File: 2025_05_08_THC_Maleic_Acid_Slurry_n60C_100C_5Cmin_x3.csv
Filename,2025_05_08_THC_Maleic_Acid_Slurry_n60C_100C_5Cmin_x3
Instrument name,DSC2A-00468 (192.168.1.100)
Operator,Yarger
rundate,5/8/2025
Sample name,2025_05_08_THC_Maleic_Acid_Slurry_n60C_100C_5Cmin_x3
proceduresegments,Data Off ; Equilibrate -60.00 °C; Data On ; Ramp 5.00 °C/min to 100.00 °C; Data Off ; Isothermal 1.0 min; Data On ; Ramp 5.00 °C/min to -60.00 °C; Data Off ; Isothermal 1.0 min; Data On ; Ramp 5.00 °C/min to 100.00 °C; Data Off ; Isothermal 1.0 min; Data On ; Ramp 5.00 °C/min to -60.00 °C; Data Off ; Isothermal 1.0 min; Data On ; Ramp 5.00 °C/min to 30.00 °C
[File Parameters]
Run date,5/8/2025 8:42:15 PM
Trios version,5.1.1.46572
Original File Name,
Current File Name,D:\DSC2500\JYarger\2025_05_08_THC_Maleic_Acid_Slurry_n60C_100C_5Cmin_x3.tri
[Procedure]
Procedure Name,THC_MA_n60C_100C_5Cmin_x3
Sample Name,2025_05_08_THC_Maleic_Acid_Slurry_n60C_100C_5Cmin_x3
Sample Mass,9.97 mg
Reference Sample Mass,0 mg
Pan Mass,56.36 mg
Pan Number,26
Reference Pan Mass,57.13 mg
Reference Pan Number,37
Pan Type,Tzero Aluminum Hermetic
Comments,Al Hermetic DSC Consumables sealed Pan/Lid. Y2 Tray (Google Sheet: DSC_Samples_Vext_Y2_Tray_May2025)
Project Name,CA
Operator,Yarger
Test,Custom
Unload Max Temperature,30
Unload Min Temperature,30
Load Max Temperature,30
Load Min Temperature,30
Stop on Gas Flow Error,Yes
[Signal List]
Signal #1,Time (min)
Signal #2,Temperature (°C)
Signal #3,Heat Flow (mW)
Signal #4,Delta T (µV)
Signal #5,Delta Tzero (µV)
Signal #6,Tzero Temperature (°C)
Signal #7,Cell Purge (mL/min)
Signal #8,Heater Temp (°C)
Signal #9,Power Delivered (W)
Signal #10,Reference Junction Temperature (°C)
Signal #11,Flange Temperature (°C)
Signal #12,Heat Flow Phase (rad)
Signal #13,Total Heat Capacity (J/°C)
Signal #14,Heat Capacity (J/°C)
[Configuration]
Company Name,ASU
Instrument Name,DSC2A-00468
Instrument Type,DSC2500
Serial Number,DSC2A-00468
IP,192.168.1.100
Location of Instrument,MRRC
DisplayType,Unknown
Sample Interval ,0.1 s/pt
Selected Heat Flow,T4P
Exotherm Direction,Down
Cell Serial,DRC2-00792
Lid Type,Standard
Cooler,RCS 90
Leave Cooler on at End of Sequence,On
Gas 2,Nitrogen
Gas Selected,Channel 1
Flow Rate,50 mL/min
Secondary Purge,On
Licensed Heat Flow,Heat Flow T4P
Modulation Licensed,Yes
[Versions]
Common IDD Version,1
Cortex Version,VER 2.10.2.31
Driver,5.0.0.6
GDM Version,1.0.3.3
TouchscreenVersion,1.0.0.16145
FEP Version,1.2.1.21
FEP Bootloader,2.0.0.5
AutoSampler Version,2.1.1.26
Auto Sampler Bootloader,2.0.0.5
FCM Version,1.1.0.3
FCM Bootloader,2.0.0.5
[Experiment Logs]
Experiment Log Entry # 1,Data On set to 0
Experiment Log Entry # 3,Equilibrate Segment -60 (C) Started
Experiment Log Entry # 5,Air Cool is off.
Experiment Log Entry # 7,Data On set to 1
Experiment Log Entry # 9,Ramp Segment 5 C/min to 100 Started
Experiment Log Entry # 11,Data On set to 0
Experiment Log Entry # 13,Isothermal Segment 1 min started
Experiment Log Entry # 15,Data On set to 1
Experiment Log Entry # 17,Ramp Segment 5 C/min to -60 Started
Experiment Log Entry # 19,Data On set to 0
Experiment Log Entry # 21,Isothermal Segment 1 min started
Experiment Log Entry # 23,Data On set to 1
Experiment Log Entry # 25,Ramp Segment 5 C/min to 100 Started
Experiment Log Entry # 27,Data On set to 0
Experiment Log Entry # 29,Isothermal Segment 1 min started
Experiment Log Entry # 31,Data On set to 1
Experiment Log Entry # 33,Ramp Segment 5 C/min to -60 Started
Experiment Log Entry # 35,Data On set to 0
Experiment Log Entry # 37,Isothermal Segment 1 min started
Experiment Log Entry # 39,Data On set to 1
Experiment Log Entry # 41,Ramp Segment 5 C/min to 30 Started
[Method Log]
Method Log Entry # 1,Data Off
Method Log Entry # 2,Equilibrate -60 °C
Method Log Entry # 3,Data On
Method Log Entry # 4,(Ramp 390768) Ramp 5 °C/minute to 100 °C
Method Log Entry # 5,Data Off
Method Log Entry # 6,Isothermal 1 minutes
Method Log Entry # 7,Data On
Method Log Entry # 8,(Ramp 390772) Ramp 5 °C/minute to -60 °C
Method Log Entry # 9,Data Off
Method Log Entry # 10,Isothermal 1 minutes
Method Log Entry # 11,Data On
Method Log Entry # 12,(Ramp 390776) Ramp 5 °C/minute to 100 °C
Method Log Entry # 13,Data Off
Method Log Entry # 14,Isothermal 1 minutes
Method Log Entry # 15,Data On
Method Log Entry # 16,(Ramp 390780) Ramp 5 °C/minute to -60 °C
Method Log Entry # 17,Data Off
Method Log Entry # 18,Isothermal 1 minutes
Method Log Entry # 19,Data On
Method Log Entry # 20,(Ramp 390784) Ramp 5 °C/minute to 30 °C
Cell Serial,DRC2-00792
[T1 Calibration]
Slope,-0.008529666
Offset,9.636258
Initial Temperature,98.23
GUID,f8bfdadc-4977-4fdf-ba6d-0ba9134940c3
[TZero Calibration]
Date Applied,11/29/2022 4:06:13 PM
Description,From -89.059 °C to 396.009 °C at 20.000°C/min
Gas Type,Nitrogen
Pan Type,None
Source Files 1,C:\Users\yargerlab\Desktop\DSC Data\General\TZero_calibration_11_29_22_2nd(2).tri
Source Files 2,C:\Users\yargerlab\Desktop\DSC Data\General\TZero_calibration_11_29_22_2nd(3).tri
Delta T Offset,13.05235
Delta T Slope,-0.007271007
Delta T0 Offset,-13.69128
Delta T0 Slope,0.06063341
[Temperature Calibration]
Date Applied,11/29/2022 7:12:28 PM
Description,From 106.590 °C to 186.590 °C at 10.000°C/min
Gas Type,Nitrogen
Pan Type,Tzero Aluminum Hermetic
Source Files 1,C:\Users\yargerlab\Desktop\DSC Data\General\Indium(6).tri
Measured 1,157.391
Known 1,156.598
[Cell Constant Calibration]
Date Applied,11/29/2022 7:12:29 PM
Description,From 106.590 °C to 186.590 °C at 10.000°C/min
Gas Type,Nitrogen
Pan Type,Tzero Aluminum Hermetic
Source Files 1,C:\Users\yargerlab\Desktop\DSC Data\General\Indium(6).tri
T4P KCell,1.006051
Onset Slope,63.26126 mW/°C
[Direct Cp Calibration]
Date Applied,11/30/2022 11:04:51 AM
Description,From -79.983 °C to 298.409 °C at 10.000°C/min
Gas Type,Nitrogen
Pan Type,Tzero Aluminum Hermetic
Source Files 1,C:\Users\yargerlab\Desktop\DSC Data\General\Sapphire_Heat_Capacity_11_30_22.tri
[Rev Cp Calibration]
Date Applied,11/30/2022 1:58:51 PM
Description,From -79.996 °C to 292.812 °C at 3.000°C/min
Gas Type,Nitrogen
Pan Type,Tzero Aluminum Hermetic
Source Files 1,C:\Users\yargerlab\Desktop\DSC Data\General\Sapphire_MDSC_Calibration_11_30_22.tri
[step]
Ramp 5.00 °C/min to 100.00 °C
Time,Temperature,Heat Flow (Normalized)
min,°C,W/g
0.00,-59.64,-0.060
0.02,-59.66,-0.061
0.04,-59.67,-0.054
0.07,-59.67,-0.050
0.09,-59.64,-0.047
0.11,-59.60,-0.045
0.13,-59.55,-0.042
0.15,-59.48,-0.035
0.17,-59.41,-0.027
0.19,-59.33,-0.018
0.22,-59.25,-0.009
0.24,-59.17,0.000
0.26,-59.08,0.008
0.28,-59.00,0.015
0.30,-58.91,0.021
0.33,-58.81,0.026
0.35,-58.72,0.032
0.37,-58.63,0.037
0.39,-58.53,0.041
0.41,-58.43,0.045
0.43,-58.33,0.048
0.45,-58.24,0.051
0.48,-58.14,0.054
0.50,-58.04,0.056
0.52,-57.94,0.058
0.54,-57.83,0.060
0.56,-57.73,0.061
0.58,-57.63,0.063
0.61,-57.52,0.064
0.63,-57.42,0.065
0.65,-57.32,0.066
0.67,-57.21,0.067
0.69,-57.11,0.068
0.72,-57.00,0.068
0.74,-56.90,0.069
0.76,-56.79,0.069
0.78,-56.68,0.070
0.80,-56.58,0.071
0.82,-56.47,0.071
0.85,-56.37,0.071
0.87,-56.26,0.071
0.89,-56.15,0.072
0.91,-56.05,0.072
0.93,-55.94,0.072
0.95,-55.84,0.072
0.98,-55.73,0.073
1.00,-55.62,0.073
1.02,-55.51,0.073
1.04,-55.41,0.073
1.06,-55.30,0.074
1.08,-55.19,0.074
1.11,-55.09,0.074
1.13,-54.98,0.074
1.15,-54.87,0.074
1.17,-54.76,0.075
1.19,-54.66,0.075
1.21,-54.55,0.075
1.23,-54.44,0.075
1.26,-54.33,0.075
1.28,-54.23,0.075
1.30,-54.12,0.075
1.32,-54.01,0.075
1.34,-53.90,0.076
1.37,-53.80,0.076
1.39,-53.69,0.076
1.41,-53.58,0.076
1.43,-53.47,0.076
1.45,-53.36,0.076
1.47,-53.26,0.076
1.49,-53.15,0.076
1.52,-53.04,0.076
1.54,-52.93,0.076
1.56,-52.82,0.076
1.58,-52.72,0.076
1.60,-52.61,0.077
1.63,-52.50,0.077
1.65,-52.39,0.077
1.67,-52.29,0.077
1.69,-52.18,0.077
1.71,-52.07,0.077
1.73,-51.96,0.077
1.76,-51.85,0.077
1.78,-51.74,0.077
1.80,-51.64,0.077
1.82,-51.53,0.077
1.84,-51.42,0.077
1.86,-51.31,0.077
1.88,-51.20,0.077
1.91,-51.10,0.077
1.93,-50.99,0.077
1.95,-50.88,0.077
1.97,-50.77,0.077
1.99,-50.66,0.077
2.02,-50.56,0.077
2.04,-50.45,0.077
2.06,-50.34,0.077
2.08,-50.23,0.077
2.10,-50.12,0.077
2.12,-50.01,0.077
2.14,-49.91,0.077
2.17,-49.80,0.077
2.19,-49.69,0.077
2.21,-49.58,0.077
2.23,-49.47,0.077
2.25,-49.37,0.077
2.28,-49.26,0.077
2.30,-49.15,0.077
2.32,-49.04,0.077
2.34,-48.93,0.077
2.36,-48.83,0.077
2.38,-48.72,0.077
2.41,-48.61,0.077
2.43,-48.50,0.077
2.45,-48.39,0.077
2.47,-48.28,0.077
2.49,-48.18,0.077
2.51,-48.07,0.077
2.54,-47.96,0.077
2.56,-47.85,0.077
2.58,-47.74,0.077
2.60,-47.63,0.077
2.62,-47.53,0.077
2.64,-47.42,0.077
2.66,-47.31,0.077
2.69,-47.20,0.077
2.71,-47.09,0.077
2.73,-46.99,0.077
2.75,-46.88,0.078
2.77,-46.77,0.077
2.79,-46.66,0.077
2.82,-46.55,0.077
2.84,-46.45,0.077
2.86,-46.33,0.078
2.88,-46.23,0.078
2.90,-46.12,0.078
2.93,-46.01,0.078
2.95,-45.90,0.078
2.97,-45.79,0.078
2.99,-45.69,0.078
3.01,-45.58,0.078
3.03,-45.47,0.078
3.06,-45.36,0.078
3.08,-45.25,0.078
3.10,-45.15,0.078
3.12,-45.04,0.078
3.14,-44.93,0.078
3.16,-44.82,0.078
3.19,-44.71,0.078
3.21,-44.60,0.078
3.23,-44.50,0.078
3.25,-44.39,0.078
3.27,-44.28,0.078
3.29,-44.17,0.078
3.31,-44.06,0.078
3.34,-43.95,0.078
3.36,-43.85,0.078
3.38,-43.74,0.078
3.40,-43.63,0.078
3.42,-43.52,0.078
3.44,-43.41,0.078
3.47,-43.30,0.078
3.49,-43.19,0.078
3.51,-43.09,0.078
3.53,-42.98,0.078
3.55,-42.87,0.078
3.58,-42.76,0.078
3.60,-42.65,0.078
3.62,-42.54,0.078
3.64,-42.43,0.078
3.66,-42.33,0.078
3.68,-42.22,0.078
3.71,-42.11,0.078
3.73,-42.00,0.078
3.75,-41.89,0.078
3.77,-41.78,0.078
3.79,-41.68,0.078
3.81,-41.57,0.078
3.84,-41.46,0.078
3.86,-41.35,0.078
3.88,-41.24,0.078
3.90,-41.13,0.078
3.92,-41.03,0.078
3.94,-40.92,0.078
3.96,-40.81,0.078
3.99,-40.70,0.078
4.01,-40.59,0.078
4.03,-40.49,0.078
4.05,-40.38,0.078
4.07,-40.27,0.078
4.09,-40.16,0.078
4.12,-40.05,0.078
4.14,-39.94,0.078
4.16,-39.83,0.078
4.18,-39.73,0.078
4.20,-39.62,0.078
4.23,-39.51,0.078
4.25,-39.40,0.078
4.27,-39.29,0.078
4.29,-39.18,0.078
4.31,-39.07,0.078
4.33,-38.97,0.078
4.35,-38.86,0.078
4.38,-38.75,0.078
4.40,-38.64,0.078
4.42,-38.53,0.078
4.44,-38.42,0.079
4.46,-38.31,0.079
4.49,-38.20,0.079
4.51,-38.10,0.079
4.53,-37.99,0.079
4.55,-37.88,0.079
4.57,-37.77,0.079
4.59,-37.66,0.079
4.61,-37.56,0.079
4.64,-37.44,0.079
4.66,-37.34,0.079
4.68,-37.23,0.079
4.70,-37.12,0.079
4.72,-37.01,0.079
4.75,-36.90,0.079
4.77,-36.79,0.079
4.79,-36.69,0.079
4.81,-36.58,0.079
4.83,-36.47,0.079
4.85,-36.36,0.079
4.88,-36.25,0.079
4.90,-36.14,0.079
4.92,-36.04,0.079
4.94,-35.93,0.079
4.96,-35.82,0.079
4.98,-35.71,0.079
5.00,-35.60,0.079
5.03,-35.49,0.079
5.05,-35.38,0.079
5.07,-35.28,0.079
5.09,-35.17,0.079
5.11,-35.06,0.079
5.14,-34.95,0.079
5.16,-34.84,0.079
5.18,-34.73,0.079
5.20,-34.63,0.079
5.22,-34.52,0.079
5.24,-34.41,0.079
5.26,-34.30,0.079
5.29,-34.19,0.079
5.31,-34.08,0.079
5.33,-33.97,0.079
5.35,-33.87,0.079
5.37,-33.76,0.079
5.40,-33.65,0.079
5.42,-33.54,0.079
5.44,-33.43,0.079
5.46,-33.32,0.079
5.48,-33.21,0.079
5.50,-33.11,0.079
5.53,-33.00,0.079
5.55,-32.89,0.079
5.57,-32.78,0.079
5.59,-32.67,0.079
5.61,-32.56,0.079
5.63,-32.45,0.079
5.65,-32.35,0.079
5.68,-32.24,0.079
5.70,-32.13,0.079
5.72,-32.02,0.079
5.74,-31.91,0.079
5.76,-31.80,0.079
5.79,-31.69,0.079
5.81,-31.59,0.079
5.83,-31.48,0.080
5.85,-31.37,0.080
5.87,-31.26,0.080
5.89,-31.16,0.080
5.91,-31.05,0.080
5.94,-30.94,0.080
5.96,-30.83,0.080
5.98,-30.72,0.080
6.00,-30.61,0.080
6.02,-30.50,0.080
6.05,-30.40,0.080
6.07,-30.29,0.080
6.09,-30.18,0.080
6.11,-30.07,0.080
6.13,-29.96,0.080
6.15,-29.85,0.080
6.18,-29.74,0.080
6.20,-29.64,0.080
6.22,-29.53,0.080
6.24,-29.42,0.080
6.26,-29.31,0.080
6.28,-29.20,0.080
6.30,-29.09,0.080
6.33,-28.98,0.080
6.35,-28.88,0.080
6.37,-28.77,0.080
6.39,-28.66,0.080
6.41,-28.55,0.080
6.44,-28.44,0.080
6.46,-28.33,0.080
6.48,-28.23,0.080
6.50,-28.12,0.080
6.52,-28.01,0.080
6.54,-27.90,0.080
6.56,-27.79,0.080
6.59,-27.69,0.080
6.61,-27.58,0.080
6.63,-27.47,0.080
6.65,-27.36,0.080
6.67,-27.25,0.080
6.70,-27.14,0.080
6.72,-27.03,0.080
6.74,-26.92,0.080
6.76,-26.82,0.080
6.78,-26.71,0.080
6.80,-26.60,0.080
6.83,-26.49,0.080
6.85,-26.38,0.080
6.87,-26.27,0.080
6.89,-26.16,0.080
6.91,-26.05,0.080
6.93,-25.94,0.081
6.95,-25.83,0.081
6.98,-25.73,0.081
7.00,-25.62,0.081
7.02,-25.51,0.081
7.04,-25.40,0.081
7.06,-25.29,0.081
7.09,-25.18,0.081
7.11,-25.08,0.081
7.13,-24.97,0.081
7.15,-24.86,0.081
7.17,-24.75,0.081
7.19,-24.64,0.081
7.21,-24.54,0.081
7.24,-24.43,0.081
7.26,-24.32,0.081
7.28,-24.21,0.081
7.30,-24.10,0.081
7.32,-23.99,0.081
7.35,-23.89,0.081
7.37,-23.78,0.081
7.39,-23.67,0.081
7.41,-23.56,0.081
7.43,-23.45,0.081
7.45,-23.35,0.081
7.48,-23.24,0.081
7.50,-23.13,0.081
7.52,-23.03,0.081
7.54,-22.92,0.081
7.56,-22.81,0.081
7.58,-22.70,0.081
7.60,-22.59,0.081
7.63,-22.48,0.081
7.65,-22.38,0.081
7.67,-22.27,0.081
7.69,-22.16,0.081
7.71,-22.05,0.081
7.74,-21.94,0.081
7.76,-21.83,0.081
7.78,-21.72,0.081
7.80,-21.62,0.081
7.82,-21.51,0.081
7.84,-21.40,0.081
7.86,-21.29,0.081
7.89,-21.18,0.081
7.91,-21.07,0.081
7.93,-20.96,0.081
7.95,-20.85,0.081
7.97,-20.75,0.081
8.00,-20.64,0.081
8.02,-20.53,0.082
8.04,-20.42,0.082
8.06,-20.31,0.082
8.08,-20.20,0.082
8.10,-20.10,0.082
8.13,-19.99,0.082
8.15,-19.88,0.082
8.17,-19.77,0.082
8.19,-19.66,0.082
8.21,-19.55,0.082
8.23,-19.45,0.082
8.25,-19.34,0.082
8.28,-19.23,0.082
8.30,-19.12,0.082
8.32,-19.01,0.082
8.34,-18.90,0.082
8.36,-18.79,0.082
8.39,-18.68,0.082
8.41,-18.57,0.082
8.43,-18.47,0.082
8.45,-18.36,0.082
8.47,-18.25,0.082
8.49,-18.14,0.082
8.51,-18.03,0.082
8.54,-17.92,0.082
8.56,-17.82,0.082
8.58,-17.71,0.082
8.60,-17.60,0.082
8.62,-17.49,0.082
8.65,-17.38,0.083
8.67,-17.27,0.083
8.69,-17.17,0.083
8.71,-17.06,0.083
8.73,-16.95,0.083
8.75,-16.84,0.083
8.78,-16.73,0.083
8.80,-16.62,0.083
8.82,-16.52,0.083
8.84,-16.41,0.083
8.86,-16.30,0.083
8.88,-16.19,0.083
8.90,-16.08,0.083
8.93,-15.97,0.083
8.95,-15.87,0.083
8.97,-15.76,0.083
8.99,-15.65,0.083
9.01,-15.54,0.083
9.03,-15.43,0.083
9.06,-15.32,0.083
9.08,-15.22,0.083
9.10,-15.11,0.083
9.12,-15.00,0.083
9.14,-14.89,0.083
9.17,-14.78,0.083
9.19,-14.67,0.083
9.21,-14.57,0.083
9.23,-14.46,0.083
9.25,-14.35,0.084
9.27,-14.24,0.084
9.30,-14.13,0.084
9.32,-14.02,0.084
9.34,-13.91,0.084
9.36,-13.81,0.084
9.38,-13.70,0.084
9.40,-13.59,0.084
9.43,-13.48,0.084
9.45,-13.37,0.084
9.47,-13.26,0.084
9.49,-13.16,0.084
9.51,-13.05,0.084
9.53,-12.94,0.084
9.55,-12.83,0.084
9.58,-12.72,0.084
9.60,-12.61,0.084
9.62,-12.51,0.085
9.64,-12.40,0.085
9.66,-12.29,0.085
9.68,-12.18,0.085
9.71,-12.07,0.085
9.73,-11.96,0.085
9.75,-11.85,0.085
9.77,-11.75,0.085
9.79,-11.64,0.085
9.82,-11.53,0.085
9.84,-11.42,0.085
9.86,-11.31,0.085
9.88,-11.20,0.085
9.90,-11.10,0.086
9.92,-10.99,0.086
9.95,-10.88,0.086
9.97,-10.77,0.086
9.99,-10.66,0.086
10.01,-10.55,0.086
10.03,-10.45,0.086
10.05,-10.34,0.086
10.08,-10.23,0.086
10.10,-10.12,0.086
10.12,-10.01,0.086
10.14,-9.90,0.087
10.16,-9.80,0.087
10.18,-9.69,0.087
10.20,-9.58,0.087
10.23,-9.47,0.087
10.25,-9.36,0.087
10.27,-9.25,0.087
10.29,-9.15,0.087
10.31,-9.04,0.087
10.33,-8.93,0.087
10.36,-8.82,0.088
10.38,-8.71,0.088
10.40,-8.60,0.088
10.42,-8.50,0.088
10.44,-8.39,0.088
10.47,-8.28,0.088
10.49,-8.17,0.088
10.51,-8.06,0.088
10.53,-7.95,0.089
10.55,-7.85,0.089
10.57,-7.74,0.089
10.60,-7.63,0.089
10.62,-7.52,0.089
10.64,-7.41,0.089
10.66,-7.31,0.089
10.68,-7.20,0.089
10.70,-7.09,0.089
10.73,-6.98,0.090
10.75,-6.87,0.090
10.77,-6.76,0.090
10.79,-6.65,0.090
10.81,-6.55,0.090
10.83,-6.44,0.090
10.85,-6.33,0.091
10.88,-6.22,0.091
10.90,-6.11,0.091
10.92,-6.00,0.091
10.94,-5.89,0.091
10.96,-5.78,0.091
10.98,-5.68,0.092
11.01,-5.57,0.092
11.03,-5.46,0.092
11.05,-5.35,0.092
11.07,-5.24,0.092
11.09,-5.14,0.092
11.12,-5.03,0.093
11.14,-4.92,0.093
11.16,-4.81,0.093
11.18,-4.70,0.093
11.20,-4.59,0.093
11.22,-4.49,0.093
11.25,-4.38,0.094
11.27,-4.27,0.094
11.29,-4.16,0.094
11.31,-4.05,0.094
11.33,-3.94,0.094
11.35,-3.84,0.094
11.38,-3.73,0.095
11.40,-3.62,0.095
11.42,-3.51,0.095
11.44,-3.40,0.095
11.46,-3.30,0.095
11.48,-3.19,0.095
11.50,-3.08,0.095
11.53,-2.97,0.096
11.55,-2.86,0.096
11.57,-2.75,0.096
11.59,-2.65,0.096
11.61,-2.54,0.096
11.63,-2.43,0.096
11.66,-2.32,0.097
11.68,-2.21,0.097
11.70,-2.11,0.097
11.72,-2.00,0.097
11.74,-1.89,0.097
11.77,-1.78,0.097
11.79,-1.67,0.098
11.81,-1.56,0.098
11.83,-1.45,0.098
11.85,-1.35,0.098
11.87,-1.24,0.098
11.90,-1.13,0.098
11.92,-1.02,0.098
11.94,-0.91,0.099
11.96,-0.81,0.099
11.98,-0.70,0.099
12.00,-0.59,0.099
12.03,-0.48,0.099
12.05,-0.37,0.099
12.07,-0.26,0.099
12.09,-0.15,0.099
12.11,-0.05,0.099
12.13,0.06,0.100
12.15,0.17,0.100
12.18,0.28,0.100
12.20,0.39,0.100
12.22,0.50,0.100
12.24,0.60,0.100
12.26,0.71,0.100
12.28,0.82,0.100
12.31,0.93,0.100
12.33,1.04,0.100
12.35,1.15,0.100
12.37,1.25,0.100
12.39,1.36,0.100
12.42,1.47,0.101
12.44,1.58,0.101
12.46,1.69,0.101
12.48,1.80,0.101
12.50,1.90,0.101
12.52,2.01,0.101
12.55,2.12,0.101
12.57,2.23,0.101
12.59,2.34,0.101
12.61,2.45,0.101
12.63,2.55,0.101
12.65,2.66,0.101
12.68,2.77,0.101
12.70,2.88,0.101
12.72,2.99,0.101
12.74,3.10,0.101
12.76,3.21,0.101
12.78,3.31,0.101
12.80,3.42,0.101
12.83,3.53,0.101
12.85,3.64,0.101
12.87,3.75,0.101
12.89,3.86,0.101
12.91,3.96,0.101
12.93,4.07,0.101
12.96,4.18,0.101
12.98,4.29,0.101
13.00,4.40,0.101
13.02,4.51,0.101
13.04,4.62,0.101
13.07,4.72,0.101
13.09,4.83,0.101
13.11,4.94,0.101
13.13,5.05,0.101
13.15,5.16,0.101
13.17,5.27,0.101
13.20,5.37,0.101
13.22,5.48,0.101
13.24,5.59,0.101
13.26,5.70,0.101
13.28,5.81,0.101
13.30,5.92,0.101
13.33,6.02,0.101
13.35,6.13,0.101
13.37,6.24,0.101
13.39,6.35,0.101
13.41,6.46,0.101
13.43,6.57,0.101
13.45,6.68,0.101
13.48,6.78,0.101
13.50,6.89,0.101
13.52,7.00,0.101
13.54,7.11,0.101
13.56,7.22,0.101
13.58,7.33,0.101
13.61,7.44,0.101
13.63,7.54,0.101
13.65,7.65,0.101
13.67,7.76,0.102
13.69,7.87,0.102
13.72,7.98,0.102
13.74,8.09,0.102
13.76,8.19,0.102
13.78,8.30,0.102
13.80,8.41,0.102
13.82,8.52,0.102
13.85,8.63,0.102
13.87,8.74,0.102
13.89,8.84,0.102
13.91,8.95,0.102
13.93,9.06,0.102
13.95,9.17,0.102
13.98,9.28,0.102
14.00,9.39,0.102
14.02,9.49,0.102
14.04,9.60,0.102
14.06,9.71,0.102
14.08,9.82,0.102
14.10,9.93,0.102
14.13,10.04,0.102
14.15,10.15,0.102
14.17,10.25,0.102
14.19,10.36,0.102
14.21,10.47,0.102
14.23,10.58,0.102
14.26,10.69,0.102
14.28,10.80,0.102
14.30,10.90,0.102
14.32,11.01,0.102
14.34,11.12,0.102
14.37,11.23,0.102
14.39,11.34,0.102
14.41,11.45,0.102
14.43,11.55,0.102
14.45,11.66,0.102
14.47,11.77,0.102
14.50,11.88,0.102
14.52,11.99,0.102
14.54,12.10,0.102
14.56,12.21,0.102
14.58,12.31,0.102
14.60,12.42,0.102
14.63,12.53,0.103
14.65,12.64,0.103
14.67,12.75,0.103
14.69,12.86,0.103
14.71,12.96,0.103
14.73,13.07,0.103
14.75,13.18,0.103
14.78,13.29,0.103
14.80,13.40,0.103
14.82,13.51,0.103
14.84,13.62,0.103
14.86,13.72,0.103
14.88,13.83,0.103
14.91,13.94,0.103
14.93,14.05,0.103
14.95,14.16,0.103
14.97,14.27,0.103
14.99,14.37,0.103
15.02,14.48,0.103
15.04,14.59,0.103
15.06,14.70,0.103
15.08,14.81,0.103
15.10,14.92,0.103
15.12,15.02,0.103
15.15,15.13,0.103
15.17,15.24,0.103
15.19,15.35,0.103
15.21,15.46,0.103
15.23,15.57,0.103
15.25,15.67,0.103
15.28,15.78,0.103
15.30,15.89,0.103
15.32,16.00,0.103
15.34,16.11,0.103
15.36,16.22,0.103
15.38,16.33,0.103
15.40,16.43,0.103
15.43,16.54,0.103
15.45,16.65,0.103
15.47,16.76,0.104
15.49,16.87,0.104
15.51,16.98,0.104
15.53,17.09,0.104
15.56,17.19,0.104
15.58,17.30,0.104
15.60,17.41,0.104
15.62,17.52,0.104
15.64,17.63,0.104
15.67,17.74,0.104
15.69,17.84,0.104
15.71,17.95,0.104
15.73,18.06,0.104
15.75,18.17,0.104
15.77,18.28,0.104
15.80,18.38,0.104
15.82,18.49,0.104
15.84,18.60,0.104
15.86,18.71,0.104
15.88,18.82,0.104
15.90,18.93,0.104
15.93,19.04,0.104
15.95,19.14,0.104
15.97,19.25,0.104
15.99,19.36,0.104
16.01,19.47,0.104
16.03,19.58,0.104
16.05,19.69,0.104
16.08,19.79,0.104
16.10,19.90,0.104
16.12,20.01,0.104
16.14,20.12,0.104
16.16,20.23,0.104
16.18,20.34,0.104
16.21,20.44,0.104
16.23,20.55,0.105
16.25,20.66,0.105
16.27,20.77,0.105
16.29,20.88,0.105
16.32,20.99,0.105
16.34,21.09,0.105
16.36,21.20,0.105
16.38,21.31,0.105
16.40,21.42,0.105
16.42,21.53,0.105
16.45,21.64,0.105
16.47,21.75,0.105
16.49,21.85,0.105
16.51,21.96,0.105
16.53,22.07,0.105
16.55,22.18,0.105
16.58,22.29,0.105
16.60,22.40,0.105
16.62,22.50,0.105
16.64,22.61,0.105
16.66,22.72,0.105
16.68,22.83,0.105
16.70,22.94,0.105
16.73,23.05,0.105
16.75,23.15,0.105
16.77,23.26,0.105
16.79,23.37,0.105
16.81,23.48,0.105
16.83,23.59,0.105
16.86,23.70,0.105
16.88,23.81,0.106
16.90,23.91,0.106
16.92,24.02,0.106
16.94,24.13,0.106
16.97,24.24,0.106
16.99,24.35,0.106
17.01,24.45,0.106
17.03,24.56,0.106
17.05,24.67,0.106
17.07,24.78,0.106
17.09,24.89,0.106
17.12,25.00,0.106
17.14,25.11,0.106
17.16,25.21,0.106
17.18,25.32,0.106
17.20,25.43,0.106
17.23,25.54,0.106
17.25,25.65,0.106
17.27,25.76,0.106
17.29,25.86,0.106
17.31,25.97,0.106
17.33,26.08,0.106
17.36,26.19,0.106
17.38,26.30,0.106
17.40,26.41,0.106
17.42,26.51,0.106
17.44,26.62,0.106
17.46,26.73,0.106
17.48,26.84,0.107
17.51,26.95,0.107
17.53,27.06,0.107
17.55,27.17,0.107
17.57,27.27,0.107
17.59,27.38,0.107
17.62,27.49,0.107
17.64,27.60,0.107
17.66,27.71,0.107
17.68,27.82,0.107
17.70,27.92,0.107
17.72,28.03,0.107
17.74,28.14,0.107
17.77,28.25,0.107
17.79,28.36,0.107
17.81,28.47,0.107
17.83,28.57,0.107
17.85,28.68,0.107
17.88,28.79,0.107
17.90,28.90,0.107
17.92,29.01,0.107
17.94,29.12,0.107
17.96,29.22,0.107
17.98,29.33,0.107
18.01,29.44,0.107
18.03,29.55,0.107
18.05,29.66,0.107
18.07,29.77,0.107
18.09,29.88,0.108
18.11,29.98,0.108
18.13,30.09,0.108
18.16,30.20,0.108
18.18,30.31,0.108
18.20,30.42,0.108
18.22,30.53,0.108
18.24,30.64,0.108
18.27,30.74,0.108
18.29,30.85,0.108
18.31,30.96,0.108
18.33,31.07,0.108
18.35,31.18,0.108
18.37,31.28,0.108
18.39,31.39,0.108
18.42,31.50,0.108
18.44,31.61,0.108
18.46,31.72,0.108
18.48,31.83,0.108
18.50,31.94,0.108
18.53,32.04,0.108
18.55,32.15,0.108
18.57,32.26,0.108
18.59,32.37,0.108
18.61,32.48,0.108
18.63,32.59,0.108
18.66,32.70,0.108
18.68,32.80,0.108
18.70,32.91,0.108
18.72,33.02,0.108
18.74,33.13,0.108
18.76,33.24,0.108
18.78,33.34,0.109
18.81,33.45,0.109
18.83,33.56,0.109
18.85,33.67,0.109
18.87,33.78,0.109
18.89,33.89,0.109
18.92,33.99,0.109
18.94,34.10,0.109
18.96,34.21,0.109
18.98,34.32,0.109
19.00,34.43,0.109
19.02,34.54,0.109
19.04,34.64,0.109
19.07,34.75,0.109
19.09,34.86,0.109
19.11,34.97,0.109
19.13,35.08,0.109
19.15,35.19,0.109
19.18,35.29,0.109
19.20,35.40,0.109
19.22,35.51,0.109
19.24,35.62,0.109
19.26,35.73,0.109
19.28,35.84,0.109
19.31,35.95,0.109
19.33,36.05,0.109
19.35,36.16,0.109
19.37,36.27,0.109
19.39,36.38,0.109
19.41,36.49,0.109
19.43,36.60,0.109
19.46,36.70,0.109
19.48,36.81,0.110
19.50,36.92,0.110
19.52,37.03,0.110
19.54,37.14,0.110
19.57,37.25,0.110
19.59,37.35,0.110
19.61,37.46,0.110
19.63,37.57,0.110
19.65,37.68,0.110
19.67,37.79,0.110
19.69,37.90,0.110
19.72,38.01,0.110
19.74,38.11,0.110
19.76,38.22,0.110
19.78,38.33,0.110
19.80,38.44,0.110
19.83,38.55,0.110
19.85,38.66,0.110
19.87,38.76,0.110
19.89,38.87,0.110
19.91,38.98,0.110
19.93,39.09,0.110
19.96,39.20,0.110
19.98,39.31,0.110
20.00,39.41,0.110
20.02,39.52,0.110
20.04,39.63,0.110
20.06,39.74,0.110
20.08,39.85,0.110
20.11,39.96,0.110
20.13,40.06,0.110
20.15,40.17,0.110
20.17,40.28,0.110
20.19,40.39,0.110
20.22,40.50,0.110
20.24,40.61,0.110
20.26,40.72,0.110
20.28,40.82,0.111
20.30,40.93,0.111
20.32,41.04,0.111
20.34,41.15,0.111
20.37,41.26,0.111
20.39,41.37,0.111
20.41,41.47,0.111
20.43,41.58,0.111
20.45,41.69,0.111
20.48,41.80,0.111
20.50,41.91,0.111
20.52,42.02,0.111
20.54,42.13,0.111
20.56,42.23,0.111
20.58,42.34,0.111
20.61,42.45,0.111
20.63,42.56,0.111
20.65,42.67,0.111
20.67,42.78,0.111
20.69,42.88,0.111
20.71,42.99,0.111
20.73,43.10,0.111
20.76,43.21,0.111
20.78,43.32,0.111
20.80,43.43,0.111
20.82,43.53,0.111
20.84,43.64,0.111
20.87,43.75,0.111
20.89,43.86,0.111
20.91,43.97,0.111
20.93,44.08,0.111
20.95,44.19,0.111
20.97,44.29,0.111
20.99,44.40,0.111
21.02,44.51,0.111
21.04,44.62,0.112
21.06,44.73,0.112
21.08,44.84,0.112
21.10,44.94,0.112
21.13,45.05,0.112
21.15,45.16,0.112
21.17,45.27,0.112
21.19,45.38,0.112
21.21,45.48,0.112
21.23,45.59,0.112
21.26,45.70,0.112
21.28,45.81,0.112
21.30,45.92,0.112
21.32,46.03,0.112
21.34,46.14,0.112
21.36,46.24,0.112
21.38,46.35,0.112
21.41,46.46,0.112
21.43,46.57,0.112
21.45,46.68,0.112
21.47,46.79,0.112
21.49,46.90,0.112
21.52,47.00,0.112
21.54,47.11,0.112
21.56,47.22,0.112
21.58,47.33,0.112
21.60,47.44,0.112
21.62,47.55,0.112
21.64,47.65,0.112
21.67,47.76,0.112
21.69,47.87,0.112
21.71,47.98,0.112
21.73,48.09,0.113
21.75,48.20,0.113
21.78,48.31,0.113
21.80,48.41,0.113
21.82,48.52,0.113
21.84,48.63,0.113
21.86,48.74,0.113
21.88,48.85,0.113
21.91,48.96,0.113
21.93,49.06,0.113
21.95,49.17,0.113
21.97,49.28,0.113
21.99,49.39,0.113
22.01,49.50,0.113
22.03,49.61,0.113
22.06,49.72,0.113
22.08,49.82,0.113
22.10,49.93,0.113
22.12,50.04,0.113
22.14,50.15,0.113
22.17,50.26,0.113
22.19,50.37,0.113
22.21,50.47,0.113
22.23,50.58,0.113
22.25,50.69,0.113
22.27,50.80,0.113
22.29,50.91,0.113
22.32,51.02,0.113
22.34,51.13,0.113
22.36,51.23,0.113
22.38,51.34,0.113
22.40,51.45,0.113
22.43,51.56,0.113
22.45,51.67,0.114
22.47,51.78,0.114
22.49,51.88,0.114
22.51,51.99,0.114
22.53,52.10,0.114
22.56,52.21,0.114
22.58,52.32,0.114
22.60,52.43,0.114
22.62,52.53,0.114
22.64,52.64,0.114
22.66,52.75,0.114
22.68,52.86,0.114
22.71,52.97,0.114
22.73,53.08,0.114
22.75,53.19,0.114
22.77,53.29,0.114
22.79,53.40,0.114
22.82,53.51,0.114
22.84,53.62,0.114
22.86,53.73,0.114
22.88,53.83,0.114
22.90,53.94,0.114
22.92,54.05,0.114
22.94,54.16,0.114
22.97,54.27,0.114
22.99,54.38,0.114
23.01,54.48,0.114
23.03,54.59,0.114
23.05,54.70,0.114
23.08,54.81,0.114
23.10,54.92,0.114
23.12,55.03,0.114
23.14,55.13,0.114
23.16,55.24,0.114
23.18,55.35,0.114
23.21,55.46,0.114
23.23,55.57,0.114
23.25,55.68,0.114
23.27,55.78,0.114
23.29,55.89,0.114
23.31,56.00,0.115
23.33,56.11,0.115
23.36,56.22,0.115
23.38,56.33,0.115
23.40,56.43,0.115
23.42,56.54,0.115
23.44,56.65,0.115
23.47,56.76,0.115
23.49,56.87,0.115
23.51,56.98,0.115
23.53,57.09,0.115
23.55,57.19,0.115
23.57,57.30,0.115
23.59,57.41,0.115
23.62,57.52,0.115
23.64,57.63,0.115
23.66,57.74,0.115
23.68,57.84,0.115
23.70,57.95,0.115
23.73,58.06,0.115
23.75,58.17,0.115
23.77,58.28,0.115
23.79,58.39,0.115
23.81,58.49,0.115
23.83,58.60,0.115
23.86,58.71,0.115
23.88,58.82,0.115
23.90,58.93,0.115
23.92,59.03,0.115
23.94,59.14,0.115
23.96,59.25,0.115
23.98,59.36,0.115
24.01,59.47,0.115
24.03,59.58,0.115
24.05,59.69,0.115
24.07,59.80,0.115
24.09,59.90,0.116
24.12,60.01,0.116
24.14,60.12,0.116
24.16,60.23,0.116
24.18,60.34,0.116
24.20,60.44,0.116
24.22,60.55,0.116
24.24,60.66,0.116
24.27,60.77,0.116
24.29,60.88,0.116
24.31,60.99,0.116
24.33,61.10,0.116
24.35,61.20,0.116
24.38,61.31,0.116
24.40,61.42,0.116
24.42,61.53,0.116
24.44,61.64,0.116
24.46,61.75,0.116
24.48,61.86,0.116
24.51,61.96,0.116
24.53,62.07,0.116
24.55,62.18,0.116
24.57,62.29,0.116
24.59,62.40,0.116
24.61,62.51,0.116
24.63,62.61,0.116
24.66,62.72,0.116
24.68,62.83,0.116
24.70,62.94,0.116
24.72,63.05,0.116
24.74,63.16,0.116
24.77,63.26,0.116
24.79,63.37,0.116
24.81,63.48,0.116
24.83,63.59,0.116
24.85,63.70,0.116
24.87,63.80,0.116
24.89,63.91,0.116
24.92,64.02,0.116
24.94,64.13,0.116
24.96,64.24,0.116
24.98,64.35,0.117
25.00,64.46,0.117
25.03,64.56,0.117
25.05,64.67,0.117
25.07,64.78,0.117
25.09,64.89,0.117
25.11,65.00,0.117
25.13,65.11,0.117
25.16,65.21,0.117
25.18,65.32,0.117
25.20,65.43,0.117
25.22,65.54,0.117
25.24,65.65,0.117
25.26,65.76,0.117
25.28,65.87,0.117
25.31,65.97,0.117
25.33,66.08,0.117
25.35,66.19,0.117
25.37,66.30,0.117
25.39,66.41,0.117
25.42,66.52,0.117
25.44,66.62,0.117
25.46,66.73,0.117
25.48,66.84,0.117
25.50,66.95,0.117
25.52,67.06,0.117
25.54,67.17,0.117
25.57,67.27,0.117
25.59,67.38,0.117
25.61,67.49,0.117
25.63,67.60,0.117
25.65,67.71,0.117
25.68,67.82,0.117
25.70,67.92,0.117
25.72,68.03,0.117
25.74,68.14,0.117
25.76,68.25,0.117
25.78,68.36,0.117
25.81,68.47,0.117
25.83,68.58,0.118
25.85,68.68,0.118
25.87,68.79,0.118
25.89,68.90,0.118
25.91,69.01,0.118
25.93,69.12,0.118
25.96,69.23,0.118
25.98,69.33,0.118
26.00,69.44,0.118
26.02,69.55,0.118
26.04,69.66,0.118
26.07,69.77,0.118
26.09,69.88,0.118
26.11,69.98,0.118
26.13,70.09,0.118
26.15,70.20,0.118
26.17,70.31,0.118
26.19,70.42,0.118
26.22,70.53,0.118
26.24,70.64,0.118
26.26,70.74,0.118
26.28,70.85,0.118
26.30,70.96,0.118
26.33,71.07,0.118
26.35,71.18,0.118
26.37,71.28,0.118
26.39,71.39,0.118
26.41,71.50,0.118
26.43,71.61,0.118
26.46,71.72,0.118
26.48,71.83,0.118
26.50,71.93,0.118
26.52,72.04,0.118
26.54,72.15,0.118
26.56,72.26,0.118
26.58,72.37,0.118
26.61,72.48,0.118
26.63,72.59,0.118
26.65,72.69,0.118
26.67,72.80,0.118
26.69,72.91,0.118
26.72,73.02,0.118
26.74,73.13,0.118
26.76,73.24,0.118
26.78,73.34,0.118
26.80,73.45,0.119
26.82,73.56,0.119
26.84,73.67,0.119
26.87,73.78,0.119
26.89,73.89,0.119
26.91,74.00,0.119
26.93,74.10,0.119
26.95,74.21,0.119
26.98,74.32,0.119
27.00,74.43,0.119
27.02,74.54,0.119
27.04,74.64,0.119
27.06,74.75,0.119
27.08,74.86,0.119
27.11,74.97,0.119
27.13,75.08,0.119
27.15,75.19,0.119
27.17,75.30,0.119
27.19,75.40,0.119
27.21,75.51,0.119
27.23,75.62,0.119
27.26,75.73,0.119
27.28,75.84,0.119
27.30,75.95,0.119
27.32,76.05,0.119
27.34,76.16,0.119
27.37,76.27,0.119
27.39,76.38,0.119
27.41,76.49,0.119
27.43,76.60,0.119
27.45,76.70,0.119
27.47,76.81,0.119
27.49,76.92,0.119
27.52,77.03,0.119
27.54,77.14,0.119
27.56,77.25,0.119
27.58,77.36,0.119
27.60,77.46,0.119
27.63,77.57,0.119
27.65,77.68,0.119
27.67,77.79,0.119
27.69,77.90,0.119
27.71,78.01,0.119
27.73,78.12,0.119
27.76,78.22,0.119
27.78,78.33,0.119
27.80,78.44,0.119
27.82,78.55,0.119
27.84,78.66,0.119
27.86,78.77,0.119
27.88,78.87,0.119
27.91,78.98,0.119
27.93,79.09,0.119
27.95,79.20,0.119
27.97,79.31,0.119
27.99,79.41,0.119
28.02,79.52,0.119
28.04,79.63,0.119
28.06,79.74,0.119
28.08,79.85,0.119
28.10,79.96,0.119
28.12,80.07,0.119
28.14,80.17,0.119
28.17,80.28,0.119
28.19,80.39,0.119
28.21,80.50,0.119
28.23,80.61,0.119
28.25,80.71,0.119
28.28,80.82,0.119
28.30,80.93,0.119
28.32,81.04,0.119
28.34,81.15,0.119
28.36,81.26,0.119
28.38,81.37,0.119
28.41,81.47,0.119
28.43,81.58,0.119
28.45,81.69,0.119
28.47,81.80,0.119
28.49,81.91,0.119
28.51,82.02,0.119
28.53,82.13,0.119
28.56,82.23,0.119
28.58,82.34,0.119
28.60,82.45,0.119
28.62,82.56,0.119
28.64,82.67,0.119
28.67,82.78,0.119
28.69,82.88,0.119
28.71,82.99,0.119
28.73,83.10,0.119
28.75,83.21,0.119
28.77,83.32,0.119
28.79,83.43,0.119
28.82,83.53,0.119
28.84,83.64,0.119
28.86,83.75,0.119
28.88,83.86,0.119
28.90,83.97,0.119
28.93,84.08,0.119
28.95,84.18,0.119
28.97,84.29,0.119
28.99,84.40,0.119
29.01,84.51,0.119
29.03,84.62,0.119
29.06,84.73,0.119
29.08,84.83,0.119
29.10,84.94,0.119
29.12,85.05,0.119
29.14,85.16,0.119
29.16,85.27,0.119
29.18,85.38,0.119
29.21,85.49,0.119
29.23,85.59,0.119
29.25,85.70,0.119
29.27,85.81,0.119
29.29,85.92,0.119
29.32,86.03,0.119
29.34,86.14,0.119
29.36,86.24,0.119
29.38,86.35,0.119
29.40,86.46,0.119
29.42,86.57,0.119
29.44,86.68,0.119
29.47,86.79,0.119
29.49,86.90,0.119
29.51,87.00,0.119
29.53,87.11,0.119
29.55,87.22,0.119
29.58,87.33,0.119
29.60,87.44,0.119
29.62,87.55,0.119
29.64,87.65,0.119
29.66,87.76,0.119
29.68,87.87,0.119
29.71,87.98,0.119
29.73,88.09,0.119
29.75,88.20,0.119
29.77,88.30,0.119
29.79,88.41,0.119
29.81,88.52,0.119
29.83,88.63,0.119
29.86,88.74,0.119
29.88,88.85,0.119
29.90,88.95,0.119
29.92,89.06,0.119
29.94,89.17,0.119
29.97,89.28,0.119
29.99,89.39,0.119
30.01,89.50,0.119
30.03,89.61,0.119
30.05,89.71,0.119
30.07,89.82,0.119
30.09,89.93,0.119
30.12,90.04,0.119
30.14,90.15,0.119
30.16,90.25,0.119
30.18,90.36,0.119
30.20,90.47,0.119
30.23,90.58,0.119
30.25,90.69,0.119
30.27,90.80,0.119
30.29,90.91,0.119
30.31,91.01,0.119
30.33,91.12,0.119
30.36,91.23,0.119
30.38,91.34,0.119
30.40,91.45,0.119
30.42,91.56,0.119
30.44,91.67,0.119
30.46,91.77,0.119
30.48,91.88,0.119
30.51,91.99,0.119
30.53,92.10,0.119
30.55,92.21,0.119
30.57,92.32,0.119
30.59,92.42,0.119
30.62,92.53,0.119
30.64,92.64,0.119
30.66,92.75,0.119
30.68,92.86,0.119
30.70,92.97,0.119
30.72,93.07,0.119
30.74,93.18,0.119
30.77,93.29,0.119
30.79,93.40,0.119
30.81,93.51,0.119
30.83,93.62,0.119
30.85,93.73,0.119
30.88,93.83,0.119
30.90,93.94,0.119
30.92,94.05,0.119
30.94,94.16,0.119
30.96,94.27,0.119
30.98,94.37,0.119
31.01,94.48,0.119
31.03,94.59,0.119
31.05,94.70,0.119
31.07,94.81,0.119
31.09,94.92,0.120
31.11,95.03,0.120
31.13,95.13,0.120
31.16,95.24,0.120
31.18,95.35,0.120
31.20,95.46,0.120
31.22,95.57,0.120
31.24,95.67,0.120
31.27,95.78,0.120
31.29,95.89,0.120
31.31,96.00,0.120
31.33,96.11,0.120
31.35,96.22,0.120
31.37,96.33,0.120
31.39,96.44,0.120
31.42,96.54,0.120
31.44,96.65,0.120
31.46,96.76,0.120
31.48,96.87,0.120
31.50,96.98,0.120
31.53,97.08,0.120
31.55,97.19,0.120
31.57,97.30,0.120
31.59,97.41,0.120
31.61,97.52,0.120
31.63,97.63,0.120
31.66,97.74,0.120
31.68,97.84,0.120
31.70,97.95,0.120
31.72,98.06,0.120
31.74,98.17,0.120
31.76,98.28,0.120
31.78,98.39,0.120
31.81,98.49,0.120
31.83,98.60,0.120
31.85,98.71,0.120
31.87,98.82,0.120
31.89,98.93,0.120
31.92,99.04,0.120
31.94,99.15,
31.96,99.25,
31.98,,
31.98,,

[step]
Ramp 5.00 °C/min to -60.00 °C
Time,Temperature,Heat Flow (Normalized)
min,°C,W/g
32.98,100.13,-0.027
33.01,100.13,-0.028
33.03,100.12,-0.028
33.05,100.11,-0.028
33.07,100.08,-0.028
33.09,100.04,-0.028
33.12,99.98,-0.030
33.14,99.91,-0.044
33.16,99.83,-0.055
33.18,99.76,-0.069
33.20,99.67,-0.080
33.22,99.59,-0.091
33.24,99.50,-0.101
33.27,99.41,-0.111
33.29,99.31,-0.118
33.31,99.22,-0.125
33.33,99.12,-0.133
33.35,99.02,-0.138
33.38,98.92,-0.142
33.40,98.82,-0.147
33.42,98.72,-0.151
33.44,98.62,-0.154
33.46,98.52,-0.157
33.48,98.42,-0.160
33.51,98.31,-0.162
33.53,98.21,-0.164
33.55,98.10,-0.165
33.57,98.00,-0.167
33.59,97.89,-0.168
33.61,97.79,-0.169
33.63,97.68,-0.170
33.66,97.58,-0.171
33.68,97.47,-0.171
33.70,97.36,-0.172
33.72,97.26,-0.172
33.74,97.15,-0.173
33.77,97.04,-0.173
33.79,96.94,-0.173
33.81,96.83,-0.173
33.83,96.72,-0.174
33.85,96.61,-0.174
33.87,96.51,-0.174
33.89,96.40,-0.175
33.92,96.29,-0.175
33.94,96.18,-0.175
33.96,96.08,-0.175
33.98,95.97,-0.175
34.00,95.86,-0.175
34.03,95.75,-0.176
34.05,95.65,-0.176
34.07,95.54,-0.176
34.09,95.43,-0.176
34.11,95.32,-0.176
34.13,95.21,-0.176
34.16,95.11,-0.176
34.18,95.00,-0.176
34.20,94.89,-0.176
34.22,94.78,-0.176
34.24,94.67,-0.176
34.26,94.57,-0.176
34.29,94.46,-0.176
34.31,94.35,-0.176
34.33,94.24,-0.176
34.35,94.14,-0.176
34.37,94.03,-0.176
34.39,93.92,-0.176
34.41,93.81,-0.176
34.44,93.70,-0.176
34.46,93.59,-0.176
34.48,93.49,-0.176
34.50,93.38,-0.176
34.52,93.27,-0.176
34.54,93.16,-0.176
34.57,93.05,-0.176
34.59,92.94,-0.176
34.61,92.84,-0.176
34.63,92.73,-0.176
34.65,92.62,-0.176
34.68,92.51,-0.176
34.70,92.40,-0.175
34.72,92.29,-0.175
34.74,92.19,-0.175
34.76,92.08,-0.175
34.78,91.97,-0.175
34.81,91.86,-0.175
34.83,91.75,-0.175
34.85,91.65,-0.175
34.87,91.54,-0.175
34.89,91.43,-0.175
34.91,91.32,-0.175
34.94,91.21,-0.175
34.96,91.10,-0.174
34.98,91.00,-0.174
35.00,90.89,-0.174
35.02,90.78,-0.174
35.04,90.67,-0.174
35.06,90.56,-0.174
35.09,90.45,-0.174
35.11,90.35,-0.174
35.13,90.24,-0.174
35.15,90.13,-0.174
35.17,90.02,-0.173
35.19,89.91,-0.173
35.22,89.80,-0.173
35.24,89.70,-0.173
35.26,89.59,-0.173
35.28,89.48,-0.173
35.30,89.37,-0.173
35.33,89.26,-0.173
35.35,89.16,-0.173
35.37,89.05,-0.173
35.39,88.94,-0.173
35.41,88.83,-0.172
35.43,88.72,-0.172
35.46,88.61,-0.172
35.48,88.51,-0.172
35.50,88.40,-0.172
35.52,88.29,-0.172
35.54,88.18,-0.172
35.56,88.07,-0.172
35.59,87.96,-0.172
35.61,87.86,-0.171
35.63,87.75,-0.171
35.65,87.64,-0.171
35.67,87.53,-0.171
35.69,87.42,-0.171
35.71,87.31,-0.171
35.74,87.21,-0.171
35.76,87.10,-0.171
35.78,86.99,-0.171
35.80,86.88,-0.171
35.82,86.77,-0.171
35.84,86.66,-0.171
35.87,86.56,-0.171
35.89,86.45,-0.171
35.91,86.34,-0.170
35.93,86.23,-0.170
35.95,86.12,-0.170
35.98,86.02,-0.170
36.00,85.91,-0.170
36.02,85.80,-0.170
36.04,85.69,-0.170
36.06,85.58,-0.170
36.08,85.47,-0.170
36.11,85.36,-0.170
36.13,85.26,-0.170
36.15,85.15,-0.170
36.17,85.04,-0.170
36.19,84.93,-0.170
36.21,84.82,-0.169
36.24,84.72,-0.169
36.26,84.61,-0.169
36.28,84.50,-0.169
36.30,84.39,-0.169
36.32,84.28,-0.169
36.34,84.17,-0.169
36.36,84.06,-0.169
36.39,83.96,-0.169
36.41,83.85,-0.169
36.43,83.74,-0.169
36.45,83.63,-0.169
36.47,83.52,-0.169
36.49,83.41,-0.169
36.52,83.31,-0.169
36.54,83.20,-0.169
36.56,83.09,-0.169
36.58,82.98,-0.169
36.60,82.87,-0.169
36.63,82.77,-0.168
36.65,82.66,-0.168
36.67,82.55,-0.168
36.69,82.44,-0.168
36.71,82.33,-0.168
36.73,82.23,-0.168
36.76,82.12,-0.168
36.78,82.01,-0.168
36.80,81.90,-0.168
36.82,81.79,-0.168
36.84,81.68,-0.168
36.86,81.57,-0.168
36.89,81.47,-0.168
36.91,81.36,-0.168
36.93,81.25,-0.168
36.95,81.14,-0.168
36.97,81.03,-0.168
36.99,80.92,-0.167
37.01,80.82,-0.167
37.04,80.71,-0.167
37.06,80.60,-0.167
37.08,80.49,-0.167
37.10,80.38,-0.167
37.12,80.27,-0.167
37.14,80.17,-0.167
37.17,80.06,-0.167
37.19,79.95,-0.167
37.21,79.84,-0.167
37.23,79.73,-0.167
37.25,79.62,-0.167
37.28,79.52,-0.167
37.30,79.41,-0.167
37.32,79.30,-0.167
37.34,79.19,-0.166
37.36,79.08,-0.166
37.38,78.97,-0.166
37.41,78.87,-0.166
37.43,78.76,-0.166
37.45,78.65,-0.166
37.47,78.54,-0.166
37.49,78.43,-0.166
37.51,78.32,-0.166
37.54,78.22,-0.166
37.56,78.11,-0.166
37.58,78.00,-0.166
37.60,77.89,-0.166
37.62,77.78,-0.166
37.64,77.68,-0.166
37.66,77.57,-0.166
37.69,77.46,-0.166
37.71,77.35,-0.165
37.73,77.24,-0.165
37.75,77.13,-0.165
37.77,77.03,-0.165
37.79,76.92,-0.165
37.82,76.81,-0.165
37.84,76.70,-0.165
37.86,76.59,-0.165
37.88,76.48,-0.165
37.90,76.38,-0.165
37.93,76.27,-0.165
37.95,76.16,-0.165
37.97,76.05,-0.165
37.99,75.94,-0.165
38.01,75.83,-0.165
38.03,75.73,-0.164
38.06,75.62,-0.164
38.08,75.51,-0.164
38.10,75.40,-0.164
38.12,75.29,-0.164
38.14,75.18,-0.164
38.16,75.08,-0.164
38.19,74.97,-0.164
38.21,74.86,-0.164
38.23,74.75,-0.164
38.25,74.64,-0.164
38.27,74.54,-0.164
38.29,74.43,-0.164
38.31,74.32,-0.164
38.34,74.21,-0.164
38.36,74.10,-0.164
38.38,73.99,-0.164
38.40,73.89,-0.164
38.42,73.78,-0.164
38.44,73.67,-0.163
38.47,73.56,-0.163
38.49,73.45,-0.163
38.51,73.34,-0.163
38.53,73.23,-0.163
38.55,73.13,-0.163
38.58,73.02,-0.163
38.60,72.91,-0.163
38.62,72.80,-0.163
38.64,72.69,-0.163
38.66,72.58,-0.163
38.68,72.48,-0.163
38.71,72.37,-0.163
38.73,72.26,-0.163
38.75,72.15,-0.163
38.77,72.04,-0.163
38.79,71.94,-0.163
38.81,71.83,-0.163
38.84,71.72,-0.163
38.86,71.61,-0.163
38.88,71.50,-0.162
38.90,71.39,-0.162
38.92,71.29,-0.162
38.94,71.18,-0.162
38.96,71.07,-0.162
38.99,70.96,-0.162
39.01,70.85,-0.162
39.03,70.75,-0.162
39.05,70.64,-0.162
39.07,70.53,-0.162
39.09,70.42,-0.162
39.12,70.31,-0.162
39.14,70.20,-0.162
39.16,70.10,-0.162
39.18,69.99,-0.162
39.20,69.88,-0.162
39.23,69.77,-0.162
39.25,69.66,-0.162
39.27,69.55,-0.161
39.29,69.45,-0.161
39.31,69.34,-0.161
39.33,69.23,-0.161
39.36,69.12,-0.161
39.38,69.01,-0.161
39.40,68.90,-0.161
39.42,68.79,-0.161
39.44,68.69,-0.161
39.46,68.58,-0.161
39.49,68.47,-0.161
39.51,68.36,-0.161
39.53,68.25,-0.161
39.55,68.15,-0.161
39.57,68.04,-0.161
39.59,67.93,-0.161
39.61,67.82,-0.161
39.64,67.71,-0.161
39.66,67.60,-0.161
39.68,67.50,-0.161
39.70,67.39,-0.160
39.72,67.28,-0.160
39.74,67.17,-0.160
39.77,67.06,-0.160
39.79,66.95,-0.160
39.81,66.85,-0.160
39.83,66.74,-0.160
39.85,66.63,-0.160
39.88,66.52,-0.160
39.90,66.41,-0.160
39.92,66.30,-0.160
39.94,66.20,-0.160
39.96,66.09,-0.160
39.98,65.98,-0.160
40.01,65.87,-0.160
40.03,65.76,-0.160
40.05,65.65,-0.160
40.07,65.55,-0.160
40.09,65.44,-0.159
40.11,65.33,-0.159
40.14,65.22,-0.159
40.16,65.11,-0.159
40.18,65.00,-0.159
40.20,64.90,-0.159
40.22,64.79,-0.159
40.24,64.68,-0.159
40.26,64.57,-0.159
40.29,64.46,-0.159
40.31,64.36,-0.159
40.33,64.25,-0.159
40.35,64.14,-0.159
40.37,64.03,-0.159
40.39,63.92,-0.159
40.42,63.81,-0.159
40.44,63.70,-0.159
40.46,63.60,-0.159
40.48,63.49,-0.158
40.50,63.38,-0.158
40.53,63.27,-0.158
40.55,63.16,-0.158
40.57,63.05,-0.158
40.59,62.95,-0.158
40.61,62.84,-0.158
40.63,62.73,-0.158
40.66,62.62,-0.158
40.68,62.51,-0.158
40.70,62.41,-0.158
40.72,62.30,-0.158
40.74,62.19,-0.158
40.76,62.08,-0.158
40.79,61.97,-0.158
40.81,61.86,-0.158
40.83,61.76,-0.158
40.85,61.65,-0.158
40.87,61.54,-0.158
40.89,61.43,-0.158
40.91,61.32,-0.158
40.94,61.22,-0.157
40.96,61.11,-0.157
40.98,61.00,-0.157
41.00,60.89,-0.157
41.02,60.78,-0.157
41.04,60.67,-0.157
41.07,60.56,-0.157
41.09,60.46,-0.157
41.11,60.35,-0.157
41.13,60.24,-0.157
41.15,60.13,-0.157
[...]
136.16,-39.91,0.079
136.17,-39.85,0.079
136.19,-39.78,0.079
136.20,-39.71,0.079
136.21,-39.65,0.079
136.23,-39.58,0.079
136.24,-39.51,0.079
136.25,-39.45,0.079
136.27,-39.38,0.079
136.28,-39.31,0.079
136.29,-39.25,0.079
136.31,-39.18,0.079
136.32,-39.11,0.079
136.33,-39.05,0.079
136.35,-38.98,0.079
136.36,-38.91,0.079
136.37,-38.85,0.079
136.39,-38.78,0.079
136.40,-38.71,0.079
136.41,-38.64,0.080
136.43,-38.58,0.080
136.44,-38.51,0.080
136.45,-38.45,0.080
136.47,-38.38,0.080
136.48,-38.31,0.080
136.49,-38.25,0.080
136.51,-38.18,0.080
136.52,-38.11,0.080
136.53,-38.05,0.080
136.55,-37.98,0.080
136.56,-37.91,0.080
136.57,-37.85,0.080
136.59,-37.78,0.080
136.60,-37.71,0.080
136.61,-37.64,0.080
136.63,-37.58,0.080
136.64,-37.51,0.080
136.65,-37.45,0.080
136.67,-37.38,0.080
136.68,-37.31,0.080
136.69,-37.24,0.080
136.71,-37.18,0.080
136.72,-37.11,0.080
136.73,-37.04,0.080
136.75,-36.98,0.080
136.76,-36.91,0.080
136.77,-36.84,0.080
136.79,-36.78,0.080
136.80,-36.71,0.080
136.81,-36.64,0.080
136.83,-36.58,0.080
136.84,-36.51,0.080
136.85,-36.44,0.080
136.87,-36.38,0.080
136.88,-36.31,0.080
136.89,-36.24,0.080
136.91,-36.18,0.080
136.92,-36.11,0.080
136.93,-36.04,0.080
136.95,-35.98,0.080
136.96,-35.91,0.080
136.97,-35.84,0.080
136.99,-35.78,0.080
137.00,-35.71,0.080
137.01,-35.64,0.080
137.03,-35.58,0.080
137.04,-35.51,0.080
137.05,-35.44,0.080
137.07,-35.38,0.080
137.08,-35.31,0.080
137.09,-35.24,0.080
137.11,-35.18,0.080
137.12,-35.11,0.080
137.13,-35.04,0.080
137.15,-34.97,0.080
137.16,-34.91,0.080
137.17,-34.84,0.080
137.19,-34.77,0.080
137.20,-34.71,0.080
137.21,-34.64,0.080
137.23,-34.57,0.080
137.24,-34.51,0.080
137.25,-34.44,0.080
137.27,-34.37,0.080
137.28,-34.31,0.080
137.29,-34.24,0.080
137.31,-34.17,0.080
137.32,-34.11,0.080
137.33,-34.04,0.080
137.35,-33.97,0.080
137.36,-33.91,0.080
137.37,-33.84,0.080
137.39,-33.77,0.080
137.40,-33.71,0.080
137.41,-33.64,0.080
137.43,-33.57,0.080
137.44,-33.51,0.080
137.45,-33.44,0.080
137.47,-33.37,0.080
137.48,-33.31,0.080
137.49,-33.24,0.080
137.51,-33.17,0.080
137.52,-33.11,0.080
137.53,-33.04,0.080
137.55,-32.97,0.081
137.56,-32.90,0.081
137.57,-32.84,0.081
137.59,-32.77,0.081
137.60,-32.71,0.081
137.61,-32.64,0.081
137.63,-32.57,0.081
137.64,-32.51,0.081
137.65,-32.44,0.081
137.67,-32.37,0.081
137.68,-32.31,0.081
137.69,-32.24,0.081
137.71,-32.17,0.081
137.72,-32.11,0.081
137.73,-32.04,0.081
137.75,-31.97,0.081
137.76,-31.90,0.081
137.77,-31.84,0.081
137.79,-31.77,0.081
137.80,-31.70,0.081
137.81,-31.64,0.081
137.83,-31.57,0.081
137.84,-31.50,0.081
137.85,-31.44,0.081
137.87,-31.37,0.081
137.88,-31.30,0.081
137.89,-31.24,0.081
137.91,-31.17,0.081
137.92,-31.10,0.081
137.93,-31.04,0.081
137.95,-30.97,0.081
137.96,-30.90,0.081
137.97,-30.84,0.081
137.99,-30.77,0.081
138.00,-30.70,0.081
138.01,-30.64,0.081
138.03,-30.57,0.081
138.04,-30.50,0.081
138.05,-30.44,0.081
138.07,-30.37,0.081
138.08,-30.30,0.081
138.09,-30.24,0.081
138.11,-30.17,0.081
138.12,-30.10,0.081
138.13,-30.04,0.081
138.15,-29.97,0.081
138.16,-29.90,0.081
138.17,-29.84,0.081
138.19,-29.77,0.081
138.20,-29.70,0.081
138.21,-29.63,0.081
138.23,-29.57,0.081
138.24,-29.50,0.081
138.25,-29.44,0.081
138.27,-29.37,0.081
138.28,-29.30,0.081
138.29,-29.24,0.081
138.31,-29.17,0.081
138.32,-29.10,0.081
138.33,-29.04,0.081
138.35,-28.97,0.081
138.36,-28.90,0.081
138.37,-28.84,0.081
138.39,-28.77,0.081
138.40,-28.70,0.081
138.41,-28.63,0.081
138.43,-28.57,0.081
138.44,-28.50,0.081
138.45,-28.44,0.081
138.47,-28.37,0.081
138.48,-28.30,0.081
138.49,-28.23,0.081
138.51,-28.17,0.081
138.52,-28.10,0.081
138.53,-28.03,0.082
138.55,-27.97,0.082
138.56,-27.90,0.082
138.57,-27.83,0.082
138.59,-27.77,0.082
138.60,-27.70,0.082
138.61,-27.63,0.082
138.63,-27.57,0.082
138.64,-27.50,0.082
138.65,-27.43,0.082
138.67,-27.37,0.082
138.68,-27.30,0.082
138.69,-27.23,0.082
138.71,-27.17,0.082
138.72,-27.10,0.082
138.73,-27.03,0.082
138.75,-26.97,0.082
138.76,-26.90,0.082
138.77,-26.83,0.082
138.79,-26.77,0.082
138.80,-26.70,0.082
138.81,-26.63,0.082
138.83,-26.57,0.082
138.84,-26.50,0.082
138.85,-26.43,0.082
138.87,-26.37,0.082
138.88,-26.30,0.082
138.89,-26.23,0.082
138.91,-26.17,0.082
138.92,-26.10,0.082
138.93,-26.03,0.082
138.95,-25.96,0.082
138.96,-25.90,0.082
138.97,-25.83,0.082
138.99,-25.76,0.082
139.00,-25.70,0.082
139.01,-25.63,0.082
139.03,-25.56,0.082
139.04,-25.50,0.082
139.05,-25.43,0.082
139.07,-25.36,0.082
139.08,-25.30,0.082
139.09,-25.23,0.082
139.11,-25.17,0.082
139.12,-25.10,0.082
139.13,-25.03,0.082
139.15,-24.96,0.082
139.16,-24.90,0.082
139.17,-24.83,0.082
139.19,-24.76,0.082
139.20,-24.70,0.082
139.21,-24.63,0.082
139.23,-24.56,0.082
139.24,-24.50,0.082
139.25,-24.43,0.082
139.27,-24.36,0.082
139.28,-24.30,0.082
139.29,-24.23,0.082
139.31,-24.16,0.082
139.32,-24.10,0.082
139.33,-24.03,0.082
139.35,-23.96,0.082
139.36,-23.90,0.082
139.37,-23.83,0.082
139.39,-23.76,0.082
139.40,-23.70,0.083
139.41,-23.63,0.083
139.43,-23.56,0.083
139.44,-23.50,0.083
139.45,-23.43,0.083
139.47,-23.36,0.083
139.48,-23.30,0.083
139.49,-23.23,0.083
139.51,-23.16,0.083
139.52,-23.10,0.083
139.53,-23.03,0.083
139.55,-22.96,0.083
139.56,-22.90,0.083
139.57,-22.83,0.083
139.59,-22.76,0.083
139.60,-22.69,0.083
139.61,-22.63,0.083
139.63,-22.56,0.083
139.64,-22.50,0.083
139.65,-22.43,0.083
139.67,-22.36,0.083
139.68,-22.30,0.083
139.69,-22.23,0.083
139.71,-22.16,0.083
139.72,-22.10,0.083
139.73,-22.03,0.083
139.75,-21.96,0.083
139.76,-21.90,0.083
139.77,-21.83,0.083
139.79,-21.76,0.083
139.80,-21.70,0.083
139.81,-21.63,0.083
139.83,-21.56,0.083
139.84,-21.50,0.083
139.85,-21.43,0.083
139.87,-21.36,0.083
139.88,-21.29,0.083
139.89,-21.23,0.083
139.91,-21.16,0.083
139.92,-21.10,0.083
139.93,-21.03,0.083
139.95,-20.96,0.083
139.96,-20.90,0.083
139.97,-20.83,0.083
139.99,-20.76,0.083
140.00,-20.70,0.083
140.01,-20.63,0.083
140.03,-20.56,0.083
140.04,-20.49,0.083
140.05,-20.43,0.083
140.07,-20.36,0.083
140.08,-20.29,0.083
140.09,-20.23,0.083
140.11,-20.16,0.083
140.12,-20.09,0.084
140.13,-20.03,0.084
140.15,-19.96,0.084
140.16,-19.89,0.084
140.17,-19.83,0.084
140.19,-19.76,0.084
140.20,-19.69,0.084
140.21,-19.63,0.084
140.23,-19.56,0.084
140.24,-19.49,0.084
140.25,-19.43,0.084
140.27,-19.36,0.084
140.28,-19.29,0.084
140.29,-19.23,0.084
140.31,-19.16,0.084
140.32,-19.09,0.084
140.33,-19.03,0.084
140.35,-18.96,0.084
140.36,-18.89,0.084
140.37,-18.83,0.084
140.39,-18.76,0.084
140.40,-18.69,0.084
140.41,-18.63,0.084
140.43,-18.56,0.084
140.44,-18.49,0.084
140.45,-18.43,0.084
140.47,-18.36,0.084
140.48,-18.29,0.084
140.49,-18.23,0.084
140.51,-18.16,0.084
140.52,-18.09,0.084
140.53,-18.03,0.084
140.55,-17.96,0.084
140.56,-17.89,0.084
140.57,-17.83,0.084
140.59,-17.76,0.084
140.60,-17.69,0.084
140.61,-17.63,0.084
140.63,-17.56,0.084
140.64,-17.49,0.084
140.65,-17.42,0.084
140.67,-17.36,0.084
140.68,-17.29,0.084
140.69,-17.23,0.085
140.71,-17.16,0.085
140.72,-17.09,0.085
140.73,-17.03,0.085
140.75,-16.96,0.085
140.76,-16.89,0.085
140.77,-16.83,0.085
140.79,-16.76,0.085
140.80,-16.69,0.085
140.81,-16.63,0.085
140.83,-16.56,0.085
140.84,-16.49,0.085
140.85,-16.43,0.085
140.87,-16.36,0.085
140.88,-16.29,0.085
140.89,-16.22,0.085
140.91,-16.16,0.085
140.92,-16.09,0.085
140.93,-16.03,0.085
140.95,-15.96,0.085
140.96,-15.89,0.085
140.97,-15.83,0.085
140.99,-15.76,0.085
141.00,-15.69,0.085
141.01,-15.62,0.085
141.03,-15.56,0.085
141.04,-15.49,0.085
141.05,-15.42,0.085
141.07,-15.36,0.085
141.08,-15.29,0.085
141.09,-15.22,0.085
141.11,-15.16,0.085
141.12,-15.09,0.086
141.13,-15.02,0.086
141.15,-14.96,0.086
141.16,-14.89,0.086
141.17,-14.82,0.086
141.19,-14.76,0.086
141.20,-14.69,0.086
141.21,-14.62,0.086
141.23,-14.56,0.086
141.24,-14.49,0.086
141.25,-14.42,0.086
141.27,-14.36,0.086
141.28,-14.29,0.086
141.29,-14.22,0.086
141.31,-14.16,0.086
141.32,-14.09,0.086
141.33,-14.02,0.086
141.35,-13.96,0.086
141.36,-13.89,0.086
141.37,-13.82,0.086
141.39,-13.76,0.086
141.40,-13.69,0.086
141.41,-13.62,0.086
141.43,-13.55,0.086
141.44,-13.49,0.086
141.45,-13.42,0.086
141.47,-13.36,0.087
141.48,-13.29,0.087
141.49,-13.22,0.087
141.51,-13.16,0.087
141.52,-13.09,0.087
141.53,-13.02,0.087
141.55,-12.96,0.087
141.56,-12.89,0.087
141.57,-12.82,0.087
141.59,-12.76,0.087
141.60,-12.69,0.087
141.61,-12.62,0.087
141.63,-12.56,0.087
141.64,-12.49,0.087
141.65,-12.42,0.087
141.67,-12.36,0.087
141.68,-12.29,0.087
141.69,-12.22,0.087
141.71,-12.16,0.087
141.72,-12.09,0.087
141.73,-12.02,0.088
141.75,-11.96,0.088
141.76,-11.89,0.088
141.77,-11.82,0.088
141.79,-11.76,0.088
141.80,-11.69,0.088
141.81,-11.62,0.088
141.83,-11.56,0.088
141.84,-11.49,0.088
141.85,-11.42,0.088
141.87,-11.36,0.088
141.88,-11.29,0.088
141.89,-11.22,0.088
141.91,-11.16,0.088
141.92,-11.09,0.088
141.93,-11.02,0.088
141.95,-10.96,0.088
141.96,-10.89,0.089
141.97,-10.82,0.089
141.99,-10.76,0.089
142.00,-10.69,0.089
142.01,-10.62,0.089
142.03,-10.56,0.089
142.04,-10.49,0.089
142.05,-10.42,0.089
142.07,-10.36,0.089
142.08,-10.29,0.089
142.09,-10.22,0.089
142.11,-10.15,0.089
142.12,-10.09,0.089
142.13,-10.02,0.089
142.15,-9.96,0.090
142.16,-9.89,0.090
142.17,-9.82,0.090
142.19,-9.76,0.090
142.20,-9.69,0.090
142.21,-9.62,0.090
142.23,-9.56,0.090
142.24,-9.49,0.090
142.25,-9.42,0.090
142.27,-9.36,0.090
142.28,-9.29,0.090
142.29,-9.22,0.091
142.31,-9.16,0.091
142.32,-9.09,0.091
142.33,-9.02,0.091
142.35,-8.96,0.091
142.36,-8.89,0.091
142.37,-8.82,0.091
142.39,-8.76,0.091
142.40,-8.69,0.091
142.41,-8.62,0.091
142.43,-8.56,0.091
142.44,-8.49,0.092
142.45,-8.42,0.092
142.47,-8.36,0.092
142.48,-8.29,0.092
142.49,-8.22,0.092
142.51,-8.16,0.092
142.52,-8.09,0.092
142.53,-8.02,0.092
142.55,-7.96,0.092
142.56,-7.89,0.092
142.57,-7.82,0.093
142.59,-7.76,0.093
142.60,-7.69,0.093
142.61,-7.62,0.093
142.63,-7.56,0.093
142.64,-7.49,0.093
142.65,-7.42,0.093
142.67,-7.36,0.093
142.68,-7.29,0.093
142.69,-7.22,0.094
142.71,-7.16,0.094
142.72,-7.09,0.094
142.73,-7.02,0.094
142.75,-6.96,0.094
142.76,-6.89,0.094
142.77,-6.82,0.094
142.79,-6.76,0.094
142.80,-6.69,0.095
142.81,-6.62,0.095
142.83,-6.56,0.095
142.84,-6.49,0.095
142.85,-6.42,0.095
142.87,-6.36,0.095
142.88,-6.29,0.095
142.89,-6.22,0.095
142.91,-6.16,0.095
142.92,-6.09,0.096
142.93,-6.03,0.096
142.95,-5.96,0.096
142.96,-5.89,0.096
142.97,-5.82,0.096
142.99,-5.76,0.096
143.00,-5.69,0.096
143.01,-5.62,0.097
143.03,-5.56,0.097
143.04,-5.49,0.097
143.05,-5.43,0.097
143.07,-5.36,0.097
143.08,-5.29,0.097
143.09,-5.22,0.097
143.11,-5.16,0.097
143.12,-5.09,0.098
143.13,-5.02,0.098
143.15,-4.96,0.098
143.16,-4.89,0.098
143.17,-4.83,0.098
143.19,-4.76,0.098
143.20,-4.69,0.098
143.21,-4.63,0.099
143.23,-4.56,0.099
143.24,-4.49,0.099
143.25,-4.43,0.099
143.27,-4.36,0.099
143.28,-4.29,0.099
143.29,-4.23,0.099
143.31,-4.16,0.099
143.32,-4.09,0.100
143.33,-4.03,0.100
143.35,-3.96,0.100
143.36,-3.89,0.100
143.37,-3.83,0.100
143.39,-3.76,0.100
143.40,-3.69,0.100
143.41,-3.63,0.100
143.43,-3.56,0.101
143.44,-3.49,0.101
143.45,-3.43,0.101
143.47,-3.36,0.101
143.48,-3.29,0.101
143.49,-3.23,0.101
143.51,-3.16,0.101
143.52,-3.09,0.101
143.53,-3.03,0.101
143.55,-2.96,0.102
143.56,-2.89,0.102
143.57,-2.83,0.102
143.59,-2.76,0.102
143.60,-2.69,0.102
143.61,-2.63,0.102
143.63,-2.56,0.102
143.64,-2.49,0.102
143.65,-2.43,0.102
143.67,-2.36,0.102
143.68,-2.29,0.102
143.69,-2.23,0.102
143.71,-2.16,0.103
143.72,-2.09,0.103
143.73,-2.02,0.103
143.75,-1.96,0.103
143.76,-1.89,0.103
143.77,-1.82,0.103
143.79,-1.76,0.103
143.80,-1.69,0.103
143.81,-1.62,0.103
143.83,-1.56,0.103
143.84,-1.49,0.103
143.85,-1.42,0.103
143.87,-1.36,0.103
143.88,-1.29,0.103
143.89,-1.23,0.103
143.91,-1.16,0.103
143.92,-1.09,0.103
143.93,-1.02,0.103
143.95,-0.96,0.103
143.96,-0.89,0.103
143.97,-0.83,0.103
143.99,-0.76,0.103
144.00,-0.69,0.103
144.01,-0.62,0.103
144.03,-0.56,0.104
144.04,-0.49,0.104
144.05,-0.43,0.104
144.07,-0.36,0.104
144.08,-0.29,0.104
144.09,-0.22,0.104
144.11,-0.16,0.104
144.12,-0.09,0.104
144.13,-0.02,0.104
144.15,0.04,0.104
144.16,0.11,0.104
144.17,0.18,0.104
144.19,0.24,0.104
144.20,0.31,0.104
144.21,0.38,0.104
144.23,0.44,0.104
144.24,0.51,0.104
144.25,0.58,0.104
144.27,0.64,0.103
144.28,0.71,0.103
144.29,0.78,0.103
144.31,0.84,0.103
144.32,0.91,0.103
144.33,0.98,0.103
144.35,1.04,0.103
144.36,1.11,0.103
144.37,1.18,0.103
144.39,1.24,0.103
144.40,1.31,0.103
144.41,1.38,0.103
144.43,1.45,0.103
144.44,1.51,0.103
144.45,1.58,0.103
144.47,1.64,0.103
144.48,1.71,0.103
144.49,1.78,0.103
144.51,1.85,0.103
144.52,1.91,0.103
144.53,1.98,0.103
144.55,2.05,0.103
144.56,2.11,0.103
144.57,2.18,0.103
144.59,2.25,0.103
144.60,2.31,0.103
144.61,2.38,0.103
144.63,2.45,0.103
144.64,2.52,0.103
144.65,2.58,0.103
144.67,2.65,0.103
144.68,2.72,0.103
144.69,2.79,0.103
144.71,2.85,0.103
144.72,2.92,0.103
144.73,2.99,0.103
144.75,3.05,0.103
144.76,3.12,0.103
144.77,3.19,0.103
144.79,3.25,0.103
144.80,3.32,0.103
144.81,3.39,0.103
144.83,3.45,0.103
144.84,3.52,0.103
144.85,3.59,0.103
144.87,3.65,0.103
144.88,3.72,0.103
144.89,3.79,0.103
144.91,3.85,0.103
144.92,3.92,0.103
144.93,3.99,0.103
144.95,4.05,0.103
144.96,4.12,0.103
144.97,4.19,0.103
144.99,4.25,0.103
145.00,4.32,0.103
145.01,4.39,0.103
145.03,4.45,0.103
145.04,4.52,0.103
145.05,4.59,0.103
145.07,4.65,0.103
145.08,4.72,0.103
145.09,4.79,0.103
145.11,4.85,0.103
145.12,4.92,0.103
145.13,4.99,0.103
145.15,5.05,0.103
145.16,5.12,0.103
145.17,5.19,0.103
145.19,5.25,0.103
145.20,5.32,0.103
145.21,5.39,0.103
145.23,5.45,0.103
145.24,5.52,0.103
145.25,5.59,0.103
145.27,5.65,0.103
145.28,5.72,0.103
145.29,5.79,0.103
145.31,5.85,0.103
145.32,5.92,0.103
145.33,5.99,0.103
145.35,6.05,0.103
145.36,6.12,0.103
145.37,6.18,0.103
145.39,6.25,0.103
145.40,6.32,0.103
145.41,6.39,0.103
145.43,6.45,0.103
145.44,6.52,0.103
145.45,6.59,0.103
145.47,6.65,0.103
145.48,6.72,0.103
145.49,6.78,0.103
145.51,6.85,0.103
145.52,6.92,0.103
145.53,6.99,0.103
145.55,7.05,0.103
145.56,7.12,0.103
145.57,7.19,0.103
145.59,7.25,0.103
145.60,7.32,0.103
145.61,7.39,0.103
145.63,7.45,0.103
145.64,7.52,0.103
145.65,7.59,0.103
145.67,7.65,0.103
145.68,7.72,0.103
145.69,7.79,0.103
145.71,7.85,0.103
145.72,7.92,0.103
145.73,7.99,0.103
145.75,8.05,0.103
145.76,8.12,0.103
145.77,8.19,0.103
145.79,8.25,0.103
145.80,8.32,0.103
145.81,8.39,0.103
145.83,8.45,0.103
145.84,8.52,0.103
145.85,8.59,0.103
145.87,8.65,0.103
145.88,8.72,0.103
145.89,8.79,0.103
145.91,8.85,0.103
145.92,8.92,0.103
145.93,8.99,0.103
145.95,9.05,0.103
145.96,9.12,0.103
145.97,9.19,0.103
145.99,9.25,0.103
146.00,9.32,0.103
146.01,9.39,0.103
146.03,9.45,0.103
146.04,9.52,0.103
146.05,9.59,0.103
146.07,9.65,0.103
146.08,9.72,0.103
146.09,9.79,0.103
146.11,9.85,0.104
146.12,9.92,0.104
146.13,9.99,0.104
146.15,10.05,0.104
146.16,10.12,0.104
146.17,10.19,0.104
146.19,10.25,0.104
146.20,10.32,0.104
146.21,10.39,0.104
146.23,10.45,0.104
146.24,10.52,0.104
146.25,10.59,0.104
146.27,10.66,0.104
146.28,10.72,0.104
146.29,10.79,0.104
146.31,10.85,0.104
146.32,10.92,0.104
146.33,10.99,0.104
146.35,11.05,0.104
146.36,11.12,0.104
146.37,11.19,0.104
146.39,11.26,0.104
146.40,11.32,0.104
146.41,11.39,0.104
146.43,11.46,0.104
146.44,11.52,0.104
146.45,11.59,0.104
146.47,11.65,0.104
146.48,11.72,0.104
146.49,11.79,0.104
146.51,11.85,0.104
146.52,11.92,0.104
146.53,11.99,0.104
146.55,12.06,0.104
146.56,12.12,0.104
146.57,12.19,0.104
146.59,12.26,0.104
146.60,12.32,0.104
146.61,12.39,0.104
146.63,12.45,0.104
146.64,12.52,0.104
146.65,12.59,0.104
146.67,12.66,0.104
146.68,12.72,0.104
146.69,12.79,0.104
146.71,12.86,0.104
146.72,12.92,0.104
146.73,12.99,0.104
146.75,13.06,0.104
146.76,13.12,0.104
146.77,13.19,0.104
146.79,13.26,0.104
146.80,13.32,0.104
146.81,13.39,0.104
146.83,13.46,0.104
146.84,13.52,0.104
146.85,13.59,0.104
146.87,13.66,0.104
146.88,13.72,0.104
146.89,13.79,0.104
146.91,13.86,0.105
146.92,13.92,0.105
146.93,13.99,0.105
146.95,14.06,0.105
146.96,14.12,0.105
146.97,14.19,0.105
146.99,14.26,0.105
147.00,14.32,0.105
147.01,14.39,0.105
147.03,14.46,0.105
147.04,14.52,0.105
147.05,14.59,0.105
147.07,14.66,0.105
147.08,14.72,0.105
147.09,14.79,0.105
147.11,14.86,0.105
147.12,14.92,0.105
147.13,14.99,0.105
147.15,15.06,0.105
147.16,15.12,0.105
147.17,15.19,0.105
147.19,15.26,0.105
147.20,15.32,0.105
147.21,15.39,0.105
147.23,15.46,0.105
147.24,15.53,0.105
147.25,15.59,0.105
147.27,15.66,0.105
147.28,15.72,0.105
147.29,15.79,0.105
147.31,15.86,0.105
147.32,15.92,0.105
147.33,15.99,0.105
147.35,16.06,0.105
147.36,16.13,0.105
147.37,16.19,0.105
147.39,16.26,0.105
147.40,16.32,0.105
147.41,16.39,0.105
147.43,16.46,0.105
147.44,16.53,0.105
147.45,16.59,0.105
147.47,16.66,0.105
147.48,16.73,0.105
147.49,16.79,0.105
147.51,16.86,0.105
147.52,16.92,0.105
147.53,16.99,0.105
147.55,17.06,0.105
147.56,17.13,0.105
147.57,17.19,0.105
147.59,17.26,0.105
147.60,17.33,0.105
147.61,17.39,0.105
147.63,17.46,0.105
147.64,17.53,0.105
147.65,17.59,0.105
147.67,17.66,0.106
147.68,17.73,0.106
147.69,17.79,0.106
147.71,17.86,0.106
147.72,17.93,0.106
147.73,17.99,0.106
147.75,18.06,0.106
147.76,18.13,0.106
147.77,18.19,0.106
147.79,18.26,0.106
147.80,18.33,0.106
147.81,18.39,0.106
147.83,18.46,0.106
147.84,18.53,0.106
147.85,18.59,0.106
147.87,18.66,0.106
147.88,18.73,0.106
147.89,18.79,0.106
147.91,18.86,0.106
147.92,18.92,0.106
147.93,18.99,0.106
147.95,19.06,0.106
147.96,19.13,0.106
147.97,19.19,0.106
147.99,19.26,0.106
148.00,19.33,0.106
148.01,19.39,0.106
148.03,19.46,0.106
148.04,19.53,0.106
148.05,19.59,0.106
148.07,19.66,0.106
148.08,19.73,0.106
148.09,19.79,0.106
148.11,19.86,0.106
148.12,19.93,0.106
148.13,19.99,0.106
148.15,20.06,0.106
148.16,20.13,0.106
148.17,20.19,0.106
148.19,20.26,0.106
148.20,20.33,0.106
148.21,20.39,0.106
148.23,20.46,0.106
148.24,20.53,0.106
148.25,20.60,0.106
148.27,20.66,0.106
148.28,20.73,0.106
148.29,20.79,0.106
148.31,20.86,0.106
148.32,20.93,0.106
148.33,20.99,0.106
148.35,21.06,0.106
148.36,21.13,0.106
148.37,21.20,0.106
148.39,21.26,0.106
148.40,21.33,0.106
148.41,21.39,0.106
148.43,21.46,0.106
148.44,21.53,0.107
148.45,21.60,0.107
148.47,21.66,0.107
148.48,21.73,0.107
148.49,21.80,0.107
148.51,21.86,0.107
148.52,21.93,0.107
148.53,21.99,0.107
148.55,22.06,0.107
148.56,22.13,0.107
148.57,22.20,0.107
148.59,22.26,0.107
148.60,22.33,0.107
148.61,22.40,0.107
148.63,22.46,0.107
148.64,22.53,0.107
148.65,22.60,0.107
148.67,22.66,0.107
148.68,22.73,0.107
148.69,22.80,0.107
148.71,22.86,0.107
148.72,22.93,0.107
148.73,23.00,0.107
148.75,23.06,0.107
148.76,23.13,0.107
148.77,23.20,0.107
148.79,23.26,0.107
148.80,23.33,0.107
148.81,23.40,0.107
148.83,23.46,0.107
148.84,23.53,0.107
148.85,23.60,0.107
148.87,23.66,0.107
148.88,23.73,0.107
148.89,23.80,0.107
148.91,23.86,0.107
148.92,23.93,0.107
148.93,24.00,0.107
148.95,24.06,0.107
148.96,24.13,0.107
148.97,24.20,0.107
148.99,24.26,0.107
149.00,24.33,0.107
149.01,24.40,0.107
149.03,24.46,0.107
149.04,24.53,0.107
149.05,24.60,0.107
149.07,24.66,0.107
149.08,24.73,0.107
149.09,24.80,0.107
149.11,24.86,0.107
149.12,24.93,0.107
149.13,25.00,0.108
149.15,25.06,0.108
149.16,25.13,0.108
149.17,25.20,0.108
149.19,25.26,0.108
149.20,25.33,0.108
149.21,25.40,0.108
149.23,25.46,0.108
149.24,25.53,0.108
149.25,25.60,0.108
149.27,25.66,0.108
149.28,25.73,0.108
149.29,25.80,0.108
149.31,25.87,0.108
149.32,25.93,0.108
149.33,26.00,0.108
149.35,26.06,0.108
149.36,26.13,0.108
149.37,26.20,0.108
149.39,26.27,0.108
149.40,26.33,0.108
149.41,26.40,0.108
149.43,26.46,0.108
149.44,26.53,0.108
149.45,26.60,0.108
149.47,26.67,0.108
149.48,26.73,0.108
149.49,26.80,0.108
149.51,26.87,0.108
149.52,26.93,0.108
149.53,27.00,0.108
149.55,27.07,0.108
149.56,27.13,0.108
149.57,27.20,0.108
149.59,27.27,0.108
149.60,27.33,0.108
149.61,27.40,0.108
149.63,27.47,0.108
149.64,27.53,0.108
149.65,27.60,0.108
149.67,27.67,0.108
149.68,27.73,0.108
149.69,27.80,0.108
149.71,27.87,0.108
149.72,27.93,0.108
149.73,28.00,0.108
149.75,28.07,0.108
149.76,28.13,0.108
149.77,28.20,0.108
149.79,28.27,0.109
149.80,28.33,0.109
149.81,28.40,0.109
149.83,28.47,0.109
149.84,28.53,0.109
149.85,28.60,0.109
149.87,28.67,0.109
149.88,28.73,0.109
149.89,28.80,0.109
149.91,28.87,0.109
149.92,28.93,0.109
149.93,29.00,
149.95,29.07,
149.96,29.13,
149.97,29.20,
149.98,,