File: 2025_05_01_THC_IsonicotinicAcid_Slurry_n60C_170C_5Cmin_x3.csv
Filename,2025_05_01_THC_IsonicotinicAcid_Slurry_n60C_170C_5Cmin_x3
Instrument name,DSC2A-00468 (192.168.1.100)
Operator,Yarger
rundate,5/1/2025
Sample name,2025_05_01_THC_IsonicotinicAcid_Slurry_n60C_170C_5Cmin_x3
proceduresegments,Data Off ; Equilibrate -60.00 °C; Data On ; Ramp 5.00 °C/min to 170.00 °C; Data Off ; Isothermal 1.0 min; Data On ; Ramp 5.00 °C/min to -60.00 °C; Data Off ; Isothermal 1.0 min; Data On ; Ramp 5.00 °C/min to 170.00 °C; Data Off ; Isothermal 1.0 min; Data On ; Ramp 5.00 °C/min to -60.00 °C; Data Off ; Isothermal 1.0 min; Data On ; Ramp 5.00 °C/min to 170.00 °C
[File Parameters]
Run date,5/1/2025 2:26:57 AM
Trios version,5.1.1.46572
Original File Name,
Current File Name,D:\DSC2500\JYarger\2025_05_01_THC_IsonicotinicAcid_Slurry_n60C_170C_5Cmin_x3.tri
[Procedure]
Procedure Name,THC_INA_n60C_170C_5Cmin_x3
Sample Name,2025_05_01_THC_IsonicotinicAcid_Slurry_n60C_170C_5Cmin_x3
Sample Mass,8.51 mg
Reference Sample Mass,0 mg
Pan Mass,54.25 mg
Pan Number,14
Reference Pan Mass,53.35 mg
Reference Pan Number,1
Pan Type,Tzero Aluminum Hermetic
Comments,Al Hermetic DSC Consumables sealed Pan/Lid. Y2 Tray (Google Sheet: DSC_Samples_Vext_Y2_Tray_May2025)
Project Name,CA
Operator,Yarger
Test,Custom
Unload Max Temperature,30
Unload Min Temperature,30
Load Max Temperature,30
Load Min Temperature,30
Stop on Gas Flow Error,Yes
[Signal List]
Signal #1,Time (min)
Signal #2,Temperature (°C)
Signal #3,Heat Flow (mW)
Signal #4,Delta T (µV)
Signal #5,Delta Tzero (µV)
Signal #6,Tzero Temperature (°C)
Signal #7,Cell Purge (mL/min)
Signal #8,Heater Temp (°C)
Signal #9,Power Delivered (W)
Signal #10,Reference Junction Temperature (°C)
Signal #11,Flange Temperature (°C)
Signal #12,Heat Flow Phase (rad)
Signal #13,Total Heat Capacity (J/°C)
Signal #14,Heat Capacity (J/°C)
[Configuration]
Company Name,ASU
Instrument Name,DSC2A-00468
Instrument Type,DSC2500
Serial Number,DSC2A-00468
IP,192.168.1.100
Location of Instrument,MRRC
DisplayType,Unknown
Sample Interval ,0.1 s/pt
Selected Heat Flow,T4P
Exotherm Direction,Down
Cell Serial,DRC2-00792
Lid Type,Standard
Cooler,RCS 90
Leave Cooler on at End of Sequence,On
Gas 2,Nitrogen
Gas Selected,Channel 1
Flow Rate,50 mL/min
Secondary Purge,On
Licensed Heat Flow,Heat Flow T4P
Modulation Licensed,Yes
[Versions]
Common IDD Version,1
Cortex Version,VER 2.10.2.31
Driver,5.0.0.6
GDM Version,1.0.3.3
TouchscreenVersion,1.0.0.16145
FEP Version,1.2.1.21
FEP Bootloader,2.0.0.5
AutoSampler Version,2.1.1.26
Auto Sampler Bootloader,2.0.0.5
FCM Version,1.1.0.3
FCM Bootloader,2.0.0.5
[Experiment Logs]
Experiment Log Entry # 1,Data On set to 0
Experiment Log Entry # 3,Equilibrate Segment -60 (C) Started
Experiment Log Entry # 5,Air Cool is off.
Experiment Log Entry # 7,Data On set to 1
Experiment Log Entry # 9,Ramp Segment 5 C/min to 170 Started
Experiment Log Entry # 11,Data On set to 0
Experiment Log Entry # 13,Isothermal Segment 1 min started
Experiment Log Entry # 15,Data On set to 1
Experiment Log Entry # 17,Ramp Segment 5 C/min to -60 Started
Experiment Log Entry # 19,Data On set to 0
Experiment Log Entry # 21,Isothermal Segment 1 min started
Experiment Log Entry # 23,Data On set to 1
Experiment Log Entry # 25,Ramp Segment 5 C/min to 170 Started
Experiment Log Entry # 27,Data On set to 0
Experiment Log Entry # 29,Isothermal Segment 1 min started
Experiment Log Entry # 31,Data On set to 1
Experiment Log Entry # 33,Ramp Segment 5 C/min to -60 Started
Experiment Log Entry # 35,Data On set to 0
Experiment Log Entry # 37,Isothermal Segment 1 min started
Experiment Log Entry # 39,Data On set to 1
Experiment Log Entry # 41,Ramp Segment 5 C/min to 170 Started
[Method Log]
Method Log Entry # 1,Data Off
Method Log Entry # 2,Equilibrate -60 °C
Method Log Entry # 3,Data On
Method Log Entry # 4,(Ramp 122831) Ramp 5 °C/minute to 170 °C
Method Log Entry # 5,Data Off
Method Log Entry # 6,Isothermal 1 minutes
Method Log Entry # 7,Data On
Method Log Entry # 8,(Ramp 122835) Ramp 5 °C/minute to -60 °C
Method Log Entry # 9,Data Off
Method Log Entry # 10,Isothermal 1 minutes
Method Log Entry # 11,Data On
Method Log Entry # 12,(Ramp 122839) Ramp 5 °C/minute to 170 °C
Method Log Entry # 13,Data Off
Method Log Entry # 14,Isothermal 1 minutes
Method Log Entry # 15,Data On
Method Log Entry # 16,(Ramp 122843) Ramp 5 °C/minute to -60 °C
Method Log Entry # 17,Data Off
Method Log Entry # 18,Isothermal 1 minutes
Method Log Entry # 19,Data On
Method Log Entry # 20,(Ramp 122847) Ramp 5 °C/minute to 170 °C
Cell Serial,DRC2-00792
[T1 Calibration]
Slope,-0.008529666
Offset,9.636258
Initial Temperature,98.23
GUID,f8bfdadc-4977-4fdf-ba6d-0ba9134940c3
[TZero Calibration]
Date Applied,11/29/2022 4:06:13 PM
Description,From -89.059 °C to 396.009 °C at 20.000°C/min
Gas Type,Nitrogen
Pan Type,None
Source Files 1,C:\Users\yargerlab\Desktop\DSC Data\General\TZero_calibration_11_29_22_2nd(2).tri
Source Files 2,C:\Users\yargerlab\Desktop\DSC Data\General\TZero_calibration_11_29_22_2nd(3).tri
Delta T Offset,13.05235
Delta T Slope,-0.007271007
Delta T0 Offset,-13.69128
Delta T0 Slope,0.06063341
[Temperature Calibration]
Date Applied,11/29/2022 7:12:28 PM
Description,From 106.590 °C to 186.590 °C at 10.000°C/min
Gas Type,Nitrogen
Pan Type,Tzero Aluminum Hermetic
Source Files 1,C:\Users\yargerlab\Desktop\DSC Data\General\Indium(6).tri
Measured 1,157.391
Known 1,156.598
[Cell Constant Calibration]
Date Applied,11/29/2022 7:12:29 PM
Description,From 106.590 °C to 186.590 °C at 10.000°C/min
Gas Type,Nitrogen
Pan Type,Tzero Aluminum Hermetic
Source Files 1,C:\Users\yargerlab\Desktop\DSC Data\General\Indium(6).tri
T4P KCell,1.006051
Onset Slope,63.26126 mW/°C
[Direct Cp Calibration]
Date Applied,11/30/2022 11:04:51 AM
Description,From -79.983 °C to 298.409 °C at 10.000°C/min
Gas Type,Nitrogen
Pan Type,Tzero Aluminum Hermetic
Source Files 1,C:\Users\yargerlab\Desktop\DSC Data\General\Sapphire_Heat_Capacity_11_30_22.tri
[Rev Cp Calibration]
Date Applied,11/30/2022 1:58:51 PM
Description,From -79.996 °C to 292.812 °C at 3.000°C/min
Gas Type,Nitrogen
Pan Type,Tzero Aluminum Hermetic
Source Files 1,C:\Users\yargerlab\Desktop\DSC Data\General\Sapphire_MDSC_Calibration_11_30_22.tri
[step]
Ramp 5.00 °C/min to 170.00 °C
Time,Temperature,Heat Flow (Normalized)
min,°C,W/g
0.00,-59.66,-0.051
0.03,-59.68,-0.050
0.06,-59.68,-0.044
0.09,-59.64,-0.043
0.13,-59.57,-0.041
0.16,-59.47,-0.027
0.19,-59.36,-0.011
0.22,-59.25,0.006
0.25,-59.12,0.019
0.29,-58.99,0.030
0.32,-58.86,0.038
0.35,-58.72,0.045
0.38,-58.58,0.051
0.41,-58.43,0.056
0.44,-58.29,0.060
0.48,-58.14,0.063
0.51,-57.99,0.066
0.54,-57.84,0.067
0.57,-57.69,0.069
0.60,-57.54,0.070
0.63,-57.39,0.071
0.67,-57.23,0.072
0.70,-57.08,0.073
0.73,-56.93,0.073
0.76,-56.77,0.074
0.79,-56.62,0.074
0.82,-56.46,0.075
0.85,-56.30,0.075
0.89,-56.15,0.075
0.92,-55.99,0.076
0.95,-55.84,0.076
0.98,-55.68,0.076
1.01,-55.53,0.077
1.05,-55.37,0.077
1.08,-55.21,0.077
1.11,-55.06,0.077
1.14,-54.90,0.077
1.17,-54.74,0.078
1.20,-54.59,0.078
1.23,-54.43,0.078
1.27,-54.27,0.078
1.30,-54.11,0.078
1.33,-53.96,0.078
1.36,-53.80,0.078
1.39,-53.64,0.078
1.43,-53.48,0.078
1.46,-53.33,0.079
1.49,-53.17,0.079
1.52,-53.01,0.079
1.55,-52.85,0.079
1.58,-52.70,0.079
1.62,-52.54,0.079
1.65,-52.38,0.079
1.68,-52.22,0.079
1.71,-52.06,0.079
1.74,-51.91,0.079
1.77,-51.75,0.079
1.81,-51.59,0.079
1.84,-51.43,0.079
1.87,-51.27,0.079
1.90,-51.12,0.079
1.93,-50.96,0.079
1.96,-50.80,0.079
1.99,-50.64,0.079
2.03,-50.49,0.079
2.06,-50.33,0.079
2.09,-50.17,0.079
2.12,-50.01,0.079
2.15,-49.85,0.079
2.19,-49.70,0.079
2.22,-49.54,0.079
2.25,-49.38,0.079
2.28,-49.22,0.079
2.31,-49.06,0.079
2.34,-48.91,0.079
2.38,-48.75,0.079
2.41,-48.59,0.079
2.44,-48.43,0.079
2.47,-48.27,0.079
2.50,-48.11,0.079
2.53,-47.96,0.079
2.56,-47.80,0.079
2.60,-47.64,0.079
2.63,-47.48,0.079
2.66,-47.32,0.079
2.69,-47.17,0.079
2.72,-47.01,0.079
2.76,-46.85,0.080
2.79,-46.69,0.080
2.82,-46.53,0.080
2.85,-46.38,0.080
2.88,-46.22,0.080
2.91,-46.06,0.080
2.94,-45.90,0.080
2.98,-45.74,0.080
3.01,-45.58,0.080
3.04,-45.43,0.080
3.07,-45.27,0.080
3.10,-45.11,0.080
3.14,-44.95,0.080
3.17,-44.79,0.080
3.20,-44.64,0.080
3.23,-44.48,0.080
3.26,-44.32,0.080
3.29,-44.16,0.080
3.33,-44.00,0.080
3.36,-43.84,0.080
3.39,-43.69,0.080
3.42,-43.53,0.080
3.45,-43.37,0.080
3.48,-43.21,0.080
3.51,-43.05,0.080
3.55,-42.89,0.080
3.58,-42.74,0.080
3.61,-42.58,0.080
3.64,-42.42,0.080
3.67,-42.26,0.080
3.71,-42.10,0.080
3.74,-41.94,0.080
3.77,-41.79,0.080
3.80,-41.63,0.080
3.83,-41.47,0.080
3.86,-41.31,0.080
3.89,-41.15,0.080
3.93,-40.99,0.080
3.96,-40.84,0.080
3.99,-40.68,0.080
4.02,-40.52,0.080
4.05,-40.36,0.080
4.09,-40.20,0.080
4.12,-40.04,0.080
4.15,-39.88,0.080
4.18,-39.73,0.080
4.21,-39.57,0.080
4.24,-39.41,0.080
4.28,-39.25,0.080
4.31,-39.09,0.080
4.34,-38.93,0.080
4.37,-38.77,0.081
4.40,-38.62,0.081
4.43,-38.46,0.081
4.46,-38.30,0.081
4.50,-38.14,0.081
4.53,-37.98,0.081
4.56,-37.82,0.081
4.59,-37.67,0.081
4.62,-37.51,0.081
4.65,-37.35,0.081
4.69,-37.19,0.081
4.72,-37.03,0.081
4.75,-36.87,0.081
4.78,-36.71,0.081
4.81,-36.55,0.081
4.85,-36.40,0.081
4.88,-36.24,0.081
4.91,-36.08,0.081
4.94,-35.92,0.081
4.97,-35.76,0.081
5.00,-35.60,0.081
5.04,-35.45,0.081
5.07,-35.29,0.081
5.10,-35.13,0.081
5.13,-34.97,0.081
5.16,-34.81,0.081
5.19,-34.66,0.081
5.23,-34.50,0.081
5.26,-34.34,0.081
5.29,-34.18,0.082
5.32,-34.02,0.082
5.35,-33.86,0.082
5.38,-33.70,0.082
5.41,-33.54,0.082
5.45,-33.39,0.082
5.48,-33.23,0.082
5.51,-33.07,0.082
5.54,-32.91,0.082
5.57,-32.75,0.082
5.60,-32.59,0.082
5.64,-32.44,0.082
5.67,-32.28,0.082
5.70,-32.12,0.082
5.73,-31.96,0.082
5.76,-31.80,0.083
5.80,-31.64,0.083
5.83,-31.48,0.083
5.86,-31.32,0.083
5.89,-31.17,0.083
5.92,-31.01,0.083
5.95,-30.85,0.083
5.99,-30.69,0.083
6.02,-30.53,0.083
6.05,-30.38,0.083
6.08,-30.22,0.083
6.11,-30.06,0.083
6.14,-29.90,0.083
6.18,-29.74,0.084
6.21,-29.58,0.084
6.24,-29.43,0.084
6.27,-29.27,0.084
6.30,-29.11,0.084
6.33,-28.95,0.084
6.36,-28.79,0.084
6.40,-28.63,0.084
6.43,-28.47,0.084
6.46,-28.32,0.084
6.49,-28.16,0.085
6.52,-28.00,0.085
6.55,-27.84,0.085
6.59,-27.68,0.085
6.62,-27.52,0.085
6.65,-27.37,0.085
6.68,-27.21,0.085
6.71,-27.05,0.086
6.75,-26.89,0.086
6.78,-26.73,0.086
6.81,-26.58,0.086
6.84,-26.42,0.086
6.87,-26.26,0.086
6.90,-26.10,0.087
6.94,-25.94,0.087
6.97,-25.78,0.087
7.00,-25.62,0.087
7.03,-25.47,0.087
7.06,-25.31,0.087
7.09,-25.15,0.088
7.13,-24.99,0.088
7.16,-24.83,0.088
7.19,-24.67,0.088
7.22,-24.52,0.089
7.25,-24.36,0.089
7.28,-24.20,0.089
7.31,-24.04,0.089
7.35,-23.88,0.090
7.38,-23.72,0.090
7.41,-23.57,0.090
7.44,-23.41,0.090
7.47,-23.25,0.091
7.50,-23.09,0.091
7.54,-22.93,0.091
7.57,-22.77,0.091
7.60,-22.62,0.092
7.63,-22.46,0.092
7.66,-22.30,0.092
7.70,-22.14,0.093
7.73,-21.98,0.093
7.76,-21.83,0.093
7.79,-21.67,0.093
7.82,-21.51,0.094
7.85,-21.35,0.094
7.89,-21.19,0.094
7.92,-21.03,0.095
7.95,-20.88,0.095
7.98,-20.72,0.095
8.01,-20.56,0.096
8.04,-20.40,0.096
8.08,-20.24,0.096
8.11,-20.08,0.096
8.14,-19.93,0.097
8.17,-19.77,0.097
8.20,-19.61,0.097
8.23,-19.45,0.098
8.26,-19.29,0.098
8.30,-19.14,0.098
8.33,-18.98,0.098
8.36,-18.82,0.099
8.39,-18.66,0.099
8.42,-18.50,0.099
8.45,-18.34,0.099
8.49,-18.19,0.099
8.52,-18.03,0.100
8.55,-17.87,0.100
8.58,-17.71,0.100
8.61,-17.55,0.100
8.65,-17.39,0.100
8.68,-17.23,0.101
8.71,-17.08,0.101
8.74,-16.92,0.101
8.77,-16.76,0.101
8.80,-16.60,0.101
8.83,-16.44,0.101
8.87,-16.28,0.101
8.90,-16.12,0.101
8.93,-15.97,0.101
8.96,-15.81,0.101
8.99,-15.65,0.101
9.03,-15.49,0.101
9.06,-15.33,0.101
9.09,-15.17,0.101
9.12,-15.01,0.101
9.15,-14.86,0.101
9.18,-14.70,0.101
9.22,-14.54,0.102
9.25,-14.38,0.101
9.28,-14.22,0.101
9.31,-14.07,0.101
9.34,-13.91,0.101
9.37,-13.75,0.101
9.40,-13.59,0.101
9.44,-13.43,0.101
9.47,-13.27,0.101
9.50,-13.11,0.101
9.53,-12.96,0.101
9.56,-12.80,0.101
9.60,-12.64,0.101
9.63,-12.48,0.101
9.66,-12.32,0.101
9.69,-12.16,0.101
9.72,-12.01,0.101
9.75,-11.85,0.101
9.78,-11.69,0.101
9.82,-11.53,0.101
9.85,-11.37,0.101
9.88,-11.21,0.101
9.91,-11.05,0.101
9.94,-10.90,0.101
9.98,-10.74,0.101
10.01,-10.58,0.101
10.04,-10.42,0.101
10.07,-10.26,0.102
10.10,-10.10,0.102
10.13,-9.95,0.102
10.17,-9.79,0.102
10.20,-9.63,0.102
10.23,-9.47,0.102
10.26,-9.31,0.102
10.29,-9.15,0.102
10.32,-8.99,0.102
10.35,-8.84,0.102
10.39,-8.68,0.102
10.42,-8.52,0.102
10.45,-8.36,0.102
10.48,-8.20,0.102
10.51,-8.04,0.102
10.55,-7.89,0.102
10.58,-7.73,0.102
10.61,-7.57,0.102
10.64,-7.41,0.102
10.67,-7.25,0.102
10.70,-7.09,0.102
10.73,-6.94,0.102
10.77,-6.78,0.102
10.80,-6.62,0.102
10.83,-6.46,0.102
10.86,-6.30,0.102
10.89,-6.14,0.102
10.93,-5.98,0.102
10.96,-5.83,0.102
10.99,-5.67,0.102
11.02,-5.51,0.102
11.05,-5.35,0.103
11.08,-5.19,0.103
11.12,-5.03,0.103
11.15,-4.87,0.103
11.18,-4.72,0.103
11.21,-4.56,0.103
11.24,-4.40,0.103
11.27,-4.24,0.103
11.30,-4.08,0.103
11.34,-3.92,0.103
11.37,-3.77,0.103
11.40,-3.61,0.103
11.43,-3.45,0.103
11.46,-3.29,0.103
11.50,-3.13,0.103
11.53,-2.97,0.103
11.56,-2.81,0.103
11.59,-2.66,0.103
11.62,-2.50,0.103
11.65,-2.34,0.103
11.68,-2.18,0.103
11.72,-2.02,0.103
11.75,-1.86,0.103
11.78,-1.70,0.103
11.81,-1.55,0.103
11.84,-1.39,0.103
11.88,-1.23,0.103
11.91,-1.07,0.103
11.94,-0.91,0.104
11.97,-0.75,0.104
12.00,-0.59,0.104
12.03,-0.44,0.104
12.07,-0.28,0.104
12.10,-0.12,0.104
12.13,0.04,0.104
12.16,0.20,0.104
12.19,0.35,0.104
12.22,0.51,0.104
12.25,0.67,0.104
12.29,0.83,0.104
12.32,0.99,0.104
12.35,1.15,0.104
12.38,1.31,0.104
12.41,1.46,0.104
12.45,1.62,0.104
12.48,1.78,0.104
12.51,1.94,0.104
12.54,2.10,0.104
12.57,2.26,0.104
12.60,2.41,0.104
12.63,2.57,0.104
12.67,2.73,0.104
12.70,2.89,0.104
12.73,3.05,0.104
12.76,3.21,0.104
12.79,3.37,0.104
12.83,3.52,0.104
12.86,3.68,0.104
12.89,3.84,0.104
12.92,4.00,0.104
12.95,4.16,0.104
12.98,4.32,0.105
13.02,4.48,0.105
13.05,4.63,0.105
13.08,4.79,0.105
13.11,4.95,0.105
13.14,5.11,0.105
13.17,5.27,0.105
13.20,5.43,0.105
13.24,5.58,0.105
13.27,5.74,0.105
13.30,5.90,0.105
13.33,6.06,0.105
13.36,6.22,0.105
13.40,6.37,0.105
13.43,6.53,0.105
13.46,6.69,0.105
13.49,6.85,0.105
13.52,7.01,0.105
13.55,7.17,0.105
13.58,7.33,0.105
13.62,7.49,0.105
13.65,7.64,0.105
13.68,7.80,0.105
13.71,7.96,0.105
13.74,8.12,0.106
13.78,8.28,0.106
13.81,8.43,0.106
13.84,8.59,0.106
13.87,8.75,0.106
13.90,8.91,0.106
13.93,9.07,0.106
13.97,9.23,0.106
14.00,9.39,0.106
14.03,9.54,0.106
14.06,9.70,0.106
14.09,9.86,0.106
14.12,10.02,0.106
14.15,10.18,0.106
14.19,10.34,0.106
14.22,10.50,0.106
14.25,10.65,0.106
14.28,10.81,0.106
14.31,10.97,0.106
14.35,11.13,0.106
14.38,11.29,0.106
14.41,11.45,0.106
14.44,11.60,0.106
14.47,11.76,0.107
14.50,11.92,0.107
14.53,12.08,0.107
14.57,12.24,0.107
14.60,12.40,0.107
14.63,12.56,0.107
14.66,12.71,0.107
14.69,12.87,0.107
14.73,13.03,0.107
14.76,13.19,0.107
14.79,13.35,0.107
14.82,13.51,0.107
14.85,13.67,0.107
14.88,13.82,0.107
14.92,13.98,0.107
14.95,14.14,0.107
14.98,14.30,0.107
15.01,14.46,0.107
15.04,14.62,0.107
15.07,14.77,0.107
15.10,14.93,0.108
15.14,15.09,0.108
15.17,15.25,0.108
15.20,15.41,0.108
15.23,15.57,0.108
15.26,15.72,0.108
15.30,15.88,0.108
15.33,16.04,0.108
15.36,16.20,0.108
15.39,16.36,0.108
15.42,16.52,0.108
15.45,16.67,0.108
15.48,16.83,0.108
15.52,16.99,0.108
15.55,17.15,0.108
15.58,17.31,0.108
15.61,17.47,0.108
15.64,17.62,0.108
15.68,17.78,0.108
15.71,17.94,0.108
15.74,18.10,0.108
15.77,18.26,0.108
15.80,18.42,0.108
15.83,18.58,0.108
15.87,18.73,0.109
15.90,18.89,0.109
15.93,19.05,0.109
15.96,19.21,0.109
15.99,19.37,0.109
16.02,19.53,0.109
16.05,19.68,0.109
16.09,19.84,0.109
16.12,20.00,0.109
16.15,20.16,0.109
16.18,20.32,0.109
16.21,20.48,0.109
16.25,20.63,0.109
16.28,20.79,0.109
16.31,20.95,0.109
16.34,21.11,0.109
16.37,21.27,0.109
16.40,21.43,0.109
16.43,21.58,0.109
16.47,21.75,0.109
16.50,21.90,0.109
16.53,22.06,0.110
16.56,22.22,0.110
16.59,22.38,0.110
16.63,22.54,0.110
16.66,22.70,0.110
16.69,22.85,0.110
16.72,23.01,0.110
16.75,23.17,0.110
16.78,23.33,0.110
16.82,23.49,0.110
16.85,23.65,0.110
16.88,23.80,0.110
16.91,23.96,0.110
16.94,24.12,0.110
16.97,24.28,0.110
17.00,24.44,0.110
17.04,24.60,0.110
17.07,24.75,0.110
17.10,24.91,0.111
17.13,25.07,0.111
17.16,25.23,0.111
17.19,25.39,0.111
17.23,25.55,0.111
17.26,25.71,0.111
17.29,25.86,0.111
17.32,26.02,0.111
17.35,26.18,0.111
17.38,26.34,0.111
17.42,26.50,0.111
17.45,26.65,0.111
17.48,26.81,0.111
17.51,26.97,0.111
17.54,27.13,0.111
17.58,27.29,0.111
17.61,27.45,0.111
17.64,27.61,0.111
17.67,27.76,0.111
17.70,27.92,0.112
17.73,28.08,0.112
17.77,28.24,0.112
17.80,28.40,0.112
17.83,28.56,0.112
17.86,28.72,0.112
17.89,28.87,0.112
17.92,29.03,0.112
17.96,29.19,0.112
17.99,29.35,0.112
18.02,29.51,0.112
18.05,29.67,0.112
18.08,29.82,0.112
18.11,29.98,0.112
18.14,30.14,0.112
18.18,30.30,0.112
18.21,30.46,0.112
18.24,30.62,0.112
18.27,30.77,0.112
18.30,30.93,0.112
18.33,31.09,0.112
18.37,31.25,0.113
18.40,31.41,0.113
18.43,31.57,0.113
18.46,31.73,0.113
18.49,31.88,0.113
18.53,32.04,0.113
18.56,32.20,0.113
18.59,32.36,0.113
18.62,32.51,0.113
18.65,32.67,0.113
18.68,32.83,0.113
18.72,32.99,0.113
18.75,33.15,0.113
18.78,33.31,0.113
18.81,33.47,0.113
18.84,33.62,0.113
18.87,33.78,0.113
18.91,33.94,0.113
18.94,34.10,0.113
18.97,34.26,0.113
19.00,34.42,0.113
19.03,34.58,0.113
19.06,34.73,0.114
19.09,34.89,0.114
19.13,35.05,0.114
19.16,35.21,0.114
19.19,35.37,0.114
19.22,35.53,0.114
19.25,35.69,0.114
19.28,35.84,0.114
19.32,36.00,0.114
19.35,36.16,0.114
19.38,36.32,0.114
19.41,36.48,0.114
19.44,36.64,0.114
19.48,36.80,0.114
19.51,36.95,0.114
19.54,37.11,0.114
19.57,37.27,0.114
19.60,37.43,0.114
19.63,37.59,0.114
19.67,37.74,0.114
19.70,37.90,0.114
19.73,38.06,0.114
19.76,38.22,0.114
19.79,38.38,0.114
19.82,38.54,0.115
19.86,38.70,0.115
19.89,38.85,0.115
19.92,39.01,0.115
19.95,39.17,0.115
19.98,39.33,0.115
20.01,39.49,0.115
20.04,39.65,0.115
20.08,39.81,0.115
20.11,39.96,0.115
20.14,40.12,0.115
20.17,40.28,0.115
20.20,40.44,0.115
20.23,40.60,0.115
20.27,40.76,0.115
20.30,40.91,0.115
20.33,41.07,0.115
20.36,41.23,0.115
20.39,41.39,0.116
20.43,41.55,0.116
20.46,41.71,0.116
20.49,41.87,0.116
20.52,42.02,0.116
20.55,42.18,0.116
20.58,42.34,0.116
20.62,42.50,0.116
20.65,42.66,0.116
20.68,42.82,0.116
20.71,42.97,0.116
20.74,43.13,0.116
20.77,43.29,0.116
20.81,43.45,0.116
20.84,43.61,0.116
20.87,43.77,0.116
20.90,43.93,0.116
20.93,44.08,0.116
20.96,44.24,0.116
20.99,44.40,0.116
21.03,44.56,0.117
21.06,44.72,0.117
21.09,44.88,0.117
21.12,45.03,0.117
21.15,45.19,0.117
21.18,45.35,0.117
21.22,45.51,0.117
21.25,45.67,0.117
21.28,45.82,0.117
21.31,45.98,0.117
21.34,46.14,0.117
21.38,46.30,0.117
21.41,46.46,0.117
21.44,46.62,0.117
21.47,46.78,0.117
21.50,46.93,0.117
21.53,47.09,0.117
21.57,47.25,0.117
21.60,47.41,0.117
21.63,47.57,0.117
21.66,47.73,0.117
21.69,47.88,0.117
21.72,48.04,0.118
21.76,48.20,0.118
21.79,48.36,0.118
21.82,48.52,0.118
21.85,48.68,0.118
21.88,48.84,0.118
21.91,48.99,0.118
21.94,49.15,0.118
21.98,49.31,0.118
22.01,49.47,0.118
22.04,49.63,0.118
22.07,49.79,0.118
22.10,49.95,0.118
22.13,50.10,0.118
22.17,50.26,0.118
22.20,50.42,0.118
22.23,50.58,0.118
22.26,50.74,0.118
22.29,50.89,0.118
22.33,51.05,0.118
22.36,51.21,0.119
22.39,51.37,0.119
22.42,51.53,0.119
22.45,51.69,0.119
22.48,51.85,0.119
22.52,52.00,0.119
22.55,52.16,0.119
22.58,52.32,0.119
22.61,52.48,0.119
22.64,52.64,0.119
22.67,52.80,0.119
22.71,52.95,0.119
22.74,53.11,0.119
22.77,53.27,0.119
22.80,53.43,0.119
22.83,53.59,0.119
22.86,53.75,0.119
22.89,53.91,0.120
22.93,54.06,0.120
22.96,54.22,0.120
22.99,54.38,0.120
23.02,54.54,0.120
23.05,54.70,0.120
23.08,54.86,0.120
23.12,55.01,0.120
23.15,55.17,0.120
23.18,55.33,0.120
23.21,55.49,0.120
23.24,55.65,0.120
23.28,55.81,0.120
23.31,55.97,0.120
23.34,56.12,0.120
23.37,56.28,0.120
23.40,56.44,0.120
23.43,56.60,0.120
23.47,56.76,0.120
23.50,56.92,0.120
23.53,57.08,0.120
23.56,57.23,0.120
23.59,57.39,0.120
23.62,57.55,0.121
23.66,57.71,0.121
23.69,57.87,0.121
23.72,58.03,0.121
23.75,58.18,0.121
23.78,58.34,0.121
23.81,58.50,0.121
23.84,58.66,0.121
23.88,58.82,0.121
23.91,58.98,0.121
23.94,59.13,0.121
23.97,59.29,0.121
24.00,59.45,0.121
24.03,59.61,0.121
24.07,59.77,0.121
24.10,59.93,0.121
24.13,60.08,0.121
24.16,60.24,0.121
24.19,60.40,0.121
24.23,60.56,0.121
24.26,60.72,0.121
24.29,60.88,0.121
24.32,61.04,0.121
24.35,61.19,0.121
24.38,61.35,0.121
24.42,61.51,0.121
24.45,61.67,0.121
24.48,61.83,0.121
24.51,61.99,0.121
24.54,62.14,0.121
24.57,62.30,0.122
24.61,62.46,0.122
24.64,62.62,0.122
24.67,62.78,0.122
24.70,62.94,0.122
24.73,63.09,0.122
24.76,63.25,0.122
24.79,63.41,0.122
24.83,63.57,0.122
24.86,63.73,0.122
24.89,63.88,0.122
24.92,64.04,0.122
24.95,64.20,0.122
24.98,64.36,0.122
25.02,64.52,0.122
25.05,64.68,0.122
25.08,64.84,0.122
25.11,64.99,0.122
25.14,65.15,0.122
25.18,65.31,0.122
25.21,65.47,0.122
25.24,65.63,0.122
25.27,65.79,0.122
25.30,65.94,0.122
25.33,66.10,0.123
25.37,66.26,0.123
25.40,66.42,0.123
25.43,66.58,0.123
25.46,66.74,0.123
25.49,66.90,0.123
25.52,67.05,0.123
25.56,67.21,0.123
25.59,67.37,0.123
25.62,67.53,0.123
25.65,67.69,0.123
25.68,67.85,0.123
25.71,68.00,0.123
25.74,68.16,0.123
25.78,68.32,0.123
25.81,68.48,0.123
25.84,68.64,0.123
25.87,68.80,0.123
25.90,68.96,0.123
25.93,69.11,0.123
25.97,69.27,0.123
26.00,69.43,0.123
26.03,69.59,0.123
26.06,69.75,0.123
26.09,69.91,0.123
26.13,70.06,0.123
26.16,70.22,0.123
26.19,70.38,0.123
26.22,70.54,0.123
26.25,70.70,0.123
26.28,70.86,0.123
26.32,71.01,0.123
26.35,71.17,0.123
26.38,71.33,0.124
26.41,71.49,0.124
26.44,71.65,0.124
26.47,71.81,0.124
26.51,71.97,0.124
26.54,72.12,0.124
26.57,72.28,0.124
26.60,72.44,0.124
26.63,72.60,0.124
26.66,72.76,0.124
26.69,72.92,0.124
26.73,73.07,0.124
26.76,73.23,0.124
26.79,73.39,0.124
26.82,73.55,0.124
26.85,73.71,0.124
26.88,73.86,0.124
26.92,74.02,0.124
26.95,74.18,0.124
26.98,74.34,0.124
27.01,74.50,0.124
27.04,74.66,0.124
27.08,74.82,0.124
27.11,74.97,0.124
27.14,75.13,0.124
27.17,75.29,0.124
27.20,75.45,0.124
27.23,75.61,0.124
27.27,75.77,0.124
27.30,75.93,0.124
27.33,76.08,0.124
27.36,76.24,0.124
27.39,76.40,0.124
27.42,76.56,0.124
27.46,76.72,0.124
27.49,76.88,0.125
27.52,77.03,0.125
27.55,77.19,0.125
27.58,77.35,0.125
27.61,77.51,0.125
27.64,77.67,0.125
27.68,77.83,0.125
27.71,77.99,0.125
27.74,78.14,0.125
27.77,78.30,0.125
27.80,78.46,0.125
27.83,78.62,0.125
27.87,78.78,0.125
27.90,78.94,0.125
27.93,79.09,0.125
27.96,79.25,0.125
27.99,79.41,0.125
28.03,79.57,0.125
28.06,79.73,0.125
28.09,79.89,0.125
28.12,80.05,0.125
28.15,80.20,0.125
28.18,80.36,0.125
28.22,80.52,0.125
28.25,80.68,0.125
28.28,80.84,0.125
28.31,81.00,0.125
28.34,81.15,0.125
28.37,81.31,0.125
28.41,81.47,0.125
28.44,81.63,0.125
28.47,81.79,0.125
28.50,81.95,0.125
28.53,82.10,0.125
28.56,82.26,0.125
28.59,82.42,0.125
28.63,82.58,0.125
28.66,82.74,0.125
28.69,82.90,0.125
28.72,83.06,0.125
28.75,83.21,0.125
28.78,83.37,0.125
28.82,83.53,0.125
28.85,83.69,0.125
28.88,83.85,0.125
28.91,84.01,0.125
28.94,84.16,0.125
28.98,84.32,0.125
29.01,84.48,0.125
29.04,84.64,0.125
29.07,84.80,0.125
29.10,84.96,0.125
29.13,85.11,0.125
29.17,85.27,0.125
29.20,85.43,0.125
29.23,85.59,0.125
29.26,85.75,0.125
29.29,85.91,0.125
29.32,86.06,0.125
29.36,86.22,0.125
29.39,86.38,0.125
29.42,86.54,0.125
29.45,86.70,0.125
29.48,86.86,0.125
29.51,87.02,0.125
29.54,87.17,0.125
29.58,87.33,0.125
29.61,87.49,0.125
29.64,87.65,0.125
29.67,87.81,0.125
29.70,87.97,0.125
29.73,88.13,0.125
29.77,88.28,0.125
29.80,88.44,0.125
29.83,88.60,0.125
29.86,88.76,0.125
29.89,88.92,0.125
29.93,89.07,0.125
29.96,89.23,0.125
29.99,89.39,0.124
30.02,89.55,0.124
30.05,89.71,0.124
30.08,89.87,0.124
30.12,90.02,0.125
30.15,90.18,0.125
30.18,90.34,0.125
30.21,90.50,0.125
30.24,90.66,0.125
30.27,90.82,0.125
30.31,90.98,0.125
30.34,91.14,0.125
30.37,91.29,0.125
30.40,91.45,0.125
30.43,91.61,0.125
30.46,91.77,0.125
30.49,91.93,0.124
30.53,92.08,0.124
30.56,92.24,0.124
30.59,92.40,0.124
30.62,92.56,0.124
30.65,92.72,0.124
30.68,92.88,0.124
30.72,93.04,0.124
30.75,93.19,0.124
30.78,93.35,0.124
30.81,93.51,0.124
30.84,93.67,0.124
30.88,93.83,0.124
30.91,93.99,0.124
30.94,94.15,0.124
30.97,94.30,0.124
31.00,94.46,0.124
31.03,94.62,0.124
31.07,94.78,0.124
31.10,94.93,0.124
31.13,95.09,0.124
31.16,95.25,0.124
31.19,95.41,0.124
31.22,95.57,0.124
31.26,95.73,0.124
31.29,95.89,0.124
31.32,96.04,0.124
31.35,96.20,0.124
31.38,96.36,0.124
31.41,96.52,0.124
31.44,96.68,0.124
31.48,96.84,0.124
31.51,97.00,0.124
31.54,97.15,0.124
31.57,97.31,0.124
31.60,97.47,0.124
31.63,97.63,0.124
31.67,97.79,0.124
31.70,97.95,0.124
31.73,98.11,0.124
31.76,98.26,0.124
31.79,98.42,0.124
31.83,98.58,0.124
31.86,98.74,0.124
31.89,98.90,0.124
31.92,99.06,0.124
31.95,99.22,0.124
31.98,99.38,0.124
32.02,99.53,0.124
32.05,99.69,0.124
32.08,99.85,0.124
32.11,100.01,0.124
32.14,100.17,0.124
32.17,100.33,0.124
32.21,100.49,0.123
32.24,100.64,0.123
32.27,100.80,0.123
32.30,100.96,0.123
32.33,101.12,0.123
32.36,101.28,0.123
32.39,101.43,0.123
32.43,101.59,0.123
32.46,101.75,0.123
32.49,101.91,0.123
32.52,102.07,0.123
32.55,102.23,0.123
32.58,102.38,0.122
32.62,102.54,0.122
32.65,102.70,0.122
32.68,102.86,0.122
32.71,103.02,0.122
32.74,103.18,0.122
32.78,103.34,0.122
32.81,103.49,0.122
32.84,103.65,0.122
32.87,103.81,0.122
32.90,103.97,0.122
32.93,104.13,0.122
32.97,104.29,0.122
33.00,104.44,0.122
33.03,104.60,0.122
33.06,104.76,0.122
33.09,104.92,0.122
33.12,105.08,0.121
33.16,105.24,0.121
33.19,105.39,0.121
33.22,105.55,0.121
33.25,105.71,0.121
33.28,105.87,0.121
33.31,106.03,0.121
33.34,106.19,0.121
33.38,106.35,0.121
33.41,106.50,0.121
33.44,106.66,0.121
33.47,106.82,0.121
33.50,106.98,0.121
33.53,107.14,0.121
33.57,107.30,0.121
33.60,107.45,0.121
33.63,107.61,0.121
33.66,107.77,0.120
33.69,107.93,0.120
33.73,108.09,0.120
33.76,108.25,0.120
33.79,108.40,0.120
33.82,108.56,0.120
33.85,108.72,0.120
33.88,108.88,0.120
33.92,109.04,0.120
33.95,109.20,0.120
33.98,109.36,0.120
34.01,109.51,0.120
34.04,109.67,0.120
34.07,109.83,0.120
34.11,109.99,0.120
34.14,110.15,0.119
34.17,110.31,0.119
34.20,110.46,0.119
34.23,110.62,0.119
34.26,110.78,0.119
34.29,110.94,0.119
34.33,111.10,0.119
34.36,111.26,0.119
34.39,111.42,0.119
34.42,111.57,0.119
34.45,111.73,0.119
34.49,111.89,0.119
34.52,112.05,0.118
34.55,112.21,0.118
34.58,112.37,0.118
34.61,112.53,0.118
34.64,112.68,0.118
34.68,112.84,0.118
34.71,113.00,0.118
34.74,113.16,0.118
34.77,113.32,0.118
34.80,113.48,0.118
34.83,113.63,0.118
34.86,113.79,0.118
34.90,113.95,0.118
34.93,114.11,0.118
34.96,114.27,0.117
34.99,114.43,0.117
35.02,114.59,0.117
35.06,114.74,0.117
35.09,114.90,0.117
35.12,115.06,0.117
35.15,115.22,0.117
35.18,115.38,0.117
35.21,115.54,0.117
35.24,115.69,0.117
35.28,115.85,0.117
35.31,116.01,0.117
35.34,116.17,0.117
35.37,116.33,0.117
35.40,116.49,0.117
35.44,116.64,0.116
35.47,116.80,0.116
35.50,116.96,0.116
35.53,117.12,0.116
35.56,117.28,0.116
35.59,117.44,0.116
35.63,117.59,0.116
35.66,117.75,0.116
35.69,117.91,0.116
35.72,118.07,0.116
35.75,118.23,0.116
35.78,118.39,0.116
35.81,118.55,0.116
35.85,118.70,0.116
35.88,118.86,0.116
35.91,119.02,0.116
35.94,119.18,0.116
35.97,119.34,0.116
36.01,119.50,0.116
36.04,119.66,0.116
36.07,119.81,0.116
36.10,119.97,0.116
36.13,120.13,0.116
36.16,120.29,0.116
36.19,120.45,0.116
36.23,120.61,0.116
36.26,120.76,0.116
36.29,120.92,0.116
36.32,121.08,0.116
36.35,121.24,0.116
36.39,121.40,0.116
36.42,121.55,0.116
36.45,121.71,0.116
36.48,121.87,0.115
36.51,122.03,0.115
36.54,122.19,0.115
36.58,122.35,0.115
36.61,122.51,0.115
36.64,122.66,0.115
36.67,122.82,0.115
36.70,122.98,0.115
36.73,123.14,0.116
36.76,123.30,0.116
36.80,123.46,0.116
36.83,123.61,0.116
36.86,123.77,0.116
36.89,123.93,0.116
36.92,124.09,0.116
36.96,124.25,0.116
36.99,124.41,0.116
37.02,124.57,0.116
37.05,124.72,0.116
37.08,124.88,0.116
37.11,125.04,0.116
37.14,125.20,0.116
37.18,125.36,0.116
37.21,125.52,0.116
37.24,125.68,0.116
37.27,125.83,0.116
37.30,125.99,0.116
37.34,126.15,0.116
37.37,126.31,0.116
37.40,126.47,0.116
37.43,126.62,0.117
37.46,126.78,0.117
37.49,126.94,0.117
37.53,127.10,0.117
37.56,127.26,0.117
37.59,127.41,0.117
37.62,127.57,0.117
37.65,127.73,0.117
37.68,127.89,0.117
37.71,128.05,0.117
37.75,128.21,0.118
37.78,128.36,0.118
37.81,128.52,0.118
37.84,128.68,0.118
37.87,128.84,0.118
37.91,129.00,0.118
37.94,129.16,0.119
37.97,129.31,0.119
38.00,129.47,0.119
38.03,129.63,0.119
38.06,129.79,0.119
38.09,129.95,0.120
38.13,130.11,0.120
38.16,130.26,0.120
38.19,130.42,0.120
38.22,130.58,0.120
38.25,130.74,0.120
38.29,130.90,0.121
38.32,131.06,0.121
38.35,131.21,0.121
38.38,131.37,0.121
38.41,131.53,0.121
38.44,131.69,0.121
38.48,131.85,0.122
38.51,132.01,0.122
38.54,132.16,0.122
38.57,132.32,0.122
38.60,132.48,0.122
38.63,132.64,0.123
38.66,132.80,0.123
38.70,132.96,0.123
38.73,133.12,0.123
38.76,133.27,0.123
38.79,133.43,0.124
38.82,133.59,0.124
38.86,133.75,0.124
38.89,133.91,0.124
38.92,134.06,0.124
38.95,134.22,0.124
38.98,134.38,0.125
39.01,134.54,0.125
39.04,134.70,0.125
39.08,134.86,0.125
39.11,135.01,0.125
39.14,135.17,0.126
39.17,135.33,0.126
39.20,135.49,0.126
39.24,135.65,0.126
39.27,135.81,0.126
39.30,135.96,0.126
39.33,136.12,0.127
39.36,136.28,0.127
39.39,136.44,0.127
39.43,136.60,0.127
39.46,136.76,0.127
39.49,136.91,0.127
39.52,137.07,0.128
39.55,137.23,0.128
39.58,137.39,0.128
39.61,137.55,0.128
39.65,137.71,0.128
39.68,137.86,0.128
39.71,138.02,0.129
39.74,138.18,0.129
39.77,138.34,0.129
39.81,138.50,0.129
39.84,138.66,0.129
39.87,138.81,0.129
39.90,138.97,0.129
39.93,139.13,0.129
39.96,139.29,0.130
39.99,139.45,0.130
40.03,139.61,0.130
40.06,139.76,0.130
40.09,139.92,0.130
40.12,140.08,0.130
40.15,140.24,0.130
40.19,140.40,0.130
40.22,140.56,0.130
40.25,140.71,0.130
40.28,140.87,0.131
40.31,141.03,0.131
40.34,141.19,0.131
40.38,141.35,0.131
40.41,141.51,0.131
40.44,141.66,0.131
40.47,141.82,0.131
40.50,141.98,0.131
40.53,142.14,0.131
40.56,142.30,0.131
40.60,142.45,0.132
40.63,142.61,0.132
40.66,142.77,0.132
40.69,142.93,0.132
40.72,143.09,0.132
40.76,143.25,0.132
40.79,143.41,0.132
40.82,143.56,0.132
40.85,143.72,0.132
40.88,143.88,0.132
40.91,144.04,0.132
40.94,144.20,0.132
40.98,144.35,0.133
41.01,144.51,0.133
41.04,144.67,0.133
41.07,144.83,0.133
41.10,144.99,0.133
41.14,145.15,0.133
41.17,145.31,0.133
41.20,145.46,0.133
41.23,145.62,0.133
41.26,145.78,0.133
41.29,145.94,0.133
41.33,146.10,0.133
41.36,146.26,0.133
41.39,146.41,0.133
41.42,146.57,0.133
41.45,146.73,0.133
41.48,146.89,0.133
41.51,147.05,0.134
41.55,147.20,0.134
41.58,147.36,0.134
41.61,147.52,0.134
41.64,147.68,0.134
41.67,147.84,0.134
41.71,148.00,0.134
41.74,148.16,0.134
41.77,148.32,0.134
41.80,148.47,0.134
41.83,148.63,0.134
41.86,148.79,0.134
41.89,148.95,0.134
41.93,149.11,0.134
41.96,149.26,0.134
41.99,149.42,0.134
42.02,149.58,0.134
42.05,149.74,0.134
42.09,149.90,0.134
42.12,150.06,0.134
42.15,150.22,0.135
42.18,150.37,0.135
42.21,150.53,0.135
42.24,150.69,0.135
42.28,150.85,0.135
42.31,151.01,0.135
42.34,151.17,0.135
42.37,151.32,0.135
42.40,151.48,0.135
42.43,151.64,0.135
42.46,151.80,0.135
42.50,151.96,0.135
42.53,152.12,0.135
42.56,152.27,0.135
42.59,152.43,0.135
42.62,152.59,0.135
42.66,152.75,0.135
42.69,152.91,0.135
42.72,153.07,0.135
42.75,153.22,0.135
42.78,153.38,0.135
42.81,153.54,0.135
42.84,153.70,0.135
42.88,153.86,0.135
42.91,154.02,0.135
42.94,154.18,0.135
42.97,154.33,0.135
43.00,154.49,0.135
43.04,154.65,0.135
43.07,154.81,0.135
43.10,154.97,0.135
43.13,155.13,0.135
43.16,155.28,0.135
43.19,155.44,0.135
43.23,155.60,0.135
43.26,155.76,0.135
43.29,155.92,0.135
43.32,156.08,0.135
43.35,156.23,0.135
43.38,156.39,0.135
43.41,156.55,0.136
43.45,156.71,0.136
43.48,156.87,0.136
43.51,157.03,0.136
43.54,157.18,0.136
43.57,157.34,0.136
43.61,157.50,0.135
43.64,157.66,0.135
43.67,157.82,0.135
43.70,157.97,0.135
43.73,158.13,0.135
43.76,158.29,0.135
43.79,158.45,0.136
43.83,158.61,0.136
43.86,158.77,0.136
43.89,158.93,0.136
43.92,159.08,0.136
43.95,159.24,0.136
43.99,159.40,0.136
44.02,159.56,0.136
44.05,159.72,0.136
44.08,159.88,0.136
44.11,160.03,0.136
44.14,160.19,0.136
44.18,160.35,0.136
44.21,160.51,0.136
44.24,160.67,0.136
44.27,160.82,0.136
44.30,160.98,0.136
44.33,161.14,0.136
44.36,161.30,0.136
44.40,161.46,0.136
44.43,161.62,0.136
44.46,161.78,0.136
44.49,161.93,0.136
44.52,162.09,0.136
44.56,162.25,0.136
44.59,162.41,0.136
44.62,162.57,0.136
44.65,162.73,0.136
44.68,162.88,0.136
44.71,163.04,0.136
44.74,163.20,0.136
44.78,163.36,0.136
44.81,163.52,0.136
44.84,163.67,0.137
44.87,163.83,0.137
44.90,163.99,0.137
44.94,164.15,0.137
44.97,164.31,0.137
45.00,164.47,0.137
45.03,164.63,0.137
45.06,164.78,0.137
45.09,164.94,0.137
45.13,165.10,0.137
45.16,165.26,0.137
45.19,165.42,0.137
45.22,165.58,0.137
45.25,165.73,0.137
45.28,165.89,0.137
45.31,166.05,0.137
45.35,166.21,0.137
45.38,166.37,0.137
45.41,166.53,0.137
45.44,166.68,0.137
45.47,166.84,0.137
45.51,167.00,0.137
45.54,167.16,0.137
45.57,167.32,0.137
45.60,167.48,0.137
45.63,167.63,0.138
45.66,167.79,0.138
45.69,167.95,0.138
45.73,168.11,0.138
45.76,168.27,0.138
45.79,168.43,0.138
45.82,168.58,0.138
45.85,168.74,0.138
45.89,168.90,0.138
45.92,169.06,0.138
45.95,169.22,
45.98,,
45.99,,

[step]
Ramp 5.00 °C/min to -60.00 °C
Time,Temperature,Heat Flow (Normalized)
min,°C,W/g
46.99,170.12,-0.032
47.02,170.12,-0.032
47.05,170.10,-0.032
47.08,170.07,-0.030
47.11,170.00,-0.039
47.14,169.90,-0.063
47.18,169.79,-0.091
47.21,169.67,-0.117
47.24,169.53,-0.137
47.27,169.40,-0.152
47.30,169.26,-0.163
47.34,169.11,-0.171
47.37,168.96,-0.178
47.40,168.81,-0.182
47.43,168.66,-0.185
47.46,168.51,-0.188
47.49,168.36,-0.191
47.53,168.21,-0.192
47.56,168.05,-0.194
47.59,167.90,-0.194
47.62,167.74,-0.195
47.65,167.58,-0.195
47.68,167.43,-0.196
47.71,167.27,-0.196
47.75,167.11,-0.196
47.78,166.96,-0.197
47.81,166.80,-0.197
47.84,166.64,-0.197
47.87,166.49,-0.198
47.91,166.33,-0.198
47.94,166.17,-0.198
47.97,166.01,-0.198
48.00,165.86,-0.198
48.03,165.70,-0.198
48.06,165.54,-0.198
48.09,165.38,-0.198
48.13,165.23,-0.198
48.16,165.07,-0.198
48.19,164.91,-0.198
48.22,164.75,-0.198
48.25,164.59,-0.198
48.29,164.44,-0.198
48.32,164.28,-0.198
48.35,164.12,-0.198
48.38,163.96,-0.198
48.41,163.81,-0.198
48.44,163.65,-0.198
48.48,163.49,-0.198
48.51,163.33,-0.198
48.54,163.17,-0.197
48.57,163.01,-0.197
48.60,162.86,-0.197
48.63,162.70,-0.197
48.66,162.54,-0.197
48.70,162.38,-0.197
48.73,162.23,-0.197
48.76,162.07,-0.197
48.79,161.91,-0.197
48.82,161.75,-0.197
48.86,161.59,-0.196
48.89,161.43,-0.196
48.92,161.27,-0.196
48.95,161.12,-0.196
48.98,160.96,-0.196
49.01,160.80,-0.196
49.04,160.64,-0.196
49.08,160.48,-0.195
49.11,160.33,-0.195
49.14,160.17,-0.195
49.17,160.01,-0.195
49.20,159.85,-0.195
49.24,159.69,-0.195
49.27,159.54,-0.195
49.30,159.38,-0.195
49.33,159.22,-0.194
49.36,159.06,-0.194
49.39,158.90,-0.194
49.43,158.74,-0.194
49.46,158.59,-0.194
49.49,158.43,-0.194
49.52,158.27,-0.194
49.55,158.11,-0.194
49.58,157.95,-0.194
49.61,157.79,-0.193
49.65,157.64,-0.193
49.68,157.48,-0.193
49.71,157.32,-0.193
49.74,157.16,-0.193
49.77,157.00,-0.193
49.81,156.84,-0.193
49.84,156.69,-0.193
49.87,156.53,-0.192
49.90,156.37,-0.192
49.93,156.21,-0.192
49.96,156.05,-0.192
49.99,155.90,-0.192
50.03,155.74,-0.192
50.06,155.58,-0.192
50.09,155.42,-0.192
50.12,155.26,-0.192
50.15,155.11,-0.191
50.19,154.95,-0.191
50.22,154.79,-0.191
50.25,154.63,-0.191
50.28,154.47,-0.191
50.31,154.31,-0.191
50.34,154.15,-0.191
50.38,154.00,-0.191
50.41,153.84,-0.191
50.44,153.68,-0.191
50.47,153.52,-0.191
50.50,153.36,-0.191
50.53,153.20,-0.190
50.56,153.05,-0.190
50.60,152.89,-0.190
50.63,152.73,-0.190
50.66,152.57,-0.190
50.69,152.41,-0.190
50.72,152.26,-0.190
50.76,152.10,-0.190
50.79,151.94,-0.190
50.82,151.78,-0.190
50.85,151.62,-0.190
50.88,151.46,-0.189
50.91,151.31,-0.189
50.94,151.15,-0.189
50.98,150.99,-0.189
51.01,150.83,-0.189
51.04,150.67,-0.189
51.07,150.52,-0.189
51.10,150.36,-0.189
51.14,150.20,-0.189
51.17,150.04,-0.189
51.20,149.88,-0.189
51.23,149.72,-0.189
51.26,149.57,-0.189
51.29,149.41,-0.189
51.33,149.25,-0.188
51.36,149.09,-0.188
51.39,148.93,-0.188
51.42,148.77,-0.188
51.45,148.62,-0.188
51.48,148.46,-0.188
51.51,148.30,-0.188
51.55,148.14,-0.188
51.58,147.98,-0.188
51.61,147.83,-0.188
51.64,147.67,-0.188
51.67,147.51,-0.188
51.71,147.35,-0.188
51.74,147.19,-0.188
51.77,147.03,-0.187
51.80,146.88,-0.187
51.83,146.72,-0.187
51.86,146.56,-0.187
51.89,146.40,-0.187
51.93,146.24,-0.187
51.96,146.08,-0.187
51.99,145.93,-0.187
52.02,145.77,-0.187
52.05,145.61,-0.187
52.09,145.45,-0.187
52.12,145.29,-0.187
52.15,145.13,-0.187
52.18,144.98,-0.187
52.21,144.82,-0.187
52.24,144.66,-0.186
52.28,144.50,-0.186
52.31,144.34,-0.186
52.34,144.18,-0.186
52.37,144.03,-0.186
52.40,143.87,-0.186
52.43,143.71,-0.186
52.46,143.55,-0.186
52.50,143.39,-0.186
52.53,143.24,-0.186
52.56,143.08,-0.185
52.59,142.92,-0.185
52.62,142.76,-0.185
52.66,142.60,-0.185
52.69,142.44,-0.185
52.72,142.29,-0.185
52.75,142.13,-0.185
52.78,141.97,-0.185
52.81,141.81,-0.185
52.84,141.65,-0.185
52.88,141.50,-0.185
52.91,141.34,-0.184
52.94,141.18,-0.184
52.97,141.02,-0.184
53.00,140.86,-0.184
53.04,140.70,-0.184
53.07,140.55,-0.184
53.10,140.39,-0.184
53.13,140.23,-0.184
53.16,140.07,-0.184
53.19,139.91,-0.184
53.23,139.75,-0.184
53.26,139.60,-0.184
53.29,139.44,-0.184
53.32,139.28,-0.184
53.35,139.12,-0.184
53.38,138.96,-0.183
53.41,138.81,-0.183
53.45,138.65,-0.183
53.48,138.49,-0.183
53.51,138.33,-0.183
53.54,138.17,-0.183
53.57,138.01,-0.183
53.61,137.86,-0.183
53.64,137.70,-0.183
53.67,137.54,-0.183
53.70,137.38,-0.183
53.73,137.22,-0.183
53.76,137.06,-0.183
53.79,136.91,-0.183
53.83,136.75,-0.183
53.86,136.59,-0.183
53.89,136.43,-0.183
53.92,136.27,-0.183
53.95,136.11,-0.183
53.99,135.96,-0.183
54.02,135.80,-0.182
54.05,135.64,-0.182
54.08,135.48,-0.182
54.11,135.32,-0.182
54.14,135.16,-0.182
54.18,135.01,-0.182
54.21,134.85,-0.182
54.24,134.69,-0.182
54.27,134.53,-0.182
54.30,134.37,-0.182
54.33,134.22,-0.182
54.36,134.06,-0.182
54.40,133.90,-0.182
54.43,133.74,-0.182
54.46,133.58,-0.182
54.49,133.42,-0.182
54.52,133.27,-0.181
54.56,133.11,-0.181
54.59,132.95,-0.181
54.62,132.79,-0.181
54.65,132.63,-0.181
54.68,132.48,-0.181
54.71,132.32,-0.181
54.74,132.16,-0.181
54.78,132.00,-0.181
54.81,131.84,-0.181
54.84,131.68,-0.181
54.87,131.53,-0.181
54.90,131.37,-0.181
54.94,131.21,-0.181
54.97,131.05,-0.181
55.00,130.89,-0.181
55.03,130.74,-0.181
55.06,130.58,-0.181
55.09,130.42,-0.180
55.13,130.26,-0.180
55.16,130.10,-0.180
55.19,129.94,-0.180
55.22,129.79,-0.180
55.25,129.63,-0.180
55.28,129.47,-0.180
55.31,129.31,-0.180
55.35,129.15,-0.180
55.38,129.00,-0.180
55.41,128.84,-0.180
55.44,128.68,-0.180
55.47,128.52,-0.180
55.51,128.36,-0.180
55.54,128.20,-0.180
55.57,128.05,-0.180
55.60,127.89,-0.180
55.63,127.73,-0.180
55.66,127.57,-0.180
55.69,127.41,-0.180
55.73,127.25,-0.180
55.76,127.10,-0.180
55.79,126.94,-0.180
55.82,126.78,-0.179
55.85,126.62,-0.179
55.89,126.46,-0.179
55.92,126.30,-0.179
55.95,126.15,-0.179
55.98,125.99,-0.179
56.01,125.83,-0.179
56.04,125.67,-0.179
56.08,125.51,-0.179
56.11,125.36,-0.179
56.14,125.20,-0.179
56.17,125.04,-0.179
56.20,124.88,-0.179
56.23,124.72,-0.179
56.26,124.56,-0.179
56.30,124.41,-0.179
56.33,124.25,-0.179
56.36,124.09,-0.179
56.39,123.93,-0.179
56.42,123.77,-0.179
56.46,123.61,-0.179
56.49,123.46,-0.179
56.52,123.30,-0.179
56.55,123.14,-0.178
56.58,122.98,-0.178
56.61,122.82,-0.178
56.64,122.66,-0.178
56.68,122.51,-0.178
56.71,122.35,-0.178
56.74,122.19,-0.178
56.77,122.03,-0.178
56.80,121.87,-0.178
56.84,121.72,-0.178
56.87,121.56,-0.178
56.90,121.40,-0.178
56.93,121.24,-0.178
56.96,121.08,-0.178
56.99,120.92,-0.178
57.03,120.77,-0.178
57.06,120.61,-0.178
57.09,120.45,-0.178
57.12,120.29,-0.178
57.15,120.13,-0.178
57.18,119.97,-0.178
57.21,119.82,-0.178
57.25,119.66,-0.178
57.28,119.50,-0.178
57.31,119.34,-0.178
57.34,119.18,-0.177
57.37,119.02,-0.177
57.41,118.87,-0.177
57.44,118.71,-0.177
57.47,118.55,-0.177
57.50,118.39,-0.177
57.53,118.23,-0.177
57.56,118.07,-0.177
57.59,117.92,-0.177
57.63,117.76,-0.177
57.66,117.60,-0.177
57.69,117.44,-0.177
57.72,117.28,-0.177
57.75,117.13,-0.177
57.79,116.97,-0.177
57.82,116.81,-0.177
57.85,116.65,-0.177
57.88,116.49,-0.177
57.91,116.34,-0.177
57.94,116.18,-0.177
57.98,116.02,-0.177
58.01,115.86,-0.177
58.04,115.70,-0.177
58.07,115.54,-0.176
58.10,115.39,-0.176
58.13,115.23,-0.176
58.16,115.07,-0.176
58.20,114.91,-0.176
58.23,114.75,-0.176
[...]
201.38,6.25,0.110
201.42,6.41,0.110
201.45,6.57,0.110
201.48,6.73,0.110
201.51,6.88,0.110
201.54,7.04,0.110
201.57,7.20,0.110
201.60,7.36,0.110
201.64,7.52,0.110
201.67,7.67,0.110
201.70,7.83,0.110
201.73,7.99,0.110
201.76,8.15,0.110
201.80,8.31,0.110
201.83,8.47,0.111
201.86,8.62,0.111
201.89,8.78,0.111
201.92,8.94,0.111
201.95,9.10,0.111
201.98,9.26,0.111
202.02,9.42,0.111
202.05,9.58,0.111
202.08,9.73,0.111
202.11,9.89,0.111
202.14,10.05,0.111
202.18,10.21,0.111
202.21,10.37,0.111
202.24,10.52,0.111
202.27,10.69,0.111
202.30,10.84,0.111
202.33,11.00,0.111
202.37,11.16,0.112
202.40,11.32,0.112
202.43,11.48,0.112
202.46,11.63,0.112
202.49,11.79,0.112
202.52,11.95,0.112
202.55,12.11,0.112
202.59,12.27,0.112
202.62,12.43,0.112
202.65,12.59,0.112
202.68,12.74,0.112
202.71,12.90,0.112
202.75,13.06,0.112
202.78,13.22,0.112
202.81,13.38,0.112
202.84,13.54,0.112
202.87,13.69,0.112
202.90,13.85,0.112
202.93,14.01,0.112
202.97,14.17,0.112
203.00,14.33,0.112
203.03,14.49,0.113
203.06,14.64,0.113
203.09,14.80,0.113
203.13,14.96,0.113
203.16,15.12,0.113
203.19,15.28,0.113
203.22,15.44,0.113
203.25,15.59,0.113
203.28,15.75,0.113
203.32,15.91,0.113
203.35,16.07,0.113
203.38,16.23,0.113
203.41,16.39,0.113
203.44,16.54,0.113
203.47,16.70,0.113
203.50,16.86,0.113
203.54,17.02,0.113
203.57,17.18,0.113
203.60,17.34,0.113
203.63,17.50,0.113
203.66,17.65,0.113
203.70,17.81,0.113
203.73,17.97,0.114
203.76,18.13,0.114
203.79,18.29,0.114
203.82,18.45,0.114
203.85,18.61,0.114
203.88,18.76,0.114
203.92,18.92,0.114
203.95,19.08,0.114
203.98,19.24,0.114
204.01,19.40,0.114
204.04,19.55,0.114
204.08,19.71,0.114
204.11,19.87,0.114
204.14,20.03,0.114
204.17,20.19,0.114
204.20,20.35,0.114
204.23,20.51,0.114
204.27,20.66,0.115
204.30,20.82,0.115
204.33,20.98,0.115
204.36,21.14,0.115
204.39,21.30,0.115
204.42,21.46,0.115
204.45,21.61,0.115
204.49,21.77,0.115
204.52,21.93,0.115
204.55,22.09,0.115
204.58,22.25,0.115
204.61,22.41,0.115
204.65,22.57,0.115
204.68,22.72,0.115
204.71,22.88,0.115
204.74,23.04,0.115
204.77,23.20,0.115
204.80,23.36,0.115
204.83,23.52,0.116
204.87,23.67,0.116
204.90,23.83,0.116
204.93,23.99,0.116
204.96,24.15,0.116
204.99,24.31,0.116
205.03,24.47,0.116
205.06,24.63,0.116
205.09,24.78,0.116
205.12,24.94,0.116
205.15,25.10,0.116
205.18,25.26,0.116
205.22,25.42,0.116
205.25,25.58,0.116
205.28,25.73,0.116
205.31,25.89,0.116
205.34,26.05,0.116
205.37,26.21,0.116
205.40,26.37,0.117
205.44,26.53,0.117
205.47,26.69,0.117
205.50,26.84,0.117
205.53,27.00,0.117
205.56,27.16,0.117
205.60,27.32,0.117
205.63,27.48,0.117
205.66,27.64,0.117
205.69,27.79,0.117
205.72,27.95,0.117
205.75,28.11,0.117
205.78,28.27,0.117
205.82,28.43,0.117
205.85,28.59,0.117
205.88,28.74,0.117
205.91,28.90,0.117
205.94,29.06,0.117
205.98,29.22,0.117
206.01,29.38,0.118
206.04,29.54,0.118
206.07,29.69,0.118
206.10,29.85,0.118
206.13,30.01,0.118
206.17,30.17,0.118
206.20,30.33,0.118
206.23,30.49,0.118
206.26,30.65,0.118
206.29,30.80,0.118
206.32,30.96,0.118
206.35,31.12,0.118
206.39,31.28,0.118
206.42,31.44,0.118
206.45,31.60,0.118
206.48,31.75,0.118
206.51,31.91,0.118
206.55,32.07,0.118
206.58,32.23,0.118
206.61,32.39,0.119
206.64,32.55,0.119
206.67,32.71,0.119
206.70,32.86,0.119
206.73,33.02,0.119
206.77,33.18,0.119
206.80,33.34,0.119
206.83,33.50,0.119
206.86,33.66,0.119
206.89,33.81,0.119
206.93,33.97,0.119
206.96,34.13,0.119
206.99,34.29,0.119
207.02,34.45,0.119
207.05,34.61,0.119
207.08,34.77,0.119
207.12,34.92,0.119
207.15,35.08,0.119
207.18,35.24,0.119
207.21,35.40,0.119
207.24,35.56,0.120
207.27,35.72,0.120
207.30,35.87,0.120
207.34,36.03,0.120
207.37,36.19,0.120
207.40,36.35,0.120
207.43,36.51,0.120
207.46,36.67,0.120
207.50,36.83,0.120
207.53,36.98,0.120
207.56,37.14,0.120
207.59,37.30,0.120
207.62,37.46,0.120
207.65,37.62,0.120
207.68,37.78,0.120
207.72,37.93,0.120
207.75,38.09,0.120
207.78,38.25,0.120
207.81,38.41,0.120
207.84,38.57,0.120
207.88,38.73,0.120
207.91,38.88,0.120
207.94,39.04,0.120
207.97,39.20,0.121
208.00,39.36,0.121
208.03,39.52,0.121
208.07,39.68,0.121
208.10,39.83,0.121
208.13,39.99,0.121
208.16,40.15,0.121
208.19,40.31,0.121
208.22,40.47,0.121
208.25,40.63,0.121
208.29,40.79,0.121
208.32,40.95,0.121
208.35,41.10,0.121
208.38,41.26,0.121
208.41,41.42,0.121
208.45,41.58,0.121
208.48,41.74,0.121
208.51,41.90,0.121
208.54,42.05,0.121
208.57,42.21,0.121
208.60,42.37,0.122
208.63,42.53,0.122
208.67,42.69,0.122
208.70,42.84,0.122
208.73,43.00,0.122
208.76,43.16,0.122
208.79,43.32,0.122
208.83,43.48,0.122
208.86,43.64,0.122
208.89,43.79,0.122
208.92,43.95,0.122
208.95,44.11,0.122
208.98,44.27,0.122
209.02,44.43,0.122
209.05,44.59,0.122
209.08,44.75,0.122
209.11,44.91,0.122
209.14,45.06,0.123
209.17,45.22,0.123
209.20,45.38,0.123
209.24,45.54,0.123
209.27,45.70,0.123
209.30,45.86,0.123
209.33,46.01,0.123
209.36,46.17,0.123
209.40,46.33,0.123
209.43,46.49,0.123
209.46,46.65,0.123
209.49,46.81,0.123
209.52,46.96,0.123
209.55,47.12,0.123
209.58,47.28,0.123
209.62,47.44,0.123
209.65,47.60,0.123
209.68,47.76,0.123
209.71,47.92,0.123
209.74,48.07,0.124
209.78,48.23,0.124
209.81,48.39,0.124
209.84,48.55,0.124
209.87,48.71,0.124
209.90,48.86,0.124
209.93,49.02,0.124
209.97,49.18,0.124
210.00,49.34,0.124
210.03,49.50,0.124
210.06,49.66,0.124
210.09,49.82,0.124
210.12,49.97,0.124
210.15,50.13,0.124
210.19,50.29,0.124
210.22,50.45,0.124
210.25,50.61,0.124
210.28,50.77,0.124
210.31,50.92,0.124
210.35,51.08,0.124
210.38,51.24,0.124
210.41,51.40,0.124
210.44,51.56,0.124
210.47,51.72,0.125
210.50,51.88,0.125
210.53,52.04,0.125
210.57,52.19,0.125
210.60,52.35,0.125
210.63,52.51,0.125
210.66,52.67,0.125
210.69,52.83,0.125
210.73,52.98,0.125
210.76,53.14,0.125
210.79,53.30,0.125
210.82,53.46,0.125
210.85,53.62,0.125
210.88,53.78,0.125
210.92,53.94,0.125
210.95,54.09,0.125
210.98,54.25,0.125
211.01,54.41,0.125
211.04,54.57,0.125
211.07,54.73,0.125
211.10,54.89,0.125
211.14,55.04,0.125
211.17,55.20,0.126
211.20,55.36,0.126
211.23,55.52,0.126
211.26,55.68,0.126
211.30,55.84,0.126
211.33,56.00,0.126
211.36,56.15,0.126
211.39,56.31,0.126
211.42,56.47,0.126
211.45,56.63,0.126
211.48,56.79,0.126
211.52,56.94,0.126
211.55,57.10,0.126
211.58,57.26,0.126
211.61,57.42,0.126
211.64,57.58,0.126
211.68,57.74,0.126
211.71,57.90,0.126
211.74,58.06,0.126
211.77,58.21,0.127
211.80,58.37,0.127
211.83,58.53,0.127
211.87,58.69,0.127
211.90,58.85,0.127
211.93,59.01,0.127
211.96,59.16,0.127
211.99,59.32,0.127
212.02,59.48,0.127
212.05,59.64,0.127
212.09,59.80,0.127
212.12,59.96,0.127
212.15,60.12,0.127
212.18,60.27,0.127
212.21,60.43,0.127
212.25,60.59,0.127
212.28,60.75,0.127
212.31,60.91,0.127
212.34,61.07,0.127
212.37,61.22,0.127
212.40,61.38,0.127
212.43,61.54,0.127
212.47,61.70,0.127
212.50,61.86,0.127
212.53,62.01,0.128
212.56,62.17,0.128
212.59,62.33,0.128
212.63,62.49,0.128
212.66,62.65,0.128
212.69,62.81,0.128
212.72,62.97,0.128
212.75,63.12,0.128
212.78,63.28,0.128
212.82,63.44,0.128
212.85,63.60,0.128
212.88,63.76,0.128
212.91,63.92,0.128
212.94,64.08,0.128
212.97,64.23,0.128
213.00,64.39,0.128
213.04,64.55,0.128
213.07,64.71,0.128
213.10,64.86,0.128
213.13,65.02,0.128
213.16,65.18,0.128
213.20,65.34,0.129
213.23,65.50,0.129
213.26,65.66,0.129
213.29,65.82,0.129
213.32,65.98,0.129
213.35,66.13,0.129
213.38,66.29,0.129
213.42,66.45,0.129
213.45,66.61,0.129
213.48,66.77,0.129
213.51,66.93,0.129
213.54,67.08,0.129
213.58,67.24,0.129
213.61,67.40,0.129
213.64,67.56,0.129
213.67,67.72,0.129
213.70,67.88,0.129
213.73,68.03,0.129
213.77,68.19,0.129
213.80,68.35,0.129
213.83,68.51,0.129
213.86,68.67,0.130
213.89,68.83,0.130
213.92,68.98,0.130
213.95,69.14,0.130
213.99,69.30,0.130
214.02,69.46,0.130
214.05,69.62,0.130
214.08,69.78,0.130
214.11,69.94,0.130
214.15,70.09,0.130
214.18,70.25,0.130
214.21,70.41,0.130
214.24,70.57,0.130
214.27,70.73,0.130
214.30,70.89,0.130
214.33,71.04,0.130
214.37,71.20,0.130
214.40,71.36,0.130
214.43,71.52,0.130
214.46,71.68,0.131
214.49,71.84,0.131
214.53,71.99,0.131
214.56,72.15,0.131
214.59,72.31,0.131
214.62,72.47,0.131
214.65,72.63,0.131
214.68,72.79,0.131
214.72,72.94,0.131
214.75,73.10,0.131
214.78,73.26,0.131
214.81,73.42,0.131
214.84,73.58,0.131
214.87,73.74,0.131
214.90,73.90,0.131
214.94,74.05,0.131
214.97,74.21,0.131
215.00,74.37,0.131
215.03,74.53,0.131
215.06,74.69,0.132
215.10,74.85,0.132
215.13,75.00,0.132
215.16,75.16,0.132
215.19,75.32,0.132
215.22,75.48,0.132
215.25,75.64,0.132
215.28,75.80,0.132
215.32,75.95,0.132
215.35,76.11,0.132
215.38,76.27,0.132
215.41,76.43,0.132
215.44,76.59,0.132
215.48,76.75,0.132
215.51,76.91,0.132
215.54,77.06,0.132
215.57,77.22,0.132
215.60,77.38,0.132
215.63,77.54,0.133
215.67,77.70,0.133
215.70,77.86,0.133
215.73,78.01,0.133
215.76,78.17,0.133
215.79,78.33,0.133
215.82,78.49,0.133
215.85,78.65,0.133
215.89,78.81,0.133
215.92,78.96,0.133
215.95,79.12,0.133
215.98,79.28,0.133
216.01,79.44,0.133
216.05,79.60,0.133
216.08,79.76,0.133
216.11,79.92,0.133
216.14,80.07,0.133
216.17,80.23,0.133
216.20,80.39,0.133
216.23,80.55,0.133
216.27,80.71,0.133
216.30,80.87,0.133
216.33,81.02,0.133
216.36,81.18,0.134
216.39,81.34,0.134
216.43,81.50,0.134
216.46,81.66,0.134
216.49,81.82,0.134
216.52,81.97,0.134
216.55,82.13,0.134
216.58,82.29,0.134
216.62,82.45,0.134
216.65,82.61,0.134
216.68,82.77,0.134
216.71,82.92,0.134
216.74,83.08,0.134
216.77,83.24,0.134
216.80,83.40,0.134
216.84,83.56,0.134
216.87,83.72,0.134
216.90,83.88,0.134
216.93,84.03,0.134
216.96,84.19,0.134
217.00,84.35,0.134
217.03,84.51,0.134
217.06,84.67,0.134
217.09,84.83,0.134
217.12,84.98,0.134
217.15,85.14,0.134
217.18,85.30,0.134
217.22,85.46,0.135
217.25,85.62,0.135
217.28,85.78,0.135
217.31,85.93,0.135
217.34,86.09,0.135
217.38,86.25,0.135
217.41,86.41,0.135
217.44,86.57,0.135
217.47,86.73,0.135
217.50,86.89,0.135
217.53,87.04,0.135
217.57,87.20,0.135
217.60,87.36,0.135
217.63,87.52,0.135
217.66,87.68,0.135
217.69,87.84,0.135
217.72,87.99,0.135
217.75,88.15,0.135
217.79,88.31,0.135
217.82,88.47,0.135
217.85,88.63,0.135
217.88,88.79,0.135
217.91,88.95,0.135
217.95,89.10,0.136
217.98,89.26,0.136
218.01,89.42,0.136
218.04,89.58,0.136
218.07,89.74,0.136
218.10,89.90,0.136
218.13,90.05,0.136
218.17,90.21,0.136
218.20,90.37,0.136
218.23,90.53,0.136
218.26,90.69,0.136
218.29,90.85,0.136
218.33,91.00,0.136
218.36,91.16,0.136
218.39,91.32,0.136
218.42,91.48,0.136
218.45,91.64,0.136
218.48,91.79,0.136
218.52,91.96,0.136
218.55,92.11,0.136
218.58,92.27,0.136
218.61,92.43,0.136
218.64,92.59,0.136
218.67,92.75,0.137
218.70,92.90,0.137
218.74,93.06,0.137
218.77,93.22,0.137
218.80,93.38,0.137
218.83,93.54,0.137
218.86,93.70,0.137
218.90,93.86,0.137
218.93,94.01,0.137
218.96,94.17,0.137
218.99,94.33,0.137
219.02,94.49,0.137
219.05,94.65,0.137
219.08,94.81,0.137
219.12,94.96,0.137
219.15,95.12,0.137
219.18,95.28,0.137
219.21,95.44,0.137
219.24,95.60,0.138
219.28,95.76,0.138
219.31,95.91,0.138
219.34,96.07,0.138
219.37,96.23,0.138
219.40,96.39,0.138
219.43,96.55,0.138
219.47,96.71,0.138
219.50,96.86,0.138
219.53,97.02,0.138
219.56,97.18,0.138
219.59,97.34,0.138
219.62,97.50,0.138
219.65,97.66,0.138
219.69,97.81,0.138
219.72,97.97,0.138
219.75,98.13,0.138
219.78,98.29,0.138
219.81,98.45,0.138
219.85,98.61,0.138
219.88,98.76,0.138
219.91,98.92,0.138
219.94,99.08,0.138
219.97,99.24,0.138
220.00,99.40,0.138
220.03,99.56,0.139
220.07,99.72,0.139
220.10,99.87,0.139
220.13,100.03,0.139
220.16,100.19,0.139
220.19,100.35,0.139
220.23,100.51,0.139
220.26,100.67,0.139
220.29,100.82,0.139
220.32,100.98,0.139
220.35,101.14,0.139
220.38,101.30,0.139
220.42,101.46,0.139
220.45,101.62,0.139
220.48,101.77,0.139
220.51,101.93,0.139
220.54,102.09,0.139
220.57,102.25,0.139
220.60,102.41,0.139
220.64,102.57,0.139
220.67,102.73,0.140
220.70,102.88,0.140
220.73,103.04,0.140
220.76,103.20,0.140
220.80,103.36,0.140
220.83,103.52,0.140
220.86,103.68,0.140
220.89,103.83,0.140
220.92,103.99,0.140
220.95,104.15,0.140
220.98,104.31,0.140
221.02,104.47,0.140
221.05,104.63,0.140
221.08,104.78,0.140
221.11,104.94,0.140
221.14,105.10,0.140
221.18,105.26,0.140
221.21,105.42,0.140
221.24,105.58,0.140
221.27,105.73,0.140
221.30,105.89,0.140
221.33,106.05,0.140
221.37,106.21,0.140
221.40,106.37,0.141
221.43,106.53,0.141
221.46,106.69,0.141
221.49,106.84,0.141
221.52,107.00,0.141
221.55,107.16,0.141
221.59,107.32,0.141
221.62,107.48,0.141
221.65,107.64,0.141
221.68,107.79,0.141
221.71,107.95,0.141
221.75,108.11,0.141
221.78,108.27,0.141
221.81,108.43,0.141
221.84,108.59,0.141
221.87,108.74,0.141
221.90,108.90,0.141
221.93,109.06,0.141
221.97,109.22,0.141
222.00,109.38,0.141
222.03,109.54,0.141
222.06,109.70,0.141
222.09,109.85,0.141
222.13,110.01,0.141
222.16,110.17,0.141
222.19,110.33,0.141
222.22,110.49,0.141
222.25,110.64,0.141
222.28,110.80,0.142
222.32,110.96,0.142
222.35,111.12,0.142
222.38,111.28,0.142
222.41,111.44,0.142
222.44,111.60,0.142
222.47,111.76,0.142
222.50,111.91,0.142
222.54,112.08,0.142
222.57,112.23,0.142
222.60,112.39,0.142
222.63,112.55,0.142
222.66,112.70,0.142
222.70,112.86,0.142
222.73,113.02,0.142
222.76,113.18,0.142
222.79,113.34,0.142
222.82,113.49,0.142
222.85,113.65,0.142
222.88,113.81,0.142
222.92,113.97,0.142
222.95,114.13,0.142
222.98,114.29,0.142
223.01,114.44,0.142
223.04,114.60,0.142
223.08,114.76,0.142
223.11,114.92,0.143
223.14,115.08,0.143
223.17,115.24,0.143
223.20,115.40,0.143
223.23,115.56,0.143
223.27,115.72,0.143
223.30,115.87,0.143
223.33,116.03,0.143
223.36,116.19,0.143
223.39,116.35,0.143
223.42,116.51,0.143
223.45,116.66,0.143
223.49,116.82,0.143
223.52,116.98,0.143
223.55,117.14,0.143
223.58,117.30,0.143
223.61,117.46,0.143
223.65,117.61,0.143
223.68,117.77,0.143
223.71,117.93,0.143
223.74,118.09,0.143
223.77,118.25,0.144
223.80,118.41,0.144
223.83,118.56,0.144
223.87,118.72,0.144
223.90,118.88,0.144
223.93,119.04,0.144
223.96,119.20,0.144
223.99,119.36,0.144
224.03,119.51,0.144
224.06,119.67,0.144
224.09,119.83,0.144
224.12,119.99,0.144
224.15,120.15,0.144
224.18,120.31,0.144
224.22,120.46,0.144
224.25,120.62,0.144
224.28,120.78,0.144
224.31,120.94,0.144
224.34,121.10,0.144
224.37,121.26,0.144
224.40,121.41,0.144
224.44,121.57,0.144
224.47,121.73,0.144
224.50,121.89,0.145
224.53,122.05,0.145
224.56,122.21,0.145
224.60,122.37,0.145
224.63,122.52,0.145
224.66,122.68,0.145
224.69,122.84,0.145
224.72,123.00,0.145
224.75,123.16,0.145
224.78,123.32,0.145
224.82,123.47,0.145
224.85,123.63,0.145
224.88,123.79,0.145
224.91,123.95,0.145
224.94,124.11,0.145
224.98,124.27,0.145
225.01,124.42,0.145
225.04,124.58,0.145
225.07,124.74,0.145
225.10,124.90,0.145
225.13,125.06,0.145
225.17,125.22,0.145
225.20,125.37,0.145
225.23,125.53,0.145
225.26,125.69,0.145
225.29,125.85,0.145
225.32,126.01,0.145
225.35,126.17,0.146
225.39,126.32,0.146
225.42,126.48,0.146
225.45,126.64,0.146
225.48,126.80,0.146
225.51,126.96,0.146
225.55,127.12,0.146
225.58,127.28,0.146
225.61,127.44,0.146
225.64,127.59,0.146
225.67,127.75,0.146
225.70,127.91,0.146
225.73,128.07,0.146
225.77,128.23,0.146
225.80,128.38,0.146
225.83,128.54,0.146
225.86,128.70,0.146
225.89,128.86,0.146
225.93,129.02,0.146
225.96,129.18,0.146
225.99,129.33,0.146
226.02,129.49,0.146
226.05,129.65,0.146
226.08,129.81,0.146
226.12,129.97,0.146
226.15,130.13,0.146
226.18,130.28,0.146
226.21,130.44,0.147
226.24,130.60,0.147
226.27,130.76,0.147
226.30,130.92,0.147
226.34,131.08,0.147
226.37,131.23,0.147
226.40,131.39,0.147
226.43,131.55,0.147
226.46,131.71,0.147
226.50,131.87,0.147
226.53,132.03,0.147
226.56,132.19,0.147
226.59,132.34,0.147
226.62,132.50,0.147
226.65,132.66,0.147
226.68,132.82,0.147
226.72,132.98,0.147
226.75,133.14,0.147
226.78,133.29,0.147
226.81,133.45,0.147
226.84,133.61,0.147
226.88,133.77,0.147
226.91,133.93,0.147
226.94,134.09,0.147
226.97,134.24,0.147
227.00,134.40,0.148
227.03,134.56,0.148
227.07,134.72,0.148
227.10,134.88,0.148
227.13,135.04,0.148
227.16,135.20,0.148
227.19,135.35,0.148
227.22,135.51,0.148
227.25,135.67,0.148
227.29,135.83,0.148
227.32,135.99,0.148
227.35,136.14,0.148
227.38,136.30,0.148
227.41,136.46,0.148
227.45,136.62,0.148
227.48,136.78,0.148
227.51,136.94,0.148
227.54,137.10,0.148
227.57,137.25,0.148
227.60,137.41,0.148
227.63,137.57,0.148
227.67,137.73,0.148
227.70,137.89,0.148
227.73,138.05,0.148
227.76,138.20,0.148
227.79,138.36,0.148
227.83,138.52,0.148
227.86,138.68,0.148
227.89,138.84,0.148
227.92,139.00,0.149
227.95,139.15,0.149
227.98,139.31,0.149
228.02,139.47,0.149
228.05,139.63,0.149
228.08,139.79,0.149
228.11,139.95,0.149
228.14,140.11,0.149
228.17,140.26,0.149
228.20,140.42,0.149
228.24,140.58,0.149
228.27,140.74,0.149
228.30,140.90,0.149
228.33,141.05,0.149
228.36,141.21,0.149
228.40,141.37,0.149
228.43,141.53,0.149
228.46,141.69,0.149
228.49,141.85,0.149
228.52,142.00,0.149
228.55,142.16,0.149
228.58,142.32,0.149
228.62,142.48,0.149
228.65,142.64,0.149
228.68,142.80,0.149
228.71,142.95,0.149
228.74,143.11,0.149
228.78,143.27,0.149
228.81,143.43,0.149
228.84,143.59,0.150
228.87,143.75,0.150
228.90,143.91,0.150
228.93,144.06,0.150
228.97,144.22,0.150
229.00,144.38,0.150
229.03,144.54,0.150
229.06,144.70,0.150
229.09,144.86,0.150
229.12,145.01,0.150
229.15,145.17,0.150
229.19,145.33,0.150
229.22,145.49,0.150
229.25,145.65,0.150
229.28,145.81,0.150
229.31,145.96,0.150
229.35,146.12,0.150
229.38,146.28,0.150
229.41,146.44,0.150
229.44,146.60,0.150
229.47,146.76,0.150
229.50,146.92,0.150
229.53,147.08,0.150
229.57,147.24,0.151
229.60,147.40,0.151
229.63,147.55,0.151
229.66,147.71,0.151
229.69,147.87,0.151
229.73,148.03,0.151
229.76,148.19,0.151
229.79,148.34,0.151
229.82,148.50,0.151
229.85,148.66,0.151
229.88,148.82,0.150
229.92,148.98,0.150
229.95,149.14,0.150
229.98,149.29,0.150
230.01,149.45,0.150
230.04,149.61,0.150
230.07,149.77,0.150
230.10,149.93,0.150
230.14,150.08,0.150
230.17,150.24,0.150
230.20,150.40,0.150
230.23,150.56,0.150
230.26,150.72,0.150
230.30,150.87,0.150
230.33,151.03,0.150
230.36,151.19,0.150
230.39,151.35,0.150
230.42,151.51,0.150
230.45,151.66,0.150
230.48,151.82,0.150
230.52,151.98,0.150
230.55,152.14,0.150
230.58,152.30,0.150
230.61,152.46,0.150
230.64,152.62,0.151
230.68,152.77,0.151
230.71,152.93,0.151
230.74,153.09,0.151
230.77,153.25,0.151
230.80,153.41,0.151
230.83,153.57,0.151
230.87,153.72,0.151
230.90,153.88,0.151
230.93,154.04,0.151
230.96,154.20,0.151
230.99,154.36,0.151
231.02,154.52,0.151
231.05,154.67,0.151
231.09,154.83,0.151
231.12,154.99,0.151
231.15,155.15,0.151
231.18,155.31,0.151
231.21,155.47,0.151
231.25,155.63,0.151
231.28,155.78,0.151
231.31,155.94,0.151
231.34,156.10,0.151
231.37,156.26,0.151
231.40,156.42,0.151
231.43,156.57,0.151
231.47,156.73,0.152
231.50,156.89,0.152
231.53,157.05,0.152
231.56,157.21,0.152
231.59,157.37,0.152
231.63,157.53,0.152
231.66,157.68,0.152
231.69,157.84,0.152
231.72,158.00,0.152
231.75,158.16,0.152
231.78,158.32,0.152
231.82,158.48,0.152
231.85,158.63,0.152
231.88,158.79,0.152
231.91,158.95,0.152
231.94,159.11,0.152
231.97,159.27,0.152
232.00,159.43,0.152
232.04,159.58,0.152
232.07,159.74,0.152
232.10,159.90,0.152
232.13,160.06,0.152
232.16,160.22,0.152
232.20,160.38,0.152
232.23,160.53,0.152
232.26,160.69,0.152
232.29,160.85,0.152
232.32,161.01,0.152
232.35,161.17,0.152
232.38,161.32,0.152
232.42,161.48,0.152
232.45,161.64,0.152
232.48,161.80,0.152
232.51,161.96,0.152
232.54,162.12,0.152
232.58,162.28,0.153
232.61,162.44,0.153
232.64,162.59,0.153
232.67,162.75,0.153
232.70,162.91,0.153
232.73,163.07,0.153
232.77,163.23,0.153
232.80,163.38,0.153
232.83,163.54,0.153
232.86,163.70,0.153
232.89,163.86,0.153
232.92,164.02,0.153
232.95,164.18,0.153
232.99,164.34,0.153
233.02,164.49,0.153
233.05,164.65,0.153
233.08,164.81,0.153
233.11,164.97,0.153
233.15,165.13,0.153
233.18,165.28,0.153
233.21,165.44,0.153
233.24,165.60,0.153
233.27,165.76,0.153
233.30,165.92,0.153
233.33,166.08,0.153
233.37,166.23,0.153
233.40,166.39,0.154
233.43,166.55,0.154
233.46,166.71,0.154
233.49,166.87,0.154
233.53,167.03,0.154
233.56,167.19,0.154
233.59,167.35,0.154
233.62,167.50,0.154
233.65,167.66,0.154
233.68,167.82,0.154
233.72,167.98,0.154
233.75,168.13,0.154
233.78,168.29,0.154
233.81,168.45,0.154
233.84,168.61,0.154
233.87,168.77,0.154
233.90,168.93,0.154
233.94,169.09,
233.97,169.24,
233.99,,