File: DSC/2023_06_29_CBD_Fragility_SBK.txt
Filename	2023_06_29_CBD_Fragiity_SBK
Instrument name	DSC2A-00468 (192.168.1.100)
Operator	SBK
rundate	6/29/2023
Sample name	2023_06_29_CBD_Fragiity_SBK
proceduresegments	Data Off ; Equilibrate -50.00 °C; Data On ; Ramp 10.00 °C/min to 100.00 °C; Data Off ; Isothermal 1.0 min; Data On ; Ramp 10.00 °C/min to -50.00 °C; Data Off ; Isothermal 1.0 min; Data On ; Ramp 10.00 °C/min to 40.00 °C; Data Off ; Isothermal 1.0 min; Data On ; Ramp 35.00 °C/min to -50.00 °C; Data Off ; Isothermal 1.0 min; Data On ; Ramp 10.00 °C/min to 40.00 °C; Data Off ; Isothermal 1.0 min; Data On ; Ramp 25.00 °C/min to -50.00 °C; Data Off ; Isothermal 1.0 min; Data On ; Ramp 10.00 °C/min to 40.00 °C; Data Off ; Isothermal 1.0 min; Data On ; Ramp 20.00 °C/min to -50.00 °C; Data Off ; Isothermal 1.0 min; Data On ; Ramp 10.00 °C/min to 40.00 °C; Data Off ; Isothermal 1.0 min; Data On ; Sample Interval  0.2 s/pt; Ramp 5.00 °C/min to -50.00 °C; Data Off ; Isothermal 1.0 min; Data On ; Sample Interval  0.1 s/pt; Ramp 10.00 °C/min to 40.00 °C; Data Off ; Isothermal 1.0 min; Data On ; Sample Interval  1.0 s/pt; Ramp 1.00 °C/min to -50.00 °C; Data Off ; Isothermal 1.0 min; Data On ; Sample Interval  0.1 s/pt; Ramp 10.00 °C/min to 40.00 °C; Data Off ; Isothermal 1.0 min; Data On ; Sample Interval  2.0 s/pt; Ramp 0.50 °C/min to -50.00 °C; Data Off ; Isothermal 1.0 min; Data On ; Sample Interval  0.1 s/pt; Ramp 10.00 °C/min to 40.00 °C
[File Parameters]
Run date	6/29/2023 11:23:26 AM
Trios version	5.1.1.46572
Original File Name
Current File Name	C:\Users\yargerlab\Desktop\DSC Data\General\2023_06_29_CBD_Fragiity_SBK.tri
[Procedure]
Procedure Name	DSC -50C to 40C Varied cooling rates CBD fragility
Sample Name	2023_06_29_CBD_Fragiity_SBK
Sample Mass	3.95 mg
Reference Sample Mass	0 mg
Pan Mass	53.51 mg
Pan Number	41
Reference Pan Mass	53.66 mg
Reference Pan Number	46
Pan Type	Aluminum Hermetic
Comments	CBD powder, likely crystaline, newly prepared sample. DSC84010 aluminum pan and DSC84011 aluminum hermetic lid.
Project Name	Silk ASDs
Operator	SBK
Test	Custom
Unload Max Temperature	30
Unload Min Temperature	30
Load Max Temperature	30
Load Min Temperature	30
Stop on Gas Flow Error	Yes
[Signal List]
Signal #1	Time (min)
Signal #2	Temperature (°C)
Signal #3	Heat Flow (mW)
Signal #4	Delta T (µV)
Signal #5	Delta Tzero (µV)
Signal #6	Tzero Temperature (°C)
Signal #7	Cell Purge (mL/min)
Signal #8	Heater Temp (°C)
Signal #9	Power Delivered (W)
Signal #10	Reference Junction Temperature (°C)
Signal #11	Flange Temperature (°C)
Signal #12	Heat Flow Phase (rad)
Signal #13	Total Heat Capacity (J/°C)
Signal #14	Heat Capacity (J/°C)
[Configuration]
Company Name	ASU
Instrument Name	DSC2A-00468
Instrument Type	DSC2500
Serial Number	DSC2A-00468
IP	192.168.1.100
Location of Instrument	MRRC
DisplayType	Unknown
Sample Interval 	0.1 s/pt
Selected Heat Flow	T4P
Exotherm Direction	Down
Cell Serial	DRC2-00792
Lid Type	Standard
Cooler	RCS 90
Leave Cooler on at End of Sequence	On
Gas 2	Nitrogen
Gas Selected	Channel 1
Flow Rate	50 mL/min
Secondary Purge	On
Licensed Heat Flow	Heat Flow T4P
Modulation Licensed	Yes
[Versions]
Common IDD Version	1
Cortex Version	VER 2.10.2.31
Driver	5.0.0.6
GDM Version	1.0.3.3
TouchscreenVersion	1.0.0.16145
FEP Version	1.2.1.21
FEP Bootloader	2.0.0.5
AutoSampler Version	2.1.1.26
Auto Sampler Bootloader	2.0.0.5
FCM Version	1.1.0.3
FCM Bootloader	2.0.0.5
[Experiment Logs]
Experiment Log Entry # 1	Data On set to 0
Experiment Log Entry # 3	Equilibrate Segment -50 (C) Started
Experiment Log Entry # 5	Air Cool is off.
Experiment Log Entry # 7	Data On set to 1
Experiment Log Entry # 9	Ramp Segment 10 C/min to 100 Started
Experiment Log Entry # 11	Data On set to 0
Experiment Log Entry # 13	Isothermal Segment 1 min started
Experiment Log Entry # 15	Data On set to 1
Experiment Log Entry # 17	Ramp Segment 10 C/min to -50 Started
Experiment Log Entry # 19	Data On set to 0
Experiment Log Entry # 21	Isothermal Segment 1 min started
Experiment Log Entry # 23	Data On set to 1
Experiment Log Entry # 25	Ramp Segment 10 C/min to 40 Started
Experiment Log Entry # 27	Data On set to 0
Experiment Log Entry # 29	Isothermal Segment 1 min started
Experiment Log Entry # 31	Data On set to 1
Experiment Log Entry # 33	Ramp Segment 35 C/min to -50 Started
Experiment Log Entry # 35	Data On set to 0
Experiment Log Entry # 37	Isothermal Segment 1 min started
Experiment Log Entry # 39	Data On set to 1
Experiment Log Entry # 41	Ramp Segment 10 C/min to 40 Started
Experiment Log Entry # 43	Data On set to 0
Experiment Log Entry # 45	Isothermal Segment 1 min started
Experiment Log Entry # 47	Data On set to 1
Experiment Log Entry # 49	Ramp Segment 25 C/min to -50 Started
Experiment Log Entry # 51	Data On set to 0
Experiment Log Entry # 53	Isothermal Segment 1 min started
Experiment Log Entry # 55	Data On set to 1
Experiment Log Entry # 57	Ramp Segment 10 C/min to 40 Started
Experiment Log Entry # 59	Data On set to 0
Experiment Log Entry # 61	Isothermal Segment 1 min started
Experiment Log Entry # 63	Data On set to 1
Experiment Log Entry # 65	Ramp Segment 20 C/min to -50 Started
Experiment Log Entry # 67	Data On set to 0
Experiment Log Entry # 69	Isothermal Segment 1 min started
Experiment Log Entry # 71	Data On set to 1
Experiment Log Entry # 73	Ramp Segment 10 C/min to 40 Started
Experiment Log Entry # 75	Data On set to 0
Experiment Log Entry # 77	Isothermal Segment 1 min started
Experiment Log Entry # 79	Data On set to 1
Experiment Log Entry # 81	Sampling Rate set to 0.2 sec/pt
Experiment Log Entry # 83	Ramp Segment 5 C/min to -50 Started
Experiment Log Entry # 85	Data On set to 0
Experiment Log Entry # 87	Isothermal Segment 1 min started
Experiment Log Entry # 89	Data On set to 1
Experiment Log Entry # 91	Sampling Rate set to 0.1 sec/pt
Experiment Log Entry # 93	Ramp Segment 10 C/min to 40 Started
Experiment Log Entry # 95	Data On set to 0
Experiment Log Entry # 97	Isothermal Segment 1 min started
Experiment Log Entry # 99	Data On set to 1
Experiment Log Entry # 101	Sampling Rate set to 1 sec/pt
Experiment Log Entry # 103	Ramp Segment 1 C/min to -50 Started
Experiment Log Entry # 105	Data On set to 0
Experiment Log Entry # 107	Isothermal Segment 1 min started
Experiment Log Entry # 109	Data On set to 1
Experiment Log Entry # 111	Sampling Rate set to 0.1 sec/pt
Experiment Log Entry # 113	Ramp Segment 10 C/min to 40 Started
Experiment Log Entry # 115	Data On set to 0
Experiment Log Entry # 117	Isothermal Segment 1 min started
Experiment Log Entry # 119	Data On set to 1
Experiment Log Entry # 121	Sampling Rate set to 2 sec/pt
Experiment Log Entry # 123	Ramp Segment 0.5 C/min to -50 Started
Experiment Log Entry # 125	Data On set to 0
Experiment Log Entry # 127	Isothermal Segment 1 min started
Experiment Log Entry # 129	Data On set to 1
Experiment Log Entry # 131	Sampling Rate set to 0.1 sec/pt
Experiment Log Entry # 133	Ramp Segment 10 C/min to 40 Started
[Method Log]
Method Log Entry # 1	Data Off
Method Log Entry # 2	Equilibrate -50 °C
Method Log Entry # 3	Data On
Method Log Entry # 4	(Ramp 9842) Ramp 10 °C/minute to 100 °C
Method Log Entry # 5	Data Off
Method Log Entry # 6	Isothermal 1 minutes
Method Log Entry # 7	Data On
Method Log Entry # 8	(Ramp 9846) Ramp 10 °C/minute to -50 °C
Method Log Entry # 9	Data Off
Method Log Entry # 10	Isothermal 1 minutes
Method Log Entry # 11	Data On
Method Log Entry # 12	(Ramp 9850) Ramp 10 °C/minute to 40 °C
Method Log Entry # 13	Data Off
Method Log Entry # 14	Isothermal 1 minutes
Method Log Entry # 15	Data On
Method Log Entry # 16	(Ramp 9854) Ramp 35 °C/minute to -50 °C
Method Log Entry # 17	Data Off
Method Log Entry # 18	Isothermal 1 minutes
Method Log Entry # 19	Data On
Method Log Entry # 20	(Ramp 9858) Ramp 10 °C/minute to 40 °C
Method Log Entry # 21	Data Off
Method Log Entry # 22	Isothermal 1 minutes
Method Log Entry # 23	Data On
Method Log Entry # 24	(Ramp 9862) Ramp 25 °C/minute to -50 °C
Method Log Entry # 25	Data Off
Method Log Entry # 26	Isothermal 1 minutes
Method Log Entry # 27	Data On
Method Log Entry # 28	(Ramp 9866) Ramp 10 °C/minute to 40 °C
Method Log Entry # 29	Data Off
Method Log Entry # 30	Isothermal 1 minutes
Method Log Entry # 31	Data On
Method Log Entry # 32	(Ramp 9870) Ramp 20 °C/minute to -50 °C
Method Log Entry # 33	Data Off
Method Log Entry # 34	Isothermal 1 minutes
Method Log Entry # 35	Data On
Method Log Entry # 36	(Ramp 9874) Ramp 10 °C/minute to 40 °C
Method Log Entry # 37	Data Off
Method Log Entry # 38	Isothermal 1 minutes
Method Log Entry # 39	Data On
Method Log Entry # 40	Sampling Interval 0.2 Seconds/point
Method Log Entry # 41	(Ramp 9879) Ramp 5 °C/minute to -50 °C
Method Log Entry # 42	Data Off
Method Log Entry # 43	Isothermal 1 minutes
Method Log Entry # 44	Data On
Method Log Entry # 45	Sampling Interval 0.1 Seconds/point
Method Log Entry # 46	(Ramp 9884) Ramp 10 °C/minute to 40 °C
Method Log Entry # 47	Data Off
Method Log Entry # 48	Isothermal 1 minutes
Method Log Entry # 49	Data On
Method Log Entry # 50	Sampling Interval 1 Seconds/point
Method Log Entry # 51	(Ramp 9889) Ramp 1 °C/minute to -50 °C
Method Log Entry # 52	Data Off
Method Log Entry # 53	Isothermal 1 minutes
Method Log Entry # 54	Data On
Method Log Entry # 55	Sampling Interval 0.1 Seconds/point
Method Log Entry # 56	(Ramp 9894) Ramp 10 °C/minute to 40 °C
Method Log Entry # 57	Data Off
Method Log Entry # 58	Isothermal 1 minutes
Method Log Entry # 59	Data On
Method Log Entry # 60	Sampling Interval 2 Seconds/point
Method Log Entry # 61	(Ramp 9899) Ramp 0.5 °C/minute to -50 °C
Method Log Entry # 62	Data Off
Method Log Entry # 63	Isothermal 1 minutes
Method Log Entry # 64	Data On
Method Log Entry # 65	Sampling Interval 0.1 Seconds/point
Method Log Entry # 66	(Ramp 9904) Ramp 10 °C/minute to 40 °C
Cell Serial	DRC2-00792
[T1 Calibration]
Slope	-0.008529666
Offset	9.636258
Initial Temperature	98.23
GUID	f8bfdadc-4977-4fdf-ba6d-0ba9134940c3
[TZero Calibration]
Date Applied	11/29/2022 4:06:13 PM
Description	From -89.059 °C to 396.009 °C at 20.000°C/min
Gas Type	Nitrogen
Pan Type	None
Source Files 1	C:\Users\yargerlab\Desktop\DSC Data\General\TZero_calibration_11_29_22_2nd(2).tri
Source Files 2	C:\Users\yargerlab\Desktop\DSC Data\General\TZero_calibration_11_29_22_2nd(3).tri
Delta T Offset	13.05235
Delta T Slope	-0.007271007
Delta T0 Offset	-13.69128
Delta T0 Slope	0.06063341
[Temperature Calibration]
Date Applied	11/29/2022 7:12:28 PM
Description	From 106.590 °C to 186.590 °C at 10.000°C/min
Gas Type	Nitrogen
Pan Type	Tzero Aluminum Hermetic
Source Files 1	C:\Users\yargerlab\Desktop\DSC Data\General\Indium(6).tri
Measured 1	157.391
Known 1	156.598
[Cell Constant Calibration]
Date Applied	11/29/2022 7:12:29 PM
Description	From 106.590 °C to 186.590 °C at 10.000°C/min
Gas Type	Nitrogen
Pan Type	Tzero Aluminum Hermetic
Source Files 1	C:\Users\yargerlab\Desktop\DSC Data\General\Indium(6).tri
T4P KCell	1.006051
Onset Slope	63.26126 mW/°C
[Direct Cp Calibration]
Date Applied	11/30/2022 11:04:51 AM
Description	From -79.983 °C to 298.409 °C at 10.000°C/min
Gas Type	Nitrogen
Pan Type	Tzero Aluminum Hermetic
Source Files 1	C:\Users\yargerlab\Desktop\DSC Data\General\Sapphire_Heat_Capacity_11_30_22.tri
[Rev Cp Calibration]
Date Applied	11/30/2022 1:58:51 PM
Description	From -79.996 °C to 292.812 °C at 3.000°C/min
Gas Type	Nitrogen
Pan Type	Tzero Aluminum Hermetic
Source Files 1	C:\Users\yargerlab\Desktop\DSC Data\General\Sapphire_MDSC_Calibration_11_30_22.tri
[step]
Ramp 10.00 °C/min to 100.00 °C
Time	Temperature	Heat Flow (Normalized)
min	°C	W/g
0.00	-49.73	-0.048
0.01	-49.74	-0.048
0.02	-49.74	-0.045
0.03	-49.75	-0.043
0.04	-49.75	-0.039
0.05	-49.75	-0.036
0.06	-49.74	-0.033
0.07	-49.74	-0.031
0.08	-49.73	-0.029
0.09	-49.71	-0.027
0.10	-49.68	-0.025
0.11	-49.65	-0.022
0.12	-49.61	-0.018
0.13	-49.57	-0.013
0.14	-49.52	-0.006
0.15	-49.47	0.004
0.16	-49.41	0.015
0.17	-49.35	0.024
0.18	-49.29	0.036
0.19	-49.22	0.048
0.20	-49.14	0.059
0.21	-49.07	0.069
0.22	-48.99	0.082
0.23	-48.92	0.092
0.24	-48.84	0.103
0.25	-48.76	0.111
0.26	-48.67	0.120
0.27	-48.59	0.128
0.28	-48.50	0.136
0.29	-48.42	0.142
0.30	-48.33	0.148
0.31	-48.25	0.153
0.32	-48.16	0.159
0.33	-48.07	0.162
0.34	-47.98	0.169
0.35	-47.89	0.170
0.36	-47.80	0.175
0.37	-47.70	0.179
0.38	-47.61	0.182
0.39	-47.52	0.184
0.40	-47.43	0.187
0.41	-47.33	0.189
0.42	-47.24	0.192
0.43	-47.14	0.195
0.44	-47.05	0.196
0.45	-46.95	0.198
0.46	-46.86	0.198
0.47	-46.76	0.201
0.48	-46.67	0.202
0.49	-46.57	0.203
0.50	-46.48	0.204
0.51	-46.38	0.204
0.52	-46.28	0.206
0.53	-46.19	0.208
0.54	-46.09	0.208
0.55	-45.99	0.209
0.56	-45.90	0.209
0.57	-45.80	0.210
0.58	-45.70	0.210
0.59	-45.60	0.210
0.60	-45.51	0.211
0.61	-45.41	0.211
0.62	-45.31	0.212
0.63	-45.22	0.212
0.64	-45.12	0.212
0.65	-45.02	0.212
0.66	-44.92	0.213
0.67	-44.82	0.213
0.68	-44.73	0.213
0.69	-44.63	0.213
0.70	-44.53	0.214
0.71	-44.43	0.214
0.72	-44.33	0.214
0.73	-44.23	0.214
0.74	-44.14	0.215
0.75	-44.04	0.215
0.76	-43.94	0.215
0.77	-43.84	0.215
0.78	-43.74	0.215
0.79	-43.65	0.216
0.80	-43.55	0.216
0.81	-43.45	0.216
0.82	-43.35	0.216
0.83	-43.25	0.216
0.84	-43.15	0.217
0.85	-43.05	0.217
0.86	-42.95	0.217
0.87	-42.86	0.217
0.88	-42.76	0.217
0.89	-42.66	0.217
0.90	-42.56	0.218
0.91	-42.46	0.218
0.92	-42.36	0.218
0.93	-42.26	0.218
0.94	-42.16	0.218
0.95	-42.06	0.218
0.96	-41.96	0.218
0.97	-41.87	0.219
0.98	-41.77	0.219
0.99	-41.67	0.219
1.00	-41.57	0.219
1.01	-41.47	0.219
1.02	-41.37	0.219
1.03	-41.27	0.219
1.04	-41.17	0.219
1.05	-41.07	0.219
1.06	-40.97	0.219
1.07	-40.87	0.219
1.08	-40.77	0.220
1.09	-40.67	0.220
1.10	-40.57	0.220
1.11	-40.47	0.220
1.12	-40.38	0.220
1.13	-40.28	0.220
1.14	-40.18	0.220
1.15	-40.08	0.220
1.16	-39.98	0.220
1.17	-39.88	0.220
1.18	-39.78	0.220
1.19	-39.68	0.220
1.20	-39.58	0.220
1.21	-39.48	0.220
1.22	-39.38	0.220
1.23	-39.28	0.220
1.24	-39.18	0.220
1.25	-39.08	0.220
1.26	-38.98	0.220
1.27	-38.88	0.221
1.28	-38.78	0.221
1.29	-38.68	0.221
1.30	-38.58	0.221
1.31	-38.48	0.221
1.32	-38.38	0.221
1.33	-38.28	0.221
1.34	-38.18	0.221
1.35	-38.08	0.221
1.36	-37.99	0.221
1.37	-37.88	0.221
1.38	-37.78	0.221
1.39	-37.69	0.221
1.40	-37.59	0.221
1.41	-37.48	0.221
1.42	-37.38	0.221
1.43	-37.29	0.221
1.44	-37.19	0.221
1.45	-37.09	0.221
1.46	-36.99	0.221
1.47	-36.89	0.221
1.48	-36.79	0.221
1.49	-36.69	0.221
1.50	-36.59	0.221
1.51	-36.49	0.221
1.52	-36.39	0.221
1.53	-36.29	0.221
1.54	-36.19	0.221
1.55	-36.09	0.221
1.56	-35.99	0.221
1.57	-35.89	0.221
1.58	-35.79	0.221
1.59	-35.69	0.221
1.60	-35.59	0.221
1.61	-35.49	0.221
1.62	-35.39	0.221
1.63	-35.29	0.221
1.64	-35.19	0.221
1.65	-35.09	0.221
1.66	-34.99	0.221
1.67	-34.89	0.221
1.68	-34.79	0.221
1.69	-34.69	0.221
1.70	-34.59	0.221
1.71	-34.49	0.221
1.72	-34.39	0.221
1.73	-34.29	0.221
1.74	-34.19	0.221
1.75	-34.09	0.222
1.76	-33.99	0.221
1.77	-33.89	0.221
1.78	-33.79	0.221
1.79	-33.69	0.221
1.80	-33.59	0.221
1.81	-33.49	0.221
1.82	-33.39	0.221
1.83	-33.29	0.221
1.84	-33.19	0.221
1.85	-33.09	0.221
1.86	-32.99	0.221
1.87	-32.89	0.221
1.88	-32.79	0.221
1.89	-32.69	0.221
1.90	-32.59	0.221
1.91	-32.49	0.221
1.92	-32.39	0.221
1.93	-32.29	0.221
1.94	-32.19	0.221
1.95	-32.09	0.222
1.96	-31.99	0.222
1.97	-31.89	0.222
1.98	-31.79	0.222
1.99	-31.69	0.222
2.00	-31.59	0.222
2.01	-31.49	0.222
2.02	-31.39	0.222
2.03	-31.29	0.222
2.04	-31.19	0.222
2.05	-31.09	0.222
2.06	-30.99	0.222
2.07	-30.89	0.222
2.08	-30.79	0.222
2.09	-30.69	0.222
2.10	-30.59	0.222
2.11	-30.49	0.222
2.12	-30.39	0.222
2.13	-30.29	0.222
2.14	-30.19	0.222
2.15	-30.09	0.222
2.16	-29.99	0.222
2.17	-29.89	0.222
2.18	-29.79	0.222
2.19	-29.68	0.222
2.20	-29.59	0.222
2.21	-29.48	0.222
2.22	-29.38	0.222
2.23	-29.29	0.222
2.24	-29.19	0.222
2.25	-29.09	0.222
2.26	-28.98	0.222
2.27	-28.89	0.222
2.28	-28.78	0.222
2.29	-28.68	0.222
2.30	-28.58	0.222
2.31	-28.48	0.222
2.32	-28.38	0.222
2.33	-28.28	0.222
2.34	-28.18	0.222
2.35	-28.08	0.222
2.36	-27.98	0.222
2.37	-27.88	0.222
2.38	-27.78	0.222
2.39	-27.68	0.222
2.40	-27.58	0.222
2.41	-27.48	0.222
2.42	-27.38	0.222
2.43	-27.28	0.222
2.44	-27.18	0.222
2.45	-27.08	0.222
2.46	-26.98	0.222
2.47	-26.88	0.222
2.48	-26.78	0.222
2.49	-26.68	0.222
2.50	-26.58	0.222
2.51	-26.48	0.222
2.52	-26.38	0.222
2.53	-26.28	0.222
2.54	-26.18	0.222
2.55	-26.08	0.222
2.56	-25.98	0.222
2.57	-25.88	0.222
2.58	-25.78	0.222
2.59	-25.68	0.222
2.60	-25.58	0.222
2.61	-25.48	0.222
2.62	-25.38	0.222
2.63	-25.28	0.222
2.64	-25.18	0.222
2.65	-25.08	0.222
2.66	-24.98	0.222
2.67	-24.88	0.222
2.68	-24.78	0.222
2.69	-24.68	0.222
2.70	-24.58	0.222
2.71	-24.48	0.222
2.72	-24.38	0.222
2.73	-24.28	0.222
2.74	-24.18	0.222
2.75	-24.08	0.222
2.76	-23.98	0.222
2.77	-23.88	0.222
2.78	-23.78	0.222
2.79	-23.68	0.222
2.80	-23.58	0.222
2.81	-23.48	0.222
2.82	-23.38	0.222
2.83	-23.28	0.222
2.84	-23.18	0.222
2.85	-23.08	0.223
2.86	-22.98	0.223
2.87	-22.88	0.222
2.88	-22.78	0.223
2.89	-22.68	0.223
2.90	-22.58	0.223
2.91	-22.48	0.223
2.92	-22.38	0.223
2.93	-22.28	0.223
2.94	-22.18	0.223
2.95	-22.08	0.223
2.96	-21.98	0.223
2.97	-21.87	0.223
2.98	-21.78	0.222
2.99	-21.67	0.222
3.00	-21.58	0.222
3.01	-21.48	0.223
3.02	-21.38	0.223
3.03	-21.27	0.223
3.04	-21.17	0.223
3.05	-21.08	0.223
3.06	-20.97	0.223
3.07	-20.88	0.223
3.08	-20.77	0.223
3.09	-20.67	0.223
3.10	-20.57	0.223
3.11	-20.47	0.223
3.12	-20.37	0.223
3.13	-20.27	0.223
3.14	-20.17	0.223
3.15	-20.07	0.223
3.16	-19.97	0.223
3.17	-19.87	0.223
3.18	-19.77	0.223
3.19	-19.67	0.223
3.20	-19.57	0.223
3.21	-19.47	0.223
3.22	-19.37	0.223
3.23	-19.27	0.223
3.24	-19.17	0.223
3.25	-19.07	0.223
3.26	-18.97	0.223
3.27	-18.87	0.223
3.28	-18.77	0.223
3.29	-18.67	0.223
3.30	-18.57	0.223
3.31	-18.47	0.223
3.32	-18.37	0.223
3.33	-18.27	0.223
3.34	-18.17	0.223
3.35	-18.07	0.223
3.36	-17.97	0.223
3.37	-17.87	0.223
3.38	-17.77	0.223
3.39	-17.67	0.223
3.40	-17.57	0.223
3.41	-17.47	0.223
3.42	-17.37	0.223
3.43	-17.27	0.223
3.44	-17.17	0.223
3.45	-17.07	0.223
3.46	-16.97	0.223
3.47	-16.87	0.223
3.48	-16.77	0.223
3.49	-16.67	0.223
3.50	-16.57	0.223
3.51	-16.47	0.223
3.52	-16.37	0.223
3.53	-16.27	0.223
3.54	-16.17	0.223
3.55	-16.07	0.223
3.56	-15.97	0.223
3.57	-15.87	0.223
3.58	-15.77	0.223
3.59	-15.67	0.223
3.60	-15.57	0.223
3.61	-15.47	0.223
3.62	-15.37	0.223
3.63	-15.27	0.223
3.64	-15.17	0.223
3.65	-15.07	0.223
3.66	-14.97	0.223
3.67	-14.87	0.223
3.68	-14.77	0.223
3.69	-14.67	0.223
3.70	-14.57	0.223
3.71	-14.47	0.223
3.72	-14.37	0.223
3.73	-14.27	0.223
3.74	-14.17	0.223
3.75	-14.06	0.223
3.76	-13.96	0.223
3.77	-13.86	0.223
3.78	-13.76	0.224
3.79	-13.66	0.223
3.80	-13.57	0.224
3.81	-13.46	0.224
3.82	-13.36	0.224
3.83	-13.26	0.224
3.84	-13.16	0.224
3.85	-13.07	0.224
3.86	-12.96	0.224
3.87	-12.86	0.224
3.88	-12.76	0.224
3.89	-12.66	0.224
3.90	-12.56	0.224
3.91	-12.46	0.224
3.92	-12.36	0.224
3.93	-12.26	0.224
3.94	-12.16	0.224
3.95	-12.06	0.224
3.96	-11.96	0.224
3.97	-11.86	0.224
3.98	-11.76	0.224
3.99	-11.66	0.224
4.00	-11.56	0.224
4.01	-11.46	0.224
4.02	-11.36	0.224
4.03	-11.26	0.224
4.04	-11.16	0.224
4.05	-11.06	0.224
4.06	-10.96	0.224
4.07	-10.86	0.224
4.08	-10.76	0.224
4.09	-10.66	0.224
4.10	-10.56	0.224
4.11	-10.46	0.224
4.12	-10.36	0.224
4.13	-10.26	0.224
4.14	-10.16	0.224
4.15	-10.06	0.224
4.16	-9.96	0.224
4.17	-9.86	0.224
4.18	-9.76	0.224
4.19	-9.66	0.224
4.20	-9.56	0.224
4.21	-9.46	0.225
4.22	-9.36	0.225
4.23	-9.26	0.225
4.24	-9.16	0.225
4.25	-9.06	0.225
4.26	-8.96	0.225
4.27	-8.86	0.225
4.28	-8.76	0.225
4.29	-8.66	0.225
4.30	-8.56	0.225
4.31	-8.46	0.225
4.32	-8.36	0.225
4.33	-8.26	0.225
4.34	-8.16	0.225
4.35	-8.06	0.225
4.36	-7.96	0.225
4.37	-7.86	0.225
4.38	-7.76	0.225
4.39	-7.66	0.225
4.40	-7.56	0.225
4.41	-7.46	0.225
4.42	-7.36	0.225
4.43	-7.26	0.225
4.44	-7.16	0.225
4.45	-7.06	0.225
4.46	-6.96	0.225
4.47	-6.86	0.225
4.48	-6.76	0.225
4.49	-6.66	0.226
4.50	-6.56	0.226
4.51	-6.46	0.226
4.52	-6.36	0.226
4.53	-6.26	0.226
4.54	-6.15	0.226
4.55	-6.06	0.226
4.56	-5.95	0.226
4.57	-5.85	0.226
4.58	-5.75	0.226
4.59	-5.65	0.226
4.60	-5.55	0.226
4.61	-5.46	0.226
4.62	-5.36	0.226
4.63	-5.26	0.226
4.64	-5.15	0.226
4.65	-5.05	0.226
4.66	-4.95	0.226
4.67	-4.85	0.226
4.68	-4.75	0.226
4.69	-4.65	0.226
4.70	-4.55	0.226
4.71	-4.45	0.226
4.72	-4.35	0.226
4.73	-4.25	0.227
4.74	-4.15	0.227
4.75	-4.05	0.227
4.76	-3.95	0.227
4.77	-3.85	0.227
4.78	-3.75	0.227
4.79	-3.65	0.227
4.80	-3.55	0.227
4.81	-3.45	0.227
4.82	-3.35	0.227
4.83	-3.25	0.227
4.84	-3.15	0.227
4.85	-3.05	0.227
4.86	-2.95	0.227
4.87	-2.85	0.227
4.88	-2.75	0.227
4.89	-2.65	0.227
4.90	-2.55	0.227
4.91	-2.45	0.227
4.92	-2.35	0.227
4.93	-2.25	0.227
4.94	-2.15	0.227
4.95	-2.05	0.227
4.96	-1.95	0.227
4.97	-1.85	0.227
4.98	-1.75	0.227
4.99	-1.65	0.227
5.00	-1.55	0.227
5.01	-1.45	0.227
5.02	-1.35	0.228
5.03	-1.25	0.228
5.04	-1.15	0.228
5.05	-1.05	0.228
5.06	-0.95	0.228
5.07	-0.85	0.228
5.08	-0.75	0.228
5.09	-0.65	0.228
5.10	-0.55	0.228
5.11	-0.45	0.228
5.12	-0.35	0.228
5.13	-0.25	0.228
5.14	-0.15	0.228
5.15	-0.05	0.228
5.16	0.05	0.228
5.17	0.15	0.228
5.18	0.26	0.228
5.19	0.36	0.228
5.20	0.45	0.228
5.21	0.55	0.228
5.22	0.65	0.228
5.23	0.75	0.228
5.24	0.85	0.228
5.25	0.96	0.228
5.26	1.05	0.228
5.27	1.16	0.228
5.28	1.26	0.228
5.29	1.35	0.228
5.30	1.46	0.228
5.31	1.56	0.229
5.32	1.66	0.229
5.33	1.75	0.229
5.34	1.86	0.229
5.35	1.96	0.229
5.36	2.06	0.229
5.37	2.16	0.229
5.38	2.26	0.229
5.39	2.36	0.229
5.40	2.46	0.229
5.41	2.56	0.229
5.42	2.66	0.229
5.43	2.76	0.229
5.44	2.86	0.229
5.45	2.96	0.229
5.46	3.06	0.229
5.47	3.16	0.229
5.48	3.26	0.229
5.49	3.36	0.229
5.50	3.46	0.229
5.51	3.56	0.229
5.52	3.66	0.229
5.53	3.76	0.230
5.54	3.86	0.230
5.55	3.96	0.230
5.56	4.06	0.230
5.57	4.16	0.230
5.58	4.26	0.230
5.59	4.36	0.230
5.60	4.46	0.230
5.61	4.56	0.230
5.62	4.66	0.230
5.63	4.76	0.230
5.64	4.86	0.230
5.65	4.96	0.230
5.66	5.06	0.230
5.67	5.16	0.230
5.68	5.26	0.230
5.69	5.36	0.230
5.70	5.46	0.230
5.71	5.56	0.231
5.72	5.66	0.231
5.73	5.76	0.231
5.74	5.86	0.231
5.75	5.96	0.231
5.76	6.06	0.231
5.77	6.16	0.231
5.78	6.26	0.231
5.79	6.36	0.231
5.80	6.46	0.231
5.81	6.56	0.231
5.82	6.66	0.231
5.83	6.76	0.231
5.84	6.86	0.231
5.85	6.96	0.231
5.86	7.06	0.231
5.87	7.16	0.231
5.88	7.26	0.231
5.89	7.36	0.231
5.90	7.46	0.232
5.91	7.56	0.232
5.92	7.66	0.232
5.93	7.76	0.232
5.94	7.86	0.232
5.95	7.96	0.232
5.96	8.06	0.232
5.97	8.16	0.232
5.98	8.26	0.232
5.99	8.36	0.232
6.00	8.47	0.232
6.01	8.57	0.232
6.02	8.67	0.232
6.03	8.77	0.232
6.04	8.87	0.232
6.05	8.97	0.232
6.06	9.07	0.232
6.07	9.17	0.233
6.08	9.27	0.233
6.09	9.37	0.233
6.10	9.47	0.233
6.11	9.57	0.233
6.12	9.67	0.233
6.13	9.77	0.233
6.14	9.87	0.233
6.15	9.97	0.233
6.16	10.07	0.233
6.17	10.17	0.233
6.18	10.27	0.233
6.19	10.37	0.233
6.20	10.47	0.233
6.21	10.57	0.233
6.22	10.67	0.233
6.23	10.77	0.234
6.24	10.87	0.234
6.25	10.97	0.234
6.26	11.07	0.234
6.27	11.17	0.234
6.28	11.27	0.234
6.29	11.37	0.234
6.30	11.47	0.234
6.31	11.57	0.234
6.32	11.67	0.234
6.33	11.77	0.234
6.34	11.87	0.234
6.35	11.97	0.234
6.36	12.07	0.234
6.37	12.17	0.234
6.38	12.27	0.234
6.39	12.37	0.234
6.40	12.47	0.234
6.41	12.57	0.234
6.42	12.67	0.234
6.43	12.77	0.234
6.44	12.87	0.234
6.45	12.97	0.234
6.46	13.07	0.234
6.47	13.17	0.234
6.48	13.27	0.234
6.49	13.37	0.234
6.50	13.47	0.234
6.51	13.57	0.234
6.52	13.67	0.234
6.53	13.77	0.235
6.54	13.87	0.235
6.55	13.97	0.235
6.56	14.07	0.235
6.57	14.17	0.235
6.58	14.27	0.235
6.59	14.37	0.235
6.60	14.47	0.235
6.61	14.57	0.235
6.62	14.67	0.235
6.63	14.77	0.235
6.64	14.87	0.235
6.65	14.97	0.235
6.66	15.07	0.235
6.67	15.17	0.236
6.68	15.27	0.236
6.69	15.37	0.236
6.70	15.47	0.236
6.71	15.57	0.236
6.72	15.67	0.236
6.73	15.77	0.236
6.74	15.87	0.236
6.75	15.97	0.236
6.76	16.07	0.236
6.77	16.17	0.236
6.78	16.27	0.236
6.79	16.37	0.236
6.80	16.47	0.236
6.81	16.57	0.236
6.82	16.67	0.236
6.83	16.77	0.237
6.84	16.87	0.237
6.85	16.97	0.237
6.86	17.07	0.237
6.87	17.18	0.237
6.88	17.28	0.237
6.89	17.37	0.237
6.90	17.48	0.237
6.91	17.57	0.237
6.92	17.68	0.237
6.93	17.78	0.237
6.94	17.87	0.237
6.95	17.98	0.237
6.96	18.08	0.237
6.97	18.18	0.237
6.98	18.28	0.238
6.99	18.38	0.238
7.00	18.48	0.238
7.01	18.58	0.238
7.02	18.68	0.238
7.03	18.78	0.238
7.04	18.88	0.238
7.05	18.98	0.238
7.06	19.08	0.238
7.07	19.18	0.238
7.08	19.28	0.238
7.09	19.38	0.238
7.10	19.48	0.238
7.11	19.58	0.238
7.12	19.68	0.238
7.13	19.78	0.239
7.14	19.88	0.239
7.15	19.98	0.239
7.16	20.08	0.239
7.17	20.18	0.239
7.18	20.28	0.239
7.19	20.38	0.239
7.20	20.48	0.239
7.21	20.58	0.239
7.22	20.68	0.239
7.23	20.78	0.239
7.24	20.88	0.239
7.25	20.98	0.239
7.26	21.08	0.239
7.27	21.18	0.239
7.28	21.28	0.240
7.29	21.38	0.240
7.30	21.48	0.240
7.31	21.58	0.240
7.32	21.68	0.240
7.33	21.78	0.240
7.34	21.88	0.240
7.35	21.98	0.240
7.36	22.08	0.240
7.37	22.18	0.240
7.38	22.28	0.240
7.39	22.38	0.240
7.40	22.48	0.240
7.41	22.58	0.240
7.42	22.68	0.240
7.43	22.78	0.241
7.44	22.88	0.241
7.45	22.98	0.241
7.46	23.08	0.241
7.47	23.18	0.241
7.48	23.28	0.241
7.49	23.38	0.241
7.50	23.48	0.241
7.51	23.58	0.241
7.52	23.68	0.241
7.53	23.78	0.241
7.54	23.88	0.241
7.55	23.98	0.241
7.56	24.08	0.241
7.57	24.18	0.241
7.58	24.28	0.242
7.59	24.38	0.242
7.60	24.48	0.242
7.61	24.58	0.242
7.62	24.68	0.242
7.63	24.78	0.242
7.64	24.88	0.242
7.65	24.98	0.242
7.66	25.08	0.242
7.67	25.18	0.242
7.68	25.28	0.242
7.69	25.38	0.242
7.70	25.49	0.242
7.71	25.59	0.242
7.72	25.68	0.242
7.73	25.78	0.242
7.74	25.89	0.243
7.75	25.99	0.243
7.76	26.09	0.243
7.77	26.19	0.243
7.78	26.29	0.243
7.79	26.39	0.243
7.80	26.49	0.243
7.81	26.59	0.243
7.82	26.69	0.243
7.83	26.79	0.244
7.84	26.89	0.244
7.85	26.99	0.244
7.86	27.09	0.244
7.87	27.19	0.244
7.88	27.29	0.244
7.89	27.39	0.244
7.90	27.49	0.244
7.91	27.59	0.244
7.92	27.69	0.244
7.93	27.79	0.244
7.94	27.89	0.244
7.95	27.99	0.244
7.96	28.09	0.244
7.97	28.19	0.244
7.98	28.29	0.244
7.99	28.39	0.245
8.00	28.49	0.245
8.01	28.59	0.245
8.02	28.69	0.245
8.03	28.79	0.245
8.04	28.89	0.245
8.05	28.99	0.245
8.06	29.09	0.245
8.07	29.19	0.245
8.08	29.29	0.245
8.09	29.39	0.245
8.10	29.49	0.245
8.11	29.59	0.245
8.12	29.69	0.246
8.13	29.79	0.246
8.14	29.89	0.246
8.15	29.99	0.246
8.16	30.09	0.246
8.17	30.19	0.246
8.18	30.29	0.246
8.19	30.39	0.246
8.20	30.49	0.246
8.21	30.59	0.246
8.22	30.69	0.246
8.23	30.79	0.246
8.24	30.89	0.246
8.25	30.99	0.246
8.26	31.09	0.246
8.27	31.19	0.246
8.28	31.29	0.247
8.29	31.39	0.247
8.30	31.49	0.247
8.31	31.59	0.247
8.32	31.69	0.247
8.33	31.79	0.247
8.34	31.89	0.247
8.35	31.99	0.247
8.36	32.09	0.247
8.37	32.19	0.247
8.38	32.29	0.247
8.39	32.39	0.247
8.40	32.49	0.247
8.41	32.59	0.247
8.42	32.69	0.248
8.43	32.79	0.248
8.44	32.89	0.248
8.45	32.99	0.248
8.46	33.09	0.248
8.47	33.19	0.248
8.48	33.29	0.248
8.49	33.39	0.248
8.50	33.50	0.248
8.51	33.59	0.248
8.52	33.69	0.248
8.53	33.80	0.248
8.54	33.90	0.248
8.55	34.00	0.249
8.56	34.10	0.249
8.57	34.20	0.249
8.58	34.30	0.249
8.59	34.40	0.249
8.60	34.49	0.249
8.61	34.59	0.249
8.62	34.70	0.249
8.63	34.80	0.249
8.64	34.90	0.249
8.65	35.00	0.249
8.66	35.10	0.249
8.67	35.20	0.249
8.68	35.30	0.249
8.69	35.40	0.249
8.70	35.50	0.249
8.71	35.60	0.249
8.72	35.70	0.250
8.73	35.80	0.250
8.74	35.90	0.250
8.75	36.00	0.250
8.76	36.10	0.250
8.77	36.20	0.250
8.78	36.30	0.250
8.79	36.40	0.250
8.80	36.50	0.250
8.81	36.60	0.250
8.82	36.70	0.250
8.83	36.80	0.250
8.84	36.90	0.250
8.85	37.00	0.250
8.86	37.10	0.251
8.87	37.20	0.251
8.88	37.30	0.251
8.89	37.40	0.251
8.90	37.50	0.251
8.91	37.60	0.251
8.92	37.70	0.251
8.93	37.80	0.251
8.94	37.90	0.251
8.95	38.00	0.251
8.96	38.10	0.251
8.97	38.20	0.251
8.98	38.30	0.251
8.99	38.40	0.251
9.00	38.50	0.251
9.01	38.60	0.252
9.02	38.70	0.252
9.03	38.80	0.252
9.04	38.90	0.252
9.05	39.00	0.252
9.06	39.10	0.252
9.07	39.20	0.252
9.08	39.30	0.252
9.09	39.40	0.252
9.10	39.50	0.252
9.11	39.60	0.252
9.12	39.70	0.252
9.13	39.80	0.253
9.14	39.90	0.253
9.15	40.00	0.253
9.16	40.10	0.253
9.17	40.20	0.253
9.18	40.30	0.253
9.19	40.40	0.253
9.20	40.50	0.253
9.21	40.60	0.253
9.22	40.70	0.253
9.23	40.80	0.253
9.24	40.90	0.253
9.25	41.00	0.253
9.26	41.10	0.253
9.27	41.20	0.254
9.28	41.30	0.254
9.29	41.40	0.254
9.30	41.50	0.254
9.31	41.60	0.254
9.32	41.70	0.254
9.33	41.80	0.254
9.34	41.90	0.254
9.35	42.00	0.254
9.36	42.10	0.254
9.37	42.20	0.254
9.38	42.30	0.254
9.39	42.40	0.254
9.40	42.50	0.254
9.41	42.60	0.254
9.42	42.70	0.255
9.43	42.80	0.255
9.44	42.90	0.255
9.45	43.01	0.255
9.46	43.11	0.255
9.47	43.21	0.255
9.48	43.31	0.255
9.49	43.41	0.255
9.50	43.51	0.255
9.51	43.61	0.255
9.52	43.71	0.255
9.53	43.81	0.255
9.54	43.91	0.256
9.55	44.01	0.256
9.56	44.11	0.256
9.57	44.21	0.256
9.58	44.31	0.256
9.59	44.41	0.256
9.60	44.51	0.256
9.61	44.61	0.256
9.62	44.71	0.256
9.63	44.81	0.256
9.64	44.91	0.256
9.65	45.01	0.256
9.66	45.11	0.256
9.67	45.21	0.257
9.68	45.31	0.257
9.69	45.41	0.257
9.70	45.51	0.257
9.71	45.61	0.257
9.72	45.71	0.257
9.73	45.81	0.257
9.74	45.91	0.257
9.75	46.01	0.257
9.76	46.11	0.257
9.77	46.21	0.258
9.78	46.31	0.258
9.79	46.41	0.258
9.80	46.51	0.258
9.81	46.61	0.258
9.82	46.71	0.258
9.83	46.81	0.258
9.84	46.91	0.258
9.85	47.01	0.258
9.86	47.11	0.258
9.87	47.21	0.258
9.88	47.31	0.258
9.89	47.41	0.259
9.90	47.51	0.259
9.91	47.61	0.259
9.92	47.71	0.259
9.93	47.81	0.259
9.94	47.91	0.259
9.95	48.01	0.259
9.96	48.11	0.259
9.97	48.21	0.259
9.98	48.31	0.259
9.99	48.41	0.259
10.00	48.51	0.260
10.01	48.61	0.260
10.02	48.71	0.260
10.03	48.81	0.260
10.04	48.91	0.260
10.05	49.01	0.260
10.06	49.11	0.260
10.07	49.21	0.260
10.08	49.31	0.260
10.09	49.41	0.260
10.10	49.51	0.260
10.11	49.61	0.261
10.12	49.71	0.261
10.13	49.81	0.261
10.14	49.91	0.261
10.15	50.01	0.261
10.16	50.11	0.261
10.17	50.21	0.261
10.18	50.31	0.261
10.19	50.41	0.261
10.20	50.51	0.261
10.21	50.61	0.261
10.22	50.71	0.262
10.23	50.81	0.262
10.24	50.91	0.262
10.25	51.01	0.262
10.26	51.11	0.262
10.27	51.21	0.262
10.28	51.31	0.262
10.29	51.41	0.262
10.30	51.51	0.262
10.31	51.61	0.262
10.32	51.71	0.262
10.33	51.82	0.263
10.34	51.91	0.263
10.35	52.01	0.263
10.36	52.11	0.263
10.37	52.21	0.263
10.38	52.31	0.263
10.39	52.42	0.263
10.40	52.52	0.263
10.41	52.62	0.263
10.42	52.71	0.264
10.43	52.82	0.264
10.44	52.92	0.264
10.45	53.02	0.264
10.46	53.12	0.264
10.47	53.22	0.264
10.48	53.32	0.264
10.49	53.41	0.264
10.50	53.52	0.264
10.51	53.62	0.264
10.52	53.72	0.265
10.53	53.81	0.265
10.54	53.92	0.265
10.55	54.02	0.265
10.56	54.12	0.265
10.57	54.22	0.265
10.58	54.32	0.266
10.59	54.42	0.266
10.60	54.52	0.266
10.61	54.62	0.266
10.62	54.72	0.266
10.63	54.82	0.266
10.64	54.92	0.266
10.65	55.02	0.267
10.66	55.12	0.267
10.67	55.22	0.267
10.68	55.32	0.267
10.69	55.42	0.267
10.70	55.52	0.267
10.71	55.62	0.267
10.72	55.72	0.268
10.73	55.82	0.268
10.74	55.92	0.268
10.75	56.02	0.268
10.76	56.12	0.268
10.77	56.22	0.268
10.78	56.32	0.268
10.79	56.42	0.269
10.80	56.52	0.269
10.81	56.62	0.269
10.82	56.72	0.269
10.83	56.82	0.269
10.84	56.92	0.269
10.85	57.02	0.270
10.86	57.12	0.270
10.87	57.22	0.270
10.88	57.32	0.270
10.89	57.42	0.271
10.90	57.52	0.271
10.91	57.62	0.271
10.92	57.72	0.271
10.93	57.82	0.272
10.94	57.92	0.272
10.95	58.02	0.272
10.96	58.12	0.272
10.97	58.22	0.273
10.98	58.32	0.273
10.99	58.42	0.273
11.00	58.52	0.273
11.01	58.62	0.274
11.02	58.72	0.274
11.03	58.82	0.274
11.04	58.92	0.275
11.05	59.02	0.275
11.06	59.12	0.276
11.07	59.22	0.276
11.08	59.32	0.277
11.09	59.42	0.277
11.10	59.52	0.277
11.11	59.62	0.278
11.12	59.72	0.278
11.13	59.82	0.278
11.14	59.92	0.279
11.15	60.02	0.280
11.16	60.12	0.281
11.17	60.22	0.282
11.18	60.32	0.283
11.19	60.42	0.284
11.20	60.52	0.284
11.21	60.62	0.286
11.22	60.72	0.286
11.23	60.82	0.288
11.24	60.92	0.290
11.25	61.02	0.292
11.26	61.12	0.293
11.27	61.22	0.295
11.28	61.32	0.299
11.29	61.42	0.300
11.30	61.52	0.303
11.31	61.62	0.306
11.32	61.72	0.306
11.33	61.82	0.308
11.34	61.92	0.313
11.35	62.01	0.315
11.36	62.11	0.318
11.37	62.21	0.321
11.38	62.31	0.325
11.39	62.41	0.329
11.40	62.51	0.332
11.41	62.61	0.336
11.42	62.71	0.344
11.43	62.81	0.347
11.44	62.91	0.351
11.45	63.01	0.362
11.46	63.11	0.365
11.47	63.21	0.374
11.48	63.30	0.380
11.49	63.40	0.389
11.50	63.50	0.399
11.51	63.60	0.409
11.52	63.70	0.421
11.53	63.80	0.433
11.54	63.89	0.447
11.55	63.99	0.464
11.56	64.09	0.481
11.57	64.18	0.502
11.58	64.28	0.523
11.59	64.38	0.546
11.60	64.47	0.574
11.61	64.57	0.605
11.62	64.66	0.635
11.63	64.75	0.670
11.64	64.85	0.709
11.65	64.94	0.752
11.66	65.03	0.804
11.67	65.12	0.856
11.68	65.21	0.917
11.69	65.30	0.981
11.70	65.39	1.051
11.71	65.47	1.130
11.72	65.56	1.218
11.73	65.64	1.319
11.74	65.72	1.425
11.75	65.80	1.531
11.76	65.88	1.637
11.77	65.95	1.748
11.78	66.03	1.865
11.79	66.10	1.967
11.80	66.18	2.075
11.81	66.25	2.194
11.82	66.33	2.283
11.83	66.40	2.399
11.84	66.47	2.527
11.85	66.54	2.638
11.86	66.61	2.736
11.87	66.69	2.810
11.88	66.76	2.884
11.89	66.83	2.952
11.90	66.91	3.005
11.91	66.99	3.034
11.92	67.07	3.042
11.93	67.16	3.033
11.94	67.24	3.014
11.95	67.34	2.985
11.96	67.43	2.947
11.97	67.53	2.895
11.98	67.63	2.840
11.99	67.73	2.779
12.00	67.84	2.713
12.01	67.94	2.646
12.02	68.05	2.575
12.03	68.16	2.509
12.04	68.28	2.459
12.05	68.39	2.383
12.06	68.50	2.296
12.07	68.62	2.211
12.08	68.74	2.121
12.09	68.85	2.029
12.10	68.98	1.940
12.11	69.09	1.855
12.12	69.22	1.769
12.13	69.34	1.687
12.14	69.46	1.608
12.15	69.58	1.527
12.16	69.70	1.450
12.17	69.82	1.376
12.18	69.94	1.314
12.19	70.06	1.238
12.20	70.18	1.165
12.21	70.30	1.108
12.22	70.42	1.050
12.23	70.54	0.983
12.24	70.66	0.923
12.25	70.78	0.873
12.26	70.90	0.820
12.27	71.01	0.772
12.28	71.13	0.728
12.29	71.24	0.686
12.30	71.36	0.646
12.31	71.47	0.610
12.32	71.59	0.578
12.33	71.70	0.545
12.34	71.81	0.524
12.35	71.92	0.502
12.36	72.03	0.488
12.37	72.14	0.473
12.38	72.25	0.461
12.39	72.35	0.449
12.40	72.46	0.438
12.41	72.57	0.429
12.42	72.67	0.420
12.43	72.78	0.413
12.44	72.88	0.406
12.45	72.98	0.399
12.46	73.09	0.395
12.47	73.19	0.389
12.48	73.29	0.384
12.49	73.40	0.380
12.50	73.50	0.379
12.51	73.60	0.375
12.52	73.70	0.371
12.53	73.81	0.368
12.54	73.91	0.365
12.55	74.01	0.364
12.56	74.11	0.363
12.57	74.21	0.361
12.58	74.31	0.360
12.59	74.41	0.358
12.60	74.51	0.357
12.61	74.61	0.356
12.62	74.72	0.355
12.63	74.82	0.354
12.64	74.92	0.354
12.65	75.02	0.353
12.66	75.12	0.352
12.67	75.22	0.352
12.68	75.32	0.352
12.69	75.42	0.351
12.70	75.52	0.351
12.71	75.62	0.350
12.72	75.72	0.350
12.73	75.82	0.350
12.74	75.92	0.350
12.75	76.02	0.350
12.76	76.12	0.349
12.77	76.22	0.349
12.78	76.32	0.349
12.79	76.42	0.349
12.80	76.52	0.349
12.81	76.62	0.349
12.82	76.72	0.348
12.83	76.82	0.348
12.84	76.92	0.348
12.85	77.02	0.348
12.86	77.12	0.348
12.87	77.22	0.347
12.88	77.32	0.347
12.89	77.42	0.347
12.90	77.52	0.347
12.91	77.62	0.347
12.92	77.72	0.347
12.93	77.82	0.347
12.94	77.92	0.347
12.95	78.02	0.347
12.96	78.12	0.346
12.97	78.22	0.346
12.98	78.33	0.346
12.99	78.43	0.346
13.00	78.53	0.346
13.01	78.63	0.346
13.02	78.73	0.346
13.03	78.82	0.346
13.04	78.93	0.346
13.05	79.03	0.346
13.06	79.13	0.346
13.07	79.23	0.346
13.08	79.33	0.346
13.09	79.43	0.346
13.10	79.53	0.346
13.11	79.63	0.346
13.12	79.73	0.346
13.13	79.83	0.346
13.14	79.93	0.346
13.15	80.03	0.345
13.16	80.13	0.345
13.17	80.23	0.345
13.18	80.33	0.345
13.19	80.43	0.345
13.20	80.53	0.345
13.21	80.63	0.345
13.22	80.73	0.345
13.23	80.83	0.345
13.24	80.93	0.345
13.25	81.03	0.345
13.26	81.13	0.346
13.27	81.23	0.346
13.28	81.33	0.346
13.29	81.43	0.346
13.30	81.53	0.346
13.31	81.63	0.346
13.32	81.73	0.346
13.33	81.83	0.346
13.34	81.93	0.346
13.35	82.03	0.346
13.36	82.13	0.346
13.37	82.23	0.346
13.38	82.33	0.346
13.39	82.43	0.346
13.40	82.53	0.346
13.41	82.63	0.346
13.42	82.73	0.346
13.43	82.83	0.346
13.44	82.93	0.346
13.45	83.03	0.346
13.46	83.13	0.346
13.47	83.23	0.346
13.48	83.33	0.346
13.49	83.43	0.346
13.50	83.53	0.346
13.51	83.63	0.346
13.52	83.73	0.346
13.53	83.83	0.346
13.54	83.93	0.346
13.55	84.03	0.346
13.56	84.13	0.346
13.57	84.23	0.346
13.58	84.33	0.346
13.59	84.43	0.346
13.60	84.53	0.346
13.61	84.63	0.346
13.62	84.73	0.346
13.63	84.83	0.346
13.64	84.93	0.346
13.65	85.03	0.346
13.66	85.13	0.347
13.67	85.23	0.347
13.68	85.33	0.347
13.69	85.43	0.347
13.70	85.53	0.347
13.71	85.63	0.347
13.72	85.73	0.347
13.73	85.83	0.347
13.74	85.93	0.347
13.75	86.03	0.347
13.76	86.13	0.347
13.77	86.23	0.347
13.78	86.33	0.347
13.79	86.44	0.347
13.80	86.53	0.347
13.81	86.63	0.347
13.82	86.74	0.347
13.83	86.83	0.347
13.84	86.93	0.347
13.85	87.03	0.347
13.86	87.13	0.347
13.87	87.24	0.348
13.88	87.34	0.348
13.89	87.44	0.348
13.90	87.54	0.348
13.91	87.64	0.348
13.92	87.74	0.348
13.93	87.84	0.348
13.94	87.94	0.348
13.95	88.04	0.348
13.96	88.13	0.348
13.97	88.24	0.348
13.98	88.34	0.348
13.99	88.44	0.348
14.00	88.54	0.348
14.01	88.64	0.348
14.02	88.74	0.348
14.03	88.84	0.349
14.04	88.94	0.349
14.05	89.04	0.349
14.06	89.14	0.349
14.07	89.24	0.349
14.08	89.34	0.349
14.09	89.44	0.349
14.10	89.54	0.349
14.11	89.64	0.349
14.12	89.74	0.349
14.13	89.84	0.349
14.14	89.94	0.349
14.15	90.04	0.349
14.16	90.14	0.349
14.17	90.24	0.349
14.18	90.34	0.350
14.19	90.44	0.350
14.20	90.54	0.350
14.21	90.64	0.350
14.22	90.74	0.350
14.23	90.84	0.350
14.24	90.94	0.350
14.25	91.04	0.350
14.26	91.14	0.350
14.27	91.24	0.350
14.28	91.34	0.350
14.29	91.44	0.350
14.30	91.54	0.350
14.31	91.64	0.350
14.32	91.74	0.351
14.33	91.84	0.351
14.34	91.94	0.351
14.35	92.04	0.351
14.36	92.14	0.351
14.37	92.24	0.351
14.38	92.34	0.351
14.39	92.44	0.351
14.40	92.54	0.351
14.41	92.64	0.351
14.42	92.74	0.351
14.43	92.84	0.351
14.44	92.94	0.351
14.45	93.04	0.351
14.46	93.14	0.352
14.47	93.24	0.352
14.48	93.34	0.352
14.49	93.44	0.352
14.50	93.54	0.352
14.51	93.64	0.352
14.52	93.74	0.352
14.53	93.84	0.352
14.54	93.94	0.352
14.55	94.04	0.352
14.56	94.14	0.352
14.57	94.24	0.352
14.58	94.34	0.353
14.59	94.44	0.353
14.60	94.54	0.353
14.61	94.64	0.353
14.62	94.74	0.353
14.63	94.84	0.353
14.64	94.94	0.353
14.65	95.04	0.353
14.66	95.14	0.353
14.67	95.24	0.353
14.68	95.34	0.353
14.69	95.44	0.353
14.70	95.54	0.353
14.71	95.64	0.353
14.72	95.74	0.353
14.73	95.84	0.353
14.74	95.94	0.353
14.75	96.04	0.354
14.76	96.14	0.354
14.77	96.24	0.354
14.78	96.34	0.354
14.79	96.44	0.354
14.80	96.55	0.354
14.81	96.64	0.354
14.82	96.75	0.354
14.83	96.84	0.354
14.84	96.95	0.354
14.85	97.04	0.354
14.86	97.14	0.354
14.87	97.24	0.354
14.88	97.34	0.354
14.89	97.44	0.354
14.90	97.55	0.354
14.91	97.65	0.355
14.92	97.75	0.355
14.93	97.84	0.355
14.94	97.94
14.95	98.05
14.96	98.15
14.97	98.25
14.98	98.35
14.99
14.99

[step]
Ramp 10.00 °C/min to -50.00 °C
Time	Temperature	Heat Flow (Normalized)
min	°C	W/g
16.00	100.10	-0.042
16.00	100.10	-0.042
16.02	100.10	-0.042
16.03	100.09	-0.042
16.03	100.09	-0.043
16.05	100.08	-0.043
16.05	100.07	-0.043
16.07	100.06	-0.045
16.08	100.04	-0.050
16.08	100.01	-0.063
16.10	99.97	-0.078
16.10	99.93	-0.095
16.12	99.88	-0.114
16.13	99.83	-0.135
16.13	99.77	-0.160
16.15	99.70	-0.182
16.15	99.64	-0.206
16.17	99.57	-0.227
16.18	99.49	-0.247
16.18	99.42	-0.266
16.20	99.34	-0.282
16.20	99.26	-0.295
16.22	99.18	-0.309
16.23	99.10	-0.320
16.23	99.02	-0.332
16.25	98.93	-0.341
16.25	98.84	-0.351
16.27	98.76	-0.357
16.28	98.67	-0.369
16.28	98.58	-0.374
16.30	98.49	-0.380
16.30	98.39	-0.388
16.32	98.30	-0.390
16.33	98.21	-0.398
16.33	98.12	-0.402
16.35	98.02	-0.406
16.35	97.93	-0.409
16.37	97.84	-0.410
16.38	97.74	-0.417
16.38	97.65	-0.418
16.40	97.55	-0.420
16.40	97.45	-0.422
16.42	97.36	-0.423
16.43	97.26	-0.426
16.43	97.17	-0.427
16.45	97.07	-0.429
16.45	96.97	-0.430
16.47	96.88	-0.431
16.48	96.78	-0.433
16.48	96.68	-0.434
16.50	96.58	-0.434
16.50	96.48	-0.435
16.52	96.39	-0.435
16.53	96.29	-0.436
16.53	96.19	-0.437
16.55	96.09	-0.437
16.55	96.00	-0.437
16.57	95.90	-0.438
16.58	95.80	-0.438
16.58	95.70	-0.439
16.60	95.60	-0.439
16.60	95.50	-0.439
16.62	95.40	-0.439
16.63	95.30	-0.440
16.63	95.21	-0.440
16.65	95.11	-0.440
16.65	95.01	-0.440
16.67	94.91	-0.440
16.68	94.81	-0.441
16.68	94.71	-0.441
16.70	94.61	-0.441
16.70	94.51	-0.441
16.72	94.42	-0.441
16.73	94.32	-0.441
16.73	94.22	-0.442
16.75	94.12	-0.442
16.75	94.02	-0.442
16.77	93.92	-0.442
16.78	93.82	-0.442
16.78	93.72	-0.442
16.80	93.62	-0.442
16.80	93.52	-0.442
16.82	93.42	-0.443
16.83	93.32	-0.443
16.83	93.23	-0.443
16.85	93.13	-0.443
16.85	93.03	-0.443
16.87	92.93	-0.443
16.88	92.83	-0.443
16.88	92.73	-0.443
16.90	92.63	-0.443
16.90	92.53	-0.443
16.92	92.43	-0.443
16.93	92.33	-0.443
16.93	92.23	-0.443
16.95	92.13	-0.443
16.95	92.03	-0.443
16.97	91.93	-0.444
16.98	91.83	-0.444
16.98	91.73	-0.444
17.00	91.64	-0.444
17.00	91.54	-0.444
17.02	91.44	-0.444
17.03	91.34	-0.444
17.03	91.24	-0.444
17.05	91.14	-0.444
17.05	91.04	-0.444
17.07	90.94	-0.444
17.08	90.84	-0.443
17.08	90.74	-0.443
[...]
398.78	-31.44	0.210
398.78	-31.37	0.210
398.79	-31.31	0.210
398.79	-31.24	0.211
398.80	-31.17	0.211
398.81	-31.11	0.211
398.82	-31.04	0.211
398.82	-30.97	0.211
398.83	-30.90	0.211
398.83	-30.84	0.211
398.84	-30.77	0.211
398.85	-30.71	0.211
398.86	-30.64	0.211
398.86	-30.57	0.211
398.87	-30.50	0.211
398.88	-30.44	0.211
398.88	-30.37	0.211
398.89	-30.30	0.212
398.89	-30.24	0.212
398.90	-30.17	0.212
398.91	-30.10	0.212
398.92	-30.04	0.212
398.92	-29.97	0.212
398.93	-29.91	0.212
398.93	-29.84	0.212
398.94	-29.77	0.212
398.95	-29.71	0.212
398.96	-29.64	0.212
398.96	-29.57	0.212
398.97	-29.50	0.212
398.98	-29.44	0.212
398.98	-29.37	0.213
398.99	-29.30	0.213
398.99	-29.24	0.213
399.00	-29.17	0.213
399.01	-29.10	0.213
399.02	-29.04	0.213
399.02	-28.97	0.213
399.03	-28.90	0.213
399.03	-28.84	0.213
399.04	-28.77	0.213
399.05	-28.70	0.213
399.06	-28.64	0.213
399.06	-28.57	0.213
399.07	-28.50	0.213
399.08	-28.44	0.214
399.08	-28.37	0.214
399.09	-28.30	0.214
399.09	-28.24	0.214
399.10	-28.17	0.214
399.11	-28.10	0.214
399.12	-28.04	0.214
399.12	-27.97	0.214
399.13	-27.90	0.214
399.13	-27.84	0.214
399.14	-27.77	0.214
399.15	-27.70	0.214
399.16	-27.64	0.215
399.16	-27.57	0.215
399.17	-27.50	0.215
399.18	-27.44	0.215
399.18	-27.37	0.215
399.19	-27.30	0.215
399.19	-27.24	0.215
399.20	-27.17	0.215
399.21	-27.10	0.215
399.22	-27.03	0.215
399.22	-26.97	0.215
399.23	-26.90	0.215
399.23	-26.84	0.215
399.24	-26.77	0.215
399.25	-26.70	0.216
399.26	-26.64	0.216
399.26	-26.57	0.216
399.27	-26.50	0.216
399.28	-26.43	0.216
399.28	-26.37	0.216
399.29	-26.30	0.216
399.29	-26.24	0.216
399.30	-26.17	0.216
399.31	-26.10	0.216
399.32	-26.03	0.216
399.32	-25.97	0.217
399.33	-25.90	0.217
399.33	-25.83	0.217
399.34	-25.77	0.217
399.35	-25.70	0.217
399.36	-25.63	0.217
399.36	-25.57	0.217
399.37	-25.50	0.217
399.38	-25.43	0.217
399.38	-25.37	0.217
399.39	-25.30	0.218
399.39	-25.23	0.218
399.40	-25.17	0.218
399.41	-25.10	0.218
399.42	-25.03	0.218
399.42	-24.97	0.218
399.43	-24.90	0.218
399.43	-24.83	0.218
399.44	-24.77	0.218
399.45	-24.70	0.218
399.46	-24.63	0.218
399.46	-24.57	0.219
399.47	-24.50	0.219
399.48	-24.43	0.219
399.48	-24.37	0.219
399.49	-24.30	0.219
399.49	-24.23	0.219
399.50	-24.17	0.219
399.51	-24.10	0.219
399.52	-24.03	0.219
399.52	-23.97	0.220
399.53	-23.90	0.220
399.53	-23.83	0.220
399.54	-23.77	0.220
399.55	-23.70	0.220
399.56	-23.63	0.220
399.56	-23.57	0.220
399.57	-23.50	0.220
399.58	-23.43	0.220
399.58	-23.36	0.220
399.59	-23.30	0.221
399.59	-23.23	0.221
399.60	-23.17	0.221
399.61	-23.10	0.221
399.62	-23.03	0.221
399.62	-22.97	0.221
399.63	-22.90	0.221
399.63	-22.83	0.221
399.64	-22.76	0.222
399.65	-22.70	0.222
399.66	-22.63	0.222
399.66	-22.56	0.222
399.67	-22.50	0.222
399.68	-22.43	0.222
399.68	-22.37	0.222
399.69	-22.30	0.222
399.69	-22.23	0.222
399.70	-22.16	0.223
399.71	-22.10	0.223
399.72	-22.03	0.223
399.72	-21.96	0.223
399.73	-21.90	0.223
399.73	-21.83	0.223
399.74	-21.76	0.223
399.75	-21.70	0.223
399.76	-21.63	0.223
399.76	-21.56	0.224
399.77	-21.50	0.224
399.78	-21.43	0.224
399.78	-21.36	0.224
399.79	-21.30	0.224
399.79	-21.23	0.225
399.80	-21.16	0.225
399.81	-21.10	0.225
399.82	-21.03	0.225
399.82	-20.96	0.225
399.83	-20.90	0.225
399.83	-20.83	0.226
399.84	-20.76	0.226
399.85	-20.70	0.226
399.86	-20.63	0.226
399.86	-20.56	0.226
399.87	-20.50	0.226
399.88	-20.43	0.226
399.88	-20.36	0.227
399.89	-20.30	0.227
399.89	-20.23	0.227
399.90	-20.16	0.227
399.91	-20.10	0.227
399.92	-20.03	0.227
399.92	-19.96	0.228
399.93	-19.90	0.228
399.93	-19.83	0.228
399.94	-19.76	0.228
399.95	-19.70	0.228
399.96	-19.63	0.228
399.96	-19.56	0.229
399.97	-19.50	0.229
399.98	-19.43	0.229
399.98	-19.36	0.230
399.99	-19.30	0.230
399.99	-19.23	0.230
400.00	-19.16	0.231
400.01	-19.10	0.231
400.02	-19.03	0.231
400.02	-18.96	0.231
400.03	-18.90	0.231
400.03	-18.83	0.231
400.04	-18.76	0.231
400.05	-18.70	0.232
400.06	-18.63	0.232
400.06	-18.56	0.232
400.07	-18.50	0.232
400.08	-18.43	0.232
400.08	-18.36	0.233
400.09	-18.30	0.233
400.09	-18.23	0.233
400.10	-18.16	0.234
400.11	-18.10	0.234
400.12	-18.03	0.234
400.12	-17.96	0.234
400.13	-17.90	0.235
400.13	-17.83	0.235
400.14	-17.76	0.235
400.15	-17.70	0.236
400.16	-17.63	0.236
400.16	-17.56	0.236
400.17	-17.50	0.236
400.18	-17.43	0.237
400.18	-17.36	0.237
400.19	-17.30	0.237
400.19	-17.23	0.237
400.20	-17.16	0.238
400.21	-17.10	0.238
400.22	-17.03	0.238
400.22	-16.96	0.240
400.23	-16.90	0.241
400.23	-16.83	0.242
400.24	-16.76	0.242
400.25	-16.70	0.242
400.26	-16.63	0.243
400.26	-16.56	0.245
400.27	-16.50	0.246
400.28	-16.43	0.246
400.28	-16.36	0.246
400.29	-16.30	0.247
400.29	-16.23	0.247
400.30	-16.16	0.247
400.31	-16.10	0.248
400.32	-16.03	0.249
400.32	-15.96	0.249
400.33	-15.90	0.250
400.33	-15.83	0.250
400.34	-15.76	0.251
400.35	-15.70	0.252
400.36	-15.63	0.252
400.36	-15.57	0.253
400.37	-15.50	0.254
400.38	-15.43	0.255
400.38	-15.36	0.257
400.39	-15.30	0.258
400.39	-15.23	0.259
400.40	-15.17	0.260
400.41	-15.10	0.261
400.42	-15.03	0.262
400.42	-14.97	0.263
400.43	-14.90	0.263
400.43	-14.83	0.265
400.44	-14.77	0.266
400.45	-14.70	0.267
400.46	-14.63	0.268
400.46	-14.57	0.271
400.47	-14.50	0.273
400.48	-14.43	0.274
400.48	-14.37	0.274
400.49	-14.30	0.275
400.49	-14.23	0.277
400.50	-14.17	0.279
400.51	-14.10	0.281
400.52	-14.03	0.283
400.52	-13.97	0.284
400.53	-13.90	0.285
400.53	-13.84	0.288
400.54	-13.77	0.291
400.55	-13.70	0.292
400.56	-13.64	0.293
400.56	-13.57	0.296
400.57	-13.51	0.299
400.58	-13.44	0.300
400.58	-13.37	0.302
400.59	-13.31	0.303
400.59	-13.24	0.305
400.60	-13.17	0.308
400.61	-13.11	0.311
400.62	-13.04	0.314
400.62	-12.98	0.316
400.63	-12.91	0.318
400.63	-12.84	0.321
400.64	-12.78	0.324
400.65	-12.71	0.326
400.66	-12.64	0.328
400.66	-12.58	0.334
400.67	-12.51	0.338
400.68	-12.45	0.338
400.68	-12.38	0.340
400.69	-12.32	0.343
400.69	-12.25	0.347
400.70	-12.18	0.352
400.71	-12.12	0.355
400.72	-12.05	0.358
400.72	-11.99	0.362
400.73	-11.92	0.365
400.73	-11.85	0.367
400.74	-11.79	0.372
400.75	-11.72	0.375
400.76	-11.66	0.378
400.76	-11.59	0.380
400.77	-11.53	0.384
400.78	-11.46	0.388
400.78	-11.39	0.391
400.79	-11.33	0.396
400.79	-11.26	0.398
400.80	-11.20	0.402
400.81	-11.13	0.404
400.82	-11.07	0.405
400.82	-11.00	0.407
400.83	-10.93	0.408
400.83	-10.87	0.410
400.84	-10.80	0.412
400.85	-10.73	0.414
400.86	-10.67	0.414
400.86	-10.60	0.415
400.87	-10.54	0.416
400.88	-10.47	0.416
400.88	-10.40	0.415
400.89	-10.34	0.414
400.89	-10.27	0.414
400.90	-10.20	0.413
400.91	-10.14	0.412
400.92	-10.07	0.410
400.92	-10.01	0.408
400.93	-9.94	0.405
400.93	-9.87	0.400
400.94	-9.80	0.394
400.95	-9.73	0.387
400.96	-9.67	0.383
400.96	-9.60	0.379
400.97	-9.53	0.375
400.98	-9.47	0.371
400.98	-9.40	0.364
400.99	-9.33	0.359
400.99	-9.26	0.357
401.00	-9.20	0.354
401.01	-9.13	0.348
401.02	-9.06	0.345
401.02	-8.99	0.343
401.03	-8.92	0.339
401.03	-8.86	0.335
401.04	-8.79	0.332
401.05	-8.72	0.328
401.06	-8.65	0.326
401.06	-8.59	0.325
401.07	-8.52	0.324
401.08	-8.45	0.322
401.08	-8.38	0.320
401.09	-8.32	0.317
401.09	-8.25	0.316
401.10	-8.18	0.315
401.11	-8.11	0.315
401.12	-8.05	0.314
401.12	-7.98	0.313
401.13	-7.91	0.312
401.13	-7.84	0.311
401.14	-7.77	0.309
401.15	-7.71	0.309
401.16	-7.64	0.310
401.16	-7.57	0.309
401.17	-7.51	0.308
401.18	-7.44	0.308
401.18	-7.37	0.307
401.19	-7.31	0.306
401.19	-7.24	0.306
401.20	-7.17	0.305
401.21	-7.10	0.305
401.22	-7.04	0.305
401.22	-6.97	0.305
401.23	-6.90	0.305
401.23	-6.83	0.304
401.24	-6.77	0.304
401.25	-6.70	0.304
401.26	-6.63	0.304
401.26	-6.57	0.304
401.27	-6.50	0.303
401.28	-6.43	0.303
401.28	-6.37	0.303
401.29	-6.30	0.303
401.29	-6.23	0.303
401.30	-6.17	0.303
401.31	-6.10	0.302
401.32	-6.03	0.302
401.32	-5.97	0.302
401.33	-5.90	0.302
401.33	-5.83	0.302
401.34	-5.76	0.302
401.35	-5.70	0.302
401.36	-5.63	0.302
401.36	-5.57	0.301
401.37	-5.50	0.301
401.38	-5.43	0.301
401.38	-5.36	0.301
401.39	-5.30	0.301
401.39	-5.23	0.301
401.40	-5.16	0.301
401.41	-5.10	0.301
401.42	-5.03	0.300
401.42	-4.96	0.300
401.43	-4.90	0.300
401.43	-4.83	0.300
401.44	-4.76	0.300
401.45	-4.70	0.300
401.46	-4.63	0.300
401.46	-4.56	0.300
401.47	-4.50	0.300
401.48	-4.43	0.300
401.48	-4.36	0.300
401.49	-4.29	0.299
401.49	-4.23	0.299
401.50	-4.16	0.299
401.51	-4.09	0.299
401.52	-4.03	0.299
401.52	-3.96	0.299
401.53	-3.89	0.299
401.53	-3.83	0.299
401.54	-3.76	0.299
401.55	-3.69	0.299
401.56	-3.63	0.299
401.56	-3.56	0.299
401.57	-3.49	0.299
401.58	-3.43	0.299
401.58	-3.36	0.298
401.59	-3.29	0.298
401.59	-3.23	0.298
401.60	-3.16	0.298
401.61	-3.09	0.298
401.62	-3.03	0.298
401.62	-2.96	0.298
401.63	-2.89	0.298
401.63	-2.83	0.298
401.64	-2.76	0.298
401.65	-2.69	0.298
401.66	-2.63	0.298
401.66	-2.56	0.298
401.67	-2.49	0.298
401.68	-2.43	0.298
401.68	-2.36	0.298
401.69	-2.29	0.298
401.69	-2.23	0.298
401.70	-2.16	0.298
401.71	-2.09	0.298
401.72	-2.02	0.298
401.72	-1.96	0.298
401.73	-1.89	0.298
401.73	-1.82	0.298
401.74	-1.76	0.298
401.75	-1.69	0.298
401.76	-1.62	0.298
401.76	-1.56	0.298
401.77	-1.49	0.298
401.78	-1.42	0.298
401.78	-1.36	0.298
401.79	-1.29	0.298
401.79	-1.22	0.298
401.80	-1.16	0.297
401.81	-1.09	0.297
401.82	-1.02	0.297
401.82	-0.96	0.297
401.83	-0.89	0.297
401.83	-0.82	0.297
401.84	-0.76	0.297
401.85	-0.69	0.297
401.86	-0.62	0.297
401.86	-0.56	0.297
401.87	-0.49	0.297
401.88	-0.42	0.297
401.88	-0.36	0.297
401.89	-0.29	0.297
401.89	-0.22	0.297
401.90	-0.16	0.297
401.91	-0.09	0.297
401.92	-0.02	0.297
401.92	0.05	0.297
401.93	0.11	0.297
401.93	0.18	0.297
401.94	0.25	0.297
401.95	0.31	0.297
401.96	0.38	0.297
401.96	0.45	0.298
401.97	0.51	0.298
401.98	0.58	0.298
401.98	0.65	0.298
401.99	0.71	0.298
401.99	0.78	0.298
402.00	0.85	0.298
402.01	0.91	0.298
402.02	0.98	0.298
402.02	1.05	0.298
402.03	1.11	0.298
402.03	1.18	0.298
402.04	1.25	0.298
402.05	1.31	0.298
402.06	1.38	0.298
402.06	1.45	0.298
402.07	1.51	0.298
402.08	1.58	0.298
402.08	1.65	0.298
402.09	1.71	0.298
402.09	1.78	0.298
402.10	1.85	0.298
402.11	1.91	0.298
402.12	1.98	0.298
402.12	2.05	0.298
402.13	2.11	0.298
402.13	2.18	0.298
402.14	2.25	0.298
402.15	2.32	0.298
402.16	2.38	0.298
402.16	2.45	0.298
402.17	2.51	0.298
402.18	2.58	0.298
402.18	2.65	0.298
402.19	2.71	0.298
402.19	2.78	0.298
402.20	2.85	0.298
402.21	2.92	0.298
402.22	2.98	0.298
402.22	3.05	0.298
402.23	3.12	0.299
402.23	3.18	0.299
402.24	3.25	0.299
402.25	3.32	0.299
402.26	3.38	0.299
402.26	3.45	0.299
402.27	3.52	0.299
402.28	3.58	0.299
402.28	3.65	0.299
402.29	3.72	0.299
402.29	3.78	0.299
402.30	3.85	0.299
402.31	3.92	0.299
402.32	3.98	0.299
402.32	4.05	0.299
402.33	4.12	0.299
402.33	4.18	0.299
402.34	4.25	0.299
402.35	4.32	0.299
402.36	4.39	0.299
402.36	4.45	0.299
402.37	4.52	0.299
402.38	4.58	0.299
402.38	4.65	0.299
402.39	4.72	0.299
402.39	4.78	0.299
402.40	4.85	0.299
402.41	4.92	0.299
402.42	4.98	0.299
402.42	5.05	0.299
402.43	5.12	0.299
402.43	5.18	0.299
402.44	5.25	0.299
402.45	5.32	0.299
402.46	5.39	0.299
402.46	5.45	0.299
402.47	5.52	0.300
402.48	5.59	0.300
402.48	5.65	0.300
402.49	5.72	0.300
402.49	5.79	0.300
402.50	5.85	0.300
402.51	5.92	0.300
402.52	5.99	0.300
402.52	6.05	0.300
402.53	6.12	0.300
402.53	6.19	0.300
402.54	6.25	0.300
402.55	6.32	0.300
402.56	6.39	0.300
402.56	6.45	0.300
402.57	6.52	0.300
402.58	6.59	0.300
402.58	6.65	0.300
402.59	6.72	0.300
402.59	6.79	0.300
402.60	6.85	0.300
402.61	6.92	0.300
402.62	6.99	0.301
402.62	7.06	0.301
402.63	7.12	0.301
402.63	7.19	0.301
402.64	7.25	0.301
402.65	7.32	0.301
402.66	7.39	0.301
402.66	7.46	0.301
402.67	7.52	0.301
402.68	7.59	0.301
402.68	7.65	0.301
402.69	7.72	0.301
402.69	7.79	0.301
402.70	7.86	0.301
402.71	7.92	0.301
402.72	7.99	0.301
402.72	8.06	0.301
402.73	8.12	0.301
402.73	8.19	0.301
402.74	8.26	0.301
402.75	8.32	0.301
402.76	8.39	0.301
402.76	8.46	0.301
402.77	8.52	0.302
402.78	8.59	0.302
402.78	8.66	0.302
402.79	8.72	0.302
402.79	8.79	0.302
402.80	8.86	0.302
402.81	8.92	0.302
402.82	8.99	0.302
402.82	9.06	0.302
402.83	9.13	0.302
402.83	9.19	0.302
402.84	9.26	0.302
402.85	9.33	0.302
402.86	9.39	0.302
402.86	9.46	0.302
402.87	9.53	0.302
402.88	9.59	0.302
402.88	9.66	0.302
402.89	9.73	0.302
402.89	9.79	0.302
402.90	9.86	0.302
402.91	9.93	0.302
402.92	9.99	0.302
402.92	10.06	0.302
402.93	10.13	0.302
402.93	10.19	0.302
402.94	10.26	0.303
402.95	10.33	0.303
402.96	10.39	0.303
402.96	10.46	0.303
402.97	10.53	0.303
402.98	10.59	0.303
402.98	10.66	0.303
402.99	10.73	0.303
402.99	10.79	0.303
403.00	10.86	0.303
403.01	10.93	0.303
403.02	10.99	0.303
403.02	11.06	0.303
403.03	11.13	0.303
403.03	11.20	0.303
403.04	11.26	0.303
403.05	11.33	0.303
403.06	11.40	0.303
403.06	11.46	0.303
403.07	11.53	0.303
403.08	11.59	0.303
403.08	11.66	0.303
403.09	11.73	0.303
403.09	11.80	0.303
403.10	11.86	0.303
403.11	11.93	0.303
403.12	12.00	0.303
403.12	12.06	0.304
403.13	12.13	0.304
403.13	12.20	0.304
403.14	12.26	0.304
403.15	12.33	0.304
403.16	12.40	0.304
403.16	12.46	0.304
403.17	12.53	0.304
403.18	12.60	0.304
403.18	12.66	0.304
403.19	12.73	0.304
403.19	12.80	0.304
403.20	12.86	0.304
403.21	12.93	0.304
403.22	13.00	0.304
403.22	13.06	0.304
403.23	13.13	0.304
403.23	13.20	0.304
403.24	13.26	0.304
403.25	13.33	0.304
403.26	13.40	0.304
403.26	13.46	0.304
403.27	13.53	0.304
403.28	13.60	0.304
403.28	13.67	0.304
403.29	13.73	0.304
403.29	13.80	0.304
403.30	13.86	0.305
403.31	13.93	0.305
403.32	14.00	0.305
403.32	14.07	0.305
403.33	14.13	0.305
403.33	14.20	0.305
403.34	14.27	0.305
403.35	14.33	0.305
403.36	14.40	0.305
403.36	14.47	0.305
403.37	14.53	0.305
403.38	14.60	0.305
403.38	14.67	0.305
403.39	14.73	0.305
403.39	14.80	0.305
403.40	14.87	0.305
403.41	14.93	0.305
403.42	15.00	0.305
403.42	15.07	0.305
403.43	15.13	0.305
403.43	15.20	0.305
403.44	15.27	0.305
403.45	15.33	0.305
403.46	15.40	0.306
403.46	15.47	0.306
403.47	15.53	0.306
403.48	15.60	0.306
403.48	15.67	0.306
403.49	15.73	0.306
403.49	15.80	0.306
403.50	15.87	0.306
403.51	15.93	0.306
403.52	16.00	0.306
403.52	16.07	0.306
403.53	16.13	0.306
403.53	16.20	0.306
403.54	16.27	0.306
403.55	16.33	0.306
403.56	16.40	0.306
403.56	16.47	0.306
403.57	16.54	0.306
403.58	16.60	0.306
403.58	16.67	0.306
403.59	16.73	0.306
403.59	16.80	0.306
403.60	16.87	0.307
403.61	16.94	0.307
403.62	17.00	0.307
403.62	17.07	0.307
403.63	17.14	0.307
403.63	17.20	0.307
403.64	17.27	0.307
403.65	17.34	0.307
403.66	17.40	0.307
403.66	17.47	0.307
403.67	17.54	0.307
403.68	17.60	0.307
403.68	17.67	0.307
403.69	17.74	0.307
403.69	17.80	0.307
403.70	17.87	0.307
403.71	17.94	0.307
403.72	18.00	0.307
403.72	18.07	0.307
403.73	18.14	0.307
403.73	18.20	0.307
403.74	18.27	0.307
403.75	18.34	0.308
403.76	18.40	0.308
403.76	18.47	0.308
403.77	18.54	0.308
403.78	18.60	0.308
403.78	18.67	0.308
403.79	18.74	0.308
403.79	18.80	0.308
403.80	18.87	0.308
403.81	18.94	0.308
403.82	19.00	0.308
403.82	19.07	0.308
403.83	19.14	0.308
403.83	19.20	0.308
403.84	19.27	0.308
403.85	19.34	0.308
403.86	19.41	0.308
403.86	19.47	0.308
403.87	19.54	0.308
403.88	19.61	0.308
403.88	19.67	0.308
403.89	19.74	0.308
403.89	19.81	0.308
403.90	19.87	0.309
403.91	19.94	0.309
403.92	20.01	0.309
403.92	20.07	0.309
403.93	20.14	0.309
403.93	20.21	0.309
403.94	20.27	0.309
403.95	20.34	0.309
403.96	20.41	0.309
403.96	20.47	0.309
403.97	20.54	0.309
403.98	20.61	0.309
403.98	20.67	0.309
403.99	20.74	0.309
403.99	20.81	0.309
404.00	20.87	0.309
404.01	20.94	0.309
404.02	21.01	0.309
404.02	21.07	0.309
404.03	21.14	0.309
404.03	21.21	0.310
404.04	21.27	0.310
404.05	21.34	0.310
404.06	21.41	0.310
404.06	21.47	0.310
404.07	21.54	0.310
404.08	21.61	0.310
404.08	21.67	0.310
404.09	21.74	0.310
404.09	21.81	0.310
404.10	21.87	0.310
404.11	21.94	0.310
404.12	22.01	0.310
404.12	22.07	0.310
404.13	22.14	0.310
404.13	22.21	0.310
404.14	22.27	0.310
404.15	22.34	0.310
404.16	22.41	0.310
404.16	22.47	0.310
404.17	22.54	0.310
404.18	22.61	0.310
404.18	22.68	0.310
404.19	22.74	0.310
404.19	22.81	0.311
404.20	22.88	0.311
404.21	22.94	0.311
404.22	23.01	0.311
404.22	23.08	0.311
404.23	23.14	0.311
404.23	23.21	0.311
404.24	23.28	0.311
404.25	23.34	0.311
404.26	23.41	0.311
404.26	23.48	0.311
404.27	23.54	0.311
404.28	23.61	0.311
404.28	23.68	0.311
404.29	23.74	0.311
404.29	23.81	0.311
404.30	23.88	0.311
404.31	23.94	0.311
404.32	24.01	0.311
404.32	24.08	0.311
404.33	24.14	0.311
404.33	24.21	0.311
404.34	24.28	0.312
404.35	24.34	0.312
404.36	24.41	0.312
404.36	24.48	0.312
404.37	24.54	0.312
404.38	24.61	0.312
404.38	24.68	0.312
404.39	24.74	0.312
404.39	24.81	0.312
404.40	24.88	0.312
404.41	24.94	0.312
404.42	25.01	0.312
404.42	25.08	0.312
404.43	25.14	0.312
404.43	25.21	0.312
404.44	25.28	0.312
404.45	25.35	0.312
404.46	25.41	0.312
404.46	25.48	0.312
404.47	25.55	0.312
404.48	25.61	0.312
404.48	25.68	0.313
404.49	25.74	0.313
404.49	25.81	0.313
404.50	25.88	0.313
404.51	25.95	0.313
404.52	26.01	0.313
404.52	26.08	0.313
404.53	26.15	0.313
404.53	26.21	0.313
404.54	26.28	0.313
404.55	26.35	0.313
404.56	26.41	0.313
404.56	26.48	0.313
404.57	26.55	0.313
404.58	26.61	0.313
404.58	26.68	0.313
404.59	26.75	0.313
404.59	26.81	0.313
404.60	26.88	0.313
404.61	26.95	0.313
404.62	27.01	0.313
404.62	27.08	0.313
404.63	27.15	0.314
404.63	27.21	0.314
404.64	27.28	0.314
404.65	27.35	0.314
404.66	27.41	0.314
404.66	27.48	0.314
404.67	27.55	0.314
404.68	27.62	0.314
404.68	27.68	0.314
404.69	27.75	0.314
404.69	27.81	0.314
404.70	27.88	0.314
404.71	27.95	0.314
404.72	28.02	0.314
404.72	28.08	0.314
404.73	28.15	0.314
404.73	28.22	0.314
404.74	28.28	0.314
404.75	28.35	0.314
404.76	28.42	0.314
404.76	28.48	0.314
404.77	28.55	0.314
404.78	28.62	0.315
404.78	28.68	0.315
404.79	28.75	0.315
404.79	28.82	0.315
404.80	28.88	0.315
404.81	28.95	0.315
404.82	29.02	0.315
404.82	29.08	0.315
404.83	29.15	0.315
404.83	29.22	0.315
404.84	29.28	0.315
404.85	29.35	0.315
404.86	29.42	0.315
404.86	29.48	0.315
404.87	29.55	0.315
404.88	29.62	0.315
404.88	29.68	0.315
404.89	29.75	0.315
404.89	29.82	0.315
404.90	29.88	0.315
404.91	29.95	0.315
404.92	30.02	0.315
404.92	30.08	0.315
404.93	30.15	0.315
404.93	30.22	0.315
404.94	30.29	0.316
404.95	30.35	0.316
404.96	30.42	0.316
404.96	30.49	0.316
404.97	30.55	0.316
404.98	30.62	0.316
404.98	30.69	0.316
404.99	30.75	0.316
404.99	30.82	0.316
405.00	30.88	0.316
405.01	30.95	0.316
405.02	31.02	0.316
405.02	31.09	0.316
405.03	31.15	0.316
405.03	31.22	0.316
405.04	31.29	0.316
405.05	31.35	0.316
405.06	31.42	0.316
405.06	31.49	0.316
405.07	31.55	0.316
405.08	31.62	0.316
405.08	31.69	0.316
405.09	31.75	0.316
405.09	31.82	0.317
405.10	31.89	0.317
405.11	31.95	0.317
405.12	32.02	0.317
405.12	32.09	0.317
405.13	32.15	0.317
405.13	32.22	0.317
405.14	32.29	0.317
405.15	32.35	0.317
405.16	32.42	0.317
405.16	32.49	0.317
405.17	32.55	0.317
405.18	32.62	0.317
405.18	32.69	0.317
405.19	32.75	0.317
405.19	32.82	0.317
405.20	32.89	0.317
405.21	32.95	0.317
405.22	33.02	0.317
405.22	33.09	0.317
405.23	33.15	0.317
405.23	33.22	0.317
405.24	33.29	0.317
405.25	33.36	0.317
405.26	33.42	0.317
405.26	33.49	0.318
405.27	33.55	0.318
405.28	33.62	0.318
405.28	33.69	0.318
405.29	33.75	0.318
405.29	33.82	0.318
405.30	33.89	0.318
405.31	33.96	0.318
405.32	34.02	0.318
405.32	34.09	0.318
405.33	34.16	0.318
405.33	34.22	0.318
405.34	34.29	0.318
405.35	34.36	0.318
405.36	34.42	0.318
405.36	34.49	0.318
405.37	34.56	0.318
405.38	34.62	0.318
405.38	34.69	0.318
405.39	34.76	0.318
405.39	34.82	0.318
405.40	34.89	0.318
405.41	34.96	0.318
405.42	35.02	0.318
405.42	35.09	0.318
405.43	35.16	0.319
405.43	35.22	0.319
405.44	35.29	0.319
405.45	35.36	0.319
405.46	35.42	0.319
405.46	35.49	0.319
405.47	35.56	0.319
405.48	35.62	0.319
405.48	35.69	0.319
405.49	35.76	0.319
405.49	35.82	0.319
405.50	35.89	0.319
405.51	35.96	0.319
405.52	36.02	0.319
405.52	36.09	0.319
405.53	36.16	0.319
405.53	36.22	0.319
405.54	36.29	0.319
405.55	36.36	0.319
405.56	36.43	0.319
405.56	36.49	0.319
405.57	36.56	0.319
405.58	36.62	0.319
405.58	36.69	0.320
405.59	36.76	0.320
405.59	36.83	0.320
405.60	36.89	0.320
405.61	36.96	0.320
405.62	37.03	0.320
405.62	37.09	0.320
405.63	37.16	0.320
405.63	37.23	0.320
405.64	37.29	0.320
405.65	37.36	0.320
405.66	37.43	0.320
405.66	37.49	0.320
405.67	37.56	0.320
405.68	37.63	0.320
405.68	37.69	0.320
405.69	37.76	0.320
405.69	37.83
405.70	37.89
405.71	37.96
405.72	38.03
405.72	38.09
405.73	38.16
405.73	38.23
405.74
405.75