File: DSC/2023_08_09_CBD_simple_fragility_SBK.txt
Filename	2023_08_09_CBD_simple_fragility_SBK
Instrument name	DSC2A-00468 (192.168.1.100)
Operator	SBK
rundate	8/9/2023
Sample name	2023_08_09_CBD_simple_fragility_SBK
proceduresegments	Data Off ; Equilibrate -50.00 °C; Data On ; Ramp 10.00 °C/min to 100.00 °C; Data Off ; Isothermal 1.0 min; Data On ; Ramp 10.00 °C/min to -55.00 °C; Data Off ; Isothermal 1.0 min; Data On ; Ramp 10.00 °C/min to 40.00 °C; Data Off ; Isothermal 1.0 min; Data On ; Ramp 10.00 °C/min to -55.00 °C; Data Off ; Isothermal 1.0 min; Data On ; Ramp 10.00 °C/min to 40.00 °C; Data Off ; Isothermal 1.0 min; Data On ; Ramp 10.00 °C/min to -55.00 °C; Data Off ; Isothermal 1.0 min; Data On ; Ramp 10.00 °C/min to 40.00 °C; Data Off ; Isothermal 1.0 min; Data On ; Ramp 40.00 °C/min to -55.00 °C; Data Off ; Isothermal 1.0 min; Data On ; Ramp 10.00 °C/min to 40.00 °C; Data Off ; Isothermal 1.0 min; Data On ; Ramp 20.00 °C/min to -55.00 °C; Data Off ; Isothermal 1.0 min; Data On ; Ramp 10.00 °C/min to 40.00 °C; Data Off ; Isothermal 1.0 min; Data On ; Ramp 5.00 °C/min to -55.00 °C; Data Off ; Isothermal 1.0 min; Data On ; Ramp 10.00 °C/min to 40.00 °C; Data Off ; Isothermal 1.0 min; Data On ; Sample Interval  1.0 s/pt; Ramp 1.00 °C/min to -55.00 °C; Sample Interval  0.1 s/pt; Data Off ; Isothermal 1.0 min; Data On ; Ramp 10.00 °C/min to 40.00 °C; Data Off ; Isothermal 1.0 min; Data On ; Sample Interval  2.0 s/pt; Ramp 0.50 °C/min to -55.00 °C; Sample Interval  0.1 s/pt; Data Off ; Isothermal 1.0 min; Data On ; Ramp 10.00 °C/min to 40.00 °C; Data Off ; Isothermal 1.0 min; Data On ; Ramp 10.00 °C/min to -55.00 °C; Data Off ; Isothermal 1.0 min; Data On ; Ramp 10.00 °C/min to 40.00 °C; Data Off ; Equilibrate 20.00 °C; Isothermal 5000.0 min
[File Parameters]
Run date	8/9/2023 2:41:47 PM
Trios version	5.1.1.46572
Original File Name	C:\Users\yargerlab\Desktop\DSC Data\General\2023_08_09_CBD_simple_fragility_SBK.tri
Current File Name	C:\Users\kauff\Documents\ASU\data_DSC\2023_08_09_CBD_simple_fragility_SBK.tri
[Procedure]
Procedure Name	DSC -50C to 40C Varied cooling rates CBD fragility
Sample Name	2023_08_09_CBD_simple_fragility_SBK
Sample Mass	7.3 mg
Reference Sample Mass	0 mg
Pan Mass	54.38 mg
Pan Number	24
Reference Pan Mass	53.72 mg
Reference Pan Number	37
Pan Type	Aluminum Hermetic
Comments	CBD powder, crystaline, newly prepared sample. DSC84010 aluminum pan and DSC84011 aluminum hermetic lid.
Project Name	Silk ASDs
Operator	SBK
Test	Custom
Unload Max Temperature	30
Unload Min Temperature	30
Load Max Temperature	30
Load Min Temperature	30
Stop on Gas Flow Error	Yes
[Signal List]
Signal #1	Time (min)
Signal #2	Temperature (°C)
Signal #3	Heat Flow (mW)
Signal #4	Delta T (µV)
Signal #5	Delta Tzero (µV)
Signal #6	Tzero Temperature (°C)
Signal #7	Cell Purge (mL/min)
Signal #8	Heater Temp (°C)
Signal #9	Power Delivered (W)
Signal #10	Reference Junction Temperature (°C)
Signal #11	Flange Temperature (°C)
Signal #12	Heat Flow Phase (rad)
Signal #13	Total Heat Capacity (J/°C)
Signal #14	Heat Capacity (J/°C)
[Configuration]
Company Name	ASU
Instrument Name	DSC2A-00468
Instrument Type	DSC2500
Serial Number	DSC2A-00468
IP	192.168.1.100
Location of Instrument	MRRC
DisplayType	Unknown
Sample Interval 	0.1 s/pt
Selected Heat Flow	T4P
Exotherm Direction	Down
Cell Serial	DRC2-00792
Lid Type	Standard
Cooler	RCS 90
Leave Cooler on at End of Sequence	On
Gas 2	Nitrogen
Gas Selected	Channel 1
Flow Rate	50 mL/min
Secondary Purge	On
Licensed Heat Flow	Heat Flow T4P
Modulation Licensed	Yes
[Versions]
Common IDD Version	1
Cortex Version	VER 2.10.2.31
Driver	5.0.0.6
GDM Version	1.0.3.3
TouchscreenVersion	1.0.0.16145
FEP Version	1.2.1.21
FEP Bootloader	2.0.0.5
AutoSampler Version	2.1.1.26
Auto Sampler Bootloader	2.0.0.5
FCM Version	1.1.0.3
FCM Bootloader	2.0.0.5
[Experiment Logs]
Experiment Log Entry # 1	Air Cool is off.
Experiment Log Entry # 3	Data On set to 0
Experiment Log Entry # 5	Equilibrate Segment -50 (C) Started
Experiment Log Entry # 7	Data On set to 1
Experiment Log Entry # 9	Ramp Segment 10 C/min to 100 Started
Experiment Log Entry # 11	Data On set to 0
Experiment Log Entry # 13	Isothermal Segment 1 min started
Experiment Log Entry # 15	Data On set to 1
Experiment Log Entry # 17	Ramp Segment 10 C/min to -55 Started
Experiment Log Entry # 19	Data On set to 0
Experiment Log Entry # 21	Isothermal Segment 1 min started
Experiment Log Entry # 23	Data On set to 1
Experiment Log Entry # 25	Ramp Segment 10 C/min to 40 Started
Experiment Log Entry # 27	Data On set to 0
Experiment Log Entry # 29	Isothermal Segment 1 min started
Experiment Log Entry # 31	Data On set to 1
Experiment Log Entry # 33	Ramp Segment 10 C/min to -55 Started
Experiment Log Entry # 35	Data On set to 0
Experiment Log Entry # 37	Isothermal Segment 1 min started
Experiment Log Entry # 39	Data On set to 1
Experiment Log Entry # 41	Ramp Segment 10 C/min to 40 Started
Experiment Log Entry # 43	Data On set to 0
Experiment Log Entry # 45	Isothermal Segment 1 min started
Experiment Log Entry # 47	Data On set to 1
Experiment Log Entry # 49	Ramp Segment 10 C/min to -55 Started
Experiment Log Entry # 51	Data On set to 0
Experiment Log Entry # 53	Isothermal Segment 1 min started
Experiment Log Entry # 55	Data On set to 1
Experiment Log Entry # 57	Ramp Segment 10 C/min to 40 Started
Experiment Log Entry # 59	Data On set to 0
Experiment Log Entry # 61	Isothermal Segment 1 min started
Experiment Log Entry # 63	Data On set to 1
Experiment Log Entry # 65	Ramp Segment 40 C/min to -55 Started
Experiment Log Entry # 67	Data On set to 0
Experiment Log Entry # 69	Isothermal Segment 1 min started
Experiment Log Entry # 71	Data On set to 1
Experiment Log Entry # 73	Ramp Segment 10 C/min to 40 Started
Experiment Log Entry # 75	Data On set to 0
Experiment Log Entry # 77	Isothermal Segment 1 min started
Experiment Log Entry # 79	Data On set to 1
Experiment Log Entry # 81	Ramp Segment 20 C/min to -55 Started
Experiment Log Entry # 83	Data On set to 0
Experiment Log Entry # 85	Isothermal Segment 1 min started
Experiment Log Entry # 87	Data On set to 1
Experiment Log Entry # 89	Ramp Segment 10 C/min to 40 Started
Experiment Log Entry # 91	Data On set to 0
Experiment Log Entry # 93	Isothermal Segment 1 min started
Experiment Log Entry # 95	Data On set to 1
Experiment Log Entry # 97	Ramp Segment 5 C/min to -55 Started
Experiment Log Entry # 99	Data On set to 0
Experiment Log Entry # 101	Isothermal Segment 1 min started
Experiment Log Entry # 103	Data On set to 1
Experiment Log Entry # 105	Ramp Segment 10 C/min to 40 Started
Experiment Log Entry # 107	Data On set to 0
Experiment Log Entry # 109	Isothermal Segment 1 min started
Experiment Log Entry # 111	Data On set to 1
Experiment Log Entry # 113	Sampling Rate set to 1 sec/pt
Experiment Log Entry # 115	Ramp Segment 1 C/min to -55 Started
Experiment Log Entry # 117	Sampling Rate set to 0.1 sec/pt
Experiment Log Entry # 119	Data On set to 0
Experiment Log Entry # 121	Isothermal Segment 1 min started
Experiment Log Entry # 123	Data On set to 1
Experiment Log Entry # 125	Ramp Segment 10 C/min to 40 Started
Experiment Log Entry # 127	Data On set to 0
Experiment Log Entry # 129	Isothermal Segment 1 min started
Experiment Log Entry # 131	Data On set to 1
Experiment Log Entry # 133	Sampling Rate set to 2 sec/pt
Experiment Log Entry # 135	Ramp Segment 0.5 C/min to -55 Started
Experiment Log Entry # 137	Sampling Rate set to 0.1 sec/pt
Experiment Log Entry # 139	Data On set to 0
Experiment Log Entry # 141	Isothermal Segment 1 min started
Experiment Log Entry # 143	Data On set to 1
Experiment Log Entry # 145	Ramp Segment 10 C/min to 40 Started
Experiment Log Entry # 147	Data On set to 0
Experiment Log Entry # 149	Isothermal Segment 1 min started
Experiment Log Entry # 151	Data On set to 1
Experiment Log Entry # 153	Ramp Segment 10 C/min to -55 Started
Experiment Log Entry # 155	Data On set to 0
Experiment Log Entry # 157	Isothermal Segment 1 min started
Experiment Log Entry # 159	Data On set to 1
Experiment Log Entry # 161	Ramp Segment 10 C/min to 40 Started
Experiment Log Entry # 163	Data On set to 0
Experiment Log Entry # 165	Equilibrate Segment 20 (C) Started
Experiment Log Entry # 167	Isothermal Segment 5000 min started
Experiment Log Entry # 169	Auto sampler has detected that GDM has gone offline
Experiment Log Entry # 171	An attempt to access flash memory was unsuccessful (ErrCode=3, FlashLoc=5, IsWrite=0).
Experiment Log Entry # 173	Ending Experiment because user stopped
[Method Log]
Method Log Entry # 1	Data Off
Method Log Entry # 2	Equilibrate -50 °C
Method Log Entry # 3	Data On
Method Log Entry # 4	(Ramp 3840052) Ramp 10 °C/minute to 100 °C
Method Log Entry # 5	Data Off
Method Log Entry # 6	Isothermal 1 minutes
Method Log Entry # 7	Data On
Method Log Entry # 8	(Ramp 3840056) Ramp 10 °C/minute to -55 °C
Method Log Entry # 9	Data Off
Method Log Entry # 10	Isothermal 1 minutes
Method Log Entry # 11	Data On
Method Log Entry # 12	(Ramp 3840060) Ramp 10 °C/minute to 40 °C
Method Log Entry # 13	Data Off
Method Log Entry # 14	Isothermal 1 minutes
Method Log Entry # 15	Data On
Method Log Entry # 16	(Ramp 3840064) Ramp 10 °C/minute to -55 °C
Method Log Entry # 17	Data Off
Method Log Entry # 18	Isothermal 1 minutes
Method Log Entry # 19	Data On
Method Log Entry # 20	(Ramp 3840068) Ramp 10 °C/minute to 40 °C
Method Log Entry # 21	Data Off
Method Log Entry # 22	Isothermal 1 minutes
Method Log Entry # 23	Data On
Method Log Entry # 24	(Ramp 3840072) Ramp 10 °C/minute to -55 °C
Method Log Entry # 25	Data Off
Method Log Entry # 26	Isothermal 1 minutes
Method Log Entry # 27	Data On
Method Log Entry # 28	(Ramp 3840076) Ramp 10 °C/minute to 40 °C
Method Log Entry # 29	Data Off
Method Log Entry # 30	Isothermal 1 minutes
Method Log Entry # 31	Data On
Method Log Entry # 32	(Ramp 3840080) Ramp 40 °C/minute to -55 °C
Method Log Entry # 33	Data Off
Method Log Entry # 34	Isothermal 1 minutes
Method Log Entry # 35	Data On
Method Log Entry # 36	(Ramp 3840084) Ramp 10 °C/minute to 40 °C
Method Log Entry # 37	Data Off
Method Log Entry # 38	Isothermal 1 minutes
Method Log Entry # 39	Data On
Method Log Entry # 40	(Ramp 3840088) Ramp 20 °C/minute to -55 °C
Method Log Entry # 41	Data Off
Method Log Entry # 42	Isothermal 1 minutes
Method Log Entry # 43	Data On
Method Log Entry # 44	(Ramp 3840092) Ramp 10 °C/minute to 40 °C
Method Log Entry # 45	Data Off
Method Log Entry # 46	Isothermal 1 minutes
Method Log Entry # 47	Data On
Method Log Entry # 48	(Ramp 3840096) Ramp 5 °C/minute to -55 °C
Method Log Entry # 49	Data Off
Method Log Entry # 50	Isothermal 1 minutes
Method Log Entry # 51	Data On
Method Log Entry # 52	(Ramp 3840100) Ramp 10 °C/minute to 40 °C
Method Log Entry # 53	Data Off
Method Log Entry # 54	Isothermal 1 minutes
Method Log Entry # 55	Data On
Method Log Entry # 56	Sampling Interval 1 Seconds/point
Method Log Entry # 57	(Ramp 3840105) Ramp 1 °C/minute to -55 °C
Method Log Entry # 58	Sampling Interval 0.1 Seconds/point
Method Log Entry # 59	Data Off
Method Log Entry # 60	Isothermal 1 minutes
Method Log Entry # 61	Data On
Method Log Entry # 62	(Ramp 3840110) Ramp 10 °C/minute to 40 °C
Method Log Entry # 63	Data Off
Method Log Entry # 64	Isothermal 1 minutes
Method Log Entry # 65	Data On
Method Log Entry # 66	Sampling Interval 2 Seconds/point
Method Log Entry # 67	(Ramp 3840115) Ramp 0.5 °C/minute to -55 °C
Method Log Entry # 68	Sampling Interval 0.1 Seconds/point
Method Log Entry # 69	Data Off
Method Log Entry # 70	Isothermal 1 minutes
Method Log Entry # 71	Data On
Method Log Entry # 72	(Ramp 3840120) Ramp 10 °C/minute to 40 °C
Method Log Entry # 73	Data Off
Method Log Entry # 74	Isothermal 1 minutes
Method Log Entry # 75	Data On
Method Log Entry # 76	(Ramp 3840124) Ramp 10 °C/minute to -55 °C
Method Log Entry # 77	Data Off
Method Log Entry # 78	Isothermal 1 minutes
Method Log Entry # 79	Data On
Method Log Entry # 80	(Ramp 3840128) Ramp 10 °C/minute to 40 °C
Method Log Entry # 81	Data Off
Method Log Entry # 82	Equilibrate 20 °C
Method Log Entry # 83	Isothermal 5000 minutes
Cell Serial	DRC2-00792
[T1 Calibration]
Slope	-0.008529666
Offset	9.636258
Initial Temperature	98.23
GUID	f8bfdadc-4977-4fdf-ba6d-0ba9134940c3
[TZero Calibration]
Date Applied	11/29/2022 4:06:13 PM
Description	From -89.059 °C to 396.009 °C at 20.000°C/min
Gas Type	Nitrogen
Pan Type	None
Source Files 1	C:\Users\yargerlab\Desktop\DSC Data\General\TZero_calibration_11_29_22_2nd(2).tri
Source Files 2	C:\Users\yargerlab\Desktop\DSC Data\General\TZero_calibration_11_29_22_2nd(3).tri
Delta T Offset	13.05235
Delta T Slope	-0.007271007
Delta T0 Offset	-13.69128
Delta T0 Slope	0.06063341
[Temperature Calibration]
Date Applied	11/29/2022 7:12:28 PM
Description	From 106.590 °C to 186.590 °C at 10.000°C/min
Gas Type	Nitrogen
Pan Type	Tzero Aluminum Hermetic
Source Files 1	C:\Users\yargerlab\Desktop\DSC Data\General\Indium(6).tri
Measured 1	157.391
Known 1	156.598
[Cell Constant Calibration]
Date Applied	11/29/2022 7:12:29 PM
Description	From 106.590 °C to 186.590 °C at 10.000°C/min
Gas Type	Nitrogen
Pan Type	Tzero Aluminum Hermetic
Source Files 1	C:\Users\yargerlab\Desktop\DSC Data\General\Indium(6).tri
T4P KCell	1.006051
Onset Slope	63.26126 mW/°C
[Direct Cp Calibration]
Date Applied	11/30/2022 11:04:51 AM
Description	From -79.983 °C to 298.409 °C at 10.000°C/min
Gas Type	Nitrogen
Pan Type	Tzero Aluminum Hermetic
Source Files 1	C:\Users\yargerlab\Desktop\DSC Data\General\Sapphire_Heat_Capacity_11_30_22.tri
[Rev Cp Calibration]
Date Applied	11/30/2022 1:58:51 PM
Description	From -79.996 °C to 292.812 °C at 3.000°C/min
Gas Type	Nitrogen
Pan Type	Tzero Aluminum Hermetic
Source Files 1	C:\Users\yargerlab\Desktop\DSC Data\General\Sapphire_MDSC_Calibration_11_30_22.tri
[step]
Ramp 10.00 °C/min to 100.00 °C
Time	Temperature	Heat Flow (Normalized)	Heat Capacity (Normalized)
min	°C	W/g	J/(g.°C)
0.00	-49.69	-0.049	0.000
0.01	-49.70	-0.050	11.901
0.02	-49.71	-0.047	0.000
0.03	-49.71	-0.044	0.000
0.04	-49.71	-0.041	0.000
0.05	-49.72	-0.038	0.000
0.06	-49.71	-0.036	0.000
0.07	-49.71	-0.034	-1.159
0.08	-49.70	-0.032	-0.871
0.09	-49.68	-0.030	-0.676
0.10	-49.66	-0.026	-0.503
0.11	-49.63	-0.021	-0.362
0.12	-49.60	-0.016	-0.235
0.13	-49.56	-0.009	-0.117
0.14	-49.52	-0.001	-0.009
0.15	-49.47	0.009	0.096
0.16	-49.42	0.019	0.190
0.17	-49.36	0.029	0.276
0.18	-49.30	0.040	0.358
0.19	-49.23	0.051	0.430
0.20	-49.16	0.062	0.498
0.21	-49.09	0.073	0.561
0.22	-49.02	0.084	0.616
0.23	-48.94	0.094	0.666
0.24	-48.86	0.102	0.707
0.25	-48.78	0.111	0.746
0.26	-48.70	0.120	0.792
0.27	-48.62	0.127	0.820
0.28	-48.53	0.134	0.848
0.29	-48.45	0.140	0.870
0.30	-48.36	0.146	0.899
0.31	-48.28	0.151	0.919
0.32	-48.19	0.158	0.946
0.33	-48.10	0.162	0.963
0.34	-48.02	0.165	0.975
0.35	-47.92	0.171	0.998
0.36	-47.83	0.173	1.006
0.37	-47.74	0.177	1.022
0.38	-47.65	0.180	1.030
0.39	-47.56	0.184	1.044
0.40	-47.47	0.186	1.053
0.41	-47.38	0.189	1.065
0.42	-47.28	0.191	1.070
0.43	-47.19	0.193	1.077
0.44	-47.10	0.195	1.086
0.45	-47.00	0.197	1.091
0.46	-46.91	0.199	1.098
0.47	-46.81	0.201	1.108
0.48	-46.72	0.201	1.107
0.49	-46.62	0.204	1.119
0.50	-46.53	0.204	1.116
0.51	-46.43	0.206	1.122
0.52	-46.34	0.207	1.124
0.53	-46.24	0.207	1.126
0.54	-46.14	0.208	1.130
0.55	-46.05	0.210	1.134
0.56	-45.95	0.210	1.138
0.57	-45.86	0.211	1.138
0.58	-45.76	0.212	1.142
0.59	-45.66	0.212	1.142
0.60	-45.57	0.213	1.144
0.61	-45.47	0.213	1.146
0.62	-45.37	0.214	1.150
0.63	-45.28	0.214	1.149
0.64	-45.18	0.215	1.151
0.65	-45.08	0.215	1.151
0.66	-44.98	0.215	1.151
0.67	-44.89	0.216	1.152
0.68	-44.79	0.216	1.153
0.69	-44.69	0.216	1.154
0.70	-44.59	0.216	1.155
0.71	-44.50	0.217	1.157
0.72	-44.40	0.217	1.157
0.73	-44.30	0.217	1.157
0.74	-44.20	0.217	1.157
0.75	-44.10	0.218	1.158
0.76	-44.01	0.218	1.158
0.77	-43.91	0.218	1.158
0.78	-43.81	0.218	1.159
0.79	-43.71	0.218	1.160
0.80	-43.61	0.219	1.161
0.81	-43.51	0.219	1.161
0.82	-43.42	0.219	1.162
0.83	-43.32	0.219	1.163
0.84	-43.22	0.219	1.164
0.85	-43.12	0.220	1.164
0.86	-43.02	0.220	1.164
0.87	-42.92	0.220	1.164
0.88	-42.83	0.220	1.165
0.89	-42.73	0.220	1.165
0.90	-42.63	0.220	1.166
0.91	-42.53	0.221	1.167
0.92	-42.43	0.221	1.168
0.93	-42.33	0.221	1.168
0.94	-42.23	0.221	1.168
0.95	-42.13	0.221	1.170
0.96	-42.04	0.221	1.170
0.97	-41.94	0.221	1.170
0.98	-41.84	0.222	1.171
0.99	-41.74	0.222	1.171
1.00	-41.64	0.222	1.171
1.01	-41.54	0.222	1.172
1.02	-41.44	0.222	1.172
1.03	-41.34	0.222	1.173
1.04	-41.24	0.222	1.174
1.05	-41.15	0.223	1.174
1.06	-41.05	0.223	1.175
1.07	-40.95	0.223	1.175
1.08	-40.85	0.223	1.175
1.09	-40.75	0.223	1.176
1.10	-40.65	0.223	1.176
1.11	-40.55	0.223	1.177
1.12	-40.45	0.223	1.177
1.13	-40.35	0.223	1.177
1.14	-40.25	0.223	1.178
1.15	-40.15	0.224	1.178
1.16	-40.05	0.224	1.178
1.17	-39.95	0.224	1.180
1.18	-39.85	0.224	1.179
1.19	-39.76	0.224	1.180
1.20	-39.66	0.224	1.181
1.21	-39.56	0.224	1.181
1.22	-39.46	0.224	1.182
1.23	-39.36	0.225	1.182
1.24	-39.26	0.225	1.182
1.25	-39.16	0.225	1.183
1.26	-39.06	0.225	1.184
1.27	-38.96	0.225	1.184
1.28	-38.86	0.225	1.185
1.29	-38.76	0.225	1.185
1.30	-38.66	0.225	1.185
1.31	-38.56	0.225	1.185
1.32	-38.46	0.225	1.186
1.33	-38.36	0.226	1.186
1.34	-38.26	0.226	1.186
1.35	-38.16	0.226	1.188
1.36	-38.07	0.226	1.188
1.37	-37.96	0.226	1.188
1.38	-37.87	0.226	1.189
1.39	-37.77	0.226	1.189
1.40	-37.67	0.226	1.189
1.41	-37.57	0.226	1.191
1.42	-37.47	0.226	1.191
1.43	-37.37	0.226	1.192
1.44	-37.27	0.227	1.192
1.45	-37.17	0.227	1.192
1.46	-37.07	0.227	1.193
1.47	-36.97	0.227	1.194
1.48	-36.87	0.227	1.194
1.49	-36.77	0.227	1.195
1.50	-36.67	0.227	1.195
1.51	-36.57	0.227	1.196
1.52	-36.47	0.227	1.196
1.53	-36.37	0.227	1.196
1.54	-36.27	0.227	1.197
1.55	-36.17	0.228	1.197
1.56	-36.07	0.228	1.198
1.57	-35.97	0.228	1.198
1.58	-35.87	0.228	1.198
1.59	-35.77	0.228	1.199
1.60	-35.67	0.228	1.199
1.61	-35.57	0.228	1.198
1.62	-35.47	0.228	1.199
1.63	-35.37	0.228	1.200
1.64	-35.27	0.228	1.200
1.65	-35.17	0.228	1.200
1.66	-35.07	0.228	1.201
1.67	-34.97	0.228	1.200
1.68	-34.87	0.228	1.201
1.69	-34.77	0.228	1.201
1.70	-34.67	0.228	1.202
1.71	-34.57	0.229	1.203
1.72	-34.47	0.229	1.204
1.73	-34.37	0.229	1.204
1.74	-34.27	0.229	1.204
1.75	-34.17	0.229	1.204
1.76	-34.07	0.229	1.205
1.77	-33.97	0.229	1.205
1.78	-33.87	0.229	1.206
1.79	-33.77	0.229	1.206
1.80	-33.67	0.229	1.206
1.81	-33.57	0.229	1.207
1.82	-33.47	0.229	1.207
1.83	-33.37	0.229	1.207
1.84	-33.27	0.229	1.208
1.85	-33.17	0.229	1.208
1.86	-33.07	0.229	1.208
1.87	-32.97	0.230	1.209
1.88	-32.87	0.230	1.209
1.89	-32.77	0.230	1.210
1.90	-32.67	0.230	1.210
1.91	-32.57	0.230	1.210
1.92	-32.47	0.230	1.210
1.93	-32.37	0.230	1.211
1.94	-32.27	0.230	1.211
1.95	-32.17	0.230	1.212
1.96	-32.07	0.230	1.211
1.97	-31.97	0.230	1.213
1.98	-31.87	0.230	1.212
1.99	-31.77	0.230	1.212
2.00	-31.67	0.230	1.213
2.01	-31.57	0.230	1.214
2.02	-31.47	0.230	1.213
2.03	-31.37	0.230	1.214
2.04	-31.27	0.230	1.215
2.05	-31.17	0.230	1.215
2.06	-31.07	0.231	1.216
2.07	-30.97	0.231	1.216
2.08	-30.87	0.231	1.216
2.09	-30.77	0.231	1.216
2.10	-30.67	0.231	1.216
2.11	-30.57	0.231	1.217
2.12	-30.47	0.231	1.218
2.13	-30.37	0.231	1.218
2.14	-30.27	0.231	1.217
2.15	-30.17	0.231	1.218
2.16	-30.07	0.231	1.219
2.17	-29.97	0.231	1.219
2.18	-29.87	0.231	1.219
2.19	-29.77	0.231	1.219
2.20	-29.67	0.231	1.220
2.21	-29.57	0.231	1.220
2.22	-29.47	0.231	1.220
2.23	-29.37	0.231	1.221
2.24	-29.27	0.231	1.221
2.25	-29.17	0.231	1.220
2.26	-29.07	0.232	1.221
2.27	-28.97	0.232	1.222
2.28	-28.87	0.232	1.222
2.29	-28.77	0.232	1.223
2.30	-28.67	0.232	1.223
2.31	-28.57	0.232	1.224
2.32	-28.47	0.232	1.224
2.33	-28.37	0.232	1.225
2.34	-28.27	0.232	1.225
2.35	-28.17	0.232	1.226
2.36	-28.07	0.232	1.226
2.37	-27.97	0.232	1.226
2.38	-27.87	0.232	1.226
2.39	-27.77	0.232	1.226
2.40	-27.67	0.232	1.227
2.41	-27.57	0.232	1.227
2.42	-27.47	0.232	1.228
2.43	-27.37	0.232	1.228
2.44	-27.27	0.232	1.228
2.45	-27.17	0.232	1.229
2.46	-27.07	0.232	1.229
2.47	-26.97	0.233	1.229
2.48	-26.87	0.233	1.229
2.49	-26.77	0.233	1.229
2.50	-26.67	0.233	1.230
2.51	-26.57	0.233	1.231
2.52	-26.47	0.233	1.230
2.53	-26.37	0.233	1.230
2.54	-26.27	0.233	1.231
2.55	-26.17	0.233	1.231
2.56	-26.07	0.233	1.232
2.57	-25.97	0.233	1.232
2.58	-25.87	0.233	1.232
2.59	-25.77	0.233	1.233
2.60	-25.67	0.233	1.234
2.61	-25.57	0.233	1.234
2.62	-25.47	0.233	1.233
2.63	-25.37	0.233	1.234
2.64	-25.27	0.233	1.235
2.65	-25.17	0.233	1.235
2.66	-25.07	0.233	1.235
2.67	-24.97	0.234	1.235
2.68	-24.87	0.234	1.236
2.69	-24.77	0.234	1.237
2.70	-24.67	0.234	1.237
2.71	-24.57	0.234	1.236
2.72	-24.47	0.234	1.237
2.73	-24.37	0.234	1.238
2.74	-24.27	0.234	1.238
2.75	-24.17	0.234	1.238
2.76	-24.07	0.234	1.239
2.77	-23.96	0.234	1.240
2.78	-23.87	0.234	1.240
2.79	-23.77	0.234	1.240
2.80	-23.67	0.234	1.239
2.81	-23.57	0.234	1.240
2.82	-23.46	0.234	1.241
2.83	-23.37	0.234	1.241
2.84	-23.26	0.234	1.241
2.85	-23.16	0.234	1.242
2.86	-23.07	0.234	1.242
2.87	-22.97	0.234	1.242
2.88	-22.87	0.235	1.242
2.89	-22.76	0.235	1.242
2.90	-22.66	0.235	1.243
2.91	-22.56	0.235	1.243
2.92	-22.46	0.235	1.244
2.93	-22.36	0.235	1.244
2.94	-22.26	0.235	1.244
2.95	-22.16	0.235	1.245
2.96	-22.06	0.235	1.245
2.97	-21.96	0.235	1.245
2.98	-21.86	0.235	1.246
2.99	-21.76	0.235	1.246
3.00	-21.66	0.235	1.247
3.01	-21.56	0.235	1.248
3.02	-21.46	0.235	1.248
3.03	-21.36	0.235	1.248
3.04	-21.26	0.235	1.249
3.05	-21.16	0.236	1.249
3.06	-21.06	0.236	1.249
3.07	-20.96	0.236	1.250
3.08	-20.86	0.236	1.250
3.09	-20.76	0.236	1.251
3.10	-20.66	0.236	1.251
3.11	-20.56	0.236	1.250
3.12	-20.46	0.236	1.251
3.13	-20.36	0.236	1.252
3.14	-20.26	0.236	1.252
3.15	-20.16	0.236	1.252
3.16	-20.06	0.236	1.252
3.17	-19.96	0.236	1.253
3.18	-19.86	0.236	1.253
3.19	-19.76	0.236	1.253
3.20	-19.66	0.236	1.254
3.21	-19.56	0.236	1.254
3.22	-19.46	0.236	1.255
3.23	-19.36	0.236	1.255
3.24	-19.26	0.236	1.255
3.25	-19.16	0.237	1.256
3.26	-19.06	0.237	1.255
3.27	-18.96	0.237	1.256
3.28	-18.86	0.237	1.257
3.29	-18.76	0.237	1.256
3.30	-18.66	0.237	1.257
3.31	-18.56	0.237	1.258
3.32	-18.46	0.237	1.258
3.33	-18.36	0.237	1.257
3.34	-18.26	0.237	1.258
3.35	-18.16	0.237	1.259
3.36	-18.06	0.237	1.259
3.37	-17.96	0.237	1.259
3.38	-17.86	0.237	1.259
3.39	-17.76	0.237	1.260
3.40	-17.66	0.237	1.260
3.41	-17.56	0.237	1.260
3.42	-17.46	0.237	1.260
3.43	-17.36	0.237	1.261
3.44	-17.26	0.237	1.261
3.45	-17.16	0.237	1.261
3.46	-17.06	0.238	1.262
3.47	-16.96	0.238	1.262
3.48	-16.86	0.238	1.263
3.49	-16.76	0.238	1.264
3.50	-16.66	0.238	1.264
3.51	-16.56	0.238	1.264
3.52	-16.46	0.238	1.264
3.53	-16.36	0.238	1.264
3.54	-16.26	0.238	1.265
3.55	-16.16	0.238	1.265
3.56	-16.06	0.238	1.265
3.57	-15.96	0.238	1.266
3.58	-15.86	0.238	1.266
3.59	-15.76	0.238	1.266
3.60	-15.66	0.238	1.266
3.61	-15.56	0.238	1.267
3.62	-15.46	0.238	1.268
3.63	-15.36	0.238	1.267
3.64	-15.26	0.238	1.268
3.65	-15.16	0.239	1.269
3.66	-15.06	0.239	1.268
3.67	-14.96	0.239	1.269
3.68	-14.86	0.239	1.270
3.69	-14.75	0.239	1.270
3.70	-14.66	0.239	1.270
3.71	-14.55	0.239	1.270
3.72	-14.45	0.239	1.270
3.73	-14.36	0.239	1.271
3.74	-14.26	0.239	1.271
3.75	-14.16	0.239	1.271
3.76	-14.05	0.239	1.272
3.77	-13.95	0.239	1.272
3.78	-13.86	0.239	1.273
3.79	-13.75	0.239	1.273
3.80	-13.65	0.239	1.273
3.81	-13.55	0.239	1.274
3.82	-13.45	0.239	1.274
3.83	-13.35	0.239	1.274
3.84	-13.25	0.239	1.275
3.85	-13.15	0.239	1.275
3.86	-13.05	0.239	1.276
3.87	-12.95	0.239	1.276
3.88	-12.85	0.239	1.275
3.89	-12.75	0.240	1.276
3.90	-12.65	0.240	1.276
3.91	-12.55	0.240	1.277
3.92	-12.45	0.240	1.276
3.93	-12.35	0.240	1.277
3.94	-12.25	0.240	1.277
3.95	-12.15	0.240	1.278
3.96	-12.05	0.240	1.278
3.97	-11.95	0.240	1.278
3.98	-11.85	0.240	1.278
3.99	-11.75	0.240	1.279
4.00	-11.65	0.240	1.279
4.01	-11.55	0.240	1.279
4.02	-11.45	0.240	1.279
4.03	-11.35	0.240	1.280
4.04	-11.25	0.240	1.280
4.05	-11.15	0.240	1.281
4.06	-11.05	0.240	1.281
4.07	-10.95	0.240	1.282
4.08	-10.85	0.240	1.281
4.09	-10.75	0.240	1.282
4.10	-10.65	0.240	1.282
4.11	-10.55	0.241	1.283
4.12	-10.45	0.241	1.283
4.13	-10.35	0.241	1.283
4.14	-10.25	0.241	1.284
4.15	-10.15	0.241	1.284
4.16	-10.05	0.241	1.285
4.17	-9.95	0.241	1.285
4.18	-9.85	0.241	1.285
4.19	-9.75	0.241	1.286
4.20	-9.65	0.241	1.286
4.21	-9.55	0.241	1.286
4.22	-9.45	0.241	1.287
4.23	-9.35	0.241	1.287
4.24	-9.25	0.241	1.287
4.25	-9.15	0.241	1.287
4.26	-9.05	0.241	1.287
4.27	-8.95	0.241	1.288
4.28	-8.85	0.242	1.288
4.29	-8.75	0.242	1.289
4.30	-8.65	0.242	1.289
4.31	-8.55	0.242	1.289
4.32	-8.45	0.242	1.290
4.33	-8.35	0.242	1.290
4.34	-8.25	0.242	1.291
4.35	-8.15	0.242	1.291
4.36	-8.05	0.242	1.292
4.37	-7.95	0.242	1.292
4.38	-7.85	0.242	1.292
4.39	-7.75	0.242	1.293
4.40	-7.65	0.242	1.293
4.41	-7.55	0.242	1.293
4.42	-7.45	0.242	1.294
4.43	-7.35	0.242	1.294
4.44	-7.25	0.242	1.295
4.45	-7.15	0.242	1.295
4.46	-7.05	0.243	1.295
4.47	-6.95	0.243	1.296
4.48	-6.85	0.243	1.296
4.49	-6.75	0.243	1.296
4.50	-6.65	0.243	1.297
4.51	-6.55	0.243	1.297
4.52	-6.45	0.243	1.297
4.53	-6.35	0.243	1.297
4.54	-6.25	0.243	1.298
4.55	-6.15	0.243	1.298
4.56	-6.05	0.243	1.298
4.57	-5.95	0.243	1.298
4.58	-5.85	0.243	1.299
4.59	-5.75	0.243	1.300
4.60	-5.65	0.243	1.300
4.61	-5.55	0.243	1.300
4.62	-5.44	0.243	1.300
4.63	-5.35	0.243	1.300
4.64	-5.25	0.244	1.301
4.65	-5.14	0.244	1.302
4.66	-5.05	0.244	1.302
4.67	-4.94	0.244	1.303
4.68	-4.84	0.244	1.303
4.69	-4.75	0.244	1.303
4.70	-4.64	0.244	1.303
4.71	-4.54	0.244	1.303
4.72	-4.44	0.244	1.304
4.73	-4.34	0.244	1.304
4.74	-4.24	0.244	1.305
4.75	-4.14	0.244	1.306
4.76	-4.04	0.244	1.306
4.77	-3.94	0.244	1.307
4.78	-3.84	0.245	1.308
4.79	-3.74	0.245	1.307
4.80	-3.64	0.245	1.308
4.81	-3.54	0.245	1.309
4.82	-3.44	0.245	1.309
4.83	-3.34	0.245	1.309
4.84	-3.24	0.245	1.309
4.85	-3.14	0.245	1.309
4.86	-3.04	0.245	1.310
4.87	-2.94	0.245	1.310
4.88	-2.84	0.245	1.310
4.89	-2.74	0.245	1.311
4.90	-2.64	0.245	1.311
4.91	-2.54	0.245	1.311
4.92	-2.44	0.245	1.312
4.93	-2.34	0.245	1.313
4.94	-2.24	0.246	1.313
4.95	-2.14	0.246	1.313
4.96	-2.04	0.246	1.313
4.97	-1.94	0.246	1.314
4.98	-1.84	0.246	1.314
4.99	-1.74	0.246	1.314
5.00	-1.64	0.246	1.315
5.01	-1.54	0.246	1.315
5.02	-1.44	0.246	1.316
5.03	-1.34	0.246	1.316
5.04	-1.24	0.246	1.317
5.05	-1.14	0.246	1.317
5.06	-1.04	0.247	1.318
5.07	-0.94	0.247	1.318
5.08	-0.84	0.247	1.319
5.09	-0.74	0.247	1.319
5.10	-0.64	0.247	1.320
5.11	-0.54	0.247	1.320
5.12	-0.44	0.247	1.319
5.13	-0.34	0.247	1.320
5.14	-0.24	0.247	1.320
5.15	-0.14	0.247	1.321
5.16	-0.04	0.247	1.321
5.17	0.06	0.247	1.322
5.18	0.16	0.247	1.322
5.19	0.26	0.247	1.323
5.20	0.36	0.247	1.322
5.21	0.46	0.247	1.323
5.22	0.56	0.247	1.324
5.23	0.66	0.247	1.324
5.24	0.76	0.248	1.324
5.25	0.86	0.248	1.324
5.26	0.96	0.248	1.325
5.27	1.06	0.248	1.325
5.28	1.16	0.248	1.325
5.29	1.26	0.248	1.326
5.30	1.36	0.248	1.326
5.31	1.46	0.248	1.326
5.32	1.56	0.248	1.327
5.33	1.66	0.248	1.327
5.34	1.76	0.248	1.327
5.35	1.87	0.248	1.328
5.36	1.96	0.248	1.328
5.37	2.06	0.248	1.328
5.38	2.16	0.248	1.329
5.39	2.26	0.248	1.329
5.40	2.37	0.249	1.330
5.41	2.46	0.249	1.330
5.42	2.57	0.249	1.330
5.43	2.67	0.249	1.330
5.44	2.77	0.249	1.331
5.45	2.87	0.249	1.332
5.46	2.97	0.249	1.332
5.47	3.07	0.249	1.332
5.48	3.17	0.249	1.333
5.49	3.27	0.249	1.333
5.50	3.37	0.249	1.334
5.51	3.47	0.249	1.334
5.52	3.57	0.249	1.334
5.53	3.67	0.249	1.335
5.54	3.77	0.250	1.335
5.55	3.87	0.250	1.335
5.56	3.97	0.250	1.336
5.57	4.07	0.250	1.336
5.58	4.17	0.250	1.336
5.59	4.27	0.250	1.336
5.60	4.37	0.250	1.337
5.61	4.47	0.250	1.337
5.62	4.57	0.250	1.338
5.63	4.67	0.250	1.339
5.64	4.77	0.250	1.338
5.65	4.87	0.250	1.338
5.66	4.97	0.250	1.339
5.67	5.07	0.250	1.340
5.68	5.17	0.250	1.340
5.69	5.27	0.251	1.341
5.70	5.37	0.251	1.340
5.71	5.47	0.251	1.341
5.72	5.57	0.251	1.342
5.73	5.67	0.251	1.341
5.74	5.77	0.251	1.342
5.75	5.87	0.251	1.343
5.76	5.97	0.251	1.343
5.77	6.07	0.251	1.343
5.78	6.17	0.251	1.343
5.79	6.27	0.251	1.344
5.80	6.37	0.251	1.345
5.81	6.47	0.251	1.344
5.82	6.57	0.252	1.344
5.83	6.67	0.252	1.345
5.84	6.77	0.252	1.346
5.85	6.87	0.252	1.346
5.86	6.97	0.252	1.347
5.87	7.07	0.252	1.346
5.88	7.17	0.252	1.347
5.89	7.27	0.252	1.347
5.90	7.37	0.252	1.348
5.91	7.47	0.252	1.348
5.92	7.57	0.252	1.348
5.93	7.67	0.252	1.349
5.94	7.77	0.252	1.350
5.95	7.87	0.252	1.350
5.96	7.97	0.253	1.350
5.97	8.07	0.253	1.351
5.98	8.17	0.253	1.351
5.99	8.27	0.253	1.351
6.00	8.37	0.253	1.352
6.01	8.47	0.253	1.353
6.02	8.57	0.253	1.354
6.03	8.67	0.253	1.354
6.04	8.77	0.253	1.354
6.05	8.87	0.253	1.354
6.06	8.97	0.253	1.355
6.07	9.07	0.253	1.356
6.08	9.17	0.254	1.355
6.09	9.27	0.254	1.356
6.10	9.37	0.254	1.357
6.11	9.47	0.254	1.358
6.12	9.57	0.254	1.358
6.13	9.67	0.254	1.358
6.14	9.77	0.254	1.358
6.15	9.87	0.254	1.358
6.16	9.97	0.254	1.359
6.17	10.07	0.254	1.360
6.18	10.17	0.254	1.360
6.19	10.28	0.254	1.361
6.20	10.37	0.254	1.361
6.21	10.47	0.255	1.361
6.22	10.57	0.255	1.362
6.23	10.67	0.255	1.362
6.24	10.77	0.255	1.363
6.25	10.87	0.255	1.363
6.26	10.98	0.255	1.363
6.27	11.07	0.255	1.363
6.28	11.17	0.255	1.365
6.29	11.27	0.255	1.365
6.30	11.38	0.255	1.365
6.31	11.47	0.255	1.365
6.32	11.58	0.255	1.366
6.33	11.67	0.256	1.367
6.34	11.77	0.256	1.367
6.35	11.88	0.256	1.368
6.36	11.97	0.256	1.368
6.37	12.08	0.256	1.368
6.38	12.18	0.256	1.368
6.39	12.28	0.256	1.369
6.40	12.38	0.256	1.370
6.41	12.48	0.256	1.370
6.42	12.58	0.256	1.370
6.43	12.68	0.256	1.371
6.44	12.78	0.257	1.371
6.45	12.88	0.257	1.372
6.46	12.98	0.257	1.372
6.47	13.08	0.257	1.373
6.48	13.18	0.257	1.373
6.49	13.28	0.257	1.374
6.50	13.38	0.257	1.374
6.51	13.48	0.257	1.374
6.52	13.58	0.257	1.375
6.53	13.68	0.257	1.375
6.54	13.78	0.257	1.375
6.55	13.88	0.257	1.376
6.56	13.98	0.257	1.375
6.57	14.08	0.257	1.376
6.58	14.18	0.257	1.376
6.59	14.28	0.258	1.377
6.60	14.38	0.258	1.377
6.61	14.48	0.258	1.377
6.62	14.58	0.258	1.378
6.63	14.68	0.258	1.379
6.64	14.78	0.258	1.379
6.65	14.88	0.258	1.379
6.66	14.98	0.258	1.380
6.67	15.08	0.258	1.380
6.68	15.18	0.258	1.381
6.69	15.28	0.258	1.381
6.70	15.38	0.259	1.382
6.71	15.48	0.259	1.382
6.72	15.58	0.259	1.383
6.73	15.68	0.259	1.383
6.74	15.78	0.259	1.383
6.75	15.88	0.259	1.384
6.76	15.98	0.259	1.385
6.77	16.08	0.259	1.385
6.78	16.18	0.259	1.385
6.79	16.28	0.259	1.386
6.80	16.38	0.259	1.386
6.81	16.48	0.259	1.386
6.82	16.58	0.259	1.386
6.83	16.68	0.259	1.387
6.84	16.78	0.260	1.388
6.85	16.88	0.260	1.387
6.86	16.98	0.260	1.388
6.87	17.08	0.260	1.388
6.88	17.18	0.260	1.388
6.89	17.28	0.260	1.389
6.90	17.38	0.260	1.389
6.91	17.48	0.260	1.389
6.92	17.58	0.260	1.390
6.93	17.68	0.260	1.391
6.94	17.78	0.260	1.391
6.95	17.88	0.260	1.391
6.96	17.98	0.260	1.392
6.97	18.08	0.260	1.392
6.98	18.18	0.261	1.393
6.99	18.28	0.261	1.393
7.00	18.38	0.261	1.394
7.01	18.48	0.261	1.394
7.02	18.58	0.261	1.395
7.03	18.68	0.261	1.396
7.04	18.78	0.261	1.396
7.05	18.88	0.261	1.397
7.06	18.98	0.261	1.398
7.07	19.08	0.262	1.398
7.08	19.18	0.262	1.399
7.09	19.28	0.262	1.399
7.10	19.38	0.262	1.400
7.11	19.48	0.262	1.400
7.12	19.58	0.262	1.400
7.13	19.68	0.262	1.401
7.14	19.78	0.262	1.401
7.15	19.88	0.262	1.401
7.16	19.98	0.262	1.402
7.17	20.08	0.262	1.403
7.18	20.18	0.262	1.403
7.19	20.28	0.263	1.404
7.20	20.38	0.263	1.405
7.21	20.48	0.263	1.405
7.22	20.58	0.263	1.405
7.23	20.68	0.263	1.406
7.24	20.78	0.263	1.406
7.25	20.88	0.263	1.406
7.26	20.99	0.263	1.406
7.27	21.08	0.263	1.407
7.28	21.19	0.263	1.408
7.29	21.29	0.263	1.408
7.30	21.38	0.263	1.408
7.31	21.48	0.264	1.409
7.32	21.59	0.264	1.410
7.33	21.69	0.264	1.410
7.34	21.78	0.264	1.410
7.35	21.88	0.264	1.411
7.36	21.99	0.264	1.411
7.37	22.09	0.264	1.411
7.38	22.19	0.264	1.412
7.39	22.29	0.264	1.413
7.40	22.39	0.264	1.413
7.41	22.49	0.264	1.413
7.42	22.59	0.264	1.414
7.43	22.69	0.265	1.414
7.44	22.79	0.265	1.415
7.45	22.89	0.265	1.415
7.46	22.99	0.265	1.415
7.47	23.09	0.265	1.416
7.48	23.19	0.265	1.416
7.49	23.29	0.265	1.416
7.50	23.39	0.265	1.417
7.51	23.49	0.265	1.418
7.52	23.59	0.265	1.418
7.53	23.69	0.265	1.418
7.54	23.79	0.265	1.419
7.55	23.89	0.265	1.419
7.56	23.99	0.266	1.419
7.57	24.09	0.266	1.420
7.58	24.19	0.266	1.421
7.59	24.29	0.266	1.421
7.60	24.39	0.266	1.421
7.61	24.49	0.266	1.422
7.62	24.59	0.266	1.422
7.63	24.69	0.266	1.423
7.64	24.79	0.266	1.424
7.65	24.89	0.266	1.425
7.66	24.99	0.266	1.425
7.67	25.09	0.267	1.425
7.68	25.19	0.267	1.426
7.69	25.29	0.267	1.427
7.70	25.39	0.267	1.427
7.71	25.49	0.267	1.427
7.72	25.59	0.267	1.427
7.73	25.69	0.267	1.428
7.74	25.79	0.267	1.428
7.75	25.89	0.267	1.429
7.76	25.99	0.267	1.429
7.77	26.09	0.267	1.430
7.78	26.19	0.268	1.431
7.79	26.29	0.268	1.431
7.80	26.39	0.268	1.432
7.81	26.49	0.268	1.432
7.82	26.59	0.268	1.432
7.83	26.69	0.268	1.432
7.84	26.79	0.268	1.433
7.85	26.89	0.268	1.433
7.86	26.99	0.268	1.433
7.87	27.09	0.268	1.434
7.88	27.19	0.268	1.434
7.89	27.29	0.269	1.435
7.90	27.39	0.269	1.436
7.91	27.49	0.269	1.436
7.92	27.59	0.269	1.437
7.93	27.69	0.269	1.437
7.94	27.79	0.269	1.438
7.95	27.89	0.269	1.438
7.96	27.99	0.269	1.438
7.97	28.09	0.269	1.439
7.98	28.19	0.269	1.439
7.99	28.29	0.269	1.440
8.00	28.39	0.270	1.440
8.01	28.49	0.270	1.441
8.02	28.59	0.270	1.441
8.03	28.69	0.270	1.442
8.04	28.79	0.270	1.442
8.05	28.89	0.270	1.443
8.06	28.99	0.270	1.444
8.07	29.09	0.270	1.445
8.08	29.19	0.270	1.445
8.09	29.29	0.271	1.447
8.10	29.39	0.271	1.447
8.11	29.49	0.271	1.447
8.12	29.59	0.271	1.448
8.13	29.69	0.271	1.448
8.14	29.79	0.271	1.449
8.15	29.89	0.271	1.449
8.16	29.99	0.271	1.449
8.17	30.09	0.271	1.450
8.18	30.19	0.271	1.451
8.19	30.29	0.271	1.450
8.20	30.39	0.271	1.451
8.21	30.49	0.271	1.452
8.22	30.59	0.272	1.452
8.23	30.69	0.272	1.453
8.24	30.79	0.272	1.453
8.25	30.89	0.272	1.454
8.26	30.99	0.272	1.455
8.27	31.09	0.272	1.455
8.28	31.19	0.272	1.456
8.29	31.30	0.272	1.457
8.30	31.39	0.272	1.457
8.31	31.50	0.272	1.457
8.32	31.60	0.273	1.458
8.33	31.69	0.273	1.458
8.34	31.80	0.273	1.458
8.35	31.89	0.273	1.458
8.36	31.99	0.273	1.460
8.37	32.10	0.273	1.460
8.38	32.20	0.273	1.460
8.39	32.30	0.273	1.461
8.40	32.40	0.273	1.461
8.41	32.50	0.273	1.462
8.42	32.60	0.273	1.462
8.43	32.69	0.273	1.462
8.44	32.80	0.274	1.463
8.45	32.90	0.274	1.463
8.46	33.00	0.274	1.463
8.47	33.10	0.274	1.464
8.48	33.20	0.274	1.464
8.49	33.30	0.274	1.465
8.50	33.40	0.274	1.465
8.51	33.50	0.274	1.466
8.52	33.60	0.274	1.466
8.53	33.70	0.274	1.466
8.54	33.80	0.274	1.468
8.55	33.90	0.275	1.468
8.56	34.00	0.275	1.469
8.57	34.10	0.275	1.470
8.58	34.20	0.275	1.470
8.59	34.30	0.275	1.470
8.60	34.40	0.275	1.471
8.61	34.50	0.275	1.471
8.62	34.60	0.275	1.471
8.63	34.70	0.275	1.471
8.64	34.80	0.275	1.472
8.65	34.90	0.275	1.473
8.66	35.00	0.275	1.473
8.67	35.10	0.276	1.474
8.68	35.20	0.276	1.474
8.69	35.30	0.276	1.475
8.70	35.40	0.276	1.476
8.71	35.50	0.276	1.476
8.72	35.60	0.276	1.476
8.73	35.70	0.276	1.477
8.74	35.80	0.276	1.477
8.75	35.90	0.276	1.477
8.76	36.00	0.276	1.477
8.77	36.10	0.276	1.477
8.78	36.20	0.277	1.477
8.79	36.30	0.277	1.478
8.80	36.40	0.277	1.479
8.81	36.50	0.277	1.478
8.82	36.60	0.277	1.479
8.83	36.70	0.277	1.480
8.84	36.80	0.277	1.480
8.85	36.90	0.277	1.480
8.86	37.00	0.277	1.481
8.87	37.10	0.277	1.481
8.88	37.20	0.277	1.481
8.89	37.30	0.277	1.482
8.90	37.40	0.278	1.482
8.91	37.50	0.278	1.483
8.92	37.60	0.278	1.484
8.93	37.70	0.278	1.484
8.94	37.80	0.278	1.485
8.95	37.90	0.278	1.485
8.96	38.00	0.278	1.486
8.97	38.10	0.278	1.486
8.98	38.20	0.278	1.486
8.99	38.30	0.278	1.487
9.00	38.40	0.278	1.487
9.01	38.50	0.279	1.488
9.02	38.60	0.279	1.488
9.03	38.70	0.279	1.488
9.04	38.80	0.279	1.489
9.05	38.90	0.279	1.490
9.06	39.00	0.279	1.490
9.07	39.10	0.279	1.490
9.08	39.20	0.279	1.491
9.09	39.30	0.279	1.491
9.10	39.40	0.279	1.492
9.11	39.50	0.279	1.492
9.12	39.60	0.279	1.492
9.13	39.70	0.280	1.492
9.14	39.80	0.280	1.493
9.15	39.90	0.280	1.494
9.16	40.00	0.280	1.494
9.17	40.10	0.280	1.495
9.18	40.20	0.280	1.494
9.19	40.30	0.280	1.495
9.20	40.40	0.280	1.496
9.21	40.50	0.280	1.496
9.22	40.60	0.280	1.497
9.23	40.70	0.280	1.496
9.24	40.80	0.281	1.497
9.25	40.90	0.281	1.497
9.26	41.00	0.281	1.498
9.27	41.10	0.281	1.498
9.28	41.20	0.281	1.498
9.29	41.30	0.281	1.499
9.30	41.40	0.281	1.500
9.31	41.50	0.281	1.500
9.32	41.60	0.281	1.501
9.33	41.70	0.281	1.501
9.34	41.80	0.281	1.501
9.35	41.90	0.282	1.502
9.36	42.00	0.282	1.502
9.37	42.11	0.282	1.502
9.38	42.21	0.282	1.503
9.39	42.30	0.282	1.504
9.40	42.40	0.282	1.503
9.41	42.50	0.282	1.504
9.42	42.61	0.282	1.504
9.43	42.71	0.282	1.505
9.44	42.81	0.282	1.505
9.45	42.90	0.282	1.506
9.46	43.01	0.283	1.506
9.47	43.10	0.283	1.507
9.48	43.21	0.283	1.507
9.49	43.31	0.283	1.507
9.50	43.41	0.283	1.508
9.51	43.51	0.283	1.509
9.52	43.61	0.283	1.509
9.53	43.71	0.283	1.509
9.54	43.81	0.283	1.510
9.55	43.91	0.284	1.510
9.56	44.01	0.284	1.511
9.57	44.11	0.284	1.511
9.58	44.21	0.284	1.512
9.59	44.31	0.284	1.512
9.60	44.41	0.284	1.513
9.61	44.51	0.284	1.513
9.62	44.61	0.284	1.514
9.63	44.71	0.284	1.514
9.64	44.81	0.284	1.515
9.65	44.91	0.284	1.515
9.66	45.01	0.285	1.515
9.67	45.11	0.285	1.517
9.68	45.21	0.285	1.517
9.69	45.31	0.285	1.518
9.70	45.41	0.285	1.518
9.71	45.51	0.285	1.518
9.72	45.61	0.285	1.519
9.73	45.71	0.285	1.519
9.74	45.81	0.285	1.520
9.75	45.91	0.285	1.520
9.76	46.01	0.285	1.521
9.77	46.11	0.286	1.521
9.78	46.21	0.286	1.521
9.79	46.31	0.286	1.522
9.80	46.41	0.286	1.522
9.81	46.51	0.286	1.523
9.82	46.61	0.286	1.524
9.83	46.71	0.286	1.524
9.84	46.81	0.286	1.524
9.85	46.91	0.286	1.525
9.86	47.01	0.287	1.526
9.87	47.11	0.287	1.526
9.88	47.21	0.287	1.526
9.89	47.31	0.287	1.527
9.90	47.41	0.287	1.527
9.91	47.51	0.287	1.527
9.92	47.61	0.287	1.528
9.93	47.71	0.287	1.529
9.94	47.81	0.287	1.530
9.95	47.91	0.287	1.530
9.96	48.01	0.288	1.531
9.97	48.11	0.288	1.531
9.98	48.21	0.288	1.532
9.99	48.31	0.288	1.533
10.00	48.41	0.288	1.533
10.01	48.51	0.288	1.534
10.02	48.61	0.288	1.534
10.03	48.71	0.288	1.535
10.04	48.81	0.288	1.536
10.05	48.91	0.288	1.536
10.06	49.01	0.289	1.536
10.07	49.11	0.289	1.536
10.08	49.21	0.289	1.536
10.09	49.31	0.289	1.537
10.10	49.41	0.289	1.538
10.11	49.51	0.289	1.539
10.12	49.61	0.289	1.540
10.13	49.71	0.289	1.540
10.14	49.81	0.289	1.541
10.15	49.91	0.290	1.542
10.16	50.01	0.290	1.542
10.17	50.11	0.290	1.543
10.18	50.21	0.290	1.543
10.19	50.31	0.290	1.544
10.20	50.41	0.290	1.545
10.21	50.51	0.290	1.546
10.22	50.61	0.290	1.547
10.23	50.71	0.291	1.547
10.24	50.81	0.291	1.548
10.25	50.91	0.291	1.549
10.26	51.01	0.291	1.549
10.27	51.11	0.291	1.551
10.28	51.21	0.291	1.552
10.29	51.31	0.291	1.551
10.30	51.41	0.291	1.552
10.31	51.51	0.291	1.553
10.32	51.61	0.292	1.553
10.33	51.71	0.292	1.554
10.34	51.81	0.292	1.555
10.35	51.91	0.292	1.556
10.36	52.01	0.292	1.557
10.37	52.11	0.292	1.557
10.38	52.21	0.292	1.558
10.39	52.31	0.292	1.559
10.40	52.41	0.293	1.560
10.41	52.51	0.293	1.560
10.42	52.61	0.293	1.561
10.43	52.72	0.293	1.562
10.44	52.81	0.293	1.563
10.45	52.91	0.293	1.564
10.46	53.01	0.294	1.565
10.47	53.11	0.294	1.565
10.48	53.21	0.294	1.565
10.49	53.31	0.294	1.566
10.50	53.41	0.294	1.566
10.51	53.51	0.294	1.566
10.52	53.61	0.294	1.568
10.53	53.71	0.294	1.569
10.54	53.81	0.294	1.570
10.55	53.91	0.295	1.572
10.56	54.01	0.295	1.572
10.57	54.11	0.295	1.574
10.58	54.21	0.295	1.574
10.59	54.31	0.296	1.575
10.60	54.41	0.296	1.576
10.61	54.51	0.296	1.577
10.62	54.61	0.296	1.578
10.63	54.71	0.296	1.578
10.64	54.81	0.296	1.579
10.65	54.91	0.296	1.580
10.66	55.02	0.296	1.581
10.67	55.11	0.297	1.583
10.68	55.21	0.297	1.585
10.69	55.31	0.297	1.586
10.70	55.41	0.298	1.587
10.71	55.52	0.298	1.588
10.72	55.61	0.298	1.589
10.73	55.72	0.298	1.589
10.74	55.82	0.298	1.591
10.75	55.91	0.298	1.592
10.76	56.02	0.299	1.592
10.77	56.11	0.299	1.594
10.78	56.22	0.299	1.595
10.79	56.31	0.299	1.596
10.80	56.41	0.299	1.597
10.81	56.52	0.300	1.599
10.82	56.62	0.300	1.600
10.83	56.72	0.300	1.602
10.84	56.82	0.300	1.604
10.85	56.91	0.300	1.604
10.86	57.02	0.301	1.605
10.87	57.11	0.301	1.606
10.88	57.21	0.301	1.607
10.89	57.31	0.301	1.609
10.90	57.41	0.301	1.610
10.91	57.51	0.302	1.611
10.92	57.61	0.302	1.613
10.93	57.72	0.302	1.615
10.94	57.81	0.303	1.617
10.95	57.92	0.303	1.619
10.96	58.01	0.303	1.621
10.97	58.11	0.304	1.623
10.98	58.21	0.305	1.627
10.99	58.31	0.305	1.629
11.00	58.41	0.305	1.631
11.01	58.51	0.306	1.635
11.02	58.61	0.306	1.638
11.03	58.71	0.307	1.641
11.04	58.82	0.308	1.644
11.05	58.91	0.308	1.646
11.06	59.01	0.309	1.653
11.07	59.11	0.310	1.656
11.08	59.21	0.311	1.661
11.09	59.31	0.311	1.665
11.10	59.41	0.312	1.672
11.11	59.51	0.313	1.675
11.12	59.61	0.314	1.679
11.13	59.71	0.315	1.686
11.14	59.81	0.316	1.690
11.15	59.91	0.316	1.694
11.16	60.01	0.318	1.705
11.17	60.11	0.320	1.712
[...]
467.59	-15.59	0.227	1.211
467.60	-15.52	0.227	1.214
467.61	-15.46	0.228	1.218
467.61	-15.39	0.228	1.222
467.62	-15.32	0.230	1.229
467.63	-15.26	0.231	1.234
467.63	-15.19	0.231	1.237
467.64	-15.12	0.232	1.243
467.64	-15.06	0.233	1.247
467.65	-14.99	0.234	1.251
467.66	-14.93	0.235	1.257
467.67	-14.86	0.236	1.263
467.67	-14.79	0.237	1.268
467.68	-14.73	0.238	1.272
467.68	-14.66	0.238	1.274
467.69	-14.59	0.238	1.278
467.70	-14.53	0.240	1.288
467.71	-14.46	0.242	1.298
467.71	-14.39	0.243	1.303
467.72	-14.33	0.244	1.306
467.73	-14.26	0.244	1.310
467.73	-14.20	0.245	1.315
467.74	-14.13	0.247	1.322
467.74	-14.06	0.247	1.327
467.75	-13.99	0.248	1.332
467.76	-13.93	0.250	1.340
467.77	-13.86	0.251	1.345
467.77	-13.80	0.252	1.350
467.78	-13.73	0.253	1.356
467.78	-13.67	0.254	1.363
467.79	-13.60	0.256	1.372
467.80	-13.53	0.257	1.380
467.81	-13.47	0.258	1.385
467.81	-13.40	0.259	1.388
467.82	-13.34	0.260	1.395
467.83	-13.27	0.261	1.404
467.83	-13.20	0.262	1.407
467.84	-13.14	0.263	1.413
467.84	-13.07	0.265	1.424
467.85	-13.00	0.266	1.428
467.86	-12.94	0.266	1.432
467.87	-12.87	0.268	1.442
467.87	-12.81	0.270	1.450
467.88	-12.74	0.270	1.453
467.88	-12.67	0.272	1.460
467.89	-12.61	0.272	1.463
467.90	-12.54	0.274	1.472
467.91	-12.48	0.275	1.479
467.91	-12.41	0.275	1.480
467.92	-12.34	0.276	1.483
467.93	-12.28	0.278	1.496
467.93	-12.21	0.280	1.504
467.94	-12.14	0.280	1.505
467.94	-12.08	0.281	1.507
467.95	-12.01	0.282	1.512
467.96	-11.95	0.282	1.515
467.97	-11.88	0.283	1.517
467.97	-11.81	0.283	1.521
467.98	-11.75	0.284	1.525
467.98	-11.68	0.285	1.528
467.99	-11.61	0.286	1.531
468.00	-11.55	0.286	1.535
468.01	-11.48	0.287	1.538
468.01	-11.42	0.287	1.539
468.02	-11.35	0.287	1.539
468.03	-11.28	0.287	1.539
468.03	-11.22	0.287	1.539
468.04	-11.15	0.287	1.539
468.04	-11.08	0.288	1.539
468.05	-11.02	0.288	1.540
468.06	-10.95	0.288	1.540
468.07	-10.88	0.288	1.539
468.07	-10.82	0.288	1.538
468.08	-10.75	0.288	1.538
468.08	-10.68	0.288	1.538
468.09	-10.62	0.288	1.537
468.10	-10.55	0.288	1.536
468.11	-10.48	0.288	1.534
468.11	-10.42	0.288	1.533
468.12	-10.35	0.288	1.532
468.13	-10.28	0.287	1.531
468.13	-10.22	0.287	1.529
468.14	-10.15	0.287	1.527
468.14	-10.08	0.286	1.524
468.15	-10.02	0.285	1.519
468.16	-9.95	0.284	1.513
468.17	-9.88	0.284	1.509
468.17	-9.81	0.284	1.508
468.18	-9.75	0.282	1.501
468.18	-9.68	0.281	1.493
468.19	-9.61	0.280	1.487
468.20	-9.55	0.279	1.485
468.21	-9.48	0.279	1.483
468.21	-9.41	0.278	1.476
468.22	-9.34	0.277	1.471
468.23	-9.28	0.276	1.468
468.23	-9.21	0.276	1.466
468.24	-9.14	0.276	1.464
468.24	-9.08	0.275	1.461
468.25	-9.01	0.274	1.456
468.26	-8.94	0.274	1.453
468.27	-8.88	0.273	1.451
468.27	-8.81	0.273	1.450
468.28	-8.74	0.273	1.448
468.28	-8.67	0.272	1.446
468.29	-8.61	0.272	1.444
468.30	-8.54	0.272	1.443
468.31	-8.47	0.271	1.440
468.31	-8.41	0.271	1.439
468.32	-8.34	0.270	1.437
468.33	-8.27	0.270	1.436
468.33	-8.21	0.270	1.435
468.34	-8.14	0.269	1.432
468.34	-8.07	0.269	1.431
468.35	-8.00	0.269	1.431
468.36	-7.94	0.269	1.431
468.37	-7.87	0.268	1.426
468.37	-7.80	0.268	1.424
468.38	-7.74	0.268	1.425
468.38	-7.67	0.268	1.425
468.39	-7.60	0.268	1.424
468.40	-7.54	0.267	1.424
468.41	-7.47	0.267	1.424
468.41	-7.40	0.267	1.423
468.42	-7.34	0.267	1.424
468.43	-7.27	0.267	1.423
468.43	-7.20	0.267	1.422
468.44	-7.13	0.267	1.422
468.44	-7.07	0.267	1.422
468.45	-7.00	0.267	1.422
468.46	-6.94	0.267	1.422
468.47	-6.87	0.266	1.421
468.47	-6.80	0.266	1.420
468.48	-6.73	0.266	1.420
468.48	-6.67	0.266	1.420
468.49	-6.60	0.266	1.420
468.50	-6.53	0.266	1.419
468.51	-6.47	0.266	1.419
468.51	-6.40	0.266	1.419
468.52	-6.33	0.266	1.418
468.53	-6.27	0.266	1.418
468.53	-6.20	0.266	1.418
468.54	-6.13	0.266	1.417
468.54	-6.07	0.266	1.418
468.55	-6.00	0.266	1.417
468.56	-5.93	0.266	1.416
468.57	-5.87	0.265	1.417
468.57	-5.80	0.265	1.417
468.58	-5.73	0.265	1.416
468.58	-5.66	0.265	1.416
468.59	-5.60	0.265	1.416
468.60	-5.53	0.265	1.416
468.61	-5.46	0.265	1.415
468.61	-5.40	0.265	1.415
468.62	-5.33	0.265	1.415
468.63	-5.26	0.265	1.415
468.63	-5.20	0.265	1.415
468.64	-5.13	0.265	1.415
468.64	-5.06	0.265	1.415
468.65	-5.00	0.265	1.414
468.66	-4.93	0.265	1.414
468.67	-4.86	0.265	1.414
468.67	-4.80	0.265	1.414
468.68	-4.73	0.265	1.414
468.68	-4.66	0.265	1.413
468.69	-4.60	0.265	1.413
468.70	-4.53	0.265	1.414
468.71	-4.46	0.265	1.414
468.71	-4.39	0.265	1.413
468.72	-4.33	0.264	1.413
468.73	-4.26	0.264	1.413
468.73	-4.20	0.264	1.413
468.74	-4.13	0.264	1.413
468.74	-4.06	0.264	1.412
468.75	-3.99	0.264	1.412
468.76	-3.93	0.264	1.412
468.77	-3.86	0.264	1.412
468.77	-3.79	0.264	1.412
468.78	-3.73	0.264	1.412
468.78	-3.66	0.264	1.412
468.79	-3.59	0.264	1.412
468.80	-3.53	0.264	1.412
468.81	-3.46	0.264	1.412
468.81	-3.39	0.264	1.412
468.82	-3.33	0.264	1.411
468.83	-3.26	0.264	1.411
468.83	-3.19	0.264	1.411
468.84	-3.13	0.264	1.411
468.84	-3.06	0.264	1.411
468.85	-2.99	0.264	1.411
468.86	-2.93	0.264	1.411
468.87	-2.86	0.264	1.410
468.87	-2.79	0.264	1.411
468.88	-2.73	0.264	1.411
468.88	-2.66	0.264	1.411
468.89	-2.59	0.264	1.411
468.90	-2.53	0.264	1.411
468.91	-2.46	0.264	1.411
468.91	-2.39	0.264	1.411
468.92	-2.33	0.264	1.411
468.93	-2.26	0.264	1.411
468.93	-2.19	0.264	1.411
468.94	-2.13	0.264	1.411
468.94	-2.06	0.264	1.411
468.95	-1.99	0.264	1.412
468.96	-1.92	0.264	1.412
468.97	-1.86	0.264	1.412
468.97	-1.79	0.264	1.412
468.98	-1.72	0.264	1.412
468.98	-1.66	0.264	1.412
468.99	-1.59	0.264	1.412
469.00	-1.52	0.264	1.412
469.01	-1.46	0.264	1.412
469.01	-1.39	0.264	1.412
469.02	-1.32	0.264	1.413
469.03	-1.26	0.264	1.413
469.03	-1.19	0.264	1.413
469.04	-1.12	0.264	1.413
469.04	-1.06	0.264	1.414
469.05	-0.99	0.264	1.413
469.06	-0.92	0.264	1.413
469.07	-0.86	0.264	1.414
469.07	-0.79	0.264	1.414
469.08	-0.72	0.264	1.414
469.08	-0.66	0.264	1.414
469.09	-0.59	0.264	1.414
469.10	-0.52	0.264	1.413
469.11	-0.46	0.264	1.413
469.11	-0.39	0.264	1.414
469.12	-0.32	0.264	1.414
469.13	-0.25	0.264	1.414
469.13	-0.19	0.264	1.414
469.14	-0.12	0.264	1.414
469.14	-0.05	0.265	1.414
469.15	0.01	0.265	1.414
469.16	0.08	0.265	1.415
469.17	0.15	0.265	1.415
469.17	0.21	0.265	1.415
469.18	0.28	0.265	1.415
469.18	0.35	0.265	1.415
469.19	0.41	0.265	1.415
469.20	0.48	0.265	1.415
469.21	0.55	0.265	1.416
469.21	0.61	0.265	1.416
469.22	0.68	0.265	1.416
469.23	0.75	0.265	1.417
469.23	0.81	0.265	1.417
469.24	0.88	0.265	1.416
469.24	0.95	0.265	1.416
469.25	1.01	0.265	1.416
469.26	1.08	0.265	1.417
469.27	1.15	0.265	1.417
469.27	1.21	0.265	1.417
469.28	1.28	0.265	1.417
469.28	1.35	0.265	1.418
469.29	1.41	0.265	1.417
469.30	1.48	0.265	1.418
469.31	1.55	0.265	1.418
469.31	1.62	0.265	1.418
469.32	1.68	0.265	1.419
469.33	1.75	0.265	1.419
469.33	1.81	0.265	1.419
469.34	1.88	0.265	1.419
469.34	1.95	0.265	1.418
469.35	2.01	0.265	1.419
469.36	2.08	0.265	1.419
469.37	2.15	0.265	1.419
469.37	2.21	0.265	1.420
469.38	2.28	0.265	1.419
469.38	2.35	0.265	1.419
469.39	2.41	0.265	1.419
469.40	2.48	0.265	1.420
469.41	2.55	0.265	1.420
469.41	2.62	0.266	1.420
469.42	2.68	0.266	1.420
469.43	2.75	0.266	1.420
469.43	2.82	0.266	1.420
469.44	2.88	0.266	1.420
469.44	2.95	0.266	1.420
469.45	3.02	0.266	1.420
469.46	3.08	0.266	1.421
469.47	3.15	0.266	1.422
469.47	3.22	0.266	1.422
469.48	3.28	0.266	1.422
469.48	3.35	0.266	1.422
469.49	3.42	0.266	1.422
469.50	3.48	0.266	1.423
469.51	3.55	0.266	1.422
469.51	3.62	0.266	1.423
469.52	3.68	0.266	1.423
469.53	3.75	0.266	1.423
469.53	3.82	0.266	1.423
469.54	3.89	0.266	1.423
469.54	3.95	0.266	1.424
469.55	4.02	0.266	1.425
469.56	4.08	0.266	1.425
469.57	4.15	0.266	1.425
469.57	4.22	0.266	1.425
469.58	4.28	0.266	1.425
469.58	4.35	0.266	1.426
469.59	4.42	0.266	1.426
469.60	4.49	0.266	1.426
469.61	4.55	0.267	1.426
469.61	4.62	0.267	1.426
469.62	4.68	0.267	1.426
469.63	4.75	0.267	1.426
469.63	4.82	0.267	1.427
469.64	4.89	0.267	1.427
469.64	4.95	0.267	1.428
469.65	5.02	0.267	1.428
469.66	5.08	0.267	1.427
469.67	5.15	0.267	1.427
469.67	5.22	0.267	1.427
469.68	5.28	0.267	1.427
469.68	5.35	0.267	1.428
469.69	5.42	0.267	1.428
469.70	5.48	0.267	1.428
469.71	5.55	0.267	1.429
469.71	5.62	0.267	1.429
469.72	5.69	0.267	1.429
469.73	5.75	0.267	1.429
469.73	5.82	0.267	1.430
469.74	5.89	0.267	1.431
469.74	5.95	0.267	1.431
469.75	6.02	0.267	1.430
469.76	6.09	0.267	1.430
469.77	6.15	0.268	1.430
469.77	6.22	0.268	1.431
469.78	6.29	0.268	1.431
469.78	6.35	0.268	1.431
469.79	6.42	0.268	1.431
469.80	6.49	0.268	1.431
469.81	6.55	0.268	1.431
469.81	6.62	0.268	1.432
469.82	6.69	0.268	1.432
469.83	6.75	0.268	1.433
469.83	6.82	0.268	1.432
469.84	6.89	0.268	1.433
469.84	6.95	0.268	1.433
469.85	7.02	0.268	1.433
469.86	7.09	0.268	1.433
469.87	7.15	0.268	1.434
469.87	7.22	0.268	1.435
469.88	7.29	0.268	1.435
469.88	7.35	0.268	1.435
469.89	7.42	0.268	1.435
469.90	7.49	0.268	1.435
469.91	7.55	0.268	1.435
469.91	7.62	0.268	1.435
469.92	7.69	0.268	1.435
469.93	7.76	0.269	1.435
469.93	7.82	0.269	1.436
469.94	7.89	0.269	1.436
469.94	7.96	0.269	1.436
469.95	8.02	0.269	1.436
469.96	8.09	0.269	1.437
469.97	8.16	0.269	1.437
469.97	8.22	0.269	1.438
469.98	8.29	0.269	1.438
469.98	8.36	0.269	1.438
469.99	8.42	0.269	1.438
470.00	8.49	0.269	1.439
470.01	8.56	0.269	1.439
470.01	8.62	0.269	1.439
470.02	8.69	0.269	1.439
470.03	8.76	0.269	1.439
470.03	8.82	0.269	1.440
470.04	8.89	0.269	1.440
470.04	8.96	0.269	1.441
470.05	9.02	0.269	1.441
470.06	9.09	0.269	1.441
470.07	9.16	0.270	1.441
470.07	9.22	0.270	1.441
470.08	9.29	0.270	1.441
470.08	9.36	0.270	1.442
470.09	9.42	0.270	1.442
470.10	9.49	0.270	1.442
470.11	9.56	0.270	1.442
470.11	9.62	0.270	1.442
470.12	9.69	0.270	1.442
470.13	9.76	0.270	1.443
470.13	9.82	0.270	1.443
470.14	9.89	0.270	1.443
470.14	9.96	0.270	1.443
470.15	10.02	0.270	1.444
470.16	10.09	0.270	1.444
470.17	10.16	0.270	1.445
470.17	10.22	0.270	1.445
470.18	10.29	0.270	1.446
470.18	10.36	0.270	1.446
470.19	10.43	0.270	1.445
470.20	10.49	0.270	1.446
470.21	10.56	0.271	1.446
470.21	10.63	0.271	1.446
470.22	10.69	0.271	1.446
470.23	10.76	0.271	1.447
470.23	10.83	0.271	1.448
470.24	10.89	0.271	1.447
470.24	10.96	0.271	1.447
470.25	11.03	0.271	1.447
470.26	11.09	0.271	1.448
470.27	11.16	0.271	1.448
470.27	11.23	0.271	1.448
470.28	11.29	0.271	1.448
470.28	11.36	0.271	1.449
470.29	11.43	0.271	1.449
470.30	11.49	0.271	1.450
470.31	11.56	0.271	1.450
470.31	11.63	0.271	1.450
470.32	11.69	0.271	1.451
470.33	11.76	0.271	1.451
470.33	11.83	0.271	1.451
470.34	11.89	0.271	1.451
470.34	11.96	0.271	1.451
470.35	12.03	0.271	1.451
470.36	12.09	0.271	1.451
470.37	12.16	0.272	1.451
470.37	12.23	0.272	1.451
470.38	12.30	0.272	1.452
470.38	12.36	0.272	1.452
470.39	12.43	0.272	1.452
470.40	12.49	0.272	1.453
470.41	12.56	0.272	1.453
470.41	12.63	0.272	1.453
470.42	12.70	0.272	1.453
470.43	12.76	0.272	1.453
470.43	12.83	0.272	1.453
470.44	12.89	0.272	1.454
470.44	12.96	0.272	1.454
470.45	13.03	0.272	1.454
470.46	13.10	0.272	1.455
470.47	13.16	0.272	1.455
470.47	13.23	0.272	1.456
470.48	13.29	0.272	1.456
470.48	13.36	0.272	1.456
470.49	13.43	0.272	1.456
470.50	13.50	0.272	1.456
470.51	13.56	0.272	1.456
470.51	13.63	0.272	1.457
470.52	13.70	0.272	1.457
470.53	13.76	0.273	1.457
470.53	13.83	0.273	1.457
470.54	13.90	0.273	1.457
470.54	13.96	0.273	1.458
470.55	14.03	0.273	1.458
470.56	14.10	0.273	1.459
470.57	14.16	0.273	1.458
470.57	14.23	0.273	1.458
470.58	14.30	0.273	1.459
470.58	14.36	0.273	1.459
470.59	14.43	0.273	1.459
470.60	14.50	0.273	1.460
470.61	14.56	0.273	1.459
470.61	14.63	0.273	1.460
470.62	14.70	0.273	1.461
470.63	14.76	0.273	1.461
470.63	14.83	0.273	1.461
470.64	14.90	0.273	1.461
470.64	14.96	0.273	1.461
470.65	15.03	0.273	1.462
470.66	15.10	0.273	1.462
470.67	15.16	0.273	1.462
470.67	15.23	0.274	1.462
470.68	15.30	0.274	1.462
470.68	15.36	0.274	1.462
470.69	15.43	0.274	1.463
470.70	15.50	0.274	1.464
470.71	15.56	0.274	1.464
470.71	15.63	0.274	1.464
470.72	15.70	0.274	1.464
470.73	15.77	0.274	1.464
470.73	15.83	0.274	1.465
470.74	15.90	0.274	1.466
470.74	15.96	0.274	1.465
470.75	16.03	0.274	1.465
470.76	16.10	0.274	1.465
470.77	16.17	0.274	1.465
470.77	16.23	0.274	1.466
470.78	16.30	0.274	1.466
470.78	16.37	0.274	1.466
470.79	16.43	0.274	1.466
470.80	16.50	0.274	1.466
470.81	16.57	0.274	1.466
470.81	16.63	0.274	1.466
470.82	16.70	0.274	1.466
470.83	16.77	0.274	1.466
470.83	16.83	0.274	1.467
470.84	16.90	0.274	1.466
470.84	16.97	0.274	1.467
470.85	17.03	0.274	1.467
470.86	17.10	0.275	1.468
470.87	17.17	0.275	1.468
470.87	17.23	0.275	1.468
470.88	17.30	0.275	1.469
470.88	17.37	0.275	1.469
470.89	17.43	0.275	1.469
470.90	17.50	0.275	1.469
470.91	17.57	0.275	1.469
470.91	17.63	0.275	1.469
470.92	17.70	0.275	1.469
470.93	17.77	0.275	1.470
470.93	17.83	0.275	1.470
470.94	17.90	0.275	1.470
470.94	17.97	0.275	1.471
470.95	18.03	0.275	1.471
470.96	18.10	0.275	1.471
470.97	18.17	0.275	1.472
470.97	18.24	0.275	1.472
470.98	18.30	0.275	1.472
470.98	18.37	0.275	1.472
470.99	18.43	0.275	1.473
471.00	18.50	0.275	1.473
471.01	18.57	0.276	1.473
471.01	18.63	0.276	1.473
471.02	18.70	0.276	1.473
471.03	18.77	0.276	1.474
471.03	18.84	0.276	1.474
471.04	18.90	0.276	1.474
471.04	18.97	0.276	1.474
471.05	19.04	0.276	1.474
471.06	19.10	0.276	1.474
471.07	19.17	0.276	1.475
471.07	19.23	0.276	1.476
471.08	19.30	0.276	1.475
471.08	19.37	0.276	1.475
471.09	19.44	0.276	1.476
471.10	19.50	0.276	1.476
471.11	19.57	0.276	1.476
471.11	19.64	0.276	1.476
471.12	19.70	0.276	1.477
471.13	19.77	0.276	1.477
471.13	19.84	0.276	1.477
471.14	19.90	0.276	1.478
471.14	19.97	0.276	1.478
471.15	20.04	0.277	1.479
471.16	20.10	0.277	1.478
471.17	20.17	0.277	1.478
471.17	20.24	0.277	1.479
471.18	20.30	0.277	1.479
471.18	20.37	0.277	1.479
471.19	20.44	0.277	1.479
471.20	20.50	0.277	1.479
471.21	20.57	0.277	1.480
471.21	20.64	0.277	1.480
471.22	20.70	0.277	1.480
471.23	20.77	0.277	1.481
471.23	20.84	0.277	1.481
471.24	20.90	0.277	1.481
471.24	20.97	0.277	1.482
471.25	21.04	0.277	1.482
471.26	21.10	0.277	1.482
471.27	21.17	0.277	1.482
471.27	21.24	0.277	1.482
471.28	21.30	0.277	1.483
471.28	21.37	0.277	1.483
471.29	21.44	0.278	1.483
471.30	21.51	0.278	1.484
471.31	21.57	0.278	1.484
471.31	21.64	0.278	1.484
471.32	21.71	0.278	1.484
471.33	21.77	0.278	1.485
471.33	21.84	0.278	1.485
471.34	21.90	0.278	1.485
471.34	21.97	0.278	1.485
471.35	22.04	0.278	1.485
471.36	22.10	0.278	1.485
471.37	22.17	0.278	1.486
471.37	22.24	0.278	1.486
471.38	22.30	0.278	1.486
471.38	22.37	0.278	1.487
471.39	22.44	0.278	1.487
471.40	22.51	0.278	1.487
471.41	22.57	0.278	1.488
471.41	22.64	0.278	1.488
471.42	22.71	0.278	1.488
471.43	22.77	0.278	1.488
471.43	22.84	0.278	1.489
471.44	22.91	0.278	1.489
471.44	22.97	0.279	1.489
471.45	23.04	0.279	1.489
471.46	23.11	0.279	1.489
471.47	23.17	0.279	1.490
471.47	23.24	0.279	1.490
471.48	23.31	0.279	1.490
471.48	23.37	0.279	1.490
471.49	23.44	0.279	1.491
471.50	23.51	0.279	1.491
471.51	23.57	0.279	1.491
471.51	23.64	0.279	1.491
471.52	23.71	0.279	1.492
471.53	23.77	0.279	1.492
471.53	23.84	0.279	1.492
471.54	23.91	0.279	1.492
471.54	23.97	0.279	1.493
471.55	24.04	0.279	1.493
471.56	24.11	0.279	1.494
471.57	24.17	0.279	1.494
471.57	24.24	0.279	1.494
471.58	24.31	0.279	1.494
471.58	24.37	0.280	1.495
471.59	24.44	0.280	1.494
471.60	24.51	0.280	1.495
471.61	24.57	0.280	1.495
471.61	24.64	0.280	1.495
471.62	24.71	0.280	1.495
471.63	24.77	0.280	1.496
471.63	24.84	0.280	1.496
471.64	24.91	0.280	1.496
471.64	24.97	0.280	1.497
471.65	25.04	0.280	1.497
471.66	25.11	0.280	1.497
471.67	25.18	0.280	1.497
471.67	25.24	0.280	1.497
471.68	25.31	0.280	1.498
471.68	25.37	0.280	1.498
471.69	25.44	0.280	1.498
471.70	25.51	0.280	1.498
471.71	25.57	0.280	1.498
471.71	25.64	0.280	1.499
471.72	25.71	0.280	1.499
471.73	25.77	0.281	1.499
471.73	25.84	0.281	1.499
471.74	25.91	0.281	1.499
471.74	25.98	0.281	1.500
471.75	26.04	0.281	1.500
471.76	26.11	0.281	1.500
471.77	26.18	0.281	1.501
471.77	26.24	0.281	1.501
471.78	26.31	0.281	1.501
471.78	26.38	0.281	1.502
471.79	26.44	0.281	1.502
471.80	26.51	0.281	1.502
471.81	26.58	0.281	1.503
471.81	26.64	0.281	1.503
471.82	26.71	0.281	1.503
471.83	26.78	0.281	1.503
471.83	26.84	0.281	1.503
471.84	26.91	0.281	1.504
471.84	26.98	0.281	1.504
471.85	27.04	0.281	1.504
471.86	27.11	0.281	1.504
471.87	27.18	0.281	1.505
471.87	27.24	0.282	1.505
471.88	27.31	0.282	1.505
471.88	27.38	0.282	1.506
471.89	27.45	0.282	1.506
471.90	27.51	0.282	1.507
471.91	27.58	0.282	1.507
471.91	27.64	0.282	1.507
471.92	27.71	0.282	1.508
471.93	27.78	0.282	1.508
471.93	27.84	0.282	1.508
471.94	27.91	0.282	1.509
471.94	27.98	0.282	1.509
471.95	28.04	0.282	1.509
471.96	28.11	0.282	1.509
471.97	28.18	0.282	1.509
471.97	28.24	0.282	1.510
471.98	28.31	0.282	1.510
471.98	28.38	0.282	1.510
471.99	28.45	0.282	1.510
472.00	28.51	0.282	1.510
472.01	28.58	0.283	1.510
472.01	28.64	0.283	1.510
472.02	28.71	0.283	1.511
472.03	28.78	0.283	1.511
472.03	28.85	0.283	1.512
472.04	28.91	0.283	1.512
472.04	28.98	0.283	1.512
472.05	29.04	0.283	1.512
472.06	29.11	0.283	1.512
472.07	29.18	0.283	1.513
472.07	29.25	0.283	1.512
472.08	29.31	0.283	1.512
472.08	29.38	0.283	1.513
472.09	29.45	0.283	1.513
472.10	29.51	0.283	1.513
472.11	29.58	0.283	1.513
472.11	29.65	0.283	1.514
472.12	29.71	0.283	1.513
472.13	29.78	0.283	1.513
472.13	29.85	0.283	1.514
472.14	29.91	0.283	1.515
472.14	29.98	0.283	1.515
472.15	30.05	0.283	1.514
472.16	30.11	0.284	1.514
472.17	30.18	0.284	1.515
472.17	30.25	0.284	1.515
472.18	30.31	0.284	1.515
472.18	30.38	0.284	1.516
472.19	30.45	0.284	1.516
472.20	30.51	0.284	1.517
472.21	30.58	0.284	1.517
472.21	30.65	0.284	1.517
472.22	30.71	0.284	1.517
472.23	30.78	0.284	1.517
472.23	30.85	0.284	1.517
472.24	30.92	0.284	1.518
472.24	30.98	0.284	1.518
472.25	31.05	0.284	1.518
472.26	31.12	0.284	1.518
472.27	31.18	0.284	1.519
472.27	31.25	0.284	1.519
472.28	31.32	0.284	1.520
472.28	31.38	0.284	1.520
472.29	31.45	0.284	1.520
472.30	31.51	0.284	1.520
472.31	31.58	0.284	1.520
472.31	31.65	0.284	1.520
472.32	31.72	0.285	1.522
472.33	31.78	0.285	1.522
472.33	31.85	0.285	1.522
472.34	31.92	0.285	1.522
472.34	31.98	0.285	1.522
472.35	32.05	0.285	1.523
472.36	32.12	0.285	1.523
472.37	32.18	0.285	1.523
472.37	32.25	0.285	1.523
472.38	32.32	0.285	1.523
472.38	32.38	0.285	1.524
472.39	32.45	0.285	1.524
472.40	32.52	0.285	1.524
472.41	32.58	0.285	1.524
472.41	32.65	0.285	1.525
472.42	32.72	0.285	1.525
472.43	32.78	0.285	1.525
472.43	32.85	0.285	1.525
472.44	32.92	0.285	1.525
472.44	32.98	0.285	1.526
472.45	33.05	0.285	1.526
472.46	33.12	0.285	1.527
472.47	33.18	0.285	1.526
472.47	33.25	0.285	1.527
472.48	33.32	0.286	1.527
472.48	33.39	0.286	1.528
472.49	33.45	0.286	1.528
472.50	33.52	0.286	1.528
472.51	33.59	0.286	1.528
472.51	33.65	0.286	1.528
472.52	33.72	0.286	1.528
472.53	33.78	0.286	1.528
472.53	33.85	0.286	1.529
472.54	33.92	0.286	1.529
472.54	33.98	0.286	1.529
472.55	34.05	0.286	1.529
472.56	34.12	0.286	1.529
472.57	34.18	0.286	1.530
472.57	34.25	0.286	1.530
472.58	34.32	0.286	1.530
472.58	34.38	0.286	1.530
472.59	34.45	0.286	1.530
472.60	34.52	0.286	1.531
472.61	34.59	0.286	1.531
472.61	34.65	0.286	1.531
472.62	34.72	0.286	1.531
472.63	34.79	0.286	1.532
472.63	34.85	0.286	1.532
472.64	34.92	0.286	1.532
472.64	34.99	0.287	1.532
472.65	35.05	0.287	1.532
472.66	35.12	0.287	1.532
472.67	35.19	0.287	1.532
472.67	35.25	0.287	1.533
472.68	35.32	0.287	1.533
472.68	35.39	0.287	1.533
472.69	35.45	0.287	1.533
472.70	35.52	0.287	1.533
472.71	35.59	0.287	1.534
472.71	35.65	0.287	1.534
472.72	35.72	0.287	1.533
472.73	35.79	0.287	1.533
472.73	35.85	0.287	1.534
472.74	35.92	0.287	1.534
472.74	35.99	0.287	1.534
472.75	36.05	0.287	1.534
472.76	36.12	0.287	1.535
472.77	36.19	0.287	1.535
472.77	36.25	0.287	1.535
472.78	36.32	0.287	1.535
472.78	36.39	0.287	1.535
472.79	36.45	0.287	1.536
472.80	36.52	0.287	1.536
472.81	36.59	0.287	1.536
472.81	36.65	0.288	1.536
472.82	36.72	0.288	1.536
472.83	36.79	0.288	1.536
472.83	36.86	0.288	1.537
472.84	36.92	0.288	1.537
472.84	36.99	0.288	1.538
472.85	37.06	0.288	1.538
472.86	37.12	0.288	1.538
472.87	37.19	0.288
472.87	37.26	0.288
472.88	37.32	0.288
472.88	37.39	0.288
472.89	37.46	0.288
472.90	37.52	0.288
472.91	37.59	0.288
472.91	37.66	0.288
472.92	37.72	0.288
472.93	37.79
472.93	37.86
472.94	37.92
472.94	37.99
472.95	38.06
472.96	38.12
472.97	38.19
472.97
472.98