File: DSC/2023_07_04_CBN_Fragility_SBK.txt
Filename	2023_07_04_CBN_Fragility_SBK
Instrument name	DSC2A-00468 (192.168.1.100)
Operator	SBK
rundate	7/4/2023
Sample name	2023_07_04_CBN_Fragility_SBK
proceduresegments	Data Off ; Equilibrate -50.00 °C; Data On ; Ramp 10.00 °C/min to 100.00 °C; Data Off ; Isothermal 1.0 min; Data On ; Ramp 10.00 °C/min to -50.00 °C; Data Off ; Isothermal 1.0 min; Data On ; Ramp 10.00 °C/min to 100.00 °C; Data Off ; Isothermal 1.0 min; Data On ; Ramp 40.00 °C/min to -50.00 °C; Data Off ; Isothermal 1.0 min; Data On ; Ramp 10.00 °C/min to 100.00 °C; Data Off ; Isothermal 1.0 min; Data On ; Ramp 30.00 °C/min to -50.00 °C; Data Off ; Isothermal 1.0 min; Data On ; Ramp 10.00 °C/min to 100.00 °C; Data Off ; Isothermal 1.0 min; Data On ; Ramp 20.00 °C/min to -50.00 °C; Data Off ; Isothermal 1.0 min; Data On ; Ramp 10.00 °C/min to 100.00 °C; Data Off ; Isothermal 1.0 min; Data On ; Sample Interval  0.2 s/pt; Ramp 5.00 °C/min to -50.00 °C; Data Off ; Isothermal 1.0 min; Data On ; Sample Interval  0.1 s/pt; Ramp 10.00 °C/min to 100.00 °C; Data Off ; Isothermal 1.0 min; Data On ; Sample Interval  1.0 s/pt; Ramp 1.00 °C/min to -50.00 °C; Data Off ; Isothermal 1.0 min; Data On ; Sample Interval  0.1 s/pt; Ramp 10.00 °C/min to 100.00 °C; Data Off ; Isothermal 1.0 min; Data On ; Sample Interval  2.0 s/pt; Ramp 0.50 °C/min to -50.00 °C; Data Off ; Isothermal 1.0 min; Data On ; Sample Interval  0.1 s/pt; Ramp 10.00 °C/min to 100.00 °C
[File Parameters]
Run date	7/4/2023 11:05:52 AM
Trios version	5.1.1.46572
Original File Name	C:\Users\yargerlab\Desktop\DSC Data\General\2023_07_04_CBN_Fragility_SBK.tri
Current File Name	C:\Users\kauff\Documents\ASU\data_DSC\2023_07_04_CBN_Fragility_SBK.tri
[Procedure]
Procedure Name	DSC -50C to 100C Varied cooling rates (40 - 0.5 cpm) cannabinoid fragility
Sample Name	2023_07_04_CBN_Fragility_SBK
Sample Mass	2.72 mg
Reference Sample Mass	0 mg
Pan Mass	54.61 mg
Pan Number	45
Reference Pan Mass	53.66 mg
Reference Pan Number	46
Pan Type	Aluminum Hermetic
Comments	CBN crystalline powder, new sample. DSC84010 aluminum pan and DSC84011 aluminum hermetic lid. Wider temperature range to ensure full melting. Wider range of temperature scan rates.
Project Name	Silk ASDs
Operator	SBK
Test	Custom
Unload Max Temperature	30
Unload Min Temperature	30
Load Max Temperature	30
Load Min Temperature	30
Stop on Gas Flow Error	Yes
[Signal List]
Signal #1	Time (min)
Signal #2	Temperature (°C)
Signal #3	Heat Flow (mW)
Signal #4	Delta T (µV)
Signal #5	Delta Tzero (µV)
Signal #6	Tzero Temperature (°C)
Signal #7	Cell Purge (mL/min)
Signal #8	Heater Temp (°C)
Signal #9	Power Delivered (W)
Signal #10	Reference Junction Temperature (°C)
Signal #11	Flange Temperature (°C)
Signal #12	Heat Flow Phase (rad)
Signal #13	Total Heat Capacity (J/°C)
Signal #14	Heat Capacity (J/°C)
[Configuration]
Company Name	ASU
Instrument Name	DSC2A-00468
Instrument Type	DSC2500
Serial Number	DSC2A-00468
IP	192.168.1.100
Location of Instrument	MRRC
DisplayType	Unknown
Sample Interval 	0.1 s/pt
Selected Heat Flow	T4P
Exotherm Direction	Down
Cell Serial	DRC2-00792
Lid Type	Standard
Cooler	RCS 90
Leave Cooler on at End of Sequence	On
Gas 2	Nitrogen
Gas Selected	Channel 1
Flow Rate	50 mL/min
Secondary Purge	On
Licensed Heat Flow	Heat Flow T4P
Modulation Licensed	Yes
[Versions]
Common IDD Version	1
Cortex Version	VER 2.10.2.31
Driver	5.0.0.6
GDM Version	1.0.3.3
TouchscreenVersion	1.0.0.16145
FEP Version	1.2.1.21
FEP Bootloader	2.0.0.5
AutoSampler Version	2.1.1.26
Auto Sampler Bootloader	2.0.0.5
FCM Version	1.1.0.3
FCM Bootloader	2.0.0.5
[Experiment Logs]
Experiment Log Entry # 1	Data On set to 0
Experiment Log Entry # 3	Equilibrate Segment -50 (C) Started
Experiment Log Entry # 5	Data On set to 1
Experiment Log Entry # 7	Ramp Segment 10 C/min to 100 Started
Experiment Log Entry # 9	Data On set to 0
Experiment Log Entry # 11	Isothermal Segment 1 min started
Experiment Log Entry # 13	Data On set to 1
Experiment Log Entry # 15	Ramp Segment 10 C/min to -50 Started
Experiment Log Entry # 17	Data On set to 0
Experiment Log Entry # 19	Isothermal Segment 1 min started
Experiment Log Entry # 21	Data On set to 1
Experiment Log Entry # 23	Ramp Segment 10 C/min to 100 Started
Experiment Log Entry # 25	Data On set to 0
Experiment Log Entry # 27	Isothermal Segment 1 min started
Experiment Log Entry # 29	Data On set to 1
Experiment Log Entry # 31	Ramp Segment 40 C/min to -50 Started
Experiment Log Entry # 33	Data On set to 0
Experiment Log Entry # 35	Isothermal Segment 1 min started
Experiment Log Entry # 37	Data On set to 1
Experiment Log Entry # 39	Ramp Segment 10 C/min to 100 Started
Experiment Log Entry # 41	Data On set to 0
Experiment Log Entry # 43	Isothermal Segment 1 min started
Experiment Log Entry # 45	Data On set to 1
Experiment Log Entry # 47	Ramp Segment 30 C/min to -50 Started
Experiment Log Entry # 49	Data On set to 0
Experiment Log Entry # 51	Isothermal Segment 1 min started
Experiment Log Entry # 53	Data On set to 1
Experiment Log Entry # 55	Ramp Segment 10 C/min to 100 Started
Experiment Log Entry # 57	Data On set to 0
Experiment Log Entry # 59	Isothermal Segment 1 min started
Experiment Log Entry # 61	Data On set to 1
Experiment Log Entry # 63	Ramp Segment 20 C/min to -50 Started
Experiment Log Entry # 65	Data On set to 0
Experiment Log Entry # 67	Isothermal Segment 1 min started
Experiment Log Entry # 69	Data On set to 1
Experiment Log Entry # 71	Ramp Segment 10 C/min to 100 Started
Experiment Log Entry # 73	Data On set to 0
Experiment Log Entry # 75	Isothermal Segment 1 min started
Experiment Log Entry # 77	Data On set to 1
Experiment Log Entry # 79	Sampling Rate set to 0.2 sec/pt
Experiment Log Entry # 81	Ramp Segment 5 C/min to -50 Started
Experiment Log Entry # 83	Data On set to 0
Experiment Log Entry # 85	Isothermal Segment 1 min started
Experiment Log Entry # 87	Data On set to 1
Experiment Log Entry # 89	Sampling Rate set to 0.1 sec/pt
Experiment Log Entry # 91	Ramp Segment 10 C/min to 100 Started
Experiment Log Entry # 93	Data On set to 0
Experiment Log Entry # 95	Isothermal Segment 1 min started
Experiment Log Entry # 97	Data On set to 1
Experiment Log Entry # 99	Sampling Rate set to 1 sec/pt
Experiment Log Entry # 101	Ramp Segment 1 C/min to -50 Started
Experiment Log Entry # 103	Auto sampler has detected that GDM has gone offline
Experiment Log Entry # 105	Data On set to 0
Experiment Log Entry # 107	Isothermal Segment 1 min started
Experiment Log Entry # 109	Data On set to 1
Experiment Log Entry # 111	Sampling Rate set to 0.1 sec/pt
Experiment Log Entry # 113	Ramp Segment 10 C/min to 100 Started
Experiment Log Entry # 115	Data On set to 0
Experiment Log Entry # 117	Isothermal Segment 1 min started
Experiment Log Entry # 119	Data On set to 1
Experiment Log Entry # 121	Sampling Rate set to 2 sec/pt
Experiment Log Entry # 123	Ramp Segment 0.5 C/min to -50 Started
Experiment Log Entry # 125	Data On set to 0
Experiment Log Entry # 127	Isothermal Segment 1 min started
Experiment Log Entry # 129	Data On set to 1
Experiment Log Entry # 131	Sampling Rate set to 0.1 sec/pt
Experiment Log Entry # 133	Ramp Segment 10 C/min to 100 Started
[Method Log]
Method Log Entry # 1	Data Off
Method Log Entry # 2	Equilibrate -50 °C
Method Log Entry # 3	Data On
Method Log Entry # 4	(Ramp 6097) Ramp 10 °C/minute to 100 °C
Method Log Entry # 5	Data Off
Method Log Entry # 6	Isothermal 1 minutes
Method Log Entry # 7	Data On
Method Log Entry # 8	(Ramp 6101) Ramp 10 °C/minute to -50 °C
Method Log Entry # 9	Data Off
Method Log Entry # 10	Isothermal 1 minutes
Method Log Entry # 11	Data On
Method Log Entry # 12	(Ramp 6105) Ramp 10 °C/minute to 100 °C
Method Log Entry # 13	Data Off
Method Log Entry # 14	Isothermal 1 minutes
Method Log Entry # 15	Data On
Method Log Entry # 16	(Ramp 6109) Ramp 40 °C/minute to -50 °C
Method Log Entry # 17	Data Off
Method Log Entry # 18	Isothermal 1 minutes
Method Log Entry # 19	Data On
Method Log Entry # 20	(Ramp 6113) Ramp 10 °C/minute to 100 °C
Method Log Entry # 21	Data Off
Method Log Entry # 22	Isothermal 1 minutes
Method Log Entry # 23	Data On
Method Log Entry # 24	(Ramp 6117) Ramp 30 °C/minute to -50 °C
Method Log Entry # 25	Data Off
Method Log Entry # 26	Isothermal 1 minutes
Method Log Entry # 27	Data On
Method Log Entry # 28	(Ramp 6121) Ramp 10 °C/minute to 100 °C
Method Log Entry # 29	Data Off
Method Log Entry # 30	Isothermal 1 minutes
Method Log Entry # 31	Data On
Method Log Entry # 32	(Ramp 6125) Ramp 20 °C/minute to -50 °C
Method Log Entry # 33	Data Off
Method Log Entry # 34	Isothermal 1 minutes
Method Log Entry # 35	Data On
Method Log Entry # 36	(Ramp 6129) Ramp 10 °C/minute to 100 °C
Method Log Entry # 37	Data Off
Method Log Entry # 38	Isothermal 1 minutes
Method Log Entry # 39	Data On
Method Log Entry # 40	Sampling Interval 0.2 Seconds/point
Method Log Entry # 41	(Ramp 6134) Ramp 5 °C/minute to -50 °C
Method Log Entry # 42	Data Off
Method Log Entry # 43	Isothermal 1 minutes
Method Log Entry # 44	Data On
Method Log Entry # 45	Sampling Interval 0.1 Seconds/point
Method Log Entry # 46	(Ramp 6139) Ramp 10 °C/minute to 100 °C
Method Log Entry # 47	Data Off
Method Log Entry # 48	Isothermal 1 minutes
Method Log Entry # 49	Data On
Method Log Entry # 50	Sampling Interval 1 Seconds/point
Method Log Entry # 51	(Ramp 6144) Ramp 1 °C/minute to -50 °C
Method Log Entry # 52	Data Off
Method Log Entry # 53	Isothermal 1 minutes
Method Log Entry # 54	Data On
Method Log Entry # 55	Sampling Interval 0.1 Seconds/point
Method Log Entry # 56	(Ramp 6149) Ramp 10 °C/minute to 100 °C
Method Log Entry # 57	Data Off
Method Log Entry # 58	Isothermal 1 minutes
Method Log Entry # 59	Data On
Method Log Entry # 60	Sampling Interval 2 Seconds/point
Method Log Entry # 61	(Ramp 6154) Ramp 0.5 °C/minute to -50 °C
Method Log Entry # 62	Data Off
Method Log Entry # 63	Isothermal 1 minutes
Method Log Entry # 64	Data On
Method Log Entry # 65	Sampling Interval 0.1 Seconds/point
Method Log Entry # 66	(Ramp 6159) Ramp 10 °C/minute to 100 °C
Cell Serial	DRC2-00792
[T1 Calibration]
Slope	-0.008529666
Offset	9.636258
Initial Temperature	98.23
GUID	f8bfdadc-4977-4fdf-ba6d-0ba9134940c3
[TZero Calibration]
Date Applied	11/29/2022 4:06:13 PM
Description	From -89.059 °C to 396.009 °C at 20.000°C/min
Gas Type	Nitrogen
Pan Type	None
Source Files 1	C:\Users\yargerlab\Desktop\DSC Data\General\TZero_calibration_11_29_22_2nd(2).tri
Source Files 2	C:\Users\yargerlab\Desktop\DSC Data\General\TZero_calibration_11_29_22_2nd(3).tri
Delta T Offset	13.05235
Delta T Slope	-0.007271007
Delta T0 Offset	-13.69128
Delta T0 Slope	0.06063341
[Temperature Calibration]
Date Applied	11/29/2022 7:12:28 PM
Description	From 106.590 °C to 186.590 °C at 10.000°C/min
Gas Type	Nitrogen
Pan Type	Tzero Aluminum Hermetic
Source Files 1	C:\Users\yargerlab\Desktop\DSC Data\General\Indium(6).tri
Measured 1	157.391
Known 1	156.598
[Cell Constant Calibration]
Date Applied	11/29/2022 7:12:29 PM
Description	From 106.590 °C to 186.590 °C at 10.000°C/min
Gas Type	Nitrogen
Pan Type	Tzero Aluminum Hermetic
Source Files 1	C:\Users\yargerlab\Desktop\DSC Data\General\Indium(6).tri
T4P KCell	1.006051
Onset Slope	63.26126 mW/°C
[Direct Cp Calibration]
Date Applied	11/30/2022 11:04:51 AM
Description	From -79.983 °C to 298.409 °C at 10.000°C/min
Gas Type	Nitrogen
Pan Type	Tzero Aluminum Hermetic
Source Files 1	C:\Users\yargerlab\Desktop\DSC Data\General\Sapphire_Heat_Capacity_11_30_22.tri
[Rev Cp Calibration]
Date Applied	11/30/2022 1:58:51 PM
Description	From -79.996 °C to 292.812 °C at 3.000°C/min
Gas Type	Nitrogen
Pan Type	Tzero Aluminum Hermetic
Source Files 1	C:\Users\yargerlab\Desktop\DSC Data\General\Sapphire_MDSC_Calibration_11_30_22.tri
[step]
Ramp 10.00 °C/min to 100.00 °C
Time	Temperature	Heat Flow (Normalized)	Heat Capacity (Normalized)
min	°C	W/g	J/(g.°C)
0.00	-49.74	-0.062	0.000
0.01	-49.75	-0.062	0.000
0.02	-49.75	-0.059	0.000
0.03	-49.76	-0.055	0.000
0.04	-49.76	-0.050	0.000
0.05	-49.76	-0.047	0.000
0.06	-49.76	-0.044	-1.578
0.07	-49.75	-0.042	-1.188
0.08	-49.73	-0.041	-0.978
0.09	-49.71	-0.041	-0.826
0.10	-49.69	-0.041	-0.712
0.11	-49.66	-0.041	-0.625
0.12	-49.62	-0.041	-0.557
0.13	-49.58	-0.040	-0.491
0.14	-49.53	-0.038	-0.429
0.15	-49.47	-0.031	-0.318
0.16	-49.41	-0.018	-0.175
0.17	-49.35	-0.006	-0.057
0.18	-49.28	0.011	0.090
0.19	-49.22	0.024	0.193
0.20	-49.14	0.037	0.286
0.21	-49.07	0.050	0.365
0.22	-48.99	0.063	0.446
0.23	-48.92	0.077	0.527
0.24	-48.84	0.088	0.589
0.25	-48.75	0.101	0.658
0.26	-48.67	0.112	0.718
0.27	-48.59	0.120	0.759
0.28	-48.50	0.133	0.822
0.29	-48.42	0.138	0.847
0.30	-48.33	0.146	0.884
0.31	-48.24	0.155	0.924
0.32	-48.16	0.161	0.952
0.33	-48.06	0.166	0.974
0.34	-47.98	0.170	0.989
0.35	-47.89	0.178	1.029
0.36	-47.79	0.184	1.054
0.37	-47.70	0.186	1.059
0.38	-47.61	0.190	1.078
0.39	-47.52	0.194	1.096
0.40	-47.42	0.197	1.105
0.41	-47.33	0.200	1.117
0.42	-47.24	0.204	1.133
0.43	-47.14	0.208	1.152
0.44	-47.05	0.210	1.161
0.45	-46.95	0.211	1.161
0.46	-46.86	0.213	1.166
0.47	-46.76	0.216	1.183
0.48	-46.67	0.218	1.189
0.49	-46.57	0.219	1.191
0.50	-46.48	0.221	1.199
0.51	-46.38	0.222	1.202
0.52	-46.28	0.223	1.206
0.53	-46.19	0.224	1.207
0.54	-46.09	0.225	1.211
0.55	-45.99	0.225	1.214
0.56	-45.90	0.226	1.217
0.57	-45.80	0.227	1.218
0.58	-45.70	0.227	1.219
0.59	-45.61	0.229	1.226
0.60	-45.51	0.229	1.226
0.61	-45.41	0.230	1.228
0.62	-45.31	0.230	1.230
0.63	-45.22	0.230	1.230
0.64	-45.12	0.231	1.232
0.65	-45.02	0.231	1.233
0.66	-44.92	0.232	1.235
0.67	-44.83	0.232	1.236
0.68	-44.73	0.232	1.236
0.69	-44.63	0.233	1.237
0.70	-44.53	0.233	1.239
0.71	-44.43	0.234	1.244
0.72	-44.33	0.234	1.244
0.73	-44.24	0.235	1.246
0.74	-44.14	0.235	1.246
0.75	-44.04	0.235	1.247
0.76	-43.94	0.235	1.248
0.77	-43.84	0.236	1.249
0.78	-43.75	0.236	1.251
0.79	-43.65	0.236	1.252
0.80	-43.55	0.236	1.252
0.81	-43.45	0.237	1.254
0.82	-43.35	0.237	1.256
0.83	-43.25	0.237	1.256
0.84	-43.15	0.238	1.256
0.85	-43.06	0.238	1.258
0.86	-42.96	0.238	1.258
0.87	-42.86	0.238	1.259
0.88	-42.76	0.239	1.260
0.89	-42.66	0.239	1.260
0.90	-42.56	0.239	1.261
0.91	-42.46	0.239	1.261
0.92	-42.36	0.239	1.262
0.93	-42.26	0.239	1.262
0.94	-42.17	0.239	1.261
0.95	-42.07	0.240	1.263
0.96	-41.97	0.240	1.264
0.97	-41.87	0.240	1.264
0.98	-41.77	0.240	1.264
0.99	-41.67	0.240	1.265
1.00	-41.57	0.241	1.266
1.01	-41.47	0.241	1.266
1.02	-41.37	0.241	1.266
1.03	-41.27	0.241	1.269
1.04	-41.17	0.241	1.269
1.05	-41.07	0.241	1.269
1.06	-40.97	0.241	1.270
1.07	-40.88	0.241	1.269
1.08	-40.78	0.241	1.270
1.09	-40.68	0.242	1.271
1.10	-40.58	0.242	1.271
1.11	-40.48	0.242	1.271
1.12	-40.38	0.242	1.271
1.13	-40.28	0.242	1.272
1.14	-40.18	0.242	1.272
1.15	-40.08	0.242	1.273
1.16	-39.98	0.242	1.273
1.17	-39.88	0.242	1.272
1.18	-39.78	0.242	1.273
1.19	-39.68	0.242	1.273
1.20	-39.58	0.242	1.273
1.21	-39.48	0.243	1.274
1.22	-39.38	0.243	1.274
1.23	-39.28	0.243	1.274
1.24	-39.18	0.243	1.275
1.25	-39.08	0.243	1.275
1.26	-38.98	0.243	1.275
1.27	-38.88	0.243	1.275
1.28	-38.78	0.243	1.276
1.29	-38.68	0.243	1.276
1.30	-38.59	0.243	1.276
1.31	-38.48	0.243	1.277
1.32	-38.38	0.243	1.277
1.33	-38.28	0.243	1.277
1.34	-38.19	0.243	1.277
1.35	-38.09	0.243	1.277
1.36	-37.99	0.243	1.277
1.37	-37.89	0.243	1.278
1.38	-37.79	0.243	1.278
1.39	-37.69	0.243	1.279
1.40	-37.59	0.243	1.279
1.41	-37.49	0.243	1.279
1.42	-37.39	0.243	1.279
1.43	-37.29	0.243	1.279
1.44	-37.19	0.243	1.279
1.45	-37.09	0.244	1.279
1.46	-36.99	0.243	1.278
1.47	-36.89	0.243	1.278
1.48	-36.79	0.243	1.279
1.49	-36.69	0.243	1.278
1.50	-36.59	0.243	1.278
1.51	-36.49	0.243	1.278
1.52	-36.39	0.243	1.278
1.53	-36.29	0.243	1.278
1.54	-36.19	0.243	1.278
1.55	-36.09	0.243	1.278
1.56	-35.99	0.243	1.279
1.57	-35.89	0.243	1.278
1.58	-35.79	0.243	1.279
1.59	-35.69	0.244	1.279
1.60	-35.59	0.243	1.278
1.61	-35.49	0.244	1.279
1.62	-35.39	0.244	1.280
1.63	-35.29	0.244	1.280
1.64	-35.19	0.244	1.280
1.65	-35.09	0.244	1.280
1.66	-34.99	0.244	1.280
1.67	-34.89	0.244	1.280
1.68	-34.79	0.244	1.281
1.69	-34.69	0.244	1.280
1.70	-34.59	0.244	1.280
1.71	-34.49	0.244	1.281
1.72	-34.39	0.244	1.280
1.73	-34.29	0.244	1.281
1.74	-34.19	0.244	1.281
1.75	-34.09	0.244	1.281
1.76	-33.99	0.244	1.280
1.77	-33.89	0.244	1.281
1.78	-33.79	0.244	1.280
1.79	-33.69	0.244	1.280
1.80	-33.59	0.243	1.280
1.81	-33.49	0.244	1.280
1.82	-33.39	0.244	1.280
1.83	-33.29	0.244	1.281
1.84	-33.19	0.244	1.280
1.85	-33.09	0.244	1.280
1.86	-32.99	0.244	1.281
1.87	-32.89	0.244	1.281
1.88	-32.79	0.243	1.281
1.89	-32.69	0.244	1.281
1.90	-32.59	0.244	1.281
1.91	-32.49	0.243	1.280
1.92	-32.39	0.243	1.281
1.93	-32.29	0.243	1.281
1.94	-32.19	0.243	1.281
1.95	-32.09	0.243	1.281
1.96	-31.99	0.243	1.282
1.97	-31.89	0.243	1.282
1.98	-31.79	0.243	1.282
1.99	-31.69	0.243	1.282
2.00	-31.59	0.243	1.282
2.01	-31.49	0.243	1.283
2.02	-31.39	0.243	1.283
2.03	-31.29	0.243	1.282
2.04	-31.18	0.243	1.282
2.05	-31.09	0.243	1.283
2.06	-30.98	0.243	1.283
2.07	-30.88	0.243	1.283
2.08	-30.79	0.243	1.283
2.09	-30.68	0.243	1.282
2.10	-30.58	0.243	1.283
2.11	-30.49	0.243	1.284
2.12	-30.39	0.243	1.283
2.13	-30.29	0.243	1.283
2.14	-30.18	0.243	1.283
2.15	-30.08	0.243	1.283
2.16	-29.98	0.243	1.284
2.17	-29.89	0.243	1.284
2.18	-29.78	0.243	1.283
2.19	-29.68	0.243	1.283
2.20	-29.58	0.243	1.283
2.21	-29.49	0.243	1.282
2.22	-29.38	0.243	1.283
2.23	-29.28	0.243	1.284
2.24	-29.18	0.243	1.284
2.25	-29.08	0.243	1.284
2.26	-28.98	0.243	1.284
2.27	-28.88	0.243	1.283
2.28	-28.78	0.243	1.284
2.29	-28.68	0.243	1.284
2.30	-28.58	0.243	1.283
2.31	-28.48	0.243	1.283
2.32	-28.38	0.243	1.283
2.33	-28.28	0.243	1.283
2.34	-28.18	0.243	1.283
2.35	-28.08	0.243	1.283
2.36	-27.98	0.243	1.284
2.37	-27.88	0.243	1.284
2.38	-27.78	0.243	1.284
2.39	-27.68	0.243	1.284
2.40	-27.58	0.243	1.285
2.41	-27.48	0.243	1.285
2.42	-27.38	0.243	1.285
2.43	-27.28	0.243	1.285
2.44	-27.18	0.243	1.285
2.45	-27.08	0.243	1.285
2.46	-26.98	0.243	1.285
2.47	-26.88	0.243	1.285
2.48	-26.78	0.243	1.285
2.49	-26.68	0.243	1.285
2.50	-26.58	0.243	1.286
2.51	-26.48	0.243	1.286
2.52	-26.38	0.243	1.287
2.53	-26.28	0.243	1.287
2.54	-26.18	0.243	1.287
2.55	-26.08	0.243	1.286
2.56	-25.98	0.243	1.286
2.57	-25.88	0.243	1.286
2.58	-25.78	0.243	1.287
2.59	-25.68	0.243	1.286
2.60	-25.58	0.243	1.286
2.61	-25.48	0.243	1.287
2.62	-25.38	0.243	1.287
2.63	-25.28	0.243	1.287
2.64	-25.18	0.243	1.286
2.65	-25.08	0.243	1.286
2.66	-24.98	0.243	1.286
2.67	-24.88	0.243	1.287
2.68	-24.78	0.243	1.288
2.69	-24.68	0.243	1.288
2.70	-24.58	0.243	1.288
2.71	-24.48	0.243	1.287
2.72	-24.38	0.243	1.286
2.73	-24.28	0.243	1.287
2.74	-24.18	0.243	1.288
2.75	-24.08	0.243	1.287
2.76	-23.98	0.243	1.288
2.77	-23.88	0.243	1.288
2.78	-23.78	0.243	1.288
2.79	-23.68	0.243	1.288
2.80	-23.58	0.243	1.288
2.81	-23.48	0.243	1.288
2.82	-23.38	0.243	1.289
2.83	-23.28	0.243	1.289
2.84	-23.18	0.244	1.289
2.85	-23.08	0.244	1.289
2.86	-22.98	0.244	1.290
2.87	-22.88	0.244	1.290
2.88	-22.78	0.244	1.290
2.89	-22.68	0.244	1.290
2.90	-22.58	0.244	1.290
2.91	-22.48	0.244	1.291
2.92	-22.37	0.244	1.291
2.93	-22.28	0.244	1.290
2.94	-22.18	0.244	1.291
2.95	-22.08	0.244	1.291
2.96	-21.98	0.244	1.291
2.97	-21.88	0.244	1.292
2.98	-21.78	0.244	1.291
2.99	-21.67	0.244	1.292
3.00	-21.57	0.244	1.293
3.01	-21.47	0.244	1.293
3.02	-21.37	0.244	1.293
3.03	-21.27	0.244	1.293
3.04	-21.17	0.244	1.293
3.05	-21.07	0.244	1.294
3.06	-20.97	0.244	1.295
3.07	-20.87	0.244	1.295
3.08	-20.77	0.244	1.295
3.09	-20.67	0.244	1.295
3.10	-20.57	0.244	1.296
3.11	-20.48	0.244	1.296
3.12	-20.37	0.244	1.294
3.13	-20.27	0.244	1.294
3.14	-20.17	0.244	1.295
3.15	-20.07	0.244	1.295
3.16	-19.97	0.244	1.294
3.17	-19.87	0.244	1.295
3.18	-19.77	0.244	1.295
3.19	-19.67	0.244	1.295
3.20	-19.57	0.244	1.295
3.21	-19.47	0.244	1.295
3.22	-19.37	0.244	1.296
3.23	-19.27	0.244	1.296
3.24	-19.17	0.244	1.296
3.25	-19.07	0.244	1.296
3.26	-18.97	0.244	1.297
3.27	-18.87	0.244	1.297
3.28	-18.77	0.244	1.297
3.29	-18.67	0.244	1.298
3.30	-18.57	0.244	1.297
3.31	-18.47	0.244	1.297
3.32	-18.37	0.244	1.298
3.33	-18.27	0.244	1.298
3.34	-18.17	0.244	1.299
3.35	-18.07	0.245	1.299
3.36	-17.97	0.245	1.299
3.37	-17.87	0.245	1.299
3.38	-17.77	0.245	1.299
3.39	-17.67	0.245	1.300
3.40	-17.57	0.245	1.300
3.41	-17.47	0.245	1.300
3.42	-17.37	0.245	1.300
3.43	-17.27	0.245	1.300
3.44	-17.17	0.245	1.301
3.45	-17.07	0.245	1.301
3.46	-16.97	0.245	1.301
3.47	-16.87	0.245	1.301
3.48	-16.77	0.245	1.302
3.49	-16.67	0.245	1.301
3.50	-16.57	0.245	1.302
3.51	-16.47	0.245	1.302
3.52	-16.37	0.245	1.302
3.53	-16.27	0.245	1.302
3.54	-16.17	0.245	1.302
3.55	-16.07	0.245	1.303
3.56	-15.97	0.245	1.303
3.57	-15.87	0.245	1.303
3.58	-15.77	0.245	1.303
3.59	-15.67	0.245	1.303
3.60	-15.57	0.245	1.304
3.61	-15.47	0.245	1.304
3.62	-15.37	0.245	1.305
3.63	-15.27	0.245	1.305
3.64	-15.17	0.245	1.305
3.65	-15.07	0.245	1.305
3.66	-14.97	0.245	1.305
3.67	-14.87	0.245	1.306
3.68	-14.77	0.245	1.306
3.69	-14.67	0.246	1.306
3.70	-14.57	0.246	1.306
3.71	-14.47	0.246	1.307
3.72	-14.37	0.246	1.307
3.73	-14.27	0.246	1.307
3.74	-14.17	0.246	1.308
3.75	-14.07	0.246	1.308
3.76	-13.97	0.246	1.308
3.77	-13.87	0.246	1.308
3.78	-13.77	0.246	1.308
3.79	-13.66	0.246	1.308
3.80	-13.56	0.246	1.309
3.81	-13.47	0.246	1.309
3.82	-13.36	0.246	1.310
3.83	-13.26	0.246	1.310
3.84	-13.16	0.246	1.311
3.85	-13.06	0.246	1.311
3.86	-12.97	0.246	1.311
3.87	-12.86	0.246	1.311
3.88	-12.76	0.246	1.312
3.89	-12.66	0.246	1.312
3.90	-12.56	0.246	1.312
3.91	-12.46	0.246	1.313
3.92	-12.36	0.247	1.313
3.93	-12.26	0.247	1.314
3.94	-12.16	0.247	1.315
3.95	-12.06	0.247	1.315
3.96	-11.96	0.247	1.315
3.97	-11.86	0.247	1.316
3.98	-11.76	0.247	1.316
3.99	-11.66	0.247	1.316
4.00	-11.56	0.247	1.317
4.01	-11.46	0.247	1.318
4.02	-11.36	0.247	1.317
4.03	-11.26	0.247	1.318
4.04	-11.16	0.247	1.318
4.05	-11.06	0.247	1.319
4.06	-10.96	0.248	1.319
4.07	-10.86	0.248	1.320
4.08	-10.76	0.248	1.321
4.09	-10.66	0.248	1.321
4.10	-10.56	0.248	1.322
4.11	-10.46	0.248	1.323
4.12	-10.36	0.248	1.323
4.13	-10.26	0.248	1.324
4.14	-10.16	0.248	1.324
4.15	-10.06	0.248	1.325
4.16	-9.96	0.248	1.325
4.17	-9.86	0.249	1.326
4.18	-9.76	0.249	1.326
4.19	-9.66	0.249	1.327
4.20	-9.56	0.249	1.328
4.21	-9.46	0.249	1.327
4.22	-9.36	0.249	1.329
4.23	-9.26	0.249	1.329
4.24	-9.16	0.249	1.330
4.25	-9.06	0.249	1.330
4.26	-8.96	0.249	1.332
4.27	-8.86	0.250	1.332
4.28	-8.76	0.250	1.333
4.29	-8.66	0.250	1.333
4.30	-8.56	0.250	1.334
4.31	-8.46	0.250	1.336
4.32	-8.36	0.250	1.337
4.33	-8.26	0.251	1.337
4.34	-8.16	0.251	1.339
4.35	-8.06	0.251	1.339
4.36	-7.96	0.251	1.340
4.37	-7.86	0.251	1.340
4.38	-7.76	0.251	1.342
4.39	-7.66	0.251	1.342
4.40	-7.56	0.252	1.343
4.41	-7.46	0.252	1.344
4.42	-7.36	0.252	1.344
4.43	-7.26	0.252	1.346
4.44	-7.16	0.252	1.347
4.45	-7.06	0.252	1.347
4.46	-6.96	0.252	1.348
4.47	-6.86	0.253	1.348
4.48	-6.76	0.253	1.350
4.49	-6.66	0.253	1.351
4.50	-6.56	0.253	1.352
4.51	-6.46	0.253	1.353
4.52	-6.36	0.253	1.354
4.53	-6.26	0.254	1.356
4.54	-6.16	0.254	1.356
4.55	-6.06	0.254	1.357
4.56	-5.96	0.254	1.358
4.57	-5.86	0.254	1.359
4.58	-5.76	0.255	1.361
4.59	-5.66	0.255	1.362
4.60	-5.56	0.255	1.363
4.61	-5.46	0.255	1.364
4.62	-5.36	0.255	1.365
4.63	-5.26	0.256	1.367
4.64	-5.16	0.256	1.367
4.65	-5.06	0.256	1.368
4.66	-4.96	0.257	1.371
4.67	-4.86	0.257	1.373
4.68	-4.76	0.257	1.374
4.69	-4.66	0.257	1.375
4.70	-4.56	0.258	1.377
4.71	-4.46	0.258	1.379
4.72	-4.36	0.258	1.380
4.73	-4.26	0.259	1.382
4.74	-4.16	0.259	1.384
4.75	-4.06	0.259	1.386
4.76	-3.95	0.260	1.387
4.77	-3.85	0.260	1.390
4.78	-3.76	0.260	1.392
4.79	-3.65	0.261	1.395
4.80	-3.55	0.261	1.396
4.81	-3.45	0.261	1.398
4.82	-3.36	0.262	1.403
4.83	-3.25	0.263	1.404
4.84	-3.15	0.263	1.406
4.85	-3.05	0.263	1.409
4.86	-2.95	0.264	1.412
4.87	-2.86	0.264	1.413
4.88	-2.76	0.265	1.417
4.89	-2.66	0.265	1.421
4.90	-2.55	0.266	1.422
4.91	-2.45	0.266	1.425
4.92	-2.35	0.267	1.429
4.93	-2.26	0.267	1.432
4.94	-2.15	0.268	1.436
4.95	-2.05	0.269	1.439
4.96	-1.95	0.270	1.446
4.97	-1.85	0.270	1.448
4.98	-1.76	0.271	1.454
4.99	-1.66	0.272	1.459
5.00	-1.55	0.273	1.462
5.01	-1.45	0.274	1.466
5.02	-1.35	0.274	1.469
5.03	-1.25	0.275	1.472
5.04	-1.16	0.276	1.477
5.05	-1.05	0.280	1.500
5.06	-0.95	0.281	1.505
5.07	-0.86	0.281	1.507
5.08	-0.76	0.283	1.514
5.09	-0.65	0.284	1.521
5.10	-0.56	0.285	1.526
5.11	-0.46	0.286	1.533
5.12	-0.35	0.287	1.536
5.13	-0.26	0.288	1.541
5.14	-0.16	0.290	1.553
5.15	-0.06	0.290	1.556
5.16	0.04	0.292	1.566
5.17	0.14	0.294	1.576
5.18	0.24	0.295	1.583
5.19	0.34	0.296	1.589
5.20	0.44	0.299	1.602
5.21	0.54	0.302	1.618
5.22	0.64	0.303	1.626
5.23	0.74	0.305	1.638
5.24	0.84	0.307	1.645
5.25	0.94	0.308	1.653
5.26	1.04	0.311	1.668
5.27	1.14	0.313	1.678
5.28	1.24	0.314	1.684
5.29	1.34	0.316	1.696
5.30	1.44	0.319	1.711
5.31	1.54	0.320	1.720
5.32	1.64	0.321	1.725
5.33	1.74	0.324	1.739
5.34	1.84	0.325	1.744
5.35	1.94	0.327	1.753
5.36	2.04	0.328	1.761
5.37	2.14	0.330	1.770
5.38	2.24	0.332	1.785
5.39	2.34	0.334	1.794
5.40	2.44	0.336	1.801
5.41	2.54	0.337	1.807
5.42	2.64	0.338	1.812
5.43	2.74	0.339	1.821
5.44	2.84	0.340	1.826
5.45	2.94	0.341	1.829
5.46	3.04	0.342	1.833
5.47	3.14	0.343	1.839
5.48	3.24	0.343	1.840
5.49	3.34	0.344	1.845
5.50	3.44	0.345	1.848
5.51	3.54	0.346	1.853
5.52	3.64	0.347	1.858
5.53	3.74	0.347	1.859
5.54	3.84	0.347	1.860
5.55	3.94	0.348	1.862
5.56	4.04	0.348	1.862
5.57	4.14	0.348	1.863
5.58	4.24	0.348	1.864
5.59	4.34	0.349	1.864
5.60	4.44	0.349	1.865
5.61	4.54	0.349	1.865
5.62	4.64	0.349	1.866
5.63	4.74	0.349	1.865
5.64	4.84	0.349	1.865
5.65	4.94	0.349	1.864
5.66	5.04	0.349	1.863
5.67	5.14	0.349	1.862
5.68	5.24	0.348	1.862
5.69	5.34	0.348	1.861
5.70	5.44	0.348	1.860
5.71	5.54	0.348	1.858
5.72	5.64	0.348	1.857
5.73	5.74	0.347	1.854
5.74	5.84	0.346	1.850
5.75	5.94	0.346	1.850
5.76	6.04	0.346	1.849
5.77	6.14	0.346	1.847
5.78	6.24	0.346	1.846
5.79	6.34	0.345	1.845
5.80	6.44	0.345	1.844
5.81	6.54	0.345	1.841
5.82	6.64	0.344	1.840
5.83	6.74	0.344	1.839
5.84	6.84	0.344	1.838
5.85	6.94	0.344	1.837
5.86	7.04	0.343	1.835
5.87	7.14	0.343	1.834
5.88	7.24	0.343	1.833
5.89	7.34	0.343	1.831
5.90	7.44	0.342	1.829
5.91	7.55	0.342	1.828
5.92	7.64	0.342	1.827
5.93	7.74	0.342	1.825
5.94	7.84	0.341	1.824
5.95	7.95	0.341	1.823
5.96	8.05	0.341	1.822
5.97	8.15	0.341	1.822
5.98	8.24	0.341	1.821
5.99	8.35	0.340	1.819
6.00	8.45	0.340	1.818
6.01	8.55	0.340	1.816
6.02	8.65	0.340	1.815
6.03	8.75	0.340	1.815
6.04	8.85	0.339	1.814
6.05	8.95	0.339	1.812
6.06	9.05	0.339	1.811
6.07	9.15	0.339	1.811
6.08	9.25	0.339	1.809
6.09	9.35	0.339	1.809
6.10	9.45	0.339	1.809
6.11	9.55	0.338	1.809
6.12	9.65	0.338	1.809
6.13	9.75	0.338	1.808
6.14	9.85	0.338	1.808
6.15	9.95	0.338	1.808
6.16	10.05	0.338	1.807
6.17	10.15	0.338	1.806
6.18	10.25	0.338	1.806
6.19	10.35	0.338	1.806
6.20	10.45	0.338	1.805
6.21	10.55	0.337	1.804
6.22	10.65	0.337	1.804
6.23	10.75	0.337	1.804
6.24	10.85	0.337	1.802
6.25	10.95	0.337	1.804
6.26	11.05	0.337	1.803
6.27	11.15	0.337	1.802
6.28	11.25	0.337	1.802
6.29	11.35	0.337	1.802
6.30	11.45	0.337	1.802
6.31	11.55	0.337	1.800
6.32	11.65	0.337	1.800
6.33	11.75	0.337	1.800
6.34	11.85	0.337	1.799
6.35	11.95	0.337	1.799
6.36	12.05	0.337	1.800
6.37	12.15	0.337	1.800
6.38	12.25	0.337	1.800
6.39	12.35	0.337	1.799
6.40	12.45	0.337	1.800
6.41	12.55	0.337	1.799
6.42	12.65	0.337	1.799
6.43	12.75	0.337	1.800
6.44	12.85	0.337	1.800
6.45	12.95	0.337	1.800
6.46	13.05	0.337	1.800
6.47	13.15	0.336	1.799
6.48	13.25	0.336	1.798
6.49	13.35	0.336	1.798
6.50	13.45	0.336	1.798
6.51	13.55	0.336	1.798
6.52	13.65	0.336	1.798
6.53	13.75	0.336	1.797
6.54	13.85	0.336	1.798
6.55	13.95	0.336	1.798
6.56	14.05	0.336	1.798
6.57	14.15	0.336	1.797
6.58	14.25	0.336	1.797
6.59	14.36	0.337	1.799
6.60	14.45	0.337	1.799
6.61	14.55	0.337	1.799
6.62	14.65	0.337	1.799
6.63	14.76	0.337	1.799
6.64	14.86	0.337	1.800
6.65	14.96	0.337	1.801
6.66	15.06	0.337	1.800
6.67	15.16	0.337	1.801
6.68	15.26	0.337	1.802
6.69	15.36	0.337	1.802
6.70	15.46	0.337	1.802
6.71	15.56	0.337	1.802
6.72	15.66	0.338	1.803
6.73	15.76	0.338	1.805
6.74	15.86	0.338	1.804
6.75	15.96	0.338	1.805
6.76	16.06	0.338	1.805
6.77	16.16	0.338	1.806
6.78	16.26	0.338	1.806
6.79	16.36	0.338	1.806
6.80	16.46	0.338	1.807
6.81	16.56	0.338	1.807
6.82	16.66	0.338	1.808
6.83	16.76	0.338	1.808
6.84	16.86	0.338	1.808
6.85	16.96	0.339	1.809
6.86	17.06	0.339	1.809
6.87	17.16	0.339	1.809
6.88	17.26	0.339	1.809
6.89	17.36	0.339	1.810
6.90	17.46	0.339	1.810
6.91	17.56	0.339	1.810
6.92	17.66	0.339	1.811
6.93	17.76	0.339	1.811
6.94	17.86	0.339	1.812
6.95	17.96	0.339	1.813
6.96	18.06	0.339	1.813
6.97	18.16	0.339	1.813
6.98	18.26	0.339	1.813
6.99	18.36	0.340	1.814
7.00	18.46	0.340	1.814
7.01	18.56	0.340	1.814
7.02	18.66	0.340	1.816
7.03	18.76	0.340	1.816
7.04	18.86	0.340	1.817
7.05	18.96	0.340	1.817
7.06	19.06	0.340	1.818
7.07	19.16	0.340	1.818
7.08	19.26	0.340	1.818
7.09	19.36	0.340	1.819
7.10	19.46	0.340	1.819
7.11	19.56	0.340	1.819
7.12	19.66	0.340	1.820
7.13	19.76	0.340	1.820
7.14	19.86	0.340	1.820
7.15	19.96	0.341	1.820
7.16	20.06	0.341	1.821
7.17	20.16	0.341	1.821
7.18	20.26	0.341	1.822
7.19	20.36	0.341	1.822
7.20	20.46	0.341	1.822
7.21	20.56	0.341	1.822
7.22	20.66	0.341	1.823
7.23	20.76	0.341	1.823
7.24	20.86	0.341	1.823
7.25	20.96	0.341	1.824
7.26	21.06	0.341	1.824
7.27	21.16	0.341	1.824
7.28	21.26	0.341	1.825
7.29	21.36	0.342	1.825
7.30	21.46	0.342	1.826
7.31	21.56	0.342	1.828
7.32	21.66	0.342	1.826
7.33	21.76	0.342	1.826
7.34	21.87	0.342	1.828
7.35	21.97	0.342	1.828
7.36	22.07	0.342	1.828
7.37	22.17	0.342	1.829
7.38	22.27	0.342	1.829
7.39	22.37	0.342	1.829
7.40	22.47	0.342	1.829
7.41	22.57	0.342	1.829
7.42	22.67	0.343	1.829
7.43	22.77	0.343	1.831
7.44	22.87	0.343	1.831
7.45	22.97	0.343	1.831
7.46	23.07	0.343	1.832
7.47	23.17	0.343	1.833
7.48	23.27	0.343	1.834
7.49	23.37	0.343	1.834
7.50	23.47	0.343	1.834
7.51	23.57	0.343	1.834
7.52	23.67	0.343	1.836
7.53	23.77	0.343	1.836
7.54	23.87	0.343	1.836
7.55	23.97	0.344	1.836
7.56	24.07	0.344	1.836
7.57	24.17	0.344	1.837
7.58	24.27	0.344	1.838
7.59	24.37	0.344	1.838
7.60	24.47	0.344	1.838
7.61	24.57	0.344	1.839
7.62	24.67	0.344	1.840
7.63	24.77	0.344	1.840
7.64	24.87	0.344	1.840
7.65	24.97	0.344	1.841
7.66	25.07	0.344	1.841
7.67	25.17	0.344	1.842
7.68	25.27	0.345	1.841
7.69	25.37	0.345	1.841
7.70	25.47	0.345	1.842
7.71	25.57	0.345	1.843
7.72	25.67	0.345	1.842
7.73	25.77	0.345	1.843
7.74	25.87	0.345	1.844
7.75	25.97	0.345	1.844
7.76	26.07	0.345	1.844
7.77	26.17	0.345	1.844
7.78	26.27	0.345	1.844
7.79	26.37	0.345	1.844
7.80	26.47	0.345	1.845
7.81	26.57	0.345	1.846
7.82	26.67	0.346	1.846
7.83	26.77	0.346	1.846
7.84	26.87	0.346	1.847
7.85	26.97	0.346	1.848
7.86	27.07	0.346	1.848
7.87	27.17	0.346	1.849
7.88	27.27	0.346	1.849
7.89	27.37	0.346	1.850
7.90	27.47	0.346	1.850
7.91	27.57	0.346	1.850
7.92	27.67	0.346	1.851
7.93	27.77	0.346	1.851
7.94	27.87	0.346	1.851
7.95	27.97	0.346	1.851
7.96	28.07	0.346	1.852
7.97	28.17	0.347	1.852
7.98	28.27	0.347	1.853
7.99	28.37	0.347	1.853
8.00	28.47	0.347	1.854
8.01	28.57	0.347	1.854
8.02	28.67	0.347	1.855
8.03	28.77	0.347	1.855
8.04	28.87	0.347	1.856
8.05	28.97	0.347	1.856
8.06	29.07	0.347	1.856
8.07	29.17	0.347	1.857
8.08	29.27	0.347	1.857
8.09	29.37	0.347	1.857
8.10	29.47	0.348	1.858
8.11	29.57	0.348	1.858
8.12	29.67	0.348	1.858
8.13	29.77	0.348	1.859
8.14	29.87	0.348	1.859
8.15	29.97	0.348	1.859
8.16	30.07	0.348	1.859
8.17	30.17	0.348	1.859
8.18	30.27	0.348	1.859
8.19	30.38	0.348	1.860
8.20	30.47	0.348	1.860
8.21	30.58	0.348	1.860
8.22	30.68	0.348	1.860
8.23	30.78	0.348	1.861
8.24	30.88	0.348	1.860
8.25	30.98	0.348	1.861
8.26	31.08	0.348	1.862
8.27	31.18	0.348	1.862
8.28	31.28	0.349	1.862
8.29	31.38	0.349	1.864
8.30	31.48	0.349	1.864
8.31	31.58	0.349	1.865
8.32	31.68	0.349	1.865
8.33	31.78	0.349	1.866
8.34	31.88	0.349	1.867
8.35	31.98	0.349	1.866
8.36	32.08	0.349	1.867
8.37	32.18	0.349	1.868
8.38	32.28	0.349	1.868
8.39	32.38	0.349	1.869
8.40	32.48	0.349	1.868
8.41	32.58	0.349	1.869
8.42	32.68	0.350	1.870
8.43	32.78	0.350	1.869
8.44	32.88	0.350	1.869
8.45	32.98	0.350	1.870
8.46	33.08	0.350	1.871
8.47	33.18	0.350	1.871
8.48	33.28	0.350	1.872
8.49	33.38	0.350	1.871
8.50	33.48	0.350	1.872
8.51	33.58	0.350	1.873
8.52	33.68	0.350	1.873
8.53	33.78	0.350	1.872
8.54	33.88	0.350	1.872
8.55	33.98	0.350	1.873
8.56	34.08	0.350	1.874
8.57	34.18	0.350	1.873
8.58	34.28	0.350	1.873
8.59	34.38	0.351	1.874
8.60	34.48	0.351	1.873
8.61	34.58	0.351	1.875
8.62	34.68	0.351	1.875
8.63	34.78	0.351	1.876
8.64	34.88	0.351	1.876
8.65	34.98	0.351	1.876
8.66	35.08	0.351	1.877
8.67	35.18	0.351	1.877
8.68	35.28	0.351	1.877
8.69	35.38	0.351	1.878
8.70	35.48	0.351	1.878
8.71	35.58	0.352	1.879
8.72	35.68	0.352	1.879
8.73	35.78	0.352	1.879
8.74	35.88	0.352	1.881
8.75	35.98	0.352	1.881
8.76	36.08	0.352	1.880
8.77	36.18	0.352	1.881
8.78	36.28	0.352	1.881
8.79	36.38	0.352	1.881
8.80	36.48	0.352	1.882
8.81	36.58	0.352	1.882
8.82	36.68	0.352	1.882
8.83	36.78	0.352	1.882
8.84	36.88	0.352	1.882
8.85	36.98	0.352	1.883
8.86	37.08	0.352	1.882
8.87	37.18	0.352	1.882
8.88	37.28	0.353	1.883
8.89	37.38	0.353	1.883
8.90	37.48	0.353	1.883
8.91	37.58	0.353	1.884
8.92	37.68	0.353	1.884
8.93	37.78	0.353	1.885
8.94	37.88	0.353	1.885
8.95	37.98	0.353	1.885
8.96	38.08	0.353	1.886
8.97	38.18	0.353	1.886
8.98	38.28	0.353	1.886
8.99	38.39	0.353	1.886
9.00	38.49	0.353	1.886
9.01	38.58	0.353	1.887
9.02	38.69	0.353	1.887
9.03	38.78	0.354	1.887
9.04	38.89	0.354	1.888
9.05	38.99	0.354	1.889
9.06	39.09	0.354	1.889
9.07	39.19	0.354	1.889
9.08	39.29	0.354	1.890
9.09	39.39	0.354	1.891
9.10	39.49	0.354	1.890
9.11	39.59	0.354	1.891
9.12	39.69	0.354	1.892
9.13	39.79	0.354	1.891
9.14	39.89	0.354	1.891
9.15	39.99	0.354	1.892
9.16	40.09	0.354	1.892
9.17	40.19	0.354	1.892
9.18	40.29	0.355	1.891
9.19	40.39	0.355	1.892
9.20	40.49	0.355	1.892
9.21	40.59	0.355	1.893
9.22	40.69	0.355	1.893
9.23	40.79	0.355	1.894
9.24	40.89	0.355	1.893
9.25	40.99	0.355	1.893
9.26	41.09	0.355	1.893
9.27	41.19	0.355	1.892
9.28	41.29	0.355	1.893
9.29	41.39	0.355	1.894
9.30	41.49	0.355	1.894
9.31	41.59	0.355	1.893
9.32	41.69	0.355	1.894
9.33	41.79	0.355	1.895
9.34	41.89	0.355	1.895
9.35	41.99	0.355	1.895
9.36	42.09	0.355	1.895
9.37	42.19	0.356	1.895
9.38	42.29	0.356	1.896
9.39	42.39	0.356	1.896
9.40	42.49	0.356	1.897
9.41	42.59	0.356	1.897
9.42	42.69	0.356	1.897
9.43	42.79	0.356	1.898
9.44	42.89	0.356	1.898
9.45	42.99	0.356	1.898
9.46	43.09	0.356	1.899
9.47	43.19	0.356	1.899
9.48	43.29	0.356	1.899
9.49	43.39	0.356	1.899
9.50	43.49	0.356	1.899
9.51	43.59	0.356	1.899
9.52	43.69	0.356	1.900
9.53	43.79	0.356	1.899
9.54	43.89	0.357	1.901
9.55	43.99	0.357	1.900
9.56	44.09	0.357	1.900
9.57	44.19	0.357	1.901
9.58	44.29	0.357	1.901
9.59	44.39	0.357	1.900
9.60	44.49	0.357	1.901
9.61	44.59	0.357	1.901
9.62	44.69	0.357	1.901
9.63	44.79	0.357	1.901
9.64	44.89	0.357	1.902
9.65	44.99	0.357	1.902
9.66	45.09	0.357	1.901
9.67	45.19	0.357	1.903
9.68	45.29	0.358	1.903
9.69	45.39	0.358	1.903
9.70	45.49	0.358	1.904
9.71	45.59	0.358	1.904
9.72	45.69	0.358	1.904
9.73	45.79	0.358	1.905
9.74	45.89	0.358	1.904
9.75	45.99	0.358	1.905
9.76	46.09	0.358	1.906
9.77	46.19	0.358	1.906
9.78	46.29	0.358	1.906
9.79	46.39	0.358	1.906
9.80	46.49	0.358	1.905
9.81	46.59	0.359	1.907
9.82	46.69	0.359	1.908
9.83	46.79	0.359	1.908
9.84	46.89	0.359	1.908
9.85	47.00	0.359	1.908
9.86	47.09	0.359	1.909
9.87	47.20	0.359	1.909
9.88	47.30	0.359	1.910
9.89	47.40	0.359	1.910
9.90	47.50	0.359	1.911
9.91	47.60	0.359	1.911
9.92	47.70	0.359	1.911
9.93	47.80	0.359	1.911
9.94	47.90	0.360	1.913
9.95	48.00	0.360	1.914
9.96	48.10	0.360	1.914
9.97	48.20	0.360	1.915
9.98	48.30	0.360	1.915
9.99	48.40	0.360	1.916
10.00	48.50	0.360	1.916
10.01	48.60	0.360	1.917
10.02	48.70	0.360	1.917
10.03	48.80	0.360	1.917
10.04	48.90	0.360	1.918
10.05	49.00	0.360	1.919
10.06	49.10	0.360	1.918
10.07	49.20	0.360	1.919
10.08	49.30	0.361	1.918
10.09	49.40	0.361	1.919
10.10	49.50	0.361	1.920
10.11	49.60	0.361	1.920
10.12	49.70	0.361	1.921
10.13	49.80	0.361	1.922
10.14	49.90	0.361	1.922
10.15	50.00	0.361	1.923
10.16	50.10	0.361	1.923
10.17	50.20	0.361	1.923
10.18	50.30	0.361	1.923
10.19	50.40	0.361	1.924
10.20	50.50	0.361	1.924
10.21	50.60	0.361	1.925
10.22	50.70	0.362	1.925
10.23	50.80	0.362	1.926
10.24	50.90	0.362	1.926
10.25	51.00	0.362	1.926
10.26	51.10	0.362	1.927
10.27	51.20	0.362	1.927
10.28	51.30	0.362	1.928
10.29	51.40	0.362	1.929
10.30	51.50	0.362	1.928
10.31	51.60	0.362	1.929
10.32	51.70	0.362	1.929
10.33	51.80	0.362	1.929
10.34	51.90	0.362	1.929
10.35	52.00	0.362	1.929
10.36	52.10	0.362	1.929
10.37	52.20	0.362	1.929
10.38	52.30	0.362	1.930
10.39	52.40	0.363	1.930
10.40	52.50	0.363	1.931
10.41	52.60	0.363	1.931
10.42	52.70	0.363	1.931
10.43	52.80	0.363	1.931
10.44	52.90	0.363	1.932
10.45	53.00	0.363	1.933
10.46	53.10	0.363	1.933
10.47	53.20	0.363	1.933
10.48	53.30	0.363	1.934
10.49	53.40	0.363	1.934
10.50	53.50	0.363	1.935
10.51	53.60	0.363	1.935
10.52	53.70	0.364	1.936
10.53	53.80	0.364	1.936
10.54	53.90	0.364	1.936
10.55	54.00	0.364	1.937
10.56	54.10	0.364	1.938
10.57	54.20	0.364	1.938
10.58	54.30	0.364	1.939
10.59	54.41	0.364	1.939
10.60	54.50	0.364	1.940
10.61	54.61	0.364	1.940
10.62	54.71	0.364	1.941
10.63	54.80	0.364	1.940
10.64	54.91	0.364	1.940
10.65	55.01	0.364	1.942
10.66	55.11	0.364	1.941
10.67	55.20	0.364	1.942
10.68	55.30	0.364	1.943
10.69	55.41	0.364	1.944
10.70	55.50	0.365	1.943
10.71	55.60	0.365	1.944
10.72	55.70	0.365	1.944
10.73	55.81	0.365	1.944
10.74	55.91	0.365	1.944
10.75	56.01	0.365	1.945
10.76	56.11	0.365	1.946
10.77	56.21	0.365	1.945
10.78	56.31	0.365	1.946
10.79	56.41	0.365	1.946
10.80	56.51	0.365	1.946
10.81	56.61	0.365	1.946
10.82	56.71	0.365	1.946
10.83	56.81	0.365	1.948
10.84	56.91	0.365	1.947
10.85	57.01	0.365	1.947
10.86	57.11	0.365	1.948
10.87	57.21	0.366	1.949
10.88	57.31	0.366	1.949
10.89	57.41	0.366	1.949
10.90	57.51	0.366	1.950
10.91	57.61	0.366	1.950
10.92	57.71	0.366	1.950
10.93	57.81	0.366	1.952
10.94	57.91	0.366	1.952
10.95	58.01	0.366	1.952
10.96	58.11	0.366	1.952
10.97	58.21	0.366	1.952
10.98	58.31	0.366	1.953
10.99	58.41	0.366	1.954
11.00	58.51	0.366	1.954
11.01	58.61	0.366	1.955
11.02	58.71	0.366	1.955
11.03	58.81	0.367	1.955
11.04	58.91	0.367	1.955
11.05	59.01	0.367	1.956
11.06	59.11	0.367	1.956
11.07	59.21	0.367	1.956
11.08	59.31	0.367	1.956
11.09	59.41	0.367	1.956
11.10	59.51	0.367	1.956
11.11	59.61	0.367	1.956
11.12	59.71	0.367	1.957
11.13	59.81	0.367	1.957
11.14	59.91	0.367	1.957
11.15	60.01	0.367	1.958
11.16	60.11	0.367	1.958
11.17	60.21	0.367	1.958
11.18	60.31	0.368	1.960
11.19	60.41	0.367	1.959
11.20	60.51	0.367	1.959
11.21	60.61	0.368	1.960
11.22	60.71	0.368	1.961
11.23	60.81	0.368	1.962
11.24	60.91	0.368	1.962
11.25	61.01	0.368	1.962
11.26	61.11	0.368	1.962
11.27	61.21	0.368	1.963
11.28	61.31	0.368	1.963
11.29	61.41	0.368	1.964
11.30	61.51	0.368	1.965
11.31	61.61	0.368	1.965
11.32	61.71	0.368	1.966
11.33	61.81	0.368	1.967
11.34	61.91	0.368	1.966
11.35	62.01	0.368	1.966
11.36	62.11	0.368	1.966
11.37	62.21	0.368	1.966
11.38	62.31	0.368	1.965
11.39	62.41	0.368	1.966
11.40	62.51	0.368	1.967
11.41	62.61	0.369	1.967
11.42	62.71	0.369	1.967
11.43	62.81	0.369	1.967
11.44	62.91	0.369	1.968
11.45	63.01	0.369	1.967
11.46	63.11	0.369	1.968
11.47	63.21	0.369	1.967
11.48	63.31	0.369	1.968
11.49	63.41	0.369	1.968
11.50	63.51	0.369	1.968
11.51	63.61	0.369	1.969
11.52	63.71	0.369	1.969
11.53	63.81	0.369	1.968
11.54	63.91	0.369	1.968
11.55	64.01	0.369	1.969
11.56	64.11	0.370	1.969
11.57	64.22	0.370	1.970
11.58	64.31	0.370	1.971
11.59	64.41	0.370	1.971
11.60	64.52	0.370	1.971
11.61	64.62	0.370	1.972
11.62	64.72	0.370	1.972
11.63	64.82	0.370	1.972
11.64	64.92	0.370	1.973
11.65	65.02	0.370	1.974
11.66	65.12	0.370	1.974
11.67	65.22	0.370	1.975
11.68	65.32	0.370	1.974
11.69	65.42	0.370	1.975
11.70	65.52	0.370	1.976
11.71	65.62	0.371	1.976
11.72	65.72	0.371	1.977
11.73	65.82	0.371	1.977
11.74	65.92	0.371	1.977
11.75	66.02	0.371	1.978
11.76	66.12	0.371	1.979
11.77	66.22	0.371	1.979
11.78	66.32	0.371	1.979
11.79	66.42	0.371	1.979
11.80	66.52	0.371	1.979
11.81	66.62	0.371	1.980
11.82	66.72	0.371	1.980
11.83	66.82	0.371	1.981
11.84	66.92	0.371	1.981
11.85	67.02	0.372	1.982
11.86	67.12	0.372	1.983
11.87	67.22	0.372	1.982
11.88	67.32	0.372	1.982
11.89	67.42	0.372	1.983
11.90	67.52	0.372	1.983
11.91	67.62	0.372	1.983
11.92	67.72	0.372	1.984
11.93	67.82	0.372	1.983
11.94	67.92	0.372	1.984
11.95	68.02	0.372	1.985
11.96	68.12	0.372	1.985
11.97	68.22	0.372	1.985
11.98	68.32	0.372	1.986
11.99	68.42	0.372	1.986
12.00	68.52	0.372	1.985
12.01	68.62	0.372	1.986
12.02	68.72	0.373	1.987
[...]
635.61	4.42	0.470	2.519
635.62	4.54	0.468	2.504
635.64	4.66	0.465	2.484
635.65	4.77	0.458	2.443
635.66	4.89	0.446	2.373
635.67	5.01	0.438	2.326
635.68	5.13	0.425	2.257
635.69	5.24	0.417	2.212
635.71	5.36	0.406	2.155
635.72	5.48	0.398	2.111
635.73	5.60	0.390	2.066
635.74	5.72	0.384	2.034
635.75	5.84	0.378	2.000
635.76	5.95	0.372	1.971
635.78	6.07	0.370	1.956
635.79	6.19	0.362	1.917
635.80	6.31	0.362	1.916
635.81	6.43	0.358	1.897
635.82	6.55	0.356	1.887
635.83	6.66	0.353	1.875
635.84	6.78	0.352	1.867
635.86	6.90	0.350	1.861
635.87	7.02	0.350	1.858
635.88	7.13	0.349	1.857
635.89	7.25	0.347	1.847
635.90	7.37	0.347	1.845
635.91	7.49	0.346	1.842
635.93	7.60	0.345	1.840
635.94	7.72	0.345	1.837
635.95	7.84	0.344	1.835
635.96	7.95	0.344	1.834
635.97	8.07	0.344	1.831
635.99	8.19	0.343	1.830
636.00	8.31	0.343	1.828
636.01	8.42	0.342	1.827
636.02	8.54	0.342	1.825
636.03	8.66	0.342	1.824
636.04	8.77	0.342	1.823
636.06	8.89	0.341	1.821
636.07	9.01	0.341	1.821
636.08	9.12	0.341	1.820
636.09	9.24	0.340	1.818
636.10	9.36	0.340	1.816
636.11	9.48	0.340	1.816
636.13	9.59	0.340	1.814
636.14	9.71	0.339	1.813
636.15	9.83	0.339	1.811
636.16	9.94	0.339	1.810
636.17	10.06	0.339	1.810
636.18	10.18	0.338	1.808
636.19	10.29	0.338	1.808
636.21	10.41	0.338	1.807
636.22	10.53	0.338	1.807
636.23	10.64	0.338	1.805
636.24	10.76	0.337	1.805
636.25	10.88	0.337	1.804
636.26	11.00	0.337	1.803
636.28	11.11	0.337	1.801
636.29	11.23	0.337	1.800
636.30	11.34	0.337	1.801
636.31	11.46	0.337	1.800
636.32	11.58	0.337	1.799
636.34	11.70	0.336	1.798
636.35	11.81	0.336	1.798
636.36	11.93	0.336	1.798
636.37	12.05	0.336	1.795
636.38	12.16	0.336	1.794
636.39	12.28	0.336	1.794
636.41	12.40	0.336	1.794
636.42	12.51	0.336	1.793
636.43	12.63	0.336	1.793
636.44	12.75	0.336	1.793
636.45	12.86	0.335	1.792
636.46	12.98	0.335	1.792
636.48	13.10	0.335	1.792
636.49	13.21	0.335	1.792
636.50	13.33	0.335	1.791
636.51	13.45	0.335	1.792
636.52	13.56	0.335	1.791
636.53	13.68	0.335	1.791
636.54	13.80	0.335	1.792
636.56	13.92	0.335	1.792
636.57	14.03	0.335	1.791
636.58	14.15	0.335	1.792
636.59	14.27	0.335	1.793
636.60	14.38	0.335	1.793
636.61	14.50	0.335	1.793
636.63	14.62	0.336	1.793
636.64	14.73	0.336	1.793
636.65	14.85	0.336	1.795
636.66	14.97	0.336	1.795
636.67	15.08	0.336	1.795
636.69	15.20	0.336	1.795
636.70	15.32	0.336	1.795
636.71	15.43	0.336	1.795
636.72	15.55	0.336	1.796
636.73	15.67	0.336	1.796
636.74	15.78	0.336	1.796
636.76	15.90	0.336	1.796
636.77	16.02	0.336	1.798
636.78	16.13	0.336	1.798
636.79	16.25	0.337	1.799
636.80	16.37	0.337	1.799
636.81	16.48	0.337	1.800
636.83	16.60	0.337	1.800
636.84	16.72	0.337	1.801
636.85	16.84	0.337	1.801
636.86	16.95	0.337	1.801
636.87	17.07	0.337	1.801
636.88	17.19	0.337	1.801
636.89	17.30	0.337	1.802
636.91	17.42	0.337	1.802
636.92	17.54	0.337	1.803
636.93	17.65	0.337	1.803
636.94	17.77	0.337	1.804
636.95	17.89	0.338	1.804
636.96	18.01	0.338	1.805
636.98	18.12	0.338	1.805
636.99	18.24	0.338	1.806
637.00	18.35	0.338	1.806
637.01	18.47	0.338	1.806
637.02	18.59	0.338	1.807
637.04	18.70	0.338	1.807
637.05	18.82	0.338	1.807
637.06	18.94	0.338	1.807
637.07	19.06	0.338	1.809
637.08	19.17	0.339	1.809
637.09	19.29	0.339	1.810
637.11	19.41	0.339	1.810
637.12	19.52	0.339	1.811
637.13	19.64	0.339	1.812
637.14	19.76	0.339	1.810
637.15	19.87	0.339	1.811
637.16	19.99	0.339	1.812
637.18	20.11	0.339	1.812
637.19	20.22	0.339	1.812
637.20	20.34	0.339	1.813
637.21	20.46	0.339	1.814
637.22	20.57	0.339	1.815
637.23	20.69	0.339	1.814
637.24	20.81	0.339	1.814
637.26	20.92	0.339	1.816
637.27	21.04	0.340	1.815
637.28	21.16	0.340	1.815
637.29	21.27	0.340	1.816
637.30	21.39	0.340	1.817
637.31	21.51	0.340	1.817
637.33	21.63	0.340	1.817
637.34	21.74	0.340	1.818
637.35	21.86	0.340	1.818
637.36	21.97	0.340	1.819
637.37	22.09	0.340	1.819
637.39	22.21	0.340	1.819
637.40	22.33	0.341	1.820
637.41	22.44	0.341	1.821
637.42	22.56	0.341	1.820
637.43	22.68	0.341	1.821
637.44	22.79	0.341	1.822
637.46	22.91	0.341	1.822
637.47	23.03	0.341	1.821
637.48	23.14	0.341	1.822
637.49	23.26	0.341	1.822
637.50	23.38	0.341	1.823
637.51	23.49	0.341	1.823
637.53	23.61	0.341	1.824
637.54	23.73	0.341	1.825
637.55	23.85	0.342	1.825
637.56	23.96	0.342	1.825
637.57	24.08	0.342	1.826
637.58	24.20	0.342	1.826
637.59	24.31	0.342	1.827
637.61	24.43	0.342	1.827
637.62	24.55	0.342	1.827
637.63	24.66	0.342	1.828
637.64	24.78	0.342	1.828
637.65	24.90	0.342	1.828
637.66	25.01	0.342	1.829
637.68	25.13	0.342	1.829
637.69	25.25	0.342	1.830
637.70	25.36	0.343	1.830
637.71	25.48	0.343	1.830
637.72	25.60	0.343	1.831
637.74	25.71	0.343	1.832
637.75	25.83	0.343	1.832
637.76	25.95	0.343	1.832
637.77	26.06	0.343	1.832
637.78	26.18	0.343	1.833
637.79	26.30	0.343	1.833
637.81	26.41	0.343	1.834
637.82	26.53	0.343	1.834
637.83	26.65	0.343	1.835
637.84	26.76	0.344	1.836
637.85	26.88	0.344	1.836
637.86	27.00	0.344	1.836
637.88	27.12	0.344	1.837
637.89	27.23	0.344	1.837
637.90	27.35	0.344	1.837
637.91	27.47	0.344	1.837
637.92	27.58	0.344	1.839
637.93	27.70	0.344	1.838
637.94	27.82	0.344	1.839
637.96	27.93	0.344	1.839
637.97	28.05	0.344	1.840
637.98	28.17	0.344	1.840
637.99	28.28	0.344	1.841
638.00	28.40	0.345	1.841
638.01	28.52	0.345	1.843
638.03	28.64	0.345	1.843
638.04	28.75	0.345	1.842
638.05	28.87	0.345	1.843
638.06	28.98	0.345	1.844
638.07	29.10	0.345	1.844
638.09	29.22	0.345	1.845
638.10	29.33	0.345	1.846
638.11	29.45	0.345	1.846
638.12	29.57	0.345	1.846
638.13	29.68	0.345	1.847
638.14	29.80	0.345	1.847
638.16	29.92	0.345	1.847
638.17	30.04	0.345	1.847
638.18	30.15	0.345	1.847
638.19	30.27	0.346	1.847
638.20	30.39	0.346	1.848
638.21	30.50	0.346	1.848
638.23	30.62	0.346	1.849
638.24	30.74	0.346	1.849
638.25	30.85	0.346	1.849
638.26	30.97	0.346	1.849
638.27	31.09	0.346	1.849
638.28	31.20	0.346	1.850
638.29	31.32	0.346	1.851
638.31	31.44	0.346	1.852
638.32	31.55	0.346	1.852
638.33	31.67	0.346	1.852
638.34	31.79	0.347	1.853
638.35	31.91	0.347	1.853
638.36	32.02	0.347	1.853
638.38	32.14	0.347	1.854
638.39	32.26	0.347	1.854
638.40	32.37	0.347	1.855
638.41	32.49	0.347	1.856
638.42	32.61	0.347	1.856
638.44	32.72	0.347	1.857
638.45	32.84	0.347	1.857
638.46	32.96	0.347	1.858
638.47	33.07	0.347	1.858
638.48	33.19	0.348	1.859
638.49	33.31	0.348	1.859
638.51	33.42	0.348	1.859
638.52	33.54	0.348	1.859
638.53	33.66	0.348	1.860
638.54	33.77	0.348	1.860
638.55	33.89	0.348	1.860
638.56	34.01	0.348	1.861
638.58	34.12	0.348	1.861
638.59	34.24	0.348	1.861
638.60	34.36	0.348	1.861
638.61	34.47	0.348	1.861
638.62	34.59	0.349	1.864
638.63	34.71	0.349	1.864
638.64	34.83	0.349	1.864
638.66	34.94	0.349	1.864
638.67	35.06	0.349	1.864
638.68	35.18	0.349	1.864
638.69	35.29	0.349	1.865
638.70	35.41	0.349	1.864
638.71	35.53	0.349	1.865
638.73	35.64	0.349	1.865
638.74	35.76	0.349	1.866
638.75	35.88	0.349	1.866
638.76	35.99	0.349	1.866
638.77	36.11	0.349	1.867
638.79	36.23	0.350	1.868
638.80	36.34	0.349	1.868
638.81	36.46	0.350	1.868
638.82	36.58	0.350	1.867
638.83	36.69	0.350	1.867
638.84	36.81	0.350	1.869
638.86	36.93	0.350	1.870
638.87	37.04	0.350	1.870
638.88	37.16	0.350	1.870
638.89	37.28	0.350	1.870
638.90	37.39	0.350	1.872
638.91	37.51	0.350	1.870
638.93	37.63	0.350	1.871
638.94	37.75	0.350	1.871
638.95	37.86	0.350	1.872
638.96	37.98	0.350	1.871
638.97	38.10	0.351	1.871
638.98	38.21	0.351	1.872
638.99	38.33	0.351	1.872
639.01	38.45	0.351	1.874
639.02	38.56	0.351	1.873
639.03	38.68	0.351	1.874
639.04	38.80	0.351	1.873
639.05	38.91	0.351	1.873
639.06	39.03	0.351	1.874
639.08	39.15	0.351	1.874
639.09	39.26	0.351	1.875
639.10	39.38	0.351	1.876
639.11	39.50	0.351	1.875
639.12	39.61	0.351	1.876
639.14	39.73	0.351	1.876
639.15	39.85	0.352	1.877
639.16	39.96	0.352	1.878
639.17	40.08	0.352	1.878
639.18	40.20	0.352	1.879
639.19	40.32	0.352	1.879
639.21	40.43	0.352	1.878
639.22	40.55	0.352	1.880
639.23	40.67	0.352	1.879
639.24	40.78	0.352	1.879
639.25	40.90	0.352	1.880
639.26	41.02	0.352	1.879
639.28	41.13	0.352	1.881
639.29	41.25	0.352	1.881
639.30	41.37	0.353	1.881
639.31	41.48	0.353	1.881
639.32	41.60	0.353	1.881
639.33	41.72	0.353	1.881
639.34	41.83	0.353	1.882
639.36	41.95	0.353	1.881
639.37	42.07	0.353	1.882
639.38	42.18	0.353	1.882
639.39	42.30	0.353	1.882
639.40	42.42	0.353	1.883
639.41	42.53	0.353	1.882
639.43	42.65	0.353	1.883
639.44	42.77	0.353	1.884
639.45	42.88	0.353	1.885
639.46	43.00	0.354	1.884
639.47	43.12	0.354	1.885
639.49	43.24	0.354	1.884
639.50	43.35	0.354	1.885
639.51	43.47	0.354	1.885
639.52	43.59	0.354	1.886
639.53	43.70	0.354	1.886
639.54	43.82	0.354	1.886
639.56	43.94	0.354	1.886
639.57	44.05	0.354	1.887
639.58	44.17	0.354	1.887
639.59	44.29	0.354	1.887
639.60	44.40	0.354	1.888
639.61	44.52	0.354	1.887
639.63	44.64	0.354	1.887
639.64	44.75	0.355	1.887
639.65	44.87	0.355	1.887
639.66	44.99	0.355	1.888
639.67	45.10	0.355	1.888
639.68	45.22	0.355	1.889
639.69	45.34	0.355	1.890
639.71	45.45	0.355	1.891
639.72	45.57	0.355	1.891
639.73	45.69	0.355	1.892
639.74	45.81	0.355	1.893
639.75	45.92	0.355	1.893
639.76	46.04	0.356	1.893
639.78	46.16	0.356	1.894
639.79	46.27	0.356	1.894
639.80	46.39	0.356	1.895
639.81	46.51	0.356	1.895
639.82	46.62	0.356	1.896
639.84	46.74	0.356	1.896
639.85	46.86	0.356	1.896
639.86	46.97	0.356	1.896
639.87	47.09	0.356	1.897
639.88	47.21	0.356	1.897
639.89	47.32	0.356	1.897
639.91	47.44	0.356	1.898
639.92	47.56	0.357	1.898
639.93	47.67	0.357	1.898
639.94	47.79	0.357	1.899
639.95	47.91	0.357	1.898
639.96	48.02	0.357	1.899
639.98	48.14	0.357	1.899
639.99	48.26	0.357	1.900
640.00	48.37	0.357	1.901
640.01	48.49	0.357	1.901
640.02	48.61	0.357	1.901
640.03	48.72	0.357	1.901
640.04	48.84	0.357	1.902
640.06	48.96	0.358	1.903
640.07	49.08	0.358	1.903
640.08	49.19	0.358	1.903
640.09	49.31	0.358	1.903
640.10	49.43	0.358	1.903
640.11	49.54	0.358	1.904
640.13	49.66	0.358	1.905
640.14	49.78	0.358	1.905
640.15	49.89	0.358	1.905
640.16	50.01	0.358	1.906
640.17	50.13	0.358	1.907
640.19	50.24	0.358	1.907
640.20	50.36	0.358	1.907
640.21	50.48	0.359	1.908
640.22	50.59	0.359	1.909
640.23	50.71	0.359	1.909
640.24	50.83	0.359	1.909
640.26	50.94	0.359	1.910
640.27	51.06	0.359	1.910
640.28	51.18	0.359	1.910
640.29	51.29	0.359	1.911
640.30	51.41	0.359	1.912
640.31	51.53	0.359	1.911
640.33	51.64	0.359	1.913
640.34	51.76	0.360	1.914
640.35	51.88	0.359	1.914
640.36	52.00	0.360	1.914
640.37	52.11	0.360	1.915
640.38	52.23	0.360	1.916
640.39	52.35	0.360	1.915
640.41	52.46	0.360	1.918
640.42	52.58	0.360	1.918
640.43	52.70	0.360	1.919
640.44	52.81	0.360	1.917
640.45	52.93	0.360	1.918
640.46	53.05	0.360	1.919
640.48	53.16	0.360	1.919
640.49	53.28	0.360	1.920
640.50	53.40	0.360	1.920
640.51	53.51	0.361	1.920
640.52	53.63	0.361	1.922
640.54	53.75	0.361	1.922
640.55	53.87	0.361	1.922
640.56	53.98	0.361	1.923
640.57	54.10	0.361	1.924
640.58	54.22	0.361	1.924
640.59	54.33	0.361	1.924
640.61	54.45	0.361	1.925
640.62	54.57	0.361	1.924
640.63	54.68	0.361	1.925
640.64	54.80	0.361	1.926
640.65	54.92	0.361	1.926
640.66	55.03	0.361	1.926
640.68	55.15	0.361	1.927
640.69	55.27	0.361	1.927
640.70	55.38	0.362	1.928
640.71	55.50	0.362	1.928
640.72	55.62	0.362	1.928
640.73	55.73	0.362	1.928
640.74	55.85	0.362	1.928
640.76	55.97	0.362	1.927
640.77	56.08	0.362	1.929
640.78	56.20	0.362	1.929
640.79	56.32	0.362	1.929
640.80	56.43	0.362	1.930
640.81	56.55	0.362	1.930
640.83	56.67	0.362	1.929
640.84	56.78	0.362	1.930
640.85	56.90	0.362	1.931
640.86	57.02	0.362	1.932
640.87	57.13	0.363	1.931
640.89	57.25	0.363	1.933
640.90	57.37	0.363	1.933
640.91	57.49	0.363	1.934
640.92	57.60	0.363	1.933
640.93	57.72	0.363	1.933
640.94	57.84	0.363	1.935
640.96	57.95	0.363	1.937
640.97	58.07	0.363	1.936
640.98	58.19	0.363	1.936
640.99	58.30	0.363	1.937
641.00	58.42	0.363	1.937
641.01	58.54	0.364	1.938
641.03	58.65	0.364	1.940
641.04	58.77	0.364	1.941
641.05	58.89	0.364	1.940
641.06	59.00	0.364	1.940
641.07	59.12	0.364	1.942
641.08	59.24	0.364	1.942
641.09	59.36	0.364	1.941
641.11	59.47	0.364	1.941
641.12	59.59	0.364	1.942
641.13	59.71	0.364	1.942
641.14	59.82	0.364	1.942
641.15	59.94	0.364	1.942
641.16	60.06	0.364	1.943
641.18	60.17	0.364	1.944
641.19	60.29	0.364	1.944
641.20	60.41	0.365	1.944
641.21	60.52	0.365	1.944
641.22	60.64	0.365	1.945
641.24	60.76	0.365	1.945
641.25	60.87	0.365	1.946
641.26	60.99	0.365	1.947
641.27	61.11	0.365	1.946
641.28	61.22	0.365	1.947
641.29	61.34	0.365	1.946
641.31	61.46	0.365	1.947
641.32	61.57	0.365	1.948
641.33	61.69	0.365	1.949
641.34	61.81	0.365	1.949
641.35	61.92	0.365	1.949
641.36	62.04	0.365	1.949
641.38	62.16	0.365	1.950
641.39	62.27	0.365	1.949
641.40	62.39	0.366	1.950
641.41	62.51	0.366	1.951
641.42	62.62	0.366	1.951
641.43	62.74	0.366	1.951
641.44	62.86	0.366	1.951
641.46	62.98	0.366	1.951
641.47	63.09	0.366	1.951
641.48	63.21	0.366	1.951
641.49	63.33	0.366	1.952
641.50	63.44	0.366	1.952
641.51	63.56	0.366	1.952
641.53	63.68	0.366	1.952
641.54	63.79	0.366	1.952
641.55	63.91	0.366	1.953
641.56	64.03	0.366	1.953
641.57	64.14	0.366	1.953
641.59	64.26	0.367	1.954
641.60	64.38	0.367	1.955
641.61	64.49	0.367	1.955
641.62	64.61	0.367	1.956
641.63	64.73	0.367	1.956
641.64	64.84	0.367	1.957
641.66	64.96	0.367	1.957
641.67	65.08	0.367	1.958
641.68	65.19	0.367	1.959
641.69	65.31	0.367	1.959
641.70	65.43	0.367	1.959
641.71	65.55	0.367	1.959
641.73	65.66	0.367	1.959
641.74	65.78	0.368	1.960
641.75	65.90	0.368	1.960
641.76	66.01	0.368	1.960
641.77	66.13	0.368	1.961
641.78	66.25	0.368	1.961
641.79	66.36	0.368	1.961
641.81	66.48	0.368	1.961
641.82	66.60	0.368	1.962
641.83	66.71	0.368	1.961
641.84	66.83	0.368	1.962
641.85	66.95	0.368	1.963
641.86	67.06	0.368	1.963
641.88	67.18	0.368	1.963
641.89	67.30	0.368	1.964
641.90	67.42	0.369	1.964
641.91	67.53	0.369	1.964
641.92	67.65	0.369	1.965
641.94	67.76	0.369	1.965
641.95	67.88	0.369	1.966
641.96	68.00	0.369	1.966
641.97	68.11	0.369	1.967
641.98	68.23	0.369	1.968
641.99	68.35	0.369	1.968
642.01	68.47	0.369	1.968
642.02	68.58	0.369	1.968
642.03	68.70	0.369	1.969
642.04	68.82	0.369	1.969
642.05	68.93	0.369	1.969
642.06	69.05	0.369	1.970
642.08	69.17	0.369	1.969
642.09	69.28	0.369	1.970
642.10	69.40	0.370	1.971
642.11	69.52	0.370	1.971
642.12	69.63	0.370	1.971
642.13	69.75	0.370	1.972
642.14	69.87	0.370	1.971
642.16	69.98	0.370	1.972
642.17	70.10	0.370	1.973
642.18	70.22	0.370	1.972
642.19	70.33	0.370	1.972
642.20	70.45	0.370	1.973
642.21	70.57	0.370	1.974
642.23	70.68	0.370	1.974
642.24	70.80	0.370	1.974
642.25	70.92	0.371	1.975
642.26	71.03	0.371	1.974
642.27	71.15	0.371	1.976
642.29	71.27	0.371	1.976
642.30	71.38	0.371	1.976
642.31	71.50	0.371	1.977
642.32	71.62	0.371	1.977
642.33	71.73	0.371	1.978
642.34	71.85	0.371	1.977
642.36	71.97	0.371	1.979
642.37	72.09	0.371	1.978
642.38	72.20	0.371	1.978
642.39	72.32	0.371	1.979
642.40	72.44	0.371	1.979
642.41	72.55	0.371	1.979
642.43	72.67	0.372	1.980
642.44	72.79	0.372	1.980
642.45	72.90	0.372	1.981
642.46	73.02	0.372	1.981
642.47	73.14	0.372	1.981
642.48	73.25	0.372	1.982
642.49	73.37	0.372	1.982
642.51	73.49	0.372	1.982
642.52	73.60	0.372	1.983
642.53	73.72	0.372	1.983
642.54	73.84	0.372	1.985
642.55	73.95	0.372	1.984
642.56	74.07	0.373	1.985
642.58	74.19	0.373	1.985
642.59	74.30	0.373	1.986
642.60	74.42	0.373	1.987
642.61	74.54	0.373	1.987
642.62	74.66	0.373	1.987
642.64	74.77	0.373	1.988
642.65	74.89	0.373	1.988
642.66	75.01	0.373	1.988
642.67	75.12	0.373	1.989
642.68	75.24	0.373	1.988
642.69	75.36	0.373	1.989
642.71	75.47	0.373	1.989
642.72	75.59	0.373	1.990
642.73	75.71	0.374	1.991
642.74	75.82	0.374	1.991
642.75	75.94	0.374	1.990
642.76	76.06	0.374	1.992
642.78	76.17	0.374	1.993
642.79	76.29	0.374	1.993
642.80	76.41	0.374	1.993
642.81	76.52	0.374	1.994
642.82	76.64	0.374	1.994
642.83	76.76	0.374	1.995
642.84	76.88	0.374	1.995
642.86	76.99	0.374	1.995
642.87	77.11	0.374	1.996
642.88	77.22	0.374	1.997
642.89	77.34	0.374	1.997
642.90	77.46	0.375	1.998
642.91	77.58	0.375	1.997
642.93	77.69	0.375	1.998
642.94	77.81	0.375	1.997
642.95	77.92	0.375	1.998
642.96	78.04	0.375	1.998
642.97	78.16	0.375	1.999
642.99	78.27	0.375	1.999
643.00	78.39	0.375	2.000
643.01	78.51	0.375	1.999
643.02	78.63	0.375	2.000
643.03	78.74	0.375	2.000
643.04	78.86	0.375	2.000
643.06	78.98	0.375	2.000
643.07	79.09	0.375	2.001
643.08	79.21	0.375	2.000
643.09	79.33	0.375	2.001
643.10	79.44	0.375	2.001
643.11	79.56	0.376	2.002
643.13	79.68	0.376	2.003
643.14	79.79	0.376	2.003
643.15	79.91	0.376	2.003
643.16	80.03	0.376	2.003
643.17	80.14	0.376	2.002
643.18	80.26	0.376	2.003
643.19	80.38	0.376	2.003
643.21	80.50	0.376	2.004
643.22	80.61	0.376	2.004
643.23	80.73	0.376	2.005
643.24	80.84	0.376	2.005
643.25	80.96	0.376	2.006
643.26	81.08	0.376	2.006
643.28	81.20	0.376	2.006
643.29	81.31	0.376	2.006
643.30	81.43	0.376	2.006
643.31	81.55	0.376	2.006
643.32	81.66	0.376	2.007
643.34	81.78	0.376	2.007
643.35	81.90	0.376	2.007
643.36	82.01	0.376	2.008
643.37	82.13	0.376	2.007
643.38	82.25	0.377	2.007
643.39	82.36	0.377	2.008
643.41	82.48	0.377	2.008
643.42	82.60	0.377	2.008
643.43	82.71	0.377	2.009
643.44	82.83	0.377	2.009
643.45	82.95	0.377	2.009
643.46	83.06	0.377	2.010
643.48	83.18	0.377	2.009
643.49	83.30	0.377	2.010
643.50	83.41	0.377	2.009
643.51	83.53	0.377	2.011
643.52	83.65	0.377	2.009
643.53	83.77	0.377	2.009
643.54	83.88	0.377	2.009
643.56	84.00	0.377	2.010
643.57	84.11	0.377	2.010
643.58	84.23	0.377	2.010
643.59	84.35	0.377	2.010
643.60	84.47	0.377	2.010
643.61	84.58	0.377	2.010
643.63	84.70	0.377	2.010
643.64	84.82	0.377	2.010
643.65	84.93	0.377	2.011
643.66	85.05	0.377	2.011
643.67	85.17	0.377	2.011
643.69	85.28	0.377	2.011
643.70	85.40	0.377	2.011
643.71	85.52	0.377	2.012
643.72	85.63	0.378	2.012
643.73	85.75	0.377	2.013
643.74	85.87	0.378	2.013
643.76	85.99	0.378	2.013
643.77	86.10	0.378	2.014
643.78	86.22	0.378	2.014
643.79	86.34	0.378	2.014
643.80	86.45	0.378	2.015
643.81	86.57	0.378	2.015
643.83	86.69	0.378	2.015
643.84	86.80	0.378	2.016
643.85	86.92	0.378	2.015
643.86	87.04	0.378	2.016
643.87	87.15	0.378	2.016
643.88	87.27	0.378	2.016
643.89	87.39	0.378	2.018
643.91	87.50	0.378	2.017
643.92	87.62	0.378	2.018
643.93	87.74	0.378	2.018
643.94	87.85	0.378	2.018
643.95	87.97	0.378	2.018
643.96	88.09	0.378	2.018
643.98	88.20	0.378	2.018
643.99	88.32	0.378	2.019
644.00	88.44	0.379	2.019
644.01	88.55	0.379	2.019
644.02	88.67	0.379	2.020
644.04	88.79	0.379	2.020
644.05	88.90	0.379	2.019
644.06	89.02	0.379	2.021
644.07	89.14	0.379	2.021
644.08	89.26	0.379	2.023
644.09	89.37	0.379	2.022
644.11	89.49	0.379	2.023
644.12	89.61	0.379	2.023
644.13	89.72	0.379	2.023
644.14	89.84	0.379	2.024
644.15	89.96	0.379	2.025
644.16	90.07	0.380	2.025
644.18	90.19	0.380	2.025
644.19	90.30	0.380	2.026
644.20	90.42	0.380	2.026
644.21	90.54	0.380	2.026
644.22	90.66	0.380	2.027
644.23	90.77	0.380	2.027
644.24	90.89	0.380	2.028
644.26	91.01	0.380	2.027
644.27	91.12	0.380	2.027
644.28	91.24	0.380	2.027
644.29	91.36	0.380	2.028
644.30	91.47	0.381	2.028
644.31	91.59	0.381	2.028
644.33	91.71	0.381	2.029
644.34	91.82	0.381	2.030
644.35	91.94	0.381	2.030
644.36	92.06	0.381	2.031
644.37	92.17	0.381	2.032
644.39	92.29	0.381	2.032
644.40	92.41	0.381	2.033
644.41	92.52	0.381	2.033
644.42	92.64	0.381	2.034
644.43	92.76	0.381	2.034
644.44	92.87	0.382	2.034
644.46	92.99	0.382	2.035
644.47	93.11	0.382	2.036
644.48	93.23	0.382	2.036
644.49	93.34	0.382	2.037
644.50	93.46	0.382	2.036
644.51	93.57	0.382	2.037
644.53	93.69	0.382	2.038
644.54	93.81	0.382	2.038
644.55	93.93	0.382	2.038
644.56	94.04	0.382	2.038
644.57	94.16	0.382	2.039
644.58	94.28	0.383	2.039
644.59	94.39	0.383	2.040
644.61	94.51	0.383	2.040
644.62	94.63	0.383	2.040
644.63	94.74	0.383	2.040
644.64	94.86	0.383	2.041
644.65	94.98	0.383	2.042
644.66	95.09	0.383	2.042
644.68	95.21	0.383	2.042
644.69	95.33	0.383	2.043
644.70	95.44	0.383	2.044
644.71	95.56	0.383	2.043
644.72	95.68	0.383	2.042
644.74	95.79	0.383	2.042
644.75	95.91	0.383	2.043
644.76	96.03	0.384	2.044
644.77	96.14	0.384	2.044
644.78	96.26	0.384	2.043
644.79	96.38	0.384	2.044
644.81	96.49	0.384	2.044
644.82	96.61	0.384	2.044
644.83	96.73	0.384	2.045
644.84	96.85	0.384	2.045
644.85	96.96	0.384	2.046
644.86	97.08	0.384	2.046
644.88	97.20	0.384	2.047
644.89	97.31	0.385
644.90	97.43	0.385
644.91	97.55	0.385
644.92	97.66	0.385
644.93	97.78	0.385
644.94	97.89
644.96	98.01
644.97	98.13
644.98	98.25
644.99	98.36
645.00