File: DSC/2023_06_14_Indium_wire_std.txt
Filename	2023_06_14_Indium_wire_std
Instrument name	DSC2A-00468 (192.168.1.100)
Operator	SBK
rundate	6/14/2023
Sample name	2023_06_14_Indium_wire_std
proceduresegments	Data Off ; Equilibrate 120.00 °C; Data On ; Ramp 10.00 °C/min to 180.00 °C; Data Off ; Isothermal 0.1 min; Data On ; Ramp 10.00 °C/min to 120.00 °C
[File Parameters]
Run date	6/14/2023 2:24:41 PM
Trios version	5.1.1.46572
Original File Name	C:\Users\yargerlab\Desktop\DSC Data\General\2023_06_14_Indium_wire_std.tri
Current File Name	C:\Users\yargerlab\Desktop\DSC Data\General\2023_06_14_Indium_wire_std.tri
[Procedure]
Procedure Name	Indium Test
Sample Name	2023_06_14_Indium_wire_std
Sample Mass	20.72 mg
Reference Sample Mass	0 mg
Pan Mass	53.8 mg
Pan Number	52
Reference Pan Mass	53.66 mg
Reference Pan Number	46
Pan Type	Aluminum Hermetic
Comments	New indium wire standard using DSC84010 aluminum pan and DSC84011 hermetic aluminum lid.
Project Name	SIlk ASDs
Operator	SBK
Test	Custom
Unload Max Temperature	30
Unload Min Temperature	30
Load Max Temperature	30
Load Min Temperature	30
Stop on Gas Flow Error	Yes
[Signal List]
Signal #1	Time (min)
Signal #2	Temperature (°C)
Signal #3	Heat Flow (mW)
Signal #4	Delta T (µV)
Signal #5	Delta Tzero (µV)
Signal #6	Tzero Temperature (°C)
Signal #7	Cell Purge (mL/min)
Signal #8	Heater Temp (°C)
Signal #9	Power Delivered (W)
Signal #10	Reference Junction Temperature (°C)
Signal #11	Flange Temperature (°C)
Signal #12	Heat Flow Phase (rad)
Signal #13	Total Heat Capacity (J/°C)
Signal #14	Heat Capacity (J/°C)
[Configuration]
Company Name	ASU
Instrument Name	DSC2A-00468
Instrument Type	DSC2500
Serial Number	DSC2A-00468
IP	192.168.1.100
Location of Instrument	MRRC
DisplayType	Unknown
Sample Interval 	0.1 s/pt
Selected Heat Flow	T4P
Exotherm Direction	Down
Cell Serial	DRC2-00792
Lid Type	Standard
Cooler	RCS 90
Leave Cooler on at End of Sequence	On
Gas 2	Nitrogen
Gas Selected	Channel 1
Flow Rate	50 mL/min
Secondary Purge	On
Licensed Heat Flow	Heat Flow T4P
Modulation Licensed	Yes
[Versions]
Common IDD Version	1
Cortex Version	VER 2.10.2.31
Driver	5.0.0.6
GDM Version	1.0.3.3
TouchscreenVersion	1.0.0.16145
FEP Version	1.2.1.21
FEP Bootloader	2.0.0.5
AutoSampler Version	2.1.1.26
Auto Sampler Bootloader	2.0.0.5
FCM Version	1.1.0.3
FCM Bootloader	2.0.0.5
[Experiment Logs]
Experiment Log Entry # 1	Data On set to 0
Experiment Log Entry # 3	Equilibrate Segment 120 (C) Started
Experiment Log Entry # 5	Data On set to 1
Experiment Log Entry # 7	Ramp Segment 10 C/min to 180 Started
Experiment Log Entry # 9	Data On set to 0
Experiment Log Entry # 11	Isothermal Segment 0.1 min started
Experiment Log Entry # 13	Data On set to 1
Experiment Log Entry # 15	Ramp Segment 10 C/min to 120 Started
[Method Log]
Method Log Entry # 1	Data Off
Method Log Entry # 2	Equilibrate 120 °C
Method Log Entry # 3	Data On
Method Log Entry # 4	(Ramp 61851) Ramp 10 °C/minute to 180 °C
Method Log Entry # 5	Data Off
Method Log Entry # 6	Isothermal 0.1 minutes
Method Log Entry # 7	Data On
Method Log Entry # 8	(Ramp 61855) Ramp 10 °C/minute to 120 °C
Cell Serial	DRC2-00792
[T1 Calibration]
Slope	-0.008529666
Offset	9.636258
Initial Temperature	98.23
GUID	f8bfdadc-4977-4fdf-ba6d-0ba9134940c3
[TZero Calibration]
Date Applied	11/29/2022 4:06:13 PM
Description	From -89.059 °C to 396.009 °C at 20.000°C/min
Gas Type	Nitrogen
Pan Type	None
Source Files 1	C:\Users\yargerlab\Desktop\DSC Data\General\TZero_calibration_11_29_22_2nd(2).tri
Source Files 2	C:\Users\yargerlab\Desktop\DSC Data\General\TZero_calibration_11_29_22_2nd(3).tri
Delta T Offset	13.05235
Delta T Slope	-0.007271007
Delta T0 Offset	-13.69128
Delta T0 Slope	0.06063341
[Temperature Calibration]
Date Applied	11/29/2022 7:12:28 PM
Description	From 106.590 °C to 186.590 °C at 10.000°C/min
Gas Type	Nitrogen
Pan Type	Tzero Aluminum Hermetic
Source Files 1	C:\Users\yargerlab\Desktop\DSC Data\General\Indium(6).tri
Measured 1	157.391
Known 1	156.598
[Cell Constant Calibration]
Date Applied	11/29/2022 7:12:29 PM
Description	From 106.590 °C to 186.590 °C at 10.000°C/min
Gas Type	Nitrogen
Pan Type	Tzero Aluminum Hermetic
Source Files 1	C:\Users\yargerlab\Desktop\DSC Data\General\Indium(6).tri
T4P KCell	1.006051
Onset Slope	63.26126 mW/°C
[Direct Cp Calibration]
Date Applied	11/30/2022 11:04:51 AM
Description	From -79.983 °C to 298.409 °C at 10.000°C/min
Gas Type	Nitrogen
Pan Type	Tzero Aluminum Hermetic
Source Files 1	C:\Users\yargerlab\Desktop\DSC Data\General\Sapphire_Heat_Capacity_11_30_22.tri
[Rev Cp Calibration]
Date Applied	11/30/2022 1:58:51 PM
Description	From -79.996 °C to 292.812 °C at 3.000°C/min
Gas Type	Nitrogen
Pan Type	Tzero Aluminum Hermetic
Source Files 1	C:\Users\yargerlab\Desktop\DSC Data\General\Sapphire_MDSC_Calibration_11_30_22.tri
[step]
Ramp 10.00 °C/min to 180.00 °C
Time	Temperature	Heat Flow (Normalized)
min	°C	W/g
0.00	120.06	-0.004
0.01	120.06	-0.004
0.01	120.07	-0.004
0.01	120.07	-0.004
0.02	120.07	-0.005
0.03	120.07	-0.005
0.03	120.07	-0.005
0.03	120.08	-0.006
0.04	120.08	-0.006
0.05	120.08	-0.007
0.05	120.09	-0.008
0.05	120.09	-0.010
0.06	120.10	-0.011
0.07	120.11	-0.013
0.07	120.12	-0.014
0.08	120.13	-0.016
0.08	120.14	-0.018
0.08	120.16	-0.020
0.09	120.17	-0.022
0.09	120.19	-0.023
0.10	120.21	-0.025
0.11	120.23	-0.026
0.11	120.25	-0.028
0.12	120.27	-0.029
0.12	120.30	-0.029
0.13	120.32	-0.030
0.13	120.35	-0.030
0.14	120.38	-0.030
0.14	120.41	-0.030
0.14	120.45	-0.030
0.15	120.48	-0.029
0.16	120.51	-0.028
0.16	120.55	-0.027
0.16	120.58	-0.026
0.17	120.62	-0.025
0.18	120.66	-0.023
0.18	120.70	-0.022
0.19	120.73	-0.020
0.19	120.77	-0.019
0.19	120.81	-0.017
0.20	120.86	-0.015
0.21	120.90	-0.013
0.21	120.94	-0.012
0.21	120.98	-0.010
0.22	121.02	-0.009
0.23	121.07	-0.008
0.23	121.11	-0.006
0.24	121.15	-0.005
0.24	121.20	-0.003
0.24	121.24	-0.002
0.25	121.29	-0.001
0.26	121.33	0.000
0.26	121.37	0.001
0.26	121.42	0.002
0.27	121.46	0.003
0.28	121.51	0.003
0.28	121.56	0.004
0.29	121.60	0.005
0.29	121.65	0.006
0.30	121.69	0.006
0.30	121.74	0.007
0.30	121.79	0.007
0.31	121.83	0.008
0.31	121.88	0.009
0.32	121.93	0.009
0.33	121.97	0.010
0.33	122.02	0.010
0.34	122.07	0.011
0.34	122.11	0.011
0.35	122.16	0.011
0.35	122.21	0.012
0.35	122.26	0.012
0.36	122.30	0.012
0.36	122.35	0.013
0.37	122.40	0.013
0.38	122.45	0.014
0.38	122.50	0.014
0.39	122.54	0.014
0.39	122.59	0.014
0.40	122.64	0.015
0.40	122.69	0.015
0.40	122.74	0.015
0.41	122.79	0.015
0.41	122.83	0.015
0.42	122.88	0.016
0.43	122.93	0.016
0.43	122.98	0.017
0.44	123.03	0.017
0.44	123.08	0.017
0.45	123.13	0.017
0.45	123.17	0.017
0.45	123.22	0.017
0.46	123.27	0.017
0.46	123.32	0.017
0.47	123.37	0.018
0.48	123.42	0.018
0.48	123.47	0.018
0.49	123.52	0.018
0.49	123.57	0.018
0.50	123.62	0.018
0.50	123.66	0.018
0.50	123.71	0.018
0.51	123.76	0.018
0.51	123.81	0.018
0.52	123.86	0.018
0.53	123.91	0.019
0.53	123.96	0.019
0.53	124.01	0.019
0.54	124.06	0.019
0.55	124.11	0.019
0.55	124.16	0.019
0.55	124.21	0.019
0.56	124.25	0.019
0.57	124.30	0.019
0.57	124.35	0.019
0.58	124.40	0.019
0.58	124.45	0.019
0.58	124.50	0.019
0.59	124.55	0.019
0.60	124.60	0.019
0.60	124.65	0.019
0.60	124.70	0.019
0.61	124.75	0.019
0.62	124.80	0.019
0.62	124.85	0.019
0.63	124.90	0.019
0.63	124.95	0.019
0.63	125.00	0.019
0.64	125.05	0.020
0.65	125.09	0.020
0.65	125.14	0.020
0.65	125.19	0.020
0.66	125.24	0.020
0.67	125.29	0.020
0.67	125.34	0.020
0.68	125.39	0.020
0.68	125.44	0.020
0.68	125.49	0.020
0.69	125.54	0.020
0.70	125.59	0.020
0.70	125.64	0.020
0.70	125.69	0.020
0.71	125.74	0.020
0.72	125.79	0.020
0.72	125.84	0.020
0.73	125.89	0.020
0.73	125.94	0.020
0.73	125.99	0.020
0.74	126.04	0.020
0.75	126.09	0.020
0.75	126.14	0.020
0.75	126.19	0.020
0.76	126.24	0.020
0.77	126.29	0.020
0.77	126.34	0.020
0.78	126.39	0.020
0.78	126.44	0.020
0.78	126.48	0.020
0.79	126.54	0.020
0.80	126.58	0.020
0.80	126.63	0.020
0.80	126.69	0.020
0.81	126.73	0.020
0.82	126.78	0.020
0.82	126.83	0.020
0.83	126.88	0.020
0.83	126.93	0.020
0.83	126.98	0.020
0.84	127.03	0.021
0.85	127.08	0.021
0.85	127.13	0.021
0.85	127.18	0.021
0.86	127.23	0.021
0.87	127.28	0.021
0.87	127.33	0.021
0.88	127.38	0.021
0.88	127.43	0.021
0.88	127.48	0.021
0.89	127.53	0.021
0.90	127.58	0.019
0.90	127.63	0.018
0.90	127.68	0.018
0.91	127.73	0.019
0.92	127.78	0.019
0.92	127.83	0.019
0.93	127.88	0.019
0.93	127.93	0.019
0.93	127.98	0.019
0.94	128.03	0.019
0.95	128.08	0.019
0.95	128.13	0.020
0.95	128.18	0.020
0.96	128.23	0.020
0.97	128.28	0.020
0.97	128.33	0.020
0.98	128.38	0.020
0.98	128.43	0.020
0.98	128.48	0.020
0.99	128.53	0.020
1.00	128.58	0.020
1.00	128.63	0.020
1.00	128.68	0.020
1.01	128.73	0.020
1.02	128.78	0.020
1.02	128.83	0.020
1.03	128.88	0.020
1.03	128.93	0.020
1.03	128.97	0.020
1.04	129.03	0.020
1.05	129.08	0.020
1.05	129.13	0.020
1.05	129.18	0.020
1.06	129.22	0.020
1.07	129.28	0.020
1.07	129.32	0.020
1.08	129.37	0.020
1.08	129.43	0.021
1.08	129.47	0.021
1.09	129.52	0.021
1.09	129.58	0.021
1.10	129.63	0.021
1.11	129.68	0.021
1.11	129.72	0.021
1.12	129.77	0.021
1.12	129.82	0.021
1.13	129.87	0.021
1.13	129.92	0.021
1.13	129.97	0.021
1.14	130.02	0.021
1.14	130.07	0.021
1.15	130.12	0.021
1.16	130.17	0.021
1.16	130.22	0.021
1.17	130.27	0.021
1.17	130.32	0.021
1.18	130.37	0.021
1.18	130.42	0.021
1.18	130.47	0.021
1.19	130.52	0.021
1.19	130.57	0.021
1.20	130.62	0.021
1.21	130.67	0.021
1.21	130.72	0.021
1.22	130.77	0.021
1.22	130.82	0.021
1.23	130.87	0.021
1.23	130.92	0.021
1.23	130.97	0.021
1.24	131.02	0.021
1.24	131.07	0.021
1.25	131.12	0.021
1.26	131.17	0.021
1.26	131.22	0.021
1.27	131.27	0.021
1.27	131.32	0.021
1.28	131.37	0.021
1.28	131.42	0.021
1.28	131.47	0.021
1.29	131.52	0.021
1.29	131.57	0.021
1.30	131.62	0.021
1.31	131.67	0.021
1.31	131.72	0.021
1.32	131.77	0.021
1.32	131.82	0.022
1.33	131.87	0.022
1.33	131.92	0.022
1.33	131.97	0.022
1.34	132.02	0.022
1.34	132.07	0.022
1.35	132.12	0.022
1.36	132.17	0.022
1.36	132.22	0.022
1.37	132.27	0.022
1.37	132.32	0.022
1.38	132.37	0.022
1.38	132.42	0.022
1.38	132.47	0.022
1.39	132.52	0.022
1.39	132.57	0.022
1.40	132.62	0.022
1.41	132.67	0.022
1.41	132.72	0.022
1.42	132.77	0.022
1.42	132.82	0.022
1.43	132.87	0.022
1.43	132.92	0.022
1.43	132.97	0.022
1.44	133.02	0.022
1.44	133.07	0.022
1.45	133.12	0.022
1.46	133.17	0.022
1.46	133.22	0.022
1.47	133.27	0.022
1.47	133.32	0.022
1.48	133.37	0.022
1.48	133.42	0.022
1.48	133.47	0.022
1.49	133.52	0.022
1.49	133.57	0.022
1.50	133.62	0.022
1.51	133.67	0.022
1.51	133.72	0.022
1.52	133.77	0.022
1.52	133.82	0.022
1.53	133.87	0.022
1.53	133.92	0.022
1.53	133.97	0.022
1.54	134.02	0.022
1.54	134.07	0.022
1.55	134.12	0.022
1.56	134.17	0.022
1.56	134.22	0.022
1.57	134.27	0.022
1.57	134.32	0.022
1.58	134.37	0.022
1.58	134.42	0.022
1.58	134.47	0.022
1.59	134.52	0.022
1.59	134.57	0.022
1.60	134.62	0.022
1.61	134.67	0.022
1.61	134.72	0.022
1.62	134.77	0.022
1.62	134.82	0.022
1.63	134.87	0.022
1.63	134.92	0.022
1.63	134.97	0.022
1.64	135.02	0.022
1.64	135.07	0.022
1.65	135.12	0.022
1.66	135.17	0.022
1.66	135.22	0.022
1.67	135.27	0.022
1.67	135.32	0.022
1.68	135.37	0.022
1.68	135.42	0.022
1.68	135.47	0.022
1.69	135.52	0.022
1.69	135.57	0.022
1.70	135.62	0.022
1.71	135.67	0.022
1.71	135.72	0.022
1.72	135.77	0.022
1.72	135.82	0.022
1.73	135.87	0.022
1.73	135.92	0.022
1.73	135.97	0.022
1.74	136.02	0.022
1.74	136.07	0.022
1.75	136.12	0.022
1.76	136.17	0.022
1.76	136.22	0.022
1.77	136.27	0.022
1.77	136.32	0.022
1.78	136.37	0.022
1.78	136.42	0.022
1.78	136.47	0.022
1.79	136.52	0.022
1.79	136.57	0.022
1.80	136.62	0.022
1.81	136.67	0.022
1.81	136.72	0.022
1.82	136.77	0.022
1.82	136.82	0.022
1.83	136.87	0.022
1.83	136.92	0.022
1.83	136.97	0.022
1.84	137.02	0.022
1.84	137.07	0.022
1.85	137.12	0.022
1.86	137.17	0.022
1.86	137.22	0.022
1.87	137.27	0.022
1.87	137.32	0.022
1.88	137.37	0.022
1.88	137.42	0.022
1.88	137.47	0.022
1.89	137.52	0.022
1.89	137.57	0.022
1.90	137.62	0.022
1.91	137.67	0.022
1.91	137.72	0.022
1.92	137.77	0.022
1.92	137.82	0.022
1.93	137.87	0.022
1.93	137.92	0.022
1.93	137.97	0.022
1.94	138.02	0.022
1.94	138.07	0.022
1.95	138.12	0.022
1.96	138.17	0.022
1.96	138.22	0.022
1.97	138.27	0.022
1.97	138.32	0.022
1.98	138.37	0.022
1.98	138.42	0.022
1.98	138.47	0.022
1.99	138.52	0.022
1.99	138.57	0.022
2.00	138.62	0.022
2.01	138.67	0.022
2.01	138.72	0.022
2.02	138.77	0.022
2.02	138.82	0.022
2.03	138.87	0.022
2.03	138.92	0.022
2.03	138.97	0.022
2.04	139.02	0.022
2.04	139.07	0.022
2.05	139.12	0.022
2.06	139.17	0.022
2.06	139.22	0.022
2.07	139.27	0.022
2.07	139.32	0.022
2.08	139.37	0.022
2.08	139.42	0.022
2.08	139.47	0.022
2.09	139.52	0.022
2.09	139.57	0.022
2.10	139.62	0.022
2.11	139.67	0.022
2.11	139.72	0.022
2.12	139.77	0.022
2.12	139.82	0.022
2.13	139.87	0.022
2.13	139.92	0.022
2.14	139.97	0.022
2.14	140.02	0.022
2.14	140.07	0.022
2.15	140.12	0.022
2.16	140.17	0.022
2.16	140.22	0.022
2.16	140.27	0.022
2.17	140.32	0.022
2.18	140.37	0.022
2.18	140.42	0.022
2.19	140.47	0.022
2.19	140.52	0.022
2.19	140.57	0.022
2.20	140.62	0.022
2.21	140.67	0.022
2.21	140.72	0.022
2.21	140.77	0.022
2.22	140.82	0.022
2.23	140.87	0.022
2.23	140.92	0.022
2.24	140.97	0.022
2.24	141.02	0.022
2.24	141.07	0.022
2.25	141.12	0.022
2.26	141.17	0.022
2.26	141.22	0.022
2.26	141.27	0.022
2.27	141.32	0.022
2.28	141.37	0.022
2.28	141.42	0.022
2.29	141.47	0.022
2.29	141.52	0.022
2.29	141.57	0.022
2.30	141.62	0.022
2.31	141.67	0.022
2.31	141.72	0.023
2.31	141.77	0.023
2.32	141.82	0.023
2.33	141.87	0.023
2.33	141.92	0.023
2.34	141.97	0.023
2.34	142.02	0.023
2.34	142.07	0.023
2.35	142.12	0.023
2.36	142.17	0.023
2.36	142.22	0.023
2.36	142.27	0.023
2.37	142.32	0.023
2.38	142.37	0.023
2.38	142.42	0.023
2.39	142.47	0.023
2.39	142.52	0.023
2.39	142.57	0.023
2.40	142.62	0.023
2.41	142.67	0.023
2.41	142.72	0.023
2.41	142.77	0.023
2.42	142.82	0.023
2.43	142.87	0.023
2.43	142.92	0.023
2.44	142.97	0.023
2.44	143.02	0.023
2.44	143.07	0.023
2.45	143.12	0.023
2.46	143.17	0.023
2.46	143.22	0.023
2.46	143.27	0.023
2.47	143.32	0.023
2.48	143.37	0.023
2.48	143.42	0.023
2.49	143.47	0.023
2.49	143.52	0.023
2.49	143.57	0.023
2.50	143.62	0.023
2.51	143.67	0.023
2.51	143.72	0.023
2.51	143.77	0.023
2.52	143.82	0.023
2.53	143.87	0.023
2.53	143.92	0.023
2.54	143.97	0.023
2.54	144.02	0.023
2.54	144.07	0.023
2.55	144.12	0.023
2.56	144.17	0.023
2.56	144.22	0.023
2.56	144.27	0.023
2.57	144.32	0.023
2.58	144.37	0.023
2.58	144.42	0.023
2.59	144.47	0.023
2.59	144.52	0.023
2.59	144.57	0.023
2.60	144.62	0.023
2.61	144.67	0.023
2.61	144.72	0.023
2.61	144.77	0.023
2.62	144.82	0.023
2.63	144.87	0.023
2.63	144.93	0.023
2.64	144.97	0.023
2.64	145.02	0.023
2.64	145.07	0.023
2.65	145.12	0.023
2.66	145.18	0.023
2.66	145.22	0.023
2.66	145.27	0.023
2.67	145.32	0.023
2.68	145.37	0.023
2.68	145.42	0.023
2.69	145.47	0.023
2.69	145.53	0.023
2.69	145.58	0.023
2.70	145.63	0.023
2.71	145.68	0.023
2.71	145.73	0.023
2.71	145.78	0.023
2.72	145.83	0.023
2.73	145.88	0.023
2.73	145.93	0.023
2.74	145.98	0.023
2.74	146.03	0.023
2.74	146.08	0.023
2.75	146.13	0.023
2.76	146.18	0.023
2.76	146.23	0.023
2.76	146.28	0.023
2.77	146.33	0.023
2.78	146.38	0.023
2.78	146.43	0.023
2.79	146.48	0.023
2.79	146.53	0.023
2.79	146.58	0.023
2.80	146.63	0.023
2.81	146.68	0.023
2.81	146.73	0.023
2.81	146.78	0.023
2.82	146.83	0.023
2.83	146.88	0.023
2.83	146.93	0.023
2.84	146.98	0.023
2.84	147.03	0.023
2.84	147.08	0.023
2.85	147.13	0.023
2.86	147.18	0.023
2.86	147.23	0.023
2.86	147.28	0.023
2.87	147.33	0.023
2.88	147.38	0.023
2.88	147.43	0.023
2.89	147.48	0.023
2.89	147.53	0.023
2.89	147.58	0.023
2.90	147.63	0.023
2.91	147.68	0.023
2.91	147.73	0.023
2.91	147.78	0.023
2.92	147.83	0.023
2.93	147.88	0.023
2.93	147.93	0.023
2.94	147.98	0.023
2.94	148.03	0.023
2.94	148.08	0.023
2.95	148.13	0.023
2.96	148.18	0.023
2.96	148.23	0.023
2.96	148.28	0.023
2.97	148.33	0.023
2.98	148.38	0.023
2.98	148.43	0.023
2.99	148.48	0.023
2.99	148.53	0.023
2.99	148.58	0.023
3.00	148.63	0.023
3.01	148.68	0.023
3.01	148.73	0.023
3.01	148.78	0.023
3.02	148.83	0.023
3.03	148.88	0.023
3.03	148.93	0.023
3.04	148.98	0.023
3.04	149.03	0.023
3.04	149.08	0.023
3.05	149.13	0.023
3.06	149.18	0.023
3.06	149.23	0.023
3.06	149.28	0.023
3.07	149.33	0.023
3.08	149.38	0.023
3.08	149.43	0.023
3.09	149.48	0.023
3.09	149.53	0.023
3.09	149.58	0.023
3.10	149.63	0.023
3.11	149.68	0.023
3.11	149.73	0.023
3.11	149.78	0.023
3.12	149.83	0.023
3.13	149.88	0.023
3.13	149.93	0.023
3.14	149.98	0.023
3.14	150.03	0.023
3.14	150.08	0.023
3.15	150.13	0.023
3.16	150.18	0.023
3.16	150.23	0.023
3.16	150.28	0.023
3.17	150.33	0.023
3.18	150.38	0.023
3.18	150.43	0.023
3.19	150.48	0.023
3.19	150.53	0.023
3.19	150.58	0.023
3.20	150.63	0.023
3.21	150.68	0.023
3.21	150.73	0.023
3.21	150.78	0.023
3.22	150.83	0.023
3.23	150.88	0.023
3.23	150.93	0.024
3.24	150.98	0.024
3.24	151.03	0.024
3.24	151.08	0.024
3.25	151.13	0.024
3.26	151.18	0.024
3.26	151.23	0.024
3.26	151.28	0.024
3.27	151.33	0.024
3.28	151.38	0.024
3.28	151.43	0.024
3.29	151.48	0.024
3.29	151.53	0.024
3.29	151.58	0.024
3.30	151.63	0.024
3.31	151.68	0.024
3.31	151.73	0.024
3.31	151.78	0.024
3.32	151.83	0.024
3.33	151.88	0.024
3.33	151.93	0.024
3.34	151.98	0.024
3.34	152.03	0.024
3.34	152.08	0.024
3.35	152.13	0.024
3.36	152.18	0.024
3.36	152.23	0.024
3.36	152.28	0.024
3.37	152.33	0.024
3.38	152.38	0.024
3.38	152.43	0.024
3.39	152.48	0.024
3.39	152.53	0.024
3.39	152.58	0.024
3.40	152.63	0.024
3.41	152.68	0.024
3.41	152.73	0.024
3.41	152.78	0.024
3.42	152.83	0.024
3.43	152.88	0.024
3.43	152.93	0.024
3.44	152.98	0.024
3.44	153.03	0.024
3.44	153.08	0.024
3.45	153.13	0.024
3.46	153.18	0.024
3.46	153.23	0.024
3.46	153.28	0.024
3.47	153.33	0.024
3.48	153.38	0.024
3.48	153.43	0.024
3.49	153.48	0.024
3.49	153.53	0.024
3.49	153.58	0.024
3.50	153.63	0.024
3.51	153.68	0.024
3.51	153.73	0.024
3.51	153.78	0.024
3.52	153.83	0.024
3.53	153.88	0.024
3.53	153.93	0.024
3.54	153.98	0.024
3.54	154.03	0.024
3.54	154.08	0.024
3.55	154.13	0.024
3.56	154.18	0.024
3.56	154.23	0.024
3.56	154.28	0.024
3.57	154.33	0.024
3.58	154.38	0.024
3.58	154.43	0.024
3.59	154.48	0.024
3.59	154.53	0.024
3.59	154.58	0.024
3.60	154.63	0.024
3.61	154.68	0.024
3.61	154.73	0.024
3.61	154.78	0.024
3.62	154.83	0.024
3.63	154.88	0.024
3.63	154.93	0.024
3.64	154.98	0.024
3.64	155.03	0.024
3.64	155.08	0.024
3.65	155.13	0.024
3.66	155.18	0.024
3.66	155.23	0.024
3.66	155.28	0.024
3.67	155.33	0.024
3.68	155.38	0.024
3.68	155.43	0.024
3.69	155.48	0.024
3.69	155.53	0.024
3.69	155.58	0.024
3.70	155.63	0.024
3.71	155.68	0.024
3.71	155.73	0.024
3.71	155.78	0.024
3.72	155.83	0.024
3.73	155.88	0.024
3.73	155.93	0.024
3.74	155.98	0.025
3.74	156.03	0.025
3.74	156.08	0.025
3.75	156.13	0.025
3.76	156.18	0.025
3.76	156.23	0.025
3.76	156.28	0.025
3.77	156.33	0.025
3.78	156.38	0.025
3.78	156.43	0.025
3.79	156.48	0.025
3.79	156.53	0.026
3.79	156.58	0.026
3.80	156.63	0.027
3.81	156.68	0.029
3.81	156.73	0.032
3.81	156.78	0.035
3.82	156.83	0.041
3.83	156.88	0.056
3.83	156.92	0.083
3.84	156.96	0.122
3.84	157.00	0.163
3.84	157.03	0.199
3.85	157.07	0.232
3.86	157.09	0.264
3.86	157.12	0.295
3.86	157.15	0.323
3.87	157.17	0.350
3.88	157.20	0.376
3.88	157.22	0.401
3.89	157.25	0.426
3.89	157.27	0.449
3.89	157.29	0.472
3.90	157.32	0.494
3.91	157.34	0.516
3.91	157.36	0.538
3.91	157.39	0.560
3.92	157.41	0.582
3.93	157.43	0.607
3.93	157.46	0.634
3.94	157.48	0.660
3.94	157.50	0.687
3.94	157.52	0.714
3.95	157.54	0.738
3.96	157.56	0.759
3.96	157.58	0.777
3.96	157.60	0.796
3.97	157.63	0.814
3.98	157.65	0.831
3.98	157.67	0.847
3.99	157.70	0.864
3.99	157.72	0.880
3.99	157.75	0.895
4.00	157.78	0.910
4.01	157.80	0.924
4.01	157.83	0.935
4.01	157.86	0.937
4.02	157.89	0.932
4.03	157.92	0.930
4.03	157.96	0.941
4.04	157.99	0.957
4.04	158.03	0.976
4.04	158.06	0.995
4.05	158.09	1.015
4.06	158.12	1.035
4.06	158.15	1.053
4.06	158.18	1.072
4.07	158.21	1.090
4.08	158.25	1.108
4.08	158.27	1.126
4.09	158.30	1.143
4.09	158.33	1.161
4.09	158.36	1.179
4.10	158.39	1.197
4.11	158.42	1.215
4.11	158.45	1.231
4.11	158.48	1.246
4.12	158.51	1.262
4.13	158.54	1.277
4.13	158.57	1.292
4.14	158.60	1.305
4.14	158.63	1.315
4.14	158.66	1.308
4.15	158.70	1.279
4.16	158.74	1.239
4.16	158.79	1.215
4.16	158.84	1.209
4.17	158.89	1.202
4.18	158.94	1.187
4.18	158.99	1.169
4.19	159.05	1.161
4.19	159.10	1.164
4.19	159.15	1.171
4.20	159.20	1.180
4.21	159.25	1.190
4.21	159.30	1.200
4.21	159.35	1.210
4.22	159.39	1.218
4.23	159.44	1.224
4.23	159.49	1.222
4.24	159.54	1.201
4.24	159.59	1.157
4.24	159.65	1.107
4.25	159.71	1.073
4.26	159.78	1.055
4.26	159.84	1.044
4.26	159.91	1.029
4.27	159.97	1.003
4.28	160.04	0.970
4.28	160.11	0.941
4.29	160.18	0.911
4.29	160.25	0.846
4.30	160.34	0.732
4.30	160.44	0.602
4.30	160.54	0.507
4.31	160.65	0.448
4.31	160.76	0.407
4.32	160.86	0.376
4.33	160.96	0.350
4.33	161.06	0.329
4.34	161.16	0.310
4.34	161.26	0.293
4.35	161.35	0.278
4.35	161.44	0.263
4.35	161.53	0.250
4.36	161.61	0.238
4.36	161.70	0.226
4.37	161.78	0.215
4.38	161.86	0.205
4.38	161.94	0.195
4.39	162.02	0.186
4.39	162.09	0.177
4.40	162.17	0.169
4.40	162.24	0.161
4.40	162.31	0.154
4.41	162.38	0.147
4.41	162.45	0.139
4.42	162.52	0.133
4.43	162.59	0.129
4.43	162.66	0.123
4.44	162.72	0.117
4.44	162.79	0.112
4.45	162.85	0.108
4.45	162.91	0.103
4.45	162.97	0.099
4.46	163.04	0.095
4.46	163.10	0.091
4.47	163.16	0.087
4.48	163.22	0.084
4.48	163.28	0.081
4.49	163.34	0.078
4.49	163.40	0.075
4.50	163.45	0.072
4.50	163.51	0.069
4.50	163.57	0.067
4.51	163.62	0.065
4.51	163.68	0.062
4.52	163.74	0.061
4.53	163.79	0.059
4.53	163.85	0.057
4.54	163.90	0.055
4.54	163.96	0.053
4.55	164.01	0.052
4.55	164.07	0.050
4.55	164.12	0.049
4.56	164.17	0.048
4.56	164.23	0.047
4.57	164.28	0.045
4.58	164.33	0.044
4.58	164.39	0.043
4.59	164.44	0.043
4.59	164.49	0.042
4.60	164.54	0.041
4.60	164.60	0.040
4.60	164.65	0.039
4.61	164.70	0.038
4.61	164.75	0.038
4.62	164.80	0.037
4.63	164.86	0.036
4.63	164.91	0.036
4.64	164.96	0.035
4.64	165.01	0.035
4.65	165.06	0.035
4.65	165.11	0.034
4.65	165.17	0.034
4.66	165.22	0.033
4.66	165.27	0.032
4.67	165.32	0.032
4.68	165.37	0.032
4.68	165.42	0.032
4.69	165.47	0.031
4.69	165.52	0.031
4.70	165.57	0.031
4.70	165.62	0.031
4.70	165.68	0.030
4.71	165.73	0.030
4.71	165.78	0.030
4.72	165.83	0.030
4.73	165.88	0.030
4.73	165.93	0.029
4.74	165.98	0.029
4.74	166.03	0.029
4.75	166.08	0.029
4.75	166.13	0.029
4.75	166.18	0.029
4.76	166.23	0.029
4.76	166.28	0.029
4.77	166.33	0.029
4.78	166.38	0.028
4.78	166.43	0.028
4.79	166.48	0.028
4.79	166.53	0.028
4.80	166.58	0.028
4.80	166.63	0.028
4.80	166.68	0.028
4.81	166.73	0.028
4.81	166.78	0.028
4.82	166.84	0.028
4.83	166.88	0.028
4.83	166.94	0.028
4.84	166.99	0.028
4.84	167.04	0.028
4.85	167.09	0.028
4.85	167.14	0.028
4.85	167.19	0.028
4.86	167.24	0.028
4.86	167.29	0.028
4.87	167.34	0.028
4.88	167.39	0.028
4.88	167.44	0.028
4.89	167.49	0.028
4.89	167.54	0.028
4.90	167.59	0.028
4.90	167.64	0.028
4.90	167.69	0.028
4.91	167.74	0.028
4.91	167.79	0.028
4.92	167.84	0.028
4.93	167.89	0.028
4.93	167.94	0.028
4.94	167.99	0.028
4.94	168.04	0.028
4.95	168.09	0.028
4.95	168.14	0.028
4.95	168.19	0.028
4.96	168.24	0.028
4.96	168.29	0.028
4.97	168.34	0.028
4.98	168.39	0.028
4.98	168.44	0.028
4.99	168.49	0.028
4.99	168.54	0.028
5.00	168.59	0.028
5.00	168.64	0.028
5.00	168.69	0.027
5.01	168.74	0.027
5.01	168.79	0.027
5.02	168.84	0.027
5.03	168.89	0.027
5.03	168.94	0.027
5.04	168.99	0.027
5.04	169.04	0.027
5.05	169.09	0.027
5.05	169.14	0.027
5.05	169.19	0.027
5.06	169.24	0.027
5.06	169.29	0.027
5.07	169.34	0.027
5.08	169.39	0.027
5.08	169.44	0.027
5.09	169.49	0.027
5.09	169.54	0.027
5.10	169.59	0.027
5.10	169.64	0.027
5.10	169.69	0.027
5.11	169.74	0.027
5.11	169.79	0.027
5.12	169.84	0.027
5.13	169.89	0.027
5.13	169.94	0.028
5.14	169.99	0.028
5.14	170.04	0.028
5.15	170.09	0.028
5.15	170.14	0.028
5.15	170.19	0.028
5.16	170.24	0.028
5.16	170.29	0.028
5.17	170.34	0.028
5.18	170.39	0.028
5.18	170.44	0.028
5.19	170.49	0.028
5.19	170.54	0.028
5.20	170.59	0.028
5.20	170.64	0.028
5.20	170.69	0.028
5.21	170.74	0.028
5.21	170.79	0.028
5.22	170.84	0.028
5.23	170.89	0.028
5.23	170.94	0.028
5.24	170.99	0.028
5.24	171.04	0.028
5.25	171.09	0.028
5.25	171.14	0.028
5.25	171.19	0.028
5.26	171.24	0.028
5.26	171.29	0.028
5.27	171.34	0.028
5.28	171.39	0.028
5.28	171.44	0.028
5.29	171.49	0.028
5.29	171.54	0.028
5.30	171.59	0.028
5.30	171.64	0.028
5.30	171.69	0.028
5.31	171.74	0.028
5.31	171.79	0.028
5.32	171.84	0.028
5.33	171.89	0.028
5.33	171.94	0.028
5.34	171.99	0.028
5.34	172.04	0.028
5.35	172.09	0.028
5.35	172.14	0.028
5.35	172.19	0.028
5.36	172.24	0.028
5.36	172.29	0.028
5.37	172.34	0.028
5.38	172.39	0.028
5.38	172.44	0.028
5.39	172.49	0.028
5.39	172.54	0.029
5.40	172.59	0.029
5.40	172.64	0.029
5.40	172.69	0.029
5.41	172.74	0.029
5.41	172.79	0.029
5.42	172.84	0.029
5.43	172.89	0.029
5.43	172.94	0.029
5.44	172.99	0.029
5.44	173.04	0.029
5.45	173.09	0.029
5.45	173.14	0.029
5.45	173.19	0.029
5.46	173.24	0.029
5.46	173.29	0.029
5.47	173.34	0.029
5.48	173.39	0.029
5.48	173.44	0.029
5.49	173.49	0.029
5.49	173.54	0.029
5.50	173.59	0.029
5.50	173.64	0.029
5.50	173.69	0.029
5.51	173.74	0.029
5.51	173.79	0.029
5.52	173.84	0.029
5.53	173.89	0.029
5.53	173.94	0.029
5.54	173.99	0.029
5.54	174.04	0.029
5.55	174.09	0.029
5.55	174.14	0.029
5.55	174.19	0.029
5.56	174.24	0.029
5.56	174.29	0.029
5.57	174.34	0.030
5.58	174.39	0.030
5.58	174.44	0.030
5.59	174.49	0.030
5.59	174.54	0.030
5.60	174.59	0.030
5.60	174.64	0.030
5.60	174.69	0.030
5.61	174.74	0.030
5.61	174.79	0.030
5.62	174.84	0.030
5.63	174.89	0.030
5.63	174.94	0.030
5.64	174.99	0.030
5.64	175.04	0.030
5.65	175.09	0.030
5.65	175.14	0.030
5.65	175.19	0.030
5.66	175.24	0.030
5.66	175.29	0.030
5.67	175.34	0.030
5.68	175.39	0.030
5.68	175.44	0.030
5.69	175.49	0.030
5.69	175.54	0.030
5.70	175.59	0.030
5.70	175.64	0.030
5.70	175.69	0.030
5.71	175.74	0.030
5.71	175.79	0.030
5.72	175.84	0.030
5.73	175.89	0.030
5.73	175.94	0.030
5.74	175.99	0.031
5.74	176.04	0.031
5.75	176.09	0.031
5.75	176.14	0.031
5.75	176.19	0.031
5.76	176.24	0.031
5.76	176.29	0.031
5.77	176.34	0.031
5.78	176.39	0.031
5.78	176.44	0.031
5.79	176.49	0.031
5.79	176.54	0.031
5.80	176.59	0.031
5.80	176.64	0.031
5.80	176.69	0.031
5.81	176.74	0.031
5.81	176.79	0.031
5.82	176.84	0.031
5.83	176.89	0.031
5.83	176.94	0.031
5.84	176.99	0.031
5.84	177.04	0.031
5.85	177.09	0.031
5.85	177.14	0.031
5.85	177.19	0.031
5.86	177.24	0.031
5.86	177.29	0.031
5.87	177.34	0.031
5.88	177.39	0.031
5.88	177.44	0.031
5.89	177.49	0.031
5.89	177.54	0.031
5.90	177.59	0.032
5.90	177.64	0.032
5.90	177.69	0.032
5.91	177.74	0.032
5.91	177.79	0.032
5.92	177.84	0.032
5.93	177.89	0.032
5.93	177.94	0.032
5.94	177.99	0.032
5.94	178.04
5.95	178.09
5.95	178.14
5.95	178.19
5.96	178.24
5.96	178.29
5.97	178.34
5.98	178.39
5.98	178.44
5.99	178.49
5.99
6.00
6.00

[step]
Ramp 10.00 °C/min to 120.00 °C
Time	Temperature	Heat Flow (Normalized)
min	°C	W/g
6.10	179.51	0.041
6.10	179.55	0.041
6.11	179.58	0.040
6.11	179.61	0.040
6.12	179.63	0.040
6.12	179.66	0.040
6.13	179.68	0.040
6.13	179.71	0.040
6.14	179.73	0.040
6.14	179.74	0.040
6.15	179.76	0.040
6.15	179.78	0.040
6.16	179.79	0.040
6.16	179.80	0.039
6.17	179.81	0.039
6.17	179.81	0.038
6.18	179.82	0.037
6.18	179.82	0.036
6.19	179.82	0.035
6.19	179.81	0.035
6.20	179.81	0.034
6.20	179.80	0.032
6.21	179.79	0.031
6.21	179.78	0.030
6.22	179.76	0.028
6.22	179.75	0.026
6.23	179.72	0.024
6.23	179.70	0.022
6.24	179.68	0.019
6.24	179.66	0.017
6.25	179.63	0.014
6.25	179.61	0.011
6.26	179.58	0.008
6.26	179.55	0.005
6.27	179.52	0.002
6.27	179.49	0.000
6.28	179.45	-0.003
6.28	179.42	-0.006
6.29	179.38	-0.008
6.29	179.35	-0.011
6.30	179.31	-0.013
6.30	179.28	-0.016
6.31	179.24	-0.018
6.31	179.20	-0.020
6.32	179.16	-0.022
6.32	179.12	-0.024
6.33	179.08	-0.025
6.33	179.04	-0.027
6.34	179.00	-0.029
6.34	178.96	-0.030
6.35	178.92	-0.031
6.35	178.88	-0.032
6.36	178.83	-0.034
6.36	178.79	-0.035
6.37	178.75	-0.036
6.37	178.70	-0.037
6.38	178.66	-0.038
6.38	178.62	-0.039
6.39	178.57	-0.040
6.39	178.53	-0.040
6.40	178.48	-0.041
6.40	178.44	-0.042
6.41	178.39	-0.043
6.41	178.35	-0.043
6.42	178.30	-0.044
6.42	178.25	-0.045
6.43	178.21	-0.045
6.43	178.16	-0.045
6.44	178.12	-0.046
6.44	178.07	-0.046
6.45	178.02	-0.047
6.45	177.98	-0.048
6.46	177.93	-0.048
6.46	177.88	-0.048
6.47	177.84	-0.048
6.47	177.79	-0.049
6.48	177.74	-0.049
6.48	177.69	-0.050
6.49	177.65	-0.050
6.49	177.60	-0.050
6.50	177.55	-0.050
6.50	177.50	-0.050
6.51	177.45	-0.050
6.51	177.41	-0.051
6.52	177.36	-0.052
6.52	177.31	-0.052
6.53	177.26	-0.052
6.53	177.21	-0.052
6.54	177.17	-0.052
6.54	177.12	-0.052
6.55	177.07	-0.052
6.55	177.02	-0.052
6.56	176.97	-0.052
6.56	176.92	-0.052
6.57	176.87	-0.053
6.57	176.83	-0.053
6.58	176.78	-0.053
6.58	176.73	-0.053
6.59	176.68	-0.053
6.59	176.63	-0.053
6.60	176.58	-0.053
6.60	176.53	-0.054
6.61	176.49	-0.054
6.61	176.44	-0.054
6.62	176.39	-0.054
6.62	176.34	-0.054
6.63	176.29	-0.054
6.63	176.24	-0.054
6.64	176.19	-0.054
6.64	176.14	-0.054
6.65	176.09	-0.054
6.65	176.05	-0.054
6.66	176.00	-0.054
6.66	175.95	-0.054
6.67	175.90	-0.054
6.67	175.85	-0.054
6.68	175.80	-0.054
6.68	175.75	-0.054
6.69	175.70	-0.054
6.69	175.65	-0.054
6.70	175.60	-0.054
6.70	175.55	-0.054
6.71	175.51	-0.054
6.71	175.46	-0.054
6.72	175.41	-0.054
6.72	175.36	-0.054
6.73	175.31	-0.054
6.73	175.26	-0.055
6.74	175.21	-0.055
6.74	175.16	-0.055
6.75	175.11	-0.055
6.75	175.06	-0.055
6.76	175.01	-0.055
6.76	174.96	-0.055
6.77	174.92	-0.055
6.77	174.87	-0.055
6.78	174.82	-0.055
6.78	174.77	-0.055
6.79	174.72	-0.055
6.79	174.67	-0.055
6.80	174.62	-0.055
6.80	174.57	-0.055
6.81	174.52	-0.055
6.81	174.47	-0.055
6.82	174.42	-0.055
6.82	174.37	-0.055
6.83	174.32	-0.055
6.83	174.27	-0.055
6.84	174.22	-0.055
6.84	174.18	-0.055
6.85	174.12	-0.055
6.85	174.08	-0.055
6.86	174.03	-0.055
6.86	173.98	-0.055
6.87	173.93	-0.055
6.87	173.88	-0.055
6.88	173.83	-0.055
6.88	173.78	-0.055
6.89	173.73	-0.055
6.89	173.68	-0.055
6.90	173.63	-0.055
6.90	173.58	-0.055
6.91	173.53	-0.055
6.91	173.48	-0.055
6.92	173.43	-0.055
6.92	173.38	-0.055
6.93	173.33	-0.055
6.93	173.28	-0.055
6.94	173.23	-0.055
6.94	173.18	-0.055
6.95	173.13	-0.055
6.95	173.09	-0.055
6.96	173.04	-0.055
6.96	172.99	-0.055
6.97	172.94	-0.055
6.97	172.89	-0.055
6.98	172.84	-0.055
6.98	172.79	-0.055
6.99	172.74	-0.055
6.99	172.69	-0.055
7.00	172.64	-0.055
7.00	172.59	-0.055
7.01	172.54	-0.055
7.01	172.49	-0.055
7.02	172.44	-0.055
7.02	172.39	-0.055
7.03	172.34	-0.055
7.03	172.29	-0.055
7.04	172.24	-0.055
7.04	172.19	-0.055
7.05	172.14	-0.055
7.05	172.09	-0.055
7.06	172.04	-0.055
7.06	171.99	-0.055
7.07	171.94	-0.055
7.07	171.89	-0.055
7.08	171.84	-0.055
7.08	171.80	-0.055
7.09	171.75	-0.055
7.09	171.70	-0.055
7.10	171.65	-0.055
7.10	171.60	-0.055
7.11	171.55	-0.055
7.11	171.50	-0.055
7.12	171.45	-0.055
7.12	171.40	-0.055
7.13	171.35	-0.055
7.13	171.30	-0.055
7.14	171.25	-0.055
7.14	171.20	-0.055
7.15	171.15	-0.055
7.15	171.10	-0.055
7.16	171.05	-0.055
7.16	171.00	-0.055
7.17	170.95	-0.055
7.17	170.90	-0.055
7.18	170.85	-0.055
7.18	170.80	-0.055
7.19	170.75	-0.055
7.19	170.70	-0.055
7.20	170.65	-0.055
7.20	170.60	-0.055
7.21	170.55	-0.055
7.21	170.50	-0.055
7.22	170.45	-0.055
7.22	170.40	-0.055
7.23	170.35	-0.055
7.23	170.30	-0.055
7.24	170.25	-0.055
7.24	170.20	-0.055
7.25	170.15	-0.055
7.25	170.10	-0.055
7.26	170.05	-0.055
7.26	170.00	-0.055
7.27	169.95	-0.055
7.27	169.91	-0.055
7.28	169.86	-0.055
7.28	169.80	-0.055
7.29	169.76	-0.055
7.29	169.71	-0.055
7.30	169.66	-0.055
7.30	169.61	-0.055
7.31	169.56	-0.055
7.31	169.51	-0.055
7.32	169.46	-0.055
7.32	169.41	-0.055
7.33	169.36	-0.055
7.33	169.31	-0.055
7.34	169.26	-0.055
7.34	169.21	-0.055
7.35	169.16	-0.055
7.35	169.11	-0.055
7.36	169.06	-0.055
7.36	169.01	-0.055
7.37	168.96	-0.055
7.37	168.91	-0.055
7.38	168.86	-0.055
7.38	168.81	-0.055
7.39	168.76	-0.055
7.39	168.71	-0.055
7.40	168.66	-0.055
7.40	168.61	-0.055
7.41	168.56	-0.055
7.41	168.51	-0.055
7.42	168.46	-0.055
7.42	168.41	-0.055
7.43	168.36	-0.055
7.43	168.31	-0.055
7.44	168.26	-0.055
7.44	168.21	-0.055
7.45	168.16	-0.055
7.45	168.11	-0.055
7.46	168.06	-0.055
7.46	168.01	-0.055
7.47	167.96	-0.055
7.47	167.91	-0.055
7.48	167.86	-0.055
7.48	167.81	-0.055
7.49	167.77	-0.055
7.49	167.72	-0.055
7.50	167.67	-0.055
7.50	167.62	-0.055
7.51	167.57	-0.055
7.51	167.52	-0.055
7.52	167.47	-0.055
7.52	167.42	-0.055
7.53	167.37	-0.055
7.53	167.32	-0.055
7.54	167.27	-0.055
7.54	167.22	-0.055
7.55	167.17	-0.055
7.55	167.12	-0.055
7.56	167.07	-0.055
7.56	167.02	-0.055
7.57	166.97	-0.055
7.57	166.92	-0.055
7.58	166.87	-0.055
7.58	166.82	-0.055
7.59	166.77	-0.055
7.59	166.72	-0.055
7.60	166.67	-0.055
7.60	166.62	-0.055
7.61	166.57	-0.055
7.61	166.52	-0.055
7.62	166.47	-0.055
7.62	166.42	-0.055
7.63	166.37	-0.055
7.63	166.32	-0.055
7.64	166.27	-0.055
7.64	166.22	-0.055
7.65	166.17	-0.055
7.65	166.12	-0.055
7.66	166.07	-0.055
7.66	166.02	-0.055
7.67	165.97	-0.055
7.67	165.92	-0.055
7.68	165.87	-0.055
7.68	165.82	-0.055
7.69	165.77	-0.055
7.69	165.72	-0.055
7.70	165.67	-0.055
7.70	165.62	-0.055
7.71	165.57	-0.055
7.71	165.52	-0.055
7.72	165.47	-0.055
7.72	165.42	-0.055
7.73	165.37	-0.055
7.73	165.32	-0.055
7.74	165.27	-0.055
7.74	165.22	-0.055
7.75	165.17	-0.055
7.75	165.12	-0.055
7.76	165.07	-0.055
7.76	165.02	-0.055
7.77	164.97	-0.055
7.77	164.92	-0.055
7.78	164.87	-0.055
7.78	164.82	-0.055
7.79	164.77	-0.055
7.79	164.73	-0.055
7.80	164.67	-0.055
7.80	164.62	-0.055
7.81	164.57	-0.055
7.81	164.52	-0.055
7.82	164.47	-0.055
7.82	164.42	-0.055
7.83	164.38	-0.055
7.83	164.32	-0.055
7.84	164.27	-0.055
7.84	164.23	-0.055
7.85	164.18	-0.055
7.85	164.13	-0.055
7.86	164.08	-0.055
7.86	164.03	-0.055
7.87	163.98	-0.055
7.87	163.93	-0.055
7.88	163.88	-0.055
7.88	163.83	-0.055
7.89	163.78	-0.055
7.89	163.73	-0.055
7.90	163.68	-0.055
7.90	163.63	-0.055
7.91	163.57	-0.055
7.91	163.53	-0.055
7.92	163.47	-0.055
7.92	163.43	-0.055
7.93	163.38	-0.055
7.93	163.32	-0.055
7.94	163.27	-0.055
7.94	163.22	-0.055
7.95	163.17	-0.055
7.95	163.12	-0.055
7.96	163.07	-0.055
7.96	163.02	-0.055
7.97	162.98	-0.055
7.97	162.92	-0.055
7.98	162.88	-0.055
7.98	162.82	-0.055
7.99	162.78	-0.055
7.99	162.72	-0.055
8.00	162.68	-0.055
8.00	162.62	-0.055
8.01	162.58	-0.055
8.01	162.52	-0.055
8.02	162.48	-0.055
8.02	162.43	-0.055
8.03	162.37	-0.055
8.03	162.33	-0.055
8.04	162.28	-0.055
8.04	162.23	-0.055
8.05	162.18	-0.055
8.05	162.12	-0.055
8.06	162.08	-0.055
8.06	162.03	-0.055
8.07	161.98	-0.055
8.07	161.93	-0.055
8.08	161.88	-0.055
8.08	161.83	-0.055
8.09	161.78	-0.055
8.09	161.73	-0.055
8.10	161.68	-0.055
8.10	161.63	-0.055
8.11	161.58	-0.055
8.11	161.53	-0.055
8.12	161.48	-0.055
8.12	161.43	-0.055
8.13	161.38	-0.055
8.13	161.33	-0.055
8.14	161.28	-0.055
8.14	161.23	-0.055
8.15	161.18	-0.055
8.15	161.13	-0.055
8.16	161.08	-0.055
8.16	161.03	-0.055
8.17	160.98	-0.055
8.17	160.93	-0.055
8.18	160.88	-0.054
8.18	160.83	-0.054
8.19	160.78	-0.054
8.19	160.73	-0.054
8.20	160.68	-0.054
8.20	160.63	-0.054
8.21	160.58	-0.054
8.21	160.53	-0.054
8.22	160.48	-0.054
8.22	160.43	-0.054
8.23	160.38	-0.054
8.23	160.33	-0.054
8.24	160.28	-0.054
8.24	160.23	-0.054
8.25	160.18	-0.054
8.25	160.13	-0.054
8.26	160.08	-0.054
8.26	160.03	-0.054
8.27	159.98	-0.054
8.27	159.93	-0.054
8.28	159.88	-0.054
8.28	159.83	-0.054
8.29	159.78	-0.054
8.29	159.73	-0.054
8.30	159.68	-0.054
8.30	159.63	-0.054
8.31	159.58	-0.054
8.31	159.53	-0.054
8.32	159.48	-0.054
8.32	159.43	-0.054
8.33	159.38	-0.054
8.33	159.33	-0.054
8.34	159.28	-0.054
8.34	159.23	-0.054
8.35	159.18	-0.054
8.35	159.13	-0.054
8.36	159.08	-0.054
8.36	159.03	-0.054
8.37	158.98	-0.054
8.37	158.93	-0.054
8.38	158.88	-0.054
8.38	158.83	-0.054
8.39	158.78	-0.054
8.39	158.73	-0.054
8.40	158.68	-0.054
8.40	158.63	-0.054
8.41	158.58	-0.054
8.41	158.53	-0.054
8.42	158.48	-0.054
8.42	158.43	-0.054
8.43	158.38	-0.054
8.43	158.33	-0.054
8.44	158.28	-0.054
8.44	158.23	-0.054
8.45	158.18	-0.054
8.45	158.13	-0.054
8.46	158.08	-0.054
8.46	158.03	-0.054
8.47	157.98	-0.054
8.47	157.93	-0.054
8.48	157.88	-0.054
8.48	157.83	-0.054
8.49	157.78	-0.054
8.49	157.73	-0.054
8.50	157.68	-0.054
8.50	157.63	-0.054
8.51	157.58	-0.054
8.51	157.53	-0.054
8.52	157.48	-0.054
8.52	157.43	-0.054
8.53	157.39	-0.054
8.53	157.33	-0.054
8.54	157.28	-0.054
8.54	157.24	-0.054
8.55	157.18	-0.054
8.55	157.14	-0.054
8.56	157.09	-0.054
8.56	157.04	-0.054
8.57	156.99	-0.054
8.57	156.94	-0.054
8.58	156.89	-0.054
8.58	156.84	-0.054
8.59	156.79	-0.054
8.59	156.74	-0.054
8.60	156.69	-0.054
8.60	156.64	-0.054
8.61	156.59	-0.054
8.61	156.54	-0.054
8.62	156.49	-0.054
8.62	156.44	-0.054
8.63	156.39	-0.054
8.63	156.34	-0.054
8.64	156.29	-0.054
8.64	156.24	-0.054
8.65	156.19	-0.054
8.65	156.14	-0.054
8.66	156.09	-0.054
8.66	156.04	-0.054
8.67	155.99	-0.054
8.67	155.94	-0.054
8.68	155.89	-0.054
8.68	155.84	-0.054
8.69	155.79	-0.054
8.69	155.74	-0.054
8.70	155.69	-0.054
8.70	155.64	-0.054
8.71	155.59	-0.054
8.71	155.54	-0.054
8.72	155.49	-0.054
8.72	155.44	-0.054
8.73	155.39	-0.054
8.73	155.34	-0.054
8.74	155.29	-0.054
8.74	155.24	-0.054
8.75	155.19	-0.054
8.75	155.14	-0.054
8.76	155.09	-0.054
8.76	155.04	-0.054
8.77	154.99	-0.054
8.77	154.94	-0.054
8.78	154.89	-0.054
8.78	154.84	-0.054
8.79	154.79	-0.054
8.79	154.74	-0.054
8.80	154.69	-0.054
8.80	154.64	-0.062
8.81	154.59	-0.109
8.81	154.55	-0.264
8.82	154.54	-0.534
8.82	154.55	-0.878
8.83	154.60	-1.354
8.83	154.69	-2.101
8.84	154.89	-2.726
8.84	155.08	-2.830
8.85	155.22	-2.560
8.85	155.31	-2.287
8.86	155.36	-2.035
8.86	155.38	-1.856
8.87	155.39	-1.747
8.87	155.39	-1.680
8.88	155.37	-1.638
8.88	155.36	-1.600
8.89	155.34	-1.553
8.89	155.31	-1.510
8.90	155.27	-1.497
8.90	155.24	-1.514
8.91	155.21	-1.539
8.91	155.18	-1.564
8.92	155.15	-1.590
8.92	155.12	-1.615
8.93	155.09	-1.638
8.93	155.06	-1.660
8.94	155.04	-1.681
8.94	155.01	-1.701
8.95	154.98	-1.721
8.95	154.95	-1.742
8.96	154.93	-1.762
8.96	154.90	-1.780
8.97	154.87	-1.792
8.97	154.85	-1.788
8.98	154.81	-1.765
8.98	154.78	-1.743
8.99	154.74	-1.742
8.99	154.70	-1.760
9.00	154.67	-1.789
9.00	154.63	-1.807
9.01	154.60	-1.762
9.01	154.55	-1.666
9.02	154.49	-1.589
9.02	154.43	-1.565
9.03	154.37	-1.553
9.03	154.31	-1.530
9.04	154.25	-1.480
9.04	154.18	-1.416
9.05	154.11	-1.368
9.05	154.04	-1.353
9.06	153.96	-1.355
9.06	153.90	-1.366
9.07	153.83	-1.371
9.07	153.77	-1.333
9.08	153.69	-1.181
9.08	153.60	-0.916
9.09	153.47	-0.648
9.09	153.34	-0.495
9.10	153.20	-0.425
9.10	153.07	-0.380
9.11	152.94	-0.348
9.11	152.81	-0.324
9.12	152.69	-0.305
9.12	152.57	-0.288
9.13	152.46	-0.273
9.13	152.35	-0.260
9.14	152.24	-0.248
9.14	152.14	-0.237
9.15	152.04	-0.227
9.15	151.94	-0.217
9.16	151.84	-0.208
9.16	151.75	-0.199
9.17	151.66	-0.191
9.17	151.57	-0.183
9.18	151.49	-0.176
9.18	151.40	-0.169
9.19	151.32	-0.162
9.19	151.24	-0.157
9.20	151.17	-0.151
9.20	151.09	-0.146
9.21	151.01	-0.140
9.21	150.94	-0.136
9.22	150.87	-0.131
9.22	150.80	-0.127
9.23	150.73	-0.122
9.23	150.66	-0.119
9.24	150.59	-0.115
9.24	150.52	-0.111
9.25	150.46	-0.108
9.25	150.39	-0.105
9.26	150.33	-0.102
9.26	150.27	-0.099
9.27	150.20	-0.097
9.27	150.14	-0.094
9.28	150.08	-0.092
9.28	150.02	-0.090
9.29	149.96	-0.088
9.29	149.90	-0.086
9.30	149.84	-0.084
9.30	149.78	-0.082
9.31	149.73	-0.081
9.31	149.67	-0.079
9.32	149.61	-0.078
9.32	149.56	-0.076
9.33	149.50	-0.075
9.33	149.44	-0.073
9.34	149.39	-0.073
9.34	149.33	-0.072
9.35	149.28	-0.071
9.35	149.22	-0.069
9.36	149.17	-0.068
9.36	149.11	-0.068
9.37	149.06	-0.067
9.37	149.01	-0.066
9.38	148.95	-0.065
9.38	148.90	-0.064
9.39	148.85	-0.064
9.39	148.80	-0.063
9.40	148.74	-0.062
9.40	148.69	-0.062
9.41	148.64	-0.062
9.41	148.59	-0.061
9.42	148.53	-0.061
9.42	148.48	-0.060
9.43	148.43	-0.060
9.43	148.38	-0.060
9.44	148.33	-0.059
9.44	148.27	-0.059
9.45	148.22	-0.059
9.45	148.17	-0.058
9.46	148.12	-0.058
9.46	148.07	-0.058
9.47	148.02	-0.057
9.47	147.97	-0.057
9.48	147.92	-0.057
9.48	147.86	-0.057
9.49	147.81	-0.057
9.49	147.76	-0.057
9.50	147.71	-0.056
9.50	147.66	-0.056
9.51	147.61	-0.056
9.51	147.56	-0.056
9.52	147.51	-0.056
9.52	147.46	-0.055
9.53	147.41	-0.055
9.53	147.36	-0.055
9.54	147.31	-0.055
9.54	147.26	-0.055
9.55	147.21	-0.055
9.55	147.16	-0.055
9.56	147.10	-0.055
9.56	147.06	-0.055
9.57	147.00	-0.055
9.57	146.95	-0.055
9.58	146.90	-0.055
9.58	146.85	-0.055
9.59	146.80	-0.055
9.59	146.75	-0.055
9.60	146.70	-0.054
9.60	146.65	-0.054
9.61	146.60	-0.054
9.61	146.55	-0.054
9.62	146.50	-0.054
9.62	146.45	-0.054
9.63	146.40	-0.054
9.63	146.35	-0.054
9.64	146.30	-0.054
9.64	146.25	-0.054
9.65	146.20	-0.054
9.65	146.15	-0.054
9.66	146.10	-0.054
9.66	146.05	-0.054
9.67	146.00	-0.054
9.67	145.95	-0.054
9.68	145.90	-0.054
9.68	145.85	-0.054
9.69	145.80	-0.054
9.69	145.75	-0.054
9.70	145.70	-0.054
9.70	145.65	-0.054
9.71	145.60	-0.054
9.71	145.55	-0.054
9.72	145.50	-0.054
9.72	145.45	-0.054
9.73	145.40	-0.054
9.73	145.35	-0.054
9.74	145.30	-0.054
9.74	145.25	-0.053
9.75	145.20	-0.053
9.75	145.15	-0.053
9.76	145.10	-0.053
9.76	145.05	-0.053
9.77	145.00	-0.053
9.77	144.95	-0.053
9.78	144.90	-0.053
9.78	144.85	-0.053
9.79	144.80	-0.053
9.79	144.75	-0.053
9.80	144.70	-0.053
9.80	144.65	-0.053
9.81	144.60	-0.053
9.81	144.55	-0.053
9.82	144.50	-0.053
9.82	144.45	-0.053
9.83	144.40	-0.053
9.83	144.35	-0.053
9.84	144.30	-0.053
9.84	144.25	-0.053
9.85	144.20	-0.053
9.85	144.15	-0.053
9.86	144.10	-0.053
9.86	144.05	-0.053
9.87	144.00	-0.053
9.87	143.95	-0.053
9.88	143.90	-0.053
9.88	143.85	-0.053
9.89	143.80	-0.053
9.89	143.75	-0.053
9.90	143.70	-0.053
9.90	143.65	-0.053
9.91	143.60	-0.053
9.91	143.55	-0.053
9.92	143.50	-0.053
9.92	143.45	-0.053
9.93	143.40	-0.053
9.93	143.35	-0.053
9.94	143.30	-0.053
9.94	143.25	-0.053
9.95	143.20	-0.053
9.95	143.15	-0.053
9.96	143.10	-0.053
9.96	143.05	-0.053
9.97	143.00	-0.053
9.97	142.95	-0.053
9.98	142.90	-0.053
9.98	142.85	-0.053
9.99	142.80	-0.053
9.99	142.75	-0.053
10.00	142.70	-0.053
10.00	142.65	-0.053
10.01	142.60	-0.053
10.01	142.55	-0.053
10.02	142.50	-0.053
10.02	142.45	-0.053
10.03	142.40	-0.053
10.03	142.35	-0.053
10.04	142.30	-0.053
10.04	142.25	-0.053
10.05	142.20	-0.053
10.05	142.15	-0.053
10.06	142.10	-0.053
10.06	142.05	-0.053
10.07	142.00	-0.053
10.07	141.95	-0.053
10.08	141.90	-0.053
10.08	141.85	-0.053
10.09	141.80	-0.053
10.09	141.75	-0.053
10.10	141.70	-0.053
10.10	141.65	-0.053
10.11	141.60	-0.053
10.11	141.56	-0.053
10.12	141.51	-0.053
10.12	141.45	-0.053
10.13	141.40	-0.053
10.13	141.35	-0.053
10.14	141.31	-0.053
10.14	141.26	-0.053
10.15	141.20	-0.053
10.15	141.16	-0.053
10.16	141.11	-0.053
10.16	141.06	-0.053
10.17	141.01	-0.053
10.17	140.96	-0.053
10.18	140.90	-0.053
10.18	140.86	-0.053
10.19	140.80	-0.053
10.19	140.75	-0.053
10.20	140.70	-0.053
10.20	140.66	-0.053
10.21	140.61	-0.053
10.21	140.56	-0.053
10.22	140.51	-0.052
10.22	140.46	-0.052
10.23	140.41	-0.052
10.23	140.35	-0.052
10.24	140.31	-0.052
10.24	140.26	-0.052
10.25	140.20	-0.052
10.25	140.16	-0.052
10.26	140.11	-0.052
10.26	140.06	-0.052
10.27	140.01	-0.052
10.27	139.96	-0.052
10.28	139.91	-0.052
10.28	139.86	-0.052
10.29	139.81	-0.052
10.29	139.75	-0.052
10.30	139.71	-0.052
10.30	139.66	-0.052
10.31	139.61	-0.052
10.31	139.56	-0.052
10.32	139.51	-0.052
10.32	139.46	-0.052
10.33	139.41	-0.052
10.33	139.36	-0.052
10.34	139.31	-0.052
10.34	139.26	-0.052
10.35	139.21	-0.052
10.35	139.16	-0.052
10.36	139.11	-0.052
10.36	139.06	-0.052
10.37	139.01	-0.052
10.37	138.96	-0.052
10.38	138.91	-0.052
10.38	138.86	-0.052
10.39	138.81	-0.052
10.39	138.76	-0.052
10.40	138.71	-0.052
10.40	138.66	-0.052
10.41	138.61	-0.052
10.41	138.56	-0.052
10.42	138.51	-0.052
10.42	138.46	-0.052
10.43	138.41	-0.052
10.43	138.36	-0.052
10.44	138.31	-0.052
10.44	138.26	-0.052
10.45	138.21	-0.052
10.45	138.16	-0.052
10.46	138.11	-0.052
10.46	138.06	-0.052
10.47	138.01	-0.052
10.47	137.96	-0.052
10.48	137.91	-0.052
10.48	137.86	-0.052
10.49	137.81	-0.052
10.49	137.76	-0.052
10.50	137.71	-0.052
10.50	137.66	-0.052
10.51	137.61	-0.052
10.51	137.56	-0.052
10.52	137.51	-0.052
10.52	137.46	-0.052
10.53	137.41	-0.052
10.53	137.36	-0.052
10.54	137.31	-0.052
10.54	137.26	-0.052
10.55	137.21	-0.052
10.55	137.16	-0.052
10.56	137.11	-0.052
10.56	137.06	-0.052
10.57	137.01	-0.052
10.57	136.96	-0.052
10.58	136.91	-0.052
10.58	136.86	-0.052
10.59	136.81	-0.052
10.59	136.76	-0.052
10.60	136.71	-0.052
10.60	136.66	-0.052
10.61	136.61	-0.052
10.61	136.56	-0.052
10.62	136.51	-0.052
10.62	136.46	-0.052
10.63	136.41	-0.052
10.63	136.36	-0.052
10.64	136.31	-0.052
10.64	136.26	-0.052
10.65	136.21	-0.052
10.65	136.16	-0.052
10.66	136.11	-0.052
10.66	136.06	-0.052
10.67	136.01	-0.052
10.67	135.96	-0.052
10.68	135.91	-0.052
10.68	135.86	-0.052
10.69	135.81	-0.052
10.69	135.76	-0.052
10.70	135.71	-0.052
10.70	135.66	-0.052
10.71	135.61	-0.052
10.71	135.56	-0.052
10.72	135.51	-0.052
10.72	135.46	-0.052
10.73	135.41	-0.052
10.73	135.36	-0.052
10.74	135.31	-0.052
10.74	135.26	-0.052
10.75	135.21	-0.052
10.75	135.16	-0.052
10.76	135.11	-0.052
10.76	135.06	-0.052
10.77	135.01	-0.052
10.77	134.96	-0.052
10.78	134.91	-0.052
10.78	134.86	-0.052
10.79	134.81	-0.052
10.79	134.76	-0.052
10.80	134.71	-0.052
10.80	134.66	-0.052
10.81	134.61	-0.052
10.81	134.56	-0.052
10.82	134.51	-0.052
10.82	134.46	-0.052
10.83	134.41	-0.052
10.83	134.36	-0.052
10.84	134.31	-0.052
10.84	134.26	-0.052
10.85	134.21	-0.052
10.85	134.16	-0.052
10.86	134.11	-0.052
10.86	134.06	-0.052
10.87	134.01	-0.052
10.87	133.96	-0.052
10.88	133.91	-0.052
10.88	133.86	-0.052
10.89	133.81	-0.052
10.89	133.76	-0.052
10.90	133.71	-0.052
10.90	133.66	-0.052
10.91	133.61	-0.052
10.91	133.56	-0.052
10.92	133.51	-0.052
10.92	133.46	-0.052
10.93	133.41	-0.052
10.93	133.36	-0.052
10.94	133.31	-0.052
10.94	133.26	-0.052
10.95	133.21	-0.052
10.95	133.16	-0.052
10.96	133.11	-0.052
10.96	133.06	-0.052
10.97	133.01	-0.052
10.97	132.96	-0.052
10.98	132.91	-0.052
10.98	132.86	-0.052
10.99	132.81	-0.052
10.99	132.76	-0.052
11.00	132.71	-0.052
11.00	132.66	-0.052
11.01	132.61	-0.052
11.01	132.56	-0.052
11.02	132.51	-0.052
11.02	132.46	-0.052
11.03	132.41	-0.052
11.03	132.36	-0.052
11.04	132.31	-0.052
11.04	132.26	-0.052
11.05	132.21	-0.052
11.05	132.16	-0.052
11.06	132.11	-0.052
11.06	132.06	-0.052
11.07	132.01	-0.052
11.07	131.96	-0.052
11.08	131.91	-0.052
11.08	131.86	-0.052
11.09	131.81	-0.052
11.09	131.76	-0.052
11.10	131.71	-0.052
11.10	131.66	-0.052
11.11	131.61	-0.052
11.11	131.56	-0.052
11.12	131.51	-0.052
11.12	131.47	-0.052
11.13	131.41	-0.052
11.13	131.36	-0.052
11.14	131.31	-0.052
11.14	131.26	-0.052
11.15	131.21	-0.052
11.15	131.16	-0.052
11.16	131.12	-0.052
11.16	131.06	-0.052
11.17	131.02	-0.052
11.17	130.97	-0.052
11.18	130.91	-0.052
11.18	130.87	-0.051
11.19	130.82	-0.051
11.19	130.77	-0.051
11.20	130.72	-0.051
11.20	130.67	-0.051
11.21	130.62	-0.051
11.21	130.57	-0.051
11.22	130.51	-0.051
11.22	130.46	-0.051
11.23	130.42	-0.051
11.23	130.37	-0.051
11.24	130.32	-0.051
11.24	130.27	-0.051
11.25	130.22	-0.051
11.25	130.17	-0.051
11.26	130.11	-0.051
11.26	130.07	-0.051
11.27	130.02	-0.051
11.27	129.97	-0.051
11.28	129.92	-0.051
11.28	129.87	-0.051
11.29	129.82	-0.051
11.29	129.77	-0.051
11.30	129.72	-0.051
11.30	129.67	-0.051
11.31	129.62	-0.051
11.31	129.57	-0.051
11.32	129.52	-0.051
11.32	129.47	-0.051
11.33	129.42	-0.051
11.33	129.37	-0.051
11.34	129.32	-0.051
11.34	129.27	-0.051
11.35	129.22	-0.051
11.35	129.17	-0.051
11.36	129.12	-0.051
11.36	129.07	-0.051
11.37	129.02	-0.051
11.37	128.97	-0.051
11.38	128.92	-0.051
11.38	128.87	-0.051
11.39	128.82	-0.051
11.39	128.77	-0.051
11.40	128.72	-0.051
11.40	128.67	-0.051
11.41	128.62	-0.051
11.41	128.57	-0.051
11.42	128.52	-0.051
11.42	128.47	-0.051
11.43	128.42	-0.051
11.43	128.37	-0.051
11.44	128.32	-0.051
11.44	128.27	-0.051
11.45	128.22	-0.051
11.45	128.17	-0.051
11.46	128.12	-0.051
11.46	128.07	-0.051
11.47	128.02	-0.051
11.47	127.97	-0.051
11.48	127.92	-0.051
11.48	127.87	-0.051
11.49	127.82	-0.051
11.49	127.77	-0.051
11.50	127.72	-0.051
11.50	127.67	-0.051
11.51	127.62	-0.051
11.51	127.57	-0.051
11.52	127.52	-0.051
11.52	127.47	-0.051
11.53	127.42	-0.051
11.53	127.37	-0.051
11.54	127.32	-0.051
11.54	127.27	-0.051
11.55	127.22	-0.051
11.55	127.17	-0.051
11.56	127.12	-0.051
11.56	127.07	-0.051
11.57	127.02	-0.051
11.57	126.97	-0.051
11.58	126.92	-0.051
11.58	126.87	-0.051
11.59	126.82	-0.051
11.59	126.77	-0.051
11.60	126.72	-0.051
11.60	126.67	-0.051
11.61	126.62	-0.051
11.61	126.57	-0.051
11.62	126.52	-0.051
11.62	126.47	-0.051
11.63	126.42	-0.051
11.63	126.37	-0.051
11.64	126.32	-0.051
11.64	126.27	-0.051
11.65	126.22	-0.051
11.65	126.17	-0.051
11.66	126.12	-0.051
11.66	126.07	-0.051
11.67	126.02	-0.051
11.67	125.97	-0.051
11.68	125.92	-0.051
11.68	125.87	-0.051
11.69	125.82	-0.051
11.69	125.77	-0.051
11.70	125.72	-0.051
11.70	125.67	-0.051
11.71	125.62	-0.051
11.71	125.57	-0.051
11.72	125.52	-0.051
11.72	125.47	-0.051
11.73	125.42	-0.051
11.73	125.37	-0.051
11.74	125.32	-0.051
11.74	125.27	-0.051
11.75	125.22	-0.051
11.75	125.17	-0.051
11.76	125.12	-0.051
11.76	125.07	-0.051
11.77	125.02	-0.051
11.77	124.97	-0.051
11.78	124.92	-0.051
11.78	124.87	-0.051
11.79	124.82	-0.051
11.79	124.77	-0.051
11.80	124.72	-0.051
11.80	124.67	-0.051
11.81	124.62	-0.051
11.81	124.57	-0.051
11.82	124.52	-0.051
11.82	124.47	-0.051
11.83	124.42	-0.051
11.83	124.37	-0.051
11.84	124.32	-0.051
11.84	124.27	-0.051
11.85	124.22	-0.051
11.85	124.17	-0.051
11.86	124.12	-0.051
11.86	124.07	-0.051
11.87	124.02	-0.051
11.87	123.97	-0.051
11.88	123.92	-0.051
11.88	123.87	-0.051
11.89	123.82	-0.051
11.89	123.77	-0.051
11.90	123.72	-0.051
11.90	123.67	-0.051
11.91	123.62	-0.051
11.91	123.57	-0.051
11.92	123.52	-0.051
11.92	123.47	-0.051
11.93	123.42	-0.051
11.93	123.37	-0.051
11.94	123.32	-0.051
11.94	123.27	-0.051
11.95	123.22	-0.051
11.95	123.17	-0.051
11.96	123.12	-0.051
11.96	123.07	-0.051
11.97	123.02	-0.051
11.97	122.97	-0.051
11.98	122.92	-0.051
11.98	122.87	-0.051
11.99	122.82	-0.051
11.99	122.77	-0.051
12.00	122.72	-0.051
12.00	122.67	-0.051
12.01	122.62	-0.051
12.01	122.57	-0.051
12.02	122.52	-0.051
12.02	122.47	-0.051
12.03	122.42	-0.051
12.03	122.37	-0.051
12.04	122.32	-0.051
12.04	122.27	-0.051
12.05	122.22
12.05	122.17
12.06	122.12
12.06	122.07
12.07	122.02
12.07	121.97
12.08	121.92
12.08	121.87
12.09	121.82
12.09	121.77
12.10
12.10
12.10