File: DSC/2023_05_24_CBD_powder_Al_Herm_Tzero.txt
Filename	2023_05_24_CBD_powder_Al_Herm_Tzero
Instrument name	DSC2A-00468 (192.168.1.100)
Operator	SBK
rundate	5/24/2023
Sample name	2023_05_24_CBD_powder_Al_Herm_Tzero
proceduresegments	Data Off ; Equilibrate 30.00 °C; Data On ; Ramp 10.00 °C/min to 100.00 °C; Data Off ; Isothermal 1.0 min; Data On ; Ramp 10.00 °C/min to -30.00 °C; Data Off ; Isothermal 1.0 min; Data On ; Ramp 10.00 °C/min to 100.00 °C
[File Parameters]
Run date	5/24/2023 3:13:45 PM
Trios version	5.1.1.46572
Original File Name
Current File Name	C:\Users\yargerlab\Desktop\DSC Data\General\2023_05_24_CBD_powder_Al_Herm_Tzero.tri
[Procedure]
Procedure Name	DSC 30C to 100C to n30C at 10Cmin
Sample Name	2023_05_24_CBD_powder_Al_Herm_Tzero
Sample Mass	2.1 mg
Reference Sample Mass	0 mg
Pan Mass	51.88 mg
Pan Number	20
Reference Pan Mass	51.62 mg
Reference Pan Number	2
Pan Type	Tzero Aluminum Hermetic
Comments	CBD Powder
Project Name	Silk ASDs
Operator	SBK
Test	Custom
Unload Max Temperature	30
Unload Min Temperature	30
Load Max Temperature	30
Load Min Temperature	30
Stop on Gas Flow Error	Yes
[Signal List]
Signal #1	Time (min)
Signal #2	Temperature (°C)
Signal #3	Heat Flow (mW)
Signal #4	Delta T (µV)
Signal #5	Delta Tzero (µV)
Signal #6	Tzero Temperature (°C)
Signal #7	Cell Purge (mL/min)
Signal #8	Heater Temp (°C)
Signal #9	Power Delivered (W)
Signal #10	Reference Junction Temperature (°C)
Signal #11	Flange Temperature (°C)
Signal #12	Heat Flow Phase (rad)
Signal #13	Total Heat Capacity (J/°C)
Signal #14	Heat Capacity (J/°C)
[Configuration]
Company Name	ASU
Instrument Name	DSC2A-00468
Instrument Type	DSC2500
Serial Number	DSC2A-00468
IP	192.168.1.100
Location of Instrument	MRRC
DisplayType	Unknown
Sample Interval 	0.1 s/pt
Selected Heat Flow	T4P
Exotherm Direction	Down
Cell Serial	DRC2-00792
Lid Type	Standard
Cooler	RCS 90
Leave Cooler on at End of Sequence	On
Gas 2	Nitrogen
Gas Selected	Channel 1
Flow Rate	50 mL/min
Secondary Purge	On
Licensed Heat Flow	Heat Flow T4P
Modulation Licensed	Yes
[Versions]
Common IDD Version	1
Cortex Version	VER 2.10.2.31
Driver	5.0.0.6
GDM Version	1.0.3.3
TouchscreenVersion	1.0.0.16145
FEP Version	1.2.1.21
FEP Bootloader	2.0.0.5
AutoSampler Version	2.1.1.26
Auto Sampler Bootloader	2.0.0.5
FCM Version	1.1.0.3
FCM Bootloader	2.0.0.5
[Experiment Logs]
Experiment Log Entry # 1	Data On set to 0
Experiment Log Entry # 3	Equilibrate Segment 30 (C) Started
Experiment Log Entry # 5	Data On set to 1
Experiment Log Entry # 7	Ramp Segment 10 C/min to 100 Started
Experiment Log Entry # 9	Data On set to 0
Experiment Log Entry # 11	Isothermal Segment 1 min started
Experiment Log Entry # 13	Data On set to 1
Experiment Log Entry # 15	Ramp Segment 10 C/min to -30 Started
Experiment Log Entry # 17	Data On set to 0
Experiment Log Entry # 19	Isothermal Segment 1 min started
Experiment Log Entry # 21	Data On set to 1
Experiment Log Entry # 23	Ramp Segment 10 C/min to 100 Started
[Method Log]
Method Log Entry # 1	Data Off
Method Log Entry # 2	Equilibrate 30 °C
Method Log Entry # 3	Data On
Method Log Entry # 4	(Ramp 773) Ramp 10 °C/minute to 100 °C
Method Log Entry # 5	Data Off
Method Log Entry # 6	Isothermal 1 minutes
Method Log Entry # 7	Data On
Method Log Entry # 8	(Ramp 777) Ramp 10 °C/minute to -30 °C
Method Log Entry # 9	Data Off
Method Log Entry # 10	Isothermal 1 minutes
Method Log Entry # 11	Data On
Method Log Entry # 12	(Ramp 781) Ramp 10 °C/minute to 100 °C
Cell Serial	DRC2-00792
[T1 Calibration]
Slope	-0.008529666
Offset	9.636258
Initial Temperature	98.23
GUID	f8bfdadc-4977-4fdf-ba6d-0ba9134940c3
[TZero Calibration]
Date Applied	11/29/2022 4:06:13 PM
Description	From -89.059 °C to 396.009 °C at 20.000°C/min
Gas Type	Nitrogen
Pan Type	None
Source Files 1	C:\Users\yargerlab\Desktop\DSC Data\General\TZero_calibration_11_29_22_2nd(2).tri
Source Files 2	C:\Users\yargerlab\Desktop\DSC Data\General\TZero_calibration_11_29_22_2nd(3).tri
Delta T Offset	13.05235
Delta T Slope	-0.007271007
Delta T0 Offset	-13.69128
Delta T0 Slope	0.06063341
[Temperature Calibration]
Date Applied	11/29/2022 7:12:28 PM
Description	From 106.590 °C to 186.590 °C at 10.000°C/min
Gas Type	Nitrogen
Pan Type	Tzero Aluminum Hermetic
Source Files 1	C:\Users\yargerlab\Desktop\DSC Data\General\Indium(6).tri
Measured 1	157.391
Known 1	156.598
[Cell Constant Calibration]
Date Applied	11/29/2022 7:12:29 PM
Description	From 106.590 °C to 186.590 °C at 10.000°C/min
Gas Type	Nitrogen
Pan Type	Tzero Aluminum Hermetic
Source Files 1	C:\Users\yargerlab\Desktop\DSC Data\General\Indium(6).tri
T4P KCell	1.006051
Onset Slope	63.26126 mW/°C
[Direct Cp Calibration]
Date Applied	11/30/2022 11:04:51 AM
Description	From -79.983 °C to 298.409 °C at 10.000°C/min
Gas Type	Nitrogen
Pan Type	Tzero Aluminum Hermetic
Source Files 1	C:\Users\yargerlab\Desktop\DSC Data\General\Sapphire_Heat_Capacity_11_30_22.tri
[Rev Cp Calibration]
Date Applied	11/30/2022 1:58:51 PM
Description	From -79.996 °C to 292.812 °C at 3.000°C/min
Gas Type	Nitrogen
Pan Type	Tzero Aluminum Hermetic
Source Files 1	C:\Users\yargerlab\Desktop\DSC Data\General\Sapphire_MDSC_Calibration_11_30_22.tri
[step]
Ramp 10.00 °C/min to 100.00 °C
Time	Temperature	Heat Flow (Normalized)
min	°C	W/g
0.00	29.97	0.051
0.01	29.97	0.046
0.01	29.97	0.042
0.01	29.98	0.037
0.02	29.98	0.036
0.03	29.98	0.033
0.03	29.99	0.030
0.03	29.99	0.024
0.04	30.00	0.016
0.05	30.00	0.007
0.05	30.01	-0.005
0.05	30.02	-0.020
0.06	30.03	-0.038
0.07	30.04	-0.060
0.07	30.05	-0.084
0.08	30.07	-0.108
0.08	30.08	-0.132
0.08	30.10	-0.159
0.09	30.12	-0.186
0.09	30.14	-0.212
0.10	30.17	-0.237
0.11	30.19	-0.264
0.11	30.22	-0.286
0.12	30.25	-0.300
0.12	30.28	-0.313
0.13	30.31	-0.325
0.13	30.34	-0.333
0.14	30.37	-0.337
0.14	30.41	-0.338
0.14	30.44	-0.337
0.15	30.48	-0.332
0.16	30.52	-0.328
0.16	30.55	-0.319
0.16	30.59	-0.307
0.17	30.63	-0.295
0.18	30.67	-0.283
0.18	30.71	-0.270
0.19	30.75	-0.258
0.19	30.79	-0.244
0.19	30.84	-0.232
0.20	30.88	-0.220
0.21	30.92	-0.207
0.21	30.96	-0.197
0.21	31.00	-0.186
0.22	31.05	-0.175
0.23	31.09	-0.163
0.23	31.13	-0.155
0.24	31.17	-0.148
0.24	31.22	-0.142
0.24	31.26	-0.136
0.25	31.31	-0.131
0.26	31.35	-0.122
0.26	31.40	-0.117
0.26	31.44	-0.112
0.27	31.49	-0.106
0.28	31.53	-0.101
0.28	31.58	-0.096
0.29	31.63	-0.091
0.29	31.67	-0.084
0.30	31.72	-0.082
0.30	31.76	-0.080
0.30	31.81	-0.074
0.31	31.86	-0.066
0.31	31.91	-0.062
0.32	31.95	-0.059
0.33	32.00	-0.057
0.33	32.05	-0.053
0.34	32.09	-0.050
0.34	32.14	-0.045
0.35	32.19	-0.040
0.35	32.24	-0.034
0.35	32.28	-0.033
0.36	32.33	-0.033
0.36	32.38	-0.028
0.37	32.43	-0.022
0.38	32.48	-0.020
0.38	32.53	-0.020
0.39	32.57	-0.017
0.39	32.62	-0.013
0.40	32.67	-0.011
0.40	32.72	-0.009
0.40	32.77	-0.006
0.41	32.82	-0.004
0.41	32.87	-0.003
0.42	32.91	-0.002
0.43	32.96	-0.001
0.43	33.01	0.003
0.44	33.06	0.005
0.44	33.11	0.006
0.45	33.16	0.007
0.45	33.21	0.008
0.45	33.26	0.010
0.46	33.31	0.011
0.46	33.36	0.012
0.47	33.41	0.013
0.48	33.45	0.014
0.48	33.50	0.014
0.49	33.55	0.015
0.49	33.60	0.017
0.50	33.65	0.019
0.50	33.70	0.020
0.50	33.75	0.021
0.51	33.80	0.021
0.51	33.85	0.021
0.52	33.90	0.022
0.53	33.95	0.022
0.53	34.00	0.022
0.53	34.05	0.023
0.54	34.10	0.024
0.55	34.15	0.025
0.55	34.20	0.025
0.55	34.24	0.025
0.56	34.29	0.026
0.57	34.34	0.026
0.57	34.39	0.027
0.58	34.44	0.027
0.58	34.49	0.028
0.58	34.54	0.028
0.59	34.59	0.028
0.60	34.64	0.028
0.60	34.69	0.029
0.60	34.74	0.029
0.61	34.79	0.029
0.62	34.84	0.030
0.62	34.89	0.030
0.63	34.94	0.030
0.63	34.99	0.030
0.63	35.04	0.031
0.64	35.09	0.031
0.65	35.14	0.031
0.65	35.19	0.031
0.65	35.24	0.031
0.66	35.29	0.032
0.67	35.34	0.032
0.67	35.39	0.032
0.68	35.44	0.032
0.68	35.49	0.033
0.68	35.54	0.033
0.69	35.59	0.033
0.70	35.64	0.033
0.70	35.69	0.033
0.70	35.73	0.033
0.71	35.79	0.034
0.72	35.83	0.034
0.72	35.88	0.034
0.73	35.93	0.034
0.73	35.98	0.034
0.73	36.03	0.035
0.74	36.08	0.035
0.75	36.13	0.035
0.75	36.18	0.035
0.75	36.23	0.035
0.76	36.28	0.036
0.77	36.33	0.036
0.77	36.38	0.036
0.78	36.43	0.036
0.78	36.48	0.036
0.78	36.53	0.037
0.79	36.58	0.037
0.80	36.63	0.037
0.80	36.68	0.037
0.80	36.73	0.037
0.81	36.78	0.037
0.82	36.83	0.038
0.82	36.88	0.038
0.83	36.93	0.038
0.83	36.98	0.038
0.83	37.03	0.038
0.84	37.08	0.038
0.85	37.13	0.039
0.85	37.18	0.039
0.85	37.23	0.039
0.86	37.28	0.039
0.87	37.33	0.039
0.87	37.38	0.039
0.88	37.43	0.039
0.88	37.48	0.040
0.88	37.53	0.040
0.89	37.58	0.040
0.90	37.63	0.040
0.90	37.68	0.040
0.90	37.73	0.040
0.91	37.78	0.040
0.92	37.83	0.041
0.92	37.88	0.041
0.93	37.93	0.041
0.93	37.98	0.041
0.93	38.03	0.041
0.94	38.08	0.041
0.95	38.13	0.041
0.95	38.18	0.041
0.95	38.23	0.041
0.96	38.28	0.041
0.97	38.33	0.041
0.97	38.37	0.042
0.98	38.43	0.042
0.98	38.47	0.042
0.98	38.52	0.042
0.99	38.57	0.042
1.00	38.63	0.042
1.00	38.67	0.042
1.00	38.73	0.042
1.01	38.77	0.042
1.02	38.82	0.042
1.02	38.87	0.043
1.03	38.92	0.043
1.03	38.97	0.043
1.03	39.02	0.043
1.04	39.07	0.043
1.05	39.12	0.043
1.05	39.17	0.043
1.05	39.22	0.043
1.06	39.27	0.043
1.07	39.32	0.043
1.07	39.37	0.043
1.08	39.42	0.043
1.08	39.47	0.043
1.08	39.52	0.043
1.09	39.57	0.043
1.09	39.62	0.043
1.10	39.67	0.044
1.11	39.72	0.044
1.11	39.77	0.044
1.12	39.82	0.044
1.12	39.87	0.044
1.13	39.92	0.044
1.13	39.97	0.044
1.13	40.02	0.044
1.14	40.07	0.044
1.14	40.12	0.044
1.15	40.17	0.044
1.16	40.22	0.044
1.16	40.27	0.044
1.17	40.32	0.045
1.17	40.37	0.045
1.18	40.42	0.045
1.18	40.47	0.045
1.18	40.52	0.045
1.19	40.57	0.045
1.19	40.62	0.045
1.20	40.67	0.045
1.21	40.72	0.045
1.21	40.77	0.045
1.22	40.82	0.045
1.22	40.87	0.045
1.23	40.92	0.045
1.23	40.97	0.045
1.23	41.02	0.045
1.24	41.07	0.045
1.24	41.12	0.045
1.25	41.17	0.045
1.26	41.22	0.045
1.26	41.27	0.045
1.27	41.32	0.045
1.27	41.37	0.045
1.28	41.42	0.045
1.28	41.47	0.045
1.28	41.52	0.045
1.29	41.57	0.046
1.29	41.62	0.046
1.30	41.67	0.046
1.31	41.72	0.046
1.31	41.77	0.046
1.32	41.82	0.046
1.32	41.87	0.046
1.33	41.92	0.046
1.33	41.97	0.046
1.33	42.02	0.046
1.34	42.07	0.046
1.34	42.12	0.046
1.35	42.17	0.046
1.36	42.22	0.046
1.36	42.27	0.046
1.37	42.32	0.046
1.37	42.37	0.046
1.38	42.42	0.046
1.38	42.47	0.046
1.38	42.52	0.046
1.39	42.57	0.046
1.39	42.62	0.046
1.40	42.67	0.046
1.41	42.72	0.046
1.41	42.77	0.046
1.42	42.82	0.046
1.42	42.87	0.046
1.43	42.92	0.046
1.43	42.97	0.046
1.43	43.02	0.046
1.44	43.07	0.047
1.44	43.12	0.047
1.45	43.17	0.047
1.46	43.22	0.047
1.46	43.27	0.047
1.47	43.32	0.047
1.47	43.37	0.047
1.48	43.42	0.047
1.48	43.47	0.047
1.48	43.52	0.047
1.49	43.57	0.047
1.49	43.62	0.047
1.50	43.67	0.047
1.51	43.72	0.047
1.51	43.77	0.047
1.52	43.82	0.047
1.52	43.87	0.047
1.53	43.92	0.047
1.53	43.97	0.047
1.53	44.02	0.047
1.54	44.07	0.047
1.54	44.12	0.047
1.55	44.17	0.047
1.56	44.22	0.047
1.56	44.27	0.047
1.57	44.32	0.047
1.57	44.37	0.047
1.58	44.42	0.047
1.58	44.47	0.047
1.58	44.52	0.047
1.59	44.57	0.047
1.59	44.62	0.047
1.60	44.67	0.047
1.61	44.72	0.047
1.61	44.77	0.047
1.62	44.82	0.047
1.62	44.87	0.047
1.63	44.92	0.047
1.63	44.97	0.047
1.63	45.02	0.047
1.64	45.07	0.047
1.64	45.12	0.047
1.65	45.17	0.047
1.66	45.22	0.048
1.66	45.27	0.048
1.67	45.32	0.048
1.67	45.37	0.047
1.68	45.42	0.047
1.68	45.47	0.048
1.68	45.52	0.048
1.69	45.57	0.048
1.69	45.62	0.048
1.70	45.67	0.048
1.71	45.72	0.048
1.71	45.77	0.048
1.72	45.82	0.048
1.72	45.87	0.048
1.73	45.92	0.048
1.73	45.97	0.048
1.73	46.02	0.048
1.74	46.07	0.048
1.74	46.12	0.048
1.75	46.17	0.048
1.76	46.22	0.048
1.76	46.27	0.048
1.77	46.32	0.048
1.77	46.37	0.048
1.78	46.42	0.048
1.78	46.47	0.048
1.78	46.52	0.048
1.79	46.57	0.048
1.79	46.62	0.048
1.80	46.67	0.048
1.81	46.72	0.048
1.81	46.77	0.048
1.82	46.82	0.048
1.82	46.87	0.048
1.83	46.92	0.048
1.83	46.97	0.048
1.83	47.02	0.048
1.84	47.07	0.048
1.84	47.12	0.048
1.85	47.17	0.048
1.86	47.22	0.048
1.86	47.27	0.048
1.87	47.32	0.048
1.87	47.37	0.048
1.88	47.42	0.048
1.88	47.47	0.048
1.88	47.52	0.048
1.89	47.57	0.048
1.89	47.62	0.048
1.90	47.67	0.048
1.91	47.72	0.048
1.91	47.77	0.048
1.92	47.82	0.048
1.92	47.87	0.048
1.93	47.92	0.048
1.93	47.97	0.048
1.93	48.02	0.048
1.94	48.07	0.048
1.94	48.12	0.048
1.95	48.17	0.048
1.96	48.22	0.048
1.96	48.27	0.048
1.97	48.32	0.048
1.97	48.37	0.048
1.98	48.42	0.048
1.98	48.47	0.048
1.98	48.52	0.048
1.99	48.57	0.048
1.99	48.62	0.048
2.00	48.67	0.048
2.01	48.72	0.048
2.01	48.77	0.048
2.02	48.82	0.048
2.02	48.87	0.048
2.03	48.92	0.048
2.03	48.97	0.048
2.03	49.02	0.048
2.04	49.07	0.048
2.04	49.12	0.048
2.05	49.17	0.048
2.06	49.22	0.048
2.06	49.27	0.048
2.07	49.32	0.048
2.07	49.37	0.048
2.08	49.42	0.048
2.08	49.47	0.048
2.08	49.52	0.048
2.09	49.57	0.048
2.09	49.62	0.048
2.10	49.67	0.048
2.11	49.72	0.048
2.11	49.77	0.048
2.12	49.82	0.048
2.12	49.87	0.048
2.13	49.92	0.049
2.13	49.97	0.049
2.14	50.02	0.049
2.14	50.07	0.048
2.14	50.12	0.048
2.15	50.17	0.048
2.16	50.22	0.048
2.16	50.27	0.049
2.16	50.32	0.049
2.17	50.37	0.048
2.18	50.42	0.048
2.18	50.47	0.048
2.19	50.52	0.049
2.19	50.57	0.049
2.19	50.62	0.049
2.20	50.67	0.049
2.21	50.72	0.049
2.21	50.77	0.049
2.21	50.82	0.049
2.22	50.87	0.049
2.23	50.92	0.049
2.23	50.97	0.049
2.24	51.02	0.049
2.24	51.07	0.049
2.24	51.12	0.049
2.25	51.17	0.049
2.26	51.22	0.049
2.26	51.27	0.049
2.26	51.32	0.049
2.27	51.37	0.049
2.28	51.42	0.049
2.28	51.47	0.049
2.29	51.52	0.049
2.29	51.57	0.049
2.29	51.62	0.049
2.30	51.67	0.049
2.31	51.72	0.049
2.31	51.77	0.049
2.31	51.82	0.049
2.32	51.87	0.049
2.33	51.92	0.049
2.33	51.97	0.049
2.34	52.02	0.049
2.34	52.07	0.049
2.34	52.12	0.049
2.35	52.17	0.049
2.36	52.22	0.049
2.36	52.28	0.049
2.36	52.32	0.049
2.37	52.37	0.049
2.38	52.42	0.049
2.38	52.47	0.049
2.39	52.52	0.049
2.39	52.57	0.049
2.39	52.63	0.049
2.40	52.68	0.050
2.41	52.72	0.050
2.41	52.77	0.050
2.41	52.83	0.050
2.42	52.87	0.050
2.43	52.92	0.050
2.43	52.97	0.050
2.44	53.02	0.050
2.44	53.07	0.050
2.44	53.13	0.050
2.45	53.18	0.050
2.46	53.22	0.050
2.46	53.27	0.050
2.46	53.33	0.050
2.47	53.38	0.050
2.48	53.43	0.050
2.48	53.48	0.050
2.49	53.52	0.050
2.49	53.58	0.050
2.49	53.62	0.050
2.50	53.68	0.050
2.51	53.73	0.050
2.51	53.78	0.050
2.51	53.83	0.050
2.52	53.88	0.050
2.53	53.93	0.050
2.53	53.98	0.050
2.54	54.03	0.050
2.54	54.08	0.050
2.54	54.13	0.050
2.55	54.18	0.050
2.56	54.23	0.050
2.56	54.28	0.050
2.56	54.33	0.050
2.57	54.38	0.050
2.58	54.42	0.050
2.58	54.48	0.050
2.59	54.53	0.050
2.59	54.58	0.050
2.59	54.63	0.050
2.60	54.68	0.050
2.61	54.73	0.050
2.61	54.78	0.051
2.61	54.83	0.051
2.62	54.88	0.051
2.63	54.93	0.051
2.63	54.98	0.051
2.64	55.03	0.051
2.64	55.08	0.051
2.64	55.13	0.051
2.65	55.18	0.051
2.66	55.23	0.051
2.66	55.28	0.051
2.66	55.33	0.051
2.67	55.38	0.051
2.68	55.43	0.051
2.68	55.48	0.051
2.69	55.53	0.051
2.69	55.58	0.051
2.69	55.63	0.051
2.70	55.68	0.051
2.71	55.73	0.051
2.71	55.78	0.051
2.71	55.83	0.051
2.72	55.88	0.051
2.73	55.93	0.051
2.73	55.98	0.051
2.74	56.03	0.051
2.74	56.08	0.051
2.74	56.13	0.052
2.75	56.18	0.052
2.76	56.23	0.052
2.76	56.28	0.052
2.76	56.33	0.052
2.77	56.38	0.052
2.78	56.43	0.052
2.78	56.48	0.052
2.79	56.53	0.052
2.79	56.58	0.052
2.79	56.63	0.052
2.80	56.68	0.052
2.81	56.73	0.052
2.81	56.78	0.052
2.81	56.83	0.052
2.82	56.88	0.052
2.83	56.93	0.052
2.83	56.98	0.052
2.84	57.03	0.052
2.84	57.08	0.053
2.84	57.13	0.053
2.85	57.18	0.053
2.86	57.23	0.053
2.86	57.28	0.053
2.86	57.33	0.053
2.87	57.38	0.053
2.88	57.43	0.053
2.88	57.48	0.053
2.89	57.53	0.053
2.89	57.58	0.053
2.89	57.63	0.053
2.90	57.68	0.053
2.91	57.73	0.053
2.91	57.78	0.053
2.91	57.83	0.053
2.92	57.88	0.054
2.93	57.93	0.054
2.93	57.98	0.054
2.94	58.03	0.054
2.94	58.08	0.054
2.94	58.13	0.054
2.95	58.18	0.054
2.96	58.23	0.054
2.96	58.28	0.054
2.96	58.33	0.054
2.97	58.38	0.054
2.98	58.43	0.055
2.98	58.48	0.055
2.99	58.53	0.055
2.99	58.58	0.055
2.99	58.63	0.055
3.00	58.68	0.055
3.01	58.73	0.055
3.01	58.78	0.055
3.01	58.83	0.055
3.02	58.88	0.055
3.03	58.93	0.055
3.03	58.98	0.055
3.04	59.03	0.056
3.04	59.08	0.056
3.04	59.13	0.056
3.05	59.18	0.056
3.06	59.23	0.056
3.06	59.28	0.056
3.06	59.33	0.056
3.07	59.38	0.056
3.08	59.43	0.056
3.08	59.48	0.057
3.09	59.53	0.057
3.09	59.58	0.057
3.09	59.63	0.057
3.10	59.68	0.057
3.11	59.73	0.057
3.11	59.78	0.057
3.11	59.83	0.057
3.12	59.88	0.058
3.13	59.93	0.058
3.13	59.98	0.058
3.14	60.03	0.058
3.14	60.08	0.058
3.14	60.13	0.058
3.15	60.18	0.058
3.16	60.23	0.059
3.16	60.28	0.059
3.16	60.33	0.059
3.17	60.38	0.059
3.18	60.43	0.059
3.18	60.48	0.059
3.19	60.53	0.060
3.19	60.58	0.060
3.19	60.63	0.060
3.20	60.68	0.060
3.21	60.73	0.060
3.21	60.78	0.061
3.21	60.83	0.061
3.22	60.88	0.061
3.23	60.93	0.062
3.23	60.98	0.062
3.24	61.03	0.062
3.24	61.08	0.062
3.24	61.13	0.063
3.25	61.18	0.063
3.26	61.23	0.063
3.26	61.28	0.063
3.26	61.33	0.064
3.27	61.38	0.064
3.28	61.43	0.064
3.28	61.48	0.065
3.29	61.53	0.065
3.29	61.58	0.066
3.29	61.63	0.066
3.30	61.68	0.066
3.31	61.73	0.067
3.31	61.78	0.067
3.31	61.83	0.068
3.32	61.88	0.069
3.33	61.93	0.069
3.33	61.98	0.070
3.34	62.03	0.071
3.34	62.08	0.072
3.34	62.13	0.073
3.35	62.18	0.074
3.36	62.23	0.074
3.36	62.28	0.075
3.36	62.33	0.076
3.37	62.38	0.077
3.38	62.43	0.079
3.38	62.48	0.080
3.39	62.53	0.081
3.39	62.58	0.083
3.39	62.63	0.086
3.40	62.68	0.088
3.41	62.73	0.090
3.41	62.78	0.091
3.41	62.83	0.092
3.42	62.88	0.095
3.43	62.93	0.100
3.43	62.98	0.103
3.44	63.03	0.104
3.44	63.08	0.106
3.44	63.13	0.108
3.45	63.18	0.110
3.46	63.23	0.113
3.46	63.28	0.118
3.46	63.33	0.124
3.47	63.38	0.128
3.48	63.43	0.133
3.48	63.47	0.135
3.49	63.52	0.136
3.49	63.58	0.139
3.49	63.62	0.144
3.50	63.67	0.151
3.51	63.72	0.158
3.51	63.77	0.162
3.51	63.82	0.166
3.52	63.87	0.170
3.53	63.92	0.179
3.53	63.97	0.189
3.54	64.02	0.195
3.54	64.07	0.199
3.54	64.12	0.204
3.55	64.17	0.216
3.56	64.22	0.228
3.56	64.27	0.236
3.56	64.32	0.242
3.57	64.37	0.251
3.58	64.42	0.265
3.58	64.47	0.278
3.59	64.51	0.288
3.59	64.56	0.297
3.59	64.61	0.308
3.60	64.66	0.325
3.61	64.71	0.339
3.61	64.76	0.356
3.61	64.81	0.375
3.62	64.85	0.391
3.63	64.90	0.410
3.63	64.95	0.431
3.64	65.00	0.452
3.64	65.05	0.476
3.64	65.10	0.501
3.65	65.14	0.524
3.66	65.19	0.550
3.66	65.24	0.581
3.66	65.29	0.614
3.67	65.33	0.643
3.68	65.38	0.677
3.68	65.43	0.714
3.69	65.47	0.751
3.69	65.52	0.789
3.69	65.56	0.831
3.70	65.61	0.875
3.71	65.66	0.919
3.71	65.70	0.967
3.71	65.75	1.020
3.72	65.79	1.073
3.73	65.84	1.127
3.73	65.88	1.184
3.74	65.93	1.242
3.74	65.97	1.298
3.74	66.01	1.352
3.75	66.06	1.410
3.76	66.10	1.466
3.76	66.15	1.526
3.76	66.19	1.589
3.77	66.23	1.651
3.78	66.27	1.711
3.78	66.32	1.767
3.79	66.36	1.823
3.79	66.40	1.881
3.79	66.44	1.936
3.80	66.49	1.987
3.81	66.53	2.035
3.81	66.57	2.077
3.81	66.62	2.112
3.82	66.66	2.146
3.83	66.70	2.181
3.83	66.75	2.215
3.84	66.79	2.247
3.84	66.83	2.283
3.84	66.88	2.326
3.85	66.92	2.374
3.86	66.96	2.424
3.86	67.01	2.481
3.86	67.05	2.539
3.87	67.09	2.593
3.88	67.14	2.643
3.88	67.18	2.692
3.89	67.22	2.734
3.89	67.27	2.762
3.89	67.31	2.783
3.90	67.35	2.806
3.91	67.40	2.823
3.91	67.44	2.836
3.91	67.49	2.846
3.92	67.53	2.852
3.93	67.58	2.851
3.93	67.63	2.845
3.94	67.67	2.836
3.94	67.72	2.824
3.94	67.77	2.805
3.95	67.82	2.782
3.96	67.86	2.757
3.96	67.91	2.725
3.96	67.96	2.687
3.97	68.01	2.650
3.98	68.06	2.614
3.98	68.11	2.570
3.99	68.17	2.522
3.99	68.22	2.472
3.99	68.27	2.418
4.00	68.32	2.356
4.01	68.38	2.293
4.01	68.43	2.227
4.01	68.49	2.160
4.02	68.54	2.090
4.03	68.60	2.017
4.03	68.65	1.945
4.04	68.71	1.874
4.04	68.77	1.804
4.04	68.82	1.731
4.05	68.88	1.658
4.06	68.94	1.587
4.06	69.00	1.516
4.06	69.05	1.447
4.07	69.11	1.379
4.08	69.17	1.309
4.08	69.23	1.241
4.09	69.29	1.177
4.09	69.35	1.118
4.09	69.41	1.061
4.10	69.46	1.002
4.11	69.52	0.946
4.11	69.58	0.893
4.11	69.64	0.843
4.12	69.70	0.795
4.13	69.76	0.752
4.13	69.81	0.715
4.14	69.87	0.677
4.14	69.93	0.642
4.14	69.99	0.607
4.15	70.04	0.581
4.16	70.10	0.553
4.16	70.16	0.528
4.16	70.21	0.503
4.17	70.27	0.482
4.18	70.32	0.459
4.18	70.38	0.441
4.19	70.43	0.425
4.19	70.49	0.409
4.19	70.54	0.390
4.20	70.60	0.373
4.21	70.65	0.361
4.21	70.71	0.348
4.21	70.76	0.335
4.22	70.81	0.325
4.23	70.87	0.314
4.23	70.92	0.304
4.24	70.98	0.294
4.24	71.03	0.286
4.24	71.08	0.276
4.25	71.13	0.268
4.26	71.19	0.261
4.26	71.24	0.252
4.26	71.29	0.245
4.27	71.34	0.239
4.28	71.40	0.233
4.28	71.45	0.226
4.29	71.50	0.220
4.29	71.55	0.214
4.30	71.60	0.208
4.30	71.66	0.207
4.30	71.71	0.203
4.31	71.76	0.195
4.31	71.81	0.192
4.32	71.86	0.189
4.33	71.91	0.185
4.33	71.96	0.178
4.34	72.01	0.177
4.34	72.06	0.176
4.35	72.12	0.175
4.35	72.17	0.170
4.35	72.22	0.163
4.36	72.27	0.159
4.36	72.32	0.159
4.37	72.37	0.158
4.38	72.42	0.156
4.38	72.47	0.153
4.39	72.52	0.150
4.39	72.57	0.148
4.40	72.63	0.147
4.40	72.68	0.147
4.40	72.73	0.144
4.41	72.78	0.142
4.41	72.83	0.141
4.42	72.88	0.140
4.43	72.93	0.140
4.43	72.98	0.139
4.44	73.03	0.137
4.44	73.08	0.136
4.45	73.13	0.136
4.45	73.18	0.135
4.45	73.23	0.134
4.46	73.28	0.133
4.46	73.33	0.133
4.47	73.38	0.132
4.48	73.43	0.132
4.48	73.48	0.131
4.49	73.53	0.131
4.49	73.58	0.131
4.50	73.63	0.130
4.50	73.69	0.130
4.50	73.73	0.130
4.51	73.78	0.129
4.51	73.83	0.129
4.52	73.88	0.129
4.53	73.94	0.129
4.53	73.99	0.128
4.54	74.04	0.127
4.54	74.09	0.127
4.55	74.14	0.126
4.55	74.18	0.125
4.55	74.24	0.124
4.56	74.29	0.124
4.56	74.34	0.124
4.57	74.39	0.123
4.58	74.44	0.123
4.58	74.49	0.123
4.59	74.54	0.123
4.59	74.59	0.122
4.60	74.64	0.122
4.60	74.69	0.122
4.60	74.74	0.122
4.61	74.79	0.122
4.61	74.84	0.122
4.62	74.89	0.122
4.63	74.94	0.121
4.63	74.99	0.121
4.64	75.04	0.121
4.64	75.09	0.121
4.65	75.14	0.121
4.65	75.19	0.121
4.65	75.24	0.120
4.66	75.29	0.120
4.66	75.34	0.120
4.67	75.39	0.120
4.68	75.44	0.120
4.68	75.49	0.120
4.69	75.54	0.119
4.69	75.59	0.119
4.70	75.64	0.119
4.70	75.69	0.119
4.70	75.74	0.119
4.71	75.79	0.119
4.71	75.84	0.119
4.72	75.89	0.118
4.73	75.94	0.118
4.73	75.99	0.118
4.74	76.04	0.118
4.74	76.09	0.118
4.75	76.14	0.118
4.75	76.19	0.118
4.75	76.24	0.118
4.76	76.29	0.117
4.76	76.34	0.117
4.77	76.39	0.117
4.78	76.44	0.117
4.78	76.49	0.117
4.79	76.54	0.117
4.79	76.59	0.117
4.80	76.64	0.117
4.80	76.69	0.116
4.80	76.74	0.116
4.81	76.79	0.116
4.81	76.84	0.116
4.82	76.89	0.116
4.83	76.94	0.116
4.83	76.99	0.116
4.84	77.04	0.116
4.84	77.09	0.116
4.85	77.14	0.116
4.85	77.19	0.116
4.85	77.24	0.115
4.86	77.29	0.115
4.86	77.34	0.115
4.87	77.39	0.115
4.88	77.44	0.115
4.88	77.49	0.115
4.89	77.54	0.115
4.89	77.59	0.115
4.90	77.64	0.115
4.90	77.69	0.115
4.90	77.74	0.115
4.91	77.79	0.115
4.91	77.84	0.115
4.92	77.89	0.114
4.93	77.94	0.114
4.93	77.99	0.114
4.94	78.04	0.114
4.94	78.09	0.114
4.95	78.14	0.114
4.95	78.19	0.114
4.95	78.24	0.114
4.96	78.29	0.114
4.96	78.34	0.114
4.97	78.39	0.114
4.98	78.44	0.114
4.98	78.49	0.114
4.99	78.54	0.114
4.99	78.59	0.114
5.00	78.64	0.114
5.00	78.69	0.114
5.00	78.74	0.114
5.01	78.79	0.114
5.01	78.84	0.114
5.02	78.89	0.113
5.03	78.94	0.113
5.03	78.99	0.113
5.04	79.04	0.113
5.04	79.09	0.113
5.05	79.14	0.113
5.05	79.19	0.113
5.05	79.24	0.113
5.06	79.29	0.113
5.06	79.34	0.113
5.07	79.39	0.113
5.08	79.44	0.113
5.08	79.49	0.113
5.09	79.54	0.113
5.09	79.59	0.113
5.10	79.64	0.113
5.10	79.69	0.113
5.10	79.74	0.113
5.11	79.79	0.113
5.11	79.84	0.113
5.12	79.89	0.113
5.13	79.94	0.113
5.13	79.99	0.113
5.14	80.04	0.113
5.14	80.09	0.113
5.15	80.14	0.113
5.15	80.19	0.113
5.15	80.24	0.113
5.16	80.29	0.113
5.16	80.35	0.113
5.17	80.40	0.113
5.18	80.45	0.113
5.18	80.49	0.113
5.19	80.54	0.113
5.19	80.60	0.113
5.20	80.65	0.113
5.20	80.70	0.113
5.20	80.75	0.113
5.21	80.80	0.113
5.21	80.85	0.113
5.22	80.90	0.112
5.23	80.95	0.112
5.23	81.00	0.112
5.24	81.05	0.112
5.24	81.10	0.112
5.25	81.15	0.112
5.25	81.20	0.112
5.25	81.25	0.112
5.26	81.30	0.112
5.26	81.35	0.112
5.27	81.40	0.112
5.28	81.45	0.112
5.28	81.50	0.112
5.29	81.55	0.112
5.29	81.60	0.112
5.30	81.65	0.112
5.30	81.70	0.112
5.30	81.75	0.112
5.31	81.80	0.112
5.31	81.85	0.112
5.32	81.90	0.112
5.33	81.95	0.112
5.33	82.00	0.112
5.34	82.05	0.112
5.34	82.10	0.112
5.35	82.15	0.112
5.35	82.20	0.112
5.35	82.25	0.112
5.36	82.30	0.112
5.36	82.35	0.112
5.37	82.40	0.112
5.38	82.45	0.112
5.38	82.50	0.112
5.39	82.55	0.112
5.39	82.60	0.112
5.40	82.65	0.112
5.40	82.70	0.112
5.40	82.75	0.112
5.41	82.80	0.112
5.41	82.85	0.112
5.42	82.90	0.112
5.43	82.95	0.112
5.43	83.00	0.112
5.44	83.05	0.112
5.44	83.10	0.112
5.45	83.15	0.112
5.45	83.20	0.112
5.45	83.25	0.112
5.46	83.30	0.112
5.46	83.35	0.112
5.47	83.40	0.112
5.48	83.45	0.112
5.48	83.50	0.112
5.49	83.55	0.112
5.49	83.60	0.112
5.50	83.65	0.112
5.50	83.70	0.112
5.50	83.75	0.112
5.51	83.80	0.112
5.51	83.85	0.112
5.52	83.90	0.112
5.53	83.95	0.112
5.53	84.00	0.112
5.54	84.05	0.112
5.54	84.10	0.112
5.55	84.15	0.112
5.55	84.20	0.112
5.55	84.25	0.112
5.56	84.30	0.112
5.56	84.35	0.112
5.57	84.40	0.112
5.58	84.45	0.112
5.58	84.50	0.112
5.59	84.55	0.112
5.59	84.60	0.112
5.60	84.65	0.112
5.60	84.70	0.112
5.60	84.75	0.112
5.61	84.80	0.112
5.61	84.85	0.112
5.62	84.90	0.112
5.63	84.95	0.112
5.63	85.00	0.112
5.64	85.05	0.112
5.64	85.10	0.112
5.65	85.15	0.112
5.65	85.20	0.112
5.65	85.25	0.112
5.66	85.30	0.112
5.66	85.35	0.112
5.67	85.40	0.112
5.68	85.45	0.112
5.68	85.50	0.112
5.69	85.55	0.112
5.69	85.60	0.112
5.70	85.65	0.112
5.70	85.70	0.112
5.70	85.75	0.112
5.71	85.80	0.112
5.71	85.85	0.112
5.72	85.90	0.112
5.73	85.95	0.112
5.73	86.00	0.112
5.74	86.05	0.112
5.74	86.10	0.112
5.75	86.15	0.112
5.75	86.20	0.112
5.75	86.25	0.112
5.76	86.30	0.112
5.76	86.35	0.112
5.77	86.40	0.112
5.78	86.45	0.112
5.78	86.50	0.112
5.79	86.55	0.112
5.79	86.60	0.112
5.80	86.65	0.112
5.80	86.70	0.112
5.80	86.75	0.112
5.81	86.80	0.112
5.81	86.85	0.112
5.82	86.90	0.112
5.83	86.95	0.112
5.83	87.00	0.112
5.84	87.05	0.112
5.84	87.10	0.112
5.85	87.15	0.112
5.85	87.20	0.112
5.85	87.25	0.112
5.86	87.30	0.112
5.86	87.36	0.112
5.87	87.41	0.112
5.88	87.46	0.112
5.88	87.51	0.112
5.89	87.56	0.112
5.89	87.60	0.112
5.90	87.65	0.112
5.90	87.70	0.112
5.90	87.76	0.112
5.91	87.80	0.112
5.91	87.86	0.112
5.92	87.91	0.112
5.93	87.96	0.112
5.93	88.01	0.112
5.94	88.06	0.112
5.94	88.11	0.112
5.95	88.16	0.112
5.95	88.21	0.112
5.95	88.25	0.112
5.96	88.31	0.112
5.96	88.35	0.112
5.97	88.40	0.112
5.98	88.46	0.112
5.98	88.50	0.112
5.99	88.56	0.112
5.99	88.60	0.112
6.00	88.66	0.112
6.00	88.71	0.112
6.00	88.75	0.112
6.01	88.81	0.112
6.01	88.85	0.112
6.02	88.91	0.112
6.03	88.96	0.112
6.03	89.00	0.112
6.04	89.05	0.112
6.04	89.11	0.112
6.05	89.16	0.112
6.05	89.21	0.112
6.05	89.26	0.112
6.06	89.31	0.112
6.06	89.36	0.112
6.07	89.41	0.112
6.08	89.46	0.112
6.08	89.50	0.112
6.09	89.55	0.112
6.09	89.61	0.112
6.10	89.66	0.112
6.10	89.71	0.112
6.10	89.76	0.112
6.11	89.81	0.112
6.11	89.86	0.112
6.12	89.90	0.112
6.13	89.95	0.112
6.13	90.00	0.112
6.14	90.06	0.113
6.14	90.11	0.113
6.15	90.16	0.113
6.15	90.21	0.112
6.15	90.26	0.113
6.16	90.31	0.113
6.16	90.36	0.113
6.17	90.40	0.113
6.18	90.46	0.113
6.18	90.50	0.113
6.19	90.56	0.113
6.19	90.61	0.113
6.20	90.66	0.113
6.20	90.71	0.113
6.20	90.76	0.113
6.21	90.81	0.113
6.21	90.85	0.113
6.22	90.91	0.113
6.23	90.96	0.113
6.23	91.00	0.113
6.24	91.05	0.113
6.24	91.10	0.113
6.25	91.16	0.113
6.25	91.21	0.113
6.25	91.25	0.113
6.26	91.30	0.113
6.26	91.35	0.113
6.27	91.40	0.113
6.28	91.46	0.113
6.28	91.51	0.113
6.29	91.55	0.113
6.29	91.60	0.113
6.30	91.66	0.113
6.30	91.71	0.113
6.30	91.76	0.113
6.31	91.81	0.113
6.31	91.85	0.113
6.32	91.90	0.113
6.33	91.95	0.113
6.33	92.00	0.113
6.34	92.06	0.113
6.34	92.11	0.113
6.35	92.16	0.113
6.35	92.21	0.113
6.35	92.26	0.113
6.36	92.30	0.113
6.36	92.35	0.113
6.37	92.41	0.113
6.38	92.46	0.113
6.38	92.50	0.113
6.39	92.55	0.113
6.39	92.61	0.113
6.40	92.66	0.113
6.40	92.71	0.113
6.40	92.76	0.113
6.41	92.81	0.113
6.41	92.86	0.113
6.42	92.90	0.113
6.43	92.96	0.113
6.43	93.01	0.114
6.44	93.06	0.113
6.44	93.11	0.113
6.45	93.16	0.113
6.45	93.21	0.114
6.45	93.26	0.113
6.46	93.31	0.113
6.46	93.36	0.114
6.47	93.41	0.114
6.48	93.46	0.114
6.48	93.51	0.114
6.49	93.56	0.114
6.49	93.61	0.114
6.50	93.66	0.114
6.50	93.71	0.114
6.50	93.75	0.114
6.51	93.81	0.114
6.51	93.86	0.114
6.52	93.91	0.114
6.53	93.96	0.114
6.53	94.01	0.114
6.54	94.06	0.114
6.54	94.11	0.114
6.55	94.16	0.114
6.55	94.21	0.114
6.55	94.26	0.114
6.56	94.31	0.114
6.56	94.36	0.114
6.57	94.41	0.114
6.58	94.46	0.114
6.58	94.51	0.114
6.59	94.56	0.114
6.59	94.61	0.114
6.60	94.66	0.114
6.60	94.71	0.114
6.60	94.76	0.114
6.61	94.81	0.114
6.61	94.86	0.114
6.62	94.91	0.114
6.63	94.96	0.114
6.63	95.01	0.114
6.64	95.06	0.114
6.64	95.11	0.114
6.65	95.16	0.114
6.65	95.21	0.115
6.65	95.26	0.115
6.66	95.31	0.115
6.66	95.36	0.115
6.67	95.41	0.114
6.68	95.46	0.114
6.68	95.51	0.114
6.69	95.56	0.114
6.69	95.61	0.115
6.70	95.66	0.115
6.70	95.71	0.115
6.70	95.76	0.115
6.71	95.81	0.115
6.71	95.86	0.115
6.72	95.91	0.115
6.73	95.96	0.115
6.73	96.01	0.115
6.74	96.06	0.115
6.74	96.11	0.115
6.75	96.16	0.115
6.75	96.21	0.115
6.75	96.26	0.115
6.76	96.31	0.115
6.76	96.36	0.115
6.77	96.41	0.115
6.78	96.46	0.115
6.78	96.51	0.115
6.79	96.56	0.115
6.79	96.61	0.115
6.80	96.66	0.115
6.80	96.71	0.115
6.80	96.76	0.115
6.81	96.81	0.115
6.81	96.86	0.115
6.82	96.91	0.115
6.83	96.96	0.115
6.83	97.01	0.115
6.84	97.06	0.115
6.84	97.11	0.115
6.85	97.16	0.115
6.85	97.21	0.115
6.85	97.26	0.115
6.86	97.31	0.115
6.86	97.36	0.115
6.87	97.41	0.115
6.88	97.46	0.115
6.88	97.51	0.115
6.89	97.56	0.115
6.89	97.61	0.115
6.90	97.66	0.115
6.90	97.71	0.115
6.90	97.76	0.115
6.91	97.81	0.115
6.91	97.86	0.115
6.92	97.91	0.115
6.93	97.96	0.115
6.93	98.01	0.115
6.94	98.06	0.115
6.94	98.11	0.115
6.95	98.16
6.95	98.21
6.95	98.26
6.96	98.31
6.96	98.36
6.97	98.41
6.98	98.46
6.98	98.51
6.99	98.56
6.99	98.61
7.00
7.00

[step]
Ramp 10.00 °C/min to -30.00 °C
Time	Temperature	Heat Flow (Normalized)
min	°C	W/g
8.00	100.11	-0.096
8.01	100.11	-0.096
8.02	100.11	-0.096
8.03	100.10	-0.096
8.04	100.10	-0.096
8.05	100.09	-0.089
8.06	100.08	-0.051
8.07	100.06	-0.009
8.08	100.04	0.034
8.09	100.01	0.080
8.10	99.97	0.120
8.11	99.92	0.147
8.12	99.87	0.160
8.13	99.81	0.159
8.14	99.74	0.143
8.15	99.67	0.121
8.16	99.60	0.089
8.17	99.53	0.053
8.18	99.45	0.014
8.19	99.38	-0.010
8.20	99.30	-0.039
8.21	99.21	-0.069
8.22	99.13	-0.088
8.23	99.05	-0.106
8.24	98.96	-0.121
8.25	98.87	-0.140
8.26	98.79	-0.148
8.27	98.70	-0.163
8.28	98.61	-0.171
8.29	98.52	-0.191
8.30	98.43	-0.198
8.31	98.33	-0.207
8.32	98.24	-0.214
8.33	98.15	-0.227
8.34	98.05	-0.232
8.35	97.96	-0.238
8.36	97.86	-0.246
8.37	97.77	-0.250
8.38	97.67	-0.256
8.39	97.58	-0.259
8.40	97.48	-0.262
8.41	97.39	-0.265
8.42	97.29	-0.266
8.43	97.19	-0.271
8.44	97.09	-0.273
8.45	97.00	-0.275
8.46	96.90	-0.277
8.47	96.80	-0.278
8.48	96.70	-0.279
8.49	96.61	-0.280
8.50	96.51	-0.281
8.51	96.41	-0.284
8.52	96.31	-0.285
8.53	96.21	-0.285
8.54	96.12	-0.288
8.55	96.02	-0.288
8.56	95.92	-0.289
8.57	95.82	-0.290
8.58	95.72	-0.291
8.59	95.62	-0.291
8.60	95.53	-0.292
8.61	95.43	-0.292
8.62	95.33	-0.292
8.63	95.23	-0.293
8.64	95.13	-0.293
8.65	95.03	-0.293
8.66	94.93	-0.294
8.67	94.83	-0.294
8.68	94.73	-0.294
8.69	94.64	-0.294
8.70	94.54	-0.295
8.71	94.44	-0.295
8.72	94.34	-0.295
8.73	94.24	-0.296
8.74	94.14	-0.296
8.75	94.04	-0.296
8.76	93.94	-0.296
8.77	93.84	-0.296
8.78	93.74	-0.296
8.79	93.65	-0.297
8.80	93.55	-0.297
8.81	93.45	-0.297
8.82	93.35	-0.297
8.83	93.25	-0.297
8.84	93.15	-0.297
8.85	93.05	-0.297
8.86	92.95	-0.297
8.87	92.85	-0.298
8.88	92.75	-0.298
8.89	92.65	-0.298
8.90	92.55	-0.298
8.91	92.45	-0.298
8.92	92.35	-0.298
8.93	92.26	-0.298
8.94	92.16	-0.298
8.95	92.05	-0.298
8.96	91.96	-0.298
8.97	91.86	-0.298
8.98	91.76	-0.298
8.99	91.66	-0.298
9.00	91.56	-0.298
9.01	91.46	-0.298
9.02	91.36	-0.298
9.03	91.26	-0.298
9.04	91.16	-0.298
9.05	91.06	-0.298
9.06	90.96	-0.298
9.07	90.86	-0.298
9.08	90.76	-0.298
9.09	90.66	-0.297
9.10	90.56	-0.297
9.11	90.46	-0.297
9.12	90.36	-0.297
9.13	90.26	-0.297
9.14	90.16	-0.297
9.15	90.06	-0.297
9.16	89.96	-0.297
9.17	89.87	-0.297
9.18	89.76	-0.296
9.19	89.66	-0.296
9.20	89.57	-0.296
9.21	89.47	-0.296
9.22	89.37	-0.296
9.23	89.27	-0.296
9.24	89.17	-0.296
9.25	89.07	-0.296
9.26	88.97	-0.295
9.27	88.87	-0.295
9.28	88.77	-0.295
9.29	88.67	-0.295
9.30	88.57	-0.295
9.31	88.47	-0.295
9.32	88.37	-0.294
9.33	88.27	-0.294
9.34	88.17	-0.294
9.35	88.07	-0.294
9.36	87.97	-0.293
9.37	87.87	-0.293
9.38	87.77	-0.293
9.39	87.67	-0.293
9.40	87.57	-0.293
9.41	87.47	-0.292
9.42	87.37	-0.292
9.43	87.27	-0.292
9.44	87.17	-0.292
9.45	87.07	-0.292
9.46	86.97	-0.291
9.47	86.87	-0.291
9.48	86.77	-0.291
9.49	86.67	-0.291
9.50	86.57	-0.291
9.51	86.47	-0.290
9.52	86.37	-0.290
9.53	86.27	-0.290
9.54	86.17	-0.290
9.55	86.07	-0.290
9.56	85.97	-0.290
9.57	85.87	-0.289
9.58	85.77	-0.289
9.59	85.67	-0.289
9.60	85.58	-0.289
9.61	85.47	-0.288
9.62	85.37	-0.288
9.63	85.28	-0.288
9.64	85.17	-0.288
9.65	85.07	-0.288
9.66	84.97	-0.288
9.67	84.88	-0.287
9.68	84.78	-0.287
9.69	84.68	-0.287
9.70	84.58	-0.287
9.71	84.48	-0.287
9.72	84.38	-0.287
9.73	84.28	-0.286
9.74	84.18	-0.286
9.75	84.08	-0.286
9.76	83.98	-0.286
9.77	83.88	-0.286
9.78	83.78	-0.286
9.79	83.68	-0.286
9.80	83.58	-0.285
9.81	83.48	-0.285
9.82	83.38	-0.285
9.83	83.28	-0.285
9.84	83.18	-0.285
9.85	83.08	-0.285
9.86	82.98	-0.285
9.87	82.88	-0.285
9.88	82.78	-0.284
9.89	82.68	-0.284
9.90	82.58	-0.284
9.91	82.48	-0.284
9.92	82.38	-0.284
9.93	82.28	-0.283
9.94	82.18	-0.283
9.95	82.08	-0.283
9.96	81.98	-0.283
9.97	81.88	-0.283
9.98	81.78	-0.283
9.99	81.68	-0.283
10.00	81.58	-0.283
10.01	81.48	-0.283
10.02	81.38	-0.283
10.03	81.28	-0.283
10.04	81.18	-0.283
10.05	81.08	-0.282
10.06	80.98	-0.282
10.07	80.88	-0.282
10.08	80.78	-0.282
10.09	80.68	-0.282
10.10	80.58	-0.282
10.11	80.48	-0.282
10.12	80.38	-0.281
10.13	80.28	-0.281
10.14	80.18	-0.281
10.15	80.08	-0.281
10.16	79.98	-0.281
10.17	79.88	-0.281
10.18	79.78	-0.280
10.19	79.68	-0.280
10.20	79.58	-0.280
10.21	79.48	-0.279
10.22	79.38	-0.279
10.23	79.28	-0.279
10.24	79.18	-0.279
10.25	79.08	-0.279
10.26	78.98	-0.279
10.27	78.88	-0.279
10.28	78.78	-0.279
10.29	78.68	-0.279
10.30	78.58	-0.279
10.31	78.48	-0.278
10.32	78.38	-0.278
10.33	78.28	-0.278
10.34	78.18	-0.278
10.35	78.08	-0.278
10.36	77.98	-0.277
10.37	77.88	-0.277
10.38	77.78	-0.277
10.39	77.68	-0.277
10.40	77.58	-0.277
10.41	77.48	-0.277
10.42	77.38	-0.277
10.43	77.28	-0.276
10.44	77.18	-0.276
10.45	77.08	-0.276
10.46	76.98	-0.276
10.47	76.88	-0.276
10.48	76.78	-0.275
10.49	76.68	-0.275
10.50	76.58	-0.275
10.51	76.48	-0.275
10.52	76.38	-0.275
10.53	76.29	-0.275
10.54	76.18	-0.275
10.55	76.08	-0.274
10.56	75.98	-0.274
10.57	75.89	-0.274
10.58	75.79	-0.274
10.59	75.69	-0.274
10.60	75.59	-0.274
10.61	75.49	-0.274
10.62	75.39	-0.273
10.63	75.29	-0.273
10.64	75.19	-0.273
10.65	75.09	-0.273
10.66	74.99	-0.273
10.67	74.89	-0.273
10.68	74.79	-0.272
10.69	74.69	-0.272
10.70	74.59	-0.272
10.71	74.49	-0.272
10.72	74.39	-0.272
10.73	74.29	-0.272
10.74	74.19	-0.271
10.75	74.09	-0.271
10.76	73.99	-0.271
10.77	73.89	-0.271
10.78	73.79	-0.271
10.79	73.69	-0.271
10.80	73.59	-0.270
10.81	73.49	-0.270
10.82	73.39	-0.270
10.83	73.29	-0.270
10.84	73.19	-0.270
10.85	73.09	-0.270
10.86	72.99	-0.269
10.87	72.89	-0.269
10.88	72.79	-0.269
10.89	72.69	-0.269
10.90	72.59	-0.269
10.91	72.49	-0.268
10.92	72.39	-0.268
10.93	72.29	-0.268
10.94	72.19	-0.268
10.95	72.09	-0.268
10.96	71.99	-0.267
10.97	71.89	-0.267
10.98	71.79	-0.267
10.99	71.69	-0.267
11.00	71.59	-0.267
11.01	71.49	-0.267
11.02	71.39	-0.266
11.03	71.29	-0.266
11.04	71.19	-0.266
11.05	71.09	-0.266
11.06	70.99	-0.266
11.07	70.89	-0.266
11.08	70.79	-0.265
11.09	70.69	-0.265
11.10	70.59	-0.265
11.11	70.49	-0.265
11.12	70.39	-0.265
11.13	70.29	-0.265
11.14	70.19	-0.265
11.15	70.09	-0.264
11.16	69.99	-0.264
11.17	69.89	-0.264
11.18	69.79	-0.264
11.19	69.69	-0.264
11.20	69.59	-0.264
11.21	69.49	-0.263
11.22	69.39	-0.263
11.23	69.29	-0.263
11.24	69.19	-0.263
11.25	69.09	-0.263
11.26	68.99	-0.263
11.27	68.89	-0.262
11.28	68.79	-0.262
11.29	68.69	-0.262
11.30	68.59	-0.262
11.31	68.49	-0.262
11.32	68.39	-0.261
11.33	68.29	-0.261
11.34	68.19	-0.261
11.35	68.09	-0.261
11.36	67.99	-0.261
11.37	67.89	-0.261
11.38	67.79	-0.260
11.39	67.69	-0.260
11.40	67.59	-0.260
11.41	67.49	-0.260
11.42	67.39	-0.260
11.43	67.29	-0.259
11.44	67.19	-0.259
11.45	67.09	-0.259
11.46	66.99	-0.259
11.47	66.89	-0.259
11.48	66.79	-0.259
11.49	66.69	-0.259
11.50	66.59	-0.258
11.51	66.49	-0.258
11.52	66.39	-0.258
11.53	66.29	-0.258
11.54	66.19	-0.258
11.55	66.09	-0.258
11.56	65.99	-0.258
11.57	65.89	-0.257
11.58	65.79	-0.257
11.59	65.69	-0.257
11.60	65.59	-0.257
11.61	65.49	-0.257
11.62	65.39	-0.257
11.63	65.29	-0.257
11.64	65.19	-0.256
11.65	65.09	-0.256
11.66	64.99	-0.256
11.67	64.89	-0.256
11.68	64.79	-0.256
11.69	64.69	-0.256
11.70	64.60	-0.256
11.71	64.49	-0.255
11.72	64.39	-0.255
11.73	64.30	-0.255
11.74	64.20	-0.255
11.75	64.09	-0.255
11.76	64.00	-0.255
11.77	63.90	-0.254
11.78	63.80	-0.254
11.79	63.70	-0.254
11.80	63.59	-0.254
11.81	63.50	-0.254
11.82	63.40	-0.254
11.83	63.30	-0.254
11.84	63.20	-0.253
11.85	63.10	-0.253
11.86	63.00	-0.253
11.87	62.90	-0.253
11.88	62.80	-0.253
11.89	62.70	-0.253
11.90	62.60	-0.253
11.91	62.50	-0.252
11.92	62.40	-0.252
11.93	62.30	-0.252
11.94	62.20	-0.252
11.95	62.10	-0.252
11.96	62.00	-0.252
11.97	61.90	-0.252
11.98	61.80	-0.251
11.99	61.70	-0.251
12.00	61.60	-0.251
12.01	61.50	-0.251
12.02	61.40	-0.251
12.03	61.30	-0.251
12.04	61.20	-0.251
12.05	61.10	-0.251
12.06	61.00	-0.250
12.07	60.90	-0.250
12.08	60.80	-0.250
12.09	60.70	-0.250
12.10	60.60	-0.250
12.11	60.50	-0.250
12.12	60.40	-0.250
12.13	60.30	-0.249
12.14	60.20	-0.249
12.15	60.10	-0.249
12.16	60.00	-0.249
12.17	59.90	-0.249
12.18	59.80	-0.249
12.19	59.70	-0.249
12.20	59.60	-0.249
12.21	59.50	-0.249
12.22	59.40	-0.248
12.23	59.30	-0.248
12.24	59.20	-0.248
12.25	59.10	-0.248
12.26	59.00	-0.248
12.27	58.90	-0.248
12.28	58.80	-0.247
12.29	58.70	-0.247
12.30	58.60	-0.247
12.31	58.50	-0.247
12.32	58.40	-0.247
12.33	58.30	-0.246
12.34	58.20	-0.246
12.35	58.10	-0.246
12.36	58.00	-0.246
12.37	57.90	-0.246
12.38	57.80	-0.246
12.39	57.70	-0.246
12.40	57.60	-0.245
12.41	57.50	-0.245
12.42	57.40	-0.245
12.43	57.30	-0.245
12.44	57.20	-0.245
12.45	57.10	-0.245
12.46	57.00	-0.244
12.47	56.90	-0.244
12.48	56.80	-0.244
12.49	56.70	-0.244
12.50	56.60	-0.244
12.51	56.50	-0.244
12.52	56.40	-0.243
12.53	56.30	-0.243
12.54	56.20	-0.243
12.55	56.10	-0.243
12.56	56.00	-0.243
12.57	55.90	-0.243
12.58	55.80	-0.243
12.59	55.70	-0.243
12.60	55.60	-0.242
12.61	55.50	-0.242
12.62	55.40	-0.242
12.63	55.30	-0.242
12.64	55.20	-0.242
12.65	55.10	-0.242
12.66	55.00	-0.241
12.67	54.90	-0.241
12.68	54.80	-0.241
12.69	54.70	-0.241
12.70	54.60	-0.241
12.71	54.50	-0.241
12.72	54.40	-0.241
12.73	54.30	-0.241
12.74	54.20	-0.240
12.75	54.10	-0.240
12.76	54.00	-0.240
12.77	53.90	-0.240
12.78	53.80	-0.240
12.79	53.70	-0.240
12.80	53.60	-0.240
12.81	53.50	-0.239
12.82	53.40	-0.239
12.83	53.30	-0.239
12.84	53.20	-0.239
12.85	53.10	-0.239
12.86	53.00	-0.238
12.87	52.91	-0.238
12.88	52.80	-0.238
12.89	52.70	-0.238
12.90	52.60	-0.238
12.91	52.50	-0.238
12.92	52.41	-0.238
12.93	52.30	-0.237
12.94	52.20	-0.237
12.95	52.10	-0.237
12.96	52.00	-0.237
12.97	51.91	-0.237
12.98	51.80	-0.237
12.99	51.70	-0.237
13.00	51.60	-0.236
13.01	51.50	-0.236
13.02	51.41	-0.236
13.03	51.30	-0.236
13.04	51.20	-0.236
13.05	51.10	-0.236
13.06	51.01	-0.236
13.07	50.91	-0.236
13.08	50.81	-0.235
13.09	50.71	-0.235
13.10	50.61	-0.235
13.11	50.51	-0.235
13.12	50.41	-0.235
13.13	50.31	-0.235
13.14	50.21	-0.234
13.15	50.11	-0.234
13.16	50.01	-0.234
13.17	49.91	-0.234
13.18	49.81	-0.234
13.19	49.71	-0.234
13.20	49.61	-0.233
13.21	49.51	-0.233
13.22	49.41	-0.233
13.23	49.31	-0.233
13.24	49.21	-0.233
13.25	49.11	-0.233
13.26	49.01	-0.233
13.27	48.91	-0.233
13.28	48.81	-0.233
13.29	48.71	-0.233
13.30	48.61	-0.233
13.31	48.51	-0.232
13.32	48.41	-0.232
13.33	48.31	-0.232
13.34	48.21	-0.232
13.35	48.11	-0.232
13.36	48.01	-0.232
13.37	47.91	-0.231
13.38	47.81	-0.231
13.39	47.71	-0.231
13.40	47.61	-0.231
13.41	47.51	-0.231
13.42	47.41	-0.231
13.43	47.31	-0.231
13.44	47.21	-0.230
13.45	47.11	-0.230
13.46	47.01	-0.230
13.47	46.91	-0.230
13.48	46.81	-0.230
13.49	46.71	-0.230
13.50	46.61	-0.230
13.51	46.51	-0.230
13.52	46.41	-0.229
13.53	46.31	-0.229
13.54	46.21	-0.229
13.55	46.11	-0.229
13.56	46.01	-0.229
13.57	45.91	-0.229
13.58	45.81	-0.229
13.59	45.71	-0.228
13.60	45.61	-0.228
13.61	45.51	-0.228
13.62	45.41	-0.228
13.63	45.31	-0.228
13.64	45.21	-0.228
13.65	45.11	-0.227
13.66	45.01	-0.227
13.67	44.91	-0.227
13.68	44.81	-0.227
13.69	44.71	-0.227
13.70	44.61	-0.227
13.71	44.51	-0.226
13.72	44.41	-0.226
13.73	44.31	-0.226
13.74	44.21	-0.226
13.75	44.11	-0.226
13.76	44.01	-0.226
13.77	43.91	-0.226
13.78	43.81	-0.225
13.79	43.71	-0.225
13.80	43.61	-0.225
13.81	43.51	-0.225
13.82	43.41	-0.225
13.83	43.31	-0.225
13.84	43.21	-0.225
13.85	43.11	-0.224
[...]
26.65	14.96	0.103	0.217
26.66	15.06	0.103	0.217
26.67	15.16	0.103	0.217
26.68	15.26	0.103	0.216
26.69	15.36	0.103	0.216
26.70	15.46	0.103	0.216
26.71	15.56	0.103	0.216
26.72	15.66	0.103	0.216
26.73	15.76	0.103	0.216
26.74	15.86	0.103	0.216
26.75	15.96	0.103	0.216
26.76	16.06	0.103	0.216
26.77	16.16	0.103	0.216
26.78	16.26	0.103	0.216
26.79	16.36	0.103	0.216
26.80	16.46	0.103	0.216
26.81	16.56	0.103	0.216
26.82	16.66	0.103	0.216
26.83	16.76	0.103	0.216
26.84	16.86	0.103	0.216
26.85	16.96	0.103	0.216
26.86	17.06	0.103	0.216
26.87	17.16	0.103	0.216
26.88	17.26	0.103	0.216
26.89	17.36	0.103	0.216
26.90	17.46	0.103	0.216
26.91	17.56	0.103	0.216
26.92	17.66	0.103	0.216
26.93	17.76	0.103	0.216
26.94	17.86	0.103	0.216
26.95	17.96	0.103	0.216
26.96	18.06	0.103	0.215
26.97	18.16	0.103	0.215
26.98	18.26	0.102	0.215
26.99	18.36	0.102	0.215
27.00	18.46	0.102	0.215
27.01	18.56	0.102	0.215
27.02	18.66	0.102	0.215
27.03	18.76	0.102	0.215
27.04	18.86	0.102	0.215
27.05	18.96	0.102	0.215
27.06	19.07	0.102	0.215
27.07	19.16	0.102	0.215
27.08	19.27	0.102	0.215
27.09	19.36	0.102	0.215
27.10	19.46	0.102	0.215
27.11	19.57	0.102	0.215
27.12	19.67	0.102	0.215
27.13	19.77	0.102	0.215
27.14	19.87	0.102	0.215
27.15	19.97	0.102	0.214
27.16	20.07	0.102	0.214
27.17	20.17	0.102	0.214
27.18	20.27	0.102	0.214
27.19	20.37	0.102	0.214
27.20	20.47	0.102	0.215
27.21	20.57	0.102	0.215
27.22	20.67	0.102	0.215
27.23	20.77	0.102	0.215
27.24	20.87	0.102	0.215
27.25	20.97	0.102	0.214
27.26	21.07	0.102	0.214
27.27	21.17	0.102	0.214
27.28	21.27	0.102	0.214
27.29	21.37	0.102	0.214
27.30	21.47	0.102	0.214
27.31	21.57	0.102	0.214
27.32	21.67	0.102	0.214
27.33	21.77	0.102	0.214
27.34	21.87	0.102	0.214
27.35	21.97	0.102	0.214
27.36	22.07	0.102	0.214
27.37	22.17	0.102	0.214
27.38	22.27	0.102	0.214
27.39	22.37	0.102	0.214
27.40	22.47	0.102	0.214
27.41	22.57	0.102	0.214
27.42	22.67	0.102	0.214
27.43	22.77	0.102	0.214
27.44	22.87	0.102	0.214
27.45	22.97	0.102	0.214
27.46	23.07	0.102	0.214
27.47	23.17	0.102	0.214
27.48	23.27	0.102	0.214
27.49	23.37	0.102	0.214
27.50	23.47	0.102	0.213
27.51	23.57	0.102	0.213
27.52	23.67	0.102	0.214
27.53	23.77	0.102	0.214
27.54	23.87	0.102	0.214
27.55	23.97	0.102	0.214
27.56	24.07	0.102	0.213
27.57	24.17	0.102	0.213
27.58	24.27	0.102	0.214
27.59	24.37	0.102	0.214
27.60	24.47	0.102	0.214
27.61	24.57	0.102	0.214
27.62	24.67	0.102	0.214
27.63	24.77	0.102	0.214
27.64	24.87	0.102	0.214
27.65	24.97	0.102	0.214
27.66	25.07	0.102	0.214
27.67	25.17	0.102	0.214
27.68	25.27	0.102	0.214
27.69	25.37	0.102	0.214
27.70	25.47	0.102	0.214
27.71	25.57	0.102	0.214
27.72	25.67	0.102	0.214
27.73	25.77	0.102	0.214
27.74	25.87	0.102	0.214
27.75	25.97	0.102	0.214
27.76	26.07	0.102	0.214
27.77	26.17	0.102	0.214
27.78	26.27	0.102	0.214
27.79	26.37	0.102	0.214
27.80	26.47	0.102	0.214
27.81	26.57	0.102	0.214
27.82	26.67	0.102	0.214
27.83	26.77	0.102	0.214
27.84	26.87	0.102	0.214
27.85	26.97	0.102	0.214
27.86	27.07	0.102	0.214
27.87	27.18	0.102	0.214
27.88	27.27	0.102	0.214
27.89	27.38	0.102	0.214
27.90	27.47	0.102	0.214
27.91	27.57	0.102	0.215
27.92	27.68	0.102	0.215
27.93	27.77	0.102	0.215
27.94	27.88	0.102	0.215
27.95	27.98	0.102	0.215
27.96	28.07	0.102	0.215
27.97	28.18	0.102	0.215
27.98	28.28	0.102	0.215
27.99	28.38	0.103	0.215
28.00	28.48	0.103	0.215
28.01	28.58	0.103	0.216
28.02	28.68	0.103	0.216
28.03	28.78	0.103	0.216
28.04	28.88	0.103	0.216
28.05	28.98	0.103	0.216
28.06	29.08	0.103	0.216
28.07	29.18	0.103	0.216
28.08	29.28	0.103	0.216
28.09	29.38	0.103	0.217
28.10	29.48	0.103	0.217
28.11	29.58	0.103	0.217
28.12	29.68	0.103	0.217
28.13	29.78	0.103	0.217
28.14	29.88	0.103	0.217
28.15	29.98	0.103	0.217
28.16	30.08	0.104	0.217
28.17	30.18	0.104	0.217
28.18	30.28	0.104	0.218
28.19	30.38	0.104	0.218
28.20	30.48	0.104	0.218
28.21	30.58	0.104	0.218
28.22	30.68	0.104	0.218
28.23	30.78	0.104	0.218
28.24	30.88	0.104	0.218
28.25	30.98	0.104	0.218
28.26	31.08	0.104	0.218
28.27	31.18	0.104	0.219
28.28	31.28	0.104	0.219
28.29	31.38	0.104	0.219
28.30	31.48	0.104	0.219
28.31	31.58	0.104	0.219
28.32	31.68	0.104	0.219
28.33	31.78	0.104	0.219
28.34	31.88	0.104	0.219
28.35	31.98	0.105	0.219
28.36	32.08	0.105	0.220
28.37	32.18	0.105	0.220
28.38	32.28	0.105	0.220
28.39	32.38	0.105	0.220
28.40	32.48	0.105	0.220
28.41	32.58	0.105	0.220
28.42	32.68	0.105	0.220
28.43	32.78	0.105	0.220
28.44	32.88	0.105	0.220
28.45	32.98	0.105	0.221
28.46	33.08	0.105	0.221
28.47	33.18	0.105	0.221
28.48	33.28	0.105	0.221
28.49	33.38	0.105	0.221
28.50	33.48	0.105	0.221
28.51	33.58	0.105	0.221
28.52	33.68	0.106	0.222
28.53	33.78	0.106	0.222
28.54	33.88	0.106	0.222
28.55	33.98	0.106	0.222
28.56	34.08	0.106	0.222
28.57	34.18	0.106	0.222
28.58	34.28	0.106	0.222
28.59	34.38	0.106	0.222
28.60	34.48	0.106	0.222
28.61	34.58	0.106	0.222
28.62	34.68	0.106	0.223
28.63	34.78	0.106	0.223
28.64	34.88	0.106	0.223
28.65	34.98	0.106	0.223
28.66	35.08	0.106	0.223
28.67	35.18	0.106	0.223
28.68	35.28	0.106	0.223
28.69	35.38	0.106	0.223
28.70	35.48	0.106	0.223
28.71	35.58	0.107	0.224
28.72	35.68	0.107	0.224
28.73	35.79	0.106	0.224
28.74	35.88	0.107	0.224
28.75	35.98	0.107	0.224
28.76	36.08	0.107	0.224
28.77	36.18	0.107	0.224
28.78	36.28	0.106	0.224
28.79	36.38	0.107	0.224
28.80	36.48	0.107	0.224
28.81	36.58	0.107	0.224
28.82	36.69	0.107	0.224
28.83	36.79	0.107	0.224
28.84	36.88	0.107	0.224
28.85	36.98	0.107	0.225
28.86	37.09	0.107	0.225
28.87	37.19	0.107	0.225
28.88	37.29	0.107	0.225
28.89	37.39	0.107	0.225
28.90	37.49	0.107	0.225
28.91	37.59	0.107	0.225
28.92	37.69	0.107	0.225
28.93	37.79	0.107	0.225
28.94	37.89	0.107	0.225
28.95	37.99	0.107	0.225
28.96	38.09	0.107	0.225
28.97	38.19	0.107	0.226
28.98	38.29	0.107	0.226
28.99	38.39	0.107	0.225
29.00	38.49	0.107	0.226
29.01	38.59	0.108	0.226
29.02	38.69	0.108	0.226
29.03	38.79	0.108	0.226
29.04	38.89	0.108	0.226
29.05	38.99	0.108	0.226
29.06	39.09	0.108	0.227
29.07	39.19	0.108	0.226
29.08	39.29	0.108	0.227
29.09	39.39	0.108	0.227
29.10	39.49	0.108	0.227
29.11	39.59	0.108	0.227
29.12	39.69	0.108	0.227
29.13	39.79	0.108	0.227
29.14	39.89	0.108	0.227
29.15	39.99	0.108	0.227
29.16	40.09	0.108	0.227
29.17	40.19	0.108	0.227
29.18	40.29	0.108	0.227
29.19	40.39	0.108	0.228
29.20	40.49	0.108	0.228
29.21	40.59	0.108	0.228
29.22	40.69	0.109	0.228
29.23	40.79	0.109	0.228
29.24	40.89	0.109	0.228
29.25	40.99	0.109	0.228
29.26	41.09	0.109	0.228
29.27	41.19	0.109	0.228
29.28	41.29	0.109	0.228
29.29	41.39	0.109	0.228
29.30	41.49	0.109	0.228
29.31	41.59	0.109	0.228
29.32	41.69	0.109	0.229
29.33	41.79	0.109	0.229
29.34	41.89	0.109	0.229
29.35	41.99	0.109	0.229
29.36	42.09	0.109	0.229
29.37	42.19	0.109	0.229
29.38	42.29	0.109	0.229
29.39	42.39	0.109	0.229
29.40	42.49	0.109	0.229
29.41	42.59	0.109	0.229
29.42	42.69	0.109	0.229
29.43	42.79	0.109	0.229
29.44	42.89	0.109	0.229
29.45	42.99	0.109	0.229
29.46	43.09	0.109	0.229
29.47	43.19	0.109	0.230
29.48	43.29	0.109	0.230
29.49	43.39	0.109	0.230
29.50	43.49	0.109	0.230
29.51	43.59	0.110	0.230
29.52	43.69	0.110	0.230
29.53	43.79	0.110	0.230
29.54	43.89	0.110	0.230
29.55	43.99	0.110	0.230
29.56	44.09	0.110	0.230
29.57	44.19	0.110	0.230
29.58	44.29	0.110	0.231
29.59	44.39	0.110	0.230
29.60	44.49	0.110	0.230
29.61	44.59	0.110	0.230
29.62	44.69	0.110	0.231
29.63	44.79	0.110	0.230
29.64	44.89	0.110	0.231
29.65	45.00	0.110	0.231
29.66	45.09	0.110	0.231
29.67	45.19	0.110	0.231
29.68	45.30	0.110	0.231
29.69	45.40	0.110	0.231
29.70	45.49	0.110	0.231
29.71	45.60	0.110	0.231
29.72	45.70	0.110	0.231
29.73	45.80	0.110	0.232
29.74	45.90	0.110	0.232
29.75	46.00	0.110	0.232
29.76	46.10	0.110	0.232
29.77	46.20	0.110	0.232
29.78	46.30	0.110	0.232
29.79	46.40	0.110	0.232
29.80	46.50	0.111	0.232
29.81	46.60	0.111	0.232
29.82	46.70	0.110	0.232
29.83	46.80	0.110	0.232
29.84	46.90	0.110	0.232
29.85	47.00	0.110	0.232
29.86	47.10	0.110	0.232
29.87	47.20	0.111	0.232
29.88	47.30	0.111	0.232
29.89	47.40	0.110	0.232
29.90	47.50	0.110	0.232
29.91	47.60	0.111	0.232
29.92	47.70	0.111	0.232
29.93	47.80	0.111	0.232
29.94	47.90	0.111	0.232
29.95	48.00	0.111	0.232
29.96	48.10	0.111	0.232
29.97	48.20	0.111	0.232
29.98	48.30	0.111	0.233
29.99	48.40	0.111	0.232
30.00	48.50	0.111	0.232
30.01	48.60	0.111	0.232
30.02	48.70	0.111	0.232
30.03	48.80	0.111	0.232
30.04	48.90	0.111	0.232
30.05	49.00	0.111	0.232
30.06	49.10	0.111	0.232
30.07	49.20	0.111	0.233
30.08	49.30	0.111	0.233
30.09	49.40	0.111	0.233
30.10	49.50	0.111	0.233
30.11	49.60	0.111	0.233
30.12	49.70	0.111	0.233
30.13	49.80	0.111	0.233
30.14	49.90	0.111	0.233
30.15	50.00	0.111	0.233
30.16	50.10	0.111	0.233
30.17	50.20	0.111	0.233
30.18	50.30	0.111	0.233
30.19	50.40	0.111	0.233
30.20	50.50	0.111	0.233
30.21	50.60	0.111	0.233
30.22	50.70	0.111	0.233
30.23	50.80	0.111	0.233
30.24	50.90	0.111	0.233
30.25	51.00	0.111	0.233
30.26	51.10	0.111	0.233
30.27	51.20	0.111	0.233
30.28	51.30	0.111	0.234
30.29	51.40	0.111	0.234
30.30	51.50	0.111	0.234
30.31	51.60	0.111	0.234
30.32	51.70	0.111	0.234
30.33	51.80	0.111	0.234
30.34	51.90	0.111	0.233
30.35	52.00	0.111	0.233
30.36	52.10	0.111	0.234
30.37	52.20	0.111	0.234
30.38	52.30	0.111	0.234
30.39	52.40	0.111	0.234
30.40	52.50	0.111	0.234
30.41	52.60	0.111	0.234
30.42	52.70	0.111	0.234
30.43	52.80	0.111	0.234
30.44	52.90	0.111	0.234
30.45	53.00	0.111	0.234
30.46	53.10	0.112	0.234
30.47	53.20	0.112	0.234
30.48	53.30	0.112	0.234
30.49	53.40	0.111	0.234
30.50	53.50	0.111	0.234
30.51	53.60	0.112	0.234
30.52	53.70	0.112	0.234
30.53	53.80	0.112	0.234
30.54	53.90	0.112	0.234
30.55	54.01	0.112	0.234
30.56	54.11	0.112	0.235
30.57	54.20	0.112	0.235
30.58	54.31	0.112	0.235
30.59	54.41	0.112	0.235
30.60	54.51	0.112	0.235
30.61	54.61	0.112	0.235
30.62	54.70	0.112	0.235
30.63	54.81	0.112	0.235
30.64	54.91	0.112	0.235
30.65	55.01	0.112	0.235
30.66	55.10	0.112	0.235
30.67	55.21	0.112	0.235
30.68	55.31	0.112	0.235
30.69	55.41	0.112	0.235
30.70	55.51	0.112	0.235
30.71	55.61	0.112	0.235
30.72	55.71	0.112	0.235
30.73	55.81	0.112	0.235
30.74	55.91	0.112	0.236
30.75	56.01	0.112	0.235
30.76	56.11	0.112	0.235
30.77	56.21	0.112	0.236
30.78	56.31	0.112	0.236
30.79	56.41	0.112	0.236
30.80	56.51	0.112	0.236
30.81	56.61	0.112	0.236
30.82	56.71	0.112	0.236
30.83	56.81	0.112	0.236
30.84	56.91	0.112	0.236
30.85	57.01	0.113	0.236
30.86	57.11	0.113	0.236
30.87	57.21	0.113	0.237
30.88	57.31	0.113	0.237
30.89	57.41	0.113	0.237
30.90	57.51	0.113	0.237
30.91	57.61	0.113	0.237
30.92	57.71	0.113	0.237
30.93	57.81	0.113	0.237
30.94	57.91	0.113	0.237
30.95	58.01	0.113	0.237
30.96	58.11	0.113	0.237
30.97	58.21	0.113	0.237
30.98	58.31	0.113	0.237
30.99	58.41	0.113	0.237
31.00	58.51	0.113	0.237
31.01	58.61	0.113	0.237
31.02	58.71	0.113	0.237
31.03	58.81	0.113	0.237
31.04	58.91	0.113	0.237
31.05	59.01	0.113	0.237
31.06	59.11	0.113	0.238
31.07	59.21	0.113	0.237
31.08	59.31	0.113	0.237
31.09	59.41	0.113	0.237
31.10	59.51	0.113	0.237
31.11	59.61	0.113	0.238
31.12	59.71	0.113	0.238
31.13	59.81	0.113	0.238
31.14	59.91	0.113	0.238
31.15	60.01	0.113	0.238
31.16	60.11	0.113	0.238
31.17	60.21	0.113	0.238
31.18	60.31	0.113	0.238
31.19	60.41	0.113	0.238
31.20	60.51	0.113	0.238
31.21	60.61	0.113	0.238
31.22	60.71	0.113	0.238
31.23	60.81	0.113	0.238
31.24	60.91	0.113	0.238
31.25	61.01	0.113	0.238
31.26	61.11	0.113	0.238
31.27	61.21	0.113	0.238
31.28	61.31	0.113	0.238
31.29	61.41	0.113	0.238
31.30	61.51	0.113	0.238
31.31	61.61	0.113	0.238
31.32	61.71	0.113	0.238
31.33	61.81	0.113	0.238
31.34	61.91	0.113	0.238
31.35	62.01	0.113	0.238
31.36	62.11	0.113	0.238
31.37	62.21	0.113	0.238
31.38	62.31	0.113	0.238
31.39	62.41	0.113	0.238
31.40	62.51	0.113	0.238
31.41	62.62	0.113	0.238
31.42	62.71	0.113	0.238
31.43	62.81	0.113	0.238
31.44	62.91	0.113	0.238
31.45	63.02	0.113	0.238
31.46	63.11	0.113	0.238
31.47	63.21	0.113	0.238
31.48	63.31	0.114	0.238
31.49	63.41	0.114	0.239
31.50	63.51	0.114	0.239
31.51	63.61	0.114	0.239
31.52	63.71	0.114	0.239
31.53	63.82	0.114	0.239
31.54	63.91	0.114	0.239
31.55	64.02	0.114	0.239
31.56	64.12	0.114	0.239
31.57	64.22	0.114	0.239
31.58	64.32	0.114	0.239
31.59	64.42	0.114	0.239
31.60	64.52	0.114	0.239
31.61	64.62	0.114	0.239
31.62	64.72	0.114	0.239
31.63	64.82	0.114	0.239
31.64	64.92	0.114	0.239
31.65	65.02	0.114	0.239
31.66	65.12	0.114	0.239
31.67	65.22	0.114	0.239
31.68	65.32	0.114	0.239
31.69	65.42	0.114	0.239
31.70	65.52	0.114	0.240
31.71	65.62	0.114	0.240
31.72	65.72	0.114	0.240
31.73	65.82	0.114	0.240
31.74	65.92	0.114	0.240
31.75	66.02	0.114	0.240
31.76	66.12	0.114	0.240
31.77	66.22	0.115	0.241
31.78	66.32	0.114	0.240
31.79	66.42	0.114	0.240
31.80	66.52	0.115	0.241
31.81	66.62	0.115	0.241
31.82	66.72	0.114	0.240
31.83	66.82	0.114	0.240
31.84	66.92	0.115	0.240
31.85	67.02	0.115	0.241
31.86	67.12	0.115	0.240
31.87	67.22	0.115	0.241
31.88	67.32	0.115	0.241
31.89	67.42	0.115	0.241
31.90	67.52	0.114	0.240
31.91	67.62	0.115	0.241
31.92	67.72	0.115	0.241
31.93	67.82	0.115	0.241
31.94	67.92	0.115	0.241
31.95	68.02	0.115	0.241
31.96	68.12	0.115	0.241
31.97	68.22	0.115	0.241
31.98	68.32	0.115	0.241
31.99	68.42	0.115	0.241
32.00	68.52	0.115	0.241
32.01	68.62	0.115	0.241
32.02	68.72	0.115	0.241
32.03	68.82	0.115	0.241
32.04	68.92	0.115	0.241
32.05	69.02	0.115	0.241
32.06	69.12	0.115	0.241
32.07	69.22	0.115	0.241
32.08	69.32	0.115	0.241
32.09	69.42	0.115	0.241
32.10	69.52	0.115	0.241
32.11	69.62	0.115	0.241
32.12	69.72	0.115	0.241
32.13	69.82	0.115	0.241
32.14	69.92	0.115	0.241
32.15	70.02	0.115	0.241
32.16	70.12	0.115	0.242
32.17	70.22	0.115	0.242
32.18	70.32	0.115	0.241
32.19	70.42	0.115	0.242
32.20	70.52	0.115	0.242
32.21	70.62	0.115	0.242
32.22	70.72	0.115	0.242
32.23	70.82	0.115	0.242
32.24	70.92	0.115	0.242
32.25	71.02	0.115	0.242
32.26	71.12	0.115	0.242
32.27	71.22	0.115	0.242
32.28	71.32	0.115	0.242
32.29	71.42	0.115	0.242
32.30	71.52	0.115	0.242
32.31	71.62	0.115	0.242
32.32	71.72	0.115	0.242
32.33	71.82	0.115	0.242
32.34	71.92	0.115	0.242
32.35	72.02	0.115	0.242
32.36	72.12	0.115	0.242
32.37	72.22	0.115	0.242
32.38	72.32	0.115	0.242
32.39	72.42	0.116	0.243
32.40	72.52	0.115	0.242
32.41	72.63	0.115	0.242
32.42	72.73	0.116	0.243
32.43	72.82	0.116	0.243
32.44	72.93	0.116	0.243
32.45	73.03	0.116	0.243
32.46	73.13	0.116	0.243
32.47	73.23	0.116	0.243
32.48	73.32	0.116	0.243
32.49	73.42	0.116	0.243
32.50	73.53	0.116	0.243
32.51	73.63	0.116	0.243
32.52	73.73	0.116	0.243
32.53	73.83	0.116	0.243
32.54	73.93	0.116	0.243
32.55	74.03	0.116	0.243
32.56	74.13	0.116	0.244
32.57	74.23	0.116	0.244
32.58	74.33	0.116	0.244
32.59	74.43	0.116	0.243
32.60	74.53	0.116	0.244
32.61	74.63	0.116	0.244
32.62	74.73	0.116	0.244
32.63	74.83	0.116	0.244
32.64	74.93	0.116	0.244
32.65	75.03	0.116	0.244
32.66	75.13	0.116	0.244
32.67	75.23	0.116	0.244
32.68	75.33	0.116	0.244
32.69	75.43	0.116	0.244
32.70	75.53	0.116	0.244
32.71	75.63	0.116	0.244
32.72	75.73	0.116	0.244
32.73	75.83	0.116	0.244
32.74	75.93	0.116	0.244
32.75	76.03	0.116	0.244
32.76	76.13	0.116	0.244
32.77	76.23	0.116	0.244
32.78	76.33	0.116	0.244
32.79	76.43	0.116	0.244
32.80	76.53	0.116	0.244
32.81	76.63	0.116	0.244
32.82	76.73	0.116	0.245
32.83	76.83	0.116	0.244
32.84	76.93	0.117	0.245
32.85	77.03	0.117	0.245
32.86	77.13	0.116	0.244
32.87	77.23	0.116	0.245
32.88	77.33	0.117	0.245
32.89	77.43	0.116	0.245
32.90	77.53	0.116	0.245
32.91	77.63	0.117	0.245
32.92	77.73	0.116	0.244
32.93	77.83	0.117	0.245
32.94	77.93	0.117	0.245
32.95	78.03	0.117	0.245
32.96	78.13	0.117	0.245
32.97	78.23	0.117	0.245
32.98	78.33	0.117	0.245
32.99	78.43	0.117	0.245
33.00	78.53	0.117	0.245
33.01	78.63	0.117	0.245
33.02	78.73	0.117	0.245
33.03	78.83	0.117	0.245
33.04	78.93	0.117	0.245
33.05	79.03	0.117	0.245
33.06	79.13	0.117	0.245
33.07	79.23	0.117	0.245
33.08	79.33	0.117	0.245
33.09	79.43	0.117	0.245
33.10	79.53	0.117	0.245
33.11	79.63	0.117	0.245
33.12	79.73	0.117	0.245
33.13	79.83	0.117	0.245
33.14	79.93	0.117	0.245
33.15	80.03	0.117	0.245
33.16	80.13	0.117	0.245
33.17	80.23	0.117	0.245
33.18	80.33	0.117	0.245
33.19	80.43	0.117	0.245
33.20	80.53	0.117	0.245
33.21	80.63	0.117	0.246
33.22	80.73	0.117	0.245
33.23	80.83	0.117	0.246
33.24	80.93	0.117	0.246
33.25	81.03	0.117	0.246
33.26	81.13	0.117	0.245
33.27	81.23	0.117	0.245
33.28	81.33	0.117	0.245
33.29	81.43	0.117	0.245
33.30	81.53	0.117	0.245
33.31	81.63	0.117	0.245
33.32	81.73	0.117	0.245
33.33	81.83	0.117	0.245
33.34	81.93	0.117	0.245
33.35	82.03	0.117	0.245
33.36	82.13	0.117	0.245
33.37	82.24	0.117	0.245
33.38	82.34	0.117	0.245
33.39	82.43	0.117	0.245
33.40	82.53	0.117	0.245
33.41	82.63	0.117	0.245
33.42	82.74	0.117	0.245
33.43	82.84	0.117	0.245
33.44	82.94	0.117	0.245
33.45	83.04	0.117	0.245
33.46	83.14	0.117	0.245
33.47	83.24	0.117	0.245
33.48	83.34	0.117	0.245
33.49	83.44	0.117	0.245
33.50	83.54	0.117	0.245
33.51	83.64	0.117	0.245
33.52	83.74	0.117	0.245
33.53	83.84	0.116	0.245
33.54	83.94	0.116	0.245
33.55	84.04	0.116	0.245
33.56	84.14	0.116	0.244
33.57	84.24	0.116	0.244
33.58	84.34	0.116	0.244
33.59	84.44	0.116	0.244
33.60	84.54	0.116	0.244
33.61	84.64	0.116	0.244
33.62	84.74	0.116	0.244
33.63	84.84	0.116	0.244
33.64	84.94	0.116	0.244
33.65	85.04	0.116	0.244
33.66	85.14	0.116	0.244
33.67	85.24	0.116	0.244
33.68	85.34	0.116	0.244
33.69	85.44	0.116	0.244
33.70	85.54	0.116	0.244
33.71	85.64	0.116	0.244
33.72	85.74	0.116	0.244
33.73	85.84	0.116	0.244
33.74	85.94	0.116	0.244
33.75	86.04	0.116	0.244
33.76	86.14	0.116	0.244
33.77	86.24	0.116	0.244
33.78	86.34	0.116	0.244
33.79	86.44	0.116	0.244
33.80	86.54	0.116	0.244
33.81	86.64	0.116	0.244
33.82	86.74	0.116	0.244
33.83	86.84	0.116	0.244
33.84	86.94	0.116	0.244
33.85	87.04	0.116	0.244
33.86	87.14	0.116	0.244
33.87	87.24	0.116	0.244
33.88	87.34	0.116	0.244
33.89	87.44	0.116	0.244
33.90	87.54	0.116	0.244
33.91	87.64	0.116	0.244
33.92	87.74	0.116	0.244
33.93	87.84	0.116	0.244
33.94	87.94	0.116	0.244
33.95	88.04	0.116	0.244
33.96	88.14	0.116	0.244
33.97	88.24	0.116	0.244
33.98	88.34	0.116	0.244
33.99	88.44	0.116	0.244
34.00	88.54	0.116	0.244
34.01	88.65	0.116	0.244
34.02	88.74	0.116	0.244
34.03	88.85	0.116	0.244
34.04	88.95	0.116	0.244
34.05	89.04	0.116	0.244
34.06	89.15	0.116	0.244
34.07	89.25	0.116	0.244
34.08	89.35	0.116	0.244
34.09	89.45	0.116	0.244
34.10	89.55	0.116	0.244
34.11	89.65	0.116	0.244
34.12	89.75	0.116	0.244
34.13	89.85	0.116	0.244
34.14	89.95	0.116	0.244
34.15	90.05	0.116	0.244
34.16	90.15	0.116	0.244
34.17	90.25	0.117	0.245
34.18	90.35	0.117	0.245
34.19	90.45	0.117	0.245
34.20	90.55	0.117	0.245
34.21	90.65	0.117	0.245
34.22	90.75	0.117	0.245
34.23	90.85	0.117	0.245
34.24	90.95	0.117	0.245
34.25	91.05	0.117	0.245
34.26	91.15	0.117	0.245
34.27	91.25	0.117	0.245
34.28	91.35	0.117	0.245
34.29	91.45	0.117	0.245
34.30	91.55	0.117	0.245
34.31	91.65	0.117	0.245
34.32	91.75	0.117	0.245
34.33	91.85	0.117	0.245
34.34	91.95	0.117	0.246
34.35	92.05	0.117	0.246
34.36	92.15	0.117	0.246
34.37	92.25	0.117	0.246
34.38	92.35	0.117	0.246
34.39	92.45	0.117	0.246
34.40	92.55	0.117	0.246
34.41	92.65	0.117	0.246
34.42	92.75	0.117	0.246
34.43	92.85	0.117	0.246
34.44	92.95	0.117	0.246
34.45	93.05	0.117	0.246
34.46	93.15	0.117	0.246
34.47	93.25	0.117	0.246
34.48	93.35	0.117	0.246
34.49	93.45	0.117	0.246
34.50	93.55	0.117	0.246
34.51	93.65	0.117	0.246
34.52	93.75	0.117	0.246
34.53	93.85	0.117	0.246
34.54	93.95	0.117	0.246
34.55	94.05	0.117	0.246
34.56	94.15	0.117	0.246
34.57	94.25	0.117	0.246
34.58	94.35	0.117	0.246
34.59	94.45	0.117	0.247
34.60	94.55	0.117	0.247
34.61	94.65	0.117	0.247
34.62	94.75	0.117	0.247
34.63	94.85	0.118	0.247
34.64	94.95	0.117	0.247
34.65	95.05	0.117	0.247
34.66	95.15	0.118	0.247
34.67	95.25	0.117	0.247
34.68	95.35	0.118	0.247
34.69	95.45	0.118	0.247
34.70	95.55	0.118	0.247
34.71	95.65	0.118	0.247
34.72	95.75	0.118	0.247
34.73	95.85	0.118	0.247
34.74	95.95	0.118	0.247
34.75	96.05	0.118	0.247
34.76	96.15	0.118	0.247
34.77	96.25	0.118	0.247
34.78	96.35	0.118	0.247
34.79	96.45	0.118	0.247
34.80	96.55	0.118	0.247
34.81	96.65	0.118	0.247
34.82	96.75	0.118	0.247
34.83	96.85	0.118	0.247
34.84	96.95	0.118	0.247
34.85	97.05	0.118	0.247
34.86	97.15	0.118	0.247
34.87	97.25	0.118	0.248
34.88	97.35	0.118	0.247
34.89	97.45	0.118	0.248
34.90	97.55	0.118	0.248
34.91	97.65	0.118	0.248
34.92	97.75	0.118	0.248
34.93	97.85	0.118	0.248
34.94	97.95	0.118	0.248
34.95	98.05
34.96	98.15
34.97	98.25
34.98	98.35
34.99	98.45
35.00