File: DSC/2023_06_26_CBC_Al_herm_SBK.txt
Filename	2023_06_26_CBC_Al_herm_SBK
Instrument name	DSC2A-00468 (192.168.1.100)
Operator	SBK
rundate	6/26/2023
Sample name	2023_06_26_CBC_Al_herm
proceduresegments	Data Off ; Equilibrate 30.00 °C; Data On ; Ramp 5.00 °C/min to -90.00 °C; Data Off ; Isothermal 1.0 min; Data On ; Ramp 5.00 °C/min to 30.00 °C; Data Off ; Isothermal 1.0 min; Data On ; Ramp 5.00 °C/min to -90.00 °C; Data Off ; Isothermal 1.0 min; Data On ; Ramp 5.00 °C/min to 30.00 °C; Data Off ; Isothermal 1.0 min; Data On ; Ramp 5.00 °C/min to -90.00 °C; Data Off ; Isothermal 1.0 min; Data On ; Ramp 5.00 °C/min to 30.00 °C
[File Parameters]
Run date	6/26/2023 10:44:07 AM
Trios version	5.1.1.46572
Original File Name	C:\Users\yargerlab\Desktop\DSC Data\General\2023_06_26_CBC_Al_herm.tri
Current File Name	C:\Users\yargerlab\Desktop\DSC Data\General\2023_06_26_CBC_Al_herm_SBK.tri
[Procedure]
Procedure Name	DSC -90C to 30C at 5 C/min 3 cycles
Sample Name	2023_06_26_CBC_Al_herm
Sample Mass	16.02 mg
Reference Sample Mass	0 mg
Pan Mass	54.55 mg
Pan Number	40
Reference Pan Mass	53.66 mg
Reference Pan Number	46
Pan Type	Aluminum Hermetic
Comments	CBC liquid. New sample. DSC84010 aluminum pan and DSC84011 hermetic aluminum lid.
Project Name	SIlk ASDs
Operator	SBK
Test	Custom
Unload Max Temperature	30
Unload Min Temperature	30
Load Max Temperature	30
Load Min Temperature	30
Stop on Gas Flow Error	Yes
[Signal List]
Signal #1	Time (min)
Signal #2	Temperature (°C)
Signal #3	Heat Flow (mW)
Signal #4	Delta T (µV)
Signal #5	Delta Tzero (µV)
Signal #6	Tzero Temperature (°C)
Signal #7	Cell Purge (mL/min)
Signal #8	Heater Temp (°C)
Signal #9	Power Delivered (W)
Signal #10	Reference Junction Temperature (°C)
Signal #11	Flange Temperature (°C)
Signal #12	Heat Flow Phase (rad)
Signal #13	Total Heat Capacity (J/°C)
Signal #14	Heat Capacity (J/°C)
[Configuration]
Company Name	ASU
Instrument Name	DSC2A-00468
Instrument Type	DSC2500
Serial Number	DSC2A-00468
IP	192.168.1.100
Location of Instrument	MRRC
DisplayType	Unknown
Sample Interval 	0.1 s/pt
Selected Heat Flow	T4P
Exotherm Direction	Down
Cell Serial	DRC2-00792
Lid Type	Standard
Cooler	RCS 90
Leave Cooler on at End of Sequence	On
Gas 2	Nitrogen
Gas Selected	Channel 1
Flow Rate	50 mL/min
Secondary Purge	On
Licensed Heat Flow	Heat Flow T4P
Modulation Licensed	Yes
[Versions]
Common IDD Version	1
Cortex Version	VER 2.10.2.31
Driver	5.0.0.6
GDM Version	1.0.3.3
TouchscreenVersion	1.0.0.16145
FEP Version	1.2.1.21
FEP Bootloader	2.0.0.5
AutoSampler Version	2.1.1.26
Auto Sampler Bootloader	2.0.0.5
FCM Version	1.1.0.3
FCM Bootloader	2.0.0.5
[Experiment Logs]
Experiment Log Entry # 1	Data On set to 0
Experiment Log Entry # 3	Equilibrate Segment 30 (C) Started
Experiment Log Entry # 5	Air Cool is off.
Experiment Log Entry # 7	Data On set to 1
Experiment Log Entry # 9	Ramp Segment 5 C/min to -90 Started
Experiment Log Entry # 11	Data On set to 0
Experiment Log Entry # 13	Isothermal Segment 1 min started
Experiment Log Entry # 15	Data On set to 1
Experiment Log Entry # 17	Ramp Segment 5 C/min to 30 Started
Experiment Log Entry # 19	Data On set to 0
Experiment Log Entry # 21	Isothermal Segment 1 min started
Experiment Log Entry # 23	Data On set to 1
Experiment Log Entry # 25	Ramp Segment 5 C/min to -90 Started
Experiment Log Entry # 27	Data On set to 0
Experiment Log Entry # 29	Isothermal Segment 1 min started
Experiment Log Entry # 31	Data On set to 1
Experiment Log Entry # 33	Ramp Segment 5 C/min to 30 Started
Experiment Log Entry # 35	Data On set to 0
Experiment Log Entry # 37	Isothermal Segment 1 min started
Experiment Log Entry # 39	Data On set to 1
Experiment Log Entry # 41	Ramp Segment 5 C/min to -90 Started
Experiment Log Entry # 43	Data On set to 0
Experiment Log Entry # 45	Isothermal Segment 1 min started
Experiment Log Entry # 47	Data On set to 1
Experiment Log Entry # 49	Ramp Segment 5 C/min to 30 Started
[Method Log]
Method Log Entry # 1	Data Off
Method Log Entry # 2	Equilibrate 30 °C
Method Log Entry # 3	Data On
Method Log Entry # 4	(Ramp 6911) Ramp 5 °C/minute to -90 °C
Method Log Entry # 5	Data Off
Method Log Entry # 6	Isothermal 1 minutes
Method Log Entry # 7	Data On
Method Log Entry # 8	(Ramp 6915) Ramp 5 °C/minute to 30 °C
Method Log Entry # 9	Data Off
Method Log Entry # 10	Isothermal 1 minutes
Method Log Entry # 11	Data On
Method Log Entry # 12	(Ramp 6919) Ramp 5 °C/minute to -90 °C
Method Log Entry # 13	Data Off
Method Log Entry # 14	Isothermal 1 minutes
Method Log Entry # 15	Data On
Method Log Entry # 16	(Ramp 6923) Ramp 5 °C/minute to 30 °C
Method Log Entry # 17	Data Off
Method Log Entry # 18	Isothermal 1 minutes
Method Log Entry # 19	Data On
Method Log Entry # 20	(Ramp 6927) Ramp 5 °C/minute to -90 °C
Method Log Entry # 21	Data Off
Method Log Entry # 22	Isothermal 1 minutes
Method Log Entry # 23	Data On
Method Log Entry # 24	(Ramp 6931) Ramp 5 °C/minute to 30 °C
Cell Serial	DRC2-00792
[T1 Calibration]
Slope	-0.008529666
Offset	9.636258
Initial Temperature	98.23
GUID	f8bfdadc-4977-4fdf-ba6d-0ba9134940c3
[TZero Calibration]
Date Applied	11/29/2022 4:06:13 PM
Description	From -89.059 °C to 396.009 °C at 20.000°C/min
Gas Type	Nitrogen
Pan Type	None
Source Files 1	C:\Users\yargerlab\Desktop\DSC Data\General\TZero_calibration_11_29_22_2nd(2).tri
Source Files 2	C:\Users\yargerlab\Desktop\DSC Data\General\TZero_calibration_11_29_22_2nd(3).tri
Delta T Offset	13.05235
Delta T Slope	-0.007271007
Delta T0 Offset	-13.69128
Delta T0 Slope	0.06063341
[Temperature Calibration]
Date Applied	11/29/2022 7:12:28 PM
Description	From 106.590 °C to 186.590 °C at 10.000°C/min
Gas Type	Nitrogen
Pan Type	Tzero Aluminum Hermetic
Source Files 1	C:\Users\yargerlab\Desktop\DSC Data\General\Indium(6).tri
Measured 1	157.391
Known 1	156.598
[Cell Constant Calibration]
Date Applied	11/29/2022 7:12:29 PM
Description	From 106.590 °C to 186.590 °C at 10.000°C/min
Gas Type	Nitrogen
Pan Type	Tzero Aluminum Hermetic
Source Files 1	C:\Users\yargerlab\Desktop\DSC Data\General\Indium(6).tri
T4P KCell	1.006051
Onset Slope	63.26126 mW/°C
[Direct Cp Calibration]
Date Applied	11/30/2022 11:04:51 AM
Description	From -79.983 °C to 298.409 °C at 10.000°C/min
Gas Type	Nitrogen
Pan Type	Tzero Aluminum Hermetic
Source Files 1	C:\Users\yargerlab\Desktop\DSC Data\General\Sapphire_Heat_Capacity_11_30_22.tri
[Rev Cp Calibration]
Date Applied	11/30/2022 1:58:51 PM
Description	From -79.996 °C to 292.812 °C at 3.000°C/min
Gas Type	Nitrogen
Pan Type	Tzero Aluminum Hermetic
Source Files 1	C:\Users\yargerlab\Desktop\DSC Data\General\Sapphire_MDSC_Calibration_11_30_22.tri
[step]
Ramp 5.00 °C/min to -90.00 °C
Time	Temperature	Heat Flow (Normalized)
min	°C	W/g
0.00	30.07	-0.008
0.02	30.07	-0.008
0.03	30.07	-0.007
0.05	30.07	-0.007
0.07	30.06	-0.006
0.08	30.04	-0.007
0.10	30.02	-0.013
0.12	29.99	-0.022
0.13	29.95	-0.032
0.15	29.90	-0.045
0.17	29.86	-0.056
0.18	29.80	-0.069
0.20	29.75	-0.079
0.22	29.69	-0.088
0.23	29.63	-0.097
0.25	29.57	-0.104
0.27	29.51	-0.110
0.28	29.44	-0.115
0.30	29.37	-0.122
0.32	29.30	-0.126
0.33	29.23	-0.130
0.35	29.16	-0.134
0.37	29.09	-0.138
0.38	29.01	-0.141
0.40	28.94	-0.143
0.42	28.86	-0.146
0.43	28.79	-0.148
0.45	28.71	-0.150
0.47	28.64	-0.152
0.48	28.56	-0.154
0.50	28.48	-0.155
0.52	28.40	-0.156
0.53	28.32	-0.158
0.55	28.24	-0.158
0.57	28.16	-0.159
0.58	28.08	-0.160
0.60	28.00	-0.161
0.62	27.92	-0.161
0.63	27.84	-0.162
0.65	27.76	-0.163
0.67	27.68	-0.163
0.68	27.60	-0.164
0.70	27.52	-0.164
0.72	27.44	-0.164
0.73	27.36	-0.164
0.75	27.27	-0.165
0.77	27.19	-0.165
0.78	27.11	-0.165
0.80	27.03	-0.166
0.82	26.95	-0.166
0.83	26.86	-0.166
0.85	26.78	-0.166
0.87	26.70	-0.166
0.88	26.62	-0.166
0.90	26.53	-0.167
0.92	26.45	-0.167
0.93	26.37	-0.167
0.95	26.29	-0.167
0.97	26.21	-0.167
0.98	26.12	-0.167
1.00	26.04	-0.167
1.02	25.96	-0.167
1.03	25.87	-0.167
1.05	25.79	-0.167
1.07	25.71	-0.168
1.08	25.63	-0.168
1.10	25.54	-0.168
1.12	25.46	-0.168
1.13	25.38	-0.168
1.15	25.30	-0.168
1.17	25.21	-0.168
1.18	25.13	-0.168
1.20	25.05	-0.168
1.22	24.96	-0.168
1.23	24.88	-0.168
1.25	24.80	-0.168
1.27	24.71	-0.168
1.28	24.63	-0.168
1.30	24.55	-0.168
1.32	24.46	-0.168
1.33	24.38	-0.168
1.35	24.30	-0.168
1.37	24.22	-0.168
1.38	24.13	-0.168
1.40	24.05	-0.169
1.42	23.97	-0.169
1.43	23.88	-0.169
1.45	23.80	-0.169
1.47	23.72	-0.169
1.48	23.63	-0.169
1.50	23.55	-0.169
1.52	23.47	-0.169
1.53	23.38	-0.169
1.55	23.30	-0.169
1.57	23.22	-0.169
1.58	23.13	-0.169
1.60	23.05	-0.169
1.62	22.97	-0.169
1.63	22.88	-0.169
1.65	22.80	-0.169
1.67	22.72	-0.169
1.68	22.63	-0.169
1.70	22.55	-0.168
1.72	22.47	-0.168
1.73	22.38	-0.169
1.75	22.30	-0.169
1.77	22.22	-0.169
1.78	22.14	-0.168
1.80	22.05	-0.168
1.82	21.97	-0.168
1.83	21.89	-0.168
1.85	21.80	-0.168
1.87	21.72	-0.168
1.88	21.64	-0.168
1.90	21.55	-0.168
1.92	21.47	-0.168
1.93	21.39	-0.168
1.95	21.30	-0.168
1.97	21.22	-0.168
1.98	21.14	-0.168
2.00	21.05	-0.168
2.02	20.97	-0.168
2.03	20.89	-0.168
2.05	20.80	-0.168
2.07	20.72	-0.168
2.08	20.64	-0.168
2.10	20.55	-0.168
2.12	20.47	-0.168
2.13	20.39	-0.168
2.15	20.30	-0.168
2.17	20.22	-0.168
2.18	20.14	-0.168
2.20	20.05	-0.168
2.22	19.97	-0.168
2.23	19.89	-0.168
2.25	19.80	-0.168
2.27	19.72	-0.168
2.28	19.64	-0.168
2.30	19.55	-0.168
2.32	19.47	-0.168
2.33	19.39	-0.168
2.35	19.30	-0.168
2.37	19.22	-0.168
2.38	19.14	-0.168
2.40	19.05	-0.168
2.42	18.97	-0.168
2.43	18.89	-0.168
2.45	18.80	-0.168
2.47	18.72	-0.168
2.48	18.64	-0.167
2.50	18.55	-0.167
2.52	18.47	-0.167
2.53	18.39	-0.167
2.55	18.30	-0.167
2.57	18.22	-0.167
2.58	18.14	-0.167
2.60	18.05	-0.167
2.62	17.97	-0.167
2.63	17.89	-0.167
2.65	17.80	-0.167
2.67	17.72	-0.167
2.68	17.64	-0.167
2.70	17.55	-0.167
2.72	17.47	-0.167
2.73	17.39	-0.167
2.75	17.30	-0.167
2.77	17.22	-0.167
2.78	17.14	-0.167
2.80	17.06	-0.167
2.82	16.97	-0.167
2.83	16.89	-0.167
2.85	16.80	-0.167
2.87	16.72	-0.167
2.88	16.64	-0.167
2.90	16.55	-0.167
2.92	16.47	-0.167
2.93	16.39	-0.167
2.95	16.30	-0.167
2.97	16.22	-0.167
2.98	16.14	-0.166
3.00	16.05	-0.166
3.02	15.97	-0.166
3.03	15.89	-0.166
3.05	15.80	-0.166
3.07	15.72	-0.166
3.08	15.64	-0.166
3.10	15.56	-0.166
3.12	15.47	-0.166
3.13	15.39	-0.166
3.15	15.31	-0.166
3.17	15.22	-0.166
3.18	15.14	-0.166
3.20	15.06	-0.166
3.22	14.97	-0.166
3.23	14.89	-0.166
3.25	14.81	-0.166
3.27	14.72	-0.166
3.28	14.64	-0.166
3.30	14.55	-0.166
3.32	14.47	-0.166
3.33	14.39	-0.166
3.35	14.31	-0.166
3.37	14.22	-0.166
3.38	14.14	-0.166
3.40	14.06	-0.166
3.42	13.97	-0.166
3.43	13.89	-0.166
3.45	13.80	-0.166
3.47	13.72	-0.166
3.48	13.64	-0.166
3.50	13.56	-0.165
3.52	13.47	-0.165
3.53	13.39	-0.165
3.55	13.31	-0.165
3.57	13.22	-0.165
3.58	13.14	-0.165
3.60	13.06	-0.165
3.62	12.97	-0.165
3.63	12.89	-0.165
3.65	12.81	-0.165
3.67	12.72	-0.165
3.68	12.64	-0.165
3.70	12.56	-0.165
3.72	12.47	-0.165
3.73	12.39	-0.165
3.75	12.30	-0.165
3.77	12.22	-0.165
3.78	12.14	-0.165
3.80	12.06	-0.165
3.82	11.97	-0.165
3.83	11.89	-0.165
3.85	11.81	-0.165
3.87	11.72	-0.165
3.88	11.64	-0.165
3.90	11.56	-0.165
3.92	11.47	-0.165
3.93	11.39	-0.165
3.95	11.31	-0.165
3.97	11.22	-0.165
3.98	11.14	-0.165
4.00	11.06	-0.164
4.02	10.97	-0.164
4.03	10.89	-0.164
4.05	10.81	-0.164
4.07	10.72	-0.164
4.08	10.64	-0.164
4.10	10.56	-0.164
4.12	10.47	-0.164
4.13	10.39	-0.164
4.15	10.31	-0.164
4.17	10.22	-0.164
4.18	10.14	-0.164
4.20	10.06	-0.164
4.22	9.97	-0.164
4.23	9.89	-0.164
4.25	9.81	-0.164
4.27	9.72	-0.164
4.28	9.64	-0.164
4.30	9.56	-0.164
4.32	9.47	-0.164
4.33	9.39	-0.164
4.35	9.31	-0.164
4.37	9.22	-0.164
4.38	9.14	-0.164
4.40	9.06	-0.164
4.42	8.97	-0.164
4.43	8.89	-0.164
4.45	8.81	-0.163
4.47	8.72	-0.163
4.48	8.64	-0.163
4.50	8.56	-0.163
4.52	8.47	-0.163
4.53	8.39	-0.163
4.55	8.31	-0.163
4.57	8.22	-0.163
4.58	8.14	-0.163
4.60	8.06	-0.163
4.62	7.97	-0.163
4.63	7.89	-0.163
4.65	7.81	-0.163
4.67	7.72	-0.163
4.68	7.64	-0.163
4.70	7.56	-0.163
4.72	7.47	-0.163
4.73	7.39	-0.163
4.75	7.31	-0.163
4.77	7.22	-0.163
4.78	7.14	-0.163
4.80	7.06	-0.163
4.82	6.97	-0.163
4.83	6.89	-0.163
4.85	6.81	-0.163
4.87	6.72	-0.163
4.88	6.64	-0.163
4.90	6.56	-0.163
4.92	6.47	-0.163
4.93	6.39	-0.163
4.95	6.31	-0.162
4.97	6.22	-0.162
4.98	6.14	-0.162
5.00	6.06	-0.162
5.02	5.97	-0.162
5.03	5.89	-0.162
5.05	5.81	-0.162
5.07	5.72	-0.162
5.08	5.64	-0.162
5.10	5.56	-0.162
5.12	5.47	-0.162
5.13	5.39	-0.162
5.15	5.31	-0.162
5.17	5.22	-0.162
5.18	5.14	-0.162
5.20	5.06	-0.162
5.22	4.97	-0.162
5.23	4.89	-0.162
5.25	4.81	-0.162
5.27	4.72	-0.162
5.28	4.64	-0.162
5.30	4.56	-0.162
5.32	4.48	-0.162
5.33	4.39	-0.162
5.35	4.31	-0.162
5.37	4.22	-0.162
5.38	4.14	-0.162
5.40	4.06	-0.161
5.42	3.98	-0.161
5.43	3.89	-0.161
5.45	3.81	-0.161
5.47	3.72	-0.161
5.48	3.64	-0.161
5.50	3.56	-0.161
5.52	3.48	-0.161
5.53	3.39	-0.161
5.55	3.31	-0.161
5.57	3.23	-0.161
5.58	3.14	-0.161
5.60	3.06	-0.161
5.62	2.98	-0.161
5.63	2.89	-0.161
5.65	2.81	-0.161
5.67	2.72	-0.161
5.68	2.64	-0.161
5.70	2.56	-0.161
5.72	2.48	-0.161
5.73	2.39	-0.161
5.75	2.31	-0.161
5.77	2.23	-0.161
5.78	2.14	-0.161
5.80	2.06	-0.161
5.82	1.98	-0.161
5.83	1.89	-0.161
5.85	1.81	-0.161
5.87	1.73	-0.161
5.88	1.64	-0.161
5.90	1.56	-0.161
5.92	1.48	-0.161
5.93	1.39	-0.160
5.95	1.31	-0.160
5.97	1.23	-0.160
5.98	1.14	-0.160
6.00	1.06	-0.160
6.02	0.98	-0.160
6.03	0.89	-0.160
6.05	0.81	-0.160
6.07	0.73	-0.160
6.08	0.64	-0.160
6.10	0.56	-0.160
6.12	0.48	-0.160
6.13	0.39	-0.160
6.15	0.31	-0.160
6.17	0.23	-0.160
6.18	0.14	-0.160
6.20	0.06	-0.160
6.22	-0.02	-0.160
6.23	-0.11	-0.160
6.25	-0.19	-0.160
6.27	-0.27	-0.160
6.28	-0.35	-0.160
6.30	-0.44	-0.160
6.32	-0.52	-0.160
6.33	-0.61	-0.160
6.35	-0.69	-0.160
6.37	-0.77	-0.160
6.38	-0.85	-0.160
6.40	-0.94	-0.160
6.42	-1.02	-0.160
6.43	-1.11	-0.160
6.45	-1.19	-0.160
6.47	-1.27	-0.159
6.48	-1.35	-0.159
6.50	-1.44	-0.159
6.52	-1.52	-0.159
6.53	-1.61	-0.159
6.55	-1.69	-0.159
6.57	-1.77	-0.159
6.58	-1.85	-0.159
6.60	-1.94	-0.159
6.62	-2.02	-0.159
6.63	-2.11	-0.159
6.65	-2.19	-0.159
6.67	-2.27	-0.159
6.68	-2.35	-0.159
6.70	-2.44	-0.159
6.72	-2.52	-0.159
6.73	-2.60	-0.159
6.75	-2.69	-0.159
6.77	-2.77	-0.159
6.78	-2.85	-0.159
6.80	-2.94	-0.159
6.82	-3.02	-0.159
6.83	-3.10	-0.159
6.85	-3.19	-0.159
6.87	-3.27	-0.159
6.88	-3.35	-0.159
6.90	-3.44	-0.159
6.92	-3.52	-0.159
6.93	-3.60	-0.159
6.95	-3.69	-0.159
6.97	-3.77	-0.159
6.98	-3.86	-0.159
7.00	-3.94	-0.159
7.02	-4.02	-0.159
7.03	-4.10	-0.159
7.05	-4.19	-0.159
7.07	-4.27	-0.158
7.08	-4.35	-0.158
7.10	-4.44	-0.158
7.12	-4.52	-0.158
7.13	-4.60	-0.158
7.15	-4.69	-0.158
7.17	-4.77	-0.158
7.18	-4.85	-0.158
7.20	-4.94	-0.158
7.22	-5.02	-0.158
7.23	-5.10	-0.158
7.25	-5.19	-0.158
7.27	-5.27	-0.158
7.28	-5.35	-0.158
7.30	-5.44	-0.158
7.32	-5.52	-0.158
7.33	-5.60	-0.158
7.35	-5.69	-0.158
7.37	-5.77	-0.158
7.38	-5.85	-0.158
7.40	-5.93	-0.158
7.42	-6.02	-0.158
7.43	-6.10	-0.158
7.45	-6.19	-0.158
7.47	-6.27	-0.158
7.48	-6.35	-0.158
7.50	-6.44	-0.158
7.52	-6.52	-0.158
7.53	-6.60	-0.158
7.55	-6.69	-0.158
7.57	-6.77	-0.158
7.58	-6.85	-0.158
7.60	-6.94	-0.157
7.62	-7.02	-0.157
7.63	-7.10	-0.157
7.65	-7.18	-0.157
7.67	-7.27	-0.157
7.68	-7.35	-0.157
7.70	-7.43	-0.157
7.72	-7.52	-0.157
7.73	-7.60	-0.157
7.75	-7.68	-0.157
7.77	-7.77	-0.157
7.78	-7.85	-0.157
7.80	-7.93	-0.157
7.82	-8.02	-0.157
7.83	-8.10	-0.157
7.85	-8.18	-0.157
7.87	-8.27	-0.157
7.88	-8.35	-0.157
7.90	-8.43	-0.157
7.92	-8.52	-0.157
7.93	-8.60	-0.157
7.95	-8.68	-0.157
7.97	-8.77	-0.157
7.98	-8.85	-0.157
8.00	-8.93	-0.157
8.02	-9.02	-0.157
8.03	-9.10	-0.157
8.05	-9.18	-0.157
8.07	-9.27	-0.157
8.08	-9.35	-0.157
8.10	-9.43	-0.157
8.12	-9.52	-0.157
8.13	-9.60	-0.157
8.15	-9.68	-0.156
8.17	-9.77	-0.156
8.18	-9.85	-0.156
8.20	-9.93	-0.156
8.22	-10.02	-0.156
8.23	-10.10	-0.156
8.25	-10.18	-0.156
8.27	-10.27	-0.156
8.28	-10.35	-0.156
8.30	-10.43	-0.156
8.32	-10.52	-0.156
8.33	-10.60	-0.156
8.35	-10.68	-0.156
8.37	-10.77	-0.156
8.38	-10.85	-0.156
8.40	-10.93	-0.156
8.42	-11.01	-0.156
8.43	-11.10	-0.156
8.45	-11.18	-0.156
8.47	-11.26	-0.156
8.48	-11.35	-0.156
8.50	-11.43	-0.156
8.52	-11.51	-0.156
8.53	-11.60	-0.156
8.55	-11.68	-0.156
8.57	-11.77	-0.156
8.58	-11.85	-0.156
8.60	-11.93	-0.156
8.62	-12.01	-0.156
8.63	-12.10	-0.156
8.65	-12.18	-0.156
8.67	-12.27	-0.156
8.68	-12.35	-0.156
8.70	-12.43	-0.156
8.72	-12.52	-0.156
8.73	-12.60	-0.156
8.75	-12.68	-0.156
8.77	-12.76	-0.155
8.78	-12.85	-0.155
8.80	-12.93	-0.155
8.82	-13.02	-0.155
8.83	-13.10	-0.155
8.85	-13.18	-0.155
8.87	-13.27	-0.155
8.88	-13.35	-0.155
8.90	-13.43	-0.155
8.92	-13.51	-0.155
8.93	-13.60	-0.155
8.95	-13.68	-0.155
8.97	-13.77	-0.155
8.98	-13.85	-0.155
9.00	-13.93	-0.155
9.02	-14.02	-0.155
9.03	-14.10	-0.155
9.05	-14.18	-0.155
9.07	-14.27	-0.155
9.08	-14.35	-0.155
9.10	-14.43	-0.155
9.12	-14.52	-0.155
9.13	-14.60	-0.155
9.15	-14.68	-0.155
9.17	-14.77	-0.155
9.18	-14.85	-0.155
9.20	-14.93	-0.155
9.22	-15.01	-0.155
9.23	-15.10	-0.155
9.25	-15.18	-0.155
9.27	-15.26	-0.155
9.28	-15.35	-0.155
9.30	-15.43	-0.154
9.32	-15.52	-0.154
9.33	-15.60	-0.154
9.35	-15.68	-0.154
9.37	-15.77	-0.154
9.38	-15.85	-0.154
9.40	-15.93	-0.154
9.42	-16.02	-0.154
9.43	-16.10	-0.154
9.45	-16.18	-0.154
9.47	-16.27	-0.154
9.48	-16.35	-0.154
9.50	-16.43	-0.154
9.52	-16.52	-0.154
9.53	-16.60	-0.154
9.55	-16.68	-0.154
9.57	-16.77	-0.154
9.58	-16.85	-0.154
9.60	-16.93	-0.154
9.62	-17.02	-0.154
9.63	-17.10	-0.154
9.65	-17.18	-0.154
9.67	-17.27	-0.154
9.68	-17.35	-0.154
9.70	-17.43	-0.154
9.72	-17.52	-0.154
9.73	-17.60	-0.154
9.75	-17.68	-0.154
9.77	-17.77	-0.154
9.78	-17.85	-0.154
9.80	-17.93	-0.154
9.82	-18.02	-0.154
9.83	-18.10	-0.154
9.85	-18.19	-0.154
9.87	-18.27	-0.154
9.88	-18.35	-0.154
9.90	-18.43	-0.154
9.92	-18.52	-0.154
9.93	-18.60	-0.154
9.95	-18.69	-0.153
9.97	-18.77	-0.153
9.98	-18.85	-0.153
10.00	-18.94	-0.153
10.02	-19.02	-0.153
10.03	-19.10	-0.153
10.05	-19.18	-0.153
10.07	-19.27	-0.153
10.08	-19.35	-0.153
10.10	-19.44	-0.153
10.12	-19.52	-0.153
10.13	-19.60	-0.153
10.15	-19.69	-0.153
10.17	-19.77	-0.153
10.18	-19.85	-0.153
10.20	-19.94	-0.153
10.22	-20.02	-0.153
10.23	-20.10	-0.153
10.25	-20.19	-0.153
10.27	-20.27	-0.153
10.28	-20.35	-0.153
10.30	-20.44	-0.153
10.32	-20.52	-0.153
10.33	-20.60	-0.153
10.35	-20.69	-0.153
10.37	-20.77	-0.153
10.38	-20.85	-0.153
10.40	-20.94	-0.153
10.42	-21.02	-0.153
10.43	-21.10	-0.153
10.45	-21.19	-0.153
10.47	-21.27	-0.153
10.48	-21.35	-0.153
10.50	-21.44	-0.153
10.52	-21.52	-0.153
10.53	-21.60	-0.153
10.55	-21.69	-0.153
10.57	-21.77	-0.153
10.58	-21.85	-0.152
10.60	-21.94	-0.152
10.62	-22.02	-0.152
10.63	-22.11	-0.152
10.65	-22.19	-0.152
10.67	-22.27	-0.152
10.68	-22.35	-0.152
10.70	-22.44	-0.152
10.72	-22.52	-0.152
10.73	-22.61	-0.152
10.75	-22.69	-0.152
10.77	-22.77	-0.152
10.78	-22.86	-0.152
10.80	-22.94	-0.152
10.82	-23.02	-0.152
10.83	-23.11	-0.152
10.85	-23.19	-0.152
10.87	-23.27	-0.152
10.88	-23.36	-0.152
10.90	-23.44	-0.152
10.92	-23.52	-0.152
10.93	-23.61	-0.152
10.95	-23.69	-0.152
10.97	-23.77	-0.152
10.98	-23.86	-0.152
11.00	-23.94	-0.152
11.02	-24.03	-0.152
11.03	-24.11	-0.152
11.05	-24.19	-0.152
11.07	-24.27	-0.152
11.08	-24.36	-0.151
11.10	-24.44	-0.151
11.12	-24.52	-0.151
11.13	-24.61	-0.151
11.15	-24.69	-0.151
11.17	-24.77	-0.151
11.18	-24.86	-0.151
11.20	-24.94	-0.151
11.22	-25.02	-0.151
11.23	-25.11	-0.151
11.25	-25.19	-0.151
11.27	-25.27	-0.151
11.28	-25.36	-0.151
11.30	-25.44	-0.151
11.32	-25.52	-0.151
11.33	-25.61	-0.151
11.35	-25.69	-0.151
11.37	-25.77	-0.151
11.38	-25.86	-0.151
11.40	-25.94	-0.151
11.42	-26.03	-0.151
11.43	-26.11	-0.151
11.45	-26.19	-0.151
11.47	-26.27	-0.151
11.48	-26.36	-0.151
11.50	-26.44	-0.151
11.52	-26.53	-0.151
11.53	-26.61	-0.151
11.55	-26.69	-0.151
11.57	-26.78	-0.151
11.58	-26.86	-0.151
11.60	-26.94	-0.151
11.62	-27.03	-0.150
11.63	-27.11	-0.150
11.65	-27.19	-0.150
11.67	-27.28	-0.150
11.68	-27.36	-0.150
11.70	-27.44	-0.150
11.72	-27.53	-0.150
11.73	-27.61	-0.150
11.75	-27.69	-0.150
11.77	-27.78	-0.150
11.78	-27.86	-0.150
11.80	-27.94	-0.150
11.82	-28.03	-0.150
11.83	-28.11	-0.150
11.85	-28.19	-0.150
11.87	-28.28	-0.150
11.88	-28.36	-0.150
11.90	-28.44	-0.150
11.92	-28.53	-0.150
11.93	-28.61	-0.150
11.95	-28.69	-0.150
11.97	-28.78	-0.150
11.98	-28.86	-0.150
12.00	-28.94	-0.150
12.02	-29.03	-0.150
12.03	-29.11	-0.150
12.05	-29.19	-0.150
12.07	-29.28	-0.150
12.08	-29.36	-0.150
12.10	-29.44	-0.150
12.12	-29.53	-0.150
12.13	-29.61	-0.149
12.15	-29.69	-0.149
12.17	-29.78	-0.149
12.18	-29.86	-0.149
12.20	-29.94	-0.149
12.22	-30.03	-0.149
12.23	-30.11	-0.149
12.25	-30.19	-0.149
12.27	-30.28	-0.149
12.28	-30.36	-0.149
12.30	-30.44	-0.149
12.32	-30.53	-0.149
12.33	-30.61	-0.149
12.35	-30.69	-0.149
12.37	-30.78	-0.149
12.38	-30.86	-0.149
12.40	-30.94	-0.149
12.42	-31.03	-0.149
12.43	-31.11	-0.149
12.45	-31.19	-0.149
12.47	-31.28	-0.149
12.48	-31.36	-0.149
12.50	-31.44	-0.149
12.52	-31.53	-0.149
12.53	-31.61	-0.149
12.55	-31.69	-0.149
12.57	-31.78	-0.149
12.58	-31.86	-0.149
12.60	-31.95	-0.149
12.62	-32.03	-0.149
12.63	-32.11	-0.149
12.65	-32.20	-0.149
12.67	-32.28	-0.148
12.68	-32.36	-0.148
12.70	-32.45	-0.148
12.72	-32.53	-0.148
12.73	-32.61	-0.148
12.75	-32.69	-0.148
12.77	-32.78	-0.148
12.78	-32.86	-0.148
12.80	-32.95	-0.148
12.82	-33.03	-0.148
12.83	-33.11	-0.148
12.85	-33.20	-0.148
12.87	-33.28	-0.148
12.88	-33.36	-0.148
12.90	-33.45	-0.148
12.92	-33.53	-0.148
12.93	-33.61	-0.148
12.95	-33.70	-0.148
12.97	-33.78	-0.148
12.98	-33.86	-0.148
13.00	-33.95	-0.148
13.02	-34.03	-0.148
13.03	-34.11	-0.148
13.05	-34.19	-0.148
13.07	-34.28	-0.148
13.08	-34.36	-0.148
13.10	-34.44	-0.148
13.12	-34.53	-0.148
13.13	-34.61	-0.148
13.15	-34.70	-0.148
13.17	-34.78	-0.148
13.18	-34.86	-0.148
13.20	-34.94	-0.148
13.22	-35.03	-0.148
13.23	-35.11	-0.148
13.25	-35.20	-0.148
13.27	-35.28	-0.147
13.28	-35.36	-0.147
13.30	-35.45	-0.147
13.32	-35.53	-0.147
13.33	-35.61	-0.147
13.35	-35.70	-0.147
13.37	-35.78	-0.147
13.38	-35.86	-0.147
13.40	-35.95	-0.147
13.42	-36.03	-0.147
13.43	-36.11	-0.147
13.45	-36.20	-0.147
13.47	-36.28	-0.147
13.48	-36.36	-0.147
13.50	-36.45	-0.147
13.52	-36.53	-0.147
13.53	-36.61	-0.147
13.55	-36.70	-0.147
13.57	-36.78	-0.147
13.58	-36.86	-0.147
13.60	-36.94	-0.147
13.62	-37.03	-0.147
13.63	-37.11	-0.147
13.65	-37.20	-0.147
13.67	-37.28	-0.147
13.68	-37.36	-0.147
13.70	-37.45	-0.147
13.72	-37.53	-0.147
13.73	-37.61	-0.147
13.75	-37.70	-0.147
13.77	-37.78	-0.147
13.78	-37.86	-0.147
13.80	-37.95	-0.147
13.82	-38.03	-0.146
13.83	-38.11	-0.146
13.85	-38.20	-0.146
13.87	-38.28	-0.146
13.88	-38.36	-0.146
13.90	-38.45	-0.146
13.92	-38.53	-0.146
13.93	-38.61	-0.146
13.95	-38.70	-0.146
13.97	-38.78	-0.146
13.98	-38.86	-0.146
14.00	-38.95	-0.146
14.02	-39.03	-0.146
14.03	-39.11	-0.146
14.05	-39.20	-0.146
14.07	-39.28	-0.146
14.08	-39.36	-0.146
14.10	-39.45	-0.146
14.12	-39.53	-0.146
14.13	-39.61	-0.146
14.15	-39.70	-0.146
14.17	-39.78	-0.146
14.18	-39.86	-0.146
14.20	-39.95	-0.146
14.22	-40.03	-0.146
14.23	-40.11	-0.146
14.25	-40.20	-0.146
14.27	-40.28	-0.146
14.28	-40.36	-0.146
14.30	-40.45	-0.145
14.32	-40.53	-0.145
14.33	-40.61	-0.145
14.35	-40.70	-0.145
14.37	-40.78	-0.145
14.38	-40.86	-0.145
14.40	-40.95	-0.145
14.42	-41.03	-0.145
14.43	-41.11	-0.145
14.45	-41.20	-0.145
14.47	-41.28	-0.145
14.48	-41.36	-0.145
14.50	-41.45	-0.145
14.52	-41.53	-0.145
14.53	-41.62	-0.145
14.55	-41.70	-0.145
14.57	-41.78	-0.145
14.58	-41.86	-0.145
14.60	-41.95	-0.145
14.62	-42.03	-0.145
14.63	-42.11	-0.145
14.65	-42.20	-0.145
14.67	-42.28	-0.144
14.68	-42.37	-0.144
14.70	-42.45	-0.144
14.72	-42.53	-0.144
14.73	-42.62	-0.144
14.75	-42.70	-0.144
14.77	-42.78	-0.144
14.78	-42.86	-0.144
14.80	-42.95	-0.144
14.82	-43.03	-0.144
14.83	-43.12	-0.144
14.85	-43.20	-0.144
14.87	-43.28	-0.144
14.88	-43.37	-0.144
14.90	-43.45	-0.143
14.92	-43.53	-0.143
14.93	-43.62	-0.143
14.95	-43.70	-0.143
14.97	-43.78	-0.143
14.98	-43.87	-0.143
15.00	-43.95	-0.143
15.02	-44.03	-0.143
15.03	-44.12	-0.143
15.05	-44.20	-0.143
15.07	-44.28	-0.142
15.08	-44.37	-0.142
15.10	-44.45	-0.142
15.12	-44.54	-0.142
15.13	-44.62	-0.142
15.15	-44.70	-0.142
15.17	-44.79	-0.142
15.18	-44.87	-0.141
15.20	-44.95	-0.141
15.22	-45.04	-0.141
15.23	-45.12	-0.141
15.25	-45.20	-0.141
15.27	-45.29	-0.141
15.28	-45.37	-0.141
15.30	-45.45	-0.140
15.32	-45.54	-0.140
15.33	-45.62	-0.140
15.35	-45.70	-0.140
15.37	-45.79	-0.140
15.38	-45.87	-0.140
15.40	-45.96	-0.139
15.42	-46.04	-0.139
15.43	-46.12	-0.139
15.45	-46.21	-0.138
15.47	-46.29	-0.138
15.48	-46.37	-0.138
15.50	-46.46	-0.138
15.52	-46.54	-0.138
15.53	-46.62	-0.137
15.55	-46.71	-0.137
15.57	-46.79	-0.137
15.58	-46.87	-0.137
15.60	-46.96	-0.136
15.62	-47.04	-0.136
15.63	-47.13	-0.136
15.65	-47.21	-0.135
15.67	-47.29	-0.135
15.68	-47.38	-0.135
15.70	-47.46	-0.135
15.72	-47.54	-0.134
15.73	-47.63	-0.134
15.75	-47.71	-0.134
15.77	-47.80	-0.134
15.78	-47.88	-0.133
15.80	-47.96	-0.133
15.82	-48.05	-0.133
15.83	-48.13	-0.133
15.85	-48.21	-0.132
15.87	-48.30	-0.132
15.88	-48.38	-0.132
15.90	-48.46	-0.131
15.92	-48.55	-0.131
15.93	-48.63	-0.131
15.95	-48.72	-0.130
15.97	-48.80	-0.130
15.98	-48.88	-0.130
16.00	-48.97	-0.129
16.02	-49.05	-0.129
16.03	-49.13	-0.129
16.05	-49.22	-0.129
16.07	-49.30	-0.128
16.08	-49.39	-0.128
16.10	-49.47	-0.128
16.12	-49.55	-0.127
16.13	-49.64	-0.127
16.15	-49.72	-0.127
16.17	-49.81	-0.126
16.18	-49.89	-0.125
16.20	-49.97	-0.125
16.22	-50.06	-0.125
16.23	-50.14	-0.125
16.25	-50.22	-0.125
16.27	-50.31	-0.124
16.28	-50.39	-0.124
16.30	-50.48	-0.124
16.32	-50.56	-0.123
16.33	-50.64	-0.123
16.35	-50.73	-0.123
16.37	-50.81	-0.123
16.38	-50.89	-0.123
16.40	-50.98	-0.122
16.42	-51.06	-0.122
16.43	-51.14	-0.122
16.45	-51.23	-0.121
16.47	-51.31	-0.121
16.48	-51.40	-0.121
16.50	-51.48	-0.120
16.52	-51.56	-0.120
16.53	-51.65	-0.120
16.55	-51.73	-0.120
16.57	-51.82	-0.119
16.58	-51.90	-0.119
16.60	-51.98	-0.119
16.62	-52.07	-0.118
16.63	-52.15	-0.118
16.65	-52.23	-0.118
16.67	-52.32	-0.118
16.68	-52.40	-0.118
16.70	-52.49	-0.117
16.72	-52.57	-0.117
16.73	-52.65	-0.117
16.75	-52.74	-0.117
16.77	-52.82	-0.117
16.78	-52.90	-0.116
16.80	-52.99	-0.116
16.82	-53.07	-0.116
16.83	-53.15	-0.116
16.85	-53.24	-0.115
16.87	-53.32	-0.115
16.88	-53.40	-0.115
16.90	-53.49	-0.115
16.92	-53.57	-0.114
16.93	-53.66	-0.114
16.95	-53.74	-0.114
16.97	-53.82	-0.114
16.98	-53.91	-0.114
17.00	-53.99	-0.113
17.02	-54.07	-0.113
17.03	-54.16	-0.113
17.05	-54.24	-0.113
17.07	-54.32	-0.113
17.08	-54.41	-0.112
17.10	-54.49	-0.112
17.12	-54.58	-0.112
17.13	-54.66	-0.112
17.15	-54.74	-0.112
17.17	-54.83	-0.111
17.18	-54.91	-0.111
17.20	-54.99	-0.111
17.22	-55.08	-0.111
17.23	-55.16	-0.111
17.25	-55.25	-0.110
17.27	-55.33	-0.110
17.28	-55.41	-0.110
17.30	-55.50	-0.110
17.32	-55.58	-0.110
17.33	-55.66	-0.110
17.35	-55.75	-0.109
17.37	-55.83	-0.109
17.38	-55.91	-0.109
17.40	-56.00	-0.109
17.42	-56.08	-0.109
17.43	-56.16	-0.109
17.45	-56.25	-0.108
17.47	-56.33	-0.108
17.48	-56.41	-0.108
17.50	-56.50	-0.108
17.52	-56.58	-0.108
17.53	-56.66	-0.107
17.55	-56.75	-0.107
17.57	-56.83	-0.107
17.58	-56.92	-0.107
17.60	-57.00	-0.107
17.62	-57.08	-0.107
17.63	-57.17	-0.106
17.65	-57.25	-0.106
17.67	-57.33	-0.106
17.68	-57.42	-0.106
17.70	-57.50	-0.106
17.72	-57.58	-0.106
17.73	-57.67	-0.105
17.75	-57.75	-0.105
17.77	-57.83	-0.105
17.78	-57.92	-0.105
17.80	-58.00	-0.105
17.82	-58.08	-0.105
17.83	-58.17	-0.104
17.85	-58.25	-0.104
17.87	-58.34	-0.104
17.88	-58.42	-0.104
17.90	-58.50	-0.103
17.92	-58.59	-0.103
17.93	-58.67	-0.103
17.95	-58.75	-0.103
17.97	-58.84	-0.103
17.98	-58.92	-0.103
18.00	-59.00	-0.103
18.02	-59.09	-0.103
18.03	-59.17	-0.103
18.05	-59.25	-0.102
18.07	-59.34	-0.102
18.08	-59.42	-0.102
18.10	-59.51	-0.102
18.12	-59.59	-0.102
18.13	-59.67	-0.102
18.15	-59.76	-0.102
18.17	-59.84	-0.102
18.18	-59.92	-0.101
18.20	-60.01	-0.101
18.22	-60.09	-0.101
18.23	-60.17	-0.101
18.25	-60.26	-0.101
18.27	-60.34	-0.101
18.28	-60.42	-0.101
18.30	-60.51	-0.101
18.32	-60.59	-0.101
18.33	-60.67	-0.101
18.35	-60.76	-0.100
18.37	-60.84	-0.100
18.38	-60.92	-0.100
18.40	-61.01	-0.100
18.42	-61.09	-0.100
18.43	-61.17	-0.100
18.45	-61.26	-0.100
18.47	-61.34	-0.100
18.48	-61.42	-0.100
18.50	-61.51	-0.099
18.52	-61.59	-0.099
18.53	-61.67	-0.099
18.55	-61.76	-0.099
18.57	-61.84	-0.099
18.58	-61.92	-0.099
18.60	-62.01	-0.099
18.62	-62.09	-0.099
18.63	-62.18	-0.099
18.65	-62.26	-0.099
18.67	-62.34	-0.099
18.68	-62.43	-0.098
18.70	-62.51	-0.098
18.72	-62.59	-0.098
18.73	-62.68	-0.098
18.75	-62.76	-0.098
18.77	-62.84	-0.098
18.78	-62.93	-0.098
18.80	-63.01	-0.098
18.82	-63.09	-0.098
18.83	-63.18	-0.098
18.85	-63.26	-0.097
18.87	-63.34	-0.097
18.88	-63.43	-0.097
18.90	-63.51	-0.097
18.92	-63.60	-0.097
18.93	-63.68	-0.097
18.95	-63.76	-0.097
18.97	-63.85	-0.097
18.98	-63.93	-0.097
19.00	-64.01	-0.097
19.02	-64.09	-0.096
19.03	-64.18	-0.096
19.05	-64.26	-0.096
19.07	-64.35	-0.096
19.08	-64.43	-0.096
19.10	-64.51	-0.096
19.12	-64.59	-0.096
19.13	-64.68	-0.096
19.15	-64.76	-0.096
19.17	-64.85	-0.096
19.18	-64.93	-0.096
19.20	-65.01	-0.095
19.22	-65.10	-0.095
19.23	-65.18	-0.095
19.25	-65.26	-0.095
19.27	-65.35	-0.095
19.28	-65.43	-0.095
19.30	-65.51	-0.095
19.32	-65.60	-0.095
19.33	-65.68	-0.095
19.35	-65.76	-0.095
19.37	-65.85	-0.095
19.38	-65.93	-0.095
19.40	-66.01	-0.095
19.42	-66.10	-0.095
19.43	-66.18	-0.094
19.45	-66.26	-0.094
19.47	-66.35	-0.094
19.48	-66.43	-0.094
19.50	-66.52	-0.094
19.52	-66.60	-0.094
19.53	-66.68	-0.094
19.55	-66.76	-0.094
19.57	-66.85	-0.094
19.58	-66.93	-0.094
19.60	-67.01	-0.094
19.62	-67.10	-0.094
19.63	-67.18	-0.094
19.65	-67.27	-0.093
19.67	-67.35	-0.093
19.68	-67.43	-0.093
19.70	-67.51	-0.093
19.72	-67.60	-0.093
19.73	-67.68	-0.093
19.75	-67.76	-0.093
19.77	-67.85	-0.093
19.78	-67.93	-0.093
19.80	-68.02	-0.093
19.82	-68.10	-0.093
19.83	-68.18	-0.093
19.85	-68.27	-0.093
19.87	-68.35	-0.092
19.88	-68.43	-0.092
19.90	-68.52	-0.092
19.92	-68.60	-0.092
19.93	-68.68	-0.092
19.95	-68.76	-0.092
19.97	-68.85	-0.092
19.98	-68.93	-0.092
20.00	-69.02	-0.092
20.02	-69.10	-0.092
20.03	-69.18	-0.092
20.05	-69.27	-0.092
20.07	-69.35	-0.091
20.08	-69.43	-0.091
20.10	-69.52	-0.091
20.12	-69.60	-0.091
20.13	-69.68	-0.091
20.15	-69.77	-0.091
20.17	-69.85	-0.091
20.18	-69.93	-0.091
20.20	-70.02	-0.091
20.22	-70.10	-0.091
20.23	-70.18	-0.091
20.25	-70.27	-0.091
20.27	-70.35	-0.091
20.28	-70.43	-0.091
20.30	-70.52	-0.091
20.32	-70.60	-0.091
20.33	-70.68	-0.091
20.35	-70.77	-0.090
20.37	-70.85	-0.090
20.38	-70.93	-0.090
20.40	-71.02	-0.090
20.42	-71.10	-0.090
20.43	-71.18	-0.090
20.45	-71.27	-0.090
20.47	-71.35	-0.090
20.48	-71.43	-0.090
20.50	-71.52	-0.090
20.52	-71.60	-0.090
20.53	-71.68	-0.090
20.55	-71.77	-0.090
20.57	-71.85	-0.090
20.58	-71.93	-0.090
20.60	-72.01	-0.090
20.62	-72.10	-0.090
20.63	-72.19	-0.089
20.65	-72.27	-0.089
20.67	-72.35	-0.089
20.68	-72.43	-0.089
20.70	-72.52	-0.089
20.72	-72.60	-0.089
20.73	-72.68	-0.089
20.75	-72.77	-0.089
20.77	-72.85	-0.089
20.78	-72.93	-0.089
20.80	-73.02	-0.089
20.82	-73.10	-0.089
20.83	-73.18	-0.089
20.85	-73.27	-0.089
20.87	-73.35	-0.089
20.88	-73.43	-0.089
20.90	-73.52	-0.089
20.92	-73.60	-0.089
20.93	-73.68	-0.089
20.95	-73.77	-0.088
20.97	-73.85	-0.088
20.98	-73.93	-0.088
21.00	-74.02	-0.088
21.02	-74.10	-0.088
21.03	-74.19	-0.088
21.05	-74.27	-0.088
21.07	-74.35	-0.088
21.08	-74.43	-0.088
21.10	-74.52	-0.088
21.12	-74.60	-0.088
21.13	-74.68	-0.088
21.15	-74.77	-0.088
21.17	-74.85	-0.088
21.18	-74.93	-0.088
21.20	-75.02	-0.088
21.22	-75.10	-0.088
21.23	-75.18	-0.088
21.25	-75.27	-0.088
21.27	-75.35	-0.088
21.28	-75.43	-0.088
21.30	-75.52	-0.088
21.32	-75.60	-0.088
21.33	-75.68	-0.088
21.35	-75.77	-0.088
21.37	-75.85	-0.088
21.38	-75.94	-0.088
21.40	-76.02	-0.087
21.42	-76.10	-0.087
21.43	-76.18	-0.087
21.45	-76.27	-0.087
21.47	-76.35	-0.087
21.48	-76.43	-0.087
21.50	-76.52	-0.087
21.52	-76.60	-0.087
21.53	-76.68	-0.087
21.55	-76.77	-0.087
21.57	-76.85	-0.087
21.58	-76.93	-0.087
21.60	-77.02	-0.087
21.62	-77.10	-0.087
21.63	-77.18	-0.087
21.65	-77.27	-0.087
21.67	-77.35	-0.087
21.68	-77.43	-0.087
21.70	-77.52	-0.087
21.72	-77.60	-0.087
21.73	-77.68	-0.087
21.75	-77.77	-0.087
21.77	-77.85	-0.087
21.78	-77.93	-0.087
21.80	-78.02	-0.087
21.82	-78.10	-0.087
21.83	-78.18	-0.087
21.85	-78.27	-0.086
21.87	-78.35	-0.086
21.88	-78.43	-0.086
21.90	-78.51	-0.086
21.92	-78.60	-0.086
21.93	-78.68	-0.086
21.95	-78.76	-0.086
21.97	-78.85	-0.086
21.98	-78.93	-0.086
22.00	-79.01	-0.086
22.02	-79.10	-0.086
22.03	-79.18	-0.086
22.05	-79.26	-0.086
22.07	-79.34	-0.086
22.08	-79.43	-0.086
22.10	-79.51	-0.086
22.12	-79.59	-0.086
22.13	-79.68	-0.086
22.15	-79.76	-0.086
22.17	-79.84	-0.086
22.18	-79.92	-0.085
22.20	-80.01	-0.085
22.22	-80.09	-0.085
22.23	-80.17	-0.085
22.25	-80.25	-0.085
22.27	-80.34	-0.085
22.28	-80.42	-0.085
22.30	-80.50	-0.085
22.32	-80.59	-0.085
22.33	-80.67	-0.085
22.35	-80.75	-0.085
22.37	-80.83	-0.085
22.38	-80.92	-0.085
22.40	-81.00	-0.085
22.42	-81.08	-0.085
22.43	-81.17	-0.085
22.45	-81.25	-0.085
22.47	-81.33	-0.085
22.48	-81.41	-0.085
22.50	-81.50	-0.085
22.52	-81.58	-0.085
22.53	-81.66	-0.085
22.55	-81.74	-0.085
22.57	-81.83	-0.085
22.58	-81.91	-0.084
22.60	-81.99	-0.084
22.62	-82.07	-0.084
22.63	-82.16	-0.084
22.65	-82.24	-0.084
22.67	-82.32	-0.084
22.68	-82.41	-0.084
22.70	-82.49	-0.084
22.72	-82.57	-0.084
22.73	-82.65	-0.084
22.75	-82.74	-0.084
22.77	-82.82	-0.084
22.78	-82.90	-0.084
22.80	-82.98	-0.084
22.82	-83.07	-0.084
22.83	-83.15	-0.084
22.85	-83.23	-0.084
22.87	-83.31	-0.084
22.88	-83.40	-0.084
22.90	-83.48	-0.084
22.92	-83.56	-0.084
22.93	-83.64	-0.083
22.95	-83.73	-0.083
22.97	-83.81	-0.083
22.98	-83.89	-0.083
23.00	-83.97	-0.083
23.02	-84.06	-0.083
23.03	-84.14	-0.083
23.05	-84.22	-0.083
23.07	-84.30	-0.083
23.08	-84.38	-0.083
23.10	-84.47	-0.083
23.12	-84.55	-0.083
23.13	-84.63	-0.083
23.15	-84.71	-0.083
23.17	-84.79	-0.083
23.18	-84.87	-0.083
23.20	-84.95	-0.083
23.22	-85.04	-0.082
23.23	-85.12	-0.082
23.25	-85.20	-0.082
23.27	-85.28	-0.082
23.28	-85.36	-0.082
23.30	-85.44	-0.082
23.32	-85.52	-0.082
23.33	-85.60	-0.082
23.35	-85.67	-0.081
23.37	-85.75	-0.081
23.38	-85.83	-0.081
23.40	-85.91	-0.081
23.42	-85.99	-0.080
23.43	-86.07	-0.080
23.45	-86.14	-0.080
23.47	-86.22	-0.080
23.48	-86.30	-0.079
23.50	-86.37	-0.078
23.52	-86.45	-0.078
23.53	-86.52	-0.078
23.55	-86.60	-0.077
23.57	-86.67	-0.076
23.58	-86.75	-0.076
23.60	-86.82	-0.076
23.62	-86.89	-0.076
23.63	-86.97	-0.075
23.65	-87.04	-0.075
23.67	-87.11	-0.075
23.68	-87.18	-0.074
23.70	-87.26	-0.073
23.72	-87.33	-0.073
23.73	-87.40	-0.073
23.75	-87.47	-0.072
23.77	-87.54	-0.072
23.78	-87.61	-0.072
23.80	-87.68	-0.071
23.82	-87.75	-0.071
23.83	-87.81	-0.071
23.85	-87.88	-0.070
23.87	-87.95	-0.070
23.88	-88.02	-0.070
23.90	-88.09	-0.069
23.92	-88.15	-0.069
23.93	-88.22	-0.068
23.95	-88.28
23.97	-88.35
23.98	-88.42
23.99

[step]
Ramp 5.00 °C/min to 30.00 °C
Time	Temperature	Heat Flow (Normalized)
min	°C	W/g
25.00	-89.95	0.001
25.01	-89.95	0.002
25.03	-89.95	0.002
25.05	-89.94	0.002
25.06	-89.93	0.002
25.08	-89.91	0.001
25.10	-89.89	0.001
25.11	-89.83	-0.054
25.13	-89.76	-0.040
25.15	-89.71	-0.015
25.16	-89.67	0.000
25.18	-89.62	0.011
25.20	-89.57	0.019
25.21	-89.52	0.026
25.23	-89.46	0.032
25.25	-89.40	0.038
25.26	-89.33	0.044
25.28	-89.27	0.049
25.30	-89.20	0.053
25.31	-89.13	0.057
25.33	-89.06	0.060
25.35	-88.99	0.063
25.36	-88.92	0.066
25.38	-88.85	0.069
25.40	-88.77	0.071
25.41	-88.69	0.073
25.43	-88.62	0.074
25.45	-88.54	0.075
25.46	-88.47	0.078
25.48	-88.39	0.078
25.50	-88.31	0.079
25.51	-88.23	0.081
25.53	-88.15	0.081
25.55	-88.07	0.082
25.56	-87.99	0.082
25.58	-87.91	0.083
25.60	-87.83	0.084
25.61	-87.75	0.085
25.63	-87.67	0.085
25.65	-87.59	0.085
25.66	-87.51	0.085
25.68	-87.43	0.085
25.70	-87.34	0.086
25.71	-87.26	0.086
25.73	-87.18	0.086
25.75	-87.10	0.086
25.76	-87.02	0.086
25.78	-86.94	0.087
25.80	-86.86	0.087
25.81	-86.77	0.087
25.83	-86.69	0.087
25.85	-86.61	0.087
25.86	-86.53	0.087
25.88	-86.44	0.087
25.90	-86.36	0.087
25.91	-86.28	0.087
25.93	-86.20	0.088
25.95	-86.11	0.088
25.96	-86.03	0.088
25.98	-85.95	0.088
26.00	-85.86	0.088
26.01	-85.78	0.088
26.03	-85.70	0.088
26.05	-85.62	0.088
26.06	-85.53	0.088
26.08	-85.45	0.088
26.10	-85.37	0.088
26.11	-85.29	0.088
26.13	-85.20	0.088
26.15	-85.12	0.089
26.16	-85.04	0.089
26.18	-84.95	0.089
26.20	-84.87	0.089
26.21	-84.79	0.089
26.23	-84.71	0.089
26.25	-84.62	0.089
26.26	-84.54	0.089
26.28	-84.46	0.089
26.30	-84.38	0.089
26.31	-84.29	0.089
26.33	-84.21	0.089
26.35	-84.12	0.089
26.36	-84.04	0.089
26.38	-83.96	0.089
26.40	-83.87	0.089
26.41	-83.79	0.089
26.43	-83.71	0.089
26.45	-83.63	0.089
26.46	-83.54	0.089
26.48	-83.46	0.089
26.50	-83.38	0.089
26.51	-83.29	0.089
26.53	-83.21	0.089
26.55	-83.13	0.089
26.56	-83.04	0.089
26.58	-82.96	0.089
26.60	-82.88	0.089
26.61	-82.79	0.089
26.63	-82.71	0.089
26.65	-82.63	0.089
26.66	-82.54	0.089
26.68	-82.46	0.089
26.70	-82.38	0.089
26.71	-82.29	0.089
26.73	-82.21	0.090
26.75	-82.13	0.090
26.76	-82.04	0.090
26.78	-81.96	0.090
26.80	-81.88	0.090
26.81	-81.79	0.090
26.83	-81.71	0.090
26.85	-81.63	0.090
26.86	-81.54	0.090
26.88	-81.46	0.090
26.90	-81.38	0.090
26.91	-81.29	0.090
26.93	-81.21	0.090
26.95	-81.13	0.090
26.96	-81.04	0.090
26.98	-80.96	0.090
27.00	-80.88	0.090
27.01	-80.79	0.090
27.03	-80.71	0.090
27.05	-80.63	0.090
27.06	-80.54	0.090
27.08	-80.46	0.090
27.10	-80.38	0.090
27.11	-80.29	0.090
27.13	-80.21	0.090
27.15	-80.13	0.090
27.16	-80.04	0.090
27.18	-79.96	0.090
27.20	-79.88	0.090
27.21	-79.79	0.090
27.23	-79.71	0.090
27.25	-79.63	0.090
27.26	-79.54	0.090
27.28	-79.46	0.090
27.30	-79.38	0.090
27.31	-79.29	0.090
27.33	-79.21	0.090
27.35	-79.13	0.090
27.36	-79.04	0.090
27.38	-78.96	0.090
27.40	-78.88	0.090
27.41	-78.79	0.090
27.43	-78.71	0.090
27.45	-78.63	0.090
27.46	-78.54	0.090
27.48	-78.46	0.090
27.50	-78.38	0.090
27.51	-78.29	0.090
27.53	-78.21	0.090
27.55	-78.13	0.090
27.56	-78.04	0.090
27.58	-77.96	0.090
27.60	-77.88	0.090
27.61	-77.79	0.090
27.63	-77.71	0.090
27.65	-77.63	0.090
27.66	-77.54	0.090
27.68	-77.46	0.090
27.70	-77.38	0.090
27.71	-77.29	0.090
27.73	-77.21	0.090
27.75	-77.13	0.090
27.76	-77.04	0.090
27.78	-76.96	0.090
27.80	-76.87	0.090
27.81	-76.79	0.090
27.83	-76.71	0.090
27.85	-76.63	0.090
27.86	-76.54	0.090
27.88	-76.46	0.090
27.90	-76.37	0.090
27.91	-76.29	0.090
27.93	-76.21	0.090
27.95	-76.12	0.090
27.96	-76.04	0.090
27.98	-75.96	0.090
28.00	-75.87	0.090
28.01	-75.79	0.090
28.03	-75.71	0.090
28.05	-75.62	0.090
28.06	-75.54	0.090
28.08	-75.46	0.090
28.10	-75.37	0.090
28.11	-75.29	0.090
28.13	-75.21	0.090
28.15	-75.12	0.090
28.16	-75.04	0.090
28.18	-74.96	0.090
28.20	-74.87	0.090
28.21	-74.79	0.090
28.23	-74.71	0.090
28.25	-74.62	0.090
28.26	-74.54	0.090
28.28	-74.46	0.090
28.30	-74.37	0.090
28.31	-74.29	0.090
28.33	-74.21	0.090
28.35	-74.12	0.090
28.36	-74.04	0.090
28.38	-73.96	0.090
28.40	-73.87	0.090
28.41	-73.79	0.090
28.43	-73.71	0.090
28.45	-73.62	0.090
28.46	-73.54	0.090
28.48	-73.46	0.090
28.50	-73.37	0.090
28.51	-73.29	0.090
28.53	-73.21	0.090
28.55	-73.12	0.090
28.56	-73.04	0.090
28.58	-72.96	0.090
28.60	-72.87	0.090
28.61	-72.79	0.090
28.63	-72.70	0.090
28.65	-72.62	0.090
28.66	-72.54	0.090
28.68	-72.46	0.090
28.70	-72.37	0.090
28.71	-72.29	0.090
28.73	-72.20	0.090
28.75	-72.12	0.090
28.76	-72.04	0.090
28.78	-71.95	0.090
28.80	-71.87	0.090
28.81	-71.79	0.090
28.83	-71.70	0.090
28.85	-71.62	0.090
28.86	-71.54	0.090
28.88	-71.45	0.090
28.90	-71.37	0.090
28.91	-71.29	0.090
28.93	-71.20	0.090
28.95	-71.12	0.090
28.96	-71.04	0.090
28.98	-70.95	0.091
29.00	-70.87	0.091
29.01	-70.79	0.091
29.03	-70.70	0.091
29.05	-70.62	0.091
29.06	-70.54	0.091
29.08	-70.45	0.091
29.10	-70.37	0.091
29.11	-70.29	0.091
29.13	-70.20	0.091
29.15	-70.12	0.091
29.16	-70.04	0.091
29.18	-69.95	0.091
29.20	-69.87	0.091
29.21	-69.79	0.091
29.23	-69.70	0.091
29.25	-69.62	0.091
29.26	-69.54	0.091
29.28	-69.45	0.091
29.30	-69.37	0.091
29.31	-69.29	0.091
29.33	-69.20	0.091
29.35	-69.12	0.091
29.36	-69.04	0.091
29.38	-68.95	0.091
29.40	-68.87	0.091
29.41	-68.79	0.091
29.43	-68.70	0.091
29.45	-68.62	0.091
29.46	-68.54	0.091
29.48	-68.45	0.091
29.50	-68.37	0.091
29.51	-68.29	0.091
29.53	-68.20	0.091
29.55	-68.12	0.091
29.56	-68.03	0.091
29.58	-67.95	0.091
29.60	-67.87	0.091
29.61	-67.79	0.091
29.63	-67.70	0.091
29.65	-67.62	0.091
29.66	-67.54	0.091
29.68	-67.45	0.092
29.70	-67.37	0.092
29.71	-67.29	0.092
29.73	-67.20	0.092
29.75	-67.12	0.092
29.76	-67.04	0.092
29.78	-66.95	0.092
29.80	-66.87	0.092
29.81	-66.79	0.092
29.83	-66.70	0.092
29.85	-66.62	0.092
29.86	-66.53	0.092
29.88	-66.45	0.092
29.90	-66.37	0.092
29.91	-66.29	0.092
29.93	-66.20	0.092
29.95	-66.12	0.092
29.96	-66.04	0.092
29.98	-65.95	0.092
[...]
131.85	-56.61	0.091
131.87	-56.53	0.091
131.89	-56.44	0.091
131.90	-56.36	0.091
131.92	-56.28	0.091
131.94	-56.20	0.091
131.95	-56.11	0.091
131.97	-56.03	0.091
131.99	-55.94	0.091
132.00	-55.86	0.091
132.02	-55.78	0.091
132.04	-55.70	0.091
132.05	-55.61	0.091
132.07	-55.53	0.091
132.09	-55.45	0.091
132.10	-55.36	0.092
132.12	-55.28	0.092
132.14	-55.20	0.092
132.15	-55.11	0.092
132.17	-55.03	0.092
132.19	-54.95	0.092
132.20	-54.86	0.092
132.22	-54.78	0.092
132.24	-54.70	0.092
132.25	-54.61	0.092
132.27	-54.53	0.093
132.29	-54.45	0.093
132.30	-54.36	0.093
132.32	-54.28	0.093
132.34	-54.20	0.093
132.35	-54.11	0.093
132.37	-54.03	0.093
132.39	-53.95	0.093
132.40	-53.86	0.093
132.42	-53.78	0.093
132.44	-53.70	0.093
132.45	-53.62	0.094
132.47	-53.53	0.094
132.49	-53.45	0.094
132.50	-53.37	0.094
132.52	-53.28	0.094
132.54	-53.20	0.094
132.55	-53.12	0.094
132.57	-53.03	0.094
132.59	-52.95	0.094
132.60	-52.87	0.095
132.62	-52.78	0.095
132.64	-52.70	0.095
132.65	-52.62	0.095
132.67	-52.54	0.095
132.69	-52.45	0.095
132.70	-52.37	0.095
132.72	-52.28	0.096
132.74	-52.20	0.096
132.75	-52.12	0.096
132.77	-52.04	0.096
132.79	-51.95	0.096
132.80	-51.87	0.097
132.82	-51.79	0.097
132.84	-51.70	0.097
132.85	-51.62	0.097
132.87	-51.54	0.097
132.89	-51.45	0.097
132.90	-51.37	0.098
132.92	-51.29	0.098
132.94	-51.20	0.098
132.95	-51.12	0.098
132.97	-51.04	0.098
132.99	-50.96	0.099
133.00	-50.87	0.099
133.02	-50.79	0.099
133.04	-50.71	0.099
133.05	-50.62	0.100
133.07	-50.54	0.100
133.09	-50.46	0.100
133.10	-50.38	0.100
133.12	-50.29	0.101
133.14	-50.21	0.101
133.15	-50.13	0.101
133.17	-50.04	0.101
133.19	-49.96	0.102
133.20	-49.88	0.102
133.22	-49.79	0.102
133.24	-49.71	0.103
133.25	-49.63	0.103
133.27	-49.55	0.104
133.29	-49.46	0.104
133.30	-49.38	0.104
133.32	-49.30	0.105
133.34	-49.21	0.106
133.35	-49.13	0.106
133.37	-49.05	0.106
133.39	-48.97	0.107
133.40	-48.89	0.108
133.42	-48.80	0.108
133.44	-48.72	0.108
133.45	-48.63	0.109
133.47	-48.55	0.110
133.49	-48.47	0.110
133.50	-48.39	0.111
133.52	-48.31	0.111
133.54	-48.22	0.112
133.55	-48.14	0.113
133.57	-48.06	0.113
133.59	-47.98	0.114
133.60	-47.89	0.115
133.62	-47.81	0.115
133.64	-47.73	0.116
133.65	-47.65	0.117
133.67	-47.56	0.118
133.69	-47.48	0.118
133.70	-47.40	0.119
133.72	-47.32	0.120
133.74	-47.23	0.121
133.75	-47.15	0.122
133.77	-47.07	0.122
133.79	-46.99	0.124
133.80	-46.90	0.124
133.82	-46.82	0.125
133.84	-46.74	0.126
133.85	-46.66	0.127
133.87	-46.58	0.127
133.89	-46.49	0.128
133.90	-46.41	0.130
133.92	-46.33	0.130
133.94	-46.25	0.131
133.95	-46.16	0.132
133.97	-46.08	0.133
133.99	-46.00	0.134
134.00	-45.92	0.135
134.02	-45.84	0.136
134.04	-45.75	0.137
134.05	-45.67	0.138
134.07	-45.59	0.138
134.09	-45.51	0.139
134.10	-45.43	0.140
134.12	-45.34	0.141
134.14	-45.26	0.141
134.15	-45.18	0.142
134.17	-45.10	0.142
134.19	-45.01	0.143
134.20	-44.93	0.143
134.22	-44.85	0.144
134.24	-44.77	0.144
134.25	-44.68	0.145
134.27	-44.60	0.145
134.29	-44.52	0.145
134.30	-44.44	0.145
134.32	-44.35	0.145
134.34	-44.27	0.146
134.35	-44.19	0.146
134.37	-44.10	0.146
134.39	-44.02	0.146
134.40	-43.94	0.146
134.42	-43.85	0.146
134.44	-43.77	0.146
134.45	-43.69	0.146
134.47	-43.60	0.146
134.49	-43.52	0.145
134.50	-43.44	0.145
134.52	-43.35	0.144
134.54	-43.27	0.144
134.55	-43.18	0.143
134.57	-43.10	0.143
134.59	-43.01	0.142
134.60	-42.93	0.142
134.62	-42.85	0.141
134.64	-42.76	0.141
134.65	-42.68	0.140
134.67	-42.59	0.140
134.69	-42.51	0.139
134.70	-42.43	0.139
134.72	-42.34	0.138
134.74	-42.26	0.138
134.75	-42.17	0.137
134.77	-42.09	0.137
134.79	-42.01	0.137
134.80	-41.92	0.136
134.82	-41.84	0.136
134.84	-41.75	0.136
134.85	-41.67	0.136
134.87	-41.59	0.136
134.89	-41.50	0.135
134.90	-41.42	0.135
134.92	-41.33	0.135
134.94	-41.25	0.135
134.95	-41.17	0.135
134.97	-41.08	0.135
134.99	-41.00	0.134
135.00	-40.91	0.134
135.02	-40.83	0.134
135.04	-40.75	0.134
135.05	-40.67	0.134
135.07	-40.58	0.134
135.09	-40.50	0.134
135.10	-40.41	0.134
135.12	-40.33	0.133
135.14	-40.25	0.133
135.15	-40.16	0.133
135.17	-40.08	0.133
135.19	-40.00	0.133
135.20	-39.91	0.133
135.22	-39.83	0.133
135.24	-39.75	0.133
135.25	-39.66	0.133
135.27	-39.58	0.133
135.29	-39.49	0.133
135.30	-39.41	0.133
135.32	-39.33	0.133
135.34	-39.25	0.133
135.35	-39.16	0.132
135.37	-39.08	0.132
135.39	-38.99	0.132
135.40	-38.91	0.132
135.42	-38.83	0.132
135.44	-38.74	0.132
135.45	-38.66	0.132
135.47	-38.58	0.132
135.49	-38.49	0.132
135.50	-38.41	0.132
135.52	-38.33	0.132
135.54	-38.24	0.132
135.55	-38.16	0.132
135.57	-38.08	0.132
135.59	-37.99	0.132
135.60	-37.91	0.132
135.62	-37.83	0.132
135.64	-37.74	0.132
135.65	-37.66	0.132
135.67	-37.58	0.132
135.69	-37.49	0.132
135.70	-37.41	0.132
135.72	-37.32	0.132
135.74	-37.24	0.132
135.75	-37.16	0.132
135.77	-37.07	0.132
135.79	-36.99	0.132
135.80	-36.91	0.132
135.82	-36.82	0.132
135.84	-36.74	0.132
135.85	-36.66	0.132
135.87	-36.57	0.132
135.89	-36.49	0.132
135.90	-36.41	0.132
135.92	-36.32	0.132
135.94	-36.24	0.132
135.95	-36.16	0.132
135.97	-36.07	0.132
135.99	-35.99	0.132
136.00	-35.90	0.132
136.02	-35.82	0.132
136.04	-35.74	0.132
136.05	-35.66	0.132
136.07	-35.57	0.132
136.09	-35.49	0.132
136.10	-35.40	0.132
136.12	-35.32	0.132
136.14	-35.24	0.132
136.15	-35.15	0.132
136.17	-35.07	0.132
136.19	-34.99	0.132
136.20	-34.90	0.132
136.22	-34.82	0.132
136.24	-34.74	0.132
136.25	-34.65	0.132
136.27	-34.57	0.132
136.29	-34.48	0.132
136.30	-34.40	0.132
136.32	-34.32	0.132
136.34	-34.24	0.132
136.35	-34.15	0.132
136.37	-34.07	0.132
136.39	-33.98	0.132
136.40	-33.90	0.132
136.42	-33.82	0.132
136.44	-33.73	0.132
136.45	-33.65	0.132
136.47	-33.57	0.132
136.49	-33.48	0.132
136.50	-33.40	0.132
136.52	-33.32	0.132
136.54	-33.23	0.132
136.55	-33.15	0.132
136.57	-33.07	0.132
136.59	-32.98	0.132
136.60	-32.90	0.132
136.62	-32.82	0.132
136.64	-32.73	0.132
136.65	-32.65	0.132
136.67	-32.57	0.132
136.69	-32.48	0.132
136.70	-32.40	0.132
136.72	-32.32	0.132
136.74	-32.23	0.133
136.75	-32.15	0.133
136.77	-32.07	0.133
136.79	-31.98	0.133
136.80	-31.90	0.133
136.82	-31.82	0.133
136.84	-31.73	0.133
136.85	-31.65	0.133
136.87	-31.57	0.133
136.89	-31.48	0.133
136.90	-31.40	0.133
136.92	-31.31	0.133
136.94	-31.23	0.133
136.95	-31.15	0.133
136.97	-31.06	0.133
136.99	-30.98	0.133
137.00	-30.90	0.133
137.02	-30.81	0.133
137.04	-30.73	0.133
137.05	-30.65	0.133
137.07	-30.56	0.133
137.09	-30.48	0.133
137.10	-30.40	0.133
137.12	-30.31	0.133
137.14	-30.23	0.133
137.15	-30.15	0.133
137.17	-30.06	0.133
137.19	-29.98	0.133
137.20	-29.90	0.133
137.22	-29.81	0.133
137.24	-29.73	0.133
137.25	-29.65	0.133
137.27	-29.56	0.133
137.29	-29.48	0.133
137.30	-29.40	0.133
137.32	-29.31	0.133
137.34	-29.23	0.133
137.35	-29.15	0.133
137.37	-29.06	0.133
137.39	-28.98	0.133
137.40	-28.90	0.133
137.42	-28.81	0.133
137.44	-28.73	0.133
137.45	-28.65	0.133
137.47	-28.56	0.133
137.49	-28.48	0.133
137.50	-28.40	0.133
137.52	-28.31	0.133
137.54	-28.23	0.133
137.55	-28.15	0.133
137.57	-28.06	0.133
137.59	-27.98	0.133
137.60	-27.90	0.133
137.62	-27.81	0.133
137.64	-27.73	0.133
137.65	-27.65	0.133
137.67	-27.56	0.133
137.69	-27.48	0.133
137.70	-27.40	0.133
137.72	-27.31	0.133
137.74	-27.23	0.133
137.75	-27.15	0.133
137.77	-27.06	0.133
137.79	-26.98	0.133
137.80	-26.90	0.133
137.82	-26.81	0.133
137.84	-26.73	0.133
137.85	-26.65	0.133
137.87	-26.56	0.134
137.89	-26.48	0.134
137.90	-26.39	0.134
137.92	-26.31	0.134
137.94	-26.23	0.134
137.95	-26.14	0.134
137.97	-26.06	0.134
137.99	-25.98	0.134
138.00	-25.89	0.134
138.02	-25.81	0.134
138.04	-25.73	0.134
138.05	-25.64	0.134
138.07	-25.56	0.134
138.09	-25.48	0.134
138.10	-25.39	0.134
138.12	-25.31	0.134
138.14	-25.23	0.134
138.15	-25.14	0.134
138.17	-25.06	0.134
138.19	-24.98	0.134
138.20	-24.89	0.134
138.22	-24.81	0.134
138.24	-24.73	0.134
138.25	-24.64	0.134
138.27	-24.56	0.134
138.29	-24.48	0.134
138.30	-24.39	0.134
138.32	-24.31	0.134
138.34	-24.23	0.134
138.35	-24.14	0.134
138.37	-24.06	0.134
138.39	-23.98	0.134
138.40	-23.89	0.134
138.42	-23.81	0.134
138.44	-23.72	0.134
138.45	-23.64	0.134
138.47	-23.56	0.134
138.49	-23.47	0.134
138.50	-23.39	0.134
138.52	-23.31	0.134
138.54	-23.22	0.134
138.55	-23.14	0.134
138.57	-23.06	0.134
138.59	-22.97	0.134
138.60	-22.89	0.134
138.62	-22.81	0.134
138.64	-22.72	0.134
138.65	-22.64	0.134
138.67	-22.56	0.134
138.69	-22.47	0.135
138.70	-22.39	0.135
138.72	-22.31	0.135
138.74	-22.22	0.135
138.75	-22.14	0.135
138.77	-22.05	0.135
138.79	-21.97	0.135
138.80	-21.89	0.135
138.82	-21.80	0.135
138.84	-21.72	0.135
138.85	-21.64	0.135
138.87	-21.56	0.135
138.89	-21.47	0.135
138.90	-21.39	0.135
138.92	-21.30	0.135
138.94	-21.22	0.135
138.95	-21.14	0.135
138.97	-21.05	0.135
138.99	-20.97	0.135
139.00	-20.89	0.135
139.02	-20.80	0.135
139.04	-20.72	0.135
139.05	-20.64	0.135
139.07	-20.55	0.135
139.09	-20.47	0.135
139.10	-20.39	0.135
139.12	-20.30	0.135
139.14	-20.22	0.135
139.15	-20.13	0.135
139.17	-20.05	0.135
139.19	-19.97	0.135
139.20	-19.88	0.135
139.22	-19.80	0.135
139.24	-19.72	0.135
139.25	-19.63	0.135
139.27	-19.55	0.135
139.29	-19.47	0.135
139.30	-19.38	0.135
139.32	-19.30	0.135
139.34	-19.22	0.135
139.35	-19.13	0.135
139.37	-19.05	0.135
139.39	-18.97	0.135
139.40	-18.88	0.135
139.42	-18.80	0.135
139.44	-18.72	0.135
139.45	-18.63	0.135
139.47	-18.55	0.135
139.49	-18.47	0.135
139.50	-18.38	0.135
139.52	-18.30	0.135
139.54	-18.22	0.135
139.55	-18.13	0.135
139.57	-18.05	0.136
139.59	-17.96	0.135
139.60	-17.88	0.136
139.62	-17.80	0.136
139.64	-17.72	0.136
139.65	-17.63	0.136
139.67	-17.55	0.136
139.69	-17.47	0.136
139.70	-17.38	0.136
139.72	-17.30	0.136
139.74	-17.21	0.136
139.75	-17.13	0.136
139.77	-17.05	0.136
139.79	-16.96	0.136
139.80	-16.88	0.136
139.82	-16.80	0.136
139.84	-16.71	0.136
139.85	-16.63	0.136
139.87	-16.55	0.136
139.89	-16.46	0.136
139.90	-16.38	0.136
139.92	-16.30	0.136
139.94	-16.21	0.136
139.95	-16.13	0.136
139.97	-16.05	0.136
139.99	-15.96	0.136
140.00	-15.88	0.136
140.02	-15.80	0.136
140.04	-15.71	0.136
140.05	-15.63	0.136
140.07	-15.55	0.136
140.09	-15.46	0.136
140.10	-15.38	0.136
140.12	-15.30	0.136
140.14	-15.21	0.136
140.15	-15.13	0.136
140.17	-15.05	0.136
140.19	-14.96	0.136
140.20	-14.88	0.136
140.22	-14.80	0.136
140.24	-14.71	0.136
140.25	-14.63	0.136
140.27	-14.55	0.136
140.29	-14.46	0.136
140.30	-14.38	0.136
140.32	-14.30	0.136
140.34	-14.21	0.136
140.35	-14.13	0.136
140.37	-14.05	0.136
140.39	-13.96	0.136
140.40	-13.88	0.136
140.42	-13.80	0.136
140.44	-13.71	0.136
140.45	-13.63	0.136
140.47	-13.54	0.136
140.49	-13.46	0.136
140.50	-13.38	0.136
140.52	-13.29	0.136
140.54	-13.21	0.136
140.55	-13.13	0.137
140.57	-13.04	0.137
140.59	-12.96	0.137
140.60	-12.88	0.137
140.62	-12.79	0.137
140.64	-12.71	0.137
140.65	-12.63	0.137
140.67	-12.54	0.137
140.69	-12.46	0.137
140.70	-12.38	0.137
140.72	-12.29	0.137
140.74	-12.21	0.137
140.75	-12.13	0.137
140.77	-12.04	0.137
140.79	-11.96	0.137
140.80	-11.88	0.137
140.82	-11.79	0.137
140.84	-11.71	0.137
140.85	-11.63	0.137
140.87	-11.54	0.137
140.89	-11.46	0.137
140.90	-11.38	0.137
140.92	-11.29	0.137
140.94	-11.21	0.137
140.95	-11.13	0.137
140.97	-11.04	0.137
140.99	-10.96	0.137
141.00	-10.88	0.137
141.02	-10.79	0.137
141.04	-10.71	0.137
141.05	-10.63	0.137
141.07	-10.54	0.137
141.09	-10.46	0.137
141.10	-10.38	0.137
141.12	-10.29	0.137
141.14	-10.21	0.137
141.15	-10.13	0.137
141.17	-10.04	0.137
141.19	-9.96	0.137
141.20	-9.88	0.137
141.22	-9.79	0.137
141.24	-9.71	0.137
141.25	-9.62	0.137
141.27	-9.54	0.137
141.29	-9.46	0.137
141.30	-9.37	0.137
141.32	-9.29	0.137
141.34	-9.21	0.137
141.35	-9.12	0.137
141.37	-9.04	0.137
141.39	-8.96	0.137
141.40	-8.87	0.137
141.42	-8.79	0.138
141.44	-8.71	0.138
141.45	-8.62	0.138
141.47	-8.54	0.138
141.49	-8.46	0.138
141.50	-8.37	0.138
141.52	-8.29	0.138
141.54	-8.21	0.138
141.55	-8.12	0.138
141.57	-8.04	0.138
141.59	-7.96	0.138
141.60	-7.87	0.138
141.62	-7.79	0.138
141.64	-7.71	0.138
141.65	-7.62	0.138
141.67	-7.54	0.138
141.69	-7.46	0.138
141.70	-7.37	0.138
141.72	-7.29	0.138
141.74	-7.21	0.138
141.75	-7.12	0.138
141.77	-7.04	0.138
141.79	-6.96	0.138
141.80	-6.87	0.138
141.82	-6.79	0.138
141.84	-6.71	0.138
141.85	-6.62	0.138
141.87	-6.54	0.138
141.89	-6.46	0.138
141.90	-6.37	0.138
141.92	-6.29	0.138
141.94	-6.20	0.138
141.95	-6.12	0.138
141.97	-6.04	0.138
141.99	-5.96	0.138
142.00	-5.87	0.138
142.02	-5.79	0.138
142.04	-5.70	0.138
142.05	-5.62	0.138
142.07	-5.54	0.138
142.09	-5.46	0.138
142.10	-5.37	0.138
142.12	-5.29	0.138
142.14	-5.21	0.138
142.15	-5.12	0.138
142.17	-5.04	0.138
142.19	-4.95	0.138
142.20	-4.87	0.139
142.22	-4.79	0.139
142.24	-4.70	0.139
142.25	-4.62	0.139
142.27	-4.54	0.139
142.29	-4.45	0.139
142.30	-4.37	0.139
142.32	-4.29	0.139
142.34	-4.20	0.139
142.35	-4.12	0.139
142.37	-4.04	0.139
142.39	-3.95	0.139
142.40	-3.87	0.139
142.42	-3.79	0.139
142.44	-3.70	0.139
142.45	-3.62	0.139
142.47	-3.54	0.139
142.49	-3.45	0.139
142.50	-3.37	0.139
142.52	-3.29	0.139
142.54	-3.20	0.139
142.55	-3.12	0.139
142.57	-3.03	0.139
142.59	-2.95	0.139
142.60	-2.87	0.139
142.62	-2.79	0.139
142.64	-2.70	0.139
142.65	-2.62	0.139
142.67	-2.53	0.139
142.69	-2.45	0.139
142.70	-2.37	0.139
142.72	-2.28	0.139
142.74	-2.20	0.139
142.75	-2.12	0.139
142.77	-2.03	0.139
142.79	-1.95	0.139
142.80	-1.87	0.139
142.82	-1.78	0.139
142.84	-1.70	0.139
142.85	-1.62	0.139
142.87	-1.53	0.139
142.89	-1.45	0.139
142.90	-1.37	0.139
142.92	-1.28	0.139
142.94	-1.20	0.140
142.95	-1.12	0.140
142.97	-1.03	0.140
142.99	-0.95	0.140
143.00	-0.87	0.140
143.02	-0.78	0.140
143.04	-0.70	0.140
143.05	-0.62	0.140
143.07	-0.53	0.140
143.09	-0.45	0.140
143.10	-0.37	0.140
143.12	-0.28	0.140
143.14	-0.20	0.140
143.15	-0.12	0.140
143.17	-0.03	0.140
143.19	0.05	0.140
143.20	0.13	0.140
143.22	0.22	0.140
143.24	0.30	0.140
143.25	0.39	0.140
143.27	0.47	0.140
143.29	0.55	0.140
143.30	0.64	0.140
143.32	0.72	0.140
143.34	0.80	0.140
143.35	0.88	0.140
143.37	0.97	0.140
143.39	1.05	0.140
143.40	1.14	0.140
143.42	1.22	0.140
143.44	1.30	0.140
143.45	1.39	0.140
143.47	1.47	0.140
143.49	1.55	0.140
143.50	1.64	0.140
143.52	1.72	0.140
143.54	1.80	0.140
143.55	1.89	0.140
143.57	1.97	0.140
143.59	2.05	0.140
143.60	2.14	0.140
143.62	2.22	0.140
143.64	2.30	0.140
143.65	2.39	0.140
143.67	2.47	0.140
143.69	2.55	0.140
143.70	2.64	0.140
143.72	2.72	0.141
143.74	2.80	0.141
143.75	2.89	0.141
143.77	2.97	0.141
143.79	3.05	0.141
143.80	3.14	0.141
143.82	3.22	0.141
143.84	3.30	0.141
143.85	3.39	0.141
143.87	3.47	0.141
143.89	3.55	0.141
143.90	3.64	0.141
143.92	3.72	0.141
143.94	3.81	0.141
143.95	3.89	0.141
143.97	3.97	0.141
143.99	4.06	0.141
144.00	4.14	0.141
144.02	4.22	0.141
144.04	4.30	0.141
144.05	4.39	0.141
144.07	4.47	0.141
144.09	4.56	0.141
144.10	4.64	0.141
144.12	4.72	0.141
144.14	4.81	0.141
144.15	4.89	0.141
144.17	4.97	0.141
144.19	5.06	0.141
144.20	5.14	0.141
144.22	5.22	0.141
144.24	5.31	0.141
144.25	5.39	0.141
144.27	5.47	0.141
144.29	5.56	0.141
144.30	5.64	0.141
144.32	5.72	0.141
144.34	5.81	0.141
144.35	5.89	0.141
144.37	5.97	0.141
144.39	6.06	0.141
144.40	6.14	0.141
144.42	6.22	0.142
144.44	6.31	0.142
144.45	6.39	0.142
144.47	6.47	0.142
144.49	6.56	0.142
144.50	6.64	0.142
144.52	6.73	0.142
144.54	6.81	0.142
144.55	6.89	0.142
144.57	6.97	0.142
144.59	7.06	0.142
144.60	7.14	0.142
144.62	7.22	0.142
144.64	7.31	0.142
144.65	7.39	0.142
144.67	7.47	0.142
144.69	7.56	0.142
144.70	7.64	0.142
144.72	7.72	0.142
144.74	7.81	0.142
144.75	7.89	0.142
144.77	7.98	0.142
144.79	8.06	0.142
144.80	8.14	0.142
144.82	8.23	0.142
144.84	8.31	0.142
144.85	8.39	0.142
144.87	8.48	0.142
144.89	8.56	0.142
144.90	8.64	0.142
144.92	8.73	0.142
144.94	8.81	0.142
144.95	8.89	0.142
144.97	8.98	0.142
144.99	9.06	0.142
145.00	9.14	0.142
145.02	9.23	0.142
145.04	9.31	0.142
145.05	9.39	0.142
145.07	9.48	0.142
145.09	9.56	0.143
145.10	9.64	0.143
145.12	9.73	0.143
145.14	9.81	0.143
145.15	9.89	0.143
145.17	9.98	0.143
145.19	10.06	0.143
145.20	10.14	0.143
145.22	10.23	0.143
145.24	10.31	0.143
145.25	10.39	0.143
145.27	10.48	0.143
145.29	10.56	0.143
145.30	10.64	0.143
145.32	10.73	0.143
145.34	10.81	0.143
145.35	10.89	0.143
145.37	10.98	0.143
145.39	11.06	0.143
145.40	11.14	0.143
145.42	11.23	0.143
145.44	11.31	0.143
145.45	11.39	0.143
145.47	11.48	0.143
145.49	11.56	0.143
145.50	11.65	0.143
145.52	11.73	0.143
145.54	11.81	0.143
145.55	11.90	0.143
145.57	11.98	0.143
145.59	12.06	0.143
145.60	12.15	0.143
145.62	12.23	0.143
145.64	12.31	0.143
145.65	12.39	0.143
145.67	12.48	0.143
145.69	12.56	0.143
145.70	12.64	0.143
145.72	12.73	0.143
145.74	12.81	0.143
145.75	12.90	0.143
145.77	12.98	0.143
145.79	13.06	0.143
145.80	13.15	0.143
145.82	13.23	0.143
145.84	13.31	0.143
145.85	13.40	0.144
145.87	13.48	0.144
145.89	13.56	0.144
145.90	13.65	0.144
145.92	13.73	0.144
145.94	13.81	0.144
145.95	13.90	0.144
145.97	13.98	0.144
145.99	14.06	0.144
146.00	14.15	0.144
146.02	14.23	0.144
146.04	14.31	0.144
146.05	14.40	0.144
146.07	14.48	0.144
146.09	14.56	0.144
146.10	14.65	0.144
146.12	14.73	0.144
146.14	14.81	0.144
146.15	14.90	0.144
146.17	14.98	0.144
146.19	15.06	0.144
146.20	15.15	0.144
146.22	15.23	0.144
146.24	15.32	0.144
146.25	15.40	0.144
146.27	15.48	0.144
146.29	15.56	0.144
146.30	15.65	0.144
146.32	15.73	0.144
146.34	15.81	0.144
146.35	15.90	0.144
146.37	15.98	0.144
146.39	16.07	0.144
146.40	16.15	0.144
146.42	16.23	0.144
146.44	16.32	0.144
146.45	16.40	0.144
146.47	16.48	0.145
146.49	16.57	0.145
146.50	16.65	0.145
146.52	16.73	0.145
146.54	16.82	0.145
146.55	16.90	0.145
146.57	16.98	0.145
146.59	17.07	0.145
146.60	17.15	0.145
146.62	17.23	0.145
146.64	17.32	0.145
146.65	17.40	0.145
146.67	17.48	0.145
146.69	17.57	0.145
146.70	17.65	0.145
146.72	17.73	0.145
146.74	17.82	0.145
146.75	17.90	0.145
146.77	17.98	0.145
146.79	18.07	0.145
146.80	18.15	0.145
146.82	18.23	0.145
146.84	18.32	0.145
146.85	18.40	0.145
146.87	18.49	0.145
146.89	18.57	0.145
146.90	18.65	0.145
146.92	18.73	0.145
146.94	18.82	0.145
146.95	18.90	0.145
146.97	18.98	0.145
146.99	19.07	0.145
147.00	19.15	0.145
147.02	19.23	0.145
147.04	19.32	0.145
147.05	19.40	0.145
147.07	19.49	0.145
147.09	19.57	0.145
147.10	19.65	0.145
147.12	19.74	0.145
147.14	19.82	0.145
147.15	19.90	0.145
147.17	19.99	0.146
147.19	20.07	0.146
147.20	20.15	0.146
147.22	20.24	0.146
147.24	20.32	0.146
147.25	20.40	0.146
147.27	20.49	0.146
147.29	20.57	0.146
147.30	20.65	0.146
147.32	20.74	0.146
147.34	20.82	0.146
147.35	20.90	0.146
147.37	20.99	0.146
147.39	21.07	0.146
147.40	21.15	0.146
147.42	21.24	0.146
147.44	21.32	0.146
147.45	21.40	0.146
147.47	21.49	0.146
147.49	21.57	0.146
147.50	21.65	0.146
147.52	21.74	0.146
147.54	21.82	0.146
147.55	21.90	0.146
147.57	21.99	0.146
147.59	22.07	0.146
147.60	22.15	0.146
147.62	22.24	0.146
147.64	22.32	0.146
147.65	22.40	0.146
147.67	22.49	0.146
147.69	22.57	0.146
147.70	22.65	0.146
147.72	22.74	0.146
147.74	22.82	0.146
147.75	22.90	0.146
147.77	22.99	0.147
147.79	23.07	0.147
147.80	23.15	0.147
147.82	23.24	0.147
147.84	23.32	0.147
147.85	23.40	0.147
147.87	23.49	0.147
147.89	23.57	0.147
147.90	23.65	0.147
147.92	23.74	0.147
147.94	23.82	0.147
147.95	23.90	0.147
147.97	23.99	0.147
147.99	24.07	0.147
148.00	24.16	0.147
148.02	24.24	0.147
148.04	24.32	0.147
148.05	24.41	0.147
148.07	24.49	0.147
148.09	24.57	0.147
148.10	24.66	0.147
148.12	24.74	0.147
148.14	24.82	0.147
148.15	24.90	0.147
148.17	24.99	0.147
148.19	25.07	0.147
148.20	25.16	0.147
148.22	25.24	0.147
148.24	25.32	0.147
148.25	25.41	0.147
148.27	25.49	0.147
148.29	25.57	0.147
148.30	25.66	0.147
148.32	25.74	0.147
148.34	25.82	0.147
148.35	25.91	0.147
148.37	25.99	0.147
148.39	26.07	0.147
148.40	26.16	0.147
148.42	26.24	0.147
148.44	26.32	0.148
148.45	26.41	0.148
148.47	26.49	0.148
148.49	26.57	0.148
148.50	26.66	0.148
148.52	26.74	0.148
148.54	26.83	0.148
148.55	26.91	0.148
148.57	26.99	0.148
148.59	27.07	0.148
148.60	27.16	0.148
148.62	27.24	0.148
148.64	27.32	0.148
148.65	27.41	0.148
148.67	27.49	0.148
148.69	27.58	0.148
148.70	27.66	0.148
148.72	27.74	0.148
148.74	27.83	0.148
148.75	27.91	0.148
148.77	27.99	0.148
148.79	28.08	0.148
148.80	28.16	0.148
148.82	28.24	0.148
148.84	28.33	0.148
148.85	28.41	0.148
148.87	28.49	0.148
148.89	28.57	0.148
148.90	28.66	0.148
148.92	28.74	0.148
148.94	28.83	0.148
148.95	28.91
148.97	28.99
148.99	29.07
149.00
149.01