File: DSC/2023_06_10_CBD_Al_NonHerm_Tzero.txt
Filename	2023_06_10_CBD_Al_NonHerm_Tzero
Instrument name	DSC2A-00468 (192.168.1.100)
Operator	JLY
rundate	6/11/2023
Sample name	2023_06_10_CBD_Al_NonHerm_Tzero
proceduresegments	Data Off ; Equilibrate 30.00 °C; Data On ; Ramp 10.00 °C/min to 100.00 °C; Data Off ; Isothermal 1.0 min; Data On ; Ramp 10.00 °C/min to -50.00 °C; Data Off ; Isothermal 1.0 min; Data On ; Ramp 10.00 °C/min to 100.00 °C; Data Off ; Isothermal 1.0 min; Data On ; Ramp 10.00 °C/min to -50.00 °C; Data Off ; Isothermal 1.0 min; Data On ; Ramp 10.00 °C/min to 100.00 °C
[File Parameters]
Run date	6/11/2023 3:28:59 AM
Trios version	5.1.1.46572
Original File Name
Current File Name	C:\Users\yargerlab\Desktop\DSC Data\General\2023_06_10_CBD_Al_NonHerm_Tzero.tri
[Procedure]
Procedure Name	DSC -30C to 160C at 10 C/min 3 cycles
Sample Name	2023_06_10_CBD_Al_NonHerm_Tzero
Sample Mass	5.06 mg
Reference Sample Mass	0 mg
Pan Mass	51.14 mg
Pan Number	16
Reference Pan Mass	51.33 mg
Reference Pan Number	10
Pan Type	Tzero Aluminum
Comments	CBD  in Tzero Al non-herm std lid in Pan.  Last run 05/22/23.  Been in Y1 Tray since 05/22/23.  Test to see if humidity exposure causes crystallization.  See how much the sample has changed being in an open pan in Y1 DSC tray.
Project Name	ASDs
Operator	JLY
Test	Custom
Unload Max Temperature	30
Unload Min Temperature	30
Load Max Temperature	30
Load Min Temperature	30
Stop on Gas Flow Error	Yes
[Signal List]
Signal #1	Time (min)
Signal #2	Temperature (°C)
Signal #3	Heat Flow (mW)
Signal #4	Delta T (µV)
Signal #5	Delta Tzero (µV)
Signal #6	Tzero Temperature (°C)
Signal #7	Cell Purge (mL/min)
Signal #8	Heater Temp (°C)
Signal #9	Power Delivered (W)
Signal #10	Reference Junction Temperature (°C)
Signal #11	Flange Temperature (°C)
Signal #12	Heat Flow Phase (rad)
Signal #13	Total Heat Capacity (J/°C)
Signal #14	Heat Capacity (J/°C)
[Configuration]
Company Name	ASU
Instrument Name	DSC2A-00468
Instrument Type	DSC2500
Serial Number	DSC2A-00468
IP	192.168.1.100
Location of Instrument	MRRC
DisplayType	Unknown
Sample Interval 	0.1 s/pt
Selected Heat Flow	T4P
Exotherm Direction	Down
Cell Serial	DRC2-00792
Lid Type	Standard
Cooler	RCS 90
Leave Cooler on at End of Sequence	On
Gas 2	Nitrogen
Gas Selected	Channel 1
Flow Rate	50 mL/min
Secondary Purge	On
Licensed Heat Flow	Heat Flow T4P
Modulation Licensed	Yes
[Versions]
Common IDD Version	1
Cortex Version	VER 2.10.2.31
Driver	5.0.0.6
GDM Version	1.0.3.3
TouchscreenVersion	1.0.0.16145
FEP Version	1.2.1.21
FEP Bootloader	2.0.0.5
AutoSampler Version	2.1.1.26
Auto Sampler Bootloader	2.0.0.5
FCM Version	1.1.0.3
FCM Bootloader	2.0.0.5
[Experiment Logs]
Experiment Log Entry # 1	Data On set to 0
Experiment Log Entry # 3	Equilibrate Segment 30 (C) Started
Experiment Log Entry # 5	Air Cool is off.
Experiment Log Entry # 7	Data On set to 1
Experiment Log Entry # 9	Ramp Segment 10 C/min to 100 Started
Experiment Log Entry # 11	Data On set to 0
Experiment Log Entry # 13	Isothermal Segment 1 min started
Experiment Log Entry # 15	Data On set to 1
Experiment Log Entry # 17	Ramp Segment 10 C/min to -50 Started
Experiment Log Entry # 19	Data On set to 0
Experiment Log Entry # 21	Isothermal Segment 1 min started
Experiment Log Entry # 23	Data On set to 1
Experiment Log Entry # 25	Ramp Segment 10 C/min to 100 Started
Experiment Log Entry # 27	Data On set to 0
Experiment Log Entry # 29	Isothermal Segment 1 min started
Experiment Log Entry # 31	Data On set to 1
Experiment Log Entry # 33	Ramp Segment 10 C/min to -50 Started
Experiment Log Entry # 35	Data On set to 0
Experiment Log Entry # 37	Isothermal Segment 1 min started
Experiment Log Entry # 39	Data On set to 1
Experiment Log Entry # 41	Ramp Segment 10 C/min to 100 Started
[Method Log]
Method Log Entry # 1	Data Off
Method Log Entry # 2	Equilibrate 30 °C
Method Log Entry # 3	Data On
Method Log Entry # 4	(Ramp 92852) Ramp 10 °C/minute to 100 °C
Method Log Entry # 5	Data Off
Method Log Entry # 6	Isothermal 1 minutes
Method Log Entry # 7	Data On
Method Log Entry # 8	(Ramp 92856) Ramp 10 °C/minute to -50 °C
Method Log Entry # 9	Data Off
Method Log Entry # 10	Isothermal 1 minutes
Method Log Entry # 11	Data On
Method Log Entry # 12	(Ramp 92860) Ramp 10 °C/minute to 100 °C
Method Log Entry # 13	Data Off
Method Log Entry # 14	Isothermal 1 minutes
Method Log Entry # 15	Data On
Method Log Entry # 16	(Ramp 92864) Ramp 10 °C/minute to -50 °C
Method Log Entry # 17	Data Off
Method Log Entry # 18	Isothermal 1 minutes
Method Log Entry # 19	Data On
Method Log Entry # 20	(Ramp 92868) Ramp 10 °C/minute to 100 °C
Cell Serial	DRC2-00792
[T1 Calibration]
Slope	-0.008529666
Offset	9.636258
Initial Temperature	98.23
GUID	f8bfdadc-4977-4fdf-ba6d-0ba9134940c3
[TZero Calibration]
Date Applied	11/29/2022 4:06:13 PM
Description	From -89.059 °C to 396.009 °C at 20.000°C/min
Gas Type	Nitrogen
Pan Type	None
Source Files 1	C:\Users\yargerlab\Desktop\DSC Data\General\TZero_calibration_11_29_22_2nd(2).tri
Source Files 2	C:\Users\yargerlab\Desktop\DSC Data\General\TZero_calibration_11_29_22_2nd(3).tri
Delta T Offset	13.05235
Delta T Slope	-0.007271007
Delta T0 Offset	-13.69128
Delta T0 Slope	0.06063341
[Temperature Calibration]
Date Applied	11/29/2022 7:12:28 PM
Description	From 106.590 °C to 186.590 °C at 10.000°C/min
Gas Type	Nitrogen
Pan Type	Tzero Aluminum Hermetic
Source Files 1	C:\Users\yargerlab\Desktop\DSC Data\General\Indium(6).tri
Measured 1	157.391
Known 1	156.598
[Cell Constant Calibration]
Date Applied	11/29/2022 7:12:29 PM
Description	From 106.590 °C to 186.590 °C at 10.000°C/min
Gas Type	Nitrogen
Pan Type	Tzero Aluminum Hermetic
Source Files 1	C:\Users\yargerlab\Desktop\DSC Data\General\Indium(6).tri
T4P KCell	1.006051
Onset Slope	63.26126 mW/°C
[Direct Cp Calibration]
Date Applied	11/30/2022 11:04:51 AM
Description	From -79.983 °C to 298.409 °C at 10.000°C/min
Gas Type	Nitrogen
Pan Type	Tzero Aluminum Hermetic
Source Files 1	C:\Users\yargerlab\Desktop\DSC Data\General\Sapphire_Heat_Capacity_11_30_22.tri
[Rev Cp Calibration]
Date Applied	11/30/2022 1:58:51 PM
Description	From -79.996 °C to 292.812 °C at 3.000°C/min
Gas Type	Nitrogen
Pan Type	Tzero Aluminum Hermetic
Source Files 1	C:\Users\yargerlab\Desktop\DSC Data\General\Sapphire_MDSC_Calibration_11_30_22.tri
[step]
Ramp 10.00 °C/min to 100.00 °C
Time	Temperature	Heat Flow (Normalized)
min	°C	W/g
0.00	30.06	-0.016
0.01	30.06	-0.016
0.01	30.06	-0.015
0.01	30.06	-0.015
0.02	30.06	-0.015
0.03	30.06	-0.015
0.03	30.06	-0.015
0.03	30.06	-0.014
0.04	30.07	-0.014
0.05	30.07	-0.013
0.05	30.07	-0.013
0.05	30.08	-0.012
0.06	30.08	-0.011
0.07	30.09	-0.010
0.07	30.10	-0.009
0.08	30.11	-0.007
0.08	30.12	-0.005
0.08	30.14	-0.001
0.09	30.15	0.004
0.09	30.17	0.009
0.10	30.18	0.014
0.11	30.20	0.020
0.11	30.23	0.026
0.12	30.25	0.033
0.12	30.28	0.040
0.13	30.30	0.047
0.13	30.33	0.056
0.14	30.36	0.064
0.14	30.39	0.073
0.14	30.42	0.082
0.15	30.45	0.092
0.16	30.49	0.102
0.16	30.52	0.112
0.16	30.55	0.121
0.17	30.59	0.129
0.18	30.63	0.139
0.18	30.66	0.147
0.19	30.70	0.157
0.19	30.74	0.165
0.19	30.78	0.172
0.20	30.82	0.179
0.21	30.86	0.186
0.21	30.89	0.193
0.21	30.93	0.199
0.22	30.98	0.206
0.23	31.02	0.212
0.23	31.06	0.218
0.24	31.10	0.223
0.24	31.14	0.228
0.24	31.18	0.233
0.25	31.23	0.238
0.26	31.27	0.242
0.26	31.31	0.247
0.26	31.36	0.252
0.27	31.40	0.255
0.28	31.44	0.259
0.28	31.49	0.263
0.29	31.53	0.267
0.29	31.58	0.271
0.30	31.62	0.275
0.30	31.67	0.278
0.30	31.71	0.281
0.31	31.76	0.284
0.31	31.80	0.287
0.32	31.85	0.291
0.33	31.90	0.293
0.33	31.94	0.295
0.34	31.99	0.298
0.34	32.04	0.301
0.35	32.08	0.303
0.35	32.13	0.307
0.35	32.18	0.309
0.36	32.22	0.310
0.36	32.27	0.311
0.37	32.32	0.314
0.38	32.37	0.317
0.38	32.41	0.318
0.39	32.46	0.318
0.39	32.51	0.321
0.40	32.56	0.324
0.40	32.60	0.326
0.40	32.65	0.326
0.41	32.70	0.326
0.41	32.75	0.327
0.42	32.80	0.329
0.43	32.85	0.330
0.43	32.89	0.332
0.44	32.94	0.332
0.44	32.99	0.333
0.45	33.04	0.335
0.45	33.09	0.337
0.45	33.14	0.338
0.46	33.19	0.338
0.46	33.23	0.338
0.47	33.28	0.339
0.48	33.33	0.340
0.48	33.38	0.341
0.49	33.43	0.341
0.49	33.48	0.342
0.50	33.53	0.343
0.50	33.58	0.344
0.50	33.62	0.345
0.51	33.67	0.345
0.51	33.72	0.345
0.52	33.77	0.346
0.53	33.82	0.346
0.53	33.87	0.347
0.53	33.92	0.348
0.54	33.97	0.348
0.55	34.02	0.349
0.55	34.07	0.349
0.55	34.12	0.349
0.56	34.17	0.350
0.57	34.21	0.350
0.57	34.26	0.350
0.58	34.31	0.351
0.58	34.36	0.352
0.58	34.41	0.352
0.59	34.46	0.352
0.60	34.51	0.352
0.60	34.56	0.353
0.60	34.61	0.353
0.61	34.66	0.353
0.62	34.71	0.353
0.62	34.76	0.353
0.63	34.81	0.354
0.63	34.86	0.354
0.63	34.91	0.354
0.64	34.96	0.354
0.65	35.00	0.355
0.65	35.05	0.355
0.65	35.10	0.355
0.66	35.15	0.355
0.67	35.20	0.355
0.67	35.25	0.356
0.68	35.30	0.356
0.68	35.35	0.356
0.68	35.40	0.356
0.69	35.45	0.356
0.70	35.50	0.356
0.70	35.55	0.356
0.70	35.60	0.356
0.71	35.65	0.357
0.72	35.70	0.357
0.72	35.75	0.357
0.73	35.80	0.357
0.73	35.85	0.357
0.73	35.90	0.357
0.74	35.95	0.357
0.75	36.00	0.357
0.75	36.05	0.358
0.75	36.10	0.358
0.76	36.14	0.358
0.77	36.19	0.358
0.77	36.24	0.358
0.78	36.29	0.358
0.78	36.34	0.358
0.78	36.39	0.358
0.79	36.44	0.358
0.80	36.49	0.359
0.80	36.54	0.359
0.80	36.59	0.359
0.81	36.64	0.359
0.82	36.69	0.359
0.82	36.74	0.359
0.83	36.79	0.359
0.83	36.84	0.359
0.83	36.89	0.359
0.84	36.94	0.360
0.85	36.99	0.360
0.85	37.04	0.360
0.85	37.09	0.360
0.86	37.14	0.360
0.87	37.19	0.360
0.87	37.24	0.360
0.88	37.29	0.360
0.88	37.34	0.360
0.88	37.39	0.360
0.89	37.44	0.361
0.90	37.49	0.361
0.90	37.54	0.361
0.90	37.59	0.361
0.91	37.64	0.361
0.92	37.69	0.361
0.92	37.74	0.361
0.93	37.79	0.361
0.93	37.84	0.361
0.93	37.89	0.361
0.94	37.94	0.361
0.95	37.99	0.362
0.95	38.04	0.362
0.95	38.09	0.362
0.96	38.14	0.362
0.97	38.19	0.362
0.97	38.24	0.362
0.98	38.29	0.362
0.98	38.34	0.362
0.98	38.39	0.362
0.99	38.44	0.362
1.00	38.48	0.362
1.00	38.53	0.363
1.00	38.58	0.363
1.01	38.63	0.363
1.02	38.68	0.363
1.02	38.73	0.363
1.03	38.78	0.363
1.03	38.83	0.363
1.03	38.88	0.363
1.04	38.93	0.363
1.05	38.98	0.363
1.05	39.03	0.363
1.05	39.08	0.363
1.06	39.13	0.363
1.07	39.18	0.364
1.07	39.23	0.364
1.08	39.28	0.364
1.08	39.33	0.364
1.08	39.38	0.364
1.09	39.43	0.364
1.09	39.48	0.364
1.10	39.53	0.364
1.11	39.58	0.364
1.11	39.63	0.364
1.12	39.68	0.364
1.12	39.73	0.364
1.13	39.78	0.364
1.13	39.83	0.364
1.13	39.88	0.364
1.14	39.93	0.365
1.14	39.98	0.365
1.15	40.03	0.365
1.16	40.08	0.365
1.16	40.13	0.365
1.17	40.18	0.365
1.17	40.23	0.365
1.18	40.28	0.365
1.18	40.33	0.365
1.18	40.38	0.365
1.19	40.43	0.365
1.19	40.48	0.365
1.20	40.53	0.365
1.21	40.58	0.365
1.21	40.63	0.365
1.22	40.68	0.365
1.22	40.73	0.366
1.23	40.78	0.366
1.23	40.83	0.366
1.23	40.88	0.366
1.24	40.93	0.366
1.24	40.98	0.366
1.25	41.03	0.366
1.26	41.08	0.366
1.26	41.13	0.366
1.27	41.18	0.366
1.27	41.23	0.366
1.28	41.28	0.366
1.28	41.33	0.366
1.28	41.38	0.366
1.29	41.43	0.366
1.29	41.48	0.366
1.30	41.53	0.366
1.31	41.58	0.366
1.31	41.63	0.366
1.32	41.68	0.367
1.32	41.73	0.367
1.33	41.78	0.367
1.33	41.83	0.367
1.33	41.88	0.367
1.34	41.93	0.367
1.34	41.98	0.367
1.35	42.03	0.367
1.36	42.08	0.367
1.36	42.13	0.367
1.37	42.18	0.367
1.37	42.23	0.367
1.38	42.28	0.367
1.38	42.33	0.367
1.38	42.38	0.367
1.39	42.43	0.367
1.39	42.48	0.367
1.40	42.53	0.367
1.41	42.58	0.367
1.41	42.63	0.367
1.42	42.68	0.367
1.42	42.73	0.367
1.43	42.78	0.368
1.43	42.83	0.368
1.43	42.88	0.368
1.44	42.93	0.368
1.44	42.98	0.368
1.45	43.03	0.368
1.46	43.08	0.368
1.46	43.13	0.368
1.47	43.18	0.368
1.47	43.23	0.368
1.48	43.28	0.368
1.48	43.33	0.368
1.48	43.38	0.368
1.49	43.43	0.368
1.49	43.48	0.368
1.50	43.53	0.368
1.51	43.58	0.368
1.51	43.63	0.368
1.52	43.68	0.368
1.52	43.73	0.368
1.53	43.78	0.368
1.53	43.83	0.368
1.53	43.88	0.368
1.54	43.93	0.368
1.54	43.98	0.368
1.55	44.03	0.368
1.56	44.08	0.368
1.56	44.13	0.369
1.57	44.18	0.369
1.57	44.23	0.369
1.58	44.28	0.369
1.58	44.33	0.369
1.58	44.38	0.369
1.59	44.43	0.369
1.59	44.48	0.369
1.60	44.53	0.369
1.61	44.58	0.369
1.61	44.63	0.369
1.62	44.68	0.369
1.62	44.73	0.369
1.63	44.78	0.369
1.63	44.83	0.369
1.63	44.88	0.369
1.64	44.93	0.369
1.64	44.98	0.369
1.65	45.03	0.369
1.66	45.08	0.369
1.66	45.13	0.369
1.67	45.18	0.369
1.67	45.23	0.369
1.68	45.28	0.369
1.68	45.33	0.369
1.68	45.38	0.369
1.69	45.43	0.369
1.69	45.48	0.370
1.70	45.53	0.370
1.71	45.58	0.370
1.71	45.63	0.370
1.72	45.68	0.370
1.72	45.73	0.370
1.73	45.78	0.370
1.73	45.83	0.370
1.73	45.88	0.370
1.74	45.93	0.370
1.74	45.98	0.370
1.75	46.03	0.370
1.76	46.08	0.370
1.76	46.13	0.370
1.77	46.18	0.370
1.77	46.23	0.370
1.78	46.28	0.370
1.78	46.33	0.370
1.78	46.38	0.370
1.79	46.43	0.370
1.79	46.48	0.370
1.80	46.53	0.370
1.81	46.58	0.370
1.81	46.63	0.370
1.82	46.68	0.370
1.82	46.73	0.370
1.83	46.78	0.370
1.83	46.83	0.370
1.83	46.88	0.370
1.84	46.93	0.370
1.84	46.98	0.371
1.85	47.03	0.371
1.86	47.08	0.371
1.86	47.13	0.371
1.87	47.18	0.371
1.87	47.23	0.371
1.88	47.28	0.371
1.88	47.33	0.371
1.88	47.38	0.371
1.89	47.43	0.371
1.89	47.48	0.371
1.90	47.53	0.371
1.91	47.58	0.371
1.91	47.63	0.371
1.92	47.68	0.371
1.92	47.73	0.371
1.93	47.78	0.371
1.93	47.83	0.371
1.93	47.88	0.371
1.94	47.93	0.371
1.94	47.98	0.371
1.95	48.03	0.371
1.96	48.08	0.371
1.96	48.13	0.371
1.97	48.18	0.371
1.97	48.23	0.371
1.98	48.28	0.371
1.98	48.33	0.371
1.98	48.38	0.371
1.99	48.43	0.371
1.99	48.48	0.371
2.00	48.53	0.371
2.01	48.58	0.372
2.01	48.63	0.372
2.02	48.68	0.372
2.02	48.73	0.372
2.03	48.78	0.372
2.03	48.83	0.372
2.03	48.88	0.372
2.04	48.93	0.372
2.04	48.98	0.372
2.05	49.03	0.372
2.06	49.08	0.372
2.06	49.13	0.372
2.07	49.18	0.372
2.07	49.23	0.372
2.08	49.28	0.372
2.08	49.33	0.372
2.08	49.38	0.372
2.09	49.43	0.372
2.09	49.48	0.372
2.10	49.53	0.372
2.11	49.58	0.372
2.11	49.63	0.372
2.12	49.68	0.372
2.12	49.73	0.372
2.13	49.78	0.372
2.13	49.83	0.372
2.14	49.88	0.372
2.14	49.93	0.372
2.14	49.98	0.372
2.15	50.03	0.373
2.16	50.08	0.373
2.16	50.13	0.373
2.16	50.18	0.373
2.17	50.23	0.373
2.18	50.28	0.373
2.18	50.33	0.373
2.19	50.38	0.373
2.19	50.43	0.373
2.19	50.48	0.373
2.20	50.53	0.373
2.21	50.58	0.373
2.21	50.63	0.373
2.21	50.68	0.373
2.22	50.73	0.373
2.23	50.78	0.373
2.23	50.83	0.373
2.24	50.88	0.373
2.24	50.93	0.373
2.24	50.98	0.373
2.25	51.03	0.373
2.26	51.08	0.373
2.26	51.13	0.373
2.26	51.18	0.373
2.27	51.23	0.373
2.28	51.28	0.373
2.28	51.33	0.373
2.29	51.38	0.373
2.29	51.43	0.373
2.29	51.48	0.373
2.30	51.53	0.373
2.31	51.58	0.374
2.31	51.63	0.374
2.31	51.68	0.374
2.32	51.73	0.374
2.33	51.78	0.374
2.33	51.83	0.374
2.34	51.88	0.374
2.34	51.93	0.374
2.34	51.98	0.374
2.35	52.03	0.374
2.36	52.08	0.374
2.36	52.13	0.374
2.36	52.18	0.374
2.37	52.23	0.374
2.38	52.28	0.374
2.38	52.33	0.374
2.39	52.38	0.374
2.39	52.43	0.374
2.39	52.48	0.374
2.40	52.53	0.374
2.41	52.58	0.374
2.41	52.63	0.374
2.41	52.68	0.374
2.42	52.73	0.374
2.43	52.78	0.374
2.43	52.83	0.374
2.44	52.88	0.374
2.44	52.93	0.374
2.44	52.98	0.374
2.45	53.03	0.374
2.46	53.08	0.374
2.46	53.13	0.374
2.46	53.18	0.375
2.47	53.23	0.375
2.48	53.28	0.375
2.48	53.33	0.375
2.49	53.38	0.375
2.49	53.43	0.375
2.49	53.48	0.375
2.50	53.53	0.375
2.51	53.58	0.375
2.51	53.63	0.375
2.51	53.68	0.375
2.52	53.73	0.375
2.53	53.78	0.375
2.53	53.83	0.375
2.54	53.88	0.375
2.54	53.93	0.375
2.54	53.98	0.375
2.55	54.03	0.375
2.56	54.08	0.375
2.56	54.13	0.375
2.56	54.18	0.375
2.57	54.23	0.375
2.58	54.28	0.375
2.58	54.33	0.375
2.59	54.38	0.375
2.59	54.43	0.375
2.59	54.48	0.375
2.60	54.53	0.375
2.61	54.58	0.376
2.61	54.63	0.376
2.61	54.68	0.376
2.62	54.73	0.376
2.63	54.78	0.376
2.63	54.83	0.376
2.64	54.88	0.376
2.64	54.93	0.376
2.64	54.98	0.376
2.65	55.03	0.376
2.66	55.08	0.376
2.66	55.13	0.376
2.66	55.18	0.376
2.67	55.23	0.376
2.68	55.28	0.376
2.68	55.33	0.376
2.69	55.38	0.376
2.69	55.43	0.376
2.69	55.48	0.376
2.70	55.53	0.376
2.71	55.58	0.376
2.71	55.63	0.376
2.71	55.68	0.376
2.72	55.73	0.376
2.73	55.78	0.376
2.73	55.83	0.376
2.74	55.88	0.376
2.74	55.93	0.376
2.74	55.98	0.376
2.75	56.03	0.376
2.76	56.08	0.376
2.76	56.13	0.376
2.76	56.18	0.377
2.77	56.23	0.377
2.78	56.28	0.377
2.78	56.33	0.377
2.79	56.38	0.377
2.79	56.43	0.377
2.79	56.48	0.377
2.80	56.53	0.377
2.81	56.58	0.377
2.81	56.63	0.377
2.81	56.68	0.377
2.82	56.73	0.377
2.83	56.78	0.377
2.83	56.83	0.377
2.84	56.89	0.377
2.84	56.93	0.377
2.84	56.98	0.377
2.85	57.03	0.377
2.86	57.08	0.377
2.86	57.13	0.377
2.86	57.18	0.377
2.87	57.23	0.377
2.88	57.28	0.377
2.88	57.34	0.377
2.89	57.38	0.377
2.89	57.44	0.377
2.89	57.48	0.377
2.90	57.53	0.377
2.91	57.58	0.378
2.91	57.63	0.378
2.91	57.69	0.378
2.92	57.73	0.378
2.93	57.79	0.378
2.93	57.84	0.378
2.94	57.89	0.378
2.94	57.93	0.378
2.94	57.99	0.378
2.95	58.04	0.378
2.96	58.09	0.378
2.96	58.14	0.378
2.96	58.19	0.378
2.97	58.24	0.378
2.98	58.29	0.378
2.98	58.34	0.378
2.99	58.39	0.378
2.99	58.44	0.378
2.99	58.49	0.378
3.00	58.54	0.378
3.01	58.59	0.378
3.01	58.64	0.378
3.01	58.69	0.378
3.02	58.74	0.378
3.03	58.79	0.378
3.03	58.84	0.378
3.04	58.89	0.378
3.04	58.94	0.378
3.04	58.99	0.378
3.05	59.04	0.378
3.06	59.09	0.378
3.06	59.14	0.378
3.06	59.19	0.379
3.07	59.24	0.379
3.08	59.29	0.379
3.08	59.34	0.379
3.09	59.39	0.379
3.09	59.44	0.379
3.09	59.49	0.379
3.10	59.54	0.379
3.11	59.59	0.379
3.11	59.64	0.379
3.11	59.69	0.379
3.12	59.74	0.379
3.13	59.79	0.379
3.13	59.84	0.379
3.14	59.89	0.379
3.14	59.94	0.379
3.14	59.99	0.379
3.15	60.04	0.379
3.16	60.09	0.379
3.16	60.14	0.379
3.16	60.19	0.379
3.17	60.24	0.379
3.18	60.29	0.379
3.18	60.34	0.379
3.19	60.39	0.379
3.19	60.44	0.379
3.19	60.49	0.379
3.20	60.54	0.379
3.21	60.59	0.379
3.21	60.64	0.380
3.21	60.69	0.380
3.22	60.74	0.380
3.23	60.79	0.380
3.23	60.84	0.380
3.24	60.89	0.380
3.24	60.94	0.380
3.24	60.99	0.380
3.25	61.04	0.380
3.26	61.09	0.380
3.26	61.14	0.380
3.26	61.19	0.380
3.27	61.24	0.380
3.28	61.29	0.380
3.28	61.34	0.380
3.29	61.39	0.380
3.29	61.44	0.380
3.29	61.49	0.380
3.30	61.54	0.380
3.31	61.59	0.380
3.31	61.64	0.380
3.31	61.69	0.380
3.32	61.74	0.380
3.33	61.79	0.380
3.33	61.83	0.380
3.34	61.89	0.380
3.34	61.94	0.380
3.34	61.99	0.380
3.35	62.04	0.380
3.36	62.09	0.380
3.36	62.14	0.381
3.36	62.19	0.381
3.37	62.24	0.381
3.38	62.29	0.381
3.38	62.34	0.381
3.39	62.39	0.381
3.39	62.44	0.381
3.39	62.49	0.381
3.40	62.54	0.381
3.41	62.59	0.381
3.41	62.64	0.381
3.41	62.69	0.381
3.42	62.74	0.381
3.43	62.79	0.381
3.43	62.84	0.381
3.44	62.88	0.381
3.44	62.94	0.381
3.44	62.99	0.381
3.45	63.04	0.381
3.46	63.09	0.381
3.46	63.14	0.381
3.46	63.19	0.381
3.47	63.24	0.382
3.48	63.29	0.382
3.48	63.34	0.382
3.49	63.39	0.382
3.49	63.44	0.382
3.49	63.49	0.382
3.50	63.54	0.382
3.51	63.59	0.382
3.51	63.64	0.382
3.51	63.69	0.382
3.52	63.74	0.382
3.53	63.79	0.382
3.53	63.84	0.382
3.54	63.89	0.382
3.54	63.94	0.382
3.54	63.99	0.382
3.55	64.04	0.382
3.56	64.09	0.382
3.56	64.14	0.383
3.56	64.19	0.383
3.57	64.24	0.383
3.58	64.29	0.383
3.58	64.34	0.383
3.59	64.39	0.383
3.59	64.44	0.383
3.59	64.49	0.383
3.60	64.54	0.383
3.61	64.59	0.383
3.61	64.64	0.383
3.61	64.69	0.383
3.62	64.74	0.383
3.63	64.79	0.383
3.63	64.84	0.383
3.64	64.89	0.383
3.64	64.94	0.383
3.64	64.99	0.383
3.65	65.04	0.383
3.66	65.09	0.383
3.66	65.14	0.383
3.66	65.19	0.384
3.67	65.24	0.384
3.68	65.29	0.384
3.68	65.34	0.384
3.69	65.39	0.384
3.69	65.44	0.384
3.69	65.49	0.384
3.70	65.54	0.384
3.71	65.59	0.384
3.71	65.64	0.384
3.71	65.69	0.384
3.72	65.74	0.384
3.73	65.79	0.384
3.73	65.84	0.384
3.74	65.89	0.384
3.74	65.94	0.384
3.74	65.99	0.384
3.75	66.04	0.384
3.76	66.09	0.384
3.76	66.14	0.384
3.76	66.19	0.384
3.77	66.24	0.384
3.78	66.29	0.385
3.78	66.34	0.385
3.79	66.39	0.385
3.79	66.44	0.385
3.79	66.49	0.385
3.80	66.54	0.385
3.81	66.59	0.385
3.81	66.64	0.385
3.81	66.69	0.385
3.82	66.74	0.385
3.83	66.79	0.385
3.83	66.84	0.385
3.84	66.89	0.385
3.84	66.94	0.385
3.84	66.99	0.385
3.85	67.04	0.385
3.86	67.09	0.385
3.86	67.14	0.385
3.86	67.19	0.385
3.87	67.24	0.385
3.88	67.29	0.385
3.88	67.34	0.385
3.89	67.39	0.385
3.89	67.44	0.385
3.89	67.49	0.385
3.90	67.54	0.385
3.91	67.59	0.385
3.91	67.64	0.386
3.91	67.69	0.386
3.92	67.74	0.386
3.93	67.79	0.386
3.93	67.84	0.386
3.94	67.89	0.386
3.94	67.94	0.386
3.94	67.99	0.386
3.95	68.04	0.386
3.96	68.09	0.386
3.96	68.14	0.386
3.96	68.19	0.386
3.97	68.24	0.386
3.98	68.29	0.386
3.98	68.34	0.386
3.99	68.39	0.386
3.99	68.44	0.386
3.99	68.49	0.386
4.00	68.54	0.386
4.01	68.59	0.386
4.01	68.64	0.386
4.01	68.69	0.386
4.02	68.74	0.386
4.03	68.79	0.386
4.03	68.84	0.387
4.04	68.89	0.387
4.04	68.94	0.387
4.04	68.99	0.387
4.05	69.04	0.387
4.06	69.09	0.387
4.06	69.14	0.387
4.06	69.19	0.387
4.07	69.24	0.387
4.08	69.29	0.387
4.08	69.34	0.387
4.09	69.39	0.387
4.09	69.44	0.387
4.09	69.49	0.387
4.10	69.54	0.387
4.11	69.59	0.387
4.11	69.64	0.387
4.11	69.69	0.387
4.12	69.74	0.387
4.13	69.79	0.387
4.13	69.85	0.387
4.14	69.89	0.388
4.14	69.94	0.388
4.14	69.99	0.388
4.15	70.04	0.388
4.16	70.09	0.388
4.16	70.14	0.388
4.16	70.19	0.388
4.17	70.24	0.388
4.18	70.29	0.388
4.18	70.35	0.388
4.19	70.40	0.388
4.19	70.45	0.388
4.19	70.49	0.388
4.20	70.55	0.388
4.21	70.59	0.388
4.21	70.65	0.388
4.21	70.70	0.388
4.22	70.75	0.388
4.23	70.80	0.388
4.23	70.85	0.388
4.24	70.90	0.388
4.24	70.95	0.388
4.24	71.00	0.388
4.25	71.05	0.388
4.26	71.10	0.389
4.26	71.15	0.389
4.26	71.20	0.389
4.27	71.25	0.389
4.28	71.30	0.389
4.28	71.35	0.389
4.29	71.40	0.389
4.29	71.45	0.389
4.30	71.50	0.389
4.30	71.55	0.389
4.30	71.60	0.389
4.31	71.65	0.389
4.31	71.70	0.389
4.32	71.75	0.389
4.33	71.80	0.389
4.33	71.85	0.389
4.34	71.90	0.389
4.34	71.95	0.389
4.35	72.00	0.389
4.35	72.05	0.389
4.35	72.10	0.389
4.36	72.15	0.389
4.36	72.20	0.389
4.37	72.25	0.389
4.38	72.30	0.389
4.38	72.35	0.390
4.39	72.40	0.390
4.39	72.45	0.390
4.40	72.50	0.390
4.40	72.55	0.390
4.40	72.60	0.390
4.41	72.65	0.390
4.41	72.70	0.390
4.42	72.75	0.390
4.43	72.80	0.390
4.43	72.85	0.390
4.44	72.90	0.390
4.44	72.95	0.390
4.45	73.00	0.390
4.45	73.05	0.390
4.45	73.10	0.390
4.46	73.15	0.390
4.46	73.20	0.390
4.47	73.25	0.390
4.48	73.30	0.390
4.48	73.35	0.390
4.49	73.40	0.390
4.49	73.45	0.390
4.50	73.50	0.390
4.50	73.55	0.390
4.50	73.60	0.391
4.51	73.65	0.391
4.51	73.70	0.391
4.52	73.75	0.391
4.53	73.80	0.391
4.53	73.85	0.391
4.54	73.90	0.391
4.54	73.95	0.391
4.55	74.00	0.391
4.55	74.05	0.391
4.55	74.10	0.391
4.56	74.15	0.391
4.56	74.20	0.391
4.57	74.25	0.391
4.58	74.30	0.391
4.58	74.35	0.391
4.59	74.40	0.391
4.59	74.45	0.391
4.60	74.50	0.391
4.60	74.55	0.391
4.60	74.60	0.391
4.61	74.65	0.391
4.61	74.70	0.391
4.62	74.75	0.391
4.63	74.80	0.392
4.63	74.85	0.392
4.64	74.90	0.392
4.64	74.95	0.392
4.65	75.00	0.392
4.65	75.05	0.392
4.65	75.10	0.392
4.66	75.15	0.392
4.66	75.20	0.392
4.67	75.25	0.392
4.68	75.30	0.392
4.68	75.35	0.392
4.69	75.40	0.392
4.69	75.45	0.392
4.70	75.50	0.392
4.70	75.55	0.392
4.70	75.60	0.392
4.71	75.65	0.392
4.71	75.70	0.392
4.72	75.75	0.392
4.73	75.80	0.393
4.73	75.85	0.393
4.74	75.90	0.393
4.74	75.95	0.393
4.75	76.00	0.393
4.75	76.05	0.393
4.75	76.10	0.393
4.76	76.15	0.393
4.76	76.20	0.393
4.77	76.25	0.393
4.78	76.30	0.393
4.78	76.35	0.393
4.79	76.40	0.393
4.79	76.45	0.393
4.80	76.50	0.393
4.80	76.55	0.393
4.80	76.60	0.393
4.81	76.65	0.393
4.81	76.70	0.393
4.82	76.75	0.393
4.83	76.80	0.394
4.83	76.85	0.394
4.84	76.90	0.394
4.84	76.95	0.394
4.85	77.00	0.394
4.85	77.05	0.394
4.85	77.10	0.394
4.86	77.15	0.394
4.86	77.20	0.394
4.87	77.25	0.394
4.88	77.30	0.394
4.88	77.35	0.394
4.89	77.40	0.394
4.89	77.45	0.394
4.90	77.50	0.394
4.90	77.55	0.394
4.90	77.60	0.394
4.91	77.65	0.394
4.91	77.70	0.394
4.92	77.75	0.395
4.93	77.80	0.395
4.93	77.85	0.395
4.94	77.90	0.395
4.94	77.95	0.395
4.95	78.00	0.395
4.95	78.05	0.395
4.95	78.10	0.395
4.96	78.15	0.395
4.96	78.20	0.395
4.97	78.25	0.395
4.98	78.30	0.395
4.98	78.35	0.395
4.99	78.40	0.395
4.99	78.45	0.395
5.00	78.50	0.395
5.00	78.55	0.395
5.00	78.60	0.395
5.01	78.65	0.395
5.01	78.70	0.395
5.02	78.75	0.395
5.03	78.80	0.395
5.03	78.85	0.396
5.04	78.90	0.396
5.04	78.95	0.396
5.05	79.00	0.396
5.05	79.05	0.396
5.05	79.10	0.396
5.06	79.15	0.396
5.06	79.20	0.396
5.07	79.25	0.396
5.08	79.30	0.396
5.08	79.35	0.396
5.09	79.40	0.396
5.09	79.45	0.396
5.10	79.50	0.396
5.10	79.55	0.396
5.10	79.60	0.396
5.11	79.65	0.396
5.11	79.70	0.396
5.12	79.75	0.396
5.13	79.80	0.396
5.13	79.85	0.396
5.14	79.90	0.396
5.14	79.95	0.396
5.15	80.00	0.396
5.15	80.05	0.397
5.15	80.10	0.397
5.16	80.15	0.397
5.16	80.20	0.397
5.17	80.25	0.397
5.18	80.30	0.397
5.18	80.35	0.397
5.19	80.40	0.397
5.19	80.45	0.397
5.20	80.50	0.397
5.20	80.55	0.397
5.20	80.60	0.397
5.21	80.65	0.397
5.21	80.71	0.397
5.22	80.75	0.397
5.23	80.80	0.397
5.23	80.85	0.397
5.24	80.90	0.397
5.24	80.96	0.397
5.25	81.00	0.397
5.25	81.05	0.397
5.25	81.11	0.397
5.26	81.15	0.397
5.26	81.21	0.398
5.27	81.25	0.398
5.28	81.30	0.398
5.28	81.36	0.398
5.29	81.41	0.398
5.29	81.45	0.398
5.30	81.50	0.398
5.30	81.56	0.398
5.30	81.60	0.398
5.31	81.65	0.398
5.31	81.70	0.398
5.32	81.76	0.398
5.33	81.80	0.398
5.33	81.85	0.398
5.34	81.90	0.398
5.34	81.96	0.398
5.35	82.01	0.398
5.35	82.06	0.398
5.35	82.11	0.398
5.36	82.15	0.398
5.36	82.21	0.398
5.37	82.26	0.398
5.38	82.31	0.398
5.38	82.36	0.398
5.39	82.41	0.398
5.39	82.46	0.398
5.40	82.51	0.399
5.40	82.56	0.399
5.40	82.61	0.399
5.41	82.66	0.399
5.41	82.71	0.399
5.42	82.76	0.399
5.43	82.81	0.399
5.43	82.86	0.399
5.44	82.91	0.399
5.44	82.96	0.399
5.45	83.01	0.399
5.45	83.06	0.399
5.45	83.11	0.399
5.46	83.16	0.399
5.46	83.21	0.399
5.47	83.26	0.399
5.48	83.31	0.399
5.48	83.36	0.399
5.49	83.41	0.399
5.49	83.46	0.399
5.50	83.51	0.399
5.50	83.56	0.399
5.50	83.61	0.399
5.51	83.66	0.399
5.51	83.71	0.399
5.52	83.76	0.399
5.53	83.81	0.399
5.53	83.86	0.399
5.54	83.91	0.400
5.54	83.96	0.400
5.55	84.01	0.400
5.55	84.06	0.400
5.55	84.11	0.400
5.56	84.16	0.400
5.56	84.21	0.400
5.57	84.26	0.400
5.58	84.31	0.400
5.58	84.36	0.400
5.59	84.41	0.400
5.59	84.46	0.400
5.60	84.51	0.400
5.60	84.56	0.400
5.60	84.61	0.400
5.61	84.66	0.400
5.61	84.71	0.400
5.62	84.76	0.400
5.63	84.81	0.400
5.63	84.86	0.400
5.64	84.91	0.400
5.64	84.96	0.400
5.65	85.01	0.400
5.65	85.06	0.400
5.65	85.11	0.400
5.66	85.16	0.400
5.66	85.21	0.400
5.67	85.26	0.400
5.68	85.31	0.400
5.68	85.36	0.400
5.69	85.41	0.400
5.69	85.46	0.401
5.70	85.51	0.401
5.70	85.56	0.401
5.70	85.61	0.401
5.71	85.66	0.401
5.71	85.71	0.401
5.72	85.76	0.401
5.73	85.81	0.401
5.73	85.86	0.401
5.74	85.91	0.401
5.74	85.96	0.401
5.75	86.01	0.401
5.75	86.06	0.401
5.75	86.11	0.401
5.76	86.16	0.401
5.76	86.21	0.401
5.77	86.26	0.401
5.78	86.31	0.401
5.78	86.36	0.401
5.79	86.41	0.401
5.79	86.46	0.401
5.80	86.51	0.401
5.80	86.56	0.401
5.80	86.61	0.401
5.81	86.66	0.401
5.81	86.71	0.401
5.82	86.76	0.401
5.83	86.81	0.401
5.83	86.86	0.402
5.84	86.91	0.402
5.84	86.96	0.402
5.85	87.01	0.402
5.85	87.06	0.402
5.85	87.11	0.402
5.86	87.16	0.402
5.86	87.21	0.402
5.87	87.26	0.402
5.88	87.31	0.402
5.88	87.36	0.402
5.89	87.41	0.402
5.89	87.46	0.402
5.90	87.51	0.402
5.90	87.56	0.402
5.90	87.61	0.402
5.91	87.66	0.402
5.91	87.71	0.402
5.92	87.76	0.402
5.93	87.81	0.402
5.93	87.86	0.402
5.94	87.91	0.402
5.94	87.96	0.402
5.95	88.01	0.402
5.95	88.06	0.403
5.95	88.11	0.403
5.96	88.16	0.403
5.96	88.21	0.403
5.97	88.26	0.403
5.98	88.31	0.403
5.98	88.36	0.403
5.99	88.41	0.403
5.99	88.46	0.403
6.00	88.51	0.403
6.00	88.56	0.403
6.00	88.61	0.403
6.01	88.66	0.403
6.01	88.71	0.403
6.02	88.76	0.403
6.03	88.81	0.403
6.03	88.86	0.403
6.04	88.91	0.403
6.04	88.96	0.403
6.05	89.01	0.403
6.05	89.06	0.403
6.05	89.11	0.403
6.06	89.16	0.403
6.06	89.21	0.403
6.07	89.26	0.403
6.08	89.31	0.403
6.08	89.36	0.404
6.09	89.41	0.404
6.09	89.46	0.404
6.10	89.51	0.404
6.10	89.56	0.404
6.10	89.61	0.404
6.11	89.66	0.404
6.11	89.71	0.404
6.12	89.76	0.404
6.13	89.81	0.404
6.13	89.86	0.404
6.14	89.91	0.404
6.14	89.96	0.404
6.15	90.01	0.404
6.15	90.06	0.404
6.15	90.11	0.404
6.16	90.17	0.404
6.16	90.21	0.404
6.17	90.26	0.404
6.18	90.31	0.404
6.18	90.36	0.404
6.19	90.41	0.404
6.19	90.46	0.404
6.20	90.51	0.404
6.20	90.56	0.404
6.20	90.61	0.404
6.21	90.66	0.404
6.21	90.71	0.404
6.22	90.76	0.405
6.23	90.81	0.405
6.23	90.86	0.405
6.24	90.91	0.405
6.24	90.97	0.405
6.25	91.01	0.405
6.25	91.06	0.405
6.25	91.11	0.405
6.26	91.16	0.405
6.26	91.21	0.405
6.27	91.26	0.405
6.28	91.31	0.405
6.28	91.36	0.405
6.29	91.41	0.405
6.29	91.47	0.405
6.30	91.52	0.405
6.30	91.56	0.405
6.30	91.61	0.405
6.31	91.67	0.405
6.31	91.72	0.405
6.32	91.77	0.405
6.33	91.82	0.405
6.33	91.87	0.406
6.34	91.92	0.406
6.34	91.97	0.406
6.35	92.01	0.406
6.35	92.07	0.406
6.35	92.12	0.406
6.36	92.17	0.406
6.36	92.22	0.406
6.37	92.26	0.406
6.38	92.32	0.406
6.38	92.37	0.406
6.39	92.42	0.406
6.39	92.46	0.406
6.40	92.51	0.406
6.40	92.56	0.406
6.40	92.61	0.406
6.41	92.67	0.406
6.41	92.72	0.406
6.42	92.77	0.406
6.43	92.82	0.406
6.43	92.87	0.406
6.44	92.92	0.406
6.44	92.97	0.406
6.45	93.01	0.406
6.45	93.07	0.407
6.45	93.11	0.407
6.46	93.17	0.407
6.46	93.22	0.407
6.47	93.27	0.407
6.48	93.32	0.407
6.48	93.37	0.407
6.49	93.42	0.407
6.49	93.47	0.407
6.50	93.52	0.407
6.50	93.57	0.407
6.50	93.62	0.407
6.51	93.66	0.407
6.51	93.72	0.407
6.52	93.77	0.407
6.53	93.82	0.407
6.53	93.87	0.407
6.54	93.92	0.407
6.54	93.97	0.407
6.55	94.02	0.407
6.55	94.07	0.407
6.55	94.12	0.407
6.56	94.17	0.407
6.56	94.22	0.408
6.57	94.27	0.408
6.58	94.32	0.408
6.58	94.37	0.408
6.59	94.42	0.408
6.59	94.47	0.408
6.60	94.52	0.408
6.60	94.57	0.408
6.60	94.62	0.408
6.61	94.67	0.408
6.61	94.72	0.408
6.62	94.77	0.408
6.63	94.82	0.408
6.63	94.87	0.408
6.64	94.92	0.408
6.64	94.97	0.408
6.65	95.02	0.408
6.65	95.07	0.408
6.65	95.12	0.408
6.66	95.17	0.408
6.66	95.22	0.408
6.67	95.27	0.408
6.68	95.32	0.408
6.68	95.37	0.408
6.69	95.42	0.408
6.69	95.47	0.408
6.70	95.52	0.409
6.70	95.57	0.409
6.70	95.62	0.409
6.71	95.67	0.409
6.71	95.72	0.409
6.72	95.77	0.409
6.73	95.82	0.409
6.73	95.87	0.409
6.74	95.92	0.409
6.74	95.97	0.409
6.75	96.02	0.409
6.75	96.07	0.409
6.75	96.12	0.409
6.76	96.17	0.409
6.76	96.22	0.409
6.77	96.27	0.409
6.78	96.32	0.409
6.78	96.37	0.409
6.79	96.42	0.409
6.79	96.47	0.409
6.80	96.52	0.409
6.80	96.57	0.409
6.80	96.62	0.409
6.81	96.67	0.410
6.81	96.72	0.410
6.82	96.77	0.410
6.83	96.82	0.410
6.83	96.87	0.410
6.84	96.92	0.410
6.84	96.97	0.410
6.85	97.02	0.410
6.85	97.07	0.410
6.85	97.12	0.410
6.86	97.17	0.410
6.86	97.22	0.410
6.87	97.27	0.410
6.88	97.32	0.410
6.88	97.37	0.410
6.89	97.42	0.410
6.89	97.47	0.410
6.90	97.52	0.410
6.90	97.57	0.410
6.90	97.62	0.410
6.91	97.67	0.410
6.91	97.72	0.411
6.92	97.77	0.411
6.93	97.82	0.411
6.93	97.87	0.411
6.94	97.92	0.411
6.94	97.97	0.411
6.95	98.02
6.95	98.07
6.95	98.12
6.96	98.17
6.96	98.22
6.97	98.27
6.98	98.32
6.98	98.37
6.99	98.42
6.99	98.47
7.00
7.00
7.00

[step]
Ramp 10.00 °C/min to -50.00 °C
Time	Temperature	Heat Flow (Normalized)
min	°C	W/g
8.00	100.10	-0.002
8.01	100.10	-0.002
8.02	100.10	-0.002
8.03	100.09	-0.002
8.04	100.09	-0.002
8.05	100.08	-0.003
8.06	100.07	-0.003
8.07	100.06	-0.007
8.08	100.03	-0.015
8.09	100.00	-0.029
8.10	99.97	-0.042
8.11	99.93	-0.059
8.12	99.88	-0.079
8.13	99.82	-0.101
8.14	99.76	-0.124
8.15	99.70	-0.149
8.16	99.63	-0.170
8.17	99.56	-0.192
8.18	99.48	-0.211
8.19	99.41	-0.229
8.20	99.33	-0.247
8.21	99.25	-0.260
8.22	99.17	-0.273
8.23	99.09	-0.287
8.24	99.00	-0.296
8.25	98.92	-0.306
8.26	98.83	-0.314
8.27	98.74	-0.324
8.28	98.65	-0.332
8.29	98.56	-0.340
8.30	98.47	-0.345
8.31	98.38	-0.353
8.32	98.29	-0.358
8.33	98.19	-0.363
8.34	98.10	-0.369
8.35	98.01	-0.371
8.36	97.91	-0.377
8.37	97.82	-0.380
8.38	97.72	-0.383
8.39	97.63	-0.385
8.40	97.53	-0.389
8.41	97.43	-0.391
8.42	97.34	-0.393
8.43	97.24	-0.395
8.44	97.15	-0.397
8.45	97.05	-0.399
8.46	96.95	-0.401
8.47	96.85	-0.403
8.48	96.76	-0.404
8.49	96.66	-0.405
8.50	96.56	-0.406
8.51	96.46	-0.407
8.52	96.36	-0.408
8.53	96.27	-0.409
8.54	96.17	-0.409
8.55	96.07	-0.410
8.56	95.97	-0.411
8.57	95.87	-0.412
8.58	95.78	-0.412
8.59	95.68	-0.412
8.60	95.58	-0.413
8.61	95.48	-0.414
8.62	95.38	-0.414
8.63	95.28	-0.414
8.64	95.18	-0.415
8.65	95.09	-0.415
8.66	94.99	-0.415
8.67	94.89	-0.415
8.68	94.79	-0.416
8.69	94.69	-0.416
8.70	94.59	-0.416
8.71	94.49	-0.417
8.72	94.39	-0.417
8.73	94.29	-0.417
8.74	94.19	-0.418
8.75	94.10	-0.418
8.76	94.00	-0.418
8.77	93.90	-0.418
8.78	93.80	-0.418
8.79	93.70	-0.419
8.80	93.60	-0.419
8.81	93.50	-0.419
8.82	93.40	-0.419
8.83	93.30	-0.419
8.84	93.20	-0.419
8.85	93.10	-0.420
8.86	93.00	-0.420
8.87	92.90	-0.420
8.88	92.80	-0.420
8.89	92.70	-0.420
8.90	92.61	-0.420
8.91	92.51	-0.421
8.92	92.41	-0.421
8.93	92.31	-0.421
8.94	92.21	-0.421
8.95	92.11	-0.421
8.96	92.01	-0.421
8.97	91.91	-0.422
8.98	91.81	-0.422
8.99	91.71	-0.422
9.00	91.61	-0.422
9.01	91.51	-0.422
9.02	91.41	-0.422
9.03	91.31	-0.422
9.04	91.21	-0.422
9.05	91.11	-0.423
9.06	91.01	-0.423
9.07	90.91	-0.423
9.08	90.81	-0.423
9.09	90.71	-0.423
9.10	90.61	-0.423
9.11	90.51	-0.423
9.12	90.41	-0.423
9.13	90.32	-0.423
9.14	90.22	-0.423
9.15	90.12	-0.424
9.16	90.02	-0.424
9.17	89.92	-0.424
9.18	89.82	-0.424
9.19	89.72	-0.424
9.20	89.62	-0.424
9.21	89.52	-0.424
9.22	89.42	-0.424
9.23	89.32	-0.424
9.24	89.22	-0.424
9.25	89.12	-0.424
9.26	89.02	-0.424
9.27	88.92	-0.424
9.28	88.82	-0.424
9.29	88.72	-0.424
9.30	88.62	-0.424
9.31	88.52	-0.424
9.32	88.42	-0.424
9.33	88.32	-0.424
9.34	88.22	-0.424
9.35	88.12	-0.425
9.36	88.02	-0.425
9.37	87.92	-0.425
9.38	87.82	-0.425
9.39	87.72	-0.425
9.40	87.62	-0.425
9.41	87.52	-0.425
9.42	87.42	-0.425
9.43	87.32	-0.425
9.44	87.22	-0.425
9.45	87.12	-0.425
9.46	87.02	-0.425
9.47	86.92	-0.425
9.48	86.83	-0.425
9.49	86.73	-0.425
9.50	86.63	-0.425
9.51	86.53	-0.425
9.52	86.43	-0.425
9.53	86.32	-0.425
9.54	86.23	-0.425
9.55	86.13	-0.425
9.56	86.03	-0.425
9.57	85.93	-0.425
9.58	85.83	-0.425
9.59	85.73	-0.425
9.60	85.63	-0.425
9.61	85.53	-0.425
9.62	85.43	-0.425
9.63	85.33	-0.425
9.64	85.23	-0.425
9.65	85.13	-0.425
9.66	85.03	-0.425
9.67	84.93	-0.425
9.68	84.83	-0.425
9.69	84.73	-0.425
9.70	84.63	-0.425
9.71	84.53	-0.425
9.72	84.43	-0.425
9.73	84.33	-0.425
9.74	84.23	-0.424
9.75	84.13	-0.424
9.76	84.03	-0.424
9.77	83.93	-0.424
9.78	83.83	-0.424
9.79	83.73	-0.424
9.80	83.63	-0.424
9.81	83.53	-0.424
9.82	83.43	-0.424
9.83	83.33	-0.424
9.84	83.23	-0.424
9.85	83.13	-0.424
9.86	83.03	-0.424
9.87	82.93	-0.424
9.88	82.83	-0.424
9.89	82.73	-0.424
9.90	82.63	-0.424
9.91	82.53	-0.424
9.92	82.43	-0.424
9.93	82.33	-0.424
9.94	82.23	-0.424
9.95	82.13	-0.424
9.96	82.03	-0.424
9.97	81.93	-0.424
9.98	81.83	-0.424
9.99	81.73	-0.424
10.00	81.63	-0.424
10.01	81.53	-0.424
10.02	81.43	-0.424
10.03	81.33	-0.424
10.04	81.23	-0.424
10.05	81.13	-0.424
10.06	81.03	-0.424
10.07	80.93	-0.424
10.08	80.83	-0.424
10.09	80.73	-0.424
10.10	80.63	-0.424
10.11	80.53	-0.424
10.12	80.43	-0.424
10.13	80.33	-0.424
10.14	80.23	-0.424
10.15	80.13	-0.424
10.16	80.03	-0.424
10.17	79.93	-0.424
10.18	79.83	-0.424
10.19	79.73	-0.424
10.20	79.63	-0.424
10.21	79.53	-0.424
10.22	79.43	-0.424
10.23	79.33	-0.424
10.24	79.23	-0.424
10.25	79.13	-0.424
10.26	79.03	-0.424
10.27	78.93	-0.424
10.28	78.83	-0.424
10.29	78.73	-0.424
10.30	78.63	-0.424
10.31	78.53	-0.424
10.32	78.44	-0.424
10.33	78.33	-0.423
10.34	78.24	-0.423
10.35	78.13	-0.423
10.36	78.04	-0.423
10.37	77.93	-0.423
10.38	77.84	-0.423
10.39	77.74	-0.423
10.40	77.64	-0.423
10.41	77.54	-0.423
10.42	77.44	-0.423
10.43	77.34	-0.423
10.44	77.24	-0.423
10.45	77.14	-0.423
10.46	77.03	-0.423
10.47	76.94	-0.423
10.48	76.84	-0.423
10.49	76.73	-0.423
10.50	76.64	-0.423
10.51	76.54	-0.423
10.52	76.44	-0.423
10.53	76.34	-0.423
10.54	76.24	-0.423
10.55	76.14	-0.423
10.56	76.04	-0.422
10.57	75.94	-0.422
10.58	75.84	-0.422
10.59	75.74	-0.422
10.60	75.64	-0.422
10.61	75.54	-0.422
10.62	75.44	-0.422
10.63	75.34	-0.422
10.64	75.24	-0.422
10.65	75.14	-0.422
10.66	75.04	-0.422
10.67	74.94	-0.422
10.68	74.84	-0.422
10.69	74.74	-0.422
10.70	74.64	-0.422
10.71	74.54	-0.422
10.72	74.44	-0.422
10.73	74.34	-0.422
10.74	74.24	-0.422
10.75	74.14	-0.422
10.76	74.04	-0.421
10.77	73.94	-0.421
10.78	73.84	-0.421
10.79	73.74	-0.421
10.80	73.64	-0.421
10.81	73.54	-0.421
10.82	73.44	-0.421
10.83	73.34	-0.421
10.84	73.24	-0.421
10.85	73.14	-0.421
10.86	73.04	-0.421
10.87	72.94	-0.421
10.88	72.84	-0.421
10.89	72.74	-0.421
10.90	72.64	-0.421
10.91	72.54	-0.421
10.92	72.44	-0.420
10.93	72.34	-0.420
10.94	72.24	-0.420
10.95	72.14	-0.420
10.96	72.04	-0.420
10.97	71.94	-0.420
10.98	71.84	-0.420
10.99	71.74	-0.420
11.00	71.64	-0.420
11.01	71.54	-0.420
11.02	71.44	-0.420
11.03	71.34	-0.420
11.04	71.24	-0.420
11.05	71.14	-0.420
11.06	71.04	-0.420
11.07	70.94	-0.420
11.08	70.84	-0.420
11.09	70.74	-0.420
11.10	70.64	-0.420
11.11	70.54	-0.419
11.12	70.44	-0.419
11.13	70.34	-0.419
11.14	70.24	-0.419
11.15	70.14	-0.419
11.16	70.04	-0.419
11.17	69.94	-0.419
11.18	69.84	-0.419
11.19	69.74	-0.419
11.20	69.64	-0.419
11.21	69.54	-0.419
11.22	69.44	-0.419
11.23	69.34	-0.419
11.24	69.24	-0.419
11.25	69.14	-0.419
11.26	69.04	-0.419
11.27	68.94	-0.419
11.28	68.84	-0.419
11.29	68.74	-0.419
11.30	68.64	-0.418
11.31	68.54	-0.418
11.32	68.44	-0.418
11.33	68.34	-0.418
11.34	68.24	-0.418
11.35	68.14	-0.418
11.36	68.04	-0.418
11.37	67.94	-0.418
11.38	67.84	-0.418
11.39	67.74	-0.418
11.40	67.64	-0.418
11.41	67.54	-0.418
11.42	67.44	-0.418
11.43	67.34	-0.418
11.44	67.24	-0.418
11.45	67.14	-0.418
11.46	67.04	-0.418
11.47	66.94	-0.418
11.48	66.84	-0.417
11.49	66.74	-0.417
11.50	66.64	-0.417
11.51	66.54	-0.417
11.52	66.44	-0.417
11.53	66.34	-0.417
11.54	66.24	-0.417
11.55	66.14	-0.417
11.56	66.04	-0.417
11.57	65.94	-0.417
11.58	65.84	-0.417
11.59	65.74	-0.417
11.60	65.64	-0.417
11.61	65.54	-0.417
11.62	65.44	-0.417
11.63	65.34	-0.417
11.64	65.24	-0.417
11.65	65.14	-0.417
11.66	65.04	-0.416
11.67	64.94	-0.416
11.68	64.84	-0.416
11.69	64.74	-0.416
11.70	64.64	-0.416
11.71	64.54	-0.416
11.72	64.44	-0.416
11.73	64.35	-0.416
11.74	64.25	-0.416
11.75	64.15	-0.416
11.76	64.05	-0.416
11.77	63.95	-0.416
11.78	63.85	-0.416
11.79	63.75	-0.416
11.80	63.65	-0.416
11.81	63.55	-0.416
11.82	63.45	-0.416
11.83	63.35	-0.415
11.84	63.25	-0.415
11.85	63.15	-0.415
11.86	63.05	-0.415
11.87	62.95	-0.415
11.88	62.85	-0.415
11.89	62.75	-0.415
11.90	62.65	-0.415
11.91	62.55	-0.415
11.92	62.45	-0.415
11.93	62.35	-0.415
11.94	62.25	-0.415
11.95	62.15	-0.415
11.96	62.05	-0.415
11.97	61.95	-0.415
11.98	61.85	-0.414
11.99	61.75	-0.414
12.00	61.65	-0.414
12.01	61.55	-0.414
12.02	61.45	-0.414
12.03	61.35	-0.414
12.04	61.25	-0.414
12.05	61.15	-0.414
12.06	61.05	-0.414
12.07	60.95	-0.414
12.08	60.85	-0.414
12.09	60.75	-0.414
12.10	60.65	-0.414
12.11	60.55	-0.414
12.12	60.45	-0.414
12.13	60.35	-0.414
12.14	60.25	-0.413
12.15	60.15	-0.413
12.16	60.05	-0.413
12.17	59.95	-0.413
12.18	59.85	-0.413
12.19	59.75	-0.413
12.20	59.65	-0.413
12.21	59.55	-0.413
12.22	59.45	-0.413
12.23	59.35	-0.413
12.24	59.25	-0.413
12.25	59.15	-0.413
12.26	59.05	-0.413
12.27	58.95	-0.413
12.28	58.85	-0.413
12.29	58.75	-0.413
12.30	58.65	-0.413
12.31	58.55	-0.412
12.32	58.45	-0.412
12.33	58.35	-0.412
12.34	58.25	-0.412
12.35	58.15	-0.412
12.36	58.05	-0.412
12.37	57.95	-0.412
12.38	57.85	-0.412
12.39	57.75	-0.412
12.40	57.65	-0.412
12.41	57.55	-0.412
12.42	57.45	-0.412
12.43	57.35	-0.412
12.44	57.25	-0.412
12.45	57.15	-0.412
12.46	57.05	-0.412
12.47	56.95	-0.412
12.48	56.85	-0.411
12.49	56.75	-0.411
12.50	56.65	-0.411
12.51	56.55	-0.411
12.52	56.45	-0.411
12.53	56.35	-0.411
12.54	56.25	-0.411
12.55	56.15	-0.411
12.56	56.05	-0.411
12.57	55.95	-0.411
12.58	55.85	-0.411
12.59	55.75	-0.411
12.60	55.65	-0.411
12.61	55.55	-0.411
12.62	55.45	-0.411
12.63	55.35	-0.410
12.64	55.25	-0.410
12.65	55.15	-0.410
12.66	55.05	-0.410
12.67	54.95	-0.410
12.68	54.85	-0.410
12.69	54.75	-0.410
12.70	54.65	-0.410
12.71	54.55	-0.410
12.72	54.45	-0.410
12.73	54.35	-0.410
12.74	54.25	-0.410
12.75	54.15	-0.410
12.76	54.05	-0.410
12.77	53.95	-0.410
12.78	53.85	-0.410
12.79	53.75	-0.409
12.80	53.65	-0.409
12.81	53.55	-0.409
12.82	53.45	-0.409
12.83	53.35	-0.409
12.84	53.25	-0.409
12.85	53.15	-0.409
12.86	53.05	-0.409
12.87	52.95	-0.409
12.88	52.85	-0.409
12.89	52.75	-0.409
12.90	52.65	-0.409
12.91	52.55	-0.409
12.92	52.45	-0.409
12.93	52.35	-0.409
12.94	52.25	-0.408
12.95	52.15	-0.408
12.96	52.05	-0.408
12.97	51.95	-0.408
12.98	51.85	-0.408
12.99	51.75	-0.408
13.00	51.65	-0.408
13.01	51.55	-0.408
13.02	51.45	-0.408
13.03	51.35	-0.408
13.04	51.25	-0.408
13.05	51.16	-0.408
13.06	51.05	-0.408
13.07	50.95	-0.408
13.08	50.85	-0.408
13.09	50.76	-0.407
13.10	50.66	-0.407
13.11	50.55	-0.407
13.12	50.45	-0.407
13.13	50.35	-0.407
13.14	50.26	-0.407
13.15	50.15	-0.407
13.16	50.06	-0.407
13.17	49.95	-0.407
13.18	49.85	-0.407
13.19	49.75	-0.407
13.20	49.66	-0.407
13.21	49.56	-0.407
13.22	49.46	-0.407
13.23	49.35	-0.407
13.24	49.25	-0.407
13.25	49.15	-0.407
13.26	49.05	-0.406
13.27	48.96	-0.406
[...]
59.84	-13.23	0.325
59.85	-13.13	0.327
59.86	-13.03	0.329
59.87	-12.93	0.331
59.88	-12.84	0.332
59.89	-12.73	0.333
59.90	-12.64	0.335
59.91	-12.54	0.337
59.92	-12.44	0.338
59.93	-12.34	0.339
59.94	-12.24	0.340
59.95	-12.14	0.341
59.96	-12.04	0.342
59.97	-11.94	0.343
59.98	-11.84	0.343
59.99	-11.74	0.344
60.00	-11.64	0.345
60.01	-11.54	0.346
60.02	-11.44	0.346
60.03	-11.34	0.347
60.04	-11.24	0.347
60.05	-11.14	0.347
60.06	-11.04	0.347
60.07	-10.94	0.347
60.08	-10.84	0.347
60.09	-10.74	0.347
60.10	-10.64	0.348
60.11	-10.54	0.348
60.12	-10.44	0.348
60.13	-10.34	0.348
60.14	-10.24	0.348
60.15	-10.14	0.348
60.16	-10.04	0.348
60.17	-9.94	0.348
60.18	-9.84	0.347
60.19	-9.74	0.347
60.20	-9.64	0.347
60.21	-9.54	0.347
60.22	-9.44	0.347
60.23	-9.34	0.347
60.24	-9.24	0.346
60.25	-9.14	0.346
60.26	-9.04	0.346
60.27	-8.94	0.346
60.28	-8.84	0.345
60.29	-8.74	0.345
60.30	-8.64	0.345
60.31	-8.54	0.345
60.32	-8.44	0.344
60.33	-8.34	0.344
60.34	-8.24	0.344
60.35	-8.14	0.343
60.36	-8.04	0.343
60.37	-7.94	0.343
60.38	-7.84	0.343
60.39	-7.74	0.342
60.40	-7.63	0.342
60.41	-7.54	0.342
60.42	-7.43	0.341
60.43	-7.33	0.340
60.44	-7.23	0.340
60.45	-7.13	0.340
60.46	-7.03	0.340
60.47	-6.93	0.339
60.48	-6.83	0.339
60.49	-6.73	0.339
60.50	-6.63	0.339
60.51	-6.53	0.338
60.52	-6.43	0.338
60.53	-6.33	0.338
60.54	-6.23	0.338
60.55	-6.13	0.337
60.56	-6.03	0.337
60.57	-5.93	0.337
60.58	-5.83	0.337
60.59	-5.73	0.337
60.60	-5.63	0.336
60.61	-5.53	0.336
60.62	-5.43	0.336
60.63	-5.33	0.336
60.64	-5.23	0.336
60.65	-5.13	0.336
60.66	-5.03	0.335
60.67	-4.93	0.335
60.68	-4.83	0.335
60.69	-4.73	0.335
60.70	-4.63	0.335
60.71	-4.53	0.335
60.72	-4.43	0.335
60.73	-4.33	0.334
60.74	-4.23	0.334
60.75	-4.13	0.334
60.76	-4.03	0.334
60.77	-3.93	0.334
60.78	-3.83	0.334
60.79	-3.73	0.334
60.80	-3.63	0.334
60.81	-3.53	0.334
60.82	-3.43	0.334
60.83	-3.33	0.333
60.84	-3.23	0.333
60.85	-3.13	0.333
60.86	-3.03	0.333
60.87	-2.93	0.333
60.88	-2.83	0.333
60.89	-2.73	0.333
60.90	-2.63	0.333
60.91	-2.53	0.333
60.92	-2.43	0.333
60.93	-2.33	0.333
60.94	-2.23	0.333
60.95	-2.13	0.333
60.96	-2.03	0.333
60.97	-1.93	0.333
60.98	-1.83	0.333
60.99	-1.73	0.333
61.00	-1.63	0.333
61.01	-1.53	0.333
61.02	-1.43	0.333
61.03	-1.32	0.333
61.04	-1.22	0.333
61.05	-1.12	0.333
61.06	-1.02	0.333
61.07	-0.92	0.333
61.08	-0.82	0.333
61.09	-0.72	0.333
61.10	-0.62	0.333
61.11	-0.52	0.333
61.12	-0.42	0.333
61.13	-0.32	0.333
61.14	-0.22	0.333
61.15	-0.12	0.333
61.16	-0.02	0.333
61.17	0.08	0.333
61.18	0.18	0.333
61.19	0.28	0.333
61.20	0.38	0.333
61.21	0.48	0.333
61.22	0.58	0.333
61.23	0.68	0.333
61.24	0.78	0.333
61.25	0.88	0.333
61.26	0.98	0.333
61.27	1.08	0.333
61.28	1.18	0.333
61.29	1.28	0.333
61.30	1.38	0.333
61.31	1.48	0.333
61.32	1.58	0.333
61.33	1.68	0.333
61.34	1.78	0.333
61.35	1.88	0.333
61.36	1.98	0.334
61.37	2.08	0.334
61.38	2.18	0.334
61.39	2.28	0.334
61.40	2.38	0.334
61.41	2.48	0.334
61.42	2.58	0.334
61.43	2.68	0.334
61.44	2.78	0.334
61.45	2.88	0.334
61.46	2.98	0.334
61.47	3.08	0.334
61.48	3.18	0.334
61.49	3.28	0.334
61.50	3.38	0.334
61.51	3.48	0.334
61.52	3.58	0.334
61.53	3.68	0.334
61.54	3.78	0.334
61.55	3.88	0.334
61.56	3.98	0.335
61.57	4.08	0.335
61.58	4.18	0.335
61.59	4.28	0.335
61.60	4.38	0.335
61.61	4.48	0.335
61.62	4.58	0.335
61.63	4.68	0.335
61.64	4.78	0.335
61.65	4.88	0.335
61.66	4.98	0.335
61.67	5.08	0.335
61.68	5.18	0.335
61.69	5.28	0.335
61.70	5.38	0.335
61.71	5.48	0.335
61.72	5.58	0.335
61.73	5.68	0.336
61.74	5.78	0.336
61.75	5.88	0.336
61.76	5.98	0.336
61.77	6.09	0.336
61.78	6.18	0.336
61.79	6.28	0.336
61.80	6.38	0.336
61.81	6.48	0.336
61.82	6.58	0.336
61.83	6.69	0.336
61.84	6.79	0.336
61.85	6.89	0.336
61.86	6.99	0.336
61.87	7.09	0.336
61.88	7.19	0.337
61.89	7.29	0.337
61.90	7.39	0.337
61.91	7.49	0.337
61.92	7.59	0.337
61.93	7.69	0.337
61.94	7.79	0.337
61.95	7.89	0.337
61.96	7.99	0.337
61.97	8.09	0.337
61.98	8.19	0.337
61.99	8.29	0.337
62.00	8.39	0.337
62.01	8.49	0.337
62.02	8.59	0.337
62.03	8.69	0.337
62.04	8.79	0.337
62.05	8.89	0.338
62.06	8.99	0.338
62.07	9.09	0.338
62.08	9.19	0.338
62.09	9.29	0.338
62.10	9.39	0.338
62.11	9.49	0.338
62.12	9.59	0.338
62.13	9.69	0.338
62.14	9.79	0.338
62.15	9.89	0.338
62.16	9.99	0.338
62.17	10.09	0.338
62.18	10.19	0.338
62.19	10.29	0.338
62.20	10.39	0.339
62.21	10.49	0.339
62.22	10.59	0.339
62.23	10.69	0.339
62.24	10.79	0.339
62.25	10.89	0.339
62.26	10.99	0.339
62.27	11.09	0.339
62.28	11.19	0.339
62.29	11.29	0.339
62.30	11.39	0.339
62.31	11.49	0.339
62.32	11.59	0.339
62.33	11.69	0.339
62.34	11.79	0.339
62.35	11.89	0.339
62.36	11.99	0.340
62.37	12.09	0.340
62.38	12.19	0.340
62.39	12.29	0.340
62.40	12.39	0.340
62.41	12.49	0.340
62.42	12.59	0.340
62.43	12.69	0.340
62.44	12.79	0.340
62.45	12.89	0.340
62.46	12.99	0.340
62.47	13.09	0.340
62.48	13.19	0.340
62.49	13.29	0.341
62.50	13.39	0.341
62.51	13.49	0.341
62.52	13.59	0.341
62.53	13.69	0.341
62.54	13.79	0.341
62.55	13.89	0.341
62.56	13.99	0.341
62.57	14.09	0.341
62.58	14.19	0.341
62.59	14.29	0.341
62.60	14.39	0.341
62.61	14.49	0.341
62.62	14.59	0.341
62.63	14.69	0.341
62.64	14.79	0.341
62.65	14.89	0.341
62.66	14.99	0.342
62.67	15.09	0.342
62.68	15.19	0.342
62.69	15.30	0.342
62.70	15.40	0.342
62.71	15.50	0.342
62.72	15.59	0.342
62.73	15.70	0.342
62.74	15.80	0.342
62.75	15.90	0.342
62.76	15.99	0.342
62.77	16.10	0.342
62.78	16.20	0.342
62.79	16.30	0.342
62.80	16.40	0.343
62.81	16.50	0.343
62.82	16.60	0.343
62.83	16.70	0.343
62.84	16.80	0.343
62.85	16.90	0.343
62.86	17.00	0.343
62.87	17.10	0.343
62.88	17.20	0.343
62.89	17.30	0.343
62.90	17.40	0.343
62.91	17.50	0.343
62.92	17.60	0.344
62.93	17.70	0.344
62.94	17.80	0.344
62.95	17.90	0.344
62.96	18.00	0.344
62.97	18.10	0.344
62.98	18.20	0.344
62.99	18.30	0.344
63.00	18.40	0.344
63.01	18.50	0.344
63.02	18.60	0.344
63.03	18.70	0.344
63.04	18.80	0.344
63.05	18.90	0.344
63.06	19.00	0.345
63.07	19.10	0.345
63.08	19.20	0.345
63.09	19.30	0.345
63.10	19.40	0.345
63.11	19.50	0.345
63.12	19.60	0.345
63.13	19.70	0.345
63.14	19.80	0.345
63.15	19.90	0.345
63.16	20.00	0.345
63.17	20.10	0.345
63.18	20.20	0.345
63.19	20.30	0.346
63.20	20.40	0.346
63.21	20.50	0.346
63.22	20.60	0.346
63.23	20.70	0.346
63.24	20.80	0.346
63.25	20.90	0.346
63.26	21.00	0.346
63.27	21.10	0.346
63.28	21.20	0.346
63.29	21.30	0.346
63.30	21.40	0.346
63.31	21.50	0.346
63.32	21.60	0.346
63.33	21.70	0.346
63.34	21.80	0.347
63.35	21.90	0.347
63.36	22.00	0.347
63.37	22.10	0.347
63.38	22.20	0.347
63.39	22.30	0.347
63.40	22.40	0.347
63.41	22.50	0.347
63.42	22.60	0.347
63.43	22.70	0.347
63.44	22.80	0.347
63.45	22.90	0.347
63.46	23.00	0.348
63.47	23.10	0.348
63.48	23.20	0.348
63.49	23.30	0.348
63.50	23.40	0.348
63.51	23.50	0.348
63.52	23.60	0.348
63.53	23.70	0.348
63.54	23.80	0.348
63.55	23.90	0.348
63.56	24.00	0.348
63.57	24.10	0.349
63.58	24.20	0.349
63.59	24.30	0.349
63.60	24.40	0.349
63.61	24.50	0.349
63.62	24.60	0.349
63.63	24.70	0.349
63.64	24.80	0.349
63.65	24.90	0.349
63.66	25.00	0.349
63.67	25.10	0.349
63.68	25.20	0.349
63.69	25.30	0.349
63.70	25.40	0.350
63.71	25.51	0.350
63.72	25.60	0.350
63.73	25.71	0.350
63.74	25.80	0.350
63.75	25.91	0.350
63.76	26.00	0.350
63.77	26.11	0.350
63.78	26.20	0.350
63.79	26.31	0.350
63.80	26.41	0.350
63.81	26.51	0.350
63.82	26.61	0.350
63.83	26.71	0.351
63.84	26.81	0.351
63.85	26.91	0.351
63.86	27.01	0.351
63.87	27.11	0.351
63.88	27.21	0.351
63.89	27.31	0.351
63.90	27.41	0.351
63.91	27.51	0.351
63.92	27.61	0.351
63.93	27.71	0.351
63.94	27.81	0.351
63.95	27.91	0.352
63.96	28.01	0.352
63.97	28.11	0.352
63.98	28.21	0.352
63.99	28.31	0.352
64.00	28.41	0.352
64.01	28.51	0.352
64.02	28.61	0.352
64.03	28.71	0.352
64.04	28.81	0.352
64.05	28.91	0.352
64.06	29.01	0.352
64.07	29.11	0.352
64.08	29.21	0.353
64.09	29.31	0.353
64.10	29.41	0.353
64.11	29.51	0.353
64.12	29.61	0.353
64.13	29.71	0.353
64.14	29.81	0.353
64.15	29.91	0.353
64.16	30.01	0.353
64.17	30.11	0.353
64.18	30.21	0.353
64.19	30.31	0.353
64.20	30.41	0.354
64.21	30.51	0.354
64.22	30.61	0.354
64.23	30.71	0.354
64.24	30.81	0.354
64.25	30.91	0.354
64.26	31.01	0.354
64.27	31.11	0.354
64.28	31.21	0.354
64.29	31.31	0.354
64.30	31.41	0.354
64.31	31.51	0.354
64.32	31.61	0.354
64.33	31.71	0.355
64.34	31.81	0.355
64.35	31.91	0.355
64.36	32.01	0.355
64.37	32.11	0.355
64.38	32.21	0.355
64.39	32.31	0.355
64.40	32.41	0.355
64.41	32.51	0.355
64.42	32.61	0.355
64.43	32.71	0.355
64.44	32.81	0.355
64.45	32.91	0.355
64.46	33.01	0.355
64.47	33.11	0.356
64.48	33.21	0.356
64.49	33.31	0.356
64.50	33.41	0.356
64.51	33.51	0.356
64.52	33.61	0.356
64.53	33.71	0.356
64.54	33.81	0.356
64.55	33.91	0.356
64.56	34.01	0.356
64.57	34.11	0.356
64.58	34.21	0.356
64.59	34.31	0.357
64.60	34.41	0.357
64.61	34.51	0.357
64.62	34.61	0.357
64.63	34.71	0.357
64.64	34.81	0.357
64.65	34.91	0.357
64.66	35.01	0.357
64.67	35.11	0.357
64.68	35.21	0.357
64.69	35.31	0.357
64.70	35.41	0.357
64.71	35.51	0.357
64.72	35.61	0.358
64.73	35.71	0.358
64.74	35.82	0.358
64.75	35.92	0.358
64.76	36.01	0.358
64.77	36.11	0.358
64.78	36.22	0.358
64.79	36.31	0.358
64.80	36.42	0.358
64.81	36.52	0.358
64.82	36.62	0.358
64.83	36.72	0.358
64.84	36.82	0.358
64.85	36.92	0.359
64.86	37.02	0.359
64.87	37.12	0.359
64.88	37.22	0.359
64.89	37.32	0.359
64.90	37.42	0.359
64.91	37.52	0.359
64.92	37.62	0.359
64.93	37.72	0.359
64.94	37.82	0.359
64.95	37.92	0.359
64.96	38.02	0.359
64.97	38.12	0.359
64.98	38.22	0.359
64.99	38.32	0.359
65.00	38.42	0.360
65.01	38.52	0.360
65.02	38.62	0.360
65.03	38.72	0.360
65.04	38.82	0.360
65.05	38.92	0.360
65.06	39.02	0.360
65.07	39.12	0.360
65.08	39.22	0.360
65.09	39.32	0.360
65.10	39.42	0.360
65.11	39.52	0.360
65.12	39.62	0.360
65.13	39.72	0.360
65.14	39.82	0.361
65.15	39.92	0.361
65.16	40.02	0.361
65.17	40.12	0.361
65.18	40.22	0.361
65.19	40.32	0.361
65.20	40.42	0.361
65.21	40.52	0.361
65.22	40.62	0.361
65.23	40.72	0.361
65.24	40.82	0.361
65.25	40.92	0.361
65.26	41.02	0.361
65.27	41.12	0.361
65.28	41.22	0.361
65.29	41.32	0.362
65.30	41.42	0.362
65.31	41.52	0.362
65.32	41.62	0.362
65.33	41.72	0.362
65.34	41.82	0.362
65.35	41.92	0.362
65.36	42.02	0.362
65.37	42.12	0.362
65.38	42.22	0.362
65.39	42.32	0.362
65.40	42.42	0.362
65.41	42.52	0.362
65.42	42.62	0.363
65.43	42.72	0.363
65.44	42.82	0.363
65.45	42.92	0.363
65.46	43.02	0.363
65.47	43.12	0.363
65.48	43.22	0.363
65.49	43.32	0.363
65.50	43.42	0.363
65.51	43.52	0.363
65.52	43.62	0.363
65.53	43.72	0.363
65.54	43.82	0.363
65.55	43.92	0.364
65.56	44.02	0.364
65.57	44.12	0.364
65.58	44.22	0.364
65.59	44.32	0.364
65.60	44.42	0.364
65.61	44.52	0.364
65.62	44.62	0.364
65.63	44.72	0.364
65.64	44.82	0.364
65.65	44.92	0.364
65.66	45.02	0.364
65.67	45.12	0.365
65.68	45.23	0.365
65.69	45.32	0.365
65.70	45.43	0.365
65.71	45.52	0.365
65.72	45.63	0.365
65.73	45.73	0.365
65.74	45.83	0.365
65.75	45.93	0.365
65.76	46.03	0.365
65.77	46.13	0.365
65.78	46.23	0.366
65.79	46.33	0.366
65.80	46.43	0.366
65.81	46.53	0.366
65.82	46.63	0.366
65.83	46.73	0.366
65.84	46.83	0.366
65.85	46.93	0.366
65.86	47.03	0.366
65.87	47.13	0.366
65.88	47.23	0.366
65.89	47.33	0.366
65.90	47.43	0.367
65.91	47.53	0.367
65.92	47.63	0.367
65.93	47.73	0.367
65.94	47.83	0.367
65.95	47.93	0.367
65.96	48.03	0.367
65.97	48.13	0.367
65.98	48.23	0.367
65.99	48.33	0.367
66.00	48.43	0.367
66.01	48.53	0.367
66.02	48.63	0.367
66.03	48.73	0.368
66.04	48.83	0.368
66.05	48.93	0.368
66.06	49.03	0.368
66.07	49.13	0.368
66.08	49.23	0.368
66.09	49.33	0.368
66.10	49.43	0.368
66.11	49.53	0.368
66.12	49.63	0.368
66.13	49.73	0.368
66.14	49.83	0.368
66.15	49.93	0.369
66.16	50.03	0.369
66.17	50.13	0.369
66.18	50.23	0.369
66.19	50.33	0.369
66.20	50.43	0.369
66.21	50.53	0.369
66.22	50.63	0.369
66.23	50.73	0.369
66.24	50.83	0.369
66.25	50.93	0.369
66.26	51.03	0.369
66.27	51.13	0.369
66.28	51.23	0.370
66.29	51.33	0.370
66.30	51.43	0.370
66.31	51.53	0.370
66.32	51.63	0.370
66.33	51.73	0.370
66.34	51.83	0.370
66.35	51.93	0.370
66.36	52.03	0.370
66.37	52.13	0.370
66.38	52.23	0.370
66.39	52.33	0.370
66.40	52.43	0.370
66.41	52.53	0.371
66.42	52.63	0.371
66.43	52.73	0.371
66.44	52.83	0.371
66.45	52.93	0.371
66.46	53.03	0.371
66.47	53.13	0.371
66.48	53.23	0.371
66.49	53.33	0.371
66.50	53.43	0.371
66.51	53.53	0.371
66.52	53.63	0.371
66.53	53.73	0.371
66.54	53.83	0.372
66.55	53.93	0.372
66.56	54.03	0.372
66.57	54.13	0.372
66.58	54.23	0.372
66.59	54.33	0.372
66.60	54.43	0.372
66.61	54.53	0.372
66.62	54.63	0.372
66.63	54.73	0.372
66.64	54.83	0.372
66.65	54.93	0.372
66.66	55.03	0.373
66.67	55.13	0.373
66.68	55.23	0.373
66.69	55.33	0.373
66.70	55.43	0.373
66.71	55.53	0.373
66.72	55.63	0.373
66.73	55.73	0.373
66.74	55.83	0.373
66.75	55.93	0.373
66.76	56.03	0.373
66.77	56.13	0.374
66.78	56.23	0.374
66.79	56.33	0.374
66.80	56.43	0.374
66.81	56.53	0.374
66.82	56.63	0.374
66.83	56.73	0.374
66.84	56.83	0.374
66.85	56.93	0.374
66.86	57.03	0.374
66.87	57.13	0.374
66.88	57.23	0.375
66.89	57.34	0.375
66.90	57.44	0.375
66.91	57.54	0.375
66.92	57.64	0.375
66.93	57.74	0.375
66.94	57.84	0.375
66.95	57.94	0.375
66.96	58.04	0.375
66.97	58.14	0.375
66.98	58.24	0.375
66.99	58.34	0.375
67.00	58.44	0.376
67.01	58.54	0.376
67.02	58.64	0.376
67.03	58.74	0.376
67.04	58.84	0.376
67.05	58.94	0.376
67.06	59.04	0.376
67.07	59.14	0.376
67.08	59.24	0.376
67.09	59.34	0.376
67.10	59.44	0.376
67.11	59.54	0.376
67.12	59.64	0.376
67.13	59.74	0.377
67.14	59.84	0.377
67.15	59.94	0.377
67.16	60.04	0.377
67.17	60.14	0.377
67.18	60.24	0.377
67.19	60.34	0.377
67.20	60.44	0.377
67.21	60.54	0.377
67.22	60.64	0.377
67.23	60.74	0.377
67.24	60.84	0.377
67.25	60.94	0.378
67.26	61.04	0.378
67.27	61.14	0.378
67.28	61.24	0.378
67.29	61.34	0.378
67.30	61.44	0.378
67.31	61.54	0.378
67.32	61.64	0.378
67.33	61.74	0.378
67.34	61.84	0.378
67.35	61.94	0.378
67.36	62.04	0.378
67.37	62.14	0.379
67.38	62.24	0.379
67.39	62.34	0.379
67.40	62.44	0.379
67.41	62.54	0.379
67.42	62.64	0.379
67.43	62.74	0.379
67.44	62.84	0.379
67.45	62.94	0.379
67.46	63.04	0.379
67.47	63.14	0.379
67.48	63.24	0.379
67.49	63.34	0.380
67.50	63.44	0.380
67.51	63.54	0.380
67.52	63.64	0.380
67.53	63.74	0.380
67.54	63.84	0.380
67.55	63.94	0.380
67.56	64.04	0.380
67.57	64.14	0.380
67.58	64.24	0.380
67.59	64.34	0.380
67.60	64.44	0.381
67.61	64.54	0.381
67.62	64.64	0.381
67.63	64.74	0.381
67.64	64.84	0.381
67.65	64.94	0.381
67.66	65.04	0.381
67.67	65.14	0.381
67.68	65.24	0.381
67.69	65.34	0.381
67.70	65.44	0.381
67.71	65.54	0.382
67.72	65.64	0.382
67.73	65.74	0.382
67.74	65.84	0.382
67.75	65.94	0.382
67.76	66.04	0.382
67.77	66.14	0.382
67.78	66.24	0.382
67.79	66.34	0.382
67.80	66.44	0.382
67.81	66.54	0.382
67.82	66.64	0.382
67.83	66.74	0.382
67.84	66.84	0.383
67.85	66.94	0.383
67.86	67.04	0.383
67.87	67.14	0.383
67.88	67.24	0.383
67.89	67.34	0.383
67.90	67.44	0.383
67.91	67.54	0.383
67.92	67.64	0.383
67.93	67.74	0.383
67.94	67.84	0.383
67.95	67.94	0.384
67.96	68.04	0.384
67.97	68.15	0.384
67.98	68.24	0.384
67.99	68.34	0.384
68.00	68.45	0.384
68.01	68.55	0.384
68.02	68.64	0.384
68.03	68.75	0.384
68.04	68.85	0.384
68.05	68.95	0.384
68.06	69.05	0.384
68.07	69.15	0.385
68.08	69.25	0.385
68.09	69.35	0.385
68.10	69.45	0.385
68.11	69.55	0.385
68.12	69.65	0.385
68.13	69.75	0.385
68.14	69.85	0.385
68.15	69.95	0.385
68.16	70.05	0.385
68.17	70.15	0.385
68.18	70.25	0.385
68.19	70.35	0.386
68.20	70.45	0.386
68.21	70.55	0.386
68.22	70.65	0.386
68.23	70.75	0.386
68.24	70.85	0.386
68.25	70.95	0.386
68.26	71.05	0.386
68.27	71.15	0.386
68.28	71.25	0.386
68.29	71.35	0.386
68.30	71.45	0.386
68.31	71.55	0.387
68.32	71.65	0.387
68.33	71.75	0.387
68.34	71.85	0.387
68.35	71.95	0.387
68.36	72.05	0.387
68.37	72.15	0.387
68.38	72.25	0.387
68.39	72.35	0.387
68.40	72.45	0.387
68.41	72.55	0.387
68.42	72.65	0.388
68.43	72.75	0.388
68.44	72.85	0.388
68.45	72.95	0.388
68.46	73.05	0.388
68.47	73.15	0.388
68.48	73.25	0.388
68.49	73.35	0.388
68.50	73.45	0.388
68.51	73.55	0.388
68.52	73.65	0.388
68.53	73.75	0.388
68.54	73.85	0.389
68.55	73.95	0.389
68.56	74.05	0.389
68.57	74.15	0.389
68.58	74.25	0.389
68.59	74.35	0.389
68.60	74.45	0.389
68.61	74.55	0.389
68.62	74.65	0.389
68.63	74.75	0.389
68.64	74.85	0.389
68.65	74.95	0.390
68.66	75.05	0.390
68.67	75.15	0.390
68.68	75.25	0.390
68.69	75.35	0.390
68.70	75.45	0.390
68.71	75.55	0.390
68.72	75.65	0.390
68.73	75.75	0.390
68.74	75.85	0.390
68.75	75.95	0.390
68.76	76.05	0.390
68.77	76.15	0.390
68.78	76.25	0.391
68.79	76.35	0.391
68.80	76.45	0.391
68.81	76.55	0.391
68.82	76.65	0.391
68.83	76.75	0.391
68.84	76.85	0.391
68.85	76.95	0.391
68.86	77.05	0.391
68.87	77.15	0.391
68.88	77.25	0.391
68.89	77.35	0.391
68.90	77.45	0.392
68.91	77.55	0.392
68.92	77.65	0.392
68.93	77.75	0.392
68.94	77.85	0.392
68.95	77.95	0.392
68.96	78.05	0.392
68.97	78.15	0.392
68.98	78.25	0.392
68.99	78.35	0.392
69.00	78.45	0.392
69.01	78.55	0.393
69.02	78.65	0.393
69.03	78.75	0.393
69.04	78.86	0.393
69.05	78.95	0.393
69.06	79.05	0.393
69.07	79.15	0.393
69.08	79.25	0.393
69.09	79.35	0.393
69.10	79.45	0.393
69.11	79.55	0.393
69.12	79.65	0.393
69.13	79.75	0.393
69.14	79.85	0.394
69.15	79.95	0.394
69.16	80.05	0.394
69.17	80.15	0.394
69.18	80.25	0.394
69.19	80.36	0.394
69.20	80.46	0.394
69.21	80.55	0.394
69.22	80.65	0.395
69.23	80.75	0.395
69.24	80.86	0.395
69.25	80.96	0.395
69.26	81.06	0.395
69.27	81.16	0.395
69.28	81.26	0.395
69.29	81.36	0.395
69.30	81.46	0.395
69.31	81.56	0.395
69.32	81.66	0.396
69.33	81.76	0.396
69.34	81.86	0.396
69.35	81.96	0.396
69.36	82.06	0.396
69.37	82.16	0.396
69.38	82.26	0.396
69.39	82.36	0.396
69.40	82.46	0.396
69.41	82.56	0.396
69.42	82.66	0.396
69.43	82.76	0.396
69.44	82.86	0.397
69.45	82.96	0.397
69.46	83.06	0.397
69.47	83.16	0.397
69.48	83.26	0.397
69.49	83.36	0.397
69.50	83.46	0.397
69.51	83.56	0.397
69.52	83.66	0.397
69.53	83.76	0.397
69.54	83.86	0.397
69.55	83.96	0.397
69.56	84.06	0.397
69.57	84.16	0.397
69.58	84.26	0.397
69.59	84.36	0.397
69.60	84.46	0.397
69.61	84.56	0.397
69.62	84.66	0.397
69.63	84.76	0.397
69.64	84.86	0.397
69.65	84.96	0.397
69.66	85.06	0.397
69.67	85.16	0.397
69.68	85.26	0.397
69.69	85.36	0.398
69.70	85.46	0.398
69.71	85.56	0.398
69.72	85.66	0.398
69.73	85.76	0.398
69.74	85.86	0.398
69.75	85.96	0.398
69.76	86.06	0.398
69.77	86.16	0.398
69.78	86.26	0.398
69.79	86.36	0.399
69.80	86.46	0.399
69.81	86.56	0.399
69.82	86.66	0.399
69.83	86.76	0.399
69.84	86.86	0.399
69.85	86.96	0.399
69.86	87.06	0.399
69.87	87.16	0.399
69.88	87.26	0.399
69.89	87.36	0.400
69.90	87.46	0.400
69.91	87.56	0.400
69.92	87.66	0.400
69.93	87.76	0.400
69.94	87.86	0.400
69.95	87.96	0.400
69.96	88.06	0.400
69.97	88.16	0.400
69.98	88.26	0.400
69.99	88.36	0.400
70.00	88.46	0.401
70.01	88.56	0.401
70.02	88.66	0.401
70.03	88.76	0.401
70.04	88.86	0.401
70.05	88.96	0.401
70.06	89.06	0.401
70.07	89.17	0.401
70.08	89.27	0.401
70.09	89.36	0.401
70.10	89.47	0.402
70.11	89.56	0.402
70.12	89.66	0.402
70.13	89.77	0.402
70.14	89.86	0.402
70.15	89.97	0.402
70.16	90.06	0.402
70.17	90.17	0.402
70.18	90.26	0.402
70.19	90.37	0.402
70.20	90.47	0.402
70.21	90.57	0.403
70.22	90.67	0.403
70.23	90.77	0.403
70.24	90.87	0.403
70.25	90.97	0.403
70.26	91.07	0.403
70.27	91.17	0.403
70.28	91.27	0.403
70.29	91.37	0.403
70.30	91.47	0.404
70.31	91.57	0.404
70.32	91.67	0.404
70.33	91.77	0.404
70.34	91.87	0.404
70.35	91.97	0.404
70.36	92.07	0.404
70.37	92.17	0.404
70.38	92.27	0.404
70.39	92.37	0.405
70.40	92.47	0.405
70.41	92.57	0.405
70.42	92.67	0.405
70.43	92.77	0.405
70.44	92.87	0.405
70.45	92.97	0.405
70.46	93.07	0.405
70.47	93.17	0.405
70.48	93.27	0.405
70.49	93.37	0.405
70.50	93.47	0.406
70.51	93.57	0.406
70.52	93.67	0.406
70.53	93.77	0.406
70.54	93.87	0.406
70.55	93.97	0.406
70.56	94.07	0.406
70.57	94.17	0.406
70.58	94.27	0.406
70.59	94.37	0.407
70.60	94.47	0.407
70.61	94.57	0.407
70.62	94.67	0.407
70.63	94.77	0.407
70.64	94.87	0.407
70.65	94.97	0.407
70.66	95.07	0.407
70.67	95.17	0.408
70.68	95.27	0.408
70.69	95.37	0.408
70.70	95.47	0.408
70.71	95.57	0.408
70.72	95.67	0.408
70.73	95.77	0.408
70.74	95.87	0.408
70.75	95.97	0.408
70.76	96.07	0.408
70.77	96.17	0.408
70.78	96.27	0.409
70.79	96.37	0.409
70.80	96.47	0.409
70.81	96.57	0.409
70.82	96.67	0.409
70.83	96.77	0.409
70.84	96.87	0.409
70.85	96.97	0.409
70.86	97.07	0.409
70.87	97.17	0.409
70.88	97.27	0.410
70.89	97.37	0.410
70.90	97.47	0.410
70.91	97.57	0.410
70.92	97.67	0.410
70.93	97.77	0.410
70.94	97.87	0.410
70.95	97.97
70.96	98.07
70.97	98.17
70.98	98.27
70.99	98.37
71.00