File: DSC/2023_06_26_hagfish_gamma_protein_SBK.txt
Filename	2023_06_26_hagfish_gamma_protein_SBK
Instrument name	DSC2A-00468 (192.168.1.100)
Operator	SBK
rundate	6/26/2023
Sample name	2023_06_26_hagfish_gamma_protein_SBK
proceduresegments	Data Off ; Equilibrate -80.00 °C; Data On ; Ramp 5.00 °C/min to 100.00 °C; Data Off ; Isothermal 1.0 min; Data On ; Ramp 5.00 °C/min to -80.00 °C; Data Off ; Isothermal 1.0 min; Data On ; Ramp 5.00 °C/min to 100.00 °C
[File Parameters]
Run date	6/26/2023 3:43:52 PM
Trios version	5.1.1.46572
Original File Name
Current File Name	C:\Users\yargerlab\Desktop\DSC Data\General\2023_06_26_hagfish_gamma_protein_SBK.tri
[Procedure]
Procedure Name	DSC n80C 100C 2 cycle
Sample Name	2023_06_26_hagfish_gamma_protein_SBK
Sample Mass	4.49 mg
Reference Sample Mass	0 mg
Pan Mass	54.65 mg
Pan Number	39
Reference Pan Mass	53.66 mg
Reference Pan Number	46
Pan Type	Aluminum Hermetic
Comments	Hagfish gamma protein powder. Refrigerated before use, and run quickly after sample prep. Aluminum pan with hermetic aluminum lid. (DSC84010 and DSC84011)
Project Name	Silk ASDs
Operator	SBK
Test	Custom
Unload Max Temperature	30
Unload Min Temperature	30
Load Max Temperature	30
Load Min Temperature	30
Stop on Gas Flow Error	Yes
[Signal List]
Signal #1	Time (min)
Signal #2	Temperature (°C)
Signal #3	Heat Flow (mW)
Signal #4	Delta T (µV)
Signal #5	Delta Tzero (µV)
Signal #6	Tzero Temperature (°C)
Signal #7	Cell Purge (mL/min)
Signal #8	Heater Temp (°C)
Signal #9	Power Delivered (W)
Signal #10	Reference Junction Temperature (°C)
Signal #11	Flange Temperature (°C)
Signal #12	Heat Flow Phase (rad)
Signal #13	Total Heat Capacity (J/°C)
Signal #14	Heat Capacity (J/°C)
[Configuration]
Company Name	ASU
Instrument Name	DSC2A-00468
Instrument Type	DSC2500
Serial Number	DSC2A-00468
IP	192.168.1.100
Location of Instrument	MRRC
DisplayType	Unknown
Sample Interval 	0.1 s/pt
Selected Heat Flow	T4P
Exotherm Direction	Down
Cell Serial	DRC2-00792
Lid Type	Standard
Cooler	RCS 90
Leave Cooler on at End of Sequence	On
Gas 2	Nitrogen
Gas Selected	Channel 1
Flow Rate	50 mL/min
Secondary Purge	On
Licensed Heat Flow	Heat Flow T4P
Modulation Licensed	Yes
[Versions]
Common IDD Version	1
Cortex Version	VER 2.10.2.31
Driver	5.0.0.6
GDM Version	1.0.3.3
TouchscreenVersion	1.0.0.16145
FEP Version	1.2.1.21
FEP Bootloader	2.0.0.5
AutoSampler Version	2.1.1.26
Auto Sampler Bootloader	2.0.0.5
FCM Version	1.1.0.3
FCM Bootloader	2.0.0.5
[Experiment Logs]
Experiment Log Entry # 1	Data On set to 0
Experiment Log Entry # 3	Equilibrate Segment -80 (C) Started
Experiment Log Entry # 5	Air Cool is off.
Experiment Log Entry # 7	Data On set to 1
Experiment Log Entry # 9	Ramp Segment 5 C/min to 100 Started
Experiment Log Entry # 11	Data On set to 0
Experiment Log Entry # 13	Isothermal Segment 1 min started
Experiment Log Entry # 15	Data On set to 1
Experiment Log Entry # 17	Ramp Segment 5 C/min to -80 Started
Experiment Log Entry # 19	Data On set to 0
Experiment Log Entry # 21	Isothermal Segment 1 min started
Experiment Log Entry # 23	Data On set to 1
Experiment Log Entry # 25	Ramp Segment 5 C/min to 100 Started
[Method Log]
Method Log Entry # 1	Data Off
Method Log Entry # 2	Equilibrate -80 °C
Method Log Entry # 3	Data On
Method Log Entry # 4	(Ramp 68763) Ramp 5 °C/minute to 100 °C
Method Log Entry # 5	Data Off
Method Log Entry # 6	Isothermal 1 minutes
Method Log Entry # 7	Data On
Method Log Entry # 8	(Ramp 68767) Ramp 5 °C/minute to -80 °C
Method Log Entry # 9	Data Off
Method Log Entry # 10	Isothermal 1 minutes
Method Log Entry # 11	Data On
Method Log Entry # 12	(Ramp 68771) Ramp 5 °C/minute to 100 °C
Cell Serial	DRC2-00792
[T1 Calibration]
Slope	-0.008529666
Offset	9.636258
Initial Temperature	98.23
GUID	f8bfdadc-4977-4fdf-ba6d-0ba9134940c3
[TZero Calibration]
Date Applied	11/29/2022 4:06:13 PM
Description	From -89.059 °C to 396.009 °C at 20.000°C/min
Gas Type	Nitrogen
Pan Type	None
Source Files 1	C:\Users\yargerlab\Desktop\DSC Data\General\TZero_calibration_11_29_22_2nd(2).tri
Source Files 2	C:\Users\yargerlab\Desktop\DSC Data\General\TZero_calibration_11_29_22_2nd(3).tri
Delta T Offset	13.05235
Delta T Slope	-0.007271007
Delta T0 Offset	-13.69128
Delta T0 Slope	0.06063341
[Temperature Calibration]
Date Applied	11/29/2022 7:12:28 PM
Description	From 106.590 °C to 186.590 °C at 10.000°C/min
Gas Type	Nitrogen
Pan Type	Tzero Aluminum Hermetic
Source Files 1	C:\Users\yargerlab\Desktop\DSC Data\General\Indium(6).tri
Measured 1	157.391
Known 1	156.598
[Cell Constant Calibration]
Date Applied	11/29/2022 7:12:29 PM
Description	From 106.590 °C to 186.590 °C at 10.000°C/min
Gas Type	Nitrogen
Pan Type	Tzero Aluminum Hermetic
Source Files 1	C:\Users\yargerlab\Desktop\DSC Data\General\Indium(6).tri
T4P KCell	1.006051
Onset Slope	63.26126 mW/°C
[Direct Cp Calibration]
Date Applied	11/30/2022 11:04:51 AM
Description	From -79.983 °C to 298.409 °C at 10.000°C/min
Gas Type	Nitrogen
Pan Type	Tzero Aluminum Hermetic
Source Files 1	C:\Users\yargerlab\Desktop\DSC Data\General\Sapphire_Heat_Capacity_11_30_22.tri
[Rev Cp Calibration]
Date Applied	11/30/2022 1:58:51 PM
Description	From -79.996 °C to 292.812 °C at 3.000°C/min
Gas Type	Nitrogen
Pan Type	Tzero Aluminum Hermetic
Source Files 1	C:\Users\yargerlab\Desktop\DSC Data\General\Sapphire_MDSC_Calibration_11_30_22.tri
[step]
Ramp 5.00 °C/min to 100.00 °C
Time	Temperature	Heat Flow (Normalized)
min	°C	W/g
0.00	-79.75	-0.028
0.03	-79.76	-0.026
0.05	-79.75	-0.024
0.08	-79.73	-0.052
0.10	-79.68	-0.080
0.13	-79.60	-0.081
0.15	-79.52	-0.068
0.18	-79.44	-0.038
0.20	-79.35	-0.025
0.23	-79.25	-0.017
0.25	-79.15	-0.006
0.28	-79.04	0.005
0.30	-78.94	0.016
0.33	-78.83	0.025
0.35	-78.71	0.031
0.38	-78.60	0.035
0.40	-78.48	0.039
0.43	-78.37	0.043
0.45	-78.25	0.047
0.48	-78.13	0.049
0.50	-78.01	0.052
0.53	-77.89	0.053
0.55	-77.77	0.054
0.58	-77.65	0.054
0.60	-77.53	0.056
0.63	-77.41	0.056
0.65	-77.28	0.057
0.68	-77.16	0.057
0.70	-77.04	0.058
0.73	-76.92	0.058
0.75	-76.79	0.059
0.78	-76.67	0.059
0.80	-76.55	0.060
0.83	-76.43	0.060
0.85	-76.30	0.060
0.88	-76.18	0.061
0.90	-76.06	0.061
0.93	-75.93	0.061
0.95	-75.81	0.061
0.98	-75.68	0.061
1.00	-75.56	0.062
1.03	-75.44	0.062
1.05	-75.32	0.062
1.08	-75.19	0.062
1.10	-75.06	0.062
1.13	-74.94	0.062
1.15	-74.82	0.062
1.18	-74.69	0.062
1.20	-74.57	0.062
1.23	-74.45	0.063
1.25	-74.32	0.063
1.28	-74.19	0.062
1.30	-74.07	0.063
1.33	-73.95	0.063
1.35	-73.82	0.063
1.38	-73.69	0.063
1.40	-73.57	0.063
1.43	-73.45	0.063
1.45	-73.32	0.063
1.48	-73.20	0.063
1.50	-73.07	0.063
1.53	-72.95	0.063
1.55	-72.82	0.063
1.58	-72.70	0.062
1.60	-72.57	0.062
1.63	-72.45	0.062
1.65	-72.32	0.062
1.68	-72.20	0.062
1.70	-72.07	0.062
1.73	-71.95	0.062
1.75	-71.82	0.062
1.78	-71.70	0.062
1.80	-71.57	0.062
1.83	-71.45	0.062
1.85	-71.32	0.062
1.88	-71.20	0.062
1.90	-71.07	0.062
1.93	-70.95	0.062
1.95	-70.82	0.062
1.98	-70.70	0.062
2.00	-70.57	0.062
2.03	-70.45	0.062
2.05	-70.32	0.062
2.08	-70.20	0.062
2.10	-70.08	0.062
2.13	-69.95	0.062
2.15	-69.82	0.062
2.18	-69.70	0.062
2.20	-69.57	0.062
2.23	-69.45	0.062
2.25	-69.32	0.062
2.28	-69.20	0.062
2.30	-69.07	0.062
2.33	-68.95	0.062
2.35	-68.82	0.062
2.38	-68.70	0.062
2.40	-68.57	0.062
2.43	-68.45	0.062
2.45	-68.32	0.062
2.48	-68.20	0.062
2.50	-68.07	0.062
2.53	-67.95	0.062
2.55	-67.82	0.062
2.58	-67.70	0.062
2.60	-67.57	0.062
2.63	-67.45	0.062
2.65	-67.32	0.062
2.68	-67.20	0.062
2.70	-67.07	0.062
2.73	-66.95	0.062
2.75	-66.82	0.062
2.78	-66.70	0.062
2.80	-66.57	0.062
2.83	-66.45	0.062
2.85	-66.32	0.062
2.88	-66.20	0.062
2.90	-66.07	0.062
2.93	-65.95	0.062
2.95	-65.82	0.062
2.98	-65.70	0.062
3.00	-65.57	0.062
3.03	-65.45	0.062
3.05	-65.32	0.062
3.08	-65.20	0.062
3.10	-65.07	0.062
3.13	-64.95	0.062
3.15	-64.82	0.062
3.18	-64.70	0.062
3.20	-64.57	0.062
3.23	-64.45	0.062
3.25	-64.32	0.062
3.28	-64.20	0.062
3.30	-64.07	0.062
3.33	-63.95	0.062
3.35	-63.82	0.062
3.38	-63.70	0.062
3.40	-63.57	0.062
3.43	-63.45	0.062
3.45	-63.32	0.062
3.48	-63.20	0.062
3.50	-63.07	0.062
3.53	-62.95	0.062
3.55	-62.82	0.062
3.58	-62.70	0.062
3.60	-62.57	0.062
3.63	-62.45	0.062
3.65	-62.32	0.062
3.68	-62.20	0.062
3.70	-62.07	0.062
3.73	-61.95	0.062
3.75	-61.82	0.062
3.78	-61.70	0.062
3.80	-61.57	0.062
3.83	-61.45	0.062
3.85	-61.32	0.062
3.88	-61.20	0.062
3.90	-61.07	0.062
3.93	-60.95	0.062
3.95	-60.82	0.062
3.98	-60.70	0.062
4.00	-60.57	0.062
4.03	-60.45	0.062
4.05	-60.32	0.062
4.08	-60.20	0.062
4.10	-60.07	0.062
4.13	-59.95	0.062
4.15	-59.82	0.062
4.18	-59.70	0.062
4.20	-59.57	0.062
4.23	-59.45	0.062
4.25	-59.32	0.062
4.28	-59.20	0.062
4.30	-59.07	0.062
4.33	-58.95	0.062
4.35	-58.82	0.062
4.38	-58.70	0.062
4.40	-58.57	0.062
4.43	-58.45	0.062
4.45	-58.32	0.062
4.48	-58.19	0.062
4.50	-58.07	0.062
4.53	-57.95	0.062
4.55	-57.82	0.062
4.58	-57.70	0.062
4.60	-57.57	0.062
4.63	-57.45	0.062
4.65	-57.32	0.062
4.68	-57.19	0.062
4.70	-57.07	0.062
4.73	-56.95	0.062
4.75	-56.82	0.062
4.78	-56.70	0.062
4.80	-56.57	0.062
4.83	-56.45	0.062
4.85	-56.32	0.062
4.88	-56.20	0.062
4.90	-56.07	0.062
4.93	-55.95	0.062
4.95	-55.82	0.062
4.98	-55.70	0.062
5.00	-55.57	0.062
5.03	-55.44	0.062
5.05	-55.32	0.062
5.08	-55.19	0.062
5.10	-55.07	0.062
5.13	-54.95	0.062
5.15	-54.82	0.062
5.18	-54.70	0.062
5.20	-54.57	0.062
5.23	-54.44	0.062
5.25	-54.32	0.062
5.28	-54.19	0.062
5.30	-54.07	0.062
5.33	-53.95	0.062
5.35	-53.82	0.062
5.38	-53.70	0.062
5.40	-53.57	0.062
5.43	-53.45	0.062
5.45	-53.32	0.062
5.48	-53.20	0.062
5.50	-53.07	0.062
5.53	-52.95	0.062
5.55	-52.82	0.062
5.58	-52.70	0.062
5.60	-52.57	0.063
5.63	-52.45	0.063
5.65	-52.32	0.063
5.68	-52.20	0.062
5.70	-52.07	0.063
5.73	-51.95	0.063
5.75	-51.82	0.063
5.78	-51.70	0.063
5.80	-51.57	0.063
5.83	-51.45	0.063
5.85	-51.32	0.063
5.88	-51.20	0.063
5.90	-51.07	0.063
5.93	-50.95	0.063
5.95	-50.82	0.063
5.98	-50.70	0.063
6.00	-50.57	0.063
6.03	-50.45	0.063
6.05	-50.32	0.063
6.08	-50.20	0.063
6.10	-50.07	0.063
6.13	-49.95	0.063
6.15	-49.82	0.063
6.18	-49.70	0.063
6.20	-49.57	0.063
6.23	-49.45	0.063
6.25	-49.32	0.063
6.28	-49.20	0.063
6.30	-49.07	0.063
6.33	-48.95	0.063
6.35	-48.82	0.063
6.38	-48.70	0.063
6.40	-48.57	0.063
6.43	-48.45	0.063
6.45	-48.32	0.063
6.48	-48.20	0.063
6.50	-48.07	0.063
6.53	-47.95	0.063
6.55	-47.82	0.063
6.58	-47.70	0.063
6.60	-47.57	0.063
6.63	-47.45	0.063
6.65	-47.32	0.063
6.68	-47.20	0.063
6.70	-47.07	0.063
6.73	-46.95	0.063
6.75	-46.82	0.063
6.78	-46.70	0.063
6.80	-46.57	0.063
6.83	-46.45	0.063
6.85	-46.32	0.063
6.88	-46.20	0.063
6.90	-46.07	0.063
6.93	-45.95	0.063
6.95	-45.82	0.063
6.98	-45.70	0.063
7.00	-45.57	0.063
7.03	-45.45	0.063
7.05	-45.32	0.063
7.08	-45.20	0.063
7.10	-45.07	0.063
7.13	-44.95	0.063
7.15	-44.82	0.063
7.18	-44.70	0.063
7.20	-44.57	0.063
7.23	-44.45	0.063
7.25	-44.32	0.063
7.28	-44.20	0.063
7.30	-44.08	0.063
7.33	-43.95	0.063
7.35	-43.82	0.063
7.38	-43.70	0.063
7.40	-43.57	0.063
7.43	-43.45	0.063
7.45	-43.32	0.063
7.48	-43.20	0.063
7.50	-43.07	0.063
7.53	-42.95	0.063
7.55	-42.82	0.063
7.58	-42.70	0.064
7.60	-42.57	0.064
7.63	-42.45	0.064
7.65	-42.32	0.064
7.68	-42.20	0.063
7.70	-42.07	0.063
7.73	-41.95	0.063
7.75	-41.82	0.063
7.78	-41.70	0.064
7.80	-41.57	0.064
7.83	-41.45	0.064
7.85	-41.32	0.064
7.88	-41.20	0.064
7.90	-41.07	0.064
7.93	-40.95	0.064
7.95	-40.82	0.064
7.98	-40.70	0.064
8.00	-40.57	0.064
8.03	-40.45	0.064
8.05	-40.32	0.064
8.08	-40.20	0.064
8.10	-40.07	0.064
8.13	-39.95	0.064
8.15	-39.82	0.064
8.18	-39.70	0.064
8.20	-39.57	0.064
8.23	-39.44	0.064
8.25	-39.32	0.064
8.28	-39.20	0.064
8.30	-39.07	0.064
8.33	-38.95	0.064
8.35	-38.82	0.064
8.38	-38.69	0.064
8.40	-38.57	0.064
8.43	-38.44	0.064
8.45	-38.32	0.064
8.48	-38.19	0.064
8.50	-38.07	0.064
8.53	-37.94	0.064
8.55	-37.82	0.064
8.58	-37.69	0.064
8.60	-37.57	0.064
8.63	-37.44	0.064
8.65	-37.32	0.064
8.68	-37.19	0.064
8.70	-37.07	0.064
8.73	-36.94	0.064
8.75	-36.82	0.064
8.78	-36.69	0.064
8.80	-36.57	0.064
8.83	-36.44	0.064
8.85	-36.32	0.064
8.88	-36.19	0.064
8.90	-36.07	0.064
8.93	-35.94	0.064
8.95	-35.82	0.064
8.98	-35.69	0.064
9.00	-35.56	0.064
9.03	-35.44	0.064
9.05	-35.32	0.064
9.08	-35.19	0.064
9.10	-35.07	0.064
9.13	-34.94	0.064
9.15	-34.81	0.064
9.18	-34.69	0.064
9.20	-34.56	0.064
9.23	-34.44	0.064
9.25	-34.31	0.064
9.28	-34.19	0.064
9.30	-34.06	0.064
9.33	-33.94	0.064
9.35	-33.81	0.064
9.38	-33.69	0.064
9.40	-33.56	0.064
9.43	-33.44	0.064
9.45	-33.31	0.064
9.48	-33.19	0.065
9.50	-33.06	0.065
9.53	-32.94	0.065
9.55	-32.81	0.065
9.58	-32.69	0.065
9.60	-32.56	0.065
9.63	-32.44	0.065
9.65	-32.31	0.065
9.68	-32.19	0.065
9.70	-32.06	0.064
9.73	-31.94	0.065
9.75	-31.81	0.065
9.78	-31.69	0.064
9.80	-31.56	0.065
9.83	-31.44	0.065
9.85	-31.31	0.064
9.88	-31.19	0.064
9.90	-31.06	0.065
9.93	-30.94	0.065
9.95	-30.81	0.065
9.98	-30.69	0.065
10.00	-30.56	0.065
10.03	-30.44	0.065
10.05	-30.31	0.065
10.08	-30.19	0.065
10.10	-30.06	0.065
10.13	-29.93	0.065
10.15	-29.81	0.065
10.18	-29.69	0.065
10.20	-29.56	0.065
10.23	-29.44	0.065
10.25	-29.31	0.065
10.28	-29.18	0.065
10.30	-29.06	0.065
10.33	-28.93	0.065
10.35	-28.81	0.065
10.38	-28.68	0.065
10.40	-28.56	0.065
10.43	-28.43	0.065
10.45	-28.31	0.065
10.48	-28.18	0.065
10.50	-28.06	0.065
10.53	-27.93	0.065
10.55	-27.81	0.065
10.58	-27.68	0.065
10.60	-27.56	0.065
10.63	-27.43	0.065
10.65	-27.31	0.065
10.68	-27.18	0.065
10.70	-27.06	0.065
10.73	-26.93	0.065
10.75	-26.81	0.065
10.78	-26.68	0.065
10.80	-26.56	0.065
10.83	-26.43	0.065
10.85	-26.31	0.065
10.88	-26.18	0.065
10.90	-26.06	0.065
10.93	-25.93	0.065
10.95	-25.81	0.065
10.98	-25.68	0.065
11.00	-25.56	0.065
11.03	-25.43	0.065
11.05	-25.30	0.065
11.08	-25.18	0.065
11.10	-25.05	0.065
11.13	-24.93	0.065
11.15	-24.80	0.065
11.18	-24.68	0.065
11.20	-24.55	0.065
11.23	-24.43	0.065
11.25	-24.30	0.065
11.28	-24.18	0.065
11.30	-24.05	0.065
11.33	-23.93	0.066
11.35	-23.80	0.065
11.38	-23.68	0.065
11.40	-23.55	0.065
11.43	-23.43	0.065
11.45	-23.30	0.066
11.48	-23.18	0.066
11.50	-23.05	0.066
11.53	-22.93	0.066
11.55	-22.80	0.066
11.58	-22.68	0.066
11.60	-22.55	0.066
11.63	-22.43	0.066
11.65	-22.30	0.066
11.68	-22.18	0.066
11.70	-22.05	0.066
11.73	-21.92	0.066
11.75	-21.80	0.066
11.78	-21.68	0.066
11.80	-21.55	0.066
11.83	-21.42	0.066
11.85	-21.30	0.066
11.88	-21.18	0.066
11.90	-21.05	0.066
11.93	-20.92	0.066
11.95	-20.80	0.066
11.98	-20.67	0.066
12.00	-20.55	0.066
12.03	-20.42	0.066
12.05	-20.30	0.066
12.08	-20.17	0.066
12.10	-20.05	0.066
12.13	-19.92	0.066
12.15	-19.80	0.066
12.18	-19.67	0.066
12.20	-19.55	0.066
12.23	-19.42	0.066
12.25	-19.30	0.066
12.28	-19.17	0.066
12.30	-19.05	0.066
12.33	-18.92	0.066
12.35	-18.80	0.066
12.38	-18.67	0.066
12.40	-18.55	0.066
12.43	-18.42	0.066
12.45	-18.30	0.066
12.48	-18.17	0.066
12.50	-18.05	0.066
12.53	-17.92	0.066
12.55	-17.80	0.066
12.58	-17.67	0.066
12.60	-17.55	0.066
12.63	-17.42	0.066
12.65	-17.30	0.066
12.68	-17.17	0.066
12.70	-17.05	0.066
12.73	-16.92	0.067
12.75	-16.80	0.066
12.78	-16.67	0.066
12.80	-16.55	0.067
12.83	-16.42	0.067
12.85	-16.30	0.067
12.88	-16.17	0.067
12.90	-16.05	0.067
12.93	-15.92	0.067
12.95	-15.79	0.067
12.98	-15.67	0.067
13.00	-15.54	0.067
13.03	-15.42	0.067
13.05	-15.29	0.067
13.08	-15.17	0.067
13.10	-15.04	0.067
13.13	-14.92	0.067
13.15	-14.79	0.067
13.18	-14.67	0.067
13.20	-14.54	0.067
13.23	-14.42	0.067
13.25	-14.29	0.067
13.28	-14.17	0.067
13.30	-14.04	0.067
13.33	-13.92	0.067
13.35	-13.79	0.067
13.38	-13.67	0.067
13.40	-13.54	0.067
13.43	-13.42	0.067
13.45	-13.29	0.067
13.48	-13.17	0.067
13.50	-13.04	0.067
13.53	-12.92	0.067
13.55	-12.79	0.067
13.58	-12.67	0.067
13.60	-12.54	0.067
13.63	-12.42	0.067
13.65	-12.29	0.067
13.68	-12.17	0.067
13.70	-12.04	0.067
13.73	-11.92	0.067
13.75	-11.79	0.067
13.78	-11.67	0.067
13.80	-11.54	0.067
13.83	-11.42	0.067
13.85	-11.29	0.067
13.88	-11.16	0.067
13.90	-11.04	0.067
13.93	-10.92	0.067
13.95	-10.79	0.067
13.98	-10.67	0.067
14.00	-10.54	0.067
14.03	-10.42	0.067
14.05	-10.29	0.067
14.08	-10.17	0.067
14.10	-10.04	0.067
14.13	-9.92	0.067
14.15	-9.79	0.067
14.18	-9.67	0.067
14.20	-9.54	0.067
14.23	-9.42	0.067
14.25	-9.29	0.067
14.28	-9.16	0.067
14.30	-9.04	0.067
14.33	-8.91	0.067
14.35	-8.79	0.067
14.38	-8.66	0.067
14.40	-8.54	0.067
14.43	-8.41	0.067
14.45	-8.29	0.068
14.48	-8.16	0.068
14.50	-8.04	0.068
14.53	-7.91	0.068
14.55	-7.79	0.068
14.58	-7.66	0.068
14.60	-7.54	0.068
14.63	-7.41	0.068
14.65	-7.29	0.068
14.68	-7.16	0.068
14.70	-7.04	0.068
14.73	-6.91	0.068
14.75	-6.79	0.068
14.78	-6.66	0.068
14.80	-6.54	0.068
14.83	-6.41	0.068
14.85	-6.29	0.068
14.88	-6.16	0.068
14.90	-6.04	0.068
14.93	-5.91	0.068
14.95	-5.79	0.068
14.98	-5.66	0.068
15.00	-5.54	0.068
15.03	-5.41	0.068
15.05	-5.29	0.068
15.08	-5.16	0.068
15.10	-5.04	0.068
15.13	-4.91	0.068
15.15	-4.79	0.069
15.18	-4.66	0.069
15.20	-4.54	0.069
15.23	-4.41	0.069
15.25	-4.29	0.069
15.28	-4.16	0.069
15.30	-4.03	0.069
15.33	-3.91	0.069
15.35	-3.78	0.069
15.38	-3.66	0.069
15.40	-3.53	0.069
15.43	-3.41	0.069
15.45	-3.28	0.069
15.48	-3.16	0.069
15.50	-3.03	0.069
15.53	-2.91	0.069
15.55	-2.78	0.069
15.58	-2.66	0.069
15.60	-2.53	0.069
15.63	-2.41	0.069
15.65	-2.28	0.069
15.68	-2.16	0.069
15.70	-2.03	0.069
15.73	-1.91	0.069
15.75	-1.78	0.069
15.78	-1.66	0.069
15.80	-1.53	0.069
15.83	-1.41	0.069
15.85	-1.28	0.069
15.88	-1.16	0.069
15.90	-1.03	0.069
15.93	-0.91	0.069
15.95	-0.78	0.069
15.98	-0.66	0.069
16.00	-0.53	0.069
16.03	-0.41	0.069
16.05	-0.28	0.070
16.08	-0.16	0.070
16.10	-0.03	0.070
16.13	0.09	0.070
16.15	0.22	0.070
16.18	0.34	0.070
16.20	0.47	0.070
16.23	0.59	0.070
16.25	0.72	0.070
16.28	0.84	0.070
16.30	0.97	0.070
16.33	1.10	0.070
16.35	1.22	0.070
16.38	1.34	0.070
16.40	1.47	0.070
16.43	1.59	0.070
16.45	1.72	0.070
16.48	1.85	0.070
16.50	1.97	0.070
16.53	2.09	0.070
16.55	2.22	0.070
16.58	2.34	0.070
16.60	2.47	0.070
16.63	2.60	0.070
16.65	2.72	0.070
16.68	2.85	0.070
16.70	2.97	0.070
16.73	3.10	0.070
16.75	3.22	0.070
16.78	3.35	0.070
16.80	3.47	0.070
16.83	3.60	0.071
16.85	3.72	0.071
16.88	3.85	0.071
16.90	3.97	0.071
16.93	4.10	0.071
16.95	4.22	0.071
16.98	4.35	0.071
17.00	4.47	0.071
17.03	4.60	0.071
17.05	4.72	0.071
17.08	4.85	0.071
17.10	4.97	0.071
17.13	5.10	0.071
17.15	5.22	0.071
17.18	5.35	0.071
17.20	5.47	0.071
17.23	5.60	0.071
17.25	5.72	0.071
17.28	5.85	0.071
17.30	5.97	0.071
17.33	6.10	0.071
17.35	6.22	0.071
17.38	6.35	0.072
17.40	6.47	0.072
17.43	6.60	0.072
17.45	6.72	0.072
17.48	6.85	0.072
17.50	6.97	0.072
17.53	7.10	0.072
17.55	7.22	0.072
17.58	7.35	0.072
17.60	7.47	0.072
17.63	7.60	0.072
17.65	7.73	0.072
17.68	7.85	0.072
17.70	7.97	0.072
17.73	8.10	0.072
17.75	8.22	0.072
17.78	8.35	0.072
17.80	8.48	0.072
17.83	8.60	0.072
17.85	8.73	0.072
17.88	8.85	0.072
17.90	8.98	0.072
17.93	9.10	0.072
17.95	9.23	0.073
17.98	9.35	0.073
18.00	9.48	0.073
18.03	9.60	0.073
18.05	9.73	0.073
18.08	9.85	0.073
18.10	9.98	0.073
18.13	10.10	0.073
18.15	10.23	0.073
18.18	10.35	0.073
18.20	10.48	0.073
18.23	10.60	0.073
18.25	10.73	0.073
18.28	10.85	0.073
18.30	10.98	0.073
18.33	11.10	0.073
18.35	11.23	0.073
18.38	11.35	0.073
18.40	11.48	0.073
18.43	11.60	0.073
18.45	11.73	0.073
18.48	11.85	0.073
18.50	11.98	0.073
18.53	12.10	0.073
18.55	12.23	0.073
18.58	12.35	0.073
18.60	12.48	0.073
18.63	12.60	0.073
18.65	12.73	0.073
18.68	12.85	0.074
18.70	12.98	0.073
18.73	13.10	0.073
18.75	13.23	0.073
18.78	13.35	0.073
18.80	13.48	0.073
18.83	13.60	0.074
18.85	13.73	0.074
18.88	13.85	0.074
18.90	13.98	0.074
18.93	14.11	0.074
18.95	14.23	0.074
18.98	14.35	0.074
19.00	14.48	0.074
19.03	14.61	0.074
19.05	14.73	0.074
19.08	14.86	0.074
19.10	14.98	0.074
19.13	15.11	0.074
19.15	15.23	0.074
19.18	15.36	0.074
19.20	15.48	0.074
19.23	15.61	0.074
19.25	15.73	0.075
19.28	15.86	0.075
19.30	15.98	0.075
19.33	16.11	0.075
19.35	16.23	0.075
19.38	16.36	0.075
19.40	16.48	0.075
19.43	16.61	0.075
19.45	16.73	0.075
19.48	16.86	0.075
19.50	16.98	0.075
19.53	17.11	0.075
19.55	17.23	0.075
19.58	17.36	0.075
19.60	17.48	0.075
19.63	17.61	0.075
19.65	17.73	0.075
19.68	17.86	0.075
19.70	17.98	0.075
19.73	18.11	0.076
19.75	18.23	0.076
19.78	18.36	0.076
19.80	18.48	0.076
19.83	18.61	0.076
19.85	18.73	0.076
19.88	18.86	0.076
19.90	18.98	0.076
19.93	19.11	0.076
19.95	19.23	0.076
19.98	19.36	0.076
20.00	19.48	0.076
20.03	19.61	0.076
20.05	19.73	0.076
20.08	19.86	0.076
20.10	19.98	0.076
20.13	20.11	0.076
20.15	20.23	0.076
20.18	20.36	0.076
20.20	20.48	0.076
20.23	20.61	0.076
20.25	20.74	0.077
20.28	20.86	0.077
20.30	20.98	0.077
20.33	21.11	0.077
20.35	21.23	0.077
20.38	21.36	0.077
20.40	21.48	0.077
20.43	21.61	0.077
20.45	21.73	0.077
20.48	21.86	0.077
20.50	21.99	0.077
20.53	22.11	0.077
20.55	22.24	0.077
20.58	22.36	0.077
20.60	22.49	0.077
20.63	22.61	0.077
20.65	22.73	0.077
20.68	22.86	0.078
20.70	22.98	0.078
20.73	23.11	0.078
20.75	23.24	0.078
20.78	23.36	0.078
20.80	23.49	0.078
20.83	23.61	0.078
20.85	23.74	0.078
20.88	23.86	0.078
20.90	23.99	0.078
20.93	24.11	0.078
20.95	24.24	0.078
20.98	24.36	0.078
21.00	24.49	0.078
21.03	24.61	0.078
21.05	24.74	0.078
21.08	24.86	0.078
21.10	24.99	0.078
21.13	25.11	0.079
21.15	25.24	0.079
21.18	25.36	0.079
21.20	25.49	0.079
21.23	25.61	0.079
21.25	25.74	0.079
21.28	25.86	0.079
21.30	25.99	0.079
21.33	26.11	0.079
21.35	26.24	0.079
21.38	26.36	0.079
21.40	26.49	0.079
21.43	26.61	0.079
21.45	26.74	0.079
21.48	26.86	0.079
21.50	26.99	0.079
21.53	27.11	0.079
21.55	27.24	0.080
21.58	27.36	0.080
21.60	27.49	0.080
21.63	27.62	0.080
21.65	27.74	0.080
21.68	27.86	0.080
21.70	27.99	0.080
21.73	28.11	0.080
21.75	28.24	0.080
21.78	28.37	0.080
21.80	28.49	0.080
21.83	28.61	0.080
21.85	28.74	0.080
21.88	28.87	0.080
21.90	28.99	0.080
21.93	29.12	0.080
21.95	29.24	0.080
21.98	29.37	0.081
22.00	29.49	0.081
22.03	29.62	0.081
22.05	29.74	0.081
22.08	29.87	0.081
22.10	29.99	0.081
22.13	30.12	0.081
22.15	30.24	0.081
22.18	30.37	0.081
22.20	30.49	0.081
22.23	30.62	0.081
22.25	30.74	0.081
22.28	30.87	0.081
22.30	30.99	0.081
22.33	31.12	0.081
22.35	31.24	0.081
22.38	31.37	0.081
22.40	31.49	0.082
22.43	31.62	0.082
22.45	31.74	0.082
22.48	31.87	0.082
22.50	31.99	0.082
22.53	32.12	0.082
22.55	32.24	0.082
22.58	32.37	0.082
22.60	32.49	0.082
22.63	32.62	0.082
22.65	32.74	0.082
22.68	32.87	0.082
22.70	32.99	0.082
22.73	33.12	0.082
22.75	33.24	0.082
22.78	33.37	0.082
22.80	33.49	0.082
22.83	33.62	0.083
22.85	33.74	0.083
22.88	33.87	0.083
22.90	33.99	0.083
22.93	34.12	0.083
22.95	34.24	0.083
22.98	34.37	0.083
23.00	34.49	0.083
23.03	34.62	0.083
23.05	34.74	0.083
23.08	34.87	0.083
23.10	34.99	0.083
23.13	35.12	0.083
23.15	35.24	0.084
23.18	35.37	0.084
23.20	35.49	0.084
23.23	35.62	0.084
23.25	35.74	0.084
23.28	35.87	0.084
23.30	35.99	0.084
23.33	36.12	0.084
23.35	36.24	0.084
23.38	36.37	0.084
23.40	36.50	0.084
23.43	36.62	0.084
23.45	36.74	0.084
23.48	36.87	0.084
23.50	36.99	0.085
23.53	37.12	0.085
23.55	37.24	0.085
23.58	37.37	0.085
23.60	37.50	0.085
23.63	37.62	0.085
23.65	37.75	0.085
23.68	37.87	0.085
23.70	38.00	0.085
23.73	38.12	0.085
23.75	38.25	0.085
23.78	38.37	0.085
23.80	38.50	0.085
23.83	38.62	0.086
23.85	38.75	0.086
23.88	38.87	0.086
23.90	39.00	0.086
23.93	39.12	0.086
23.95	39.25	0.086
23.98	39.37	0.086
24.00	39.50	0.086
24.03	39.62	0.086
24.05	39.75	0.086
24.08	39.87	0.086
24.10	40.00	0.087
24.13	40.12	0.087
24.15	40.25	0.087
24.18	40.37	0.087
24.20	40.50	0.087
24.23	40.62	0.087
24.25	40.75	0.087
24.28	40.87	0.087
24.30	41.00	0.087
24.33	41.12	0.087
24.35	41.25	0.087
24.38	41.37	0.087
24.40	41.50	0.088
24.43	41.62	0.088
24.45	41.75	0.088
24.48	41.87	0.088
24.50	42.00	0.088
24.53	42.12	0.088
24.55	42.25	0.088
24.58	42.37	0.088
24.60	42.50	0.088
24.63	42.62	0.088
24.65	42.75	0.088
24.68	42.87	0.088
24.70	43.00	0.089
24.73	43.12	0.089
24.75	43.25	0.089
24.78	43.37	0.089
24.80	43.50	0.089
24.83	43.62	0.089
24.85	43.75	0.089
24.88	43.87	0.089
24.90	44.00	0.089
24.93	44.12	0.089
24.95	44.25	0.090
24.98	44.37	0.090
25.00	44.50	0.090
25.03	44.62	0.090
25.05	44.75	0.090
25.08	44.88	0.090
25.10	45.00	0.090
25.13	45.13	0.090
25.15	45.25	0.090
25.18	45.38	0.091
25.20	45.50	0.091
25.23	45.62	0.091
25.25	45.75	0.091
25.28	45.88	0.091
25.30	46.00	0.091
25.33	46.12	0.091
25.35	46.25	0.091
25.38	46.38	0.091
25.40	46.50	0.091
25.43	46.62	0.092
25.45	46.75	0.092
25.48	46.88	0.092
25.50	47.00	0.092
25.53	47.13	0.092
25.55	47.25	0.092
25.58	47.38	0.092
25.60	47.50	0.092
25.63	47.63	0.092
25.65	47.75	0.092
25.68	47.88	0.093
25.70	48.00	0.093
25.73	48.13	0.093
25.75	48.25	0.093
25.78	48.38	0.093
25.80	48.50	0.093
25.83	48.63	0.093
25.85	48.75	0.093
25.88	48.88	0.093
25.90	49.00	0.094
25.93	49.13	0.094
25.95	49.25	0.094
25.98	49.38	0.094
26.00	49.50	0.094
26.03	49.63	0.094
26.05	49.75	0.094
26.08	49.88	0.094
26.10	50.00	0.095
26.13	50.13	0.095
26.15	50.25	0.095
26.18	50.38	0.095
26.20	50.50	0.095
26.23	50.63	0.095
26.25	50.75	0.095
26.28	50.88	0.095
26.30	51.00	0.096
26.33	51.13	0.096
26.35	51.25	0.096
26.38	51.38	0.096
26.40	51.50	0.096
26.43	51.63	0.096
26.45	51.75	0.096
26.48	51.88	0.097
26.50	52.00	0.097
26.53	52.13	0.097
26.55	52.25	0.097
26.58	52.38	0.097
26.60	52.50	0.097
26.63	52.63	0.098
26.65	52.75	0.098
26.68	52.88	0.098
26.70	53.00	0.098
26.73	53.13	0.098
26.75	53.25	0.098
26.78	53.38	0.099
26.80	53.50	0.099
26.83	53.63	0.099
26.85	53.75	0.099
26.88	53.88	0.099
26.90	54.00	0.099
26.93	54.13	0.100
26.95	54.25	0.100
26.98	54.38	0.100
27.00	54.50	0.100
27.03	54.63	0.100
27.05	54.75	0.100
27.08	54.88	0.101
27.10	55.00	0.101
27.13	55.13	0.101
27.15	55.25	0.101
27.18	55.38	0.101
27.20	55.50	0.101
27.23	55.63	0.102
27.25	55.75	0.102
27.28	55.88	0.102
27.30	56.00	0.102
27.33	56.13	0.102
27.35	56.25	0.103
27.38	56.38	0.103
27.40	56.50	0.103
27.43	56.63	0.103
27.45	56.75	0.103
27.48	56.88	0.104
27.50	57.00	0.104
27.53	57.13	0.104
27.55	57.25	0.104
27.58	57.38	0.104
27.60	57.50	0.105
27.63	57.63	0.105
27.65	57.75	0.105
27.68	57.88	0.105
27.70	58.00	0.105
27.73	58.13	0.105
27.75	58.25	0.105
27.78	58.38	0.106
27.80	58.50	0.106
27.83	58.63	0.106
27.85	58.75	0.106
27.88	58.88	0.106
27.90	59.00	0.106
27.93	59.13	0.107
27.95	59.26	0.107
27.98	59.38	0.107
28.00	59.51	0.107
28.03	59.63	0.107
28.05	59.76	0.108
28.08	59.88	0.108
28.10	60.00	0.108
28.13	60.13	0.108
28.15	60.26	0.108
28.18	60.38	0.108
28.20	60.51	0.109
28.23	60.63	0.109
28.25	60.76	0.109
28.28	60.88	0.109
28.30	61.01	0.109
28.33	61.13	0.110
28.35	61.25	0.110
28.38	61.38	0.110
28.40	61.50	0.110
28.43	61.63	0.110
28.45	61.76	0.110
28.48	61.88	0.111
28.50	62.01	0.111
28.53	62.13	0.111
28.55	62.26	0.111
28.58	62.38	0.111
28.60	62.51	0.112
28.63	62.63	0.112
28.65	62.76	0.112
28.68	62.88	0.112
28.70	63.01	0.112
28.73	63.13	0.112
28.75	63.26	0.113
28.78	63.38	0.113
28.80	63.51	0.113
28.83	63.63	0.113
28.85	63.76	0.113
28.88	63.88	0.113
28.90	64.01	0.114
28.93	64.13	0.114
28.95	64.26	0.114
28.98	64.38	0.114
29.00	64.51	0.114
29.03	64.63	0.114
29.05	64.76	0.115
29.08	64.88	0.115
29.10	65.01	0.115
29.13	65.13	0.115
29.15	65.26	0.115
29.18	65.38	0.115
29.20	65.51	0.115
29.23	65.63	0.116
29.25	65.76	0.116
29.28	65.88	0.116
29.30	66.01	0.116
29.33	66.13	0.116
29.35	66.26	0.116
29.38	66.38	0.116
29.40	66.51	0.116
29.43	66.63	0.116
29.45	66.76	0.116
29.48	66.88	0.117
29.50	67.01	0.117
29.53	67.13	0.117
29.55	67.26	0.117
29.58	67.38	0.117
29.60	67.51	0.117
29.63	67.63	0.117
29.65	67.76	0.117
29.68	67.88	0.117
29.70	68.01	0.117
29.73	68.13	0.117
29.75	68.26	0.117
29.78	68.38	0.117
29.80	68.51	0.117
29.83	68.63	0.117
29.85	68.76	0.117
29.88	68.88	0.117
29.90	69.01	0.117
29.93	69.13	0.117
29.95	69.26	0.117
29.98	69.38	0.117
30.00	69.51	0.117
30.03	69.63	0.117
30.05	69.76	0.117
30.08	69.88	0.117
30.10	70.01	0.117
30.13	70.13	0.117
30.15	70.26	0.117
30.18	70.38	0.117
30.20	70.51	0.117
30.23	70.63	0.117
30.25	70.76	0.117
30.28	70.89	0.116
30.30	71.01	0.116
30.33	71.14	0.116
30.35	71.26	0.116
30.38	71.39	0.116
30.40	71.51	0.116
30.43	71.64	0.116
30.45	71.76	0.116
30.48	71.89	0.116
30.50	72.01	0.116
30.53	72.14	0.116
30.55	72.26	0.116
30.58	72.39	0.116
30.60	72.51	0.115
30.63	72.64	0.115
30.65	72.76	0.115
30.68	72.89	0.115
30.70	73.01	0.115
30.73	73.14	0.115
30.75	73.26	0.115
30.78	73.39	0.115
30.80	73.51	0.115
30.83	73.64	0.115
30.85	73.76	0.115
30.88	73.89	0.115
30.90	74.01	0.115
30.93	74.14	0.115
30.95	74.26	0.115
30.98	74.39	0.115
31.00	74.51	0.115
31.03	74.64	0.115
31.05	74.76	0.115
31.08	74.89	0.115
31.10	75.01	0.115
31.13	75.14	0.115
31.15	75.26	0.115
31.18	75.39	0.115
31.20	75.51	0.115
31.23	75.64	0.115
31.25	75.76	0.115
31.28	75.89	0.115
31.30	76.01	0.115
31.33	76.14	0.115
31.35	76.26	0.115
31.38	76.39	0.115
31.40	76.51	0.115
31.43	76.64	0.115
31.45	76.76	0.115
31.48	76.89	0.115
31.50	77.01	0.115
31.53	77.14	0.115
31.55	77.27	0.115
31.58	77.39	0.116
31.60	77.52	0.116
31.63	77.64	0.116
31.65	77.76	0.116
31.68	77.89	0.116
31.70	78.02	0.116
31.73	78.14	0.116
31.75	78.27	0.116
31.78	78.39	0.116
31.80	78.52	0.116
31.83	78.64	0.116
31.85	78.77	0.116
31.88	78.89	0.116
31.90	79.02	0.116
31.93	79.14	0.116
31.95	79.27	0.116
31.98	79.39	0.116
32.00	79.52	0.116
32.03	79.64	0.117
32.05	79.77	0.117
32.08	79.89	0.117
32.10	80.02	0.117
32.13	80.14	0.117
32.15	80.27	0.117
32.18	80.39	0.117
32.20	80.52	0.117
32.23	80.64	0.117
32.25	80.77	0.117
32.28	80.89	0.117
32.30	81.02	0.117
32.33	81.14	0.117
32.35	81.27	0.117
32.38	81.39	0.117
32.40	81.52	0.117
32.43	81.64	0.118
32.45	81.77	0.118
32.48	81.89	0.118
32.50	82.02	0.118
32.53	82.14	0.118
32.55	82.27	0.118
32.58	82.39	0.118
32.60	82.52	0.118
32.63	82.64	0.118
32.65	82.77	0.118
32.68	82.89	0.118
32.70	83.02	0.119
32.73	83.14	0.119
32.75	83.27	0.119
32.78	83.39	0.119
32.80	83.52	0.119
32.83	83.64	0.119
32.85	83.77	0.119
32.88	83.89	0.119
32.90	84.02	0.119
32.93	84.14	0.119
32.95	84.27	0.119
32.98	84.39	0.120
33.00	84.52	0.120
33.03	84.64	0.120
33.05	84.77	0.120
33.08	84.89	0.120
33.10	85.02	0.120
33.13	85.14	0.120
33.15	85.27	0.120
33.18	85.39	0.120
33.20	85.52	0.120
33.23	85.64	0.121
33.25	85.77	0.121
33.28	85.89	0.121
33.30	86.02	0.121
33.33	86.14	0.121
33.35	86.27	0.121
33.38	86.39	0.121
33.40	86.52	0.121
33.43	86.64	0.121
33.45	86.77	0.122
33.48	86.89	0.122
33.50	87.02	0.122
33.53	87.14	0.122
33.55	87.27	0.122
33.58	87.39	0.122
33.60	87.52	0.122
33.63	87.64	0.123
33.65	87.77	0.123
33.68	87.89	0.123
33.70	88.02	0.123
33.73	88.14	0.123
33.75	88.27	0.123
33.78	88.39	0.123
33.80	88.52	0.123
33.83	88.64	0.124
33.85	88.77	0.124
33.88	88.90	0.124
33.90	89.02	0.124
33.93	89.14	0.124
33.95	89.27	0.124
33.98	89.40	0.125
34.00	89.52	0.125
34.03	89.64	0.125
34.05	89.77	0.125
34.08	89.90	0.125
34.10	90.02	0.125
34.13	90.14	0.125
34.15	90.27	0.126
34.18	90.40	0.126
34.20	90.52	0.126
34.23	90.65	0.126
34.25	90.77	0.126
34.28	90.90	0.126
34.30	91.02	0.126
34.33	91.15	0.127
34.35	91.27	0.127
34.38	91.40	0.127
34.40	91.52	0.127
34.43	91.65	0.127
34.45	91.77	0.127
34.48	91.90	0.127
34.50	92.02	0.128
34.53	92.15	0.128
34.55	92.27	0.128
34.58	92.40	0.128
34.60	92.52	0.128
34.63	92.64	0.129
34.65	92.77	0.129
34.68	92.90	0.129
34.70	93.02	0.129
34.73	93.15	0.129
34.75	93.27	0.129
34.78	93.40	0.129
34.80	93.52	0.130
34.83	93.65	0.130
34.85	93.77	0.130
34.88	93.90	0.130
34.90	94.02	0.130
34.93	94.15	0.130
34.95	94.27	0.131
34.98	94.40	0.131
35.00	94.52	0.131
35.03	94.65	0.131
35.05	94.77	0.131
35.08	94.90	0.131
35.10	95.02	0.132
35.13	95.15	0.132
35.15	95.27	0.132
35.18	95.40	0.132
35.20	95.52	0.132
35.23	95.65	0.132
35.25	95.77	0.133
35.28	95.90	0.133
35.30	96.02	0.133
35.33	96.15	0.133
35.35	96.27	0.133
35.38	96.40	0.133
35.40	96.52	0.133
35.43	96.65	0.134
35.45	96.77	0.134
35.48	96.90	0.134
35.50	97.02	0.134
35.53	97.15	0.134
35.55	97.27	0.134
35.58	97.40	0.135
35.60	97.52	0.135
35.63	97.65	0.135
35.65	97.77	0.135
35.68	97.90	0.135
35.70	98.02	0.135
35.73	98.15	0.135
35.75	98.27	0.136
35.78	98.40	0.136
35.80	98.52	0.136
35.83	98.65	0.136
35.85	98.77	0.136
35.88	98.90	0.136
35.90	99.02	0.137
35.93	99.15	0.137
35.95	99.27
35.98	99.40
35.98

[step]
Ramp 5.00 °C/min to -80.00 °C
Time	Temperature	Heat Flow (Normalized)
min	°C	W/g
36.99	100.12	-0.035
37.01	100.12	-0.035
37.04	100.11	-0.035
37.06	100.09	-0.016
37.09	100.05	0.002
37.11	99.99	0.001
37.14	99.92	-0.025
37.16	99.83	-0.059
37.19	99.74	-0.089
37.21	99.64	-0.112
37.24	99.53	-0.129
37.26	99.43	-0.144
37.29	99.32	-0.156
37.31	99.20	-0.164
37.34	99.09	-0.171
37.36	98.97	-0.176
37.39	98.85	-0.183
37.41	98.73	-0.187
37.44	98.61	-0.189
37.46	98.49	-0.193
37.49	98.37	-0.194
37.51	98.25	-0.195
37.54	98.13	-0.196
37.56	98.00	-0.197
37.59	97.88	-0.197
37.61	97.76	-0.198
37.64	97.64	-0.198
37.66	97.51	-0.199
37.69	97.39	-0.200
37.71	97.26	-0.200
37.74	97.14	-0.201
37.76	97.02	-0.201
37.79	96.89	-0.201
37.81	96.77	-0.201
37.84	96.64	-0.202
37.86	96.52	-0.202
37.89	96.40	-0.202
37.91	96.27	-0.202
37.94	96.15	-0.202
37.96	96.02	-0.203
37.99	95.90	-0.203
38.01	95.77	-0.203
38.04	95.65	-0.203
38.06	95.53	-0.203
38.09	95.40	-0.203
38.11	95.28	-0.202
38.14	95.15	-0.202
38.16	95.03	-0.202
38.19	94.90	-0.202
38.21	94.78	-0.202
38.24	94.65	-0.202
38.26	94.53	-0.202
38.29	94.40	-0.202
38.31	94.28	-0.202
38.34	94.15	-0.202
38.36	94.03	-0.202
38.39	93.91	-0.201
38.41	93.78	-0.201
38.44	93.65	-0.201
38.46	93.53	-0.201
38.49	93.41	-0.201
38.51	93.28	-0.201
38.54	93.16	-0.200
38.56	93.03	-0.200
38.59	92.91	-0.200
38.61	92.78	-0.200
38.64	92.66	-0.200
38.66	92.53	-0.200
38.69	92.41	-0.199
38.71	92.28	-0.199
38.74	92.16	-0.199
38.76	92.03	-0.199
38.79	91.91	-0.199
38.81	91.78	-0.198
38.84	91.66	-0.198
38.86	91.53	-0.198
38.89	91.41	-0.198
38.91	91.28	-0.198
38.94	91.16	-0.197
38.96	91.03	-0.197
38.99	90.91	-0.197
39.01	90.78	-0.197
39.04	90.66	-0.197
39.06	90.53	-0.196
39.09	90.41	-0.196
39.11	90.28	-0.196
39.14	90.16	-0.196
39.16	90.03	-0.196
39.19	89.91	-0.195
39.21	89.78	-0.195
39.24	89.66	-0.195
39.26	89.53	-0.195
39.29	89.41	-0.194
39.31	89.28	-0.194
39.34	89.16	-0.194
39.36	89.03	-0.194
39.39	88.91	-0.194
39.41	88.78	-0.193
39.44	88.66	-0.193
39.46	88.53	-0.193
39.49	88.41	-0.193
39.51	88.28	-0.193
39.54	88.16	-0.192
39.56	88.03	-0.192
39.59	87.91	-0.192
39.61	87.78	-0.192
39.64	87.66	-0.191
39.66	87.53	-0.191
39.69	87.41	-0.191
39.71	87.28	-0.191
39.74	87.16	-0.191
39.76	87.03	-0.190
39.79	86.91	-0.190
39.81	86.78	-0.190
39.84	86.66	-0.190
39.86	86.53	-0.190
39.89	86.41	-0.189
39.91	86.28	-0.189
39.94	86.16	-0.189
39.96	86.03	-0.189
39.99	85.91	-0.189
40.01	85.78	-0.188
40.04	85.66	-0.188
40.06	85.53	-0.188
40.09	85.41	-0.188
40.11	85.28	-0.188
40.14	85.16	-0.187
40.16	85.03	-0.187
40.19	84.91	-0.187
40.21	84.78	-0.187
40.24	84.66	-0.187
40.26	84.54	-0.187
40.29	84.41	-0.186
40.31	84.29	-0.186
40.34	84.16	-0.186
40.36	84.04	-0.186
40.39	83.91	-0.186
40.41	83.78	-0.185
40.44	83.66	-0.185
40.46	83.54	-0.185
40.49	83.41	-0.185
40.51	83.29	-0.185
40.54	83.16	-0.185
40.56	83.04	-0.185
40.59	82.91	-0.184
40.61	82.79	-0.184
40.64	82.66	-0.184
40.66	82.54	-0.184
40.69	82.41	-0.184
40.71	82.29	-0.184
40.74	82.16	-0.183
40.76	82.04	-0.183
40.79	81.91	-0.183
40.81	81.79	-0.183
40.84	81.66	-0.183
40.86	81.53	-0.183
40.89	81.41	-0.183
40.91	81.29	-0.183
40.94	81.16	-0.183
40.96	81.03	-0.182
40.99	80.91	-0.182
41.01	80.79	-0.182
41.04	80.66	-0.182
41.06	80.53	-0.181
41.09	80.41	-0.181
41.11	80.29	-0.181
41.14	80.16	-0.181
41.16	80.04	-0.181
41.19	79.91	-0.181
41.21	79.78	-0.181
41.24	79.66	-0.180
41.26	79.54	-0.180
41.29	79.41	-0.180
41.31	79.28	-0.180
41.34	79.16	-0.180
41.36	79.03	-0.180
41.39	78.91	-0.179
41.41	78.78	-0.179
41.44	78.66	-0.179
41.46	78.54	-0.179
41.49	78.41	-0.179
41.51	78.28	-0.179
41.54	78.16	-0.179
41.56	78.03	-0.178
41.59	77.91	-0.178
41.61	77.79	-0.178
41.64	77.66	-0.177
41.66	77.53	-0.177
41.69	77.41	-0.177
41.71	77.28	-0.177
41.74	77.16	-0.177
41.76	77.03	-0.177
41.79	76.91	-0.177
41.81	76.78	-0.177
41.84	76.66	-0.177
41.86	76.53	-0.176
41.89	76.41	-0.176
41.91	76.28	-0.176
41.94	76.16	-0.176
41.96	76.04	-0.176
41.99	75.91	-0.176
42.01	75.79	-0.175
42.04	75.66	-0.175
42.06	75.53	-0.175
42.09	75.41	-0.175
42.11	75.29	-0.175
42.14	75.16	-0.175
42.16	75.04	-0.174
42.19	74.91	-0.174
42.21	74.79	-0.174
42.24	74.66	-0.174
42.26	74.54	-0.174
42.29	74.41	-0.173
42.31	74.29	-0.173
42.34	74.16	-0.173
42.36	74.04	-0.173
42.39	73.91	-0.173
42.41	73.79	-0.173
42.44	73.66	-0.173
42.46	73.54	-0.172
42.49	73.41	-0.172
42.51	73.29	-0.172
42.54	73.16	-0.172
42.56	73.04	-0.172
42.59	72.91	-0.172
42.61	72.79	-0.171
42.64	72.66	-0.171
42.66	72.54	-0.171
42.69	72.41	-0.171
42.71	72.29	-0.171
42.74	72.16	-0.171
42.76	72.04	-0.171
42.79	71.91	-0.170
42.81	71.79	-0.170
42.84	71.66	-0.170
42.86	71.54	-0.170
42.89	71.41	-0.170
42.91	71.29	-0.170
42.94	71.16	-0.170
42.96	71.04	-0.169
42.99	70.91	-0.169
43.01	70.79	-0.169
43.04	70.66	-0.169
43.06	70.54	-0.169
43.09	70.41	-0.169
43.11	70.29	-0.169
43.14	70.16	-0.168
43.16	70.04	-0.168
43.19	69.91	-0.168
43.21	69.79	-0.168
43.24	69.66	-0.168
43.26	69.54	-0.167
43.29	69.41	-0.167
43.31	69.29	-0.167
43.34	69.16	-0.167
43.36	69.04	-0.167
43.39	68.91	-0.167
43.41	68.79	-0.167
43.44	68.66	-0.166
43.46	68.54	-0.166
43.49	68.41	-0.166
43.51	68.29	-0.166
43.54	68.16	-0.166
43.56	68.04	-0.166
43.59	67.91	-0.166
43.61	67.79	-0.166
43.64	67.66	-0.165
43.66	67.54	-0.165
43.69	67.41	-0.165
43.71	67.29	-0.165
43.74	67.16	-0.165
43.76	67.04	-0.165
43.79	66.91	-0.164
43.81	66.79	-0.164
43.84	66.66	-0.164
43.86	66.54	-0.164
43.89	66.41	-0.164
43.91	66.29	-0.164
43.94	66.16	-0.164
43.96	66.04	-0.164
43.99	65.91	-0.163
44.01	65.79	-0.163
44.04	65.66	-0.163
44.06	65.54	-0.163
44.09	65.41	-0.163
44.11	65.29	-0.163
44.14	65.16	-0.162
44.16	65.04	-0.162
44.19	64.91	-0.162
44.21	64.79	-0.162
44.24	64.66	-0.162
44.26	64.54	-0.162
44.29	64.41	-0.162
44.31	64.29	-0.161
44.34	64.16	-0.161
44.36	64.04	-0.161
44.39	63.91	-0.161
44.41	63.79	-0.161
44.44	63.66	-0.161
44.46	63.54	-0.161
44.49	63.41	-0.160
44.51	63.29	-0.160
44.54	63.16	-0.160
44.56	63.04	-0.160
44.59	62.91	-0.160
44.61	62.79	-0.160
44.64	62.66	-0.160
44.66	62.54	-0.160
44.69	62.41	-0.159
44.71	62.29	-0.159
44.74	62.16	-0.159
44.76	62.04	-0.159
44.79	61.91	-0.159
44.81	61.79	-0.159
44.84	61.66	-0.159
44.86	61.54	-0.158
44.89	61.41	-0.158
44.91	61.29	-0.158
44.94	61.16	-0.158
44.96	61.04	-0.158
44.99	60.91	-0.158
45.01	60.79	-0.157
45.04	60.66	-0.157
45.06	60.54	-0.157
45.09	60.41	-0.157
45.11	60.29	-0.157
45.14	60.16	-0.157
45.16	60.04	-0.157
45.19	59.91	-0.157
45.21	59.79	-0.156
45.24	59.66	-0.156
45.26	59.54	-0.156
45.29	59.41	-0.156
45.31	59.29	-0.156
45.34	59.17	-0.156
45.36	59.04	-0.155
45.39	58.91	-0.155
45.41	58.79	-0.155
45.44	58.66	-0.155
45.46	58.54	-0.155
45.49	58.41	-0.155
45.51	58.29	-0.155
45.54	58.17	-0.155
45.56	58.04	-0.154
45.59	57.92	-0.154
45.61	57.79	-0.154
45.64	57.66	-0.154
45.66	57.54	-0.154
45.69	57.41	-0.154
45.71	57.29	-0.154
45.74	57.16	-0.154
45.76	57.04	-0.154
45.79	56.91	-0.153
45.81	56.79	-0.153
45.84	56.66	-0.153
45.86	56.54	-0.153
45.89	56.41	-0.153
45.91	56.29	-0.153
45.94	56.16	-0.153
45.96	56.04	-0.153
45.99	55.91	-0.152
46.01	55.79	-0.152
46.04	55.67	-0.152
46.06	55.54	-0.152
46.09	55.41	-0.152
46.11	55.29	-0.152
46.14	55.16	-0.152
46.16	55.04	-0.152
46.19	54.91	-0.151
46.21	54.79	-0.151
46.24	54.66	-0.151
46.26	54.54	-0.151
46.29	54.41	-0.151
46.31	54.29	-0.151
46.34	54.16	-0.151
46.36	54.04	-0.150
46.39	53.91	-0.150
46.41	53.79	-0.150
46.44	53.67	-0.150
46.46	53.54	-0.150
46.49	53.41	-0.150
46.51	53.29	-0.150
46.54	53.17	-0.150
46.56	53.04	-0.149
46.59	52.92	-0.149
46.61	52.79	-0.149
46.64	52.67	-0.149
46.66	52.54	-0.149
46.69	52.42	-0.148
46.71	52.29	-0.148
46.74	52.17	-0.148
46.76	52.04	-0.148
46.79	51.92	-0.148
46.81	51.79	-0.148
46.84	51.66	-0.148
46.86	51.54	-0.148
46.89	51.42	-0.148
46.91	51.29	-0.148
46.94	51.17	-0.147
46.96	51.04	-0.147
46.99	50.92	-0.147
47.01	50.79	-0.147
47.04	50.67	-0.147
47.06	50.54	-0.147
47.09	50.42	-0.147
47.11	50.29	-0.146
47.14	50.17	-0.146
47.16	50.04	-0.146
47.19	49.92	-0.146
47.21	49.79	-0.146
47.24	49.67	-0.146
47.26	49.54	-0.146
47.29	49.42	-0.146
47.31	49.29	-0.145
47.34	49.17	-0.145
47.36	49.04	-0.145
47.39	48.92	-0.145
47.41	48.79	-0.145
47.44	48.67	-0.145
47.46	48.54	-0.145
47.49	48.42	-0.145
47.51	48.29	-0.145
47.54	48.17	-0.145
47.56	48.04	-0.144
47.59	47.92	-0.144
47.61	47.79	-0.144
47.64	47.67	-0.144
47.66	47.54	-0.144
47.69	47.42	-0.144
47.71	47.29	-0.144
47.74	47.17	-0.144
47.76	47.04	-0.143
47.79	46.92	-0.143
47.81	46.79	-0.143
47.84	46.67	-0.143
47.86	46.54	-0.143
47.89	46.42	-0.143
47.91	46.29	-0.143
47.94	46.17	-0.143
47.96	46.04	-0.142
47.99	45.92	-0.142
48.01	45.79	-0.142
48.04	45.67	-0.142
48.06	45.54	-0.142
48.09	45.42	-0.142
48.11	45.29	-0.142
48.14	45.17	-0.141
48.16	45.04	-0.141
48.19	44.92	-0.141
48.21	44.79	-0.141
[...]
82.94	-35.96	0.068
82.96	-35.84	0.068
82.99	-35.71	0.068
83.01	-35.59	0.068
83.04	-35.46	0.068
83.06	-35.34	0.068
83.09	-35.21	0.068
83.11	-35.09	0.068
83.14	-34.96	0.068
83.16	-34.83	0.068
83.19	-34.71	0.068
83.21	-34.58	0.068
83.24	-34.46	0.068
83.26	-34.33	0.068
83.29	-34.21	0.068
83.31	-34.08	0.068
83.34	-33.96	0.068
83.36	-33.83	0.068
83.39	-33.71	0.068
83.41	-33.58	0.068
83.44	-33.46	0.068
83.46	-33.33	0.068
83.49	-33.21	0.068
83.51	-33.08	0.068
83.54	-32.96	0.068
83.56	-32.83	0.068
83.59	-32.70	0.068
83.61	-32.58	0.068
83.64	-32.45	0.068
83.66	-32.33	0.068
83.69	-32.20	0.068
83.71	-32.08	0.068
83.74	-31.95	0.068
83.76	-31.83	0.068
83.79	-31.70	0.069
83.81	-31.58	0.069
83.84	-31.45	0.069
83.86	-31.33	0.069
83.89	-31.20	0.069
83.91	-31.08	0.069
83.94	-30.95	0.069
83.96	-30.83	0.069
83.99	-30.70	0.069
84.01	-30.58	0.069
84.04	-30.45	0.069
84.06	-30.32	0.069
84.09	-30.20	0.069
84.11	-30.08	0.069
84.14	-29.95	0.069
84.16	-29.83	0.069
84.19	-29.70	0.069
84.21	-29.58	0.069
84.24	-29.45	0.069
84.26	-29.33	0.069
84.29	-29.20	0.069
84.31	-29.08	0.069
84.34	-28.95	0.069
84.36	-28.82	0.069
84.39	-28.70	0.069
84.41	-28.57	0.069
84.44	-28.45	0.069
84.46	-28.32	0.069
84.49	-28.20	0.069
84.51	-28.07	0.069
84.54	-27.95	0.069
84.56	-27.82	0.069
84.59	-27.70	0.069
84.61	-27.57	0.069
84.64	-27.45	0.069
84.66	-27.32	0.069
84.69	-27.20	0.069
84.71	-27.07	0.069
84.74	-26.95	0.069
84.76	-26.82	0.069
84.79	-26.70	0.069
84.81	-26.57	0.069
84.84	-26.45	0.069
84.86	-26.32	0.069
84.89	-26.20	0.069
84.91	-26.07	0.069
84.94	-25.95	0.069
84.96	-25.82	0.069
84.99	-25.70	0.069
85.01	-25.57	0.069
85.04	-25.45	0.069
85.06	-25.32	0.069
85.09	-25.20	0.069
85.11	-25.07	0.069
85.14	-24.94	0.069
85.16	-24.82	0.069
85.19	-24.70	0.070
85.21	-24.57	0.070
85.24	-24.45	0.070
85.26	-24.32	0.070
85.29	-24.20	0.070
85.31	-24.07	0.070
85.34	-23.95	0.070
85.36	-23.82	0.070
85.39	-23.69	0.070
85.41	-23.57	0.070
85.44	-23.44	0.070
85.46	-23.32	0.070
85.49	-23.19	0.070
85.51	-23.07	0.070
85.54	-22.95	0.070
85.56	-22.82	0.070
85.59	-22.69	0.070
85.61	-22.57	0.070
85.64	-22.45	0.070
85.66	-22.32	0.070
85.69	-22.19	0.070
85.71	-22.07	0.070
85.74	-21.94	0.070
85.76	-21.82	0.070
85.79	-21.69	0.070
85.81	-21.57	0.070
85.84	-21.44	0.070
85.86	-21.32	0.070
85.89	-21.19	0.070
85.91	-21.07	0.070
85.94	-20.94	0.070
85.96	-20.82	0.070
85.99	-20.69	0.070
86.01	-20.57	0.070
86.04	-20.44	0.070
86.06	-20.32	0.070
86.09	-20.19	0.071
86.11	-20.07	0.070
86.14	-19.94	0.070
86.16	-19.82	0.070
86.19	-19.69	0.070
86.21	-19.57	0.070
86.24	-19.44	0.070
86.26	-19.32	0.070
86.29	-19.19	0.071
86.31	-19.07	0.070
86.34	-18.94	0.071
86.36	-18.82	0.071
86.39	-18.69	0.071
86.41	-18.56	0.071
86.44	-18.44	0.071
86.46	-18.32	0.071
86.49	-18.19	0.071
86.51	-18.07	0.071
86.54	-17.94	0.071
86.56	-17.81	0.071
86.59	-17.69	0.071
86.61	-17.56	0.071
86.64	-17.44	0.071
86.66	-17.31	0.071
86.69	-17.19	0.071
86.71	-17.06	0.071
86.74	-16.94	0.071
86.76	-16.81	0.071
86.79	-16.69	0.071
86.81	-16.56	0.071
86.84	-16.44	0.071
86.86	-16.31	0.071
86.89	-16.19	0.071
86.91	-16.06	0.071
86.94	-15.94	0.071
86.96	-15.81	0.071
86.99	-15.69	0.071
87.01	-15.56	0.071
87.04	-15.44	0.071
87.06	-15.31	0.071
87.09	-15.19	0.071
87.11	-15.06	0.071
87.14	-14.94	0.071
87.16	-14.81	0.071
87.19	-14.69	0.071
87.21	-14.56	0.071
87.24	-14.44	0.071
87.26	-14.31	0.071
87.29	-14.19	0.072
87.31	-14.06	0.072
87.34	-13.94	0.071
87.36	-13.81	0.072
87.39	-13.69	0.072
87.41	-13.56	0.072
87.44	-13.44	0.072
87.46	-13.31	0.072
87.49	-13.19	0.072
87.51	-13.06	0.072
87.54	-12.94	0.072
87.56	-12.81	0.072
87.59	-12.69	0.072
87.61	-12.56	0.072
87.64	-12.44	0.072
87.66	-12.31	0.072
87.69	-12.18	0.072
87.71	-12.06	0.072
87.74	-11.93	0.072
87.76	-11.81	0.072
87.79	-11.68	0.072
87.81	-11.56	0.072
87.84	-11.44	0.072
87.86	-11.31	0.072
87.89	-11.18	0.072
87.91	-11.06	0.072
87.94	-10.94	0.072
87.96	-10.81	0.072
87.99	-10.68	0.072
88.01	-10.56	0.072
88.04	-10.43	0.072
88.06	-10.31	0.072
88.09	-10.18	0.072
88.11	-10.06	0.072
88.14	-9.93	0.073
88.16	-9.81	0.072
88.19	-9.68	0.072
88.21	-9.56	0.072
88.24	-9.43	0.072
88.26	-9.31	0.072
88.29	-9.18	0.073
88.31	-9.06	0.073
88.34	-8.93	0.073
88.36	-8.81	0.072
88.39	-8.68	0.073
88.41	-8.56	0.073
88.44	-8.43	0.073
88.46	-8.31	0.073
88.49	-8.18	0.073
88.51	-8.06	0.073
88.54	-7.93	0.073
88.56	-7.81	0.073
88.59	-7.68	0.073
88.61	-7.56	0.073
88.64	-7.43	0.073
88.66	-7.31	0.073
88.69	-7.18	0.073
88.71	-7.06	0.073
88.74	-6.93	0.073
88.76	-6.81	0.073
88.79	-6.68	0.073
88.81	-6.56	0.073
88.84	-6.43	0.073
88.86	-6.31	0.073
88.89	-6.18	0.073
88.91	-6.06	0.073
88.94	-5.93	0.073
88.96	-5.81	0.073
88.99	-5.68	0.074
89.01	-5.55	0.074
89.04	-5.43	0.074
89.06	-5.30	0.074
89.09	-5.18	0.074
89.11	-5.05	0.074
89.14	-4.93	0.074
89.16	-4.80	0.074
89.19	-4.68	0.074
89.21	-4.55	0.074
89.24	-4.43	0.074
89.26	-4.31	0.074
89.29	-4.18	0.074
89.31	-4.05	0.074
89.34	-3.93	0.074
89.36	-3.80	0.074
89.39	-3.68	0.074
89.41	-3.55	0.074
89.44	-3.43	0.074
89.46	-3.30	0.074
89.49	-3.18	0.074
89.51	-3.05	0.074
89.54	-2.93	0.074
89.56	-2.80	0.074
89.59	-2.68	0.074
89.61	-2.55	0.074
89.64	-2.43	0.074
89.66	-2.30	0.074
89.69	-2.18	0.075
89.71	-2.05	0.075
89.74	-1.93	0.075
89.76	-1.80	0.075
89.79	-1.68	0.075
89.81	-1.55	0.075
89.84	-1.43	0.075
89.86	-1.30	0.075
89.89	-1.18	0.075
89.91	-1.05	0.075
89.94	-0.93	0.075
89.96	-0.80	0.075
89.99	-0.67	0.075
90.01	-0.55	0.075
90.04	-0.43	0.075
90.06	-0.30	0.075
90.09	-0.17	0.075
90.11	-0.05	0.075
90.14	0.08	0.075
90.16	0.20	0.075
90.19	0.33	0.075
90.21	0.45	0.075
90.24	0.58	0.075
90.26	0.70	0.075
90.29	0.83	0.075
90.31	0.95	0.076
90.34	1.08	0.076
90.36	1.20	0.076
90.39	1.33	0.076
90.41	1.45	0.076
90.44	1.58	0.076
90.46	1.70	0.076
90.49	1.83	0.076
90.51	1.95	0.076
90.54	2.08	0.076
90.56	2.20	0.076
90.59	2.33	0.076
90.61	2.45	0.076
90.64	2.58	0.076
90.66	2.70	0.076
90.69	2.83	0.076
90.71	2.95	0.076
90.74	3.08	0.076
90.76	3.20	0.076
90.79	3.33	0.076
90.81	3.45	0.076
90.84	3.58	0.076
90.86	3.70	0.076
90.89	3.83	0.077
90.91	3.95	0.077
90.94	4.08	0.077
90.96	4.20	0.077
90.99	4.33	0.077
91.01	4.45	0.077
91.04	4.58	0.077
91.06	4.70	0.077
91.09	4.83	0.077
91.11	4.96	0.077
91.14	5.08	0.077
91.16	5.20	0.077
91.19	5.33	0.077
91.21	5.45	0.077
91.24	5.58	0.077
91.26	5.71	0.077
91.29	5.83	0.077
91.31	5.96	0.077
91.34	6.08	0.077
91.36	6.21	0.077
91.39	6.33	0.077
91.41	6.46	0.077
91.44	6.58	0.077
91.46	6.71	0.077
91.49	6.83	0.077
91.51	6.96	0.078
91.54	7.08	0.078
91.56	7.21	0.078
91.59	7.33	0.078
91.61	7.46	0.078
91.64	7.58	0.078
91.66	7.71	0.078
91.69	7.83	0.078
91.71	7.96	0.078
91.74	8.08	0.078
91.76	8.21	0.078
91.79	8.33	0.078
91.81	8.46	0.078
91.84	8.58	0.078
91.86	8.71	0.078
91.89	8.83	0.078
91.91	8.96	0.078
91.94	9.08	0.078
91.96	9.21	0.078
91.99	9.33	0.078
92.01	9.46	0.079
92.04	9.58	0.079
92.06	9.71	0.079
92.09	9.83	0.079
92.11	9.96	0.079
92.14	10.08	0.079
92.16	10.21	0.079
92.19	10.33	0.079
92.21	10.46	0.079
92.24	10.58	0.079
92.26	10.71	0.079
92.29	10.83	0.079
92.31	10.96	0.079
92.34	11.09	0.079
92.36	11.21	0.079
92.39	11.34	0.079
92.41	11.46	0.079
92.44	11.59	0.079
92.46	11.71	0.079
92.49	11.84	0.079
92.51	11.96	0.079
92.54	12.09	0.079
92.56	12.21	0.079
92.59	12.34	0.079
92.61	12.46	0.079
92.64	12.59	0.080
92.66	12.71	0.080
92.69	12.84	0.080
92.71	12.96	0.080
92.74	13.09	0.080
92.76	13.21	0.080
92.79	13.34	0.080
92.81	13.46	0.080
92.84	13.59	0.080
92.86	13.71	0.080
92.89	13.84	0.080
92.91	13.96	0.080
92.94	14.09	0.080
92.96	14.21	0.080
92.99	14.34	0.080
93.01	14.46	0.080
93.04	14.59	0.080
93.06	14.71	0.080
93.09	14.84	0.080
93.11	14.96	0.080
93.14	15.09	0.081
93.16	15.21	0.081
93.19	15.34	0.081
93.21	15.46	0.081
93.24	15.59	0.081
93.26	15.71	0.081
93.29	15.84	0.081
93.31	15.96	0.081
93.34	16.09	0.081
93.36	16.21	0.081
93.39	16.34	0.081
93.41	16.46	0.081
93.44	16.59	0.081
93.46	16.71	0.081
93.49	16.84	0.081
93.51	16.96	0.081
93.54	17.09	0.081
93.56	17.21	0.082
93.59	17.34	0.082
93.61	17.46	0.082
93.64	17.59	0.082
93.66	17.71	0.082
93.69	17.84	0.082
93.71	17.96	0.082
93.74	18.09	0.082
93.76	18.21	0.082
93.79	18.34	0.082
93.81	18.47	0.082
93.84	18.59	0.082
93.86	18.72	0.082
93.89	18.84	0.082
93.91	18.97	0.082
93.94	19.09	0.082
93.96	19.22	0.082
93.99	19.34	0.082
94.01	19.47	0.082
94.04	19.59	0.082
94.06	19.72	0.082
94.09	19.84	0.083
94.11	19.97	0.083
94.14	20.09	0.083
94.16	20.22	0.083
94.19	20.34	0.083
94.21	20.47	0.083
94.24	20.59	0.083
94.26	20.72	0.083
94.29	20.84	0.083
94.31	20.97	0.083
94.34	21.09	0.083
94.36	21.22	0.083
94.39	21.34	0.083
94.41	21.47	0.083
94.44	21.59	0.083
94.46	21.72	0.084
94.49	21.84	0.084
94.51	21.97	0.084
94.54	22.09	0.084
94.56	22.22	0.084
94.59	22.34	0.084
94.61	22.47	0.084
94.64	22.59	0.084
94.66	22.72	0.084
94.69	22.84	0.084
94.71	22.97	0.084
94.74	23.09	0.084
94.76	23.22	0.084
94.79	23.34	0.084
94.81	23.47	0.084
94.84	23.59	0.084
94.86	23.72	0.084
94.89	23.84	0.085
94.91	23.97	0.085
94.94	24.09	0.085
94.96	24.22	0.085
94.99	24.34	0.085
95.01	24.47	0.085
95.04	24.59	0.085
95.06	24.72	0.085
95.09	24.84	0.085
95.11	24.97	0.085
95.14	25.09	0.085
95.16	25.22	0.085
95.19	25.34	0.085
95.21	25.47	0.085
95.24	25.59	0.085
95.26	25.72	0.085
95.29	25.84	0.085
95.31	25.97	0.085
95.34	26.10	0.085
95.36	26.22	0.086
95.39	26.34	0.086
95.41	26.47	0.086
95.44	26.60	0.086
95.46	26.72	0.086
95.49	26.85	0.086
95.51	26.97	0.086
95.54	27.10	0.086
95.56	27.22	0.086
95.59	27.35	0.086
95.61	27.47	0.086
95.64	27.60	0.086
95.66	27.72	0.086
95.69	27.85	0.086
95.71	27.97	0.086
95.74	28.10	0.087
95.76	28.22	0.087
95.79	28.35	0.087
95.81	28.47	0.087
95.84	28.60	0.087
95.86	28.72	0.087
95.89	28.85	0.087
95.91	28.97	0.087
95.94	29.10	0.087
95.96	29.22	0.087
95.99	29.35	0.087
96.01	29.47	0.087
96.04	29.60	0.087
96.06	29.72	0.087
96.09	29.85	0.087
96.11	29.97	0.087
96.14	30.10	0.088
96.16	30.22	0.088
96.19	30.35	0.088
96.21	30.47	0.088
96.24	30.60	0.088
96.26	30.72	0.088
96.29	30.85	0.088
96.31	30.97	0.088
96.34	31.10	0.088
96.36	31.22	0.088
96.39	31.35	0.088
96.41	31.47	0.088
96.44	31.60	0.088
96.46	31.72	0.088
96.49	31.85	0.088
96.51	31.97	0.088
96.54	32.10	0.089
96.56	32.22	0.089
96.59	32.35	0.089
96.61	32.47	0.089
96.64	32.60	0.089
96.66	32.72	0.089
96.69	32.85	0.089
96.71	32.97	0.089
96.74	33.10	0.089
96.76	33.22	0.089
96.79	33.35	0.089
96.81	33.47	0.089
96.84	33.60	0.089
96.86	33.73	0.089
96.89	33.85	0.090
96.91	33.98	0.090
96.94	34.10	0.090
96.96	34.23	0.090
96.99	34.35	0.090
97.01	34.48	0.090
97.04	34.60	0.090
97.06	34.73	0.090
97.09	34.85	0.090
97.11	34.98	0.090
97.14	35.10	0.090
97.16	35.23	0.090
97.19	35.35	0.090
97.21	35.48	0.090
97.24	35.60	0.090
97.26	35.73	0.090
97.29	35.85	0.090
97.31	35.98	0.090
97.34	36.10	0.090
97.36	36.23	0.090
97.39	36.35	0.090
97.41	36.48	0.091
97.44	36.60	0.091
97.46	36.73	0.091
97.49	36.85	0.091
97.51	36.98	0.091
97.54	37.10	0.091
97.56	37.23	0.091
97.59	37.35	0.091
97.61	37.48	0.091
97.64	37.60	0.091
97.66	37.73	0.091
97.69	37.85	0.091
97.71	37.98	0.091
97.74	38.10	0.091
97.76	38.23	0.092
97.79	38.35	0.092
97.81	38.48	0.092
97.84	38.60	0.092
97.86	38.73	0.092
97.89	38.85	0.092
97.91	38.98	0.092
97.94	39.10	0.092
97.96	39.23	0.092
97.99	39.35	0.092
98.01	39.48	0.092
98.04	39.60	0.092
98.06	39.73	0.092
98.09	39.85	0.092
98.11	39.98	0.093
98.14	40.11	0.093
98.16	40.23	0.093
98.19	40.36	0.093
98.21	40.48	0.093
98.24	40.61	0.093
98.26	40.73	0.093
98.29	40.86	0.093
98.31	40.98	0.093
98.34	41.11	0.093
98.36	41.23	0.093
98.39	41.36	0.093
98.41	41.48	0.093
98.44	41.61	0.093
98.46	41.73	0.093
98.49	41.86	0.094
98.51	41.98	0.094
98.54	42.11	0.094
98.56	42.23	0.094
98.59	42.36	0.094
98.61	42.48	0.094
98.64	42.61	0.094
98.66	42.73	0.094
98.69	42.86	0.094
98.71	42.98	0.094
98.74	43.11	0.094
98.76	43.23	0.094
98.79	43.36	0.094
98.81	43.48	0.094
98.84	43.61	0.095
98.86	43.73	0.095
98.89	43.86	0.095
98.91	43.98	0.095
98.94	44.11	0.095
98.96	44.23	0.095
98.99	44.36	0.095
99.01	44.48	0.095
99.04	44.61	0.095
99.06	44.73	0.095
99.09	44.86	0.095
99.11	44.98	0.095
99.14	45.11	0.095
99.16	45.23	0.096
99.19	45.36	0.096
99.21	45.48	0.096
99.24	45.61	0.096
99.26	45.73	0.096
99.29	45.86	0.096
99.31	45.98	0.096
99.34	46.11	0.096
99.36	46.23	0.096
99.39	46.36	0.096
99.41	46.48	0.096
99.44	46.61	0.096
99.46	46.73	0.096
99.49	46.86	0.097
99.51	46.98	0.097
99.54	47.11	0.097
99.56	47.23	0.097
99.59	47.36	0.097
99.61	47.48	0.097
99.64	47.61	0.097
99.66	47.73	0.097
99.69	47.86	0.097
99.71	47.99	0.097
99.74	48.11	0.097
99.76	48.23	0.098
99.79	48.36	0.098
99.81	48.48	0.098
99.84	48.61	0.098
99.86	48.73	0.098
99.89	48.86	0.098
99.91	48.98	0.098
99.94	49.11	0.098
99.96	49.23	0.098
99.99	49.36	0.098
100.01	49.48	0.098
100.04	49.61	0.098
100.06	49.73	0.098
100.09	49.86	0.098
100.11	49.98	0.098
100.14	50.11	0.099
100.16	50.24	0.099
100.19	50.36	0.099
100.21	50.48	0.099
100.24	50.61	0.099
100.26	50.74	0.099
100.29	50.86	0.099
100.31	50.99	0.099
100.34	51.11	0.099
100.36	51.24	0.099
100.39	51.36	0.099
100.41	51.49	0.099
100.44	51.61	0.100
100.46	51.74	0.100
100.49	51.86	0.100
100.51	51.99	0.100
100.54	52.11	0.100
100.56	52.24	0.100
100.59	52.36	0.100
100.61	52.49	0.100
100.64	52.61	0.100
100.66	52.74	0.100
100.69	52.86	0.100
100.71	52.99	0.100
100.74	53.11	0.100
100.76	53.24	0.100
100.79	53.36	0.100
100.81	53.49	0.101
100.84	53.61	0.101
100.86	53.74	0.101
100.89	53.86	0.101
100.91	53.99	0.101
100.94	54.11	0.101
100.96	54.24	0.101
100.99	54.36	0.101
101.01	54.49	0.101
101.04	54.61	0.101
101.06	54.74	0.101
101.09	54.86	0.102
101.11	54.99	0.102
101.14	55.11	0.102
101.16	55.24	0.102
101.19	55.36	0.102
101.21	55.49	0.102
101.24	55.61	0.102
101.26	55.74	0.102
101.29	55.86	0.102
101.31	55.99	0.102
101.34	56.11	0.102
101.36	56.24	0.102
101.39	56.36	0.103
101.41	56.49	0.103
101.44	56.61	0.103
101.46	56.74	0.103
101.49	56.86	0.103
101.51	56.99	0.103
101.54	57.11	0.103
101.56	57.24	0.103
101.59	57.36	0.103
101.61	57.49	0.103
101.64	57.61	0.103
101.66	57.74	0.104
101.69	57.86	0.104
101.71	57.99	0.104
101.74	58.11	0.104
101.76	58.24	0.104
101.79	58.37	0.104
101.81	58.49	0.104
101.84	58.61	0.104
101.86	58.74	0.104
101.89	58.86	0.104
101.91	58.99	0.104
101.94	59.12	0.105
101.96	59.24	0.105
101.99	59.36	0.105
102.01	59.49	0.105
102.04	59.62	0.105
102.06	59.74	0.105
102.09	59.87	0.105
102.11	59.99	0.105
102.14	60.12	0.105
102.16	60.24	0.105
102.19	60.37	0.105
102.21	60.49	0.105
102.24	60.62	0.106
102.26	60.74	0.106
102.29	60.87	0.106
102.31	60.99	0.106
102.34	61.12	0.106
102.36	61.24	0.106
102.39	61.37	0.106
102.41	61.49	0.106
102.44	61.62	0.106
102.46	61.74	0.106
102.49	61.87	0.106
102.51	61.99	0.107
102.54	62.12	0.107
102.56	62.24	0.107
102.59	62.37	0.107
102.61	62.49	0.107
102.64	62.62	0.107
102.66	62.74	0.107
102.69	62.87	0.107
102.71	62.99	0.107
102.74	63.12	0.107
102.76	63.24	0.107
102.79	63.37	0.108
102.81	63.49	0.108
102.84	63.62	0.108
102.86	63.74	0.108
102.89	63.87	0.108
102.91	63.99	0.108
102.94	64.12	0.108
102.96	64.24	0.108
102.99	64.37	0.108
103.01	64.49	0.108
103.04	64.62	0.109
103.06	64.74	0.109
103.09	64.87	0.109
103.11	64.99	0.109
103.14	65.12	0.109
103.16	65.24	0.109
103.19	65.37	0.109
103.21	65.49	0.109
103.24	65.62	0.109
103.26	65.74	0.109
103.29	65.87	0.109
103.31	65.99	0.110
103.34	66.12	0.110
103.36	66.24	0.110
103.39	66.37	0.110
103.41	66.49	0.110
103.44	66.62	0.110
103.46	66.74	0.110
103.49	66.87	0.110
103.51	66.99	0.110
103.54	67.12	0.110
103.56	67.24	0.111
103.59	67.37	0.111
103.61	67.49	0.111
103.64	67.62	0.111
103.66	67.74	0.111
103.69	67.87	0.111
103.71	67.99	0.111
103.74	68.12	0.111
103.76	68.24	0.111
103.79	68.37	0.111
103.81	68.49	0.112
103.84	68.62	0.112
103.86	68.74	0.112
103.89	68.87	0.112
103.91	68.99	0.112
103.94	69.12	0.112
103.96	69.25	0.112
103.99	69.37	0.112
104.01	69.49	0.112
104.04	69.62	0.112
104.06	69.74	0.113
104.09	69.87	0.113
104.11	70.00	0.113
104.14	70.12	0.113
104.16	70.24	0.113
104.19	70.37	0.113
104.21	70.49	0.113
104.24	70.62	0.113
104.26	70.75	0.113
104.29	70.87	0.113
104.31	71.00	0.114
104.34	71.12	0.114
104.36	71.24	0.114
104.39	71.37	0.114
104.41	71.49	0.114
104.44	71.62	0.114
104.46	71.75	0.114
104.49	71.87	0.114
104.51	72.00	0.115
104.54	72.12	0.115
104.56	72.25	0.115
104.59	72.37	0.115
104.61	72.50	0.115
104.64	72.62	0.115
104.66	72.75	0.115
104.69	72.87	0.115
104.71	72.99	0.115
104.74	73.12	0.116
104.76	73.25	0.116
104.79	73.37	0.116
104.81	73.50	0.116
104.84	73.62	0.116
104.86	73.75	0.116
104.89	73.87	0.116
104.91	74.00	0.116
104.94	74.12	0.117
104.96	74.25	0.117
104.99	74.37	0.117
105.01	74.50	0.117
105.04	74.62	0.117
105.06	74.75	0.117
105.09	74.87	0.117
105.11	75.00	0.117
105.14	75.12	0.117
105.16	75.25	0.117
105.19	75.37	0.118
105.21	75.50	0.118
105.24	75.62	0.118
105.26	75.75	0.118
105.29	75.87	0.118
105.31	76.00	0.118
105.34	76.12	0.118
105.36	76.25	0.118
105.39	76.37	0.118
105.41	76.50	0.119
105.44	76.62	0.119
105.46	76.75	0.119
105.49	76.87	0.119
105.51	77.00	0.119
105.54	77.12	0.119
105.56	77.25	0.119
105.59	77.37	0.119
105.61	77.50	0.119
105.64	77.62	0.120
105.66	77.75	0.120
105.69	77.87	0.120
105.71	78.00	0.120
105.74	78.12	0.120
105.76	78.25	0.120
105.79	78.37	0.120
105.81	78.50	0.120
105.84	78.62	0.120
105.86	78.75	0.121
105.89	78.87	0.121
105.91	79.00	0.121
105.94	79.12	0.121
105.96	79.25	0.121
105.99	79.37	0.121
106.01	79.50	0.121
106.04	79.62	0.121
106.06	79.75	0.121
106.09	79.87	0.122
106.11	80.00	0.122
106.14	80.12	0.122
106.16	80.25	0.122
106.19	80.37	0.122
106.21	80.50	0.122
106.24	80.62	0.122
106.26	80.75	0.122
106.29	80.87	0.123
106.31	81.00	0.123
106.34	81.12	0.123
106.36	81.25	0.123
106.39	81.37	0.123
106.41	81.50	0.123
106.44	81.63	0.123
106.46	81.75	0.123
106.49	81.88	0.123
106.51	82.00	0.124
106.54	82.13	0.124
106.56	82.25	0.124
106.59	82.37	0.124
106.61	82.50	0.124
106.64	82.62	0.124
106.66	82.75	0.124
106.69	82.88	0.124
106.71	83.00	0.124
106.74	83.13	0.125
106.76	83.25	0.125
106.79	83.37	0.125
106.81	83.50	0.125
106.84	83.62	0.125
106.86	83.75	0.125
106.89	83.88	0.125
106.91	84.00	0.125
106.94	84.13	0.125
106.96	84.25	0.126
106.99	84.38	0.126
107.01	84.50	0.126
107.04	84.63	0.126
107.06	84.75	0.126
107.09	84.88	0.126
107.11	85.00	0.126
107.14	85.13	0.126
107.16	85.25	0.127
107.19	85.38	0.127
107.21	85.50	0.127
107.24	85.63	0.127
107.26	85.75	0.127
107.29	85.88	0.127
107.31	86.00	0.127
107.34	86.13	0.127
107.36	86.25	0.128
107.39	86.38	0.128
107.41	86.50	0.128
107.44	86.63	0.128
107.46	86.75	0.128
107.49	86.88	0.128
107.51	87.00	0.128
107.54	87.13	0.128
107.56	87.25	0.129
107.59	87.38	0.129
107.61	87.50	0.129
107.64	87.63	0.129
107.66	87.75	0.129
107.69	87.88	0.129
107.71	88.00	0.129
107.74	88.13	0.129
107.76	88.25	0.129
107.79	88.38	0.130
107.81	88.50	0.130
107.84	88.63	0.130
107.86	88.75	0.130
107.89	88.88	0.130
107.91	89.00	0.130
107.94	89.13	0.130
107.96	89.25	0.131
107.99	89.38	0.131
108.01	89.50	0.131
108.04	89.63	0.131
108.06	89.75	0.131
108.09	89.88	0.131
108.11	90.00	0.132
108.14	90.13	0.132
108.16	90.25	0.132
108.19	90.38	0.132
108.21	90.50	0.132
108.24	90.63	0.132
108.26	90.75	0.132
108.29	90.88	0.133
108.31	91.00	0.133
108.34	91.13	0.133
108.36	91.25	0.133
108.39	91.38	0.133
108.41	91.50	0.133
108.44	91.63	0.133
108.46	91.75	0.134
108.49	91.88	0.134
108.51	92.00	0.134
108.54	92.13	0.134
108.56	92.25	0.134
108.59	92.38	0.134
108.61	92.50	0.135
108.64	92.63	0.135
108.66	92.75	0.135
108.69	92.88	0.135
108.71	93.00	0.135
108.74	93.13	0.135
108.76	93.25	0.136
108.79	93.38	0.136
108.81	93.50	0.136
108.84	93.63	0.136
108.86	93.75	0.136
108.89	93.88	0.136
108.91	94.00	0.136
108.94	94.13	0.137
108.96	94.25	0.137
108.99	94.38	0.137
109.01	94.50	0.137
109.04	94.63	0.137
109.06	94.76	0.137
109.09	94.88	0.138
109.11	95.01	0.138
109.14	95.13	0.138
109.16	95.26	0.138
109.19	95.38	0.138
109.21	95.51	0.138
109.24	95.63	0.139
109.26	95.76	0.139
109.29	95.88	0.139
109.31	96.01	0.139
109.34	96.13	0.139
109.36	96.26	0.139
109.39	96.38	0.140
109.41	96.51	0.140
109.44	96.63	0.140
109.46	96.76	0.140
109.49	96.88	0.140
109.51	97.01	0.140
109.54	97.13	0.141
109.56	97.26	0.141
109.59	97.38	0.141
109.61	97.51	0.141
109.64	97.63	0.141
109.66	97.76	0.141
109.69	97.88	0.141
109.71	98.01	0.141
109.74	98.13	0.142
109.76	98.26	0.142
109.79	98.38	0.142
109.81	98.50	0.142
109.84	98.63	0.142
109.86	98.75	0.142
109.89	98.88	0.143
109.91	99.01	0.143
109.94	99.13
109.96	99.25
109.99