File: DSC/2023_06_15_CBD_Fragility_SBK.txt
Filename	2023_06_15_CBD_Fragiity_SBK
Instrument name	DSC2A-00468 (192.168.1.100)
Operator	SBK
rundate	6/15/2023
Sample name	2023_06_15_CBD_Fragiity_SBK
proceduresegments	Data Off ; Equilibrate -50.00 °C; Data On ; Ramp 10.00 °C/min to 80.00 °C; Data Off ; Isothermal 1.0 min; Data On ; Ramp 10.00 °C/min to -50.00 °C; Data Off ; Isothermal 1.0 min; Data On ; Ramp 10.00 °C/min to 80.00 °C; Data Off ; Isothermal 1.0 min; Data On ; Ramp 30.00 °C/min to -50.00 °C; Data Off ; Isothermal 1.0 min; Data On ; Ramp 10.00 °C/min to 80.00 °C; Data Off ; Isothermal 1.0 min; Data On ; Ramp 25.00 °C/min to -50.00 °C; Data Off ; Isothermal 1.0 min; Data On ; Ramp 10.00 °C/min to 80.00 °C; Data Off ; Isothermal 1.0 min; Data On ; Ramp 20.00 °C/min to -50.00 °C; Data Off ; Isothermal 1.0 min; Data On ; Ramp 10.00 °C/min to 80.00 °C; Data Off ; Isothermal 1.0 min; Data On ; Ramp 5.00 °C/min to -50.00 °C; Data Off ; Isothermal 1.0 min; Data On ; Ramp 10.00 °C/min to 80.00 °C
[File Parameters]
Run date	6/15/2023 11:16:27 AM
Trios version	5.1.1.46572
Original File Name	C:\Users\yargerlab\Desktop\DSC Data\General\2023_06_15_CBD_Fragiity_SBK.tri
Current File Name	C:\Users\yargerlab\Desktop\DSC Data\General\2023_06_15_CBD_Fragiity_SBK.tri
[Procedure]
Procedure Name	DSC -50C to 80C Varied cooling rates OTP fragility
Sample Name	2023_06_15_CBD_Fragiity_SBK
Sample Mass	2.1 mg
Reference Sample Mass	0 mg
Pan Mass	51.88 mg
Pan Number	20
Reference Pan Mass	51.62 mg
Reference Pan Number	2
Pan Type	Tzero Aluminum Hermetic
Comments	CBD powder, sample last run on 5/24/23. First run of fragility testing. Tzero aluminum pan and hermetic lid.
Project Name	Silk ASDs
Operator	SBK
Test	Custom
Unload Max Temperature	30
Unload Min Temperature	30
Load Max Temperature	30
Load Min Temperature	30
Stop on Gas Flow Error	Yes
[Signal List]
Signal #1	Time (min)
Signal #2	Temperature (°C)
Signal #3	Heat Flow (mW)
Signal #4	Delta T (µV)
Signal #5	Delta Tzero (µV)
Signal #6	Tzero Temperature (°C)
Signal #7	Cell Purge (mL/min)
Signal #8	Heater Temp (°C)
Signal #9	Power Delivered (W)
Signal #10	Reference Junction Temperature (°C)
Signal #11	Flange Temperature (°C)
Signal #12	Heat Flow Phase (rad)
Signal #13	Total Heat Capacity (J/°C)
Signal #14	Heat Capacity (J/°C)
[Configuration]
Company Name	ASU
Instrument Name	DSC2A-00468
Instrument Type	DSC2500
Serial Number	DSC2A-00468
IP	192.168.1.100
Location of Instrument	MRRC
DisplayType	Unknown
Sample Interval 	0.1 s/pt
Selected Heat Flow	T4P
Exotherm Direction	Down
Cell Serial	DRC2-00792
Lid Type	Standard
Cooler	RCS 90
Leave Cooler on at End of Sequence	On
Gas 2	Nitrogen
Gas Selected	Channel 1
Flow Rate	50 mL/min
Secondary Purge	On
Licensed Heat Flow	Heat Flow T4P
Modulation Licensed	Yes
[Versions]
Common IDD Version	1
Cortex Version	VER 2.10.2.31
Driver	5.0.0.6
GDM Version	1.0.3.3
TouchscreenVersion	1.0.0.16145
FEP Version	1.2.1.21
FEP Bootloader	2.0.0.5
AutoSampler Version	2.1.1.26
Auto Sampler Bootloader	2.0.0.5
FCM Version	1.1.0.3
FCM Bootloader	2.0.0.5
[Experiment Logs]
Experiment Log Entry # 1	Data On set to 0
Experiment Log Entry # 3	Equilibrate Segment -50 (C) Started
Experiment Log Entry # 5	Air Cool is off.
Experiment Log Entry # 7	Data On set to 1
Experiment Log Entry # 9	Ramp Segment 10 C/min to 80 Started
Experiment Log Entry # 11	Data On set to 0
Experiment Log Entry # 13	Isothermal Segment 1 min started
Experiment Log Entry # 15	Data On set to 1
Experiment Log Entry # 17	Ramp Segment 10 C/min to -50 Started
Experiment Log Entry # 19	Data On set to 0
Experiment Log Entry # 21	Isothermal Segment 1 min started
Experiment Log Entry # 23	Data On set to 1
Experiment Log Entry # 25	Ramp Segment 10 C/min to 80 Started
Experiment Log Entry # 27	Data On set to 0
Experiment Log Entry # 29	Isothermal Segment 1 min started
Experiment Log Entry # 31	Data On set to 1
Experiment Log Entry # 33	Ramp Segment 30 C/min to -50 Started
Experiment Log Entry # 35	Data On set to 0
Experiment Log Entry # 37	Isothermal Segment 1 min started
Experiment Log Entry # 39	Data On set to 1
Experiment Log Entry # 41	Ramp Segment 10 C/min to 80 Started
Experiment Log Entry # 43	Data On set to 0
Experiment Log Entry # 45	Isothermal Segment 1 min started
Experiment Log Entry # 47	Data On set to 1
Experiment Log Entry # 49	Ramp Segment 25 C/min to -50 Started
Experiment Log Entry # 51	Data On set to 0
Experiment Log Entry # 53	Isothermal Segment 1 min started
Experiment Log Entry # 55	Data On set to 1
Experiment Log Entry # 57	Ramp Segment 10 C/min to 80 Started
Experiment Log Entry # 59	Data On set to 0
Experiment Log Entry # 61	Isothermal Segment 1 min started
Experiment Log Entry # 63	Data On set to 1
Experiment Log Entry # 65	Ramp Segment 20 C/min to -50 Started
Experiment Log Entry # 67	Data On set to 0
Experiment Log Entry # 69	Isothermal Segment 1 min started
Experiment Log Entry # 71	Data On set to 1
Experiment Log Entry # 73	Ramp Segment 10 C/min to 80 Started
Experiment Log Entry # 75	Data On set to 0
Experiment Log Entry # 77	Isothermal Segment 1 min started
Experiment Log Entry # 79	Data On set to 1
Experiment Log Entry # 81	Ramp Segment 5 C/min to -50 Started
Experiment Log Entry # 83	Data On set to 0
Experiment Log Entry # 85	Isothermal Segment 1 min started
Experiment Log Entry # 87	Data On set to 1
Experiment Log Entry # 89	Ramp Segment 10 C/min to 80 Started
[Method Log]
Method Log Entry # 1	Data Off
Method Log Entry # 2	Equilibrate -50 °C
Method Log Entry # 3	Data On
Method Log Entry # 4	(Ramp 137480) Ramp 10 °C/minute to 80 °C
Method Log Entry # 5	Data Off
Method Log Entry # 6	Isothermal 1 minutes
Method Log Entry # 7	Data On
Method Log Entry # 8	(Ramp 137484) Ramp 10 °C/minute to -50 °C
Method Log Entry # 9	Data Off
Method Log Entry # 10	Isothermal 1 minutes
Method Log Entry # 11	Data On
Method Log Entry # 12	(Ramp 137488) Ramp 10 °C/minute to 80 °C
Method Log Entry # 13	Data Off
Method Log Entry # 14	Isothermal 1 minutes
Method Log Entry # 15	Data On
Method Log Entry # 16	(Ramp 137492) Ramp 30 °C/minute to -50 °C
Method Log Entry # 17	Data Off
Method Log Entry # 18	Isothermal 1 minutes
Method Log Entry # 19	Data On
Method Log Entry # 20	(Ramp 137496) Ramp 10 °C/minute to 80 °C
Method Log Entry # 21	Data Off
Method Log Entry # 22	Isothermal 1 minutes
Method Log Entry # 23	Data On
Method Log Entry # 24	(Ramp 137500) Ramp 25 °C/minute to -50 °C
Method Log Entry # 25	Data Off
Method Log Entry # 26	Isothermal 1 minutes
Method Log Entry # 27	Data On
Method Log Entry # 28	(Ramp 137504) Ramp 10 °C/minute to 80 °C
Method Log Entry # 29	Data Off
Method Log Entry # 30	Isothermal 1 minutes
Method Log Entry # 31	Data On
Method Log Entry # 32	(Ramp 137508) Ramp 20 °C/minute to -50 °C
Method Log Entry # 33	Data Off
Method Log Entry # 34	Isothermal 1 minutes
Method Log Entry # 35	Data On
Method Log Entry # 36	(Ramp 137512) Ramp 10 °C/minute to 80 °C
Method Log Entry # 37	Data Off
Method Log Entry # 38	Isothermal 1 minutes
Method Log Entry # 39	Data On
Method Log Entry # 40	(Ramp 137516) Ramp 5 °C/minute to -50 °C
Method Log Entry # 41	Data Off
Method Log Entry # 42	Isothermal 1 minutes
Method Log Entry # 43	Data On
Method Log Entry # 44	(Ramp 137520) Ramp 10 °C/minute to 80 °C
Cell Serial	DRC2-00792
[T1 Calibration]
Slope	-0.008529666
Offset	9.636258
Initial Temperature	98.23
GUID	f8bfdadc-4977-4fdf-ba6d-0ba9134940c3
[TZero Calibration]
Date Applied	11/29/2022 4:06:13 PM
Description	From -89.059 °C to 396.009 °C at 20.000°C/min
Gas Type	Nitrogen
Pan Type	None
Source Files 1	C:\Users\yargerlab\Desktop\DSC Data\General\TZero_calibration_11_29_22_2nd(2).tri
Source Files 2	C:\Users\yargerlab\Desktop\DSC Data\General\TZero_calibration_11_29_22_2nd(3).tri
Delta T Offset	13.05235
Delta T Slope	-0.007271007
Delta T0 Offset	-13.69128
Delta T0 Slope	0.06063341
[Temperature Calibration]
Date Applied	11/29/2022 7:12:28 PM
Description	From 106.590 °C to 186.590 °C at 10.000°C/min
Gas Type	Nitrogen
Pan Type	Tzero Aluminum Hermetic
Source Files 1	C:\Users\yargerlab\Desktop\DSC Data\General\Indium(6).tri
Measured 1	157.391
Known 1	156.598
[Cell Constant Calibration]
Date Applied	11/29/2022 7:12:29 PM
Description	From 106.590 °C to 186.590 °C at 10.000°C/min
Gas Type	Nitrogen
Pan Type	Tzero Aluminum Hermetic
Source Files 1	C:\Users\yargerlab\Desktop\DSC Data\General\Indium(6).tri
T4P KCell	1.006051
Onset Slope	63.26126 mW/°C
[Direct Cp Calibration]
Date Applied	11/30/2022 11:04:51 AM
Description	From -79.983 °C to 298.409 °C at 10.000°C/min
Gas Type	Nitrogen
Pan Type	Tzero Aluminum Hermetic
Source Files 1	C:\Users\yargerlab\Desktop\DSC Data\General\Sapphire_Heat_Capacity_11_30_22.tri
[Rev Cp Calibration]
Date Applied	11/30/2022 1:58:51 PM
Description	From -79.996 °C to 292.812 °C at 3.000°C/min
Gas Type	Nitrogen
Pan Type	Tzero Aluminum Hermetic
Source Files 1	C:\Users\yargerlab\Desktop\DSC Data\General\Sapphire_MDSC_Calibration_11_30_22.tri
[step]
Ramp 10.00 °C/min to 80.00 °C
Time	Temperature	Heat Flow (Normalized)
min	°C	W/g
0.00	-49.74	0.001
0.01	-49.75	0.001
0.02	-49.75	0.002
0.03	-49.76	0.003
0.04	-49.76	0.005
0.05	-49.76	0.010
0.06	-49.75	0.014
0.07	-49.75	0.020
0.08	-49.73	0.028
0.09	-49.72	0.037
0.10	-49.69	0.048
0.11	-49.66	0.058
0.12	-49.63	0.069
0.13	-49.59	0.080
0.14	-49.54	0.088
0.15	-49.48	0.100
0.16	-49.42	0.112
0.17	-49.36	0.122
0.18	-49.30	0.128
0.19	-49.22	0.140
0.20	-49.15	0.148
0.21	-49.08	0.154
0.22	-49.00	0.163
0.23	-48.92	0.170
0.24	-48.83	0.175
0.25	-48.75	0.183
0.26	-48.66	0.183
0.27	-48.58	0.188
0.28	-48.49	0.191
0.29	-48.40	0.196
0.30	-48.31	0.201
0.31	-48.22	0.201
0.32	-48.13	0.203
0.33	-48.04	0.204
0.34	-47.95	0.206
0.35	-47.85	0.206
0.36	-47.76	0.207
0.37	-47.67	0.208
0.38	-47.58	0.209
0.39	-47.48	0.209
0.40	-47.39	0.210
0.41	-47.29	0.210
0.42	-47.20	0.211
0.43	-47.10	0.211
0.44	-47.00	0.211
0.45	-46.91	0.212
0.46	-46.81	0.212
0.47	-46.72	0.212
0.48	-46.62	0.213
0.49	-46.52	0.213
0.50	-46.43	0.213
0.51	-46.33	0.213
0.52	-46.23	0.214
0.53	-46.14	0.214
0.54	-46.04	0.214
0.55	-45.94	0.214
0.56	-45.85	0.214
0.57	-45.75	0.214
0.58	-45.65	0.214
0.59	-45.55	0.215
0.60	-45.45	0.215
0.61	-45.36	0.215
0.62	-45.26	0.215
0.63	-45.16	0.215
0.64	-45.06	0.215
0.65	-44.96	0.215
0.66	-44.87	0.215
0.67	-44.77	0.215
0.68	-44.67	0.215
0.69	-44.57	0.215
0.70	-44.47	0.215
0.71	-44.38	0.215
0.72	-44.28	0.214
0.73	-44.18	0.214
0.74	-44.08	0.214
0.75	-43.98	0.214
0.76	-43.88	0.214
0.77	-43.79	0.214
0.78	-43.69	0.214
0.79	-43.59	0.214
0.80	-43.49	0.214
0.81	-43.39	0.214
0.82	-43.29	0.213
0.83	-43.19	0.213
0.84	-43.10	0.213
0.85	-42.99	0.213
0.86	-42.90	0.213
0.87	-42.80	0.213
0.88	-42.70	0.213
0.89	-42.60	0.212
0.90	-42.50	0.212
0.91	-42.40	0.212
0.92	-42.30	0.212
0.93	-42.20	0.212
0.94	-42.11	0.211
0.95	-42.01	0.211
0.96	-41.91	0.211
0.97	-41.81	0.211
0.98	-41.71	0.211
0.99	-41.61	0.211
1.00	-41.51	0.210
1.01	-41.41	0.210
1.02	-41.31	0.210
1.03	-41.21	0.210
1.04	-41.11	0.210
1.05	-41.02	0.210
1.06	-40.92	0.209
1.07	-40.82	0.209
1.08	-40.72	0.209
1.09	-40.62	0.209
1.10	-40.52	0.209
1.11	-40.42	0.209
1.12	-40.32	0.208
1.13	-40.22	0.208
1.14	-40.12	0.208
1.15	-40.02	0.208
1.16	-39.92	0.208
1.17	-39.82	0.208
1.18	-39.72	0.208
1.19	-39.62	0.207
1.20	-39.52	0.207
1.21	-39.42	0.207
1.22	-39.32	0.207
1.23	-39.22	0.207
1.24	-39.12	0.206
1.25	-39.03	0.206
1.26	-38.92	0.206
1.27	-38.83	0.206
1.28	-38.73	0.206
1.29	-38.63	0.206
1.30	-38.53	0.206
1.31	-38.43	0.205
1.32	-38.33	0.205
1.33	-38.23	0.205
1.34	-38.13	0.205
1.35	-38.03	0.205
1.36	-37.93	0.205
1.37	-37.83	0.205
1.38	-37.73	0.205
1.39	-37.63	0.205
1.40	-37.53	0.204
1.41	-37.43	0.204
1.42	-37.33	0.204
1.43	-37.23	0.204
1.44	-37.13	0.204
1.45	-37.03	0.203
1.46	-36.93	0.203
1.47	-36.83	0.203
1.48	-36.73	0.203
1.49	-36.63	0.203
1.50	-36.53	0.203
1.51	-36.43	0.203
1.52	-36.33	0.203
1.53	-36.23	0.203
1.54	-36.13	0.203
1.55	-36.03	0.202
1.56	-35.93	0.202
1.57	-35.83	0.202
1.58	-35.73	0.202
1.59	-35.63	0.202
1.60	-35.53	0.202
1.61	-35.43	0.202
1.62	-35.33	0.202
1.63	-35.23	0.201
1.64	-35.13	0.201
1.65	-35.03	0.201
1.66	-34.93	0.201
1.67	-34.83	0.201
1.68	-34.73	0.201
1.69	-34.63	0.201
1.70	-34.53	0.201
1.71	-34.43	0.201
1.72	-34.33	0.201
1.73	-34.23	0.201
1.74	-34.13	0.201
1.75	-34.03	0.201
1.76	-33.93	0.201
1.77	-33.83	0.200
1.78	-33.73	0.200
1.79	-33.63	0.200
1.80	-33.53	0.200
1.81	-33.43	0.200
1.82	-33.33	0.200
1.83	-33.23	0.200
1.84	-33.13	0.200
1.85	-33.03	0.200
1.86	-32.93	0.200
1.87	-32.83	0.200
1.88	-32.73	0.200
1.89	-32.63	0.200
1.90	-32.53	0.200
1.91	-32.43	0.200
1.92	-32.33	0.200
1.93	-32.23	0.199
1.94	-32.13	0.199
1.95	-32.03	0.199
1.96	-31.93	0.199
1.97	-31.83	0.199
1.98	-31.73	0.199
1.99	-31.63	0.199
2.00	-31.53	0.199
2.01	-31.43	0.199
2.02	-31.33	0.199
2.03	-31.23	0.199
2.04	-31.13	0.199
2.05	-31.03	0.199
2.06	-30.93	0.199
2.07	-30.83	0.199
2.08	-30.73	0.199
2.09	-30.63	0.199
2.10	-30.53	0.199
2.11	-30.43	0.199
2.12	-30.33	0.198
2.13	-30.23	0.198
2.14	-30.13	0.198
2.15	-30.03	0.198
2.16	-29.93	0.198
2.17	-29.83	0.198
2.18	-29.73	0.198
2.19	-29.63	0.198
2.20	-29.53	0.198
2.21	-29.43	0.198
2.22	-29.33	0.198
2.23	-29.23	0.198
2.24	-29.13	0.198
2.25	-29.03	0.198
2.26	-28.93	0.198
2.27	-28.83	0.198
2.28	-28.73	0.198
2.29	-28.63	0.198
2.30	-28.53	0.198
2.31	-28.43	0.198
2.32	-28.33	0.198
2.33	-28.23	0.198
2.34	-28.13	0.198
2.35	-28.03	0.198
2.36	-27.93	0.198
2.37	-27.83	0.198
2.38	-27.73	0.198
2.39	-27.63	0.198
2.40	-27.53	0.198
2.41	-27.43	0.198
2.42	-27.33	0.198
2.43	-27.23	0.198
2.44	-27.13	0.198
2.45	-27.03	0.198
2.46	-26.93	0.198
2.47	-26.83	0.198
2.48	-26.73	0.198
2.49	-26.63	0.198
2.50	-26.53	0.198
2.51	-26.43	0.198
2.52	-26.33	0.198
2.53	-26.23	0.198
2.54	-26.13	0.198
2.55	-26.03	0.198
2.56	-25.93	0.198
2.57	-25.83	0.198
2.58	-25.73	0.198
2.59	-25.63	0.198
2.60	-25.53	0.198
2.61	-25.43	0.198
2.62	-25.33	0.198
2.63	-25.23	0.198
2.64	-25.13	0.198
2.65	-25.03	0.198
2.66	-24.93	0.198
2.67	-24.83	0.198
2.68	-24.73	0.198
2.69	-24.63	0.199
2.70	-24.53	0.199
2.71	-24.43	0.199
2.72	-24.33	0.199
2.73	-24.23	0.199
2.74	-24.13	0.199
2.75	-24.03	0.199
2.76	-23.92	0.199
2.77	-23.83	0.199
2.78	-23.72	0.199
2.79	-23.63	0.199
2.80	-23.53	0.199
2.81	-23.42	0.199
2.82	-23.33	0.199
2.83	-23.23	0.199
2.84	-23.12	0.199
2.85	-23.02	0.199
2.86	-22.92	0.199
2.87	-22.82	0.199
2.88	-22.73	0.199
2.89	-22.62	0.199
2.90	-22.52	0.200
2.91	-22.42	0.200
2.92	-22.32	0.200
2.93	-22.22	0.200
2.94	-22.12	0.200
2.95	-22.02	0.200
2.96	-21.92	0.200
2.97	-21.82	0.200
2.98	-21.72	0.200
2.99	-21.62	0.200
3.00	-21.52	0.201
3.01	-21.42	0.201
3.02	-21.32	0.201
3.03	-21.22	0.201
3.04	-21.12	0.201
3.05	-21.02	0.201
3.06	-20.92	0.201
3.07	-20.82	0.201
3.08	-20.72	0.201
3.09	-20.62	0.202
3.10	-20.52	0.202
3.11	-20.42	0.202
3.12	-20.32	0.202
3.13	-20.22	0.202
3.14	-20.12	0.202
3.15	-20.02	0.202
3.16	-19.92	0.203
3.17	-19.82	0.203
3.18	-19.72	0.203
3.19	-19.62	0.203
3.20	-19.52	0.203
3.21	-19.42	0.204
3.22	-19.32	0.204
3.23	-19.22	0.204
3.24	-19.12	0.204
3.25	-19.02	0.205
3.26	-18.92	0.205
3.27	-18.82	0.205
3.28	-18.72	0.205
3.29	-18.62	0.206
3.30	-18.52	0.206
3.31	-18.42	0.206
3.32	-18.32	0.206
3.33	-18.22	0.207
3.34	-18.12	0.207
3.35	-18.02	0.207
3.36	-17.92	0.207
3.37	-17.82	0.208
3.38	-17.72	0.209
3.39	-17.62	0.209
3.40	-17.52	0.209
3.41	-17.42	0.209
3.42	-17.32	0.210
3.43	-17.22	0.211
3.44	-17.12	0.211
3.45	-17.02	0.212
3.46	-16.92	0.212
3.47	-16.82	0.212
3.48	-16.72	0.213
3.49	-16.62	0.213
3.50	-16.52	0.213
3.51	-16.42	0.214
3.52	-16.32	0.214
3.53	-16.22	0.215
3.54	-16.12	0.215
3.55	-16.02	0.217
3.56	-15.92	0.218
3.57	-15.82	0.218
3.58	-15.72	0.220
3.59	-15.62	0.221
3.60	-15.52	0.221
3.61	-15.42	0.222
3.62	-15.32	0.223
3.63	-15.22	0.223
3.64	-15.12	0.224
3.65	-15.02	0.225
3.66	-14.92	0.225
3.67	-14.82	0.226
3.68	-14.72	0.227
3.69	-14.62	0.228
3.70	-14.52	0.229
3.71	-14.42	0.230
3.72	-14.32	0.231
3.73	-14.22	0.232
3.74	-14.12	0.233
3.75	-14.02	0.236
3.76	-13.92	0.237
3.77	-13.82	0.238
3.78	-13.72	0.239
3.79	-13.62	0.240
3.80	-13.52	0.242
3.81	-13.42	0.244
3.82	-13.32	0.245
3.83	-13.22	0.246
3.84	-13.12	0.247
3.85	-13.02	0.248
3.86	-12.92	0.249
3.87	-12.82	0.250
3.88	-12.72	0.252
3.89	-12.62	0.253
3.90	-12.52	0.254
3.91	-12.42	0.255
3.92	-12.32	0.256
3.93	-12.23	0.257
3.94	-12.12	0.258
3.95	-12.02	0.259
3.96	-11.92	0.259
3.97	-11.82	0.260
3.98	-11.72	0.261
3.99	-11.62	0.262
4.00	-11.52	0.262
4.01	-11.42	0.263
4.02	-11.32	0.263
4.03	-11.22	0.264
4.04	-11.12	0.264
4.05	-11.02	0.265
4.06	-10.92	0.265
4.07	-10.82	0.266
4.08	-10.72	0.266
4.09	-10.62	0.267
4.10	-10.52	0.267
4.11	-10.42	0.267
4.12	-10.32	0.267
4.13	-10.22	0.268
4.14	-10.12	0.268
4.15	-10.02	0.268
4.16	-9.92	0.268
4.17	-9.82	0.268
4.18	-9.72	0.267
4.19	-9.62	0.267
4.20	-9.52	0.267
4.21	-9.42	0.267
4.22	-9.32	0.267
4.23	-9.22	0.267
4.24	-9.12	0.267
4.25	-9.02	0.266
4.26	-8.92	0.266
4.27	-8.82	0.266
4.28	-8.72	0.265
4.29	-8.62	0.265
4.30	-8.52	0.265
4.31	-8.42	0.264
4.32	-8.32	0.264
4.33	-8.22	0.264
4.34	-8.12	0.264
4.35	-8.02	0.263
4.36	-7.92	0.263
4.37	-7.82	0.263
4.38	-7.72	0.262
4.39	-7.62	0.262
4.40	-7.52	0.262
4.41	-7.41	0.262
4.42	-7.32	0.261
4.43	-7.22	0.261
4.44	-7.12	0.261
4.45	-7.01	0.261
4.46	-6.92	0.260
4.47	-6.81	0.260
4.48	-6.72	0.260
4.49	-6.62	0.260
4.50	-6.52	0.260
4.51	-6.41	0.260
4.52	-6.31	0.259
4.53	-6.21	0.259
4.54	-6.11	0.259
4.55	-6.01	0.259
4.56	-5.91	0.258
4.57	-5.81	0.258
4.58	-5.71	0.258
4.59	-5.61	0.258
4.60	-5.51	0.258
4.61	-5.41	0.258
4.62	-5.31	0.257
4.63	-5.21	0.257
4.64	-5.11	0.257
4.65	-5.01	0.257
4.66	-4.91	0.257
4.67	-4.81	0.257
4.68	-4.71	0.257
4.69	-4.61	0.257
4.70	-4.51	0.257
4.71	-4.41	0.257
4.72	-4.31	0.257
4.73	-4.21	0.257
4.74	-4.11	0.257
4.75	-4.01	0.257
4.76	-3.91	0.257
4.77	-3.81	0.257
4.78	-3.71	0.257
4.79	-3.61	0.257
4.80	-3.51	0.256
4.81	-3.41	0.256
4.82	-3.31	0.256
4.83	-3.21	0.256
4.84	-3.11	0.256
4.85	-3.01	0.256
4.86	-2.91	0.256
4.87	-2.81	0.256
4.88	-2.71	0.256
4.89	-2.61	0.256
4.90	-2.51	0.256
4.91	-2.41	0.256
4.92	-2.31	0.256
4.93	-2.21	0.256
4.94	-2.11	0.256
4.95	-2.01	0.256
4.96	-1.91	0.256
4.97	-1.81	0.256
4.98	-1.71	0.256
4.99	-1.61	0.256
5.00	-1.51	0.256
5.01	-1.41	0.256
5.02	-1.31	0.256
5.03	-1.21	0.256
5.04	-1.11	0.256
5.05	-1.01	0.256
5.06	-0.91	0.256
5.07	-0.81	0.256
5.08	-0.71	0.256
5.09	-0.61	0.256
5.10	-0.51	0.256
5.11	-0.41	0.256
5.12	-0.31	0.256
5.13	-0.21	0.256
5.14	-0.11	0.256
5.15	-0.01	0.256
5.16	0.09	0.256
5.17	0.19	0.256
5.18	0.29	0.256
5.19	0.39	0.256
5.20	0.49	0.256
5.21	0.60	0.256
5.22	0.69	0.257
5.23	0.80	0.257
5.24	0.90	0.257
5.25	1.00	0.257
5.26	1.09	0.257
5.27	1.19	0.257
5.28	1.29	0.257
5.29	1.40	0.257
5.30	1.50	0.257
5.31	1.60	0.257
5.32	1.70	0.257
5.33	1.80	0.257
5.34	1.89	0.257
5.35	2.00	0.257
5.36	2.10	0.257
5.37	2.20	0.257
5.38	2.30	0.257
5.39	2.40	0.257
5.40	2.50	0.257
5.41	2.60	0.257
5.42	2.70	0.257
5.43	2.80	0.257
5.44	2.90	0.257
5.45	3.00	0.257
5.46	3.10	0.257
5.47	3.20	0.257
5.48	3.30	0.257
5.49	3.40	0.257
5.50	3.50	0.257
5.51	3.60	0.257
5.52	3.70	0.257
5.53	3.80	0.257
5.54	3.90	0.257
5.55	4.00	0.257
5.56	4.10	0.257
5.57	4.20	0.257
5.58	4.30	0.257
5.59	4.40	0.257
5.60	4.50	0.257
5.61	4.60	0.257
5.62	4.70	0.257
5.63	4.80	0.257
5.64	4.90	0.257
5.65	5.00	0.257
5.66	5.10	0.257
5.67	5.20	0.257
5.68	5.30	0.257
5.69	5.40	0.257
5.70	5.50	0.257
5.71	5.60	0.257
5.72	5.70	0.257
5.73	5.80	0.257
5.74	5.90	0.257
5.75	6.00	0.257
5.76	6.10	0.257
5.77	6.20	0.257
5.78	6.30	0.257
5.79	6.40	0.257
5.80	6.50	0.258
5.81	6.60	0.258
5.82	6.70	0.258
5.83	6.80	0.258
5.84	6.90	0.258
5.85	7.00	0.258
5.86	7.10	0.258
5.87	7.20	0.258
5.88	7.30	0.258
5.89	7.40	0.258
5.90	7.50	0.258
5.91	7.60	0.258
5.92	7.70	0.258
5.93	7.80	0.258
5.94	7.90	0.258
5.95	8.01	0.258
5.96	8.10	0.258
5.97	8.21	0.258
5.98	8.31	0.258
5.99	8.40	0.258
6.00	8.51	0.258
6.01	8.61	0.258
6.02	8.71	0.258
6.03	8.81	0.258
6.04	8.91	0.258
6.05	9.00	0.258
6.06	9.11	0.258
6.07	9.21	0.258
6.08	9.31	0.258
6.09	9.41	0.258
6.10	9.51	0.258
6.11	9.61	0.258
6.12	9.71	0.258
6.13	9.81	0.258
6.14	9.91	0.258
6.15	10.01	0.258
6.16	10.11	0.258
6.17	10.21	0.258
6.18	10.31	0.258
6.19	10.41	0.258
6.20	10.51	0.258
6.21	10.61	0.259
6.22	10.71	0.258
6.23	10.81	0.259
6.24	10.91	0.259
6.25	11.01	0.259
6.26	11.11	0.258
6.27	11.21	0.259
6.28	11.31	0.259
6.29	11.41	0.259
6.30	11.51	0.259
6.31	11.61	0.259
6.32	11.71	0.259
6.33	11.81	0.259
6.34	11.91	0.259
6.35	12.01	0.259
6.36	12.11	0.259
6.37	12.21	0.259
6.38	12.31	0.259
6.39	12.41	0.259
6.40	12.51	0.259
6.41	12.61	0.259
6.42	12.71	0.259
6.43	12.81	0.259
6.44	12.91	0.259
6.45	13.01	0.259
6.46	13.11	0.259
6.47	13.21	0.259
6.48	13.31	0.259
6.49	13.41	0.259
6.50	13.51	0.259
6.51	13.61	0.259
6.52	13.71	0.259
6.53	13.81	0.259
6.54	13.91	0.259
6.55	14.01	0.259
6.56	14.11	0.259
6.57	14.21	0.259
6.58	14.31	0.259
6.59	14.41	0.259
6.60	14.51	0.259
6.61	14.61	0.259
6.62	14.71	0.259
6.63	14.81	0.259
6.64	14.91	0.259
6.65	15.01	0.259
6.66	15.11	0.259
6.67	15.21	0.259
6.68	15.31	0.260
6.69	15.41	0.260
6.70	15.51	0.260
6.71	15.61	0.260
6.72	15.71	0.260
6.73	15.82	0.260
6.74	15.91	0.260
6.75	16.02	0.260
6.76	16.11	0.260
6.77	16.22	0.260
6.78	16.32	0.260
6.79	16.42	0.260
6.80	16.52	0.260
6.81	16.62	0.260
6.82	16.72	0.260
6.83	16.82	0.260
6.84	16.92	0.260
6.85	17.01	0.260
6.86	17.12	0.260
6.87	17.22	0.260
6.88	17.32	0.260
6.89	17.42	0.260
6.90	17.52	0.260
6.91	17.62	0.260
6.92	17.72	0.260
6.93	17.82	0.260
6.94	17.92	0.260
6.95	18.02	0.260
6.96	18.12	0.260
6.97	18.22	0.260
6.98	18.32	0.260
6.99	18.42	0.260
7.00	18.52	0.260
7.01	18.62	0.260
7.02	18.72	0.260
7.03	18.82	0.260
7.04	18.92	0.260
7.05	19.02	0.260
7.06	19.12	0.260
7.07	19.22	0.260
7.08	19.32	0.260
7.09	19.42	0.260
7.10	19.52	0.260
7.11	19.62	0.260
7.12	19.72	0.260
7.13	19.82	0.260
7.14	19.92	0.260
7.15	20.02	0.260
7.16	20.12	0.260
7.17	20.22	0.261
7.18	20.32	0.261
7.19	20.42	0.261
7.20	20.52	0.261
7.21	20.62	0.261
7.22	20.72	0.261
7.23	20.82	0.261
7.24	20.92	0.261
7.25	21.02	0.261
7.26	21.12	0.261
7.27	21.22	0.261
7.28	21.32	0.261
7.29	21.42	0.261
7.30	21.52	0.261
7.31	21.62	0.261
7.32	21.72	0.261
7.33	21.82	0.261
7.34	21.92	0.261
7.35	22.02	0.261
7.36	22.12	0.261
7.37	22.22	0.262
7.38	22.32	0.262
7.39	22.42	0.262
7.40	22.52	0.262
7.41	22.62	0.262
7.42	22.72	0.262
7.43	22.82	0.262
7.44	22.92	0.262
7.45	23.02	0.262
7.46	23.12	0.262
7.47	23.22	0.262
7.48	23.32	0.262
7.49	23.42	0.262
7.50	23.52	0.262
7.51	23.62	0.262
7.52	23.72	0.262
7.53	23.82	0.262
7.54	23.92	0.262
7.55	24.02	0.262
7.56	24.12	0.262
7.57	24.22	0.262
7.58	24.32	0.262
7.59	24.42	0.262
7.60	24.52	0.263
7.61	24.62	0.262
7.62	24.72	0.262
7.63	24.83	0.263
7.64	24.92	0.263
7.65	25.02	0.263
7.66	25.13	0.263
7.67	25.23	0.263
7.68	25.33	0.263
7.69	25.43	0.263
7.70	25.53	0.263
7.71	25.63	0.263
7.72	25.73	0.263
7.73	25.83	0.263
7.74	25.93	0.263
7.75	26.03	0.263
7.76	26.13	0.263
7.77	26.23	0.263
7.78	26.33	0.263
7.79	26.43	0.263
7.80	26.53	0.263
7.81	26.63	0.264
7.82	26.73	0.264
7.83	26.83	0.264
7.84	26.93	0.264
7.85	27.03	0.264
7.86	27.13	0.264
7.87	27.23	0.264
7.88	27.33	0.264
7.89	27.43	0.264
7.90	27.53	0.264
7.91	27.63	0.264
7.92	27.73	0.264
7.93	27.83	0.264
7.94	27.93	0.264
7.95	28.03	0.264
7.96	28.13	0.265
7.97	28.23	0.265
7.98	28.33	0.265
7.99	28.43	0.265
8.00	28.53	0.265
8.01	28.63	0.265
8.02	28.73	0.265
8.03	28.83	0.265
8.04	28.93	0.265
8.05	29.03	0.265
8.06	29.13	0.266
8.07	29.23	0.266
8.08	29.33	0.266
8.09	29.43	0.266
8.10	29.53	0.266
8.11	29.63	0.266
8.12	29.73	0.266
8.13	29.83	0.266
8.14	29.93	0.266
8.15	30.03	0.266
8.16	30.13	0.266
8.17	30.23	0.266
8.18	30.33	0.266
8.19	30.43	0.266
8.20	30.53	0.266
8.21	30.63	0.266
8.22	30.73	0.267
8.23	30.83	0.266
8.24	30.93	0.267
8.25	31.03	0.267
8.26	31.13	0.267
8.27	31.23	0.267
8.28	31.33	0.267
8.29	31.43	0.267
8.30	31.53	0.267
8.31	31.63	0.267
8.32	31.73	0.267
8.33	31.83	0.267
8.34	31.93	0.267
8.35	32.03	0.267
8.36	32.13	0.267
8.37	32.23	0.268
8.38	32.33	0.268
8.39	32.43	0.268
8.40	32.53	0.268
8.41	32.63	0.268
8.42	32.73	0.268
8.43	32.83	0.268
8.44	32.93	0.268
8.45	33.03	0.268
8.46	33.14	0.268
8.47	33.23	0.268
8.48	33.33	0.268
8.49	33.44	0.269
8.50	33.53	0.269
8.51	33.63	0.269
8.52	33.74	0.269
8.53	33.84	0.269
8.54	33.94	0.269
8.55	34.04	0.269
8.56	34.14	0.269
8.57	34.24	0.269
8.58	34.34	0.269
8.59	34.44	0.269
8.60	34.54	0.270
8.61	34.64	0.270
8.62	34.74	0.270
8.63	34.84	0.270
8.64	34.94	0.270
8.65	35.04	0.270
8.66	35.14	0.270
8.67	35.24	0.270
8.68	35.34	0.270
8.69	35.44	0.270
8.70	35.54	0.270
8.71	35.64	0.270
8.72	35.74	0.270
8.73	35.84	0.270
8.74	35.94	0.271
8.75	36.04	0.271
8.76	36.14	0.271
8.77	36.24	0.271
8.78	36.34	0.271
8.79	36.44	0.271
8.80	36.54	0.271
8.81	36.64	0.271
8.82	36.74	0.271
8.83	36.84	0.271
8.84	36.94	0.271
8.85	37.04	0.271
8.86	37.14	0.271
8.87	37.24	0.271
8.88	37.34	0.271
8.89	37.44	0.271
8.90	37.54	0.272
8.91	37.64	0.272
8.92	37.74	0.272
8.93	37.84	0.272
8.94	37.94	0.272
8.95	38.04	0.272
8.96	38.14	0.272
8.97	38.24	0.272
8.98	38.34	0.272
8.99	38.44	0.272
9.00	38.54	0.272
9.01	38.64	0.272
9.02	38.74	0.272
9.03	38.84	0.272
9.04	38.94	0.272
9.05	39.04	0.273
9.06	39.14	0.273
9.07	39.24	0.273
9.08	39.34	0.273
9.09	39.44	0.273
9.10	39.54	0.273
9.11	39.64	0.273
9.12	39.74	0.273
9.13	39.84	0.273
9.14	39.94	0.273
9.15	40.04	0.273
9.16	40.14	0.273
9.17	40.24	0.273
9.18	40.34	0.273
9.19	40.44	0.273
9.20	40.54	0.273
9.21	40.64	0.273
9.22	40.74	0.274
9.23	40.84	0.274
9.24	40.94	0.274
9.25	41.04	0.274
9.26	41.14	0.274
9.27	41.24	0.274
9.28	41.34	0.274
9.29	41.44	0.274
9.30	41.54	0.274
9.31	41.64	0.274
9.32	41.74	0.274
9.33	41.84	0.275
9.34	41.94	0.275
9.35	42.05	0.275
9.36	42.14	0.275
9.37	42.24	0.275
9.38	42.34	0.275
9.39	42.44	0.275
9.40	42.54	0.275
9.41	42.64	0.275
9.42	42.74	0.275
9.43	42.84	0.275
9.44	42.94	0.276
9.45	43.05	0.276
9.46	43.15	0.276
9.47	43.25	0.276
9.48	43.35	0.276
9.49	43.45	0.276
9.50	43.55	0.276
9.51	43.65	0.276
9.52	43.75	0.276
9.53	43.85	0.276
9.54	43.95	0.276
9.55	44.04	0.276
9.56	44.15	0.277
9.57	44.25	0.277
9.58	44.35	0.277
9.59	44.45	0.277
9.60	44.55	0.277
9.61	44.65	0.277
9.62	44.75	0.277
9.63	44.85	0.277
9.64	44.95	0.277
9.65	45.05	0.277
9.66	45.15	0.277
9.67	45.25	0.277
9.68	45.35	0.277
9.69	45.45	0.278
9.70	45.55	0.278
9.71	45.65	0.278
9.72	45.75	0.278
9.73	45.85	0.278
9.74	45.95	0.278
9.75	46.05	0.278
9.76	46.15	0.278
9.77	46.25	0.278
9.78	46.35	0.278
9.79	46.45	0.278
9.80	46.55	0.279
9.81	46.65	0.279
9.82	46.75	0.279
9.83	46.85	0.279
9.84	46.95	0.279
9.85	47.05	0.279
9.86	47.15	0.279
9.87	47.25	0.279
9.88	47.35	0.279
9.89	47.45	0.279
9.90	47.55	0.279
9.91	47.65	0.279
9.92	47.75	0.279
9.93	47.85	0.279
9.94	47.95	0.279
9.95	48.05	0.279
9.96	48.15	0.279
9.97	48.25	0.279
9.98	48.35	0.280
9.99	48.45	0.280
10.00	48.55	0.280
10.01	48.65	0.280
10.02	48.75	0.280
10.03	48.85	0.280
10.04	48.95	0.280
10.05	49.05	0.280
10.06	49.15	0.280
10.07	49.25	0.280
10.08	49.35	0.280
10.09	49.45	0.280
10.10	49.55	0.280
10.11	49.65	0.280
10.12	49.75	0.280
10.13	49.86	0.280
10.14	49.95	0.280
10.15	50.05	0.280
10.16	50.15	0.281
10.17	50.26	0.281
10.18	50.36	0.281
10.19	50.46	0.281
10.20	50.56	0.281
10.21	50.66	0.281
10.22	50.76	0.281
10.23	50.86	0.281
10.24	50.96	0.281
10.25	51.06	0.281
10.26	51.16	0.281
10.27	51.26	0.281
10.28	51.36	0.281
10.29	51.46	0.281
10.30	51.56	0.281
10.31	51.66	0.281
10.32	51.76	0.281
10.33	51.86	0.281
10.34	51.96	0.281
10.35	52.06	0.282
10.36	52.16	0.282
10.37	52.26	0.282
10.38	52.36	0.282
10.39	52.46	0.282
10.40	52.56	0.282
10.41	52.66	0.282
10.42	52.76	0.282
10.43	52.86	0.282
10.44	52.96	0.282
10.45	53.06	0.282
10.46	53.16	0.282
10.47	53.26	0.282
10.48	53.36	0.282
10.49	53.46	0.282
10.50	53.56	0.282
10.51	53.66	0.282
10.52	53.76	0.282
10.53	53.86	0.282
10.54	53.96	0.282
10.55	54.06	0.282
10.56	54.16	0.282
10.57	54.26	0.283
10.58	54.36	0.283
10.59	54.46	0.283
10.60	54.56	0.283
10.61	54.66	0.283
10.62	54.76	0.283
10.63	54.86	0.283
10.64	54.96	0.283
10.65	55.06	0.283
10.66	55.16	0.283
10.67	55.26	0.283
10.68	55.36	0.283
10.69	55.46	0.283
10.70	55.56	0.283
10.71	55.66	0.283
10.72	55.76	0.283
10.73	55.86	0.284
10.74	55.96	0.284
10.75	56.06	0.284
10.76	56.16	0.284
10.77	56.26	0.284
10.78	56.36	0.284
10.79	56.46	0.284
10.80	56.56	0.284
10.81	56.66	0.284
10.82	56.76	0.284
10.83	56.86	0.284
10.84	56.96	0.284
10.85	57.06	0.284
10.86	57.16	0.284
10.87	57.26	0.284
10.88	57.36	0.284
10.89	57.46	0.284
10.90	57.56	0.284
10.91	57.66	0.284
10.92	57.76	0.284
10.93	57.86	0.284
10.94	57.96	0.284
10.95	58.06	0.285
10.96	58.16	0.285
10.97	58.26	0.285
10.98	58.36	0.285
10.99	58.46	0.285
11.00	58.56	0.285
11.01	58.66	0.285
11.02	58.76	0.285
11.03	58.86	0.285
11.04	58.96	0.285
11.05	59.06	0.285
11.06	59.16	0.285
11.07	59.26	0.285
11.08	59.36	0.285
11.09	59.46	0.285
11.10	59.57	0.286
11.11	59.66	0.286
11.12	59.76	0.286
11.13	59.86	0.286
11.14	59.96	0.286
11.15	60.07	0.286
11.16	60.17	0.286
11.17	60.26	0.286
11.18	60.37	0.286
11.19	60.46	0.286
11.20	60.57	0.286
11.21	60.67	0.286
11.22	60.77	0.286
11.23	60.86	0.286
11.24	60.97	0.286
11.25	61.07	0.286
11.26	61.17	0.286
11.27	61.27	0.286
11.28	61.37	0.286
11.29	61.47	0.286
11.30	61.57	0.287
11.31	61.67	0.287
11.32	61.77	0.287
11.33	61.86	0.287
11.34	61.97	0.287
11.35	62.07	0.287
11.36	62.17	0.287
11.37	62.27	0.287
11.38	62.37	0.287
11.39	62.47	0.287
11.40	62.57	0.287
11.41	62.67	0.287
11.42	62.77	0.287
11.43	62.87	0.287
11.44	62.97	0.287
11.45	63.07	0.287
11.46	63.17	0.287
11.47	63.27	0.287
11.48	63.37	0.288
11.49	63.47	0.287
11.50	63.57	0.288
11.51	63.67	0.288
11.52	63.77	0.288
11.53	63.87	0.288
11.54	63.97	0.288
11.55	64.07	0.288
11.56	64.17	0.288
11.57	64.27	0.288
11.58	64.37	0.288
11.59	64.47	0.288
11.60	64.57	0.288
11.61	64.67	0.288
11.62	64.77	0.288
11.63	64.87	0.288
11.64	64.97	0.288
11.65	65.07	0.288
11.66	65.17	0.288
11.67	65.27	0.288
11.68	65.37	0.288
11.69	65.47	0.289
11.70	65.57	0.289
11.71	65.67	0.289
11.72	65.77	0.289
11.73	65.87	0.289
11.74	65.97	0.289
11.75	66.07	0.289
11.76	66.17	0.289
11.77	66.27	0.289
11.78	66.37	0.289
11.79	66.47	0.289
11.80	66.57	0.289
11.81	66.67	0.289
11.82	66.77	0.289
11.83	66.87	0.289
11.84	66.97	0.289
11.85	67.07	0.289
11.86	67.17	0.289
11.87	67.27	0.289
11.88	67.37	0.289
11.89	67.47	0.289
11.90	67.57	0.289
11.91	67.67	0.290
11.92	67.77	0.290
11.93	67.87	0.290
11.94	67.97	0.290
11.95	68.07	0.290
11.96	68.17	0.290
11.97	68.27	0.290
11.98	68.37	0.290
11.99	68.47	0.290
12.00	68.57	0.290
12.01	68.67	0.290
12.02	68.77	0.290
12.03	68.87	0.290
12.04	68.97	0.290
12.05	69.07	0.290
12.06	69.17	0.290
12.07	69.27	0.291
12.08	69.37	0.291
12.09	69.47	0.291
12.10	69.57	0.291
12.11	69.67	0.291
12.12	69.77	0.291
12.13	69.87	0.291
12.14	69.97	0.291
12.15	70.08	0.291
12.16	70.17	0.291
12.17	70.28	0.291
12.18	70.37	0.291
12.19	70.48	0.291
12.20	70.58	0.291
12.21	70.68	0.291
12.22	70.78	0.291
12.23	70.88	0.291
12.24	70.98	0.292
12.25	71.08	0.292
12.26	71.18	0.292
12.27	71.28	0.292
12.28	71.38	0.292
12.29	71.48	0.292
12.30	71.58	0.292
12.31	71.68	0.292
12.32	71.78	0.292
12.33	71.88	0.292
12.34	71.98	0.292
12.35	72.08	0.292
12.36	72.18	0.292
12.37	72.28	0.292
12.38	72.38	0.292
12.39	72.48	0.292
12.40	72.58	0.292
12.41	72.68	0.292
12.42	72.78	0.292
12.43	72.88	0.292
12.44	72.98	0.292
12.45	73.08	0.292
12.46	73.18	0.292
12.47	73.28	0.292
12.48	73.38	0.292
12.49	73.48	0.293
12.50	73.58	0.293
12.51	73.68	0.293
12.52	73.78	0.293
12.53	73.88	0.293
12.54	73.98	0.293
12.55	74.08	0.293
12.56	74.18	0.293
12.57	74.28	0.293
12.58	74.38	0.293
12.59	74.48	0.293
12.60	74.58	0.293
12.61	74.68	0.293
12.62	74.78	0.293
12.63	74.88	0.293
12.64	74.98	0.293
12.65	75.08	0.293
12.66	75.18	0.293
12.67	75.28	0.293
12.68	75.38	0.293
12.69	75.48	0.293
12.70	75.58	0.293
12.71	75.68	0.294
12.72	75.78	0.294
12.73	75.88	0.294
12.74	75.98	0.294
12.75	76.08	0.294
12.76	76.18	0.294
12.77	76.28	0.294
12.78	76.38	0.294
12.79	76.48	0.294
12.80	76.58	0.294
12.81	76.68	0.294
12.82	76.78	0.294
12.83	76.88	0.294
12.84	76.98	0.294
12.85	77.08	0.294
12.86	77.18	0.294
12.87	77.28	0.294
12.88	77.38	0.294
12.89	77.48	0.294
12.90	77.58	0.294
12.91	77.68	0.295
12.92	77.78	0.295
12.93	77.88	0.295
12.94	77.98
12.95	78.08
12.96	78.18
12.97	78.28
12.98	78.38
12.99
12.99

[step]
Ramp 10.00 °C/min to -50.00 °C
Time	Temperature	Heat Flow (Normalized)
min	°C	W/g
14.00	80.09	-0.072
14.00	80.09	-0.072
14.02	80.09	-0.072
14.03	80.09	-0.072
14.03	80.08	-0.073
14.05	80.08	-0.075
14.05	80.07	-0.083
14.07	80.05	-0.100
14.08	80.03	-0.121
14.08	80.00	-0.143
14.10	79.97	-0.165
14.10	79.93	-0.186
14.12	79.88	-0.207
14.13	79.83	-0.229
14.13	79.77	-0.255
14.15	79.70	-0.275
14.15	79.63	-0.295
14.17	79.56	-0.308
14.18	79.49	-0.321
14.18	79.41	-0.337
14.20	79.33	-0.350
14.20	79.25	-0.358
14.22	79.16	-0.368
14.23	79.08	-0.377
14.23	78.99	-0.383
14.25	78.90	-0.388
14.25	78.82	-0.396
14.27	78.73	-0.401
14.28	78.64	-0.404
14.28	78.54	-0.410
14.30	78.45	-0.413
14.30	78.36	-0.414
14.32	78.27	-0.417
14.33	78.17	-0.419
14.33	78.08	-0.422
14.35	77.98	-0.424
14.35	77.89	-0.425
14.37	77.79	-0.426
14.38	77.70	-0.427
14.38	77.60	-0.428
14.40	77.50	-0.429
14.40	77.41	-0.429
14.42	77.31	-0.430
14.43	77.21	-0.430
14.43	77.12	-0.430
14.45	77.02	-0.431
14.45	76.92	-0.431
14.47	76.82	-0.432
14.48	76.72	-0.432
14.48	76.63	-0.432
14.50	76.53	-0.433
14.50	76.43	-0.433
14.52	76.33	-0.434
14.53	76.24	-0.434
14.53	76.14	-0.434
14.55	76.04	-0.434
14.55	75.94	-0.435
14.57	75.84	-0.435
14.58	75.74	-0.435
14.58	75.65	-0.435
14.60	75.55	-0.435
14.60	75.45	-0.435
14.62	75.35	-0.436
14.63	75.25	-0.436
14.63	75.15	-0.436
14.65	75.05	-0.436
14.65	74.95	-0.436
14.67	74.85	-0.436
14.68	74.76	-0.436
14.68	74.66	-0.436
14.70	74.56	-0.436
14.70	74.46	-0.437
14.72	74.36	-0.437
14.73	74.26	-0.437
14.73	74.16	-0.436
14.75	74.06	-0.437
14.75	73.96	-0.437
14.77	73.86	-0.437
14.78	73.77	-0.437
14.78	73.67	-0.437
14.80	73.57	-0.436
14.80	73.47	-0.436
14.82	73.37	-0.436
14.83	73.27	-0.436
14.83	73.17	-0.436
14.85	73.07	-0.436
14.85	72.97	-0.436
14.87	72.87	-0.436
14.88	72.77	-0.436
14.88	72.67	-0.436
14.90	72.57	-0.436
14.90	72.48	-0.435
14.92	72.38	-0.435
14.93	72.28	-0.435
14.93	72.18	-0.435
14.95	72.08	-0.435
14.95	71.98	-0.435
14.97	71.88	-0.435
14.98	71.78	-0.435
14.98	71.68	-0.435
15.00	71.58	-0.434
15.00	71.48	-0.434
15.02	71.38	-0.434
15.03	71.28	-0.434
15.03	71.18	-0.434
15.05	71.08	-0.434
15.05	70.98	-0.434
15.07	70.88	-0.434
15.08	70.79	-0.433
15.08	70.69	-0.433
15.10	70.59	-0.433
15.10	70.49	-0.433
15.12	70.39	-0.433
15.13	70.29	-0.433
15.13	70.19	-0.432
15.15	70.09	-0.432
15.15	69.99	-0.432
15.17	69.89	-0.432
15.18	69.79	-0.432
15.18	69.69	-0.432
15.20	69.59	-0.431
15.20	69.49	-0.431
15.22	69.39	-0.431
15.23	69.29	-0.431
15.23	69.19	-0.431
15.25	69.09	-0.431
15.25	68.99	-0.430
15.27	68.89	-0.430
15.28	68.79	-0.430
15.28	68.69	-0.430
15.30	68.59	-0.430
15.30	68.49	-0.429
15.32	68.39	-0.429
15.33	68.29	-0.429
15.33	68.19	-0.429
15.35	68.09	-0.429
15.35	67.99	-0.428
15.37	67.90	-0.428
15.38	67.80	-0.428
15.38	67.70	-0.428
15.40	67.59	-0.428
15.40	67.50	-0.427
15.42	67.40	-0.427
15.43	67.30	-0.427
15.43	67.20	-0.427
15.45	67.10	-0.427
15.45	67.00	-0.427
15.47	66.90	-0.426
15.48	66.80	-0.426
15.48	66.70	-0.426
15.50	66.60	-0.426
15.50	66.50	-0.426
15.52	66.40	-0.425
15.53	66.30	-0.425
15.53	66.20	-0.425
15.55	66.10	-0.425
15.55	66.00	-0.425
15.57	65.90	-0.425
15.58	65.80	-0.424
15.58	65.70	-0.424
15.60	65.60	-0.424
15.60	65.50	-0.424
15.62	65.40	-0.423
15.63	65.30	-0.423
15.63	65.20	-0.423
15.65	65.10	-0.423
15.65	65.00	-0.423
15.67	64.90	-0.422
15.68	64.80	-0.422
15.68	64.70	-0.422
15.70	64.60	-0.422
15.70	64.50	-0.422
15.72	64.40	-0.421
15.73	64.30	-0.421
15.73	64.20	-0.421
15.75	64.10	-0.420
15.75	64.00	-0.420
15.77	63.90	-0.420
15.78	63.80	-0.420
15.78	63.70	-0.420
15.80	63.60	-0.420
15.80	63.50	-0.420
15.82	63.40	-0.419
15.83	63.30	-0.419
15.83	63.20	-0.419
15.85	63.10	-0.419
15.85	63.00	-0.419
15.87	62.90	-0.418
15.88	62.80	-0.418
15.88	62.70	-0.418
15.90	62.60	-0.418
15.90	62.50	-0.417
15.92	62.40	-0.417
15.93	62.30	-0.417
15.93	62.20	-0.417
15.95	62.10	-0.417
15.95	62.00	-0.416
15.97	61.90	-0.416
15.98	61.81	-0.416
15.98	61.70	-0.416
16.00	61.61	-0.416
16.00	61.51	-0.416
16.02	61.41	-0.415
16.03	61.31	-0.415
16.03	61.21	-0.415
16.05	61.11	-0.415
16.05	61.01	-0.414
16.07	60.91	-0.414
16.08	60.81	-0.414
16.08	60.71	-0.414
16.10	60.61	-0.413
16.10	60.51	-0.413
16.12	60.41	-0.413
16.13	60.31	-0.413
16.13	60.21	-0.413
16.15	60.11	-0.413
16.15	60.01	-0.412
16.17	59.91	-0.412
16.18	59.81	-0.412
16.18	59.71	-0.412
16.20	59.61	-0.412
16.20	59.51	-0.412
16.22	59.41	-0.412
16.23	59.31	-0.411
16.23	59.21	-0.411
16.25	59.11	-0.411
16.25	59.01	-0.411
16.27	58.91	-0.411
16.28	58.81	-0.410
16.28	58.71	-0.410
16.30	58.61	-0.410
16.30	58.51	-0.410
16.32	58.41	-0.410
16.33	58.31	-0.409
16.33	58.21	-0.409
16.35	58.11	-0.409
16.35	58.01	-0.409
16.37	57.91	-0.409
16.38	57.81	-0.408
16.38	57.71	-0.408
16.40	57.61	-0.408
16.40	57.51	-0.408
16.42	57.41	-0.408
16.43	57.31	-0.408
16.43	57.21	-0.407
16.45	57.11	-0.407
16.45	57.01	-0.407
16.47	56.91	-0.406
16.48	56.81	-0.406
16.48	56.71	-0.406
16.50	56.61	-0.406
16.50	56.51	-0.406
16.52	56.41	-0.405
16.53	56.31	-0.405
16.53	56.21	-0.405
16.55	56.11	-0.405
16.55	56.01	-0.405
16.57	55.91	-0.405
16.58	55.81	-0.405
16.58	55.71	-0.404
16.60	55.61	-0.404
16.60	55.51	-0.404
16.62	55.41	-0.404
16.63	55.31	-0.404
16.63	55.21	-0.404
16.65	55.11	-0.404
16.65	55.01	-0.403
16.67	54.91	-0.403
16.68	54.81	-0.403
16.68	54.71	-0.403
16.70	54.61	-0.403
16.70	54.51	-0.403
16.72	54.41	-0.402
16.73	54.31	-0.402
16.73	54.21	-0.402
16.75	54.11	-0.402
16.75	54.01	-0.402
16.77	53.91	-0.402
16.78	53.81	-0.401
16.78	53.71	-0.401
16.80	53.61	-0.401
16.80	53.51	-0.401
16.82	53.41	-0.401
16.83	53.31	-0.400
16.83	53.21	-0.400
16.85	53.12	-0.400
16.85	53.01	-0.400
16.87	52.92	-0.400
16.88	52.81	-0.399
16.88	52.71	-0.399
16.90	52.62	-0.399
16.90	52.52	-0.399
16.92	52.42	-0.399
16.93	52.32	-0.398
16.93	52.21	-0.398
16.95	52.11	-0.398
16.95	52.02	-0.398
16.97	51.92	-0.398
16.98	51.81	-0.398
16.98	51.72	-0.397
17.00	51.62	-0.397
17.00	51.52	-0.397
17.02	51.42	-0.397
17.03	51.32	-0.397
17.03	51.22	-0.397
17.05	51.12	-0.396
17.05	51.02	-0.396
17.07	50.92	-0.396
17.08	50.82	-0.396
17.08	50.72	-0.396
17.09	50.62	-0.396
17.11	50.52	-0.396
17.12	50.42	-0.395
17.13	50.32	-0.395
17.13	50.22	-0.395
17.14	50.12	-0.395
17.16	50.02	-0.395
17.17	49.92	-0.395
17.18	49.82	-0.394
17.18	49.72	-0.394
17.19	49.62	-0.394
17.21	49.52	-0.394
17.22	49.42	-0.394
17.23	49.32	-0.394
17.23	49.22	-0.394
17.24	49.12	-0.394
17.26	49.02	-0.393
17.27	48.92	-0.393
17.28	48.82	-0.393
17.28	48.72	-0.393
17.29	48.62	-0.393
17.31	48.52	-0.393
17.32	48.42	-0.392
17.33	48.32	-0.392
17.33	48.22	-0.392
17.34	48.12	-0.392
17.36	48.02	-0.392
17.37	47.92	-0.392
17.38	47.82	-0.391
17.38	47.72	-0.391
17.39	47.62	-0.391
17.41	47.52	-0.391
17.42	47.42	-0.391
17.43	47.32	-0.391
17.43	47.22	-0.390
17.44	47.12	-0.390
17.46	47.02	-0.390
17.47	46.92	-0.390
17.48	46.82	-0.390
17.48	46.72	-0.390
17.49	46.62	-0.390
17.51	46.52	-0.389
17.52	46.42	-0.389
17.53	46.32	-0.389
17.53	46.22	-0.389
17.54	46.12	-0.389
17.56	46.02	-0.389
17.57	45.92	-0.389
17.58	45.82	-0.388
17.58	45.72	-0.388
17.59	45.62	-0.388
17.61	45.52	-0.388
17.62	45.42	-0.388
17.63	45.32	-0.387
17.63	45.22	-0.387
17.64	45.12	-0.387
17.66	45.02	-0.387
17.67	44.92	-0.387
17.68	44.82	-0.387
17.68	44.72	-0.386
17.69	44.62	-0.386
17.71	44.52	-0.386
17.72	44.42	-0.386
17.73	44.32	-0.386
17.73	44.22	-0.386
17.74	44.12	-0.386
17.76	44.02	-0.385
17.77	43.92	-0.385
17.78	43.82	-0.385
17.78	43.72	-0.385
17.79	43.62	-0.385
17.81	43.52	-0.384
17.82	43.42	-0.384
17.83	43.32	-0.384
17.83	43.22	-0.384
17.84	43.13	-0.384
17.86	43.02	-0.384
17.87	42.92	-0.383
17.88	42.83	-0.383
17.88	42.73	-0.383
17.89	42.63	-0.383
17.91	42.53	-0.383
17.92	42.43	-0.383
17.93	42.33	-0.383
17.93	42.23	-0.383
17.94	42.13	-0.382
17.96	42.02	-0.382
17.97	41.93	-0.382
17.98	41.83	-0.382
17.98	41.73	-0.382
17.99	41.63	-0.381
18.01	41.52	-0.381
18.02	41.43	-0.381
18.03	41.33	-0.381
18.03	41.23	-0.381
18.04	41.13	-0.380
18.06	41.03	-0.380
18.07	40.93	-0.380
18.08	40.83	-0.380
18.08	40.73	-0.380
18.09	40.63	-0.379
18.11	40.53	-0.379
18.12	40.43	-0.379
18.13	40.33	-0.379
18.13	40.23	-0.379
18.14	40.13	-0.379
18.16	40.03	-0.378
18.17	39.93	-0.378
18.18	39.83	-0.378
18.18	39.73	-0.378
18.19	39.63	-0.378
18.21	39.53	-0.378
18.22	39.43	-0.378
18.23	39.33	-0.377
18.23	39.23	-0.377
18.24	39.13	-0.377
18.26	39.03	-0.377
18.27	38.93	-0.377
18.28	38.83	-0.377
18.28	38.73	-0.376
18.29	38.63	-0.376
18.31	38.53	-0.376
18.32	38.43	-0.376
18.33	38.33	-0.376
18.33	38.23	-0.376
[...]
132.60	-26.64	0.195
132.61	-26.54	0.195
132.62	-26.44	0.195
132.63	-26.34	0.195
132.64	-26.24	0.195
132.65	-26.14	0.195
132.66	-26.04	0.195
132.67	-25.94	0.195
132.68	-25.84	0.195
132.69	-25.74	0.195
132.70	-25.64	0.195
132.71	-25.54	0.195
132.72	-25.44	0.196
132.73	-25.34	0.196
132.74	-25.24	0.196
132.75	-25.14	0.196
132.76	-25.04	0.196
132.77	-24.94	0.196
132.78	-24.84	0.196
132.79	-24.74	0.196
132.80	-24.64	0.196
132.81	-24.54	0.196
132.82	-24.44	0.196
132.83	-24.34	0.196
132.84	-24.24	0.196
132.85	-24.14	0.196
132.86	-24.04	0.197
132.87	-23.94	0.197
132.88	-23.84	0.197
132.89	-23.74	0.197
132.90	-23.64	0.197
132.91	-23.54	0.197
132.92	-23.44	0.197
132.93	-23.34	0.197
132.94	-23.24	0.197
132.95	-23.14	0.197
132.96	-23.04	0.198
132.97	-22.94	0.198
132.98	-22.84	0.198
132.99	-22.74	0.198
133.00	-22.64	0.198
133.01	-22.54	0.198
133.02	-22.44	0.198
133.03	-22.34	0.198
133.04	-22.24	0.198
133.05	-22.14	0.199
133.06	-22.04	0.199
133.07	-21.94	0.199
133.08	-21.84	0.199
133.09	-21.74	0.199
133.10	-21.63	0.199
133.11	-21.54	0.199
133.12	-21.43	0.199
133.13	-21.34	0.199
133.14	-21.23	0.200
133.15	-21.14	0.200
133.16	-21.03	0.200
133.17	-20.94	0.200
133.18	-20.83	0.200
133.19	-20.73	0.201
133.20	-20.64	0.201
133.21	-20.54	0.201
133.22	-20.43	0.201
133.23	-20.34	0.201
133.24	-20.23	0.201
133.25	-20.14	0.202
133.26	-20.03	0.202
133.27	-19.93	0.202
133.28	-19.83	0.202
133.29	-19.73	0.203
133.30	-19.63	0.203
133.31	-19.53	0.203
133.32	-19.43	0.203
133.33	-19.33	0.204
133.34	-19.23	0.204
133.35	-19.13	0.204
133.36	-19.03	0.204
133.37	-18.93	0.205
133.38	-18.83	0.205
133.39	-18.73	0.205
133.40	-18.63	0.206
133.41	-18.53	0.206
133.42	-18.43	0.206
133.43	-18.33	0.206
133.44	-18.23	0.207
133.45	-18.13	0.207
133.46	-18.03	0.208
133.47	-17.93	0.208
133.48	-17.83	0.208
133.49	-17.73	0.209
133.50	-17.63	0.209
133.51	-17.53	0.209
133.52	-17.43	0.210
133.53	-17.33	0.211
133.54	-17.23	0.211
133.55	-17.13	0.211
133.56	-17.03	0.212
133.57	-16.93	0.212
133.58	-16.83	0.213
133.59	-16.73	0.213
133.60	-16.63	0.214
133.61	-16.53	0.214
133.62	-16.43	0.215
133.63	-16.33	0.216
133.64	-16.23	0.217
133.65	-16.13	0.217
133.66	-16.03	0.218
133.67	-15.93	0.219
133.68	-15.83	0.220
133.69	-15.73	0.221
133.70	-15.63	0.222
133.71	-15.53	0.223
133.72	-15.43	0.224
133.73	-15.33	0.225
133.74	-15.23	0.226
133.75	-15.13	0.227
133.76	-15.03	0.228
133.77	-14.93	0.229
133.78	-14.83	0.230
133.79	-14.73	0.231
133.80	-14.63	0.235
133.81	-14.53	0.236
133.82	-14.43	0.237
133.83	-14.33	0.241
133.84	-14.23	0.242
133.85	-14.13	0.243
133.86	-14.03	0.245
133.87	-13.94	0.246
133.88	-13.83	0.248
133.89	-13.74	0.251
133.90	-13.64	0.253
133.91	-13.54	0.255
133.92	-13.44	0.256
133.93	-13.34	0.259
133.94	-13.23	0.260
133.95	-13.14	0.263
133.96	-13.04	0.265
133.97	-12.94	0.267
133.98	-12.84	0.269
133.99	-12.74	0.270
134.00	-12.64	0.273
134.01	-12.54	0.274
134.02	-12.44	0.276
134.03	-12.34	0.278
134.04	-12.24	0.279
134.05	-12.14	0.281
134.06	-12.04	0.281
134.07	-11.94	0.282
134.08	-11.84	0.283
134.09	-11.74	0.283
134.10	-11.64	0.284
134.11	-11.54	0.284
134.12	-11.44	0.285
134.13	-11.34	0.285
134.14	-11.24	0.285
134.15	-11.14	0.286
134.16	-11.04	0.286
134.17	-10.94	0.286
134.18	-10.84	0.286
134.19	-10.74	0.286
134.20	-10.64	0.286
134.21	-10.54	0.286
134.22	-10.44	0.286
134.23	-10.34	0.285
134.24	-10.24	0.285
134.25	-10.14	0.284
134.26	-10.04	0.283
134.27	-9.93	0.281
134.28	-9.83	0.279
134.29	-9.73	0.279
134.30	-9.63	0.278
134.31	-9.53	0.275
134.32	-9.43	0.274
134.33	-9.33	0.274
134.34	-9.23	0.273
134.35	-9.13	0.272
134.36	-9.03	0.272
134.37	-8.93	0.271
134.38	-8.83	0.270
134.39	-8.73	0.269
134.40	-8.63	0.269
134.41	-8.53	0.268
134.42	-8.43	0.268
134.43	-8.33	0.267
134.44	-8.23	0.267
134.45	-8.13	0.266
134.46	-8.03	0.266
134.47	-7.93	0.266
134.48	-7.83	0.265
134.49	-7.73	0.265
134.50	-7.63	0.265
134.51	-7.53	0.264
134.52	-7.43	0.264
134.53	-7.33	0.264
134.54	-7.23	0.263
134.55	-7.13	0.263
134.56	-7.03	0.262
134.57	-6.93	0.262
134.58	-6.83	0.262
134.59	-6.73	0.262
134.60	-6.63	0.261
134.61	-6.53	0.261
134.62	-6.43	0.261
134.63	-6.33	0.260
134.64	-6.23	0.260
134.65	-6.12	0.260
134.66	-6.02	0.260
134.67	-5.93	0.259
134.68	-5.83	0.259
134.69	-5.72	0.259
134.70	-5.63	0.258
134.71	-5.53	0.258
134.72	-5.42	0.258
134.73	-5.32	0.258
134.74	-5.22	0.257
134.75	-5.12	0.257
134.76	-5.02	0.257
134.77	-4.92	0.257
134.78	-4.82	0.257
134.79	-4.72	0.256
134.80	-4.62	0.256
134.81	-4.52	0.256
134.82	-4.42	0.256
134.83	-4.32	0.256
134.84	-4.22	0.256
134.85	-4.12	0.256
134.86	-4.02	0.256
134.87	-3.92	0.256
134.88	-3.82	0.256
134.89	-3.72	0.256
134.90	-3.62	0.256
134.91	-3.52	0.256
134.92	-3.42	0.256
134.93	-3.32	0.256
134.94	-3.22	0.255
134.95	-3.12	0.255
134.96	-3.02	0.256
134.97	-2.92	0.255
134.98	-2.82	0.255
134.99	-2.72	0.255
135.00	-2.62	0.255
135.01	-2.52	0.255
135.02	-2.42	0.255
135.03	-2.32	0.255
135.04	-2.22	0.255
135.05	-2.12	0.255
135.06	-2.02	0.255
135.07	-1.92	0.255
135.08	-1.82	0.255
135.09	-1.72	0.255
135.10	-1.62	0.255
135.11	-1.52	0.252
135.12	-1.42	0.251
135.13	-1.32	0.251
135.14	-1.22	0.252
135.15	-1.12	0.252
135.16	-1.02	0.252
135.17	-0.92	0.252
135.18	-0.82	0.252
135.19	-0.72	0.252
135.20	-0.62	0.253
135.21	-0.52	0.253
135.22	-0.42	0.253
135.23	-0.32	0.253
135.24	-0.22	0.253
135.25	-0.12	0.253
135.26	-0.02	0.253
135.27	0.08	0.253
135.28	0.18	0.253
135.29	0.28	0.253
135.30	0.38	0.254
135.31	0.48	0.254
135.32	0.58	0.254
135.33	0.68	0.254
135.34	0.78	0.254
135.35	0.88	0.254
135.36	0.98	0.254
135.37	1.08	0.254
135.38	1.18	0.254
135.39	1.28	0.254
135.40	1.38	0.254
135.41	1.48	0.254
135.42	1.58	0.254
135.43	1.68	0.255
135.44	1.78	0.255
135.45	1.88	0.255
135.46	1.98	0.255
135.47	2.08	0.255
135.48	2.18	0.255
135.49	2.28	0.255
135.50	2.38	0.255
135.51	2.48	0.255
135.52	2.58	0.255
135.53	2.68	0.255
135.54	2.79	0.255
135.55	2.89	0.255
135.56	2.99	0.255
135.57	3.09	0.256
135.58	3.19	0.256
135.59	3.29	0.256
135.60	3.39	0.256
135.61	3.49	0.256
135.62	3.59	0.256
135.63	3.69	0.256
135.64	3.79	0.256
135.65	3.89	0.256
135.66	3.99	0.256
135.67	4.09	0.256
135.68	4.19	0.256
135.69	4.29	0.256
135.70	4.39	0.256
135.71	4.49	0.256
135.72	4.59	0.256
135.73	4.69	0.256
135.74	4.79	0.256
135.75	4.89	0.256
135.76	4.99	0.256
135.77	5.09	0.256
135.78	5.19	0.256
135.79	5.29	0.257
135.80	5.39	0.256
135.81	5.49	0.257
135.82	5.59	0.256
135.83	5.69	0.257
135.84	5.79	0.257
135.85	5.89	0.257
135.86	5.99	0.257
135.87	6.09	0.257
135.88	6.19	0.257
135.89	6.29	0.257
135.90	6.39	0.257
135.91	6.49	0.257
135.92	6.59	0.257
135.93	6.69	0.257
135.94	6.79	0.257
135.95	6.89	0.257
135.96	6.99	0.257
135.97	7.09	0.257
135.98	7.19	0.257
135.99	7.29	0.257
136.00	7.39	0.257
136.01	7.49	0.257
136.02	7.59	0.257
136.03	7.69	0.257
136.04	7.79	0.257
136.05	7.89	0.257
136.06	7.99	0.258
136.07	8.09	0.258
136.08	8.19	0.258
136.09	8.29	0.258
136.10	8.39	0.258
136.11	8.49	0.258
136.12	8.59	0.258
136.13	8.69	0.258
136.14	8.79	0.258
136.15	8.89	0.258
136.16	8.99	0.258
136.17	9.10	0.258
136.18	9.20	0.258
136.19	9.29	0.258
136.20	9.39	0.258
136.21	9.49	0.258
136.22	9.60	0.258
136.23	9.70	0.258
136.24	9.80	0.258
136.25	9.90	0.258
136.26	10.00	0.258
136.27	10.09	0.258
136.28	10.20	0.258
136.29	10.30	0.258
136.30	10.40	0.258
136.31	10.50	0.258
136.32	10.60	0.258
136.33	10.70	0.258
136.34	10.80	0.258
136.35	10.90	0.258
136.36	11.00	0.259
136.37	11.10	0.258
136.38	11.20	0.259
136.39	11.30	0.259
136.40	11.40	0.259
136.41	11.50	0.259
136.42	11.60	0.259
136.43	11.70	0.259
136.44	11.80	0.259
136.45	11.90	0.259
136.46	12.00	0.259
136.47	12.10	0.259
136.48	12.20	0.259
136.49	12.30	0.259
136.50	12.40	0.259
136.51	12.50	0.259
136.52	12.60	0.259
136.53	12.70	0.259
136.54	12.80	0.259
136.55	12.90	0.259
136.56	13.00	0.259
136.57	13.10	0.259
136.58	13.20	0.259
136.59	13.30	0.259
136.60	13.40	0.259
136.61	13.50	0.259
136.62	13.60	0.259
136.63	13.70	0.259
136.64	13.80	0.259
136.65	13.90	0.259
136.66	14.00	0.259
136.67	14.10	0.259
136.68	14.20	0.259
136.69	14.30	0.259
136.70	14.40	0.259
136.71	14.50	0.260
136.72	14.60	0.260
136.73	14.70	0.260
136.74	14.80	0.260
136.75	14.90	0.260
136.76	15.00	0.260
136.77	15.10	0.260
136.78	15.20	0.260
136.79	15.30	0.260
136.80	15.40	0.260
136.81	15.50	0.260
136.82	15.60	0.260
136.83	15.70	0.260
136.84	15.80	0.260
136.85	15.90	0.260
136.86	16.01	0.260
136.87	16.11	0.260
136.88	16.20	0.260
136.89	16.30	0.260
136.90	16.40	0.260
136.91	16.50	0.260
136.92	16.60	0.260
136.93	16.70	0.260
136.94	16.81	0.260
136.95	16.91	0.260
136.96	17.01	0.260
136.97	17.11	0.260
136.98	17.21	0.260
136.99	17.31	0.260
137.00	17.41	0.260
137.01	17.51	0.260
137.02	17.61	0.260
137.03	17.71	0.260
137.04	17.81	0.260
137.05	17.91	0.260
137.06	18.01	0.260
137.07	18.11	0.260
137.08	18.21	0.260
137.09	18.31	0.260
137.10	18.41	0.260
137.11	18.51	0.260
137.12	18.61	0.260
137.13	18.71	0.260
137.14	18.81	0.260
137.15	18.91	0.260
137.16	19.01	0.260
137.17	19.11	0.260
137.18	19.21	0.261
137.19	19.31	0.261
137.20	19.41	0.261
137.21	19.51	0.261
137.22	19.61	0.261
137.23	19.71	0.261
137.24	19.81	0.261
137.25	19.91	0.261
137.26	20.01	0.261
137.27	20.11	0.261
137.28	20.21	0.261
137.29	20.31	0.261
137.30	20.41	0.261
137.31	20.51	0.261
137.32	20.61	0.261
137.33	20.71	0.261
137.34	20.81	0.261
137.35	20.91	0.261
137.36	21.01	0.261
137.37	21.11	0.261
137.38	21.21	0.261
137.39	21.31	0.261
137.40	21.41	0.261
137.41	21.51	0.261
137.42	21.61	0.261
137.43	21.71	0.261
137.44	21.81	0.261
137.45	21.91	0.262
137.46	22.01	0.262
137.47	22.11	0.262
137.48	22.21	0.262
137.49	22.31	0.262
137.50	22.41	0.262
137.51	22.51	0.262
137.52	22.61	0.262
137.53	22.71	0.262
137.54	22.81	0.262
137.55	22.91	0.262
137.56	23.01	0.262
137.57	23.11	0.262
137.58	23.21	0.262
137.59	23.31	0.262
137.60	23.41	0.262
137.61	23.51	0.262
137.62	23.61	0.263
137.63	23.71	0.263
137.64	23.81	0.263
137.65	23.91	0.263
137.66	24.01	0.263
137.67	24.11	0.263
137.68	24.21	0.263
137.69	24.31	0.263
137.70	24.41	0.263
137.71	24.51	0.263
137.72	24.61	0.263
137.73	24.71	0.263
137.74	24.81	0.263
137.75	24.91	0.263
137.76	25.01	0.263
137.77	25.11	0.263
137.78	25.21	0.263
137.79	25.32	0.263
137.80	25.41	0.263
137.81	25.51	0.263
137.82	25.62	0.264
137.83	25.72	0.264
137.84	25.82	0.264
137.85	25.92	0.264
137.86	26.02	0.264
137.87	26.12	0.264
137.88	26.22	0.264
137.89	26.32	0.264
137.90	26.42	0.264
137.91	26.52	0.264
137.92	26.62	0.264
137.93	26.72	0.264
137.94	26.82	0.264
137.95	26.92	0.264
137.96	27.02	0.264
137.97	27.12	0.264
137.98	27.22	0.265
137.99	27.32	0.265
138.00	27.42	0.265
138.01	27.52	0.265
138.02	27.62	0.265
138.03	27.72	0.265
138.04	27.82	0.265
138.05	27.92	0.265
138.06	28.02	0.265
138.07	28.12	0.265
138.08	28.22	0.265
138.09	28.32	0.266
138.10	28.42	0.266
138.11	28.52	0.266
138.12	28.62	0.266
138.13	28.72	0.266
138.14	28.82	0.266
138.15	28.92	0.266
138.16	29.02	0.266
138.17	29.12	0.266
138.18	29.22	0.266
138.19	29.32	0.267
138.20	29.42	0.267
138.21	29.52	0.267
138.22	29.62	0.267
138.23	29.72	0.267
138.24	29.82	0.267
138.25	29.92	0.267
138.26	30.02	0.267
138.27	30.12	0.267
138.28	30.22	0.267
138.29	30.32	0.268
138.30	30.42	0.268
138.31	30.52	0.268
138.32	30.62	0.268
138.33	30.72	0.268
138.34	30.82	0.268
138.35	30.92	0.268
138.36	31.02	0.268
138.37	31.12	0.268
138.38	31.22	0.268
138.39	31.32	0.268
138.40	31.42	0.269
138.41	31.52	0.269
138.42	31.62	0.269
138.43	31.72	0.269
138.44	31.82	0.269
138.45	31.92	0.269
138.46	32.02	0.269
138.47	32.12	0.269
138.48	32.22	0.269
138.49	32.32	0.270
138.50	32.42	0.270
138.51	32.52	0.270
138.52	32.62	0.270
138.53	32.72	0.270
138.54	32.82	0.270
138.55	32.92	0.270
138.56	33.02	0.270
138.57	33.12	0.270
138.58	33.22	0.270
138.59	33.32	0.270
138.60	33.42	0.270
138.61	33.52	0.271
138.62	33.62	0.271
138.63	33.72	0.271
138.64	33.82	0.271
138.65	33.92	0.271
138.66	34.02	0.271
138.67	34.12	0.271
138.68	34.22	0.271
138.69	34.32	0.271
138.70	34.43	0.271
138.71	34.52	0.271
138.72	34.63	0.271
138.73	34.72	0.272
138.74	34.83	0.272
138.75	34.93	0.272
138.76	35.03	0.272
138.77	35.13	0.272
138.78	35.23	0.272
138.79	35.33	0.272
138.80	35.43	0.272
138.81	35.53	0.272
138.82	35.63	0.272
138.83	35.72	0.272
138.84	35.83	0.272
138.85	35.93	0.272
138.86	36.03	0.273
138.87	36.13	0.272
138.88	36.23	0.273
138.89	36.33	0.273
138.90	36.43	0.273
138.91	36.53	0.273
138.92	36.63	0.273
138.93	36.73	0.273
138.94	36.83	0.273
138.95	36.93	0.273
138.96	37.03	0.273
138.97	37.13	0.273
138.98	37.23	0.273
138.99	37.33	0.273
139.00	37.43	0.273
139.01	37.53	0.274
139.02	37.63	0.274
139.03	37.73	0.274
139.04	37.83	0.274
139.05	37.93	0.274
139.06	38.03	0.274
139.07	38.13	0.274
139.08	38.23	0.274
139.09	38.33	0.274
139.10	38.43	0.274
139.11	38.53	0.274
139.12	38.63	0.275
139.13	38.73	0.275
139.14	38.83	0.275
139.15	38.93	0.275
139.16	39.03	0.275
139.17	39.13	0.275
139.18	39.23	0.275
139.19	39.33	0.275
139.20	39.43	0.275
139.21	39.53	0.275
139.22	39.63	0.275
139.23	39.73	0.275
139.24	39.83	0.275
139.25	39.93	0.276
139.26	40.03	0.276
139.27	40.13	0.276
139.28	40.23	0.276
139.29	40.33	0.276
139.30	40.43	0.276
139.31	40.53	0.276
139.32	40.63	0.276
139.33	40.73	0.276
139.34	40.83	0.276
139.35	40.93	0.276
139.36	41.03	0.276
139.37	41.13	0.276
139.38	41.23	0.276
139.39	41.33	0.276
139.40	41.43	0.276
139.41	41.53	0.276
139.42	41.63	0.276
139.43	41.73	0.276
139.44	41.83	0.277
139.45	41.93	0.277
139.46	42.03	0.277
139.47	42.13	0.277
139.48	42.23	0.277
139.49	42.34	0.277
139.50	42.43	0.277
139.51	42.53	0.277
139.52	42.64	0.277
139.53	42.74	0.277
139.54	42.84	0.277
139.55	42.94	0.277
139.56	43.03	0.277
139.57	43.13	0.277
139.58	43.24	0.277
139.59	43.34	0.277
139.60	43.44	0.277
139.61	43.54	0.277
139.62	43.64	0.278
139.63	43.74	0.278
139.64	43.84	0.278
139.65	43.94	0.278
139.66	44.04	0.278
139.67	44.14	0.278
139.68	44.24	0.278
139.69	44.34	0.278
139.70	44.44	0.278
139.71	44.54	0.278
139.72	44.64	0.278
139.73	44.74	0.278
139.74	44.84	0.279
139.75	44.94	0.279
139.76	45.04	0.279
139.77	45.14	0.279
139.78	45.24	0.279
139.79	45.34	0.279
139.80	45.44	0.279
139.81	45.54	0.279
139.82	45.64	0.279
139.83	45.74	0.279
139.84	45.84	0.279
139.85	45.94	0.279
139.86	46.04	0.279
139.87	46.14	0.279
139.88	46.24	0.280
139.89	46.34	0.280
139.90	46.44	0.280
139.91	46.54	0.280
139.92	46.64	0.280
139.93	46.74	0.280
139.94	46.84	0.280
139.95	46.94	0.280
139.96	47.04	0.280
139.97	47.14	0.280
139.98	47.24	0.280
139.99	47.34	0.280
140.00	47.44	0.280
140.01	47.54	0.280
140.02	47.64	0.280
140.03	47.74	0.280
140.04	47.84	0.280
140.05	47.94	0.280
140.06	48.04	0.281
140.07	48.14	0.281
140.08	48.24	0.281
140.09	48.34	0.281
140.10	48.44	0.281
140.11	48.54	0.281
140.12	48.64	0.281
140.13	48.74	0.281
140.14	48.84	0.281
140.15	48.94	0.281
140.16	49.04	0.281
140.17	49.14	0.281
140.18	49.24	0.281
140.19	49.34	0.281
140.20	49.44	0.281
140.21	49.54	0.282
140.22	49.64	0.282
140.23	49.74	0.282
140.24	49.84	0.282
140.25	49.94	0.282
140.26	50.04	0.282
140.27	50.14	0.282
140.28	50.24	0.282
140.29	50.34	0.282
140.30	50.44	0.282
140.31	50.54	0.282
140.32	50.64	0.282
140.33	50.74	0.282
140.34	50.85	0.282
140.35	50.94	0.282
140.36	51.04	0.282
140.37	51.14	0.283
140.38	51.24	0.283
140.39	51.34	0.283
140.40	51.45	0.283
140.41	51.54	0.283
140.42	51.64	0.283
140.43	51.74	0.283
140.44	51.85	0.283
140.45	51.95	0.283
140.46	52.04	0.283
140.47	52.14	0.283
140.48	52.24	0.283
140.49	52.35	0.283
140.50	52.45	0.283
140.51	52.55	0.283
140.52	52.65	0.284
140.53	52.75	0.283
140.54	52.85	0.284
140.55	52.95	0.284
140.56	53.05	0.284
140.57	53.15	0.284
140.58	53.25	0.284
140.59	53.35	0.284
140.60	53.45	0.284
140.61	53.55	0.284
140.62	53.65	0.284
140.63	53.75	0.284
140.64	53.85	0.284
140.65	53.95	0.284
140.66	54.05	0.284
140.67	54.15	0.284
140.68	54.25	0.285
140.69	54.35	0.285
140.70	54.45	0.285
140.71	54.55	0.285
140.72	54.65	0.285
140.73	54.75	0.285
140.74	54.85	0.285
140.75	54.95	0.285
140.76	55.05	0.285
140.77	55.15	0.285
140.78	55.25	0.285
140.79	55.35	0.285
140.80	55.45	0.285
140.81	55.55	0.285
140.82	55.65	0.285
140.83	55.75	0.285
140.84	55.85	0.285
140.85	55.95	0.286
140.86	56.05	0.286
140.87	56.15	0.286
140.88	56.25	0.286
140.89	56.35	0.286
140.90	56.45	0.286
140.91	56.55	0.286
140.92	56.65	0.286
140.93	56.75	0.286
140.94	56.85	0.286
140.95	56.95	0.286
140.96	57.05	0.286
140.97	57.15	0.286
140.98	57.25	0.286
140.99	57.35	0.286
141.00	57.45	0.286
141.01	57.55	0.286
141.02	57.65	0.287
141.03	57.75	0.287
141.04	57.85	0.287
141.05	57.95	0.287
141.06	58.05	0.287
141.07	58.15	0.287
141.08	58.25	0.287
141.09	58.35	0.287
141.10	58.45	0.287
141.11	58.55	0.287
141.12	58.65	0.287
141.13	58.75	0.287
141.14	58.85	0.287
141.15	58.95	0.287
141.16	59.05	0.287
141.17	59.15	0.287
141.18	59.25	0.287
141.19	59.35	0.287
141.20	59.45	0.287
141.21	59.55	0.287
141.22	59.65	0.287
141.23	59.75	0.288
141.24	59.85	0.288
141.25	59.95	0.288
141.26	60.05	0.288
141.27	60.15	0.288
141.28	60.25	0.288
141.29	60.35	0.288
141.30	60.45	0.288
141.31	60.55	0.288
141.32	60.65	0.288
141.33	60.76	0.288
141.34	60.86	0.288
141.35	60.95	0.288
141.36	61.05	0.288
141.37	61.16	0.288
141.38	61.25	0.288
141.39	61.35	0.288
141.40	61.46	0.288
141.41	61.56	0.288
141.42	61.66	0.289
141.43	61.75	0.289
141.44	61.86	0.289
141.45	61.96	0.289
141.46	62.06	0.289
141.47	62.16	0.289
141.48	62.26	0.289
141.49	62.36	0.289
141.50	62.46	0.289
141.51	62.55	0.289
141.52	62.66	0.289
141.53	62.76	0.289
141.54	62.86	0.289
141.55	62.96	0.289
141.56	63.06	0.290
141.57	63.16	0.290
141.58	63.26	0.290
141.59	63.36	0.290
141.60	63.46	0.290
141.61	63.56	0.290
141.62	63.66	0.290
141.63	63.76	0.290
141.64	63.86	0.290
141.65	63.96	0.290
141.66	64.06	0.290
141.67	64.16	0.290
141.68	64.26	0.290
141.69	64.36	0.290
141.70	64.46	0.290
141.71	64.56	0.290
141.72	64.66	0.290
141.73	64.76	0.290
141.74	64.86	0.290
141.75	64.96	0.290
141.76	65.06	0.291
141.77	65.16	0.291
141.78	65.26	0.291
141.79	65.36	0.291
141.80	65.46	0.291
141.81	65.56	0.291
141.82	65.66	0.291
141.83	65.76	0.291
141.84	65.86	0.291
141.85	65.96	0.291
141.86	66.06	0.291
141.87	66.16	0.291
141.88	66.26	0.291
141.89	66.36	0.291
141.90	66.46	0.291
141.91	66.56	0.292
141.92	66.66	0.292
141.93	66.76	0.292
141.94	66.86	0.292
141.95	66.96	0.292
141.96	67.06	0.292
141.97	67.16	0.292
141.98	67.26	0.292
141.99	67.36	0.292
142.00	67.46	0.292
142.01	67.56	0.292
142.02	67.66	0.292
142.03	67.76	0.292
142.04	67.86	0.292
142.05	67.96	0.292
142.06	68.06	0.292
142.07	68.16	0.292
142.08	68.26	0.292
142.09	68.36	0.292
142.10	68.46	0.292
142.11	68.56	0.292
142.12	68.66	0.292
142.13	68.76	0.293
142.14	68.86	0.293
142.15	68.96	0.293
142.16	69.06	0.293
142.17	69.16	0.293
142.18	69.26	0.293
142.19	69.36	0.293
142.20	69.46	0.293
142.21	69.56	0.293
142.22	69.66	0.293
142.23	69.76	0.293
142.24	69.86	0.293
142.25	69.96	0.293
142.26	70.06	0.293
142.27	70.16	0.293
142.28	70.26	0.293
142.29	70.36	0.293
142.30	70.46	0.293
142.31	70.56	0.293
142.32	70.66	0.293
142.33	70.76	0.293
142.34	70.87	0.294
142.35	70.97	0.294
142.36	71.06	0.294
142.37	71.16	0.294
142.38	71.26	0.294
142.39	71.37	0.294
142.40	71.47	0.294
142.41	71.57	0.294
142.42	71.67	0.294
142.43	71.77	0.294
142.44	71.87	0.294
142.45	71.97	0.294
142.46	72.06	0.294
142.47	72.17	0.294
142.48	72.27	0.294
142.49	72.37	0.294
142.50	72.47	0.294
142.51	72.57	0.294
142.52	72.67	0.294
142.53	72.77	0.294
142.54	72.87	0.294
142.55	72.97	0.295
142.56	73.07	0.295
142.57	73.17	0.295
142.58	73.27	0.295
142.59	73.37	0.295
142.60	73.47	0.295
142.61	73.57	0.295
142.62	73.67	0.295
142.63	73.77	0.295
142.64	73.87	0.295
142.65	73.97	0.295
142.66	74.07	0.295
142.67	74.17	0.295
142.68	74.27	0.295
142.69	74.37	0.295
142.70	74.47	0.295
142.71	74.57	0.295
142.72	74.67	0.295
142.73	74.77	0.295
142.74	74.87	0.295
142.75	74.97	0.295
142.76	75.07	0.296
142.77	75.17	0.296
142.78	75.27	0.296
142.79	75.37	0.296
142.80	75.47	0.296
142.81	75.57	0.296
142.82	75.67	0.296
142.83	75.77	0.296
142.84	75.87	0.296
142.85	75.97	0.296
142.86	76.07	0.296
142.87	76.17	0.296
142.88	76.27	0.296
142.89	76.37	0.296
142.90	76.47	0.296
142.91	76.57	0.296
142.92	76.67	0.296
142.93	76.77	0.296
142.94	76.87	0.296
142.95	76.97	0.296
142.96	77.07	0.296
142.97	77.17	0.296
142.98	77.27	0.297
142.99	77.37	0.297
143.00	77.47	0.297
143.01	77.57	0.297
143.02	77.67	0.297
143.03	77.77	0.297
143.04	77.87	0.297
143.05	77.97
143.06	78.07
143.07	78.17
143.08	78.27
143.09	78.37
143.10