File: DSC/2023_04_21_CBD_Xtal_Powder_Pinhole_Lid_n90C_100C_10Cmin.txt
Filename	2023_04_21_CBD_Xtal_Powder_Pinhole_Lid_n90C_100C_10Cmin
Instrument name	DSC2A-00468 (192.168.1.100)
Operator	JLY
rundate	4/21/2023
Sample name	2023_04_21_CBD_Xtal_Powder_Pinhole_Lid_n90C_100C_10Cmin
proceduresegments	Data Off ; Equilibrate -90.00 °C; Data On ; Ramp 10.00 °C/min to 100.00 °C; Data Off ; Isothermal 0.1 min; Data On ; Ramp 10.00 °C/min to -90.00 °C; Data Off ; Isothermal 0.1 min; Data On ; Ramp 10.00 °C/min to 100.00 °C
[File Parameters]
Run date	4/21/2023 6:01:27 PM
Trios version	5.1.1.46572
Original File Name
Current File Name	C:\Users\yargerlab\Desktop\DSC Data\General\2023_04_21_CBD_Xtal_Powder_Pinhole_Lid_n90C_100C_10Cmin.tri
[Procedure]
Procedure Name	DSC n90C to 100C at 10Cmin 2cycle.
Sample Name	2023_04_21_CBD_Xtal_Powder_Pinhole_Lid_n90C_100C_10Cmin
Sample Mass	3.76 mg
Reference Sample Mass	0 mg
Pan Mass	51.31 mg
Pan Number	41
Reference Pan Mass	51.13 mg
Reference Pan Number	37
Pan Type	Tzero Aluminum Pin Hole Hermetic
Comments	Alod Al pan with Pinhole Tzero Lid, Hermetically Sealed - CBD Crystalline Powder Std.
Project Name	CA
Operator	JLY
Test	Custom
Unload Max Temperature	30
Unload Min Temperature	30
Load Max Temperature	30
Load Min Temperature	30
Stop on Gas Flow Error	Yes
[Signal List]
Signal #1	Time (min)
Signal #2	Temperature (°C)
Signal #3	Heat Flow (mW)
Signal #4	Delta T (µV)
Signal #5	Delta Tzero (µV)
Signal #6	Tzero Temperature (°C)
Signal #7	Cell Purge (mL/min)
Signal #8	Heater Temp (°C)
Signal #9	Power Delivered (W)
Signal #10	Reference Junction Temperature (°C)
Signal #11	Flange Temperature (°C)
Signal #12	Heat Flow Phase (rad)
Signal #13	Total Heat Capacity (J/°C)
Signal #14	Heat Capacity (J/°C)
[Configuration]
Company Name	ASU
Instrument Name	DSC2A-00468
Instrument Type	DSC2500
Serial Number	DSC2A-00468
IP	192.168.1.100
Location of Instrument	MRRC
DisplayType	Unknown
Sample Interval 	0.1 s/pt
Selected Heat Flow	T4P
Exotherm Direction	Down
Cell Serial	DRC2-00792
Lid Type	Standard
Cooler	RCS 90
Leave Cooler on at End of Sequence	On
Gas 2	Nitrogen
Gas Selected	Channel 1
Flow Rate	50 mL/min
Secondary Purge	On
Licensed Heat Flow	Heat Flow T4P
Modulation Licensed	Yes
[Versions]
Common IDD Version	1
Cortex Version	VER 2.10.2.31
Driver	5.0.0.6
GDM Version	1.0.3.3
TouchscreenVersion	1.0.0.16145
FEP Version	1.2.1.21
FEP Bootloader	2.0.0.5
AutoSampler Version	2.1.1.26
Auto Sampler Bootloader	2.0.0.5
FCM Version	1.1.0.3
FCM Bootloader	2.0.0.5
[Experiment Logs]
Experiment Log Entry # 1	Data On set to 0
Experiment Log Entry # 3	Equilibrate Segment -90 (C) Started
Experiment Log Entry # 5	Air Cool is off.
Experiment Log Entry # 7	Data On set to 1
Experiment Log Entry # 9	Ramp Segment 10 C/min to 100 Started
Experiment Log Entry # 11	Data On set to 0
Experiment Log Entry # 13	Isothermal Segment 0.1 min started
Experiment Log Entry # 15	Data On set to 1
Experiment Log Entry # 17	Ramp Segment 10 C/min to -90 Started
Experiment Log Entry # 19	Data On set to 0
Experiment Log Entry # 21	Isothermal Segment 0.1 min started
Experiment Log Entry # 23	Data On set to 1
Experiment Log Entry # 25	Ramp Segment 10 C/min to 100 Started
[Method Log]
Method Log Entry # 1	Data Off
Method Log Entry # 2	Equilibrate -90 °C
Method Log Entry # 3	Data On
Method Log Entry # 4	(Ramp 79934) Ramp 10 °C/minute to 100 °C
Method Log Entry # 5	Data Off
Method Log Entry # 6	Isothermal 0.1 minutes
Method Log Entry # 7	Data On
Method Log Entry # 8	(Ramp 79938) Ramp 10 °C/minute to -90 °C
Method Log Entry # 9	Data Off
Method Log Entry # 10	Isothermal 0.1 minutes
Method Log Entry # 11	Data On
Method Log Entry # 12	(Ramp 79942) Ramp 10 °C/minute to 100 °C
Cell Serial	DRC2-00792
[T1 Calibration]
Slope	-0.008529666
Offset	9.636258
Initial Temperature	98.23
GUID	f8bfdadc-4977-4fdf-ba6d-0ba9134940c3
[TZero Calibration]
Date Applied	11/29/2022 4:06:13 PM
Description	From -89.059 °C to 396.009 °C at 20.000°C/min
Gas Type	Nitrogen
Pan Type	None
Source Files 1	C:\Users\yargerlab\Desktop\DSC Data\General\TZero_calibration_11_29_22_2nd(2).tri
Source Files 2	C:\Users\yargerlab\Desktop\DSC Data\General\TZero_calibration_11_29_22_2nd(3).tri
Delta T Offset	13.05235
Delta T Slope	-0.007271007
Delta T0 Offset	-13.69128
Delta T0 Slope	0.06063341
[Temperature Calibration]
Date Applied	11/29/2022 7:12:28 PM
Description	From 106.590 °C to 186.590 °C at 10.000°C/min
Gas Type	Nitrogen
Pan Type	Tzero Aluminum Hermetic
Source Files 1	C:\Users\yargerlab\Desktop\DSC Data\General\Indium(6).tri
Measured 1	157.391
Known 1	156.598
[Cell Constant Calibration]
Date Applied	11/29/2022 7:12:29 PM
Description	From 106.590 °C to 186.590 °C at 10.000°C/min
Gas Type	Nitrogen
Pan Type	Tzero Aluminum Hermetic
Source Files 1	C:\Users\yargerlab\Desktop\DSC Data\General\Indium(6).tri
T4P KCell	1.006051
Onset Slope	63.26126 mW/°C
[Direct Cp Calibration]
Date Applied	11/30/2022 11:04:51 AM
Description	From -79.983 °C to 298.409 °C at 10.000°C/min
Gas Type	Nitrogen
Pan Type	Tzero Aluminum Hermetic
Source Files 1	C:\Users\yargerlab\Desktop\DSC Data\General\Sapphire_Heat_Capacity_11_30_22.tri
[Rev Cp Calibration]
Date Applied	11/30/2022 1:58:51 PM
Description	From -79.996 °C to 292.812 °C at 3.000°C/min
Gas Type	Nitrogen
Pan Type	Tzero Aluminum Hermetic
Source Files 1	C:\Users\yargerlab\Desktop\DSC Data\General\Sapphire_MDSC_Calibration_11_30_22.tri
[step]
Ramp 10.00 °C/min to 100.00 °C
Time	Temperature	Heat Flow (Normalized)
min	°C	W/g
0.00	-89.82	-0.032
0.01	-89.83	-0.031
0.03	-89.84	-0.029
0.04	-89.84	-0.025
0.05	-89.84	-0.023
0.07	-89.83	-0.022
0.08	-89.81	-0.022
0.09	-89.78	-0.024
0.11	-89.73	-0.030
0.12	-89.68	-0.032
0.13	-89.61	-0.032
0.15	-89.53	-0.022
0.16	-89.44	-0.001
0.17	-89.35	0.019
0.19	-89.26	0.039
0.20	-89.16	0.058
0.21	-89.06	0.072
0.23	-88.96	0.089
0.24	-88.85	0.099
0.25	-88.74	0.107
0.27	-88.63	0.118
0.28	-88.52	0.127
0.29	-88.40	0.136
0.31	-88.28	0.142
0.32	-88.16	0.150
0.33	-88.04	0.156
0.35	-87.92	0.162
0.36	-87.80	0.168
0.37	-87.68	0.172
0.39	-87.56	0.176
0.40	-87.43	0.178
0.41	-87.31	0.183
0.43	-87.18	0.186
0.44	-87.05	0.186
0.45	-86.93	0.189
0.47	-86.80	0.190
0.48	-86.67	0.192
0.49	-86.55	0.194
0.51	-86.42	0.195
0.52	-86.29	0.196
0.53	-86.16	0.197
0.55	-86.03	0.198
0.56	-85.91	0.198
0.57	-85.78	0.199
0.59	-85.65	0.199
0.60	-85.52	0.200
0.61	-85.39	0.200
0.63	-85.26	0.200
0.64	-85.13	0.201
0.65	-85.00	0.201
0.67	-84.87	0.201
0.68	-84.74	0.202
0.69	-84.61	0.202
0.71	-84.48	0.202
0.72	-84.35	0.203
0.73	-84.22	0.203
0.75	-84.09	0.203
0.76	-83.96	0.203
0.77	-83.83	0.204
0.79	-83.70	0.204
0.80	-83.57	0.204
0.81	-83.44	0.204
0.83	-83.31	0.204
0.84	-83.18	0.204
0.85	-83.05	0.205
0.87	-82.91	0.205
0.88	-82.78	0.205
0.89	-82.65	0.205
0.91	-82.52	0.205
0.92	-82.39	0.205
0.93	-82.26	0.205
0.95	-82.13	0.205
0.96	-82.00	0.206
0.97	-81.86	0.206
0.99	-81.73	0.206
1.00	-81.60	0.206
1.01	-81.47	0.206
1.03	-81.34	0.206
1.04	-81.21	0.206
1.05	-81.08	0.206
1.07	-80.94	0.206
1.08	-80.81	0.206
1.09	-80.68	0.206
1.11	-80.55	0.206
1.12	-80.42	0.206
1.13	-80.28	0.206
1.15	-80.15	0.206
1.16	-80.02	0.206
1.17	-79.89	0.206
1.19	-79.76	0.206
1.20	-79.62	0.206
1.21	-79.49	0.206
1.23	-79.36	0.206
1.24	-79.23	0.206
1.25	-79.10	0.206
1.27	-78.96	0.205
1.28	-78.83	0.205
1.29	-78.70	0.205
1.31	-78.57	0.205
1.32	-78.43	0.205
1.33	-78.30	0.205
1.35	-78.17	0.205
1.36	-78.04	0.205
1.37	-77.91	0.205
1.39	-77.77	0.205
1.40	-77.64	0.205
1.41	-77.51	0.205
1.43	-77.38	0.205
1.44	-77.24	0.205
1.45	-77.11	0.204
1.47	-76.98	0.204
1.48	-76.85	0.204
1.49	-76.71	0.204
1.51	-76.58	0.204
1.52	-76.45	0.204
1.53	-76.32	0.204
1.55	-76.18	0.204
1.56	-76.05	0.204
1.57	-75.92	0.204
1.59	-75.79	0.204
1.60	-75.65	0.203
1.61	-75.52	0.203
1.63	-75.39	0.203
1.64	-75.25	0.203
1.65	-75.12	0.203
1.67	-74.99	0.203
1.68	-74.86	0.203
1.69	-74.72	0.203
1.71	-74.59	0.203
1.72	-74.46	0.203
1.73	-74.33	0.203
1.75	-74.19	0.203
1.76	-74.06	0.203
1.77	-73.93	0.203
1.79	-73.79	0.202
1.80	-73.66	0.202
1.81	-73.53	0.202
1.83	-73.39	0.202
1.84	-73.26	0.202
1.85	-73.13	0.202
1.87	-73.00	0.202
1.88	-72.86	0.202
1.89	-72.73	0.202
1.91	-72.60	0.202
1.92	-72.47	0.202
1.93	-72.33	0.202
1.95	-72.20	0.202
1.96	-72.06	0.202
1.97	-71.93	0.202
1.99	-71.80	0.202
2.00	-71.67	0.202
2.01	-71.53	0.202
2.03	-71.40	0.202
2.04	-71.27	0.202
2.05	-71.14	0.202
2.07	-71.00	0.202
2.08	-70.87	0.202
2.09	-70.74	0.202
2.11	-70.60	0.202
2.12	-70.47	0.202
2.13	-70.34	0.202
2.15	-70.20	0.202
2.16	-70.07	0.202
2.17	-69.94	0.202
2.19	-69.80	0.202
2.20	-69.67	0.202
2.21	-69.54	0.202
2.23	-69.41	0.202
2.24	-69.27	0.202
2.25	-69.14	0.202
2.27	-69.01	0.203
2.28	-68.87	0.203
2.29	-68.74	0.203
2.31	-68.61	0.203
2.32	-68.48	0.203
2.33	-68.34	0.203
2.35	-68.21	0.203
2.36	-68.08	0.203
2.37	-67.94	0.203
2.39	-67.81	0.203
2.40	-67.68	0.203
2.41	-67.54	0.203
2.43	-67.41	0.203
2.44	-67.28	0.203
2.45	-67.14	0.203
2.47	-67.01	0.203
2.48	-66.88	0.203
2.49	-66.75	0.203
2.51	-66.61	0.204
2.52	-66.48	0.204
2.53	-66.35	0.204
2.55	-66.21	0.204
2.56	-66.08	0.204
2.57	-65.95	0.204
2.59	-65.82	0.204
2.60	-65.68	0.204
2.61	-65.55	0.204
2.63	-65.42	0.204
2.64	-65.28	0.204
2.65	-65.15	0.204
2.67	-65.02	0.204
2.68	-64.88	0.204
2.69	-64.75	0.204
2.71	-64.62	0.204
2.72	-64.49	0.204
2.73	-64.35	0.204
2.75	-64.22	0.204
2.76	-64.09	0.205
2.77	-63.95	0.205
2.79	-63.82	0.205
2.80	-63.69	0.205
2.81	-63.55	0.205
2.83	-63.42	0.205
2.84	-63.29	0.205
2.85	-63.15	0.205
2.87	-63.02	0.205
2.88	-62.89	0.205
2.89	-62.76	0.205
2.91	-62.62	0.205
2.92	-62.49	0.205
2.93	-62.36	0.205
2.95	-62.22	0.205
2.96	-62.09	0.205
2.97	-61.96	0.205
2.99	-61.82	0.206
3.00	-61.69	0.206
3.01	-61.56	0.206
3.03	-61.42	0.206
3.04	-61.29	0.206
3.05	-61.16	0.206
3.07	-61.03	0.206
3.08	-60.89	0.206
3.09	-60.76	0.206
3.11	-60.63	0.206
3.12	-60.49	0.206
3.13	-60.36	0.206
3.15	-60.23	0.206
3.16	-60.09	0.206
3.17	-59.96	0.206
3.19	-59.83	0.207
3.20	-59.69	0.207
3.21	-59.56	0.207
3.23	-59.43	0.207
3.24	-59.30	0.207
3.25	-59.16	0.207
3.27	-59.03	0.207
3.28	-58.90	0.207
3.29	-58.76	0.207
3.31	-58.63	0.207
3.32	-58.50	0.207
3.33	-58.36	0.208
3.35	-58.23	0.208
3.36	-58.09	0.208
3.37	-57.96	0.208
3.39	-57.83	0.208
3.40	-57.70	0.208
3.41	-57.56	0.208
3.43	-57.43	0.208
3.44	-57.30	0.208
3.45	-57.16	0.208
3.47	-57.03	0.208
3.48	-56.90	0.208
3.49	-56.76	0.208
3.51	-56.63	0.209
3.52	-56.49	0.209
3.53	-56.36	0.209
3.55	-56.23	0.209
3.56	-56.10	0.209
3.57	-55.96	0.209
3.59	-55.83	0.209
3.60	-55.69	0.209
3.61	-55.56	0.209
3.63	-55.43	0.209
3.64	-55.29	0.209
3.65	-55.16	0.210
3.67	-55.03	0.210
3.68	-54.89	0.210
3.69	-54.76	0.210
3.71	-54.63	0.210
3.72	-54.49	0.210
3.73	-54.36	0.210
3.75	-54.22	0.210
3.76	-54.09	0.210
3.77	-53.96	0.210
3.79	-53.82	0.211
3.80	-53.69	0.211
3.81	-53.56	0.211
3.83	-53.42	0.211
3.84	-53.29	0.211
3.85	-53.16	0.211
3.87	-53.02	0.211
3.88	-52.89	0.211
3.89	-52.76	0.211
3.91	-52.62	0.211
3.92	-52.49	0.212
3.93	-52.36	0.212
3.95	-52.22	0.212
3.96	-52.09	0.212
3.97	-51.95	0.212
3.99	-51.82	0.212
4.00	-51.69	0.212
4.01	-51.55	0.212
4.03	-51.42	0.212
4.04	-51.29	0.212
4.05	-51.15	0.212
4.07	-51.02	0.212
4.08	-50.89	0.212
4.09	-50.75	0.213
4.11	-50.62	0.213
4.12	-50.49	0.213
4.13	-50.35	0.213
4.15	-50.22	0.213
4.16	-50.09	0.213
4.17	-49.95	0.213
4.19	-49.82	0.213
4.20	-49.69	0.213
4.21	-49.55	0.213
4.23	-49.42	0.213
4.24	-49.28	0.213
4.25	-49.15	0.213
4.27	-49.01	0.214
4.28	-48.88	0.214
4.29	-48.75	0.214
4.31	-48.61	0.214
4.32	-48.48	0.214
4.33	-48.35	0.214
4.35	-48.21	0.214
4.36	-48.08	0.214
4.37	-47.95	0.214
4.39	-47.81	0.214
4.40	-47.68	0.214
4.41	-47.55	0.214
4.43	-47.41	0.214
4.44	-47.28	0.215
4.45	-47.15	0.215
4.47	-47.01	0.215
4.48	-46.88	0.215
4.49	-46.75	0.215
4.51	-46.61	0.215
4.52	-46.48	0.215
4.53	-46.34	0.215
4.55	-46.21	0.215
4.56	-46.08	0.215
4.57	-45.94	0.215
4.59	-45.81	0.215
4.60	-45.68	0.215
4.61	-45.54	0.215
4.63	-45.41	0.215
4.64	-45.28	0.216
4.65	-45.14	0.216
4.67	-45.01	0.216
4.68	-44.88	0.216
4.69	-44.74	0.216
4.71	-44.61	0.216
4.72	-44.48	0.216
4.73	-44.34	0.216
4.75	-44.21	0.216
4.76	-44.08	0.216
4.77	-43.94	0.216
4.79	-43.81	0.216
4.80	-43.68	0.216
4.81	-43.54	0.216
4.83	-43.41	0.216
4.84	-43.28	0.216
4.85	-43.14	0.216
4.87	-43.01	0.216
4.88	-42.88	0.216
4.89	-42.74	0.216
4.91	-42.61	0.217
4.92	-42.48	0.217
4.93	-42.34	0.217
4.95	-42.21	0.217
4.96	-42.08	0.217
4.97	-41.94	0.217
4.99	-41.81	0.217
5.00	-41.67	0.217
5.01	-41.54	0.217
5.03	-41.41	0.217
5.04	-41.27	0.217
5.05	-41.14	0.217
5.07	-41.01	0.217
5.08	-40.87	0.217
5.09	-40.74	0.217
5.11	-40.61	0.218
5.12	-40.47	0.218
5.13	-40.34	0.218
5.15	-40.20	0.218
5.16	-40.07	0.218
5.17	-39.94	0.218
5.19	-39.80	0.218
5.20	-39.67	0.218
5.21	-39.54	0.218
5.23	-39.40	0.218
5.24	-39.27	0.218
5.25	-39.14	0.218
5.27	-39.00	0.218
5.28	-38.87	0.218
5.29	-38.74	0.218
5.31	-38.60	0.218
5.32	-38.47	0.219
5.33	-38.34	0.219
5.35	-38.20	0.219
5.36	-38.07	0.219
5.37	-37.93	0.219
5.39	-37.80	0.219
5.40	-37.67	0.219
5.41	-37.53	0.219
5.43	-37.40	0.219
5.44	-37.27	0.219
5.45	-37.13	0.219
5.47	-37.00	0.219
5.48	-36.87	0.219
5.49	-36.73	0.219
5.51	-36.60	0.219
5.52	-36.46	0.219
5.53	-36.33	0.219
5.55	-36.20	0.220
5.56	-36.06	0.220
5.57	-35.93	0.220
5.59	-35.80	0.220
5.60	-35.66	0.220
5.61	-35.53	0.220
5.63	-35.40	0.220
5.64	-35.26	0.220
5.65	-35.13	0.220
5.67	-34.99	0.220
5.68	-34.86	0.220
5.69	-34.73	0.220
5.71	-34.60	0.220
5.72	-34.46	0.220
5.73	-34.33	0.221
5.75	-34.20	0.221
5.76	-34.06	0.221
5.77	-33.93	0.221
5.79	-33.79	0.221
5.80	-33.66	0.221
5.81	-33.53	0.221
5.83	-33.39	0.221
5.84	-33.26	0.221
5.85	-33.13	0.221
5.87	-32.99	0.221
5.88	-32.86	0.221
5.89	-32.73	0.221
5.91	-32.59	0.221
5.92	-32.46	0.221
5.93	-32.33	0.222
5.95	-32.19	0.222
5.96	-32.06	0.222
5.97	-31.93	0.222
5.99	-31.79	0.222
6.00	-31.66	0.222
6.01	-31.52	0.222
6.03	-31.39	0.222
6.04	-31.26	0.222
6.05	-31.12	0.222
6.07	-30.99	0.222
6.08	-30.86	0.222
6.09	-30.72	0.222
6.11	-30.59	0.222
6.12	-30.45	0.223
6.13	-30.32	0.223
6.15	-30.19	0.223
6.16	-30.05	0.223
6.17	-29.92	0.223
6.19	-29.79	0.223
6.20	-29.65	0.223
6.21	-29.52	0.224
6.23	-29.38	0.224
6.24	-29.25	0.224
6.25	-29.12	0.224
6.27	-28.99	0.224
6.28	-28.85	0.224
6.29	-28.72	0.224
6.31	-28.58	0.224
6.32	-28.45	0.224
6.33	-28.32	0.224
6.35	-28.18	0.224
6.36	-28.05	0.224
6.37	-27.92	0.224
6.39	-27.78	0.224
6.40	-27.65	0.225
6.41	-27.52	0.225
6.43	-27.38	0.225
6.44	-27.25	0.225
6.45	-27.12	0.225
6.47	-26.98	0.225
6.48	-26.85	0.225
6.49	-26.72	0.225
6.51	-26.58	0.225
6.52	-26.45	0.225
6.53	-26.32	0.225
6.55	-26.18	0.226
6.56	-26.05	0.226
6.57	-25.92	0.226
6.59	-25.78	0.226
6.60	-25.65	0.226
6.61	-25.52	0.226
6.63	-25.38	0.226
6.64	-25.25	0.226
6.65	-25.12	0.226
6.67	-24.98	0.227
6.68	-24.85	0.227
6.69	-24.72	0.227
6.71	-24.58	0.227
6.72	-24.45	0.227
6.73	-24.32	0.227
6.75	-24.18	0.227
6.76	-24.05	0.228
6.77	-23.92	0.228
6.79	-23.78	0.228
6.80	-23.65	0.228
6.81	-23.52	0.228
6.83	-23.38	0.229
6.84	-23.25	0.229
6.85	-23.11	0.229
6.87	-22.98	0.229
6.88	-22.85	0.229
6.89	-22.72	0.230
6.91	-22.58	0.230
6.92	-22.45	0.230
6.93	-22.31	0.230
6.95	-22.18	0.230
6.96	-22.05	0.231
6.97	-21.91	0.231
6.99	-21.78	0.231
7.00	-21.65	0.231
7.01	-21.52	0.232
7.03	-21.38	0.232
7.04	-21.25	0.232
7.05	-21.12	0.232
7.07	-20.98	0.233
7.08	-20.85	0.233
7.09	-20.72	0.233
7.11	-20.58	0.233
7.12	-20.45	0.234
7.13	-20.31	0.235
7.15	-20.18	0.235
7.16	-20.05	0.235
7.17	-19.92	0.236
7.19	-19.78	0.236
7.20	-19.65	0.236
7.21	-19.52	0.237
7.23	-19.38	0.237
7.24	-19.25	0.238
7.25	-19.12	0.238
7.27	-18.98	0.238
7.28	-18.85	0.239
7.29	-18.72	0.240
7.31	-18.58	0.240
7.32	-18.45	0.240
7.33	-18.32	0.241
7.35	-18.18	0.242
7.36	-18.05	0.244
7.37	-17.92	0.245
7.39	-17.78	0.245
7.40	-17.65	0.247
7.41	-17.51	0.247
7.43	-17.38	0.248
7.44	-17.25	0.249
7.45	-17.12	0.250
7.47	-16.98	0.251
7.48	-16.85	0.252
7.49	-16.72	0.253
7.51	-16.58	0.253
7.52	-16.45	0.255
7.53	-16.32	0.256
7.55	-16.19	0.258
7.56	-16.05	0.259
7.57	-15.92	0.262
7.59	-15.78	0.263
7.60	-15.65	0.266
7.61	-15.52	0.267
7.63	-15.39	0.269
7.64	-15.25	0.272
7.65	-15.12	0.274
7.67	-14.99	0.275
7.68	-14.85	0.278
7.69	-14.72	0.280
7.71	-14.59	0.282
7.72	-14.46	0.285
7.73	-14.32	0.286
7.75	-14.19	0.289
7.76	-14.06	0.291
7.77	-13.92	0.293
7.79	-13.79	0.296
7.80	-13.66	0.299
7.81	-13.53	0.301
7.83	-13.39	0.302
7.84	-13.26	0.305
7.85	-13.13	0.306
7.87	-13.00	0.308
7.88	-12.86	0.310
7.89	-12.73	0.311
7.91	-12.60	0.312
7.92	-12.46	0.314
7.93	-12.33	0.315
7.95	-12.20	0.316
7.96	-12.06	0.316
7.97	-11.93	0.317
7.99	-11.80	0.317
8.00	-11.66	0.318
8.01	-11.53	0.318
8.03	-11.40	0.318
8.04	-11.27	0.318
8.05	-11.13	0.318
8.07	-11.00	0.318
8.08	-10.86	0.319
8.09	-10.73	0.318
8.11	-10.60	0.318
8.12	-10.46	0.318
8.13	-10.33	0.317
8.15	-10.19	0.317
8.16	-10.06	0.317
8.17	-9.93	0.316
8.19	-9.79	0.316
8.20	-9.66	0.315
8.21	-9.53	0.315
8.23	-9.39	0.314
8.24	-9.26	0.314
8.25	-9.13	0.313
8.27	-8.99	0.313
8.28	-8.86	0.313
8.29	-8.73	0.312
8.31	-8.59	0.312
8.32	-8.46	0.312
8.33	-8.33	0.311
8.35	-8.19	0.311
8.36	-8.06	0.311
8.37	-7.93	0.310
8.39	-7.79	0.310
8.40	-7.66	0.309
8.41	-7.52	0.309
8.43	-7.39	0.309
8.44	-7.26	0.309
8.45	-7.12	0.308
8.47	-6.99	0.308
8.48	-6.86	0.308
8.49	-6.72	0.308
8.51	-6.59	0.308
8.52	-6.46	0.307
8.53	-6.32	0.307
8.55	-6.19	0.307
8.56	-6.05	0.307
8.57	-5.92	0.307
8.59	-5.79	0.307
8.60	-5.65	0.307
8.61	-5.52	0.306
8.63	-5.39	0.306
8.64	-5.25	0.306
8.65	-5.12	0.306
8.67	-4.99	0.306
8.68	-4.85	0.306
8.69	-4.72	0.306
8.71	-4.59	0.306
8.72	-4.45	0.306
8.73	-4.32	0.306
8.75	-4.19	0.306
8.76	-4.05	0.306
8.77	-3.92	0.306
8.79	-3.79	0.306
8.80	-3.65	0.305
8.81	-3.52	0.305
8.83	-3.39	0.305
8.84	-3.25	0.305
8.85	-3.12	0.305
8.87	-2.98	0.305
8.88	-2.85	0.305
8.89	-2.72	0.305
8.91	-2.58	0.305
8.92	-2.45	0.305
8.93	-2.32	0.305
8.95	-2.18	0.305
8.96	-2.05	0.305
8.97	-1.92	0.305
8.99	-1.78	0.305
9.00	-1.65	0.305
9.01	-1.52	0.305
9.03	-1.38	0.305
9.04	-1.25	0.305
9.05	-1.12	0.305
9.07	-0.98	0.305
9.08	-0.85	0.305
9.09	-0.72	0.305
9.11	-0.58	0.305
9.12	-0.45	0.305
9.13	-0.31	0.305
9.15	-0.18	0.305
9.16	-0.05	0.306
9.17	0.08	0.306
9.19	0.22	0.306
9.20	0.35	0.306
9.21	0.49	0.306
9.23	0.62	0.306
9.24	0.75	0.306
9.25	0.89	0.306
9.27	1.02	0.306
9.28	1.15	0.306
9.29	1.29	0.306
9.31	1.42	0.306
9.32	1.55	0.306
9.33	1.69	0.306
9.35	1.82	0.306
9.36	1.95	0.306
9.37	2.09	0.306
9.39	2.22	0.306
9.40	2.35	0.307
9.41	2.49	0.307
9.43	2.62	0.307
9.44	2.75	0.307
9.45	2.89	0.307
9.47	3.02	0.307
9.48	3.16	0.307
9.49	3.29	0.307
9.51	3.42	0.307
9.52	3.56	0.307
9.53	3.69	0.307
9.55	3.82	0.307
9.56	3.96	0.307
9.57	4.09	0.307
9.59	4.22	0.307
9.60	4.36	0.308
9.61	4.49	0.308
9.63	4.62	0.308
9.64	4.76	0.308
9.65	4.89	0.308
9.67	5.02	0.308
9.68	5.16	0.308
9.69	5.29	0.308
9.71	5.42	0.308
9.72	5.56	0.308
9.73	5.69	0.308
9.75	5.82	0.308
9.76	5.96	0.308
9.77	6.09	0.309
9.79	6.23	0.309
9.80	6.36	0.309
9.81	6.49	0.309
9.83	6.63	0.309
9.84	6.76	0.309
9.85	6.89	0.309
9.87	7.03	0.309
9.88	7.16	0.309
9.89	7.29	0.309
9.91	7.43	0.309
9.92	7.56	0.309
9.93	7.69	0.310
9.95	7.83	0.310
9.96	7.96	0.310
9.97	8.10	0.310
9.99	8.23	0.310
10.00	8.36	0.310
10.01	8.50	0.310
10.03	8.63	0.310
10.04	8.76	0.310
10.05	8.90	0.310
10.07	9.03	0.310
10.08	9.16	0.311
10.09	9.30	0.311
10.11	9.43	0.311
10.12	9.56	0.311
10.13	9.70	0.311
10.15	9.83	0.311
10.16	9.96	0.311
10.17	10.10	0.311
10.19	10.23	0.311
10.20	10.36	0.311
10.21	10.50	0.311
10.23	10.63	0.311
10.24	10.76	0.311
10.25	10.90	0.312
10.27	11.03	0.312
10.28	11.17	0.312
10.29	11.30	0.312
10.31	11.43	0.312
10.32	11.57	0.312
10.33	11.70	0.312
10.35	11.83	0.312
10.36	11.97	0.312
10.37	12.10	0.312
10.39	12.23	0.313
10.40	12.37	0.313
10.41	12.50	0.313
10.43	12.63	0.313
10.44	12.77	0.313
10.45	12.90	0.313
10.47	13.04	0.313
10.48	13.17	0.313
10.49	13.30	0.313
10.51	13.44	0.313
10.52	13.57	0.313
10.53	13.70	0.313
10.55	13.84	0.314
10.56	13.97	0.314
10.57	14.10	0.314
10.59	14.24	0.314
10.60	14.37	0.314
10.61	14.50	0.314
10.63	14.64	0.314
10.64	14.77	0.314
10.65	14.90	0.314
10.67	15.04	0.314
10.68	15.17	0.314
10.69	15.30	0.314
10.71	15.44	0.314
10.72	15.57	0.315
10.73	15.70	0.315
10.75	15.84	0.315
10.76	15.97	0.315
10.77	16.10	0.315
10.79	16.24	0.315
10.80	16.37	0.315
10.81	16.50	0.315
10.83	16.64	0.315
10.84	16.77	0.315
10.85	16.90	0.315
10.87	17.04	0.315
10.88	17.17	0.315
10.89	17.31	0.316
10.91	17.44	0.316
10.92	17.57	0.316
10.93	17.71	0.316
10.95	17.84	0.316
10.96	17.97	0.316
10.97	18.11	0.316
10.99	18.24	0.316
11.00	18.37	0.316
11.01	18.51	0.317
11.03	18.64	0.317
11.04	18.77	0.317
11.05	18.91	0.317
11.07	19.04	0.317
11.08	19.17	0.317
11.09	19.31	0.317
11.11	19.44	0.317
11.12	19.57	0.317
11.13	19.71	0.317
11.15	19.84	0.317
11.16	19.97	0.317
11.17	20.11	0.318
11.19	20.24	0.318
11.20	20.37	0.318
11.21	20.51	0.318
11.23	20.64	0.318
11.24	20.77	0.318
11.25	20.91	0.318
11.27	21.04	0.318
11.28	21.17	0.318
11.29	21.31	0.318
11.31	21.44	0.319
11.32	21.58	0.319
11.33	21.71	0.319
11.35	21.84	0.319
11.36	21.98	0.319
11.37	22.11	0.319
11.39	22.24	0.319
11.40	22.38	0.319
11.41	22.51	0.319
11.43	22.64	0.319
11.44	22.78	0.319
11.45	22.91	0.319
11.47	23.04	0.320
11.48	23.18	0.320
11.49	23.31	0.320
11.51	23.44	0.320
11.52	23.58	0.320
11.53	23.71	0.320
11.55	23.84	0.320
11.56	23.98	0.320
11.57	24.11	0.320
11.59	24.24	0.320
11.60	24.38	0.321
11.61	24.51	0.321
11.63	24.64	0.321
11.64	24.78	0.321
11.65	24.91	0.321
11.67	25.04	0.321
11.68	25.18	0.321
11.69	25.31	0.321
11.71	25.45	0.321
11.72	25.58	0.322
11.73	25.71	0.322
11.75	25.85	0.322
11.76	25.98	0.322
11.77	26.11	0.322
11.79	26.25	0.322
11.80	26.38	0.322
11.81	26.51	0.322
11.83	26.65	0.322
11.84	26.78	0.323
11.85	26.91	0.323
11.87	27.05	0.323
11.88	27.18	0.323
11.89	27.31	0.323
11.91	27.45	0.323
11.92	27.58	0.323
11.93	27.71	0.323
11.95	27.85	0.323
11.96	27.98	0.323
11.97	28.12	0.324
11.99	28.25	0.324
12.00	28.38	0.324
12.01	28.52	0.324
12.03	28.65	0.324
12.04	28.78	0.324
12.05	28.92	0.324
12.07	29.05	0.324
12.08	29.18	0.324
12.09	29.32	0.324
12.11	29.45	0.325
12.12	29.58	0.325
12.13	29.72	0.325
12.15	29.85	0.325
12.16	29.98	0.325
12.17	30.12	0.325
12.19	30.25	0.325
12.20	30.38	0.325
12.21	30.52	0.325
12.23	30.65	0.326
12.24	30.78	0.326
12.25	30.92	0.326
12.27	31.05	0.326
12.28	31.19	0.326
12.29	31.32	0.326
12.31	31.45	0.326
12.32	31.59	0.326
12.33	31.72	0.326
12.35	31.85	0.326
12.36	31.98	0.327
12.37	32.12	0.327
12.39	32.25	0.327
12.40	32.38	0.327
12.41	32.52	0.327
12.43	32.65	0.327
12.44	32.79	0.327
12.45	32.92	0.327
12.47	33.05	0.327
12.48	33.19	0.327
12.49	33.32	0.327
12.51	33.45	0.328
12.52	33.59	0.328
12.53	33.72	0.328
12.55	33.85	0.328
12.56	33.99	0.328
12.57	34.12	0.328
12.59	34.25	0.328
12.60	34.39	0.328
12.61	34.52	0.328
12.63	34.65	0.328
12.64	34.79	0.329
12.65	34.92	0.329
12.67	35.05	0.329
12.68	35.19	0.329
12.69	35.32	0.329
12.71	35.45	0.329
12.72	35.59	0.329
12.73	35.72	0.329
12.75	35.85	0.329
12.76	35.99	0.329
12.77	36.12	0.329
12.79	36.25	0.330
12.80	36.39	0.330
12.81	36.52	0.330
12.83	36.66	0.330
12.84	36.79	0.330
12.85	36.92	0.330
12.87	37.06	0.330
12.88	37.19	0.330
12.89	37.32	0.330
12.91	37.46	0.330
12.92	37.59	0.331
12.93	37.72	0.331
12.95	37.86	0.331
12.96	37.99	0.331
12.97	38.12	0.331
12.99	38.26	0.331
13.00	38.39	0.331
13.01	38.52	0.331
13.03	38.66	0.331
13.04	38.79	0.331
13.05	38.92	0.332
13.07	39.06	0.332
13.08	39.19	0.332
13.09	39.33	0.332
13.11	39.46	0.332
13.12	39.59	0.332
13.13	39.72	0.332
13.15	39.86	0.332
13.16	39.99	0.332
13.17	40.13	0.332
13.19	40.26	0.333
13.20	40.39	0.333
13.21	40.53	0.333
13.23	40.66	0.333
13.24	40.79	0.333
13.25	40.93	0.333
13.27	41.06	0.333
13.28	41.19	0.333
13.29	41.33	0.333
13.31	41.46	0.333
13.32	41.59	0.333
13.33	41.73	0.334
13.35	41.86	0.334
13.36	41.99	0.334
13.37	42.13	0.334
13.39	42.26	0.334
13.40	42.39	0.334
13.41	42.53	0.334
13.43	42.66	0.334
13.44	42.79	0.334
13.45	42.93	0.335
13.47	43.06	0.335
13.48	43.20	0.335
13.49	43.33	0.335
13.51	43.46	0.335
13.52	43.59	0.335
13.53	43.73	0.335
13.55	43.86	0.335
13.56	43.99	0.335
13.57	44.13	0.335
13.59	44.26	0.336
13.60	44.40	0.336
13.61	44.53	0.336
13.63	44.66	0.336
13.64	44.80	0.336
13.65	44.93	0.336
13.67	45.06	0.336
13.68	45.20	0.336
13.69	45.33	0.336
13.71	45.46	0.336
13.72	45.60	0.336
13.73	45.73	0.337
13.75	45.86	0.337
13.76	46.00	0.337
13.77	46.13	0.337
13.79	46.26	0.337
13.80	46.40	0.337
13.81	46.53	0.337
13.83	46.66	0.338
13.84	46.80	0.338
13.85	46.93	0.338
13.87	47.06	0.338
13.88	47.20	0.338
13.89	47.33	0.338
13.91	47.47	0.338
13.92	47.60	0.338
13.93	47.73	0.338
13.95	47.87	0.338
13.96	48.00	0.338
13.97	48.13	0.339
13.99	48.27	0.339
14.00	48.40	0.339
14.01	48.53	0.339
14.03	48.67	0.339
14.04	48.80	0.339
14.05	48.93	0.339
14.07	49.07	0.339
14.08	49.20	0.339
14.09	49.33	0.339
14.11	49.47	0.340
14.12	49.60	0.340
14.13	49.74	0.340
14.15	49.87	0.340
14.16	50.00	0.340
14.17	50.14	0.340
14.19	50.27	0.340
14.20	50.40	0.340
14.21	50.53	0.340
14.23	50.67	0.341
14.24	50.80	0.341
14.25	50.93	0.341
14.27	51.07	0.341
14.28	51.20	0.341
14.29	51.34	0.341
14.31	51.47	0.341
14.32	51.60	0.341
14.33	51.74	0.341
14.35	51.87	0.341
14.36	52.00	0.341
14.37	52.14	0.341
14.39	52.27	0.342
14.40	52.40	0.342
14.41	52.54	0.342
14.43	52.67	0.342
14.44	52.80	0.342
14.45	52.94	0.342
14.47	53.07	0.342
14.48	53.20	0.342
14.49	53.34	0.342
14.51	53.47	0.343
14.52	53.60	0.343
14.53	53.74	0.343
14.55	53.87	0.343
14.56	54.00	0.343
14.57	54.14	0.343
14.59	54.27	0.343
14.60	54.40	0.343
14.61	54.54	0.343
14.63	54.67	0.344
14.64	54.81	0.344
14.65	54.94	0.344
14.67	55.07	0.344
14.68	55.21	0.344
14.69	55.34	0.344
14.71	55.47	0.344
14.72	55.61	0.344
14.73	55.74	0.344
14.75	55.87	0.344
14.76	56.01	0.344
14.77	56.14	0.344
14.79	56.27	0.345
14.80	56.41	0.345
14.81	56.54	0.345
14.83	56.67	0.345
14.84	56.81	0.345
14.85	56.94	0.345
14.87	57.07	0.345
14.88	57.21	0.345
14.89	57.34	0.345
14.91	57.47	0.346
14.92	57.61	0.346
14.93	57.74	0.346
14.95	57.87	0.346
14.96	58.01	0.346
14.97	58.14	0.346
14.99	58.27	0.346
15.00	58.41	0.346
15.01	58.54	0.346
15.03	58.67	0.346
15.04	58.81	0.347
15.05	58.94	0.347
15.07	59.07	0.347
15.08	59.21	0.347
15.09	59.34	0.347
15.11	59.48	0.347
15.12	59.61	0.347
15.13	59.74	0.347
15.15	59.88	0.347
15.16	60.01	0.347
15.17	60.14	0.347
15.19	60.28	0.348
15.20	60.41	0.348
15.21	60.54	0.348
15.23	60.68	0.348
15.24	60.81	0.348
15.25	60.94	0.348
15.27	61.08	0.348
15.28	61.21	0.348
15.29	61.34	0.348
15.31	61.48	0.348
15.32	61.61	0.349
15.33	61.74	0.349
15.35	61.88	0.349
15.36	62.01	0.349
15.37	62.14	0.349
15.39	62.28	0.349
15.40	62.41	0.349
15.41	62.54	0.349
15.43	62.68	0.349
15.44	62.81	0.349
15.45	62.94	0.350
15.47	63.08	0.350
15.48	63.21	0.350
15.49	63.34	0.350
15.51	63.48	0.350
15.52	63.61	0.350
15.53	63.75	0.350
15.55	63.88	0.350
15.56	64.01	0.350
15.57	64.15	0.350
15.59	64.28	0.351
15.60	64.41	0.351
15.61	64.55	0.351
15.63	64.68	0.351
15.64	64.81	0.351
15.65	64.95	0.351
15.67	65.08	0.351
15.68	65.21	0.351
15.69	65.35	0.351
15.71	65.48	0.351
15.72	65.62	0.351
15.73	65.75	0.351
15.75	65.88	0.351
15.76	66.01	0.352
15.77	66.15	0.352
15.79	66.28	0.352
15.80	66.41	0.352
15.81	66.55	0.352
15.83	66.68	0.352
15.84	66.81	0.352
15.85	66.95	0.352
15.87	67.08	0.352
15.88	67.22	0.352
15.89	67.35	0.352
15.91	67.48	0.352
15.92	67.62	0.353
15.93	67.75	0.353
15.95	67.88	0.353
15.96	68.02	0.353
15.97	68.15	0.353
15.99	68.28	0.353
16.00	68.42	0.353
16.01	68.55	0.353
16.03	68.68	0.353
16.04	68.82	0.353
16.05	68.95	0.353
16.07	69.08	0.353
16.08	69.22	0.354
16.09	69.35	0.354
16.11	69.48	0.354
16.12	69.62	0.354
16.13	69.75	0.354
16.15	69.88	0.354
16.16	70.02	0.354
16.17	70.15	0.354
16.19	70.28	0.354
16.20	70.42	0.354
16.21	70.55	0.354
16.23	70.68	0.355
16.24	70.82	0.355
16.25	70.95	0.355
16.27	71.09	0.355
16.28	71.22	0.355
16.29	71.35	0.355
16.31	71.49	0.355
16.32	71.62	0.355
16.33	71.75	0.355
16.35	71.89	0.355
16.36	72.02	0.355
16.37	72.15	0.356
16.39	72.29	0.356
16.40	72.42	0.356
16.41	72.55	0.356
16.43	72.69	0.356
16.44	72.82	0.356
16.45	72.95	0.356
16.47	73.09	0.356
16.48	73.22	0.356
16.49	73.35	0.356
16.51	73.49	0.356
16.52	73.62	0.356
16.53	73.76	0.356
16.55	73.89	0.356
16.56	74.02	0.357
16.57	74.16	0.357
16.59	74.29	0.357
16.60	74.42	0.357
16.61	74.56	0.357
16.63	74.69	0.357
16.64	74.82	0.357
16.65	74.96	0.357
16.67	75.09	0.357
16.68	75.22	0.357
16.69	75.36	0.357
16.71	75.49	0.357
16.72	75.62	0.358
16.73	75.76	0.358
16.75	75.89	0.358
16.76	76.02	0.358
16.77	76.16	0.358
16.79	76.29	0.358
16.80	76.42	0.358
16.81	76.56	0.358
16.83	76.69	0.358
16.84	76.82	0.358
16.85	76.96	0.358
16.87	77.09	0.358
16.88	77.22	0.359
16.89	77.36	0.359
16.91	77.49	0.359
16.92	77.62	0.359
16.93	77.76	0.359
16.95	77.89	0.359
16.96	78.03	0.359
16.97	78.16	0.359
16.99	78.29	0.359
17.00	78.43	0.359
17.01	78.56	0.359
17.03	78.69	0.359
17.04	78.83	0.360
17.05	78.96	0.360
17.07	79.09	0.360
17.08	79.23	0.360
17.09	79.36	0.360
17.11	79.49	0.360
17.12	79.63	0.360
17.13	79.76	0.360
17.15	79.90	0.360
17.16	80.03	0.360
17.17	80.16	0.360
17.19	80.30	0.360
17.20	80.43	0.360
17.21	80.56	0.361
17.23	80.69	0.361
17.24	80.83	0.361
17.25	80.96	0.361
17.27	81.09	0.361
17.28	81.23	0.361
17.29	81.36	0.361
17.31	81.50	0.361
17.32	81.63	0.361
17.33	81.76	0.361
17.35	81.90	0.361
17.36	82.03	0.361
17.37	82.16	0.361
17.39	82.30	0.361
17.40	82.43	0.361
17.41	82.56	0.361
17.43	82.70	0.361
17.44	82.83	0.361
17.45	82.96	0.361
17.47	83.10	0.361
17.48	83.23	0.361
17.49	83.36	0.361
17.51	83.50	0.361
17.52	83.63	0.361
17.53	83.76	0.361
17.55	83.89	0.361
17.56	84.03	0.361
17.57	84.16	0.361
17.59	84.30	0.361
17.60	84.43	0.361
17.61	84.56	0.362
17.63	84.70	0.362
17.64	84.83	0.362
17.65	84.96	0.362
17.67	85.10	0.362
17.68	85.23	0.362
17.69	85.36	0.362
17.71	85.50	0.362
17.72	85.63	0.362
17.73	85.76	0.362
17.75	85.90	0.362
17.76	86.03	0.362
17.77	86.16	0.362
17.79	86.30	0.362
17.80	86.43	0.362
17.81	86.56	0.362
17.83	86.70	0.362
17.84	86.83	0.362
17.85	86.96	0.362
17.87	87.10	0.362
17.88	87.23	0.362
17.89	87.36	0.362
17.91	87.50	0.363
17.92	87.63	0.363
17.93	87.77	0.363
17.95	87.90	0.363
17.96	88.03	0.363
17.97	88.16	0.363
17.99	88.30	0.363
18.00	88.43	0.363
18.01	88.56	0.363
18.03	88.70	0.363
18.04	88.83	0.363
18.05	88.97	0.363
18.07	89.10	0.363
18.08	89.23	0.363
18.09	89.37	0.363
18.11	89.50	0.363
18.12	89.63	0.363
18.13	89.77	0.363
18.15	89.90	0.364
18.16	90.03	0.364
18.17	90.17	0.364
18.19	90.30	0.364
18.20	90.43	0.364
18.21	90.57	0.364
18.23	90.70	0.364
18.24	90.83	0.364
18.25	90.97	0.364
18.27	91.10	0.364
18.28	91.23	0.364
18.29	91.37	0.364
18.31	91.50	0.364
18.32	91.63	0.365
18.33	91.77	0.365
18.35	91.90	0.365
18.36	92.03	0.365
18.37	92.17	0.365
18.39	92.30	0.365
18.40	92.43	0.365
18.41	92.57	0.365
18.43	92.70	0.365
18.44	92.84	0.365
18.45	92.97	0.365
18.47	93.10	0.366
18.48	93.24	0.366
18.49	93.37	0.366
18.51	93.50	0.366
18.52	93.64	0.366
18.53	93.77	0.366
18.55	93.90	0.366
18.56	94.04	0.366
18.57	94.17	0.366
18.59	94.30	0.366
18.60	94.44	0.366
18.61	94.57	0.366
18.63	94.70	0.366
18.64	94.84	0.366
18.65	94.97	0.367
18.67	95.10	0.367
18.68	95.24	0.367
18.69	95.37	0.367
18.71	95.50	0.367
18.72	95.64	0.367
18.73	95.77	0.367
18.75	95.90	0.367
18.76	96.04	0.367
18.77	96.17	0.367
18.79	96.30	0.367
18.80	96.44	0.367
18.81	96.57	0.367
18.83	96.71	0.367
18.84	96.84	0.367
18.85	96.97	0.368
18.87	97.11	0.368
18.88	97.24	0.368
18.89	97.37	0.368
18.91	97.51	0.368
18.92	97.64	0.368
18.93	97.77	0.368
18.95	97.91	0.368
18.96	98.04
18.97	98.17
18.99	98.31
19.00
19.01

[step]
Ramp 10.00 °C/min to -90.00 °C
Time	Temperature	Heat Flow (Normalized)
min	°C	W/g
19.11	99.40	0.373
19.12	99.48	0.372
19.13	99.54	0.363
19.15	99.60	0.341
19.16	99.64	0.316
19.18	99.66	0.291
19.19	99.67	0.262
19.20	99.67	0.232
19.22	99.65	0.196
19.23	99.62	0.155
19.24	99.57	0.108
19.26	99.51	0.056
19.27	99.44	0.004
19.28	99.36	-0.046
19.29	99.27	-0.091
19.31	99.18	-0.133
19.32	99.09	-0.168
19.33	98.99	-0.201
19.35	98.89	-0.225
19.36	98.78	-0.249
19.38	98.67	-0.269
19.39	98.56	-0.290
19.40	98.45	-0.304
19.42	98.33	-0.322
19.43	98.22	-0.333
19.44	98.10	-0.345
19.46	97.98	-0.355
19.47	97.86	-0.365
19.48	97.74	-0.372
19.49	97.61	-0.378
19.51	97.49	-0.387
19.52	97.37	-0.389
19.53	97.24	-0.394
19.55	97.12	-0.397
19.56	96.99	-0.403
19.58	96.86	-0.405
19.59	96.74	-0.407
19.60	96.61	-0.410
19.62	96.48	-0.412
19.63	96.35	-0.414
19.64	96.23	-0.415
19.66	96.10	-0.418
19.67	95.97	-0.418
19.68	95.84	-0.419
19.69	95.71	-0.420
19.71	95.58	-0.421
19.72	95.46	-0.421
19.73	95.33	-0.422
19.75	95.20	-0.423
19.76	95.07	-0.423
19.78	94.94	-0.424
19.79	94.81	-0.424
19.80	94.68	-0.425
19.82	94.55	-0.425
19.83	94.42	-0.426
19.84	94.29	-0.426
19.86	94.16	-0.426
19.87	94.03	-0.427
19.88	93.90	-0.427
19.89	93.77	-0.428
19.91	93.64	-0.428
19.92	93.51	-0.428
19.93	93.37	-0.429
19.95	93.24	-0.429
19.96	93.11	-0.429
19.98	92.98	-0.430
19.99	92.85	-0.430
20.00	92.72	-0.430
20.02	92.59	-0.430
20.03	92.46	-0.431
20.04	92.33	-0.431
20.06	92.19	-0.431
20.07	92.06	-0.432
20.08	91.93	-0.432
20.09	91.80	-0.432
20.11	91.67	-0.432
20.12	91.54	-0.432
20.13	91.41	-0.433
20.15	91.27	-0.433
20.16	91.14	-0.433
20.18	91.01	-0.433
20.19	90.88	-0.433
20.20	90.75	-0.433
20.22	90.62	-0.434
20.23	90.48	-0.434
20.24	90.35	-0.434
20.26	90.22	-0.434
20.27	90.09	-0.434
20.28	89.96	-0.434
20.29	89.82	-0.434
20.31	89.69	-0.434
20.32	89.56	-0.434
20.33	89.43	-0.434
20.35	89.30	-0.434
20.36	89.16	-0.434
20.38	89.03	-0.435
20.39	88.90	-0.435
20.40	88.77	-0.435
20.42	88.63	-0.435
20.43	88.50	-0.435
20.44	88.37	-0.435
20.46	88.24	-0.435
20.47	88.10	-0.435
20.48	87.97	-0.435
20.49	87.84	-0.435
20.51	87.70	-0.435
20.52	87.57	-0.435
20.53	87.44	-0.435
20.55	87.31	-0.435
20.56	87.18	-0.435
20.58	87.04	-0.435
20.59	86.91	-0.435
20.60	86.78	-0.435
20.62	86.64	-0.435
20.63	86.51	-0.435
20.64	86.38	-0.434
20.66	86.25	-0.434
20.67	86.11	-0.434
20.68	85.98	-0.434
20.69	85.85	-0.434
20.71	85.72	-0.434
20.72	85.58	-0.434
20.73	85.45	-0.434
20.75	85.32	-0.434
20.76	85.18	-0.434
20.78	85.05	-0.434
20.79	84.92	-0.434
20.80	84.79	-0.434
20.82	84.65	-0.434
20.83	84.52	-0.434
20.84	84.39	-0.434
20.86	84.26	-0.434
20.87	84.12	-0.434
20.88	83.99	-0.434
20.89	83.86	-0.433
20.91	83.72	-0.433
20.92	83.59	-0.433
20.93	83.46	-0.433
20.95	83.32	-0.433
20.96	83.19	-0.433
20.98	83.06	-0.433
20.99	82.93	-0.433
21.00	82.79	-0.433
21.02	82.66	-0.433
21.03	82.53	-0.433
21.04	82.39	-0.433
21.06	82.26	-0.433
21.07	82.13	-0.432
21.08	81.99	-0.432
21.09	81.86	-0.432
21.11	81.73	-0.432
21.12	81.60	-0.432
21.13	81.46	-0.432
21.15	81.33	-0.432
21.16	81.20	-0.432
21.18	81.07	-0.432
21.19	80.93	-0.432
21.20	80.80	-0.432
21.22	80.66	-0.431
21.23	80.53	-0.431
21.24	80.40	-0.431
21.26	80.27	-0.431
21.27	80.13	-0.431
21.28	80.00	-0.431
21.29	79.87	-0.431
21.31	79.73	-0.431
21.32	79.60	-0.431
21.33	79.47	-0.431
21.35	79.33	-0.431
21.36	79.20	-0.431
21.38	79.07	-0.431
21.39	78.94	-0.431
21.40	78.80	-0.430
21.42	78.67	-0.430
21.43	78.54	-0.430
21.44	78.40	-0.430
21.46	78.27	-0.430
21.47	78.14	-0.430
21.48	78.00	-0.430
21.49	77.87	-0.430
21.51	77.74	-0.430
21.52	77.60	-0.429
21.53	77.47	-0.429
21.55	77.34	-0.429
21.56	77.21	-0.429
21.58	77.07	-0.429
21.59	76.94	-0.429
21.60	76.81	-0.429
21.62	76.67	-0.429
21.63	76.54	-0.429
21.64	76.41	-0.428
21.66	76.27	-0.428
21.67	76.14	-0.428
21.68	76.01	-0.428
21.69	75.87	-0.428
21.71	75.74	-0.428
21.72	75.61	-0.428
21.73	75.48	-0.427
21.75	75.34	-0.427
21.76	75.21	-0.427
21.78	75.08	-0.427
21.79	74.94	-0.427
21.80	74.81	-0.427
21.82	74.68	-0.427
21.83	74.54	-0.426
21.84	74.41	-0.426
21.86	74.28	-0.426
21.87	74.14	-0.426
21.88	74.01	-0.426
21.89	73.88	-0.426
21.91	73.74	-0.425
21.92	73.61	-0.425
21.93	73.48	-0.425
21.95	73.35	-0.425
21.96	73.21	-0.425
21.98	73.08	-0.425
21.99	72.95	-0.425
22.00	72.81	-0.425
22.02	72.68	-0.424
22.03	72.55	-0.424
22.04	72.41	-0.424
22.06	72.28	-0.424
22.07	72.15	-0.424
22.08	72.01	-0.424
22.09	71.88	-0.424
22.11	71.75	-0.424
22.12	71.61	-0.423
22.13	71.48	-0.423
22.15	71.35	-0.423
22.16	71.21	-0.423
22.18	71.08	-0.423
22.19	70.95	-0.423
22.20	70.82	-0.422
22.22	70.68	-0.422
22.23	70.55	-0.422
22.24	70.42	-0.422
22.26	70.28	-0.422
22.27	70.15	-0.422
22.28	70.02	-0.421
22.29	69.88	-0.421
22.31	69.75	-0.421
22.32	69.62	-0.421
22.33	69.48	-0.421
22.35	69.35	-0.421
22.36	69.22	-0.421
22.38	69.08	-0.421
22.39	68.95	-0.420
22.40	68.82	-0.420
22.42	68.69	-0.420
22.43	68.55	-0.420
22.44	68.42	-0.420
22.46	68.29	-0.420
22.47	68.15	-0.419
22.48	68.02	-0.419
22.49	67.89	-0.419
22.51	67.75	-0.419
22.52	67.62	-0.419
22.53	67.49	-0.419
22.55	67.35	-0.419
22.56	67.22	-0.418
22.58	67.09	-0.418
22.59	66.95	-0.418
22.60	66.82	-0.418
22.62	66.69	-0.418
22.63	66.55	-0.418
22.64	66.42	-0.418
22.66	66.29	-0.418
22.67	66.15	-0.418
22.68	66.02	-0.417
22.69	65.89	-0.417
22.71	65.76	-0.417
22.72	65.62	-0.417
22.73	65.49	-0.417
22.75	65.36	-0.417
22.76	65.22	-0.416
22.78	65.09	-0.416
22.79	64.96	-0.416
22.80	64.83	-0.416
22.82	64.69	-0.416
22.83	64.56	-0.416
22.84	64.43	-0.416
22.86	64.29	-0.415
22.87	64.16	-0.415
22.88	64.03	-0.415
22.89	63.89	-0.415
22.91	63.76	-0.415
22.92	63.63	-0.415
22.93	63.49	-0.415
22.95	63.36	-0.414
22.96	63.23	-0.414
22.98	63.09	-0.414
22.99	62.96	-0.414
23.00	62.83	-0.414
23.02	62.69	-0.414
23.03	62.56	-0.414
23.04	62.43	-0.413
23.06	62.30	-0.413
23.07	62.16	-0.413
23.08	62.03	-0.413
23.09	61.90	-0.413
23.11	61.76	-0.413
23.12	61.63	-0.413
23.13	61.50	-0.413
23.15	61.36	-0.412
23.16	61.23	-0.412
23.18	61.10	-0.412
23.19	60.96	-0.412
23.20	60.83	-0.412
23.22	60.70	-0.412
23.23	60.56	-0.411
23.24	60.43	-0.411
23.26	60.30	-0.411
23.27	60.16	-0.411
23.28	60.03	-0.411
23.29	59.90	-0.411
23.31	59.77	-0.411
23.32	59.63	-0.411
23.33	59.50	-0.410
23.35	59.37	-0.410
23.36	59.23	-0.410
23.38	59.10	-0.410
23.39	58.97	-0.410
23.40	58.83	-0.410
23.42	58.70	-0.410
23.43	58.57	-0.410
23.44	58.44	-0.410
23.46	58.30	-0.410
23.47	58.17	-0.409
23.48	58.04	-0.409
23.49	57.90	-0.409
23.51	57.77	-0.409
23.52	57.64	-0.409
23.53	57.50	-0.409
23.55	57.37	-0.408
23.56	57.24	-0.408
23.58	57.10	-0.408
23.59	56.97	-0.408
23.60	56.84	-0.408
23.62	56.70	-0.408
23.63	56.57	-0.407
23.64	56.44	-0.407
23.66	56.30	-0.407
23.67	56.17	-0.407
23.68	56.04	-0.407
23.69	55.91	-0.407
23.71	55.77	-0.407
23.72	55.64	-0.406
23.73	55.51	-0.406
23.75	55.37	-0.406
23.76	55.24	-0.406
23.78	55.11	-0.406
23.79	54.97	-0.405
23.80	54.84	-0.405
23.82	54.71	-0.405
23.83	54.57	-0.405
23.84	54.44	-0.405
23.86	54.31	-0.405
23.87	54.17	-0.405
23.88	54.04	-0.405
23.89	53.91	-0.404
23.91	53.77	-0.404
23.92	53.64	-0.404
23.93	53.51	-0.404
23.95	53.37	-0.404
23.96	53.24	-0.404
23.98	53.11	-0.404
23.99	52.98	-0.403
24.00	52.84	-0.403
24.02	52.71	-0.403
24.03	52.58	-0.403
24.04	52.44	-0.403
24.06	52.31	-0.403
24.07	52.18	-0.403
24.08	52.04	-0.403
24.09	51.91	-0.402
24.11	51.78	-0.402
24.12	51.64	-0.402
24.13	51.51	-0.402
24.15	51.38	-0.402
24.16	51.24	-0.402
24.18	51.11	-0.402
24.19	50.97	-0.402
24.20	50.84	-0.402
24.22	50.71	-0.402
24.23	50.58	-0.401
24.24	50.44	-0.401
24.26	50.31	-0.401
24.27	50.18	-0.401
24.28	50.05	-0.401
24.29	49.91	-0.400
24.31	49.78	-0.400
24.32	49.65	-0.400
24.33	49.51	-0.399
24.35	49.38	-0.399
24.36	49.25	-0.399
24.38	49.11	-0.399
24.39	48.98	-0.399
24.40	48.85	-0.399
24.42	48.72	-0.399
24.43	48.58	-0.399
24.44	48.45	-0.398
24.46	48.31	-0.398
24.47	48.18	-0.398
24.48	48.05	-0.398
24.49	47.91	-0.398
24.51	47.78	-0.398
24.52	47.65	-0.398
24.53	47.51	-0.398
24.55	47.38	-0.398
24.56	47.25	-0.398
24.58	47.11	-0.398
24.59	46.98	-0.398
24.60	46.85	-0.398
24.62	46.71	-0.397
24.63	46.58	-0.397
24.64	46.45	-0.397
24.66	46.32	-0.397
24.67	46.18	-0.397
24.68	46.05	-0.396
24.69	45.92	-0.396
24.71	45.79	-0.396
24.72	45.65	-0.395
24.73	45.52	-0.395
24.75	45.39	-0.395
24.76	45.25	-0.395
24.78	45.12	-0.395
24.79	44.99	-0.395
24.80	44.85	-0.394
24.82	44.72	-0.394
24.83	44.59	-0.394
24.84	44.45	-0.394
24.86	44.32	-0.394
24.87	44.19	-0.394
24.88	44.05	-0.394
24.89	43.92	-0.394
24.91	43.78	-0.394
24.92	43.65	-0.394
24.93	43.52	-0.394
24.95	43.39	-0.394
24.96	43.25	-0.394
24.98	43.12	-0.393
24.99	42.99	-0.393
25.00	42.85	-0.393
25.02	42.72	-0.393
25.03	42.59	-0.392
25.04	42.45	-0.392
25.06	42.32	-0.392
25.07	42.19	-0.392
25.08	42.05	-0.392
25.09	41.92	-0.392
25.11	41.79	-0.392
25.12	41.65	-0.391
25.13	41.52	-0.391
25.15	41.39	-0.391
25.16	41.26	-0.391
25.18	41.12	-0.391
25.19	40.99	-0.391
25.20	40.86	-0.391
25.22	40.72	-0.390
25.23	40.59	-0.390
25.24	40.46	-0.390
25.26	40.33	-0.390
25.27	40.19	-0.389
25.28	40.06	-0.389
25.29	39.93	-0.389
25.31	39.80	-0.389
25.32	39.66	-0.388
25.33	39.53	-0.388
25.35	39.40	-0.388
25.36	39.26	-0.388
25.38	39.13	-0.388
25.39	39.00	-0.388
25.40	38.86	-0.388
25.42	38.73	-0.388
25.43	38.60	-0.388
25.44	38.46	-0.387
25.46	38.33	-0.387
25.47	38.20	-0.387
[...]
42.03	-48.96	0.214
42.04	-48.82	0.214
42.06	-48.69	0.214
42.07	-48.56	0.215
42.08	-48.42	0.215
42.09	-48.29	0.215
42.11	-48.16	0.215
42.12	-48.02	0.215
42.14	-47.89	0.215
42.15	-47.76	0.215
42.16	-47.62	0.215
42.18	-47.49	0.215
42.19	-47.36	0.215
42.20	-47.22	0.215
42.21	-47.09	0.215
42.23	-46.95	0.215
42.24	-46.82	0.215
42.26	-46.69	0.215
42.27	-46.55	0.215
42.28	-46.42	0.215
42.29	-46.29	0.216
42.31	-46.15	0.216
42.32	-46.02	0.216
42.34	-45.89	0.216
42.35	-45.75	0.216
42.36	-45.62	0.216
42.38	-45.49	0.216
42.39	-45.35	0.216
42.40	-45.22	0.216
42.41	-45.09	0.216
42.43	-44.95	0.216
42.44	-44.82	0.216
42.46	-44.68	0.216
42.47	-44.55	0.216
42.48	-44.42	0.216
42.49	-44.28	0.216
42.51	-44.15	0.217
42.52	-44.02	0.217
42.54	-43.88	0.217
42.55	-43.75	0.217
42.56	-43.62	0.217
42.58	-43.48	0.217
42.59	-43.35	0.217
42.60	-43.21	0.217
42.61	-43.08	0.217
42.63	-42.95	0.217
42.64	-42.81	0.217
42.66	-42.68	0.217
42.67	-42.55	0.217
42.68	-42.41	0.217
42.69	-42.28	0.217
42.71	-42.15	0.218
42.72	-42.01	0.218
42.74	-41.88	0.218
42.75	-41.75	0.218
42.76	-41.61	0.218
42.78	-41.48	0.218
42.79	-41.35	0.218
42.80	-41.21	0.218
42.81	-41.08	0.218
42.83	-40.94	0.218
42.84	-40.81	0.218
42.86	-40.68	0.218
42.87	-40.55	0.218
42.88	-40.41	0.218
42.89	-40.28	0.218
42.91	-40.14	0.218
42.92	-40.01	0.218
42.94	-39.88	0.218
42.95	-39.74	0.218
42.96	-39.61	0.219
42.98	-39.48	0.219
42.99	-39.34	0.219
43.00	-39.21	0.219
43.01	-39.08	0.219
43.03	-38.94	0.219
43.04	-38.81	0.219
43.06	-38.68	0.219
43.07	-38.54	0.219
43.08	-38.41	0.219
43.09	-38.27	0.219
43.11	-38.14	0.219
43.12	-38.01	0.219
43.14	-37.88	0.219
43.15	-37.74	0.219
43.16	-37.61	0.219
43.18	-37.48	0.220
43.19	-37.34	0.220
43.20	-37.21	0.220
43.21	-37.07	0.220
43.23	-36.94	0.220
43.24	-36.81	0.220
43.26	-36.67	0.220
43.27	-36.54	0.220
43.28	-36.41	0.220
43.29	-36.27	0.220
43.31	-36.14	0.220
43.32	-36.01	0.220
43.34	-35.87	0.220
43.35	-35.74	0.220
43.36	-35.60	0.220
43.38	-35.47	0.221
43.39	-35.34	0.221
43.40	-35.20	0.221
43.41	-35.07	0.221
43.43	-34.94	0.221
43.44	-34.80	0.221
43.46	-34.67	0.221
43.47	-34.54	0.221
43.48	-34.40	0.221
43.49	-34.27	0.221
43.51	-34.14	0.221
43.52	-34.00	0.221
43.54	-33.87	0.221
43.55	-33.74	0.221
43.56	-33.60	0.221
43.58	-33.47	0.222
43.59	-33.34	0.222
43.60	-33.20	0.222
43.61	-33.07	0.222
43.63	-32.93	0.222
43.64	-32.80	0.222
43.66	-32.67	0.222
43.67	-32.53	0.222
43.68	-32.40	0.222
43.69	-32.27	0.222
43.71	-32.13	0.222
43.72	-32.00	0.222
43.74	-31.87	0.222
43.75	-31.73	0.222
43.76	-31.60	0.222
43.78	-31.47	0.223
43.79	-31.33	0.223
43.80	-31.20	0.223
43.81	-31.07	0.223
43.83	-30.93	0.223
43.84	-30.80	0.223
43.86	-30.67	0.223
43.87	-30.53	0.223
43.88	-30.40	0.223
43.89	-30.27	0.223
43.91	-30.13	0.223
43.92	-30.00	0.223
43.94	-29.86	0.224
43.95	-29.73	0.224
43.96	-29.60	0.224
43.98	-29.46	0.224
43.99	-29.33	0.224
44.00	-29.20	0.224
44.01	-29.06	0.224
44.03	-28.93	0.224
44.04	-28.80	0.224
44.06	-28.66	0.224
44.07	-28.53	0.224
44.08	-28.40	0.225
44.09	-28.26	0.225
44.11	-28.13	0.225
44.12	-28.00	0.225
44.14	-27.86	0.225
44.15	-27.73	0.225
44.16	-27.59	0.225
44.18	-27.46	0.225
44.19	-27.33	0.225
44.20	-27.20	0.225
44.21	-27.06	0.226
44.23	-26.93	0.226
44.24	-26.80	0.226
44.26	-26.66	0.226
44.27	-26.53	0.226
44.28	-26.39	0.226
44.29	-26.26	0.226
44.31	-26.13	0.226
44.32	-25.99	0.226
44.34	-25.86	0.227
44.35	-25.73	0.227
44.36	-25.59	0.227
44.38	-25.46	0.227
44.39	-25.33	0.227
44.40	-25.19	0.227
44.41	-25.06	0.227
44.43	-24.93	0.227
44.44	-24.79	0.227
44.46	-24.66	0.228
44.47	-24.53	0.228
44.48	-24.39	0.228
44.49	-24.26	0.228
44.51	-24.13	0.228
44.52	-23.99	0.228
44.54	-23.86	0.228
44.55	-23.73	0.229
44.56	-23.59	0.229
44.58	-23.46	0.229
44.59	-23.33	0.229
44.60	-23.19	0.229
44.61	-23.06	0.229
44.63	-22.93	0.229
44.64	-22.79	0.230
44.66	-22.66	0.230
44.67	-22.53	0.230
44.68	-22.39	0.230
44.69	-22.26	0.230
44.71	-22.12	0.230
44.72	-21.99	0.231
44.74	-21.86	0.231
44.75	-21.72	0.231
44.76	-21.59	0.231
44.78	-21.46	0.231
44.79	-21.32	0.232
44.80	-21.19	0.232
44.81	-21.06	0.232
44.83	-20.92	0.232
44.84	-20.79	0.233
44.86	-20.66	0.233
44.87	-20.52	0.233
44.88	-20.39	0.234
44.89	-20.26	0.234
44.91	-20.12	0.234
44.92	-19.99	0.234
44.94	-19.86	0.235
44.95	-19.72	0.235
44.96	-19.59	0.235
44.98	-19.46	0.235
44.99	-19.32	0.236
45.00	-19.19	0.236
45.01	-19.06	0.237
45.03	-18.92	0.237
45.04	-18.79	0.237
45.06	-18.66	0.237
45.07	-18.52	0.238
45.08	-18.39	0.239
45.09	-18.26	0.239
45.11	-18.12	0.240
45.12	-17.99	0.240
45.14	-17.86	0.241
45.15	-17.72	0.241
45.16	-17.59	0.241
45.18	-17.46	0.242
45.19	-17.32	0.242
45.20	-17.19	0.243
45.21	-17.06	0.245
45.23	-16.92	0.245
45.24	-16.79	0.246
45.26	-16.66	0.247
45.27	-16.52	0.248
45.28	-16.39	0.249
45.29	-16.26	0.250
45.31	-16.12	0.251
45.32	-15.99	0.251
45.34	-15.86	0.253
45.35	-15.72	0.255
45.36	-15.59	0.256
45.38	-15.46	0.257
45.39	-15.32	0.259
45.40	-15.19	0.260
45.41	-15.06	0.261
45.43	-14.93	0.263
45.44	-14.79	0.265
45.46	-14.66	0.266
45.47	-14.53	0.267
45.48	-14.39	0.270
45.49	-14.26	0.271
45.51	-14.13	0.274
45.52	-13.99	0.278
45.54	-13.86	0.281
45.55	-13.72	0.285
45.56	-13.59	0.286
45.58	-13.46	0.289
45.59	-13.33	0.291
45.60	-13.19	0.294
45.61	-13.06	0.295
45.63	-12.93	0.297
45.64	-12.79	0.300
45.66	-12.66	0.303
45.67	-12.53	0.305
45.68	-12.40	0.307
45.69	-12.26	0.309
45.71	-12.13	0.312
45.72	-12.00	0.314
45.74	-11.87	0.316
45.75	-11.73	0.318
45.76	-11.60	0.320
45.78	-11.47	0.322
45.79	-11.33	0.324
45.80	-11.20	0.324
45.81	-11.07	0.326
45.83	-10.94	0.326
45.84	-10.80	0.327
45.86	-10.67	0.328
45.87	-10.54	0.328
45.88	-10.40	0.328
45.89	-10.27	0.329
45.91	-10.14	0.329
45.92	-10.00	0.329
45.94	-9.87	0.329
45.95	-9.74	0.328
45.96	-9.60	0.328
45.98	-9.47	0.327
45.99	-9.34	0.326
46.00	-9.20	0.325
46.01	-9.07	0.324
46.03	-8.94	0.324
46.04	-8.80	0.322
46.06	-8.67	0.320
46.07	-8.53	0.319
46.08	-8.40	0.318
46.09	-8.27	0.316
46.11	-8.13	0.316
46.12	-8.00	0.315
46.14	-7.87	0.314
46.15	-7.73	0.314
46.16	-7.60	0.313
46.18	-7.47	0.313
46.19	-7.33	0.312
46.20	-7.20	0.312
46.21	-7.06	0.312
46.23	-6.93	0.311
46.24	-6.80	0.311
46.26	-6.66	0.311
46.27	-6.53	0.310
46.28	-6.40	0.310
46.29	-6.26	0.309
46.31	-6.13	0.309
46.32	-6.00	0.309
46.34	-5.86	0.309
46.35	-5.73	0.308
46.36	-5.59	0.308
46.38	-5.46	0.308
46.39	-5.33	0.308
46.40	-5.19	0.308
46.41	-5.06	0.307
46.43	-4.93	0.307
46.44	-4.79	0.307
46.46	-4.66	0.307
46.47	-4.53	0.307
46.48	-4.39	0.307
46.49	-4.26	0.306
46.51	-4.13	0.306
46.52	-3.99	0.306
46.54	-3.86	0.306
46.55	-3.73	0.306
46.56	-3.59	0.306
46.58	-3.46	0.306
46.59	-3.33	0.306
46.60	-3.19	0.306
46.61	-3.06	0.306
46.63	-2.92	0.306
46.64	-2.79	0.306
46.66	-2.66	0.305
46.67	-2.52	0.305
46.68	-2.39	0.305
46.69	-2.26	0.305
46.71	-2.12	0.305
46.72	-1.99	0.305
46.74	-1.86	0.305
46.75	-1.72	0.305
46.76	-1.59	0.305
46.78	-1.46	0.305
46.79	-1.32	0.305
46.80	-1.19	0.305
46.81	-1.06	0.305
46.83	-0.92	0.305
46.84	-0.79	0.305
46.86	-0.66	0.305
46.87	-0.52	0.305
46.88	-0.39	0.305
46.89	-0.25	0.305
46.91	-0.12	0.305
46.92	0.01	0.305
46.94	0.15	0.305
46.95	0.28	0.305
46.96	0.41	0.306
46.98	0.55	0.306
46.99	0.68	0.306
47.00	0.81	0.306
47.01	0.95	0.306
47.03	1.08	0.306
47.04	1.21	0.306
47.06	1.35	0.306
47.07	1.48	0.306
47.08	1.62	0.306
47.09	1.75	0.306
47.11	1.88	0.306
47.12	2.02	0.306
47.14	2.15	0.306
47.15	2.28	0.306
47.16	2.41	0.306
47.18	2.55	0.306
47.19	2.68	0.306
47.20	2.82	0.306
47.21	2.95	0.306
47.23	3.08	0.306
47.24	3.22	0.306
47.26	3.35	0.306
47.27	3.48	0.306
47.28	3.62	0.306
47.29	3.75	0.307
47.31	3.89	0.307
47.32	4.02	0.307
47.34	4.15	0.307
47.35	4.28	0.307
47.36	4.42	0.307
47.38	4.55	0.307
47.39	4.69	0.307
47.40	4.82	0.307
47.41	4.95	0.307
47.43	5.09	0.307
47.44	5.22	0.307
47.46	5.35	0.307
47.47	5.49	0.307
47.48	5.62	0.308
47.49	5.75	0.308
47.51	5.89	0.308
47.52	6.02	0.308
47.54	6.15	0.308
47.55	6.29	0.308
47.56	6.42	0.308
47.58	6.55	0.308
47.59	6.69	0.308
47.60	6.82	0.308
47.61	6.95	0.308
47.63	7.09	0.309
47.64	7.22	0.309
47.66	7.36	0.309
47.67	7.49	0.309
47.68	7.62	0.309
47.69	7.76	0.309
47.71	7.89	0.309
47.72	8.02	0.309
47.74	8.16	0.309
47.75	8.29	0.309
47.76	8.42	0.309
47.78	8.56	0.309
47.79	8.69	0.309
47.80	8.82	0.309
47.81	8.96	0.310
47.83	9.09	0.310
47.84	9.22	0.310
47.86	9.36	0.310
47.87	9.49	0.310
47.88	9.62	0.310
47.89	9.76	0.310
47.91	9.89	0.310
47.92	10.02	0.310
47.94	10.16	0.310
47.95	10.29	0.310
47.96	10.43	0.310
47.98	10.56	0.311
47.99	10.69	0.311
48.00	10.83	0.311
48.01	10.96	0.311
48.03	11.09	0.311
48.04	11.23	0.311
48.06	11.36	0.311
48.07	11.49	0.311
48.08	11.63	0.311
48.09	11.76	0.311
48.11	11.89	0.311
48.12	12.03	0.311
48.14	12.16	0.311
48.15	12.29	0.311
48.16	12.43	0.312
48.18	12.56	0.312
48.19	12.69	0.312
48.20	12.83	0.312
48.21	12.96	0.312
48.23	13.09	0.312
48.24	13.23	0.312
48.26	13.36	0.312
48.27	13.49	0.312
48.28	13.63	0.312
48.29	13.76	0.313
48.31	13.89	0.313
48.32	14.03	0.313
48.34	14.16	0.313
48.35	14.30	0.313
48.36	14.43	0.313
48.38	14.56	0.313
48.39	14.70	0.313
48.40	14.83	0.313
48.41	14.96	0.313
48.43	15.10	0.313
48.44	15.23	0.313
48.46	15.36	0.313
48.47	15.50	0.314
48.48	15.63	0.314
48.49	15.76	0.314
48.51	15.90	0.314
48.52	16.03	0.314
48.54	16.16	0.314
48.55	16.30	0.314
48.56	16.43	0.314
48.58	16.56	0.314
48.59	16.70	0.314
48.60	16.83	0.314
48.61	16.96	0.314
48.63	17.10	0.315
48.64	17.23	0.315
48.66	17.36	0.315
48.67	17.50	0.315
48.68	17.63	0.315
48.69	17.76	0.315
48.71	17.90	0.315
48.72	18.03	0.315
48.74	18.17	0.315
48.75	18.30	0.315
48.76	18.43	0.315
48.78	18.57	0.315
48.79	18.70	0.316
48.80	18.83	0.316
48.81	18.96	0.316
48.83	19.10	0.316
48.84	19.23	0.316
48.86	19.37	0.316
48.87	19.50	0.316
48.88	19.63	0.316
48.89	19.77	0.316
48.91	19.90	0.316
48.92	20.03	0.316
48.94	20.17	0.316
48.95	20.30	0.316
48.96	20.43	0.317
48.98	20.57	0.317
48.99	20.70	0.317
49.00	20.83	0.317
49.01	20.97	0.317
49.03	21.10	0.317
49.04	21.23	0.317
49.06	21.37	0.317
49.07	21.50	0.317
49.08	21.63	0.317
49.09	21.77	0.317
49.11	21.90	0.317
49.12	22.04	0.318
49.14	22.17	0.318
49.15	22.30	0.318
49.16	22.43	0.318
49.18	22.57	0.318
49.19	22.70	0.318
49.20	22.84	0.318
49.21	22.97	0.318
49.23	23.10	0.318
49.24	23.24	0.318
49.26	23.37	0.318
49.27	23.50	0.319
49.28	23.64	0.319
49.29	23.77	0.319
49.31	23.90	0.319
49.32	24.04	0.319
49.34	24.17	0.319
49.35	24.31	0.319
49.36	24.44	0.319
49.38	24.57	0.319
49.39	24.71	0.320
49.40	24.84	0.320
49.41	24.97	0.320
49.43	25.11	0.320
49.44	25.24	0.320
49.46	25.37	0.320
49.47	25.51	0.320
49.48	25.64	0.320
49.49	25.77	0.320
49.51	25.91	0.320
49.52	26.04	0.320
49.54	26.17	0.321
49.55	26.31	0.321
49.56	26.44	0.321
49.58	26.57	0.321
49.59	26.71	0.321
49.60	26.84	0.321
49.61	26.97	0.321
49.63	27.11	0.321
49.64	27.24	0.321
49.66	27.37	0.321
49.67	27.51	0.321
49.68	27.64	0.321
49.69	27.77	0.321
49.71	27.91	0.322
49.72	28.04	0.322
49.74	28.17	0.322
49.75	28.31	0.322
49.76	28.44	0.322
49.78	28.58	0.322
49.79	28.71	0.322
49.80	28.84	0.322
49.81	28.97	0.322
49.83	29.11	0.322
49.84	29.24	0.323
49.86	29.38	0.323
49.87	29.51	0.323
49.88	29.64	0.323
49.89	29.78	0.323
49.91	29.91	0.323
49.92	30.04	0.323
49.94	30.18	0.323
49.95	30.31	0.323
49.96	30.44	0.323
49.98	30.58	0.323
49.99	30.71	0.323
50.00	30.84	0.324
50.01	30.98	0.324
50.03	31.11	0.324
50.04	31.25	0.324
50.06	31.38	0.324
50.07	31.51	0.324
50.08	31.64	0.324
50.09	31.78	0.324
50.11	31.91	0.324
50.12	32.04	0.324
50.14	32.18	0.324
50.15	32.31	0.324
50.16	32.44	0.325
50.18	32.58	0.325
50.19	32.71	0.325
50.20	32.85	0.325
50.21	32.98	0.325
50.23	33.11	0.325
50.24	33.25	0.325
50.26	33.38	0.325
50.27	33.51	0.325
50.28	33.65	0.325
50.29	33.78	0.325
50.31	33.91	0.325
50.32	34.05	0.326
50.34	34.18	0.326
50.35	34.31	0.326
50.36	34.45	0.326
50.38	34.58	0.326
50.39	34.71	0.326
50.40	34.85	0.326
50.41	34.98	0.326
50.43	35.11	0.326
50.44	35.25	0.326
50.46	35.38	0.327
50.47	35.51	0.327
50.48	35.65	0.327
50.49	35.78	0.327
50.51	35.92	0.327
50.52	36.05	0.327
50.54	36.18	0.327
50.55	36.32	0.327
50.56	36.45	0.327
50.58	36.58	0.327
50.59	36.72	0.327
50.60	36.85	0.327
50.61	36.98	0.327
50.63	37.12	0.328
50.64	37.25	0.328
50.66	37.38	0.328
50.67	37.52	0.328
50.68	37.65	0.328
50.69	37.78	0.328
50.71	37.92	0.328
50.72	38.05	0.328
50.74	38.18	0.328
50.75	38.32	0.328
50.76	38.45	0.328
50.78	38.58	0.328
50.79	38.72	0.328
50.80	38.85	0.329
50.81	38.98	0.329
50.83	39.12	0.329
50.84	39.25	0.329
50.86	39.38	0.329
50.87	39.52	0.329
50.88	39.65	0.329
50.89	39.78	0.329
50.91	39.92	0.329
50.92	40.05	0.329
50.94	40.19	0.329
50.95	40.32	0.330
50.96	40.45	0.330
50.98	40.59	0.330
50.99	40.72	0.330
51.00	40.85	0.330
51.01	40.99	0.330
51.03	41.12	0.330
51.04	41.25	0.330
51.06	41.39	0.330
51.07	41.52	0.330
51.08	41.65	0.330
51.09	41.79	0.330
51.11	41.92	0.331
51.12	42.05	0.331
51.14	42.19	0.331
51.15	42.32	0.331
51.16	42.45	0.331
51.18	42.59	0.331
51.19	42.72	0.331
51.20	42.85	0.331
51.21	42.99	0.331
51.23	43.12	0.331
51.24	43.25	0.331
51.26	43.39	0.331
51.27	43.52	0.331
51.28	43.66	0.332
51.29	43.79	0.332
51.31	43.92	0.332
51.32	44.06	0.332
51.34	44.19	0.332
51.35	44.32	0.332
51.36	44.46	0.332
51.38	44.59	0.332
51.39	44.72	0.332
51.40	44.86	0.332
51.41	44.99	0.332
51.43	45.12	0.332
51.44	45.26	0.333
51.46	45.39	0.333
51.47	45.52	0.333
51.48	45.66	0.333
51.49	45.79	0.333
51.51	45.92	0.333
51.52	46.06	0.333
51.54	46.19	0.333
51.55	46.32	0.333
51.56	46.46	0.333
51.58	46.59	0.333
51.59	46.72	0.334
51.60	46.86	0.334
51.61	46.99	0.334
51.63	47.12	0.334
51.64	47.26	0.334
51.66	47.39	0.334
51.67	47.53	0.334
51.68	47.66	0.334
51.69	47.79	0.334
51.71	47.93	0.335
51.72	48.06	0.335
51.74	48.19	0.335
51.75	48.33	0.335
51.76	48.46	0.335
51.78	48.59	0.335
51.79	48.73	0.335
51.80	48.86	0.335
51.81	48.99	0.335
51.83	49.13	0.335
51.84	49.26	0.335
51.86	49.39	0.335
51.87	49.53	0.336
51.88	49.66	0.336
51.89	49.79	0.336
51.91	49.93	0.336
51.92	50.06	0.336
51.94	50.20	0.336
51.95	50.33	0.336
51.96	50.46	0.336
51.98	50.59	0.336
51.99	50.73	0.336
52.00	50.86	0.336
52.01	51.00	0.336
52.03	51.13	0.337
52.04	51.26	0.337
52.06	51.40	0.337
52.07	51.53	0.337
52.08	51.66	0.337
52.09	51.80	0.337
52.11	51.93	0.337
52.12	52.06	0.337
52.14	52.20	0.337
52.15	52.33	0.337
52.16	52.46	0.337
52.18	52.60	0.337
52.19	52.73	0.338
52.20	52.86	0.338
52.21	53.00	0.338
52.23	53.13	0.338
52.24	53.26	0.338
52.26	53.40	0.338
52.27	53.53	0.338
52.28	53.66	0.338
52.29	53.80	0.338
52.31	53.93	0.338
52.32	54.06	0.338
52.34	54.20	0.338
52.35	54.33	0.339
52.36	54.46	0.339
52.38	54.60	0.339
52.39	54.73	0.339
52.40	54.87	0.339
52.41	55.00	0.339
52.43	55.13	0.339
52.44	55.27	0.339
52.46	55.40	0.339
52.47	55.53	0.339
52.48	55.67	0.339
52.49	55.80	0.339
52.51	55.93	0.339
52.52	56.07	0.340
52.54	56.20	0.340
52.55	56.33	0.340
52.56	56.47	0.340
52.58	56.60	0.340
52.59	56.73	0.340
52.60	56.87	0.340
52.61	57.00	0.340
52.63	57.13	0.340
52.64	57.27	0.340
52.66	57.40	0.340
52.67	57.53	0.341
52.68	57.67	0.341
52.69	57.80	0.341
52.71	57.93	0.341
52.72	58.07	0.341
52.74	58.20	0.341
52.75	58.34	0.341
52.76	58.47	0.341
52.78	58.60	0.341
52.79	58.73	0.341
52.80	58.87	0.341
52.81	59.00	0.342
52.83	59.13	0.342
52.84	59.27	0.342
52.86	59.40	0.342
52.87	59.54	0.342
52.88	59.67	0.342
52.89	59.80	0.342
52.91	59.94	0.342
52.92	60.07	0.342
52.94	60.20	0.342
52.95	60.34	0.342
52.96	60.47	0.342
52.98	60.60	0.342
52.99	60.74	0.342
53.00	60.87	0.342
53.01	61.00	0.343
53.03	61.14	0.343
53.04	61.27	0.343
53.06	61.41	0.343
53.07	61.54	0.343
53.08	61.67	0.343
53.09	61.80	0.343
53.11	61.94	0.343
53.12	62.07	0.343
53.14	62.21	0.343
53.15	62.34	0.343
53.16	62.47	0.343
53.18	62.61	0.343
53.19	62.74	0.344
53.20	62.87	0.344
53.21	63.01	0.344
53.23	63.14	0.344
53.24	63.27	0.344
53.26	63.41	0.344
53.27	63.54	0.344
53.28	63.67	0.344
53.29	63.81	0.344
53.31	63.94	0.344
53.32	64.07	0.344
53.34	64.21	0.344
53.35	64.34	0.345
53.36	64.47	0.345
53.38	64.61	0.345
53.39	64.74	0.345
53.40	64.87	0.345
53.41	65.01	0.345
53.43	65.14	0.345
53.44	65.27	0.345
53.46	65.41	0.345
53.47	65.54	0.345
53.48	65.68	0.345
53.49	65.81	0.345
53.51	65.94	0.345
53.52	66.08	0.346
53.54	66.21	0.346
53.55	66.34	0.346
53.56	66.48	0.346
53.58	66.61	0.346
53.59	66.74	0.346
53.60	66.88	0.346
53.61	67.01	0.346
53.63	67.14	0.346
53.64	67.28	0.346
53.66	67.41	0.346
53.67	67.54	0.346
53.68	67.68	0.346
53.69	67.81	0.346
53.71	67.94	0.347
53.72	68.08	0.347
53.74	68.21	0.347
53.75	68.34	0.347
53.76	68.48	0.347
53.78	68.61	0.347
53.79	68.74	0.347
53.80	68.88	0.347
53.81	69.01	0.347
53.83	69.15	0.347
53.84	69.28	0.347
53.86	69.41	0.347
53.87	69.55	0.347
53.88	69.68	0.347
53.89	69.81	0.348
53.91	69.95	0.348
53.92	70.08	0.348
53.94	70.21	0.348
53.95	70.35	0.348
53.96	70.48	0.348
53.98	70.61	0.348
53.99	70.75	0.348
54.00	70.88	0.348
54.01	71.01	0.348
54.03	71.15	0.348
54.04	71.28	0.348
54.06	71.41	0.348
54.07	71.55	0.348
54.08	71.68	0.349
54.09	71.81	0.349
54.11	71.95	0.349
54.12	72.08	0.349
54.14	72.22	0.349
54.15	72.35	0.349
54.16	72.48	0.349
54.18	72.62	0.349
54.19	72.75	0.349
54.20	72.88	0.349
54.21	73.01	0.349
54.23	73.15	0.350
54.24	73.28	0.350
54.26	73.42	0.350
54.27	73.55	0.350
54.28	73.68	0.350
54.29	73.82	0.350
54.31	73.95	0.350
54.32	74.08	0.350
54.34	74.22	0.350
54.35	74.35	0.350
54.36	74.48	0.350
54.38	74.62	0.350
54.39	74.75	0.350
54.40	74.88	0.350
54.41	75.02	0.351
54.43	75.15	0.351
54.44	75.28	0.351
54.46	75.42	0.351
54.47	75.55	0.351
54.48	75.68	0.351
54.49	75.82	0.351
54.51	75.95	0.351
54.52	76.08	0.351
54.54	76.22	0.351
54.55	76.35	0.351
54.56	76.49	0.351
54.58	76.62	0.352
54.59	76.75	0.352
54.60	76.89	0.352
54.61	77.02	0.352
54.63	77.15	0.352
54.64	77.29	0.352
54.66	77.42	0.352
54.67	77.55	0.352
54.68	77.69	0.352
54.69	77.82	0.352
54.71	77.95	0.352
54.72	78.09	0.353
54.74	78.22	0.353
54.75	78.35	0.353
54.76	78.49	0.353
54.78	78.62	0.353
54.79	78.75	0.353
54.80	78.89	0.353
54.81	79.02	0.353
54.83	79.15	0.353
54.84	79.29	0.353
54.86	79.42	0.353
54.87	79.55	0.353
54.88	79.69	0.353
54.89	79.82	0.353
54.91	79.95	0.354
54.92	80.09	0.354
54.94	80.22	0.354
54.95	80.35	0.354
54.96	80.49	0.354
54.98	80.62	0.354
54.99	80.76	0.354
55.00	80.89	0.354
55.01	81.02	0.354
55.03	81.16	0.354
55.04	81.29	0.354
55.06	81.42	0.354
55.07	81.56	0.354
55.08	81.69	0.354
55.09	81.82	0.354
55.11	81.96	0.354
55.12	82.09	0.355
55.14	82.22	0.355
55.15	82.36	0.355
55.16	82.49	0.355
55.18	82.62	0.355
55.19	82.76	0.355
55.20	82.89	0.355
55.21	83.02	0.355
55.23	83.16	0.355
55.24	83.29	0.355
55.26	83.43	0.355
55.27	83.56	0.355
55.28	83.69	0.355
55.29	83.83	0.355
55.31	83.96	0.355
55.32	84.09	0.355
55.34	84.23	0.355
55.35	84.36	0.355
55.36	84.49	0.355
55.38	84.63	0.355
55.39	84.76	0.355
55.40	84.89	0.355
55.41	85.03	0.355
55.43	85.16	0.355
55.44	85.29	0.355
55.46	85.43	0.355
55.47	85.56	0.355
55.48	85.69	0.356
55.49	85.83	0.356
55.51	85.96	0.356
55.52	86.09	0.356
55.54	86.23	0.356
55.55	86.36	0.356
55.56	86.49	0.356
55.58	86.63	0.356
55.59	86.76	0.356
55.60	86.89	0.356
55.61	87.03	0.356
55.63	87.16	0.356
55.64	87.29	0.356
55.66	87.43	0.356
55.67	87.56	0.356
55.68	87.69	0.356
55.69	87.83	0.356
55.71	87.96	0.356
55.72	88.09	0.357
55.74	88.23	0.357
55.75	88.36	0.357
55.76	88.49	0.357
55.78	88.63	0.357
55.79	88.76	0.357
55.80	88.89	0.357
55.81	89.03	0.357
55.83	89.16	0.357
55.84	89.29	0.357
55.86	89.43	0.357
55.87	89.56	0.357
55.88	89.69	0.357
55.89	89.83	0.358
55.91	89.96	0.358
55.92	90.09	0.358
55.94	90.23	0.358
55.95	90.36	0.358
55.96	90.49	0.358
55.98	90.63	0.358
55.99	90.76	0.358
56.00	90.89	0.358
56.01	91.03	0.358
56.03	91.16	0.358
56.04	91.29	0.358
56.06	91.43	0.359
56.07	91.56	0.359
56.08	91.70	0.359
56.09	91.83	0.359
56.11	91.96	0.359
56.12	92.09	0.359
56.14	92.23	0.359
56.15	92.36	0.359
56.16	92.50	0.359
56.18	92.63	0.359
56.19	92.76	0.359
56.20	92.90	0.359
56.21	93.03	0.360
56.23	93.16	0.360
56.24	93.30	0.360
56.26	93.43	0.360
56.27	93.56	0.360
56.28	93.70	0.360
56.29	93.83	0.360
56.31	93.96	0.360
56.32	94.10	0.360
56.34	94.23	0.360
56.35	94.36	0.360
56.36	94.50	0.361
56.38	94.63	0.361
56.39	94.76	0.361
56.40	94.90	0.361
56.41	95.03	0.361
56.43	95.16	0.361
56.44	95.30	0.361
56.46	95.43	0.361
56.47	95.56	0.361
56.48	95.70	0.361
56.49	95.83	0.361
56.51	95.96	0.361
56.52	96.10	0.362
56.54	96.23	0.362
56.55	96.36	0.362
56.56	96.50	0.362
56.58	96.63	0.362
56.59	96.77	0.362
56.60	96.90	0.362
56.61	97.03	0.362
56.63	97.17	0.362
56.64	97.30
56.66	97.43
56.67	97.57
56.68	97.70
56.69