File: DSC/2023_06_26_hagfish_alpha_protein_SBK.txt
Filename	2023_06_26_hagfish_alpha_protein_SBK
Instrument name	DSC2A-00468 (192.168.1.100)
Operator	SBK
rundate	6/26/2023
Sample name	2023_06_26_hagfish_alpha_protein_SBK
proceduresegments	Data Off ; Equilibrate -80.00 °C; Data On ; Ramp 5.00 °C/min to 100.00 °C; Data Off ; Isothermal 1.0 min; Data On ; Ramp 5.00 °C/min to -80.00 °C; Data Off ; Isothermal 1.0 min; Data On ; Ramp 5.00 °C/min to 100.00 °C
[File Parameters]
Run date	6/26/2023 1:43:12 PM
Trios version	5.1.1.46572
Original File Name
Current File Name	C:\Users\yargerlab\Desktop\DSC Data\General\2023_06_26_hagfish_alpha_protein_SBK.tri
[Procedure]
Procedure Name	DSC n80C 100C 2 cycle
Sample Name	2023_06_26_hagfish_alpha_protein_SBK
Sample Mass	2.9 mg
Reference Sample Mass	0 mg
Pan Mass	54.37 mg
Pan Number	38
Reference Pan Mass	53.66 mg
Reference Pan Number	46
Pan Type	Aluminum Hermetic
Comments	Hagfish alpha protein powder. Refrigerated before use, and run quickly after sample prep. Aluminum pan with hermetic aluminum lid. (DSC84010 and DSC84011)
Project Name	Silk ASDs
Operator	SBK
Test	Custom
Unload Max Temperature	30
Unload Min Temperature	30
Load Max Temperature	30
Load Min Temperature	30
Stop on Gas Flow Error	Yes
[Signal List]
Signal #1	Time (min)
Signal #2	Temperature (°C)
Signal #3	Heat Flow (mW)
Signal #4	Delta T (µV)
Signal #5	Delta Tzero (µV)
Signal #6	Tzero Temperature (°C)
Signal #7	Cell Purge (mL/min)
Signal #8	Heater Temp (°C)
Signal #9	Power Delivered (W)
Signal #10	Reference Junction Temperature (°C)
Signal #11	Flange Temperature (°C)
Signal #12	Heat Flow Phase (rad)
Signal #13	Total Heat Capacity (J/°C)
Signal #14	Heat Capacity (J/°C)
[Configuration]
Company Name	ASU
Instrument Name	DSC2A-00468
Instrument Type	DSC2500
Serial Number	DSC2A-00468
IP	192.168.1.100
Location of Instrument	MRRC
DisplayType	Unknown
Sample Interval 	0.1 s/pt
Selected Heat Flow	T4P
Exotherm Direction	Down
Cell Serial	DRC2-00792
Lid Type	Standard
Cooler	RCS 90
Leave Cooler on at End of Sequence	On
Gas 2	Nitrogen
Gas Selected	Channel 1
Flow Rate	50 mL/min
Secondary Purge	On
Licensed Heat Flow	Heat Flow T4P
Modulation Licensed	Yes
[Versions]
Common IDD Version	1
Cortex Version	VER 2.10.2.31
Driver	5.0.0.6
GDM Version	1.0.3.3
TouchscreenVersion	1.0.0.16145
FEP Version	1.2.1.21
FEP Bootloader	2.0.0.5
AutoSampler Version	2.1.1.26
Auto Sampler Bootloader	2.0.0.5
FCM Version	1.1.0.3
FCM Bootloader	2.0.0.5
[Experiment Logs]
Experiment Log Entry # 1	Data On set to 0
Experiment Log Entry # 3	Equilibrate Segment -80 (C) Started
Experiment Log Entry # 5	Air Cool is off.
Experiment Log Entry # 7	Data On set to 1
Experiment Log Entry # 9	Ramp Segment 5 C/min to 100 Started
Experiment Log Entry # 11	Data On set to 0
Experiment Log Entry # 13	Isothermal Segment 1 min started
Experiment Log Entry # 15	Data On set to 1
Experiment Log Entry # 17	Ramp Segment 5 C/min to -80 Started
Experiment Log Entry # 19	Data On set to 0
Experiment Log Entry # 21	Isothermal Segment 1 min started
Experiment Log Entry # 23	Data On set to 1
Experiment Log Entry # 25	Ramp Segment 5 C/min to 100 Started
[Method Log]
Method Log Entry # 1	Data Off
Method Log Entry # 2	Equilibrate -80 °C
Method Log Entry # 3	Data On
Method Log Entry # 4	(Ramp 47776) Ramp 5 °C/minute to 100 °C
Method Log Entry # 5	Data Off
Method Log Entry # 6	Isothermal 1 minutes
Method Log Entry # 7	Data On
Method Log Entry # 8	(Ramp 47780) Ramp 5 °C/minute to -80 °C
Method Log Entry # 9	Data Off
Method Log Entry # 10	Isothermal 1 minutes
Method Log Entry # 11	Data On
Method Log Entry # 12	(Ramp 47784) Ramp 5 °C/minute to 100 °C
Cell Serial	DRC2-00792
[T1 Calibration]
Slope	-0.008529666
Offset	9.636258
Initial Temperature	98.23
GUID	f8bfdadc-4977-4fdf-ba6d-0ba9134940c3
[TZero Calibration]
Date Applied	11/29/2022 4:06:13 PM
Description	From -89.059 °C to 396.009 °C at 20.000°C/min
Gas Type	Nitrogen
Pan Type	None
Source Files 1	C:\Users\yargerlab\Desktop\DSC Data\General\TZero_calibration_11_29_22_2nd(2).tri
Source Files 2	C:\Users\yargerlab\Desktop\DSC Data\General\TZero_calibration_11_29_22_2nd(3).tri
Delta T Offset	13.05235
Delta T Slope	-0.007271007
Delta T0 Offset	-13.69128
Delta T0 Slope	0.06063341
[Temperature Calibration]
Date Applied	11/29/2022 7:12:28 PM
Description	From 106.590 °C to 186.590 °C at 10.000°C/min
Gas Type	Nitrogen
Pan Type	Tzero Aluminum Hermetic
Source Files 1	C:\Users\yargerlab\Desktop\DSC Data\General\Indium(6).tri
Measured 1	157.391
Known 1	156.598
[Cell Constant Calibration]
Date Applied	11/29/2022 7:12:29 PM
Description	From 106.590 °C to 186.590 °C at 10.000°C/min
Gas Type	Nitrogen
Pan Type	Tzero Aluminum Hermetic
Source Files 1	C:\Users\yargerlab\Desktop\DSC Data\General\Indium(6).tri
T4P KCell	1.006051
Onset Slope	63.26126 mW/°C
[Direct Cp Calibration]
Date Applied	11/30/2022 11:04:51 AM
Description	From -79.983 °C to 298.409 °C at 10.000°C/min
Gas Type	Nitrogen
Pan Type	Tzero Aluminum Hermetic
Source Files 1	C:\Users\yargerlab\Desktop\DSC Data\General\Sapphire_Heat_Capacity_11_30_22.tri
[Rev Cp Calibration]
Date Applied	11/30/2022 1:58:51 PM
Description	From -79.996 °C to 292.812 °C at 3.000°C/min
Gas Type	Nitrogen
Pan Type	Tzero Aluminum Hermetic
Source Files 1	C:\Users\yargerlab\Desktop\DSC Data\General\Sapphire_MDSC_Calibration_11_30_22.tri
[step]
Ramp 5.00 °C/min to 100.00 °C
Time	Temperature	Heat Flow (Normalized)
min	°C	W/g
0.00	-79.77	-0.014
0.03	-79.78	-0.013
0.05	-79.77	-0.010
0.08	-79.75	-0.011
0.10	-79.71	-0.016
0.13	-79.64	-0.016
0.15	-79.56	0.007
0.18	-79.47	0.030
0.20	-79.38	0.038
0.23	-79.28	0.051
0.25	-79.18	0.058
0.28	-79.07	0.066
0.30	-78.96	0.075
0.33	-78.85	0.079
0.35	-78.73	0.083
0.38	-78.62	0.086
0.40	-78.50	0.088
0.43	-78.38	0.090
0.45	-78.26	0.091
0.48	-78.14	0.092
0.50	-78.02	0.093
0.53	-77.90	0.093
0.55	-77.78	0.094
0.58	-77.66	0.095
0.60	-77.54	0.095
0.63	-77.41	0.096
0.65	-77.29	0.096
0.68	-77.17	0.097
0.70	-77.05	0.097
0.73	-76.92	0.097
0.75	-76.80	0.098
0.78	-76.68	0.098
0.80	-76.55	0.098
0.83	-76.43	0.098
0.85	-76.31	0.098
0.88	-76.18	0.099
0.90	-76.06	0.099
0.93	-75.94	0.099
0.95	-75.81	0.099
0.98	-75.69	0.099
1.00	-75.57	0.099
1.03	-75.44	0.099
1.05	-75.32	0.099
1.08	-75.19	0.098
1.10	-75.07	0.098
1.13	-74.94	0.098
1.15	-74.82	0.098
1.18	-74.69	0.098
1.20	-74.57	0.098
1.23	-74.45	0.098
1.25	-74.32	0.098
1.28	-74.20	0.098
1.30	-74.07	0.098
1.33	-73.95	0.098
1.35	-73.83	0.097
1.38	-73.70	0.097
1.40	-73.58	0.097
1.43	-73.45	0.097
1.45	-73.33	0.097
1.48	-73.20	0.097
1.50	-73.08	0.097
1.53	-72.95	0.097
1.55	-72.83	0.097
1.58	-72.70	0.096
1.60	-72.58	0.096
1.63	-72.45	0.096
1.65	-72.33	0.096
1.68	-72.20	0.096
1.70	-72.08	0.096
1.73	-71.95	0.096
1.75	-71.82	0.096
1.78	-71.70	0.095
1.80	-71.58	0.095
1.83	-71.45	0.096
1.85	-71.33	0.095
1.88	-71.20	0.095
1.90	-71.08	0.095
1.93	-70.95	0.095
1.95	-70.83	0.095
1.98	-70.70	0.095
2.00	-70.58	0.095
2.03	-70.45	0.095
2.05	-70.33	0.095
2.08	-70.20	0.095
2.10	-70.08	0.095
2.13	-69.95	0.095
2.15	-69.83	0.095
2.18	-69.70	0.095
2.20	-69.58	0.095
2.23	-69.45	0.095
2.25	-69.33	0.095
2.28	-69.20	0.095
2.30	-69.08	0.094
2.33	-68.95	0.094
2.35	-68.83	0.094
2.38	-68.70	0.094
2.40	-68.58	0.094
2.43	-68.45	0.094
2.45	-68.33	0.094
2.48	-68.20	0.094
2.50	-68.08	0.094
2.53	-67.95	0.094
2.55	-67.83	0.094
2.58	-67.70	0.094
2.60	-67.58	0.094
2.63	-67.45	0.094
2.65	-67.33	0.094
2.68	-67.20	0.094
2.70	-67.08	0.094
2.73	-66.95	0.094
2.75	-66.83	0.094
2.78	-66.70	0.094
2.80	-66.58	0.094
2.83	-66.45	0.094
2.85	-66.33	0.094
2.88	-66.20	0.094
2.90	-66.08	0.094
2.93	-65.95	0.094
2.95	-65.83	0.094
2.98	-65.70	0.094
3.00	-65.58	0.094
3.03	-65.45	0.094
3.05	-65.33	0.094
3.08	-65.20	0.094
3.10	-65.08	0.094
3.13	-64.95	0.094
3.15	-64.83	0.094
3.18	-64.70	0.094
3.20	-64.58	0.094
3.23	-64.45	0.094
3.25	-64.33	0.094
3.28	-64.20	0.094
3.30	-64.07	0.094
3.33	-63.95	0.094
3.35	-63.83	0.094
3.38	-63.70	0.094
3.40	-63.58	0.094
3.43	-63.45	0.094
3.45	-63.33	0.094
3.48	-63.20	0.094
3.50	-63.07	0.094
3.53	-62.95	0.094
3.55	-62.83	0.094
3.58	-62.70	0.094
3.60	-62.57	0.094
3.63	-62.45	0.094
3.65	-62.32	0.094
3.68	-62.20	0.094
3.70	-62.07	0.094
3.73	-61.95	0.094
3.75	-61.82	0.094
3.78	-61.70	0.094
3.80	-61.58	0.094
3.83	-61.45	0.094
3.85	-61.32	0.094
3.88	-61.20	0.094
3.90	-61.07	0.094
3.93	-60.95	0.094
3.95	-60.82	0.094
3.98	-60.70	0.094
4.00	-60.58	0.094
4.03	-60.45	0.094
4.05	-60.32	0.094
4.08	-60.20	0.094
4.10	-60.07	0.094
4.13	-59.95	0.094
4.15	-59.82	0.094
4.18	-59.70	0.094
4.20	-59.58	0.094
4.23	-59.45	0.094
4.25	-59.32	0.094
4.28	-59.20	0.094
4.30	-59.07	0.094
4.33	-58.95	0.094
4.35	-58.82	0.094
4.38	-58.70	0.094
4.40	-58.57	0.094
4.43	-58.45	0.094
4.45	-58.32	0.094
4.48	-58.20	0.094
4.50	-58.07	0.094
4.53	-57.95	0.094
4.55	-57.82	0.094
4.58	-57.70	0.094
4.60	-57.57	0.094
4.63	-57.45	0.094
4.65	-57.32	0.094
4.68	-57.20	0.094
4.70	-57.07	0.094
4.73	-56.95	0.094
4.75	-56.82	0.094
4.78	-56.70	0.094
4.80	-56.57	0.094
4.83	-56.45	0.094
4.85	-56.32	0.094
4.88	-56.20	0.094
4.90	-56.07	0.094
4.93	-55.95	0.094
4.95	-55.82	0.094
4.98	-55.70	0.094
5.00	-55.57	0.094
5.03	-55.45	0.094
5.05	-55.32	0.094
5.08	-55.20	0.094
5.10	-55.07	0.094
5.13	-54.95	0.094
5.15	-54.82	0.094
5.18	-54.70	0.094
5.20	-54.57	0.094
5.23	-54.45	0.094
5.25	-54.32	0.094
5.28	-54.20	0.094
5.30	-54.07	0.094
5.33	-53.95	0.094
5.35	-53.82	0.094
5.38	-53.70	0.094
5.40	-53.57	0.094
5.43	-53.45	0.094
5.45	-53.32	0.094
5.48	-53.20	0.094
5.50	-53.07	0.094
5.53	-52.95	0.094
5.55	-52.82	0.094
5.58	-52.70	0.094
5.60	-52.57	0.094
5.63	-52.45	0.094
5.65	-52.32	0.094
5.68	-52.20	0.094
5.70	-52.07	0.094
5.73	-51.95	0.094
5.75	-51.82	0.094
5.78	-51.70	0.094
5.80	-51.57	0.094
5.83	-51.45	0.094
5.85	-51.32	0.094
5.88	-51.20	0.094
5.90	-51.07	0.094
5.93	-50.95	0.094
5.95	-50.82	0.094
5.98	-50.70	0.094
6.00	-50.57	0.094
6.03	-50.45	0.094
6.05	-50.32	0.094
6.08	-50.20	0.094
6.10	-50.07	0.094
6.13	-49.95	0.095
6.15	-49.82	0.095
6.18	-49.70	0.095
6.20	-49.57	0.095
6.23	-49.45	0.095
6.25	-49.32	0.095
6.28	-49.20	0.095
6.30	-49.07	0.095
6.33	-48.95	0.095
6.35	-48.82	0.095
6.38	-48.70	0.095
6.40	-48.57	0.095
6.43	-48.45	0.095
6.45	-48.32	0.095
6.48	-48.20	0.095
6.50	-48.07	0.095
6.53	-47.95	0.095
6.55	-47.82	0.095
6.58	-47.70	0.095
6.60	-47.57	0.095
6.63	-47.45	0.095
6.65	-47.32	0.095
6.68	-47.20	0.095
6.70	-47.07	0.095
6.73	-46.95	0.095
6.75	-46.82	0.095
6.78	-46.70	0.095
6.80	-46.57	0.095
6.83	-46.45	0.095
6.85	-46.32	0.095
6.88	-46.20	0.095
6.90	-46.07	0.095
6.93	-45.95	0.095
6.95	-45.83	0.095
6.98	-45.70	0.095
7.00	-45.58	0.095
7.03	-45.45	0.095
7.05	-45.32	0.095
7.08	-45.20	0.095
7.10	-45.07	0.095
7.13	-44.95	0.095
7.15	-44.83	0.095
7.18	-44.70	0.095
7.20	-44.57	0.095
7.23	-44.45	0.095
7.25	-44.33	0.095
7.28	-44.20	0.095
7.30	-44.07	0.095
7.33	-43.95	0.095
7.35	-43.82	0.095
7.38	-43.70	0.095
7.40	-43.58	0.095
7.43	-43.45	0.095
7.45	-43.32	0.095
7.48	-43.20	0.095
7.50	-43.07	0.095
7.53	-42.95	0.095
7.55	-42.82	0.095
7.58	-42.70	0.095
7.60	-42.58	0.095
7.63	-42.45	0.095
7.65	-42.32	0.095
7.68	-42.20	0.095
7.70	-42.07	0.095
7.73	-41.95	0.095
7.75	-41.82	0.095
7.78	-41.70	0.095
7.80	-41.57	0.095
7.83	-41.45	0.095
7.85	-41.32	0.095
7.88	-41.20	0.095
7.90	-41.07	0.095
7.93	-40.95	0.095
7.95	-40.82	0.095
7.98	-40.70	0.095
8.00	-40.57	0.095
8.03	-40.45	0.095
8.05	-40.32	0.095
8.08	-40.20	0.095
8.10	-40.07	0.095
8.13	-39.95	0.095
8.15	-39.82	0.095
8.18	-39.70	0.095
8.20	-39.57	0.095
8.23	-39.45	0.095
8.25	-39.32	0.095
8.28	-39.20	0.095
8.30	-39.07	0.095
8.33	-38.94	0.095
8.35	-38.82	0.095
8.38	-38.70	0.095
8.40	-38.57	0.095
8.43	-38.44	0.095
8.45	-38.32	0.095
8.48	-38.19	0.095
8.50	-38.07	0.095
8.53	-37.94	0.095
8.55	-37.82	0.095
8.58	-37.69	0.095
8.60	-37.57	0.095
8.63	-37.44	0.095
8.65	-37.32	0.095
8.68	-37.19	0.095
8.70	-37.07	0.095
8.73	-36.94	0.095
8.75	-36.82	0.095
8.78	-36.69	0.095
8.80	-36.57	0.095
8.83	-36.44	0.095
8.85	-36.32	0.095
8.88	-36.19	0.095
8.90	-36.07	0.095
8.93	-35.94	0.095
8.95	-35.82	0.095
8.98	-35.69	0.095
9.00	-35.57	0.095
9.03	-35.44	0.095
9.05	-35.32	0.095
9.08	-35.19	0.095
9.10	-35.06	0.095
9.13	-34.94	0.095
9.15	-34.81	0.095
9.18	-34.69	0.095
9.20	-34.56	0.095
9.23	-34.44	0.095
9.25	-34.31	0.095
9.28	-34.19	0.095
9.30	-34.06	0.095
9.33	-33.94	0.095
9.35	-33.81	0.095
9.38	-33.69	0.095
9.40	-33.56	0.095
9.43	-33.44	0.095
9.45	-33.31	0.095
9.48	-33.19	0.095
9.50	-33.06	0.095
9.53	-32.94	0.095
9.55	-32.81	0.095
9.58	-32.69	0.095
9.60	-32.56	0.095
9.63	-32.44	0.095
9.65	-32.31	0.095
9.68	-32.19	0.095
9.70	-32.06	0.095
9.73	-31.94	0.095
9.75	-31.81	0.095
9.78	-31.69	0.095
9.80	-31.56	0.095
9.83	-31.44	0.095
9.85	-31.31	0.095
9.88	-31.19	0.095
9.90	-31.06	0.095
9.93	-30.93	0.095
9.95	-30.81	0.095
9.98	-30.68	0.095
10.00	-30.56	0.095
10.03	-30.43	0.095
10.05	-30.31	0.095
10.08	-30.18	0.095
10.10	-30.06	0.095
10.13	-29.93	0.095
10.15	-29.81	0.095
10.18	-29.68	0.095
10.20	-29.56	0.095
10.23	-29.43	0.095
10.25	-29.31	0.095
10.28	-29.18	0.095
10.30	-29.06	0.095
10.33	-28.93	0.095
10.35	-28.81	0.095
10.38	-28.68	0.095
10.40	-28.56	0.095
10.43	-28.43	0.095
10.45	-28.31	0.095
10.48	-28.18	0.096
10.50	-28.06	0.096
10.53	-27.93	0.096
10.55	-27.81	0.096
10.58	-27.68	0.096
10.60	-27.55	0.096
10.63	-27.43	0.096
10.65	-27.31	0.096
10.68	-27.18	0.096
10.70	-27.06	0.096
10.73	-26.93	0.096
10.75	-26.80	0.095
10.78	-26.68	0.095
10.80	-26.56	0.096
10.83	-26.43	0.096
10.85	-26.30	0.095
10.88	-26.18	0.096
10.90	-26.05	0.096
10.93	-25.93	0.096
10.95	-25.80	0.096
10.98	-25.68	0.096
11.00	-25.55	0.096
11.03	-25.43	0.096
11.05	-25.30	0.096
11.08	-25.18	0.096
11.10	-25.05	0.096
11.13	-24.93	0.096
11.15	-24.80	0.096
11.18	-24.68	0.096
11.20	-24.55	0.096
11.23	-24.43	0.096
11.25	-24.30	0.096
11.28	-24.18	0.096
11.30	-24.05	0.096
11.33	-23.93	0.096
11.35	-23.80	0.096
11.38	-23.68	0.096
11.40	-23.55	0.096
11.43	-23.43	0.096
11.45	-23.30	0.096
11.48	-23.18	0.096
11.50	-23.05	0.096
11.53	-22.93	0.096
11.55	-22.80	0.096
11.58	-22.68	0.096
11.60	-22.55	0.096
11.63	-22.43	0.096
11.65	-22.30	0.096
11.68	-22.17	0.096
11.70	-22.05	0.096
11.73	-21.92	0.096
11.75	-21.80	0.096
11.78	-21.67	0.096
11.80	-21.55	0.096
11.83	-21.42	0.096
11.85	-21.30	0.096
11.88	-21.17	0.096
11.90	-21.05	0.096
11.93	-20.92	0.096
11.95	-20.80	0.096
11.98	-20.67	0.096
12.00	-20.55	0.096
12.03	-20.42	0.096
12.05	-20.30	0.096
12.08	-20.17	0.096
12.10	-20.05	0.096
12.13	-19.92	0.096
12.15	-19.80	0.096
12.18	-19.67	0.096
12.20	-19.55	0.096
12.23	-19.42	0.096
12.25	-19.30	0.096
12.28	-19.17	0.096
12.30	-19.05	0.096
12.33	-18.92	0.096
12.35	-18.80	0.096
12.38	-18.67	0.096
12.40	-18.55	0.096
12.43	-18.42	0.096
12.45	-18.30	0.096
12.48	-18.17	0.096
12.50	-18.05	0.096
12.53	-17.92	0.096
12.55	-17.80	0.096
12.58	-17.67	0.096
12.60	-17.55	0.096
12.63	-17.42	0.096
12.65	-17.29	0.096
12.68	-17.17	0.097
12.70	-17.05	0.096
12.73	-16.92	0.096
12.75	-16.80	0.097
12.78	-16.67	0.097
12.80	-16.55	0.097
12.83	-16.42	0.097
12.85	-16.30	0.097
12.88	-16.17	0.097
12.90	-16.05	0.097
12.93	-15.92	0.097
12.95	-15.79	0.097
12.98	-15.67	0.097
13.00	-15.55	0.097
13.03	-15.42	0.097
13.05	-15.30	0.097
13.08	-15.17	0.097
13.10	-15.05	0.097
13.13	-14.92	0.097
13.15	-14.79	0.097
13.18	-14.67	0.097
13.20	-14.55	0.097
13.23	-14.42	0.097
13.25	-14.29	0.097
13.28	-14.17	0.097
13.30	-14.04	0.097
13.33	-13.92	0.097
13.35	-13.79	0.097
13.38	-13.67	0.097
13.40	-13.54	0.097
13.43	-13.42	0.097
13.45	-13.29	0.097
13.48	-13.17	0.097
13.50	-13.04	0.097
13.53	-12.92	0.097
13.55	-12.79	0.097
13.58	-12.67	0.097
13.60	-12.54	0.097
13.63	-12.42	0.097
13.65	-12.29	0.097
13.68	-12.17	0.097
13.70	-12.04	0.097
13.73	-11.92	0.097
13.75	-11.79	0.097
13.78	-11.67	0.097
13.80	-11.54	0.097
13.83	-11.42	0.097
13.85	-11.29	0.097
13.88	-11.17	0.097
13.90	-11.04	0.097
13.93	-10.92	0.097
13.95	-10.79	0.097
13.98	-10.66	0.097
14.00	-10.54	0.097
14.03	-10.42	0.097
14.05	-10.29	0.097
14.08	-10.17	0.097
14.10	-10.04	0.097
14.13	-9.91	0.097
14.15	-9.79	0.097
14.18	-9.66	0.097
14.20	-9.54	0.097
14.23	-9.41	0.097
14.25	-9.29	0.097
14.28	-9.16	0.097
14.30	-9.04	0.097
14.33	-8.91	0.097
14.35	-8.79	0.097
14.38	-8.66	0.097
14.40	-8.54	0.098
14.43	-8.41	0.098
14.45	-8.29	0.098
14.48	-8.16	0.098
14.50	-8.04	0.098
14.53	-7.91	0.098
14.55	-7.79	0.098
14.58	-7.66	0.098
14.60	-7.54	0.098
14.63	-7.41	0.098
14.65	-7.28	0.098
14.68	-7.16	0.098
14.70	-7.04	0.098
14.73	-6.91	0.098
14.75	-6.79	0.098
14.78	-6.66	0.098
14.80	-6.53	0.098
14.83	-6.41	0.098
14.85	-6.28	0.098
14.88	-6.16	0.098
14.90	-6.04	0.098
14.93	-5.91	0.098
14.95	-5.78	0.098
14.98	-5.66	0.098
15.00	-5.53	0.098
15.03	-5.41	0.098
15.05	-5.28	0.098
15.08	-5.16	0.098
15.10	-5.03	0.098
15.13	-4.91	0.099
15.15	-4.78	0.099
15.18	-4.66	0.099
15.20	-4.53	0.098
15.23	-4.41	0.099
15.25	-4.28	0.098
15.28	-4.16	0.099
15.30	-4.03	0.099
15.33	-3.91	0.099
15.35	-3.78	0.099
15.38	-3.66	0.099
15.40	-3.53	0.099
15.43	-3.41	0.099
15.45	-3.28	0.099
15.48	-3.16	0.099
15.50	-3.03	0.099
15.53	-2.91	0.099
15.55	-2.78	0.099
15.58	-2.66	0.099
15.60	-2.53	0.099
15.63	-2.41	0.099
15.65	-2.28	0.099
15.68	-2.16	0.099
15.70	-2.03	0.099
15.73	-1.90	0.099
15.75	-1.78	0.099
15.78	-1.66	0.099
15.80	-1.53	0.099
15.83	-1.40	0.099
15.85	-1.28	0.099
15.88	-1.15	0.099
15.90	-1.03	0.099
15.93	-0.90	0.099
15.95	-0.78	0.099
15.98	-0.66	0.099
16.00	-0.53	0.099
16.03	-0.40	0.099
16.05	-0.28	0.099
16.08	-0.15	0.099
16.10	-0.03	0.099
16.13	0.10	0.099
16.15	0.22	0.099
16.18	0.35	0.099
16.20	0.47	0.100
16.23	0.60	0.100
16.25	0.72	0.100
16.28	0.85	0.100
16.30	0.97	0.100
16.33	1.10	0.100
16.35	1.22	0.100
16.38	1.35	0.100
16.40	1.47	0.100
16.43	1.60	0.100
16.45	1.72	0.100
16.48	1.85	0.100
16.50	1.97	0.100
16.53	2.10	0.100
16.55	2.22	0.100
16.58	2.35	0.100
16.60	2.47	0.100
16.63	2.60	0.100
16.65	2.72	0.100
16.68	2.85	0.100
16.70	2.97	0.100
16.73	3.10	0.100
16.75	3.22	0.100
16.78	3.35	0.100
16.80	3.47	0.100
16.83	3.60	0.100
16.85	3.72	0.100
16.88	3.85	0.100
16.90	3.97	0.100
16.93	4.10	0.100
16.95	4.22	0.100
16.98	4.35	0.100
17.00	4.47	0.100
17.03	4.60	0.100
17.05	4.73	0.100
17.08	4.85	0.100
17.10	4.97	0.101
17.13	5.10	0.101
17.15	5.23	0.101
17.18	5.35	0.101
17.20	5.48	0.101
17.23	5.60	0.101
17.25	5.73	0.101
17.28	5.85	0.101
17.30	5.98	0.101
17.33	6.10	0.101
17.35	6.23	0.101
17.38	6.35	0.101
17.40	6.48	0.101
17.43	6.60	0.101
17.45	6.73	0.101
17.48	6.85	0.101
17.50	6.98	0.101
17.53	7.10	0.101
17.55	7.23	0.101
17.58	7.35	0.101
17.60	7.48	0.102
17.63	7.60	0.102
17.65	7.73	0.102
17.68	7.85	0.102
17.70	7.98	0.102
17.73	8.10	0.102
17.75	8.23	0.102
17.78	8.35	0.102
17.80	8.48	0.102
17.83	8.60	0.102
17.85	8.73	0.102
17.88	8.85	0.102
17.90	8.98	0.102
17.93	9.10	0.102
17.95	9.23	0.102
17.98	9.35	0.102
18.00	9.48	0.102
18.03	9.60	0.102
18.05	9.73	0.102
18.08	9.85	0.102
18.10	9.98	0.102
18.13	10.10	0.102
18.15	10.23	0.102
18.18	10.35	0.102
18.20	10.48	0.102
18.23	10.61	0.102
18.25	10.73	0.102
18.28	10.86	0.102
18.30	10.98	0.102
18.33	11.10	0.103
18.35	11.23	0.103
18.38	11.36	0.103
18.40	11.48	0.103
18.43	11.61	0.103
18.45	11.73	0.103
18.48	11.85	0.103
18.50	11.98	0.103
18.53	12.11	0.103
18.55	12.23	0.103
18.58	12.36	0.103
18.60	12.48	0.103
18.63	12.61	0.103
18.65	12.73	0.103
18.68	12.86	0.103
18.70	12.98	0.103
18.73	13.11	0.103
18.75	13.23	0.103
18.78	13.36	0.103
18.80	13.48	0.103
18.83	13.61	0.103
18.85	13.73	0.103
18.88	13.86	0.103
18.90	13.98	0.103
18.93	14.11	0.103
18.95	14.23	0.103
18.98	14.36	0.103
19.00	14.48	0.104
19.03	14.61	0.104
19.05	14.73	0.104
19.08	14.86	0.104
19.10	14.98	0.104
19.13	15.11	0.104
19.15	15.23	0.104
19.18	15.36	0.104
19.20	15.48	0.104
19.23	15.61	0.104
19.25	15.73	0.104
19.28	15.86	0.104
19.30	15.98	0.104
19.33	16.11	0.105
19.35	16.23	0.105
19.38	16.36	0.105
19.40	16.48	0.105
19.43	16.61	0.105
19.45	16.73	0.105
19.48	16.86	0.105
19.50	16.98	0.105
19.53	17.11	0.105
19.55	17.23	0.105
19.58	17.36	0.105
19.60	17.49	0.105
19.63	17.61	0.105
19.65	17.74	0.105
19.68	17.86	0.105
19.70	17.99	0.105
19.73	18.11	0.105
19.75	18.24	0.105
19.78	18.36	0.106
19.80	18.49	0.106
19.83	18.61	0.106
19.85	18.74	0.106
19.88	18.86	0.106
19.90	18.99	0.106
19.93	19.11	0.106
19.95	19.24	0.106
19.98	19.36	0.106
20.00	19.49	0.106
20.03	19.61	0.106
20.05	19.74	0.106
20.08	19.86	0.106
20.10	19.99	0.106
20.13	20.11	0.106
20.15	20.24	0.106
20.18	20.36	0.106
20.20	20.49	0.106
20.23	20.61	0.107
20.25	20.74	0.107
20.28	20.86	0.107
20.30	20.99	0.107
20.33	21.11	0.107
20.35	21.24	0.107
20.38	21.36	0.107
20.40	21.49	0.107
20.43	21.61	0.107
20.45	21.74	0.107
20.48	21.86	0.107
20.50	21.99	0.107
20.53	22.11	0.107
20.55	22.24	0.107
20.58	22.36	0.107
20.60	22.49	0.107
20.63	22.61	0.107
20.65	22.74	0.107
20.68	22.86	0.107
20.70	22.99	0.107
20.73	23.11	0.107
20.75	23.24	0.108
20.78	23.36	0.108
20.80	23.49	0.108
20.83	23.61	0.108
20.85	23.74	0.108
20.88	23.86	0.108
20.90	23.99	0.108
20.93	24.12	0.108
20.95	24.24	0.108
20.98	24.37	0.108
21.00	24.49	0.108
21.03	24.62	0.108
21.05	24.74	0.108
21.08	24.86	0.109
21.10	24.99	0.109
21.13	25.12	0.109
21.15	25.24	0.109
21.18	25.37	0.109
21.20	25.49	0.109
21.23	25.62	0.109
21.25	25.74	0.109
21.28	25.87	0.109
21.30	25.99	0.109
21.33	26.12	0.109
21.35	26.24	0.109
21.38	26.37	0.109
21.40	26.49	0.109
21.43	26.62	0.109
21.45	26.74	0.110
21.48	26.87	0.110
21.50	26.99	0.110
21.53	27.12	0.110
21.55	27.24	0.110
21.58	27.37	0.110
21.60	27.49	0.110
21.63	27.62	0.110
21.65	27.74	0.110
21.68	27.87	0.110
21.70	27.99	0.110
21.73	28.12	0.110
21.75	28.24	0.110
21.78	28.37	0.111
21.80	28.49	0.111
21.83	28.62	0.110
21.85	28.74	0.111
21.88	28.87	0.111
21.90	28.99	0.111
21.93	29.12	0.111
21.95	29.24	0.111
21.98	29.37	0.111
22.00	29.49	0.111
22.03	29.62	0.111
22.05	29.74	0.111
22.08	29.87	0.111
22.10	29.99	0.111
22.13	30.12	0.111
22.15	30.24	0.112
22.18	30.37	0.112
22.20	30.49	0.112
22.23	30.62	0.112
22.25	30.74	0.112
22.28	30.87	0.112
22.30	31.00	0.112
22.33	31.12	0.112
22.35	31.24	0.112
22.38	31.37	0.112
22.40	31.49	0.112
22.43	31.62	0.112
22.45	31.74	0.112
22.48	31.87	0.112
22.50	32.00	0.112
22.53	32.12	0.113
22.55	32.25	0.113
22.58	32.37	0.113
22.60	32.50	0.113
22.63	32.62	0.113
22.65	32.75	0.113
22.68	32.87	0.113
22.70	33.00	0.113
22.73	33.12	0.113
22.75	33.25	0.113
22.78	33.37	0.113
22.80	33.50	0.113
22.83	33.62	0.114
22.85	33.75	0.114
22.88	33.87	0.114
22.90	34.00	0.114
22.93	34.12	0.114
22.95	34.25	0.114
22.98	34.37	0.114
23.00	34.50	0.114
23.03	34.62	0.114
23.05	34.75	0.114
23.08	34.87	0.114
23.10	35.00	0.114
23.13	35.12	0.114
23.15	35.25	0.114
23.18	35.37	0.115
23.20	35.50	0.115
23.23	35.62	0.115
23.25	35.75	0.115
23.28	35.87	0.115
23.30	36.00	0.115
23.33	36.12	0.115
23.35	36.25	0.115
23.38	36.37	0.116
23.40	36.50	0.115
23.43	36.62	0.116
23.45	36.75	0.116
23.48	36.87	0.116
23.50	37.00	0.116
23.53	37.12	0.116
23.55	37.25	0.116
23.58	37.37	0.116
23.60	37.50	0.116
23.63	37.62	0.116
23.65	37.75	0.116
23.68	37.87	0.116
23.70	38.00	0.116
23.73	38.12	0.116
23.75	38.25	0.116
23.78	38.38	0.116
23.80	38.50	0.117
23.83	38.62	0.117
23.85	38.75	0.117
23.88	38.87	0.117
23.90	39.00	0.117
23.93	39.12	0.117
23.95	39.25	0.117
23.98	39.38	0.117
24.00	39.50	0.117
24.03	39.63	0.117
24.05	39.75	0.117
24.08	39.87	0.117
24.10	40.00	0.117
24.13	40.13	0.118
24.15	40.25	0.118
24.18	40.38	0.118
24.20	40.50	0.118
24.23	40.63	0.118
24.25	40.75	0.118
24.28	40.88	0.118
24.30	41.00	0.118
24.33	41.13	0.118
24.35	41.25	0.118
24.38	41.38	0.118
24.40	41.50	0.119
24.43	41.63	0.119
24.45	41.75	0.119
24.48	41.88	0.119
24.50	42.00	0.119
24.53	42.13	0.119
24.55	42.25	0.119
24.58	42.38	0.119
24.60	42.50	0.119
24.63	42.63	0.120
24.65	42.75	0.120
24.68	42.88	0.120
24.70	43.00	0.120
24.73	43.13	0.120
24.75	43.25	0.120
24.78	43.38	0.120
24.80	43.50	0.120
24.83	43.63	0.120
24.85	43.75	0.121
24.88	43.88	0.121
24.90	44.00	0.121
24.93	44.13	0.121
24.95	44.25	0.121
24.98	44.38	0.121
25.00	44.50	0.121
25.03	44.63	0.121
25.05	44.75	0.121
25.08	44.88	0.122
25.10	45.00	0.122
25.13	45.13	0.122
25.15	45.25	0.122
25.18	45.38	0.122
25.20	45.50	0.122
25.23	45.63	0.122
25.25	45.75	0.122
25.28	45.88	0.123
25.30	46.00	0.123
25.33	46.13	0.123
25.35	46.25	0.123
25.38	46.38	0.123
25.40	46.50	0.123
25.43	46.63	0.123
25.45	46.75	0.123
25.48	46.88	0.123
25.50	47.00	0.124
25.53	47.13	0.124
25.55	47.26	0.124
25.58	47.38	0.124
25.60	47.51	0.124
25.63	47.63	0.124
25.65	47.76	0.124
25.68	47.88	0.124
25.70	48.01	0.125
25.73	48.13	0.125
25.75	48.26	0.125
25.78	48.38	0.125
25.80	48.51	0.125
25.83	48.63	0.125
25.85	48.76	0.125
25.88	48.88	0.125
25.90	49.00	0.125
25.93	49.13	0.126
25.95	49.26	0.126
25.98	49.38	0.126
26.00	49.51	0.126
26.03	49.63	0.126
26.05	49.76	0.126
26.08	49.88	0.126
26.10	50.01	0.126
26.13	50.13	0.127
26.15	50.26	0.127
26.18	50.38	0.127
26.20	50.51	0.127
26.23	50.63	0.127
26.25	50.76	0.127
26.28	50.88	0.128
26.30	51.01	0.128
26.33	51.13	0.128
26.35	51.26	0.128
26.38	51.38	0.128
26.40	51.51	0.128
26.43	51.63	0.128
26.45	51.76	0.128
26.48	51.88	0.129
26.50	52.01	0.129
26.53	52.13	0.129
26.55	52.26	0.129
26.58	52.38	0.129
26.60	52.51	0.129
26.63	52.63	0.129
26.65	52.76	0.129
26.68	52.88	0.130
26.70	53.01	0.130
26.73	53.13	0.130
26.75	53.26	0.130
26.78	53.38	0.130
26.80	53.51	0.130
26.83	53.63	0.131
26.85	53.76	0.131
26.88	53.88	0.131
26.90	54.01	0.131
26.93	54.13	0.131
26.95	54.26	0.131
26.98	54.38	0.131
27.00	54.51	0.132
27.03	54.63	0.132
27.05	54.76	0.132
27.08	54.88	0.132
27.10	55.01	0.133
27.13	55.13	0.133
27.15	55.26	0.133
27.18	55.38	0.133
27.20	55.51	0.133
27.23	55.63	0.133
27.25	55.76	0.134
27.28	55.88	0.134
27.30	56.01	0.134
27.33	56.13	0.134
27.35	56.26	0.134
27.38	56.38	0.134
27.40	56.51	0.135
27.43	56.63	0.135
27.45	56.76	0.135
27.48	56.88	0.135
27.50	57.01	0.135
27.53	57.13	0.135
27.55	57.26	0.136
27.58	57.39	0.136
27.60	57.51	0.136
27.63	57.63	0.136
27.65	57.76	0.137
27.68	57.88	0.137
27.70	58.01	0.137
27.73	58.13	0.137
27.75	58.26	0.137
27.78	58.38	0.138
27.80	58.51	0.138
27.83	58.63	0.138
27.85	58.76	0.138
27.88	58.89	0.138
27.90	59.01	0.139
27.93	59.14	0.139
27.95	59.26	0.139
27.98	59.39	0.139
28.00	59.51	0.140
28.03	59.64	0.140
28.05	59.76	0.140
28.08	59.89	0.140
28.10	60.01	0.141
28.13	60.14	0.141
28.15	60.26	0.141
28.18	60.39	0.141
28.20	60.51	0.141
28.23	60.64	0.142
28.25	60.76	0.142
28.28	60.89	0.142
28.30	61.01	0.142
28.33	61.14	0.143
28.35	61.26	0.143
28.38	61.39	0.143
28.40	61.51	0.143
28.43	61.64	0.144
28.45	61.76	0.144
28.48	61.89	0.144
28.50	62.01	0.144
28.53	62.14	0.144
28.55	62.26	0.145
28.58	62.39	0.145
28.60	62.51	0.145
28.63	62.64	0.145
28.65	62.76	0.145
28.68	62.89	0.146
28.70	63.01	0.146
28.73	63.14	0.146
28.75	63.26	0.146
28.78	63.39	0.147
28.80	63.51	0.147
28.83	63.64	0.147
28.85	63.76	0.147
28.88	63.89	0.148
28.90	64.01	0.148
28.93	64.14	0.148
28.95	64.26	0.148
28.98	64.39	0.149
29.00	64.51	0.149
29.03	64.64	0.149
29.05	64.76	0.149
29.08	64.89	0.149
29.10	65.01	0.150
29.13	65.14	0.150
29.15	65.26	0.150
29.18	65.39	0.151
29.20	65.51	0.151
29.23	65.64	0.151
29.25	65.76	0.151
29.28	65.89	0.152
29.30	66.01	0.152
29.33	66.14	0.152
29.35	66.26	0.152
29.38	66.39	0.153
29.40	66.51	0.153
29.43	66.64	0.153
29.45	66.76	0.153
29.48	66.89	0.154
29.50	67.01	0.154
29.53	67.14	0.154
29.55	67.26	0.154
29.58	67.39	0.155
29.60	67.51	0.155
29.63	67.64	0.155
29.65	67.76	0.155
29.68	67.89	0.155
29.70	68.01	0.156
29.73	68.14	0.156
29.75	68.26	0.156
29.78	68.39	0.156
29.80	68.51	0.157
29.83	68.64	0.157
29.85	68.76	0.157
29.88	68.89	0.157
29.90	69.01	0.157
29.93	69.14	0.158
29.95	69.26	0.158
29.98	69.39	0.158
30.00	69.51	0.158
30.03	69.64	0.159
30.05	69.76	0.159
30.08	69.89	0.159
30.10	70.01	0.159
30.13	70.14	0.159
30.15	70.26	0.160
30.18	70.39	0.160
30.20	70.51	0.160
30.23	70.64	0.160
30.25	70.76	0.160
30.28	70.89	0.161
30.30	71.01	0.161
30.33	71.14	0.161
30.35	71.27	0.161
30.38	71.39	0.161
30.40	71.51	0.162
30.43	71.64	0.162
30.45	71.76	0.162
30.48	71.89	0.162
30.50	72.02	0.162
30.53	72.14	0.162
30.55	72.27	0.162
30.58	72.39	0.163
30.60	72.52	0.163
30.63	72.64	0.163
30.65	72.77	0.163
30.68	72.89	0.163
30.70	73.02	0.163
30.73	73.14	0.163
30.75	73.27	0.163
30.78	73.39	0.163
30.80	73.51	0.163
30.83	73.64	0.163
30.85	73.77	0.163
30.88	73.89	0.163
30.90	74.02	0.163
30.93	74.14	0.163
30.95	74.27	0.163
30.98	74.39	0.163
31.00	74.52	0.163
31.03	74.64	0.163
31.05	74.77	0.163
31.08	74.89	0.163
31.10	75.02	0.163
31.13	75.14	0.163
31.15	75.27	0.163
31.18	75.39	0.163
31.20	75.52	0.163
31.23	75.64	0.163
31.25	75.77	0.163
31.28	75.89	0.162
31.30	76.02	0.162
31.33	76.14	0.162
31.35	76.27	0.162
31.38	76.39	0.162
31.40	76.52	0.162
31.43	76.64	0.162
31.45	76.77	0.162
31.48	76.89	0.162
31.50	77.02	0.162
31.53	77.14	0.161
31.55	77.27	0.161
31.58	77.39	0.161
31.60	77.52	0.161
31.63	77.65	0.161
31.65	77.77	0.161
31.68	77.89	0.161
31.70	78.02	0.161
31.73	78.14	0.161
31.75	78.27	0.160
31.78	78.40	0.160
31.80	78.52	0.160
31.83	78.65	0.160
31.85	78.77	0.160
31.88	78.90	0.160
31.90	79.02	0.160
31.93	79.15	0.160
31.95	79.27	0.160
31.98	79.40	0.160
32.00	79.52	0.160
32.03	79.65	0.160
32.05	79.77	0.160
32.08	79.90	0.160
32.10	80.02	0.160
32.13	80.15	0.160
32.15	80.27	0.160
32.18	80.40	0.160
32.20	80.52	0.160
32.23	80.65	0.160
32.25	80.77	0.160
32.28	80.90	0.160
32.30	81.02	0.160
32.33	81.15	0.160
32.35	81.27	0.160
32.38	81.40	0.160
32.40	81.52	0.160
32.43	81.65	0.160
32.45	81.77	0.160
32.48	81.90	0.160
32.50	82.02	0.160
32.53	82.15	0.160
32.55	82.27	0.160
32.58	82.40	0.160
32.60	82.52	0.160
32.63	82.65	0.160
32.65	82.77	0.160
32.68	82.90	0.160
32.70	83.02	0.160
32.73	83.15	0.160
32.75	83.27	0.160
32.78	83.40	0.160
32.80	83.52	0.160
32.83	83.65	0.160
32.85	83.77	0.160
32.88	83.90	0.161
32.90	84.02	0.161
32.93	84.15	0.161
32.95	84.27	0.161
32.98	84.40	0.161
33.00	84.52	0.161
33.03	84.65	0.161
33.05	84.77	0.161
33.08	84.90	0.161
33.10	85.02	0.161
33.13	85.15	0.161
33.15	85.27	0.162
33.18	85.40	0.162
33.20	85.52	0.162
33.23	85.65	0.162
33.25	85.77	0.162
33.28	85.90	0.162
33.30	86.02	0.162
33.33	86.15	0.162
33.35	86.27	0.162
33.38	86.40	0.162
33.40	86.52	0.162
33.43	86.65	0.163
33.45	86.77	0.163
33.48	86.90	0.163
33.50	87.02	0.163
33.53	87.15	0.163
33.55	87.27	0.163
33.58	87.40	0.163
33.60	87.52	0.164
33.63	87.65	0.164
33.65	87.77	0.164
33.68	87.90	0.164
33.70	88.03	0.164
33.73	88.15	0.164
33.75	88.27	0.164
33.78	88.40	0.164
33.80	88.53	0.164
33.83	88.65	0.165
33.85	88.78	0.165
33.88	88.90	0.165
33.90	89.03	0.165
33.93	89.15	0.165
33.95	89.28	0.165
33.98	89.40	0.166
34.00	89.53	0.166
34.03	89.65	0.166
34.05	89.78	0.166
34.08	89.90	0.166
34.10	90.03	0.166
34.13	90.15	0.166
34.15	90.28	0.167
34.18	90.40	0.167
34.20	90.53	0.167
34.23	90.65	0.167
34.25	90.78	0.167
34.28	90.90	0.167
34.30	91.03	0.167
34.33	91.15	0.167
34.35	91.28	0.168
34.38	91.40	0.168
34.40	91.53	0.168
34.43	91.65	0.168
34.45	91.78	0.168
34.48	91.90	0.168
34.50	92.03	0.169
34.53	92.15	0.169
34.55	92.28	0.169
34.58	92.40	0.169
34.60	92.53	0.169
34.63	92.65	0.170
34.65	92.78	0.170
34.68	92.90	0.170
34.70	93.03	0.170
34.73	93.15	0.170
34.75	93.28	0.170
34.78	93.40	0.171
34.80	93.53	0.171
34.83	93.65	0.171
34.85	93.78	0.171
34.88	93.90	0.171
34.90	94.03	0.172
34.93	94.15	0.172
34.95	94.28	0.172
34.98	94.40	0.172
35.00	94.53	0.172
35.03	94.65	0.172
35.05	94.78	0.173
35.08	94.90	0.173
35.10	95.03	0.173
35.13	95.15	0.173
35.15	95.28	0.173
35.18	95.40	0.173
35.20	95.53	0.174
35.23	95.65	0.174
35.25	95.78	0.174
35.28	95.90	0.174
35.30	96.03	0.174
35.33	96.16	0.175
35.35	96.28	0.175
35.38	96.41	0.175
35.40	96.53	0.175
35.43	96.66	0.175
35.45	96.78	0.175
35.48	96.91	0.175
35.50	97.03	0.176
35.53	97.16	0.176
35.55	97.28	0.176
35.58	97.41	0.176
35.60	97.53	0.176
35.63	97.66	0.176
35.65	97.78	0.176
35.68	97.90	0.177
35.70	98.03	0.177
35.73	98.16	0.177
35.75	98.28	0.177
35.78	98.41	0.177
35.80	98.53	0.177
35.83	98.65	0.177
35.85	98.78	0.177
35.88	98.90	0.178
35.90	99.03	0.178
35.93	99.16	0.178
35.95	99.28
35.98	99.40
35.98

[step]
Ramp 5.00 °C/min to -80.00 °C
Time	Temperature	Heat Flow (Normalized)
min	°C	W/g
36.99	100.12	-0.053
37.01	100.11	-0.053
37.04	100.11	-0.053
37.06	100.09	-0.053
37.09	100.06	-0.058
37.11	100.00	-0.089
37.14	99.93	-0.128
37.16	99.84	-0.160
37.19	99.74	-0.187
37.21	99.64	-0.207
37.24	99.54	-0.223
37.26	99.43	-0.233
37.29	99.31	-0.243
37.31	99.20	-0.250
37.34	99.08	-0.256
37.36	98.96	-0.260
37.39	98.85	-0.263
37.41	98.73	-0.265
37.44	98.60	-0.267
37.46	98.48	-0.268
37.49	98.36	-0.269
37.51	98.24	-0.270
37.54	98.12	-0.270
37.56	97.99	-0.271
37.59	97.87	-0.272
37.61	97.75	-0.273
37.64	97.62	-0.273
37.66	97.50	-0.274
37.69	97.37	-0.274
37.71	97.25	-0.274
37.74	97.13	-0.274
37.76	97.00	-0.275
37.79	96.88	-0.275
37.81	96.75	-0.275
37.84	96.63	-0.275
37.86	96.51	-0.275
37.89	96.38	-0.275
37.91	96.26	-0.275
37.94	96.13	-0.275
37.96	96.01	-0.275
37.99	95.89	-0.275
38.01	95.76	-0.275
38.04	95.64	-0.275
38.06	95.51	-0.275
38.09	95.39	-0.275
38.11	95.26	-0.275
38.14	95.14	-0.274
38.16	95.01	-0.274
38.19	94.89	-0.274
38.21	94.76	-0.274
38.24	94.64	-0.274
38.26	94.52	-0.274
38.29	94.39	-0.274
38.31	94.27	-0.273
38.34	94.14	-0.273
38.36	94.02	-0.273
38.39	93.89	-0.273
38.41	93.77	-0.272
38.44	93.64	-0.272
38.46	93.52	-0.272
38.49	93.39	-0.272
38.51	93.27	-0.271
38.54	93.14	-0.271
38.56	93.02	-0.271
38.59	92.89	-0.271
38.61	92.77	-0.270
38.64	92.64	-0.270
38.66	92.52	-0.270
38.69	92.39	-0.270
38.71	92.27	-0.269
38.74	92.14	-0.269
38.76	92.02	-0.269
38.79	91.89	-0.269
38.81	91.77	-0.268
38.84	91.64	-0.268
38.86	91.52	-0.268
38.89	91.39	-0.268
38.91	91.27	-0.267
38.94	91.14	-0.267
38.96	91.02	-0.267
38.99	90.89	-0.267
39.01	90.77	-0.266
39.04	90.64	-0.266
39.06	90.52	-0.266
39.09	90.40	-0.265
39.11	90.27	-0.265
39.14	90.15	-0.265
39.16	90.02	-0.265
39.19	89.90	-0.264
39.21	89.77	-0.264
39.24	89.64	-0.264
39.26	89.52	-0.264
39.29	89.39	-0.263
39.31	89.27	-0.263
39.34	89.15	-0.263
39.36	89.02	-0.263
39.39	88.89	-0.262
39.41	88.77	-0.262
39.44	88.64	-0.262
39.46	88.52	-0.261
39.49	88.39	-0.261
39.51	88.27	-0.261
39.54	88.14	-0.260
39.56	88.02	-0.260
39.59	87.90	-0.260
39.61	87.77	-0.259
39.64	87.64	-0.259
39.66	87.52	-0.259
39.69	87.39	-0.259
39.71	87.27	-0.259
39.74	87.15	-0.258
39.76	87.02	-0.258
39.79	86.89	-0.258
39.81	86.77	-0.258
39.84	86.65	-0.257
39.86	86.52	-0.257
39.89	86.40	-0.257
39.91	86.27	-0.257
39.94	86.14	-0.257
39.96	86.02	-0.256
39.99	85.89	-0.256
40.01	85.77	-0.256
40.04	85.64	-0.256
40.06	85.52	-0.256
40.09	85.40	-0.256
40.11	85.27	-0.255
40.14	85.14	-0.255
40.16	85.02	-0.255
40.19	84.89	-0.255
40.21	84.77	-0.255
40.24	84.64	-0.254
40.26	84.52	-0.254
40.29	84.40	-0.254
40.31	84.27	-0.254
40.34	84.14	-0.253
40.36	84.02	-0.253
40.39	83.89	-0.253
40.41	83.77	-0.252
40.44	83.65	-0.252
40.46	83.52	-0.252
40.49	83.40	-0.252
40.51	83.27	-0.252
40.54	83.15	-0.252
40.56	83.02	-0.251
40.59	82.90	-0.251
40.61	82.77	-0.251
40.64	82.65	-0.251
40.66	82.52	-0.251
40.69	82.40	-0.250
40.71	82.27	-0.250
40.74	82.15	-0.250
40.76	82.02	-0.250
40.79	81.90	-0.250
40.81	81.77	-0.249
40.84	81.65	-0.249
40.86	81.52	-0.249
40.89	81.40	-0.249
40.91	81.27	-0.249
40.94	81.15	-0.249
40.96	81.02	-0.248
40.99	80.90	-0.248
41.01	80.77	-0.248
41.04	80.65	-0.248
41.06	80.52	-0.248
41.09	80.40	-0.247
41.11	80.27	-0.247
41.14	80.15	-0.247
41.16	80.02	-0.247
41.19	79.90	-0.247
41.21	79.77	-0.247
41.24	79.65	-0.247
41.26	79.53	-0.246
41.29	79.40	-0.246
41.31	79.27	-0.246
41.34	79.15	-0.246
41.36	79.02	-0.246
41.39	78.90	-0.245
41.41	78.77	-0.245
41.44	78.65	-0.245
41.46	78.52	-0.245
41.49	78.40	-0.245
41.51	78.27	-0.245
41.54	78.15	-0.244
41.56	78.02	-0.244
41.59	77.90	-0.244
41.61	77.77	-0.244
41.64	77.65	-0.244
41.66	77.52	-0.243
41.69	77.40	-0.243
41.71	77.27	-0.243
41.74	77.15	-0.243
41.76	77.02	-0.243
41.79	76.90	-0.242
41.81	76.77	-0.242
41.84	76.65	-0.242
41.86	76.52	-0.242
41.89	76.40	-0.242
41.91	76.27	-0.241
41.94	76.15	-0.241
41.96	76.02	-0.241
41.99	75.90	-0.241
42.01	75.77	-0.241
42.04	75.65	-0.240
42.06	75.52	-0.240
42.09	75.40	-0.240
42.11	75.27	-0.240
42.14	75.15	-0.240
42.16	75.02	-0.240
42.19	74.90	-0.239
42.21	74.77	-0.239
42.24	74.65	-0.239
42.26	74.52	-0.239
42.29	74.40	-0.239
42.31	74.27	-0.238
42.34	74.15	-0.238
42.36	74.02	-0.238
42.39	73.90	-0.238
42.41	73.77	-0.238
42.44	73.65	-0.237
42.46	73.52	-0.237
42.49	73.40	-0.237
42.51	73.27	-0.237
42.54	73.15	-0.237
42.56	73.02	-0.236
42.59	72.90	-0.236
42.61	72.77	-0.236
42.64	72.65	-0.236
42.66	72.52	-0.235
42.69	72.40	-0.235
42.71	72.27	-0.235
42.74	72.15	-0.235
42.76	72.02	-0.235
42.79	71.90	-0.234
42.81	71.77	-0.234
42.84	71.65	-0.234
42.86	71.52	-0.234
42.89	71.40	-0.234
42.91	71.27	-0.233
42.94	71.15	-0.233
42.96	71.02	-0.233
42.99	70.90	-0.233
43.01	70.77	-0.233
43.04	70.65	-0.233
43.06	70.53	-0.232
43.09	70.40	-0.232
43.11	70.28	-0.232
43.14	70.15	-0.232
43.16	70.03	-0.232
43.19	69.90	-0.231
43.21	69.78	-0.231
43.24	69.65	-0.231
43.26	69.53	-0.231
43.29	69.40	-0.231
43.31	69.28	-0.231
43.34	69.15	-0.231
43.36	69.03	-0.230
43.39	68.90	-0.230
43.41	68.78	-0.230
43.44	68.65	-0.230
43.46	68.53	-0.230
43.49	68.40	-0.229
43.51	68.28	-0.229
43.54	68.15	-0.229
43.56	68.03	-0.229
43.59	67.90	-0.229
43.61	67.78	-0.229
43.64	67.65	-0.228
43.66	67.53	-0.228
43.69	67.40	-0.228
43.71	67.28	-0.228
43.74	67.15	-0.228
43.76	67.03	-0.228
43.79	66.90	-0.227
43.81	66.78	-0.227
43.84	66.65	-0.227
43.86	66.53	-0.227
43.89	66.40	-0.227
43.91	66.28	-0.227
43.94	66.15	-0.227
43.96	66.03	-0.226
43.99	65.90	-0.226
44.01	65.78	-0.226
44.04	65.65	-0.226
44.06	65.53	-0.226
44.09	65.40	-0.225
44.11	65.28	-0.225
44.14	65.15	-0.225
44.16	65.03	-0.225
44.19	64.90	-0.225
44.21	64.78	-0.224
44.24	64.65	-0.224
44.26	64.53	-0.224
44.29	64.40	-0.224
44.31	64.28	-0.224
44.34	64.15	-0.223
44.36	64.03	-0.223
44.39	63.90	-0.223
44.41	63.78	-0.223
44.44	63.65	-0.223
44.46	63.53	-0.222
44.49	63.40	-0.222
44.51	63.28	-0.222
44.54	63.15	-0.222
44.56	63.03	-0.222
44.59	62.90	-0.222
44.61	62.78	-0.222
44.64	62.65	-0.221
44.66	62.53	-0.221
44.69	62.40	-0.221
44.71	62.28	-0.221
44.74	62.15	-0.221
44.76	62.03	-0.221
44.79	61.90	-0.220
44.81	61.78	-0.220
44.84	61.65	-0.220
44.86	61.53	-0.220
44.89	61.40	-0.220
44.91	61.28	-0.220
44.94	61.15	-0.219
44.96	61.03	-0.219
44.99	60.90	-0.219
45.01	60.78	-0.219
45.04	60.65	-0.219
45.06	60.53	-0.219
45.09	60.40	-0.218
45.11	60.28	-0.218
45.14	60.15	-0.218
45.16	60.03	-0.218
45.19	59.90	-0.218
45.21	59.78	-0.218
45.24	59.65	-0.217
45.26	59.53	-0.217
45.29	59.40	-0.217
45.31	59.28	-0.217
45.34	59.15	-0.217
45.36	59.03	-0.216
45.39	58.90	-0.216
45.41	58.78	-0.216
45.44	58.65	-0.216
45.46	58.53	-0.216
45.49	58.40	-0.216
45.51	58.28	-0.216
45.54	58.15	-0.215
45.56	58.03	-0.215
45.59	57.90	-0.215
45.61	57.78	-0.215
45.64	57.65	-0.215
45.66	57.53	-0.215
45.69	57.40	-0.215
45.71	57.28	-0.215
45.74	57.15	-0.214
45.76	57.03	-0.214
45.79	56.90	-0.214
45.81	56.78	-0.214
45.84	56.65	-0.214
45.86	56.53	-0.213
45.89	56.40	-0.212
45.91	56.28	-0.212
45.94	56.15	-0.212
45.96	56.03	-0.212
45.99	55.90	-0.212
46.01	55.78	-0.212
46.04	55.65	-0.212
46.06	55.53	-0.212
46.09	55.40	-0.212
46.11	55.28	-0.212
46.14	55.15	-0.212
46.16	55.03	-0.211
46.19	54.90	-0.211
46.21	54.78	-0.211
46.24	54.65	-0.211
46.26	54.53	-0.211
46.29	54.41	-0.211
46.31	54.28	-0.211
46.34	54.16	-0.210
46.36	54.03	-0.210
46.39	53.90	-0.210
46.41	53.78	-0.210
46.44	53.66	-0.210
46.46	53.53	-0.210
46.49	53.40	-0.210
46.51	53.28	-0.210
46.54	53.15	-0.209
46.56	53.03	-0.209
46.59	52.90	-0.209
46.61	52.78	-0.209
46.64	52.66	-0.209
46.66	52.53	-0.209
46.69	52.41	-0.208
46.71	52.28	-0.208
46.74	52.15	-0.208
46.76	52.03	-0.208
46.79	51.91	-0.208
46.81	51.78	-0.208
46.84	51.66	-0.208
46.86	51.53	-0.207
46.89	51.40	-0.207
46.91	51.28	-0.207
46.94	51.15	-0.207
46.96	51.03	-0.207
46.99	50.91	-0.207
47.01	50.78	-0.207
47.04	50.66	-0.206
47.06	50.53	-0.206
47.09	50.41	-0.206
47.11	50.28	-0.206
47.14	50.16	-0.206
47.16	50.03	-0.205
47.19	49.91	-0.206
47.21	49.78	-0.205
47.24	49.66	-0.205
47.26	49.53	-0.205
47.29	49.41	-0.205
47.31	49.28	-0.205
47.34	49.16	-0.205
47.36	49.03	-0.204
47.39	48.91	-0.204
47.41	48.78	-0.204
47.44	48.66	-0.204
47.46	48.53	-0.204
47.49	48.41	-0.204
47.51	48.28	-0.203
47.54	48.16	-0.203
47.56	48.03	-0.203
47.59	47.91	-0.203
47.61	47.78	-0.203
47.64	47.66	-0.203
47.66	47.53	-0.203
47.69	47.41	-0.202
47.71	47.28	-0.202
47.74	47.16	-0.202
47.76	47.03	-0.202
47.79	46.91	-0.202
47.81	46.78	-0.202
47.84	46.66	-0.202
47.86	46.53	-0.201
47.89	46.41	-0.201
47.91	46.28	-0.201
47.94	46.16	-0.201
47.96	46.03	-0.201
47.99	45.91	-0.200
48.01	45.78	-0.200
48.04	45.66	-0.200
48.06	45.53	-0.200
48.09	45.41	-0.200
48.11	45.28	-0.200
48.14	45.16	-0.200
48.16	45.03	-0.199
48.19	44.91	-0.199
48.21	44.78	-0.199
[...]
82.94	-35.96	0.098
82.96	-35.83	0.098
82.99	-35.71	0.098
83.01	-35.58	0.098
83.04	-35.46	0.099
83.06	-35.33	0.099
83.09	-35.20	0.099
83.11	-35.08	0.098
83.14	-34.95	0.098
83.16	-34.83	0.098
83.19	-34.71	0.098
83.21	-34.58	0.099
83.24	-34.45	0.098
83.26	-34.33	0.099
83.29	-34.20	0.099
83.31	-34.08	0.099
83.34	-33.96	0.099
83.36	-33.83	0.099
83.39	-33.70	0.099
83.41	-33.58	0.099
83.44	-33.45	0.099
83.46	-33.33	0.099
83.49	-33.20	0.099
83.51	-33.08	0.099
83.54	-32.95	0.099
83.56	-32.83	0.099
83.59	-32.70	0.099
83.61	-32.58	0.099
83.64	-32.45	0.099
83.66	-32.33	0.099
83.69	-32.20	0.099
83.71	-32.08	0.099
83.74	-31.95	0.099
83.76	-31.83	0.099
83.79	-31.70	0.099
83.81	-31.58	0.099
83.84	-31.45	0.099
83.86	-31.33	0.099
83.89	-31.20	0.099
83.91	-31.08	0.099
83.94	-30.95	0.099
83.96	-30.83	0.099
83.99	-30.70	0.099
84.01	-30.57	0.099
84.04	-30.45	0.099
84.06	-30.32	0.099
84.09	-30.20	0.099
84.11	-30.07	0.099
84.14	-29.95	0.099
84.16	-29.82	0.099
84.19	-29.70	0.099
84.21	-29.57	0.099
84.24	-29.45	0.099
84.26	-29.32	0.099
84.29	-29.20	0.099
84.31	-29.07	0.099
84.34	-28.95	0.099
84.36	-28.82	0.099
84.39	-28.70	0.099
84.41	-28.57	0.099
84.44	-28.45	0.099
84.46	-28.32	0.099
84.49	-28.20	0.099
84.51	-28.07	0.099
84.54	-27.95	0.099
84.56	-27.82	0.099
84.59	-27.70	0.099
84.61	-27.57	0.099
84.64	-27.45	0.099
84.66	-27.32	0.099
84.69	-27.20	0.099
84.71	-27.07	0.099
84.74	-26.95	0.099
84.76	-26.82	0.099
84.79	-26.70	0.099
84.81	-26.57	0.099
84.84	-26.45	0.099
84.86	-26.32	0.099
84.89	-26.20	0.099
84.91	-26.07	0.099
84.94	-25.95	0.099
84.96	-25.82	0.099
84.99	-25.70	0.099
85.01	-25.57	0.099
85.04	-25.45	0.099
85.06	-25.32	0.099
85.09	-25.20	0.100
85.11	-25.07	0.100
85.14	-24.95	0.100
85.16	-24.82	0.100
85.19	-24.70	0.099
85.21	-24.57	0.100
85.24	-24.45	0.100
85.26	-24.32	0.099
85.29	-24.20	0.099
85.31	-24.07	0.099
85.34	-23.94	0.100
85.36	-23.82	0.100
85.39	-23.70	0.100
85.41	-23.57	0.100
85.44	-23.45	0.100
85.46	-23.32	0.100
85.49	-23.20	0.100
85.51	-23.07	0.100
85.54	-22.94	0.100
85.56	-22.82	0.100
85.59	-22.69	0.100
85.61	-22.57	0.100
85.64	-22.44	0.100
85.66	-22.32	0.100
85.69	-22.19	0.100
85.71	-22.07	0.100
85.74	-21.94	0.100
85.76	-21.82	0.100
85.79	-21.69	0.100
85.81	-21.57	0.100
85.84	-21.44	0.100
85.86	-21.32	0.100
85.89	-21.19	0.100
85.91	-21.07	0.100
85.94	-20.94	0.100
85.96	-20.81	0.100
85.99	-20.69	0.100
86.01	-20.56	0.100
86.04	-20.44	0.100
86.06	-20.31	0.100
86.09	-20.19	0.100
86.11	-20.06	0.100
86.14	-19.94	0.100
86.16	-19.81	0.100
86.19	-19.69	0.100
86.21	-19.57	0.100
86.24	-19.44	0.100
86.26	-19.31	0.100
86.29	-19.19	0.100
86.31	-19.06	0.100
86.34	-18.94	0.100
86.36	-18.81	0.100
86.39	-18.69	0.100
86.41	-18.56	0.100
86.44	-18.44	0.100
86.46	-18.31	0.101
86.49	-18.19	0.100
86.51	-18.06	0.101
86.54	-17.94	0.100
86.56	-17.81	0.100
86.59	-17.69	0.101
86.61	-17.56	0.100
86.64	-17.44	0.101
86.66	-17.31	0.101
86.69	-17.19	0.101
86.71	-17.06	0.101
86.74	-16.94	0.101
86.76	-16.81	0.101
86.79	-16.69	0.101
86.81	-16.56	0.101
86.84	-16.43	0.101
86.86	-16.31	0.101
86.89	-16.18	0.101
86.91	-16.06	0.101
86.94	-15.94	0.101
86.96	-15.81	0.101
86.99	-15.68	0.101
87.01	-15.56	0.101
87.04	-15.44	0.101
87.06	-15.31	0.101
87.09	-15.19	0.101
87.11	-15.06	0.101
87.14	-14.93	0.101
87.16	-14.81	0.101
87.19	-14.68	0.101
87.21	-14.56	0.101
87.24	-14.43	0.101
87.26	-14.31	0.101
87.29	-14.18	0.101
87.31	-14.06	0.101
87.34	-13.93	0.101
87.36	-13.81	0.101
87.39	-13.68	0.101
87.41	-13.56	0.101
87.44	-13.43	0.101
87.46	-13.31	0.101
87.49	-13.18	0.101
87.51	-13.06	0.101
87.54	-12.93	0.101
87.56	-12.81	0.101
87.59	-12.68	0.101
87.61	-12.56	0.101
87.64	-12.43	0.101
87.66	-12.31	0.101
87.69	-12.18	0.101
87.71	-12.06	0.101
87.74	-11.93	0.101
87.76	-11.81	0.101
87.79	-11.68	0.101
87.81	-11.56	0.101
87.84	-11.43	0.101
87.86	-11.31	0.102
87.89	-11.18	0.101
87.91	-11.06	0.102
87.94	-10.93	0.102
87.96	-10.81	0.102
87.99	-10.68	0.102
88.01	-10.56	0.102
88.04	-10.43	0.102
88.06	-10.30	0.102
88.09	-10.18	0.102
88.11	-10.06	0.102
88.14	-9.93	0.102
88.16	-9.81	0.102
88.19	-9.68	0.102
88.21	-9.56	0.102
88.24	-9.43	0.102
88.26	-9.30	0.102
88.29	-9.18	0.102
88.31	-9.05	0.102
88.34	-8.93	0.102
88.36	-8.80	0.102
88.39	-8.68	0.102
88.41	-8.55	0.102
88.44	-8.43	0.102
88.46	-8.30	0.102
88.49	-8.18	0.102
88.51	-8.05	0.102
88.54	-7.93	0.102
88.56	-7.80	0.102
88.59	-7.68	0.102
88.61	-7.55	0.102
88.64	-7.43	0.102
88.66	-7.30	0.102
88.69	-7.18	0.102
88.71	-7.05	0.102
88.74	-6.93	0.102
88.76	-6.80	0.102
88.79	-6.68	0.102
88.81	-6.55	0.102
88.84	-6.43	0.102
88.86	-6.30	0.103
88.89	-6.18	0.103
88.91	-6.05	0.103
88.94	-5.93	0.103
88.96	-5.80	0.103
88.99	-5.68	0.103
89.01	-5.55	0.103
89.04	-5.43	0.103
89.06	-5.30	0.103
89.09	-5.18	0.103
89.11	-5.05	0.103
89.14	-4.93	0.103
89.16	-4.80	0.103
89.19	-4.68	0.103
89.21	-4.55	0.103
89.24	-4.43	0.103
89.26	-4.30	0.103
89.29	-4.18	0.103
89.31	-4.05	0.103
89.34	-3.93	0.103
89.36	-3.80	0.103
89.39	-3.67	0.103
89.41	-3.55	0.103
89.44	-3.43	0.103
89.46	-3.30	0.103
89.49	-3.17	0.103
89.51	-3.05	0.103
89.54	-2.92	0.104
89.56	-2.80	0.104
89.59	-2.67	0.104
89.61	-2.55	0.104
89.64	-2.42	0.104
89.66	-2.30	0.104
89.69	-2.17	0.104
89.71	-2.05	0.104
89.74	-1.92	0.104
89.76	-1.80	0.104
89.79	-1.67	0.104
89.81	-1.55	0.104
89.84	-1.42	0.104
89.86	-1.30	0.104
89.89	-1.17	0.104
89.91	-1.05	0.104
89.94	-0.92	0.104
89.96	-0.80	0.104
89.99	-0.67	0.104
90.01	-0.55	0.104
90.04	-0.42	0.104
90.06	-0.30	0.104
90.09	-0.17	0.104
90.11	-0.05	0.104
90.14	0.08	0.104
90.16	0.20	0.104
90.19	0.33	0.104
90.21	0.45	0.104
90.24	0.58	0.104
90.26	0.70	0.104
90.29	0.83	0.104
90.31	0.96	0.105
90.34	1.08	0.105
90.36	1.20	0.105
90.39	1.33	0.105
90.41	1.46	0.105
90.44	1.58	0.105
90.46	1.71	0.105
90.49	1.83	0.105
90.51	1.96	0.105
90.54	2.08	0.105
90.56	2.21	0.105
90.59	2.33	0.105
90.61	2.46	0.105
90.64	2.58	0.105
90.66	2.71	0.105
90.69	2.83	0.105
90.71	2.96	0.105
90.74	3.08	0.105
90.76	3.21	0.105
90.79	3.33	0.105
90.81	3.46	0.105
90.84	3.58	0.105
90.86	3.71	0.105
90.89	3.83	0.106
90.91	3.96	0.106
90.94	4.08	0.106
90.96	4.21	0.106
90.99	4.33	0.106
91.01	4.46	0.106
91.04	4.58	0.106
91.06	4.71	0.106
91.09	4.83	0.106
91.11	4.96	0.106
91.14	5.08	0.106
91.16	5.21	0.106
91.19	5.33	0.106
91.21	5.46	0.106
91.24	5.58	0.106
91.26	5.71	0.107
91.29	5.83	0.107
91.31	5.96	0.107
91.34	6.08	0.107
91.36	6.21	0.107
91.39	6.33	0.107
91.41	6.46	0.107
91.44	6.58	0.107
91.46	6.71	0.107
91.49	6.84	0.107
91.51	6.96	0.107
91.54	7.08	0.107
91.56	7.21	0.107
91.59	7.34	0.107
91.61	7.46	0.107
91.64	7.59	0.107
91.66	7.71	0.107
91.69	7.84	0.107
91.71	7.96	0.107
91.74	8.09	0.107
91.76	8.21	0.107
91.79	8.34	0.107
91.81	8.46	0.107
91.84	8.59	0.107
91.86	8.71	0.107
91.89	8.84	0.107
91.91	8.96	0.107
91.94	9.09	0.107
91.96	9.21	0.108
91.99	9.34	0.108
92.01	9.46	0.108
92.04	9.59	0.108
92.06	9.71	0.108
92.09	9.84	0.108
92.11	9.96	0.108
92.14	10.09	0.108
92.16	10.21	0.108
92.19	10.34	0.108
92.21	10.46	0.108
92.24	10.59	0.108
92.26	10.71	0.108
92.29	10.84	0.108
92.31	10.96	0.108
92.34	11.09	0.108
92.36	11.21	0.108
92.39	11.34	0.108
92.41	11.46	0.108
92.44	11.59	0.108
92.46	11.71	0.108
92.49	11.84	0.108
92.51	11.96	0.108
92.54	12.09	0.108
92.56	12.21	0.108
92.59	12.34	0.108
92.61	12.46	0.108
92.64	12.59	0.109
92.66	12.71	0.109
92.69	12.84	0.108
92.71	12.96	0.108
92.74	13.09	0.108
92.76	13.21	0.108
92.79	13.34	0.108
92.81	13.47	0.108
92.84	13.59	0.109
92.86	13.72	0.109
92.89	13.84	0.109
92.91	13.97	0.109
92.94	14.09	0.109
92.96	14.22	0.109
92.99	14.34	0.109
93.01	14.47	0.109
93.04	14.59	0.109
93.06	14.72	0.109
93.09	14.84	0.109
93.11	14.97	0.109
93.14	15.09	0.110
93.16	15.22	0.110
93.19	15.34	0.110
93.21	15.47	0.110
93.24	15.59	0.110
93.26	15.72	0.110
93.29	15.84	0.110
93.31	15.97	0.110
93.34	16.09	0.110
93.36	16.22	0.110
93.39	16.34	0.110
93.41	16.47	0.110
93.44	16.59	0.110
93.46	16.72	0.110
93.49	16.84	0.110
93.51	16.97	0.110
93.54	17.09	0.111
93.56	17.22	0.111
93.59	17.34	0.111
93.61	17.47	0.111
93.64	17.59	0.111
93.66	17.72	0.111
93.69	17.84	0.111
93.71	17.97	0.111
93.74	18.09	0.111
93.76	18.22	0.111
93.79	18.34	0.111
93.81	18.47	0.111
93.84	18.59	0.111
93.86	18.72	0.111
93.89	18.84	0.111
93.91	18.97	0.111
93.94	19.10	0.111
93.96	19.22	0.112
93.99	19.35	0.112
94.01	19.47	0.112
94.04	19.59	0.112
94.06	19.72	0.112
94.09	19.84	0.112
94.11	19.97	0.112
94.14	20.10	0.112
94.16	20.22	0.112
94.19	20.35	0.112
94.21	20.47	0.112
94.24	20.60	0.112
94.26	20.72	0.112
94.29	20.85	0.112
94.31	20.97	0.112
94.34	21.10	0.112
94.36	21.22	0.113
94.39	21.35	0.113
94.41	21.47	0.113
94.44	21.60	0.113
94.46	21.72	0.113
94.49	21.85	0.113
94.51	21.97	0.113
94.54	22.10	0.113
94.56	22.22	0.113
94.59	22.35	0.113
94.61	22.47	0.113
94.64	22.60	0.113
94.66	22.72	0.113
94.69	22.85	0.114
94.71	22.97	0.114
94.74	23.10	0.114
94.76	23.22	0.114
94.79	23.35	0.114
94.81	23.47	0.114
94.84	23.60	0.114
94.86	23.72	0.114
94.89	23.85	0.114
94.91	23.97	0.114
94.94	24.10	0.114
94.96	24.22	0.114
94.99	24.35	0.114
95.01	24.47	0.114
95.04	24.60	0.114
95.06	24.72	0.114
95.09	24.85	0.114
95.11	24.97	0.114
95.14	25.10	0.114
95.16	25.22	0.115
95.19	25.35	0.115
95.21	25.47	0.115
95.24	25.60	0.115
95.26	25.72	0.115
95.29	25.85	0.115
95.31	25.97	0.115
95.34	26.10	0.115
95.36	26.22	0.115
95.39	26.35	0.115
95.41	26.47	0.115
95.44	26.60	0.115
95.46	26.72	0.115
95.49	26.85	0.115
95.51	26.98	0.115
95.54	27.10	0.115
95.56	27.23	0.115
95.59	27.35	0.116
95.61	27.48	0.116
95.64	27.60	0.116
95.66	27.73	0.116
95.69	27.85	0.116
95.71	27.98	0.116
95.74	28.10	0.116
95.76	28.22	0.116
95.79	28.35	0.116
95.81	28.48	0.116
95.84	28.60	0.116
95.86	28.73	0.116
95.89	28.85	0.116
95.91	28.98	0.116
95.94	29.10	0.117
95.96	29.23	0.117
95.99	29.35	0.117
96.01	29.48	0.117
96.04	29.60	0.117
96.06	29.73	0.117
96.09	29.85	0.117
96.11	29.98	0.117
96.14	30.10	0.117
96.16	30.23	0.117
96.19	30.35	0.117
96.21	30.48	0.117
96.24	30.60	0.117
96.26	30.73	0.117
96.29	30.85	0.118
96.31	30.98	0.118
96.34	31.10	0.118
96.36	31.23	0.118
96.39	31.35	0.118
96.41	31.48	0.118
96.44	31.60	0.118
96.46	31.73	0.118
96.49	31.85	0.118
96.51	31.98	0.118
96.54	32.10	0.118
96.56	32.23	0.118
96.59	32.35	0.118
96.61	32.48	0.118
96.64	32.60	0.118
96.66	32.73	0.119
96.69	32.85	0.119
96.71	32.98	0.119
96.74	33.10	0.119
96.76	33.23	0.119
96.79	33.36	0.119
96.81	33.48	0.119
96.84	33.60	0.119
96.86	33.73	0.119
96.89	33.86	0.119
96.91	33.98	0.119
96.94	34.11	0.119
96.96	34.23	0.119
96.99	34.35	0.119
97.01	34.48	0.119
97.04	34.61	0.119
97.06	34.73	0.120
97.09	34.86	0.120
97.11	34.98	0.120
97.14	35.11	0.120
97.16	35.23	0.120
97.19	35.36	0.120
97.21	35.48	0.120
97.24	35.61	0.120
97.26	35.73	0.120
97.29	35.86	0.120
97.31	35.98	0.120
97.34	36.11	0.120
97.36	36.23	0.120
97.39	36.36	0.121
97.41	36.48	0.120
97.44	36.61	0.121
97.46	36.73	0.121
97.49	36.86	0.121
97.51	36.98	0.121
97.54	37.11	0.121
97.56	37.23	0.121
97.59	37.36	0.121
97.61	37.48	0.121
97.64	37.61	0.121
97.66	37.73	0.121
97.69	37.86	0.121
97.71	37.98	0.121
97.74	38.11	0.122
97.76	38.23	0.122
97.79	38.36	0.122
97.81	38.48	0.122
97.84	38.61	0.122
97.86	38.73	0.122
97.89	38.86	0.122
97.91	38.98	0.122
97.94	39.11	0.122
97.96	39.23	0.123
97.99	39.36	0.123
98.01	39.48	0.123
98.04	39.61	0.123
98.06	39.73	0.123
98.09	39.86	0.123
98.11	39.98	0.123
98.14	40.11	0.123
98.16	40.23	0.123
98.19	40.36	0.123
98.21	40.48	0.123
98.24	40.61	0.123
98.26	40.73	0.123
98.29	40.86	0.123
98.31	40.98	0.123
98.34	41.11	0.123
98.36	41.23	0.123
98.39	41.36	0.124
98.41	41.48	0.124
98.44	41.61	0.124
98.46	41.73	0.124
98.49	41.86	0.124
98.51	41.98	0.124
98.54	42.11	0.124
98.56	42.23	0.124
98.59	42.36	0.124
98.61	42.48	0.124
98.64	42.61	0.124
98.66	42.73	0.124
98.69	42.86	0.124
98.71	42.99	0.125
98.74	43.11	0.125
98.76	43.23	0.125
98.79	43.36	0.125
98.81	43.48	0.125
98.84	43.61	0.125
98.86	43.74	0.125
98.89	43.86	0.125
98.91	43.99	0.125
98.94	44.11	0.125
98.96	44.24	0.126
98.99	44.36	0.126
99.01	44.49	0.126
99.04	44.61	0.126
99.06	44.74	0.126
99.09	44.86	0.126
99.11	44.99	0.126
99.14	45.11	0.126
99.16	45.24	0.126
99.19	45.36	0.126
99.21	45.49	0.126
99.24	45.61	0.127
99.26	45.74	0.127
99.29	45.86	0.127
99.31	45.99	0.127
99.34	46.11	0.127
99.36	46.24	0.127
99.39	46.36	0.127
99.41	46.49	0.127
99.44	46.61	0.127
99.46	46.74	0.127
99.49	46.86	0.127
99.51	46.99	0.127
99.54	47.11	0.127
99.56	47.24	0.128
99.59	47.36	0.128
99.61	47.49	0.128
99.64	47.61	0.128
99.66	47.74	0.128
99.69	47.86	0.128
99.71	47.99	0.128
99.74	48.11	0.128
99.76	48.24	0.128
99.79	48.36	0.128
99.81	48.49	0.128
99.84	48.61	0.128
99.86	48.74	0.129
99.89	48.86	0.129
99.91	48.99	0.129
99.94	49.11	0.129
99.96	49.24	0.129
99.99	49.36	0.129
100.01	49.49	0.129
100.04	49.61	0.129
100.06	49.74	0.129
100.09	49.86	0.129
100.11	49.99	0.130
100.14	50.11	0.130
100.16	50.24	0.130
100.19	50.36	0.130
100.21	50.49	0.130
100.24	50.61	0.130
100.26	50.74	0.130
100.29	50.86	0.130
100.31	50.99	0.130
100.34	51.12	0.130
100.36	51.24	0.130
100.39	51.37	0.131
100.41	51.49	0.131
100.44	51.61	0.131
100.46	51.74	0.131
100.49	51.87	0.131
100.51	51.99	0.131
100.54	52.12	0.131
100.56	52.24	0.131
100.59	52.37	0.131
100.61	52.49	0.131
100.64	52.62	0.132
100.66	52.74	0.132
100.69	52.87	0.132
100.71	52.99	0.132
100.74	53.12	0.132
100.76	53.24	0.132
100.79	53.37	0.132
100.81	53.49	0.132
100.84	53.62	0.132
100.86	53.74	0.133
100.89	53.87	0.133
100.91	53.99	0.133
100.94	54.12	0.133
100.96	54.24	0.133
100.99	54.37	0.133
101.01	54.49	0.133
101.04	54.62	0.133
101.06	54.74	0.133
101.09	54.87	0.133
101.11	54.99	0.133
101.14	55.12	0.134
101.16	55.24	0.134
101.19	55.37	0.134
101.21	55.49	0.134
101.24	55.62	0.134
101.26	55.74	0.134
101.29	55.87	0.134
101.31	55.99	0.134
101.34	56.12	0.134
101.36	56.24	0.135
101.39	56.37	0.135
101.41	56.49	0.135
101.44	56.62	0.135
101.46	56.74	0.135
101.49	56.87	0.135
101.51	56.99	0.135
101.54	57.12	0.136
101.56	57.24	0.136
101.59	57.37	0.136
101.61	57.50	0.136
101.64	57.62	0.136
101.66	57.75	0.136
101.69	57.87	0.136
101.71	58.00	0.136
101.74	58.12	0.136
101.76	58.24	0.137
101.79	58.37	0.137
101.81	58.49	0.137
101.84	58.62	0.137
101.86	58.74	0.137
101.89	58.87	0.137
101.91	58.99	0.137
101.94	59.12	0.137
101.96	59.24	0.137
101.99	59.37	0.138
102.01	59.49	0.138
102.04	59.62	0.138
102.06	59.75	0.138
102.09	59.87	0.138
102.11	59.99	0.138
102.14	60.12	0.138
102.16	60.25	0.138
102.19	60.37	0.138
102.21	60.50	0.139
102.24	60.62	0.139
102.26	60.75	0.139
102.29	60.87	0.139
102.31	61.00	0.139
102.34	61.12	0.139
102.36	61.25	0.139
102.39	61.37	0.139
102.41	61.50	0.139
102.44	61.62	0.139
102.46	61.75	0.140
102.49	61.87	0.140
102.51	62.00	0.140
102.54	62.12	0.140
102.56	62.25	0.140
102.59	62.37	0.140
102.61	62.50	0.140
102.64	62.62	0.140
102.66	62.75	0.141
102.69	62.87	0.141
102.71	63.00	0.141
102.74	63.12	0.141
102.76	63.25	0.141
102.79	63.37	0.141
102.81	63.50	0.141
102.84	63.62	0.141
102.86	63.75	0.142
102.89	63.87	0.142
102.91	64.00	0.142
102.94	64.12	0.142
102.96	64.25	0.142
102.99	64.37	0.142
103.01	64.50	0.142
103.04	64.62	0.142
103.06	64.75	0.142
103.09	64.87	0.143
103.11	65.00	0.143
103.14	65.12	0.143
103.16	65.25	0.143
103.19	65.37	0.143
103.21	65.50	0.143
103.24	65.62	0.143
103.26	65.75	0.143
103.29	65.87	0.144
103.31	66.00	0.144
103.34	66.12	0.144
103.36	66.25	0.144
103.39	66.37	0.144
103.41	66.50	0.144
103.44	66.62	0.144
103.46	66.75	0.144
103.49	66.87	0.145
103.51	67.00	0.145
103.54	67.12	0.145
103.56	67.25	0.145
103.59	67.37	0.145
103.61	67.50	0.145
103.64	67.62	0.145
103.66	67.75	0.145
103.69	67.87	0.146
103.71	68.00	0.146
103.74	68.12	0.146
103.76	68.25	0.146
103.79	68.38	0.146
103.81	68.50	0.146
103.84	68.62	0.146
103.86	68.75	0.146
103.89	68.87	0.146
103.91	69.00	0.146
103.94	69.12	0.147
103.96	69.25	0.147
103.99	69.37	0.147
104.01	69.50	0.147
104.04	69.62	0.147
104.06	69.75	0.147
104.09	69.88	0.147
104.11	70.00	0.147
104.14	70.13	0.148
104.16	70.25	0.148
104.19	70.38	0.148
104.21	70.50	0.148
104.24	70.63	0.148
104.26	70.75	0.148
104.29	70.88	0.148
104.31	71.00	0.148
104.34	71.13	0.149
104.36	71.25	0.149
104.39	71.38	0.149
104.41	71.50	0.149
104.44	71.63	0.149
104.46	71.75	0.149
104.49	71.88	0.149
104.51	72.00	0.150
104.54	72.13	0.150
104.56	72.25	0.150
104.59	72.38	0.150
104.61	72.50	0.150
104.64	72.63	0.150
104.66	72.75	0.150
104.69	72.88	0.150
104.71	73.00	0.150
104.74	73.13	0.151
104.76	73.25	0.151
104.79	73.38	0.151
104.81	73.50	0.151
104.84	73.63	0.151
104.86	73.75	0.151
104.89	73.88	0.151
104.91	74.00	0.151
104.94	74.13	0.151
104.96	74.25	0.152
104.99	74.38	0.152
105.01	74.50	0.152
105.04	74.63	0.152
105.06	74.75	0.152
105.09	74.88	0.152
105.11	75.00	0.152
105.14	75.13	0.153
105.16	75.25	0.153
105.19	75.38	0.153
105.21	75.50	0.153
105.24	75.63	0.153
105.26	75.75	0.153
105.29	75.88	0.153
105.31	76.00	0.153
105.34	76.13	0.154
105.36	76.25	0.154
105.39	76.38	0.154
105.41	76.50	0.154
105.44	76.63	0.154
105.46	76.75	0.154
105.49	76.88	0.154
105.51	77.00	0.154
105.54	77.13	0.155
105.56	77.25	0.155
105.59	77.38	0.155
105.61	77.50	0.155
105.64	77.63	0.155
105.66	77.75	0.155
105.69	77.88	0.155
105.71	78.00	0.156
105.74	78.13	0.156
105.76	78.25	0.156
105.79	78.38	0.156
105.81	78.50	0.156
105.84	78.63	0.156
105.86	78.75	0.156
105.89	78.88	0.157
105.91	79.00	0.157
105.94	79.13	0.157
105.96	79.26	0.157
105.99	79.38	0.157
106.01	79.50	0.157
106.04	79.63	0.157
106.06	79.76	0.158
106.09	79.88	0.158
106.11	80.01	0.158
106.14	80.13	0.158
106.16	80.25	0.158
106.19	80.38	0.158
106.21	80.51	0.158
106.24	80.63	0.158
106.26	80.76	0.159
106.29	80.88	0.159
106.31	81.01	0.159
106.34	81.13	0.159
106.36	81.26	0.159
106.39	81.38	0.159
106.41	81.51	0.159
106.44	81.63	0.160
106.46	81.76	0.160
106.49	81.88	0.160
106.51	82.01	0.160
106.54	82.13	0.160
106.56	82.26	0.160
106.59	82.38	0.160
106.61	82.51	0.160
106.64	82.63	0.160
106.66	82.76	0.161
106.69	82.88	0.161
106.71	83.01	0.161
106.74	83.13	0.161
106.76	83.26	0.161
106.79	83.38	0.161
106.81	83.51	0.161
106.84	83.63	0.161
106.86	83.76	0.161
106.89	83.88	0.162
106.91	84.01	0.162
106.94	84.13	0.162
106.96	84.26	0.162
106.99	84.38	0.162
107.01	84.51	0.162
107.04	84.63	0.163
107.06	84.76	0.163
107.09	84.88	0.163
107.11	85.01	0.163
107.14	85.13	0.163
107.16	85.26	0.163
107.19	85.38	0.163
107.21	85.51	0.163
107.24	85.63	0.164
107.26	85.76	0.164
107.29	85.88	0.164
107.31	86.01	0.164
107.34	86.13	0.164
107.36	86.26	0.164
107.39	86.38	0.164
107.41	86.51	0.165
107.44	86.63	0.165
107.46	86.76	0.165
107.49	86.88	0.165
107.51	87.01	0.165
107.54	87.13	0.165
107.56	87.26	0.165
107.59	87.38	0.165
107.61	87.51	0.166
107.64	87.63	0.166
107.66	87.76	0.166
107.69	87.88	0.166
107.71	88.01	0.166
107.74	88.13	0.166
107.76	88.26	0.166
107.79	88.38	0.167
107.81	88.51	0.167
107.84	88.63	0.167
107.86	88.76	0.167
107.89	88.88	0.167
107.91	89.01	0.167
107.94	89.13	0.168
107.96	89.26	0.168
107.99	89.38	0.168
108.01	89.51	0.168
108.04	89.63	0.168
108.06	89.76	0.168
108.09	89.88	0.169
108.11	90.01	0.169
108.14	90.13	0.169
108.16	90.26	0.169
108.19	90.38	0.169
108.21	90.51	0.169
108.24	90.63	0.170
108.26	90.76	0.170
108.29	90.88	0.170
108.31	91.01	0.170
108.34	91.13	0.170
108.36	91.26	0.170
108.39	91.38	0.170
108.41	91.51	0.171
108.44	91.63	0.171
108.46	91.76	0.171
108.49	91.88	0.171
108.51	92.01	0.171
108.54	92.13	0.172
108.56	92.26	0.172
108.59	92.38	0.172
108.61	92.51	0.172
108.64	92.63	0.172
108.66	92.76	0.173
108.69	92.89	0.173
108.71	93.01	0.173
108.74	93.14	0.173
108.76	93.26	0.173
108.79	93.39	0.174
108.81	93.51	0.174
108.84	93.63	0.174
108.86	93.76	0.174
108.89	93.89	0.174
108.91	94.01	0.175
108.94	94.14	0.175
108.96	94.26	0.175
108.99	94.39	0.175
109.01	94.51	0.175
109.04	94.64	0.175
109.06	94.76	0.176
109.09	94.89	0.176
109.11	95.01	0.176
109.14	95.14	0.176
109.16	95.26	0.177
109.19	95.39	0.177
109.21	95.51	0.177
109.24	95.64	0.177
109.26	95.76	0.177
109.29	95.89	0.178
109.31	96.01	0.178
109.34	96.14	0.178
109.36	96.26	0.178
109.39	96.39	0.178
109.41	96.51	0.178
109.44	96.64	0.178
109.46	96.76	0.179
109.49	96.89	0.179
109.51	97.01	0.179
109.54	97.14	0.179
109.56	97.26	0.179
109.59	97.39	0.179
109.61	97.51	0.180
109.64	97.64	0.180
109.66	97.76	0.180
109.69	97.89	0.180
109.71	98.01	0.180
109.74	98.14	0.180
109.76	98.26	0.181
109.79	98.39	0.181
109.81	98.51	0.181
109.84	98.64	0.181
109.86	98.76	0.181
109.89	98.89	0.181
109.91	99.01	0.182
109.94	99.14
109.96	99.26
109.99