File: DSC/2023_06_29_CBD_Fragility_SBK.txt
Filename	2023_06_29_CBD_Fragility_SBK
Instrument name	DSC2A-00468 (192.168.1.100)
Operator	SBK
rundate	6/29/2023
Sample name	2023_06_29_CBD_Fragiity_SBK
proceduresegments	Data Off ; Equilibrate -50.00 °C; Data On ; Ramp 10.00 °C/min to 100.00 °C; Data Off ; Isothermal 1.0 min; Data On ; Ramp 10.00 °C/min to -50.00 °C; Data Off ; Isothermal 1.0 min; Data On ; Ramp 10.00 °C/min to 40.00 °C; Data Off ; Isothermal 1.0 min; Data On ; Ramp 35.00 °C/min to -50.00 °C; Data Off ; Isothermal 1.0 min; Data On ; Ramp 10.00 °C/min to 40.00 °C; Data Off ; Isothermal 1.0 min; Data On ; Ramp 25.00 °C/min to -50.00 °C; Data Off ; Isothermal 1.0 min; Data On ; Ramp 10.00 °C/min to 40.00 °C; Data Off ; Isothermal 1.0 min; Data On ; Ramp 20.00 °C/min to -50.00 °C; Data Off ; Isothermal 1.0 min; Data On ; Ramp 10.00 °C/min to 40.00 °C; Data Off ; Isothermal 1.0 min; Data On ; Sample Interval  0.2 s/pt; Ramp 5.00 °C/min to -50.00 °C; Data Off ; Isothermal 1.0 min; Data On ; Sample Interval  0.1 s/pt; Ramp 10.00 °C/min to 40.00 °C; Data Off ; Isothermal 1.0 min; Data On ; Sample Interval  1.0 s/pt; Ramp 1.00 °C/min to -50.00 °C; Data Off ; Isothermal 1.0 min; Data On ; Sample Interval  0.1 s/pt; Ramp 10.00 °C/min to 40.00 °C; Data Off ; Isothermal 1.0 min; Data On ; Sample Interval  2.0 s/pt; Ramp 0.50 °C/min to -50.00 °C; Data Off ; Isothermal 1.0 min; Data On ; Sample Interval  0.1 s/pt; Ramp 10.00 °C/min to 40.00 °C
[File Parameters]
Run date	6/29/2023 11:23:26 AM
Trios version	5.1.1.46572
Original File Name	C:\Users\yargerlab\Desktop\DSC Data\General\2023_06_29_CBD_Fragiity_SBK.tri
Current File Name	C:\Users\kauff\Documents\ASU\data_DSC\2023_06_29_CBD_Fragility_SBK.tri
[Procedure]
Procedure Name	DSC -50C to 40C Varied cooling rates CBD fragility
Sample Name	2023_06_29_CBD_Fragiity_SBK
Sample Mass	3.95 mg
Reference Sample Mass	0 mg
Pan Mass	53.51 mg
Pan Number	41
Reference Pan Mass	53.66 mg
Reference Pan Number	46
Pan Type	Aluminum Hermetic
Comments	CBD powder, likely crystaline, newly prepared sample. DSC84010 aluminum pan and DSC84011 aluminum hermetic lid.
Project Name	Silk ASDs
Operator	SBK
Test	Custom
Unload Max Temperature	30
Unload Min Temperature	30
Load Max Temperature	30
Load Min Temperature	30
Stop on Gas Flow Error	Yes
[Signal List]
Signal #1	Time (min)
Signal #2	Temperature (°C)
Signal #3	Heat Flow (mW)
Signal #4	Delta T (µV)
Signal #5	Delta Tzero (µV)
Signal #6	Tzero Temperature (°C)
Signal #7	Cell Purge (mL/min)
Signal #8	Heater Temp (°C)
Signal #9	Power Delivered (W)
Signal #10	Reference Junction Temperature (°C)
Signal #11	Flange Temperature (°C)
Signal #12	Heat Flow Phase (rad)
Signal #13	Total Heat Capacity (J/°C)
Signal #14	Heat Capacity (J/°C)
[Configuration]
Company Name	ASU
Instrument Name	DSC2A-00468
Instrument Type	DSC2500
Serial Number	DSC2A-00468
IP	192.168.1.100
Location of Instrument	MRRC
DisplayType	Unknown
Sample Interval 	0.1 s/pt
Selected Heat Flow	T4P
Exotherm Direction	Down
Cell Serial	DRC2-00792
Lid Type	Standard
Cooler	RCS 90
Leave Cooler on at End of Sequence	On
Gas 2	Nitrogen
Gas Selected	Channel 1
Flow Rate	50 mL/min
Secondary Purge	On
Licensed Heat Flow	Heat Flow T4P
Modulation Licensed	Yes
[Versions]
Common IDD Version	1
Cortex Version	VER 2.10.2.31
Driver	5.0.0.6
GDM Version	1.0.3.3
TouchscreenVersion	1.0.0.16145
FEP Version	1.2.1.21
FEP Bootloader	2.0.0.5
AutoSampler Version	2.1.1.26
Auto Sampler Bootloader	2.0.0.5
FCM Version	1.1.0.3
FCM Bootloader	2.0.0.5
[Experiment Logs]
Experiment Log Entry # 1	Data On set to 0
Experiment Log Entry # 3	Equilibrate Segment -50 (C) Started
Experiment Log Entry # 5	Air Cool is off.
Experiment Log Entry # 7	Data On set to 1
Experiment Log Entry # 9	Ramp Segment 10 C/min to 100 Started
Experiment Log Entry # 11	Data On set to 0
Experiment Log Entry # 13	Isothermal Segment 1 min started
Experiment Log Entry # 15	Data On set to 1
Experiment Log Entry # 17	Ramp Segment 10 C/min to -50 Started
Experiment Log Entry # 19	Data On set to 0
Experiment Log Entry # 21	Isothermal Segment 1 min started
Experiment Log Entry # 23	Data On set to 1
Experiment Log Entry # 25	Ramp Segment 10 C/min to 40 Started
Experiment Log Entry # 27	Data On set to 0
Experiment Log Entry # 29	Isothermal Segment 1 min started
Experiment Log Entry # 31	Data On set to 1
Experiment Log Entry # 33	Ramp Segment 35 C/min to -50 Started
Experiment Log Entry # 35	Data On set to 0
Experiment Log Entry # 37	Isothermal Segment 1 min started
Experiment Log Entry # 39	Data On set to 1
Experiment Log Entry # 41	Ramp Segment 10 C/min to 40 Started
Experiment Log Entry # 43	Data On set to 0
Experiment Log Entry # 45	Isothermal Segment 1 min started
Experiment Log Entry # 47	Data On set to 1
Experiment Log Entry # 49	Ramp Segment 25 C/min to -50 Started
Experiment Log Entry # 51	Data On set to 0
Experiment Log Entry # 53	Isothermal Segment 1 min started
Experiment Log Entry # 55	Data On set to 1
Experiment Log Entry # 57	Ramp Segment 10 C/min to 40 Started
Experiment Log Entry # 59	Data On set to 0
Experiment Log Entry # 61	Isothermal Segment 1 min started
Experiment Log Entry # 63	Data On set to 1
Experiment Log Entry # 65	Ramp Segment 20 C/min to -50 Started
Experiment Log Entry # 67	Data On set to 0
Experiment Log Entry # 69	Isothermal Segment 1 min started
Experiment Log Entry # 71	Data On set to 1
Experiment Log Entry # 73	Ramp Segment 10 C/min to 40 Started
Experiment Log Entry # 75	Data On set to 0
Experiment Log Entry # 77	Isothermal Segment 1 min started
Experiment Log Entry # 79	Data On set to 1
Experiment Log Entry # 81	Sampling Rate set to 0.2 sec/pt
Experiment Log Entry # 83	Ramp Segment 5 C/min to -50 Started
Experiment Log Entry # 85	Data On set to 0
Experiment Log Entry # 87	Isothermal Segment 1 min started
Experiment Log Entry # 89	Data On set to 1
Experiment Log Entry # 91	Sampling Rate set to 0.1 sec/pt
Experiment Log Entry # 93	Ramp Segment 10 C/min to 40 Started
Experiment Log Entry # 95	Data On set to 0
Experiment Log Entry # 97	Isothermal Segment 1 min started
Experiment Log Entry # 99	Data On set to 1
Experiment Log Entry # 101	Sampling Rate set to 1 sec/pt
Experiment Log Entry # 103	Ramp Segment 1 C/min to -50 Started
Experiment Log Entry # 105	Data On set to 0
Experiment Log Entry # 107	Isothermal Segment 1 min started
Experiment Log Entry # 109	Data On set to 1
Experiment Log Entry # 111	Sampling Rate set to 0.1 sec/pt
Experiment Log Entry # 113	Ramp Segment 10 C/min to 40 Started
Experiment Log Entry # 115	Data On set to 0
Experiment Log Entry # 117	Isothermal Segment 1 min started
Experiment Log Entry # 119	Data On set to 1
Experiment Log Entry # 121	Sampling Rate set to 2 sec/pt
Experiment Log Entry # 123	Ramp Segment 0.5 C/min to -50 Started
Experiment Log Entry # 125	Data On set to 0
Experiment Log Entry # 127	Isothermal Segment 1 min started
Experiment Log Entry # 129	Data On set to 1
Experiment Log Entry # 131	Sampling Rate set to 0.1 sec/pt
Experiment Log Entry # 133	Ramp Segment 10 C/min to 40 Started
[Method Log]
Method Log Entry # 1	Data Off
Method Log Entry # 2	Equilibrate -50 °C
Method Log Entry # 3	Data On
Method Log Entry # 4	(Ramp 9842) Ramp 10 °C/minute to 100 °C
Method Log Entry # 5	Data Off
Method Log Entry # 6	Isothermal 1 minutes
Method Log Entry # 7	Data On
Method Log Entry # 8	(Ramp 9846) Ramp 10 °C/minute to -50 °C
Method Log Entry # 9	Data Off
Method Log Entry # 10	Isothermal 1 minutes
Method Log Entry # 11	Data On
Method Log Entry # 12	(Ramp 9850) Ramp 10 °C/minute to 40 °C
Method Log Entry # 13	Data Off
Method Log Entry # 14	Isothermal 1 minutes
Method Log Entry # 15	Data On
Method Log Entry # 16	(Ramp 9854) Ramp 35 °C/minute to -50 °C
Method Log Entry # 17	Data Off
Method Log Entry # 18	Isothermal 1 minutes
Method Log Entry # 19	Data On
Method Log Entry # 20	(Ramp 9858) Ramp 10 °C/minute to 40 °C
Method Log Entry # 21	Data Off
Method Log Entry # 22	Isothermal 1 minutes
Method Log Entry # 23	Data On
Method Log Entry # 24	(Ramp 9862) Ramp 25 °C/minute to -50 °C
Method Log Entry # 25	Data Off
Method Log Entry # 26	Isothermal 1 minutes
Method Log Entry # 27	Data On
Method Log Entry # 28	(Ramp 9866) Ramp 10 °C/minute to 40 °C
Method Log Entry # 29	Data Off
Method Log Entry # 30	Isothermal 1 minutes
Method Log Entry # 31	Data On
Method Log Entry # 32	(Ramp 9870) Ramp 20 °C/minute to -50 °C
Method Log Entry # 33	Data Off
Method Log Entry # 34	Isothermal 1 minutes
Method Log Entry # 35	Data On
Method Log Entry # 36	(Ramp 9874) Ramp 10 °C/minute to 40 °C
Method Log Entry # 37	Data Off
Method Log Entry # 38	Isothermal 1 minutes
Method Log Entry # 39	Data On
Method Log Entry # 40	Sampling Interval 0.2 Seconds/point
Method Log Entry # 41	(Ramp 9879) Ramp 5 °C/minute to -50 °C
Method Log Entry # 42	Data Off
Method Log Entry # 43	Isothermal 1 minutes
Method Log Entry # 44	Data On
Method Log Entry # 45	Sampling Interval 0.1 Seconds/point
Method Log Entry # 46	(Ramp 9884) Ramp 10 °C/minute to 40 °C
Method Log Entry # 47	Data Off
Method Log Entry # 48	Isothermal 1 minutes
Method Log Entry # 49	Data On
Method Log Entry # 50	Sampling Interval 1 Seconds/point
Method Log Entry # 51	(Ramp 9889) Ramp 1 °C/minute to -50 °C
Method Log Entry # 52	Data Off
Method Log Entry # 53	Isothermal 1 minutes
Method Log Entry # 54	Data On
Method Log Entry # 55	Sampling Interval 0.1 Seconds/point
Method Log Entry # 56	(Ramp 9894) Ramp 10 °C/minute to 40 °C
Method Log Entry # 57	Data Off
Method Log Entry # 58	Isothermal 1 minutes
Method Log Entry # 59	Data On
Method Log Entry # 60	Sampling Interval 2 Seconds/point
Method Log Entry # 61	(Ramp 9899) Ramp 0.5 °C/minute to -50 °C
Method Log Entry # 62	Data Off
Method Log Entry # 63	Isothermal 1 minutes
Method Log Entry # 64	Data On
Method Log Entry # 65	Sampling Interval 0.1 Seconds/point
Method Log Entry # 66	(Ramp 9904) Ramp 10 °C/minute to 40 °C
Cell Serial	DRC2-00792
[T1 Calibration]
Slope	-0.008529666
Offset	9.636258
Initial Temperature	98.23
GUID	f8bfdadc-4977-4fdf-ba6d-0ba9134940c3
[TZero Calibration]
Date Applied	11/29/2022 4:06:13 PM
Description	From -89.059 °C to 396.009 °C at 20.000°C/min
Gas Type	Nitrogen
Pan Type	None
Source Files 1	C:\Users\yargerlab\Desktop\DSC Data\General\TZero_calibration_11_29_22_2nd(2).tri
Source Files 2	C:\Users\yargerlab\Desktop\DSC Data\General\TZero_calibration_11_29_22_2nd(3).tri
Delta T Offset	13.05235
Delta T Slope	-0.007271007
Delta T0 Offset	-13.69128
Delta T0 Slope	0.06063341
[Temperature Calibration]
Date Applied	11/29/2022 7:12:28 PM
Description	From 106.590 °C to 186.590 °C at 10.000°C/min
Gas Type	Nitrogen
Pan Type	Tzero Aluminum Hermetic
Source Files 1	C:\Users\yargerlab\Desktop\DSC Data\General\Indium(6).tri
Measured 1	157.391
Known 1	156.598
[Cell Constant Calibration]
Date Applied	11/29/2022 7:12:29 PM
Description	From 106.590 °C to 186.590 °C at 10.000°C/min
Gas Type	Nitrogen
Pan Type	Tzero Aluminum Hermetic
Source Files 1	C:\Users\yargerlab\Desktop\DSC Data\General\Indium(6).tri
T4P KCell	1.006051
Onset Slope	63.26126 mW/°C
[Direct Cp Calibration]
Date Applied	11/30/2022 11:04:51 AM
Description	From -79.983 °C to 298.409 °C at 10.000°C/min
Gas Type	Nitrogen
Pan Type	Tzero Aluminum Hermetic
Source Files 1	C:\Users\yargerlab\Desktop\DSC Data\General\Sapphire_Heat_Capacity_11_30_22.tri
[Rev Cp Calibration]
Date Applied	11/30/2022 1:58:51 PM
Description	From -79.996 °C to 292.812 °C at 3.000°C/min
Gas Type	Nitrogen
Pan Type	Tzero Aluminum Hermetic
Source Files 1	C:\Users\yargerlab\Desktop\DSC Data\General\Sapphire_MDSC_Calibration_11_30_22.tri
[step]
Ramp 10.00 °C/min to 100.00 °C
Time	Temperature	Heat Flow (Normalized)	Heat Capacity (Normalized)
min	°C	W/g	J/(g.°C)
0.00	-49.73	-0.048	0.000
0.01	-49.74	-0.048	23.480
0.02	-49.74	-0.045	0.000
0.03	-49.75	-0.043	0.000
0.04	-49.75	-0.039	0.000
0.05	-49.75	-0.036	0.000
0.06	-49.74	-0.033	0.000
0.07	-49.74	-0.031	-0.923
0.08	-49.73	-0.029	-0.716
0.09	-49.71	-0.027	-0.563
0.10	-49.68	-0.025	-0.449
0.11	-49.65	-0.022	-0.351
0.12	-49.61	-0.018	-0.255
0.13	-49.57	-0.013	-0.167
0.14	-49.52	-0.006	-0.066
0.15	-49.47	0.004	0.042
0.16	-49.41	0.015	0.149
0.17	-49.35	0.024	0.221
0.18	-49.29	0.036	0.308
0.19	-49.22	0.048	0.385
0.20	-49.14	0.059	0.456
0.21	-49.07	0.069	0.511
0.22	-48.99	0.082	0.587
0.23	-48.92	0.092	0.635
0.24	-48.84	0.103	0.690
0.25	-48.76	0.111	0.726
0.26	-48.67	0.120	0.773
0.27	-48.59	0.128	0.807
0.28	-48.50	0.136	0.841
0.29	-48.42	0.142	0.868
0.30	-48.33	0.148	0.893
0.31	-48.25	0.153	0.914
0.32	-48.16	0.159	0.942
0.33	-48.07	0.162	0.952
0.34	-47.98	0.169	0.984
0.35	-47.89	0.170	0.981
0.36	-47.80	0.175	1.000
0.37	-47.70	0.179	1.020
0.38	-47.61	0.182	1.031
0.39	-47.52	0.184	1.036
0.40	-47.43	0.187	1.045
0.41	-47.33	0.189	1.054
0.42	-47.24	0.192	1.064
0.43	-47.14	0.195	1.078
0.44	-47.05	0.196	1.079
0.45	-46.95	0.198	1.088
0.46	-46.86	0.198	1.087
0.47	-46.76	0.201	1.097
0.48	-46.67	0.202	1.099
0.49	-46.57	0.203	1.103
0.50	-46.48	0.204	1.108
0.51	-46.38	0.204	1.107
0.52	-46.28	0.206	1.113
0.53	-46.19	0.208	1.120
0.54	-46.09	0.208	1.120
0.55	-45.99	0.209	1.122
0.56	-45.90	0.209	1.123
0.57	-45.80	0.210	1.125
0.58	-45.70	0.210	1.126
0.59	-45.60	0.210	1.128
0.60	-45.51	0.211	1.128
0.61	-45.41	0.211	1.129
0.62	-45.31	0.212	1.132
0.63	-45.22	0.212	1.132
0.64	-45.12	0.212	1.132
0.65	-45.02	0.212	1.132
0.66	-44.92	0.213	1.133
0.67	-44.82	0.213	1.133
0.68	-44.73	0.213	1.133
0.69	-44.63	0.213	1.134
0.70	-44.53	0.214	1.136
0.71	-44.43	0.214	1.136
0.72	-44.33	0.214	1.137
0.73	-44.23	0.214	1.137
0.74	-44.14	0.215	1.137
0.75	-44.04	0.215	1.138
0.76	-43.94	0.215	1.139
0.77	-43.84	0.215	1.140
0.78	-43.74	0.215	1.140
0.79	-43.65	0.216	1.141
0.80	-43.55	0.216	1.142
0.81	-43.45	0.216	1.142
0.82	-43.35	0.216	1.142
0.83	-43.25	0.216	1.143
0.84	-43.15	0.217	1.143
0.85	-43.05	0.217	1.145
0.86	-42.95	0.217	1.145
0.87	-42.86	0.217	1.146
0.88	-42.76	0.217	1.146
0.89	-42.66	0.217	1.147
0.90	-42.56	0.218	1.147
0.91	-42.46	0.218	1.148
0.92	-42.36	0.218	1.148
0.93	-42.26	0.218	1.149
0.94	-42.16	0.218	1.150
0.95	-42.06	0.218	1.151
0.96	-41.96	0.218	1.150
0.97	-41.87	0.219	1.151
0.98	-41.77	0.219	1.151
0.99	-41.67	0.219	1.152
1.00	-41.57	0.219	1.152
1.01	-41.47	0.219	1.152
1.02	-41.37	0.219	1.153
1.03	-41.27	0.219	1.154
1.04	-41.17	0.219	1.155
1.05	-41.07	0.219	1.155
1.06	-40.97	0.219	1.155
1.07	-40.87	0.219	1.155
1.08	-40.77	0.220	1.155
1.09	-40.67	0.220	1.155
1.10	-40.57	0.220	1.156
1.11	-40.47	0.220	1.156
1.12	-40.38	0.220	1.156
1.13	-40.28	0.220	1.156
1.14	-40.18	0.220	1.156
1.15	-40.08	0.220	1.156
1.16	-39.98	0.220	1.156
1.17	-39.88	0.220	1.157
1.18	-39.78	0.220	1.157
1.19	-39.68	0.220	1.156
1.20	-39.58	0.220	1.157
1.21	-39.48	0.220	1.157
1.22	-39.38	0.220	1.158
1.23	-39.28	0.220	1.158
1.24	-39.18	0.220	1.158
1.25	-39.08	0.220	1.158
1.26	-38.98	0.220	1.159
1.27	-38.88	0.221	1.159
1.28	-38.78	0.221	1.158
1.29	-38.68	0.221	1.159
1.30	-38.58	0.221	1.159
1.31	-38.48	0.221	1.158
1.32	-38.38	0.221	1.159
1.33	-38.28	0.221	1.160
1.34	-38.18	0.221	1.160
1.35	-38.08	0.221	1.159
1.36	-37.99	0.221	1.159
1.37	-37.88	0.221	1.160
1.38	-37.78	0.221	1.161
1.39	-37.69	0.221	1.161
1.40	-37.59	0.221	1.160
1.41	-37.48	0.221	1.160
1.42	-37.38	0.221	1.160
1.43	-37.29	0.221	1.161
1.44	-37.19	0.221	1.161
1.45	-37.09	0.221	1.161
1.46	-36.99	0.221	1.161
1.47	-36.89	0.221	1.162
1.48	-36.79	0.221	1.162
1.49	-36.69	0.221	1.162
1.50	-36.59	0.221	1.162
1.51	-36.49	0.221	1.162
1.52	-36.39	0.221	1.162
1.53	-36.29	0.221	1.162
1.54	-36.19	0.221	1.162
1.55	-36.09	0.221	1.162
1.56	-35.99	0.221	1.163
1.57	-35.89	0.221	1.162
1.58	-35.79	0.221	1.162
1.59	-35.69	0.221	1.163
1.60	-35.59	0.221	1.163
1.61	-35.49	0.221	1.163
1.62	-35.39	0.221	1.163
1.63	-35.29	0.221	1.163
1.64	-35.19	0.221	1.164
1.65	-35.09	0.221	1.164
1.66	-34.99	0.221	1.165
1.67	-34.89	0.221	1.164
1.68	-34.79	0.221	1.164
1.69	-34.69	0.221	1.164
1.70	-34.59	0.221	1.164
1.71	-34.49	0.221	1.165
1.72	-34.39	0.221	1.165
1.73	-34.29	0.221	1.165
1.74	-34.19	0.221	1.165
1.75	-34.09	0.222	1.165
1.76	-33.99	0.221	1.165
1.77	-33.89	0.221	1.166
1.78	-33.79	0.221	1.166
1.79	-33.69	0.221	1.165
1.80	-33.59	0.221	1.165
1.81	-33.49	0.221	1.165
1.82	-33.39	0.221	1.165
1.83	-33.29	0.221	1.165
1.84	-33.19	0.221	1.166
1.85	-33.09	0.221	1.165
1.86	-32.99	0.221	1.166
1.87	-32.89	0.221	1.165
1.88	-32.79	0.221	1.166
1.89	-32.69	0.221	1.166
1.90	-32.59	0.221	1.165
1.91	-32.49	0.221	1.166
1.92	-32.39	0.221	1.166
1.93	-32.29	0.221	1.166
1.94	-32.19	0.221	1.165
1.95	-32.09	0.222	1.166
1.96	-31.99	0.222	1.167
1.97	-31.89	0.222	1.167
1.98	-31.79	0.222	1.167
1.99	-31.69	0.222	1.168
2.00	-31.59	0.222	1.167
2.01	-31.49	0.222	1.167
2.02	-31.39	0.222	1.167
2.03	-31.29	0.222	1.168
2.04	-31.19	0.222	1.168
2.05	-31.09	0.222	1.169
2.06	-30.99	0.222	1.169
2.07	-30.89	0.222	1.169
2.08	-30.79	0.222	1.168
2.09	-30.69	0.222	1.168
2.10	-30.59	0.222	1.169
2.11	-30.49	0.222	1.169
2.12	-30.39	0.222	1.169
2.13	-30.29	0.222	1.168
2.14	-30.19	0.222	1.169
2.15	-30.09	0.222	1.169
2.16	-29.99	0.222	1.169
2.17	-29.89	0.222	1.169
2.18	-29.79	0.222	1.169
2.19	-29.68	0.222	1.169
2.20	-29.59	0.222	1.169
2.21	-29.48	0.222	1.169
2.22	-29.38	0.222	1.170
2.23	-29.29	0.222	1.170
2.24	-29.19	0.222	1.170
2.25	-29.09	0.222	1.170
2.26	-28.98	0.222	1.170
2.27	-28.89	0.222	1.170
2.28	-28.78	0.222	1.171
2.29	-28.68	0.222	1.172
2.30	-28.58	0.222	1.171
2.31	-28.48	0.222	1.172
2.32	-28.38	0.222	1.172
2.33	-28.28	0.222	1.172
2.34	-28.18	0.222	1.172
2.35	-28.08	0.222	1.172
2.36	-27.98	0.222	1.172
2.37	-27.88	0.222	1.172
2.38	-27.78	0.222	1.174
2.39	-27.68	0.222	1.173
2.40	-27.58	0.222	1.173
2.41	-27.48	0.222	1.174
2.42	-27.38	0.222	1.173
2.43	-27.28	0.222	1.173
2.44	-27.18	0.222	1.173
2.45	-27.08	0.222	1.174
2.46	-26.98	0.222	1.174
2.47	-26.88	0.222	1.174
2.48	-26.78	0.222	1.174
2.49	-26.68	0.222	1.173
2.50	-26.58	0.222	1.174
2.51	-26.48	0.222	1.174
2.52	-26.38	0.222	1.174
2.53	-26.28	0.222	1.174
2.54	-26.18	0.222	1.174
2.55	-26.08	0.222	1.174
2.56	-25.98	0.222	1.174
2.57	-25.88	0.222	1.174
2.58	-25.78	0.222	1.174
2.59	-25.68	0.222	1.175
2.60	-25.58	0.222	1.175
2.61	-25.48	0.222	1.174
2.62	-25.38	0.222	1.175
2.63	-25.28	0.222	1.175
2.64	-25.18	0.222	1.175
2.65	-25.08	0.222	1.175
2.66	-24.98	0.222	1.175
2.67	-24.88	0.222	1.175
2.68	-24.78	0.222	1.175
2.69	-24.68	0.222	1.176
2.70	-24.58	0.222	1.176
2.71	-24.48	0.222	1.177
2.72	-24.38	0.222	1.177
2.73	-24.28	0.222	1.176
2.74	-24.18	0.222	1.177
2.75	-24.08	0.222	1.178
2.76	-23.98	0.222	1.178
2.77	-23.88	0.222	1.177
2.78	-23.78	0.222	1.177
2.79	-23.68	0.222	1.178
2.80	-23.58	0.222	1.178
2.81	-23.48	0.222	1.178
2.82	-23.38	0.222	1.178
2.83	-23.28	0.222	1.178
2.84	-23.18	0.222	1.178
2.85	-23.08	0.223	1.179
2.86	-22.98	0.223	1.179
2.87	-22.88	0.222	1.178
2.88	-22.78	0.223	1.178
2.89	-22.68	0.223	1.179
2.90	-22.58	0.223	1.178
2.91	-22.48	0.223	1.179
2.92	-22.38	0.223	1.179
2.93	-22.28	0.223	1.179
2.94	-22.18	0.223	1.179
2.95	-22.08	0.223	1.179
2.96	-21.98	0.223	1.179
2.97	-21.87	0.223	1.179
2.98	-21.78	0.222	1.179
2.99	-21.67	0.222	1.178
3.00	-21.58	0.222	1.179
3.01	-21.48	0.223	1.179
3.02	-21.38	0.223	1.179
3.03	-21.27	0.223	1.180
3.04	-21.17	0.223	1.180
3.05	-21.08	0.223	1.180
3.06	-20.97	0.223	1.180
3.07	-20.88	0.223	1.180
3.08	-20.77	0.223	1.181
3.09	-20.67	0.223	1.181
3.10	-20.57	0.223	1.181
3.11	-20.47	0.223	1.181
3.12	-20.37	0.223	1.180
3.13	-20.27	0.223	1.181
3.14	-20.17	0.223	1.181
3.15	-20.07	0.223	1.180
3.16	-19.97	0.223	1.181
3.17	-19.87	0.223	1.181
3.18	-19.77	0.223	1.181
3.19	-19.67	0.223	1.182
3.20	-19.57	0.223	1.182
3.21	-19.47	0.223	1.182
3.22	-19.37	0.223	1.182
3.23	-19.27	0.223	1.182
3.24	-19.17	0.223	1.182
3.25	-19.07	0.223	1.182
3.26	-18.97	0.223	1.182
3.27	-18.87	0.223	1.183
3.28	-18.77	0.223	1.182
3.29	-18.67	0.223	1.182
3.30	-18.57	0.223	1.183
3.31	-18.47	0.223	1.183
3.32	-18.37	0.223	1.184
3.33	-18.27	0.223	1.184
3.34	-18.17	0.223	1.183
3.35	-18.07	0.223	1.184
3.36	-17.97	0.223	1.184
3.37	-17.87	0.223	1.183
3.38	-17.77	0.223	1.183
3.39	-17.67	0.223	1.184
3.40	-17.57	0.223	1.185
3.41	-17.47	0.223	1.185
3.42	-17.37	0.223	1.184
3.43	-17.27	0.223	1.185
3.44	-17.17	0.223	1.185
3.45	-17.07	0.223	1.185
3.46	-16.97	0.223	1.185
3.47	-16.87	0.223	1.185
3.48	-16.77	0.223	1.185
3.49	-16.67	0.223	1.186
3.50	-16.57	0.223	1.186
3.51	-16.47	0.223	1.186
3.52	-16.37	0.223	1.186
3.53	-16.27	0.223	1.186
3.54	-16.17	0.223	1.186
3.55	-16.07	0.223	1.187
3.56	-15.97	0.223	1.187
3.57	-15.87	0.223	1.187
3.58	-15.77	0.223	1.187
3.59	-15.67	0.223	1.187
3.60	-15.57	0.223	1.187
3.61	-15.47	0.223	1.187
3.62	-15.37	0.223	1.187
3.63	-15.27	0.223	1.187
3.64	-15.17	0.223	1.187
3.65	-15.07	0.223	1.187
3.66	-14.97	0.223	1.188
3.67	-14.87	0.223	1.188
3.68	-14.77	0.223	1.188
3.69	-14.67	0.223	1.187
3.70	-14.57	0.223	1.188
3.71	-14.47	0.223	1.188
3.72	-14.37	0.223	1.188
3.73	-14.27	0.223	1.188
3.74	-14.17	0.223	1.188
3.75	-14.06	0.223	1.189
3.76	-13.96	0.223	1.189
3.77	-13.86	0.223	1.189
3.78	-13.76	0.224	1.190
3.79	-13.66	0.223	1.189
3.80	-13.57	0.224	1.189
3.81	-13.46	0.224	1.190
3.82	-13.36	0.224	1.190
3.83	-13.26	0.224	1.190
3.84	-13.16	0.224	1.190
3.85	-13.07	0.224	1.191
3.86	-12.96	0.224	1.191
3.87	-12.86	0.224	1.191
3.88	-12.76	0.224	1.191
3.89	-12.66	0.224	1.192
3.90	-12.56	0.224	1.192
3.91	-12.46	0.224	1.192
3.92	-12.36	0.224	1.192
3.93	-12.26	0.224	1.192
3.94	-12.16	0.224	1.192
3.95	-12.06	0.224	1.192
3.96	-11.96	0.224	1.192
3.97	-11.86	0.224	1.192
3.98	-11.76	0.224	1.193
3.99	-11.66	0.224	1.193
4.00	-11.56	0.224	1.193
4.01	-11.46	0.224	1.194
4.02	-11.36	0.224	1.194
4.03	-11.26	0.224	1.195
4.04	-11.16	0.224	1.195
4.05	-11.06	0.224	1.195
4.06	-10.96	0.224	1.194
4.07	-10.86	0.224	1.194
4.08	-10.76	0.224	1.195
4.09	-10.66	0.224	1.195
4.10	-10.56	0.224	1.195
4.11	-10.46	0.224	1.195
4.12	-10.36	0.224	1.196
4.13	-10.26	0.224	1.197
4.14	-10.16	0.224	1.196
4.15	-10.06	0.224	1.197
4.16	-9.96	0.224	1.197
4.17	-9.86	0.224	1.198
4.18	-9.76	0.224	1.197
4.19	-9.66	0.224	1.197
4.20	-9.56	0.224	1.197
4.21	-9.46	0.225	1.198
4.22	-9.36	0.225	1.198
4.23	-9.26	0.225	1.198
4.24	-9.16	0.225	1.198
4.25	-9.06	0.225	1.198
4.26	-8.96	0.225	1.199
4.27	-8.86	0.225	1.199
4.28	-8.76	0.225	1.199
4.29	-8.66	0.225	1.199
4.30	-8.56	0.225	1.199
4.31	-8.46	0.225	1.199
4.32	-8.36	0.225	1.200
4.33	-8.26	0.225	1.200
4.34	-8.16	0.225	1.200
4.35	-8.06	0.225	1.200
4.36	-7.96	0.225	1.201
4.37	-7.86	0.225	1.201
4.38	-7.76	0.225	1.202
4.39	-7.66	0.225	1.202
4.40	-7.56	0.225	1.202
4.41	-7.46	0.225	1.202
4.42	-7.36	0.225	1.202
4.43	-7.26	0.225	1.202
4.44	-7.16	0.225	1.203
4.45	-7.06	0.225	1.204
4.46	-6.96	0.225	1.203
4.47	-6.86	0.225	1.204
4.48	-6.76	0.225	1.204
4.49	-6.66	0.226	1.204
4.50	-6.56	0.226	1.204
4.51	-6.46	0.226	1.205
4.52	-6.36	0.226	1.205
4.53	-6.26	0.226	1.206
4.54	-6.15	0.226	1.205
4.55	-6.06	0.226	1.205
4.56	-5.95	0.226	1.206
4.57	-5.85	0.226	1.205
4.58	-5.75	0.226	1.206
4.59	-5.65	0.226	1.206
4.60	-5.55	0.226	1.206
4.61	-5.46	0.226	1.206
4.62	-5.36	0.226	1.207
4.63	-5.26	0.226	1.207
4.64	-5.15	0.226	1.207
4.65	-5.05	0.226	1.208
4.66	-4.95	0.226	1.208
4.67	-4.85	0.226	1.209
4.68	-4.75	0.226	1.209
4.69	-4.65	0.226	1.210
4.70	-4.55	0.226	1.209
4.71	-4.45	0.226	1.210
4.72	-4.35	0.226	1.210
4.73	-4.25	0.227	1.210
4.74	-4.15	0.227	1.210
4.75	-4.05	0.227	1.211
4.76	-3.95	0.227	1.211
4.77	-3.85	0.227	1.211
4.78	-3.75	0.227	1.211
4.79	-3.65	0.227	1.212
4.80	-3.55	0.227	1.211
4.81	-3.45	0.227	1.212
4.82	-3.35	0.227	1.211
4.83	-3.25	0.227	1.211
4.84	-3.15	0.227	1.212
4.85	-3.05	0.227	1.211
4.86	-2.95	0.227	1.212
4.87	-2.85	0.227	1.212
4.88	-2.75	0.227	1.212
4.89	-2.65	0.227	1.212
4.90	-2.55	0.227	1.212
4.91	-2.45	0.227	1.213
4.92	-2.35	0.227	1.213
4.93	-2.25	0.227	1.213
4.94	-2.15	0.227	1.214
4.95	-2.05	0.227	1.214
4.96	-1.95	0.227	1.214
4.97	-1.85	0.227	1.215
4.98	-1.75	0.227	1.215
4.99	-1.65	0.227	1.215
5.00	-1.55	0.227	1.216
5.01	-1.45	0.227	1.216
5.02	-1.35	0.228	1.217
5.03	-1.25	0.228	1.216
5.04	-1.15	0.228	1.218
5.05	-1.05	0.228	1.217
5.06	-0.95	0.228	1.218
5.07	-0.85	0.228	1.218
5.08	-0.75	0.228	1.218
5.09	-0.65	0.228	1.218
5.10	-0.55	0.228	1.219
5.11	-0.45	0.228	1.218
5.12	-0.35	0.228	1.219
5.13	-0.25	0.228	1.219
5.14	-0.15	0.228	1.220
5.15	-0.05	0.228	1.219
5.16	0.05	0.228	1.220
5.17	0.15	0.228	1.220
5.18	0.26	0.228	1.220
5.19	0.36	0.228	1.220
5.20	0.45	0.228	1.220
5.21	0.55	0.228	1.220
5.22	0.65	0.228	1.220
5.23	0.75	0.228	1.222
5.24	0.85	0.228	1.221
5.25	0.96	0.228	1.221
5.26	1.05	0.228	1.221
5.27	1.16	0.228	1.221
5.28	1.26	0.228	1.222
5.29	1.35	0.228	1.222
5.30	1.46	0.228	1.222
5.31	1.56	0.229	1.222
5.32	1.66	0.229	1.222
5.33	1.75	0.229	1.223
5.34	1.86	0.229	1.223
5.35	1.96	0.229	1.224
5.36	2.06	0.229	1.224
5.37	2.16	0.229	1.224
5.38	2.26	0.229	1.224
5.39	2.36	0.229	1.224
5.40	2.46	0.229	1.225
5.41	2.56	0.229	1.225
5.42	2.66	0.229	1.225
5.43	2.76	0.229	1.225
5.44	2.86	0.229	1.226
5.45	2.96	0.229	1.226
5.46	3.06	0.229	1.227
5.47	3.16	0.229	1.227
5.48	3.26	0.229	1.226
5.49	3.36	0.229	1.226
5.50	3.46	0.229	1.227
5.51	3.56	0.229	1.227
5.52	3.66	0.229	1.227
5.53	3.76	0.230	1.227
5.54	3.86	0.230	1.227
5.55	3.96	0.230	1.227
5.56	4.06	0.230	1.228
5.57	4.16	0.230	1.229
5.58	4.26	0.230	1.230
5.59	4.36	0.230	1.230
5.60	4.46	0.230	1.230
5.61	4.56	0.230	1.230
5.62	4.66	0.230	1.231
5.63	4.76	0.230	1.231
5.64	4.86	0.230	1.232
5.65	4.96	0.230	1.231
5.66	5.06	0.230	1.231
5.67	5.16	0.230	1.232
5.68	5.26	0.230	1.232
5.69	5.36	0.230	1.232
5.70	5.46	0.230	1.233
5.71	5.56	0.231	1.233
5.72	5.66	0.231	1.233
5.73	5.76	0.231	1.234
5.74	5.86	0.231	1.234
5.75	5.96	0.231	1.235
5.76	6.06	0.231	1.234
5.77	6.16	0.231	1.234
5.78	6.26	0.231	1.235
5.79	6.36	0.231	1.235
5.80	6.46	0.231	1.236
5.81	6.56	0.231	1.236
5.82	6.66	0.231	1.236
5.83	6.76	0.231	1.237
5.84	6.86	0.231	1.237
5.85	6.96	0.231	1.237
5.86	7.06	0.231	1.237
5.87	7.16	0.231	1.237
5.88	7.26	0.231	1.238
5.89	7.36	0.231	1.238
5.90	7.46	0.232	1.238
5.91	7.56	0.232	1.239
5.92	7.66	0.232	1.239
5.93	7.76	0.232	1.239
5.94	7.86	0.232	1.240
5.95	7.96	0.232	1.240
5.96	8.06	0.232	1.240
5.97	8.16	0.232	1.241
5.98	8.26	0.232	1.241
5.99	8.36	0.232	1.241
6.00	8.47	0.232	1.241
6.01	8.57	0.232	1.241
6.02	8.67	0.232	1.241
6.03	8.77	0.232	1.242
6.04	8.87	0.232	1.242
6.05	8.97	0.232	1.243
6.06	9.07	0.232	1.243
6.07	9.17	0.233	1.244
6.08	9.27	0.233	1.244
6.09	9.37	0.233	1.244
6.10	9.47	0.233	1.244
6.11	9.57	0.233	1.244
6.12	9.67	0.233	1.245
6.13	9.77	0.233	1.245
6.14	9.87	0.233	1.245
6.15	9.97	0.233	1.246
6.16	10.07	0.233	1.246
6.17	10.17	0.233	1.246
6.18	10.27	0.233	1.247
6.19	10.37	0.233	1.248
6.20	10.47	0.233	1.248
6.21	10.57	0.233	1.248
6.22	10.67	0.233	1.249
6.23	10.77	0.234	1.249
6.24	10.87	0.234	1.248
6.25	10.97	0.234	1.248
6.26	11.07	0.234	1.249
6.27	11.17	0.234	1.249
6.28	11.27	0.234	1.250
6.29	11.37	0.234	1.250
6.30	11.47	0.234	1.250
6.31	11.57	0.234	1.250
6.32	11.67	0.234	1.250
6.33	11.77	0.234	1.250
6.34	11.87	0.234	1.251
6.35	11.97	0.234	1.251
6.36	12.07	0.234	1.251
6.37	12.17	0.234	1.251
6.38	12.27	0.234	1.251
6.39	12.37	0.234	1.252
6.40	12.47	0.234	1.252
6.41	12.57	0.234	1.252
6.42	12.67	0.234	1.252
6.43	12.77	0.234	1.252
6.44	12.87	0.234	1.253
6.45	12.97	0.234	1.253
6.46	13.07	0.234	1.252
6.47	13.17	0.234	1.252
6.48	13.27	0.234	1.252
6.49	13.37	0.234	1.252
6.50	13.47	0.234	1.253
6.51	13.57	0.234	1.253
6.52	13.67	0.234	1.253
6.53	13.77	0.235	1.255
6.54	13.87	0.235	1.254
6.55	13.97	0.235	1.254
6.56	14.07	0.235	1.255
6.57	14.17	0.235	1.256
6.58	14.27	0.235	1.256
6.59	14.37	0.235	1.257
6.60	14.47	0.235	1.257
6.61	14.57	0.235	1.257
6.62	14.67	0.235	1.257
6.63	14.77	0.235	1.258
6.64	14.87	0.235	1.257
6.65	14.97	0.235	1.258
6.66	15.07	0.235	1.259
6.67	15.17	0.236	1.259
6.68	15.27	0.236	1.260
6.69	15.37	0.236	1.259
6.70	15.47	0.236	1.260
6.71	15.57	0.236	1.260
6.72	15.67	0.236	1.260
6.73	15.77	0.236	1.261
6.74	15.87	0.236	1.261
6.75	15.97	0.236	1.262
6.76	16.07	0.236	1.262
6.77	16.17	0.236	1.262
6.78	16.27	0.236	1.263
6.79	16.37	0.236	1.263
6.80	16.47	0.236	1.264
6.81	16.57	0.236	1.264
6.82	16.67	0.236	1.264
6.83	16.77	0.237	1.265
6.84	16.87	0.237	1.266
6.85	16.97	0.237	1.265
6.86	17.07	0.237	1.266
6.87	17.18	0.237	1.266
6.88	17.28	0.237	1.266
6.89	17.37	0.237	1.266
6.90	17.48	0.237	1.266
6.91	17.57	0.237	1.267
6.92	17.68	0.237	1.267
6.93	17.78	0.237	1.268
6.94	17.87	0.237	1.268
6.95	17.98	0.237	1.268
6.96	18.08	0.237	1.268
6.97	18.18	0.237	1.269
6.98	18.28	0.238	1.269
6.99	18.38	0.238	1.270
7.00	18.48	0.238	1.270
7.01	18.58	0.238	1.271
7.02	18.68	0.238	1.271
7.03	18.78	0.238	1.272
7.04	18.88	0.238	1.272
7.05	18.98	0.238	1.272
7.06	19.08	0.238	1.272
7.07	19.18	0.238	1.273
7.08	19.28	0.238	1.273
7.09	19.38	0.238	1.274
7.10	19.48	0.238	1.274
7.11	19.58	0.238	1.274
7.12	19.68	0.238	1.275
7.13	19.78	0.239	1.276
7.14	19.88	0.239	1.276
7.15	19.98	0.239	1.275
7.16	20.08	0.239	1.276
7.17	20.18	0.239	1.276
7.18	20.28	0.239	1.277
7.19	20.38	0.239	1.277
7.20	20.48	0.239	1.277
7.21	20.58	0.239	1.278
7.22	20.68	0.239	1.278
7.23	20.78	0.239	1.278
7.24	20.88	0.239	1.278
7.25	20.98	0.239	1.279
7.26	21.08	0.239	1.279
7.27	21.18	0.239	1.280
7.28	21.28	0.240	1.280
7.29	21.38	0.240	1.280
7.30	21.48	0.240	1.281
7.31	21.58	0.240	1.282
7.32	21.68	0.240	1.282
7.33	21.78	0.240	1.282
7.34	21.88	0.240	1.282
7.35	21.98	0.240	1.283
7.36	22.08	0.240	1.284
7.37	22.18	0.240	1.284
7.38	22.28	0.240	1.284
7.39	22.38	0.240	1.284
7.40	22.48	0.240	1.285
7.41	22.58	0.240	1.285
7.42	22.68	0.240	1.285
7.43	22.78	0.241	1.286
7.44	22.88	0.241	1.286
7.45	22.98	0.241	1.286
7.46	23.08	0.241	1.287
7.47	23.18	0.241	1.287
7.48	23.28	0.241	1.288
7.49	23.38	0.241	1.288
7.50	23.48	0.241	1.288
7.51	23.58	0.241	1.289
7.52	23.68	0.241	1.290
7.53	23.78	0.241	1.289
7.54	23.88	0.241	1.289
7.55	23.98	0.241	1.290
7.56	24.08	0.241	1.290
7.57	24.18	0.241	1.290
7.58	24.28	0.242	1.291
7.59	24.38	0.242	1.292
7.60	24.48	0.242	1.292
7.61	24.58	0.242	1.292
7.62	24.68	0.242	1.292
7.63	24.78	0.242	1.293
7.64	24.88	0.242	1.293
7.65	24.98	0.242	1.293
7.66	25.08	0.242	1.294
7.67	25.18	0.242	1.294
7.68	25.28	0.242	1.294
7.69	25.38	0.242	1.294
7.70	25.49	0.242	1.295
7.71	25.59	0.242	1.294
7.72	25.68	0.242	1.295
7.73	25.78	0.242	1.296
7.74	25.89	0.243	1.297
7.75	25.99	0.243	1.298
7.76	26.09	0.243	1.298
7.77	26.19	0.243	1.299
7.78	26.29	0.243	1.300
7.79	26.39	0.243	1.300
7.80	26.49	0.243	1.300
7.81	26.59	0.243	1.300
7.82	26.69	0.243	1.301
7.83	26.79	0.244	1.301
7.84	26.89	0.244	1.302
7.85	26.99	0.244	1.302
7.86	27.09	0.244	1.303
7.87	27.19	0.244	1.303
7.88	27.29	0.244	1.303
7.89	27.39	0.244	1.304
7.90	27.49	0.244	1.304
7.91	27.59	0.244	1.305
7.92	27.69	0.244	1.305
7.93	27.79	0.244	1.305
7.94	27.89	0.244	1.305
7.95	27.99	0.244	1.306
7.96	28.09	0.244	1.306
7.97	28.19	0.244	1.306
7.98	28.29	0.244	1.307
7.99	28.39	0.245	1.307
8.00	28.49	0.245	1.308
8.01	28.59	0.245	1.308
8.02	28.69	0.245	1.308
8.03	28.79	0.245	1.309
8.04	28.89	0.245	1.308
8.05	28.99	0.245	1.309
8.06	29.09	0.245	1.309
8.07	29.19	0.245	1.310
8.08	29.29	0.245	1.311
8.09	29.39	0.245	1.311
8.10	29.49	0.245	1.312
8.11	29.59	0.245	1.312
8.12	29.69	0.246	1.313
8.13	29.79	0.246	1.313
8.14	29.89	0.246	1.313
8.15	29.99	0.246	1.313
8.16	30.09	0.246	1.314
8.17	30.19	0.246	1.315
8.18	30.29	0.246	1.315
8.19	30.39	0.246	1.316
8.20	30.49	0.246	1.316
8.21	30.59	0.246	1.316
8.22	30.69	0.246	1.316
8.23	30.79	0.246	1.316
8.24	30.89	0.246	1.317
8.25	30.99	0.246	1.317
8.26	31.09	0.246	1.317
8.27	31.19	0.246	1.318
8.28	31.29	0.247	1.318
8.29	31.39	0.247	1.319
8.30	31.49	0.247	1.319
8.31	31.59	0.247	1.320
8.32	31.69	0.247	1.320
8.33	31.79	0.247	1.320
8.34	31.89	0.247	1.321
8.35	31.99	0.247	1.321
8.36	32.09	0.247	1.322
8.37	32.19	0.247	1.322
8.38	32.29	0.247	1.322
8.39	32.39	0.247	1.323
8.40	32.49	0.247	1.323
8.41	32.59	0.247	1.323
8.42	32.69	0.248	1.324
8.43	32.79	0.248	1.324
8.44	32.89	0.248	1.324
8.45	32.99	0.248	1.324
8.46	33.09	0.248	1.325
8.47	33.19	0.248	1.325
8.48	33.29	0.248	1.325
8.49	33.39	0.248	1.326
8.50	33.50	0.248	1.326
8.51	33.59	0.248	1.327
8.52	33.69	0.248	1.327
8.53	33.80	0.248	1.327
8.54	33.90	0.248	1.328
8.55	34.00	0.249	1.329
8.56	34.10	0.249	1.329
8.57	34.20	0.249	1.329
8.58	34.30	0.249	1.329
8.59	34.40	0.249	1.330
8.60	34.49	0.249	1.331
8.61	34.59	0.249	1.332
8.62	34.70	0.249	1.332
8.63	34.80	0.249	1.332
8.64	34.90	0.249	1.332
8.65	35.00	0.249	1.332
8.66	35.10	0.249	1.332
8.67	35.20	0.249	1.332
8.68	35.30	0.249	1.332
8.69	35.40	0.249	1.333
8.70	35.50	0.249	1.333
8.71	35.60	0.249	1.333
8.72	35.70	0.250	1.334
8.73	35.80	0.250	1.334
8.74	35.90	0.250	1.334
8.75	36.00	0.250	1.334
8.76	36.10	0.250	1.335
8.77	36.20	0.250	1.335
8.78	36.30	0.250	1.335
8.79	36.40	0.250	1.336
8.80	36.50	0.250	1.336
8.81	36.60	0.250	1.336
8.82	36.70	0.250	1.337
8.83	36.80	0.250	1.337
8.84	36.90	0.250	1.338
8.85	37.00	0.250	1.338
8.86	37.10	0.251	1.339
8.87	37.20	0.251	1.338
8.88	37.30	0.251	1.339
8.89	37.40	0.251	1.340
8.90	37.50	0.251	1.340
8.91	37.60	0.251	1.340
8.92	37.70	0.251	1.341
8.93	37.80	0.251	1.341
8.94	37.90	0.251	1.341
8.95	38.00	0.251	1.341
8.96	38.10	0.251	1.342
8.97	38.20	0.251	1.342
8.98	38.30	0.251	1.342
8.99	38.40	0.251	1.343
9.00	38.50	0.251	1.343
9.01	38.60	0.252	1.343
9.02	38.70	0.252	1.343
9.03	38.80	0.252	1.344
9.04	38.90	0.252	1.344
9.05	39.00	0.252	1.345
9.06	39.10	0.252	1.345
9.07	39.20	0.252	1.345
9.08	39.30	0.252	1.346
9.09	39.40	0.252	1.347
9.10	39.50	0.252	1.346
9.11	39.60	0.252	1.346
9.12	39.70	0.252	1.346
9.13	39.80	0.253	1.348
9.14	39.90	0.253	1.348
9.15	40.00	0.253	1.348
9.16	40.10	0.253	1.349
9.17	40.20	0.253	1.349
9.18	40.30	0.253	1.349
9.19	40.40	0.253	1.350
9.20	40.50	0.253	1.350
9.21	40.60	0.253	1.350
9.22	40.70	0.253	1.351
9.23	40.80	0.253	1.351
9.24	40.90	0.253	1.351
9.25	41.00	0.253	1.351
9.26	41.10	0.253	1.352
9.27	41.20	0.254	1.353
9.28	41.30	0.254	1.353
9.29	41.40	0.254	1.353
9.30	41.50	0.254	1.353
9.31	41.60	0.254	1.354
9.32	41.70	0.254	1.354
9.33	41.80	0.254	1.354
9.34	41.90	0.254	1.355
9.35	42.00	0.254	1.355
9.36	42.10	0.254	1.354
9.37	42.20	0.254	1.355
9.38	42.30	0.254	1.355
9.39	42.40	0.254	1.356
9.40	42.50	0.254	1.356
9.41	42.60	0.254	1.355
9.42	42.70	0.255	1.356
9.43	42.80	0.255	1.356
9.44	42.90	0.255	1.358
9.45	43.01	0.255	1.358
9.46	43.11	0.255	1.358
9.47	43.21	0.255	1.359
9.48	43.31	0.255	1.359
9.49	43.41	0.255	1.360
9.50	43.51	0.255	1.360
9.51	43.61	0.255	1.360
9.52	43.71	0.255	1.361
9.53	43.81	0.255	1.361
9.54	43.91	0.256	1.362
9.55	44.01	0.256	1.362
9.56	44.11	0.256	1.362
9.57	44.21	0.256	1.363
9.58	44.31	0.256	1.363
9.59	44.41	0.256	1.364
9.60	44.51	0.256	1.364
9.61	44.61	0.256	1.364
9.62	44.71	0.256	1.365
9.63	44.81	0.256	1.365
9.64	44.91	0.256	1.365
9.65	45.01	0.256	1.365
9.66	45.11	0.256	1.366
9.67	45.21	0.257	1.367
9.68	45.31	0.257	1.367
9.69	45.41	0.257	1.367
9.70	45.51	0.257	1.367
9.71	45.61	0.257	1.368
9.72	45.71	0.257	1.368
9.73	45.81	0.257	1.369
9.74	45.91	0.257	1.370
9.75	46.01	0.257	1.371
9.76	46.11	0.257	1.371
9.77	46.21	0.258	1.371
9.78	46.31	0.258	1.371
9.79	46.41	0.258	1.371
9.80	46.51	0.258	1.371
9.81	46.61	0.258	1.372
9.82	46.71	0.258	1.373
9.83	46.81	0.258	1.373
9.84	46.91	0.258	1.373
9.85	47.01	0.258	1.374
9.86	47.11	0.258	1.375
9.87	47.21	0.258	1.375
9.88	47.31	0.258	1.376
9.89	47.41	0.259	1.377
9.90	47.51	0.259	1.376
9.91	47.61	0.259	1.377
9.92	47.71	0.259	1.377
9.93	47.81	0.259	1.378
9.94	47.91	0.259	1.378
9.95	48.01	0.259	1.379
9.96	48.11	0.259	1.379
9.97	48.21	0.259	1.380
9.98	48.31	0.259	1.381
9.99	48.41	0.259	1.381
10.00	48.51	0.260	1.382
10.01	48.61	0.260	1.382
10.02	48.71	0.260	1.382
10.03	48.81	0.260	1.382
10.04	48.91	0.260	1.383
10.05	49.01	0.260	1.384
10.06	49.11	0.260	1.385
10.07	49.21	0.260	1.385
10.08	49.31	0.260	1.384
10.09	49.41	0.260	1.385
10.10	49.51	0.260	1.386
10.11	49.61	0.261	1.387
10.12	49.71	0.261	1.387
10.13	49.81	0.261	1.387
10.14	49.91	0.261	1.388
10.15	50.01	0.261	1.389
10.16	50.11	0.261	1.389
10.17	50.21	0.261	1.390
10.18	50.31	0.261	1.390
10.19	50.41	0.261	1.391
10.20	50.51	0.261	1.392
10.21	50.61	0.261	1.392
10.22	50.71	0.262	1.392
10.23	50.81	0.262	1.393
10.24	50.91	0.262	1.394
10.25	51.01	0.262	1.394
10.26	51.11	0.262	1.394
10.27	51.21	0.262	1.395
10.28	51.31	0.262	1.396
10.29	51.41	0.262	1.396
10.30	51.51	0.262	1.396
10.31	51.61	0.262	1.397
10.32	51.71	0.262	1.398
10.33	51.82	0.263	1.398
10.34	51.91	0.263	1.399
10.35	52.01	0.263	1.399
10.36	52.11	0.263	1.399
10.37	52.21	0.263	1.400
10.38	52.31	0.263	1.401
10.39	52.42	0.263	1.402
10.40	52.52	0.263	1.403
10.41	52.62	0.263	1.404
10.42	52.71	0.264	1.404
10.43	52.82	0.264	1.405
10.44	52.92	0.264	1.406
10.45	53.02	0.264	1.406
10.46	53.12	0.264	1.407
10.47	53.22	0.264	1.407
10.48	53.32	0.264	1.408
10.49	53.41	0.264	1.408
10.50	53.52	0.264	1.409
10.51	53.62	0.264	1.410
10.52	53.72	0.265	1.411
10.53	53.81	0.265	1.412
10.54	53.92	0.265	1.413
10.55	54.02	0.265	1.413
10.56	54.12	0.265	1.414
10.57	54.22	0.265	1.414
10.58	54.32	0.266	1.415
10.59	54.42	0.266	1.415
10.60	54.52	0.266	1.416
10.61	54.62	0.266	1.417
10.62	54.72	0.266	1.419
10.63	54.82	0.266	1.419
10.64	54.92	0.266	1.420
10.65	55.02	0.267	1.421
10.66	55.12	0.267	1.422
10.67	55.22	0.267	1.423
10.68	55.32	0.267	1.424
10.69	55.42	0.267	1.424
10.70	55.52	0.267	1.425
10.71	55.62	0.267	1.426
10.72	55.72	0.268	1.427
10.73	55.82	0.268	1.427
10.74	55.92	0.268	1.428
10.75	56.02	0.268	1.429
10.76	56.12	0.268	1.430
10.77	56.22	0.268	1.431
10.78	56.32	0.268	1.432
10.79	56.42	0.269	1.433
10.80	56.52	0.269	1.434
10.81	56.62	0.269	1.435
10.82	56.72	0.269	1.435
10.83	56.82	0.269	1.436
10.84	56.92	0.269	1.437
10.85	57.02	0.270	1.439
10.86	57.12	0.270	1.440
10.87	57.22	0.270	1.441
10.88	57.32	0.270	1.442
10.89	57.42	0.271	1.443
10.90	57.52	0.271	1.444
10.91	57.62	0.271	1.445
10.92	57.72	0.271	1.446
10.93	57.82	0.272	1.448
10.94	57.92	0.272	1.450
10.95	58.02	0.272	1.451
10.96	58.12	0.272	1.452
10.97	58.22	0.273	1.454
10.98	58.32	0.273	1.455
10.99	58.42	0.273	1.457
11.00	58.52	0.273	1.458
11.01	58.62	0.274	1.460
11.02	58.72	0.274	1.463
11.03	58.82	0.274	1.464
11.04	58.92	0.275	1.466
11.05	59.02	0.275	1.469
11.06	59.12	0.276	1.471
11.07	59.22	0.276	1.473
11.08	59.32	0.277	1.477
11.09	59.42	0.277	1.480
11.10	59.52	0.277	1.481
11.11	59.62	0.278	1.483
11.12	59.72	0.278	1.485
11.13	59.82	0.278	1.488
11.14	59.92	0.279	1.490
11.15	60.02	0.280	1.496
11.16	60.12	0.281	1.499
11.17	60.22	0.282	1.508
11.18	60.32	0.283	1.512
11.19	60.42	0.284	1.516
11.20	60.52	0.284	1.521
11.21	60.62	0.286	1.528
11.22	60.72	0.286	1.531
11.23	60.82	0.288	1.539
11.24	60.92	0.290	1.553
11.25	61.02	0.292	1.563
11.26	61.12	0.293	1.568
11.27	61.22	0.295	1.581
11.28	61.32	0.299	1.600
11.29	61.42	0.300	1.608
11.30	61.52	0.303	1.623
11.31	61.62	0.306	1.637
11.32	61.72	0.306	1.641
11.33	61.82	0.308	1.652
11.34	61.92	0.313	1.678
11.35	62.01	0.315	1.689
11.36	62.11	0.318	1.705
11.37	62.21	0.321	1.723
11.38	62.31	0.325	1.745
11.39	62.41	0.329	1.770
11.40	62.51	0.332	1.787
11.41	62.61	0.336	1.810
11.42	62.71	0.344	1.853
11.43	62.81	0.347	1.873
11.44	62.91	0.351	1.895
11.45	63.01	0.362	1.954
11.46	63.11	0.365	1.972
11.47	63.21	0.374	2.030
11.48	63.30	0.380	2.063
11.49	63.40	0.389	2.114
11.50	63.50	0.399	2.176
11.51	63.60	0.409	2.232
11.52	63.70	0.421	2.305
11.53	63.80	0.433	2.377
11.54	63.89	0.447	2.463
11.55	63.99	0.464	2.564
11.56	64.09	0.481	2.665
11.57	64.18	0.502	2.796
11.58	64.28	0.523	2.928
11.59	64.38	0.546	3.075
11.60	64.47	0.574	3.251
11.61	64.57	0.605	3.448
11.62	64.66	0.635	3.650
11.63	64.75	0.670	3.879
11.64	64.85	0.709	4.142
11.65	64.94	0.752	4.440
11.66	65.03	0.804	4.793
11.67	65.12	0.856	5.161
11.68	65.21	0.917	5.593
11.69	65.30	0.981	6.057
11.70	65.39	1.051	6.570
11.71	65.47	1.130	7.154
11.72	65.56	1.218	7.812
11.73	65.64	1.319	8.564
11.74	65.72	1.425	9.369
11.75	65.80	1.531	10.201
11.76	65.88	1.637	11.045
11.77	65.95	1.748	11.927
11.78	66.03	1.865	12.855
11.79	66.10	1.967	13.673
11.80	66.18	2.075	14.529
11.81	66.25	2.194	15.426
11.82	66.33	2.283	16.083
11.83	66.40	2.399	16.873
11.84	66.47	2.527	17.691
11.85	66.54	2.638	18.318
11.86	66.61	2.736	18.789
11.87	66.69	2.810	19.055
11.88	66.76	2.884	19.239
11.89	66.83	2.952	19.357
11.90	66.91	3.005	19.341
11.91	66.99	3.034	19.131
11.92	67.07	3.042	18.776
11.93	67.16	3.033	18.322
11.94	67.24	3.014	17.810
11.95	67.34	2.985	17.248
11.96	67.43	2.947	16.638
11.97	67.53	2.895	15.984
11.98	67.63	2.840	15.332
11.99	67.73	2.779	14.684
12.00	67.84	2.713	14.032
12.01	67.94	2.646	13.413
12.02	68.05	2.575	12.815
12.03	68.16	2.509	12.285
12.04	68.28	2.459	11.856
12.05	68.39	2.383	11.339
12.06	68.50	2.296	10.797
12.07	68.62	2.211	10.288
12.08	68.74	2.121	9.782
[...]
400.36	-15.57	0.253	1.350
400.37	-15.50	0.254	1.353
400.38	-15.43	0.255	1.359
400.38	-15.36	0.257	1.369
400.39	-15.30	0.258	1.376
400.39	-15.23	0.259	1.380
400.40	-15.17	0.260	1.387
400.41	-15.10	0.261	1.393
400.42	-15.03	0.262	1.400
400.42	-14.97	0.263	1.403
400.43	-14.90	0.263	1.406
400.43	-14.83	0.265	1.415
400.44	-14.77	0.266	1.420
400.45	-14.70	0.267	1.426
400.46	-14.63	0.268	1.433
400.46	-14.57	0.271	1.446
400.47	-14.50	0.273	1.459
400.48	-14.43	0.274	1.463
400.48	-14.37	0.274	1.466
400.49	-14.30	0.275	1.473
400.49	-14.23	0.277	1.482
400.50	-14.17	0.279	1.493
400.51	-14.10	0.281	1.504
400.52	-14.03	0.283	1.513
400.52	-13.97	0.284	1.521
400.53	-13.90	0.285	1.526
400.53	-13.84	0.288	1.543
400.54	-13.77	0.291	1.562
400.55	-13.70	0.292	1.565
400.56	-13.64	0.293	1.570
400.56	-13.57	0.296	1.585
400.57	-13.51	0.299	1.602
400.58	-13.44	0.300	1.612
400.58	-13.37	0.302	1.619
400.59	-13.31	0.303	1.630
400.59	-13.24	0.305	1.639
400.60	-13.17	0.308	1.653
400.61	-13.11	0.311	1.672
400.62	-13.04	0.314	1.685
400.62	-12.98	0.316	1.696
400.63	-12.91	0.318	1.708
400.63	-12.84	0.321	1.726
400.64	-12.78	0.324	1.746
400.65	-12.71	0.326	1.753
400.66	-12.64	0.328	1.766
400.66	-12.58	0.334	1.800
400.67	-12.51	0.338	1.820
400.68	-12.45	0.338	1.823
400.68	-12.38	0.340	1.833
400.69	-12.32	0.343	1.851
400.69	-12.25	0.347	1.873
400.70	-12.18	0.352	1.897
400.71	-12.12	0.355	1.915
400.72	-12.05	0.358	1.931
400.72	-11.99	0.362	1.955
400.73	-11.92	0.365	1.969
400.73	-11.85	0.367	1.983
400.74	-11.79	0.372	2.006
400.75	-11.72	0.375	2.025
400.76	-11.66	0.378	2.040
400.76	-11.59	0.380	2.054
400.77	-11.53	0.384	2.076
400.78	-11.46	0.388	2.096
400.78	-11.39	0.391	2.113
400.79	-11.33	0.396	2.135
400.79	-11.26	0.398	2.147
400.80	-11.20	0.402	2.169
400.81	-11.13	0.404	2.178
400.82	-11.07	0.405	2.184
400.82	-11.00	0.407	2.195
400.83	-10.93	0.408	2.198
400.83	-10.87	0.410	2.206
400.84	-10.80	0.412	2.217
400.85	-10.73	0.414	2.222
400.86	-10.67	0.414	2.221
400.86	-10.60	0.415	2.227
400.87	-10.54	0.416	2.232
400.88	-10.47	0.416	2.226
400.88	-10.40	0.415	2.220
400.89	-10.34	0.414	2.214
400.89	-10.27	0.414	2.209
400.90	-10.20	0.413	2.203
400.91	-10.14	0.412	2.194
400.92	-10.07	0.410	2.183
400.92	-10.01	0.408	2.171
400.93	-9.94	0.405	2.152
400.93	-9.87	0.400	2.126
400.94	-9.80	0.394	2.091
400.95	-9.73	0.387	2.051
400.96	-9.67	0.383	2.028
400.96	-9.60	0.379	2.007
400.97	-9.53	0.375	1.985
400.98	-9.47	0.371	1.961
400.98	-9.40	0.364	1.925
400.99	-9.33	0.359	1.897
400.99	-9.26	0.357	1.884
401.00	-9.20	0.354	1.866
401.01	-9.13	0.348	1.837
401.02	-9.06	0.345	1.819
401.02	-8.99	0.343	1.810
401.03	-8.92	0.339	1.785
401.03	-8.86	0.335	1.763
401.04	-8.79	0.332	1.752
401.05	-8.72	0.328	1.727
401.06	-8.65	0.326	1.718
401.06	-8.59	0.325	1.713
401.07	-8.52	0.324	1.706
401.08	-8.45	0.322	1.699
401.08	-8.38	0.320	1.687
401.09	-8.32	0.317	1.673
401.09	-8.25	0.316	1.665
401.10	-8.18	0.315	1.663
401.11	-8.11	0.315	1.663
401.12	-8.05	0.314	1.660
401.12	-7.98	0.313	1.653
401.13	-7.91	0.312	1.648
401.13	-7.84	0.311	1.643
401.14	-7.77	0.309	1.635
401.15	-7.71	0.309	1.636
401.16	-7.64	0.310	1.640
401.16	-7.57	0.309	1.639
401.17	-7.51	0.308	1.634
401.18	-7.44	0.308	1.633
401.18	-7.37	0.307	1.628
401.19	-7.31	0.306	1.624
401.19	-7.24	0.306	1.622
401.20	-7.17	0.305	1.620
401.21	-7.10	0.305	1.618
401.22	-7.04	0.305	1.619
401.22	-6.97	0.305	1.619
401.23	-6.90	0.305	1.619
401.23	-6.83	0.304	1.618
401.24	-6.77	0.304	1.618
401.25	-6.70	0.304	1.618
401.26	-6.63	0.304	1.618
401.26	-6.57	0.304	1.617
401.27	-6.50	0.303	1.616
401.28	-6.43	0.303	1.615
401.28	-6.37	0.303	1.614
401.29	-6.30	0.303	1.613
401.29	-6.23	0.303	1.614
401.30	-6.17	0.303	1.613
401.31	-6.10	0.302	1.612
401.32	-6.03	0.302	1.612
401.32	-5.97	0.302	1.611
401.33	-5.90	0.302	1.611
401.33	-5.83	0.302	1.610
401.34	-5.76	0.302	1.610
401.35	-5.70	0.302	1.610
401.36	-5.63	0.302	1.609
401.36	-5.57	0.301	1.609
401.37	-5.50	0.301	1.608
401.38	-5.43	0.301	1.607
401.38	-5.36	0.301	1.607
401.39	-5.30	0.301	1.606
401.39	-5.23	0.301	1.605
401.40	-5.16	0.301	1.605
401.41	-5.10	0.301	1.604
401.42	-5.03	0.300	1.604
401.42	-4.96	0.300	1.603
401.43	-4.90	0.300	1.603
401.43	-4.83	0.300	1.602
401.44	-4.76	0.300	1.601
401.45	-4.70	0.300	1.601
401.46	-4.63	0.300	1.601
401.46	-4.56	0.300	1.601
401.47	-4.50	0.300	1.601
401.48	-4.43	0.300	1.600
401.48	-4.36	0.300	1.600
401.49	-4.29	0.299	1.600
401.49	-4.23	0.299	1.599
401.50	-4.16	0.299	1.599
401.51	-4.09	0.299	1.598
401.52	-4.03	0.299	1.597
401.52	-3.96	0.299	1.597
401.53	-3.89	0.299	1.597
401.53	-3.83	0.299	1.597
401.54	-3.76	0.299	1.597
401.55	-3.69	0.299	1.596
401.56	-3.63	0.299	1.596
401.56	-3.56	0.299	1.595
401.57	-3.49	0.299	1.595
401.58	-3.43	0.299	1.595
401.58	-3.36	0.298	1.594
401.59	-3.29	0.298	1.595
401.59	-3.23	0.298	1.594
401.60	-3.16	0.298	1.593
401.61	-3.09	0.298	1.594
401.62	-3.03	0.298	1.593
401.62	-2.96	0.298	1.593
401.63	-2.89	0.298	1.593
401.63	-2.83	0.298	1.593
401.64	-2.76	0.298	1.593
401.65	-2.69	0.298	1.593
401.66	-2.63	0.298	1.593
401.66	-2.56	0.298	1.592
401.67	-2.49	0.298	1.592
401.68	-2.43	0.298	1.592
401.68	-2.36	0.298	1.592
401.69	-2.29	0.298	1.591
401.69	-2.23	0.298	1.591
401.70	-2.16	0.298	1.591
401.71	-2.09	0.298	1.591
401.72	-2.02	0.298	1.592
401.72	-1.96	0.298	1.592
401.73	-1.89	0.298	1.591
401.73	-1.82	0.298	1.591
401.74	-1.76	0.298	1.590
401.75	-1.69	0.298	1.590
401.76	-1.62	0.298	1.590
401.76	-1.56	0.298	1.591
401.77	-1.49	0.298	1.591
401.78	-1.42	0.298	1.591
401.78	-1.36	0.298	1.591
401.79	-1.29	0.298	1.591
401.79	-1.22	0.298	1.591
401.80	-1.16	0.297	1.591
401.81	-1.09	0.297	1.591
401.82	-1.02	0.297	1.590
401.82	-0.96	0.297	1.590
401.83	-0.89	0.297	1.590
401.83	-0.82	0.297	1.590
401.84	-0.76	0.297	1.590
401.85	-0.69	0.297	1.590
401.86	-0.62	0.297	1.590
401.86	-0.56	0.297	1.590
401.87	-0.49	0.297	1.590
401.88	-0.42	0.297	1.590
401.88	-0.36	0.297	1.590
401.89	-0.29	0.297	1.591
401.89	-0.22	0.297	1.591
401.90	-0.16	0.297	1.591
401.91	-0.09	0.297	1.591
401.92	-0.02	0.297	1.591
401.92	0.05	0.297	1.591
401.93	0.11	0.297	1.591
401.93	0.18	0.297	1.591
401.94	0.25	0.297	1.591
401.95	0.31	0.297	1.591
401.96	0.38	0.297	1.591
401.96	0.45	0.298	1.591
401.97	0.51	0.298	1.591
401.98	0.58	0.298	1.591
401.98	0.65	0.298	1.591
401.99	0.71	0.298	1.591
401.99	0.78	0.298	1.591
402.00	0.85	0.298	1.591
402.01	0.91	0.298	1.591
402.02	0.98	0.298	1.592
402.02	1.05	0.298	1.592
402.03	1.11	0.298	1.592
402.03	1.18	0.298	1.592
402.04	1.25	0.298	1.592
402.05	1.31	0.298	1.592
402.06	1.38	0.298	1.593
402.06	1.45	0.298	1.593
402.07	1.51	0.298	1.593
402.08	1.58	0.298	1.593
402.08	1.65	0.298	1.593
402.09	1.71	0.298	1.594
402.09	1.78	0.298	1.594
402.10	1.85	0.298	1.594
402.11	1.91	0.298	1.595
402.12	1.98	0.298	1.595
402.12	2.05	0.298	1.594
402.13	2.11	0.298	1.594
402.13	2.18	0.298	1.594
402.14	2.25	0.298	1.594
402.15	2.32	0.298	1.595
402.16	2.38	0.298	1.595
402.16	2.45	0.298	1.595
402.17	2.51	0.298	1.595
402.18	2.58	0.298	1.595
402.18	2.65	0.298	1.595
402.19	2.71	0.298	1.596
402.19	2.78	0.298	1.596
402.20	2.85	0.298	1.596
402.21	2.92	0.298	1.596
402.22	2.98	0.298	1.596
402.22	3.05	0.298	1.596
402.23	3.12	0.299	1.596
402.23	3.18	0.299	1.596
402.24	3.25	0.299	1.597
402.25	3.32	0.299	1.597
402.26	3.38	0.299	1.597
402.26	3.45	0.299	1.597
402.27	3.52	0.299	1.597
402.28	3.58	0.299	1.597
402.28	3.65	0.299	1.597
402.29	3.72	0.299	1.597
402.29	3.78	0.299	1.598
402.30	3.85	0.299	1.598
402.31	3.92	0.299	1.598
402.32	3.98	0.299	1.598
402.32	4.05	0.299	1.599
402.33	4.12	0.299	1.599
402.33	4.18	0.299	1.600
402.34	4.25	0.299	1.599
402.35	4.32	0.299	1.599
402.36	4.39	0.299	1.599
402.36	4.45	0.299	1.599
402.37	4.52	0.299	1.599
402.38	4.58	0.299	1.599
402.38	4.65	0.299	1.600
402.39	4.72	0.299	1.599
402.39	4.78	0.299	1.599
402.40	4.85	0.299	1.599
402.41	4.92	0.299	1.599
402.42	4.98	0.299	1.600
402.42	5.05	0.299	1.600
402.43	5.12	0.299	1.600
402.43	5.18	0.299	1.600
402.44	5.25	0.299	1.600
402.45	5.32	0.299	1.601
402.46	5.39	0.299	1.601
402.46	5.45	0.299	1.601
402.47	5.52	0.300	1.602
402.48	5.59	0.300	1.602
402.48	5.65	0.300	1.602
402.49	5.72	0.300	1.603
402.49	5.79	0.300	1.603
402.50	5.85	0.300	1.603
402.51	5.92	0.300	1.603
402.52	5.99	0.300	1.603
402.52	6.05	0.300	1.603
402.53	6.12	0.300	1.604
402.53	6.19	0.300	1.604
402.54	6.25	0.300	1.604
402.55	6.32	0.300	1.604
402.56	6.39	0.300	1.604
402.56	6.45	0.300	1.605
402.57	6.52	0.300	1.605
402.58	6.59	0.300	1.606
402.58	6.65	0.300	1.607
402.59	6.72	0.300	1.607
402.59	6.79	0.300	1.606
402.60	6.85	0.300	1.606
402.61	6.92	0.300	1.607
402.62	6.99	0.301	1.607
402.62	7.06	0.301	1.607
402.63	7.12	0.301	1.607
402.63	7.19	0.301	1.607
402.64	7.25	0.301	1.607
402.65	7.32	0.301	1.608
402.66	7.39	0.301	1.607
402.66	7.46	0.301	1.608
402.67	7.52	0.301	1.608
402.68	7.59	0.301	1.608
402.68	7.65	0.301	1.609
402.69	7.72	0.301	1.609
402.69	7.79	0.301	1.609
402.70	7.86	0.301	1.610
402.71	7.92	0.301	1.610
402.72	7.99	0.301	1.610
402.72	8.06	0.301	1.610
402.73	8.12	0.301	1.611
402.73	8.19	0.301	1.611
402.74	8.26	0.301	1.611
402.75	8.32	0.301	1.611
402.76	8.39	0.301	1.612
402.76	8.46	0.301	1.612
402.77	8.52	0.302	1.612
402.78	8.59	0.302	1.612
402.78	8.66	0.302	1.611
402.79	8.72	0.302	1.612
402.79	8.79	0.302	1.612
402.80	8.86	0.302	1.612
402.81	8.92	0.302	1.612
402.82	8.99	0.302	1.613
402.82	9.06	0.302	1.614
402.83	9.13	0.302	1.614
402.83	9.19	0.302	1.614
402.84	9.26	0.302	1.614
402.85	9.33	0.302	1.615
402.86	9.39	0.302	1.615
402.86	9.46	0.302	1.616
402.87	9.53	0.302	1.616
402.88	9.59	0.302	1.615
402.88	9.66	0.302	1.616
402.89	9.73	0.302	1.616
402.89	9.79	0.302	1.617
402.90	9.86	0.302	1.616
402.91	9.93	0.302	1.616
402.92	9.99	0.302	1.617
402.92	10.06	0.302	1.617
402.93	10.13	0.302	1.617
402.93	10.19	0.302	1.617
402.94	10.26	0.303	1.617
402.95	10.33	0.303	1.617
402.96	10.39	0.303	1.618
402.96	10.46	0.303	1.619
402.97	10.53	0.303	1.619
402.98	10.59	0.303	1.618
402.98	10.66	0.303	1.619
402.99	10.73	0.303	1.619
402.99	10.79	0.303	1.619
403.00	10.86	0.303	1.620
403.01	10.93	0.303	1.620
403.02	10.99	0.303	1.620
403.02	11.06	0.303	1.620
403.03	11.13	0.303	1.620
403.03	11.20	0.303	1.621
403.04	11.26	0.303	1.621
403.05	11.33	0.303	1.621
403.06	11.40	0.303	1.621
403.06	11.46	0.303	1.621
403.07	11.53	0.303	1.621
403.08	11.59	0.303	1.621
403.08	11.66	0.303	1.621
403.09	11.73	0.303	1.621
403.09	11.80	0.303	1.622
403.10	11.86	0.303	1.622
403.11	11.93	0.303	1.622
403.12	12.00	0.303	1.622
403.12	12.06	0.304	1.623
403.13	12.13	0.304	1.622
403.13	12.20	0.304	1.622
403.14	12.26	0.304	1.623
403.15	12.33	0.304	1.623
403.16	12.40	0.304	1.623
403.16	12.46	0.304	1.623
403.17	12.53	0.304	1.623
403.18	12.60	0.304	1.623
403.18	12.66	0.304	1.623
403.19	12.73	0.304	1.623
403.19	12.80	0.304	1.623
403.20	12.86	0.304	1.624
403.21	12.93	0.304	1.624
403.22	13.00	0.304	1.624
403.22	13.06	0.304	1.624
403.23	13.13	0.304	1.625
403.23	13.20	0.304	1.624
403.24	13.26	0.304	1.624
403.25	13.33	0.304	1.625
403.26	13.40	0.304	1.625
403.26	13.46	0.304	1.625
403.27	13.53	0.304	1.625
403.28	13.60	0.304	1.626
403.28	13.67	0.304	1.626
403.29	13.73	0.304	1.627
403.29	13.80	0.304	1.627
403.30	13.86	0.305	1.627
403.31	13.93	0.305	1.627
403.32	14.00	0.305	1.628
403.32	14.07	0.305	1.628
403.33	14.13	0.305	1.629
403.33	14.20	0.305	1.629
403.34	14.27	0.305	1.629
403.35	14.33	0.305	1.630
403.36	14.40	0.305	1.630
403.36	14.47	0.305	1.630
403.37	14.53	0.305	1.630
403.38	14.60	0.305	1.630
403.38	14.67	0.305	1.631
403.39	14.73	0.305	1.632
403.39	14.80	0.305	1.631
403.40	14.87	0.305	1.631
403.41	14.93	0.305	1.632
403.42	15.00	0.305	1.632
403.42	15.07	0.305	1.633
403.43	15.13	0.305	1.632
403.43	15.20	0.305	1.632
403.44	15.27	0.305	1.633
403.45	15.33	0.305	1.633
403.46	15.40	0.306	1.634
403.46	15.47	0.306	1.634
403.47	15.53	0.306	1.635
403.48	15.60	0.306	1.636
403.48	15.67	0.306	1.635
403.49	15.73	0.306	1.635
403.49	15.80	0.306	1.635
403.50	15.87	0.306	1.635
403.51	15.93	0.306	1.635
403.52	16.00	0.306	1.635
403.52	16.07	0.306	1.636
403.53	16.13	0.306	1.636
403.53	16.20	0.306	1.636
403.54	16.27	0.306	1.636
403.55	16.33	0.306	1.636
403.56	16.40	0.306	1.636
403.56	16.47	0.306	1.636
403.57	16.54	0.306	1.637
403.58	16.60	0.306	1.638
403.58	16.67	0.306	1.638
403.59	16.73	0.306	1.638
403.59	16.80	0.306	1.639
403.60	16.87	0.307	1.639
403.61	16.94	0.307	1.639
403.62	17.00	0.307	1.639
403.62	17.07	0.307	1.639
403.63	17.14	0.307	1.639
403.63	17.20	0.307	1.639
403.64	17.27	0.307	1.640
403.65	17.34	0.307	1.640
403.66	17.40	0.307	1.640
403.66	17.47	0.307	1.640
403.67	17.54	0.307	1.640
403.68	17.60	0.307	1.640
403.68	17.67	0.307	1.640
403.69	17.74	0.307	1.641
403.69	17.80	0.307	1.642
403.70	17.87	0.307	1.643
403.71	17.94	0.307	1.643
403.72	18.00	0.307	1.643
403.72	18.07	0.307	1.643
403.73	18.14	0.307	1.644
403.73	18.20	0.307	1.643
403.74	18.27	0.307	1.643
403.75	18.34	0.308	1.644
403.76	18.40	0.308	1.644
403.76	18.47	0.308	1.644
403.77	18.54	0.308	1.645
403.78	18.60	0.308	1.645
403.78	18.67	0.308	1.645
403.79	18.74	0.308	1.645
403.79	18.80	0.308	1.645
403.80	18.87	0.308	1.645
403.81	18.94	0.308	1.646
403.82	19.00	0.308	1.646
403.82	19.07	0.308	1.646
403.83	19.14	0.308	1.646
403.83	19.20	0.308	1.647
403.84	19.27	0.308	1.647
403.85	19.34	0.308	1.648
403.86	19.41	0.308	1.648
403.86	19.47	0.308	1.648
403.87	19.54	0.308	1.649
403.88	19.61	0.308	1.648
403.88	19.67	0.308	1.649
403.89	19.74	0.308	1.649
403.89	19.81	0.308	1.649
403.90	19.87	0.309	1.649
403.91	19.94	0.309	1.649
403.92	20.01	0.309	1.649
403.92	20.07	0.309	1.650
403.93	20.14	0.309	1.650
403.93	20.21	0.309	1.650
403.94	20.27	0.309	1.651
403.95	20.34	0.309	1.653
403.96	20.41	0.309	1.652
403.96	20.47	0.309	1.652
403.97	20.54	0.309	1.652
403.98	20.61	0.309	1.652
403.98	20.67	0.309	1.652
403.99	20.74	0.309	1.653
403.99	20.81	0.309	1.653
404.00	20.87	0.309	1.653
404.01	20.94	0.309	1.654
404.02	21.01	0.309	1.654
404.02	21.07	0.309	1.654
404.03	21.14	0.309	1.655
404.03	21.21	0.310	1.655
404.04	21.27	0.310	1.655
404.05	21.34	0.310	1.654
404.06	21.41	0.310	1.655
404.06	21.47	0.310	1.655
404.07	21.54	0.310	1.655
404.08	21.61	0.310	1.656
404.08	21.67	0.310	1.656
404.09	21.74	0.310	1.656
404.09	21.81	0.310	1.657
404.10	21.87	0.310	1.658
404.11	21.94	0.310	1.658
404.12	22.01	0.310	1.658
404.12	22.07	0.310	1.658
404.13	22.14	0.310	1.658
404.13	22.21	0.310	1.658
404.14	22.27	0.310	1.658
404.15	22.34	0.310	1.658
404.16	22.41	0.310	1.658
404.16	22.47	0.310	1.659
404.17	22.54	0.310	1.659
404.18	22.61	0.310	1.659
404.18	22.68	0.310	1.659
404.19	22.74	0.310	1.659
404.19	22.81	0.311	1.660
404.20	22.88	0.311	1.660
404.21	22.94	0.311	1.660
404.22	23.01	0.311	1.660
404.22	23.08	0.311	1.661
404.23	23.14	0.311	1.661
404.23	23.21	0.311	1.661
404.24	23.28	0.311	1.662
404.25	23.34	0.311	1.662
404.26	23.41	0.311	1.662
404.26	23.48	0.311	1.662
404.27	23.54	0.311	1.662
404.28	23.61	0.311	1.663
404.28	23.68	0.311	1.664
404.29	23.74	0.311	1.664
404.29	23.81	0.311	1.663
404.30	23.88	0.311	1.664
404.31	23.94	0.311	1.664
404.32	24.01	0.311	1.664
404.32	24.08	0.311	1.664
404.33	24.14	0.311	1.664
404.33	24.21	0.311	1.665
404.34	24.28	0.312	1.665
404.35	24.34	0.312	1.665
404.36	24.41	0.312	1.665
404.36	24.48	0.312	1.665
404.37	24.54	0.312	1.665
404.38	24.61	0.312	1.666
404.38	24.68	0.312	1.667
404.39	24.74	0.312	1.667
404.39	24.81	0.312	1.667
404.40	24.88	0.312	1.667
404.41	24.94	0.312	1.667
404.42	25.01	0.312	1.667
404.42	25.08	0.312	1.668
404.43	25.14	0.312	1.668
404.43	25.21	0.312	1.668
404.44	25.28	0.312	1.668
404.45	25.35	0.312	1.669
404.46	25.41	0.312	1.669
404.46	25.48	0.312	1.670
404.47	25.55	0.312	1.670
404.48	25.61	0.312	1.670
404.48	25.68	0.313	1.670
404.49	25.74	0.313	1.670
404.49	25.81	0.313	1.671
404.50	25.88	0.313	1.670
404.51	25.95	0.313	1.670
404.52	26.01	0.313	1.671
404.52	26.08	0.313	1.672
404.53	26.15	0.313	1.671
404.53	26.21	0.313	1.672
404.54	26.28	0.313	1.673
404.55	26.35	0.313	1.673
404.56	26.41	0.313	1.673
404.56	26.48	0.313	1.673
404.57	26.55	0.313	1.673
404.58	26.61	0.313	1.674
404.58	26.68	0.313	1.674
404.59	26.75	0.313	1.674
404.59	26.81	0.313	1.674
404.60	26.88	0.313	1.675
404.61	26.95	0.313	1.675
404.62	27.01	0.313	1.675
404.62	27.08	0.313	1.675
404.63	27.15	0.314	1.676
404.63	27.21	0.314	1.676
404.64	27.28	0.314	1.677
404.65	27.35	0.314	1.677
404.66	27.41	0.314	1.677
404.66	27.48	0.314	1.677
404.67	27.55	0.314	1.677
404.68	27.62	0.314	1.677
404.68	27.68	0.314	1.678
404.69	27.75	0.314	1.678
404.69	27.81	0.314	1.678
404.70	27.88	0.314	1.679
404.71	27.95	0.314	1.679
404.72	28.02	0.314	1.679
404.72	28.08	0.314	1.680
404.73	28.15	0.314	1.680
404.73	28.22	0.314	1.680
404.74	28.28	0.314	1.680
404.75	28.35	0.314	1.680
404.76	28.42	0.314	1.680
404.76	28.48	0.314	1.680
404.77	28.55	0.314	1.681
404.78	28.62	0.315	1.681
404.78	28.68	0.315	1.681
404.79	28.75	0.315	1.681
404.79	28.82	0.315	1.681
404.80	28.88	0.315	1.682
404.81	28.95	0.315	1.682
404.82	29.02	0.315	1.683
404.82	29.08	0.315	1.683
404.83	29.15	0.315	1.683
404.83	29.22	0.315	1.682
404.84	29.28	0.315	1.683
404.85	29.35	0.315	1.683
404.86	29.42	0.315	1.683
404.86	29.48	0.315	1.683
404.87	29.55	0.315	1.684
404.88	29.62	0.315	1.684
404.88	29.68	0.315	1.684
404.89	29.75	0.315	1.685
404.89	29.82	0.315	1.685
404.90	29.88	0.315	1.685
404.91	29.95	0.315	1.685
404.92	30.02	0.315	1.686
404.92	30.08	0.315	1.685
404.93	30.15	0.315	1.686
404.93	30.22	0.315	1.686
404.94	30.29	0.316	1.686
404.95	30.35	0.316	1.686
404.96	30.42	0.316	1.687
404.96	30.49	0.316	1.688
404.97	30.55	0.316	1.688
404.98	30.62	0.316	1.688
404.98	30.69	0.316	1.688
404.99	30.75	0.316	1.688
404.99	30.82	0.316	1.688
405.00	30.88	0.316	1.688
405.01	30.95	0.316	1.689
405.02	31.02	0.316	1.689
405.02	31.09	0.316	1.689
405.03	31.15	0.316	1.689
405.03	31.22	0.316	1.690
405.04	31.29	0.316	1.690
405.05	31.35	0.316	1.690
405.06	31.42	0.316	1.690
405.06	31.49	0.316	1.691
405.07	31.55	0.316	1.691
405.08	31.62	0.316	1.691
405.08	31.69	0.316	1.691
405.09	31.75	0.316	1.691
405.09	31.82	0.317	1.692
405.10	31.89	0.317	1.692
405.11	31.95	0.317	1.693
405.12	32.02	0.317	1.693
405.12	32.09	0.317	1.693
405.13	32.15	0.317	1.693
405.13	32.22	0.317	1.694
405.14	32.29	0.317	1.694
405.15	32.35	0.317	1.694
405.16	32.42	0.317	1.695
405.16	32.49	0.317	1.695
405.17	32.55	0.317	1.695
405.18	32.62	0.317	1.695
405.18	32.69	0.317	1.696
405.19	32.75	0.317	1.696
405.19	32.82	0.317	1.697
405.20	32.89	0.317	1.697
405.21	32.95	0.317	1.696
405.22	33.02	0.317	1.696
405.22	33.09	0.317	1.697
405.23	33.15	0.317	1.698
405.23	33.22	0.317	1.698
405.24	33.29	0.317	1.697
405.25	33.36	0.317	1.697
405.26	33.42	0.317	1.698
405.26	33.49	0.318	1.698
405.27	33.55	0.318	1.698
405.28	33.62	0.318	1.699
405.28	33.69	0.318	1.699
405.29	33.75	0.318	1.699
405.29	33.82	0.318	1.699
405.30	33.89	0.318	1.699
405.31	33.96	0.318	1.699
405.32	34.02	0.318	1.700
405.32	34.09	0.318	1.700
405.33	34.16	0.318	1.700
405.33	34.22	0.318	1.700
405.34	34.29	0.318	1.701
405.35	34.36	0.318	1.701
405.36	34.42	0.318	1.701
405.36	34.49	0.318	1.701
405.37	34.56	0.318	1.702
405.38	34.62	0.318	1.702
405.38	34.69	0.318	1.701
405.39	34.76	0.318	1.701
405.39	34.82	0.318	1.702
405.40	34.89	0.318	1.703
405.41	34.96	0.318	1.703
405.42	35.02	0.318	1.703
405.42	35.09	0.318	1.702
405.43	35.16	0.319	1.702
405.43	35.22	0.319	1.703
405.44	35.29	0.319	1.704
405.45	35.36	0.319	1.704
405.46	35.42	0.319	1.704
405.46	35.49	0.319	1.704
405.47	35.56	0.319	1.704
405.48	35.62	0.319	1.704
405.48	35.69	0.319	1.704
405.49	35.76	0.319	1.704
405.49	35.82	0.319	1.705
405.50	35.89	0.319	1.706
405.51	35.96	0.319	1.706
405.52	36.02	0.319	1.705
405.52	36.09	0.319	1.706
405.53	36.16	0.319	1.706
405.53	36.22	0.319	1.706
405.54	36.29	0.319	1.707
405.55	36.36	0.319	1.707
405.56	36.43	0.319	1.706
405.56	36.49	0.319	1.707
405.57	36.56	0.319	1.707
405.58	36.62	0.319	1.707
405.58	36.69	0.320	1.708
405.59	36.76	0.320	1.708
405.59	36.83	0.320	1.708
405.60	36.89	0.320	1.707
405.61	36.96	0.320	1.708
405.62	37.03	0.320	1.708
405.62	37.09	0.320	1.709
405.63	37.16	0.320	1.709
405.63	37.23	0.320
405.64	37.29	0.320
405.65	37.36	0.320
405.66	37.43	0.320
405.66	37.49	0.320
405.67	37.56	0.320
405.68	37.63	0.320
405.68	37.69	0.320
405.69	37.76	0.320
405.69	37.83
405.70	37.89
405.71	37.96
405.72	38.03
405.72	38.09
405.73	38.16
405.73	38.23
405.74
405.75