File: DSC/2023_07_18_OTP_fragility_SBK.txt
Filename	2023_07_18_OTP_fragility_SBK
Instrument name	DSC2A-00468 (192.168.1.100)
Operator	SBK
rundate	7/18/2023
Sample name	2023_07_18_OTP_fragility_SBK
proceduresegments	Data Off ; Equilibrate -50.00 °C; Data On ; Ramp 10.00 °C/min to 80.00 °C; Data Off ; Isothermal 1.0 min; Data On ; Ramp 10.00 °C/min to -50.00 °C; Data Off ; Isothermal 1.0 min; Data On ; Ramp 10.00 °C/min to 0.00 °C; Data Off ; Isothermal 1.0 min; Data On ; Ramp 35.00 °C/min to -50.00 °C; Data Off ; Isothermal 1.0 min; Data On ; Ramp 10.00 °C/min to 0.00 °C; Data Off ; Isothermal 1.0 min; Data On ; Ramp 25.00 °C/min to -50.00 °C; Data Off ; Isothermal 1.0 min; Data On ; Ramp 10.00 °C/min to 0.00 °C; Data Off ; Isothermal 1.0 min; Data On ; Ramp 20.00 °C/min to -50.00 °C; Data Off ; Isothermal 1.0 min; Data On ; Ramp 10.00 °C/min to 0.00 °C; Data Off ; Isothermal 1.0 min; Data On ; Sample Interval  0.2 s/pt; Ramp 5.00 °C/min to -50.00 °C; Data Off ; Isothermal 1.0 min; Data On ; Sample Interval  0.1 s/pt; Ramp 10.00 °C/min to 0.00 °C; Data Off ; Isothermal 1.0 min; Data On ; Sample Interval  1.0 s/pt; Ramp 1.00 °C/min to -50.00 °C; Data Off ; Isothermal 1.0 min; Data On ; Sample Interval  0.1 s/pt; Ramp 10.00 °C/min to 0.00 °C; Data Off ; Isothermal 1.0 min; Data On ; Sample Interval  2.0 s/pt; Ramp 0.50 °C/min to -50.00 °C; Data Off ; Isothermal 1.0 min; Data On ; Sample Interval  0.1 s/pt; Ramp 10.00 °C/min to 0.00 °C; Data Off ; Equilibrate 20.00 °C; Isothermal 500.0 min
[File Parameters]
Run date	7/18/2023 6:09:59 PM
Trios version	5.1.1.46572
Original File Name	C:\Users\yargerlab\Desktop\DSC Data\General\2023_07_18_OTP_fragility_SBK.tri
Current File Name	C:\Users\kauff\Documents\ASU\data_DSC\2023_07_18_OTP_fragility_SBK.tri
[Procedure]
Procedure Name	DSC -50C to 80C Varied cooling rates OTP fragility
Sample Name	2023_07_18_OTP_fragility_SBK
Sample Mass	2.47 mg
Reference Sample Mass	0 mg
Pan Mass	52.86 mg
Pan Number	8
Reference Pan Mass	53.66 mg
Reference Pan Number	46
Pan Type	Aluminum Hermetic
Comments	o-Terphenyl in DSC84010 aluminum pan and DSC84011 hermetic aluminum lid. Validation of fragility test method.
Project Name	SIlk ASDs
Operator	SBK
Test	Custom
Unload Max Temperature	30
Unload Min Temperature	30
Load Max Temperature	30
Load Min Temperature	30
Stop on Gas Flow Error	Yes
[Signal List]
Signal #1	Time (min)
Signal #2	Temperature (°C)
Signal #3	Heat Flow (mW)
Signal #4	Delta T (µV)
Signal #5	Delta Tzero (µV)
Signal #6	Tzero Temperature (°C)
Signal #7	Cell Purge (mL/min)
Signal #8	Heater Temp (°C)
Signal #9	Power Delivered (W)
Signal #10	Reference Junction Temperature (°C)
Signal #11	Flange Temperature (°C)
Signal #12	Heat Flow Phase (rad)
Signal #13	Total Heat Capacity (J/°C)
Signal #14	Heat Capacity (J/°C)
[Configuration]
Company Name	ASU
Instrument Name	DSC2A-00468
Instrument Type	DSC2500
Serial Number	DSC2A-00468
IP	192.168.1.100
Location of Instrument	MRRC
DisplayType	Unknown
Sample Interval 	0.1 s/pt
Selected Heat Flow	T4P
Exotherm Direction	Down
Cell Serial	DRC2-00792
Lid Type	Standard
Cooler	RCS 90
Leave Cooler on at End of Sequence	On
Gas 2	Nitrogen
Gas Selected	Channel 1
Flow Rate	50 mL/min
Secondary Purge	On
Licensed Heat Flow	Heat Flow T4P
Modulation Licensed	Yes
[Versions]
Common IDD Version	1
Cortex Version	VER 2.10.2.31
Driver	5.0.0.6
GDM Version	1.0.3.3
TouchscreenVersion	1.0.0.16145
FEP Version	1.2.1.21
FEP Bootloader	2.0.0.5
AutoSampler Version	2.1.1.26
Auto Sampler Bootloader	2.0.0.5
FCM Version	1.1.0.3
FCM Bootloader	2.0.0.5
[Experiment Logs]
Experiment Log Entry # 1	Data On set to 0
Experiment Log Entry # 3	Equilibrate Segment -50 (C) Started
Experiment Log Entry # 5	Air Cool is off.
Experiment Log Entry # 7	Data On set to 1
Experiment Log Entry # 9	Ramp Segment 10 C/min to 80 Started
Experiment Log Entry # 11	Data On set to 0
Experiment Log Entry # 13	Isothermal Segment 1 min started
Experiment Log Entry # 15	Data On set to 1
Experiment Log Entry # 17	Ramp Segment 10 C/min to -50 Started
Experiment Log Entry # 19	Data On set to 0
Experiment Log Entry # 21	Isothermal Segment 1 min started
Experiment Log Entry # 23	Data On set to 1
Experiment Log Entry # 25	Ramp Segment 10 C/min to 0 Started
Experiment Log Entry # 27	Data On set to 0
Experiment Log Entry # 29	Isothermal Segment 1 min started
Experiment Log Entry # 31	Data On set to 1
Experiment Log Entry # 33	Ramp Segment 35 C/min to -50 Started
Experiment Log Entry # 35	Data On set to 0
Experiment Log Entry # 37	Isothermal Segment 1 min started
Experiment Log Entry # 39	Data On set to 1
Experiment Log Entry # 41	Ramp Segment 10 C/min to 0 Started
Experiment Log Entry # 43	Data On set to 0
Experiment Log Entry # 45	Isothermal Segment 1 min started
Experiment Log Entry # 47	Data On set to 1
Experiment Log Entry # 49	Ramp Segment 25 C/min to -50 Started
Experiment Log Entry # 51	Data On set to 0
Experiment Log Entry # 53	Isothermal Segment 1 min started
Experiment Log Entry # 55	Data On set to 1
Experiment Log Entry # 57	Ramp Segment 10 C/min to 0 Started
Experiment Log Entry # 59	Data On set to 0
Experiment Log Entry # 61	Isothermal Segment 1 min started
Experiment Log Entry # 63	Data On set to 1
Experiment Log Entry # 65	Ramp Segment 20 C/min to -50 Started
Experiment Log Entry # 67	Data On set to 0
Experiment Log Entry # 69	Isothermal Segment 1 min started
Experiment Log Entry # 71	Data On set to 1
Experiment Log Entry # 73	Ramp Segment 10 C/min to 0 Started
Experiment Log Entry # 75	Data On set to 0
Experiment Log Entry # 77	Isothermal Segment 1 min started
Experiment Log Entry # 79	Data On set to 1
Experiment Log Entry # 81	Sampling Rate set to 0.2 sec/pt
Experiment Log Entry # 83	Ramp Segment 5 C/min to -50 Started
Experiment Log Entry # 85	Data On set to 0
Experiment Log Entry # 87	Isothermal Segment 1 min started
Experiment Log Entry # 89	Data On set to 1
Experiment Log Entry # 91	Sampling Rate set to 0.1 sec/pt
Experiment Log Entry # 93	Ramp Segment 10 C/min to 0 Started
Experiment Log Entry # 95	Data On set to 0
Experiment Log Entry # 97	Isothermal Segment 1 min started
Experiment Log Entry # 99	Data On set to 1
Experiment Log Entry # 101	Sampling Rate set to 1 sec/pt
Experiment Log Entry # 103	Ramp Segment 1 C/min to -50 Started
Experiment Log Entry # 105	Data On set to 0
Experiment Log Entry # 107	Isothermal Segment 1 min started
Experiment Log Entry # 109	Data On set to 1
Experiment Log Entry # 111	Sampling Rate set to 0.1 sec/pt
Experiment Log Entry # 113	Ramp Segment 10 C/min to 0 Started
Experiment Log Entry # 115	Data On set to 0
Experiment Log Entry # 117	Isothermal Segment 1 min started
Experiment Log Entry # 119	Data On set to 1
Experiment Log Entry # 121	Sampling Rate set to 2 sec/pt
Experiment Log Entry # 123	Ramp Segment 0.5 C/min to -50 Started
Experiment Log Entry # 125	Data On set to 0
Experiment Log Entry # 127	Isothermal Segment 1 min started
Experiment Log Entry # 129	Data On set to 1
Experiment Log Entry # 131	Sampling Rate set to 0.1 sec/pt
Experiment Log Entry # 133	Ramp Segment 10 C/min to 0 Started
Experiment Log Entry # 135	Data On set to 0
Experiment Log Entry # 137	Equilibrate Segment 20 (C) Started
Experiment Log Entry # 139	Isothermal Segment 500 min started
Experiment Log Entry # 141	FEP has detected that FCM has gone offline
[Method Log]
Method Log Entry # 1	Data Off
Method Log Entry # 2	Equilibrate -50 °C
Method Log Entry # 3	Data On
Method Log Entry # 4	(Ramp 62596) Ramp 10 °C/minute to 80 °C
Method Log Entry # 5	Data Off
Method Log Entry # 6	Isothermal 1 minutes
Method Log Entry # 7	Data On
Method Log Entry # 8	(Ramp 62600) Ramp 10 °C/minute to -50 °C
Method Log Entry # 9	Data Off
Method Log Entry # 10	Isothermal 1 minutes
Method Log Entry # 11	Data On
Method Log Entry # 12	(Ramp 62604) Ramp 10 °C/minute to 0 °C
Method Log Entry # 13	Data Off
Method Log Entry # 14	Isothermal 1 minutes
Method Log Entry # 15	Data On
Method Log Entry # 16	(Ramp 62608) Ramp 35 °C/minute to -50 °C
Method Log Entry # 17	Data Off
Method Log Entry # 18	Isothermal 1 minutes
Method Log Entry # 19	Data On
Method Log Entry # 20	(Ramp 62612) Ramp 10 °C/minute to 0 °C
Method Log Entry # 21	Data Off
Method Log Entry # 22	Isothermal 1 minutes
Method Log Entry # 23	Data On
Method Log Entry # 24	(Ramp 62616) Ramp 25 °C/minute to -50 °C
Method Log Entry # 25	Data Off
Method Log Entry # 26	Isothermal 1 minutes
Method Log Entry # 27	Data On
Method Log Entry # 28	(Ramp 62620) Ramp 10 °C/minute to 0 °C
Method Log Entry # 29	Data Off
Method Log Entry # 30	Isothermal 1 minutes
Method Log Entry # 31	Data On
Method Log Entry # 32	(Ramp 62624) Ramp 20 °C/minute to -50 °C
Method Log Entry # 33	Data Off
Method Log Entry # 34	Isothermal 1 minutes
Method Log Entry # 35	Data On
Method Log Entry # 36	(Ramp 62628) Ramp 10 °C/minute to 0 °C
Method Log Entry # 37	Data Off
Method Log Entry # 38	Isothermal 1 minutes
Method Log Entry # 39	Data On
Method Log Entry # 40	Sampling Interval 0.2 Seconds/point
Method Log Entry # 41	(Ramp 62633) Ramp 5 °C/minute to -50 °C
Method Log Entry # 42	Data Off
Method Log Entry # 43	Isothermal 1 minutes
Method Log Entry # 44	Data On
Method Log Entry # 45	Sampling Interval 0.1 Seconds/point
Method Log Entry # 46	(Ramp 62638) Ramp 10 °C/minute to 0 °C
Method Log Entry # 47	Data Off
Method Log Entry # 48	Isothermal 1 minutes
Method Log Entry # 49	Data On
Method Log Entry # 50	Sampling Interval 1 Seconds/point
Method Log Entry # 51	(Ramp 62643) Ramp 1 °C/minute to -50 °C
Method Log Entry # 52	Data Off
Method Log Entry # 53	Isothermal 1 minutes
Method Log Entry # 54	Data On
Method Log Entry # 55	Sampling Interval 0.1 Seconds/point
Method Log Entry # 56	(Ramp 62648) Ramp 10 °C/minute to 0 °C
Method Log Entry # 57	Data Off
Method Log Entry # 58	Isothermal 1 minutes
Method Log Entry # 59	Data On
Method Log Entry # 60	Sampling Interval 2 Seconds/point
Method Log Entry # 61	(Ramp 62653) Ramp 0.5 °C/minute to -50 °C
Method Log Entry # 62	Data Off
Method Log Entry # 63	Isothermal 1 minutes
Method Log Entry # 64	Data On
Method Log Entry # 65	Sampling Interval 0.1 Seconds/point
Method Log Entry # 66	(Ramp 62658) Ramp 10 °C/minute to 0 °C
Method Log Entry # 67	Data Off
Method Log Entry # 68	Equilibrate 20 °C
Method Log Entry # 69	Isothermal 500 minutes
Cell Serial	DRC2-00792
[T1 Calibration]
Slope	-0.008529666
Offset	9.636258
Initial Temperature	98.23
GUID	f8bfdadc-4977-4fdf-ba6d-0ba9134940c3
[TZero Calibration]
Date Applied	11/29/2022 4:06:13 PM
Description	From -89.059 °C to 396.009 °C at 20.000°C/min
Gas Type	Nitrogen
Pan Type	None
Source Files 1	C:\Users\yargerlab\Desktop\DSC Data\General\TZero_calibration_11_29_22_2nd(2).tri
Source Files 2	C:\Users\yargerlab\Desktop\DSC Data\General\TZero_calibration_11_29_22_2nd(3).tri
Delta T Offset	13.05235
Delta T Slope	-0.007271007
Delta T0 Offset	-13.69128
Delta T0 Slope	0.06063341
[Temperature Calibration]
Date Applied	11/29/2022 7:12:28 PM
Description	From 106.590 °C to 186.590 °C at 10.000°C/min
Gas Type	Nitrogen
Pan Type	Tzero Aluminum Hermetic
Source Files 1	C:\Users\yargerlab\Desktop\DSC Data\General\Indium(6).tri
Measured 1	157.391
Known 1	156.598
[Cell Constant Calibration]
Date Applied	11/29/2022 7:12:29 PM
Description	From 106.590 °C to 186.590 °C at 10.000°C/min
Gas Type	Nitrogen
Pan Type	Tzero Aluminum Hermetic
Source Files 1	C:\Users\yargerlab\Desktop\DSC Data\General\Indium(6).tri
T4P KCell	1.006051
Onset Slope	63.26126 mW/°C
[Direct Cp Calibration]
Date Applied	11/30/2022 11:04:51 AM
Description	From -79.983 °C to 298.409 °C at 10.000°C/min
Gas Type	Nitrogen
Pan Type	Tzero Aluminum Hermetic
Source Files 1	C:\Users\yargerlab\Desktop\DSC Data\General\Sapphire_Heat_Capacity_11_30_22.tri
[Rev Cp Calibration]
Date Applied	11/30/2022 1:58:51 PM
Description	From -79.996 °C to 292.812 °C at 3.000°C/min
Gas Type	Nitrogen
Pan Type	Tzero Aluminum Hermetic
Source Files 1	C:\Users\yargerlab\Desktop\DSC Data\General\Sapphire_MDSC_Calibration_11_30_22.tri
[step]
Ramp 10.00 °C/min to 80.00 °C
Time	Temperature	Heat Flow (Normalized)	Heat Capacity (Normalized)
min	°C	W/g	J/(g.°C)
0.00	-49.74	-0.032	0.000
0.01	-49.75	-0.031	0.000
0.02	-49.75	-0.030	0.000
0.03	-49.76	-0.029	0.000
0.04	-49.76	-0.027	0.000
0.05	-49.76	-0.022	0.000
0.06	-49.75	-0.016	-0.558
0.07	-49.74	-0.006	-0.177
0.08	-49.73	0.004	0.089
0.09	-49.71	0.015	0.294
0.10	-49.69	0.024	0.409
0.11	-49.66	0.035	0.531
0.12	-49.62	0.046	0.622
0.13	-49.58	0.054	0.664
0.14	-49.53	0.065	0.720
0.15	-49.47	0.075	0.767
0.16	-49.42	0.087	0.822
0.17	-49.35	0.093	0.822
0.18	-49.29	0.104	0.872
0.19	-49.22	0.109	0.865
0.20	-49.14	0.118	0.892
0.21	-49.06	0.126	0.915
0.22	-48.99	0.131	0.912
0.23	-48.91	0.139	0.937
0.24	-48.83	0.143	0.944
0.25	-48.74	0.146	0.937
0.26	-48.66	0.151	0.952
0.27	-48.58	0.157	0.970
0.28	-48.49	0.159	0.968
0.29	-48.40	0.161	0.967
0.30	-48.31	0.166	0.984
0.31	-48.22	0.169	0.992
0.32	-48.13	0.171	0.994
0.33	-48.04	0.173	0.998
0.34	-47.95	0.175	1.003
0.35	-47.86	0.176	1.001
0.36	-47.77	0.178	1.006
0.37	-47.67	0.179	1.005
0.38	-47.58	0.180	1.005
0.39	-47.49	0.180	1.006
0.40	-47.39	0.181	1.005
0.41	-47.30	0.182	1.007
0.42	-47.20	0.183	1.009
0.43	-47.11	0.184	1.009
0.44	-47.01	0.185	1.013
0.45	-46.92	0.186	1.016
0.46	-46.82	0.187	1.016
0.47	-46.73	0.187	1.017
0.48	-46.63	0.188	1.017
0.49	-46.53	0.188	1.016
0.50	-46.44	0.188	1.016
0.51	-46.34	0.189	1.018
0.52	-46.25	0.189	1.019
0.53	-46.15	0.189	1.018
0.54	-46.05	0.190	1.019
0.55	-45.95	0.190	1.019
0.56	-45.86	0.190	1.020
0.57	-45.76	0.191	1.021
0.58	-45.66	0.191	1.022
0.59	-45.57	0.191	1.023
0.60	-45.47	0.192	1.024
0.61	-45.37	0.192	1.025
0.62	-45.27	0.192	1.025
0.63	-45.17	0.192	1.025
0.64	-45.08	0.193	1.026
0.65	-44.98	0.193	1.027
0.66	-44.88	0.193	1.027
0.67	-44.78	0.194	1.029
0.68	-44.68	0.194	1.029
0.69	-44.59	0.194	1.029
0.70	-44.49	0.194	1.031
0.71	-44.39	0.194	1.032
0.72	-44.29	0.195	1.032
0.73	-44.19	0.195	1.034
0.74	-44.09	0.195	1.034
0.75	-44.00	0.195	1.034
0.76	-43.90	0.196	1.036
0.77	-43.80	0.196	1.037
0.78	-43.70	0.196	1.037
0.79	-43.60	0.196	1.037
0.80	-43.50	0.196	1.038
0.81	-43.40	0.197	1.039
0.82	-43.30	0.197	1.039
0.83	-43.21	0.197	1.039
0.84	-43.11	0.197	1.039
0.85	-43.01	0.197	1.040
0.86	-42.91	0.197	1.041
0.87	-42.81	0.197	1.041
0.88	-42.71	0.197	1.042
0.89	-42.61	0.198	1.042
0.90	-42.51	0.198	1.042
0.91	-42.42	0.198	1.042
0.92	-42.32	0.198	1.043
0.93	-42.22	0.198	1.043
0.94	-42.12	0.198	1.043
0.95	-42.02	0.198	1.044
0.96	-41.92	0.198	1.044
0.97	-41.82	0.198	1.044
0.98	-41.72	0.198	1.044
0.99	-41.62	0.198	1.044
1.00	-41.52	0.198	1.044
1.01	-41.42	0.199	1.045
1.02	-41.32	0.199	1.045
1.03	-41.22	0.199	1.045
1.04	-41.13	0.199	1.046
1.05	-41.03	0.199	1.046
1.06	-40.93	0.199	1.046
1.07	-40.83	0.199	1.047
1.08	-40.73	0.199	1.047
1.09	-40.63	0.199	1.047
1.10	-40.53	0.199	1.047
1.11	-40.43	0.199	1.047
1.12	-40.33	0.199	1.047
1.13	-40.23	0.199	1.047
1.14	-40.13	0.199	1.046
1.15	-40.03	0.199	1.047
1.16	-39.93	0.199	1.047
1.17	-39.83	0.199	1.047
1.18	-39.73	0.199	1.047
1.19	-39.63	0.199	1.047
1.20	-39.53	0.199	1.047
1.21	-39.43	0.199	1.048
1.22	-39.33	0.199	1.047
1.23	-39.23	0.199	1.048
1.24	-39.14	0.199	1.048
1.25	-39.03	0.199	1.048
1.26	-38.94	0.199	1.048
1.27	-38.84	0.199	1.048
1.28	-38.73	0.199	1.047
1.29	-38.64	0.199	1.047
1.30	-38.54	0.199	1.047
1.31	-38.44	0.199	1.047
1.32	-38.34	0.199	1.048
1.33	-38.24	0.199	1.048
1.34	-38.14	0.199	1.047
1.35	-38.04	0.199	1.047
1.36	-37.94	0.199	1.047
1.37	-37.84	0.199	1.047
1.38	-37.74	0.199	1.047
1.39	-37.64	0.199	1.047
1.40	-37.54	0.199	1.046
1.41	-37.44	0.199	1.046
1.42	-37.34	0.199	1.047
1.43	-37.24	0.199	1.046
1.44	-37.14	0.199	1.046
1.45	-37.04	0.199	1.047
1.46	-36.94	0.199	1.046
1.47	-36.84	0.199	1.046
1.48	-36.74	0.199	1.046
1.49	-36.64	0.199	1.047
1.50	-36.54	0.199	1.047
1.51	-36.44	0.199	1.047
1.52	-36.34	0.199	1.047
1.53	-36.24	0.199	1.047
1.54	-36.14	0.199	1.047
1.55	-36.04	0.199	1.046
1.56	-35.94	0.199	1.046
1.57	-35.84	0.199	1.047
1.58	-35.74	0.199	1.047
1.59	-35.64	0.199	1.046
1.60	-35.54	0.199	1.047
1.61	-35.44	0.199	1.046
1.62	-35.34	0.199	1.046
1.63	-35.24	0.199	1.046
1.64	-35.14	0.199	1.046
1.65	-35.04	0.199	1.047
1.66	-34.94	0.199	1.047
1.67	-34.84	0.199	1.046
1.68	-34.74	0.199	1.047
1.69	-34.64	0.199	1.047
1.70	-34.54	0.199	1.046
1.71	-34.44	0.199	1.046
1.72	-34.34	0.199	1.047
1.73	-34.24	0.199	1.046
1.74	-34.14	0.199	1.046
1.75	-34.04	0.199	1.046
1.76	-33.94	0.199	1.046
1.77	-33.84	0.199	1.046
1.78	-33.74	0.199	1.045
1.79	-33.64	0.199	1.046
1.80	-33.54	0.199	1.047
1.81	-33.44	0.199	1.047
1.82	-33.34	0.199	1.047
1.83	-33.24	0.199	1.046
1.84	-33.14	0.199	1.046
1.85	-33.04	0.199	1.047
1.86	-32.94	0.199	1.046
1.87	-32.84	0.199	1.046
1.88	-32.74	0.199	1.047
1.89	-32.64	0.199	1.046
1.90	-32.54	0.199	1.047
1.91	-32.44	0.199	1.047
1.92	-32.34	0.199	1.047
1.93	-32.24	0.199	1.046
1.94	-32.14	0.199	1.047
1.95	-32.04	0.199	1.047
1.96	-31.94	0.199	1.047
1.97	-31.84	0.199	1.046
1.98	-31.74	0.199	1.047
1.99	-31.64	0.199	1.046
2.00	-31.54	0.199	1.046
2.01	-31.44	0.199	1.046
2.02	-31.34	0.199	1.046
2.03	-31.24	0.199	1.046
2.04	-31.14	0.199	1.046
2.05	-31.04	0.199	1.046
2.06	-30.94	0.199	1.046
2.07	-30.84	0.199	1.047
2.08	-30.74	0.199	1.046
2.09	-30.64	0.199	1.048
2.10	-30.54	0.199	1.048
2.11	-30.44	0.199	1.047
2.12	-30.34	0.199	1.047
2.13	-30.24	0.199	1.048
2.14	-30.14	0.199	1.047
2.15	-30.04	0.199	1.047
2.16	-29.94	0.199	1.047
2.17	-29.84	0.199	1.047
2.18	-29.74	0.199	1.047
2.19	-29.64	0.198	1.047
2.20	-29.54	0.199	1.047
2.21	-29.44	0.198	1.046
2.22	-29.34	0.198	1.047
2.23	-29.24	0.199	1.048
2.24	-29.14	0.198	1.047
2.25	-29.04	0.199	1.047
2.26	-28.94	0.199	1.048
2.27	-28.84	0.199	1.048
2.28	-28.74	0.199	1.048
2.29	-28.64	0.199	1.048
2.30	-28.54	0.199	1.048
2.31	-28.44	0.199	1.048
2.32	-28.34	0.199	1.048
2.33	-28.24	0.199	1.048
2.34	-28.14	0.199	1.049
2.35	-28.04	0.199	1.048
2.36	-27.94	0.198	1.048
2.37	-27.84	0.199	1.049
2.38	-27.74	0.199	1.049
2.39	-27.64	0.199	1.049
2.40	-27.54	0.198	1.048
2.41	-27.44	0.199	1.049
2.42	-27.34	0.199	1.049
2.43	-27.24	0.199	1.049
2.44	-27.14	0.199	1.050
2.45	-27.04	0.199	1.050
2.46	-26.94	0.199	1.050
2.47	-26.84	0.199	1.049
2.48	-26.74	0.199	1.049
2.49	-26.64	0.199	1.049
2.50	-26.54	0.199	1.049
2.51	-26.44	0.199	1.050
2.52	-26.34	0.199	1.050
2.53	-26.24	0.199	1.050
2.54	-26.13	0.199	1.049
2.55	-26.04	0.199	1.050
2.56	-25.94	0.199	1.050
2.57	-25.84	0.199	1.051
2.58	-25.73	0.199	1.050
2.59	-25.63	0.199	1.051
2.60	-25.53	0.199	1.050
2.61	-25.43	0.199	1.051
2.62	-25.33	0.199	1.051
2.63	-25.23	0.199	1.051
2.64	-25.13	0.199	1.051
2.65	-25.03	0.199	1.051
2.66	-24.93	0.199	1.050
2.67	-24.83	0.199	1.050
2.68	-24.73	0.199	1.051
2.69	-24.63	0.199	1.051
2.70	-24.53	0.199	1.051
2.71	-24.43	0.199	1.051
2.72	-24.33	0.199	1.052
2.73	-24.23	0.199	1.052
2.74	-24.13	0.199	1.052
2.75	-24.03	0.199	1.052
2.76	-23.93	0.199	1.052
2.77	-23.83	0.199	1.052
2.78	-23.73	0.199	1.052
2.79	-23.63	0.199	1.052
2.80	-23.53	0.199	1.052
2.81	-23.43	0.199	1.053
2.82	-23.33	0.199	1.053
2.83	-23.23	0.199	1.053
2.84	-23.13	0.199	1.053
2.85	-23.03	0.199	1.053
2.86	-22.93	0.199	1.054
2.87	-22.83	0.199	1.054
2.88	-22.73	0.199	1.054
2.89	-22.63	0.199	1.054
2.90	-22.53	0.199	1.054
2.91	-22.43	0.199	1.055
2.92	-22.33	0.199	1.054
2.93	-22.23	0.199	1.055
2.94	-22.13	0.199	1.055
2.95	-22.03	0.199	1.054
2.96	-21.93	0.199	1.055
2.97	-21.83	0.199	1.055
2.98	-21.73	0.199	1.055
2.99	-21.63	0.199	1.055
3.00	-21.53	0.199	1.055
3.01	-21.43	0.199	1.056
3.02	-21.33	0.199	1.056
3.03	-21.23	0.199	1.056
3.04	-21.13	0.199	1.056
3.05	-21.03	0.199	1.057
3.06	-20.93	0.199	1.057
3.07	-20.83	0.199	1.057
3.08	-20.73	0.199	1.057
3.09	-20.63	0.199	1.057
3.10	-20.53	0.199	1.057
3.11	-20.43	0.199	1.057
3.12	-20.33	0.199	1.057
3.13	-20.23	0.199	1.057
3.14	-20.13	0.199	1.058
3.15	-20.03	0.199	1.058
3.16	-19.93	0.199	1.058
3.17	-19.83	0.199	1.058
3.18	-19.73	0.199	1.058
3.19	-19.63	0.199	1.058
3.20	-19.53	0.199	1.058
3.21	-19.43	0.199	1.058
3.22	-19.33	0.199	1.058
3.23	-19.23	0.199	1.058
3.24	-19.13	0.199	1.059
3.25	-19.03	0.199	1.059
3.26	-18.93	0.199	1.058
3.27	-18.83	0.199	1.058
3.28	-18.73	0.200	1.060
3.29	-18.63	0.200	1.059
3.30	-18.53	0.200	1.059
3.31	-18.43	0.200	1.060
3.32	-18.32	0.200	1.059
3.33	-18.22	0.200	1.060
3.34	-18.13	0.200	1.060
3.35	-18.02	0.200	1.060
3.36	-17.92	0.200	1.060
3.37	-17.82	0.200	1.061
3.38	-17.72	0.200	1.061
3.39	-17.62	0.200	1.061
3.40	-17.52	0.200	1.061
3.41	-17.42	0.200	1.061
3.42	-17.32	0.200	1.062
3.43	-17.22	0.200	1.062
3.44	-17.12	0.200	1.061
3.45	-17.02	0.200	1.061
3.46	-16.92	0.200	1.062
3.47	-16.82	0.200	1.062
3.48	-16.72	0.200	1.063
3.49	-16.62	0.200	1.064
3.50	-16.52	0.200	1.063
3.51	-16.42	0.200	1.063
3.52	-16.32	0.200	1.064
3.53	-16.22	0.200	1.064
3.54	-16.12	0.200	1.064
3.55	-16.02	0.200	1.064
3.56	-15.92	0.200	1.064
3.57	-15.82	0.200	1.064
3.58	-15.72	0.200	1.065
3.59	-15.62	0.200	1.065
3.60	-15.52	0.200	1.065
3.61	-15.42	0.200	1.066
3.62	-15.32	0.200	1.066
3.63	-15.22	0.200	1.066
3.64	-15.12	0.200	1.066
3.65	-15.02	0.200	1.067
3.66	-14.92	0.200	1.066
3.67	-14.82	0.200	1.066
3.68	-14.72	0.200	1.067
3.69	-14.62	0.201	1.067
3.70	-14.52	0.200	1.067
3.71	-14.42	0.200	1.067
3.72	-14.32	0.200	1.067
3.73	-14.22	0.201	1.067
3.74	-14.12	0.201	1.067
3.75	-14.02	0.201	1.068
3.76	-13.92	0.201	1.068
3.77	-13.82	0.201	1.067
3.78	-13.72	0.201	1.067
3.79	-13.62	0.201	1.068
3.80	-13.52	0.201	1.069
3.81	-13.42	0.201	1.069
3.82	-13.32	0.201	1.069
3.83	-13.22	0.201	1.069
3.84	-13.12	0.201	1.070
3.85	-13.02	0.201	1.070
3.86	-12.92	0.201	1.070
3.87	-12.82	0.201	1.070
3.88	-12.72	0.201	1.070
3.89	-12.62	0.201	1.071
3.90	-12.52	0.201	1.070
3.91	-12.42	0.201	1.071
3.92	-12.32	0.201	1.071
3.93	-12.22	0.201	1.071
3.94	-12.12	0.201	1.071
3.95	-12.02	0.201	1.072
3.96	-11.92	0.201	1.072
3.97	-11.82	0.201	1.072
3.98	-11.72	0.201	1.072
3.99	-11.62	0.201	1.073
4.00	-11.52	0.201	1.072
4.01	-11.42	0.201	1.073
4.02	-11.32	0.201	1.073
4.03	-11.22	0.201	1.073
4.04	-11.12	0.201	1.073
4.05	-11.02	0.201	1.073
4.06	-10.92	0.201	1.073
4.07	-10.81	0.201	1.072
4.08	-10.72	0.201	1.072
4.09	-10.62	0.201	1.072
4.10	-10.52	0.201	1.073
4.11	-10.42	0.201	1.074
4.12	-10.32	0.201	1.073
4.13	-10.21	0.201	1.074
4.14	-10.12	0.201	1.074
4.15	-10.02	0.201	1.074
4.16	-9.92	0.201	1.074
4.17	-9.82	0.202	1.075
4.18	-9.71	0.202	1.075
4.19	-9.61	0.202	1.075
4.20	-9.51	0.202	1.075
4.21	-9.41	0.202	1.075
4.22	-9.31	0.202	1.075
4.23	-9.21	0.202	1.076
4.24	-9.11	0.202	1.076
4.25	-9.01	0.202	1.077
4.26	-8.91	0.202	1.077
4.27	-8.81	0.202	1.077
4.28	-8.71	0.202	1.078
4.29	-8.61	0.202	1.077
4.30	-8.51	0.202	1.078
4.31	-8.41	0.202	1.079
4.32	-8.31	0.202	1.078
4.33	-8.21	0.202	1.078
4.34	-8.11	0.202	1.079
4.35	-8.01	0.202	1.079
4.36	-7.91	0.202	1.080
4.37	-7.81	0.202	1.080
4.38	-7.71	0.202	1.080
4.39	-7.61	0.202	1.080
4.40	-7.51	0.202	1.080
4.41	-7.41	0.202	1.080
4.42	-7.31	0.202	1.081
4.43	-7.21	0.202	1.081
4.44	-7.11	0.202	1.081
4.45	-7.01	0.203	1.081
4.46	-6.91	0.203	1.081
4.47	-6.81	0.203	1.082
4.48	-6.71	0.203	1.082
4.49	-6.61	0.203	1.083
4.50	-6.51	0.203	1.084
4.51	-6.41	0.203	1.084
4.52	-6.31	0.203	1.083
4.53	-6.21	0.203	1.085
4.54	-6.11	0.203	1.084
4.55	-6.01	0.203	1.085
4.56	-5.91	0.203	1.085
4.57	-5.81	0.203	1.085
4.58	-5.71	0.203	1.086
4.59	-5.61	0.203	1.086
4.60	-5.51	0.203	1.086
4.61	-5.41	0.203	1.087
4.62	-5.31	0.204	1.087
4.63	-5.21	0.204	1.087
4.64	-5.11	0.204	1.087
4.65	-5.01	0.204	1.088
4.66	-4.91	0.204	1.088
4.67	-4.81	0.204	1.089
4.68	-4.71	0.204	1.089
4.69	-4.61	0.204	1.089
4.70	-4.51	0.204	1.090
4.71	-4.41	0.204	1.090
4.72	-4.31	0.204	1.091
4.73	-4.21	0.204	1.091
4.74	-4.11	0.204	1.092
4.75	-4.01	0.204	1.092
4.76	-3.91	0.204	1.092
4.77	-3.81	0.204	1.093
4.78	-3.71	0.204	1.093
4.79	-3.61	0.205	1.093
4.80	-3.51	0.205	1.093
4.81	-3.41	0.205	1.094
4.82	-3.31	0.205	1.093
4.83	-3.20	0.205	1.094
4.84	-3.11	0.205	1.094
4.85	-3.00	0.205	1.094
4.86	-2.91	0.205	1.095
4.87	-2.80	0.205	1.094
4.88	-2.70	0.205	1.095
4.89	-2.61	0.205	1.096
4.90	-2.51	0.205	1.097
4.91	-2.40	0.205	1.097
4.92	-2.30	0.205	1.096
4.93	-2.20	0.205	1.097
4.94	-2.10	0.205	1.097
4.95	-2.00	0.205	1.098
4.96	-1.90	0.205	1.098
4.97	-1.80	0.205	1.097
4.98	-1.70	0.205	1.098
4.99	-1.60	0.205	1.098
5.00	-1.50	0.205	1.098
5.01	-1.40	0.205	1.098
5.02	-1.30	0.206	1.099
5.03	-1.20	0.206	1.100
5.04	-1.10	0.206	1.100
5.05	-1.00	0.206	1.100
5.06	-0.90	0.206	1.101
5.07	-0.80	0.206	1.101
5.08	-0.70	0.206	1.102
5.09	-0.60	0.206	1.102
5.10	-0.50	0.206	1.102
5.11	-0.40	0.206	1.103
5.12	-0.30	0.206	1.104
5.13	-0.20	0.206	1.104
5.14	-0.10	0.207	1.104
5.15	0.00	0.207	1.105
5.16	0.10	0.207	1.104
5.17	0.20	0.207	1.105
5.18	0.30	0.207	1.105
5.19	0.40	0.207	1.105
5.20	0.50	0.207	1.105
5.21	0.60	0.207	1.106
5.22	0.70	0.207	1.106
5.23	0.80	0.207	1.106
5.24	0.90	0.207	1.106
5.25	1.00	0.207	1.106
5.26	1.10	0.207	1.107
5.27	1.20	0.207	1.107
5.28	1.30	0.207	1.107
5.29	1.40	0.207	1.107
5.30	1.50	0.207	1.108
5.31	1.60	0.207	1.109
5.32	1.70	0.207	1.108
5.33	1.80	0.207	1.108
5.34	1.90	0.207	1.108
5.35	2.00	0.207	1.109
5.36	2.10	0.208	1.110
5.37	2.20	0.208	1.110
5.38	2.30	0.208	1.110
5.39	2.40	0.208	1.111
5.40	2.50	0.208	1.111
5.41	2.60	0.208	1.112
5.42	2.70	0.208	1.112
5.43	2.80	0.208	1.112
5.44	2.90	0.208	1.113
5.45	3.00	0.208	1.113
5.46	3.10	0.208	1.113
5.47	3.20	0.208	1.113
5.48	3.30	0.208	1.113
5.49	3.40	0.208	1.114
5.50	3.50	0.208	1.115
5.51	3.60	0.208	1.115
5.52	3.70	0.209	1.115
5.53	3.80	0.209	1.115
5.54	3.90	0.209	1.116
5.55	4.00	0.209	1.116
5.56	4.11	0.209	1.116
5.57	4.21	0.209	1.116
5.58	4.31	0.209	1.117
5.59	4.41	0.209	1.118
5.60	4.51	0.209	1.117
5.61	4.60	0.209	1.117
5.62	4.71	0.209	1.117
5.63	4.81	0.209	1.118
5.64	4.91	0.209	1.118
5.65	5.01	0.209	1.119
5.66	5.11	0.209	1.119
5.67	5.21	0.210	1.120
5.68	5.31	0.209	1.120
5.69	5.40	0.210	1.121
5.70	5.51	0.210	1.121
5.71	5.61	0.210	1.121
5.72	5.71	0.210	1.121
5.73	5.81	0.210	1.122
5.74	5.91	0.210	1.123
5.75	6.01	0.210	1.123
5.76	6.11	0.210	1.123
5.77	6.21	0.210	1.124
5.78	6.31	0.210	1.124
5.79	6.41	0.210	1.124
5.80	6.51	0.210	1.125
5.81	6.61	0.210	1.126
5.82	6.71	0.210	1.125
5.83	6.81	0.211	1.126
5.84	6.91	0.211	1.126
5.85	7.01	0.211	1.126
5.86	7.11	0.211	1.127
5.87	7.21	0.211	1.127
5.88	7.31	0.211	1.128
5.89	7.41	0.211	1.128
5.90	7.51	0.211	1.128
5.91	7.61	0.211	1.129
5.92	7.71	0.211	1.129
5.93	7.81	0.211	1.129
5.94	7.91	0.211	1.130
5.95	8.01	0.211	1.130
5.96	8.11	0.211	1.130
5.97	8.21	0.212	1.131
5.98	8.31	0.212	1.131
5.99	8.41	0.212	1.131
6.00	8.51	0.212	1.132
6.01	8.61	0.212	1.132
6.02	8.71	0.212	1.133
6.03	8.81	0.212	1.133
6.04	8.91	0.212	1.134
6.05	9.01	0.212	1.135
6.06	9.11	0.212	1.135
6.07	9.21	0.212	1.135
6.08	9.31	0.212	1.137
6.09	9.41	0.212	1.135
6.10	9.51	0.212	1.136
6.11	9.61	0.213	1.137
6.12	9.71	0.213	1.137
6.13	9.81	0.213	1.137
6.14	9.91	0.213	1.137
6.15	10.01	0.213	1.138
6.16	10.11	0.213	1.138
6.17	10.21	0.213	1.138
6.18	10.31	0.213	1.139
6.19	10.41	0.213	1.139
6.20	10.51	0.213	1.140
6.21	10.61	0.213	1.141
6.22	10.72	0.213	1.141
6.23	10.82	0.213	1.141
6.24	10.92	0.214	1.142
6.25	11.01	0.214	1.142
6.26	11.12	0.214	1.143
6.27	11.21	0.214	1.143
6.28	11.32	0.214	1.143
6.29	11.41	0.214	1.143
6.30	11.51	0.214	1.144
6.31	11.61	0.214	1.145
6.32	11.72	0.214	1.145
6.33	11.82	0.214	1.145
6.34	11.92	0.214	1.146
6.35	12.02	0.214	1.146
6.36	12.11	0.214	1.146
6.37	12.21	0.214	1.147
6.38	12.32	0.215	1.147
6.39	12.42	0.215	1.147
6.40	12.52	0.215	1.148
6.41	12.62	0.215	1.148
6.42	12.72	0.215	1.148
6.43	12.82	0.215	1.149
6.44	12.92	0.215	1.149
6.45	13.02	0.215	1.150
6.46	13.12	0.215	1.150
6.47	13.22	0.215	1.150
6.48	13.32	0.215	1.150
6.49	13.42	0.215	1.151
6.50	13.52	0.215	1.151
6.51	13.62	0.215	1.151
6.52	13.72	0.215	1.151
6.53	13.82	0.215	1.152
6.54	13.92	0.215	1.152
6.55	14.02	0.216	1.152
6.56	14.12	0.216	1.152
6.57	14.22	0.216	1.152
6.58	14.32	0.216	1.153
6.59	14.42	0.216	1.153
6.60	14.52	0.216	1.153
6.61	14.62	0.216	1.152
6.62	14.72	0.216	1.152
6.63	14.82	0.216	1.153
6.64	14.92	0.216	1.153
6.65	15.02	0.216	1.153
6.66	15.12	0.216	1.153
6.67	15.22	0.216	1.154
6.68	15.32	0.216	1.153
6.69	15.42	0.216	1.154
6.70	15.52	0.216	1.154
6.71	15.62	0.216	1.155
6.72	15.72	0.216	1.155
6.73	15.82	0.216	1.156
6.74	15.92	0.216	1.156
6.75	16.02	0.216	1.157
6.76	16.12	0.216	1.158
6.77	16.22	0.217	1.158
6.78	16.32	0.217	1.158
6.79	16.42	0.217	1.158
6.80	16.52	0.217	1.159
6.81	16.62	0.217	1.160
6.82	16.72	0.217	1.160
6.83	16.82	0.217	1.161
6.84	16.92	0.217	1.161
6.85	17.02	0.217	1.161
6.86	17.12	0.217	1.162
6.87	17.22	0.217	1.162
6.88	17.32	0.218	1.163
6.89	17.42	0.218	1.163
6.90	17.52	0.218	1.164
6.91	17.62	0.218	1.164
6.92	17.72	0.218	1.165
6.93	17.82	0.218	1.165
6.94	17.92	0.218	1.165
6.95	18.02	0.218	1.165
6.96	18.12	0.218	1.165
6.97	18.22	0.218	1.166
6.98	18.32	0.218	1.167
6.99	18.42	0.218	1.167
7.00	18.52	0.218	1.168
7.01	18.62	0.218	1.168
7.02	18.72	0.219	1.168
7.03	18.82	0.219	1.169
7.04	18.92	0.219	1.170
7.05	19.02	0.219	1.170
7.06	19.12	0.219	1.170
7.07	19.22	0.219	1.171
7.08	19.32	0.219	1.171
7.09	19.42	0.219	1.171
7.10	19.52	0.219	1.172
7.11	19.62	0.219	1.173
7.12	19.73	0.220	1.173
7.13	19.82	0.220	1.173
7.14	19.92	0.220	1.174
7.15	20.02	0.220	1.174
7.16	20.12	0.220	1.175
7.17	20.22	0.220	1.176
7.18	20.32	0.220	1.176
7.19	20.42	0.220	1.177
7.20	20.52	0.220	1.176
7.21	20.62	0.220	1.178
7.22	20.73	0.220	1.178
7.23	20.83	0.221	1.179
7.24	20.93	0.221	1.179
7.25	21.03	0.221	1.180
7.26	21.13	0.221	1.181
7.27	21.23	0.221	1.181
7.28	21.33	0.221	1.181
7.29	21.43	0.221	1.181
7.30	21.53	0.221	1.182
7.31	21.63	0.221	1.183
7.32	21.73	0.221	1.184
7.33	21.83	0.222	1.184
7.34	21.93	0.222	1.185
7.35	22.03	0.222	1.185
7.36	22.13	0.222	1.186
7.37	22.23	0.222	1.186
7.38	22.33	0.222	1.187
7.39	22.43	0.222	1.187
7.40	22.53	0.222	1.188
7.41	22.63	0.222	1.189
7.42	22.73	0.223	1.190
7.43	22.83	0.223	1.190
7.44	22.93	0.223	1.191
7.45	23.03	0.223	1.192
7.46	23.13	0.223	1.192
7.47	23.23	0.223	1.192
7.48	23.33	0.223	1.192
7.49	23.43	0.223	1.193
7.50	23.53	0.223	1.194
7.51	23.63	0.223	1.194
7.52	23.73	0.224	1.195
7.53	23.83	0.224	1.195
7.54	23.93	0.224	1.196
7.55	24.03	0.224	1.196
7.56	24.13	0.224	1.197
7.57	24.23	0.224	1.198
7.58	24.33	0.224	1.198
7.59	24.43	0.224	1.198
7.60	24.53	0.224	1.198
7.61	24.63	0.224	1.199
7.62	24.73	0.224	1.200
7.63	24.83	0.224	1.200
7.64	24.93	0.225	1.200
7.65	25.03	0.225	1.200
7.66	25.13	0.225	1.201
7.67	25.23	0.225	1.202
7.68	25.33	0.225	1.202
7.69	25.43	0.225	1.203
7.70	25.53	0.225	1.203
7.71	25.63	0.225	1.203
7.72	25.73	0.225	1.204
7.73	25.83	0.225	1.203
7.74	25.93	0.225	1.203
7.75	26.03	0.225	1.204
7.76	26.13	0.225	1.204
7.77	26.23	0.225	1.205
7.78	26.33	0.226	1.206
7.79	26.43	0.226	1.206
7.80	26.53	0.226	1.206
7.81	26.63	0.226	1.206
7.82	26.73	0.226	1.206
7.83	26.83	0.226	1.207
7.84	26.93	0.226	1.207
7.85	27.03	0.226	1.207
7.86	27.13	0.226	1.208
7.87	27.23	0.226	1.208
7.88	27.33	0.226	1.209
7.89	27.43	0.226	1.209
7.90	27.53	0.226	1.209
7.91	27.63	0.226	1.209
7.92	27.73	0.226	1.209
7.93	27.83	0.226	1.210
7.94	27.93	0.227	1.211
7.95	28.03	0.227	1.211
7.96	28.13	0.227	1.211
7.97	28.23	0.227	1.211
7.98	28.33	0.227	1.212
7.99	28.43	0.227	1.212
8.00	28.53	0.227	1.213
8.01	28.64	0.227	1.214
8.02	28.74	0.227	1.214
8.03	28.83	0.227	1.214
8.04	28.93	0.227	1.214
8.05	29.04	0.227	1.215
8.06	29.14	0.227	1.215
8.07	29.24	0.227	1.215
8.08	29.33	0.227	1.215
8.09	29.44	0.228	1.216
8.10	29.54	0.228	1.216
8.11	29.64	0.228	1.217
8.12	29.74	0.228	1.218
8.13	29.84	0.228	1.218
8.14	29.94	0.228	1.218
8.15	30.04	0.228	1.219
8.16	30.14	0.228	1.219
8.17	30.24	0.228	1.219
8.18	30.34	0.228	1.219
8.19	30.44	0.228	1.220
8.20	30.54	0.228	1.220
8.21	30.64	0.228	1.221
8.22	30.74	0.229	1.222
8.23	30.84	0.229	1.222
8.24	30.94	0.229	1.222
8.25	31.04	0.229	1.222
8.26	31.14	0.229	1.223
8.27	31.24	0.229	1.223
8.28	31.34	0.229	1.224
8.29	31.44	0.229	1.224
8.30	31.54	0.229	1.224
8.31	31.64	0.229	1.224
8.32	31.74	0.229	1.225
8.33	31.84	0.229	1.226
8.34	31.94	0.229	1.226
8.35	32.04	0.230	1.228
8.36	32.14	0.230	1.228
8.37	32.24	0.230	1.228
8.38	32.34	0.230	1.229
8.39	32.44	0.230	1.230
8.40	32.54	0.230	1.230
8.41	32.64	0.230	1.230
8.42	32.74	0.230	1.230
8.43	32.84	0.230	1.231
8.44	32.94	0.230	1.231
8.45	33.04	0.230	1.231
8.46	33.14	0.230	1.232
8.47	33.24	0.230	1.233
8.48	33.34	0.231	1.233
8.49	33.44	0.231	1.233
8.50	33.54	0.231	1.234
8.51	33.64	0.231	1.235
8.52	33.74	0.231	1.235
8.53	33.84	0.231	1.235
8.54	33.94	0.231	1.236
8.55	34.04	0.231	1.236
8.56	34.14	0.231	1.237
8.57	34.24	0.231	1.238
8.58	34.34	0.231	1.237
8.59	34.44	0.232	1.238
8.60	34.54	0.232	1.239
8.61	34.64	0.232	1.240
8.62	34.74	0.232	1.240
8.63	34.84	0.232	1.240
8.64	34.94	0.232	1.241
8.65	35.04	0.232	1.241
8.66	35.14	0.232	1.242
8.67	35.24	0.232	1.242
8.68	35.34	0.232	1.242
8.69	35.44	0.232	1.243
8.70	35.54	0.233	1.243
8.71	35.64	0.233	1.244
8.72	35.74	0.233	1.244
8.73	35.84	0.233	1.244
8.74	35.94	0.233	1.245
8.75	36.04	0.233	1.245
8.76	36.14	0.233	1.246
8.77	36.24	0.233	1.246
8.78	36.34	0.233	1.247
8.79	36.44	0.233	1.247
8.80	36.54	0.233	1.247
8.81	36.64	0.233	1.247
8.82	36.74	0.234	1.248
8.83	36.84	0.234	1.250
8.84	36.94	0.234	1.250
8.85	37.04	0.234	1.249
8.86	37.14	0.234	1.250
8.87	37.24	0.234	1.251
8.88	37.34	0.234	1.251
8.89	37.44	0.234	1.252
8.90	37.54	0.234	1.252
8.91	37.64	0.234	1.252
8.92	37.75	0.234	1.252
8.93	37.84	0.235	1.253
8.94	37.94	0.235	1.253
8.95	38.05	0.235	1.254
8.96	38.15	0.235	1.254
8.97	38.24	0.235	1.254
8.98	38.35	0.235	1.254
8.99	38.45	0.235	1.254
9.00	38.55	0.235	1.255
9.01	38.65	0.235	1.256
9.02	38.75	0.235	1.256
9.03	38.85	0.235	1.257
9.04	38.95	0.235	1.257
9.05	39.05	0.236	1.259
9.06	39.15	0.236	1.259
9.07	39.25	0.236	1.259
9.08	39.35	0.236	1.260
9.09	39.45	0.236	1.260
9.10	39.55	0.236	1.260
9.11	39.65	0.236	1.261
9.12	39.75	0.236	1.261
9.13	39.85	0.236	1.262
9.14	39.95	0.236	1.262
9.15	40.05	0.237	1.263
9.16	40.15	0.237	1.263
9.17	40.25	0.237	1.264
9.18	40.35	0.237	1.264
9.19	40.45	0.237	1.265
9.20	40.55	0.237	1.265
9.21	40.65	0.237	1.266
9.22	40.75	0.237	1.266
9.23	40.85	0.237	1.266
9.24	40.95	0.237	1.266
9.25	41.05	0.237	1.267
9.26	41.15	0.238	1.267
9.27	41.25	0.238	1.267
9.28	41.35	0.238	1.268
9.29	41.45	0.238	1.268
9.30	41.55	0.238	1.268
9.31	41.65	0.238	1.269
9.32	41.75	0.238	1.269
9.33	41.85	0.238	1.270
9.34	41.95	0.238	1.270
9.35	42.05	0.238	1.271
9.36	42.15	0.238	1.272
9.37	42.25	0.239	1.271
9.38	42.35	0.239	1.271
9.39	42.45	0.239	1.272
9.40	42.55	0.239	1.273
9.41	42.65	0.239	1.273
9.42	42.75	0.239	1.273
9.43	42.85	0.239	1.274
9.44	42.95	0.239	1.274
9.45	43.05	0.239	1.275
9.46	43.15	0.239	1.276
9.47	43.25	0.240	1.277
9.48	43.35	0.240	1.277
9.49	43.45	0.240	1.277
9.50	43.55	0.240	1.278
9.51	43.65	0.240	1.278
9.52	43.75	0.240	1.279
9.53	43.85	0.240	1.280
9.54	43.95	0.240	1.280
9.55	44.05	0.240	1.279
9.56	44.15	0.240	1.279
9.57	44.25	0.240	1.280
9.58	44.35	0.240	1.281
9.59	44.45	0.241	1.281
9.60	44.55	0.241	1.281
9.61	44.65	0.241	1.283
9.62	44.75	0.241	1.283
9.63	44.85	0.241	1.283
9.64	44.95	0.241	1.283
9.65	45.05	0.241	1.284
9.66	45.15	0.241	1.284
9.67	45.25	0.241	1.284
9.68	45.35	0.241	1.285
9.69	45.45	0.241	1.286
9.70	45.55	0.241	1.286
9.71	45.65	0.242	1.286
9.72	45.75	0.242	1.288
9.73	45.85	0.242	1.288
9.74	45.95	0.242	1.289
9.75	46.05	0.242	1.289
9.76	46.15	0.242	1.289
9.77	46.25	0.242	1.289
9.78	46.35	0.242	1.290
9.79	46.45	0.242	1.290
9.80	46.55	0.242	1.291
9.81	46.65	0.243	1.291
9.82	46.75	0.243	1.292
9.83	46.85	0.243	1.292
9.84	46.95	0.243	1.293
9.85	47.05	0.243	1.293
9.86	47.15	0.243	1.294
9.87	47.25	0.243	1.295
9.88	47.35	0.243	1.295
9.89	47.46	0.243	1.295
9.90	47.56	0.243	1.295
9.91	47.66	0.243	1.295
9.92	47.76	0.244	1.296
9.93	47.86	0.244	1.296
9.94	47.96	0.244	1.297
9.95	48.06	0.244	1.297
9.96	48.16	0.244	1.298
9.97	48.26	0.244	1.299
9.98	48.36	0.244	1.299
9.99	48.46	0.244	1.299
10.00	48.56	0.244	1.301
10.01	48.66	0.245	1.301
10.02	48.76	0.245	1.302
10.03	48.86	0.245	1.302
10.04	48.96	0.245	1.303
10.05	49.06	0.245	1.304
10.06	49.16	0.245	1.304
10.07	49.26	0.245	1.305
10.08	49.36	0.245	1.305
10.09	49.46	0.245	1.306
10.10	49.56	0.245	1.306
10.11	49.66	0.245	1.307
10.12	49.76	0.246	1.308
10.13	49.86	0.246	1.310
10.14	49.96	0.246	1.310
10.15	50.06	0.246	1.310
10.16	50.16	0.246	1.311
10.17	50.26	0.246	1.311
10.18	50.36	0.246	1.312
10.19	50.46	0.247	1.313
10.20	50.56	0.247	1.313
10.21	50.66	0.247	1.314
10.22	50.76	0.247	1.314
10.23	50.86	0.247	1.315
10.24	50.96	0.247	1.315
10.25	51.06	0.247	1.316
10.26	51.16	0.247	1.317
10.27	51.26	0.247	1.317
10.28	51.36	0.248	1.318
10.29	51.46	0.248	1.319
10.30	51.56	0.248	1.319
10.31	51.66	0.248	1.320
10.32	51.76	0.248	1.321
10.33	51.86	0.248	1.321
10.34	51.96	0.248	1.322
10.35	52.06	0.248	1.323
10.36	52.16	0.249	1.324
10.37	52.26	0.249	1.325
10.38	52.36	0.249	1.327
10.39	52.46	0.249	1.328
10.40	52.56	0.249	1.329
10.41	52.66	0.250	1.329
10.42	52.76	0.250	1.330
10.43	52.86	0.250	1.332
10.44	52.96	0.250	1.333
10.45	53.06	0.250	1.334
10.46	53.16	0.251	1.335
10.47	53.26	0.251	1.336
10.48	53.36	0.251	1.338
10.49	53.46	0.251	1.338
10.50	53.56	0.251	1.340
10.51	53.66	0.252	1.341
10.52	53.76	0.252	1.342
10.53	53.86	0.252	1.344
10.54	53.96	0.252	1.346
10.55	54.06	0.253	1.347
10.56	54.16	0.253	1.349
10.57	54.26	0.253	1.353
10.58	54.36	0.254	1.361
10.59	54.46	0.254	1.372
10.60	54.56	0.254	1.390
10.61	54.66	0.255	1.417
10.62	54.76	0.256	1.458
10.63	54.86	0.259	1.513
10.64	54.96	0.262	1.585
10.65	55.06	0.274	1.721
10.66	55.16	0.308	2.022
10.67	55.26	0.389	2.671
10.68	55.35	0.581	4.182
10.69	55.44	0.894	6.764
10.70	55.52	1.313	10.448
10.71	55.58	1.815	15.155
10.72	55.64	2.368	20.638
10.73	55.69	2.937	26.462
10.74	55.73	3.519	32.380
10.75	55.76	4.100	37.948
10.76	55.79	4.624	42.545
10.77	55.82	5.082	46.272
10.78	55.85	5.490	49.137
10.79	55.87	5.910	51.561
10.80	55.90	6.223	52.470
10.81	55.94	6.372	51.405
10.82	55.98	6.363	48.737
10.83	56.04	6.201	44.869
10.84	56.11	5.845	39.847
10.85	56.21	5.339	34.244
10.86	56.31	4.992	30.116
10.87	56.42	4.795	27.269
10.88	56.54	4.584	24.618
10.89	56.65	4.354	22.136
10.90	56.78	4.111	19.841
10.91	56.90	3.862	17.791
10.92	57.03	3.622	16.033
10.93	57.16	3.380	14.486
10.94	57.29	3.145	13.162
10.95	57.43	2.914	12.009
10.96	57.56	2.665	10.897
10.97	57.70	2.408	9.791
10.98	57.84	2.129	8.631
10.99	57.98	1.832	7.422
11.00	58.12	1.552	6.297
11.01	58.26	1.326	5.402
11.02	58.40	1.168	4.785
11.03	58.54	1.065	4.393
11.04	58.67	0.975	4.053
11.05	58.80	0.906	3.802
11.06	58.93	0.844	3.576
11.07	59.05	0.788	3.376
11.08	59.17	0.737	3.197
11.09	59.29	0.693	3.047
11.10	59.41	0.655	2.925
11.11	59.52	0.621	2.813
11.12	59.64	0.588	2.703
11.13	59.75	0.561	2.618
11.14	59.86	0.535	2.531
11.15	59.97	0.509	2.438
11.16	60.08	0.492	2.379
11.17	60.19	0.474	2.317
11.18	60.30	0.456	2.247
11.19	60.41	0.442	2.194
11.20	60.51	0.428	2.142
11.21	60.62	0.418	2.102
11.22	60.72	0.407	2.061
11.23	60.82	0.398	2.025
11.24	60.93	0.390	1.994
11.25	61.03	0.384	1.972
11.26	61.14	0.371	1.916
11.27	61.24	0.371	1.918
11.28	61.34	0.363	1.886
11.29	61.44	0.360	1.873
11.30	61.54	0.354	1.850
11.31	61.65	0.354	1.849
11.32	61.75	0.351	1.838
11.33	61.85	0.346	1.818
11.34	61.95	0.342	1.800
11.35	62.05	0.340	1.788
11.36	62.15	0.339	1.787
11.37	62.25	0.337	1.781
11.38	62.36	0.335	1.773
11.39	62.46	0.334	1.768
11.40	62.56	0.334	1.767
11.41	62.66	0.333	1.766
11.42	62.76	0.333	1.764
11.43	62.86	0.331	1.756
11.44	62.96	0.330	1.752
11.45	63.06	0.329	1.747
11.46	63.16	0.329	1.745
11.47	63.26	0.328	1.745
11.48	63.36	0.328	1.743
11.49	63.46	0.327	1.739
11.50	63.56	0.326	1.737
11.51	63.66	0.326	1.736
11.52	63.76	0.326	1.735
11.53	63.86	0.326	1.732
11.54	63.96	0.325	1.732
11.55	64.06	0.325	1.732
11.56	64.16	0.325	1.731
11.57	64.26	0.325	1.730
11.58	64.36	0.325	1.729
11.59	64.46	0.324	1.728
11.60	64.56	0.324	1.727
11.61	64.66	0.324	1.726
11.62	64.76	0.324	1.726
11.63	64.86	0.324	1.724
11.64	64.96	0.323	1.723
11.65	65.06	0.323	1.722
11.66	65.16	0.323	1.722
11.67	65.26	0.323	1.722
11.68	65.36	0.323	1.721
11.69	65.46	0.323	1.721
11.70	65.56	0.323	1.720
11.71	65.67	0.322	1.719
11.72	65.76	0.322	1.718
11.73	65.87	0.322	1.718
11.74	65.97	0.322	1.717
11.75	66.07	0.322	1.717
11.76	66.17	0.322	1.716
11.77	66.27	0.322	1.715
11.78	66.37	0.322	1.715
11.79	66.47	0.322	1.714
11.80	66.57	0.322	1.714
11.81	66.67	0.322	1.715
11.82	66.77	0.321	1.713
11.83	66.87	0.321	1.714
11.84	66.97	0.321	1.714
11.85	67.07	0.321	1.714
11.86	67.17	0.321	1.713
11.87	67.27	0.321	1.713
11.88	67.37	0.321	1.713
11.89	67.47	0.321	1.713
11.90	67.57	0.321	1.713
11.91	67.67	0.321	1.713
11.92	67.77	0.321	1.713
[...]
237.08	-40.81	0.199	1.045
237.09	-40.76	0.199	1.046
237.09	-40.71	0.199	1.045
237.10	-40.66	0.199	1.045
237.10	-40.61	0.199	1.046
237.11	-40.56	0.199	1.046
237.11	-40.51	0.199	1.046
237.12	-40.46	0.199	1.045
237.12	-40.41	0.199	1.045
237.13	-40.36	0.199	1.046
237.13	-40.31	0.199	1.046
237.14	-40.26	0.199	1.046
237.14	-40.21	0.199	1.046
237.15	-40.16	0.199	1.047
237.15	-40.11	0.199	1.047
237.16	-40.06	0.199	1.048
237.16	-40.01	0.200	1.048
237.17	-39.96	0.200	1.048
237.17	-39.91	0.200	1.048
237.18	-39.86	0.200	1.048
237.18	-39.81	0.200	1.049
237.19	-39.76	0.200	1.049
237.19	-39.71	0.200	1.049
237.20	-39.66	0.200	1.049
237.20	-39.61	0.200	1.049
237.21	-39.56	0.200	1.049
237.21	-39.51	0.200	1.049
237.22	-39.47	0.200	1.050
237.22	-39.41	0.200	1.050
237.23	-39.36	0.200	1.050
237.23	-39.31	0.200	1.050
237.24	-39.26	0.200	1.050
237.24	-39.22	0.200	1.051
237.25	-39.16	0.200	1.051
237.25	-39.12	0.200	1.051
237.26	-39.07	0.200	1.052
237.26	-39.02	0.200	1.052
237.27	-38.97	0.200	1.052
237.27	-38.92	0.200	1.051
237.28	-38.87	0.200	1.051
237.28	-38.82	0.200	1.051
237.29	-38.77	0.200	1.052
237.29	-38.72	0.200	1.052
237.30	-38.67	0.200	1.052
237.30	-38.62	0.200	1.052
237.31	-38.57	0.200	1.052
237.31	-38.52	0.200	1.052
237.32	-38.47	0.201	1.053
237.32	-38.42	0.201	1.053
237.33	-38.37	0.201	1.053
237.33	-38.32	0.201	1.053
237.34	-38.27	0.201	1.053
237.34	-38.22	0.201	1.054
237.35	-38.17	0.201	1.054
237.35	-38.12	0.201	1.054
237.36	-38.07	0.201	1.054
237.36	-38.02	0.201	1.054
237.37	-37.97	0.201	1.054
237.37	-37.92	0.201	1.054
237.38	-37.87	0.201	1.054
237.38	-37.82	0.201	1.054
237.39	-37.77	0.201	1.055
237.39	-37.72	0.201	1.055
237.40	-37.67	0.201	1.055
237.40	-37.62	0.201	1.056
237.41	-37.57	0.201	1.056
237.41	-37.52	0.201	1.057
237.42	-37.47	0.201	1.056
237.42	-37.42	0.201	1.056
237.43	-37.37	0.201	1.056
237.43	-37.32	0.201	1.056
237.44	-37.27	0.201	1.057
237.44	-37.22	0.201	1.057
237.45	-37.17	0.201	1.057
237.45	-37.12	0.201	1.057
237.46	-37.07	0.201	1.057
237.46	-37.02	0.201	1.057
237.47	-36.97	0.201	1.057
237.47	-36.92	0.201	1.057
237.48	-36.87	0.201	1.058
237.48	-36.82	0.201	1.058
237.49	-36.77	0.201	1.058
237.49	-36.72	0.201	1.058
237.50	-36.67	0.201	1.058
237.50	-36.62	0.201	1.058
237.51	-36.57	0.202	1.058
237.51	-36.52	0.202	1.059
237.52	-36.47	0.202	1.059
237.52	-36.42	0.202	1.058
237.53	-36.37	0.202	1.059
237.53	-36.32	0.202	1.059
237.54	-36.27	0.202	1.060
237.54	-36.22	0.202	1.060
237.55	-36.17	0.202	1.060
237.55	-36.12	0.202	1.060
237.56	-36.07	0.202	1.060
237.56	-36.02	0.202	1.060
237.57	-35.97	0.202	1.061
237.57	-35.92	0.202	1.061
237.58	-35.87	0.202	1.061
237.58	-35.82	0.202	1.061
237.59	-35.77	0.202	1.062
237.59	-35.72	0.202	1.062
237.60	-35.67	0.202	1.062
237.60	-35.62	0.202	1.062
237.61	-35.57	0.202	1.062
237.61	-35.52	0.202	1.062
237.62	-35.47	0.202	1.063
237.62	-35.42	0.202	1.063
237.63	-35.37	0.202	1.063
237.63	-35.32	0.202	1.063
237.64	-35.27	0.202	1.063
237.64	-35.22	0.202	1.063
237.65	-35.17	0.202	1.063
237.65	-35.12	0.202	1.063
237.66	-35.07	0.202	1.063
237.66	-35.02	0.202	1.064
237.67	-34.97	0.202	1.064
237.67	-34.92	0.202	1.064
237.68	-34.87	0.202	1.064
237.68	-34.82	0.202	1.064
237.69	-34.77	0.202	1.064
237.69	-34.72	0.203	1.065
237.70	-34.67	0.203	1.065
237.70	-34.62	0.203	1.065
237.71	-34.57	0.203	1.065
237.71	-34.52	0.203	1.065
237.72	-34.47	0.203	1.066
237.72	-34.42	0.203	1.067
237.73	-34.37	0.203	1.066
237.73	-34.32	0.203	1.065
237.74	-34.27	0.203	1.065
237.74	-34.22	0.203	1.066
237.75	-34.17	0.203	1.066
237.75	-34.12	0.203	1.066
237.76	-34.07	0.203	1.067
237.76	-34.02	0.203	1.067
237.77	-33.97	0.203	1.068
237.77	-33.92	0.203	1.067
237.78	-33.87	0.203	1.067
237.78	-33.82	0.203	1.067
237.79	-33.77	0.203	1.067
237.79	-33.72	0.203	1.067
237.80	-33.67	0.203	1.068
237.80	-33.62	0.203	1.068
237.81	-33.57	0.203	1.069
237.81	-33.52	0.203	1.069
237.82	-33.47	0.203	1.070
237.82	-33.42	0.203	1.070
237.83	-33.37	0.203	1.070
237.83	-33.32	0.203	1.071
237.84	-33.27	0.203	1.070
237.84	-33.22	0.203	1.070
237.85	-33.17	0.203	1.071
237.85	-33.12	0.203	1.070
237.86	-33.07	0.204	1.070
237.86	-33.02	0.204	1.071
237.87	-32.97	0.204	1.071
237.87	-32.92	0.204	1.072
237.88	-32.87	0.204	1.072
237.88	-32.82	0.204	1.072
237.89	-32.77	0.204	1.072
237.89	-32.72	0.204	1.072
237.90	-32.67	0.204	1.072
237.90	-32.62	0.204	1.072
237.91	-32.57	0.204	1.072
237.91	-32.52	0.204	1.072
237.92	-32.47	0.204	1.072
237.92	-32.42	0.204	1.073
237.93	-32.37	0.204	1.074
237.93	-32.32	0.204	1.075
237.94	-32.27	0.204	1.075
237.94	-32.22	0.204	1.076
237.95	-32.17	0.204	1.076
237.95	-32.12	0.204	1.075
237.96	-32.07	0.204	1.075
237.96	-32.02	0.204	1.075
237.97	-31.97	0.204	1.076
237.97	-31.92	0.204	1.076
237.98	-31.87	0.204	1.076
237.98	-31.82	0.204	1.076
237.99	-31.77	0.204	1.077
237.99	-31.72	0.205	1.077
238.00	-31.67	0.205	1.077
238.00	-31.62	0.205	1.077
238.01	-31.57	0.205	1.078
238.01	-31.52	0.205	1.078
238.02	-31.47	0.205	1.078
238.02	-31.42	0.205	1.079
238.03	-31.37	0.205	1.079
238.03	-31.32	0.205	1.079
238.04	-31.27	0.205	1.079
238.04	-31.22	0.205	1.079
238.05	-31.17	0.205	1.079
238.05	-31.12	0.205	1.079
238.06	-31.07	0.205	1.079
238.06	-31.02	0.205	1.079
238.07	-30.97	0.205	1.080
238.07	-30.92	0.205	1.080
238.08	-30.87	0.205	1.080
238.08	-30.82	0.205	1.080
238.09	-30.77	0.205	1.081
238.09	-30.72	0.205	1.081
238.10	-30.67	0.205	1.081
238.10	-30.62	0.205	1.081
238.11	-30.57	0.205	1.081
238.11	-30.52	0.205	1.082
238.12	-30.47	0.205	1.082
238.12	-30.42	0.205	1.082
238.13	-30.37	0.205	1.082
238.13	-30.32	0.205	1.082
238.14	-30.27	0.205	1.082
238.14	-30.22	0.205	1.082
238.15	-30.17	0.205	1.083
238.15	-30.12	0.206	1.083
238.16	-30.07	0.206	1.084
238.16	-30.02	0.205	1.084
238.17	-29.97	0.206	1.084
238.17	-29.92	0.206	1.084
238.18	-29.87	0.206	1.084
238.18	-29.82	0.206	1.084
238.19	-29.77	0.206	1.085
238.19	-29.72	0.206	1.085
238.20	-29.67	0.206	1.086
238.20	-29.62	0.206	1.086
238.21	-29.57	0.206	1.086
238.21	-29.52	0.206	1.087
238.22	-29.47	0.206	1.088
238.22	-29.42	0.206	1.088
238.23	-29.37	0.206	1.088
238.23	-29.32	0.206	1.088
238.24	-29.27	0.206	1.088
238.24	-29.22	0.206	1.088
238.25	-29.16	0.206	1.089
238.25	-29.12	0.206	1.089
238.26	-29.07	0.207	1.090
238.26	-29.02	0.207	1.090
238.27	-28.96	0.207	1.091
238.27	-28.92	0.207	1.091
238.28	-28.86	0.207	1.091
238.28	-28.82	0.207	1.092
238.29	-28.77	0.207	1.092
238.29	-28.72	0.207	1.092
238.30	-28.66	0.207	1.093
238.30	-28.62	0.207	1.093
238.31	-28.56	0.207	1.093
238.31	-28.52	0.207	1.094
238.32	-28.47	0.207	1.094
238.32	-28.42	0.207	1.095
238.33	-28.37	0.207	1.095
238.33	-28.31	0.207	1.095
238.34	-28.27	0.208	1.096
238.34	-28.21	0.208	1.096
238.35	-28.17	0.208	1.097
238.35	-28.11	0.208	1.097
238.36	-28.06	0.208	1.098
238.36	-28.01	0.208	1.098
238.37	-27.97	0.208	1.099
238.37	-27.92	0.208	1.100
238.38	-27.87	0.208	1.100
238.38	-27.82	0.208	1.100
238.39	-27.76	0.208	1.101
238.39	-27.71	0.208	1.101
238.40	-27.67	0.209	1.102
238.40	-27.61	0.209	1.102
238.41	-27.56	0.209	1.103
238.41	-27.51	0.209	1.103
238.42	-27.47	0.209	1.104
238.42	-27.41	0.209	1.104
238.43	-27.36	0.209	1.105
238.43	-27.31	0.209	1.106
238.44	-27.26	0.209	1.106
238.44	-27.21	0.209	1.107
238.45	-27.16	0.210	1.107
238.45	-27.11	0.210	1.108
238.46	-27.06	0.210	1.109
238.46	-27.01	0.210	1.110
238.47	-26.96	0.210	1.111
238.47	-26.92	0.210	1.112
238.48	-26.86	0.211	1.113
238.48	-26.81	0.211	1.114
238.49	-26.77	0.211	1.115
238.49	-26.72	0.211	1.116
238.50	-26.66	0.211	1.117
238.50	-26.61	0.211	1.117
238.51	-26.56	0.211	1.118
238.51	-26.52	0.212	1.119
238.52	-26.46	0.212	1.120
238.52	-26.41	0.212	1.121
238.53	-26.36	0.212	1.124
238.53	-26.31	0.213	1.124
238.54	-26.26	0.213	1.126
238.54	-26.21	0.213	1.127
238.55	-26.16	0.214	1.131
238.55	-26.11	0.214	1.133
238.56	-26.06	0.214	1.134
238.56	-26.01	0.215	1.135
238.57	-25.96	0.215	1.136
238.57	-25.91	0.215	1.137
238.58	-25.86	0.215	1.138
238.58	-25.81	0.215	1.139
238.59	-25.76	0.216	1.142
238.59	-25.71	0.216	1.145
238.60	-25.66	0.216	1.146
238.60	-25.61	0.217	1.147
238.61	-25.56	0.217	1.149
238.61	-25.51	0.217	1.150
238.62	-25.46	0.217	1.152
238.62	-25.41	0.218	1.156
238.63	-25.36	0.219	1.159
238.63	-25.31	0.219	1.160
238.64	-25.26	0.219	1.161
238.64	-25.21	0.220	1.165
238.65	-25.16	0.221	1.171
238.65	-25.11	0.222	1.176
238.66	-25.06	0.223	1.181
238.66	-25.01	0.223	1.184
238.67	-24.96	0.224	1.186
238.67	-24.91	0.224	1.188
238.68	-24.86	0.224	1.190
238.68	-24.81	0.225	1.194
238.69	-24.76	0.225	1.196
238.69	-24.71	0.227	1.203
238.70	-24.66	0.228	1.208
238.70	-24.61	0.228	1.212
238.71	-24.56	0.229	1.215
238.71	-24.51	0.231	1.228
238.72	-24.47	0.234	1.241
238.72	-24.42	0.235	1.250
238.73	-24.37	0.236	1.255
238.73	-24.32	0.237	1.259
238.74	-24.26	0.238	1.263
238.74	-24.21	0.239	1.267
238.75	-24.16	0.240	1.274
238.75	-24.11	0.242	1.288
238.76	-24.07	0.245	1.302
238.76	-24.02	0.247	1.314
238.77	-23.97	0.249	1.325
238.77	-23.92	0.251	1.335
238.78	-23.87	0.253	1.345
238.78	-23.82	0.255	1.357
238.79	-23.77	0.256	1.364
238.79	-23.72	0.260	1.383
238.80	-23.67	0.265	1.409
238.80	-23.62	0.267	1.420
238.81	-23.57	0.267	1.425
238.81	-23.52	0.269	1.431
238.82	-23.47	0.270	1.438
238.82	-23.42	0.273	1.456
238.83	-23.37	0.278	1.479
238.83	-23.32	0.281	1.498
238.84	-23.27	0.282	1.505
238.84	-23.22	0.284	1.512
238.85	-23.17	0.285	1.520
238.85	-23.12	0.287	1.531
238.86	-23.07	0.291	1.552
238.86	-23.02	0.295	1.574
238.87	-22.97	0.298	1.590
238.87	-22.92	0.300	1.602
238.88	-22.87	0.303	1.614
238.88	-22.82	0.305	1.623
238.89	-22.77	0.307	1.634
238.89	-22.72	0.309	1.648
238.90	-22.67	0.312	1.662
238.90	-22.62	0.314	1.675
238.91	-22.57	0.317	1.687
238.91	-22.52	0.319	1.697
238.92	-22.47	0.320	1.703
238.92	-22.43	0.320	1.704
238.93	-22.38	0.321	1.706
238.93	-22.33	0.322	1.713
238.94	-22.28	0.323	1.719
238.94	-22.23	0.324	1.724
238.95	-22.18	0.325	1.725
238.95	-22.13	0.324	1.723
238.96	-22.08	0.325	1.722
238.96	-22.03	0.325	1.722
238.97	-21.98	0.324	1.721
238.97	-21.93	0.324	1.719
238.98	-21.88	0.323	1.713
238.98	-21.83	0.322	1.705
238.99	-21.78	0.321	1.701
238.99	-21.73	0.321	1.698
239.00	-21.68	0.319	1.688
239.00	-21.63	0.316	1.670
239.01	-21.58	0.310	1.637
239.01	-21.53	0.305	1.613
239.02	-21.48	0.300	1.587
239.02	-21.42	0.296	1.565
239.03	-21.38	0.290	1.533
239.03	-21.32	0.288	1.519
239.04	-21.27	0.284	1.498
239.04	-21.22	0.279	1.474
239.05	-21.17	0.274	1.447
239.05	-21.12	0.273	1.441
239.06	-21.07	0.272	1.435
239.06	-21.02	0.271	1.428
239.07	-20.97	0.268	1.415
239.07	-20.92	0.266	1.403
239.08	-20.87	0.264	1.393
239.08	-20.82	0.263	1.388
239.09	-20.77	0.263	1.385
239.09	-20.72	0.262	1.380
239.10	-20.67	0.260	1.370
239.10	-20.62	0.259	1.364
239.11	-20.57	0.257	1.356
239.11	-20.52	0.256	1.351
239.12	-20.47	0.255	1.347
239.12	-20.42	0.255	1.345
239.13	-20.37	0.255	1.345
239.13	-20.32	0.255	1.346
239.14	-20.27	0.255	1.346
239.14	-20.21	0.255	1.345
239.15	-20.17	0.255	1.344
239.15	-20.11	0.254	1.342
239.16	-20.06	0.254	1.339
239.16	-20.01	0.253	1.336
239.17	-19.96	0.253	1.335
239.17	-19.91	0.252	1.334
239.18	-19.86	0.252	1.334
239.18	-19.81	0.252	1.333
239.19	-19.76	0.252	1.332
239.19	-19.71	0.252	1.331
239.20	-19.66	0.252	1.330
239.20	-19.61	0.251	1.330
239.21	-19.56	0.251	1.329
239.21	-19.51	0.251	1.328
239.22	-19.46	0.251	1.327
239.22	-19.41	0.251	1.326
239.23	-19.36	0.251	1.326
239.23	-19.31	0.250	1.326
239.24	-19.26	0.250	1.325
239.24	-19.21	0.250	1.324
239.25	-19.16	0.250	1.324
239.25	-19.11	0.250	1.324
239.26	-19.06	0.250	1.323
239.26	-19.01	0.250	1.323
239.27	-18.96	0.250	1.322
239.27	-18.91	0.250	1.322
239.28	-18.86	0.249	1.322
239.28	-18.81	0.249	1.321
239.29	-18.76	0.249	1.319
239.29	-18.71	0.249	1.319
239.30	-18.66	0.249	1.319
239.30	-18.61	0.249	1.318
239.31	-18.56	0.249	1.318
239.31	-18.51	0.248	1.317
239.32	-18.46	0.248	1.317
239.32	-18.41	0.248	1.316
239.33	-18.36	0.248	1.315
239.33	-18.31	0.248	1.315
239.34	-18.26	0.248	1.314
239.34	-18.21	0.248	1.314
239.35	-18.16	0.248	1.314
239.35	-18.11	0.248	1.313
239.36	-18.06	0.247	1.312
239.36	-18.01	0.247	1.311
239.37	-17.96	0.247	1.311
239.37	-17.91	0.247	1.311
239.38	-17.86	0.247	1.311
239.38	-17.81	0.247	1.311
239.39	-17.76	0.247	1.310
239.39	-17.71	0.247	1.310
239.40	-17.66	0.247	1.310
239.40	-17.61	0.247	1.309
239.41	-17.56	0.247	1.309
239.41	-17.51	0.246	1.309
239.42	-17.46	0.246	1.309
239.42	-17.41	0.246	1.308
239.43	-17.36	0.246	1.307
239.43	-17.31	0.246	1.307
239.44	-17.26	0.246	1.306
239.44	-17.21	0.246	1.306
239.45	-17.16	0.246	1.306
239.45	-17.11	0.246	1.306
239.46	-17.06	0.246	1.305
239.46	-17.01	0.246	1.305
239.47	-16.96	0.246	1.305
239.47	-16.91	0.246	1.304
239.48	-16.86	0.245	1.304
239.48	-16.81	0.245	1.304
239.49	-16.76	0.245	1.303
239.49	-16.71	0.245	1.303
239.50	-16.65	0.245	1.303
239.50	-16.60	0.245	1.303
239.51	-16.56	0.245	1.302
239.51	-16.51	0.245	1.302
239.52	-16.46	0.245	1.301
239.52	-16.41	0.245	1.301
239.53	-16.35	0.245	1.301
239.53	-16.30	0.245	1.301
239.54	-16.25	0.245	1.300
239.54	-16.20	0.245	1.300
239.55	-16.16	0.245	1.299
239.55	-16.11	0.245	1.299
239.56	-16.06	0.244	1.299
239.56	-16.00	0.244	1.299
239.57	-15.95	0.244	1.298
239.57	-15.91	0.244	1.299
239.58	-15.85	0.244	1.299
239.58	-15.81	0.244	1.299
239.59	-15.75	0.244	1.298
239.59	-15.71	0.244	1.298
239.60	-15.65	0.244	1.298
239.60	-15.60	0.244	1.298
239.61	-15.55	0.244	1.297
239.61	-15.50	0.244	1.297
239.62	-15.45	0.244	1.297
239.62	-15.40	0.244	1.297
239.63	-15.35	0.244	1.296
239.63	-15.31	0.244	1.296
239.64	-15.25	0.244	1.296
239.64	-15.20	0.244	1.296
239.65	-15.15	0.244	1.295
239.65	-15.10	0.244	1.295
239.66	-15.05	0.244	1.295
239.66	-15.00	0.244	1.295
239.67	-14.95	0.243	1.295
239.67	-14.90	0.243	1.293
239.68	-14.85	0.243	1.293
239.68	-14.80	0.243	1.293
239.69	-14.75	0.243	1.293
239.69	-14.70	0.243	1.293
239.70	-14.65	0.243	1.293
239.70	-14.60	0.243	1.293
239.71	-14.55	0.243	1.292
239.71	-14.50	0.243	1.292
239.72	-14.45	0.243	1.292
239.72	-14.40	0.243	1.292
239.73	-14.35	0.243	1.292
239.73	-14.30	0.243	1.292
239.74	-14.25	0.243	1.293
239.74	-14.20	0.243	1.293
239.75	-14.15	0.243	1.293
239.75	-14.10	0.243	1.293
239.76	-14.05	0.243	1.293
239.76	-14.00	0.243	1.293
239.77	-13.95	0.243	1.292
239.77	-13.90	0.243	1.292
239.78	-13.85	0.243	1.292
239.78	-13.80	0.243	1.292
239.79	-13.75	0.243	1.292
239.79	-13.70	0.243	1.292
239.80	-13.65	0.243	1.292
239.80	-13.60	0.243	1.292
239.81	-13.55	0.243	1.292
239.81	-13.50	0.243	1.292
239.82	-13.45	0.243	1.291
239.82	-13.40	0.243	1.291
239.83	-13.35	0.243	1.291
239.83	-13.30	0.243	1.291
239.84	-13.25	0.242	1.290
239.84	-13.20	0.242	1.291
239.85	-13.15	0.242	1.291
239.85	-13.10	0.242	1.292
239.86	-13.05	0.243	1.291
239.86	-13.00	0.243	1.291
239.87	-12.95	0.243	1.291
239.87	-12.90	0.242	1.291
239.88	-12.85	0.242	1.291
239.88	-12.80	0.242	1.290
239.89	-12.75	0.242	1.290
239.89	-12.70	0.242	1.290
239.90	-12.65	0.242	1.290
239.90	-12.60	0.242	1.290
239.91	-12.55	0.242	1.290
239.91	-12.50	0.242	1.290
239.92	-12.45	0.242	1.289
239.92	-12.40	0.242	1.289
239.93	-12.35	0.242	1.289
239.93	-12.30	0.242	1.289
239.94	-12.25	0.242	1.289
239.94	-12.20	0.242	1.290
239.95	-12.15	0.242	1.290
239.95	-12.10	0.242	1.289
239.96	-12.05	0.242	1.289
239.96	-12.00	0.242	1.289
239.97	-11.95	0.242	1.289
239.97	-11.90	0.242	1.289
239.98	-11.85	0.242	1.289
239.98	-11.80	0.242	1.288
239.99	-11.75	0.242	1.288
239.99	-11.70	0.242	1.288
240.00	-11.65	0.242	1.288
240.00	-11.60	0.242	1.288
240.01	-11.55	0.242	1.288
240.01	-11.50	0.242	1.288
240.02	-11.45	0.242	1.288
240.02	-11.40	0.242	1.288
240.03	-11.35	0.242	1.288
240.03	-11.30	0.242	1.288
240.04	-11.25	0.242	1.288
240.04	-11.20	0.242	1.288
240.05	-11.15	0.242	1.287
240.05	-11.10	0.242	1.287
240.06	-11.05	0.242	1.287
240.06	-11.00	0.242	1.288
240.07	-10.95	0.242	1.288
240.07	-10.90	0.242	1.288
240.08	-10.85	0.242	1.287
240.08	-10.80	0.242	1.287
240.09	-10.75	0.241	1.287
240.09	-10.70	0.241	1.287
240.10	-10.65	0.241	1.287
240.10	-10.60	0.241	1.287
240.11	-10.55	0.241	1.286
240.11	-10.50	0.241	1.286
240.12	-10.44	0.241	1.286
240.12	-10.40	0.241	1.286
240.13	-10.35	0.241	1.286
240.13	-10.30	0.241	1.285
240.14	-10.24	0.241	1.285
240.14	-10.20	0.241	1.285
240.15	-10.14	0.241	1.285
240.15	-10.10	0.241	1.285
240.16	-10.05	0.241	1.285
240.16	-10.00	0.241	1.285
240.17	-9.95	0.241	1.284
240.17	-9.90	0.241	1.284
240.18	-9.85	0.241	1.284
240.18	-9.80	0.241	1.284
240.19	-9.75	0.241	1.284
240.19	-9.69	0.241	1.283
240.20	-9.64	0.241	1.283
240.20	-9.59	0.241	1.283
240.21	-9.54	0.241	1.283
240.21	-9.49	0.241	1.283
240.22	-9.45	0.241	1.283
240.22	-9.40	0.241	1.283
240.23	-9.34	0.241	1.283
240.23	-9.29	0.240	1.282
240.24	-9.24	0.240	1.282
240.24	-9.19	0.240	1.282
240.25	-9.14	0.240	1.281
240.25	-9.09	0.240	1.281
240.26	-9.04	0.240	1.280
240.26	-8.99	0.240	1.279
240.27	-8.94	0.240	1.279
240.27	-8.89	0.240	1.279
240.28	-8.84	0.240	1.279
240.28	-8.79	0.240	1.279
240.29	-8.74	0.240	1.279
240.29	-8.69	0.240	1.278
240.30	-8.64	0.240	1.278
240.30	-8.59	0.239	1.277
240.31	-8.54	0.239	1.276
240.31	-8.49	0.239	1.276
240.32	-8.44	0.239	1.275
240.32	-8.39	0.239	1.275
240.33	-8.34	0.239	1.275
240.33	-8.29	0.239	1.275
240.34	-8.24	0.239	1.275
240.34	-8.19	0.239	1.275
240.35	-8.14	0.239	1.275
240.35	-8.09	0.239	1.274
240.36	-8.04	0.239	1.273
240.36	-7.99	0.239	1.272
240.37	-7.94	0.238	1.272
240.37	-7.89	0.238	1.271
240.38	-7.84	0.238	1.271
240.38	-7.79	0.238	1.271
240.39	-7.74	0.238	1.271
240.39	-7.69	0.238	1.270
240.40	-7.64	0.238	1.269
240.40	-7.59	0.238	1.269
240.41	-7.54	0.238	1.268
240.41	-7.49	0.238	1.268
240.42	-7.44	0.238	1.267
240.42	-7.39	0.238	1.267
240.43	-7.34	0.237	1.266
240.43	-7.29	0.237	1.266
240.44	-7.24	0.237	1.265
240.44	-7.19	0.237	1.265
240.45	-7.14	0.237	1.265
240.45	-7.09	0.237	1.264
240.46	-7.04	0.237	1.264
240.46	-6.99	0.237	1.263
240.47	-6.94	0.237	1.262
240.47	-6.89	0.236	1.261
240.48	-6.84	0.236	1.261
240.48	-6.79	0.236	1.260
240.49	-6.74	0.236	1.259
240.49	-6.69	0.236	1.258
240.50	-6.64	0.236	1.258
240.50	-6.59	0.236	1.258
240.51	-6.54	0.236	1.257
240.51	-6.49	0.235	1.255
240.52	-6.44	0.235	1.254
240.52	-6.39	0.235	1.253
240.53	-6.34	0.235	1.253
240.53	-6.29	0.235	1.252
240.54	-6.24	0.235	1.252
240.54	-6.19	0.234	1.250
240.55	-6.14	0.234	1.248
240.55	-6.09	0.234	1.248
240.56	-6.04	0.234	1.247
240.56	-5.99	0.234	1.247
240.57	-5.94	0.233	1.246
240.57	-5.89	0.233	1.245
240.58	-5.84	0.233	1.244
240.58	-5.79	0.233	1.243
240.59	-5.74	0.233	1.242
240.59	-5.68	0.233	1.241
240.60	-5.64	0.232	1.239
240.60	-5.59	0.232	1.238
240.61	-5.54	0.232	1.237
240.61	-5.49	0.232	1.235
240.62	-5.44	0.231	1.235
240.62	-5.39	0.231	1.234
240.63	-5.34	0.231	1.233
240.63	-5.29	0.231	1.231
240.64	-5.24	0.231	1.230
240.64	-5.19	0.230	1.230
240.65	-5.14	0.230	1.229
240.65	-5.08	0.230	1.228
240.66	-5.04	0.230	1.226
240.66	-4.98	0.229	1.223
240.67	-4.93	0.229	1.222
240.67	-4.89	0.229	1.221
240.68	-4.83	0.229	1.219
240.68	-4.78	0.228	1.218
240.69	-4.74	0.228	1.217
240.69	-4.68	0.228	1.217
240.70	-4.63	0.228	1.215
240.70	-4.58	0.227	1.214
240.71	-4.53	0.227	1.212
240.71	-4.48	0.226	1.207
240.72	-4.43	0.225	1.202
240.72	-4.38	0.225	1.201
240.73	-4.33	0.225	1.199
240.73	-4.28	0.225	1.198
240.74	-4.23	0.224	1.196
240.74	-4.18	0.224	1.195
240.75	-4.13	0.224	1.193
240.75	-4.08	0.223	1.190
240.76	-4.03	0.222	1.187
240.76	-3.98	0.222	1.185
240.77	-3.93	0.222	1.183
240.77	-3.88	0.221	1.181
240.78	-3.83	0.221	1.179
240.78	-3.78	0.221	1.178
240.79	-3.73	0.221	1.177
240.79	-3.68	0.220	1.175
240.80	-3.63	0.220	1.174
240.80	-3.58	0.220	1.172
240.81	-3.53	0.219	1.170
240.81	-3.48	0.219	1.169
240.82	-3.43	0.219	1.167
240.82	-3.38	0.218	1.164
240.83	-3.33	0.218	1.161
240.83	-3.28	0.217	1.159
240.84	-3.23	0.217	1.156
240.84	-3.18	0.216	1.154
240.85	-3.13	0.216	1.151
240.85	-3.08	0.215	1.146
240.86	-3.03	0.214	1.143
240.86	-2.98	0.214	1.141
240.87	-2.93	0.213	1.138
240.87	-2.88	0.213	1.135
240.88	-2.83	0.213	1.134
240.88	-2.78	0.212
240.89	-2.73	0.212
240.89	-2.68	0.212
240.90	-2.63	0.211
240.90	-2.58	0.210
240.91	-2.53	0.206
240.91	-2.48	0.204
240.92	-2.43	0.204
240.92	-2.38	0.204
240.93	-2.33	0.203
240.93	-2.28	0.202
240.94	-2.23	0.201
240.94	-2.18
240.95	-2.13
240.95	-2.08
240.96	-2.03
240.96	-1.98
240.97	-1.92
240.97	-1.87
240.98	-1.83
240.98	-1.77
240.99	-1.73
240.99
241.00