File: DSC/2023_07_01_OTP_Fragility_SBK.txt
Filename	2023_07_01_OTP_Fragility_SBK
Instrument name	DSC2A-00468 (192.168.1.100)
Operator	SBK
rundate	7/1/2023
Sample name	2023_07_01_OTP_Fragility_SBK
proceduresegments	Data Off ; Equilibrate -50.00 °C; Data On ; Ramp 10.00 °C/min to 80.00 °C; Data Off ; Isothermal 1.0 min; Data On ; Ramp 10.00 °C/min to -50.00 °C; Data Off ; Isothermal 1.0 min; Data On ; Ramp 10.00 °C/min to 0.00 °C; Data Off ; Isothermal 1.0 min; Data On ; Ramp 35.00 °C/min to -50.00 °C; Data Off ; Isothermal 1.0 min; Data On ; Ramp 10.00 °C/min to 0.00 °C; Data Off ; Isothermal 1.0 min; Data On ; Ramp 25.00 °C/min to -50.00 °C; Data Off ; Isothermal 1.0 min; Data On ; Ramp 10.00 °C/min to 0.00 °C; Data Off ; Isothermal 1.0 min; Data On ; Ramp 20.00 °C/min to -50.00 °C; Data Off ; Isothermal 1.0 min; Data On ; Ramp 10.00 °C/min to 0.00 °C; Data Off ; Isothermal 1.0 min; Data On ; Sample Interval  0.2 s/pt; Ramp 5.00 °C/min to -50.00 °C; Data Off ; Isothermal 1.0 min; Data On ; Sample Interval  0.1 s/pt; Ramp 10.00 °C/min to 0.00 °C; Data Off ; Isothermal 1.0 min; Data On ; Sample Interval  1.0 s/pt; Ramp 1.00 °C/min to -50.00 °C; Data Off ; Isothermal 1.0 min; Data On ; Sample Interval  0.1 s/pt; Ramp 10.00 °C/min to 0.00 °C; Data Off ; Isothermal 1.0 min; Data On ; Sample Interval  2.0 s/pt; Ramp 0.50 °C/min to -50.00 °C; Data Off ; Isothermal 1.0 min; Data On ; Sample Interval  0.1 s/pt; Ramp 10.00 °C/min to 0.00 °C
[File Parameters]
Run date	7/1/2023 11:15:13 AM
Trios version	5.1.1.46572
Original File Name	C:\Users\yargerlab\Desktop\DSC Data\General\2023_07_01_OTP_Fragility_SBK.tri
Current File Name	C:\Users\kauff\Documents\ASU\data_DSC\2023_07_01_OTP_Fragility_SBK.tri
[Procedure]
Procedure Name	DSC -50C to 80C Varied cooling rates OTP fragility
Sample Name	2023_07_01_OTP_Fragility_SBK
Sample Mass	7.86 mg
Reference Sample Mass	0 mg
Pan Mass	54.32 mg
Pan Number	54
Reference Pan Mass	53.72 mg
Reference Pan Number	37
Pan Type	Aluminum Hermetic
Comments	o-Terphenyl powder, newly prepared sample. DSC84010 aluminum pan and DSC84011 aluminum hermetic lid.
Project Name	Silk ASDs
Operator	SBK
Test	Custom
Unload Max Temperature	30
Unload Min Temperature	30
Load Max Temperature	30
Load Min Temperature	30
Stop on Gas Flow Error	Yes
[Signal List]
Signal #1	Time (min)
Signal #2	Temperature (°C)
Signal #3	Heat Flow (mW)
Signal #4	Delta T (µV)
Signal #5	Delta Tzero (µV)
Signal #6	Tzero Temperature (°C)
Signal #7	Cell Purge (mL/min)
Signal #8	Heater Temp (°C)
Signal #9	Power Delivered (W)
Signal #10	Reference Junction Temperature (°C)
Signal #11	Flange Temperature (°C)
Signal #12	Heat Flow Phase (rad)
Signal #13	Total Heat Capacity (J/°C)
Signal #14	Heat Capacity (J/°C)
[Configuration]
Company Name	ASU
Instrument Name	DSC2A-00468
Instrument Type	DSC2500
Serial Number	DSC2A-00468
IP	192.168.1.100
Location of Instrument	MRRC
DisplayType	Unknown
Sample Interval 	0.1 s/pt
Selected Heat Flow	T4P
Exotherm Direction	Down
Cell Serial	DRC2-00792
Lid Type	Standard
Cooler	RCS 90
Leave Cooler on at End of Sequence	On
Gas 2	Nitrogen
Gas Selected	Channel 1
Flow Rate	50 mL/min
Secondary Purge	On
Licensed Heat Flow	Heat Flow T4P
Modulation Licensed	Yes
[Versions]
Common IDD Version	1
Cortex Version	VER 2.10.2.31
Driver	5.0.0.6
GDM Version	1.0.3.3
TouchscreenVersion	1.0.0.16145
FEP Version	1.2.1.21
FEP Bootloader	2.0.0.5
AutoSampler Version	2.1.1.26
Auto Sampler Bootloader	2.0.0.5
FCM Version	1.1.0.3
FCM Bootloader	2.0.0.5
[Experiment Logs]
Experiment Log Entry # 1	Air Cool is off.
Experiment Log Entry # 3	Data On set to 0
Experiment Log Entry # 5	Equilibrate Segment -50 (C) Started
Experiment Log Entry # 7	Data On set to 1
Experiment Log Entry # 9	Ramp Segment 10 C/min to 80 Started
Experiment Log Entry # 11	Data On set to 0
Experiment Log Entry # 13	Isothermal Segment 1 min started
Experiment Log Entry # 15	Data On set to 1
Experiment Log Entry # 17	Ramp Segment 10 C/min to -50 Started
Experiment Log Entry # 19	Data On set to 0
Experiment Log Entry # 21	Isothermal Segment 1 min started
Experiment Log Entry # 23	Data On set to 1
Experiment Log Entry # 25	Ramp Segment 10 C/min to 0 Started
Experiment Log Entry # 27	Data On set to 0
Experiment Log Entry # 29	Isothermal Segment 1 min started
Experiment Log Entry # 31	Data On set to 1
Experiment Log Entry # 33	Ramp Segment 35 C/min to -50 Started
Experiment Log Entry # 35	Data On set to 0
Experiment Log Entry # 37	Isothermal Segment 1 min started
Experiment Log Entry # 39	Data On set to 1
Experiment Log Entry # 41	Ramp Segment 10 C/min to 0 Started
Experiment Log Entry # 43	Data On set to 0
Experiment Log Entry # 45	Isothermal Segment 1 min started
Experiment Log Entry # 47	Data On set to 1
Experiment Log Entry # 49	Ramp Segment 25 C/min to -50 Started
Experiment Log Entry # 51	Data On set to 0
Experiment Log Entry # 53	Isothermal Segment 1 min started
Experiment Log Entry # 55	Data On set to 1
Experiment Log Entry # 57	Ramp Segment 10 C/min to 0 Started
Experiment Log Entry # 59	Data On set to 0
Experiment Log Entry # 61	Isothermal Segment 1 min started
Experiment Log Entry # 63	Data On set to 1
Experiment Log Entry # 65	Ramp Segment 20 C/min to -50 Started
Experiment Log Entry # 67	Data On set to 0
Experiment Log Entry # 69	Isothermal Segment 1 min started
Experiment Log Entry # 71	Data On set to 1
Experiment Log Entry # 73	Ramp Segment 10 C/min to 0 Started
Experiment Log Entry # 75	Data On set to 0
Experiment Log Entry # 77	Isothermal Segment 1 min started
Experiment Log Entry # 79	Data On set to 1
Experiment Log Entry # 81	Sampling Rate set to 0.2 sec/pt
Experiment Log Entry # 83	Ramp Segment 5 C/min to -50 Started
Experiment Log Entry # 85	Data On set to 0
Experiment Log Entry # 87	Isothermal Segment 1 min started
Experiment Log Entry # 89	Data On set to 1
Experiment Log Entry # 91	Sampling Rate set to 0.1 sec/pt
Experiment Log Entry # 93	Ramp Segment 10 C/min to 0 Started
Experiment Log Entry # 95	Data On set to 0
Experiment Log Entry # 97	Isothermal Segment 1 min started
Experiment Log Entry # 99	Data On set to 1
Experiment Log Entry # 101	Sampling Rate set to 1 sec/pt
Experiment Log Entry # 103	Ramp Segment 1 C/min to -50 Started
Experiment Log Entry # 105	Data On set to 0
Experiment Log Entry # 107	Isothermal Segment 1 min started
Experiment Log Entry # 109	Data On set to 1
Experiment Log Entry # 111	Sampling Rate set to 0.1 sec/pt
Experiment Log Entry # 113	Ramp Segment 10 C/min to 0 Started
Experiment Log Entry # 115	Data On set to 0
Experiment Log Entry # 117	Isothermal Segment 1 min started
Experiment Log Entry # 119	Data On set to 1
Experiment Log Entry # 121	Sampling Rate set to 2 sec/pt
Experiment Log Entry # 123	Ramp Segment 0.5 C/min to -50 Started
Experiment Log Entry # 125	Data On set to 0
Experiment Log Entry # 127	Isothermal Segment 1 min started
Experiment Log Entry # 129	Data On set to 1
Experiment Log Entry # 131	Sampling Rate set to 0.1 sec/pt
Experiment Log Entry # 133	Ramp Segment 10 C/min to 0 Started
[Method Log]
Method Log Entry # 1	Data Off
Method Log Entry # 2	Equilibrate -50 °C
Method Log Entry # 3	Data On
Method Log Entry # 4	(Ramp 205988) Ramp 10 °C/minute to 80 °C
Method Log Entry # 5	Data Off
Method Log Entry # 6	Isothermal 1 minutes
Method Log Entry # 7	Data On
Method Log Entry # 8	(Ramp 205992) Ramp 10 °C/minute to -50 °C
Method Log Entry # 9	Data Off
Method Log Entry # 10	Isothermal 1 minutes
Method Log Entry # 11	Data On
Method Log Entry # 12	(Ramp 205996) Ramp 10 °C/minute to 0 °C
Method Log Entry # 13	Data Off
Method Log Entry # 14	Isothermal 1 minutes
Method Log Entry # 15	Data On
Method Log Entry # 16	(Ramp 206000) Ramp 35 °C/minute to -50 °C
Method Log Entry # 17	Data Off
Method Log Entry # 18	Isothermal 1 minutes
Method Log Entry # 19	Data On
Method Log Entry # 20	(Ramp 206004) Ramp 10 °C/minute to 0 °C
Method Log Entry # 21	Data Off
Method Log Entry # 22	Isothermal 1 minutes
Method Log Entry # 23	Data On
Method Log Entry # 24	(Ramp 206008) Ramp 25 °C/minute to -50 °C
Method Log Entry # 25	Data Off
Method Log Entry # 26	Isothermal 1 minutes
Method Log Entry # 27	Data On
Method Log Entry # 28	(Ramp 206012) Ramp 10 °C/minute to 0 °C
Method Log Entry # 29	Data Off
Method Log Entry # 30	Isothermal 1 minutes
Method Log Entry # 31	Data On
Method Log Entry # 32	(Ramp 206016) Ramp 20 °C/minute to -50 °C
Method Log Entry # 33	Data Off
Method Log Entry # 34	Isothermal 1 minutes
Method Log Entry # 35	Data On
Method Log Entry # 36	(Ramp 206020) Ramp 10 °C/minute to 0 °C
Method Log Entry # 37	Data Off
Method Log Entry # 38	Isothermal 1 minutes
Method Log Entry # 39	Data On
Method Log Entry # 40	Sampling Interval 0.2 Seconds/point
Method Log Entry # 41	(Ramp 206025) Ramp 5 °C/minute to -50 °C
Method Log Entry # 42	Data Off
Method Log Entry # 43	Isothermal 1 minutes
Method Log Entry # 44	Data On
Method Log Entry # 45	Sampling Interval 0.1 Seconds/point
Method Log Entry # 46	(Ramp 206030) Ramp 10 °C/minute to 0 °C
Method Log Entry # 47	Data Off
Method Log Entry # 48	Isothermal 1 minutes
Method Log Entry # 49	Data On
Method Log Entry # 50	Sampling Interval 1 Seconds/point
Method Log Entry # 51	(Ramp 206035) Ramp 1 °C/minute to -50 °C
Method Log Entry # 52	Data Off
Method Log Entry # 53	Isothermal 1 minutes
Method Log Entry # 54	Data On
Method Log Entry # 55	Sampling Interval 0.1 Seconds/point
Method Log Entry # 56	(Ramp 206040) Ramp 10 °C/minute to 0 °C
Method Log Entry # 57	Data Off
Method Log Entry # 58	Isothermal 1 minutes
Method Log Entry # 59	Data On
Method Log Entry # 60	Sampling Interval 2 Seconds/point
Method Log Entry # 61	(Ramp 206045) Ramp 0.5 °C/minute to -50 °C
Method Log Entry # 62	Data Off
Method Log Entry # 63	Isothermal 1 minutes
Method Log Entry # 64	Data On
Method Log Entry # 65	Sampling Interval 0.1 Seconds/point
Method Log Entry # 66	(Ramp 206050) Ramp 10 °C/minute to 0 °C
Cell Serial	DRC2-00792
[T1 Calibration]
Slope	-0.008529666
Offset	9.636258
Initial Temperature	98.23
GUID	f8bfdadc-4977-4fdf-ba6d-0ba9134940c3
[TZero Calibration]
Date Applied	11/29/2022 4:06:13 PM
Description	From -89.059 °C to 396.009 °C at 20.000°C/min
Gas Type	Nitrogen
Pan Type	None
Source Files 1	C:\Users\yargerlab\Desktop\DSC Data\General\TZero_calibration_11_29_22_2nd(2).tri
Source Files 2	C:\Users\yargerlab\Desktop\DSC Data\General\TZero_calibration_11_29_22_2nd(3).tri
Delta T Offset	13.05235
Delta T Slope	-0.007271007
Delta T0 Offset	-13.69128
Delta T0 Slope	0.06063341
[Temperature Calibration]
Date Applied	11/29/2022 7:12:28 PM
Description	From 106.590 °C to 186.590 °C at 10.000°C/min
Gas Type	Nitrogen
Pan Type	Tzero Aluminum Hermetic
Source Files 1	C:\Users\yargerlab\Desktop\DSC Data\General\Indium(6).tri
Measured 1	157.391
Known 1	156.598
[Cell Constant Calibration]
Date Applied	11/29/2022 7:12:29 PM
Description	From 106.590 °C to 186.590 °C at 10.000°C/min
Gas Type	Nitrogen
Pan Type	Tzero Aluminum Hermetic
Source Files 1	C:\Users\yargerlab\Desktop\DSC Data\General\Indium(6).tri
T4P KCell	1.006051
Onset Slope	63.26126 mW/°C
[Direct Cp Calibration]
Date Applied	11/30/2022 11:04:51 AM
Description	From -79.983 °C to 298.409 °C at 10.000°C/min
Gas Type	Nitrogen
Pan Type	Tzero Aluminum Hermetic
Source Files 1	C:\Users\yargerlab\Desktop\DSC Data\General\Sapphire_Heat_Capacity_11_30_22.tri
[Rev Cp Calibration]
Date Applied	11/30/2022 1:58:51 PM
Description	From -79.996 °C to 292.812 °C at 3.000°C/min
Gas Type	Nitrogen
Pan Type	Tzero Aluminum Hermetic
Source Files 1	C:\Users\yargerlab\Desktop\DSC Data\General\Sapphire_MDSC_Calibration_11_30_22.tri
[step]
Ramp 10.00 °C/min to 80.00 °C
Time	Temperature	Heat Flow (Normalized)	Heat Capacity (Normalized)
min	°C	W/g	J/(g.°C)
0.00	-49.72	-0.042	0.000
0.01	-49.72	-0.042	22.186
0.02	-49.73	-0.041	0.000
0.03	-49.73	-0.038	0.000
0.04	-49.74	-0.035	0.000
0.05	-49.74	-0.033	0.000
0.06	-49.73	-0.031	0.000
0.07	-49.73	-0.029	-0.841
0.08	-49.71	-0.028	-0.657
0.09	-49.69	-0.027	-0.535
0.10	-49.67	-0.025	-0.440
0.11	-49.64	-0.023	-0.359
0.12	-49.60	-0.022	-0.297
0.13	-49.55	-0.019	-0.237
0.14	-49.50	-0.015	-0.173
0.15	-49.45	-0.011	-0.114
0.16	-49.39	-0.006	-0.059
0.17	-49.33	-0.001	-0.005
0.18	-49.26	0.006	0.051
0.19	-49.19	0.012	0.096
0.20	-49.12	0.019	0.146
0.21	-49.05	0.025	0.187
0.22	-48.97	0.032	0.232
0.23	-48.89	0.039	0.273
0.24	-48.82	0.045	0.308
0.25	-48.74	0.051	0.339
0.26	-48.65	0.057	0.372
0.27	-48.57	0.063	0.404
0.28	-48.49	0.069	0.435
0.29	-48.40	0.075	0.462
0.30	-48.32	0.077	0.475
0.31	-48.23	0.084	0.506
0.32	-48.15	0.088	0.528
0.33	-48.06	0.092	0.546
0.34	-47.97	0.095	0.562
0.35	-47.88	0.099	0.578
0.36	-47.79	0.102	0.591
0.37	-47.70	0.106	0.611
0.38	-47.61	0.108	0.619
0.39	-47.52	0.112	0.637
0.40	-47.42	0.114	0.644
0.41	-47.33	0.116	0.657
0.42	-47.24	0.119	0.667
0.43	-47.15	0.122	0.681
0.44	-47.05	0.122	0.678
0.45	-46.96	0.125	0.693
0.46	-46.87	0.127	0.700
0.47	-46.77	0.128	0.705
0.48	-46.68	0.130	0.712
0.49	-46.58	0.131	0.719
0.50	-46.48	0.132	0.723
0.51	-46.39	0.134	0.728
0.52	-46.30	0.135	0.733
0.53	-46.20	0.136	0.739
0.54	-46.10	0.137	0.742
0.55	-46.01	0.138	0.746
0.56	-45.91	0.138	0.748
0.57	-45.81	0.139	0.751
0.58	-45.72	0.140	0.753
0.59	-45.62	0.140	0.756
0.60	-45.52	0.141	0.760
0.61	-45.43	0.143	0.767
0.62	-45.33	0.143	0.765
0.63	-45.23	0.143	0.767
0.64	-45.13	0.144	0.770
0.65	-45.04	0.144	0.771
0.66	-44.94	0.145	0.772
0.67	-44.84	0.145	0.773
0.68	-44.74	0.145	0.774
0.69	-44.65	0.145	0.775
0.70	-44.55	0.146	0.775
0.71	-44.45	0.146	0.776
0.72	-44.35	0.146	0.777
0.73	-44.26	0.146	0.778
0.74	-44.16	0.147	0.779
0.75	-44.06	0.147	0.780
0.76	-43.96	0.147	0.781
0.77	-43.86	0.147	0.782
0.78	-43.76	0.148	0.784
0.79	-43.66	0.148	0.784
0.80	-43.57	0.148	0.784
0.81	-43.47	0.148	0.785
0.82	-43.37	0.148	0.785
0.83	-43.27	0.149	0.786
0.84	-43.17	0.149	0.786
0.85	-43.07	0.149	0.787
0.86	-42.97	0.149	0.787
0.87	-42.88	0.149	0.788
0.88	-42.78	0.149	0.788
0.89	-42.68	0.149	0.788
0.90	-42.58	0.149	0.789
0.91	-42.48	0.150	0.790
0.92	-42.38	0.150	0.790
0.93	-42.28	0.150	0.791
0.94	-42.18	0.150	0.791
0.95	-42.08	0.150	0.792
0.96	-41.99	0.150	0.792
0.97	-41.89	0.150	0.793
0.98	-41.79	0.151	0.793
0.99	-41.69	0.151	0.794
1.00	-41.59	0.151	0.794
1.01	-41.49	0.151	0.795
1.02	-41.39	0.151	0.796
1.03	-41.29	0.151	0.796
1.04	-41.19	0.151	0.796
1.05	-41.09	0.151	0.796
1.06	-40.99	0.151	0.797
1.07	-40.89	0.152	0.798
1.08	-40.79	0.152	0.798
1.09	-40.70	0.152	0.799
1.10	-40.60	0.152	0.799
1.11	-40.50	0.152	0.800
1.12	-40.40	0.152	0.800
1.13	-40.30	0.152	0.801
1.14	-40.20	0.152	0.801
1.15	-40.10	0.152	0.802
1.16	-40.00	0.153	0.802
1.17	-39.90	0.153	0.803
1.18	-39.80	0.153	0.803
1.19	-39.70	0.153	0.803
1.20	-39.60	0.153	0.803
1.21	-39.50	0.153	0.804
1.22	-39.40	0.153	0.805
1.23	-39.30	0.153	0.805
1.24	-39.20	0.153	0.805
1.25	-39.10	0.153	0.806
1.26	-39.00	0.153	0.806
1.27	-38.90	0.154	0.807
1.28	-38.80	0.154	0.808
1.29	-38.70	0.154	0.808
1.30	-38.60	0.154	0.808
1.31	-38.50	0.154	0.808
1.32	-38.41	0.154	0.808
1.33	-38.31	0.154	0.809
1.34	-38.20	0.154	0.809
1.35	-38.11	0.154	0.809
1.36	-38.01	0.154	0.810
1.37	-37.91	0.154	0.810
1.38	-37.81	0.154	0.811
1.39	-37.71	0.154	0.811
1.40	-37.61	0.154	0.811
1.41	-37.51	0.154	0.812
1.42	-37.41	0.154	0.812
1.43	-37.31	0.155	0.812
1.44	-37.21	0.155	0.813
1.45	-37.11	0.155	0.813
1.46	-37.01	0.155	0.814
1.47	-36.91	0.155	0.814
1.48	-36.81	0.155	0.814
1.49	-36.71	0.155	0.814
1.50	-36.61	0.155	0.814
1.51	-36.51	0.155	0.815
1.52	-36.41	0.155	0.815
1.53	-36.31	0.155	0.816
1.54	-36.21	0.155	0.816
1.55	-36.11	0.155	0.816
1.56	-36.01	0.155	0.816
1.57	-35.91	0.155	0.816
1.58	-35.81	0.155	0.817
1.59	-35.71	0.155	0.817
1.60	-35.61	0.155	0.817
1.61	-35.51	0.156	0.818
1.62	-35.41	0.156	0.818
1.63	-35.31	0.156	0.819
1.64	-35.21	0.156	0.819
1.65	-35.11	0.156	0.819
1.66	-35.01	0.156	0.819
1.67	-34.91	0.156	0.820
1.68	-34.81	0.156	0.820
1.69	-34.71	0.156	0.820
1.70	-34.61	0.156	0.820
1.71	-34.51	0.156	0.821
1.72	-34.41	0.156	0.821
1.73	-34.31	0.156	0.821
1.74	-34.21	0.156	0.821
1.75	-34.11	0.156	0.822
1.76	-34.01	0.156	0.822
1.77	-33.91	0.156	0.823
1.78	-33.81	0.156	0.822
1.79	-33.71	0.156	0.823
1.80	-33.61	0.156	0.823
1.81	-33.51	0.156	0.823
1.82	-33.41	0.157	0.824
1.83	-33.31	0.157	0.824
1.84	-33.21	0.157	0.825
1.85	-33.11	0.157	0.825
1.86	-33.01	0.157	0.825
1.87	-32.91	0.157	0.825
1.88	-32.81	0.157	0.826
1.89	-32.71	0.157	0.826
1.90	-32.61	0.157	0.826
1.91	-32.51	0.157	0.826
1.92	-32.41	0.157	0.827
1.93	-32.31	0.157	0.827
1.94	-32.21	0.157	0.827
1.95	-32.11	0.157	0.828
1.96	-32.01	0.157	0.828
1.97	-31.91	0.157	0.828
1.98	-31.81	0.157	0.829
1.99	-31.71	0.157	0.829
2.00	-31.61	0.157	0.829
2.01	-31.51	0.157	0.830
2.02	-31.41	0.158	0.830
2.03	-31.31	0.158	0.830
2.04	-31.21	0.158	0.830
2.05	-31.11	0.158	0.831
2.06	-31.01	0.158	0.831
2.07	-30.91	0.158	0.831
2.08	-30.81	0.158	0.832
2.09	-30.71	0.158	0.832
2.10	-30.61	0.158	0.832
2.11	-30.51	0.158	0.832
2.12	-30.41	0.158	0.833
2.13	-30.31	0.158	0.833
2.14	-30.21	0.158	0.833
2.15	-30.11	0.158	0.833
2.16	-30.01	0.158	0.834
2.17	-29.91	0.158	0.834
2.18	-29.81	0.158	0.834
2.19	-29.71	0.158	0.835
2.20	-29.61	0.158	0.835
2.21	-29.51	0.158	0.835
2.22	-29.41	0.158	0.835
2.23	-29.31	0.158	0.836
2.24	-29.21	0.158	0.836
2.25	-29.11	0.158	0.836
2.26	-29.01	0.159	0.836
2.27	-28.91	0.159	0.836
2.28	-28.81	0.159	0.837
2.29	-28.71	0.159	0.837
2.30	-28.61	0.159	0.838
2.31	-28.51	0.159	0.838
2.32	-28.41	0.159	0.838
2.33	-28.31	0.159	0.838
2.34	-28.21	0.159	0.838
2.35	-28.11	0.159	0.839
2.36	-28.01	0.159	0.839
2.37	-27.91	0.159	0.839
2.38	-27.81	0.159	0.839
2.39	-27.71	0.159	0.840
2.40	-27.61	0.159	0.840
2.41	-27.51	0.159	0.840
2.42	-27.41	0.159	0.841
2.43	-27.31	0.159	0.841
2.44	-27.21	0.159	0.841
2.45	-27.11	0.159	0.841
2.46	-27.01	0.159	0.842
2.47	-26.91	0.159	0.842
2.48	-26.81	0.159	0.842
2.49	-26.71	0.159	0.843
2.50	-26.61	0.160	0.843
2.51	-26.51	0.160	0.843
2.52	-26.41	0.160	0.844
2.53	-26.31	0.160	0.844
2.54	-26.21	0.160	0.844
2.55	-26.10	0.160	0.845
2.56	-26.00	0.160	0.845
2.57	-25.90	0.160	0.845
2.58	-25.80	0.160	0.845
2.59	-25.70	0.160	0.846
2.60	-25.60	0.160	0.846
2.61	-25.50	0.160	0.846
2.62	-25.40	0.160	0.847
2.63	-25.30	0.160	0.847
2.64	-25.20	0.160	0.847
2.65	-25.10	0.160	0.848
2.66	-25.00	0.160	0.847
2.67	-24.90	0.160	0.848
2.68	-24.80	0.160	0.848
2.69	-24.70	0.160	0.848
2.70	-24.60	0.160	0.849
2.71	-24.50	0.160	0.849
2.72	-24.40	0.160	0.849
2.73	-24.30	0.161	0.850
2.74	-24.20	0.161	0.850
2.75	-24.10	0.161	0.850
2.76	-24.00	0.161	0.850
2.77	-23.90	0.161	0.851
2.78	-23.80	0.161	0.851
2.79	-23.70	0.161	0.851
2.80	-23.60	0.161	0.851
2.81	-23.50	0.161	0.852
2.82	-23.40	0.161	0.852
2.83	-23.30	0.161	0.852
2.84	-23.20	0.161	0.853
2.85	-23.10	0.161	0.853
2.86	-23.00	0.161	0.854
2.87	-22.90	0.161	0.854
2.88	-22.80	0.161	0.854
2.89	-22.70	0.161	0.854
2.90	-22.60	0.161	0.855
2.91	-22.50	0.161	0.855
2.92	-22.40	0.161	0.855
2.93	-22.30	0.161	0.856
2.94	-22.20	0.162	0.856
2.95	-22.10	0.162	0.856
2.96	-22.00	0.162	0.856
2.97	-21.90	0.162	0.857
2.98	-21.80	0.162	0.857
2.99	-21.70	0.162	0.858
3.00	-21.60	0.162	0.858
3.01	-21.50	0.162	0.858
3.02	-21.40	0.162	0.859
3.03	-21.30	0.162	0.859
3.04	-21.20	0.162	0.859
3.05	-21.10	0.162	0.860
3.06	-21.00	0.162	0.859
3.07	-20.90	0.162	0.860
3.08	-20.80	0.162	0.860
3.09	-20.70	0.162	0.861
3.10	-20.60	0.162	0.861
3.11	-20.50	0.162	0.861
3.12	-20.40	0.162	0.862
3.13	-20.30	0.162	0.862
3.14	-20.20	0.162	0.862
3.15	-20.10	0.163	0.863
3.16	-20.00	0.163	0.862
3.17	-19.90	0.163	0.863
3.18	-19.80	0.163	0.863
3.19	-19.70	0.163	0.863
3.20	-19.60	0.163	0.863
3.21	-19.50	0.163	0.864
3.22	-19.40	0.163	0.864
3.23	-19.30	0.163	0.865
3.24	-19.20	0.163	0.865
3.25	-19.10	0.163	0.865
3.26	-19.00	0.163	0.866
3.27	-18.90	0.163	0.866
3.28	-18.80	0.163	0.866
3.29	-18.70	0.163	0.866
3.30	-18.60	0.163	0.866
3.31	-18.50	0.163	0.867
3.32	-18.40	0.163	0.868
3.33	-18.30	0.163	0.867
3.34	-18.20	0.163	0.868
3.35	-18.10	0.163	0.868
3.36	-18.00	0.164	0.869
3.37	-17.90	0.164	0.869
3.38	-17.80	0.164	0.869
3.39	-17.70	0.164	0.869
3.40	-17.60	0.164	0.870
3.41	-17.50	0.164	0.870
3.42	-17.40	0.164	0.870
3.43	-17.29	0.164	0.870
3.44	-17.19	0.164	0.871
3.45	-17.09	0.164	0.871
3.46	-16.99	0.164	0.871
3.47	-16.90	0.164	0.872
3.48	-16.79	0.164	0.872
3.49	-16.69	0.164	0.872
3.50	-16.59	0.164	0.872
3.51	-16.49	0.164	0.872
3.52	-16.39	0.164	0.873
3.53	-16.29	0.164	0.873
3.54	-16.19	0.164	0.874
3.55	-16.09	0.164	0.874
3.56	-15.99	0.164	0.874
3.57	-15.89	0.164	0.874
3.58	-15.79	0.165	0.875
3.59	-15.69	0.165	0.875
3.60	-15.59	0.165	0.876
3.61	-15.49	0.165	0.876
3.62	-15.39	0.165	0.876
3.63	-15.29	0.165	0.877
3.64	-15.19	0.165	0.877
3.65	-15.09	0.165	0.878
3.66	-14.99	0.165	0.877
3.67	-14.89	0.165	0.878
3.68	-14.79	0.165	0.878
3.69	-14.69	0.165	0.878
3.70	-14.59	0.165	0.878
3.71	-14.49	0.165	0.878
3.72	-14.39	0.165	0.879
3.73	-14.29	0.165	0.880
3.74	-14.19	0.165	0.880
3.75	-14.09	0.165	0.880
3.76	-13.99	0.165	0.880
3.77	-13.89	0.165	0.881
3.78	-13.79	0.165	0.881
3.79	-13.69	0.166	0.881
3.80	-13.59	0.166	0.882
3.81	-13.49	0.166	0.882
3.82	-13.39	0.166	0.882
3.83	-13.29	0.166	0.882
3.84	-13.19	0.166	0.882
3.85	-13.09	0.166	0.883
3.86	-12.99	0.166	0.883
3.87	-12.89	0.166	0.884
3.88	-12.79	0.166	0.884
3.89	-12.69	0.166	0.884
3.90	-12.59	0.166	0.884
3.91	-12.49	0.166	0.885
3.92	-12.39	0.166	0.885
3.93	-12.29	0.166	0.885
3.94	-12.19	0.166	0.885
3.95	-12.09	0.166	0.886
3.96	-11.99	0.166	0.887
3.97	-11.89	0.166	0.887
3.98	-11.79	0.166	0.887
3.99	-11.69	0.167	0.888
4.00	-11.59	0.167	0.887
4.01	-11.49	0.167	0.888
4.02	-11.39	0.167	0.889
4.03	-11.29	0.167	0.889
4.04	-11.19	0.167	0.889
4.05	-11.09	0.167	0.889
4.06	-10.99	0.167	0.889
4.07	-10.89	0.167	0.890
4.08	-10.79	0.167	0.890
4.09	-10.69	0.167	0.890
4.10	-10.59	0.167	0.891
4.11	-10.49	0.167	0.891
4.12	-10.39	0.167	0.892
4.13	-10.29	0.167	0.892
4.14	-10.19	0.167	0.893
4.15	-10.09	0.167	0.893
4.16	-9.99	0.167	0.893
4.17	-9.89	0.168	0.894
4.18	-9.79	0.168	0.895
4.19	-9.69	0.168	0.895
4.20	-9.59	0.168	0.895
4.21	-9.49	0.168	0.895
4.22	-9.39	0.168	0.896
4.23	-9.29	0.168	0.896
4.24	-9.19	0.168	0.896
4.25	-9.09	0.168	0.897
4.26	-8.98	0.168	0.897
4.27	-8.88	0.168	0.897
4.28	-8.79	0.168	0.897
4.29	-8.69	0.168	0.898
4.30	-8.59	0.168	0.898
4.31	-8.48	0.168	0.898
4.32	-8.39	0.168	0.899
4.33	-8.28	0.168	0.899
4.34	-8.18	0.168	0.899
4.35	-8.08	0.169	0.899
4.36	-7.98	0.169	0.900
4.37	-7.88	0.169	0.900
4.38	-7.78	0.169	0.900
4.39	-7.68	0.169	0.900
4.40	-7.58	0.169	0.901
4.41	-7.48	0.169	0.902
4.42	-7.38	0.169	0.902
4.43	-7.28	0.169	0.903
4.44	-7.18	0.169	0.903
4.45	-7.08	0.169	0.903
4.46	-6.98	0.169	0.904
4.47	-6.88	0.169	0.904
4.48	-6.78	0.169	0.904
4.49	-6.68	0.169	0.904
4.50	-6.58	0.169	0.904
4.51	-6.48	0.169	0.905
4.52	-6.38	0.170	0.905
4.53	-6.28	0.170	0.905
4.54	-6.18	0.170	0.905
4.55	-6.08	0.170	0.906
4.56	-5.98	0.170	0.907
4.57	-5.88	0.170	0.907
4.58	-5.78	0.170	0.907
4.59	-5.68	0.170	0.908
4.60	-5.58	0.170	0.908
4.61	-5.48	0.170	0.908
4.62	-5.38	0.170	0.909
4.63	-5.28	0.170	0.909
4.64	-5.18	0.170	0.909
4.65	-5.08	0.170	0.910
4.66	-4.98	0.170	0.910
4.67	-4.88	0.170	0.910
4.68	-4.78	0.170	0.911
4.69	-4.68	0.170	0.912
4.70	-4.58	0.171	0.912
4.71	-4.48	0.171	0.912
4.72	-4.38	0.171	0.912
4.73	-4.28	0.171	0.913
4.74	-4.18	0.171	0.914
4.75	-4.08	0.171	0.914
4.76	-3.98	0.171	0.913
4.77	-3.88	0.171	0.914
4.78	-3.78	0.171	0.915
4.79	-3.68	0.171	0.915
4.80	-3.58	0.171	0.915
4.81	-3.48	0.171	0.915
4.82	-3.38	0.171	0.915
4.83	-3.28	0.171	0.915
4.84	-3.18	0.171	0.916
4.85	-3.08	0.171	0.917
4.86	-2.98	0.171	0.917
4.87	-2.88	0.172	0.917
4.88	-2.78	0.172	0.917
4.89	-2.68	0.172	0.917
4.90	-2.58	0.172	0.918
4.91	-2.48	0.172	0.918
4.92	-2.38	0.172	0.918
4.93	-2.28	0.172	0.919
4.94	-2.18	0.172	0.919
4.95	-2.08	0.172	0.919
4.96	-1.98	0.172	0.920
4.97	-1.88	0.172	0.920
4.98	-1.78	0.172	0.920
4.99	-1.68	0.172	0.920
5.00	-1.58	0.172	0.921
5.01	-1.48	0.172	0.921
5.02	-1.38	0.172	0.921
5.03	-1.28	0.172	0.922
5.04	-1.18	0.173	0.923
5.05	-1.08	0.173	0.923
5.06	-0.97	0.173	0.923
5.07	-0.88	0.173	0.924
5.08	-0.77	0.173	0.924
5.09	-0.67	0.173	0.924
5.10	-0.57	0.173	0.925
5.11	-0.48	0.173	0.925
5.12	-0.37	0.173	0.925
5.13	-0.27	0.173	0.925
5.14	-0.18	0.173	0.926
5.15	-0.07	0.173	0.926
5.16	0.03	0.173	0.926
5.17	0.13	0.173	0.927
5.18	0.23	0.173	0.927
5.19	0.33	0.173	0.927
5.20	0.43	0.173	0.928
5.21	0.53	0.173	0.928
5.22	0.63	0.174	0.928
5.23	0.73	0.174	0.928
5.24	0.83	0.174	0.928
5.25	0.93	0.174	0.929
5.26	1.03	0.174	0.930
5.27	1.13	0.174	0.929
5.28	1.23	0.174	0.930
5.29	1.33	0.174	0.931
5.30	1.43	0.174	0.931
5.31	1.53	0.174	0.931
5.32	1.63	0.174	0.931
5.33	1.73	0.174	0.932
5.34	1.83	0.174	0.932
5.35	1.93	0.174	0.932
5.36	2.03	0.174	0.933
5.37	2.13	0.174	0.933
5.38	2.23	0.175	0.934
5.39	2.33	0.175	0.934
5.40	2.43	0.175	0.934
5.41	2.53	0.175	0.934
5.42	2.63	0.175	0.935
5.43	2.73	0.175	0.936
5.44	2.83	0.175	0.936
5.45	2.93	0.175	0.935
5.46	3.03	0.175	0.936
5.47	3.13	0.175	0.936
5.48	3.23	0.175	0.937
5.49	3.33	0.175	0.937
5.50	3.43	0.175	0.938
5.51	3.53	0.175	0.938
5.52	3.63	0.175	0.938
5.53	3.73	0.175	0.938
5.54	3.83	0.176	0.939
5.55	3.93	0.176	0.939
5.56	4.03	0.176	0.940
5.57	4.13	0.176	0.940
5.58	4.23	0.176	0.941
5.59	4.33	0.176	0.941
5.60	4.43	0.176	0.941
5.61	4.53	0.176	0.942
5.62	4.63	0.176	0.942
5.63	4.73	0.176	0.943
5.64	4.83	0.176	0.943
5.65	4.93	0.176	0.944
5.66	5.03	0.176	0.944
5.67	5.13	0.176	0.944
5.68	5.23	0.177	0.945
5.69	5.33	0.177	0.945
5.70	5.43	0.177	0.945
5.71	5.53	0.177	0.945
5.72	5.63	0.177	0.945
5.73	5.73	0.177	0.946
5.74	5.83	0.177	0.947
5.75	5.93	0.177	0.947
5.76	6.03	0.177	0.947
5.77	6.13	0.177	0.947
5.78	6.23	0.177	0.948
5.79	6.33	0.177	0.948
5.80	6.43	0.177	0.949
5.81	6.53	0.177	0.949
5.82	6.63	0.177	0.949
5.83	6.73	0.178	0.949
5.84	6.83	0.178	0.950
5.85	6.93	0.178	0.950
5.86	7.03	0.178	0.951
5.87	7.14	0.178	0.951
5.88	7.23	0.178	0.951
5.89	7.33	0.178	0.951
5.90	7.43	0.178	0.952
5.91	7.54	0.178	0.953
5.92	7.63	0.178	0.953
5.93	7.73	0.178	0.954
5.94	7.84	0.178	0.954
5.95	7.94	0.178	0.954
5.96	8.04	0.179	0.955
5.97	8.14	0.179	0.956
5.98	8.24	0.179	0.956
5.99	8.34	0.179	0.956
6.00	8.44	0.179	0.956
6.01	8.53	0.179	0.957
6.02	8.64	0.179	0.957
6.03	8.74	0.179	0.958
6.04	8.84	0.179	0.959
6.05	8.94	0.179	0.959
6.06	9.04	0.179	0.959
6.07	9.14	0.179	0.959
6.08	9.23	0.179	0.960
6.09	9.34	0.180	0.960
6.10	9.44	0.180	0.961
6.11	9.54	0.180	0.961
6.12	9.64	0.180	0.961
6.13	9.74	0.180	0.962
6.14	9.84	0.180	0.962
6.15	9.94	0.180	0.962
6.16	10.04	0.180	0.963
6.17	10.14	0.180	0.963
6.18	10.24	0.180	0.963
6.19	10.34	0.180	0.964
6.20	10.44	0.180	0.964
6.21	10.54	0.180	0.964
6.22	10.64	0.180	0.964
6.23	10.74	0.180	0.964
6.24	10.84	0.181	0.965
6.25	10.94	0.181	0.965
6.26	11.04	0.181	0.966
6.27	11.14	0.181	0.966
6.28	11.24	0.181	0.967
6.29	11.34	0.181	0.967
6.30	11.44	0.181	0.967
6.31	11.54	0.181	0.967
6.32	11.64	0.181	0.968
6.33	11.74	0.181	0.968
6.34	11.84	0.181	0.968
6.35	11.94	0.181	0.968
6.36	12.04	0.181	0.969
6.37	12.14	0.181	0.969
6.38	12.24	0.181	0.969
6.39	12.34	0.181	0.969
6.40	12.44	0.181	0.970
6.41	12.54	0.182	0.970
6.42	12.64	0.182	0.970
6.43	12.74	0.182	0.971
6.44	12.84	0.182	0.971
6.45	12.94	0.182	0.972
6.46	13.04	0.182	0.972
6.47	13.14	0.182	0.972
6.48	13.24	0.182	0.972
6.49	13.34	0.182	0.972
6.50	13.44	0.182	0.973
6.51	13.54	0.182	0.973
6.52	13.64	0.182	0.974
6.53	13.74	0.182	0.974
6.54	13.84	0.182	0.975
6.55	13.94	0.182	0.975
6.56	14.04	0.182	0.975
6.57	14.14	0.182	0.975
6.58	14.24	0.183	0.976
6.59	14.34	0.183	0.976
6.60	14.44	0.183	0.977
6.61	14.54	0.183	0.977
6.62	14.64	0.183	0.977
6.63	14.74	0.183	0.978
6.64	14.84	0.183	0.978
6.65	14.94	0.183	0.978
6.66	15.04	0.183	0.979
6.67	15.14	0.183	0.979
6.68	15.24	0.183	0.980
6.69	15.34	0.183	0.980
6.70	15.44	0.183	0.980
6.71	15.54	0.183	0.981
6.72	15.64	0.184	0.981
6.73	15.74	0.184	0.981
6.74	15.84	0.184	0.982
6.75	15.94	0.184	0.982
6.76	16.04	0.184	0.983
6.77	16.14	0.184	0.983
6.78	16.24	0.184	0.984
6.79	16.34	0.184	0.984
6.80	16.44	0.184	0.984
6.81	16.54	0.184	0.984
6.82	16.64	0.184	0.985
6.83	16.75	0.184	0.985
6.84	16.84	0.184	0.985
6.85	16.94	0.184	0.986
6.86	17.04	0.184	0.986
6.87	17.15	0.185	0.986
6.88	17.24	0.185	0.987
6.89	17.34	0.185	0.987
6.90	17.45	0.185	0.987
6.91	17.55	0.185	0.988
6.92	17.65	0.185	0.988
6.93	17.75	0.185	0.989
6.94	17.85	0.185	0.989
6.95	17.95	0.185	0.989
6.96	18.05	0.185	0.990
6.97	18.15	0.185	0.990
6.98	18.25	0.185	0.991
6.99	18.35	0.185	0.991
7.00	18.45	0.185	0.991
7.01	18.55	0.185	0.992
7.02	18.65	0.186	0.992
7.03	18.75	0.186	0.992
7.04	18.85	0.186	0.993
7.05	18.95	0.186	0.993
7.06	19.05	0.186	0.993
7.07	19.15	0.186	0.994
7.08	19.25	0.186	0.994
7.09	19.35	0.186	0.995
7.10	19.45	0.186	0.995
7.11	19.55	0.186	0.995
7.12	19.65	0.186	0.996
7.13	19.75	0.186	0.996
7.14	19.85	0.186	0.996
7.15	19.95	0.186	0.997
7.16	20.05	0.187	0.997
7.17	20.15	0.187	0.997
7.18	20.25	0.187	0.998
7.19	20.35	0.187	0.998
7.20	20.45	0.187	0.999
7.21	20.55	0.187	0.999
7.22	20.65	0.187	1.000
7.23	20.75	0.187	1.000
7.24	20.85	0.187	1.000
7.25	20.95	0.187	1.001
7.26	21.05	0.187	1.001
7.27	21.15	0.187	1.001
7.28	21.25	0.187	1.001
7.29	21.35	0.187	1.002
7.30	21.45	0.188	1.002
7.31	21.55	0.188	1.003
7.32	21.65	0.188	1.003
7.33	21.75	0.188	1.003
7.34	21.85	0.188	1.003
7.35	21.95	0.188	1.004
7.36	22.05	0.188	1.004
7.37	22.15	0.188	1.005
7.38	22.25	0.188	1.005
7.39	22.35	0.188	1.005
7.40	22.45	0.188	1.006
7.41	22.55	0.188	1.006
7.42	22.65	0.188	1.007
7.43	22.75	0.188	1.007
7.44	22.85	0.189	1.008
7.45	22.95	0.189	1.008
7.46	23.05	0.189	1.008
7.47	23.15	0.189	1.009
7.48	23.25	0.189	1.009
7.49	23.35	0.189	1.010
7.50	23.45	0.189	1.010
7.51	23.55	0.189	1.011
7.52	23.65	0.189	1.011
7.53	23.75	0.189	1.011
7.54	23.85	0.189	1.012
7.55	23.95	0.189	1.012
7.56	24.05	0.189	1.013
7.57	24.15	0.189	1.013
7.58	24.25	0.190	1.013
7.59	24.35	0.190	1.014
7.60	24.45	0.190	1.014
7.61	24.55	0.190	1.014
7.62	24.65	0.190	1.014
7.63	24.75	0.190	1.014
7.64	24.85	0.190	1.015
7.65	24.95	0.190	1.016
7.66	25.05	0.190	1.016
7.67	25.15	0.190	1.016
7.68	25.25	0.190	1.016
7.69	25.35	0.190	1.017
7.70	25.45	0.190	1.018
7.71	25.55	0.191	1.018
7.72	25.65	0.191	1.018
7.73	25.76	0.191	1.019
7.74	25.85	0.191	1.019
7.75	25.96	0.191	1.019
7.76	26.06	0.191	1.020
7.77	26.16	0.191	1.020
7.78	26.26	0.191	1.020
7.79	26.36	0.191	1.021
7.80	26.46	0.191	1.022
7.81	26.56	0.191	1.022
7.82	26.66	0.191	1.023
7.83	26.76	0.191	1.023
7.84	26.86	0.191	1.023
7.85	26.96	0.191	1.024
7.86	27.06	0.192	1.024
7.87	27.16	0.192	1.024
7.88	27.26	0.192	1.024
7.89	27.36	0.192	1.025
7.90	27.46	0.192	1.025
7.91	27.56	0.192	1.026
7.92	27.66	0.192	1.026
7.93	27.76	0.192	1.026
7.94	27.86	0.192	1.027
7.95	27.96	0.192	1.027
7.96	28.06	0.192	1.027
7.97	28.16	0.192	1.028
7.98	28.26	0.192	1.028
7.99	28.36	0.192	1.029
8.00	28.46	0.192	1.029
8.01	28.56	0.193	1.029
8.02	28.66	0.193	1.029
8.03	28.76	0.193	1.030
8.04	28.86	0.193	1.031
8.05	28.96	0.193	1.031
8.06	29.06	0.193	1.032
8.07	29.16	0.193	1.032
8.08	29.26	0.193	1.032
8.09	29.36	0.193	1.033
8.10	29.46	0.193	1.033
8.11	29.56	0.193	1.033
8.12	29.66	0.193	1.034
8.13	29.76	0.193	1.034
8.14	29.86	0.193	1.034
8.15	29.96	0.194	1.035
8.16	30.06	0.194	1.035
8.17	30.16	0.194	1.035
8.18	30.26	0.194	1.036
8.19	30.36	0.194	1.036
8.20	30.46	0.194	1.036
8.21	30.56	0.194	1.037
8.22	30.66	0.194	1.037
8.23	30.76	0.194	1.038
8.24	30.86	0.194	1.038
8.25	30.96	0.194	1.038
8.26	31.06	0.194	1.039
8.27	31.16	0.194	1.039
8.28	31.26	0.194	1.040
8.29	31.36	0.195	1.040
8.30	31.46	0.195	1.040
8.31	31.56	0.195	1.041
8.32	31.66	0.195	1.041
8.33	31.76	0.195	1.041
8.34	31.86	0.195	1.041
8.35	31.96	0.195	1.041
8.36	32.06	0.195	1.043
8.37	32.16	0.195	1.043
8.38	32.26	0.195	1.043
8.39	32.36	0.195	1.044
8.40	32.46	0.195	1.044
8.41	32.56	0.195	1.044
8.42	32.66	0.195	1.045
8.43	32.76	0.195	1.045
8.44	32.86	0.196	1.045
8.45	32.96	0.196	1.046
8.46	33.06	0.196	1.047
8.47	33.16	0.196	1.047
8.48	33.26	0.196	1.047
8.49	33.36	0.196	1.048
8.50	33.46	0.196	1.048
8.51	33.56	0.196	1.048
8.52	33.66	0.196	1.049
8.53	33.76	0.196	1.049
8.54	33.86	0.196	1.049
8.55	33.96	0.196	1.050
8.56	34.06	0.196	1.050
8.57	34.16	0.196	1.050
8.58	34.26	0.197	1.051
8.59	34.36	0.197	1.051
8.60	34.46	0.197	1.051
8.61	34.56	0.197	1.051
8.62	34.66	0.197	1.051
8.63	34.76	0.197	1.052
8.64	34.87	0.197	1.052
8.65	34.96	0.197	1.052
8.66	35.06	0.197	1.053
8.67	35.16	0.197	1.053
8.68	35.26	0.197	1.053
8.69	35.37	0.197	1.054
8.70	35.47	0.197	1.055
8.71	35.57	0.197	1.055
8.72	35.67	0.197	1.055
8.73	35.77	0.198	1.056
8.74	35.87	0.198	1.056
8.75	35.97	0.198	1.056
8.76	36.07	0.198	1.057
8.77	36.17	0.198	1.057
8.78	36.27	0.198	1.058
8.79	36.37	0.198	1.058
8.80	36.47	0.198	1.058
8.81	36.57	0.198	1.059
8.82	36.67	0.198	1.059
8.83	36.77	0.198	1.060
8.84	36.87	0.198	1.060
8.85	36.97	0.198	1.060
8.86	37.07	0.198	1.061
8.87	37.17	0.198	1.061
8.88	37.27	0.199	1.061
8.89	37.37	0.199	1.062
8.90	37.47	0.199	1.061
8.91	37.57	0.199	1.062
8.92	37.67	0.199	1.062
8.93	37.77	0.199	1.062
8.94	37.87	0.199	1.062
8.95	37.97	0.199	1.063
8.96	38.07	0.199	1.063
8.97	38.17	0.199	1.064
8.98	38.27	0.199	1.064
8.99	38.37	0.199	1.064
9.00	38.47	0.199	1.065
9.01	38.57	0.199	1.065
9.02	38.67	0.199	1.065
9.03	38.77	0.200	1.065
9.04	38.87	0.200	1.066
9.05	38.97	0.200	1.066
9.06	39.07	0.200	1.067
9.07	39.17	0.200	1.067
9.08	39.27	0.200	1.067
9.09	39.37	0.200	1.067
9.10	39.47	0.200	1.068
9.11	39.57	0.200	1.068
9.12	39.67	0.200	1.069
9.13	39.77	0.200	1.069
9.14	39.87	0.200	1.069
9.15	39.97	0.200	1.070
9.16	40.07	0.200	1.070
9.17	40.17	0.201	1.070
9.18	40.27	0.201	1.071
9.19	40.37	0.201	1.071
9.20	40.47	0.201	1.071
9.21	40.57	0.201	1.072
9.22	40.67	0.201	1.072
9.23	40.77	0.201	1.072
9.24	40.87	0.201	1.073
9.25	40.97	0.201	1.073
9.26	41.07	0.201	1.073
9.27	41.17	0.201	1.074
9.28	41.27	0.201	1.074
9.29	41.37	0.201	1.075
9.30	41.47	0.201	1.075
9.31	41.57	0.202	1.075
9.32	41.67	0.202	1.075
9.33	41.77	0.202	1.076
9.34	41.87	0.202	1.076
9.35	41.97	0.202	1.076
9.36	42.07	0.202	1.076
9.37	42.17	0.202	1.077
9.38	42.27	0.202	1.077
9.39	42.37	0.202	1.077
9.40	42.47	0.202	1.078
9.41	42.57	0.202	1.078
9.42	42.67	0.202	1.078
9.43	42.77	0.202	1.079
9.44	42.87	0.202	1.079
9.45	42.97	0.203	1.080
9.46	43.07	0.203	1.080
9.47	43.17	0.203	1.080
9.48	43.27	0.203	1.081
9.49	43.37	0.203	1.081
9.50	43.47	0.203	1.081
9.51	43.57	0.203	1.081
9.52	43.67	0.203	1.082
9.53	43.77	0.203	1.083
9.54	43.87	0.203	1.083
9.55	43.97	0.203	1.083
9.56	44.07	0.203	1.084
9.57	44.17	0.203	1.084
9.58	44.27	0.203	1.084
9.59	44.37	0.204	1.085
9.60	44.47	0.204	1.085
9.61	44.57	0.204	1.085
9.62	44.67	0.204	1.085
9.63	44.77	0.204	1.085
9.64	44.87	0.204	1.086
9.65	44.97	0.204	1.086
9.66	45.07	0.204	1.086
9.67	45.17	0.204	1.087
9.68	45.28	0.204	1.087
9.69	45.37	0.204	1.088
9.70	45.48	0.204	1.088
9.71	45.58	0.204	1.088
9.72	45.68	0.204	1.088
9.73	45.78	0.205	1.089
9.74	45.88	0.205	1.089
9.75	45.97	0.205	1.090
9.76	46.08	0.205	1.091
9.77	46.18	0.205	1.090
9.78	46.28	0.205	1.091
9.79	46.38	0.205	1.091
9.80	46.48	0.205	1.091
9.81	46.58	0.205	1.092
9.82	46.68	0.205	1.093
9.83	46.78	0.205	1.093
9.84	46.88	0.205	1.094
9.85	46.98	0.205	1.094
9.86	47.08	0.206	1.095
9.87	47.18	0.206	1.095
9.88	47.28	0.206	1.096
9.89	47.38	0.206	1.096
9.90	47.48	0.206	1.095
9.91	47.58	0.206	1.096
9.92	47.68	0.206	1.096
9.93	47.78	0.206	1.097
9.94	47.88	0.206	1.097
9.95	47.98	0.206	1.097
9.96	48.08	0.206	1.098
9.97	48.18	0.206	1.098
9.98	48.28	0.206	1.099
9.99	48.38	0.206	1.099
10.00	48.48	0.207	1.100
10.01	48.58	0.207	1.101
10.02	48.68	0.207	1.101
10.03	48.78	0.207	1.101
10.04	48.88	0.207	1.102
10.05	48.98	0.207	1.102
10.06	49.08	0.207	1.102
10.07	49.18	0.207	1.102
10.08	49.28	0.207	1.102
10.09	49.38	0.207	1.103
10.10	49.48	0.207	1.104
10.11	49.58	0.208	1.105
10.12	49.68	0.208	1.105
10.13	49.78	0.208	1.105
10.14	49.88	0.208	1.106
10.15	49.98	0.208	1.106
10.16	50.08	0.208	1.107
10.17	50.18	0.208	1.107
10.18	50.28	0.208	1.108
10.19	50.38	0.208	1.108
10.20	50.48	0.208	1.109
10.21	50.58	0.208	1.109
10.22	50.68	0.208	1.109
10.23	50.78	0.209	1.110
10.24	50.88	0.209	1.111
10.25	50.98	0.209	1.112
10.26	51.08	0.209	1.112
10.27	51.18	0.209	1.113
10.28	51.28	0.209	1.113
10.29	51.38	0.209	1.114
10.30	51.48	0.209	1.115
10.31	51.58	0.209	1.115
10.32	51.68	0.209	1.115
10.33	51.78	0.210	1.116
10.34	51.88	0.210	1.117
10.35	51.98	0.210	1.117
10.36	52.08	0.210	1.118
10.37	52.18	0.210	1.118
10.38	52.28	0.210	1.120
10.39	52.38	0.210	1.120
10.40	52.48	0.210	1.120
10.41	52.58	0.210	1.121
10.42	52.68	0.210	1.121
10.43	52.78	0.211	1.122
10.44	52.88	0.211	1.123
10.45	52.98	0.211	1.123
10.46	53.08	0.211	1.124
10.47	53.18	0.211	1.124
10.48	53.28	0.211	1.125
10.49	53.38	0.211	1.127
10.50	53.48	0.211	1.127
10.51	53.58	0.212	1.128
10.52	53.68	0.212	1.129
10.53	53.78	0.212	1.130
10.54	53.88	0.212	1.131
10.55	53.98	0.212	1.132
10.56	54.08	0.212	1.133
10.57	54.18	0.213	1.135
10.58	54.28	0.213	1.136
10.59	54.38	0.213	1.137
10.60	54.48	0.213	1.141
10.61	54.58	0.214	1.147
10.62	54.68	0.214	1.155
10.63	54.78	0.215	1.169
10.64	54.88	0.215	1.187
10.65	54.98	0.216	1.209
10.66	55.08	0.217	1.237
10.67	55.18	0.218	1.266
10.68	55.28	0.220	1.304
10.69	55.38	0.231	1.395
10.70	55.48	0.255	1.558
10.71	55.57	0.303	1.878
10.72	55.66	0.379	2.375
10.73	55.75	0.475	3.012
10.74	55.82	0.583	3.733
10.75	55.89	0.693	4.473
10.76	55.96	0.797	5.190
10.77	56.02	0.882	5.786
10.78	56.08	0.928	6.149
10.79	56.15	0.933	6.245
10.80	56.22	0.920	6.237
10.81	56.30	0.928	6.384
10.82	56.38	0.963	6.715
10.83	56.46	0.981	6.923
10.84	56.55	0.983	6.967
10.85	56.63	1.005	7.124
10.86	56.72	1.014	7.177
10.87	56.81	1.028	7.307
10.88	56.89	1.082	7.812
10.89	56.97	1.158	8.593
10.90	57.05	1.232	9.444
10.91	57.12	1.337	10.629
10.92	57.19	1.436	11.843
10.93	57.26	1.491	12.717
10.94	57.33	1.527	13.411
10.95	57.40	1.579	14.154
10.96	57.47	1.673	15.243
10.97	57.53	1.881	17.409
10.98	57.57	2.159	20.331
10.99	57.59	2.367	22.757
11.00	57.62	2.495	24.472
11.01	57.65	2.618	26.153
11.02	57.68	2.704	27.313
11.03	57.72	2.760	27.806
11.04	57.76	2.750	27.384
11.05	57.82	2.718	26.541
11.06	57.89	2.720	25.891
11.07	57.96	2.762	25.312
11.08	58.02	2.870	24.887
11.09	58.08	2.990	24.230
11.10	58.14	3.110	23.559
11.11	58.19	3.217	22.808
11.12	58.25	3.235	21.526
11.13	58.31	3.171	19.890
11.14	58.40	3.090	18.398
11.15	58.49	3.018	17.210
11.16	58.58	2.966	16.272
11.17	58.69	2.913	15.422
11.18	58.79	2.838	14.499
11.19	58.91	2.748	13.529
11.20	59.03	2.656	12.603
11.21	59.15	2.561	11.706
11.22	59.28	2.462	10.878
11.23	59.42	2.369	10.170
11.24	59.56	2.282	9.575
11.25	59.69	2.194	9.049
11.26	59.83	2.113	8.583
11.27	59.97	2.038	8.176
11.28	60.11	1.966	7.811
11.29	60.25	1.896	7.477
11.30	60.39	1.830	7.178
11.31	60.53	1.766	6.903
11.32	60.67	1.702	6.641
11.33	60.81	1.640	6.397
11.34	60.94	1.580	6.169
11.35	61.08	1.522	5.948
11.36	61.21	1.464	5.732
11.37	61.35	1.404	5.509
11.38	61.48	1.347	5.297
11.39	61.62	1.287	5.075
11.40	61.75	1.226	4.848
11.41	61.89	1.163	4.614
11.42	62.02	1.100	4.383
11.43	62.16	1.036	4.148
11.44	62.29	0.973	3.915
11.45	62.42	0.909	3.675
11.46	62.56	0.846	3.443
11.47	62.70	0.787	3.225
11.48	62.83	0.736	3.033
11.49	62.96	0.689	2.861
11.50	63.09	0.649	2.715
11.51	63.22	0.613	2.587
11.52	63.35	0.585	2.491
11.53	63.47	0.554	2.383
11.54	63.60	0.528	2.291
11.55	63.72	0.514	2.252
11.56	63.84	0.491	2.174
11.57	63.96	0.471	2.108
11.58	64.08	0.455	2.063
11.59	64.19	0.442	2.024
11.60	64.31	0.427	1.978
11.61	64.42	0.415	1.944
11.62	64.53	0.404	1.911
11.63	64.64	0.393	1.876
11.64	64.75	0.384	1.848
11.65	64.86	0.376	1.821
11.66	64.97	0.368	1.798
11.67	65.08	0.360	1.772
11.68	65.18	0.354	1.753
11.69	65.29	0.347	1.730
11.70	65.40	0.343	1.719
11.71	65.50	0.337	1.697
11.72	65.61	0.333	1.686
11.73	65.71	0.328	1.669
11.74	65.82	0.325	1.660
11.75	65.92	0.322	1.647
11.76	66.02	0.318	1.636
11.77	66.13	0.316	1.627
11.78	66.23	0.312	1.613
11.79	66.33	0.311	1.609
11.80	66.44	0.309	1.604
11.81	66.54	0.307	1.600
11.82	66.64	0.304	1.585
11.83	66.74	0.303	1.585
11.84	66.84	0.302	1.582
11.85	66.95	0.301	1.577
11.86	67.05	0.299	1.570
11.87	67.15	0.298	1.569
11.88	67.25	0.298	1.568
11.89	67.35	0.297	1.565
11.90	67.45	0.296	1.563
11.91	67.55	0.295	1.560
11.92	67.65	0.295	1.556
11.93	67.76	0.294	1.554
11.94	67.86	0.294	1.553
11.95	67.96	0.293	1.553
11.96	68.06	0.293	1.552
11.97	68.16	0.293	1.552
11.98	68.26	0.293	1.552
11.99	68.36	0.292	1.551
12.00	68.46	0.292	1.551
12.01	68.56	0.292	1.549
12.02	68.66	0.291	1.548
12.03	68.76	0.291	1.548
12.04	68.86	0.291	1.547
12.05	68.96	0.291	1.547
12.06	69.06	0.291	1.547
12.07	69.16	0.291	1.547
12.08	69.26	0.291	1.548
[...]
237.07	-40.89	0.174	0.914
237.08	-40.84	0.174	0.914
237.08	-40.79	0.174	0.915
237.09	-40.74	0.174	0.915
237.09	-40.69	0.174	0.915
237.10	-40.64	0.174	0.915
237.10	-40.59	0.174	0.915
237.11	-40.54	0.174	0.915
237.11	-40.49	0.174	0.916
237.12	-40.44	0.174	0.916
237.12	-40.39	0.174	0.916
237.13	-40.34	0.174	0.916
237.13	-40.29	0.174	0.916
237.14	-40.24	0.174	0.917
237.14	-40.19	0.175	0.917
237.15	-40.14	0.175	0.916
237.15	-40.09	0.175	0.916
237.16	-40.04	0.175	0.917
237.16	-39.99	0.175	0.918
237.17	-39.94	0.175	0.918
237.17	-39.89	0.175	0.918
237.18	-39.84	0.175	0.918
237.18	-39.80	0.175	0.918
237.19	-39.75	0.175	0.918
237.19	-39.70	0.175	0.918
237.20	-39.64	0.175	0.919
237.20	-39.60	0.175	0.920
237.21	-39.54	0.175	0.920
237.21	-39.50	0.175	0.919
237.22	-39.45	0.175	0.919
237.22	-39.40	0.175	0.920
237.23	-39.35	0.175	0.920
237.23	-39.30	0.175	0.920
237.24	-39.25	0.175	0.921
237.24	-39.20	0.175	0.921
237.25	-39.14	0.175	0.922
237.25	-39.10	0.175	0.922
237.26	-39.05	0.175	0.922
237.26	-39.00	0.176	0.922
237.27	-38.95	0.176	0.922
237.27	-38.90	0.176	0.923
237.28	-38.85	0.176	0.922
237.28	-38.80	0.176	0.922
237.29	-38.75	0.176	0.922
237.29	-38.70	0.176	0.922
237.30	-38.65	0.176	0.923
237.30	-38.60	0.176	0.923
237.31	-38.55	0.176	0.923
237.31	-38.50	0.176	0.923
237.32	-38.45	0.176	0.924
237.32	-38.40	0.176	0.925
237.33	-38.35	0.176	0.925
237.33	-38.30	0.176	0.925
237.34	-38.25	0.176	0.926
237.34	-38.20	0.176	0.926
237.35	-38.15	0.176	0.926
237.35	-38.10	0.176	0.926
237.36	-38.05	0.176	0.926
237.36	-38.00	0.177	0.926
237.37	-37.95	0.177	0.927
237.37	-37.90	0.177	0.927
237.38	-37.85	0.177	0.928
237.38	-37.80	0.177	0.928
237.39	-37.75	0.177	0.928
237.39	-37.70	0.177	0.928
237.40	-37.65	0.177	0.928
237.40	-37.60	0.177	0.928
237.41	-37.55	0.177	0.928
237.41	-37.50	0.177	0.928
237.42	-37.45	0.177	0.929
237.42	-37.40	0.177	0.929
237.43	-37.35	0.177	0.929
237.43	-37.30	0.177	0.930
237.44	-37.25	0.177	0.930
237.44	-37.20	0.177	0.930
237.45	-37.15	0.177	0.930
237.45	-37.10	0.177	0.930
237.46	-37.05	0.177	0.930
237.46	-37.00	0.177	0.930
237.47	-36.95	0.177	0.930
237.47	-36.90	0.177	0.931
237.48	-36.85	0.177	0.931
237.48	-36.80	0.177	0.931
237.49	-36.75	0.177	0.932
237.49	-36.70	0.177	0.932
237.50	-36.65	0.177	0.932
237.50	-36.60	0.177	0.932
237.51	-36.55	0.178	0.933
237.51	-36.50	0.178	0.933
237.52	-36.45	0.178	0.933
237.52	-36.40	0.178	0.933
237.53	-36.35	0.178	0.934
237.53	-36.30	0.178	0.934
237.54	-36.25	0.178	0.934
237.54	-36.20	0.178	0.934
237.55	-36.15	0.178	0.934
237.55	-36.10	0.178	0.935
237.56	-36.05	0.178	0.935
237.56	-36.00	0.178	0.935
237.57	-35.95	0.178	0.935
237.57	-35.90	0.178	0.936
237.58	-35.85	0.178	0.935
237.58	-35.80	0.178	0.935
237.59	-35.75	0.178	0.936
237.59	-35.70	0.178	0.936
237.60	-35.65	0.178	0.937
237.60	-35.60	0.178	0.937
237.61	-35.55	0.178	0.937
237.61	-35.50	0.178	0.938
237.62	-35.45	0.178	0.938
237.62	-35.40	0.178	0.938
237.63	-35.35	0.178	0.937
237.63	-35.30	0.178	0.938
237.64	-35.25	0.178	0.938
237.64	-35.20	0.179	0.938
237.65	-35.15	0.179	0.938
237.65	-35.10	0.179	0.938
237.66	-35.05	0.179	0.939
237.66	-35.00	0.179	0.939
237.67	-34.95	0.179	0.939
237.67	-34.90	0.179	0.939
237.68	-34.85	0.179	0.939
237.68	-34.80	0.179	0.940
237.69	-34.75	0.179	0.940
237.69	-34.70	0.179	0.940
237.70	-34.65	0.179	0.940
237.70	-34.60	0.179	0.941
237.71	-34.55	0.179	0.941
237.71	-34.50	0.179	0.942
237.72	-34.45	0.179	0.942
237.72	-34.40	0.179	0.942
237.73	-34.35	0.179	0.942
237.73	-34.30	0.179	0.942
237.74	-34.25	0.179	0.942
237.74	-34.20	0.179	0.943
237.75	-34.15	0.179	0.943
237.75	-34.10	0.179	0.944
237.76	-34.05	0.179	0.944
237.76	-34.00	0.179	0.944
237.77	-33.95	0.179	0.944
237.77	-33.90	0.180	0.944
237.78	-33.85	0.180	0.945
237.78	-33.80	0.180	0.945
237.79	-33.75	0.180	0.945
237.79	-33.70	0.180	0.945
237.80	-33.65	0.180	0.946
237.80	-33.60	0.180	0.946
237.81	-33.55	0.180	0.946
237.81	-33.50	0.180	0.946
237.82	-33.45	0.180	0.946
237.82	-33.40	0.180	0.947
237.83	-33.35	0.180	0.947
237.83	-33.30	0.180	0.947
237.84	-33.25	0.180	0.948
237.84	-33.20	0.180	0.948
237.85	-33.15	0.180	0.949
237.85	-33.10	0.180	0.949
237.86	-33.05	0.180	0.949
237.86	-33.00	0.180	0.949
237.87	-32.95	0.180	0.949
237.87	-32.90	0.180	0.949
237.88	-32.85	0.180	0.949
237.88	-32.80	0.180	0.950
237.89	-32.75	0.180	0.951
237.89	-32.70	0.181	0.951
237.90	-32.65	0.181	0.951
237.90	-32.60	0.181	0.951
237.91	-32.55	0.181	0.951
237.91	-32.50	0.181	0.951
237.92	-32.45	0.181	0.951
237.92	-32.40	0.181	0.952
237.93	-32.35	0.181	0.953
237.93	-32.30	0.181	0.953
237.94	-32.25	0.181	0.953
237.94	-32.20	0.181	0.953
237.95	-32.15	0.181	0.953
237.95	-32.10	0.181	0.953
237.96	-32.05	0.181	0.954
237.96	-32.00	0.181	0.954
237.97	-31.95	0.181	0.955
237.97	-31.90	0.181	0.955
237.98	-31.85	0.181	0.955
237.98	-31.80	0.181	0.956
237.99	-31.75	0.181	0.956
237.99	-31.70	0.181	0.956
238.00	-31.65	0.182	0.957
238.00	-31.60	0.182	0.957
238.01	-31.55	0.182	0.957
238.01	-31.50	0.182	0.958
238.02	-31.45	0.182	0.958
238.02	-31.40	0.182	0.958
238.03	-31.35	0.182	0.958
238.03	-31.30	0.182	0.959
238.04	-31.25	0.182	0.959
238.04	-31.20	0.182	0.960
238.05	-31.15	0.182	0.960
238.05	-31.10	0.182	0.960
238.06	-31.05	0.182	0.960
238.06	-31.00	0.182	0.961
238.07	-30.95	0.182	0.961
238.07	-30.90	0.182	0.961
238.08	-30.85	0.182	0.962
238.08	-30.80	0.182	0.962
238.09	-30.75	0.182	0.962
238.09	-30.70	0.182	0.963
238.10	-30.65	0.183	0.963
238.10	-30.60	0.183	0.964
238.11	-30.55	0.183	0.964
238.11	-30.50	0.183	0.964
238.12	-30.45	0.183	0.964
238.12	-30.40	0.183	0.965
238.13	-30.35	0.183	0.965
238.13	-30.30	0.183	0.965
238.14	-30.25	0.183	0.965
238.14	-30.20	0.183	0.966
238.15	-30.15	0.183	0.967
238.15	-30.10	0.183	0.968
238.16	-30.05	0.183	0.968
238.16	-30.00	0.183	0.969
238.17	-29.95	0.184	0.969
238.17	-29.90	0.184	0.969
238.18	-29.85	0.184	0.969
238.18	-29.80	0.184	0.970
238.19	-29.75	0.184	0.970
238.19	-29.70	0.184	0.971
238.20	-29.65	0.184	0.971
238.20	-29.60	0.184	0.971
238.21	-29.55	0.184	0.971
238.21	-29.50	0.184	0.972
238.22	-29.45	0.184	0.973
238.22	-29.40	0.184	0.973
238.23	-29.35	0.184	0.973
238.23	-29.30	0.184	0.973
238.24	-29.25	0.184	0.974
238.24	-29.20	0.185	0.974
238.25	-29.15	0.185	0.975
238.25	-29.10	0.185	0.976
238.26	-29.05	0.185	0.977
238.26	-29.00	0.185	0.978
238.27	-28.95	0.185	0.979
238.27	-28.90	0.185	0.979
238.28	-28.85	0.185	0.979
238.28	-28.80	0.185	0.980
238.29	-28.75	0.186	0.981
238.29	-28.70	0.186	0.982
238.30	-28.65	0.186	0.982
238.30	-28.60	0.186	0.982
238.31	-28.55	0.186	0.983
238.31	-28.50	0.186	0.983
238.32	-28.45	0.186	0.984
238.32	-28.40	0.186	0.986
238.33	-28.35	0.187	0.986
238.33	-28.30	0.187	0.988
238.34	-28.25	0.187	0.989
238.34	-28.20	0.187	0.989
238.35	-28.15	0.187	0.989
238.35	-28.10	0.187	0.990
238.36	-28.05	0.188	0.991
238.36	-28.00	0.188	0.993
238.37	-27.95	0.188	0.993
238.37	-27.90	0.188	0.994
238.38	-27.85	0.188	0.994
238.38	-27.80	0.188	0.995
238.39	-27.75	0.188	0.995
238.39	-27.70	0.188	0.996
238.40	-27.65	0.189	0.998
238.40	-27.60	0.189	1.000
238.41	-27.55	0.189	1.001
238.41	-27.50	0.189	1.002
238.42	-27.45	0.189	1.002
238.42	-27.40	0.190	1.003
238.43	-27.35	0.190	1.007
238.43	-27.30	0.191	1.008
238.44	-27.25	0.191	1.009
238.44	-27.20	0.191	1.010
238.45	-27.15	0.191	1.013
238.45	-27.10	0.192	1.017
238.46	-27.05	0.192	1.018
238.46	-27.00	0.192	1.019
238.47	-26.95	0.193	1.020
238.47	-26.90	0.193	1.022
238.48	-26.85	0.193	1.022
238.48	-26.80	0.193	1.022
238.49	-26.75	0.193	1.025
238.49	-26.70	0.194	1.029
238.50	-26.65	0.195	1.033
238.50	-26.60	0.195	1.035
238.51	-26.55	0.196	1.037
238.51	-26.50	0.196	1.038
238.52	-26.45	0.196	1.039
238.52	-26.40	0.196	1.041
238.53	-26.35	0.197	1.043
238.53	-26.30	0.197	1.045
238.54	-26.25	0.197	1.046
238.54	-26.20	0.198	1.048
238.55	-26.15	0.198	1.049
238.55	-26.10	0.198	1.052
238.56	-26.05	0.199	1.057
238.56	-26.01	0.200	1.062
238.57	-25.95	0.201	1.066
238.57	-25.90	0.201	1.070
238.58	-25.85	0.202	1.072
238.58	-25.80	0.202	1.074
238.59	-25.75	0.203	1.076
238.59	-25.70	0.203	1.079
238.60	-25.66	0.203	1.081
238.60	-25.61	0.204	1.085
238.61	-25.56	0.205	1.090
238.61	-25.51	0.206	1.097
238.62	-25.46	0.207	1.099
238.62	-25.41	0.207	1.100
238.63	-25.36	0.207	1.104
238.63	-25.30	0.208	1.109
238.64	-25.26	0.209	1.113
238.64	-25.21	0.210	1.118
238.65	-25.16	0.211	1.124
238.65	-25.11	0.212	1.129
238.66	-25.06	0.213	1.132
238.66	-25.01	0.213	1.135
238.67	-24.96	0.214	1.141
238.67	-24.91	0.215	1.147
238.68	-24.86	0.216	1.152
238.68	-24.81	0.216	1.154
238.69	-24.76	0.217	1.160
238.69	-24.71	0.218	1.166
238.70	-24.66	0.219	1.170
238.70	-24.61	0.220	1.175
238.71	-24.56	0.222	1.186
238.71	-24.51	0.223	1.195
238.72	-24.46	0.224	1.198
238.72	-24.41	0.224	1.201
238.73	-24.36	0.226	1.210
238.73	-24.31	0.228	1.220
238.74	-24.26	0.229	1.226
238.74	-24.21	0.229	1.229
238.75	-24.17	0.231	1.238
238.75	-24.12	0.233	1.253
238.76	-24.07	0.235	1.262
238.76	-24.02	0.236	1.270
238.77	-23.97	0.238	1.278
238.77	-23.92	0.239	1.285
238.78	-23.87	0.240	1.293
238.78	-23.82	0.242	1.301
238.79	-23.77	0.244	1.314
238.79	-23.72	0.245	1.321
238.80	-23.67	0.247	1.332
238.80	-23.62	0.249	1.341
238.81	-23.57	0.251	1.356
238.81	-23.53	0.253	1.363
238.82	-23.47	0.255	1.373
238.82	-23.42	0.255	1.378
238.83	-23.38	0.258	1.392
238.83	-23.33	0.262	1.412
238.84	-23.28	0.264	1.424
238.84	-23.23	0.265	1.432
238.85	-23.18	0.267	1.442
238.85	-23.13	0.269	1.456
238.86	-23.08	0.272	1.471
238.86	-23.04	0.274	1.482
238.87	-22.99	0.275	1.488
238.87	-22.94	0.277	1.499
238.88	-22.89	0.280	1.514
238.88	-22.84	0.283	1.529
238.89	-22.79	0.285	1.540
238.89	-22.74	0.286	1.548
238.90	-22.69	0.288	1.557
238.90	-22.64	0.290	1.567
238.91	-22.59	0.293	1.581
238.91	-22.55	0.295	1.591
238.92	-22.50	0.297	1.600
238.92	-22.45	0.297	1.603
238.93	-22.40	0.298	1.607
238.93	-22.35	0.300	1.612
238.94	-22.30	0.301	1.617
238.94	-22.25	0.302	1.623
238.95	-22.20	0.303	1.627
238.95	-22.15	0.303	1.626
238.96	-22.11	0.303	1.623
238.96	-22.06	0.303	1.621
238.97	-22.01	0.303	1.618
238.97	-21.96	0.303	1.616
238.98	-21.91	0.302	1.609
238.98	-21.86	0.301	1.603
238.99	-21.81	0.300	1.597
238.99	-21.76	0.299	1.589
239.00	-21.71	0.298	1.578
239.00	-21.66	0.295	1.564
239.01	-21.61	0.292	1.544
239.01	-21.56	0.287	1.517
239.02	-21.51	0.285	1.507
239.02	-21.46	0.284	1.498
239.03	-21.41	0.282	1.484
239.03	-21.36	0.277	1.458
239.04	-21.30	0.274	1.442
239.04	-21.25	0.271	1.423
239.05	-21.20	0.270	1.415
239.05	-21.15	0.267	1.398
239.06	-21.10	0.264	1.383
239.06	-21.05	0.261	1.367
239.07	-21.00	0.259	1.354
239.07	-20.95	0.257	1.346
239.08	-20.90	0.256	1.335
239.08	-20.85	0.254	1.325
239.09	-20.79	0.252	1.313
239.09	-20.74	0.250	1.306
239.10	-20.69	0.249	1.296
239.10	-20.64	0.247	1.286
239.11	-20.59	0.246	1.282
239.11	-20.54	0.245	1.275
239.12	-20.49	0.244	1.271
239.12	-20.44	0.243	1.266
239.13	-20.38	0.243	1.266
239.13	-20.33	0.242	1.260
239.14	-20.28	0.241	1.257
239.14	-20.23	0.240	1.253
239.15	-20.18	0.239	1.250
239.15	-20.13	0.239	1.245
239.16	-20.08	0.238	1.241
239.16	-20.03	0.237	1.239
239.17	-19.98	0.237	1.240
239.17	-19.93	0.237	1.241
239.18	-19.88	0.237	1.238
239.18	-19.83	0.236	1.234
239.19	-19.78	0.235	1.232
239.19	-19.72	0.235	1.231
239.20	-19.67	0.235	1.230
239.20	-19.62	0.234	1.229
239.21	-19.57	0.234	1.228
239.21	-19.52	0.234	1.226
239.22	-19.47	0.233	1.226
239.22	-19.42	0.233	1.226
239.23	-19.37	0.233	1.226
239.23	-19.32	0.233	1.225
239.24	-19.27	0.233	1.224
239.24	-19.22	0.232	1.223
239.25	-19.17	0.232	1.223
239.25	-19.12	0.232	1.222
239.26	-19.07	0.232	1.221
239.26	-19.02	0.232	1.221
239.27	-18.97	0.232	1.221
239.27	-18.92	0.231	1.220
239.28	-18.87	0.231	1.220
239.28	-18.82	0.231	1.219
239.29	-18.77	0.231	1.220
239.29	-18.71	0.231	1.219
239.30	-18.66	0.231	1.219
239.30	-18.61	0.231	1.220
239.31	-18.56	0.231	1.220
239.31	-18.51	0.231	1.220
239.32	-18.46	0.231	1.219
239.32	-18.41	0.230	1.218
239.33	-18.36	0.230	1.218
239.33	-18.31	0.230	1.217
239.34	-18.26	0.230	1.217
239.34	-18.21	0.230	1.217
239.35	-18.16	0.230	1.217
239.35	-18.11	0.230	1.217
239.36	-18.06	0.230	1.217
239.36	-18.01	0.230	1.216
239.37	-17.96	0.230	1.216
239.37	-17.91	0.230	1.216
239.38	-17.86	0.230	1.216
239.38	-17.81	0.229	1.216
239.39	-17.76	0.229	1.215
239.39	-17.71	0.229	1.215
239.40	-17.66	0.229	1.216
239.40	-17.61	0.229	1.216
239.41	-17.56	0.229	1.215
239.41	-17.51	0.229	1.215
239.42	-17.46	0.229	1.214
239.42	-17.41	0.229	1.214
239.43	-17.36	0.229	1.214
239.43	-17.31	0.229	1.214
239.44	-17.26	0.229	1.215
239.44	-17.21	0.229	1.214
239.45	-17.16	0.229	1.214
239.45	-17.11	0.229	1.213
239.46	-17.06	0.229	1.213
239.46	-17.01	0.229	1.214
239.47	-16.96	0.229	1.213
239.47	-16.91	0.229	1.213
239.48	-16.86	0.229	1.214
239.48	-16.81	0.229	1.213
239.49	-16.76	0.228	1.213
239.49	-16.71	0.228	1.213
239.50	-16.66	0.228	1.213
239.50	-16.61	0.228	1.213
239.51	-16.56	0.228	1.212
239.51	-16.51	0.228	1.212
239.52	-16.46	0.228	1.212
239.52	-16.41	0.228	1.212
239.53	-16.36	0.228	1.212
239.53	-16.31	0.228	1.212
239.54	-16.26	0.228	1.212
239.54	-16.21	0.228	1.212
239.55	-16.16	0.228	1.211
239.55	-16.11	0.228	1.211
239.56	-16.06	0.228	1.211
239.56	-16.01	0.228	1.211
239.57	-15.95	0.228	1.212
239.57	-15.91	0.228	1.211
239.58	-15.86	0.228	1.211
239.58	-15.81	0.228	1.211
239.59	-15.76	0.228	1.211
239.59	-15.71	0.228	1.211
239.60	-15.66	0.228	1.211
239.60	-15.61	0.228	1.211
239.61	-15.56	0.228	1.211
239.61	-15.51	0.228	1.211
239.62	-15.46	0.228	1.211
239.62	-15.41	0.228	1.211
239.63	-15.36	0.228	1.211
239.63	-15.31	0.228	1.210
239.64	-15.26	0.228	1.210
239.64	-15.21	0.228	1.210
239.65	-15.15	0.228	1.210
239.65	-15.10	0.228	1.211
239.66	-15.06	0.228	1.211
239.66	-15.01	0.228	1.211
239.67	-14.95	0.228	1.210
239.67	-14.90	0.228	1.210
239.68	-14.85	0.228	1.210
239.68	-14.80	0.228	1.210
239.69	-14.75	0.227	1.210
239.69	-14.70	0.227	1.210
239.70	-14.65	0.228	1.210
239.70	-14.60	0.228	1.210
239.71	-14.55	0.228	1.210
239.71	-14.50	0.227	1.210
239.72	-14.45	0.227	1.210
239.72	-14.40	0.227	1.210
239.73	-14.35	0.227	1.210
239.73	-14.30	0.227	1.209
239.74	-14.25	0.227	1.209
239.74	-14.20	0.227	1.209
239.75	-14.15	0.227	1.210
239.75	-14.10	0.227	1.210
239.76	-14.05	0.227	1.210
239.76	-14.00	0.227	1.209
239.77	-13.95	0.227	1.209
239.77	-13.90	0.227	1.210
239.78	-13.85	0.227	1.210
239.78	-13.80	0.227	1.210
239.79	-13.75	0.227	1.210
239.79	-13.70	0.227	1.210
239.80	-13.65	0.227	1.210
239.80	-13.60	0.227	1.210
239.81	-13.55	0.227	1.210
239.81	-13.50	0.227	1.210
239.82	-13.45	0.227	1.210
239.82	-13.40	0.227	1.210
239.83	-13.35	0.227	1.210
239.83	-13.30	0.227	1.210
239.84	-13.25	0.227	1.211
239.84	-13.20	0.227	1.211
239.85	-13.15	0.227	1.211
239.85	-13.10	0.227	1.211
239.86	-13.05	0.227	1.210
239.86	-13.00	0.227	1.210
239.87	-12.95	0.227	1.211
239.87	-12.90	0.227	1.211
239.88	-12.85	0.227	1.211
239.88	-12.80	0.227	1.211
239.89	-12.75	0.227	1.211
239.89	-12.70	0.227	1.211
239.90	-12.65	0.227	1.211
239.90	-12.60	0.227	1.211
239.91	-12.55	0.227	1.211
239.91	-12.50	0.227	1.211
239.92	-12.45	0.227	1.211
239.92	-12.40	0.227	1.211
239.93	-12.35	0.227	1.211
239.93	-12.30	0.227	1.212
239.94	-12.25	0.227	1.212
239.94	-12.20	0.227	1.212
239.95	-12.15	0.227	1.212
239.95	-12.10	0.228	1.212
239.96	-12.05	0.228	1.212
239.96	-12.00	0.228	1.212
239.97	-11.95	0.228	1.212
239.97	-11.90	0.228	1.212
239.98	-11.85	0.228	1.212
239.98	-11.80	0.228	1.212
239.99	-11.75	0.228	1.212
239.99	-11.70	0.228	1.212
240.00	-11.65	0.228	1.212
240.00	-11.60	0.228	1.212
240.01	-11.55	0.228	1.212
240.01	-11.50	0.228	1.212
240.02	-11.45	0.228	1.212
240.02	-11.40	0.228	1.212
240.03	-11.35	0.228	1.212
240.03	-11.30	0.228	1.213
240.04	-11.25	0.228	1.212
240.04	-11.20	0.228	1.212
240.05	-11.15	0.228	1.212
240.05	-11.10	0.228	1.212
240.06	-11.05	0.228	1.212
240.06	-11.00	0.228	1.213
240.07	-10.95	0.228	1.213
240.07	-10.90	0.228	1.213
240.08	-10.85	0.228	1.213
240.08	-10.80	0.228	1.213
240.09	-10.75	0.228	1.213
240.09	-10.70	0.228	1.213
240.10	-10.65	0.228	1.213
240.10	-10.60	0.228	1.213
240.11	-10.55	0.228	1.213
240.11	-10.50	0.228	1.213
240.12	-10.45	0.228	1.214
240.12	-10.40	0.228	1.213
240.13	-10.35	0.228	1.213
240.13	-10.30	0.228	1.213
240.14	-10.25	0.228	1.214
240.14	-10.20	0.228	1.214
240.15	-10.15	0.228	1.214
240.15	-10.10	0.228	1.214
240.16	-10.05	0.228	1.214
240.16	-10.00	0.228	1.214
240.17	-9.95	0.228	1.214
240.17	-9.90	0.228	1.214
240.18	-9.85	0.228	1.214
240.18	-9.80	0.228	1.214
240.19	-9.75	0.228	1.214
240.19	-9.70	0.228	1.214
240.20	-9.65	0.228	1.214
240.20	-9.60	0.228	1.215
240.21	-9.55	0.228	1.214
240.21	-9.50	0.228	1.214
240.22	-9.45	0.228	1.214
240.22	-9.40	0.228	1.214
240.23	-9.35	0.228	1.214
240.23	-9.29	0.228	1.214
240.24	-9.25	0.228	1.214
240.24	-9.20	0.228	1.214
240.25	-9.14	0.228	1.215
240.25	-9.10	0.228	1.215
240.26	-9.05	0.228	1.214
240.26	-9.00	0.228	1.214
240.27	-8.95	0.228	1.214
240.27	-8.90	0.228	1.214
240.28	-8.85	0.228	1.214
240.28	-8.80	0.228	1.214
240.29	-8.74	0.228	1.214
240.29	-8.70	0.228	1.214
240.30	-8.64	0.228	1.214
240.30	-8.59	0.228	1.214
240.31	-8.54	0.228	1.215
240.31	-8.49	0.228	1.215
240.32	-8.44	0.228	1.214
240.32	-8.39	0.228	1.215
240.33	-8.34	0.228	1.215
240.33	-8.29	0.228	1.214
240.34	-8.24	0.228	1.214
240.34	-8.19	0.228	1.214
240.35	-8.14	0.228	1.214
240.35	-8.09	0.228	1.214
240.36	-8.04	0.228	1.214
240.36	-7.99	0.228	1.214
240.37	-7.94	0.228	1.214
240.37	-7.89	0.228	1.214
240.38	-7.84	0.228	1.214
240.38	-7.79	0.228	1.214
240.39	-7.74	0.228	1.214
240.39	-7.69	0.228	1.213
240.40	-7.64	0.228	1.213
240.40	-7.59	0.228	1.213
240.41	-7.54	0.228	1.213
240.41	-7.49	0.228	1.213
240.42	-7.44	0.228	1.213
240.42	-7.39	0.227	1.213
240.43	-7.34	0.227	1.213
240.43	-7.29	0.227	1.213
240.44	-7.24	0.227	1.213
240.44	-7.19	0.227	1.213
240.45	-7.14	0.227	1.213
240.45	-7.09	0.227	1.213
240.46	-7.04	0.227	1.213
240.46	-6.99	0.227	1.213
240.47	-6.94	0.227	1.213
240.47	-6.89	0.227	1.212
240.48	-6.84	0.227	1.212
240.48	-6.79	0.227	1.213
240.49	-6.74	0.227	1.213
240.49	-6.69	0.227	1.212
240.50	-6.64	0.227	1.212
240.50	-6.59	0.227	1.212
240.51	-6.54	0.227	1.212
240.51	-6.49	0.227	1.211
240.52	-6.44	0.227	1.211
240.52	-6.39	0.227	1.211
240.53	-6.34	0.227	1.211
240.53	-6.29	0.227	1.211
240.54	-6.24	0.227	1.211
240.54	-6.19	0.227	1.211
240.55	-6.14	0.227	1.210
240.55	-6.09	0.227	1.210
240.56	-6.04	0.227	1.210
240.56	-5.99	0.227	1.210
240.57	-5.94	0.227	1.210
240.57	-5.89	0.227	1.209
240.58	-5.84	0.227	1.209
240.58	-5.79	0.227	1.209
240.59	-5.74	0.227	1.209
240.59	-5.69	0.226	1.209
240.60	-5.64	0.226	1.209
240.60	-5.59	0.226	1.208
240.61	-5.54	0.226	1.208
240.61	-5.49	0.226	1.208
240.62	-5.44	0.226	1.208
240.62	-5.39	0.226	1.207
240.63	-5.34	0.226	1.207
240.63	-5.29	0.226	1.207
240.64	-5.24	0.226	1.206
240.64	-5.19	0.226	1.206
240.65	-5.14	0.226	1.206
240.65	-5.09	0.226	1.206
240.66	-5.04	0.226	1.205
240.66	-4.99	0.226	1.205
240.67	-4.94	0.226	1.205
240.67	-4.89	0.226	1.205
240.68	-4.83	0.226	1.204
240.68	-4.79	0.226	1.204
240.69	-4.74	0.226	1.204
240.69	-4.69	0.226	1.203
240.70	-4.64	0.225	1.203
240.70	-4.59	0.225	1.203
240.71	-4.54	0.225	1.202
240.71	-4.49	0.225	1.202
240.72	-4.44	0.225	1.202
240.72	-4.39	0.225	1.201
240.73	-4.33	0.225	1.200
240.73	-4.29	0.225	1.199
240.74	-4.23	0.225	1.199
240.74	-4.18	0.225	1.198
240.75	-4.13	0.225	1.198
240.75	-4.08	0.225	1.197
240.76	-4.03	0.224	1.198
240.76	-3.98	0.224	1.197
240.77	-3.93	0.224	1.196
240.77	-3.88	0.224	1.196
240.78	-3.83	0.224	1.196
240.78	-3.78	0.224	1.195
240.79	-3.73	0.224	1.195
240.79	-3.68	0.224	1.194
240.80	-3.63	0.224	1.194
240.80	-3.58	0.224	1.194
240.81	-3.53	0.224	1.193
240.81	-3.48	0.223	1.191
240.82	-3.43	0.223	1.188
240.82	-3.38	0.223	1.188
240.83	-3.33	0.222	1.187
240.83	-3.28	0.222	1.186
240.84	-3.23	0.222	1.186
240.84	-3.18	0.222	1.185
240.85	-3.13	0.222	1.185
240.85	-3.08	0.222	1.184
240.86	-3.03	0.222	1.183
240.86	-2.98	0.222	1.183
240.87	-2.93	0.222	1.182
240.87	-2.88	0.222
240.88	-2.83	0.222
240.88	-2.78	0.221
240.89	-2.73	0.221
240.89	-2.68	0.221
240.90	-2.63	0.221
240.90	-2.58	0.220
240.91	-2.53	0.220
240.91	-2.48	0.220
240.92	-2.43	0.220
240.92	-2.38	0.220
240.93	-2.33	0.220
240.93	-2.28
240.94	-2.23
240.94	-2.18
240.95	-2.13
240.95	-2.08
240.96	-2.03
240.96	-1.98
240.97	-1.93
240.97	-1.88
240.98	-1.83
240.98
240.99