File: DSC/2023_07_01_CBD_Fragility_n50C_100C_SBK.txt
Filename	2023_07_01_CBD_Fragility_n50C_100C_SBK
Instrument name	DSC2A-00468 (192.168.1.100)
Operator	SBK
rundate	7/2/2023
Sample name	2023_07_01_CBD_Fragility_n50C_100C_SBK
proceduresegments	Equilibrate 100.00 °C; Ramp 10.00 °C/min to -50.00 °C; Data Off ; Isothermal 1.0 min; Data On ; Ramp 10.00 °C/min to 100.00 °C; Data Off ; Isothermal 1.0 min; Data On ; Ramp 40.00 °C/min to -50.00 °C; Data Off ; Isothermal 1.0 min; Data On ; Ramp 10.00 °C/min to 100.00 °C; Data Off ; Isothermal 1.0 min; Data On ; Ramp 30.00 °C/min to -50.00 °C; Data Off ; Isothermal 1.0 min; Data On ; Ramp 10.00 °C/min to 100.00 °C; Data Off ; Isothermal 1.0 min; Data On ; Ramp 20.00 °C/min to -50.00 °C; Data Off ; Isothermal 1.0 min; Data On ; Ramp 10.00 °C/min to 100.00 °C; Data Off ; Isothermal 1.0 min; Data On ; Sample Interval  0.2 s/pt; Ramp 5.00 °C/min to -50.00 °C; Data Off ; Isothermal 1.0 min; Data On ; Sample Interval  0.1 s/pt; Ramp 10.00 °C/min to 100.00 °C; Data Off ; Isothermal 1.0 min; Data On ; Sample Interval  1.0 s/pt; Ramp 1.00 °C/min to -50.00 °C; Data Off ; Isothermal 1.0 min; Data On ; Sample Interval  0.1 s/pt; Ramp 10.00 °C/min to 100.00 °C; Data Off ; Isothermal 1.0 min; Data On ; Sample Interval  2.0 s/pt; Ramp 0.50 °C/min to -50.00 °C; Data Off ; Isothermal 1.0 min; Data On ; Sample Interval  0.1 s/pt; Ramp 10.00 °C/min to 100.00 °C; Data Off ; Isothermal 1.0 min; Data On ; Sample Interval  10.0 s/pt; Ramp 0.10 °C/min to -50.00 °C; Data Off ; Isothermal 1.0 min; Data On ; Sample Interval  0.1 s/pt; Ramp 10.00 °C/min to 100.00 °C
[File Parameters]
Run date	7/2/2023 10:30:34 AM
Trios version	5.1.1.46572
Original File Name	C:\Users\yargerlab\Desktop\DSC Data\General\2023_07_01_CBD_Fragility_n50C_100C_SBK.tri
Current File Name	C:\Users\kauff\Documents\ASU\data_DSC\2023_07_01_CBD_Fragility_n50C_100C_SBK.tri
[Procedure]
Procedure Name	DSC -50C to 100C Varied cooling rates (40 - 0.1 cpm) cannabinoid fragility
Sample Name	2023_07_01_CBD_Fragility_n50C_100C_SBK
Sample Mass	3.95 mg
Reference Sample Mass	0 mg
Pan Mass	53.51 mg
Pan Number	41
Reference Pan Mass	53.66 mg
Reference Pan Number	46
Pan Type	Aluminum Hermetic
Comments	CBD crystalline powder. DSC84010 aluminum pan and DSC84011 aluminum hermetic lid. Wider temperature range to ensure full melting. Wider range of temperature scan rates.
Project Name	Silk ASDs
Operator	SBK
Test	Custom
Unload Max Temperature	30
Unload Min Temperature	30
Load Max Temperature	30
Load Min Temperature	30
Stop on Gas Flow Error	Yes
[Signal List]
Signal #1	Time (min)
Signal #2	Temperature (°C)
Signal #3	Heat Flow (mW)
Signal #4	Delta T (µV)
Signal #5	Delta Tzero (µV)
Signal #6	Tzero Temperature (°C)
Signal #7	Cell Purge (mL/min)
Signal #8	Heater Temp (°C)
Signal #9	Power Delivered (W)
Signal #10	Reference Junction Temperature (°C)
Signal #11	Flange Temperature (°C)
Signal #12	Heat Flow Phase (rad)
Signal #13	Total Heat Capacity (J/°C)
Signal #14	Heat Capacity (J/°C)
[Configuration]
Company Name	ASU
Instrument Name	DSC2A-00468
Instrument Type	DSC2500
Serial Number	DSC2A-00468
IP	192.168.1.100
Location of Instrument	MRRC
DisplayType	Unknown
Sample Interval 	0.1 s/pt
Selected Heat Flow	T4P
Exotherm Direction	Down
Cell Serial	DRC2-00792
Lid Type	Standard
Cooler	RCS 90
Leave Cooler on at End of Sequence	On
Gas 2	Nitrogen
Gas Selected	Channel 1
Flow Rate	50 mL/min
Secondary Purge	On
Licensed Heat Flow	Heat Flow T4P
Modulation Licensed	Yes
[Versions]
Common IDD Version	1
Cortex Version	VER 2.10.2.31
Driver	5.0.0.6
GDM Version	1.0.3.3
TouchscreenVersion	1.0.0.16145
FEP Version	1.2.1.21
FEP Bootloader	2.0.0.5
AutoSampler Version	2.1.1.26
Auto Sampler Bootloader	2.0.0.5
FCM Version	1.1.0.3
FCM Bootloader	2.0.0.5
[Experiment Logs]
Experiment Log Entry # 1	Equilibrate Segment 100 (C) Started
Experiment Log Entry # 3	Air Cool is off.
Experiment Log Entry # 5	Ramp Segment 10 C/min to -50 Started
Experiment Log Entry # 7	Data On set to 0
Experiment Log Entry # 9	Isothermal Segment 1 min started
Experiment Log Entry # 11	Data On set to 1
Experiment Log Entry # 13	Ramp Segment 10 C/min to 100 Started
Experiment Log Entry # 15	Data On set to 0
Experiment Log Entry # 17	Isothermal Segment 1 min started
Experiment Log Entry # 19	Data On set to 1
Experiment Log Entry # 21	Ramp Segment 40 C/min to -50 Started
Experiment Log Entry # 23	Data On set to 0
Experiment Log Entry # 25	Isothermal Segment 1 min started
Experiment Log Entry # 27	Data On set to 1
Experiment Log Entry # 29	Ramp Segment 10 C/min to 100 Started
Experiment Log Entry # 31	Data On set to 0
Experiment Log Entry # 33	Isothermal Segment 1 min started
Experiment Log Entry # 35	Data On set to 1
Experiment Log Entry # 37	Ramp Segment 30 C/min to -50 Started
Experiment Log Entry # 39	Data On set to 0
Experiment Log Entry # 41	Isothermal Segment 1 min started
Experiment Log Entry # 43	Data On set to 1
Experiment Log Entry # 45	Ramp Segment 10 C/min to 100 Started
Experiment Log Entry # 47	Data On set to 0
Experiment Log Entry # 49	Isothermal Segment 1 min started
Experiment Log Entry # 51	Data On set to 1
Experiment Log Entry # 53	Ramp Segment 20 C/min to -50 Started
Experiment Log Entry # 55	Data On set to 0
Experiment Log Entry # 57	Isothermal Segment 1 min started
Experiment Log Entry # 59	Data On set to 1
Experiment Log Entry # 61	Ramp Segment 10 C/min to 100 Started
Experiment Log Entry # 63	Data On set to 0
Experiment Log Entry # 65	Isothermal Segment 1 min started
Experiment Log Entry # 67	Data On set to 1
Experiment Log Entry # 69	Sampling Rate set to 0.2 sec/pt
Experiment Log Entry # 71	Ramp Segment 5 C/min to -50 Started
Experiment Log Entry # 73	Data On set to 0
Experiment Log Entry # 75	Isothermal Segment 1 min started
Experiment Log Entry # 77	Data On set to 1
Experiment Log Entry # 79	Sampling Rate set to 0.1 sec/pt
Experiment Log Entry # 81	Ramp Segment 10 C/min to 100 Started
Experiment Log Entry # 83	Data On set to 0
Experiment Log Entry # 85	Isothermal Segment 1 min started
Experiment Log Entry # 87	Data On set to 1
Experiment Log Entry # 89	Sampling Rate set to 1 sec/pt
Experiment Log Entry # 91	Ramp Segment 1 C/min to -50 Started
Experiment Log Entry # 93	Data On set to 0
Experiment Log Entry # 95	Isothermal Segment 1 min started
Experiment Log Entry # 97	Data On set to 1
Experiment Log Entry # 99	Sampling Rate set to 0.1 sec/pt
Experiment Log Entry # 101	Ramp Segment 10 C/min to 100 Started
Experiment Log Entry # 103	Data On set to 0
Experiment Log Entry # 105	Isothermal Segment 1 min started
Experiment Log Entry # 107	Data On set to 1
Experiment Log Entry # 109	Sampling Rate set to 2 sec/pt
Experiment Log Entry # 111	Ramp Segment 0.5 C/min to -50 Started
Experiment Log Entry # 113	Data On set to 0
Experiment Log Entry # 115	Isothermal Segment 1 min started
Experiment Log Entry # 117	Data On set to 1
Experiment Log Entry # 119	Sampling Rate set to 0.1 sec/pt
Experiment Log Entry # 121	Ramp Segment 10 C/min to 100 Started
Experiment Log Entry # 123	Auto sampler has detected that FEP has gone offline
Experiment Log Entry # 125	Data On set to 0
Experiment Log Entry # 127	Isothermal Segment 1 min started
Experiment Log Entry # 129	Data On set to 1
Experiment Log Entry # 131	Sampling Rate set to 10 sec/pt
Experiment Log Entry # 133	Ramp Segment 0.1 C/min to -50 Started
Experiment Log Entry # 135	Auto sampler has detected that FCM has gone offline
Experiment Log Entry # 137	Data On set to 0
Experiment Log Entry # 139	Isothermal Segment 1 min started
Experiment Log Entry # 141	Data On set to 1
Experiment Log Entry # 143	Sampling Rate set to 0.1 sec/pt
Experiment Log Entry # 145	Ramp Segment 10 C/min to 100 Started
[Method Log]
Method Log Entry # 1	Equilibrate 100 °C
Method Log Entry # 2	(Ramp 345815) Ramp 10 °C/minute to -50 °C
Method Log Entry # 3	Data Off
Method Log Entry # 4	Isothermal 1 minutes
Method Log Entry # 5	Data On
Method Log Entry # 6	(Ramp 345819) Ramp 10 °C/minute to 100 °C
Method Log Entry # 7	Data Off
Method Log Entry # 8	Isothermal 1 minutes
Method Log Entry # 9	Data On
Method Log Entry # 10	(Ramp 345823) Ramp 40 °C/minute to -50 °C
Method Log Entry # 11	Data Off
Method Log Entry # 12	Isothermal 1 minutes
Method Log Entry # 13	Data On
Method Log Entry # 14	(Ramp 345827) Ramp 10 °C/minute to 100 °C
Method Log Entry # 15	Data Off
Method Log Entry # 16	Isothermal 1 minutes
Method Log Entry # 17	Data On
Method Log Entry # 18	(Ramp 345831) Ramp 30 °C/minute to -50 °C
Method Log Entry # 19	Data Off
Method Log Entry # 20	Isothermal 1 minutes
Method Log Entry # 21	Data On
Method Log Entry # 22	(Ramp 345835) Ramp 10 °C/minute to 100 °C
Method Log Entry # 23	Data Off
Method Log Entry # 24	Isothermal 1 minutes
Method Log Entry # 25	Data On
Method Log Entry # 26	(Ramp 345839) Ramp 20 °C/minute to -50 °C
Method Log Entry # 27	Data Off
Method Log Entry # 28	Isothermal 1 minutes
Method Log Entry # 29	Data On
Method Log Entry # 30	(Ramp 345843) Ramp 10 °C/minute to 100 °C
Method Log Entry # 31	Data Off
Method Log Entry # 32	Isothermal 1 minutes
Method Log Entry # 33	Data On
Method Log Entry # 34	Sampling Interval 0.2 Seconds/point
Method Log Entry # 35	(Ramp 345848) Ramp 5 °C/minute to -50 °C
Method Log Entry # 36	Data Off
Method Log Entry # 37	Isothermal 1 minutes
Method Log Entry # 38	Data On
Method Log Entry # 39	Sampling Interval 0.1 Seconds/point
Method Log Entry # 40	(Ramp 345853) Ramp 10 °C/minute to 100 °C
Method Log Entry # 41	Data Off
Method Log Entry # 42	Isothermal 1 minutes
Method Log Entry # 43	Data On
Method Log Entry # 44	Sampling Interval 1 Seconds/point
Method Log Entry # 45	(Ramp 345858) Ramp 1 °C/minute to -50 °C
Method Log Entry # 46	Data Off
Method Log Entry # 47	Isothermal 1 minutes
Method Log Entry # 48	Data On
Method Log Entry # 49	Sampling Interval 0.1 Seconds/point
Method Log Entry # 50	(Ramp 345863) Ramp 10 °C/minute to 100 °C
Method Log Entry # 51	Data Off
Method Log Entry # 52	Isothermal 1 minutes
Method Log Entry # 53	Data On
Method Log Entry # 54	Sampling Interval 2 Seconds/point
Method Log Entry # 55	(Ramp 345868) Ramp 0.5 °C/minute to -50 °C
Method Log Entry # 56	Data Off
Method Log Entry # 57	Isothermal 1 minutes
Method Log Entry # 58	Data On
Method Log Entry # 59	Sampling Interval 0.1 Seconds/point
Method Log Entry # 60	(Ramp 345873) Ramp 10 °C/minute to 100 °C
Method Log Entry # 61	Data Off
Method Log Entry # 62	Isothermal 1 minutes
Method Log Entry # 63	Data On
Method Log Entry # 64	Sampling Interval 10 Seconds/point
Method Log Entry # 65	(Ramp 345878) Ramp 0.1 °C/minute to -50 °C
Method Log Entry # 66	Data Off
Method Log Entry # 67	Isothermal 1 minutes
Method Log Entry # 68	Data On
Method Log Entry # 69	Sampling Interval 0.1 Seconds/point
Method Log Entry # 70	(Ramp 345883) Ramp 10 °C/minute to 100 °C
Cell Serial	DRC2-00792
[T1 Calibration]
Slope	-0.008529666
Offset	9.636258
Initial Temperature	98.23
GUID	f8bfdadc-4977-4fdf-ba6d-0ba9134940c3
[TZero Calibration]
Date Applied	11/29/2022 4:06:13 PM
Description	From -89.059 °C to 396.009 °C at 20.000°C/min
Gas Type	Nitrogen
Pan Type	None
Source Files 1	C:\Users\yargerlab\Desktop\DSC Data\General\TZero_calibration_11_29_22_2nd(2).tri
Source Files 2	C:\Users\yargerlab\Desktop\DSC Data\General\TZero_calibration_11_29_22_2nd(3).tri
Delta T Offset	13.05235
Delta T Slope	-0.007271007
Delta T0 Offset	-13.69128
Delta T0 Slope	0.06063341
[Temperature Calibration]
Date Applied	11/29/2022 7:12:28 PM
Description	From 106.590 °C to 186.590 °C at 10.000°C/min
Gas Type	Nitrogen
Pan Type	Tzero Aluminum Hermetic
Source Files 1	C:\Users\yargerlab\Desktop\DSC Data\General\Indium(6).tri
Measured 1	157.391
Known 1	156.598
[Cell Constant Calibration]
Date Applied	11/29/2022 7:12:29 PM
Description	From 106.590 °C to 186.590 °C at 10.000°C/min
Gas Type	Nitrogen
Pan Type	Tzero Aluminum Hermetic
Source Files 1	C:\Users\yargerlab\Desktop\DSC Data\General\Indium(6).tri
T4P KCell	1.006051
Onset Slope	63.26126 mW/°C
[Direct Cp Calibration]
Date Applied	11/30/2022 11:04:51 AM
Description	From -79.983 °C to 298.409 °C at 10.000°C/min
Gas Type	Nitrogen
Pan Type	Tzero Aluminum Hermetic
Source Files 1	C:\Users\yargerlab\Desktop\DSC Data\General\Sapphire_Heat_Capacity_11_30_22.tri
[Rev Cp Calibration]
Date Applied	11/30/2022 1:58:51 PM
Description	From -79.996 °C to 292.812 °C at 3.000°C/min
Gas Type	Nitrogen
Pan Type	Tzero Aluminum Hermetic
Source Files 1	C:\Users\yargerlab\Desktop\DSC Data\General\Sapphire_MDSC_Calibration_11_30_22.tri
[step]
Ramp 10.00 °C/min to -50.00 °C
Time	Temperature	Heat Flow (Normalized)	Heat Capacity (Normalized)
min	°C	W/g	J/(g.°C)
0.00	100.10	-0.023	0.000
0.01	100.10	-0.029	0.000
0.02	100.10	-0.031	0.000
0.03	100.10	-0.035	0.000
0.05	100.10	-0.040	0.000
0.06	100.09	-0.053	1.473
0.07	100.08	-0.069	1.569
0.08	100.05	-0.091	1.748
0.09	100.03	-0.118	1.942
0.11	99.99	-0.148	2.133
0.12	99.94	-0.179	2.291
0.13	99.88	-0.211	2.424
0.14	99.82	-0.240	2.510
0.15	99.74	-0.268	2.563
0.16	99.67	-0.292	2.579
0.18	99.58	-0.312	2.577
0.19	99.50	-0.333	2.589
0.20	99.41	-0.348	2.574
0.21	99.32	-0.362	2.562
0.22	99.23	-0.376	2.567
0.23	99.13	-0.388	2.575
0.24	99.03	-0.397	2.568
0.26	98.93	-0.408	2.585
0.27	98.83	-0.416	2.584
0.28	98.73	-0.424	2.596
0.29	98.63	-0.431	2.596
0.30	98.52	-0.436	2.600
0.31	98.41	-0.443	2.608
0.33	98.31	-0.448	2.614
0.34	98.20	-0.453	2.617
0.35	98.09	-0.455	2.609
0.36	97.98	-0.458	2.610
0.37	97.87	-0.461	2.610
0.39	97.76	-0.464	2.612
0.40	97.65	-0.466	2.610
0.41	97.54	-0.468	2.615
0.42	97.42	-0.469	2.611
0.43	97.31	-0.472	2.616
0.44	97.20	-0.472	2.611
0.45	97.09	-0.473	2.609
0.47	96.97	-0.474	2.609
0.48	96.86	-0.476	2.612
0.49	96.74	-0.476	2.609
0.50	96.63	-0.476	2.606
0.51	96.52	-0.477	2.605
0.53	96.40	-0.477	2.605
0.54	96.29	-0.478	2.602
0.55	96.17	-0.478	2.601
0.56	96.06	-0.478	2.600
0.57	95.94	-0.478	2.599
0.58	95.83	-0.479	2.598
0.60	95.72	-0.479	2.598
0.61	95.60	-0.479	2.598
0.62	95.49	-0.479	2.596
0.63	95.37	-0.480	2.596
0.64	95.26	-0.480	2.596
0.65	95.14	-0.480	2.595
0.67	95.03	-0.480	2.595
0.68	94.91	-0.480	2.594
0.69	94.80	-0.481	2.594
0.70	94.68	-0.481	2.594
0.71	94.56	-0.481	2.594
0.72	94.45	-0.481	2.594
0.73	94.33	-0.481	2.594
0.75	94.22	-0.481	2.594
0.76	94.10	-0.482	2.594
0.77	93.99	-0.482	2.593
0.78	93.87	-0.482	2.594
0.79	93.75	-0.482	2.593
0.80	93.64	-0.482	2.592
0.82	93.52	-0.482	2.593
0.83	93.41	-0.482	2.594
0.84	93.29	-0.482	2.592
0.85	93.18	-0.482	2.592
0.86	93.06	-0.482	2.592
0.88	92.94	-0.482	2.592
0.89	92.83	-0.482	2.592
0.90	92.71	-0.482	2.591
0.91	92.60	-0.482	2.591
0.92	92.48	-0.482	2.591
0.93	92.36	-0.482	2.591
0.95	92.25	-0.482	2.590
0.96	92.13	-0.482	2.590
0.97	92.02	-0.482	2.590
0.98	91.90	-0.482	2.588
0.99	91.78	-0.482	2.588
1.00	91.67	-0.482	2.588
1.02	91.55	-0.482	2.587
1.03	91.44	-0.482	2.585
1.04	91.32	-0.482	2.586
1.05	91.20	-0.482	2.585
1.06	91.09	-0.482	2.585
1.07	90.97	-0.482	2.584
1.08	90.86	-0.482	2.583
1.10	90.74	-0.482	2.583
1.11	90.62	-0.482	2.582
1.12	90.51	-0.481	2.580
1.13	90.39	-0.481	2.580
1.14	90.28	-0.481	2.579
1.16	90.16	-0.481	2.577
1.17	90.04	-0.481	2.576
1.18	89.93	-0.481	2.576
1.19	89.81	-0.481	2.575
1.20	89.69	-0.481	2.574
1.21	89.58	-0.480	2.573
1.23	89.46	-0.480	2.573
1.24	89.34	-0.480	2.572
1.25	89.23	-0.480	2.571
1.26	89.11	-0.480	2.569
1.27	89.00	-0.480	2.569
1.28	88.88	-0.480	2.568
1.29	88.76	-0.479	2.567
1.31	88.65	-0.479	2.566
1.32	88.53	-0.479	2.565
1.33	88.41	-0.479	2.564
1.34	88.30	-0.479	2.564
1.35	88.18	-0.479	2.563
1.37	88.07	-0.478	2.561
1.38	87.95	-0.478	2.561
1.39	87.83	-0.478	2.559
1.40	87.72	-0.478	2.558
1.41	87.60	-0.478	2.558
1.42	87.48	-0.478	2.557
1.43	87.37	-0.477	2.557
1.45	87.25	-0.477	2.555
1.46	87.13	-0.477	2.554
1.47	87.02	-0.477	2.553
1.48	86.90	-0.477	2.552
1.49	86.78	-0.477	2.550
1.51	86.67	-0.476	2.550
1.52	86.55	-0.476	2.549
1.53	86.44	-0.476	2.548
1.54	86.32	-0.476	2.546
1.55	86.20	-0.476	2.546
1.56	86.09	-0.476	2.545
1.58	85.97	-0.476	2.544
1.59	85.85	-0.475	2.543
1.60	85.74	-0.475	2.542
1.61	85.62	-0.475	2.541
1.62	85.50	-0.475	2.540
1.63	85.39	-0.475	2.539
1.64	85.27	-0.475	2.538
1.66	85.15	-0.475	2.538
1.67	85.04	-0.474	2.536
1.68	84.92	-0.474	2.536
1.69	84.81	-0.474	2.535
1.70	84.69	-0.474	2.534
1.72	84.57	-0.474	2.534
1.73	84.46	-0.474	2.532
1.74	84.34	-0.473	2.532
1.75	84.22	-0.473	2.532
1.76	84.11	-0.473	2.531
1.77	83.99	-0.473	2.530
1.78	83.87	-0.473	2.529
1.80	83.76	-0.473	2.528
1.81	83.64	-0.473	2.527
1.82	83.52	-0.472	2.526
1.83	83.41	-0.472	2.526
1.84	83.29	-0.472	2.525
1.86	83.17	-0.472	2.523
1.87	83.06	-0.472	2.524
1.88	82.94	-0.472	2.522
1.89	82.83	-0.472	2.521
1.90	82.71	-0.472	2.520
1.91	82.59	-0.471	2.520
1.93	82.48	-0.471	2.520
1.94	82.36	-0.471	2.518
1.95	82.24	-0.471	2.517
1.96	82.13	-0.471	2.516
1.97	82.01	-0.471	2.515
1.98	81.89	-0.471	2.516
1.99	81.78	-0.471	2.514
2.01	81.66	-0.470	2.514
2.02	81.54	-0.470	2.514
2.03	81.43	-0.470	2.512
2.04	81.31	-0.470	2.511
2.05	81.19	-0.470	2.511
2.07	81.08	-0.470	2.510
2.08	80.96	-0.470	2.510
2.09	80.84	-0.469	2.507
2.10	80.73	-0.469	2.506
2.11	80.61	-0.469	2.506
2.12	80.50	-0.469	2.506
2.14	80.38	-0.469	2.505
2.15	80.26	-0.469	2.505
2.16	80.15	-0.469	2.505
2.17	80.03	-0.468	2.503
2.18	79.91	-0.468	2.503
2.19	79.80	-0.468	2.501
2.21	79.68	-0.468	2.501
2.22	79.56	-0.468	2.499
2.23	79.45	-0.468	2.499
2.24	79.33	-0.468	2.498
2.25	79.21	-0.468	2.497
2.26	79.10	-0.467	2.497
2.28	78.98	-0.467	2.496
2.29	78.86	-0.467	2.494
2.30	78.75	-0.467	2.495
2.31	78.63	-0.467	2.493
2.32	78.51	-0.467	2.492
2.33	78.40	-0.467	2.491
2.34	78.28	-0.466	2.490
2.36	78.16	-0.466	2.488
2.37	78.05	-0.466	2.488
2.38	77.93	-0.466	2.488
2.39	77.81	-0.466	2.487
2.40	77.70	-0.466	2.486
2.41	77.58	-0.466	2.486
2.43	77.46	-0.465	2.485
2.44	77.35	-0.465	2.485
2.45	77.23	-0.465	2.485
2.46	77.11	-0.465	2.483
2.47	77.00	-0.465	2.482
2.49	76.88	-0.465	2.483
2.50	76.76	-0.465	2.482
2.51	76.65	-0.464	2.481
2.52	76.53	-0.464	2.480
2.53	76.42	-0.464	2.479
2.54	76.30	-0.464	2.478
2.56	76.18	-0.464	2.478
2.57	76.07	-0.464	2.477
2.58	75.95	-0.464	2.476
2.59	75.83	-0.464	2.475
2.60	75.72	-0.463	2.476
2.61	75.60	-0.463	2.474
2.63	75.48	-0.463	2.474
2.64	75.37	-0.463	2.471
2.65	75.25	-0.463	2.471
2.66	75.13	-0.463	2.471
2.67	75.02	-0.462	2.470
2.68	74.90	-0.462	2.468
2.69	74.78	-0.462	2.467
2.71	74.67	-0.462	2.466
2.72	74.55	-0.462	2.465
2.73	74.43	-0.462	2.465
2.74	74.32	-0.462	2.464
2.75	74.20	-0.461	2.463
2.76	74.08	-0.461	2.463
2.78	73.97	-0.461	2.461
2.79	73.85	-0.461	2.461
2.80	73.73	-0.461	2.460
2.81	73.62	-0.461	2.459
2.82	73.50	-0.461	2.459
2.84	73.38	-0.461	2.459
2.85	73.27	-0.460	2.458
2.86	73.15	-0.460	2.457
2.87	73.03	-0.460	2.456
2.88	72.92	-0.460	2.455
2.89	72.80	-0.460	2.454
2.91	72.68	-0.460	2.454
2.92	72.57	-0.459	2.449
2.93	72.45	-0.459	2.449
2.94	72.34	-0.459	2.449
2.95	72.22	-0.458	2.448
2.96	72.10	-0.458	2.447
2.98	71.99	-0.458	2.447
2.99	71.87	-0.458	2.447
3.00	71.75	-0.458	2.446
3.01	71.64	-0.458	2.445
3.02	71.52	-0.458	2.444
3.03	71.40	-0.458	2.444
3.04	71.29	-0.457	2.443
3.06	71.17	-0.457	2.442
3.07	71.05	-0.457	2.442
3.08	70.94	-0.457	2.441
3.09	70.82	-0.457	2.441
3.10	70.70	-0.457	2.440
3.11	70.59	-0.457	2.439
3.13	70.47	-0.457	2.438
3.14	70.35	-0.456	2.437
3.15	70.24	-0.456	2.437
3.16	70.12	-0.456	2.436
3.17	70.00	-0.456	2.435
3.19	69.89	-0.456	2.435
3.20	69.77	-0.456	2.434
3.21	69.65	-0.456	2.434
3.22	69.54	-0.456	2.433
3.23	69.42	-0.455	2.432
3.24	69.30	-0.455	2.431
3.26	69.19	-0.455	2.430
3.27	69.07	-0.455	2.429
3.28	68.95	-0.455	2.429
3.29	68.84	-0.455	2.428
3.30	68.72	-0.455	2.427
3.31	68.60	-0.454	2.426
3.33	68.49	-0.454	2.427
3.34	68.37	-0.454	2.425
3.35	68.26	-0.454	2.425
3.36	68.14	-0.454	2.425
3.37	68.02	-0.454	2.423
3.38	67.90	-0.454	2.423
3.39	67.79	-0.453	2.422
3.41	67.67	-0.453	2.421
3.42	67.56	-0.453	2.421
3.43	67.44	-0.453	2.420
3.44	67.32	-0.453	2.420
3.45	67.21	-0.453	2.418
3.46	67.09	-0.453	2.418
3.48	66.97	-0.452	2.417
3.49	66.86	-0.452	2.417
3.50	66.74	-0.452	2.416
3.51	66.62	-0.452	2.416
3.52	66.51	-0.452	2.415
3.54	66.39	-0.452	2.413
3.55	66.27	-0.452	2.412
3.56	66.16	-0.452	2.413
3.57	66.04	-0.451	2.412
3.58	65.92	-0.451	2.412
3.59	65.81	-0.451	2.412
3.61	65.69	-0.451	2.410
3.62	65.57	-0.451	2.410
3.63	65.46	-0.451	2.409
3.64	65.34	-0.451	2.408
3.65	65.23	-0.451	2.408
3.66	65.11	-0.450	2.408
3.68	64.99	-0.450	2.407
3.69	64.88	-0.450	2.406
3.70	64.76	-0.450	2.405
3.71	64.64	-0.450	2.404
3.72	64.53	-0.450	2.404
3.73	64.41	-0.450	2.403
3.74	64.29	-0.450	2.404
3.76	64.18	-0.449	2.402
3.77	64.06	-0.449	2.402
3.78	63.94	-0.449	2.400
3.79	63.83	-0.449	2.398
3.80	63.71	-0.449	2.398
3.81	63.59	-0.449	2.398
3.83	63.48	-0.449	2.398
3.84	63.36	-0.448	2.397
3.85	63.24	-0.448	2.396
3.86	63.13	-0.448	2.395
3.87	63.01	-0.448	2.394
3.89	62.89	-0.448	2.393
3.90	62.78	-0.448	2.393
3.91	62.66	-0.448	2.393
3.92	62.54	-0.448	2.392
3.93	62.43	-0.447	2.389
3.94	62.31	-0.447	2.389
3.96	62.20	-0.447	2.388
3.97	62.08	-0.447	2.388
3.98	61.96	-0.447	2.387
3.99	61.85	-0.447	2.387
4.00	61.73	-0.446	2.387
4.01	61.61	-0.446	2.386
4.03	61.50	-0.446	2.384
4.04	61.38	-0.446	2.385
4.05	61.26	-0.446	2.384
4.06	61.15	-0.446	2.383
4.07	61.03	-0.446	2.382
4.08	60.91	-0.446	2.382
4.09	60.80	-0.445	2.381
4.11	60.68	-0.445	2.380
4.12	60.56	-0.445	2.380
4.13	60.45	-0.445	2.380
4.14	60.33	-0.445	2.379
4.15	60.22	-0.445	2.378
4.16	60.10	-0.445	2.377
4.18	59.98	-0.445	2.377
4.19	59.86	-0.444	2.376
4.20	59.75	-0.444	2.375
4.21	59.63	-0.444	2.374
4.22	59.51	-0.444	2.375
4.24	59.40	-0.444	2.373
4.25	59.28	-0.444	2.372
4.26	59.17	-0.444	2.371
4.27	59.05	-0.444	2.371
4.28	58.93	-0.443	2.370
4.29	58.82	-0.443	2.370
4.30	58.70	-0.443	2.369
4.32	58.58	-0.443	2.369
4.33	58.47	-0.443	2.367
4.34	58.35	-0.443	2.366
4.35	58.23	-0.443	2.366
4.36	58.12	-0.442	2.365
4.38	58.00	-0.442	2.364
4.39	57.88	-0.442	2.364
4.40	57.77	-0.442	2.364
4.41	57.65	-0.442	2.363
4.42	57.53	-0.442	2.360
4.43	57.42	-0.442	2.361
4.45	57.30	-0.442	2.360
4.46	57.18	-0.442	2.360
4.47	57.07	-0.441	2.358
4.48	56.95	-0.441	2.357
4.49	56.83	-0.441	2.356
4.50	56.72	-0.441	2.356
4.51	56.60	-0.441	2.355
4.53	56.48	-0.441	2.354
4.54	56.37	-0.441	2.353
4.55	56.25	-0.441	2.353
4.56	56.13	-0.441	2.353
4.57	56.02	-0.440	2.351
4.59	55.90	-0.440	2.351
4.60	55.78	-0.440	2.350
4.61	55.67	-0.440	2.349
4.62	55.55	-0.440	2.349
4.63	55.44	-0.440	2.348
4.64	55.32	-0.440	2.347
4.65	55.20	-0.439	2.347
4.67	55.09	-0.439	2.346
4.68	54.97	-0.439	2.345
4.69	54.85	-0.439	2.345
4.70	54.74	-0.439	2.343
4.71	54.62	-0.439	2.342
4.73	54.50	-0.439	2.342
4.74	54.39	-0.439	2.341
4.75	54.27	-0.438	2.340
4.76	54.15	-0.438	2.338
4.77	54.04	-0.438	2.338
4.78	53.92	-0.438	2.338
4.80	53.80	-0.438	2.336
4.81	53.69	-0.438	2.336
4.82	53.57	-0.438	2.336
4.83	53.45	-0.438	2.335
4.84	53.34	-0.437	2.334
4.85	53.22	-0.437	2.334
4.86	53.10	-0.437	2.333
4.88	52.99	-0.437	2.333
4.89	52.87	-0.437	2.332
4.90	52.75	-0.437	2.331
4.91	52.64	-0.437	2.330
4.92	52.52	-0.437	2.330
4.94	52.40	-0.436	2.329
4.95	52.29	-0.436	2.329
4.96	52.17	-0.436	2.327
4.97	52.06	-0.436	2.327
4.98	51.94	-0.436	2.326
4.99	51.82	-0.436	2.326
5.00	51.71	-0.436	2.325
5.02	51.59	-0.436	2.323
5.03	51.47	-0.435	2.322
5.04	51.36	-0.435	2.323
5.05	51.24	-0.435	2.322
5.06	51.12	-0.435	2.322
5.08	51.00	-0.435	2.319
5.09	50.89	-0.434	2.315
5.10	50.77	-0.434	2.316
5.11	50.66	-0.434	2.316
5.12	50.54	-0.434	2.314
5.13	50.42	-0.434	2.313
5.15	50.31	-0.434	2.312
5.16	50.19	-0.434	2.313
5.17	50.08	-0.434	2.312
5.18	49.96	-0.433	2.312
5.19	49.84	-0.433	2.309
5.20	49.72	-0.433	2.308
5.21	49.61	-0.433	2.309
5.23	49.49	-0.433	2.309
5.24	49.37	-0.433	2.308
5.25	49.26	-0.432	2.306
5.26	49.14	-0.432	2.304
5.27	49.03	-0.432	2.304
5.29	48.91	-0.432	2.305
5.30	48.79	-0.432	2.304
5.31	48.67	-0.432	2.302
5.32	48.56	-0.432	2.303
5.33	48.44	-0.432	2.302
5.34	48.33	-0.432	2.302
5.35	48.21	-0.431	2.301
5.37	48.09	-0.431	2.300
5.38	47.98	-0.431	2.299
5.39	47.86	-0.431	2.299
5.40	47.74	-0.431	2.299
5.41	47.63	-0.431	2.298
5.43	47.51	-0.431	2.298
5.44	47.39	-0.431	2.297
5.45	47.28	-0.430	2.295
5.46	47.16	-0.430	2.295
5.47	47.04	-0.430	2.295
5.48	46.93	-0.430	2.295
5.50	46.81	-0.430	2.295
5.51	46.69	-0.430	2.293
5.52	46.58	-0.430	2.293
5.53	46.46	-0.430	2.293
5.54	46.34	-0.430	2.292
5.55	46.23	-0.429	2.292
5.56	46.11	-0.429	2.290
5.58	46.00	-0.429	2.290
5.59	45.88	-0.429	2.290
5.60	45.76	-0.429	2.289
5.61	45.64	-0.429	2.288
5.62	45.53	-0.429	2.287
5.64	45.41	-0.429	2.287
5.65	45.30	-0.428	2.287
5.66	45.18	-0.428	2.286
5.67	45.06	-0.428	2.285
5.68	44.95	-0.428	2.284
5.69	44.83	-0.428	2.283
5.70	44.71	-0.428	2.284
5.72	44.60	-0.428	2.284
5.73	44.48	-0.428	2.283
5.74	44.36	-0.427	2.282
5.75	44.25	-0.427	2.281
5.76	44.13	-0.427	2.281
5.78	44.01	-0.427	2.280
5.79	43.90	-0.427	2.280
5.80	43.78	-0.427	2.279
5.81	43.66	-0.427	2.279
5.82	43.55	-0.427	2.278
5.83	43.43	-0.426	2.278
5.85	43.31	-0.426	2.276
5.86	43.20	-0.426	2.275
5.87	43.08	-0.426	2.276
5.88	42.96	-0.426	2.276
5.89	42.85	-0.426	2.275
5.90	42.73	-0.426	2.274
5.91	42.61	-0.426	2.273
5.93	42.50	-0.426	2.272
5.94	42.38	-0.425	2.273
5.95	42.26	-0.425	2.272
5.96	42.15	-0.425	2.272
5.97	42.03	-0.425	2.272
5.99	41.91	-0.425	2.271
6.00	41.80	-0.425	2.269
6.01	41.68	-0.424	2.268
6.02	41.56	-0.424	2.268
6.03	41.45	-0.424	2.267
6.04	41.33	-0.424	2.267
6.05	41.22	-0.424	2.266
6.07	41.10	-0.424	2.266
6.08	40.98	-0.424	2.265
6.09	40.87	-0.423	2.264
6.10	40.75	-0.423	2.263
6.11	40.63	-0.423	2.263
6.13	40.52	-0.423	2.263
6.14	40.40	-0.423	2.260
6.15	40.28	-0.423	2.261
6.16	40.17	-0.423	2.260
6.17	40.05	-0.423	2.259
6.18	39.93	-0.422	2.258
6.20	39.82	-0.422	2.259
6.21	39.70	-0.422	2.258
6.22	39.58	-0.422	2.257
6.23	39.47	-0.422	2.257
6.24	39.35	-0.422	2.257
6.25	39.23	-0.422	2.256
6.26	39.12	-0.421	2.255
6.28	39.00	-0.421	2.255
6.29	38.88	-0.421	2.254
6.30	38.77	-0.421	2.253
6.31	38.65	-0.421	2.253
6.32	38.54	-0.421	2.253
6.34	38.42	-0.421	2.253
6.35	38.30	-0.421	2.251
6.36	38.19	-0.421	2.250
6.37	38.07	-0.420	2.250
6.38	37.95	-0.420	2.250
6.39	37.83	-0.420	2.249
6.40	37.72	-0.420	2.249
6.42	37.60	-0.420	2.248
6.43	37.49	-0.420	2.246
6.44	37.37	-0.420	2.246
6.45	37.25	-0.420	2.246
6.46	37.13	-0.419	2.245
6.48	37.02	-0.419	2.244
6.49	36.90	-0.419	2.244
6.50	36.79	-0.419	2.244
6.51	36.67	-0.419	2.242
6.52	36.55	-0.419	2.242
6.53	36.44	-0.419	2.241
6.55	36.32	-0.418	2.241
6.56	36.20	-0.418	2.241
6.57	36.09	-0.418	2.241
6.58	35.97	-0.418	2.239
6.59	35.85	-0.418	2.239
6.60	35.74	-0.418	2.237
6.61	35.62	-0.418	2.236
6.63	35.50	-0.417	2.236
6.64	35.39	-0.417	2.235
6.65	35.27	-0.417	2.236
6.66	35.15	-0.417	2.235
6.67	35.04	-0.417	2.234
6.69	34.92	-0.417	2.233
6.70	34.80	-0.416	2.232
6.71	34.69	-0.416	2.232
6.72	34.57	-0.416	2.231
6.73	34.46	-0.416	2.228
6.74	34.34	-0.416	2.227
6.75	34.22	-0.416	2.227
6.77	34.11	-0.416	2.226
6.78	33.99	-0.415	2.226
6.79	33.87	-0.415	2.226
6.80	33.76	-0.415	2.226
6.81	33.64	-0.415	2.225
6.83	33.52	-0.415	2.225
6.84	33.41	-0.415	2.224
6.85	33.29	-0.415	2.223
6.86	33.17	-0.415	2.223
6.87	33.06	-0.415	2.222
6.88	32.94	-0.415	2.221
6.90	32.82	-0.414	2.220
6.91	32.71	-0.414	2.219
6.92	32.59	-0.414	2.220
6.93	32.47	-0.414	2.219
6.94	32.36	-0.414	2.218
6.95	32.24	-0.414	2.217
6.96	32.13	-0.414	2.217
6.98	32.01	-0.414	2.216
6.99	31.89	-0.413	2.215
7.00	31.78	-0.413	2.215
7.01	31.66	-0.413	2.215
7.02	31.54	-0.413	2.213
7.04	31.42	-0.413	2.213
7.05	31.31	-0.413	2.213
7.06	31.19	-0.413	2.212
7.07	31.07	-0.413	2.210
7.08	30.96	-0.413	2.210
7.09	30.84	-0.412	2.209
7.10	30.73	-0.412	2.209
7.12	30.61	-0.412	2.208
7.13	30.49	-0.412	2.207
7.14	30.38	-0.412	2.206
7.15	30.26	-0.412	2.205
7.16	30.14	-0.411	2.204
7.18	30.03	-0.411	2.204
7.19	29.91	-0.411	2.202
7.20	29.79	-0.411	2.203
7.21	29.68	-0.411	2.202
7.22	29.56	-0.411	2.201
7.23	29.44	-0.411	2.201
7.25	29.33	-0.411	2.200
7.26	29.21	-0.410	2.198
7.27	29.09	-0.410	2.198
7.28	28.98	-0.410	2.197
7.29	28.86	-0.410	2.197
7.30	28.75	-0.410	2.196
7.31	28.63	-0.410	2.195
7.33	28.51	-0.410	2.194
7.34	28.40	-0.410	2.195
7.35	28.28	-0.409	2.194
7.36	28.16	-0.409	2.193
7.37	28.04	-0.409	2.192
7.39	27.93	-0.409	2.192
7.40	27.81	-0.409	2.190
7.41	27.70	-0.409	2.190
7.42	27.58	-0.409	2.189
7.43	27.46	-0.408	2.189
7.44	27.35	-0.408	2.187
7.45	27.23	-0.408	2.188
7.47	27.11	-0.408	2.187
7.48	27.00	-0.408	2.186
7.49	26.88	-0.408	2.184
7.50	26.76	-0.408	2.183
7.51	26.65	-0.408	2.183
7.53	26.53	-0.407	2.182
7.54	26.41	-0.407	2.182
7.55	26.30	-0.407	2.181
7.56	26.18	-0.407	2.180
7.57	26.06	-0.407	2.180
7.58	25.95	-0.407	2.179
7.60	25.83	-0.407	2.178
7.61	25.71	-0.406	2.177
7.62	25.60	-0.406	2.176
7.63	25.48	-0.406	2.176
7.64	25.36	-0.406	2.176
7.65	25.25	-0.406	2.175
7.66	25.13	-0.406	2.174
7.68	25.02	-0.406	2.173
7.69	24.90	-0.405	2.172
7.70	24.78	-0.405	2.172
7.71	24.67	-0.405	2.171
7.72	24.55	-0.405	2.170
7.74	24.43	-0.405	2.169
7.75	24.32	-0.405	2.168
7.76	24.20	-0.405	2.167
7.77	24.08	-0.404	2.166
7.78	23.97	-0.404	2.165
7.79	23.85	-0.404	2.165
7.80	23.74	-0.404	2.164
7.82	23.62	-0.404	2.163
7.83	23.50	-0.404	2.161
7.84	23.38	-0.403	2.161
7.85	23.27	-0.403	2.160
7.86	23.15	-0.403	2.159
7.88	23.03	-0.403	2.158
7.89	22.92	-0.403	2.157
7.90	22.80	-0.403	2.157
7.91	22.68	-0.403	2.156
7.92	22.57	-0.402	2.155
7.93	22.45	-0.402	2.154
7.95	22.34	-0.402	2.154
7.96	22.22	-0.402	2.153
7.97	22.10	-0.402	2.152
7.98	21.98	-0.402	2.151
7.99	21.87	-0.402	2.151
8.00	21.75	-0.401	2.151
8.01	21.64	-0.401	2.150
8.03	21.52	-0.401	2.149
8.04	21.40	-0.401	2.149
8.05	21.29	-0.401	2.148
8.06	21.17	-0.401	2.147
8.07	21.05	-0.401	2.146
8.09	20.94	-0.400	2.146
8.10	20.82	-0.400	2.145
8.11	20.70	-0.400	2.143
8.12	20.59	-0.400	2.143
8.13	20.47	-0.400	2.142
8.14	20.36	-0.400	2.141
8.15	20.24	-0.400	2.140
8.17	20.12	-0.399	2.140
8.18	20.00	-0.399	2.140
8.19	19.89	-0.399	2.139
8.20	19.77	-0.399	2.137
8.21	19.65	-0.399	2.135
8.23	19.54	-0.398	2.135
8.24	19.42	-0.398	2.134
8.25	19.31	-0.398	2.134
8.26	19.19	-0.398	2.133
8.27	19.07	-0.398	2.132
8.28	18.95	-0.398	2.132
8.30	18.84	-0.398	2.130
8.31	18.72	-0.398	2.130
8.32	18.61	-0.398	2.130
8.33	18.49	-0.397	2.130
8.34	18.37	-0.397	2.127
8.35	18.26	-0.397	2.128
8.36	18.14	-0.397	2.126
8.38	18.02	-0.397	2.126
8.39	17.91	-0.396	2.124
8.40	17.79	-0.396	2.124
8.41	17.67	-0.396	2.123
8.42	17.56	-0.396	2.122
8.44	17.44	-0.396	2.122
8.45	17.32	-0.396	2.121
8.46	17.21	-0.396	2.120
8.47	17.09	-0.395	2.119
8.48	16.97	-0.395	2.119
8.49	16.86	-0.395	2.117
8.50	16.74	-0.395	2.117
8.52	16.62	-0.395	2.116
8.53	16.51	-0.395	2.115
8.54	16.39	-0.395	2.114
8.55	16.27	-0.394	2.114
8.56	16.16	-0.394	2.113
8.58	16.04	-0.394	2.113
8.59	15.93	-0.394	2.112
8.60	15.81	-0.394	2.111
8.61	15.69	-0.394	2.110
8.62	15.58	-0.394	2.110
8.63	15.46	-0.393	2.108
8.65	15.34	-0.393	2.108
8.66	15.23	-0.393	2.108
8.67	15.11	-0.393	2.106
8.68	14.99	-0.393	2.106
8.69	14.88	-0.393	2.105
8.70	14.76	-0.393	2.105
8.72	14.64	-0.393	2.103
8.73	14.53	-0.393	2.103
8.74	14.41	-0.392	2.103
8.75	14.30	-0.392	2.102
8.76	14.18	-0.392	2.101
8.77	14.06	-0.392	2.100
8.78	13.95	-0.392	2.099
8.80	13.83	-0.392	2.099
8.81	13.71	-0.392	2.099
8.82	13.60	-0.391	2.099
8.83	13.48	-0.391	2.097
8.84	13.36	-0.391	2.097
8.85	13.25	-0.391	2.096
8.87	13.13	-0.391	2.096
8.88	13.01	-0.391	2.095
8.89	12.90	-0.391	2.093
8.90	12.78	-0.391	2.093
8.91	12.66	-0.390	2.092
8.93	12.55	-0.390	2.091
8.94	12.43	-0.390	2.091
8.95	12.31	-0.390	2.091
8.96	12.20	-0.390	2.089
8.97	12.08	-0.390	2.089
8.98	11.97	-0.390	2.089
9.00	11.85	-0.389	2.088
9.01	11.73	-0.389	2.087
9.02	11.61	-0.389	2.085
9.03	11.50	-0.389	2.085
9.04	11.38	-0.389	2.084
9.05	11.26	-0.389	2.083
9.07	11.15	-0.389	2.083
9.08	11.03	-0.389	2.083
9.09	10.92	-0.388	2.083
9.10	10.80	-0.388	2.082
9.11	10.68	-0.388	2.082
9.12	10.57	-0.388	2.081
9.13	10.45	-0.388	2.080
9.15	10.33	-0.388	2.079
9.16	10.22	-0.387	2.078
9.17	10.10	-0.387	2.078
9.18	9.99	-0.387	2.076
9.19	9.87	-0.387	2.074
9.20	9.75	-0.387	2.074
9.22	9.63	-0.387	2.073
9.23	9.52	-0.386	2.072
9.24	9.40	-0.386	2.073
9.25	9.29	-0.386	2.072
9.26	9.17	-0.386	2.069
9.28	9.05	-0.386	2.068
9.29	8.94	-0.385	2.066
9.30	8.82	-0.385	2.066
9.31	8.70	-0.385	2.066
9.32	8.59	-0.385	2.064
9.33	8.47	-0.385	2.064
9.35	8.36	-0.385	2.062
9.36	8.24	-0.385	2.063
9.37	8.12	-0.384	2.062
9.38	8.00	-0.384	2.060
9.39	7.89	-0.384	2.061
9.40	7.77	-0.384	2.060
9.42	7.65	-0.384	2.059
9.43	7.54	-0.384	2.059
9.44	7.42	-0.384	2.058
9.45	7.31	-0.383	2.057
9.46	7.19	-0.383	2.056
9.47	7.07	-0.383	2.056
9.48	6.96	-0.383	2.055
9.50	6.84	-0.383	2.053
9.51	6.73	-0.383	2.052
9.52	6.61	-0.383	2.052
9.53	6.49	-0.382	2.050
9.54	6.38	-0.382	2.050
9.55	6.26	-0.382	2.049
9.57	6.14	-0.382	2.048
9.58	6.02	-0.382	2.048
9.59	5.91	-0.382	2.046
9.60	5.79	-0.382	2.046
9.61	5.67	-0.381	2.045
9.63	5.56	-0.381	2.043
9.64	5.44	-0.381	2.042
9.65	5.32	-0.381	2.042
9.66	5.21	-0.381	2.042
9.67	5.09	-0.381	2.041
9.68	4.98	-0.381	2.041
9.70	4.86	-0.381	2.039
9.71	4.74	-0.380	2.039
9.72	4.63	-0.380	2.038
9.73	4.51	-0.380	2.037
9.74	4.39	-0.380	2.036
9.75	4.28	-0.380	2.036
9.77	4.16	-0.380	2.035
9.78	4.04	-0.380	2.035
9.79	3.93	-0.379	2.033
9.80	3.81	-0.379	2.033
9.81	3.69	-0.379	2.031
9.82	3.58	-0.379	2.032
9.83	3.46	-0.379	2.031
9.85	3.34	-0.379	2.030
9.86	3.23	-0.379	2.029
9.87	3.11	-0.379	2.027
9.88	2.99	-0.378	2.026
9.89	2.88	-0.378	2.027
9.90	2.76	-0.378	2.026
9.92	2.64	-0.378	2.024
9.93	2.53	-0.378	2.024
9.94	2.41	-0.378	2.023
9.95	2.29	-0.378	2.022
9.96	2.18	-0.378	2.022
9.98	2.06	-0.377	2.020
9.99	1.94	-0.377	2.020
10.00	1.83	-0.377	2.020
10.01	1.71	-0.377	2.019
10.02	1.59	-0.377	2.019
10.03	1.48	-0.377	2.018
10.05	1.36	-0.377	2.017
10.06	1.24	-0.377	2.016
10.07	1.13	-0.377	2.016
10.08	1.01	-0.376	2.015
10.09	0.89	-0.376	2.014
10.10	0.78	-0.376	2.013
10.12	0.66	-0.376	2.014
10.13	0.54	-0.376	2.013
10.14	0.43	-0.376	2.012
10.15	0.31	-0.376	2.011
10.16	0.19	-0.376	2.010
10.17	0.08	-0.376	2.010
10.18	-0.04	-0.375	2.009
10.20	-0.16	-0.375	2.008
10.21	-0.28	-0.375	2.008
10.22	-0.39	-0.375	2.007
10.23	-0.51	-0.375	2.006
10.24	-0.62	-0.375	2.006
10.25	-0.74	-0.375	2.006
10.27	-0.86	-0.375	2.005
10.28	-0.97	-0.375	2.004
10.29	-1.09	-0.375	2.004
10.30	-1.21	-0.374	2.003
10.31	-1.32	-0.374	2.002
10.33	-1.44	-0.374	2.000
10.34	-1.56	-0.374	2.001
10.35	-1.68	-0.374	2.000
10.36	-1.79	-0.374	2.000
10.37	-1.91	-0.374	1.999
10.38	-2.03	-0.374	1.998
10.40	-2.14	-0.373	1.997
10.41	-2.26	-0.373	1.997
10.42	-2.38	-0.373	1.996
10.43	-2.49	-0.373	1.996
10.44	-2.61	-0.373	1.994
10.45	-2.73	-0.373	1.994
10.47	-2.84	-0.373	1.993
10.48	-2.96	-0.373	1.993
10.49	-3.08	-0.372	1.992
10.50	-3.19	-0.372	1.991
10.51	-3.31	-0.372	1.990
10.52	-3.43	-0.372	1.989
10.53	-3.54	-0.372	1.989
10.55	-3.66	-0.372	1.989
10.56	-3.78	-0.372	1.987
10.57	-3.89	-0.372	1.987
10.58	-4.01	-0.372	1.987
10.59	-4.13	-0.372	1.986
10.60	-4.25	-0.371	1.985
10.62	-4.36	-0.371	1.985
10.63	-4.48	-0.371	1.984
10.64	-4.59	-0.371	1.984
10.65	-4.71	-0.371	1.982
10.66	-4.83	-0.371	1.982
10.68	-4.94	-0.371	1.981
10.69	-5.06	-0.371	1.980
10.70	-5.18	-0.371	1.980
10.71	-5.30	-0.370	1.980
10.72	-5.41	-0.370	1.979
10.73	-5.53	-0.370	1.977
10.75	-5.65	-0.370	1.976
10.76	-5.76	-0.370	1.976
10.77	-5.88	-0.370	1.976
10.78	-6.00	-0.370	1.975
10.79	-6.11	-0.370	1.973
10.80	-6.23	-0.369	1.973
10.82	-6.35	-0.369	1.972
10.83	-6.46	-0.369	1.970
10.84	-6.58	-0.369	1.970
10.85	-6.70	-0.369	1.971
10.86	-6.81	-0.369	1.969
10.87	-6.93	-0.369	1.969
10.88	-7.05	-0.369	1.968
10.90	-7.17	-0.368	1.967
10.91	-7.28	-0.368	1.966
10.92	-7.40	-0.368	1.965
10.93	-7.52	-0.368	1.965
10.94	-7.63	-0.368	1.964
10.95	-7.75	-0.368	1.963
10.97	-7.87	-0.367	1.960
10.98	-7.98	-0.367	1.960
10.99	-8.10	-0.367	1.960
11.00	-8.22	-0.367	1.959
11.01	-8.33	-0.367	1.958
11.03	-8.45	-0.367	1.957
11.04	-8.57	-0.367	1.957
11.05	-8.68	-0.366	1.955
11.06	-8.80	-0.366	1.954
11.07	-8.92	-0.366	1.953
11.08	-9.03	-0.366	1.951
11.10	-9.15	-0.366	1.950
11.11	-9.27	-0.365	1.950
11.12	-9.38	-0.365	1.948
11.13	-9.50	-0.365	1.947
11.14	-9.62	-0.365	1.947
11.15	-9.73	-0.365	1.945
11.17	-9.85	-0.364	1.944
11.18	-9.97	-0.364	1.943
11.19	-10.09	-0.364	1.942
11.20	-10.20	-0.364	1.941
11.21	-10.32	-0.364	1.938
11.22	-10.43	-0.363	1.937
11.23	-10.55	-0.363	1.936
11.25	-10.67	-0.363	1.933
11.26	-10.79	-0.363	1.932
11.27	-10.90	-0.362	1.932
11.28	-11.02	-0.362	1.930
11.29	-11.14	-0.362	1.928
11.30	-11.25	-0.361	1.925
11.32	-11.37	-0.361	1.923
11.33	-11.49	-0.361	1.922
11.34	-11.60	-0.361	1.921
11.35	-11.72	-0.360	1.920
11.36	-11.84	-0.360	1.915
11.38	-11.95	-0.359	1.914
11.39	-12.07	-0.359	1.913
11.40	-12.19	-0.359	1.910
11.41	-12.30	-0.358	1.908
11.42	-12.42	-0.357	1.902
11.43	-12.54	-0.357	1.900
11.45	-12.65	-0.357	1.898
11.46	-12.77	-0.356	1.896
11.47	-12.89	-0.356	1.895
11.48	-13.01	-0.356	1.892
11.49	-13.12	-0.355	1.891
11.50	-13.24	-0.355	1.889
11.52	-13.36	-0.354	1.885
11.53	-13.47	-0.354	1.881
11.54	-13.59	-0.353	1.880
11.55	-13.71	-0.353	1.877
11.56	-13.82	-0.352	1.872
11.57	-13.94	-0.351	1.871
11.58	-14.06	-0.351	1.865
11.60	-14.17	-0.349	1.858
11.61	-14.29	-0.349	1.856
11.62	-14.41	-0.349	1.854
11.63	-14.52	-0.348	1.850
11.64	-14.64	-0.348	1.848
11.65	-14.76	-0.347	1.846
11.67	-14.87	-0.347	1.842
11.68	-14.99	-0.346	1.838
11.69	-15.11	-0.345	1.836
11.70	-15.23	-0.345	1.834
11.71	-15.34	-0.344	1.831
11.73	-15.46	-0.344	1.829
11.74	-15.58	-0.343	1.825
11.75	-15.69	-0.343	1.821
11.76	-15.81	-0.342	1.819
11.77	-15.93	-0.341	1.812
11.78	-16.05	-0.341	1.809
11.80	-16.16	-0.340	1.808
11.81	-16.28	-0.339	1.803
11.82	-16.39	-0.339	1.800
11.83	-16.51	-0.338	1.797
11.84	-16.63	-0.338	1.793
11.85	-16.74	-0.337	1.790
11.87	-16.86	-0.335	1.781
11.88	-16.98	-0.335	1.779
11.89	-17.10	-0.334	1.774
11.90	-17.21	-0.334	1.771
11.91	-17.33	-0.333	1.768
11.92	-17.45	-0.332	1.764
11.93	-17.56	-0.332	1.761
11.95	-17.68	-0.332	1.759
11.96	-17.80	-0.331	1.756
11.97	-17.91	-0.330	1.754
11.98	-18.03	-0.330	1.749
11.99	-18.15	-0.329	1.746
12.00	-18.27	-0.328	1.739
12.02	-18.38	-0.327	1.735
12.03	-18.50	-0.326	1.730
12.04	-18.62	-0.326	1.728
12.05	-18.73	-0.325	1.724
12.06	-18.85	-0.325	1.721
12.08	-18.97	-0.323	1.715
12.09	-19.08	-0.322	1.710
12.10	-19.20	-0.322	1.707
12.11	-19.32	-0.322	1.706
12.12	-19.43	-0.321	1.701
12.13	-19.55	-0.320	1.699
12.15	-19.67	-0.320	1.696
12.16	-19.79	-0.319	1.691
12.17	-19.90	-0.319	1.689
12.18	-20.02	-0.318	1.684
12.19	-20.14	-0.317	1.680
12.20	-20.25	-0.317	1.678
12.22	-20.37	-0.316	1.675
12.23	-20.49	-0.316	1.673
12.24	-20.60	-0.315	1.670
12.25	-20.72	-0.314	1.666
12.26	-20.84	-0.313	1.659
12.27	-20.95	-0.313	1.657
12.28	-21.07	-0.312	1.654
12.30	-21.19	-0.312	1.651
12.31	-21.30	-0.311	1.648
12.32	-21.42	-0.310	1.644
12.33	-21.54	-0.309	1.635
12.34	-21.65	-0.308	1.634
12.35	-21.77	-0.308	1.631
12.37	-21.89	-0.307	1.624
12.38	-22.00	-0.306	1.622
12.39	-22.12	-0.306	1.620
12.40	-22.24	-0.306	1.619
12.41	-22.36	-0.305	1.615
12.43	-22.47	-0.304	1.613
12.44	-22.59	-0.304	1.610
12.45	-22.71	-0.304	1.607
12.46	-22.82	-0.303	1.603
12.47	-22.94	-0.302	1.601
12.48	-23.06	-0.302	1.598
12.50	-23.17	-0.301	1.594
12.51	-23.29	-0.301	1.592
12.52	-23.41	-0.300	1.590
12.53	-23.52	-0.300	1.587
12.54	-23.64	-0.299	1.584
12.55	-23.76	-0.299	1.583
12.57	-23.87	-0.299	1.580
12.58	-23.99	-0.298	1.575
12.59	-24.11	-0.298	1.574
12.60	-24.23	-0.297	1.572
12.61	-24.34	-0.296	1.564
12.62	-24.46	-0.295	1.562
12.63	-24.58	-0.295	1.561
12.65	-24.69	-0.295	1.559
12.66	-24.81	-0.294	1.554
12.67	-24.93	-0.294	1.553
12.68	-25.04	-0.293	1.549
12.69	-25.16	-0.293	1.548
12.70	-25.28	-0.292	1.542
12.72	-25.39	-0.291	1.538
12.73	-25.51	-0.291	1.537
12.74	-25.63	-0.290	1.536
12.75	-25.74	-0.290	1.533
12.76	-25.86	-0.290	1.531
12.78	-25.98	-0.289	1.529
12.79	-26.10	-0.288	1.522
12.80	-26.21	-0.287	1.519
12.81	-26.33	-0.287	1.517
12.82	-26.44	-0.287	1.516
12.83	-26.56	-0.287	1.514
12.85	-26.68	-0.286	1.510
12.86	-26.79	-0.285	1.508
12.87	-26.91	-0.285	1.505
12.88	-27.03	-0.285	1.504
12.89	-27.15	-0.284	1.503
12.90	-27.26	-0.284	1.500
12.92	-27.38	-0.284	1.499
12.93	-27.50	-0.283	1.497
12.94	-27.61	-0.283	1.495
12.95	-27.73	-0.283	1.492
12.96	-27.84	-0.282	1.491
12.97	-27.96	-0.282	1.490
12.98	-28.08	-0.282	1.488
13.00	-28.20	-0.282	1.486
13.01	-28.31	-0.281	1.483
13.02	-28.43	-0.281	1.481
13.03	-28.55	-0.280	1.479
13.04	-28.66	-0.280	1.478
13.05	-28.78	-0.280	1.475
13.07	-28.90	-0.279	1.474
13.08	-29.01	-0.279	1.472
13.09	-29.13	-0.279	1.470
13.10	-29.25	-0.278	1.469
13.11	-29.36	-0.278	1.466
13.13	-29.48	-0.278	1.463
13.14	-29.60	-0.277	1.462
13.15	-29.71	-0.277	1.461
13.16	-29.83	-0.277	1.459
[...]
2136.82	8.18	0.329	1.758
2136.83	8.29	0.329	1.757
2136.84	8.41	0.329	1.758
2136.85	8.53	0.329	1.758
2136.86	8.64	0.329	1.758
2136.88	8.76	0.329	1.758
2136.89	8.88	0.329	1.759
2136.90	8.99	0.329	1.759
2136.91	9.11	0.329	1.760
2136.92	9.23	0.329	1.760
2136.94	9.34	0.329	1.761
2136.95	9.46	0.329	1.761
2136.96	9.58	0.330	1.762
2136.97	9.69	0.330	1.761
2136.98	9.81	0.330	1.762
2136.99	9.93	0.330	1.763
2137.00	10.04	0.330	1.764
2137.02	10.16	0.330	1.764
2137.03	10.28	0.330	1.764
2137.04	10.39	0.330	1.765
2137.05	10.51	0.330	1.766
2137.06	10.63	0.330	1.767
2137.08	10.75	0.330	1.767
2137.09	10.86	0.331	1.767
2137.10	10.98	0.331	1.768
2137.11	11.10	0.331	1.768
2137.12	11.21	0.331	1.768
2137.13	11.33	0.331	1.768
2137.15	11.45	0.331	1.768
2137.16	11.56	0.331	1.769
2137.17	11.68	0.331	1.769
2137.18	11.80	0.331	1.769
2137.19	11.91	0.331	1.771
2137.20	12.03	0.331	1.771
2137.21	12.15	0.331	1.771
2137.23	12.26	0.331	1.772
2137.24	12.38	0.331	1.772
2137.25	12.50	0.332	1.772
2137.26	12.62	0.332	1.772
2137.27	12.73	0.332	1.773
2137.29	12.85	0.332	1.773
2137.30	12.96	0.332	1.773
2137.31	13.08	0.332	1.773
2137.32	13.20	0.332	1.773
2137.33	13.32	0.332	1.775
2137.34	13.43	0.332	1.775
2137.35	13.55	0.332	1.775
2137.37	13.67	0.332	1.775
2137.38	13.78	0.332	1.776
2137.39	13.90	0.332	1.776
2137.40	14.02	0.332	1.776
2137.41	14.13	0.332	1.777
2137.43	14.25	0.333	1.778
2137.44	14.37	0.333	1.778
2137.45	14.48	0.333	1.778
2137.46	14.60	0.333	1.779
2137.47	14.72	0.333	1.779
2137.48	14.83	0.333	1.781
2137.50	14.95	0.333	1.782
2137.51	15.07	0.333	1.783
2137.52	15.19	0.334	1.783
2137.53	15.30	0.334	1.782
2137.54	15.42	0.334	1.784
2137.55	15.54	0.334	1.785
2137.56	15.65	0.334	1.784
2137.58	15.77	0.334	1.785
2137.59	15.89	0.334	1.785
2137.60	16.00	0.334	1.786
2137.61	16.12	0.334	1.786
2137.62	16.24	0.334	1.787
2137.64	16.35	0.334	1.787
2137.65	16.47	0.334	1.787
2137.66	16.59	0.335	1.788
2137.67	16.70	0.335	1.788
2137.68	16.82	0.335	1.788
2137.69	16.94	0.335	1.789
2137.70	17.05	0.335	1.789
2137.72	17.17	0.335	1.790
2137.73	17.29	0.335	1.790
2137.74	17.40	0.335	1.790
2137.75	17.52	0.335	1.792
2137.76	17.64	0.335	1.792
2137.78	17.75	0.335	1.792
2137.79	17.87	0.335	1.792
2137.80	17.99	0.335	1.793
2137.81	18.11	0.336	1.794
2137.82	18.22	0.336	1.794
2137.83	18.34	0.336	1.794
2137.85	18.46	0.336	1.795
2137.86	18.57	0.336	1.795
2137.87	18.69	0.336	1.795
2137.88	18.81	0.336	1.796
2137.89	18.92	0.336	1.798
2137.90	19.04	0.336	1.798
2137.91	19.16	0.336	1.798
2137.93	19.27	0.336	1.798
2137.94	19.39	0.336	1.799
2137.95	19.51	0.337	1.804
2137.96	19.62	0.337	1.803
2137.97	19.74	0.337	1.803
2137.99	19.86	0.337	1.804
2138.00	19.97	0.338	1.805
2138.01	20.09	0.338	1.805
2138.02	20.21	0.338	1.805
2138.03	20.32	0.338	1.806
2138.04	20.44	0.338	1.806
2138.05	20.56	0.338	1.806
2138.07	20.68	0.338	1.806
2138.08	20.79	0.338	1.807
2138.09	20.91	0.338	1.807
2138.10	21.03	0.338	1.807
2138.11	21.14	0.338	1.808
2138.13	21.26	0.338	1.809
2138.14	21.37	0.338	1.810
2138.15	21.49	0.338	1.809
2138.16	21.61	0.338	1.809
2138.17	21.72	0.339	1.810
2138.18	21.84	0.339	1.810
2138.20	21.96	0.339	1.811
2138.21	22.08	0.339	1.812
2138.22	22.19	0.339	1.812
2138.23	22.31	0.339	1.812
2138.24	22.43	0.339	1.812
2138.25	22.54	0.339	1.813
2138.26	22.66	0.339	1.814
2138.28	22.78	0.339	1.813
2138.29	22.89	0.340	1.814
2138.30	23.01	0.340	1.815
2138.31	23.13	0.340	1.815
2138.32	23.24	0.340	1.816
2138.34	23.36	0.340	1.816
2138.35	23.48	0.340	1.817
2138.36	23.59	0.340	1.818
2138.37	23.71	0.340	1.819
2138.38	23.83	0.340	1.819
2138.39	23.94	0.340	1.820
2138.40	24.06	0.340	1.820
2138.42	24.18	0.341	1.820
2138.43	24.30	0.341	1.821
2138.44	24.41	0.341	1.822
2138.45	24.53	0.341	1.821
2138.46	24.65	0.341	1.822
2138.48	24.76	0.341	1.822
2138.49	24.88	0.341	1.823
2138.50	25.00	0.341	1.824
2138.51	25.11	0.341	1.824
2138.52	25.23	0.341	1.825
2138.53	25.35	0.341	1.825
2138.55	25.46	0.342	1.825
2138.56	25.58	0.342	1.826
2138.57	25.70	0.342	1.826
2138.58	25.81	0.342	1.826
2138.59	25.93	0.342	1.827
2138.60	26.05	0.342	1.827
2138.61	26.16	0.342	1.828
2138.63	26.28	0.342	1.829
2138.64	26.40	0.342	1.829
2138.65	26.51	0.342	1.829
2138.66	26.63	0.342	1.830
2138.67	26.75	0.343	1.830
2138.69	26.86	0.343	1.831
2138.70	26.98	0.343	1.832
2138.71	27.10	0.343	1.832
2138.72	27.22	0.343	1.832
2138.73	27.33	0.343	1.833
2138.74	27.45	0.343	1.834
2138.75	27.57	0.343	1.834
2138.77	27.68	0.343	1.834
2138.78	27.80	0.343	1.835
2138.79	27.92	0.343	1.835
2138.80	28.03	0.344	1.837
2138.81	28.15	0.344	1.836
2138.83	28.27	0.344	1.837
2138.84	28.38	0.344	1.837
2138.85	28.50	0.344	1.839
2138.86	28.62	0.344	1.840
2138.87	28.73	0.344	1.839
2138.88	28.85	0.344	1.840
2138.90	28.97	0.344	1.841
2138.91	29.08	0.344	1.841
2138.92	29.20	0.344	1.841
2138.93	29.32	0.345	1.842
2138.94	29.44	0.345	1.842
2138.95	29.55	0.345	1.843
2138.96	29.67	0.345	1.844
2138.98	29.79	0.345	1.844
2138.99	29.90	0.345	1.845
2139.00	30.02	0.345	1.844
2139.01	30.14	0.345	1.845
2139.02	30.25	0.345	1.847
2139.04	30.37	0.346	1.846
2139.05	30.49	0.346	1.848
2139.06	30.60	0.346	1.847
2139.07	30.72	0.346	1.849
2139.08	30.84	0.346	1.849
2139.09	30.95	0.346	1.850
2139.10	31.07	0.346	1.851
2139.12	31.19	0.346	1.852
2139.13	31.30	0.346	1.852
2139.14	31.42	0.346	1.852
2139.15	31.54	0.347	1.853
2139.16	31.66	0.347	1.854
2139.18	31.77	0.347	1.853
2139.19	31.89	0.347	1.853
2139.20	32.01	0.347	1.854
2139.21	32.12	0.347	1.855
2139.22	32.24	0.347	1.855
2139.23	32.36	0.347	1.855
2139.25	32.47	0.347	1.856
2139.26	32.59	0.347	1.857
2139.27	32.71	0.347	1.857
2139.28	32.82	0.347	1.858
2139.29	32.94	0.347	1.857
2139.30	33.06	0.348	1.858
2139.31	33.17	0.348	1.859
2139.33	33.29	0.348	1.859
2139.34	33.41	0.348	1.860
2139.35	33.52	0.348	1.861
2139.36	33.64	0.348	1.860
2139.37	33.76	0.348	1.862
2139.39	33.87	0.348	1.863
2139.40	33.99	0.348	1.863
2139.41	34.11	0.348	1.862
2139.42	34.22	0.349	1.863
2139.43	34.34	0.349	1.863
2139.44	34.46	0.349	1.864
2139.45	34.58	0.349	1.865
2139.47	34.69	0.349	1.865
2139.48	34.81	0.349	1.865
2139.49	34.93	0.349	1.866
2139.50	35.04	0.349	1.866
2139.51	35.16	0.349	1.866
2139.53	35.28	0.349	1.867
2139.54	35.39	0.349	1.867
2139.55	35.51	0.349	1.867
2139.56	35.63	0.349	1.868
2139.57	35.74	0.350	1.868
2139.58	35.86	0.350	1.868
2139.60	35.98	0.350	1.868
2139.61	36.09	0.350	1.870
2139.62	36.21	0.350	1.870
2139.63	36.33	0.350	1.870
2139.64	36.44	0.350	1.871
2139.65	36.56	0.350	1.871
2139.66	36.68	0.350	1.871
2139.68	36.79	0.350	1.871
2139.69	36.91	0.350	1.871
2139.70	37.03	0.351	1.872
2139.71	37.14	0.351	1.873
2139.72	37.26	0.351	1.873
2139.74	37.38	0.351	1.873
2139.75	37.50	0.351	1.873
2139.76	37.61	0.351	1.874
2139.77	37.73	0.351	1.874
2139.78	37.85	0.351	1.875
2139.79	37.96	0.351	1.875
2139.80	38.08	0.351	1.876
2139.82	38.20	0.351	1.876
2139.83	38.31	0.351	1.876
2139.84	38.43	0.351	1.877
2139.85	38.55	0.351	1.877
2139.86	38.66	0.352	1.877
2139.88	38.78	0.352	1.878
2139.89	38.90	0.352	1.878
2139.90	39.01	0.352	1.879
2139.91	39.13	0.352	1.879
2139.92	39.25	0.352	1.880
2139.93	39.37	0.352	1.880
2139.95	39.48	0.352	1.880
2139.96	39.60	0.352	1.881
2139.97	39.72	0.352	1.881
2139.98	39.83	0.352	1.881
2139.99	39.95	0.353	1.882
2140.00	40.07	0.353	1.881
2140.01	40.18	0.353	1.882
2140.03	40.30	0.353	1.883
2140.04	40.42	0.353	1.882
2140.05	40.53	0.353	1.884
2140.06	40.65	0.353	1.884
2140.07	40.77	0.353	1.884
2140.09	40.88	0.353	1.885
2140.10	41.00	0.353	1.885
2140.11	41.12	0.353	1.885
2140.12	41.23	0.354	1.885
2140.13	41.35	0.354	1.886
2140.14	41.47	0.354	1.885
2140.15	41.58	0.354	1.886
2140.17	41.70	0.354	1.886
2140.18	41.82	0.354	1.887
2140.19	41.93	0.354	1.888
2140.20	42.05	0.354	1.888
2140.21	42.17	0.354	1.889
2140.23	42.29	0.354	1.888
2140.24	42.40	0.354	1.889
2140.25	42.52	0.354	1.889
2140.26	42.64	0.355	1.889
2140.27	42.75	0.355	1.891
2140.28	42.87	0.355	1.891
2140.30	42.99	0.355	1.891
2140.31	43.10	0.355	1.891
2140.32	43.22	0.355	1.891
2140.33	43.34	0.355	1.892
2140.34	43.45	0.355	1.892
2140.35	43.57	0.355	1.893
2140.36	43.69	0.355	1.893
2140.38	43.80	0.355	1.894
2140.39	43.92	0.355	1.894
2140.40	44.04	0.356	1.895
2140.41	44.15	0.356	1.895
2140.42	44.27	0.356	1.895
2140.44	44.39	0.356	1.895
2140.45	44.50	0.356	1.896
2140.46	44.62	0.356	1.896
2140.47	44.74	0.356	1.895
2140.48	44.86	0.356	1.896
2140.49	44.97	0.356	1.897
2140.50	45.09	0.356	1.898
2140.52	45.21	0.356	1.898
2140.53	45.32	0.357	1.898
2140.54	45.44	0.357	1.899
2140.55	45.55	0.357	1.899
2140.56	45.67	0.357	1.899
2140.58	45.79	0.357	1.901
2140.59	45.91	0.357	1.901
2140.60	46.02	0.357	1.901
2140.61	46.14	0.357	1.902
2140.62	46.26	0.357	1.902
2140.63	46.37	0.358	1.902
2140.65	46.49	0.358	1.902
2140.66	46.61	0.358	1.903
2140.67	46.72	0.358	1.905
2140.68	46.84	0.358	1.905
2140.69	46.96	0.358	1.905
2140.70	47.07	0.358	1.905
2140.71	47.19	0.358	1.907
2140.73	47.31	0.358	1.907
2140.74	47.42	0.358	1.907
2140.75	47.54	0.358	1.907
2140.76	47.66	0.358	1.908
2140.77	47.77	0.359	1.908
2140.79	47.89	0.359	1.908
2140.80	48.01	0.359	1.908
2140.81	48.12	0.359	1.909
2140.82	48.24	0.359	1.909
2140.83	48.36	0.359	1.910
2140.84	48.48	0.359	1.911
2140.85	48.59	0.359	1.911
2140.87	48.71	0.359	1.911
2140.88	48.83	0.359	1.912
2140.89	48.94	0.360	1.913
2140.90	49.06	0.360	1.914
2140.91	49.18	0.360	1.913
2140.93	49.29	0.360	1.913
2140.94	49.41	0.360	1.914
2140.95	49.53	0.360	1.915
2140.96	49.64	0.360	1.916
2140.97	49.76	0.360	1.916
2140.98	49.88	0.360	1.917
2141.00	49.99	0.360	1.917
2141.01	50.11	0.360	1.918
2141.02	50.23	0.360	1.918
2141.03	50.35	0.361	1.919
2141.04	50.46	0.361	1.920
2141.05	50.58	0.361	1.921
2141.06	50.69	0.361	1.921
2141.08	50.81	0.361	1.921
2141.09	50.93	0.361	1.922
2141.10	51.05	0.361	1.922
2141.11	51.16	0.361	1.922
2141.12	51.28	0.361	1.923
2141.14	51.40	0.361	1.923
2141.15	51.51	0.361	1.924
2141.16	51.63	0.361	1.924
2141.17	51.75	0.362	1.924
2141.18	51.86	0.362	1.925
2141.19	51.98	0.362	1.926
2141.20	52.10	0.362	1.927
2141.22	52.21	0.362	1.928
2141.23	52.33	0.362	1.928
2141.24	52.45	0.362	1.929
2141.25	52.56	0.362	1.929
2141.26	52.68	0.362	1.929
2141.28	52.80	0.362	1.929
2141.29	52.91	0.362	1.930
2141.30	53.03	0.362	1.931
2141.31	53.15	0.363	1.931
2141.32	53.26	0.363	1.931
2141.33	53.38	0.363	1.931
2141.35	53.50	0.363	1.932
2141.36	53.62	0.363	1.933
2141.37	53.73	0.363	1.933
2141.38	53.85	0.363	1.934
2141.39	53.97	0.363	1.934
2141.40	54.08	0.363	1.935
2141.41	54.20	0.363	1.935
2141.43	54.32	0.363	1.936
2141.44	54.43	0.363	1.936
2141.45	54.55	0.363	1.936
2141.46	54.67	0.364	1.937
2141.47	54.78	0.364	1.938
2141.49	54.90	0.364	1.938
2141.50	55.02	0.364	1.938
2141.51	55.13	0.364	1.939
2141.52	55.25	0.364	1.939
2141.53	55.37	0.364	1.940
2141.54	55.48	0.364	1.941
2141.55	55.60	0.364	1.941
2141.57	55.72	0.364	1.942
2141.58	55.84	0.364	1.943
2141.59	55.95	0.364	1.943
2141.60	56.07	0.364	1.943
2141.61	56.19	0.365	1.943
2141.63	56.30	0.365	1.944
2141.64	56.42	0.365	1.944
2141.65	56.54	0.365	1.945
2141.66	56.65	0.365	1.945
2141.67	56.77	0.365	1.946
2141.68	56.89	0.365	1.946
2141.70	57.00	0.365	1.947
2141.71	57.12	0.365	1.947
2141.72	57.24	0.365	1.947
2141.73	57.35	0.365	1.948
2141.74	57.47	0.365	1.948
2141.75	57.59	0.365	1.949
2141.76	57.70	0.366	1.950
2141.78	57.82	0.366	1.950
2141.79	57.94	0.366	1.950
2141.80	58.05	0.366	1.951
2141.81	58.17	0.366	1.951
2141.82	58.29	0.366	1.951
2141.84	58.40	0.366	1.952
2141.85	58.52	0.366	1.952
2141.86	58.64	0.366	1.953
2141.87	58.75	0.366	1.953
2141.88	58.87	0.366	1.954
2141.89	58.99	0.366	1.954
2141.90	59.10	0.366	1.954
2141.92	59.22	0.366	1.955
2141.93	59.34	0.367	1.954
2141.94	59.46	0.367	1.955
2141.95	59.57	0.367	1.956
2141.96	59.69	0.367	1.956
2141.98	59.81	0.367	1.956
2141.99	59.92	0.367	1.957
2142.00	60.04	0.367	1.957
2142.01	60.16	0.367	1.957
2142.02	60.27	0.367	1.958
2142.03	60.39	0.367	1.958
2142.05	60.51	0.367	1.959
2142.06	60.62	0.368	1.960
2142.07	60.74	0.368	1.960
2142.08	60.86	0.368	1.961
2142.09	60.97	0.368	1.961
2142.10	61.09	0.368	1.962
2142.11	61.21	0.368	1.962
2142.13	61.32	0.368	1.963
2142.14	61.44	0.368	1.964
2142.15	61.56	0.368	1.964
2142.16	61.67	0.368	1.964
2142.17	61.79	0.368	1.965
2142.19	61.91	0.368	1.966
2142.20	62.03	0.368	1.966
2142.21	62.14	0.368	1.966
2142.22	62.26	0.369	1.966
2142.23	62.38	0.369	1.967
2142.24	62.49	0.369	1.967
2142.25	62.61	0.369	1.967
2142.27	62.73	0.369	1.968
2142.28	62.84	0.369	1.969
2142.29	62.96	0.369	1.969
2142.30	63.08	0.369	1.969
2142.31	63.19	0.369	1.969
2142.33	63.31	0.369	1.969
2142.34	63.43	0.369	1.970
2142.35	63.54	0.369	1.970
2142.36	63.66	0.369	1.970
2142.37	63.78	0.370	1.970
2142.38	63.89	0.370	1.970
2142.40	64.01	0.370	1.970
2142.41	64.13	0.370	1.971
2142.42	64.24	0.370	1.971
2142.43	64.36	0.370	1.971
2142.44	64.48	0.370	1.973
2142.45	64.59	0.370	1.972
2142.46	64.71	0.370	1.973
2142.48	64.83	0.370	1.974
2142.49	64.94	0.370	1.974
2142.50	65.06	0.370	1.974
2142.51	65.18	0.370	1.975
2142.52	65.29	0.371	1.976
2142.54	65.41	0.371	1.975
2142.55	65.53	0.371	1.976
2142.56	65.65	0.371	1.977
2142.57	65.76	0.371	1.978
2142.58	65.88	0.371	1.978
2142.59	66.00	0.371	1.978
2142.60	66.11	0.371	1.978
2142.62	66.23	0.371	1.979
2142.63	66.35	0.371	1.979
2142.64	66.46	0.371	1.979
2142.65	66.58	0.371	1.980
2142.66	66.70	0.371	1.980
2142.68	66.81	0.371	1.980
2142.69	66.93	0.372	1.981
2142.70	67.05	0.372	1.981
2142.71	67.16	0.372	1.981
2142.72	67.28	0.372	1.982
2142.73	67.40	0.372	1.983
2142.75	67.51	0.372	1.982
2142.76	67.63	0.372	1.983
2142.77	67.75	0.372	1.983
2142.78	67.86	0.372	1.982
2142.79	67.98	0.372	1.984
2142.80	68.10	0.372	1.985
2142.81	68.22	0.372	1.985
2142.83	68.33	0.372	1.985
2142.84	68.45	0.373	1.986
2142.85	68.57	0.373	1.986
2142.86	68.68	0.373	1.986
2142.87	68.80	0.373	1.987
2142.89	68.92	0.373	1.986
2142.90	69.03	0.373	1.988
2142.91	69.15	0.373	1.987
2142.92	69.27	0.373	1.988
2142.93	69.38	0.373	1.988
2142.94	69.50	0.373	1.989
2142.95	69.62	0.373	1.989
2142.97	69.73	0.373	1.990
2142.98	69.85	0.374	1.990
2142.99	69.97	0.374	1.992
2143.00	70.08	0.374	1.992
2143.01	70.20	0.374	1.991
2143.03	70.32	0.374	1.992
2143.04	70.43	0.374	1.993
2143.05	70.55	0.374	1.993
2143.06	70.67	0.374	1.993
2143.07	70.78	0.374	1.993
2143.08	70.90	0.374	1.993
2143.10	71.02	0.374	1.993
2143.11	71.13	0.374	1.994
2143.12	71.25	0.374	1.993
2143.13	71.37	0.374	1.994
2143.14	71.49	0.374	1.994
2143.15	71.60	0.374	1.995
2143.16	71.72	0.374	1.995
2143.18	71.84	0.374	1.996
2143.19	71.95	0.375	1.996
2143.20	72.07	0.375	1.996
2143.21	72.19	0.375	1.997
2143.22	72.30	0.375	1.998
2143.24	72.42	0.375	1.998
2143.25	72.54	0.375	1.998
2143.26	72.65	0.375	1.998
2143.27	72.77	0.375	2.000
2143.28	72.89	0.375	2.000
2143.29	73.00	0.375	2.001
2143.30	73.12	0.375	2.001
2143.32	73.24	0.376	2.002
2143.33	73.35	0.376	2.003
2143.34	73.47	0.376	2.003
2143.35	73.59	0.376	2.003
2143.36	73.71	0.376	2.003
2143.38	73.82	0.376	2.003
2143.39	73.94	0.376	2.004
2143.40	74.05	0.376	2.004
2143.41	74.17	0.376	2.004
2143.42	74.29	0.376	2.005
2143.43	74.41	0.376	2.005
2143.45	74.52	0.376	2.005
2143.46	74.64	0.377	2.006
2143.47	74.76	0.377	2.007
2143.48	74.87	0.377	2.006
2143.49	74.99	0.377	2.008
2143.50	75.11	0.377	2.008
2143.51	75.22	0.377	2.009
2143.53	75.34	0.377	2.009
2143.54	75.46	0.377	2.009
2143.55	75.57	0.377	2.010
2143.56	75.69	0.377	2.010
2143.57	75.81	0.377	2.011
2143.59	75.92	0.377	2.011
2143.60	76.04	0.377	2.012
2143.61	76.16	0.377	2.013
2143.62	76.27	0.377	2.012
2143.63	76.39	0.378	2.012
2143.64	76.51	0.378	2.013
2143.65	76.62	0.378	2.013
2143.67	76.74	0.378	2.013
2143.68	76.86	0.378	2.015
2143.69	76.97	0.378	2.015
2143.70	77.09	0.378	2.015
2143.71	77.21	0.378	2.015
2143.73	77.33	0.378	2.016
2143.74	77.44	0.378	2.016
2143.75	77.56	0.378	2.017
2143.76	77.68	0.379	2.018
2143.77	77.79	0.379	2.018
2143.78	77.91	0.379	2.019
2143.80	78.03	0.379	2.018
2143.81	78.14	0.379	2.019
2143.82	78.26	0.379	2.020
2143.83	78.38	0.379	2.020
2143.84	78.49	0.379	2.021
2143.85	78.61	0.379	2.021
2143.86	78.73	0.379	2.022
2143.88	78.84	0.379	2.022
2143.89	78.96	0.379	2.022
2143.90	79.08	0.379	2.022
2143.91	79.19	0.379	2.023
2143.92	79.31	0.379	2.023
2143.94	79.43	0.380	2.023
2143.95	79.54	0.380	2.024
2143.96	79.66	0.380	2.024
2143.97	79.78	0.380	2.025
2143.98	79.90	0.380	2.025
2143.99	80.01	0.380	2.025
2144.00	80.13	0.380	2.025
2144.02	80.25	0.380	2.026
2144.03	80.36	0.380	2.026
2144.04	80.48	0.380	2.026
2144.05	80.60	0.380	2.027
2144.06	80.71	0.380	2.027
2144.08	80.83	0.380	2.027
2144.09	80.95	0.380	2.028
2144.10	81.06	0.380	2.028
2144.11	81.18	0.380	2.029
2144.12	81.30	0.381	2.029
2144.13	81.41	0.381	2.030
2144.15	81.53	0.381	2.030
2144.16	81.65	0.381	2.030
2144.17	81.76	0.381	2.030
2144.18	81.88	0.381	2.031
2144.19	82.00	0.381	2.031
2144.20	82.11	0.381	2.031
2144.21	82.23	0.381	2.032
2144.23	82.35	0.381	2.032
2144.24	82.46	0.381	2.032
2144.25	82.58	0.381	2.033
2144.26	82.70	0.381	2.033
2144.27	82.81	0.381	2.034
2144.29	82.93	0.381	2.034
2144.30	83.05	0.381	2.033
2144.31	83.16	0.381	2.033
2144.32	83.28	0.381	2.034
2144.33	83.40	0.381	2.034
2144.34	83.51	0.381	2.034
2144.35	83.63	0.382	2.035
2144.37	83.75	0.382	2.035
2144.38	83.86	0.382	2.035
2144.39	83.98	0.382	2.035
2144.40	84.10	0.382	2.036
2144.41	84.22	0.382	2.036
2144.43	84.33	0.382	2.036
2144.44	84.45	0.382	2.036
2144.45	84.57	0.382	2.037
2144.46	84.68	0.382	2.036
2144.47	84.80	0.382	2.037
2144.48	84.92	0.382	2.038
2144.50	85.03	0.382	2.039
2144.51	85.15	0.382	2.039
2144.52	85.27	0.382	2.039
2144.53	85.38	0.382	2.039
2144.54	85.50	0.382	2.041
2144.55	85.62	0.382	2.040
2144.56	85.73	0.382	2.040
2144.58	85.85	0.383	2.040
2144.59	85.97	0.383	2.041
2144.60	86.08	0.383	2.040
2144.61	86.20	0.383	2.041
2144.62	86.32	0.383	2.040
2144.64	86.44	0.383	2.041
2144.65	86.55	0.383	2.041
2144.66	86.67	0.383	2.041
2144.67	86.79	0.383	2.042
2144.68	86.90	0.383	2.042
2144.69	87.02	0.383	2.043
2144.70	87.14	0.383	2.042
2144.72	87.25	0.383	2.043
2144.73	87.37	0.383	2.044
2144.74	87.49	0.383	2.044
2144.75	87.60	0.383	2.044
2144.76	87.72	0.383	2.045
2144.78	87.84	0.383	2.046
2144.79	87.95	0.383	2.045
2144.80	88.07	0.384	2.046
2144.81	88.19	0.384	2.047
2144.82	88.30	0.384	2.047
2144.83	88.42	0.384	2.047
2144.85	88.54	0.384	2.048
2144.86	88.65	0.384	2.047
2144.87	88.77	0.384	2.048
2144.88	88.89	0.384	2.049
2144.89	89.00	0.384	2.049
2144.90	89.12	0.384	2.049
2144.91	89.24	0.384	2.049
2144.93	89.35	0.384	2.049
2144.94	89.47	0.384	2.050
2144.95	89.59	0.384	2.049
2144.96	89.71	0.384	2.051
2144.97	89.82	0.385	2.051
2144.99	89.94	0.385	2.051
2145.00	90.05	0.385	2.051
2145.01	90.17	0.385	2.052
2145.02	90.29	0.385	2.053
2145.03	90.40	0.385	2.053
2145.04	90.52	0.385	2.053
2145.05	90.64	0.385	2.053
2145.07	90.76	0.385	2.054
2145.08	90.87	0.385	2.055
2145.09	90.99	0.385	2.055
2145.10	91.11	0.386	2.055
2145.11	91.22	0.386	2.056
2145.13	91.34	0.386	2.057
2145.14	91.46	0.386	2.056
2145.15	91.57	0.386	2.057
2145.16	91.69	0.386	2.057
2145.17	91.81	0.386	2.057
2145.18	91.92	0.386	2.058
2145.20	92.04	0.386	2.058
2145.21	92.16	0.386	2.058
2145.22	92.27	0.386	2.058
2145.23	92.39	0.387	2.059
2145.24	92.51	0.387	2.059
2145.25	92.63	0.387	2.060
2145.26	92.74	0.387	2.061
2145.28	92.86	0.387	2.060
2145.29	92.98	0.387	2.061
2145.30	93.09	0.387	2.062
2145.31	93.21	0.387	2.062
2145.32	93.33	0.387	2.062
2145.34	93.44	0.387	2.063
2145.35	93.56	0.388	2.064
2145.36	93.68	0.388	2.064
2145.37	93.79	0.388	2.065
2145.38	93.91	0.388	2.065
2145.39	94.03	0.388	2.066
2145.40	94.14	0.388	2.066
2145.42	94.26	0.388	2.067
2145.43	94.38	0.388	2.067
2145.44	94.50	0.388	2.068
2145.45	94.61	0.388	2.068
2145.46	94.73	0.388	2.069
2145.48	94.85	0.388	2.070
2145.49	94.96	0.389	2.069
2145.50	95.08	0.389	2.070
2145.51	95.20	0.389	2.071
2145.52	95.31	0.389	2.071
2145.53	95.43	0.389	2.072
2145.55	95.55	0.389	2.071
2145.56	95.66	0.389	2.072
2145.57	95.78	0.389	2.073
2145.58	95.90	0.389	2.073
2145.59	96.01	0.389	2.073
2145.60	96.13	0.389	2.074
2145.61	96.25	0.389	2.074
2145.63	96.36	0.389	2.075
2145.64	96.48	0.389	2.075
2145.65	96.60	0.389	2.075
2145.66	96.71	0.390	2.076
2145.67	96.83	0.390	2.076
2145.69	96.95	0.390	2.076
2145.70	97.07	0.390	2.076
2145.71	97.18	0.390	2.076
2145.72	97.30	0.390
2145.73	97.42	0.390
2145.74	97.53	0.390
2145.75	97.65	0.390
2145.77	97.77	0.390
2145.78	97.88
2145.79	98.00
2145.80	98.12
2145.81	98.23
2145.83	98.35
2145.83