File: DSC/2023_06_13_OTP_Fragility.txt
Filename	2023_06_13_OTP_Fragility
Instrument name	DSC2A-00468 (192.168.1.100)
Operator	SBK
rundate	6/13/2023
Sample name	2023_06_13_OTP_Fragility
proceduresegments	Data Off ; Equilibrate -50.00 °C; Data On ; Ramp 10.00 °C/min to 80.00 °C; Data Off ; Isothermal 1.0 min; Data On ; Ramp 10.00 °C/min to -50.00 °C; Data Off ; Isothermal 1.0 min; Data On ; Ramp 10.00 °C/min to 80.00 °C; Data Off ; Isothermal 1.0 min; Data On ; Ramp 30.00 °C/min to -50.00 °C; Data Off ; Isothermal 1.0 min; Data On ; Ramp 10.00 °C/min to 80.00 °C; Data Off ; Isothermal 1.0 min; Data On ; Ramp 25.00 °C/min to -50.00 °C; Data Off ; Isothermal 1.0 min; Data On ; Ramp 10.00 °C/min to 80.00 °C; Data Off ; Isothermal 1.0 min; Data On ; Ramp 20.00 °C/min to -50.00 °C; Data Off ; Isothermal 1.0 min; Data On ; Ramp 10.00 °C/min to 80.00 °C; Data Off ; Isothermal 1.0 min; Data On ; Ramp 5.00 °C/min to -50.00 °C; Data Off ; Isothermal 1.0 min; Data On ; Ramp 10.00 °C/min to 80.00 °C
[File Parameters]
Run date	6/13/2023 4:37:05 PM
Trios version	5.1.1.46572
Original File Name	C:\Users\yargerlab\Desktop\DSC Data\General\2023_06_13_OTP_Fragility.tri
Current File Name	C:\Users\yargerlab\Desktop\DSC Data\General\2023_06_13_OTP_Fragility.tri
[Procedure]
Procedure Name	DSC -50C to 80C Varied cooling rates OTP fragility
Sample Name	2023_06_13_OTP_Fragility
Sample Mass	4.3 mg
Reference Sample Mass	0 mg
Pan Mass	53.88 mg
Pan Number	49
Reference Pan Mass	53.66 mg
Reference Pan Number	46
Pan Type	Aluminum Hermetic
Comments	First run with new sample of o-Terphenyl. Goal to obtain fragility data to confirm with literature values before runs with CBD.
Project Name	Silk ASDs
Operator	SBK
Test	Custom
Unload Max Temperature	30
Unload Min Temperature	30
Load Max Temperature	30
Load Min Temperature	30
Stop on Gas Flow Error	Yes
[Signal List]
Signal #1	Time (min)
Signal #2	Temperature (°C)
Signal #3	Heat Flow (mW)
Signal #4	Delta T (µV)
Signal #5	Delta Tzero (µV)
Signal #6	Tzero Temperature (°C)
Signal #7	Cell Purge (mL/min)
Signal #8	Heater Temp (°C)
Signal #9	Power Delivered (W)
Signal #10	Reference Junction Temperature (°C)
Signal #11	Flange Temperature (°C)
Signal #12	Heat Flow Phase (rad)
Signal #13	Total Heat Capacity (J/°C)
Signal #14	Heat Capacity (J/°C)
[Configuration]
Company Name	ASU
Instrument Name	DSC2A-00468
Instrument Type	DSC2500
Serial Number	DSC2A-00468
IP	192.168.1.100
Location of Instrument	MRRC
DisplayType	Unknown
Sample Interval 	0.1 s/pt
Selected Heat Flow	T4P
Exotherm Direction	Down
Cell Serial	DRC2-00792
Lid Type	Standard
Cooler	RCS 90
Leave Cooler on at End of Sequence	On
Gas 2	Nitrogen
Gas Selected	Channel 1
Flow Rate	50 mL/min
Secondary Purge	On
Licensed Heat Flow	Heat Flow T4P
Modulation Licensed	Yes
[Versions]
Common IDD Version	1
Cortex Version	VER 2.10.2.31
Driver	5.0.0.6
GDM Version	1.0.3.3
TouchscreenVersion	1.0.0.16145
FEP Version	1.2.1.21
FEP Bootloader	2.0.0.5
AutoSampler Version	2.1.1.26
Auto Sampler Bootloader	2.0.0.5
FCM Version	1.1.0.3
FCM Bootloader	2.0.0.5
[Experiment Logs]
Experiment Log Entry # 1	Data On set to 0
Experiment Log Entry # 3	Equilibrate Segment -50 (C) Started
Experiment Log Entry # 5	Air Cool is off.
Experiment Log Entry # 7	Data On set to 1
Experiment Log Entry # 9	Ramp Segment 10 C/min to 80 Started
Experiment Log Entry # 11	Data On set to 0
Experiment Log Entry # 13	Isothermal Segment 1 min started
Experiment Log Entry # 15	Data On set to 1
Experiment Log Entry # 17	Ramp Segment 10 C/min to -50 Started
Experiment Log Entry # 19	Data On set to 0
Experiment Log Entry # 21	Isothermal Segment 1 min started
Experiment Log Entry # 23	Data On set to 1
Experiment Log Entry # 25	Ramp Segment 10 C/min to 80 Started
Experiment Log Entry # 27	Data On set to 0
Experiment Log Entry # 29	Isothermal Segment 1 min started
Experiment Log Entry # 31	Data On set to 1
Experiment Log Entry # 33	Ramp Segment 30 C/min to -50 Started
Experiment Log Entry # 35	Data On set to 0
Experiment Log Entry # 37	Isothermal Segment 1 min started
Experiment Log Entry # 39	Data On set to 1
Experiment Log Entry # 41	Ramp Segment 10 C/min to 80 Started
Experiment Log Entry # 43	Data On set to 0
Experiment Log Entry # 45	Isothermal Segment 1 min started
Experiment Log Entry # 47	Data On set to 1
Experiment Log Entry # 49	Ramp Segment 25 C/min to -50 Started
Experiment Log Entry # 51	Data On set to 0
Experiment Log Entry # 53	Isothermal Segment 1 min started
Experiment Log Entry # 55	Data On set to 1
Experiment Log Entry # 57	Ramp Segment 10 C/min to 80 Started
Experiment Log Entry # 59	Data On set to 0
Experiment Log Entry # 61	Isothermal Segment 1 min started
Experiment Log Entry # 63	Data On set to 1
Experiment Log Entry # 65	Ramp Segment 20 C/min to -50 Started
Experiment Log Entry # 67	Data On set to 0
Experiment Log Entry # 69	Isothermal Segment 1 min started
Experiment Log Entry # 71	Data On set to 1
Experiment Log Entry # 73	Ramp Segment 10 C/min to 80 Started
Experiment Log Entry # 75	Data On set to 0
Experiment Log Entry # 77	Isothermal Segment 1 min started
Experiment Log Entry # 79	Data On set to 1
Experiment Log Entry # 81	Ramp Segment 5 C/min to -50 Started
Experiment Log Entry # 83	Auto sampler has detected that GDM has gone offline
Experiment Log Entry # 85	Data On set to 0
Experiment Log Entry # 87	Isothermal Segment 1 min started
Experiment Log Entry # 89	Data On set to 1
Experiment Log Entry # 91	Ramp Segment 10 C/min to 80 Started
[Method Log]
Method Log Entry # 1	Data Off
Method Log Entry # 2	Equilibrate -50 °C
Method Log Entry # 3	Data On
Method Log Entry # 4	(Ramp 8536) Ramp 10 °C/minute to 80 °C
Method Log Entry # 5	Data Off
Method Log Entry # 6	Isothermal 1 minutes
Method Log Entry # 7	Data On
Method Log Entry # 8	(Ramp 8540) Ramp 10 °C/minute to -50 °C
Method Log Entry # 9	Data Off
Method Log Entry # 10	Isothermal 1 minutes
Method Log Entry # 11	Data On
Method Log Entry # 12	(Ramp 8544) Ramp 10 °C/minute to 80 °C
Method Log Entry # 13	Data Off
Method Log Entry # 14	Isothermal 1 minutes
Method Log Entry # 15	Data On
Method Log Entry # 16	(Ramp 8548) Ramp 30 °C/minute to -50 °C
Method Log Entry # 17	Data Off
Method Log Entry # 18	Isothermal 1 minutes
Method Log Entry # 19	Data On
Method Log Entry # 20	(Ramp 8552) Ramp 10 °C/minute to 80 °C
Method Log Entry # 21	Data Off
Method Log Entry # 22	Isothermal 1 minutes
Method Log Entry # 23	Data On
Method Log Entry # 24	(Ramp 8556) Ramp 25 °C/minute to -50 °C
Method Log Entry # 25	Data Off
Method Log Entry # 26	Isothermal 1 minutes
Method Log Entry # 27	Data On
Method Log Entry # 28	(Ramp 8560) Ramp 10 °C/minute to 80 °C
Method Log Entry # 29	Data Off
Method Log Entry # 30	Isothermal 1 minutes
Method Log Entry # 31	Data On
Method Log Entry # 32	(Ramp 8564) Ramp 20 °C/minute to -50 °C
Method Log Entry # 33	Data Off
Method Log Entry # 34	Isothermal 1 minutes
Method Log Entry # 35	Data On
Method Log Entry # 36	(Ramp 8568) Ramp 10 °C/minute to 80 °C
Method Log Entry # 37	Data Off
Method Log Entry # 38	Isothermal 1 minutes
Method Log Entry # 39	Data On
Method Log Entry # 40	(Ramp 8572) Ramp 5 °C/minute to -50 °C
Method Log Entry # 41	Data Off
Method Log Entry # 42	Isothermal 1 minutes
Method Log Entry # 43	Data On
Method Log Entry # 44	(Ramp 8576) Ramp 10 °C/minute to 80 °C
Cell Serial	DRC2-00792
[T1 Calibration]
Slope	-0.008529666
Offset	9.636258
Initial Temperature	98.23
GUID	f8bfdadc-4977-4fdf-ba6d-0ba9134940c3
[TZero Calibration]
Date Applied	11/29/2022 4:06:13 PM
Description	From -89.059 °C to 396.009 °C at 20.000°C/min
Gas Type	Nitrogen
Pan Type	None
Source Files 1	C:\Users\yargerlab\Desktop\DSC Data\General\TZero_calibration_11_29_22_2nd(2).tri
Source Files 2	C:\Users\yargerlab\Desktop\DSC Data\General\TZero_calibration_11_29_22_2nd(3).tri
Delta T Offset	13.05235
Delta T Slope	-0.007271007
Delta T0 Offset	-13.69128
Delta T0 Slope	0.06063341
[Temperature Calibration]
Date Applied	11/29/2022 7:12:28 PM
Description	From 106.590 °C to 186.590 °C at 10.000°C/min
Gas Type	Nitrogen
Pan Type	Tzero Aluminum Hermetic
Source Files 1	C:\Users\yargerlab\Desktop\DSC Data\General\Indium(6).tri
Measured 1	157.391
Known 1	156.598
[Cell Constant Calibration]
Date Applied	11/29/2022 7:12:29 PM
Description	From 106.590 °C to 186.590 °C at 10.000°C/min
Gas Type	Nitrogen
Pan Type	Tzero Aluminum Hermetic
Source Files 1	C:\Users\yargerlab\Desktop\DSC Data\General\Indium(6).tri
T4P KCell	1.006051
Onset Slope	63.26126 mW/°C
[Direct Cp Calibration]
Date Applied	11/30/2022 11:04:51 AM
Description	From -79.983 °C to 298.409 °C at 10.000°C/min
Gas Type	Nitrogen
Pan Type	Tzero Aluminum Hermetic
Source Files 1	C:\Users\yargerlab\Desktop\DSC Data\General\Sapphire_Heat_Capacity_11_30_22.tri
[Rev Cp Calibration]
Date Applied	11/30/2022 1:58:51 PM
Description	From -79.996 °C to 292.812 °C at 3.000°C/min
Gas Type	Nitrogen
Pan Type	Tzero Aluminum Hermetic
Source Files 1	C:\Users\yargerlab\Desktop\DSC Data\General\Sapphire_MDSC_Calibration_11_30_22.tri
[step]
Ramp 10.00 °C/min to 80.00 °C
Time	Temperature	Heat Flow (Normalized)
min	°C	W/g
0.00	-49.73	-0.047
0.01	-49.74	-0.047
0.02	-49.74	-0.045
0.03	-49.75	-0.041
0.04	-49.75	-0.039
0.05	-49.75	-0.038
0.06	-49.74	-0.039
0.07	-49.74	-0.040
0.08	-49.72	-0.047
0.09	-49.70	-0.063
0.10	-49.67	-0.077
0.11	-49.64	-0.087
0.12	-49.60	-0.098
0.13	-49.55	-0.105
0.14	-49.50	-0.111
0.15	-49.45	-0.112
0.16	-49.39	-0.112
0.17	-49.32	-0.108
0.18	-49.26	-0.105
0.19	-49.18	-0.098
0.20	-49.11	-0.084
0.21	-49.04	-0.072
0.22	-48.96	-0.059
0.23	-48.88	-0.049
0.24	-48.80	-0.038
0.25	-48.72	-0.029
0.26	-48.64	-0.019
0.27	-48.55	-0.008
0.28	-48.47	-0.002
0.29	-48.38	0.007
0.30	-48.30	0.015
0.31	-48.21	0.020
0.32	-48.12	0.026
0.33	-48.03	0.030
0.34	-47.94	0.037
0.35	-47.85	0.042
0.36	-47.76	0.046
0.37	-47.67	0.051
0.38	-47.58	0.053
0.39	-47.49	0.057
0.40	-47.39	0.060
0.41	-47.30	0.063
0.42	-47.21	0.066
0.43	-47.11	0.069
0.44	-47.02	0.072
0.45	-46.93	0.074
0.46	-46.83	0.077
0.47	-46.73	0.077
0.48	-46.64	0.079
0.49	-46.54	0.082
0.50	-46.45	0.083
0.51	-46.35	0.084
0.52	-46.26	0.086
0.53	-46.16	0.087
0.54	-46.06	0.087
0.55	-45.97	0.088
0.56	-45.87	0.089
0.57	-45.77	0.090
0.58	-45.68	0.091
0.59	-45.58	0.091
0.60	-45.48	0.092
0.61	-45.38	0.092
0.62	-45.29	0.093
0.63	-45.19	0.094
0.64	-45.09	0.094
0.65	-44.99	0.094
0.66	-44.90	0.095
0.67	-44.80	0.095
0.68	-44.70	0.096
0.69	-44.60	0.096
0.70	-44.51	0.096
0.71	-44.41	0.097
0.72	-44.31	0.097
0.73	-44.21	0.098
0.74	-44.11	0.098
0.75	-44.01	0.098
0.76	-43.92	0.098
0.77	-43.82	0.098
0.78	-43.72	0.099
0.79	-43.62	0.099
0.80	-43.52	0.099
0.81	-43.42	0.099
0.82	-43.33	0.099
0.83	-43.23	0.099
0.84	-43.13	0.100
0.85	-43.03	0.100
0.86	-42.93	0.100
0.87	-42.83	0.100
0.88	-42.73	0.100
0.89	-42.63	0.100
0.90	-42.54	0.101
0.91	-42.44	0.101
0.92	-42.34	0.101
0.93	-42.24	0.101
0.94	-42.14	0.101
0.95	-42.04	0.101
0.96	-41.94	0.101
0.97	-41.84	0.102
0.98	-41.74	0.102
0.99	-41.64	0.102
1.00	-41.55	0.102
1.01	-41.44	0.102
1.02	-41.35	0.102
1.03	-41.25	0.102
1.04	-41.15	0.102
1.05	-41.05	0.103
1.06	-40.95	0.103
1.07	-40.85	0.103
1.08	-40.75	0.103
1.09	-40.65	0.103
1.10	-40.55	0.103
1.11	-40.45	0.103
1.12	-40.35	0.103
1.13	-40.25	0.103
1.14	-40.15	0.103
1.15	-40.05	0.103
1.16	-39.95	0.104
1.17	-39.86	0.104
1.18	-39.75	0.104
1.19	-39.66	0.104
1.20	-39.56	0.104
1.21	-39.46	0.104
1.22	-39.36	0.104
1.23	-39.26	0.104
1.24	-39.16	0.104
1.25	-39.06	0.104
1.26	-38.96	0.104
1.27	-38.86	0.104
1.28	-38.76	0.104
1.29	-38.66	0.104
1.30	-38.56	0.104
1.31	-38.46	0.104
1.32	-38.36	0.104
1.33	-38.26	0.105
1.34	-38.16	0.105
1.35	-38.06	0.105
1.36	-37.96	0.105
1.37	-37.86	0.105
1.38	-37.76	0.105
1.39	-37.66	0.105
1.40	-37.56	0.105
1.41	-37.46	0.105
1.42	-37.36	0.105
1.43	-37.27	0.105
1.44	-37.16	0.105
1.45	-37.06	0.105
1.46	-36.96	0.105
1.47	-36.86	0.105
1.48	-36.76	0.105
1.49	-36.66	0.105
1.50	-36.57	0.105
1.51	-36.46	0.105
1.52	-36.37	0.105
1.53	-36.26	0.105
1.54	-36.16	0.105
1.55	-36.06	0.105
1.56	-35.97	0.105
1.57	-35.87	0.105
1.58	-35.77	0.105
1.59	-35.67	0.105
1.60	-35.56	0.105
1.61	-35.47	0.105
1.62	-35.37	0.105
1.63	-35.27	0.105
1.64	-35.17	0.105
1.65	-35.07	0.105
1.66	-34.97	0.105
1.67	-34.87	0.106
1.68	-34.77	0.106
1.69	-34.67	0.106
1.70	-34.57	0.106
1.71	-34.47	0.106
1.72	-34.37	0.106
1.73	-34.27	0.106
1.74	-34.17	0.106
1.75	-34.07	0.106
1.76	-33.97	0.106
1.77	-33.87	0.106
1.78	-33.77	0.106
1.79	-33.67	0.106
1.80	-33.57	0.106
1.81	-33.47	0.106
1.82	-33.37	0.106
1.83	-33.27	0.106
1.84	-33.17	0.106
1.85	-33.07	0.106
1.86	-32.97	0.106
1.87	-32.87	0.106
1.88	-32.77	0.106
1.89	-32.67	0.106
1.90	-32.57	0.106
1.91	-32.47	0.106
1.92	-32.37	0.106
1.93	-32.27	0.106
1.94	-32.17	0.106
1.95	-32.07	0.106
1.96	-31.97	0.106
1.97	-31.86	0.106
1.98	-31.77	0.106
1.99	-31.67	0.106
2.00	-31.57	0.106
2.01	-31.47	0.106
2.02	-31.37	0.106
2.03	-31.27	0.106
2.04	-31.17	0.106
2.05	-31.07	0.106
2.06	-30.97	0.106
2.07	-30.87	0.106
2.08	-30.77	0.106
2.09	-30.66	0.106
2.10	-30.57	0.106
2.11	-30.47	0.106
2.12	-30.36	0.106
2.13	-30.26	0.106
2.14	-30.16	0.106
2.15	-30.06	0.106
2.16	-29.96	0.106
2.17	-29.86	0.106
2.18	-29.76	0.106
2.19	-29.66	0.106
2.20	-29.56	0.106
2.21	-29.46	0.106
2.22	-29.36	0.106
2.23	-29.26	0.106
2.24	-29.16	0.106
2.25	-29.06	0.106
2.26	-28.96	0.106
2.27	-28.86	0.106
2.28	-28.76	0.106
2.29	-28.66	0.106
2.30	-28.56	0.106
2.31	-28.46	0.106
2.32	-28.36	0.106
2.33	-28.26	0.106
2.34	-28.16	0.106
2.35	-28.06	0.106
2.36	-27.96	0.106
2.37	-27.86	0.106
2.38	-27.76	0.106
2.39	-27.66	0.106
2.40	-27.56	0.106
2.41	-27.46	0.106
2.42	-27.36	0.106
2.43	-27.26	0.106
2.44	-27.16	0.106
2.45	-27.06	0.106
2.46	-26.96	0.106
2.47	-26.86	0.106
2.48	-26.76	0.106
2.49	-26.66	0.106
2.50	-26.56	0.106
2.51	-26.46	0.106
2.52	-26.36	0.106
2.53	-26.26	0.106
2.54	-26.16	0.106
2.55	-26.06	0.106
2.56	-25.96	0.106
2.57	-25.86	0.106
2.58	-25.76	0.106
2.59	-25.66	0.106
2.60	-25.56	0.106
2.61	-25.46	0.106
2.62	-25.36	0.106
2.63	-25.26	0.106
2.64	-25.16	0.106
2.65	-25.06	0.106
2.66	-24.96	0.106
2.67	-24.86	0.106
2.68	-24.76	0.106
2.69	-24.66	0.106
2.70	-24.56	0.106
2.71	-24.46	0.106
2.72	-24.36	0.107
2.73	-24.26	0.107
2.74	-24.16	0.107
2.75	-24.06	0.107
2.76	-23.96	0.107
2.77	-23.86	0.107
2.78	-23.76	0.107
2.79	-23.66	0.107
2.80	-23.56	0.107
2.81	-23.46	0.107
2.82	-23.36	0.107
2.83	-23.26	0.107
2.84	-23.16	0.107
2.85	-23.06	0.107
2.86	-22.96	0.107
2.87	-22.86	0.107
2.88	-22.76	0.107
2.89	-22.66	0.107
2.90	-22.56	0.107
2.91	-22.46	0.107
2.92	-22.36	0.107
2.93	-22.26	0.107
2.94	-22.16	0.107
2.95	-22.06	0.107
2.96	-21.96	0.107
2.97	-21.86	0.107
2.98	-21.76	0.107
2.99	-21.66	0.107
3.00	-21.56	0.107
3.01	-21.46	0.107
3.02	-21.36	0.107
3.03	-21.25	0.107
3.04	-21.16	0.107
3.05	-21.06	0.107
3.06	-20.96	0.107
3.07	-20.85	0.107
3.08	-20.75	0.107
3.09	-20.65	0.107
3.10	-20.56	0.107
3.11	-20.45	0.107
3.12	-20.35	0.107
3.13	-20.25	0.107
3.14	-20.15	0.107
3.15	-20.05	0.107
3.16	-19.95	0.107
3.17	-19.85	0.107
3.18	-19.75	0.107
3.19	-19.65	0.107
3.20	-19.55	0.107
3.21	-19.45	0.107
3.22	-19.35	0.107
3.23	-19.25	0.107
3.24	-19.15	0.107
3.25	-19.05	0.107
3.26	-18.95	0.108
3.27	-18.85	0.108
3.28	-18.75	0.108
3.29	-18.65	0.108
3.30	-18.55	0.108
3.31	-18.45	0.108
3.32	-18.35	0.108
3.33	-18.25	0.108
3.34	-18.15	0.108
3.35	-18.05	0.108
3.36	-17.95	0.108
3.37	-17.85	0.108
3.38	-17.75	0.108
3.39	-17.65	0.108
3.40	-17.55	0.108
3.41	-17.45	0.108
3.42	-17.35	0.108
3.43	-17.25	0.108
3.44	-17.15	0.108
3.45	-17.05	0.108
3.46	-16.95	0.108
3.47	-16.85	0.108
3.48	-16.75	0.108
3.49	-16.65	0.108
3.50	-16.55	0.108
3.51	-16.45	0.108
3.52	-16.35	0.108
3.53	-16.25	0.108
3.54	-16.15	0.108
3.55	-16.05	0.108
3.56	-15.95	0.108
3.57	-15.85	0.108
3.58	-15.75	0.108
3.59	-15.65	0.108
3.60	-15.55	0.108
3.61	-15.45	0.108
3.62	-15.35	0.108
3.63	-15.25	0.108
3.64	-15.15	0.108
3.65	-15.05	0.108
3.66	-14.94	0.108
3.67	-14.85	0.108
3.68	-14.74	0.108
3.69	-14.65	0.108
3.70	-14.54	0.108
3.71	-14.45	0.108
3.72	-14.34	0.108
3.73	-14.25	0.108
3.74	-14.14	0.108
3.75	-14.04	0.109
3.76	-13.94	0.109
3.77	-13.84	0.109
3.78	-13.74	0.109
3.79	-13.64	0.109
3.80	-13.54	0.109
3.81	-13.44	0.109
3.82	-13.34	0.109
3.83	-13.24	0.109
3.84	-13.14	0.109
3.85	-13.04	0.109
3.86	-12.94	0.109
3.87	-12.84	0.109
3.88	-12.74	0.109
3.89	-12.64	0.109
3.90	-12.54	0.109
3.91	-12.44	0.109
3.92	-12.34	0.109
3.93	-12.24	0.109
3.94	-12.14	0.109
3.95	-12.04	0.109
3.96	-11.94	0.109
3.97	-11.84	0.109
3.98	-11.74	0.109
3.99	-11.64	0.109
4.00	-11.54	0.109
4.01	-11.44	0.109
4.02	-11.34	0.109
4.03	-11.24	0.109
4.04	-11.14	0.109
4.05	-11.04	0.110
4.06	-10.94	0.110
4.07	-10.84	0.109
4.08	-10.74	0.110
4.09	-10.64	0.110
4.10	-10.54	0.110
4.11	-10.44	0.110
4.12	-10.34	0.110
4.13	-10.24	0.110
4.14	-10.14	0.110
4.15	-10.04	0.110
4.16	-9.94	0.110
4.17	-9.84	0.110
4.18	-9.74	0.110
4.19	-9.64	0.110
4.20	-9.54	0.110
4.21	-9.44	0.110
4.22	-9.34	0.110
4.23	-9.24	0.110
4.24	-9.14	0.110
4.25	-9.04	0.110
4.26	-8.94	0.110
4.27	-8.84	0.110
4.28	-8.74	0.110
4.29	-8.64	0.110
4.30	-8.54	0.110
4.31	-8.44	0.110
4.32	-8.34	0.110
4.33	-8.24	0.110
4.34	-8.14	0.111
4.35	-8.04	0.110
4.36	-7.94	0.110
4.37	-7.84	0.111
4.38	-7.74	0.111
4.39	-7.64	0.111
4.40	-7.54	0.111
4.41	-7.44	0.111
4.42	-7.34	0.111
4.43	-7.24	0.111
4.44	-7.14	0.111
4.45	-7.04	0.111
4.46	-6.94	0.111
4.47	-6.84	0.111
4.48	-6.74	0.111
4.49	-6.64	0.111
4.50	-6.54	0.111
4.51	-6.43	0.111
4.52	-6.34	0.111
4.53	-6.23	0.111
4.54	-6.13	0.111
4.55	-6.04	0.111
4.56	-5.94	0.111
4.57	-5.83	0.111
4.58	-5.73	0.112
4.59	-5.63	0.112
4.60	-5.53	0.112
4.61	-5.43	0.112
4.62	-5.33	0.112
4.63	-5.23	0.112
4.64	-5.13	0.112
4.65	-5.03	0.112
4.66	-4.93	0.112
4.67	-4.83	0.112
4.68	-4.73	0.112
4.69	-4.63	0.112
4.70	-4.53	0.112
4.71	-4.43	0.112
4.72	-4.33	0.112
4.73	-4.23	0.112
4.74	-4.13	0.112
4.75	-4.03	0.112
4.76	-3.93	0.112
4.77	-3.83	0.112
4.78	-3.73	0.112
4.79	-3.63	0.112
4.80	-3.53	0.112
4.81	-3.43	0.112
4.82	-3.33	0.112
4.83	-3.23	0.112
4.84	-3.13	0.112
4.85	-3.03	0.113
4.86	-2.93	0.113
4.87	-2.83	0.113
4.88	-2.73	0.113
4.89	-2.63	0.113
4.90	-2.53	0.113
4.91	-2.43	0.113
4.92	-2.33	0.113
4.93	-2.23	0.113
4.94	-2.13	0.113
4.95	-2.03	0.113
4.96	-1.93	0.113
4.97	-1.83	0.113
4.98	-1.73	0.113
4.99	-1.63	0.113
5.00	-1.53	0.113
5.01	-1.43	0.113
5.02	-1.33	0.113
5.03	-1.23	0.113
5.04	-1.13	0.113
5.05	-1.03	0.113
5.06	-0.93	0.113
5.07	-0.83	0.114
5.08	-0.73	0.114
5.09	-0.63	0.114
5.10	-0.53	0.114
5.11	-0.43	0.114
5.12	-0.33	0.114
5.13	-0.23	0.114
5.14	-0.13	0.114
5.15	-0.03	0.114
5.16	0.07	0.114
5.17	0.17	0.114
5.18	0.27	0.114
5.19	0.37	0.114
5.20	0.47	0.114
5.21	0.57	0.114
5.22	0.67	0.114
5.23	0.78	0.114
5.24	0.88	0.114
5.25	0.98	0.114
5.26	1.07	0.114
5.27	1.18	0.114
5.28	1.28	0.114
5.29	1.38	0.114
5.30	1.48	0.114
5.31	1.58	0.114
5.32	1.68	0.115
5.33	1.78	0.115
5.34	1.88	0.115
5.35	1.98	0.115
5.36	2.08	0.115
5.37	2.18	0.115
5.38	2.28	0.115
5.39	2.38	0.115
5.40	2.48	0.115
5.41	2.58	0.115
5.42	2.68	0.115
5.43	2.78	0.115
5.44	2.88	0.115
5.45	2.98	0.115
5.46	3.08	0.115
5.47	3.18	0.115
5.48	3.28	0.115
5.49	3.38	0.115
5.50	3.48	0.115
5.51	3.58	0.115
5.52	3.68	0.115
5.53	3.78	0.115
5.54	3.88	0.115
5.55	3.98	0.115
5.56	4.08	0.115
5.57	4.18	0.116
5.58	4.28	0.116
5.59	4.38	0.116
5.60	4.48	0.116
5.61	4.58	0.116
5.62	4.68	0.116
5.63	4.78	0.116
5.64	4.88	0.116
5.65	4.98	0.116
5.66	5.08	0.116
5.67	5.18	0.116
5.68	5.28	0.116
5.69	5.38	0.116
5.70	5.48	0.116
5.71	5.58	0.116
5.72	5.68	0.116
5.73	5.78	0.116
5.74	5.88	0.116
5.75	5.98	0.117
5.76	6.08	0.117
5.77	6.18	0.117
5.78	6.28	0.117
5.79	6.38	0.117
5.80	6.48	0.117
5.81	6.58	0.117
5.82	6.68	0.117
5.83	6.78	0.117
5.84	6.88	0.117
5.85	6.98	0.117
5.86	7.08	0.117
5.87	7.18	0.117
5.88	7.28	0.117
5.89	7.38	0.117
5.90	7.48	0.117
5.91	7.58	0.117
5.92	7.68	0.117
5.93	7.78	0.118
5.94	7.88	0.118
5.95	7.98	0.118
5.96	8.08	0.118
5.97	8.18	0.118
5.98	8.28	0.118
5.99	8.38	0.118
6.00	8.48	0.118
6.01	8.58	0.118
6.02	8.68	0.118
6.03	8.78	0.118
6.04	8.88	0.118
6.05	8.98	0.118
6.06	9.08	0.118
6.07	9.18	0.118
6.08	9.28	0.118
6.09	9.39	0.118
6.10	9.48	0.118
6.11	9.59	0.118
6.12	9.69	0.118
6.13	9.79	0.118
6.14	9.89	0.118
6.15	9.99	0.118
6.16	10.09	0.118
6.17	10.19	0.118
6.18	10.29	0.118
6.19	10.39	0.118
6.20	10.49	0.118
6.21	10.59	0.118
6.22	10.69	0.119
6.23	10.79	0.119
6.24	10.89	0.119
6.25	10.99	0.119
6.26	11.09	0.119
6.27	11.19	0.119
6.28	11.29	0.119
6.29	11.39	0.119
6.30	11.49	0.119
6.31	11.59	0.119
6.32	11.69	0.119
6.33	11.79	0.119
6.34	11.89	0.119
6.35	11.99	0.119
6.36	12.09	0.119
6.37	12.19	0.120
6.38	12.29	0.120
6.39	12.39	0.120
6.40	12.49	0.120
6.41	12.59	0.120
6.42	12.69	0.120
6.43	12.79	0.120
6.44	12.89	0.120
6.45	12.99	0.120
6.46	13.09	0.120
6.47	13.19	0.120
6.48	13.29	0.120
6.49	13.39	0.120
6.50	13.49	0.120
6.51	13.59	0.120
6.52	13.69	0.120
6.53	13.79	0.120
6.54	13.89	0.120
6.55	13.99	0.120
6.56	14.09	0.121
6.57	14.19	0.121
6.58	14.29	0.121
6.59	14.39	0.121
6.60	14.49	0.121
6.61	14.59	0.121
6.62	14.69	0.121
6.63	14.79	0.121
6.64	14.89	0.121
6.65	14.99	0.121
6.66	15.09	0.121
6.67	15.19	0.121
6.68	15.29	0.121
6.69	15.39	0.121
6.70	15.49	0.121
6.71	15.59	0.121
6.72	15.69	0.121
6.73	15.79	0.121
6.74	15.89	0.121
6.75	15.99	0.122
6.76	16.09	0.122
6.77	16.19	0.122
6.78	16.29	0.122
6.79	16.39	0.122
6.80	16.49	0.122
6.81	16.59	0.122
6.82	16.69	0.122
6.83	16.79	0.122
6.84	16.89	0.122
6.85	16.99	0.122
6.86	17.09	0.122
6.87	17.19	0.122
6.88	17.29	0.122
6.89	17.39	0.122
6.90	17.49	0.122
6.91	17.60	0.122
6.92	17.69	0.122
6.93	17.79	0.123
6.94	17.90	0.123
6.95	17.99	0.123
6.96	18.09	0.123
6.97	18.20	0.123
6.98	18.30	0.123
6.99	18.40	0.123
7.00	18.49	0.123
7.01	18.60	0.123
7.02	18.70	0.123
7.03	18.80	0.123
7.04	18.90	0.123
7.05	19.00	0.123
7.06	19.10	0.123
7.07	19.20	0.123
7.08	19.30	0.123
7.09	19.40	0.123
7.10	19.50	0.123
7.11	19.60	0.123
7.12	19.70	0.123
7.13	19.80	0.123
7.14	19.90	0.123
7.15	20.00	0.124
7.16	20.10	0.124
7.17	20.20	0.124
7.18	20.30	0.124
7.19	20.40	0.124
7.20	20.50	0.124
7.21	20.60	0.124
7.22	20.70	0.124
7.23	20.80	0.124
7.24	20.90	0.124
7.25	21.00	0.124
7.26	21.10	0.124
7.27	21.20	0.124
7.28	21.30	0.124
7.29	21.40	0.124
7.30	21.50	0.124
7.31	21.60	0.124
7.32	21.70	0.124
7.33	21.80	0.124
7.34	21.90	0.124
7.35	22.00	0.125
7.36	22.10	0.124
7.37	22.20	0.125
7.38	22.30	0.125
7.39	22.40	0.125
7.40	22.50	0.125
7.41	22.60	0.125
7.42	22.70	0.125
7.43	22.80	0.125
7.44	22.90	0.125
7.45	23.00	0.125
7.46	23.10	0.125
7.47	23.20	0.125
7.48	23.30	0.125
7.49	23.40	0.125
7.50	23.50	0.125
7.51	23.60	0.125
7.52	23.70	0.125
7.53	23.80	0.125
7.54	23.90	0.125
7.55	24.00	0.126
7.56	24.10	0.126
7.57	24.20	0.126
7.58	24.30	0.126
7.59	24.40	0.126
7.60	24.50	0.126
7.61	24.60	0.126
7.62	24.70	0.126
7.63	24.80	0.126
7.64	24.90	0.126
7.65	25.00	0.126
7.66	25.10	0.126
7.67	25.20	0.126
7.68	25.30	0.126
7.69	25.41	0.126
7.70	25.50	0.126
7.71	25.60	0.126
7.72	25.70	0.127
7.73	25.80	0.127
7.74	25.90	0.127
7.75	26.00	0.127
7.76	26.11	0.127
7.77	26.21	0.127
7.78	26.31	0.127
7.79	26.40	0.127
7.80	26.51	0.127
7.81	26.61	0.127
7.82	26.71	0.127
7.83	26.81	0.127
7.84	26.91	0.127
7.85	27.01	0.127
7.86	27.10	0.127
7.87	27.21	0.127
7.88	27.31	0.127
7.89	27.41	0.127
7.90	27.51	0.128
7.91	27.61	0.128
7.92	27.71	0.128
7.93	27.81	0.128
7.94	27.91	0.128
7.95	28.01	0.128
7.96	28.11	0.128
7.97	28.21	0.128
7.98	28.31	0.128
7.99	28.41	0.128
8.00	28.51	0.128
8.01	28.61	0.128
8.02	28.71	0.128
8.03	28.81	0.128
8.04	28.91	0.128
8.05	29.01	0.128
8.06	29.11	0.128
8.07	29.21	0.128
8.08	29.31	0.129
8.09	29.41	0.129
8.10	29.51	0.129
8.11	29.61	0.129
8.12	29.71	0.129
8.13	29.81	0.129
8.14	29.91	0.129
8.15	30.01	0.129
8.16	30.11	0.129
8.17	30.21	0.129
8.18	30.31	0.129
8.19	30.41	0.129
8.20	30.51	0.129
8.21	30.61	0.129
8.22	30.71	0.129
8.23	30.81	0.129
8.24	30.91	0.130
8.25	31.01	0.130
8.26	31.11	0.130
8.27	31.21	0.130
8.28	31.31	0.130
8.29	31.41	0.130
8.30	31.51	0.130
8.31	31.61	0.130
8.32	31.71	0.130
8.33	31.81	0.130
8.34	31.91	0.130
8.35	32.01	0.130
8.36	32.11	0.130
8.37	32.21	0.130
8.38	32.31	0.130
8.39	32.41	0.130
8.40	32.51	0.130
8.41	32.61	0.130
8.42	32.71	0.131
8.43	32.81	0.131
8.44	32.91	0.131
8.45	33.01	0.131
8.46	33.11	0.131
8.47	33.21	0.131
8.48	33.31	0.131
8.49	33.41	0.131
8.50	33.51	0.131
8.51	33.61	0.131
8.52	33.71	0.131
8.53	33.81	0.131
8.54	33.91	0.131
8.55	34.01	0.131
8.56	34.11	0.131
8.57	34.21	0.131
8.58	34.31	0.131
8.59	34.41	0.131
8.60	34.51	0.132
8.61	34.61	0.132
8.62	34.71	0.132
8.63	34.81	0.132
8.64	34.92	0.132
8.65	35.01	0.132
8.66	35.11	0.132
8.67	35.22	0.132
8.68	35.31	0.132
8.69	35.41	0.132
8.70	35.51	0.132
8.71	35.62	0.132
8.72	35.72	0.132
8.73	35.82	0.132
8.74	35.92	0.132
8.75	36.02	0.132
8.76	36.12	0.133
8.77	36.22	0.133
8.78	36.32	0.133
8.79	36.42	0.133
8.80	36.52	0.133
8.81	36.62	0.133
8.82	36.72	0.133
8.83	36.82	0.133
8.84	36.92	0.133
8.85	37.02	0.133
8.86	37.12	0.133
8.87	37.22	0.133
8.88	37.32	0.133
8.89	37.42	0.133
8.90	37.52	0.133
8.91	37.62	0.133
8.92	37.72	0.133
8.93	37.82	0.133
8.94	37.92	0.134
8.95	38.02	0.134
8.96	38.12	0.134
8.97	38.22	0.134
8.98	38.32	0.134
8.99	38.42	0.134
9.00	38.52	0.134
9.01	38.62	0.134
9.02	38.72	0.134
9.03	38.82	0.134
9.04	38.92	0.134
9.05	39.02	0.134
9.06	39.12	0.134
9.07	39.22	0.134
9.08	39.32	0.134
9.09	39.42	0.134
9.10	39.52	0.134
9.11	39.62	0.134
9.12	39.72	0.135
9.13	39.82	0.135
9.14	39.92	0.135
9.15	40.02	0.135
9.16	40.12	0.135
9.17	40.22	0.135
9.18	40.32	0.135
9.19	40.42	0.135
9.20	40.52	0.135
9.21	40.62	0.135
9.22	40.72	0.135
9.23	40.82	0.135
9.24	40.92	0.135
9.25	41.02	0.135
9.26	41.12	0.135
9.27	41.22	0.135
9.28	41.32	0.135
9.29	41.42	0.136
9.30	41.52	0.136
9.31	41.62	0.136
9.32	41.72	0.136
9.33	41.82	0.136
9.34	41.92	0.136
9.35	42.02	0.136
9.36	42.12	0.136
9.37	42.22	0.136
9.38	42.32	0.136
9.39	42.42	0.136
9.40	42.52	0.136
9.41	42.62	0.136
9.42	42.72	0.136
9.43	42.82	0.136
9.44	42.92	0.136
9.45	43.02	0.136
9.46	43.12	0.137
9.47	43.22	0.137
9.48	43.32	0.137
9.49	43.42	0.137
9.50	43.52	0.137
9.51	43.62	0.137
9.52	43.72	0.137
9.53	43.82	0.137
9.54	43.92	0.137
9.55	44.02	0.137
9.56	44.12	0.137
9.57	44.22	0.137
9.58	44.32	0.137
9.59	44.43	0.137
9.60	44.52	0.137
9.61	44.63	0.137
9.62	44.73	0.137
9.63	44.83	0.138
9.64	44.93	0.138
9.65	45.03	0.138
9.66	45.12	0.138
9.67	45.22	0.138
9.68	45.33	0.138
9.69	45.43	0.138
9.70	45.53	0.138
9.71	45.63	0.138
9.72	45.73	0.138
9.73	45.83	0.138
9.74	45.93	0.138
9.75	46.03	0.138
9.76	46.13	0.138
9.77	46.23	0.138
9.78	46.33	0.139
9.79	46.43	0.139
9.80	46.53	0.139
9.81	46.63	0.139
9.82	46.73	0.139
9.83	46.83	0.139
9.84	46.93	0.139
9.85	47.03	0.139
9.86	47.13	0.139
9.87	47.23	0.139
9.88	47.33	0.139
9.89	47.43	0.139
9.90	47.53	0.139
9.91	47.63	0.139
9.92	47.73	0.139
9.93	47.83	0.140
9.94	47.93	0.140
9.95	48.03	0.140
9.96	48.13	0.140
9.97	48.23	0.140
9.98	48.33	0.140
9.99	48.43	0.140
10.00	48.53	0.140
10.01	48.63	0.140
10.02	48.73	0.140
10.03	48.83	0.140
10.04	48.93	0.140
10.05	49.03	0.140
10.06	49.13	0.140
10.07	49.23	0.140
10.08	49.33	0.140
10.09	49.43	0.140
10.10	49.53	0.141
10.11	49.63	0.141
10.12	49.73	0.141
10.13	49.83	0.141
10.14	49.93	0.141
10.15	50.03	0.141
10.16	50.13	0.141
10.17	50.23	0.141
10.18	50.33	0.141
10.19	50.43	0.141
10.20	50.53	0.141
10.21	50.63	0.141
10.22	50.73	0.142
10.23	50.83	0.142
10.24	50.93	0.142
10.25	51.03	0.142
10.26	51.13	0.142
10.27	51.23	0.142
10.28	51.33	0.142
10.29	51.43	0.142
10.30	51.53	0.142
10.31	51.63	0.143
10.32	51.73	0.143
10.33	51.83	0.143
10.34	51.93	0.143
10.35	52.03	0.143
10.36	52.13	0.143
10.37	52.23	0.143
10.38	52.33	0.143
10.39	52.43	0.143
10.40	52.53	0.143
10.41	52.63	0.143
10.42	52.73	0.144
10.43	52.83	0.144
10.44	52.93	0.144
10.45	53.03	0.144
10.46	53.13	0.144
10.47	53.24	0.144
10.48	53.33	0.145
10.49	53.43	0.145
10.50	53.53	0.145
10.51	53.63	0.145
10.52	53.73	0.145
10.53	53.83	0.145
10.54	53.93	0.146
10.55	54.03	0.146
10.56	54.13	0.146
10.57	54.23	0.146
10.58	54.33	0.147
10.59	54.44	0.147
10.60	54.53	0.147
10.61	54.63	0.147
10.62	54.73	0.148
10.63	54.83	0.148
10.64	54.93	0.149
10.65	55.03	0.150
10.66	55.13	0.151
10.67	55.23	0.155
10.68	55.33	0.172
10.69	55.43	0.202
10.70	55.53	0.275
10.71	55.62	0.414
10.72	55.70	0.620
10.73	55.78	0.875
10.74	55.84	1.160
10.75	55.90	1.452
10.76	55.94	1.751
10.77	55.99	2.032
10.78	56.03	2.292
10.79	56.06	2.544
10.80	56.10	2.778
10.81	56.13	2.980
10.82	56.17	3.177
10.83	56.21	3.363
10.84	56.25	3.544
10.85	56.29	3.724
10.86	56.33	3.884
10.87	56.37	4.012
10.88	56.42	4.094
10.89	56.47	4.142
10.90	56.53	4.189
10.91	56.60	4.249
10.92	56.66	4.266
10.93	56.74	4.211
10.94	56.82	4.018
10.95	56.93	3.748
10.96	57.04	3.537
10.97	57.16	3.380
10.98	57.28	3.248
10.99	57.40	3.123
11.00	57.53	3.004
11.01	57.66	2.884
11.02	57.79	2.762
11.03	57.92	2.641
11.04	58.05	2.514
11.05	58.18	2.390
11.06	58.31	2.266
11.07	58.45	2.135
11.08	58.58	2.007
11.09	58.72	1.882
11.10	58.86	1.754
11.11	58.99	1.617
11.12	59.13	1.482
11.13	59.27	1.341
11.14	59.41	1.200
11.15	59.55	1.066
11.16	59.69	0.948
11.17	59.82	0.865
11.18	59.96	0.781
11.19	60.09	0.735
11.20	60.22	0.679
11.21	60.35	0.634
11.22	60.47	0.597
11.23	60.60	0.561
11.24	60.72	0.527
11.25	60.84	0.500
11.26	60.95	0.473
11.27	61.07	0.447
11.28	61.18	0.428
11.29	61.30	0.408
11.30	61.41	0.389
11.31	61.52	0.372
11.32	61.63	0.359
11.33	61.74	0.342
11.34	61.85	0.333
11.35	61.95	0.320
11.36	62.06	0.311
11.37	62.16	0.300
11.38	62.27	0.292
11.39	62.38	0.285
11.40	62.48	0.277
11.41	62.58	0.270
11.42	62.69	0.265
11.43	62.79	0.260
11.44	62.89	0.255
11.45	63.00	0.251
11.46	63.10	0.247
11.47	63.20	0.242
11.48	63.30	0.240
11.49	63.41	0.236
11.50	63.51	0.236
11.51	63.61	0.234
11.52	63.71	0.229
11.53	63.81	0.229
11.54	63.92	0.226
11.55	64.02	0.226
11.56	64.12	0.223
11.57	64.22	0.222
11.58	64.32	0.221
11.59	64.42	0.220
11.60	64.52	0.219
11.61	64.62	0.218
11.62	64.72	0.218
11.63	64.82	0.217
11.64	64.92	0.217
11.65	65.03	0.216
11.66	65.13	0.216
11.67	65.23	0.216
11.68	65.33	0.216
11.69	65.43	0.216
11.70	65.53	0.215
11.71	65.63	0.215
11.72	65.73	0.214
11.73	65.83	0.214
11.74	65.93	0.214
11.75	66.03	0.213
11.76	66.13	0.213
11.77	66.23	0.213
11.78	66.33	0.213
11.79	66.43	0.213
11.80	66.53	0.212
11.81	66.63	0.212
11.82	66.73	0.212
11.83	66.83	0.212
11.84	66.93	0.212
11.85	67.03	0.211
11.86	67.13	0.211
11.87	67.23	0.211
11.88	67.33	0.211
11.89	67.43	0.211
11.90	67.53	0.211
11.91	67.63	0.211
11.92	67.73	0.211
11.93	67.83	0.210
11.94	67.93	0.210
11.95	68.03	0.210
11.96	68.13	0.210
11.97	68.23	0.210
11.98	68.33	0.210
11.99	68.43	0.210
12.00	68.53	0.210
12.01	68.63	0.210
12.02	68.73	0.210
12.03	68.83	0.209
12.04	68.93	0.209
12.05	69.03	0.209
12.06	69.13	0.209
12.07	69.24	0.209
12.08	69.33	0.209
12.09	69.44	0.209
12.10	69.54	0.209
12.11	69.64	0.209
12.12	69.74	0.209
12.13	69.83	0.209
12.14	69.94	0.209
12.15	70.04	0.209
12.16	70.13	0.209
12.17	70.24	0.209
12.18	70.34	0.209
12.19	70.43	0.209
12.20	70.54	0.209
12.21	70.64	0.209
12.22	70.74	0.209
12.23	70.84	0.209
12.24	70.94	0.209
12.25	71.04	0.209
12.26	71.14	0.209
12.27	71.24	0.209
12.28	71.34	0.209
12.29	71.44	0.209
12.30	71.54	0.209
12.31	71.64	0.209
12.32	71.74	0.209
12.33	71.84	0.209
12.34	71.94	0.209
12.35	72.04	0.209
12.36	72.14	0.209
12.37	72.24	0.209
12.38	72.34	0.209
12.39	72.44	0.209
12.40	72.54	0.209
12.41	72.64	0.209
12.42	72.74	0.209
12.43	72.84	0.209
12.44	72.94	0.209
12.45	73.04	0.209
12.46	73.14	0.209
12.47	73.24	0.209
12.48	73.34	0.209
12.49	73.44	0.209
12.50	73.54	0.209
12.51	73.64	0.209
12.52	73.74	0.209
12.53	73.84	0.209
12.54	73.94	0.209
12.55	74.04	0.209
12.56	74.14	0.209
12.57	74.24	0.209
12.58	74.34	0.209
12.59	74.44	0.209
12.60	74.54	0.209
12.61	74.64	0.209
12.62	74.74	0.209
12.63	74.84	0.209
12.64	74.94	0.209
12.65	75.04	0.209
12.66	75.14	0.209
12.67	75.24	0.209
12.68	75.34	0.209
12.69	75.44	0.210
12.70	75.54	0.210
12.71	75.64	0.210
12.72	75.74	0.210
12.73	75.84	0.210
12.74	75.94	0.210
12.75	76.04	0.210
12.76	76.14	0.210
12.77	76.24	0.210
12.78	76.34	0.210
12.79	76.44	0.210
12.80	76.54	0.210
12.81	76.64	0.210
12.82	76.74	0.210
12.83	76.84	0.210
12.84	76.94	0.210
12.85	77.04	0.210
12.86	77.14	0.210
12.87	77.24	0.210
12.88	77.34	0.210
12.89	77.44	0.210
12.90	77.54	0.210
12.91	77.64	0.210
12.92	77.74	0.210
12.93	77.84	0.210
12.94	77.94
12.95	78.04
12.96	78.14
12.97	78.24
12.98	78.34
12.99
12.99

[step]
Ramp 10.00 °C/min to -50.00 °C
Time	Temperature	Heat Flow (Normalized)
min	°C	W/g
14.00	80.09	-0.030
14.00	80.09	-0.030
14.02	80.09	-0.030
14.03	80.08	-0.031
14.03	80.08	-0.031
14.05	80.07	-0.030
14.05	80.06	-0.018
14.07	80.04	-0.002
14.08	80.02	0.014
14.08	79.99	0.028
14.10	79.95	0.040
14.10	79.91	0.045
14.12	79.85	0.045
14.13	79.80	0.037
14.13	79.73	0.031
14.15	79.67	0.010
14.15	79.60	-0.010
14.17	79.53	-0.033
14.18	79.46	-0.052
14.18	79.38	-0.073
14.20	79.30	-0.089
14.20	79.22	-0.104
14.22	79.14	-0.119
14.23	79.06	-0.132
14.23	78.98	-0.142
14.25	78.89	-0.153
14.25	78.81	-0.163
14.27	78.72	-0.172
14.28	78.63	-0.180
14.28	78.54	-0.187
14.30	78.45	-0.193
14.30	78.36	-0.202
14.32	78.27	-0.207
14.33	78.18	-0.214
14.33	78.09	-0.219
14.35	77.99	-0.224
14.35	77.90	-0.228
14.37	77.81	-0.232
14.38	77.71	-0.238
14.38	77.62	-0.240
14.40	77.52	-0.243
14.40	77.43	-0.246
14.42	77.33	-0.247
14.43	77.24	-0.249
14.43	77.14	-0.253
14.45	77.04	-0.254
14.45	76.95	-0.255
14.47	76.85	-0.257
14.48	76.75	-0.259
14.48	76.66	-0.259
14.50	76.56	-0.261
14.50	76.46	-0.263
14.52	76.36	-0.264
14.53	76.27	-0.266
14.53	76.17	-0.266
14.55	76.07	-0.266
14.55	75.97	-0.267
14.57	75.88	-0.267
14.58	75.78	-0.267
14.58	75.68	-0.268
14.60	75.58	-0.268
14.60	75.48	-0.269
14.62	75.38	-0.269
14.63	75.29	-0.269
14.63	75.19	-0.270
14.65	75.09	-0.270
14.65	74.99	-0.270
14.67	74.89	-0.270
14.68	74.79	-0.270
14.68	74.69	-0.271
14.70	74.59	-0.271
14.70	74.50	-0.271
14.72	74.40	-0.271
14.73	74.30	-0.271
14.73	74.20	-0.272
14.75	74.10	-0.272
14.75	74.00	-0.272
14.77	73.90	-0.273
14.78	73.80	-0.273
14.78	73.70	-0.273
14.80	73.60	-0.273
14.80	73.50	-0.273
14.82	73.41	-0.273
14.83	73.31	-0.273
14.83	73.21	-0.274
14.85	73.11	-0.274
14.85	73.01	-0.274
14.87	72.91	-0.274
14.88	72.81	-0.274
14.88	72.71	-0.274
14.90	72.61	-0.274
14.90	72.51	-0.275
14.92	72.41	-0.275
14.93	72.31	-0.275
14.93	72.21	-0.275
14.95	72.12	-0.275
14.95	72.02	-0.275
14.97	71.92	-0.275
14.98	71.82	-0.275
14.98	71.72	-0.275
15.00	71.62	-0.275
15.00	71.52	-0.275
15.02	71.42	-0.275
15.03	71.32	-0.275
15.03	71.22	-0.275
15.05	71.12	-0.275
15.05	71.02	-0.275
15.07	70.92	-0.275
15.08	70.82	-0.275
15.08	70.72	-0.275
15.10	70.62	-0.275
15.10	70.52	-0.275
15.12	70.42	-0.275
15.13	70.32	-0.275
15.13	70.22	-0.275
15.15	70.12	-0.275
15.15	70.03	-0.275
15.17	69.92	-0.275
15.18	69.83	-0.275
15.18	69.73	-0.275
15.20	69.63	-0.275
15.20	69.53	-0.275
15.22	69.43	-0.275
15.23	69.33	-0.275
15.23	69.23	-0.275
15.25	69.13	-0.275
15.25	69.03	-0.275
15.27	68.93	-0.275
15.28	68.83	-0.275
15.28	68.73	-0.275
15.30	68.63	-0.275
15.30	68.53	-0.275
15.32	68.43	-0.275
15.33	68.33	-0.275
15.33	68.23	-0.275
15.35	68.13	-0.275
15.35	68.03	-0.274
15.37	67.93	-0.274
15.38	67.83	-0.274
15.38	67.73	-0.274
15.40	67.63	-0.274
15.40	67.53	-0.274
15.42	67.43	-0.274
15.43	67.33	-0.274
15.43	67.23	-0.274
15.45	67.13	-0.274
15.45	67.03	-0.274
15.47	66.93	-0.274
15.48	66.83	-0.274
15.48	66.73	-0.274
15.50	66.63	-0.274
15.50	66.53	-0.273
15.52	66.44	-0.273
15.53	66.34	-0.273
15.53	66.24	-0.273
15.55	66.14	-0.273
15.55	66.04	-0.273
15.57	65.94	-0.273
15.58	65.83	-0.273
15.58	65.74	-0.272
15.60	65.64	-0.272
15.60	65.54	-0.272
15.62	65.44	-0.272
15.63	65.34	-0.272
15.63	65.24	-0.272
15.65	65.14	-0.272
15.65	65.04	-0.272
15.67	64.94	-0.272
15.68	64.84	-0.272
15.68	64.74	-0.272
15.70	64.64	-0.272
15.70	64.54	-0.272
15.72	64.44	-0.271
15.73	64.34	-0.271
15.73	64.24	-0.271
15.75	64.14	-0.271
15.75	64.04	-0.271
15.77	63.94	-0.271
15.78	63.84	-0.271
15.78	63.74	-0.271
15.80	63.64	-0.271
15.80	63.54	-0.271
15.82	63.44	-0.270
15.83	63.34	-0.270
15.83	63.24	-0.270
15.85	63.14	-0.270
15.85	63.04	-0.270
15.87	62.94	-0.270
15.88	62.84	-0.270
15.88	62.74	-0.270
15.90	62.64	-0.269
15.90	62.54	-0.269
15.92	62.44	-0.269
15.93	62.34	-0.269
15.93	62.24	-0.269
15.95	62.14	-0.269
15.95	62.04	-0.269
15.97	61.94	-0.269
15.98	61.84	-0.269
15.98	61.74	-0.269
16.00	61.64	-0.269
16.00	61.54	-0.268
16.02	61.44	-0.268
16.03	61.34	-0.268
16.03	61.24	-0.268
16.05	61.14	-0.268
16.05	61.04	-0.268
16.07	60.94	-0.268
16.08	60.84	-0.268
16.08	60.74	-0.268
16.10	60.64	-0.268
16.10	60.54	-0.268
16.12	60.44	-0.268
16.13	60.34	-0.267
16.13	60.24	-0.267
16.15	60.14	-0.267
16.15	60.04	-0.267
16.17	59.94	-0.267
16.18	59.84	-0.267
16.18	59.74	-0.267
16.20	59.64	-0.267
16.20	59.55	-0.267
16.22	59.44	-0.267
16.23	59.34	-0.267
16.23	59.25	-0.266
16.25	59.14	-0.266
16.25	59.05	-0.266
16.27	58.95	-0.266
16.28	58.85	-0.266
16.28	58.75	-0.266
16.30	58.65	-0.266
16.30	58.55	-0.266
16.32	58.45	-0.266
16.33	58.35	-0.265
16.33	58.25	-0.265
16.35	58.15	-0.265
16.35	58.05	-0.265
16.37	57.95	-0.265
16.38	57.85	-0.265
16.38	57.75	-0.265
16.40	57.65	-0.265
16.40	57.55	-0.265
16.42	57.45	-0.265
16.43	57.35	-0.264
16.43	57.25	-0.264
16.45	57.15	-0.264
16.45	57.05	-0.264
16.47	56.95	-0.264
16.48	56.85	-0.264
16.48	56.75	-0.264
16.50	56.65	-0.264
16.50	56.55	-0.264
16.52	56.45	-0.264
16.53	56.35	-0.264
16.53	56.25	-0.263
16.55	56.15	-0.263
16.55	56.05	-0.263
16.57	55.95	-0.263
16.58	55.85	-0.263
16.58	55.75	-0.263
16.60	55.65	-0.262
16.60	55.55	-0.263
16.62	55.45	-0.262
16.63	55.35	-0.262
16.63	55.25	-0.262
16.65	55.15	-0.262
16.65	55.05	-0.262
16.67	54.95	-0.262
16.68	54.85	-0.262
16.68	54.75	-0.262
16.70	54.65	-0.262
16.70	54.55	-0.262
16.72	54.45	-0.261
16.73	54.35	-0.261
16.73	54.25	-0.261
16.75	54.15	-0.261
16.75	54.05	-0.261
16.77	53.95	-0.261
16.78	53.85	-0.261
16.78	53.75	-0.261
16.80	53.65	-0.261
16.80	53.55	-0.261
16.82	53.45	-0.261
16.83	53.35	-0.260
16.83	53.25	-0.260
16.85	53.15	-0.260
16.85	53.05	-0.260
16.87	52.95	-0.260
16.88	52.85	-0.260
16.88	52.75	-0.260
16.90	52.65	-0.260
16.90	52.55	-0.260
16.92	52.45	-0.260
16.93	52.35	-0.260
16.93	52.25	-0.259
16.95	52.15	-0.259
16.95	52.05	-0.259
16.97	51.95	-0.259
16.98	51.85	-0.259
16.98	51.75	-0.259
17.00	51.65	-0.259
17.00	51.55	-0.259
17.02	51.45	-0.259
17.03	51.35	-0.259
17.03	51.25	-0.259
17.05	51.15	-0.259
17.05	51.05	-0.258
17.07	50.95	-0.258
17.08	50.85	-0.258
17.08	50.75	-0.258
17.09	50.65	-0.258
17.11	50.55	-0.258
17.12	50.45	-0.258
17.13	50.35	-0.258
17.13	50.25	-0.258
17.14	50.15	-0.258
17.16	50.06	-0.258
17.17	49.95	-0.258
17.18	49.85	-0.257
17.18	49.76	-0.257
17.19	49.66	-0.257
17.21	49.56	-0.257
17.22	49.45	-0.257
17.23	49.35	-0.257
17.23	49.25	-0.257
17.24	49.15	-0.257
17.26	49.05	-0.257
17.27	48.96	-0.256
17.28	48.86	-0.256
17.28	48.76	-0.256
17.29	48.66	-0.256
17.31	48.56	-0.256
17.32	48.46	-0.256
17.33	48.36	-0.256
17.33	48.26	-0.256
17.34	48.16	-0.256
17.36	48.06	-0.256
17.37	47.96	-0.255
17.38	47.86	-0.255
17.38	47.76	-0.255
17.39	47.66	-0.255
17.41	47.56	-0.255
17.42	47.46	-0.255
17.43	47.36	-0.255
17.43	47.26	-0.255
17.44	47.16	-0.255
17.46	47.06	-0.255
17.47	46.96	-0.255
17.48	46.86	-0.254
17.48	46.76	-0.254
17.49	46.66	-0.254
17.51	46.56	-0.254
17.52	46.46	-0.254
17.53	46.36	-0.254
17.53	46.26	-0.254
17.54	46.16	-0.254
17.56	46.06	-0.254
17.57	45.96	-0.254
17.58	45.86	-0.253
17.58	45.76	-0.253
17.59	45.66	-0.253
17.61	45.56	-0.253
17.62	45.46	-0.253
17.63	45.36	-0.253
17.63	45.26	-0.253
17.64	45.16	-0.253
17.66	45.06	-0.253
17.67	44.96	-0.253
17.68	44.86	-0.253
17.68	44.76	-0.252
17.69	44.66	-0.252
17.71	44.56	-0.252
17.72	44.46	-0.252
17.73	44.36	-0.252
17.73	44.26	-0.252
17.74	44.16	-0.252
17.76	44.06	-0.252
17.77	43.96	-0.252
17.78	43.86	-0.252
17.78	43.76	-0.252
17.79	43.66	-0.252
17.81	43.56	-0.251
17.82	43.46	-0.251
17.83	43.36	-0.251
17.83	43.26	-0.251
17.84	43.16	-0.251
17.86	43.06	-0.251
17.87	42.96	-0.251
17.88	42.86	-0.251
17.88	42.76	-0.251
17.89	42.66	-0.251
17.91	42.56	-0.250
17.92	42.46	-0.250
17.93	42.36	-0.250
17.93	42.26	-0.250
17.94	42.16	-0.250
17.96	42.06	-0.250
17.97	41.96	-0.250
17.98	41.86	-0.250
17.98	41.76	-0.250
17.99	41.66	-0.250
18.01	41.56	-0.250
18.02	41.46	-0.250
18.03	41.37	-0.249
18.03	41.26	-0.249
18.04	41.16	-0.249
18.06	41.06	-0.249
18.07	40.96	-0.249
18.08	40.86	-0.249
18.08	40.76	-0.249
18.09	40.67	-0.249
18.11	40.56	-0.249
18.12	40.47	-0.249
18.13	40.36	-0.249
18.13	40.27	-0.248
18.14	40.17	-0.248
18.16	40.06	-0.248
18.17	39.97	-0.248
18.18	39.87	-0.248
18.18	39.76	-0.248
18.19	39.66	-0.248
18.21	39.56	-0.248
18.22	39.47	-0.248
18.23	39.37	-0.248
18.23	39.27	-0.247
18.24	39.17	-0.247
18.26	39.07	-0.247
18.27	38.97	-0.247
18.28	38.87	-0.247
18.28	38.77	-0.247
18.29	38.67	-0.247
[...]
132.65	-26.18	0.143
132.66	-26.08	0.144
132.67	-25.98	0.147
132.68	-25.88	0.149
132.69	-25.78	0.154
132.70	-25.68	0.155
132.71	-25.58	0.157
132.72	-25.48	0.160
132.73	-25.38	0.162
132.74	-25.28	0.167
132.75	-25.18	0.169
132.76	-25.08	0.171
132.77	-24.98	0.174
132.78	-24.88	0.178
132.79	-24.78	0.181
132.80	-24.69	0.187
132.81	-24.59	0.188
132.82	-24.49	0.192
132.83	-24.39	0.195
132.84	-24.29	0.199
132.85	-24.19	0.203
132.86	-24.09	0.210
132.87	-23.99	0.211
132.88	-23.89	0.215
132.89	-23.79	0.219
132.90	-23.70	0.221
132.91	-23.60	0.224
132.92	-23.50	0.229
132.93	-23.40	0.232
132.94	-23.30	0.233
132.95	-23.20	0.237
132.96	-23.10	0.238
132.97	-23.00	0.239
132.98	-22.90	0.240
132.99	-22.80	0.240
133.00	-22.70	0.240
133.01	-22.61	0.240
133.02	-22.50	0.240
133.03	-22.40	0.239
133.04	-22.30	0.238
133.05	-22.20	0.235
133.06	-22.10	0.231
133.07	-22.00	0.228
133.08	-21.90	0.224
133.09	-21.80	0.218
133.10	-21.70	0.216
133.11	-21.60	0.212
133.12	-21.50	0.211
133.13	-21.40	0.207
133.14	-21.30	0.205
133.15	-21.20	0.202
133.16	-21.10	0.200
133.17	-21.00	0.199
133.18	-20.89	0.198
133.19	-20.79	0.196
133.20	-20.69	0.195
133.21	-20.59	0.194
133.22	-20.49	0.193
133.23	-20.39	0.192
133.24	-20.29	0.191
133.25	-20.19	0.191
133.26	-20.09	0.190
133.27	-19.99	0.190
133.28	-19.89	0.190
133.29	-19.79	0.189
133.30	-19.69	0.189
133.31	-19.59	0.188
133.32	-19.48	0.188
133.33	-19.39	0.188
133.34	-19.28	0.187
133.35	-19.18	0.187
133.36	-19.08	0.187
133.37	-18.98	0.186
133.38	-18.88	0.186
133.39	-18.78	0.186
133.40	-18.68	0.186
133.41	-18.58	0.186
133.42	-18.48	0.185
133.43	-18.38	0.185
133.44	-18.28	0.185
133.45	-18.18	0.185
133.46	-18.08	0.185
133.47	-17.98	0.185
133.48	-17.88	0.184
133.49	-17.78	0.184
133.50	-17.68	0.184
133.51	-17.58	0.184
133.52	-17.48	0.183
133.53	-17.38	0.183
133.54	-17.28	0.183
133.55	-17.18	0.183
133.56	-17.08	0.183
133.57	-16.98	0.183
133.58	-16.88	0.183
133.59	-16.78	0.182
133.60	-16.68	0.182
133.61	-16.58	0.182
133.62	-16.48	0.182
133.63	-16.38	0.182
133.64	-16.28	0.182
133.65	-16.18	0.182
133.66	-16.08	0.181
133.67	-15.97	0.181
133.68	-15.88	0.181
133.69	-15.77	0.181
133.70	-15.68	0.181
133.71	-15.58	0.181
133.72	-15.48	0.181
133.73	-15.38	0.181
133.74	-15.28	0.181
133.75	-15.17	0.181
133.76	-15.07	0.181
133.77	-14.97	0.181
133.78	-14.87	0.180
133.79	-14.77	0.181
133.80	-14.67	0.180
133.81	-14.57	0.180
133.82	-14.47	0.180
133.83	-14.37	0.180
133.84	-14.27	0.180
133.85	-14.17	0.180
133.86	-14.07	0.180
133.87	-13.97	0.180
133.88	-13.87	0.180
133.89	-13.77	0.180
133.90	-13.67	0.180
133.91	-13.57	0.180
133.92	-13.47	0.180
133.93	-13.37	0.180
133.94	-13.27	0.180
133.95	-13.17	0.180
133.96	-13.07	0.180
133.97	-12.97	0.180
133.98	-12.87	0.180
133.99	-12.77	0.179
134.00	-12.67	0.179
134.01	-12.57	0.179
134.02	-12.47	0.179
134.03	-12.37	0.179
134.04	-12.27	0.179
134.05	-12.17	0.180
134.06	-12.07	0.179
134.07	-11.97	0.179
134.08	-11.87	0.179
134.09	-11.77	0.179
134.10	-11.67	0.179
134.11	-11.57	0.179
134.12	-11.47	0.179
134.13	-11.37	0.179
134.14	-11.27	0.179
134.15	-11.17	0.179
134.16	-11.07	0.179
134.17	-10.97	0.179
134.18	-10.87	0.179
134.19	-10.77	0.179
134.20	-10.67	0.179
134.21	-10.57	0.179
134.22	-10.47	0.179
134.23	-10.37	0.179
134.24	-10.27	0.179
134.25	-10.17	0.179
134.26	-10.07	0.179
134.27	-9.97	0.179
134.28	-9.87	0.179
134.29	-9.77	0.179
134.30	-9.67	0.179
134.31	-9.57	0.179
134.32	-9.47	0.179
134.33	-9.37	0.179
134.34	-9.27	0.179
134.35	-9.17	0.179
134.36	-9.07	0.179
134.37	-8.97	0.179
134.38	-8.87	0.179
134.39	-8.77	0.179
134.40	-8.67	0.179
134.41	-8.57	0.179
134.42	-8.47	0.179
134.43	-8.37	0.179
134.44	-8.27	0.179
134.45	-8.17	0.179
134.46	-8.07	0.179
134.47	-7.97	0.179
134.48	-7.87	0.179
134.49	-7.77	0.179
134.50	-7.67	0.179
134.51	-7.57	0.179
134.52	-7.47	0.179
134.53	-7.37	0.179
134.54	-7.27	0.179
134.55	-7.16	0.179
134.56	-7.07	0.179
134.57	-6.97	0.179
134.58	-6.87	0.179
134.59	-6.77	0.179
134.60	-6.67	0.179
134.61	-6.56	0.179
134.62	-6.46	0.179
134.63	-6.37	0.179
134.64	-6.26	0.179
134.65	-6.17	0.179
134.66	-6.06	0.179
134.67	-5.96	0.179
134.68	-5.86	0.179
134.69	-5.76	0.179
134.70	-5.66	0.179
134.71	-5.56	0.179
134.72	-5.46	0.179
134.73	-5.36	0.179
134.74	-5.26	0.179
134.75	-5.16	0.179
134.76	-5.06	0.180
134.77	-4.96	0.180
134.78	-4.86	0.180
134.79	-4.76	0.180
134.80	-4.66	0.180
134.81	-4.56	0.180
134.82	-4.46	0.180
134.83	-4.36	0.180
134.84	-4.26	0.180
134.85	-4.16	0.180
134.86	-4.06	0.180
134.87	-3.96	0.180
134.88	-3.86	0.180
134.89	-3.76	0.180
134.90	-3.66	0.180
134.91	-3.56	0.180
134.92	-3.46	0.180
134.93	-3.36	0.180
134.94	-3.26	0.180
134.95	-3.16	0.180
134.96	-3.06	0.180
134.97	-2.96	0.180
134.98	-2.86	0.180
134.99	-2.76	0.180
135.00	-2.66	0.180
135.01	-2.56	0.180
135.02	-2.46	0.180
135.03	-2.36	0.180
135.04	-2.26	0.180
135.05	-2.16	0.180
135.06	-2.06	0.180
135.07	-1.96	0.180
135.08	-1.86	0.180
135.09	-1.76	0.180
135.10	-1.66	0.180
135.11	-1.56	0.180
135.12	-1.46	0.180
135.13	-1.36	0.180
135.14	-1.26	0.180
135.15	-1.16	0.180
135.16	-1.06	0.180
135.17	-0.96	0.180
135.18	-0.85	0.180
135.19	-0.76	0.180
135.20	-0.66	0.180
135.21	-0.56	0.180
135.22	-0.46	0.181
135.23	-0.35	0.181
135.24	-0.25	0.181
135.25	-0.15	0.181
135.26	-0.05	0.181
135.27	0.05	0.181
135.28	0.15	0.181
135.29	0.25	0.181
135.30	0.35	0.181
135.31	0.45	0.181
135.32	0.55	0.181
135.33	0.65	0.181
135.34	0.75	0.181
135.35	0.85	0.181
135.36	0.95	0.181
135.37	1.05	0.181
135.38	1.15	0.181
135.39	1.25	0.181
135.40	1.35	0.181
135.41	1.45	0.181
135.42	1.55	0.181
135.43	1.65	0.181
135.44	1.75	0.181
135.45	1.85	0.181
135.46	1.95	0.181
135.47	2.05	0.181
135.48	2.15	0.181
135.49	2.25	0.181
135.50	2.35	0.181
135.51	2.45	0.181
135.52	2.55	0.181
135.53	2.65	0.181
135.54	2.75	0.181
135.55	2.85	0.181
135.56	2.95	0.181
135.57	3.05	0.181
135.58	3.15	0.181
135.59	3.25	0.181
135.60	3.35	0.181
135.61	3.45	0.181
135.62	3.55	0.181
135.63	3.65	0.181
135.64	3.75	0.181
135.65	3.85	0.181
135.66	3.95	0.181
135.67	4.05	0.181
135.68	4.15	0.181
135.69	4.25	0.181
135.70	4.35	0.181
135.71	4.45	0.181
135.72	4.55	0.182
135.73	4.65	0.182
135.74	4.75	0.182
135.75	4.85	0.182
135.76	4.95	0.182
135.77	5.05	0.182
135.78	5.15	0.182
135.79	5.25	0.182
135.80	5.35	0.182
135.81	5.45	0.182
135.82	5.55	0.182
135.83	5.65	0.182
135.84	5.76	0.182
135.85	5.85	0.182
135.86	5.96	0.182
135.87	6.05	0.182
135.88	6.16	0.182
135.89	6.26	0.182
135.90	6.36	0.182
135.91	6.45	0.182
135.92	6.56	0.182
135.93	6.66	0.182
135.94	6.76	0.182
135.95	6.86	0.182
135.96	6.96	0.182
135.97	7.06	0.182
135.98	7.16	0.182
135.99	7.26	0.182
136.00	7.36	0.182
136.01	7.46	0.182
136.02	7.56	0.182
136.03	7.66	0.182
136.04	7.76	0.182
136.05	7.86	0.182
136.06	7.96	0.182
136.07	8.06	0.182
136.08	8.16	0.182
136.09	8.26	0.182
136.10	8.36	0.182
136.11	8.46	0.182
136.12	8.56	0.182
136.13	8.66	0.182
136.14	8.76	0.182
136.15	8.86	0.182
136.16	8.96	0.182
136.17	9.06	0.182
136.18	9.16	0.182
136.19	9.26	0.182
136.20	9.36	0.182
136.21	9.46	0.182
136.22	9.56	0.182
136.23	9.66	0.182
136.24	9.76	0.182
136.25	9.86	0.182
136.26	9.96	0.182
136.27	10.06	0.182
136.28	10.16	0.182
136.29	10.26	0.182
136.30	10.36	0.182
136.31	10.46	0.182
136.32	10.56	0.182
136.33	10.66	0.182
136.34	10.76	0.182
136.35	10.86	0.182
136.36	10.96	0.182
136.37	11.06	0.182
136.38	11.16	0.182
136.39	11.26	0.182
136.40	11.36	0.182
136.41	11.46	0.182
136.42	11.56	0.182
136.43	11.66	0.182
136.44	11.76	0.182
136.45	11.86	0.182
136.46	11.97	0.182
136.47	12.06	0.182
136.48	12.16	0.182
136.49	12.27	0.182
136.50	12.36	0.182
136.51	12.46	0.181
136.52	12.56	0.181
136.53	12.67	0.181
136.54	12.77	0.181
136.55	12.87	0.181
136.56	12.97	0.181
136.57	13.07	0.181
136.58	13.17	0.180
136.59	13.27	0.180
136.60	13.37	0.180
136.61	13.47	0.179
136.62	13.57	0.179
136.63	13.67	0.179
136.64	13.77	0.178
136.65	13.87	0.178
136.66	13.97	0.177
136.67	14.07	0.177
136.68	14.17	0.176
136.69	14.27	0.176
136.70	14.37	0.175
136.71	14.47	0.174
136.72	14.57	0.172
136.73	14.67	0.171
136.74	14.77	0.170
136.75	14.87	0.167
136.76	14.97	0.166
136.77	15.07	0.165
136.78	15.17	0.163
136.79	15.27	0.161
136.80	15.38	0.161
136.81	15.47	0.159
136.82	15.58	0.157
136.83	15.68	0.154
136.84	15.78	0.151
136.85	15.88	0.150
136.86	15.98	0.148
136.87	16.08	0.146
136.88	16.18	0.142
136.89	16.28	0.139
136.90	16.38	0.137
136.91	16.48	0.133
136.92	16.58	0.128
136.93	16.68	0.127
136.94	16.78	0.125
136.95	16.89	0.120
136.96	16.99	0.118
136.97	17.09	0.114
136.98	17.19	0.110
136.99	17.29	0.106
137.00	17.39	0.103
137.01	17.49	0.099
137.02	17.59	0.094
137.03	17.70	0.089
137.04	17.80	0.085
137.05	17.90	0.078
137.06	18.00	0.073
137.07	18.10	0.066
137.08	18.20	0.062
137.09	18.30	0.054
137.10	18.41	0.048
137.11	18.51	0.041
137.12	18.61	0.033
137.13	18.71	0.028
137.14	18.81	0.018
137.15	18.92	0.010
137.16	19.02	0.000
137.17	19.12	-0.009
137.18	19.22	-0.019
137.19	19.33	-0.027
137.20	19.43	-0.039
137.21	19.53	-0.052
137.22	19.64	-0.065
137.23	19.74	-0.078
137.24	19.84	-0.092
137.25	19.95	-0.107
137.26	20.05	-0.121
137.27	20.15	-0.136
137.28	20.26	-0.151
137.29	20.36	-0.168
137.30	20.47	-0.185
137.31	20.57	-0.203
137.32	20.68	-0.223
137.33	20.78	-0.243
137.34	20.89	-0.262
137.35	21.00	-0.284
137.36	21.10	-0.307
137.37	21.21	-0.326
137.38	21.31	-0.352
137.39	21.42	-0.375
137.40	21.53	-0.402
137.41	21.63	-0.427
137.42	21.74	-0.457
137.43	21.85	-0.484
137.44	21.96	-0.514
137.45	22.07	-0.544
137.46	22.17	-0.576
137.47	22.28	-0.607
137.48	22.39	-0.641
137.49	22.50	-0.672
137.50	22.61	-0.707
137.51	22.72	-0.743
137.52	22.83	-0.782
137.53	22.94	-0.818
137.54	23.05	-0.864
137.55	23.16	-0.904
137.56	23.28	-0.945
137.57	23.39	-0.988
137.58	23.50	-1.033
137.59	23.61	-1.078
137.60	23.73	-1.122
137.61	23.84	-1.167
137.62	23.95	-1.210
137.63	24.07	-1.255
137.64	24.18	-1.300
137.65	24.29	-1.342
137.66	24.41	-1.383
137.67	24.52	-1.425
137.68	24.63	-1.459
137.69	24.75	-1.491
137.70	24.86	-1.518
137.71	24.97	-1.545
137.72	25.08	-1.566
137.73	25.19	-1.585
137.74	25.30	-1.603
137.75	25.41	-1.621
137.76	25.52	-1.633
137.77	25.63	-1.645
137.78	25.73	-1.653
137.79	25.84	-1.658
137.80	25.94	-1.658
137.81	26.05	-1.653
137.82	26.15	-1.646
137.83	26.25	-1.630
137.84	26.36	-1.608
137.85	26.46	-1.578
137.86	26.55	-1.535
137.87	26.65	-1.483
137.88	26.74	-1.423
137.89	26.83	-1.353
137.90	26.92	-1.282
137.91	27.01	-1.208
137.92	27.09	-1.132
137.93	27.18	-1.059
137.94	27.26	-0.980
137.95	27.34	-0.902
137.96	27.42	-0.824
137.97	27.50	-0.747
137.98	27.58	-0.673
137.99	27.66	-0.600
138.00	27.74	-0.534
138.01	27.82	-0.469
138.02	27.89	-0.409
138.03	27.97	-0.353
138.04	28.05	-0.300
138.05	28.13	-0.254
138.06	28.22	-0.212
138.07	28.30	-0.177
138.08	28.38	-0.147
138.09	28.47	-0.121
138.10	28.55	-0.100
138.11	28.64	-0.081
138.12	28.73	-0.063
138.13	28.82	-0.048
138.14	28.91	-0.032
138.15	29.00	-0.021
138.16	29.09	-0.009
138.17	29.19	0.000
138.18	29.28	0.011
138.19	29.37	0.019
138.20	29.47	0.026
138.21	29.56	0.032
138.22	29.66	0.039
138.23	29.75	0.044
138.24	29.85	0.048
138.25	29.95	0.052
138.26	30.04	0.056
138.27	30.14	0.057
138.28	30.24	0.061
138.29	30.34	0.063
138.30	30.44	0.066
138.31	30.53	0.067
138.32	30.63	0.068
138.33	30.73	0.069
138.34	30.83	0.069
138.35	30.93	0.070
138.36	31.03	0.071
138.37	31.13	0.072
138.38	31.23	0.072
138.39	31.33	0.072
138.40	31.43	0.073
138.41	31.53	0.073
138.42	31.63	0.075
138.43	31.73	0.077
138.44	31.83	0.077
138.45	31.92	0.079
138.46	32.02	0.079
138.47	32.12	0.080
138.48	32.22	0.081
138.49	32.32	0.082
138.50	32.42	0.083
138.51	32.52	0.084
138.52	32.62	0.085
138.53	32.72	0.085
138.54	32.82	0.086
138.55	32.92	0.087
138.56	33.02	0.088
138.57	33.12	0.089
138.58	33.22	0.090
138.59	33.32	0.091
138.60	33.42	0.092
138.61	33.52	0.093
138.62	33.62	0.094
138.63	33.72	0.095
138.64	33.82	0.095
138.65	33.92	0.096
138.66	34.02	0.097
138.67	34.12	0.097
138.68	34.22	0.097
138.69	34.32	0.097
138.70	34.42	0.098
138.71	34.52	0.098
138.72	34.62	0.098
138.73	34.72	0.098
138.74	34.82	0.098
138.75	34.92	0.098
138.76	35.02	0.099
138.77	35.12	0.099
138.78	35.22	0.099
138.79	35.32	0.099
138.80	35.42	0.099
138.81	35.52	0.099
138.82	35.62	0.099
138.83	35.72	0.099
138.84	35.82	0.099
138.85	35.92	0.101
138.86	36.02	0.103
138.87	36.12	0.106
138.88	36.22	0.109
138.89	36.32	0.113
138.90	36.42	0.114
138.91	36.52	0.117
138.92	36.62	0.119
138.93	36.72	0.120
138.94	36.82	0.121
138.95	36.92	0.122
138.96	37.02	0.123
138.97	37.12	0.124
138.98	37.22	0.125
138.99	37.32	0.125
139.00	37.42	0.126
139.01	37.52	0.126
139.02	37.62	0.126
139.03	37.72	0.127
139.04	37.82	0.127
139.05	37.92	0.127
139.06	38.02	0.127
139.07	38.12	0.127
139.08	38.22	0.128
139.09	38.31	0.128
139.10	38.42	0.128
139.11	38.52	0.128
139.12	38.62	0.128
139.13	38.72	0.129
139.14	38.82	0.129
139.15	38.92	0.129
139.16	39.02	0.129
139.17	39.12	0.129
139.18	39.22	0.129
139.19	39.32	0.130
139.20	39.42	0.130
139.21	39.52	0.130
139.22	39.62	0.130
139.23	39.72	0.130
139.24	39.82	0.131
139.25	39.92	0.131
139.26	40.02	0.131
139.27	40.12	0.131
139.28	40.22	0.131
139.29	40.32	0.132
139.30	40.42	0.132
139.31	40.52	0.132
139.32	40.62	0.132
139.33	40.72	0.132
139.34	40.82	0.132
139.35	40.92	0.132
139.36	41.02	0.133
139.37	41.12	0.133
139.38	41.22	0.133
139.39	41.32	0.133
139.40	41.42	0.133
139.41	41.52	0.133
139.42	41.62	0.133
139.43	41.72	0.133
139.44	41.82	0.134
139.45	41.92	0.134
139.46	42.02	0.134
139.47	42.12	0.134
139.48	42.22	0.134
139.49	42.32	0.134
139.50	42.42	0.134
139.51	42.52	0.134
139.52	42.62	0.134
139.53	42.72	0.135
139.54	42.82	0.135
139.55	42.92	0.135
139.56	43.02	0.135
139.57	43.12	0.135
139.58	43.22	0.135
139.59	43.32	0.135
139.60	43.42	0.135
139.61	43.52	0.135
139.62	43.62	0.135
139.63	43.72	0.136
139.64	43.82	0.136
139.65	43.92	0.136
139.66	44.02	0.136
139.67	44.12	0.136
139.68	44.22	0.136
139.69	44.32	0.136
139.70	44.42	0.136
139.71	44.52	0.136
139.72	44.62	0.136
139.73	44.72	0.136
139.74	44.82	0.136
139.75	44.92	0.137
139.76	45.02	0.137
139.77	45.12	0.137
139.78	45.22	0.137
139.79	45.32	0.137
139.80	45.42	0.137
139.81	45.52	0.137
139.82	45.62	0.137
139.83	45.72	0.137
139.84	45.82	0.137
139.85	45.92	0.137
139.86	46.02	0.137
139.87	46.12	0.137
139.88	46.22	0.138
139.89	46.32	0.138
139.90	46.42	0.138
139.91	46.52	0.138
139.92	46.62	0.138
139.93	46.72	0.138
139.94	46.82	0.138
139.95	46.92	0.138
139.96	47.02	0.138
139.97	47.12	0.138
139.98	47.22	0.138
139.99	47.32	0.138
140.00	47.42	0.138
140.01	47.52	0.138
140.02	47.63	0.138
140.03	47.72	0.138
140.04	47.82	0.138
140.05	47.93	0.138
140.06	48.03	0.139
140.07	48.13	0.139
140.08	48.22	0.139
140.09	48.32	0.139
140.10	48.43	0.139
140.11	48.52	0.139
140.12	48.63	0.139
140.13	48.73	0.139
140.14	48.83	0.139
140.15	48.93	0.139
140.16	49.03	0.139
140.17	49.13	0.139
140.18	49.23	0.139
140.19	49.33	0.139
140.20	49.43	0.139
140.21	49.53	0.139
140.22	49.63	0.140
140.23	49.73	0.140
140.24	49.83	0.140
140.25	49.93	0.140
140.26	50.03	0.140
140.27	50.13	0.140
140.28	50.23	0.140
140.29	50.33	0.140
140.30	50.43	0.140
140.31	50.53	0.140
140.32	50.63	0.140
140.33	50.73	0.140
140.34	50.83	0.140
140.35	50.93	0.141
140.36	51.03	0.141
140.37	51.13	0.141
140.38	51.23	0.141
140.39	51.33	0.141
140.40	51.43	0.141
140.41	51.53	0.141
140.42	51.63	0.141
140.43	51.73	0.141
140.44	51.83	0.141
140.45	51.93	0.141
140.46	52.03	0.141
140.47	52.13	0.141
140.48	52.23	0.141
140.49	52.33	0.141
140.50	52.43	0.142
140.51	52.53	0.142
140.52	52.63	0.142
140.53	52.73	0.142
140.54	52.83	0.142
140.55	52.93	0.142
140.56	53.03	0.142
140.57	53.13	0.142
140.58	53.23	0.143
140.59	53.33	0.143
140.60	53.43	0.143
140.61	53.53	0.143
140.62	53.63	0.144
140.63	53.73	0.144
140.64	53.83	0.145
140.65	53.93	0.147
140.66	54.03	0.148
140.67	54.13	0.152
140.68	54.23	0.159
140.69	54.33	0.164
140.70	54.43	0.178
140.71	54.53	0.194
140.72	54.62	0.215
140.73	54.72	0.250
140.74	54.81	0.305
140.75	54.91	0.365
140.76	55.00	0.420
140.77	55.09	0.469
140.78	55.18	0.527
140.79	55.26	0.600
140.80	55.35	0.695
140.81	55.43	0.817
140.82	55.51	0.958
140.83	55.59	1.115
140.84	55.66	1.285
140.85	55.72	1.452
140.86	55.79	1.614
140.87	55.85	1.764
140.88	55.91	1.909
140.89	55.97	2.041
140.90	56.04	2.167
140.91	56.10	2.292
140.92	56.16	2.398
140.93	56.22	2.505
140.94	56.29	2.604
140.95	56.35	2.705
140.96	56.42	2.804
140.97	56.48	2.894
140.98	56.55	2.969
140.99	56.62	3.035
141.00	56.70	3.102
141.01	56.77	3.172
141.02	56.84	3.228
141.03	56.92	3.249
141.04	57.00	3.239
141.05	57.09	3.202
141.06	57.17	3.165
141.07	57.27	3.121
141.08	57.36	3.065
141.09	57.46	3.004
141.10	57.57	2.945
141.11	57.67	2.909
141.12	57.78	2.874
141.13	57.89	2.830
141.14	57.99	2.811
141.15	58.10	2.818
141.16	58.20	2.809
141.17	58.31	2.760
141.18	58.42	2.656
141.19	58.53	2.517
141.20	58.65	2.352
141.21	58.78	2.190
141.22	58.91	2.040
141.23	59.04	1.899
141.24	59.17	1.770
141.25	59.30	1.658
141.26	59.43	1.555
141.27	59.57	1.459
141.28	59.70	1.358
141.29	59.83	1.249
141.30	59.96	1.123
141.31	60.10	0.994
141.32	60.23	0.884
141.33	60.36	0.789
141.34	60.49	0.736
141.35	60.62	0.672
141.36	60.75	0.628
141.37	60.87	0.588
141.38	61.00	0.555
141.39	61.12	0.521
141.40	61.23	0.493
141.41	61.35	0.467
141.42	61.47	0.442
141.43	61.58	0.419
141.44	61.69	0.402
141.45	61.81	0.383
141.46	61.92	0.367
141.47	62.03	0.353
141.48	62.13	0.340
141.49	62.24	0.328
141.50	62.35	0.315
141.51	62.46	0.306
141.52	62.56	0.296
141.53	62.67	0.288
141.54	62.77	0.282
141.55	62.88	0.273
141.56	62.98	0.268
141.57	63.09	0.262
141.58	63.19	0.256
141.59	63.29	0.251
141.60	63.40	0.249
141.61	63.50	0.244
141.62	63.60	0.240
141.63	63.70	0.237
141.64	63.81	0.234
141.65	63.91	0.232
141.66	64.01	0.230
141.67	64.11	0.227
141.68	64.21	0.225
141.69	64.31	0.224
141.70	64.41	0.222
141.71	64.51	0.221
141.72	64.62	0.220
141.73	64.72	0.219
141.74	64.82	0.218
141.75	64.92	0.217
141.76	65.02	0.216
141.77	65.12	0.216
141.78	65.22	0.215
141.79	65.32	0.215
141.80	65.42	0.214
141.81	65.52	0.214
141.82	65.62	0.213
141.83	65.72	0.213
141.84	65.82	0.212
141.85	65.92	0.212
141.86	66.02	0.212
141.87	66.12	0.212
141.88	66.22	0.211
141.89	66.33	0.211
141.90	66.43	0.211
141.91	66.53	0.211
141.92	66.63	0.211
141.93	66.73	0.210
141.94	66.83	0.210
141.95	66.93	0.210
141.96	67.03	0.210
141.97	67.13	0.209
141.98	67.23	0.209
141.99	67.33	0.209
142.00	67.43	0.209
142.01	67.53	0.209
142.02	67.63	0.209
142.03	67.73	0.209
142.04	67.83	0.209
142.05	67.93	0.208
142.06	68.03	0.208
142.07	68.13	0.208
142.08	68.23	0.208
142.09	68.33	0.208
142.10	68.43	0.208
142.11	68.53	0.208
142.12	68.63	0.208
142.13	68.73	0.208
142.14	68.83	0.208
142.15	68.93	0.207
142.16	69.03	0.207
142.17	69.13	0.207
142.18	69.23	0.207
142.19	69.33	0.207
142.20	69.43	0.207
142.21	69.53	0.207
142.22	69.63	0.207
142.23	69.73	0.207
142.24	69.83	0.207
142.25	69.93	0.207
142.26	70.03	0.207
142.27	70.13	0.207
142.28	70.23	0.207
142.29	70.33	0.207
142.30	70.43	0.207
142.31	70.53	0.207
142.32	70.63	0.207
142.33	70.73	0.207
142.34	70.83	0.207
142.35	70.93	0.207
142.36	71.03	0.207
142.37	71.13	0.207
142.38	71.23	0.207
142.39	71.33	0.207
142.40	71.43	0.207
142.41	71.53	0.207
142.42	71.63	0.207
142.43	71.73	0.207
142.44	71.83	0.207
142.45	71.93	0.207
142.46	72.03	0.207
142.47	72.13	0.207
142.48	72.23	0.207
142.49	72.33	0.207
142.50	72.43	0.207
142.51	72.53	0.207
142.52	72.63	0.207
142.53	72.73	0.207
142.54	72.83	0.207
142.55	72.94	0.207
142.56	73.04	0.207
142.57	73.14	0.207
142.58	73.23	0.207
142.59	73.34	0.207
142.60	73.44	0.207
142.61	73.54	0.207
142.62	73.64	0.207
142.63	73.74	0.207
142.64	73.84	0.207
142.65	73.94	0.207
142.66	74.04	0.207
142.67	74.14	0.207
142.68	74.24	0.207
142.69	74.34	0.207
142.70	74.44	0.207
142.71	74.54	0.207
142.72	74.64	0.207
142.73	74.74	0.207
142.74	74.84	0.207
142.75	74.94	0.207
142.76	75.04	0.207
142.77	75.14	0.207
142.78	75.24	0.207
142.79	75.34	0.207
142.80	75.44	0.207
142.81	75.54	0.207
142.82	75.64	0.207
142.83	75.74	0.207
142.84	75.84	0.207
142.85	75.94	0.207
142.86	76.04	0.207
142.87	76.14	0.208
142.88	76.24	0.208
142.89	76.34	0.208
142.90	76.44	0.208
142.91	76.54	0.208
142.92	76.64	0.208
142.93	76.74	0.208
142.94	76.84	0.208
142.95	76.94	0.208
142.96	77.04	0.208
142.97	77.14	0.208
142.98	77.24	0.208
142.99	77.34	0.208
143.00	77.44	0.208
143.01	77.54	0.208
143.02	77.64	0.208
143.03	77.74	0.208
143.04	77.84	0.208
143.05	77.94
143.06	78.04
143.07	78.14
143.08	78.24
143.09	78.34
143.10