File: DSC/2023_05_24_CBD_Al_NonHerm_Tzero.txt
Filename	2023_05_24_CBD_Al_NonHerm_Tzero
Instrument name	DSC2A-00468 (192.168.1.100)
Operator	JLY
rundate	5/25/2023
Sample name	2023_05_24_CBD_Al_NonHerm_Tzero
proceduresegments	Data Off ; Equilibrate 30.00 °C; Data On ; Ramp 10.00 °C/min to 100.00 °C; Data Off ; Isothermal 1.0 min; Data On ; Ramp 10.00 °C/min to -50.00 °C; Data Off ; Isothermal 1.0 min; Data On ; Ramp 10.00 °C/min to 100.00 °C; Data Off ; Isothermal 1.0 min; Data Off ; Ramp 10.00 °C/min to -50.00 °C; Data Off ; Isothermal 1.0 min; Data Off ; Ramp 10.00 °C/min to 100.00 °C; Data Off
[File Parameters]
Run date	5/25/2023 10:55:11 AM
Trios version	5.1.1.46572
Original File Name
Current File Name	C:\Users\yargerlab\Desktop\DSC Data\General\2023_05_24_CBD_Al_NonHerm_Tzero.tri
[Procedure]
Procedure Name	DSC 30C to 100C to n50C at 10Cmin 2 cyles
Sample Name	2023_05_24_CBD_Al_NonHerm_Tzero
Sample Mass	5.06 mg
Reference Sample Mass	0 mg
Pan Mass	51.14 mg
Pan Number	16
Reference Pan Mass	51.33 mg
Reference Pan Number	10
Pan Type	Tzero Aluminum
Comments	CBD Xtal Powder, same used for spray dried CBD:PVP ASDs.  Tzero Std lid (non hermetic) and Tzero Pan.
Project Name	ASDs
Operator	JLY
Test	Custom
Unload Max Temperature	30
Unload Min Temperature	30
Load Max Temperature	30
Load Min Temperature	30
Stop on Gas Flow Error	Yes
[Signal List]
Signal #1	Time (min)
Signal #2	Temperature (°C)
Signal #3	Heat Flow (mW)
Signal #4	Delta T (µV)
Signal #5	Delta Tzero (µV)
Signal #6	Tzero Temperature (°C)
Signal #7	Cell Purge (mL/min)
Signal #8	Heater Temp (°C)
Signal #9	Power Delivered (W)
Signal #10	Reference Junction Temperature (°C)
Signal #11	Flange Temperature (°C)
Signal #12	Heat Flow Phase (rad)
Signal #13	Total Heat Capacity (J/°C)
Signal #14	Heat Capacity (J/°C)
[Configuration]
Company Name	ASU
Instrument Name	DSC2A-00468
Instrument Type	DSC2500
Serial Number	DSC2A-00468
IP	192.168.1.100
Location of Instrument	MRRC
DisplayType	Unknown
Sample Interval 	0.1 s/pt
Selected Heat Flow	T4P
Exotherm Direction	Down
Cell Serial	DRC2-00792
Lid Type	Standard
Cooler	RCS 90
Leave Cooler on at End of Sequence	On
Gas 2	Nitrogen
Gas Selected	Channel 1
Flow Rate	50 mL/min
Secondary Purge	On
Licensed Heat Flow	Heat Flow T4P
Modulation Licensed	Yes
[Versions]
Common IDD Version	1
Cortex Version	VER 2.10.2.31
Driver	5.0.0.6
GDM Version	1.0.3.3
TouchscreenVersion	1.0.0.16145
FEP Version	1.2.1.21
FEP Bootloader	2.0.0.5
AutoSampler Version	2.1.1.26
Auto Sampler Bootloader	2.0.0.5
FCM Version	1.1.0.3
FCM Bootloader	2.0.0.5
[Experiment Logs]
Experiment Log Entry # 1	Data On set to 0
Experiment Log Entry # 3	Equilibrate Segment 30 (C) Started
Experiment Log Entry # 5	Air Cool is off.
Experiment Log Entry # 7	Data On set to 1
Experiment Log Entry # 9	Ramp Segment 10 C/min to 100 Started
Experiment Log Entry # 11	Data On set to 0
Experiment Log Entry # 13	Isothermal Segment 1 min started
Experiment Log Entry # 15	Data On set to 1
Experiment Log Entry # 17	Ramp Segment 10 C/min to -50 Started
Experiment Log Entry # 19	Data On set to 0
Experiment Log Entry # 21	Isothermal Segment 1 min started
Experiment Log Entry # 23	Data On set to 1
Experiment Log Entry # 25	Ramp Segment 10 C/min to 100 Started
Experiment Log Entry # 27	Data On set to 0
Experiment Log Entry # 29	Isothermal Segment 1 min started
Experiment Log Entry # 31	Data On set to 0
Experiment Log Entry # 33	Ramp Segment 10 C/min to -50 Started
Experiment Log Entry # 35	Data On set to 0
Experiment Log Entry # 37	Isothermal Segment 1 min started
Experiment Log Entry # 39	Data On set to 0
Experiment Log Entry # 41	Ramp Segment 10 C/min to 100 Started
Experiment Log Entry # 43	Data On set to 0
[Method Log]
Method Log Entry # 1	Data Off
Method Log Entry # 2	Equilibrate 30 °C
Method Log Entry # 3	Data On
Method Log Entry # 4	(Ramp 9017) Ramp 10 °C/minute to 100 °C
Method Log Entry # 5	Data Off
Method Log Entry # 6	Isothermal 1 minutes
Method Log Entry # 7	Data On
Method Log Entry # 8	(Ramp 9021) Ramp 10 °C/minute to -50 °C
Method Log Entry # 9	Data Off
Method Log Entry # 10	Isothermal 1 minutes
Method Log Entry # 11	Data On
Method Log Entry # 12	(Ramp 9025) Ramp 10 °C/minute to 100 °C
Method Log Entry # 13	Data Off
Method Log Entry # 14	Isothermal 1 minutes
Method Log Entry # 15	Data Off
Method Log Entry # 16	(Ramp 9029) Ramp 10 °C/minute to -50 °C
Method Log Entry # 17	Data Off
Method Log Entry # 18	Isothermal 1 minutes
Method Log Entry # 19	Data Off
Method Log Entry # 20	(Ramp 9033) Ramp 10 °C/minute to 100 °C
Method Log Entry # 21	Data Off
Cell Serial	DRC2-00792
[T1 Calibration]
Slope	-0.008529666
Offset	9.636258
Initial Temperature	98.23
GUID	f8bfdadc-4977-4fdf-ba6d-0ba9134940c3
[TZero Calibration]
Date Applied	11/29/2022 4:06:13 PM
Description	From -89.059 °C to 396.009 °C at 20.000°C/min
Gas Type	Nitrogen
Pan Type	None
Source Files 1	C:\Users\yargerlab\Desktop\DSC Data\General\TZero_calibration_11_29_22_2nd(2).tri
Source Files 2	C:\Users\yargerlab\Desktop\DSC Data\General\TZero_calibration_11_29_22_2nd(3).tri
Delta T Offset	13.05235
Delta T Slope	-0.007271007
Delta T0 Offset	-13.69128
Delta T0 Slope	0.06063341
[Temperature Calibration]
Date Applied	11/29/2022 7:12:28 PM
Description	From 106.590 °C to 186.590 °C at 10.000°C/min
Gas Type	Nitrogen
Pan Type	Tzero Aluminum Hermetic
Source Files 1	C:\Users\yargerlab\Desktop\DSC Data\General\Indium(6).tri
Measured 1	157.391
Known 1	156.598
[Cell Constant Calibration]
Date Applied	11/29/2022 7:12:29 PM
Description	From 106.590 °C to 186.590 °C at 10.000°C/min
Gas Type	Nitrogen
Pan Type	Tzero Aluminum Hermetic
Source Files 1	C:\Users\yargerlab\Desktop\DSC Data\General\Indium(6).tri
T4P KCell	1.006051
Onset Slope	63.26126 mW/°C
[Direct Cp Calibration]
Date Applied	11/30/2022 11:04:51 AM
Description	From -79.983 °C to 298.409 °C at 10.000°C/min
Gas Type	Nitrogen
Pan Type	Tzero Aluminum Hermetic
Source Files 1	C:\Users\yargerlab\Desktop\DSC Data\General\Sapphire_Heat_Capacity_11_30_22.tri
[Rev Cp Calibration]
Date Applied	11/30/2022 1:58:51 PM
Description	From -79.996 °C to 292.812 °C at 3.000°C/min
Gas Type	Nitrogen
Pan Type	Tzero Aluminum Hermetic
Source Files 1	C:\Users\yargerlab\Desktop\DSC Data\General\Sapphire_MDSC_Calibration_11_30_22.tri
[step]
Ramp 10.00 °C/min to 100.00 °C
Time	Temperature	Heat Flow (Normalized)
min	°C	W/g
0.00	29.97	0.021
0.01	29.97	0.020
0.01	29.97	0.019
0.01	29.98	0.018
0.02	29.98	0.017
0.03	29.98	0.016
0.03	29.99	0.016
0.03	29.99	0.016
0.04	30.00	0.015
0.05	30.00	0.015
0.05	30.01	0.015
0.05	30.02	0.015
0.06	30.03	0.015
0.07	30.04	0.015
0.07	30.05	0.015
0.08	30.06	0.015
0.08	30.08	0.016
0.08	30.10	0.017
0.09	30.11	0.018
0.09	30.14	0.022
0.10	30.16	0.027
0.11	30.18	0.033
0.11	30.21	0.039
0.12	30.23	0.044
0.12	30.26	0.049
0.13	30.29	0.055
0.13	30.32	0.061
0.14	30.36	0.066
0.14	30.39	0.073
0.14	30.42	0.080
0.15	30.46	0.086
0.16	30.49	0.093
0.16	30.53	0.100
0.16	30.57	0.107
0.17	30.61	0.113
0.18	30.65	0.119
0.18	30.69	0.126
0.19	30.73	0.132
0.19	30.77	0.138
0.19	30.81	0.144
0.20	30.85	0.149
0.21	30.89	0.154
0.21	30.93	0.158
0.21	30.97	0.164
0.22	31.01	0.169
0.23	31.06	0.172
0.23	31.10	0.176
0.24	31.14	0.181
0.24	31.19	0.185
0.24	31.23	0.189
0.25	31.28	0.192
0.26	31.32	0.194
0.26	31.37	0.197
0.26	31.41	0.202
0.27	31.46	0.206
0.28	31.50	0.208
0.28	31.55	0.209
0.29	31.59	0.212
0.29	31.64	0.215
0.30	31.69	0.218
0.30	31.73	0.220
0.30	31.78	0.222
0.31	31.83	0.224
0.31	31.87	0.226
0.32	31.92	0.228
0.33	31.97	0.230
0.33	32.01	0.233
0.34	32.06	0.235
0.34	32.11	0.237
0.35	32.16	0.237
0.35	32.20	0.237
0.35	32.25	0.240
0.36	32.30	0.243
0.36	32.35	0.245
0.37	32.40	0.245
0.38	32.45	0.245
0.38	32.49	0.247
0.39	32.54	0.249
0.39	32.59	0.249
0.40	32.64	0.250
0.40	32.69	0.251
0.40	32.74	0.253
0.41	32.79	0.254
0.41	32.83	0.255
0.42	32.88	0.255
0.43	32.93	0.255
0.43	32.98	0.256
0.44	33.03	0.257
0.44	33.08	0.258
0.45	33.13	0.259
0.45	33.18	0.260
0.45	33.23	0.260
0.46	33.28	0.260
0.46	33.33	0.261
0.47	33.38	0.262
0.48	33.42	0.262
0.48	33.47	0.262
0.49	33.52	0.263
0.49	33.57	0.263
0.50	33.62	0.264
0.50	33.67	0.264
0.50	33.72	0.264
0.51	33.77	0.265
0.51	33.82	0.265
0.52	33.87	0.265
0.53	33.92	0.265
0.53	33.97	0.266
0.53	34.02	0.266
0.54	34.07	0.266
0.55	34.12	0.266
0.55	34.17	0.267
0.55	34.22	0.267
0.56	34.27	0.267
0.57	34.32	0.267
0.57	34.37	0.267
0.58	34.42	0.267
0.58	34.46	0.268
0.58	34.52	0.268
0.59	34.56	0.268
0.60	34.61	0.268
0.60	34.67	0.268
0.60	34.71	0.268
0.61	34.76	0.269
0.62	34.81	0.269
0.62	34.86	0.269
0.63	34.91	0.269
0.63	34.96	0.269
0.63	35.01	0.269
0.64	35.06	0.269
0.65	35.11	0.270
0.65	35.16	0.270
0.65	35.21	0.270
0.66	35.26	0.270
0.67	35.31	0.270
0.67	35.36	0.270
0.68	35.41	0.270
0.68	35.46	0.270
0.68	35.51	0.270
0.69	35.56	0.270
0.70	35.61	0.271
0.70	35.66	0.271
0.70	35.71	0.271
0.71	35.76	0.271
0.72	35.81	0.271
0.72	35.86	0.271
0.73	35.91	0.271
0.73	35.96	0.271
0.73	36.01	0.271
0.74	36.06	0.271
0.75	36.11	0.271
0.75	36.16	0.271
0.75	36.21	0.272
0.76	36.26	0.272
0.77	36.31	0.272
0.77	36.36	0.272
0.78	36.41	0.272
0.78	36.46	0.272
0.78	36.51	0.272
0.79	36.56	0.272
0.80	36.61	0.272
0.80	36.66	0.272
0.80	36.71	0.272
0.81	36.76	0.272
0.82	36.81	0.272
0.82	36.86	0.272
0.83	36.91	0.273
0.83	36.95	0.273
0.83	37.01	0.273
0.84	37.06	0.273
0.85	37.11	0.273
0.85	37.15	0.273
0.85	37.20	0.273
0.86	37.25	0.273
0.87	37.30	0.273
0.87	37.35	0.273
0.88	37.40	0.273
0.88	37.45	0.273
0.88	37.50	0.273
0.89	37.55	0.273
0.90	37.60	0.273
0.90	37.65	0.274
0.90	37.70	0.274
0.91	37.75	0.274
0.92	37.80	0.274
0.92	37.85	0.274
0.93	37.90	0.274
0.93	37.95	0.274
0.93	38.00	0.274
0.94	38.05	0.274
0.95	38.10	0.274
0.95	38.15	0.274
0.95	38.20	0.274
0.96	38.25	0.274
0.97	38.30	0.274
0.97	38.35	0.274
0.98	38.40	0.274
0.98	38.45	0.274
0.98	38.50	0.274
0.99	38.55	0.275
1.00	38.60	0.275
1.00	38.65	0.275
1.00	38.70	0.275
1.01	38.75	0.275
1.02	38.80	0.275
1.02	38.85	0.275
1.03	38.90	0.275
1.03	38.95	0.275
1.03	39.00	0.275
1.04	39.05	0.275
1.05	39.10	0.275
1.05	39.15	0.275
1.05	39.20	0.275
1.06	39.25	0.275
1.07	39.30	0.275
1.07	39.35	0.275
1.08	39.40	0.275
1.08	39.45	0.275
1.08	39.50	0.275
1.09	39.55	0.276
1.09	39.60	0.276
1.10	39.65	0.276
1.11	39.70	0.276
1.11	39.75	0.276
1.12	39.80	0.276
1.12	39.85	0.276
1.13	39.90	0.276
1.13	39.95	0.276
1.13	40.00	0.276
1.14	40.05	0.276
1.14	40.10	0.276
1.15	40.15	0.276
1.16	40.20	0.276
1.16	40.25	0.276
1.17	40.30	0.276
1.17	40.35	0.276
1.18	40.40	0.276
1.18	40.45	0.276
1.18	40.50	0.276
1.19	40.55	0.276
1.19	40.60	0.276
1.20	40.65	0.276
1.21	40.70	0.277
1.21	40.75	0.277
1.22	40.80	0.277
1.22	40.85	0.277
1.23	40.90	0.277
1.23	40.95	0.277
1.23	41.00	0.277
1.24	41.05	0.277
1.24	41.10	0.277
1.25	41.15	0.277
1.26	41.20	0.277
1.26	41.25	0.277
1.27	41.30	0.277
1.27	41.35	0.277
1.28	41.40	0.277
1.28	41.45	0.277
1.28	41.50	0.277
1.29	41.55	0.277
1.29	41.60	0.277
1.30	41.65	0.277
1.31	41.70	0.277
1.31	41.75	0.277
1.32	41.80	0.277
1.32	41.85	0.277
1.33	41.90	0.277
1.33	41.95	0.277
1.33	42.00	0.277
1.34	42.05	0.277
1.34	42.10	0.278
1.35	42.15	0.278
1.36	42.20	0.278
1.36	42.25	0.278
1.37	42.30	0.278
1.37	42.35	0.278
1.38	42.40	0.278
1.38	42.45	0.278
1.38	42.50	0.278
1.39	42.55	0.278
1.39	42.60	0.278
1.40	42.65	0.278
1.41	42.70	0.278
1.41	42.75	0.278
1.42	42.80	0.278
1.42	42.85	0.278
1.43	42.90	0.278
1.43	42.95	0.278
1.43	43.00	0.278
1.44	43.05	0.278
1.44	43.10	0.278
1.45	43.15	0.278
1.46	43.20	0.278
1.46	43.25	0.278
1.47	43.30	0.278
1.47	43.35	0.278
1.48	43.40	0.278
1.48	43.45	0.279
1.48	43.50	0.279
1.49	43.55	0.279
1.49	43.60	0.279
1.50	43.65	0.279
1.51	43.70	0.279
1.51	43.75	0.279
1.52	43.80	0.279
1.52	43.85	0.279
1.53	43.90	0.279
1.53	43.95	0.279
1.53	44.00	0.279
1.54	44.05	0.279
1.54	44.10	0.279
1.55	44.15	0.279
1.56	44.20	0.279
1.56	44.25	0.279
1.57	44.30	0.279
1.57	44.34	0.279
1.58	44.40	0.279
1.58	44.45	0.279
1.58	44.50	0.279
1.59	44.55	0.279
1.59	44.60	0.279
1.60	44.65	0.279
1.61	44.69	0.279
1.61	44.75	0.279
1.62	44.80	0.279
1.62	44.85	0.279
1.63	44.90	0.279
1.63	44.95	0.279
1.63	44.99	0.279
1.64	45.05	0.279
1.64	45.10	0.280
1.65	45.15	0.280
1.66	45.20	0.280
1.66	45.25	0.280
1.67	45.30	0.280
1.67	45.35	0.280
1.68	45.40	0.280
1.68	45.45	0.280
1.68	45.50	0.280
1.69	45.55	0.280
1.69	45.60	0.280
1.70	45.65	0.280
1.71	45.70	0.280
1.71	45.75	0.280
1.72	45.80	0.280
1.72	45.85	0.280
1.73	45.90	0.280
1.73	45.95	0.280
1.73	46.00	0.280
1.74	46.05	0.280
1.74	46.10	0.280
1.75	46.15	0.280
1.76	46.20	0.280
1.76	46.25	0.280
1.77	46.30	0.280
1.77	46.35	0.280
1.78	46.40	0.280
1.78	46.45	0.280
1.78	46.50	0.281
1.79	46.55	0.281
1.79	46.60	0.281
1.80	46.65	0.281
1.81	46.70	0.281
1.81	46.75	0.281
1.82	46.80	0.281
1.82	46.85	0.281
1.83	46.90	0.281
1.83	46.95	0.281
1.83	47.00	0.281
1.84	47.05	0.281
1.84	47.10	0.281
1.85	47.15	0.281
1.86	47.20	0.281
1.86	47.25	0.281
1.87	47.30	0.281
1.87	47.35	0.281
1.88	47.40	0.281
1.88	47.45	0.281
1.88	47.50	0.281
1.89	47.55	0.281
1.89	47.60	0.281
1.90	47.65	0.281
1.91	47.70	0.281
1.91	47.75	0.281
1.92	47.80	0.281
1.92	47.85	0.281
1.93	47.90	0.281
1.93	47.95	0.281
1.93	48.00	0.281
1.94	48.05	0.281
1.94	48.10	0.282
1.95	48.15	0.282
1.96	48.20	0.282
1.96	48.25	0.282
1.97	48.30	0.282
1.97	48.35	0.282
1.98	48.40	0.282
1.98	48.45	0.282
1.98	48.50	0.282
1.99	48.55	0.282
1.99	48.60	0.282
2.00	48.65	0.282
2.01	48.70	0.282
2.01	48.75	0.282
2.02	48.80	0.282
2.02	48.85	0.282
2.03	48.90	0.282
2.03	48.95	0.282
2.03	49.00	0.282
2.04	49.05	0.282
2.04	49.10	0.282
2.05	49.15	0.282
2.06	49.20	0.282
2.06	49.25	0.282
2.07	49.30	0.282
2.07	49.35	0.282
2.08	49.40	0.282
2.08	49.45	0.283
2.08	49.50	0.283
2.09	49.55	0.283
2.09	49.60	0.283
2.10	49.65	0.283
2.11	49.70	0.283
2.11	49.75	0.283
2.12	49.80	0.283
2.12	49.85	0.283
2.13	49.90	0.283
2.13	49.95	0.283
2.14	50.00	0.283
2.14	50.05	0.283
2.14	50.10	0.283
2.15	50.15	0.283
2.16	50.20	0.283
2.16	50.25	0.283
2.16	50.30	0.283
2.17	50.35	0.283
2.18	50.40	0.283
2.18	50.45	0.283
2.19	50.50	0.283
2.19	50.55	0.283
2.19	50.60	0.283
2.20	50.65	0.284
2.21	50.70	0.284
2.21	50.75	0.284
2.21	50.80	0.284
2.22	50.85	0.284
2.23	50.90	0.284
2.23	50.95	0.284
2.24	51.00	0.284
2.24	51.05	0.284
2.24	51.10	0.284
2.25	51.15	0.284
2.26	51.20	0.284
2.26	51.25	0.284
2.26	51.30	0.284
2.27	51.35	0.284
2.28	51.40	0.284
2.28	51.45	0.284
2.29	51.50	0.284
2.29	51.55	0.284
2.29	51.60	0.284
2.30	51.65	0.284
2.31	51.70	0.284
2.31	51.75	0.284
2.31	51.80	0.284
2.32	51.85	0.285
2.33	51.90	0.285
2.33	51.95	0.285
2.34	52.00	0.285
2.34	52.05	0.285
2.34	52.10	0.285
2.35	52.15	0.285
2.36	52.20	0.285
2.36	52.25	0.285
2.36	52.30	0.285
2.37	52.35	0.285
2.38	52.40	0.285
2.38	52.45	0.285
2.39	52.50	0.285
2.39	52.55	0.285
2.39	52.60	0.285
2.40	52.65	0.285
2.41	52.70	0.285
2.41	52.75	0.285
2.41	52.80	0.285
2.42	52.85	0.285
2.43	52.90	0.286
2.43	52.95	0.286
2.44	53.00	0.286
2.44	53.05	0.286
2.44	53.10	0.286
2.45	53.15	0.286
2.46	53.20	0.286
2.46	53.25	0.286
2.46	53.30	0.286
2.47	53.35	0.286
2.48	53.40	0.286
2.48	53.45	0.286
2.49	53.50	0.286
2.49	53.55	0.286
2.49	53.60	0.286
2.50	53.65	0.286
2.51	53.70	0.286
2.51	53.75	0.286
2.51	53.80	0.286
2.52	53.85	0.286
2.53	53.90	0.287
2.53	53.95	0.287
2.54	54.00	0.287
2.54	54.05	0.287
2.54	54.10	0.287
2.55	54.15	0.287
2.56	54.20	0.287
2.56	54.25	0.287
2.56	54.30	0.287
2.57	54.35	0.287
2.58	54.40	0.287
2.58	54.45	0.287
2.59	54.50	0.287
2.59	54.55	0.287
2.59	54.60	0.287
2.60	54.65	0.287
2.61	54.70	0.287
2.61	54.75	0.287
2.61	54.80	0.287
2.62	54.85	0.288
2.63	54.90	0.288
2.63	54.95	0.288
2.64	55.00	0.288
2.64	55.05	0.288
2.64	55.10	0.288
2.65	55.15	0.288
2.66	55.20	0.288
2.66	55.25	0.288
2.66	55.30	0.288
2.67	55.35	0.288
2.68	55.40	0.288
2.68	55.45	0.288
2.69	55.50	0.288
2.69	55.55	0.288
2.69	55.60	0.289
2.70	55.65	0.289
2.71	55.70	0.289
2.71	55.75	0.289
2.71	55.80	0.289
2.72	55.85	0.289
2.73	55.90	0.289
2.73	55.95	0.289
2.74	56.00	0.289
2.74	56.05	0.289
2.74	56.10	0.289
2.75	56.15	0.289
2.76	56.20	0.289
2.76	56.25	0.290
2.76	56.30	0.290
2.77	56.35	0.290
2.78	56.40	0.290
2.78	56.45	0.290
2.79	56.50	0.290
2.79	56.55	0.290
2.79	56.60	0.290
2.80	56.65	0.290
2.81	56.70	0.290
2.81	56.75	0.290
2.81	56.80	0.291
2.82	56.85	0.291
2.83	56.90	0.291
2.83	56.95	0.291
2.84	57.00	0.291
2.84	57.05	0.291
2.84	57.10	0.291
2.85	57.15	0.291
2.86	57.20	0.291
2.86	57.25	0.291
2.86	57.30	0.291
2.87	57.35	0.291
2.88	57.40	0.292
2.88	57.45	0.292
2.89	57.50	0.292
2.89	57.55	0.292
2.89	57.60	0.292
2.90	57.65	0.292
2.91	57.70	0.292
2.91	57.75	0.292
2.91	57.80	0.292
2.92	57.85	0.292
2.93	57.90	0.292
2.93	57.95	0.293
2.94	58.00	0.293
2.94	58.05	0.293
2.94	58.10	0.293
2.95	58.15	0.293
2.96	58.20	0.293
2.96	58.25	0.293
2.96	58.30	0.293
2.97	58.35	0.294
2.98	58.40	0.294
2.98	58.45	0.294
2.99	58.50	0.294
2.99	58.55	0.294
2.99	58.60	0.295
3.00	58.65	0.295
3.01	58.70	0.295
3.01	58.75	0.295
3.01	58.80	0.295
3.02	58.85	0.295
3.03	58.90	0.295
3.03	58.95	0.295
3.04	59.00	0.296
3.04	59.05	0.296
3.04	59.10	0.296
3.05	59.15	0.296
3.06	59.20	0.296
3.06	59.25	0.296
3.06	59.30	0.297
3.07	59.35	0.297
3.08	59.40	0.297
3.08	59.45	0.297
3.09	59.50	0.298
3.09	59.55	0.298
3.09	59.60	0.298
3.10	59.65	0.298
3.11	59.70	0.299
3.11	59.75	0.299
3.11	59.80	0.299
3.12	59.85	0.299
3.13	59.90	0.300
3.13	59.95	0.301
3.14	60.00	0.301
3.14	60.05	0.301
3.14	60.10	0.302
3.15	60.15	0.302
3.16	60.20	0.302
3.16	60.25	0.303
3.16	60.30	0.303
3.17	60.35	0.304
3.18	60.40	0.304
3.18	60.45	0.304
3.19	60.50	0.304
3.19	60.55	0.305
3.19	60.60	0.305
3.20	60.65	0.306
3.21	60.70	0.307
3.21	60.75	0.308
3.21	60.80	0.309
3.22	60.85	0.309
3.23	60.90	0.310
3.23	60.95	0.311
3.24	61.00	0.312
3.24	61.05	0.313
3.24	61.10	0.313
3.25	61.15	0.314
3.26	61.20	0.314
3.26	61.25	0.315
3.26	61.30	0.317
3.27	61.35	0.317
3.28	61.40	0.318
3.28	61.45	0.319
3.29	61.50	0.320
3.29	61.55	0.321
3.29	61.60	0.322
3.30	61.65	0.323
3.31	61.70	0.324
3.31	61.75	0.326
3.31	61.80	0.327
3.32	61.85	0.328
3.33	61.90	0.329
3.33	61.95	0.330
3.34	62.00	0.331
3.34	62.05	0.333
3.34	62.10	0.334
3.35	62.15	0.335
3.36	62.20	0.337
3.36	62.25	0.339
3.36	62.30	0.340
3.37	62.34	0.342
3.38	62.40	0.344
3.38	62.44	0.345
3.39	62.49	0.346
3.39	62.54	0.348
3.39	62.59	0.350
3.40	62.64	0.352
3.41	62.69	0.354
3.41	62.74	0.356
3.41	62.79	0.358
3.42	62.84	0.360
3.43	62.89	0.362
3.43	62.94	0.365
3.44	62.99	0.367
3.44	63.04	0.369
3.44	63.09	0.372
3.45	63.14	0.375
3.46	63.19	0.378
3.46	63.24	0.381
3.46	63.28	0.384
3.47	63.33	0.387
3.48	63.38	0.391
3.48	63.43	0.394
3.49	63.48	0.397
3.49	63.53	0.402
3.49	63.58	0.405
3.50	63.63	0.410
3.51	63.68	0.414
3.51	63.73	0.419
3.51	63.78	0.423
3.52	63.83	0.428
3.53	63.87	0.433
3.53	63.92	0.439
3.54	63.97	0.444
3.54	64.02	0.451
3.54	64.07	0.456
3.55	64.12	0.462
3.56	64.17	0.469
3.56	64.22	0.477
3.56	64.26	0.485
3.57	64.31	0.493
3.58	64.36	0.501
3.58	64.41	0.510
3.59	64.46	0.518
3.59	64.50	0.528
3.59	64.55	0.539
3.60	64.60	0.550
3.61	64.65	0.562
3.61	64.69	0.573
3.61	64.74	0.586
3.62	64.79	0.600
3.63	64.83	0.615
3.63	64.88	0.628
3.64	64.93	0.643
3.64	64.98	0.660
3.64	65.02	0.679
3.65	65.07	0.696
3.66	65.11	0.714
3.66	65.16	0.735
3.66	65.20	0.757
3.67	65.25	0.778
3.68	65.29	0.800
3.68	65.34	0.823
3.69	65.38	0.849
3.69	65.43	0.876
3.69	65.47	0.903
3.70	65.52	0.931
3.71	65.56	0.960
3.71	65.60	0.991
3.71	65.64	1.024
3.72	65.69	1.058
3.73	65.73	1.093
3.73	65.77	1.129
3.74	65.81	1.165
3.74	65.85	1.203
3.74	65.89	1.242
3.75	65.93	1.280
3.76	65.97	1.320
3.76	66.01	1.361
3.76	66.05	1.403
3.77	66.09	1.440
3.78	66.13	1.476
3.78	66.17	1.513
3.79	66.21	1.554
3.79	66.25	1.597
3.79	66.28	1.637
3.80	66.32	1.669
3.81	66.36	1.699
3.81	66.40	1.732
3.81	66.44	1.771
3.82	66.47	1.808
3.83	66.51	1.843
3.83	66.55	1.876
3.84	66.59	1.910
3.84	66.63	1.944
3.84	66.67	1.978
3.85	66.70	2.010
3.86	66.74	2.041
3.86	66.78	2.071
3.86	66.82	2.099
3.87	66.86	2.128
3.88	66.90	2.158
3.88	66.94	2.192
3.89	66.98	2.224
3.89	67.02	2.255
3.89	67.06	2.287
3.90	67.10	2.320
3.91	67.14	2.352
3.91	67.17	2.383
3.91	67.21	2.413
3.92	67.25	2.442
3.93	67.29	2.468
3.93	67.33	2.493
3.94	67.37	2.518
3.94	67.41	2.542
3.94	67.45	2.565
3.95	67.49	2.588
3.96	67.53	2.611
3.96	67.58	2.636
3.96	67.62	2.669
3.97	67.66	2.714
3.98	67.70	2.764
3.98	67.74	2.810
3.99	67.78	2.843
3.99	67.82	2.863
3.99	67.85	2.876
4.00	67.90	2.887
4.01	67.94	2.896
4.01	67.98	2.903
4.01	68.02	2.906
4.02	68.06	2.905
4.03	68.11	2.900
4.03	68.15	2.895
4.04	68.20	2.887
4.04	68.24	2.877
4.04	68.29	2.863
4.05	68.34	2.849
4.06	68.39	2.835
4.06	68.44	2.817
4.06	68.49	2.798
4.07	68.54	2.777
4.08	68.59	2.754
4.08	68.64	2.729
4.09	68.69	2.702
4.09	68.74	2.674
4.09	68.80	2.642
4.10	68.85	2.610
4.11	68.91	2.575
4.11	68.96	2.540
4.11	69.02	2.502
4.12	69.08	2.463
4.13	69.13	2.422
4.13	69.19	2.381
4.14	69.25	2.338
4.14	69.31	2.295
4.14	69.37	2.251
4.15	69.43	2.206
4.16	69.49	2.160
4.16	69.55	2.113
4.16	69.61	2.064
4.17	69.67	2.016
4.18	69.74	1.965
4.18	69.80	1.914
4.19	69.86	1.861
4.19	69.93	1.811
4.19	69.99	1.759
4.20	70.06	1.707
4.21	70.12	1.653
4.21	70.19	1.599
4.21	70.25	1.546
4.22	70.32	1.494
4.23	70.38	1.444
4.23	70.45	1.393
4.24	70.51	1.343
4.24	70.58	1.293
4.24	70.64	1.244
4.25	70.71	1.199
4.26	70.78	1.153
4.26	70.84	1.108
4.26	70.91	1.064
4.27	70.97	1.023
4.28	71.04	0.983
4.28	71.10	0.945
4.29	71.17	0.910
4.29	71.23	0.877
4.30	71.30	0.841
4.30	71.36	0.808
4.30	71.42	0.784
4.31	71.49	0.766
4.31	71.55	0.745
4.32	71.61	0.720
4.33	71.67	0.697
4.33	71.73	0.679
4.34	71.79	0.665
4.34	71.85	0.651
4.35	71.91	0.636
4.35	71.97	0.622
4.35	72.03	0.609
4.36	72.09	0.596
4.36	72.15	0.585
4.37	72.20	0.574
4.38	72.26	0.564
4.38	72.32	0.554
4.39	72.37	0.545
4.39	72.43	0.536
4.40	72.48	0.527
4.40	72.54	0.519
4.40	72.60	0.512
4.41	72.65	0.505
4.41	72.71	0.499
4.42	72.76	0.491
4.43	72.81	0.484
4.43	72.87	0.479
4.44	72.92	0.476
4.44	72.98	0.470
4.45	73.03	0.464
4.45	73.08	0.458
4.45	73.14	0.453
4.46	73.19	0.449
4.46	73.24	0.445
4.47	73.30	0.441
4.48	73.35	0.438
4.48	73.40	0.434
4.49	73.45	0.431
4.49	73.51	0.427
4.50	73.56	0.425
4.50	73.61	0.422
4.50	73.66	0.420
4.51	73.71	0.417
4.51	73.77	0.413
4.52	73.82	0.410
4.53	73.87	0.408
4.53	73.92	0.407
4.54	73.97	0.405
4.54	74.02	0.402
4.55	74.07	0.401
4.55	74.13	0.399
4.55	74.18	0.397
4.56	74.23	0.396
4.56	74.28	0.395
4.57	74.33	0.394
4.58	74.38	0.392
4.58	74.43	0.390
4.59	74.48	0.390
4.59	74.53	0.389
4.60	74.58	0.388
4.60	74.64	0.387
4.60	74.69	0.386
4.61	74.74	0.385
4.61	74.79	0.385
4.62	74.84	0.383
4.63	74.89	0.382
4.63	74.94	0.381
4.64	74.99	0.380
4.64	75.04	0.380
4.65	75.09	0.380
4.65	75.14	0.379
4.65	75.19	0.378
4.66	75.24	0.378
4.66	75.29	0.377
4.67	75.34	0.377
4.68	75.39	0.377
4.68	75.44	0.376
4.69	75.49	0.375
4.69	75.54	0.375
4.70	75.60	0.375
4.70	75.65	0.375
4.70	75.70	0.374
4.71	75.75	0.374
4.71	75.80	0.374
4.72	75.85	0.374
4.73	75.90	0.374
4.73	75.95	0.374
4.74	76.00	0.374
4.74	76.05	0.373
4.75	76.10	0.373
4.75	76.15	0.373
4.75	76.20	0.373
4.76	76.25	0.373
4.76	76.30	0.373
4.77	76.35	0.373
4.78	76.40	0.372
4.78	76.45	0.372
4.79	76.50	0.372
4.79	76.55	0.372
4.80	76.60	0.372
4.80	76.65	0.372
4.80	76.70	0.372
4.81	76.75	0.372
4.81	76.80	0.372
4.82	76.85	0.371
4.83	76.90	0.371
4.83	76.95	0.371
4.84	77.00	0.371
4.84	77.05	0.371
4.85	77.10	0.371
4.85	77.15	0.371
4.85	77.20	0.371
4.86	77.25	0.371
4.86	77.30	0.370
4.87	77.35	0.370
4.88	77.40	0.370
4.88	77.45	0.370
4.89	77.50	0.370
4.89	77.55	0.370
4.90	77.60	0.370
4.90	77.65	0.370
4.90	77.70	0.370
4.91	77.75	0.370
4.91	77.80	0.370
4.92	77.85	0.370
4.93	77.90	0.370
4.93	77.95	0.370
4.94	78.00	0.370
4.94	78.05	0.369
4.95	78.10	0.369
4.95	78.16	0.369
4.95	78.20	0.369
4.96	78.26	0.369
4.96	78.30	0.369
4.97	78.36	0.369
4.98	78.41	0.369
4.98	78.46	0.369
4.99	78.51	0.369
4.99	78.56	0.369
5.00	78.61	0.369
5.00	78.66	0.369
5.00	78.71	0.369
5.01	78.76	0.369
5.01	78.81	0.369
5.02	78.86	0.369
5.03	78.91	0.369
5.03	78.96	0.369
5.04	79.01	0.369
5.04	79.06	0.368
5.05	79.11	0.368
5.05	79.16	0.368
5.05	79.21	0.368
5.06	79.26	0.368
5.06	79.31	0.368
5.07	79.36	0.368
5.08	79.41	0.368
5.08	79.46	0.368
5.09	79.51	0.368
5.09	79.56	0.368
5.10	79.61	0.368
5.10	79.66	0.368
5.10	79.71	0.368
5.11	79.76	0.368
5.11	79.81	0.368
5.12	79.86	0.368
5.13	79.91	0.368
5.13	79.96	0.368
5.14	80.01	0.368
5.14	80.06	0.368
5.15	80.11	0.368
5.15	80.16	0.368
5.15	80.21	0.368
5.16	80.26	0.368
5.16	80.31	0.368
5.17	80.36	0.368
5.18	80.41	0.368
5.18	80.46	0.368
5.19	80.51	0.368
5.19	80.56	0.368
5.20	80.61	0.368
5.20	80.66	0.368
5.20	80.71	0.368
5.21	80.76	0.368
5.21	80.81	0.368
5.22	80.86	0.368
5.23	80.91	0.368
5.23	80.96	0.367
5.24	81.01	0.367
5.24	81.06	0.367
5.25	81.11	0.367
5.25	81.16	0.367
5.25	81.21	0.367
5.26	81.26	0.367
5.26	81.31	0.367
5.27	81.36	0.367
5.28	81.41	0.367
5.28	81.46	0.367
5.29	81.51	0.367
5.29	81.56	0.367
5.30	81.61	0.367
5.30	81.66	0.367
5.30	81.71	0.367
5.31	81.76	0.367
5.31	81.81	0.367
5.32	81.86	0.367
5.33	81.91	0.367
5.33	81.96	0.367
5.34	82.01	0.367
5.34	82.06	0.367
5.35	82.11	0.367
5.35	82.16	0.367
5.35	82.21	0.367
5.36	82.26	0.367
5.36	82.31	0.367
5.37	82.36	0.367
5.38	82.41	0.367
5.38	82.46	0.367
5.39	82.51	0.367
5.39	82.56	0.367
5.40	82.61	0.367
5.40	82.66	0.367
5.40	82.71	0.367
5.41	82.76	0.367
5.41	82.81	0.367
5.42	82.86	0.367
5.43	82.91	0.367
5.43	82.96	0.367
5.44	83.01	0.367
5.44	83.06	0.367
5.45	83.11	0.367
5.45	83.16	0.367
5.45	83.21	0.367
5.46	83.26	0.367
5.46	83.31	0.367
5.47	83.36	0.367
5.48	83.41	0.367
5.48	83.46	0.367
5.49	83.51	0.367
5.49	83.56	0.367
5.50	83.61	0.367
5.50	83.66	0.367
5.50	83.71	0.367
5.51	83.76	0.367
5.51	83.81	0.367
5.52	83.86	0.367
5.53	83.91	0.367
5.53	83.96	0.367
5.54	84.01	0.367
5.54	84.06	0.367
5.55	84.11	0.367
5.55	84.16	0.367
5.55	84.21	0.367
5.56	84.26	0.367
5.56	84.31	0.367
5.57	84.36	0.367
5.58	84.41	0.367
5.58	84.46	0.367
5.59	84.51	0.367
5.59	84.56	0.367
5.60	84.61	0.367
5.60	84.66	0.367
5.60	84.71	0.367
5.61	84.76	0.367
5.61	84.81	0.367
5.62	84.86	0.367
5.63	84.91	0.367
5.63	84.96	0.367
5.64	85.01	0.367
5.64	85.06	0.367
5.65	85.11	0.367
5.65	85.16	0.367
5.65	85.21	0.367
5.66	85.26	0.367
5.66	85.31	0.367
5.67	85.36	0.367
5.68	85.41	0.367
5.68	85.46	0.367
5.69	85.51	0.367
5.69	85.56	0.367
5.70	85.61	0.367
5.70	85.66	0.367
5.70	85.71	0.367
5.71	85.76	0.367
5.71	85.81	0.367
5.72	85.86	0.367
5.73	85.91	0.367
5.73	85.96	0.367
5.74	86.01	0.367
5.74	86.06	0.367
5.75	86.11	0.367
5.75	86.16	0.367
5.75	86.21	0.367
5.76	86.26	0.367
5.76	86.31	0.367
5.77	86.36	0.367
5.78	86.41	0.367
5.78	86.46	0.367
5.79	86.51	0.368
5.79	86.56	0.368
5.80	86.61	0.367
5.80	86.66	0.368
5.80	86.71	0.368
5.81	86.76	0.368
5.81	86.81	0.368
5.82	86.86	0.368
5.83	86.91	0.368
5.83	86.96	0.368
5.84	87.01	0.368
5.84	87.06	0.368
5.85	87.11	0.368
5.85	87.16	0.368
5.85	87.21	0.368
5.86	87.26	0.368
5.86	87.31	0.368
5.87	87.36	0.368
5.88	87.41	0.368
5.88	87.46	0.368
5.89	87.51	0.368
5.89	87.56	0.368
5.90	87.61	0.368
5.90	87.66	0.368
5.90	87.71	0.368
5.91	87.76	0.368
5.91	87.81	0.368
5.92	87.86	0.368
5.93	87.91	0.368
5.93	87.96	0.368
5.94	88.01	0.368
5.94	88.06	0.368
5.95	88.11	0.368
5.95	88.16	0.368
5.95	88.21	0.368
5.96	88.26	0.368
5.96	88.31	0.368
5.97	88.36	0.368
5.98	88.41	0.368
5.98	88.46	0.368
5.99	88.51	0.368
5.99	88.56	0.368
6.00	88.61	0.368
6.00	88.66	0.368
6.00	88.71	0.368
6.01	88.76	0.369
6.01	88.81	0.369
6.02	88.86	0.369
6.03	88.91	0.369
6.03	88.96	0.369
6.04	89.01	0.369
6.04	89.06	0.369
6.05	89.11	0.369
6.05	89.16	0.369
6.05	89.21	0.369
6.06	89.26	0.369
6.06	89.31	0.369
6.07	89.36	0.369
6.08	89.41	0.369
6.08	89.46	0.369
6.09	89.51	0.369
6.09	89.56	0.369
6.10	89.61	0.369
6.10	89.66	0.369
6.10	89.71	0.369
6.11	89.76	0.369
6.11	89.81	0.369
6.12	89.86	0.369
6.13	89.91	0.369
6.13	89.96	0.369
6.14	90.01	0.369
6.14	90.06	0.369
6.15	90.11	0.369
6.15	90.16	0.369
6.15	90.21	0.369
6.16	90.26	0.369
6.16	90.31	0.369
6.17	90.36	0.369
6.18	90.41	0.369
6.18	90.46	0.369
6.19	90.51	0.369
6.19	90.56	0.369
6.20	90.61	0.369
6.20	90.66	0.369
6.20	90.71	0.369
6.21	90.76	0.370
6.21	90.81	0.370
6.22	90.86	0.370
6.23	90.91	0.370
6.23	90.96	0.370
6.24	91.01	0.370
6.24	91.06	0.370
6.25	91.11	0.370
6.25	91.16	0.370
6.25	91.21	0.370
6.26	91.26	0.370
6.26	91.31	0.370
6.27	91.36	0.370
6.28	91.41	0.370
6.28	91.46	0.370
6.29	91.51	0.370
6.29	91.56	0.370
6.30	91.61	0.370
6.30	91.66	0.370
6.30	91.71	0.370
6.31	91.76	0.370
6.31	91.81	0.370
6.32	91.86	0.370
6.33	91.91	0.370
6.33	91.96	0.370
6.34	92.01	0.370
6.34	92.06	0.370
6.35	92.11	0.370
6.35	92.16	0.370
6.35	92.21	0.371
6.36	92.26	0.371
6.36	92.31	0.371
6.37	92.36	0.371
6.38	92.41	0.371
6.38	92.46	0.371
6.39	92.51	0.371
6.39	92.56	0.371
6.40	92.61	0.371
6.40	92.66	0.371
6.40	92.71	0.371
6.41	92.76	0.371
6.41	92.81	0.371
6.42	92.86	0.371
6.43	92.91	0.371
6.43	92.96	0.371
6.44	93.02	0.371
6.44	93.06	0.371
6.45	93.11	0.371
6.45	93.16	0.371
6.45	93.22	0.371
6.46	93.27	0.371
6.46	93.31	0.371
6.47	93.37	0.371
6.48	93.42	0.371
6.48	93.47	0.371
6.49	93.51	0.371
6.49	93.57	0.371
6.50	93.61	0.371
6.50	93.67	0.372
6.50	93.72	0.372
6.51	93.77	0.372
6.51	93.82	0.372
6.52	93.87	0.372
6.53	93.92	0.372
6.53	93.97	0.372
6.54	94.02	0.372
6.54	94.07	0.372
6.55	94.12	0.372
6.55	94.17	0.372
6.55	94.22	0.372
6.56	94.27	0.372
6.56	94.31	0.372
6.57	94.37	0.372
6.58	94.42	0.372
6.58	94.47	0.372
6.59	94.52	0.372
6.59	94.57	0.372
6.60	94.62	0.372
6.60	94.67	0.372
6.60	94.72	0.372
6.61	94.77	0.372
6.61	94.82	0.372
6.62	94.87	0.372
6.63	94.92	0.372
6.63	94.97	0.372
6.64	95.02	0.372
6.64	95.07	0.372
6.65	95.12	0.373
6.65	95.17	0.373
6.65	95.22	0.373
6.66	95.27	0.373
6.66	95.32	0.373
6.67	95.37	0.373
6.68	95.42	0.373
6.68	95.47	0.373
6.69	95.52	0.373
6.69	95.57	0.373
6.70	95.62	0.373
6.70	95.67	0.373
6.70	95.72	0.373
6.71	95.77	0.373
6.71	95.82	0.373
6.72	95.87	0.373
6.73	95.92	0.373
6.73	95.97	0.373
6.74	96.02	0.373
6.74	96.07	0.373
6.75	96.12	0.373
6.75	96.17	0.373
6.75	96.22	0.373
6.76	96.27	0.373
6.76	96.32	0.373
6.77	96.37	0.373
6.78	96.42	0.373
6.78	96.47	0.373
6.79	96.52	0.373
6.79	96.57	0.373
6.80	96.62	0.374
6.80	96.67	0.374
6.80	96.72	0.374
6.81	96.77	0.374
6.81	96.82	0.374
6.82	96.87	0.374
6.83	96.92	0.374
6.83	96.97	0.374
6.84	97.02	0.374
6.84	97.07	0.374
6.85	97.12	0.374
6.85	97.17	0.374
6.85	97.22	0.374
6.86	97.27	0.374
6.86	97.32	0.374
6.87	97.37	0.374
6.88	97.42	0.374
6.88	97.47	0.374
6.89	97.52	0.374
6.89	97.57	0.374
6.90	97.62	0.374
6.90	97.67	0.374
6.90	97.72	0.374
6.91	97.77	0.374
6.91	97.82	0.374
6.92	97.87	0.374
6.93	97.92	0.374
6.93	97.97	0.374
6.94	98.02	0.374
6.94	98.07	0.374
6.95	98.12
6.95	98.17
6.95	98.22
6.96	98.27
6.96	98.32
6.97	98.37
6.98	98.42
6.98	98.47
6.99	98.52
6.99	98.57
7.00
7.00

[step]
Ramp 10.00 °C/min to -50.00 °C
Time	Temperature	Heat Flow (Normalized)
min	°C	W/g
8.00	100.11	-0.018
8.01	100.11	-0.018
8.02	100.10	-0.019
8.03	100.10	-0.019
8.04	100.10	-0.019
8.05	100.09	-0.020
8.06	100.08	-0.024
8.07	100.07	-0.033
8.08	100.04	-0.046
8.09	100.01	-0.059
8.10	99.98	-0.076
8.11	99.93	-0.094
8.12	99.89	-0.115
8.13	99.83	-0.135
8.14	99.77	-0.158
8.15	99.70	-0.180
8.16	99.64	-0.200
8.17	99.57	-0.218
8.18	99.49	-0.236
8.19	99.42	-0.252
8.20	99.34	-0.266
8.21	99.26	-0.278
8.22	99.17	-0.290
8.23	99.09	-0.300
8.24	99.01	-0.309
8.25	98.92	-0.318
8.26	98.83	-0.327
8.27	98.75	-0.335
8.28	98.66	-0.341
8.29	98.57	-0.347
8.30	98.47	-0.354
8.31	98.38	-0.357
8.32	98.29	-0.364
8.33	98.20	-0.367
8.34	98.10	-0.372
8.35	98.01	-0.377
8.36	97.91	-0.379
8.37	97.82	-0.381
8.38	97.72	-0.385
8.39	97.63	-0.387
8.40	97.53	-0.388
8.41	97.43	-0.392
8.42	97.34	-0.393
8.43	97.24	-0.394
8.44	97.14	-0.396
8.45	97.05	-0.398
8.46	96.95	-0.399
8.47	96.85	-0.400
8.48	96.75	-0.401
8.49	96.66	-0.402
8.50	96.56	-0.403
8.51	96.46	-0.403
8.52	96.36	-0.404
8.53	96.26	-0.405
8.54	96.17	-0.405
8.55	96.07	-0.406
8.56	95.97	-0.406
8.57	95.87	-0.407
8.58	95.77	-0.408
8.59	95.67	-0.408
8.60	95.58	-0.408
8.61	95.48	-0.409
8.62	95.38	-0.409
8.63	95.28	-0.409
8.64	95.18	-0.409
8.65	95.08	-0.409
8.66	94.98	-0.410
8.67	94.88	-0.410
8.68	94.78	-0.410
8.69	94.69	-0.411
8.70	94.59	-0.411
8.71	94.49	-0.411
8.72	94.39	-0.411
8.73	94.29	-0.411
8.74	94.19	-0.412
8.75	94.09	-0.412
8.76	93.99	-0.412
8.77	93.89	-0.412
8.78	93.79	-0.412
8.79	93.69	-0.412
8.80	93.59	-0.412
8.81	93.49	-0.413
8.82	93.40	-0.413
8.83	93.30	-0.413
8.84	93.20	-0.413
8.85	93.10	-0.413
8.86	93.00	-0.413
8.87	92.90	-0.413
8.88	92.80	-0.413
8.89	92.70	-0.414
8.90	92.60	-0.414
8.91	92.50	-0.414
8.92	92.40	-0.414
8.93	92.30	-0.414
8.94	92.20	-0.414
8.95	92.10	-0.414
8.96	92.00	-0.414
8.97	91.90	-0.414
8.98	91.81	-0.415
8.99	91.70	-0.415
9.00	91.60	-0.415
9.01	91.51	-0.415
9.02	91.41	-0.415
9.03	91.31	-0.415
9.04	91.21	-0.415
9.05	91.11	-0.415
9.06	91.01	-0.415
9.07	90.91	-0.415
9.08	90.81	-0.415
9.09	90.71	-0.415
9.10	90.61	-0.415
9.11	90.51	-0.415
9.12	90.41	-0.415
9.13	90.31	-0.415
9.14	90.21	-0.416
9.15	90.11	-0.416
9.16	90.01	-0.416
9.17	89.91	-0.416
9.18	89.81	-0.416
9.19	89.71	-0.416
9.20	89.61	-0.416
9.21	89.51	-0.416
9.22	89.41	-0.416
9.23	89.31	-0.416
9.24	89.21	-0.416
9.25	89.11	-0.416
9.26	89.01	-0.416
9.27	88.91	-0.416
9.28	88.81	-0.416
9.29	88.71	-0.416
9.30	88.61	-0.416
9.31	88.52	-0.416
9.32	88.42	-0.416
9.33	88.31	-0.416
9.34	88.21	-0.416
9.35	88.12	-0.416
9.36	88.02	-0.416
9.37	87.92	-0.416
9.38	87.82	-0.416
9.39	87.72	-0.416
9.40	87.62	-0.416
9.41	87.52	-0.416
9.42	87.42	-0.416
9.43	87.32	-0.416
9.44	87.22	-0.416
9.45	87.12	-0.416
9.46	87.02	-0.416
9.47	86.92	-0.416
9.48	86.82	-0.416
9.49	86.72	-0.416
9.50	86.62	-0.416
9.51	86.52	-0.416
9.52	86.42	-0.416
9.53	86.32	-0.416
9.54	86.22	-0.416
9.55	86.12	-0.416
9.56	86.02	-0.416
9.57	85.92	-0.416
9.58	85.82	-0.416
9.59	85.72	-0.416
9.60	85.62	-0.416
9.61	85.52	-0.416
9.62	85.42	-0.416
9.63	85.32	-0.416
9.64	85.22	-0.416
9.65	85.12	-0.416
9.66	85.02	-0.416
9.67	84.92	-0.416
9.68	84.82	-0.415
9.69	84.72	-0.415
9.70	84.62	-0.415
9.71	84.52	-0.415
9.72	84.42	-0.415
9.73	84.32	-0.416
9.74	84.22	-0.415
9.75	84.12	-0.415
9.76	84.02	-0.415
9.77	83.92	-0.415
9.78	83.82	-0.415
9.79	83.72	-0.415
9.80	83.62	-0.415
9.81	83.52	-0.415
9.82	83.42	-0.415
9.83	83.32	-0.416
9.84	83.22	-0.415
9.85	83.12	-0.415
9.86	83.02	-0.416
9.87	82.92	-0.416
9.88	82.82	-0.416
9.89	82.72	-0.416
9.90	82.62	-0.416
9.91	82.52	-0.416
9.92	82.42	-0.416
9.93	82.32	-0.416
9.94	82.22	-0.416
9.95	82.12	-0.416
9.96	82.02	-0.416
9.97	81.93	-0.416
9.98	81.83	-0.416
9.99	81.72	-0.416
10.00	81.62	-0.416
10.01	81.52	-0.416
10.02	81.43	-0.416
10.03	81.33	-0.416
10.04	81.23	-0.416
10.05	81.13	-0.415
10.06	81.03	-0.415
10.07	80.93	-0.416
10.08	80.83	-0.416
10.09	80.73	-0.416
10.10	80.63	-0.416
10.11	80.53	-0.416
10.12	80.43	-0.416
10.13	80.33	-0.416
10.14	80.23	-0.416
10.15	80.13	-0.416
10.16	80.03	-0.416
10.17	79.93	-0.416
10.18	79.83	-0.416
10.19	79.73	-0.416
10.20	79.63	-0.416
10.21	79.53	-0.416
10.22	79.43	-0.416
10.23	79.33	-0.416
10.24	79.23	-0.416
10.25	79.13	-0.416
10.26	79.03	-0.416
10.27	78.93	-0.416
10.28	78.83	-0.416
10.29	78.73	-0.416
10.30	78.63	-0.416
10.31	78.53	-0.416
10.32	78.43	-0.416
10.33	78.33	-0.416
10.34	78.23	-0.416
10.35	78.13	-0.416
10.36	78.03	-0.416
10.37	77.93	-0.416
10.38	77.83	-0.416
10.39	77.73	-0.416
10.40	77.63	-0.415
10.41	77.53	-0.415
10.42	77.43	-0.415
10.43	77.33	-0.415
10.44	77.23	-0.415
10.45	77.13	-0.415
10.46	77.03	-0.415
10.47	76.93	-0.415
10.48	76.83	-0.415
10.49	76.73	-0.415
10.50	76.63	-0.415
10.51	76.53	-0.415
10.52	76.43	-0.415
10.53	76.33	-0.415
10.54	76.23	-0.415
10.55	76.13	-0.415
10.56	76.03	-0.415
10.57	75.93	-0.415
10.58	75.83	-0.415
10.59	75.73	-0.415
10.60	75.63	-0.415
10.61	75.53	-0.415
10.62	75.43	-0.415
10.63	75.33	-0.415
10.64	75.23	-0.415
10.65	75.13	-0.415
10.66	75.03	-0.415
10.67	74.93	-0.415
10.68	74.83	-0.415
10.69	74.73	-0.415
10.70	74.63	-0.415
10.71	74.53	-0.415
10.72	74.43	-0.415
10.73	74.33	-0.415
10.74	74.23	-0.414
10.75	74.13	-0.414
10.76	74.03	-0.414
10.77	73.93	-0.414
10.78	73.83	-0.414
10.79	73.73	-0.414
10.80	73.63	-0.414
10.81	73.53	-0.414
10.82	73.43	-0.414
10.83	73.33	-0.414
10.84	73.23	-0.414
10.85	73.13	-0.414
10.86	73.03	-0.414
10.87	72.93	-0.414
10.88	72.83	-0.414
10.89	72.73	-0.414
10.90	72.63	-0.414
10.91	72.53	-0.414
10.92	72.43	-0.414
10.93	72.33	-0.414
10.94	72.23	-0.414
10.95	72.13	-0.413
10.96	72.03	-0.413
10.97	71.93	-0.413
10.98	71.83	-0.413
10.99	71.73	-0.413
11.00	71.63	-0.413
11.01	71.53	-0.413
11.02	71.43	-0.413
11.03	71.33	-0.413
11.04	71.23	-0.413
11.05	71.13	-0.413
11.06	71.03	-0.413
11.07	70.93	-0.413
11.08	70.83	-0.413
11.09	70.73	-0.413
11.10	70.63	-0.413
11.11	70.53	-0.413
11.12	70.43	-0.413
11.13	70.33	-0.413
11.14	70.23	-0.413
11.15	70.13	-0.413
11.16	70.03	-0.413
11.17	69.93	-0.413
11.18	69.83	-0.412
11.19	69.73	-0.412
11.20	69.63	-0.412
11.21	69.53	-0.412
11.22	69.43	-0.412
11.23	69.34	-0.412
11.24	69.23	-0.412
11.25	69.14	-0.412
11.26	69.04	-0.412
11.27	68.93	-0.412
11.28	68.84	-0.412
11.29	68.73	-0.412
11.30	68.63	-0.412
11.31	68.54	-0.412
11.32	68.44	-0.412
11.33	68.33	-0.412
11.34	68.24	-0.412
11.35	68.14	-0.411
11.36	68.04	-0.411
11.37	67.94	-0.411
11.38	67.84	-0.411
11.39	67.74	-0.411
11.40	67.64	-0.411
11.41	67.54	-0.411
11.42	67.44	-0.411
11.43	67.34	-0.411
11.44	67.24	-0.411
11.45	67.14	-0.411
11.46	67.04	-0.411
11.47	66.94	-0.411
11.48	66.84	-0.411
11.49	66.74	-0.411
11.50	66.64	-0.411
11.51	66.54	-0.411
11.52	66.44	-0.411
11.53	66.34	-0.410
11.54	66.24	-0.410
11.55	66.14	-0.410
11.56	66.04	-0.410
11.57	65.94	-0.410
11.58	65.84	-0.410
11.59	65.74	-0.410
11.60	65.64	-0.410
11.61	65.54	-0.410
11.62	65.44	-0.410
11.63	65.34	-0.410
11.64	65.24	-0.410
11.65	65.14	-0.410
11.66	65.04	-0.409
11.67	64.94	-0.409
11.68	64.84	-0.409
11.69	64.74	-0.409
11.70	64.64	-0.409
11.71	64.54	-0.409
11.72	64.44	-0.409
11.73	64.34	-0.409
11.74	64.24	-0.409
11.75	64.14	-0.409
11.76	64.04	-0.409
11.77	63.94	-0.409
11.78	63.84	-0.409
11.79	63.74	-0.409
11.80	63.64	-0.408
11.81	63.54	-0.408
11.82	63.44	-0.408
11.83	63.34	-0.408
11.84	63.24	-0.408
11.85	63.14	-0.408
11.86	63.04	-0.408
11.87	62.94	-0.408
11.88	62.84	-0.408
11.89	62.74	-0.408
11.90	62.64	-0.408
11.91	62.54	-0.408
11.92	62.44	-0.408
11.93	62.34	-0.408
11.94	62.24	-0.408
11.95	62.14	-0.408
11.96	62.04	-0.408
11.97	61.94	-0.407
11.98	61.84	-0.407
11.99	61.74	-0.407
12.00	61.64	-0.407
12.01	61.54	-0.407
12.02	61.44	-0.407
12.03	61.34	-0.407
12.04	61.24	-0.407
12.05	61.14	-0.407
12.06	61.04	-0.407
12.07	60.94	-0.407
12.08	60.84	-0.406
12.09	60.74	-0.406
12.10	60.64	-0.406
12.11	60.54	-0.406
12.12	60.44	-0.406
12.13	60.34	-0.406
12.14	60.24	-0.406
12.15	60.14	-0.406
12.16	60.04	-0.406
12.17	59.94	-0.406
12.18	59.84	-0.405
12.19	59.74	-0.405
12.20	59.64	-0.405
12.21	59.54	-0.405
12.22	59.44	-0.405
12.23	59.34	-0.405
12.24	59.24	-0.405
12.25	59.14	-0.405
12.26	59.04	-0.405
12.27	58.94	-0.405
12.28	58.84	-0.405
12.29	58.74	-0.405
12.30	58.64	-0.404
12.31	58.54	-0.404
12.32	58.44	-0.404
12.33	58.34	-0.404
12.34	58.24	-0.404
12.35	58.14	-0.404
12.36	58.04	-0.404
12.37	57.94	-0.404
12.38	57.84	-0.404
12.39	57.74	-0.404
12.40	57.64	-0.404
12.41	57.54	-0.404
12.42	57.44	-0.404
12.43	57.34	-0.404
12.44	57.24	-0.404
12.45	57.14	-0.404
12.46	57.04	-0.404
12.47	56.94	-0.404
12.48	56.84	-0.403
12.49	56.74	-0.403
12.50	56.64	-0.403
12.51	56.54	-0.403
12.52	56.44	-0.403
12.53	56.34	-0.403
12.54	56.24	-0.403
12.55	56.14	-0.403
12.56	56.04	-0.403
12.57	55.94	-0.403
12.58	55.84	-0.403
12.59	55.74	-0.402
12.60	55.64	-0.402
12.61	55.54	-0.402
12.62	55.44	-0.402
12.63	55.34	-0.402
12.64	55.24	-0.402
12.65	55.14	-0.402
12.66	55.04	-0.402
12.67	54.94	-0.402
12.68	54.84	-0.402
12.69	54.74	-0.402
12.70	54.64	-0.402
12.71	54.54	-0.401
12.72	54.44	-0.401
12.73	54.34	-0.401
12.74	54.24	-0.401
12.75	54.14	-0.401
12.76	54.04	-0.401
12.77	53.94	-0.401
12.78	53.85	-0.401
12.79	53.74	-0.401
12.80	53.64	-0.401
12.81	53.54	-0.401
12.82	53.44	-0.401
12.83	53.34	-0.401
12.84	53.24	-0.401
12.85	53.14	-0.401
12.86	53.04	-0.400
12.87	52.94	-0.400
12.88	52.84	-0.400
12.89	52.75	-0.400
12.90	52.64	-0.400
12.91	52.55	-0.400
12.92	52.44	-0.400
12.93	52.34	-0.400
12.94	52.24	-0.400
12.95	52.14	-0.400
12.96	52.04	-0.400
12.97	51.94	-0.400
12.98	51.84	-0.400
12.99	51.74	-0.400
13.00	51.65	-0.400
13.01	51.54	-0.400
13.02	51.44	-0.400
13.03	51.34	-0.400
13.04	51.25	-0.400
13.05	51.14	-0.400
13.06	51.04	-0.399
13.07	50.94	-0.399
13.08	50.84	-0.399
13.09	50.74	-0.399
13.10	50.64	-0.399
13.11	50.54	-0.399
13.12	50.44	-0.399
13.13	50.34	-0.399
13.14	50.24	-0.399
13.15	50.15	-0.399
13.16	50.05	-0.398
13.17	49.95	-0.398
13.18	49.85	-0.398
13.19	49.75	-0.398
13.20	49.65	-0.398
13.21	49.55	-0.398
13.22	49.45	-0.398
13.23	49.34	-0.398
13.24	49.24	-0.398
13.25	49.15	-0.397
13.26	49.05	-0.397
13.27	48.95	-0.397
13.28	48.85	-0.397
13.29	48.75	-0.397
13.30	48.65	-0.397
[...]
27.84	-13.22	0.310
27.85	-13.12	0.312
27.86	-13.02	0.314
27.87	-12.93	0.316
27.88	-12.83	0.318
27.89	-12.73	0.320
27.90	-12.63	0.321
27.91	-12.53	0.324
27.92	-12.43	0.325
27.93	-12.33	0.328
27.94	-12.23	0.329
27.95	-12.13	0.332
27.96	-12.03	0.333
27.97	-11.93	0.335
27.98	-11.83	0.336
27.99	-11.73	0.338
28.00	-11.63	0.338
28.01	-11.53	0.340
28.02	-11.44	0.341
28.03	-11.33	0.341
28.04	-11.24	0.342
28.05	-11.14	0.342
28.06	-11.04	0.343
28.07	-10.94	0.343
28.08	-10.84	0.343
28.09	-10.74	0.344
28.10	-10.64	0.344
28.11	-10.54	0.344
28.12	-10.44	0.344
28.13	-10.34	0.344
28.14	-10.24	0.344
28.15	-10.13	0.344
28.16	-10.03	0.344
28.17	-9.93	0.344
28.18	-9.83	0.343
28.19	-9.73	0.343
28.20	-9.63	0.342
28.21	-9.53	0.341
28.22	-9.43	0.340
28.23	-9.33	0.339
28.24	-9.23	0.337
28.25	-9.13	0.336
28.26	-9.02	0.334
28.27	-8.92	0.334
28.28	-8.82	0.332
28.29	-8.72	0.331
28.30	-8.62	0.330
28.31	-8.52	0.329
28.32	-8.42	0.328
28.33	-8.32	0.327
28.34	-8.22	0.327
28.35	-8.12	0.326
28.36	-8.02	0.326
28.37	-7.92	0.325
28.38	-7.82	0.324
28.39	-7.72	0.324
28.40	-7.62	0.324
28.41	-7.52	0.324
28.42	-7.42	0.323
28.43	-7.32	0.323
28.44	-7.22	0.323
28.45	-7.12	0.323
28.46	-7.02	0.322
28.47	-6.92	0.322
28.48	-6.82	0.322
28.49	-6.72	0.322
28.50	-6.62	0.322
28.51	-6.52	0.321
28.52	-6.42	0.321
28.53	-6.32	0.321
28.54	-6.22	0.321
28.55	-6.12	0.321
28.56	-6.02	0.320
28.57	-5.92	0.320
28.58	-5.82	0.320
28.59	-5.72	0.320
28.60	-5.62	0.320
28.61	-5.52	0.320
28.62	-5.42	0.319
28.63	-5.32	0.319
28.64	-5.22	0.319
28.65	-5.12	0.319
28.66	-5.01	0.319
28.67	-4.92	0.319
28.68	-4.82	0.319
28.69	-4.72	0.319
28.70	-4.62	0.318
28.71	-4.52	0.318
28.72	-4.41	0.318
28.73	-4.32	0.318
28.74	-4.21	0.318
28.75	-4.12	0.318
28.76	-4.02	0.318
28.77	-3.92	0.318
28.78	-3.81	0.318
28.79	-3.72	0.318
28.80	-3.62	0.318
28.81	-3.51	0.318
28.82	-3.41	0.318
28.83	-3.31	0.317
28.84	-3.21	0.317
28.85	-3.12	0.317
28.86	-3.01	0.317
28.87	-2.91	0.317
28.88	-2.82	0.317
28.89	-2.71	0.317
28.90	-2.62	0.317
28.91	-2.51	0.317
28.92	-2.41	0.317
28.93	-2.31	0.317
28.94	-2.22	0.317
28.95	-2.11	0.317
28.96	-2.01	0.317
28.97	-1.91	0.317
28.98	-1.81	0.317
28.99	-1.71	0.317
29.00	-1.61	0.317
29.01	-1.51	0.317
29.02	-1.41	0.317
29.03	-1.31	0.317
29.04	-1.21	0.317
29.05	-1.11	0.317
29.06	-1.01	0.317
29.07	-0.91	0.317
29.08	-0.81	0.317
29.09	-0.71	0.317
29.10	-0.61	0.317
29.11	-0.51	0.317
29.12	-0.41	0.317
29.13	-0.31	0.317
29.14	-0.21	0.317
29.15	-0.11	0.317
29.16	-0.01	0.317
29.17	0.09	0.317
29.18	0.19	0.317
29.19	0.29	0.317
29.20	0.39	0.317
29.21	0.49	0.317
29.22	0.59	0.317
29.23	0.69	0.317
29.24	0.79	0.317
29.25	0.89	0.317
29.26	0.99	0.317
29.27	1.09	0.317
29.28	1.19	0.317
29.29	1.29	0.317
29.30	1.39	0.317
29.31	1.49	0.317
29.32	1.59	0.317
29.33	1.69	0.317
29.34	1.79	0.317
29.35	1.89	0.318
29.36	1.99	0.318
29.37	2.09	0.318
29.38	2.19	0.318
29.39	2.29	0.318
29.40	2.39	0.318
29.41	2.49	0.318
29.42	2.59	0.318
29.43	2.69	0.318
29.44	2.79	0.318
29.45	2.89	0.318
29.46	2.99	0.318
29.47	3.09	0.318
29.48	3.19	0.318
29.49	3.29	0.318
29.50	3.39	0.318
29.51	3.49	0.318
29.52	3.59	0.318
29.53	3.69	0.318
29.54	3.79	0.318
29.55	3.89	0.318
29.56	3.99	0.318
29.57	4.09	0.318
29.58	4.19	0.318
29.59	4.29	0.319
29.60	4.39	0.319
29.61	4.49	0.319
29.62	4.59	0.319
29.63	4.69	0.319
29.64	4.79	0.319
29.65	4.89	0.319
29.66	4.99	0.319
29.67	5.09	0.319
29.68	5.19	0.319
29.69	5.29	0.319
29.70	5.40	0.319
29.71	5.49	0.319
29.72	5.60	0.319
29.73	5.69	0.319
29.74	5.79	0.319
29.75	5.90	0.319
29.76	5.99	0.319
29.77	6.10	0.319
29.78	6.20	0.319
29.79	6.30	0.320
29.80	6.40	0.320
29.81	6.50	0.320
29.82	6.60	0.320
29.83	6.70	0.320
29.84	6.80	0.320
29.85	6.90	0.320
29.86	7.00	0.320
29.87	7.10	0.320
29.88	7.20	0.320
29.89	7.30	0.320
29.90	7.40	0.320
29.91	7.50	0.320
29.92	7.60	0.320
29.93	7.70	0.320
29.94	7.80	0.320
29.95	7.90	0.320
29.96	8.00	0.320
29.97	8.10	0.320
29.98	8.20	0.321
29.99	8.30	0.321
30.00	8.40	0.321
30.01	8.50	0.321
30.02	8.60	0.321
30.03	8.70	0.321
30.04	8.80	0.321
30.05	8.90	0.321
30.06	9.00	0.321
30.07	9.10	0.321
30.08	9.20	0.321
30.09	9.30	0.321
30.10	9.40	0.321
30.11	9.50	0.321
30.12	9.60	0.321
30.13	9.70	0.321
30.14	9.80	0.321
30.15	9.90	0.321
30.16	10.00	0.322
30.17	10.10	0.322
30.18	10.20	0.322
30.19	10.30	0.322
30.20	10.40	0.322
30.21	10.50	0.322
30.22	10.60	0.322
30.23	10.70	0.322
30.24	10.80	0.322
30.25	10.90	0.322
30.26	11.00	0.322
30.27	11.10	0.322
30.28	11.20	0.322
30.29	11.30	0.322
30.30	11.40	0.322
30.31	11.50	0.322
30.32	11.60	0.322
30.33	11.70	0.322
30.34	11.80	0.323
30.35	11.90	0.323
30.36	12.00	0.323
30.37	12.10	0.323
30.38	12.20	0.323
30.39	12.30	0.323
30.40	12.40	0.323
30.41	12.50	0.323
30.42	12.60	0.323
30.43	12.70	0.323
30.44	12.80	0.323
30.45	12.90	0.323
30.46	13.00	0.323
30.47	13.10	0.323
30.48	13.20	0.323
30.49	13.30	0.323
30.50	13.40	0.324
30.51	13.50	0.323
30.52	13.60	0.324
30.53	13.70	0.324
30.54	13.80	0.324
30.55	13.90	0.324
30.56	14.00	0.324
30.57	14.11	0.324
30.58	14.20	0.324
30.59	14.31	0.324
30.60	14.40	0.324
30.61	14.51	0.324
30.62	14.61	0.324
30.63	14.71	0.324
30.64	14.81	0.324
30.65	14.90	0.324
30.66	15.01	0.324
30.67	15.11	0.324
30.68	15.21	0.325
30.69	15.31	0.325
30.70	15.41	0.325
30.71	15.51	0.325
30.72	15.61	0.325
30.73	15.71	0.325
30.74	15.81	0.325
30.75	15.91	0.325
30.76	16.01	0.325
30.77	16.11	0.325
30.78	16.21	0.325
30.79	16.31	0.325
30.80	16.41	0.325
30.81	16.51	0.325
30.82	16.61	0.325
30.83	16.71	0.325
30.84	16.81	0.325
30.85	16.91	0.325
30.86	17.01	0.326
30.87	17.11	0.326
30.88	17.21	0.326
30.89	17.31	0.326
30.90	17.41	0.326
30.91	17.51	0.326
30.92	17.61	0.326
30.93	17.71	0.326
30.94	17.81	0.326
30.95	17.91	0.326
30.96	18.01	0.326
30.97	18.11	0.326
30.98	18.21	0.326
30.99	18.31	0.326
31.00	18.41	0.326
31.01	18.51	0.327
31.02	18.61	0.327
31.03	18.71	0.327
31.04	18.81	0.327
31.05	18.91	0.327
31.06	19.01	0.327
31.07	19.11	0.327
31.08	19.21	0.327
31.09	19.31	0.327
31.10	19.41	0.327
31.11	19.51	0.327
31.12	19.61	0.327
31.13	19.71	0.327
31.14	19.81	0.327
31.15	19.91	0.327
31.16	20.01	0.327
31.17	20.11	0.327
31.18	20.21	0.327
31.19	20.31	0.328
31.20	20.41	0.328
31.21	20.51	0.328
31.22	20.61	0.328
31.23	20.71	0.328
31.24	20.81	0.328
31.25	20.91	0.328
31.26	21.01	0.328
31.27	21.11	0.328
31.28	21.21	0.328
31.29	21.31	0.328
31.30	21.41	0.328
31.31	21.51	0.328
31.32	21.61	0.328
31.33	21.71	0.328
31.34	21.81	0.329
31.35	21.91	0.329
31.36	22.01	0.329
31.37	22.11	0.329
31.38	22.21	0.329
31.39	22.31	0.329
31.40	22.41	0.329
31.41	22.51	0.329
31.42	22.61	0.329
31.43	22.71	0.329
31.44	22.81	0.329
31.45	22.91	0.329
31.46	23.01	0.329
31.47	23.11	0.329
31.48	23.21	0.329
31.49	23.31	0.329
31.50	23.41	0.330
31.51	23.51	0.330
31.52	23.61	0.330
31.53	23.71	0.330
31.54	23.81	0.330
31.55	23.91	0.330
31.56	24.01	0.330
31.57	24.11	0.330
31.58	24.21	0.330
31.59	24.31	0.330
31.60	24.41	0.330
31.61	24.52	0.330
31.62	24.61	0.330
31.63	24.72	0.330
31.64	24.82	0.330
31.65	24.92	0.330
31.66	25.01	0.331
31.67	25.11	0.331
31.68	25.22	0.331
31.69	25.32	0.331
31.70	25.42	0.331
31.71	25.52	0.331
31.72	25.62	0.331
31.73	25.72	0.331
31.74	25.82	0.331
31.75	25.92	0.331
31.76	26.02	0.331
31.77	26.12	0.331
31.78	26.22	0.331
31.79	26.32	0.331
31.80	26.42	0.331
31.81	26.52	0.332
31.82	26.62	0.332
31.83	26.72	0.332
31.84	26.82	0.332
31.85	26.92	0.332
31.86	27.02	0.332
31.87	27.12	0.332
31.88	27.22	0.332
31.89	27.32	0.332
31.90	27.42	0.332
31.91	27.52	0.332
31.92	27.62	0.332
31.93	27.72	0.332
31.94	27.82	0.332
31.95	27.92	0.332
31.96	28.02	0.332
31.97	28.12	0.332
31.98	28.22	0.333
31.99	28.32	0.333
32.00	28.42	0.333
32.01	28.52	0.333
32.02	28.62	0.333
32.03	28.72	0.333
32.04	28.82	0.333
32.05	28.92	0.333
32.06	29.02	0.333
32.07	29.12	0.333
32.08	29.22	0.333
32.09	29.32	0.333
32.10	29.42	0.333
32.11	29.52	0.333
32.12	29.62	0.333
32.13	29.72	0.333
32.14	29.82	0.334
32.15	29.92	0.334
32.16	30.02	0.334
32.17	30.12	0.334
32.18	30.22	0.334
32.19	30.32	0.334
32.20	30.42	0.334
32.21	30.52	0.334
32.22	30.62	0.334
32.23	30.72	0.334
32.24	30.82	0.334
32.25	30.92	0.334
32.26	31.02	0.334
32.27	31.12	0.334
32.28	31.22	0.334
32.29	31.32	0.334
32.30	31.42	0.334
32.31	31.52	0.335
32.32	31.62	0.335
32.33	31.72	0.335
32.34	31.82	0.335
32.35	31.92	0.335
32.36	32.02	0.335
32.37	32.12	0.335
32.38	32.22	0.335
32.39	32.32	0.335
32.40	32.42	0.335
32.41	32.52	0.335
32.42	32.62	0.335
32.43	32.72	0.335
32.44	32.82	0.335
32.45	32.92	0.335
32.46	33.02	0.335
32.47	33.12	0.335
32.48	33.22	0.336
32.49	33.32	0.336
32.50	33.42	0.336
32.51	33.52	0.336
32.52	33.62	0.336
32.53	33.73	0.336
32.54	33.82	0.336
32.55	33.93	0.336
32.56	34.02	0.336
32.57	34.13	0.336
32.58	34.23	0.336
32.59	34.32	0.336
32.60	34.42	0.336
32.61	34.52	0.336
32.62	34.62	0.336
32.63	34.73	0.336
32.64	34.83	0.336
32.65	34.93	0.336
32.66	35.03	0.336
32.67	35.13	0.337
32.68	35.23	0.337
32.69	35.33	0.337
32.70	35.43	0.337
32.71	35.53	0.337
32.72	35.63	0.337
32.73	35.73	0.337
32.74	35.83	0.337
32.75	35.93	0.337
32.76	36.03	0.337
32.77	36.13	0.337
32.78	36.23	0.337
32.79	36.33	0.337
32.80	36.43	0.337
32.81	36.53	0.337
32.82	36.63	0.337
32.83	36.73	0.337
32.84	36.83	0.337
32.85	36.93	0.337
32.86	37.03	0.338
32.87	37.13	0.338
32.88	37.23	0.338
32.89	37.33	0.338
32.90	37.43	0.338
32.91	37.53	0.338
32.92	37.63	0.338
32.93	37.73	0.338
32.94	37.83	0.338
32.95	37.93	0.338
32.96	38.03	0.338
32.97	38.13	0.338
32.98	38.23	0.338
32.99	38.33	0.338
33.00	38.43	0.338
33.01	38.53	0.338
33.02	38.63	0.338
33.03	38.73	0.338
33.04	38.83	0.338
33.05	38.93	0.339
33.06	39.03	0.339
33.07	39.13	0.339
33.08	39.23	0.339
33.09	39.33	0.339
33.10	39.43	0.339
33.11	39.53	0.339
33.12	39.63	0.339
33.13	39.73	0.339
33.14	39.83	0.339
33.15	39.93	0.339
33.16	40.03	0.339
33.17	40.13	0.339
33.18	40.23	0.339
33.19	40.33	0.339
33.20	40.43	0.339
33.21	40.53	0.339
33.22	40.63	0.339
33.23	40.73	0.339
33.24	40.83	0.340
33.25	40.93	0.340
33.26	41.03	0.340
33.27	41.13	0.340
33.28	41.23	0.340
33.29	41.33	0.340
33.30	41.43	0.340
33.31	41.53	0.340
33.32	41.63	0.340
33.33	41.73	0.340
33.34	41.83	0.340
33.35	41.93	0.340
33.36	42.03	0.340
33.37	42.13	0.340
33.38	42.23	0.340
33.39	42.33	0.340
33.40	42.43	0.340
33.41	42.53	0.340
33.42	42.63	0.341
33.43	42.73	0.341
33.44	42.83	0.341
33.45	42.93	0.341
33.46	43.03	0.341
33.47	43.13	0.341
33.48	43.23	0.341
33.49	43.33	0.341
33.50	43.43	0.341
33.51	43.54	0.341
33.52	43.63	0.341
33.53	43.73	0.341
33.54	43.83	0.341
33.55	43.94	0.341
33.56	44.04	0.341
33.57	44.13	0.341
33.58	44.23	0.342
33.59	44.33	0.342
33.60	44.43	0.342
33.61	44.53	0.342
33.62	44.63	0.342
33.63	44.73	0.342
33.64	44.84	0.342
33.65	44.94	0.342
33.66	45.04	0.342
33.67	45.14	0.342
33.68	45.24	0.342
33.69	45.34	0.342
33.70	45.44	0.342
33.71	45.54	0.342
33.72	45.64	0.342
33.73	45.74	0.342
33.74	45.84	0.342
33.75	45.94	0.343
33.76	46.04	0.343
33.77	46.14	0.343
33.78	46.24	0.343
33.79	46.34	0.343
33.80	46.44	0.343
33.81	46.54	0.343
33.82	46.64	0.343
33.83	46.74	0.343
33.84	46.84	0.343
33.85	46.94	0.343
33.86	47.04	0.343
33.87	47.14	0.343
33.88	47.24	0.343
33.89	47.34	0.343
33.90	47.44	0.343
33.91	47.54	0.343
33.92	47.64	0.343
33.93	47.74	0.343
33.94	47.84	0.344
33.95	47.94	0.344
33.96	48.04	0.344
33.97	48.14	0.344
33.98	48.24	0.344
33.99	48.34	0.344
34.00	48.44	0.344
34.01	48.54	0.344
34.02	48.64	0.344
34.03	48.74	0.344
34.04	48.84	0.344
34.05	48.94	0.344
34.06	49.04	0.344
34.07	49.14	0.344
34.08	49.24	0.344
34.09	49.34	0.344
34.10	49.44	0.344
34.11	49.54	0.345
34.12	49.64	0.345
34.13	49.74	0.345
34.14	49.84	0.345
34.15	49.94	0.345
34.16	50.04	0.345
34.17	50.14	0.345
34.18	50.24	0.345
34.19	50.34	0.345
34.20	50.44	0.345
34.21	50.54	0.345
34.22	50.64	0.345
34.23	50.74	0.345
34.24	50.84	0.345
34.25	50.94	0.345
34.26	51.04	0.345
34.27	51.14	0.345
34.28	51.24	0.346
34.29	51.34	0.346
34.30	51.44	0.346
34.31	51.54	0.346
34.32	51.64	0.346
34.33	51.74	0.346
34.34	51.84	0.346
34.35	51.94	0.346
34.36	52.04	0.346
34.37	52.14	0.346
34.38	52.24	0.346
34.39	52.34	0.346
34.40	52.45	0.346
34.41	52.54	0.346
34.42	52.64	0.346
34.43	52.74	0.346
34.44	52.84	0.346
34.45	52.94	0.346
34.46	53.05	0.346
34.47	53.14	0.346
34.48	53.24	0.347
34.49	53.34	0.347
34.50	53.44	0.347
34.51	53.55	0.347
34.52	53.64	0.347
34.53	53.75	0.347
34.54	53.85	0.347
34.55	53.95	0.347
34.56	54.05	0.347
34.57	54.15	0.347
34.58	54.25	0.347
34.59	54.35	0.347
34.60	54.45	0.347
34.61	54.55	0.347
34.62	54.65	0.347
34.63	54.75	0.347
34.64	54.85	0.347
34.65	54.95	0.348
34.66	55.05	0.348
34.67	55.15	0.348
34.68	55.25	0.348
34.69	55.35	0.348
34.70	55.45	0.348
34.71	55.55	0.348
34.72	55.65	0.348
34.73	55.75	0.348
34.74	55.85	0.348
34.75	55.95	0.348
34.76	56.05	0.348
34.77	56.15	0.348
34.78	56.25	0.348
34.79	56.35	0.348
34.80	56.45	0.348
34.81	56.55	0.348
34.82	56.65	0.348
34.83	56.75	0.348
34.84	56.85	0.349
34.85	56.95	0.349
34.86	57.05	0.349
34.87	57.15	0.349
34.88	57.25	0.349
34.89	57.35	0.349
34.90	57.45	0.349
34.91	57.55	0.349
34.92	57.65	0.349
34.93	57.75	0.349
34.94	57.85	0.349
34.95	57.95	0.349
34.96	58.05	0.349
34.97	58.15	0.349
34.98	58.25	0.349
34.99	58.35	0.349
35.00	58.45	0.349
35.01	58.55	0.349
35.02	58.65	0.350
35.03	58.75	0.350
35.04	58.85	0.350
35.05	58.95	0.350
35.06	59.05	0.350
35.07	59.15	0.350
35.08	59.25	0.350
35.09	59.35	0.350
35.10	59.45	0.350
35.11	59.55	0.350
35.12	59.65	0.350
35.13	59.75	0.350
35.14	59.85	0.350
35.15	59.95	0.350
35.16	60.05	0.350
35.17	60.15	0.350
35.18	60.25	0.350
35.19	60.35	0.350
35.20	60.45	0.350
35.21	60.55	0.350
35.22	60.65	0.351
35.23	60.75	0.351
35.24	60.85	0.351
35.25	60.95	0.351
35.26	61.05	0.351
35.27	61.15	0.351
35.28	61.25	0.351
35.29	61.35	0.351
35.30	61.45	0.351
35.31	61.55	0.351
35.32	61.65	0.351
35.33	61.75	0.351
35.34	61.85	0.351
35.35	61.95	0.351
35.36	62.05	0.351
35.37	62.15	0.351
35.38	62.25	0.351
35.39	62.35	0.351
35.40	62.45	0.351
35.41	62.55	0.352
35.42	62.65	0.352
35.43	62.75	0.352
35.44	62.85	0.352
35.45	62.95	0.352
35.46	63.05	0.352
35.47	63.15	0.352
35.48	63.25	0.352
35.49	63.35	0.352
35.50	63.45	0.352
35.51	63.55	0.352
35.52	63.65	0.352
35.53	63.75	0.352
35.54	63.85	0.352
35.55	63.95	0.352
35.56	64.06	0.352
35.57	64.16	0.352
35.58	64.26	0.352
35.59	64.36	0.353
35.60	64.46	0.353
35.61	64.56	0.353
35.62	64.66	0.353
35.63	64.76	0.353
35.64	64.85	0.353
35.65	64.96	0.353
35.66	65.06	0.353
35.67	65.16	0.353
35.68	65.26	0.353
35.69	65.36	0.353
35.70	65.46	0.353
35.71	65.56	0.353
35.72	65.66	0.353
35.73	65.76	0.353
35.74	65.86	0.353
35.75	65.96	0.353
35.76	66.06	0.354
35.77	66.16	0.354
35.78	66.26	0.354
35.79	66.36	0.354
35.80	66.46	0.354
35.81	66.56	0.354
35.82	66.66	0.354
35.83	66.76	0.354
35.84	66.86	0.354
35.85	66.96	0.354
35.86	67.06	0.354
35.87	67.16	0.354
35.88	67.26	0.354
35.89	67.36	0.354
35.90	67.46	0.354
35.91	67.56	0.354
35.92	67.66	0.354
35.93	67.76	0.355
35.94	67.86	0.355
35.95	67.96	0.355
35.96	68.06	0.355
35.97	68.16	0.355
35.98	68.26	0.355
35.99	68.36	0.355
36.00	68.46	0.355
36.01	68.56	0.355
36.02	68.66	0.355
36.03	68.76	0.355
36.04	68.86	0.355
36.05	68.96	0.355
36.06	69.06	0.355
36.07	69.16	0.355
36.08	69.26	0.355
36.09	69.36	0.356
36.10	69.46	0.356
36.11	69.56	0.356
36.12	69.66	0.356
36.13	69.76	0.356
36.14	69.86	0.356
36.15	69.96	0.356
36.16	70.06	0.356
36.17	70.16	0.356
36.18	70.26	0.356
36.19	70.36	0.356
36.20	70.46	0.356
36.21	70.56	0.356
36.22	70.66	0.356
36.23	70.76	0.356
36.24	70.86	0.356
36.25	70.96	0.357
36.26	71.06	0.357
36.27	71.16	0.357
36.28	71.26	0.357
36.29	71.36	0.357
36.30	71.46	0.357
36.31	71.56	0.357
36.32	71.66	0.357
36.33	71.76	0.357
36.34	71.86	0.357
36.35	71.96	0.357
36.36	72.06	0.357
36.37	72.16	0.357
36.38	72.26	0.357
36.39	72.36	0.357
36.40	72.46	0.357
36.41	72.56	0.357
36.42	72.66	0.358
36.43	72.76	0.358
36.44	72.86	0.358
36.45	72.96	0.358
36.46	73.06	0.358
36.47	73.16	0.358
36.48	73.26	0.358
36.49	73.36	0.358
36.50	73.46	0.358
36.51	73.56	0.358
36.52	73.66	0.358
36.53	73.76	0.358
36.54	73.86	0.358
36.55	73.96	0.358
36.56	74.06	0.358
36.57	74.17	0.358
36.58	74.26	0.359
36.59	74.37	0.359
36.60	74.47	0.359
36.61	74.57	0.359
36.62	74.66	0.359
36.63	74.77	0.359
36.64	74.86	0.359
36.65	74.96	0.359
36.66	75.06	0.359
36.67	75.17	0.359
36.68	75.27	0.359
36.69	75.37	0.359
36.70	75.47	0.359
36.71	75.57	0.359
36.72	75.67	0.359
36.73	75.77	0.359
36.74	75.87	0.359
36.75	75.97	0.360
36.76	76.07	0.360
36.77	76.17	0.360
36.78	76.27	0.360
36.79	76.37	0.360
36.80	76.47	0.360
36.81	76.57	0.360
36.82	76.67	0.360
36.83	76.77	0.360
36.84	76.87	0.360
36.85	76.97	0.360
36.86	77.07	0.360
36.87	77.17	0.360
36.88	77.27	0.360
36.89	77.37	0.360
36.90	77.47	0.360
36.91	77.57	0.361
36.92	77.67	0.361
36.93	77.77	0.361
36.94	77.87	0.361
36.95	77.97	0.361
36.96	78.07	0.361
36.97	78.17	0.361
36.98	78.27	0.361
36.99	78.37	0.361
37.00	78.47	0.361
37.01	78.57	0.361
37.02	78.67	0.361
37.03	78.77	0.361
37.04	78.87	0.361
37.05	78.97	0.361
37.06	79.07	0.361
37.07	79.17	0.361
37.08	79.27	0.361
37.09	79.37	0.362
37.10	79.47	0.362
37.11	79.57	0.362
37.12	79.67	0.362
37.13	79.77	0.362
37.14	79.87	0.362
37.15	79.97	0.362
37.16	80.07	0.362
37.17	80.17	0.362
37.18	80.27	0.362
37.19	80.37	0.362
37.20	80.47	0.362
37.21	80.57	0.362
37.22	80.67	0.362
37.23	80.77	0.362
37.24	80.87	0.362
37.25	80.97	0.362
37.26	81.07	0.362
37.27	81.17	0.363
37.28	81.27	0.363
37.29	81.37	0.363
37.30	81.47	0.363
37.31	81.57	0.363
37.32	81.67	0.363
37.33	81.77	0.363
37.34	81.87	0.363
37.35	81.97	0.363
37.36	82.07	0.363
37.37	82.18	0.363
37.38	82.27	0.363
37.39	82.38	0.363
37.40	82.48	0.363
37.41	82.58	0.363
37.42	82.68	0.363
37.43	82.78	0.363
37.44	82.88	0.363
37.45	82.98	0.363
37.46	83.08	0.364
37.47	83.18	0.364
37.48	83.28	0.364
37.49	83.38	0.364
37.50	83.48	0.364
37.51	83.58	0.364
37.52	83.68	0.364
37.53	83.78	0.364
37.54	83.88	0.364
37.55	83.98	0.364
37.56	84.08	0.364
37.57	84.18	0.364
37.58	84.28	0.364
37.59	84.38	0.364
37.60	84.48	0.364
37.61	84.58	0.364
37.62	84.68	0.364
37.63	84.78	0.364
37.64	84.88	0.364
37.65	84.98	0.364
37.66	85.08	0.364
37.67	85.18	0.364
37.68	85.28	0.364
37.69	85.38	0.364
37.70	85.48	0.364
37.71	85.58	0.364
37.72	85.68	0.365
37.73	85.78	0.365
37.74	85.88	0.365
37.75	85.98	0.365
37.76	86.08	0.365
37.77	86.18	0.365
37.78	86.28	0.365
37.79	86.38	0.365
37.80	86.48	0.365
37.81	86.58	0.365
37.82	86.68	0.365
37.83	86.78	0.365
37.84	86.88	0.365
37.85	86.98	0.365
37.86	87.08	0.365
37.87	87.18	0.365
37.88	87.28	0.365
37.89	87.38	0.365
37.90	87.48	0.365
37.91	87.58	0.365
37.92	87.68	0.365
37.93	87.78	0.365
37.94	87.88	0.366
37.95	87.98	0.366
37.96	88.08	0.366
37.97	88.18	0.366
37.98	88.28	0.366
37.99	88.38	0.366
38.00	88.48	0.366
38.01	88.58	0.366
38.02	88.68	0.366
38.03	88.78	0.366
38.04	88.88	0.366
38.05	88.98	0.366
38.06	89.08	0.366
38.07	89.18	0.366
38.08	89.28	0.366
38.09	89.38	0.366
38.10	89.48	0.366
38.11	89.58	0.367
38.12	89.68	0.367
38.13	89.78	0.367
38.14	89.88	0.367
38.15	89.98	0.367
38.16	90.08	0.367
38.17	90.18	0.367
38.18	90.28	0.367
38.19	90.38	0.367
38.20	90.48	0.367
38.21	90.58	0.367
38.22	90.68	0.367
38.23	90.78	0.367
38.24	90.88	0.367
38.25	90.98	0.367
38.26	91.08	0.367
38.27	91.18	0.368
38.28	91.28	0.368
38.29	91.38	0.368
38.30	91.48	0.368
38.31	91.58	0.368
38.32	91.68	0.368
38.33	91.78	0.368
38.34	91.88	0.368
38.35	91.98	0.368
38.36	92.08	0.368
38.37	92.18	0.368
38.38	92.28	0.368
38.39	92.38	0.368
38.40	92.48	0.368
38.41	92.58	0.368
38.42	92.68	0.368
38.43	92.78	0.368
38.44	92.88	0.369
38.45	92.98	0.369
38.46	93.08	0.369
38.47	93.18	0.369
38.48	93.28	0.369
38.49	93.38	0.369
38.50	93.48	0.369
38.51	93.58	0.369
38.52	93.68	0.369
38.53	93.78	0.369
38.54	93.88	0.369
38.55	93.98	0.369
38.56	94.08	0.369
38.57	94.18	0.370
38.58	94.28	0.370
38.59	94.38	0.370
38.60	94.48	0.370
38.61	94.58	0.370
38.62	94.68	0.370
38.63	94.78	0.370
38.64	94.88	0.370
38.65	94.98	0.370
38.66	95.08	0.370
38.67	95.18	0.370
38.68	95.28	0.370
38.69	95.38	0.370
38.70	95.48	0.370
38.71	95.58	0.371
38.72	95.68	0.371
38.73	95.78	0.371
38.74	95.88	0.371
38.75	95.98	0.371
38.76	96.08	0.371
38.77	96.18	0.371
38.78	96.28	0.371
38.79	96.38	0.371
38.80	96.48	0.371
38.81	96.58	0.371
38.82	96.68	0.371
38.83	96.78	0.371
38.84	96.88	0.372
38.85	96.98	0.372
38.86	97.08	0.372
38.87	97.18	0.372
38.88	97.28	0.372
38.89	97.38	0.372
38.90	97.48	0.372
38.91	97.58	0.372
38.92	97.68	0.372
38.93	97.78	0.372
38.94	97.88	0.372
38.95	97.98
38.96	98.08
38.97	98.19
38.98	98.29
38.99	98.39
39.00