File: DSC/2023_04_22_CBD_Pinhole_Lid_n40C_20C_Fragility.txt
Filename	2023_04_22_CBD_Pinhole_Lid_n40C_20C_Fragility
Instrument name	DSC2A-00468 (192.168.1.100)
Operator	JLY
rundate	4/22/2023
Sample name	2023_04_22_CBD_Pinhole_Lid_n40C_20C_Fragility
proceduresegments	Data Off ; Equilibrate -30.00 °C; Data On ; Ramp 5.00 °C/min to 20.00 °C; Data Off ; Isothermal 0.1 min; Data On ; Ramp 50.00 °C/min to -30.00 °C; Data Off ; Isothermal 0.1 min; Data On ; Ramp 5.00 °C/min to 20.00 °C; Data Off ; Isothermal 0.1 min; Data On ; Ramp 50.00 °C/min to -30.00 °C; Data Off ; Isothermal 0.1 min; Data On ; Ramp 5.00 °C/min to 20.00 °C; Data Off ; Isothermal 0.1 min; Data On ; Ramp 20.00 °C/min to -30.00 °C; Data Off ; Isothermal 0.1 min; Data On ; Ramp 5.00 °C/min to 20.00 °C; Data Off ; Isothermal 0.1 min; Data On ; Ramp 10.00 °C/min to -30.00 °C; Data Off ; Isothermal 0.1 min; Data On ; Ramp 5.00 °C/min to 20.00 °C; Data Off ; Isothermal 0.1 min; Data On ; Ramp 5.00 °C/min to -30.00 °C; Data Off ; Isothermal 0.1 min; Data On ; Ramp 5.00 °C/min to 20.00 °C; Data Off ; Isothermal 0.1 min; Data On ; Ramp 1.00 °C/min to -30.00 °C; Data Off ; Isothermal 0.1 min; Data On ; Ramp 5.00 °C/min to 20.00 °C; Data Off ; Isothermal 0.1 min; Data On ; Ramp 0.50 °C/min to -30.00 °C; Data Off ; Isothermal 0.1 min; Data Off ; Ramp 5.00 °C/min to 20.00 °C
[File Parameters]
Run date	4/22/2023 2:47:36 PM
Trios version	5.1.1.46572
Original File Name
Current File Name	C:\Users\yargerlab\Desktop\DSC Data\General\2023_04_22_CBD_Pinhole_Lid_n40C_20C_Fragility.tri
[Procedure]
Procedure Name	DSC n30C to 20C at Variable Cooling and heating rate of 5 C/min.
Sample Name	2023_04_22_CBD_Pinhole_Lid_n40C_20C_Fragility
Sample Mass	3.76 mg
Reference Sample Mass	0 mg
Pan Mass	51.31 mg
Pan Number	41
Reference Pan Mass	51.13 mg
Reference Pan Number	37
Pan Type	Tzero Aluminum Pin Hole Hermetic
Comments	Alod Al pan with Pinhole Tzero Lid, Hermetically Sealed - CBD Crystalline, Run 2x DSC Before and melted, Now a CBD supercooled liquid at room temp, Fragility DSC Run.
Project Name	CA
Operator	JLY
Test	Custom
Unload Max Temperature	30
Unload Min Temperature	30
Load Max Temperature	30
Load Min Temperature	30
Stop on Gas Flow Error	Yes
[Signal List]
Signal #1	Time (min)
Signal #2	Temperature (°C)
Signal #3	Heat Flow (mW)
Signal #4	Delta T (µV)
Signal #5	Delta Tzero (µV)
Signal #6	Tzero Temperature (°C)
Signal #7	Cell Purge (mL/min)
Signal #8	Heater Temp (°C)
Signal #9	Power Delivered (W)
Signal #10	Reference Junction Temperature (°C)
Signal #11	Flange Temperature (°C)
Signal #12	Heat Flow Phase (rad)
Signal #13	Total Heat Capacity (J/°C)
Signal #14	Heat Capacity (J/°C)
[Configuration]
Company Name	ASU
Instrument Name	DSC2A-00468
Instrument Type	DSC2500
Serial Number	DSC2A-00468
IP	192.168.1.100
Location of Instrument	MRRC
DisplayType	Unknown
Sample Interval 	0.1 s/pt
Selected Heat Flow	T4P
Exotherm Direction	Down
Cell Serial	DRC2-00792
Lid Type	Standard
Cooler	RCS 90
Leave Cooler on at End of Sequence	On
Gas 2	Nitrogen
Gas Selected	Channel 1
Flow Rate	50 mL/min
Secondary Purge	On
Licensed Heat Flow	Heat Flow T4P
Modulation Licensed	Yes
[Versions]
Common IDD Version	1
Cortex Version	VER 2.10.2.31
Driver	5.0.0.6
GDM Version	1.0.3.3
TouchscreenVersion	1.0.0.16145
FEP Version	1.2.1.21
FEP Bootloader	2.0.0.5
AutoSampler Version	2.1.1.26
Auto Sampler Bootloader	2.0.0.5
FCM Version	1.1.0.3
FCM Bootloader	2.0.0.5
[Experiment Logs]
Experiment Log Entry # 1	Data On set to 0
Experiment Log Entry # 3	Equilibrate Segment -30 (C) Started
Experiment Log Entry # 5	Air Cool is off.
Experiment Log Entry # 7	Data On set to 1
Experiment Log Entry # 9	Ramp Segment 5 C/min to 20 Started
Experiment Log Entry # 11	Data On set to 0
Experiment Log Entry # 13	Isothermal Segment 0.1 min started
Experiment Log Entry # 15	Data On set to 1
Experiment Log Entry # 17	Ramp Segment 50 C/min to -30 Started
Experiment Log Entry # 19	Data On set to 0
Experiment Log Entry # 21	Isothermal Segment 0.1 min started
Experiment Log Entry # 23	Data On set to 1
Experiment Log Entry # 25	Ramp Segment 5 C/min to 20 Started
Experiment Log Entry # 27	Data On set to 0
Experiment Log Entry # 29	Isothermal Segment 0.1 min started
Experiment Log Entry # 31	Data On set to 1
Experiment Log Entry # 33	Ramp Segment 50 C/min to -30 Started
Experiment Log Entry # 35	Data On set to 0
Experiment Log Entry # 37	Isothermal Segment 0.1 min started
Experiment Log Entry # 39	Data On set to 1
Experiment Log Entry # 41	Ramp Segment 5 C/min to 20 Started
Experiment Log Entry # 43	Data On set to 0
Experiment Log Entry # 45	Isothermal Segment 0.1 min started
Experiment Log Entry # 47	Data On set to 1
Experiment Log Entry # 49	Ramp Segment 20 C/min to -30 Started
Experiment Log Entry # 51	Data On set to 0
Experiment Log Entry # 53	Isothermal Segment 0.1 min started
Experiment Log Entry # 55	Data On set to 1
Experiment Log Entry # 57	Ramp Segment 5 C/min to 20 Started
Experiment Log Entry # 59	Data On set to 0
Experiment Log Entry # 61	Isothermal Segment 0.1 min started
Experiment Log Entry # 63	Data On set to 1
Experiment Log Entry # 65	Ramp Segment 10 C/min to -30 Started
Experiment Log Entry # 67	Data On set to 0
Experiment Log Entry # 69	Isothermal Segment 0.1 min started
Experiment Log Entry # 71	Data On set to 1
Experiment Log Entry # 73	Ramp Segment 5 C/min to 20 Started
Experiment Log Entry # 75	Data On set to 0
Experiment Log Entry # 77	Isothermal Segment 0.1 min started
Experiment Log Entry # 79	Data On set to 1
Experiment Log Entry # 81	Ramp Segment 5 C/min to -30 Started
Experiment Log Entry # 83	Data On set to 0
Experiment Log Entry # 85	Isothermal Segment 0.1 min started
Experiment Log Entry # 87	Data On set to 1
Experiment Log Entry # 89	Ramp Segment 5 C/min to 20 Started
Experiment Log Entry # 91	Data On set to 0
Experiment Log Entry # 93	Isothermal Segment 0.1 min started
Experiment Log Entry # 95	Data On set to 1
Experiment Log Entry # 97	Ramp Segment 1 C/min to -30 Started
Experiment Log Entry # 99	Data On set to 0
Experiment Log Entry # 101	Isothermal Segment 0.1 min started
Experiment Log Entry # 103	Data On set to 1
Experiment Log Entry # 105	Ramp Segment 5 C/min to 20 Started
Experiment Log Entry # 107	Data On set to 0
Experiment Log Entry # 109	Isothermal Segment 0.1 min started
Experiment Log Entry # 111	Data On set to 1
Experiment Log Entry # 113	Ramp Segment 0.5 C/min to -30 Started
Experiment Log Entry # 115	Data On set to 0
Experiment Log Entry # 117	Isothermal Segment 0.1 min started
Experiment Log Entry # 119	Data On set to 0
Experiment Log Entry # 121	Ramp Segment 5 C/min to 20 Started
[Method Log]
Method Log Entry # 1	Data Off
Method Log Entry # 2	Equilibrate -30 °C
Method Log Entry # 3	Data On
Method Log Entry # 4	(Ramp 96388) Ramp 5 °C/minute to 20 °C
Method Log Entry # 5	Data Off
Method Log Entry # 6	Isothermal 0.1 minutes
Method Log Entry # 7	Data On
Method Log Entry # 8	(Ramp 96392) Ramp 50 °C/minute to -30 °C
Method Log Entry # 9	Data Off
Method Log Entry # 10	Isothermal 0.1 minutes
Method Log Entry # 11	Data On
Method Log Entry # 12	(Ramp 96396) Ramp 5 °C/minute to 20 °C
Method Log Entry # 13	Data Off
Method Log Entry # 14	Isothermal 0.1 minutes
Method Log Entry # 15	Data On
Method Log Entry # 16	(Ramp 96400) Ramp 50 °C/minute to -30 °C
Method Log Entry # 17	Data Off
Method Log Entry # 18	Isothermal 0.1 minutes
Method Log Entry # 19	Data On
Method Log Entry # 20	(Ramp 96404) Ramp 5 °C/minute to 20 °C
Method Log Entry # 21	Data Off
Method Log Entry # 22	Isothermal 0.1 minutes
Method Log Entry # 23	Data On
Method Log Entry # 24	(Ramp 96408) Ramp 20 °C/minute to -30 °C
Method Log Entry # 25	Data Off
Method Log Entry # 26	Isothermal 0.1 minutes
Method Log Entry # 27	Data On
Method Log Entry # 28	(Ramp 96412) Ramp 5 °C/minute to 20 °C
Method Log Entry # 29	Data Off
Method Log Entry # 30	Isothermal 0.1 minutes
Method Log Entry # 31	Data On
Method Log Entry # 32	(Ramp 96416) Ramp 10 °C/minute to -30 °C
Method Log Entry # 33	Data Off
Method Log Entry # 34	Isothermal 0.1 minutes
Method Log Entry # 35	Data On
Method Log Entry # 36	(Ramp 96420) Ramp 5 °C/minute to 20 °C
Method Log Entry # 37	Data Off
Method Log Entry # 38	Isothermal 0.1 minutes
Method Log Entry # 39	Data On
Method Log Entry # 40	(Ramp 96424) Ramp 5 °C/minute to -30 °C
Method Log Entry # 41	Data Off
Method Log Entry # 42	Isothermal 0.1 minutes
Method Log Entry # 43	Data On
Method Log Entry # 44	(Ramp 96428) Ramp 5 °C/minute to 20 °C
Method Log Entry # 45	Data Off
Method Log Entry # 46	Isothermal 0.1 minutes
Method Log Entry # 47	Data On
Method Log Entry # 48	(Ramp 96432) Ramp 1 °C/minute to -30 °C
Method Log Entry # 49	Data Off
Method Log Entry # 50	Isothermal 0.1 minutes
Method Log Entry # 51	Data On
Method Log Entry # 52	(Ramp 96436) Ramp 5 °C/minute to 20 °C
Method Log Entry # 53	Data Off
Method Log Entry # 54	Isothermal 0.1 minutes
Method Log Entry # 55	Data On
Method Log Entry # 56	(Ramp 96440) Ramp 0.5 °C/minute to -30 °C
Method Log Entry # 57	Data Off
Method Log Entry # 58	Isothermal 0.1 minutes
Method Log Entry # 59	Data Off
Method Log Entry # 60	(Ramp 96444) Ramp 5 °C/minute to 20 °C
Cell Serial	DRC2-00792
[T1 Calibration]
Slope	-0.008529666
Offset	9.636258
Initial Temperature	98.23
GUID	f8bfdadc-4977-4fdf-ba6d-0ba9134940c3
[TZero Calibration]
Date Applied	11/29/2022 4:06:13 PM
Description	From -89.059 °C to 396.009 °C at 20.000°C/min
Gas Type	Nitrogen
Pan Type	None
Source Files 1	C:\Users\yargerlab\Desktop\DSC Data\General\TZero_calibration_11_29_22_2nd(2).tri
Source Files 2	C:\Users\yargerlab\Desktop\DSC Data\General\TZero_calibration_11_29_22_2nd(3).tri
Delta T Offset	13.05235
Delta T Slope	-0.007271007
Delta T0 Offset	-13.69128
Delta T0 Slope	0.06063341
[Temperature Calibration]
Date Applied	11/29/2022 7:12:28 PM
Description	From 106.590 °C to 186.590 °C at 10.000°C/min
Gas Type	Nitrogen
Pan Type	Tzero Aluminum Hermetic
Source Files 1	C:\Users\yargerlab\Desktop\DSC Data\General\Indium(6).tri
Measured 1	157.391
Known 1	156.598
[Cell Constant Calibration]
Date Applied	11/29/2022 7:12:29 PM
Description	From 106.590 °C to 186.590 °C at 10.000°C/min
Gas Type	Nitrogen
Pan Type	Tzero Aluminum Hermetic
Source Files 1	C:\Users\yargerlab\Desktop\DSC Data\General\Indium(6).tri
T4P KCell	1.006051
Onset Slope	63.26126 mW/°C
[Direct Cp Calibration]
Date Applied	11/30/2022 11:04:51 AM
Description	From -79.983 °C to 298.409 °C at 10.000°C/min
Gas Type	Nitrogen
Pan Type	Tzero Aluminum Hermetic
Source Files 1	C:\Users\yargerlab\Desktop\DSC Data\General\Sapphire_Heat_Capacity_11_30_22.tri
[Rev Cp Calibration]
Date Applied	11/30/2022 1:58:51 PM
Description	From -79.996 °C to 292.812 °C at 3.000°C/min
Gas Type	Nitrogen
Pan Type	Tzero Aluminum Hermetic
Source Files 1	C:\Users\yargerlab\Desktop\DSC Data\General\Sapphire_MDSC_Calibration_11_30_22.tri
[step]
Ramp 5.00 °C/min to 20.00 °C
Time	Temperature	Heat Flow (Normalized)
min	°C	W/g
0.00	-29.75	-0.043
0.01	-29.75	-0.049
0.02	-29.75	-0.048
0.03	-29.75	-0.046
0.03	-29.75	-0.043
0.04	-29.76	-0.040
0.05	-29.76	-0.037
0.06	-29.76	-0.034
0.07	-29.76	-0.031
0.08	-29.75	-0.030
0.08	-29.75	-0.029
0.09	-29.74	-0.028
0.10	-29.74	-0.027
0.11	-29.73	-0.027
0.12	-29.72	-0.027
0.13	-29.70	-0.027
0.13	-29.68	-0.027
0.14	-29.67	-0.027
0.15	-29.65	-0.027
0.16	-29.62	-0.027
0.17	-29.60	-0.026
0.18	-29.58	-0.023
0.18	-29.55	-0.018
0.19	-29.52	-0.011
0.20	-29.49	-0.005
0.21	-29.47	0.001
0.22	-29.44	0.007
0.23	-29.40	0.013
0.23	-29.37	0.018
0.24	-29.34	0.023
0.25	-29.31	0.029
0.26	-29.28	0.033
0.27	-29.24	0.039
0.28	-29.21	0.042
0.28	-29.17	0.047
0.29	-29.14	0.051
0.30	-29.10	0.053
0.31	-29.07	0.056
0.32	-29.03	0.059
0.33	-29.00	0.062
0.33	-28.96	0.065
0.34	-28.92	0.067
0.35	-28.89	0.070
0.36	-28.85	0.072
0.37	-28.81	0.073
0.38	-28.77	0.075
0.38	-28.74	0.077
0.39	-28.70	0.079
0.40	-28.66	0.080
0.41	-28.62	0.081
0.42	-28.59	0.082
0.43	-28.55	0.084
0.43	-28.51	0.085
0.44	-28.47	0.087
0.45	-28.43	0.088
0.46	-28.39	0.089
0.47	-28.35	0.089
0.48	-28.31	0.090
0.48	-28.28	0.090
0.49	-28.24	0.091
0.50	-28.20	0.091
0.51	-28.16	0.092
0.52	-28.12	0.092
0.53	-28.08	0.092
0.53	-28.04	0.093
0.54	-28.00	0.093
0.55	-27.96	0.093
0.56	-27.92	0.094
0.57	-27.88	0.094
0.58	-27.84	0.094
0.58	-27.80	0.094
0.59	-27.76	0.095
0.60	-27.72	0.095
0.61	-27.68	0.095
0.62	-27.64	0.095
0.63	-27.60	0.096
0.63	-27.56	0.096
0.64	-27.52	0.096
0.65	-27.48	0.096
0.66	-27.44	0.097
0.67	-27.40	0.097
0.68	-27.36	0.097
0.68	-27.32	0.097
0.69	-27.28	0.097
0.70	-27.24	0.098
0.71	-27.20	0.098
0.72	-27.16	0.098
0.73	-27.12	0.098
0.73	-27.08	0.098
0.74	-27.04	0.098
0.75	-27.00	0.099
0.76	-26.96	0.099
0.77	-26.92	0.099
0.78	-26.88	0.099
0.78	-26.84	0.099
0.79	-26.80	0.099
0.80	-26.76	0.100
0.81	-26.72	0.100
0.82	-26.68	0.100
0.83	-26.64	0.100
0.83	-26.60	0.100
0.84	-26.56	0.100
0.85	-26.51	0.100
0.86	-26.48	0.101
0.87	-26.43	0.101
0.88	-26.39	0.101
0.88	-26.35	0.101
0.89	-26.31	0.101
0.90	-26.27	0.101
0.91	-26.23	0.101
0.92	-26.19	0.101
0.93	-26.15	0.102
0.93	-26.11	0.102
0.94	-26.07	0.102
0.95	-26.03	0.102
0.96	-25.99	0.102
0.97	-25.95	0.102
0.98	-25.91	0.102
0.98	-25.87	0.102
0.99	-25.82	0.102
1.00	-25.78	0.102
1.01	-25.74	0.102
1.02	-25.70	0.102
1.03	-25.66	0.102
1.03	-25.62	0.103
1.04	-25.58	0.103
1.05	-25.54	0.103
1.06	-25.49	0.103
1.07	-25.45	0.103
1.08	-25.41	0.103
1.08	-25.37	0.103
1.09	-25.33	0.103
1.10	-25.29	0.103
1.11	-25.25	0.103
1.12	-25.21	0.103
1.13	-25.17	0.103
1.13	-25.13	0.103
1.14	-25.09	0.103
1.15	-25.05	0.103
1.16	-25.00	0.104
1.17	-24.96	0.104
1.18	-24.92	0.104
1.18	-24.88	0.104
1.19	-24.84	0.104
1.20	-24.80	0.104
1.21	-24.76	0.104
1.22	-24.72	0.104
1.23	-24.68	0.104
1.23	-24.63	0.104
1.24	-24.59	0.104
1.25	-24.55	0.104
1.26	-24.51	0.104
1.27	-24.47	0.104
1.28	-24.43	0.104
1.28	-24.39	0.104
1.29	-24.35	0.104
1.30	-24.31	0.104
1.31	-24.26	0.104
1.32	-24.22	0.104
1.33	-24.18	0.104
1.33	-24.14	0.104
1.34	-24.10	0.104
1.35	-24.06	0.104
1.36	-24.02	0.104
1.37	-23.97	0.104
1.38	-23.93	0.104
1.38	-23.89	0.105
1.39	-23.85	0.104
1.40	-23.81	0.105
1.41	-23.77	0.105
1.42	-23.73	0.105
1.43	-23.69	0.105
1.43	-23.64	0.105
1.44	-23.60	0.105
1.45	-23.56	0.105
1.46	-23.52	0.105
1.47	-23.48	0.105
1.48	-23.44	0.105
1.48	-23.40	0.105
1.49	-23.36	0.105
1.50	-23.31	0.105
1.51	-23.27	0.105
1.52	-23.23	0.105
1.53	-23.19	0.105
1.53	-23.15	0.105
1.54	-23.11	0.105
1.55	-23.07	0.105
1.56	-23.02	0.105
1.57	-22.98	0.105
1.58	-22.94	0.105
1.58	-22.90	0.105
1.59	-22.86	0.105
1.60	-22.82	0.105
1.61	-22.78	0.105
1.62	-22.73	0.105
1.63	-22.69	0.106
1.63	-22.65	0.106
1.64	-22.61	0.106
1.65	-22.57	0.106
1.66	-22.53	0.106
1.67	-22.49	0.106
1.68	-22.45	0.106
1.68	-22.40	0.106
1.69	-22.36	0.106
1.70	-22.32	0.106
1.71	-22.28	0.106
1.72	-22.24	0.106
1.73	-22.19	0.106
1.73	-22.15	0.106
1.74	-22.11	0.106
1.75	-22.07	0.106
1.76	-22.03	0.106
1.77	-21.99	0.106
1.78	-21.95	0.106
1.78	-21.91	0.106
1.79	-21.86	0.106
1.80	-21.82	0.106
1.81	-21.78	0.106
1.82	-21.74	0.106
1.83	-21.70	0.106
1.83	-21.66	0.106
1.84	-21.61	0.106
1.85	-21.57	0.106
1.86	-21.53	0.107
1.87	-21.49	0.107
1.88	-21.45	0.107
1.88	-21.41	0.107
1.89	-21.37	0.107
1.90	-21.32	0.107
1.91	-21.28	0.107
1.92	-21.24	0.107
1.93	-21.20	0.107
1.93	-21.16	0.107
1.94	-21.12	0.107
1.95	-21.08	0.107
1.96	-21.03	0.107
1.97	-20.99	0.107
1.98	-20.95	0.107
1.98	-20.91	0.107
1.99	-20.87	0.107
2.00	-20.83	0.107
2.01	-20.78	0.107
2.02	-20.74	0.107
2.03	-20.70	0.107
2.03	-20.66	0.108
2.04	-20.62	0.108
2.05	-20.58	0.108
2.06	-20.54	0.108
2.07	-20.49	0.108
2.08	-20.45	0.108
2.08	-20.41	0.108
2.09	-20.37	0.108
2.10	-20.33	0.108
2.11	-20.29	0.108
2.12	-20.25	0.108
2.13	-20.20	0.108
2.13	-20.16	0.108
2.14	-20.12	0.108
2.15	-20.08	0.109
2.16	-20.04	0.109
2.17	-19.99	0.109
2.18	-19.95	0.109
2.18	-19.91	0.109
2.19	-19.87	0.109
2.20	-19.83	0.109
2.21	-19.79	0.109
2.22	-19.75	0.109
2.23	-19.70	0.109
2.23	-19.66	0.109
2.24	-19.62	0.109
2.25	-19.58	0.109
2.26	-19.54	0.110
2.27	-19.50	0.110
2.28	-19.46	0.110
2.28	-19.41	0.110
2.29	-19.37	0.110
2.30	-19.33	0.110
2.31	-19.29	0.110
2.32	-19.25	0.110
2.33	-19.21	0.110
2.33	-19.16	0.110
2.34	-19.12	0.110
2.35	-19.08	0.111
2.36	-19.04	0.111
2.37	-19.00	0.111
2.38	-18.96	0.111
2.38	-18.91	0.111
2.39	-18.87	0.111
2.40	-18.83	0.111
2.41	-18.79	0.111
2.42	-18.75	0.111
2.43	-18.70	0.112
2.43	-18.66	0.112
2.44	-18.62	0.112
2.45	-18.58	0.112
2.46	-18.54	0.112
2.47	-18.50	0.112
2.48	-18.46	0.112
2.48	-18.41	0.112
2.49	-18.37	0.113
2.50	-18.33	0.113
2.51	-18.29	0.113
2.52	-18.25	0.113
2.53	-18.21	0.113
2.53	-18.17	0.113
2.54	-18.13	0.113
2.55	-18.08	0.113
2.56	-18.04	0.114
2.57	-18.00	0.114
2.58	-17.96	0.114
2.58	-17.92	0.114
2.59	-17.87	0.114
2.60	-17.83	0.114
2.61	-17.79	0.114
2.62	-17.75	0.115
2.63	-17.71	0.115
2.63	-17.67	0.115
2.64	-17.62	0.115
2.65	-17.58	0.116
2.66	-17.54	0.116
2.67	-17.50	0.116
2.68	-17.46	0.116
2.68	-17.42	0.116
2.69	-17.38	0.116
2.70	-17.33	0.117
2.71	-17.29	0.117
2.72	-17.25	0.117
2.73	-17.21	0.117
2.73	-17.17	0.117
2.74	-17.13	0.118
2.75	-17.09	0.118
2.76	-17.04	0.118
2.77	-17.00	0.118
2.78	-16.96	0.118
2.78	-16.92	0.119
2.79	-16.88	0.119
2.80	-16.84	0.119
2.81	-16.79	0.119
2.82	-16.75	0.119
2.83	-16.71	0.120
2.83	-16.67	0.120
2.84	-16.63	0.120
2.85	-16.59	0.120
2.86	-16.54	0.120
2.87	-16.50	0.121
2.88	-16.46	0.121
2.88	-16.42	0.121
2.89	-16.38	0.121
2.90	-16.34	0.122
2.91	-16.29	0.122
2.92	-16.25	0.122
2.93	-16.21	0.123
2.93	-16.17	0.123
2.94	-16.13	0.123
2.95	-16.09	0.123
2.96	-16.05	0.124
2.97	-16.00	0.124
2.98	-15.96	0.124
2.98	-15.92	0.125
2.99	-15.88	0.125
3.00	-15.84	0.125
3.01	-15.80	0.126
3.02	-15.75	0.126
3.03	-15.71	0.126
3.03	-15.67	0.126
3.04	-15.63	0.126
3.05	-15.59	0.127
3.06	-15.55	0.127
3.07	-15.51	0.127
3.08	-15.46	0.128
3.08	-15.42	0.128
3.09	-15.38	0.128
3.10	-15.34	0.129
3.11	-15.30	0.129
3.12	-15.25	0.129
3.13	-15.21	0.129
3.13	-15.17	0.130
3.14	-15.13	0.130
3.15	-15.09	0.130
3.16	-15.05	0.130
3.17	-15.01	0.131
3.18	-14.96	0.131
3.18	-14.92	0.131
3.19	-14.88	0.132
3.20	-14.84	0.132
3.21	-14.80	0.132
3.22	-14.76	0.133
3.23	-14.71	0.133
3.23	-14.67	0.133
3.24	-14.63	0.133
3.25	-14.59	0.134
3.26	-14.55	0.134
3.27	-14.51	0.134
3.28	-14.47	0.135
3.28	-14.42	0.135
3.29	-14.38	0.135
3.30	-14.34	0.135
3.31	-14.30	0.136
3.32	-14.26	0.136
3.33	-14.21	0.136
3.33	-14.17	0.136
3.34	-14.13	0.137
3.35	-14.09	0.137
3.36	-14.05	0.137
3.37	-14.01	0.138
3.38	-13.97	0.138
3.38	-13.92	0.138
3.39	-13.88	0.138
3.40	-13.84	0.138
3.41	-13.80	0.139
3.42	-13.76	0.139
3.43	-13.71	0.139
3.43	-13.67	0.139
3.44	-13.63	0.139
3.45	-13.59	0.140
3.46	-13.55	0.140
3.47	-13.50	0.140
3.48	-13.46	0.141
3.48	-13.42	0.141
3.49	-13.38	0.142
3.50	-13.34	0.142
3.51	-13.30	0.142
3.52	-13.25	0.142
3.53	-13.21	0.142
3.53	-13.17	0.143
3.54	-13.13	0.143
3.55	-13.09	0.143
3.56	-13.05	0.143
3.57	-13.01	0.143
3.58	-12.96	0.143
3.58	-12.92	0.143
3.59	-12.88	0.143
3.60	-12.84	0.144
3.61	-12.80	0.144
3.62	-12.76	0.144
3.63	-12.72	0.144
3.63	-12.67	0.144
3.64	-12.63	0.144
3.65	-12.59	0.144
3.66	-12.55	0.144
3.67	-12.51	0.144
3.68	-12.47	0.144
3.68	-12.43	0.144
3.69	-12.39	0.144
3.70	-12.34	0.143
3.71	-12.30	0.143
3.72	-12.26	0.143
3.73	-12.22	0.143
3.73	-12.17	0.143
3.74	-12.13	0.143
3.75	-12.09	0.143
3.76	-12.05	0.143
3.77	-12.01	0.143
3.78	-11.97	0.143
3.78	-11.92	0.143
3.79	-11.88	0.143
3.80	-11.84	0.143
3.81	-11.80	0.143
3.82	-11.76	0.143
3.83	-11.72	0.143
3.83	-11.67	0.143
3.84	-11.64	0.143
3.85	-11.59	0.143
3.86	-11.55	0.142
3.87	-11.51	0.142
3.88	-11.47	0.142
3.88	-11.42	0.142
3.89	-11.38	0.142
3.90	-11.34	0.142
3.91	-11.30	0.142
3.92	-11.26	0.142
3.93	-11.22	0.142
3.93	-11.17	0.142
3.94	-11.13	0.141
3.95	-11.09	0.141
3.96	-11.05	0.141
3.97	-11.01	0.141
3.98	-10.96	0.141
3.98	-10.92	0.141
3.99	-10.88	0.141
4.00	-10.84	0.141
4.01	-10.80	0.141
4.02	-10.76	0.140
4.03	-10.71	0.140
4.03	-10.67	0.140
4.04	-10.63	0.140
4.05	-10.59	0.140
4.06	-10.55	0.140
4.07	-10.51	0.140
4.08	-10.46	0.140
4.08	-10.42	0.140
4.09	-10.38	0.140
4.10	-10.34	0.139
4.11	-10.30	0.139
4.12	-10.26	0.139
4.13	-10.21	0.139
4.13	-10.17	0.139
4.14	-10.13	0.139
4.15	-10.09	0.139
4.16	-10.05	0.139
4.17	-10.01	0.139
4.18	-9.96	0.139
4.18	-9.92	0.139
4.19	-9.88	0.138
4.20	-9.84	0.138
4.21	-9.80	0.138
4.22	-9.76	0.138
4.23	-9.71	0.138
4.23	-9.67	0.138
4.24	-9.63	0.138
4.25	-9.59	0.138
4.26	-9.55	0.138
4.27	-9.50	0.138
4.28	-9.46	0.138
4.28	-9.42	0.138
4.29	-9.38	0.138
4.30	-9.33	0.138
4.31	-9.29	0.138
4.32	-9.25	0.137
4.33	-9.21	0.137
4.33	-9.17	0.138
4.34	-9.12	0.138
4.35	-9.08	0.137
4.36	-9.04	0.137
4.37	-9.00	0.137
4.38	-8.96	0.137
4.38	-8.92	0.137
4.39	-8.88	0.137
4.40	-8.83	0.137
4.41	-8.79	0.137
4.42	-8.75	0.137
4.43	-8.71	0.137
4.43	-8.67	0.137
4.44	-8.62	0.137
4.45	-8.58	0.137
4.46	-8.54	0.137
4.47	-8.50	0.137
4.48	-8.46	0.137
4.48	-8.42	0.137
4.49	-8.37	0.137
4.50	-8.33	0.137
4.51	-8.29	0.137
4.52	-8.25	0.137
4.53	-8.21	0.137
4.53	-8.17	0.137
4.54	-8.12	0.136
4.55	-8.08	0.136
4.56	-8.04	0.136
4.57	-8.00	0.136
4.58	-7.96	0.136
4.58	-7.92	0.136
4.59	-7.88	0.136
4.60	-7.83	0.136
4.61	-7.79	0.136
4.62	-7.75	0.136
4.63	-7.71	0.136
4.63	-7.67	0.136
4.64	-7.63	0.136
4.65	-7.58	0.136
4.66	-7.54	0.136
4.67	-7.50	0.136
4.68	-7.46	0.136
4.68	-7.42	0.136
4.69	-7.38	0.136
4.70	-7.33	0.136
4.71	-7.29	0.136
4.72	-7.25	0.136
4.73	-7.21	0.136
4.73	-7.17	0.136
4.74	-7.13	0.136
4.75	-7.08	0.136
4.76	-7.04	0.136
4.77	-7.00	0.136
4.78	-6.96	0.136
4.78	-6.92	0.136
4.79	-6.88	0.136
4.80	-6.84	0.136
4.81	-6.79	0.136
4.82	-6.75	0.136
4.83	-6.71	0.136
4.83	-6.67	0.136
4.84	-6.63	0.135
4.85	-6.58	0.135
4.86	-6.54	0.135
4.87	-6.50	0.135
4.88	-6.46	0.135
4.88	-6.42	0.135
4.89	-6.38	0.135
4.90	-6.34	0.135
4.91	-6.29	0.135
4.92	-6.25	0.135
4.93	-6.21	0.135
4.93	-6.17	0.135
4.94	-6.13	0.135
4.95	-6.09	0.135
4.96	-6.04	0.135
4.97	-6.00	0.135
4.98	-5.96	0.135
4.98	-5.92	0.135
4.99	-5.88	0.135
5.00	-5.84	0.135
5.01	-5.80	0.135
5.02	-5.76	0.135
5.03	-5.71	0.135
5.03	-5.67	0.135
5.04	-5.63	0.135
5.05	-5.59	0.135
5.06	-5.55	0.135
5.07	-5.50	0.135
5.08	-5.46	0.135
5.08	-5.42	0.135
5.09	-5.38	0.135
5.10	-5.34	0.135
5.11	-5.29	0.135
5.12	-5.25	0.135
5.13	-5.21	0.135
5.13	-5.17	0.135
5.14	-5.13	0.135
5.15	-5.08	0.135
5.16	-5.04	0.135
5.17	-5.00	0.135
5.18	-4.96	0.135
5.18	-4.92	0.135
5.19	-4.88	0.135
5.20	-4.83	0.135
5.21	-4.79	0.135
5.22	-4.75	0.135
5.23	-4.71	0.135
5.23	-4.67	0.135
5.24	-4.63	0.135
5.25	-4.58	0.135
5.26	-4.54	0.135
5.27	-4.50	0.135
5.28	-4.46	0.135
5.28	-4.42	0.135
5.29	-4.37	0.135
5.30	-4.33	0.135
5.31	-4.29	0.135
5.32	-4.25	0.135
5.33	-4.21	0.135
5.33	-4.17	0.135
5.34	-4.12	0.135
5.35	-4.08	0.135
5.36	-4.04	0.135
5.37	-4.00	0.135
5.38	-3.96	0.135
5.38	-3.92	0.135
5.39	-3.88	0.135
5.40	-3.83	0.135
5.41	-3.79	0.135
5.42	-3.75	0.135
5.43	-3.71	0.135
5.43	-3.67	0.135
5.44	-3.63	0.135
5.45	-3.58	0.135
5.46	-3.54	0.135
5.47	-3.50	0.135
5.48	-3.46	0.135
5.48	-3.42	0.135
5.49	-3.38	0.135
5.50	-3.33	0.135
5.51	-3.29	0.135
5.52	-3.25	0.135
5.53	-3.21	0.135
5.53	-3.17	0.135
5.54	-3.13	0.135
5.55	-3.08	0.135
5.56	-3.04	0.135
5.57	-3.00	0.135
5.58	-2.96	0.135
5.58	-2.92	0.135
5.59	-2.87	0.135
5.60	-2.83	0.135
5.61	-2.79	0.135
5.62	-2.75	0.135
5.63	-2.71	0.135
5.63	-2.67	0.135
5.64	-2.62	0.135
5.65	-2.58	0.135
5.66	-2.54	0.135
5.67	-2.50	0.135
5.68	-2.46	0.135
5.68	-2.42	0.135
5.69	-2.37	0.135
5.70	-2.33	0.135
5.71	-2.29	0.135
5.72	-2.25	0.135
5.73	-2.21	0.135
5.73	-2.17	0.135
5.74	-2.13	0.135
5.75	-2.08	0.135
5.76	-2.04	0.135
5.77	-2.00	0.135
5.78	-1.96	0.135
5.78	-1.92	0.135
5.79	-1.88	0.135
5.80	-1.83	0.135
5.81	-1.79	0.135
5.82	-1.75	0.135
5.83	-1.71	0.135
5.83	-1.66	0.135
5.84	-1.62	0.135
5.85	-1.58	0.135
5.86	-1.54	0.135
5.87	-1.50	0.135
5.88	-1.46	0.135
5.88	-1.41	0.135
5.89	-1.38	0.135
5.90	-1.33	0.135
5.91	-1.29	0.135
5.92	-1.25	0.135
5.93	-1.21	0.135
5.93	-1.17	0.135
5.94	-1.13	0.135
5.95	-1.08	0.135
5.96	-1.04	0.135
5.97	-1.00	0.135
5.98	-0.96	0.135
5.98	-0.92	0.135
5.99	-0.87	0.135
6.00	-0.83	0.135
6.01	-0.79	0.135
6.02	-0.75	0.135
6.03	-0.71	0.135
6.03	-0.67	0.135
6.04	-0.62	0.135
6.05	-0.58	0.135
6.06	-0.54	0.135
6.07	-0.50	0.135
6.08	-0.46	0.135
6.08	-0.42	0.135
6.09	-0.38	0.135
6.10	-0.33	0.135
6.11	-0.29	0.135
6.12	-0.25	0.135
6.13	-0.21	0.135
6.13	-0.17	0.135
6.14	-0.13	0.135
6.15	-0.08	0.135
6.16	-0.04	0.135
6.17	0.00	0.135
6.18	0.04	0.135
6.18	0.08	0.135
6.19	0.12	0.135
6.20	0.17	0.135
6.21	0.21	0.135
6.22	0.25	0.135
6.23	0.29	0.135
6.23	0.33	0.135
6.24	0.37	0.135
6.25	0.42	0.135
6.26	0.46	0.135
6.27	0.50	0.135
6.28	0.54	0.135
6.28	0.58	0.135
6.29	0.62	0.135
6.30	0.67	0.135
6.31	0.71	0.135
6.32	0.75	0.135
6.33	0.79	0.135
6.33	0.83	0.135
6.34	0.87	0.135
6.35	0.92	0.135
6.36	0.96	0.135
6.37	1.00	0.135
6.38	1.04	0.135
6.38	1.08	0.135
6.39	1.12	0.135
6.40	1.17	0.135
6.41	1.21	0.135
6.42	1.25	0.135
6.43	1.29	0.135
6.43	1.33	0.135
6.44	1.37	0.135
6.45	1.42	0.135
6.46	1.46	0.135
6.47	1.50	0.135
6.48	1.54	0.135
6.48	1.58	0.135
6.49	1.63	0.135
6.50	1.67	0.135
6.51	1.71	0.135
6.52	1.75	0.135
6.53	1.79	0.135
6.53	1.83	0.135
6.54	1.87	0.135
6.55	1.92	0.135
6.56	1.96	0.135
6.57	2.00	0.135
6.58	2.04	0.135
6.58	2.08	0.135
6.59	2.13	0.135
6.60	2.17	0.135
6.61	2.21	0.135
6.62	2.25	0.135
6.63	2.29	0.135
6.63	2.34	0.135
6.64	2.38	0.135
6.65	2.42	0.135
6.66	2.46	0.135
6.67	2.50	0.135
6.68	2.54	0.135
6.68	2.59	0.135
6.69	2.63	0.135
6.70	2.67	0.135
6.71	2.71	0.135
6.72	2.75	0.135
6.73	2.79	0.135
6.73	2.84	0.135
6.74	2.88	0.135
6.75	2.92	0.135
6.76	2.96	0.135
6.77	3.00	0.135
6.78	3.05	0.135
6.78	3.09	0.135
6.79	3.13	0.135
6.80	3.17	0.135
6.81	3.21	0.135
6.82	3.25	0.135
6.83	3.29	0.135
6.83	3.34	0.135
6.84	3.38	0.135
6.85	3.42	0.135
6.86	3.46	0.135
6.87	3.50	0.135
6.88	3.55	0.135
6.88	3.59	0.135
6.89	3.63	0.135
6.90	3.67	0.135
6.91	3.71	0.135
6.92	3.75	0.135
6.93	3.79	0.135
6.93	3.84	0.135
6.94	3.88	0.135
6.95	3.92	0.135
6.96	3.96	0.135
6.97	4.00	0.135
6.98	4.05	0.135
6.98	4.09	0.135
6.99	4.13	0.135
7.00	4.17	0.135
7.01	4.21	0.135
7.02	4.25	0.135
7.03	4.29	0.135
7.03	4.34	0.135
7.04	4.38	0.135
7.05	4.42	0.135
7.06	4.46	0.135
7.07	4.50	0.135
7.08	4.54	0.135
7.08	4.59	0.135
7.09	4.63	0.135
7.10	4.67	0.135
7.11	4.71	0.135
7.12	4.75	0.135
7.13	4.79	0.135
7.13	4.84	0.135
7.14	4.88	0.135
7.15	4.92	0.135
7.16	4.96	0.135
7.17	5.00	0.135
7.18	5.04	0.135
7.18	5.09	0.135
7.19	5.13	0.135
7.20	5.17	0.135
7.21	5.21	0.135
7.22	5.25	0.135
7.23	5.30	0.135
7.23	5.34	0.135
7.24	5.38	0.135
7.25	5.42	0.135
7.26	5.46	0.135
7.27	5.50	0.135
7.28	5.55	0.135
7.28	5.59	0.135
7.29	5.63	0.135
7.30	5.67	0.135
7.31	5.71	0.135
7.32	5.75	0.135
7.33	5.79	0.135
7.33	5.84	0.135
7.34	5.88	0.135
7.35	5.92	0.135
7.36	5.96	0.135
7.37	6.00	0.135
7.38	6.04	0.135
7.38	6.09	0.135
7.39	6.13	0.135
7.40	6.17	0.135
7.41	6.21	0.135
7.42	6.25	0.135
7.43	6.29	0.135
7.43	6.34	0.135
7.44	6.38	0.135
7.45	6.42	0.135
7.46	6.46	0.135
7.47	6.50	0.135
7.48	6.54	0.135
7.48	6.59	0.135
7.49	6.63	0.135
7.50	6.67	0.135
7.51	6.71	0.136
7.52	6.75	0.135
7.53	6.80	0.136
7.53	6.84	0.136
7.54	6.88	0.136
7.55	6.92	0.135
7.56	6.96	0.136
7.57	7.00	0.136
7.58	7.04	0.136
7.58	7.09	0.136
7.59	7.13	0.136
7.60	7.17	0.136
7.61	7.21	0.136
7.62	7.25	0.136
7.63	7.29	0.136
7.63	7.34	0.136
7.64	7.38	0.136
7.65	7.42	0.136
7.66	7.46	0.136
7.67	7.50	0.136
7.68	7.55	0.136
7.68	7.59	0.136
7.69	7.63	0.136
7.70	7.67	0.136
7.71	7.71	0.136
7.72	7.75	0.136
7.73	7.79	0.136
7.73	7.84	0.136
7.74	7.88	0.136
7.75	7.92	0.136
7.76	7.96	0.136
7.77	8.00	0.136
7.78	8.05	0.136
7.78	8.09	0.136
7.79	8.13	0.136
7.80	8.17	0.136
7.81	8.21	0.136
7.82	8.25	0.136
7.83	8.30	0.136
7.83	8.34	0.136
7.84	8.38	0.136
7.85	8.42	0.136
7.86	8.46	0.136
7.87	8.50	0.136
7.88	8.54	0.136
7.88	8.59	0.136
7.89	8.63	0.136
7.90	8.67	0.136
7.91	8.71	0.136
7.92	8.75	0.136
7.93	8.80	0.136
7.93	8.84	0.136
7.94	8.88	0.136
7.95	8.92	0.136
7.96	8.96	0.136
7.97	9.00	0.136
7.98	9.05	0.136
7.98	9.09	0.136
7.99	9.13	0.136
8.00	9.17	0.136
8.01	9.21	0.136
8.02	9.26	0.136
8.03	9.29	0.136
8.03	9.34	0.136
8.04	9.38	0.136
8.05	9.42	0.136
8.06	9.46	0.136
8.07	9.50	0.136
8.08	9.55	0.136
8.08	9.59	0.136
8.09	9.63	0.136
8.10	9.67	0.136
8.11	9.71	0.136
8.12	9.76	0.136
8.13	9.80	0.136
8.13	9.84	0.136
8.14	9.88	0.136
8.15	9.92	0.136
8.16	9.96	0.136
8.17	10.01	0.136
8.18	10.05	0.136
8.18	10.09	0.136
8.19	10.13	0.136
8.20	10.17	0.136
8.21	10.21	0.136
8.22	10.25	0.136
8.23	10.30	0.136
8.23	10.34	0.136
8.24	10.38	0.136
8.25	10.42	0.136
8.26	10.46	0.136
8.27	10.51	0.136
8.28	10.55	0.136
8.28	10.59	0.136
8.29	10.63	0.136
8.30	10.67	0.136
8.31	10.71	0.136
8.32	10.76	0.136
8.33	10.80	0.136
8.33	10.84	0.136
8.34	10.88	0.136
8.35	10.92	0.136
8.36	10.96	0.136
8.37	11.01	0.136
8.38	11.05	0.136
8.38	11.09	0.136
8.39	11.13	0.136
8.40	11.17	0.136
8.41	11.21	0.136
8.42	11.26	0.136
8.43	11.30	0.136
8.43	11.34	0.136
8.44	11.38	0.136
8.45	11.42	0.136
8.46	11.46	0.136
8.47	11.51	0.136
8.48	11.55	0.136
8.48	11.59	0.136
8.49	11.63	0.136
8.50	11.67	0.136
8.51	11.71	0.136
8.52	11.76	0.136
8.53	11.80	0.136
8.53	11.84	0.136
8.54	11.88	0.136
8.55	11.92	0.136
8.56	11.96	0.136
8.57	12.01	0.136
8.58	12.05	0.136
8.58	12.09	0.136
8.59	12.13	0.136
8.60	12.17	0.136
8.61	12.22	0.136
8.62	12.26	0.136
8.63	12.30	0.136
8.63	12.34	0.136
8.64	12.38	0.136
8.65	12.42	0.136
8.66	12.46	0.136
8.67	12.51	0.136
8.68	12.55	0.136
8.68	12.59	0.136
8.69	12.63	0.136
8.70	12.67	0.136
8.71	12.72	0.136
8.72	12.76	0.136
8.73	12.80	0.136
8.73	12.84	0.136
8.74	12.88	0.136
8.75	12.92	0.136
8.76	12.97	0.136
8.77	13.01	0.136
8.78	13.05	0.136
8.78	13.09	0.136
8.79	13.13	0.136
8.80	13.18	0.136
8.81	13.22	0.136
8.82	13.26	0.136
8.83	13.30	0.136
8.83	13.34	0.136
8.84	13.38	0.136
8.85	13.42	0.136
8.86	13.47	0.136
8.87	13.51	0.136
8.88	13.55	0.136
8.88	13.59	0.136
8.89	13.63	0.136
8.90	13.67	0.136
8.91	13.72	0.136
8.92	13.76	0.136
8.93	13.80	0.136
8.93	13.84	0.136
8.94	13.88	0.136
8.95	13.92	0.136
8.96	13.97	0.136
8.97	14.01	0.136
8.98	14.05	0.136
8.98	14.09	0.136
8.99	14.13	0.136
9.00	14.17	0.136
9.01	14.22	0.136
9.02	14.26	0.136
9.03	14.30	0.136
9.03	14.34	0.136
9.04	14.38	0.136
9.05	14.43	0.136
9.06	14.47	0.136
9.07	14.51	0.136
9.08	14.55	0.136
9.08	14.59	0.136
9.09	14.63	0.136
9.10	14.68	0.136
9.11	14.72	0.136
9.12	14.76	0.136
9.13	14.80	0.136
9.13	14.84	0.136
9.14	14.88	0.136
9.15	14.92	0.136
9.16	14.97	0.136
9.17	15.01	0.136
9.18	15.05	0.136
9.18	15.09	0.136
9.19	15.13	0.136
9.20	15.18	0.136
9.21	15.22	0.136
9.22	15.26	0.136
9.23	15.30	0.136
9.23	15.34	0.136
9.24	15.38	0.136
9.25	15.43	0.136
9.26	15.47	0.137
9.27	15.51	0.137
9.28	15.55	0.137
9.28	15.59	0.137
9.29	15.63	0.137
9.30	15.68	0.137
9.31	15.72	0.137
9.32	15.76	0.137
9.33	15.80	0.137
9.33	15.84	0.137
9.34	15.88	0.137
9.35	15.92	0.137
9.36	15.97	0.137
9.37	16.01	0.137
9.38	16.05	0.137
9.38	16.09	0.137
9.39	16.13	0.137
9.40	16.18	0.137
9.41	16.22	0.137
9.42	16.26	0.137
9.43	16.30	0.137
9.43	16.34	0.137
9.44	16.38	0.137
9.45	16.42	0.137
9.46	16.47	0.137
9.47	16.51	0.137
9.48	16.55	0.137
9.48	16.59	0.137
9.49	16.63	0.137
9.50	16.68	0.137
9.51	16.72	0.137
9.52	16.76	0.137
9.53	16.80	0.137
9.53	16.84	0.137
9.54	16.88	0.137
9.55	16.93	0.137
9.56	16.97	0.137
9.57	17.01	0.137
9.58	17.05	0.137
9.58	17.09	0.137
9.59	17.13	0.137
9.60	17.18	0.137
9.61	17.22	0.137
9.62	17.26	0.137
9.63	17.30	0.137
9.63	17.34	0.137
9.64	17.39	0.137
9.65	17.43	0.137
9.66	17.47	0.137
9.67	17.51	0.137
9.68	17.55	0.137
9.68	17.59	0.137
9.69	17.63	0.137
9.70	17.68	0.137
9.71	17.72	0.137
9.72	17.76	0.137
9.73	17.80	0.137
9.73	17.84	0.137
9.74	17.88	0.137
9.75	17.93	0.137
9.76	17.97	0.137
9.77	18.01	0.137
9.78	18.05	0.137
9.78	18.09	0.137
9.79	18.13	0.137
9.80	18.18	0.137
9.81	18.22	0.137
9.82	18.26	0.137
9.83	18.30	0.137
9.83	18.34	0.137
9.84	18.38	0.137
9.85	18.43	0.137
9.86	18.47	0.137
9.87	18.51	0.137
9.88	18.55	0.137
9.88	18.59	0.137
9.89	18.63	0.137
9.90	18.68	0.137
9.91	18.72	0.137
9.92	18.76	0.137
9.93	18.80	0.137
9.93	18.84	0.137
9.94	18.89	0.137
9.95	18.93
9.96	18.97
9.97	19.01
9.98	19.05
9.98	19.09
9.99	19.13
10.00

[step]
Ramp 50.00 °C/min to -30.00 °C
Time	Temperature	Heat Flow (Normalized)
min	°C	W/g
10.10	19.62	0.144
10.10	19.63	0.145
10.10	19.63	0.145
10.11	19.64	0.145
10.11	19.64	0.145
10.11	19.65	0.145
10.11	19.65	0.145
10.11	19.66	0.145
10.12	19.66	0.145
10.12	19.66	0.145
10.12	19.67	0.145
10.12	19.67	0.145
10.12	19.67	0.145
10.12	19.68	0.145
10.13	19.68	0.145
10.13	19.68	0.145
10.13	19.69	0.145
10.13	19.69	0.145
10.13	19.69	0.145
10.13	19.69	0.145
10.13	19.69	0.145
10.14	19.69	0.145
10.14	19.70	0.145
10.14	19.70	0.145
10.14	19.70	0.144
10.14	19.70	0.144
10.15	19.70	0.144
10.15	19.70	0.144
10.15	19.70	0.144
10.15	19.70	0.144
10.15	19.70	0.144
10.15	19.69	0.144
10.15	19.69	0.144
10.16	19.69	0.144
10.16	19.69	0.145
10.16	19.68	0.145
10.16	19.68	0.146
10.16	19.68	0.147
10.17	19.67	0.148
10.17	19.67	0.150
10.17	19.66	0.152
10.17	19.66	0.153
10.17	19.65	0.155
10.17	19.64	0.157
10.18	19.64	0.159
10.18	19.63	0.160
10.18	19.62	0.160
10.18	19.61	0.161
10.18	19.61	0.162
10.18	19.60	0.162
10.18	19.59	0.163
10.19	19.58	0.163
10.19	19.57	0.163
10.19	19.56	0.163
10.19	19.54	0.163
10.19	19.53	0.163
10.20	19.52	0.163
10.20	19.51	0.163
10.20	19.49	0.163
10.20	19.48	0.162
10.20	19.47	0.162
10.20	19.45	0.161
10.20	19.44	0.159
10.21	19.42	0.156
10.21	19.40	0.151
10.21	19.39	0.145
10.21	19.37	0.138
10.21	19.35	0.133
10.22	19.34	0.129
10.22	19.32	0.125
10.22	19.30	0.121
10.22	19.28	0.116
10.22	19.26	0.113
10.22	19.24	0.107
10.23	19.22	0.102
10.23	19.20	0.097
10.23	19.18	0.092
10.23	19.16	0.086
10.23	19.14	0.081
10.23	19.11	0.075
10.23	19.09	0.070
10.24	19.07	0.065
10.24	19.04	0.060
10.24	19.02	0.054
10.24	19.00	0.048
10.24	18.97	0.042
10.25	18.95	0.035
10.25	18.92	0.029
10.25	18.90	0.022
10.25	18.87	0.014
10.25	18.85	0.006
10.25	18.82	-0.001
10.25	18.79	-0.008
10.26	18.76	-0.014
10.26	18.73	-0.022
10.26	18.71	-0.029
10.26	18.68	-0.035
10.26	18.65	-0.042
10.27	18.62	-0.049
10.27	18.59	-0.056
10.27	18.56	-0.064
10.27	18.53	-0.071
10.27	18.51	-0.079
10.27	18.47	-0.087
10.28	18.44	-0.094
10.28	18.41	-0.102
10.28	18.38	-0.110
10.28	18.35	-0.117
10.28	18.32	-0.125
10.28	18.29	-0.133
10.28	18.25	-0.141
10.29	18.22	-0.148
10.29	18.19	-0.156
10.29	18.15	-0.164
10.29	18.12	-0.172
10.29	18.09	-0.179
10.30	18.05	-0.187
10.30	18.02	-0.195
10.30	17.98	-0.203
10.30	17.95	-0.210
10.30	17.91	-0.218
10.30	17.88	-0.225
10.30	17.84	-0.233
10.31	17.81	-0.240
10.31	17.77	-0.248
10.31	17.73	-0.256
10.31	17.70	-0.264
10.31	17.66	-0.271
10.32	17.62	-0.279
10.32	17.59	-0.288
10.32	17.55	-0.294
10.32	17.51	-0.302
10.32	17.47	-0.310
10.32	17.44	-0.317
10.33	17.40	-0.324
10.33	17.36	-0.332
10.33	17.32	-0.340
10.33	17.28	-0.347
10.33	17.24	-0.354
10.33	17.20	-0.362
10.33	17.16	-0.369
10.34	17.12	-0.376
10.34	17.08	-0.382
10.34	17.04	-0.389
10.34	17.00	-0.395
10.34	16.96	-0.402
10.35	16.92	-0.410
10.35	16.88	-0.417
10.35	16.84	-0.423
10.35	16.80	-0.431
10.35	16.76	-0.437
10.35	16.72	-0.444
10.35	16.68	-0.451
10.36	16.63	-0.457
10.36	16.59	-0.463
10.36	16.55	-0.471
10.36	16.51	-0.477
10.36	16.47	-0.484
10.37	16.42	-0.491
10.37	16.38	-0.496
10.37	16.34	-0.503
10.37	16.29	-0.510
10.37	16.25	-0.516
10.37	16.21	-0.522
10.38	16.16	-0.528
10.38	16.12	-0.534
10.38	16.08	-0.540
10.38	16.03	-0.545
10.38	15.99	-0.551
10.38	15.95	-0.557
10.38	15.90	-0.562
10.39	15.86	-0.567
10.39	15.81	-0.573
10.39	15.77	-0.579
10.39	15.72	-0.585
10.39	15.68	-0.591
10.40	15.63	-0.596
10.40	15.59	-0.602
10.40	15.54	-0.606
10.40	15.50	-0.611
10.40	15.45	-0.616
10.40	15.41	-0.622
10.40	15.36	-0.627
10.41	15.31	-0.632
10.41	15.27	-0.637
10.41	15.22	-0.642
10.41	15.18	-0.647
10.41	15.13	-0.651
10.42	15.08	-0.656
10.42	15.04	-0.661
10.42	14.99	-0.666
10.42	14.95	-0.670
10.42	14.90	-0.676
10.42	14.85	-0.680
10.43	14.81	-0.685
10.43	14.76	-0.689
10.43	14.71	-0.694
10.43	14.66	-0.699
10.43	14.62	-0.702
10.43	14.57	-0.706
10.43	14.52	-0.710
10.44	14.48	-0.715
10.44	14.43	-0.720
10.44	14.38	-0.723
10.44	14.33	-0.727
10.44	14.28	-0.730
10.45	14.24	-0.735
10.45	14.19	-0.739
10.45	14.14	-0.743
10.45	14.09	-0.747
10.45	14.04	-0.750
10.45	14.00	-0.753
10.45	13.95	-0.757
10.46	13.90	-0.762
10.46	13.85	-0.765
10.46	13.80	-0.770
10.46	13.75	-0.774
10.46	13.71	-0.778
10.47	13.66	-0.782
10.47	13.61	-0.785
10.47	13.56	-0.788
10.47	13.51	-0.791
10.47	13.46	-0.793
10.47	13.41	-0.796
10.48	13.36	-0.799
10.48	13.31	-0.802
10.48	13.27	-0.805
10.48	13.22	-0.809
10.48	13.17	-0.813
10.48	13.12	-0.816
10.48	13.07	-0.819
10.49	13.02	-0.822
10.49	12.97	-0.825
10.49	12.92	-0.828
10.49	12.87	-0.830
10.49	12.82	-0.832
10.50	12.77	-0.835
10.50	12.72	-0.837
10.50	12.67	-0.839
10.50	12.62	-0.842
10.50	12.57	-0.844
10.50	12.52	-0.847
10.50	12.47	-0.851
10.51	12.42	-0.854
10.51	12.37	-0.857
10.51	12.32	-0.859
10.51	12.27	-0.862
10.51	12.22	-0.865
10.52	12.17	-0.867
10.52	12.12	-0.868
10.52	12.07	-0.871
10.52	12.02	-0.873
10.52	11.97	-0.874
10.52	11.92	-0.876
10.53	11.87	-0.879
10.53	11.82	-0.881
10.53	11.77	-0.883
10.53	11.72	-0.884
10.53	11.67	-0.886
10.53	11.62	-0.888
10.53	11.57	-0.890
10.54	11.52	-0.893
10.54	11.47	-0.895
10.54	11.41	-0.897
10.54	11.36	-0.899
10.54	11.31	-0.901
10.55	11.26	-0.903
10.55	11.21	-0.905
10.55	11.16	-0.907
10.55	11.11	-0.908
10.55	11.06	-0.909
10.55	11.01	-0.910
10.55	10.96	-0.912
10.56	10.91	-0.914
10.56	10.86	-0.916
10.56	10.81	-0.918
10.56	10.75	-0.919
10.56	10.70	-0.922
10.57	10.65	-0.924
10.57	10.60	-0.925
10.57	10.55	-0.927
10.57	10.50	-0.927
10.57	10.45	-0.928
10.57	10.40	-0.929
10.58	10.34	-0.931
10.58	10.29	-0.932
10.58	10.24	-0.933
10.58	10.19	-0.934
10.58	10.14	-0.936
10.58	10.09	-0.937
10.58	10.04	-0.938
10.59	9.99	-0.940
10.59	9.93	-0.941
10.59	9.88	-0.943
10.59	9.83	-0.944
10.59	9.78	-0.946
10.60	9.73	-0.946
10.60	9.68	-0.947
10.60	9.63	-0.948
10.60	9.58	-0.949
10.60	9.52	-0.949
10.60	9.47	-0.951
10.60	9.42	-0.953
10.61	9.37	-0.953
10.61	9.32	-0.954
10.61	9.27	-0.956
10.61	9.22	-0.958
10.61	9.16	-0.958
10.62	9.11	-0.959
10.62	9.06	-0.960
10.62	9.01	-0.960
10.62	8.96	-0.961
10.62	8.91	-0.962
10.62	8.86	-0.963
10.63	8.80	-0.964
10.63	8.75	-0.965
10.63	8.70	-0.965
10.63	8.65	-0.965
10.63	8.60	-0.966
10.63	8.54	-0.966
10.63	8.49	-0.967
10.64	8.44	-0.967
10.64	8.39	-0.968
10.64	8.34	-0.969
10.64	8.29	-0.970
10.64	8.24	-0.971
10.65	8.18	-0.973
10.65	8.13	-0.974
10.65	8.08	-0.975
10.65	8.03	-0.975
10.65	7.98	-0.975
10.65	7.93	-0.975
10.65	7.87	-0.975
10.66	7.82	-0.975
10.66	7.77	-0.976
10.66	7.72	-0.976
10.66	7.67	-0.977
10.66	7.62	-0.977
10.67	7.56	-0.978
10.67	7.51	-0.978
10.67	7.46	-0.979
10.67	7.41	-0.980
10.67	7.36	-0.980
10.67	7.31	-0.981
10.68	7.26	-0.981
10.68	7.20	-0.982
10.68	7.15	-0.982
10.68	7.10	-0.982
10.68	7.05	-0.983
10.68	7.00	-0.983
10.68	6.95	-0.984
10.69	6.89	-0.984
10.69	6.84	-0.985
10.69	6.79	-0.986
10.69	6.74	-0.986
10.69	6.69	-0.987
10.70	6.63	-0.987
10.70	6.58	-0.987
10.70	6.53	-0.987
10.70	6.48	-0.987
10.70	6.43	-0.986
10.70	6.38	-0.986
10.70	6.33	-0.987
10.71	6.27	-0.987
10.71	6.22	-0.987
10.71	6.17	-0.987
10.71	6.12	-0.988
10.71	6.07	-0.988
10.72	6.02	-0.988
10.72	5.96	-0.988
10.72	5.91	-0.988
10.72	5.86	-0.989
10.72	5.81	-0.989
10.72	5.76	-0.989
10.73	5.71	-0.989
10.73	5.65	-0.990
10.73	5.60	-0.990
10.73	5.55	-0.990
10.73	5.50	-0.990
10.73	5.45	-0.990
10.73	5.40	-0.990
10.74	5.35	-0.991
10.74	5.29	-0.991
10.74	5.24	-0.991
10.74	5.19	-0.991
10.74	5.14	-0.991
10.75	5.09	-0.991
10.75	5.04	-0.991
10.75	4.99	-0.991
10.75	4.93	-0.991
10.75	4.88	-0.991
10.75	4.83	-0.991
10.75	4.78	-0.991
10.76	4.73	-0.991
10.76	4.68	-0.991
10.76	4.63	-0.991
10.76	4.57	-0.991
10.76	4.52	-0.991
10.77	4.47	-0.991
10.77	4.42	-0.991
10.77	4.37	-0.991
10.77	4.32	-0.991
10.77	4.27	-0.991
10.77	4.21	-0.991
10.78	4.16	-0.991
10.78	4.11	-0.991
10.78	4.06	-0.991
10.78	4.01	-0.991
10.78	3.96	-0.991
10.78	3.91	-0.991
10.78	3.85	-0.991
10.79	3.80	-0.991
10.79	3.75	-0.991
10.79	3.70	-0.991
10.79	3.65	-0.991
10.79	3.60	-0.991
10.80	3.55	-0.991
10.80	3.50	-0.991
10.80	3.45	-0.991
10.80	3.40	-0.991
10.80	3.34	-0.991
10.80	3.29	-0.991
10.80	3.24	-0.991
10.81	3.19	-0.991
10.81	3.14	-0.991
10.81	3.09	-0.991
10.81	3.04	-0.991
10.81	2.99	-0.991
10.82	2.93	-0.991
10.82	2.88	-0.990
10.82	2.83	-0.990
10.82	2.78	-0.990
10.82	2.73	-0.990
10.82	2.68	-0.990
10.83	2.63	-0.990
10.83	2.58	-0.990
10.83	2.53	-0.990
10.83	2.48	-0.990
10.83	2.43	-0.990
10.83	2.37	-0.990
10.83	2.32	-0.990
10.84	2.27	-0.989
10.84	2.22	-0.989
10.84	2.17	-0.989
10.84	2.12	-0.989
10.84	2.07	-0.989
10.85	2.02	-0.989
10.85	1.97	-0.989
10.85	1.92	-0.989
10.85	1.86	-0.989
10.85	1.82	-0.989
10.85	1.76	-0.988
10.85	1.71	-0.988
10.86	1.66	-0.988
10.86	1.61	-0.988
10.86	1.56	-0.988
[...]
167.52	2.06	-0.034
167.58	2.02	-0.034
167.65	1.99	-0.035
167.72	1.96	-0.035
167.78	1.92	-0.034
167.85	1.89	-0.034
167.92	1.85	-0.034
167.98	1.82	-0.034
168.05	1.79	-0.032
168.12	1.75	-0.034
168.18	1.72	-0.036
168.25	1.69	-0.034
168.32	1.66	-0.033
168.38	1.62	-0.035
168.45	1.59	-0.035
168.52	1.56	-0.036
168.58	1.52	-0.035
168.65	1.49	-0.034
168.72	1.45	-0.035
168.78	1.42	-0.037
168.85	1.39	-0.036
168.92	1.36	-0.036
168.98	1.32	-0.035
169.05	1.29	-0.034
169.12	1.25	-0.035
169.18	1.22	-0.035
169.25	1.19	-0.035
169.32	1.16	-0.035
169.38	1.12	-0.036
169.45	1.09	-0.035
169.52	1.05	-0.027
169.58	1.02	-0.032
169.65	0.99	-0.034
169.72	0.95	-0.037
169.78	0.92	-0.036
169.85	0.89	-0.034
169.92	0.85	-0.033
169.98	0.82	-0.034
170.05	0.79	-0.034
170.12	0.76	-0.033
170.18	0.72	-0.034
170.25	0.69	-0.033
170.32	0.65	-0.034
170.38	0.62	-0.032
170.45	0.59	-0.034
170.52	0.55	-0.035
170.58	0.52	-0.035
170.65	0.49	-0.034
170.72	0.45	-0.034
170.78	0.42	-0.035
170.85	0.39	-0.035
170.92	0.35	-0.033
170.98	0.32	-0.034
171.05	0.29	-0.034
171.12	0.26	-0.031
171.18	0.22	-0.033
171.25	0.19	-0.033
171.32	0.15	-0.035
171.38	0.12	-0.035
171.45	0.09	-0.035
171.52	0.06	-0.033
171.58	0.02	-0.034
171.65	-0.01	-0.035
171.72	-0.04	-0.034
171.78	-0.08	-0.033
171.85	-0.11	-0.033
171.92	-0.15	-0.034
171.98	-0.18	-0.033
172.05	-0.21	-0.034
172.12	-0.25	-0.034
172.18	-0.28	-0.034
172.25	-0.31	-0.033
172.32	-0.35	-0.035
172.38	-0.38	-0.037
172.45	-0.41	-0.035
172.52	-0.44	-0.034
172.58	-0.48	-0.034
172.65	-0.51	-0.034
172.72	-0.54	-0.034
172.78	-0.58	-0.034
172.85	-0.61	-0.034
172.92	-0.64	-0.034
172.98	-0.68	-0.035
173.05	-0.71	-0.035
173.12	-0.74	-0.033
173.18	-0.78	-0.034
173.25	-0.81	-0.033
173.32	-0.85	-0.034
173.38	-0.88	-0.034
173.45	-0.91	-0.036
173.52	-0.94	-0.034
173.58	-0.98	-0.034
173.65	-1.01	-0.034
173.72	-1.04	-0.034
173.78	-1.08	-0.034
173.85	-1.11	-0.033
173.92	-1.14	-0.030
173.98	-1.18	-0.034
174.05	-1.21	-0.034
174.12	-1.24	-0.033
174.18	-1.28	-0.033
174.25	-1.31	-0.034
174.32	-1.34	-0.033
174.38	-1.38	-0.035
174.45	-1.41	-0.034
174.52	-1.45	-0.034
174.58	-1.48	-0.034
174.65	-1.51	-0.034
174.72	-1.55	-0.034
174.78	-1.58	-0.033
174.85	-1.61	-0.033
174.92	-1.64	-0.032
174.98	-1.68	-0.033
175.05	-1.71	-0.032
175.12	-1.75	-0.033
175.18	-1.78	-0.032
175.25	-1.81	-0.033
175.32	-1.84	-0.031
175.38	-1.88	-0.032
175.45	-1.91	-0.032
175.52	-1.94	-0.033
175.58	-1.98	-0.033
175.65	-2.01	-0.032
175.72	-2.04	-0.033
175.78	-2.08	-0.033
175.85	-2.11	-0.033
175.92	-2.14	-0.031
175.98	-2.18	-0.032
176.05	-2.21	-0.033
176.12	-2.25	-0.033
176.18	-2.28	-0.034
176.25	-2.31	-0.034
176.32	-2.34	-0.035
176.38	-2.38	-0.034
176.45	-2.41	-0.034
176.52	-2.44	-0.033
176.58	-2.48	-0.035
176.65	-2.51	-0.034
176.72	-2.54	-0.033
176.78	-2.58	-0.033
176.85	-2.61	-0.033
176.92	-2.64	-0.032
176.98	-2.68	-0.034
177.05	-2.71	-0.034
177.12	-2.74	-0.035
177.18	-2.78	-0.034
177.25	-2.81	-0.034
177.32	-2.84	-0.033
177.38	-2.88	-0.035
177.45	-2.91	-0.033
177.52	-2.95	-0.032
177.58	-2.98	-0.030
177.65	-3.01	-0.031
177.72	-3.04	-0.031
177.78	-3.08	-0.033
177.85	-3.11	-0.033
177.92	-3.14	-0.032
177.98	-3.18	-0.031
178.05	-3.21	-0.033
178.12	-3.25	-0.034
178.18	-3.28	-0.034
178.25	-3.31	-0.031
178.32	-3.34	-0.033
178.38	-3.38	-0.033
178.45	-3.41	-0.033
178.52	-3.44	-0.036
178.58	-3.48	-0.034
178.65	-3.51	-0.034
178.72	-3.54	-0.034
178.78	-3.58	-0.034
178.85	-3.61	-0.033
178.92	-3.65	-0.034
178.98	-3.68	-0.032
179.05	-3.71	-0.032
179.12	-3.75	-0.032
179.18	-3.78	-0.032
179.25	-3.81	-0.033
179.32	-3.85	-0.034
179.38	-3.88	-0.032
179.45	-3.91	-0.033
179.52	-3.95	-0.033
179.58	-3.98	-0.032
179.65	-4.01	-0.033
179.72	-4.04	-0.031
179.78	-4.08	-0.032
179.85	-4.11	-0.032
179.92	-4.15	-0.033
179.98	-4.18	-0.033
180.05	-4.21	-0.032
180.12	-4.24	-0.033
180.18	-4.28	-0.034
180.25	-4.31	-0.034
180.32	-4.34	-0.035
180.38	-4.38	-0.033
180.45	-4.41	-0.033
180.52	-4.44	-0.034
180.58	-4.48	-0.033
180.65	-4.51	-0.034
180.72	-4.54	-0.032
180.78	-4.58	-0.033
180.85	-4.61	-0.033
180.92	-4.64	-0.036
180.98	-4.68	-0.034
181.05	-4.71	-0.036
181.12	-4.75	-0.034
181.18	-4.78	-0.033
181.25	-4.81	-0.033
181.32	-4.84	-0.033
181.38	-4.88	-0.033
181.45	-4.91	-0.031
181.52	-4.94	-0.032
181.58	-4.98	-0.033
181.65	-5.01	-0.031
181.72	-5.04	-0.032
181.78	-5.08	-0.033
181.85	-5.11	-0.032
181.92	-5.15	-0.032
181.98	-5.18	-0.032
182.05	-5.21	-0.033
182.12	-5.24	-0.032
182.18	-5.28	-0.032
182.25	-5.31	-0.033
182.32	-5.34	-0.032
182.38	-5.38	-0.033
182.45	-5.41	-0.031
182.52	-5.44	-0.032
182.58	-5.48	-0.032
182.65	-5.51	-0.032
182.72	-5.54	-0.032
182.78	-5.58	-0.031
182.85	-5.61	-0.032
182.92	-5.65	-0.032
182.98	-5.68	-0.032
183.05	-5.71	-0.032
183.12	-5.74	-0.031
183.18	-5.78	-0.032
183.25	-5.81	-0.032
183.32	-5.84	-0.030
183.38	-5.88	-0.030
183.45	-5.91	-0.031
183.52	-5.94	-0.033
183.58	-5.98	-0.032
183.65	-6.01	-0.032
183.72	-6.05	-0.034
183.78	-6.08	-0.032
183.85	-6.11	-0.032
183.92	-6.14	-0.027
183.98	-6.18	-0.034
184.05	-6.21	-0.031
184.12	-6.25	-0.035
184.18	-6.28	-0.034
184.25	-6.31	-0.032
184.32	-6.35	-0.032
184.38	-6.38	-0.031
184.45	-6.41	-0.032
184.52	-6.45	-0.033
184.58	-6.48	-0.032
184.65	-6.51	-0.032
184.72	-6.54	-0.032
184.78	-6.58	-0.032
184.85	-6.61	-0.032
184.92	-6.64	-0.033
184.98	-6.68	-0.031
185.05	-6.71	-0.033
185.12	-6.75	-0.033
185.18	-6.78	-0.030
185.25	-6.81	-0.030
185.32	-6.85	-0.030
185.38	-6.88	-0.032
185.45	-6.91	-0.033
185.52	-6.94	-0.032
185.58	-6.98	-0.031
185.65	-7.01	-0.030
185.72	-7.04	-0.035
185.78	-7.08	-0.032
185.85	-7.11	-0.032
185.92	-7.15	-0.030
185.98	-7.18	-0.030
186.05	-7.21	-0.031
186.12	-7.25	-0.030
186.18	-7.28	-0.032
186.25	-7.31	-0.030
186.32	-7.34	-0.030
186.38	-7.38	-0.032
186.45	-7.41	-0.033
186.52	-7.44	-0.031
186.58	-7.48	-0.032
186.65	-7.51	-0.031
186.72	-7.54	-0.032
186.78	-7.58	-0.032
186.85	-7.61	-0.033
186.92	-7.64	-0.030
186.98	-7.68	-0.031
187.05	-7.71	-0.030
187.12	-7.74	-0.030
187.18	-7.78	-0.031
187.25	-7.81	-0.033
187.32	-7.84	-0.032
187.38	-7.88	-0.032
187.45	-7.91	-0.032
187.52	-7.94	-0.031
187.58	-7.98	-0.030
187.65	-8.01	-0.028
187.72	-8.04	-0.031
187.78	-8.08	-0.031
187.85	-8.11	-0.031
187.92	-8.14	-0.031
187.98	-8.18	-0.029
188.05	-8.21	-0.029
188.12	-8.24	-0.030
188.18	-8.28	-0.033
188.25	-8.31	-0.032
188.32	-8.35	-0.033
188.38	-8.38	-0.031
188.45	-8.41	-0.030
188.52	-8.44	-0.030
188.58	-8.48	-0.031
188.65	-8.51	-0.030
188.72	-8.54	-0.031
188.78	-8.58	-0.031
188.85	-8.61	-0.031
188.92	-8.65	-0.030
188.98	-8.68	-0.031
189.05	-8.71	-0.032
189.12	-8.74	-0.030
189.18	-8.78	-0.031
189.25	-8.81	-0.029
189.32	-8.85	-0.031
189.38	-8.88	-0.032
189.45	-8.91	-0.031
189.52	-8.95	-0.033
189.58	-8.98	-0.031
189.65	-9.01	-0.029
189.72	-9.04	-0.030
189.78	-9.08	-0.028
189.85	-9.11	-0.030
189.92	-9.15	-0.030
189.98	-9.18	-0.031
190.05	-9.21	-0.029
190.12	-9.25	-0.033
190.18	-9.28	-0.033
190.25	-9.31	-0.031
190.32	-9.34	-0.030
190.38	-9.38	-0.030
190.45	-9.41	-0.030
190.52	-9.44	-0.031
190.58	-9.48	-0.031
190.65	-9.51	-0.029
190.72	-9.55	-0.030
190.78	-9.58	-0.030
190.85	-9.61	-0.029
190.92	-9.64	-0.029
190.98	-9.68	-0.030
191.05	-9.71	-0.029
191.12	-9.74	-0.030
191.18	-9.78	-0.032
191.25	-9.81	-0.031
191.32	-9.84	-0.031
191.38	-9.88	-0.030
191.45	-9.91	-0.032
191.52	-9.94	-0.031
191.58	-9.98	-0.032
191.65	-10.01	-0.030
191.72	-10.05	-0.030
191.78	-10.08	-0.031
191.85	-10.11	-0.033
191.92	-10.14	-0.030
191.98	-10.18	-0.031
192.05	-10.21	-0.031
192.12	-10.24	-0.029
192.18	-10.28	-0.030
192.25	-10.31	-0.032
192.32	-10.34	-0.031
192.38	-10.38	-0.031
192.45	-10.41	-0.031
192.52	-10.44	-0.029
192.58	-10.48	-0.029
192.65	-10.51	-0.029
192.72	-10.54	-0.030
192.78	-10.58	-0.031
192.85	-10.61	-0.030
192.92	-10.64	-0.030
192.98	-10.68	-0.033
193.05	-10.71	-0.032
193.12	-10.74	-0.031
193.18	-10.78	-0.031
193.25	-10.81	-0.032
193.32	-10.84	-0.029
193.38	-10.88	-0.030
193.45	-10.91	-0.029
193.52	-10.94	-0.030
193.58	-10.98	-0.030
193.65	-11.01	-0.030
193.72	-11.04	-0.030
193.78	-11.08	-0.030
193.85	-11.11	-0.030
193.92	-11.14	-0.031
193.98	-11.18	-0.031
194.05	-11.21	-0.031
194.12	-11.24	-0.029
194.18	-11.28	-0.029
194.25	-11.31	-0.030
194.32	-11.35	-0.030
194.38	-11.38	-0.028
194.45	-11.41	-0.031
194.52	-11.44	-0.030
194.58	-11.48	-0.030
194.65	-11.51	-0.031
194.72	-11.54	-0.032
194.78	-11.58	-0.029
194.85	-11.61	-0.029
194.92	-11.64	-0.030
194.98	-11.68	-0.029
195.05	-11.71	-0.029
195.12	-11.74	-0.031
195.18	-11.78	-0.031
195.25	-11.81	-0.031
195.32	-11.84	-0.029
195.38	-11.88	-0.029
195.45	-11.91	-0.031
195.52	-11.94	-0.030
195.58	-11.98	-0.028
195.65	-12.01	-0.031
195.72	-12.04	-0.029
195.78	-12.08	-0.033
195.85	-12.11	-0.030
195.92	-12.14	-0.030
195.98	-12.18	-0.030
196.05	-12.21	-0.030
196.12	-12.24	-0.030
196.18	-12.28	-0.030
196.25	-12.31	-0.031
196.32	-12.34	-0.027
196.38	-12.38	-0.029
196.45	-12.41	-0.031
196.52	-12.44	-0.028
196.58	-12.48	-0.028
196.65	-12.51	-0.029
196.72	-12.55	-0.029
196.78	-12.58	-0.030
196.85	-12.61	-0.028
196.92	-12.64	-0.030
196.98	-12.68	-0.031
197.05	-12.71	-0.030
197.12	-12.74	-0.030
197.18	-12.78	-0.030
197.25	-12.81	-0.030
197.32	-12.85	-0.030
197.38	-12.88	-0.030
197.45	-12.91	-0.029
197.52	-12.95	-0.029
197.58	-12.98	-0.026
197.65	-13.01	-0.029
197.72	-13.05	-0.028
197.78	-13.08	-0.033
197.85	-13.11	-0.030
197.92	-13.14	-0.030
197.98	-13.18	-0.030
198.05	-13.21	-0.030
198.12	-13.24	-0.030
198.18	-13.28	-0.030
198.25	-13.31	-0.028
198.32	-13.34	-0.028
198.38	-13.38	-0.027
198.45	-13.41	-0.028
198.52	-13.44	-0.029
198.58	-13.48	-0.030
198.65	-13.51	-0.028
198.72	-13.54	-0.029
198.78	-13.58	-0.028
198.85	-13.61	-0.030
198.92	-13.64	-0.029
198.98	-13.68	-0.029
199.05	-13.71	-0.029
199.12	-13.74	-0.031
199.18	-13.78	-0.028
199.25	-13.81	-0.028
199.32	-13.84	-0.031
199.38	-13.88	-0.030
199.45	-13.91	-0.028
199.52	-13.95	-0.029
199.58	-13.98	-0.031
199.65	-14.01	-0.029
199.72	-14.04	-0.029
199.78	-14.08	-0.029
199.85	-14.11	-0.030
199.92	-14.15	-0.029
199.98	-14.18	-0.028
200.05	-14.21	-0.029
200.12	-14.24	-0.028
200.18	-14.28	-0.028
200.25	-14.31	-0.028
200.32	-14.34	-0.029
200.38	-14.38	-0.031
200.45	-14.41	-0.031
200.52	-14.44	-0.030
200.58	-14.48	-0.031
200.65	-14.51	-0.028
200.72	-14.54	-0.031
200.78	-14.58	-0.029
200.85	-14.61	-0.028
200.92	-14.64	-0.029
200.98	-14.68	-0.030
201.05	-14.71	-0.031
201.12	-14.74	-0.030
201.18	-14.78	-0.029
201.25	-14.81	-0.030
201.32	-14.85	-0.029
201.38	-14.88	-0.030
201.45	-14.91	-0.027
201.52	-14.94	-0.028
201.58	-14.98	-0.030
201.65	-15.01	-0.030
201.72	-15.05	-0.030
201.78	-15.08	-0.030
201.85	-15.11	-0.031
201.92	-15.14	-0.031
201.98	-15.18	-0.030
202.05	-15.21	-0.031
202.12	-15.24	-0.028
202.18	-15.28	-0.028
202.25	-15.31	-0.028
202.32	-15.34	-0.028
202.38	-15.38	-0.028
202.45	-15.41	-0.028
202.52	-15.44	-0.029
202.58	-15.48	-0.029
202.65	-15.51	-0.029
202.72	-15.54	-0.028
202.78	-15.58	-0.028
202.85	-15.61	-0.027
202.92	-15.64	-0.028
202.98	-15.68	-0.028
203.05	-15.71	-0.028
203.12	-15.74	-0.028
203.18	-15.78	-0.029
203.25	-15.81	-0.033
203.32	-15.84	-0.029
203.38	-15.88	-0.025
203.45	-15.91	-0.028
203.52	-15.94	-0.028
203.58	-15.98	-0.029
203.65	-16.01	-0.028
203.72	-16.05	-0.028
203.78	-16.08	-0.029
203.85	-16.11	-0.028
203.92	-16.14	-0.029
203.98	-16.18	-0.030
204.05	-16.21	-0.026
204.12	-16.24	-0.026
204.18	-16.28	-0.028
204.25	-16.31	-0.028
204.32	-16.34	-0.028
204.38	-16.38	-0.028
204.45	-16.41	-0.027
204.52	-16.44	-0.028
204.58	-16.48	-0.028
204.65	-16.51	-0.027
204.72	-16.54	-0.028
204.78	-16.58	-0.027
204.85	-16.61	-0.029
204.92	-16.64	-0.029
204.98	-16.68	-0.028
205.05	-16.71	-0.029
205.12	-16.75	-0.028
205.18	-16.78	-0.029
205.25	-16.81	-0.029
205.32	-16.84	-0.027
205.38	-16.88	-0.028
205.45	-16.91	-0.028
205.52	-16.94	-0.028
205.58	-16.98	-0.028
205.65	-17.01	-0.028
205.72	-17.05	-0.031
205.78	-17.08	-0.029
205.85	-17.11	-0.028
205.92	-17.14	-0.028
205.98	-17.18	-0.027
206.05	-17.21	-0.028
206.12	-17.24	-0.027
206.18	-17.28	-0.027
206.25	-17.31	-0.026
206.32	-17.34	-0.027
206.38	-17.38	-0.029
206.45	-17.41	-0.029
206.52	-17.45	-0.028
206.58	-17.48	-0.028
206.65	-17.51	-0.028
206.72	-17.54	-0.028
206.78	-17.58	-0.029
206.85	-17.61	-0.027
206.92	-17.64	-0.027
206.98	-17.68	-0.027
207.05	-17.71	-0.027
207.12	-17.74	-0.027
207.18	-17.78	-0.027
207.25	-17.81	-0.029
207.32	-17.84	-0.026
207.38	-17.88	-0.026
207.45	-17.91	-0.027
207.52	-17.94	-0.027
207.58	-17.98	-0.027
207.65	-18.01	-0.029
207.72	-18.05	-0.030
207.78	-18.08	-0.027
207.85	-18.11	-0.027
207.92	-18.14	-0.027
207.98	-18.18	-0.026
208.05	-18.21	-0.027
208.12	-18.25	-0.027
208.18	-18.28	-0.028
208.25	-18.31	-0.027
208.32	-18.34	-0.026
208.38	-18.38	-0.026
208.45	-18.41	-0.026
208.52	-18.45	-0.028
208.58	-18.48	-0.028
208.65	-18.51	-0.027
208.72	-18.54	-0.027
208.78	-18.58	-0.026
208.85	-18.61	-0.030
208.92	-18.65	-0.028
208.98	-18.68	-0.028
209.05	-18.71	-0.029
209.12	-18.74	-0.028
209.18	-18.78	-0.027
209.25	-18.81	-0.025
209.32	-18.84	-0.026
209.38	-18.88	-0.025
209.45	-18.91	-0.024
209.52	-18.94	-0.026
209.58	-18.98	-0.029
209.65	-19.01	-0.027
209.72	-19.04	-0.027
209.78	-19.08	-0.026
209.85	-19.11	-0.028
209.92	-19.14	-0.028
209.98	-19.18	-0.028
210.05	-19.21	-0.025
210.12	-19.24	-0.026
210.18	-19.28	-0.026
210.25	-19.31	-0.026
210.32	-19.35	-0.026
210.38	-19.38	-0.028
210.45	-19.41	-0.027
210.52	-19.44	-0.026
210.58	-19.48	-0.026
210.65	-19.51	-0.026
210.72	-19.54	-0.026
210.78	-19.58	-0.030
210.85	-19.61	-0.027
210.92	-19.64	-0.027
210.98	-19.68	-0.029
211.05	-19.71	-0.024
211.12	-19.74	-0.026
211.18	-19.78	-0.027
211.25	-19.81	-0.027
211.32	-19.84	-0.025
211.38	-19.88	-0.025
211.45	-19.91	-0.025
211.52	-19.95	-0.025
211.58	-19.98	-0.027
211.65	-20.01	-0.025
211.72	-20.04	-0.026
211.78	-20.08	-0.026
211.85	-20.11	-0.026
211.92	-20.14	-0.025
211.98	-20.18	-0.025
212.05	-20.21	-0.028
212.12	-20.24	-0.027
212.18	-20.28	-0.025
212.25	-20.31	-0.026
212.32	-20.34	-0.024
212.38	-20.38	-0.032
212.45	-20.41	-0.028
212.52	-20.45	-0.025
212.58	-20.48	-0.027
212.65	-20.51	-0.026
212.72	-20.54	-0.024
212.78	-20.58	-0.025
212.85	-20.61	-0.025
212.92	-20.64	-0.025
212.98	-20.68	-0.024
213.05	-20.71	-0.025
213.12	-20.74	-0.025
213.18	-20.78	-0.026
213.25	-20.81	-0.022
213.32	-20.84	-0.026
213.38	-20.88	-0.024
213.45	-20.91	-0.023
213.52	-20.94	-0.028
213.58	-20.98	-0.027
213.65	-21.01	-0.026
213.72	-21.04	-0.025
213.78	-21.08	-0.022
213.85	-21.11	-0.024
213.92	-21.14	-0.025
213.98	-21.18	-0.023
214.05	-21.21	-0.026
214.12	-21.25	-0.025
214.18	-21.28	-0.024
214.25	-21.31	-0.023
214.32	-21.34	-0.024
214.38	-21.38	-0.024
214.45	-21.41	-0.025
214.52	-21.45	-0.025
214.58	-21.48	-0.024
214.65	-21.51	-0.026
214.72	-21.55	-0.024
214.78	-21.58	-0.024
214.85	-21.61	-0.024
214.92	-21.64	-0.025
214.98	-21.68	-0.024
215.05	-21.71	-0.024
215.12	-21.74	-0.025
215.18	-21.78	-0.024
215.25	-21.81	-0.024
215.32	-21.84	-0.024
215.38	-21.88	-0.024
215.45	-21.91	-0.024
215.52	-21.94	-0.026
215.58	-21.98	-0.023
215.65	-22.01	-0.024
215.72	-22.04	-0.025
215.78	-22.08	-0.023
215.85	-22.11	-0.025
215.92	-22.14	-0.025
215.98	-22.18	-0.025
216.05	-22.21	-0.023
216.12	-22.24	-0.022
216.18	-22.28	-0.023
216.25	-22.31	-0.024
216.32	-22.34	-0.024
216.38	-22.38	-0.024
216.45	-22.41	-0.024
216.52	-22.45	-0.023
216.58	-22.48	-0.025
216.65	-22.51	-0.024
216.72	-22.55	-0.023
216.78	-22.58	-0.023
216.85	-22.61	-0.025
216.92	-22.65	-0.024
216.98	-22.68	-0.022
217.05	-22.71	-0.023
217.12	-22.75	-0.023
217.18	-22.78	-0.022
217.25	-22.81	-0.023
217.32	-22.85	-0.023
217.38	-22.88	-0.021
217.45	-22.91	-0.023
217.52	-22.95	-0.025
217.58	-22.98	-0.024
217.65	-23.01	-0.024
217.72	-23.05	-0.025
217.78	-23.08	-0.022
217.85	-23.11	-0.023
217.92	-23.14	-0.023
217.98	-23.18	-0.022
218.05	-23.21	-0.025
218.12	-23.24	-0.024
218.18	-23.28	-0.024
218.25	-23.31	-0.021
218.32	-23.34	-0.022
218.38	-23.38	-0.022
218.45	-23.41	-0.022
218.52	-23.44	-0.023
218.58	-23.48	-0.021
218.65	-23.51	-0.023
218.72	-23.55	-0.024
218.78	-23.58	-0.023
218.85	-23.61	-0.022
218.92	-23.64	-0.023
218.98	-23.68	-0.023
219.05	-23.71	-0.022
219.12	-23.75	-0.023
219.18	-23.78	-0.022
219.25	-23.81	-0.023
219.32	-23.85	-0.022
219.38	-23.88	-0.023
219.45	-23.91	-0.023
219.52	-23.95	-0.023
219.58	-23.98	-0.023
219.65	-24.01	-0.023
219.72	-24.05	-0.023
219.78	-24.08	-0.022
219.85	-24.11	-0.022
219.92	-24.15	-0.021
219.98	-24.18	-0.024
220.05	-24.21	-0.023
220.12	-24.24	-0.023
220.18	-24.28	-0.024
220.25	-24.31	-0.021
220.32	-24.35	-0.022
220.38	-24.38	-0.024
220.45	-24.41	-0.026
220.52	-24.44	-0.024
220.58	-24.48	-0.024
220.65	-24.51	-0.024
220.72	-24.54	-0.023
220.78	-24.58	-0.020
220.85	-24.61	-0.023
220.92	-24.64	-0.022
220.98	-24.68	-0.022
221.05	-24.71	-0.022
221.12	-24.74	-0.020
221.18	-24.78	-0.023
221.25	-24.81	-0.023
221.32	-24.84	-0.022
221.38	-24.88	-0.023
221.45	-24.91	-0.022
221.52	-24.95	-0.022
221.58	-24.98	-0.022
221.65	-25.01	-0.022
221.72	-25.05	-0.024
221.78	-25.08	-0.019
221.85	-25.11	-0.021
221.92	-25.14	-0.021
221.98	-25.18	-0.021
222.05	-25.21	-0.021
222.12	-25.24	-0.022
222.18	-25.28	-0.022
222.25	-25.31	-0.022
222.32	-25.35	-0.024
222.38	-25.38	-0.022
222.45	-25.41	-0.023
222.52	-25.45	-0.022
222.58	-25.48	-0.023
222.65	-25.51	-0.022
222.72	-25.54	-0.022
222.78	-25.58	-0.023
222.85	-25.61	-0.023
222.92	-25.65	-0.023
222.98	-25.68	-0.021
223.05	-25.71	-0.021
223.12	-25.74	-0.021
223.18	-25.78	-0.021
223.25	-25.81	-0.023
223.32	-25.84	-0.023
223.38	-25.88	-0.022
223.45	-25.91	-0.022
223.52	-25.95	-0.021
223.58	-25.98	-0.021
223.65	-26.01	-0.022
223.72	-26.04	-0.023
223.78	-26.08	-0.021
223.85	-26.11	-0.027
223.92	-26.14	-0.022
223.98	-26.18	-0.023
224.05	-26.21	-0.021
224.12	-26.25	-0.021
224.18	-26.28	-0.020
224.25	-26.31	-0.020
224.32	-26.34	-0.022
224.38	-26.38	-0.021
224.45	-26.41	-0.020
224.52	-26.45	-0.022
224.58	-26.48	-0.021
224.65	-26.51	-0.021
224.72	-26.55	-0.021
224.78	-26.58	-0.020
224.85	-26.61	-0.022
224.92	-26.65	-0.022
224.98	-26.68	-0.019
225.05	-26.71	-0.021
225.12	-26.75	-0.021
225.18	-26.78	-0.023
225.25	-26.81	-0.021
225.32	-26.85	-0.022
225.38	-26.88	-0.021
225.45	-26.91	-0.021
225.52	-26.94	-0.022
225.58	-26.98	-0.021
225.65	-27.01	-0.021
225.72	-27.05	-0.021
225.78	-27.08	-0.023
225.85	-27.11	-0.022
225.92	-27.14	-0.022
225.98	-27.18	-0.021
226.05	-27.21	-0.020
226.12	-27.24	-0.022
226.18	-27.28	-0.023
226.25	-27.31	-0.022
226.32	-27.34	-0.020
226.38	-27.38	-0.022
226.45	-27.41	-0.022
226.52	-27.44	-0.020
226.58	-27.48	-0.021
226.65	-27.51	-0.020
226.72	-27.55	-0.021
226.78	-27.58	-0.018
226.85	-27.61	-0.021
226.92	-27.65	-0.022
226.98	-27.68	-0.021
227.05	-27.71	-0.022
227.12	-27.74	-0.020
227.18	-27.78	-0.017
227.25	-27.81	-0.018
227.32	-27.84	-0.020
227.38	-27.88	-0.021
227.45	-27.91	-0.018
227.52	-27.95	-0.020
227.58	-27.98	-0.020
227.65	-28.01	-0.020
227.72	-28.05	-0.019
227.78	-28.08	-0.020
227.85	-28.11	-0.020
227.92	-28.15	-0.019
227.98	-28.18	-0.020
228.05	-28.21	-0.020
228.12	-28.24	-0.020
228.18	-28.28	-0.018
228.25	-28.31	-0.022
228.32	-28.35	-0.019
228.38	-28.38	-0.020
228.45	-28.41	-0.021
228.52	-28.45	-0.021
228.58	-28.48	-0.021
228.65	-28.51	-0.020
228.72	-28.54	-0.020
228.78	-28.58	-0.020
228.85	-28.61	-0.021
228.92	-28.65	-0.018
228.98	-28.68	-0.020
229.05	-28.71	-0.018
229.12	-28.74	-0.018
229.18	-28.78	-0.019
229.25	-28.81	-0.021
229.32	-28.84	-0.021
229.38	-28.88	-0.021
229.45	-28.91	-0.020
229.52	-28.95	-0.021
229.58	-28.98	-0.020
229.65	-29.01	-0.021
229.72	-29.05	-0.021
229.78	-29.08	-0.021
229.85	-29.11	-0.021
229.92	-29.15	-0.021
229.98	-29.18	-0.020
230.05	-29.21	-0.017
230.12	-29.24	-0.019
230.18	-29.28	-0.021
230.25	-29.31	-0.023
230.32	-29.34	-0.019
230.38	-29.38	-0.023
230.45	-29.41	-0.019
230.52	-29.44	-0.019
230.58	-29.48	-0.021
230.65	-29.51	-0.022
230.72	-29.54	-0.020
230.78	-29.58	-0.020
230.85	-29.61	-0.019
230.92	-29.64	-0.019
230.98	-29.68	-0.020
231.05	-29.71	-0.021
231.12	-29.75	-0.018
231.18	-29.78	-0.018
231.25	-29.81	-0.019
231.32	-29.84	-0.020
231.38	-29.88	-0.019
231.45	-29.91	-0.020
231.52	-29.95	-0.020
231.58	-29.98	-0.021
231.65	-30.01	-0.021
231.72	-30.04	-0.020
231.78	-30.08	-0.019
231.85	-30.11	-0.020
231.92	-30.14	-0.020
231.98	-30.18	-0.020
232.05	-30.21	-0.020
232.12	-30.24	-0.020
232.18	-30.28	-0.020
232.25	-30.31	-0.019
232.31