File: DSC/2023_08_04_OTP_fragility_SBK.txt
Filename	2023_08_04_OTP_fragility_SBK
Instrument name	DSC2A-00468 (192.168.1.100)
Operator	SBK
rundate	8/4/2023
Sample name	2023_08_04_OTP_fragility_SBK
proceduresegments	Data Off ; Equilibrate -85.00 °C; Data On ; Ramp 10.00 °C/min to 75.00 °C; Ramp 40.00 °C/min to 5.00 °C; Ramp 10.00 °C/min to -85.00 °C; Data Off ; Isothermal 1.0 min; Data On ; Ramp 10.00 °C/min to 5.00 °C; Data Off ; Isothermal 1.0 min; Data On ; Ramp 10.00 °C/min to -85.00 °C; Data Off ; Isothermal 1.0 min; Data On ; Ramp 10.00 °C/min to 5.00 °C; Data Off ; Isothermal 1.0 min; Data On ; Ramp 10.00 °C/min to -85.00 °C; Data Off ; Isothermal 1.0 min; Data On ; Ramp 10.00 °C/min to 5.00 °C; Data Off ; Isothermal 1.0 min; Data On ; Ramp 40.00 °C/min to -85.00 °C; Data Off ; Isothermal 15.0 min; Data On ; Ramp 10.00 °C/min to 5.00 °C; Data Off ; Isothermal 1.0 min; Data On ; Ramp 10.00 °C/min to -85.00 °C; Data Off ; Isothermal 1.0 min; Data On ; Ramp 30.00 °C/min to -85.00 °C; Data Off ; Isothermal 10.0 min; Data On ; Ramp 10.00 °C/min to 5.00 °C; Data Off ; Isothermal 1.0 min; Data On ; Ramp 20.00 °C/min to -85.00 °C; Data Off ; Isothermal 10.0 min; Data On ; Ramp 10.00 °C/min to 5.00 °C; Data Off ; Isothermal 1.0 min; Data On ; Ramp 5.00 °C/min to -85.00 °C; Data Off ; Isothermal 1.0 min; Data On ; Ramp 10.00 °C/min to 5.00 °C; Data Off ; Isothermal 1.0 min; Data On ; Sample Interval  1.0 s/pt; Ramp 1.00 °C/min to -85.00 °C; Data Off ; Isothermal 1.0 min; Data On ; Sample Interval  0.1 s/pt; Ramp 10.00 °C/min to 5.00 °C; Data Off ; Isothermal 1.0 min; Data On ; Sample Interval  1.0 s/pt; Ramp 0.50 °C/min to -85.00 °C; Data Off ; Isothermal 1.0 min; Sample Interval  0.1 s/pt; Data On ; Ramp 10.00 °C/min to 5.00 °C; Data Off ; Isothermal 1.0 min; Data On ; Ramp 10.00 °C/min to -85.00 °C; Data Off ; Isothermal 1.0 min; Data On ; Ramp 10.00 °C/min to 5.00 °C; Data Off ; Equilibrate 20.00 °C; Isothermal 5000.0 min
[File Parameters]
Run date	8/4/2023 3:22:53 PM
Trios version	5.1.1.46572
Original File Name	C:\Users\yargerlab\Desktop\DSC Data\General\2023_08_04_OTP_fragility_SBK.tri
Current File Name	C:\Users\kauff\Documents\ASU\data_DSC\2023_08_04_OTP_fragility_SBK.tri
[Procedure]
Procedure Name	OTP fragility
Sample Name	2023_08_04_OTP_fragility_SBK
Sample Mass	6.19 mg
Reference Sample Mass	0 mg
Pan Mass	53.55 mg
Pan Number	15
Reference Pan Mass	53.66 mg
Reference Pan Number	46
Pan Type	Aluminum Hermetic
Comments	DSC84010 al pan, DSC84011 al herm lid. New sample of o-terphenyl for fragility testing.
Project Name	Silk ASDs
Operator	SBK
Test	Custom
Unload Max Temperature	30
Unload Min Temperature	30
Load Max Temperature	30
Load Min Temperature	30
Stop on Gas Flow Error	Yes
[Signal List]
Signal #1	Time (min)
Signal #2	Temperature (°C)
Signal #3	Heat Flow (mW)
Signal #4	Delta T (µV)
Signal #5	Delta Tzero (µV)
Signal #6	Tzero Temperature (°C)
Signal #7	Cell Purge (mL/min)
Signal #8	Heater Temp (°C)
Signal #9	Power Delivered (W)
Signal #10	Reference Junction Temperature (°C)
Signal #11	Flange Temperature (°C)
Signal #12	Heat Flow Phase (rad)
Signal #13	Total Heat Capacity (J/°C)
Signal #14	Heat Capacity (J/°C)
[Configuration]
Company Name	ASU
Instrument Name	DSC2A-00468
Instrument Type	DSC2500
Serial Number	DSC2A-00468
IP	192.168.1.100
Location of Instrument	MRRC
DisplayType	Unknown
Sample Interval 	0.1 s/pt
Selected Heat Flow	T4P
Exotherm Direction	Down
Cell Serial	DRC2-00792
Lid Type	Standard
Cooler	RCS 90
Leave Cooler on at End of Sequence	On
Gas 2	Nitrogen
Gas Selected	Channel 1
Flow Rate	50 mL/min
Secondary Purge	On
Licensed Heat Flow	Heat Flow T4P
Modulation Licensed	Yes
[Versions]
Common IDD Version	1
Cortex Version	VER 2.10.2.31
Driver	5.0.0.6
GDM Version	1.0.3.3
TouchscreenVersion	1.0.0.16145
FEP Version	1.2.1.21
FEP Bootloader	2.0.0.5
AutoSampler Version	2.1.1.26
Auto Sampler Bootloader	2.0.0.5
FCM Version	1.1.0.3
FCM Bootloader	2.0.0.5
[Experiment Logs]
Experiment Log Entry # 1	Data On set to 0
Experiment Log Entry # 3	Equilibrate Segment -85 (C) Started
Experiment Log Entry # 5	Air Cool is off.
Experiment Log Entry # 7	Data On set to 1
Experiment Log Entry # 9	Ramp Segment 10 C/min to 75 Started
Experiment Log Entry # 11	Ramp Segment 40 C/min to 5 Started
Experiment Log Entry # 13	Ramp Segment 10 C/min to -85 Started
Experiment Log Entry # 15	Data On set to 0
Experiment Log Entry # 17	Isothermal Segment 1 min started
Experiment Log Entry # 19	Data On set to 1
Experiment Log Entry # 21	Ramp Segment 10 C/min to 5 Started
Experiment Log Entry # 23	Data On set to 0
Experiment Log Entry # 25	Isothermal Segment 1 min started
Experiment Log Entry # 27	Data On set to 1
Experiment Log Entry # 29	Ramp Segment 10 C/min to -85 Started
Experiment Log Entry # 31	Data On set to 0
Experiment Log Entry # 33	Isothermal Segment 1 min started
Experiment Log Entry # 35	Data On set to 1
Experiment Log Entry # 37	Ramp Segment 10 C/min to 5 Started
Experiment Log Entry # 39	Data On set to 0
Experiment Log Entry # 41	Isothermal Segment 1 min started
Experiment Log Entry # 43	Data On set to 1
Experiment Log Entry # 45	Ramp Segment 10 C/min to -85 Started
Experiment Log Entry # 47	Data On set to 0
Experiment Log Entry # 49	Isothermal Segment 1 min started
Experiment Log Entry # 51	Data On set to 1
Experiment Log Entry # 53	Ramp Segment 10 C/min to 5 Started
Experiment Log Entry # 55	Data On set to 0
Experiment Log Entry # 57	Isothermal Segment 1 min started
Experiment Log Entry # 59	Data On set to 1
Experiment Log Entry # 61	Ramp Segment 40 C/min to -85 Started
Experiment Log Entry # 63	Data On set to 0
Experiment Log Entry # 65	Isothermal Segment 15 min started
Experiment Log Entry # 67	Data On set to 1
Experiment Log Entry # 69	Ramp Segment 10 C/min to 5 Started
Experiment Log Entry # 71	Data On set to 0
Experiment Log Entry # 73	Isothermal Segment 1 min started
Experiment Log Entry # 75	Data On set to 1
Experiment Log Entry # 77	Ramp Segment 10 C/min to -85 Started
Experiment Log Entry # 79	Data On set to 0
Experiment Log Entry # 81	Isothermal Segment 1 min started
Experiment Log Entry # 83	Data On set to 1
Experiment Log Entry # 85	Ramp Segment 30 C/min to -85 Started
Experiment Log Entry # 87	Data On set to 0
Experiment Log Entry # 89	Isothermal Segment 10 min started
Experiment Log Entry # 91	Data On set to 1
Experiment Log Entry # 93	Ramp Segment 10 C/min to 5 Started
Experiment Log Entry # 95	Data On set to 0
Experiment Log Entry # 97	Isothermal Segment 1 min started
Experiment Log Entry # 99	Data On set to 1
Experiment Log Entry # 101	Ramp Segment 20 C/min to -85 Started
Experiment Log Entry # 103	Data On set to 0
Experiment Log Entry # 105	Isothermal Segment 10 min started
Experiment Log Entry # 107	Data On set to 1
Experiment Log Entry # 109	Ramp Segment 10 C/min to 5 Started
Experiment Log Entry # 111	Data On set to 0
Experiment Log Entry # 113	Isothermal Segment 1 min started
Experiment Log Entry # 115	Data On set to 1
Experiment Log Entry # 117	Ramp Segment 5 C/min to -85 Started
Experiment Log Entry # 119	Data On set to 0
Experiment Log Entry # 121	Isothermal Segment 1 min started
Experiment Log Entry # 123	Data On set to 1
Experiment Log Entry # 125	Ramp Segment 10 C/min to 5 Started
Experiment Log Entry # 127	Data On set to 0
Experiment Log Entry # 129	Isothermal Segment 1 min started
Experiment Log Entry # 131	Data On set to 1
Experiment Log Entry # 133	Sampling Rate set to 1 sec/pt
Experiment Log Entry # 135	Ramp Segment 1 C/min to -85 Started
Experiment Log Entry # 137	Auto sampler has detected that FEP has gone offline
Experiment Log Entry # 139	Data On set to 0
Experiment Log Entry # 141	Isothermal Segment 1 min started
Experiment Log Entry # 143	Data On set to 1
Experiment Log Entry # 145	Sampling Rate set to 0.1 sec/pt
Experiment Log Entry # 147	Ramp Segment 10 C/min to 5 Started
Experiment Log Entry # 149	Data On set to 0
Experiment Log Entry # 151	Isothermal Segment 1 min started
Experiment Log Entry # 153	Data On set to 1
Experiment Log Entry # 155	Sampling Rate set to 1 sec/pt
Experiment Log Entry # 157	Ramp Segment 0.5 C/min to -85 Started
Experiment Log Entry # 159	Data On set to 0
Experiment Log Entry # 161	Isothermal Segment 1 min started
Experiment Log Entry # 163	Sampling Rate set to 0.1 sec/pt
Experiment Log Entry # 165	Data On set to 1
Experiment Log Entry # 167	Ramp Segment 10 C/min to 5 Started
Experiment Log Entry # 169	Data On set to 0
Experiment Log Entry # 171	Isothermal Segment 1 min started
Experiment Log Entry # 173	Data On set to 1
Experiment Log Entry # 175	Ramp Segment 10 C/min to -85 Started
Experiment Log Entry # 177	Data On set to 0
Experiment Log Entry # 179	Isothermal Segment 1 min started
Experiment Log Entry # 181	Data On set to 1
Experiment Log Entry # 183	Ramp Segment 10 C/min to 5 Started
Experiment Log Entry # 185	Data On set to 0
Experiment Log Entry # 187	Equilibrate Segment 20 (C) Started
Experiment Log Entry # 189	Isothermal Segment 5000 min started
Experiment Log Entry # 191	FEP has detected that FCM has gone offline
Experiment Log Entry # 193	Auto sampler has detected that GDM has gone offline
Experiment Log Entry # 195	Auto sampler has detected that FEP has gone offline
Experiment Log Entry # 197	Auto sampler has detected that Cortex has gone offline
Experiment Log Entry # 199	Auto sampler has detected that GDM has gone offline
Experiment Log Entry # 201	Ending Experiment because user stopped
[Method Log]
Method Log Entry # 1	Data Off
Method Log Entry # 2	Equilibrate -85 °C
Method Log Entry # 3	Data On
Method Log Entry # 4	(Ramp 11945) Ramp 10 °C/minute to 75 °C
Method Log Entry # 5	(Ramp 11946) Ramp 40 °C/minute to 5 °C
Method Log Entry # 6	(Ramp 11947) Ramp 10 °C/minute to -85 °C
Method Log Entry # 7	Data Off
Method Log Entry # 8	Isothermal 1 minutes
Method Log Entry # 9	Data On
Method Log Entry # 10	(Ramp 11951) Ramp 10 °C/minute to 5 °C
Method Log Entry # 11	Data Off
Method Log Entry # 12	Isothermal 1 minutes
Method Log Entry # 13	Data On
Method Log Entry # 14	(Ramp 11955) Ramp 10 °C/minute to -85 °C
Method Log Entry # 15	Data Off
Method Log Entry # 16	Isothermal 1 minutes
Method Log Entry # 17	Data On
Method Log Entry # 18	(Ramp 11959) Ramp 10 °C/minute to 5 °C
Method Log Entry # 19	Data Off
Method Log Entry # 20	Isothermal 1 minutes
Method Log Entry # 21	Data On
Method Log Entry # 22	(Ramp 11963) Ramp 10 °C/minute to -85 °C
Method Log Entry # 23	Data Off
Method Log Entry # 24	Isothermal 1 minutes
Method Log Entry # 25	Data On
Method Log Entry # 26	(Ramp 11967) Ramp 10 °C/minute to 5 °C
Method Log Entry # 27	Data Off
Method Log Entry # 28	Isothermal 1 minutes
Method Log Entry # 29	Data On
Method Log Entry # 30	(Ramp 11971) Ramp 40 °C/minute to -85 °C
Method Log Entry # 31	Data Off
Method Log Entry # 32	Isothermal 15 minutes
Method Log Entry # 33	Data On
Method Log Entry # 34	(Ramp 11975) Ramp 10 °C/minute to 5 °C
Method Log Entry # 35	Data Off
Method Log Entry # 36	Isothermal 1 minutes
Method Log Entry # 37	Data On
Method Log Entry # 38	(Ramp 11979) Ramp 10 °C/minute to -85 °C
Method Log Entry # 39	Data Off
Method Log Entry # 40	Isothermal 1 minutes
Method Log Entry # 41	Data On
Method Log Entry # 42	(Ramp 11983) Ramp 30 °C/minute to -85 °C
Method Log Entry # 43	Data Off
Method Log Entry # 44	Isothermal 10 minutes
Method Log Entry # 45	Data On
Method Log Entry # 46	(Ramp 11987) Ramp 10 °C/minute to 5 °C
Method Log Entry # 47	Data Off
Method Log Entry # 48	Isothermal 1 minutes
Method Log Entry # 49	Data On
Method Log Entry # 50	(Ramp 11991) Ramp 20 °C/minute to -85 °C
Method Log Entry # 51	Data Off
Method Log Entry # 52	Isothermal 10 minutes
Method Log Entry # 53	Data On
Method Log Entry # 54	(Ramp 11995) Ramp 10 °C/minute to 5 °C
Method Log Entry # 55	Data Off
Method Log Entry # 56	Isothermal 1 minutes
Method Log Entry # 57	Data On
Method Log Entry # 58	(Ramp 11999) Ramp 5 °C/minute to -85 °C
Method Log Entry # 59	Data Off
Method Log Entry # 60	Isothermal 1 minutes
Method Log Entry # 61	Data On
Method Log Entry # 62	(Ramp 12003) Ramp 10 °C/minute to 5 °C
Method Log Entry # 63	Data Off
Method Log Entry # 64	Isothermal 1 minutes
Method Log Entry # 65	Data On
Method Log Entry # 66	Sampling Interval 1 Seconds/point
Method Log Entry # 67	(Ramp 12008) Ramp 1 °C/minute to -85 °C
Method Log Entry # 68	Data Off
Method Log Entry # 69	Isothermal 1 minutes
Method Log Entry # 70	Data On
Method Log Entry # 71	Sampling Interval 0.1 Seconds/point
Method Log Entry # 72	(Ramp 12013) Ramp 10 °C/minute to 5 °C
Method Log Entry # 73	Data Off
Method Log Entry # 74	Isothermal 1 minutes
Method Log Entry # 75	Data On
Method Log Entry # 76	Sampling Interval 1 Seconds/point
Method Log Entry # 77	(Ramp 12018) Ramp 0.5 °C/minute to -85 °C
Method Log Entry # 78	Data Off
Method Log Entry # 79	Isothermal 1 minutes
Method Log Entry # 80	Sampling Interval 0.1 Seconds/point
Method Log Entry # 81	Data On
Method Log Entry # 82	(Ramp 12023) Ramp 10 °C/minute to 5 °C
Method Log Entry # 83	Data Off
Method Log Entry # 84	Isothermal 1 minutes
Method Log Entry # 85	Data On
Method Log Entry # 86	(Ramp 12027) Ramp 10 °C/minute to -85 °C
Method Log Entry # 87	Data Off
Method Log Entry # 88	Isothermal 1 minutes
Method Log Entry # 89	Data On
Method Log Entry # 90	(Ramp 12031) Ramp 10 °C/minute to 5 °C
Method Log Entry # 91	Data Off
Method Log Entry # 92	Equilibrate 20 °C
Method Log Entry # 93	Isothermal 5000 minutes
Cell Serial	DRC2-00792
[T1 Calibration]
Slope	-0.008529666
Offset	9.636258
Initial Temperature	98.23
GUID	f8bfdadc-4977-4fdf-ba6d-0ba9134940c3
[TZero Calibration]
Date Applied	11/29/2022 4:06:13 PM
Description	From -89.059 °C to 396.009 °C at 20.000°C/min
Gas Type	Nitrogen
Pan Type	None
Source Files 1	C:\Users\yargerlab\Desktop\DSC Data\General\TZero_calibration_11_29_22_2nd(2).tri
Source Files 2	C:\Users\yargerlab\Desktop\DSC Data\General\TZero_calibration_11_29_22_2nd(3).tri
Delta T Offset	13.05235
Delta T Slope	-0.007271007
Delta T0 Offset	-13.69128
Delta T0 Slope	0.06063341
[Temperature Calibration]
Date Applied	11/29/2022 7:12:28 PM
Description	From 106.590 °C to 186.590 °C at 10.000°C/min
Gas Type	Nitrogen
Pan Type	Tzero Aluminum Hermetic
Source Files 1	C:\Users\yargerlab\Desktop\DSC Data\General\Indium(6).tri
Measured 1	157.391
Known 1	156.598
[Cell Constant Calibration]
Date Applied	11/29/2022 7:12:29 PM
Description	From 106.590 °C to 186.590 °C at 10.000°C/min
Gas Type	Nitrogen
Pan Type	Tzero Aluminum Hermetic
Source Files 1	C:\Users\yargerlab\Desktop\DSC Data\General\Indium(6).tri
T4P KCell	1.006051
Onset Slope	63.26126 mW/°C
[Direct Cp Calibration]
Date Applied	11/30/2022 11:04:51 AM
Description	From -79.983 °C to 298.409 °C at 10.000°C/min
Gas Type	Nitrogen
Pan Type	Tzero Aluminum Hermetic
Source Files 1	C:\Users\yargerlab\Desktop\DSC Data\General\Sapphire_Heat_Capacity_11_30_22.tri
[Rev Cp Calibration]
Date Applied	11/30/2022 1:58:51 PM
Description	From -79.996 °C to 292.812 °C at 3.000°C/min
Gas Type	Nitrogen
Pan Type	Tzero Aluminum Hermetic
Source Files 1	C:\Users\yargerlab\Desktop\DSC Data\General\Sapphire_MDSC_Calibration_11_30_22.tri
[step]
Ramp 10.00 °C/min to 75.00 °C
Time	Temperature	Heat Flow (Normalized)	Heat Capacity (Normalized)
min	°C	W/g	J/(g.°C)
0.00	-84.74	-0.011	0.000
0.01	-84.75	-0.010	0.000
0.02	-84.75	-0.010	0.000
0.03	-84.75	-0.009	0.000
0.05	-84.75	-0.004	0.000
0.06	-84.74	0.006	0.166
0.07	-84.73	0.017	0.367
0.08	-84.70	0.029	0.510
0.09	-84.67	0.044	0.662
0.11	-84.63	0.056	0.740
0.12	-84.58	0.070	0.813
0.13	-84.52	0.083	0.866
0.14	-84.46	0.094	0.886
0.15	-84.38	0.103	0.895
0.16	-84.31	0.110	0.887
0.18	-84.22	0.117	0.883
0.19	-84.14	0.120	0.854
0.20	-84.05	0.126	0.856
0.21	-83.96	0.130	0.846
0.22	-83.86	0.134	0.841
0.23	-83.77	0.137	0.836
0.24	-83.67	0.140	0.832
0.26	-83.57	0.143	0.838
0.27	-83.47	0.147	0.845
0.28	-83.37	0.148	0.838
0.29	-83.27	0.151	0.842
0.30	-83.16	0.153	0.844
0.31	-83.06	0.155	0.850
0.33	-82.95	0.156	0.845
0.34	-82.85	0.157	0.846
0.35	-82.74	0.158	0.843
0.36	-82.63	0.159	0.843
0.37	-82.52	0.160	0.842
0.39	-82.41	0.160	0.840
0.40	-82.30	0.161	0.839
0.41	-82.19	0.161	0.836
0.42	-82.08	0.161	0.835
0.43	-81.97	0.162	0.835
0.44	-81.86	0.163	0.835
0.45	-81.74	0.163	0.834
0.47	-81.63	0.163	0.834
0.48	-81.52	0.163	0.832
0.49	-81.41	0.163	0.832
0.50	-81.30	0.164	0.831
0.51	-81.18	0.164	0.831
0.53	-81.07	0.164	0.831
0.54	-80.96	0.164	0.830
0.55	-80.84	0.164	0.829
0.56	-80.73	0.165	0.829
0.57	-80.62	0.165	0.829
0.58	-80.50	0.165	0.829
0.60	-80.39	0.165	0.829
0.61	-80.28	0.165	0.828
0.62	-80.16	0.165	0.828
0.63	-80.05	0.165	0.828
0.64	-79.94	0.165	0.827
0.65	-79.82	0.165	0.827
0.67	-79.71	0.166	0.827
0.68	-79.59	0.166	0.827
0.69	-79.48	0.166	0.827
0.70	-79.36	0.166	0.830
0.71	-79.25	0.166	0.830
0.72	-79.13	0.166	0.830
0.73	-79.02	0.166	0.831
0.75	-78.90	0.166	0.830
0.76	-78.79	0.166	0.830
0.77	-78.67	0.166	0.830
0.78	-78.56	0.166	0.831
0.79	-78.44	0.166	0.830
0.80	-78.33	0.166	0.831
0.82	-78.21	0.166	0.831
0.83	-78.10	0.166	0.831
0.84	-77.98	0.166	0.832
0.85	-77.87	0.166	0.832
0.86	-77.75	0.166	0.832
0.88	-77.64	0.166	0.832
0.89	-77.52	0.166	0.831
0.90	-77.41	0.166	0.832
0.91	-77.29	0.166	0.832
0.92	-77.18	0.166	0.832
0.93	-77.06	0.166	0.832
0.95	-76.95	0.166	0.831
0.96	-76.83	0.166	0.832
0.97	-76.71	0.166	0.832
0.98	-76.60	0.166	0.832
0.99	-76.48	0.166	0.831
1.00	-76.37	0.166	0.832
1.02	-76.25	0.166	0.831
1.03	-76.14	0.166	0.832
1.04	-76.02	0.166	0.832
1.05	-75.90	0.166	0.832
1.06	-75.79	0.166	0.832
1.07	-75.67	0.166	0.832
1.08	-75.56	0.166	0.832
1.10	-75.44	0.166	0.832
1.11	-75.33	0.166	0.832
1.12	-75.21	0.166	0.832
1.13	-75.09	0.166	0.831
1.14	-74.98	0.166	0.832
1.16	-74.86	0.165	0.832
1.17	-74.75	0.165	0.832
1.18	-74.63	0.165	0.832
1.19	-74.51	0.165	0.833
1.20	-74.40	0.165	0.832
1.21	-74.28	0.165	0.832
1.23	-74.17	0.165	0.832
1.24	-74.05	0.165	0.832
1.25	-73.93	0.165	0.833
1.26	-73.82	0.165	0.832
1.27	-73.70	0.165	0.832
1.28	-73.59	0.165	0.832
1.29	-73.47	0.165	0.832
1.31	-73.35	0.165	0.833
1.32	-73.24	0.165	0.832
1.33	-73.12	0.165	0.832
1.34	-73.01	0.165	0.832
1.35	-72.89	0.165	0.832
1.37	-72.77	0.165	0.832
1.38	-72.66	0.165	0.833
1.39	-72.54	0.165	0.832
1.40	-72.43	0.165	0.833
1.41	-72.31	0.165	0.833
1.42	-72.19	0.165	0.833
1.43	-72.08	0.165	0.833
1.45	-71.96	0.165	0.834
1.46	-71.84	0.165	0.833
1.47	-71.73	0.165	0.834
1.48	-71.61	0.165	0.834
1.49	-71.50	0.165	0.834
1.51	-71.38	0.165	0.834
1.52	-71.26	0.165	0.834
1.53	-71.15	0.165	0.835
1.54	-71.03	0.165	0.835
1.55	-70.91	0.165	0.836
1.56	-70.80	0.165	0.836
1.58	-70.68	0.165	0.836
1.59	-70.56	0.165	0.837
1.60	-70.45	0.165	0.837
1.61	-70.33	0.165	0.837
1.62	-70.21	0.165	0.837
1.63	-70.10	0.165	0.837
1.64	-69.98	0.165	0.838
1.66	-69.87	0.165	0.838
1.67	-69.75	0.165	0.839
1.68	-69.63	0.165	0.840
1.69	-69.52	0.165	0.840
1.70	-69.40	0.165	0.840
1.72	-69.28	0.165	0.841
1.73	-69.17	0.165	0.840
1.74	-69.05	0.165	0.841
1.75	-68.93	0.165	0.841
1.76	-68.82	0.165	0.841
1.77	-68.70	0.165	0.841
1.78	-68.59	0.165	0.842
1.80	-68.47	0.165	0.842
1.81	-68.35	0.165	0.842
1.82	-68.24	0.165	0.843
1.83	-68.12	0.165	0.843
1.84	-68.00	0.166	0.844
1.86	-67.89	0.166	0.845
1.87	-67.77	0.166	0.845
1.88	-67.65	0.166	0.845
1.89	-67.54	0.166	0.845
1.90	-67.42	0.166	0.847
1.91	-67.30	0.166	0.846
1.93	-67.19	0.166	0.846
1.94	-67.07	0.166	0.847
1.95	-66.95	0.166	0.847
1.96	-66.84	0.166	0.847
1.97	-66.72	0.166	0.849
1.98	-66.61	0.166	0.849
1.99	-66.49	0.166	0.848
2.01	-66.37	0.166	0.849
2.02	-66.26	0.166	0.849
2.03	-66.14	0.166	0.849
2.04	-66.02	0.166	0.850
2.05	-65.91	0.166	0.850
2.07	-65.79	0.166	0.850
2.08	-65.67	0.166	0.851
2.09	-65.56	0.166	0.852
2.10	-65.44	0.166	0.852
2.11	-65.33	0.166	0.852
2.12	-65.21	0.167	0.852
2.14	-65.09	0.167	0.853
2.15	-64.97	0.167	0.853
2.16	-64.86	0.167	0.854
2.17	-64.74	0.167	0.854
2.18	-64.62	0.167	0.854
2.19	-64.51	0.167	0.855
2.21	-64.39	0.167	0.855
2.22	-64.28	0.167	0.855
2.23	-64.16	0.167	0.856
2.24	-64.04	0.167	0.856
2.25	-63.93	0.167	0.857
2.26	-63.81	0.167	0.857
2.28	-63.70	0.167	0.858
2.29	-63.58	0.167	0.858
2.30	-63.46	0.167	0.858
2.31	-63.34	0.167	0.859
2.32	-63.23	0.167	0.859
2.33	-63.11	0.167	0.859
2.34	-63.00	0.167	0.860
2.36	-62.88	0.167	0.860
2.37	-62.76	0.168	0.861
2.38	-62.65	0.168	0.861
2.39	-62.53	0.168	0.861
2.40	-62.41	0.168	0.861
2.41	-62.30	0.168	0.862
2.43	-62.18	0.168	0.862
2.44	-62.06	0.168	0.863
2.45	-61.95	0.168	0.863
2.46	-61.83	0.168	0.863
2.47	-61.72	0.168	0.864
2.49	-61.60	0.168	0.864
2.50	-61.48	0.168	0.865
2.51	-61.36	0.168	0.865
2.52	-61.25	0.168	0.865
2.53	-61.13	0.168	0.866
2.54	-61.02	0.168	0.866
2.56	-60.90	0.169	0.867
2.57	-60.78	0.169	0.867
2.58	-60.67	0.169	0.868
2.59	-60.55	0.169	0.868
2.60	-60.43	0.169	0.869
2.61	-60.32	0.169	0.869
2.63	-60.20	0.169	0.869
2.64	-60.08	0.169	0.869
2.65	-59.97	0.169	0.870
2.66	-59.85	0.169	0.871
2.67	-59.73	0.169	0.871
2.68	-59.62	0.169	0.871
2.69	-59.50	0.169	0.872
2.71	-59.38	0.169	0.872
2.72	-59.27	0.169	0.873
2.73	-59.15	0.170	0.874
2.74	-59.03	0.170	0.873
2.75	-58.92	0.170	0.874
2.76	-58.80	0.170	0.875
2.78	-58.68	0.170	0.875
2.79	-58.57	0.170	0.875
2.80	-58.45	0.170	0.876
2.81	-58.33	0.170	0.876
2.82	-58.22	0.170	0.877
2.84	-58.10	0.170	0.877
2.85	-57.98	0.170	0.878
2.86	-57.87	0.170	0.878
2.87	-57.75	0.170	0.879
2.88	-57.63	0.170	0.879
2.89	-57.52	0.170	0.879
2.91	-57.40	0.171	0.880
2.92	-57.29	0.171	0.881
2.93	-57.17	0.171	0.881
2.94	-57.05	0.171	0.882
2.95	-56.93	0.171	0.882
2.96	-56.82	0.171	0.881
2.98	-56.70	0.171	0.882
2.99	-56.58	0.171	0.882
3.00	-56.47	0.171	0.882
3.01	-56.35	0.171	0.883
3.02	-56.23	0.171	0.883
3.03	-56.12	0.171	0.884
3.04	-56.00	0.171	0.884
3.06	-55.88	0.172	0.884
3.07	-55.77	0.172	0.884
3.08	-55.65	0.172	0.885
3.09	-55.53	0.172	0.885
3.10	-55.42	0.172	0.886
3.11	-55.30	0.172	0.886
3.13	-55.18	0.172	0.886
3.14	-55.06	0.172	0.887
3.15	-54.95	0.172	0.888
3.16	-54.83	0.172	0.889
3.17	-54.71	0.172	0.889
3.19	-54.60	0.172	0.889
3.20	-54.48	0.172	0.890
3.21	-54.36	0.173	0.890
3.22	-54.25	0.173	0.891
3.23	-54.13	0.173	0.892
3.24	-54.01	0.173	0.892
3.26	-53.90	0.173	0.892
3.27	-53.78	0.173	0.893
3.28	-53.66	0.173	0.893
3.29	-53.55	0.173	0.893
3.30	-53.43	0.173	0.894
3.31	-53.31	0.173	0.894
3.33	-53.20	0.173	0.895
3.34	-53.08	0.173	0.895
3.35	-52.96	0.173	0.896
3.36	-52.84	0.173	0.897
3.37	-52.73	0.173	0.897
3.38	-52.61	0.174	0.897
3.39	-52.49	0.174	0.898
3.41	-52.38	0.174	0.898
3.42	-52.26	0.174	0.899
3.43	-52.14	0.174	0.899
3.44	-52.03	0.174	0.900
3.45	-51.91	0.174	0.900
3.46	-51.79	0.174	0.901
3.48	-51.68	0.174	0.901
3.49	-51.56	0.174	0.902
3.50	-51.44	0.174	0.902
3.51	-51.32	0.174	0.902
3.52	-51.21	0.174	0.902
3.54	-51.09	0.174	0.903
3.55	-50.97	0.175	0.903
3.56	-50.86	0.175	0.903
3.57	-50.74	0.175	0.904
3.58	-50.62	0.175	0.904
3.59	-50.51	0.175	0.905
3.61	-50.39	0.175	0.905
3.62	-50.27	0.175	0.906
3.63	-50.16	0.175	0.906
3.64	-50.04	0.175	0.906
3.65	-49.92	0.175	0.907
3.66	-49.81	0.175	0.908
3.68	-49.69	0.175	0.908
3.69	-49.57	0.175	0.909
3.70	-49.46	0.175	0.909
3.71	-49.34	0.176	0.910
3.72	-49.22	0.176	0.910
3.73	-49.10	0.176	0.911
3.74	-48.99	0.176	0.911
3.76	-48.87	0.176	0.911
3.77	-48.76	0.176	0.912
3.78	-48.64	0.176	0.912
3.79	-48.52	0.176	0.913
3.80	-48.40	0.176	0.913
3.81	-48.29	0.176	0.914
3.83	-48.17	0.176	0.914
3.84	-48.05	0.176	0.915
3.85	-47.94	0.176	0.914
3.86	-47.82	0.177	0.915
3.87	-47.70	0.177	0.916
3.89	-47.59	0.177	0.916
3.90	-47.47	0.177	0.917
3.91	-47.35	0.177	0.918
3.92	-47.23	0.177	0.918
3.93	-47.12	0.177	0.917
3.94	-47.00	0.177	0.919
3.96	-46.88	0.177	0.919
3.97	-46.77	0.177	0.919
3.98	-46.65	0.177	0.920
3.99	-46.53	0.177	0.920
4.00	-46.42	0.177	0.921
4.01	-46.30	0.177	0.921
4.03	-46.18	0.178	0.922
4.04	-46.06	0.178	0.923
4.05	-45.95	0.178	0.923
4.06	-45.83	0.178	0.923
4.07	-45.71	0.178	0.924
4.08	-45.60	0.178	0.924
4.09	-45.48	0.178	0.924
4.11	-45.36	0.178	0.924
4.12	-45.25	0.178	0.925
4.13	-45.13	0.178	0.926
4.14	-45.01	0.178	0.926
4.15	-44.90	0.178	0.927
4.16	-44.78	0.178	0.927
4.18	-44.66	0.178	0.928
4.19	-44.55	0.178	0.928
4.20	-44.43	0.178	0.929
4.21	-44.31	0.178	0.929
4.22	-44.20	0.179	0.930
4.24	-44.08	0.179	0.930
4.25	-43.96	0.179	0.931
4.26	-43.85	0.179	0.931
4.27	-43.73	0.179	0.931
4.28	-43.61	0.179	0.931
4.29	-43.49	0.179	0.932
4.30	-43.38	0.179	0.932
4.32	-43.26	0.179	0.933
4.33	-43.14	0.179	0.933
4.34	-43.03	0.179	0.934
4.35	-42.91	0.179	0.934
4.36	-42.79	0.179	0.934
4.38	-42.68	0.179	0.935
4.39	-42.56	0.180	0.936
4.40	-42.44	0.180	0.936
4.41	-42.33	0.180	0.936
4.42	-42.21	0.180	0.937
4.43	-42.09	0.180	0.938
4.45	-41.97	0.180	0.937
4.46	-41.86	0.180	0.938
4.47	-41.74	0.180	0.939
4.48	-41.62	0.180	0.939
4.49	-41.51	0.180	0.940
4.50	-41.39	0.180	0.939
4.51	-41.27	0.180	0.940
4.53	-41.16	0.180	0.941
4.54	-41.04	0.180	0.941
4.55	-40.92	0.180	0.941
4.56	-40.81	0.181	0.942
4.57	-40.69	0.181	0.943
4.59	-40.57	0.181	0.943
4.60	-40.46	0.181	0.944
4.61	-40.34	0.181	0.944
4.62	-40.22	0.181	0.945
4.63	-40.10	0.181	0.945
4.64	-39.99	0.181	0.945
4.65	-39.87	0.181	0.946
4.67	-39.75	0.181	0.946
4.68	-39.64	0.181	0.946
4.69	-39.52	0.181	0.947
4.70	-39.40	0.181	0.948
4.71	-39.29	0.181	0.948
4.73	-39.17	0.181	0.948
4.74	-39.05	0.181	0.949
4.75	-38.94	0.182	0.949
4.76	-38.82	0.182	0.950
4.77	-38.70	0.182	0.951
4.78	-38.58	0.182	0.950
4.80	-38.47	0.182	0.951
4.81	-38.35	0.182	0.951
4.82	-38.23	0.182	0.952
4.83	-38.12	0.182	0.952
4.84	-38.00	0.182	0.952
4.85	-37.88	0.182	0.952
4.86	-37.77	0.182	0.953
4.88	-37.65	0.182	0.954
4.89	-37.53	0.182	0.954
4.90	-37.42	0.182	0.954
4.91	-37.30	0.182	0.955
4.92	-37.18	0.182	0.956
4.94	-37.07	0.183	0.956
4.95	-36.95	0.183	0.956
4.96	-36.83	0.183	0.957
4.97	-36.72	0.183	0.957
4.98	-36.60	0.183	0.958
4.99	-36.48	0.183	0.958
5.00	-36.37	0.183	0.959
5.02	-36.25	0.183	0.959
5.03	-36.13	0.183	0.960
5.04	-36.01	0.183	0.961
5.05	-35.90	0.183	0.961
5.06	-35.78	0.183	0.962
5.08	-35.66	0.183	0.961
5.09	-35.55	0.183	0.962
5.10	-35.43	0.183	0.963
5.11	-35.31	0.184	0.963
5.12	-35.20	0.184	0.963
5.13	-35.08	0.184	0.964
5.15	-34.96	0.184	0.964
5.16	-34.85	0.184	0.964
5.17	-34.73	0.184	0.965
5.18	-34.61	0.184	0.965
5.19	-34.49	0.184	0.966
5.20	-34.38	0.184	0.966
5.21	-34.26	0.184	0.967
5.23	-34.14	0.184	0.967
5.24	-34.03	0.184	0.968
5.25	-33.91	0.184	0.968
5.26	-33.79	0.184	0.968
5.27	-33.68	0.184	0.969
5.29	-33.56	0.185	0.970
5.30	-33.44	0.185	0.970
5.31	-33.33	0.185	0.970
5.32	-33.21	0.185	0.971
5.33	-33.09	0.185	0.971
5.34	-32.98	0.185	0.972
5.35	-32.86	0.185	0.972
5.37	-32.74	0.185	0.973
5.38	-32.63	0.185	0.973
5.39	-32.51	0.185	0.974
5.40	-32.39	0.185	0.974
5.41	-32.28	0.185	0.974
5.43	-32.16	0.185	0.974
5.44	-32.04	0.185	0.975
5.45	-31.93	0.185	0.975
5.46	-31.81	0.185	0.976
5.47	-31.69	0.186	0.977
5.48	-31.58	0.186	0.977
5.50	-31.46	0.186	0.977
5.51	-31.34	0.186	0.977
5.52	-31.22	0.186	0.979
5.53	-31.11	0.186	0.978
5.54	-30.99	0.186	0.979
5.55	-30.87	0.186	0.980
5.56	-30.76	0.186	0.980
5.58	-30.64	0.186	0.980
5.59	-30.52	0.186	0.981
5.60	-30.41	0.186	0.982
5.61	-30.29	0.186	0.982
5.62	-30.17	0.186	0.982
5.64	-30.05	0.186	0.982
5.65	-29.94	0.186	0.983
5.66	-29.82	0.187	0.983
5.67	-29.71	0.187	0.984
5.68	-29.59	0.187	0.984
5.69	-29.47	0.187	0.985
5.70	-29.36	0.187	0.985
5.72	-29.24	0.187	0.985
5.73	-29.12	0.187	0.986
5.74	-29.01	0.187	0.987
5.75	-28.89	0.187	0.988
5.76	-28.77	0.187	0.987
5.78	-28.65	0.187	0.988
5.79	-28.54	0.187	0.989
5.80	-28.42	0.188	0.989
5.81	-28.30	0.188	0.989
5.82	-28.19	0.188	0.990
5.83	-28.07	0.188	0.990
5.85	-27.95	0.188	0.991
5.86	-27.84	0.188	0.992
5.87	-27.72	0.188	0.992
5.88	-27.60	0.188	0.992
5.89	-27.49	0.188	0.993
5.90	-27.37	0.188	0.994
5.91	-27.25	0.188	0.994
5.93	-27.14	0.188	0.995
5.94	-27.02	0.188	0.995
5.95	-26.90	0.188	0.995
5.96	-26.78	0.188	0.996
5.97	-26.67	0.189	0.997
5.99	-26.55	0.189	0.997
6.00	-26.43	0.189	0.997
6.01	-26.32	0.189	0.998
6.02	-26.20	0.189	0.998
6.03	-26.09	0.189	0.999
6.04	-25.97	0.189	0.999
6.05	-25.85	0.189	0.999
6.07	-25.73	0.189	1.000
6.08	-25.62	0.189	1.000
6.09	-25.50	0.189	1.001
6.10	-25.38	0.189	1.002
6.11	-25.27	0.190	1.002
6.13	-25.15	0.190	1.003
6.14	-25.03	0.190	1.003
6.15	-24.92	0.190	1.004
6.16	-24.80	0.190	1.004
6.17	-24.68	0.190	1.006
6.18	-24.57	0.190	1.006
6.20	-24.45	0.190	1.006
6.21	-24.33	0.190	1.007
6.22	-24.21	0.190	1.007
6.23	-24.10	0.190	1.007
6.24	-23.98	0.190	1.008
6.25	-23.87	0.190	1.008
6.26	-23.75	0.190	1.008
6.28	-23.63	0.190	1.009
6.29	-23.51	0.191	1.009
6.30	-23.40	0.191	1.009
6.31	-23.28	0.191	1.010
6.32	-23.16	0.191	1.010
6.34	-23.05	0.191	1.010
6.35	-22.93	0.191	1.011
6.36	-22.81	0.191	1.012
6.37	-22.70	0.191	1.012
6.38	-22.58	0.191	1.012
6.39	-22.46	0.191	1.013
6.40	-22.35	0.191	1.013
6.42	-22.23	0.191	1.014
6.43	-22.11	0.191	1.014
6.44	-21.99	0.191	1.014
6.45	-21.88	0.192	1.015
6.46	-21.76	0.192	1.015
6.48	-21.65	0.192	1.016
6.49	-21.53	0.192	1.016
6.50	-21.41	0.192	1.016
6.51	-21.30	0.192	1.017
6.52	-21.18	0.192	1.018
6.53	-21.06	0.192	1.018
6.55	-20.94	0.192	1.018
6.56	-20.83	0.192	1.019
6.57	-20.71	0.192	1.019
6.58	-20.59	0.192	1.020
6.59	-20.48	0.192	1.020
6.60	-20.36	0.192	1.021
6.61	-20.24	0.192	1.021
6.63	-20.13	0.193	1.022
6.64	-20.01	0.193	1.022
6.65	-19.89	0.193	1.023
6.66	-19.78	0.193	1.022
6.67	-19.66	0.193	1.024
6.69	-19.54	0.193	1.024
6.70	-19.43	0.193	1.024
6.71	-19.31	0.193	1.025
6.72	-19.19	0.193	1.025
6.73	-19.08	0.193	1.025
6.74	-18.96	0.193	1.026
6.75	-18.84	0.193	1.027
6.77	-18.73	0.194	1.028
6.78	-18.61	0.194	1.028
6.79	-18.49	0.194	1.028
6.80	-18.37	0.194	1.029
6.81	-18.26	0.194	1.029
6.83	-18.14	0.194	1.030
6.84	-18.02	0.194	1.030
6.85	-17.91	0.194	1.030
6.86	-17.79	0.194	1.030
6.87	-17.67	0.194	1.031
6.88	-17.56	0.194	1.031
6.90	-17.44	0.194	1.033
6.91	-17.32	0.194	1.032
6.92	-17.21	0.194	1.033
6.93	-17.09	0.194	1.034
6.94	-16.97	0.195	1.034
6.95	-16.86	0.195	1.034
6.96	-16.74	0.195	1.034
6.98	-16.62	0.195	1.035
6.99	-16.51	0.195	1.035
7.00	-16.39	0.195	1.036
7.01	-16.27	0.195	1.036
7.02	-16.16	0.195	1.037
7.04	-16.04	0.195	1.037
7.05	-15.92	0.195	1.038
7.06	-15.80	0.195	1.038
7.07	-15.69	0.195	1.039
7.08	-15.57	0.195	1.039
7.09	-15.46	0.195	1.040
7.10	-15.34	0.195	1.040
7.12	-15.22	0.195	1.040
7.13	-15.10	0.196	1.041
7.14	-14.99	0.196	1.041
7.15	-14.87	0.196	1.042
7.16	-14.75	0.196	1.042
7.18	-14.64	0.196	1.043
7.19	-14.52	0.196	1.043
7.20	-14.40	0.196	1.044
7.21	-14.29	0.196	1.044
7.22	-14.17	0.196	1.045
7.23	-14.05	0.196	1.045
7.25	-13.94	0.196	1.045
7.26	-13.82	0.196	1.046
7.27	-13.70	0.196	1.046
7.28	-13.59	0.197	1.046
7.29	-13.47	0.197	1.047
7.30	-13.35	0.197	1.047
7.31	-13.24	0.197	1.048
7.33	-13.12	0.197	1.048
7.34	-13.00	0.197	1.049
7.35	-12.89	0.197	1.049
7.36	-12.77	0.197	1.050
7.37	-12.65	0.197	1.050
7.39	-12.54	0.197	1.050
7.40	-12.42	0.197	1.051
7.41	-12.30	0.197	1.051
7.42	-12.19	0.197	1.052
7.43	-12.07	0.198	1.053
7.44	-11.95	0.198	1.053
7.45	-11.83	0.198	1.053
7.47	-11.72	0.198	1.054
7.48	-11.60	0.198	1.054
7.49	-11.48	0.198	1.055
7.50	-11.37	0.198	1.055
7.51	-11.25	0.198	1.055
7.53	-11.14	0.198	1.056
7.54	-11.02	0.198	1.056
7.55	-10.90	0.198	1.057
7.56	-10.78	0.198	1.057
7.57	-10.67	0.198	1.058
7.58	-10.55	0.199	1.058
7.60	-10.43	0.199	1.059
7.61	-10.32	0.199	1.059
7.62	-10.20	0.199	1.060
7.63	-10.08	0.199	1.060
7.64	-9.97	0.199	1.060
7.65	-9.85	0.199	1.061
7.66	-9.73	0.199	1.061
7.68	-9.62	0.199	1.062
7.69	-9.50	0.199	1.062
7.70	-9.38	0.199	1.063
7.71	-9.27	0.199	1.063
7.72	-9.15	0.199	1.064
7.74	-9.03	0.199	1.064
7.75	-8.91	0.200	1.064
7.76	-8.80	0.200	1.065
7.77	-8.68	0.200	1.066
7.78	-8.56	0.200	1.066
7.79	-8.45	0.200	1.067
7.80	-8.33	0.200	1.068
7.82	-8.21	0.200	1.067
7.83	-8.10	0.200	1.067
7.84	-7.98	0.200	1.068
7.85	-7.86	0.200	1.069
7.86	-7.75	0.200	1.069
7.88	-7.63	0.200	1.070
7.89	-7.51	0.200	1.070
7.90	-7.40	0.201	1.070
7.91	-7.28	0.201	1.071
7.92	-7.16	0.201	1.072
7.93	-7.05	0.201	1.072
7.95	-6.93	0.201	1.073
7.96	-6.81	0.201	1.073
7.97	-6.70	0.201	1.073
7.98	-6.58	0.201	1.074
7.99	-6.46	0.201	1.075
8.00	-6.35	0.201	1.075
8.01	-6.23	0.201	1.075
8.03	-6.11	0.201	1.076
8.04	-6.00	0.202	1.076
8.05	-5.88	0.202	1.077
8.06	-5.76	0.202	1.078
8.07	-5.64	0.202	1.077
8.09	-5.53	0.202	1.078
8.10	-5.41	0.202	1.079
8.11	-5.29	0.202	1.079
8.12	-5.18	0.202	1.081
8.13	-5.06	0.202	1.081
8.14	-4.94	0.202	1.082
8.15	-4.83	0.202	1.082
8.17	-4.71	0.203	1.082
8.18	-4.59	0.203	1.083
8.19	-4.48	0.203	1.083
8.20	-4.36	0.203	1.083
8.21	-4.24	0.203	1.084
8.23	-4.13	0.203	1.085
8.24	-4.01	0.203	1.085
8.25	-3.89	0.203	1.086
8.26	-3.78	0.203	1.086
8.27	-3.66	0.203	1.087
8.28	-3.54	0.203	1.088
8.30	-3.43	0.203	1.088
8.31	-3.31	0.204	1.088
8.32	-3.19	0.204	1.088
8.33	-3.08	0.204	1.088
8.34	-2.96	0.204	1.089
8.35	-2.84	0.204	1.090
8.36	-2.73	0.204	1.090
8.38	-2.61	0.204	1.090
8.39	-2.49	0.204	1.091
8.40	-2.37	0.204	1.091
8.41	-2.26	0.204	1.092
8.42	-2.14	0.204	1.092
8.44	-2.02	0.204	1.093
8.45	-1.91	0.204	1.093
8.46	-1.79	0.204	1.093
8.47	-1.67	0.205	1.094
8.48	-1.56	0.205	1.094
8.49	-1.44	0.205	1.094
8.50	-1.32	0.205	1.095
8.52	-1.21	0.205	1.095
8.53	-1.09	0.205	1.096
8.54	-0.97	0.205	1.097
8.55	-0.86	0.205	1.097
8.56	-0.74	0.205	1.098
8.58	-0.62	0.205	1.098
8.59	-0.51	0.205	1.098
8.60	-0.39	0.205	1.099
8.61	-0.27	0.205	1.098
8.62	-0.15	0.205	1.099
8.63	-0.04	0.206	1.099
8.65	0.08	0.206	1.100
8.66	0.20	0.206	1.100
8.67	0.31	0.206	1.101
8.68	0.43	0.206	1.101
8.69	0.55	0.206	1.101
8.70	0.66	0.206	1.102
8.72	0.78	0.206	1.103
8.73	0.90	0.206	1.104
8.74	1.01	0.206	1.103
8.75	1.13	0.206	1.104
8.76	1.25	0.207	1.104
8.77	1.36	0.207	1.105
8.78	1.48	0.207	1.105
8.80	1.60	0.207	1.106
8.81	1.71	0.207	1.106
8.82	1.83	0.207	1.106
8.83	1.95	0.207	1.107
8.84	2.06	0.207	1.108
8.85	2.18	0.207	1.108
8.87	2.30	0.207	1.109
8.88	2.41	0.207	1.109
8.89	2.53	0.207	1.110
8.90	2.65	0.208	1.110
8.91	2.77	0.208	1.110
8.93	2.88	0.208	1.111
8.94	3.00	0.208	1.111
8.95	3.12	0.208	1.112
8.96	3.23	0.208	1.112
8.97	3.35	0.208	1.113
8.98	3.47	0.208	1.113
9.00	3.58	0.208	1.114
9.01	3.70	0.208	1.114
9.02	3.82	0.208	1.114
9.03	3.93	0.208	1.115
9.04	4.05	0.209	1.115
9.05	4.17	0.209	1.116
9.07	4.28	0.209	1.116
9.08	4.40	0.209	1.117
9.09	4.52	0.209	1.117
9.10	4.64	0.209	1.118
9.11	4.75	0.209	1.119
9.12	4.87	0.209	1.119
9.13	4.99	0.209	1.119
9.15	5.10	0.209	1.120
9.16	5.22	0.210	1.121
9.17	5.34	0.210	1.121
9.18	5.45	0.210	1.122
9.19	5.57	0.210	1.122
9.20	5.69	0.210	1.122
9.22	5.80	0.210	1.123
9.23	5.92	0.210	1.123
9.24	6.04	0.210	1.124
9.25	6.15	0.210	1.124
9.26	6.27	0.210	1.125
9.28	6.39	0.210	1.125
9.29	6.50	0.210	1.126
9.30	6.62	0.211	1.126
9.31	6.74	0.211	1.126
9.32	6.85	0.211	1.128
9.33	6.97	0.211	1.128
9.35	7.09	0.211	1.129
9.36	7.20	0.211	1.129
9.37	7.32	0.211	1.130
9.38	7.44	0.211	1.130
9.39	7.56	0.211	1.130
9.40	7.67	0.211	1.131
9.42	7.79	0.212	1.132
9.43	7.90	0.212	1.132
9.44	8.02	0.212	1.132
9.45	8.14	0.212	1.133
9.46	8.26	0.212	1.133
9.47	8.37	0.212	1.134
9.48	8.49	0.212	1.134
9.50	8.61	0.212	1.135
9.51	8.72	0.212	1.136
9.52	8.84	0.212	1.136
9.53	8.96	0.213	1.137
9.54	9.07	0.213	1.137
9.55	9.19	0.213	1.138
9.57	9.31	0.213	1.138
9.58	9.42	0.213	1.138
9.59	9.54	0.213	1.139
9.60	9.66	0.213	1.139
9.61	9.77	0.213	1.139
9.63	9.89	0.213	1.140
9.64	10.01	0.213	1.140
9.65	10.12	0.213	1.141
9.66	10.24	0.213	1.142
9.67	10.36	0.214	1.143
9.68	10.47	0.214	1.143
9.70	10.59	0.214	1.143
9.71	10.71	0.214	1.144
9.72	10.83	0.214	1.144
9.73	10.94	0.214	1.144
9.74	11.06	0.214	1.145
9.75	11.18	0.214	1.145
9.77	11.29	0.214	1.146
9.78	11.41	0.214	1.146
9.79	11.53	0.215	1.147
9.80	11.64	0.215	1.148
9.81	11.76	0.215	1.148
9.82	11.88	0.215	1.148
9.83	11.99	0.215	1.149
9.85	12.11	0.215	1.150
9.86	12.23	0.215	1.150
9.87	12.34	0.215	1.150
9.88	12.46	0.215	1.151
9.89	12.58	0.215	1.151
9.90	12.69	0.215	1.152
9.92	12.81	0.216	1.152
9.93	12.93	0.216	1.152
9.94	13.04	0.216	1.153
9.95	13.16	0.216	1.154
9.96	13.28	0.216	1.154
9.98	13.39	0.216	1.155
9.99	13.51	0.216	1.156
10.00	13.63	0.216	1.156
10.01	13.74	0.216	1.156
10.02	13.86	0.216	1.157
10.03	13.98	0.216	1.157
10.05	14.09	0.217	1.157
10.06	14.21	0.217	1.158
10.07	14.33	0.217	1.158
10.08	14.45	0.217	1.158
10.09	14.56	0.217	1.159
10.10	14.68	0.217	1.160
10.12	14.80	0.217	1.160
10.13	14.91	0.217	1.161
10.14	15.03	0.217	1.161
10.15	15.15	0.217	1.161
10.16	15.26	0.217	1.161
10.17	15.38	0.217	1.162
10.18	15.50	0.217	1.162
10.20	15.61	0.217	1.162
10.21	15.73	0.217	1.163
10.22	15.85	0.218	1.163
10.23	15.96	0.218	1.164
10.24	16.08	0.218	1.164
10.25	16.20	0.218	1.164
10.27	16.31	0.218	1.165
10.28	16.43	0.218	1.165
10.29	16.55	0.218	1.166
10.30	16.66	0.218	1.166
10.31	16.78	0.218	1.167
10.33	16.90	0.218	1.167
10.34	17.01	0.219	1.168
10.35	17.13	0.219	1.169
10.36	17.25	0.219	1.169
10.37	17.36	0.219	1.170
10.38	17.48	0.219	1.171
10.40	17.60	0.219	1.171
10.41	17.72	0.219	1.172
10.42	17.83	0.219	1.173
10.43	17.95	0.219	1.173
10.44	18.07	0.220	1.174
10.45	18.18	0.220	1.175
10.47	18.30	0.220	1.175
10.48	18.42	0.220	1.176
10.49	18.53	0.220	1.176
10.50	18.65	0.220	1.178
10.51	18.77	0.220	1.178
10.52	18.88	0.220	1.179
10.53	19.00	0.221	1.180
10.55	19.12	0.221	1.181
10.56	19.23	0.221	1.181
10.57	19.35	0.221	1.182
10.58	19.47	0.221	1.181
10.59	19.58	0.221	1.182
10.60	19.70	0.221	1.182
10.62	19.82	0.221	1.183
10.63	19.93	0.221	1.183
10.64	20.05	0.221	1.184
10.65	20.17	0.222	1.184
10.66	20.28	0.222	1.184
10.68	20.40	0.222	1.185
10.69	20.52	0.222	1.185
10.70	20.63	0.222	1.186
10.71	20.75	0.222	1.187
10.72	20.87	0.222	1.187
10.73	20.98	0.222	1.188
10.75	21.10	0.222	1.188
10.76	21.22	0.222	1.188
10.77	21.34	0.222	1.189
10.78	21.45	0.223	1.190
10.79	21.57	0.223	1.190
10.80	21.69	0.223	1.190
10.82	21.80	0.223	1.190
10.83	21.92	0.223	1.191
10.84	22.04	0.223	1.192
10.85	22.15	0.223	1.192
10.86	22.27	0.223	1.192
10.87	22.39	0.223	1.192
10.88	22.50	0.223	1.193
10.90	22.62	0.223	1.194
10.91	22.74	0.223	1.194
10.92	22.85	0.224	1.195
10.93	22.97	0.224	1.195
10.94	23.09	0.224	1.196
10.95	23.20	0.224	1.196
10.97	23.32	0.224	1.197
10.98	23.44	0.224	1.197
10.99	23.55	0.224	1.198
11.00	23.67	0.224	1.198
11.01	23.79	0.224	1.199
11.03	23.91	0.224	1.199
11.04	24.02	0.224	1.200
11.05	24.14	0.224	1.201
11.06	24.25	0.225	1.201
11.07	24.37	0.225	1.201
11.08	24.49	0.225	1.202
11.10	24.61	0.225	1.202
11.11	24.72	0.225	1.202
11.12	24.84	0.225	1.203
11.13	24.96	0.225	1.204
11.14	25.07	0.225	1.204
11.15	25.19	0.225	1.205
11.17	25.31	0.225	1.204
11.18	25.42	0.225	1.205
11.19	25.54	0.226	1.206
11.20	25.66	0.226	1.206
11.21	25.77	0.226	1.206
11.22	25.89	0.226	1.207
11.23	26.01	0.226	1.207
11.25	26.12	0.226	1.208
11.26	26.24	0.226	1.209
11.27	26.36	0.226	1.209
11.28	26.47	0.226	1.210
11.29	26.59	0.226	1.210
11.30	26.71	0.227	1.211
11.32	26.82	0.227	1.211
11.33	26.94	0.227	1.211
11.34	27.06	0.227	1.211
11.35	27.17	0.227	1.213
11.36	27.29	0.227	1.214
11.38	27.41	0.227	1.214
11.39	27.53	0.227	1.215
11.40	27.64	0.227	1.215
11.41	27.76	0.227	1.216
11.42	27.88	0.227	1.216
11.43	27.99	0.228	1.217
11.45	28.11	0.228	1.217
11.46	28.23	0.228	1.218
11.47	28.34	0.228	1.218
11.48	28.46	0.228	1.218
11.49	28.58	0.228	1.219
11.50	28.69	0.228	1.220
11.52	28.81	0.228	1.220
11.53	28.93	0.228	1.220
11.54	29.04	0.228	1.222
11.55	29.16	0.228	1.222
11.56	29.28	0.229	1.222
11.57	29.39	0.229	1.222
11.58	29.51	0.229	1.222
11.60	29.63	0.229	1.223
11.61	29.74	0.229	1.223
11.62	29.86	0.229	1.224
11.63	29.98	0.229	1.224
11.64	30.09	0.229	1.224
11.65	30.21	0.229	1.225
11.67	30.33	0.229	1.226
11.68	30.44	0.229	1.226
11.69	30.56	0.229	1.227
11.70	30.68	0.230	1.227
11.71	30.80	0.230	1.227
11.73	30.91	0.230	1.228
11.74	31.03	0.230	1.228
11.75	31.15	0.230	1.229
11.76	31.26	0.230	1.229
11.77	31.38	0.230	1.230
11.78	31.50	0.230	1.231
11.80	31.61	0.230	1.231
11.81	31.73	0.230	1.231
11.82	31.85	0.230	1.232
11.83	31.96	0.231	1.233
11.84	32.08	0.231	1.234
11.85	32.20	0.231	1.234
11.87	32.31	0.231	1.235
11.88	32.43	0.231	1.235
11.89	32.55	0.231	1.235
11.90	32.66	0.231	1.237
11.91	32.78	0.231	1.237
11.92	32.90	0.231	1.237
11.93	33.01	0.231	1.238
11.95	33.13	0.232	1.238
11.96	33.25	0.232	1.238
11.97	33.36	0.232	1.239
11.98	33.48	0.232	1.239
11.99	33.60	0.232	1.240
12.00	33.72	0.232	1.240
12.02	33.83	0.232	1.241
12.03	33.95	0.232	1.241
12.04	34.06	0.232	1.242
12.05	34.18	0.232	1.242
12.06	34.30	0.232	1.243
12.08	34.42	0.232	1.243
12.09	34.53	0.233	1.244
12.10	34.65	0.233	1.244
12.11	34.77	0.233	1.244
12.12	34.88	0.233	1.246
12.13	35.00	0.233	1.245
12.15	35.12	0.233	1.246
12.16	35.23	0.233	1.246
12.17	35.35	0.233	1.247
12.18	35.47	0.233	1.247
12.19	35.58	0.233	1.247
12.20	35.70	0.233	1.248
[...]
494.42	-49.12	0.178	0.920
494.43	-49.06	0.178	0.920
494.43	-48.99	0.178	0.921
494.44	-48.92	0.178	0.921
494.45	-48.86	0.178	0.921
494.46	-48.79	0.178	0.921
494.46	-48.72	0.178	0.921
494.47	-48.65	0.178	0.922
494.48	-48.59	0.178	0.922
494.48	-48.52	0.178	0.922
494.49	-48.45	0.178	0.922
494.49	-48.39	0.178	0.922
494.50	-48.32	0.178	0.923
494.51	-48.25	0.178	0.923
494.52	-48.19	0.178	0.923
494.52	-48.12	0.178	0.923
494.53	-48.05	0.178	0.924
494.53	-47.99	0.178	0.924
494.54	-47.92	0.178	0.924
494.55	-47.85	0.178	0.925
494.56	-47.79	0.178	0.925
494.56	-47.72	0.178	0.925
494.57	-47.65	0.178	0.925
494.58	-47.59	0.179	0.926
494.58	-47.52	0.179	0.926
494.59	-47.45	0.179	0.926
494.59	-47.38	0.179	0.926
494.60	-47.32	0.179	0.926
494.61	-47.25	0.179	0.928
494.62	-47.18	0.179	0.928
494.62	-47.12	0.179	0.928
494.63	-47.05	0.179	0.928
494.63	-46.98	0.179	0.929
494.64	-46.92	0.179	0.929
494.65	-46.85	0.179	0.929
494.66	-46.78	0.179	0.929
494.66	-46.72	0.179	0.929
494.67	-46.65	0.179	0.930
494.68	-46.58	0.179	0.930
494.68	-46.52	0.179	0.930
494.69	-46.45	0.179	0.931
494.69	-46.38	0.179	0.931
494.70	-46.32	0.179	0.932
494.71	-46.25	0.179	0.931
494.72	-46.18	0.179	0.932
494.72	-46.12	0.179	0.932
494.73	-46.05	0.179	0.933
494.73	-45.98	0.180	0.933
494.74	-45.91	0.180	0.933
494.75	-45.85	0.180	0.933
494.76	-45.78	0.180	0.933
494.76	-45.72	0.180	0.934
494.77	-45.65	0.180	0.934
494.78	-45.58	0.180	0.934
494.78	-45.51	0.180	0.934
494.79	-45.45	0.180	0.934
494.79	-45.38	0.180	0.935
494.80	-45.32	0.180	0.935
494.81	-45.25	0.180	0.935
494.82	-45.18	0.180	0.936
494.82	-45.11	0.180	0.936
494.83	-45.05	0.180	0.936
494.83	-44.98	0.180	0.936
494.84	-44.91	0.180	0.936
494.85	-44.85	0.180	0.937
494.86	-44.78	0.180	0.937
494.86	-44.71	0.180	0.937
494.87	-44.65	0.180	0.938
494.88	-44.58	0.180	0.938
494.88	-44.51	0.180	0.938
494.89	-44.45	0.180	0.938
494.89	-44.38	0.180	0.938
494.90	-44.31	0.180	0.938
494.91	-44.25	0.180	0.939
494.92	-44.18	0.181	0.939
494.92	-44.11	0.181	0.939
494.93	-44.05	0.181	0.940
494.93	-43.98	0.181	0.940
494.94	-43.91	0.181	0.940
494.95	-43.84	0.181	0.940
494.96	-43.78	0.181	0.941
494.96	-43.71	0.181	0.941
494.97	-43.64	0.181	0.941
494.98	-43.58	0.181	0.941
494.98	-43.51	0.181	0.942
494.99	-43.44	0.181	0.942
494.99	-43.38	0.181	0.942
495.00	-43.31	0.181	0.943
495.01	-43.24	0.181	0.942
495.02	-43.18	0.181	0.942
495.02	-43.11	0.181	0.943
495.03	-43.04	0.181	0.943
495.03	-42.98	0.181	0.944
495.04	-42.91	0.181	0.944
495.05	-42.84	0.181	0.944
495.06	-42.78	0.181	0.945
495.06	-42.71	0.181	0.945
495.07	-42.64	0.181	0.945
495.08	-42.58	0.181	0.945
495.08	-42.51	0.181	0.945
495.09	-42.44	0.181	0.945
495.09	-42.38	0.182	0.946
495.10	-42.31	0.182	0.946
495.11	-42.24	0.182	0.946
495.12	-42.17	0.182	0.946
495.12	-42.11	0.182	0.946
495.13	-42.04	0.182	0.947
495.13	-41.98	0.182	0.947
495.14	-41.91	0.182	0.947
495.15	-41.84	0.182	0.948
495.16	-41.78	0.182	0.948
495.16	-41.71	0.182	0.948
495.17	-41.64	0.182	0.948
495.18	-41.57	0.182	0.948
495.18	-41.51	0.182	0.949
495.19	-41.44	0.182	0.949
495.19	-41.37	0.182	0.949
495.20	-41.31	0.182	0.949
495.21	-41.24	0.182	0.950
495.22	-41.17	0.182	0.951
495.22	-41.11	0.182	0.950
495.23	-41.04	0.182	0.950
495.23	-40.97	0.182	0.951
495.24	-40.91	0.182	0.951
495.25	-40.84	0.182	0.951
495.26	-40.77	0.182	0.952
495.26	-40.71	0.182	0.952
495.27	-40.64	0.182	0.952
495.28	-40.57	0.182	0.952
495.28	-40.51	0.182	0.953
495.29	-40.44	0.183	0.953
495.29	-40.37	0.183	0.953
495.30	-40.30	0.183	0.953
495.31	-40.24	0.183	0.953
495.32	-40.17	0.183	0.954
495.32	-40.11	0.183	0.954
495.33	-40.04	0.183	0.954
495.33	-39.97	0.183	0.955
495.34	-39.90	0.183	0.955
495.35	-39.84	0.183	0.955
495.36	-39.77	0.183	0.955
495.36	-39.70	0.183	0.956
495.37	-39.64	0.183	0.956
495.38	-39.57	0.183	0.956
495.38	-39.50	0.183	0.956
495.39	-39.44	0.183	0.956
495.39	-39.37	0.183	0.956
495.40	-39.30	0.183	0.957
495.41	-39.24	0.183	0.957
495.42	-39.17	0.183	0.957
495.42	-39.10	0.183	0.958
495.43	-39.04	0.183	0.958
495.43	-38.97	0.183	0.959
495.44	-38.90	0.183	0.959
495.45	-38.84	0.183	0.959
495.46	-38.77	0.183	0.959
495.46	-38.70	0.183	0.960
495.47	-38.64	0.184	0.960
495.48	-38.57	0.184	0.960
495.48	-38.50	0.184	0.960
495.49	-38.43	0.184	0.960
495.49	-38.37	0.184	0.961
495.50	-38.30	0.184	0.961
495.51	-38.23	0.184	0.961
495.52	-38.17	0.184	0.962
495.52	-38.10	0.184	0.962
495.53	-38.04	0.184	0.962
495.53	-37.97	0.184	0.962
495.54	-37.90	0.184	0.963
495.55	-37.83	0.184	0.963
495.56	-37.77	0.184	0.963
495.56	-37.70	0.184	0.963
495.57	-37.63	0.184	0.964
495.58	-37.57	0.184	0.964
495.58	-37.50	0.184	0.965
495.59	-37.43	0.184	0.965
495.59	-37.37	0.184	0.965
495.60	-37.30	0.184	0.965
495.61	-37.23	0.184	0.965
495.62	-37.17	0.184	0.966
495.62	-37.10	0.184	0.966
495.63	-37.03	0.184	0.966
495.63	-36.97	0.184	0.966
495.64	-36.90	0.185	0.967
495.65	-36.83	0.185	0.967
495.66	-36.76	0.185	0.967
495.66	-36.70	0.185	0.967
495.67	-36.63	0.185	0.968
495.68	-36.57	0.185	0.968
495.68	-36.50	0.185	0.968
495.69	-36.43	0.185	0.969
495.69	-36.37	0.185	0.969
495.70	-36.30	0.185	0.969
495.71	-36.23	0.185	0.969
495.72	-36.17	0.185	0.970
495.72	-36.10	0.185	0.970
495.73	-36.03	0.185	0.971
495.73	-35.97	0.185	0.971
495.74	-35.90	0.185	0.971
495.75	-35.83	0.185	0.971
495.76	-35.77	0.185	0.972
495.76	-35.70	0.185	0.972
495.77	-35.63	0.185	0.972
495.78	-35.56	0.185	0.972
495.78	-35.50	0.185	0.972
495.79	-35.43	0.185	0.972
495.79	-35.36	0.185	0.972
495.80	-35.30	0.185	0.973
495.81	-35.23	0.185	0.973
495.82	-35.16	0.186	0.974
495.82	-35.10	0.186	0.973
495.83	-35.03	0.186	0.974
495.83	-34.96	0.186	0.974
495.84	-34.90	0.186	0.974
495.85	-34.83	0.186	0.975
495.86	-34.76	0.186	0.975
495.86	-34.70	0.186	0.976
495.87	-34.63	0.186	0.976
495.88	-34.56	0.186	0.976
495.88	-34.50	0.186	0.976
495.89	-34.43	0.186	0.976
495.89	-34.36	0.186	0.977
495.90	-34.30	0.186	0.977
495.91	-34.23	0.186	0.977
495.92	-34.16	0.186	0.977
495.92	-34.10	0.186	0.977
495.93	-34.03	0.186	0.978
495.93	-33.96	0.186	0.978
495.94	-33.89	0.186	0.978
495.95	-33.83	0.186	0.979
495.96	-33.76	0.186	0.979
495.96	-33.69	0.186	0.979
495.97	-33.63	0.186	0.979
495.98	-33.56	0.186	0.979
495.98	-33.49	0.186	0.979
495.99	-33.43	0.186	0.980
495.99	-33.36	0.187	0.980
496.00	-33.30	0.187	0.980
496.01	-33.23	0.187	0.980
496.02	-33.16	0.187	0.980
496.02	-33.10	0.187	0.981
496.03	-33.03	0.187	0.981
496.03	-32.96	0.187	0.982
496.04	-32.89	0.187	0.982
496.05	-32.83	0.187	0.982
496.06	-32.76	0.187	0.982
496.06	-32.69	0.187	0.983
496.07	-32.63	0.187	0.983
496.08	-32.56	0.187	0.983
496.08	-32.49	0.187	0.984
496.09	-32.43	0.187	0.984
496.09	-32.36	0.187	0.984
496.10	-32.29	0.187	0.984
496.11	-32.23	0.187	0.985
496.12	-32.16	0.187	0.985
496.12	-32.09	0.187	0.985
496.13	-32.03	0.187	0.985
496.13	-31.96	0.187	0.986
496.14	-31.89	0.187	0.986
496.15	-31.82	0.187	0.986
496.16	-31.76	0.187	0.986
496.16	-31.69	0.187	0.987
496.17	-31.63	0.187	0.987
496.18	-31.56	0.187	0.987
496.18	-31.49	0.188	0.987
496.19	-31.43	0.188	0.988
496.19	-31.36	0.188	0.988
496.20	-31.29	0.188	0.988
496.21	-31.23	0.188	0.988
496.22	-31.16	0.188	0.989
496.22	-31.09	0.188	0.990
496.23	-31.02	0.188	0.990
496.23	-30.96	0.188	0.991
496.24	-30.89	0.188	0.991
496.25	-30.83	0.188	0.991
496.26	-30.76	0.188	0.991
496.26	-30.69	0.188	0.991
496.27	-30.62	0.188	0.991
496.28	-30.56	0.188	0.991
496.28	-30.49	0.188	0.992
496.29	-30.42	0.188	0.992
496.29	-30.36	0.188	0.993
496.30	-30.29	0.188	0.993
496.31	-30.22	0.188	0.992
496.32	-30.16	0.188	0.993
496.32	-30.09	0.188	0.993
496.33	-30.02	0.188	0.993
496.33	-29.96	0.188	0.993
496.34	-29.89	0.189	0.994
496.35	-29.82	0.189	0.994
496.36	-29.76	0.189	0.994
496.36	-29.69	0.189	0.995
496.37	-29.62	0.189	0.995
496.38	-29.56	0.189	0.995
496.38	-29.49	0.189	0.996
496.39	-29.42	0.189	0.996
496.39	-29.36	0.189	0.996
496.40	-29.29	0.189	0.997
496.41	-29.22	0.189	0.997
496.42	-29.16	0.189	0.997
496.42	-29.09	0.189	0.997
496.43	-29.02	0.189	0.997
496.43	-28.96	0.189	0.998
496.44	-28.89	0.189	0.998
496.45	-28.82	0.189	0.998
496.46	-28.76	0.189	0.999
496.46	-28.69	0.189	0.999
496.47	-28.62	0.189	0.998
496.48	-28.56	0.189	0.999
496.48	-28.49	0.189	0.999
496.49	-28.42	0.189	0.999
496.49	-28.36	0.189	0.999
496.50	-28.29	0.190	1.000
496.51	-28.22	0.190	1.001
496.52	-28.16	0.190	1.001
496.52	-28.09	0.190	1.001
496.53	-28.02	0.190	1.001
496.53	-27.96	0.190	1.002
496.54	-27.89	0.190	1.002
496.55	-27.82	0.190	1.002
496.56	-27.76	0.190	1.002
496.56	-27.69	0.190	1.002
496.57	-27.62	0.190	1.003
496.58	-27.55	0.190	1.003
496.58	-27.49	0.190	1.003
496.59	-27.42	0.190	1.004
496.59	-27.35	0.190	1.004
496.60	-27.29	0.190	1.004
496.61	-27.22	0.190	1.004
496.62	-27.15	0.190	1.004
496.62	-27.09	0.190	1.005
496.63	-27.02	0.190	1.005
496.63	-26.95	0.190	1.005
496.64	-26.89	0.190	1.005
496.65	-26.82	0.190	1.005
496.66	-26.75	0.190	1.005
496.66	-26.69	0.190	1.006
496.67	-26.62	0.191	1.007
496.68	-26.55	0.191	1.007
496.68	-26.49	0.191	1.007
496.69	-26.42	0.191	1.007
496.69	-26.35	0.191	1.007
496.70	-26.29	0.191	1.007
496.71	-26.22	0.191	1.008
496.72	-26.15	0.191	1.009
496.72	-26.09	0.191	1.009
496.73	-26.02	0.191	1.009
496.73	-25.95	0.191	1.009
496.74	-25.89	0.191	1.009
496.75	-25.82	0.191	1.010
496.76	-25.75	0.191	1.010
496.76	-25.69	0.191	1.010
496.77	-25.62	0.191	1.010
496.78	-25.55	0.191	1.011
496.78	-25.49	0.191	1.011
496.79	-25.42	0.191	1.011
496.79	-25.35	0.191	1.011
496.80	-25.28	0.191	1.012
496.81	-25.22	0.191	1.012
496.82	-25.15	0.191	1.012
496.82	-25.08	0.191	1.012
496.83	-25.02	0.192	1.013
496.83	-24.95	0.192	1.013
496.84	-24.88	0.192	1.013
496.85	-24.82	0.192	1.014
496.86	-24.75	0.192	1.014
496.86	-24.68	0.192	1.014
496.87	-24.62	0.192	1.014
496.88	-24.55	0.192	1.015
496.88	-24.48	0.192	1.015
496.89	-24.42	0.192	1.015
496.89	-24.35	0.192	1.015
496.90	-24.28	0.192	1.016
496.91	-24.22	0.192	1.016
496.92	-24.15	0.192	1.016
496.92	-24.08	0.192	1.016
496.93	-24.02	0.192	1.017
496.93	-23.95	0.192	1.017
496.94	-23.88	0.192	1.017
496.95	-23.82	0.192	1.017
496.96	-23.75	0.192	1.017
496.96	-23.68	0.192	1.018
496.97	-23.62	0.192	1.018
496.98	-23.55	0.192	1.018
496.98	-23.48	0.192	1.019
496.99	-23.41	0.192	1.019
496.99	-23.35	0.192	1.019
497.00	-23.28	0.193	1.019
497.01	-23.21	0.193	1.020
497.02	-23.15	0.193	1.020
497.02	-23.08	0.193	1.021
497.03	-23.01	0.193	1.021
497.03	-22.95	0.193	1.021
497.04	-22.88	0.193	1.021
497.05	-22.81	0.193	1.021
497.06	-22.75	0.193	1.022
497.06	-22.68	0.193	1.022
497.07	-22.61	0.193	1.022
497.08	-22.55	0.193	1.023
497.08	-22.48	0.193	1.023
497.09	-22.41	0.193	1.023
497.09	-22.35	0.193	1.023
497.10	-22.28	0.193	1.024
497.11	-22.21	0.193	1.024
497.12	-22.15	0.193	1.024
497.12	-22.08	0.193	1.024
497.13	-22.01	0.193	1.025
497.13	-21.95	0.193	1.025
497.14	-21.88	0.193	1.025
497.15	-21.81	0.194	1.025
497.16	-21.75	0.194	1.026
497.16	-21.68	0.194	1.026
497.17	-21.61	0.194	1.026
497.18	-21.55	0.194	1.026
497.18	-21.48	0.194	1.027
497.19	-21.41	0.194	1.027
497.19	-21.35	0.194	1.027
497.20	-21.28	0.194	1.027
497.21	-21.21	0.194	1.027
497.22	-21.14	0.194	1.028
497.22	-21.08	0.194	1.028
497.23	-21.01	0.194	1.028
497.23	-20.95	0.194	1.028
497.24	-20.88	0.194	1.029
497.25	-20.81	0.194	1.029
497.26	-20.75	0.194	1.029
497.26	-20.68	0.194	1.030
497.27	-20.61	0.194	1.030
497.28	-20.55	0.194	1.030
497.28	-20.48	0.194	1.030
497.29	-20.41	0.194	1.030
497.29	-20.34	0.194	1.031
497.30	-20.28	0.195	1.032
497.31	-20.21	0.195	1.032
497.32	-20.14	0.195	1.032
497.32	-20.08	0.195	1.033
497.33	-20.01	0.195	1.033
497.33	-19.94	0.195	1.033
497.34	-19.88	0.195	1.033
497.35	-19.81	0.195	1.033
497.36	-19.74	0.195	1.033
497.36	-19.68	0.195	1.034
497.37	-19.61	0.195	1.034
497.38	-19.54	0.195	1.034
497.38	-19.48	0.195	1.035
497.39	-19.41	0.195	1.035
497.39	-19.34	0.195	1.035
497.40	-19.28	0.195	1.036
497.41	-19.21	0.195	1.036
497.42	-19.14	0.195	1.036
497.42	-19.08	0.195	1.036
497.43	-19.01	0.195	1.037
497.43	-18.94	0.195	1.037
497.44	-18.88	0.195	1.037
497.45	-18.81	0.195	1.038
497.46	-18.74	0.195	1.038
497.46	-18.68	0.196	1.038
497.47	-18.61	0.196	1.039
497.48	-18.54	0.196	1.038
497.48	-18.48	0.196	1.039
497.49	-18.41	0.196	1.039
497.49	-18.34	0.196	1.039
497.50	-18.27	0.196	1.040
497.51	-18.21	0.196	1.040
497.52	-18.14	0.196	1.040
497.52	-18.07	0.196	1.040
497.53	-18.01	0.196	1.041
497.53	-17.94	0.196	1.041
497.54	-17.88	0.196	1.041
497.55	-17.81	0.196	1.042
497.56	-17.74	0.196	1.042
497.56	-17.68	0.196	1.042
497.57	-17.61	0.196	1.042
497.58	-17.54	0.196	1.043
497.58	-17.47	0.196	1.043
497.59	-17.41	0.196	1.043
497.59	-17.34	0.196	1.043
497.60	-17.27	0.196	1.044
497.61	-17.21	0.197	1.044
497.62	-17.14	0.197	1.045
497.62	-17.07	0.197	1.045
497.63	-17.01	0.197	1.045
497.63	-16.94	0.197	1.045
497.64	-16.87	0.197	1.045
497.65	-16.81	0.197	1.046
497.66	-16.74	0.197	1.046
497.66	-16.67	0.197	1.046
497.67	-16.61	0.197	1.047
497.68	-16.54	0.197	1.047
497.68	-16.47	0.197	1.047
497.69	-16.41	0.197	1.047
497.69	-16.34	0.197	1.047
497.70	-16.27	0.197	1.047
497.71	-16.21	0.197	1.048
497.72	-16.14	0.197	1.048
497.72	-16.07	0.197	1.048
497.73	-16.01	0.197	1.049
497.73	-15.94	0.197	1.049
497.74	-15.87	0.197	1.050
497.75	-15.81	0.197	1.050
497.76	-15.74	0.197	1.050
497.76	-15.67	0.198	1.050
497.77	-15.61	0.198	1.051
497.78	-15.54	0.198	1.051
497.78	-15.47	0.198	1.051
497.79	-15.40	0.198	1.052
497.79	-15.34	0.198	1.052
497.80	-15.27	0.198	1.052
497.81	-15.21	0.198	1.052
497.82	-15.14	0.198	1.053
497.82	-15.07	0.198	1.053
497.83	-15.01	0.198	1.054
497.83	-14.94	0.198	1.054
497.84	-14.87	0.198	1.054
497.85	-14.81	0.198	1.054
497.86	-14.74	0.198	1.054
497.86	-14.67	0.198	1.055
497.87	-14.60	0.198	1.055
497.88	-14.54	0.198	1.055
497.88	-14.47	0.198	1.056
497.89	-14.40	0.198	1.056
497.89	-14.34	0.198	1.056
497.90	-14.27	0.198	1.057
497.91	-14.20	0.198	1.057
497.92	-14.14	0.199	1.057
497.92	-14.07	0.199	1.057
497.93	-14.00	0.199	1.057
497.93	-13.94	0.199	1.058
497.94	-13.87	0.199	1.058
497.95	-13.80	0.199	1.058
497.96	-13.74	0.199	1.058
497.96	-13.67	0.199	1.059
497.97	-13.60	0.199	1.059
497.98	-13.54	0.199	1.059
497.98	-13.47	0.199	1.059
497.99	-13.40	0.199	1.060
497.99	-13.34	0.199	1.061
498.00	-13.27	0.199	1.061
498.01	-13.20	0.199	1.061
498.02	-13.14	0.199	1.061
498.02	-13.07	0.199	1.061
498.03	-13.00	0.199	1.061
498.03	-12.94	0.199	1.061
498.04	-12.87	0.199	1.062
498.05	-12.80	0.199	1.062
498.06	-12.74	0.200	1.063
498.06	-12.67	0.200	1.063
498.07	-12.60	0.200	1.063
498.08	-12.54	0.200	1.064
498.08	-12.47	0.200	1.064
498.09	-12.40	0.200	1.064
498.09	-12.33	0.200	1.064
498.10	-12.27	0.200	1.064
498.11	-12.20	0.200	1.065
498.12	-12.14	0.200	1.065
498.12	-12.07	0.200	1.065
498.13	-12.00	0.200	1.066
498.13	-11.94	0.200	1.066
498.14	-11.87	0.200	1.066
498.15	-11.80	0.200	1.066
498.16	-11.74	0.200	1.067
498.16	-11.67	0.200	1.067
498.17	-11.60	0.200	1.068
498.18	-11.54	0.200	1.068
498.18	-11.47	0.200	1.068
498.19	-11.40	0.200	1.068
498.19	-11.33	0.200	1.069
498.20	-11.27	0.201	1.069
498.21	-11.20	0.201	1.069
498.22	-11.13	0.201	1.070
498.22	-11.07	0.201	1.070
498.23	-11.00	0.201	1.070
498.23	-10.93	0.201	1.070
498.24	-10.87	0.201	1.070
498.25	-10.80	0.201	1.071
498.26	-10.73	0.201	1.071
498.26	-10.67	0.201	1.072
498.27	-10.60	0.201	1.072
498.28	-10.53	0.201	1.072
498.28	-10.47	0.201	1.072
498.29	-10.40	0.201	1.073
498.29	-10.33	0.201	1.073
498.30	-10.27	0.201	1.073
498.31	-10.20	0.201	1.073
498.32	-10.13	0.201	1.073
498.32	-10.07	0.201	1.074
498.33	-10.00	0.201	1.074
498.33	-9.93	0.201	1.074
498.34	-9.87	0.201	1.075
498.35	-9.80	0.202	1.076
498.36	-9.73	0.202	1.076
498.36	-9.67	0.202	1.076
498.37	-9.60	0.202	1.077
498.38	-9.53	0.202	1.077
498.38	-9.47	0.202	1.077
498.39	-9.40	0.202	1.078
498.39	-9.33	0.202	1.078
498.40	-9.27	0.202	1.078
498.41	-9.20	0.202	1.078
498.42	-9.13	0.202	1.078
498.42	-9.07	0.202	1.079
498.43	-9.00	0.202	1.079
498.43	-8.93	0.202	1.080
498.44	-8.86	0.202	1.080
498.45	-8.80	0.202	1.080
498.46	-8.73	0.202	1.080
498.46	-8.67	0.202	1.080
498.47	-8.60	0.203	1.080
498.48	-8.53	0.203	1.080
498.48	-8.46	0.203	1.081
498.49	-8.40	0.203	1.081
498.49	-8.33	0.203	1.082
498.50	-8.26	0.203	1.082
498.51	-8.20	0.203	1.082
498.52	-8.13	0.203	1.082
498.52	-8.06	0.203	1.083
498.53	-8.00	0.203	1.083
498.53	-7.93	0.203	1.084
498.54	-7.87	0.203	1.084
498.55	-7.80	0.203	1.084
498.56	-7.73	0.203	1.084
498.56	-7.66	0.203	1.085
498.57	-7.60	0.203	1.085
498.58	-7.53	0.203	1.085
498.58	-7.46	0.203	1.086
498.59	-7.40	0.204	1.086
498.59	-7.33	0.204	1.086
498.60	-7.26	0.204	1.087
498.61	-7.20	0.204	1.087
498.62	-7.13	0.204	1.087
498.62	-7.06	0.204	1.087
498.63	-7.00	0.204	1.088
498.63	-6.93	0.204	1.088
498.64	-6.86	0.204	1.088
498.65	-6.80	0.204	1.089
498.66	-6.73	0.204	1.089
498.66	-6.66	0.204	1.089
498.67	-6.60	0.204	1.089
498.68	-6.53	0.204	1.090
498.68	-6.46	0.204	1.090
498.69	-6.40	0.204	1.090
498.69	-6.33	0.204	1.090
498.70	-6.26	0.204	1.090
498.71	-6.19	0.204	1.091
498.72	-6.13	0.204	1.091
498.72	-6.06	0.204	1.092
498.73	-6.00	0.204	1.092
498.73	-5.93	0.204	1.092
498.74	-5.86	0.204	1.092
498.75	-5.79	0.205	1.092
498.76	-5.73	0.205	1.093
498.76	-5.66	0.205	1.093
498.77	-5.60	0.205	1.094
498.78	-5.53	0.205	1.094
498.78	-5.46	0.205	1.094
498.79	-5.40	0.205	1.094
498.79	-5.33	0.205	1.096
498.80	-5.26	0.205	1.096
498.81	-5.19	0.205	1.096
498.82	-5.13	0.205	1.096
498.82	-5.06	0.205	1.097
498.83	-4.99	0.205	1.097
498.83	-4.93	0.205	1.097
498.84	-4.86	0.205	1.097
498.85	-4.79	0.205	1.097
498.86	-4.73	0.205	1.097
498.86	-4.66	0.205	1.098
498.87	-4.60	0.205	1.098
498.88	-4.53	0.206	1.098
498.88	-4.46	0.206	1.098
498.89	-4.39	0.206	1.099
498.89	-4.33	0.206	1.099
498.90	-4.26	0.206	1.099
498.91	-4.19	0.206	1.099
498.92	-4.13	0.206	1.100
498.92	-4.06	0.206	1.100
498.93	-3.99	0.206	1.100
498.93	-3.92	0.206	1.100
498.94	-3.86	0.206	1.101
498.95	-3.79	0.206	1.101
498.96	-3.73	0.206	1.102
498.96	-3.66	0.206	1.102
498.97	-3.59	0.206	1.102
498.98	-3.52	0.206	1.102
498.98	-3.46	0.206	1.103
498.99	-3.39	0.206	1.103
498.99	-3.33	0.206	1.103
499.00	-3.26	0.206	1.103
499.01	-3.19	0.206	1.104
499.02	-3.12	0.206	1.104
499.02	-3.06	0.206	1.104
499.03	-2.99	0.206	1.103
499.03	-2.92	0.206	1.104
499.04	-2.86	0.207	1.104
499.05	-2.79	0.207	1.104
499.06	-2.73	0.207	1.105
499.06	-2.66	0.207	1.104
499.07	-2.59	0.207	1.104
499.08	-2.52	0.207	1.105
499.08	-2.46	0.207	1.105
499.09	-2.39	0.207	1.105
499.09	-2.32	0.207	1.105
499.10	-2.26	0.207	1.105
499.11	-2.19	0.207	1.105
499.12	-2.12	0.207	1.105
499.12	-2.06	0.207	1.105
499.13	-1.99	0.207	1.107
499.13	-1.92	0.207	1.107
499.14	-1.86	0.207	1.107
499.15	-1.79	0.207	1.108
499.16	-1.72	0.207	1.108
499.16	-1.66	0.207	1.108
499.17	-1.59	0.207	1.109
499.18	-1.52	0.208	1.109
499.18	-1.46	0.208	1.109
499.19	-1.39	0.208	1.109
499.19	-1.32	0.208	1.110
499.20	-1.26	0.208	1.110
499.21	-1.19	0.208	1.110
499.22	-1.12	0.208	1.110
499.22	-1.05	0.208	1.110
499.23	-0.99	0.208	1.110
499.23	-0.92	0.208	1.111
499.24	-0.86	0.208	1.111
499.25	-0.79	0.208	1.111
499.26	-0.72	0.208	1.112
499.26	-0.65	0.208	1.112
499.27	-0.59	0.208	1.113
499.28	-0.52	0.208	1.113
499.28	-0.46	0.208	1.113
499.29	-0.39	0.208	1.113
499.29	-0.32	0.208	1.113
499.30	-0.26	0.208	1.113
499.31	-0.19	0.208	1.113
499.32	-0.12	0.208	1.114
499.32	-0.05	0.208	1.116
499.33	0.01	0.208	1.116
499.33	0.08	0.208	1.115
499.34	0.15	0.209	1.116
499.35	0.21	0.209	1.116
499.36	0.28	0.209	1.116
499.36	0.35	0.209	1.117
499.37	0.41	0.209	1.117
499.38	0.48	0.209	1.117
499.38	0.55	0.209	1.117
499.39	0.61	0.209	1.117
499.39	0.68	0.209	1.117
499.40	0.75	0.209	1.117
499.41	0.81	0.209	1.117
499.42	0.88	0.209	1.117
499.42	0.95	0.209	1.117
499.43	1.01	0.209	1.119
499.43	1.08	0.209	1.119
499.44	1.15	0.209	1.119
499.45	1.21	0.209	1.119
499.46	1.28	0.209	1.120
499.46	1.35	0.209	1.120
499.47	1.41	0.209	1.120
499.48	1.48	0.209	1.120
499.48	1.55	0.209	1.120
499.49	1.61	0.209	1.120
499.49	1.68	0.209	1.121
499.50	1.75	0.209	1.121
499.51	1.81	0.210	1.122
499.52	1.88	0.210	1.122
499.52	1.95	0.210	1.122
499.53	2.01	0.210
499.53	2.08	0.210
499.54	2.15	0.210
499.55	2.21	0.210
499.56	2.28	0.210
499.56	2.35	0.210
499.57	2.41	0.210
499.58	2.48	0.210
499.58	2.55	0.210
499.59	2.62
499.59	2.68
499.60	2.75
499.61	2.81
499.62	2.88
499.62	2.95
499.63	3.01
499.63	3.08
499.64
499.64