File: DSC/2023_06_19_Adamantane_std.txt
Filename	2023_06_19_Adamantane_std
Instrument name	DSC2A-00468 (192.168.1.100)
Operator	SBK
rundate	6/19/2023
Sample name	2023_06_19_Adamantane_std
proceduresegments	Data Off ; Equilibrate -85.00 °C; Data On ; Ramp 10.00 °C/min to -35.00 °C; Data Off ; Isothermal 1.0 min; Data On ; Ramp 10.00 °C/min to -85.00 °C; Data Off ; Isothermal 1.0 min; Data On ; Ramp 10.00 °C/min to -35.00 °C
[File Parameters]
Run date	6/19/2023 10:09:32 AM
Trios version	5.1.1.46572
Original File Name	C:\Users\yargerlab\Desktop\DSC Data\General\2023_06_19_Adamantane_std.tri
Current File Name	C:\Users\yargerlab\Desktop\DSC Data\General\2023_06_19_Adamantane_std.tri
[Procedure]
Procedure Name	DSC n85C n35C 2 cycle
Sample Name	2023_06_19_Adamantane_std
Sample Mass	4.81 mg
Reference Sample Mass	0 mg
Pan Mass	52.76 mg
Pan Number	47
Reference Pan Mass	53.66 mg
Reference Pan Number	46
Pan Type	Aluminum Hermetic
Comments	Adamantane standard. Aluminum pan with hermetic aluminum lid.
Project Name	Silk ASDs
Operator	SBK
Test	Custom
Unload Max Temperature	30
Unload Min Temperature	30
Load Max Temperature	30
Load Min Temperature	30
Stop on Gas Flow Error	Yes
[Signal List]
Signal #1	Time (min)
Signal #2	Temperature (°C)
Signal #3	Heat Flow (mW)
Signal #4	Delta T (µV)
Signal #5	Delta Tzero (µV)
Signal #6	Tzero Temperature (°C)
Signal #7	Cell Purge (mL/min)
Signal #8	Heater Temp (°C)
Signal #9	Power Delivered (W)
Signal #10	Reference Junction Temperature (°C)
Signal #11	Flange Temperature (°C)
Signal #12	Heat Flow Phase (rad)
Signal #13	Total Heat Capacity (J/°C)
Signal #14	Heat Capacity (J/°C)
[Configuration]
Company Name	ASU
Instrument Name	DSC2A-00468
Instrument Type	DSC2500
Serial Number	DSC2A-00468
IP	192.168.1.100
Location of Instrument	MRRC
DisplayType	Unknown
Sample Interval 	0.1 s/pt
Selected Heat Flow	T4P
Exotherm Direction	Down
Cell Serial	DRC2-00792
Lid Type	Standard
Cooler	RCS 90
Leave Cooler on at End of Sequence	On
Gas 2	Nitrogen
Gas Selected	Channel 1
Flow Rate	50 mL/min
Secondary Purge	On
Licensed Heat Flow	Heat Flow T4P
Modulation Licensed	Yes
[Versions]
Common IDD Version	1
Cortex Version	VER 2.10.2.31
Driver	5.0.0.6
GDM Version	1.0.3.3
TouchscreenVersion	1.0.0.16145
FEP Version	1.2.1.21
FEP Bootloader	2.0.0.5
AutoSampler Version	2.1.1.26
Auto Sampler Bootloader	2.0.0.5
FCM Version	1.1.0.3
FCM Bootloader	2.0.0.5
[Experiment Logs]
Experiment Log Entry # 1	Data On set to 0
Experiment Log Entry # 3	Equilibrate Segment -85 (C) Started
Experiment Log Entry # 5	Air Cool is off.
Experiment Log Entry # 7	Data On set to 1
Experiment Log Entry # 9	Ramp Segment 10 C/min to -35 Started
Experiment Log Entry # 11	Data On set to 0
Experiment Log Entry # 13	Isothermal Segment 1 min started
Experiment Log Entry # 15	Data On set to 1
Experiment Log Entry # 17	Ramp Segment 10 C/min to -85 Started
Experiment Log Entry # 19	Data On set to 0
Experiment Log Entry # 21	Isothermal Segment 1 min started
Experiment Log Entry # 23	Data On set to 1
Experiment Log Entry # 25	Ramp Segment 10 C/min to -35 Started
[Method Log]
Method Log Entry # 1	Data Off
Method Log Entry # 2	Equilibrate -85 °C
Method Log Entry # 3	Data On
Method Log Entry # 4	(Ramp 5468) Ramp 10 °C/minute to -35 °C
Method Log Entry # 5	Data Off
Method Log Entry # 6	Isothermal 1 minutes
Method Log Entry # 7	Data On
Method Log Entry # 8	(Ramp 5472) Ramp 10 °C/minute to -85 °C
Method Log Entry # 9	Data Off
Method Log Entry # 10	Isothermal 1 minutes
Method Log Entry # 11	Data On
Method Log Entry # 12	(Ramp 5476) Ramp 10 °C/minute to -35 °C
Cell Serial	DRC2-00792
[T1 Calibration]
Slope	-0.008529666
Offset	9.636258
Initial Temperature	98.23
GUID	f8bfdadc-4977-4fdf-ba6d-0ba9134940c3
[TZero Calibration]
Date Applied	11/29/2022 4:06:13 PM
Description	From -89.059 °C to 396.009 °C at 20.000°C/min
Gas Type	Nitrogen
Pan Type	None
Source Files 1	C:\Users\yargerlab\Desktop\DSC Data\General\TZero_calibration_11_29_22_2nd(2).tri
Source Files 2	C:\Users\yargerlab\Desktop\DSC Data\General\TZero_calibration_11_29_22_2nd(3).tri
Delta T Offset	13.05235
Delta T Slope	-0.007271007
Delta T0 Offset	-13.69128
Delta T0 Slope	0.06063341
[Temperature Calibration]
Date Applied	11/29/2022 7:12:28 PM
Description	From 106.590 °C to 186.590 °C at 10.000°C/min
Gas Type	Nitrogen
Pan Type	Tzero Aluminum Hermetic
Source Files 1	C:\Users\yargerlab\Desktop\DSC Data\General\Indium(6).tri
Measured 1	157.391
Known 1	156.598
[Cell Constant Calibration]
Date Applied	11/29/2022 7:12:29 PM
Description	From 106.590 °C to 186.590 °C at 10.000°C/min
Gas Type	Nitrogen
Pan Type	Tzero Aluminum Hermetic
Source Files 1	C:\Users\yargerlab\Desktop\DSC Data\General\Indium(6).tri
T4P KCell	1.006051
Onset Slope	63.26126 mW/°C
[Direct Cp Calibration]
Date Applied	11/30/2022 11:04:51 AM
Description	From -79.983 °C to 298.409 °C at 10.000°C/min
Gas Type	Nitrogen
Pan Type	Tzero Aluminum Hermetic
Source Files 1	C:\Users\yargerlab\Desktop\DSC Data\General\Sapphire_Heat_Capacity_11_30_22.tri
[Rev Cp Calibration]
Date Applied	11/30/2022 1:58:51 PM
Description	From -79.996 °C to 292.812 °C at 3.000°C/min
Gas Type	Nitrogen
Pan Type	Tzero Aluminum Hermetic
Source Files 1	C:\Users\yargerlab\Desktop\DSC Data\General\Sapphire_MDSC_Calibration_11_30_22.tri
[step]
Ramp 10.00 °C/min to -35.00 °C
Time	Temperature	Heat Flow (Normalized)
min	°C	W/g
0.00	-84.74	-0.017
0.00	-84.75	-0.017
0.01	-84.75	-0.017
0.01	-84.75	-0.016
0.01	-84.75	-0.016
0.02	-84.75	-0.015
0.02	-84.75	-0.015
0.02	-84.75	-0.015
0.03	-84.76	-0.015
0.03	-84.76	-0.014
0.03	-84.76	-0.014
0.04	-84.76	-0.013
0.04	-84.75	-0.013
0.04	-84.76	-0.012
0.05	-84.75	-0.012
0.05	-84.75	-0.012
0.05	-84.75	-0.012
0.06	-84.75	-0.012
0.06	-84.74	-0.012
0.06	-84.73	-0.012
0.07	-84.73	-0.012
0.07	-84.72	-0.012
0.07	-84.71	-0.012
0.08	-84.71	-0.012
0.08	-84.70	-0.013
0.08	-84.69	-0.014
0.09	-84.68	-0.016
0.09	-84.66	-0.018
0.09	-84.65	-0.021
0.10	-84.64	-0.024
0.10	-84.62	-0.027
0.10	-84.61	-0.028
0.11	-84.59	-0.030
0.11	-84.57	-0.031
0.11	-84.56	-0.032
0.12	-84.54	-0.034
0.12	-84.52	-0.034
0.12	-84.50	-0.035
0.13	-84.48	-0.035
0.13	-84.46	-0.035
0.13	-84.44	-0.035
0.14	-84.42	-0.036
0.14	-84.40	-0.036
0.14	-84.37	-0.036
0.15	-84.35	-0.035
0.15	-84.33	-0.035
0.15	-84.30	-0.035
0.16	-84.28	-0.035
0.16	-84.26	-0.034
0.16	-84.23	-0.034
0.17	-84.21	-0.033
0.17	-84.18	-0.032
0.17	-84.16	-0.031
0.18	-84.13	-0.029
0.18	-84.11	-0.025
0.18	-84.08	-0.019
0.19	-84.06	-0.015
0.19	-84.03	-0.010
0.19	-84.00	-0.008
0.20	-83.98	-0.006
0.20	-83.95	-0.004
0.20	-83.92	-0.001
0.21	-83.90	0.001
0.21	-83.87	0.004
0.21	-83.85	0.004
0.22	-83.82	0.005
0.22	-83.79	0.009
0.22	-83.76	0.011
0.23	-83.74	0.013
0.23	-83.71	0.015
0.23	-83.68	0.017
0.24	-83.66	0.019
0.24	-83.63	0.021
0.24	-83.60	0.023
0.25	-83.57	0.026
0.25	-83.55	0.028
0.25	-83.52	0.028
0.26	-83.49	0.028
0.26	-83.46	0.029
0.26	-83.43	0.030
0.27	-83.40	0.031
0.27	-83.38	0.033
0.27	-83.34	0.036
0.28	-83.32	0.038
0.28	-83.29	0.040
0.28	-83.26	0.042
0.29	-83.23	0.042
0.29	-83.20	0.044
0.29	-83.17	0.045
0.30	-83.14	0.044
0.30	-83.11	0.045
0.30	-83.08	0.046
0.31	-83.05	0.049
0.31	-83.02	0.050
0.31	-82.99	0.051
0.32	-82.96	0.051
0.32	-82.93	0.052
0.32	-82.90	0.052
0.33	-82.87	0.054
0.33	-82.84	0.055
0.33	-82.81	0.056
0.34	-82.78	0.058
0.34	-82.75	0.060
0.34	-82.72	0.061
0.35	-82.69	0.061
0.35	-82.66	0.061
0.35	-82.63	0.063
0.36	-82.60	0.064
0.36	-82.57	0.066
0.36	-82.54	0.067
0.37	-82.51	0.067
0.37	-82.47	0.067
0.37	-82.44	0.067
0.38	-82.41	0.068
0.38	-82.38	0.069
0.38	-82.35	0.070
0.39	-82.32	0.072
0.39	-82.29	0.072
0.39	-82.26	0.073
0.40	-82.23	0.074
0.40	-82.20	0.074
0.40	-82.17	0.075
0.41	-82.13	0.076
0.41	-82.10	0.076
0.41	-82.07	0.076
0.42	-82.04	0.077
0.42	-82.01	0.077
0.42	-81.97	0.078
0.43	-81.94	0.078
0.43	-81.91	0.079
0.43	-81.88	0.079
0.44	-81.85	0.080
0.44	-81.82	0.080
0.44	-81.79	0.081
0.45	-81.75	0.082
0.45	-81.72	0.082
0.45	-81.69	0.082
0.46	-81.66	0.082
0.46	-81.63	0.083
0.46	-81.59	0.084
0.47	-81.56	0.085
0.47	-81.53	0.085
0.47	-81.50	0.085
0.48	-81.47	0.085
0.48	-81.43	0.086
0.48	-81.40	0.086
0.49	-81.37	0.086
0.49	-81.34	0.087
0.49	-81.31	0.087
0.50	-81.28	0.087
0.50	-81.24	0.088
0.50	-81.21	0.088
0.51	-81.18	0.088
0.51	-81.15	0.088
0.51	-81.12	0.088
0.52	-81.08	0.089
0.52	-81.05	0.089
0.52	-81.02	0.090
0.53	-80.99	0.090
0.53	-80.96	0.091
0.53	-80.92	0.091
0.54	-80.89	0.091
0.54	-80.86	0.091
0.54	-80.83	0.091
0.55	-80.79	0.092
0.55	-80.76	0.092
0.55	-80.73	0.092
0.56	-80.70	0.092
0.56	-80.66	0.092
0.56	-80.63	0.092
0.57	-80.60	0.092
0.57	-80.57	0.092
0.57	-80.53	0.093
0.58	-80.50	0.093
0.58	-80.47	0.093
0.58	-80.44	0.093
0.59	-80.41	0.094
0.59	-80.37	0.094
0.59	-80.34	0.094
0.60	-80.31	0.094
0.60	-80.28	0.094
0.60	-80.24	0.094
0.61	-80.21	0.094
0.61	-80.18	0.094
0.61	-80.14	0.094
0.62	-80.11	0.094
0.62	-80.08	0.094
0.62	-80.05	0.095
0.63	-80.02	0.095
0.63	-79.98	0.095
0.63	-79.95	0.095
0.64	-79.92	0.095
0.64	-79.88	0.095
0.64	-79.85	0.095
0.65	-79.82	0.095
0.65	-79.79	0.095
0.65	-79.75	0.095
0.66	-79.72	0.095
0.66	-79.69	0.095
0.66	-79.66	0.095
0.67	-79.62	0.096
0.67	-79.59	0.096
0.67	-79.56	0.096
0.68	-79.53	0.096
0.68	-79.49	0.096
0.68	-79.46	0.096
0.69	-79.43	0.096
0.69	-79.40	0.096
0.69	-79.36	0.097
0.70	-79.33	0.097
0.70	-79.30	0.097
0.70	-79.26	0.097
0.71	-79.23	0.097
0.71	-79.20	0.097
0.71	-79.17	0.097
0.72	-79.13	0.097
0.72	-79.10	0.097
0.72	-79.07	0.097
0.73	-79.03	0.097
0.73	-79.00	0.098
0.73	-78.97	0.098
0.74	-78.94	0.098
0.74	-78.90	0.098
0.74	-78.87	0.098
0.75	-78.84	0.098
0.75	-78.81	0.098
0.75	-78.77	0.098
0.76	-78.74	0.098
0.76	-78.71	0.098
0.76	-78.67	0.098
0.77	-78.64	0.098
0.77	-78.61	0.098
0.77	-78.58	0.098
0.78	-78.54	0.098
0.78	-78.51	0.099
0.78	-78.48	0.099
0.79	-78.44	0.099
0.79	-78.41	0.099
0.79	-78.38	0.099
0.80	-78.35	0.099
0.80	-78.31	0.099
0.80	-78.28	0.099
0.81	-78.25	0.099
0.81	-78.21	0.099
0.81	-78.18	0.099
0.82	-78.15	0.099
0.82	-78.12	0.099
0.82	-78.08	0.099
0.83	-78.05	0.099
0.83	-78.02	0.099
0.83	-77.99	0.099
0.84	-77.95	0.100
0.84	-77.92	0.100
0.84	-77.89	0.100
0.85	-77.85	0.100
0.85	-77.82	0.100
0.85	-77.79	0.100
0.86	-77.75	0.100
0.86	-77.72	0.100
0.86	-77.69	0.100
0.87	-77.65	0.100
0.87	-77.62	0.100
0.87	-77.59	0.100
0.88	-77.56	0.100
0.88	-77.52	0.100
0.88	-77.49	0.100
0.89	-77.46	0.100
0.89	-77.42	0.100
0.89	-77.39	0.100
0.90	-77.36	0.100
0.90	-77.32	0.100
0.90	-77.29	0.101
0.91	-77.26	0.101
0.91	-77.23	0.101
0.91	-77.19	0.101
0.92	-77.16	0.101
0.92	-77.13	0.101
0.92	-77.09	0.101
0.93	-77.06	0.101
0.93	-77.03	0.101
0.93	-77.00	0.101
0.94	-76.96	0.101
0.94	-76.93	0.101
0.94	-76.90	0.101
0.95	-76.86	0.101
0.95	-76.83	0.101
0.95	-76.80	0.101
0.96	-76.76	0.101
0.96	-76.73	0.101
0.96	-76.70	0.101
0.97	-76.66	0.101
0.97	-76.63	0.101
0.97	-76.60	0.101
0.98	-76.57	0.101
0.98	-76.53	0.102
0.98	-76.50	0.102
0.99	-76.47	0.102
0.99	-76.43	0.102
0.99	-76.40	0.102
1.00	-76.37	0.102
1.00	-76.33	0.102
1.00	-76.30	0.102
1.01	-76.27	0.102
1.01	-76.23	0.102
1.01	-76.20	0.102
1.02	-76.17	0.102
1.02	-76.14	0.102
1.02	-76.10	0.102
1.03	-76.07	0.102
1.03	-76.04	0.102
1.03	-76.00	0.102
1.04	-75.97	0.102
1.04	-75.94	0.102
1.04	-75.90	0.102
1.05	-75.87	0.102
1.05	-75.84	0.102
1.05	-75.81	0.102
1.06	-75.77	0.103
1.06	-75.74	0.103
1.06	-75.71	0.103
1.07	-75.67	0.103
1.07	-75.64	0.103
1.07	-75.61	0.103
1.08	-75.57	0.103
1.08	-75.54	0.103
1.08	-75.51	0.103
1.09	-75.47	0.103
1.09	-75.44	0.103
1.09	-75.41	0.103
1.10	-75.37	0.103
1.10	-75.34	0.103
1.10	-75.31	0.103
1.11	-75.28	0.103
1.11	-75.24	0.103
1.11	-75.21	0.103
1.12	-75.18	0.103
1.12	-75.14	0.103
1.12	-75.11	0.103
1.13	-75.08	0.103
1.13	-75.04	0.103
1.13	-75.01	0.103
1.14	-74.98	0.103
1.14	-74.94	0.103
1.14	-74.91	0.104
1.15	-74.88	0.104
1.15	-74.85	0.104
1.15	-74.81	0.104
1.16	-74.78	0.104
1.16	-74.75	0.104
1.16	-74.71	0.104
1.17	-74.68	0.104
1.17	-74.65	0.104
1.17	-74.61	0.104
1.18	-74.58	0.104
1.18	-74.55	0.104
1.18	-74.51	0.104
1.19	-74.48	0.104
1.19	-74.45	0.104
1.19	-74.41	0.104
1.20	-74.38	0.104
1.20	-74.35	0.104
1.20	-74.31	0.104
1.21	-74.28	0.104
1.21	-74.25	0.104
1.21	-74.21	0.104
1.22	-74.18	0.104
1.22	-74.15	0.104
1.22	-74.12	0.104
1.23	-74.08	0.104
1.23	-74.05	0.104
1.23	-74.01	0.104
1.24	-73.98	0.105
1.24	-73.95	0.105
1.24	-73.92	0.105
1.25	-73.88	0.105
1.25	-73.85	0.105
1.25	-73.82	0.105
1.26	-73.78	0.105
1.26	-73.75	0.105
1.26	-73.72	0.105
1.27	-73.68	0.105
1.27	-73.65	0.105
1.27	-73.62	0.105
1.28	-73.58	0.105
1.28	-73.55	0.105
1.28	-73.52	0.105
1.29	-73.48	0.105
1.29	-73.45	0.105
1.29	-73.42	0.105
1.30	-73.39	0.105
1.30	-73.35	0.105
1.30	-73.32	0.106
1.31	-73.28	0.106
1.31	-73.25	0.106
1.31	-73.22	0.106
1.32	-73.19	0.106
1.32	-73.15	0.106
1.32	-73.12	0.106
1.33	-73.09	0.106
1.33	-73.05	0.106
1.33	-73.02	0.106
1.34	-72.99	0.106
1.34	-72.95	0.106
1.34	-72.92	0.106
1.35	-72.89	0.106
1.35	-72.85	0.106
1.35	-72.82	0.106
1.36	-72.79	0.106
1.36	-72.75	0.106
1.36	-72.72	0.106
1.37	-72.69	0.106
1.37	-72.66	0.106
1.37	-72.62	0.106
1.38	-72.59	0.106
1.38	-72.55	0.106
1.38	-72.52	0.106
1.39	-72.49	0.106
1.39	-72.46	0.107
1.39	-72.42	0.107
1.40	-72.39	0.107
1.40	-72.36	0.107
1.40	-72.32	0.107
1.41	-72.29	0.107
1.41	-72.26	0.107
1.41	-72.23	0.107
1.42	-72.19	0.107
1.42	-72.16	0.107
1.42	-72.12	0.107
1.43	-72.09	0.107
1.43	-72.06	0.107
1.43	-72.02	0.107
1.44	-71.99	0.108
1.44	-71.96	0.108
1.44	-71.92	0.108
1.45	-71.89	0.108
1.45	-71.86	0.108
1.45	-71.83	0.108
1.46	-71.79	0.108
1.46	-71.76	0.108
1.46	-71.73	0.108
1.47	-71.69	0.108
1.47	-71.66	0.108
1.47	-71.63	0.108
1.48	-71.59	0.108
1.48	-71.56	0.108
1.48	-71.53	0.108
1.49	-71.49	0.108
1.49	-71.46	0.108
1.49	-71.43	0.108
1.50	-71.39	0.109
1.50	-71.36	0.109
1.50	-71.33	0.109
1.51	-71.29	0.109
1.51	-71.26	0.109
1.51	-71.23	0.109
1.52	-71.19	0.109
1.52	-71.16	0.109
1.52	-71.13	0.109
1.53	-71.09	0.109
1.53	-71.06	0.109
1.53	-71.03	0.110
1.54	-70.99	0.110
1.54	-70.96	0.110
1.54	-70.93	0.110
1.55	-70.90	0.110
1.55	-70.86	0.110
1.55	-70.83	0.110
1.56	-70.80	0.110
1.56	-70.76	0.110
1.56	-70.73	0.110
1.57	-70.70	0.110
1.57	-70.66	0.110
1.57	-70.63	0.110
1.58	-70.60	0.110
1.58	-70.56	0.110
1.58	-70.53	0.110
1.59	-70.50	0.111
1.59	-70.46	0.111
1.59	-70.43	0.111
1.60	-70.40	0.111
1.60	-70.36	0.111
1.60	-70.33	0.111
1.61	-70.30	0.111
1.61	-70.26	0.111
1.61	-70.23	0.111
1.62	-70.20	0.111
1.62	-70.16	0.112
1.62	-70.13	0.112
1.63	-70.10	0.112
1.63	-70.06	0.112
1.63	-70.03	0.112
1.64	-70.00	0.112
1.64	-69.96	0.112
1.64	-69.93	0.112
1.65	-69.90	0.112
1.65	-69.86	0.112
1.65	-69.83	0.113
1.66	-69.80	0.113
1.66	-69.77	0.113
1.66	-69.73	0.113
1.67	-69.70	0.113
1.67	-69.67	0.113
1.67	-69.63	0.113
1.68	-69.60	0.114
1.68	-69.57	0.114
1.68	-69.53	0.114
1.69	-69.50	0.114
1.69	-69.47	0.114
1.69	-69.43	0.114
1.70	-69.40	0.115
1.70	-69.37	0.115
1.70	-69.33	0.115
1.71	-69.30	0.115
1.71	-69.27	0.115
1.71	-69.23	0.116
1.72	-69.20	0.116
1.72	-69.17	0.116
1.72	-69.14	0.116
1.73	-69.10	0.116
1.73	-69.07	0.116
1.73	-69.04	0.116
1.74	-69.00	0.116
1.74	-68.97	0.117
1.74	-68.94	0.117
1.75	-68.90	0.117
1.75	-68.87	0.118
1.75	-68.84	0.118
1.76	-68.80	0.118
1.76	-68.77	0.119
1.76	-68.74	0.119
1.77	-68.70	0.119
1.77	-68.67	0.119
1.77	-68.64	0.119
1.78	-68.60	0.119
1.78	-68.57	0.119
1.78	-68.54	0.120
1.79	-68.50	0.120
1.79	-68.47	0.120
1.79	-68.44	0.120
1.80	-68.40	0.121
1.80	-68.37	0.122
1.80	-68.34	0.123
1.81	-68.30	0.123
1.81	-68.27	0.123
1.81	-68.24	0.123
1.82	-68.21	0.124
1.82	-68.17	0.124
1.82	-68.14	0.124
1.83	-68.11	0.124
1.83	-68.07	0.124
1.83	-68.04	0.125
1.84	-68.00	0.126
1.84	-67.97	0.127
1.84	-67.94	0.127
1.85	-67.91	0.127
1.85	-67.87	0.128
1.85	-67.84	0.128
1.86	-67.81	0.128
1.86	-67.77	0.128
1.86	-67.74	0.129
1.87	-67.71	0.130
1.87	-67.67	0.132
1.87	-67.64	0.133
1.88	-67.61	0.134
1.88	-67.57	0.135
1.88	-67.54	0.135
1.89	-67.51	0.136
1.89	-67.48	0.136
1.89	-67.44	0.137
1.90	-67.41	0.138
1.90	-67.38	0.138
1.90	-67.34	0.139
1.91	-67.31	0.139
1.91	-67.28	0.140
1.91	-67.24	0.141
1.92	-67.21	0.142
1.92	-67.18	0.143
1.92	-67.15	0.144
1.93	-67.11	0.146
1.93	-67.08	0.147
1.93	-67.05	0.148
1.94	-67.01	0.149
1.94	-66.98	0.150
1.94	-66.95	0.151
1.95	-66.91	0.152
1.95	-66.88	0.153
1.95	-66.85	0.154
1.96	-66.82	0.156
1.96	-66.78	0.157
1.96	-66.75	0.158
1.97	-66.72	0.159
1.97	-66.68	0.159
1.97	-66.65	0.160
1.98	-66.62	0.162
1.98	-66.59	0.165
1.98	-66.55	0.168
1.99	-66.52	0.171
1.99	-66.49	0.173
1.99	-66.46	0.174
2.00	-66.42	0.178
2.00	-66.39	0.180
2.00	-66.36	0.185
2.01	-66.32	0.188
2.01	-66.29	0.193
2.01	-66.26	0.199
2.02	-66.23	0.202
2.02	-66.19	0.206
2.02	-66.16	0.211
2.03	-66.13	0.215
2.03	-66.10	0.220
2.03	-66.06	0.222
2.04	-66.03	0.225
2.04	-66.00	0.228
2.04	-65.97	0.231
2.05	-65.94	0.235
2.05	-65.90	0.238
2.05	-65.87	0.240
2.06	-65.84	0.244
2.06	-65.81	0.246
2.06	-65.78	0.248
2.07	-65.74	0.248
2.07	-65.71	0.249
2.07	-65.68	0.251
2.08	-65.65	0.254
2.08	-65.61	0.256
2.08	-65.58	0.258
2.09	-65.55	0.260
2.09	-65.52	0.262
2.09	-65.49	0.264
2.10	-65.45	0.266
2.10	-65.42	0.269
2.10	-65.39	0.271
2.11	-65.36	0.273
2.11	-65.32	0.276
2.11	-65.29	0.278
2.12	-65.26	0.280
2.12	-65.23	0.283
2.12	-65.19	0.285
2.13	-65.16	0.289
2.13	-65.13	0.292
2.13	-65.10	0.294
2.14	-65.07	0.298
2.14	-65.03	0.303
2.14	-65.00	0.307
2.15	-64.97	0.312
2.15	-64.94	0.317
2.15	-64.91	0.320
2.16	-64.87	0.325
2.16	-64.84	0.329
2.16	-64.81	0.333
2.17	-64.78	0.338
2.17	-64.75	0.343
2.17	-64.71	0.348
2.18	-64.68	0.353
2.18	-64.65	0.357
2.18	-64.62	0.362
2.19	-64.59	0.366
2.19	-64.55	0.370
2.19	-64.52	0.375
2.20	-64.49	0.381
2.20	-64.46	0.386
2.20	-64.43	0.390
2.21	-64.40	0.394
2.21	-64.37	0.398
2.21	-64.33	0.402
2.22	-64.30	0.407
2.22	-64.27	0.414
2.22	-64.24	0.420
2.23	-64.21	0.424
2.23	-64.18	0.429
2.23	-64.15	0.434
2.24	-64.11	0.438
2.24	-64.08	0.443
2.24	-64.05	0.448
2.25	-64.02	0.452
2.25	-63.99	0.458
2.25	-63.96	0.464
2.26	-63.93	0.470
2.26	-63.90	0.476
2.26	-63.86	0.481
2.27	-63.83	0.486
2.27	-63.80	0.491
2.27	-63.77	0.494
2.28	-63.74	0.499
2.28	-63.71	0.506
2.28	-63.68	0.512
2.29	-63.65	0.517
2.29	-63.61	0.523
2.29	-63.58	0.527
2.30	-63.55	0.532
2.30	-63.52	0.538
2.30	-63.49	0.542
2.31	-63.46	0.546
2.31	-63.43	0.551
2.31	-63.40	0.558
2.32	-63.36	0.564
2.32	-63.33	0.569
2.32	-63.30	0.573
2.33	-63.27	0.577
2.33	-63.24	0.582
2.33	-63.21	0.588
2.34	-63.18	0.594
2.34	-63.15	0.599
2.34	-63.12	0.604
2.35	-63.08	0.609
2.35	-63.05	0.613
2.35	-63.02	0.617
2.36	-62.99	0.623
2.36	-62.96	0.627
2.36	-62.93	0.632
2.37	-62.90	0.637
2.37	-62.87	0.642
2.37	-62.83	0.645
2.38	-62.80	0.649
2.38	-62.77	0.653
2.38	-62.74	0.658
2.39	-62.71	0.663
2.39	-62.68	0.669
2.39	-62.65	0.673
2.40	-62.62	0.677
2.40	-62.59	0.682
2.40	-62.55	0.685
2.41	-62.52	0.689
2.41	-62.49	0.694
2.41	-62.46	0.698
2.42	-62.43	0.700
2.42	-62.40	0.705
2.42	-62.36	0.710
2.43	-62.34	0.715
2.43	-62.30	0.719
2.43	-62.27	0.721
2.44	-62.24	0.724
2.44	-62.21	0.726
2.44	-62.18	0.730
2.45	-62.15	0.734
2.45	-62.11	0.738
2.45	-62.08	0.742
2.46	-62.05	0.744
2.46	-62.02	0.747
2.46	-61.99	0.750
2.47	-61.95	0.753
2.47	-61.92	0.757
2.47	-61.89	0.760
2.48	-61.86	0.763
2.48	-61.83	0.766
2.48	-61.80	0.768
2.49	-61.76	0.770
2.49	-61.73	0.772
2.49	-61.70	0.775
2.50	-61.67	0.778
2.50	-61.64	0.780
2.50	-61.61	0.781
2.51	-61.57	0.783
2.51	-61.54	0.786
2.51	-61.51	0.787
2.52	-61.48	0.789
2.52	-61.45	0.790
2.52	-61.41	0.791
2.53	-61.38	0.792
2.53	-61.35	0.793
2.53	-61.32	0.793
2.54	-61.28	0.794
2.54	-61.25	0.795
2.54	-61.22	0.795
2.55	-61.19	0.794
2.55	-61.16	0.793
2.55	-61.12	0.791
2.56	-61.09	0.790
2.56	-61.06	0.790
2.56	-61.02	0.789
2.57	-60.99	0.788
2.57	-60.96	0.785
2.57	-60.92	0.782
2.58	-60.89	0.778
2.58	-60.86	0.775
2.58	-60.83	0.771
2.59	-60.79	0.766
2.59	-60.76	0.760
2.59	-60.73	0.754
2.60	-60.69	0.747
2.60	-60.66	0.741
2.60	-60.62	0.735
2.61	-60.59	0.728
2.61	-60.56	0.720
2.61	-60.52	0.711
2.62	-60.49	0.702
2.62	-60.45	0.692
2.62	-60.42	0.681
2.63	-60.38	0.670
2.63	-60.35	0.657
2.63	-60.31	0.646
2.64	-60.28	0.634
2.64	-60.24	0.622
2.64	-60.20	0.608
2.65	-60.17	0.594
2.65	-60.13	0.582
2.65	-60.10	0.569
2.66	-60.06	0.557
2.66	-60.02	0.545
2.66	-59.99	0.532
2.67	-59.95	0.519
2.67	-59.91	0.507
2.67	-59.88	0.495
2.68	-59.84	0.485
2.68	-59.80	0.476
2.68	-59.76	0.465
2.69	-59.73	0.454
2.69	-59.69	0.443
2.69	-59.65	0.433
2.70	-59.61	0.423
2.70	-59.58	0.415
2.70	-59.54	0.406
2.71	-59.50	0.397
2.71	-59.47	0.388
2.71	-59.43	0.381
2.72	-59.39	0.373
2.72	-59.36	0.365
2.72	-59.32	0.359
2.73	-59.28	0.351
2.73	-59.24	0.344
2.73	-59.21	0.338
2.74	-59.17	0.329
2.74	-59.13	0.322
2.74	-59.10	0.318
2.75	-59.06	0.312
2.75	-59.02	0.308
2.75	-58.99	0.303
2.76	-58.95	0.296
2.76	-58.91	0.290
2.76	-58.88	0.284
2.77	-58.84	0.280
2.77	-58.80	0.276
2.77	-58.77	0.271
2.78	-58.73	0.266
2.78	-58.70	0.262
2.78	-58.66	0.257
2.79	-58.62	0.254
2.79	-58.59	0.249
2.79	-58.55	0.245
2.80	-58.51	0.241
2.80	-58.48	0.237
2.80	-58.44	0.234
2.81	-58.41	0.231
2.81	-58.37	0.228
2.81	-58.34	0.225
2.82	-58.30	0.222
2.82	-58.26	0.218
2.82	-58.23	0.214
2.83	-58.19	0.212
2.83	-58.16	0.209
2.83	-58.12	0.206
2.84	-58.09	0.203
2.84	-58.05	0.201
2.84	-58.02	0.199
2.85	-57.98	0.197
2.85	-57.95	0.195
2.85	-57.91	0.192
2.86	-57.88	0.188
2.86	-57.84	0.186
2.86	-57.81	0.184
2.87	-57.77	0.183
2.87	-57.73	0.181
2.87	-57.70	0.178
2.88	-57.67	0.175
2.88	-57.63	0.174
2.88	-57.60	0.173
2.89	-57.56	0.172
2.89	-57.53	0.171
2.89	-57.49	0.168
2.90	-57.46	0.165
2.90	-57.42	0.163
2.90	-57.39	0.162
2.91	-57.35	0.161
2.91	-57.32	0.161
2.91	-57.29	0.159
2.92	-57.25	0.157
2.92	-57.22	0.156
2.92	-57.18	0.156
2.93	-57.15	0.155
2.93	-57.11	0.154
2.93	-57.08	0.151
2.94	-57.04	0.149
2.94	-57.01	0.149
2.94	-56.98	0.148
2.95	-56.94	0.147
2.95	-56.91	0.146
2.95	-56.87	0.144
2.96	-56.84	0.142
2.96	-56.80	0.142
2.96	-56.77	0.141
2.97	-56.74	0.141
2.97	-56.70	0.140
2.97	-56.67	0.139
2.98	-56.63	0.138
2.98	-56.60	0.137
2.98	-56.57	0.137
2.99	-56.53	0.137
2.99	-56.50	0.137
2.99	-56.46	0.136
3.00	-56.43	0.135
3.00	-56.40	0.134
3.00	-56.36	0.133
3.01	-56.33	0.133
3.01	-56.30	0.133
3.01	-56.26	0.132
3.02	-56.23	0.132
3.02	-56.19	0.131
3.02	-56.16	0.130
3.03	-56.13	0.130
3.03	-56.09	0.129
3.03	-56.06	0.129
3.04	-56.03	0.128
3.04	-55.99	0.128
3.04	-55.96	0.127
3.05	-55.92	0.127
3.05	-55.89	0.127
3.05	-55.86	0.126
3.06	-55.82	0.126
3.06	-55.79	0.126
3.06	-55.75	0.126
3.07	-55.72	0.125
3.07	-55.69	0.125
3.07	-55.65	0.124
3.08	-55.62	0.124
3.08	-55.58	0.124
3.08	-55.55	0.124
3.09	-55.52	0.124
3.09	-55.48	0.123
3.09	-55.45	0.122
3.10	-55.42	0.121
3.10	-55.38	0.121
3.10	-55.35	0.121
3.11	-55.31	0.121
3.11	-55.28	0.121
3.11	-55.25	0.120
3.12	-55.21	0.120
3.12	-55.18	0.120
3.12	-55.15	0.120
3.13	-55.11	0.120
3.13	-55.08	0.120
3.13	-55.05	0.120
3.14	-55.01	0.120
3.14	-54.98	0.119
3.14	-54.95	0.119
3.15	-54.91	0.118
3.15	-54.88	0.118
3.15	-54.85	0.118
3.16	-54.81	0.118
3.16	-54.78	0.118
3.16	-54.74	0.118
3.17	-54.71	0.118
3.17	-54.68	0.117
3.17	-54.64	0.117
3.18	-54.61	0.117
3.18	-54.58	0.117
3.18	-54.54	0.117
3.19	-54.51	0.117
3.19	-54.48	0.117
3.19	-54.44	0.117
3.20	-54.41	0.117
3.20	-54.38	0.117
3.20	-54.34	0.117
3.21	-54.31	0.117
3.21	-54.28	0.117
3.21	-54.24	0.117
3.22	-54.21	0.117
3.22	-54.18	0.116
3.22	-54.14	0.116
3.23	-54.11	0.116
3.23	-54.07	0.116
3.23	-54.04	0.116
3.24	-54.01	0.116
3.24	-53.97	0.116
3.24	-53.94	0.116
3.25	-53.91	0.116
3.25	-53.87	0.116
3.25	-53.84	0.116
3.26	-53.81	0.116
3.26	-53.77	0.116
3.26	-53.74	0.116
3.27	-53.71	0.116
3.27	-53.67	0.115
3.27	-53.64	0.115
3.28	-53.61	0.115
3.28	-53.57	0.115
3.28	-53.54	0.115
3.29	-53.50	0.115
3.29	-53.47	0.115
3.29	-53.44	0.115
3.30	-53.41	0.115
3.30	-53.37	0.115
3.30	-53.34	0.115
3.31	-53.30	0.115
3.31	-53.27	0.115
3.31	-53.24	0.115
3.32	-53.21	0.115
3.32	-53.17	0.115
3.32	-53.14	0.115
3.33	-53.10	0.115
3.33	-53.07	0.115
3.33	-53.04	0.114
3.34	-53.00	0.114
3.34	-52.97	0.114
3.34	-52.94	0.114
3.35	-52.90	0.114
3.35	-52.87	0.114
3.35	-52.84	0.114
3.36	-52.80	0.114
3.36	-52.77	0.114
3.36	-52.74	0.114
3.37	-52.70	0.114
3.37	-52.67	0.114
3.37	-52.64	0.114
3.38	-52.60	0.114
3.38	-52.57	0.114
3.38	-52.54	0.114
3.39	-52.50	0.114
3.39	-52.47	0.114
3.39	-52.44	0.114
3.40	-52.40	0.114
3.40	-52.37	0.114
3.40	-52.34	0.114
3.41	-52.30	0.114
3.41	-52.27	0.114
3.41	-52.23	0.114
3.42	-52.20	0.113
3.42	-52.17	0.113
3.42	-52.13	0.113
3.43	-52.10	0.113
3.43	-52.07	0.113
3.43	-52.04	0.113
3.44	-52.00	0.113
3.44	-51.97	0.113
3.44	-51.94	0.113
3.45	-51.90	0.113
3.45	-51.87	0.113
3.45	-51.83	0.113
3.46	-51.80	0.113
3.46	-51.77	0.113
3.46	-51.73	0.113
3.47	-51.70	0.113
3.47	-51.67	0.113
3.47	-51.63	0.113
3.48	-51.60	0.113
3.48	-51.57	0.113
3.48	-51.53	0.113
3.49	-51.50	0.113
3.49	-51.47	0.113
3.49	-51.43	0.113
3.50	-51.40	0.113
3.50	-51.37	0.113
3.50	-51.33	0.113
3.51	-51.30	0.113
3.51	-51.27	0.113
3.51	-51.23	0.113
3.52	-51.20	0.113
3.52	-51.17	0.113
3.52	-51.13	0.112
3.53	-51.10	0.112
3.53	-51.07	0.112
3.53	-51.03	0.112
3.54	-51.00	0.112
3.54	-50.97	0.112
3.54	-50.93	0.112
3.55	-50.90	0.112
3.55	-50.87	0.112
3.55	-50.83	0.112
3.56	-50.80	0.112
3.56	-50.76	0.112
3.56	-50.73	0.112
3.57	-50.70	0.112
3.57	-50.66	0.112
3.57	-50.63	0.112
3.58	-50.60	0.112
3.58	-50.56	0.112
3.58	-50.53	0.112
3.59	-50.50	0.112
3.59	-50.47	0.112
3.59	-50.43	0.112
3.60	-50.40	0.112
3.60	-50.36	0.112
3.60	-50.33	0.112
3.61	-50.30	0.112
3.61	-50.26	0.112
3.61	-50.23	0.112
3.62	-50.20	0.112
3.62	-50.16	0.112
3.62	-50.13	0.112
3.63	-50.10	0.112
3.63	-50.06	0.112
3.63	-50.03	0.112
3.64	-50.00	0.112
3.64	-49.96	0.112
3.64	-49.93	0.112
3.65	-49.90	0.112
3.65	-49.86	0.112
3.65	-49.83	0.112
3.66	-49.80	0.112
3.66	-49.76	0.112
3.66	-49.73	0.112
3.67	-49.70	0.112
3.67	-49.66	0.112
3.67	-49.63	0.112
3.68	-49.60	0.112
3.68	-49.56	0.112
3.68	-49.53	0.112
3.69	-49.50	0.112
3.69	-49.46	0.112
3.69	-49.43	0.112
3.70	-49.40	0.112
3.70	-49.36	0.112
3.70	-49.33	0.112
3.71	-49.30	0.112
3.71	-49.26	0.112
3.71	-49.23	0.112
3.72	-49.19	0.112
3.72	-49.16	0.112
3.72	-49.13	0.112
3.73	-49.09	0.112
3.73	-49.06	0.112
3.73	-49.03	0.112
3.74	-48.99	0.112
3.74	-48.96	0.112
3.74	-48.93	0.112
3.75	-48.89	0.112
3.75	-48.86	0.112
3.75	-48.83	0.112
3.76	-48.80	0.112
3.76	-48.76	0.112
3.76	-48.73	0.112
3.77	-48.69	0.112
3.77	-48.66	0.112
3.77	-48.63	0.112
3.78	-48.59	0.112
3.78	-48.56	0.112
3.78	-48.53	0.112
3.79	-48.49	0.112
3.79	-48.46	0.112
3.79	-48.43	0.112
3.80	-48.39	0.112
3.80	-48.36	0.112
3.80	-48.32	0.112
3.81	-48.29	0.112
3.81	-48.26	0.112
3.81	-48.23	0.112
3.82	-48.19	0.112
3.82	-48.16	0.112
3.82	-48.13	0.112
3.83	-48.09	0.112
3.83	-48.06	0.112
3.83	-48.03	0.112
3.84	-47.99	0.112
3.84	-47.96	0.112
3.84	-47.93	0.112
3.85	-47.89	0.112
3.85	-47.86	0.112
3.85	-47.83	0.112
3.86	-47.79	0.112
3.86	-47.76	0.112
3.86	-47.72	0.112
3.87	-47.69	0.112
3.87	-47.66	0.112
3.87	-47.62	0.112
3.88	-47.59	0.112
3.88	-47.56	0.112
3.88	-47.52	0.112
3.89	-47.49	0.112
3.89	-47.46	0.112
3.89	-47.42	0.112
3.90	-47.39	0.112
3.90	-47.36	0.112
3.90	-47.32	0.112
3.91	-47.29	0.112
3.91	-47.26	0.112
3.91	-47.22	0.112
3.92	-47.19	0.112
3.92	-47.16	0.112
3.92	-47.12	0.112
3.93	-47.09	0.112
3.93	-47.06	0.112
3.93	-47.02	0.112
3.94	-46.99	0.112
3.94	-46.96	0.112
3.94	-46.92	0.112
3.95	-46.89	0.112
3.95	-46.86	0.112
3.95	-46.82	0.112
3.96	-46.79	0.112
3.96	-46.76	0.112
3.96	-46.72	0.112
3.97	-46.69	0.112
3.97	-46.66	0.112
3.97	-46.62	0.112
3.98	-46.59	0.112
3.98	-46.55	0.112
3.98	-46.52	0.112
3.99	-46.49	0.112
3.99	-46.46	0.112
3.99	-46.42	0.112
4.00	-46.39	0.112
4.00	-46.36	0.112
4.00	-46.32	0.112
4.01	-46.29	0.112
4.01	-46.25	0.112
4.01	-46.22	0.112
4.02	-46.19	0.112
4.02	-46.15	0.112
4.02	-46.12	0.112
4.03	-46.09	0.112
4.03	-46.05	0.112
4.03	-46.02	0.112
4.04	-45.99	0.112
4.04	-45.95	0.112
4.04	-45.92	0.112
4.05	-45.89	0.112
4.05	-45.85	0.112
4.05	-45.82	0.112
4.06	-45.79	0.112
4.06	-45.75	0.112
4.06	-45.72	0.112
4.07	-45.69	0.112
4.07	-45.65	0.112
4.07	-45.62	0.112
4.08	-45.59	0.112
4.08	-45.55	0.112
4.08	-45.52	0.112
4.09	-45.49	0.113
4.09	-45.45	0.113
4.09	-45.42	0.113
4.10	-45.39	0.113
4.10	-45.35	0.113
4.10	-45.32	0.113
4.11	-45.29	0.113
4.11	-45.25	0.113
4.11	-45.22	0.113
4.12	-45.19	0.113
4.12	-45.15	0.113
4.12	-45.12	0.113
4.13	-45.09	0.113
4.13	-45.05	0.113
4.13	-45.02	0.113
4.14	-44.99	0.113
4.14	-44.95	0.113
4.14	-44.92	0.113
4.15	-44.89	0.113
4.15	-44.85	0.113
4.15	-44.82	0.113
4.16	-44.79	0.113
4.16	-44.75	0.113
4.16	-44.72	0.113
4.17	-44.68	0.113
4.17	-44.65	0.113
4.17	-44.62	0.113
4.18	-44.59	0.113
4.18	-44.55	0.113
4.18	-44.52	0.113
4.19	-44.49	0.113
4.19	-44.45	0.113
4.19	-44.42	0.113
4.20	-44.39	0.113
4.20	-44.35	0.113
4.20	-44.32	0.113
4.21	-44.29	0.113
4.21	-44.25	0.113
4.21	-44.22	0.113
4.22	-44.19	0.113
4.22	-44.15	0.113
4.22	-44.12	0.113
4.23	-44.09	0.113
4.23	-44.05	0.113
4.23	-44.02	0.113
4.24	-43.98	0.113
4.24	-43.95	0.113
4.24	-43.92	0.113
4.25	-43.88	0.113
4.25	-43.85	0.113
4.25	-43.82	0.113
4.26	-43.78	0.113
4.26	-43.75	0.113
4.26	-43.72	0.113
4.27	-43.68	0.113
4.27	-43.65	0.113
4.27	-43.62	0.113
4.28	-43.58	0.113
4.28	-43.55	0.113
4.28	-43.52	0.113
4.29	-43.48	0.113
4.29	-43.45	0.113
4.29	-43.42	0.113
4.30	-43.38	0.113
4.30	-43.35	0.113
4.30	-43.32	0.113
4.31	-43.28	0.113
4.31	-43.25	0.113
4.31	-43.22	0.113
4.32	-43.18	0.113
4.32	-43.15	0.113
4.32	-43.12	0.113
4.33	-43.08	0.113
4.33	-43.05	0.113
4.33	-43.02	0.113
4.34	-42.98	0.113
4.34	-42.95	0.113
4.34	-42.92	0.113
4.35	-42.88	0.113
4.35	-42.85	0.113
4.35	-42.82	0.113
4.36	-42.78	0.113
4.36	-42.75	0.113
4.36	-42.71	0.113
4.37	-42.68	0.113
4.37	-42.65	0.113
4.37	-42.61	0.113
4.38	-42.58	0.113
4.38	-42.55	0.113
4.38	-42.51	0.113
4.39	-42.48	0.113
4.39	-42.45	0.113
4.39	-42.41	0.113
4.40	-42.38	0.113
4.40	-42.35	0.113
4.40	-42.31	0.113
4.41	-42.28	0.113
4.41	-42.25	0.113
4.41	-42.21	0.113
4.42	-42.18	0.114
4.42	-42.15	0.114
4.42	-42.11	0.114
4.43	-42.08	0.114
4.43	-42.05	0.114
4.43	-42.01	0.114
4.44	-41.98	0.114
4.44	-41.95	0.114
4.44	-41.91	0.114
4.45	-41.88	0.114
4.45	-41.85	0.114
4.45	-41.81	0.114
4.46	-41.78	0.114
4.46	-41.75	0.114
4.46	-41.71	0.114
4.47	-41.68	0.114
4.47	-41.65	0.114
4.47	-41.61	0.114
4.48	-41.58	0.114
4.48	-41.55	0.114
4.48	-41.51	0.114
4.49	-41.48	0.114
4.49	-41.45	0.114
4.49	-41.41	0.114
4.50	-41.38	0.114
4.50	-41.35	0.114
4.50	-41.31	0.114
4.51	-41.28	0.114
4.51	-41.25	0.114
4.51	-41.21	0.114
4.52	-41.18	0.114
4.52	-41.15	0.114
4.52	-41.11	0.114
4.53	-41.08	0.114
4.53	-41.04	0.114
4.53	-41.01	0.114
4.54	-40.98	0.114
4.54	-40.94	0.114
4.54	-40.91	0.114
4.55	-40.88	0.114
4.55	-40.84	0.114
4.55	-40.81	0.114
4.56	-40.78	0.114
4.56	-40.74	0.114
4.56	-40.71	0.114
4.57	-40.68	0.114
4.57	-40.64	0.114
4.57	-40.61	0.114
4.58	-40.58	0.114
4.58	-40.54	0.114
4.58	-40.51	0.114
4.59	-40.48	0.114
4.59	-40.44	0.114
4.59	-40.41	0.114
4.60	-40.38	0.114
4.60	-40.34	0.114
4.60	-40.31	0.114
4.61	-40.28	0.114
4.61	-40.24	0.114
4.61	-40.21	0.114
4.62	-40.18	0.114
4.62	-40.14	0.114
4.62	-40.11	0.114
4.63	-40.08	0.114
4.63	-40.04	0.114
4.63	-40.01	0.114
4.64	-39.98	0.114
4.64	-39.94	0.114
4.64	-39.91	0.114
4.65	-39.88	0.114
4.65	-39.84	0.114
4.65	-39.81	0.114
4.66	-39.78	0.114
4.66	-39.74	0.114
4.66	-39.71	0.114
4.67	-39.68	0.114
4.67	-39.64	0.114
4.67	-39.61	0.115
4.68	-39.58	0.115
4.68	-39.54	0.115
4.68	-39.51	0.115
4.69	-39.48	0.115
4.69	-39.44	0.115
4.69	-39.41	0.115
4.70	-39.38	0.115
4.70	-39.34	0.115
4.70	-39.31	0.115
4.71	-39.27	0.115
4.71	-39.24	0.115
4.71	-39.21	0.115
4.72	-39.17	0.115
4.72	-39.14	0.115
4.72	-39.11	0.115
4.73	-39.07	0.115
4.73	-39.04	0.115
4.73	-39.01	0.115
4.74	-38.98	0.115
4.74	-38.94	0.115
4.74	-38.91	0.115
4.75	-38.87	0.115
4.75	-38.84	0.115
4.75	-38.81	0.115
4.76	-38.77	0.115
4.76	-38.74	0.115
4.76	-38.71	0.115
4.77	-38.67	0.115
4.77	-38.64	0.115
4.77	-38.61	0.115
4.78	-38.57	0.115
4.78	-38.54	0.115
4.78	-38.51	0.115
4.79	-38.47	0.115
4.79	-38.44	0.115
4.79	-38.41	0.115
4.80	-38.37	0.115
4.80	-38.34	0.115
4.80	-38.31	0.115
4.81	-38.27	0.115
4.81	-38.24	0.115
4.81	-38.21	0.115
4.82	-38.17	0.115
4.82	-38.14	0.115
4.82	-38.11	0.115
4.83	-38.07	0.115
4.83	-38.04	0.115
4.83	-38.01	0.115
4.84	-37.97	0.115
4.84	-37.94	0.115
4.84	-37.91	0.115
4.85	-37.87	0.115
4.85	-37.84	0.115
4.85	-37.81	0.115
4.86	-37.77	0.115
4.86	-37.74	0.115
4.86	-37.71	0.115
4.87	-37.67	0.115
4.87	-37.64	0.115
4.87	-37.60	0.115
4.88	-37.57	0.115
4.88	-37.54	0.115
4.88	-37.50	0.115
4.89	-37.47	0.115
4.89	-37.44	0.115
4.89	-37.40	0.115
4.90	-37.37	0.116
4.90	-37.34	0.116
4.90	-37.31	0.116
4.91	-37.27	0.116
4.91	-37.24	0.116
4.91	-37.20	0.116
4.92	-37.17	0.116
4.92	-37.14	0.116
4.92	-37.10	0.116
4.93	-37.07	0.116
4.93	-37.04	0.116
4.93	-37.01	0.116
4.94	-36.97
4.94	-36.94
4.94	-36.90
4.95	-36.87
4.95	-36.84
4.95	-36.80
4.96	-36.77
4.96	-36.74
4.96	-36.70
4.97	-36.67
4.97	-36.64
4.97	-36.60
4.98	-36.57
4.98	-36.54
4.98	-36.50
4.99
4.99
4.99

[step]
Ramp 10.00 °C/min to -85.00 °C
Time	Temperature	Heat Flow (Normalized)
min	°C	W/g
5.99	-34.91	-0.010
6.00	-34.91	-0.010
6.00	-34.91	-0.010
6.01	-34.91	-0.010
6.01	-34.91	-0.010
6.02	-34.91	-0.010
6.02	-34.92	-0.010
6.03	-34.92	-0.010
6.03	-34.92	-0.011
6.04	-34.93	-0.011
6.04	-34.93	-0.011
6.05	-34.93	-0.011
6.05	-34.94	-0.011
6.06	-34.95	-0.011
6.06	-34.96	-0.011
6.07	-34.97	-0.011
6.07	-34.98	-0.011
6.08	-34.99	-0.010
6.08	-35.01	-0.008
6.09	-35.03	-0.005
6.09	-35.05	-0.001
6.10	-35.07	0.002
6.10	-35.10	0.005
6.11	-35.12	0.008
6.11	-35.15	0.009
6.12	-35.18	0.010
6.12	-35.21	0.010
6.13	-35.24	0.011
6.13	-35.27	0.010
6.14	-35.30	0.009
6.14	-35.34	0.009
6.15	-35.37	0.008
6.15	-35.40	0.007
6.16	-35.44	0.005
6.16	-35.48	0.001
6.17	-35.51	-0.007
6.17	-35.55	-0.015
6.18	-35.58	-0.018
6.18	-35.62	-0.021
6.19	-35.66	-0.024
6.19	-35.69	-0.026
6.20	-35.73	-0.029
6.20	-35.77	-0.033
6.21	-35.81	-0.034
6.21	-35.85	-0.038
6.22	-35.89	-0.040
6.22	-35.93	-0.042
6.23	-35.97	-0.043
6.23	-36.01	-0.046
6.24	-36.05	-0.048
6.24	-36.10	-0.050
6.25	-36.14	-0.052
6.25	-36.18	-0.056
6.26	-36.22	-0.056
6.26	-36.27	-0.058
6.27	-36.31	-0.062
6.27	-36.35	-0.066
6.28	-36.40	-0.067
6.28	-36.44	-0.068
6.29	-36.49	-0.071
6.29	-36.53	-0.073
6.30	-36.57	-0.075
6.30	-36.62	-0.077
6.31	-36.66	-0.079
6.31	-36.71	-0.081
6.32	-36.75	-0.083
6.32	-36.80	-0.084
6.33	-36.84	-0.087
6.33	-36.89	-0.088
6.34	-36.94	-0.088
6.34	-36.98	-0.088
6.35	-37.03	-0.090
6.35	-37.07	-0.093
6.36	-37.12	-0.095
6.36	-37.16	-0.096
6.37	-37.21	-0.097
6.37	-37.26	-0.099
6.38	-37.30	-0.100
6.38	-37.35	-0.100
6.39	-37.40	-0.100
6.39	-37.45	-0.101
6.40	-37.49	-0.103
6.40	-37.54	-0.104
6.41	-37.59	-0.105
6.41	-37.64	-0.106
6.42	-37.68	-0.107
6.42	-37.73	-0.107
6.43	-37.78	-0.108
6.43	-37.82	-0.109
6.44	-37.87	-0.110
6.44	-37.92	-0.110
6.45	-37.97	-0.111
6.45	-38.02	-0.111
6.46	-38.06	-0.111
6.46	-38.11	-0.112
6.47	-38.16	-0.112
6.47	-38.21	-0.113
6.48	-38.26	-0.114
6.48	-38.31	-0.114
6.49	-38.35	-0.114
6.49	-38.40	-0.115
6.50	-38.45	-0.115
6.50	-38.50	-0.116
6.51	-38.55	-0.117
6.51	-38.59	-0.117
6.52	-38.64	-0.117
6.52	-38.69	-0.117
6.53	-38.74	-0.118
6.53	-38.79	-0.118
6.54	-38.84	-0.118
6.54	-38.89	-0.118
6.55	-38.93	-0.119
6.55	-38.98	-0.119
6.56	-39.03	-0.119
6.56	-39.08	-0.119
6.57	-39.13	-0.119
6.57	-39.18	-0.119
6.58	-39.23	-0.120
6.58	-39.28	-0.120
6.59	-39.32	-0.120
6.59	-39.37	-0.120
6.60	-39.42	-0.120
6.60	-39.47	-0.121
6.61	-39.52	-0.121
6.61	-39.57	-0.121
6.62	-39.62	-0.121
6.62	-39.67	-0.121
6.63	-39.72	-0.121
6.63	-39.76	-0.121
6.64	-39.81	-0.121
6.64	-39.86	-0.121
6.65	-39.91	-0.121
6.65	-39.96	-0.121
6.66	-40.01	-0.121
6.66	-40.06	-0.122
6.67	-40.11	-0.122
6.67	-40.16	-0.122
6.68	-40.21	-0.122
6.68	-40.26	-0.122
6.69	-40.31	-0.122
6.69	-40.36	-0.122
6.70	-40.40	-0.122
6.70	-40.45	-0.122
6.71	-40.50	-0.122
6.71	-40.55	-0.122
6.72	-40.60	-0.122
6.72	-40.65	-0.122
6.73	-40.70	-0.123
6.73	-40.75	-0.123
6.74	-40.80	-0.123
6.74	-40.85	-0.123
6.75	-40.90	-0.123
6.75	-40.95	-0.123
6.76	-41.00	-0.123
6.76	-41.05	-0.123
6.77	-41.09	-0.123
6.77	-41.14	-0.123
6.78	-41.19	-0.123
6.78	-41.24	-0.123
6.79	-41.29	-0.123
6.79	-41.34	-0.123
6.80	-41.39	-0.123
6.80	-41.44	-0.123
6.81	-41.49	-0.124
6.81	-41.54	-0.124
6.82	-41.59	-0.124
6.82	-41.64	-0.124
6.83	-41.69	-0.124
6.83	-41.74	-0.124
6.84	-41.79	-0.124
6.84	-41.84	-0.124
6.85	-41.89	-0.124
6.85	-41.94	-0.124
6.86	-41.99	-0.124
6.86	-42.04	-0.124
6.87	-42.09	-0.124
6.87	-42.14	-0.124
6.88	-42.19	-0.124
6.88	-42.24	-0.124
6.89	-42.28	-0.124
6.89	-42.33	-0.124
6.90	-42.38	-0.124
6.90	-42.43	-0.124
6.91	-42.48	-0.124
6.91	-42.53	-0.124
6.92	-42.58	-0.124
6.92	-42.63	-0.124
6.93	-42.68	-0.124
6.93	-42.73	-0.124
6.94	-42.78	-0.124
6.94	-42.83	-0.124
6.95	-42.88	-0.124
6.95	-42.93	-0.124
6.96	-42.98	-0.124
6.96	-43.03	-0.124
6.97	-43.08	-0.124
6.97	-43.13	-0.124
6.98	-43.18	-0.124
6.98	-43.23	-0.124
6.99	-43.28	-0.124
6.99	-43.33	-0.124
7.00	-43.38	-0.124
7.00	-43.43	-0.124
7.01	-43.48	-0.124
7.01	-43.53	-0.124
7.02	-43.57	-0.124
7.02	-43.63	-0.124
7.03	-43.68	-0.124
7.03	-43.72	-0.124
7.04	-43.77	-0.124
7.04	-43.82	-0.123
7.05	-43.87	-0.123
7.05	-43.92	-0.123
7.06	-43.97	-0.123
7.06	-44.02	-0.123
7.07	-44.07	-0.123
7.07	-44.12	-0.123
7.08	-44.17	-0.123
7.08	-44.22	-0.123
7.09	-44.27	-0.123
7.09	-44.32	-0.123
7.10	-44.37	-0.123
7.10	-44.42	-0.123
7.11	-44.47	-0.123
7.11	-44.52	-0.123
7.12	-44.57	-0.123
7.12	-44.62	-0.123
7.13	-44.67	-0.123
7.13	-44.72	-0.123
7.14	-44.77	-0.122
7.14	-44.82	-0.122
7.15	-44.87	-0.122
7.15	-44.92	-0.122
7.16	-44.97	-0.122
7.16	-45.02	-0.122
7.17	-45.07	-0.122
7.17	-45.12	-0.122
7.18	-45.17	-0.122
7.18	-45.22	-0.122
7.19	-45.27	-0.122
7.19	-45.32	-0.122
7.20	-45.37	-0.122
7.20	-45.42	-0.122
7.21	-45.47	-0.122
7.21	-45.52	-0.122
7.22	-45.57	-0.122
7.22	-45.62	-0.122
7.23	-45.67	-0.122
7.23	-45.71	-0.122
7.24	-45.77	-0.122
7.24	-45.82	-0.122
7.25	-45.87	-0.121
7.25	-45.92	-0.121
7.26	-45.97	-0.121
7.26	-46.02	-0.121
7.27	-46.07	-0.121
7.27	-46.12	-0.121
7.28	-46.16	-0.121
7.28	-46.22	-0.121
7.29	-46.26	-0.121
7.29	-46.31	-0.121
7.30	-46.36	-0.121
7.30	-46.41	-0.121
7.31	-46.46	-0.121
7.31	-46.51	-0.121
7.32	-46.56	-0.121
7.32	-46.61	-0.121
7.33	-46.66	-0.120
7.33	-46.71	-0.120
7.34	-46.76	-0.120
7.34	-46.81	-0.120
7.35	-46.86	-0.120
7.35	-46.91	-0.120
7.36	-46.96	-0.120
7.36	-47.01	-0.120
7.37	-47.06	-0.120
7.37	-47.11	-0.120
7.38	-47.16	-0.120
7.38	-47.21	-0.120
7.39	-47.26	-0.120
7.39	-47.31	-0.120
7.40	-47.36	-0.120
7.40	-47.41	-0.120
7.41	-47.46	-0.120
7.41	-47.51	-0.119
7.42	-47.56	-0.119
7.42	-47.61	-0.119
7.43	-47.66	-0.119
7.43	-47.71	-0.119
7.44	-47.76	-0.119
7.44	-47.81	-0.119
7.45	-47.86	-0.119
7.45	-47.91	-0.119
7.46	-47.96	-0.119
7.46	-48.01	-0.119
7.47	-48.06	-0.119
7.47	-48.11	-0.119
7.48	-48.16	-0.118
7.48	-48.21	-0.118
7.49	-48.26	-0.118
7.49	-48.31	-0.118
7.50	-48.36	-0.118
7.50	-48.41	-0.118
7.51	-48.46	-0.118
7.51	-48.51	-0.118
7.52	-48.56	-0.118
7.52	-48.61	-0.118
7.53	-48.66	-0.118
7.53	-48.71	-0.118
7.54	-48.76	-0.117
7.54	-48.81	-0.117
7.55	-48.86	-0.117
7.55	-48.91	-0.117
7.56	-48.96	-0.117
7.56	-49.01	-0.117
7.57	-49.06	-0.117
7.57	-49.11	-0.117
7.58	-49.16	-0.117
7.58	-49.21	-0.117
7.59	-49.26	-0.117
7.59	-49.31	-0.117
7.60	-49.36	-0.117
7.60	-49.41	-0.117
7.61	-49.46	-0.117
7.61	-49.51	-0.116
7.62	-49.56	-0.116
7.62	-49.61	-0.116
7.63	-49.66	-0.116
7.63	-49.71	-0.116
7.64	-49.76	-0.116
7.64	-49.81	-0.116
7.65	-49.86	-0.116
7.65	-49.91	-0.116
7.66	-49.96	-0.116
7.66	-50.01	-0.116
7.67	-50.06	-0.116
7.67	-50.11	-0.116
7.68	-50.16	-0.116
7.68	-50.21	-0.116
7.69	-50.26	-0.115
7.69	-50.31	-0.115
7.70	-50.36	-0.115
7.70	-50.41	-0.115
7.71	-50.46	-0.115
7.71	-50.51	-0.115
7.72	-50.56	-0.115
7.72	-50.61	-0.115
7.73	-50.66	-0.115
7.73	-50.71	-0.115
7.74	-50.76	-0.115
7.74	-50.81	-0.115
7.75	-50.86	-0.114
7.75	-50.91	-0.114
7.76	-50.96	-0.114
7.76	-51.01	-0.114
7.77	-51.06	-0.114
7.77	-51.11	-0.114
7.78	-51.16	-0.114
7.78	-51.20	-0.114
7.79	-51.26	-0.114
7.79	-51.31	-0.114
7.80	-51.36	-0.114
7.80	-51.41	-0.113
7.81	-51.46	-0.113
7.81	-51.51	-0.113
7.82	-51.56	-0.113
7.82	-51.60	-0.113
7.83	-51.66	-0.113
7.83	-51.71	-0.113
7.84	-51.76	-0.113
7.84	-51.81	-0.113
7.85	-51.85	-0.113
7.85	-51.90	-0.113
7.86	-51.96	-0.113
7.86	-52.00	-0.113
7.87	-52.06	-0.112
7.87	-52.10	-0.112
7.88	-52.16	-0.112
7.88	-52.21	-0.112
7.89	-52.26	-0.112
7.89	-52.31	-0.112
7.90	-52.35	-0.112
7.90	-52.41	-0.112
7.91	-52.46	-0.112
7.91	-52.50	-0.112
7.92	-52.56	-0.112
7.92	-52.60	-0.112
7.93	-52.65	-0.112
7.93	-52.71	-0.112
7.94	-52.76	-0.111
7.94	-52.81	-0.111
7.95	-52.85	-0.111
7.95	-52.90	-0.111
7.96	-52.96	-0.111
7.96	-53.00	-0.111
7.97	-53.05	-0.111
7.97	-53.10	-0.111
7.98	-53.16	-0.111
7.98	-53.20	-0.111
7.99	-53.25	-0.111
7.99	-53.30	-0.111
8.00	-53.35	-0.111
8.00	-53.40	-0.110
8.01	-53.45	-0.110
8.01	-53.50	-0.110
8.02	-53.56	-0.110
[...]
10.80	-79.21	-0.061
10.80	-79.24	-0.061
10.81	-79.28	-0.061
10.81	-79.31	-0.060
10.82	-79.35	-0.060
10.82	-79.38	-0.059
10.83	-79.41	-0.059
10.83	-79.45	-0.059
10.84	-79.48	-0.059
10.84	-79.52	-0.059
10.85	-79.55	-0.059
10.85	-79.58	-0.059
10.86	-79.61	-0.059
10.86	-79.65	-0.058
10.87	-79.68	-0.057
10.87	-79.72	-0.057
10.88	-79.75	-0.057
10.88	-79.78	-0.057
10.89	-79.81	-0.056
10.89	-79.85	-0.056
10.90	-79.88	-0.056
10.90	-79.91	-0.056
10.91	-79.95	-0.056
10.91	-79.98	-0.056
10.92	-80.01	-0.056
10.92	-80.05	-0.055
10.93	-80.08	-0.055
10.93	-80.11	-0.055
10.94	-80.14
10.94	-80.18
10.95	-80.21
10.95	-80.24
10.96	-80.27
10.96	-80.31
10.97	-80.34
10.97	-80.37
10.98	-80.40
10.98	-80.43
10.99
10.99

[step]
Ramp 10.00 °C/min to -35.00 °C
Time	Temperature	Heat Flow (Normalized)
min	°C	W/g
12.00	-85.44	-0.034
12.00	-85.43	-0.033
12.00	-85.43	-0.033
12.01	-85.43	-0.032
12.02	-85.43	-0.031
12.02	-85.43	-0.029
12.03	-85.43	-0.028
12.03	-85.43	-0.027
12.03	-85.43	-0.026
12.04	-85.43	-0.025
12.05	-85.43	-0.023
12.05	-85.43	-0.021
12.05	-85.44	-0.019
12.06	-85.44	-0.017
12.07	-85.44	-0.015
12.07	-85.44	-0.013
12.08	-85.44	-0.012
12.08	-85.44	-0.010
12.08	-85.44	-0.007
12.09	-85.44	-0.006
12.10	-85.44	-0.004
12.10	-85.44	-0.003
12.10	-85.44	-0.003
12.11	-85.43	-0.004
12.12	-85.42	-0.004
12.12	-85.41	-0.005
12.13	-85.40	-0.005
12.13	-85.39	-0.006
12.13	-85.37	-0.008
12.14	-85.36	-0.011
12.15	-85.34	-0.014
12.15	-85.31	-0.019
12.15	-85.29	-0.023
12.16	-85.27	-0.027
12.17	-85.24	-0.029
12.17	-85.21	-0.032
12.18	-85.18	-0.033
12.18	-85.15	-0.033
12.18	-85.12	-0.033
12.19	-85.09	-0.033
12.20	-85.05	-0.033
12.20	-85.02	-0.033
12.20	-84.98	-0.032
12.21	-84.95	-0.032
12.22	-84.91	-0.032
12.22	-84.87	-0.030
12.23	-84.84	-0.027
12.23	-84.80	-0.021
12.23	-84.76	-0.017
12.24	-84.72	-0.012
12.25	-84.68	-0.006
12.25	-84.64	-0.002
12.25	-84.60	0.001
12.26	-84.56	0.003
12.27	-84.52	0.007
12.27	-84.48	0.010
12.28	-84.44	0.014
12.28	-84.40	0.017
12.28	-84.36	0.021
12.29	-84.32	0.022
12.30	-84.27	0.025
12.30	-84.23	0.027
12.30	-84.19	0.029
12.31	-84.15	0.031
12.32	-84.10	0.033
12.32	-84.06	0.036
12.33	-84.02	0.037
12.33	-83.97	0.039
12.33	-83.93	0.041
12.34	-83.89	0.043
12.35	-83.84	0.044
12.35	-83.80	0.045
12.35	-83.75	0.047
12.36	-83.71	0.049
12.37	-83.66	0.052
12.37	-83.62	0.053
12.38	-83.57	0.054
12.38	-83.53	0.056
12.38	-83.48	0.059
12.39	-83.44	0.059
12.40	-83.39	0.060
12.40	-83.35	0.061
12.40	-83.30	0.063
12.41	-83.25	0.065
12.42	-83.21	0.067
12.42	-83.16	0.068
12.43	-83.11	0.069
12.43	-83.07	0.070
12.43	-83.02	0.070
12.44	-82.97	0.072
12.45	-82.93	0.074
12.45	-82.88	0.075
12.45	-82.83	0.075
12.46	-82.79	0.075
12.47	-82.74	0.076
12.47	-82.69	0.078
12.48	-82.64	0.079
12.48	-82.60	0.080
12.48	-82.55	0.080
12.49	-82.50	0.081
12.50	-82.45	0.081
12.50	-82.41	0.082
12.50	-82.36	0.082
12.51	-82.31	0.083
12.52	-82.27	0.084
12.52	-82.22	0.085
12.53	-82.17	0.085
12.53	-82.12	0.086
12.53	-82.07	0.086
12.54	-82.02	0.086
12.55	-81.98	0.086
12.55	-81.93	0.086
12.55	-81.88	0.087
12.56	-81.83	0.088
12.57	-81.78	0.088
12.57	-81.74	0.089
12.58	-81.69	0.090
12.58	-81.64	0.090
12.58	-81.59	0.090
12.59	-81.54	0.090
12.60	-81.49	0.090
12.60	-81.45	0.090
12.60	-81.40	0.091
12.61	-81.35	0.092
12.62	-81.30	0.092
12.62	-81.25	0.092
12.63	-81.20	0.093
12.63	-81.15	0.093
12.63	-81.10	0.093
12.64	-81.06	0.093
12.65	-81.01	0.093
12.65	-80.96	0.093
12.65	-80.91	0.093
12.66	-80.86	0.094
12.67	-80.81	0.094
12.67	-80.77	0.094
12.68	-80.72	0.094
12.68	-80.67	0.094
12.68	-80.62	0.095
12.69	-80.57	0.095
12.70	-80.52	0.095
12.70	-80.47	0.095
12.70	-80.42	0.095
12.71	-80.37	0.095
12.72	-80.33	0.095
12.72	-80.28	0.095
12.73	-80.23	0.096
12.73	-80.18	0.096
12.73	-80.13	0.096
12.74	-80.08	0.096
12.75	-80.03	0.096
12.75	-79.98	0.096
12.75	-79.93	0.096
12.76	-79.88	0.096
12.77	-79.84	0.096
12.77	-79.79	0.096
12.78	-79.74	0.096
12.78	-79.69	0.097
12.78	-79.64	0.097
12.79	-79.59	0.097
12.80	-79.54	0.097
12.80	-79.49	0.097
12.80	-79.44	0.097
12.81	-79.39	0.097
12.82	-79.34	0.097
12.82	-79.29	0.098
12.83	-79.24	0.098
12.83	-79.19	0.098
12.83	-79.15	0.098
12.84	-79.10	0.098
12.85	-79.05	0.098
12.85	-79.00	0.098
12.85	-78.95	0.098
12.86	-78.90	0.098
12.87	-78.85	0.098
12.87	-78.80	0.098
12.88	-78.75	0.099
12.88	-78.70	0.099
12.88	-78.65	0.099
12.89	-78.60	0.099
12.90	-78.55	0.099
12.90	-78.50	0.099
12.90	-78.46	0.099
12.91	-78.41	0.099
12.92	-78.36	0.099
12.92	-78.31	0.099
12.93	-78.26	0.099
12.93	-78.21	0.100
12.93	-78.16	0.100
12.94	-78.11	0.100
12.95	-78.06	0.100
12.95	-78.01	0.100
12.95	-77.96	0.100
12.96	-77.91	0.100
12.97	-77.86	0.100
12.97	-77.81	0.100
12.98	-77.76	0.100
12.98	-77.71	0.101
12.98	-77.66	0.101
12.99	-77.61	0.101
13.00	-77.57	0.101
13.00	-77.52	0.101
13.00	-77.47	0.101
13.01	-77.42	0.101
13.02	-77.37	0.101
13.02	-77.32	0.101
13.03	-77.27	0.101
13.03	-77.22	0.101
13.03	-77.17	0.101
13.04	-77.12	0.101
13.05	-77.07	0.101
13.05	-77.02	0.101
13.05	-76.97	0.101
13.06	-76.92	0.101
13.07	-76.87	0.102
13.07	-76.82	0.102
13.08	-76.77	0.102
13.08	-76.72	0.102
13.08	-76.67	0.102
13.09	-76.62	0.102
13.10	-76.57	0.102
13.10	-76.52	0.102
13.10	-76.47	0.102
13.11	-76.42	0.102
13.12	-76.37	0.102
13.12	-76.32	0.102
13.13	-76.27	0.102
13.13	-76.22	0.102
13.13	-76.18	0.102
13.14	-76.13	0.102
13.15	-76.08	0.102
13.15	-76.03	0.102
13.15	-75.98	0.102
13.16	-75.93	0.103
13.17	-75.88	0.103
13.17	-75.83	0.103
13.18	-75.78	0.103
13.18	-75.73	0.103
13.18	-75.68	0.103
13.19	-75.63	0.103
13.20	-75.58	0.103
13.20	-75.53	0.103
13.20	-75.48	0.103
13.21	-75.43	0.103
13.22	-75.38	0.103
13.22	-75.33	0.103
13.23	-75.28	0.103
13.23	-75.23	0.103
13.23	-75.18	0.103
13.24	-75.13	0.103
13.25	-75.08	0.103
13.25	-75.03	0.103
13.25	-74.98	0.103
13.26	-74.93	0.103
13.27	-74.88	0.104
13.27	-74.83	0.104
13.28	-74.78	0.104
13.28	-74.73	0.104
13.28	-74.68	0.104
13.29	-74.63	0.104
13.30	-74.58	0.104
13.30	-74.53	0.104
13.30	-74.48	0.104
13.31	-74.44	0.104
13.32	-74.38	0.104
13.32	-74.34	0.104
13.33	-74.29	0.104
13.33	-74.24	0.104
13.33	-74.19	0.104
13.34	-74.14	0.104
13.35	-74.09	0.104
13.35	-74.04	0.105
13.35	-73.99	0.105
13.36	-73.94	0.105
13.37	-73.89	0.105
13.37	-73.84	0.105
13.38	-73.79	0.105
13.38	-73.74	0.105
13.38	-73.69	0.105
13.39	-73.64	0.105
13.40	-73.59	0.105
13.40	-73.54	0.105
13.40	-73.49	0.105
13.41	-73.44	0.105
13.42	-73.39	0.105
13.42	-73.34	0.105
13.43	-73.29	0.105
13.43	-73.24	0.105
13.43	-73.19	0.106
13.44	-73.14	0.106
13.45	-73.09	0.106
13.45	-73.04	0.106
13.45	-72.99	0.106
13.46	-72.94	0.106
13.47	-72.89	0.106
13.47	-72.84	0.106
13.48	-72.79	0.106
13.48	-72.74	0.106
13.48	-72.69	0.106
13.49	-72.64	0.106
13.50	-72.59	0.106
13.50	-72.54	0.106
13.50	-72.49	0.106
13.51	-72.44	0.106
13.52	-72.39	0.107
13.52	-72.34	0.107
13.53	-72.29	0.107
13.53	-72.24	0.107
13.53	-72.19	0.107
13.54	-72.14	0.107
13.55	-72.09	0.107
13.55	-72.04	0.107
13.55	-71.99	0.107
13.56	-71.94	0.107
13.57	-71.90	0.107
13.57	-71.84	0.107
13.58	-71.80	0.108
13.58	-71.74	0.108
13.58	-71.70	0.108
13.59	-71.65	0.108
13.60	-71.59	0.108
13.60	-71.54	0.108
13.60	-71.49	0.108
13.61	-71.45	0.108
13.62	-71.40	0.108
13.62	-71.35	0.108
13.63	-71.30	0.108
13.63	-71.25	0.108
13.63	-71.20	0.109
13.64	-71.15	0.109
13.65	-71.10	0.109
13.65	-71.05	0.109
13.65	-71.00	0.109
13.66	-70.95	0.109
13.67	-70.90	0.109
13.67	-70.85	0.109
13.68	-70.80	0.110
13.68	-70.75	0.110
13.68	-70.70	0.110
13.69	-70.65	0.110
13.70	-70.60	0.110
13.70	-70.55	0.110
13.70	-70.50	0.110
13.71	-70.45	0.111
13.72	-70.40	0.111
13.72	-70.35	0.111
13.73	-70.30	0.111
13.73	-70.25	0.111
13.73	-70.20	0.111
13.74	-70.15	0.111
13.75	-70.10	0.111
13.75	-70.05	0.111
13.75	-70.00	0.112
13.76	-69.95	0.112
13.77	-69.90	0.112
13.77	-69.85	0.112
13.78	-69.80	0.112
13.78	-69.75	0.113
13.78	-69.70	0.113
13.79	-69.65	0.113
13.80	-69.60	0.113
13.80	-69.55	0.113
13.80	-69.50	0.113
13.81	-69.45	0.113
13.82	-69.40	0.114
13.82	-69.35	0.114
13.83	-69.30	0.114
13.83	-69.25	0.114
13.83	-69.20	0.114
13.84	-69.15	0.115
13.85	-69.10	0.116
13.85	-69.05	0.116
13.85	-69.00	0.116
13.86	-68.95	0.116
13.87	-68.90	0.116
13.87	-68.85	0.117
13.88	-68.80	0.117
13.88	-68.75	0.118
13.88	-68.71	0.118
13.89	-68.66	0.118
13.90	-68.60	0.119
13.90	-68.55	0.119
13.90	-68.51	0.119
13.91	-68.45	0.119
13.92	-68.41	0.120
13.92	-68.36	0.120
13.93	-68.31	0.121
13.93	-68.26	0.121
13.93	-68.21	0.121
13.94	-68.16	0.122
13.95	-68.11	0.124
13.95	-68.06	0.124
13.95	-68.01	0.125
13.96	-67.96	0.126
13.97	-67.91	0.126
13.97	-67.86	0.127
13.98	-67.81	0.128
13.98	-67.76	0.128
13.98	-67.71	0.129
13.99	-67.66	0.130
14.00	-67.61	0.131
14.00	-67.56	0.132
14.00	-67.51	0.134
14.01	-67.46	0.134
14.02	-67.41	0.135
14.02	-67.36	0.136
14.03	-67.31	0.137
14.03	-67.26	0.138
14.03	-67.21	0.140
14.04	-67.16	0.142
14.05	-67.11	0.143
14.05	-67.06	0.145
14.05	-67.01	0.146
14.06	-66.96	0.147
14.07	-66.92	0.149
14.07	-66.87	0.151
14.08	-66.81	0.153
14.08	-66.77	0.156
14.08	-66.72	0.159
14.09	-66.67	0.160
14.10	-66.62	0.162
14.10	-66.57	0.165
14.10	-66.52	0.170
14.11	-66.47	0.175
14.12	-66.42	0.178
14.12	-66.37	0.183
14.13	-66.32	0.189
14.13	-66.28	0.196
14.13	-66.23	0.202
14.14	-66.18	0.210
14.15	-66.13	0.217
14.15	-66.08	0.219
14.15	-66.03	0.222
14.16	-65.98	0.228
14.17	-65.93	0.233
14.17	-65.89	0.236
14.18	-65.84	0.240
14.18	-65.79	0.243
14.18	-65.74	0.245
14.19	-65.69	0.247
14.20	-65.64	0.250
14.20	-65.60	0.254
14.20	-65.55	0.259
14.21	-65.50	0.263
14.22	-65.45	0.265
14.22	-65.40	0.266
14.23	-65.35	0.269
14.23	-65.31	0.275
14.23	-65.26	0.279
14.24	-65.21	0.284
14.25	-65.16	0.289
14.25	-65.11	0.294
14.25	-65.07	0.299
14.26	-65.02	0.305
14.27	-64.97	0.311
14.27	-64.92	0.318
14.28	-64.87	0.324
14.28	-64.83	0.331
14.28	-64.78	0.337
14.29	-64.73	0.345
14.30	-64.68	0.351
14.30	-64.63	0.358
14.30	-64.59	0.365
14.31	-64.54	0.373
14.32	-64.49	0.382
14.32	-64.44	0.389
14.33	-64.40	0.395
14.33	-64.35	0.402
14.33	-64.30	0.410
14.34	-64.26	0.418
14.35	-64.21	0.425
14.35	-64.16	0.432
14.35	-64.12	0.439
14.36	-64.07	0.447
14.37	-64.02	0.455
14.37	-63.97	0.462
14.38	-63.92	0.470
14.38	-63.88	0.478
14.38	-63.83	0.485
14.39	-63.79	0.492
14.40	-63.74	0.501
14.40	-63.69	0.510
14.40	-63.64	0.518
14.41	-63.60	0.524
14.42	-63.55	0.531
14.42	-63.50	0.539
14.43	-63.46	0.547
14.43	-63.41	0.555
14.43	-63.36	0.563
14.44	-63.32	0.570
14.45	-63.27	0.578
14.45	-63.22	0.585
14.45	-63.18	0.594
14.46	-63.13	0.601
14.47	-63.08	0.607
14.47	-63.04	0.614
14.48	-62.99	0.623
14.48	-62.94	0.630
14.48	-62.90	0.636
14.49	-62.85	0.643
14.50	-62.80	0.650
14.50	-62.76	0.656
14.50	-62.71	0.663
14.51	-62.66	0.671
14.52	-62.62	0.678
14.52	-62.57	0.682
14.53	-62.52	0.688
14.53	-62.47	0.693
14.53	-62.43	0.700
14.54	-62.38	0.705
14.55	-62.33	0.713
14.55	-62.29	0.718
14.55	-62.24	0.723
14.56	-62.19	0.728
14.57	-62.15	0.732
14.57	-62.10	0.736
14.58	-62.05	0.740
14.58	-62.00	0.747
14.58	-61.96	0.753
14.59	-61.91	0.756
14.60	-61.86	0.759
14.60	-61.81	0.765
14.60	-61.77	0.769
14.61	-61.72	0.773
14.62	-61.67	0.775
14.62	-61.62	0.778
14.63	-61.57	0.779
14.63	-61.52	0.785
14.63	-61.48	0.787
14.64	-61.43	0.787
14.65	-61.38	0.788
14.65	-61.33	0.790
14.65	-61.28	0.792
14.66	-61.24	0.792
14.67	-61.19	0.792
14.67	-61.14	0.791
14.68	-61.09	0.788
14.68	-61.04	0.787
14.68	-60.99	0.785
14.69	-60.94	0.783
14.70	-60.89	0.780
14.70	-60.84	0.774
14.70	-60.79	0.765
14.71	-60.74	0.757
14.72	-60.69	0.748
14.72	-60.64	0.739
14.73	-60.59	0.729
14.73	-60.54	0.719
14.73	-60.49	0.705
14.74	-60.43	0.692
14.75	-60.38	0.676
14.75	-60.33	0.660
14.75	-60.28	0.643
14.76	-60.22	0.625
14.77	-60.17	0.606
14.77	-60.11	0.586
14.78	-60.06	0.565
14.78	-60.01	0.547
14.78	-59.95	0.529
14.79	-59.90	0.511
14.80	-59.84	0.492
14.80	-59.79	0.476
14.80	-59.73	0.461
14.81	-59.67	0.446
14.82	-59.62	0.432
14.82	-59.56	0.416
14.83	-59.51	0.402
14.83	-59.45	0.389
14.83	-59.40	0.379
14.84	-59.34	0.369
14.85	-59.28	0.356
14.85	-59.23	0.344
14.85	-59.17	0.336
14.86	-59.12	0.327
14.87	-59.06	0.316
14.87	-59.01	0.307
14.88	-58.95	0.299
14.88	-58.90	0.292
14.88	-58.84	0.283
14.89	-58.79	0.275
14.90	-58.73	0.269
14.90	-58.68	0.262
14.90	-58.62	0.255
14.91	-58.57	0.251
14.92	-58.52	0.244
14.92	-58.46	0.236
14.93	-58.41	0.231
14.93	-58.36	0.229
14.93	-58.30	0.224
14.94	-58.25	0.217
14.95	-58.20	0.214
14.95	-58.14	0.209
14.95	-58.09	0.205
14.96	-58.04	0.198
14.97	-57.98	0.197
14.97	-57.93	0.195
14.98	-57.88	0.192
14.98	-57.82	0.187
14.98	-57.77	0.183
14.99	-57.72	0.179
15.00	-57.67	0.177
15.00	-57.61	0.174
15.00	-57.56	0.174
15.01	-57.51	0.171
15.02	-57.46	0.168
15.02	-57.41	0.166
15.03	-57.35	0.163
15.03	-57.30	0.159
15.03	-57.25	0.157
15.04	-57.20	0.155
15.05	-57.15	0.154
15.05	-57.10	0.153
15.05	-57.04	0.151
15.06	-56.99	0.149
15.07	-56.94	0.148
15.07	-56.89	0.146
15.08	-56.84	0.144
15.08	-56.79	0.142
15.08	-56.74	0.142
15.09	-56.69	0.141
15.10	-56.63	0.140
15.10	-56.58	0.138
15.10	-56.53	0.136
15.11	-56.48	0.136
15.12	-56.43	0.136
15.12	-56.38	0.135
15.13	-56.33	0.134
15.13	-56.28	0.133
15.13	-56.23	0.132
15.14	-56.18	0.131
15.15	-56.12	0.130
15.15	-56.07	0.129
15.15	-56.02	0.129
15.16	-55.97	0.129
15.17	-55.92	0.128
15.17	-55.87	0.127
15.18	-55.82	0.126
15.18	-55.77	0.126
15.18	-55.72	0.125
15.19	-55.67	0.124
15.20	-55.62	0.124
15.20	-55.57	0.123
15.20	-55.52	0.123
15.21	-55.47	0.123
15.22	-55.42	0.123
15.22	-55.37	0.122
15.23	-55.31	0.121
15.23	-55.26	0.121
15.23	-55.21	0.121
15.24	-55.16	0.121
15.25	-55.11	0.120
15.25	-55.06	0.120
15.25	-55.01	0.120
15.26	-54.96	0.120
15.27	-54.91	0.120
15.27	-54.86	0.120
15.28	-54.81	0.119
15.28	-54.76	0.119
15.28	-54.71	0.119
15.29	-54.66	0.119
15.30	-54.61	0.118
15.30	-54.56	0.118
15.30	-54.51	0.118
15.31	-54.46	0.118
15.32	-54.41	0.118
15.32	-54.36	0.118
15.33	-54.31	0.118
15.33	-54.26	0.118
15.33	-54.21	0.117
15.34	-54.16	0.117
15.35	-54.11	0.117
15.35	-54.06	0.117
15.35	-54.01	0.116
15.36	-53.96	0.116
15.37	-53.91	0.116
15.37	-53.86	0.116
15.38	-53.81	0.116
15.38	-53.76	0.116
15.38	-53.70	0.116
15.39	-53.66	0.116
15.40	-53.61	0.115
15.40	-53.55	0.115
15.40	-53.51	0.115
15.41	-53.46	0.115
15.42	-53.40	0.115
15.42	-53.35	0.115
15.43	-53.30	0.115
15.43	-53.25	0.115
15.43	-53.20	0.115
15.44	-53.15	0.115
15.45	-53.10	0.115
15.45	-53.05	0.115
15.45	-53.00	0.115
15.46	-52.95	0.115
15.47	-52.90	0.115
15.47	-52.85	0.114
15.48	-52.80	0.114
15.48	-52.75	0.114
15.48	-52.70	0.114
15.49	-52.65	0.114
15.50	-52.60	0.114
15.50	-52.55	0.114
15.50	-52.50	0.114
15.51	-52.45	0.114
15.52	-52.40	0.114
15.52	-52.35	0.114
15.53	-52.30	0.114
15.53	-52.25	0.113
15.53	-52.20	0.113
15.54	-52.15	0.113
15.55	-52.10	0.113
15.55	-52.05	0.113
15.55	-52.00	0.113
15.56	-51.95	0.113
15.57	-51.90	0.113
15.57	-51.85	0.113
15.58	-51.80	0.113
15.58	-51.75	0.113
15.58	-51.70	0.113
15.59	-51.65	0.113
15.60	-51.60	0.113
15.60	-51.55	0.113
15.60	-51.50	0.113
15.61	-51.45	0.113
15.62	-51.40	0.113
15.62	-51.35	0.113
15.63	-51.30	0.113
15.63	-51.25	0.113
15.63	-51.20	0.113
15.64	-51.15	0.113
15.65	-51.10	0.113
15.65	-51.05	0.112
15.65	-51.00	0.112
15.66	-50.95	0.112
15.67	-50.90	0.112
15.67	-50.85	0.112
15.68	-50.80	0.112
15.68	-50.75	0.112
15.68	-50.70	0.112
15.69	-50.65	0.112
15.70	-50.60	0.112
15.70	-50.54	0.112
15.70	-50.50	0.112
15.71	-50.45	0.112
15.72	-50.40	0.112
15.72	-50.35	0.112
15.73	-50.30	0.112
15.73	-50.25	0.112
15.73	-50.19	0.112
15.74	-50.14	0.112
15.75	-50.09	0.112
15.75	-50.05	0.112
15.75	-50.00	0.112
15.76	-49.95	0.112
15.77	-49.90	0.112
15.77	-49.85	0.112
15.78	-49.80	0.112
15.78	-49.75	0.112
15.78	-49.70	0.112
15.79	-49.64	0.112
15.80	-49.59	0.112
15.80	-49.54	0.112
15.80	-49.50	0.112
15.81	-49.45	0.112
15.82	-49.39	0.112
15.82	-49.34	0.112
15.83	-49.29	0.112
15.83	-49.24	0.112
15.83	-49.19	0.112
15.84	-49.14	0.112
15.85	-49.09	0.112
15.85	-49.04	0.112
15.85	-48.99	0.112
15.86	-48.94	0.112
15.87	-48.89	0.112
15.87	-48.84	0.112
15.88	-48.79	0.112
15.88	-48.74	0.112
15.88	-48.69	0.112
15.89	-48.64	0.112
15.90	-48.59	0.112
15.90	-48.54	0.112
15.90	-48.49	0.112
15.91	-48.44	0.112
15.92	-48.39	0.112
15.92	-48.34	0.112
15.93	-48.29	0.112
15.93	-48.24	0.112
15.93	-48.19	0.112
15.94	-48.14	0.112
15.95	-48.09	0.112
15.95	-48.04	0.112
15.95	-47.99	0.112
15.96	-47.94	0.112
15.97	-47.89	0.112
15.97	-47.84	0.112
15.98	-47.79	0.112
15.98	-47.74	0.112
15.98	-47.69	0.112
15.99	-47.64	0.112
16.00	-47.59	0.112
16.00	-47.54	0.112
16.00	-47.49	0.112
16.01	-47.44	0.112
16.02	-47.39	0.112
16.02	-47.34	0.112
16.03	-47.29	0.112
16.03	-47.24	0.112
16.03	-47.19	0.112
16.04	-47.14	0.112
16.05	-47.09	0.112
16.05	-47.04	0.112
16.05	-46.99	0.112
16.06	-46.94	0.112
16.07	-46.89	0.112
16.07	-46.84	0.112
16.08	-46.79	0.112
16.08	-46.74	0.112
16.08	-46.69	0.112
16.09	-46.64	0.112
16.10	-46.59	0.112
16.10	-46.54	0.112
16.10	-46.49	0.112
16.11	-46.44	0.112
16.12	-46.39	0.112
16.12	-46.34	0.112
16.13	-46.29	0.112
16.13	-46.24	0.112
16.13	-46.19	0.112
16.14	-46.14	0.112
16.15	-46.09	0.113
16.15	-46.04	0.113
16.15	-45.99	0.113
16.16	-45.94	0.113
16.17	-45.89	0.113
16.17	-45.84	0.113
16.18	-45.79	0.113
16.18	-45.74	0.113
16.18	-45.69	0.113
16.19	-45.64	0.113
16.20	-45.59	0.113
16.20	-45.54	0.113
16.20	-45.49	0.113
16.21	-45.44	0.113
16.22	-45.39	0.113
16.22	-45.34	0.113
16.23	-45.29	0.113
16.23	-45.24	0.113
16.23	-45.19	0.113
16.24	-45.14	0.113
16.25	-45.08	0.113
16.25	-45.04	0.113
16.25	-44.99	0.113
16.26	-44.94	0.113
16.27	-44.89	0.113
16.27	-44.84	0.113
16.28	-44.79	0.113
16.28	-44.74	0.113
16.28	-44.68	0.113
16.29	-44.64	0.113
16.30	-44.59	0.113
16.30	-44.53	0.113
16.30	-44.48	0.113
16.31	-44.44	0.113
16.32	-44.38	0.113
16.32	-44.34	0.113
16.33	-44.28	0.113
16.33	-44.23	0.113
16.33	-44.18	0.113
16.34	-44.13	0.113
16.35	-44.08	0.113
16.35	-44.03	0.113
16.35	-43.98	0.113
16.36	-43.93	0.113
16.37	-43.88	0.113
16.37	-43.83	0.113
16.38	-43.78	0.113
16.38	-43.73	0.113
16.38	-43.68	0.113
16.39	-43.63	0.113
16.40	-43.58	0.113
16.40	-43.53	0.113
16.40	-43.48	0.113
16.41	-43.43	0.113
16.42	-43.38	0.113
16.42	-43.33	0.113
16.43	-43.28	0.113
16.43	-43.23	0.113
16.43	-43.18	0.113
16.44	-43.13	0.113
16.45	-43.08	0.113
16.45	-43.03	0.114
16.45	-42.98	0.114
16.46	-42.93	0.114
16.47	-42.88	0.113
16.47	-42.83	0.114
16.48	-42.78	0.114
16.48	-42.73	0.114
16.48	-42.68	0.114
16.49	-42.63	0.114
16.50	-42.58	0.114
16.50	-42.53	0.114
16.50	-42.48	0.114
16.51	-42.43	0.114
16.52	-42.38	0.114
16.52	-42.33	0.114
16.53	-42.28	0.114
16.53	-42.23	0.114
16.53	-42.18	0.114
16.54	-42.13	0.114
16.55	-42.08	0.114
16.55	-42.03	0.114
16.55	-41.98	0.114
16.56	-41.93	0.114
16.57	-41.88	0.114
16.57	-41.83	0.114
16.58	-41.78	0.114
16.58	-41.73	0.114
16.58	-41.68	0.114
16.59	-41.63	0.114
16.60	-41.58	0.114
16.60	-41.53	0.114
16.60	-41.48	0.114
16.61	-41.43	0.114
16.62	-41.38	0.114
16.62	-41.33	0.114
16.63	-41.28	0.114
16.63	-41.23	0.114
16.63	-41.18	0.114
16.64	-41.13	0.114
16.65	-41.08	0.114
16.65	-41.03	0.114
16.65	-40.98	0.114
16.66	-40.93	0.114
16.67	-40.88	0.114
16.67	-40.83	0.114
16.68	-40.78	0.114
16.68	-40.73	0.114
16.68	-40.68	0.114
16.69	-40.63	0.115
16.70	-40.58	0.115
16.70	-40.53	0.115
16.70	-40.48	0.115
16.71	-40.43	0.115
16.72	-40.38	0.115
16.72	-40.33	0.115
16.73	-40.28	0.115
16.73	-40.23	0.115
16.73	-40.18	0.115
16.74	-40.13	0.115
16.75	-40.08	0.115
16.75	-40.02	0.115
16.75	-39.98	0.115
16.76	-39.93	0.115
16.77	-39.88	0.115
16.77	-39.83	0.115
16.78	-39.78	0.115
16.78	-39.72	0.115
16.78	-39.68	0.115
16.79	-39.63	0.115
16.80	-39.58	0.115
16.80	-39.53	0.115
16.80	-39.48	0.115
16.81	-39.42	0.115
16.82	-39.38	0.115
16.82	-39.33	0.115
16.83	-39.28	0.115
16.83	-39.22	0.115
16.83	-39.18	0.115
16.84	-39.13	0.115
16.85	-39.08	0.115
16.85	-39.02	0.115
16.85	-38.97	0.115
16.86	-38.92	0.115
16.87	-38.87	0.115
16.87	-38.82	0.115
16.88	-38.77	0.115
16.88	-38.72	0.115
16.88	-38.67	0.115
16.89	-38.62	0.115
16.90	-38.57	0.115
16.90	-38.52	0.115
16.90	-38.47	0.115
16.91	-38.42	0.115
16.92	-38.37	0.115
16.92	-38.32	0.115
16.93	-38.27	0.115
16.93	-38.22	0.115
16.93	-38.17	0.115
16.94	-38.12	0.115
16.95	-38.07	0.116
16.95	-38.02	0.116
16.95	-37.97	0.116
16.96	-37.92	0.116
16.97	-37.87	0.116
16.97	-37.82	0.116
16.98	-37.77	0.116
16.98	-37.72	0.116
16.98	-37.67	0.116
16.99	-37.62	0.116
17.00	-37.57
17.00	-37.52
17.00	-37.47
17.01	-37.42
17.02	-37.37
17.02	-37.32
17.03	-37.27
17.03	-37.22
17.03	-37.17
17.04	-37.12
17.05
17.05
17.05