File: DSC/2023_07_01_CBD_Fragility_n50C_100C_SBK.txt
Filename	2023_07_01_CBD_Fragility_n50C_100C_SBK
Instrument name	DSC2A-00468 (192.168.1.100)
Operator	SBK
rundate	7/2/2023
Sample name	2023_07_01_CBD_Fragility_n50C_100C_SBK
proceduresegments	Equilibrate 100.00 °C; Ramp 10.00 °C/min to -50.00 °C; Data Off ; Isothermal 1.0 min; Data On ; Ramp 10.00 °C/min to 100.00 °C; Data Off ; Isothermal 1.0 min; Data On ; Ramp 40.00 °C/min to -50.00 °C; Data Off ; Isothermal 1.0 min; Data On ; Ramp 10.00 °C/min to 100.00 °C; Data Off ; Isothermal 1.0 min; Data On ; Ramp 30.00 °C/min to -50.00 °C; Data Off ; Isothermal 1.0 min; Data On ; Ramp 10.00 °C/min to 100.00 °C; Data Off ; Isothermal 1.0 min; Data On ; Ramp 20.00 °C/min to -50.00 °C; Data Off ; Isothermal 1.0 min; Data On ; Ramp 10.00 °C/min to 100.00 °C; Data Off ; Isothermal 1.0 min; Data On ; Sample Interval  0.2 s/pt; Ramp 5.00 °C/min to -50.00 °C; Data Off ; Isothermal 1.0 min; Data On ; Sample Interval  0.1 s/pt; Ramp 10.00 °C/min to 100.00 °C; Data Off ; Isothermal 1.0 min; Data On ; Sample Interval  1.0 s/pt; Ramp 1.00 °C/min to -50.00 °C; Data Off ; Isothermal 1.0 min; Data On ; Sample Interval  0.1 s/pt; Ramp 10.00 °C/min to 100.00 °C; Data Off ; Isothermal 1.0 min; Data On ; Sample Interval  2.0 s/pt; Ramp 0.50 °C/min to -50.00 °C; Data Off ; Isothermal 1.0 min; Data On ; Sample Interval  0.1 s/pt; Ramp 10.00 °C/min to 100.00 °C; Data Off ; Isothermal 1.0 min; Data On ; Sample Interval  10.0 s/pt; Ramp 0.10 °C/min to -50.00 °C; Data Off ; Isothermal 1.0 min; Data On ; Sample Interval  0.1 s/pt; Ramp 10.00 °C/min to 100.00 °C
[File Parameters]
Run date	7/2/2023 10:30:34 AM
Trios version	5.1.1.46572
Original File Name
Current File Name	C:\Users\yargerlab\Desktop\DSC Data\General\2023_07_01_CBD_Fragility_n50C_100C_SBK.tri
[Procedure]
Procedure Name	DSC -50C to 100C Varied cooling rates (40 - 0.1 cpm) cannabinoid fragility
Sample Name	2023_07_01_CBD_Fragility_n50C_100C_SBK
Sample Mass	3.95 mg
Reference Sample Mass	0 mg
Pan Mass	53.51 mg
Pan Number	41
Reference Pan Mass	53.66 mg
Reference Pan Number	46
Pan Type	Aluminum Hermetic
Comments	CBD crystalline powder. DSC84010 aluminum pan and DSC84011 aluminum hermetic lid. Wider temperature range to ensure full melting. Wider range of temperature scan rates.
Project Name	Silk ASDs
Operator	SBK
Test	Custom
Unload Max Temperature	30
Unload Min Temperature	30
Load Max Temperature	30
Load Min Temperature	30
Stop on Gas Flow Error	Yes
[Signal List]
Signal #1	Time (min)
Signal #2	Temperature (°C)
Signal #3	Heat Flow (mW)
Signal #4	Delta T (µV)
Signal #5	Delta Tzero (µV)
Signal #6	Tzero Temperature (°C)
Signal #7	Cell Purge (mL/min)
Signal #8	Heater Temp (°C)
Signal #9	Power Delivered (W)
Signal #10	Reference Junction Temperature (°C)
Signal #11	Flange Temperature (°C)
Signal #12	Heat Flow Phase (rad)
Signal #13	Total Heat Capacity (J/°C)
Signal #14	Heat Capacity (J/°C)
[Configuration]
Company Name	ASU
Instrument Name	DSC2A-00468
Instrument Type	DSC2500
Serial Number	DSC2A-00468
IP	192.168.1.100
Location of Instrument	MRRC
DisplayType	Unknown
Sample Interval 	0.1 s/pt
Selected Heat Flow	T4P
Exotherm Direction	Down
Cell Serial	DRC2-00792
Lid Type	Standard
Cooler	RCS 90
Leave Cooler on at End of Sequence	On
Gas 2	Nitrogen
Gas Selected	Channel 1
Flow Rate	50 mL/min
Secondary Purge	On
Licensed Heat Flow	Heat Flow T4P
Modulation Licensed	Yes
[Versions]
Common IDD Version	1
Cortex Version	VER 2.10.2.31
Driver	5.0.0.6
GDM Version	1.0.3.3
TouchscreenVersion	1.0.0.16145
FEP Version	1.2.1.21
FEP Bootloader	2.0.0.5
AutoSampler Version	2.1.1.26
Auto Sampler Bootloader	2.0.0.5
FCM Version	1.1.0.3
FCM Bootloader	2.0.0.5
[Experiment Logs]
Experiment Log Entry # 1	Equilibrate Segment 100 (C) Started
Experiment Log Entry # 3	Air Cool is off.
Experiment Log Entry # 5	Ramp Segment 10 C/min to -50 Started
Experiment Log Entry # 7	Data On set to 0
Experiment Log Entry # 9	Isothermal Segment 1 min started
Experiment Log Entry # 11	Data On set to 1
Experiment Log Entry # 13	Ramp Segment 10 C/min to 100 Started
Experiment Log Entry # 15	Data On set to 0
Experiment Log Entry # 17	Isothermal Segment 1 min started
Experiment Log Entry # 19	Data On set to 1
Experiment Log Entry # 21	Ramp Segment 40 C/min to -50 Started
Experiment Log Entry # 23	Data On set to 0
Experiment Log Entry # 25	Isothermal Segment 1 min started
Experiment Log Entry # 27	Data On set to 1
Experiment Log Entry # 29	Ramp Segment 10 C/min to 100 Started
Experiment Log Entry # 31	Data On set to 0
Experiment Log Entry # 33	Isothermal Segment 1 min started
Experiment Log Entry # 35	Data On set to 1
Experiment Log Entry # 37	Ramp Segment 30 C/min to -50 Started
Experiment Log Entry # 39	Data On set to 0
Experiment Log Entry # 41	Isothermal Segment 1 min started
Experiment Log Entry # 43	Data On set to 1
Experiment Log Entry # 45	Ramp Segment 10 C/min to 100 Started
Experiment Log Entry # 47	Data On set to 0
Experiment Log Entry # 49	Isothermal Segment 1 min started
Experiment Log Entry # 51	Data On set to 1
Experiment Log Entry # 53	Ramp Segment 20 C/min to -50 Started
Experiment Log Entry # 55	Data On set to 0
Experiment Log Entry # 57	Isothermal Segment 1 min started
Experiment Log Entry # 59	Data On set to 1
Experiment Log Entry # 61	Ramp Segment 10 C/min to 100 Started
Experiment Log Entry # 63	Data On set to 0
Experiment Log Entry # 65	Isothermal Segment 1 min started
Experiment Log Entry # 67	Data On set to 1
Experiment Log Entry # 69	Sampling Rate set to 0.2 sec/pt
Experiment Log Entry # 71	Ramp Segment 5 C/min to -50 Started
Experiment Log Entry # 73	Data On set to 0
Experiment Log Entry # 75	Isothermal Segment 1 min started
Experiment Log Entry # 77	Data On set to 1
Experiment Log Entry # 79	Sampling Rate set to 0.1 sec/pt
Experiment Log Entry # 81	Ramp Segment 10 C/min to 100 Started
Experiment Log Entry # 83	Data On set to 0
Experiment Log Entry # 85	Isothermal Segment 1 min started
Experiment Log Entry # 87	Data On set to 1
Experiment Log Entry # 89	Sampling Rate set to 1 sec/pt
Experiment Log Entry # 91	Ramp Segment 1 C/min to -50 Started
Experiment Log Entry # 93	Data On set to 0
Experiment Log Entry # 95	Isothermal Segment 1 min started
Experiment Log Entry # 97	Data On set to 1
Experiment Log Entry # 99	Sampling Rate set to 0.1 sec/pt
Experiment Log Entry # 101	Ramp Segment 10 C/min to 100 Started
Experiment Log Entry # 103	Data On set to 0
Experiment Log Entry # 105	Isothermal Segment 1 min started
Experiment Log Entry # 107	Data On set to 1
Experiment Log Entry # 109	Sampling Rate set to 2 sec/pt
Experiment Log Entry # 111	Ramp Segment 0.5 C/min to -50 Started
Experiment Log Entry # 113	Data On set to 0
Experiment Log Entry # 115	Isothermal Segment 1 min started
Experiment Log Entry # 117	Data On set to 1
Experiment Log Entry # 119	Sampling Rate set to 0.1 sec/pt
Experiment Log Entry # 121	Ramp Segment 10 C/min to 100 Started
Experiment Log Entry # 123	Auto sampler has detected that FEP has gone offline
Experiment Log Entry # 125	Data On set to 0
Experiment Log Entry # 127	Isothermal Segment 1 min started
Experiment Log Entry # 129	Data On set to 1
Experiment Log Entry # 131	Sampling Rate set to 10 sec/pt
Experiment Log Entry # 133	Ramp Segment 0.1 C/min to -50 Started
Experiment Log Entry # 135	Auto sampler has detected that FCM has gone offline
Experiment Log Entry # 137	Data On set to 0
Experiment Log Entry # 139	Isothermal Segment 1 min started
Experiment Log Entry # 141	Data On set to 1
Experiment Log Entry # 143	Sampling Rate set to 0.1 sec/pt
Experiment Log Entry # 145	Ramp Segment 10 C/min to 100 Started
[Method Log]
Method Log Entry # 1	Equilibrate 100 °C
Method Log Entry # 2	(Ramp 345815) Ramp 10 °C/minute to -50 °C
Method Log Entry # 3	Data Off
Method Log Entry # 4	Isothermal 1 minutes
Method Log Entry # 5	Data On
Method Log Entry # 6	(Ramp 345819) Ramp 10 °C/minute to 100 °C
Method Log Entry # 7	Data Off
Method Log Entry # 8	Isothermal 1 minutes
Method Log Entry # 9	Data On
Method Log Entry # 10	(Ramp 345823) Ramp 40 °C/minute to -50 °C
Method Log Entry # 11	Data Off
Method Log Entry # 12	Isothermal 1 minutes
Method Log Entry # 13	Data On
Method Log Entry # 14	(Ramp 345827) Ramp 10 °C/minute to 100 °C
Method Log Entry # 15	Data Off
Method Log Entry # 16	Isothermal 1 minutes
Method Log Entry # 17	Data On
Method Log Entry # 18	(Ramp 345831) Ramp 30 °C/minute to -50 °C
Method Log Entry # 19	Data Off
Method Log Entry # 20	Isothermal 1 minutes
Method Log Entry # 21	Data On
Method Log Entry # 22	(Ramp 345835) Ramp 10 °C/minute to 100 °C
Method Log Entry # 23	Data Off
Method Log Entry # 24	Isothermal 1 minutes
Method Log Entry # 25	Data On
Method Log Entry # 26	(Ramp 345839) Ramp 20 °C/minute to -50 °C
Method Log Entry # 27	Data Off
Method Log Entry # 28	Isothermal 1 minutes
Method Log Entry # 29	Data On
Method Log Entry # 30	(Ramp 345843) Ramp 10 °C/minute to 100 °C
Method Log Entry # 31	Data Off
Method Log Entry # 32	Isothermal 1 minutes
Method Log Entry # 33	Data On
Method Log Entry # 34	Sampling Interval 0.2 Seconds/point
Method Log Entry # 35	(Ramp 345848) Ramp 5 °C/minute to -50 °C
Method Log Entry # 36	Data Off
Method Log Entry # 37	Isothermal 1 minutes
Method Log Entry # 38	Data On
Method Log Entry # 39	Sampling Interval 0.1 Seconds/point
Method Log Entry # 40	(Ramp 345853) Ramp 10 °C/minute to 100 °C
Method Log Entry # 41	Data Off
Method Log Entry # 42	Isothermal 1 minutes
Method Log Entry # 43	Data On
Method Log Entry # 44	Sampling Interval 1 Seconds/point
Method Log Entry # 45	(Ramp 345858) Ramp 1 °C/minute to -50 °C
Method Log Entry # 46	Data Off
Method Log Entry # 47	Isothermal 1 minutes
Method Log Entry # 48	Data On
Method Log Entry # 49	Sampling Interval 0.1 Seconds/point
Method Log Entry # 50	(Ramp 345863) Ramp 10 °C/minute to 100 °C
Method Log Entry # 51	Data Off
Method Log Entry # 52	Isothermal 1 minutes
Method Log Entry # 53	Data On
Method Log Entry # 54	Sampling Interval 2 Seconds/point
Method Log Entry # 55	(Ramp 345868) Ramp 0.5 °C/minute to -50 °C
Method Log Entry # 56	Data Off
Method Log Entry # 57	Isothermal 1 minutes
Method Log Entry # 58	Data On
Method Log Entry # 59	Sampling Interval 0.1 Seconds/point
Method Log Entry # 60	(Ramp 345873) Ramp 10 °C/minute to 100 °C
Method Log Entry # 61	Data Off
Method Log Entry # 62	Isothermal 1 minutes
Method Log Entry # 63	Data On
Method Log Entry # 64	Sampling Interval 10 Seconds/point
Method Log Entry # 65	(Ramp 345878) Ramp 0.1 °C/minute to -50 °C
Method Log Entry # 66	Data Off
Method Log Entry # 67	Isothermal 1 minutes
Method Log Entry # 68	Data On
Method Log Entry # 69	Sampling Interval 0.1 Seconds/point
Method Log Entry # 70	(Ramp 345883) Ramp 10 °C/minute to 100 °C
Cell Serial	DRC2-00792
[T1 Calibration]
Slope	-0.008529666
Offset	9.636258
Initial Temperature	98.23
GUID	f8bfdadc-4977-4fdf-ba6d-0ba9134940c3
[TZero Calibration]
Date Applied	11/29/2022 4:06:13 PM
Description	From -89.059 °C to 396.009 °C at 20.000°C/min
Gas Type	Nitrogen
Pan Type	None
Source Files 1	C:\Users\yargerlab\Desktop\DSC Data\General\TZero_calibration_11_29_22_2nd(2).tri
Source Files 2	C:\Users\yargerlab\Desktop\DSC Data\General\TZero_calibration_11_29_22_2nd(3).tri
Delta T Offset	13.05235
Delta T Slope	-0.007271007
Delta T0 Offset	-13.69128
Delta T0 Slope	0.06063341
[Temperature Calibration]
Date Applied	11/29/2022 7:12:28 PM
Description	From 106.590 °C to 186.590 °C at 10.000°C/min
Gas Type	Nitrogen
Pan Type	Tzero Aluminum Hermetic
Source Files 1	C:\Users\yargerlab\Desktop\DSC Data\General\Indium(6).tri
Measured 1	157.391
Known 1	156.598
[Cell Constant Calibration]
Date Applied	11/29/2022 7:12:29 PM
Description	From 106.590 °C to 186.590 °C at 10.000°C/min
Gas Type	Nitrogen
Pan Type	Tzero Aluminum Hermetic
Source Files 1	C:\Users\yargerlab\Desktop\DSC Data\General\Indium(6).tri
T4P KCell	1.006051
Onset Slope	63.26126 mW/°C
[Direct Cp Calibration]
Date Applied	11/30/2022 11:04:51 AM
Description	From -79.983 °C to 298.409 °C at 10.000°C/min
Gas Type	Nitrogen
Pan Type	Tzero Aluminum Hermetic
Source Files 1	C:\Users\yargerlab\Desktop\DSC Data\General\Sapphire_Heat_Capacity_11_30_22.tri
[Rev Cp Calibration]
Date Applied	11/30/2022 1:58:51 PM
Description	From -79.996 °C to 292.812 °C at 3.000°C/min
Gas Type	Nitrogen
Pan Type	Tzero Aluminum Hermetic
Source Files 1	C:\Users\yargerlab\Desktop\DSC Data\General\Sapphire_MDSC_Calibration_11_30_22.tri
[step]
Ramp 10.00 °C/min to -50.00 °C
Time	Temperature	Heat Flow (Normalized)
min	°C	W/g
0.00	100.10	-0.023
0.01	100.10	-0.029
0.02	100.10	-0.031
0.03	100.10	-0.035
0.05	100.10	-0.040
0.06	100.09	-0.053
0.07	100.08	-0.069
0.08	100.05	-0.091
0.09	100.03	-0.118
0.11	99.99	-0.148
0.12	99.94	-0.179
0.13	99.88	-0.211
0.14	99.82	-0.240
0.15	99.74	-0.268
0.16	99.67	-0.292
0.18	99.58	-0.312
0.19	99.50	-0.333
0.20	99.41	-0.348
0.21	99.32	-0.362
0.22	99.23	-0.376
0.23	99.13	-0.388
0.24	99.03	-0.397
0.26	98.93	-0.408
0.27	98.83	-0.416
0.28	98.73	-0.424
0.29	98.63	-0.431
0.30	98.52	-0.436
0.31	98.41	-0.443
0.33	98.31	-0.448
0.34	98.20	-0.453
0.35	98.09	-0.455
0.36	97.98	-0.458
0.37	97.87	-0.461
0.39	97.76	-0.464
0.40	97.65	-0.466
0.41	97.54	-0.468
0.42	97.42	-0.469
0.43	97.31	-0.472
0.44	97.20	-0.472
0.45	97.09	-0.473
0.47	96.97	-0.474
0.48	96.86	-0.476
0.49	96.74	-0.476
0.50	96.63	-0.476
0.51	96.52	-0.477
0.53	96.40	-0.477
0.54	96.29	-0.478
0.55	96.17	-0.478
0.56	96.06	-0.478
0.57	95.94	-0.478
0.58	95.83	-0.479
0.60	95.72	-0.479
0.61	95.60	-0.479
0.62	95.49	-0.479
0.63	95.37	-0.480
0.64	95.26	-0.480
0.65	95.14	-0.480
0.67	95.03	-0.480
0.68	94.91	-0.480
0.69	94.80	-0.481
0.70	94.68	-0.481
0.71	94.56	-0.481
0.72	94.45	-0.481
0.73	94.33	-0.481
0.75	94.22	-0.481
0.76	94.10	-0.482
0.77	93.99	-0.482
0.78	93.87	-0.482
0.79	93.75	-0.482
0.80	93.64	-0.482
0.82	93.52	-0.482
0.83	93.41	-0.482
0.84	93.29	-0.482
0.85	93.18	-0.482
0.86	93.06	-0.482
0.88	92.94	-0.482
0.89	92.83	-0.482
0.90	92.71	-0.482
0.91	92.60	-0.482
0.92	92.48	-0.482
0.93	92.36	-0.482
0.95	92.25	-0.482
0.96	92.13	-0.482
0.97	92.02	-0.482
0.98	91.90	-0.482
0.99	91.78	-0.482
1.00	91.67	-0.482
1.02	91.55	-0.482
1.03	91.44	-0.482
1.04	91.32	-0.482
1.05	91.20	-0.482
1.06	91.09	-0.482
1.07	90.97	-0.482
1.08	90.86	-0.482
1.10	90.74	-0.482
1.11	90.62	-0.482
1.12	90.51	-0.481
1.13	90.39	-0.481
1.14	90.28	-0.481
1.16	90.16	-0.481
1.17	90.04	-0.481
1.18	89.93	-0.481
1.19	89.81	-0.481
1.20	89.69	-0.481
1.21	89.58	-0.480
1.23	89.46	-0.480
1.24	89.34	-0.480
1.25	89.23	-0.480
1.26	89.11	-0.480
1.27	89.00	-0.480
1.28	88.88	-0.480
1.29	88.76	-0.479
1.31	88.65	-0.479
1.32	88.53	-0.479
1.33	88.41	-0.479
1.34	88.30	-0.479
1.35	88.18	-0.479
1.37	88.07	-0.478
1.38	87.95	-0.478
1.39	87.83	-0.478
1.40	87.72	-0.478
1.41	87.60	-0.478
1.42	87.48	-0.478
1.43	87.37	-0.477
1.45	87.25	-0.477
1.46	87.13	-0.477
1.47	87.02	-0.477
1.48	86.90	-0.477
1.49	86.78	-0.477
1.51	86.67	-0.476
1.52	86.55	-0.476
1.53	86.44	-0.476
1.54	86.32	-0.476
1.55	86.20	-0.476
1.56	86.09	-0.476
1.58	85.97	-0.476
1.59	85.85	-0.475
1.60	85.74	-0.475
1.61	85.62	-0.475
1.62	85.50	-0.475
1.63	85.39	-0.475
1.64	85.27	-0.475
1.66	85.15	-0.475
1.67	85.04	-0.474
1.68	84.92	-0.474
1.69	84.81	-0.474
1.70	84.69	-0.474
1.72	84.57	-0.474
1.73	84.46	-0.474
1.74	84.34	-0.473
1.75	84.22	-0.473
1.76	84.11	-0.473
1.77	83.99	-0.473
1.78	83.87	-0.473
1.80	83.76	-0.473
1.81	83.64	-0.473
1.82	83.52	-0.472
1.83	83.41	-0.472
1.84	83.29	-0.472
1.86	83.17	-0.472
1.87	83.06	-0.472
1.88	82.94	-0.472
1.89	82.83	-0.472
1.90	82.71	-0.472
1.91	82.59	-0.471
1.93	82.48	-0.471
1.94	82.36	-0.471
1.95	82.24	-0.471
1.96	82.13	-0.471
1.97	82.01	-0.471
1.98	81.89	-0.471
1.99	81.78	-0.471
2.01	81.66	-0.470
2.02	81.54	-0.470
2.03	81.43	-0.470
2.04	81.31	-0.470
2.05	81.19	-0.470
2.07	81.08	-0.470
2.08	80.96	-0.470
2.09	80.84	-0.469
2.10	80.73	-0.469
2.11	80.61	-0.469
2.12	80.50	-0.469
2.14	80.38	-0.469
2.15	80.26	-0.469
2.16	80.15	-0.469
2.17	80.03	-0.468
2.18	79.91	-0.468
2.19	79.80	-0.468
2.21	79.68	-0.468
2.22	79.56	-0.468
2.23	79.45	-0.468
2.24	79.33	-0.468
2.25	79.21	-0.468
2.26	79.10	-0.467
2.28	78.98	-0.467
2.29	78.86	-0.467
2.30	78.75	-0.467
2.31	78.63	-0.467
2.32	78.51	-0.467
2.33	78.40	-0.467
2.34	78.28	-0.466
2.36	78.16	-0.466
2.37	78.05	-0.466
2.38	77.93	-0.466
2.39	77.81	-0.466
2.40	77.70	-0.466
2.41	77.58	-0.466
2.43	77.46	-0.465
2.44	77.35	-0.465
2.45	77.23	-0.465
2.46	77.11	-0.465
2.47	77.00	-0.465
2.49	76.88	-0.465
2.50	76.76	-0.465
2.51	76.65	-0.464
2.52	76.53	-0.464
2.53	76.42	-0.464
2.54	76.30	-0.464
2.56	76.18	-0.464
2.57	76.07	-0.464
2.58	75.95	-0.464
2.59	75.83	-0.464
2.60	75.72	-0.463
2.61	75.60	-0.463
2.63	75.48	-0.463
2.64	75.37	-0.463
2.65	75.25	-0.463
2.66	75.13	-0.463
2.67	75.02	-0.462
2.68	74.90	-0.462
2.69	74.78	-0.462
2.71	74.67	-0.462
2.72	74.55	-0.462
2.73	74.43	-0.462
2.74	74.32	-0.462
2.75	74.20	-0.461
2.76	74.08	-0.461
2.78	73.97	-0.461
2.79	73.85	-0.461
2.80	73.73	-0.461
2.81	73.62	-0.461
2.82	73.50	-0.461
2.84	73.38	-0.461
2.85	73.27	-0.460
2.86	73.15	-0.460
2.87	73.03	-0.460
2.88	72.92	-0.460
2.89	72.80	-0.460
2.91	72.68	-0.460
2.92	72.57	-0.459
2.93	72.45	-0.459
2.94	72.34	-0.459
2.95	72.22	-0.458
2.96	72.10	-0.458
2.98	71.99	-0.458
2.99	71.87	-0.458
3.00	71.75	-0.458
3.01	71.64	-0.458
3.02	71.52	-0.458
3.03	71.40	-0.458
3.04	71.29	-0.457
3.06	71.17	-0.457
3.07	71.05	-0.457
3.08	70.94	-0.457
3.09	70.82	-0.457
3.10	70.70	-0.457
3.11	70.59	-0.457
3.13	70.47	-0.457
3.14	70.35	-0.456
3.15	70.24	-0.456
3.16	70.12	-0.456
3.17	70.00	-0.456
3.19	69.89	-0.456
3.20	69.77	-0.456
3.21	69.65	-0.456
3.22	69.54	-0.456
3.23	69.42	-0.455
3.24	69.30	-0.455
3.26	69.19	-0.455
3.27	69.07	-0.455
3.28	68.95	-0.455
3.29	68.84	-0.455
3.30	68.72	-0.455
3.31	68.60	-0.454
3.33	68.49	-0.454
3.34	68.37	-0.454
3.35	68.26	-0.454
3.36	68.14	-0.454
3.37	68.02	-0.454
3.38	67.90	-0.454
3.39	67.79	-0.453
3.41	67.67	-0.453
3.42	67.56	-0.453
3.43	67.44	-0.453
3.44	67.32	-0.453
3.45	67.21	-0.453
3.46	67.09	-0.453
3.48	66.97	-0.452
3.49	66.86	-0.452
3.50	66.74	-0.452
3.51	66.62	-0.452
3.52	66.51	-0.452
3.54	66.39	-0.452
3.55	66.27	-0.452
3.56	66.16	-0.452
3.57	66.04	-0.451
3.58	65.92	-0.451
3.59	65.81	-0.451
3.61	65.69	-0.451
3.62	65.57	-0.451
3.63	65.46	-0.451
3.64	65.34	-0.451
3.65	65.23	-0.451
3.66	65.11	-0.450
3.68	64.99	-0.450
3.69	64.88	-0.450
3.70	64.76	-0.450
3.71	64.64	-0.450
3.72	64.53	-0.450
3.73	64.41	-0.450
3.74	64.29	-0.450
3.76	64.18	-0.449
3.77	64.06	-0.449
3.78	63.94	-0.449
3.79	63.83	-0.449
3.80	63.71	-0.449
3.81	63.59	-0.449
3.83	63.48	-0.449
3.84	63.36	-0.448
3.85	63.24	-0.448
3.86	63.13	-0.448
3.87	63.01	-0.448
3.89	62.89	-0.448
3.90	62.78	-0.448
3.91	62.66	-0.448
3.92	62.54	-0.448
3.93	62.43	-0.447
3.94	62.31	-0.447
3.96	62.20	-0.447
3.97	62.08	-0.447
3.98	61.96	-0.447
3.99	61.85	-0.447
4.00	61.73	-0.446
4.01	61.61	-0.446
4.03	61.50	-0.446
4.04	61.38	-0.446
4.05	61.26	-0.446
4.06	61.15	-0.446
4.07	61.03	-0.446
4.08	60.91	-0.446
4.09	60.80	-0.445
4.11	60.68	-0.445
4.12	60.56	-0.445
4.13	60.45	-0.445
4.14	60.33	-0.445
4.15	60.22	-0.445
4.16	60.10	-0.445
4.18	59.98	-0.445
4.19	59.86	-0.444
4.20	59.75	-0.444
4.21	59.63	-0.444
4.22	59.51	-0.444
4.24	59.40	-0.444
4.25	59.28	-0.444
4.26	59.17	-0.444
4.27	59.05	-0.444
4.28	58.93	-0.443
4.29	58.82	-0.443
4.30	58.70	-0.443
4.32	58.58	-0.443
4.33	58.47	-0.443
4.34	58.35	-0.443
4.35	58.23	-0.443
4.36	58.12	-0.442
4.38	58.00	-0.442
4.39	57.88	-0.442
4.40	57.77	-0.442
4.41	57.65	-0.442
4.42	57.53	-0.442
4.43	57.42	-0.442
4.45	57.30	-0.442
4.46	57.18	-0.442
4.47	57.07	-0.441
4.48	56.95	-0.441
4.49	56.83	-0.441
4.50	56.72	-0.441
4.51	56.60	-0.441
4.53	56.48	-0.441
4.54	56.37	-0.441
4.55	56.25	-0.441
4.56	56.13	-0.441
4.57	56.02	-0.440
4.59	55.90	-0.440
4.60	55.78	-0.440
4.61	55.67	-0.440
4.62	55.55	-0.440
4.63	55.44	-0.440
4.64	55.32	-0.440
4.65	55.20	-0.439
4.67	55.09	-0.439
4.68	54.97	-0.439
4.69	54.85	-0.439
4.70	54.74	-0.439
4.71	54.62	-0.439
4.73	54.50	-0.439
4.74	54.39	-0.439
4.75	54.27	-0.438
4.76	54.15	-0.438
4.77	54.04	-0.438
4.78	53.92	-0.438
4.80	53.80	-0.438
4.81	53.69	-0.438
4.82	53.57	-0.438
4.83	53.45	-0.438
4.84	53.34	-0.437
4.85	53.22	-0.437
4.86	53.10	-0.437
4.88	52.99	-0.437
4.89	52.87	-0.437
4.90	52.75	-0.437
4.91	52.64	-0.437
4.92	52.52	-0.437
4.94	52.40	-0.436
4.95	52.29	-0.436
4.96	52.17	-0.436
4.97	52.06	-0.436
4.98	51.94	-0.436
4.99	51.82	-0.436
5.00	51.71	-0.436
5.02	51.59	-0.436
5.03	51.47	-0.435
5.04	51.36	-0.435
5.05	51.24	-0.435
5.06	51.12	-0.435
5.08	51.00	-0.435
5.09	50.89	-0.434
5.10	50.77	-0.434
5.11	50.66	-0.434
5.12	50.54	-0.434
5.13	50.42	-0.434
5.15	50.31	-0.434
5.16	50.19	-0.434
5.17	50.08	-0.434
5.18	49.96	-0.433
5.19	49.84	-0.433
5.20	49.72	-0.433
5.21	49.61	-0.433
5.23	49.49	-0.433
5.24	49.37	-0.433
5.25	49.26	-0.432
5.26	49.14	-0.432
5.27	49.03	-0.432
5.29	48.91	-0.432
5.30	48.79	-0.432
5.31	48.67	-0.432
5.32	48.56	-0.432
5.33	48.44	-0.432
5.34	48.33	-0.432
5.35	48.21	-0.431
5.37	48.09	-0.431
5.38	47.98	-0.431
5.39	47.86	-0.431
5.40	47.74	-0.431
5.41	47.63	-0.431
5.43	47.51	-0.431
5.44	47.39	-0.431
5.45	47.28	-0.430
5.46	47.16	-0.430
5.47	47.04	-0.430
5.48	46.93	-0.430
5.50	46.81	-0.430
5.51	46.69	-0.430
5.52	46.58	-0.430
5.53	46.46	-0.430
5.54	46.34	-0.430
5.55	46.23	-0.429
5.56	46.11	-0.429
5.58	46.00	-0.429
5.59	45.88	-0.429
5.60	45.76	-0.429
5.61	45.64	-0.429
5.62	45.53	-0.429
5.64	45.41	-0.429
5.65	45.30	-0.428
5.66	45.18	-0.428
5.67	45.06	-0.428
5.68	44.95	-0.428
5.69	44.83	-0.428
5.70	44.71	-0.428
5.72	44.60	-0.428
5.73	44.48	-0.428
5.74	44.36	-0.427
5.75	44.25	-0.427
5.76	44.13	-0.427
5.78	44.01	-0.427
5.79	43.90	-0.427
5.80	43.78	-0.427
5.81	43.66	-0.427
5.82	43.55	-0.427
5.83	43.43	-0.426
5.85	43.31	-0.426
5.86	43.20	-0.426
5.87	43.08	-0.426
5.88	42.96	-0.426
5.89	42.85	-0.426
5.90	42.73	-0.426
5.91	42.61	-0.426
5.93	42.50	-0.426
5.94	42.38	-0.425
5.95	42.26	-0.425
5.96	42.15	-0.425
5.97	42.03	-0.425
5.99	41.91	-0.425
6.00	41.80	-0.425
6.01	41.68	-0.424
6.02	41.56	-0.424
6.03	41.45	-0.424
6.04	41.33	-0.424
6.05	41.22	-0.424
6.07	41.10	-0.424
6.08	40.98	-0.424
6.09	40.87	-0.423
6.10	40.75	-0.423
6.11	40.63	-0.423
6.13	40.52	-0.423
6.14	40.40	-0.423
6.15	40.28	-0.423
6.16	40.17	-0.423
6.17	40.05	-0.423
6.18	39.93	-0.422
6.20	39.82	-0.422
6.21	39.70	-0.422
6.22	39.58	-0.422
6.23	39.47	-0.422
6.24	39.35	-0.422
6.25	39.23	-0.422
6.26	39.12	-0.421
6.28	39.00	-0.421
6.29	38.88	-0.421
6.30	38.77	-0.421
6.31	38.65	-0.421
6.32	38.54	-0.421
6.34	38.42	-0.421
6.35	38.30	-0.421
6.36	38.19	-0.421
6.37	38.07	-0.420
6.38	37.95	-0.420
6.39	37.83	-0.420
6.40	37.72	-0.420
6.42	37.60	-0.420
6.43	37.49	-0.420
6.44	37.37	-0.420
6.45	37.25	-0.420
6.46	37.13	-0.419
6.48	37.02	-0.419
6.49	36.90	-0.419
6.50	36.79	-0.419
6.51	36.67	-0.419
6.52	36.55	-0.419
6.53	36.44	-0.419
6.55	36.32	-0.418
6.56	36.20	-0.418
6.57	36.09	-0.418
6.58	35.97	-0.418
6.59	35.85	-0.418
6.60	35.74	-0.418
6.61	35.62	-0.418
6.63	35.50	-0.417
6.64	35.39	-0.417
6.65	35.27	-0.417
6.66	35.15	-0.417
6.67	35.04	-0.417
6.69	34.92	-0.417
6.70	34.80	-0.416
6.71	34.69	-0.416
6.72	34.57	-0.416
6.73	34.46	-0.416
6.74	34.34	-0.416
6.75	34.22	-0.416
6.77	34.11	-0.416
6.78	33.99	-0.415
6.79	33.87	-0.415
6.80	33.76	-0.415
6.81	33.64	-0.415
6.83	33.52	-0.415
6.84	33.41	-0.415
6.85	33.29	-0.415
6.86	33.17	-0.415
6.87	33.06	-0.415
6.88	32.94	-0.415
6.90	32.82	-0.414
6.91	32.71	-0.414
6.92	32.59	-0.414
6.93	32.47	-0.414
6.94	32.36	-0.414
6.95	32.24	-0.414
6.96	32.13	-0.414
6.98	32.01	-0.414
6.99	31.89	-0.413
7.00	31.78	-0.413
7.01	31.66	-0.413
7.02	31.54	-0.413
7.04	31.42	-0.413
7.05	31.31	-0.413
7.06	31.19	-0.413
7.07	31.07	-0.413
7.08	30.96	-0.413
7.09	30.84	-0.412
7.10	30.73	-0.412
7.12	30.61	-0.412
7.13	30.49	-0.412
7.14	30.38	-0.412
7.15	30.26	-0.412
7.16	30.14	-0.411
7.18	30.03	-0.411
7.19	29.91	-0.411
7.20	29.79	-0.411
7.21	29.68	-0.411
7.22	29.56	-0.411
7.23	29.44	-0.411
7.25	29.33	-0.411
7.26	29.21	-0.410
7.27	29.09	-0.410
7.28	28.98	-0.410
7.29	28.86	-0.410
7.30	28.75	-0.410
7.31	28.63	-0.410
7.33	28.51	-0.410
7.34	28.40	-0.410
7.35	28.28	-0.409
7.36	28.16	-0.409
7.37	28.04	-0.409
7.39	27.93	-0.409
7.40	27.81	-0.409
7.41	27.70	-0.409
7.42	27.58	-0.409
7.43	27.46	-0.408
7.44	27.35	-0.408
7.45	27.23	-0.408
7.47	27.11	-0.408
7.48	27.00	-0.408
7.49	26.88	-0.408
7.50	26.76	-0.408
7.51	26.65	-0.408
7.53	26.53	-0.407
7.54	26.41	-0.407
7.55	26.30	-0.407
7.56	26.18	-0.407
7.57	26.06	-0.407
7.58	25.95	-0.407
7.60	25.83	-0.407
7.61	25.71	-0.406
7.62	25.60	-0.406
7.63	25.48	-0.406
7.64	25.36	-0.406
7.65	25.25	-0.406
7.66	25.13	-0.406
7.68	25.02	-0.406
7.69	24.90	-0.405
7.70	24.78	-0.405
7.71	24.67	-0.405
7.72	24.55	-0.405
7.74	24.43	-0.405
7.75	24.32	-0.405
7.76	24.20	-0.405
7.77	24.08	-0.404
7.78	23.97	-0.404
7.79	23.85	-0.404
7.80	23.74	-0.404
7.82	23.62	-0.404
7.83	23.50	-0.404
7.84	23.38	-0.403
7.85	23.27	-0.403
7.86	23.15	-0.403
7.88	23.03	-0.403
7.89	22.92	-0.403
7.90	22.80	-0.403
7.91	22.68	-0.403
7.92	22.57	-0.402
7.93	22.45	-0.402
7.95	22.34	-0.402
7.96	22.22	-0.402
7.97	22.10	-0.402
7.98	21.98	-0.402
7.99	21.87	-0.402
8.00	21.75	-0.401
8.01	21.64	-0.401
8.03	21.52	-0.401
8.04	21.40	-0.401
8.05	21.29	-0.401
8.06	21.17	-0.401
8.07	21.05	-0.401
8.09	20.94	-0.400
8.10	20.82	-0.400
8.11	20.70	-0.400
8.12	20.59	-0.400
8.13	20.47	-0.400
8.14	20.36	-0.400
8.15	20.24	-0.400
8.17	20.12	-0.399
8.18	20.00	-0.399
8.19	19.89	-0.399
8.20	19.77	-0.399
8.21	19.65	-0.399
8.23	19.54	-0.398
8.24	19.42	-0.398
8.25	19.31	-0.398
8.26	19.19	-0.398
8.27	19.07	-0.398
8.28	18.95	-0.398
8.30	18.84	-0.398
8.31	18.72	-0.398
8.32	18.61	-0.398
8.33	18.49	-0.397
8.34	18.37	-0.397
8.35	18.26	-0.397
8.36	18.14	-0.397
8.38	18.02	-0.397
8.39	17.91	-0.396
8.40	17.79	-0.396
8.41	17.67	-0.396
8.42	17.56	-0.396
8.44	17.44	-0.396
8.45	17.32	-0.396
8.46	17.21	-0.396
8.47	17.09	-0.395
8.48	16.97	-0.395
8.49	16.86	-0.395
8.50	16.74	-0.395
8.52	16.62	-0.395
8.53	16.51	-0.395
8.54	16.39	-0.395
8.55	16.27	-0.394
8.56	16.16	-0.394
8.58	16.04	-0.394
8.59	15.93	-0.394
8.60	15.81	-0.394
8.61	15.69	-0.394
8.62	15.58	-0.394
8.63	15.46	-0.393
8.65	15.34	-0.393
8.66	15.23	-0.393
8.67	15.11	-0.393
8.68	14.99	-0.393
8.69	14.88	-0.393
8.70	14.76	-0.393
8.72	14.64	-0.393
8.73	14.53	-0.393
8.74	14.41	-0.392
8.75	14.30	-0.392
8.76	14.18	-0.392
8.77	14.06	-0.392
8.78	13.95	-0.392
8.80	13.83	-0.392
8.81	13.71	-0.392
8.82	13.60	-0.391
8.83	13.48	-0.391
8.84	13.36	-0.391
8.85	13.25	-0.391
8.87	13.13	-0.391
8.88	13.01	-0.391
8.89	12.90	-0.391
8.90	12.78	-0.391
8.91	12.66	-0.390
8.93	12.55	-0.390
8.94	12.43	-0.390
8.95	12.31	-0.390
8.96	12.20	-0.390
8.97	12.08	-0.390
8.98	11.97	-0.390
9.00	11.85	-0.389
9.01	11.73	-0.389
9.02	11.61	-0.389
9.03	11.50	-0.389
9.04	11.38	-0.389
9.05	11.26	-0.389
9.07	11.15	-0.389
9.08	11.03	-0.389
9.09	10.92	-0.388
9.10	10.80	-0.388
9.11	10.68	-0.388
9.12	10.57	-0.388
9.13	10.45	-0.388
9.15	10.33	-0.388
9.16	10.22	-0.387
9.17	10.10	-0.387
9.18	9.99	-0.387
9.19	9.87	-0.387
9.20	9.75	-0.387
9.22	9.63	-0.387
9.23	9.52	-0.386
9.24	9.40	-0.386
9.25	9.29	-0.386
9.26	9.17	-0.386
9.28	9.05	-0.386
9.29	8.94	-0.385
9.30	8.82	-0.385
9.31	8.70	-0.385
9.32	8.59	-0.385
9.33	8.47	-0.385
9.35	8.36	-0.385
9.36	8.24	-0.385
9.37	8.12	-0.384
9.38	8.00	-0.384
9.39	7.89	-0.384
9.40	7.77	-0.384
9.42	7.65	-0.384
9.43	7.54	-0.384
9.44	7.42	-0.384
9.45	7.31	-0.383
9.46	7.19	-0.383
9.47	7.07	-0.383
9.48	6.96	-0.383
9.50	6.84	-0.383
9.51	6.73	-0.383
9.52	6.61	-0.383
9.53	6.49	-0.382
9.54	6.38	-0.382
9.55	6.26	-0.382
9.57	6.14	-0.382
9.58	6.02	-0.382
9.59	5.91	-0.382
9.60	5.79	-0.382
9.61	5.67	-0.381
9.63	5.56	-0.381
9.64	5.44	-0.381
9.65	5.32	-0.381
9.66	5.21	-0.381
9.67	5.09	-0.381
9.68	4.98	-0.381
9.70	4.86	-0.381
9.71	4.74	-0.380
9.72	4.63	-0.380
9.73	4.51	-0.380
9.74	4.39	-0.380
9.75	4.28	-0.380
9.77	4.16	-0.380
9.78	4.04	-0.380
9.79	3.93	-0.379
9.80	3.81	-0.379
9.81	3.69	-0.379
9.82	3.58	-0.379
9.83	3.46	-0.379
9.85	3.34	-0.379
9.86	3.23	-0.379
9.87	3.11	-0.379
9.88	2.99	-0.378
9.89	2.88	-0.378
9.90	2.76	-0.378
9.92	2.64	-0.378
9.93	2.53	-0.378
9.94	2.41	-0.378
9.95	2.29	-0.378
9.96	2.18	-0.378
9.98	2.06	-0.377
9.99	1.94	-0.377
10.00	1.83	-0.377
10.01	1.71	-0.377
10.02	1.59	-0.377
10.03	1.48	-0.377
10.05	1.36	-0.377
10.06	1.24	-0.377
10.07	1.13	-0.377
10.08	1.01	-0.376
10.09	0.89	-0.376
10.10	0.78	-0.376
10.12	0.66	-0.376
10.13	0.54	-0.376
10.14	0.43	-0.376
10.15	0.31	-0.376
10.16	0.19	-0.376
10.17	0.08	-0.376
10.18	-0.04	-0.375
10.20	-0.16	-0.375
10.21	-0.28	-0.375
10.22	-0.39	-0.375
10.23	-0.51	-0.375
10.24	-0.62	-0.375
10.25	-0.74	-0.375
10.27	-0.86	-0.375
10.28	-0.97	-0.375
10.29	-1.09	-0.375
10.30	-1.21	-0.374
10.31	-1.32	-0.374
10.33	-1.44	-0.374
10.34	-1.56	-0.374
10.35	-1.68	-0.374
10.36	-1.79	-0.374
10.37	-1.91	-0.374
10.38	-2.03	-0.374
10.40	-2.14	-0.373
10.41	-2.26	-0.373
10.42	-2.38	-0.373
10.43	-2.49	-0.373
10.44	-2.61	-0.373
10.45	-2.73	-0.373
10.47	-2.84	-0.373
10.48	-2.96	-0.373
10.49	-3.08	-0.372
10.50	-3.19	-0.372
10.51	-3.31	-0.372
10.52	-3.43	-0.372
10.53	-3.54	-0.372
10.55	-3.66	-0.372
10.56	-3.78	-0.372
10.57	-3.89	-0.372
10.58	-4.01	-0.372
10.59	-4.13	-0.372
10.60	-4.25	-0.371
10.62	-4.36	-0.371
10.63	-4.48	-0.371
10.64	-4.59	-0.371
10.65	-4.71	-0.371
10.66	-4.83	-0.371
10.68	-4.94	-0.371
10.69	-5.06	-0.371
10.70	-5.18	-0.371
10.71	-5.30	-0.370
10.72	-5.41	-0.370
10.73	-5.53	-0.370
10.75	-5.65	-0.370
10.76	-5.76	-0.370
10.77	-5.88	-0.370
10.78	-6.00	-0.370
10.79	-6.11	-0.370
10.80	-6.23	-0.369
10.82	-6.35	-0.369
10.83	-6.46	-0.369
10.84	-6.58	-0.369
10.85	-6.70	-0.369
10.86	-6.81	-0.369
10.87	-6.93	-0.369
10.88	-7.05	-0.369
10.90	-7.17	-0.368
10.91	-7.28	-0.368
10.92	-7.40	-0.368
10.93	-7.52	-0.368
10.94	-7.63	-0.368
10.95	-7.75	-0.368
10.97	-7.87	-0.367
10.98	-7.98	-0.367
10.99	-8.10	-0.367
11.00	-8.22	-0.367
11.01	-8.33	-0.367
11.03	-8.45	-0.367
11.04	-8.57	-0.367
11.05	-8.68	-0.366
11.06	-8.80	-0.366
11.07	-8.92	-0.366
11.08	-9.03	-0.366
11.10	-9.15	-0.366
11.11	-9.27	-0.365
11.12	-9.38	-0.365
11.13	-9.50	-0.365
11.14	-9.62	-0.365
11.15	-9.73	-0.365
11.17	-9.85	-0.364
11.18	-9.97	-0.364
11.19	-10.09	-0.364
11.20	-10.20	-0.364
11.21	-10.32	-0.364
11.22	-10.43	-0.363
11.23	-10.55	-0.363
11.25	-10.67	-0.363
11.26	-10.79	-0.363
11.27	-10.90	-0.362
11.28	-11.02	-0.362
11.29	-11.14	-0.362
11.30	-11.25	-0.361
11.32	-11.37	-0.361
11.33	-11.49	-0.361
11.34	-11.60	-0.361
11.35	-11.72	-0.360
11.36	-11.84	-0.360
11.38	-11.95	-0.359
11.39	-12.07	-0.359
11.40	-12.19	-0.359
11.41	-12.30	-0.358
11.42	-12.42	-0.357
11.43	-12.54	-0.357
11.45	-12.65	-0.357
11.46	-12.77	-0.356
11.47	-12.89	-0.356
11.48	-13.01	-0.356
11.49	-13.12	-0.355
11.50	-13.24	-0.355
11.52	-13.36	-0.354
11.53	-13.47	-0.354
11.54	-13.59	-0.353
11.55	-13.71	-0.353
11.56	-13.82	-0.352
11.57	-13.94	-0.351
11.58	-14.06	-0.351
11.60	-14.17	-0.349
11.61	-14.29	-0.349
11.62	-14.41	-0.349
11.63	-14.52	-0.348
11.64	-14.64	-0.348
11.65	-14.76	-0.347
11.67	-14.87	-0.347
11.68	-14.99	-0.346
11.69	-15.11	-0.345
11.70	-15.23	-0.345
11.71	-15.34	-0.344
11.73	-15.46	-0.344
11.74	-15.58	-0.343
11.75	-15.69	-0.343
11.76	-15.81	-0.342
11.77	-15.93	-0.341
11.78	-16.05	-0.341
11.80	-16.16	-0.340
11.81	-16.28	-0.339
11.82	-16.39	-0.339
11.83	-16.51	-0.338
11.84	-16.63	-0.338
11.85	-16.74	-0.337
11.87	-16.86	-0.335
11.88	-16.98	-0.335
11.89	-17.10	-0.334
11.90	-17.21	-0.334
11.91	-17.33	-0.333
11.92	-17.45	-0.332
11.93	-17.56	-0.332
11.95	-17.68	-0.332
11.96	-17.80	-0.331
11.97	-17.91	-0.330
11.98	-18.03	-0.330
11.99	-18.15	-0.329
12.00	-18.27	-0.328
12.02	-18.38	-0.327
12.03	-18.50	-0.326
12.04	-18.62	-0.326
12.05	-18.73	-0.325
12.06	-18.85	-0.325
12.08	-18.97	-0.323
12.09	-19.08	-0.322
12.10	-19.20	-0.322
12.11	-19.32	-0.322
12.12	-19.43	-0.321
12.13	-19.55	-0.320
12.15	-19.67	-0.320
12.16	-19.79	-0.319
12.17	-19.90	-0.319
12.18	-20.02	-0.318
12.19	-20.14	-0.317
12.20	-20.25	-0.317
12.22	-20.37	-0.316
12.23	-20.49	-0.316
12.24	-20.60	-0.315
12.25	-20.72	-0.314
12.26	-20.84	-0.313
12.27	-20.95	-0.313
12.28	-21.07	-0.312
12.30	-21.19	-0.312
12.31	-21.30	-0.311
12.32	-21.42	-0.310
12.33	-21.54	-0.309
12.34	-21.65	-0.308
12.35	-21.77	-0.308
12.37	-21.89	-0.307
12.38	-22.00	-0.306
12.39	-22.12	-0.306
12.40	-22.24	-0.306
12.41	-22.36	-0.305
12.43	-22.47	-0.304
12.44	-22.59	-0.304
12.45	-22.71	-0.304
12.46	-22.82	-0.303
12.47	-22.94	-0.302
12.48	-23.06	-0.302
12.50	-23.17	-0.301
12.51	-23.29	-0.301
12.52	-23.41	-0.300
12.53	-23.52	-0.300
12.54	-23.64	-0.299
12.55	-23.76	-0.299
12.57	-23.87	-0.299
12.58	-23.99	-0.298
12.59	-24.11	-0.298
12.60	-24.23	-0.297
12.61	-24.34	-0.296
12.62	-24.46	-0.295
12.63	-24.58	-0.295
12.65	-24.69	-0.295
12.66	-24.81	-0.294
12.67	-24.93	-0.294
12.68	-25.04	-0.293
12.69	-25.16	-0.293
12.70	-25.28	-0.292
12.72	-25.39	-0.291
12.73	-25.51	-0.291
12.74	-25.63	-0.290
12.75	-25.74	-0.290
12.76	-25.86	-0.290
12.78	-25.98	-0.289
12.79	-26.10	-0.288
12.80	-26.21	-0.287
12.81	-26.33	-0.287
12.82	-26.44	-0.287
12.83	-26.56	-0.287
12.85	-26.68	-0.286
12.86	-26.79	-0.285
12.87	-26.91	-0.285
12.88	-27.03	-0.285
12.89	-27.15	-0.284
12.90	-27.26	-0.284
12.92	-27.38	-0.284
12.93	-27.50	-0.283
12.94	-27.61	-0.283
12.95	-27.73	-0.283
12.96	-27.84	-0.282
12.97	-27.96	-0.282
12.98	-28.08	-0.282
13.00	-28.20	-0.282
13.01	-28.31	-0.281
13.02	-28.43	-0.281
13.03	-28.55	-0.280
13.04	-28.66	-0.280
13.05	-28.78	-0.280
13.07	-28.90	-0.279
13.08	-29.01	-0.279
13.09	-29.13	-0.279
13.10	-29.25	-0.278
13.11	-29.36	-0.278
13.13	-29.48	-0.278
13.14	-29.60	-0.277
13.15	-29.71	-0.277
13.16	-29.83	-0.277
13.17	-29.95	-0.276
13.18	-30.06	-0.276
13.20	-30.18	-0.275
13.21	-30.30	-0.275
13.22	-30.41	-0.275
13.23	-30.53	-0.274
13.24	-30.65	-0.274
13.25	-30.76	-0.273
13.27	-30.88	-0.273
13.28	-31.00	-0.272
13.29	-31.11	-0.272
13.30	-31.23	-0.272
13.31	-31.35	-0.271
13.32	-31.46	-0.271
13.33	-31.58	-0.271
13.35	-31.70	-0.270
13.36	-31.82	-0.270
13.37	-31.93	-0.270
13.38	-32.05	-0.269
13.39	-32.17	-0.269
13.40	-32.28	-0.269
13.42	-32.40	-0.268
13.43	-32.51	-0.268
13.44	-32.63	-0.268
13.45	-32.75	-0.267
13.46	-32.87	-0.267
13.48	-32.98	-0.267
13.49	-33.10	-0.267
13.50	-33.21	-0.266
13.51	-33.33	-0.266
13.52	-33.45	-0.266
13.53	-33.57	-0.265
13.55	-33.68	-0.265
13.56	-33.80	-0.265
13.57	-33.92	-0.265
13.58	-34.03	-0.264
13.59	-34.15	-0.264
13.60	-34.27	-0.264
13.62	-34.38	-0.263
13.63	-34.50	-0.263
13.64	-34.62	-0.262
13.65	-34.73	-0.262
13.66	-34.85	-0.262
13.67	-34.97	-0.261
13.68	-35.08	-0.261
13.70	-35.20	-0.261
13.71	-35.32	-0.260
13.72	-35.43	-0.260
13.73	-35.55	-0.260
13.74	-35.67	-0.260
13.75	-35.78	-0.259
13.77	-35.90	-0.259
13.78	-36.02	-0.258
13.79	-36.13	-0.258
13.80	-36.25	-0.258
13.81	-36.37	-0.257
13.83	-36.48	-0.257
13.84	-36.60	-0.257
13.85	-36.72	-0.256
13.86	-36.83	-0.256
13.87	-36.95	-0.256
13.88	-37.07	-0.255
13.90	-37.19	-0.255
13.91	-37.30	-0.255
13.92	-37.42	-0.254
13.93	-37.53	-0.254
13.94	-37.65	-0.254
13.95	-37.77	-0.254
13.97	-37.88	-0.253
13.98	-38.00	-0.253
13.99	-38.12	-0.253
14.00	-38.23	-0.253
14.01	-38.35	-0.252
14.02	-38.47	-0.252
14.03	-38.59	-0.252
14.05	-38.70	-0.252
14.06	-38.82	-0.252
14.07	-38.94	-0.251
14.08	-39.05	-0.251
14.09	-39.17	-0.251
14.10	-39.29	-0.250
14.12	-39.40	-0.250
14.13	-39.52	-0.250
14.14	-39.64	-0.250
14.15	-39.75	-0.249
14.16	-39.87	-0.249
14.18	-39.99	-0.248
14.19	-40.10	-0.248
14.20	-40.22	-0.248
14.21	-40.34	-0.247
14.22	-40.45	-0.247
14.23	-40.57	-0.247
14.25	-40.69	-0.247
14.26	-40.80	-0.247
14.27	-40.92	-0.246
14.28	-41.04	-0.246
14.29	-41.15	-0.246
14.30	-41.27	-0.246
14.32	-41.39	-0.246
14.33	-41.50	-0.245
14.34	-41.62	-0.245
14.35	-41.73	-0.245
14.36	-41.85	-0.244
14.37	-41.97	-0.244
14.38	-42.09	-0.244
14.40	-42.20	-0.244
14.41	-42.32	-0.244
14.42	-42.44	-0.244
14.43	-42.55	-0.243
14.44	-42.67	-0.243
14.45	-42.79	-0.243
14.47	-42.90	-0.242
14.48	-43.02	-0.242
14.49	-43.14	-0.242
14.50	-43.25	-0.242
14.51	-43.37	-0.241
14.53	-43.49	-0.241
14.54	-43.60	-0.241
14.55	-43.72	-0.241
14.56	-43.84	-0.241
14.57	-43.95	-0.240
14.58	-44.07	-0.240
14.60	-44.19	-0.240
14.61	-44.30	-0.240
14.62	-44.42	-0.240
14.63	-44.54	-0.239
14.64	-44.65	-0.239
14.65	-44.77	-0.239
14.67	-44.89	-0.239
14.68	-45.00	-0.238
14.69	-45.12	-0.238
14.70	-45.24	-0.238
14.71	-45.35	-0.238
14.72	-45.47	-0.238
14.73	-45.59	-0.237
14.75	-45.70	-0.237
14.76	-45.82	-0.237
14.77	-45.94	-0.237
14.78	-46.05	-0.236
14.79	-46.17	-0.236
14.80	-46.29	-0.236
14.82	-46.40	-0.236
14.83	-46.52	-0.235
14.84	-46.64	-0.235
14.85	-46.75	-0.235
14.86	-46.87	-0.235
14.88	-46.99	-0.234
14.89	-47.10	-0.234
14.90	-47.22	-0.234
14.91	-47.34	-0.234
14.92	-47.45	-0.233
14.93	-47.57	-0.233
14.95	-47.69	-0.233
14.96	-47.80
14.97	-47.92
14.98	-48.04
14.99	-48.15
15.00

[step]
Ramp 10.00 °C/min to 100.00 °C
Time	Temperature	Heat Flow (Normalized)
min	°C	W/g
16.00	-49.89	-0.005
16.02	-49.89	-0.005
16.03	-49.89	-0.005
16.03	-49.89	-0.005
16.05	-49.89	-0.004
16.05	-49.88	-0.004
16.07	-49.88	-0.003
16.08	-49.86	0.001
16.08	-49.85	0.007
16.10	-49.83	0.014
16.10	-49.80	0.024
16.12	-49.77	0.032
16.13	-49.73	0.041
16.13	-49.69	0.051
16.15	-49.64	0.059
16.15	-49.59	0.069
16.17	-49.53	0.079
16.18	-49.47	0.091
16.18	-49.40	0.099
16.20	-49.34	0.109
16.20	-49.26	0.118
16.22	-49.19	0.126
16.23	-49.11	0.134
16.23	-49.03	0.142
16.25	-48.95	0.149
16.25	-48.87	0.155
16.27	-48.78	0.161
16.28	-48.70	0.166
16.28	-48.61	0.170
16.30	-48.53	0.174
16.30	-48.44	0.179
16.32	-48.35	0.183
16.33	-48.26	0.186
16.33	-48.17	0.189
16.35	-48.08	0.190
16.35	-47.99	0.195
16.37	-47.90	0.197
16.38	-47.80	0.198
16.38	-47.71	0.200
16.40	-47.62	0.201
16.40	-47.52	0.203
16.42	-47.43	0.205
16.43	-47.33	0.207
16.43	-47.24	0.208
16.45	-47.14	0.208
16.45	-47.05	0.210
16.47	-46.95	0.211
16.48	-46.86	0.212
16.48	-46.76	0.212
16.50	-46.66	0.213
16.50	-46.57	0.214
16.52	-46.47	0.214
16.53	-46.38	0.215
16.53	-46.28	0.216
16.55	-46.18	0.217
16.55	-46.08	0.217
16.57	-45.99	0.217
16.58	-45.89	0.218
16.58	-45.79	0.218
16.60	-45.69	0.219
16.60	-45.60	0.219
16.62	-45.50	0.219
16.63	-45.40	0.219
16.63	-45.30	0.220
16.65	-45.21	0.220
16.65	-45.11	0.220
16.67	-45.01	0.220
16.68	-44.91	0.221
16.68	-44.81	0.221
16.70	-44.71	0.221
16.70	-44.62	0.221
16.72	-44.52	0.221
16.73	-44.42	0.222
16.73	-44.32	0.222
16.75	-44.22	0.222
16.75	-44.12	0.222
16.77	-44.02	0.223
16.78	-43.93	0.223
16.78	-43.83	0.223
16.80	-43.73	0.223
16.80	-43.63	0.223
16.82	-43.53	0.223
16.83	-43.43	0.224
16.83	-43.33	0.224
16.85	-43.23	0.224
16.85	-43.13	0.224
16.87	-43.04	0.224
16.88	-42.94	0.224
16.88	-42.84	0.225
16.90	-42.74	0.225
16.90	-42.64	0.225
16.92	-42.54	0.225
16.93	-42.44	0.225
16.93	-42.34	0.225
16.95	-42.24	0.225
16.95	-42.14	0.226
16.97	-42.04	0.226
16.98	-41.95	0.226
16.98	-41.85	0.226
17.00	-41.75	0.226
17.00	-41.65	0.226
17.02	-41.55	0.226
17.03	-41.45	0.226
17.03	-41.35	0.227
17.05	-41.25	0.227
17.05	-41.15	0.227
17.07	-41.05	0.227
17.08	-40.95	0.227
17.08	-40.85	0.227
17.09	-40.75	0.227
17.11	-40.65	0.227
17.12	-40.55	0.228
17.13	-40.45	0.228
17.13	-40.35	0.228
17.14	-40.25	0.228
17.16	-40.15	0.228
17.17	-40.06	0.228
17.18	-39.95	0.228
17.18	-39.86	0.228
17.19	-39.76	0.228
17.21	-39.66	0.229
17.22	-39.56	0.229
17.23	-39.46	0.229
17.23	-39.36	0.229
17.24	-39.26	0.229
17.26	-39.16	0.229
17.27	-39.06	0.229
17.28	-38.96	0.229
17.28	-38.86	0.229
17.29	-38.76	0.230
17.31	-38.66	0.230
17.32	-38.56	0.230
17.33	-38.46	0.230
17.33	-38.36	0.230
17.34	-38.26	0.230
17.36	-38.16	0.230
17.37	-38.06	0.230
17.38	-37.96	0.230
17.38	-37.86	0.230
17.39	-37.76	0.230
17.41	-37.66	0.231
17.42	-37.56	0.231
17.43	-37.46	0.231
17.43	-37.36	0.231
17.44	-37.26	0.231
17.46	-37.16	0.231
17.47	-37.06	0.231
17.48	-36.96	0.231
17.48	-36.86	0.231
17.49	-36.76	0.232
17.51	-36.66	0.232
17.52	-36.56	0.232
17.53	-36.46	0.232
17.53	-36.36	0.232
17.54	-36.26	0.232
17.56	-36.16	0.232
17.57	-36.06	0.232
17.58	-35.96	0.232
17.58	-35.86	0.232
17.59	-35.76	0.233
17.61	-35.66	0.233
17.62	-35.57	0.233
17.63	-35.46	0.233
17.63	-35.36	0.233
17.64	-35.26	0.233
17.66	-35.17	0.233
17.67	-35.07	0.233
17.68	-34.96	0.233
17.68	-34.86	0.234
17.69	-34.77	0.234
17.71	-34.66	0.234
17.72	-34.57	0.234
17.73	-34.47	0.234
17.73	-34.36	0.234
17.74	-34.27	0.234
17.76	-34.16	0.234
17.77	-34.07	0.234
17.78	-33.97	0.234
17.78	-33.86	0.235
17.79	-33.76	0.235
17.81	-33.67	0.235
17.82	-33.56	0.235
17.83	-33.46	0.235
17.83	-33.36	0.235
17.84	-33.26	0.235
17.86	-33.16	0.235
17.87	-33.06	0.235
17.88	-32.97	0.236
17.88	-32.86	0.236
17.89	-32.76	0.236
17.91	-32.66	0.236
17.92	-32.56	0.236
17.93	-32.46	0.236
17.93	-32.36	0.236
[...]
2134.16	-18.44	0.257
2134.17	-18.33	0.257
2134.18	-18.21	0.258
2134.19	-18.09	0.258
2134.20	-17.98	0.258
2134.22	-17.86	0.259
2134.23	-17.74	0.259
2134.24	-17.63	0.259
2134.25	-17.51	0.260
2134.26	-17.39	0.261
2134.28	-17.28	0.261
2134.29	-17.16	0.262
2134.30	-17.04	0.262
2134.31	-16.93	0.263
2134.32	-16.81	0.263
2134.33	-16.69	0.264
2134.35	-16.58	0.264
2134.36	-16.46	0.265
2134.37	-16.34	0.265
2134.38	-16.23	0.266
2134.39	-16.11	0.267
2134.40	-15.99	0.268
2134.41	-15.88	0.268
2134.43	-15.76	0.269
2134.44	-15.64	0.270
2134.45	-15.53	0.271
2134.46	-15.41	0.273
2134.47	-15.29	0.273
2134.49	-15.18	0.274
2134.50	-15.06	0.276
2134.51	-14.94	0.277
2134.52	-14.83	0.278
2134.53	-14.71	0.279
2134.54	-14.59	0.282
2134.55	-14.48	0.283
2134.57	-14.36	0.285
2134.58	-14.24	0.286
2134.59	-14.13	0.289
2134.60	-14.01	0.290
2134.61	-13.90	0.293
2134.63	-13.78	0.295
2134.64	-13.66	0.297
2134.65	-13.55	0.300
2134.66	-13.43	0.304
2134.67	-13.31	0.306
2134.68	-13.20	0.310
2134.70	-13.08	0.312
2134.71	-12.97	0.315
2134.72	-12.85	0.319
2134.73	-12.73	0.324
2134.74	-12.62	0.327
2134.75	-12.50	0.332
2134.76	-12.39	0.335
2134.78	-12.27	0.339
2134.79	-12.16	0.347
2134.80	-12.04	0.352
2134.81	-11.92	0.356
2134.82	-11.81	0.363
2134.84	-11.69	0.370
2134.85	-11.58	0.378
2134.86	-11.46	0.386
2134.87	-11.35	0.392
2134.88	-11.23	0.402
2134.89	-11.12	0.412
2134.90	-11.01	0.423
2134.92	-10.89	0.433
2134.93	-10.78	0.444
2134.94	-10.66	0.455
2134.95	-10.55	0.469
2134.96	-10.43	0.480
2134.98	-10.32	0.494
2134.99	-10.21	0.505
2135.00	-10.10	0.519
2135.01	-9.98	0.530
2135.02	-9.87	0.539
2135.03	-9.75	0.544
2135.05	-9.64	0.551
2135.06	-9.53	0.551
2135.07	-9.41	0.549
2135.08	-9.30	0.541
2135.09	-9.18	0.530
2135.10	-9.06	0.512
2135.11	-8.94	0.497
2135.13	-8.83	0.477
2135.14	-8.71	0.459
2135.15	-8.59	0.440
2135.16	-8.47	0.425
2135.17	-8.34	0.408
2135.19	-8.22	0.394
2135.20	-8.10	0.384
2135.21	-7.98	0.376
2135.22	-7.86	0.369
2135.23	-7.74	0.363
2135.24	-7.62	0.356
2135.25	-7.50	0.354
2135.27	-7.38	0.351
2135.28	-7.27	0.349
2135.29	-7.15	0.346
2135.30	-7.03	0.343
2135.31	-6.91	0.341
2135.33	-6.79	0.339
2135.34	-6.67	0.338
2135.35	-6.55	0.337
2135.36	-6.44	0.335
2135.37	-6.32	0.335
2135.38	-6.20	0.334
2135.40	-6.08	0.333
2135.41	-5.97	0.333
2135.42	-5.85	0.332
2135.43	-5.73	0.332
2135.44	-5.61	0.331
2135.45	-5.50	0.331
2135.46	-5.38	0.330
2135.48	-5.26	0.329
2135.49	-5.14	0.329
2135.50	-5.03	0.329
2135.51	-4.91	0.329
2135.52	-4.79	0.328
2135.54	-4.68	0.328
2135.55	-4.56	0.328
2135.56	-4.44	0.328
2135.57	-4.33	0.328
2135.58	-4.21	0.327
2135.59	-4.09	0.327
2135.60	-3.98	0.327
2135.62	-3.86	0.327
2135.63	-3.74	0.327
2135.64	-3.62	0.327
2135.65	-3.51	0.326
2135.66	-3.39	0.326
2135.68	-3.27	0.326
2135.69	-3.16	0.326
2135.70	-3.04	0.326
2135.71	-2.92	0.326
2135.72	-2.81	0.326
2135.73	-2.69	0.326
2135.75	-2.58	0.326
2135.76	-2.46	0.323
2135.77	-2.34	0.321
2135.78	-2.23	0.321
2135.79	-2.11	0.321
2135.80	-1.99	0.321
2135.81	-1.87	0.322
2135.83	-1.76	0.322
2135.84	-1.64	0.322
2135.85	-1.52	0.323
2135.86	-1.40	0.323
2135.87	-1.29	0.323
2135.89	-1.17	0.323
2135.90	-1.05	0.323
2135.91	-0.94	0.323
2135.92	-0.82	0.323
2135.93	-0.70	0.323
2135.94	-0.58	0.323
2135.95	-0.47	0.323
2135.97	-0.35	0.323
2135.98	-0.23	0.324
2135.99	-0.12	0.324
2136.00	0.00	0.324
2136.01	0.12	0.324
2136.03	0.23	0.324
2136.04	0.35	0.324
2136.05	0.47	0.324
2136.06	0.58	0.324
2136.07	0.70	0.324
2136.08	0.82	0.324
2136.10	0.93	0.324
2136.11	1.05	0.324
2136.12	1.17	0.324
2136.13	1.28	0.324
2136.14	1.40	0.324
2136.15	1.52	0.324
2136.16	1.63	0.324
2136.18	1.75	0.324
2136.19	1.87	0.324
2136.20	1.99	0.324
2136.21	2.10	0.325
2136.22	2.22	0.325
2136.24	2.34	0.325
2136.25	2.45	0.325
2136.26	2.57	0.325
2136.27	2.68	0.325
2136.28	2.80	0.325
2136.29	2.92	0.325
2136.30	3.04	0.325
2136.32	3.15	0.325
2136.33	3.27	0.325
2136.34	3.39	0.325
2136.35	3.50	0.325
2136.36	3.62	0.326
2136.38	3.74	0.326
2136.39	3.85	0.326
2136.40	3.97	0.326
2136.41	4.09	0.326
2136.42	4.20	0.326
2136.43	4.32	0.326
2136.45	4.44	0.326
2136.46	4.55	0.326
2136.47	4.67	0.326
2136.48	4.79	0.326
2136.49	4.90	0.326
2136.50	5.02	0.326
2136.51	5.14	0.327
2136.53	5.25	0.327
2136.54	5.37	0.327
2136.55	5.49	0.327
2136.56	5.61	0.327
2136.57	5.72	0.327
2136.59	5.84	0.327
2136.60	5.95	0.327
2136.61	6.07	0.327
2136.62	6.19	0.327
2136.63	6.31	0.327
2136.64	6.42	0.327
2136.65	6.54	0.328
2136.67	6.66	0.328
2136.68	6.77	0.328
2136.69	6.89	0.328
2136.70	7.01	0.328
2136.71	7.12	0.328
2136.73	7.24	0.328
2136.74	7.36	0.328
2136.75	7.47	0.328
2136.76	7.59	0.328
2136.77	7.71	0.328
2136.78	7.82	0.328
2136.80	7.94	0.328
2136.81	8.06	0.329
2136.82	8.18	0.329
2136.83	8.29	0.329
2136.84	8.41	0.329
2136.85	8.53	0.329
2136.86	8.64	0.329
2136.88	8.76	0.329
2136.89	8.88	0.329
2136.90	8.99	0.329
2136.91	9.11	0.329
2136.92	9.23	0.329
2136.94	9.34	0.329
2136.95	9.46	0.329
2136.96	9.58	0.330
2136.97	9.69	0.330
2136.98	9.81	0.330
2136.99	9.93	0.330
2137.00	10.04	0.330
2137.02	10.16	0.330
2137.03	10.28	0.330
2137.04	10.39	0.330
2137.05	10.51	0.330
2137.06	10.63	0.330
2137.08	10.75	0.330
2137.09	10.86	0.331
2137.10	10.98	0.331
2137.11	11.10	0.331
2137.12	11.21	0.331
2137.13	11.33	0.331
2137.15	11.45	0.331
2137.16	11.56	0.331
2137.17	11.68	0.331
2137.18	11.80	0.331
2137.19	11.91	0.331
2137.20	12.03	0.331
2137.21	12.15	0.331
2137.23	12.26	0.331
2137.24	12.38	0.331
2137.25	12.50	0.332
2137.26	12.62	0.332
2137.27	12.73	0.332
2137.29	12.85	0.332
2137.30	12.96	0.332
2137.31	13.08	0.332
2137.32	13.20	0.332
2137.33	13.32	0.332
2137.34	13.43	0.332
2137.35	13.55	0.332
2137.37	13.67	0.332
2137.38	13.78	0.332
2137.39	13.90	0.332
2137.40	14.02	0.332
2137.41	14.13	0.332
2137.43	14.25	0.333
2137.44	14.37	0.333
2137.45	14.48	0.333
2137.46	14.60	0.333
2137.47	14.72	0.333
2137.48	14.83	0.333
2137.50	14.95	0.333
2137.51	15.07	0.333
2137.52	15.19	0.334
2137.53	15.30	0.334
2137.54	15.42	0.334
2137.55	15.54	0.334
2137.56	15.65	0.334
2137.58	15.77	0.334
2137.59	15.89	0.334
2137.60	16.00	0.334
2137.61	16.12	0.334
2137.62	16.24	0.334
2137.64	16.35	0.334
2137.65	16.47	0.334
2137.66	16.59	0.335
2137.67	16.70	0.335
2137.68	16.82	0.335
2137.69	16.94	0.335
2137.70	17.05	0.335
2137.72	17.17	0.335
2137.73	17.29	0.335
2137.74	17.40	0.335
2137.75	17.52	0.335
2137.76	17.64	0.335
2137.78	17.75	0.335
2137.79	17.87	0.335
2137.80	17.99	0.335
2137.81	18.11	0.336
2137.82	18.22	0.336
2137.83	18.34	0.336
2137.85	18.46	0.336
2137.86	18.57	0.336
2137.87	18.69	0.336
2137.88	18.81	0.336
2137.89	18.92	0.336
2137.90	19.04	0.336
2137.91	19.16	0.336
2137.93	19.27	0.336
2137.94	19.39	0.336
2137.95	19.51	0.337
2137.96	19.62	0.337
2137.97	19.74	0.337
2137.99	19.86	0.337
2138.00	19.97	0.338
2138.01	20.09	0.338
2138.02	20.21	0.338
2138.03	20.32	0.338
2138.04	20.44	0.338
2138.05	20.56	0.338
2138.07	20.68	0.338
2138.08	20.79	0.338
2138.09	20.91	0.338
2138.10	21.03	0.338
2138.11	21.14	0.338
2138.13	21.26	0.338
2138.14	21.37	0.338
2138.15	21.49	0.338
2138.16	21.61	0.338
2138.17	21.72	0.339
2138.18	21.84	0.339
2138.20	21.96	0.339
2138.21	22.08	0.339
2138.22	22.19	0.339
2138.23	22.31	0.339
2138.24	22.43	0.339
2138.25	22.54	0.339
2138.26	22.66	0.339
2138.28	22.78	0.339
2138.29	22.89	0.340
2138.30	23.01	0.340
2138.31	23.13	0.340
2138.32	23.24	0.340
2138.34	23.36	0.340
2138.35	23.48	0.340
2138.36	23.59	0.340
2138.37	23.71	0.340
2138.38	23.83	0.340
2138.39	23.94	0.340
2138.40	24.06	0.340
2138.42	24.18	0.341
2138.43	24.30	0.341
2138.44	24.41	0.341
2138.45	24.53	0.341
2138.46	24.65	0.341
2138.48	24.76	0.341
2138.49	24.88	0.341
2138.50	25.00	0.341
2138.51	25.11	0.341
2138.52	25.23	0.341
2138.53	25.35	0.341
2138.55	25.46	0.342
2138.56	25.58	0.342
2138.57	25.70	0.342
2138.58	25.81	0.342
2138.59	25.93	0.342
2138.60	26.05	0.342
2138.61	26.16	0.342
2138.63	26.28	0.342
2138.64	26.40	0.342
2138.65	26.51	0.342
2138.66	26.63	0.342
2138.67	26.75	0.343
2138.69	26.86	0.343
2138.70	26.98	0.343
2138.71	27.10	0.343
2138.72	27.22	0.343
2138.73	27.33	0.343
2138.74	27.45	0.343
2138.75	27.57	0.343
2138.77	27.68	0.343
2138.78	27.80	0.343
2138.79	27.92	0.343
2138.80	28.03	0.344
2138.81	28.15	0.344
2138.83	28.27	0.344
2138.84	28.38	0.344
2138.85	28.50	0.344
2138.86	28.62	0.344
2138.87	28.73	0.344
2138.88	28.85	0.344
2138.90	28.97	0.344
2138.91	29.08	0.344
2138.92	29.20	0.344
2138.93	29.32	0.345
2138.94	29.44	0.345
2138.95	29.55	0.345
2138.96	29.67	0.345
2138.98	29.79	0.345
2138.99	29.90	0.345
2139.00	30.02	0.345
2139.01	30.14	0.345
2139.02	30.25	0.345
2139.04	30.37	0.346
2139.05	30.49	0.346
2139.06	30.60	0.346
2139.07	30.72	0.346
2139.08	30.84	0.346
2139.09	30.95	0.346
2139.10	31.07	0.346
2139.12	31.19	0.346
2139.13	31.30	0.346
2139.14	31.42	0.346
2139.15	31.54	0.347
2139.16	31.66	0.347
2139.18	31.77	0.347
2139.19	31.89	0.347
2139.20	32.01	0.347
2139.21	32.12	0.347
2139.22	32.24	0.347
2139.23	32.36	0.347
2139.25	32.47	0.347
2139.26	32.59	0.347
2139.27	32.71	0.347
2139.28	32.82	0.347
2139.29	32.94	0.347
2139.30	33.06	0.348
2139.31	33.17	0.348
2139.33	33.29	0.348
2139.34	33.41	0.348
2139.35	33.52	0.348
2139.36	33.64	0.348
2139.37	33.76	0.348
2139.39	33.87	0.348
2139.40	33.99	0.348
2139.41	34.11	0.348
2139.42	34.22	0.349
2139.43	34.34	0.349
2139.44	34.46	0.349
2139.45	34.58	0.349
2139.47	34.69	0.349
2139.48	34.81	0.349
2139.49	34.93	0.349
2139.50	35.04	0.349
2139.51	35.16	0.349
2139.53	35.28	0.349
2139.54	35.39	0.349
2139.55	35.51	0.349
2139.56	35.63	0.349
2139.57	35.74	0.350
2139.58	35.86	0.350
2139.60	35.98	0.350
2139.61	36.09	0.350
2139.62	36.21	0.350
2139.63	36.33	0.350
2139.64	36.44	0.350
2139.65	36.56	0.350
2139.66	36.68	0.350
2139.68	36.79	0.350
2139.69	36.91	0.350
2139.70	37.03	0.351
2139.71	37.14	0.351
2139.72	37.26	0.351
2139.74	37.38	0.351
2139.75	37.50	0.351
2139.76	37.61	0.351
2139.77	37.73	0.351
2139.78	37.85	0.351
2139.79	37.96	0.351
2139.80	38.08	0.351
2139.82	38.20	0.351
2139.83	38.31	0.351
2139.84	38.43	0.351
2139.85	38.55	0.351
2139.86	38.66	0.352
2139.88	38.78	0.352
2139.89	38.90	0.352
2139.90	39.01	0.352
2139.91	39.13	0.352
2139.92	39.25	0.352
2139.93	39.37	0.352
2139.95	39.48	0.352
2139.96	39.60	0.352
2139.97	39.72	0.352
2139.98	39.83	0.352
2139.99	39.95	0.353
2140.00	40.07	0.353
2140.01	40.18	0.353
2140.03	40.30	0.353
2140.04	40.42	0.353
2140.05	40.53	0.353
2140.06	40.65	0.353
2140.07	40.77	0.353
2140.09	40.88	0.353
2140.10	41.00	0.353
2140.11	41.12	0.353
2140.12	41.23	0.354
2140.13	41.35	0.354
2140.14	41.47	0.354
2140.15	41.58	0.354
2140.17	41.70	0.354
2140.18	41.82	0.354
2140.19	41.93	0.354
2140.20	42.05	0.354
2140.21	42.17	0.354
2140.23	42.29	0.354
2140.24	42.40	0.354
2140.25	42.52	0.354
2140.26	42.64	0.355
2140.27	42.75	0.355
2140.28	42.87	0.355
2140.30	42.99	0.355
2140.31	43.10	0.355
2140.32	43.22	0.355
2140.33	43.34	0.355
2140.34	43.45	0.355
2140.35	43.57	0.355
2140.36	43.69	0.355
2140.38	43.80	0.355
2140.39	43.92	0.355
2140.40	44.04	0.356
2140.41	44.15	0.356
2140.42	44.27	0.356
2140.44	44.39	0.356
2140.45	44.50	0.356
2140.46	44.62	0.356
2140.47	44.74	0.356
2140.48	44.86	0.356
2140.49	44.97	0.356
2140.50	45.09	0.356
2140.52	45.21	0.356
2140.53	45.32	0.357
2140.54	45.44	0.357
2140.55	45.55	0.357
2140.56	45.67	0.357
2140.58	45.79	0.357
2140.59	45.91	0.357
2140.60	46.02	0.357
2140.61	46.14	0.357
2140.62	46.26	0.357
2140.63	46.37	0.358
2140.65	46.49	0.358
2140.66	46.61	0.358
2140.67	46.72	0.358
2140.68	46.84	0.358
2140.69	46.96	0.358
2140.70	47.07	0.358
2140.71	47.19	0.358
2140.73	47.31	0.358
2140.74	47.42	0.358
2140.75	47.54	0.358
2140.76	47.66	0.358
2140.77	47.77	0.359
2140.79	47.89	0.359
2140.80	48.01	0.359
2140.81	48.12	0.359
2140.82	48.24	0.359
2140.83	48.36	0.359
2140.84	48.48	0.359
2140.85	48.59	0.359
2140.87	48.71	0.359
2140.88	48.83	0.359
2140.89	48.94	0.360
2140.90	49.06	0.360
2140.91	49.18	0.360
2140.93	49.29	0.360
2140.94	49.41	0.360
2140.95	49.53	0.360
2140.96	49.64	0.360
2140.97	49.76	0.360
2140.98	49.88	0.360
2141.00	49.99	0.360
2141.01	50.11	0.360
2141.02	50.23	0.360
2141.03	50.35	0.361
2141.04	50.46	0.361
2141.05	50.58	0.361
2141.06	50.69	0.361
2141.08	50.81	0.361
2141.09	50.93	0.361
2141.10	51.05	0.361
2141.11	51.16	0.361
2141.12	51.28	0.361
2141.14	51.40	0.361
2141.15	51.51	0.361
2141.16	51.63	0.361
2141.17	51.75	0.362
2141.18	51.86	0.362
2141.19	51.98	0.362
2141.20	52.10	0.362
2141.22	52.21	0.362
2141.23	52.33	0.362
2141.24	52.45	0.362
2141.25	52.56	0.362
2141.26	52.68	0.362
2141.28	52.80	0.362
2141.29	52.91	0.362
2141.30	53.03	0.362
2141.31	53.15	0.363
2141.32	53.26	0.363
2141.33	53.38	0.363
2141.35	53.50	0.363
2141.36	53.62	0.363
2141.37	53.73	0.363
2141.38	53.85	0.363
2141.39	53.97	0.363
2141.40	54.08	0.363
2141.41	54.20	0.363
2141.43	54.32	0.363
2141.44	54.43	0.363
2141.45	54.55	0.363
2141.46	54.67	0.364
2141.47	54.78	0.364
2141.49	54.90	0.364
2141.50	55.02	0.364
2141.51	55.13	0.364
2141.52	55.25	0.364
2141.53	55.37	0.364
2141.54	55.48	0.364
2141.55	55.60	0.364
2141.57	55.72	0.364
2141.58	55.84	0.364
2141.59	55.95	0.364
2141.60	56.07	0.364
2141.61	56.19	0.365
2141.63	56.30	0.365
2141.64	56.42	0.365
2141.65	56.54	0.365
2141.66	56.65	0.365
2141.67	56.77	0.365
2141.68	56.89	0.365
2141.70	57.00	0.365
2141.71	57.12	0.365
2141.72	57.24	0.365
2141.73	57.35	0.365
2141.74	57.47	0.365
2141.75	57.59	0.365
2141.76	57.70	0.366
2141.78	57.82	0.366
2141.79	57.94	0.366
2141.80	58.05	0.366
2141.81	58.17	0.366
2141.82	58.29	0.366
2141.84	58.40	0.366
2141.85	58.52	0.366
2141.86	58.64	0.366
2141.87	58.75	0.366
2141.88	58.87	0.366
2141.89	58.99	0.366
2141.90	59.10	0.366
2141.92	59.22	0.366
2141.93	59.34	0.367
2141.94	59.46	0.367
2141.95	59.57	0.367
2141.96	59.69	0.367
2141.98	59.81	0.367
2141.99	59.92	0.367
2142.00	60.04	0.367
2142.01	60.16	0.367
2142.02	60.27	0.367
2142.03	60.39	0.367
2142.05	60.51	0.367
2142.06	60.62	0.368
2142.07	60.74	0.368
2142.08	60.86	0.368
2142.09	60.97	0.368
2142.10	61.09	0.368
2142.11	61.21	0.368
2142.13	61.32	0.368
2142.14	61.44	0.368
2142.15	61.56	0.368
2142.16	61.67	0.368
2142.17	61.79	0.368
2142.19	61.91	0.368
2142.20	62.03	0.368
2142.21	62.14	0.368
2142.22	62.26	0.369
2142.23	62.38	0.369
2142.24	62.49	0.369
2142.25	62.61	0.369
2142.27	62.73	0.369
2142.28	62.84	0.369
2142.29	62.96	0.369
2142.30	63.08	0.369
2142.31	63.19	0.369
2142.33	63.31	0.369
2142.34	63.43	0.369
2142.35	63.54	0.369
2142.36	63.66	0.369
2142.37	63.78	0.370
2142.38	63.89	0.370
2142.40	64.01	0.370
2142.41	64.13	0.370
2142.42	64.24	0.370
2142.43	64.36	0.370
2142.44	64.48	0.370
2142.45	64.59	0.370
2142.46	64.71	0.370
2142.48	64.83	0.370
2142.49	64.94	0.370
2142.50	65.06	0.370
2142.51	65.18	0.370
2142.52	65.29	0.371
2142.54	65.41	0.371
2142.55	65.53	0.371
2142.56	65.65	0.371
2142.57	65.76	0.371
2142.58	65.88	0.371
2142.59	66.00	0.371
2142.60	66.11	0.371
2142.62	66.23	0.371
2142.63	66.35	0.371
2142.64	66.46	0.371
2142.65	66.58	0.371
2142.66	66.70	0.371
2142.68	66.81	0.371
2142.69	66.93	0.372
2142.70	67.05	0.372
2142.71	67.16	0.372
2142.72	67.28	0.372
2142.73	67.40	0.372
2142.75	67.51	0.372
2142.76	67.63	0.372
2142.77	67.75	0.372
2142.78	67.86	0.372
2142.79	67.98	0.372
2142.80	68.10	0.372
2142.81	68.22	0.372
2142.83	68.33	0.372
2142.84	68.45	0.373
2142.85	68.57	0.373
2142.86	68.68	0.373
2142.87	68.80	0.373
2142.89	68.92	0.373
2142.90	69.03	0.373
2142.91	69.15	0.373
2142.92	69.27	0.373
2142.93	69.38	0.373
2142.94	69.50	0.373
2142.95	69.62	0.373
2142.97	69.73	0.373
2142.98	69.85	0.374
2142.99	69.97	0.374
2143.00	70.08	0.374
2143.01	70.20	0.374
2143.03	70.32	0.374
2143.04	70.43	0.374
2143.05	70.55	0.374
2143.06	70.67	0.374
2143.07	70.78	0.374
2143.08	70.90	0.374
2143.10	71.02	0.374
2143.11	71.13	0.374
2143.12	71.25	0.374
2143.13	71.37	0.374
2143.14	71.49	0.374
2143.15	71.60	0.374
2143.16	71.72	0.374
2143.18	71.84	0.374
2143.19	71.95	0.375
2143.20	72.07	0.375
2143.21	72.19	0.375
2143.22	72.30	0.375
2143.24	72.42	0.375
2143.25	72.54	0.375
2143.26	72.65	0.375
2143.27	72.77	0.375
2143.28	72.89	0.375
2143.29	73.00	0.375
2143.30	73.12	0.375
2143.32	73.24	0.376
2143.33	73.35	0.376
2143.34	73.47	0.376
2143.35	73.59	0.376
2143.36	73.71	0.376
2143.38	73.82	0.376
2143.39	73.94	0.376
2143.40	74.05	0.376
2143.41	74.17	0.376
2143.42	74.29	0.376
2143.43	74.41	0.376
2143.45	74.52	0.376
2143.46	74.64	0.377
2143.47	74.76	0.377
2143.48	74.87	0.377
2143.49	74.99	0.377
2143.50	75.11	0.377
2143.51	75.22	0.377
2143.53	75.34	0.377
2143.54	75.46	0.377
2143.55	75.57	0.377
2143.56	75.69	0.377
2143.57	75.81	0.377
2143.59	75.92	0.377
2143.60	76.04	0.377
2143.61	76.16	0.377
2143.62	76.27	0.377
2143.63	76.39	0.378
2143.64	76.51	0.378
2143.65	76.62	0.378
2143.67	76.74	0.378
2143.68	76.86	0.378
2143.69	76.97	0.378
2143.70	77.09	0.378
2143.71	77.21	0.378
2143.73	77.33	0.378
2143.74	77.44	0.378
2143.75	77.56	0.378
2143.76	77.68	0.379
2143.77	77.79	0.379
2143.78	77.91	0.379
2143.80	78.03	0.379
2143.81	78.14	0.379
2143.82	78.26	0.379
2143.83	78.38	0.379
2143.84	78.49	0.379
2143.85	78.61	0.379
2143.86	78.73	0.379
2143.88	78.84	0.379
2143.89	78.96	0.379
2143.90	79.08	0.379
2143.91	79.19	0.379
2143.92	79.31	0.379
2143.94	79.43	0.380
2143.95	79.54	0.380
2143.96	79.66	0.380
2143.97	79.78	0.380
2143.98	79.90	0.380
2143.99	80.01	0.380
2144.00	80.13	0.380
2144.02	80.25	0.380
2144.03	80.36	0.380
2144.04	80.48	0.380
2144.05	80.60	0.380
2144.06	80.71	0.380
2144.08	80.83	0.380
2144.09	80.95	0.380
2144.10	81.06	0.380
2144.11	81.18	0.380
2144.12	81.30	0.381
2144.13	81.41	0.381
2144.15	81.53	0.381
2144.16	81.65	0.381
2144.17	81.76	0.381
2144.18	81.88	0.381
2144.19	82.00	0.381
2144.20	82.11	0.381
2144.21	82.23	0.381
2144.23	82.35	0.381
2144.24	82.46	0.381
2144.25	82.58	0.381
2144.26	82.70	0.381
2144.27	82.81	0.381
2144.29	82.93	0.381
2144.30	83.05	0.381
2144.31	83.16	0.381
2144.32	83.28	0.381
2144.33	83.40	0.381
2144.34	83.51	0.381
2144.35	83.63	0.382
2144.37	83.75	0.382
2144.38	83.86	0.382
2144.39	83.98	0.382
2144.40	84.10	0.382
2144.41	84.22	0.382
2144.43	84.33	0.382
2144.44	84.45	0.382
2144.45	84.57	0.382
2144.46	84.68	0.382
2144.47	84.80	0.382
2144.48	84.92	0.382
2144.50	85.03	0.382
2144.51	85.15	0.382
2144.52	85.27	0.382
2144.53	85.38	0.382
2144.54	85.50	0.382
2144.55	85.62	0.382
2144.56	85.73	0.382
2144.58	85.85	0.383
2144.59	85.97	0.383
2144.60	86.08	0.383
2144.61	86.20	0.383
2144.62	86.32	0.383
2144.64	86.44	0.383
2144.65	86.55	0.383
2144.66	86.67	0.383
2144.67	86.79	0.383
2144.68	86.90	0.383
2144.69	87.02	0.383
2144.70	87.14	0.383
2144.72	87.25	0.383
2144.73	87.37	0.383
2144.74	87.49	0.383
2144.75	87.60	0.383
2144.76	87.72	0.383
2144.78	87.84	0.383
2144.79	87.95	0.383
2144.80	88.07	0.384
2144.81	88.19	0.384
2144.82	88.30	0.384
2144.83	88.42	0.384
2144.85	88.54	0.384
2144.86	88.65	0.384
2144.87	88.77	0.384
2144.88	88.89	0.384
2144.89	89.00	0.384
2144.90	89.12	0.384
2144.91	89.24	0.384
2144.93	89.35	0.384
2144.94	89.47	0.384
2144.95	89.59	0.384
2144.96	89.71	0.384
2144.97	89.82	0.385
2144.99	89.94	0.385
2145.00	90.05	0.385
2145.01	90.17	0.385
2145.02	90.29	0.385
2145.03	90.40	0.385
2145.04	90.52	0.385
2145.05	90.64	0.385
2145.07	90.76	0.385
2145.08	90.87	0.385
2145.09	90.99	0.385
2145.10	91.11	0.386
2145.11	91.22	0.386
2145.13	91.34	0.386
2145.14	91.46	0.386
2145.15	91.57	0.386
2145.16	91.69	0.386
2145.17	91.81	0.386
2145.18	91.92	0.386
2145.20	92.04	0.386
2145.21	92.16	0.386
2145.22	92.27	0.386
2145.23	92.39	0.387
2145.24	92.51	0.387
2145.25	92.63	0.387
2145.26	92.74	0.387
2145.28	92.86	0.387
2145.29	92.98	0.387
2145.30	93.09	0.387
2145.31	93.21	0.387
2145.32	93.33	0.387
2145.34	93.44	0.387
2145.35	93.56	0.388
2145.36	93.68	0.388
2145.37	93.79	0.388
2145.38	93.91	0.388
2145.39	94.03	0.388
2145.40	94.14	0.388
2145.42	94.26	0.388
2145.43	94.38	0.388
2145.44	94.50	0.388
2145.45	94.61	0.388
2145.46	94.73	0.388
2145.48	94.85	0.388
2145.49	94.96	0.389
2145.50	95.08	0.389
2145.51	95.20	0.389
2145.52	95.31	0.389
2145.53	95.43	0.389
2145.55	95.55	0.389
2145.56	95.66	0.389
2145.57	95.78	0.389
2145.58	95.90	0.389
2145.59	96.01	0.389
2145.60	96.13	0.389
2145.61	96.25	0.389
2145.63	96.36	0.389
2145.64	96.48	0.389
2145.65	96.60	0.389
2145.66	96.71	0.390
2145.67	96.83	0.390
2145.69	96.95	0.390
2145.70	97.07	0.390
2145.71	97.18	0.390
2145.72	97.30	0.390
2145.73	97.42	0.390
2145.74	97.53	0.390
2145.75	97.65	0.390
2145.77	97.77	0.390
2145.78	97.88
2145.79	98.00
2145.80	98.12
2145.81	98.23
2145.83	98.35
2145.83