File: DSC/2023_06_14_CBC_Al_herm.txt
Filename	2023_06_14_CBC_Al_herm
Instrument name	DSC2A-00468 (192.168.1.100)
Operator	SBK
rundate	6/14/2023
Sample name	2023_06_14_CBC_Al_herm
proceduresegments	Data Off ; Equilibrate 30.00 °C; Data On ; Ramp 5.00 °C/min to -90.00 °C; Data Off ; Isothermal 1.0 min; Data On ; Ramp 5.00 °C/min to 30.00 °C; Data Off ; Isothermal 1.0 min; Data On ; Ramp 5.00 °C/min to -90.00 °C; Data Off ; Isothermal 1.0 min; Data On ; Ramp 5.00 °C/min to 30.00 °C; Data Off ; Isothermal 1.0 min; Data On ; Ramp 5.00 °C/min to -90.00 °C; Data Off ; Isothermal 1.0 min; Data On ; Ramp 5.00 °C/min to 30.00 °C
[File Parameters]
Run date	6/14/2023 5:35:16 PM
Trios version	5.1.1.46572
Original File Name	C:\Users\yargerlab\Desktop\DSC Data\General\2023_06_14_CBC_Al_herm.tri
Current File Name	C:\Users\yargerlab\Desktop\DSC Data\General\2023_06_14_CBC_Al_herm.tri
[Procedure]
Procedure Name	DSC -90C to 30C at 5 C/min 3 cycles
Sample Name	2023_06_14_CBC_Al_herm
Sample Mass	10.78 mg
Reference Sample Mass	0 mg
Pan Mass	54.21 mg
Pan Number	51
Reference Pan Mass	53.66 mg
Reference Pan Number	46
Pan Type	Aluminum Hermetic
Comments	CBC liquid. New vial. DSC84010 aluminum pan and DSC84011 hermetic aluminum lid.
Project Name	SIlk ASDs
Operator	SBK
Test	Custom
Unload Max Temperature	30
Unload Min Temperature	30
Load Max Temperature	30
Load Min Temperature	30
Stop on Gas Flow Error	Yes
[Signal List]
Signal #1	Time (min)
Signal #2	Temperature (°C)
Signal #3	Heat Flow (mW)
Signal #4	Delta T (µV)
Signal #5	Delta Tzero (µV)
Signal #6	Tzero Temperature (°C)
Signal #7	Cell Purge (mL/min)
Signal #8	Heater Temp (°C)
Signal #9	Power Delivered (W)
Signal #10	Reference Junction Temperature (°C)
Signal #11	Flange Temperature (°C)
Signal #12	Heat Flow Phase (rad)
Signal #13	Total Heat Capacity (J/°C)
Signal #14	Heat Capacity (J/°C)
[Configuration]
Company Name	ASU
Instrument Name	DSC2A-00468
Instrument Type	DSC2500
Serial Number	DSC2A-00468
IP	192.168.1.100
Location of Instrument	MRRC
DisplayType	Unknown
Sample Interval 	0.1 s/pt
Selected Heat Flow	T4P
Exotherm Direction	Down
Cell Serial	DRC2-00792
Lid Type	Standard
Cooler	RCS 90
Leave Cooler on at End of Sequence	On
Gas 2	Nitrogen
Gas Selected	Channel 1
Flow Rate	50 mL/min
Secondary Purge	On
Licensed Heat Flow	Heat Flow T4P
Modulation Licensed	Yes
[Versions]
Common IDD Version	1
Cortex Version	VER 2.10.2.31
Driver	5.0.0.6
GDM Version	1.0.3.3
TouchscreenVersion	1.0.0.16145
FEP Version	1.2.1.21
FEP Bootloader	2.0.0.5
AutoSampler Version	2.1.1.26
Auto Sampler Bootloader	2.0.0.5
FCM Version	1.1.0.3
FCM Bootloader	2.0.0.5
[Experiment Logs]
Experiment Log Entry # 1	Data On set to 0
Experiment Log Entry # 3	Equilibrate Segment 30 (C) Started
Experiment Log Entry # 5	Air Cool is off.
Experiment Log Entry # 7	Data On set to 1
Experiment Log Entry # 9	Ramp Segment 5 C/min to -90 Started
Experiment Log Entry # 11	Data On set to 0
Experiment Log Entry # 13	Isothermal Segment 1 min started
Experiment Log Entry # 15	Data On set to 1
Experiment Log Entry # 17	Ramp Segment 5 C/min to 30 Started
Experiment Log Entry # 19	Data On set to 0
Experiment Log Entry # 21	Isothermal Segment 1 min started
Experiment Log Entry # 23	Data On set to 1
Experiment Log Entry # 25	Ramp Segment 5 C/min to -90 Started
Experiment Log Entry # 27	Data On set to 0
Experiment Log Entry # 29	Isothermal Segment 1 min started
Experiment Log Entry # 31	Data On set to 1
Experiment Log Entry # 33	Ramp Segment 5 C/min to 30 Started
Experiment Log Entry # 35	Data On set to 0
Experiment Log Entry # 37	Isothermal Segment 1 min started
Experiment Log Entry # 39	Data On set to 1
Experiment Log Entry # 41	Ramp Segment 5 C/min to -90 Started
Experiment Log Entry # 43	Data On set to 0
Experiment Log Entry # 45	Isothermal Segment 1 min started
Experiment Log Entry # 47	Data On set to 1
Experiment Log Entry # 49	Ramp Segment 5 C/min to 30 Started
[Method Log]
Method Log Entry # 1	Data Off
Method Log Entry # 2	Equilibrate 30 °C
Method Log Entry # 3	Data On
Method Log Entry # 4	(Ramp 96028) Ramp 5 °C/minute to -90 °C
Method Log Entry # 5	Data Off
Method Log Entry # 6	Isothermal 1 minutes
Method Log Entry # 7	Data On
Method Log Entry # 8	(Ramp 96032) Ramp 5 °C/minute to 30 °C
Method Log Entry # 9	Data Off
Method Log Entry # 10	Isothermal 1 minutes
Method Log Entry # 11	Data On
Method Log Entry # 12	(Ramp 96036) Ramp 5 °C/minute to -90 °C
Method Log Entry # 13	Data Off
Method Log Entry # 14	Isothermal 1 minutes
Method Log Entry # 15	Data On
Method Log Entry # 16	(Ramp 96040) Ramp 5 °C/minute to 30 °C
Method Log Entry # 17	Data Off
Method Log Entry # 18	Isothermal 1 minutes
Method Log Entry # 19	Data On
Method Log Entry # 20	(Ramp 96044) Ramp 5 °C/minute to -90 °C
Method Log Entry # 21	Data Off
Method Log Entry # 22	Isothermal 1 minutes
Method Log Entry # 23	Data On
Method Log Entry # 24	(Ramp 96048) Ramp 5 °C/minute to 30 °C
Cell Serial	DRC2-00792
[T1 Calibration]
Slope	-0.008529666
Offset	9.636258
Initial Temperature	98.23
GUID	f8bfdadc-4977-4fdf-ba6d-0ba9134940c3
[TZero Calibration]
Date Applied	11/29/2022 4:06:13 PM
Description	From -89.059 °C to 396.009 °C at 20.000°C/min
Gas Type	Nitrogen
Pan Type	None
Source Files 1	C:\Users\yargerlab\Desktop\DSC Data\General\TZero_calibration_11_29_22_2nd(2).tri
Source Files 2	C:\Users\yargerlab\Desktop\DSC Data\General\TZero_calibration_11_29_22_2nd(3).tri
Delta T Offset	13.05235
Delta T Slope	-0.007271007
Delta T0 Offset	-13.69128
Delta T0 Slope	0.06063341
[Temperature Calibration]
Date Applied	11/29/2022 7:12:28 PM
Description	From 106.590 °C to 186.590 °C at 10.000°C/min
Gas Type	Nitrogen
Pan Type	Tzero Aluminum Hermetic
Source Files 1	C:\Users\yargerlab\Desktop\DSC Data\General\Indium(6).tri
Measured 1	157.391
Known 1	156.598
[Cell Constant Calibration]
Date Applied	11/29/2022 7:12:29 PM
Description	From 106.590 °C to 186.590 °C at 10.000°C/min
Gas Type	Nitrogen
Pan Type	Tzero Aluminum Hermetic
Source Files 1	C:\Users\yargerlab\Desktop\DSC Data\General\Indium(6).tri
T4P KCell	1.006051
Onset Slope	63.26126 mW/°C
[Direct Cp Calibration]
Date Applied	11/30/2022 11:04:51 AM
Description	From -79.983 °C to 298.409 °C at 10.000°C/min
Gas Type	Nitrogen
Pan Type	Tzero Aluminum Hermetic
Source Files 1	C:\Users\yargerlab\Desktop\DSC Data\General\Sapphire_Heat_Capacity_11_30_22.tri
[Rev Cp Calibration]
Date Applied	11/30/2022 1:58:51 PM
Description	From -79.996 °C to 292.812 °C at 3.000°C/min
Gas Type	Nitrogen
Pan Type	Tzero Aluminum Hermetic
Source Files 1	C:\Users\yargerlab\Desktop\DSC Data\General\Sapphire_MDSC_Calibration_11_30_22.tri
[step]
Ramp 5.00 °C/min to -90.00 °C
Time	Temperature	Heat Flow (Normalized)
min	°C	W/g
0.00	30.05	-0.019
0.02	30.05	-0.016
0.03	30.05	-0.014
0.05	30.04	-0.011
0.07	30.04	-0.008
0.08	30.02	-0.006
0.10	30.00	-0.007
0.12	29.96	-0.012
0.13	29.92	-0.026
0.15	29.88	-0.038
0.17	29.83	-0.053
0.18	29.77	-0.066
0.20	29.72	-0.078
0.22	29.65	-0.088
0.23	29.59	-0.097
0.25	29.53	-0.105
0.27	29.46	-0.111
0.28	29.39	-0.117
0.30	29.32	-0.122
0.32	29.25	-0.127
0.33	29.18	-0.131
0.35	29.11	-0.135
0.37	29.03	-0.139
0.38	28.96	-0.141
0.40	28.88	-0.144
0.42	28.81	-0.147
0.43	28.73	-0.148
0.45	28.65	-0.149
0.47	28.57	-0.151
0.48	28.50	-0.153
0.50	28.42	-0.154
0.52	28.34	-0.154
0.53	28.26	-0.155
0.55	28.18	-0.156
0.57	28.10	-0.157
0.58	28.02	-0.157
0.60	27.94	-0.158
0.62	27.85	-0.159
0.63	27.77	-0.160
0.65	27.69	-0.160
0.67	27.61	-0.160
0.68	27.53	-0.160
0.70	27.45	-0.160
0.72	27.37	-0.161
0.73	27.29	-0.161
0.75	27.20	-0.161
0.77	27.12	-0.161
0.78	27.04	-0.162
0.80	26.96	-0.162
0.82	26.88	-0.162
0.83	26.79	-0.162
0.85	26.71	-0.162
0.87	26.63	-0.162
0.88	26.55	-0.163
0.90	26.47	-0.163
0.92	26.38	-0.163
0.93	26.30	-0.163
0.95	26.22	-0.163
0.97	26.13	-0.163
0.98	26.05	-0.163
1.00	25.97	-0.164
1.02	25.89	-0.164
1.03	25.80	-0.164
1.05	25.72	-0.164
1.07	25.64	-0.164
1.08	25.55	-0.164
1.10	25.47	-0.164
1.12	25.39	-0.164
1.13	25.31	-0.164
1.15	25.22	-0.164
1.17	25.14	-0.164
1.18	25.06	-0.164
1.20	24.98	-0.164
1.22	24.89	-0.164
1.23	24.81	-0.164
1.25	24.73	-0.165
1.27	24.64	-0.165
1.28	24.56	-0.165
1.30	24.48	-0.165
1.32	24.39	-0.165
1.33	24.31	-0.165
1.35	24.23	-0.165
1.37	24.14	-0.165
1.38	24.06	-0.165
1.40	23.98	-0.165
1.42	23.90	-0.165
1.43	23.81	-0.165
1.45	23.73	-0.165
1.47	23.64	-0.165
1.48	23.56	-0.165
1.50	23.48	-0.165
1.52	23.40	-0.165
1.53	23.31	-0.165
1.55	23.23	-0.165
1.57	23.14	-0.165
1.58	23.06	-0.165
1.60	22.98	-0.165
1.62	22.90	-0.165
1.63	22.81	-0.165
1.65	22.73	-0.165
1.67	22.65	-0.165
1.68	22.56	-0.165
1.70	22.48	-0.165
1.72	22.40	-0.165
1.73	22.31	-0.165
1.75	22.23	-0.165
1.77	22.15	-0.165
1.78	22.06	-0.164
1.80	21.98	-0.164
1.82	21.90	-0.164
1.83	21.81	-0.164
1.85	21.73	-0.164
1.87	21.65	-0.164
1.88	21.56	-0.164
1.90	21.48	-0.164
1.92	21.40	-0.164
1.93	21.31	-0.164
1.95	21.23	-0.164
1.97	21.15	-0.164
1.98	21.06	-0.164
2.00	20.98	-0.164
2.02	20.90	-0.164
2.03	20.82	-0.164
2.05	20.73	-0.164
2.07	20.65	-0.164
2.08	20.56	-0.164
2.10	20.48	-0.164
2.12	20.40	-0.164
2.13	20.32	-0.164
2.15	20.23	-0.164
2.17	20.15	-0.164
2.18	20.07	-0.164
2.20	19.98	-0.164
2.22	19.90	-0.164
2.23	19.82	-0.164
2.25	19.73	-0.164
2.27	19.65	-0.164
2.28	19.57	-0.164
2.30	19.48	-0.163
2.32	19.40	-0.163
2.33	19.31	-0.163
2.35	19.23	-0.163
2.37	19.15	-0.163
2.38	19.07	-0.163
2.40	18.98	-0.163
2.42	18.90	-0.163
2.43	18.82	-0.163
2.45	18.73	-0.163
2.47	18.65	-0.163
2.48	18.57	-0.163
2.50	18.48	-0.163
2.52	18.40	-0.163
2.53	18.32	-0.163
2.55	18.23	-0.163
2.57	18.15	-0.163
2.58	18.07	-0.163
2.60	17.98	-0.163
2.62	17.90	-0.163
2.63	17.81	-0.163
2.65	17.73	-0.163
2.67	17.65	-0.163
2.68	17.57	-0.162
2.70	17.48	-0.162
2.72	17.40	-0.162
2.73	17.32	-0.162
2.75	17.23	-0.162
2.77	17.15	-0.162
2.78	17.07	-0.162
2.80	16.98	-0.162
2.82	16.90	-0.162
2.83	16.82	-0.162
2.85	16.73	-0.162
2.87	16.65	-0.162
2.88	16.57	-0.162
2.90	16.48	-0.162
2.92	16.40	-0.162
2.93	16.32	-0.162
2.95	16.23	-0.162
2.97	16.15	-0.162
2.98	16.07	-0.162
3.00	15.98	-0.162
3.02	15.90	-0.162
3.03	15.82	-0.162
3.05	15.73	-0.162
3.07	15.65	-0.162
3.08	15.57	-0.162
3.10	15.48	-0.162
3.12	15.40	-0.162
3.13	15.32	-0.162
3.15	15.23	-0.162
3.17	15.15	-0.161
3.18	15.07	-0.161
3.20	14.98	-0.161
3.22	14.90	-0.161
3.23	14.82	-0.161
3.25	14.73	-0.161
3.27	14.65	-0.161
3.28	14.57	-0.161
3.30	14.48	-0.161
3.32	14.40	-0.161
3.33	14.32	-0.161
3.35	14.23	-0.161
3.37	14.15	-0.161
3.38	14.07	-0.161
3.40	13.98	-0.161
3.42	13.90	-0.161
3.43	13.82	-0.161
3.45	13.73	-0.161
3.47	13.65	-0.161
3.48	13.57	-0.161
3.50	13.48	-0.161
3.52	13.40	-0.161
3.53	13.32	-0.161
3.55	13.23	-0.161
3.57	13.15	-0.160
3.58	13.07	-0.160
3.60	12.98	-0.160
3.62	12.90	-0.160
3.63	12.82	-0.160
3.65	12.73	-0.160
3.67	12.65	-0.160
3.68	12.57	-0.160
3.70	12.48	-0.160
3.72	12.40	-0.160
3.73	12.32	-0.160
3.75	12.23	-0.160
3.77	12.15	-0.160
3.78	12.07	-0.160
3.80	11.98	-0.160
3.82	11.90	-0.160
3.83	11.82	-0.160
3.85	11.73	-0.160
3.87	11.65	-0.160
3.88	11.57	-0.160
3.90	11.48	-0.160
3.92	11.40	-0.159
3.93	11.32	-0.159
3.95	11.23	-0.159
3.97	11.15	-0.159
3.98	11.07	-0.159
4.00	10.99	-0.159
4.02	10.90	-0.159
4.03	10.82	-0.159
4.05	10.73	-0.159
4.07	10.65	-0.159
4.08	10.57	-0.159
4.10	10.49	-0.159
4.12	10.40	-0.159
4.13	10.32	-0.159
4.15	10.24	-0.159
4.17	10.15	-0.159
4.18	10.07	-0.159
4.20	9.99	-0.159
4.22	9.90	-0.159
4.23	9.82	-0.159
4.25	9.73	-0.159
4.27	9.65	-0.159
4.28	9.57	-0.159
4.30	9.49	-0.159
4.32	9.40	-0.159
4.33	9.32	-0.159
4.35	9.24	-0.159
4.37	9.15	-0.158
4.38	9.07	-0.158
4.40	8.99	-0.158
4.42	8.90	-0.158
4.43	8.82	-0.158
4.45	8.74	-0.158
4.47	8.65	-0.158
4.48	8.57	-0.158
4.50	8.48	-0.158
4.52	8.40	-0.158
4.53	8.32	-0.158
4.55	8.24	-0.158
4.57	8.15	-0.158
4.58	8.07	-0.158
4.60	7.98	-0.158
4.62	7.90	-0.158
4.63	7.82	-0.158
4.65	7.74	-0.158
4.67	7.65	-0.158
4.68	7.57	-0.158
4.70	7.49	-0.158
4.72	7.40	-0.158
4.73	7.32	-0.158
4.75	7.24	-0.158
4.77	7.15	-0.158
4.78	7.07	-0.157
4.80	6.99	-0.157
4.82	6.90	-0.157
4.83	6.82	-0.157
4.85	6.74	-0.157
4.87	6.65	-0.157
4.88	6.57	-0.157
4.90	6.49	-0.157
4.92	6.40	-0.157
4.93	6.32	-0.157
4.95	6.24	-0.157
4.97	6.15	-0.157
4.98	6.07	-0.157
5.00	5.99	-0.157
5.02	5.90	-0.157
5.03	5.82	-0.157
5.05	5.74	-0.157
5.07	5.65	-0.157
5.08	5.57	-0.157
5.10	5.49	-0.157
5.12	5.40	-0.157
5.13	5.32	-0.157
5.15	5.24	-0.157
5.17	5.15	-0.157
5.18	5.07	-0.156
5.20	4.99	-0.156
5.22	4.91	-0.156
5.23	4.82	-0.156
5.25	4.74	-0.156
5.27	4.65	-0.156
5.28	4.57	-0.156
5.30	4.49	-0.156
5.32	4.41	-0.156
5.33	4.32	-0.156
5.35	4.24	-0.156
5.37	4.15	-0.156
5.38	4.07	-0.156
5.40	3.99	-0.156
5.42	3.90	-0.156
5.43	3.82	-0.156
5.45	3.74	-0.156
5.47	3.65	-0.156
5.48	3.57	-0.156
5.50	3.49	-0.156
5.52	3.41	-0.156
5.53	3.32	-0.156
5.55	3.24	-0.156
5.57	3.16	-0.156
5.58	3.07	-0.156
5.60	2.99	-0.155
5.62	2.90	-0.155
5.63	2.82	-0.155
5.65	2.74	-0.155
5.67	2.65	-0.155
5.68	2.57	-0.155
5.70	2.49	-0.155
5.72	2.40	-0.155
5.73	2.32	-0.155
5.75	2.24	-0.155
5.77	2.15	-0.155
5.78	2.07	-0.155
5.80	1.99	-0.155
5.82	1.90	-0.155
5.83	1.82	-0.155
5.85	1.74	-0.155
5.87	1.65	-0.155
5.88	1.57	-0.155
5.90	1.49	-0.155
5.92	1.41	-0.155
5.93	1.32	-0.155
5.95	1.24	-0.155
5.97	1.16	-0.155
5.98	1.07	-0.155
6.00	0.99	-0.155
6.02	0.91	-0.154
6.03	0.82	-0.154
6.05	0.74	-0.154
6.07	0.66	-0.154
6.08	0.57	-0.154
6.10	0.49	-0.154
6.12	0.41	-0.154
6.13	0.32	-0.154
6.15	0.24	-0.154
6.17	0.16	-0.154
6.18	0.07	-0.154
6.20	-0.01	-0.154
6.22	-0.09	-0.154
6.23	-0.18	-0.154
6.25	-0.26	-0.154
6.27	-0.34	-0.154
6.28	-0.43	-0.154
6.30	-0.51	-0.154
6.32	-0.59	-0.154
6.33	-0.68	-0.154
6.35	-0.76	-0.154
6.37	-0.84	-0.154
6.38	-0.93	-0.154
6.40	-1.01	-0.154
6.42	-1.09	-0.154
6.43	-1.18	-0.154
6.45	-1.26	-0.154
6.47	-1.34	-0.154
6.48	-1.43	-0.154
6.50	-1.51	-0.154
6.52	-1.59	-0.153
6.53	-1.68	-0.153
6.55	-1.76	-0.153
6.57	-1.84	-0.153
6.58	-1.92	-0.153
6.60	-2.01	-0.153
6.62	-2.09	-0.153
6.63	-2.17	-0.153
6.65	-2.26	-0.153
6.67	-2.34	-0.153
6.68	-2.43	-0.153
6.70	-2.51	-0.153
6.72	-2.59	-0.153
6.73	-2.68	-0.153
6.75	-2.76	-0.153
6.77	-2.84	-0.153
6.78	-2.93	-0.153
6.80	-3.01	-0.153
6.82	-3.09	-0.153
6.83	-3.18	-0.153
6.85	-3.26	-0.153
6.87	-3.34	-0.153
6.88	-3.42	-0.153
6.90	-3.51	-0.153
6.92	-3.59	-0.153
6.93	-3.67	-0.153
6.95	-3.76	-0.153
6.97	-3.84	-0.153
6.98	-3.92	-0.153
7.00	-4.01	-0.153
7.02	-4.09	-0.152
7.03	-4.17	-0.152
7.05	-4.26	-0.152
7.07	-4.34	-0.152
7.08	-4.42	-0.152
7.10	-4.51	-0.152
7.12	-4.59	-0.152
7.13	-4.67	-0.152
7.15	-4.76	-0.152
7.17	-4.84	-0.152
7.18	-4.92	-0.152
7.20	-5.01	-0.152
7.22	-5.09	-0.152
7.23	-5.17	-0.152
7.25	-5.26	-0.152
7.27	-5.34	-0.152
7.28	-5.42	-0.152
7.30	-5.51	-0.152
7.32	-5.59	-0.152
7.33	-5.67	-0.152
7.35	-5.76	-0.152
7.37	-5.84	-0.152
7.38	-5.92	-0.152
7.40	-6.01	-0.152
7.42	-6.09	-0.152
7.43	-6.17	-0.152
7.45	-6.26	-0.152
7.47	-6.34	-0.152
7.48	-6.42	-0.152
7.50	-6.51	-0.152
7.52	-6.59	-0.151
7.53	-6.67	-0.151
7.55	-6.75	-0.151
7.57	-6.84	-0.151
7.58	-6.92	-0.151
7.60	-7.00	-0.151
7.62	-7.09	-0.151
7.63	-7.17	-0.151
7.65	-7.26	-0.151
7.67	-7.34	-0.151
7.68	-7.42	-0.151
7.70	-7.51	-0.151
7.72	-7.59	-0.151
7.73	-7.67	-0.151
7.75	-7.75	-0.151
7.77	-7.84	-0.151
7.78	-7.92	-0.151
7.80	-8.00	-0.151
7.82	-8.09	-0.151
7.83	-8.17	-0.151
7.85	-8.25	-0.151
7.87	-8.34	-0.151
7.88	-8.42	-0.151
7.90	-8.50	-0.151
7.92	-8.59	-0.151
7.93	-8.67	-0.151
7.95	-8.75	-0.151
7.97	-8.84	-0.151
7.98	-8.92	-0.151
8.00	-9.00	-0.151
8.02	-9.09	-0.150
8.03	-9.17	-0.150
8.05	-9.25	-0.150
8.07	-9.34	-0.150
8.08	-9.42	-0.150
8.10	-9.50	-0.150
8.12	-9.59	-0.150
8.13	-9.67	-0.150
8.15	-9.75	-0.150
8.17	-9.83	-0.150
8.18	-9.92	-0.150
8.20	-10.00	-0.150
8.22	-10.09	-0.150
8.23	-10.17	-0.150
8.25	-10.25	-0.150
8.27	-10.34	-0.150
8.28	-10.42	-0.150
8.30	-10.50	-0.150
8.32	-10.59	-0.150
8.33	-10.67	-0.150
8.35	-10.75	-0.150
8.37	-10.84	-0.150
8.38	-10.92	-0.150
8.40	-11.00	-0.150
8.42	-11.09	-0.150
8.43	-11.17	-0.150
8.45	-11.25	-0.150
8.47	-11.34	-0.150
8.48	-11.42	-0.150
8.50	-11.50	-0.150
8.52	-11.59	-0.150
8.53	-11.67	-0.150
8.55	-11.75	-0.149
8.57	-11.83	-0.149
8.58	-11.92	-0.149
8.60	-12.00	-0.149
8.62	-12.09	-0.149
8.63	-12.17	-0.149
8.65	-12.25	-0.149
8.67	-12.34	-0.149
8.68	-12.42	-0.149
8.70	-12.50	-0.149
8.72	-12.59	-0.149
8.73	-12.67	-0.149
8.75	-12.75	-0.149
8.77	-12.84	-0.149
8.78	-12.92	-0.149
8.80	-13.00	-0.149
8.82	-13.09	-0.149
8.83	-13.17	-0.149
8.85	-13.25	-0.149
8.87	-13.34	-0.149
8.88	-13.42	-0.149
8.90	-13.50	-0.149
8.92	-13.59	-0.149
8.93	-13.67	-0.149
8.95	-13.75	-0.149
8.97	-13.84	-0.149
8.98	-13.92	-0.149
9.00	-14.00	-0.149
9.02	-14.09	-0.149
9.03	-14.17	-0.149
9.05	-14.25	-0.148
9.07	-14.34	-0.148
9.08	-14.42	-0.148
9.10	-14.50	-0.148
9.12	-14.59	-0.148
9.13	-14.67	-0.148
9.15	-14.75	-0.148
9.17	-14.83	-0.148
9.18	-14.92	-0.148
9.20	-15.00	-0.148
9.22	-15.09	-0.148
9.23	-15.17	-0.148
9.25	-15.25	-0.148
9.27	-15.34	-0.148
9.28	-15.42	-0.148
9.30	-15.50	-0.148
9.32	-15.59	-0.148
9.33	-15.67	-0.148
9.35	-15.75	-0.148
9.37	-15.84	-0.148
9.38	-15.92	-0.148
9.40	-16.00	-0.148
9.42	-16.09	-0.148
9.43	-16.17	-0.148
9.45	-16.25	-0.148
9.47	-16.34	-0.148
9.48	-16.42	-0.148
9.50	-16.50	-0.148
9.52	-16.59	-0.148
9.53	-16.67	-0.148
9.55	-16.75	-0.148
9.57	-16.84	-0.148
9.58	-16.92	-0.148
9.60	-17.00	-0.148
9.62	-17.09	-0.148
9.63	-17.17	-0.148
9.65	-17.25	-0.147
9.67	-17.34	-0.147
9.68	-17.42	-0.147
9.70	-17.50	-0.147
9.72	-17.59	-0.147
9.73	-17.67	-0.147
9.75	-17.76	-0.147
9.77	-17.84	-0.147
9.78	-17.92	-0.147
9.80	-18.01	-0.147
9.82	-18.09	-0.147
9.83	-18.17	-0.147
9.85	-18.26	-0.147
9.87	-18.34	-0.147
9.88	-18.42	-0.147
9.90	-18.51	-0.147
9.92	-18.59	-0.147
9.93	-18.67	-0.147
9.95	-18.76	-0.147
9.97	-18.84	-0.147
9.98	-18.92	-0.147
10.00	-19.01	-0.147
10.02	-19.09	-0.147
10.03	-19.17	-0.147
10.05	-19.26	-0.147
10.07	-19.34	-0.147
10.08	-19.42	-0.147
10.10	-19.51	-0.147
10.12	-19.59	-0.147
10.13	-19.67	-0.147
10.15	-19.76	-0.146
10.17	-19.84	-0.146
10.18	-19.92	-0.146
10.20	-20.01	-0.146
10.22	-20.09	-0.146
10.23	-20.17	-0.146
10.25	-20.26	-0.146
10.27	-20.34	-0.146
10.28	-20.42	-0.146
10.30	-20.51	-0.146
10.32	-20.59	-0.146
10.33	-20.67	-0.146
10.35	-20.76	-0.146
10.37	-20.84	-0.146
10.38	-20.92	-0.146
10.40	-21.01	-0.146
10.42	-21.09	-0.146
10.43	-21.17	-0.146
10.45	-21.26	-0.146
10.47	-21.34	-0.146
10.48	-21.43	-0.146
10.50	-21.51	-0.146
10.52	-21.59	-0.146
10.53	-21.67	-0.146
10.55	-21.76	-0.146
10.57	-21.84	-0.146
10.58	-21.93	-0.146
10.60	-22.01	-0.146
10.62	-22.09	-0.145
10.63	-22.17	-0.145
10.65	-22.26	-0.145
10.67	-22.34	-0.145
10.68	-22.43	-0.145
10.70	-22.51	-0.145
10.72	-22.59	-0.145
10.73	-22.68	-0.145
10.75	-22.76	-0.145
10.77	-22.84	-0.145
10.78	-22.93	-0.145
10.80	-23.01	-0.145
10.82	-23.09	-0.145
10.83	-23.18	-0.145
10.85	-23.26	-0.145
10.87	-23.34	-0.145
10.88	-23.43	-0.145
10.90	-23.51	-0.145
10.92	-23.59	-0.145
10.93	-23.68	-0.145
10.95	-23.76	-0.145
10.97	-23.84	-0.145
10.98	-23.93	-0.145
11.00	-24.01	-0.145
11.02	-24.09	-0.145
11.03	-24.18	-0.145
11.05	-24.26	-0.145
11.07	-24.34	-0.145
11.08	-24.43	-0.145
11.10	-24.51	-0.144
11.12	-24.59	-0.144
11.13	-24.68	-0.144
11.15	-24.76	-0.144
11.17	-24.84	-0.144
11.18	-24.93	-0.144
11.20	-25.01	-0.144
11.22	-25.09	-0.144
11.23	-25.18	-0.144
11.25	-25.26	-0.144
11.27	-25.34	-0.144
11.28	-25.43	-0.144
11.30	-25.51	-0.144
11.32	-25.59	-0.144
11.33	-25.68	-0.144
11.35	-25.76	-0.144
11.37	-25.85	-0.144
11.38	-25.93	-0.144
11.40	-26.01	-0.144
11.42	-26.10	-0.144
11.43	-26.18	-0.144
11.45	-26.26	-0.144
11.47	-26.34	-0.144
11.48	-26.43	-0.144
11.50	-26.51	-0.144
11.52	-26.59	-0.144
11.53	-26.68	-0.144
11.55	-26.76	-0.143
11.57	-26.84	-0.143
11.58	-26.93	-0.143
11.60	-27.01	-0.143
11.62	-27.10	-0.143
11.63	-27.18	-0.143
11.65	-27.26	-0.143
11.67	-27.35	-0.143
11.68	-27.43	-0.142
11.70	-27.51	-0.142
11.72	-27.60	-0.142
11.73	-27.68	-0.142
11.75	-27.76	-0.142
11.77	-27.85	-0.142
11.78	-27.93	-0.142
11.80	-28.01	-0.142
11.82	-28.10	-0.142
11.83	-28.18	-0.142
11.85	-28.26	-0.143
11.87	-28.35	-0.142
11.88	-28.43	-0.142
11.90	-28.51	-0.142
11.92	-28.60	-0.142
11.93	-28.68	-0.142
11.95	-28.76	-0.142
11.97	-28.85	-0.142
11.98	-28.93	-0.142
12.00	-29.01	-0.142
12.02	-29.10	-0.142
12.03	-29.18	-0.142
12.05	-29.26	-0.142
12.07	-29.35	-0.142
12.08	-29.43	-0.142
12.10	-29.51	-0.142
12.12	-29.60	-0.142
12.13	-29.68	-0.142
12.15	-29.76	-0.142
12.17	-29.85	-0.142
12.18	-29.93	-0.142
12.20	-30.01	-0.142
12.22	-30.10	-0.142
12.23	-30.18	-0.142
12.25	-30.26	-0.142
12.27	-30.35	-0.142
12.28	-30.43	-0.142
12.30	-30.51	-0.142
12.32	-30.60	-0.142
12.33	-30.68	-0.142
12.35	-30.76	-0.142
12.37	-30.85	-0.142
12.38	-30.93	-0.142
12.40	-31.01	-0.142
12.42	-31.10	-0.142
12.43	-31.18	-0.142
12.45	-31.26	-0.142
12.47	-31.35	-0.142
12.48	-31.43	-0.142
12.50	-31.52	-0.141
12.52	-31.60	-0.141
12.53	-31.68	-0.141
12.55	-31.76	-0.141
12.57	-31.85	-0.141
12.58	-31.93	-0.141
12.60	-32.02	-0.141
12.62	-32.10	-0.141
12.63	-32.18	-0.141
12.65	-32.26	-0.141
12.67	-32.35	-0.141
12.68	-32.43	-0.141
12.70	-32.51	-0.141
12.72	-32.60	-0.141
12.73	-32.68	-0.141
12.75	-32.77	-0.141
12.77	-32.85	-0.141
12.78	-32.93	-0.141
12.80	-33.02	-0.141
12.82	-33.10	-0.141
12.83	-33.18	-0.141
12.85	-33.26	-0.141
12.87	-33.35	-0.141
12.88	-33.43	-0.141
12.90	-33.51	-0.141
12.92	-33.60	-0.141
12.93	-33.68	-0.141
12.95	-33.77	-0.141
12.97	-33.85	-0.140
12.98	-33.93	-0.140
13.00	-34.02	-0.140
13.02	-34.10	-0.140
13.03	-34.18	-0.140
13.05	-34.26	-0.140
13.07	-34.35	-0.140
13.08	-34.43	-0.140
13.10	-34.52	-0.140
13.12	-34.60	-0.140
13.13	-34.68	-0.140
13.15	-34.77	-0.140
13.17	-34.85	-0.140
13.18	-34.93	-0.140
13.20	-35.01	-0.140
13.22	-35.10	-0.140
13.23	-35.18	-0.140
13.25	-35.26	-0.140
13.27	-35.35	-0.140
13.28	-35.43	-0.140
13.30	-35.52	-0.140
13.32	-35.60	-0.140
13.33	-35.68	-0.140
13.35	-35.77	-0.140
13.37	-35.85	-0.140
13.38	-35.93	-0.140
13.40	-36.02	-0.140
13.42	-36.10	-0.140
13.43	-36.18	-0.140
13.45	-36.27	-0.140
13.47	-36.35	-0.139
13.48	-36.43	-0.139
13.50	-36.51	-0.139
13.52	-36.60	-0.139
13.53	-36.68	-0.139
13.55	-36.77	-0.139
13.57	-36.85	-0.139
13.58	-36.93	-0.139
13.60	-37.02	-0.139
13.62	-37.10	-0.139
13.63	-37.18	-0.139
13.65	-37.27	-0.139
13.67	-37.35	-0.139
13.68	-37.43	-0.139
13.70	-37.52	-0.139
13.72	-37.60	-0.139
13.73	-37.68	-0.139
13.75	-37.77	-0.139
13.77	-37.85	-0.139
13.78	-37.93	-0.139
13.80	-38.02	-0.139
13.82	-38.10	-0.139
13.83	-38.18	-0.139
13.85	-38.27	-0.139
13.87	-38.35	-0.139
13.88	-38.43	-0.139
13.90	-38.52	-0.139
13.92	-38.60	-0.139
13.93	-38.68	-0.139
13.95	-38.77	-0.139
13.97	-38.85	-0.138
13.98	-38.93	-0.138
14.00	-39.02	-0.138
14.02	-39.10	-0.138
14.03	-39.18	-0.138
14.05	-39.27	-0.138
14.07	-39.35	-0.138
14.08	-39.43	-0.138
14.10	-39.52	-0.138
14.12	-39.60	-0.138
14.13	-39.68	-0.138
14.15	-39.77	-0.138
14.17	-39.85	-0.138
14.18	-39.93	-0.138
14.20	-40.02	-0.138
14.22	-40.10	-0.138
14.23	-40.18	-0.138
14.25	-40.27	-0.138
14.27	-40.35	-0.138
14.28	-40.43	-0.138
14.30	-40.52	-0.138
14.32	-40.60	-0.138
14.33	-40.68	-0.137
14.35	-40.77	-0.137
14.37	-40.85	-0.137
14.38	-40.93	-0.137
14.40	-41.02	-0.137
14.42	-41.10	-0.137
14.43	-41.18	-0.137
14.45	-41.27	-0.137
14.47	-41.35	-0.137
14.48	-41.43	-0.137
14.50	-41.52	-0.137
14.52	-41.60	-0.137
14.53	-41.68	-0.137
14.55	-41.77	-0.137
14.57	-41.85	-0.137
14.58	-41.94	-0.137
14.60	-42.02	-0.137
14.62	-42.10	-0.137
14.63	-42.19	-0.136
14.65	-42.27	-0.136
14.67	-42.35	-0.136
14.68	-42.44	-0.136
14.70	-42.52	-0.136
14.72	-42.60	-0.136
14.73	-42.69	-0.136
14.75	-42.77	-0.136
14.77	-42.85	-0.136
14.78	-42.94	-0.136
14.80	-43.02	-0.136
14.82	-43.10	-0.136
14.83	-43.18	-0.136
14.85	-43.27	-0.136
14.87	-43.35	-0.136
14.88	-43.43	-0.135
14.90	-43.52	-0.135
14.92	-43.60	-0.135
14.93	-43.69	-0.135
14.95	-43.77	-0.135
14.97	-43.85	-0.135
14.98	-43.94	-0.135
15.00	-44.02	-0.135
15.02	-44.10	-0.135
15.03	-44.19	-0.135
15.05	-44.27	-0.134
15.07	-44.35	-0.134
15.08	-44.44	-0.134
15.10	-44.52	-0.134
15.12	-44.61	-0.134
15.13	-44.69	-0.134
15.15	-44.77	-0.134
15.17	-44.85	-0.134
15.18	-44.94	-0.133
15.20	-45.02	-0.133
15.22	-45.11	-0.133
15.23	-45.19	-0.133
15.25	-45.27	-0.133
15.27	-45.36	-0.133
15.28	-45.44	-0.133
15.30	-45.52	-0.132
15.32	-45.61	-0.132
15.33	-45.69	-0.132
15.35	-45.77	-0.132
15.37	-45.86	-0.131
15.38	-45.94	-0.131
15.40	-46.02	-0.131
15.42	-46.11	-0.131
15.43	-46.19	-0.131
15.45	-46.27	-0.131
15.47	-46.36	-0.130
15.48	-46.44	-0.130
15.50	-46.52	-0.130
15.52	-46.61	-0.130
15.53	-46.69	-0.129
15.55	-46.77	-0.129
15.57	-46.86	-0.129
15.58	-46.94	-0.129
15.60	-47.03	-0.129
15.62	-47.11	-0.128
15.63	-47.19	-0.128
15.65	-47.28	-0.128
15.67	-47.36	-0.127
15.68	-47.44	-0.127
15.70	-47.53	-0.127
15.72	-47.61	-0.126
15.73	-47.69	-0.126
15.75	-47.78	-0.125
15.77	-47.86	-0.125
15.78	-47.94	-0.125
15.80	-48.03	-0.125
15.82	-48.11	-0.124
15.83	-48.19	-0.124
15.85	-48.28	-0.124
15.87	-48.36	-0.124
15.88	-48.45	-0.124
15.90	-48.53	-0.123
15.92	-48.61	-0.123
15.93	-48.70	-0.123
15.95	-48.78	-0.122
15.97	-48.86	-0.122
15.98	-48.95	-0.122
16.00	-49.03	-0.122
16.02	-49.12	-0.121
16.03	-49.20	-0.121
16.05	-49.28	-0.121
16.07	-49.37	-0.120
16.08	-49.45	-0.120
16.10	-49.53	-0.120
16.12	-49.62	-0.119
16.13	-49.70	-0.119
16.15	-49.78	-0.118
16.17	-49.87	-0.118
16.18	-49.95	-0.118
16.20	-50.04	-0.118
16.22	-50.12	-0.118
16.23	-50.20	-0.117
16.25	-50.29	-0.117
16.27	-50.37	-0.117
16.28	-50.45	-0.116
16.30	-50.54	-0.116
16.32	-50.62	-0.116
16.33	-50.70	-0.115
16.35	-50.79	-0.115
16.37	-50.87	-0.115
16.38	-50.96	-0.114
16.40	-51.04	-0.114
16.42	-51.12	-0.114
16.43	-51.20	-0.114
16.45	-51.29	-0.113
16.47	-51.37	-0.113
16.48	-51.46	-0.113
16.50	-51.54	-0.113
16.52	-51.62	-0.112
16.53	-51.71	-0.112
16.55	-51.79	-0.111
16.57	-51.87	-0.111
16.58	-51.96	-0.111
16.60	-52.04	-0.111
16.62	-52.13	-0.111
16.63	-52.21	-0.110
16.65	-52.29	-0.110
16.67	-52.38	-0.110
16.68	-52.46	-0.109
16.70	-52.54	-0.109
16.72	-52.63	-0.108
16.73	-52.71	-0.108
16.75	-52.79	-0.108
16.77	-52.88	-0.107
16.78	-52.96	-0.107
16.80	-53.05	-0.107
16.82	-53.13	-0.107
16.83	-53.21	-0.107
16.85	-53.30	-0.107
16.87	-53.38	-0.106
16.88	-53.46	-0.106
16.90	-53.55	-0.106
16.92	-53.63	-0.106
16.93	-53.71	-0.106
16.95	-53.80	-0.105
16.97	-53.88	-0.104
16.98	-53.96	-0.104
17.00	-54.05	-0.104
17.02	-54.13	-0.104
17.03	-54.21	-0.104
17.05	-54.30	-0.104
17.07	-54.38	-0.103
17.08	-54.46	-0.103
17.10	-54.55	-0.103
17.12	-54.63	-0.103
17.13	-54.72	-0.103
17.15	-54.80	-0.102
17.17	-54.88	-0.102
17.18	-54.97	-0.102
17.20	-55.05	-0.102
17.22	-55.13	-0.102
17.23	-55.22	-0.102
17.25	-55.30	-0.101
17.27	-55.38	-0.101
17.28	-55.47	-0.101
17.30	-55.55	-0.101
17.32	-55.64	-0.101
17.33	-55.72	-0.100
17.35	-55.80	-0.100
17.37	-55.88	-0.100
17.38	-55.97	-0.100
17.40	-56.05	-0.100
17.42	-56.13	-0.100
17.43	-56.22	-0.099
17.45	-56.30	-0.099
17.47	-56.38	-0.099
17.48	-56.47	-0.099
17.50	-56.55	-0.099
17.52	-56.64	-0.099
17.53	-56.72	-0.098
17.55	-56.80	-0.098
17.57	-56.88	-0.098
17.58	-56.97	-0.098
17.60	-57.05	-0.098
17.62	-57.14	-0.097
17.63	-57.22	-0.097
17.65	-57.30	-0.097
17.67	-57.39	-0.097
17.68	-57.47	-0.097
17.70	-57.55	-0.097
17.72	-57.64	-0.096
17.73	-57.72	-0.096
17.75	-57.80	-0.096
17.77	-57.89	-0.096
17.78	-57.97	-0.096
17.80	-58.05	-0.096
17.82	-58.14	-0.095
17.83	-58.22	-0.095
17.85	-58.31	-0.095
17.87	-58.39	-0.095
17.88	-58.47	-0.095
17.90	-58.56	-0.095
17.92	-58.64	-0.095
17.93	-58.72	-0.094
17.95	-58.81	-0.094
17.97	-58.89	-0.094
17.98	-58.97	-0.094
18.00	-59.06	-0.094
18.02	-59.14	-0.094
18.03	-59.22	-0.094
18.05	-59.31	-0.093
18.07	-59.39	-0.093
18.08	-59.48	-0.093
18.10	-59.56	-0.093
18.12	-59.64	-0.092
18.13	-59.72	-0.092
18.15	-59.81	-0.092
18.17	-59.89	-0.092
18.18	-59.97	-0.092
18.20	-60.06	-0.091
18.22	-60.14	-0.091
18.23	-60.23	-0.091
18.25	-60.31	-0.091
18.27	-60.39	-0.091
18.28	-60.48	-0.091
18.30	-60.56	-0.091
18.32	-60.64	-0.091
18.33	-60.73	-0.091
18.35	-60.81	-0.091
18.37	-60.89	-0.091
18.38	-60.98	-0.091
18.40	-61.06	-0.090
18.42	-61.14	-0.090
18.43	-61.23	-0.090
18.45	-61.31	-0.090
18.47	-61.39	-0.090
18.48	-61.48	-0.090
18.50	-61.56	-0.090
18.52	-61.64	-0.090
18.53	-61.73	-0.089
18.55	-61.81	-0.089
18.57	-61.89	-0.089
18.58	-61.98	-0.089
18.60	-62.06	-0.089
18.62	-62.14	-0.089
18.63	-62.23	-0.089
18.65	-62.31	-0.089
18.67	-62.39	-0.089
18.68	-62.48	-0.089
18.70	-62.56	-0.088
18.72	-62.64	-0.088
18.73	-62.73	-0.088
18.75	-62.81	-0.088
18.77	-62.90	-0.088
18.78	-62.98	-0.088
18.80	-63.06	-0.088
18.82	-63.14	-0.088
18.83	-63.23	-0.088
18.85	-63.31	-0.087
18.87	-63.39	-0.087
18.88	-63.48	-0.087
18.90	-63.56	-0.087
18.92	-63.64	-0.087
18.93	-63.73	-0.087
18.95	-63.81	-0.087
18.97	-63.90	-0.087
18.98	-63.98	-0.087
19.00	-64.06	-0.087
19.02	-64.15	-0.087
19.03	-64.23	-0.086
19.05	-64.31	-0.086
19.07	-64.40	-0.086
19.08	-64.48	-0.086
19.10	-64.56	-0.086
19.12	-64.65	-0.086
19.13	-64.73	-0.086
19.15	-64.81	-0.086
19.17	-64.90	-0.086
19.18	-64.98	-0.086
19.20	-65.06	-0.086
19.22	-65.15	-0.085
19.23	-65.23	-0.085
19.25	-65.31	-0.085
19.27	-65.40	-0.085
19.28	-65.48	-0.085
19.30	-65.56	-0.085
19.32	-65.65	-0.085
19.33	-65.73	-0.085
19.35	-65.81	-0.085
19.37	-65.90	-0.084
19.38	-65.98	-0.084
19.40	-66.06	-0.084
19.42	-66.15	-0.084
19.43	-66.23	-0.084
19.45	-66.31	-0.084
19.47	-66.40	-0.084
19.48	-66.48	-0.084
19.50	-66.56	-0.084
19.52	-66.65	-0.084
19.53	-66.73	-0.084
19.55	-66.81	-0.084
19.57	-66.90	-0.084
19.58	-66.98	-0.083
19.60	-67.06	-0.083
19.62	-67.15	-0.083
19.63	-67.23	-0.083
19.65	-67.31	-0.083
19.67	-67.40	-0.083
19.68	-67.48	-0.083
19.70	-67.56	-0.083
19.72	-67.65	-0.083
19.73	-67.73	-0.083
19.75	-67.81	-0.083
19.77	-67.90	-0.083
19.78	-67.98	-0.083
19.80	-68.07	-0.082
19.82	-68.15	-0.082
19.83	-68.23	-0.082
19.85	-68.32	-0.082
19.87	-68.40	-0.082
19.88	-68.48	-0.082
19.90	-68.56	-0.082
19.92	-68.65	-0.082
19.93	-68.73	-0.082
19.95	-68.82	-0.082
19.97	-68.90	-0.082
19.98	-68.98	-0.082
20.00	-69.06	-0.082
20.02	-69.15	-0.081
20.03	-69.23	-0.081
20.05	-69.32	-0.081
20.07	-69.40	-0.081
20.08	-69.48	-0.081
20.10	-69.57	-0.081
20.12	-69.65	-0.081
20.13	-69.73	-0.081
20.15	-69.81	-0.081
20.17	-69.90	-0.081
20.18	-69.98	-0.081
20.20	-70.07	-0.081
20.22	-70.15	-0.080
20.23	-70.23	-0.080
20.25	-70.32	-0.080
20.27	-70.40	-0.080
20.28	-70.48	-0.080
20.30	-70.57	-0.080
20.32	-70.65	-0.080
20.33	-70.73	-0.080
20.35	-70.82	-0.080
20.37	-70.90	-0.080
20.38	-70.98	-0.080
20.40	-71.07	-0.079
20.42	-71.15	-0.079
20.43	-71.23	-0.079
20.45	-71.31	-0.079
20.47	-71.40	-0.079
20.48	-71.48	-0.079
20.50	-71.57	-0.079
20.52	-71.65	-0.079
20.53	-71.73	-0.079
20.55	-71.82	-0.079
20.57	-71.90	-0.079
20.58	-71.98	-0.079
20.60	-72.07	-0.078
20.62	-72.15	-0.078
20.63	-72.23	-0.078
20.65	-72.32	-0.078
20.67	-72.40	-0.078
20.68	-72.48	-0.078
20.70	-72.57	-0.078
20.72	-72.65	-0.078
20.73	-72.74	-0.078
20.75	-72.82	-0.078
20.77	-72.90	-0.078
20.78	-72.98	-0.078
20.80	-73.07	-0.078
20.82	-73.15	-0.078
20.83	-73.23	-0.078
20.85	-73.32	-0.077
20.87	-73.40	-0.077
20.88	-73.48	-0.077
20.90	-73.57	-0.077
20.92	-73.65	-0.077
20.93	-73.73	-0.077
20.95	-73.82	-0.077
20.97	-73.90	-0.077
20.98	-73.98	-0.077
21.00	-74.07	-0.077
21.02	-74.15	-0.077
21.03	-74.23	-0.077
21.05	-74.32	-0.077
21.07	-74.40	-0.077
21.08	-74.48	-0.077
21.10	-74.57	-0.076
21.12	-74.65	-0.076
21.13	-74.73	-0.076
21.15	-74.82	-0.076
21.17	-74.90	-0.076
21.18	-74.98	-0.076
21.20	-75.07	-0.076
21.22	-75.15	-0.076
21.23	-75.23	-0.076
21.25	-75.32	-0.076
21.27	-75.40	-0.076
21.28	-75.48	-0.076
21.30	-75.57	-0.076
21.32	-75.65	-0.076
21.33	-75.73	-0.076
21.35	-75.82	-0.076
21.37	-75.90	-0.076
21.38	-75.98	-0.076
21.40	-76.07	-0.076
21.42	-76.15	-0.076
21.43	-76.23	-0.076
21.45	-76.32	-0.076
21.47	-76.40	-0.076
21.48	-76.48	-0.076
21.50	-76.57	-0.075
21.52	-76.65	-0.075
21.53	-76.73	-0.075
21.55	-76.82	-0.075
21.57	-76.90	-0.075
21.58	-76.98	-0.075
21.60	-77.07	-0.075
21.62	-77.15	-0.075
21.63	-77.23	-0.075
21.65	-77.32	-0.075
21.67	-77.40	-0.075
21.68	-77.48	-0.075
21.70	-77.57	-0.075
21.72	-77.65	-0.075
21.73	-77.73	-0.075
21.75	-77.82	-0.075
21.77	-77.90	-0.075
21.78	-77.98	-0.075
21.80	-78.07	-0.075
21.82	-78.15	-0.075
21.83	-78.23	-0.075
21.85	-78.31	-0.075
21.87	-78.40	-0.074
21.88	-78.48	-0.074
21.90	-78.56	-0.074
21.92	-78.65	-0.074
21.93	-78.73	-0.074
21.95	-78.81	-0.074
21.97	-78.89	-0.074
21.98	-78.98	-0.074
22.00	-79.06	-0.074
22.02	-79.14	-0.074
22.03	-79.23	-0.074
22.05	-79.31	-0.074
22.07	-79.39	-0.074
22.08	-79.48	-0.074
22.10	-79.56	-0.074
22.12	-79.64	-0.074
22.13	-79.72	-0.074
22.15	-79.81	-0.073
22.17	-79.89	-0.073
22.18	-79.97	-0.073
22.20	-80.06	-0.073
22.22	-80.14	-0.073
22.23	-80.22	-0.073
22.25	-80.30	-0.073
22.27	-80.39	-0.073
22.28	-80.47	-0.073
22.30	-80.55	-0.073
22.32	-80.64	-0.073
22.33	-80.72	-0.073
22.35	-80.80	-0.073
22.37	-80.88	-0.073
22.38	-80.96	-0.073
22.40	-81.05	-0.073
22.42	-81.13	-0.073
22.43	-81.21	-0.072
22.45	-81.30	-0.072
22.47	-81.38	-0.072
22.48	-81.46	-0.072
22.50	-81.55	-0.072
22.52	-81.63	-0.072
22.53	-81.71	-0.072
22.55	-81.79	-0.072
22.57	-81.88	-0.072
22.58	-81.96	-0.072
22.60	-82.04	-0.072
22.62	-82.12	-0.072
22.63	-82.21	-0.072
22.65	-82.29	-0.072
22.67	-82.37	-0.072
22.68	-82.45	-0.072
22.70	-82.54	-0.072
22.72	-82.62	-0.072
22.73	-82.70	-0.072
22.75	-82.79	-0.072
22.77	-82.87	-0.072
22.78	-82.95	-0.072
22.80	-83.03	-0.072
22.82	-83.12	-0.072
22.83	-83.20	-0.071
22.85	-83.28	-0.071
22.87	-83.36	-0.071
22.88	-83.44	-0.071
22.90	-83.53	-0.071
22.92	-83.61	-0.071
22.93	-83.69	-0.071
22.95	-83.78	-0.071
22.97	-83.86	-0.071
22.98	-83.94	-0.071
23.00	-84.02	-0.071
23.02	-84.10	-0.071
23.03	-84.19	-0.071
23.05	-84.27	-0.071
23.07	-84.35	-0.071
23.08	-84.43	-0.071
23.10	-84.52	-0.071
23.12	-84.60	-0.071
23.13	-84.68	-0.070
23.15	-84.76	-0.070
23.17	-84.84	-0.070
23.18	-84.92	-0.070
23.20	-85.00	-0.070
23.22	-85.09	-0.070
23.23	-85.17	-0.070
23.25	-85.24	-0.070
23.27	-85.33	-0.070
23.28	-85.41	-0.070
23.30	-85.49	-0.070
23.32	-85.57	-0.070
23.33	-85.64	-0.070
23.35	-85.73	-0.069
23.37	-85.80	-0.069
23.38	-85.88	-0.069
23.40	-85.96	-0.069
23.42	-86.04	-0.069
23.43	-86.11	-0.068
23.45	-86.19	-0.068
23.47	-86.27	-0.068
23.48	-86.35	-0.068
23.50	-86.42	-0.067
23.52	-86.49	-0.067
23.53	-86.57	-0.067
23.55	-86.65	-0.066
23.57	-86.72	-0.066
23.58	-86.80	-0.066
23.60	-86.87	-0.065
23.62	-86.94	-0.065
23.63	-87.02	-0.065
23.65	-87.09	-0.064
23.67	-87.16	-0.064
23.68	-87.23	-0.064
23.70	-87.30	-0.063
23.72	-87.37	-0.063
23.73	-87.45	-0.063
23.75	-87.52	-0.062
23.77	-87.58	-0.062
23.78	-87.66	-0.061
23.80	-87.72	-0.061
23.82	-87.79	-0.061
23.83	-87.86	-0.060
23.85	-87.93	-0.060
23.87	-88.00	-0.060
23.88	-88.07	-0.059
23.90	-88.13	-0.059
23.92	-88.20	-0.058
23.93	-88.27	-0.058
23.95	-88.33
23.97	-88.40
23.98	-88.47
23.99

[step]
Ramp 5.00 °C/min to 30.00 °C
Time	Temperature	Heat Flow (Normalized)
min	°C	W/g
25.00	-89.95	0.005
25.01	-89.95	0.005
25.03	-89.95	0.006
25.05	-89.95	0.006
25.06	-89.93	0.004
25.08	-89.91	-0.003
25.10	-89.88	-0.009
25.11	-89.85	-0.010
25.13	-89.80	-0.007
25.15	-89.75	0.002
25.16	-89.70	0.010
25.18	-89.65	0.018
25.20	-89.59	0.023
25.21	-89.53	0.028
25.23	-89.46	0.033
25.25	-89.40	0.037
25.26	-89.33	0.043
25.28	-89.26	0.047
25.30	-89.19	0.052
25.31	-89.12	0.055
25.33	-89.05	0.058
25.35	-88.97	0.060
25.36	-88.90	0.063
25.38	-88.82	0.064
25.40	-88.74	0.067
25.41	-88.67	0.069
25.43	-88.59	0.071
25.45	-88.51	0.071
25.46	-88.43	0.073
25.48	-88.35	0.074
25.50	-88.27	0.075
25.51	-88.19	0.075
25.53	-88.11	0.077
25.55	-88.03	0.077
25.56	-87.95	0.077
25.58	-87.87	0.078
25.60	-87.79	0.079
25.61	-87.71	0.079
25.63	-87.63	0.080
25.65	-87.55	0.080
25.66	-87.47	0.080
25.68	-87.38	0.080
25.70	-87.30	0.080
25.71	-87.22	0.081
25.73	-87.14	0.081
25.75	-87.06	0.081
25.76	-86.97	0.081
25.78	-86.89	0.081
25.80	-86.81	0.081
25.81	-86.73	0.081
25.83	-86.65	0.082
25.85	-86.56	0.082
25.86	-86.48	0.082
25.88	-86.40	0.082
25.90	-86.31	0.082
25.91	-86.23	0.082
25.93	-86.15	0.082
25.95	-86.07	0.082
25.96	-85.98	0.082
25.98	-85.90	0.083
26.00	-85.82	0.083
26.01	-85.74	0.083
26.03	-85.66	0.083
26.05	-85.57	0.083
26.06	-85.49	0.083
26.08	-85.41	0.083
26.10	-85.32	0.083
26.11	-85.24	0.083
26.13	-85.16	0.083
26.15	-85.07	0.083
26.16	-84.99	0.083
26.18	-84.91	0.083
26.20	-84.83	0.083
26.21	-84.74	0.083
26.23	-84.66	0.083
26.25	-84.58	0.083
26.26	-84.49	0.083
26.28	-84.41	0.083
26.30	-84.33	0.083
26.31	-84.24	0.083
26.33	-84.16	0.083
26.35	-84.08	0.083
26.36	-84.00	0.083
26.38	-83.91	0.083
26.40	-83.83	0.083
26.41	-83.75	0.083
26.43	-83.66	0.084
26.45	-83.58	0.084
26.46	-83.50	0.084
26.48	-83.41	0.084
26.50	-83.33	0.084
26.51	-83.25	0.084
26.53	-83.16	0.084
26.55	-83.08	0.084
26.56	-83.00	0.084
26.58	-82.91	0.084
26.60	-82.83	0.084
26.61	-82.75	0.084
26.63	-82.66	0.084
26.65	-82.58	0.084
26.66	-82.50	0.084
26.68	-82.41	0.084
26.70	-82.33	0.084
26.71	-82.25	0.084
26.73	-82.16	0.084
26.75	-82.08	0.084
26.76	-82.00	0.084
26.78	-81.92	0.084
26.80	-81.83	0.084
26.81	-81.75	0.084
26.83	-81.66	0.084
26.85	-81.58	0.084
26.86	-81.50	0.084
26.88	-81.42	0.084
26.90	-81.33	0.084
26.91	-81.25	0.084
26.93	-81.16	0.084
26.95	-81.08	0.084
26.96	-81.00	0.084
26.98	-80.91	0.084
27.00	-80.83	0.084
27.01	-80.75	0.084
27.03	-80.66	0.084
27.05	-80.58	0.084
27.06	-80.50	0.084
27.08	-80.42	0.084
27.10	-80.33	0.084
27.11	-80.25	0.084
27.13	-80.16	0.084
27.15	-80.08	0.084
27.16	-80.00	0.084
27.18	-79.91	0.084
27.20	-79.83	0.084
27.21	-79.75	0.084
27.23	-79.66	0.084
27.25	-79.58	0.084
27.26	-79.50	0.084
27.28	-79.41	0.084
27.30	-79.33	0.084
27.31	-79.25	0.084
27.33	-79.16	0.084
27.35	-79.08	0.084
27.36	-79.00	0.084
27.38	-78.91	0.084
27.40	-78.83	0.083
27.41	-78.75	0.084
27.43	-78.66	0.084
27.45	-78.58	0.084
27.46	-78.50	0.084
27.48	-78.41	0.084
27.50	-78.33	0.083
27.51	-78.25	0.083
27.53	-78.16	0.083
27.55	-78.08	0.083
27.56	-78.00	0.084
27.58	-77.91	0.083
27.60	-77.83	0.083
27.61	-77.74	0.083
27.63	-77.66	0.083
27.65	-77.58	0.083
27.66	-77.50	0.083
27.68	-77.41	0.083
27.70	-77.33	0.083
27.71	-77.25	0.083
27.73	-77.16	0.083
27.75	-77.08	0.083
27.76	-77.00	0.083
27.78	-76.91	0.083
27.80	-76.83	0.083
27.81	-76.74	0.083
27.83	-76.66	0.083
27.85	-76.58	0.083
27.86	-76.50	0.083
27.88	-76.41	0.083
27.90	-76.33	0.083
27.91	-76.24	0.083
27.93	-76.16	0.083
27.95	-76.08	0.083
27.96	-75.99	0.083
27.98	-75.91	0.083
28.00	-75.83	0.083
28.01	-75.74	0.083
28.03	-75.66	0.083
28.05	-75.58	0.083
28.06	-75.49	0.083
28.08	-75.41	0.083
28.10	-75.33	0.083
28.11	-75.24	0.083
28.13	-75.16	0.083
28.15	-75.08	0.083
28.16	-74.99	0.083
28.18	-74.91	0.083
28.20	-74.83	0.083
28.21	-74.74	0.083
28.23	-74.66	0.083
28.25	-74.58	0.083
28.26	-74.49	0.083
28.28	-74.41	0.083
28.30	-74.33	0.083
28.31	-74.24	0.083
28.33	-74.16	0.083
28.35	-74.08	0.083
28.36	-73.99	0.083
28.38	-73.91	0.083
28.40	-73.83	0.083
28.41	-73.74	0.083
28.43	-73.66	0.083
28.45	-73.58	0.083
28.46	-73.49	0.083
28.48	-73.41	0.083
28.50	-73.32	0.083
28.51	-73.24	0.083
28.53	-73.16	0.083
28.55	-73.08	0.083
28.56	-72.99	0.083
28.58	-72.91	0.083
28.60	-72.82	0.083
28.61	-72.74	0.083
28.63	-72.66	0.083
28.65	-72.57	0.083
28.66	-72.49	0.083
28.68	-72.41	0.083
28.70	-72.32	0.083
28.71	-72.24	0.083
28.73	-72.16	0.083
28.75	-72.07	0.083
28.76	-71.99	0.083
28.78	-71.91	0.083
28.80	-71.82	0.083
28.81	-71.74	0.083
28.83	-71.66	0.083
28.85	-71.57	0.083
28.86	-71.49	0.083
28.88	-71.41	0.083
28.90	-71.32	0.084
28.91	-71.24	0.084
28.93	-71.16	0.084
28.95	-71.07	0.084
28.96	-70.99	0.084
28.98	-70.91	0.084
29.00	-70.82	0.084
29.01	-70.74	0.084
29.03	-70.66	0.084
29.05	-70.57	0.084
29.06	-70.49	0.084
29.08	-70.41	0.084
29.10	-70.32	0.084
29.11	-70.24	0.084
29.13	-70.16	0.084
29.15	-70.07	0.084
29.16	-69.99	0.084
29.18	-69.91	0.084
29.20	-69.82	0.084
29.21	-69.74	0.084
29.23	-69.66	0.084
29.25	-69.57	0.084
29.26	-69.49	0.084
29.28	-69.41	0.084
29.30	-69.32	0.084
29.31	-69.24	0.084
29.33	-69.15	0.084
29.35	-69.07	0.084
29.36	-68.99	0.084
29.38	-68.90	0.084
29.40	-68.82	0.084
29.41	-68.74	0.084
29.43	-68.66	0.084
29.45	-68.57	0.084
29.46	-68.49	0.084
29.48	-68.41	0.084
29.50	-68.32	0.084
29.51	-68.24	0.084
29.53	-68.16	0.084
29.55	-68.07	0.084
29.56	-67.99	0.084
29.58	-67.91	0.084
29.60	-67.82	0.084
29.61	-67.74	0.084
29.63	-67.66	0.084
29.65	-67.57	0.084
29.66	-67.49	0.084
29.68	-67.41	0.084
29.70	-67.32	0.085
29.71	-67.24	0.085
29.73	-67.15	0.085
29.75	-67.07	0.085
29.76	-66.99	0.085
29.78	-66.91	0.085
29.80	-66.82	0.085
29.81	-66.74	0.085
29.83	-66.65	0.085
29.85	-66.57	0.085
29.86	-66.49	0.085
29.88	-66.41	0.085
29.90	-66.32	0.085
29.91	-66.24	0.085
29.93	-66.16	0.085
29.95	-66.07	0.085
29.96	-65.99	0.085
29.98	-65.91	0.085
30.00	-65.82	0.085
[...]
131.85	-56.57	0.087
131.87	-56.48	0.087
131.89	-56.40	0.087
131.90	-56.32	0.087
131.92	-56.24	0.087
131.94	-56.15	0.088
131.95	-56.07	0.088
131.97	-55.99	0.088
131.99	-55.90	0.088
132.00	-55.82	0.088
132.02	-55.73	0.088
132.04	-55.65	0.088
132.05	-55.57	0.088
132.07	-55.49	0.088
132.09	-55.40	0.088
132.10	-55.32	0.088
132.12	-55.24	0.088
132.14	-55.15	0.088
132.15	-55.07	0.088
132.17	-54.98	0.088
132.19	-54.90	0.088
132.20	-54.82	0.088
132.22	-54.74	0.089
132.24	-54.65	0.089
132.25	-54.57	0.089
132.27	-54.49	0.089
132.29	-54.40	0.089
132.30	-54.32	0.089
132.32	-54.24	0.089
132.34	-54.15	0.089
132.35	-54.07	0.089
132.37	-53.99	0.089
132.39	-53.90	0.089
132.40	-53.82	0.089
132.42	-53.74	0.090
132.44	-53.66	0.090
132.45	-53.57	0.090
132.47	-53.49	0.090
132.49	-53.40	0.090
132.50	-53.32	0.090
132.52	-53.24	0.090
132.54	-53.15	0.090
132.55	-53.07	0.090
132.57	-52.99	0.090
132.59	-52.90	0.091
132.60	-52.82	0.091
132.62	-52.74	0.091
132.64	-52.66	0.091
132.65	-52.57	0.091
132.67	-52.49	0.091
132.69	-52.40	0.091
132.70	-52.32	0.091
132.72	-52.24	0.092
132.74	-52.16	0.092
132.75	-52.07	0.092
132.77	-51.99	0.092
132.79	-51.91	0.092
132.80	-51.82	0.092
132.82	-51.74	0.092
132.84	-51.66	0.093
132.85	-51.58	0.093
132.87	-51.49	0.093
132.89	-51.41	0.093
132.90	-51.32	0.093
132.92	-51.24	0.094
132.94	-51.16	0.094
132.95	-51.07	0.094
132.97	-50.99	0.094
132.99	-50.91	0.094
133.00	-50.82	0.094
133.02	-50.74	0.095
133.04	-50.66	0.095
133.05	-50.58	0.095
133.07	-50.49	0.095
133.09	-50.41	0.095
133.10	-50.33	0.096
133.12	-50.24	0.096
133.14	-50.16	0.096
133.15	-50.08	0.096
133.17	-49.99	0.097
133.19	-49.91	0.097
133.20	-49.83	0.097
133.22	-49.75	0.098
133.24	-49.66	0.098
133.25	-49.58	0.099
133.27	-49.50	0.099
133.29	-49.41	0.099
133.30	-49.33	0.100
133.32	-49.25	0.100
133.34	-49.16	0.101
133.35	-49.08	0.101
133.37	-49.00	0.102
133.39	-48.92	0.102
133.40	-48.83	0.102
133.42	-48.75	0.103
133.44	-48.67	0.103
133.45	-48.58	0.104
133.47	-48.50	0.104
133.49	-48.42	0.105
133.50	-48.34	0.105
133.52	-48.25	0.106
133.54	-48.17	0.107
133.55	-48.09	0.108
133.57	-48.00	0.108
133.59	-47.92	0.109
133.60	-47.84	0.109
133.62	-47.76	0.110
133.64	-47.67	0.111
133.65	-47.59	0.111
133.67	-47.51	0.112
133.69	-47.43	0.113
133.70	-47.34	0.114
133.72	-47.26	0.114
133.74	-47.18	0.116
133.75	-47.10	0.117
133.77	-47.01	0.117
133.79	-46.93	0.118
133.80	-46.85	0.119
133.82	-46.76	0.120
133.84	-46.68	0.121
133.85	-46.60	0.122
133.87	-46.52	0.123
133.89	-46.44	0.124
133.90	-46.35	0.125
133.92	-46.27	0.125
133.94	-46.19	0.126
133.95	-46.10	0.127
133.97	-46.02	0.128
133.99	-45.94	0.129
134.00	-45.86	0.130
134.02	-45.77	0.131
134.04	-45.69	0.132
134.05	-45.61	0.133
134.07	-45.53	0.134
134.09	-45.44	0.134
134.10	-45.36	0.135
134.12	-45.28	0.136
134.14	-45.20	0.136
134.15	-45.11	0.137
134.17	-45.03	0.138
134.19	-44.95	0.138
134.20	-44.86	0.139
134.22	-44.78	0.140
134.24	-44.70	0.140
134.25	-44.62	0.140
134.27	-44.54	0.140
134.29	-44.45	0.140
134.30	-44.37	0.141
134.32	-44.29	0.141
134.34	-44.20	0.141
134.35	-44.12	0.141
134.37	-44.03	0.141
134.39	-43.95	0.141
134.40	-43.87	0.141
134.42	-43.78	0.141
134.44	-43.70	0.141
134.45	-43.62	0.141
134.47	-43.53	0.140
134.49	-43.45	0.140
134.50	-43.37	0.140
134.52	-43.28	0.140
134.54	-43.20	0.139
134.55	-43.12	0.139
134.57	-43.03	0.138
134.59	-42.95	0.137
134.60	-42.86	0.137
134.62	-42.78	0.137
134.64	-42.70	0.136
134.65	-42.61	0.136
134.67	-42.53	0.135
134.69	-42.44	0.135
134.70	-42.36	0.134
134.72	-42.28	0.134
134.74	-42.19	0.133
134.75	-42.11	0.133
134.77	-42.02	0.133
134.79	-41.94	0.133
134.80	-41.86	0.132
134.82	-41.77	0.132
134.84	-41.69	0.132
134.85	-41.61	0.132
134.87	-41.52	0.131
134.89	-41.44	0.131
134.90	-41.36	0.131
134.92	-41.27	0.131
134.94	-41.19	0.131
134.95	-41.10	0.130
134.97	-41.02	0.130
134.99	-40.94	0.130
135.00	-40.85	0.130
135.02	-40.77	0.130
135.04	-40.69	0.130
135.05	-40.60	0.129
135.07	-40.52	0.129
135.09	-40.44	0.129
135.10	-40.35	0.129
135.12	-40.27	0.129
135.14	-40.19	0.129
135.15	-40.10	0.129
135.17	-40.02	0.129
135.19	-39.93	0.129
135.20	-39.85	0.128
135.22	-39.77	0.128
135.24	-39.68	0.128
135.25	-39.60	0.128
135.27	-39.52	0.128
135.29	-39.43	0.128
135.30	-39.35	0.128
135.32	-39.27	0.128
135.34	-39.18	0.128
135.35	-39.10	0.128
135.37	-39.02	0.128
135.39	-38.93	0.128
135.40	-38.85	0.128
135.42	-38.77	0.128
135.44	-38.68	0.128
135.45	-38.60	0.128
135.47	-38.52	0.128
135.49	-38.43	0.128
135.50	-38.35	0.127
135.52	-38.27	0.127
135.54	-38.18	0.127
135.55	-38.10	0.127
135.57	-38.02	0.127
135.59	-37.93	0.127
135.60	-37.85	0.127
135.62	-37.77	0.127
135.64	-37.68	0.127
135.65	-37.60	0.127
135.67	-37.52	0.127
135.69	-37.43	0.127
135.70	-37.35	0.127
135.72	-37.27	0.127
135.74	-37.18	0.127
135.75	-37.10	0.127
135.77	-37.01	0.127
135.79	-36.93	0.127
135.80	-36.85	0.127
135.82	-36.76	0.127
135.84	-36.68	0.127
135.85	-36.60	0.127
135.87	-36.51	0.127
135.89	-36.43	0.127
135.90	-36.35	0.127
135.92	-36.26	0.127
135.94	-36.18	0.127
135.95	-36.10	0.127
135.97	-36.01	0.127
135.99	-35.93	0.127
136.00	-35.85	0.127
136.02	-35.76	0.127
136.04	-35.68	0.127
136.05	-35.60	0.127
136.07	-35.51	0.127
136.09	-35.43	0.127
136.10	-35.34	0.127
136.12	-35.26	0.127
136.14	-35.18	0.127
136.15	-35.09	0.127
136.17	-35.01	0.127
136.19	-34.93	0.127
136.20	-34.84	0.127
136.22	-34.76	0.127
136.24	-34.68	0.127
136.25	-34.59	0.127
136.27	-34.51	0.127
136.29	-34.42	0.127
136.30	-34.34	0.127
136.32	-34.26	0.127
136.34	-34.18	0.127
136.35	-34.09	0.128
136.37	-34.01	0.128
136.39	-33.93	0.128
136.40	-33.84	0.128
136.42	-33.76	0.128
136.44	-33.67	0.128
136.45	-33.59	0.128
136.47	-33.51	0.128
136.49	-33.43	0.128
136.50	-33.34	0.128
136.52	-33.26	0.128
136.54	-33.17	0.128
136.55	-33.09	0.128
136.57	-33.01	0.128
136.59	-32.92	0.128
136.60	-32.84	0.128
136.62	-32.76	0.128
136.64	-32.67	0.128
136.65	-32.59	0.128
136.67	-32.51	0.128
136.69	-32.42	0.128
136.70	-32.34	0.128
136.72	-32.26	0.128
136.74	-32.17	0.128
136.75	-32.09	0.128
136.77	-32.01	0.128
136.79	-31.92	0.128
136.80	-31.84	0.128
136.82	-31.76	0.128
136.84	-31.67	0.128
136.85	-31.59	0.128
136.87	-31.50	0.128
136.89	-31.42	0.128
136.90	-31.34	0.128
136.92	-31.25	0.128
136.94	-31.17	0.128
136.95	-31.09	0.128
136.97	-31.00	0.128
136.99	-30.92	0.128
137.00	-30.84	0.128
137.02	-30.75	0.128
137.04	-30.67	0.128
137.05	-30.59	0.128
137.07	-30.50	0.128
137.09	-30.42	0.128
137.10	-30.34	0.128
137.12	-30.25	0.128
137.14	-30.17	0.128
137.15	-30.09	0.128
137.17	-30.00	0.128
137.19	-29.92	0.128
137.20	-29.83	0.128
137.22	-29.75	0.128
137.24	-29.67	0.128
137.25	-29.58	0.128
137.27	-29.50	0.128
137.29	-29.42	0.128
137.30	-29.33	0.128
137.32	-29.25	0.128
137.34	-29.17	0.128
137.35	-29.08	0.128
137.37	-29.00	0.128
137.39	-28.92	0.128
137.40	-28.83	0.128
137.42	-28.75	0.128
137.44	-28.67	0.128
137.45	-28.58	0.128
137.47	-28.50	0.128
137.49	-28.42	0.128
137.50	-28.33	0.128
137.52	-28.25	0.128
137.54	-28.17	0.128
137.55	-28.08	0.128
137.57	-28.00	0.128
137.59	-27.91	0.128
137.60	-27.83	0.128
137.62	-27.75	0.128
137.64	-27.66	0.128
137.65	-27.58	0.128
137.67	-27.50	0.128
137.69	-27.41	0.128
137.70	-27.33	0.128
137.72	-27.25	0.128
137.74	-27.16	0.128
137.75	-27.08	0.128
137.77	-27.00	0.128
137.79	-26.91	0.128
137.80	-26.83	0.128
137.82	-26.75	0.128
137.84	-26.66	0.128
137.85	-26.58	0.128
137.87	-26.50	0.128
137.89	-26.41	0.128
137.90	-26.33	0.128
137.92	-26.25	0.128
137.94	-26.16	0.128
137.95	-26.08	0.128
137.97	-26.00	0.128
137.99	-25.91	0.128
138.00	-25.83	0.128
138.02	-25.75	0.128
138.04	-25.66	0.129
138.05	-25.58	0.129
138.07	-25.49	0.129
138.09	-25.41	0.129
138.10	-25.33	0.129
138.12	-25.24	0.129
138.14	-25.16	0.129
138.15	-25.08	0.129
138.17	-25.00	0.129
138.19	-24.91	0.129
138.20	-24.83	0.129
138.22	-24.74	0.129
138.24	-24.66	0.129
138.25	-24.58	0.129
138.27	-24.50	0.129
138.29	-24.41	0.129
138.30	-24.33	0.129
138.32	-24.24	0.129
138.34	-24.16	0.129
138.35	-24.08	0.129
138.37	-23.99	0.129
138.39	-23.91	0.129
138.40	-23.83	0.129
138.42	-23.74	0.129
138.44	-23.66	0.129
138.45	-23.58	0.129
138.47	-23.49	0.129
138.49	-23.41	0.129
138.50	-23.33	0.129
138.52	-23.24	0.129
138.54	-23.16	0.129
138.55	-23.08	0.129
138.57	-22.99	0.129
138.59	-22.91	0.129
138.60	-22.83	0.129
138.62	-22.74	0.129
138.64	-22.66	0.129
138.65	-22.58	0.129
138.67	-22.49	0.129
138.69	-22.41	0.129
138.70	-22.33	0.129
138.72	-22.24	0.129
138.74	-22.16	0.129
138.75	-22.08	0.129
138.77	-21.99	0.129
138.79	-21.91	0.129
138.80	-21.83	0.129
138.82	-21.74	0.129
138.84	-21.66	0.129
138.85	-21.58	0.129
138.87	-21.49	0.129
138.89	-21.41	0.129
138.90	-21.32	0.129
138.92	-21.24	0.129
138.94	-21.16	0.129
138.95	-21.08	0.129
138.97	-20.99	0.129
138.99	-20.91	0.129
139.00	-20.82	0.129
139.02	-20.74	0.129
139.04	-20.66	0.129
139.05	-20.57	0.129
139.07	-20.49	0.129
139.09	-20.41	0.129
139.10	-20.32	0.129
139.12	-20.24	0.129
139.14	-20.16	0.129
139.15	-20.07	0.129
139.17	-19.99	0.129
139.19	-19.91	0.129
139.20	-19.83	0.129
139.22	-19.74	0.129
139.24	-19.66	0.129
139.25	-19.57	0.129
139.27	-19.49	0.129
139.29	-19.41	0.130
139.30	-19.32	0.130
139.32	-19.24	0.130
139.34	-19.16	0.130
139.35	-19.07	0.130
139.37	-18.99	0.130
139.39	-18.91	0.130
139.40	-18.82	0.130
139.42	-18.74	0.130
139.44	-18.66	0.130
139.45	-18.57	0.130
139.47	-18.49	0.130
139.49	-18.41	0.130
139.50	-18.32	0.130
139.52	-18.24	0.130
139.54	-18.15	0.130
139.55	-18.07	0.130
139.57	-17.99	0.130
139.59	-17.91	0.130
139.60	-17.82	0.130
139.62	-17.74	0.130
139.64	-17.65	0.130
139.65	-17.57	0.130
139.67	-17.49	0.130
139.69	-17.41	0.130
139.70	-17.32	0.130
139.72	-17.24	0.130
139.74	-17.15	0.130
139.75	-17.07	0.130
139.77	-16.99	0.130
139.79	-16.91	0.130
139.80	-16.82	0.130
139.82	-16.74	0.130
139.84	-16.65	0.130
139.85	-16.57	0.130
139.87	-16.49	0.130
139.89	-16.40	0.130
139.90	-16.32	0.130
139.92	-16.24	0.130
139.94	-16.15	0.130
139.95	-16.07	0.130
139.97	-15.99	0.130
139.99	-15.90	0.130
140.00	-15.82	0.130
140.02	-15.74	0.130
140.04	-15.65	0.130
140.05	-15.57	0.130
140.07	-15.49	0.130
140.09	-15.40	0.130
140.10	-15.32	0.130
140.12	-15.24	0.130
140.14	-15.15	0.130
140.15	-15.07	0.130
140.17	-14.98	0.130
140.19	-14.90	0.130
140.20	-14.82	0.130
140.22	-14.73	0.130
140.24	-14.65	0.130
140.25	-14.57	0.130
140.27	-14.48	0.130
140.29	-14.40	0.130
140.30	-14.32	0.130
140.32	-14.23	0.130
140.34	-14.15	0.130
140.35	-14.07	0.130
140.37	-13.99	0.130
140.39	-13.90	0.130
140.40	-13.82	0.130
140.42	-13.73	0.130
140.44	-13.65	0.130
140.45	-13.57	0.130
140.47	-13.49	0.130
140.49	-13.40	0.130
140.50	-13.32	0.130
140.52	-13.23	0.130
140.54	-13.15	0.130
140.55	-13.07	0.130
140.57	-12.98	0.130
140.59	-12.90	0.130
140.60	-12.82	0.130
140.62	-12.73	0.130
140.64	-12.65	0.130
140.65	-12.57	0.131
140.67	-12.48	0.131
140.69	-12.40	0.131
140.70	-12.32	0.131
140.72	-12.23	0.131
140.74	-12.15	0.131
140.75	-12.07	0.131
140.77	-11.98	0.131
140.79	-11.90	0.131
140.80	-11.82	0.131
140.82	-11.73	0.131
140.84	-11.65	0.131
140.85	-11.57	0.131
140.87	-11.48	0.131
140.89	-11.40	0.131
140.90	-11.32	0.131
140.92	-11.23	0.131
140.94	-11.15	0.131
140.95	-11.07	0.131
140.97	-10.98	0.131
140.99	-10.90	0.131
141.00	-10.82	0.131
141.02	-10.73	0.131
141.04	-10.65	0.131
141.05	-10.57	0.131
141.07	-10.48	0.131
141.09	-10.40	0.131
141.10	-10.31	0.131
141.12	-10.23	0.131
141.14	-10.15	0.131
141.15	-10.06	0.131
141.17	-9.98	0.131
141.19	-9.90	0.131
141.20	-9.81	0.131
141.22	-9.73	0.131
141.24	-9.65	0.131
141.25	-9.56	0.131
141.27	-9.48	0.131
141.29	-9.40	0.131
141.30	-9.31	0.131
141.32	-9.23	0.131
141.34	-9.15	0.131
141.35	-9.06	0.131
141.37	-8.98	0.131
141.39	-8.90	0.131
141.40	-8.81	0.131
141.42	-8.73	0.131
141.44	-8.65	0.131
141.45	-8.56	0.131
141.47	-8.48	0.131
141.49	-8.40	0.131
141.50	-8.31	0.131
141.52	-8.23	0.131
141.54	-8.15	0.131
141.55	-8.06	0.131
141.57	-7.98	0.131
141.59	-7.90	0.131
141.60	-7.81	0.132
141.62	-7.73	0.132
141.64	-7.65	0.132
141.65	-7.56	0.132
141.67	-7.48	0.132
141.69	-7.40	0.132
141.70	-7.31	0.132
141.72	-7.23	0.132
141.74	-7.15	0.132
141.75	-7.06	0.132
141.77	-6.98	0.132
141.79	-6.90	0.132
141.80	-6.81	0.132
141.82	-6.73	0.132
141.84	-6.64	0.132
141.85	-6.56	0.132
141.87	-6.48	0.132
141.89	-6.39	0.132
141.90	-6.31	0.132
141.92	-6.23	0.132
141.94	-6.14	0.132
141.95	-6.06	0.132
141.97	-5.98	0.132
141.99	-5.89	0.132
142.00	-5.81	0.132
142.02	-5.73	0.132
142.04	-5.64	0.132
142.05	-5.56	0.132
142.07	-5.48	0.132
142.09	-5.39	0.132
142.10	-5.31	0.132
142.12	-5.23	0.132
142.14	-5.14	0.132
142.15	-5.06	0.132
142.17	-4.98	0.132
142.19	-4.89	0.132
142.20	-4.81	0.132
142.22	-4.73	0.132
142.24	-4.64	0.132
142.25	-4.56	0.132
142.27	-4.48	0.132
142.29	-4.39	0.132
142.30	-4.31	0.132
142.32	-4.23	0.132
142.34	-4.14	0.132
142.35	-4.06	0.132
142.37	-3.98	0.132
142.39	-3.89	0.132
142.40	-3.81	0.132
142.42	-3.73	0.132
142.44	-3.64	0.132
142.45	-3.56	0.132
142.47	-3.47	0.132
142.49	-3.39	0.132
142.50	-3.31	0.132
142.52	-3.23	0.132
142.54	-3.14	0.132
142.55	-3.06	0.132
142.57	-2.98	0.133
142.59	-2.89	0.133
142.60	-2.81	0.133
142.62	-2.73	0.133
142.64	-2.64	0.133
142.65	-2.56	0.133
142.67	-2.47	0.133
142.69	-2.39	0.133
142.70	-2.31	0.133
142.72	-2.22	0.133
142.74	-2.14	0.133
142.75	-2.06	0.133
142.77	-1.97	0.133
142.79	-1.89	0.133
142.80	-1.81	0.133
142.82	-1.72	0.133
142.84	-1.64	0.133
142.85	-1.56	0.133
142.87	-1.47	0.133
142.89	-1.39	0.133
142.90	-1.31	0.133
142.92	-1.22	0.133
142.94	-1.14	0.133
142.95	-1.06	0.133
142.97	-0.97	0.133
142.99	-0.89	0.133
143.00	-0.81	0.133
143.02	-0.72	0.133
143.04	-0.64	0.133
143.05	-0.56	0.133
143.07	-0.47	0.133
143.09	-0.39	0.133
143.10	-0.31	0.133
143.12	-0.22	0.133
143.14	-0.14	0.133
143.15	-0.05	0.133
143.17	0.03	0.133
143.19	0.11	0.133
143.20	0.20	0.133
143.22	0.28	0.133
143.24	0.36	0.133
143.25	0.45	0.133
143.27	0.53	0.133
143.29	0.61	0.133
143.30	0.70	0.133
143.32	0.78	0.133
143.34	0.86	0.133
143.35	0.95	0.133
143.37	1.03	0.133
143.39	1.11	0.133
143.40	1.20	0.133
143.42	1.28	0.133
143.44	1.36	0.133
143.45	1.45	0.133
143.47	1.53	0.133
143.49	1.61	0.134
143.50	1.70	0.134
143.52	1.78	0.134
143.54	1.86	0.134
143.55	1.95	0.134
143.57	2.03	0.134
143.59	2.11	0.134
143.60	2.20	0.134
143.62	2.28	0.134
143.64	2.36	0.134
143.65	2.45	0.134
143.67	2.53	0.134
143.69	2.61	0.134
143.70	2.70	0.134
143.72	2.78	0.134
143.74	2.87	0.134
143.75	2.95	0.134
143.77	3.03	0.134
143.79	3.12	0.134
143.80	3.20	0.134
143.82	3.28	0.134
143.84	3.36	0.134
143.85	3.45	0.134
143.87	3.53	0.134
143.89	3.62	0.134
143.90	3.70	0.134
143.92	3.78	0.134
143.94	3.87	0.134
143.95	3.95	0.134
143.97	4.03	0.134
143.99	4.12	0.134
144.00	4.20	0.134
144.02	4.28	0.134
144.04	4.37	0.134
144.05	4.45	0.134
144.07	4.53	0.134
144.09	4.62	0.134
144.10	4.70	0.134
144.12	4.78	0.134
144.14	4.87	0.134
144.15	4.95	0.134
144.17	5.03	0.134
144.19	5.12	0.134
144.20	5.20	0.134
144.22	5.28	0.134
144.24	5.37	0.134
144.25	5.45	0.134
144.27	5.53	0.134
144.29	5.62	0.134
144.30	5.70	0.134
144.32	5.78	0.134
144.34	5.87	0.134
144.35	5.95	0.134
144.37	6.03	0.135
144.39	6.12	0.135
144.40	6.20	0.135
144.42	6.29	0.135
144.44	6.37	0.135
144.45	6.45	0.135
144.47	6.54	0.135
144.49	6.62	0.135
144.50	6.70	0.135
144.52	6.78	0.135
144.54	6.87	0.135
144.55	6.95	0.135
144.57	7.04	0.135
144.59	7.12	0.135
144.60	7.20	0.135
144.62	7.29	0.135
144.64	7.37	0.135
144.65	7.45	0.135
144.67	7.53	0.135
144.69	7.62	0.135
144.70	7.70	0.135
144.72	7.79	0.135
144.74	7.87	0.135
144.75	7.95	0.135
144.77	8.04	0.135
144.79	8.12	0.135
144.80	8.20	0.135
144.82	8.29	0.135
144.84	8.37	0.135
144.85	8.45	0.135
144.87	8.54	0.135
144.89	8.62	0.135
144.90	8.70	0.135
144.92	8.79	0.135
144.94	8.87	0.135
144.95	8.95	0.135
144.97	9.04	0.135
144.99	9.12	0.135
145.00	9.20	0.135
145.02	9.29	0.135
145.04	9.37	0.135
145.05	9.45	0.135
145.07	9.54	0.135
145.09	9.62	0.135
145.10	9.70	0.135
145.12	9.79	0.135
145.14	9.87	0.135
145.15	9.95	0.135
145.17	10.04	0.135
145.19	10.12	0.135
145.20	10.20	0.135
145.22	10.29	0.135
145.24	10.37	0.135
145.25	10.46	0.135
145.27	10.54	0.135
145.29	10.62	0.136
145.30	10.71	0.136
145.32	10.79	0.136
145.34	10.87	0.136
145.35	10.96	0.136
145.37	11.04	0.136
145.39	11.12	0.136
145.40	11.21	0.136
145.42	11.29	0.136
145.44	11.37	0.136
145.45	11.46	0.136
145.47	11.54	0.136
145.49	11.62	0.136
145.50	11.71	0.136
145.52	11.79	0.136
145.54	11.87	0.136
145.55	11.96	0.136
145.57	12.04	0.136
145.59	12.12	0.136
145.60	12.21	0.136
145.62	12.29	0.136
145.64	12.37	0.136
145.65	12.46	0.136
145.67	12.54	0.136
145.69	12.62	0.136
145.70	12.71	0.136
145.72	12.79	0.136
145.74	12.87	0.136
145.75	12.96	0.136
145.77	13.04	0.136
145.79	13.12	0.136
145.80	13.21	0.136
145.82	13.29	0.136
145.84	13.37	0.136
145.85	13.46	0.136
145.87	13.54	0.136
145.89	13.62	0.136
145.90	13.71	0.136
145.92	13.79	0.136
145.94	13.87	0.136
145.95	13.96	0.136
145.97	14.04	0.136
145.99	14.12	0.136
146.00	14.21	0.136
146.02	14.29	0.136
146.04	14.37	0.136
146.05	14.46	0.136
146.07	14.54	0.136
146.09	14.63	0.136
146.10	14.71	0.137
146.12	14.79	0.137
146.14	14.87	0.137
146.15	14.96	0.137
146.17	15.04	0.137
146.19	15.13	0.137
146.20	15.21	0.137
146.22	15.29	0.137
146.24	15.38	0.137
146.25	15.46	0.137
146.27	15.54	0.137
146.29	15.63	0.137
146.30	15.71	0.137
146.32	15.79	0.137
146.34	15.88	0.137
146.35	15.96	0.137
146.37	16.04	0.137
146.39	16.13	0.137
146.40	16.21	0.137
146.42	16.29	0.137
146.44	16.38	0.137
146.45	16.46	0.137
146.47	16.54	0.137
146.49	16.63	0.137
146.50	16.71	0.137
146.52	16.79	0.137
146.54	16.88	0.137
146.55	16.96	0.137
146.57	17.04	0.137
146.59	17.13	0.137
146.60	17.21	0.137
146.62	17.29	0.137
146.64	17.38	0.137
146.65	17.46	0.137
146.67	17.54	0.137
146.69	17.63	0.137
146.70	17.71	0.137
146.72	17.79	0.137
146.74	17.88	0.137
146.75	17.96	0.137
146.77	18.05	0.137
146.79	18.13	0.137
146.80	18.21	0.138
146.82	18.29	0.138
146.84	18.38	0.138
146.85	18.46	0.138
146.87	18.55	0.138
146.89	18.63	0.138
146.90	18.71	0.138
146.92	18.80	0.138
146.94	18.88	0.138
146.95	18.96	0.138
146.97	19.04	0.138
146.99	19.13	0.138
147.00	19.21	0.138
147.02	19.30	0.138
147.04	19.38	0.138
147.05	19.46	0.138
147.07	19.55	0.138
147.09	19.63	0.138
147.10	19.71	0.138
147.12	19.80	0.138
147.14	19.88	0.138
147.15	19.96	0.138
147.17	20.05	0.138
147.19	20.13	0.138
147.20	20.21	0.138
147.22	20.30	0.138
147.24	20.38	0.138
147.25	20.46	0.138
147.27	20.55	0.138
147.29	20.63	0.138
147.30	20.71	0.138
147.32	20.80	0.138
147.34	20.88	0.138
147.35	20.96	0.138
147.37	21.05	0.138
147.39	21.13	0.138
147.40	21.21	0.138
147.42	21.30	0.138
147.44	21.38	0.138
147.45	21.46	0.138
147.47	21.55	0.138
147.49	21.63	0.138
147.50	21.71	0.139
147.52	21.80	0.139
147.54	21.88	0.139
147.55	21.96	0.139
147.57	22.05	0.139
147.59	22.13	0.139
147.60	22.22	0.139
147.62	22.30	0.139
147.64	22.38	0.139
147.65	22.46	0.139
147.67	22.55	0.139
147.69	22.63	0.139
147.70	22.71	0.139
147.72	22.80	0.139
147.74	22.88	0.139
147.75	22.97	0.139
147.77	23.05	0.139
147.79	23.13	0.139
147.80	23.22	0.139
147.82	23.30	0.139
147.84	23.38	0.139
147.85	23.47	0.139
147.87	23.55	0.139
147.89	23.63	0.139
147.90	23.72	0.139
147.92	23.80	0.139
147.94	23.88	0.139
147.95	23.97	0.139
147.97	24.05	0.139
147.99	24.13	0.139
148.00	24.22	0.139
148.02	24.30	0.139
148.04	24.38	0.139
148.05	24.47	0.139
148.07	24.55	0.139
148.09	24.63	0.139
148.10	24.72	0.139
148.12	24.80	0.139
148.14	24.88	0.139
148.15	24.97	0.139
148.17	25.05	0.139
148.19	25.13	0.139
148.20	25.22	0.139
148.22	25.30	0.139
148.24	25.38	0.139
148.25	25.47	0.139
148.27	25.55	0.139
148.29	25.63	0.139
148.30	25.72	0.139
148.32	25.80	0.139
148.34	25.89	0.140
148.35	25.97	0.140
148.37	26.05	0.140
148.39	26.13	0.140
148.40	26.22	0.140
148.42	26.30	0.140
148.44	26.38	0.140
148.45	26.47	0.140
148.47	26.55	0.140
148.49	26.64	0.140
148.50	26.72	0.140
148.52	26.80	0.140
148.54	26.88	0.140
148.55	26.97	0.140
148.57	27.05	0.140
148.59	27.14	0.140
148.60	27.22	0.140
148.62	27.30	0.140
148.64	27.39	0.140
148.65	27.47	0.140
148.67	27.55	0.140
148.69	27.64	0.140
148.70	27.72	0.140
148.72	27.80	0.140
148.74	27.89	0.140
148.75	27.97	0.140
148.77	28.05	0.140
148.79	28.14	0.140
148.80	28.22	0.140
148.82	28.30	0.140
148.84	28.39	0.140
148.85	28.47	0.140
148.87	28.55	0.140
148.89	28.64	0.140
148.90	28.72	0.140
148.92	28.80	0.140
148.94	28.89	0.140
148.95	28.97
148.97	29.05
148.99	29.14
149.00
149.01