File: DSC/2025_05_20_CBD_Sorbic_Acid_Slurry_n60C_150C_5Cmin_x3.csv
Filename,2025_05_20_CBD_Sorbic_Acid_Slurry_n60C_150C_5Cmin_x3
Instrument name,DSC2A-00468 (192.168.1.100)
Operator,Yarger
rundate,5/21/2025
Sample name,2025_05_20_CBD_Sorbic_Acid_Slurry_n60C_150C_5Cmin_x3
proceduresegments,Data Off ; Equilibrate -60.00 °C; Data On ; Ramp 5.00 °C/min to 150.00 °C; Data Off ; Isothermal 1.0 min; Data On ; Ramp 5.00 °C/min to -60.00 °C; Data Off ; Isothermal 1.0 min; Data On ; Ramp 5.00 °C/min to 150.00 °C; Data Off ; Isothermal 1.0 min; Data On ; Ramp 5.00 °C/min to -60.00 °C; Data Off ; Isothermal 1.0 min; Data On ; Ramp 5.00 °C/min to 30.00 °C
[File Parameters]
Run date,5/21/2025 1:34:51 AM
Trios version,5.1.1.46572
Original File Name,
Current File Name,D:\DSC2500\JYarger\2025_05_20_CBD_Sorbic_Acid_Slurry_n60C_150C_5Cmin_x3.tri
[Procedure]
Procedure Name,CBD_SA_n60C_150C_5Cmin_x3
Sample Name,2025_05_20_CBD_Sorbic_Acid_Slurry_n60C_150C_5Cmin_x3
Sample Mass,5.01 mg
Reference Sample Mass,0 mg
Pan Mass,56.5 mg
Pan Number,39
Reference Pan Mass,57.13 mg
Reference Pan Number,37
Pan Type,Tzero Aluminum Hermetic
Comments,Al Hermetic DSC Consumables sealed Pan/Lid. Y2 Tray (Google Sheet: DSC_Samples_Vext_Y2_Tray_May2025)
Project Name,CA
Operator,Yarger
Test,Custom
Unload Max Temperature,30
Unload Min Temperature,30
Load Max Temperature,30
Load Min Temperature,30
Stop on Gas Flow Error,Yes
[Signal List]
Signal #1,Time (min)
Signal #2,Temperature (°C)
Signal #3,Heat Flow (mW)
Signal #4,Delta T (µV)
Signal #5,Delta Tzero (µV)
Signal #6,Tzero Temperature (°C)
Signal #7,Cell Purge (mL/min)
Signal #8,Heater Temp (°C)
Signal #9,Power Delivered (W)
Signal #10,Reference Junction Temperature (°C)
Signal #11,Flange Temperature (°C)
Signal #12,Heat Flow Phase (rad)
Signal #13,Total Heat Capacity (J/°C)
Signal #14,Heat Capacity (J/°C)
[Configuration]
Company Name,ASU
Instrument Name,DSC2A-00468
Instrument Type,DSC2500
Serial Number,DSC2A-00468
IP,192.168.1.100
Location of Instrument,MRRC
DisplayType,Unknown
Sample Interval ,0.1 s/pt
Selected Heat Flow,T4P
Exotherm Direction,Down
Cell Serial,DRC2-00792
Lid Type,Standard
Cooler,RCS 90
Leave Cooler on at End of Sequence,On
Gas 2,Nitrogen
Gas Selected,Channel 1
Flow Rate,50 mL/min
Secondary Purge,On
Licensed Heat Flow,Heat Flow T4P
Modulation Licensed,Yes
[Versions]
Common IDD Version,1
Cortex Version,VER 2.10.2.31
Driver,5.0.0.6
GDM Version,1.0.3.3
TouchscreenVersion,1.0.0.16145
FEP Version,1.2.1.21
FEP Bootloader,2.0.0.5
AutoSampler Version,2.1.1.26
Auto Sampler Bootloader,2.0.0.5
FCM Version,1.1.0.3
FCM Bootloader,2.0.0.5
[Experiment Logs]
Experiment Log Entry # 1,Data On set to 0
Experiment Log Entry # 3,Equilibrate Segment -60 (C) Started
Experiment Log Entry # 5,Air Cool is off.
Experiment Log Entry # 7,Data On set to 1
Experiment Log Entry # 9,Ramp Segment 5 C/min to 150 Started
Experiment Log Entry # 11,Data On set to 0
Experiment Log Entry # 13,Isothermal Segment 1 min started
Experiment Log Entry # 15,Data On set to 1
Experiment Log Entry # 17,Ramp Segment 5 C/min to -60 Started
Experiment Log Entry # 19,Data On set to 0
Experiment Log Entry # 21,Isothermal Segment 1 min started
Experiment Log Entry # 23,Data On set to 1
Experiment Log Entry # 25,Ramp Segment 5 C/min to 150 Started
Experiment Log Entry # 27,FEP has detected that Cortex has gone offline
Experiment Log Entry # 29,Data On set to 0
Experiment Log Entry # 31,Isothermal Segment 1 min started
Experiment Log Entry # 33,Data On set to 1
Experiment Log Entry # 35,Ramp Segment 5 C/min to -60 Started
Experiment Log Entry # 37,Data On set to 0
Experiment Log Entry # 39,Isothermal Segment 1 min started
Experiment Log Entry # 41,Data On set to 1
Experiment Log Entry # 43,Ramp Segment 5 C/min to 30 Started
[Method Log]
Method Log Entry # 1,Data Off
Method Log Entry # 2,Equilibrate -60 °C
Method Log Entry # 3,Data On
Method Log Entry # 4,(Ramp 131260) Ramp 5 °C/minute to 150 °C
Method Log Entry # 5,Data Off
Method Log Entry # 6,Isothermal 1 minutes
Method Log Entry # 7,Data On
Method Log Entry # 8,(Ramp 131264) Ramp 5 °C/minute to -60 °C
Method Log Entry # 9,Data Off
Method Log Entry # 10,Isothermal 1 minutes
Method Log Entry # 11,Data On
Method Log Entry # 12,(Ramp 131268) Ramp 5 °C/minute to 150 °C
Method Log Entry # 13,Data Off
Method Log Entry # 14,Isothermal 1 minutes
Method Log Entry # 15,Data On
Method Log Entry # 16,(Ramp 131272) Ramp 5 °C/minute to -60 °C
Method Log Entry # 17,Data Off
Method Log Entry # 18,Isothermal 1 minutes
Method Log Entry # 19,Data On
Method Log Entry # 20,(Ramp 131276) Ramp 5 °C/minute to 30 °C
Cell Serial,DRC2-00792
[T1 Calibration]
Slope,-0.008529666
Offset,9.636258
Initial Temperature,98.23
GUID,f8bfdadc-4977-4fdf-ba6d-0ba9134940c3
[TZero Calibration]
Date Applied,11/29/2022 4:06:13 PM
Description,From -89.059 °C to 396.009 °C at 20.000°C/min
Gas Type,Nitrogen
Pan Type,None
Source Files 1,C:\Users\yargerlab\Desktop\DSC Data\General\TZero_calibration_11_29_22_2nd(2).tri
Source Files 2,C:\Users\yargerlab\Desktop\DSC Data\General\TZero_calibration_11_29_22_2nd(3).tri
Delta T Offset,13.05235
Delta T Slope,-0.007271007
Delta T0 Offset,-13.69128
Delta T0 Slope,0.06063341
[Temperature Calibration]
Date Applied,11/29/2022 7:12:28 PM
Description,From 106.590 °C to 186.590 °C at 10.000°C/min
Gas Type,Nitrogen
Pan Type,Tzero Aluminum Hermetic
Source Files 1,C:\Users\yargerlab\Desktop\DSC Data\General\Indium(6).tri
Measured 1,157.391
Known 1,156.598
[Cell Constant Calibration]
Date Applied,11/29/2022 7:12:29 PM
Description,From 106.590 °C to 186.590 °C at 10.000°C/min
Gas Type,Nitrogen
Pan Type,Tzero Aluminum Hermetic
Source Files 1,C:\Users\yargerlab\Desktop\DSC Data\General\Indium(6).tri
T4P KCell,1.006051
Onset Slope,63.26126 mW/°C
[Direct Cp Calibration]
Date Applied,11/30/2022 11:04:51 AM
Description,From -79.983 °C to 298.409 °C at 10.000°C/min
Gas Type,Nitrogen
Pan Type,Tzero Aluminum Hermetic
Source Files 1,C:\Users\yargerlab\Desktop\DSC Data\General\Sapphire_Heat_Capacity_11_30_22.tri
[Rev Cp Calibration]
Date Applied,11/30/2022 1:58:51 PM
Description,From -79.996 °C to 292.812 °C at 3.000°C/min
Gas Type,Nitrogen
Pan Type,Tzero Aluminum Hermetic
Source Files 1,C:\Users\yargerlab\Desktop\DSC Data\General\Sapphire_MDSC_Calibration_11_30_22.tri
[step]
Ramp 5.00 °C/min to 150.00 °C
Time,Temperature,Heat Flow (Normalized)
min,°C,W/g
0.00,-59.67,-0.061
0.03,-59.69,-0.060
0.06,-59.70,-0.050
0.08,-59.67,-0.037
0.11,-59.62,-0.021
0.14,-59.55,-0.005
0.17,-59.45,0.011
0.20,-59.35,0.024
0.23,-59.24,0.037
0.26,-59.13,0.048
0.28,-59.01,0.057
0.31,-58.89,0.065
0.34,-58.77,0.071
0.37,-58.64,0.076
0.40,-58.51,0.080
0.43,-58.38,0.083
0.45,-58.25,0.086
0.48,-58.12,0.090
0.51,-57.98,0.090
0.54,-57.85,0.092
0.57,-57.71,0.093
0.60,-57.58,0.094
0.62,-57.44,0.095
0.65,-57.30,0.095
0.68,-57.17,0.096
0.71,-57.03,0.097
0.74,-56.89,0.097
0.77,-56.75,0.098
0.79,-56.61,0.098
0.82,-56.47,0.099
0.85,-56.33,0.099
0.88,-56.19,0.100
0.91,-56.06,0.100
0.93,-55.92,0.101
0.96,-55.78,0.101
0.99,-55.64,0.101
1.02,-55.50,0.101
1.05,-55.36,0.102
1.08,-55.22,0.102
1.11,-55.08,0.102
1.13,-54.94,0.102
1.16,-54.80,0.102
1.19,-54.65,0.103
1.22,-54.52,0.103
1.25,-54.38,0.103
1.28,-54.23,0.103
1.30,-54.09,0.103
1.33,-53.95,0.103
1.36,-53.81,0.103
1.39,-53.67,0.103
1.42,-53.53,0.103
1.44,-53.39,0.103
1.47,-53.25,0.103
1.50,-53.11,0.104
1.53,-52.97,0.104
1.56,-52.83,0.104
1.59,-52.68,0.104
1.62,-52.54,0.104
1.64,-52.40,0.104
1.67,-52.26,0.104
1.70,-52.12,0.104
1.73,-51.98,0.104
1.76,-51.84,0.104
1.78,-51.69,0.104
1.81,-51.55,0.104
1.84,-51.41,0.104
1.87,-51.27,0.104
1.90,-51.13,0.104
1.93,-50.99,0.104
1.96,-50.84,0.104
1.98,-50.71,0.104
2.01,-50.56,0.104
2.04,-50.42,0.104
2.07,-50.28,0.104
2.10,-50.14,0.104
2.13,-50.00,0.104
2.15,-49.86,0.104
2.18,-49.71,0.104
2.21,-49.57,0.104
2.24,-49.43,0.104
2.27,-49.29,0.104
2.29,-49.15,0.104
2.32,-49.01,0.104
2.35,-48.86,0.104
2.38,-48.72,0.104
2.41,-48.58,0.104
2.44,-48.44,0.104
2.46,-48.30,0.104
2.49,-48.16,0.104
2.52,-48.02,0.104
2.55,-47.87,0.104
2.58,-47.73,0.104
2.61,-47.59,0.104
2.64,-47.45,0.104
2.66,-47.31,0.104
2.69,-47.17,0.104
2.72,-47.03,0.104
2.75,-46.88,0.104
2.78,-46.74,0.104
2.81,-46.60,0.104
2.83,-46.46,0.104
2.86,-46.32,0.104
2.89,-46.18,0.104
2.92,-46.04,0.104
2.95,-45.89,0.104
2.98,-45.75,0.104
3.00,-45.61,0.104
3.03,-45.47,0.104
3.06,-45.33,0.104
3.09,-45.19,0.104
3.12,-45.04,0.104
3.14,-44.90,0.104
3.17,-44.76,0.104
3.20,-44.62,0.104
3.23,-44.48,0.104
3.26,-44.33,0.104
3.29,-44.19,0.104
3.31,-44.05,0.104
3.34,-43.91,0.104
3.37,-43.77,0.104
3.40,-43.63,0.104
3.43,-43.49,0.104
3.46,-43.34,0.104
3.49,-43.20,0.104
3.51,-43.06,0.104
3.54,-42.92,0.104
3.57,-42.78,0.104
3.60,-42.63,0.104
3.63,-42.49,0.104
3.66,-42.35,0.104
3.68,-42.21,0.104
3.71,-42.07,0.104
3.74,-41.93,0.104
3.77,-41.79,0.104
3.80,-41.65,0.104
3.83,-41.51,0.104
3.85,-41.37,0.104
3.88,-41.22,0.104
3.91,-41.08,0.104
3.94,-40.94,0.104
3.97,-40.80,0.104
3.99,-40.66,0.104
4.02,-40.52,0.104
4.05,-40.37,0.104
4.08,-40.23,0.104
4.11,-40.09,0.104
4.14,-39.95,0.104
4.16,-39.80,0.104
4.19,-39.66,0.104
4.22,-39.52,0.104
4.25,-39.38,0.104
4.28,-39.23,0.105
4.31,-39.09,0.105
4.34,-38.95,0.105
4.36,-38.81,0.105
4.39,-38.67,0.105
4.42,-38.52,0.105
4.45,-38.38,0.105
4.48,-38.24,0.105
4.50,-38.10,0.105
4.53,-37.96,0.105
4.56,-37.81,0.105
4.59,-37.67,0.105
4.62,-37.53,0.105
4.65,-37.39,0.105
4.68,-37.25,0.105
4.70,-37.10,0.105
4.73,-36.96,0.105
4.76,-36.82,0.105
4.79,-36.68,0.105
4.82,-36.54,0.105
4.85,-36.39,0.105
4.87,-36.25,0.105
4.90,-36.11,0.105
4.93,-35.97,0.105
4.96,-35.83,0.105
4.99,-35.68,0.105
5.01,-35.54,0.105
5.04,-35.40,0.105
5.07,-35.26,0.105
5.10,-35.12,0.105
5.13,-34.98,0.105
5.16,-34.83,0.105
5.19,-34.69,0.105
5.21,-34.55,0.105
5.24,-34.41,0.105
5.27,-34.26,0.105
5.30,-34.12,0.105
5.33,-33.98,0.106
5.35,-33.84,0.106
5.38,-33.70,0.106
5.41,-33.56,0.106
5.44,-33.41,0.106
5.47,-33.27,0.106
5.50,-33.13,0.106
5.53,-32.99,0.106
5.55,-32.85,0.106
5.58,-32.71,0.106
5.61,-32.56,0.106
5.64,-32.42,0.106
5.67,-32.28,0.106
5.70,-32.14,0.106
5.72,-32.00,0.106
5.75,-31.85,0.106
5.78,-31.71,0.106
5.81,-31.57,0.106
5.84,-31.43,0.106
5.86,-31.28,0.106
5.89,-31.14,0.106
5.92,-31.00,0.106
5.95,-30.86,0.106
5.98,-30.72,0.106
6.01,-30.58,0.106
6.04,-30.44,0.106
6.06,-30.29,0.106
6.09,-30.15,0.106
6.12,-30.01,0.106
6.15,-29.87,0.106
6.18,-29.73,0.106
6.20,-29.59,0.107
6.23,-29.44,0.107
6.26,-29.30,0.106
6.29,-29.16,0.107
6.32,-29.02,0.107
6.35,-28.88,0.107
6.38,-28.73,0.107
6.40,-28.59,0.107
6.43,-28.45,0.107
6.46,-28.31,0.107
6.49,-28.17,0.107
6.52,-28.02,0.107
6.55,-27.88,0.107
6.57,-27.74,0.107
6.60,-27.60,0.107
6.63,-27.46,0.107
6.66,-27.32,0.107
6.69,-27.17,0.107
6.71,-27.03,0.107
6.74,-26.89,0.107
6.77,-26.75,0.107
6.80,-26.61,0.107
6.83,-26.46,0.107
6.86,-26.32,0.107
6.89,-26.18,0.108
6.91,-26.04,0.108
6.94,-25.90,0.108
6.97,-25.76,0.108
7.00,-25.62,0.108
7.03,-25.47,0.108
7.05,-25.33,0.108
7.08,-25.19,0.108
7.11,-25.05,0.108
7.14,-24.90,0.108
7.17,-24.76,0.108
7.20,-24.62,0.108
7.23,-24.48,0.108
7.25,-24.34,0.108
7.28,-24.20,0.108
7.31,-24.05,0.108
7.34,-23.91,0.108
7.37,-23.77,0.108
7.40,-23.63,0.108
7.42,-23.49,0.108
7.45,-23.35,0.108
7.48,-23.20,0.108
7.51,-23.06,0.108
7.54,-22.92,0.108
7.56,-22.78,0.108
7.59,-22.64,0.108
7.62,-22.49,0.108
7.65,-22.35,0.108
7.68,-22.21,0.109
7.71,-22.07,0.108
7.74,-21.93,0.109
7.76,-21.79,0.109
7.79,-21.64,0.109
7.82,-21.50,0.109
7.85,-21.36,0.109
7.88,-21.22,0.109
7.90,-21.08,0.109
7.93,-20.94,0.109
7.96,-20.79,0.109
7.99,-20.65,0.109
8.02,-20.51,0.109
8.05,-20.37,0.109
8.08,-20.23,0.109
8.10,-20.08,0.109
8.13,-19.94,0.109
8.16,-19.80,0.109
8.19,-19.66,0.109
8.22,-19.52,0.109
8.25,-19.38,0.109
8.27,-19.23,0.109
8.30,-19.09,0.109
8.33,-18.95,0.109
8.36,-18.81,0.109
8.39,-18.67,0.109
8.41,-18.53,0.109
8.44,-18.38,0.109
8.47,-18.24,0.109
8.50,-18.10,0.109
8.53,-17.96,0.109
8.56,-17.82,0.109
8.58,-17.68,0.109
8.61,-17.53,0.109
8.64,-17.39,0.109
8.67,-17.25,0.109
8.70,-17.11,0.109
8.73,-16.97,0.110
8.75,-16.82,0.110
8.78,-16.68,0.110
8.81,-16.54,0.110
8.84,-16.39,0.110
8.87,-16.25,0.110
8.90,-16.11,0.110
8.93,-15.97,0.110
8.95,-15.83,0.110
8.98,-15.68,0.110
9.01,-15.54,0.110
9.04,-15.40,0.110
9.07,-15.26,0.110
9.10,-15.12,0.110
9.12,-14.98,0.110
9.15,-14.84,0.110
9.18,-14.69,0.110
9.21,-14.55,0.110
9.24,-14.41,0.110
9.27,-14.27,0.110
9.29,-14.13,0.110
9.32,-13.99,0.110
9.35,-13.84,0.110
9.38,-13.70,0.110
9.41,-13.56,0.110
9.43,-13.42,0.110
9.46,-13.28,0.110
9.49,-13.14,0.110
9.52,-12.99,0.110
9.55,-12.85,0.110
9.58,-12.71,0.110
9.60,-12.57,0.110
9.63,-12.43,0.110
9.66,-12.28,0.110
9.69,-12.14,0.110
9.72,-12.00,0.110
9.75,-11.86,0.110
9.78,-11.72,0.110
9.80,-11.58,0.110
9.83,-11.43,0.110
9.86,-11.29,0.111
9.89,-11.15,0.111
9.92,-11.01,0.111
9.95,-10.87,0.111
9.97,-10.73,0.111
10.00,-10.58,0.111
10.03,-10.44,0.111
10.06,-10.30,0.111
10.09,-10.16,0.111
10.12,-10.02,0.111
10.14,-9.88,0.111
10.17,-9.73,0.111
10.20,-9.59,0.111
10.23,-9.45,0.111
10.26,-9.31,0.111
10.28,-9.17,0.111
10.31,-9.02,0.111
10.34,-8.88,0.111
10.37,-8.74,0.111
10.40,-8.60,0.111
10.43,-8.46,0.111
10.45,-8.32,0.111
10.48,-8.17,0.111
10.51,-8.03,0.111
10.54,-7.89,0.111
10.57,-7.75,0.112
10.60,-7.61,0.112
10.63,-7.47,0.112
10.65,-7.32,0.112
10.68,-7.18,0.112
10.71,-7.04,0.112
10.74,-6.90,0.112
10.77,-6.76,0.112
10.80,-6.62,0.112
10.82,-6.47,0.112
10.85,-6.33,0.112
10.88,-6.19,0.112
10.91,-6.05,0.112
10.94,-5.91,0.112
10.97,-5.76,0.112
10.99,-5.62,0.112
11.02,-5.48,0.112
11.05,-5.34,0.112
11.08,-5.20,0.112
11.11,-5.06,0.112
11.13,-4.92,0.112
11.16,-4.77,0.112
11.19,-4.63,0.112
11.22,-4.49,0.112
11.25,-4.35,0.112
11.28,-4.21,0.112
11.30,-4.06,0.113
11.33,-3.92,0.113
11.36,-3.78,0.113
11.39,-3.64,0.113
11.42,-3.50,0.113
11.45,-3.35,0.113
11.48,-3.21,0.113
11.50,-3.07,0.113
11.53,-2.93,0.113
11.56,-2.79,0.113
11.59,-2.65,0.113
11.62,-2.50,0.113
11.65,-2.36,0.113
11.67,-2.22,0.113
11.70,-2.08,0.113
11.73,-1.94,0.113
11.76,-1.79,0.113
11.79,-1.65,0.113
11.82,-1.51,0.113
11.84,-1.37,0.113
11.87,-1.23,0.113
11.90,-1.08,0.113
11.93,-0.94,0.113
11.96,-0.80,0.113
11.98,-0.66,0.113
12.01,-0.52,0.113
12.04,-0.38,0.114
12.07,-0.23,0.114
12.10,-0.09,0.114
12.13,0.05,0.114
12.15,0.19,0.114
12.18,0.33,0.114
12.21,0.47,0.114
12.24,0.61,0.114
12.27,0.76,0.114
12.30,0.90,0.114
12.33,1.04,0.114
12.35,1.18,0.114
12.38,1.33,0.114
12.41,1.47,0.114
12.44,1.61,0.114
12.47,1.75,0.114
12.50,1.89,0.114
12.52,2.03,0.114
12.55,2.18,0.114
12.58,2.32,0.114
12.61,2.46,0.114
12.64,2.60,0.114
12.67,2.74,0.114
12.69,2.89,0.114
12.72,3.03,0.114
12.75,3.17,0.114
12.78,3.31,0.114
12.81,3.45,0.115
12.83,3.59,0.115
12.86,3.73,0.115
12.89,3.88,0.115
12.92,4.02,0.115
12.95,4.16,0.115
12.98,4.30,0.115
13.00,4.44,0.115
13.03,4.58,0.115
13.06,4.73,0.115
13.09,4.87,0.115
13.12,5.01,0.115
13.15,5.15,0.115
13.18,5.29,0.115
13.20,5.44,0.115
13.23,5.58,0.115
13.26,5.72,0.115
13.29,5.86,0.115
13.32,6.00,0.115
13.35,6.14,0.115
13.37,6.29,0.115
13.40,6.43,0.115
13.43,6.57,0.115
13.46,6.71,0.115
13.49,6.85,0.115
13.52,6.99,0.115
13.54,7.14,0.116
13.57,7.28,0.116
13.60,7.42,0.116
13.63,7.56,0.116
13.66,7.70,0.116
13.68,7.85,0.116
13.71,7.99,0.116
13.74,8.13,0.116
13.77,8.27,0.116
13.80,8.41,0.116
13.83,8.56,0.116
13.85,8.70,0.116
13.88,8.84,0.116
13.91,8.98,0.116
13.94,9.12,0.116
13.97,9.26,0.116
14.00,9.41,0.116
14.03,9.55,0.117
14.05,9.69,0.117
14.08,9.83,0.117
14.11,9.98,0.117
14.14,10.12,0.117
14.17,10.26,0.117
14.20,10.40,0.117
14.22,10.54,0.117
14.25,10.68,0.117
14.28,10.82,0.117
14.31,10.97,0.117
14.34,11.11,0.117
14.37,11.25,0.117
14.39,11.39,0.117
14.42,11.53,0.117
14.45,11.68,0.117
14.48,11.82,0.117
14.51,11.96,0.117
14.53,12.10,0.117
14.56,12.24,0.117
14.59,12.38,0.117
14.62,12.53,0.118
14.65,12.67,0.118
14.68,12.81,0.118
14.70,12.95,0.118
14.73,13.09,0.118
14.76,13.23,0.118
14.79,13.38,0.118
14.82,13.52,0.118
14.85,13.66,0.118
14.88,13.80,0.118
14.90,13.94,0.118
14.93,14.08,0.118
14.96,14.23,0.118
14.99,14.37,0.118
15.02,14.51,0.118
15.05,14.65,0.118
15.07,14.79,0.118
15.10,14.93,0.118
15.13,15.08,0.118
15.16,15.22,0.118
15.19,15.36,0.118
15.22,15.50,0.119
15.24,15.64,0.119
15.27,15.78,0.119
15.30,15.93,0.119
15.33,16.07,0.119
15.36,16.21,0.119
15.38,16.35,0.119
15.41,16.50,0.119
15.44,16.64,0.119
15.47,16.78,0.119
15.50,16.92,0.119
15.53,17.06,0.119
15.55,17.20,0.119
15.58,17.35,0.119
15.61,17.49,0.119
15.64,17.63,0.119
15.67,17.77,0.119
15.70,17.91,0.119
15.73,18.05,0.119
15.75,18.20,0.119
15.78,18.34,0.120
15.81,18.48,0.120
15.84,18.62,0.120
15.87,18.76,0.120
15.90,18.90,0.120
15.92,19.05,0.120
15.95,19.19,0.120
15.98,19.33,0.120
16.01,19.47,0.120
16.04,19.61,0.120
16.07,19.75,0.120
16.09,19.90,0.120
16.12,20.04,0.120
16.15,20.18,0.120
16.18,20.32,0.120
16.21,20.46,0.120
16.23,20.61,0.120
16.26,20.75,0.120
16.29,20.89,0.120
16.32,21.03,0.120
16.35,21.17,0.121
16.38,21.31,0.121
16.40,21.46,0.121
16.43,21.60,0.121
16.46,21.74,0.121
16.49,21.88,0.121
16.52,22.02,0.121
16.55,22.16,0.121
16.58,22.31,0.121
16.60,22.45,0.121
16.63,22.59,0.121
16.66,22.73,0.121
16.69,22.87,0.121
16.72,23.02,0.121
16.75,23.16,0.121
16.77,23.30,0.121
16.80,23.44,0.122
16.83,23.58,0.122
16.86,23.72,0.122
16.89,23.87,0.122
16.92,24.01,0.122
16.94,24.15,0.122
16.97,24.29,0.122
17.00,24.43,0.122
17.03,24.57,0.122
17.06,24.72,0.122
17.08,24.86,0.122
17.11,25.00,0.122
17.14,25.14,0.122
17.17,25.28,0.122
17.20,25.43,0.122
17.23,25.57,0.122
17.26,25.71,0.122
17.28,25.85,0.122
17.31,25.99,0.123
17.34,26.13,0.123
17.37,26.28,0.123
17.40,26.42,0.123
17.43,26.56,0.123
17.45,26.70,0.123
17.48,26.84,0.123
17.51,26.98,0.123
17.54,27.13,0.123
17.57,27.27,0.123
17.59,27.41,0.123
17.62,27.55,0.123
17.65,27.69,0.123
17.68,27.84,0.123
17.71,27.98,0.123
17.74,28.12,0.123
17.77,28.26,0.123
17.79,28.40,0.123
17.82,28.54,0.123
17.85,28.69,0.123
17.88,28.83,0.123
17.91,28.97,0.124
17.93,29.11,0.124
17.96,29.25,0.124
17.99,29.39,0.124
18.02,29.54,0.124
18.05,29.68,0.124
18.08,29.82,0.124
18.11,29.96,0.124
18.13,30.10,0.124
18.16,30.25,0.124
18.19,30.39,0.124
18.22,30.53,0.124
18.25,30.67,0.124
18.28,30.81,0.124
18.30,30.95,0.124
18.33,31.10,0.124
18.36,31.24,0.124
18.39,31.38,0.124
18.42,31.52,0.124
18.44,31.66,0.125
18.47,31.81,0.125
18.50,31.95,0.125
18.53,32.09,0.125
18.56,32.23,0.125
18.59,32.37,0.125
18.62,32.52,0.125
18.64,32.66,0.125
18.67,32.80,0.125
18.70,32.94,0.125
18.73,33.08,0.125
18.76,33.22,0.125
18.78,33.37,0.125
18.81,33.51,0.125
18.84,33.65,0.125
18.87,33.79,0.125
18.90,33.93,0.125
18.93,34.07,0.125
18.96,34.21,0.125
18.98,34.36,0.125
19.01,34.50,0.125
19.04,34.64,0.126
19.07,34.78,0.126
19.10,34.92,0.126
19.13,35.06,0.126
19.15,35.21,0.126
19.18,35.35,0.126
19.21,35.49,0.126
19.24,35.63,0.126
19.27,35.78,0.126
19.29,35.92,0.126
19.32,36.06,0.126
19.35,36.20,0.126
19.38,36.34,0.126
19.41,36.48,0.126
19.44,36.62,0.126
19.47,36.77,0.126
19.49,36.91,0.126
19.52,37.05,0.126
19.55,37.19,0.126
19.58,37.33,0.127
19.61,37.48,0.127
19.63,37.62,0.127
19.66,37.76,0.127
19.69,37.90,0.127
19.72,38.04,0.127
19.75,38.18,0.127
19.78,38.33,0.127
19.81,38.47,0.127
19.83,38.61,0.127
19.86,38.75,0.127
19.89,38.89,0.127
19.92,39.03,0.127
19.95,39.18,0.127
19.98,39.32,0.127
20.00,39.46,0.127
20.03,39.60,0.127
20.06,39.74,0.127
20.09,39.89,0.127
20.12,40.03,0.128
20.14,40.17,0.128
20.17,40.31,0.128
20.20,40.45,0.128
20.23,40.59,0.128
20.26,40.74,0.128
20.29,40.88,0.128
20.32,41.02,0.128
20.34,41.16,0.128
20.37,41.30,0.128
20.40,41.45,0.128
20.43,41.59,0.128
20.46,41.73,0.128
20.48,41.87,0.128
20.51,42.01,0.128
20.54,42.15,0.128
20.57,42.30,0.128
20.60,42.44,0.128
20.63,42.58,0.128
20.66,42.72,0.129
20.68,42.86,0.129
20.71,43.00,0.129
20.74,43.15,0.129
20.77,43.29,0.129
20.80,43.43,0.129
20.83,43.57,0.129
20.85,43.71,0.129
20.88,43.85,0.129
20.91,44.00,0.129
20.94,44.14,0.129
20.97,44.28,0.129
20.99,44.42,0.129
21.02,44.56,0.129
21.05,44.71,0.129
21.08,44.85,0.129
21.11,44.99,0.129
21.14,45.13,0.130
21.17,45.27,0.130
21.19,45.41,0.130
21.22,45.56,0.130
21.25,45.70,0.130
21.28,45.84,0.130
21.31,45.98,0.130
21.33,46.12,0.130
21.36,46.26,0.130
21.39,46.41,0.130
21.42,46.55,0.130
21.45,46.69,0.130
21.48,46.83,0.130
21.51,46.97,0.130
21.53,47.12,0.130
21.56,47.26,0.130
21.59,47.40,0.130
21.62,47.54,0.131
21.65,47.68,0.131
21.68,47.82,0.131
21.70,47.97,0.131
21.73,48.11,0.131
21.76,48.25,0.131
21.79,48.39,0.131
21.82,48.53,0.131
21.84,48.67,0.131
21.87,48.82,0.131
21.90,48.96,0.131
21.93,49.10,0.131
21.96,49.24,0.131
21.99,49.38,0.131
22.02,49.53,0.131
22.04,49.67,0.131
22.07,49.81,0.131
22.10,49.95,0.131
22.13,50.09,0.132
22.16,50.24,0.132
22.18,50.38,0.132
22.21,50.52,0.132
22.24,50.66,0.132
22.27,50.80,0.132
22.30,50.94,0.132
22.33,51.09,0.132
22.36,51.23,0.132
22.38,51.37,0.132
22.41,51.51,0.132
22.44,51.65,0.132
22.47,51.80,0.132
22.50,51.94,0.132
22.53,52.08,0.132
22.55,52.22,0.132
22.58,52.36,0.132
22.61,52.50,0.133
22.64,52.65,0.133
22.67,52.79,0.133
22.69,52.93,0.133
22.72,53.07,0.133
22.75,53.21,0.133
22.78,53.35,0.133
22.81,53.50,0.133
22.84,53.64,0.133
22.87,53.78,0.133
22.89,53.92,0.133
22.92,54.06,0.133
22.95,54.20,0.133
22.98,54.34,0.133
23.01,54.49,0.133
23.03,54.63,0.133
23.06,54.77,0.133
23.09,54.91,0.133
23.12,55.05,0.133
23.15,55.19,0.133
23.18,55.34,0.133
23.21,55.48,0.133
23.23,55.62,0.133
23.26,55.76,0.134
23.29,55.90,0.134
23.32,56.05,0.134
23.35,56.19,0.134
23.38,56.33,0.134
23.40,56.47,0.134
23.43,56.61,0.134
23.46,56.75,0.134
23.49,56.90,0.134
23.52,57.04,0.134
23.54,57.18,0.134
23.57,57.32,0.134
23.60,57.46,0.134
23.63,57.61,0.134
23.66,57.75,0.134
23.69,57.89,0.134
23.72,58.03,0.134
23.74,58.17,0.134
23.77,58.31,0.134
23.80,58.45,0.134
23.83,58.60,0.135
23.86,58.74,0.135
23.88,58.88,0.135
23.91,59.02,0.135
23.94,59.16,0.135
23.97,59.30,0.135
24.00,59.45,0.135
24.03,59.59,0.135
24.06,59.73,0.135
24.08,59.87,0.135
24.11,60.01,0.135
24.14,60.16,0.135
24.17,60.30,0.135
24.20,60.44,0.135
24.23,60.58,0.135
24.25,60.72,0.135
24.28,60.86,0.135
24.31,61.01,0.135
24.34,61.15,0.135
24.37,61.29,0.135
24.39,61.43,0.135
24.42,61.57,0.135
24.45,61.72,0.136
24.48,61.86,0.136
24.51,62.00,0.136
24.54,62.14,0.136
24.57,62.28,0.136
24.59,62.42,0.136
24.62,62.56,0.136
24.65,62.71,0.136
24.68,62.85,0.136
24.71,62.99,0.136
24.73,63.13,0.136
24.76,63.27,0.136
24.79,63.41,0.136
24.82,63.56,0.136
24.85,63.70,0.136
24.88,63.84,0.136
24.91,63.98,0.136
24.93,64.12,0.136
24.96,64.27,0.137
24.99,64.41,0.137
25.02,64.55,0.137
25.05,64.69,0.137
25.08,64.83,0.137
25.10,64.98,0.137
25.13,65.12,0.137
25.16,65.26,0.137
25.19,65.40,0.137
25.22,65.54,0.137
25.24,65.68,0.137
25.27,65.83,0.137
25.30,65.97,0.137
25.33,66.11,0.137
25.36,66.25,0.137
25.39,66.39,0.137
25.42,66.53,0.137
25.44,66.68,0.137
25.47,66.82,0.138
25.50,66.96,0.138
25.53,67.10,0.138
25.56,67.24,0.138
25.58,67.39,0.138
25.61,67.53,0.138
25.64,67.67,0.138
25.67,67.81,0.138
25.70,67.95,0.138
25.73,68.09,0.138
25.76,68.24,0.138
25.78,68.38,0.138
25.81,68.52,0.138
25.84,68.66,0.138
25.87,68.80,0.138
25.90,68.95,0.138
25.93,69.09,0.138
25.95,69.23,0.138
25.98,69.37,0.138
26.01,69.51,0.138
26.04,69.65,0.138
26.07,69.79,0.138
26.09,69.94,0.139
26.12,70.08,0.139
26.15,70.22,0.139
26.18,70.36,0.139
26.21,70.50,0.139
26.24,70.65,0.139
26.27,70.79,0.139
26.29,70.93,0.139
26.32,71.07,0.139
26.35,71.21,0.139
26.38,71.35,0.139
26.41,71.49,0.139
26.43,71.64,0.139
26.46,71.78,0.139
26.49,71.92,0.139
26.52,72.06,0.139
26.55,72.20,0.139
26.58,72.35,0.140
26.61,72.49,0.140
26.63,72.63,0.140
26.66,72.77,0.140
26.69,72.91,0.140
26.72,73.05,0.140
26.75,73.20,0.140
26.78,73.34,0.140
26.80,73.48,0.140
26.83,73.62,0.140
26.86,73.76,0.140
26.89,73.90,0.140
26.92,74.05,0.140
26.94,74.19,0.140
26.97,74.33,0.140
27.00,74.47,0.140
27.03,74.61,0.140
27.06,74.75,0.140
27.09,74.90,0.140
27.12,75.04,0.140
27.14,75.18,0.140
27.17,75.32,0.140
27.20,75.46,0.141
27.23,75.61,0.141
27.26,75.75,0.141
27.28,75.89,0.141
27.31,76.03,0.141
27.34,76.17,0.141
27.37,76.32,0.141
27.40,76.46,0.141
27.43,76.60,0.141
27.46,76.74,0.141
27.48,76.88,0.141
27.51,77.02,0.141
27.54,77.16,0.141
27.57,77.31,0.141
27.60,77.45,0.141
27.63,77.59,0.141
27.65,77.73,0.141
27.68,77.87,0.141
27.71,78.02,0.141
27.74,78.16,0.141
27.77,78.30,0.142
27.79,78.44,0.142
27.82,78.58,0.142
27.85,78.73,0.142
27.88,78.87,0.142
27.91,79.01,0.142
27.94,79.15,0.142
27.97,79.29,0.142
27.99,79.43,0.142
28.02,79.58,0.142
28.05,79.72,0.142
28.08,79.86,0.142
28.11,80.00,0.142
28.13,80.14,0.142
28.16,80.28,0.142
28.19,80.43,0.142
28.22,80.57,0.142
28.25,80.71,0.142
28.28,80.85,0.142
28.31,80.99,0.142
28.33,81.13,0.142
28.36,81.28,0.142
28.39,81.42,0.142
28.42,81.56,0.142
28.45,81.70,0.142
28.48,81.84,0.142
28.50,81.98,0.142
28.53,82.13,0.142
28.56,82.27,0.142
28.59,82.41,0.142
28.62,82.55,0.142
28.64,82.69,0.143
28.67,82.83,0.142
28.70,82.98,0.143
28.73,83.12,0.142
28.76,83.26,0.143
28.79,83.40,0.143
28.82,83.54,0.143
28.84,83.69,0.142
28.87,83.83,0.142
28.90,83.97,0.143
28.93,84.11,0.143
28.96,84.25,0.143
28.98,84.40,0.143
29.01,84.54,0.143
29.04,84.68,0.143
29.07,84.82,0.143
29.10,84.96,0.143
29.13,85.10,0.143
29.16,85.25,0.143
29.18,85.39,0.143
29.21,85.53,0.143
29.24,85.67,0.143
29.27,85.81,0.143
29.30,85.95,0.143
29.33,86.10,0.143
29.35,86.24,0.143
29.38,86.38,0.143
29.41,86.52,0.143
29.44,86.66,0.143
29.47,86.80,0.143
29.49,86.95,0.143
29.52,87.09,0.143
29.55,87.23,0.143
29.58,87.37,0.143
29.61,87.52,0.143
29.64,87.66,0.143
29.67,87.80,0.143
29.69,87.94,0.143
29.72,88.08,0.143
29.75,88.22,0.143
29.78,88.36,0.143
29.81,88.50,0.143
29.83,88.65,0.143
29.86,88.79,0.143
29.89,88.93,0.143
29.92,89.07,0.143
29.95,89.22,0.143
29.98,89.36,0.143
30.01,89.50,0.143
30.03,89.64,0.143
30.06,89.78,0.143
30.09,89.92,0.143
30.12,90.06,0.143
30.15,90.21,0.143
30.18,90.35,0.143
30.20,90.49,0.143
30.23,90.63,0.143
30.26,90.77,0.143
30.29,90.92,0.143
30.32,91.06,0.143
30.34,91.20,0.143
30.37,91.34,0.143
30.40,91.48,0.143
30.43,91.62,0.143
30.46,91.77,0.143
30.49,91.91,0.144
30.52,92.05,0.144
30.54,92.19,0.144
30.57,92.33,0.144
30.60,92.48,0.144
30.63,92.62,0.144
30.66,92.76,0.144
30.68,92.90,0.144
30.71,93.04,0.144
30.74,93.18,0.144
30.77,93.32,0.144
30.80,93.47,0.144
30.83,93.61,0.144
30.86,93.75,0.144
30.88,93.89,0.144
30.91,94.03,0.144
30.94,94.18,0.144
30.97,94.32,0.144
31.00,94.46,0.144
31.03,94.60,0.144
31.05,94.74,0.144
31.08,94.88,0.144
31.11,95.03,0.144
31.14,95.17,0.144
31.17,95.31,0.144
31.19,95.45,0.144
31.22,95.59,0.144
31.25,95.73,0.144
31.28,95.88,0.144
31.31,96.02,0.144
31.34,96.16,0.144
31.37,96.30,0.144
31.39,96.44,0.144
31.42,96.59,0.144
31.45,96.73,0.144
31.48,96.87,0.144
31.51,97.01,0.144
31.53,97.15,0.144
31.56,97.29,0.144
31.59,97.44,0.144
31.62,97.58,0.144
31.65,97.72,0.144
31.68,97.86,0.144
31.71,98.00,0.144
31.73,98.14,0.144
31.76,98.29,0.144
31.79,98.43,0.144
31.82,98.57,0.144
31.85,98.71,0.144
31.88,98.85,0.144
31.90,98.99,0.144
31.93,99.14,0.144
31.96,99.28,0.144
31.99,99.42,0.144
32.02,99.56,0.145
32.04,99.70,0.145
32.07,99.84,0.145
32.10,99.99,0.145
32.13,100.13,0.145
32.16,100.27,0.145
32.19,100.41,0.145
32.22,100.55,0.145
32.24,100.69,0.145
32.27,100.84,0.144
32.30,100.98,0.145
32.33,101.12,0.145
32.36,101.26,0.145
32.38,101.40,0.145
32.41,101.54,0.145
32.44,101.69,0.145
32.47,101.83,0.145
32.50,101.97,0.145
32.53,102.11,0.145
32.56,102.25,0.145
32.58,102.40,0.145
32.61,102.54,0.145
32.64,102.68,0.145
32.67,102.82,0.145
32.70,102.96,0.145
32.73,103.10,0.145
32.75,103.25,0.145
32.78,103.39,0.145
32.81,103.53,0.145
32.84,103.67,0.145
32.87,103.81,0.145
32.89,103.96,0.145
32.92,104.10,0.145
32.95,104.24,0.145
32.98,104.38,0.145
33.01,104.52,0.145
33.04,104.66,0.145
33.07,104.80,0.145
33.09,104.95,0.145
33.12,105.09,0.145
33.15,105.23,0.145
33.18,105.37,0.144
33.21,105.51,0.145
33.23,105.66,0.145
33.26,105.80,0.145
33.29,105.94,0.145
33.32,106.08,0.145
33.35,106.22,0.145
33.38,106.37,0.145
33.41,106.51,0.145
33.43,106.65,0.145
33.46,106.79,0.145
33.49,106.93,0.145
33.52,107.07,0.145
33.55,107.22,0.145
33.58,107.36,0.145
33.60,107.50,0.145
33.63,107.64,0.145
33.66,107.78,0.145
33.69,107.93,0.145
33.72,108.07,0.145
33.74,108.21,0.145
33.77,108.35,0.145
33.80,108.49,0.145
33.83,108.63,0.145
33.86,108.77,0.145
33.89,108.92,0.145
33.92,109.06,0.145
33.94,109.20,0.145
33.97,109.34,0.145
34.00,109.48,0.145
34.03,109.62,0.145
34.06,109.77,0.145
34.08,109.91,0.145
34.11,110.05,0.145
34.14,110.19,0.145
34.17,110.33,0.145
34.20,110.47,0.145
34.23,110.62,0.145
34.26,110.76,0.145
34.28,110.90,0.145
34.31,111.04,0.145
34.34,111.18,0.145
34.37,111.33,0.145
34.40,111.47,0.145
34.43,111.61,0.145
34.45,111.75,0.145
34.48,111.89,0.145
34.51,112.04,0.145
34.54,112.18,0.145
34.57,112.32,0.145
34.59,112.46,0.145
34.62,112.60,0.145
34.65,112.74,0.145
34.68,112.88,0.145
34.71,113.03,0.145
34.74,113.17,0.145
34.76,113.31,0.145
34.79,113.45,0.145
34.82,113.59,0.145
34.85,113.74,0.145
34.88,113.88,0.145
34.91,114.02,0.145
34.94,114.16,0.145
34.96,114.30,0.145
34.99,114.44,0.145
35.02,114.59,0.145
35.05,114.73,0.145
35.08,114.87,0.146
35.11,115.01,0.146
35.13,115.15,0.146
35.16,115.29,0.146
35.19,115.44,0.146
35.22,115.58,0.146
35.25,115.72,0.146
35.28,115.86,0.146
35.30,116.00,0.146
35.33,116.15,0.146
35.36,116.29,0.146
35.39,116.43,0.146
35.42,116.57,0.146
35.44,116.71,0.146
35.47,116.85,0.146
35.50,117.00,0.146
35.53,117.14,0.147
35.56,117.28,0.147
35.59,117.42,0.147
35.61,117.56,0.147
35.64,117.70,0.147
35.67,117.84,0.147
35.70,117.99,0.147
35.73,118.13,0.147
35.76,118.27,0.147
35.79,118.41,0.147
35.81,118.55,0.147
35.84,118.69,0.148
35.87,118.84,0.148
35.90,118.98,0.148
35.93,119.12,0.148
35.96,119.26,0.148
35.98,119.40,0.148
36.01,119.55,0.148
36.04,119.69,0.148
36.07,119.83,0.149
36.10,119.97,0.149
36.13,120.11,0.149
36.15,120.25,0.149
36.18,120.40,0.149
36.21,120.54,0.149
36.24,120.68,0.149
36.27,120.82,0.150
36.29,120.96,0.150
36.32,121.10,0.150
36.35,121.25,0.150
36.38,121.39,0.150
36.41,121.53,0.150
36.44,121.67,0.151
36.46,121.81,0.151
36.49,121.95,0.151
36.52,122.09,0.151
36.55,122.24,0.151
36.58,122.38,0.152
36.61,122.52,0.152
36.64,122.66,0.152
36.66,122.80,0.152
36.69,122.95,0.152
36.72,123.09,0.153
36.75,123.23,0.153
36.78,123.37,0.153
36.81,123.51,0.153
36.83,123.65,0.154
36.86,123.80,0.154
36.89,123.94,0.154
36.92,124.08,0.154
36.95,124.22,0.155
36.98,124.36,0.155
37.00,124.50,0.155
37.03,124.64,0.156
37.06,124.79,0.156
37.09,124.93,0.156
37.12,125.07,0.156
37.14,125.21,0.157
37.17,125.35,0.157
37.20,125.50,0.157
37.23,125.64,0.158
37.26,125.78,0.158
37.29,125.92,0.158
37.31,126.06,0.159
37.34,126.20,0.159
37.37,126.34,0.159
37.40,126.49,0.160
37.43,126.63,0.160
37.46,126.77,0.161
37.49,126.91,0.161
37.51,127.05,0.161
37.54,127.19,0.162
37.57,127.34,0.162
37.60,127.48,0.163
37.63,127.62,0.163
37.66,127.76,0.164
37.68,127.90,0.164
37.71,128.04,0.165
37.74,128.19,0.165
37.77,128.33,0.166
37.80,128.47,0.167
37.83,128.61,0.167
37.85,128.75,0.168
37.88,128.89,0.168
37.91,129.03,0.169
37.94,129.18,0.169
37.97,129.32,0.170
37.99,129.46,0.171
38.02,129.60,0.171
38.05,129.74,0.172
38.08,129.88,0.173
38.11,130.02,0.173
38.14,130.17,0.174
38.16,130.31,0.175
38.19,130.45,0.176
38.22,130.59,0.177
38.25,130.73,0.178
38.28,130.87,0.179
38.31,131.01,0.179
38.34,131.16,0.181
38.36,131.30,0.181
38.39,131.44,0.182
38.42,131.58,0.183
38.45,131.72,0.185
38.48,131.86,0.186
38.51,132.00,0.187
38.53,132.14,0.188
38.56,132.29,0.189
38.59,132.43,0.191
38.62,132.57,0.192
38.65,132.71,0.194
38.68,132.85,0.195
38.70,132.99,0.197
38.73,133.14,0.198
38.76,133.27,0.200
38.79,133.42,0.201
38.82,133.56,0.203
38.84,133.70,0.205
38.87,133.84,0.206
38.90,133.98,0.208
38.93,134.12,0.212
38.96,134.26,0.213
38.99,134.41,0.215
39.01,134.55,0.218
39.04,134.69,0.220
39.07,134.83,0.223
39.10,134.97,0.225
39.13,135.11,0.227
39.16,135.25,0.230
39.19,135.39,0.233
39.21,135.53,0.236
39.24,135.67,0.239
39.27,135.81,0.242
39.30,135.96,0.245
39.33,136.10,0.249
39.36,136.24,0.252
39.38,136.38,0.255
39.41,136.52,0.259
39.44,136.66,0.263
39.47,136.80,0.266
39.50,136.94,0.270
39.53,137.08,0.274
39.55,137.22,0.279
39.58,137.36,0.282
39.61,137.50,0.287
39.64,137.64,0.292
39.67,137.78,0.296
39.69,137.92,0.301
39.72,138.06,0.305
39.75,138.21,0.311
39.78,138.35,0.316
39.81,138.49,0.322
39.84,138.63,0.328
39.86,138.77,0.334
39.89,138.91,0.341
39.92,139.05,0.347
39.95,139.19,0.353
39.98,139.33,0.359
40.01,139.47,0.366
40.04,139.61,0.372
40.06,139.75,0.381
40.09,139.89,0.387
40.12,140.03,0.395
40.15,140.16,0.404
40.18,140.31,0.412
40.21,140.44,0.421
40.23,140.58,0.431
40.26,140.72,0.440
40.29,140.86,0.450
40.32,141.00,0.462
40.35,141.14,0.473
40.38,141.28,0.484
40.40,141.41,0.498
40.43,141.55,0.512
40.46,141.69,0.526
40.49,141.83,0.541
40.52,141.96,0.558
40.54,142.10,0.577
40.57,142.24,0.601
40.60,142.37,0.621
40.63,142.51,0.642
40.66,142.64,0.665
40.69,142.78,0.694
40.71,142.91,0.730
40.74,143.04,0.774
40.77,143.17,0.815
40.80,143.30,0.841
40.83,143.43,0.877
40.86,143.56,0.913
40.89,143.70,0.948
40.91,143.83,0.979
40.94,143.96,1.007
40.97,144.09,1.032
41.00,144.22,1.057
41.03,144.36,1.082
41.06,144.49,1.092
41.08,144.63,1.091
41.11,144.77,1.075
41.14,144.92,1.046
41.17,145.07,1.016
41.20,145.21,0.990
41.23,145.36,0.965
41.25,145.51,0.948
41.28,145.66,0.943
41.31,145.80,0.944
41.34,145.95,0.946
41.37,146.09,0.953
41.39,146.23,0.982
41.42,146.36,0.999
41.45,146.50,1.006
41.48,146.64,1.006
41.51,146.78,1.003
41.54,146.93,0.977
41.56,147.07,0.945
41.59,147.22,0.898
41.62,147.38,0.834
41.65,147.54,0.756
41.68,147.70,0.667
41.71,147.86,0.572
41.74,148.03,0.482
41.76,148.20,0.410
41.79,148.36,0.352
41.82,148.52,0.306
41.85,148.68,0.270
41.88,148.84,0.243
41.91,148.99,0.222
41.93,149.14,
41.96,149.29,
41.98,,

[step]
Ramp 5.00 °C/min to -60.00 °C
Time,Temperature,Heat Flow (Normalized)
min,°C,W/g
42.99,150.12,-0.069
43.01,150.12,-0.069
43.04,150.11,-0.070
43.07,150.09,-0.081
43.10,150.03,-0.102
43.13,149.96,-0.129
43.16,149.86,-0.156
43.18,149.76,-0.180
43.21,149.64,-0.200
43.24,149.52,-0.217
43.27,149.40,-0.231
43.30,149.27,-0.245
43.33,149.14,-0.253
43.35,149.01,-0.260
43.38,148.88,-0.267
43.41,148.74,-0.270
43.44,148.60,-0.272
43.47,148.47,-0.274
43.49,148.33,-0.278
43.52,148.19,-0.279
43.55,148.05,-0.280
43.58,147.92,-0.281
43.61,147.78,-0.281
43.64,147.64,-0.282
43.66,147.50,-0.282
43.69,147.36,-0.283
43.72,147.22,-0.283
43.75,147.08,-0.283
43.78,146.94,-0.284
43.81,146.80,-0.284
43.84,146.66,-0.285
43.86,146.52,-0.285
43.89,146.37,-0.285
43.92,146.23,-0.285
43.95,146.09,-0.286
43.98,145.95,-0.286
44.01,145.81,-0.286
44.03,145.67,-0.286
44.06,145.52,-0.286
44.09,145.38,-0.286
44.12,145.24,-0.286
44.15,145.10,-0.285
44.18,144.96,-0.285
44.20,144.82,-0.285
44.23,144.68,-0.285
44.26,144.54,-0.285
44.29,144.40,-0.284
44.32,144.25,-0.284
44.34,144.11,-0.284
44.37,143.97,-0.284
44.40,143.83,-0.284
44.43,143.69,-0.284
44.46,143.55,-0.283
44.49,143.41,-0.283
44.51,143.26,-0.283
44.54,143.12,-0.283
44.57,142.98,-0.283
44.60,142.84,-0.282
44.63,142.70,-0.282
44.66,142.56,-0.282
44.69,142.42,-0.282
44.71,142.27,-0.281
44.74,142.13,-0.281
44.77,141.99,-0.281
44.80,141.85,-0.281
44.83,141.71,-0.281
44.86,141.57,-0.280
44.88,141.42,-0.280
44.91,141.28,-0.280
44.94,141.14,-0.280
44.97,141.00,-0.280
45.00,140.86,-0.279
45.03,140.72,-0.279
45.05,140.58,-0.279
45.08,140.43,-0.279
45.11,140.29,-0.278
45.14,140.15,-0.278
45.17,140.01,-0.278
45.19,139.87,-0.278
45.22,139.73,-0.278
45.25,139.58,-0.277
45.28,139.44,-0.277
45.31,139.30,-0.277
45.34,139.16,-0.277
45.36,139.02,-0.276
45.39,138.88,-0.276
45.42,138.74,-0.276
45.45,138.59,-0.276
45.48,138.45,-0.276
45.51,138.31,-0.275
45.54,138.17,-0.275
45.56,138.03,-0.275
45.59,137.88,-0.275
45.62,137.74,-0.275
45.65,137.60,-0.274
45.68,137.46,-0.274
45.71,137.32,-0.274
45.73,137.18,-0.274
45.76,137.04,-0.274
45.79,136.89,-0.274
45.82,136.75,-0.273
45.85,136.61,-0.273
45.88,136.47,-0.273
45.90,136.33,-0.273
45.93,136.19,-0.273
45.96,136.04,-0.273
45.99,135.90,-0.272
46.02,135.76,-0.272
46.04,135.62,-0.272
46.07,135.48,-0.272
46.10,135.34,-0.272
46.13,135.20,-0.271
46.16,135.05,-0.271
46.19,134.91,-0.271
46.21,134.77,-0.271
46.24,134.63,-0.271
46.27,134.49,-0.270
46.30,134.35,-0.270
46.33,134.20,-0.270
46.36,134.06,-0.270
46.39,133.92,-0.270
46.41,133.78,-0.270
46.44,133.64,-0.269
46.47,133.50,-0.269
46.50,133.36,-0.269
46.53,133.21,-0.269
46.56,133.07,-0.269
46.58,132.93,-0.269
46.61,132.79,-0.268
46.64,132.65,-0.268
46.67,132.50,-0.268
46.70,132.36,-0.268
46.73,132.22,-0.268
46.75,132.08,-0.268
46.78,131.94,-0.268
46.81,131.80,-0.268
46.84,131.65,-0.267
46.87,131.51,-0.267
46.89,131.37,-0.267
46.92,131.23,-0.267
46.95,131.09,-0.267
46.98,130.95,-0.267
47.01,130.80,-0.267
47.04,130.66,-0.266
47.06,130.52,-0.266
47.09,130.38,-0.266
47.12,130.24,-0.266
47.15,130.10,-0.266
47.18,129.96,-0.266
47.21,129.81,-0.266
47.24,129.67,-0.266
47.26,129.53,-0.265
47.29,129.39,-0.265
47.32,129.25,-0.265
47.35,129.11,-0.265
47.38,128.96,-0.265
47.41,128.82,-0.265
47.43,128.68,-0.265
47.46,128.54,-0.265
47.49,128.40,-0.264
47.52,128.25,-0.264
47.55,128.11,-0.264
47.58,127.97,-0.264
47.60,127.83,-0.264
47.63,127.69,-0.264
47.66,127.55,-0.264
47.69,127.41,-0.264
47.72,127.26,-0.264
47.74,127.12,-0.264
47.77,126.98,-0.263
47.80,126.84,-0.263
47.83,126.70,-0.263
47.86,126.56,-0.263
47.89,126.42,-0.263
47.91,126.28,-0.263
47.94,126.13,-0.263
47.97,125.99,-0.263
48.00,125.85,-0.262
48.03,125.71,-0.262
48.06,125.57,-0.262
48.09,125.43,-0.262
48.11,125.28,-0.262
48.14,125.14,-0.262
48.17,125.00,-0.262
48.20,124.86,-0.262
48.23,124.72,-0.262
48.26,124.57,-0.262
48.28,124.43,-0.262
48.31,124.29,-0.261
48.34,124.15,-0.261
48.37,124.01,-0.261
48.40,123.87,-0.261
48.43,123.73,-0.261
48.45,123.58,-0.261
48.48,123.44,-0.261
48.51,123.30,-0.260
48.54,123.16,-0.260
48.57,123.02,-0.260
48.59,122.88,-0.260
48.62,122.73,-0.260
48.65,122.59,-0.260
48.68,122.45,-0.260
48.71,122.31,-0.260
48.74,122.17,-0.260
48.76,122.03,-0.260
48.79,121.88,-0.260
48.82,121.74,-0.260
48.85,121.60,-0.260
48.88,121.46,-0.259
48.91,121.32,-0.259
48.94,121.18,-0.259
48.96,121.03,-0.259
48.99,120.89,-0.259
49.02,120.75,-0.259
49.05,120.61,-0.259
49.08,120.47,-0.259
49.11,120.33,-0.259
49.13,120.19,-0.259
49.16,120.04,-0.259
49.19,119.90,-0.258
49.22,119.76,-0.258
49.25,119.62,-0.258
49.28,119.48,-0.258
49.30,119.34,-0.258
49.33,119.20,-0.258
49.36,119.05,-0.258
49.39,118.91,-0.258
49.42,118.77,-0.258
49.44,118.63,-0.258
49.47,118.49,-0.258
49.50,118.35,-0.258
49.53,118.20,-0.257
49.56,118.06,-0.257
49.59,117.92,-0.257
49.61,117.78,-0.257
49.64,117.64,-0.257
49.67,117.50,-0.257
49.70,117.35,-0.257
49.73,117.21,-0.257
49.76,117.07,-0.257
49.79,116.93,-0.257
49.81,116.79,-0.257
49.84,116.65,-0.257
49.87,116.50,-0.257
49.90,116.36,-0.257
49.93,116.22,-0.257
49.96,116.08,-0.256
49.98,115.94,-0.256
50.01,115.80,-0.256
50.04,115.65,-0.256
50.07,115.51,-0.256
50.10,115.37,-0.256
50.13,115.23,-0.256
50.15,115.09,-0.256
50.18,114.95,-0.256
50.21,114.80,-0.256
50.24,114.66,-0.256
50.27,114.52,-0.256
50.29,114.38,-0.256
50.32,114.24,-0.255
50.35,114.10,-0.255
50.38,113.96,-0.255
50.41,113.81,-0.255
50.44,113.67,-0.255
50.46,113.53,-0.255
50.49,113.39,-0.255
50.52,113.25,-0.255
50.55,113.11,-0.255
50.58,112.97,-0.255
50.61,112.82,-0.255
50.64,112.68,-0.255
50.66,112.54,-0.255
50.69,112.40,-0.255
50.72,112.26,-0.255
50.75,112.12,-0.255
50.78,111.97,-0.255
50.81,111.83,-0.254
50.83,111.69,-0.254
50.86,111.55,-0.254
50.89,111.41,-0.254
50.92,111.27,-0.254
50.95,111.13,-0.254
50.98,110.98,-0.254
51.00,110.84,-0.254
51.03,110.70,-0.254
51.06,110.56,-0.254
51.09,110.42,-0.254
51.12,110.27,-0.254
51.14,110.13,-0.254
51.17,109.99,-0.254
51.20,109.85,-0.253
51.23,109.71,-0.253
51.26,109.57,-0.253
51.29,109.43,-0.253
51.31,109.28,-0.253
51.34,109.14,-0.253
51.37,109.00,-0.253
51.40,108.86,-0.253
51.43,108.72,-0.253
51.46,108.57,-0.253
51.49,108.43,-0.253
51.51,108.29,-0.253
51.54,108.15,-0.253
51.57,108.01,-0.253
51.60,107.87,-0.253
51.63,107.73,-0.252
51.66,107.58,-0.253
51.68,107.44,-0.252
51.71,107.30,-0.252
51.74,107.16,-0.252
51.77,107.02,-0.252
51.80,106.88,-0.252
51.83,106.73,-0.252
51.85,106.59,-0.252
51.88,106.45,-0.252
51.91,106.31,-0.252
51.94,106.17,-0.252
51.97,106.03,-0.252
51.99,105.88,-0.252
52.02,105.74,-0.252
52.05,105.60,-0.252
52.08,105.46,-0.252
52.11,105.32,-0.252
52.14,105.18,-0.252
52.16,105.03,-0.252
52.19,104.89,-0.251
52.22,104.75,-0.251
52.25,104.61,-0.251
52.28,104.47,-0.251
52.31,104.33,-0.251
52.34,104.19,-0.251
52.36,104.04,-0.251
[...]
176.16,-39.89,0.109
176.17,-39.83,0.109
176.18,-39.76,0.109
176.20,-39.69,0.109
176.21,-39.63,0.109
176.23,-39.56,0.109
176.24,-39.49,0.109
176.25,-39.43,0.109
176.27,-39.36,0.109
176.28,-39.29,0.109
176.29,-39.23,0.109
176.30,-39.16,0.109
176.32,-39.09,0.109
176.33,-39.03,0.109
176.35,-38.96,0.109
176.36,-38.89,0.109
176.37,-38.83,0.109
176.38,-38.76,0.109
176.40,-38.69,0.109
176.41,-38.63,0.109
176.43,-38.56,0.109
176.44,-38.49,0.109
176.45,-38.43,0.109
176.47,-38.36,0.109
176.48,-38.29,0.109
176.49,-38.23,0.109
176.50,-38.16,0.109
176.52,-38.09,0.109
176.53,-38.02,0.109
176.55,-37.96,0.109
176.56,-37.89,0.109
176.57,-37.83,0.109
176.58,-37.76,0.109
176.60,-37.69,0.109
176.61,-37.62,0.109
176.63,-37.56,0.109
176.64,-37.49,0.109
176.65,-37.42,0.109
176.67,-37.36,0.109
176.68,-37.29,0.109
176.69,-37.22,0.109
176.70,-37.16,0.109
176.72,-37.09,0.109
176.73,-37.02,0.109
176.75,-36.96,0.109
176.76,-36.89,0.109
176.77,-36.82,0.109
176.78,-36.76,0.109
176.80,-36.69,0.109
176.81,-36.62,0.109
176.83,-36.56,0.109
176.84,-36.49,0.109
176.85,-36.42,0.109
176.87,-36.36,0.109
176.88,-36.29,0.110
176.89,-36.22,0.110
176.90,-36.16,0.110
176.92,-36.09,0.110
176.93,-36.02,0.110
176.95,-35.95,0.110
176.96,-35.89,0.110
176.97,-35.82,0.110
176.98,-35.76,0.110
177.00,-35.69,0.110
177.01,-35.62,0.110
177.03,-35.55,0.109
177.04,-35.49,0.110
177.05,-35.42,0.110
177.07,-35.36,0.110
177.08,-35.29,0.110
177.09,-35.22,0.110
177.10,-35.15,0.110
177.12,-35.09,0.110
177.13,-35.02,0.110
177.15,-34.96,0.110
177.16,-34.89,0.110
177.17,-34.82,0.110
177.18,-34.75,0.110
177.20,-34.69,0.110
177.21,-34.62,0.110
177.23,-34.55,0.110
177.24,-34.49,0.110
177.25,-34.42,0.110
177.27,-34.35,0.110
177.28,-34.29,0.110
177.29,-34.22,0.110
177.30,-34.15,0.110
177.32,-34.09,0.110
177.33,-34.02,0.110
177.35,-33.95,0.110
177.36,-33.89,0.110
177.37,-33.82,0.110
177.38,-33.75,0.110
177.40,-33.69,0.110
177.41,-33.62,0.110
177.43,-33.55,0.110
177.44,-33.49,0.110
177.45,-33.42,0.110
177.47,-33.35,0.110
177.48,-33.29,0.110
177.49,-33.22,0.110
177.50,-33.15,0.110
177.52,-33.08,0.110
177.53,-33.02,0.110
177.55,-32.95,0.110
177.56,-32.88,0.110
177.57,-32.82,0.110
177.58,-32.75,0.110
177.60,-32.68,0.110
177.61,-32.62,0.110
177.63,-32.55,0.110
177.64,-32.48,0.110
177.65,-32.42,0.110
177.67,-32.35,0.110
177.68,-32.28,0.110
177.69,-32.22,0.110
177.70,-32.15,0.110
177.72,-32.08,0.110
177.73,-32.02,0.110
177.75,-31.95,0.111
177.76,-31.88,0.111
177.77,-31.82,0.111
177.78,-31.75,0.111
177.80,-31.68,0.111
177.81,-31.62,0.111
177.83,-31.55,0.111
177.84,-31.48,0.111
177.85,-31.42,0.111
177.87,-31.35,0.111
177.88,-31.28,0.111
177.89,-31.22,0.111
177.90,-31.15,0.111
177.92,-31.08,0.111
177.93,-31.02,0.111
177.95,-30.95,0.111
177.96,-30.88,0.111
177.97,-30.82,0.111
177.98,-30.75,0.111
178.00,-30.68,0.111
178.01,-30.62,0.111
178.03,-30.55,0.111
178.04,-30.48,0.111
178.05,-30.42,0.111
178.07,-30.35,0.111
178.08,-30.28,0.111
178.09,-30.22,0.111
178.10,-30.15,0.111
178.12,-30.08,0.111
178.13,-30.02,0.111
178.15,-29.95,0.111
178.16,-29.88,0.111
178.17,-29.81,0.111
178.18,-29.75,0.111
178.20,-29.68,0.111
178.21,-29.62,0.111
178.23,-29.55,0.111
178.24,-29.48,0.111
178.25,-29.42,0.111
178.27,-29.35,0.111
178.28,-29.28,0.111
178.29,-29.22,0.111
178.30,-29.15,0.111
178.32,-29.08,0.111
178.33,-29.01,0.111
178.35,-28.95,0.111
178.36,-28.88,0.111
178.37,-28.81,0.111
178.38,-28.75,0.111
178.40,-28.68,0.111
178.41,-28.61,0.111
178.43,-28.55,0.111
178.44,-28.48,0.111
178.45,-28.41,0.111
178.47,-28.35,0.111
178.48,-28.28,0.111
178.49,-28.21,0.111
178.50,-28.15,0.112
178.52,-28.08,0.111
178.53,-28.01,0.112
178.55,-27.95,0.112
178.56,-27.88,0.112
178.57,-27.81,0.112
178.58,-27.75,0.112
178.60,-27.68,0.112
178.61,-27.61,0.112
178.63,-27.55,0.112
178.64,-27.48,0.112
178.65,-27.41,0.112
178.67,-27.35,0.112
178.68,-27.28,0.112
178.69,-27.21,0.112
178.70,-27.15,0.112
178.72,-27.08,0.112
178.73,-27.01,0.112
178.75,-26.95,0.112
178.76,-26.88,0.112
178.77,-26.81,0.112
178.78,-26.75,0.112
178.80,-26.68,0.112
178.81,-26.61,0.112
178.83,-26.55,0.112
178.84,-26.48,0.112
178.85,-26.41,0.112
178.87,-26.35,0.112
178.88,-26.28,0.112
178.89,-26.21,0.112
178.90,-26.14,0.112
178.92,-26.08,0.112
178.93,-26.01,0.112
178.95,-25.94,0.112
178.96,-25.88,0.113
178.97,-25.81,0.113
178.98,-25.75,0.113
179.00,-25.68,0.113
179.01,-25.61,0.113
179.03,-25.55,0.113
179.04,-25.48,0.113
179.05,-25.41,0.113
179.07,-25.35,0.113
179.08,-25.28,0.113
179.09,-25.21,0.113
179.10,-25.14,0.113
179.12,-25.08,0.113
179.13,-25.01,0.113
179.15,-24.95,0.113
179.16,-24.88,0.113
179.17,-24.81,0.113
179.18,-24.74,0.113
179.20,-24.68,0.113
179.21,-24.61,0.113
179.23,-24.54,0.113
179.24,-24.48,0.113
179.25,-24.41,0.113
179.27,-24.34,0.113
179.28,-24.28,0.113
179.29,-24.21,0.113
179.30,-24.14,0.113
179.32,-24.08,0.113
179.33,-24.01,0.113
179.35,-23.94,0.113
179.36,-23.88,0.113
179.37,-23.81,0.113
179.38,-23.74,0.113
179.40,-23.68,0.113
179.41,-23.61,0.113
179.43,-23.54,0.113
179.44,-23.48,0.113
179.45,-23.41,0.113
179.47,-23.34,0.113
179.48,-23.28,0.113
179.49,-23.21,0.114
179.50,-23.14,0.114
179.52,-23.08,0.114
179.53,-23.01,0.114
179.55,-22.94,0.114
179.56,-22.88,0.114
179.57,-22.81,0.114
179.58,-22.74,0.114
179.60,-22.68,0.114
179.61,-22.61,0.114
179.63,-22.54,0.114
179.64,-22.48,0.114
179.65,-22.41,0.114
179.67,-22.34,0.114
179.68,-22.28,0.114
179.69,-22.21,0.114
179.70,-22.14,0.114
179.72,-22.08,0.114
179.73,-22.01,0.114
179.75,-21.94,0.114
179.76,-21.88,0.114
179.77,-21.81,0.114
179.78,-21.74,0.114
179.80,-21.68,0.114
179.81,-21.61,0.114
179.83,-21.54,0.115
179.84,-21.48,0.115
179.85,-21.41,0.115
179.87,-21.34,0.115
179.88,-21.28,0.115
179.89,-21.21,0.115
179.90,-21.14,0.115
179.92,-21.07,0.115
179.93,-21.01,0.115
179.95,-20.94,0.115
179.96,-20.87,0.115
179.97,-20.81,0.115
179.98,-20.74,0.115
180.00,-20.68,0.115
180.01,-20.61,0.115
180.03,-20.54,0.115
180.04,-20.48,0.115
180.05,-20.41,0.115
180.07,-20.34,0.115
180.08,-20.27,0.116
180.09,-20.21,0.116
180.10,-20.14,0.116
180.12,-20.07,0.116
180.13,-20.01,0.116
180.15,-19.94,0.116
180.16,-19.87,0.116
180.17,-19.81,0.116
180.18,-19.74,0.116
180.20,-19.67,0.116
180.21,-19.61,0.116
180.23,-19.54,0.116
180.24,-19.47,0.116
180.25,-19.41,0.116
180.27,-19.34,0.116
180.28,-19.27,0.116
180.29,-19.21,0.116
180.30,-19.14,0.116
180.32,-19.07,0.116
180.33,-19.01,0.116
180.35,-18.94,0.117
180.36,-18.87,0.117
180.37,-18.81,0.117
180.38,-18.74,0.117
180.40,-18.67,0.117
180.41,-18.61,0.117
180.43,-18.54,0.117
180.44,-18.47,0.117
180.45,-18.41,0.117
180.47,-18.34,0.117
180.48,-18.27,0.117
180.49,-18.21,0.117
180.50,-18.14,0.117
180.52,-18.07,0.117
180.53,-18.01,0.118
180.55,-17.94,0.118
180.56,-17.87,0.118
180.57,-17.81,0.118
180.58,-17.74,0.118
180.60,-17.67,0.118
180.61,-17.61,0.118
180.63,-17.54,0.118
180.64,-17.47,0.118
180.65,-17.41,0.118
180.67,-17.34,0.118
180.68,-17.27,0.118
180.69,-17.21,0.119
180.70,-17.14,0.119
180.72,-17.07,0.119
180.73,-17.01,0.119
180.75,-16.94,0.119
180.76,-16.87,0.119
180.77,-16.81,0.119
180.78,-16.74,0.119
180.80,-16.67,0.119
180.81,-16.61,0.119
180.83,-16.54,0.119
180.84,-16.47,0.119
180.85,-16.40,0.119
180.87,-16.34,0.119
180.88,-16.27,0.119
180.89,-16.20,0.120
180.90,-16.14,0.120
180.92,-16.07,0.120
180.93,-16.01,0.120
180.95,-15.94,0.120
180.96,-15.87,0.120
180.97,-15.81,0.120
180.98,-15.74,0.120
181.00,-15.67,0.120
181.01,-15.61,0.120
181.03,-15.54,0.120
181.04,-15.47,0.121
181.05,-15.41,0.121
181.07,-15.34,0.121
181.08,-15.27,0.121
181.09,-15.21,0.121
181.10,-15.14,0.121
181.12,-15.07,0.121
181.13,-15.01,0.121
181.15,-14.94,0.121
181.16,-14.87,0.121
181.17,-14.81,0.121
181.18,-14.74,0.122
181.20,-14.67,0.122
181.21,-14.60,0.122
181.23,-14.54,0.122
181.24,-14.47,0.122
181.25,-14.40,0.122
181.27,-14.34,0.122
181.28,-14.27,0.122
181.29,-14.20,0.122
181.30,-14.14,0.123
181.32,-14.07,0.123
181.33,-14.00,0.123
181.35,-13.93,0.123
181.36,-13.87,0.123
181.37,-13.80,0.123
181.38,-13.73,0.123
181.40,-13.67,0.123
181.41,-13.60,0.124
181.43,-13.53,0.124
181.44,-13.47,0.124
181.45,-13.40,0.124
181.47,-13.33,0.124
181.48,-13.27,0.124
181.49,-13.20,0.124
181.50,-13.13,0.124
181.52,-13.07,0.124
181.53,-13.00,0.124
181.55,-12.93,0.125
181.56,-12.87,0.125
181.57,-12.80,0.125
181.58,-12.73,0.125
181.60,-12.67,0.125
181.61,-12.60,0.125
181.63,-12.53,0.125
181.64,-12.47,0.125
181.65,-12.40,0.125
181.67,-12.33,0.125
181.68,-12.27,0.126
181.69,-12.20,0.126
181.70,-12.14,0.126
181.72,-12.07,0.126
181.73,-12.00,0.126
181.75,-11.94,0.126
181.76,-11.87,0.126
181.77,-11.80,0.126
181.78,-11.74,0.126
181.80,-11.67,0.127
181.81,-11.60,0.127
181.83,-11.53,0.127
181.84,-11.47,0.127
181.85,-11.40,0.127
181.87,-11.34,0.127
181.88,-11.27,0.127
181.89,-11.20,0.127
181.90,-11.14,0.127
181.92,-11.07,0.128
181.93,-11.00,0.128
181.95,-10.94,0.128
181.96,-10.87,0.128
181.97,-10.80,0.128
181.98,-10.74,0.128
182.00,-10.67,0.128
182.01,-10.60,0.128
182.03,-10.54,0.129
182.04,-10.47,0.129
182.05,-10.40,0.129
182.07,-10.34,0.129
182.08,-10.27,0.129
182.09,-10.20,0.129
182.10,-10.14,0.129
182.12,-10.07,0.130
182.13,-10.00,0.130
182.15,-9.94,0.130
182.16,-9.87,0.130
182.17,-9.80,0.130
182.18,-9.74,0.130
182.20,-9.67,0.130
182.21,-9.60,0.131
182.23,-9.54,0.131
182.24,-9.47,0.131
182.25,-9.40,0.131
182.27,-9.34,0.131
182.28,-9.27,0.131
182.29,-9.20,0.131
182.30,-9.14,0.132
182.32,-9.07,0.132
182.33,-9.01,0.132
182.35,-8.94,0.132
182.36,-8.87,0.132
182.37,-8.80,0.132
182.38,-8.74,0.133
182.40,-8.67,0.133
182.41,-8.60,0.133
182.43,-8.54,0.133
182.44,-8.47,0.133
182.45,-8.40,0.133
182.47,-8.34,0.133
182.48,-8.27,0.134
182.49,-8.20,0.134
182.50,-8.14,0.134
182.52,-8.07,0.134
182.53,-8.00,0.134
182.55,-7.94,0.135
182.56,-7.87,0.135
182.57,-7.80,0.135
182.58,-7.74,0.135
182.60,-7.67,0.135
182.61,-7.60,0.136
182.63,-7.54,0.136
182.64,-7.47,0.136
182.65,-7.40,0.136
182.67,-7.34,0.136
182.68,-7.27,0.136
182.69,-7.20,0.136
182.70,-7.14,0.137
182.72,-7.07,0.137
182.73,-7.00,0.137
182.75,-6.94,0.137
182.76,-6.87,0.137
182.77,-6.80,0.138
182.78,-6.74,0.138
182.80,-6.67,0.138
182.81,-6.60,0.138
182.83,-6.54,0.138
182.84,-6.47,0.138
182.85,-6.40,0.138
182.87,-6.34,0.139
182.88,-6.27,0.139
182.89,-6.20,0.139
182.90,-6.14,0.139
182.92,-6.07,0.139
182.93,-6.00,0.139
182.95,-5.94,0.139
182.96,-5.87,0.140
182.97,-5.80,0.140
182.98,-5.74,0.140
183.00,-5.67,0.140
183.01,-5.60,0.140
183.03,-5.54,0.140
183.04,-5.47,0.140
183.05,-5.40,0.140
183.07,-5.34,0.140
183.08,-5.27,0.141
183.09,-5.20,0.141
183.10,-5.14,0.141
183.12,-5.07,0.141
183.13,-5.00,0.141
183.15,-4.94,0.141
183.16,-4.87,0.141
183.17,-4.80,0.141
183.18,-4.74,0.142
183.20,-4.67,0.142
183.21,-4.60,0.142
183.23,-4.54,0.142
183.24,-4.47,0.142
183.25,-4.40,0.142
183.27,-4.34,0.142
183.28,-4.27,0.142
183.29,-4.20,0.142
183.30,-4.14,0.142
183.32,-4.07,0.142
183.33,-4.00,0.142
183.35,-3.94,0.142
183.36,-3.87,0.142
183.37,-3.80,0.143
183.38,-3.74,0.143
183.40,-3.67,0.143
183.41,-3.60,0.143
183.43,-3.54,0.143
183.44,-3.47,0.143
183.45,-3.40,0.143
183.47,-3.34,0.143
183.48,-3.27,0.143
183.49,-3.20,0.143
183.50,-3.14,0.143
183.52,-3.07,0.143
183.53,-3.00,0.143
183.55,-2.94,0.143
183.56,-2.87,0.143
183.57,-2.80,0.143
183.58,-2.74,0.144
183.60,-2.67,0.144
183.61,-2.60,0.144
183.63,-2.54,0.144
183.64,-2.47,0.144
183.65,-2.40,0.144
183.67,-2.33,0.144
183.68,-2.27,0.144
183.69,-2.20,0.144
183.70,-2.13,0.144
183.72,-2.07,0.144
183.73,-2.00,0.144
183.75,-1.93,0.144
183.76,-1.87,0.144
183.77,-1.80,0.144
183.78,-1.73,0.144
183.80,-1.67,0.144
183.81,-1.60,0.144
183.83,-1.53,0.144
183.84,-1.47,0.144
183.85,-1.40,0.144
183.87,-1.33,0.144
183.88,-1.27,0.144
183.89,-1.20,0.144
183.90,-1.13,0.144
183.92,-1.07,0.144
183.93,-1.00,0.144
183.95,-0.93,0.144
183.96,-0.87,0.144
183.97,-0.80,0.144
183.98,-0.73,0.144
184.00,-0.67,0.144
184.01,-0.60,0.144
184.03,-0.53,0.144
184.04,-0.47,0.144
184.05,-0.40,0.144
184.07,-0.33,0.144
184.08,-0.27,0.144
184.09,-0.20,0.144
184.10,-0.13,0.144
184.12,-0.07,0.144
184.13,0.00,0.144
184.15,0.07,0.144
184.16,0.13,0.144
184.17,0.20,0.144
184.18,0.27,0.144
184.20,0.33,0.144
184.21,0.40,0.144
184.23,0.47,0.144
184.24,0.53,0.144
184.25,0.60,0.144
184.27,0.67,0.144
184.28,0.74,0.144
184.29,0.80,0.144
184.30,0.87,0.144
184.32,0.94,0.144
184.33,1.00,0.144
184.35,1.07,0.144
184.36,1.14,0.144
184.37,1.20,0.144
184.38,1.27,0.144
184.40,1.34,0.144
184.41,1.40,0.144
184.43,1.47,0.144
184.44,1.54,0.144
184.45,1.60,0.144
184.47,1.67,0.144
184.48,1.74,0.144
184.49,1.80,0.144
184.50,1.87,0.144
184.52,1.94,0.145
184.53,2.00,0.145
184.55,2.07,0.145
184.56,2.14,0.145
184.57,2.20,0.145
184.58,2.27,0.145
184.60,2.34,0.145
184.61,2.40,0.145
184.63,2.47,0.145
184.64,2.54,0.145
184.65,2.60,0.145
184.67,2.67,0.145
184.68,2.74,0.145
184.69,2.80,0.145
184.70,2.87,0.145
184.72,2.94,0.145
184.73,3.00,0.145
184.75,3.07,0.145
184.76,3.14,0.145
184.77,3.20,0.145
184.78,3.27,0.145
184.80,3.34,0.145
184.81,3.40,0.145
184.83,3.47,0.145
184.84,3.54,0.145
184.85,3.60,0.145
184.87,3.67,0.145
184.88,3.74,0.145
184.89,3.80,0.145
184.90,3.87,0.145
184.92,3.94,0.145
184.93,4.00,0.145
184.95,4.07,0.145
184.96,4.14,0.145
184.97,4.20,0.145
184.98,4.27,0.145
185.00,4.34,0.145
185.01,4.41,0.145
185.03,4.47,0.145
185.04,4.54,0.145
185.05,4.60,0.145
185.07,4.67,0.145
185.08,4.74,0.145
185.09,4.81,0.145
185.10,4.87,0.145
185.12,4.94,0.145
185.13,5.00,0.145
185.15,5.07,0.146
185.16,5.14,0.146
185.17,5.20,0.146
185.18,5.27,0.146
185.20,5.34,0.146
185.21,5.40,0.146
185.23,5.47,0.146
185.24,5.54,0.146
185.25,5.61,0.146
185.27,5.67,0.146
185.28,5.74,0.146
185.29,5.81,0.146
185.30,5.87,0.146
185.32,5.94,0.146
185.33,6.01,0.146
185.35,6.07,0.146
185.36,6.14,0.146
185.37,6.20,0.146
185.38,6.27,0.146
185.40,6.34,0.146
185.41,6.41,0.146
185.43,6.47,0.146
185.44,6.54,0.146
185.45,6.61,0.146
185.47,6.67,0.146
185.48,6.74,0.147
185.49,6.81,0.147
185.50,6.87,0.147
185.52,6.94,0.147
185.53,7.00,0.147
185.55,7.07,0.147
185.56,7.14,0.147
185.57,7.21,0.147
185.58,7.27,0.147
185.60,7.34,0.147
185.61,7.41,0.147
185.63,7.47,0.147
185.64,7.54,0.147
185.65,7.61,0.147
185.67,7.67,0.147
185.68,7.74,0.147
185.69,7.81,0.147
185.70,7.87,0.147
185.72,7.94,0.147
185.73,8.01,0.147
185.75,8.07,0.147
185.76,8.14,0.147
185.77,8.21,0.147
185.78,8.27,0.147
185.80,8.34,0.147
185.81,8.41,0.147
185.83,8.47,0.148
185.84,8.54,0.148
185.85,8.61,0.148
185.87,8.67,0.148
185.88,8.74,0.148
185.89,8.81,0.148
185.90,8.87,0.148
185.92,8.94,0.148
185.93,9.01,0.148
185.95,9.07,0.148
185.96,9.14,0.148
185.97,9.21,0.148
185.98,9.27,0.148
186.00,9.34,0.148
186.01,9.41,0.148
186.03,9.47,0.148
186.04,9.54,0.148
186.05,9.61,0.148
186.07,9.68,0.148
186.08,9.74,0.148
186.09,9.81,0.148
186.10,9.88,0.148
186.12,9.94,0.148
186.13,10.01,0.148
186.15,10.07,0.148
186.16,10.14,0.148
186.17,10.21,0.148
186.18,10.28,0.148
186.20,10.34,0.148
186.21,10.41,0.148
186.23,10.48,0.148
186.24,10.54,0.148
186.25,10.61,0.148
186.27,10.68,0.148
186.28,10.74,0.148
186.29,10.81,0.148
186.30,10.88,0.149
186.32,10.94,0.149
186.33,11.01,0.149
186.35,11.08,0.149
186.36,11.14,0.149
186.37,11.21,0.149
186.38,11.28,0.149
186.40,11.34,0.149
186.41,11.41,0.149
186.43,11.48,0.149
186.44,11.54,0.149
186.45,11.61,0.149
186.47,11.68,0.149
186.48,11.74,0.149
186.49,11.81,0.149
186.50,11.88,0.149
186.52,11.94,0.149
186.53,12.01,0.149
186.55,12.08,0.149
186.56,12.14,0.149
186.57,12.21,0.149
186.58,12.28,0.149
186.60,12.34,0.149
186.61,12.41,0.149
186.63,12.48,0.149
186.64,12.54,0.149
186.65,12.61,0.149
186.67,12.68,0.149
186.68,12.74,0.149
186.69,12.81,0.149
186.70,12.88,0.149
186.72,12.95,0.149
186.73,13.01,0.149
186.75,13.08,0.149
186.76,13.14,0.149
186.77,13.21,0.149
186.78,13.28,0.149
186.80,13.34,0.149
186.81,13.41,0.149
186.83,13.48,0.149
186.84,13.55,0.149
186.85,13.61,0.149
186.87,13.68,0.149
186.88,13.74,0.149
186.89,13.81,0.149
186.90,13.88,0.149
186.92,13.95,0.149
186.93,14.01,0.149
186.95,14.08,0.149
186.96,14.14,0.149
186.97,14.21,0.149
186.98,14.28,0.149
187.00,14.35,0.149
187.01,14.41,0.149
187.03,14.48,0.149
187.04,14.55,0.149
187.05,14.61,0.149
187.07,14.68,0.149
187.08,14.74,0.149
187.09,14.81,0.149
187.10,14.88,0.149
187.12,14.95,0.149
187.13,15.01,0.149
187.15,15.08,0.149
187.16,15.15,0.149
187.17,15.21,0.149
187.18,15.28,0.149
187.20,15.35,0.149
187.21,15.41,0.149
187.23,15.48,0.149
187.24,15.55,0.149
187.25,15.61,0.149
187.27,15.68,0.149
187.28,15.75,0.149
187.29,15.81,0.149
187.30,15.88,0.149
187.32,15.95,0.149
187.33,16.01,0.149
187.35,16.08,0.149
187.36,16.15,0.149
187.37,16.21,0.149
187.38,16.28,0.150
187.40,16.35,0.150
187.41,16.41,0.150
187.43,16.48,0.150
187.44,16.55,0.150
187.45,16.61,0.150
187.47,16.68,0.150
187.48,16.75,0.150
187.49,16.81,0.150
187.50,16.88,0.150
187.52,16.95,0.150
187.53,17.01,0.150
187.55,17.08,0.150
187.56,17.15,0.150
187.57,17.21,0.150
187.58,17.28,0.150
187.60,17.35,0.150
187.61,17.41,0.150
187.63,17.48,0.150
187.64,17.55,0.150
187.65,17.61,0.150
187.67,17.68,0.150
187.68,17.75,0.150
187.69,17.81,0.150
187.70,17.88,0.150
187.72,17.95,0.150
187.73,18.01,0.150
187.75,18.08,0.150
187.76,18.15,0.150
187.77,18.21,0.150
187.78,18.28,0.150
187.80,18.35,0.150
187.81,18.41,0.150
187.83,18.48,0.150
187.84,18.55,0.150
187.85,18.61,0.150
187.87,18.68,0.150
187.88,18.75,0.150
187.89,18.82,0.150
187.90,18.88,0.150
187.92,18.95,0.150
187.93,19.02,0.150
187.95,19.08,0.150
187.96,19.15,0.150
187.97,19.21,0.150
187.98,19.28,0.150
188.00,19.35,0.150
188.01,19.41,0.150
188.03,19.48,0.150
188.04,19.55,0.150
188.05,19.62,0.150
188.07,19.68,0.150
188.08,19.75,0.150
188.09,19.82,0.151
188.10,19.88,0.151
188.12,19.95,0.151
188.13,20.02,0.151
188.15,20.08,0.151
188.16,20.15,0.151
188.17,20.22,0.151
188.18,20.28,0.151
188.20,20.35,0.151
188.21,20.42,0.151
188.23,20.48,0.151
188.24,20.55,0.151
188.25,20.62,0.151
188.27,20.69,0.151
188.28,20.75,0.151
188.29,20.82,0.151
188.30,20.88,0.151
188.32,20.95,0.151
188.33,21.02,0.151
188.35,21.08,0.151
188.36,21.15,0.151
188.37,21.22,0.151
188.38,21.28,0.151
188.40,21.35,0.151
188.41,21.42,0.151
188.43,21.48,0.151
188.44,21.55,0.151
188.45,21.62,0.151
188.47,21.69,0.151
188.48,21.75,0.151
188.49,21.82,0.151
188.50,21.88,0.151
188.52,21.95,0.151
188.53,22.02,0.151
188.55,22.09,0.151
188.56,22.15,0.151
188.57,22.22,0.151
188.58,22.29,0.151
188.60,22.35,0.151
188.61,22.42,0.151
188.63,22.49,0.151
188.64,22.55,0.151
188.65,22.62,0.151
188.67,22.69,0.151
188.68,22.75,0.151
188.69,22.82,0.152
188.70,22.89,0.152
188.72,22.95,0.152
188.73,23.02,0.152
188.75,23.08,0.152
188.76,23.15,0.152
188.77,23.22,0.152
188.78,23.29,0.152
188.80,23.35,0.152
188.81,23.42,0.152
188.83,23.49,0.152
188.84,23.55,0.152
188.85,23.62,0.152
188.87,23.69,0.152
188.88,23.75,0.152
188.89,23.82,0.152
188.90,23.89,0.152
188.92,23.95,0.152
188.93,24.02,0.152
188.95,24.09,0.152
188.96,24.15,0.152
188.97,24.22,0.152
188.98,24.29,0.152
189.00,24.35,0.152
189.01,24.42,0.152
189.03,24.49,0.152
189.04,24.55,0.152
189.05,24.62,0.152
189.07,24.69,0.152
189.08,24.75,0.152
189.09,24.82,0.152
189.10,24.89,0.152
189.12,24.95,0.152
189.13,25.02,0.152
189.15,25.09,0.152
189.16,25.15,0.152
189.17,25.22,0.152
189.18,25.29,0.152
189.20,25.35,0.152
189.21,25.42,0.152
189.23,25.49,0.152
189.24,25.55,0.152
189.25,25.62,0.152
189.27,25.69,0.152
189.28,25.75,0.153
189.29,25.82,0.153
189.30,25.89,0.152
189.32,25.95,0.153
189.33,26.02,0.153
189.35,26.09,0.153
189.36,26.15,0.153
189.37,26.22,0.153
189.38,26.29,0.153
189.40,26.35,0.153
189.41,26.42,0.153
189.43,26.49,0.153
189.44,26.56,0.153
189.45,26.62,0.153
189.47,26.69,0.153
189.48,26.76,0.153
189.49,26.82,0.153
189.50,26.89,0.153
189.52,26.95,0.153
189.53,27.02,0.153
189.55,27.09,0.153
189.56,27.15,0.153
189.57,27.22,0.153
189.58,27.29,0.153
189.60,27.36,0.153
189.61,27.42,0.153
189.63,27.49,0.153
189.64,27.55,0.153
189.65,27.62,0.153
189.67,27.69,0.153
189.68,27.75,0.153
189.69,27.82,0.153
189.70,27.89,0.153
189.72,27.96,0.153
189.73,28.02,0.153
189.75,28.09,0.153
189.76,28.16,0.153
189.77,28.22,0.153
189.78,28.29,0.153
189.80,28.36,0.153
189.81,28.42,0.153
189.83,28.49,0.153
189.84,28.56,0.153
189.85,28.62,0.153
189.87,28.69,0.153
189.88,28.76,0.153
189.89,28.82,0.153
189.90,28.89,0.154
189.92,28.96,0.154
189.93,29.02,
189.95,29.09,
189.96,29.16,
189.97,29.22,
189.98,,