File: DSC/2025_05_08_THC_Sorbic_Acid_Slurry_n60C_150C_5Cmin_x3.csv
Filename,2025_05_08_THC_Sorbic_Acid_Slurry_n60C_150C_5Cmin_x3
Instrument name,DSC2A-00468 (192.168.1.100)
Operator,Yarger
rundate,5/8/2025
Sample name,2025_05_08_THC_Sorbic_Acid_Slurry_n60C_150C_5Cmin_x3
proceduresegments,Data Off ; Equilibrate -60.00 °C; Data On ; Ramp 5.00 °C/min to 150.00 °C; Data Off ; Isothermal 1.0 min; Data On ; Ramp 5.00 °C/min to -60.00 °C; Data Off ; Isothermal 1.0 min; Data On ; Ramp 5.00 °C/min to 150.00 °C; Data Off ; Isothermal 1.0 min; Data On ; Ramp 5.00 °C/min to -60.00 °C; Data Off ; Isothermal 1.0 min; Data On ; Ramp 5.00 °C/min to 30.00 °C
[File Parameters]
Run date,5/8/2025 11:18:35 PM
Trios version,5.1.1.46572
Original File Name,
Current File Name,D:\DSC2500\JYarger\2025_05_08_THC_Sorbic_Acid_Slurry_n60C_150C_5Cmin_x3.tri
[Procedure]
Procedure Name,THC_SA_n60C_150C_5Cmin_x3
Sample Name,2025_05_08_THC_Sorbic_Acid_Slurry_n60C_150C_5Cmin_x3
Sample Mass,3.47 mg
Reference Sample Mass,0 mg
Pan Mass,56.82 mg
Pan Number,30
Reference Pan Mass,57.13 mg
Reference Pan Number,37
Pan Type,Tzero Aluminum Hermetic
Comments,Al Hermetic DSC Consumables sealed Pan/Lid. Y2 Tray (Google Sheet: DSC_Samples_Vext_Y2_Tray_May2025)
Project Name,CA
Operator,Yarger
Test,Custom
Unload Max Temperature,30
Unload Min Temperature,30
Load Max Temperature,30
Load Min Temperature,30
Stop on Gas Flow Error,Yes
[Signal List]
Signal #1,Time (min)
Signal #2,Temperature (°C)
Signal #3,Heat Flow (mW)
Signal #4,Delta T (µV)
Signal #5,Delta Tzero (µV)
Signal #6,Tzero Temperature (°C)
Signal #7,Cell Purge (mL/min)
Signal #8,Heater Temp (°C)
Signal #9,Power Delivered (W)
Signal #10,Reference Junction Temperature (°C)
Signal #11,Flange Temperature (°C)
Signal #12,Heat Flow Phase (rad)
Signal #13,Total Heat Capacity (J/°C)
Signal #14,Heat Capacity (J/°C)
[Configuration]
Company Name,ASU
Instrument Name,DSC2A-00468
Instrument Type,DSC2500
Serial Number,DSC2A-00468
IP,192.168.1.100
Location of Instrument,MRRC
DisplayType,Unknown
Sample Interval ,0.1 s/pt
Selected Heat Flow,T4P
Exotherm Direction,Down
Cell Serial,DRC2-00792
Lid Type,Standard
Cooler,RCS 90
Leave Cooler on at End of Sequence,On
Gas 2,Nitrogen
Gas Selected,Channel 1
Flow Rate,50 mL/min
Secondary Purge,On
Licensed Heat Flow,Heat Flow T4P
Modulation Licensed,Yes
[Versions]
Common IDD Version,1
Cortex Version,VER 2.10.2.31
Driver,5.0.0.6
GDM Version,1.0.3.3
TouchscreenVersion,1.0.0.16145
FEP Version,1.2.1.21
FEP Bootloader,2.0.0.5
AutoSampler Version,2.1.1.26
Auto Sampler Bootloader,2.0.0.5
FCM Version,1.1.0.3
FCM Bootloader,2.0.0.5
[Experiment Logs]
Experiment Log Entry # 1,Data On set to 0
Experiment Log Entry # 3,Equilibrate Segment -60 (C) Started
Experiment Log Entry # 5,Air Cool is off.
Experiment Log Entry # 7,Data On set to 1
Experiment Log Entry # 9,Ramp Segment 5 C/min to 150 Started
Experiment Log Entry # 11,Data On set to 0
Experiment Log Entry # 13,Isothermal Segment 1 min started
Experiment Log Entry # 15,Data On set to 1
Experiment Log Entry # 17,Ramp Segment 5 C/min to -60 Started
Experiment Log Entry # 19,Data On set to 0
Experiment Log Entry # 21,Isothermal Segment 1 min started
Experiment Log Entry # 23,Data On set to 1
Experiment Log Entry # 25,Ramp Segment 5 C/min to 150 Started
Experiment Log Entry # 27,Data On set to 0
Experiment Log Entry # 29,Isothermal Segment 1 min started
Experiment Log Entry # 31,Data On set to 1
Experiment Log Entry # 33,Ramp Segment 5 C/min to -60 Started
Experiment Log Entry # 35,Data On set to 0
Experiment Log Entry # 37,Isothermal Segment 1 min started
Experiment Log Entry # 39,Data On set to 1
Experiment Log Entry # 41,Ramp Segment 5 C/min to 30 Started
[Method Log]
Method Log Entry # 1,Data Off
Method Log Entry # 2,Equilibrate -60 °C
Method Log Entry # 3,Data On
Method Log Entry # 4,(Ramp 424293) Ramp 5 °C/minute to 150 °C
Method Log Entry # 5,Data Off
Method Log Entry # 6,Isothermal 1 minutes
Method Log Entry # 7,Data On
Method Log Entry # 8,(Ramp 424297) Ramp 5 °C/minute to -60 °C
Method Log Entry # 9,Data Off
Method Log Entry # 10,Isothermal 1 minutes
Method Log Entry # 11,Data On
Method Log Entry # 12,(Ramp 424301) Ramp 5 °C/minute to 150 °C
Method Log Entry # 13,Data Off
Method Log Entry # 14,Isothermal 1 minutes
Method Log Entry # 15,Data On
Method Log Entry # 16,(Ramp 424305) Ramp 5 °C/minute to -60 °C
Method Log Entry # 17,Data Off
Method Log Entry # 18,Isothermal 1 minutes
Method Log Entry # 19,Data On
Method Log Entry # 20,(Ramp 424309) Ramp 5 °C/minute to 30 °C
Cell Serial,DRC2-00792
[T1 Calibration]
Slope,-0.008529666
Offset,9.636258
Initial Temperature,98.23
GUID,f8bfdadc-4977-4fdf-ba6d-0ba9134940c3
[TZero Calibration]
Date Applied,11/29/2022 4:06:13 PM
Description,From -89.059 °C to 396.009 °C at 20.000°C/min
Gas Type,Nitrogen
Pan Type,None
Source Files 1,C:\Users\yargerlab\Desktop\DSC Data\General\TZero_calibration_11_29_22_2nd(2).tri
Source Files 2,C:\Users\yargerlab\Desktop\DSC Data\General\TZero_calibration_11_29_22_2nd(3).tri
Delta T Offset,13.05235
Delta T Slope,-0.007271007
Delta T0 Offset,-13.69128
Delta T0 Slope,0.06063341
[Temperature Calibration]
Date Applied,11/29/2022 7:12:28 PM
Description,From 106.590 °C to 186.590 °C at 10.000°C/min
Gas Type,Nitrogen
Pan Type,Tzero Aluminum Hermetic
Source Files 1,C:\Users\yargerlab\Desktop\DSC Data\General\Indium(6).tri
Measured 1,157.391
Known 1,156.598
[Cell Constant Calibration]
Date Applied,11/29/2022 7:12:29 PM
Description,From 106.590 °C to 186.590 °C at 10.000°C/min
Gas Type,Nitrogen
Pan Type,Tzero Aluminum Hermetic
Source Files 1,C:\Users\yargerlab\Desktop\DSC Data\General\Indium(6).tri
T4P KCell,1.006051
Onset Slope,63.26126 mW/°C
[Direct Cp Calibration]
Date Applied,11/30/2022 11:04:51 AM
Description,From -79.983 °C to 298.409 °C at 10.000°C/min
Gas Type,Nitrogen
Pan Type,Tzero Aluminum Hermetic
Source Files 1,C:\Users\yargerlab\Desktop\DSC Data\General\Sapphire_Heat_Capacity_11_30_22.tri
[Rev Cp Calibration]
Date Applied,11/30/2022 1:58:51 PM
Description,From -79.996 °C to 292.812 °C at 3.000°C/min
Gas Type,Nitrogen
Pan Type,Tzero Aluminum Hermetic
Source Files 1,C:\Users\yargerlab\Desktop\DSC Data\General\Sapphire_MDSC_Calibration_11_30_22.tri
[step]
Ramp 5.00 °C/min to 150.00 °C
Time,Temperature,Heat Flow (Normalized)
min,°C,W/g
0.00,-59.67,-0.087
0.03,-59.69,-0.086
0.06,-59.69,-0.074
0.08,-59.66,-0.068
0.11,-59.61,-0.066
0.14,-59.52,-0.062
0.17,-59.43,-0.048
0.20,-59.33,-0.029
0.23,-59.22,-0.011
0.26,-59.10,0.005
0.28,-58.98,0.020
0.31,-58.86,0.030
0.34,-58.74,0.039
0.37,-58.61,0.046
0.40,-58.48,0.053
0.43,-58.35,0.058
0.45,-58.22,0.064
0.48,-58.09,0.067
0.51,-57.96,0.070
0.54,-57.82,0.073
0.57,-57.68,0.074
0.60,-57.55,0.076
0.62,-57.41,0.078
0.65,-57.27,0.079
0.68,-57.14,0.080
0.71,-57.00,0.081
0.74,-56.86,0.082
0.77,-56.72,0.083
0.79,-56.59,0.084
0.82,-56.45,0.085
0.85,-56.31,0.085
0.88,-56.17,0.086
0.91,-56.03,0.087
0.93,-55.89,0.087
0.96,-55.75,0.088
0.99,-55.61,0.088
1.02,-55.47,0.089
1.05,-55.33,0.089
1.08,-55.19,0.090
1.11,-55.05,0.090
1.13,-54.91,0.090
1.16,-54.77,0.091
1.19,-54.63,0.091
1.22,-54.49,0.091
1.25,-54.35,0.091
1.28,-54.21,0.091
1.30,-54.07,0.091
1.33,-53.92,0.092
1.36,-53.78,0.092
1.39,-53.64,0.092
1.42,-53.50,0.092
1.44,-53.36,0.092
1.47,-53.22,0.092
1.50,-53.08,0.092
1.53,-52.94,0.092
1.56,-52.80,0.092
1.59,-52.66,0.092
1.62,-52.52,0.092
1.64,-52.37,0.092
1.67,-52.23,0.092
1.70,-52.09,0.092
1.73,-51.95,0.092
1.76,-51.81,0.092
1.78,-51.67,0.092
1.81,-51.53,0.092
1.84,-51.39,0.092
1.87,-51.24,0.092
1.90,-51.10,0.092
1.93,-50.96,0.092
1.96,-50.82,0.092
1.98,-50.68,0.092
2.01,-50.54,0.092
2.04,-50.40,0.092
2.07,-50.25,0.092
2.10,-50.11,0.092
2.13,-49.97,0.092
2.15,-49.83,0.092
2.18,-49.69,0.092
2.21,-49.55,0.092
2.24,-49.40,0.092
2.27,-49.26,0.092
2.29,-49.12,0.092
2.32,-48.98,0.092
2.35,-48.84,0.092
2.38,-48.70,0.092
2.41,-48.56,0.092
2.44,-48.42,0.092
2.46,-48.27,0.092
2.49,-48.13,0.092
2.52,-47.99,0.092
2.55,-47.85,0.092
2.58,-47.71,0.092
2.61,-47.57,0.092
2.64,-47.43,0.092
2.66,-47.28,0.091
2.69,-47.14,0.091
2.72,-47.00,0.091
2.75,-46.86,0.091
2.78,-46.72,0.091
2.81,-46.58,0.091
2.83,-46.43,0.091
2.86,-46.29,0.091
2.89,-46.15,0.091
2.92,-46.01,0.091
2.95,-45.87,0.091
2.98,-45.72,0.091
3.00,-45.58,0.091
3.03,-45.44,0.091
3.06,-45.30,0.091
3.09,-45.16,0.091
3.12,-45.02,0.091
3.14,-44.88,0.091
3.17,-44.73,0.091
3.20,-44.59,0.091
3.23,-44.45,0.091
3.26,-44.31,0.091
3.29,-44.17,0.091
3.31,-44.03,0.091
3.34,-43.88,0.091
3.37,-43.74,0.091
3.40,-43.60,0.091
3.43,-43.46,0.091
3.46,-43.32,0.091
3.49,-43.18,0.090
3.51,-43.03,0.090
3.54,-42.89,0.090
3.57,-42.75,0.090
3.60,-42.61,0.090
3.63,-42.47,0.090
3.66,-42.32,0.090
3.68,-42.18,0.090
3.71,-42.04,0.090
3.74,-41.90,0.090
3.77,-41.76,0.090
3.80,-41.61,0.090
3.83,-41.47,0.090
3.85,-41.33,0.090
3.88,-41.19,0.090
3.91,-41.05,0.090
3.94,-40.91,0.090
3.97,-40.76,0.090
3.99,-40.62,0.090
4.02,-40.48,0.090
4.05,-40.34,0.090
4.08,-40.19,0.090
4.11,-40.05,0.090
4.14,-39.91,0.090
4.16,-39.77,0.090
4.19,-39.63,0.090
4.22,-39.49,0.090
4.25,-39.35,0.090
4.28,-39.20,0.090
4.31,-39.06,0.090
4.34,-38.92,0.090
4.36,-38.78,0.090
4.39,-38.64,0.090
4.42,-38.49,0.090
4.45,-38.35,0.090
4.48,-38.21,0.090
4.50,-38.07,0.090
4.53,-37.93,0.090
4.56,-37.78,0.090
4.59,-37.64,0.090
4.62,-37.50,0.090
4.65,-37.36,0.090
4.68,-37.22,0.090
4.70,-37.08,0.090
4.73,-36.93,0.090
4.76,-36.79,0.089
4.79,-36.65,0.089
4.82,-36.51,0.089
4.85,-36.37,0.089
4.87,-36.23,0.090
4.90,-36.08,0.089
4.93,-35.94,0.089
4.96,-35.80,0.089
4.99,-35.66,0.089
5.01,-35.52,0.089
5.04,-35.38,0.089
5.07,-35.24,0.089
5.10,-35.09,0.089
5.13,-34.95,0.089
5.16,-34.81,0.089
5.19,-34.67,0.089
5.21,-34.52,0.089
5.24,-34.38,0.089
5.27,-34.24,0.089
5.30,-34.10,0.089
5.33,-33.96,0.089
5.35,-33.81,0.089
5.38,-33.67,0.089
5.41,-33.53,0.089
5.44,-33.39,0.089
5.47,-33.25,0.089
5.50,-33.10,0.089
5.53,-32.96,0.089
5.55,-32.82,0.089
5.58,-32.68,0.089
5.61,-32.54,0.090
5.64,-32.39,0.089
5.67,-32.25,0.089
5.70,-32.11,0.089
5.72,-31.97,0.089
5.75,-31.83,0.090
5.78,-31.68,0.090
5.81,-31.54,0.090
5.84,-31.40,0.090
5.86,-31.26,0.090
5.89,-31.12,0.090
5.92,-30.98,0.089
5.95,-30.83,0.089
5.98,-30.69,0.089
6.01,-30.55,0.089
6.04,-30.41,0.089
6.06,-30.26,0.089
6.09,-30.12,0.089
6.12,-29.98,0.089
6.15,-29.84,0.089
6.18,-29.70,0.089
6.20,-29.56,0.089
6.23,-29.41,0.089
6.26,-29.27,0.089
6.29,-29.13,0.089
6.32,-28.99,0.089
6.35,-28.85,0.089
6.38,-28.71,0.089
6.40,-28.56,0.089
6.43,-28.42,0.089
6.46,-28.28,0.089
6.49,-28.14,0.089
6.52,-28.00,0.089
6.55,-27.86,0.089
6.57,-27.71,0.089
6.60,-27.57,0.089
6.63,-27.43,0.089
6.66,-27.29,0.089
6.69,-27.15,0.089
6.71,-27.00,0.089
6.74,-26.86,0.089
6.77,-26.72,0.089
6.80,-26.57,0.089
6.83,-26.43,0.089
6.86,-26.29,0.089
6.89,-26.15,0.089
6.91,-26.01,0.089
6.94,-25.87,0.089
6.97,-25.73,0.089
7.00,-25.59,0.089
7.03,-25.45,0.089
7.05,-25.30,0.089
7.08,-25.16,0.089
7.11,-25.02,0.089
7.14,-24.88,0.089
7.17,-24.73,0.089
7.20,-24.59,0.089
7.23,-24.45,0.089
7.25,-24.31,0.089
7.28,-24.17,0.089
7.31,-24.03,0.089
7.34,-23.88,0.089
7.37,-23.75,0.089
7.40,-23.60,0.089
7.42,-23.46,0.089
7.45,-23.32,0.089
7.48,-23.18,0.089
7.51,-23.03,0.089
7.54,-22.89,0.089
7.56,-22.75,0.089
7.59,-22.61,0.089
7.62,-22.47,0.089
7.65,-22.33,0.089
7.68,-22.18,0.089
7.71,-22.04,0.089
7.74,-21.90,0.089
7.76,-21.76,0.089
7.79,-21.62,0.089
7.82,-21.47,0.089
7.85,-21.33,0.089
7.88,-21.19,0.089
7.90,-21.05,0.089
7.93,-20.91,0.089
7.96,-20.76,0.089
7.99,-20.62,0.089
8.02,-20.48,0.089
8.05,-20.34,0.089
8.08,-20.20,0.089
8.10,-20.05,0.089
8.13,-19.91,0.089
8.16,-19.77,0.089
8.19,-19.63,0.089
8.22,-19.49,0.089
8.25,-19.35,0.089
8.27,-19.21,0.089
8.30,-19.06,0.089
8.33,-18.92,0.089
8.36,-18.78,0.089
8.39,-18.64,0.089
8.41,-18.50,0.089
8.44,-18.35,0.089
8.47,-18.21,0.089
8.50,-18.07,0.090
8.53,-17.93,0.090
8.56,-17.79,0.090
8.58,-17.64,0.089
8.61,-17.50,0.090
8.64,-17.36,0.090
8.67,-17.22,0.089
8.70,-17.08,0.090
8.73,-16.94,0.090
8.75,-16.79,0.090
8.78,-16.65,0.090
8.81,-16.51,0.090
8.84,-16.37,0.089
8.87,-16.23,0.089
8.90,-16.09,0.089
8.93,-15.94,0.089
8.95,-15.80,0.089
8.98,-15.66,0.090
9.01,-15.52,0.090
9.04,-15.38,0.089
9.07,-15.24,0.090
9.10,-15.09,0.090
9.12,-14.95,0.090
9.15,-14.81,0.090
9.18,-14.67,0.090
9.21,-14.52,0.090
9.24,-14.38,0.090
9.27,-14.24,0.089
9.29,-14.10,0.089
9.32,-13.95,0.090
9.35,-13.81,0.090
9.38,-13.67,0.090
9.41,-13.53,0.090
9.43,-13.39,0.090
9.46,-13.25,0.090
9.49,-13.10,0.090
9.52,-12.96,0.090
9.55,-12.82,0.090
9.58,-12.68,0.090
9.60,-12.54,0.090
9.63,-12.39,0.090
9.66,-12.25,0.090
9.69,-12.11,0.090
9.72,-11.97,0.090
9.75,-11.83,0.090
9.78,-11.69,0.090
9.80,-11.55,0.090
9.83,-11.41,0.090
9.86,-11.26,0.090
9.89,-11.12,0.090
9.92,-10.98,0.090
9.95,-10.84,0.091
9.97,-10.70,0.091
10.00,-10.56,0.091
10.03,-10.41,0.091
10.06,-10.27,0.091
10.09,-10.13,0.091
10.12,-9.99,0.091
10.14,-9.85,0.091
10.17,-9.70,0.091
10.20,-9.56,0.091
10.23,-9.42,0.091
10.26,-9.28,0.091
10.28,-9.14,0.091
10.31,-9.00,0.092
10.34,-8.85,0.092
10.37,-8.71,0.092
10.40,-8.57,0.092
10.43,-8.43,0.092
10.45,-8.29,0.092
10.48,-8.15,0.092
10.51,-8.01,0.092
10.54,-7.86,0.093
10.57,-7.72,0.093
10.60,-7.58,0.093
10.63,-7.44,0.093
10.65,-7.30,0.093
10.68,-7.15,0.093
10.71,-7.01,0.094
10.74,-6.87,0.094
10.77,-6.73,0.094
10.80,-6.59,0.094
10.82,-6.45,0.094
10.85,-6.30,0.094
10.88,-6.16,0.095
10.91,-6.02,0.095
10.94,-5.88,0.095
10.97,-5.74,0.095
10.99,-5.60,0.095
11.02,-5.45,0.096
11.05,-5.31,0.096
11.08,-5.17,0.096
11.11,-5.03,0.096
11.13,-4.89,0.096
11.16,-4.75,0.097
11.19,-4.60,0.097
11.22,-4.46,0.097
11.25,-4.32,0.097
11.28,-4.18,0.098
11.30,-4.04,0.098
11.33,-3.90,0.098
11.36,-3.75,0.098
11.39,-3.61,0.098
11.42,-3.47,0.099
11.45,-3.33,0.099
11.48,-3.19,0.099
11.50,-3.04,0.099
11.53,-2.90,0.099
11.56,-2.76,0.100
11.59,-2.62,0.100
11.62,-2.48,0.100
11.65,-2.33,0.100
11.67,-2.19,0.100
11.70,-2.05,0.101
11.73,-1.91,0.101
11.76,-1.77,0.101
11.79,-1.63,0.101
11.82,-1.49,0.101
11.84,-1.34,0.101
11.87,-1.20,0.101
11.90,-1.06,0.101
11.93,-0.92,0.101
11.96,-0.78,0.101
11.98,-0.64,0.101
12.01,-0.49,0.101
12.04,-0.35,0.101
12.07,-0.21,0.101
12.10,-0.07,0.101
12.13,0.08,0.101
12.15,0.22,0.101
12.18,0.36,0.101
12.21,0.50,0.101
12.24,0.64,0.101
12.27,0.78,0.101
12.30,0.93,0.101
12.33,1.07,0.101
12.35,1.21,0.101
12.38,1.35,0.101
12.41,1.49,0.101
12.44,1.63,0.101
12.47,1.78,0.101
12.50,1.92,0.101
12.52,2.06,0.101
12.55,2.20,0.101
12.58,2.34,0.101
12.61,2.49,0.101
12.64,2.63,0.101
12.67,2.77,0.101
12.69,2.91,0.101
12.72,3.05,0.101
12.75,3.19,0.101
12.78,3.34,0.101
12.81,3.48,0.101
12.83,3.62,0.101
12.86,3.76,0.101
12.89,3.90,0.101
12.92,4.05,0.101
12.95,4.19,0.101
12.98,4.33,0.101
13.00,4.47,0.101
13.03,4.61,0.101
13.06,4.75,0.101
13.09,4.90,0.101
13.12,5.04,0.101
13.15,5.18,0.101
13.18,5.32,0.101
13.20,5.46,0.101
13.23,5.60,0.101
13.26,5.75,0.101
13.29,5.89,0.101
13.32,6.03,0.101
13.35,6.17,0.101
13.37,6.31,0.101
13.40,6.45,0.101
13.43,6.60,0.101
13.46,6.74,0.101
13.49,6.88,0.101
13.52,7.02,0.101
13.54,7.16,0.101
13.57,7.31,0.101
13.60,7.45,0.101
13.63,7.59,0.101
13.66,7.73,0.101
13.68,7.87,0.101
13.71,8.02,0.101
13.74,8.16,0.101
13.77,8.30,0.101
13.80,8.44,0.101
13.83,8.58,0.101
13.85,8.73,0.101
13.88,8.87,0.101
13.91,9.01,0.101
13.94,9.15,0.101
13.97,9.29,0.101
14.00,9.43,0.101
14.03,9.58,0.101
14.05,9.72,0.101
14.08,9.86,0.101
14.11,10.00,0.101
14.14,10.14,0.101
14.17,10.28,0.101
14.20,10.43,0.101
14.22,10.57,0.101
14.25,10.71,0.101
14.28,10.85,0.101
14.31,10.99,0.101
14.34,11.14,0.101
14.37,11.28,0.101
14.39,11.42,0.101
14.42,11.56,0.101
14.45,11.70,0.101
14.48,11.84,0.101
14.51,11.99,0.101
14.53,12.13,0.101
14.56,12.27,0.101
14.59,12.41,0.101
14.62,12.55,0.102
14.65,12.70,0.102
14.68,12.84,0.102
14.70,12.98,0.102
14.73,13.12,0.102
14.76,13.26,0.102
14.79,13.40,0.102
14.82,13.54,0.102
14.85,13.69,0.102
14.88,13.83,0.102
14.90,13.97,0.102
14.93,14.11,0.102
14.96,14.25,0.102
14.99,14.40,0.102
15.02,14.54,0.102
15.05,14.68,0.102
15.07,14.82,0.102
15.10,14.96,0.102
15.13,15.10,0.102
15.16,15.25,0.102
15.19,15.39,0.102
15.22,15.53,0.102
15.24,15.67,0.102
15.27,15.81,0.102
15.30,15.95,0.102
15.33,16.10,0.102
15.36,16.24,0.102
15.38,16.38,0.102
15.41,16.52,0.102
15.44,16.66,0.102
15.47,16.81,0.102
15.50,16.95,0.102
15.53,17.09,0.102
15.55,17.23,0.102
15.58,17.37,0.102
15.61,17.51,0.102
15.64,17.66,0.103
15.67,17.80,0.103
15.70,17.94,0.103
15.73,18.08,0.103
15.75,18.22,0.103
15.78,18.37,0.103
15.81,18.51,0.103
15.84,18.65,0.103
15.87,18.79,0.103
15.90,18.93,0.103
15.92,19.07,0.103
15.95,19.21,0.103
15.98,19.36,0.103
16.01,19.50,0.103
16.04,19.64,0.103
16.07,19.78,0.103
16.09,19.92,0.103
16.12,20.07,0.103
16.15,20.21,0.103
16.18,20.35,0.103
16.21,20.49,0.103
16.23,20.63,0.103
16.26,20.77,0.103
16.29,20.92,0.103
16.32,21.06,0.103
16.35,21.20,0.103
16.38,21.34,0.103
16.40,21.48,0.103
16.43,21.62,0.103
16.46,21.77,0.104
16.49,21.91,0.104
16.52,22.05,0.104
16.55,22.19,0.104
16.58,22.33,0.104
16.60,22.47,0.104
16.63,22.62,0.104
16.66,22.76,0.104
16.69,22.90,0.104
16.72,23.04,0.104
16.75,23.18,0.104
16.77,23.33,0.104
16.80,23.47,0.104
16.83,23.61,0.104
16.86,23.75,0.104
16.89,23.89,0.104
16.92,24.03,0.105
16.94,24.18,0.105
16.97,24.32,0.105
17.00,24.46,0.105
17.03,24.60,0.105
17.06,24.74,0.105
17.08,24.89,0.105
17.11,25.03,0.105
17.14,25.17,0.105
17.17,25.31,0.105
17.20,25.45,0.105
17.23,25.59,0.105
17.26,25.74,0.105
17.28,25.88,0.106
17.31,26.02,0.106
17.34,26.16,0.106
17.37,26.30,0.106
17.40,26.44,0.106
17.43,26.59,0.106
17.45,26.73,0.106
17.48,26.87,0.106
17.51,27.01,0.106
17.54,27.15,0.106
17.57,27.30,0.107
17.59,27.44,0.107
17.62,27.58,0.107
17.65,27.72,0.107
17.68,27.86,0.107
17.71,28.00,0.107
17.74,28.15,0.107
17.77,28.29,0.107
17.79,28.43,0.107
17.82,28.57,0.107
17.85,28.71,0.107
17.88,28.85,0.107
17.91,29.00,0.107
17.93,29.14,0.107
17.96,29.28,0.108
17.99,29.42,0.108
18.02,29.56,0.108
18.05,29.71,0.108
18.08,29.85,0.108
18.11,29.99,0.108
18.13,30.13,0.108
18.16,30.27,0.108
18.19,30.41,0.108
18.22,30.56,0.108
18.25,30.70,0.108
18.28,30.84,0.108
18.30,30.98,0.108
18.33,31.12,0.108
18.36,31.26,0.109
18.39,31.41,0.109
18.42,31.55,0.109
18.44,31.69,0.109
18.47,31.83,0.109
18.50,31.97,0.109
18.53,32.11,0.109
18.56,32.26,0.109
18.59,32.40,0.109
18.62,32.54,0.109
18.64,32.68,0.109
18.67,32.82,0.109
18.70,32.97,0.109
18.73,33.11,0.109
18.76,33.25,0.109
18.78,33.39,0.109
18.81,33.53,0.109
18.84,33.68,0.109
18.87,33.82,0.109
18.90,33.96,0.110
18.93,34.10,0.110
18.96,34.24,0.110
18.98,34.38,0.110
19.01,34.53,0.110
19.04,34.67,0.110
19.07,34.81,0.110
19.10,34.95,0.110
19.13,35.09,0.110
19.15,35.24,0.110
19.18,35.38,0.110
19.21,35.52,0.110
19.24,35.66,0.110
19.27,35.80,0.110
19.29,35.94,0.110
19.32,36.08,0.110
19.35,36.23,0.110
19.38,36.37,0.110
19.41,36.51,0.110
19.44,36.65,0.110
19.47,36.79,0.110
19.49,36.93,0.110
19.52,37.08,0.110
19.55,37.22,0.111
19.58,37.36,0.111
19.61,37.50,0.111
19.63,37.64,0.111
19.66,37.79,0.111
19.69,37.93,0.111
19.72,38.07,0.111
19.75,38.21,0.111
19.78,38.35,0.111
19.81,38.49,0.111
19.83,38.64,0.111
19.86,38.78,0.111
19.89,38.92,0.111
19.92,39.06,0.111
19.95,39.20,0.111
19.98,39.35,0.111
20.00,39.49,0.111
20.03,39.63,0.111
20.06,39.77,0.111
20.09,39.91,0.111
20.12,40.05,0.111
20.14,40.20,0.111
20.17,40.34,0.112
20.20,40.48,0.112
20.23,40.62,0.112
20.26,40.76,0.112
20.29,40.90,0.112
20.32,41.05,0.112
20.34,41.19,0.112
20.37,41.33,0.112
20.40,41.47,0.112
20.43,41.61,0.112
20.46,41.75,0.112
20.48,41.90,0.112
20.51,42.04,0.112
20.54,42.18,0.112
20.57,42.32,0.112
20.60,42.46,0.112
20.63,42.61,0.112
20.66,42.75,0.112
20.68,42.89,0.112
20.71,43.03,0.112
20.74,43.17,0.112
20.77,43.31,0.112
20.80,43.46,0.112
20.83,43.60,0.112
20.85,43.74,0.113
20.88,43.88,0.113
20.91,44.02,0.113
20.94,44.16,0.113
20.97,44.31,0.113
20.99,44.45,0.113
21.02,44.59,0.113
21.05,44.73,0.113
21.08,44.87,0.113
21.11,45.02,0.113
21.14,45.16,0.113
21.17,45.30,0.113
21.19,45.44,0.113
21.22,45.58,0.113
21.25,45.72,0.114
21.28,45.87,0.114
21.31,46.01,0.114
21.33,46.15,0.114
21.36,46.29,0.114
21.39,46.43,0.114
21.42,46.58,0.114
21.45,46.72,0.114
21.48,46.86,0.114
21.51,47.00,0.114
21.53,47.14,0.114
21.56,47.28,0.114
21.59,47.43,0.114
21.62,47.57,0.114
21.65,47.71,0.115
21.68,47.85,0.115
21.70,47.99,0.115
21.73,48.14,0.115
21.76,48.28,0.115
21.79,48.42,0.115
21.82,48.56,0.115
21.84,48.70,0.115
21.87,48.84,0.115
21.90,48.99,0.115
21.93,49.13,0.115
21.96,49.27,0.115
21.99,49.41,0.115
22.02,49.55,0.115
22.04,49.69,0.116
22.07,49.84,0.116
22.10,49.98,0.116
22.13,50.12,0.116
22.16,50.26,0.116
22.18,50.40,0.116
22.21,50.55,0.116
22.24,50.69,0.116
22.27,50.83,0.116
22.30,50.97,0.116
22.33,51.11,0.116
22.36,51.26,0.116
22.38,51.40,0.116
22.41,51.54,0.116
22.44,51.68,0.116
22.47,51.82,0.116
22.50,51.96,0.116
22.53,52.10,0.116
22.55,52.25,0.117
22.58,52.39,0.117
22.61,52.53,0.117
22.64,52.67,0.117
22.67,52.81,0.117
22.69,52.96,0.117
22.72,53.10,0.117
22.75,53.24,0.117
22.78,53.38,0.117
22.81,53.52,0.117
22.84,53.66,0.117
22.87,53.80,0.117
22.89,53.95,0.117
22.92,54.09,0.117
22.95,54.23,0.117
22.98,54.37,0.117
23.01,54.51,0.117
23.03,54.65,0.118
23.06,54.80,0.118
23.09,54.94,0.118
23.12,55.08,0.118
23.15,55.22,0.118
23.18,55.36,0.118
23.21,55.50,0.118
23.23,55.65,0.118
23.26,55.79,0.118
23.29,55.93,0.118
23.32,56.07,0.118
23.35,56.21,0.118
23.38,56.35,0.118
23.40,56.50,0.119
23.43,56.64,0.119
23.46,56.78,0.119
23.49,56.92,0.119
23.52,57.06,0.119
23.54,57.21,0.119
23.57,57.35,0.119
23.60,57.49,0.119
23.63,57.63,0.119
23.66,57.77,0.119
23.69,57.91,0.119
23.72,58.06,0.119
23.74,58.20,0.120
23.77,58.34,0.120
23.80,58.48,0.120
23.83,58.62,0.120
23.86,58.77,0.120
23.88,58.91,0.120
23.91,59.05,0.120
23.94,59.19,0.120
23.97,59.33,0.120
24.00,59.47,0.120
24.03,59.61,0.120
24.06,59.76,0.120
24.08,59.90,0.121
24.11,60.04,0.121
24.14,60.18,0.121
24.17,60.32,0.121
24.20,60.47,0.121
24.23,60.61,0.121
24.25,60.75,0.121
24.28,60.89,0.121
24.31,61.03,0.121
24.34,61.17,0.121
24.37,61.32,0.121
24.39,61.46,0.122
24.42,61.60,0.122
24.45,61.74,0.122
24.48,61.88,0.122
24.51,62.02,0.122
24.54,62.17,0.122
24.57,62.31,0.122
24.59,62.45,0.122
24.62,62.59,0.122
24.65,62.73,0.122
24.68,62.88,0.123
24.71,63.02,0.123
24.73,63.16,0.123
24.76,63.30,0.123
24.79,63.44,0.123
24.82,63.58,0.123
24.85,63.72,0.123
24.88,63.87,0.123
24.91,64.01,0.123
24.93,64.15,0.123
24.96,64.29,0.123
24.99,64.43,0.123
25.02,64.58,0.124
25.05,64.72,0.124
25.08,64.86,0.124
25.10,65.00,0.124
25.13,65.14,0.124
25.16,65.28,0.124
25.19,65.43,0.124
25.22,65.57,0.124
25.24,65.71,0.124
25.27,65.85,0.124
25.30,65.99,0.125
25.33,66.13,0.125
25.36,66.28,0.125
25.39,66.42,0.125
25.42,66.56,0.125
25.44,66.70,0.125
25.47,66.84,0.125
25.50,66.99,0.125
25.53,67.13,0.125
25.56,67.27,0.126
25.58,67.41,0.126
25.61,67.55,0.126
25.64,67.69,0.126
25.67,67.83,0.126
25.70,67.98,0.126
25.73,68.12,0.126
25.76,68.26,0.126
25.78,68.40,0.126
25.81,68.54,0.127
25.84,68.69,0.127
25.87,68.83,0.127
25.90,68.97,0.127
25.93,69.11,0.127
25.95,69.25,0.127
25.98,69.39,0.127
26.01,69.54,0.127
26.04,69.68,0.127
26.07,69.82,0.127
26.09,69.96,0.128
26.12,70.10,0.128
26.15,70.24,0.128
26.18,70.39,0.128
26.21,70.53,0.128
26.24,70.67,0.128
26.27,70.81,0.128
26.29,70.95,0.128
26.32,71.10,0.128
26.35,71.24,0.129
26.38,71.38,0.129
26.41,71.52,0.129
26.43,71.66,0.129
26.46,71.80,0.129
26.49,71.95,0.129
26.52,72.09,0.130
26.55,72.23,0.130
26.58,72.37,0.130
26.61,72.51,0.130
26.63,72.66,0.130
26.66,72.80,0.130
26.69,72.94,0.130
26.72,73.08,0.130
26.75,73.22,0.130
26.78,73.37,0.131
26.80,73.51,0.131
26.83,73.65,0.131
26.86,73.79,0.131
26.89,73.93,0.131
26.92,74.07,0.131
26.94,74.21,0.131
26.97,74.36,0.131
27.00,74.50,0.132
27.03,74.64,0.132
27.06,74.78,0.132
27.09,74.92,0.132
27.12,75.06,0.132
27.14,75.21,0.132
27.17,75.35,0.132
27.20,75.49,0.132
27.23,75.63,0.133
27.26,75.77,0.133
27.28,75.91,0.133
27.31,76.06,0.133
27.34,76.20,0.133
27.37,76.34,0.134
27.40,76.48,0.134
27.43,76.62,0.134
27.46,76.76,0.134
27.48,76.91,0.134
27.51,77.05,0.134
27.54,77.19,0.134
27.57,77.33,0.135
27.60,77.47,0.135
27.63,77.61,0.135
27.65,77.76,0.135
27.68,77.90,0.135
27.71,78.04,0.135
27.74,78.18,0.135
27.77,78.32,0.136
27.79,78.46,0.136
27.82,78.61,0.136
27.85,78.75,0.136
27.88,78.89,0.136
27.91,79.03,0.136
27.94,79.17,0.137
27.97,79.31,0.137
27.99,79.46,0.137
28.02,79.60,0.137
28.05,79.74,0.137
28.08,79.88,0.137
28.11,80.02,0.137
28.13,80.17,0.138
28.16,80.31,0.138
28.19,80.45,0.138
28.22,80.59,0.138
28.25,80.73,0.138
28.28,80.87,0.138
28.31,81.01,0.139
28.33,81.16,0.139
28.36,81.30,0.139
28.39,81.44,0.139
28.42,81.58,0.139
28.45,81.72,0.139
28.48,81.87,0.140
28.50,82.01,0.140
28.53,82.15,0.140
28.56,82.29,0.140
28.59,82.43,0.140
28.62,82.57,0.140
28.64,82.72,0.141
28.67,82.86,0.141
28.70,83.00,0.141
28.73,83.14,0.141
28.76,83.28,0.141
28.79,83.42,0.141
28.82,83.57,0.142
28.84,83.71,0.142
28.87,83.85,0.142
28.90,83.99,0.142
28.93,84.13,0.142
28.96,84.27,0.143
28.98,84.42,0.143
29.01,84.56,0.143
29.04,84.70,0.143
29.07,84.84,0.143
29.10,84.98,0.144
29.13,85.13,0.144
29.16,85.27,0.144
29.18,85.41,0.144
29.21,85.55,0.144
29.24,85.69,0.144
29.27,85.83,0.145
29.30,85.98,0.145
29.33,86.12,0.145
29.35,86.26,0.145
29.38,86.40,0.145
29.41,86.54,0.146
29.44,86.68,0.146
29.47,86.83,0.146
29.49,86.97,0.146
29.52,87.11,0.146
29.55,87.25,0.147
29.58,87.39,0.147
29.61,87.53,0.147
29.64,87.68,0.147
29.67,87.82,0.148
29.69,87.96,0.148
29.72,88.10,0.148
29.75,88.24,0.148
29.78,88.38,0.149
29.81,88.53,0.149
29.83,88.67,0.149
29.86,88.81,0.149
29.89,88.95,0.150
29.92,89.09,0.150
29.95,89.23,0.150
29.98,89.38,0.150
30.01,89.52,0.151
30.03,89.66,0.151
30.06,89.80,0.151
30.09,89.94,0.152
30.12,90.08,0.152
30.15,90.23,0.152
30.18,90.37,0.153
30.20,90.51,0.153
30.23,90.65,0.153
30.26,90.79,0.153
30.29,90.93,0.154
30.32,91.08,0.154
30.34,91.22,0.154
30.37,91.36,0.155
30.40,91.50,0.155
30.43,91.64,0.155
30.46,91.79,0.155
30.49,91.93,0.156
30.52,92.07,0.156
30.54,92.21,0.156
30.57,92.35,0.157
30.60,92.49,0.157
30.63,92.64,0.157
30.66,92.78,0.158
30.68,92.92,0.158
30.71,93.06,0.158
30.74,93.20,0.159
30.77,93.34,0.159
30.80,93.48,0.159
30.83,93.63,0.160
30.86,93.77,0.160
30.88,93.91,0.161
30.91,94.05,0.161
30.94,94.19,0.161
30.97,94.34,0.162
31.00,94.48,0.162
31.03,94.62,0.163
31.05,94.76,0.163
31.08,94.90,0.163
31.11,95.04,0.164
31.14,95.19,0.164
31.17,95.33,0.165
31.19,95.47,0.165
31.22,95.61,0.166
31.25,95.75,0.166
31.28,95.89,0.166
31.31,96.04,0.167
31.34,96.18,0.167
31.37,96.32,0.168
31.39,96.46,0.168
31.42,96.60,0.169
31.45,96.74,0.169
31.48,96.88,0.170
31.51,97.03,0.170
31.53,97.17,0.170
31.56,97.31,0.171
31.59,97.45,0.171
31.62,97.59,0.172
31.65,97.73,0.172
31.68,97.88,0.173
31.71,98.02,0.173
31.73,98.16,0.174
31.76,98.30,0.174
31.79,98.44,0.175
31.82,98.58,0.176
31.85,98.73,0.176
31.88,98.87,0.177
31.90,99.01,0.177
31.93,99.15,0.178
31.96,99.29,0.178
31.99,99.43,0.179
32.02,99.58,0.179
32.04,99.72,0.180
32.07,99.86,0.181
32.10,100.00,0.181
32.13,100.14,0.182
32.16,100.28,0.182
32.19,100.42,0.183
32.22,100.57,0.184
32.24,100.71,0.184
32.27,100.85,0.185
32.30,100.99,0.186
32.33,101.13,0.186
32.36,101.27,0.187
32.38,101.42,0.188
32.41,101.56,0.188
32.44,101.70,0.189
32.47,101.84,0.190
32.50,101.98,0.191
32.53,102.12,0.191
32.56,102.27,0.192
32.58,102.41,0.193
32.61,102.55,0.193
32.64,102.69,0.194
32.67,102.83,0.195
32.70,102.97,0.196
32.73,103.11,0.197
32.75,103.26,0.198
32.78,103.40,0.198
32.81,103.54,0.200
32.84,103.68,0.200
32.87,103.82,0.201
32.89,103.96,0.202
32.92,104.11,0.203
32.95,104.25,0.204
32.98,104.39,0.205
33.01,104.53,0.206
33.04,104.67,0.207
33.07,104.81,0.208
33.09,104.96,0.209
33.12,105.10,0.210
33.15,105.24,0.211
33.18,105.38,0.212
33.21,105.52,0.213
33.23,105.66,0.214
33.26,105.80,0.215
33.29,105.94,0.216
33.32,106.09,0.217
33.35,106.23,0.218
33.38,106.37,0.219
33.41,106.51,0.221
33.43,106.65,0.222
33.46,106.79,0.223
33.49,106.94,0.225
33.52,107.08,0.226
33.55,107.22,0.228
33.58,107.36,0.229
33.60,107.50,0.231
33.63,107.64,0.232
33.66,107.78,0.235
33.69,107.92,0.236
33.72,108.07,0.238
33.74,108.21,0.240
33.77,108.35,0.244
33.80,108.49,0.249
33.83,108.63,0.250
33.86,108.78,0.251
33.89,108.92,0.252
33.92,109.06,0.253
33.94,109.20,0.254
33.97,109.34,0.255
34.00,109.48,0.256
34.03,109.63,0.257
34.06,109.77,0.258
34.08,109.91,0.259
34.11,110.05,0.260
34.14,110.19,0.261
34.17,110.33,0.263
34.20,110.47,0.265
34.23,110.61,0.266
34.26,110.75,0.268
34.28,110.89,0.270
34.31,111.03,0.271
34.34,111.17,0.273
34.37,111.31,0.275
34.40,111.46,0.278
34.43,111.60,0.281
34.45,111.74,0.284
34.48,111.88,0.287
34.51,112.02,0.289
34.54,112.16,0.291
34.57,112.30,0.294
34.59,112.44,0.296
34.62,112.59,0.298
34.65,112.73,0.301
34.68,112.87,0.305
34.71,113.01,0.308
34.74,113.15,0.313
34.76,113.29,0.319
34.79,113.43,0.323
34.82,113.57,0.326
34.85,113.72,0.330
34.88,113.86,0.332
34.91,114.00,0.336
34.94,114.14,0.341
34.96,114.28,0.343
34.99,114.42,0.350
35.02,114.56,0.354
35.05,114.70,0.355
35.08,114.84,0.357
35.11,114.98,0.359
35.13,115.12,0.361
35.16,115.27,0.363
35.19,115.41,0.367
35.22,115.55,0.371
35.25,115.69,0.381
35.28,115.83,0.396
35.30,115.97,0.399
35.33,116.11,0.400
35.36,116.25,0.401
35.39,116.39,0.406
35.42,116.53,0.410
35.44,116.67,0.413
35.47,116.82,0.415
35.50,116.96,0.418
35.53,117.10,0.420
35.56,117.24,0.424
35.59,117.38,0.432
35.61,117.52,0.444
35.64,117.66,0.455
35.67,117.80,0.459
35.70,117.94,0.461
35.73,118.08,0.462
35.76,118.22,0.465
35.79,118.36,0.469
35.81,118.50,0.473
35.84,118.64,0.496
35.87,118.78,0.493
35.90,118.92,0.493
35.93,119.07,0.496
35.96,119.21,0.498
35.98,119.35,0.502
36.01,119.49,0.508
36.04,119.63,0.512
36.07,119.77,0.520
36.10,119.91,0.528
36.13,120.05,0.538
36.15,120.20,0.542
36.18,120.34,0.545
36.21,120.48,0.549
36.24,120.62,0.555
36.27,120.76,0.562
36.29,120.90,0.572
36.32,121.04,0.581
36.35,121.18,0.589
36.38,121.32,0.598
36.41,121.46,0.610
36.44,121.60,0.619
36.46,121.74,0.630
36.49,121.88,0.637
36.52,122.01,0.648
36.55,122.15,0.653
36.58,122.29,0.656
36.61,122.43,0.659
36.64,122.57,0.664
36.66,122.71,0.673
36.69,122.85,0.752
36.72,122.99,0.746
36.75,123.13,0.743
36.78,123.27,0.742
36.81,123.41,0.743
36.83,123.55,0.745
36.86,123.69,0.761
36.89,123.83,0.783
36.92,123.97,0.797
36.95,124.11,0.793
36.98,124.25,0.790
37.00,124.39,0.789
37.03,124.53,0.810
37.06,124.67,0.805
37.09,124.81,0.804
37.12,124.95,0.803
37.14,125.10,0.803
37.17,125.24,0.803
37.20,125.38,0.803
37.23,125.52,0.803
37.26,125.66,0.802
37.29,125.80,0.802
37.31,125.94,0.802
37.34,126.09,0.801
37.37,126.23,0.801
37.40,126.37,0.800
37.43,126.51,0.799
37.46,126.65,0.798
37.49,126.80,0.797
37.51,126.94,0.796
37.54,127.08,0.793
37.57,127.22,0.788
37.60,127.37,0.784
37.63,127.51,0.777
37.66,127.65,0.768
37.68,127.80,0.757
37.71,127.94,0.744
37.74,128.08,0.731
37.77,128.23,0.719
37.80,128.37,0.705
37.83,128.52,0.689
37.85,128.66,0.672
37.88,128.81,0.654
37.91,128.95,0.636
37.94,129.10,0.617
37.97,129.24,0.600
37.99,129.39,0.581
38.02,129.54,0.558
38.05,129.68,0.538
38.08,129.83,0.515
38.11,129.97,0.491
38.14,130.12,0.469
38.16,130.27,0.449
38.19,130.41,0.427
38.22,130.56,0.409
38.25,130.70,0.397
38.28,130.85,0.387
38.31,130.99,0.384
38.34,131.14,0.380
38.36,131.28,0.371
38.39,131.42,0.363
38.42,131.57,0.361
38.45,131.71,0.362
38.48,131.85,0.366
38.51,131.99,0.372
38.53,132.13,0.378
38.56,132.27,0.382
38.59,132.41,0.393
38.62,132.56,0.366
38.65,132.70,0.330
38.68,132.85,0.281
38.70,133.00,0.236
38.73,133.15,0.210
38.76,133.30,0.191
38.79,133.44,0.179
38.82,133.59,0.171
38.84,133.73,0.164
38.87,133.88,0.159
38.90,134.02,0.155
38.93,134.16,0.153
38.96,134.31,0.151
38.99,134.45,0.149
39.01,134.59,0.148
39.04,134.73,0.146
39.07,134.88,0.146
39.10,135.02,0.145
39.13,135.16,0.144
39.16,135.30,0.144
39.19,135.44,0.143
39.21,135.58,0.142
39.24,135.72,0.142
39.27,135.87,0.141
39.30,136.01,0.141
39.33,136.15,0.140
39.36,136.29,0.140
39.38,136.43,0.140
39.41,136.58,0.139
39.44,136.72,0.139
39.47,136.86,0.139
39.50,137.00,0.139
39.53,137.14,0.139
39.55,137.29,0.138
39.58,137.43,0.138
39.61,137.57,0.138
39.64,137.71,0.138
39.67,137.85,0.138
39.69,137.99,0.138
39.72,138.14,0.137
39.75,138.28,0.137
39.78,138.42,0.137
39.81,138.56,0.137
39.84,138.70,0.137
39.86,138.84,0.137
39.89,138.99,0.137
39.92,139.13,0.137
39.95,139.27,0.137
39.98,139.41,0.136
40.01,139.55,0.136
40.04,139.70,0.136
40.06,139.84,0.136
40.09,139.98,0.136
40.12,140.12,0.136
40.15,140.26,0.136
40.18,140.40,0.136
40.21,140.54,0.136
40.23,140.69,0.136
40.26,140.83,0.136
40.29,140.97,0.136
40.32,141.11,0.135
40.35,141.25,0.135
40.38,141.39,0.135
40.40,141.54,0.135
40.43,141.68,0.135
40.46,141.82,0.135
40.49,141.96,0.135
40.52,142.10,0.135
40.54,142.25,0.135
40.57,142.39,0.135
40.60,142.53,0.135
40.63,142.67,0.135
40.66,142.81,0.135
40.69,142.95,0.135
40.71,143.10,0.135
40.74,143.24,0.135
40.77,143.38,0.134
40.80,143.52,0.134
40.83,143.66,0.134
40.86,143.80,0.134
40.89,143.95,0.134
40.91,144.09,0.134
40.94,144.23,0.134
40.97,144.37,0.134
41.00,144.51,0.134
41.03,144.66,0.134
41.06,144.80,0.134
41.08,144.94,0.134
41.11,145.08,0.134
41.14,145.22,0.134
41.17,145.36,0.134
41.20,145.50,0.134
41.23,145.65,0.134
41.25,145.79,0.134
41.28,145.93,0.133
41.31,146.07,0.133
41.34,146.21,0.133
41.37,146.36,0.133
41.39,146.50,0.133
41.42,146.64,0.133
41.45,146.78,0.133
41.48,146.93,0.133
41.51,147.07,0.133
41.54,147.21,0.133
41.56,147.35,0.133
41.59,147.49,0.133
41.62,147.63,0.132
41.65,147.77,0.132
41.68,147.91,0.132
41.71,148.06,0.132
41.74,148.20,0.132
41.76,148.34,0.132
41.79,148.48,0.132
41.82,148.62,0.132
41.85,148.76,0.132
41.88,148.91,0.132
41.91,149.05,0.132
41.93,149.19,
41.96,149.33,
41.98,,

[step]
Ramp 5.00 °C/min to -60.00 °C
Time,Temperature,Heat Flow (Normalized)
min,°C,W/g
42.99,150.13,-0.097
43.01,150.13,-0.097
43.04,150.12,-0.097
43.07,150.09,-0.097
43.10,150.04,-0.098
43.13,149.96,-0.127
43.16,149.86,-0.161
43.18,149.76,-0.194
43.21,149.64,-0.222
43.24,149.52,-0.242
43.27,149.40,-0.259
43.30,149.27,-0.268
43.33,149.14,-0.282
43.35,149.01,-0.288
43.38,148.87,-0.296
43.41,148.74,-0.299
43.44,148.60,-0.302
43.47,148.47,-0.304
43.49,148.33,-0.306
43.52,148.19,-0.308
43.55,148.05,-0.309
43.58,147.91,-0.310
43.61,147.77,-0.311
43.64,147.63,-0.312
43.66,147.49,-0.313
43.69,147.35,-0.313
43.72,147.21,-0.314
43.75,147.07,-0.314
43.78,146.93,-0.315
43.81,146.79,-0.315
43.84,146.65,-0.316
43.86,146.51,-0.316
43.89,146.37,-0.316
43.92,146.23,-0.316
43.95,146.09,-0.317
43.98,145.95,-0.317
44.01,145.81,-0.317
44.03,145.67,-0.317
44.06,145.53,-0.317
44.09,145.38,-0.317
44.12,145.24,-0.317
44.15,145.10,-0.317
44.18,144.96,-0.317
44.20,144.82,-0.317
44.23,144.68,-0.316
44.26,144.54,-0.316
44.29,144.39,-0.316
44.32,144.25,-0.316
44.34,144.11,-0.316
44.37,143.97,-0.316
44.40,143.83,-0.315
44.43,143.69,-0.315
44.46,143.55,-0.315
44.49,143.40,-0.315
44.51,143.26,-0.315
44.54,143.12,-0.314
44.57,142.98,-0.314
44.60,142.84,-0.314
44.63,142.70,-0.314
44.66,142.56,-0.314
44.69,142.41,-0.313
44.71,142.27,-0.313
44.74,142.13,-0.313
44.77,141.99,-0.312
44.80,141.85,-0.312
44.83,141.71,-0.312
44.86,141.57,-0.311
44.88,141.42,-0.311
44.91,141.28,-0.311
44.94,141.14,-0.311
44.97,141.00,-0.310
45.00,140.86,-0.310
45.03,140.72,-0.310
45.05,140.58,-0.310
45.08,140.43,-0.309
45.11,140.29,-0.309
45.14,140.15,-0.309
45.17,140.01,-0.308
45.19,139.87,-0.308
45.22,139.72,-0.308
45.25,139.58,-0.308
45.28,139.44,-0.308
45.31,139.30,-0.307
45.34,139.16,-0.307
45.36,139.02,-0.307
45.39,138.88,-0.306
45.42,138.73,-0.306
45.45,138.59,-0.306
45.48,138.45,-0.306
45.51,138.31,-0.305
45.54,138.17,-0.305
45.56,138.03,-0.305
45.59,137.89,-0.305
45.62,137.74,-0.304
45.65,137.60,-0.304
45.68,137.46,-0.304
45.71,137.32,-0.304
45.73,137.18,-0.303
45.76,137.04,-0.303
45.79,136.89,-0.303
45.82,136.75,-0.303
45.85,136.61,-0.303
45.88,136.47,-0.302
45.90,136.33,-0.302
45.93,136.19,-0.302
45.96,136.04,-0.301
45.99,135.90,-0.301
46.02,135.76,-0.301
46.04,135.62,-0.301
46.07,135.48,-0.301
46.10,135.33,-0.300
46.13,135.19,-0.300
46.16,135.05,-0.300
46.19,134.91,-0.300
46.21,134.77,-0.300
46.24,134.63,-0.300
46.27,134.49,-0.299
46.30,134.34,-0.299
46.33,134.20,-0.299
46.36,134.06,-0.299
46.39,133.92,-0.299
46.41,133.78,-0.298
46.44,133.64,-0.298
46.47,133.49,-0.298
46.50,133.35,-0.298
46.53,133.21,-0.298
46.56,133.07,-0.297
46.58,132.93,-0.297
46.61,132.79,-0.297
46.64,132.64,-0.297
46.67,132.50,-0.297
46.70,132.36,-0.296
46.73,132.22,-0.296
46.75,132.08,-0.296
46.78,131.94,-0.296
46.81,131.80,-0.296
46.84,131.65,-0.295
46.87,131.51,-0.295
46.89,131.37,-0.295
46.92,131.23,-0.295
46.95,131.09,-0.295
46.98,130.95,-0.294
47.01,130.80,-0.294
47.04,130.66,-0.294
47.06,130.52,-0.294
47.09,130.38,-0.294
47.12,130.24,-0.293
47.15,130.10,-0.293
47.18,129.96,-0.293
47.21,129.81,-0.293
47.24,129.67,-0.293
47.26,129.53,-0.293
47.29,129.39,-0.293
47.32,129.25,-0.292
47.35,129.10,-0.292
47.38,128.96,-0.292
47.41,128.82,-0.292
47.43,128.68,-0.292
47.46,128.54,-0.291
47.49,128.40,-0.291
47.52,128.25,-0.291
47.55,128.11,-0.290
47.58,127.97,-0.290
47.60,127.83,-0.290
47.63,127.69,-0.290
47.66,127.55,-0.290
47.69,127.41,-0.290
47.72,127.26,-0.290
47.74,127.12,-0.290
47.77,126.98,-0.289
47.80,126.84,-0.289
47.83,126.70,-0.289
47.86,126.56,-0.289
47.89,126.42,-0.289
47.91,126.27,-0.289
47.94,126.13,-0.288
47.97,125.99,-0.288
48.00,125.85,-0.288
48.03,125.71,-0.288
48.06,125.57,-0.288
48.09,125.42,-0.288
48.11,125.28,-0.288
48.14,125.14,-0.288
48.17,125.00,-0.288
48.20,124.86,-0.288
48.23,124.72,-0.287
48.26,124.57,-0.287
48.28,124.43,-0.287
48.31,124.29,-0.287
48.34,124.15,-0.287
48.37,124.01,-0.287
48.40,123.87,-0.287
48.43,123.72,-0.286
48.45,123.58,-0.286
48.48,123.44,-0.286
48.51,123.30,-0.286
48.54,123.16,-0.286
48.57,123.01,-0.287
48.59,122.87,-0.344
48.62,122.74,-0.414
48.65,122.60,-0.469
48.68,122.47,-0.540
48.71,122.35,-0.644
48.74,122.22,-0.726
48.76,122.09,-0.784
48.79,121.97,-0.911
48.82,121.85,-1.022
48.85,121.73,-1.052
48.88,121.61,-1.383
48.91,121.51,-1.534
48.94,121.39,-1.502
48.96,121.27,-1.510
48.99,121.13,-1.481
49.02,121.00,-1.445
49.05,120.86,-1.447
49.08,120.72,-1.453
49.11,120.58,-1.461
49.13,120.44,-1.459
49.16,120.30,-1.457
49.19,120.16,-1.445
49.22,120.02,-1.428
49.25,119.87,-1.423
49.28,119.73,-1.407
49.30,119.58,-1.366
49.33,119.44,-1.340
49.36,119.30,-1.724
49.39,119.19,-1.722
49.42,119.05,-1.529
49.44,118.90,-1.418
49.47,118.75,-1.363
49.50,118.60,-1.310
49.53,118.44,-1.262
49.56,118.29,-1.220
49.59,118.14,-1.190
49.61,117.99,-1.156
49.64,117.84,-1.103
49.67,117.69,-1.059
49.70,117.54,-1.007
49.73,117.39,-0.958
49.76,117.23,-0.915
49.79,117.08,-0.872
49.81,116.93,-0.838
49.84,116.78,-0.807
49.87,116.63,-0.782
49.90,116.48,-0.758
49.93,116.34,-0.733
49.96,116.19,-0.706
49.98,116.04,-0.685
50.01,115.89,-0.665
50.04,115.75,-0.649
50.07,115.60,-0.631
50.10,115.46,-0.616
50.13,115.31,-0.603
50.15,115.16,-0.591
50.18,115.02,-0.576
50.21,114.88,-0.564
50.24,114.73,-0.555
50.27,114.59,-0.548
50.29,114.44,-0.540
50.32,114.30,-0.533
50.35,114.15,-0.528
50.38,114.01,-0.528
50.41,113.87,-0.523
50.44,113.73,-0.517
50.46,113.58,-0.510
50.49,113.44,-0.507
50.52,113.30,-0.501
50.55,113.15,-0.508
50.58,113.01,-0.526
50.61,112.87,-0.526
50.64,112.73,-0.526
50.66,112.59,-0.527
50.69,112.45,-0.525
50.72,112.31,-0.514
50.75,112.17,-0.506
50.78,112.02,-0.498
50.81,111.88,-0.487
50.83,111.74,-0.484
50.86,111.60,-0.481
50.89,111.45,-0.475
50.92,111.31,-0.472
50.95,111.17,-0.468
50.98,111.02,-0.464
51.00,110.88,-0.461
51.03,110.74,-0.457
51.06,110.60,-0.453
51.09,110.45,-0.449
51.12,110.31,-0.447
51.14,110.17,-0.444
51.17,110.03,-0.443
51.20,109.88,-0.440
51.23,109.74,-0.437
51.26,109.60,-0.434
51.29,109.46,-0.432
51.31,109.32,-0.430
51.34,109.17,-0.428
51.37,109.03,-0.425
51.40,108.89,-0.423
51.43,108.75,-0.421
51.46,108.60,-0.418
51.49,108.46,-0.416
51.51,108.32,-0.415
51.54,108.18,-0.413
51.57,108.04,-0.411
51.60,107.90,-0.410
51.63,107.75,-0.408
51.66,107.61,-0.405
51.68,107.47,-0.404
51.71,107.33,-0.401
51.74,107.19,-0.401
51.77,107.04,-0.399
51.80,106.90,-0.398
51.83,106.76,-0.397
51.85,106.62,-0.396
51.88,106.48,-0.395
51.91,106.33,-0.392
51.94,106.19,-0.391
51.97,106.05,-0.389
51.99,105.91,-0.387
52.02,105.77,-0.385
52.05,105.62,-0.384
52.08,105.48,-0.382
52.11,105.34,-0.379
52.14,105.20,-0.378
52.16,105.06,-0.377
52.19,104.92,-0.375
52.22,104.77,-0.374
52.25,104.63,-0.373
52.28,104.49,-0.370
52.31,104.35,-0.370
52.34,104.21,-0.367
52.36,104.06,-0.367
52.39,103.92,-0.366
52.42,103.78,-0.365
52.45,103.64,-0.363
52.48,103.50,-0.362
[...]
176.16,-39.87,0.096
176.17,-39.80,0.096
176.19,-39.74,0.096
176.20,-39.67,0.096
176.21,-39.60,0.096
176.23,-39.54,0.096
176.24,-39.47,0.096
176.25,-39.40,0.096
176.27,-39.34,0.096
176.28,-39.27,0.096
176.29,-39.20,0.096
176.31,-39.13,0.096
176.32,-39.07,0.096
176.33,-39.00,0.096
176.35,-38.94,0.096
176.36,-38.87,0.096
176.37,-38.80,0.096
176.39,-38.74,0.096
176.40,-38.67,0.096
176.41,-38.60,0.096
176.43,-38.54,0.096
176.44,-38.47,0.096
176.45,-38.40,0.096
176.47,-38.34,0.096
176.48,-38.27,0.096
176.49,-38.20,0.096
176.51,-38.13,0.096
176.52,-38.07,0.096
176.53,-38.00,0.096
176.55,-37.93,0.096
176.56,-37.87,0.096
176.57,-37.80,0.096
176.59,-37.73,0.096
176.60,-37.67,0.096
176.61,-37.60,0.095
176.63,-37.53,0.096
176.64,-37.47,0.096
176.65,-37.40,0.096
176.67,-37.33,0.095
176.68,-37.27,0.096
176.69,-37.20,0.096
176.71,-37.13,0.096
176.72,-37.07,0.096
176.73,-37.00,0.096
176.75,-36.93,0.096
176.76,-36.87,0.096
176.77,-36.80,0.096
176.79,-36.73,0.096
176.80,-36.67,0.095
176.81,-36.60,0.096
176.83,-36.53,0.096
176.84,-36.47,0.096
176.85,-36.40,0.095
176.87,-36.33,0.095
176.88,-36.27,0.095
176.89,-36.20,0.095
176.91,-36.13,0.095
176.92,-36.07,0.096
176.93,-36.00,0.096
176.95,-35.93,0.096
176.96,-35.86,0.095
176.97,-35.80,0.096
176.99,-35.73,0.096
177.00,-35.67,0.096
177.01,-35.60,0.096
177.03,-35.53,0.096
177.04,-35.46,0.095
177.05,-35.40,0.096
177.07,-35.33,0.096
177.08,-35.27,0.096
177.09,-35.20,0.096
177.11,-35.13,0.096
177.12,-35.06,0.096
177.13,-35.00,0.096
177.15,-34.93,0.096
177.16,-34.87,0.096
177.17,-34.80,0.096
177.19,-34.73,0.096
177.20,-34.66,0.096
177.21,-34.60,0.096
177.23,-34.53,0.096
177.24,-34.46,0.095
177.25,-34.40,0.095
177.27,-34.33,0.096
177.28,-34.26,0.096
177.29,-34.20,0.096
177.31,-34.13,0.096
177.32,-34.06,0.096
177.33,-34.00,0.096
177.35,-33.93,0.096
177.36,-33.86,0.096
177.37,-33.80,0.096
177.39,-33.73,0.096
177.40,-33.66,0.096
177.41,-33.60,0.096
177.43,-33.53,0.096
177.44,-33.46,0.096
177.45,-33.40,0.096
177.47,-33.33,0.096
177.48,-33.26,0.096
177.49,-33.20,0.096
177.51,-33.13,0.096
177.52,-33.06,0.096
177.53,-32.99,0.096
177.55,-32.93,0.096
177.56,-32.86,0.096
177.57,-32.79,0.096
177.59,-32.73,0.096
177.60,-32.66,0.096
177.61,-32.60,0.096
177.63,-32.53,0.096
177.64,-32.46,0.096
177.65,-32.39,0.096
177.67,-32.33,0.096
177.68,-32.26,0.096
177.69,-32.19,0.096
177.71,-32.13,0.096
177.72,-32.06,0.096
177.73,-31.99,0.096
177.75,-31.93,0.096
177.76,-31.86,0.096
177.77,-31.79,0.096
177.79,-31.73,0.096
177.80,-31.66,0.096
177.81,-31.59,0.096
177.83,-31.53,0.096
177.84,-31.46,0.096
177.85,-31.39,0.096
177.87,-31.33,0.096
177.88,-31.26,0.096
177.89,-31.19,0.096
177.91,-31.13,0.096
177.92,-31.06,0.096
177.93,-30.99,0.096
177.95,-30.93,0.096
177.96,-30.86,0.096
177.97,-30.79,0.096
177.99,-30.73,0.096
178.00,-30.66,0.096
178.01,-30.59,0.096
178.03,-30.53,0.096
178.04,-30.46,0.096
178.05,-30.39,0.096
178.07,-30.33,0.096
178.08,-30.26,0.096
178.09,-30.19,0.096
178.11,-30.13,0.096
178.12,-30.06,0.096
178.13,-29.99,0.096
178.15,-29.93,0.096
178.16,-29.86,0.096
178.17,-29.79,0.096
178.19,-29.73,0.096
178.20,-29.66,0.096
178.21,-29.59,0.096
178.23,-29.53,0.096
178.24,-29.46,0.096
178.25,-29.39,0.096
178.27,-29.32,0.096
178.28,-29.26,0.096
178.29,-29.19,0.096
178.31,-29.13,0.096
178.32,-29.06,0.096
178.33,-28.99,0.096
178.35,-28.93,0.096
178.36,-28.86,0.096
178.37,-28.79,0.096
178.39,-28.72,0.096
178.40,-28.66,0.096
178.41,-28.59,0.096
178.43,-28.52,0.096
178.44,-28.46,0.096
178.45,-28.39,0.096
178.47,-28.32,0.096
178.48,-28.26,0.096
178.49,-28.19,0.096
178.51,-28.12,0.096
178.52,-28.06,0.096
178.53,-27.99,0.096
178.55,-27.92,0.096
178.56,-27.86,0.096
178.57,-27.79,0.096
178.59,-27.72,0.096
178.60,-27.66,0.096
178.61,-27.59,0.096
178.63,-27.52,0.096
178.64,-27.46,0.096
178.65,-27.39,0.096
178.67,-27.32,0.096
178.68,-27.26,0.096
178.69,-27.19,0.096
178.71,-27.12,0.096
178.72,-27.06,0.096
178.73,-26.99,0.096
178.75,-26.92,0.096
178.76,-26.86,0.096
178.77,-26.79,0.096
178.79,-26.72,0.096
178.80,-26.66,0.096
178.81,-26.59,0.096
178.83,-26.52,0.096
178.84,-26.46,0.096
178.85,-26.39,0.096
178.87,-26.32,0.096
178.88,-26.26,0.096
178.89,-26.19,0.096
178.91,-26.12,0.096
178.92,-26.05,0.096
178.93,-25.99,0.096
178.95,-25.92,0.096
178.96,-25.86,0.096
178.97,-25.79,0.096
178.99,-25.72,0.096
179.00,-25.65,0.096
179.01,-25.59,0.096
179.03,-25.52,0.096
179.04,-25.45,0.096
179.05,-25.39,0.096
179.07,-25.32,0.096
179.08,-25.25,0.096
179.09,-25.19,0.097
179.11,-25.12,0.096
179.12,-25.05,0.096
179.13,-24.99,0.096
179.15,-24.92,0.097
179.16,-24.85,0.097
179.17,-24.79,0.097
179.19,-24.72,0.097
179.20,-24.65,0.097
179.21,-24.59,0.097
179.23,-24.52,0.097
179.24,-24.45,0.097
179.25,-24.39,0.097
179.27,-24.32,0.097
179.28,-24.25,0.097
179.29,-24.19,0.097
179.31,-24.12,0.097
179.32,-24.05,0.097
179.33,-23.99,0.097
179.35,-23.92,0.097
179.36,-23.85,0.097
179.37,-23.79,0.097
179.39,-23.72,0.097
179.40,-23.65,0.097
179.41,-23.59,0.097
179.43,-23.52,0.097
179.44,-23.45,0.097
179.45,-23.39,0.097
179.47,-23.32,0.097
179.48,-23.25,0.097
179.49,-23.19,0.097
179.51,-23.12,0.097
179.52,-23.05,0.097
179.53,-22.99,0.097
179.55,-22.92,0.097
179.56,-22.85,0.097
179.57,-22.79,0.097
179.59,-22.72,0.097
179.60,-22.65,0.097
179.61,-22.59,0.097
179.63,-22.52,0.097
179.64,-22.45,0.097
179.65,-22.39,0.097
179.67,-22.32,0.097
179.68,-22.25,0.097
179.69,-22.18,0.097
179.71,-22.12,0.097
179.72,-22.05,0.097
179.73,-21.98,0.097
179.75,-21.92,0.097
179.76,-21.85,0.097
179.77,-21.79,0.097
179.79,-21.72,0.097
179.80,-21.65,0.097
179.81,-21.58,0.097
179.83,-21.52,0.097
179.84,-21.45,0.097
179.85,-21.38,0.097
179.87,-21.32,0.097
179.88,-21.25,0.097
179.89,-21.18,0.097
179.91,-21.12,0.097
179.92,-21.05,0.097
179.93,-20.98,0.097
179.95,-20.92,0.097
179.96,-20.85,0.097
179.97,-20.78,0.098
179.99,-20.72,0.097
180.00,-20.65,0.098
180.01,-20.58,0.098
180.03,-20.52,0.098
180.04,-20.45,0.098
180.05,-20.38,0.098
180.07,-20.32,0.098
180.08,-20.25,0.098
180.09,-20.18,0.098
180.11,-20.11,0.098
180.12,-20.05,0.098
180.13,-19.98,0.098
180.15,-19.91,0.098
180.16,-19.85,0.098
180.17,-19.78,0.098
180.19,-19.71,0.098
180.20,-19.65,0.098
180.21,-19.58,0.098
180.23,-19.51,0.098
180.24,-19.45,0.098
180.25,-19.38,0.098
180.27,-19.31,0.098
180.28,-19.24,0.098
180.29,-19.18,0.098
180.31,-19.11,0.098
180.32,-19.05,0.098
180.33,-18.98,0.098
180.35,-18.91,0.098
180.36,-18.84,0.098
180.37,-18.78,0.098
180.39,-18.71,0.098
180.40,-18.64,0.098
180.41,-18.58,0.098
180.43,-18.51,0.098
180.44,-18.44,0.099
180.45,-18.38,0.099
180.47,-18.31,0.099
180.48,-18.24,0.099
180.49,-18.18,0.099
180.51,-18.11,0.099
180.52,-18.04,0.099
180.53,-17.98,0.099
180.55,-17.91,0.099
180.56,-17.84,0.099
180.57,-17.78,0.099
180.59,-17.71,0.099
180.60,-17.64,0.099
180.61,-17.58,0.099
180.63,-17.51,0.099
180.64,-17.44,0.099
180.65,-17.38,0.099
180.67,-17.31,0.099
180.68,-17.24,0.099
180.69,-17.18,0.099
180.71,-17.11,0.099
180.72,-17.05,0.099
180.73,-16.98,0.099
180.75,-16.91,0.099
180.76,-16.84,0.099
180.77,-16.78,0.099
180.79,-16.71,0.099
180.80,-16.64,0.099
180.81,-16.58,0.099
180.83,-16.51,0.099
180.84,-16.45,0.099
180.85,-16.38,0.100
180.87,-16.31,0.100
180.88,-16.25,0.100
180.89,-16.18,0.100
180.91,-16.11,0.100
180.92,-16.05,0.100
180.93,-15.98,0.100
180.95,-15.91,0.100
180.96,-15.85,0.100
180.97,-15.78,0.100
180.99,-15.71,0.100
181.00,-15.65,0.100
181.01,-15.58,0.100
181.03,-15.51,0.100
181.04,-15.45,0.100
181.05,-15.38,0.100
181.07,-15.31,0.100
181.08,-15.25,0.101
181.09,-15.18,0.101
181.11,-15.11,0.101
181.12,-15.05,0.101
181.13,-14.98,0.101
181.15,-14.91,0.101
181.16,-14.85,0.101
181.17,-14.78,0.101
181.19,-14.71,0.101
181.20,-14.65,0.101
181.21,-14.58,0.101
181.23,-14.51,0.101
181.24,-14.45,0.101
181.25,-14.38,0.101
181.27,-14.31,0.102
181.28,-14.24,0.102
181.29,-14.18,0.102
181.31,-14.11,0.102
181.32,-14.05,0.102
181.33,-13.98,0.102
181.35,-13.91,0.102
181.36,-13.84,0.102
181.37,-13.78,0.102
181.39,-13.71,0.102
181.40,-13.64,0.102
181.41,-13.58,0.103
181.43,-13.51,0.103
181.44,-13.44,0.103
181.45,-13.38,0.103
181.47,-13.31,0.103
181.48,-13.24,0.103
181.49,-13.18,0.103
181.51,-13.11,0.103
181.52,-13.04,0.103
181.53,-12.98,0.103
181.55,-12.91,0.103
181.56,-12.84,0.103
181.57,-12.78,0.104
181.59,-12.71,0.104
181.60,-12.64,0.104
181.61,-12.58,0.104
181.63,-12.51,0.104
181.64,-12.44,0.104
181.65,-12.38,0.104
181.67,-12.31,0.104
181.68,-12.24,0.104
181.69,-12.18,0.104
181.71,-12.11,0.105
181.72,-12.05,0.105
181.73,-11.98,0.105
181.75,-11.91,0.105
181.76,-11.84,0.105
181.77,-11.78,0.105
181.79,-11.71,0.105
181.80,-11.64,0.105
181.81,-11.58,0.105
181.83,-11.51,0.106
181.84,-11.44,0.106
181.85,-11.38,0.106
181.87,-11.31,0.106
181.88,-11.24,0.106
181.89,-11.18,0.106
181.91,-11.11,0.106
181.92,-11.04,0.106
181.93,-10.98,0.106
181.95,-10.91,0.106
181.96,-10.84,0.107
181.97,-10.78,0.107
181.99,-10.71,0.107
182.00,-10.64,0.107
182.01,-10.58,0.107
182.03,-10.51,0.107
182.04,-10.44,0.107
182.05,-10.38,0.107
182.07,-10.31,0.107
182.08,-10.24,0.107
182.09,-10.18,0.107
182.11,-10.11,0.108
182.12,-10.04,0.108
182.13,-9.98,0.108
182.15,-9.91,0.108
182.16,-9.84,0.108
182.17,-9.78,0.108
182.19,-9.71,0.108
182.20,-9.64,0.108
182.21,-9.58,0.108
182.23,-9.51,0.108
182.24,-9.44,0.109
182.25,-9.38,0.109
182.27,-9.31,0.109
182.28,-9.24,0.109
182.29,-9.18,0.109
182.31,-9.11,0.109
182.32,-9.04,0.109
182.33,-8.98,0.109
182.35,-8.91,0.109
182.36,-8.84,0.109
182.37,-8.78,0.109
182.39,-8.71,0.109
182.40,-8.64,0.110
182.41,-8.58,0.110
182.43,-8.51,0.110
182.44,-8.44,0.110
182.45,-8.38,0.110
182.47,-8.31,0.110
182.48,-8.24,0.110
182.49,-8.18,0.110
182.51,-8.11,0.110
182.52,-8.04,0.110
182.53,-7.98,0.110
182.55,-7.91,0.110
182.56,-7.84,0.110
182.57,-7.78,0.110
182.59,-7.71,0.110
182.60,-7.64,0.110
182.61,-7.58,0.110
182.63,-7.51,0.110
182.64,-7.44,0.111
182.65,-7.38,0.111
182.67,-7.31,0.111
182.68,-7.24,0.111
182.69,-7.18,0.111
182.71,-7.11,0.111
182.72,-7.04,0.111
182.73,-6.98,0.111
182.75,-6.91,0.111
182.76,-6.84,0.111
182.77,-6.78,0.111
182.79,-6.71,0.111
182.80,-6.64,0.111
182.81,-6.58,0.111
182.83,-6.51,0.111
182.84,-6.44,0.111
182.85,-6.38,0.111
182.87,-6.31,0.111
182.88,-6.24,0.111
182.89,-6.17,0.111
182.91,-6.11,0.111
182.92,-6.04,0.111
182.93,-5.98,0.111
182.95,-5.91,0.111
182.96,-5.84,0.111
182.97,-5.77,0.111
182.99,-5.71,0.111
183.00,-5.64,0.111
183.01,-5.57,0.111
183.03,-5.51,0.111
183.04,-5.44,0.111
183.05,-5.37,0.111
183.07,-5.31,0.111
183.08,-5.24,0.111
183.09,-5.17,0.111
183.11,-5.11,0.111
183.12,-5.04,0.111
183.13,-4.97,0.111
183.15,-4.91,0.111
183.16,-4.84,0.111
183.17,-4.77,0.111
183.19,-4.71,0.111
183.20,-4.64,0.111
183.21,-4.57,0.111
183.23,-4.51,0.111
183.24,-4.44,0.111
183.25,-4.37,0.111
183.27,-4.31,0.111
183.28,-4.24,0.111
183.29,-4.17,0.111
183.31,-4.11,0.111
183.32,-4.04,0.111
183.33,-3.97,0.111
183.35,-3.91,0.111
183.36,-3.84,0.111
183.37,-3.77,0.111
183.39,-3.71,0.111
183.40,-3.64,0.111
183.41,-3.57,0.111
183.43,-3.51,0.111
183.44,-3.44,0.111
183.45,-3.37,0.111
183.47,-3.31,0.111
183.48,-3.24,0.111
183.49,-3.17,0.111
183.51,-3.11,0.111
183.52,-3.04,0.111
183.53,-2.97,0.111
183.55,-2.91,0.111
183.56,-2.84,0.111
183.57,-2.77,0.111
183.59,-2.70,0.111
183.60,-2.64,0.111
183.61,-2.57,0.111
183.63,-2.51,0.111
183.64,-2.44,0.111
183.65,-2.37,0.111
183.67,-2.31,0.111
183.68,-2.24,0.111
183.69,-2.17,0.111
183.71,-2.11,0.111
183.72,-2.04,0.111
183.73,-1.97,0.111
183.75,-1.91,0.111
183.76,-1.84,0.111
183.77,-1.77,0.111
183.79,-1.70,0.111
183.80,-1.64,0.111
183.81,-1.57,0.111
183.83,-1.50,0.111
183.84,-1.44,0.111
183.85,-1.37,0.111
183.87,-1.30,0.111
183.88,-1.24,0.111
183.89,-1.17,0.111
183.91,-1.10,0.111
183.92,-1.04,0.111
183.93,-0.97,0.111
183.95,-0.90,0.111
183.96,-0.84,0.111
183.97,-0.77,0.111
183.99,-0.70,0.111
184.00,-0.64,0.111
184.01,-0.57,0.111
184.03,-0.50,0.110
184.04,-0.44,0.110
184.05,-0.37,0.111
184.07,-0.30,0.110
184.08,-0.24,0.110
184.09,-0.17,0.110
184.11,-0.10,0.110
184.12,-0.04,0.110
184.13,0.03,0.110
184.15,0.10,0.110
184.16,0.16,0.110
184.17,0.23,0.110
184.19,0.30,0.110
184.20,0.36,0.110
184.21,0.43,0.110
184.23,0.50,0.110
184.24,0.57,0.110
184.25,0.63,0.110
184.27,0.70,0.110
184.28,0.76,0.110
184.29,0.83,0.110
184.31,0.90,0.110
184.32,0.97,0.110
184.33,1.03,0.110
184.35,1.10,0.110
184.36,1.17,0.110
184.37,1.23,0.110
184.39,1.30,0.110
184.40,1.37,0.110
184.41,1.43,0.110
184.43,1.50,0.110
184.44,1.57,0.110
184.45,1.63,0.110
184.47,1.70,0.110
184.48,1.77,0.110
184.49,1.83,0.110
184.51,1.90,0.110
184.52,1.97,0.110
184.53,2.03,0.110
184.55,2.10,0.110
184.56,2.17,0.110
184.57,2.23,0.110
184.59,2.30,0.110
184.60,2.37,0.110
184.61,2.43,0.110
184.63,2.50,0.110
184.64,2.57,0.110
184.65,2.63,0.110
184.67,2.70,0.110
184.68,2.77,0.110
184.69,2.83,0.110
184.71,2.90,0.110
184.72,2.97,0.110
184.73,3.03,0.110
184.75,3.10,0.110
184.76,3.17,0.110
184.77,3.23,0.110
184.79,3.30,0.110
184.80,3.37,0.110
184.81,3.43,0.110
184.83,3.50,0.110
184.84,3.57,0.110
184.85,3.63,0.110
184.87,3.70,0.110
184.88,3.77,0.110
184.89,3.83,0.110
184.91,3.90,0.110
184.92,3.97,0.110
184.93,4.03,0.110
184.95,4.10,0.110
184.96,4.17,0.110
184.97,4.24,0.110
184.99,4.30,0.110
185.00,4.37,0.110
185.01,4.44,0.110
185.03,4.50,0.110
185.04,4.57,0.110
185.05,4.64,0.110
185.07,4.70,0.110
185.08,4.77,0.110
185.09,4.83,0.110
185.11,4.90,0.110
185.12,4.97,0.110
185.13,5.03,0.110
185.15,5.10,0.110
185.16,5.17,0.110
185.17,5.24,0.110
185.19,5.30,0.110
185.20,5.37,0.110
185.21,5.43,0.110
185.23,5.50,0.110
185.24,5.57,0.110
185.25,5.63,0.110
185.27,5.70,0.110
185.28,5.77,0.110
185.29,5.83,0.110
185.31,5.90,0.110
185.32,5.97,0.110
185.33,6.04,0.110
185.35,6.10,0.110
185.36,6.17,0.110
185.37,6.24,0.111
185.39,6.30,0.111
185.40,6.37,0.111
185.41,6.44,0.111
185.43,6.50,0.111
185.44,6.57,0.111
185.45,6.64,0.111
185.47,6.70,0.111
185.48,6.77,0.111
185.49,6.84,0.111
185.51,6.90,0.111
185.52,6.97,0.111
185.53,7.04,0.111
185.55,7.10,0.111
185.56,7.17,0.111
185.57,7.24,0.111
185.59,7.30,0.111
185.60,7.37,0.111
185.61,7.44,0.111
185.63,7.50,0.111
185.64,7.57,0.111
185.65,7.64,0.111
185.67,7.70,0.111
185.68,7.77,0.111
185.69,7.84,0.111
185.71,7.90,0.111
185.72,7.97,0.111
185.73,8.04,0.111
185.75,8.10,0.111
185.76,8.17,0.111
185.77,8.24,0.111
185.79,8.31,0.111
185.80,8.37,0.111
185.81,8.44,0.111
185.83,8.51,0.111
185.84,8.57,0.111
185.85,8.64,0.111
185.87,8.71,0.111
185.88,8.77,0.111
185.89,8.84,0.111
185.91,8.91,0.111
185.92,8.97,0.111
185.93,9.04,0.111
185.95,9.11,0.111
185.96,9.17,0.111
185.97,9.24,0.111
185.99,9.31,0.111
186.00,9.37,0.111
186.01,9.44,0.111
186.03,9.51,0.111
186.04,9.57,0.111
186.05,9.64,0.111
186.07,9.71,0.111
186.08,9.77,0.111
186.09,9.84,0.111
186.11,9.91,0.111
186.12,9.97,0.111
186.13,10.04,0.111
186.15,10.11,0.111
186.16,10.17,0.111
186.17,10.24,0.111
186.19,10.31,0.111
186.20,10.37,0.111
186.21,10.44,0.111
186.23,10.51,0.111
186.24,10.57,0.111
186.25,10.64,0.111
186.27,10.71,0.112
186.28,10.77,0.112
186.29,10.84,0.112
186.31,10.91,0.112
186.32,10.97,0.112
186.33,11.04,0.112
186.35,11.11,0.112
186.36,11.17,0.112
186.37,11.24,0.112
186.39,11.31,0.112
186.40,11.37,0.112
186.41,11.44,0.112
186.43,11.51,0.112
186.44,11.57,0.112
186.45,11.64,0.112
186.47,11.71,0.112
186.48,11.77,0.112
186.49,11.84,0.112
186.51,11.91,0.112
186.52,11.97,0.112
186.53,12.04,0.112
186.55,12.11,0.112
186.56,12.17,0.112
186.57,12.24,0.112
186.59,12.31,0.112
186.60,12.37,0.112
186.61,12.44,0.112
186.63,12.51,0.112
186.64,12.57,0.112
186.65,12.64,0.112
186.67,12.71,0.112
186.68,12.78,0.112
186.69,12.84,0.112
186.71,12.91,0.112
186.72,12.97,0.112
186.73,13.04,0.112
186.75,13.11,0.112
186.76,13.18,0.112
186.77,13.24,0.112
186.79,13.31,0.112
186.80,13.37,0.112
186.81,13.44,0.112
186.83,13.51,0.112
186.84,13.58,0.112
186.85,13.64,0.112
186.87,13.71,0.112
186.88,13.78,0.112
186.89,13.84,0.112
186.91,13.91,0.112
186.92,13.98,0.112
186.93,14.04,0.112
186.95,14.11,0.112
186.96,14.18,0.112
186.97,14.24,0.112
186.99,14.31,0.112
187.00,14.38,0.112
187.01,14.44,0.112
187.03,14.51,0.112
187.04,14.58,0.112
187.05,14.64,0.112
187.07,14.71,0.112
187.08,14.78,0.112
187.09,14.84,0.112
187.11,14.91,0.112
187.12,14.98,0.112
187.13,15.04,0.112
187.15,15.11,0.112
187.16,15.18,0.112
187.17,15.24,0.112
187.19,15.31,0.112
187.20,15.38,0.112
187.21,15.44,0.112
187.23,15.51,0.112
187.24,15.58,0.112
187.25,15.64,0.112
187.27,15.71,0.112
187.28,15.78,0.112
187.29,15.84,0.112
187.31,15.91,0.112
187.32,15.98,0.113
187.33,16.04,0.113
187.35,16.11,0.113
187.36,16.18,0.113
187.37,16.24,0.113
187.39,16.31,0.113
187.40,16.38,0.113
187.41,16.44,0.113
187.43,16.51,0.113
187.44,16.58,0.113
187.45,16.65,0.113
187.47,16.71,0.113
187.48,16.78,0.113
187.49,16.85,0.113
187.51,16.91,0.113
187.52,16.98,0.113
187.53,17.04,0.113
187.55,17.11,0.113
187.56,17.18,0.113
187.57,17.25,0.113
187.59,17.31,0.113
187.60,17.38,0.113
187.61,17.44,0.113
187.63,17.51,0.113
187.64,17.58,0.113
187.65,17.64,0.113
187.67,17.71,0.113
187.68,17.78,0.113
187.69,17.85,0.113
187.71,17.91,0.113
187.72,17.98,0.113
187.73,18.04,0.113
187.75,18.11,0.113
187.76,18.18,0.113
187.77,18.25,0.113
187.79,18.31,0.113
187.80,18.38,0.113
187.81,18.45,0.113
187.83,18.51,0.113
187.84,18.58,0.113
187.85,18.65,0.113
187.87,18.71,0.113
187.88,18.78,0.113
187.89,18.85,0.113
187.91,18.91,0.113
187.92,18.98,0.113
187.93,19.05,0.113
187.95,19.11,0.113
187.96,19.18,0.113
187.97,19.25,0.113
187.99,19.31,0.113
188.00,19.38,0.113
188.01,19.45,0.113
188.03,19.51,0.113
188.04,19.58,0.113
188.05,19.65,0.113
188.07,19.71,0.113
188.08,19.78,0.113
188.09,19.85,0.114
188.11,19.91,0.113
188.12,19.98,0.113
188.13,20.05,0.113
188.15,20.11,0.113
188.16,20.18,0.113
188.17,20.25,0.113
188.19,20.31,0.113
188.20,20.38,0.113
188.21,20.45,0.113
188.23,20.51,0.114
188.24,20.58,0.114
188.25,20.65,0.114
188.27,20.71,0.114
188.28,20.78,0.114
188.29,20.85,0.114
188.31,20.91,0.114
188.32,20.98,0.114
188.33,21.05,0.114
188.35,21.11,0.114
188.36,21.18,0.114
188.37,21.25,0.114
188.39,21.31,0.114
188.40,21.38,0.114
188.41,21.45,0.114
188.43,21.51,0.114
188.44,21.58,0.114
188.45,21.65,0.114
188.47,21.71,0.114
188.48,21.78,0.114
188.49,21.85,0.114
188.51,21.92,0.114
188.52,21.98,0.114
188.53,22.05,0.114
188.55,22.12,0.114
188.56,22.18,0.114
188.57,22.25,0.114
188.59,22.31,0.114
188.60,22.38,0.114
188.61,22.45,0.114
188.63,22.52,0.114
188.64,22.58,0.114
188.65,22.65,0.114
188.67,22.72,0.114
188.68,22.78,0.114
188.69,22.85,0.114
188.71,22.92,0.114
188.72,22.98,0.114
188.73,23.05,0.114
188.75,23.12,0.114
188.76,23.18,0.114
188.77,23.25,0.114
188.79,23.32,0.114
188.80,23.38,0.114
188.81,23.45,0.114
188.83,23.52,0.114
188.84,23.58,0.114
188.85,23.65,0.114
188.87,23.72,0.114
188.88,23.78,0.114
188.89,23.85,0.114
188.91,23.92,0.114
188.92,23.98,0.114
188.93,24.05,0.114
188.95,24.12,0.114
188.96,24.19,0.114
188.97,24.25,0.114
188.99,24.32,0.114
189.00,24.39,0.114
189.01,24.45,0.114
189.03,24.52,0.114
189.04,24.58,0.114
189.05,24.65,0.114
189.07,24.72,0.114
189.08,24.78,0.114
189.09,24.85,0.114
189.11,24.92,0.114
189.12,24.98,0.114
189.13,25.05,0.114
189.15,25.12,0.114
189.16,25.19,0.114
189.17,25.25,0.114
189.19,25.32,0.114
189.20,25.38,0.114
189.21,25.45,0.114
189.23,25.52,0.114
189.24,25.58,0.114
189.25,25.65,0.114
189.27,25.72,0.115
189.28,25.79,0.114
189.29,25.85,0.115
189.31,25.92,0.115
189.32,25.98,0.115
189.33,26.05,0.115
189.35,26.12,0.115
189.36,26.19,0.115
189.37,26.25,0.115
189.39,26.32,0.115
189.40,26.38,0.115
189.41,26.45,0.115
189.43,26.52,0.115
189.44,26.59,0.115
189.45,26.65,0.115
189.47,26.72,0.115
189.48,26.79,0.115
189.49,26.85,0.115
189.51,26.92,0.115
189.52,26.99,0.115
189.53,27.05,0.115
189.55,27.12,0.115
189.56,27.19,0.115
189.57,27.25,0.115
189.59,27.32,0.115
189.60,27.39,0.115
189.61,27.45,0.115
189.63,27.52,0.115
189.64,27.59,0.115
189.65,27.65,0.115
189.67,27.72,0.115
189.68,27.79,0.115
189.69,27.85,0.115
189.71,27.92,0.115
189.72,27.99,0.115
189.73,28.05,0.115
189.75,28.12,0.115
189.76,28.19,0.115
189.77,28.25,0.115
189.79,28.32,0.115
189.80,28.39,0.115
189.81,28.45,0.115
189.83,28.52,0.115
189.84,28.59,0.115
189.85,28.65,0.115
189.87,28.72,0.115
189.88,28.79,0.115
189.89,28.85,0.115
189.91,28.92,0.115
189.92,28.99,0.115
189.93,29.05,
189.95,29.12,
189.96,29.19,
189.97,29.25,
189.98,,