File: DSC/2025_06_17_Benzoic_Acid_n60_150C_10Cmin_x3.csv
Filename,2025_06_17_Benzoic_Acid_n60_150C_10Cmin_x3
Instrument name,DSC2A-00468 (192.168.1.100)
Operator,Gibbons
rundate,6/17/2025
Sample name,2025_06_17_Benzoic_Acid_n60_150C_10Cmin_x3
proceduresegments,Data Off ; Equilibrate -60.00 °C; Data On ; Ramp 10.00 °C/min to 150.00 °C; Data Off ; Isothermal 1.0 min; Data On ; Ramp 10.00 °C/min to -60.00 °C; Data Off ; Isothermal 1.0 min; Data On ; Ramp 10.00 °C/min to 150.00 °C; Data Off ; Isothermal 1.0 min; Data On ; Ramp 10.00 °C/min to -60.00 °C; Data Off ; Isothermal 1.0 min; Data On ; Ramp 10.00 °C/min to 150.00 °C; Data Off ; Isothermal 1.0 min; Data On ; Ramp 10.00 °C/min to 30.00 °C
[File Parameters]
Run date,6/17/2025 7:26:04 PM
Trios version,5.1.1.46572
Original File Name,
Current File Name,D:\DSC2500\Gibbons\2025_06_17_Benzoic_Acid_n60_150C_10Cmin_x3.tri
[Procedure]
Procedure Name,Benzoic_Acid_n60_150C_10Cmin_x3
Sample Name,2025_06_17_Benzoic_Acid_n60_150C_10Cmin_x3
Sample Mass,13.19 mg
Reference Sample Mass,0 mg
Pan Mass,56.31 mg
Pan Number,50
Reference Pan Mass,56.96 mg
Reference Pan Number,10
Pan Type,Tzero Aluminum Hermetic
Comments,Al Hermetic DSC Consumables sealed Pan/Lid. A2 Tray (Google Sheet: DSC_Samples_A2_Tray_May2025)
Project Name,CA
Operator,Gibbons
Test,Custom
Unload Max Temperature,30
Unload Min Temperature,30
Load Max Temperature,30
Load Min Temperature,30
Stop on Gas Flow Error,Yes
[Signal List]
Signal #1,Time (min)
Signal #2,Temperature (°C)
Signal #3,Heat Flow (mW)
Signal #4,Delta T (µV)
Signal #5,Delta Tzero (µV)
Signal #6,Tzero Temperature (°C)
Signal #7,Cell Purge (mL/min)
Signal #8,Heater Temp (°C)
Signal #9,Power Delivered (W)
Signal #10,Reference Junction Temperature (°C)
Signal #11,Flange Temperature (°C)
Signal #12,Heat Flow Phase (rad)
Signal #13,Total Heat Capacity (J/°C)
Signal #14,Heat Capacity (J/°C)
[Configuration]
Company Name,ASU
Instrument Name,DSC2A-00468
Instrument Type,DSC2500
Serial Number,DSC2A-00468
IP,192.168.1.100
Location of Instrument,MRRC
DisplayType,Unknown
Sample Interval ,0.1 s/pt
Selected Heat Flow,T4P
Exotherm Direction,Down
Cell Serial,DRC2-00792
Lid Type,Standard
Cooler,RCS 90
Leave Cooler on at End of Sequence,On
Gas 2,Nitrogen
Gas Selected,Channel 1
Flow Rate,50 mL/min
Secondary Purge,On
Licensed Heat Flow,Heat Flow T4P
Modulation Licensed,Yes
[Versions]
Common IDD Version,1
Cortex Version,VER 2.10.2.31
Driver,5.0.0.6
GDM Version,1.0.3.3
TouchscreenVersion,1.0.0.16145
FEP Version,1.2.1.21
FEP Bootloader,2.0.0.5
AutoSampler Version,2.1.1.26
Auto Sampler Bootloader,2.0.0.5
FCM Version,1.1.0.3
FCM Bootloader,2.0.0.5
[Experiment Logs]
Experiment Log Entry # 1,Data On set to 0
Experiment Log Entry # 3,Equilibrate Segment -60 (C) Started
Experiment Log Entry # 5,Air Cool is off.
Experiment Log Entry # 7,Data On set to 1
Experiment Log Entry # 9,Ramp Segment 10 C/min to 150 Started
Experiment Log Entry # 11,Data On set to 0
Experiment Log Entry # 13,Isothermal Segment 1 min started
Experiment Log Entry # 15,Data On set to 1
Experiment Log Entry # 17,Ramp Segment 10 C/min to -60 Started
Experiment Log Entry # 19,Data On set to 0
Experiment Log Entry # 21,Isothermal Segment 1 min started
Experiment Log Entry # 23,Data On set to 1
Experiment Log Entry # 25,Ramp Segment 10 C/min to 150 Started
Experiment Log Entry # 27,Data On set to 0
Experiment Log Entry # 29,Isothermal Segment 1 min started
Experiment Log Entry # 31,Data On set to 1
Experiment Log Entry # 33,Ramp Segment 10 C/min to -60 Started
Experiment Log Entry # 35,Data On set to 0
Experiment Log Entry # 37,Isothermal Segment 1 min started
Experiment Log Entry # 39,Data On set to 1
Experiment Log Entry # 41,Ramp Segment 10 C/min to 150 Started
Experiment Log Entry # 43,Data On set to 0
Experiment Log Entry # 45,Isothermal Segment 1 min started
Experiment Log Entry # 47,Data On set to 1
Experiment Log Entry # 49,Ramp Segment 10 C/min to 30 Started
[Method Log]
Method Log Entry # 1,Data Off
Method Log Entry # 2,Equilibrate -60 °C
Method Log Entry # 3,Data On
Method Log Entry # 4,(Ramp 589997) Ramp 10 °C/minute to 150 °C
Method Log Entry # 5,Data Off
Method Log Entry # 6,Isothermal 1 minutes
Method Log Entry # 7,Data On
Method Log Entry # 8,(Ramp 590001) Ramp 10 °C/minute to -60 °C
Method Log Entry # 9,Data Off
Method Log Entry # 10,Isothermal 1 minutes
Method Log Entry # 11,Data On
Method Log Entry # 12,(Ramp 590005) Ramp 10 °C/minute to 150 °C
Method Log Entry # 13,Data Off
Method Log Entry # 14,Isothermal 1 minutes
Method Log Entry # 15,Data On
Method Log Entry # 16,(Ramp 590009) Ramp 10 °C/minute to -60 °C
Method Log Entry # 17,Data Off
Method Log Entry # 18,Isothermal 1 minutes
Method Log Entry # 19,Data On
Method Log Entry # 20,(Ramp 590013) Ramp 10 °C/minute to 150 °C
Method Log Entry # 21,Data Off
Method Log Entry # 22,Isothermal 1 minutes
Method Log Entry # 23,Data On
Method Log Entry # 24,(Ramp 590017) Ramp 10 °C/minute to 30 °C
Cell Serial,DRC2-00792
[T1 Calibration]
Slope,-0.008529666
Offset,9.636258
Initial Temperature,98.23
GUID,f8bfdadc-4977-4fdf-ba6d-0ba9134940c3
[TZero Calibration]
Date Applied,11/29/2022 4:06:13 PM
Description,From -89.059 °C to 396.009 °C at 20.000°C/min
Gas Type,Nitrogen
Pan Type,None
Source Files 1,C:\Users\yargerlab\Desktop\DSC Data\General\TZero_calibration_11_29_22_2nd(2).tri
Source Files 2,C:\Users\yargerlab\Desktop\DSC Data\General\TZero_calibration_11_29_22_2nd(3).tri
Delta T Offset,13.05235
Delta T Slope,-0.007271007
Delta T0 Offset,-13.69128
Delta T0 Slope,0.06063341
[Temperature Calibration]
Date Applied,11/29/2022 7:12:28 PM
Description,From 106.590 °C to 186.590 °C at 10.000°C/min
Gas Type,Nitrogen
Pan Type,Tzero Aluminum Hermetic
Source Files 1,C:\Users\yargerlab\Desktop\DSC Data\General\Indium(6).tri
Measured 1,157.391
Known 1,156.598
[Cell Constant Calibration]
Date Applied,11/29/2022 7:12:29 PM
Description,From 106.590 °C to 186.590 °C at 10.000°C/min
Gas Type,Nitrogen
Pan Type,Tzero Aluminum Hermetic
Source Files 1,C:\Users\yargerlab\Desktop\DSC Data\General\Indium(6).tri
T4P KCell,1.006051
Onset Slope,63.26126 mW/°C
[Direct Cp Calibration]
Date Applied,11/30/2022 11:04:51 AM
Description,From -79.983 °C to 298.409 °C at 10.000°C/min
Gas Type,Nitrogen
Pan Type,Tzero Aluminum Hermetic
Source Files 1,C:\Users\yargerlab\Desktop\DSC Data\General\Sapphire_Heat_Capacity_11_30_22.tri
[Rev Cp Calibration]
Date Applied,11/30/2022 1:58:51 PM
Description,From -79.996 °C to 292.812 °C at 3.000°C/min
Gas Type,Nitrogen
Pan Type,Tzero Aluminum Hermetic
Source Files 1,C:\Users\yargerlab\Desktop\DSC Data\General\Sapphire_MDSC_Calibration_11_30_22.tri
[step]
Ramp 10.00 °C/min to 150.00 °C
Time,Temperature,Heat Flow (Normalized)
min,°C,W/g
0.00,-59.64,-0.052
0.01,-59.66,-0.051
0.03,-59.67,-0.047
0.05,-59.67,-0.046
0.06,-59.66,-0.048
0.08,-59.65,-0.053
0.09,-59.61,-0.061
0.11,-59.57,-0.068
0.12,-59.51,-0.073
0.14,-59.44,-0.075
0.15,-59.35,-0.072
0.16,-59.26,-0.068
0.18,-59.17,-0.057
0.19,-59.06,-0.046
0.21,-58.95,-0.035
0.23,-58.84,-0.023
0.24,-58.73,-0.011
0.26,-58.61,0.001
0.27,-58.49,0.011
0.29,-58.36,0.021
0.30,-58.24,0.029
0.31,-58.11,0.038
0.33,-57.98,0.045
0.35,-57.85,0.051
0.36,-57.72,0.058
0.38,-57.59,0.063
0.39,-57.45,0.068
0.40,-57.32,0.072
0.42,-57.18,0.077
0.44,-57.05,0.080
0.45,-56.91,0.084
0.46,-56.77,0.087
0.48,-56.63,0.089
0.50,-56.49,0.092
0.51,-56.35,0.095
0.53,-56.21,0.097
0.54,-56.07,0.099
0.55,-55.92,0.100
0.57,-55.78,0.102
0.58,-55.64,0.104
0.60,-55.49,0.105
0.62,-55.35,0.106
0.63,-55.20,0.108
0.65,-55.06,0.108
0.66,-54.92,0.110
0.68,-54.77,0.110
0.69,-54.62,0.112
0.70,-54.48,0.112
0.72,-54.33,0.112
0.73,-54.19,0.114
0.75,-54.04,0.114
0.77,-53.89,0.115
0.78,-53.75,0.115
0.80,-53.60,0.115
0.81,-53.46,0.116
0.83,-53.31,0.116
0.84,-53.16,0.117
0.85,-53.01,0.117
0.87,-52.86,0.117
0.88,-52.72,0.118
0.90,-52.57,0.118
0.92,-52.42,0.118
0.93,-52.27,0.118
0.95,-52.13,0.119
0.96,-51.98,0.119
0.98,-51.83,0.119
0.99,-51.68,0.120
1.00,-51.53,0.120
1.02,-51.38,0.120
1.03,-51.23,0.120
1.05,-51.08,0.120
1.07,-50.94,0.120
1.08,-50.79,0.120
1.09,-50.64,0.121
1.11,-50.49,0.121
1.13,-50.34,0.121
1.14,-50.19,0.121
1.16,-50.05,0.121
1.17,-49.90,0.122
1.18,-49.75,0.122
1.20,-49.60,0.122
1.22,-49.45,0.122
1.23,-49.30,0.122
1.24,-49.15,0.122
1.26,-49.00,0.122
1.28,-48.85,0.122
1.29,-48.70,0.123
1.31,-48.55,0.123
1.32,-48.40,0.123
1.33,-48.25,0.123
1.35,-48.11,0.123
1.37,-47.95,0.123
1.38,-47.81,0.124
1.39,-47.66,0.124
1.41,-47.51,0.124
1.43,-47.36,0.124
1.44,-47.21,0.124
1.46,-47.06,0.124
1.47,-46.91,0.124
1.48,-46.76,0.124
1.50,-46.61,0.124
1.52,-46.46,0.124
1.53,-46.31,0.124
1.54,-46.16,0.125
1.56,-46.01,0.125
1.58,-45.86,0.125
1.59,-45.71,0.125
1.61,-45.56,0.125
1.62,-45.41,0.125
1.63,-45.26,0.125
1.65,-45.11,0.125
1.67,-44.96,0.126
1.68,-44.81,0.126
1.69,-44.66,0.126
1.71,-44.51,0.126
1.73,-44.36,0.126
1.74,-44.21,0.126
1.76,-44.06,0.126
1.77,-43.91,0.126
1.78,-43.76,0.126
1.80,-43.61,0.126
1.82,-43.46,0.126
1.83,-43.31,0.126
1.84,-43.16,0.127
1.86,-43.01,0.127
1.88,-42.86,0.127
1.89,-42.71,0.127
1.91,-42.56,0.127
1.92,-42.41,0.127
1.93,-42.26,0.127
1.95,-42.11,0.127
1.97,-41.96,0.127
1.98,-41.81,0.127
1.99,-41.66,0.127
2.01,-41.51,0.127
2.03,-41.36,0.128
2.04,-41.21,0.128
2.06,-41.06,0.128
2.07,-40.91,0.128
2.08,-40.76,0.128
2.10,-40.61,0.128
2.12,-40.46,0.128
2.13,-40.31,0.128
2.14,-40.16,0.128
2.16,-40.01,0.128
2.18,-39.86,0.128
2.19,-39.71,0.128
2.21,-39.56,0.128
2.22,-39.41,0.128
2.24,-39.26,0.128
2.25,-39.11,0.129
2.26,-38.96,0.129
2.28,-38.81,0.129
2.29,-38.66,0.129
2.31,-38.51,0.129
2.33,-38.36,0.129
2.34,-38.21,0.129
2.36,-38.06,0.129
2.37,-37.91,0.129
2.39,-37.76,0.129
2.40,-37.61,0.129
2.41,-37.46,0.129
2.43,-37.31,0.129
2.44,-37.16,0.129
2.46,-37.01,0.130
2.48,-36.86,0.130
2.49,-36.71,0.130
2.51,-36.56,0.130
2.52,-36.41,0.130
2.54,-36.26,0.130
2.55,-36.11,0.130
2.56,-35.95,0.130
2.58,-35.80,0.130
2.59,-35.65,0.130
2.61,-35.50,0.130
2.63,-35.35,0.130
2.64,-35.20,0.130
2.66,-35.05,0.130
2.67,-34.90,0.131
2.69,-34.75,0.131
2.70,-34.60,0.131
2.71,-34.45,0.131
2.73,-34.30,0.131
2.74,-34.15,0.131
2.76,-34.00,0.131
2.78,-33.85,0.131
2.79,-33.70,0.131
2.81,-33.55,0.131
2.82,-33.40,0.131
2.84,-33.25,0.131
2.85,-33.10,0.131
2.86,-32.95,0.131
2.88,-32.80,0.131
2.89,-32.65,0.131
2.91,-32.50,0.131
2.93,-32.35,0.132
2.94,-32.20,0.132
2.96,-32.05,0.132
2.97,-31.90,0.132
2.99,-31.75,0.132
3.00,-31.60,0.132
3.01,-31.45,0.132
3.03,-31.30,0.132
3.04,-31.15,0.132
3.06,-31.00,0.132
3.08,-30.85,0.132
3.09,-30.70,0.132
3.11,-30.55,0.132
3.12,-30.40,0.132
3.14,-30.25,0.133
3.15,-30.10,0.133
3.16,-29.95,0.133
3.18,-29.80,0.133
3.19,-29.65,0.133
3.21,-29.50,0.133
3.23,-29.35,0.133
3.24,-29.20,0.133
3.26,-29.05,0.133
3.27,-28.90,0.133
3.29,-28.75,0.133
3.30,-28.60,0.133
3.31,-28.44,0.133
3.33,-28.30,0.133
3.34,-28.15,0.134
3.36,-27.99,0.134
3.38,-27.84,0.134
3.39,-27.69,0.134
3.41,-27.55,0.134
3.42,-27.39,0.134
3.44,-27.25,0.134
3.45,-27.09,0.134
3.46,-26.94,0.134
3.48,-26.79,0.134
3.49,-26.64,0.134
3.51,-26.49,0.134
3.53,-26.34,0.134
3.54,-26.19,0.134
3.56,-26.04,0.135
3.57,-25.89,0.135
3.59,-25.74,0.135
3.60,-25.59,0.135
3.61,-25.44,0.135
3.63,-25.29,0.135
3.64,-25.14,0.135
3.66,-24.99,0.135
3.68,-24.84,0.135
3.69,-24.69,0.135
3.71,-24.54,0.135
3.72,-24.39,0.135
3.74,-24.24,0.135
3.75,-24.09,0.135
3.76,-23.94,0.136
3.78,-23.79,0.136
3.79,-23.64,0.136
3.81,-23.49,0.136
3.83,-23.34,0.136
3.84,-23.19,0.136
3.86,-23.04,0.136
3.87,-22.89,0.136
3.89,-22.74,0.136
3.90,-22.59,0.136
3.91,-22.44,0.136
3.93,-22.29,0.136
3.94,-22.14,0.136
3.96,-21.99,0.136
3.98,-21.84,0.136
3.99,-21.69,0.137
4.01,-21.54,0.137
4.02,-21.39,0.137
4.04,-21.24,0.137
4.05,-21.09,0.137
4.06,-20.94,0.137
4.08,-20.79,0.137
4.09,-20.64,0.137
4.11,-20.49,0.137
4.13,-20.34,0.137
4.14,-20.19,0.137
4.16,-20.04,0.137
4.17,-19.88,0.137
4.19,-19.74,0.137
4.20,-19.58,0.138
4.21,-19.43,0.138
4.23,-19.28,0.138
4.24,-19.13,0.138
4.26,-18.98,0.138
4.28,-18.83,0.138
4.29,-18.68,0.138
4.30,-18.53,0.138
4.32,-18.38,0.138
4.34,-18.23,0.138
4.35,-18.08,0.138
4.36,-17.93,0.138
4.38,-17.78,0.138
4.40,-17.63,0.138
4.41,-17.48,0.139
4.43,-17.33,0.139
4.44,-17.18,0.139
4.45,-17.03,0.139
4.47,-16.88,0.139
4.49,-16.73,0.139
4.50,-16.58,0.139
4.51,-16.43,0.139
4.53,-16.28,0.139
4.55,-16.13,0.139
4.56,-15.98,0.139
4.58,-15.83,0.139
4.59,-15.68,0.139
4.60,-15.53,0.139
4.62,-15.38,0.140
4.64,-15.23,0.140
4.65,-15.08,0.140
4.66,-14.93,0.140
4.68,-14.78,0.140
4.70,-14.63,0.140
4.71,-14.48,0.140
4.73,-14.33,0.140
4.74,-14.18,0.140
4.75,-14.03,0.140
4.77,-13.88,0.140
4.79,-13.73,0.140
4.80,-13.58,0.140
4.81,-13.43,0.141
4.83,-13.28,0.141
4.85,-13.13,0.141
4.86,-12.98,0.141
4.88,-12.83,0.141
4.89,-12.68,0.141
4.90,-12.53,0.141
4.92,-12.38,0.141
4.94,-12.23,0.141
4.95,-12.08,0.141
4.96,-11.93,0.141
4.98,-11.78,0.141
5.00,-11.63,0.141
5.01,-11.48,0.142
5.03,-11.33,0.142
5.04,-11.18,0.142
5.05,-11.03,0.142
5.07,-10.88,0.142
5.09,-10.73,0.142
5.10,-10.58,0.142
5.11,-10.43,0.142
5.13,-10.28,0.142
5.15,-10.12,0.142
5.16,-9.97,0.142
5.18,-9.83,0.142
5.19,-9.68,0.143
5.20,-9.53,0.143
5.22,-9.37,0.143
5.24,-9.23,0.143
5.25,-9.08,0.143
5.26,-8.93,0.143
5.28,-8.78,0.143
5.30,-8.63,0.143
5.31,-8.47,0.143
5.33,-8.33,0.143
5.34,-8.17,0.143
5.35,-8.03,0.143
5.37,-7.87,0.143
5.39,-7.72,0.144
5.40,-7.57,0.144
5.41,-7.42,0.144
5.43,-7.27,0.144
5.45,-7.12,0.144
5.46,-6.97,0.144
5.48,-6.82,0.144
5.49,-6.67,0.144
5.50,-6.52,0.144
5.52,-6.37,0.144
5.54,-6.22,0.145
5.55,-6.07,0.145
5.56,-5.92,0.145
5.58,-5.77,0.145
5.60,-5.62,0.145
5.61,-5.47,0.145
5.63,-5.32,0.145
5.64,-5.17,0.145
5.65,-5.02,0.145
5.67,-4.87,0.145
5.69,-4.72,0.145
5.70,-4.57,0.145
5.71,-4.42,0.145
5.73,-4.27,0.146
5.75,-4.12,0.146
5.76,-3.97,0.146
5.78,-3.82,0.146
5.79,-3.67,0.146
5.80,-3.52,0.146
5.82,-3.37,0.146
5.84,-3.22,0.146
5.85,-3.07,0.146
5.86,-2.92,0.146
5.88,-2.77,0.146
5.90,-2.62,0.146
5.91,-2.47,0.147
5.93,-2.32,0.147
5.94,-2.17,0.147
5.95,-2.02,0.147
5.97,-1.87,0.147
5.99,-1.72,0.147
6.00,-1.57,0.147
6.01,-1.42,0.147
6.03,-1.27,0.147
6.05,-1.12,0.147
6.06,-0.97,0.147
6.08,-0.82,0.147
6.09,-0.66,0.148
6.10,-0.52,0.148
6.12,-0.36,0.148
6.14,-0.21,0.148
6.15,-0.07,0.148
6.16,0.09,0.148
6.18,0.24,0.148
6.20,0.39,0.148
6.21,0.54,0.148
6.23,0.69,0.148
6.24,0.84,0.148
6.25,0.99,0.148
6.27,1.14,0.149
6.29,1.29,0.149
6.30,1.44,0.149
6.31,1.59,0.149
6.33,1.74,0.149
6.35,1.89,0.149
6.36,2.04,0.149
6.38,2.19,0.149
6.39,2.34,0.149
6.40,2.49,0.149
6.42,2.64,0.149
6.44,2.79,0.150
6.45,2.94,0.150
6.46,3.09,0.150
6.48,3.24,0.150
6.50,3.39,0.150
6.51,3.54,0.150
6.53,3.69,0.150
6.54,3.84,0.150
6.55,3.99,0.150
6.57,4.14,0.150
6.59,4.29,0.150
6.60,4.44,0.150
6.61,4.59,0.150
6.63,4.74,0.151
6.65,4.89,0.151
6.66,5.04,0.151
6.68,5.19,0.151
6.69,5.34,0.151
6.70,5.49,0.151
6.72,5.64,0.151
6.74,5.79,0.151
6.75,5.94,0.151
6.76,6.09,0.151
6.78,6.24,0.151
6.80,6.39,0.152
6.81,6.54,0.152
6.83,6.69,0.152
6.84,6.84,0.152
6.85,6.99,0.152
6.87,7.14,0.152
6.89,7.29,0.152
6.90,7.44,0.152
6.91,7.59,0.152
6.93,7.74,0.152
6.95,7.89,0.152
6.96,8.04,0.153
6.98,8.19,0.153
6.99,8.34,0.153
7.00,8.49,0.153
7.02,8.65,0.153
7.04,8.79,0.153
7.05,8.94,0.153
7.06,9.09,0.153
7.08,9.24,0.153
7.10,9.39,0.153
7.11,9.54,0.154
7.13,9.69,0.154
7.14,9.85,0.154
7.15,9.99,0.154
7.17,10.15,0.154
7.19,10.29,0.154
7.20,10.45,0.154
7.21,10.60,0.154
7.23,10.75,0.154
7.25,10.90,0.154
7.26,11.05,0.154
7.28,11.20,0.155
7.29,11.35,0.155
7.30,11.50,0.155
7.32,11.65,0.155
7.34,11.80,0.155
7.35,11.95,0.155
7.36,12.10,0.155
7.38,12.25,0.155
7.40,12.40,0.155
7.41,12.55,0.155
7.43,12.70,0.155
7.44,12.85,0.156
7.45,13.00,0.156
7.47,13.15,0.156
7.49,13.30,0.156
7.50,13.45,0.156
7.51,13.60,0.156
7.53,13.75,0.156
7.55,13.90,0.156
7.56,14.05,0.156
7.58,14.20,0.156
7.59,14.35,0.156
7.60,14.50,0.156
7.62,14.65,0.156
7.64,14.80,0.156
7.65,14.95,0.156
7.66,15.10,0.156
7.68,15.25,0.156
7.70,15.40,0.157
7.71,15.55,0.157
7.73,15.70,0.157
7.74,15.85,0.157
7.75,16.00,0.157
7.77,16.15,0.157
7.79,16.30,0.157
7.80,16.45,0.157
7.81,16.60,0.157
7.83,16.75,0.158
7.85,16.90,0.158
7.86,17.05,0.158
7.88,17.20,0.158
7.89,17.35,0.158
7.90,17.50,0.158
7.92,17.65,0.158
7.94,17.80,0.158
7.95,17.96,0.158
7.96,18.10,0.158
7.98,18.26,0.159
8.00,18.40,0.159
8.01,18.56,0.159
8.03,18.70,0.159
8.04,18.86,0.159
8.05,19.00,0.159
8.07,19.16,0.159
8.09,19.31,0.159
8.10,19.46,0.159
8.11,19.61,0.159
8.13,19.76,0.160
8.15,19.91,0.160
8.16,20.06,0.160
8.18,20.21,0.160
8.19,20.36,0.160
8.20,20.51,0.160
8.22,20.66,0.160
8.24,20.81,0.160
8.25,20.96,0.160
8.26,21.11,0.160
8.28,21.26,0.160
8.30,21.41,0.161
8.31,21.56,0.161
8.33,21.71,0.161
8.34,21.86,0.161
8.35,22.01,0.161
8.37,22.16,0.161
8.39,22.31,0.161
8.40,22.46,0.161
8.41,22.61,0.161
8.43,22.76,0.161
8.45,22.91,0.162
8.46,23.06,0.162
8.48,23.21,0.162
8.49,23.36,0.162
8.50,23.51,0.162
8.52,23.66,0.162
8.53,23.81,0.162
8.55,23.96,0.162
8.57,24.11,0.162
8.58,24.26,0.162
8.60,24.41,0.162
8.61,24.56,0.163
8.63,24.71,0.163
8.64,24.86,0.163
8.65,25.01,0.163
8.67,25.16,0.163
8.68,25.31,0.163
8.70,25.46,0.163
8.72,25.61,0.163
8.73,25.76,0.163
8.75,25.91,0.163
8.76,26.06,0.164
8.78,26.21,0.164
8.79,26.36,0.164
8.80,26.51,0.164
8.82,26.66,0.164
8.83,26.81,0.164
8.85,26.96,0.164
8.87,27.11,0.164
8.88,27.26,0.164
8.90,27.41,0.164
8.91,27.56,0.164
8.93,27.71,0.165
8.94,27.86,0.165
8.95,28.01,0.165
8.97,28.16,0.165
8.98,28.31,0.165
9.00,28.46,0.165
9.02,28.61,0.165
9.03,28.76,0.165
9.05,28.91,0.165
9.06,29.06,0.165
9.08,29.21,0.165
9.09,29.36,0.166
9.10,29.51,0.166
9.12,29.66,0.166
9.13,29.81,0.166
9.15,29.96,0.166
9.17,30.11,0.166
9.18,30.26,0.166
9.20,30.41,0.166
9.21,30.57,0.166
9.23,30.71,0.166
9.24,30.87,0.166
9.25,31.02,0.167
9.27,31.17,0.167
9.28,31.32,0.167
9.30,31.47,0.167
9.32,31.62,0.167
9.33,31.77,0.167
9.35,31.92,0.167
9.36,32.07,0.167
9.38,32.22,0.167
9.39,32.37,0.167
9.40,32.52,0.167
9.42,32.67,0.167
9.43,32.82,0.168
9.45,32.97,0.168
9.47,33.12,0.168
9.48,33.27,0.168
9.50,33.42,0.168
9.51,33.57,0.168
9.53,33.72,0.168
9.54,33.87,0.168
9.55,34.02,0.168
9.57,34.17,0.168
9.58,34.32,0.168
9.60,34.47,0.169
9.62,34.62,0.169
9.63,34.77,0.169
9.65,34.92,0.169
9.66,35.07,0.169
9.68,35.22,0.169
9.69,35.37,0.169
9.70,35.52,0.169
9.72,35.67,0.169
9.73,35.82,0.169
9.75,35.97,0.169
9.77,36.12,0.169
9.78,36.27,0.170
9.80,36.42,0.170
9.81,36.57,0.170
9.83,36.72,0.170
9.84,36.87,0.170
9.85,37.02,0.170
9.87,37.17,0.170
9.88,37.32,0.170
9.90,37.47,0.170
9.92,37.62,0.171
9.93,37.77,0.171
9.95,37.92,0.171
9.96,38.07,0.171
9.98,38.22,0.171
9.99,38.37,0.171
10.00,38.52,0.171
10.02,38.67,0.171
10.03,38.82,0.171
10.05,38.97,0.171
10.07,39.12,0.171
10.08,39.27,0.172
10.10,39.42,0.172
10.11,39.57,0.172
10.13,39.73,0.172
10.14,39.87,0.172
10.15,40.03,0.172
10.17,40.18,0.172
10.18,40.33,0.172
10.20,40.48,0.172
10.22,40.63,0.172
10.23,40.78,0.172
10.25,40.93,0.172
10.26,41.08,0.172
10.28,41.23,0.173
10.29,41.38,0.173
10.30,41.53,0.173
10.32,41.68,0.173
10.33,41.83,0.173
10.35,41.98,0.173
10.37,42.13,0.173
10.38,42.28,0.173
10.40,42.43,0.173
10.41,42.58,0.173
10.43,42.73,0.173
10.44,42.88,0.174
10.45,43.03,0.174
10.47,43.18,0.174
10.48,43.33,0.174
10.50,43.48,0.174
10.52,43.63,0.174
10.53,43.78,0.174
10.55,43.93,0.174
10.56,44.08,0.174
10.58,44.23,0.174
10.59,44.38,0.174
10.60,44.53,0.175
10.62,44.68,0.175
10.63,44.83,0.175
10.65,44.98,0.175
10.67,45.13,0.175
10.68,45.28,0.175
10.70,45.43,0.175
10.71,45.58,0.175
10.73,45.73,0.175
10.74,45.88,0.175
10.75,46.03,0.175
10.77,46.18,0.176
10.78,46.33,0.176
10.80,46.48,0.176
10.82,46.63,0.176
10.83,46.78,0.176
10.85,46.93,0.176
10.86,47.08,0.176
10.88,47.23,0.176
10.89,47.38,0.176
10.90,47.53,0.176
10.92,47.68,0.177
10.93,47.83,0.177
10.95,47.98,0.177
10.97,48.13,0.177
10.98,48.28,0.177
11.00,48.43,0.177
11.01,48.58,0.177
11.03,48.73,0.177
11.04,48.88,0.177
11.05,49.03,0.177
11.07,49.18,0.177
11.08,49.33,0.177
11.10,49.48,0.178
11.12,49.63,0.178
11.13,49.78,0.178
11.15,49.93,0.178
11.16,50.08,0.178
11.18,50.23,0.178
11.19,50.38,0.178
11.20,50.53,0.178
11.22,50.68,0.178
11.23,50.83,0.178
11.25,50.98,0.178
11.27,51.13,0.179
11.28,51.28,0.179
11.30,51.44,0.179
11.31,51.58,0.179
11.33,51.74,0.179
11.34,51.89,0.179
11.35,52.03,0.179
11.37,52.19,0.179
11.38,52.33,0.179
11.40,52.49,0.179
11.42,52.64,0.179
11.43,52.79,0.179
11.45,52.94,0.180
11.46,53.09,0.180
11.48,53.24,0.180
11.49,53.39,0.180
11.50,53.54,0.180
11.52,53.69,0.180
11.53,53.84,0.180
11.55,53.99,0.180
11.57,54.14,0.180
11.58,54.29,0.180
11.60,54.44,0.180
11.61,54.59,0.181
11.63,54.74,0.181
11.64,54.89,0.181
11.65,55.04,0.181
11.67,55.19,0.181
11.68,55.34,0.181
11.70,55.49,0.181
11.72,55.64,0.181
11.73,55.79,0.181
11.75,55.94,0.181
11.76,56.09,0.181
11.78,56.24,0.181
11.79,56.39,0.182
11.80,56.54,0.182
11.82,56.69,0.182
11.83,56.84,0.182
11.85,56.99,0.182
11.87,57.14,0.182
11.88,57.29,0.182
11.90,57.44,0.182
11.91,57.59,0.182
11.93,57.74,0.182
11.94,57.89,0.182
11.95,58.04,0.182
11.97,58.19,0.182
11.98,58.34,0.183
12.00,58.49,0.183
12.02,58.64,0.183
12.03,58.79,0.183
12.05,58.94,0.183
12.06,59.09,0.183
12.08,59.24,0.183
12.09,59.39,0.183
12.10,59.54,0.183
12.12,59.69,0.183
12.13,59.84,0.183
12.15,59.99,0.184
12.17,60.14,0.184
12.18,60.29,0.184
12.20,60.44,0.184
12.21,60.59,0.184
12.23,60.74,0.184
12.24,60.89,0.184
12.25,61.04,0.184
12.27,61.19,0.184
12.28,61.34,0.184
12.30,61.49,0.184
12.32,61.64,0.185
12.33,61.79,0.185
12.35,61.94,0.185
12.36,62.09,0.185
12.38,62.24,0.185
12.39,62.39,0.185
12.40,62.54,0.185
12.42,62.69,0.185
12.43,62.84,0.185
12.45,62.99,0.185
12.47,63.14,0.186
12.48,63.29,0.186
12.50,63.44,0.186
12.51,63.59,0.186
12.53,63.74,0.186
12.54,63.89,0.186
12.55,64.04,0.186
12.57,64.19,0.186
12.58,64.34,0.186
12.60,64.49,0.186
12.62,64.64,0.186
12.63,64.79,0.186
12.65,64.94,0.187
12.66,65.10,0.187
12.68,65.25,0.187
12.69,65.40,0.187
12.70,65.55,0.187
12.72,65.70,0.187
12.73,65.85,0.187
12.75,66.00,0.187
12.77,66.15,0.187
12.78,66.30,0.187
12.80,66.45,0.187
12.81,66.60,0.188
12.83,66.75,0.188
12.84,66.90,0.188
12.85,67.05,0.188
12.87,67.20,0.188
12.88,67.35,0.188
12.90,67.50,0.188
12.92,67.65,0.188
12.93,67.80,0.188
12.95,67.95,0.188
12.96,68.10,0.188
12.98,68.25,0.188
12.99,68.40,0.189
13.00,68.55,0.189
13.02,68.70,0.189
13.03,68.85,0.189
13.05,69.00,0.189
13.07,69.15,0.189
13.08,69.30,0.189
13.10,69.45,0.189
13.11,69.60,0.189
13.13,69.75,0.189
13.14,69.90,0.189
13.15,70.05,0.189
13.17,70.20,0.190
13.18,70.35,0.190
13.20,70.50,0.190
13.22,70.65,0.190
13.23,70.80,0.190
13.25,70.95,0.190
13.26,71.10,0.190
13.28,71.25,0.190
13.29,71.40,0.190
13.30,71.55,0.190
13.32,71.70,0.190
13.33,71.85,0.191
13.35,72.00,0.191
13.37,72.15,0.191
13.38,72.30,0.191
13.40,72.45,0.191
13.41,72.60,0.191
13.43,72.75,0.191
13.44,72.90,0.191
13.45,73.05,0.191
13.47,73.20,0.191
13.48,73.35,0.191
13.50,73.50,0.191
13.52,73.65,0.191
13.53,73.80,0.192
13.55,73.95,0.192
13.56,74.10,0.192
13.58,74.25,0.192
13.59,74.40,0.192
13.60,74.55,0.192
13.62,74.70,0.192
13.63,74.85,0.192
13.65,75.00,0.192
13.67,75.16,0.192
13.68,75.31,0.192
13.70,75.46,0.193
13.71,75.61,0.193
13.73,75.76,0.193
13.74,75.91,0.193
13.75,76.06,0.193
13.77,76.21,0.193
13.78,76.36,0.193
13.80,76.51,0.193
13.82,76.66,0.193
13.83,76.81,0.193
13.85,76.96,0.194
13.86,77.11,0.194
13.88,77.26,0.194
13.89,77.41,0.194
13.90,77.56,0.194
13.92,77.71,0.194
13.93,77.86,0.194
13.95,78.01,0.194
13.97,78.16,0.194
13.98,78.31,0.194
14.00,78.46,0.194
14.01,78.61,0.195
14.03,78.76,0.195
14.04,78.91,0.195
14.05,79.06,0.195
14.07,79.21,0.195
14.08,79.36,0.195
14.10,79.51,0.195
14.12,79.66,0.195
14.13,79.81,0.195
14.15,79.96,0.195
14.16,80.11,0.195
14.18,80.26,0.195
14.19,80.41,0.196
14.20,80.56,0.196
14.22,80.71,0.196
14.23,80.86,0.196
14.25,81.01,0.196
14.27,81.16,0.196
14.28,81.31,0.196
14.30,81.46,0.196
14.31,81.61,0.196
14.33,81.76,0.196
14.34,81.91,0.196
14.35,82.06,0.196
14.37,82.21,0.196
14.38,82.36,0.196
14.40,82.51,0.197
14.42,82.66,0.197
14.43,82.81,0.197
14.45,82.96,0.197
14.46,83.11,0.197
14.48,83.26,0.197
14.49,83.41,0.197
14.50,83.56,0.197
14.52,83.71,0.197
14.53,83.86,0.197
14.55,84.01,0.198
14.57,84.16,0.198
14.58,84.31,0.198
14.60,84.46,0.198
14.61,84.61,0.198
14.63,84.76,0.198
14.64,84.91,0.198
14.65,85.06,0.198
14.67,85.21,0.198
14.68,85.36,0.198
14.70,85.52,0.198
14.72,85.66,0.198
14.73,85.82,0.198
14.75,85.97,0.198
14.76,86.12,0.198
14.78,86.27,0.199
14.79,86.41,0.199
14.80,86.57,0.199
14.82,86.72,0.199
14.83,86.87,0.199
14.85,87.02,0.199
14.87,87.17,0.199
14.88,87.32,0.199
14.90,87.47,0.199
14.91,87.62,0.199
14.93,87.77,0.199
14.94,87.92,0.199
14.95,88.07,0.200
14.97,88.22,0.200
14.98,88.37,0.200
15.00,88.52,0.200
15.02,88.67,0.200
15.03,88.82,0.200
15.05,88.97,0.200
15.06,89.12,0.200
15.08,89.27,0.200
15.09,89.42,0.200
15.10,89.57,0.200
15.12,89.72,0.201
15.13,89.87,0.201
15.15,90.02,0.201
15.17,90.17,0.201
15.18,90.32,0.201
15.20,90.47,0.201
15.21,90.62,0.201
15.23,90.77,0.201
15.24,90.92,0.201
15.25,91.07,0.201
15.27,91.22,0.202
15.28,91.37,0.202
15.30,91.52,0.202
15.32,91.67,0.202
15.33,91.82,0.202
15.35,91.97,0.202
15.36,92.12,0.202
15.38,92.27,0.202
15.39,92.42,0.202
15.40,92.57,0.203
15.42,92.72,0.203
15.43,92.87,0.203
15.45,93.02,0.203
15.47,93.17,0.203
15.48,93.32,0.203
15.50,93.47,0.203
15.51,93.62,0.203
15.53,93.77,0.203
15.54,93.92,0.203
15.55,94.07,0.203
15.57,94.22,0.203
15.58,94.37,0.204
15.60,94.52,0.204
15.62,94.67,0.204
15.63,94.82,0.204
15.65,94.97,0.204
15.66,95.12,0.204
15.68,95.27,0.204
15.69,95.43,0.204
15.70,95.57,0.204
15.72,95.72,0.204
15.73,95.88,0.205
15.75,96.03,0.205
15.77,96.18,0.205
15.78,96.33,0.205
15.80,96.48,0.205
15.81,96.63,0.205
15.83,96.78,0.205
15.84,96.93,0.205
15.85,97.08,0.205
15.87,97.23,0.206
15.88,97.38,0.206
15.90,97.53,0.206
15.92,97.68,0.206
15.93,97.83,0.206
15.95,97.98,0.206
15.96,98.13,0.206
15.98,98.28,0.206
15.99,98.43,0.206
16.00,98.58,0.206
16.02,98.73,0.206
16.03,98.88,0.207
16.05,99.03,0.207
16.07,99.18,0.207
16.08,99.33,0.207
16.10,99.48,0.207
16.11,99.63,0.207
16.13,99.78,0.207
16.14,99.93,0.207
16.15,100.08,0.207
16.17,100.23,0.208
16.18,100.38,0.208
16.20,100.53,0.208
16.22,100.68,0.208
16.23,100.83,0.208
16.25,100.98,0.208
16.26,101.13,0.208
16.28,101.28,0.208
16.29,101.43,0.208
16.30,101.58,0.208
16.32,101.73,0.208
16.33,101.88,0.208
16.35,102.03,0.208
16.37,102.18,0.208
16.38,102.33,0.209
16.40,102.48,0.209
16.41,102.63,0.209
16.43,102.78,0.209
16.44,102.93,0.209
16.45,103.08,0.209
16.47,103.23,0.209
16.48,103.38,0.209
16.50,103.53,0.209
16.52,103.68,0.209
16.53,103.83,0.210
16.55,103.98,0.210
16.56,104.13,0.210
16.58,104.28,0.210
16.59,104.43,0.210
16.60,104.58,0.210
16.62,104.73,0.210
16.63,104.88,0.210
16.65,105.03,0.210
16.67,105.18,0.210
16.68,105.33,0.211
16.70,105.48,0.211
16.71,105.63,0.211
16.73,105.78,0.211
16.74,105.93,0.211
16.75,106.08,0.211
16.77,106.23,0.211
16.78,106.38,0.211
16.80,106.53,0.211
16.82,106.68,0.211
16.83,106.83,0.211
16.85,106.98,0.212
16.86,107.13,0.212
16.88,107.28,0.212
16.89,107.43,0.212
16.90,107.58,0.212
16.92,107.73,0.212
16.93,107.88,0.212
16.95,108.03,0.212
16.97,108.18,0.212
16.98,108.33,0.212
17.00,108.48,0.212
17.01,108.63,0.213
17.03,108.78,0.213
17.04,108.93,0.213
17.05,109.08,0.213
17.07,109.23,0.213
17.08,109.38,0.213
17.10,109.53,0.213
17.12,109.68,0.213
17.13,109.83,0.214
17.14,109.98,0.214
17.16,110.13,0.214
17.18,110.28,0.214
17.19,110.43,0.214
17.21,110.58,0.214
17.22,110.74,0.214
17.23,110.88,0.214
17.25,111.03,0.214
17.27,111.18,0.215
17.28,111.33,0.215
17.29,111.48,0.215
17.31,111.63,0.215
17.33,111.78,0.215
17.34,111.93,0.215
17.36,112.08,0.215
17.37,112.23,0.215
17.38,112.38,0.215
17.40,112.53,0.215
17.42,112.68,0.215
17.43,112.83,0.215
17.44,112.98,0.216
17.46,113.13,0.216
17.48,113.28,0.216
17.49,113.43,0.216
17.51,113.58,0.216
17.52,113.73,0.216
17.53,113.88,0.216
17.55,114.03,0.216
17.57,114.18,0.216
17.58,114.33,0.216
17.59,114.48,0.217
17.61,114.63,0.217
17.63,114.78,0.217
17.64,114.94,0.217
17.66,115.08,0.217
17.67,115.24,0.217
17.68,115.39,0.217
17.70,115.54,0.217
17.72,115.68,0.217
17.73,115.84,0.218
17.74,115.99,0.218
17.76,116.14,0.218
17.78,116.29,0.218
17.79,116.44,0.218
17.81,116.59,0.218
17.82,116.74,0.218
17.83,116.89,0.219
17.85,117.04,0.219
17.87,117.19,0.219
17.88,117.34,0.219
17.89,117.49,0.219
17.91,117.64,0.219
17.93,117.79,0.219
17.94,117.94,0.219
17.96,118.09,0.220
17.97,118.24,0.220
17.98,118.39,0.220
18.00,118.54,0.220
18.02,118.69,0.220
18.03,118.84,0.220
18.04,118.99,0.220
18.06,119.14,0.220
18.08,119.29,0.221
18.09,119.44,0.221
18.11,119.59,0.221
18.12,119.74,0.221
18.13,119.89,0.221
18.15,120.04,0.221
18.17,120.19,0.221
18.18,120.34,0.221
18.19,120.49,0.222
18.21,120.64,0.222
18.23,120.79,0.222
18.24,120.94,0.222
18.26,121.09,0.222
18.27,121.24,0.223
18.28,121.39,0.223
18.30,121.54,0.224
18.32,121.69,0.225
18.33,121.84,0.227
18.34,121.99,0.230
18.36,122.13,0.234
18.38,122.28,0.241
18.39,122.43,0.301
18.41,122.53,0.610
18.42,122.58,0.812
18.43,122.63,0.957
18.45,122.68,1.094
18.47,122.73,1.217
18.48,122.77,1.339
18.49,122.82,1.461
18.51,122.87,1.578
18.53,122.92,1.703
18.54,122.97,1.825
18.56,123.01,1.944
18.57,123.06,2.068
18.58,123.11,2.184
18.60,123.17,2.286
18.62,123.23,2.360
18.63,123.29,2.433
18.64,123.36,2.570
18.66,123.42,2.685
18.68,123.48,2.731
18.69,123.56,2.828
18.71,123.62,3.009
18.72,123.67,3.140
18.73,123.71,3.295
18.75,123.78,3.294
18.77,123.86,3.358
18.78,123.92,3.486
18.79,124.00,3.582
18.81,124.06,3.698
18.83,124.13,3.821
18.84,124.19,3.873
18.86,124.28,3.828
18.87,124.38,3.878
18.88,124.48,3.953
18.90,124.59,3.948
18.92,124.68,4.206
18.93,124.75,4.247
18.94,124.86,4.187
18.96,124.97,4.198
18.98,125.10,4.185
18.99,125.22,4.211
19.01,125.36,4.184
19.02,125.51,4.108
19.03,125.68,4.031
19.05,125.86,3.903
19.07,126.06,3.817
19.08,126.25,3.825
19.09,126.43,3.786
19.11,126.63,3.644
19.13,126.85,3.435
19.14,127.10,3.193
19.16,127.39,2.886
19.17,127.70,2.593
19.18,128.03,2.323
19.20,128.36,2.132
19.22,128.68,1.897
19.23,129.02,1.633
19.24,129.36,1.449
19.26,129.68,1.316
19.28,129.98,1.205
19.29,130.26,1.108
19.31,130.54,1.022
19.32,130.79,0.945
19.33,131.04,0.877
19.35,131.28,0.815
19.37,131.50,0.762
19.38,131.72,0.713
19.39,131.93,0.670
19.41,132.14,0.630
19.43,132.34,0.596
19.44,132.53,0.566
19.46,132.72,0.538
19.47,132.90,0.513
19.48,133.08,0.491
19.50,133.26,0.471
19.52,133.43,0.454
19.53,133.61,0.439
19.54,133.78,0.424
19.56,133.94,0.410
19.58,134.11,0.401
19.59,134.27,0.392
19.61,134.43,0.383
19.62,134.60,0.374
19.63,134.75,0.366
19.65,134.91,0.357
19.67,135.07,0.348
19.68,135.23,0.349
19.69,135.39,0.346
19.71,135.54,0.342
19.73,135.70,0.339
19.74,135.85,0.337
19.76,136.00,0.334
19.77,136.16,0.332
19.78,136.31,0.330
19.80,136.46,0.329
19.82,136.61,0.327
19.83,136.77,0.325
19.84,136.92,0.324
19.86,137.07,0.323
19.88,137.22,0.322
19.89,137.37,0.321
19.91,137.52,0.321
19.92,137.67,0.320
19.93,137.83,0.320
19.95,137.97,0.319
19.97,138.13,0.319
19.98,138.28,0.319
19.99,138.43,0.319
20.01,138.58,0.318
20.03,138.73,0.318
20.04,138.88,0.318
20.06,139.03,0.318
20.07,139.18,0.318
20.08,139.33,0.318
20.10,139.48,0.318
20.12,139.63,0.318
20.13,139.78,0.317
20.14,139.93,0.317
20.16,140.08,0.317
20.18,140.23,0.317
20.19,140.38,0.317
20.21,140.53,0.317
20.22,140.68,0.317
20.23,140.83,0.317
20.25,140.98,0.317
20.27,141.13,0.317
20.28,141.28,0.317
20.29,141.43,0.317
20.31,141.58,0.317
20.33,141.73,0.317
20.34,141.88,0.317
20.36,142.03,0.317
20.37,142.18,0.317
20.38,142.33,0.317
20.40,142.48,0.317
20.42,142.63,0.317
20.43,142.79,0.317
20.44,142.94,0.317
20.46,143.08,0.318
20.48,143.24,0.318
20.49,143.38,0.318
20.51,143.53,0.318
20.52,143.69,0.318
20.53,143.84,0.318
20.55,143.99,0.318
20.57,144.14,0.318
20.58,144.29,0.318
20.59,144.44,0.318
20.61,144.59,0.318
20.63,144.74,0.318
20.64,144.89,0.319
20.66,145.04,0.319
20.67,145.19,0.319
20.68,145.34,0.319
20.70,145.49,0.319
20.72,145.64,0.319
20.73,145.79,0.319
20.74,145.94,0.319
20.76,146.09,0.319
20.78,146.24,0.319
20.79,146.39,0.320
20.81,146.54,0.320
20.82,146.69,0.320
20.83,146.84,0.320
20.85,146.99,0.320
20.87,147.14,0.320
20.88,147.29,0.320
20.89,147.44,0.320
20.91,147.59,0.320
20.93,147.74,0.320
20.94,147.89,
20.96,148.04,
20.97,148.19,
20.98,,
20.99,,

[step]
Ramp 10.00 °C/min to -60.00 °C
Time,Temperature,Heat Flow (Normalized)
min,°C,W/g
21.99,150.10,-0.012
22.01,150.11,-0.013
22.02,150.10,-0.013
22.04,150.10,-0.013
22.05,150.08,-0.007
22.07,150.06,0.001
22.08,150.02,0.006
22.10,149.97,0.006
22.11,149.90,-0.001
22.13,149.82,-0.021
22.14,149.74,-0.044
22.16,149.64,-0.071
22.17,149.54,-0.099
22.19,149.44,-0.125
22.20,149.33,-0.149
22.22,149.21,-0.170
22.23,149.10,-0.188
22.25,148.98,-0.205
22.26,148.85,-0.220
22.28,148.73,-0.233
22.29,148.60,-0.245
22.31,148.47,-0.256
22.32,148.34,-0.265
22.34,148.21,-0.274
22.35,148.07,-0.282
22.37,147.93,-0.289
22.38,147.80,-0.295
22.40,147.66,-0.301
22.41,147.52,-0.306
22.43,147.38,-0.310
22.44,147.24,-0.315
22.46,147.10,-0.319
22.47,146.95,-0.322
22.49,146.81,-0.325
22.50,146.67,-0.327
22.52,146.52,-0.330
22.53,146.38,-0.332
22.55,146.23,-0.334
22.56,146.09,-0.335
22.58,145.94,-0.337
22.59,145.79,-0.338
22.61,145.65,-0.340
22.62,145.50,-0.340
22.64,145.36,-0.341
22.65,145.21,-0.342
22.67,145.06,-0.343
22.68,144.91,-0.344
22.70,144.77,-0.344
22.71,144.62,-0.345
22.73,144.47,-0.345
22.74,144.32,-0.346
22.76,144.18,-0.346
22.77,144.03,-0.346
22.79,143.88,-0.347
22.80,143.73,-0.347
22.82,143.58,-0.347
22.83,143.43,-0.347
22.85,143.29,-0.347
22.86,143.14,-0.347
22.88,142.99,-0.347
22.89,142.84,-0.348
22.91,142.69,-0.348
22.92,142.54,-0.348
22.94,142.39,-0.348
22.95,142.24,-0.348
22.97,142.10,-0.348
22.98,141.95,-0.348
23.00,141.80,-0.348
23.01,141.65,-0.348
23.03,141.50,-0.348
23.04,141.35,-0.349
23.06,141.20,-0.349
23.07,141.05,-0.349
23.09,140.90,-0.349
23.10,140.75,-0.349
23.12,140.60,-0.349
23.13,140.45,-0.349
23.15,140.30,-0.349
23.16,140.15,-0.349
23.18,140.00,-0.349
23.19,139.86,-0.349
23.21,139.71,-0.349
23.22,139.56,-0.349
23.24,139.41,-0.349
23.25,139.26,-0.349
23.27,139.11,-0.349
23.28,138.96,-0.349
23.30,138.81,-0.349
23.31,138.66,-0.349
23.33,138.51,-0.349
23.34,138.36,-0.349
23.36,138.21,-0.349
23.37,138.06,-0.349
23.39,137.91,-0.349
23.40,137.76,-0.349
23.42,137.61,-0.349
23.43,137.46,-0.349
23.45,137.31,-0.349
23.46,137.16,-0.349
23.48,137.01,-0.349
23.49,136.86,-0.349
23.51,136.71,-0.349
23.52,136.56,-0.349
23.54,136.41,-0.349
23.55,136.26,-0.348
23.57,136.11,-0.348
23.58,135.96,-0.348
23.60,135.81,-0.348
23.61,135.66,-0.348
23.63,135.52,-0.348
23.64,135.37,-0.348
23.66,135.22,-0.348
23.67,135.07,-0.348
23.69,134.92,-0.347
23.70,134.77,-0.347
23.72,134.62,-0.347
23.73,134.47,-0.347
23.75,134.32,-0.347
23.76,134.17,-0.347
23.78,134.02,-0.347
23.79,133.87,-0.347
23.81,133.72,-0.347
23.82,133.57,-0.347
23.84,133.42,-0.346
23.85,133.27,-0.346
23.87,133.12,-0.346
23.88,132.97,-0.346
23.90,132.82,-0.346
23.91,132.67,-0.346
23.93,132.52,-0.346
23.94,132.37,-0.346
23.96,132.22,-0.346
23.97,132.07,-0.346
23.99,131.92,-0.345
24.00,131.77,-0.345
24.02,131.62,-0.345
24.03,131.47,-0.345
24.05,131.32,-0.345
24.06,131.17,-0.345
24.08,131.02,-0.345
24.09,130.87,-0.345
24.11,130.72,-0.345
24.12,130.57,-0.345
24.14,130.42,-0.344
24.15,130.27,-0.344
24.17,130.12,-0.344
24.18,129.97,-0.344
24.20,129.82,-0.344
24.21,129.67,-0.344
24.23,129.52,-0.344
24.24,129.37,-0.344
24.26,129.22,-0.344
24.27,129.07,-0.343
24.29,128.92,-0.343
24.30,128.77,-0.343
24.32,128.62,-0.343
24.33,128.47,-0.343
24.35,128.33,-0.343
24.36,128.18,-0.343
24.38,128.02,-0.343
24.39,127.88,-0.342
24.41,127.73,-0.342
24.42,127.58,-0.342
24.44,127.43,-0.342
24.45,127.28,-0.342
24.47,127.13,-0.342
24.48,126.98,-0.342
24.50,126.83,-0.341
24.51,126.68,-0.341
24.53,126.53,-0.341
24.54,126.38,-0.341
24.56,126.23,-0.341
24.57,126.08,-0.341
24.59,125.93,-0.341
24.60,125.78,-0.340
24.62,125.63,-0.340
24.63,125.48,-0.340
24.65,125.33,-0.340
24.66,125.18,-0.340
24.68,125.03,-0.340
24.69,124.88,-0.340
24.71,124.73,-0.340
24.72,124.58,-0.340
24.74,124.43,-0.339
24.75,124.28,-0.339
24.77,124.13,-0.339
24.78,123.98,-0.339
24.80,123.83,-0.339
24.81,123.68,-0.339
24.83,123.53,-0.339
24.84,123.38,-0.339
24.86,123.23,-0.338
24.87,123.08,-0.338
24.89,122.93,-0.338
24.90,122.78,-0.338
24.92,122.63,-0.338
24.93,122.48,-0.338
24.95,122.33,-0.338
24.96,122.18,-0.338
24.98,122.03,-0.337
24.99,121.88,-0.337
25.01,121.73,-0.337
25.02,121.58,-0.337
25.04,121.43,-0.337
25.05,121.28,-0.337
25.07,121.13,-0.336
25.08,120.98,-0.336
25.10,120.83,-0.336
25.11,120.68,-0.336
25.13,120.53,-0.336
25.14,120.38,-0.336
25.16,120.23,-0.336
25.17,120.08,-0.336
25.19,119.93,-0.335
25.20,119.78,-0.335
25.22,119.63,-0.335
25.23,119.48,-0.335
25.25,119.33,-0.335
25.26,119.18,-0.335
25.28,119.03,-0.335
25.29,118.88,-0.335
25.31,118.73,-0.334
25.32,118.58,-0.334
25.34,118.43,-0.334
25.35,118.28,-0.334
25.37,118.13,-0.334
25.38,117.98,-0.334
25.40,117.83,-0.334
25.41,117.68,-0.333
25.43,117.53,-0.333
25.44,117.38,-0.333
25.46,117.23,-0.333
25.47,117.08,-0.333
25.49,116.93,-0.333
25.50,116.78,-0.333
25.52,116.63,-0.333
25.53,116.48,-0.333
25.55,116.33,-0.332
25.56,116.18,-0.332
25.58,116.03,-0.332
25.59,115.88,-0.332
25.61,115.74,-0.332
25.62,115.58,-0.332
25.64,115.43,-0.331
25.65,115.28,-0.331
25.67,115.14,-0.331
25.68,114.98,-0.331
25.70,114.84,-0.331
25.71,114.68,-0.331
25.73,114.53,-0.331
25.74,114.39,-0.331
25.76,114.24,-0.331
25.77,114.09,-0.330
25.79,113.94,-0.330
25.80,113.79,-0.330
25.82,113.64,-0.330
25.83,113.49,-0.330
25.85,113.34,-0.330
25.86,113.19,-0.330
25.88,113.04,-0.329
25.89,112.89,-0.329
25.91,112.74,-0.329
25.92,112.59,-0.329
25.94,112.44,-0.329
25.95,112.29,-0.329
25.97,112.14,-0.329
25.98,111.99,-0.329
26.00,111.84,-0.328
26.01,111.69,-0.328
26.03,111.54,-0.328
26.04,111.39,-0.328
26.06,111.24,-0.328
26.07,111.09,-0.328
26.09,110.94,-0.328
26.10,110.79,-0.328
26.12,110.64,-0.328
26.13,110.49,-0.327
26.15,110.34,-0.327
26.16,110.19,-0.327
26.18,110.04,-0.327
26.19,109.89,-0.327
26.21,109.74,-0.327
26.22,109.59,-0.326
26.24,109.44,-0.326
26.25,109.29,-0.326
26.27,109.14,-0.326
26.28,108.99,-0.326
26.30,108.84,-0.326
26.31,108.69,-0.326
26.33,108.54,-0.326
26.34,108.39,-0.325
26.36,108.24,-0.325
26.37,108.09,-0.325
26.39,107.94,-0.325
26.40,107.79,-0.325
26.42,107.64,-0.325
26.43,107.49,-0.325
26.45,107.34,-0.325
26.46,107.19,-0.324
26.48,107.04,-0.324
26.49,106.89,-0.324
26.51,106.74,-0.324
26.52,106.59,-0.324
26.54,106.44,-0.324
26.55,106.29,-0.323
26.57,106.14,-0.323
26.58,105.99,-0.323
26.60,105.84,-0.323
26.61,105.69,-0.323
26.63,105.54,-0.323
26.64,105.39,-0.323
26.66,105.24,-0.323
26.67,105.09,-0.323
26.69,104.94,-0.322
26.70,104.79,-0.322
26.72,104.64,-0.322
26.73,104.49,-0.322
26.75,104.34,-0.322
26.76,104.19,-0.322
26.78,104.04,-0.322
26.79,103.89,-0.321
26.81,103.74,-0.321
26.82,103.59,-0.321
26.84,103.45,-0.321
26.85,103.29,-0.321
26.87,103.15,-0.321
26.88,103.00,-0.321
26.90,102.85,-0.321
26.91,102.70,-0.320
26.93,102.55,-0.320
26.94,102.40,-0.320
26.96,102.25,-0.320
26.97,102.10,-0.320
26.99,101.95,-0.320
27.00,101.80,-0.320
27.02,101.65,-0.319
27.03,101.50,-0.319
27.05,101.35,-0.319
27.06,101.20,-0.319
27.08,101.05,-0.319
27.09,100.90,-0.319
27.11,100.75,-0.319
27.12,100.60,-0.319
27.14,100.45,-0.318
27.15,100.30,-0.318
27.17,100.15,-0.318
27.18,100.00,-0.318
27.20,99.85,-0.318
27.21,99.70,-0.318
27.23,99.55,-0.318
27.24,99.45,-5.139
27.26,105.00,-41.373
27.27,108.29,-21.042
27.29,108.90,-14.014
27.30,108.70,-10.958
27.32,108.19,-9.176
27.33,107.52,-7.810
27.35,106.73,-6.218
27.36,105.77,-4.552
27.38,104.77,-3.630
27.39,103.84,-3.122
27.41,102.99,-2.763
27.42,102.22,-2.470
27.44,101.52,-2.217
27.45,100.89,-1.991
27.47,100.31,-1.792
27.48,99.78,-1.615
27.50,99.30,-1.458
27.51,98.86,-1.318
27.53,98.45,-1.195
27.54,98.07,-1.084
27.56,97.72,-0.988
27.57,97.39,-0.902
27.59,97.08,-0.825
27.60,96.79,-0.758
27.62,96.52,-0.699
27.63,96.26,-0.645
27.65,96.02,-0.598
27.66,95.78,-0.557
27.68,95.56,-0.520
27.69,95.34,-0.488
27.71,95.13,-0.459
27.72,94.93,-0.433
27.74,94.73,-0.410
27.75,94.54,-0.391
27.77,94.36,-0.373
27.78,94.18,-0.358
27.80,94.00,-0.343
27.81,93.83,-0.331
27.83,93.65,-0.320
27.84,93.49,-0.310
27.86,93.32,-0.301
27.87,93.15,-0.295
27.89,92.99,-0.288
27.90,92.83,-0.282
27.92,92.67,-0.277
27.93,92.51,-0.272
27.95,92.35,-0.269
27.96,92.19,-0.264
27.98,92.04,-0.262
27.99,91.88,-0.258
28.01,91.73,-0.256
28.02,91.57,-0.253
28.04,91.42,-0.251
28.05,91.27,-0.249
28.07,91.11,-0.247
28.08,90.96,-0.247
28.10,90.81,-0.245
[...]
113.73,114.55,-0.328
113.74,114.46,-0.328
113.74,114.38,-0.328
113.75,114.30,-0.328
113.76,114.21,-0.328
113.77,114.13,-0.328
113.78,114.05,-0.328
113.79,113.96,-0.328
113.79,113.88,-0.328
113.80,113.80,-0.328
113.81,113.71,-0.328
113.82,113.63,-0.328
113.83,113.55,-0.328
113.84,113.46,-0.328
113.84,113.38,-0.327
113.85,113.30,-0.327
113.86,113.21,-0.327
113.87,113.13,-0.327
113.88,113.05,-0.327
113.89,112.96,-0.327
113.89,112.88,-0.327
113.90,112.80,-0.327
113.91,112.71,-0.327
113.92,112.63,-0.327
113.93,112.55,-0.327
113.94,112.46,-0.327
113.94,112.38,-0.327
113.95,112.30,-0.327
113.96,112.21,-0.326
113.97,112.13,-0.326
113.98,112.05,-0.326
113.99,111.96,-0.326
113.99,111.88,-0.326
114.00,111.80,-0.326
114.01,111.71,-0.326
114.02,111.63,-0.326
114.03,111.55,-0.326
114.04,111.47,-0.326
114.04,111.38,-0.325
114.05,111.30,-0.325
114.06,111.21,-0.325
114.07,111.13,-0.325
114.08,111.05,-0.325
114.09,110.97,-0.325
114.09,110.88,-0.325
114.10,110.80,-0.325
114.11,110.71,-0.325
114.12,110.63,-0.325
114.13,110.55,-0.325
114.14,110.46,-0.325
114.14,110.38,-0.325
114.15,110.30,-0.325
114.16,110.21,-0.325
114.17,110.13,-0.324
114.18,110.05,-0.324
114.19,109.96,-0.324
114.19,109.88,-0.324
114.20,109.80,-0.324
114.21,109.72,-0.324
114.22,109.63,-0.324
114.23,109.55,-0.324
114.24,109.47,-0.324
114.24,109.38,-0.324
114.25,109.30,-0.324
114.26,109.22,-0.324
114.27,109.13,-0.324
114.28,109.05,-0.323
114.29,108.97,-0.323
114.29,108.88,-0.323
114.30,108.80,-0.323
114.31,108.72,-0.323
114.32,108.63,-0.323
114.33,108.55,-0.323
114.34,108.47,-0.323
114.34,108.38,-0.323
114.35,108.30,-0.323
114.36,108.22,-0.323
114.37,108.13,-0.323
114.38,108.05,-0.323
114.39,107.97,-0.322
114.39,107.88,-0.322
114.40,107.80,-0.322
114.41,107.72,-0.322
114.42,107.63,-0.322
114.43,107.55,-0.322
114.44,107.47,-0.322
114.44,107.38,-0.322
114.45,107.30,-0.322
114.46,107.22,-0.322
114.47,107.13,-0.322
114.48,107.05,-0.322
114.49,106.97,-0.322
114.49,106.88,-0.322
114.50,106.80,-0.321
114.51,106.72,-0.321
114.52,106.63,-0.321
114.53,106.55,-0.321
114.54,106.47,-0.321
114.54,106.38,-0.321
114.55,106.30,-0.321
114.56,106.22,-0.321
114.57,106.13,-0.321
114.58,106.05,-0.321
114.59,105.97,-0.321
114.59,105.89,-0.321
114.60,105.80,-0.321
114.61,105.72,-0.321
114.62,105.64,-0.320
114.63,105.55,-0.320
114.64,105.47,-0.320
114.64,105.39,-0.320
114.65,105.30,-0.320
114.66,105.22,-0.320
114.67,105.14,-0.320
114.68,105.05,-0.320
114.69,104.97,-0.319
114.69,104.89,-0.319
114.70,104.80,-0.319
114.71,104.72,-0.319
114.72,104.64,-0.319
114.73,104.55,-0.319
114.74,104.47,-0.319
114.74,104.39,-0.319
114.75,104.30,-0.319
114.76,104.22,-0.319
114.77,104.14,-0.319
114.78,104.05,-0.319
114.79,103.97,-0.319
114.79,103.89,-0.319
114.80,103.80,-0.318
114.81,103.72,-0.318
114.82,103.64,-0.318
114.83,103.55,-0.318
114.84,103.47,-0.318
114.84,103.39,-0.318
114.85,103.30,-0.318
114.86,103.22,-0.318
114.87,103.14,-0.318
114.88,103.05,-0.318
114.89,102.97,-0.318
114.89,102.89,-0.318
114.90,102.80,-0.318
114.91,102.72,-0.317
114.92,102.64,-0.317
114.93,102.56,-0.317
114.94,102.47,-0.317
114.94,102.39,-0.317
114.95,102.31,-0.317
114.96,102.22,-0.317
114.97,102.14,-0.317
114.98,102.05,-0.317
114.99,101.97,-0.317
114.99,101.89,-0.317
115.00,101.81,-0.317
115.01,101.72,-0.317
115.02,101.64,-0.317
115.03,101.56,-0.317
115.04,101.47,-0.317
115.04,101.39,-0.317
115.05,101.30,-0.316
115.06,101.22,-0.316
115.07,101.14,-0.316
115.08,101.06,-0.316
115.09,100.97,-0.316
115.09,100.89,-0.316
115.10,100.81,-0.316
115.11,100.72,-0.316
115.12,100.64,-0.316
115.13,100.56,-0.315
115.14,100.47,-0.315
115.14,100.39,-0.315
115.15,100.31,-0.315
115.16,100.22,-0.315
115.17,100.14,-0.315
115.18,100.06,-0.315
115.19,99.97,-0.315
115.19,99.89,-0.315
115.20,99.81,-0.315
115.21,99.72,-0.315
115.22,99.64,-0.315
115.23,99.56,-0.315
115.24,99.47,-0.315
115.24,99.39,-0.315
115.25,99.31,-0.315
115.26,99.22,-0.314
115.27,99.14,-0.314
115.28,99.06,-0.314
115.29,98.97,-0.314
115.29,98.89,-0.314
115.30,98.81,-0.314
115.31,98.73,-0.314
115.32,98.64,-0.314
115.33,98.56,-0.314
115.34,98.47,-0.313
115.34,98.39,-0.313
115.35,98.31,-0.313
115.36,98.22,-0.313
115.37,98.14,-0.313
115.38,98.06,-0.313
115.39,97.97,-0.313
115.39,97.89,-0.313
115.40,97.81,-0.313
115.41,97.73,-0.313
115.42,97.64,-0.313
115.43,97.56,-0.313
115.44,97.48,-0.313
115.44,97.39,-0.313
115.45,97.31,-0.313
115.46,97.23,-0.312
115.47,97.14,-0.312
115.48,97.06,-0.312
115.49,96.98,-0.312
115.49,96.89,-0.312
115.50,96.81,-0.312
115.51,96.73,-0.312
115.52,96.64,-0.312
115.53,96.56,-0.312
115.54,96.48,-0.312
115.54,96.39,-0.312
115.55,96.31,-0.312
115.56,96.23,-0.311
115.57,96.14,-0.311
115.58,96.06,-0.311
115.59,95.98,-0.311
115.59,95.89,-0.311
115.60,95.81,-0.311
115.61,95.73,-0.311
115.62,95.64,-0.311
115.63,95.56,-0.311
115.64,95.48,-0.311
115.64,95.39,-0.311
115.65,95.31,-0.310
115.66,95.23,-0.310
115.67,95.14,-0.310
115.68,95.06,-0.310
115.69,94.98,-0.310
115.69,94.89,-0.310
115.70,94.81,-0.310
115.71,94.73,-0.310
115.72,94.64,-0.310
115.73,94.56,-0.310
115.74,94.48,-0.310
115.74,94.39,-0.310
115.75,94.31,-0.310
115.76,94.23,-0.310
115.77,94.14,-0.310
115.78,94.06,-0.310
115.79,93.98,-0.310
115.79,93.90,-0.310
115.80,93.81,-0.310
115.81,93.73,-0.309
115.82,93.65,-0.309
115.83,93.56,-0.309
115.84,93.48,-0.309
115.84,93.40,-0.309
115.85,93.31,-0.309
115.86,93.23,-0.309
115.87,93.15,-0.309
115.88,93.06,-0.309
115.89,92.98,-0.309
115.89,92.90,-0.308
115.90,92.81,-0.308
115.91,92.73,-0.308
115.92,92.65,-0.308
115.93,92.56,-0.308
115.94,92.48,-0.308
115.94,92.40,-0.308
115.95,92.31,-0.308
115.96,92.23,-0.308
115.97,92.15,-0.308
115.98,92.06,-0.308
115.99,91.98,-0.308
115.99,91.90,-0.307
116.00,91.81,-0.307
116.01,91.73,-0.307
116.02,91.65,-0.307
116.03,91.56,-0.307
116.04,91.48,-0.307
116.04,91.40,-0.307
116.05,91.31,-0.307
116.06,91.23,-0.307
116.07,91.15,-0.307
116.08,91.06,-0.307
116.09,90.98,-0.307
116.09,90.90,-0.307
116.10,90.81,-0.307
116.11,90.73,-0.307
116.12,90.65,-0.307
116.13,90.56,-0.307
116.14,90.48,-0.306
116.14,90.40,-0.306
116.15,90.31,-3.598
116.16,91.51,-28.750
116.17,96.93,-48.812
116.18,99.85,-32.042
116.19,100.94,-22.106
116.19,101.27,-16.477
116.20,101.16,-12.700
116.21,100.77,-9.767
116.22,100.18,-7.485
116.23,99.50,-5.965
116.24,98.79,-5.105
116.24,98.11,-4.539
116.25,97.45,-4.123
116.26,96.82,-3.795
116.27,96.23,-3.524
116.28,95.67,-3.290
116.29,95.14,-3.082
116.29,94.64,-2.896
116.30,94.17,-2.725
116.31,93.72,-2.567
116.32,93.30,-2.420
116.33,92.91,-2.282
116.34,92.53,-2.152
116.34,92.17,-2.030
116.35,91.84,-1.915
116.36,91.52,-1.807
116.37,91.21,-1.705
116.38,90.92,-1.609
116.39,90.64,-1.520
116.39,90.38,-1.435
116.40,90.13,-1.356
116.41,89.89,-1.282
116.42,89.66,-1.214
116.43,89.44,-1.150
116.44,89.22,-1.090
116.44,89.02,-1.033
116.45,88.83,-0.981
116.46,88.64,-0.932
116.47,88.46,-0.886
116.48,88.28,-0.843
116.49,88.12,-0.803
116.49,87.95,-0.765
116.50,87.80,-0.729
116.51,87.64,-0.697
116.52,87.50,-0.667
116.53,87.35,-0.637
116.54,87.21,-0.612
116.54,87.08,-0.585
116.55,86.95,-0.562
116.56,86.82,-0.540
116.57,86.69,-0.520
116.58,86.57,-0.501
116.59,86.45,-0.482
116.59,86.33,-0.466
116.60,86.21,-0.450
116.61,86.10,-0.436
116.62,85.99,-0.422
116.63,85.88,-0.409
116.64,85.77,-0.398
116.64,85.66,-0.386
116.65,85.56,-0.375
116.66,85.46,-0.366
116.67,85.35,-0.357
116.68,85.25,-0.348
116.69,85.15,-0.342
116.69,85.06,-0.333
116.70,84.96,-0.326
116.71,84.86,-0.320
116.72,84.76,-0.313
116.73,84.67,-0.308
116.74,84.58,-0.303
116.74,84.48,-0.298
116.75,84.39,-0.292
116.76,84.30,-0.289
116.77,84.21,-0.285
116.78,84.12,-0.281
116.79,84.02,-0.277
116.79,83.94,-0.273
116.80,83.84,-0.270
116.81,83.76,-0.267
116.82,83.67,-0.265
116.83,83.58,-0.263
116.84,83.49,-0.260
116.84,83.40,-0.258
116.85,83.32,-0.257
116.86,83.23,-0.254
116.87,83.14,-0.252
116.88,83.06,-0.250
116.89,82.97,-0.249
116.89,82.88,-0.247
116.90,82.80,-0.246
116.91,82.71,-0.245
116.92,82.63,-0.243
116.93,82.54,-0.243
116.94,82.45,-0.241
116.94,82.37,-0.240
116.95,82.28,-0.240
116.96,82.20,-0.239
116.97,82.11,-0.238
116.98,82.03,-0.237
116.99,81.94,-0.236
116.99,81.86,-0.236
117.00,81.78,-0.236
117.01,81.69,-0.235
117.02,81.61,-0.234
117.03,81.52,-0.234
117.04,81.44,-0.233
117.04,81.36,-0.233
117.05,81.27,-0.232
117.06,81.19,-0.232
117.07,81.10,-0.231
117.08,81.02,-0.231
117.09,80.93,-0.231
117.09,80.85,-0.231
117.10,80.77,-0.230
117.11,80.68,-0.230
117.12,80.60,-0.230
117.13,80.52,-0.230
117.14,80.43,-0.229
117.14,80.35,-0.229
117.15,80.27,-0.229
117.16,80.18,-0.229
117.17,80.10,-0.229
117.18,80.01,-0.229
117.19,79.93,-0.228
117.19,79.85,-0.228
117.20,79.76,-0.228
117.21,79.68,-0.228
117.22,79.60,-0.228
117.23,79.51,-0.228
117.24,79.43,-0.228
117.24,79.35,-0.228
117.25,79.26,-0.227
117.26,79.18,-0.227
117.27,79.10,-0.227
117.28,79.01,-0.227
117.29,78.93,-0.227
117.29,78.85,-0.227
117.30,78.76,-0.227
117.31,78.68,-0.227
117.32,78.59,-0.226
117.33,78.51,-0.226
117.34,78.43,-0.226
117.34,78.34,-0.226
117.35,78.26,-0.226
117.36,78.18,-0.226
117.37,78.09,-0.226
117.38,78.01,-0.226
117.39,77.93,-0.226
117.39,77.85,-0.226
117.40,77.76,-0.226
117.41,77.68,-0.226
117.42,77.60,-0.225
117.43,77.51,-0.225
117.44,77.43,-0.225
117.44,77.34,-0.225
117.45,77.26,-0.225
117.46,77.18,-0.225
117.47,77.10,-0.225
117.48,77.01,-0.225
117.49,76.93,-0.225
117.49,76.85,-0.225
117.50,76.76,-0.225
117.51,76.68,-0.225
117.52,76.60,-0.225
117.53,76.51,-0.224
117.54,76.43,-0.224
117.54,76.35,-0.224
117.55,76.26,-0.224
117.56,76.18,-0.224
117.57,76.10,-0.224
117.58,76.01,-0.224
117.59,75.93,-0.224
117.59,75.85,-0.224
117.60,75.76,-0.224
117.61,75.68,-0.224
117.62,75.60,-0.224
117.63,75.51,-0.223
117.64,75.43,-0.223
117.64,75.35,-0.223
117.65,75.26,-0.223
117.66,75.18,-0.223
117.67,75.10,-0.223
117.68,75.02,-0.223
117.69,74.93,-0.223
117.69,74.85,-0.223
117.70,74.76,-0.223
117.71,74.68,-0.223
117.72,74.60,-0.223
117.73,74.52,-0.223
117.74,74.43,-0.222
117.74,74.35,-0.222
117.75,74.27,-0.222
117.76,74.18,-0.222
117.77,74.10,-0.222
117.78,74.02,-0.222
117.79,73.93,-0.222
117.79,73.85,-0.222
117.80,73.77,-0.222
117.81,73.68,-0.222
117.82,73.60,-0.222
117.83,73.52,-0.222
117.84,73.43,-0.222
117.84,73.35,-0.222
117.85,73.27,-0.221
117.86,73.18,-0.221
117.87,73.10,-0.221
117.88,73.02,-0.221
117.89,72.93,-0.221
117.89,72.85,-0.221
117.90,72.77,-0.221
117.91,72.68,-0.221
117.92,72.60,-0.221
117.93,72.52,-0.221
117.94,72.43,-0.221
117.94,72.35,-0.221
117.95,72.27,-0.221
117.96,72.18,-0.221
117.97,72.10,-0.221
117.98,72.02,-0.220
117.99,71.93,-0.220
117.99,71.85,-0.220
118.00,71.77,-0.220
118.01,71.68,-0.220
118.02,71.60,-0.220
118.03,71.52,-0.220
118.04,71.43,-0.220
118.04,71.35,-0.220
118.05,71.27,-0.220
118.06,71.18,-0.220
118.07,71.10,-0.220
118.08,71.02,-0.220
118.09,70.93,-0.220
118.09,70.85,-0.220
118.10,70.77,-0.220
118.11,70.68,-0.220
118.12,70.60,-0.220
118.13,70.52,-0.220
118.14,70.43,-0.219
118.14,70.35,-0.219
118.15,70.27,-0.219
118.16,70.18,-0.219
118.17,70.10,-0.219
118.18,70.02,-0.219
118.19,69.93,-0.219
118.19,69.85,-0.219
118.20,69.77,-0.219
118.21,69.68,-0.219
118.22,69.60,-0.219
118.23,69.52,-0.219
118.24,69.43,-0.219
118.24,69.35,-0.219
118.25,69.27,-0.219
118.26,69.18,-0.219
118.27,69.10,-0.219
118.28,69.02,-0.218
118.29,68.93,-0.218
118.29,68.85,-0.218
118.30,68.77,-0.218
118.31,68.68,-0.218
118.32,68.60,-0.218
118.33,68.52,-0.218
118.34,68.43,-0.218
118.34,68.35,-0.218
118.35,68.27,-0.218
118.36,68.18,-0.218
118.37,68.10,-0.218
118.38,68.02,-0.218
118.39,67.93,-0.218
118.39,67.85,-0.217
118.40,67.77,-0.217
118.41,67.69,-0.217
118.42,67.60,-0.217
118.43,67.52,-0.217
118.44,67.44,-0.217
118.44,67.35,-0.217
118.45,67.27,-0.217
118.46,67.19,-0.217
118.47,67.10,-0.217
118.48,67.02,-0.217
118.49,66.94,-0.217
118.49,66.85,-0.217
118.50,66.77,-0.217
118.51,66.69,-0.216
118.52,66.60,-0.216
118.53,66.52,-0.216
118.54,66.43,-0.216
118.54,66.35,-0.216
118.55,66.27,-0.216
118.56,66.19,-0.216
118.57,66.10,-0.216
118.58,66.02,-0.216
118.59,65.94,-0.216
118.59,65.85,-0.216
118.60,65.77,-0.216
118.61,65.69,-0.216
118.62,65.60,-0.216
118.63,65.52,-0.216
118.64,65.44,-0.216
118.64,65.35,-0.215
118.65,65.27,-0.215
118.66,65.19,-0.215
118.67,65.10,-0.215
118.68,65.02,-0.215
118.69,64.94,-0.215
118.69,64.85,-0.215
118.70,64.77,-0.215
118.71,64.69,-0.215
118.72,64.60,-0.215
118.73,64.52,-0.215
118.74,64.44,-0.215
118.74,64.35,-0.215
118.75,64.27,-0.214
118.76,64.19,-0.214
118.77,64.10,-0.214
118.78,64.02,-0.214
118.79,63.94,-0.214
118.79,63.85,-0.214
118.80,63.77,-0.214
118.81,63.69,-0.214
118.82,63.60,-0.214
118.83,63.52,-0.214
118.84,63.44,-0.214
118.84,63.35,-0.214
118.85,63.27,-0.214
118.86,63.19,-0.214
118.87,63.10,-0.214
118.88,63.02,-0.213
118.89,62.94,-0.213
118.89,62.86,-0.213
118.90,62.77,-0.213
118.91,62.69,-0.213
118.92,62.61,-0.213
118.93,62.52,-0.213
118.94,62.44,-0.213
118.94,62.36,-0.213
118.95,62.27,-0.213
118.96,62.19,-0.213
118.97,62.11,-0.213
118.98,62.02,-0.213
118.99,61.94,-0.213
118.99,61.86,-0.212
119.00,61.77,-0.212
119.01,61.69,-0.212
119.02,61.61,-0.212
119.03,61.52,-0.212
119.04,61.44,-0.212
119.04,61.36,-0.212
119.05,61.27,-0.212
119.06,61.19,-0.212
119.07,61.11,-0.212
119.08,61.02,-0.212
119.09,60.94,-0.212
119.09,60.86,-0.212
119.10,60.77,-0.212
119.11,60.69,-0.212
119.12,60.61,-0.212
119.13,60.52,-0.212
119.14,60.44,-0.212
119.14,60.36,-0.212
119.15,60.27,-0.212
119.16,60.19,-0.212
119.17,60.11,-0.212
119.18,60.02,-0.212
119.19,59.94,-0.212
119.19,59.86,-0.211
119.20,59.77,-0.211
119.21,59.69,-0.211
119.22,59.61,-0.211
119.23,59.52,-0.211
119.24,59.44,-0.211
119.24,59.36,-0.211
119.25,59.27,-0.211
119.26,59.19,-0.211
119.27,59.11,-0.211
119.28,59.02,-0.211
119.29,58.94,-0.211
119.29,58.86,-0.210
119.30,58.78,-0.210
119.31,58.69,-0.210
119.32,58.61,-0.210
119.33,58.52,-0.210
119.34,58.44,-0.210
119.34,58.36,-0.210
119.35,58.27,-0.210
119.36,58.19,-0.210
119.37,58.11,-0.210
119.38,58.02,-0.210
119.39,57.94,-0.209
119.39,57.86,-0.209
119.40,57.77,-0.209
119.41,57.69,-0.209
119.42,57.61,-0.209
119.43,57.52,-0.209
119.44,57.44,-0.209
119.44,57.36,-0.209
119.45,57.28,-0.209
119.46,57.19,-0.209
119.47,57.11,-0.209
119.48,57.03,-0.209
119.49,56.94,-0.209
119.49,56.86,-0.209
119.50,56.78,-0.208
119.51,56.69,-0.208
119.52,56.61,-0.208
119.53,56.53,-0.208
119.54,56.44,-0.208
119.54,56.36,-0.208
119.55,56.28,-0.208
119.56,56.19,-0.208
119.57,56.11,-0.208
119.58,56.02,-0.208
119.59,55.94,-0.208
119.59,55.86,-0.208
119.60,55.78,-0.208
119.61,55.69,-0.208
119.62,55.61,-0.207
119.63,55.53,-0.207
119.64,55.44,-0.207
119.64,55.36,-0.207
119.65,55.28,-0.207
119.66,55.19,-0.207
119.67,55.11,-0.207
119.68,55.03,-0.207
119.69,54.94,-0.207
119.69,54.86,-0.207
119.70,54.78,-0.207
119.71,54.69,-0.207
119.72,54.61,-0.207
119.73,54.53,-0.207
119.74,54.44,-0.207
119.74,54.36,-0.206
119.75,54.28,-0.206
119.76,54.19,-0.206
119.77,54.11,-0.206
119.78,54.03,-0.206
119.79,53.94,-0.206
119.79,53.86,-0.206
119.80,53.78,-0.206
119.81,53.69,-0.206
119.82,53.61,-0.206
119.83,53.53,-0.206
119.84,53.44,-0.206
119.84,53.36,-0.206
119.85,53.28,-0.206
119.86,53.20,-0.205
119.87,53.11,-0.205
119.88,53.03,-0.205
119.89,52.94,-0.205
119.89,52.86,-0.205
119.90,52.78,-0.205
119.91,52.69,-0.205
119.92,52.61,-0.205
119.93,52.53,-0.205
119.94,52.45,-0.205
119.94,52.36,-0.205
119.95,52.28,-0.205
119.96,52.19,-0.205
119.97,52.11,-0.205
119.98,52.03,-0.205
119.99,51.95,-0.205
119.99,51.86,-0.205
120.00,51.78,-0.204
120.01,51.70,-0.204
120.02,51.61,-0.204
120.03,51.53,-0.204
120.04,51.45,-0.204
120.04,51.36,-0.204
120.05,51.28,-0.204
120.06,51.20,-0.204
120.07,51.11,-0.204
120.08,51.03,-0.204
120.09,50.95,-0.204
120.09,50.86,-0.204
120.10,50.78,-0.204
120.11,50.70,-0.204
120.12,50.61,-0.204
120.13,50.53,-0.203
120.14,50.45,-0.203
120.14,50.36,-0.203
120.15,50.28,-0.203
120.16,50.20,-0.203
120.17,50.12,-0.203
120.18,50.03,-0.203
120.19,49.95,-0.203
120.19,49.87,-0.203
120.20,49.78,-0.203
120.21,49.70,-0.203
120.22,49.62,-0.202
120.23,49.53,-0.202
120.24,49.45,-0.202
120.24,49.36,-0.202
120.25,49.28,-0.202
120.26,49.20,-0.202
120.27,49.12,-0.202
120.28,49.03,-0.202
120.29,48.95,-0.202
120.29,48.86,-0.202
120.30,48.78,-0.202
120.31,48.70,-0.202
120.32,48.62,-0.202
120.33,48.53,-0.202
120.34,48.45,-0.202
120.34,48.36,-0.202
120.35,48.28,-0.201
120.36,48.20,-0.201
120.37,48.12,-0.201
120.38,48.03,-0.201
120.39,47.95,-0.201
120.39,47.87,-0.201
120.40,47.78,-0.201
120.41,47.70,-0.201
120.42,47.62,-0.201
120.43,47.53,-0.201
120.44,47.45,-0.201
120.44,47.37,-0.201
120.45,47.28,-0.200
120.46,47.20,-0.200
120.47,47.12,-0.200
120.48,47.03,-0.200
120.49,46.95,-0.200
120.49,46.87,-0.200
120.50,46.78,-0.200
120.51,46.70,-0.200
120.52,46.62,-0.200
120.53,46.53,-0.200
120.54,46.45,-0.200
120.54,46.37,-0.200
120.55,46.28,-0.200
120.56,46.20,-0.200
120.57,46.12,-0.199
120.58,46.03,-0.199
120.59,45.95,-0.199
120.59,45.87,-0.199
120.60,45.78,-0.199
120.61,45.70,-0.199
120.62,45.62,-0.199
120.63,45.53,-0.199
120.64,45.45,-0.199
120.64,45.37,-0.199
120.65,45.28,-0.199
120.66,45.20,-0.199
120.67,45.12,-0.199
120.68,45.04,-0.199
120.69,44.95,-0.198
120.69,44.87,-0.198
120.70,44.79,-0.198
120.71,44.70,-0.199
120.72,44.62,-0.199
120.73,44.53,-0.198
120.74,44.45,-0.198
120.74,44.37,-0.198
120.75,44.29,-0.198
120.76,44.20,-0.198
120.77,44.12,-0.198
120.78,44.04,-0.198
120.79,43.95,-0.198
120.79,43.87,-0.198
120.80,43.78,-0.198
120.81,43.70,-0.198
120.82,43.62,-0.198
120.83,43.54,-0.198
120.84,43.45,-0.197
120.84,43.37,-0.197
120.85,43.29,-0.197
120.86,43.20,-0.197
120.87,43.12,-0.197
120.88,43.04,-0.197
120.89,42.95,-0.197
120.89,42.87,-0.197
120.90,42.79,-0.197
120.91,42.70,-0.197
120.92,42.62,-0.197
120.93,42.54,-0.197
120.94,42.45,-0.196
120.94,42.37,-0.196
120.95,42.29,-0.196
120.96,42.20,-0.196
120.97,42.12,-0.196
120.98,42.04,-0.196
120.99,41.95,-0.196
120.99,41.87,-0.196
121.00,41.79,-0.195
121.01,41.70,-0.195
121.02,41.62,-0.195
121.03,41.54,-0.195
121.04,41.45,-0.195
121.04,41.37,-0.195
121.05,41.29,-0.195
121.06,41.20,-0.195
121.07,41.12,-0.195
121.08,41.04,-0.195
121.09,40.95,-0.195
121.09,40.87,-0.195
121.10,40.79,-0.195
121.11,40.70,-0.195
121.12,40.62,-0.195
121.13,40.54,-0.203
121.14,40.46,-0.202
121.14,40.37,-0.200
121.15,40.29,-0.200
121.16,40.21,-0.199
121.17,40.12,-0.197
121.18,40.04,-0.196
121.19,39.96,-0.196
121.19,39.87,-0.195
121.20,39.79,-0.195
121.21,39.71,-0.195
121.22,39.62,-0.195
121.23,39.54,-0.195
121.24,39.45,-0.195
121.24,39.37,-0.195
121.25,39.29,-0.195
121.26,39.20,-0.195
121.27,39.12,-0.194
121.28,39.04,-0.194
121.29,38.96,-0.194
121.29,38.87,-0.194
121.30,38.79,-0.194
121.31,38.71,-0.194
121.32,38.62,-0.194
121.33,38.54,-0.194
121.34,38.46,-0.194
121.34,38.37,-0.194
121.35,38.29,-0.194
121.36,38.21,-0.193
121.37,38.12,-0.193
121.38,38.04,-0.193
121.39,37.96,-0.193
121.39,37.87,-0.193
121.40,37.79,-0.193
121.41,37.71,-0.193
121.42,37.62,-0.193
121.43,37.54,-0.193
121.44,37.45,-0.192
121.44,37.37,-0.192
121.45,37.29,-0.192
121.46,37.21,-0.192
121.47,37.12,-0.192
121.48,37.04,-0.192
121.49,36.96,-0.192
121.49,36.87,-0.192
121.50,36.79,-0.192
121.51,36.71,-0.192
121.52,36.62,-0.192
121.53,36.54,-0.192
121.54,36.46,-0.192
121.54,36.37,-0.192
121.55,36.29,-0.191
121.56,36.21,-0.191
121.57,36.12,-0.191
121.58,36.04,-0.191
121.59,35.96,-0.191
121.59,35.87,-0.191
121.60,35.79,-0.191
121.61,35.71,-0.191
121.62,35.63,-0.191
121.63,35.54,-0.191
121.64,35.46,-0.190
121.64,35.37,-0.190
121.65,35.29,-0.190
121.66,35.21,-0.190
121.67,35.12,-0.190
121.68,35.04,-0.190
121.69,34.96,-0.190
121.69,34.88,-0.190
121.70,34.79,-0.190
121.71,34.71,-0.190
121.72,34.63,-0.190
121.73,34.54,-0.190
121.74,34.46,-0.190
121.74,34.38,-0.190
121.75,34.29,-0.189
121.76,34.21,-0.189
121.77,34.13,-0.189
121.78,34.04,-0.189
121.79,33.96,-0.189
121.79,33.88,-0.189
121.80,33.79,-0.189
121.81,33.71,-0.189
121.82,33.63,-0.189
121.83,33.55,-0.189
121.84,33.46,-0.189
121.84,33.38,-0.189
121.85,33.29,-0.189
121.86,33.21,-0.189
121.87,33.13,-0.188
121.88,33.04,-0.188
121.89,32.96,-0.188
121.89,32.88,-0.188
121.90,32.79,-0.188
121.91,32.71,-0.188
121.92,32.63,-0.188
121.93,32.54,-0.188
121.94,32.46,
121.94,32.38,
121.95,32.29,
121.96,32.21,
121.97,32.13,
121.98,32.04,
121.99,,
121.99,,