File: DSC/2025_04_23_CBN_Caffeine_MC_n60C_150C_5Cmin_x3.csv
Filename,2025_04_23_CBN_Caffeine_MC_n60C_150C_5Cmin_x3
Instrument name,DSC2A-00468 (192.168.1.100)
Operator,Yarger
rundate,4/23/2025
Sample name,2025_04_23_CBN_Caffeine_MC_n60C_150C_5Cmin_x3
proceduresegments,Data Off ; Equilibrate -60.00 °C; Data On ; Ramp 5.00 °C/min to 150.00 °C; Data Off ; Isothermal 1.0 min; Data On ; Ramp 5.00 °C/min to -60.00 °C; Data Off ; Isothermal 1.0 min; Data On ; Ramp 5.00 °C/min to 150.00 °C; Data Off ; Isothermal 1.0 min; Data On ; Ramp 5.00 °C/min to -60.00 °C; Data Off ; Isothermal 1.0 min; Data On ; Ramp 5.00 °C/min to 150.00 °C
[File Parameters]
Run date,4/23/2025 7:29:34 PM
Trios version,5.1.1.46572
Original File Name,
Current File Name,D:\DSC2500\JYarger\2025_04_23_CBN_Caffeine_MC_n60C_150C_5Cmin_x3.tri
[Procedure]
Procedure Name,CBN_Caff_n60_150C_5Cmin_x3
Sample Name,2025_04_23_CBN_Caffeine_MC_n60C_150C_5Cmin_x3
Sample Mass,5.24 mg
Reference Sample Mass,0 mg
Pan Mass,52.33 mg
Pan Number,30
Reference Pan Mass,52.66 mg
Reference Pan Number,19
Pan Type,Tzero Aluminum Hermetic
Comments,Al Hermetic DSC Consumables sealed Pan/Lid.
Project Name,CA
Operator,Yarger
Test,Custom
Unload Max Temperature,30
Unload Min Temperature,30
Load Max Temperature,30
Load Min Temperature,30
Stop on Gas Flow Error,Yes
[Signal List]
Signal #1,Time (min)
Signal #2,Temperature (°C)
Signal #3,Heat Flow (mW)
Signal #4,Delta T (µV)
Signal #5,Delta Tzero (µV)
Signal #6,Tzero Temperature (°C)
Signal #7,Cell Purge (mL/min)
Signal #8,Heater Temp (°C)
Signal #9,Power Delivered (W)
Signal #10,Reference Junction Temperature (°C)
Signal #11,Flange Temperature (°C)
Signal #12,Heat Flow Phase (rad)
Signal #13,Total Heat Capacity (J/°C)
Signal #14,Heat Capacity (J/°C)
[Configuration]
Company Name,ASU
Instrument Name,DSC2A-00468
Instrument Type,DSC2500
Serial Number,DSC2A-00468
IP,192.168.1.100
Location of Instrument,MRRC
DisplayType,Unknown
Sample Interval ,0.1 s/pt
Selected Heat Flow,T4P
Exotherm Direction,Down
Cell Serial,DRC2-00792
Lid Type,Standard
Cooler,RCS 90
Leave Cooler on at End of Sequence,On
Gas 2,Nitrogen
Gas Selected,Channel 1
Flow Rate,50 mL/min
Secondary Purge,On
Licensed Heat Flow,Heat Flow T4P
Modulation Licensed,Yes
[Versions]
Common IDD Version,1
Cortex Version,VER 2.10.2.31
Driver,5.0.0.6
GDM Version,1.0.3.3
TouchscreenVersion,1.0.0.16145
FEP Version,1.2.1.21
FEP Bootloader,2.0.0.5
AutoSampler Version,2.1.1.26
Auto Sampler Bootloader,2.0.0.5
FCM Version,1.1.0.3
FCM Bootloader,2.0.0.5
[Experiment Logs]
Experiment Log Entry # 1,Air Cool is off.
Experiment Log Entry # 3,Data On set to 0
Experiment Log Entry # 5,Equilibrate Segment -60 (C) Started
Experiment Log Entry # 7,Data On set to 1
Experiment Log Entry # 9,Ramp Segment 5 C/min to 150 Started
Experiment Log Entry # 11,Data On set to 0
Experiment Log Entry # 13,Isothermal Segment 1 min started
Experiment Log Entry # 15,Data On set to 1
Experiment Log Entry # 17,Ramp Segment 5 C/min to -60 Started
Experiment Log Entry # 19,Data On set to 0
Experiment Log Entry # 21,Isothermal Segment 1 min started
Experiment Log Entry # 23,Data On set to 1
Experiment Log Entry # 25,Ramp Segment 5 C/min to 150 Started
Experiment Log Entry # 27,Data On set to 0
Experiment Log Entry # 29,Isothermal Segment 1 min started
Experiment Log Entry # 31,Data On set to 1
Experiment Log Entry # 33,Ramp Segment 5 C/min to -60 Started
Experiment Log Entry # 35,Data On set to 0
Experiment Log Entry # 37,Isothermal Segment 1 min started
Experiment Log Entry # 39,Data On set to 1
Experiment Log Entry # 41,Ramp Segment 5 C/min to 150 Started
[Method Log]
Method Log Entry # 1,Data Off
Method Log Entry # 2,Equilibrate -60 °C
Method Log Entry # 3,Data On
Method Log Entry # 4,(Ramp 79113) Ramp 5 °C/minute to 150 °C
Method Log Entry # 5,Data Off
Method Log Entry # 6,Isothermal 1 minutes
Method Log Entry # 7,Data On
Method Log Entry # 8,(Ramp 79117) Ramp 5 °C/minute to -60 °C
Method Log Entry # 9,Data Off
Method Log Entry # 10,Isothermal 1 minutes
Method Log Entry # 11,Data On
Method Log Entry # 12,(Ramp 79121) Ramp 5 °C/minute to 150 °C
Method Log Entry # 13,Data Off
Method Log Entry # 14,Isothermal 1 minutes
Method Log Entry # 15,Data On
Method Log Entry # 16,(Ramp 79125) Ramp 5 °C/minute to -60 °C
Method Log Entry # 17,Data Off
Method Log Entry # 18,Isothermal 1 minutes
Method Log Entry # 19,Data On
Method Log Entry # 20,(Ramp 79129) Ramp 5 °C/minute to 150 °C
Cell Serial,DRC2-00792
[T1 Calibration]
Slope,-0.008529666
Offset,9.636258
Initial Temperature,98.23
GUID,f8bfdadc-4977-4fdf-ba6d-0ba9134940c3
[TZero Calibration]
Date Applied,11/29/2022 4:06:13 PM
Description,From -89.059 °C to 396.009 °C at 20.000°C/min
Gas Type,Nitrogen
Pan Type,None
Source Files 1,C:\Users\yargerlab\Desktop\DSC Data\General\TZero_calibration_11_29_22_2nd(2).tri
Source Files 2,C:\Users\yargerlab\Desktop\DSC Data\General\TZero_calibration_11_29_22_2nd(3).tri
Delta T Offset,13.05235
Delta T Slope,-0.007271007
Delta T0 Offset,-13.69128
Delta T0 Slope,0.06063341
[Temperature Calibration]
Date Applied,11/29/2022 7:12:28 PM
Description,From 106.590 °C to 186.590 °C at 10.000°C/min
Gas Type,Nitrogen
Pan Type,Tzero Aluminum Hermetic
Source Files 1,C:\Users\yargerlab\Desktop\DSC Data\General\Indium(6).tri
Measured 1,157.391
Known 1,156.598
[Cell Constant Calibration]
Date Applied,11/29/2022 7:12:29 PM
Description,From 106.590 °C to 186.590 °C at 10.000°C/min
Gas Type,Nitrogen
Pan Type,Tzero Aluminum Hermetic
Source Files 1,C:\Users\yargerlab\Desktop\DSC Data\General\Indium(6).tri
T4P KCell,1.006051
Onset Slope,63.26126 mW/°C
[Direct Cp Calibration]
Date Applied,11/30/2022 11:04:51 AM
Description,From -79.983 °C to 298.409 °C at 10.000°C/min
Gas Type,Nitrogen
Pan Type,Tzero Aluminum Hermetic
Source Files 1,C:\Users\yargerlab\Desktop\DSC Data\General\Sapphire_Heat_Capacity_11_30_22.tri
[Rev Cp Calibration]
Date Applied,11/30/2022 1:58:51 PM
Description,From -79.996 °C to 292.812 °C at 3.000°C/min
Gas Type,Nitrogen
Pan Type,Tzero Aluminum Hermetic
Source Files 1,C:\Users\yargerlab\Desktop\DSC Data\General\Sapphire_MDSC_Calibration_11_30_22.tri
[step]
Ramp 5.00 °C/min to 150.00 °C
Time,Temperature,Heat Flow (Normalized)
min,°C,W/g
0.00,-59.68,-0.064
0.03,-59.70,-0.064
0.06,-59.70,-0.056
0.08,-59.68,-0.058
0.11,-59.63,-0.059
0.14,-59.55,-0.054
0.17,-59.46,-0.031
0.20,-59.35,-0.009
0.23,-59.24,0.011
0.26,-59.13,0.025
0.28,-59.01,0.037
0.31,-58.88,0.045
0.34,-58.76,0.053
0.37,-58.63,0.060
0.40,-58.50,0.063
0.43,-58.36,0.069
0.45,-58.23,0.071
0.48,-58.10,0.074
0.51,-57.96,0.076
0.54,-57.83,0.077
0.57,-57.69,0.078
0.60,-57.55,0.079
0.62,-57.42,0.079
0.65,-57.28,0.080
0.68,-57.14,0.081
0.71,-57.00,0.081
0.74,-56.87,0.082
0.77,-56.73,0.082
0.79,-56.59,0.083
0.82,-56.45,0.083
0.85,-56.31,0.083
0.88,-56.17,0.084
0.91,-56.03,0.084
0.93,-55.89,0.085
0.96,-55.75,0.085
0.99,-55.61,0.085
1.02,-55.47,0.086
1.05,-55.33,0.086
1.08,-55.19,0.086
1.11,-55.05,0.086
1.13,-54.91,0.086
1.16,-54.77,0.087
1.19,-54.63,0.087
1.22,-54.49,0.087
1.25,-54.35,0.087
1.28,-54.21,0.087
1.30,-54.07,0.087
1.33,-53.92,0.088
1.36,-53.78,0.088
1.39,-53.64,0.088
1.42,-53.50,0.088
1.44,-53.36,0.088
1.47,-53.22,0.088
1.50,-53.08,0.088
1.53,-52.94,0.088
1.56,-52.80,0.088
1.59,-52.66,0.088
1.62,-52.52,0.088
1.64,-52.38,0.088
1.67,-52.23,0.088
1.70,-52.09,0.088
1.73,-51.95,0.088
1.76,-51.81,0.088
1.78,-51.67,0.088
1.81,-51.53,0.088
1.84,-51.39,0.088
1.87,-51.24,0.088
1.90,-51.10,0.088
1.93,-50.96,0.088
1.96,-50.82,0.088
1.98,-50.68,0.088
2.01,-50.54,0.088
2.04,-50.39,0.088
2.07,-50.25,0.088
2.10,-50.11,0.088
2.13,-49.97,0.088
2.15,-49.83,0.088
2.18,-49.69,0.088
2.21,-49.55,0.088
2.24,-49.41,0.088
2.27,-49.26,0.088
2.29,-49.12,0.088
2.32,-48.98,0.088
2.35,-48.84,0.088
2.38,-48.70,0.088
2.41,-48.56,0.088
2.44,-48.42,0.088
2.46,-48.27,0.088
2.49,-48.13,0.088
2.52,-47.99,0.088
2.55,-47.85,0.088
2.58,-47.71,0.088
2.61,-47.57,0.088
2.64,-47.43,0.088
2.66,-47.29,0.088
2.69,-47.14,0.088
2.72,-47.00,0.088
2.75,-46.86,0.088
2.78,-46.72,0.088
2.81,-46.58,0.088
2.83,-46.44,0.088
2.86,-46.29,0.088
2.89,-46.15,0.088
2.92,-46.01,0.088
2.95,-45.87,0.088
2.98,-45.73,0.088
3.00,-45.59,0.088
3.03,-45.44,0.088
3.06,-45.30,0.088
3.09,-45.16,0.088
3.12,-45.02,0.088
3.14,-44.88,0.088
3.17,-44.74,0.088
3.20,-44.60,0.088
3.23,-44.45,0.088
3.26,-44.31,0.088
3.29,-44.17,0.088
3.31,-44.03,0.088
3.34,-43.89,0.088
3.37,-43.75,0.088
3.40,-43.61,0.088
3.43,-43.46,0.088
3.46,-43.32,0.088
3.49,-43.18,0.088
3.51,-43.04,0.088
3.54,-42.90,0.088
3.57,-42.75,0.088
3.60,-42.61,0.088
3.63,-42.47,0.088
3.66,-42.33,0.088
3.68,-42.19,0.088
3.71,-42.04,0.088
3.74,-41.90,0.088
3.77,-41.76,0.088
3.80,-41.62,0.088
3.83,-41.48,0.088
3.85,-41.34,0.088
3.88,-41.19,0.088
3.91,-41.05,0.088
3.94,-40.91,0.088
3.97,-40.77,0.088
3.99,-40.63,0.088
4.02,-40.49,0.088
4.05,-40.34,0.088
4.08,-40.20,0.088
4.11,-40.06,0.088
4.14,-39.92,0.088
4.16,-39.78,0.088
4.19,-39.64,0.088
4.22,-39.49,0.088
4.25,-39.35,0.088
4.28,-39.21,0.088
4.31,-39.07,0.088
4.34,-38.93,0.088
4.36,-38.78,0.088
4.39,-38.64,0.088
4.42,-38.50,0.088
4.45,-38.36,0.088
4.48,-38.22,0.088
4.50,-38.07,0.088
4.53,-37.93,0.088
4.56,-37.79,0.088
4.59,-37.65,0.088
4.62,-37.51,0.088
4.65,-37.36,0.088
4.68,-37.22,0.088
4.70,-37.08,0.088
4.73,-36.94,0.088
4.76,-36.80,0.088
4.79,-36.65,0.088
4.82,-36.51,0.088
4.85,-36.37,0.088
4.87,-36.23,0.088
4.90,-36.09,0.088
4.93,-35.95,0.088
4.96,-35.80,0.088
4.99,-35.66,0.088
5.01,-35.52,0.088
5.04,-35.38,0.088
5.07,-35.24,0.088
5.10,-35.10,0.088
5.13,-34.95,0.088
5.16,-34.81,0.088
5.19,-34.67,0.088
5.21,-34.53,0.088
5.24,-34.39,0.088
5.27,-34.25,0.088
5.30,-34.10,0.088
5.33,-33.96,0.088
5.35,-33.82,0.088
5.38,-33.68,0.088
5.41,-33.54,0.088
5.44,-33.39,0.088
5.47,-33.25,0.088
5.50,-33.11,0.088
5.53,-32.97,0.088
5.55,-32.83,0.088
5.58,-32.69,0.088
5.61,-32.54,0.088
5.64,-32.40,0.089
5.67,-32.26,0.089
5.70,-32.12,0.089
5.72,-31.98,0.089
5.75,-31.83,0.089
5.78,-31.69,0.089
5.81,-31.55,0.089
5.84,-31.41,0.089
5.86,-31.27,0.089
5.89,-31.13,0.089
5.92,-30.98,0.089
5.95,-30.84,0.089
5.98,-30.70,0.089
6.01,-30.56,0.089
6.04,-30.42,0.089
6.06,-30.27,0.089
6.09,-30.13,0.089
6.12,-29.99,0.089
6.15,-29.85,0.089
6.18,-29.71,0.089
6.20,-29.57,0.089
6.23,-29.42,0.089
6.26,-29.28,0.089
6.29,-29.14,0.089
6.32,-29.00,0.089
6.35,-28.86,0.089
6.38,-28.71,0.089
6.40,-28.57,0.089
6.43,-28.43,0.089
6.46,-28.29,0.089
6.49,-28.15,0.089
6.52,-28.01,0.089
6.55,-27.87,0.089
6.57,-27.72,0.089
6.60,-27.58,0.089
6.63,-27.44,0.089
6.66,-27.30,0.089
6.69,-27.15,0.089
6.71,-27.01,0.089
6.74,-26.87,0.089
6.77,-26.73,0.089
6.80,-26.59,0.089
6.83,-26.45,0.089
6.86,-26.30,0.089
6.89,-26.16,0.089
6.91,-26.02,0.089
6.94,-25.88,0.089
6.97,-25.74,0.090
7.00,-25.60,0.090
7.03,-25.46,0.090
7.05,-25.31,0.090
7.08,-25.17,0.090
7.11,-25.03,0.090
7.14,-24.89,0.090
7.17,-24.75,0.090
7.20,-24.60,0.090
7.23,-24.46,0.090
7.25,-24.32,0.090
7.28,-24.18,0.090
7.31,-24.04,0.090
7.34,-23.90,0.090
7.37,-23.75,0.090
7.40,-23.61,0.090
7.42,-23.47,0.090
7.45,-23.33,0.090
7.48,-23.19,0.090
7.51,-23.04,0.090
7.54,-22.90,0.090
7.56,-22.76,0.090
7.59,-22.62,0.090
7.62,-22.48,0.090
7.65,-22.34,0.090
7.68,-22.19,0.090
7.71,-22.05,0.090
7.74,-21.91,0.090
7.76,-21.77,0.090
7.79,-21.62,0.090
7.82,-21.48,0.090
7.85,-21.34,0.090
7.88,-21.20,0.090
7.90,-21.06,0.090
7.93,-20.92,0.090
7.96,-20.77,0.090
7.99,-20.63,0.090
8.02,-20.49,0.090
8.05,-20.35,0.090
8.08,-20.21,0.090
8.10,-20.07,0.090
8.13,-19.93,0.090
8.16,-19.78,0.090
8.19,-19.64,0.090
8.22,-19.50,0.091
8.25,-19.36,0.091
8.27,-19.22,0.091
8.30,-19.07,0.091
8.33,-18.93,0.091
8.36,-18.79,0.091
8.39,-18.65,0.091
8.41,-18.51,0.091
8.44,-18.37,0.091
8.47,-18.22,0.091
8.50,-18.08,0.091
8.53,-17.94,0.091
8.56,-17.80,0.091
8.58,-17.66,0.091
8.61,-17.51,0.091
8.64,-17.37,0.091
8.67,-17.23,0.091
8.70,-17.09,0.091
8.73,-16.95,0.091
8.75,-16.81,0.091
8.78,-16.66,0.091
8.81,-16.52,0.091
8.84,-16.38,0.091
8.87,-16.24,0.091
8.90,-16.10,0.091
8.93,-15.96,0.091
8.95,-15.81,0.091
8.98,-15.67,0.091
9.01,-15.53,0.091
9.04,-15.39,0.091
9.07,-15.25,0.091
9.10,-15.10,0.091
9.12,-14.96,0.091
9.15,-14.82,0.091
9.18,-14.68,0.091
9.21,-14.54,0.091
9.24,-14.39,0.091
9.27,-14.25,0.091
9.29,-14.11,0.091
9.32,-13.97,0.091
9.35,-13.83,0.092
9.38,-13.69,0.092
9.41,-13.54,0.092
9.43,-13.40,0.092
9.46,-13.26,0.092
9.49,-13.12,0.092
9.52,-12.98,0.092
9.55,-12.84,0.092
9.58,-12.69,0.092
9.60,-12.55,0.092
9.63,-12.41,0.092
9.66,-12.27,0.092
9.69,-12.13,0.092
9.72,-11.99,0.092
9.75,-11.84,0.092
9.78,-11.70,0.092
9.80,-11.56,0.092
9.83,-11.42,0.092
9.86,-11.28,0.092
9.89,-11.13,0.092
9.92,-10.99,0.092
9.95,-10.85,0.092
9.97,-10.71,0.092
10.00,-10.57,0.092
10.03,-10.43,0.092
10.06,-10.28,0.092
10.09,-10.14,0.092
10.12,-10.00,0.092
10.14,-9.86,0.092
10.17,-9.72,0.093
10.20,-9.58,0.093
10.23,-9.43,0.093
10.26,-9.29,0.093
10.28,-9.15,0.093
10.31,-9.01,0.093
10.34,-8.87,0.093
10.37,-8.72,0.093
10.40,-8.58,0.093
10.43,-8.44,0.093
10.45,-8.30,0.093
10.48,-8.16,0.093
10.51,-8.02,0.093
10.54,-7.87,0.093
10.57,-7.73,0.093
10.60,-7.59,0.093
10.63,-7.45,0.093
10.65,-7.31,0.093
10.68,-7.16,0.093
10.71,-7.02,0.093
10.74,-6.88,0.093
10.77,-6.74,0.093
10.80,-6.60,0.093
10.82,-6.45,0.093
10.85,-6.31,0.093
10.88,-6.17,0.093
10.91,-6.03,0.093
10.94,-5.89,0.093
10.97,-5.75,0.094
10.99,-5.61,0.094
11.02,-5.46,0.094
11.05,-5.32,0.094
11.08,-5.18,0.094
11.11,-5.04,0.094
11.13,-4.90,0.094
11.16,-4.76,0.094
11.19,-4.61,0.094
11.22,-4.47,0.094
11.25,-4.33,0.094
11.28,-4.19,0.094
11.30,-4.05,0.094
11.33,-3.90,0.094
11.36,-3.76,0.094
11.39,-3.62,0.094
11.42,-3.48,0.094
11.45,-3.34,0.094
11.48,-3.20,0.094
11.50,-3.05,0.094
11.53,-2.91,0.094
11.56,-2.77,0.094
11.59,-2.63,0.094
11.62,-2.48,0.094
11.65,-2.34,0.094
11.67,-2.20,0.094
11.70,-2.06,0.094
11.73,-1.92,0.094
11.76,-1.78,0.094
11.79,-1.63,0.095
11.82,-1.49,0.095
11.84,-1.35,0.095
11.87,-1.21,0.095
11.90,-1.07,0.095
11.93,-0.93,0.095
11.96,-0.79,0.095
11.98,-0.64,0.095
12.01,-0.50,0.095
12.04,-0.36,0.095
12.07,-0.22,0.095
12.10,-0.08,0.095
12.13,0.07,0.095
12.15,0.21,0.095
12.18,0.35,0.095
12.21,0.49,0.095
12.24,0.63,0.095
12.27,0.77,0.095
12.30,0.92,0.095
12.33,1.06,0.095
12.35,1.20,0.095
12.38,1.34,0.095
12.41,1.48,0.095
12.44,1.63,0.095
12.47,1.77,0.096
12.50,1.91,0.096
12.52,2.05,0.096
12.55,2.19,0.096
12.58,2.33,0.096
12.61,2.48,0.096
12.64,2.62,0.096
12.67,2.76,0.096
12.69,2.90,0.096
12.72,3.04,0.096
12.75,3.18,0.096
12.78,3.32,0.096
12.81,3.47,0.096
12.83,3.61,0.096
12.86,3.75,0.096
12.89,3.89,0.096
12.92,4.03,0.096
12.95,4.18,0.096
12.98,4.32,0.096
13.00,4.46,0.096
13.03,4.60,0.096
13.06,4.74,0.096
13.09,4.89,0.096
13.12,5.03,0.096
13.15,5.17,0.096
13.18,5.31,0.097
13.20,5.45,0.097
13.23,5.59,0.097
13.26,5.74,0.097
13.29,5.88,0.097
13.32,6.02,0.097
13.35,6.16,0.097
13.37,6.30,0.097
13.40,6.44,0.097
13.43,6.58,0.097
13.46,6.73,0.097
13.49,6.87,0.097
13.52,7.01,0.097
13.54,7.15,0.097
13.57,7.29,0.097
13.60,7.44,0.097
13.63,7.58,0.097
13.66,7.72,0.097
13.68,7.86,0.097
13.71,8.00,0.097
13.74,8.15,0.097
13.77,8.29,0.098
13.80,8.43,0.098
13.83,8.57,0.098
13.85,8.71,0.098
13.88,8.86,0.098
13.91,9.00,0.098
13.94,9.14,0.098
13.97,9.28,0.098
14.00,9.42,0.098
14.03,9.56,0.098
14.05,9.70,0.098
14.08,9.85,0.098
14.11,9.99,0.098
14.14,10.13,0.098
14.17,10.27,0.098
14.20,10.42,0.098
14.22,10.56,0.098
14.25,10.70,0.098
14.28,10.84,0.098
14.31,10.98,0.099
14.34,11.12,0.099
14.37,11.26,0.099
14.39,11.41,0.099
14.42,11.55,0.099
14.45,11.69,0.099
14.48,11.83,0.099
14.51,11.97,0.099
14.53,12.11,0.099
14.56,12.26,0.099
14.59,12.40,0.099
14.62,12.54,0.099
14.65,12.68,0.099
14.68,12.82,0.099
14.70,12.96,0.099
14.73,13.11,0.099
14.76,13.25,0.099
14.79,13.39,0.099
14.82,13.53,0.099
14.85,13.67,0.099
14.88,13.82,0.099
14.90,13.96,0.099
14.93,14.10,0.100
14.96,14.24,0.100
14.99,14.38,0.100
15.02,14.53,0.100
15.05,14.67,0.100
15.07,14.81,0.100
15.10,14.95,0.100
15.13,15.09,0.100
15.16,15.23,0.100
15.19,15.38,0.100
15.22,15.52,0.100
15.24,15.66,0.100
15.27,15.80,0.100
15.30,15.94,0.100
15.33,16.08,0.100
15.36,16.23,0.100
15.38,16.37,0.101
15.41,16.51,0.101
15.44,16.65,0.101
15.47,16.79,0.101
15.50,16.93,0.101
15.53,17.08,0.101
15.55,17.22,0.101
15.58,17.36,0.101
15.61,17.50,0.101
15.64,17.64,0.101
15.67,17.78,0.101
15.70,17.93,0.101
15.73,18.07,0.101
15.75,18.21,0.101
15.78,18.35,0.101
15.81,18.49,0.101
15.84,18.64,0.101
15.87,18.78,0.101
15.90,18.92,0.101
15.92,19.06,0.101
15.95,19.20,0.101
15.98,19.34,0.101
16.01,19.49,0.101
16.04,19.63,0.101
16.07,19.77,0.101
16.09,19.91,0.101
16.12,20.05,0.102
16.15,20.19,0.102
16.18,20.34,0.102
16.21,20.48,0.102
16.23,20.62,0.102
16.26,20.76,0.102
16.29,20.90,0.102
16.32,21.05,0.102
16.35,21.19,0.102
16.38,21.33,0.102
16.40,21.47,0.102
16.43,21.61,0.102
16.46,21.75,0.102
16.49,21.89,0.102
16.52,22.04,0.102
16.55,22.18,0.102
16.58,22.32,0.102
16.60,22.46,0.103
16.63,22.60,0.103
16.66,22.75,0.103
16.69,22.89,0.103
16.72,23.03,0.103
16.75,23.17,0.103
16.77,23.31,0.103
16.80,23.46,0.103
16.83,23.60,0.103
16.86,23.74,0.103
16.89,23.88,0.103
16.92,24.02,0.103
16.94,24.16,0.103
16.97,24.31,0.103
17.00,24.45,0.103
17.03,24.59,0.103
17.06,24.73,0.103
17.08,24.87,0.103
17.11,25.02,0.104
17.14,25.16,0.104
17.17,25.30,0.104
17.20,25.44,0.104
17.23,25.58,0.104
17.26,25.72,0.104
17.28,25.87,0.104
17.31,26.01,0.104
17.34,26.15,0.104
17.37,26.29,0.104
17.40,26.43,0.104
17.43,26.57,0.104
17.45,26.72,0.104
17.48,26.86,0.104
17.51,27.00,0.104
17.54,27.14,0.104
17.57,27.28,0.104
17.59,27.42,0.104
17.62,27.57,0.104
17.65,27.71,0.104
17.68,27.85,0.105
17.71,27.99,0.105
17.74,28.13,0.105
17.77,28.28,0.105
17.79,28.42,0.105
17.82,28.56,0.105
17.85,28.70,0.105
17.88,28.84,0.105
17.91,28.98,0.105
17.93,29.12,0.105
17.96,29.27,0.105
17.99,29.41,0.105
18.02,29.55,0.105
18.05,29.69,0.105
18.08,29.83,0.105
18.11,29.98,0.105
18.13,30.12,0.105
18.16,30.26,0.106
18.19,30.40,0.106
18.22,30.54,0.106
18.25,30.68,0.106
18.28,30.83,0.106
18.30,30.97,0.106
18.33,31.11,0.106
18.36,31.25,0.106
18.39,31.39,0.106
18.42,31.54,0.106
18.44,31.68,0.106
18.47,31.82,0.106
18.50,31.96,0.106
18.53,32.10,0.107
18.56,32.24,0.107
18.59,32.39,0.107
18.62,32.53,0.107
18.64,32.67,0.107
18.67,32.81,0.107
18.70,32.95,0.107
18.73,33.09,0.107
18.76,33.24,0.107
18.78,33.38,0.107
18.81,33.52,0.107
18.84,33.66,0.107
18.87,33.80,0.107
18.90,33.94,0.107
18.93,34.09,0.108
18.96,34.23,0.108
18.98,34.37,0.108
19.01,34.51,0.108
19.04,34.65,0.108
19.07,34.79,0.108
19.10,34.93,0.108
19.13,35.08,0.108
19.15,35.22,0.108
19.18,35.36,0.108
19.21,35.50,0.108
19.24,35.64,0.109
19.27,35.79,0.109
19.29,35.93,0.109
19.32,36.07,0.109
19.35,36.21,0.109
19.38,36.35,0.109
19.41,36.50,0.109
19.44,36.64,0.109
19.47,36.78,0.109
19.49,36.92,0.109
19.52,37.06,0.110
19.55,37.20,0.110
19.58,37.35,0.110
19.61,37.49,0.110
19.63,37.63,0.110
19.66,37.77,0.110
19.69,37.91,0.110
19.72,38.06,0.110
19.75,38.20,0.110
19.78,38.34,0.110
19.81,38.48,0.111
19.83,38.62,0.111
19.86,38.76,0.111
19.89,38.90,0.111
19.92,39.05,0.111
19.95,39.19,0.111
19.98,39.33,0.111
20.00,39.47,0.111
20.03,39.61,0.112
20.06,39.76,0.112
20.09,39.90,0.112
20.12,40.04,0.112
20.14,40.18,0.112
20.17,40.32,0.112
20.20,40.46,0.112
20.23,40.61,0.113
20.26,40.75,0.113
20.29,40.89,0.113
20.32,41.03,0.113
20.34,41.17,0.113
20.37,41.31,0.114
20.40,41.46,0.114
20.43,41.60,0.114
20.46,41.74,0.114
20.48,41.88,0.115
20.51,42.02,0.115
20.54,42.16,0.115
20.57,42.31,0.115
20.60,42.45,0.116
20.63,42.59,0.116
20.66,42.73,0.116
20.68,42.87,0.117
20.71,43.01,0.117
20.74,43.16,0.118
20.77,43.30,0.118
20.80,43.44,0.119
20.83,43.58,0.119
20.85,43.72,0.120
20.88,43.86,0.120
20.91,44.00,0.121
20.94,44.14,0.122
20.97,44.29,0.122
20.99,44.43,0.123
21.02,44.57,0.124
21.05,44.71,0.124
21.08,44.85,0.125
21.11,44.99,0.126
21.14,45.14,0.127
21.17,45.28,0.127
21.19,45.42,0.128
21.22,45.56,0.129
21.25,45.70,0.130
21.28,45.84,0.131
21.31,45.98,0.131
21.33,46.13,0.133
21.36,46.27,0.134
21.39,46.41,0.135
21.42,46.55,0.136
21.45,46.69,0.137
21.48,46.83,0.138
21.51,46.98,0.139
21.53,47.11,0.140
21.56,47.26,0.141
21.59,47.40,0.142
21.62,47.54,0.143
21.65,47.68,0.144
21.68,47.82,0.145
21.70,47.96,0.147
21.73,48.11,0.148
21.76,48.25,0.149
21.79,48.39,0.151
21.82,48.53,0.152
21.84,48.67,0.153
21.87,48.81,0.155
21.90,48.95,0.156
21.93,49.09,0.158
21.96,49.24,0.159
21.99,49.38,0.162
22.02,49.52,0.164
22.04,49.66,0.165
22.07,49.80,0.167
22.10,49.94,0.168
22.13,50.08,0.170
22.16,50.22,0.172
22.18,50.36,0.173
22.21,50.51,0.176
22.24,50.65,0.178
22.27,50.79,0.180
22.30,50.93,0.183
22.33,51.07,0.184
22.36,51.21,0.187
22.38,51.35,0.189
22.41,51.49,0.191
22.44,51.63,0.192
22.47,51.78,0.195
22.50,51.92,0.196
22.53,52.06,0.198
22.55,52.20,0.200
22.58,52.34,0.202
22.61,52.48,0.205
22.64,52.62,0.207
22.67,52.76,0.210
22.69,52.90,0.212
22.72,53.04,0.214
22.75,53.18,0.216
22.78,53.32,0.218
22.81,53.47,0.220
22.84,53.61,0.223
22.87,53.75,0.225
22.89,53.89,0.227
22.92,54.03,0.229
22.95,54.17,0.231
22.98,54.31,0.233
23.01,54.45,0.236
23.03,54.59,0.238
23.06,54.73,0.240
23.09,54.88,0.243
23.12,55.02,0.245
23.15,55.16,0.247
23.18,55.30,0.249
23.21,55.44,0.252
23.23,55.58,0.254
23.26,55.72,0.256
23.29,55.86,0.259
23.32,56.00,0.261
23.35,56.14,0.263
23.38,56.29,0.266
23.40,56.43,0.268
23.43,56.57,0.271
23.46,56.71,0.274
23.49,56.85,0.276
23.52,56.99,0.278
23.54,57.13,0.282
23.57,57.27,0.284
23.60,57.41,0.286
23.63,57.55,0.288
23.66,57.69,0.290
23.69,57.84,0.292
23.72,57.98,0.296
23.74,58.12,0.298
23.77,58.26,0.300
23.80,58.40,0.303
23.83,58.54,0.305
23.86,58.68,0.307
23.88,58.82,0.309
23.91,58.96,0.310
23.94,59.10,0.312
23.97,59.25,0.314
24.00,59.39,0.314
24.03,59.53,0.316
24.06,59.67,0.317
24.08,59.81,0.318
24.11,59.95,0.319
24.14,60.09,0.320
24.17,60.23,0.321
24.20,60.38,0.322
24.23,60.52,0.323
24.25,60.66,0.323
24.28,60.80,0.324
24.31,60.94,0.325
24.34,61.08,0.326
24.37,61.22,0.326
24.39,61.37,0.327
24.42,61.51,0.327
24.45,61.65,0.328
24.48,61.79,0.328
24.51,61.93,0.329
24.54,62.07,0.329
24.57,62.22,0.330
24.59,62.36,0.331
24.62,62.50,0.331
24.65,62.64,0.332
24.68,62.78,0.331
24.71,62.92,0.331
24.73,63.07,0.331
24.76,63.21,0.330
24.79,63.35,0.329
24.82,63.49,0.328
24.85,63.64,0.326
24.88,63.78,0.324
24.91,63.92,0.323
24.93,64.06,0.320
24.96,64.21,0.317
24.99,64.35,0.315
25.02,64.49,0.311
25.05,64.63,0.308
25.08,64.78,0.306
25.10,64.92,0.304
25.13,65.06,0.302
25.16,65.20,0.300
25.19,65.35,0.297
25.22,65.49,0.295
25.24,65.63,0.293
25.27,65.77,0.291
25.30,65.92,0.289
25.33,66.06,0.288
25.36,66.20,0.286
25.39,66.34,0.285
25.42,66.49,0.283
25.44,66.63,0.282
25.47,66.77,0.281
25.50,66.91,0.280
25.53,67.06,0.278
25.56,67.20,0.277
25.58,67.34,0.276
25.61,67.48,0.275
25.64,67.63,0.274
25.67,67.77,0.272
25.70,67.91,0.270
25.73,68.05,0.270
25.76,68.19,0.269
25.78,68.34,0.268
25.81,68.48,0.266
25.84,68.62,0.265
25.87,68.76,0.264
25.90,68.91,0.263
25.93,69.05,0.261
25.95,69.19,0.260
25.98,69.33,0.259
26.01,69.48,0.257
26.04,69.62,0.256
26.07,69.76,0.255
26.09,69.90,0.253
26.12,70.04,0.250
26.15,70.19,0.248
26.18,70.33,0.246
26.21,70.47,0.245
26.24,70.61,0.243
26.27,70.76,0.241
26.29,70.90,0.240
26.32,71.04,0.237
26.35,71.18,0.235
26.38,71.33,0.233
26.41,71.47,0.231
26.43,71.61,0.229
26.46,71.75,0.227
26.49,71.90,0.225
26.52,72.04,0.223
26.55,72.18,0.222
26.58,72.32,0.218
26.61,72.47,0.217
26.63,72.61,0.215
26.66,72.75,0.213
26.69,72.89,0.212
26.72,73.04,0.210
26.75,73.18,0.209
26.78,73.32,0.207
26.80,73.46,0.204
26.83,73.61,0.203
26.86,73.75,0.201
26.89,73.89,0.199
26.92,74.03,0.198
26.94,74.17,0.197
26.97,74.32,0.195
27.00,74.46,0.194
27.03,74.60,0.193
27.06,74.74,0.191
27.09,74.89,0.188
27.12,75.03,0.187
27.14,75.17,0.184
27.17,75.31,0.182
27.20,75.46,0.180
27.23,75.60,0.178
27.26,75.74,0.176
27.28,75.88,0.175
27.31,76.03,0.174
27.34,76.17,0.173
27.37,76.31,0.171
27.40,76.45,0.169
27.43,76.60,0.167
27.46,76.74,0.166
27.48,76.88,0.165
27.51,77.02,0.164
27.54,77.16,0.162
27.57,77.31,0.161
27.60,77.45,0.161
27.63,77.59,0.160
27.65,77.73,0.159
27.68,77.88,0.159
27.71,78.02,0.158
27.74,78.16,0.158
27.77,78.30,0.158
27.79,78.44,0.157
27.82,78.58,0.157
27.85,78.73,0.157
27.88,78.87,0.157
27.91,79.01,0.156
27.94,79.15,0.156
27.97,79.29,0.156
27.99,79.43,0.156
28.02,79.57,0.156
28.05,79.72,0.155
28.08,79.86,0.155
28.11,80.00,0.155
28.13,80.14,0.155
28.16,80.28,0.155
28.19,80.43,0.155
28.22,80.57,0.155
28.25,80.71,0.155
28.28,80.85,0.155
28.31,80.99,0.155
28.33,81.13,0.155
28.36,81.27,0.155
28.39,81.42,0.155
28.42,81.56,0.155
28.45,81.70,0.155
28.48,81.84,0.155
28.50,81.98,0.155
28.53,82.13,0.155
28.56,82.27,0.155
28.59,82.41,0.155
28.62,82.55,0.155
28.64,82.69,0.155
28.67,82.83,0.155
28.70,82.97,0.155
28.73,83.12,0.155
28.76,83.26,0.155
28.79,83.40,0.155
28.82,83.54,0.156
28.84,83.68,0.156
28.87,83.83,0.156
28.90,83.97,0.156
28.93,84.11,0.156
28.96,84.25,0.156
28.98,84.39,0.156
29.01,84.53,0.156
29.04,84.68,0.156
29.07,84.82,0.156
29.10,84.96,0.156
29.13,85.10,0.156
29.16,85.24,0.156
29.18,85.38,0.156
29.21,85.53,0.156
29.24,85.67,0.156
29.27,85.81,0.156
29.30,85.95,0.156
29.33,86.09,0.156
29.35,86.24,0.156
29.38,86.38,0.157
29.41,86.52,0.157
29.44,86.66,0.157
29.47,86.80,0.157
29.49,86.94,0.157
29.52,87.09,0.157
29.55,87.23,0.157
29.58,87.37,0.157
29.61,87.51,0.157
29.64,87.65,0.157
29.67,87.80,0.157
29.69,87.94,0.157
29.72,88.08,0.157
29.75,88.22,0.157
29.78,88.36,0.157
29.81,88.50,0.157
29.83,88.64,0.157
29.86,88.79,0.157
29.89,88.93,0.157
29.92,89.07,0.157
29.95,89.21,0.157
29.98,89.35,0.157
30.01,89.49,0.158
30.03,89.64,0.158
30.06,89.78,0.158
30.09,89.92,0.158
30.12,90.06,0.158
30.15,90.20,0.158
30.18,90.35,0.158
30.20,90.49,0.158
30.23,90.63,0.158
30.26,90.77,0.158
30.29,90.91,0.158
30.32,91.05,0.158
30.34,91.19,0.158
30.37,91.34,0.158
30.40,91.48,0.158
30.43,91.62,0.158
30.46,91.76,0.158
30.49,91.90,0.159
30.52,92.05,0.159
30.54,92.19,0.159
30.57,92.33,0.159
30.60,92.47,0.159
30.63,92.61,0.159
30.66,92.76,0.159
30.68,92.90,0.159
30.71,93.04,0.159
30.74,93.18,0.159
30.77,93.32,0.159
30.80,93.46,0.159
30.83,93.61,0.159
30.86,93.75,0.159
30.88,93.89,0.159
30.91,94.03,0.159
30.94,94.17,0.159
30.97,94.31,0.159
31.00,94.46,0.160
31.03,94.60,0.160
31.05,94.74,0.160
31.08,94.88,0.160
31.11,95.02,0.160
31.14,95.16,0.160
31.17,95.31,0.160
31.19,95.45,0.160
31.22,95.59,0.160
31.25,95.73,0.160
31.28,95.87,0.160
31.31,96.01,0.160
31.34,96.16,0.160
31.37,96.30,0.160
31.39,96.44,0.160
31.42,96.58,0.160
31.45,96.72,0.160
31.48,96.86,0.160
31.51,97.01,0.160
31.53,97.15,0.161
31.56,97.29,0.161
31.59,97.43,0.161
31.62,97.57,0.161
31.65,97.72,0.161
31.68,97.86,0.161
31.71,98.00,0.161
31.73,98.14,0.161
31.76,98.28,0.161
31.79,98.42,0.161
31.82,98.57,0.161
31.85,98.71,0.161
31.88,98.85,0.161
31.90,98.99,0.161
31.93,99.13,0.162
31.96,99.27,0.162
31.99,99.42,0.162
32.02,99.56,0.162
32.04,99.70,0.162
32.07,99.84,0.162
32.10,99.98,0.162
32.13,100.12,0.162
32.16,100.27,0.162
32.19,100.41,0.162
32.22,100.55,0.162
32.24,100.69,0.162
32.27,100.83,0.162
32.30,100.97,0.162
32.33,101.12,0.162
32.36,101.26,0.162
32.38,101.40,0.163
32.41,101.54,0.163
32.44,101.68,0.163
32.47,101.83,0.163
32.50,101.97,0.163
32.53,102.11,0.163
32.56,102.25,0.163
32.58,102.39,0.163
32.61,102.53,0.163
32.64,102.67,0.163
32.67,102.82,0.163
32.70,102.96,0.163
32.73,103.10,0.163
32.75,103.24,0.163
32.78,103.38,0.164
32.81,103.52,0.164
32.84,103.67,0.164
32.87,103.81,0.164
32.89,103.95,0.164
32.92,104.09,0.164
32.95,104.23,0.164
32.98,104.38,0.164
33.01,104.52,0.164
33.04,104.66,0.164
33.07,104.80,0.164
33.09,104.94,0.165
33.12,105.08,0.165
33.15,105.23,0.165
33.18,105.37,0.165
33.21,105.51,0.165
33.23,105.65,0.165
33.26,105.79,0.165
33.29,105.94,0.165
33.32,106.08,0.165
33.35,106.22,0.165
33.38,106.36,0.165
33.41,106.50,0.165
33.43,106.64,0.165
33.46,106.79,0.165
33.49,106.93,0.166
33.52,107.07,0.166
33.55,107.21,0.166
33.58,107.35,0.166
33.60,107.49,0.166
33.63,107.63,0.166
33.66,107.78,0.166
33.69,107.92,0.166
33.72,108.06,0.166
33.74,108.20,0.166
33.77,108.34,0.166
33.80,108.49,0.166
33.83,108.63,0.166
33.86,108.77,0.166
33.89,108.91,0.167
33.92,109.05,0.167
33.94,109.19,0.167
33.97,109.33,0.167
34.00,109.48,0.167
34.03,109.62,0.167
34.06,109.76,0.167
34.08,109.90,0.167
34.11,110.04,0.167
34.14,110.19,0.167
34.17,110.33,0.168
34.20,110.47,0.168
34.23,110.61,0.168
34.26,110.75,0.168
34.28,110.89,0.168
34.31,111.04,0.168
34.34,111.18,0.168
34.37,111.32,0.168
34.40,111.46,0.168
34.43,111.60,0.168
34.45,111.74,0.169
34.48,111.89,0.169
34.51,112.03,0.169
34.54,112.17,0.169
34.57,112.31,0.169
34.59,112.45,0.169
34.62,112.60,0.169
34.65,112.74,0.169
34.68,112.88,0.169
34.71,113.02,0.169
34.74,113.16,0.169
34.76,113.30,0.170
34.79,113.45,0.170
34.82,113.59,0.170
34.85,113.73,0.170
34.88,113.87,0.170
34.91,114.01,0.170
34.94,114.15,0.170
34.96,114.30,0.170
34.99,114.44,0.170
35.02,114.58,0.170
35.05,114.72,0.170
35.08,114.86,0.170
35.11,115.00,0.171
35.13,115.15,0.171
35.16,115.29,0.171
35.19,115.43,0.171
35.22,115.57,0.171
35.25,115.71,0.171
35.28,115.85,0.171
35.30,116.00,0.171
35.33,116.14,0.171
35.36,116.28,0.171
35.39,116.42,0.171
35.42,116.56,0.172
35.44,116.70,0.172
35.47,116.84,0.172
35.50,116.99,0.172
35.53,117.13,0.172
35.56,117.27,0.172
35.59,117.41,0.172
35.61,117.55,0.172
35.64,117.70,0.172
35.67,117.84,0.172
35.70,117.98,0.172
35.73,118.12,0.173
35.76,118.26,0.173
35.79,118.41,0.173
35.81,118.55,0.173
35.84,118.69,0.173
35.87,118.83,0.173
35.90,118.97,0.173
35.93,119.11,0.173
35.96,119.25,0.173
35.98,119.40,0.173
36.01,119.54,0.173
36.04,119.68,0.173
36.07,119.82,0.173
36.10,119.96,0.174
36.13,120.11,0.174
36.15,120.25,0.174
36.18,120.39,0.174
36.21,120.53,0.174
36.24,120.67,0.174
36.27,120.81,0.174
36.29,120.96,0.174
36.32,121.10,0.174
36.35,121.24,0.174
36.38,121.38,0.174
36.41,121.52,0.175
36.44,121.66,0.175
36.46,121.81,0.175
36.49,121.95,0.175
36.52,122.09,0.175
36.55,122.23,0.175
36.58,122.37,0.175
36.61,122.51,0.175
36.64,122.65,0.175
36.66,122.80,0.175
36.69,122.94,0.175
36.72,123.08,0.176
36.75,123.22,0.176
36.78,123.36,0.176
36.81,123.51,0.176
36.83,123.65,0.176
36.86,123.79,0.176
36.89,123.93,0.176
36.92,124.07,0.176
36.95,124.21,0.176
36.98,124.36,0.177
37.00,124.50,0.177
37.03,124.64,0.177
37.06,124.78,0.177
37.09,124.92,0.177
37.12,125.07,0.177
37.14,125.21,0.177
37.17,125.35,0.177
37.20,125.49,0.177
37.23,125.63,0.177
37.26,125.77,0.177
37.29,125.91,0.177
37.31,126.06,0.177
37.34,126.20,0.178
37.37,126.34,0.178
37.40,126.48,0.178
37.43,126.62,0.178
37.46,126.76,0.178
37.49,126.91,0.178
37.51,127.05,0.178
37.54,127.19,0.178
37.57,127.33,0.178
37.60,127.47,0.179
37.63,127.61,0.179
37.66,127.76,0.179
37.68,127.90,0.179
37.71,128.04,0.179
37.74,128.18,0.179
37.77,128.32,0.179
37.80,128.46,0.179
37.83,128.61,0.179
37.85,128.75,0.179
37.88,128.89,0.180
37.91,129.03,0.180
37.94,129.17,0.180
37.97,129.32,0.180
37.99,129.46,0.180
38.02,129.60,0.180
38.05,129.74,0.180
38.08,129.88,0.180
38.11,130.02,0.180
38.14,130.17,0.180
38.16,130.31,0.181
38.19,130.45,0.181
38.22,130.59,0.181
38.25,130.73,0.181
38.28,130.87,0.181
38.31,131.02,0.181
38.34,131.16,0.181
38.36,131.30,0.181
38.39,131.44,0.181
38.42,131.58,0.181
38.45,131.72,0.181
38.48,131.86,0.181
38.51,132.01,0.181
38.53,132.15,0.182
38.56,132.29,0.182
38.59,132.43,0.182
38.62,132.57,0.182
38.65,132.72,0.182
38.68,132.86,0.182
38.70,133.00,0.182
38.73,133.14,0.182
38.76,133.28,0.182
38.79,133.42,0.182
38.82,133.57,0.182
38.84,133.71,0.183
38.87,133.85,0.183
38.90,133.99,0.183
38.93,134.13,0.183
38.96,134.27,0.183
38.99,134.42,0.183
39.01,134.56,0.183
39.04,134.70,0.183
39.07,134.84,0.183
39.10,134.98,0.184
39.13,135.13,0.184
39.16,135.27,0.184
39.19,135.41,0.184
39.21,135.55,0.184
39.24,135.69,0.184
39.27,135.83,0.184
39.30,135.97,0.184
39.33,136.12,0.184
39.36,136.26,0.184
39.38,136.40,0.184
39.41,136.54,0.184
39.44,136.68,0.185
39.47,136.82,0.185
39.50,136.97,0.185
39.53,137.11,0.185
39.55,137.25,0.185
39.58,137.39,0.185
39.61,137.53,0.185
39.64,137.67,0.185
39.67,137.82,0.186
39.69,137.96,0.186
39.72,138.10,0.186
39.75,138.24,0.186
39.78,138.38,0.186
39.81,138.52,0.186
39.84,138.67,0.186
39.86,138.81,0.186
39.89,138.95,0.187
39.92,139.09,0.187
39.95,139.23,0.187
39.98,139.37,0.187
40.01,139.52,0.187
40.04,139.66,0.187
40.06,139.80,0.188
40.09,139.94,0.188
40.12,140.08,0.188
40.15,140.22,0.188
40.18,140.37,0.189
40.21,140.51,0.189
40.23,140.65,0.189
40.26,140.79,0.189
40.29,140.93,0.190
40.32,141.08,0.190
40.35,141.22,0.190
40.38,141.36,0.190
40.40,141.50,0.191
40.43,141.64,0.191
40.46,141.78,0.191
40.49,141.92,0.191
40.52,142.06,0.192
40.54,142.21,0.192
40.57,142.35,0.192
40.60,142.49,0.193
40.63,142.63,0.193
40.66,142.77,0.194
40.69,142.91,0.195
40.71,143.06,0.195
40.74,143.20,0.196
40.77,143.34,0.196
40.80,143.48,0.197
40.83,143.62,0.197
40.86,143.76,0.198
40.89,143.91,0.199
40.91,144.05,0.199
40.94,144.19,0.200
40.97,144.33,0.200
41.00,144.47,0.201
41.03,144.61,0.201
41.06,144.75,0.202
41.08,144.90,0.202
41.11,145.04,0.203
41.14,145.18,0.203
41.17,145.32,0.203
41.20,145.46,0.204
41.23,145.60,0.204
41.25,145.75,0.204
41.28,145.89,0.204
41.31,146.03,0.205
41.34,146.17,0.205
41.37,146.31,0.205
41.39,146.45,0.205
41.42,146.60,0.205
41.45,146.74,0.205
41.48,146.88,0.205
41.51,147.02,0.205
41.54,147.16,0.205
41.56,147.30,0.205
41.59,147.45,0.205
41.62,147.59,0.205
41.65,147.73,0.205
41.68,147.87,0.205
41.71,148.01,0.204
41.74,148.16,0.204
41.76,148.30,0.204
41.79,148.44,0.204
41.82,148.58,0.204
41.85,148.72,0.204
41.88,148.86,0.204
41.91,149.01,0.204
41.93,149.15,
41.96,149.29,
41.99,,

[step]
Ramp 5.00 °C/min to -60.00 °C
Time,Temperature,Heat Flow (Normalized)
min,°C,W/g
42.99,150.11,-0.020
43.01,150.11,-0.021
43.04,150.10,-0.021
43.07,150.08,-0.020
43.10,150.03,-0.030
43.13,149.96,-0.067
43.16,149.87,-0.109
43.19,149.76,-0.143
43.21,149.65,-0.166
43.24,149.53,-0.186
43.27,149.40,-0.198
43.30,149.27,-0.207
43.33,149.14,-0.213
43.36,149.01,-0.220
43.38,148.87,-0.223
43.41,148.74,-0.226
43.44,148.60,-0.228
43.47,148.46,-0.230
43.50,148.32,-0.231
43.53,148.18,-0.234
43.55,148.05,-0.235
43.58,147.91,-0.235
43.61,147.77,-0.235
43.64,147.63,-0.236
43.67,147.49,-0.236
43.69,147.35,-0.237
43.72,147.21,-0.237
43.75,147.07,-0.238
43.78,146.93,-0.238
43.81,146.79,-0.238
43.84,146.65,-0.239
43.86,146.51,-0.239
43.89,146.37,-0.240
43.92,146.22,-0.240
43.95,146.08,-0.241
43.98,145.94,-0.241
44.01,145.80,-0.241
44.04,145.66,-0.242
44.06,145.52,-0.242
44.09,145.38,-0.242
44.12,145.24,-0.242
44.15,145.10,-0.242
44.18,144.96,-0.243
44.21,144.82,-0.243
44.23,144.67,-0.243
44.26,144.53,-0.243
44.29,144.39,-0.244
44.32,144.25,-0.244
44.35,144.11,-0.244
44.38,143.97,-0.244
44.40,143.83,-0.244
44.43,143.69,-0.244
44.46,143.54,-0.244
44.49,143.40,-0.245
44.52,143.26,-0.245
44.54,143.12,-0.245
44.57,142.98,-0.245
44.60,142.84,-0.245
44.63,142.70,-0.245
44.66,142.55,-0.245
44.69,142.41,-0.245
44.71,142.27,-0.245
44.74,142.13,-0.245
44.77,141.99,-0.245
44.80,141.85,-0.245
44.83,141.70,-0.245
44.86,141.56,-0.246
44.89,141.42,-0.246
44.91,141.28,-0.246
44.94,141.14,-0.246
44.97,141.00,-0.246
45.00,140.86,-0.246
45.03,140.72,-0.246
45.06,140.57,-0.246
45.08,140.43,-0.246
45.11,140.29,-0.246
45.14,140.15,-0.246
45.17,140.00,-0.246
45.20,139.86,-0.246
45.23,139.72,-0.246
45.25,139.58,-0.246
45.28,139.44,-0.246
45.31,139.30,-0.246
45.34,139.16,-0.245
45.37,139.02,-0.245
45.39,138.87,-0.245
45.42,138.73,-0.246
45.45,138.59,-0.246
45.48,138.45,-0.246
45.51,138.31,-0.246
45.54,138.17,-0.246
45.56,138.03,-0.246
45.59,137.89,-0.246
45.62,137.74,-0.246
45.65,137.60,-0.246
45.68,137.46,-0.246
45.71,137.32,-0.246
45.74,137.18,-0.246
45.76,137.04,-0.246
45.79,136.89,-0.246
45.82,136.75,-0.247
45.85,136.61,-0.247
45.88,136.47,-0.247
45.91,136.33,-0.247
45.93,136.19,-0.247
45.96,136.05,-0.247
45.99,135.90,-0.247
46.02,135.76,-0.247
46.05,135.62,-0.247
46.08,135.48,-0.247
46.10,135.34,-0.247
46.13,135.20,-0.248
46.16,135.06,-0.248
46.19,134.91,-0.248
46.22,134.77,-0.248
46.24,134.63,-0.248
46.27,134.49,-0.248
46.30,134.35,-0.248
46.33,134.21,-0.248
46.36,134.07,-0.248
46.39,133.92,-0.249
46.41,133.78,-0.249
46.44,133.64,-0.249
46.47,133.50,-0.249
46.50,133.36,-0.250
46.53,133.22,-0.250
46.56,133.08,-0.250
46.59,132.93,-0.250
46.61,132.79,-0.250
46.64,132.65,-0.251
46.67,132.51,-0.251
46.70,132.37,-0.251
46.73,132.22,-0.251
46.76,132.08,-0.251
46.78,131.94,-0.251
46.81,131.80,-0.251
46.84,131.66,-0.252
46.87,131.52,-0.252
46.90,131.38,-0.252
46.93,131.24,-0.251
46.95,131.09,-0.251
46.98,130.95,-0.251
47.01,130.81,-0.251
47.04,130.67,-0.251
47.07,130.53,-0.251
47.09,130.39,-0.251
47.12,130.24,-0.251
47.15,130.10,-0.251
47.18,129.96,-0.250
47.21,129.82,-0.250
47.24,129.68,-0.250
47.26,129.53,-0.249
47.29,129.39,-0.249
47.32,129.25,-0.249
47.35,129.11,-0.249
47.38,128.97,-0.248
47.41,128.83,-0.248
47.44,128.68,-0.248
47.46,128.54,-0.248
47.49,128.40,-0.247
47.52,128.26,-0.247
47.55,128.12,-0.246
47.58,127.98,-0.246
47.61,127.83,-0.246
47.63,127.69,-0.246
47.66,127.55,-0.245
47.69,127.41,-0.245
47.72,127.27,-0.245
47.75,127.13,-0.245
47.78,126.98,-0.245
47.80,126.84,-0.244
47.83,126.70,-0.244
47.86,126.56,-0.244
47.89,126.42,-0.244
47.92,126.28,-0.244
47.94,126.13,-0.243
47.97,125.99,-0.243
48.00,125.85,-0.243
48.03,125.71,-0.243
48.06,125.57,-0.243
48.09,125.42,-0.242
48.11,125.28,-0.242
48.14,125.14,-0.242
48.17,125.00,-0.242
48.20,124.86,-0.242
48.23,124.72,-0.242
48.26,124.58,-0.241
48.29,124.44,-0.241
48.31,124.29,-0.241
48.34,124.15,-0.241
48.37,124.01,-0.241
48.40,123.87,-0.241
48.43,123.73,-0.240
48.46,123.59,-0.240
48.48,123.44,-0.240
48.51,123.30,-0.240
48.54,123.16,-0.240
48.57,123.02,-0.240
48.60,122.88,-0.240
48.63,122.74,-0.240
48.65,122.59,-0.239
48.68,122.45,-0.239
48.71,122.31,-0.239
48.74,122.17,-0.239
48.77,122.03,-0.239
48.79,121.89,-0.239
48.82,121.75,-0.239
48.85,121.60,-0.238
48.88,121.46,-0.238
48.91,121.32,-0.238
48.94,121.18,-0.238
48.96,121.04,-0.238
48.99,120.89,-0.238
49.02,120.75,-0.238
49.05,120.61,-0.238
49.08,120.47,-0.238
49.11,120.33,-0.238
49.14,120.19,-0.238
49.16,120.05,-0.237
49.19,119.90,-0.237
49.22,119.76,-0.237
49.25,119.62,-0.237
49.28,119.48,-0.237
49.31,119.34,-0.237
49.33,119.20,-0.237
49.36,119.05,-0.237
49.39,118.91,-0.237
49.42,118.77,-0.237
49.45,118.63,-0.236
49.48,118.49,-0.236
49.50,118.35,-0.236
49.53,118.21,-0.236
49.56,118.06,-0.236
49.59,117.92,-0.236
49.62,117.78,-0.236
49.64,117.64,-0.236
49.67,117.50,-0.236
49.70,117.36,-0.236
49.73,117.21,-0.236
49.76,117.07,-0.236
49.79,116.93,-0.236
49.81,116.79,-0.236
49.84,116.65,-0.236
49.87,116.50,-0.236
49.90,116.36,-0.236
49.93,116.22,-0.235
49.96,116.08,-0.235
49.99,115.94,-0.235
50.01,115.80,-0.235
50.04,115.65,-0.235
50.07,115.51,-0.234
50.10,115.37,-0.234
50.13,115.23,-0.234
50.16,115.09,-0.234
50.18,114.95,-0.234
50.21,114.80,-0.234
50.24,114.66,-0.234
50.27,114.52,-0.234
50.30,114.38,-0.233
50.33,114.24,-0.233
50.35,114.10,-0.233
50.38,113.96,-0.233
50.41,113.81,-0.233
50.44,113.67,-0.233
50.47,113.53,-0.233
50.49,113.39,-0.233
50.52,113.25,-0.233
50.55,113.11,-0.233
50.58,112.97,-0.233
50.61,112.82,-0.233
50.64,112.68,-0.233
50.66,112.54,-0.233
50.69,112.40,-0.232
50.72,112.26,-0.232
50.75,112.12,-0.232
50.78,111.97,-0.232
50.81,111.83,-0.232
50.84,111.69,-0.232
50.86,111.55,-0.232
50.89,111.41,-0.232
50.92,111.27,-0.232
50.95,111.13,-0.232
50.98,110.98,-0.232
51.01,110.84,-0.232
51.03,110.70,-0.232
51.06,110.56,-0.231
51.09,110.42,-0.231
51.12,110.28,-0.231
51.15,110.13,-0.231
51.18,109.99,-0.231
51.20,109.85,-0.231
51.23,109.71,-0.231
51.26,109.57,-0.231
51.29,109.42,-0.231
51.32,109.28,-0.231
51.34,109.14,-0.231
51.37,109.00,-0.231
51.40,108.86,-0.231
51.43,108.72,-0.230
51.46,108.58,-0.230
51.49,108.43,-0.230
51.51,108.29,-0.230
51.54,108.15,-0.230
51.57,108.01,-0.230
51.60,107.87,-0.230
51.63,107.73,-0.230
51.66,107.58,-0.230
51.69,107.44,-0.230
51.71,107.30,-0.230
51.74,107.16,-0.230
51.77,107.02,-0.230
51.80,106.88,-0.230
51.83,106.74,-0.229
51.86,106.59,-0.229
51.88,106.45,-0.229
51.91,106.31,-0.229
51.94,106.17,-0.229
51.97,106.03,-0.229
52.00,105.89,-0.229
52.03,105.74,-0.229
52.05,105.60,-0.229
52.08,105.46,-0.229
52.11,105.32,-0.229
52.14,105.18,-0.229
52.17,105.03,-0.229
52.19,104.89,-0.228
52.22,104.75,-0.228
52.25,104.61,-0.228
52.28,104.47,-0.228
52.31,104.33,-0.228
52.34,104.19,-0.228
52.36,104.05,-0.228
52.39,103.90,-0.228
52.42,103.76,-0.228
52.45,103.62,-0.228
52.48,103.48,-0.228
52.51,103.34,-0.228
52.54,103.19,-0.228
52.56,103.05,-0.228
52.59,102.91,-0.228
[...]
184.62,2.49,0.106
184.65,2.63,0.106
184.68,2.77,0.106
184.71,2.91,0.106
184.74,3.05,0.107
184.77,3.20,0.107
184.79,3.34,0.107
184.82,3.48,0.107
184.85,3.62,0.107
184.88,3.76,0.107
184.91,3.90,0.107
184.93,4.05,0.108
184.96,4.19,0.108
184.99,4.33,0.108
185.02,4.47,0.108
185.05,4.61,0.108
185.08,4.75,0.108
185.10,4.90,0.109
185.13,5.04,0.109
185.16,5.18,0.109
185.19,5.32,0.109
185.22,5.46,0.109
185.25,5.60,0.110
185.28,5.74,0.110
185.30,5.89,0.110
185.33,6.03,0.110
185.36,6.17,0.111
185.39,6.31,0.111
185.42,6.45,0.111
185.45,6.60,0.111
185.47,6.74,0.112
185.50,6.88,0.112
185.53,7.02,0.112
185.56,7.16,0.113
185.59,7.30,0.113
185.62,7.45,0.113
185.64,7.59,0.114
185.67,7.73,0.114
185.70,7.87,0.115
185.73,8.01,0.115
185.76,8.15,0.115
185.78,8.30,0.116
185.81,8.44,0.116
185.84,8.58,0.117
185.87,8.72,0.117
185.90,8.86,0.118
185.93,9.00,0.118
185.95,9.14,0.119
185.98,9.29,0.120
186.01,9.43,0.120
186.04,9.57,0.121
186.07,9.71,0.121
186.10,9.85,0.122
186.13,9.99,0.123
186.15,10.14,0.123
186.18,10.28,0.124
186.21,10.42,0.125
186.24,10.56,0.126
186.27,10.70,0.126
186.30,10.84,0.127
186.32,10.98,0.128
186.35,11.12,0.129
186.38,11.27,0.130
186.41,11.41,0.131
186.44,11.55,0.132
186.47,11.69,0.133
186.49,11.83,0.134
186.52,11.97,0.135
186.55,12.11,0.136
186.58,12.26,0.137
186.61,12.40,0.138
186.63,12.54,0.139
186.66,12.68,0.140
186.69,12.82,0.141
186.72,12.96,0.142
186.75,13.11,0.143
186.78,13.25,0.144
186.80,13.39,0.144
186.83,13.53,0.145
186.86,13.67,0.146
186.89,13.81,0.147
186.92,13.96,0.147
186.95,14.10,0.148
186.98,14.24,0.148
187.00,14.38,0.149
187.03,14.52,0.149
187.06,14.66,0.149
187.09,14.80,0.149
187.12,14.95,0.149
187.15,15.09,0.149
187.17,15.23,0.149
187.20,15.37,0.149
187.23,15.51,0.149
187.26,15.66,0.149
187.29,15.80,0.149
187.32,15.94,0.148
187.34,16.08,0.148
187.37,16.23,0.147
187.40,16.37,0.147
187.43,16.51,0.146
187.46,16.65,0.146
187.48,16.79,0.146
187.51,16.93,0.145
187.54,17.08,0.145
187.57,17.22,0.144
187.60,17.36,0.144
187.63,17.50,0.144
187.65,17.64,0.143
187.68,17.79,0.143
187.71,17.93,0.143
187.74,18.07,0.142
187.77,18.21,0.142
187.80,18.35,0.142
187.83,18.50,0.142
187.85,18.64,0.142
187.88,18.78,0.141
187.91,18.92,0.141
187.94,19.06,0.141
187.97,19.20,0.141
188.00,19.35,0.141
188.02,19.49,0.141
188.05,19.63,0.140
188.08,19.77,0.140
188.11,19.91,0.140
188.14,20.05,0.140
188.17,20.20,0.140
188.19,20.34,0.140
188.22,20.48,0.140
188.25,20.62,0.140
188.28,20.76,0.140
188.31,20.91,0.140
188.33,21.05,0.140
188.36,21.19,0.140
188.39,21.33,0.140
188.42,21.47,0.140
188.45,21.61,0.140
188.48,21.76,0.140
188.50,21.90,0.140
188.53,22.04,0.140
188.56,22.18,0.140
188.59,22.32,0.140
188.62,22.46,0.140
188.65,22.61,0.140
188.68,22.75,0.140
188.70,22.89,0.140
188.73,23.03,0.140
188.76,23.17,0.140
188.79,23.32,0.140
188.82,23.46,0.140
188.85,23.60,0.140
188.87,23.74,0.140
188.90,23.88,0.140
188.93,24.02,0.141
188.96,24.17,0.141
188.99,24.31,0.141
189.02,24.45,0.141
189.04,24.59,0.141
189.07,24.73,0.141
189.10,24.88,0.141
189.13,25.02,0.141
189.16,25.16,0.141
189.18,25.30,0.141
189.21,25.44,0.141
189.24,25.58,0.141
189.27,25.73,0.141
189.30,25.87,0.141
189.33,26.01,0.141
189.35,26.15,0.141
189.38,26.29,0.141
189.41,26.43,0.141
189.44,26.58,0.141
189.47,26.72,0.141
189.50,26.86,0.141
189.53,27.00,0.141
189.55,27.14,0.141
189.58,27.29,0.141
189.61,27.43,0.141
189.64,27.57,0.141
189.67,27.71,0.141
189.70,27.85,0.141
189.72,27.99,0.141
189.75,28.14,0.141
189.78,28.28,0.142
189.81,28.42,0.142
189.84,28.56,0.142
189.87,28.70,0.142
189.89,28.84,0.142
189.92,28.99,0.142
189.95,29.13,0.142
189.98,29.27,0.142
190.01,29.41,0.142
190.03,29.55,0.142
190.06,29.70,0.142
190.09,29.84,0.142
190.12,29.98,0.142
190.15,30.12,0.142
190.18,30.26,0.142
190.20,30.40,0.142
190.23,30.55,0.142
190.26,30.69,0.142
190.29,30.83,0.142
190.32,30.97,0.142
190.35,31.11,0.143
190.38,31.26,0.143
190.40,31.40,0.142
190.43,31.54,0.143
190.46,31.68,0.143
190.49,31.82,0.143
190.52,31.96,0.143
190.55,32.10,0.143
190.57,32.25,0.143
190.60,32.39,0.143
190.63,32.53,0.143
190.66,32.67,0.143
190.69,32.81,0.143
190.72,32.96,0.143
190.74,33.10,0.143
190.77,33.24,0.143
190.80,33.38,0.143
190.83,33.52,0.143
190.86,33.66,0.143
190.88,33.81,0.143
190.91,33.95,0.143
190.94,34.09,0.143
190.97,34.23,0.143
191.00,34.37,0.143
191.03,34.52,0.143
191.05,34.66,0.143
191.08,34.80,0.143
191.11,34.94,0.143
191.14,35.08,0.143
191.17,35.22,0.143
191.20,35.37,0.143
191.23,35.51,0.143
191.25,35.65,0.143
191.28,35.79,0.144
191.31,35.93,0.143
191.34,36.07,0.144
191.37,36.22,0.144
191.40,36.36,0.144
191.42,36.50,0.144
191.45,36.64,0.144
191.48,36.78,0.144
191.51,36.93,0.144
191.54,37.07,0.144
191.57,37.21,0.144
191.59,37.35,0.144
191.62,37.49,0.144
191.65,37.63,0.144
191.68,37.78,0.144
191.71,37.92,0.144
191.73,38.06,0.144
191.76,38.20,0.144
191.79,38.34,0.144
191.82,38.49,0.144
191.85,38.63,0.144
191.88,38.77,0.144
191.90,38.91,0.144
191.93,39.05,0.144
191.96,39.19,0.144
191.99,39.34,0.144
192.02,39.48,0.144
192.05,39.62,0.144
192.08,39.76,0.144
192.10,39.90,0.144
192.13,40.04,0.144
192.16,40.19,0.145
192.19,40.33,0.145
192.22,40.47,0.145
192.25,40.61,0.145
192.27,40.75,0.145
192.30,40.90,0.145
192.33,41.04,0.145
192.36,41.18,0.145
192.39,41.32,0.145
192.42,41.46,0.145
192.44,41.60,0.145
192.47,41.75,0.145
192.50,41.89,0.145
192.53,42.03,0.145
192.56,42.17,0.145
192.58,42.31,0.145
192.61,42.45,0.145
192.64,42.60,0.145
192.67,42.74,0.145
192.70,42.88,0.145
192.73,43.02,0.145
192.75,43.16,0.145
192.78,43.30,0.145
192.81,43.45,0.145
192.84,43.59,0.145
192.87,43.73,0.145
192.90,43.87,0.145
192.93,44.01,0.145
192.95,44.16,0.145
192.98,44.30,0.146
193.01,44.44,0.146
193.04,44.58,0.146
193.07,44.72,0.146
193.10,44.86,0.146
193.12,45.01,0.146
193.15,45.15,0.146
193.18,45.29,0.146
193.21,45.43,0.146
193.24,45.57,0.146
193.27,45.71,0.146
193.29,45.86,0.146
193.32,46.00,0.146
193.35,46.14,0.146
193.38,46.28,0.146
193.41,46.42,0.146
193.43,46.57,0.146
193.46,46.71,0.146
193.49,46.85,0.146
193.52,46.99,0.146
193.55,47.13,0.146
193.58,47.27,0.146
193.60,47.41,0.146
193.63,47.56,0.146
193.66,47.70,0.146
193.69,47.84,0.146
193.72,47.98,0.146
193.75,48.12,0.146
193.78,48.27,0.147
193.80,48.41,0.147
193.83,48.55,0.146
193.86,48.69,0.147
193.89,48.83,0.147
193.92,48.97,0.147
193.95,49.12,0.147
193.97,49.26,0.147
194.00,49.40,0.147
194.03,49.54,0.147
194.06,49.68,0.147
194.09,49.83,0.147
194.12,49.97,0.147
194.14,50.11,0.147
194.17,50.25,0.147
194.20,50.39,0.147
194.23,50.53,0.147
194.26,50.68,0.147
194.28,50.82,0.147
194.31,50.96,0.147
194.34,51.10,0.147
194.37,51.24,0.147
194.40,51.38,0.147
194.43,51.53,0.147
194.45,51.67,0.147
194.48,51.81,0.147
194.51,51.95,0.147
194.54,52.09,0.147
194.57,52.23,0.147
194.60,52.38,0.147
194.63,52.52,0.147
194.65,52.66,0.148
194.68,52.80,0.148
194.71,52.95,0.148
194.74,53.09,0.148
194.77,53.23,0.148
194.80,53.37,0.148
194.82,53.51,0.148
194.85,53.65,0.148
194.88,53.80,0.148
194.91,53.94,0.148
194.94,54.08,0.148
194.97,54.22,0.148
194.99,54.36,0.148
195.02,54.51,0.148
195.05,54.65,0.148
195.08,54.79,0.148
195.11,54.93,0.148
195.13,55.07,0.148
195.16,55.21,0.148
195.19,55.35,0.148
195.22,55.50,0.148
195.25,55.64,0.148
195.28,55.78,0.148
195.30,55.92,0.148
195.33,56.06,0.148
195.36,56.20,0.148
195.39,56.35,0.148
195.42,56.49,0.148
195.45,56.63,0.148
195.48,56.77,0.148
195.50,56.91,0.148
195.53,57.06,0.148
195.56,57.20,0.149
195.59,57.34,0.149
195.62,57.48,0.149
195.65,57.62,0.149
195.67,57.76,0.149
195.70,57.91,0.149
195.73,58.05,0.149
195.76,58.19,0.149
195.79,58.33,0.149
195.82,58.47,0.149
195.84,58.61,0.149
195.87,58.76,0.149
195.90,58.90,0.149
195.93,59.04,0.149
195.96,59.18,0.149
195.98,59.32,0.149
196.01,59.46,0.149
196.04,59.61,0.149
196.07,59.75,0.149
196.10,59.89,0.149
196.13,60.03,0.149
196.15,60.17,0.149
196.18,60.31,0.149
196.21,60.46,0.149
196.24,60.60,0.149
196.27,60.74,0.149
196.30,60.88,0.149
196.33,61.02,0.149
196.35,61.17,0.149
196.38,61.31,0.149
196.41,61.45,0.149
196.44,61.59,0.149
196.47,61.73,0.149
196.50,61.87,0.150
196.52,62.02,0.150
196.55,62.16,0.150
196.58,62.30,0.150
196.61,62.44,0.150
196.64,62.58,0.150
196.67,62.72,0.150
196.69,62.87,0.150
196.72,63.01,0.150
196.75,63.15,0.150
196.78,63.29,0.150
196.81,63.43,0.150
196.83,63.57,0.150
196.86,63.72,0.150
196.89,63.86,0.150
196.92,64.00,0.150
196.95,64.14,0.150
196.98,64.28,0.150
197.00,64.43,0.150
197.03,64.57,0.150
197.06,64.71,0.150
197.09,64.85,0.150
197.12,64.99,0.150
197.15,65.14,0.150
197.18,65.28,0.150
197.20,65.42,0.150
197.23,65.56,0.150
197.26,65.70,0.151
197.29,65.84,0.151
197.32,65.99,0.151
197.35,66.13,0.151
197.37,66.27,0.151
197.40,66.41,0.151
197.43,66.55,0.151
197.46,66.69,0.151
197.49,66.84,0.151
197.52,66.98,0.151
197.54,67.12,0.151
197.57,67.26,0.151
197.60,67.40,0.151
197.63,67.54,0.151
197.66,67.69,0.151
197.68,67.83,0.151
197.71,67.97,0.151
197.74,68.11,0.151
197.77,68.25,0.151
197.80,68.40,0.151
197.83,68.54,0.151
197.85,68.68,0.151
197.88,68.82,0.151
197.91,68.96,0.151
197.94,69.10,0.151
197.97,69.24,0.151
198.00,69.39,0.152
198.03,69.53,0.152
198.05,69.67,0.152
198.08,69.81,0.152
198.11,69.95,0.152
198.14,70.10,0.152
198.17,70.24,0.152
198.20,70.38,0.152
198.22,70.52,0.152
198.25,70.66,0.152
198.28,70.80,0.152
198.31,70.95,0.152
198.34,71.09,0.152
198.37,71.23,0.152
198.39,71.37,0.152
198.42,71.51,0.152
198.45,71.65,0.152
198.48,71.80,0.152
198.51,71.94,0.153
198.53,72.08,0.153
198.56,72.22,0.153
198.59,72.36,0.153
198.62,72.51,0.153
198.65,72.65,0.153
198.68,72.79,0.153
198.70,72.93,0.153
198.73,73.07,0.153
198.76,73.21,0.153
198.79,73.36,0.153
198.82,73.50,0.153
198.85,73.64,0.153
198.88,73.78,0.153
198.90,73.92,0.153
198.93,74.06,0.153
198.96,74.21,0.153
198.99,74.35,0.154
199.02,74.49,0.154
199.05,74.63,0.154
199.07,74.77,0.154
199.10,74.91,0.154
199.13,75.06,0.154
199.16,75.20,0.154
199.19,75.34,0.154
199.22,75.48,0.154
199.24,75.62,0.154
199.27,75.77,0.154
199.30,75.91,0.154
199.33,76.05,0.154
199.36,76.19,0.154
199.38,76.33,0.154
199.41,76.47,0.155
199.44,76.62,0.155
199.47,76.76,0.155
199.50,76.90,0.155
199.53,77.04,0.155
199.55,77.18,0.155
199.58,77.32,0.155
199.61,77.47,0.155
199.64,77.61,0.155
199.67,77.75,0.155
199.70,77.89,0.155
199.73,78.03,0.155
199.75,78.17,0.155
199.78,78.32,0.155
199.81,78.46,0.155
199.84,78.60,0.155
199.87,78.74,0.155
199.90,78.88,0.155
199.92,79.02,0.156
199.95,79.17,0.156
199.98,79.31,0.156
200.01,79.45,0.156
200.04,79.59,0.156
200.07,79.73,0.156
200.09,79.87,0.156
200.12,80.02,0.156
200.15,80.16,0.156
200.18,80.30,0.156
200.21,80.44,0.156
200.23,80.58,0.156
200.26,80.73,0.156
200.29,80.87,0.157
200.32,81.01,0.157
200.35,81.15,0.157
200.38,81.29,0.157
200.40,81.43,0.157
200.43,81.58,0.157
200.46,81.72,0.157
200.49,81.86,0.157
200.52,82.00,0.157
200.55,82.14,0.157
200.58,82.29,0.157
200.60,82.43,0.157
200.63,82.57,0.158
200.66,82.71,0.158
200.69,82.85,0.158
200.72,82.99,0.158
200.75,83.13,0.158
200.77,83.27,0.158
200.80,83.42,0.158
200.83,83.56,0.158
200.86,83.70,0.158
200.89,83.84,0.158
200.92,83.98,0.158
200.94,84.13,0.158
200.97,84.27,0.158
201.00,84.41,0.158
201.03,84.55,0.158
201.06,84.69,0.158
201.08,84.84,0.159
201.11,84.98,0.159
201.14,85.12,0.159
201.17,85.26,0.159
201.20,85.40,0.159
201.23,85.54,0.159
201.25,85.69,0.159
201.28,85.83,0.159
201.31,85.97,0.159
201.34,86.11,0.159
201.37,86.25,0.159
201.40,86.40,0.160
201.43,86.54,0.160
201.45,86.68,0.160
201.48,86.82,0.160
201.51,86.96,0.160
201.54,87.10,0.160
201.57,87.24,0.160
201.60,87.39,0.160
201.62,87.53,0.160
201.65,87.67,0.160
201.68,87.81,0.160
201.71,87.95,0.160
201.74,88.09,0.160
201.77,88.24,0.161
201.79,88.38,0.161
201.82,88.52,0.161
201.85,88.66,0.161
201.88,88.80,0.161
201.91,88.94,0.161
201.93,89.09,0.161
201.96,89.23,0.161
201.99,89.37,0.161
202.02,89.51,0.161
202.05,89.65,0.161
202.08,89.80,0.161
202.10,89.94,0.161
202.13,90.08,0.161
202.16,90.22,0.161
202.19,90.36,0.162
202.22,90.50,0.162
202.25,90.65,0.162
202.28,90.79,0.162
202.30,90.93,0.162
202.33,91.07,0.162
202.36,91.21,0.162
202.39,91.35,0.162
202.42,91.50,0.162
202.45,91.64,0.162
202.47,91.78,0.162
202.50,91.92,0.162
202.53,92.06,0.163
202.56,92.20,0.163
202.59,92.35,0.163
202.62,92.49,0.163
202.64,92.63,0.163
202.67,92.77,0.163
202.70,92.91,0.163
202.73,93.05,0.163
202.76,93.20,0.163
202.78,93.34,0.163
202.81,93.48,0.163
202.84,93.62,0.163
202.87,93.76,0.163
202.90,93.91,0.164
202.93,94.05,0.164
202.95,94.19,0.164
202.98,94.33,0.164
203.01,94.47,0.164
203.04,94.61,0.164
203.07,94.76,0.164
203.10,94.90,0.164
203.13,95.04,0.164
203.15,95.18,0.164
203.18,95.32,0.164
203.21,95.46,0.164
203.24,95.61,0.164
203.27,95.75,0.164
203.30,95.89,0.164
203.32,96.03,0.164
203.35,96.17,0.164
203.38,96.31,0.164
203.41,96.46,0.165
203.44,96.60,0.165
203.47,96.74,0.165
203.49,96.88,0.165
203.52,97.02,0.165
203.55,97.17,0.165
203.58,97.31,0.165
203.61,97.45,0.165
203.63,97.59,0.165
203.66,97.73,0.165
203.69,97.87,0.165
203.72,98.01,0.165
203.75,98.16,0.165
203.78,98.30,0.165
203.80,98.44,0.165
203.83,98.58,0.165
203.86,98.72,0.165
203.89,98.87,0.165
203.92,99.01,0.166
203.95,99.15,0.166
203.98,99.29,0.166
204.00,99.43,0.166
204.03,99.57,0.166
204.06,99.72,0.166
204.09,99.86,0.166
204.12,100.00,0.166
204.15,100.14,0.166
204.17,100.28,0.166
204.20,100.43,0.166
204.23,100.57,0.167
204.26,100.71,0.167
204.29,100.85,0.167
204.32,100.99,0.167
204.34,101.13,0.167
204.37,101.28,0.167
204.40,101.42,0.167
204.43,101.56,0.167
204.46,101.70,0.167
204.48,101.84,0.167
204.51,101.98,0.167
204.54,102.12,0.167
204.57,102.27,0.167
204.60,102.41,0.167
204.63,102.55,0.167
204.65,102.69,0.167
204.68,102.83,0.167
204.71,102.97,0.167
204.74,103.12,0.167
204.77,103.26,0.167
204.80,103.40,0.167
204.83,103.54,0.167
204.85,103.68,0.167
204.88,103.83,0.168
204.91,103.97,0.168
204.94,104.11,0.168
204.97,104.25,0.168
205.00,104.39,0.168
205.02,104.53,0.168
205.05,104.68,0.168
205.08,104.82,0.168
205.11,104.96,0.168
205.14,105.10,0.168
205.17,105.24,0.168
205.19,105.38,0.168
205.22,105.53,0.168
205.25,105.67,0.168
205.28,105.81,0.169
205.31,105.95,0.169
205.33,106.09,0.169
205.36,106.24,0.169
205.39,106.38,0.169
205.42,106.52,0.169
205.45,106.66,0.169
205.48,106.80,0.169
205.50,106.94,0.169
205.53,107.09,0.169
205.56,107.23,0.169
205.59,107.37,0.169
205.62,107.51,0.169
205.65,107.65,0.170
205.68,107.79,0.170
205.70,107.94,0.170
205.73,108.08,0.170
205.76,108.22,0.170
205.79,108.36,0.170
205.82,108.50,0.170
205.85,108.64,0.170
205.87,108.79,0.170
205.90,108.93,0.170
205.93,109.07,0.170
205.96,109.21,0.170
205.99,109.35,0.170
206.02,109.49,0.170
206.04,109.64,0.170
206.07,109.78,0.170
206.10,109.92,0.170
206.13,110.06,0.170
206.16,110.20,0.171
206.18,110.35,0.171
206.21,110.49,0.171
206.24,110.63,0.171
206.27,110.77,0.171
206.30,110.91,0.171
206.33,111.05,0.171
206.35,111.20,0.171
206.38,111.34,0.171
206.41,111.48,0.171
206.44,111.62,0.171
206.47,111.76,0.171
206.50,111.91,0.171
206.53,112.04,0.171
206.55,112.19,0.171
206.58,112.33,0.171
206.61,112.47,0.171
206.64,112.61,0.171
206.67,112.75,0.172
206.70,112.89,0.172
206.72,113.04,0.172
206.75,113.18,0.172
206.78,113.32,0.172
206.81,113.46,0.172
206.84,113.60,0.172
206.87,113.74,0.172
206.89,113.89,0.172
206.92,114.03,0.172
206.95,114.17,0.172
206.98,114.31,0.172
207.01,114.45,0.172
207.03,114.59,0.172
207.06,114.74,0.172
207.09,114.88,0.173
207.12,115.02,0.173
207.15,115.16,0.173
207.18,115.30,0.173
207.20,115.45,0.173
207.23,115.59,0.173
207.26,115.73,0.173
207.29,115.87,0.173
207.32,116.01,0.173
207.35,116.16,0.173
207.38,116.30,0.173
207.40,116.44,0.173
207.43,116.58,0.173
207.46,116.72,0.173
207.49,116.86,0.174
207.52,117.01,0.174
207.55,117.15,0.174
207.57,117.29,0.174
207.60,117.43,0.174
207.63,117.57,0.174
207.66,117.71,0.174
207.69,117.85,0.174
207.72,118.00,0.174
207.74,118.14,0.174
207.77,118.28,0.174
207.80,118.42,0.174
207.83,118.56,0.174
207.86,118.70,0.174
207.88,118.85,0.174
207.91,118.99,0.174
207.94,119.13,0.174
207.97,119.27,0.175
208.00,119.42,0.175
208.03,119.56,0.175
208.05,119.70,0.175
208.08,119.84,0.175
208.11,119.98,0.175
208.14,120.12,0.175
208.17,120.26,0.175
208.20,120.41,0.175
208.23,120.55,0.175
208.25,120.69,0.175
208.28,120.83,0.176
208.31,120.97,0.176
208.34,121.12,0.176
208.37,121.26,0.176
208.40,121.40,0.176
208.42,121.54,0.176
208.45,121.68,0.176
208.48,121.82,0.176
208.51,121.97,0.176
208.54,122.11,0.176
208.57,122.25,0.176
208.59,122.39,0.177
208.62,122.53,0.177
208.65,122.67,0.176
208.68,122.81,0.177
208.71,122.96,0.176
208.73,123.10,0.177
208.76,123.24,0.177
208.79,123.38,0.177
208.82,123.52,0.177
208.85,123.66,0.177
208.88,123.81,0.177
208.90,123.95,0.177
208.93,124.09,0.177
208.96,124.23,0.178
208.99,124.37,0.178
209.02,124.52,0.178
209.05,124.66,0.178
209.08,124.80,0.178
209.10,124.94,0.178
209.13,125.08,0.178
209.16,125.22,0.178
209.19,125.37,0.178
209.22,125.51,0.178
209.25,125.65,0.179
209.27,125.80,0.179
209.30,125.94,0.179
209.33,126.08,0.179
209.36,126.22,0.179
209.39,126.36,0.179
209.42,126.51,0.179
209.44,126.65,0.179
209.47,126.79,0.179
209.50,126.93,0.179
209.53,127.07,0.179
209.56,127.21,0.179
209.58,127.35,0.179
209.61,127.50,0.179
209.64,127.64,0.179
209.67,127.78,0.179
209.70,127.92,0.179
209.73,128.06,0.179
209.75,128.20,0.179
209.78,128.34,0.178
209.81,128.49,0.179
209.84,128.63,0.179
209.87,128.77,0.179
209.90,128.91,0.179
209.93,129.05,0.179
209.95,129.19,0.179
209.98,129.33,0.179
210.01,129.48,0.179
210.04,129.62,0.179
210.07,129.76,0.179
210.10,129.90,0.179
210.12,130.04,0.179
210.15,130.18,0.179
210.18,130.33,0.180
210.21,130.47,0.180
210.24,130.61,0.180
210.27,130.75,0.180
210.29,130.89,0.180
210.32,131.03,0.180
210.35,131.18,0.180
210.38,131.32,0.180
210.41,131.46,0.180
210.43,131.60,0.180
210.46,131.74,0.181
210.49,131.89,0.181
210.52,132.03,0.181
210.55,132.17,0.181
210.58,132.31,0.181
210.60,132.45,0.181
210.63,132.59,0.181
210.66,132.73,0.181
210.69,132.88,0.181
210.72,133.02,0.181
210.75,133.16,0.181
210.78,133.30,0.182
210.80,133.44,0.182
210.83,133.59,0.182
210.86,133.73,0.182
210.89,133.87,0.182
210.92,134.01,0.182
210.95,134.15,0.182
210.97,134.30,0.182
211.00,134.44,0.182
211.03,134.58,0.183
211.06,134.72,0.183
211.09,134.86,0.183
211.12,135.00,0.183
211.14,135.14,0.183
211.17,135.28,0.183
211.20,135.43,0.183
211.23,135.57,0.183
211.26,135.71,0.183
211.28,135.85,0.183
211.31,135.99,0.183
211.34,136.13,0.183
211.37,136.28,0.183
211.40,136.42,0.183
211.43,136.56,0.183
211.45,136.70,0.184
211.48,136.84,0.184
211.51,136.98,0.184
211.54,137.12,0.184
211.57,137.27,0.184
211.60,137.41,0.184
211.63,137.55,0.184
211.65,137.69,0.184
211.68,137.83,0.184
211.71,137.98,0.185
211.74,138.12,0.185
211.77,138.26,0.185
211.80,138.40,0.185
211.82,138.54,0.185
211.85,138.69,0.185
211.88,138.83,0.186
211.91,138.97,0.186
211.94,139.11,0.186
211.97,139.25,0.186
211.99,139.39,0.186
212.02,139.53,0.186
212.05,139.68,0.186
212.08,139.82,0.186
212.11,139.96,0.186
212.13,140.10,0.186
212.16,140.24,0.186
212.19,140.39,0.186
212.22,140.53,0.186
212.25,140.67,0.186
212.28,140.81,0.187
212.30,140.95,0.187
212.33,141.09,0.187
212.36,141.24,0.187
212.39,141.38,0.187
212.42,141.52,0.187
212.45,141.66,0.187
212.48,141.80,0.187
212.50,141.94,0.187
212.53,142.08,0.187
212.56,142.23,0.187
212.59,142.37,0.187
212.62,142.51,0.187
212.65,142.65,0.187
212.67,142.79,0.187
212.70,142.93,0.187
212.73,143.08,0.187
212.76,143.22,0.187
212.79,143.36,0.187
212.82,143.50,0.187
212.84,143.64,0.187
212.87,143.78,0.187
212.90,143.93,0.187
212.93,144.07,0.187
212.96,144.21,0.187
212.98,144.35,0.187
213.01,144.50,0.187
213.04,144.64,0.188
213.07,144.78,0.188
213.10,144.92,0.188
213.13,145.06,0.188
213.15,145.20,0.188
213.18,145.34,0.187
213.21,145.49,0.187
213.24,145.63,0.187
213.27,145.77,0.187
213.30,145.91,0.187
213.33,146.05,0.187
213.35,146.19,0.187
213.38,146.34,0.187
213.41,146.48,0.187
213.44,146.62,0.187
213.47,146.76,0.187
213.50,146.90,0.187
213.52,147.04,0.187
213.55,147.19,0.187
213.58,147.33,0.187
213.61,147.47,0.187
213.64,147.61,0.187
213.67,147.75,0.187
213.69,147.90,0.187
213.72,148.04,0.187
213.75,148.18,0.187
213.78,148.32,0.187
213.81,148.46,0.187
213.83,148.61,0.187
213.86,148.75,0.187
213.89,148.89,0.187
213.92,149.03,0.187
213.95,149.17,
213.98,149.31,
213.98,,