File: DSC/2025_07_01_Succinic_Acid_n60_200_10C_min_x4.csv
Filename,2025_07_01_Succinic_Acid_n60_200_10C_min_x4
Instrument name,DSC2A-00468 (192.168.1.100)
Operator,Gibbons
rundate,7/2/2025
Sample name,2025_07_01_Succinic_Acid_n60_200_10C_min_x4
proceduresegments,Data Off ; Equilibrate -60.00 °C; Data On ; Ramp 10.00 °C/min to 200.00 °C; Data Off ; Isothermal 2.0 min; Data On ; Ramp 10.00 °C/min to -60.00 °C; Data Off ; Isothermal 2.0 min; Data On ; Ramp 10.00 °C/min to 200.00 °C; Data Off ; Isothermal 2.0 min; Data On ; Ramp 10.00 °C/min to -60.00 °C; Data Off ; Isothermal 2.0 min; Data On ; Ramp 10.00 °C/min to 200.00 °C; Data Off ; Isothermal 2.0 min; Data On ; Ramp 10.00 °C/min to -60.00 °C; Data Off ; Isothermal 2.0 min; Data On ; Ramp 10.00 °C/min to 30.00 °C
[File Parameters]
Run date,7/2/2025 12:57:31 AM
Trios version,5.1.1.46572
Original File Name,
Current File Name,D:\DSC2500\Gibbons\2025_07_01_Succinic_Acid_n60_200_10C_min_x4.tri
[Procedure]
Procedure Name,Succinic_Acid_n60_200_10C_min_x4
Sample Name,2025_07_01_Succinic_Acid_n60_200_10C_min_x4
Sample Mass,6.35 mg
Reference Sample Mass,0 mg
Pan Mass,57.31 mg
Pan Number,15
Reference Pan Mass,57.15 mg
Reference Pan Number,28
Pan Type,Tzero Aluminum Hermetic
Comments,DSC Consumables Al Hermetically Sealed Pan. Y1 Tray (Google Sheet: DSC_Samples_Y1_Tray_June2025).
Project Name,Pharma - Cocrystals
Operator,Gibbons
Test,Custom
Unload Max Temperature,30
Unload Min Temperature,30
Load Max Temperature,30
Load Min Temperature,30
Stop on Gas Flow Error,Yes
[Signal List]
Signal #1,Time (min)
Signal #2,Temperature (°C)
Signal #3,Heat Flow (mW)
Signal #4,Delta T (µV)
Signal #5,Delta Tzero (µV)
Signal #6,Tzero Temperature (°C)
Signal #7,Cell Purge (mL/min)
Signal #8,Heater Temp (°C)
Signal #9,Power Delivered (W)
Signal #10,Reference Junction Temperature (°C)
Signal #11,Flange Temperature (°C)
Signal #12,Heat Flow Phase (rad)
Signal #13,Total Heat Capacity (J/°C)
Signal #14,Heat Capacity (J/°C)
[Configuration]
Company Name,ASU
Instrument Name,DSC2A-00468
Instrument Type,DSC2500
Serial Number,DSC2A-00468
IP,192.168.1.100
Location of Instrument,MRRC
DisplayType,Unknown
Sample Interval ,0.1 s/pt
Selected Heat Flow,T4P
Exotherm Direction,Down
Cell Serial,DRC2-00792
Lid Type,Standard
Cooler,RCS 90
Leave Cooler on at End of Sequence,On
Gas 2,Nitrogen
Gas Selected,Channel 1
Flow Rate,50 mL/min
Secondary Purge,On
Licensed Heat Flow,Heat Flow T4P
Modulation Licensed,Yes
[Versions]
Common IDD Version,1
Cortex Version,VER 2.10.2.31
Driver,5.0.0.6
GDM Version,1.0.3.3
TouchscreenVersion,1.0.0.16145
FEP Version,1.2.1.21
FEP Bootloader,2.0.0.5
AutoSampler Version,2.1.1.26
Auto Sampler Bootloader,2.0.0.5
FCM Version,1.1.0.3
FCM Bootloader,2.0.0.5
[Experiment Logs]
Experiment Log Entry # 1,Data On set to 0
Experiment Log Entry # 3,Equilibrate Segment -60 (C) Started
Experiment Log Entry # 5,Air Cool is off.
Experiment Log Entry # 7,Data On set to 1
Experiment Log Entry # 9,Ramp Segment 10 C/min to 200 Started
Experiment Log Entry # 11,Data On set to 0
Experiment Log Entry # 13,Isothermal Segment 2 min started
Experiment Log Entry # 15,Data On set to 1
Experiment Log Entry # 17,Ramp Segment 10 C/min to -60 Started
Experiment Log Entry # 19,Data On set to 0
Experiment Log Entry # 21,Isothermal Segment 2 min started
Experiment Log Entry # 23,Data On set to 1
Experiment Log Entry # 25,Ramp Segment 10 C/min to 200 Started
Experiment Log Entry # 27,Data On set to 0
Experiment Log Entry # 29,Isothermal Segment 2 min started
Experiment Log Entry # 31,Data On set to 1
Experiment Log Entry # 33,Ramp Segment 10 C/min to -60 Started
Experiment Log Entry # 35,Data On set to 0
Experiment Log Entry # 37,Isothermal Segment 2 min started
Experiment Log Entry # 39,Data On set to 1
Experiment Log Entry # 41,Ramp Segment 10 C/min to 200 Started
Experiment Log Entry # 43,Data On set to 0
Experiment Log Entry # 45,Isothermal Segment 2 min started
Experiment Log Entry # 47,Data On set to 1
Experiment Log Entry # 49,Ramp Segment 10 C/min to -60 Started
Experiment Log Entry # 51,Data On set to 0
Experiment Log Entry # 53,Isothermal Segment 2 min started
Experiment Log Entry # 55,Data On set to 1
Experiment Log Entry # 57,Ramp Segment 10 C/min to 30 Started
[Method Log]
Method Log Entry # 1,Data Off
Method Log Entry # 2,Equilibrate -60 °C
Method Log Entry # 3,Data On
Method Log Entry # 4,(Ramp 1101419) Ramp 10 °C/minute to 200 °C
Method Log Entry # 5,Data Off
Method Log Entry # 6,Isothermal 2 minutes
Method Log Entry # 7,Data On
Method Log Entry # 8,(Ramp 1101423) Ramp 10 °C/minute to -60 °C
Method Log Entry # 9,Data Off
Method Log Entry # 10,Isothermal 2 minutes
Method Log Entry # 11,Data On
Method Log Entry # 12,(Ramp 1101427) Ramp 10 °C/minute to 200 °C
Method Log Entry # 13,Data Off
Method Log Entry # 14,Isothermal 2 minutes
Method Log Entry # 15,Data On
Method Log Entry # 16,(Ramp 1101431) Ramp 10 °C/minute to -60 °C
Method Log Entry # 17,Data Off
Method Log Entry # 18,Isothermal 2 minutes
Method Log Entry # 19,Data On
Method Log Entry # 20,(Ramp 1101435) Ramp 10 °C/minute to 200 °C
Method Log Entry # 21,Data Off
Method Log Entry # 22,Isothermal 2 minutes
Method Log Entry # 23,Data On
Method Log Entry # 24,(Ramp 1101439) Ramp 10 °C/minute to -60 °C
Method Log Entry # 25,Data Off
Method Log Entry # 26,Isothermal 2 minutes
Method Log Entry # 27,Data On
Method Log Entry # 28,(Ramp 1101443) Ramp 10 °C/minute to 30 °C
Cell Serial,DRC2-00792
[T1 Calibration]
Slope,-0.008529666
Offset,9.636258
Initial Temperature,98.23
GUID,f8bfdadc-4977-4fdf-ba6d-0ba9134940c3
[TZero Calibration]
Date Applied,11/29/2022 4:06:13 PM
Description,From -89.059 °C to 396.009 °C at 20.000°C/min
Gas Type,Nitrogen
Pan Type,None
Source Files 1,C:\Users\yargerlab\Desktop\DSC Data\General\TZero_calibration_11_29_22_2nd(2).tri
Source Files 2,C:\Users\yargerlab\Desktop\DSC Data\General\TZero_calibration_11_29_22_2nd(3).tri
Delta T Offset,13.05235
Delta T Slope,-0.007271007
Delta T0 Offset,-13.69128
Delta T0 Slope,0.06063341
[Temperature Calibration]
Date Applied,11/29/2022 7:12:28 PM
Description,From 106.590 °C to 186.590 °C at 10.000°C/min
Gas Type,Nitrogen
Pan Type,Tzero Aluminum Hermetic
Source Files 1,C:\Users\yargerlab\Desktop\DSC Data\General\Indium(6).tri
Measured 1,157.391
Known 1,156.598
[Cell Constant Calibration]
Date Applied,11/29/2022 7:12:29 PM
Description,From 106.590 °C to 186.590 °C at 10.000°C/min
Gas Type,Nitrogen
Pan Type,Tzero Aluminum Hermetic
Source Files 1,C:\Users\yargerlab\Desktop\DSC Data\General\Indium(6).tri
T4P KCell,1.006051
Onset Slope,63.26126 mW/°C
[Direct Cp Calibration]
Date Applied,11/30/2022 11:04:51 AM
Description,From -79.983 °C to 298.409 °C at 10.000°C/min
Gas Type,Nitrogen
Pan Type,Tzero Aluminum Hermetic
Source Files 1,C:\Users\yargerlab\Desktop\DSC Data\General\Sapphire_Heat_Capacity_11_30_22.tri
[Rev Cp Calibration]
Date Applied,11/30/2022 1:58:51 PM
Description,From -79.996 °C to 292.812 °C at 3.000°C/min
Gas Type,Nitrogen
Pan Type,Tzero Aluminum Hermetic
Source Files 1,C:\Users\yargerlab\Desktop\DSC Data\General\Sapphire_MDSC_Calibration_11_30_22.tri
[step]
Ramp 10.00 °C/min to 200.00 °C
Time,Temperature,Heat Flow (Normalized)
min,°C,W/g
0.00,-59.69,-0.065
0.02,-59.70,-0.062
0.04,-59.71,-0.056
0.05,-59.71,-0.055
0.07,-59.69,-0.057
0.09,-59.66,-0.059
0.11,-59.60,-0.061
0.13,-59.53,-0.060
0.15,-59.43,-0.044
0.16,-59.33,-0.026
0.18,-59.21,-0.003
0.20,-59.08,0.020
0.22,-58.95,0.043
0.24,-58.80,0.065
0.26,-58.66,0.081
0.28,-58.51,0.099
0.29,-58.35,0.113
0.31,-58.19,0.125
0.33,-58.03,0.135
0.35,-57.86,0.144
0.37,-57.70,0.154
0.39,-57.53,0.159
0.40,-57.36,0.166
0.42,-57.19,0.170
0.44,-57.02,0.176
0.46,-56.85,0.179
0.48,-56.67,0.184
0.50,-56.50,0.185
0.51,-56.32,0.189
0.53,-56.15,0.192
0.55,-55.97,0.193
0.57,-55.79,0.195
0.59,-55.62,0.197
0.60,-55.44,0.198
0.62,-55.26,0.199
0.64,-55.08,0.200
0.66,-54.90,0.201
0.68,-54.72,0.202
0.70,-54.55,0.202
0.72,-54.37,0.203
0.73,-54.18,0.204
0.75,-54.00,0.205
0.77,-53.82,0.205
0.79,-53.65,0.205
0.81,-53.46,0.206
0.83,-53.28,0.207
0.84,-53.10,0.207
0.86,-52.92,0.207
0.88,-52.74,0.208
0.90,-52.56,0.208
0.92,-52.38,0.208
0.93,-52.20,0.208
0.95,-52.01,0.209
0.97,-51.83,0.209
0.99,-51.65,0.209
1.01,-51.47,0.209
1.03,-51.29,0.210
1.05,-51.11,0.210
1.06,-50.92,0.210
1.08,-50.74,0.210
1.10,-50.56,0.211
1.12,-50.38,0.211
1.14,-50.19,0.211
1.16,-50.01,0.211
1.17,-49.83,0.212
1.19,-49.65,0.212
1.21,-49.46,0.212
1.23,-49.28,0.212
1.25,-49.10,0.212
1.27,-48.92,0.212
1.28,-48.73,0.213
1.30,-48.55,0.213
1.32,-48.37,0.213
1.34,-48.19,0.213
1.36,-48.00,0.213
1.38,-47.82,0.213
1.39,-47.64,0.214
1.41,-47.45,0.214
1.43,-47.27,0.214
1.45,-47.09,0.214
1.47,-46.90,0.214
1.48,-46.72,0.214
1.50,-46.54,0.215
1.52,-46.35,0.215
1.54,-46.17,0.215
1.56,-45.99,0.215
1.58,-45.81,0.215
1.59,-45.62,0.215
1.61,-45.44,0.215
1.63,-45.26,0.215
1.65,-45.07,0.215
1.67,-44.89,0.216
1.69,-44.70,0.216
1.71,-44.52,0.216
1.72,-44.34,0.216
1.74,-44.15,0.216
1.76,-43.97,0.216
1.78,-43.79,0.216
1.80,-43.60,0.216
1.82,-43.42,0.216
1.83,-43.24,0.216
1.85,-43.05,0.217
1.87,-42.87,0.217
1.89,-42.69,0.217
1.91,-42.50,0.217
1.93,-42.32,0.217
1.94,-42.14,0.217
1.96,-41.95,0.217
1.98,-41.77,0.217
2.00,-41.59,0.217
2.02,-41.40,0.217
2.03,-41.22,0.217
2.05,-41.04,0.218
2.07,-40.85,0.218
2.09,-40.67,0.218
2.11,-40.49,0.218
2.13,-40.30,0.218
2.14,-40.12,0.218
2.16,-39.94,0.218
2.18,-39.75,0.218
2.20,-39.57,0.218
2.22,-39.38,0.218
2.24,-39.20,0.218
2.26,-39.02,0.218
2.27,-38.84,0.219
2.29,-38.65,0.219
2.31,-38.47,0.219
2.33,-38.28,0.219
2.35,-38.10,0.219
2.36,-37.92,0.219
2.38,-37.73,0.219
2.40,-37.55,0.219
2.42,-37.37,0.219
2.44,-37.18,0.219
2.46,-37.00,0.219
2.48,-36.82,0.220
2.49,-36.63,0.220
2.51,-36.45,0.220
2.53,-36.27,0.220
2.55,-36.08,0.220
2.57,-35.90,0.220
2.59,-35.71,0.220
2.60,-35.53,0.220
2.62,-35.35,0.220
2.64,-35.16,0.220
2.66,-34.98,0.220
2.68,-34.80,0.220
2.69,-34.61,0.220
2.71,-34.43,0.220
2.73,-34.24,0.221
2.75,-34.06,0.221
2.77,-33.88,0.221
2.79,-33.69,0.221
2.81,-33.51,0.221
2.82,-33.33,0.221
2.84,-33.14,0.221
2.86,-32.96,0.221
2.88,-32.78,0.221
2.90,-32.59,0.221
2.91,-32.41,0.221
2.93,-32.22,0.221
2.95,-32.04,0.221
2.97,-31.86,0.221
2.99,-31.67,0.222
3.01,-31.49,0.222
3.03,-31.31,0.222
3.04,-31.12,0.222
3.06,-30.94,0.222
3.08,-30.76,0.222
3.10,-30.57,0.222
3.12,-30.39,0.222
3.14,-30.21,0.222
3.15,-30.02,0.222
3.17,-29.84,0.222
3.19,-29.65,0.222
3.21,-29.47,0.222
3.23,-29.29,0.223
3.24,-29.10,0.223
3.26,-28.92,0.223
3.28,-28.74,0.223
3.30,-28.55,0.223
3.32,-28.37,0.223
3.34,-28.18,0.223
3.36,-28.00,0.223
3.37,-27.82,0.223
3.39,-27.63,0.223
3.41,-27.45,0.223
3.43,-27.27,0.223
3.45,-27.08,0.224
3.46,-26.90,0.224
3.48,-26.72,0.224
3.50,-26.53,0.224
3.52,-26.35,0.224
3.54,-26.17,0.224
3.56,-25.98,0.224
3.58,-25.80,0.224
3.59,-25.61,0.224
3.61,-25.43,0.224
3.63,-25.25,0.224
3.65,-25.06,0.225
3.67,-24.88,0.225
3.69,-24.70,0.225
3.70,-24.51,0.225
3.72,-24.33,0.225
3.74,-24.15,0.225
3.76,-23.96,0.225
3.78,-23.78,0.225
3.79,-23.60,0.225
3.81,-23.41,0.225
3.83,-23.23,0.226
3.85,-23.04,0.226
3.87,-22.86,0.226
3.89,-22.68,0.226
3.91,-22.49,0.226
3.92,-22.31,0.226
3.94,-22.13,0.226
3.96,-21.94,0.226
3.98,-21.76,0.226
4.00,-21.57,0.226
4.01,-21.39,0.227
4.03,-21.21,0.227
4.05,-21.02,0.227
4.07,-20.84,0.227
4.09,-20.66,0.227
4.11,-20.47,0.227
4.13,-20.29,0.227
4.14,-20.11,0.227
4.16,-19.92,0.227
4.18,-19.74,0.227
4.20,-19.56,0.227
4.22,-19.37,0.228
4.24,-19.19,0.228
4.25,-19.01,0.228
4.27,-18.82,0.228
4.29,-18.64,0.228
4.31,-18.46,0.228
4.33,-18.27,0.228
4.35,-18.09,0.228
4.36,-17.91,0.228
4.38,-17.72,0.228
4.40,-17.54,0.228
4.42,-17.36,0.228
4.44,-17.17,0.229
4.45,-16.99,0.229
4.47,-16.81,0.229
4.49,-16.62,0.229
4.51,-16.44,0.229
4.53,-16.26,0.229
4.55,-16.07,0.229
4.56,-15.89,0.229
4.58,-15.70,0.229
4.60,-15.52,0.230
4.62,-15.34,0.230
4.64,-15.15,0.230
4.66,-14.97,0.230
4.68,-14.79,0.230
4.69,-14.60,0.230
4.71,-14.42,0.231
4.73,-14.24,0.231
4.75,-14.05,0.231
4.77,-13.87,0.231
4.79,-13.68,0.231
4.80,-13.50,0.231
4.82,-13.32,0.231
4.84,-13.13,0.231
4.86,-12.95,0.231
4.88,-12.77,0.232
4.90,-12.58,0.232
4.91,-12.40,0.232
4.93,-12.22,0.232
4.95,-12.03,0.232
4.97,-11.85,0.232
4.99,-11.66,0.232
5.00,-11.48,0.232
5.02,-11.30,0.232
5.04,-11.11,0.233
5.06,-10.93,0.233
5.08,-10.75,0.233
5.10,-10.56,0.233
5.11,-10.38,0.233
5.13,-10.20,0.233
5.15,-10.01,0.233
5.17,-9.83,0.234
5.19,-9.64,0.234
5.21,-9.46,0.234
5.23,-9.28,0.234
5.24,-9.10,0.234
5.26,-8.91,0.234
5.28,-8.73,0.235
5.30,-8.54,0.235
5.32,-8.36,0.235
5.34,-8.18,0.235
5.35,-7.99,0.235
5.37,-7.81,0.235
5.39,-7.63,0.235
5.41,-7.44,0.236
5.43,-7.26,0.236
5.45,-7.08,0.236
5.46,-6.89,0.236
5.48,-6.71,0.236
5.50,-6.53,0.237
5.52,-6.34,0.237
5.54,-6.16,0.237
5.55,-5.97,0.237
5.57,-5.79,0.238
5.59,-5.61,0.238
5.61,-5.42,0.238
5.63,-5.24,0.239
5.65,-5.06,0.239
5.66,-4.88,0.240
5.68,-4.69,0.241
5.70,-4.51,0.242
5.72,-4.32,0.243
5.74,-4.14,0.245
5.76,-3.96,0.247
5.78,-3.78,0.249
5.79,-3.59,0.251
5.81,-3.41,0.256
5.83,-3.23,0.260
5.85,-3.05,0.264
5.87,-2.86,0.273
5.89,-2.68,0.278
5.90,-2.50,0.277
5.92,-2.32,0.275
5.94,-2.13,0.269
5.96,-1.95,0.264
5.98,-1.76,0.263
6.00,-1.58,0.263
6.01,-1.40,0.261
6.03,-1.21,0.256
6.05,-1.03,0.253
6.07,-0.84,0.251
6.09,-0.66,0.250
6.10,-0.47,0.249
6.12,-0.29,0.249
6.14,-0.10,0.248
6.16,0.08,0.248
6.18,0.26,0.248
6.20,0.45,0.247
6.21,0.63,0.247
6.23,0.82,0.246
6.25,1.00,0.246
6.27,1.18,0.246
6.29,1.37,0.246
6.31,1.55,0.246
6.33,1.74,0.245
6.34,1.92,0.245
6.36,2.10,0.245
6.38,2.29,0.245
6.40,2.47,0.245
6.42,2.65,0.245
6.44,2.84,0.245
6.45,3.02,0.244
6.47,3.21,0.244
6.49,3.39,0.244
6.51,3.57,0.244
6.53,3.76,0.244
6.55,3.94,0.244
6.56,4.13,0.244
6.58,4.31,0.244
6.60,4.49,0.244
6.62,4.68,0.244
6.64,4.86,0.244
6.65,5.04,0.244
6.67,5.23,0.244
6.69,5.41,0.244
6.71,5.59,0.244
6.73,5.78,0.244
6.75,5.96,0.244
6.76,6.14,0.244
6.78,6.33,0.244
6.80,6.51,0.245
6.82,6.69,0.245
6.84,6.88,0.245
6.86,7.06,0.245
6.88,7.25,0.245
6.89,7.43,0.245
6.91,7.61,0.245
6.93,7.79,0.245
6.95,7.98,0.245
6.97,8.16,0.245
6.99,8.35,0.245
7.00,8.53,0.246
7.02,8.71,0.246
7.04,8.90,0.246
7.06,9.08,0.246
7.08,9.26,0.246
7.10,9.45,0.246
7.11,9.63,0.246
7.13,9.81,0.246
7.15,10.00,0.246
7.17,10.18,0.247
7.19,10.36,0.247
7.20,10.55,0.247
7.22,10.73,0.247
7.24,10.92,0.247
7.26,11.10,0.247
7.28,11.28,0.247
7.30,11.47,0.247
7.31,11.65,0.247
7.33,11.83,0.248
7.35,12.02,0.248
7.37,12.20,0.248
7.39,12.38,0.248
7.41,12.57,0.248
7.43,12.75,0.248
7.44,12.93,0.248
7.46,13.12,0.249
7.48,13.30,0.249
7.50,13.49,0.249
7.52,13.67,0.249
7.54,13.85,0.249
7.55,14.04,0.249
7.57,14.22,0.249
7.59,14.40,0.250
7.61,14.59,0.250
7.63,14.77,0.250
7.65,14.95,0.250
7.66,15.14,0.250
7.68,15.32,0.250
7.70,15.51,0.250
7.72,15.69,0.251
7.74,15.87,0.251
7.75,16.06,0.251
7.77,16.24,0.251
7.79,16.42,0.251
7.81,16.61,0.251
7.83,16.79,0.252
7.85,16.98,0.252
7.86,17.16,0.252
7.88,17.34,0.252
7.90,17.53,0.252
7.92,17.71,0.252
7.94,17.89,0.253
7.96,18.08,0.253
7.98,18.26,0.253
7.99,18.44,0.253
8.01,18.63,0.253
8.03,18.81,0.253
8.05,18.99,0.254
8.07,19.18,0.254
8.09,19.36,0.254
8.10,19.54,0.254
8.12,19.73,0.254
8.14,19.91,0.254
8.16,20.10,0.254
8.18,20.28,0.254
8.20,20.46,0.254
8.21,20.64,0.254
8.23,20.83,0.255
8.25,21.01,0.255
8.27,21.20,0.255
8.29,21.38,0.255
8.30,21.56,0.255
8.32,21.75,0.255
8.34,21.93,0.255
8.36,22.11,0.256
8.38,22.30,0.256
8.40,22.48,0.256
8.41,22.66,0.256
8.43,22.85,0.256
8.45,23.03,0.256
8.47,23.21,0.257
8.49,23.40,0.257
8.51,23.58,0.257
8.53,23.76,0.257
8.54,23.95,0.257
8.56,24.13,0.257
8.58,24.31,0.257
8.60,24.50,0.258
8.62,24.68,0.258
8.63,24.86,0.258
8.65,25.05,0.258
8.67,25.23,0.258
8.69,25.41,0.258
8.71,25.60,0.259
8.73,25.78,0.259
8.75,25.96,0.259
8.76,26.15,0.259
8.78,26.33,0.259
8.80,26.52,0.259
8.82,26.70,0.259
8.84,26.88,0.260
8.85,27.07,0.260
8.87,27.25,0.260
8.89,27.43,0.260
8.91,27.62,0.260
8.93,27.80,0.260
8.95,27.98,0.261
8.97,28.17,0.261
8.98,28.35,0.261
9.00,28.53,0.261
9.02,28.72,0.261
9.04,28.90,0.261
9.06,29.08,0.262
9.08,29.27,0.262
9.09,29.45,0.262
9.11,29.64,0.262
9.13,29.82,0.262
9.15,30.00,0.262
9.17,30.19,0.262
9.18,30.37,0.263
9.20,30.55,0.263
9.22,30.74,0.263
9.24,30.92,0.263
9.26,31.10,0.263
9.28,31.29,0.263
9.30,31.47,0.264
9.31,31.65,0.264
9.33,31.84,0.264
9.35,32.02,0.264
9.37,32.20,0.264
9.39,32.39,0.264
9.40,32.57,0.265
9.42,32.76,0.265
9.44,32.94,0.265
9.46,33.12,0.265
9.48,33.31,0.265
9.50,33.49,0.265
9.52,33.67,0.265
9.53,33.86,0.265
9.55,34.04,0.266
9.57,34.22,0.266
9.59,34.41,0.266
9.61,34.59,0.266
9.63,34.78,0.266
9.64,34.96,0.266
9.66,35.14,0.267
9.68,35.33,0.267
9.70,35.51,0.267
9.72,35.69,0.267
9.73,35.88,0.267
9.75,36.06,0.267
9.77,36.24,0.267
9.79,36.43,0.268
9.81,36.61,0.268
9.83,36.80,0.268
9.85,36.98,0.268
9.86,37.16,0.268
9.88,37.34,0.268
9.90,37.53,0.268
9.92,37.71,0.268
9.94,37.90,0.269
9.95,38.08,0.269
9.97,38.26,0.269
9.99,38.45,0.269
10.01,38.63,0.269
10.03,38.81,0.269
10.05,39.00,0.269
10.07,39.18,0.269
10.08,39.36,0.270
10.10,39.55,0.270
10.12,39.73,0.270
10.14,39.91,0.270
10.16,40.10,0.270
10.18,40.28,0.270
10.19,40.47,0.270
10.21,40.65,0.271
10.23,40.83,0.271
10.25,41.02,0.271
10.27,41.20,0.271
10.28,41.38,0.271
10.30,41.57,0.271
10.32,41.75,0.271
10.34,41.93,0.271
10.36,42.12,0.271
10.38,42.30,0.272
10.40,42.48,0.272
10.41,42.67,0.272
10.43,42.85,0.272
10.45,43.04,0.272
10.47,43.22,0.272
10.49,43.40,0.272
10.50,43.59,0.273
10.52,43.77,0.273
10.54,43.95,0.273
10.56,44.14,0.273
10.58,44.32,0.273
10.60,44.50,0.273
10.62,44.69,0.273
10.63,44.87,0.274
10.65,45.05,0.274
10.67,45.24,0.274
10.69,45.42,0.274
10.71,45.61,0.274
10.73,45.79,0.274
10.74,45.97,0.274
10.76,46.15,0.275
10.78,46.34,0.275
10.80,46.52,0.275
10.82,46.71,0.275
10.83,46.89,0.275
10.85,47.07,0.275
10.87,47.26,0.275
10.89,47.44,0.276
10.91,47.62,0.276
10.93,47.81,0.276
10.95,47.99,0.276
10.96,48.17,0.276
10.98,48.36,0.276
11.00,48.54,0.276
11.02,48.72,0.277
11.04,48.91,0.277
11.05,49.09,0.277
11.07,49.28,0.277
11.09,49.46,0.277
11.11,49.64,0.277
11.13,49.83,0.278
11.15,50.01,0.278
11.17,50.19,0.278
11.18,50.38,0.278
11.20,50.56,0.278
11.22,50.74,0.278
11.24,50.93,0.278
11.26,51.11,0.278
11.28,51.29,0.279
11.29,51.48,0.279
11.31,51.66,0.279
11.33,51.84,0.279
11.35,52.03,0.279
11.37,52.21,0.279
11.38,52.40,0.279
11.40,52.58,0.280
11.42,52.76,0.280
11.44,52.95,0.280
11.46,53.13,0.280
11.48,53.31,0.280
11.50,53.50,0.280
11.51,53.68,0.280
11.53,53.87,0.280
11.55,54.05,0.281
11.57,54.23,0.281
11.59,54.41,0.281
11.60,54.60,0.281
11.62,54.78,0.281
11.64,54.96,0.281
11.66,55.15,0.282
11.68,55.33,0.282
11.70,55.52,0.282
11.72,55.70,0.282
11.73,55.88,0.282
11.75,56.07,0.282
11.77,56.25,0.283
11.79,56.43,0.283
11.81,56.62,0.283
11.83,56.80,0.283
11.84,56.98,0.283
11.86,57.17,0.283
11.88,57.35,0.283
11.90,57.53,0.283
11.92,57.72,0.284
11.93,57.90,0.284
11.95,58.08,0.284
11.97,58.27,0.284
11.99,58.45,0.284
12.01,58.64,0.284
12.03,58.82,0.284
12.05,59.00,0.284
12.06,59.19,0.285
12.08,59.37,0.285
12.10,59.55,0.285
12.12,59.74,0.285
12.14,59.92,0.285
12.15,60.10,0.285
12.17,60.29,0.286
12.19,60.47,0.286
12.21,60.65,0.286
12.23,60.84,0.286
12.25,61.02,0.286
12.27,61.20,0.286
12.28,61.39,0.287
12.30,61.57,0.287
12.32,61.75,0.287
12.34,61.94,0.287
12.36,62.12,0.287
12.38,62.31,0.287
12.39,62.49,0.287
12.41,62.67,0.287
12.43,62.86,0.288
12.45,63.04,0.288
12.47,63.22,0.288
12.48,63.41,0.288
12.50,63.59,0.288
12.52,63.77,0.288
12.54,63.96,0.288
12.56,64.14,0.289
12.58,64.32,0.289
12.60,64.51,0.289
12.61,64.69,0.289
12.63,64.87,0.289
12.65,65.06,0.289
12.67,65.24,0.290
12.69,65.42,0.290
12.70,65.61,0.290
12.72,65.79,0.290
12.74,65.98,0.290
12.76,66.16,0.290
12.78,66.34,0.291
12.80,66.53,0.291
12.82,66.71,0.291
12.83,66.89,0.291
12.85,67.08,0.291
12.87,67.26,0.291
12.89,67.44,0.291
12.91,67.63,0.291
12.93,67.81,0.292
12.94,68.00,0.292
12.96,68.18,0.292
12.98,68.36,0.292
13.00,68.55,0.292
13.02,68.73,0.292
13.03,68.91,0.293
13.05,69.10,0.293
13.07,69.28,0.293
13.09,69.46,0.293
13.11,69.65,0.293
13.13,69.83,0.293
13.15,70.01,0.294
13.16,70.20,0.294
13.18,70.38,0.294
13.20,70.57,0.294
13.22,70.75,0.294
13.24,70.93,0.294
13.25,71.12,0.295
13.27,71.30,0.295
13.29,71.48,0.295
13.31,71.67,0.295
13.33,71.85,0.295
13.35,72.03,0.295
13.37,72.22,0.296
13.38,72.40,0.296
13.40,72.58,0.296
13.42,72.77,0.296
13.44,72.95,0.296
13.46,73.14,0.296
13.48,73.32,0.296
13.49,73.50,0.297
13.51,73.69,0.297
13.53,73.87,0.297
13.55,74.05,0.297
13.57,74.24,0.297
13.58,74.42,0.297
13.60,74.60,0.297
13.62,74.79,0.298
13.64,74.97,0.298
13.66,75.15,0.298
13.68,75.34,0.298
13.70,75.52,0.298
13.71,75.70,0.298
13.73,75.89,0.298
13.75,76.07,0.299
13.77,76.25,0.299
13.79,76.44,0.299
13.80,76.62,0.299
13.82,76.80,0.299
13.84,76.99,0.299
13.86,77.17,0.299
13.88,77.35,0.300
13.90,77.54,0.300
13.92,77.72,0.300
13.93,77.90,0.300
13.95,78.09,0.300
13.97,78.27,0.300
13.99,78.46,0.301
14.01,78.64,0.301
14.03,78.82,0.301
14.04,79.01,0.301
14.06,79.19,0.301
14.08,79.37,0.301
14.10,79.56,0.302
14.12,79.74,0.302
14.13,79.92,0.302
14.15,80.11,0.302
14.17,80.29,0.302
14.19,80.47,0.303
14.21,80.66,0.303
14.23,80.84,0.303
14.25,81.02,0.303
14.26,81.21,0.303
14.28,81.39,0.303
14.30,81.57,0.304
14.32,81.76,0.304
14.34,81.94,0.304
14.35,82.12,0.304
14.37,82.31,0.304
14.39,82.49,0.304
14.41,82.68,0.304
14.43,82.86,0.304
14.45,83.04,0.305
14.47,83.23,0.305
14.48,83.41,0.305
14.50,83.59,0.305
14.52,83.78,0.305
14.54,83.96,0.305
14.56,84.14,0.305
14.58,84.33,0.305
14.59,84.51,0.305
14.61,84.69,0.306
14.63,84.88,0.306
14.65,85.06,0.306
14.67,85.24,0.306
14.68,85.43,0.306
14.70,85.61,0.306
14.72,85.79,0.306
14.74,85.98,0.307
14.76,86.16,0.307
14.78,86.35,0.307
14.80,86.53,0.307
14.81,86.71,0.307
14.83,86.90,0.307
14.85,87.08,0.307
14.87,87.26,0.308
14.89,87.45,0.308
14.90,87.63,0.308
14.92,87.81,0.308
14.94,88.00,0.308
14.96,88.18,0.308
14.98,88.36,0.309
15.00,88.55,0.309
15.02,88.73,0.309
15.03,88.91,0.309
15.05,89.10,0.309
15.07,89.28,0.309
15.09,89.46,0.310
15.11,89.65,0.310
15.13,89.83,0.310
15.14,90.02,0.310
15.16,90.20,0.310
15.18,90.38,0.310
15.20,90.56,0.311
15.22,90.75,0.311
15.23,90.93,0.311
15.25,91.12,0.311
15.27,91.30,0.311
15.29,91.48,0.311
15.31,91.67,0.312
15.33,91.85,0.312
15.35,92.03,0.312
15.36,92.22,0.312
15.38,92.40,0.312
15.40,92.59,0.312
15.42,92.77,0.313
15.44,92.95,0.313
15.45,93.14,0.313
15.47,93.32,0.313
15.49,93.50,0.314
15.51,93.69,0.314
15.53,93.87,0.314
15.55,94.05,0.314
15.57,94.24,0.314
15.58,94.42,0.314
15.60,94.60,0.315
15.62,94.79,0.315
15.64,94.97,0.315
15.66,95.15,0.315
15.68,95.34,0.315
15.69,95.52,0.316
15.71,95.70,0.316
15.73,95.89,0.316
15.75,96.07,0.316
15.77,96.25,0.316
15.78,96.44,0.316
15.80,96.62,0.317
15.82,96.80,0.317
15.84,96.99,0.317
15.86,97.17,0.317
15.88,97.35,0.317
15.90,97.54,0.318
15.91,97.72,0.318
15.93,97.90,0.318
15.95,98.09,0.318
15.97,98.27,0.318
15.99,98.46,0.318
16.00,98.64,0.319
16.02,98.82,0.319
16.04,99.01,0.319
16.06,99.19,0.319
16.08,99.37,0.319
16.10,99.56,0.320
16.12,99.74,0.320
16.13,99.92,0.320
16.15,100.11,0.320
16.17,100.29,0.320
16.19,100.47,0.320
16.21,100.66,0.321
16.23,100.84,0.321
16.24,101.02,0.321
16.26,101.21,0.321
16.28,101.39,0.321
16.30,101.57,0.322
16.32,101.76,0.322
16.33,101.94,0.322
16.35,102.12,0.322
16.37,102.31,0.322
16.39,102.49,0.323
16.41,102.68,0.323
16.43,102.86,0.323
16.45,103.04,0.323
16.46,103.23,0.323
16.48,103.41,0.323
16.50,103.59,0.324
16.52,103.78,0.324
16.54,103.96,0.324
16.55,104.14,0.324
16.57,104.33,0.324
16.59,104.51,0.324
16.61,104.70,0.325
16.63,104.88,0.325
16.65,105.06,0.325
16.67,105.25,0.325
16.68,105.43,0.325
16.70,105.61,0.326
16.72,105.79,0.326
16.74,105.98,0.326
16.76,106.16,0.326
16.78,106.34,0.326
16.79,106.53,0.326
16.81,106.71,0.327
16.83,106.89,0.327
16.85,107.08,0.327
16.87,107.26,0.327
16.88,107.44,0.327
16.90,107.63,0.327
16.92,107.81,0.328
16.94,108.00,0.328
16.96,108.18,0.328
16.98,108.36,0.328
17.00,108.54,0.328
17.01,108.73,0.329
17.03,108.91,0.329
17.05,109.10,0.329
17.07,109.28,0.329
17.09,109.46,0.329
17.11,109.65,0.330
17.12,109.83,0.330
17.14,110.01,0.330
17.16,110.20,0.330
17.18,110.38,0.331
17.20,110.57,0.331
17.22,110.75,0.331
17.23,110.93,0.331
17.25,111.12,0.331
17.27,111.30,0.332
17.29,111.48,0.332
17.31,111.67,0.332
17.33,111.85,0.332
17.34,112.03,0.332
17.36,112.22,0.333
17.38,112.40,0.333
17.40,112.58,0.333
17.42,112.77,0.333
17.43,112.95,0.333
17.45,113.13,0.333
17.47,113.32,0.333
17.49,113.50,0.334
17.51,113.68,0.334
17.53,113.87,0.334
17.54,114.05,0.335
17.56,114.23,0.335
17.58,114.42,0.335
17.60,114.60,0.335
17.62,114.78,0.335
17.64,114.97,0.335
17.66,115.15,0.335
17.67,115.33,0.336
17.69,115.52,0.336
17.71,115.70,0.336
17.73,115.89,0.336
17.75,116.07,0.337
17.77,116.25,0.337
17.78,116.44,0.337
17.80,116.62,0.337
17.82,116.80,0.337
17.84,116.98,0.338
17.86,117.17,0.338
17.88,117.35,0.338
17.89,117.54,0.338
17.91,117.72,0.338
17.93,117.90,0.339
17.95,118.08,0.339
17.97,118.27,0.339
17.98,118.45,0.339
18.00,118.63,0.339
18.02,118.82,0.340
18.04,119.00,0.340
18.06,119.18,0.340
18.08,119.37,0.340
18.09,119.55,0.341
18.11,119.74,0.341
18.13,119.92,0.341
18.15,120.10,0.341
18.17,120.29,0.342
18.19,120.47,0.342
18.21,120.65,0.342
18.22,120.84,0.342
18.24,121.02,0.342
18.26,121.20,0.343
18.28,121.39,0.343
18.30,121.57,0.343
18.32,121.75,0.343
18.33,121.94,0.344
18.35,122.12,0.344
18.37,122.30,0.344
18.39,122.49,0.344
18.41,122.67,0.344
18.43,122.85,0.345
18.44,123.04,0.345
18.46,123.22,0.345
18.48,123.41,0.346
18.50,123.59,0.346
18.52,123.77,0.346
18.53,123.96,0.346
18.55,124.14,0.347
18.57,124.32,0.347
18.59,124.51,0.347
18.61,124.69,0.347
18.63,124.87,0.348
18.64,125.06,0.348
18.66,125.24,0.348
18.68,125.42,0.349
18.70,125.61,0.349
18.72,125.79,0.349
18.74,125.97,0.349
18.76,126.16,0.349
18.77,126.34,0.350
18.79,126.52,0.350
18.81,126.71,0.350
18.83,126.89,0.350
18.85,127.07,0.351
18.87,127.26,0.351
18.88,127.44,0.351
18.90,127.62,0.351
18.92,127.81,0.351
18.94,127.99,0.351
18.96,128.17,0.352
18.98,128.36,0.352
18.99,128.54,0.352
19.01,128.72,0.353
19.03,128.91,0.353
19.05,129.09,0.354
19.07,129.28,0.357
19.08,129.46,0.359
19.10,129.64,0.360
19.12,129.83,0.360
19.14,130.01,0.360
19.16,130.19,0.360
19.18,130.38,0.360
19.19,130.56,0.360
19.21,130.74,0.360
19.23,130.93,0.360
19.25,131.11,0.360
19.27,131.29,0.360
19.29,131.48,0.360
19.31,131.66,0.360
19.32,131.84,0.360
19.34,132.03,0.360
19.36,132.21,0.360
19.38,132.39,0.360
19.40,132.58,0.360
19.42,132.76,0.360
19.43,132.95,0.361
19.45,133.13,0.361
19.47,133.31,0.361
19.49,133.50,0.361
19.51,133.68,0.362
19.53,133.86,0.362
19.54,134.04,0.362
19.56,134.23,0.362
19.58,134.41,0.362
19.60,134.59,0.363
19.62,134.78,0.363
19.63,134.96,0.363
19.65,135.14,0.363
19.67,135.33,0.363
19.69,135.51,0.363
19.71,135.69,0.364
19.73,135.88,0.364
19.74,136.06,0.364
19.76,136.24,0.365
19.78,136.43,0.365
19.80,136.61,0.366
19.82,136.79,0.366
19.84,136.98,0.367
19.86,137.16,0.367
19.87,137.34,0.367
19.89,137.53,0.368
19.91,137.71,0.368
19.93,137.90,0.369
19.95,138.08,0.369
19.97,138.26,0.370
19.98,138.44,0.371
20.00,138.63,0.372
20.02,138.81,0.372
20.04,138.99,0.373
20.06,139.18,0.373
20.08,139.36,0.373
20.09,139.54,0.374
20.11,139.73,0.374
20.13,139.91,0.375
20.15,140.09,0.376
20.17,140.28,0.376
20.18,140.46,0.377
20.20,140.64,0.378
20.22,140.83,0.379
20.24,141.01,0.381
20.26,141.19,0.382
20.28,141.38,0.383
20.29,141.56,0.384
20.31,141.74,0.385
20.33,141.92,0.386
20.35,142.11,0.387
20.37,142.29,0.388
20.39,142.47,0.389
20.41,142.66,0.391
20.42,142.84,0.393
20.44,143.02,0.393
20.46,143.21,0.394
20.48,143.39,0.394
20.50,143.57,0.396
20.52,143.76,0.399
20.53,143.94,0.401
20.55,144.12,0.402
20.57,144.30,0.403
20.59,144.49,0.404
20.61,144.67,0.405
20.63,144.85,0.408
20.64,145.04,0.410
20.66,145.22,0.412
20.68,145.40,0.414
20.70,145.59,0.417
20.72,145.77,0.419
20.73,145.95,0.422
20.75,146.13,0.425
20.77,146.32,0.429
20.79,146.50,0.434
20.81,146.68,0.437
20.83,146.86,0.440
20.84,147.05,0.446
20.86,147.23,0.453
20.88,147.41,0.460
20.90,147.59,0.464
20.92,147.77,0.467
20.94,147.95,0.467
20.96,148.14,0.466
20.97,148.32,0.464
20.99,148.50,0.463
21.01,148.69,0.461
21.03,148.87,0.457
21.05,149.06,0.455
21.07,149.24,0.454
21.08,149.43,0.451
21.10,149.61,0.450
21.12,149.80,0.448
21.14,149.98,0.443
21.16,150.16,0.439
21.18,150.35,0.439
21.19,150.53,0.438
21.21,150.71,0.439
21.23,150.90,0.439
21.25,151.08,0.437
21.27,151.27,0.433
21.28,151.45,0.427
21.30,151.64,0.426
21.32,151.82,0.424
21.34,152.00,0.424
21.36,152.19,0.425
21.38,152.37,0.429
21.39,152.55,0.433
21.41,152.74,0.434
21.43,152.92,0.434
21.45,153.10,0.432
21.47,153.29,0.430
21.49,153.47,0.427
21.51,153.66,0.422
21.52,153.84,0.417
21.54,154.03,0.413
21.56,154.21,0.411
21.58,154.39,0.409
21.60,154.58,0.408
21.62,154.76,0.408
21.63,154.95,0.407
21.65,155.13,0.407
21.67,155.32,0.406
21.69,155.50,0.405
21.71,155.68,0.404
21.73,155.87,0.403
21.74,156.05,0.403
21.76,156.23,0.402
21.78,156.42,0.402
21.80,156.60,0.403
21.82,156.79,0.403
21.83,156.97,0.403
21.85,157.15,0.403
21.87,157.34,0.403
21.89,157.52,0.402
21.91,157.70,0.402
21.93,157.89,0.402
21.94,158.07,0.401
21.96,158.26,0.401
21.98,158.44,0.401
22.00,158.62,0.401
22.02,158.81,0.401
22.04,158.99,0.402
22.06,159.17,0.402
22.07,159.36,0.402
22.09,159.54,0.402
22.11,159.72,0.402
22.13,159.91,0.403
22.15,160.09,0.403
22.17,160.27,0.403
22.18,160.46,0.403
22.20,160.64,0.403
22.22,160.82,0.404
22.24,161.01,0.404
22.26,161.19,0.405
22.28,161.37,0.405
22.29,161.56,0.405
22.31,161.74,0.405
22.33,161.92,0.406
22.35,162.11,0.406
22.37,162.29,0.407
22.38,162.47,0.407
22.40,162.66,0.407
22.42,162.84,0.408
22.44,163.02,0.408
22.46,163.21,0.408
22.48,163.39,0.409
22.49,163.57,0.409
22.51,163.76,0.411
22.53,163.94,0.411
22.55,164.12,0.413
22.57,164.31,0.413
22.59,164.49,0.414
22.61,164.67,0.415
22.62,164.86,0.415
22.64,165.04,0.415
22.66,165.22,0.416
22.68,165.41,0.417
22.70,165.59,0.417
22.72,165.77,0.419
22.73,165.96,0.420
22.75,166.14,0.421
22.77,166.32,0.423
22.79,166.50,0.424
22.81,166.69,0.425
22.83,166.87,0.426
22.84,167.05,0.427
22.86,167.24,0.428
22.88,167.42,0.429
22.90,167.60,0.430
22.92,167.79,0.431
22.93,167.97,0.433
22.95,168.15,0.435
22.97,168.34,0.437
22.99,168.52,0.438
23.01,168.70,0.440
23.03,168.88,0.440
23.04,169.07,0.441
23.06,169.25,0.442
23.08,169.43,0.443
23.10,169.62,0.444
23.12,169.80,0.447
23.14,169.98,0.448
23.16,170.16,0.449
23.17,170.35,0.450
23.19,170.53,0.453
23.21,170.71,0.454
23.23,170.90,0.457
23.25,171.08,0.459
23.27,171.26,0.461
23.28,171.45,0.462
23.30,171.63,0.464
23.32,171.81,0.467
23.34,171.99,0.469
23.36,172.18,0.471
23.38,172.36,0.474
23.39,172.54,0.475
23.41,172.72,0.477
23.43,172.91,0.479
23.45,173.09,0.481
23.47,173.27,0.485
23.48,173.46,0.487
23.50,173.64,0.489
23.52,173.82,0.493
23.54,174.00,0.496
23.56,174.19,0.499
23.58,174.37,0.503
23.59,174.55,0.505
23.61,174.73,0.507
23.63,174.91,0.511
23.65,175.10,0.515
23.67,175.28,0.518
23.69,175.46,0.522
23.71,175.64,0.525
23.72,175.82,0.529
23.74,176.01,0.533
23.76,176.19,0.538
23.78,176.37,0.543
23.80,176.55,0.549
23.82,176.73,0.553
23.83,176.91,0.559
23.85,177.10,0.565
23.87,177.28,0.571
23.89,177.46,0.576
23.91,177.64,0.583
23.93,177.82,0.589
23.94,178.00,0.598
23.96,178.18,0.606
23.98,178.37,0.614
24.00,178.55,0.622
24.02,178.73,0.631
24.03,178.91,0.640
24.05,179.09,0.650
24.07,179.27,0.660
24.09,179.45,0.669
24.11,179.63,0.679
24.13,179.81,0.691
24.14,179.99,0.704
24.16,180.17,0.716
24.18,180.35,0.731
24.20,180.53,0.747
24.22,180.70,0.762
24.24,180.88,0.777
24.26,181.06,0.792
24.27,181.24,0.810
24.29,181.42,0.831
24.31,181.59,0.853
24.33,181.77,0.880
24.35,181.95,0.903
24.37,182.12,0.930
24.38,182.30,0.957
24.40,182.47,0.989
24.42,182.64,1.025
24.44,182.81,1.065
24.46,182.98,1.108
24.48,183.15,1.151
24.49,183.32,1.203
24.51,183.49,1.268
24.53,183.65,1.346
24.55,183.81,1.427
24.57,183.97,1.524
24.58,184.12,1.652
24.60,184.27,1.800
24.62,184.41,1.915
24.64,184.55,2.055
24.66,184.69,2.187
24.68,184.83,2.331
24.69,184.97,2.485
24.71,185.10,2.648
24.73,185.22,2.862
24.75,185.35,3.014
24.77,185.47,3.194
24.79,185.59,3.399
24.81,185.71,3.570
24.82,185.83,3.804
24.84,185.94,4.009
24.86,186.05,4.224
24.88,186.16,4.488
24.90,186.26,4.711
24.92,186.36,4.929
24.93,186.47,5.112
24.95,186.58,5.308
24.97,186.68,5.563
24.99,186.78,5.790
25.01,186.88,6.055
25.03,186.98,6.313
25.04,187.07,6.603
25.06,187.16,6.862
25.08,187.25,7.123
25.10,187.34,7.494
25.12,187.42,7.779
25.13,187.49,8.035
25.15,187.57,8.354
25.17,187.66,8.490
25.19,187.76,8.695
25.21,187.86,8.895
25.23,187.97,9.132
25.24,188.06,9.521
25.26,188.15,9.616
25.28,188.26,9.713
25.30,188.39,9.826
25.32,188.51,10.059
25.34,188.62,10.188
25.36,188.77,10.067
25.37,188.93,10.031
25.39,189.12,9.919
25.41,189.31,9.818
25.43,189.52,9.571
25.45,189.74,9.512
25.47,189.97,9.013
25.48,190.29,8.044
25.50,190.68,6.977
25.52,191.12,5.882
25.54,191.60,5.016
25.56,192.07,4.159
25.58,192.55,3.451
25.59,192.99,3.030
25.61,193.40,2.703
25.63,193.76,2.428
25.65,194.10,2.194
25.67,194.42,1.995
25.68,194.72,1.823
25.70,195.00,1.676
25.72,195.26,1.548
25.74,195.51,1.438
25.76,195.75,1.343
25.78,195.99,1.261
25.79,196.22,1.190
25.81,196.44,1.125
25.83,196.65,1.070
25.85,196.86,1.021
25.87,197.07,0.976
25.89,197.28,0.941
25.91,197.48,0.902
25.92,197.68,0.870
25.94,197.88,
25.96,198.07,
25.98,198.27,
25.99,,

[step]
Ramp 10.00 °C/min to -60.00 °C
Time,Temperature,Heat Flow (Normalized)
min,°C,W/g
27.99,200.16,-0.147
28.01,200.16,-0.147
28.03,200.15,-0.147
28.05,200.14,-0.144
28.07,200.12,-0.133
28.08,200.08,-0.129
28.10,200.02,-0.139
28.12,199.94,-0.176
28.14,199.84,-0.224
28.16,199.73,-0.280
28.18,199.60,-0.338
28.19,199.47,-0.391
28.21,199.32,-0.438
28.23,199.17,-0.476
28.25,199.02,-0.508
28.27,198.86,-0.537
28.29,198.70,-0.557
28.31,198.54,-0.578
28.32,198.37,-0.594
28.34,198.20,-0.608
28.36,198.03,-0.620
28.38,197.86,-0.631
28.40,197.69,-0.641
28.42,197.51,-0.649
28.43,197.34,-0.656
28.45,197.16,-0.662
28.47,196.98,-0.666
28.49,196.81,-0.671
28.51,196.63,-0.675
28.53,196.45,-0.677
28.54,196.27,-0.680
28.56,196.09,-0.682
28.58,195.91,-0.684
28.60,195.73,-0.686
28.62,195.55,-0.687
28.63,195.37,-0.687
28.65,195.19,-0.688
28.67,195.01,-0.689
28.69,194.83,-0.689
28.71,194.65,-0.689
28.73,194.46,-0.690
28.74,194.28,-0.690
28.76,194.10,-0.690
28.78,193.92,-0.691
28.80,193.74,-0.691
28.82,193.56,-0.691
28.84,193.37,-0.691
28.86,193.19,-0.692
28.87,193.01,-0.692
28.89,192.83,-0.692
28.91,192.64,-0.692
28.93,192.46,-0.692
28.95,192.28,-0.692
28.97,192.10,-0.692
28.98,191.92,-0.692
29.00,191.74,-0.691
29.02,191.55,-0.691
29.04,191.37,-0.691
29.06,191.19,-0.691
29.08,191.00,-0.691
29.09,190.82,-0.691
29.11,190.64,-0.690
29.13,190.46,-0.690
29.15,190.27,-0.690
29.17,190.09,-0.690
29.18,189.91,-0.689
29.20,189.72,-0.688
29.22,189.54,-0.688
29.24,189.36,-0.688
29.26,189.18,-0.687
29.28,188.99,-0.686
29.29,188.81,-0.686
29.31,188.63,-0.685
29.33,188.44,-0.685
29.35,188.26,-0.684
29.37,188.08,-0.683
29.39,187.90,-0.683
29.41,187.71,-0.683
29.42,187.53,-0.682
29.44,187.35,-0.680
29.46,187.17,-0.680
29.48,186.98,-0.679
29.50,186.80,-0.679
29.52,186.62,-0.678
29.53,186.43,-0.677
29.55,186.25,-0.677
29.57,186.07,-0.677
29.59,185.88,-0.676
29.61,185.70,-0.676
29.63,185.52,-0.676
29.64,185.33,-0.675
29.66,185.15,-0.674
29.68,184.97,-0.674
29.70,184.78,-0.674
29.72,184.60,-0.672
29.73,184.42,-0.671
29.75,184.23,-0.671
29.77,184.05,-0.670
29.79,183.87,-0.670
29.81,183.68,-0.668
29.83,183.50,-0.668
29.84,183.32,-0.667
29.86,183.14,-0.666
29.88,182.95,-0.666
29.90,182.77,-0.665
29.92,182.59,-0.665
29.94,182.40,-0.664
29.96,182.22,-0.663
29.97,182.04,-0.663
29.99,181.85,-0.662
30.01,181.67,-0.661
30.03,181.49,-0.661
30.05,181.30,-0.661
30.07,181.12,-0.660
30.08,180.94,-0.660
30.10,180.75,-0.660
30.12,180.57,-0.659
30.14,180.39,-0.659
30.16,180.20,-0.658
30.18,180.02,-0.658
30.19,179.84,-0.657
30.21,179.65,-0.656
30.23,179.47,-0.655
30.25,179.29,-0.653
30.27,179.10,-0.652
30.28,178.92,-0.652
30.30,178.74,-0.651
30.32,178.55,-0.651
30.34,178.37,-0.650
30.36,178.19,-0.650
30.38,178.00,-0.650
30.39,177.82,-0.649
30.41,177.64,-0.649
30.43,177.45,-0.649
30.45,177.27,-0.648
30.47,177.09,-0.648
30.49,176.90,-0.647
30.51,176.72,-0.646
30.52,176.54,-0.646
30.54,176.35,-0.645
30.56,176.17,-0.645
30.58,175.99,-0.644
30.60,175.80,-0.644
30.62,175.62,-0.643
30.63,175.44,-0.643
30.65,175.25,-0.643
30.67,175.07,-0.641
30.69,174.89,-0.641
30.71,174.70,-0.640
30.73,174.52,-0.640
30.74,174.34,-0.640
30.76,174.15,-0.639
30.78,173.97,-0.639
30.80,173.79,-0.638
30.82,173.60,-0.638
30.83,173.42,-0.637
30.85,173.24,-0.637
30.87,173.05,-0.636
30.89,172.88,-2.059
30.91,174.20,-27.041
30.93,176.05,-23.140
30.94,176.74,-17.980
30.96,176.92,-15.897
30.98,176.89,-14.866
31.00,176.74,-14.165
31.02,176.54,-13.595
31.04,176.29,-13.075
31.06,176.01,-12.550
31.07,175.70,-12.012
31.09,175.38,-11.466
31.11,175.04,-10.915
31.13,174.69,-10.367
31.15,174.33,-9.825
31.17,173.97,-9.291
31.18,173.60,-8.779
31.20,173.24,-8.278
31.22,172.87,-7.794
31.24,172.51,-7.330
31.26,172.14,-6.886
31.28,171.79,-6.473
31.29,171.44,-6.078
31.31,171.10,-5.702
31.33,170.76,-5.355
31.35,170.43,-5.029
31.37,170.11,-4.728
31.38,169.79,-4.449
31.40,169.49,-4.179
31.42,169.19,-3.932
31.44,168.90,-3.709
31.46,168.61,-3.507
31.48,168.33,-3.318
31.49,168.06,-3.148
31.51,167.80,-2.995
31.53,167.54,-2.857
31.55,167.29,-2.731
31.57,167.05,-2.616
31.59,166.80,-2.508
31.61,166.57,-2.410
31.62,166.34,-2.316
31.64,166.11,-2.229
31.66,165.89,-2.144
31.68,165.67,-2.062
31.70,165.45,-1.984
31.72,165.23,-1.910
31.73,165.01,-1.837
31.75,164.80,-1.771
31.77,164.59,-1.703
31.79,164.38,-1.642
31.81,164.17,-1.582
31.83,163.96,-1.527
31.84,163.75,-1.472
31.86,163.54,-1.423
31.88,163.34,-1.376
31.90,163.13,-1.331
31.92,162.93,-1.290
31.93,162.73,-1.248
31.95,162.53,-1.211
31.97,162.33,-1.175
31.99,162.13,-1.141
32.01,161.93,-1.111
32.03,161.74,-1.083
32.04,161.54,-1.055
32.06,161.34,-1.027
32.08,161.15,-1.002
32.10,160.96,-0.978
32.12,160.76,-0.955
32.14,160.57,-0.933
32.16,160.38,-0.914
32.17,160.18,-0.892
32.19,159.99,-0.875
32.21,159.80,-0.859
32.23,159.61,-0.841
32.25,159.42,-0.825
32.27,159.23,-0.810
32.28,159.04,-0.794
32.30,158.85,-0.782
32.32,158.66,-0.768
32.34,158.47,-0.757
32.36,158.28,-0.746
32.38,158.10,-0.736
32.39,157.91,-0.725
32.41,157.72,-0.715
32.43,157.53,-0.703
32.45,157.35,-0.695
32.47,157.16,-0.687
32.48,156.97,-0.678
32.50,156.79,-0.671
32.52,156.60,-0.663
32.54,156.41,-0.661
32.56,156.23,-0.665
32.58,156.04,-0.668
32.59,155.86,-0.655
32.61,155.68,-0.648
32.63,155.49,-0.650
32.65,155.31,-0.657
32.67,155.12,-0.651
32.69,154.94,-0.636
32.71,154.75,-0.629
32.72,154.57,-0.624
32.74,154.38,-0.622
32.76,154.20,-0.618
32.78,154.01,-0.618
32.80,153.83,-0.620
32.82,153.64,-0.620
32.83,153.46,-0.616
32.85,153.28,-0.612
32.87,153.09,-0.604
32.89,152.91,-0.600
32.91,152.72,-0.600
32.93,152.54,-0.601
32.94,152.35,-0.592
32.96,152.17,-0.589
32.98,151.98,-0.577
33.00,151.80,-0.568
33.02,151.61,-0.561
33.03,151.43,-0.557
33.05,151.24,-0.553
33.07,151.06,-0.549
33.09,150.87,-0.545
33.11,150.69,-0.542
33.13,150.50,-0.541
33.14,150.32,-0.535
33.16,150.13,-0.537
33.18,149.95,-0.536
33.20,149.77,-0.529
33.22,149.58,-0.525
33.24,149.40,-0.526
33.26,149.21,-0.523
33.27,149.03,-0.522
33.29,148.85,-0.519
33.31,148.66,-0.516
33.33,148.48,-0.507
33.35,148.29,-0.504
33.37,148.11,-0.502
33.38,147.92,-0.500
33.40,147.74,-0.498
33.42,147.55,-0.495
33.44,147.37,-0.492
33.46,147.18,-0.490
33.48,147.00,-0.489
33.49,146.82,-0.487
33.51,146.63,-0.483
33.53,146.45,-0.482
33.55,146.27,-0.480
33.57,146.08,-0.479
33.58,145.90,-0.478
33.60,145.71,-0.473
33.62,145.53,-0.472
33.64,145.35,-0.470
33.66,145.16,-0.469
33.68,144.98,-0.468
33.69,144.80,-0.466
33.71,144.61,-0.464
33.73,144.43,-0.462
33.75,144.25,-0.461
33.77,144.06,-0.459
33.79,143.88,-0.458
33.81,143.70,-0.457
33.82,143.51,-0.456
33.84,143.33,-0.455
33.86,143.14,-0.454
33.88,142.96,-0.453
33.90,142.78,-0.452
33.92,142.59,-0.451
33.93,142.41,-0.450
33.95,142.23,-0.449
33.97,142.04,-0.448
33.99,141.86,-0.447
34.01,141.67,-0.446
34.03,141.49,-0.445
34.04,141.31,-0.445
34.06,141.12,-0.444
34.08,140.94,-0.442
34.10,140.76,-0.442
34.12,140.57,-0.441
34.14,140.39,-0.440
34.15,140.21,-0.439
34.17,140.02,-0.438
34.19,139.84,-0.438
34.21,139.66,-0.437
34.23,139.47,-0.436
34.24,139.29,-0.435
34.26,139.10,-0.434
34.28,138.92,-0.434
34.30,138.74,-0.432
34.32,138.55,-0.432
34.34,138.37,-0.431
34.36,138.19,-0.431
34.37,138.00,-0.431
34.39,137.82,-0.430
[...]
170.08,-40.93,0.220
170.08,-40.86,0.220
170.09,-40.79,0.220
170.10,-40.73,0.220
170.10,-40.66,0.220
170.11,-40.60,0.220
170.12,-40.53,0.220
170.12,-40.46,0.220
170.13,-40.39,0.220
170.13,-40.33,0.220
170.14,-40.26,0.220
170.15,-40.19,0.220
170.15,-40.13,0.220
170.16,-40.06,0.220
170.17,-39.99,0.220
170.18,-39.93,0.220
170.18,-39.86,0.220
170.19,-39.79,0.220
170.20,-39.73,0.220
170.20,-39.66,0.220
170.21,-39.59,0.220
170.22,-39.53,0.220
170.22,-39.46,0.220
170.23,-39.39,0.220
170.23,-39.33,0.220
170.24,-39.26,0.220
170.25,-39.19,0.220
170.25,-39.13,0.220
170.26,-39.06,0.220
170.27,-38.99,0.221
170.28,-38.93,0.221
170.28,-38.86,0.221
170.29,-38.79,0.221
170.30,-38.72,0.221
170.30,-38.66,0.221
170.31,-38.59,0.221
170.32,-38.52,0.221
170.32,-38.46,0.221
170.33,-38.39,0.221
170.33,-38.32,0.221
170.34,-38.26,0.221
170.35,-38.19,0.221
170.35,-38.12,0.221
170.36,-38.06,0.221
170.37,-37.99,0.221
170.38,-37.92,0.221
170.38,-37.86,0.221
170.39,-37.79,0.221
170.40,-37.72,0.221
170.40,-37.66,0.221
170.41,-37.59,0.221
170.42,-37.52,0.221
170.42,-37.46,0.221
170.43,-37.39,0.222
170.43,-37.32,0.222
170.44,-37.26,0.222
170.45,-37.19,0.222
170.45,-37.12,0.222
170.46,-37.06,0.222
170.47,-36.99,0.222
170.48,-36.92,0.222
170.48,-36.86,0.222
170.49,-36.79,0.222
170.50,-36.72,0.222
170.50,-36.65,0.222
170.51,-36.59,0.222
170.52,-36.52,0.222
170.52,-36.46,0.222
170.53,-36.39,0.222
170.53,-36.32,0.222
170.54,-36.25,0.222
170.55,-36.19,0.222
170.55,-36.12,0.222
170.56,-36.06,0.222
170.57,-35.99,0.222
170.58,-35.92,0.222
170.58,-35.86,0.222
170.59,-35.79,0.222
170.60,-35.72,0.222
170.60,-35.66,0.222
170.61,-35.59,0.222
170.62,-35.52,0.222
170.62,-35.46,0.222
170.63,-35.39,0.222
170.63,-35.32,0.222
170.64,-35.25,0.222
170.65,-35.19,0.222
170.65,-35.12,0.223
170.66,-35.05,0.223
170.67,-34.99,0.223
170.68,-34.92,0.223
170.68,-34.85,0.223
170.69,-34.79,0.223
170.70,-34.72,0.223
170.70,-34.65,0.223
170.71,-34.59,0.223
170.72,-34.52,0.223
170.72,-34.45,0.223
170.73,-34.38,0.223
170.73,-34.32,0.223
170.74,-34.25,0.223
170.75,-34.19,0.223
170.75,-34.12,0.223
170.76,-34.05,0.223
170.77,-33.98,0.223
170.78,-33.92,0.223
170.78,-33.85,0.223
170.79,-33.78,0.223
170.80,-33.72,0.223
170.80,-33.65,0.223
170.81,-33.58,0.223
170.82,-33.52,0.223
170.82,-33.45,0.223
170.83,-33.39,0.223
170.83,-33.32,0.223
170.84,-33.25,0.223
170.85,-33.18,0.223
170.85,-33.12,0.223
170.86,-33.05,0.223
170.87,-32.98,0.223
170.88,-32.92,0.223
170.88,-32.85,0.224
170.89,-32.78,0.224
170.90,-32.72,0.224
170.90,-32.65,0.224
170.91,-32.58,0.224
170.92,-32.52,0.224
170.92,-32.45,0.224
170.93,-32.38,0.224
170.93,-32.32,0.224
170.94,-32.25,0.224
170.95,-32.18,0.224
170.95,-32.12,0.224
170.96,-32.05,0.224
170.97,-31.98,0.224
170.98,-31.92,0.224
170.98,-31.85,0.224
170.99,-31.78,0.224
171.00,-31.72,0.224
171.00,-31.65,0.224
171.01,-31.58,0.224
171.02,-31.51,0.224
171.02,-31.45,0.224
171.03,-31.38,0.224
171.03,-31.31,0.224
171.04,-31.25,0.224
171.05,-31.18,0.224
171.05,-31.12,0.224
171.06,-31.05,0.224
171.07,-30.98,0.224
171.08,-30.91,0.224
171.08,-30.85,0.225
171.09,-30.78,0.225
171.10,-30.71,0.225
171.10,-30.65,0.225
171.11,-30.58,0.225
171.12,-30.51,0.225
171.12,-30.45,0.225
171.13,-30.38,0.225
171.13,-30.31,0.225
171.14,-30.25,0.225
171.15,-30.18,0.225
171.15,-30.11,0.225
171.16,-30.04,0.225
171.17,-29.98,0.225
171.18,-29.91,0.225
171.18,-29.84,0.225
171.19,-29.78,0.225
171.20,-29.71,0.225
171.20,-29.64,0.225
171.21,-29.58,0.225
171.22,-29.51,0.225
171.22,-29.44,0.225
171.23,-29.38,0.225
171.23,-29.31,0.225
171.24,-29.24,0.225
171.25,-29.18,0.225
171.25,-29.11,0.225
171.26,-29.04,0.225
171.27,-28.98,0.225
171.28,-28.91,0.225
171.28,-28.84,0.226
171.29,-28.78,0.226
171.30,-28.71,0.226
171.30,-28.64,0.226
171.31,-28.58,0.226
171.32,-28.51,0.226
171.32,-28.44,0.226
171.33,-28.38,0.226
171.33,-28.31,0.226
171.34,-28.24,0.226
171.35,-28.18,0.226
171.35,-28.11,0.226
171.36,-28.04,0.226
171.37,-27.98,0.226
171.38,-27.91,0.226
171.38,-27.84,0.226
171.39,-27.78,0.226
171.40,-27.71,0.226
171.40,-27.64,0.226
171.41,-27.57,0.226
171.42,-27.51,0.226
171.42,-27.44,0.226
171.43,-27.37,0.226
171.43,-27.31,0.226
171.44,-27.24,0.226
171.45,-27.18,0.226
171.45,-27.11,0.226
171.46,-27.04,0.226
171.47,-26.98,0.226
171.48,-26.91,0.226
171.48,-26.84,0.226
171.49,-26.77,0.226
171.50,-26.71,0.226
171.50,-26.64,0.227
171.51,-26.57,0.227
171.52,-26.51,0.227
171.52,-26.44,0.227
171.53,-26.37,0.227
171.53,-26.31,0.227
171.54,-26.24,0.227
171.55,-26.17,0.227
171.55,-26.11,0.227
171.56,-26.04,0.227
171.57,-25.97,0.227
171.58,-25.91,0.227
171.58,-25.84,0.227
171.59,-25.77,0.227
171.60,-25.71,0.227
171.60,-25.64,0.227
171.61,-25.57,0.227
171.62,-25.51,0.227
171.62,-25.44,0.227
171.63,-25.37,0.227
171.63,-25.31,0.227
171.64,-25.24,0.227
171.65,-25.17,0.227
171.65,-25.10,0.227
171.66,-25.04,0.227
171.67,-24.97,0.227
171.68,-24.90,0.227
171.68,-24.84,0.227
171.69,-24.77,0.227
171.70,-24.70,0.228
171.70,-24.64,0.228
171.71,-24.57,0.228
171.72,-24.51,0.228
171.72,-24.44,0.228
171.73,-24.37,0.228
171.73,-24.30,0.228
171.74,-24.24,0.228
171.75,-24.17,0.228
171.75,-24.10,0.228
171.76,-24.04,0.228
171.77,-23.97,0.228
171.78,-23.90,0.228
171.78,-23.84,0.228
171.79,-23.77,0.228
171.80,-23.70,0.228
171.80,-23.64,0.228
171.81,-23.57,0.228
171.82,-23.50,0.228
171.82,-23.43,0.228
171.83,-23.37,0.228
171.83,-23.30,0.228
171.84,-23.24,0.228
171.85,-23.17,0.228
171.85,-23.10,0.228
171.86,-23.04,0.228
171.87,-22.97,0.228
171.88,-22.90,0.228
171.88,-22.83,0.228
171.89,-22.77,0.228
171.90,-22.70,0.228
171.90,-22.63,0.228
171.91,-22.57,0.228
171.92,-22.50,0.228
171.92,-22.43,0.228
171.93,-22.37,0.229
171.93,-22.30,0.229
171.94,-22.23,0.229
171.95,-22.17,0.229
171.95,-22.10,0.229
171.96,-22.03,0.229
171.97,-21.97,0.229
171.98,-21.90,0.229
171.98,-21.84,0.229
171.99,-21.77,0.229
172.00,-21.70,0.229
172.00,-21.63,0.229
172.01,-21.57,0.229
172.02,-21.50,0.229
172.02,-21.43,0.229
172.03,-21.37,0.229
172.03,-21.30,0.229
172.04,-21.23,0.229
172.05,-21.17,0.229
172.05,-21.10,0.229
172.06,-21.03,0.229
172.07,-20.97,0.229
172.08,-20.90,0.229
172.08,-20.83,0.229
172.09,-20.77,0.229
172.10,-20.70,0.229
172.10,-20.63,0.229
172.11,-20.57,0.229
172.12,-20.50,0.229
172.12,-20.43,0.229
172.13,-20.36,0.229
172.13,-20.30,0.229
172.14,-20.23,0.229
172.15,-20.17,0.229
172.15,-20.10,0.229
172.16,-20.03,0.229
172.17,-19.96,0.229
172.18,-19.90,0.229
172.18,-19.83,0.230
172.19,-19.76,0.230
172.20,-19.70,0.230
172.20,-19.63,0.230
172.21,-19.56,0.230
172.22,-19.50,0.230
172.22,-19.43,0.230
172.23,-19.36,0.230
172.23,-19.30,0.230
172.24,-19.23,0.230
172.25,-19.16,0.230
172.25,-19.10,0.230
172.26,-19.03,0.230
172.27,-18.96,0.230
172.28,-18.90,0.230
172.28,-18.83,0.230
172.29,-18.76,0.230
172.30,-18.70,0.230
172.30,-18.63,0.230
172.31,-18.56,0.230
172.32,-18.50,0.230
172.32,-18.43,0.230
172.33,-18.36,0.230
172.33,-18.30,0.230
172.34,-18.23,0.230
172.35,-18.16,0.230
172.35,-18.09,0.230
172.36,-18.03,0.230
172.37,-17.96,0.230
172.38,-17.90,0.230
172.38,-17.83,0.230
172.39,-17.76,0.230
172.40,-17.69,0.230
172.40,-17.63,0.230
172.41,-17.56,0.231
172.42,-17.49,0.231
172.42,-17.43,0.231
172.43,-17.36,0.231
172.43,-17.29,0.231
172.44,-17.23,0.231
172.45,-17.16,0.231
172.45,-17.10,0.231
172.46,-17.03,0.231
172.47,-16.96,0.231
172.48,-16.89,0.231
172.48,-16.83,0.231
172.49,-16.76,0.231
172.50,-16.69,0.231
172.50,-16.63,0.231
172.51,-16.56,0.231
172.52,-16.49,0.231
172.52,-16.43,0.231
172.53,-16.36,0.231
172.53,-16.29,0.231
172.54,-16.23,0.231
172.55,-16.16,0.231
172.55,-16.09,0.231
172.56,-16.03,0.231
172.57,-15.96,0.231
172.58,-15.89,0.231
172.58,-15.83,0.231
172.59,-15.76,0.231
172.60,-15.69,0.231
172.60,-15.62,0.231
172.61,-15.56,0.231
172.62,-15.49,0.231
172.62,-15.43,0.231
172.63,-15.36,0.232
172.63,-15.29,0.232
172.64,-15.22,0.232
172.65,-15.16,0.232
172.65,-15.09,0.232
172.66,-15.02,0.232
172.67,-14.96,0.232
172.68,-14.89,0.232
172.68,-14.82,0.232
172.69,-14.76,0.232
172.70,-14.69,0.232
172.70,-14.63,0.232
172.71,-14.56,0.232
172.72,-14.49,0.232
172.72,-14.42,0.232
172.73,-14.36,0.232
172.73,-14.29,0.232
172.74,-14.22,0.232
172.75,-14.16,0.232
172.75,-14.09,0.232
172.76,-14.02,0.232
172.77,-13.96,0.232
172.78,-13.89,0.232
172.78,-13.82,0.232
172.79,-13.76,0.232
172.80,-13.69,0.232
172.80,-13.62,0.232
172.81,-13.56,0.232
172.82,-13.49,0.232
172.82,-13.42,0.232
172.83,-13.36,0.232
172.83,-13.29,0.233
172.84,-13.22,0.233
172.85,-13.16,0.233
172.85,-13.09,0.233
172.86,-13.02,0.233
172.87,-12.96,0.233
172.88,-12.89,0.233
172.88,-12.82,0.233
172.89,-12.76,0.233
172.90,-12.69,0.233
172.90,-12.62,0.233
172.91,-12.56,0.233
172.92,-12.49,0.233
172.92,-12.42,0.233
172.93,-12.35,0.233
172.93,-12.29,0.233
172.94,-12.22,0.233
172.95,-12.15,0.233
172.95,-12.09,0.233
172.96,-12.02,0.233
172.97,-11.95,0.233
172.98,-11.89,0.233
172.98,-11.82,0.233
172.99,-11.75,0.233
173.00,-11.69,0.233
173.00,-11.62,0.233
173.01,-11.55,0.233
173.02,-11.49,0.233
173.02,-11.42,0.234
173.03,-11.35,0.234
173.03,-11.29,0.234
173.04,-11.22,0.234
173.05,-11.15,0.234
173.05,-11.09,0.234
173.06,-11.02,0.234
173.07,-10.95,0.234
173.08,-10.89,0.234
173.08,-10.82,0.234
173.09,-10.75,0.234
173.10,-10.69,0.234
173.10,-10.62,0.234
173.11,-10.55,0.234
173.12,-10.49,0.234
173.12,-10.42,0.234
173.13,-10.35,0.234
173.13,-10.29,0.234
173.14,-10.22,0.234
173.15,-10.15,0.234
173.15,-10.08,0.234
173.16,-10.02,0.234
173.17,-9.95,0.234
173.18,-9.88,0.234
173.18,-9.82,0.234
173.19,-9.75,0.234
173.20,-9.69,0.234
173.20,-9.62,0.234
173.21,-9.55,0.234
173.22,-9.48,0.234
173.22,-9.42,0.234
173.23,-9.35,0.234
173.23,-9.28,0.234
173.24,-9.22,0.234
173.25,-9.15,0.235
173.25,-9.08,0.235
173.26,-9.02,0.235
173.27,-8.95,0.235
173.28,-8.88,0.235
173.28,-8.82,0.235
173.29,-8.75,0.235
173.30,-8.68,0.235
173.30,-8.62,0.235
173.31,-8.55,0.235
173.32,-8.48,0.235
173.32,-8.42,0.235
173.33,-8.35,0.235
173.33,-8.28,0.235
173.34,-8.22,0.235
173.35,-8.15,0.235
173.35,-8.08,0.235
173.36,-8.02,0.235
173.37,-7.95,0.235
173.38,-7.88,0.235
173.38,-7.82,0.235
173.39,-7.75,0.235
173.40,-7.68,0.235
173.40,-7.62,0.235
173.41,-7.55,0.235
173.42,-7.48,0.235
173.42,-7.41,0.235
173.43,-7.35,0.235
173.43,-7.28,0.235
173.44,-7.22,0.235
173.45,-7.15,0.235
173.45,-7.08,0.235
173.46,-7.01,0.236
173.47,-6.95,0.236
173.48,-6.88,0.236
173.48,-6.82,0.236
173.49,-6.75,0.236
173.50,-6.68,0.236
173.50,-6.61,0.236
173.51,-6.55,0.236
173.52,-6.48,0.236
173.52,-6.41,0.236
173.53,-6.35,0.236
173.53,-6.28,0.236
173.54,-6.21,0.236
173.55,-6.15,0.236
173.55,-6.08,0.236
173.56,-6.01,0.236
173.57,-5.95,0.236
173.58,-5.88,0.236
173.58,-5.81,0.236
173.59,-5.75,0.236
173.60,-5.68,0.236
173.60,-5.61,0.236
173.61,-5.55,0.236
173.62,-5.48,0.236
173.62,-5.41,0.236
173.63,-5.35,0.236
173.63,-5.28,0.236
173.64,-5.21,0.236
173.65,-5.14,0.236
173.65,-5.08,0.236
173.66,-5.01,0.237
173.67,-4.95,0.237
173.68,-4.88,0.237
173.68,-4.81,0.237
173.69,-4.74,0.237
173.70,-4.68,0.237
173.70,-4.61,0.237
173.71,-4.55,0.237
173.72,-4.48,0.237
173.72,-4.41,0.237
173.73,-4.34,0.237
173.73,-4.28,0.237
173.74,-4.21,0.237
173.75,-4.15,0.237
173.75,-4.08,0.237
173.76,-4.01,0.237
173.77,-3.94,0.237
173.78,-3.88,0.237
173.78,-3.81,0.237
173.79,-3.74,0.237
173.80,-3.68,0.237
173.80,-3.61,0.237
173.81,-3.55,0.237
173.82,-3.48,0.237
173.82,-3.41,0.237
173.83,-3.34,0.237
173.83,-3.28,0.237
173.84,-3.21,0.237
173.85,-3.14,0.238
173.85,-3.08,0.238
173.86,-3.01,0.238
173.87,-2.94,0.238
173.88,-2.88,0.238
173.88,-2.81,0.238
173.89,-2.74,0.238
173.90,-2.68,0.238
173.90,-2.61,0.238
173.91,-2.54,0.238
173.92,-2.48,0.238
173.92,-2.41,0.238
173.93,-2.34,0.238
173.93,-2.28,0.238
173.94,-2.21,0.238
173.95,-2.14,0.238
173.95,-2.07,0.238
173.96,-2.01,0.238
173.97,-1.94,0.238
173.98,-1.87,0.238
173.98,-1.81,0.239
173.99,-1.74,0.239
174.00,-1.67,0.239
174.00,-1.61,0.239
174.01,-1.54,0.239
174.02,-1.47,0.239
174.02,-1.41,0.239
174.03,-1.34,0.239
174.03,-1.27,0.239
174.04,-1.21,0.239
174.05,-1.14,0.239
174.05,-1.07,0.239
174.06,-1.01,0.239
174.07,-0.94,0.239
174.08,-0.87,0.239
174.08,-0.81,0.239
174.09,-0.74,0.239
174.10,-0.67,0.239
174.10,-0.61,0.239
174.11,-0.54,0.239
174.12,-0.47,0.239
174.12,-0.41,0.239
174.13,-0.34,0.240
174.13,-0.27,0.240
174.14,-0.20,0.240
174.15,-0.14,0.240
174.15,-0.07,0.240
174.16,0.00,0.240
174.17,0.06,0.240
174.18,0.13,0.240
174.18,0.19,0.240
174.19,0.26,0.240
174.20,0.33,0.240
174.20,0.40,0.240
174.21,0.46,0.240
174.22,0.53,0.240
174.22,0.60,0.240
174.23,0.66,0.240
174.23,0.73,0.240
174.24,0.80,0.240
174.25,0.86,0.240
174.25,0.93,0.240
174.26,1.00,0.240
174.27,1.06,0.241
174.28,1.13,0.241
174.28,1.20,0.241
174.29,1.26,0.241
174.30,1.33,0.241
174.30,1.40,0.241
174.31,1.46,0.241
174.32,1.53,0.241
174.32,1.60,0.241
174.33,1.66,0.241
174.33,1.73,0.241
174.34,1.80,0.241
174.35,1.87,0.241
174.35,1.93,0.241
174.36,2.00,0.241
174.37,2.07,0.241
174.38,2.13,0.241
174.38,2.20,0.241
174.39,2.26,0.241
174.40,2.33,0.241
174.40,2.40,0.241
174.41,2.47,0.241
174.42,2.53,0.241
174.42,2.60,0.241
174.43,2.66,0.241
174.43,2.73,0.241
174.44,2.80,0.241
174.45,2.86,0.242
174.45,2.93,0.242
174.46,3.00,0.242
174.47,3.07,0.242
174.48,3.13,0.242
174.48,3.20,0.242
174.49,3.27,0.242
174.50,3.33,0.242
174.50,3.40,0.242
174.51,3.47,0.242
174.52,3.53,0.242
174.52,3.60,0.242
174.53,3.67,0.242
174.53,3.73,0.242
174.54,3.80,0.242
174.55,3.87,0.242
174.55,3.93,0.242
174.56,4.00,0.242
174.57,4.07,0.242
174.58,4.13,0.242
174.58,4.20,0.242
174.59,4.27,0.242
174.60,4.34,0.242
174.60,4.40,0.242
174.61,4.47,0.242
174.62,4.53,0.242
174.62,4.60,0.243
174.63,4.67,0.243
174.63,4.74,0.243
174.64,4.80,0.243
174.65,4.87,0.243
174.65,4.94,0.243
174.66,5.00,0.243
174.67,5.07,0.243
174.68,5.14,0.243
174.68,5.20,0.243
174.69,5.27,0.243
174.70,5.34,0.243
174.70,5.40,0.243
174.71,5.47,0.243
174.72,5.54,0.243
174.72,5.60,0.243
174.73,5.67,0.243
174.73,5.74,0.243
174.74,5.80,0.243
174.75,5.87,0.243
174.75,5.94,0.243
174.76,6.00,0.244
174.77,6.07,0.244
174.78,6.14,0.244
174.78,6.20,0.244
174.79,6.27,0.244
174.80,6.34,0.244
174.80,6.40,0.244
174.81,6.47,0.244
174.82,6.54,0.244
174.82,6.60,0.244
174.83,6.67,0.244
174.83,6.74,0.244
174.84,6.80,0.244
174.85,6.87,0.244
174.85,6.94,0.244
174.86,7.00,0.244
174.87,7.07,0.244
174.88,7.14,0.244
174.88,7.20,0.244
174.89,7.27,0.244
174.90,7.34,0.244
174.90,7.40,0.244
174.91,7.47,0.244
174.92,7.54,0.244
174.92,7.60,0.244
174.93,7.67,0.244
174.93,7.74,0.244
174.94,7.80,0.245
174.95,7.87,0.245
174.95,7.94,0.245
174.96,8.01,0.245
174.97,8.07,0.245
174.98,8.14,0.245
174.98,8.21,0.245
174.99,8.27,0.245
175.00,8.34,0.245
175.00,8.41,0.245
175.01,8.47,0.245
175.02,8.54,0.245
175.02,8.61,0.245
175.03,8.67,0.245
175.03,8.74,0.245
175.04,8.81,0.245
175.05,8.87,0.245
175.05,8.94,0.245
175.06,9.01,0.245
175.07,9.07,0.245
175.08,9.14,0.245
175.08,9.21,0.245
175.09,9.27,0.245
175.10,9.34,0.245
175.10,9.41,0.245
175.11,9.47,0.246
175.12,9.54,0.246
175.12,9.61,0.246
175.13,9.67,0.246
175.13,9.74,0.246
175.14,9.81,0.246
175.15,9.87,0.246
175.15,9.94,0.246
175.16,10.01,0.246
175.17,10.08,0.246
175.18,10.14,0.246
175.18,10.21,0.246
175.19,10.27,0.246
175.20,10.34,0.246
175.20,10.41,0.246
175.21,10.47,0.246
175.22,10.54,0.246
175.22,10.61,0.246
175.23,10.68,0.246
175.23,10.74,0.246
175.24,10.81,0.246
175.25,10.87,0.247
175.25,10.94,0.247
175.26,11.01,0.247
175.27,11.08,0.247
175.28,11.14,0.247
175.28,11.21,0.247
175.29,11.28,0.247
175.30,11.34,0.247
175.30,11.41,0.247
175.31,11.48,0.247
175.32,11.54,0.247
175.32,11.61,0.247
175.33,11.68,0.247
175.33,11.74,0.247
175.34,11.81,0.247
175.35,11.88,0.247
175.35,11.94,0.247
175.36,12.01,0.247
175.37,12.08,0.247
175.38,12.14,0.247
175.38,12.21,0.247
175.39,12.28,0.247
175.40,12.34,0.248
175.40,12.41,0.248
175.41,12.48,0.248
175.42,12.54,0.248
175.42,12.61,0.248
175.43,12.68,0.248
175.43,12.74,0.248
175.44,12.81,0.248
175.45,12.88,0.248
175.45,12.94,0.248
175.46,13.01,0.248
175.47,13.08,0.248
175.48,13.14,0.248
175.48,13.21,0.248
175.49,13.28,0.248
175.50,13.34,0.248
175.50,13.41,0.248
175.51,13.48,0.248
175.52,13.54,0.248
175.52,13.61,0.248
175.53,13.68,0.249
175.53,13.74,0.249
175.54,13.81,0.249
175.55,13.88,0.249
175.55,13.94,0.249
175.56,14.01,0.249
175.57,14.08,0.249
175.58,14.15,0.249
175.58,14.21,0.249
175.59,14.28,0.249
175.60,14.34,0.249
175.60,14.41,0.249
175.61,14.48,0.249
175.62,14.55,0.249
175.62,14.61,0.249
175.63,14.68,0.249
175.63,14.75,0.249
175.64,14.81,0.249
175.65,14.88,0.249
175.65,14.94,0.249
175.66,15.01,0.249
175.67,15.08,0.249
175.68,15.15,0.249
175.68,15.21,0.250
175.69,15.28,0.250
175.70,15.35,0.250
175.70,15.41,0.250
175.71,15.48,0.250
175.72,15.55,0.250
175.72,15.61,0.250
175.73,15.68,0.250
175.73,15.75,0.250
175.74,15.81,0.250
175.75,15.88,0.250
175.75,15.95,0.250
175.76,16.01,0.250
175.77,16.08,0.250
175.78,16.15,0.250
175.78,16.21,0.250
175.79,16.28,0.250
175.80,16.35,0.250
175.80,16.41,0.250
175.81,16.48,0.251
175.82,16.55,0.251
175.82,16.61,0.251
175.83,16.68,0.251
175.83,16.75,0.251
175.84,16.81,0.251
175.85,16.88,0.251
175.85,16.95,0.251
175.86,17.01,0.251
175.87,17.08,0.251
175.88,17.15,0.251
175.88,17.21,0.251
175.89,17.28,0.251
175.90,17.35,0.251
175.90,17.41,0.251
175.91,17.48,0.251
175.92,17.55,0.251
175.92,17.61,0.251
175.93,17.68,0.251
175.93,17.75,0.251
175.94,17.82,0.252
175.95,17.88,0.252
175.95,17.95,0.252
175.96,18.01,0.252
175.97,18.08,0.252
175.98,18.15,0.252
175.98,18.22,0.252
175.99,18.28,0.252
176.00,18.35,0.252
176.00,18.41,0.252
176.01,18.48,0.252
176.02,18.55,0.252
176.02,18.62,0.252
176.03,18.68,0.252
176.03,18.75,0.252
176.04,18.82,0.252
176.05,18.88,0.252
176.05,18.95,0.252
176.06,19.02,0.252
176.07,19.08,0.253
176.08,19.15,0.253
176.08,19.22,0.253
176.09,19.28,0.253
176.10,19.35,0.253
176.10,19.42,0.253
176.11,19.48,0.253
176.12,19.55,0.253
176.12,19.62,0.253
176.13,19.68,0.253
176.13,19.75,0.253
176.14,19.82,0.253
176.15,19.88,0.253
176.15,19.95,0.253
176.16,20.02,0.253
176.17,20.08,0.253
176.18,20.15,0.254
176.18,20.22,0.254
176.19,20.28,0.254
176.20,20.35,0.254
176.20,20.42,0.254
176.21,20.48,0.254
176.22,20.55,0.254
176.22,20.62,0.254
176.23,20.68,0.254
176.23,20.75,0.254
176.24,20.82,0.254
176.25,20.88,0.254
176.25,20.95,0.254
176.26,21.02,0.254
176.27,21.08,0.254
176.28,21.15,0.254
176.28,21.22,0.254
176.29,21.29,0.255
176.30,21.35,0.255
176.30,21.42,0.255
176.31,21.49,0.255
176.32,21.55,0.255
176.32,21.62,0.255
176.33,21.69,0.255
176.33,21.75,0.255
176.34,21.82,0.255
176.35,21.89,0.255
176.35,21.95,0.255
176.36,22.02,0.255
176.37,22.09,0.255
176.38,22.15,0.255
176.38,22.22,0.255
176.39,22.29,0.255
176.40,22.35,0.255
176.40,22.42,0.256
176.41,22.49,0.256
176.42,22.55,0.256
176.42,22.62,0.256
176.43,22.69,0.256
176.43,22.75,0.256
176.44,22.82,0.256
176.45,22.89,0.256
176.45,22.95,0.256
176.46,23.02,0.256
176.47,23.09,0.256
176.48,23.16,0.256
176.48,23.22,0.256
176.49,23.29,0.256
176.50,23.35,0.256
176.50,23.42,0.256
176.51,23.49,0.256
176.52,23.55,0.256
176.52,23.62,0.256
176.53,23.69,0.257
176.53,23.76,0.257
176.54,23.82,0.257
176.55,23.89,0.257
176.55,23.95,0.257
176.56,24.02,0.257
176.57,24.09,0.257
176.58,24.16,0.257
176.58,24.22,0.257
176.59,24.29,0.257
176.60,24.36,0.257
176.60,24.42,0.257
176.61,24.49,0.257
176.62,24.56,0.257
176.62,24.62,0.257
176.63,24.69,0.257
176.63,24.76,0.257
176.64,24.82,0.257
176.65,24.89,0.258
176.65,24.96,0.258
176.66,25.02,0.258
176.67,25.09,0.258
176.68,25.16,0.258
176.68,25.22,0.258
176.69,25.29,0.258
176.70,25.36,0.258
176.70,25.42,0.258
176.71,25.49,0.258
176.72,25.56,0.258
176.72,25.62,0.258
176.73,25.69,0.258
176.73,25.76,0.258
176.74,25.82,0.258
176.75,25.89,0.258
176.75,25.96,0.258
176.76,26.03,0.258
176.77,26.09,0.259
176.78,26.16,0.259
176.78,26.22,0.259
176.79,26.29,0.259
176.80,26.36,0.259
176.80,26.43,0.259
176.81,26.49,0.259
176.82,26.56,0.259
176.82,26.63,0.259
176.83,26.69,0.259
176.83,26.76,0.259
176.84,26.83,0.259
176.85,26.89,0.259
176.85,26.96,0.259
176.86,27.03,0.259
176.87,27.09,0.259
176.88,27.16,0.259
176.88,27.23,0.260
176.89,27.29,0.260
176.90,27.36,0.260
176.90,27.43,0.260
176.91,27.49,0.260
176.92,27.56,0.260
176.92,27.63,0.260
176.93,27.69,0.260
176.93,27.76,0.260
176.94,27.83,
176.95,27.89,
176.95,27.96,
176.96,28.03,
176.97,28.09,
176.98,28.16,
176.98,28.23,
176.99,,
176.99,,