File: DSC/2025_06_14_CBN_Saccharin_Slurry_n60C_200C_10Cmin_x3.csv
Filename,2025_06_14_CBN_Saccharin_Slurry_n60C_200C_10Cmin_x3
Instrument name,DSC2A-00468 (192.168.1.100)
Operator,Yarger
rundate,6/14/2025
Sample name,2025_06_14_CBN_Saccharin_Slurry_n60C_200C_10Cmin_x3
proceduresegments,Data Off ; Equilibrate -60.00 °C; Data On ; Ramp 10.00 °C/min to 200.00 °C; Data Off ; Isothermal 2.0 min; Data On ; Ramp 10.00 °C/min to -60.00 °C; Data Off ; Isothermal 2.0 min; Data On ; Ramp 10.00 °C/min to 200.00 °C; Data Off ; Isothermal 2.0 min; Data On ; Ramp 10.00 °C/min to -60.00 °C; Data Off ; Isothermal 2.0 min; Data On ; Ramp 10.00 °C/min to 30.00 °C
[File Parameters]
Run date,6/14/2025 11:00:03 PM
Trios version,5.1.1.46572
Original File Name,
Current File Name,D:\DSC2500\JYarger\2025_06_14_CBN_Saccharin_Slurry_n60C_200C_10Cmin_x3.tri
[Procedure]
Procedure Name,CBN_Saccharin_n60C_200C_10Cmin_x3
Sample Name,2025_06_14_CBN_Saccharin_Slurry_n60C_200C_10Cmin_x3
Sample Mass,3.74 mg
Reference Sample Mass,0 mg
Pan Mass,57.54 mg
Pan Number,38
Reference Pan Mass,57.05 mg
Reference Pan Number,28
Pan Type,Tzero Aluminum Hermetic
Comments,Al Hermetic DSC Consumables sealed Pan/Lid. A2 Tray (Google Sheet: DSC_Samples_A2_Tray_May2025)
Project Name,CA
Operator,Yarger
Test,Custom
Unload Max Temperature,30
Unload Min Temperature,30
Load Max Temperature,30
Load Min Temperature,30
Stop on Gas Flow Error,Yes
[Signal List]
Signal #1,Time (min)
Signal #2,Temperature (°C)
Signal #3,Heat Flow (mW)
Signal #4,Delta T (µV)
Signal #5,Delta Tzero (µV)
Signal #6,Tzero Temperature (°C)
Signal #7,Cell Purge (mL/min)
Signal #8,Heater Temp (°C)
Signal #9,Power Delivered (W)
Signal #10,Reference Junction Temperature (°C)
Signal #11,Flange Temperature (°C)
Signal #12,Heat Flow Phase (rad)
Signal #13,Total Heat Capacity (J/°C)
Signal #14,Heat Capacity (J/°C)
[Configuration]
Company Name,ASU
Instrument Name,DSC2A-00468
Instrument Type,DSC2500
Serial Number,DSC2A-00468
IP,192.168.1.100
Location of Instrument,MRRC
DisplayType,Unknown
Sample Interval ,0.1 s/pt
Selected Heat Flow,T4P
Exotherm Direction,Down
Cell Serial,DRC2-00792
Lid Type,Standard
Cooler,RCS 90
Leave Cooler on at End of Sequence,On
Gas 2,Nitrogen
Gas Selected,Channel 1
Flow Rate,50 mL/min
Secondary Purge,On
Licensed Heat Flow,Heat Flow T4P
Modulation Licensed,Yes
[Versions]
Common IDD Version,1
Cortex Version,VER 2.10.2.31
Driver,5.0.0.6
GDM Version,1.0.3.3
TouchscreenVersion,1.0.0.16145
FEP Version,1.2.1.21
FEP Bootloader,2.0.0.5
AutoSampler Version,2.1.1.26
Auto Sampler Bootloader,2.0.0.5
FCM Version,1.1.0.3
FCM Bootloader,2.0.0.5
[Experiment Logs]
Experiment Log Entry # 1,Data On set to 0
Experiment Log Entry # 3,Equilibrate Segment -60 (C) Started
Experiment Log Entry # 5,Air Cool is off.
Experiment Log Entry # 7,Data On set to 1
Experiment Log Entry # 9,Ramp Segment 10 C/min to 200 Started
Experiment Log Entry # 11,Data On set to 0
Experiment Log Entry # 13,Isothermal Segment 2 min started
Experiment Log Entry # 15,Data On set to 1
Experiment Log Entry # 17,Ramp Segment 10 C/min to -60 Started
Experiment Log Entry # 19,FEP has detected that FCM has gone offline
Experiment Log Entry # 21,Data On set to 0
Experiment Log Entry # 23,Isothermal Segment 2 min started
Experiment Log Entry # 25,Data On set to 1
Experiment Log Entry # 27,Ramp Segment 10 C/min to 200 Started
Experiment Log Entry # 29,Data On set to 0
Experiment Log Entry # 31,Isothermal Segment 2 min started
Experiment Log Entry # 33,Data On set to 1
Experiment Log Entry # 35,Ramp Segment 10 C/min to -60 Started
Experiment Log Entry # 37,Data On set to 0
Experiment Log Entry # 39,Isothermal Segment 2 min started
Experiment Log Entry # 41,Data On set to 1
Experiment Log Entry # 43,Ramp Segment 10 C/min to 30 Started
[Method Log]
Method Log Entry # 1,Data Off
Method Log Entry # 2,Equilibrate -60 °C
Method Log Entry # 3,Data On
Method Log Entry # 4,(Ramp 219783) Ramp 10 °C/minute to 200 °C
Method Log Entry # 5,Data Off
Method Log Entry # 6,Isothermal 2 minutes
Method Log Entry # 7,Data On
Method Log Entry # 8,(Ramp 219787) Ramp 10 °C/minute to -60 °C
Method Log Entry # 9,Data Off
Method Log Entry # 10,Isothermal 2 minutes
Method Log Entry # 11,Data On
Method Log Entry # 12,(Ramp 219791) Ramp 10 °C/minute to 200 °C
Method Log Entry # 13,Data Off
Method Log Entry # 14,Isothermal 2 minutes
Method Log Entry # 15,Data On
Method Log Entry # 16,(Ramp 219795) Ramp 10 °C/minute to -60 °C
Method Log Entry # 17,Data Off
Method Log Entry # 18,Isothermal 2 minutes
Method Log Entry # 19,Data On
Method Log Entry # 20,(Ramp 219799) Ramp 10 °C/minute to 30 °C
Cell Serial,DRC2-00792
[T1 Calibration]
Slope,-0.008529666
Offset,9.636258
Initial Temperature,98.23
GUID,f8bfdadc-4977-4fdf-ba6d-0ba9134940c3
[TZero Calibration]
Date Applied,11/29/2022 4:06:13 PM
Description,From -89.059 °C to 396.009 °C at 20.000°C/min
Gas Type,Nitrogen
Pan Type,None
Source Files 1,C:\Users\yargerlab\Desktop\DSC Data\General\TZero_calibration_11_29_22_2nd(2).tri
Source Files 2,C:\Users\yargerlab\Desktop\DSC Data\General\TZero_calibration_11_29_22_2nd(3).tri
Delta T Offset,13.05235
Delta T Slope,-0.007271007
Delta T0 Offset,-13.69128
Delta T0 Slope,0.06063341
[Temperature Calibration]
Date Applied,11/29/2022 7:12:28 PM
Description,From 106.590 °C to 186.590 °C at 10.000°C/min
Gas Type,Nitrogen
Pan Type,Tzero Aluminum Hermetic
Source Files 1,C:\Users\yargerlab\Desktop\DSC Data\General\Indium(6).tri
Measured 1,157.391
Known 1,156.598
[Cell Constant Calibration]
Date Applied,11/29/2022 7:12:29 PM
Description,From 106.590 °C to 186.590 °C at 10.000°C/min
Gas Type,Nitrogen
Pan Type,Tzero Aluminum Hermetic
Source Files 1,C:\Users\yargerlab\Desktop\DSC Data\General\Indium(6).tri
T4P KCell,1.006051
Onset Slope,63.26126 mW/°C
[Direct Cp Calibration]
Date Applied,11/30/2022 11:04:51 AM
Description,From -79.983 °C to 298.409 °C at 10.000°C/min
Gas Type,Nitrogen
Pan Type,Tzero Aluminum Hermetic
Source Files 1,C:\Users\yargerlab\Desktop\DSC Data\General\Sapphire_Heat_Capacity_11_30_22.tri
[Rev Cp Calibration]
Date Applied,11/30/2022 1:58:51 PM
Description,From -79.996 °C to 292.812 °C at 3.000°C/min
Gas Type,Nitrogen
Pan Type,Tzero Aluminum Hermetic
Source Files 1,C:\Users\yargerlab\Desktop\DSC Data\General\Sapphire_MDSC_Calibration_11_30_22.tri
[step]
Ramp 10.00 °C/min to 200.00 °C
Time,Temperature,Heat Flow (Normalized)
min,°C,W/g
0.00,-59.67,-0.091
0.02,-59.69,-0.089
0.04,-59.69,-0.082
0.05,-59.69,-0.080
0.07,-59.67,-0.088
0.09,-59.63,-0.122
0.11,-59.56,-0.145
0.13,-59.48,-0.164
0.15,-59.38,-0.172
0.16,-59.26,-0.170
0.18,-59.14,-0.161
0.20,-59.00,-0.136
0.22,-58.86,-0.112
0.24,-58.72,-0.089
0.26,-58.57,-0.065
0.28,-58.41,-0.043
0.29,-58.26,-0.022
0.31,-58.10,-0.005
0.33,-57.94,0.009
0.35,-57.78,0.022
0.37,-57.61,0.033
0.39,-57.44,0.045
0.40,-57.28,0.052
0.42,-57.10,0.061
0.44,-56.93,0.068
0.46,-56.76,0.075
0.48,-56.59,0.079
0.50,-56.41,0.084
0.51,-56.24,0.088
0.53,-56.06,0.092
0.55,-55.89,0.095
0.57,-55.71,0.098
0.59,-55.53,0.101
0.60,-55.36,0.103
0.62,-55.18,0.104
0.64,-55.00,0.106
0.66,-54.82,0.108
0.68,-54.64,0.109
0.70,-54.47,0.110
0.72,-54.29,0.112
0.73,-54.11,0.113
0.75,-53.93,0.114
0.77,-53.75,0.115
0.79,-53.57,0.115
0.81,-53.39,0.116
0.83,-53.21,0.116
0.84,-53.03,0.117
0.86,-52.85,0.118
0.88,-52.67,0.118
0.90,-52.49,0.119
0.92,-52.31,0.120
0.93,-52.12,0.121
0.95,-51.94,0.121
0.97,-51.76,0.122
0.99,-51.58,0.122
1.01,-51.40,0.122
1.03,-51.22,0.122
1.05,-51.04,0.123
1.06,-50.86,0.123
1.08,-50.67,0.123
1.10,-50.49,0.124
1.12,-50.31,0.124
1.14,-50.13,0.124
1.16,-49.94,0.125
1.17,-49.76,0.125
1.19,-49.58,0.125
1.21,-49.40,0.126
1.23,-49.22,0.126
1.25,-49.03,0.126
1.27,-48.85,0.126
1.28,-48.67,0.126
1.30,-48.49,0.127
1.32,-48.30,0.127
1.34,-48.12,0.127
1.36,-47.94,0.127
1.38,-47.76,0.128
1.39,-47.57,0.128
1.41,-47.39,0.128
1.43,-47.21,0.128
1.45,-47.02,0.129
1.47,-46.84,0.129
1.48,-46.66,0.129
1.50,-46.47,0.129
1.52,-46.29,0.129
1.54,-46.11,0.129
1.56,-45.93,0.129
1.58,-45.74,0.129
1.59,-45.56,0.130
1.61,-45.38,0.130
1.63,-45.19,0.130
1.65,-45.01,0.130
1.67,-44.83,0.130
1.69,-44.64,0.130
1.71,-44.46,0.130
1.72,-44.28,0.130
1.74,-44.09,0.130
1.76,-43.91,0.130
1.78,-43.73,0.131
1.80,-43.54,0.131
1.82,-43.36,0.131
1.83,-43.18,0.131
1.85,-42.99,0.131
1.87,-42.81,0.131
1.89,-42.63,0.131
1.91,-42.45,0.131
1.93,-42.26,0.131
1.94,-42.08,0.131
1.96,-41.89,0.131
1.98,-41.71,0.131
2.00,-41.53,0.131
2.02,-41.34,0.131
2.03,-41.16,0.131
2.05,-40.98,0.131
2.07,-40.79,0.131
2.09,-40.61,0.131
2.11,-40.43,0.131
2.13,-40.24,0.131
2.14,-40.06,0.131
2.16,-39.88,0.132
2.18,-39.69,0.132
2.20,-39.51,0.132
2.22,-39.32,0.132
2.24,-39.14,0.132
2.26,-38.96,0.132
2.27,-38.77,0.132
2.29,-38.59,0.132
2.31,-38.41,0.132
2.33,-38.22,0.132
2.35,-38.04,0.132
2.36,-37.86,0.132
2.38,-37.67,0.132
2.40,-37.49,0.132
2.42,-37.31,0.132
2.44,-37.12,0.132
2.46,-36.94,0.132
2.48,-36.76,0.132
2.49,-36.57,0.132
2.51,-36.39,0.132
2.53,-36.20,0.133
2.55,-36.02,0.133
2.57,-35.84,0.133
2.59,-35.65,0.133
2.60,-35.47,0.133
2.62,-35.28,0.133
2.64,-35.10,0.133
2.66,-34.92,0.133
2.68,-34.73,0.133
2.69,-34.55,0.133
2.71,-34.37,0.133
2.73,-34.18,0.133
2.75,-34.00,0.133
2.77,-33.82,0.133
2.79,-33.63,0.133
2.81,-33.45,0.133
2.82,-33.27,0.133
2.84,-33.08,0.133
2.86,-32.90,0.133
2.88,-32.71,0.133
2.90,-32.53,0.133
2.91,-32.35,0.133
2.93,-32.16,0.133
2.95,-31.98,0.133
2.97,-31.80,0.133
2.99,-31.61,0.133
3.01,-31.43,0.133
3.03,-31.25,0.134
3.04,-31.06,0.134
3.06,-30.88,0.134
3.08,-30.70,0.133
3.10,-30.51,0.134
3.12,-30.33,0.134
3.14,-30.15,0.134
3.15,-29.96,0.134
3.17,-29.78,0.134
3.19,-29.60,0.134
3.21,-29.41,0.134
3.23,-29.23,0.134
3.24,-29.05,0.134
3.26,-28.86,0.134
3.28,-28.68,0.134
3.30,-28.49,0.134
3.32,-28.31,0.134
3.34,-28.13,0.134
3.36,-27.94,0.134
3.37,-27.76,0.134
3.39,-27.58,0.134
3.41,-27.39,0.134
3.43,-27.21,0.134
3.45,-27.02,0.134
3.46,-26.84,0.134
3.48,-26.66,0.134
3.50,-26.47,0.134
3.52,-26.29,0.135
3.54,-26.11,0.135
3.56,-25.92,0.135
3.58,-25.74,0.135
3.59,-25.56,0.135
3.61,-25.37,0.135
3.63,-25.19,0.135
3.65,-25.00,0.135
3.67,-24.82,0.135
3.69,-24.64,0.135
3.70,-24.45,0.135
3.72,-24.27,0.135
3.74,-24.09,0.135
3.76,-23.90,0.135
3.78,-23.72,0.135
3.79,-23.54,0.135
3.81,-23.35,0.135
3.83,-23.17,0.135
3.85,-22.98,0.135
3.87,-22.80,0.135
3.89,-22.62,0.135
3.91,-22.43,0.135
3.92,-22.25,0.135
3.94,-22.07,0.136
3.96,-21.88,0.136
3.98,-21.70,0.136
4.00,-21.52,0.136
4.01,-21.33,0.136
4.03,-21.15,0.136
4.05,-20.97,0.136
4.07,-20.78,0.136
4.09,-20.60,0.136
4.11,-20.42,0.136
4.13,-20.23,0.136
4.14,-20.05,0.136
4.16,-19.86,0.136
4.18,-19.68,0.136
4.20,-19.50,0.136
4.22,-19.31,0.136
4.24,-19.13,0.136
4.25,-18.95,0.136
4.27,-18.76,0.136
4.29,-18.58,0.136
4.31,-18.40,0.137
4.33,-18.21,0.137
4.35,-18.03,0.137
4.36,-17.84,0.137
4.38,-17.66,0.137
4.40,-17.48,0.137
4.42,-17.29,0.137
4.44,-17.11,0.137
4.45,-16.93,0.137
4.47,-16.74,0.137
4.49,-16.56,0.137
4.51,-16.38,0.137
4.53,-16.19,0.137
4.55,-16.01,0.137
4.56,-15.83,0.137
4.58,-15.64,0.137
4.60,-15.46,0.137
4.62,-15.27,0.137
4.64,-15.09,0.138
4.66,-14.91,0.138
4.68,-14.72,0.138
4.69,-14.54,0.138
4.71,-14.36,0.138
4.73,-14.17,0.138
4.75,-13.99,0.138
4.77,-13.81,0.138
4.79,-13.62,0.138
4.80,-13.44,0.138
4.82,-13.26,0.138
4.84,-13.07,0.138
4.86,-12.89,0.138
4.88,-12.71,0.138
4.90,-12.52,0.138
4.91,-12.34,0.138
4.93,-12.15,0.138
4.95,-11.97,0.138
4.97,-11.79,0.138
4.99,-11.60,0.138
5.00,-11.42,0.139
5.02,-11.24,0.139
5.04,-11.05,0.139
5.06,-10.87,0.139
5.08,-10.69,0.139
5.10,-10.50,0.139
5.11,-10.32,0.139
5.13,-10.13,0.139
5.15,-9.95,0.139
5.17,-9.77,0.139
5.19,-9.58,0.139
5.21,-9.40,0.139
5.23,-9.22,0.139
5.24,-9.03,0.140
5.26,-8.85,0.140
5.28,-8.67,0.140
5.30,-8.48,0.140
5.32,-8.30,0.140
5.34,-8.12,0.140
5.35,-7.93,0.140
5.37,-7.75,0.140
5.39,-7.57,0.140
5.41,-7.38,0.140
5.43,-7.20,0.140
5.45,-7.02,0.140
5.46,-6.83,0.140
5.48,-6.65,0.141
5.50,-6.47,0.141
5.52,-6.28,0.141
5.54,-6.10,0.141
5.55,-5.92,0.141
5.57,-5.73,0.141
5.59,-5.55,0.141
5.61,-5.36,0.141
5.63,-5.18,0.141
5.65,-5.00,0.141
5.66,-4.81,0.142
5.68,-4.63,0.142
5.70,-4.45,0.142
5.72,-4.26,0.142
5.74,-4.08,0.142
5.76,-3.89,0.142
5.78,-3.71,0.142
5.79,-3.53,0.142
5.81,-3.35,0.142
5.83,-3.16,0.142
5.85,-2.98,0.142
5.87,-2.79,0.143
5.89,-2.61,0.143
5.90,-2.43,0.143
5.92,-2.24,0.143
5.94,-2.06,0.143
5.96,-1.88,0.143
5.98,-1.69,0.143
6.00,-1.51,0.143
6.01,-1.33,0.143
6.03,-1.14,0.143
6.05,-0.96,0.143
6.07,-0.77,0.144
6.09,-0.59,0.144
6.10,-0.41,0.144
6.12,-0.23,0.144
6.14,-0.04,0.144
6.16,0.14,0.144
6.18,0.33,0.144
6.20,0.51,0.144
6.21,0.69,0.144
6.23,0.88,0.144
6.25,1.06,0.145
6.27,1.24,0.145
6.29,1.43,0.145
6.31,1.61,0.145
6.33,1.80,0.145
6.34,1.98,0.145
6.36,2.16,0.145
6.38,2.35,0.145
6.40,2.53,0.145
6.42,2.71,0.145
6.44,2.90,0.145
6.45,3.08,0.146
6.47,3.26,0.146
6.49,3.45,0.146
6.51,3.63,0.146
6.53,3.81,0.146
6.55,4.00,0.146
6.56,4.18,0.146
6.58,4.37,0.146
6.60,4.55,0.146
6.62,4.73,0.146
6.64,4.92,0.146
6.65,5.10,0.147
6.67,5.28,0.147
6.69,5.47,0.147
6.71,5.65,0.147
6.73,5.83,0.147
6.75,6.02,0.147
6.76,6.20,0.147
6.78,6.39,0.147
6.80,6.57,0.147
6.82,6.75,0.147
6.84,6.94,0.147
6.86,7.12,0.148
6.88,7.30,0.148
6.89,7.49,0.148
6.91,7.67,0.148
6.93,7.85,0.148
6.95,8.04,0.148
6.97,8.22,0.148
6.99,8.40,0.148
7.00,8.59,0.148
7.02,8.77,0.149
7.04,8.95,0.149
7.06,9.14,0.149
7.08,9.32,0.149
7.10,9.51,0.149
7.11,9.69,0.149
7.13,9.87,0.149
7.15,10.06,0.149
7.17,10.24,0.149
7.19,10.42,0.149
7.20,10.61,0.150
7.22,10.79,0.150
7.24,10.97,0.150
7.26,11.16,0.150
7.28,11.34,0.150
7.30,11.53,0.150
7.31,11.71,0.150
7.33,11.89,0.150
7.35,12.08,0.150
7.37,12.26,0.151
7.39,12.44,0.151
7.41,12.63,0.151
7.43,12.81,0.151
7.44,12.99,0.151
7.46,13.18,0.151
7.48,13.36,0.151
7.50,13.54,0.151
7.52,13.73,0.151
7.54,13.91,0.152
7.55,14.09,0.152
7.57,14.28,0.152
7.59,14.46,0.152
7.61,14.65,0.152
7.63,14.83,0.152
7.65,15.01,0.152
7.66,15.20,0.152
7.68,15.38,0.152
7.70,15.56,0.152
7.72,15.75,0.153
7.74,15.93,0.153
7.75,16.11,0.153
7.77,16.30,0.153
7.79,16.48,0.153
7.81,16.66,0.153
7.83,16.85,0.153
7.85,17.03,0.153
7.86,17.21,0.153
7.88,17.40,0.154
7.90,17.58,0.154
7.92,17.76,0.154
7.94,17.95,0.154
7.96,18.13,0.154
7.98,18.31,0.154
7.99,18.50,0.154
8.01,18.68,0.154
8.03,18.87,0.155
8.05,19.05,0.155
8.07,19.23,0.155
8.09,19.41,0.155
8.10,19.60,0.155
8.12,19.78,0.155
8.14,19.97,0.155
8.16,20.15,0.155
8.18,20.33,0.155
8.20,20.52,0.156
8.21,20.70,0.156
8.23,20.88,0.156
8.25,21.07,0.156
8.27,21.25,0.156
8.29,21.43,0.156
8.30,21.62,0.156
8.32,21.80,0.156
8.34,21.98,0.156
8.36,22.17,0.157
8.38,22.35,0.157
8.40,22.53,0.157
8.41,22.72,0.157
8.43,22.90,0.157
8.45,23.08,0.157
8.47,23.27,0.158
8.49,23.45,0.158
8.51,23.64,0.158
8.53,23.82,0.158
8.54,24.00,0.158
8.56,24.19,0.158
8.58,24.37,0.158
8.60,24.55,0.158
8.62,24.74,0.159
8.63,24.92,0.159
8.65,25.10,0.159
8.67,25.29,0.159
8.69,25.47,0.159
8.71,25.65,0.159
8.73,25.84,0.159
8.75,26.02,0.159
8.76,26.21,0.159
8.78,26.39,0.160
8.80,26.57,0.160
8.82,26.76,0.160
8.84,26.94,0.160
8.85,27.12,0.160
8.87,27.31,0.160
8.89,27.49,0.160
8.91,27.67,0.160
8.93,27.86,0.160
8.95,28.04,0.161
8.97,28.22,0.161
8.98,28.41,0.161
9.00,28.59,0.161
9.02,28.78,0.161
9.04,28.96,0.161
9.06,29.14,0.161
9.08,29.33,0.161
9.09,29.51,0.161
9.11,29.69,0.162
9.13,29.88,0.162
9.15,30.06,0.162
9.17,30.24,0.162
9.18,30.43,0.162
9.20,30.61,0.162
9.22,30.80,0.162
9.24,30.98,0.163
9.26,31.16,0.163
9.28,31.35,0.163
9.30,31.53,0.163
9.31,31.71,0.163
9.33,31.90,0.164
9.35,32.08,0.164
9.37,32.26,0.164
9.39,32.45,0.164
9.40,32.63,0.164
9.42,32.81,0.164
9.44,33.00,0.164
9.46,33.18,0.165
9.48,33.36,0.165
9.50,33.55,0.165
9.52,33.73,0.165
9.53,33.92,0.165
9.55,34.10,0.165
9.57,34.28,0.165
9.59,34.47,0.165
9.61,34.65,0.166
9.63,34.83,0.166
9.64,35.02,0.166
9.66,35.20,0.166
9.68,35.38,0.166
9.70,35.57,0.166
9.72,35.75,0.167
9.73,35.93,0.167
9.75,36.12,0.167
9.77,36.30,0.167
9.79,36.49,0.167
9.81,36.67,0.167
9.83,36.85,0.167
9.85,37.04,0.167
9.86,37.22,0.168
9.88,37.40,0.168
9.90,37.59,0.168
9.92,37.77,0.168
9.94,37.95,0.168
9.95,38.14,0.168
9.97,38.32,0.168
9.99,38.50,0.169
10.01,38.69,0.169
10.03,38.87,0.169
10.05,39.05,0.169
10.07,39.24,0.169
10.08,39.42,0.169
10.10,39.61,0.169
10.12,39.79,0.169
10.14,39.97,0.169
10.16,40.16,0.170
10.18,40.34,0.170
10.19,40.52,0.170
10.21,40.71,0.170
10.23,40.89,0.170
10.25,41.07,0.170
10.27,41.26,0.170
10.28,41.44,0.170
10.30,41.62,0.171
10.32,41.81,0.171
10.34,41.99,0.171
10.36,42.17,0.171
10.38,42.36,0.171
10.40,42.54,0.171
10.41,42.73,0.172
10.43,42.91,0.172
10.45,43.09,0.172
10.47,43.27,0.172
10.49,43.46,0.172
10.50,43.64,0.172
10.52,43.83,0.172
10.54,44.01,0.173
10.56,44.19,0.173
10.58,44.38,0.173
10.60,44.56,0.173
10.62,44.74,0.173
10.63,44.93,0.173
10.65,45.11,0.173
10.67,45.29,0.174
10.69,45.48,0.174
10.71,45.66,0.174
10.73,45.85,0.174
10.74,46.03,0.175
10.76,46.21,0.175
10.78,46.40,0.175
10.80,46.58,0.175
10.82,46.76,0.175
10.83,46.95,0.176
10.85,47.13,0.176
10.87,47.32,0.176
10.89,47.50,0.176
10.91,47.68,0.176
10.93,47.87,0.177
10.95,48.05,0.177
10.96,48.23,0.177
10.98,48.41,0.178
11.00,48.60,0.178
11.02,48.78,0.178
11.04,48.97,0.178
11.05,49.15,0.178
11.07,49.33,0.179
11.09,49.52,0.179
11.11,49.70,0.179
11.13,49.88,0.179
11.15,50.07,0.179
11.17,50.25,0.180
11.18,50.43,0.180
11.20,50.62,0.180
11.22,50.80,0.180
11.24,50.99,0.181
11.26,51.17,0.181
11.28,51.35,0.181
11.29,51.54,0.181
11.31,51.72,0.181
11.33,51.90,0.182
11.35,52.09,0.182
11.37,52.27,0.182
11.38,52.45,0.182
11.40,52.64,0.183
11.42,52.82,0.183
11.44,53.00,0.183
11.46,53.19,0.184
11.48,53.37,0.184
11.50,53.56,0.184
11.51,53.74,0.184
11.53,53.92,0.184
11.55,54.11,0.185
11.57,54.29,0.185
11.59,54.47,0.185
11.60,54.66,0.185
11.62,54.84,0.185
11.64,55.02,0.186
11.66,55.21,0.186
11.68,55.39,0.186
11.70,55.57,0.186
11.72,55.76,0.186
11.73,55.94,0.187
11.75,56.12,0.187
11.77,56.31,0.187
11.79,56.49,0.187
11.81,56.67,0.187
11.83,56.86,0.188
11.84,57.04,0.188
11.86,57.22,0.188
11.88,57.41,0.188
11.90,57.59,0.188
11.92,57.77,0.188
11.93,57.96,0.189
11.95,58.14,0.189
11.97,58.33,0.189
11.99,58.51,0.189
12.01,58.70,0.190
12.03,58.88,0.190
12.05,59.06,0.190
12.06,59.25,0.191
12.08,59.43,0.191
12.10,59.61,0.191
12.12,59.80,0.192
12.14,59.98,0.192
12.15,60.16,0.192
12.17,60.34,0.192
12.19,60.53,0.193
12.21,60.71,0.193
12.23,60.89,0.193
12.25,61.08,0.193
12.27,61.26,0.194
12.28,61.45,0.194
12.30,61.63,0.194
12.32,61.81,0.195
12.34,62.00,0.195
12.36,62.18,0.195
12.38,62.36,0.196
12.39,62.55,0.196
12.41,62.73,0.196
12.43,62.91,0.197
12.45,63.09,0.197
12.47,63.28,0.197
12.48,63.46,0.198
12.50,63.65,0.198
12.52,63.83,0.199
12.54,64.01,0.199
12.56,64.19,0.200
12.58,64.38,0.201
12.60,64.56,0.201
12.61,64.74,0.202
12.63,64.93,0.203
12.65,65.11,0.203
12.67,65.29,0.204
12.69,65.48,0.204
12.70,65.66,0.204
12.72,65.84,0.204
12.74,66.03,0.205
12.76,66.21,0.206
12.78,66.39,0.207
12.80,66.58,0.209
12.82,66.76,0.210
12.83,66.94,0.211
12.85,67.13,0.212
12.87,67.31,0.213
12.89,67.49,0.214
12.91,67.67,0.214
12.93,67.86,0.215
12.94,68.04,0.216
12.96,68.23,0.218
12.98,68.41,0.220
13.00,68.59,0.222
13.02,68.78,0.226
13.03,68.96,0.227
13.05,69.14,0.230
13.07,69.32,0.232
13.09,69.51,0.236
13.11,69.69,0.238
13.13,69.87,0.244
13.15,70.06,0.248
13.16,70.24,0.254
13.18,70.42,0.261
13.20,70.60,0.267
13.22,70.79,0.273
13.24,70.97,0.280
13.25,71.15,0.288
13.27,71.33,0.299
13.29,71.51,0.313
13.31,71.70,0.325
13.33,71.88,0.337
13.35,72.06,0.354
13.37,72.24,0.376
13.38,72.42,0.399
13.40,72.60,0.423
13.42,72.77,0.453
13.44,72.95,0.487
13.46,73.13,0.527
13.48,73.30,0.572
13.49,73.48,0.631
13.51,73.65,0.699
13.53,73.82,0.786
13.55,73.99,0.889
13.57,74.15,1.010
13.58,74.31,1.147
13.60,74.46,1.290
13.62,74.62,1.419
13.64,74.77,1.510
13.66,74.93,1.565
13.68,75.10,1.595
13.70,75.26,1.605
13.71,75.43,1.619
13.73,75.61,1.618
13.75,75.79,1.570
13.77,75.97,1.465
13.79,76.17,1.366
13.80,76.36,1.276
13.82,76.56,1.190
13.84,76.76,1.136
13.86,76.96,1.088
13.88,77.16,1.035
13.90,77.35,0.979
13.92,77.55,0.919
13.93,77.75,0.852
13.95,77.95,0.788
13.97,78.15,0.716
13.99,78.35,0.640
14.01,78.55,0.558
14.03,78.75,0.494
14.04,78.95,0.446
14.06,79.15,0.407
14.08,79.35,0.379
14.10,79.54,0.356
14.12,79.73,0.339
14.13,79.93,0.326
14.15,80.12,0.312
14.17,80.31,0.301
14.19,80.50,0.291
14.21,80.68,0.283
14.23,80.87,0.275
14.25,81.06,0.271
14.26,81.24,0.266
14.28,81.43,0.261
14.30,81.61,0.259
14.32,81.80,0.258
14.34,81.98,0.255
14.35,82.17,0.253
14.37,82.35,0.251
14.39,82.54,0.250
14.41,82.72,0.248
14.43,82.90,0.247
14.45,83.09,0.247
14.47,83.27,0.247
14.48,83.46,0.246
14.50,83.64,0.246
14.52,83.82,0.245
14.54,84.01,0.245
14.56,84.19,0.245
14.58,84.37,0.244
14.59,84.56,0.244
14.61,84.74,0.244
14.63,84.93,0.243
14.65,85.11,0.243
14.67,85.29,0.243
14.68,85.48,0.243
14.70,85.66,0.242
14.72,85.84,0.242
14.74,86.03,0.242
14.76,86.21,0.242
14.78,86.39,0.242
14.80,86.58,0.242
14.81,86.76,0.242
14.83,86.94,0.242
14.85,87.13,0.242
14.87,87.31,0.241
14.89,87.50,0.241
14.90,87.68,0.241
14.92,87.86,0.241
14.94,88.05,0.241
14.96,88.23,0.241
14.98,88.41,0.241
15.00,88.60,0.241
15.02,88.78,0.241
15.03,88.96,0.241
15.05,89.15,0.241
15.07,89.33,0.241
15.09,89.51,0.241
15.11,89.70,0.241
15.13,89.88,0.242
15.14,90.06,0.242
15.16,90.25,0.242
15.18,90.43,0.242
15.20,90.62,0.242
15.22,90.80,0.242
15.23,90.98,0.242
15.25,91.16,0.242
15.27,91.35,0.242
15.29,91.53,0.242
15.31,91.71,0.242
15.33,91.90,0.242
15.35,92.08,0.242
15.36,92.27,0.242
15.38,92.45,0.242
15.40,92.63,0.242
15.42,92.82,0.243
15.44,93.00,0.243
15.45,93.19,0.243
15.47,93.37,0.243
15.49,93.55,0.243
15.51,93.74,0.243
15.53,93.92,0.243
15.55,94.10,0.243
15.57,94.28,0.243
15.58,94.47,0.244
15.60,94.65,0.244
15.62,94.83,0.244
15.64,95.02,0.244
15.66,95.20,0.244
15.68,95.38,0.244
15.69,95.57,0.244
15.71,95.75,0.244
15.73,95.94,0.244
15.75,96.12,0.244
15.77,96.30,0.244
15.78,96.49,0.244
15.80,96.67,0.244
15.82,96.85,0.245
15.84,97.04,0.245
15.86,97.22,0.245
15.88,97.40,0.245
15.90,97.59,0.245
15.91,97.77,0.245
15.93,97.96,0.245
15.95,98.14,0.245
15.97,98.32,0.246
15.99,98.51,0.246
16.00,98.69,0.246
16.02,98.87,0.246
16.04,99.06,0.246
16.06,99.24,0.246
16.08,99.42,0.246
16.10,99.61,0.246
16.12,99.79,0.246
16.13,99.97,0.246
16.15,100.16,0.246
16.17,100.34,0.246
16.19,100.52,0.246
16.21,100.71,0.247
16.23,100.89,0.246
16.24,101.07,0.247
16.26,101.26,0.247
16.28,101.44,0.247
16.30,101.63,0.247
16.32,101.81,0.247
16.33,101.99,0.247
16.35,102.18,0.247
16.37,102.36,0.247
16.39,102.54,0.247
16.41,102.73,0.247
16.43,102.91,0.247
16.45,103.09,0.247
16.46,103.28,0.247
16.48,103.46,0.248
16.50,103.64,0.248
16.52,103.83,0.248
16.54,104.01,0.248
16.55,104.19,0.248
16.57,104.38,0.248
16.59,104.56,0.248
16.61,104.74,0.248
16.63,104.93,0.248
16.65,105.11,0.248
16.67,105.30,0.248
16.68,105.48,0.248
16.70,105.66,0.249
16.72,105.85,0.249
16.74,106.03,0.249
16.76,106.21,0.249
16.78,106.40,0.249
16.79,106.58,0.249
16.81,106.76,0.249
16.83,106.95,0.249
16.85,107.13,0.249
16.87,107.31,0.249
16.88,107.50,0.250
16.90,107.68,0.250
16.92,107.86,0.250
16.94,108.05,0.250
16.96,108.23,0.250
16.98,108.41,0.250
17.00,108.60,0.250
17.01,108.78,0.250
17.03,108.97,0.250
17.05,109.15,0.250
17.07,109.33,0.250
17.09,109.52,0.250
17.11,109.70,0.250
17.12,109.88,0.250
17.14,110.07,0.250
17.16,110.25,0.250
17.18,110.43,0.250
17.20,110.62,0.251
17.22,110.80,0.251
17.23,110.98,0.251
17.25,111.17,0.251
17.27,111.35,0.251
17.29,111.53,0.251
17.31,111.72,0.251
17.33,111.90,0.251
17.34,112.09,0.251
17.36,112.27,0.251
17.38,112.45,0.251
17.40,112.64,0.251
17.42,112.82,0.252
17.43,113.00,0.252
17.45,113.19,0.252
17.47,113.37,0.252
17.49,113.55,0.252
17.51,113.74,0.252
17.53,113.92,0.252
17.54,114.10,0.252
17.56,114.29,0.253
17.58,114.47,0.253
17.60,114.65,0.253
17.62,114.84,0.253
17.64,115.02,0.253
17.66,115.20,0.253
17.67,115.39,0.253
17.69,115.57,0.253
17.71,115.75,0.253
17.73,115.94,0.254
17.75,116.12,0.254
17.77,116.30,0.254
17.78,116.49,0.254
17.80,116.67,0.254
17.82,116.85,0.254
17.84,117.04,0.254
17.86,117.22,0.255
17.88,117.40,0.255
17.89,117.59,0.255
17.91,117.77,0.255
17.93,117.95,0.255
17.95,118.14,0.255
17.97,118.32,0.256
17.98,118.50,0.256
18.00,118.69,0.256
18.02,118.87,0.256
18.04,119.06,0.256
18.06,119.24,0.257
18.08,119.42,0.257
18.09,119.61,0.257
18.11,119.79,0.257
18.13,119.97,0.258
18.15,120.16,0.258
18.17,120.34,0.258
18.19,120.53,0.258
18.21,120.71,0.259
18.22,120.89,0.259
18.24,121.08,0.259
18.26,121.26,0.259
18.28,121.44,0.259
18.30,121.63,0.259
18.32,121.81,0.260
18.33,121.99,0.260
18.35,122.18,0.260
18.37,122.36,0.260
18.39,122.54,0.261
18.41,122.73,0.261
18.43,122.91,0.261
18.44,123.09,0.261
18.46,123.28,0.262
18.48,123.46,0.262
18.50,123.64,0.262
18.52,123.83,0.262
18.53,124.01,0.263
18.55,124.19,0.263
18.57,124.38,0.263
18.59,124.56,0.263
18.61,124.74,0.264
18.63,124.93,0.264
18.64,125.11,0.264
18.66,125.29,0.264
18.68,125.48,0.265
18.70,125.66,0.265
18.72,125.84,0.265
18.74,126.03,0.265
18.76,126.21,0.266
18.77,126.39,0.266
18.79,126.58,0.266
18.81,126.76,0.267
18.83,126.95,0.267
18.85,127.13,0.267
18.87,127.31,0.267
18.88,127.50,0.268
18.90,127.68,0.268
18.92,127.86,0.268
18.94,128.05,0.268
18.96,128.23,0.269
18.98,128.41,0.269
18.99,128.60,0.269
19.01,128.78,0.269
19.03,128.96,0.270
19.05,129.15,0.270
19.07,129.33,0.270
19.08,129.51,0.270
19.10,129.70,0.271
19.12,129.88,0.271
19.14,130.06,0.271
19.16,130.25,0.271
19.18,130.43,0.271
19.19,130.61,0.272
19.21,130.80,0.272
19.23,130.98,0.272
19.25,131.17,0.272
19.27,131.35,0.272
19.29,131.53,0.272
19.31,131.72,0.273
19.32,131.90,0.273
19.34,132.08,0.273
19.36,132.27,0.273
19.38,132.45,0.273
19.40,132.63,0.273
19.42,132.82,0.273
19.43,133.00,0.274
19.45,133.18,0.274
19.47,133.37,0.274
19.49,133.55,0.274
19.51,133.73,0.275
19.53,133.92,0.275
19.54,134.10,0.275
19.56,134.28,0.275
19.58,134.47,0.275
19.60,134.65,0.276
19.62,134.84,0.276
19.63,135.02,0.276
19.65,135.20,0.276
19.67,135.39,0.276
19.69,135.57,0.277
19.71,135.75,0.277
19.73,135.94,0.277
19.74,136.12,0.277
19.76,136.30,0.277
19.78,136.49,0.278
19.80,136.67,0.278
19.82,136.85,0.278
19.84,137.04,0.278
19.86,137.22,0.278
19.87,137.40,0.278
19.89,137.59,0.279
19.91,137.77,0.279
19.93,137.95,0.279
19.95,138.14,0.279
19.97,138.32,0.279
19.98,138.50,0.280
20.00,138.69,0.280
20.02,138.87,0.280
20.04,139.05,0.280
20.06,139.24,0.280
20.08,139.42,0.280
20.09,139.60,0.281
20.11,139.79,0.281
20.13,139.97,0.281
20.15,140.15,0.281
20.17,140.34,0.281
20.18,140.52,0.282
20.20,140.70,0.282
20.22,140.89,0.282
20.24,141.07,0.282
20.26,141.25,0.283
20.28,141.44,0.283
20.29,141.62,0.283
20.31,141.81,0.283
20.33,141.99,0.283
20.35,142.17,0.283
20.37,142.36,0.284
20.39,142.54,0.284
20.41,142.72,0.284
20.42,142.91,0.284
20.44,143.09,0.285
20.46,143.27,0.285
20.48,143.46,0.285
20.50,143.64,0.285
20.52,143.82,0.285
20.53,144.01,0.286
20.55,144.19,0.286
20.57,144.37,0.286
20.59,144.56,0.286
20.61,144.74,0.286
20.63,144.93,0.287
20.64,145.11,0.287
20.66,145.29,0.287
20.68,145.48,0.287
20.70,145.66,0.287
20.72,145.84,0.288
20.73,146.03,0.288
20.75,146.21,0.288
20.77,146.39,0.288
20.79,146.58,0.288
20.81,146.76,0.289
20.83,146.94,0.289
20.84,147.13,0.289
20.86,147.31,0.289
20.88,147.49,0.289
20.90,147.68,0.290
20.92,147.86,0.290
20.94,148.04,0.290
20.96,148.23,0.290
20.97,148.41,0.290
20.99,148.59,0.291
21.01,148.78,0.291
21.03,148.96,0.291
21.05,149.14,0.291
21.07,149.33,0.291
21.08,149.51,0.291
21.10,149.69,0.292
21.12,149.88,0.292
21.14,150.06,0.292
21.16,150.24,0.292
21.18,150.43,0.292
21.19,150.61,0.293
21.21,150.79,0.293
21.23,150.98,0.293
21.25,151.16,0.293
21.27,151.34,0.293
21.28,151.53,0.293
21.30,151.71,0.294
21.32,151.89,0.294
21.34,152.08,0.294
21.36,152.26,0.294
21.38,152.44,0.294
21.39,152.63,0.295
21.41,152.81,0.295
21.43,152.99,0.295
21.45,153.18,0.295
21.47,153.36,0.296
21.49,153.54,0.296
21.51,153.73,0.296
21.52,153.91,0.296
21.54,154.09,0.297
21.56,154.28,0.297
21.58,154.46,0.297
21.60,154.65,0.297
21.62,154.83,0.298
21.63,155.01,0.298
21.65,155.19,0.298
21.67,155.38,0.298
21.69,155.56,0.298
21.71,155.75,0.299
21.73,155.93,0.299
21.74,156.11,0.299
21.76,156.30,0.299
21.78,156.48,0.299
21.80,156.66,0.300
21.82,156.85,0.300
21.83,157.03,0.300
21.85,157.21,0.300
21.87,157.40,0.301
21.89,157.58,0.301
21.91,157.77,0.301
21.93,157.95,0.301
21.94,158.13,0.302
21.96,158.31,0.302
21.98,158.50,0.302
22.00,158.68,0.302
22.02,158.87,0.303
22.04,159.05,0.303
22.06,159.23,0.303
22.07,159.41,0.303
22.09,159.60,0.304
22.11,159.78,0.304
22.13,159.96,0.304
22.15,160.15,0.304
22.17,160.33,0.304
22.18,160.51,0.305
22.20,160.70,0.305
22.22,160.88,0.305
22.24,161.06,0.305
22.26,161.25,0.306
22.28,161.43,0.306
22.29,161.62,0.306
22.31,161.80,0.306
22.33,161.98,0.307
22.35,162.17,0.307
22.37,162.35,0.307
22.38,162.53,0.308
22.40,162.71,0.308
22.42,162.90,0.308
22.44,163.08,0.309
22.46,163.27,0.309
22.48,163.45,0.309
22.49,163.63,0.309
22.51,163.81,0.310
22.53,164.00,0.310
22.55,164.18,0.310
22.57,164.37,0.310
22.59,164.55,0.311
22.61,164.74,0.311
22.62,164.92,0.311
22.64,165.10,0.312
22.66,165.29,0.313
22.68,165.47,0.313
22.70,165.65,0.313
22.72,165.84,0.314
22.73,166.02,0.314
22.75,166.20,0.314
22.77,166.39,0.314
22.79,166.57,0.315
22.81,166.75,0.315
22.83,166.93,0.315
22.84,167.12,0.316
22.86,167.30,0.316
22.88,167.48,0.316
22.90,167.67,0.316
22.92,167.85,0.317
22.93,168.03,0.317
22.95,168.22,0.317
22.97,168.40,0.318
22.99,168.58,0.318
23.01,168.77,0.318
23.03,168.95,0.319
23.04,169.14,0.319
23.06,169.32,0.319
23.08,169.50,0.319
23.10,169.68,0.320
23.12,169.87,0.320
23.14,170.05,0.321
23.16,170.24,0.321
23.17,170.42,0.321
23.19,170.60,0.322
23.21,170.79,0.322
23.23,170.97,0.322
23.25,171.15,0.323
23.27,171.33,0.323
23.28,171.52,0.324
23.30,171.70,0.324
23.32,171.89,0.325
23.34,172.07,0.325
23.36,172.25,0.325
23.38,172.44,0.326
23.39,172.62,0.326
23.41,172.80,0.327
23.43,172.99,0.327
23.45,173.17,0.328
23.47,173.35,0.328
23.48,173.54,0.329
23.50,173.72,0.329
23.52,173.90,0.329
23.54,174.09,0.330
23.56,174.27,0.330
23.58,174.45,0.331
23.59,174.63,0.331
23.61,174.82,0.332
23.63,175.00,0.332
23.65,175.19,0.333
23.67,175.37,0.333
23.69,175.55,0.334
23.71,175.74,0.334
23.72,175.92,0.335
23.74,176.10,0.335
23.76,176.29,0.336
23.78,176.47,0.336
23.80,176.65,0.337
23.82,176.84,0.337
23.83,177.02,0.338
23.85,177.20,0.338
23.87,177.39,0.339
23.89,177.57,0.339
23.91,177.75,0.340
23.93,177.94,0.340
23.94,178.12,0.341
23.96,178.30,0.342
23.98,178.49,0.342
24.00,178.67,0.343
24.02,178.85,0.343
24.03,179.04,0.344
24.05,179.22,0.344
24.07,179.40,0.346
24.09,179.59,0.346
24.11,179.77,0.347
24.13,179.95,0.347
24.14,180.14,0.348
24.16,180.32,0.349
24.18,180.50,0.349
24.20,180.69,0.350
24.22,180.87,0.351
24.24,181.05,0.351
24.26,181.23,0.353
24.27,181.42,0.353
24.29,181.60,0.354
24.31,181.78,0.355
24.33,181.97,0.355
24.35,182.15,0.356
24.37,182.34,0.357
24.38,182.52,0.358
24.40,182.70,0.358
24.42,182.89,0.359
24.44,183.07,0.360
24.46,183.25,0.361
24.48,183.44,0.362
24.49,183.62,0.363
24.51,183.80,0.364
24.53,183.99,0.365
24.55,184.17,0.365
24.57,184.35,0.366
24.58,184.53,0.367
24.60,184.72,0.367
24.62,184.90,0.368
24.64,185.08,0.369
24.66,185.27,0.370
24.68,185.45,0.371
24.69,185.63,0.372
24.71,185.82,0.373
24.73,186.00,0.373
24.75,186.18,0.374
24.77,186.37,0.375
24.79,186.55,0.377
24.81,186.73,0.377
24.82,186.92,0.378
24.84,187.10,0.380
24.86,187.28,0.381
24.88,187.47,0.383
24.90,187.65,0.384
24.92,187.83,0.385
24.93,188.02,0.386
24.95,188.20,0.387
24.97,188.38,0.387
24.99,188.57,0.388
25.01,188.75,0.390
25.03,188.93,0.391
25.04,189.12,0.392
25.06,189.30,0.394
25.08,189.48,0.395
25.10,189.67,0.397
25.12,189.85,0.397
25.13,190.03,0.400
25.15,190.21,0.401
25.17,190.40,0.402
25.19,190.58,0.403
25.21,190.76,0.404
25.23,190.95,0.407
25.24,191.13,0.409
25.26,191.31,0.410
25.28,191.50,0.411
25.30,191.68,0.413
25.32,191.86,0.414
25.34,192.05,0.417
25.36,192.23,0.418
25.37,192.41,0.420
25.39,192.60,0.422
25.41,192.78,0.424
25.43,192.96,0.426
25.45,193.15,0.428
25.47,193.33,0.430
25.48,193.51,0.432
25.50,193.70,0.433
25.52,193.88,0.435
25.54,194.06,0.437
25.56,194.24,0.439
25.58,194.43,0.440
25.59,194.61,0.442
25.61,194.79,0.444
25.63,194.98,0.447
25.65,195.16,0.449
25.67,195.34,0.450
25.68,195.53,0.453
25.70,195.71,0.455
25.72,195.89,0.457
25.74,196.07,0.460
25.76,196.26,0.462
25.78,196.44,0.465
25.79,196.62,0.468
25.81,196.81,0.470
25.83,196.99,0.473
25.85,197.17,0.477
25.87,197.35,0.480
25.89,197.54,0.481
25.91,197.72,0.486
25.92,197.90,0.489
25.94,198.09,
25.96,198.27,
25.98,198.45,
25.99,,

[step]
Ramp 10.00 °C/min to -60.00 °C
Time,Temperature,Heat Flow (Normalized)
min,°C,W/g
27.99,200.11,-0.062
28.01,200.11,-0.062
28.03,200.11,-0.062
28.05,200.09,-0.059
28.07,200.07,-0.038
28.08,200.02,-0.021
28.10,199.96,-0.019
28.12,199.87,-0.026
28.14,199.76,-0.077
28.16,199.64,-0.132
28.18,199.50,-0.192
28.19,199.36,-0.251
28.21,199.22,-0.304
28.23,199.06,-0.349
28.25,198.91,-0.388
28.27,198.75,-0.420
28.29,198.58,-0.447
28.31,198.42,-0.473
28.32,198.25,-0.492
28.34,198.08,-0.510
28.36,197.91,-0.524
28.38,197.74,-0.537
28.40,197.56,-0.550
28.42,197.38,-0.558
28.43,197.21,-0.566
28.45,197.03,-0.570
28.47,196.85,-0.576
28.49,196.68,-0.580
28.51,196.50,-0.583
28.53,196.32,-0.584
28.54,196.14,-0.587
28.56,195.96,-0.588
28.58,195.78,-0.589
28.60,195.60,-0.589
28.62,195.42,-0.590
28.63,195.23,-0.590
28.65,195.05,-0.590
28.67,194.87,-0.590
28.69,194.69,-0.590
28.71,194.51,-0.589
28.73,194.33,-0.588
28.74,194.15,-0.588
28.76,193.96,-0.587
28.78,193.78,-0.586
28.80,193.60,-0.584
28.82,193.42,-0.583
28.84,193.24,-0.580
28.86,193.05,-0.580
28.87,192.87,-0.577
28.89,192.69,-0.576
28.91,192.51,-0.575
28.93,192.32,-0.574
28.95,192.14,-0.571
28.97,191.96,-0.569
28.98,191.78,-0.566
29.00,191.59,-0.564
29.02,191.41,-0.563
29.04,191.23,-0.561
29.06,191.05,-0.559
29.08,190.86,-0.558
29.09,190.68,-0.556
29.11,190.50,-0.553
29.13,190.31,-0.550
29.15,190.13,-0.548
29.17,189.95,-0.546
29.18,189.77,-0.545
29.20,189.58,-0.543
29.22,189.40,-0.542
29.24,189.22,-0.540
29.26,189.03,-0.539
29.28,188.85,-0.537
29.29,188.67,-0.534
29.31,188.48,-0.532
29.33,188.30,-0.530
29.35,188.12,-0.529
29.37,187.93,-0.529
29.39,187.75,-0.527
29.41,187.57,-0.525
29.42,187.38,-0.524
29.44,187.20,-0.521
29.46,187.02,-0.520
29.48,186.84,-0.518
29.50,186.65,-0.516
29.52,186.47,-0.514
29.53,186.29,-0.513
29.55,186.10,-0.512
29.57,185.92,-0.511
29.59,185.74,-0.510
29.61,185.56,-0.509
29.63,185.37,-0.508
29.64,185.19,-0.506
29.66,185.01,-0.504
29.68,184.82,-0.503
29.70,184.64,-0.502
29.72,184.45,-0.501
29.73,184.27,-0.500
29.75,184.09,-0.499
29.77,183.90,-0.498
29.79,183.72,-0.496
29.81,183.54,-0.495
29.83,183.35,-0.494
29.84,183.17,-0.492
29.86,182.99,-0.490
29.88,182.80,-0.488
29.90,182.62,-0.487
29.92,182.44,-0.487
29.94,182.25,-0.486
29.96,182.07,-0.486
29.97,181.89,-0.484
29.99,181.70,-0.483
30.01,181.52,-0.480
30.03,181.34,-0.480
30.05,181.15,-0.479
30.07,180.97,-0.478
30.08,180.79,-0.477
30.10,180.60,-0.476
30.12,180.42,-0.475
30.14,180.24,-0.475
30.16,180.05,-0.474
30.18,179.87,-0.472
30.19,179.69,-0.471
30.21,179.51,-0.470
30.23,179.32,-0.468
30.25,179.14,-0.468
30.27,178.95,-0.467
30.28,178.77,-0.466
30.30,178.59,-0.465
30.32,178.41,-0.464
30.34,178.22,-0.464
30.36,178.04,-0.462
30.38,177.86,-0.460
30.39,177.67,-0.459
30.41,177.49,-0.459
30.43,177.31,-0.458
30.45,177.12,-0.458
30.47,176.94,-0.457
30.49,176.76,-0.456
30.51,176.57,-0.456
30.52,176.39,-0.455
30.54,176.21,-0.454
30.56,176.02,-0.453
30.58,175.84,-0.452
30.60,175.66,-0.452
30.62,175.47,-0.451
30.63,175.29,-0.450
30.65,175.11,-0.449
30.67,174.92,-0.448
30.69,174.74,-0.448
30.71,174.56,-0.447
30.73,174.37,-0.446
30.74,174.19,-0.446
30.76,174.01,-0.445
30.78,173.82,-0.444
30.80,173.64,-0.444
30.82,173.46,-0.443
30.83,173.27,-0.443
30.85,173.09,-0.442
30.87,172.91,-0.440
30.89,172.72,-0.439
30.91,172.54,-0.439
30.93,172.36,-0.438
30.94,172.17,-0.437
30.96,171.99,-0.437
30.98,171.81,-0.436
31.00,171.62,-0.436
31.02,171.44,-0.435
31.04,171.26,-0.435
31.06,171.07,-0.434
31.07,170.89,-0.434
31.09,170.71,-0.433
31.11,170.53,-0.432
31.13,170.34,-0.432
31.15,170.16,-0.431
31.17,169.98,-0.430
31.18,169.79,-0.430
31.20,169.61,-0.429
31.22,169.43,-0.429
31.24,169.24,-0.428
31.26,169.06,-0.427
31.28,168.88,-0.427
31.29,168.69,-0.426
31.31,168.51,-0.426
31.33,168.33,-0.425
31.35,168.14,-0.425
31.37,167.96,-0.424
31.38,167.78,-0.424
31.40,167.59,-0.423
31.42,167.41,-0.422
31.44,167.23,-0.422
31.46,167.05,-0.421
31.48,166.86,-0.420
31.49,166.68,-0.420
31.51,166.49,-0.419
31.53,166.31,-0.419
31.55,166.13,-0.419
31.57,165.94,-0.418
31.59,165.76,-0.417
31.61,165.58,-0.417
31.62,165.40,-0.416
31.64,165.21,-0.416
31.66,165.03,-0.415
31.68,164.85,-0.415
31.70,164.66,-0.415
31.72,164.48,-0.414
31.73,164.30,-0.414
31.75,164.11,-0.413
31.77,163.93,-0.413
31.79,163.75,-0.412
31.81,163.56,-0.412
31.83,163.38,-0.411
31.84,163.20,-0.411
31.86,163.01,-0.411
31.88,162.83,-0.410
31.90,162.65,-0.410
31.92,162.46,-0.409
31.93,162.28,-0.409
31.95,162.10,-0.408
31.97,161.91,-0.408
31.99,161.73,-0.407
32.01,161.55,-0.407
32.03,161.36,-0.406
32.04,161.18,-0.406
32.06,161.00,-0.406
32.08,160.81,-0.405
32.10,160.63,-0.405
32.12,160.45,-0.405
32.14,160.27,-0.404
32.16,160.08,-0.404
32.17,159.90,-0.404
32.19,159.72,-0.403
32.21,159.53,-0.403
32.23,159.35,-0.402
32.25,159.17,-0.402
32.27,158.98,-0.401
32.28,158.80,-0.401
32.30,158.62,-0.401
32.32,158.43,-0.400
32.34,158.25,-0.400
32.36,158.07,-0.399
32.38,157.89,-0.399
32.39,157.70,-0.399
32.41,157.52,-0.398
32.43,157.34,-0.398
32.45,157.15,-0.398
32.47,156.97,-0.397
32.48,156.79,-0.397
32.50,156.60,-0.397
32.52,156.42,-0.396
32.54,156.23,-0.396
32.56,156.05,-0.396
32.58,155.87,-0.396
32.59,155.68,-0.396
32.61,155.50,-0.395
32.63,155.32,-0.395
32.65,155.13,-0.395
32.67,154.95,-0.395
32.69,154.77,-0.394
32.71,154.59,-0.394
32.72,154.40,-0.394
32.74,154.22,-0.393
32.76,154.04,-0.393
32.78,153.85,-0.392
32.80,153.67,-0.392
32.82,153.49,-0.392
32.83,153.31,-0.392
32.85,153.12,-0.391
32.87,152.94,-0.391
32.89,152.76,-0.391
32.91,152.57,-0.390
32.93,152.39,-0.390
32.94,152.21,-0.390
32.96,152.02,-0.389
32.98,151.84,-0.389
33.00,151.66,-0.389
33.02,151.48,-0.388
33.03,151.29,-0.388
33.05,151.11,-0.388
33.07,150.92,-0.387
33.09,150.74,-0.387
33.11,150.56,-0.387
33.13,150.37,-0.387
33.14,150.19,-0.386
33.16,150.01,-0.386
33.18,149.82,-0.386
33.20,149.64,-0.386
33.22,149.46,-0.386
33.24,149.27,-0.386
33.26,149.09,-0.385
33.27,148.91,-0.385
33.29,148.72,-0.385
33.31,148.54,-0.385
33.33,148.36,-0.384
33.35,148.17,-0.384
33.37,147.99,-0.383
33.38,147.81,-0.383
33.40,147.63,-0.383
33.42,147.44,-0.383
33.44,147.26,-0.383
33.46,147.07,-0.382
33.48,146.89,-0.382
33.49,146.71,-0.382
33.51,146.52,-0.382
33.53,146.34,-0.381
33.55,146.16,-0.381
33.57,145.97,-0.381
33.58,145.79,-0.380
33.60,145.61,-0.380
33.62,145.43,-0.380
33.64,145.24,-0.380
33.66,145.06,-0.380
33.68,144.88,-0.379
33.69,144.69,-0.379
33.71,144.51,-0.379
33.73,144.33,-0.378
33.75,144.14,-0.378
33.77,143.96,-0.378
33.79,143.78,-0.378
33.81,143.59,-0.377
33.82,143.41,-0.377
33.84,143.23,-0.377
33.86,143.05,-0.377
33.88,142.86,-0.376
33.90,142.68,-0.376
33.92,142.50,-0.376
33.93,142.31,-0.376
33.95,142.13,-0.375
33.97,141.95,-0.375
33.99,141.76,-0.375
34.01,141.58,-0.375
34.03,141.40,-0.374
34.04,141.22,-0.374
34.06,141.03,-0.372
34.08,140.85,-0.372
34.10,140.67,-0.372
34.12,140.48,-0.372
34.14,140.30,-0.372
34.15,140.12,-0.372
34.17,139.93,-0.371
34.19,139.75,-0.371
34.21,139.57,-0.371
34.23,139.38,-0.371
34.24,139.20,-0.370
34.26,139.02,-0.370
34.28,138.83,-0.370
34.30,138.65,-0.370
34.32,138.47,-0.370
34.34,138.28,-0.370
34.36,138.10,-0.370
34.37,137.92,-0.370
34.39,137.73,-0.369
34.41,137.55,-0.369
34.43,137.37,-0.369
34.45,137.18,-0.369
34.46,137.00,-0.369
34.48,136.82,-0.368
34.50,136.63,-0.368
34.52,136.45,-0.368
34.54,136.27,-0.368
34.56,136.09,-0.368
34.58,135.90,-0.368
34.59,135.72,-0.367
34.61,135.54,-0.367
34.63,135.35,-0.367
34.65,135.17,-0.367
34.67,134.99,-0.367
34.69,134.80,-0.367
34.70,134.62,-0.367
34.72,134.44,-0.366
34.74,134.25,-0.366
34.76,134.07,-0.366
34.78,133.89,-0.366
34.79,133.71,-0.366
34.81,133.52,-0.366
34.83,133.34,-0.365
34.85,133.16,-0.365
34.87,132.97,-0.365
34.89,132.79,-0.365
34.91,132.60,-0.365
34.92,132.42,-0.365
34.94,132.24,-0.365
34.96,132.05,-0.365
34.98,131.87,-0.364
35.00,131.69,-0.364
35.01,131.51,-0.364
35.03,131.32,-0.363
35.05,131.14,-0.363
35.07,130.96,-0.363
35.09,130.77,-0.363
35.11,130.59,-0.363
35.13,130.41,-0.362
35.14,130.22,-0.362
35.16,130.04,-0.362
[...]
114.08,-40.86,0.150
114.08,-40.79,0.150
114.09,-40.73,0.150
114.10,-40.66,0.150
114.10,-40.59,0.150
114.11,-40.53,0.150
114.11,-40.46,0.150
114.12,-40.39,0.150
114.13,-40.33,0.150
114.14,-40.26,0.150
114.14,-40.19,0.150
114.15,-40.12,0.150
114.15,-40.06,0.150
114.16,-39.99,0.150
114.17,-39.92,0.150
114.18,-39.86,0.150
114.18,-39.79,0.150
114.19,-39.72,0.150
114.20,-39.66,0.150
114.20,-39.59,0.150
114.21,-39.52,0.150
114.21,-39.46,0.150
114.22,-39.39,0.150
114.23,-39.32,0.150
114.24,-39.26,0.150
114.24,-39.19,0.150
114.25,-39.12,0.150
114.25,-39.06,0.150
114.26,-38.99,0.150
114.27,-38.92,0.150
114.28,-38.86,0.150
114.28,-38.79,0.150
114.29,-38.72,0.150
114.30,-38.66,0.150
114.30,-38.59,0.150
114.31,-38.52,0.150
114.31,-38.46,0.150
114.32,-38.39,0.150
114.33,-38.32,0.150
114.34,-38.26,0.150
114.34,-38.19,0.150
114.35,-38.12,0.150
114.35,-38.06,0.150
114.36,-37.99,0.150
114.37,-37.92,0.150
114.38,-37.86,0.150
114.38,-37.79,0.150
114.39,-37.72,0.150
114.40,-37.66,0.150
114.40,-37.59,0.150
114.41,-37.52,0.151
114.41,-37.46,0.151
114.42,-37.39,0.151
114.43,-37.32,0.151
114.44,-37.25,0.151
114.44,-37.19,0.151
114.45,-37.12,0.151
114.45,-37.05,0.151
114.46,-36.99,0.151
114.47,-36.92,0.151
114.48,-36.85,0.151
114.48,-36.79,0.151
114.49,-36.72,0.151
114.50,-36.65,0.151
114.50,-36.59,0.151
114.51,-36.52,0.151
114.51,-36.45,0.151
114.52,-36.39,0.151
114.53,-36.32,0.151
114.54,-36.25,0.151
114.54,-36.19,0.151
114.55,-36.12,0.151
114.55,-36.05,0.151
114.56,-35.99,0.151
114.57,-35.92,0.151
114.58,-35.85,0.151
114.58,-35.79,0.151
114.59,-35.72,0.151
114.60,-35.65,0.151
114.60,-35.59,0.151
114.61,-35.52,0.151
114.61,-35.45,0.151
114.62,-35.39,0.151
114.63,-35.32,0.151
114.64,-35.25,0.151
114.64,-35.18,0.151
114.65,-35.12,0.151
114.65,-35.05,0.151
114.66,-34.98,0.151
114.67,-34.92,0.151
114.68,-34.85,0.151
114.68,-34.78,0.152
114.69,-34.72,0.152
114.70,-34.65,0.152
114.70,-34.58,0.151
114.71,-34.52,0.151
114.71,-34.45,0.152
114.72,-34.38,0.152
114.73,-34.32,0.152
114.74,-34.25,0.152
114.74,-34.18,0.152
114.75,-34.12,0.152
114.75,-34.05,0.152
114.76,-33.98,0.152
114.77,-33.92,0.152
114.78,-33.85,0.152
114.78,-33.78,0.152
114.79,-33.72,0.152
114.80,-33.65,0.152
114.80,-33.58,0.152
114.81,-33.52,0.152
114.81,-33.45,0.152
114.82,-33.38,0.152
114.83,-33.32,0.152
114.84,-33.25,0.152
114.84,-33.18,0.152
114.85,-33.12,0.152
114.85,-33.05,0.152
114.86,-32.98,0.152
114.87,-32.92,0.152
114.88,-32.85,0.152
114.88,-32.78,0.152
114.89,-32.71,0.152
114.90,-32.65,0.152
114.90,-32.58,0.152
114.91,-32.51,0.152
114.91,-32.45,0.152
114.92,-32.38,0.152
114.93,-32.31,0.152
114.94,-32.25,0.152
114.94,-32.18,0.152
114.95,-32.11,0.152
114.95,-32.05,0.152
114.96,-31.98,0.152
114.97,-31.91,0.152
114.98,-31.85,0.152
114.98,-31.78,0.152
114.99,-31.71,0.152
115.00,-31.65,0.152
115.00,-31.58,0.152
115.01,-31.51,0.152
115.01,-31.45,0.152
115.02,-31.38,0.152
115.03,-31.31,0.152
115.04,-31.25,0.152
115.04,-31.18,0.152
115.05,-31.11,0.152
115.05,-31.05,0.152
115.06,-30.98,0.153
115.07,-30.91,0.153
115.08,-30.85,0.153
115.08,-30.78,0.153
115.09,-30.71,0.153
115.10,-30.65,0.153
115.10,-30.58,0.153
115.11,-30.51,0.153
115.11,-30.44,0.153
115.12,-30.38,0.153
115.13,-30.31,0.153
115.14,-30.24,0.153
115.14,-30.18,0.153
115.15,-30.11,0.153
115.15,-30.04,0.153
115.16,-29.97,0.153
115.17,-29.91,0.153
115.18,-29.84,0.153
115.18,-29.77,0.153
115.19,-29.71,0.153
115.20,-29.64,0.153
115.20,-29.57,0.153
115.21,-29.51,0.153
115.21,-29.44,0.153
115.22,-29.37,0.153
115.23,-29.31,0.153
115.24,-29.24,0.153
115.24,-29.17,0.153
115.25,-29.10,0.153
115.25,-29.04,0.153
115.26,-28.97,0.153
115.27,-28.90,0.153
115.28,-28.84,0.153
115.28,-28.77,0.153
115.29,-28.70,0.153
115.30,-28.64,0.153
115.30,-28.57,0.153
115.31,-28.50,0.153
115.31,-28.44,0.153
115.32,-28.37,0.154
115.33,-28.30,0.154
115.34,-28.24,0.154
115.34,-28.17,0.154
115.35,-28.10,0.154
115.35,-28.04,0.154
115.36,-27.97,0.154
115.37,-27.90,0.154
115.38,-27.84,0.154
115.38,-27.77,0.154
115.39,-27.70,0.154
115.40,-27.64,0.154
115.40,-27.57,0.154
115.41,-27.50,0.154
115.41,-27.44,0.154
115.42,-27.37,0.154
115.43,-27.30,0.154
115.44,-27.24,0.154
115.44,-27.17,0.154
115.45,-27.10,0.154
115.45,-27.04,0.154
115.46,-26.97,0.154
115.47,-26.90,0.154
115.48,-26.84,0.154
115.48,-26.77,0.154
115.49,-26.71,0.154
115.50,-26.64,0.154
115.50,-26.57,0.154
115.51,-26.50,0.154
115.51,-26.44,0.154
115.52,-26.37,0.154
115.53,-26.30,0.154
115.54,-26.24,0.154
115.54,-26.17,0.154
115.55,-26.10,0.154
115.55,-26.04,0.154
115.56,-25.97,0.154
115.57,-25.90,0.154
115.58,-25.84,0.154
115.58,-25.77,0.154
115.59,-25.70,0.154
115.60,-25.64,0.154
115.60,-25.57,0.154
115.61,-25.50,0.154
115.61,-25.44,0.154
115.62,-25.37,0.154
115.63,-25.30,0.154
115.64,-25.24,0.154
115.64,-25.17,0.154
115.65,-25.10,0.154
115.65,-25.04,0.154
115.66,-24.97,0.154
115.67,-24.90,0.154
115.68,-24.83,0.154
115.68,-24.77,0.154
115.69,-24.70,0.154
115.70,-24.63,0.154
115.70,-24.57,0.154
115.71,-24.50,0.154
115.71,-24.43,0.154
115.72,-24.37,0.154
115.73,-24.30,0.154
115.74,-24.23,0.154
115.74,-24.17,0.154
115.75,-24.10,0.154
115.75,-24.04,0.155
115.76,-23.97,0.155
115.77,-23.90,0.155
115.78,-23.84,0.155
115.78,-23.77,0.155
115.79,-23.70,0.155
115.80,-23.63,0.155
115.80,-23.57,0.155
115.81,-23.50,0.155
115.81,-23.43,0.155
115.82,-23.37,0.155
115.83,-23.30,0.155
115.84,-23.23,0.155
115.84,-23.17,0.155
115.85,-23.10,0.155
115.85,-23.03,0.155
115.86,-22.97,0.155
115.87,-22.90,0.155
115.88,-22.83,0.155
115.88,-22.77,0.155
115.89,-22.70,0.155
115.90,-22.63,0.155
115.90,-22.57,0.155
115.91,-22.50,0.155
115.91,-22.43,0.155
115.92,-22.37,0.155
115.93,-22.30,0.155
115.94,-22.23,0.155
115.94,-22.17,0.155
115.95,-22.10,0.155
115.95,-22.03,0.155
115.96,-21.97,0.155
115.97,-21.90,0.155
115.98,-21.83,0.155
115.98,-21.77,0.155
115.99,-21.70,0.155
116.00,-21.63,0.155
116.00,-21.57,0.155
116.01,-21.50,0.155
116.01,-21.43,0.156
116.02,-21.36,0.156
116.03,-21.30,0.156
116.04,-21.23,0.156
116.04,-21.17,0.156
116.05,-21.10,0.156
116.05,-21.03,0.156
116.06,-20.96,0.156
116.07,-20.90,0.156
116.08,-20.83,0.156
116.08,-20.77,0.156
116.09,-20.70,0.156
116.10,-20.63,0.156
116.10,-20.56,0.156
116.11,-20.50,0.156
116.11,-20.43,0.156
116.12,-20.36,0.156
116.13,-20.30,0.156
116.14,-20.23,0.156
116.14,-20.17,0.156
116.15,-20.10,0.156
116.15,-20.03,0.156
116.16,-19.96,0.156
116.17,-19.90,0.156
116.18,-19.83,0.156
116.18,-19.76,0.156
116.19,-19.70,0.156
116.20,-19.63,0.156
116.20,-19.56,0.156
116.21,-19.50,0.156
116.21,-19.43,0.156
116.22,-19.36,0.156
116.23,-19.30,0.156
116.24,-19.23,0.156
116.24,-19.16,0.156
116.25,-19.10,0.156
116.25,-19.03,0.156
116.26,-18.96,0.156
116.27,-18.90,0.156
116.28,-18.83,0.157
116.28,-18.76,0.157
116.29,-18.70,0.157
116.30,-18.63,0.157
116.30,-18.56,0.157
116.31,-18.49,0.157
116.31,-18.43,0.157
116.32,-18.36,0.157
116.33,-18.30,0.157
116.34,-18.23,0.157
116.34,-18.16,0.157
116.35,-18.09,0.157
116.35,-18.03,0.157
116.36,-17.96,0.157
116.37,-17.89,0.157
116.38,-17.83,0.157
116.38,-17.76,0.157
116.39,-17.69,0.157
116.40,-17.63,0.157
116.40,-17.56,0.157
116.41,-17.49,0.157
116.41,-17.43,0.157
116.42,-17.36,0.157
116.43,-17.29,0.157
116.44,-17.23,0.157
116.44,-17.16,0.157
116.45,-17.09,0.157
116.45,-17.03,0.157
116.46,-16.96,0.157
116.47,-16.89,0.157
116.48,-16.83,0.157
116.48,-16.76,0.157
116.49,-16.69,0.157
116.50,-16.63,0.157
116.50,-16.56,0.157
116.51,-16.49,0.157
116.51,-16.43,0.158
116.52,-16.36,0.158
116.53,-16.29,0.158
116.54,-16.23,0.158
116.54,-16.16,0.158
116.55,-16.09,0.158
116.55,-16.03,0.158
116.56,-15.96,0.158
116.57,-15.89,0.158
116.58,-15.83,0.158
116.58,-15.76,0.158
116.59,-15.69,0.158
116.60,-15.63,0.158
116.60,-15.56,0.158
116.61,-15.49,0.158
116.61,-15.43,0.158
116.62,-15.36,0.158
116.63,-15.29,0.158
116.64,-15.23,0.158
116.64,-15.16,0.158
116.65,-15.09,0.158
116.65,-15.03,0.158
116.66,-14.96,0.158
116.67,-14.89,0.158
116.68,-14.82,0.158
116.68,-14.76,0.158
116.69,-14.69,0.158
116.70,-14.63,0.158
116.70,-14.56,0.158
116.71,-14.49,0.158
116.71,-14.42,0.158
116.72,-14.36,0.158
116.73,-14.29,0.159
116.74,-14.22,0.159
116.74,-14.16,0.159
116.75,-14.09,0.159
116.75,-14.02,0.159
116.76,-13.96,0.159
116.77,-13.89,0.159
116.78,-13.82,0.159
116.78,-13.76,0.159
116.79,-13.69,0.159
116.80,-13.62,0.159
116.80,-13.56,0.159
116.81,-13.49,0.159
116.81,-13.42,0.159
116.82,-13.36,0.159
116.83,-13.29,0.159
116.84,-13.22,0.159
116.84,-13.16,0.159
116.85,-13.09,0.159
116.85,-13.02,0.159
116.86,-12.95,0.159
116.87,-12.89,0.159
116.88,-12.82,0.159
116.88,-12.76,0.159
116.89,-12.69,0.159
116.90,-12.62,0.159
116.90,-12.56,0.159
116.91,-12.49,0.160
116.91,-12.42,0.160
116.92,-12.35,0.160
116.93,-12.29,0.160
116.94,-12.22,0.160
116.94,-12.15,0.160
116.95,-12.09,0.160
116.95,-12.02,0.160
116.96,-11.95,0.160
116.97,-11.89,0.160
116.98,-11.82,0.160
116.98,-11.75,0.160
116.99,-11.69,0.160
117.00,-11.62,0.160
117.00,-11.55,0.160
117.01,-11.49,0.160
117.01,-11.42,0.160
117.02,-11.35,0.160
117.03,-11.29,0.160
117.04,-11.22,0.160
117.04,-11.15,0.160
117.05,-11.09,0.160
117.05,-11.02,0.160
117.06,-10.95,0.161
117.07,-10.89,0.161
117.08,-10.82,0.161
117.08,-10.75,0.161
117.09,-10.69,0.161
117.10,-10.62,0.161
117.10,-10.55,0.161
117.11,-10.49,0.161
117.11,-10.42,0.161
117.12,-10.35,0.161
117.13,-10.29,0.161
117.14,-10.22,0.161
117.14,-10.15,0.161
117.15,-10.09,0.161
117.15,-10.02,0.161
117.16,-9.95,0.161
117.17,-9.89,0.161
117.18,-9.82,0.161
117.18,-9.75,0.161
117.19,-9.69,0.161
117.20,-9.62,0.161
117.20,-9.55,0.162
117.21,-9.49,0.162
117.21,-9.42,0.162
117.22,-9.35,0.162
117.23,-9.29,0.162
117.24,-9.22,0.162
117.24,-9.15,0.162
117.25,-9.09,0.162
117.25,-9.02,0.162
117.26,-8.95,0.162
117.27,-8.89,0.162
117.28,-8.82,0.162
117.28,-8.75,0.162
117.29,-8.69,0.163
117.30,-8.62,0.163
117.30,-8.55,0.163
117.31,-8.48,0.163
117.31,-8.42,0.163
117.32,-8.35,0.163
117.33,-8.28,0.163
117.34,-8.22,0.163
117.34,-8.15,0.163
117.35,-8.08,0.163
117.35,-8.02,0.163
117.36,-7.95,0.163
117.37,-7.88,0.163
117.38,-7.82,0.164
117.38,-7.75,0.164
117.39,-7.69,0.164
117.40,-7.62,0.164
117.40,-7.55,0.164
117.41,-7.48,0.164
117.41,-7.42,0.164
117.42,-7.35,0.164
117.43,-7.28,0.164
117.44,-7.22,0.164
117.44,-7.15,0.164
117.45,-7.08,0.165
117.45,-7.02,0.165
117.46,-6.95,0.165
117.47,-6.88,0.165
117.48,-6.82,0.165
117.48,-6.75,0.165
117.49,-6.68,0.165
117.50,-6.62,0.165
117.50,-6.55,0.165
117.51,-6.48,0.165
117.51,-6.42,0.166
117.52,-6.35,0.166
117.53,-6.28,0.166
117.54,-6.22,0.166
117.54,-6.15,0.166
117.55,-6.08,0.166
117.55,-6.02,0.166
117.56,-5.95,0.167
117.57,-5.88,0.167
117.58,-5.82,0.167
117.58,-5.75,0.167
117.59,-5.68,0.167
117.60,-5.62,0.167
117.60,-5.55,0.167
117.61,-5.48,0.168
117.61,-5.42,0.168
117.62,-5.35,0.168
117.63,-5.28,0.168
117.64,-5.22,0.168
117.64,-5.15,0.168
117.65,-5.08,0.169
117.65,-5.01,0.169
117.66,-4.95,0.169
117.67,-4.88,0.169
117.68,-4.82,0.169
117.68,-4.75,0.169
117.69,-4.68,0.169
117.70,-4.62,0.170
117.70,-4.55,0.170
117.71,-4.48,0.170
117.71,-4.42,0.170
117.72,-4.35,0.171
117.73,-4.28,0.171
117.74,-4.22,0.171
117.74,-4.15,0.171
117.75,-4.08,0.172
117.75,-4.02,0.172
117.76,-3.95,0.172
117.77,-3.88,0.172
117.78,-3.82,0.173
117.78,-3.75,0.173
117.79,-3.68,0.173
117.80,-3.62,0.174
117.80,-3.55,0.174
117.81,-3.48,0.174
117.81,-3.41,0.174
117.82,-3.35,0.174
117.83,-3.28,0.175
117.84,-3.22,0.175
117.84,-3.15,0.175
117.85,-3.08,0.175
117.85,-3.02,0.176
117.86,-2.95,0.176
117.87,-2.88,0.176
117.88,-2.81,0.176
117.88,-2.75,0.177
117.89,-2.68,0.177
117.90,-2.62,0.177
117.90,-2.55,0.178
117.91,-2.48,0.178
117.91,-2.42,0.178
117.92,-2.35,0.179
117.93,-2.28,0.179
117.94,-2.22,0.180
117.94,-2.15,0.180
117.95,-2.08,0.181
117.95,-2.01,0.181
117.96,-1.95,0.181
117.97,-1.88,0.182
117.98,-1.81,0.182
117.98,-1.75,0.182
117.99,-1.68,0.183
118.00,-1.61,0.183
118.00,-1.55,0.184
118.01,-1.48,0.184
118.01,-1.41,0.184
118.02,-1.35,0.185
118.03,-1.28,0.186
118.04,-1.21,0.187
118.04,-1.15,0.187
118.05,-1.08,0.187
118.05,-1.01,0.187
118.06,-0.95,0.188
118.07,-0.88,0.188
118.08,-0.82,0.189
118.08,-0.75,0.189
118.09,-0.68,0.190
118.10,-0.61,0.190
118.10,-0.55,0.190
118.11,-0.48,0.191
118.11,-0.41,0.192
118.12,-0.35,0.192
118.13,-0.28,0.192
118.14,-0.22,0.193
118.14,-0.15,0.193
118.15,-0.08,0.194
118.15,-0.02,0.194
118.16,0.05,0.194
118.17,0.12,0.196
118.18,0.18,0.197
118.18,0.25,0.197
118.19,0.32,0.198
118.20,0.39,0.198
118.20,0.45,0.198
118.21,0.52,0.200
118.21,0.59,0.200
118.22,0.65,0.201
118.23,0.72,0.201
118.24,0.78,0.202
118.24,0.85,0.202
118.25,0.92,0.202
118.25,0.98,0.203
118.26,1.05,0.203
118.27,1.12,0.203
118.28,1.18,0.204
118.28,1.25,0.204
118.29,1.32,0.204
118.30,1.38,0.204
118.30,1.45,0.205
118.31,1.52,0.205
118.31,1.58,0.205
118.32,1.65,0.205
118.33,1.72,0.206
118.34,1.78,0.206
118.34,1.85,0.206
118.35,1.92,0.207
118.35,1.98,0.207
118.36,2.05,0.207
118.37,2.12,0.207
118.38,2.18,0.207
118.38,2.25,0.208
118.39,2.32,0.208
118.40,2.38,0.208
118.40,2.45,0.208
118.41,2.52,0.208
118.41,2.58,0.209
118.42,2.65,0.209
118.43,2.72,0.209
118.44,2.78,0.209
118.44,2.85,0.209
118.45,2.92,0.209
118.45,2.98,0.209
118.46,3.05,0.209
118.47,3.12,0.210
118.48,3.18,0.210
118.48,3.25,0.210
118.49,3.32,0.210
118.50,3.38,0.210
118.50,3.45,0.210
118.51,3.52,0.210
118.51,3.59,0.210
118.52,3.65,0.210
118.53,3.72,0.210
118.54,3.79,0.210
118.54,3.85,0.210
118.55,3.92,0.210
118.55,3.99,0.210
118.56,4.05,0.210
118.57,4.12,0.210
118.58,4.19,0.210
118.58,4.25,0.210
118.59,4.32,0.210
118.60,4.39,0.210
118.60,4.46,0.210
118.61,4.52,0.210
118.61,4.59,0.210
118.62,4.65,0.210
118.63,4.72,0.210
118.64,4.79,0.210
118.64,4.86,0.210
118.65,4.92,0.210
118.65,4.99,0.210
118.66,5.05,0.210
118.67,5.12,0.210
118.68,5.19,0.210
118.68,5.26,0.209
118.69,5.32,0.209
118.70,5.39,0.209
118.70,5.46,0.209
118.71,5.52,0.209
118.71,5.59,0.209
118.72,5.66,0.209
118.73,5.72,0.209
118.74,5.79,0.209
118.74,5.86,0.209
118.75,5.92,0.209
118.75,5.99,0.209
118.76,6.06,0.209
118.77,6.12,0.208
118.78,6.19,0.208
118.78,6.26,0.208
118.79,6.32,0.208
118.80,6.39,0.208
118.80,6.46,0.208
118.81,6.53,0.208
118.81,6.59,0.208
118.82,6.66,0.208
118.83,6.72,0.208
118.84,6.79,0.208
118.84,6.86,0.208
118.85,6.93,0.208
118.85,6.99,0.207
118.86,7.06,0.207
118.87,7.13,0.207
118.88,7.19,0.207
118.88,7.26,0.207
118.89,7.33,0.207
118.90,7.39,0.207
118.90,7.46,0.207
118.91,7.53,0.207
118.91,7.59,0.207
118.92,7.66,0.207
118.93,7.73,0.207
118.94,7.79,0.207
118.94,7.86,0.207
118.95,7.93,0.207
118.95,7.99,0.207
118.96,8.06,0.207
118.97,8.13,0.207
118.98,8.19,0.207
118.98,8.26,0.207
118.99,8.33,0.207
119.00,8.39,0.207
119.00,8.46,0.207
119.01,8.53,0.207
119.01,8.59,0.207
119.02,8.66,0.207
119.03,8.73,0.207
119.04,8.80,0.206
119.04,8.86,0.206
119.05,8.93,0.206
119.05,8.99,0.206
119.06,9.06,0.206
119.07,9.13,0.206
119.08,9.20,0.206
119.08,9.26,0.206
119.09,9.33,0.206
119.10,9.40,0.206
119.10,9.46,0.206
119.11,9.53,0.206
119.11,9.60,0.206
119.12,9.66,0.206
119.13,9.73,0.206
119.14,9.80,0.206
119.14,9.86,0.206
119.15,9.93,0.206
119.15,10.00,0.206
119.16,10.06,0.206
119.17,10.13,0.206
119.18,10.20,0.206
119.18,10.26,0.206
119.19,10.33,0.206
119.20,10.40,0.206
119.20,10.47,0.206
119.21,10.53,0.206
119.21,10.60,0.206
119.22,10.66,0.206
119.23,10.73,0.206
119.24,10.80,0.206
119.24,10.86,0.206
119.25,10.93,0.207
119.25,11.00,0.207
119.26,11.06,0.207
119.27,11.13,0.207
119.28,11.20,0.207
119.28,11.26,0.207
119.29,11.33,0.207
119.30,11.40,0.207
119.30,11.47,0.207
119.31,11.53,0.207
119.31,11.60,0.207
119.32,11.67,0.207
119.33,11.73,0.207
119.34,11.80,0.207
119.34,11.86,0.207
119.35,11.93,0.207
119.35,12.00,0.207
119.36,12.07,0.207
119.37,12.13,0.207
119.38,12.20,0.207
119.38,12.27,0.207
119.39,12.33,0.207
119.40,12.40,0.207
119.40,12.47,0.207
119.41,12.53,0.207
119.41,12.60,0.207
119.42,12.67,0.207
119.43,12.73,0.207
119.44,12.80,0.207
119.44,12.87,0.207
119.45,12.93,0.207
119.45,13.00,0.207
119.46,13.07,0.207
119.47,13.13,0.207
119.48,13.20,0.207
119.48,13.27,0.207
119.49,13.33,0.207
119.50,13.40,0.207
119.50,13.47,0.207
119.51,13.54,0.207
119.51,13.60,0.207
119.52,13.67,0.207
119.53,13.73,0.207
119.54,13.80,0.207
119.54,13.87,0.207
119.55,13.94,0.207
119.55,14.00,0.207
119.56,14.07,0.207
119.57,14.13,0.207
119.58,14.20,0.207
119.58,14.27,0.207
119.59,14.34,0.207
119.60,14.40,0.207
119.60,14.47,0.208
119.61,14.54,0.208
119.61,14.60,0.208
119.62,14.67,0.208
119.63,14.74,0.208
119.64,14.80,0.208
119.64,14.87,0.208
119.65,14.94,0.208
119.65,15.00,0.208
119.66,15.07,0.208
119.67,15.14,0.208
119.68,15.20,0.208
119.68,15.27,0.208
119.69,15.34,0.208
119.70,15.40,0.208
119.70,15.47,0.208
119.71,15.54,0.208
119.71,15.60,0.208
119.72,15.67,0.208
119.73,15.74,0.208
119.74,15.80,0.208
119.74,15.87,0.208
119.75,15.94,0.208
119.75,16.00,0.208
119.76,16.07,0.208
119.77,16.14,0.208
119.78,16.20,0.208
119.78,16.27,0.208
119.79,16.34,0.208
119.80,16.40,0.208
119.80,16.47,0.208
119.81,16.54,0.209
119.81,16.60,0.209
119.82,16.67,0.209
119.83,16.74,0.209
119.84,16.80,0.209
119.84,16.87,0.209
119.85,16.94,0.209
119.85,17.00,0.209
119.86,17.07,0.209
119.87,17.14,0.209
119.88,17.21,0.209
119.88,17.27,0.209
119.89,17.34,0.209
119.90,17.41,0.209
119.90,17.47,0.209
119.91,17.54,0.209
119.91,17.60,0.209
119.92,17.67,0.209
119.93,17.74,0.209
119.94,17.81,0.209
119.94,17.87,0.209
119.95,17.94,0.209
119.95,18.01,0.209
119.96,18.07,0.209
119.97,18.14,0.209
119.98,18.21,0.210
119.98,18.27,0.210
119.99,18.34,0.210
120.00,18.41,0.210
120.00,18.47,0.210
120.01,18.54,0.210
120.01,18.61,0.210
120.02,18.67,0.210
120.03,18.74,0.210
120.04,18.81,0.210
120.04,18.87,0.210
120.05,18.94,0.210
120.05,19.01,0.210
120.06,19.07,0.210
120.07,19.14,0.210
120.08,19.21,0.210
120.08,19.28,0.210
120.09,19.34,0.210
120.10,19.41,0.210
120.10,19.48,0.210
120.11,19.54,0.210
120.11,19.61,0.210
120.12,19.68,0.210
120.13,19.74,0.210
120.14,19.81,0.210
120.14,19.88,0.210
120.15,19.94,0.210
120.15,20.01,0.210
120.16,20.08,0.210
120.17,20.14,0.210
120.18,20.21,0.211
120.18,20.28,0.211
120.19,20.34,0.211
120.20,20.41,0.211
120.20,20.48,0.211
120.21,20.54,0.211
120.21,20.61,0.211
120.22,20.68,0.211
120.23,20.74,0.211
120.24,20.81,0.211
120.24,20.87,0.211
120.25,20.94,0.211
120.25,21.01,0.211
120.26,21.08,0.211
120.27,21.14,0.211
120.28,21.21,0.211
120.28,21.28,0.211
120.29,21.34,0.211
120.30,21.41,0.211
120.30,21.48,0.211
120.31,21.54,0.211
120.31,21.61,0.211
120.32,21.68,0.211
120.33,21.74,0.211
120.34,21.81,0.211
120.34,21.88,0.211
120.35,21.94,0.211
120.35,22.01,0.211
120.36,22.08,0.212
120.37,22.14,0.212
120.38,22.21,0.212
120.38,22.28,0.212
120.39,22.34,0.212
120.40,22.41,0.212
120.40,22.48,0.212
120.41,22.54,0.212
120.41,22.61,0.212
120.42,22.68,0.212
120.43,22.74,0.212
120.44,22.81,0.212
120.44,22.88,0.212
120.45,22.94,0.212
120.45,23.01,0.212
120.46,23.08,0.212
120.47,23.14,0.212
120.48,23.21,0.212
120.48,23.28,0.212
120.49,23.35,0.212
120.50,23.41,0.212
120.50,23.48,0.212
120.51,23.55,0.212
120.51,23.61,0.212
120.52,23.68,0.212
120.53,23.75,0.212
120.54,23.81,0.212
120.54,23.88,0.212
120.55,23.95,0.212
120.55,24.01,0.213
120.56,24.08,0.213
120.57,24.15,0.213
120.58,24.21,0.213
120.58,24.28,0.213
120.59,24.35,0.213
120.60,24.41,0.213
120.60,24.48,0.213
120.61,24.55,0.213
120.61,24.61,0.213
120.62,24.68,0.213
120.63,24.75,0.213
120.64,24.81,0.213
120.64,24.88,0.213
120.65,24.95,0.213
120.65,25.01,0.213
120.66,25.08,0.213
120.67,25.15,0.213
120.68,25.21,0.213
120.68,25.28,0.213
120.69,25.35,0.213
120.70,25.42,0.213
120.70,25.48,0.214
120.71,25.55,0.214
120.71,25.61,0.214
120.72,25.68,0.214
120.73,25.75,0.214
120.74,25.81,0.214
120.74,25.88,0.214
120.75,25.95,0.214
120.75,26.01,0.214
120.76,26.08,0.214
120.77,26.15,0.214
120.78,26.22,0.214
120.78,26.28,0.214
120.79,26.35,0.214
120.80,26.42,0.214
120.80,26.48,0.214
120.81,26.55,0.214
120.81,26.62,0.214
120.82,26.68,0.214
120.83,26.75,0.214
120.84,26.82,0.214
120.84,26.88,0.214
120.85,26.95,0.214
120.85,27.02,0.214
120.86,27.08,0.215
120.87,27.15,0.215
120.88,27.22,0.215
120.88,27.28,0.215
120.89,27.35,0.215
120.90,27.42,0.215
120.90,27.48,0.215
120.91,27.55,0.215
120.91,27.62,0.215
120.92,27.69,0.215
120.93,27.75,0.215
120.94,27.82,0.215
120.94,27.88,
120.95,27.95,
120.95,28.02,
120.96,28.08,
120.97,28.15,
120.98,28.22,
120.98,28.29,
120.99,,
120.99,,