File: DSC/2025_06_15_CBN_PyroGA_MC_n60C_200C_100C_10Cmin_x5.csv
Filename,2025_06_15_CBN_PyroGA_MC_n60C_200C_100C_10Cmin_x5
Instrument name,DSC2A-00468 (192.168.1.100)
Operator,Yarger
rundate,6/15/2025
Sample name,2025_06_15_CBN_PyroGA_MC_n60C_200C_100C_10Cmin_x5
proceduresegments,Data Off ; Equilibrate -60.00 °C; Data On ; Ramp 10.00 °C/min to 200.00 °C; Data Off ; Isothermal 2.0 min; Data On ; Ramp 10.00 °C/min to -60.00 °C; Data Off ; Isothermal 2.0 min; Data On ; Ramp 10.00 °C/min to 200.00 °C; Data Off ; Isothermal 2.0 min; Data On ; Ramp 10.00 °C/min to -60.00 °C; Data Off ; Isothermal 2.0 min; Data On ; Ramp 10.00 °C/min to 100.00 °C; Data Off ; Isothermal 2.0 min; Data On ; Ramp 10.00 °C/min to -60.00 °C; Data Off ; Isothermal 1.0 min; Data On ; Ramp 10.00 °C/min to 100.00 °C; Data Off ; Isothermal 2.0 min; Data On ; Ramp 10.00 °C/min to -60.00 °C; Data Off ; Isothermal 2.0 min; Data On ; Ramp 10.00 °C/min to 30.00 °C
[File Parameters]
Run date,6/15/2025 7:09:32 AM
Trios version,5.1.1.46572
Original File Name,
Current File Name,D:\DSC2500\JYarger\2025_06_15_CBN_PyroGA_MC_n60C_200C_100C_10Cmin_x5.tri
[Procedure]
Procedure Name,CBN_PGA_n60C_200C_100C_10Cmin_x5
Sample Name,2025_06_15_CBN_PyroGA_MC_n60C_200C_100C_10Cmin_x5
Sample Mass,7.07 mg
Reference Sample Mass,0 mg
Pan Mass,56.42 mg
Pan Number,30
Reference Pan Mass,57.05 mg
Reference Pan Number,28
Pan Type,Tzero Aluminum Hermetic
Comments,Al Hermetic DSC Consumables sealed Pan/Lid. A2 Tray (Google Sheet: DSC_Samples_A2_Tray_May2025)
Project Name,CA
Operator,Yarger
Test,Custom
Unload Max Temperature,30
Unload Min Temperature,30
Load Max Temperature,30
Load Min Temperature,30
Stop on Gas Flow Error,Yes
[Signal List]
Signal #1,Time (min)
Signal #2,Temperature (°C)
Signal #3,Heat Flow (mW)
Signal #4,Delta T (µV)
Signal #5,Delta Tzero (µV)
Signal #6,Tzero Temperature (°C)
Signal #7,Cell Purge (mL/min)
Signal #8,Heater Temp (°C)
Signal #9,Power Delivered (W)
Signal #10,Reference Junction Temperature (°C)
Signal #11,Flange Temperature (°C)
Signal #12,Heat Flow Phase (rad)
Signal #13,Total Heat Capacity (J/°C)
Signal #14,Heat Capacity (J/°C)
[Configuration]
Company Name,ASU
Instrument Name,DSC2A-00468
Instrument Type,DSC2500
Serial Number,DSC2A-00468
IP,192.168.1.100
Location of Instrument,MRRC
DisplayType,Unknown
Sample Interval ,0.1 s/pt
Selected Heat Flow,T4P
Exotherm Direction,Down
Cell Serial,DRC2-00792
Lid Type,Standard
Cooler,RCS 90
Leave Cooler on at End of Sequence,On
Gas 2,Nitrogen
Gas Selected,Channel 1
Flow Rate,50 mL/min
Secondary Purge,On
Licensed Heat Flow,Heat Flow T4P
Modulation Licensed,Yes
[Versions]
Common IDD Version,1
Cortex Version,VER 2.10.2.31
Driver,5.0.0.6
GDM Version,1.0.3.3
TouchscreenVersion,1.0.0.16145
FEP Version,1.2.1.21
FEP Bootloader,2.0.0.5
AutoSampler Version,2.1.1.26
Auto Sampler Bootloader,2.0.0.5
FCM Version,1.1.0.3
FCM Bootloader,2.0.0.5
[Experiment Logs]
Experiment Log Entry # 1,Data On set to 0
Experiment Log Entry # 3,Equilibrate Segment -60 (C) Started
Experiment Log Entry # 5,Air Cool is off.
Experiment Log Entry # 7,Data On set to 1
Experiment Log Entry # 9,Ramp Segment 10 C/min to 200 Started
Experiment Log Entry # 11,Data On set to 0
Experiment Log Entry # 13,Isothermal Segment 2 min started
Experiment Log Entry # 15,Data On set to 1
Experiment Log Entry # 17,Ramp Segment 10 C/min to -60 Started
Experiment Log Entry # 19,Data On set to 0
Experiment Log Entry # 21,Isothermal Segment 2 min started
Experiment Log Entry # 23,Data On set to 1
Experiment Log Entry # 25,Ramp Segment 10 C/min to 200 Started
Experiment Log Entry # 27,Data On set to 0
Experiment Log Entry # 29,Isothermal Segment 2 min started
Experiment Log Entry # 31,Data On set to 1
Experiment Log Entry # 33,Ramp Segment 10 C/min to -60 Started
Experiment Log Entry # 35,Data On set to 0
Experiment Log Entry # 37,Isothermal Segment 2 min started
Experiment Log Entry # 39,Data On set to 1
Experiment Log Entry # 41,Ramp Segment 10 C/min to 100 Started
Experiment Log Entry # 43,Data On set to 0
Experiment Log Entry # 45,Isothermal Segment 2 min started
Experiment Log Entry # 47,Data On set to 1
Experiment Log Entry # 49,Ramp Segment 10 C/min to -60 Started
Experiment Log Entry # 51,Data On set to 0
Experiment Log Entry # 53,Isothermal Segment 1 min started
Experiment Log Entry # 55,Data On set to 1
Experiment Log Entry # 57,Ramp Segment 10 C/min to 100 Started
Experiment Log Entry # 59,Data On set to 0
Experiment Log Entry # 61,Isothermal Segment 2 min started
Experiment Log Entry # 63,Data On set to 1
Experiment Log Entry # 65,Ramp Segment 10 C/min to -60 Started
Experiment Log Entry # 67,Data On set to 0
Experiment Log Entry # 69,Isothermal Segment 2 min started
Experiment Log Entry # 71,Data On set to 1
Experiment Log Entry # 73,Ramp Segment 10 C/min to 30 Started
[Method Log]
Method Log Entry # 1,Data Off
Method Log Entry # 2,Equilibrate -60 °C
Method Log Entry # 3,Data On
Method Log Entry # 4,(Ramp 325319) Ramp 10 °C/minute to 200 °C
Method Log Entry # 5,Data Off
Method Log Entry # 6,Isothermal 2 minutes
Method Log Entry # 7,Data On
Method Log Entry # 8,(Ramp 325323) Ramp 10 °C/minute to -60 °C
Method Log Entry # 9,Data Off
Method Log Entry # 10,Isothermal 2 minutes
Method Log Entry # 11,Data On
Method Log Entry # 12,(Ramp 325327) Ramp 10 °C/minute to 200 °C
Method Log Entry # 13,Data Off
Method Log Entry # 14,Isothermal 2 minutes
Method Log Entry # 15,Data On
Method Log Entry # 16,(Ramp 325331) Ramp 10 °C/minute to -60 °C
Method Log Entry # 17,Data Off
Method Log Entry # 18,Isothermal 2 minutes
Method Log Entry # 19,Data On
Method Log Entry # 20,(Ramp 325335) Ramp 10 °C/minute to 100 °C
Method Log Entry # 21,Data Off
Method Log Entry # 22,Isothermal 2 minutes
Method Log Entry # 23,Data On
Method Log Entry # 24,(Ramp 325339) Ramp 10 °C/minute to -60 °C
Method Log Entry # 25,Data Off
Method Log Entry # 26,Isothermal 1 minutes
Method Log Entry # 27,Data On
Method Log Entry # 28,(Ramp 325343) Ramp 10 °C/minute to 100 °C
Method Log Entry # 29,Data Off
Method Log Entry # 30,Isothermal 2 minutes
Method Log Entry # 31,Data On
Method Log Entry # 32,(Ramp 325347) Ramp 10 °C/minute to -60 °C
Method Log Entry # 33,Data Off
Method Log Entry # 34,Isothermal 2 minutes
Method Log Entry # 35,Data On
Method Log Entry # 36,(Ramp 325351) Ramp 10 °C/minute to 30 °C
Cell Serial,DRC2-00792
[T1 Calibration]
Slope,-0.008529666
Offset,9.636258
Initial Temperature,98.23
GUID,f8bfdadc-4977-4fdf-ba6d-0ba9134940c3
[TZero Calibration]
Date Applied,11/29/2022 4:06:13 PM
Description,From -89.059 °C to 396.009 °C at 20.000°C/min
Gas Type,Nitrogen
Pan Type,None
Source Files 1,C:\Users\yargerlab\Desktop\DSC Data\General\TZero_calibration_11_29_22_2nd(2).tri
Source Files 2,C:\Users\yargerlab\Desktop\DSC Data\General\TZero_calibration_11_29_22_2nd(3).tri
Delta T Offset,13.05235
Delta T Slope,-0.007271007
Delta T0 Offset,-13.69128
Delta T0 Slope,0.06063341
[Temperature Calibration]
Date Applied,11/29/2022 7:12:28 PM
Description,From 106.590 °C to 186.590 °C at 10.000°C/min
Gas Type,Nitrogen
Pan Type,Tzero Aluminum Hermetic
Source Files 1,C:\Users\yargerlab\Desktop\DSC Data\General\Indium(6).tri
Measured 1,157.391
Known 1,156.598
[Cell Constant Calibration]
Date Applied,11/29/2022 7:12:29 PM
Description,From 106.590 °C to 186.590 °C at 10.000°C/min
Gas Type,Nitrogen
Pan Type,Tzero Aluminum Hermetic
Source Files 1,C:\Users\yargerlab\Desktop\DSC Data\General\Indium(6).tri
T4P KCell,1.006051
Onset Slope,63.26126 mW/°C
[Direct Cp Calibration]
Date Applied,11/30/2022 11:04:51 AM
Description,From -79.983 °C to 298.409 °C at 10.000°C/min
Gas Type,Nitrogen
Pan Type,Tzero Aluminum Hermetic
Source Files 1,C:\Users\yargerlab\Desktop\DSC Data\General\Sapphire_Heat_Capacity_11_30_22.tri
[Rev Cp Calibration]
Date Applied,11/30/2022 1:58:51 PM
Description,From -79.996 °C to 292.812 °C at 3.000°C/min
Gas Type,Nitrogen
Pan Type,Tzero Aluminum Hermetic
Source Files 1,C:\Users\yargerlab\Desktop\DSC Data\General\Sapphire_MDSC_Calibration_11_30_22.tri
[step]
Ramp 10.00 °C/min to 200.00 °C
Time,Temperature,Heat Flow (Normalized)
min,°C,W/g
0.00,-59.67,-0.058
0.02,-59.69,-0.057
0.04,-59.69,-0.052
0.05,-59.69,-0.044
0.07,-59.68,-0.032
0.09,-59.64,-0.019
0.11,-59.59,-0.005
0.13,-59.52,0.011
0.15,-59.43,0.028
0.16,-59.32,0.044
0.18,-59.21,0.060
0.20,-59.07,0.074
0.22,-58.94,0.088
0.24,-58.79,0.100
0.26,-58.64,0.111
0.28,-58.49,0.122
0.29,-58.34,0.131
0.31,-58.18,0.140
0.33,-58.01,0.146
0.35,-57.85,0.153
0.37,-57.68,0.158
0.39,-57.52,0.164
0.40,-57.35,0.168
0.42,-57.18,0.173
0.44,-57.01,0.176
0.46,-56.83,0.180
0.48,-56.66,0.181
0.50,-56.49,0.185
0.51,-56.31,0.186
0.53,-56.14,0.188
0.55,-55.96,0.190
0.57,-55.79,0.191
0.59,-55.61,0.193
0.60,-55.43,0.194
0.62,-55.25,0.195
0.64,-55.08,0.196
0.66,-54.90,0.197
0.68,-54.72,0.198
0.70,-54.54,0.199
0.72,-54.36,0.199
0.73,-54.18,0.200
0.75,-54.00,0.200
0.77,-53.82,0.201
0.79,-53.64,0.201
0.81,-53.46,0.201
0.83,-53.28,0.202
0.84,-53.10,0.202
0.86,-52.92,0.203
0.88,-52.74,0.203
0.90,-52.56,0.203
0.92,-52.38,0.204
0.93,-52.20,0.204
0.95,-52.02,0.204
0.97,-51.84,0.205
0.99,-51.65,0.205
1.01,-51.47,0.206
1.03,-51.29,0.206
1.05,-51.11,0.206
1.06,-50.92,0.207
1.08,-50.74,0.207
1.10,-50.56,0.207
1.12,-50.38,0.207
1.14,-50.20,0.208
1.16,-50.02,0.208
1.17,-49.83,0.208
1.19,-49.65,0.209
1.21,-49.47,0.209
1.23,-49.29,0.209
1.25,-49.10,0.209
1.27,-48.92,0.209
1.28,-48.74,0.210
1.30,-48.56,0.210
1.32,-48.37,0.210
1.34,-48.19,0.210
1.36,-48.01,0.210
1.38,-47.83,0.211
1.39,-47.64,0.211
1.41,-47.46,0.211
1.43,-47.28,0.211
1.45,-47.09,0.211
1.47,-46.91,0.212
1.48,-46.73,0.212
1.50,-46.55,0.212
1.52,-46.36,0.212
1.54,-46.18,0.212
1.56,-46.00,0.212
1.58,-45.81,0.213
1.59,-45.63,0.213
1.61,-45.45,0.213
1.63,-45.26,0.213
1.65,-45.08,0.213
1.67,-44.90,0.214
1.69,-44.71,0.214
1.71,-44.53,0.214
1.72,-44.35,0.214
1.74,-44.16,0.214
1.76,-43.98,0.214
1.78,-43.80,0.214
1.80,-43.62,0.214
1.82,-43.43,0.215
1.83,-43.25,0.215
1.85,-43.06,0.215
1.87,-42.88,0.215
1.89,-42.70,0.215
1.91,-42.51,0.215
1.93,-42.33,0.215
1.94,-42.15,0.215
1.96,-41.96,0.216
1.98,-41.78,0.216
2.00,-41.60,0.216
2.02,-41.41,0.216
2.03,-41.23,0.216
2.05,-41.05,0.216
2.07,-40.86,0.216
2.09,-40.68,0.216
2.11,-40.50,0.217
2.13,-40.31,0.217
2.14,-40.13,0.217
2.16,-39.94,0.217
2.18,-39.76,0.217
2.20,-39.58,0.217
2.22,-39.39,0.217
2.24,-39.21,0.217
2.26,-39.03,0.218
2.27,-38.84,0.218
2.29,-38.66,0.218
2.31,-38.48,0.218
2.33,-38.29,0.218
2.35,-38.11,0.218
2.36,-37.93,0.218
2.38,-37.74,0.218
2.40,-37.56,0.218
2.42,-37.38,0.219
2.44,-37.19,0.219
2.46,-37.01,0.219
2.48,-36.82,0.219
2.49,-36.64,0.219
2.51,-36.46,0.219
2.53,-36.27,0.219
2.55,-36.09,0.219
2.57,-35.91,0.219
2.59,-35.72,0.220
2.60,-35.54,0.220
2.62,-35.36,0.220
2.64,-35.17,0.220
2.66,-34.99,0.220
2.68,-34.80,0.220
2.69,-34.62,0.220
2.71,-34.44,0.220
2.73,-34.25,0.221
2.75,-34.07,0.221
2.77,-33.89,0.221
2.79,-33.70,0.221
2.81,-33.52,0.221
2.82,-33.34,0.221
2.84,-33.15,0.221
2.86,-32.97,0.221
2.88,-32.79,0.221
2.90,-32.60,0.222
2.91,-32.42,0.222
2.93,-32.23,0.222
2.95,-32.05,0.222
2.97,-31.87,0.222
2.99,-31.68,0.222
3.01,-31.50,0.222
3.03,-31.32,0.222
3.04,-31.13,0.223
3.06,-30.95,0.223
3.08,-30.77,0.223
3.10,-30.58,0.223
3.12,-30.40,0.223
3.14,-30.22,0.223
3.15,-30.03,0.223
3.17,-29.85,0.223
3.19,-29.66,0.223
3.21,-29.48,0.224
3.23,-29.30,0.224
3.24,-29.11,0.224
3.26,-28.93,0.224
3.28,-28.75,0.224
3.30,-28.56,0.224
3.32,-28.38,0.224
3.34,-28.20,0.225
3.36,-28.01,0.225
3.37,-27.83,0.225
3.39,-27.64,0.225
3.41,-27.46,0.225
3.43,-27.28,0.225
3.45,-27.10,0.225
3.46,-26.91,0.225
3.48,-26.73,0.226
3.50,-26.54,0.226
3.52,-26.36,0.226
3.54,-26.18,0.226
3.56,-25.99,0.226
3.58,-25.81,0.226
3.59,-25.63,0.226
3.61,-25.44,0.226
3.63,-25.26,0.227
3.65,-25.08,0.227
3.67,-24.89,0.227
3.69,-24.71,0.227
3.70,-24.52,0.227
3.72,-24.34,0.227
3.74,-24.16,0.227
3.76,-23.98,0.227
3.78,-23.79,0.228
3.79,-23.61,0.228
3.81,-23.42,0.228
3.83,-23.24,0.228
3.85,-23.06,0.228
3.87,-22.87,0.228
3.89,-22.69,0.228
3.91,-22.51,0.228
3.92,-22.32,0.228
3.94,-22.14,0.229
3.96,-21.96,0.229
3.98,-21.77,0.229
4.00,-21.59,0.229
4.01,-21.41,0.229
4.03,-21.22,0.229
4.05,-21.04,0.230
4.07,-20.85,0.230
4.09,-20.67,0.230
4.11,-20.49,0.230
4.13,-20.30,0.230
4.14,-20.12,0.230
4.16,-19.94,0.230
4.18,-19.75,0.230
4.20,-19.57,0.231
4.22,-19.39,0.231
4.24,-19.20,0.231
4.25,-19.02,0.231
4.27,-18.83,0.231
4.29,-18.65,0.231
4.31,-18.47,0.231
4.33,-18.29,0.231
4.35,-18.10,0.232
4.36,-17.92,0.232
4.38,-17.73,0.232
4.40,-17.55,0.232
4.42,-17.37,0.232
4.44,-17.18,0.232
4.45,-17.00,0.232
4.47,-16.82,0.232
4.49,-16.63,0.233
4.51,-16.45,0.233
4.53,-16.26,0.233
4.55,-16.08,0.233
4.56,-15.90,0.233
4.58,-15.71,0.233
4.60,-15.53,0.233
4.62,-15.35,0.234
4.64,-15.16,0.234
4.66,-14.98,0.234
4.68,-14.80,0.234
4.69,-14.61,0.234
4.71,-14.43,0.234
4.73,-14.25,0.234
4.75,-14.06,0.234
4.77,-13.88,0.235
4.79,-13.69,0.235
4.80,-13.51,0.235
4.82,-13.33,0.235
4.84,-13.15,0.235
4.86,-12.96,0.235
4.88,-12.78,0.235
4.90,-12.59,0.236
4.91,-12.41,0.236
4.93,-12.23,0.236
4.95,-12.04,0.236
4.97,-11.86,0.236
4.99,-11.68,0.236
5.00,-11.49,0.236
5.02,-11.31,0.237
5.04,-11.13,0.237
5.06,-10.94,0.237
5.08,-10.76,0.237
5.10,-10.58,0.237
5.11,-10.39,0.237
5.13,-10.21,0.237
5.15,-10.03,0.237
5.17,-9.84,0.238
5.19,-9.66,0.238
5.21,-9.47,0.238
5.23,-9.29,0.238
5.24,-9.11,0.238
5.26,-8.92,0.238
5.28,-8.74,0.238
5.30,-8.56,0.239
5.32,-8.37,0.239
5.34,-8.19,0.239
5.35,-8.01,0.239
5.37,-7.82,0.239
5.39,-7.64,0.239
5.41,-7.46,0.240
5.43,-7.27,0.240
5.45,-7.09,0.240
5.46,-6.91,0.240
5.48,-6.72,0.240
5.50,-6.54,0.240
5.52,-6.35,0.241
5.54,-6.17,0.241
5.55,-5.99,0.241
5.57,-5.81,0.241
5.59,-5.62,0.241
5.61,-5.44,0.241
5.63,-5.25,0.242
5.65,-5.07,0.242
5.66,-4.89,0.242
5.68,-4.70,0.242
5.70,-4.52,0.242
5.72,-4.34,0.242
5.74,-4.15,0.242
5.76,-3.97,0.243
5.78,-3.78,0.243
5.79,-3.60,0.243
5.81,-3.42,0.243
5.83,-3.23,0.243
5.85,-3.05,0.243
5.87,-2.87,0.244
5.89,-2.68,0.244
5.90,-2.50,0.244
5.92,-2.32,0.244
5.94,-2.13,0.244
5.96,-1.95,0.244
5.98,-1.77,0.245
6.00,-1.58,0.245
6.01,-1.40,0.245
6.03,-1.22,0.245
6.05,-1.03,0.245
6.07,-0.85,0.245
6.09,-0.67,0.245
6.10,-0.48,0.246
6.12,-0.30,0.246
6.14,-0.11,0.246
6.16,0.07,0.246
6.18,0.25,0.246
6.20,0.44,0.246
6.21,0.62,0.247
6.23,0.80,0.247
6.25,0.99,0.247
6.27,1.17,0.247
6.29,1.35,0.247
6.31,1.54,0.247
6.33,1.72,0.247
6.34,1.91,0.248
6.36,2.09,0.248
6.38,2.27,0.248
6.40,2.46,0.248
6.42,2.64,0.248
6.44,2.82,0.248
6.45,3.01,0.249
6.47,3.19,0.249
6.49,3.37,0.249
6.51,3.56,0.249
6.53,3.74,0.249
6.55,3.92,0.249
6.56,4.11,0.250
6.58,4.29,0.250
6.60,4.47,0.250
6.62,4.66,0.250
6.64,4.84,0.250
6.65,5.03,0.250
6.67,5.21,0.251
6.69,5.39,0.251
6.71,5.58,0.251
6.73,5.76,0.251
6.75,5.94,0.251
6.76,6.13,0.251
6.78,6.31,0.252
6.80,6.50,0.252
6.82,6.68,0.252
6.84,6.86,0.252
6.86,7.05,0.252
6.88,7.23,0.252
6.89,7.41,0.253
6.91,7.60,0.253
6.93,7.78,0.253
6.95,7.96,0.253
6.97,8.15,0.253
6.99,8.33,0.253
7.00,8.51,0.254
7.02,8.70,0.254
7.04,8.88,0.254
7.06,9.06,0.254
7.08,9.25,0.254
7.10,9.43,0.254
7.11,9.61,0.255
7.13,9.80,0.255
7.15,9.98,0.255
7.17,10.17,0.255
7.19,10.35,0.255
7.20,10.53,0.255
7.22,10.72,0.256
7.24,10.90,0.256
7.26,11.08,0.256
7.28,11.27,0.256
7.30,11.45,0.256
7.31,11.63,0.256
7.33,11.82,0.257
7.35,12.00,0.257
7.37,12.18,0.257
7.39,12.37,0.257
7.41,12.55,0.257
7.43,12.73,0.258
7.44,12.92,0.258
7.46,13.10,0.258
7.48,13.29,0.258
7.50,13.47,0.258
7.52,13.65,0.259
7.54,13.83,0.259
7.55,14.02,0.259
7.57,14.20,0.259
7.59,14.39,0.259
7.61,14.57,0.259
7.63,14.75,0.260
7.65,14.94,0.260
7.66,15.12,0.260
7.68,15.30,0.260
7.70,15.49,0.260
7.72,15.67,0.260
7.74,15.85,0.261
7.75,16.04,0.261
7.77,16.22,0.261
7.79,16.40,0.261
7.81,16.59,0.261
7.83,16.77,0.262
7.85,16.95,0.262
7.86,17.14,0.262
7.88,17.32,0.262
7.90,17.51,0.262
7.92,17.69,0.263
7.94,17.87,0.263
7.96,18.06,0.263
7.98,18.24,0.263
7.99,18.42,0.263
8.01,18.61,0.264
8.03,18.79,0.264
8.05,18.97,0.264
8.07,19.16,0.264
8.09,19.34,0.264
8.10,19.52,0.264
8.12,19.71,0.265
8.14,19.89,0.265
8.16,20.07,0.265
8.18,20.26,0.265
8.20,20.44,0.265
8.21,20.62,0.266
8.23,20.81,0.266
8.25,20.99,0.266
8.27,21.18,0.266
8.29,21.36,0.266
8.30,21.54,0.266
8.32,21.73,0.267
8.34,21.91,0.267
8.36,22.09,0.267
8.38,22.28,0.267
8.40,22.46,0.268
8.41,22.64,0.268
8.43,22.83,0.268
8.45,23.01,0.268
8.47,23.19,0.268
8.49,23.38,0.268
8.51,23.56,0.269
8.53,23.74,0.269
8.54,23.93,0.269
8.56,24.11,0.269
8.58,24.29,0.269
8.60,24.48,0.270
8.62,24.66,0.270
8.63,24.84,0.270
8.65,25.03,0.270
8.67,25.21,0.270
8.69,25.40,0.271
8.71,25.58,0.271
8.73,25.76,0.271
8.75,25.94,0.271
8.76,26.13,0.271
8.78,26.31,0.272
8.80,26.50,0.272
8.82,26.68,0.272
8.84,26.86,0.272
8.85,27.05,0.272
8.87,27.23,0.273
8.89,27.41,0.273
8.91,27.60,0.273
8.93,27.78,0.273
8.95,27.96,0.273
8.97,28.15,0.274
8.98,28.33,0.274
9.00,28.52,0.274
9.02,28.70,0.274
9.04,28.88,0.274
9.06,29.07,0.275
9.08,29.25,0.275
9.09,29.43,0.275
9.11,29.62,0.275
9.13,29.80,0.275
9.15,29.98,0.275
9.17,30.17,0.276
9.18,30.35,0.276
9.20,30.53,0.276
9.22,30.72,0.276
9.24,30.90,0.276
9.26,31.09,0.277
9.28,31.27,0.277
9.30,31.45,0.277
9.31,31.63,0.277
9.33,31.82,0.277
9.35,32.00,0.278
9.37,32.19,0.278
9.39,32.37,0.278
9.40,32.55,0.278
9.42,32.74,0.278
9.44,32.92,0.278
9.46,33.10,0.279
9.48,33.29,0.279
9.50,33.47,0.279
9.52,33.65,0.279
9.53,33.84,0.279
9.55,34.02,0.280
9.57,34.21,0.280
9.59,34.39,0.280
9.61,34.57,0.280
9.63,34.76,0.280
9.64,34.94,0.281
9.66,35.12,0.281
9.68,35.31,0.281
9.70,35.49,0.281
9.72,35.67,0.281
9.73,35.86,0.281
9.75,36.04,0.282
9.77,36.22,0.282
9.79,36.41,0.282
9.81,36.59,0.282
9.83,36.77,0.282
9.85,36.96,0.283
9.86,37.14,0.283
9.88,37.32,0.283
9.90,37.51,0.283
9.92,37.69,0.283
9.94,37.87,0.283
9.95,38.06,0.284
9.97,38.24,0.284
9.99,38.42,0.284
10.01,38.61,0.284
10.03,38.79,0.284
10.05,38.98,0.284
10.07,39.16,0.285
10.08,39.34,0.285
10.10,39.52,0.285
10.12,39.71,0.285
10.14,39.89,0.285
10.16,40.08,0.286
10.18,40.26,0.286
10.19,40.44,0.286
10.21,40.63,0.286
10.23,40.81,0.286
10.25,40.99,0.286
10.27,41.18,0.287
10.28,41.36,0.287
10.30,41.54,0.287
10.32,41.73,0.287
10.34,41.91,0.287
10.36,42.09,0.288
10.38,42.28,0.288
10.40,42.46,0.288
10.41,42.64,0.288
10.43,42.83,0.288
10.45,43.01,0.289
10.47,43.20,0.289
10.49,43.38,0.289
10.50,43.56,0.289
10.52,43.75,0.290
10.54,43.93,0.290
10.56,44.11,0.290
10.58,44.30,0.290
10.60,44.48,0.290
10.62,44.66,0.290
10.63,44.85,0.291
10.65,45.03,0.291
10.67,45.21,0.291
10.69,45.40,0.291
10.71,45.58,0.291
10.73,45.77,0.291
10.74,45.95,0.292
10.76,46.13,0.292
10.78,46.32,0.292
10.80,46.50,0.292
10.82,46.68,0.292
10.83,46.87,0.293
10.85,47.05,0.293
10.87,47.23,0.293
10.89,47.42,0.293
10.91,47.60,0.293
10.93,47.79,0.293
10.95,47.97,0.294
10.96,48.15,0.294
10.98,48.33,0.294
11.00,48.52,0.294
11.02,48.70,0.294
11.04,48.89,0.295
11.05,49.07,0.295
11.07,49.25,0.295
11.09,49.44,0.295
11.11,49.62,0.295
11.13,49.80,0.296
11.15,49.99,0.296
11.17,50.17,0.296
11.18,50.35,0.296
11.20,50.54,0.296
11.22,50.72,0.297
11.24,50.90,0.297
11.26,51.09,0.297
11.28,51.27,0.297
11.29,51.45,0.297
11.31,51.64,0.298
11.33,51.82,0.298
11.35,52.00,0.298
11.37,52.19,0.298
11.38,52.37,0.298
11.40,52.55,0.299
11.42,52.74,0.299
11.44,52.92,0.299
11.46,53.11,0.299
11.48,53.29,0.299
11.50,53.47,0.299
11.51,53.66,0.300
11.53,53.84,0.300
11.55,54.02,0.300
11.57,54.21,0.300
11.59,54.39,0.300
11.60,54.57,0.301
11.62,54.76,0.301
11.64,54.94,0.301
11.66,55.12,0.301
11.68,55.31,0.301
11.70,55.49,0.302
11.72,55.67,0.302
11.73,55.86,0.302
11.75,56.04,0.302
11.77,56.22,0.302
11.79,56.41,0.303
11.81,56.59,0.303
11.83,56.77,0.303
11.84,56.96,0.303
11.86,57.14,0.303
11.88,57.32,0.304
11.90,57.51,0.304
11.92,57.69,0.304
11.93,57.87,0.304
11.95,58.06,0.304
11.97,58.24,0.305
11.99,58.43,0.305
12.01,58.61,0.305
12.03,58.79,0.305
12.05,58.97,0.305
12.06,59.16,0.306
12.08,59.34,0.306
12.10,59.53,0.306
12.12,59.71,0.306
12.14,59.89,0.307
12.15,60.08,0.307
12.17,60.26,0.307
12.19,60.44,0.307
12.21,60.62,0.308
12.23,60.81,0.308
12.25,60.99,0.308
12.27,61.17,0.308
12.28,61.36,0.309
12.30,61.54,0.309
12.32,61.73,0.309
12.34,61.91,0.310
12.36,62.09,0.310
12.38,62.27,0.310
12.39,62.46,0.311
12.41,62.64,0.312
12.43,62.82,0.314
12.45,63.01,0.316
12.47,63.19,0.321
12.48,63.37,0.326
12.50,63.55,0.331
12.52,63.74,0.336
12.54,63.92,0.342
12.56,64.10,0.348
12.58,64.28,0.354
12.60,64.46,0.359
12.61,64.64,0.365
12.63,64.83,0.366
12.65,65.01,0.375
12.67,65.19,0.376
12.69,65.37,0.377
12.70,65.55,0.380
12.72,65.73,0.381
12.74,65.92,0.380
12.76,66.10,0.380
12.78,66.28,0.377
12.80,66.47,0.372
12.82,66.65,0.366
12.83,66.84,0.362
12.85,67.02,0.357
12.87,67.21,0.354
12.89,67.39,0.351
12.91,67.58,0.348
12.93,67.76,0.346
12.94,67.95,0.345
12.96,68.13,0.344
12.98,68.32,0.343
13.00,68.50,0.343
13.02,68.69,0.343
13.03,68.87,0.343
13.05,69.06,0.343
13.07,69.24,0.343
13.09,69.42,0.343
13.11,69.60,0.344
13.13,69.79,0.346
13.15,69.97,0.348
13.16,70.15,0.352
13.18,70.34,0.356
13.20,70.52,0.360
13.22,70.70,0.364
13.24,70.88,0.370
13.25,71.07,0.376
13.27,71.25,0.382
13.29,71.43,0.390
13.31,71.61,0.398
13.33,71.79,0.409
13.35,71.97,0.419
13.37,72.15,0.432
13.38,72.33,0.446
13.40,72.50,0.465
13.42,72.68,0.483
13.44,72.86,0.506
13.46,73.03,0.532
13.48,73.21,0.560
13.49,73.38,0.593
13.51,73.55,0.630
13.53,73.72,0.669
13.55,73.88,0.712
13.57,74.05,0.759
13.58,74.21,0.806
13.60,74.38,0.856
13.62,74.54,0.904
13.64,74.70,0.951
13.66,74.87,0.998
13.68,75.03,1.053
13.70,75.19,1.088
13.71,75.35,1.126
13.73,75.51,1.183
13.75,75.67,1.288
13.77,75.81,1.465
13.79,75.95,1.593
13.80,76.08,1.642
13.82,76.23,1.695
13.84,76.38,1.724
13.86,76.54,1.732
13.88,76.70,1.736
13.90,76.85,1.966
13.92,76.98,2.144
13.93,77.11,2.244
13.95,77.25,2.290
13.97,77.39,2.401
13.99,77.53,2.467
14.01,77.68,2.436
14.03,77.85,2.351
14.04,78.03,2.230
14.06,78.24,2.073
14.08,78.46,1.892
14.10,78.70,1.701
14.12,78.95,1.506
14.13,79.20,1.315
14.15,79.47,1.138
14.17,79.73,0.987
14.19,79.98,0.864
14.21,80.23,0.768
14.23,80.48,0.692
14.25,80.71,0.637
14.26,80.94,0.593
14.28,81.16,0.552
14.30,81.37,0.524
14.32,81.58,0.496
14.34,81.79,0.475
14.35,81.99,0.457
14.37,82.19,0.442
14.39,82.38,0.430
14.41,82.58,0.420
14.43,82.77,0.411
14.45,82.96,0.402
14.47,83.15,0.397
14.48,83.34,0.391
14.50,83.53,0.387
14.52,83.72,0.384
14.54,83.90,0.381
14.56,84.09,0.378
14.58,84.28,0.376
14.59,84.46,0.375
14.61,84.65,0.374
14.63,84.83,0.372
14.65,85.02,0.371
14.67,85.20,0.371
14.68,85.38,0.370
14.70,85.57,0.370
14.72,85.75,0.369
14.74,85.94,0.369
14.76,86.12,0.369
14.78,86.31,0.369
14.80,86.49,0.368
14.81,86.67,0.368
14.83,86.86,0.368
14.85,87.04,0.368
14.87,87.22,0.368
14.89,87.41,0.368
14.90,87.59,0.367
14.92,87.78,0.367
14.94,87.96,0.367
14.96,88.14,0.367
14.98,88.32,0.367
15.00,88.51,0.367
15.02,88.69,0.367
15.03,88.87,0.367
15.05,89.06,0.367
15.07,89.24,0.367
15.09,89.42,0.367
15.11,89.61,0.367
15.13,89.79,0.367
15.14,89.97,0.367
15.16,90.16,0.367
15.18,90.34,0.367
15.20,90.53,0.367
15.22,90.71,0.367
15.23,90.90,0.368
15.25,91.08,0.368
15.27,91.26,0.368
15.29,91.45,0.368
15.31,91.63,0.368
15.33,91.82,0.368
15.35,92.00,0.368
15.36,92.18,0.368
15.38,92.36,0.368
15.40,92.55,0.368
15.42,92.73,0.368
15.44,92.91,0.368
15.45,93.10,0.368
15.47,93.28,0.368
15.49,93.46,0.368
15.51,93.65,0.368
15.53,93.83,0.368
15.55,94.01,0.368
15.57,94.20,0.369
15.58,94.38,0.369
15.60,94.56,0.369
15.62,94.75,0.369
15.64,94.93,0.369
15.66,95.11,0.369
15.68,95.30,0.369
15.69,95.48,0.369
15.71,95.66,0.369
15.73,95.85,0.369
15.75,96.03,0.369
15.77,96.21,0.370
15.78,96.40,0.370
15.80,96.58,0.370
15.82,96.76,0.370
15.84,96.95,0.370
15.86,97.13,0.370
15.88,97.31,0.370
15.90,97.50,0.371
15.91,97.68,0.371
15.93,97.86,0.371
15.95,98.05,0.371
15.97,98.23,0.371
15.99,98.42,0.371
16.00,98.60,0.371
16.02,98.78,0.371
16.04,98.97,0.372
16.06,99.15,0.372
16.08,99.33,0.372
16.10,99.52,0.372
16.12,99.70,0.372
16.13,99.88,0.372
16.15,100.07,0.372
16.17,100.25,0.373
16.19,100.43,0.373
16.21,100.62,0.373
16.23,100.80,0.373
16.24,100.98,0.373
16.26,101.17,0.373
16.28,101.35,0.373
16.30,101.53,0.374
16.32,101.72,0.374
16.33,101.90,0.374
16.35,102.08,0.374
16.37,102.27,0.374
16.39,102.45,0.374
16.41,102.63,0.374
16.43,102.82,0.375
16.45,103.00,0.375
16.46,103.18,0.375
16.48,103.37,0.375
16.50,103.55,0.375
16.52,103.73,0.375
16.54,103.92,0.375
16.55,104.10,0.376
16.57,104.28,0.376
16.59,104.47,0.376
16.61,104.65,0.376
16.63,104.84,0.376
16.65,105.02,0.376
16.67,105.20,0.376
16.68,105.39,0.377
16.70,105.57,0.377
16.72,105.75,0.377
16.74,105.94,0.377
16.76,106.12,0.377
16.78,106.30,0.377
16.79,106.49,0.377
16.81,106.67,0.378
16.83,106.86,0.378
16.85,107.04,0.378
16.87,107.22,0.378
16.88,107.41,0.378
16.90,107.59,0.378
16.92,107.77,0.378
16.94,107.96,0.378
16.96,108.14,0.378
16.98,108.32,0.379
17.00,108.51,0.379
17.01,108.69,0.379
17.03,108.87,0.379
17.05,109.06,0.379
17.07,109.24,0.379
17.09,109.42,0.379
17.11,109.61,0.380
17.12,109.79,0.380
17.14,109.97,0.380
17.16,110.16,0.380
17.18,110.34,0.380
17.20,110.52,0.380
17.22,110.71,0.380
17.23,110.89,0.380
17.25,111.07,0.381
17.27,111.26,0.381
17.29,111.44,0.381
17.31,111.62,0.381
17.33,111.81,0.381
17.34,111.99,0.381
17.36,112.18,0.382
17.38,112.36,0.382
17.40,112.54,0.382
17.42,112.73,0.382
17.43,112.91,0.382
17.45,113.09,0.382
17.47,113.28,0.383
17.49,113.46,0.383
17.51,113.64,0.383
17.53,113.83,0.383
17.54,114.01,0.383
17.56,114.19,0.383
17.58,114.38,0.383
17.60,114.56,0.384
17.62,114.74,0.384
17.64,114.93,0.384
17.66,115.11,0.384
17.67,115.29,0.384
17.69,115.48,0.384
17.71,115.66,0.385
17.73,115.85,0.385
17.75,116.03,0.385
17.77,116.21,0.385
17.78,116.40,0.385
17.80,116.58,0.385
17.82,116.76,0.385
17.84,116.95,0.386
17.86,117.13,0.386
17.88,117.31,0.386
17.89,117.50,0.386
17.91,117.68,0.386
17.93,117.86,0.386
17.95,118.05,0.386
17.97,118.23,0.386
17.98,118.41,0.387
18.00,118.60,0.387
18.02,118.78,0.387
18.04,118.97,0.387
18.06,119.15,0.387
18.08,119.33,0.387
18.09,119.52,0.388
18.11,119.70,0.388
18.13,119.88,0.388
18.15,120.07,0.388
18.17,120.25,0.388
18.19,120.43,0.388
18.21,120.62,0.388
18.22,120.80,0.389
18.24,120.98,0.389
18.26,121.17,0.389
18.28,121.35,0.389
18.30,121.53,0.389
18.32,121.72,0.390
18.33,121.90,0.390
18.35,122.08,0.390
18.37,122.27,0.390
18.39,122.45,0.390
18.41,122.63,0.391
18.43,122.82,0.391
18.44,123.00,0.391
18.46,123.18,0.391
18.48,123.37,0.392
18.50,123.55,0.392
18.52,123.73,0.392
18.53,123.92,0.392
18.55,124.10,0.393
18.57,124.28,0.393
18.59,124.47,0.393
18.61,124.65,0.393
18.63,124.83,0.394
18.64,125.02,0.394
18.66,125.20,0.394
18.68,125.38,0.395
18.70,125.57,0.395
18.72,125.75,0.395
18.74,125.93,0.395
18.76,126.12,0.396
18.77,126.30,0.396
18.79,126.48,0.397
18.81,126.67,0.397
18.83,126.85,0.397
18.85,127.03,0.398
18.87,127.22,0.398
18.88,127.40,0.398
18.90,127.58,0.399
18.92,127.77,0.399
18.94,127.95,0.399
18.96,128.14,0.400
18.98,128.32,0.400
18.99,128.50,0.400
19.01,128.69,0.401
19.03,128.87,0.401
19.05,129.05,0.401
19.07,129.24,0.402
19.08,129.42,0.402
19.10,129.60,0.402
19.12,129.79,0.403
19.14,129.97,0.403
19.16,130.15,0.404
19.18,130.34,0.404
19.19,130.52,0.404
19.21,130.70,0.405
19.23,130.89,0.405
19.25,131.07,0.405
19.27,131.25,0.406
19.29,131.44,0.406
19.31,131.62,0.406
19.32,131.80,0.407
19.34,131.99,0.407
19.36,132.17,0.408
19.38,132.35,0.408
19.40,132.54,0.408
19.42,132.72,0.409
19.43,132.91,0.409
19.45,133.09,0.409
19.47,133.27,0.410
19.49,133.46,0.410
19.51,133.64,0.410
19.53,133.82,0.411
19.54,134.01,0.411
19.56,134.19,0.411
19.58,134.37,0.412
19.60,134.56,0.412
19.62,134.74,0.412
19.63,134.92,0.413
19.65,135.11,0.413
19.67,135.29,0.414
19.69,135.47,0.414
19.71,135.66,0.415
19.73,135.84,0.415
19.74,136.02,0.415
19.76,136.21,0.416
19.78,136.39,0.416
19.80,136.57,0.417
19.82,136.76,0.417
19.84,136.94,0.417
19.86,137.12,0.418
19.87,137.31,0.418
19.89,137.49,0.419
19.91,137.67,0.419
19.93,137.86,0.420
19.95,138.04,0.420
19.97,138.22,0.421
19.98,138.40,0.421
20.00,138.59,0.422
20.02,138.77,0.423
20.04,138.96,0.423
20.06,139.14,0.424
20.08,139.32,0.424
20.09,139.50,0.425
20.11,139.69,0.426
20.13,139.87,0.426
20.15,140.06,0.427
20.17,140.24,0.427
20.18,140.42,0.428
20.20,140.61,0.429
20.22,140.79,0.429
20.24,140.97,0.430
20.26,141.16,0.431
20.28,141.34,0.431
20.29,141.52,0.432
20.31,141.71,0.432
20.33,141.89,0.434
20.35,142.07,0.435
20.37,142.26,0.436
20.39,142.44,0.437
20.41,142.62,0.437
20.42,142.80,0.438
20.44,142.99,0.439
20.46,143.17,0.440
20.48,143.35,0.441
20.50,143.53,0.442
20.52,143.72,0.443
20.53,143.90,0.445
20.55,144.08,0.446
20.57,144.27,0.447
20.59,144.45,0.449
20.61,144.63,0.450
20.63,144.82,0.452
20.64,145.00,0.453
20.66,145.18,0.454
20.68,145.36,0.456
20.70,145.55,0.457
20.72,145.73,0.458
20.73,145.91,0.459
20.75,146.10,0.461
20.77,146.28,0.462
20.79,146.46,0.464
20.81,146.65,0.466
20.83,146.83,0.467
20.84,147.01,0.469
20.86,147.19,0.470
20.88,147.38,0.471
20.90,147.56,0.472
20.92,147.74,0.474
20.94,147.93,0.475
20.96,148.11,0.477
20.97,148.29,0.479
20.99,148.47,0.481
21.01,148.66,0.483
21.03,148.84,0.484
21.05,149.02,0.486
21.07,149.21,0.489
21.08,149.39,0.491
21.10,149.57,0.492
21.12,149.75,0.495
21.14,149.94,0.497
21.16,150.12,0.499
21.18,150.30,0.501
21.19,150.48,0.504
21.21,150.67,0.506
21.23,150.85,0.509
21.25,151.03,0.512
21.27,151.21,0.515
21.28,151.40,0.517
21.30,151.58,0.521
21.32,151.76,0.523
21.34,151.94,0.527
21.36,152.12,0.531
21.38,152.31,0.534
21.39,152.49,0.539
21.41,152.67,0.543
21.43,152.85,0.548
21.45,153.03,0.553
21.47,153.22,0.558
21.49,153.40,0.564
21.51,153.58,0.568
21.52,153.76,0.574
21.54,153.94,0.580
21.56,154.12,0.587
21.58,154.31,0.593
21.60,154.49,0.601
21.62,154.67,0.610
21.63,154.85,0.616
21.65,155.03,0.626
21.67,155.21,0.635
21.69,155.39,0.646
21.71,155.57,0.657
21.73,155.75,0.669
21.74,155.93,0.682
21.76,156.11,0.695
21.78,156.28,0.709
21.80,156.46,0.728
21.82,156.64,0.746
21.83,156.81,0.767
21.85,156.99,0.792
21.87,157.16,0.823
21.89,157.34,0.861
21.91,157.51,0.904
21.93,157.67,0.959
21.94,157.84,1.030
21.96,158.00,1.105
21.98,158.16,1.183
22.00,158.31,1.269
22.02,158.47,1.345
22.04,158.62,1.407
22.06,158.78,1.459
22.07,158.94,1.490
22.09,159.10,1.498
22.11,159.27,1.492
22.13,159.45,1.469
22.15,159.63,1.426
22.17,159.82,1.375
22.18,160.01,1.328
22.20,160.21,1.265
22.22,160.42,1.176
22.24,160.63,1.083
22.26,160.84,0.993
22.28,161.05,0.910
22.29,161.27,0.834
22.31,161.48,0.768
22.33,161.70,0.702
22.35,161.91,0.650
22.37,162.12,0.597
22.38,162.33,0.563
22.40,162.53,0.534
22.42,162.73,0.512
22.44,162.93,0.496
22.46,163.12,0.482
22.48,163.32,0.472
22.49,163.51,0.462
22.51,163.70,0.455
22.53,163.89,0.450
22.55,164.08,0.444
22.57,164.26,0.440
22.59,164.45,0.437
22.61,164.64,0.433
22.62,164.82,0.432
22.64,165.01,0.429
22.66,165.19,0.428
22.68,165.38,0.427
22.70,165.56,0.426
22.72,165.75,0.426
22.73,165.93,0.425
22.75,166.11,0.425
22.77,166.30,0.425
22.79,166.48,0.425
22.81,166.67,0.424
22.83,166.85,0.424
22.84,167.03,0.424
22.86,167.22,0.424
22.88,167.40,0.424
22.90,167.58,0.424
22.92,167.77,0.424
22.93,167.95,0.424
22.95,168.13,0.424
22.97,168.32,0.424
22.99,168.50,0.424
23.01,168.68,0.424
23.03,168.87,0.424
23.04,169.05,0.424
23.06,169.24,0.424
23.08,169.42,0.424
23.10,169.60,0.424
23.12,169.78,0.424
23.14,169.97,0.424
23.16,170.15,0.424
23.17,170.33,0.424
23.19,170.52,0.424
23.21,170.70,0.424
23.23,170.89,0.424
23.25,171.07,0.424
23.27,171.25,0.425
23.28,171.44,0.425
23.30,171.62,0.425
23.32,171.80,0.425
23.34,171.99,0.425
23.36,172.17,0.425
23.38,172.35,0.425
23.39,172.54,0.426
23.41,172.72,0.426
23.43,172.90,0.426
23.45,173.09,0.426
23.47,173.27,0.426
23.48,173.45,0.426
23.50,173.64,0.426
23.52,173.82,0.426
23.54,174.01,0.427
23.56,174.19,0.427
23.58,174.37,0.427
23.59,174.55,0.427
23.61,174.74,0.427
23.63,174.92,0.427
23.65,175.11,0.427
23.67,175.29,0.428
23.69,175.47,0.428
23.71,175.66,0.428
23.72,175.84,0.428
23.74,176.02,0.428
23.76,176.21,0.428
23.78,176.39,0.428
23.80,176.57,0.428
23.82,176.75,0.429
23.83,176.94,0.429
23.85,177.12,0.429
23.87,177.30,0.429
23.89,177.49,0.429
23.91,177.67,0.429
23.93,177.86,0.430
23.94,178.04,0.430
23.96,178.22,0.430
23.98,178.41,0.430
24.00,178.59,0.430
24.02,178.77,0.430
24.03,178.96,0.431
24.05,179.14,0.431
24.07,179.32,0.431
24.09,179.51,0.431
24.11,179.69,0.431
24.13,179.87,0.431
24.14,180.06,0.432
24.16,180.24,0.432
24.18,180.42,0.432
24.20,180.61,0.432
24.22,180.79,0.432
24.24,180.97,0.432
24.26,181.16,0.432
24.27,181.34,0.432
24.29,181.52,0.433
24.31,181.71,0.433
24.33,181.89,0.433
24.35,182.07,0.433
24.37,182.26,0.434
24.38,182.44,0.434
24.40,182.63,0.434
24.42,182.81,0.434
24.44,182.99,0.434
24.46,183.18,0.434
24.48,183.36,0.434
24.49,183.54,0.435
24.51,183.73,0.435
24.53,183.91,0.435
24.55,184.09,0.435
24.57,184.28,0.435
24.58,184.46,0.435
24.60,184.64,0.435
24.62,184.83,0.435
24.64,185.01,0.435
24.66,185.19,0.436
24.68,185.38,0.436
24.69,185.56,0.436
24.71,185.74,0.436
24.73,185.93,0.436
24.75,186.11,0.436
24.77,186.29,0.436
24.79,186.48,0.437
24.81,186.66,0.437
24.82,186.84,0.437
24.84,187.03,0.437
24.86,187.21,0.437
24.88,187.39,0.437
24.90,187.58,0.437
24.92,187.76,0.437
24.93,187.94,0.438
24.95,188.13,0.438
24.97,188.31,0.438
24.99,188.49,0.438
25.01,188.68,0.438
25.03,188.86,0.438
25.04,189.04,0.438
25.06,189.23,0.439
25.08,189.41,0.439
25.10,189.60,0.439
25.12,189.78,0.439
25.13,189.96,0.439
25.15,190.15,0.439
25.17,190.33,0.440
25.19,190.51,0.440
25.21,190.70,0.440
25.23,190.88,0.440
25.24,191.06,0.440
25.26,191.25,0.440
25.28,191.43,0.440
25.30,191.61,0.440
25.32,191.80,0.441
25.34,191.98,0.441
25.36,192.16,0.441
25.37,192.35,0.441
25.39,192.53,0.441
25.41,192.71,0.441
25.43,192.90,0.441
25.45,193.08,0.442
25.47,193.26,0.442
25.48,193.45,0.442
25.50,193.63,0.442
25.52,193.81,0.442
25.54,194.00,0.442
25.56,194.18,0.443
25.58,194.36,0.443
25.59,194.55,0.443
25.61,194.73,0.443
25.63,194.92,0.443
25.65,195.10,0.444
25.67,195.28,0.444
25.68,195.47,0.444
25.70,195.65,0.444
25.72,195.83,0.444
25.74,196.02,0.444
25.76,196.20,0.444
25.78,196.38,0.444
25.79,196.57,0.444
25.81,196.75,0.445
25.83,196.93,0.445
25.85,197.12,0.445
25.87,197.30,0.445
25.89,197.48,0.445
25.91,197.67,0.445
25.92,197.85,0.446
25.94,198.03,
25.96,198.22,
25.98,198.40,
25.99,,

[step]
Ramp 10.00 °C/min to -60.00 °C
Time,Temperature,Heat Flow (Normalized)
min,°C,W/g
27.99,200.10,-0.018
28.01,200.10,-0.018
28.03,200.10,-0.018
28.05,200.09,-0.022
28.07,200.07,-0.045
28.08,200.03,-0.075
28.10,199.97,-0.116
28.12,199.90,-0.164
28.14,199.80,-0.211
28.16,199.68,-0.255
28.18,199.56,-0.295
28.19,199.42,-0.327
28.21,199.28,-0.354
28.23,199.12,-0.376
28.25,198.97,-0.393
28.27,198.81,-0.408
28.29,198.64,-0.419
28.31,198.48,-0.429
28.32,198.31,-0.438
28.34,198.14,-0.446
28.36,197.97,-0.450
28.38,197.79,-0.457
28.40,197.62,-0.462
28.42,197.44,-0.465
28.43,197.26,-0.468
28.45,197.08,-0.470
28.47,196.91,-0.473
28.49,196.73,-0.475
28.51,196.55,-0.476
28.53,196.37,-0.477
28.54,196.19,-0.478
28.56,196.01,-0.479
28.58,195.83,-0.479
28.60,195.65,-0.480
28.62,195.47,-0.481
28.63,195.29,-0.481
28.65,195.11,-0.481
28.67,194.93,-0.482
28.69,194.75,-0.482
28.71,194.56,-0.483
28.73,194.38,-0.483
28.74,194.20,-0.483
28.76,194.02,-0.483
28.78,193.84,-0.484
28.80,193.66,-0.484
28.82,193.47,-0.484
28.84,193.29,-0.484
28.86,193.11,-0.484
28.87,192.93,-0.484
28.89,192.75,-0.485
28.91,192.56,-0.485
28.93,192.38,-0.485
28.95,192.20,-0.485
28.97,192.02,-0.485
28.98,191.83,-0.485
29.00,191.65,-0.486
29.02,191.47,-0.486
29.04,191.29,-0.486
29.06,191.11,-0.486
29.08,190.93,-0.486
29.09,190.74,-0.486
29.11,190.56,-0.486
29.13,190.38,-0.486
29.15,190.20,-0.486
29.17,190.01,-0.486
29.18,189.83,-0.486
29.20,189.65,-0.487
29.22,189.46,-0.487
29.24,189.28,-0.487
29.26,189.10,-0.487
29.28,188.92,-0.487
29.29,188.73,-0.487
29.31,188.55,-0.487
29.33,188.37,-0.487
29.35,188.18,-0.487
29.37,188.00,-0.487
29.39,187.82,-0.487
29.41,187.64,-0.487
29.42,187.45,-0.487
29.44,187.27,-0.487
29.46,187.09,-0.487
29.48,186.91,-0.487
29.50,186.72,-0.487
29.52,186.54,-0.487
29.53,186.36,-0.487
29.55,186.17,-0.487
29.57,185.99,-0.487
29.59,185.81,-0.487
29.61,185.62,-0.487
29.63,185.44,-0.486
29.64,185.26,-0.486
29.66,185.08,-0.486
29.68,184.89,-0.486
29.70,184.71,-0.486
29.72,184.53,-0.486
29.73,184.34,-0.486
29.75,184.16,-0.486
29.77,183.98,-0.486
29.79,183.80,-0.486
29.81,183.61,-0.486
29.83,183.43,-0.486
29.84,183.25,-0.486
29.86,183.06,-0.486
29.88,182.88,-0.486
29.90,182.70,-0.485
29.92,182.51,-0.485
29.94,182.33,-0.485
29.96,182.15,-0.485
29.97,181.96,-0.485
29.99,181.78,-0.485
30.01,181.60,-0.485
30.03,181.42,-0.485
30.05,181.23,-0.485
30.07,181.05,-0.485
30.08,180.87,-0.485
30.10,180.68,-0.485
30.12,180.50,-0.485
30.14,180.32,-0.485
30.16,180.13,-0.485
30.18,179.95,-0.484
30.19,179.77,-0.484
30.21,179.58,-0.484
30.23,179.40,-0.484
30.25,179.22,-0.484
30.27,179.04,-0.484
30.28,178.85,-0.484
30.30,178.67,-0.484
30.32,178.49,-0.484
30.34,178.30,-0.484
30.36,178.12,-0.484
30.38,177.94,-0.484
30.39,177.75,-0.483
30.41,177.57,-0.483
30.43,177.39,-0.483
30.45,177.21,-0.483
30.47,177.02,-0.483
30.49,176.84,-0.483
30.51,176.66,-0.483
30.52,176.47,-0.483
30.54,176.29,-0.483
30.56,176.11,-0.483
30.58,175.92,-0.483
30.60,175.74,-0.483
30.62,175.56,-0.483
30.63,175.37,-0.483
30.65,175.19,-0.483
30.67,175.01,-0.482
30.69,174.83,-0.482
30.71,174.64,-0.482
30.73,174.46,-0.482
30.74,174.28,-0.482
30.76,174.09,-0.482
30.78,173.91,-0.482
30.80,173.73,-0.482
30.82,173.54,-0.482
30.83,173.36,-0.482
30.85,173.18,-0.482
30.87,172.99,-0.482
30.89,172.81,-0.482
30.91,172.63,-0.481
30.93,172.44,-0.481
30.94,172.26,-0.481
30.96,172.08,-0.481
30.98,171.89,-0.481
31.00,171.71,-0.481
31.02,171.53,-0.481
31.04,171.35,-0.481
31.06,171.16,-0.481
31.07,170.98,-0.481
31.09,170.80,-0.481
31.11,170.61,-0.481
31.13,170.43,-0.481
31.15,170.25,-0.480
31.17,170.06,-0.480
31.18,169.88,-0.480
31.20,169.70,-0.480
31.22,169.51,-0.480
31.24,169.33,-0.480
31.26,169.15,-0.480
31.28,168.96,-0.480
31.29,168.78,-0.480
31.31,168.60,-0.480
31.33,168.41,-0.480
31.35,168.23,-0.479
31.37,168.05,-0.479
31.38,167.87,-0.479
31.40,167.68,-0.479
31.42,167.50,-0.479
31.44,167.32,-0.479
31.46,167.13,-0.479
31.48,166.95,-0.479
31.49,166.77,-0.479
31.51,166.58,-0.479
31.53,166.40,-0.479
31.55,166.22,-0.479
31.57,166.03,-0.479
31.59,165.85,-0.479
31.61,165.67,-0.479
31.62,165.48,-0.479
31.64,165.30,-0.478
31.66,165.12,-0.478
31.68,164.94,-0.478
31.70,164.75,-0.478
31.72,164.57,-0.478
31.73,164.39,-0.478
31.75,164.20,-0.478
31.77,164.02,-0.478
31.79,163.84,-0.478
31.81,163.65,-0.478
31.83,163.47,-0.478
31.84,163.29,-0.478
31.86,163.11,-0.478
31.88,162.92,-0.477
31.90,162.74,-0.477
31.92,162.56,-0.477
31.93,162.37,-0.477
31.95,162.19,-0.477
31.97,162.01,-0.477
31.99,161.82,-0.477
32.01,161.64,-0.477
32.03,161.46,-0.477
32.04,161.28,-0.477
32.06,161.09,-0.477
32.08,160.91,-0.477
32.10,160.73,-0.477
32.12,160.54,-0.476
32.14,160.36,-0.476
32.16,160.18,-0.476
32.17,159.99,-0.476
32.19,159.81,-0.476
32.21,159.63,-0.476
32.23,159.44,-0.476
32.25,159.26,-0.476
32.27,159.08,-0.476
32.28,158.89,-0.476
32.30,158.71,-0.476
32.32,158.53,-0.476
32.34,158.34,-0.476
32.36,158.16,-0.476
32.38,157.98,-0.476
32.39,157.79,-0.476
32.41,157.61,-0.476
32.43,157.43,-0.475
32.45,157.24,-0.475
32.47,157.06,-0.475
32.48,156.88,-0.475
32.50,156.70,-0.475
32.52,156.51,-0.475
32.54,156.33,-0.475
32.56,156.15,-0.475
32.58,155.96,-0.475
32.59,155.78,-0.475
32.61,155.60,-0.474
32.63,155.42,-0.474
32.65,155.23,-0.474
32.67,155.05,-0.474
32.69,154.87,-0.474
32.71,154.68,-0.474
32.72,154.50,-0.474
32.74,154.32,-0.474
32.76,154.13,-0.474
32.78,153.95,-0.474
32.80,153.77,-0.474
32.82,153.58,-0.474
32.83,153.40,-0.474
32.85,153.22,-0.474
32.87,153.03,-0.474
32.89,152.85,-0.474
32.91,152.67,-0.473
32.93,152.48,-0.473
32.94,152.30,-0.473
32.96,152.12,-0.473
32.98,151.94,-0.473
33.00,151.75,-0.473
33.02,151.57,-0.473
33.03,151.39,-0.473
33.05,151.20,-0.473
33.07,151.02,-0.473
33.09,150.84,-0.473
33.11,150.65,-0.473
33.13,150.47,-0.472
33.14,150.29,-0.472
33.16,150.10,-0.472
33.18,149.92,-0.472
33.20,149.74,-0.472
33.22,149.55,-0.472
33.24,149.37,-0.472
33.26,149.19,-0.472
33.27,149.01,-0.472
33.29,148.82,-0.472
33.31,148.64,-0.472
33.33,148.46,-0.472
33.35,148.27,-0.472
33.37,148.09,-0.472
33.38,147.90,-0.472
33.40,147.72,-0.472
33.42,147.54,-0.472
33.44,147.36,-0.472
33.46,147.17,-0.471
33.48,146.99,-0.471
33.49,146.81,-0.471
33.51,146.62,-0.471
33.53,146.44,-0.471
33.55,146.26,-0.471
33.57,146.07,-0.471
33.58,145.89,-0.471
33.60,145.71,-0.471
[...]
185.08,-40.93,0.216
185.08,-40.86,0.216
185.09,-40.79,0.216
185.10,-40.73,0.216
185.10,-40.66,0.216
185.11,-40.59,0.216
185.12,-40.53,0.216
185.12,-40.46,0.216
185.13,-40.39,0.216
185.13,-40.33,0.216
185.14,-40.26,0.216
185.15,-40.19,0.216
185.15,-40.13,0.216
185.16,-40.06,0.217
185.17,-39.99,0.217
185.18,-39.92,0.217
185.18,-39.86,0.217
185.19,-39.79,0.217
185.20,-39.73,0.217
185.20,-39.66,0.217
185.21,-39.59,0.217
185.22,-39.53,0.217
185.22,-39.46,0.217
185.23,-39.39,0.217
185.23,-39.33,0.217
185.24,-39.26,0.217
185.25,-39.19,0.217
185.25,-39.12,0.217
185.26,-39.06,0.217
185.27,-38.99,0.217
185.28,-38.92,0.217
185.28,-38.86,0.217
185.29,-38.79,0.217
185.30,-38.72,0.217
185.30,-38.66,0.217
185.31,-38.59,0.217
185.32,-38.52,0.217
185.32,-38.46,0.217
185.33,-38.39,0.218
185.33,-38.32,0.218
185.34,-38.26,0.218
185.35,-38.19,0.218
185.35,-38.12,0.218
185.36,-38.06,0.218
185.37,-37.99,0.218
185.38,-37.92,0.218
185.38,-37.86,0.218
185.39,-37.79,0.218
185.40,-37.72,0.218
185.40,-37.66,0.218
185.41,-37.59,0.218
185.42,-37.52,0.218
185.42,-37.46,0.218
185.43,-37.39,0.218
185.43,-37.32,0.218
185.44,-37.25,0.218
185.45,-37.19,0.218
185.45,-37.12,0.218
185.46,-37.05,0.218
185.47,-36.99,0.219
185.48,-36.92,0.219
185.48,-36.86,0.219
185.49,-36.79,0.219
185.50,-36.72,0.219
185.50,-36.66,0.219
185.51,-36.59,0.219
185.52,-36.52,0.219
185.52,-36.45,0.219
185.53,-36.39,0.219
185.53,-36.32,0.219
185.54,-36.25,0.219
185.55,-36.19,0.219
185.55,-36.12,0.219
185.56,-36.05,0.219
185.57,-35.99,0.219
185.58,-35.92,0.219
185.58,-35.86,0.219
185.59,-35.79,0.219
185.60,-35.72,0.219
185.60,-35.65,0.219
185.61,-35.59,0.219
185.62,-35.52,0.219
185.62,-35.45,0.219
185.63,-35.39,0.219
185.63,-35.32,0.219
185.64,-35.25,0.219
185.65,-35.19,0.219
185.65,-35.12,0.220
185.66,-35.05,0.220
185.67,-34.99,0.220
185.68,-34.92,0.220
185.68,-34.85,0.220
185.69,-34.79,0.220
185.70,-34.72,0.220
185.70,-34.65,0.220
185.71,-34.59,0.220
185.72,-34.52,0.220
185.72,-34.45,0.220
185.73,-34.39,0.220
185.73,-34.32,0.220
185.74,-34.25,0.220
185.75,-34.19,0.220
185.75,-34.12,0.220
185.76,-34.05,0.220
185.77,-33.99,0.220
185.78,-33.92,0.220
185.78,-33.85,0.220
185.79,-33.79,0.220
185.80,-33.72,0.220
185.80,-33.65,0.221
185.81,-33.58,0.221
185.82,-33.52,0.221
185.82,-33.45,0.221
185.83,-33.39,0.221
185.83,-33.32,0.221
185.84,-33.25,0.221
185.85,-33.18,0.221
185.85,-33.12,0.221
185.86,-33.05,0.221
185.87,-32.98,0.221
185.88,-32.92,0.221
185.88,-32.85,0.221
185.89,-32.79,0.221
185.90,-32.72,0.221
185.90,-32.65,0.221
185.91,-32.58,0.221
185.92,-32.52,0.221
185.92,-32.45,0.221
185.93,-32.38,0.221
185.93,-32.32,0.221
185.94,-32.25,0.221
185.95,-32.18,0.221
185.95,-32.12,0.221
185.96,-32.05,0.222
185.97,-31.98,0.222
185.98,-31.91,0.222
185.98,-31.85,0.222
185.99,-31.78,0.222
186.00,-31.72,0.222
186.00,-31.65,0.222
186.01,-31.58,0.222
186.02,-31.51,0.222
186.02,-31.45,0.222
186.03,-31.38,0.222
186.03,-31.32,0.222
186.04,-31.25,0.222
186.05,-31.18,0.222
186.05,-31.12,0.222
186.06,-31.05,0.222
186.07,-30.98,0.222
186.08,-30.91,0.222
186.08,-30.85,0.222
186.09,-30.78,0.222
186.10,-30.72,0.222
186.10,-30.65,0.222
186.11,-30.58,0.222
186.12,-30.51,0.222
186.12,-30.45,0.223
186.13,-30.38,0.223
186.13,-30.31,0.223
186.14,-30.24,0.223
186.15,-30.18,0.223
186.15,-30.11,0.223
186.16,-30.05,0.223
186.17,-29.98,0.223
186.18,-29.91,0.223
186.18,-29.85,0.223
186.19,-29.78,0.223
186.20,-29.71,0.223
186.20,-29.64,0.223
186.21,-29.58,0.223
186.22,-29.51,0.223
186.22,-29.44,0.223
186.23,-29.38,0.223
186.23,-29.31,0.223
186.24,-29.24,0.223
186.25,-29.18,0.223
186.25,-29.11,0.223
186.26,-29.04,0.224
186.27,-28.98,0.224
186.28,-28.91,0.224
186.28,-28.84,0.224
186.29,-28.78,0.224
186.30,-28.71,0.224
186.30,-28.64,0.224
186.31,-28.57,0.224
186.32,-28.51,0.224
186.32,-28.44,0.224
186.33,-28.38,0.224
186.33,-28.31,0.224
186.34,-28.24,0.224
186.35,-28.18,0.224
186.35,-28.11,0.224
186.36,-28.04,0.224
186.37,-27.98,0.225
186.38,-27.91,0.225
186.38,-27.84,0.225
186.39,-27.78,0.225
186.40,-27.71,0.225
186.40,-27.64,0.225
186.41,-27.58,0.225
186.42,-27.51,0.225
186.42,-27.44,0.225
186.43,-27.38,0.225
186.43,-27.31,0.225
186.44,-27.24,0.225
186.45,-27.18,0.225
186.45,-27.11,0.225
186.46,-27.04,0.225
186.47,-26.97,0.225
186.48,-26.91,0.225
186.48,-26.84,0.225
186.49,-26.77,0.225
186.50,-26.71,0.225
186.50,-26.64,0.225
186.51,-26.57,0.225
186.52,-26.51,0.225
186.52,-26.44,0.225
186.53,-26.37,0.225
186.53,-26.31,0.226
186.54,-26.24,0.226
186.55,-26.17,0.226
186.55,-26.11,0.226
186.56,-26.04,0.226
186.57,-25.97,0.226
186.58,-25.91,0.226
186.58,-25.84,0.226
186.59,-25.77,0.226
186.60,-25.71,0.226
186.60,-25.64,0.226
186.61,-25.57,0.226
186.62,-25.51,0.226
186.62,-25.44,0.226
186.63,-25.37,0.226
186.63,-25.31,0.226
186.64,-25.24,0.226
186.65,-25.17,0.226
186.65,-25.11,0.226
186.66,-25.04,0.226
186.67,-24.97,0.226
186.68,-24.90,0.226
186.68,-24.84,0.226
186.69,-24.77,0.227
186.70,-24.70,0.227
186.70,-24.64,0.227
186.71,-24.57,0.227
186.72,-24.50,0.227
186.72,-24.44,0.227
186.73,-24.37,0.227
186.73,-24.30,0.227
186.74,-24.24,0.227
186.75,-24.17,0.227
186.75,-24.10,0.227
186.76,-24.04,0.227
186.77,-23.97,0.227
186.78,-23.90,0.227
186.78,-23.84,0.227
186.79,-23.77,0.227
186.80,-23.70,0.227
186.80,-23.64,0.227
186.81,-23.57,0.227
186.82,-23.50,0.227
186.82,-23.44,0.227
186.83,-23.37,0.227
186.83,-23.30,0.228
186.84,-23.24,0.228
186.85,-23.17,0.228
186.85,-23.10,0.228
186.86,-23.04,0.228
186.87,-22.97,0.228
186.88,-22.90,0.228
186.88,-22.84,0.228
186.89,-22.77,0.228
186.90,-22.70,0.228
186.90,-22.63,0.228
186.91,-22.57,0.228
186.92,-22.50,0.228
186.92,-22.44,0.228
186.93,-22.37,0.228
186.93,-22.30,0.228
186.94,-22.24,0.228
186.95,-22.17,0.228
186.95,-22.10,0.228
186.96,-22.04,0.228
186.97,-21.97,0.228
186.98,-21.90,0.229
186.98,-21.83,0.229
186.99,-21.77,0.229
187.00,-21.70,0.229
187.00,-21.63,0.229
187.01,-21.57,0.229
187.02,-21.50,0.229
187.02,-21.43,0.229
187.03,-21.37,0.229
187.03,-21.30,0.229
187.04,-21.24,0.229
187.05,-21.17,0.229
187.05,-21.10,0.229
187.06,-21.03,0.229
187.07,-20.97,0.229
187.08,-20.90,0.229
187.08,-20.83,0.229
187.09,-20.77,0.229
187.10,-20.70,0.229
187.10,-20.63,0.229
187.11,-20.57,0.229
187.12,-20.50,0.230
187.12,-20.43,0.230
187.13,-20.37,0.230
187.13,-20.30,0.230
187.14,-20.23,0.230
187.15,-20.17,0.230
187.15,-20.10,0.230
187.16,-20.03,0.230
187.17,-19.97,0.230
187.18,-19.90,0.230
187.18,-19.83,0.230
187.19,-19.77,0.230
187.20,-19.70,0.230
187.20,-19.63,0.230
187.21,-19.57,0.230
187.22,-19.50,0.230
187.22,-19.43,0.230
187.23,-19.37,0.230
187.23,-19.30,0.230
187.24,-19.23,0.230
187.25,-19.17,0.230
187.25,-19.10,0.231
187.26,-19.03,0.231
187.27,-18.97,0.231
187.28,-18.90,0.231
187.28,-18.83,0.231
187.29,-18.77,0.231
187.30,-18.70,0.231
187.30,-18.63,0.231
187.31,-18.56,0.231
187.32,-18.50,0.231
187.32,-18.43,0.231
187.33,-18.37,0.231
187.33,-18.30,0.231
187.34,-18.23,0.231
187.35,-18.17,0.231
187.35,-18.10,0.231
187.36,-18.03,0.231
187.37,-17.97,0.231
187.38,-17.90,0.231
187.38,-17.83,0.231
187.39,-17.77,0.231
187.40,-17.70,0.231
187.40,-17.63,0.232
187.41,-17.57,0.232
187.42,-17.50,0.232
187.42,-17.43,0.232
187.43,-17.36,0.232
187.43,-17.30,0.232
187.44,-17.23,0.232
187.45,-17.16,0.232
187.45,-17.10,0.232
187.46,-17.03,0.232
187.47,-16.97,0.232
187.48,-16.90,0.232
187.48,-16.83,0.232
187.49,-16.76,0.232
187.50,-16.70,0.233
187.50,-16.63,0.233
187.51,-16.56,0.233
187.52,-16.50,0.233
187.52,-16.43,0.233
187.53,-16.36,0.233
187.53,-16.30,0.233
187.54,-16.23,0.233
187.55,-16.16,0.233
187.55,-16.09,0.233
187.56,-16.03,0.233
187.57,-15.96,0.233
187.58,-15.89,0.233
187.58,-15.83,0.233
187.59,-15.76,0.233
187.60,-15.69,0.233
187.60,-15.63,0.233
187.61,-15.56,0.233
187.62,-15.49,0.233
187.62,-15.43,0.234
187.63,-15.36,0.234
187.63,-15.29,0.234
187.64,-15.23,0.234
187.65,-15.16,0.234
187.65,-15.09,0.234
187.66,-15.03,0.234
187.67,-14.96,0.234
187.68,-14.89,0.234
187.68,-14.83,0.234
187.69,-14.76,0.234
187.70,-14.69,0.234
187.70,-14.63,0.234
187.71,-14.56,0.234
187.72,-14.49,0.234
187.72,-14.43,0.234
187.73,-14.36,0.235
187.73,-14.29,0.235
187.74,-14.22,0.235
187.75,-14.16,0.235
187.75,-14.09,0.235
187.76,-14.03,0.235
187.77,-13.96,0.235
187.78,-13.89,0.235
187.78,-13.83,0.235
187.79,-13.76,0.235
187.80,-13.69,0.235
187.80,-13.62,0.235
187.81,-13.56,0.235
187.82,-13.49,0.235
187.82,-13.43,0.235
187.83,-13.36,0.235
187.83,-13.29,0.235
187.84,-13.22,0.235
187.85,-13.16,0.236
187.85,-13.09,0.236
187.86,-13.03,0.236
187.87,-12.96,0.236
187.88,-12.89,0.236
187.88,-12.82,0.236
187.89,-12.76,0.236
187.90,-12.69,0.236
187.90,-12.63,0.236
187.91,-12.56,0.236
187.92,-12.49,0.236
187.92,-12.42,0.236
187.93,-12.36,0.236
187.93,-12.29,0.236
187.94,-12.22,0.236
187.95,-12.16,0.236
187.95,-12.09,0.236
187.96,-12.02,0.237
187.97,-11.96,0.237
187.98,-11.89,0.237
187.98,-11.82,0.237
187.99,-11.76,0.237
188.00,-11.69,0.237
188.00,-11.62,0.237
188.01,-11.56,0.237
188.02,-11.49,0.237
188.02,-11.42,0.237
188.03,-11.36,0.237
188.03,-11.29,0.237
188.04,-11.23,0.237
188.05,-11.16,0.237
188.05,-11.09,0.237
188.06,-11.02,0.237
188.07,-10.96,0.238
188.08,-10.89,0.238
188.08,-10.82,0.238
188.09,-10.76,0.238
188.10,-10.69,0.238
188.10,-10.62,0.238
188.11,-10.56,0.238
188.12,-10.49,0.238
188.12,-10.42,0.238
188.13,-10.36,0.238
188.13,-10.29,0.238
188.14,-10.22,0.239
188.15,-10.16,0.239
188.15,-10.09,0.239
188.16,-10.02,0.239
188.17,-9.96,0.239
188.18,-9.89,0.239
188.18,-9.82,0.239
188.19,-9.76,0.239
188.20,-9.69,0.239
188.20,-9.62,0.239
188.21,-9.56,0.239
188.22,-9.49,0.239
188.22,-9.42,0.240
188.23,-9.36,0.240
188.23,-9.29,0.240
188.24,-9.22,0.240
188.25,-9.16,0.240
188.25,-9.09,0.240
188.26,-9.02,0.240
188.27,-8.96,0.240
188.28,-8.89,0.240
188.28,-8.82,0.240
188.29,-8.76,0.240
188.30,-8.69,0.241
188.30,-8.62,0.241
188.31,-8.56,0.241
188.32,-8.49,0.241
188.32,-8.42,0.241
188.33,-8.36,0.241
188.33,-8.29,0.241
188.34,-8.22,0.241
188.35,-8.16,0.241
188.35,-8.09,0.241
188.36,-8.02,0.241
188.37,-7.96,0.241
188.38,-7.89,0.242
188.38,-7.82,0.242
188.39,-7.76,0.242
188.40,-7.69,0.242
188.40,-7.62,0.242
188.41,-7.55,0.242
188.42,-7.49,0.242
188.42,-7.42,0.242
188.43,-7.35,0.242
188.43,-7.29,0.243
188.44,-7.22,0.243
188.45,-7.16,0.243
188.45,-7.09,0.243
188.46,-7.02,0.243
188.47,-6.95,0.243
188.48,-6.89,0.243
188.48,-6.82,0.244
188.49,-6.75,0.244
188.50,-6.69,0.244
188.50,-6.62,0.244
188.51,-6.56,0.244
188.52,-6.49,0.244
188.52,-6.42,0.244
188.53,-6.36,0.244
188.53,-6.29,0.245
188.54,-6.22,0.245
188.55,-6.15,0.245
188.55,-6.09,0.245
188.56,-6.02,0.245
188.57,-5.95,0.245
188.58,-5.89,0.245
188.58,-5.82,0.246
188.59,-5.75,0.246
188.60,-5.69,0.246
188.60,-5.62,0.246
188.61,-5.55,0.246
188.62,-5.49,0.246
188.62,-5.42,0.246
188.63,-5.35,0.246
188.63,-5.29,0.247
188.64,-5.22,0.247
188.65,-5.15,0.247
188.65,-5.09,0.247
188.66,-5.02,0.248
188.67,-4.95,0.248
188.68,-4.89,0.248
188.68,-4.82,0.248
188.69,-4.75,0.248
188.70,-4.69,0.248
188.70,-4.62,0.248
188.71,-4.55,0.248
188.72,-4.49,0.249
188.72,-4.42,0.249
188.73,-4.35,0.249
188.73,-4.29,0.249
188.74,-4.22,0.249
188.75,-4.15,0.250
188.75,-4.09,0.250
188.76,-4.02,0.250
188.77,-3.95,0.250
188.78,-3.89,0.251
188.78,-3.82,0.251
188.79,-3.75,0.252
188.80,-3.69,0.252
188.80,-3.62,0.252
188.81,-3.55,0.252
188.82,-3.49,0.252
188.82,-3.42,0.252
188.83,-3.35,0.253
188.83,-3.29,0.253
188.84,-3.22,0.254
188.85,-3.15,0.254
188.85,-3.09,0.254
188.86,-3.02,0.254
188.87,-2.95,0.255
188.88,-2.89,0.255
188.88,-2.82,0.255
188.89,-2.76,0.255
188.90,-2.69,0.256
188.90,-2.62,0.256
188.91,-2.55,0.256
188.92,-2.49,0.256
188.92,-2.42,0.257
188.93,-2.36,0.257
188.93,-2.29,0.257
188.94,-2.22,0.258
188.95,-2.15,0.259
188.95,-2.09,0.260
188.96,-2.02,0.260
188.97,-1.95,0.260
188.98,-1.89,0.261
188.98,-1.82,0.261
188.99,-1.75,0.262
189.00,-1.69,0.263
189.00,-1.62,0.263
189.01,-1.56,0.263
189.02,-1.49,0.264
189.02,-1.42,0.264
189.03,-1.36,0.265
189.03,-1.29,0.265
189.04,-1.22,0.265
189.05,-1.16,0.266
189.05,-1.09,0.267
189.06,-1.02,0.267
189.07,-0.96,0.268
189.08,-0.89,0.268
189.08,-0.82,0.269
189.09,-0.76,0.269
189.10,-0.69,0.270
189.10,-0.62,0.271
189.11,-0.56,0.271
189.12,-0.49,0.272
189.12,-0.43,0.272
189.13,-0.36,0.273
189.13,-0.29,0.274
189.14,-0.23,0.275
189.15,-0.16,0.276
189.15,-0.09,0.276
189.16,-0.03,0.277
189.17,0.04,0.277
189.18,0.11,0.278
189.18,0.17,0.279
189.19,0.24,0.279
189.20,0.31,0.280
189.20,0.37,0.281
189.21,0.44,0.282
189.22,0.51,0.282
189.22,0.57,0.283
189.23,0.64,0.284
189.23,0.70,0.285
189.24,0.77,0.286
189.25,0.84,0.287
189.25,0.90,0.288
189.26,0.97,0.289
189.27,1.04,0.289
189.28,1.10,0.290
189.28,1.17,0.291
189.29,1.24,0.292
189.30,1.30,0.293
189.30,1.37,0.293
189.31,1.43,0.294
189.32,1.50,0.295
189.32,1.57,0.296
189.33,1.63,0.297
189.33,1.70,0.298
189.34,1.77,0.299
189.35,1.83,0.300
189.35,1.90,0.300
189.36,1.96,0.301
189.37,2.03,0.302
189.38,2.10,0.303
189.38,2.16,0.303
189.39,2.23,0.305
189.40,2.30,0.306
189.40,2.36,0.307
189.41,2.43,0.308
189.42,2.50,0.308
189.42,2.56,0.309
189.43,2.63,0.311
189.43,2.69,0.311
189.44,2.76,0.312
189.45,2.83,0.312
189.45,2.89,0.313
189.46,2.96,0.314
189.47,3.03,0.315
189.48,3.09,0.315
189.48,3.16,0.316
189.49,3.23,0.317
189.50,3.29,0.318
189.50,3.36,0.318
189.51,3.42,0.319
189.52,3.49,0.320
189.52,3.56,0.320
189.53,3.62,0.321
189.53,3.69,0.321
189.54,3.75,0.321
189.55,3.82,0.322
189.55,3.89,0.322
189.56,3.96,0.322
189.57,4.02,0.323
189.58,4.09,0.323
189.58,4.15,0.323
189.59,4.22,0.323
189.60,4.29,0.324
189.60,4.35,0.324
189.61,4.42,0.324
189.62,4.49,0.324
189.62,4.55,0.324
189.63,4.62,0.324
189.63,4.69,0.325
189.64,4.75,0.325
189.65,4.82,0.325
189.65,4.89,0.325
189.66,4.95,0.325
189.67,5.02,0.325
189.68,5.09,0.325
189.68,5.15,0.325
189.69,5.22,0.325
189.70,5.29,0.325
189.70,5.35,0.325
189.71,5.42,0.325
189.72,5.49,0.325
189.72,5.55,0.325
189.73,5.62,0.325
189.73,5.69,0.325
189.74,5.76,0.325
189.75,5.82,0.325
189.75,5.89,0.325
189.76,5.96,0.324
189.77,6.02,0.324
189.78,6.09,0.324
189.78,6.16,0.324
189.79,6.22,0.324
189.80,6.29,0.324
189.80,6.36,0.323
189.81,6.42,0.323
189.82,6.49,0.323
189.82,6.56,0.323
189.83,6.62,0.323
189.83,6.69,0.322
189.84,6.76,0.322
189.85,6.83,0.322
189.85,6.89,0.322
189.86,6.96,0.321
189.87,7.03,0.321
189.88,7.09,0.321
189.88,7.16,0.320
189.89,7.23,0.320
189.90,7.29,0.320
189.90,7.36,0.320
189.91,7.43,0.319
189.92,7.49,0.319
189.92,7.56,0.319
189.93,7.63,0.319
189.93,7.70,0.319
189.94,7.76,0.318
189.95,7.83,0.318
189.95,7.90,0.318
189.96,7.96,0.318
189.97,8.03,0.318
189.98,8.10,0.318
189.98,8.16,0.318
189.99,8.23,0.317
190.00,8.30,0.317
190.00,8.36,0.317
190.01,8.43,0.317
190.02,8.50,0.317
190.02,8.56,0.317
190.03,8.63,0.317
190.03,8.70,0.317
190.04,8.77,0.317
190.05,8.83,0.317
190.05,8.90,0.316
190.06,8.97,0.316
190.07,9.03,0.316
190.08,9.10,0.316
190.08,9.17,0.316
190.09,9.23,0.316
190.10,9.30,0.316
190.10,9.37,0.316
190.11,9.43,0.316
190.12,9.50,0.316
190.12,9.57,0.315
190.13,9.64,0.315
190.13,9.70,0.315
190.14,9.77,0.315
190.15,9.84,0.315
190.15,9.90,0.315
190.16,9.97,0.315
190.17,10.04,0.315
190.18,10.10,0.315
190.18,10.17,0.315
190.19,10.24,0.315
190.20,10.30,0.315
190.20,10.37,0.315
190.21,10.44,0.315
190.22,10.50,0.315
190.22,10.57,0.315
190.23,10.64,0.314
190.23,10.71,0.314
190.24,10.77,0.314
190.25,10.84,0.314
190.25,10.90,0.314
190.26,10.97,0.314
190.27,11.04,0.314
190.28,11.10,0.314
190.28,11.17,0.314
190.29,11.24,0.314
190.30,11.31,0.314
190.30,11.37,0.314
190.31,11.44,0.314
190.32,11.51,0.314
190.32,11.57,0.314
190.33,11.64,0.314
190.33,11.70,0.314
190.34,11.77,0.314
190.35,11.84,0.314
190.35,11.91,0.314
190.36,11.97,0.314
190.37,12.04,0.314
190.38,12.11,0.314
190.38,12.17,0.314
190.39,12.24,0.314
190.40,12.31,0.314
190.40,12.37,0.314
190.41,12.44,0.314
190.42,12.51,0.314
190.42,12.57,0.314
190.43,12.64,0.314
190.43,12.71,0.314
190.44,12.77,0.314
190.45,12.84,0.314
190.45,12.91,0.314
190.46,12.97,0.314
190.47,13.04,0.314
190.48,13.11,0.314
190.48,13.17,0.314
190.49,13.24,0.314
190.50,13.31,0.314
190.50,13.38,0.314
190.51,13.44,0.314
190.52,13.51,0.314
190.52,13.57,0.314
190.53,13.64,0.314
190.53,13.71,0.314
190.54,13.78,0.314
190.55,13.84,0.314
190.55,13.91,0.314
190.56,13.98,0.314
190.57,14.04,0.314
190.58,14.11,0.314
190.58,14.18,0.314
190.59,14.24,0.314
190.60,14.31,0.314
190.60,14.38,0.314
190.61,14.44,0.314
190.62,14.51,0.314
190.62,14.58,0.314
190.63,14.64,0.314
190.63,14.71,0.314
190.64,14.78,0.314
190.65,14.84,0.314
190.65,14.91,0.314
190.66,14.98,0.314
190.67,15.04,0.314
190.68,15.11,0.314
190.68,15.18,0.314
190.69,15.24,0.314
190.70,15.31,0.314
190.70,15.38,0.314
190.71,15.44,0.314
190.72,15.51,0.314
190.72,15.58,0.315
190.73,15.65,0.315
190.73,15.71,0.315
190.74,15.78,0.315
190.75,15.85,0.315
190.75,15.91,0.315
190.76,15.98,0.315
190.77,16.04,0.315
190.78,16.11,0.315
190.78,16.18,0.315
190.79,16.25,0.315
190.80,16.31,0.315
190.80,16.38,0.315
190.81,16.45,0.315
190.82,16.51,0.315
190.82,16.58,0.315
190.83,16.65,0.315
190.83,16.71,0.315
190.84,16.78,0.315
190.85,16.85,0.315
190.85,16.91,0.315
190.86,16.98,0.315
190.87,17.05,0.315
190.88,17.11,0.315
190.88,17.18,0.315
190.89,17.25,0.315
190.90,17.31,0.315
190.90,17.38,0.316
190.91,17.45,0.316
190.92,17.51,0.316
190.92,17.58,0.316
190.93,17.65,0.316
190.93,17.71,0.316
190.94,17.78,0.316
190.95,17.85,0.316
190.95,17.91,0.316
190.96,17.98,0.316
190.97,18.05,0.316
190.98,18.11,0.316
190.98,18.18,0.316
190.99,18.25,0.316
191.00,18.31,0.316
191.00,18.38,0.316
191.01,18.45,0.316
191.02,18.51,0.316
191.02,18.58,0.316
191.03,18.65,0.316
191.03,18.71,0.316
191.04,18.78,0.316
191.05,18.85,0.316
191.05,18.91,0.317
191.06,18.98,0.317
191.07,19.05,0.317
191.08,19.11,0.317
191.08,19.18,0.317
191.09,19.25,0.317
191.10,19.31,0.317
191.10,19.38,0.317
191.11,19.45,0.317
191.12,19.51,0.317
191.12,19.58,0.317
191.13,19.65,0.317
191.13,19.71,0.317
191.14,19.78,0.317
191.15,19.85,0.317
191.15,19.91,0.317
191.16,19.98,0.317
191.17,20.05,0.317
191.18,20.11,0.318
191.18,20.18,0.318
191.19,20.25,0.318
191.20,20.31,0.318
191.20,20.38,0.318
191.21,20.45,0.318
191.22,20.51,0.318
191.22,20.58,0.318
191.23,20.65,0.318
191.23,20.72,0.318
191.24,20.78,0.318
191.25,20.85,0.318
191.25,20.91,0.318
191.26,20.98,0.318
191.27,21.05,0.318
191.28,21.11,0.318
191.28,21.18,0.318
191.29,21.25,0.318
191.30,21.31,0.318
191.30,21.38,0.319
191.31,21.45,0.319
191.32,21.51,0.319
191.32,21.58,0.319
191.33,21.65,0.319
191.33,21.71,0.319
191.34,21.78,0.319
191.35,21.85,0.319
191.35,21.92,0.319
191.36,21.98,0.319
191.37,22.05,0.319
191.38,22.12,0.319
191.38,22.18,0.319
191.39,22.25,0.319
191.40,22.32,0.319
191.40,22.38,0.319
191.41,22.45,0.319
191.42,22.52,0.319
191.42,22.58,0.319
191.43,22.65,0.320
191.43,22.72,0.320
191.44,22.78,0.320
191.45,22.85,0.320
191.45,22.92,0.320
191.46,22.98,0.320
191.47,23.05,0.320
191.48,23.12,0.320
191.48,23.18,0.320
191.49,23.25,0.320
191.50,23.32,0.320
191.50,23.38,0.320
191.51,23.45,0.320
191.52,23.52,0.320
191.52,23.58,0.320
191.53,23.65,0.320
191.53,23.72,0.320
191.54,23.78,0.320
191.55,23.85,0.321
191.55,23.92,0.321
191.56,23.98,0.321
191.57,24.05,0.321
191.58,24.12,0.321
191.58,24.18,0.321
191.59,24.25,0.321
191.60,24.32,0.321
191.60,24.38,0.321
191.61,24.45,0.321
191.62,24.52,0.321
191.62,24.58,0.321
191.63,24.65,0.321
191.63,24.72,0.321
191.64,24.78,0.321
191.65,24.85,0.321
191.65,24.92,0.322
191.66,24.98,0.322
191.67,25.05,0.322
191.68,25.12,0.322
191.68,25.18,0.322
191.69,25.25,0.322
191.70,25.32,0.322
191.70,25.38,0.322
191.71,25.45,0.322
191.72,25.52,0.322
191.72,25.58,0.322
191.73,25.65,0.322
191.73,25.72,0.322
191.74,25.79,0.322
191.75,25.85,0.322
191.75,25.92,0.322
191.76,25.99,0.322
191.77,26.05,0.322
191.78,26.12,0.323
191.78,26.19,0.323
191.79,26.25,0.323
191.80,26.32,0.323
191.80,26.39,0.323
191.81,26.45,0.323
191.82,26.52,0.323
191.82,26.59,0.323
191.83,26.65,0.323
191.83,26.72,0.323
191.84,26.79,0.323
191.85,26.85,0.323
191.85,26.92,0.323
191.86,26.99,0.323
191.87,27.05,0.323
191.88,27.12,0.323
191.88,27.19,0.323
191.89,27.25,0.324
191.90,27.32,0.324
191.90,27.39,0.324
191.91,27.46,0.324
191.92,27.52,0.324
191.92,27.59,0.324
191.93,27.65,0.324
191.93,27.72,0.324
191.94,27.79,
191.95,27.85,
191.95,27.92,
191.96,27.99,
191.97,28.05,
191.98,28.12,
191.98,28.19,
191.99,,
192.00,,