File: DSC/2025_06_15_THC_Succinic_Acid_Slurry_n60C_200C_10Cmin_x3.csv
Filename,2025_06_15_THC_Succinic_Acid_Slurry_n60C_200C_10Cmin_x3
Instrument name,DSC2A-00468 (192.168.1.100)
Operator,Yarger
rundate,6/15/2025
Sample name,2025_06_15_THC_Succinic_Acid_Slurry_n60C_200C_10Cmin_x3
proceduresegments,Data Off ; Equilibrate -60.00 °C; Data On ; Ramp 10.00 °C/min to 200.00 °C; Data Off ; Isothermal 2.0 min; Data On ; Ramp 10.00 °C/min to -60.00 °C; Data Off ; Isothermal 2.0 min; Data On ; Ramp 10.00 °C/min to 200.00 °C; Data Off ; Isothermal 2.0 min; Data On ; Ramp 10.00 °C/min to -60.00 °C; Data Off ; Isothermal 2.0 min; Data On ; Ramp 10.00 °C/min to 30.00 °C
[File Parameters]
Run date,6/15/2025 3:14:46 AM
Trios version,5.1.1.46572
Original File Name,
Current File Name,D:\DSC2500\JYarger\2025_06_15_THC_Succinic_Acid_Slurry_n60C_200C_10Cmin_x3.tri
[Procedure]
Procedure Name,THC_SA_n60C_200C_10Cmin_x3
Sample Name,2025_06_15_THC_Succinic_Acid_Slurry_n60C_200C_10Cmin_x3
Sample Mass,3.97 mg
Reference Sample Mass,0 mg
Pan Mass,57.86 mg
Pan Number,43
Reference Pan Mass,57.05 mg
Reference Pan Number,28
Pan Type,Tzero Aluminum Hermetic
Comments,Al Hermetic DSC Consumables sealed Pan/Lid. A2 Tray (Google Sheet: DSC_Samples_A2_Tray_May2025)
Project Name,CA
Operator,Yarger
Test,Custom
Unload Max Temperature,30
Unload Min Temperature,30
Load Max Temperature,30
Load Min Temperature,30
Stop on Gas Flow Error,Yes
[Signal List]
Signal #1,Time (min)
Signal #2,Temperature (°C)
Signal #3,Heat Flow (mW)
Signal #4,Delta T (µV)
Signal #5,Delta Tzero (µV)
Signal #6,Tzero Temperature (°C)
Signal #7,Cell Purge (mL/min)
Signal #8,Heater Temp (°C)
Signal #9,Power Delivered (W)
Signal #10,Reference Junction Temperature (°C)
Signal #11,Flange Temperature (°C)
Signal #12,Heat Flow Phase (rad)
Signal #13,Total Heat Capacity (J/°C)
Signal #14,Heat Capacity (J/°C)
[Configuration]
Company Name,ASU
Instrument Name,DSC2A-00468
Instrument Type,DSC2500
Serial Number,DSC2A-00468
IP,192.168.1.100
Location of Instrument,MRRC
DisplayType,Unknown
Sample Interval ,0.1 s/pt
Selected Heat Flow,T4P
Exotherm Direction,Down
Cell Serial,DRC2-00792
Lid Type,Standard
Cooler,RCS 90
Leave Cooler on at End of Sequence,On
Gas 2,Nitrogen
Gas Selected,Channel 1
Flow Rate,50 mL/min
Secondary Purge,On
Licensed Heat Flow,Heat Flow T4P
Modulation Licensed,Yes
[Versions]
Common IDD Version,1
Cortex Version,VER 2.10.2.31
Driver,5.0.0.6
GDM Version,1.0.3.3
TouchscreenVersion,1.0.0.16145
FEP Version,1.2.1.21
FEP Bootloader,2.0.0.5
AutoSampler Version,2.1.1.26
Auto Sampler Bootloader,2.0.0.5
FCM Version,1.1.0.3
FCM Bootloader,2.0.0.5
[Experiment Logs]
Experiment Log Entry # 1,Lid Close
Experiment Log Entry # 3,Data On set to 0
Experiment Log Entry # 5,Equilibrate Segment -60 (C) Started
Experiment Log Entry # 7,Air Cool is off.
Experiment Log Entry # 9,Data On set to 1
Experiment Log Entry # 11,Ramp Segment 10 C/min to 200 Started
Experiment Log Entry # 13,Data On set to 0
Experiment Log Entry # 15,Isothermal Segment 2 min started
Experiment Log Entry # 17,Data On set to 1
Experiment Log Entry # 19,Ramp Segment 10 C/min to -60 Started
Experiment Log Entry # 21,Data On set to 0
Experiment Log Entry # 23,Isothermal Segment 2 min started
Experiment Log Entry # 25,Data On set to 1
Experiment Log Entry # 27,Ramp Segment 10 C/min to 200 Started
Experiment Log Entry # 29,Data On set to 0
Experiment Log Entry # 31,Isothermal Segment 2 min started
Experiment Log Entry # 33,Data On set to 1
Experiment Log Entry # 35,Ramp Segment 10 C/min to -60 Started
Experiment Log Entry # 37,Data On set to 0
Experiment Log Entry # 39,Isothermal Segment 2 min started
Experiment Log Entry # 41,Data On set to 1
Experiment Log Entry # 43,Ramp Segment 10 C/min to 30 Started
[Method Log]
Method Log Entry # 1,Data Off
Method Log Entry # 2,Equilibrate -60 °C
Method Log Entry # 3,Data On
Method Log Entry # 4,(Ramp 274325) Ramp 10 °C/minute to 200 °C
Method Log Entry # 5,Data Off
Method Log Entry # 6,Isothermal 2 minutes
Method Log Entry # 7,Data On
Method Log Entry # 8,(Ramp 274329) Ramp 10 °C/minute to -60 °C
Method Log Entry # 9,Data Off
Method Log Entry # 10,Isothermal 2 minutes
Method Log Entry # 11,Data On
Method Log Entry # 12,(Ramp 274333) Ramp 10 °C/minute to 200 °C
Method Log Entry # 13,Data Off
Method Log Entry # 14,Isothermal 2 minutes
Method Log Entry # 15,Data On
Method Log Entry # 16,(Ramp 274337) Ramp 10 °C/minute to -60 °C
Method Log Entry # 17,Data Off
Method Log Entry # 18,Isothermal 2 minutes
Method Log Entry # 19,Data On
Method Log Entry # 20,(Ramp 274341) Ramp 10 °C/minute to 30 °C
Cell Serial,DRC2-00792
[T1 Calibration]
Slope,-0.008529666
Offset,9.636258
Initial Temperature,98.23
GUID,f8bfdadc-4977-4fdf-ba6d-0ba9134940c3
[TZero Calibration]
Date Applied,11/29/2022 4:06:13 PM
Description,From -89.059 °C to 396.009 °C at 20.000°C/min
Gas Type,Nitrogen
Pan Type,None
Source Files 1,C:\Users\yargerlab\Desktop\DSC Data\General\TZero_calibration_11_29_22_2nd(2).tri
Source Files 2,C:\Users\yargerlab\Desktop\DSC Data\General\TZero_calibration_11_29_22_2nd(3).tri
Delta T Offset,13.05235
Delta T Slope,-0.007271007
Delta T0 Offset,-13.69128
Delta T0 Slope,0.06063341
[Temperature Calibration]
Date Applied,11/29/2022 7:12:28 PM
Description,From 106.590 °C to 186.590 °C at 10.000°C/min
Gas Type,Nitrogen
Pan Type,Tzero Aluminum Hermetic
Source Files 1,C:\Users\yargerlab\Desktop\DSC Data\General\Indium(6).tri
Measured 1,157.391
Known 1,156.598
[Cell Constant Calibration]
Date Applied,11/29/2022 7:12:29 PM
Description,From 106.590 °C to 186.590 °C at 10.000°C/min
Gas Type,Nitrogen
Pan Type,Tzero Aluminum Hermetic
Source Files 1,C:\Users\yargerlab\Desktop\DSC Data\General\Indium(6).tri
T4P KCell,1.006051
Onset Slope,63.26126 mW/°C
[Direct Cp Calibration]
Date Applied,11/30/2022 11:04:51 AM
Description,From -79.983 °C to 298.409 °C at 10.000°C/min
Gas Type,Nitrogen
Pan Type,Tzero Aluminum Hermetic
Source Files 1,C:\Users\yargerlab\Desktop\DSC Data\General\Sapphire_Heat_Capacity_11_30_22.tri
[Rev Cp Calibration]
Date Applied,11/30/2022 1:58:51 PM
Description,From -79.996 °C to 292.812 °C at 3.000°C/min
Gas Type,Nitrogen
Pan Type,Tzero Aluminum Hermetic
Source Files 1,C:\Users\yargerlab\Desktop\DSC Data\General\Sapphire_MDSC_Calibration_11_30_22.tri
[step]
Ramp 10.00 °C/min to 200.00 °C
Time,Temperature,Heat Flow (Normalized)
min,°C,W/g
0.00,-59.67,-0.081
0.02,-59.69,-0.078
0.04,-59.69,-0.070
0.05,-59.69,-0.069
0.07,-59.67,-0.072
0.09,-59.63,-0.089
0.11,-59.57,-0.105
0.13,-59.49,-0.115
0.15,-59.39,-0.114
0.16,-59.28,-0.112
0.18,-59.15,-0.091
0.20,-59.02,-0.066
0.22,-58.88,-0.045
0.24,-58.73,-0.021
0.26,-58.59,-0.001
0.28,-58.43,0.021
0.29,-58.27,0.038
0.31,-58.11,0.051
0.33,-57.95,0.066
0.35,-57.79,0.077
0.37,-57.62,0.088
0.39,-57.46,0.093
0.40,-57.29,0.104
0.42,-57.12,0.109
0.44,-56.95,0.116
0.46,-56.78,0.120
0.48,-56.60,0.124
0.50,-56.43,0.129
0.51,-56.25,0.131
0.53,-56.08,0.136
0.55,-55.90,0.139
0.57,-55.73,0.142
0.59,-55.55,0.144
0.60,-55.37,0.145
0.62,-55.19,0.146
0.64,-55.02,0.147
0.66,-54.84,0.148
0.68,-54.66,0.150
0.70,-54.48,0.151
0.72,-54.30,0.152
0.73,-54.12,0.152
0.75,-53.94,0.153
0.77,-53.76,0.154
0.79,-53.58,0.155
0.81,-53.40,0.155
0.83,-53.22,0.155
0.84,-53.04,0.156
0.86,-52.86,0.156
0.88,-52.68,0.157
0.90,-52.50,0.158
0.92,-52.32,0.158
0.93,-52.14,0.159
0.95,-51.96,0.159
0.97,-51.78,0.159
0.99,-51.60,0.160
1.01,-51.41,0.160
1.03,-51.23,0.161
1.05,-51.05,0.161
1.06,-50.87,0.161
1.08,-50.69,0.161
1.10,-50.50,0.162
1.12,-50.32,0.162
1.14,-50.14,0.163
1.16,-49.96,0.163
1.17,-49.78,0.163
1.19,-49.59,0.164
1.21,-49.41,0.164
1.23,-49.23,0.164
1.25,-49.05,0.164
1.27,-48.86,0.165
1.28,-48.68,0.165
1.30,-48.50,0.165
1.32,-48.32,0.165
1.34,-48.13,0.166
1.36,-47.95,0.166
1.38,-47.77,0.166
1.39,-47.59,0.166
1.41,-47.40,0.166
1.43,-47.22,0.166
1.45,-47.04,0.167
1.47,-46.86,0.167
1.48,-46.67,0.167
1.50,-46.49,0.167
1.52,-46.31,0.167
1.54,-46.12,0.167
1.56,-45.94,0.167
1.58,-45.76,0.167
1.59,-45.57,0.167
1.61,-45.39,0.168
1.63,-45.20,0.168
1.65,-45.02,0.168
1.67,-44.84,0.168
1.69,-44.66,0.168
1.71,-44.47,0.168
1.72,-44.29,0.168
1.74,-44.10,0.169
1.76,-43.92,0.169
1.78,-43.74,0.169
1.80,-43.56,0.169
1.82,-43.37,0.169
1.83,-43.19,0.169
1.85,-43.00,0.169
1.87,-42.82,0.169
1.89,-42.64,0.169
1.91,-42.46,0.169
1.93,-42.27,0.169
1.94,-42.09,0.169
1.96,-41.91,0.170
1.98,-41.72,0.170
2.00,-41.54,0.170
2.02,-41.36,0.170
2.03,-41.17,0.170
2.05,-40.99,0.170
2.07,-40.80,0.170
2.09,-40.62,0.170
2.11,-40.44,0.170
2.13,-40.25,0.170
2.14,-40.07,0.170
2.16,-39.89,0.170
2.18,-39.70,0.170
2.20,-39.52,0.170
2.22,-39.34,0.170
2.24,-39.15,0.170
2.26,-38.97,0.170
2.27,-38.79,0.170
2.29,-38.60,0.170
2.31,-38.42,0.170
2.33,-38.23,0.170
2.35,-38.05,0.170
2.36,-37.87,0.170
2.38,-37.68,0.170
2.40,-37.50,0.170
2.42,-37.32,0.171
2.44,-37.13,0.170
2.46,-36.95,0.171
2.48,-36.77,0.171
2.49,-36.58,0.171
2.51,-36.40,0.171
2.53,-36.22,0.171
2.55,-36.03,0.171
2.57,-35.85,0.171
2.59,-35.67,0.171
2.60,-35.48,0.171
2.62,-35.30,0.171
2.64,-35.12,0.171
2.66,-34.93,0.171
2.68,-34.75,0.171
2.69,-34.56,0.171
2.71,-34.38,0.171
2.73,-34.20,0.171
2.75,-34.01,0.171
2.77,-33.83,0.171
2.79,-33.65,0.171
2.81,-33.46,0.171
2.82,-33.28,0.171
2.84,-33.09,0.171
2.86,-32.91,0.171
2.88,-32.73,0.171
2.90,-32.54,0.171
2.91,-32.36,0.171
2.93,-32.18,0.172
2.95,-31.99,0.172
2.97,-31.81,0.172
2.99,-31.62,0.172
3.01,-31.44,0.172
3.03,-31.26,0.172
3.04,-31.07,0.172
3.06,-30.89,0.172
3.08,-30.70,0.172
3.10,-30.52,0.172
3.12,-30.34,0.172
3.14,-30.16,0.172
3.15,-29.97,0.172
3.17,-29.79,0.172
3.19,-29.60,0.172
3.21,-29.42,0.173
3.23,-29.24,0.173
3.24,-29.05,0.173
3.26,-28.87,0.173
3.28,-28.69,0.173
3.30,-28.50,0.173
3.32,-28.32,0.173
3.34,-28.14,0.173
3.36,-27.95,0.173
3.37,-27.77,0.173
3.39,-27.58,0.173
3.41,-27.40,0.173
3.43,-27.22,0.173
3.45,-27.04,0.173
3.46,-26.85,0.173
3.48,-26.67,0.173
3.50,-26.48,0.173
3.52,-26.30,0.173
3.54,-26.12,0.173
3.56,-25.93,0.173
3.58,-25.75,0.173
3.59,-25.57,0.173
3.61,-25.38,0.174
3.63,-25.20,0.174
3.65,-25.02,0.174
3.67,-24.83,0.174
3.69,-24.65,0.174
3.70,-24.46,0.174
3.72,-24.28,0.174
3.74,-24.10,0.174
3.76,-23.91,0.174
3.78,-23.73,0.174
3.79,-23.55,0.174
3.81,-23.36,0.174
3.83,-23.18,0.174
3.85,-22.99,0.174
3.87,-22.81,0.174
3.89,-22.63,0.174
3.91,-22.44,0.174
3.92,-22.26,0.174
3.94,-22.08,0.174
3.96,-21.89,0.174
3.98,-21.71,0.175
4.00,-21.53,0.175
4.01,-21.34,0.175
4.03,-21.16,0.175
4.05,-20.98,0.175
4.07,-20.79,0.175
4.09,-20.61,0.175
4.11,-20.42,0.175
4.13,-20.24,0.175
4.14,-20.06,0.175
4.16,-19.87,0.175
4.18,-19.69,0.175
4.20,-19.51,0.175
4.22,-19.32,0.175
4.24,-19.14,0.175
4.25,-18.96,0.176
4.27,-18.77,0.176
4.29,-18.59,0.176
4.31,-18.41,0.176
4.33,-18.22,0.176
4.35,-18.04,0.176
4.36,-17.86,0.176
4.38,-17.67,0.176
4.40,-17.49,0.176
4.42,-17.30,0.176
4.44,-17.12,0.176
4.45,-16.94,0.176
4.47,-16.75,0.176
4.49,-16.57,0.176
4.51,-16.39,0.176
4.53,-16.20,0.176
4.55,-16.02,0.176
4.56,-15.84,0.177
4.58,-15.65,0.177
4.60,-15.47,0.177
4.62,-15.29,0.177
4.64,-15.10,0.177
4.66,-14.92,0.177
4.68,-14.74,0.177
4.69,-14.55,0.177
4.71,-14.37,0.177
4.73,-14.18,0.177
4.75,-14.00,0.177
4.77,-13.82,0.177
4.79,-13.63,0.177
4.80,-13.45,0.177
4.82,-13.27,0.177
4.84,-13.08,0.177
4.86,-12.90,0.178
4.88,-12.71,0.178
4.90,-12.53,0.178
4.91,-12.35,0.178
4.93,-12.17,0.178
4.95,-11.98,0.178
4.97,-11.80,0.178
4.99,-11.61,0.178
5.00,-11.43,0.178
5.02,-11.25,0.178
5.04,-11.06,0.178
5.06,-10.88,0.178
5.08,-10.70,0.178
5.10,-10.51,0.179
5.11,-10.33,0.179
5.13,-10.15,0.179
5.15,-9.96,0.179
5.17,-9.78,0.179
5.19,-9.60,0.179
5.21,-9.41,0.179
5.23,-9.23,0.179
5.24,-9.05,0.179
5.26,-8.86,0.179
5.28,-8.68,0.179
5.30,-8.49,0.180
5.32,-8.31,0.180
5.34,-8.13,0.180
5.35,-7.94,0.180
5.37,-7.76,0.180
5.39,-7.58,0.180
5.41,-7.39,0.180
5.43,-7.21,0.180
5.45,-7.03,0.181
5.46,-6.84,0.181
5.48,-6.66,0.181
5.50,-6.47,0.181
5.52,-6.29,0.181
5.54,-6.11,0.181
5.55,-5.92,0.181
5.57,-5.74,0.182
5.59,-5.56,0.182
5.61,-5.37,0.182
5.63,-5.19,0.182
5.65,-5.01,0.182
5.66,-4.82,0.182
5.68,-4.64,0.183
5.70,-4.46,0.183
5.72,-4.27,0.183
5.74,-4.09,0.183
5.76,-3.91,0.183
5.78,-3.72,0.183
5.79,-3.54,0.183
5.81,-3.35,0.184
5.83,-3.17,0.184
5.85,-2.99,0.184
5.87,-2.80,0.184
5.89,-2.62,0.184
5.90,-2.44,0.184
5.92,-2.25,0.185
5.94,-2.07,0.185
5.96,-1.89,0.185
5.98,-1.70,0.185
6.00,-1.52,0.185
6.01,-1.34,0.186
6.03,-1.15,0.186
6.05,-0.97,0.186
6.07,-0.79,0.186
6.09,-0.60,0.186
6.10,-0.42,0.186
6.12,-0.23,0.187
6.14,-0.05,0.187
6.16,0.13,0.187
6.18,0.32,0.187
6.20,0.50,0.188
6.21,0.68,0.188
6.23,0.87,0.188
6.25,1.05,0.188
6.27,1.23,0.188
6.29,1.42,0.189
6.31,1.60,0.189
6.33,1.78,0.189
6.34,1.97,0.189
6.36,2.15,0.190
6.38,2.34,0.190
6.40,2.52,0.190
6.42,2.70,0.190
6.44,2.89,0.191
6.45,3.07,0.191
6.47,3.25,0.191
6.49,3.43,0.191
6.51,3.62,0.192
6.53,3.80,0.192
6.55,3.99,0.192
6.56,4.17,0.192
6.58,4.35,0.192
6.60,4.54,0.193
6.62,4.72,0.193
6.64,4.90,0.193
6.65,5.09,0.193
6.67,5.27,0.193
6.69,5.45,0.194
6.71,5.64,0.194
6.73,5.82,0.194
6.75,6.01,0.194
6.76,6.19,0.194
6.78,6.37,0.194
6.80,6.56,0.195
6.82,6.74,0.195
6.84,6.92,0.195
6.86,7.11,0.195
6.88,7.29,0.195
6.89,7.47,0.196
6.91,7.66,0.196
6.93,7.84,0.196
6.95,8.03,0.196
6.97,8.21,0.196
6.99,8.39,0.196
7.00,8.57,0.196
7.02,8.76,0.196
7.04,8.94,0.197
7.06,9.13,0.197
7.08,9.31,0.197
7.10,9.49,0.197
7.11,9.68,0.197
7.13,9.86,0.197
7.15,10.04,0.197
7.17,10.23,0.197
7.19,10.41,0.197
7.20,10.60,0.198
7.22,10.78,0.198
7.24,10.96,0.198
7.26,11.15,0.198
7.28,11.33,0.198
7.30,11.51,0.198
7.31,11.70,0.198
7.33,11.88,0.198
7.35,12.06,0.198
7.37,12.25,0.199
7.39,12.43,0.199
7.41,12.61,0.199
7.43,12.80,0.199
7.44,12.98,0.199
7.46,13.17,0.199
7.48,13.35,0.199
7.50,13.53,0.199
7.52,13.72,0.199
7.54,13.90,0.199
7.55,14.08,0.200
7.57,14.27,0.200
7.59,14.45,0.200
7.61,14.63,0.200
7.63,14.82,0.200
7.65,15.00,0.200
7.66,15.18,0.200
7.68,15.37,0.200
7.70,15.55,0.200
7.72,15.73,0.200
7.74,15.92,0.201
7.75,16.10,0.201
7.77,16.29,0.201
7.79,16.47,0.201
7.81,16.65,0.201
7.83,16.84,0.201
7.85,17.02,0.201
7.86,17.20,0.201
7.88,17.39,0.202
7.90,17.57,0.202
7.92,17.75,0.202
7.94,17.94,0.202
7.96,18.12,0.202
7.98,18.30,0.202
7.99,18.49,0.202
8.01,18.67,0.202
8.03,18.85,0.203
8.05,19.04,0.203
8.07,19.22,0.203
8.09,19.41,0.203
8.10,19.59,0.203
8.12,19.77,0.203
8.14,19.96,0.203
8.16,20.14,0.203
8.18,20.32,0.203
8.20,20.51,0.204
8.21,20.69,0.204
8.23,20.87,0.204
8.25,21.06,0.204
8.27,21.24,0.204
8.29,21.42,0.204
8.30,21.61,0.204
8.32,21.79,0.204
8.34,21.97,0.205
8.36,22.16,0.205
8.38,22.34,0.205
8.40,22.53,0.205
8.41,22.71,0.205
8.43,22.89,0.205
8.45,23.08,0.205
8.47,23.26,0.205
8.49,23.44,0.205
8.51,23.63,0.206
8.53,23.81,0.206
8.54,23.99,0.206
8.56,24.18,0.206
8.58,24.36,0.206
8.60,24.54,0.206
8.62,24.73,0.206
8.63,24.91,0.207
8.65,25.09,0.207
8.67,25.28,0.207
8.69,25.46,0.207
8.71,25.64,0.207
8.73,25.83,0.207
8.75,26.01,0.207
8.76,26.20,0.208
8.78,26.38,0.208
8.80,26.56,0.208
8.82,26.75,0.208
8.84,26.93,0.208
8.85,27.11,0.208
8.87,27.30,0.208
8.89,27.48,0.209
8.91,27.66,0.209
8.93,27.85,0.209
8.95,28.03,0.209
8.97,28.22,0.209
8.98,28.40,0.209
9.00,28.58,0.209
9.02,28.77,0.209
9.04,28.95,0.210
9.06,29.13,0.210
9.08,29.32,0.210
9.09,29.50,0.210
9.11,29.68,0.210
9.13,29.87,0.210
9.15,30.05,0.210
9.17,30.23,0.210
9.18,30.42,0.210
9.20,30.60,0.211
9.22,30.79,0.211
9.24,30.97,0.211
9.26,31.15,0.211
9.28,31.34,0.211
9.30,31.52,0.211
9.31,31.70,0.211
9.33,31.89,0.212
9.35,32.07,0.212
9.37,32.25,0.212
9.39,32.44,0.212
9.40,32.62,0.212
9.42,32.80,0.212
9.44,32.99,0.212
9.46,33.17,0.212
9.48,33.35,0.213
9.50,33.54,0.213
9.52,33.72,0.213
9.53,33.91,0.213
9.55,34.09,0.213
9.57,34.27,0.213
9.59,34.45,0.214
9.61,34.64,0.214
9.63,34.82,0.214
9.64,35.01,0.214
9.66,35.19,0.214
9.68,35.37,0.214
9.70,35.56,0.215
9.72,35.74,0.215
9.73,35.92,0.215
9.75,36.11,0.215
9.77,36.29,0.215
9.79,36.47,0.215
9.81,36.66,0.215
9.83,36.84,0.216
9.85,37.03,0.216
9.86,37.21,0.216
9.88,37.39,0.216
9.90,37.58,0.216
9.92,37.76,0.216
9.94,37.94,0.216
9.95,38.13,0.216
9.97,38.31,0.217
9.99,38.49,0.217
10.01,38.68,0.217
10.03,38.86,0.217
10.05,39.04,0.217
10.07,39.23,0.217
10.08,39.41,0.217
10.10,39.59,0.217
10.12,39.78,0.217
10.14,39.96,0.218
10.16,40.15,0.218
10.18,40.33,0.218
10.19,40.51,0.218
10.21,40.70,0.218
10.23,40.88,0.218
10.25,41.06,0.218
10.27,41.25,0.219
10.28,41.43,0.219
10.30,41.61,0.219
10.32,41.80,0.219
10.34,41.98,0.219
10.36,42.16,0.219
10.38,42.35,0.219
10.40,42.53,0.220
10.41,42.71,0.220
10.43,42.90,0.220
10.45,43.08,0.220
10.47,43.27,0.220
10.49,43.45,0.220
10.50,43.63,0.220
10.52,43.82,0.220
10.54,44.00,0.221
10.56,44.18,0.221
10.58,44.37,0.221
10.60,44.55,0.221
10.62,44.73,0.221
10.63,44.92,0.221
10.65,45.10,0.221
10.67,45.28,0.221
10.69,45.47,0.222
10.71,45.65,0.222
10.73,45.84,0.222
10.74,46.02,0.222
10.76,46.20,0.222
10.78,46.38,0.222
10.80,46.57,0.222
10.82,46.75,0.222
10.83,46.94,0.223
10.85,47.12,0.223
10.87,47.30,0.223
10.89,47.49,0.223
10.91,47.67,0.223
10.93,47.86,0.223
10.95,48.04,0.223
10.96,48.22,0.224
10.98,48.40,0.224
11.00,48.59,0.224
11.02,48.77,0.224
11.04,48.96,0.224
11.05,49.14,0.224
11.07,49.32,0.224
11.09,49.51,0.224
11.11,49.69,0.224
11.13,49.87,0.225
11.15,50.06,0.225
11.17,50.24,0.225
11.18,50.42,0.225
11.20,50.61,0.225
11.22,50.79,0.225
11.24,50.97,0.225
11.26,51.16,0.226
11.28,51.34,0.226
11.29,51.52,0.226
11.31,51.71,0.226
11.33,51.89,0.226
11.35,52.08,0.226
11.37,52.26,0.226
11.38,52.44,0.226
11.40,52.62,0.227
11.42,52.81,0.227
11.44,52.99,0.227
11.46,53.18,0.227
11.48,53.36,0.227
11.50,53.54,0.227
11.51,53.73,0.227
11.53,53.91,0.227
11.55,54.10,0.227
11.57,54.28,0.228
11.59,54.46,0.228
11.60,54.64,0.228
11.62,54.83,0.228
11.64,55.01,0.228
11.66,55.20,0.228
11.68,55.38,0.228
11.70,55.57,0.228
11.72,55.75,0.229
11.73,55.93,0.229
11.75,56.12,0.229
11.77,56.30,0.229
11.79,56.49,0.230
11.81,56.67,0.230
11.83,56.85,0.230
11.84,57.03,0.230
11.86,57.22,0.230
11.88,57.40,0.230
11.90,57.59,0.230
11.92,57.77,0.230
11.93,57.95,0.230
11.95,58.13,0.230
11.97,58.32,0.230
11.99,58.50,0.230
12.01,58.69,0.230
12.03,58.87,0.230
12.05,59.05,0.230
12.06,59.24,0.230
12.08,59.42,0.235
12.10,59.60,0.237
12.12,59.78,0.236
12.14,59.97,0.236
12.15,60.15,0.236
12.17,60.34,0.236
12.19,60.52,0.235
12.21,60.70,0.235
12.23,60.89,0.235
12.25,61.07,0.235
12.27,61.25,0.235
12.28,61.44,0.235
12.30,61.62,0.234
12.32,61.80,0.234
12.34,61.99,0.234
12.36,62.17,0.234
12.38,62.35,0.234
12.39,62.54,0.234
12.41,62.72,0.234
12.43,62.90,0.234
12.45,63.09,0.234
12.47,63.27,0.234
12.48,63.45,0.234
12.50,63.64,0.234
12.52,63.82,0.234
12.54,64.00,0.234
12.56,64.19,0.234
12.58,64.37,0.234
12.60,64.55,0.234
12.61,64.74,0.234
12.63,64.92,0.234
12.65,65.11,0.235
12.67,65.29,0.235
12.69,65.47,0.235
12.70,65.66,0.235
12.72,65.84,0.235
12.74,66.02,0.235
12.76,66.21,0.235
12.78,66.39,0.235
12.80,66.57,0.235
12.82,66.76,0.235
12.83,66.94,0.235
12.85,67.12,0.236
12.87,67.31,0.236
12.89,67.49,0.236
12.91,67.67,0.236
12.93,67.86,0.236
12.94,68.04,0.236
12.96,68.22,0.236
12.98,68.41,0.236
13.00,68.59,0.236
13.02,68.77,0.236
13.03,68.96,0.237
13.05,69.14,0.237
13.07,69.32,0.237
13.09,69.51,0.237
13.11,69.69,0.237
13.13,69.87,0.237
13.15,70.06,0.237
13.16,70.24,0.237
13.18,70.43,0.237
13.20,70.61,0.238
13.22,70.79,0.238
13.24,70.98,0.238
13.25,71.16,0.238
13.27,71.34,0.238
13.29,71.53,0.238
13.31,71.71,0.238
13.33,71.89,0.238
13.35,72.08,0.238
13.37,72.26,0.239
13.38,72.44,0.239
13.40,72.63,0.239
13.42,72.81,0.239
13.44,72.99,0.239
13.46,73.18,0.239
13.48,73.36,0.239
13.49,73.55,0.239
13.51,73.73,0.240
13.53,73.91,0.240
13.55,74.10,0.240
13.57,74.28,0.240
13.58,74.46,0.240
13.60,74.65,0.240
13.62,74.83,0.240
13.64,75.01,0.240
13.66,75.20,0.240
13.68,75.38,0.241
13.70,75.57,0.241
13.71,75.75,0.241
13.73,75.93,0.241
13.75,76.12,0.241
13.77,76.30,0.241
13.79,76.48,0.241
13.80,76.67,0.241
13.82,76.85,0.242
13.84,77.03,0.242
13.86,77.22,0.242
13.88,77.40,0.242
13.90,77.58,0.242
13.92,77.77,0.242
13.93,77.95,0.242
13.95,78.13,0.242
13.97,78.32,0.242
13.99,78.50,0.243
14.01,78.69,0.243
14.03,78.87,0.243
14.04,79.05,0.243
14.06,79.24,0.243
14.08,79.42,0.243
14.10,79.60,0.243
14.12,79.79,0.243
14.13,79.97,0.244
14.15,80.15,0.244
14.17,80.34,0.244
14.19,80.52,0.244
14.21,80.70,0.244
14.23,80.89,0.244
14.25,81.07,0.245
14.26,81.26,0.245
14.28,81.44,0.245
14.30,81.62,0.245
14.32,81.81,0.245
14.34,81.99,0.245
14.35,82.17,0.245
14.37,82.36,0.245
14.39,82.54,0.245
14.41,82.73,0.245
14.43,82.91,0.245
14.45,83.09,0.246
14.47,83.28,0.246
14.48,83.46,0.246
14.50,83.64,0.246
14.52,83.83,0.246
14.54,84.01,0.246
14.56,84.19,0.246
14.58,84.38,0.246
14.59,84.56,0.246
14.61,84.74,0.246
14.63,84.93,0.246
14.65,85.11,0.246
14.67,85.30,0.246
14.68,85.48,0.246
14.70,85.66,0.246
14.72,85.85,0.246
14.74,86.03,0.246
14.76,86.21,0.246
14.78,86.40,0.246
14.80,86.58,0.246
14.81,86.76,0.246
14.83,86.95,0.246
14.85,87.13,0.246
14.87,87.31,0.246
14.89,87.50,0.246
14.90,87.68,0.247
14.92,87.87,0.247
14.94,88.05,0.247
14.96,88.23,0.247
14.98,88.42,0.247
15.00,88.60,0.247
15.02,88.78,0.247
15.03,88.97,0.247
15.05,89.15,0.247
15.07,89.33,0.247
15.09,89.52,0.248
15.11,89.70,0.248
15.13,89.89,0.248
15.14,90.07,0.248
15.16,90.25,0.248
15.18,90.44,0.248
15.20,90.62,0.248
15.22,90.80,0.248
15.23,90.99,0.248
15.25,91.17,0.248
15.27,91.35,0.248
15.29,91.54,0.249
15.31,91.72,0.249
15.33,91.90,0.249
15.35,92.09,0.249
15.36,92.27,0.249
15.38,92.45,0.249
15.40,92.64,0.249
15.42,92.82,0.250
15.44,93.00,0.250
15.45,93.19,0.250
15.47,93.37,0.250
15.49,93.55,0.250
15.51,93.74,0.250
15.53,93.92,0.250
15.55,94.10,0.250
15.57,94.29,0.250
15.58,94.47,0.250
15.60,94.65,0.251
15.62,94.84,0.251
15.64,95.02,0.251
15.66,95.20,0.251
15.68,95.39,0.251
15.69,95.57,0.251
15.71,95.76,0.251
15.73,95.94,0.251
15.75,96.12,0.251
15.77,96.31,0.251
15.78,96.49,0.252
15.80,96.67,0.252
15.82,96.86,0.252
15.84,97.04,0.252
15.86,97.22,0.252
15.88,97.41,0.252
15.90,97.59,0.252
15.91,97.77,0.252
15.93,97.96,0.252
15.95,98.14,0.252
15.97,98.32,0.252
15.99,98.51,0.252
16.00,98.69,0.252
16.02,98.87,0.252
16.04,99.06,0.253
16.06,99.24,0.253
16.08,99.42,0.253
16.10,99.61,0.253
16.12,99.79,0.253
16.13,99.97,0.253
16.15,100.16,0.253
16.17,100.34,0.253
16.19,100.52,0.253
16.21,100.71,0.253
16.23,100.89,0.254
16.24,101.08,0.254
16.26,101.26,0.254
16.28,101.44,0.254
16.30,101.63,0.254
16.32,101.81,0.254
16.33,101.99,0.254
16.35,102.18,0.254
16.37,102.36,0.254
16.39,102.54,0.254
16.41,102.73,0.255
16.43,102.91,0.255
16.45,103.09,0.255
16.46,103.28,0.255
16.48,103.46,0.255
16.50,103.64,0.255
16.52,103.83,0.255
16.54,104.01,0.255
16.55,104.19,0.255
16.57,104.38,0.255
16.59,104.56,0.256
16.61,104.74,0.256
16.63,104.93,0.256
16.65,105.11,0.256
16.67,105.29,0.256
16.68,105.48,0.256
16.70,105.66,0.256
16.72,105.84,0.257
16.74,106.03,0.257
16.76,106.21,0.257
16.78,106.39,0.257
16.79,106.58,0.257
16.81,106.76,0.257
16.83,106.95,0.257
16.85,107.13,0.257
16.87,107.31,0.257
16.88,107.50,0.258
16.90,107.68,0.258
16.92,107.86,0.258
16.94,108.05,0.258
16.96,108.23,0.258
16.98,108.41,0.258
17.00,108.60,0.258
17.01,108.78,0.258
17.03,108.96,0.258
17.05,109.15,0.259
17.07,109.33,0.259
17.09,109.52,0.259
17.11,109.70,0.259
17.12,109.88,0.259
17.14,110.07,0.259
17.16,110.25,0.259
17.18,110.43,0.259
17.20,110.62,0.259
17.22,110.80,0.259
17.23,110.98,0.260
17.25,111.17,0.260
17.27,111.35,0.260
17.29,111.54,0.260
17.31,111.72,0.260
17.33,111.90,0.260
17.34,112.09,0.260
17.36,112.27,0.260
17.38,112.45,0.260
17.40,112.64,0.260
17.42,112.82,0.260
17.43,113.00,0.260
17.45,113.19,0.260
17.47,113.37,0.260
17.49,113.55,0.260
17.51,113.74,0.261
17.53,113.92,0.261
17.54,114.10,0.261
17.56,114.29,0.261
17.58,114.47,0.261
17.60,114.65,0.261
17.62,114.84,0.261
17.64,115.02,0.261
17.66,115.20,0.261
17.67,115.39,0.261
17.69,115.57,0.261
17.71,115.75,0.262
17.73,115.94,0.262
17.75,116.12,0.262
17.77,116.31,0.262
17.78,116.49,0.262
17.80,116.67,0.262
17.82,116.86,0.262
17.84,117.04,0.262
17.86,117.22,0.262
17.88,117.40,0.262
17.89,117.59,0.263
17.91,117.77,0.263
17.93,117.95,0.263
17.95,118.14,0.263
17.97,118.32,0.263
17.98,118.50,0.263
18.00,118.69,0.263
18.02,118.87,0.263
18.04,119.06,0.263
18.06,119.24,0.264
18.08,119.42,0.264
18.09,119.61,0.264
18.11,119.79,0.264
18.13,119.97,0.264
18.15,120.16,0.264
18.17,120.34,0.264
18.19,120.53,0.264
18.21,120.71,0.265
18.22,120.89,0.265
18.24,121.08,0.265
18.26,121.26,0.265
18.28,121.44,0.265
18.30,121.63,0.265
18.32,121.81,0.265
18.33,121.99,0.265
18.35,122.18,0.265
18.37,122.36,0.265
18.39,122.54,0.265
18.41,122.73,0.266
18.43,122.91,0.266
18.44,123.10,0.266
18.46,123.28,0.266
18.48,123.46,0.266
18.50,123.65,0.266
18.52,123.83,0.266
18.53,124.01,0.267
18.55,124.20,0.267
18.57,124.38,0.267
18.59,124.56,0.267
18.61,124.75,0.267
18.63,124.93,0.267
18.64,125.11,0.267
18.66,125.30,0.267
18.68,125.48,0.267
18.70,125.66,0.267
18.72,125.85,0.267
18.74,126.03,0.267
18.76,126.21,0.268
18.77,126.40,0.268
18.79,126.58,0.268
18.81,126.77,0.268
18.83,126.95,0.268
18.85,127.13,0.268
18.87,127.32,0.268
18.88,127.50,0.268
18.90,127.68,0.268
18.92,127.87,0.269
18.94,128.05,0.269
18.96,128.23,0.269
18.98,128.42,0.269
18.99,128.60,0.269
19.01,128.78,0.269
19.03,128.97,0.269
19.05,129.15,0.269
19.07,129.33,0.269
19.08,129.52,0.269
19.10,129.70,0.270
19.12,129.88,0.270
19.14,130.07,0.270
19.16,130.25,0.270
19.18,130.43,0.270
19.19,130.62,0.270
19.21,130.80,0.270
19.23,130.98,0.270
19.25,131.17,0.270
19.27,131.35,0.270
19.29,131.54,0.270
19.31,131.72,0.271
19.32,131.90,0.271
19.34,132.08,0.271
19.36,132.27,0.271
19.38,132.45,0.271
19.40,132.64,0.271
19.42,132.82,0.271
19.43,133.00,0.271
19.45,133.19,0.271
19.47,133.37,0.271
19.49,133.55,0.271
19.51,133.74,0.271
19.53,133.92,0.272
19.54,134.10,0.272
19.56,134.29,0.272
19.58,134.47,0.272
19.60,134.65,0.272
19.62,134.84,0.272
19.63,135.02,0.272
19.65,135.21,0.272
19.67,135.39,0.273
19.69,135.57,0.273
19.71,135.75,0.273
19.73,135.94,0.273
19.74,136.12,0.273
19.76,136.31,0.273
19.78,136.49,0.273
19.80,136.67,0.273
19.82,136.86,0.273
19.84,137.04,0.274
19.86,137.22,0.274
19.87,137.41,0.274
19.89,137.59,0.274
19.91,137.77,0.274
19.93,137.96,0.274
19.95,138.14,0.274
19.97,138.32,0.275
19.98,138.51,0.275
20.00,138.69,0.275
20.02,138.87,0.275
20.04,139.06,0.275
20.06,139.24,0.275
20.08,139.42,0.275
20.09,139.61,0.275
20.11,139.79,0.275
20.13,139.97,0.275
20.15,140.16,0.276
20.17,140.34,0.276
20.18,140.52,0.276
20.20,140.71,0.276
20.22,140.89,0.276
20.24,141.08,0.276
20.26,141.26,0.277
20.28,141.44,0.277
20.29,141.63,0.277
20.31,141.81,0.277
20.33,141.99,0.277
20.35,142.18,0.278
20.37,142.36,0.278
20.39,142.54,0.278
20.41,142.73,0.278
20.42,142.91,0.278
20.44,143.09,0.278
20.46,143.28,0.279
20.48,143.46,0.279
20.50,143.64,0.279
20.52,143.83,0.280
20.53,144.01,0.280
20.55,144.19,0.280
20.57,144.38,0.280
20.59,144.56,0.281
20.61,144.74,0.281
20.63,144.93,0.281
20.64,145.11,0.282
20.66,145.29,0.282
20.68,145.48,0.282
20.70,145.66,0.283
20.72,145.84,0.283
20.73,146.03,0.284
20.75,146.21,0.284
20.77,146.39,0.285
20.79,146.58,0.285
20.81,146.76,0.285
20.83,146.94,0.286
20.84,147.13,0.286
20.86,147.31,0.287
20.88,147.49,0.287
20.90,147.68,0.288
20.92,147.86,0.288
20.94,148.04,0.289
20.96,148.23,0.289
20.97,148.41,0.290
20.99,148.59,0.290
21.01,148.77,0.291
21.03,148.96,0.291
21.05,149.14,0.292
21.07,149.33,0.293
21.08,149.51,0.293
21.10,149.69,0.294
21.12,149.88,0.294
21.14,150.06,0.295
21.16,150.24,0.296
21.18,150.43,0.296
21.19,150.61,0.297
21.21,150.79,0.298
21.23,150.98,0.298
21.25,151.16,0.299
21.27,151.34,0.299
21.28,151.53,0.300
21.30,151.71,0.300
21.32,151.90,0.301
21.34,152.08,0.301
21.36,152.26,0.302
21.38,152.45,0.302
21.39,152.63,0.302
21.41,152.81,0.303
21.43,153.00,0.303
21.45,153.18,0.303
21.47,153.36,0.304
21.49,153.55,0.304
21.51,153.73,0.304
21.52,153.91,0.304
21.54,154.10,0.304
21.56,154.28,0.304
21.58,154.46,0.304
21.60,154.65,0.304
21.62,154.83,0.304
21.63,155.01,0.304
21.65,155.20,0.303
21.67,155.38,0.303
21.69,155.57,0.303
21.71,155.75,0.303
21.73,155.93,0.302
21.74,156.12,0.302
21.76,156.30,0.301
21.78,156.48,0.301
21.80,156.67,0.300
21.82,156.85,0.300
21.83,157.03,0.299
21.85,157.22,0.298
21.87,157.40,0.297
21.89,157.59,0.297
21.91,157.77,0.296
21.93,157.95,0.296
21.94,158.14,0.295
21.96,158.32,0.295
21.98,158.50,0.294
22.00,158.69,0.293
22.02,158.87,0.293
22.04,159.05,0.292
22.06,159.24,0.292
22.07,159.42,0.291
22.09,159.60,0.290
22.11,159.79,0.290
22.13,159.97,0.289
22.15,160.16,0.289
22.17,160.34,0.289
22.18,160.52,0.288
22.20,160.71,0.288
22.22,160.89,0.287
22.24,161.07,0.287
22.26,161.26,0.287
22.28,161.44,0.286
22.29,161.62,0.286
22.31,161.81,0.286
22.33,161.99,0.286
22.35,162.17,0.285
22.37,162.36,0.285
22.38,162.54,0.285
22.40,162.72,0.285
22.42,162.91,0.285
22.44,163.09,0.284
22.46,163.27,0.284
22.48,163.46,0.284
22.49,163.64,0.284
22.51,163.82,0.284
22.53,164.01,0.284
22.55,164.19,0.284
22.57,164.38,0.284
22.59,164.56,0.284
22.61,164.74,0.284
22.62,164.93,0.284
22.64,165.11,0.284
22.66,165.29,0.284
22.68,165.48,0.284
22.70,165.66,0.284
22.72,165.84,0.284
22.73,166.03,0.284
22.75,166.21,0.285
22.77,166.39,0.285
22.79,166.58,0.285
22.81,166.76,0.285
22.83,166.94,0.285
22.84,167.13,0.285
22.86,167.31,0.285
22.88,167.49,0.285
22.90,167.68,0.285
22.92,167.86,0.285
22.93,168.04,0.286
22.95,168.23,0.286
22.97,168.41,0.286
22.99,168.60,0.286
23.01,168.78,0.286
23.03,168.96,0.286
23.04,169.14,0.287
23.06,169.33,0.287
23.08,169.51,0.287
23.10,169.69,0.287
23.12,169.88,0.287
23.14,170.06,0.288
23.16,170.25,0.288
23.17,170.43,0.288
23.19,170.61,0.289
23.21,170.80,0.289
23.23,170.98,0.289
23.25,171.16,0.289
23.27,171.35,0.290
23.28,171.53,0.290
23.30,171.71,0.291
23.32,171.90,0.291
23.34,172.08,0.292
23.36,172.26,0.292
23.38,172.45,0.292
23.39,172.63,0.293
23.41,172.81,0.293
23.43,173.00,0.294
23.45,173.18,0.294
23.47,173.36,0.294
23.48,173.55,0.295
23.50,173.73,0.295
23.52,173.91,0.296
23.54,174.10,0.296
23.56,174.28,0.297
23.58,174.46,0.298
23.59,174.64,0.298
23.61,174.83,0.299
23.63,175.01,0.300
23.65,175.19,0.301
23.67,175.38,0.302
23.69,175.56,0.304
23.71,175.75,0.305
23.72,175.93,0.306
23.74,176.11,0.307
23.76,176.29,0.310
23.78,176.48,0.311
23.80,176.66,0.313
23.82,176.84,0.314
23.83,177.03,0.315
23.85,177.21,0.320
23.87,177.39,0.322
23.89,177.58,0.324
23.91,177.76,0.327
23.93,177.94,0.330
23.94,178.12,0.334
23.96,178.31,0.337
23.98,178.49,0.341
24.00,178.67,0.344
24.02,178.86,0.348
24.03,179.04,0.354
24.05,179.22,0.360
24.07,179.40,0.368
24.09,179.59,0.372
24.11,179.77,0.379
24.13,179.95,0.387
24.14,180.13,0.395
24.16,180.31,0.406
24.18,180.50,0.415
24.20,180.68,0.428
24.22,180.86,0.442
24.24,181.04,0.459
24.26,181.22,0.475
24.27,181.40,0.494
24.29,181.58,0.517
24.31,181.76,0.542
24.33,181.94,0.572
24.35,182.11,0.605
24.37,182.29,0.643
24.38,182.47,0.685
24.40,182.64,0.734
24.42,182.82,0.787
24.44,182.99,0.850
24.46,183.16,0.917
24.48,183.33,0.991
24.49,183.50,1.076
24.51,183.67,1.166
24.53,183.83,1.268
24.55,184.00,1.380
24.57,184.16,1.504
24.58,184.32,1.648
24.60,184.47,1.801
24.62,184.62,1.979
24.64,184.77,2.140
24.66,184.92,2.338
24.68,185.07,2.539
24.69,185.21,2.750
24.71,185.35,2.980
24.73,185.48,3.196
24.75,185.62,3.362
24.77,185.76,3.547
24.79,185.90,3.766
24.81,186.04,3.961
24.82,186.18,4.106
24.84,186.33,4.249
24.86,186.47,4.314
24.88,186.63,4.471
24.90,186.78,4.602
24.92,186.93,4.843
24.93,187.07,5.018
24.95,187.21,5.300
24.97,187.35,5.481
24.99,187.49,5.703
25.01,187.62,5.923
25.03,187.75,6.521
25.04,187.82,7.576
25.06,187.88,7.993
25.08,187.96,8.228
25.10,188.06,8.371
25.12,188.17,8.568
25.13,188.28,9.180
25.15,188.34,10.271
25.17,188.40,10.507
25.19,188.49,10.569
25.21,188.62,10.236
25.23,188.84,8.628
25.24,189.17,6.868
25.26,189.57,5.362
25.28,190.00,4.115
25.30,190.41,3.294
25.32,190.80,2.793
25.34,191.16,2.425
25.36,191.49,2.128
25.37,191.79,1.882
25.39,192.07,1.677
25.41,192.33,1.508
25.43,192.58,1.365
25.45,192.82,1.245
25.47,193.05,1.150
25.48,193.27,1.064
25.50,193.49,0.996
25.52,193.70,0.935
25.54,193.91,0.887
25.56,194.11,0.845
25.58,194.31,0.808
25.59,194.50,0.777
25.61,194.70,0.753
25.63,194.89,0.730
25.65,195.08,0.710
25.67,195.27,0.693
25.68,195.46,0.678
25.70,195.65,0.663
25.72,195.84,0.651
25.74,196.02,0.639
25.76,196.21,0.629
25.78,196.40,0.621
25.79,196.58,0.616
25.81,196.77,0.605
25.83,196.96,0.595
25.85,197.14,0.590
25.87,197.33,0.584
25.89,197.51,0.577
25.91,197.70,0.571
25.92,197.88,0.564
25.94,198.07,
25.96,198.25,
25.98,198.44,
25.99,,

[step]
Ramp 10.00 °C/min to -60.00 °C
Time,Temperature,Heat Flow (Normalized)
min,°C,W/g
27.99,200.13,-0.128
28.01,200.13,-0.128
28.03,200.12,-0.128
28.05,200.11,-0.128
28.07,200.09,-0.121
28.08,200.04,-0.111
28.10,199.97,-0.109
28.12,199.89,-0.128
28.14,199.78,-0.170
28.16,199.66,-0.216
28.18,199.53,-0.266
28.19,199.38,-0.315
28.21,199.24,-0.359
28.23,199.08,-0.394
28.25,198.93,-0.426
28.27,198.76,-0.452
28.29,198.60,-0.474
28.31,198.43,-0.492
28.32,198.26,-0.507
28.34,198.09,-0.520
28.36,197.92,-0.532
28.38,197.75,-0.543
28.40,197.57,-0.551
28.42,197.40,-0.557
28.43,197.22,-0.565
28.45,197.04,-0.570
28.47,196.86,-0.573
28.49,196.69,-0.578
28.51,196.51,-0.581
28.53,196.33,-0.586
28.54,196.15,-0.586
28.56,195.97,-0.589
28.58,195.79,-0.591
28.60,195.61,-0.592
28.62,195.43,-0.593
28.63,195.25,-0.594
28.65,195.07,-0.595
28.67,194.88,-0.595
28.69,194.70,-0.596
28.71,194.52,-0.597
28.73,194.34,-0.597
28.74,194.16,-0.598
28.76,193.98,-0.598
28.78,193.80,-0.598
28.80,193.62,-0.599
28.82,193.43,-0.599
28.84,193.25,-0.599
28.86,193.07,-0.600
28.87,192.89,-0.600
28.89,192.71,-0.600
28.91,192.52,-0.600
28.93,192.34,-0.601
28.95,192.16,-0.601
28.97,191.98,-0.601
28.98,191.79,-0.601
29.00,191.61,-0.601
29.02,191.43,-0.601
29.04,191.24,-0.601
29.06,191.06,-0.601
29.08,190.88,-0.601
29.09,190.70,-0.601
29.11,190.52,-0.600
29.13,190.33,-0.600
29.15,190.15,-0.600
29.17,189.97,-0.599
29.18,189.79,-0.599
29.20,189.60,-0.599
29.22,189.42,-0.599
29.24,189.24,-0.598
29.26,189.05,-0.598
29.28,188.87,-0.597
29.29,188.69,-0.597
29.31,188.51,-0.597
29.33,188.32,-0.596
29.35,188.14,-0.595
29.37,187.96,-0.595
29.39,187.78,-0.594
29.41,187.59,-0.594
29.42,187.41,-0.593
29.44,187.23,-0.593
29.46,187.04,-0.592
29.48,186.86,-0.591
29.50,186.68,-0.591
29.52,186.49,-0.590
29.53,186.31,-0.589
29.55,186.13,-0.589
29.57,185.94,-0.588
29.59,185.76,-0.588
29.61,185.58,-0.587
29.63,185.40,-0.587
29.64,185.21,-0.586
29.66,185.03,-0.585
29.68,184.85,-0.584
29.70,184.66,-0.584
29.72,184.48,-0.583
29.73,184.30,-0.583
29.75,184.11,-0.582
29.77,183.93,-0.581
29.79,183.75,-0.581
29.81,183.56,-0.580
29.83,183.38,-0.579
29.84,183.20,-0.578
29.86,183.01,-0.578
29.88,182.83,-0.577
29.90,182.65,-0.577
29.92,182.47,-0.576
29.94,182.28,-0.575
29.96,182.10,-0.575
29.97,181.92,-0.574
29.99,181.73,-0.573
30.01,181.55,-0.572
30.03,181.37,-0.571
30.05,181.18,-0.570
30.07,181.00,-0.569
30.08,180.82,-0.569
30.10,180.63,-0.568
30.12,180.45,-0.568
30.14,180.27,-0.567
30.16,180.08,-0.566
30.18,179.90,-0.566
30.19,179.72,-0.565
30.21,179.53,-0.565
30.23,179.35,-0.563
30.25,179.17,-0.563
30.27,178.98,-0.562
30.28,178.80,-0.561
30.30,178.62,-0.561
30.32,178.43,-0.561
30.34,178.25,-0.560
30.36,178.07,-0.560
30.38,177.89,-0.559
30.39,177.70,-0.558
30.41,177.52,-0.558
30.43,177.34,-0.557
30.45,177.15,-0.556
30.47,176.97,-0.556
30.49,176.79,-0.555
30.51,176.60,-0.554
30.52,176.42,-0.554
30.54,176.24,-0.553
30.56,176.05,-0.552
30.58,175.87,-0.552
30.60,175.69,-0.551
30.62,175.50,-0.551
30.63,175.32,-0.550
30.65,175.14,-0.550
30.67,174.95,-0.549
30.69,174.77,-0.549
30.71,174.59,-0.547
30.73,174.40,-0.547
30.74,174.22,-0.546
30.76,174.04,-0.546
30.78,173.85,-0.545
30.80,173.67,-0.545
30.82,173.49,-0.544
30.83,173.31,-0.543
30.85,173.12,-0.543
30.87,172.94,-0.542
30.89,172.76,-0.542
30.91,172.57,-0.541
30.93,172.39,-0.541
30.94,172.21,-0.540
30.96,172.02,-0.540
30.98,171.84,-0.539
31.00,171.66,-0.539
31.02,171.47,-0.539
31.04,171.29,-0.538
31.06,171.11,-0.538
31.07,170.92,-0.537
31.09,170.74,-0.536
31.11,170.56,-0.535
31.13,170.37,-0.534
31.15,170.19,-0.534
31.17,170.01,-0.533
31.18,169.82,-0.533
31.20,169.64,-0.533
31.22,169.46,-0.532
31.24,169.27,-0.532
31.26,169.09,-0.532
31.28,168.91,-0.531
31.29,168.72,-0.531
31.31,168.54,-0.530
31.33,168.36,-0.530
31.35,168.17,-0.530
31.37,167.99,-0.529
31.38,167.81,-0.529
31.40,167.63,-0.528
31.42,167.44,-0.528
31.44,167.26,-0.527
31.46,167.08,-0.527
31.48,166.89,-0.526
31.49,166.71,-0.526
31.51,166.53,-0.525
31.53,166.34,-0.988
31.55,167.33,-49.908
31.57,170.00,-38.544
31.59,170.29,-21.073
31.61,169.90,-14.126
31.62,169.32,-10.925
31.64,168.72,-9.174
31.66,168.14,-7.939
31.68,167.60,-6.964
31.70,167.10,-6.160
31.72,166.63,-5.480
31.73,166.20,-4.903
31.75,165.79,-4.413
31.77,165.42,-3.986
31.79,165.07,-3.626
31.81,164.74,-3.313
31.83,164.43,-3.047
31.84,164.13,-2.820
31.86,163.86,-2.620
31.88,163.59,-2.446
31.90,163.34,-2.296
31.92,163.09,-2.166
31.93,162.85,-2.045
31.95,162.62,-1.939
31.97,162.40,-1.833
31.99,162.18,-1.740
32.01,161.96,-1.656
32.03,161.75,-1.576
32.04,161.54,-1.499
32.06,161.33,-1.435
32.08,161.13,-1.370
32.10,160.92,-1.307
32.12,160.72,-1.253
32.14,160.52,-1.203
32.16,160.32,-1.155
32.17,160.12,-1.115
32.19,159.93,-1.073
32.21,159.73,-1.038
32.23,159.54,-1.002
32.25,159.34,-0.970
32.27,159.15,-0.943
32.28,158.96,-0.911
32.30,158.77,-0.886
32.32,158.58,-0.863
32.34,158.38,-0.839
32.36,158.20,-0.820
32.38,158.01,-0.798
32.39,157.82,-0.779
32.41,157.63,-0.762
32.43,157.44,-0.743
32.45,157.25,-0.729
32.47,157.07,-0.713
32.48,156.88,-0.701
32.50,156.69,-0.686
32.52,156.50,-0.672
32.54,156.32,-0.663
32.56,156.13,-0.653
32.58,155.95,-0.638
32.59,155.76,-0.632
32.61,155.57,-0.619
32.63,155.39,-0.612
32.65,155.20,-0.601
32.67,155.02,-0.595
32.69,154.83,-0.589
32.71,154.65,-0.581
32.72,154.46,-0.576
32.74,154.27,-0.566
32.76,154.09,-0.563
32.78,153.91,-0.557
32.80,153.72,-0.553
32.82,153.54,-0.549
32.83,153.35,-0.542
32.85,153.17,-0.537
32.87,152.98,-0.535
32.89,152.80,-0.530
32.91,152.62,-0.528
32.93,152.43,-0.521
32.94,152.25,-0.519
32.96,152.06,-0.516
32.98,151.88,-0.512
33.00,151.69,-0.508
33.02,151.51,-0.507
33.03,151.33,-0.505
33.05,151.14,-0.504
33.07,150.96,-0.502
33.09,150.77,-0.499
33.11,150.59,-0.498
33.13,150.41,-0.498
33.14,150.22,-0.498
33.16,150.04,-0.495
33.18,149.86,-0.495
33.20,149.67,-0.494
33.22,149.49,-0.492
33.24,149.31,-0.489
33.26,149.12,-0.488
33.27,148.94,-0.484
33.29,148.76,-0.483
33.31,148.57,-0.482
33.33,148.39,-0.476
33.35,148.21,-0.472
33.37,148.02,-0.469
33.38,147.84,-0.467
33.40,147.65,-0.467
33.42,147.47,-0.466
33.44,147.29,-0.465
33.46,147.10,-0.465
33.48,146.92,-0.465
33.49,146.74,-0.483
33.51,146.56,-0.487
33.53,146.37,-0.481
33.55,146.19,-0.464
33.57,146.01,-0.464
33.58,145.82,-0.460
33.60,145.64,-0.458
33.62,145.45,-0.456
33.64,145.27,-0.448
33.66,145.09,-0.442
33.68,144.90,-0.439
33.69,144.72,-0.437
33.71,144.53,-0.434
33.73,144.35,-0.433
33.75,144.17,-0.430
33.77,143.98,-0.429
33.79,143.80,-0.427
33.81,143.62,-0.426
33.82,143.43,-0.425
33.84,143.25,-0.423
33.86,143.06,-0.422
33.88,142.88,-0.421
33.90,142.70,-0.420
33.92,142.51,-0.419
33.93,142.33,-0.417
33.95,142.15,-0.417
33.97,141.96,-0.416
33.99,141.78,-0.415
34.01,141.60,-0.414
34.03,141.41,-0.414
34.04,141.23,-0.412
34.06,141.05,-0.412
34.08,140.86,-0.411
34.10,140.68,-0.410
34.12,140.50,-0.409
34.14,140.31,-0.409
34.15,140.13,-0.408
34.17,139.95,-0.407
34.19,139.76,-0.406
34.21,139.58,-0.406
34.23,139.40,-0.405
34.24,139.21,-0.405
34.26,139.03,-0.403
34.28,138.85,-0.402
34.30,138.66,-0.401
34.32,138.48,-0.401
34.34,138.30,-0.400
34.36,138.11,-0.399
34.37,137.93,-0.399
34.39,137.75,-0.398
34.41,137.57,-0.398
34.43,137.38,-0.397
34.45,137.20,-0.397
34.46,137.02,-0.396
34.48,136.83,-0.396
34.50,136.65,-0.395
34.52,136.47,-0.394
34.54,136.28,-0.393
34.56,136.10,-0.393
34.58,135.92,-0.392
34.59,135.73,-0.392
34.61,135.55,-0.391
34.63,135.37,-0.391
34.65,135.18,-0.390
34.67,135.00,-0.390
34.69,134.82,-0.389
34.70,134.63,-0.389
34.72,134.45,-0.388
34.74,134.27,-0.388
34.76,134.08,-0.388
34.78,133.90,-0.387
34.79,133.72,-0.386
34.81,133.53,-0.386
34.83,133.35,-0.386
34.85,133.17,-0.385
34.87,132.99,-0.385
34.89,132.80,-0.384
34.91,132.62,-0.384
34.92,132.43,-0.384
34.94,132.25,-0.383
34.96,132.07,-0.383
34.98,131.88,-0.382
35.00,131.70,-0.382
35.01,131.52,-0.382
35.03,131.34,-0.381
35.05,131.15,-0.381
35.07,130.97,-0.380
35.09,130.78,-0.380
35.11,130.60,-0.380
35.13,130.42,-0.379
35.14,130.23,-0.379
35.16,130.05,-0.378
35.18,129.87,-0.378
[...]
114.08,-40.87,0.170
114.08,-40.80,0.170
114.09,-40.74,0.170
114.10,-40.67,0.170
114.10,-40.60,0.170
114.11,-40.53,0.170
114.11,-40.47,0.170
114.12,-40.40,0.170
114.13,-40.33,0.170
114.14,-40.27,0.170
114.14,-40.20,0.171
114.15,-40.14,0.171
114.15,-40.07,0.171
114.16,-40.00,0.171
114.17,-39.94,0.171
114.18,-39.87,0.171
114.18,-39.80,0.171
114.19,-39.74,0.171
114.20,-39.67,0.171
114.20,-39.60,0.171
114.21,-39.53,0.171
114.21,-39.47,0.171
114.22,-39.40,0.171
114.23,-39.34,0.171
114.24,-39.27,0.171
114.24,-39.20,0.171
114.25,-39.13,0.171
114.25,-39.07,0.171
114.26,-39.00,0.171
114.27,-38.93,0.171
114.28,-38.87,0.171
114.28,-38.80,0.171
114.29,-38.73,0.171
114.30,-38.67,0.171
114.30,-38.60,0.171
114.31,-38.53,0.171
114.31,-38.47,0.171
114.32,-38.40,0.171
114.33,-38.33,0.171
114.34,-38.27,0.171
114.34,-38.20,0.171
114.35,-38.13,0.171
114.35,-38.07,0.171
114.36,-38.00,0.171
114.37,-37.93,0.171
114.38,-37.87,0.171
114.38,-37.80,0.171
114.39,-37.73,0.171
114.40,-37.67,0.171
114.40,-37.60,0.171
114.41,-37.53,0.171
114.41,-37.46,0.171
114.42,-37.40,0.171
114.43,-37.33,0.171
114.44,-37.26,0.171
114.44,-37.20,0.171
114.45,-37.13,0.171
114.45,-37.06,0.171
114.46,-37.00,0.172
114.47,-36.93,0.172
114.48,-36.86,0.172
114.48,-36.80,0.172
114.49,-36.73,0.172
114.50,-36.66,0.172
114.50,-36.60,0.172
114.51,-36.53,0.172
114.51,-36.46,0.172
114.52,-36.40,0.172
114.53,-36.33,0.172
114.54,-36.26,0.172
114.54,-36.20,0.172
114.55,-36.13,0.172
114.55,-36.06,0.172
114.56,-36.00,0.172
114.57,-35.93,0.172
114.58,-35.86,0.172
114.58,-35.80,0.172
114.59,-35.73,0.172
114.60,-35.66,0.172
114.60,-35.60,0.172
114.61,-35.53,0.172
114.61,-35.46,0.172
114.62,-35.40,0.172
114.63,-35.33,0.172
114.64,-35.26,0.172
114.64,-35.20,0.172
114.65,-35.13,0.172
114.65,-35.06,0.172
114.66,-35.00,0.172
114.67,-34.93,0.172
114.68,-34.86,0.172
114.68,-34.79,0.172
114.69,-34.73,0.172
114.70,-34.66,0.172
114.70,-34.60,0.172
114.71,-34.53,0.172
114.71,-34.46,0.172
114.72,-34.39,0.172
114.73,-34.33,0.172
114.74,-34.26,0.172
114.74,-34.19,0.172
114.75,-34.13,0.172
114.75,-34.06,0.172
114.76,-33.99,0.173
114.77,-33.93,0.173
114.78,-33.86,0.173
114.78,-33.79,0.173
114.79,-33.73,0.173
114.80,-33.66,0.173
114.80,-33.59,0.173
114.81,-33.53,0.173
114.81,-33.46,0.173
114.82,-33.39,0.173
114.83,-33.33,0.173
114.84,-33.26,0.173
114.84,-33.19,0.173
114.85,-33.13,0.173
114.85,-33.06,0.173
114.86,-32.99,0.173
114.87,-32.93,0.173
114.88,-32.86,0.173
114.88,-32.79,0.173
114.89,-32.72,0.173
114.90,-32.66,0.173
114.90,-32.59,0.173
114.91,-32.53,0.173
114.91,-32.46,0.173
114.92,-32.39,0.173
114.93,-32.32,0.173
114.94,-32.26,0.173
114.94,-32.19,0.173
114.95,-32.12,0.173
114.95,-32.06,0.173
114.96,-31.99,0.173
114.97,-31.92,0.173
114.98,-31.85,0.173
114.98,-31.79,0.173
114.99,-31.72,0.173
115.00,-31.65,0.173
115.00,-31.59,0.173
115.01,-31.52,0.173
115.01,-31.45,0.174
115.02,-31.39,0.174
115.03,-31.32,0.174
115.04,-31.25,0.174
115.04,-31.19,0.174
115.05,-31.12,0.174
115.05,-31.05,0.174
115.06,-30.99,0.174
115.07,-30.92,0.174
115.08,-30.85,0.174
115.08,-30.79,0.174
115.09,-30.72,0.174
115.10,-30.65,0.174
115.10,-30.59,0.174
115.11,-30.52,0.174
115.11,-30.45,0.174
115.12,-30.39,0.174
115.13,-30.32,0.174
115.14,-30.25,0.174
115.14,-30.19,0.174
115.15,-30.12,0.174
115.15,-30.05,0.174
115.16,-29.99,0.174
115.17,-29.92,0.174
115.18,-29.85,0.174
115.18,-29.79,0.174
115.19,-29.72,0.174
115.20,-29.65,0.174
115.20,-29.59,0.174
115.21,-29.52,0.174
115.21,-29.45,0.174
115.22,-29.39,0.174
115.23,-29.32,0.174
115.24,-29.25,0.174
115.24,-29.19,0.174
115.25,-29.12,0.174
115.25,-29.05,0.174
115.26,-28.98,0.174
115.27,-28.92,0.174
115.28,-28.85,0.174
115.28,-28.78,0.174
115.29,-28.72,0.174
115.30,-28.65,0.175
115.30,-28.58,0.175
115.31,-28.52,0.175
115.31,-28.45,0.175
115.32,-28.38,0.175
115.33,-28.32,0.175
115.34,-28.25,0.175
115.34,-28.18,0.175
115.35,-28.12,0.175
115.35,-28.05,0.175
115.36,-27.98,0.175
115.37,-27.92,0.175
115.38,-27.85,0.175
115.38,-27.78,0.175
115.39,-27.72,0.175
115.40,-27.65,0.175
115.40,-27.58,0.175
115.41,-27.52,0.175
115.41,-27.45,0.175
115.42,-27.38,0.175
115.43,-27.32,0.175
115.44,-27.25,0.175
115.44,-27.18,0.175
115.45,-27.12,0.175
115.45,-27.05,0.175
115.46,-26.98,0.175
115.47,-26.92,0.175
115.48,-26.85,0.175
115.48,-26.78,0.175
115.49,-26.72,0.175
115.50,-26.65,0.175
115.50,-26.58,0.175
115.51,-26.52,0.175
115.51,-26.45,0.175
115.52,-26.38,0.175
115.53,-26.32,0.175
115.54,-26.25,0.175
115.54,-26.18,0.175
115.55,-26.12,0.175
115.55,-26.05,0.175
115.56,-25.98,0.176
115.57,-25.92,0.175
115.58,-25.85,0.175
115.58,-25.78,0.176
115.59,-25.72,0.176
115.60,-25.65,0.176
115.60,-25.58,0.176
115.61,-25.52,0.176
115.61,-25.45,0.176
115.62,-25.38,0.176
115.63,-25.31,0.176
115.64,-25.25,0.176
115.64,-25.18,0.176
115.65,-25.11,0.176
115.65,-25.05,0.176
115.66,-24.98,0.176
115.67,-24.91,0.176
115.68,-24.85,0.176
115.68,-24.78,0.176
115.69,-24.71,0.176
115.70,-24.65,0.176
115.70,-24.58,0.176
115.71,-24.51,0.176
115.71,-24.45,0.176
115.72,-24.38,0.176
115.73,-24.31,0.176
115.74,-24.25,0.176
115.74,-24.18,0.176
115.75,-24.11,0.176
115.75,-24.05,0.176
115.76,-23.98,0.176
115.77,-23.91,0.176
115.78,-23.85,0.176
115.78,-23.78,0.176
115.79,-23.71,0.176
115.80,-23.64,0.176
115.80,-23.58,0.176
115.81,-23.51,0.177
115.81,-23.45,0.176
115.82,-23.38,0.177
115.83,-23.31,0.177
115.84,-23.25,0.177
115.84,-23.18,0.177
115.85,-23.11,0.177
115.85,-23.04,0.177
115.86,-22.98,0.177
115.87,-22.91,0.177
115.88,-22.84,0.177
115.88,-22.78,0.177
115.89,-22.71,0.177
115.90,-22.64,0.177
115.90,-22.58,0.177
115.91,-22.51,0.177
115.91,-22.45,0.177
115.92,-22.38,0.177
115.93,-22.31,0.177
115.94,-22.24,0.177
115.94,-22.18,0.177
115.95,-22.11,0.177
115.95,-22.04,0.177
115.96,-21.98,0.177
115.97,-21.91,0.177
115.98,-21.84,0.177
115.98,-21.78,0.177
115.99,-21.71,0.177
116.00,-21.64,0.177
116.00,-21.58,0.178
116.01,-21.51,0.178
116.01,-21.44,0.178
116.02,-21.38,0.178
116.03,-21.31,0.178
116.04,-21.24,0.178
116.04,-21.18,0.178
116.05,-21.11,0.178
116.05,-21.04,0.178
116.06,-20.98,0.178
116.07,-20.91,0.178
116.08,-20.84,0.178
116.08,-20.78,0.178
116.09,-20.71,0.178
116.10,-20.64,0.178
116.10,-20.58,0.178
116.11,-20.51,0.178
116.11,-20.44,0.178
116.12,-20.37,0.178
116.13,-20.31,0.178
116.14,-20.24,0.178
116.14,-20.18,0.178
116.15,-20.11,0.178
116.15,-20.04,0.178
116.16,-19.98,0.178
116.17,-19.91,0.178
116.18,-19.84,0.178
116.18,-19.77,0.178
116.19,-19.71,0.178
116.20,-19.64,0.178
116.20,-19.57,0.178
116.21,-19.51,0.178
116.21,-19.44,0.178
116.22,-19.37,0.178
116.23,-19.31,0.178
116.24,-19.24,0.179
116.24,-19.17,0.179
116.25,-19.11,0.179
116.25,-19.04,0.179
116.26,-18.97,0.179
116.27,-18.91,0.179
116.28,-18.84,0.179
116.28,-18.77,0.179
116.29,-18.71,0.179
116.30,-18.64,0.179
116.30,-18.58,0.179
116.31,-18.51,0.179
116.31,-18.44,0.179
116.32,-18.37,0.179
116.33,-18.31,0.179
116.34,-18.24,0.179
116.34,-18.17,0.179
116.35,-18.11,0.179
116.35,-18.04,0.179
116.36,-17.97,0.179
116.37,-17.91,0.180
116.38,-17.84,0.180
116.38,-17.77,0.180
116.39,-17.71,0.180
116.40,-17.64,0.180
116.40,-17.57,0.180
116.41,-17.51,0.180
116.41,-17.44,0.180
116.42,-17.37,0.180
116.43,-17.31,0.180
116.44,-17.24,0.180
116.44,-17.17,0.180
116.45,-17.10,0.180
116.45,-17.04,0.180
116.46,-16.97,0.180
116.47,-16.91,0.180
116.48,-16.84,0.180
116.48,-16.77,0.180
116.49,-16.70,0.180
116.50,-16.64,0.180
116.50,-16.57,0.180
116.51,-16.50,0.180
116.51,-16.44,0.180
116.52,-16.37,0.180
116.53,-16.30,0.180
116.54,-16.24,0.181
116.54,-16.17,0.181
116.55,-16.10,0.181
116.55,-16.04,0.181
116.56,-15.97,0.181
116.57,-15.90,0.181
116.58,-15.84,0.181
116.58,-15.77,0.181
116.59,-15.70,0.181
116.60,-15.64,0.181
116.60,-15.57,0.181
116.61,-15.50,0.181
116.61,-15.44,0.181
116.62,-15.37,0.181
116.63,-15.30,0.181
116.64,-15.24,0.181
116.64,-15.17,0.181
116.65,-15.10,0.181
116.65,-15.04,0.181
116.66,-14.97,0.182
116.67,-14.90,0.182
116.68,-14.84,0.182
116.68,-14.77,0.182
116.69,-14.70,0.182
116.70,-14.64,0.182
116.70,-14.57,0.182
116.71,-14.50,0.182
116.71,-14.43,0.182
116.72,-14.37,0.182
116.73,-14.30,0.182
116.74,-14.24,0.182
116.74,-14.17,0.182
116.75,-14.10,0.182
116.75,-14.04,0.182
116.76,-13.97,0.183
116.77,-13.90,0.183
116.78,-13.83,0.183
116.78,-13.77,0.183
116.79,-13.70,0.183
116.80,-13.64,0.183
116.80,-13.57,0.183
116.81,-13.50,0.183
116.81,-13.43,0.183
116.82,-13.37,0.183
116.83,-13.30,0.183
116.84,-13.23,0.183
116.84,-13.17,0.183
116.85,-13.10,0.183
116.85,-13.03,0.183
116.86,-12.97,0.183
116.87,-12.90,0.184
116.88,-12.83,0.184
116.88,-12.77,0.184
116.89,-12.70,0.184
116.90,-12.63,0.184
116.90,-12.57,0.184
116.91,-12.50,0.184
116.91,-12.43,0.184
116.92,-12.37,0.184
116.93,-12.30,0.184
116.94,-12.23,0.184
116.94,-12.17,0.185
116.95,-12.10,0.185
116.95,-12.03,0.185
116.96,-11.97,0.185
116.97,-11.90,0.185
116.98,-11.83,0.185
116.98,-11.77,0.185
116.99,-11.70,0.185
117.00,-11.63,0.185
117.00,-11.57,0.186
117.01,-11.50,0.186
117.01,-11.43,0.186
117.02,-11.37,0.186
117.03,-11.30,0.186
117.04,-11.23,0.186
117.04,-11.17,0.186
117.05,-11.10,0.186
117.05,-11.03,0.186
117.06,-10.97,0.186
117.07,-10.90,0.186
117.08,-10.83,0.186
117.08,-10.77,0.187
117.09,-10.70,0.187
117.10,-10.63,0.187
117.10,-10.56,0.187
117.11,-10.50,0.187
117.11,-10.43,0.187
117.12,-10.37,0.188
117.13,-10.30,0.188
117.14,-10.23,0.188
117.14,-10.16,0.188
117.15,-10.10,0.188
117.15,-10.03,0.188
117.16,-9.96,0.188
117.17,-9.90,0.188
117.18,-9.83,0.189
117.18,-9.76,0.189
117.19,-9.70,0.189
117.20,-9.63,0.189
117.20,-9.56,0.189
117.21,-9.50,0.189
117.21,-9.43,0.189
117.22,-9.36,0.190
117.23,-9.30,0.190
117.24,-9.23,0.190
117.24,-9.16,0.190
117.25,-9.10,0.190
117.25,-9.03,0.190
117.26,-8.96,0.190
117.27,-8.90,0.191
117.28,-8.83,0.191
117.28,-8.77,0.191
117.29,-8.70,0.191
117.30,-8.63,0.191
117.30,-8.56,0.191
117.31,-8.50,0.191
117.31,-8.43,0.191
117.32,-8.36,0.192
117.33,-8.30,0.192
117.34,-8.23,0.192
117.34,-8.16,0.192
117.35,-8.10,0.192
117.35,-8.03,0.192
117.36,-7.96,0.193
117.37,-7.90,0.193
117.38,-7.83,0.193
117.38,-7.76,0.193
117.39,-7.70,0.193
117.40,-7.63,0.194
117.40,-7.56,0.194
117.41,-7.50,0.194
117.41,-7.43,0.194
117.42,-7.36,0.195
117.43,-7.30,0.195
117.44,-7.23,0.195
117.44,-7.16,0.195
117.45,-7.10,0.195
117.45,-7.03,0.196
117.46,-6.96,0.196
117.47,-6.90,0.196
117.48,-6.83,0.196
117.48,-6.76,0.196
117.49,-6.70,0.197
117.50,-6.63,0.197
117.50,-6.56,0.198
117.51,-6.50,0.198
117.51,-6.43,0.198
117.52,-6.36,0.198
117.53,-6.30,0.198
117.54,-6.23,0.199
117.54,-6.16,0.199
117.55,-6.10,0.199
117.55,-6.03,0.199
117.56,-5.96,0.199
117.57,-5.90,0.199
117.58,-5.83,0.199
117.58,-5.76,0.199
117.59,-5.70,0.200
117.60,-5.63,0.200
117.60,-5.56,0.200
117.61,-5.49,0.200
117.61,-5.43,0.200
117.62,-5.36,0.200
117.63,-5.30,0.200
117.64,-5.23,0.200
117.64,-5.16,0.200
117.65,-5.10,0.200
117.65,-5.03,0.201
117.66,-4.96,0.201
117.67,-4.90,0.201
117.68,-4.83,0.201
117.68,-4.76,0.201
117.69,-4.70,0.201
117.70,-4.63,0.201
117.70,-4.56,0.201
117.71,-4.49,0.201
117.71,-4.43,0.201
117.72,-4.36,0.201
117.73,-4.29,0.201
117.74,-4.23,0.201
117.74,-4.16,0.201
117.75,-4.09,0.201
117.75,-4.03,0.201
117.76,-3.96,0.201
117.77,-3.89,0.201
117.78,-3.83,0.200
117.78,-3.76,0.200
117.79,-3.69,0.200
117.80,-3.63,0.200
117.80,-3.56,0.200
117.81,-3.49,0.200
117.81,-3.43,0.200
117.82,-3.36,0.200
117.83,-3.29,0.199
117.84,-3.23,0.199
117.84,-3.16,0.199
117.85,-3.09,0.199
117.85,-3.02,0.199
117.86,-2.96,0.199
117.87,-2.89,0.199
117.88,-2.82,0.199
117.88,-2.76,0.199
117.89,-2.69,0.199
117.90,-2.62,0.199
117.90,-2.56,0.198
117.91,-2.49,0.198
117.91,-2.42,0.198
117.92,-2.36,0.198
117.93,-2.29,0.198
117.94,-2.22,0.198
117.94,-2.16,0.198
117.95,-2.09,0.198
117.95,-2.02,0.198
117.96,-1.96,0.198
117.97,-1.89,0.198
117.98,-1.82,0.198
117.98,-1.75,0.198
117.99,-1.69,0.198
118.00,-1.62,0.198
118.00,-1.56,0.198
118.01,-1.49,0.198
118.01,-1.42,0.198
118.02,-1.35,0.198
118.03,-1.29,0.198
118.04,-1.22,0.198
118.04,-1.15,0.198
118.05,-1.09,0.198
118.05,-1.02,0.198
118.06,-0.95,0.198
118.07,-0.89,0.198
118.08,-0.82,0.198
118.08,-0.75,0.198
118.09,-0.69,0.198
118.10,-0.62,0.198
118.10,-0.55,0.198
118.11,-0.49,0.198
118.11,-0.42,0.198
118.12,-0.35,0.198
118.13,-0.29,0.198
118.14,-0.22,0.198
118.14,-0.15,0.198
118.15,-0.09,0.198
118.15,-0.02,0.198
118.16,0.05,0.198
118.17,0.11,0.198
118.18,0.18,0.198
118.18,0.25,0.198
118.19,0.31,0.198
118.20,0.38,0.198
118.20,0.45,0.198
118.21,0.52,0.198
118.21,0.58,0.198
118.22,0.65,0.198
118.23,0.72,0.198
118.24,0.78,0.198
118.24,0.85,0.198
118.25,0.92,0.198
118.25,0.98,0.198
118.26,1.05,0.198
118.27,1.12,0.197
118.28,1.18,0.198
118.28,1.25,0.198
118.29,1.32,0.198
118.30,1.38,0.198
118.30,1.45,0.198
118.31,1.52,0.198
118.31,1.58,0.198
118.32,1.65,0.198
118.33,1.72,0.198
118.34,1.78,0.198
118.34,1.85,0.198
118.35,1.92,0.198
118.35,1.98,0.198
118.36,2.05,0.198
118.37,2.12,0.198
118.38,2.18,0.198
118.38,2.25,0.198
118.39,2.32,0.198
118.40,2.38,0.198
118.40,2.45,0.198
118.41,2.52,0.198
118.41,2.59,0.198
118.42,2.65,0.198
118.43,2.72,0.198
118.44,2.78,0.198
118.44,2.85,0.198
118.45,2.92,0.198
118.45,2.98,0.198
118.46,3.05,0.198
118.47,3.12,0.198
118.48,3.19,0.198
118.48,3.25,0.198
118.49,3.32,0.198
118.50,3.39,0.198
118.50,3.45,0.198
118.51,3.52,0.198
118.51,3.59,0.198
118.52,3.65,0.198
118.53,3.72,0.198
118.54,3.79,0.198
118.54,3.85,0.198
118.55,3.92,0.198
118.55,3.99,0.198
118.56,4.05,0.198
118.57,4.12,0.198
118.58,4.19,0.198
118.58,4.25,0.198
118.59,4.32,0.198
118.60,4.39,0.198
118.60,4.45,0.198
118.61,4.52,0.198
118.61,4.59,0.198
118.62,4.65,0.198
118.63,4.72,0.198
118.64,4.79,0.198
118.64,4.85,0.198
118.65,4.92,0.198
118.65,4.99,0.198
118.66,5.05,0.198
118.67,5.12,0.198
118.68,5.19,0.198
118.68,5.25,0.198
118.69,5.32,0.198
118.70,5.39,0.198
118.70,5.45,0.198
118.71,5.52,0.198
118.71,5.59,0.199
118.72,5.65,0.199
118.73,5.72,0.199
118.74,5.79,0.199
118.74,5.86,0.199
118.75,5.92,0.199
118.75,5.99,0.199
118.76,6.06,0.199
118.77,6.12,0.199
118.78,6.19,0.199
118.78,6.26,0.199
118.79,6.32,0.199
118.80,6.39,0.199
118.80,6.46,0.199
118.81,6.52,0.199
118.81,6.59,0.199
118.82,6.66,0.199
118.83,6.72,0.199
118.84,6.79,0.199
118.84,6.86,0.199
118.85,6.92,0.199
118.85,6.99,0.199
118.86,7.06,0.199
118.87,7.12,0.199
118.88,7.19,0.199
118.88,7.26,0.200
118.89,7.32,0.200
118.90,7.39,0.200
118.90,7.46,0.200
118.91,7.52,0.200
118.91,7.59,0.200
118.92,7.66,0.200
118.93,7.72,0.200
118.94,7.79,0.200
118.94,7.86,0.200
118.95,7.92,0.200
118.95,7.99,0.200
118.96,8.06,0.200
118.97,8.13,0.200
118.98,8.19,0.200
118.98,8.26,0.200
118.99,8.32,0.200
119.00,8.39,0.200
119.00,8.46,0.200
119.01,8.53,0.200
119.01,8.59,0.200
119.02,8.66,0.200
119.03,8.73,0.200
119.04,8.79,0.200
119.04,8.86,0.200
119.05,8.93,0.201
119.05,8.99,0.201
119.06,9.06,0.201
119.07,9.13,0.201
119.08,9.19,0.201
119.08,9.26,0.201
119.09,9.33,0.201
119.10,9.39,0.201
119.10,9.46,0.201
119.11,9.53,0.201
119.11,9.59,0.201
119.12,9.66,0.201
119.13,9.73,0.201
119.14,9.79,0.201
119.14,9.86,0.201
119.15,9.93,0.201
119.15,9.99,0.201
119.16,10.06,0.201
119.17,10.13,0.201
119.18,10.19,0.201
119.18,10.26,0.201
119.19,10.33,0.201
119.20,10.39,0.201
119.20,10.46,0.201
119.21,10.53,0.202
119.21,10.59,0.202
119.22,10.66,0.202
119.23,10.73,0.202
119.24,10.79,0.202
119.24,10.86,0.202
119.25,10.93,0.202
119.25,11.00,0.202
119.26,11.06,0.202
119.27,11.13,0.202
119.28,11.20,0.202
119.28,11.26,0.202
119.29,11.33,0.202
119.30,11.39,0.202
119.30,11.46,0.202
119.31,11.53,0.202
119.31,11.60,0.202
119.32,11.66,0.202
119.33,11.73,0.202
119.34,11.79,0.202
119.34,11.86,0.202
119.35,11.93,0.202
119.35,12.00,0.202
119.36,12.06,0.202
119.37,12.13,0.202
119.38,12.20,0.203
119.38,12.26,0.203
119.39,12.33,0.203
119.40,12.40,0.203
119.40,12.46,0.203
119.41,12.53,0.203
119.41,12.60,0.203
119.42,12.66,0.203
119.43,12.73,0.203
119.44,12.80,0.203
119.44,12.86,0.203
119.45,12.93,0.203
119.45,13.00,0.203
119.46,13.07,0.203
119.47,13.13,0.203
119.48,13.20,0.203
119.48,13.26,0.203
119.49,13.33,0.204
119.50,13.40,0.204
119.50,13.46,0.204
119.51,13.53,0.204
119.51,13.60,0.204
119.52,13.67,0.204
119.53,13.73,0.204
119.54,13.80,0.204
119.54,13.86,0.204
119.55,13.93,0.204
119.55,14.00,0.204
119.56,14.07,0.204
119.57,14.13,0.204
119.58,14.20,0.204
119.58,14.26,0.204
119.59,14.33,0.204
119.60,14.40,0.204
119.60,14.47,0.204
119.61,14.53,0.204
119.61,14.60,0.204
119.62,14.67,0.204
119.63,14.73,0.204
119.64,14.80,0.204
119.64,14.87,0.204
119.65,14.93,0.204
119.65,15.00,0.205
119.66,15.07,0.205
119.67,15.13,0.205
119.68,15.20,0.205
119.68,15.27,0.205
119.69,15.33,0.205
119.70,15.40,0.205
119.70,15.47,0.205
119.71,15.53,0.205
119.71,15.60,0.205
119.72,15.67,0.205
119.73,15.73,0.205
119.74,15.80,0.205
119.74,15.87,0.205
119.75,15.93,0.205
119.75,16.00,0.205
119.76,16.07,0.205
119.77,16.13,0.205
119.78,16.20,0.205
119.78,16.27,0.205
119.79,16.34,0.205
119.80,16.40,0.205
119.80,16.47,0.205
119.81,16.53,0.205
119.81,16.60,0.206
119.82,16.67,0.206
119.83,16.73,0.206
119.84,16.80,0.206
119.84,16.87,0.206
119.85,16.94,0.206
119.85,17.00,0.206
119.86,17.07,0.206
119.87,17.13,0.206
119.88,17.20,0.206
119.88,17.27,0.206
119.89,17.34,0.206
119.90,17.40,0.206
119.90,17.47,0.206
119.91,17.54,0.206
119.91,17.60,0.206
119.92,17.67,0.206
119.93,17.74,0.206
119.94,17.80,0.206
119.94,17.87,0.206
119.95,17.94,0.206
119.95,18.00,0.206
119.96,18.07,0.207
119.97,18.14,0.207
119.98,18.20,0.207
119.98,18.27,0.207
119.99,18.34,0.207
120.00,18.40,0.207
120.00,18.47,0.207
120.01,18.54,0.207
120.01,18.61,0.207
120.02,18.67,0.207
120.03,18.74,0.207
120.04,18.80,0.207
120.04,18.87,0.207
120.05,18.94,0.207
120.05,19.00,0.207
120.06,19.07,0.207
120.07,19.14,0.207
120.08,19.21,0.207
120.08,19.27,0.207
120.09,19.34,0.207
120.10,19.40,0.207
120.10,19.47,0.208
120.11,19.54,0.208
120.11,19.60,0.208
120.12,19.67,0.208
120.13,19.74,0.208
120.14,19.81,0.208
120.14,19.87,0.208
120.15,19.94,0.208
120.15,20.00,0.208
120.16,20.07,0.208
120.17,20.14,0.208
120.18,20.20,0.208
120.18,20.27,0.208
120.19,20.34,0.208
120.20,20.41,0.208
120.20,20.47,0.208
120.21,20.54,0.208
120.21,20.61,0.208
120.22,20.67,0.208
120.23,20.74,0.208
120.24,20.81,0.208
120.24,20.87,0.209
120.25,20.94,0.209
120.25,21.01,0.209
120.26,21.07,0.209
120.27,21.14,0.209
120.28,21.21,0.209
120.28,21.27,0.209
120.29,21.34,0.209
120.30,21.41,0.209
120.30,21.47,0.209
120.31,21.54,0.209
120.31,21.61,0.209
120.32,21.67,0.209
120.33,21.74,0.209
120.34,21.81,0.209
120.34,21.87,0.209
120.35,21.94,0.209
120.35,22.01,0.209
120.36,22.07,0.209
120.37,22.14,0.209
120.38,22.21,0.210
120.38,22.27,0.210
120.39,22.34,0.210
120.40,22.41,0.210
120.40,22.47,0.210
120.41,22.54,0.210
120.41,22.61,0.210
120.42,22.68,0.210
120.43,22.74,0.210
120.44,22.81,0.210
120.44,22.88,0.210
120.45,22.94,0.210
120.45,23.01,0.210
120.46,23.08,0.210
120.47,23.14,0.210
120.48,23.21,0.210
120.48,23.28,0.210
120.49,23.34,0.210
120.50,23.41,0.210
120.50,23.48,0.210
120.51,23.54,0.210
120.51,23.61,0.210
120.52,23.68,0.210
120.53,23.74,0.211
120.54,23.81,0.211
120.54,23.88,0.211
120.55,23.94,0.211
120.55,24.01,0.211
120.56,24.08,0.211
120.57,24.14,0.211
120.58,24.21,0.211
120.58,24.28,0.211
120.59,24.34,0.211
120.60,24.41,0.211
120.60,24.48,0.211
120.61,24.54,0.211
120.61,24.61,0.211
120.62,24.68,0.211
120.63,24.74,0.211
120.64,24.81,0.211
120.64,24.88,0.212
120.65,24.94,0.212
120.65,25.01,0.212
120.66,25.08,0.212
120.67,25.14,0.212
120.68,25.21,0.212
120.68,25.28,0.212
120.69,25.34,0.212
120.70,25.41,0.212
120.70,25.48,0.212
120.71,25.54,0.212
120.71,25.61,0.212
120.72,25.68,0.212
120.73,25.74,0.212
120.74,25.81,0.212
120.74,25.88,0.212
120.75,25.94,0.213
120.75,26.01,0.213
120.76,26.08,0.213
120.77,26.15,0.213
120.78,26.21,0.213
120.78,26.28,0.213
120.79,26.35,0.213
120.80,26.41,0.213
120.80,26.48,0.213
120.81,26.55,0.213
120.81,26.61,0.213
120.82,26.68,0.213
120.83,26.75,0.213
120.84,26.81,0.213
120.84,26.88,0.213
120.85,26.94,0.214
120.85,27.01,0.214
120.86,27.08,0.214
120.87,27.15,0.214
120.88,27.21,0.214
120.88,27.28,0.214
120.89,27.35,0.214
120.90,27.41,0.214
120.90,27.48,0.214
120.91,27.55,0.214
120.91,27.61,0.214
120.92,27.68,0.214
120.93,27.75,0.214
120.94,27.81,0.214
120.94,27.88,
120.95,27.95,
120.95,28.01,
120.96,28.08,
120.97,28.15,
120.98,28.21,
120.98,28.28,
120.99,,
120.99,,