File: DSC/2025_05_08_THC_n60C_100C_5Cmin_x3.csv
Filename,2025_05_08_THC_n60C_100C_5Cmin_x3
Instrument name,DSC2A-00468 (192.168.1.100)
Operator,Yarger
rundate,5/8/2025
Sample name,2025_05_08_THC_n60C_100C_5Cmin_x3
proceduresegments,Data Off ; Equilibrate -60.00 °C; Data On ; Ramp 5.00 °C/min to 100.00 °C; Data Off ; Isothermal 1.0 min; Data On ; Ramp 5.00 °C/min to -60.00 °C; Data Off ; Isothermal 1.0 min; Data On ; Ramp 5.00 °C/min to 100.00 °C; Data Off ; Isothermal 1.0 min; Data On ; Ramp 5.00 °C/min to -60.00 °C; Data Off ; Isothermal 1.0 min; Data On ; Ramp 5.00 °C/min to 30.00 °C
[File Parameters]
Run date,5/8/2025 6:05:52 PM
Trios version,5.1.1.46572
Original File Name,
Current File Name,D:\DSC2500\JYarger\2025_05_08_THC_n60C_100C_5Cmin_x3.tri
[Procedure]
Procedure Name,THC_n60C_100C_5Cmin_x3
Sample Name,2025_05_08_THC_n60C_100C_5Cmin_x3
Sample Mass,12.27 mg
Reference Sample Mass,0 mg
Pan Mass,57.16 mg
Pan Number,24
Reference Pan Mass,57.13 mg
Reference Pan Number,37
Pan Type,Tzero Aluminum Hermetic
Comments,Al Hermetic DSC Consumables sealed Pan/Lid. Y2 Tray (Google Sheet: DSC_Samples_Vext_Y2_Tray_May2025)
Project Name,CA
Operator,Yarger
Test,Custom
Unload Max Temperature,30
Unload Min Temperature,30
Load Max Temperature,30
Load Min Temperature,30
Stop on Gas Flow Error,Yes
[Signal List]
Signal #1,Time (min)
Signal #2,Temperature (°C)
Signal #3,Heat Flow (mW)
Signal #4,Delta T (µV)
Signal #5,Delta Tzero (µV)
Signal #6,Tzero Temperature (°C)
Signal #7,Cell Purge (mL/min)
Signal #8,Heater Temp (°C)
Signal #9,Power Delivered (W)
Signal #10,Reference Junction Temperature (°C)
Signal #11,Flange Temperature (°C)
Signal #12,Heat Flow Phase (rad)
Signal #13,Total Heat Capacity (J/°C)
Signal #14,Heat Capacity (J/°C)
[Configuration]
Company Name,ASU
Instrument Name,DSC2A-00468
Instrument Type,DSC2500
Serial Number,DSC2A-00468
IP,192.168.1.100
Location of Instrument,MRRC
DisplayType,Unknown
Sample Interval ,0.1 s/pt
Selected Heat Flow,T4P
Exotherm Direction,Down
Cell Serial,DRC2-00792
Lid Type,Standard
Cooler,RCS 90
Leave Cooler on at End of Sequence,On
Gas 2,Nitrogen
Gas Selected,Channel 1
Flow Rate,50 mL/min
Secondary Purge,On
Licensed Heat Flow,Heat Flow T4P
Modulation Licensed,Yes
[Versions]
Common IDD Version,1
Cortex Version,VER 2.10.2.31
Driver,5.0.0.6
GDM Version,1.0.3.3
TouchscreenVersion,1.0.0.16145
FEP Version,1.2.1.21
FEP Bootloader,2.0.0.5
AutoSampler Version,2.1.1.26
Auto Sampler Bootloader,2.0.0.5
FCM Version,1.1.0.3
FCM Bootloader,2.0.0.5
[Experiment Logs]
Experiment Log Entry # 1,Data On set to 0
Experiment Log Entry # 3,Equilibrate Segment -60 (C) Started
Experiment Log Entry # 5,Air Cool is off.
Experiment Log Entry # 7,Data On set to 1
Experiment Log Entry # 9,Ramp Segment 5 C/min to 100 Started
Experiment Log Entry # 11,Data On set to 0
Experiment Log Entry # 13,Isothermal Segment 1 min started
Experiment Log Entry # 15,Data On set to 1
Experiment Log Entry # 17,Ramp Segment 5 C/min to -60 Started
Experiment Log Entry # 19,Auto sampler has detected that FEP has gone offline
Experiment Log Entry # 21,Data On set to 0
Experiment Log Entry # 23,Isothermal Segment 1 min started
Experiment Log Entry # 25,Data On set to 1
Experiment Log Entry # 27,Ramp Segment 5 C/min to 100 Started
Experiment Log Entry # 29,Data On set to 0
Experiment Log Entry # 31,Isothermal Segment 1 min started
Experiment Log Entry # 33,Data On set to 1
Experiment Log Entry # 35,Ramp Segment 5 C/min to -60 Started
Experiment Log Entry # 37,Data On set to 0
Experiment Log Entry # 39,Isothermal Segment 1 min started
Experiment Log Entry # 41,Data On set to 1
Experiment Log Entry # 43,Ramp Segment 5 C/min to 30 Started
[Method Log]
Method Log Entry # 1,Data Off
Method Log Entry # 2,Equilibrate -60 °C
Method Log Entry # 3,Data On
Method Log Entry # 4,(Ramp 356151) Ramp 5 °C/minute to 100 °C
Method Log Entry # 5,Data Off
Method Log Entry # 6,Isothermal 1 minutes
Method Log Entry # 7,Data On
Method Log Entry # 8,(Ramp 356155) Ramp 5 °C/minute to -60 °C
Method Log Entry # 9,Data Off
Method Log Entry # 10,Isothermal 1 minutes
Method Log Entry # 11,Data On
Method Log Entry # 12,(Ramp 356159) Ramp 5 °C/minute to 100 °C
Method Log Entry # 13,Data Off
Method Log Entry # 14,Isothermal 1 minutes
Method Log Entry # 15,Data On
Method Log Entry # 16,(Ramp 356163) Ramp 5 °C/minute to -60 °C
Method Log Entry # 17,Data Off
Method Log Entry # 18,Isothermal 1 minutes
Method Log Entry # 19,Data On
Method Log Entry # 20,(Ramp 356167) Ramp 5 °C/minute to 30 °C
Cell Serial,DRC2-00792
[T1 Calibration]
Slope,-0.008529666
Offset,9.636258
Initial Temperature,98.23
GUID,f8bfdadc-4977-4fdf-ba6d-0ba9134940c3
[TZero Calibration]
Date Applied,11/29/2022 4:06:13 PM
Description,From -89.059 °C to 396.009 °C at 20.000°C/min
Gas Type,Nitrogen
Pan Type,None
Source Files 1,C:\Users\yargerlab\Desktop\DSC Data\General\TZero_calibration_11_29_22_2nd(2).tri
Source Files 2,C:\Users\yargerlab\Desktop\DSC Data\General\TZero_calibration_11_29_22_2nd(3).tri
Delta T Offset,13.05235
Delta T Slope,-0.007271007
Delta T0 Offset,-13.69128
Delta T0 Slope,0.06063341
[Temperature Calibration]
Date Applied,11/29/2022 7:12:28 PM
Description,From 106.590 °C to 186.590 °C at 10.000°C/min
Gas Type,Nitrogen
Pan Type,Tzero Aluminum Hermetic
Source Files 1,C:\Users\yargerlab\Desktop\DSC Data\General\Indium(6).tri
Measured 1,157.391
Known 1,156.598
[Cell Constant Calibration]
Date Applied,11/29/2022 7:12:29 PM
Description,From 106.590 °C to 186.590 °C at 10.000°C/min
Gas Type,Nitrogen
Pan Type,Tzero Aluminum Hermetic
Source Files 1,C:\Users\yargerlab\Desktop\DSC Data\General\Indium(6).tri
T4P KCell,1.006051
Onset Slope,63.26126 mW/°C
[Direct Cp Calibration]
Date Applied,11/30/2022 11:04:51 AM
Description,From -79.983 °C to 298.409 °C at 10.000°C/min
Gas Type,Nitrogen
Pan Type,Tzero Aluminum Hermetic
Source Files 1,C:\Users\yargerlab\Desktop\DSC Data\General\Sapphire_Heat_Capacity_11_30_22.tri
[Rev Cp Calibration]
Date Applied,11/30/2022 1:58:51 PM
Description,From -79.996 °C to 292.812 °C at 3.000°C/min
Gas Type,Nitrogen
Pan Type,Tzero Aluminum Hermetic
Source Files 1,C:\Users\yargerlab\Desktop\DSC Data\General\Sapphire_MDSC_Calibration_11_30_22.tri
[step]
Ramp 5.00 °C/min to 100.00 °C
Time,Temperature,Heat Flow (Normalized)
min,°C,W/g
0.00,-59.65,-0.037
0.02,-59.67,-0.038
0.04,-59.68,-0.033
0.07,-59.68,-0.026
0.09,-59.66,-0.018
0.11,-59.62,-0.009
0.13,-59.57,0.002
0.15,-59.51,0.012
0.17,-59.44,0.022
0.19,-59.37,0.030
0.22,-59.29,0.038
0.24,-59.21,0.044
0.26,-59.12,0.049
0.28,-59.04,0.054
0.30,-58.95,0.058
0.33,-58.86,0.062
0.35,-58.77,0.066
0.37,-58.67,0.068
0.39,-58.57,0.071
0.41,-58.48,0.073
0.43,-58.38,0.075
0.45,-58.28,0.076
0.48,-58.18,0.078
0.50,-58.08,0.079
0.52,-57.97,0.080
0.54,-57.87,0.081
0.56,-57.77,0.082
0.58,-57.67,0.083
0.61,-57.56,0.083
0.63,-57.46,0.084
0.65,-57.36,0.085
0.67,-57.25,0.085
0.69,-57.14,0.085
0.72,-57.04,0.086
0.74,-56.93,0.086
0.76,-56.83,0.086
0.78,-56.72,0.086
0.80,-56.62,0.086
0.82,-56.51,0.087
0.85,-56.40,0.087
0.87,-56.30,0.087
0.89,-56.19,0.087
0.91,-56.08,0.087
0.93,-55.98,0.087
0.95,-55.87,0.088
0.98,-55.76,0.088
1.00,-55.66,0.088
1.02,-55.55,0.088
1.04,-55.44,0.088
1.06,-55.33,0.088
1.08,-55.23,0.089
1.11,-55.12,0.089
1.13,-55.02,0.089
1.15,-54.91,0.089
1.17,-54.80,0.089
1.19,-54.69,0.089
1.21,-54.59,0.089
1.23,-54.48,0.089
1.26,-54.37,0.089
1.28,-54.26,0.089
1.30,-54.15,0.090
1.32,-54.05,0.090
1.34,-53.94,0.090
1.37,-53.83,0.090
1.39,-53.72,0.090
1.41,-53.62,0.090
1.43,-53.51,0.090
1.45,-53.40,0.090
1.47,-53.29,0.090
1.49,-53.18,0.090
1.52,-53.08,0.090
1.54,-52.97,0.090
1.56,-52.86,0.090
1.58,-52.75,0.090
1.60,-52.64,0.090
1.63,-52.54,0.090
1.65,-52.43,0.090
1.67,-52.32,0.090
1.69,-52.21,0.091
1.71,-52.11,0.091
1.73,-52.00,0.091
1.76,-51.89,0.091
1.78,-51.78,0.091
1.80,-51.67,0.091
1.82,-51.57,0.091
1.84,-51.46,0.091
1.86,-51.35,0.091
1.88,-51.24,0.091
1.91,-51.13,0.091
1.93,-51.02,0.091
1.95,-50.92,0.091
1.97,-50.81,0.091
1.99,-50.70,0.091
2.02,-50.59,0.091
2.04,-50.48,0.091
2.06,-50.38,0.091
2.08,-50.27,0.091
2.10,-50.16,0.091
2.12,-50.05,0.091
2.14,-49.94,0.091
2.17,-49.83,0.091
2.19,-49.73,0.091
2.21,-49.62,0.091
2.23,-49.51,0.091
2.25,-49.40,0.091
2.28,-49.29,0.091
2.30,-49.19,0.091
2.32,-49.08,0.091
2.34,-48.97,0.091
2.36,-48.86,0.091
2.38,-48.75,0.091
2.41,-48.65,0.092
2.43,-48.54,0.092
2.45,-48.43,0.092
2.47,-48.32,0.092
2.49,-48.21,0.092
2.51,-48.10,0.092
2.54,-48.00,0.092
2.56,-47.89,0.092
2.58,-47.78,0.092
2.60,-47.67,0.092
2.62,-47.56,0.092
2.64,-47.45,0.092
2.66,-47.35,0.092
2.69,-47.24,0.092
2.71,-47.13,0.092
2.73,-47.02,0.092
2.75,-46.91,0.092
2.77,-46.81,0.092
2.79,-46.70,0.092
2.82,-46.59,0.092
2.84,-46.48,0.092
2.86,-46.37,0.092
2.88,-46.26,0.092
2.90,-46.16,0.092
2.93,-46.05,0.092
2.95,-45.94,0.092
2.97,-45.83,0.092
2.99,-45.73,0.092
3.01,-45.62,0.092
3.03,-45.51,0.092
3.06,-45.40,0.092
3.08,-45.29,0.092
3.10,-45.18,0.092
3.12,-45.07,0.092
3.14,-44.97,0.092
3.16,-44.86,0.092
3.19,-44.75,0.092
3.21,-44.64,0.092
3.23,-44.53,0.093
3.25,-44.42,0.093
3.27,-44.32,0.093
3.29,-44.21,0.093
3.31,-44.10,0.093
3.34,-43.99,0.093
3.36,-43.88,0.093
3.38,-43.77,0.093
3.40,-43.66,0.093
3.42,-43.56,0.093
3.44,-43.45,0.093
3.47,-43.34,0.093
3.49,-43.23,0.093
3.51,-43.12,0.093
3.53,-43.01,0.093
3.55,-42.90,0.093
3.58,-42.80,0.093
3.60,-42.69,0.093
3.62,-42.58,0.093
3.64,-42.47,0.093
3.66,-42.36,0.093
3.68,-42.26,0.093
3.71,-42.15,0.093
3.73,-42.04,0.093
3.75,-41.93,0.093
3.77,-41.82,0.094
3.79,-41.71,0.094
3.81,-41.60,0.094
3.84,-41.50,0.094
3.86,-41.39,0.094
3.88,-41.28,0.094
3.90,-41.17,0.094
3.92,-41.06,0.094
3.94,-40.96,0.094
3.96,-40.85,0.094
3.99,-40.74,0.094
4.01,-40.63,0.094
4.03,-40.52,0.094
4.05,-40.41,0.094
4.07,-40.31,0.094
4.09,-40.20,0.094
4.12,-40.09,0.094
4.14,-39.98,0.094
4.16,-39.87,0.094
4.18,-39.76,0.094
4.20,-39.65,0.094
4.23,-39.54,0.094
4.25,-39.44,0.094
4.27,-39.33,0.094
4.29,-39.22,0.094
4.31,-39.11,0.094
4.33,-39.00,0.094
4.35,-38.89,0.094
4.38,-38.78,0.094
4.40,-38.68,0.094
4.42,-38.57,0.095
4.44,-38.46,0.095
4.46,-38.35,0.095
4.49,-38.24,0.095
4.51,-38.13,0.095
4.53,-38.02,0.095
4.55,-37.92,0.095
4.57,-37.81,0.095
4.59,-37.70,0.095
4.61,-37.59,0.095
4.64,-37.48,0.095
4.66,-37.37,0.095
4.68,-37.26,0.095
4.70,-37.16,0.095
4.72,-37.05,0.095
4.75,-36.94,0.095
4.77,-36.83,0.095
4.79,-36.72,0.095
4.81,-36.61,0.095
4.83,-36.51,0.095
4.85,-36.40,0.095
4.88,-36.29,0.095
4.90,-36.18,0.095
4.92,-36.07,0.095
4.94,-35.96,0.095
4.96,-35.85,0.095
4.98,-35.75,0.095
5.00,-35.64,0.095
5.03,-35.53,0.096
5.05,-35.42,0.096
5.07,-35.31,0.096
5.09,-35.20,0.096
5.11,-35.09,0.096
5.14,-34.98,0.096
5.16,-34.87,0.096
5.18,-34.77,0.096
5.20,-34.66,0.096
5.22,-34.55,0.096
5.24,-34.44,0.096
5.26,-34.33,0.096
5.29,-34.22,0.096
5.31,-34.12,0.096
5.33,-34.01,0.096
5.35,-33.90,0.096
5.37,-33.79,0.096
5.40,-33.69,0.096
5.42,-33.58,0.096
5.44,-33.47,0.096
5.46,-33.36,0.096
5.48,-33.26,0.096
5.50,-33.15,0.096
5.53,-33.04,0.096
5.55,-32.93,0.096
5.57,-32.82,0.096
5.59,-32.71,0.096
5.61,-32.60,0.096
5.63,-32.50,0.096
5.65,-32.39,0.096
5.68,-32.28,0.096
5.70,-32.17,0.096
5.72,-32.06,0.096
5.74,-31.95,0.097
5.76,-31.84,0.097
5.79,-31.74,0.097
5.81,-31.63,0.097
5.83,-31.52,0.097
5.85,-31.41,0.097
5.87,-31.30,0.097
5.89,-31.19,0.097
5.91,-31.09,0.097
5.94,-30.98,0.097
5.96,-30.87,0.097
5.98,-30.76,0.097
6.00,-30.65,0.097
6.02,-30.54,0.097
6.05,-30.43,0.097
6.07,-30.33,0.097
6.09,-30.22,0.097
6.11,-30.11,0.097
6.13,-30.00,0.097
6.15,-29.89,0.097
6.18,-29.78,0.097
6.20,-29.68,0.097
6.22,-29.57,0.097
6.24,-29.46,0.098
6.26,-29.35,0.098
6.28,-29.24,0.098
6.30,-29.13,0.098
6.33,-29.03,0.098
6.35,-28.92,0.098
6.37,-28.81,0.098
6.39,-28.70,0.098
6.41,-28.59,0.098
6.44,-28.48,0.098
6.46,-28.38,0.098
6.48,-28.27,0.098
6.50,-28.16,0.098
6.52,-28.05,0.098
6.54,-27.94,0.098
6.56,-27.83,0.098
6.59,-27.72,0.098
6.61,-27.62,0.098
6.63,-27.51,0.098
6.65,-27.40,0.098
6.67,-27.29,0.098
6.70,-27.18,0.098
6.72,-27.07,0.099
6.74,-26.96,0.099
6.76,-26.86,0.099
6.78,-26.75,0.099
6.80,-26.64,0.099
6.83,-26.53,0.099
6.85,-26.42,0.099
6.87,-26.31,0.099
6.89,-26.20,0.099
6.91,-26.10,0.099
6.93,-25.98,0.099
6.95,-25.88,0.099
6.98,-25.77,0.099
7.00,-25.66,0.099
7.02,-25.55,0.099
7.04,-25.44,0.099
7.06,-25.34,0.099
7.09,-25.23,0.099
7.11,-25.12,0.099
7.13,-25.01,0.099
7.15,-24.91,0.099
7.17,-24.80,0.099
7.19,-24.69,0.099
7.21,-24.58,0.099
7.24,-24.47,0.099
7.26,-24.36,0.099
7.28,-24.25,0.099
7.30,-24.15,0.099
7.32,-24.04,0.099
7.35,-23.93,0.099
7.37,-23.82,0.099
7.39,-23.71,0.099
7.41,-23.60,0.100
7.43,-23.50,0.100
7.45,-23.39,0.100
7.48,-23.28,0.100
7.50,-23.17,0.100
7.52,-23.06,0.100
7.54,-22.95,0.100
7.56,-22.85,0.100
7.58,-22.74,0.100
7.60,-22.63,0.100
7.63,-22.52,0.100
7.65,-22.41,0.100
7.67,-22.30,0.100
7.69,-22.20,0.100
7.71,-22.08,0.100
7.74,-21.97,0.100
7.76,-21.87,0.101
7.78,-21.76,0.101
7.80,-21.65,0.101
7.82,-21.54,0.101
7.84,-21.43,0.101
7.86,-21.32,0.101
7.89,-21.21,0.101
7.91,-21.11,0.101
7.93,-21.00,0.101
7.95,-20.89,0.101
7.97,-20.78,0.101
8.00,-20.67,0.101
8.02,-20.56,0.101
8.04,-20.46,0.101
8.06,-20.35,0.101
8.08,-20.24,0.101
8.10,-20.13,0.101
8.13,-20.02,0.101
8.15,-19.91,0.101
8.17,-19.81,0.101
8.19,-19.70,0.101
8.21,-19.59,0.101
8.23,-19.48,0.101
8.25,-19.37,0.101
8.28,-19.26,0.101
8.30,-19.16,0.101
8.32,-19.05,0.101
8.34,-18.94,0.101
8.36,-18.83,0.101
8.39,-18.72,0.101
8.41,-18.62,0.101
8.43,-18.51,0.101
8.45,-18.40,0.102
8.47,-18.29,0.102
8.49,-18.18,0.102
8.51,-18.07,0.102
8.54,-17.97,0.102
8.56,-17.86,0.102
8.58,-17.75,0.102
8.60,-17.64,0.102
8.62,-17.53,0.102
8.65,-17.42,0.102
8.67,-17.31,0.102
8.69,-17.21,0.102
8.71,-17.10,0.102
8.73,-16.99,0.102
8.75,-16.88,0.102
8.78,-16.77,0.102
8.80,-16.66,0.102
8.82,-16.56,0.102
8.84,-16.45,0.102
8.86,-16.34,0.103
8.88,-16.23,0.103
8.90,-16.12,0.103
8.93,-16.02,0.103
8.95,-15.91,0.103
8.97,-15.80,0.103
8.99,-15.69,0.103
9.01,-15.58,0.103
9.03,-15.48,0.103
9.06,-15.37,0.103
9.08,-15.26,0.103
9.10,-15.15,0.103
9.12,-15.04,0.103
9.14,-14.94,0.103
9.17,-14.83,0.103
9.19,-14.72,0.103
9.21,-14.61,0.103
9.23,-14.50,0.103
9.25,-14.39,0.103
9.27,-14.29,0.104
9.30,-14.18,0.104
9.32,-14.07,0.104
9.34,-13.96,0.104
9.36,-13.85,0.104
9.38,-13.74,0.104
9.40,-13.63,0.104
9.43,-13.52,0.104
9.45,-13.41,0.105
9.47,-13.30,0.105
9.49,-13.19,0.105
9.51,-13.08,0.105
9.53,-12.98,0.105
9.55,-12.87,0.105
9.58,-12.76,0.105
9.60,-12.65,0.105
9.62,-12.54,0.105
9.64,-12.43,0.105
9.66,-12.33,0.105
9.68,-12.22,0.105
9.71,-12.11,0.105
9.73,-12.00,0.105
9.75,-11.89,0.105
9.77,-11.79,0.105
9.79,-11.68,0.105
9.82,-11.57,0.106
9.84,-11.46,0.106
9.86,-11.35,0.106
9.88,-11.24,0.106
9.90,-11.14,0.106
9.92,-11.03,0.106
9.95,-10.92,0.106
9.97,-10.81,0.106
9.99,-10.70,0.106
10.01,-10.60,0.106
10.03,-10.49,0.106
10.05,-10.38,0.107
10.08,-10.27,0.107
10.10,-10.16,0.107
10.12,-10.06,0.107
10.14,-9.95,0.107
10.16,-9.84,0.107
10.18,-9.73,0.107
10.20,-9.62,0.107
10.23,-9.51,0.107
10.25,-9.41,0.108
10.27,-9.30,0.108
10.29,-9.19,0.108
10.31,-9.08,0.108
10.33,-8.97,0.108
10.36,-8.86,0.108
10.38,-8.75,0.108
10.40,-8.65,0.108
10.42,-8.54,0.109
10.44,-8.43,0.109
10.47,-8.32,0.109
10.49,-8.21,0.109
10.51,-8.10,0.109
10.53,-8.00,0.109
10.55,-7.89,0.110
10.57,-7.78,0.110
10.60,-7.67,0.110
10.62,-7.56,0.110
10.64,-7.46,0.110
10.66,-7.35,0.110
10.68,-7.24,0.111
10.70,-7.13,0.111
10.73,-7.02,0.111
10.75,-6.91,0.111
10.77,-6.81,0.111
10.79,-6.70,0.112
10.81,-6.59,0.112
10.83,-6.48,0.112
10.85,-6.37,0.112
10.88,-6.27,0.112
10.90,-6.16,0.113
10.92,-6.05,0.113
10.94,-5.94,0.113
10.96,-5.83,0.114
10.98,-5.73,0.114
11.01,-5.62,0.114
11.03,-5.51,0.114
11.05,-5.40,0.114
11.07,-5.29,0.115
11.09,-5.19,0.115
11.12,-5.08,0.116
11.14,-4.97,0.116
11.16,-4.86,0.116
11.18,-4.75,0.117
11.20,-4.64,0.117
11.22,-4.54,0.118
11.25,-4.43,0.118
11.27,-4.32,0.118
11.29,-4.21,0.119
11.31,-4.11,0.119
11.33,-4.00,0.119
11.35,-3.89,0.120
11.38,-3.78,0.121
11.40,-3.67,0.121
11.42,-3.56,0.121
11.44,-3.46,0.122
11.46,-3.35,0.122
11.48,-3.24,0.123
11.50,-3.13,0.123
11.53,-3.02,0.124
11.55,-2.92,0.125
11.57,-2.81,0.125
11.59,-2.70,0.126
11.61,-2.59,0.126
11.63,-2.48,0.127
11.66,-2.38,0.128
11.68,-2.27,0.128
11.70,-2.16,0.129
11.72,-2.05,0.129
11.74,-1.94,0.130
11.77,-1.84,0.130
11.79,-1.73,0.131
11.81,-1.62,0.132
11.83,-1.51,0.132
11.85,-1.40,0.133
11.87,-1.30,0.134
11.90,-1.19,0.134
11.92,-1.08,0.135
11.94,-0.97,0.136
11.96,-0.87,0.136
11.98,-0.76,0.137
12.00,-0.65,0.138
12.03,-0.54,0.138
12.05,-0.43,0.139
12.07,-0.33,0.139
12.09,-0.22,0.140
12.11,-0.11,0.141
12.13,0.00,0.141
12.15,0.11,0.142
12.18,0.21,0.142
12.20,0.32,0.142
12.22,0.43,0.143
12.24,0.54,0.143
12.26,0.64,0.144
12.28,0.75,0.144
12.31,0.86,0.145
12.33,0.97,0.145
12.35,1.08,0.146
12.37,1.18,0.146
12.39,1.29,0.146
12.42,1.40,0.147
12.44,1.51,0.147
12.46,1.62,0.147
12.48,1.73,0.147
12.50,1.83,0.148
12.52,1.94,0.148
12.55,2.05,0.148
12.57,2.16,0.148
12.59,2.27,0.148
12.61,2.38,0.148
12.63,2.48,0.149
12.65,2.59,0.149
12.68,2.70,0.149
12.70,2.81,0.149
12.72,2.92,0.149
12.74,3.03,0.149
12.76,3.14,0.149
12.78,3.24,0.149
12.80,3.35,0.149
12.83,3.46,0.149
12.85,3.57,0.149
12.87,3.68,0.149
12.89,3.79,0.149
12.91,3.90,0.149
12.93,4.00,0.149
12.96,4.11,0.149
12.98,4.22,0.149
13.00,4.33,0.149
13.02,4.44,0.149
13.04,4.55,0.149
13.07,4.66,0.149
13.09,4.76,0.148
13.11,4.87,0.148
13.13,4.98,0.148
13.15,5.09,0.148
13.17,5.20,0.148
13.20,5.31,0.148
13.22,5.42,0.148
13.24,5.52,0.148
13.26,5.63,0.148
13.28,5.74,0.148
13.30,5.85,0.147
13.33,5.96,0.147
13.35,6.07,0.147
13.37,6.17,0.147
13.39,6.28,0.147
13.41,6.39,0.147
13.43,6.50,0.147
13.45,6.61,0.147
13.48,6.72,0.147
13.50,6.83,0.147
13.52,6.93,0.147
13.54,7.04,0.147
13.56,7.15,0.147
13.58,7.26,0.147
13.61,7.37,0.147
13.63,7.48,0.147
13.65,7.58,0.147
13.67,7.69,0.147
13.69,7.80,0.147
13.72,7.91,0.147
13.74,8.02,0.147
13.76,8.13,0.146
13.78,8.23,0.146
13.80,8.34,0.146
13.82,8.45,0.146
13.85,8.56,0.146
13.87,8.67,0.146
13.89,8.78,0.146
13.91,8.89,0.146
13.93,8.99,0.146
13.95,9.10,0.146
13.98,9.21,0.147
14.00,9.32,0.147
14.02,9.43,0.147
14.04,9.54,0.147
14.06,9.64,0.147
14.08,9.75,0.147
14.10,9.86,0.147
14.13,9.97,0.147
14.15,10.08,0.147
14.17,10.19,0.147
14.19,10.30,0.147
14.21,10.41,0.147
14.23,10.51,0.147
14.26,10.62,0.147
14.28,10.73,0.147
14.30,10.84,0.147
14.32,10.95,0.147
14.34,11.06,0.147
14.37,11.16,0.147
14.39,11.27,0.147
14.41,11.38,0.147
14.43,11.49,0.147
14.45,11.60,0.147
14.47,11.71,0.147
14.50,11.81,0.147
14.52,11.92,0.147
14.54,12.03,0.147
14.56,12.14,0.147
14.58,12.25,0.147
14.60,12.36,0.147
14.63,12.46,0.147
14.65,12.57,0.147
14.67,12.68,0.147
14.69,12.79,0.147
14.71,12.90,0.147
14.73,13.01,0.147
14.75,13.11,0.147
14.78,13.22,0.148
14.80,13.33,0.148
14.82,13.44,0.148
14.84,13.55,0.148
14.86,13.66,0.148
14.88,13.76,0.148
14.91,13.87,0.148
14.93,13.98,0.148
14.95,14.09,0.148
14.97,14.20,0.148
14.99,14.31,0.148
15.02,14.42,0.148
15.04,14.52,0.148
15.06,14.63,0.148
15.08,14.74,0.148
15.10,14.85,0.148
15.12,14.96,0.148
15.15,15.07,0.148
15.17,15.18,0.148
15.19,15.28,0.148
15.21,15.39,0.148
15.23,15.50,0.148
15.25,15.61,0.148
15.28,15.72,0.148
15.30,15.82,0.148
15.32,15.93,0.148
15.34,16.04,0.148
15.36,16.15,0.148
15.38,16.26,0.148
15.40,16.37,0.148
15.43,16.48,0.149
15.45,16.58,0.149
15.47,16.69,0.149
15.49,16.80,0.149
15.51,16.91,0.149
15.53,17.02,0.149
15.56,17.13,0.149
15.58,17.23,0.149
15.60,17.34,0.149
15.62,17.45,0.149
15.64,17.56,0.149
15.67,17.67,0.149
15.69,17.78,0.149
15.71,17.89,0.149
15.73,17.99,0.149
15.75,18.10,0.149
15.77,18.21,0.149
15.80,18.32,0.149
15.82,18.43,0.149
15.84,18.54,0.149
15.86,18.64,0.149
15.88,18.75,0.149
15.90,18.86,0.149
15.93,18.97,0.149
15.95,19.08,0.149
15.97,19.19,0.150
15.99,19.29,0.150
16.01,19.40,0.150
16.03,19.51,0.150
16.05,19.62,0.150
16.08,19.73,0.150
16.10,19.84,0.150
16.12,19.94,0.150
16.14,20.05,0.150
16.16,20.16,0.150
16.18,20.27,0.150
16.21,20.38,0.150
16.23,20.49,0.150
16.25,20.59,0.150
16.27,20.70,0.150
16.29,20.81,0.150
16.32,20.92,0.150
16.34,21.03,0.150
16.36,21.14,0.150
16.38,21.24,0.150
16.40,21.35,0.150
16.42,21.46,0.150
16.45,21.57,0.150
16.47,21.68,0.150
16.49,21.79,0.150
16.51,21.90,0.150
16.53,22.01,0.150
16.55,22.11,0.150
16.58,22.22,0.150
16.60,22.33,0.151
16.62,22.44,0.151
16.64,22.55,0.151
16.66,22.65,0.151
16.68,22.76,0.151
16.70,22.87,0.151
16.73,22.98,0.151
16.75,23.09,0.151
16.77,23.20,0.151
16.79,23.31,0.151
16.81,23.41,0.151
16.83,23.52,0.151
16.86,23.63,0.151
16.88,23.74,0.151
16.90,23.85,0.151
16.92,23.96,0.151
16.94,24.06,0.151
16.97,24.17,0.151
16.99,24.28,0.151
17.01,24.39,0.151
17.03,24.50,0.151
17.05,24.61,0.151
17.07,24.71,0.151
17.09,24.82,0.151
17.12,24.93,0.151
17.14,25.04,0.151
17.16,25.15,0.151
17.18,25.26,0.152
17.20,25.37,0.152
17.23,25.47,0.152
17.25,25.58,0.152
17.27,25.69,0.152
17.29,25.80,0.152
17.31,25.91,0.152
17.33,26.02,0.152
17.36,26.12,0.152
17.38,26.23,0.152
17.40,26.34,0.152
17.42,26.45,0.152
17.44,26.56,0.152
17.46,26.67,0.152
17.48,26.77,0.152
17.51,26.88,0.152
17.53,26.99,0.152
17.55,27.10,0.152
17.57,27.21,0.152
17.59,27.32,0.152
17.62,27.42,0.152
17.64,27.53,0.152
17.66,27.64,0.152
17.68,27.75,0.152
17.70,27.86,0.152
17.72,27.97,0.152
17.74,28.08,0.152
17.77,28.18,0.152
17.79,28.29,0.153
17.81,28.40,0.153
17.83,28.51,0.153
17.85,28.62,0.153
17.88,28.73,0.153
17.90,28.83,0.153
17.92,28.94,0.153
17.94,29.05,0.153
17.96,29.16,0.153
17.98,29.27,0.153
18.01,29.38,0.153
18.03,29.48,0.153
18.05,29.59,0.153
18.07,29.70,0.153
18.09,29.81,0.153
18.11,29.92,0.153
18.13,30.03,0.153
18.16,30.14,0.153
18.18,30.24,0.153
18.20,30.35,0.153
18.22,30.46,0.153
18.24,30.57,0.153
18.27,30.68,0.153
18.29,30.79,0.153
18.31,30.89,0.153
18.33,31.00,0.153
18.35,31.11,0.153
18.37,31.22,0.153
18.39,31.33,0.153
18.42,31.44,0.154
18.44,31.55,0.154
18.46,31.65,0.154
18.48,31.76,0.154
18.50,31.87,0.154
18.53,31.98,0.154
18.55,32.09,0.154
18.57,32.20,0.154
18.59,32.30,0.154
18.61,32.41,0.154
18.63,32.52,0.154
18.66,32.63,0.154
18.68,32.74,0.154
18.70,32.85,0.154
18.72,32.95,0.154
18.74,33.06,0.154
18.76,33.17,0.154
18.78,33.28,0.154
18.81,33.39,0.154
18.83,33.50,0.154
18.85,33.60,0.154
18.87,33.71,0.154
18.89,33.82,0.154
18.92,33.93,0.154
18.94,34.04,0.154
18.96,34.15,0.154
18.98,34.25,0.154
19.00,34.36,0.154
19.02,34.47,0.154
19.04,34.58,0.154
19.07,34.69,0.154
19.09,34.80,0.154
19.11,34.90,0.154
19.13,35.01,0.154
19.15,35.12,0.154
19.18,35.23,0.155
19.20,35.34,0.155
19.22,35.45,0.155
19.24,35.56,0.155
19.26,35.66,0.155
19.28,35.77,0.155
19.31,35.88,0.155
19.33,35.99,0.155
19.35,36.10,0.155
19.37,36.21,0.155
19.39,36.31,0.155
19.41,36.42,0.155
19.43,36.53,0.155
19.46,36.64,0.155
19.48,36.75,0.155
19.50,36.86,0.155
19.52,36.97,0.155
19.54,37.07,0.155
19.57,37.18,0.155
19.59,37.29,0.155
19.61,37.40,0.155
19.63,37.51,0.155
19.65,37.62,0.155
19.67,37.72,0.155
19.69,37.83,0.155
19.72,37.94,0.155
19.74,38.05,0.155
19.76,38.16,0.155
19.78,38.27,0.155
19.80,38.38,0.155
19.83,38.48,0.155
19.85,38.59,0.156
19.87,38.70,0.156
19.89,38.81,0.156
19.91,38.92,0.156
19.93,39.02,0.156
19.96,39.13,0.156
19.98,39.24,0.156
20.00,39.35,0.156
20.02,39.46,0.156
20.04,39.57,0.156
20.06,39.68,0.156
20.08,39.78,0.156
20.11,39.89,0.156
20.13,40.00,0.156
20.15,40.11,0.156
20.17,40.22,0.156
20.19,40.33,0.156
20.22,40.44,0.156
20.24,40.54,0.156
20.26,40.65,0.156
20.28,40.76,0.156
20.30,40.87,0.156
20.32,40.98,0.156
20.34,41.09,0.156
20.37,41.19,0.156
20.39,41.30,0.156
20.41,41.41,0.156
20.43,41.52,0.157
20.45,41.63,0.157
20.48,41.73,0.157
20.50,41.84,0.157
20.52,41.95,0.157
20.54,42.06,0.157
20.56,42.17,0.157
20.58,42.28,0.157
20.61,42.39,0.157
20.63,42.49,0.157
20.65,42.60,0.157
20.67,42.71,0.157
20.69,42.82,0.157
20.71,42.93,0.157
20.73,43.04,0.157
20.76,43.15,0.157
20.78,43.25,0.157
20.80,43.36,0.157
20.82,43.47,0.157
20.84,43.58,0.157
20.87,43.69,0.157
20.89,43.80,0.157
20.91,43.90,0.157
20.93,44.01,0.157
20.95,44.12,0.157
20.97,44.23,0.157
20.99,44.34,0.157
21.02,44.45,0.157
21.04,44.55,0.157
21.06,44.66,0.157
21.08,44.77,0.157
21.10,44.88,0.158
21.13,44.99,0.158
21.15,45.10,0.158
21.17,45.21,0.158
21.19,45.31,0.158
21.21,45.42,0.158
21.23,45.53,0.158
21.26,45.64,0.158
21.28,45.75,0.158
21.30,45.86,0.158
21.32,45.97,0.158
21.34,46.07,0.158
21.36,46.18,0.158
21.38,46.29,0.158
21.41,46.40,0.158
21.43,46.51,0.158
21.45,46.62,0.158
21.47,46.73,0.158
21.49,46.83,0.158
21.52,46.94,0.158
21.54,47.05,0.158
21.56,47.16,0.158
21.58,47.27,0.158
21.60,47.37,0.158
21.62,47.48,0.158
21.64,47.59,0.158
21.67,47.70,0.158
21.69,47.81,0.158
21.71,47.92,0.158
21.73,48.03,0.158
21.75,48.13,0.158
21.78,48.24,0.158
21.80,48.35,0.158
21.82,48.46,0.158
21.84,48.57,0.158
21.86,48.68,0.158
21.88,48.78,0.158
21.91,48.89,0.158
21.93,49.00,0.158
21.95,49.11,0.158
21.97,49.22,0.158
21.99,49.32,0.159
22.01,49.43,0.159
22.03,49.54,0.159
22.06,49.65,0.159
22.08,49.76,0.159
22.10,49.87,0.159
22.12,49.98,0.159
22.14,50.08,0.159
22.17,50.19,0.159
22.19,50.30,0.159
22.21,50.41,0.159
22.23,50.52,0.159
22.25,50.62,0.159
22.27,50.73,0.159
22.29,50.84,0.159
22.32,50.95,0.159
22.34,51.06,0.159
22.36,51.17,0.159
22.38,51.28,0.159
22.40,51.38,0.159
22.43,51.49,0.159
22.45,51.60,0.159
22.47,51.71,0.159
22.49,51.82,0.159
22.51,51.93,0.159
22.53,52.03,0.159
22.56,52.14,0.159
22.58,52.25,0.159
22.60,52.36,0.159
22.62,52.47,0.159
22.64,52.58,0.159
22.66,52.68,0.159
22.68,52.79,0.160
22.71,52.90,0.160
22.73,53.01,0.160
22.75,53.12,0.160
22.77,53.23,0.160
22.79,53.34,0.160
22.82,53.44,0.160
22.84,53.55,0.160
22.86,53.66,0.160
22.88,53.77,0.160
22.90,53.88,0.160
22.92,53.98,0.160
22.94,54.09,0.160
22.97,54.20,0.160
22.99,54.31,0.160
23.01,54.42,0.160
23.03,54.53,0.160
23.05,54.64,0.160
23.08,54.74,0.160
23.10,54.85,0.160
23.12,54.96,0.160
23.14,55.07,0.160
23.16,55.18,0.160
23.18,55.28,0.160
23.21,55.39,0.160
23.23,55.50,0.160
23.25,55.61,0.160
23.27,55.72,0.160
23.29,55.83,0.160
23.31,55.94,0.160
23.33,56.04,0.160
23.36,56.15,0.160
23.38,56.26,0.160
23.40,56.37,0.160
23.42,56.48,0.161
23.44,56.59,0.161
23.47,56.69,0.161
23.49,56.80,0.161
23.51,56.91,0.161
23.53,57.02,0.161
23.55,57.13,0.161
23.57,57.24,0.161
23.59,57.35,0.161
23.62,57.45,0.161
23.64,57.56,0.161
23.66,57.67,0.161
23.68,57.78,0.161
23.70,57.89,0.161
23.73,58.00,0.161
23.75,58.10,0.161
23.77,58.21,0.161
23.79,58.32,0.161
23.81,58.43,0.161
23.83,58.54,0.161
23.86,58.65,0.161
23.88,58.75,0.161
23.90,58.86,0.161
23.92,58.97,0.161
23.94,59.08,0.161
23.96,59.19,0.161
23.98,59.30,0.161
24.01,59.40,0.161
24.03,59.51,0.161
24.05,59.62,0.161
24.07,59.73,0.161
24.09,59.84,0.161
24.12,59.95,0.161
24.14,60.06,0.161
24.16,60.16,0.161
24.18,60.27,0.161
24.20,60.38,0.161
24.22,60.49,0.161
24.24,60.60,0.161
24.27,60.71,0.161
24.29,60.81,0.161
24.31,60.92,0.161
24.33,61.03,0.162
24.35,61.14,0.162
24.38,61.25,0.162
24.40,61.36,0.162
24.42,61.47,0.162
24.44,61.57,0.162
24.46,61.68,0.162
24.48,61.79,0.162
24.51,61.90,0.162
24.53,62.01,0.162
24.55,62.12,0.162
24.57,62.22,0.162
24.59,62.33,0.162
24.61,62.44,0.162
24.63,62.55,0.162
24.66,62.66,0.162
24.68,62.77,0.162
24.70,62.88,0.162
24.72,62.98,0.162
24.74,63.09,0.162
24.77,63.20,0.162
24.79,63.31,0.162
24.81,63.42,0.162
24.83,63.52,0.162
24.85,63.63,0.162
24.87,63.74,0.162
24.89,63.85,0.162
24.92,63.96,0.162
24.94,64.07,0.162
24.96,64.18,0.162
24.98,64.28,0.162
25.00,64.39,0.162
25.03,64.50,0.162
25.05,64.61,0.162
25.07,64.72,0.162
25.09,64.83,0.162
25.11,64.94,0.162
25.13,65.04,0.162
25.16,65.15,0.162
25.18,65.26,0.162
25.20,65.37,0.163
25.22,65.48,0.163
25.24,65.58,0.163
25.26,65.69,0.163
25.28,65.80,0.163
25.31,65.91,0.163
25.33,66.02,0.163
25.35,66.13,0.163
25.37,66.23,0.163
25.39,66.34,0.163
25.42,66.45,0.163
25.44,66.56,0.163
25.46,66.67,0.163
25.48,66.78,0.163
25.50,66.89,0.163
25.52,66.99,0.163
25.54,67.10,0.163
25.57,67.21,0.163
25.59,67.32,0.163
25.61,67.43,0.163
25.63,67.54,0.163
25.65,67.65,0.163
25.68,67.75,0.163
25.70,67.86,0.163
25.72,67.97,0.163
25.74,68.08,0.163
25.76,68.19,0.163
25.78,68.29,0.163
25.81,68.40,0.163
25.83,68.51,0.163
25.85,68.62,0.163
25.87,68.73,0.163
25.89,68.84,0.163
25.91,68.94,0.163
25.93,69.05,0.163
25.96,69.16,0.163
25.98,69.27,0.163
26.00,69.38,0.163
26.02,69.49,0.163
26.04,69.60,0.163
26.07,69.70,0.163
26.09,69.81,0.164
26.11,69.92,0.164
26.13,70.03,0.164
26.15,70.14,0.164
26.17,70.25,0.164
26.19,70.36,0.164
26.22,70.46,0.164
26.24,70.57,0.164
26.26,70.68,0.164
26.28,70.79,0.164
26.30,70.90,0.164
26.33,71.00,0.164
26.35,71.11,0.164
26.37,71.22,0.164
26.39,71.33,0.164
26.41,71.44,0.164
26.43,71.55,0.164
26.46,71.66,0.164
26.48,71.76,0.164
26.50,71.87,0.164
26.52,71.98,0.164
26.54,72.09,0.164
26.56,72.20,0.164
26.58,72.31,0.164
26.61,72.41,0.164
26.63,72.52,0.164
26.65,72.63,0.164
26.67,72.74,0.164
26.69,72.85,0.164
26.72,72.96,0.164
26.74,73.07,0.164
26.76,73.17,0.164
26.78,73.28,0.164
26.80,73.39,0.164
26.82,73.50,0.164
26.84,73.61,0.164
26.87,73.72,0.164
26.89,73.82,0.164
26.91,73.93,0.164
26.93,74.04,0.164
26.95,74.15,0.164
26.98,74.26,0.164
27.00,74.37,0.164
27.02,74.47,0.165
27.04,74.58,0.165
27.06,74.69,0.165
27.08,74.80,0.165
27.11,74.91,0.165
27.13,75.02,0.165
27.15,75.13,0.165
27.17,75.23,0.165
27.19,75.34,0.165
27.21,75.45,0.165
27.23,75.56,0.165
27.26,75.67,0.165
27.28,75.78,0.165
27.30,75.88,0.165
27.32,75.99,0.165
27.34,76.10,0.165
27.37,76.21,0.165
27.39,76.32,0.165
27.41,76.43,0.165
27.43,76.54,0.165
27.45,76.64,0.165
27.47,76.75,0.165
27.49,76.86,0.165
27.52,76.97,0.165
27.54,77.08,0.165
27.56,77.19,0.165
27.58,77.29,0.165
27.60,77.40,0.165
27.63,77.51,0.165
27.65,77.62,0.165
27.67,77.73,0.165
27.69,77.84,0.165
27.71,77.94,0.165
27.73,78.05,0.165
27.76,78.16,0.165
27.78,78.27,0.165
27.80,78.38,0.165
27.82,78.49,0.165
27.84,78.59,0.165
27.86,78.70,0.165
27.88,78.81,0.165
27.91,78.92,0.165
27.93,79.03,0.166
27.95,79.14,0.166
27.97,79.25,0.166
27.99,79.35,0.166
28.02,79.46,0.166
28.04,79.57,0.166
28.06,79.68,0.166
28.08,79.79,0.166
28.10,79.89,0.166
28.12,80.00,0.166
28.14,80.11,0.166
28.17,80.22,0.166
28.19,80.33,0.166
28.21,80.44,0.166
28.23,80.54,0.166
28.25,80.65,0.166
28.28,80.76,0.166
28.30,80.87,0.166
28.32,80.98,0.166
28.34,81.09,0.166
28.36,81.19,0.166
28.38,81.30,0.166
28.41,81.41,0.166
28.43,81.52,0.166
28.45,81.63,0.166
28.47,81.74,0.166
28.49,81.85,0.166
28.51,81.95,0.166
28.53,82.06,0.166
28.56,82.17,0.166
28.58,82.28,0.166
28.60,82.39,0.166
28.62,82.49,0.166
28.64,82.60,0.166
28.67,82.71,0.166
28.69,82.82,0.166
28.71,82.93,0.166
28.73,83.04,0.166
28.75,83.14,0.166
28.77,83.25,0.166
28.79,83.36,0.166
28.82,83.47,0.166
28.84,83.58,0.166
28.86,83.69,0.166
28.88,83.79,0.166
28.90,83.90,0.166
28.93,84.01,0.166
28.95,84.12,0.166
28.97,84.23,0.166
28.99,84.34,0.166
29.01,84.45,0.166
29.03,84.55,0.166
29.06,84.66,0.166
29.08,84.77,0.166
29.10,84.88,0.166
29.12,84.99,0.167
29.14,85.10,0.167
29.16,85.20,0.167
29.18,85.31,0.167
29.21,85.42,0.167
29.23,85.53,0.167
29.25,85.64,0.167
29.27,85.75,0.167
29.29,85.86,0.167
29.32,85.96,0.167
29.34,86.07,0.167
29.36,86.18,0.167
29.38,86.29,0.167
29.40,86.40,0.167
29.42,86.51,0.167
29.44,86.61,0.167
29.47,86.72,0.167
29.49,86.83,0.167
29.51,86.94,0.167
29.53,87.05,0.167
29.55,87.16,0.167
29.58,87.27,0.167
29.60,87.37,0.167
29.62,87.48,0.167
29.64,87.59,0.167
29.66,87.70,0.167
29.68,87.81,0.167
29.71,87.92,0.167
29.73,88.03,0.167
29.75,88.13,0.167
29.77,88.24,0.167
29.79,88.35,0.167
29.81,88.46,0.167
29.83,88.57,0.167
29.86,88.68,0.167
29.88,88.78,0.167
29.90,88.89,0.167
29.92,89.00,0.167
29.94,89.11,0.167
29.97,89.22,0.167
29.99,89.33,0.167
30.01,89.43,0.167
30.03,89.54,0.167
30.05,89.65,0.167
30.07,89.76,0.167
30.09,89.87,0.167
30.12,89.98,0.167
30.14,90.08,0.167
30.16,90.19,0.167
30.18,90.30,0.167
30.20,90.41,0.167
30.23,90.52,0.167
30.25,90.63,0.167
30.27,90.74,0.167
30.29,90.84,0.167
30.31,90.95,0.167
30.33,91.06,0.167
30.36,91.17,0.167
30.38,91.28,0.167
30.40,91.38,0.167
30.42,91.49,0.167
30.44,91.60,0.168
30.46,91.71,0.168
30.48,91.82,0.168
30.51,91.93,0.168
30.53,92.03,0.168
30.55,92.14,0.168
30.57,92.25,0.168
30.59,92.36,0.168
30.62,92.47,0.168
30.64,92.58,0.168
30.66,92.68,0.168
30.68,92.79,0.168
30.70,92.90,0.169
30.72,93.01,0.169
30.74,93.12,0.169
30.77,93.23,0.169
30.79,93.33,0.169
30.81,93.44,0.169
30.83,93.55,0.169
30.85,93.66,0.169
30.88,93.77,0.169
30.90,93.88,0.169
30.92,93.99,0.169
30.94,94.09,0.169
30.96,94.20,0.169
30.98,94.31,0.169
31.01,94.42,0.169
31.03,94.53,0.169
31.05,94.64,0.169
31.07,94.75,0.169
31.09,94.85,0.169
31.11,94.96,0.169
31.13,95.07,0.169
31.16,95.18,0.169
31.18,95.29,0.169
31.20,95.39,0.169
31.22,95.50,0.168
31.24,95.61,0.168
31.27,95.72,0.168
31.29,95.83,0.168
31.31,95.94,0.168
31.33,96.04,0.168
31.35,96.15,0.168
31.37,96.26,0.168
31.39,96.37,0.168
31.42,96.48,0.168
31.44,96.59,0.168
31.46,96.70,0.168
31.48,96.80,0.168
31.50,96.91,0.168
31.53,97.02,0.168
31.55,97.13,0.168
31.57,97.24,0.168
31.59,97.34,0.168
31.61,97.45,0.168
31.63,97.56,0.168
31.66,97.67,0.168
31.68,97.78,0.168
31.70,97.89,0.168
31.72,98.00,0.168
31.74,98.10,0.168
31.76,98.21,0.168
31.78,98.32,0.168
31.81,98.43,0.168
31.83,98.54,0.168
31.85,98.65,0.168
31.87,98.75,0.168
31.89,98.86,0.168
31.92,98.97,0.168
31.94,99.08,
31.96,99.19,
31.98,,
31.98,,

[step]
Ramp 5.00 °C/min to -60.00 °C
Time,Temperature,Heat Flow (Normalized)
min,°C,W/g
32.98,100.13,-0.016
33.01,100.12,-0.016
33.03,100.12,-0.017
33.05,100.11,-0.024
33.07,100.08,-0.035
33.09,100.05,-0.050
33.12,100.00,-0.068
33.14,99.93,-0.084
33.16,99.86,-0.100
33.18,99.79,-0.113
33.20,99.71,-0.124
33.22,99.63,-0.135
33.24,99.54,-0.144
33.27,99.45,-0.151
33.29,99.36,-0.158
33.31,99.27,-0.164
33.33,99.17,-0.169
33.35,99.07,-0.173
33.38,98.98,-0.178
33.40,98.88,-0.181
33.42,98.78,-0.183
33.44,98.67,-0.186
33.46,98.57,-0.188
33.48,98.47,-0.190
33.51,98.36,-0.191
33.53,98.26,-0.193
33.55,98.16,-0.194
33.57,98.05,-0.194
33.59,97.95,-0.195
33.61,97.84,-0.196
33.63,97.73,-0.197
33.66,97.63,-0.197
33.68,97.52,-0.198
33.70,97.42,-0.198
33.72,97.31,-0.198
33.74,97.20,-0.198
33.77,97.09,-0.199
33.79,96.99,-0.199
33.81,96.88,-0.199
33.83,96.77,-0.199
33.85,96.67,-0.200
33.87,96.56,-0.200
33.89,96.45,-0.200
33.92,96.34,-0.200
33.94,96.24,-0.200
33.96,96.13,-0.200
33.98,96.02,-0.200
34.00,95.91,-0.200
34.03,95.80,-0.201
34.05,95.70,-0.201
34.07,95.59,-0.201
34.09,95.48,-0.201
34.11,95.38,-0.201
34.13,95.27,-0.201
34.16,95.16,-0.201
34.18,95.05,-0.201
34.20,94.94,-0.201
34.22,94.84,-0.201
34.24,94.73,-0.201
34.26,94.62,-0.201
34.29,94.51,-0.201
34.31,94.40,-0.201
34.33,94.29,-0.201
34.35,94.19,-0.201
34.37,94.08,-0.201
34.39,93.97,-0.201
34.41,93.86,-0.201
34.44,93.75,-0.201
34.46,93.65,-0.201
34.48,93.54,-0.201
34.50,93.43,-0.201
34.52,93.32,-0.201
34.54,93.21,-0.201
34.57,93.11,-0.201
34.59,93.00,-0.201
34.61,92.89,-0.201
34.63,92.78,-0.201
34.65,92.67,-0.201
34.68,92.56,-0.201
34.70,92.46,-0.201
34.72,92.35,-0.201
34.74,92.24,-0.201
34.76,92.13,-0.201
34.78,92.02,-0.201
34.81,91.92,-0.201
34.83,91.81,-0.201
34.85,91.70,-0.201
34.87,91.59,-0.201
34.89,91.48,-0.201
34.91,91.37,-0.201
34.94,91.27,-0.201
34.96,91.16,-0.201
34.98,91.05,-0.201
35.00,90.94,-0.201
35.02,90.83,-0.201
35.04,90.72,-0.201
35.06,90.61,-0.201
35.09,90.51,-0.201
35.11,90.40,-0.200
35.13,90.29,-0.200
35.15,90.18,-0.200
35.17,90.08,-0.200
35.19,89.97,-0.200
35.22,89.86,-0.200
35.24,89.75,-0.200
35.26,89.64,-0.200
35.28,89.53,-0.200
35.30,89.43,-0.200
35.33,89.32,-0.200
35.35,89.21,-0.200
35.37,89.10,-0.200
35.39,88.99,-0.200
35.41,88.88,-0.200
35.43,88.78,-0.200
35.46,88.67,-0.200
35.48,88.56,-0.200
35.50,88.45,-0.199
35.52,88.34,-0.199
35.54,88.24,-0.199
35.56,88.13,-0.199
35.59,88.02,-0.199
35.61,87.91,-0.199
35.63,87.80,-0.199
35.65,87.69,-0.199
35.67,87.58,-0.199
35.69,87.48,-0.199
35.71,87.37,-0.199
35.74,87.26,-0.199
35.76,87.15,-0.199
35.78,87.04,-0.199
35.80,86.93,-0.199
35.82,86.83,-0.199
35.84,86.72,-0.199
35.87,86.61,-0.199
35.89,86.50,-0.199
35.91,86.39,-0.199
35.93,86.29,-0.199
35.95,86.18,-0.199
35.98,86.07,-0.198
36.00,85.96,-0.198
36.02,85.85,-0.198
36.04,85.74,-0.198
36.06,85.63,-0.198
36.08,85.53,-0.198
36.11,85.42,-0.198
36.13,85.31,-0.198
36.15,85.20,-0.198
36.17,85.09,-0.198
36.19,84.99,-0.198
36.21,84.88,-0.198
36.24,84.77,-0.198
36.26,84.66,-0.198
36.28,84.55,-0.198
36.30,84.44,-0.198
36.32,84.33,-0.198
36.34,84.23,-0.198
36.36,84.12,-0.198
36.39,84.01,-0.198
36.41,83.90,-0.198
36.43,83.79,-0.198
36.45,83.69,-0.198
36.47,83.58,-0.198
36.49,83.47,-0.197
36.52,83.36,-0.197
36.54,83.25,-0.197
36.56,83.14,-0.197
36.58,83.04,-0.197
36.60,82.93,-0.197
36.63,82.82,-0.197
36.65,82.71,-0.197
36.67,82.60,-0.197
36.69,82.50,-0.197
36.71,82.39,-0.197
36.73,82.28,-0.197
36.76,82.17,-0.197
36.78,82.06,-0.197
36.80,81.95,-0.197
36.82,81.85,-0.197
36.84,81.74,-0.197
36.86,81.63,-0.197
36.89,81.52,-0.197
36.91,81.41,-0.197
36.93,81.31,-0.197
36.95,81.20,-0.197
36.97,81.09,-0.197
36.99,80.98,-0.197
37.01,80.87,-0.197
37.04,80.76,-0.197
37.06,80.65,-0.197
37.08,80.55,-0.197
37.10,80.44,-0.197
37.12,80.33,-0.197
37.14,80.22,-0.197
37.17,80.11,-0.197
37.19,80.00,-0.197
37.21,79.90,-0.197
37.23,79.79,-0.197
37.25,79.68,-0.197
37.28,79.57,-0.196
37.30,79.46,-0.196
37.32,79.36,-0.196
37.34,79.25,-0.196
37.36,79.14,-0.196
37.38,79.03,-0.196
37.41,78.92,-0.196
37.43,78.82,-0.196
37.45,78.71,-0.196
37.47,78.60,-0.196
37.49,78.49,-0.196
37.51,78.38,-0.196
37.54,78.27,-0.196
37.56,78.17,-0.196
37.58,78.06,-0.196
37.60,77.95,-0.196
37.62,77.84,-0.196
37.64,77.73,-0.196
37.66,77.62,-0.196
37.69,77.52,-0.196
37.71,77.41,-0.196
37.73,77.30,-0.196
37.75,77.19,-0.196
37.77,77.08,-0.196
37.79,76.97,-0.196
37.82,76.87,-0.196
37.84,76.76,-0.196
37.86,76.65,-0.195
37.88,76.54,-0.195
37.90,76.43,-0.195
37.93,76.32,-0.195
37.95,76.22,-0.195
37.97,76.11,-0.195
37.99,76.00,-0.195
38.01,75.89,-0.195
38.03,75.78,-0.195
38.06,75.67,-0.195
38.08,75.57,-0.195
38.10,75.46,-0.195
38.12,75.35,-0.195
38.14,75.24,-0.195
38.16,75.13,-0.195
38.19,75.03,-0.195
38.21,74.92,-0.195
38.23,74.81,-0.195
38.25,74.70,-0.195
38.27,74.59,-0.195
38.29,74.48,-0.195
38.31,74.38,-0.195
38.34,74.27,-0.195
38.36,74.16,-0.195
38.38,74.05,-0.195
38.40,73.94,-0.195
38.42,73.83,-0.194
38.44,73.72,-0.194
38.47,73.62,-0.194
38.49,73.51,-0.194
38.51,73.40,-0.194
38.53,73.29,-0.194
38.55,73.18,-0.194
38.58,73.08,-0.194
38.60,72.97,-0.194
38.62,72.86,-0.194
38.64,72.75,-0.194
38.66,72.64,-0.194
38.68,72.53,-0.194
38.71,72.43,-0.194
38.73,72.32,-0.194
38.75,72.21,-0.194
38.77,72.10,-0.194
38.79,71.99,-0.194
38.81,71.88,-0.194
38.84,71.78,-0.194
38.86,71.67,-0.194
38.88,71.56,-0.194
38.90,71.45,-0.194
38.92,71.34,-0.194
38.94,71.24,-0.193
38.96,71.13,-0.193
38.99,71.02,-0.193
39.01,70.91,-0.193
39.03,70.80,-0.193
39.05,70.69,-0.193
39.07,70.59,-0.193
39.09,70.48,-0.193
39.12,70.37,-0.193
39.14,70.26,-0.193
39.16,70.15,-0.193
39.18,70.04,-0.193
39.20,69.94,-0.193
39.23,69.83,-0.193
39.25,69.72,-0.193
39.27,69.61,-0.193
39.29,69.50,-0.193
39.31,69.39,-0.193
39.33,69.29,-0.193
39.36,69.18,-0.193
39.38,69.07,-0.193
39.40,68.96,-0.193
39.42,68.85,-0.193
39.44,68.74,-0.193
39.46,68.64,-0.193
39.49,68.53,-0.193
39.51,68.42,-0.192
39.53,68.31,-0.192
39.55,68.20,-0.192
39.57,68.09,-0.192
39.59,67.99,-0.192
39.61,67.88,-0.192
39.64,67.77,-0.192
39.66,67.66,-0.192
39.68,67.55,-0.192
39.70,67.44,-0.192
39.72,67.34,-0.192
39.74,67.23,-0.192
39.77,67.12,-0.192
39.79,67.01,-0.192
39.81,66.90,-0.192
39.83,66.80,-0.192
39.85,66.69,-0.192
39.88,66.58,-0.192
39.90,66.47,-0.192
39.92,66.36,-0.192
39.94,66.25,-0.192
39.96,66.15,-0.192
39.98,66.04,-0.192
40.01,65.93,-0.192
40.03,65.82,-0.192
40.05,65.71,-0.191
40.07,65.60,-0.191
40.09,65.50,-0.191
40.11,65.39,-0.191
40.14,65.28,-0.191
40.16,65.17,-0.191
40.18,65.06,-0.191
40.20,64.95,-0.191
40.22,64.85,-0.191
40.24,64.74,-0.191
40.26,64.63,-0.191
40.29,64.52,-0.191
40.31,64.41,-0.191
40.33,64.31,-0.191
40.35,64.20,-0.191
40.37,64.09,-0.191
40.39,63.98,-0.191
40.42,63.87,-0.191
40.44,63.76,-0.191
40.46,63.66,-0.191
40.48,63.55,-0.191
40.50,63.44,-0.191
40.53,63.33,-0.191
40.55,63.22,-0.191
40.57,63.11,-0.191
40.59,63.00,-0.191
40.61,62.90,-0.191
40.63,62.79,-0.190
40.66,62.68,-0.190
40.68,62.57,-0.190
40.70,62.46,-0.190
40.72,62.36,-0.190
40.74,62.25,-0.190
40.76,62.14,-0.190
40.79,62.03,-0.190
40.81,61.92,-0.190
40.83,61.81,-0.190
40.85,61.71,-0.190
40.87,61.60,-0.190
40.89,61.49,-0.190
40.91,61.38,-0.190
40.94,61.27,-0.190
40.96,61.16,-0.190
40.98,61.06,-0.190
41.00,60.95,-0.190
41.02,60.84,-0.190
41.04,60.73,-0.190
41.07,60.62,-0.190
41.09,60.51,-0.190
41.11,60.41,-0.190
41.13,60.30,-0.190
41.15,60.19,-0.190
[...]
136.16,-39.94,0.088
136.17,-39.87,0.088
136.19,-39.80,0.088
136.20,-39.74,0.088
136.21,-39.67,0.088
136.23,-39.60,0.088
136.24,-39.54,0.088
136.25,-39.47,0.088
136.27,-39.40,0.088
136.28,-39.34,0.088
136.29,-39.27,0.088
136.31,-39.20,0.088
136.32,-39.14,0.088
136.33,-39.07,0.088
136.35,-39.00,0.088
136.36,-38.94,0.088
136.37,-38.87,0.088
136.39,-38.80,0.088
136.40,-38.74,0.088
136.41,-38.67,0.088
136.43,-38.60,0.088
136.44,-38.54,0.088
136.45,-38.47,0.088
136.47,-38.40,0.088
136.48,-38.34,0.088
136.49,-38.27,0.089
136.51,-38.20,0.089
136.52,-38.14,0.089
136.53,-38.07,0.089
136.55,-38.00,0.089
136.56,-37.93,0.089
136.57,-37.87,0.089
136.59,-37.80,0.089
136.60,-37.73,0.089
136.61,-37.67,0.089
136.63,-37.60,0.089
136.64,-37.53,0.089
136.65,-37.47,0.089
136.67,-37.40,0.089
136.68,-37.33,0.089
136.69,-37.27,0.089
136.71,-37.20,0.089
136.72,-37.13,0.089
136.73,-37.07,0.089
136.75,-37.00,0.089
136.76,-36.93,0.089
136.77,-36.87,0.089
136.79,-36.80,0.089
136.80,-36.73,0.089
136.81,-36.66,0.089
136.83,-36.60,0.089
136.84,-36.53,0.089
136.85,-36.47,0.089
136.87,-36.40,0.089
136.88,-36.33,0.089
136.89,-36.27,0.089
136.91,-36.20,0.089
136.92,-36.13,0.089
136.93,-36.07,0.089
136.95,-36.00,0.089
136.96,-35.93,0.089
136.97,-35.86,0.089
136.99,-35.80,0.089
137.00,-35.73,0.089
137.01,-35.66,0.089
137.03,-35.60,0.089
137.04,-35.53,0.089
137.05,-35.46,0.090
137.07,-35.40,0.090
137.08,-35.33,0.090
137.09,-35.26,0.090
137.11,-35.20,0.090
137.12,-35.13,0.090
137.13,-35.06,0.090
137.15,-35.00,0.090
137.16,-34.93,0.090
137.17,-34.86,0.090
137.19,-34.80,0.090
137.20,-34.73,0.090
137.21,-34.66,0.090
137.23,-34.60,0.090
137.24,-34.53,0.090
137.25,-34.46,0.090
137.27,-34.40,0.090
137.28,-34.33,0.090
137.29,-34.26,0.090
137.31,-34.20,0.090
137.32,-34.13,0.090
137.33,-34.06,0.090
137.35,-34.00,0.090
137.36,-33.93,0.090
137.37,-33.86,0.090
137.39,-33.80,0.090
137.40,-33.73,0.090
137.41,-33.66,0.090
137.43,-33.60,0.090
137.44,-33.53,0.090
137.45,-33.46,0.090
137.47,-33.40,0.090
137.48,-33.33,0.090
137.49,-33.26,0.090
137.51,-33.20,0.090
137.52,-33.13,0.090
137.53,-33.06,0.090
137.55,-33.00,0.090
137.56,-32.93,0.090
137.57,-32.86,0.090
137.59,-32.80,0.090
137.60,-32.73,0.090
137.61,-32.66,0.091
137.63,-32.60,0.091
137.64,-32.53,0.091
137.65,-32.46,0.091
137.67,-32.39,0.091
137.68,-32.33,0.091
137.69,-32.26,0.091
137.71,-32.19,0.091
137.72,-32.13,0.091
137.73,-32.06,0.091
137.75,-31.99,0.091
137.76,-31.93,0.091
137.77,-31.86,0.091
137.79,-31.79,0.091
137.80,-31.73,0.091
137.81,-31.66,0.091
137.83,-31.59,0.091
137.84,-31.53,0.091
137.85,-31.46,0.091
137.87,-31.39,0.091
137.88,-31.33,0.091
137.89,-31.26,0.091
137.91,-31.19,0.091
137.92,-31.13,0.091
137.93,-31.06,0.091
137.95,-30.99,0.091
137.96,-30.93,0.091
137.97,-30.86,0.091
137.99,-30.79,0.091
138.00,-30.73,0.091
138.01,-30.66,0.091
138.03,-30.59,0.091
138.04,-30.53,0.091
138.05,-30.46,0.091
138.07,-30.39,0.091
138.08,-30.33,0.091
138.09,-30.26,0.091
138.11,-30.19,0.091
138.12,-30.13,0.091
138.13,-30.06,0.091
138.15,-29.99,0.091
138.16,-29.93,0.091
138.17,-29.86,0.091
138.19,-29.79,0.091
138.20,-29.73,0.092
138.21,-29.66,0.092
138.23,-29.59,0.092
138.24,-29.53,0.092
138.25,-29.46,0.092
138.27,-29.39,0.092
138.28,-29.33,0.092
138.29,-29.26,0.092
138.31,-29.19,0.092
138.32,-29.13,0.092
138.33,-29.06,0.092
138.35,-28.99,0.092
138.36,-28.93,0.092
138.37,-28.86,0.092
138.39,-28.79,0.092
138.40,-28.72,0.092
138.41,-28.66,0.092
138.43,-28.59,0.092
138.44,-28.53,0.092
138.45,-28.46,0.092
138.47,-28.39,0.092
138.48,-28.32,0.092
138.49,-28.26,0.092
138.51,-28.19,0.092
138.52,-28.12,0.092
138.53,-28.06,0.092
138.55,-27.99,0.092
138.56,-27.93,0.092
138.57,-27.86,0.092
138.59,-27.79,0.092
138.60,-27.73,0.092
138.61,-27.66,0.092
138.63,-27.59,0.092
138.64,-27.53,0.092
138.65,-27.46,0.092
138.67,-27.39,0.092
138.68,-27.33,0.092
138.69,-27.26,0.092
138.71,-27.19,0.092
138.72,-27.12,0.093
138.73,-27.06,0.093
138.75,-26.99,0.093
138.76,-26.93,0.093
138.77,-26.86,0.093
138.79,-26.79,0.093
138.80,-26.72,0.093
138.81,-26.66,0.093
138.83,-26.59,0.093
138.84,-26.53,0.093
138.85,-26.46,0.093
138.87,-26.39,0.093
138.88,-26.33,0.093
138.89,-26.26,0.093
138.91,-26.19,0.093
138.92,-26.12,0.093
138.93,-26.06,0.093
138.95,-25.99,0.093
138.96,-25.92,0.093
138.97,-25.86,0.093
138.99,-25.79,0.093
139.00,-25.73,0.093
139.01,-25.66,0.093
139.03,-25.59,0.093
139.04,-25.52,0.093
139.05,-25.46,0.093
139.07,-25.39,0.093
139.08,-25.32,0.093
139.09,-25.26,0.093
139.11,-25.19,0.093
139.12,-25.12,0.093
139.13,-25.06,0.093
139.15,-24.99,0.093
139.16,-24.92,0.094
139.17,-24.86,0.094
139.19,-24.79,0.094
139.20,-24.72,0.094
139.21,-24.66,0.094
139.23,-24.59,0.094
139.24,-24.52,0.094
139.25,-24.46,0.094
139.27,-24.39,0.094
139.28,-24.32,0.094
139.29,-24.26,0.094
139.31,-24.19,0.094
139.32,-24.12,0.094
139.33,-24.05,0.094
139.35,-23.99,0.094
139.36,-23.92,0.094
139.37,-23.85,0.094
139.39,-23.79,0.094
139.40,-23.72,0.094
139.41,-23.65,0.094
139.43,-23.59,0.094
139.44,-23.52,0.094
139.45,-23.46,0.094
139.47,-23.39,0.094
139.48,-23.32,0.094
139.49,-23.26,0.094
139.51,-23.19,0.094
139.52,-23.12,0.094
139.53,-23.05,0.094
139.55,-22.99,0.094
139.56,-22.92,0.094
139.57,-22.85,0.094
139.59,-22.79,0.094
139.60,-22.72,0.094
139.61,-22.65,0.094
139.63,-22.59,0.094
139.64,-22.52,0.094
139.65,-22.45,0.094
139.67,-22.39,0.095
139.68,-22.32,0.095
139.69,-22.25,0.095
139.71,-22.19,0.095
139.72,-22.12,0.095
139.73,-22.05,0.095
139.75,-21.99,0.095
139.76,-21.92,0.095
139.77,-21.85,0.095
139.79,-21.79,0.095
139.80,-21.72,0.095
139.81,-21.65,0.095
139.83,-21.59,0.095
139.84,-21.52,0.095
139.85,-21.45,0.095
139.87,-21.39,0.095
139.88,-21.32,0.095
139.89,-21.25,0.095
139.91,-21.19,0.095
139.92,-21.12,0.095
139.93,-21.05,0.095
139.95,-20.99,0.095
139.96,-20.92,0.095
139.97,-20.85,0.095
139.99,-20.79,0.095
140.00,-20.72,0.095
140.01,-20.65,0.095
140.03,-20.59,0.095
140.04,-20.52,0.095
140.05,-20.45,0.095
140.07,-20.39,0.095
140.08,-20.32,0.095
140.09,-20.25,0.095
140.11,-20.19,0.095
140.12,-20.12,0.096
140.13,-20.05,0.096
140.15,-19.99,0.096
140.16,-19.92,0.096
140.17,-19.85,0.096
140.19,-19.79,0.096
140.20,-19.72,0.096
140.21,-19.65,0.096
140.23,-19.59,0.096
140.24,-19.52,0.096
140.25,-19.45,0.096
140.27,-19.39,0.096
140.28,-19.32,0.096
140.29,-19.25,0.096
140.31,-19.19,0.096
140.32,-19.12,0.096
140.33,-19.05,0.096
140.35,-18.99,0.096
140.36,-18.92,0.096
140.37,-18.85,0.096
140.39,-18.79,0.096
140.40,-18.72,0.096
140.41,-18.65,0.096
140.43,-18.58,0.096
140.44,-18.52,0.096
140.45,-18.45,0.096
140.47,-18.38,0.096
140.48,-18.32,0.096
140.49,-18.25,0.096
140.51,-18.19,0.096
140.52,-18.12,0.096
140.53,-18.05,0.096
140.55,-17.98,0.096
140.56,-17.92,0.097
140.57,-17.85,0.097
140.59,-17.78,0.097
140.60,-17.72,0.097
140.61,-17.65,0.097
140.63,-17.58,0.097
140.64,-17.52,0.097
140.65,-17.45,0.097
140.67,-17.38,0.097
140.68,-17.32,0.097
140.69,-17.25,0.097
140.71,-17.18,0.097
140.72,-17.12,0.097
140.73,-17.05,0.097
140.75,-16.98,0.097
140.76,-16.92,0.097
140.77,-16.85,0.097
140.79,-16.78,0.097
140.80,-16.72,0.097
140.81,-16.65,0.097
140.83,-16.58,0.097
140.84,-16.52,0.097
140.85,-16.45,0.097
140.87,-16.38,0.097
140.88,-16.32,0.097
140.89,-16.25,0.097
140.91,-16.18,0.098
140.92,-16.12,0.098
140.93,-16.05,0.098
140.95,-15.98,0.098
140.96,-15.92,0.098
140.97,-15.85,0.098
140.99,-15.78,0.098
141.00,-15.72,0.098
141.01,-15.65,0.098
141.03,-15.58,0.098
141.04,-15.52,0.098
141.05,-15.45,0.098
141.07,-15.38,0.098
141.08,-15.32,0.098
141.09,-15.25,0.098
141.11,-15.18,0.098
141.12,-15.12,0.098
141.13,-15.05,0.098
141.15,-14.98,0.098
141.16,-14.92,0.098
141.17,-14.85,0.098
141.19,-14.78,0.098
141.20,-14.72,0.098
141.21,-14.65,0.098
141.23,-14.58,0.099
141.24,-14.52,0.099
141.25,-14.45,0.099
141.27,-14.38,0.099
141.28,-14.32,0.099
141.29,-14.25,0.099
141.31,-14.18,0.099
141.32,-14.12,0.099
141.33,-14.05,0.099
141.35,-13.98,0.099
141.36,-13.92,0.099
141.37,-13.85,0.099
141.39,-13.78,0.099
141.40,-13.72,0.099
141.41,-13.65,0.099
141.43,-13.58,0.099
141.44,-13.52,0.099
141.45,-13.45,0.099
141.47,-13.38,0.099
141.48,-13.32,0.099
141.49,-13.25,0.099
141.51,-13.18,0.100
141.52,-13.12,0.100
141.53,-13.05,0.100
141.55,-12.98,0.100
141.56,-12.92,0.100
141.57,-12.85,0.100
141.59,-12.78,0.100
141.60,-12.72,0.100
141.61,-12.65,0.100
141.63,-12.58,0.100
141.64,-12.52,0.100
141.65,-12.45,0.100
141.67,-12.38,0.100
141.68,-12.32,0.100
141.69,-12.25,0.100
141.71,-12.18,0.100
141.72,-12.12,0.100
141.73,-12.05,0.100
141.75,-11.98,0.101
141.76,-11.92,0.101
141.77,-11.85,0.101
141.79,-11.78,0.101
141.80,-11.72,0.101
141.81,-11.65,0.101
141.83,-11.58,0.101
141.84,-11.52,0.101
141.85,-11.45,0.101
141.87,-11.38,0.101
141.88,-11.32,0.101
141.89,-11.25,0.101
141.91,-11.18,0.101
141.92,-11.12,0.101
141.93,-11.05,0.101
141.95,-10.98,0.102
141.96,-10.92,0.102
141.97,-10.85,0.102
141.99,-10.78,0.102
142.00,-10.72,0.102
142.01,-10.65,0.102
142.03,-10.58,0.102
142.04,-10.52,0.102
142.05,-10.45,0.102
142.07,-10.38,0.102
142.08,-10.32,0.102
142.09,-10.25,0.102
142.11,-10.18,0.102
142.12,-10.12,0.102
142.13,-10.05,0.103
142.15,-9.98,0.103
142.16,-9.92,0.103
142.17,-9.85,0.103
142.19,-9.78,0.103
142.20,-9.72,0.103
142.21,-9.65,0.103
142.23,-9.58,0.103
142.24,-9.52,0.103
142.25,-9.45,0.103
142.27,-9.38,0.103
142.28,-9.32,0.103
142.29,-9.25,0.104
142.31,-9.18,0.104
142.32,-9.12,0.104
142.33,-9.05,0.104
142.35,-8.98,0.104
142.36,-8.92,0.104
142.37,-8.85,0.104
142.39,-8.78,0.104
142.40,-8.72,0.104
142.41,-8.65,0.105
142.43,-8.58,0.105
142.44,-8.52,0.105
142.45,-8.45,0.105
142.47,-8.38,0.105
142.48,-8.32,0.105
142.49,-8.25,0.105
142.51,-8.18,0.105
142.52,-8.12,0.106
142.53,-8.05,0.106
142.55,-7.98,0.106
142.56,-7.92,0.106
142.57,-7.85,0.106
142.59,-7.78,0.106
142.60,-7.72,0.106
142.61,-7.65,0.106
142.63,-7.59,0.107
142.64,-7.52,0.107
142.65,-7.45,0.107
142.67,-7.39,0.107
142.68,-7.32,0.107
142.69,-7.25,0.107
142.71,-7.18,0.108
142.72,-7.12,0.108
142.73,-7.05,0.108
142.75,-6.99,0.108
142.76,-6.92,0.108
142.77,-6.85,0.108
142.79,-6.79,0.108
142.80,-6.72,0.108
142.81,-6.65,0.109
142.83,-6.59,0.109
142.84,-6.52,0.109
142.85,-6.45,0.109
142.87,-6.39,0.109
142.88,-6.32,0.109
142.89,-6.25,0.110
142.91,-6.19,0.110
142.92,-6.12,0.110
142.93,-6.05,0.110
142.95,-5.99,0.110
142.96,-5.92,0.111
142.97,-5.85,0.111
142.99,-5.79,0.111
143.00,-5.72,0.111
143.01,-5.66,0.111
143.03,-5.59,0.112
143.04,-5.52,0.112
143.05,-5.46,0.112
143.07,-5.39,0.112
143.08,-5.32,0.112
143.09,-5.26,0.113
143.11,-5.19,0.113
143.12,-5.12,0.114
143.13,-5.06,0.114
143.15,-4.99,0.114
143.16,-4.92,0.114
143.17,-4.86,0.115
143.19,-4.79,0.115
143.20,-4.72,0.115
143.21,-4.66,0.115
143.23,-4.59,0.116
143.24,-4.53,0.116
143.25,-4.46,0.116
143.27,-4.39,0.117
143.28,-4.32,0.117
143.29,-4.26,0.117
143.31,-4.19,0.118
143.32,-4.13,0.118
143.33,-4.06,0.118
143.35,-3.99,0.119
143.36,-3.93,0.119
143.37,-3.86,0.119
143.39,-3.79,0.120
143.40,-3.73,0.120
143.41,-3.66,0.120
143.43,-3.59,0.121
143.44,-3.53,0.121
143.45,-3.46,0.122
143.47,-3.40,0.122
143.48,-3.33,0.122
143.49,-3.26,0.123
143.51,-3.20,0.123
143.52,-3.13,0.124
143.53,-3.06,0.124
143.55,-3.00,0.124
143.56,-2.93,0.125
143.57,-2.86,0.125
143.59,-2.80,0.125
143.60,-2.73,0.126
143.61,-2.67,0.126
143.63,-2.60,0.127
143.64,-2.53,0.127
143.65,-2.47,0.128
143.67,-2.40,0.128
143.68,-2.33,0.129
143.69,-2.27,0.129
143.71,-2.20,0.129
143.72,-2.13,0.130
143.73,-2.07,0.130
143.75,-2.00,0.131
143.76,-1.94,0.131
143.77,-1.87,0.132
143.79,-1.80,0.132
143.80,-1.74,0.132
143.81,-1.67,0.133
143.83,-1.60,0.133
143.84,-1.54,0.134
143.85,-1.47,0.134
143.87,-1.40,0.134
143.88,-1.34,0.135
143.89,-1.27,0.135
143.91,-1.21,0.136
143.92,-1.14,0.136
143.93,-1.07,0.137
143.95,-1.01,0.137
143.96,-0.94,0.138
143.97,-0.87,0.138
143.99,-0.81,0.139
144.00,-0.74,0.139
144.01,-0.67,0.139
144.03,-0.61,0.140
144.04,-0.54,0.140
144.05,-0.47,0.140
144.07,-0.41,0.141
144.08,-0.34,0.141
144.09,-0.27,0.141
144.11,-0.21,0.142
144.12,-0.14,0.142
144.13,-0.08,0.142
144.15,-0.01,0.143
144.16,0.06,0.143
144.17,0.12,0.143
144.19,0.19,0.143
144.20,0.26,0.143
144.21,0.32,0.144
144.23,0.39,0.144
144.24,0.46,0.144
144.25,0.52,0.144
144.27,0.59,0.145
144.28,0.65,0.145
144.29,0.72,0.145
144.31,0.79,0.145
144.32,0.85,0.145
144.33,0.92,0.145
144.35,0.99,0.146
144.36,1.06,0.146
144.37,1.12,0.146
144.39,1.19,0.146
144.40,1.25,0.146
144.41,1.32,0.146
144.43,1.39,0.146
144.44,1.45,0.146
144.45,1.52,0.146
144.47,1.59,0.147
144.48,1.65,0.147
144.49,1.72,0.147
144.51,1.79,0.147
144.52,1.86,0.147
144.53,1.92,0.147
144.55,1.99,0.147
144.56,2.06,0.147
144.57,2.12,0.147
144.59,2.19,0.147
144.60,2.26,0.147
144.61,2.32,0.147
144.63,2.39,0.147
144.64,2.46,0.147
144.65,2.52,0.147
144.67,2.59,0.147
144.68,2.66,0.147
144.69,2.73,0.147
144.71,2.79,0.147
144.72,2.86,0.147
144.73,2.93,0.147
144.75,2.99,0.147
144.76,3.06,0.147
144.77,3.13,0.147
144.79,3.19,0.146
144.80,3.26,0.146
144.81,3.33,0.146
144.83,3.39,0.146
144.84,3.46,0.146
144.85,3.53,0.146
144.87,3.60,0.146
144.88,3.66,0.145
144.89,3.73,0.145
144.91,3.80,0.145
144.92,3.86,0.145
144.93,3.93,0.145
144.95,4.00,0.145
144.96,4.06,0.144
144.97,4.13,0.144
144.99,4.20,0.144
145.00,4.26,0.144
145.01,4.33,0.144
145.03,4.40,0.143
145.04,4.46,0.143
145.05,4.53,0.143
145.07,4.60,0.143
145.08,4.67,0.143
145.09,4.73,0.143
145.11,4.80,0.143
145.12,4.87,0.143
145.13,4.93,0.142
145.15,5.00,0.142
145.16,5.06,0.142
145.17,5.13,0.142
145.19,5.20,0.142
145.20,5.26,0.142
145.21,5.33,0.142
145.23,5.40,0.142
145.24,5.47,0.141
145.25,5.53,0.141
145.27,5.60,0.141
145.28,5.67,0.141
145.29,5.73,0.141
145.31,5.80,0.141
145.32,5.87,0.141
145.33,5.93,0.141
145.35,6.00,0.141
145.36,6.07,0.141
145.37,6.13,0.141
145.39,6.20,0.141
145.40,6.27,0.140
145.41,6.33,0.140
145.43,6.40,0.140
145.44,6.47,0.140
145.45,6.53,0.140
145.47,6.60,0.140
145.48,6.67,0.140
145.49,6.73,0.140
145.51,6.80,0.140
145.52,6.87,0.140
145.53,6.94,0.140
145.55,7.00,0.140
145.56,7.07,0.140
145.57,7.14,0.140
145.59,7.20,0.140
145.60,7.27,0.140
145.61,7.34,0.140
145.63,7.40,0.140
145.64,7.47,0.140
145.65,7.54,0.140
145.67,7.60,0.140
145.68,7.67,0.140
145.69,7.74,0.140
145.71,7.80,0.140
145.72,7.87,0.140
145.73,7.94,0.140
145.75,8.00,0.140
145.76,8.07,0.140
145.77,8.14,0.140
145.79,8.20,0.140
145.80,8.27,0.140
145.81,8.34,0.140
145.83,8.40,0.140
145.84,8.47,0.140
145.85,8.54,0.140
145.87,8.60,0.140
145.88,8.67,0.140
145.89,8.74,0.140
145.91,8.80,0.140
145.92,8.87,0.140
145.93,8.94,0.140
145.95,9.00,0.140
145.96,9.07,0.140
145.97,9.14,0.140
145.99,9.20,0.140
146.00,9.27,0.140
146.01,9.34,0.140
146.03,9.40,0.140
146.04,9.47,0.140
146.05,9.54,0.140
146.07,9.60,0.140
146.08,9.67,0.140
146.09,9.74,0.140
146.11,9.80,0.140
146.12,9.87,0.140
146.13,9.94,0.140
146.15,10.00,0.140
146.16,10.07,0.140
146.17,10.14,0.140
146.19,10.20,0.140
146.20,10.27,0.140
146.21,10.34,0.140
146.23,10.40,0.140
146.24,10.47,0.140
146.25,10.54,0.140
146.27,10.60,0.140
146.28,10.67,0.140
146.29,10.74,0.140
146.31,10.80,0.140
146.32,10.87,0.140
146.33,10.94,0.140
146.35,11.00,0.140
146.36,11.07,0.140
146.37,11.14,0.140
146.39,11.21,0.140
146.40,11.27,0.140
146.41,11.34,0.140
146.43,11.41,0.140
146.44,11.47,0.140
146.45,11.54,0.140
146.47,11.61,0.140
146.48,11.67,0.140
146.49,11.74,0.140
146.51,11.81,0.140
146.52,11.87,0.140
146.53,11.94,0.140
146.55,12.01,0.140
146.56,12.07,0.140
146.57,12.14,0.140
146.59,12.21,0.140
146.60,12.27,0.140
146.61,12.34,0.140
146.63,12.41,0.140
146.64,12.47,0.140
146.65,12.54,0.140
146.67,12.61,0.140
146.68,12.67,0.140
146.69,12.74,0.140
146.71,12.81,0.140
146.72,12.87,0.140
146.73,12.94,0.140
146.75,13.01,0.140
146.76,13.07,0.140
146.77,13.14,0.140
146.79,13.21,0.140
146.80,13.27,0.140
146.81,13.34,0.140
146.83,13.41,0.141
146.84,13.47,0.141
146.85,13.54,0.141
146.87,13.61,0.141
146.88,13.67,0.141
146.89,13.74,0.141
146.91,13.81,0.141
146.92,13.87,0.141
146.93,13.94,0.141
146.95,14.01,0.141
146.96,14.07,0.141
146.97,14.14,0.141
146.99,14.21,0.141
147.00,14.27,0.141
147.01,14.34,0.141
147.03,14.41,0.141
147.04,14.47,0.141
147.05,14.54,0.141
147.07,14.61,0.141
147.08,14.67,0.141
147.09,14.74,0.141
147.11,14.81,0.141
147.12,14.87,0.141
147.13,14.94,0.141
147.15,15.01,0.141
147.16,15.07,0.141
147.17,15.14,0.141
147.19,15.21,0.141
147.20,15.27,0.141
147.21,15.34,0.141
147.23,15.41,0.141
147.24,15.48,0.141
147.25,15.54,0.141
147.27,15.61,0.141
147.28,15.67,0.141
147.29,15.74,0.141
147.31,15.81,0.141
147.32,15.88,0.141
147.33,15.94,0.141
147.35,16.01,0.141
147.36,16.07,0.141
147.37,16.14,0.141
147.39,16.21,0.141
147.40,16.27,0.141
147.41,16.34,0.141
147.43,16.41,0.141
147.44,16.47,0.141
147.45,16.54,0.141
147.47,16.61,0.141
147.48,16.68,0.142
147.49,16.74,0.142
147.51,16.81,0.142
147.52,16.88,0.142
147.53,16.94,0.142
147.55,17.01,0.142
147.56,17.08,0.142
147.57,17.14,0.142
147.59,17.21,0.142
147.60,17.28,0.142
147.61,17.34,0.142
147.63,17.41,0.142
147.64,17.48,0.142
147.65,17.54,0.142
147.67,17.61,0.142
147.68,17.68,0.142
147.69,17.74,0.142
147.71,17.81,0.142
147.72,17.88,0.142
147.73,17.94,0.142
147.75,18.01,0.142
147.76,18.08,0.142
147.77,18.14,0.142
147.79,18.21,0.142
147.80,18.28,0.142
147.81,18.34,0.142
147.83,18.41,0.142
147.84,18.48,0.142
147.85,18.54,0.142
147.87,18.61,0.142
147.88,18.68,0.142
147.89,18.74,0.142
147.91,18.81,0.142
147.92,18.88,0.142
147.93,18.94,0.142
147.95,19.01,0.142
147.96,19.08,0.142
147.97,19.14,0.142
147.99,19.21,0.142
148.00,19.28,0.142
148.01,19.34,0.142
148.03,19.41,0.142
148.04,19.48,0.142
148.05,19.54,0.142
148.07,19.61,0.142
148.08,19.68,0.142
148.09,19.74,0.142
148.11,19.81,0.142
148.12,19.88,0.143
148.13,19.95,0.143
148.15,20.01,0.143
148.16,20.08,0.143
148.17,20.15,0.143
148.19,20.21,0.143
148.20,20.28,0.143
148.21,20.34,0.143
148.23,20.41,0.143
148.24,20.48,0.143
148.25,20.54,0.143
148.27,20.61,0.143
148.28,20.68,0.143
148.29,20.75,0.143
148.31,20.81,0.143
148.32,20.88,0.143
148.33,20.94,0.143
148.35,21.01,0.143
148.36,21.08,0.143
148.37,21.15,0.143
148.39,21.21,0.143
148.40,21.28,0.143
148.41,21.35,0.143
148.43,21.41,0.143
148.44,21.48,0.143
148.45,21.55,0.143
148.47,21.61,0.143
148.48,21.68,0.143
148.49,21.75,0.143
148.51,21.81,0.143
148.52,21.88,0.143
148.53,21.94,0.143
148.55,22.01,0.143
148.56,22.08,0.143
148.57,22.14,0.143
148.59,22.21,0.143
148.60,22.28,0.143
148.61,22.34,0.143
148.63,22.41,0.143
148.64,22.48,0.143
148.65,22.55,0.143
148.67,22.61,0.143
148.68,22.68,0.143
148.69,22.75,0.143
148.71,22.81,0.143
148.72,22.88,0.143
148.73,22.95,0.143
148.75,23.01,0.143
148.76,23.08,0.143
148.77,23.15,0.143
148.79,23.21,0.143
148.80,23.28,0.144
148.81,23.35,0.144
148.83,23.41,0.144
148.84,23.48,0.144
148.85,23.55,0.144
148.87,23.61,0.144
148.88,23.68,0.144
148.89,23.75,0.144
148.91,23.81,0.144
148.92,23.88,0.144
148.93,23.95,0.144
148.95,24.01,0.144
148.96,24.08,0.144
148.97,24.15,0.144
148.99,24.21,0.144
149.00,24.28,0.144
149.01,24.35,0.144
149.03,24.41,0.144
149.04,24.48,0.144
149.05,24.55,0.144
149.07,24.61,0.144
149.08,24.68,0.144
149.09,24.75,0.144
149.11,24.82,0.144
149.12,24.88,0.144
149.13,24.95,0.144
149.15,25.01,0.144
149.16,25.08,0.144
149.17,25.15,0.144
149.19,25.21,0.144
149.20,25.28,0.144
149.21,25.35,0.144
149.23,25.42,0.144
149.24,25.48,0.144
149.25,25.55,0.144
149.27,25.62,0.144
149.28,25.68,0.144
149.29,25.75,0.144
149.31,25.82,0.144
149.32,25.88,0.144
149.33,25.95,0.144
149.35,26.02,0.144
149.36,26.08,0.144
149.37,26.15,0.144
149.39,26.22,0.144
149.40,26.28,0.145
149.41,26.35,0.145
149.43,26.42,0.145
149.44,26.48,0.145
149.45,26.55,0.145
149.47,26.62,0.145
149.48,26.68,0.145
149.49,26.75,0.145
149.51,26.82,0.145
149.52,26.88,0.145
149.53,26.95,0.145
149.55,27.02,0.145
149.56,27.08,0.145
149.57,27.15,0.145
149.59,27.22,0.145
149.60,27.28,0.145
149.61,27.35,0.145
149.63,27.42,0.145
149.64,27.48,0.145
149.65,27.55,0.145
149.67,27.62,0.145
149.68,27.69,0.145
149.69,27.75,0.145
149.71,27.82,0.145
149.72,27.88,0.145
149.73,27.95,0.145
149.75,28.02,0.145
149.76,28.09,0.145
149.77,28.15,0.145
149.79,28.22,0.145
149.80,28.28,0.145
149.81,28.35,0.145
149.83,28.42,0.145
149.84,28.48,0.145
149.85,28.55,0.145
149.87,28.62,0.145
149.88,28.68,0.145
149.89,28.75,0.145
149.91,28.82,0.145
149.92,28.88,0.145
149.93,28.95,
149.95,29.02,
149.96,29.09,
149.97,29.15,
149.98,,