File: DSC/2025_05_08_CBN_IsonicoticAcid_MC_n60C_170C_5Cmin_x3.csv
Filename,2025_05_08_CBN_IsonicoticAcid_MC_n60C_170C_5Cmin_x3
Instrument name,DSC2A-00468 (192.168.1.100)
Operator,Yarger
rundate,5/9/2025
Sample name,2025_05_08_CBN_IsonicoticAcid_MC_n60C_170C_5Cmin_x3
proceduresegments,Data Off ; Equilibrate -60.00 °C; Data On ; Ramp 5.00 °C/min to 170.00 °C; Data Off ; Isothermal 1.0 min; Data On ; Ramp 5.00 °C/min to -60.00 °C; Data Off ; Isothermal 1.0 min; Data On ; Ramp 5.00 °C/min to 170.00 °C; Data Off ; Isothermal 1.0 min; Data On ; Ramp 5.00 °C/min to -60.00 °C; Data Off ; Isothermal 1.0 min; Data On ; Ramp 5.00 °C/min to 30.00 °C
[File Parameters]
Run date,5/9/2025 9:23:42 AM
Trios version,5.1.1.46572
Original File Name,
Current File Name,D:\DSC2500\JYarger\2025_05_08_CBN_IsonicoticAcid_MC_n60C_170C_5Cmin_x3.tri
[Procedure]
Procedure Name,CBN_INA_n60C_170C_5Cmin_x3
Sample Name,2025_05_08_CBN_IsonicoticAcid_MC_n60C_170C_5Cmin_x3
Sample Mass,587 mg
Reference Sample Mass,0 mg
Pan Mass,57.12 mg
Pan Number,32
Reference Pan Mass,57.13 mg
Reference Pan Number,37
Pan Type,Tzero Aluminum Hermetic
Comments,Al Hermetic DSC Consumables sealed Pan/Lid. Y2 Tray (Google Sheet: DSC_Samples_Vext_Y2_Tray_May2025)
Project Name,CA
Operator,Yarger
Test,Custom
Unload Max Temperature,30
Unload Min Temperature,30
Load Max Temperature,30
Load Min Temperature,30
Stop on Gas Flow Error,Yes
[Signal List]
Signal #1,Time (min)
Signal #2,Temperature (°C)
Signal #3,Heat Flow (mW)
Signal #4,Delta T (µV)
Signal #5,Delta Tzero (µV)
Signal #6,Tzero Temperature (°C)
Signal #7,Cell Purge (mL/min)
Signal #8,Heater Temp (°C)
Signal #9,Power Delivered (W)
Signal #10,Reference Junction Temperature (°C)
Signal #11,Flange Temperature (°C)
Signal #12,Heat Flow Phase (rad)
Signal #13,Total Heat Capacity (J/°C)
Signal #14,Heat Capacity (J/°C)
[Configuration]
Company Name,ASU
Instrument Name,DSC2A-00468
Instrument Type,DSC2500
Serial Number,DSC2A-00468
IP,192.168.1.100
Location of Instrument,MRRC
DisplayType,Unknown
Sample Interval ,0.1 s/pt
Selected Heat Flow,T4P
Exotherm Direction,Down
Cell Serial,DRC2-00792
Lid Type,Standard
Cooler,RCS 90
Leave Cooler on at End of Sequence,On
Gas 2,Nitrogen
Gas Selected,Channel 1
Flow Rate,50 mL/min
Secondary Purge,On
Licensed Heat Flow,Heat Flow T4P
Modulation Licensed,Yes
[Versions]
Common IDD Version,1
Cortex Version,VER 2.10.2.31
Driver,5.0.0.6
GDM Version,1.0.3.3
TouchscreenVersion,1.0.0.16145
FEP Version,1.2.1.21
FEP Bootloader,2.0.0.5
AutoSampler Version,2.1.1.26
Auto Sampler Bootloader,2.0.0.5
FCM Version,1.1.0.3
FCM Bootloader,2.0.0.5
[Experiment Logs]
Experiment Log Entry # 1,Data On set to 0
Experiment Log Entry # 3,Equilibrate Segment -60 (C) Started
Experiment Log Entry # 5,Air Cool is off.
Experiment Log Entry # 7,Data On set to 1
Experiment Log Entry # 9,Ramp Segment 5 C/min to 170 Started
Experiment Log Entry # 11,Data On set to 0
Experiment Log Entry # 13,Isothermal Segment 1 min started
Experiment Log Entry # 15,Data On set to 1
Experiment Log Entry # 17,Ramp Segment 5 C/min to -60 Started
Experiment Log Entry # 19,Data On set to 0
Experiment Log Entry # 21,Isothermal Segment 1 min started
Experiment Log Entry # 23,Data On set to 1
Experiment Log Entry # 25,Ramp Segment 5 C/min to 170 Started
Experiment Log Entry # 27,Data On set to 0
Experiment Log Entry # 29,Isothermal Segment 1 min started
Experiment Log Entry # 31,Data On set to 1
Experiment Log Entry # 33,Ramp Segment 5 C/min to -60 Started
Experiment Log Entry # 35,Data On set to 0
Experiment Log Entry # 37,Isothermal Segment 1 min started
Experiment Log Entry # 39,Data On set to 1
Experiment Log Entry # 41,Ramp Segment 5 C/min to 30 Started
[Method Log]
Method Log Entry # 1,Data Off
Method Log Entry # 2,Equilibrate -60 °C
Method Log Entry # 3,Data On
Method Log Entry # 4,(Ramp 553968) Ramp 5 °C/minute to 170 °C
Method Log Entry # 5,Data Off
Method Log Entry # 6,Isothermal 1 minutes
Method Log Entry # 7,Data On
Method Log Entry # 8,(Ramp 553972) Ramp 5 °C/minute to -60 °C
Method Log Entry # 9,Data Off
Method Log Entry # 10,Isothermal 1 minutes
Method Log Entry # 11,Data On
Method Log Entry # 12,(Ramp 553976) Ramp 5 °C/minute to 170 °C
Method Log Entry # 13,Data Off
Method Log Entry # 14,Isothermal 1 minutes
Method Log Entry # 15,Data On
Method Log Entry # 16,(Ramp 553980) Ramp 5 °C/minute to -60 °C
Method Log Entry # 17,Data Off
Method Log Entry # 18,Isothermal 1 minutes
Method Log Entry # 19,Data On
Method Log Entry # 20,(Ramp 553984) Ramp 5 °C/minute to 30 °C
Cell Serial,DRC2-00792
[T1 Calibration]
Slope,-0.008529666
Offset,9.636258
Initial Temperature,98.23
GUID,f8bfdadc-4977-4fdf-ba6d-0ba9134940c3
[TZero Calibration]
Date Applied,11/29/2022 4:06:13 PM
Description,From -89.059 °C to 396.009 °C at 20.000°C/min
Gas Type,Nitrogen
Pan Type,None
Source Files 1,C:\Users\yargerlab\Desktop\DSC Data\General\TZero_calibration_11_29_22_2nd(2).tri
Source Files 2,C:\Users\yargerlab\Desktop\DSC Data\General\TZero_calibration_11_29_22_2nd(3).tri
Delta T Offset,13.05235
Delta T Slope,-0.007271007
Delta T0 Offset,-13.69128
Delta T0 Slope,0.06063341
[Temperature Calibration]
Date Applied,11/29/2022 7:12:28 PM
Description,From 106.590 °C to 186.590 °C at 10.000°C/min
Gas Type,Nitrogen
Pan Type,Tzero Aluminum Hermetic
Source Files 1,C:\Users\yargerlab\Desktop\DSC Data\General\Indium(6).tri
Measured 1,157.391
Known 1,156.598
[Cell Constant Calibration]
Date Applied,11/29/2022 7:12:29 PM
Description,From 106.590 °C to 186.590 °C at 10.000°C/min
Gas Type,Nitrogen
Pan Type,Tzero Aluminum Hermetic
Source Files 1,C:\Users\yargerlab\Desktop\DSC Data\General\Indium(6).tri
T4P KCell,1.006051
Onset Slope,63.26126 mW/°C
[Direct Cp Calibration]
Date Applied,11/30/2022 11:04:51 AM
Description,From -79.983 °C to 298.409 °C at 10.000°C/min
Gas Type,Nitrogen
Pan Type,Tzero Aluminum Hermetic
Source Files 1,C:\Users\yargerlab\Desktop\DSC Data\General\Sapphire_Heat_Capacity_11_30_22.tri
[Rev Cp Calibration]
Date Applied,11/30/2022 1:58:51 PM
Description,From -79.996 °C to 292.812 °C at 3.000°C/min
Gas Type,Nitrogen
Pan Type,Tzero Aluminum Hermetic
Source Files 1,C:\Users\yargerlab\Desktop\DSC Data\General\Sapphire_MDSC_Calibration_11_30_22.tri
[step]
Ramp 5.00 °C/min to 170.00 °C
Time,Temperature,Heat Flow (Normalized)
min,°C,W/g
0.00,-59.66,-0.001
0.03,-59.68,-0.001
0.06,-59.68,-0.001
0.09,-59.64,-0.001
0.13,-59.57,0.000
0.16,-59.47,0.000
0.19,-59.36,0.000
0.22,-59.24,0.000
0.25,-59.11,0.000
0.29,-58.98,0.000
0.32,-58.85,0.000
0.35,-58.71,0.000
0.38,-58.57,0.000
0.41,-58.43,0.000
0.44,-58.28,0.001
0.48,-58.13,0.001
0.51,-57.98,0.001
0.54,-57.83,0.001
0.57,-57.68,0.001
0.60,-57.54,0.001
0.63,-57.38,0.001
0.67,-57.23,0.001
0.70,-57.08,0.001
0.73,-56.92,0.001
0.76,-56.77,0.001
0.79,-56.61,0.001
0.82,-56.46,0.001
0.85,-56.30,0.001
0.89,-56.15,0.001
0.92,-55.99,0.001
0.95,-55.84,0.001
0.98,-55.68,0.001
1.01,-55.52,0.001
1.05,-55.37,0.001
1.08,-55.21,0.001
1.11,-55.06,0.001
1.14,-54.90,0.001
1.17,-54.74,0.001
1.20,-54.58,0.001
1.23,-54.43,0.001
1.27,-54.27,0.001
1.30,-54.11,0.001
1.33,-53.96,0.001
1.36,-53.80,0.001
1.39,-53.64,0.001
1.43,-53.48,0.001
1.46,-53.33,0.001
1.49,-53.17,0.001
1.52,-53.01,0.001
1.55,-52.85,0.001
1.58,-52.69,0.001
1.62,-52.54,0.001
1.65,-52.38,0.001
1.68,-52.22,0.001
1.71,-52.06,0.001
1.74,-51.90,0.001
1.77,-51.75,0.001
1.81,-51.59,0.001
1.84,-51.43,0.001
1.87,-51.27,0.001
1.90,-51.12,0.001
1.93,-50.96,0.001
1.96,-50.80,0.001
1.99,-50.64,0.001
2.03,-50.48,0.001
2.06,-50.33,0.001
2.09,-50.17,0.001
2.12,-50.01,0.001
2.15,-49.85,0.001
2.19,-49.69,0.001
2.22,-49.53,0.001
2.25,-49.38,0.001
2.28,-49.22,0.001
2.31,-49.06,0.001
2.34,-48.90,0.001
2.38,-48.74,0.001
2.41,-48.59,0.001
2.44,-48.43,0.001
2.47,-48.27,0.001
2.50,-48.11,0.001
2.53,-47.96,0.001
2.56,-47.80,0.001
2.60,-47.64,0.001
2.63,-47.48,0.001
2.66,-47.32,0.001
2.69,-47.16,0.001
2.72,-47.01,0.001
2.76,-46.85,0.001
2.79,-46.69,0.001
2.82,-46.53,0.001
2.85,-46.37,0.001
2.88,-46.21,0.001
2.91,-46.06,0.001
2.94,-45.90,0.001
2.98,-45.74,0.001
3.01,-45.58,0.001
3.04,-45.42,0.001
3.07,-45.26,0.001
3.10,-45.11,0.001
3.14,-44.95,0.001
3.17,-44.79,0.001
3.20,-44.63,0.001
3.23,-44.47,0.001
3.26,-44.31,0.001
3.29,-44.16,0.001
3.33,-44.00,0.001
3.36,-43.84,0.001
3.39,-43.68,0.001
3.42,-43.52,0.001
3.45,-43.36,0.001
3.48,-43.20,0.001
3.51,-43.05,0.001
3.55,-42.89,0.001
3.58,-42.73,0.001
3.61,-42.57,0.001
3.64,-42.41,0.001
3.67,-42.25,0.001
3.71,-42.09,0.001
3.74,-41.94,0.001
3.77,-41.78,0.001
3.80,-41.62,0.001
3.83,-41.46,0.001
3.86,-41.30,0.001
3.89,-41.14,0.001
3.93,-40.99,0.001
3.96,-40.83,0.001
3.99,-40.67,0.001
4.02,-40.51,0.001
4.05,-40.35,0.001
4.09,-40.19,0.001
4.12,-40.03,0.001
4.15,-39.87,0.001
4.18,-39.72,0.001
4.21,-39.56,0.001
4.24,-39.40,0.001
4.28,-39.24,0.001
4.31,-39.08,0.001
4.34,-38.92,0.001
4.37,-38.76,0.001
4.40,-38.61,0.001
4.43,-38.45,0.001
4.46,-38.29,0.001
4.50,-38.13,0.001
4.53,-37.97,0.001
4.56,-37.81,0.001
4.59,-37.65,0.001
4.62,-37.50,0.001
4.65,-37.34,0.001
4.69,-37.18,0.001
4.72,-37.02,0.001
4.75,-36.86,0.001
4.78,-36.70,0.001
4.81,-36.54,0.001
4.85,-36.39,0.001
4.88,-36.23,0.001
4.91,-36.07,0.001
4.94,-35.91,0.001
4.97,-35.75,0.001
5.00,-35.59,0.001
5.04,-35.44,0.001
5.07,-35.28,0.001
5.10,-35.12,0.001
5.13,-34.96,0.001
5.16,-34.80,0.001
5.19,-34.65,0.001
5.23,-34.48,0.001
5.26,-34.33,0.001
5.29,-34.17,0.001
5.32,-34.01,0.001
5.35,-33.85,0.001
5.38,-33.69,0.001
5.41,-33.53,0.001
5.45,-33.38,0.001
5.48,-33.22,0.001
5.51,-33.06,0.001
5.54,-32.90,0.001
5.57,-32.74,0.001
5.60,-32.58,0.001
5.64,-32.43,0.001
5.67,-32.27,0.001
5.70,-32.11,0.001
5.73,-31.95,0.001
5.76,-31.79,0.001
5.80,-31.63,0.001
5.83,-31.47,0.001
5.86,-31.32,0.001
5.89,-31.16,0.001
5.92,-31.00,0.001
5.95,-30.84,0.001
5.99,-30.68,0.001
6.02,-30.52,0.001
6.05,-30.36,0.001
6.08,-30.21,0.001
6.11,-30.05,0.001
6.14,-29.89,0.001
6.18,-29.73,0.001
6.21,-29.57,0.001
6.24,-29.41,0.001
6.27,-29.26,0.001
6.30,-29.10,0.001
6.33,-28.94,0.001
6.36,-28.78,0.001
6.40,-28.62,0.001
6.43,-28.46,0.001
6.46,-28.30,0.001
6.49,-28.15,0.001
6.52,-27.99,0.001
6.55,-27.83,0.001
6.59,-27.67,0.001
6.62,-27.51,0.001
6.65,-27.35,0.001
6.68,-27.20,0.001
6.71,-27.04,0.001
6.75,-26.88,0.001
6.78,-26.72,0.001
6.81,-26.56,0.001
6.84,-26.40,0.001
6.87,-26.25,0.001
6.90,-26.09,0.001
6.94,-25.93,0.001
6.97,-25.77,0.001
7.00,-25.61,0.001
7.03,-25.45,0.001
7.06,-25.29,0.001
7.09,-25.13,0.001
7.13,-24.98,0.001
7.16,-24.82,0.001
7.19,-24.66,0.001
7.22,-24.50,0.001
7.25,-24.34,0.001
7.28,-24.18,0.001
7.31,-24.03,0.001
7.35,-23.87,0.001
7.38,-23.71,0.001
7.41,-23.55,0.001
7.44,-23.39,0.001
7.47,-23.23,0.001
7.50,-23.07,0.001
7.54,-22.92,0.001
7.57,-22.76,0.001
7.60,-22.60,0.001
7.63,-22.44,0.001
7.66,-22.28,0.001
7.70,-22.12,0.001
7.73,-21.97,0.001
7.76,-21.81,0.001
7.79,-21.65,0.001
7.82,-21.49,0.001
7.85,-21.33,0.001
7.89,-21.17,0.001
7.92,-21.01,0.001
7.95,-20.86,0.001
7.98,-20.70,0.001
8.01,-20.54,0.001
8.04,-20.38,0.001
8.08,-20.22,0.001
8.11,-20.06,0.001
8.14,-19.91,0.001
8.17,-19.75,0.001
8.20,-19.59,0.001
8.23,-19.43,0.001
8.26,-19.27,0.001
8.30,-19.11,0.001
8.33,-18.96,0.001
8.36,-18.80,0.001
8.39,-18.64,0.001
8.42,-18.48,0.001
8.45,-18.32,0.001
8.49,-18.16,0.001
8.52,-18.00,0.001
8.55,-17.85,0.001
8.58,-17.69,0.001
8.61,-17.53,0.001
8.65,-17.37,0.001
8.68,-17.21,0.001
8.71,-17.05,0.001
8.74,-16.89,0.001
8.77,-16.74,0.001
8.80,-16.58,0.001
8.83,-16.42,0.001
8.87,-16.26,0.001
8.90,-16.10,0.001
8.93,-15.94,0.001
8.96,-15.78,0.001
8.99,-15.62,0.001
9.03,-15.47,0.001
9.06,-15.31,0.001
9.09,-15.15,0.001
9.12,-14.99,0.001
9.15,-14.83,0.001
9.18,-14.67,0.001
9.22,-14.52,0.001
9.25,-14.36,0.001
9.28,-14.20,0.001
9.31,-14.04,0.001
9.34,-13.88,0.001
9.37,-13.72,0.001
9.40,-13.57,0.001
9.44,-13.41,0.001
9.47,-13.25,0.001
9.50,-13.09,0.001
9.53,-12.93,0.001
9.56,-12.77,0.001
9.60,-12.62,0.001
9.63,-12.46,0.001
9.66,-12.30,0.001
9.69,-12.14,0.001
9.72,-11.98,0.001
9.75,-11.82,0.001
9.78,-11.67,0.001
9.82,-11.51,0.001
9.85,-11.35,0.001
9.88,-11.19,0.001
9.91,-11.03,0.001
9.94,-10.87,0.001
9.98,-10.71,0.001
10.01,-10.56,0.001
10.04,-10.40,0.001
10.07,-10.24,0.001
10.10,-10.08,0.001
10.13,-9.92,0.001
10.17,-9.76,0.001
10.20,-9.61,0.001
10.23,-9.45,0.001
10.26,-9.29,0.001
10.29,-9.13,0.001
10.32,-8.97,0.001
10.35,-8.81,0.001
10.39,-8.66,0.001
10.42,-8.50,0.001
10.45,-8.34,0.001
10.48,-8.18,0.001
10.51,-8.02,0.001
10.55,-7.86,0.001
10.58,-7.70,0.001
10.61,-7.54,0.001
10.64,-7.39,0.001
10.67,-7.23,0.001
10.70,-7.07,0.001
10.73,-6.91,0.001
10.77,-6.75,0.001
10.80,-6.59,0.001
10.83,-6.44,0.001
10.86,-6.28,0.001
10.89,-6.12,0.001
10.93,-5.96,0.001
10.96,-5.80,0.001
10.99,-5.64,0.001
11.02,-5.49,0.001
11.05,-5.33,0.001
11.08,-5.17,0.001
11.12,-5.01,0.001
11.15,-4.85,0.001
11.18,-4.69,0.001
11.21,-4.54,0.001
11.24,-4.38,0.001
11.27,-4.22,0.001
11.30,-4.06,0.001
11.34,-3.90,0.001
11.37,-3.74,0.001
11.40,-3.58,0.001
11.43,-3.42,0.001
11.46,-3.27,0.001
11.50,-3.11,0.001
11.53,-2.95,0.001
11.56,-2.79,0.001
11.59,-2.63,0.001
11.62,-2.48,0.001
11.65,-2.32,0.001
11.68,-2.16,0.001
11.72,-2.00,0.001
11.75,-1.84,0.001
11.78,-1.68,0.001
11.81,-1.52,0.001
11.84,-1.36,0.001
11.88,-1.21,0.001
11.91,-1.05,0.001
11.94,-0.89,0.001
11.97,-0.73,0.001
12.00,-0.57,0.001
12.03,-0.41,0.001
12.07,-0.26,0.001
12.10,-0.10,0.001
12.13,0.06,0.001
12.16,0.22,0.001
12.19,0.38,0.001
12.22,0.53,0.001
12.25,0.69,0.001
12.29,0.85,0.001
12.32,1.01,0.001
12.35,1.17,0.001
12.38,1.33,0.001
12.41,1.49,0.001
12.45,1.65,0.001
12.48,1.80,0.001
12.51,1.96,0.001
12.54,2.12,0.001
12.57,2.28,0.001
12.60,2.44,0.001
12.63,2.60,0.001
12.67,2.75,0.001
12.70,2.91,0.001
12.73,3.07,0.001
12.76,3.23,0.001
12.79,3.39,0.001
12.83,3.54,0.001
12.86,3.70,0.001
12.89,3.86,0.001
12.92,4.02,0.001
12.95,4.18,0.001
12.98,4.34,0.001
13.02,4.50,0.001
13.05,4.65,0.001
13.08,4.81,0.001
13.11,4.97,0.001
13.14,5.13,0.001
13.17,5.29,0.001
13.20,5.45,0.001
13.24,5.61,0.001
13.27,5.77,0.001
13.30,5.92,0.001
13.33,6.08,0.001
13.36,6.24,0.001
13.40,6.40,0.001
13.43,6.56,0.001
13.46,6.72,0.001
13.49,6.88,0.001
13.52,7.03,0.001
13.55,7.19,0.001
13.58,7.35,0.001
13.62,7.51,0.001
13.65,7.67,0.001
13.68,7.83,0.001
13.71,7.98,0.001
13.74,8.14,0.001
13.78,8.30,0.001
13.81,8.46,0.001
13.84,8.62,0.001
13.87,8.78,0.001
13.90,8.93,0.001
13.93,9.09,0.001
13.97,9.25,0.001
14.00,9.41,0.001
14.03,9.57,0.001
14.06,9.73,0.001
14.09,9.88,0.001
14.12,10.04,0.001
14.15,10.20,0.001
14.19,10.36,0.001
14.22,10.52,0.001
14.25,10.68,0.001
14.28,10.84,0.001
14.31,10.99,0.001
14.35,11.15,0.001
14.38,11.31,0.001
14.41,11.47,0.001
14.44,11.63,0.001
14.47,11.79,0.001
14.50,11.95,0.001
14.53,12.10,0.001
14.57,12.26,0.001
14.60,12.42,0.001
14.63,12.58,0.001
14.66,12.74,0.001
14.69,12.90,0.001
14.73,13.05,0.001
14.76,13.21,0.001
14.79,13.37,0.001
14.82,13.53,0.001
14.85,13.69,0.001
14.88,13.85,0.001
14.92,14.00,0.001
14.95,14.16,0.001
14.98,14.32,0.001
15.01,14.48,0.001
15.04,14.64,0.001
15.07,14.80,0.001
15.10,14.96,0.001
15.14,15.11,0.001
15.17,15.27,0.001
15.20,15.43,0.001
15.23,15.59,0.001
15.26,15.75,0.001
15.30,15.91,0.001
15.33,16.06,0.001
15.36,16.22,0.001
15.39,16.38,0.001
15.42,16.54,0.001
15.45,16.70,0.001
15.48,16.86,0.001
15.52,17.02,0.001
15.55,17.17,0.001
15.58,17.33,0.001
15.61,17.49,0.001
15.64,17.65,0.001
15.68,17.81,0.001
15.71,17.97,0.001
15.74,18.12,0.001
15.77,18.28,0.001
15.80,18.44,0.001
15.83,18.60,0.001
15.87,18.76,0.001
15.90,18.92,0.001
15.93,19.08,0.001
15.96,19.23,0.001
15.99,19.39,0.001
16.02,19.55,0.001
16.05,19.71,0.001
16.09,19.87,0.001
16.12,20.03,0.001
16.15,20.18,0.001
16.18,20.34,0.001
16.21,20.50,0.001
16.25,20.66,0.001
16.28,20.82,0.001
16.31,20.98,0.001
16.34,21.13,0.001
16.37,21.29,0.001
16.40,21.45,0.001
16.43,21.61,0.001
16.47,21.77,0.001
16.50,21.93,0.001
16.53,22.08,0.001
16.56,22.24,0.001
16.59,22.40,0.001
16.63,22.56,0.001
16.66,22.72,0.001
16.69,22.88,0.001
16.72,23.04,0.001
16.75,23.19,0.001
16.78,23.35,0.001
16.82,23.51,0.001
16.85,23.67,0.001
16.88,23.83,0.001
16.91,23.99,0.001
16.94,24.15,0.001
16.97,24.30,0.001
17.00,24.46,0.001
17.04,24.62,0.001
17.07,24.78,0.001
17.10,24.94,0.001
17.13,25.10,0.001
17.16,25.25,0.001
17.19,25.41,0.001
17.23,25.57,0.001
17.26,25.73,0.001
17.29,25.89,0.001
17.32,26.05,0.001
17.35,26.21,0.001
17.38,26.36,0.001
17.42,26.52,0.001
17.45,26.68,0.001
17.48,26.84,0.001
17.51,27.00,0.001
17.54,27.16,0.001
17.58,27.31,0.001
17.61,27.47,0.001
17.64,27.63,0.001
17.67,27.79,0.001
17.70,27.95,0.001
17.73,28.11,0.001
17.77,28.26,0.001
17.80,28.42,0.001
17.83,28.58,0.001
17.86,28.74,0.001
17.89,28.90,0.001
17.92,29.06,0.001
17.96,29.21,0.001
17.99,29.37,0.001
18.02,29.53,0.001
18.05,29.69,0.001
18.08,29.85,0.001
18.11,30.01,0.001
18.14,30.16,0.001
18.18,30.32,0.001
18.21,30.48,0.001
18.24,30.64,0.001
18.27,30.80,0.001
18.30,30.96,0.001
18.33,31.12,0.001
18.37,31.27,0.001
18.40,31.43,0.001
18.43,31.59,0.001
18.46,31.75,0.001
18.49,31.91,0.001
18.53,32.07,0.001
18.56,32.23,0.001
18.59,32.38,0.001
18.62,32.54,0.001
18.65,32.70,0.001
18.68,32.86,0.001
18.72,33.02,0.001
18.75,33.18,0.001
18.78,33.33,0.001
18.81,33.49,0.001
18.84,33.65,0.001
18.87,33.81,0.001
18.91,33.97,0.001
18.94,34.13,0.001
18.97,34.29,0.001
19.00,34.44,0.001
19.03,34.60,0.001
19.06,34.76,0.001
19.09,34.92,0.001
19.13,35.08,0.001
19.16,35.24,0.001
19.19,35.39,0.001
19.22,35.55,0.001
19.25,35.71,0.001
19.28,35.87,0.001
19.32,36.03,0.001
19.35,36.19,0.001
19.38,36.34,0.001
19.41,36.50,0.001
19.44,36.66,0.001
19.48,36.82,0.001
19.51,36.98,0.001
19.54,37.14,0.001
19.57,37.30,0.001
19.60,37.45,0.001
19.63,37.61,0.001
19.67,37.77,0.001
19.70,37.93,0.001
19.73,38.09,0.001
19.76,38.25,0.001
19.79,38.40,0.001
19.82,38.56,0.001
19.86,38.72,0.001
19.89,38.88,0.001
19.92,39.04,0.001
19.95,39.20,0.001
19.98,39.35,0.001
20.01,39.51,0.001
20.04,39.67,0.001
20.08,39.83,0.001
20.11,39.99,0.001
20.14,40.15,0.001
20.17,40.31,0.001
20.20,40.46,0.001
20.23,40.62,0.001
20.27,40.78,0.001
20.30,40.94,0.001
20.33,41.10,0.001
20.36,41.26,0.001
20.39,41.41,0.001
20.43,41.57,0.001
20.46,41.73,0.001
20.49,41.89,0.001
20.52,42.05,0.001
20.55,42.21,0.001
20.58,42.36,0.001
20.62,42.52,0.001
20.65,42.68,0.001
20.68,42.84,0.001
20.71,43.00,0.001
20.74,43.16,0.001
20.77,43.31,0.001
20.81,43.47,0.001
20.84,43.63,0.001
20.87,43.79,0.001
20.90,43.95,0.001
20.93,44.11,0.001
20.96,44.27,0.001
20.99,44.43,0.001
21.03,44.58,0.001
21.06,44.74,0.001
21.09,44.90,0.001
21.12,45.06,0.001
21.15,45.22,0.001
21.18,45.38,0.001
21.22,45.53,0.001
21.25,45.69,0.001
21.28,45.85,0.001
21.31,46.01,0.001
21.34,46.17,0.001
21.38,46.33,0.001
21.41,46.49,0.001
21.44,46.64,0.001
21.47,46.80,0.001
21.50,46.96,0.001
21.53,47.12,0.001
21.57,47.28,0.001
21.60,47.43,0.001
21.63,47.59,0.001
21.66,47.75,0.001
21.69,47.91,0.001
21.72,48.07,0.001
21.76,48.23,0.001
21.79,48.39,0.001
21.82,48.54,0.001
21.85,48.70,0.001
21.88,48.86,0.001
21.91,49.02,0.001
21.94,49.18,0.001
21.98,49.34,0.001
22.01,49.49,0.001
22.04,49.65,0.001
22.07,49.81,0.001
22.10,49.97,0.001
22.13,50.13,0.001
22.17,50.29,0.001
22.20,50.45,0.001
22.23,50.61,0.001
22.26,50.76,0.001
22.29,50.92,0.001
22.33,51.08,0.001
22.36,51.24,0.001
22.39,51.40,0.001
22.42,51.56,0.001
22.45,51.72,0.001
22.48,51.87,0.001
22.52,52.03,0.001
22.55,52.19,0.001
22.58,52.35,0.001
22.61,52.51,0.001
22.64,52.66,0.001
22.67,52.82,0.001
22.71,52.98,0.001
22.74,53.14,0.001
22.77,53.30,0.001
22.80,53.46,0.001
22.83,53.61,0.001
22.86,53.77,0.001
22.89,53.93,0.001
22.93,54.09,0.001
22.96,54.25,0.001
22.99,54.41,0.001
23.02,54.56,0.001
23.05,54.72,0.001
23.08,54.88,0.001
23.12,55.04,0.001
23.15,55.20,0.001
23.18,55.36,0.001
23.21,55.51,0.001
23.24,55.67,0.001
23.28,55.83,0.001
23.31,55.99,0.001
23.34,56.15,0.001
23.37,56.31,0.001
23.40,56.46,0.001
23.43,56.62,0.001
23.47,56.78,0.001
23.50,56.94,0.001
23.53,57.10,0.001
23.56,57.26,0.001
23.59,57.41,0.001
23.62,57.57,0.001
23.66,57.73,0.001
23.69,57.89,0.001
23.72,58.05,0.001
23.75,58.21,0.001
23.78,58.36,0.001
23.81,58.52,0.001
23.84,58.68,0.001
23.88,58.84,0.001
23.91,59.00,0.001
23.94,59.16,0.001
23.97,59.32,0.001
24.00,59.47,0.001
24.03,59.63,0.001
24.07,59.79,0.001
24.10,59.95,0.001
24.13,60.11,0.001
24.16,60.27,0.001
24.19,60.42,0.001
24.23,60.58,0.001
24.26,60.74,0.001
24.29,60.90,0.001
24.32,61.06,0.001
24.35,61.22,0.001
24.38,61.37,0.001
24.42,61.53,0.001
24.45,61.69,0.001
24.48,61.85,0.001
24.51,62.01,0.001
24.54,62.17,0.001
24.57,62.32,0.001
24.61,62.48,0.001
24.64,62.64,0.001
24.67,62.80,0.001
24.70,62.96,0.001
24.73,63.12,0.001
24.76,63.27,0.001
24.79,63.43,0.001
24.83,63.59,0.001
24.86,63.75,0.001
24.89,63.91,0.001
24.92,64.07,0.001
24.95,64.23,0.001
24.98,64.38,0.001
25.02,64.54,0.001
25.05,64.70,0.001
25.08,64.86,0.001
25.11,65.02,0.001
25.14,65.18,0.001
25.18,65.33,0.001
25.21,65.49,0.001
25.24,65.65,0.001
25.27,65.81,0.001
25.30,65.97,0.001
25.33,66.13,0.001
25.37,66.29,0.001
25.40,66.44,0.001
25.43,66.60,0.001
25.46,66.76,0.001
25.49,66.92,0.001
25.52,67.08,0.001
25.56,67.23,0.001
25.59,67.39,0.001
25.62,67.55,0.001
25.65,67.71,0.001
25.68,67.87,0.001
25.71,68.03,0.001
25.74,68.18,0.001
25.78,68.34,0.001
25.81,68.50,0.001
25.84,68.66,0.001
25.87,68.82,0.001
25.90,68.97,0.001
25.93,69.13,0.001
25.97,69.29,0.001
26.00,69.45,0.001
26.03,69.61,0.001
26.06,69.76,0.001
26.09,69.92,0.001
26.13,70.08,0.001
26.16,70.24,0.001
26.19,70.40,0.001
26.22,70.55,0.001
26.25,70.71,0.001
26.28,70.87,0.001
26.32,71.03,0.001
26.35,71.18,0.001
26.38,71.34,0.001
26.41,71.50,0.001
26.44,71.66,0.002
26.47,71.81,0.002
26.51,71.97,0.002
26.54,72.13,0.002
26.57,72.29,0.002
26.60,72.44,0.002
26.63,72.60,0.002
26.66,72.76,0.002
26.69,72.91,0.002
26.73,73.07,0.002
26.76,73.23,0.002
26.79,73.38,0.002
26.82,73.54,0.002
26.85,73.69,0.002
26.88,73.85,0.002
26.92,74.01,0.002
26.95,74.16,0.002
26.98,74.31,0.003
27.01,74.47,0.003
27.04,74.62,0.003
27.08,74.78,0.003
27.11,74.93,0.003
27.14,75.08,0.003
27.17,75.23,0.004
27.20,75.38,0.004
27.23,75.53,0.004
27.27,75.68,0.004
27.30,75.82,0.005
27.33,75.97,0.005
27.36,76.11,0.006
27.39,76.24,0.007
27.42,76.36,0.008
27.46,76.47,0.010
27.49,76.59,0.011
27.52,76.69,0.012
27.55,76.80,0.013
27.58,76.92,0.014
27.61,77.04,0.015
27.64,77.16,0.016
27.68,77.29,0.017
27.71,77.42,0.017
27.74,77.55,0.017
27.77,77.71,0.017
27.80,77.88,0.015
27.83,78.07,0.014
27.87,78.29,0.012
27.90,78.51,0.010
27.93,78.75,0.008
27.96,78.97,0.006
27.99,79.19,0.005
28.03,79.40,0.004
28.06,79.60,0.003
28.09,79.79,0.003
28.12,79.98,0.003
28.15,80.16,0.002
28.18,80.33,0.002
28.22,80.50,0.002
28.25,80.67,0.002
28.28,80.83,0.002
28.31,81.00,0.002
28.34,81.16,0.002
28.37,81.32,0.001
28.41,81.48,0.001
28.44,81.64,0.001
28.47,81.80,0.001
28.50,81.96,0.001
28.53,82.12,0.001
28.56,82.28,0.001
28.59,82.44,0.001
28.63,82.60,0.001
28.66,82.76,0.001
28.69,82.91,0.001
28.72,83.07,0.001
28.75,83.23,0.001
28.78,83.39,0.001
28.82,83.55,0.001
28.85,83.71,0.001
28.88,83.87,0.001
28.91,84.02,0.001
28.94,84.18,0.001
28.98,84.34,0.001
29.01,84.50,0.001
29.04,84.66,0.001
29.07,84.82,0.001
29.10,84.97,0.001
29.13,85.13,0.001
29.17,85.29,0.001
29.20,85.45,0.001
29.23,85.61,0.001
29.26,85.77,0.001
29.29,85.92,0.001
29.32,86.08,0.001
29.36,86.24,0.001
29.39,86.40,0.001
29.42,86.56,0.001
29.45,86.72,0.001
29.48,86.87,0.001
29.51,87.03,0.001
29.54,87.19,0.001
29.58,87.35,0.001
29.61,87.51,0.001
29.64,87.67,0.001
29.67,87.83,0.001
29.70,87.98,0.001
29.73,88.14,0.001
29.77,88.30,0.001
29.80,88.46,0.001
29.83,88.62,0.001
29.86,88.78,0.001
29.89,88.93,0.001
29.93,89.09,0.001
29.96,89.25,0.001
29.99,89.41,0.001
30.02,89.57,0.001
30.05,89.73,0.001
30.08,89.88,0.001
30.12,90.04,0.001
30.15,90.20,0.001
30.18,90.36,0.001
30.21,90.52,0.001
30.24,90.68,0.001
30.27,90.84,0.001
30.31,90.99,0.001
30.34,91.15,0.001
30.37,91.31,0.001
30.40,91.47,0.001
30.43,91.63,0.001
30.46,91.79,0.001
30.49,91.94,0.001
30.53,92.10,0.001
30.56,92.26,0.001
30.59,92.42,0.001
30.62,92.58,0.001
30.65,92.74,0.001
30.68,92.89,0.001
30.72,93.05,0.001
30.75,93.21,0.001
30.78,93.37,0.001
30.81,93.53,0.001
30.84,93.69,0.001
30.88,93.85,0.001
30.91,94.00,0.001
30.94,94.16,0.001
30.97,94.32,0.001
31.00,94.48,0.001
31.03,94.64,0.001
31.07,94.79,0.001
31.10,94.95,0.001
31.13,95.11,0.001
31.16,95.27,0.001
31.19,95.43,0.001
31.22,95.59,0.001
31.26,95.75,0.001
31.29,95.90,0.001
31.32,96.06,0.001
31.35,96.22,0.001
31.38,96.38,0.001
31.41,96.54,0.001
31.44,96.70,0.001
31.48,96.85,0.001
31.51,97.01,0.001
31.54,97.17,0.001
31.57,97.33,0.001
31.60,97.49,0.001
31.63,97.65,0.001
31.67,97.81,0.001
31.70,97.96,0.001
31.73,98.12,0.001
31.76,98.28,0.001
31.79,98.44,0.001
31.83,98.60,0.001
31.86,98.76,0.001
31.89,98.91,0.001
31.92,99.07,0.001
31.95,99.23,0.001
31.98,99.39,0.001
32.02,99.55,0.001
32.05,99.71,0.001
32.08,99.87,0.001
32.11,100.02,0.001
32.14,100.18,0.001
32.17,100.34,0.001
32.21,100.50,0.001
32.24,100.66,0.001
32.27,100.82,0.001
32.30,100.97,0.001
32.33,101.13,0.001
32.36,101.29,0.001
32.39,101.45,0.001
32.43,101.61,0.001
32.46,101.77,0.001
32.49,101.92,0.001
32.52,102.08,0.001
32.55,102.24,0.001
32.58,102.40,0.001
32.62,102.56,0.001
32.65,102.72,0.001
32.68,102.88,0.001
32.71,103.03,0.001
32.74,103.19,0.001
32.78,103.35,0.001
32.81,103.51,0.001
32.84,103.67,0.001
32.87,103.82,0.001
32.90,103.98,0.001
32.93,104.14,0.001
32.97,104.30,0.001
33.00,104.46,0.001
33.03,104.62,0.001
33.06,104.78,0.001
33.09,104.93,0.001
33.12,105.09,0.001
33.16,105.25,0.001
33.19,105.41,0.001
33.22,105.57,0.001
33.25,105.73,0.001
33.28,105.89,0.001
33.31,106.05,0.001
33.34,106.21,0.001
33.38,106.36,0.001
33.41,106.52,0.001
33.44,106.68,0.001
33.47,106.84,0.001
33.50,107.00,0.001
33.53,107.15,0.001
33.57,107.31,0.001
33.60,107.47,0.001
33.63,107.63,0.001
33.66,107.79,0.001
33.69,107.95,0.001
33.73,108.10,0.001
33.76,108.26,0.001
33.79,108.42,0.001
33.82,108.58,0.001
33.85,108.74,0.001
33.88,108.90,0.001
33.92,109.05,0.001
33.95,109.21,0.001
33.98,109.37,0.001
34.01,109.53,0.001
34.04,109.69,0.001
34.07,109.85,0.001
34.11,110.00,0.001
34.14,110.16,0.001
34.17,110.32,0.001
34.20,110.48,0.001
34.23,110.64,0.001
34.26,110.80,0.001
34.29,110.96,0.001
34.33,111.11,0.001
34.36,111.27,0.001
34.39,111.43,0.001
34.42,111.59,0.001
34.45,111.75,0.001
34.49,111.90,0.001
34.52,112.06,0.001
34.55,112.22,0.001
34.58,112.38,0.001
34.61,112.54,0.001
34.64,112.70,0.001
34.68,112.85,0.001
34.71,113.01,0.001
34.74,113.17,0.001
34.77,113.33,0.001
34.80,113.49,0.001
34.83,113.65,0.001
34.86,113.81,0.001
34.90,113.96,0.001
34.93,114.12,0.001
34.96,114.28,0.001
34.99,114.44,0.001
35.02,114.60,0.001
35.06,114.76,0.001
35.09,114.91,0.001
35.12,115.07,0.001
35.15,115.23,0.001
35.18,115.39,0.001
35.21,115.55,0.001
35.24,115.71,0.001
35.28,115.87,0.001
35.31,116.02,0.001
35.34,116.18,0.001
35.37,116.34,0.001
35.40,116.50,0.001
35.44,116.66,0.001
35.47,116.82,0.001
35.50,116.97,0.001
35.53,117.13,0.001
35.56,117.29,0.001
35.59,117.45,0.001
35.63,117.61,0.001
35.66,117.77,0.001
35.69,117.92,0.001
35.72,118.08,0.001
35.75,118.24,0.001
35.78,118.40,0.001
35.81,118.56,0.001
35.85,118.72,0.001
35.88,118.87,0.001
35.91,119.03,0.001
35.94,119.19,0.001
35.97,119.35,0.001
36.01,119.51,0.001
36.04,119.67,0.001
36.07,119.82,0.001
36.10,119.98,0.001
36.13,120.14,0.001
36.16,120.30,0.001
36.19,120.46,0.001
36.23,120.61,0.001
36.26,120.77,0.001
36.29,120.93,0.001
36.32,121.09,0.001
36.35,121.25,0.001
36.39,121.41,0.001
36.42,121.57,0.001
36.45,121.73,0.001
36.48,121.88,0.001
36.51,122.04,0.001
36.54,122.20,0.001
36.58,122.36,0.001
36.61,122.52,0.001
36.64,122.68,0.001
36.67,122.83,0.001
36.70,122.99,0.001
36.73,123.15,0.001
36.76,123.31,0.001
36.80,123.47,0.001
36.83,123.63,0.001
36.86,123.79,0.001
36.89,123.94,0.001
36.92,124.10,0.001
36.96,124.26,0.001
36.99,124.42,0.001
37.02,124.58,0.001
37.05,124.73,0.001
37.08,124.89,0.001
37.11,125.05,0.001
37.14,125.21,0.001
37.18,125.37,0.001
37.21,125.53,0.001
37.24,125.69,0.001
37.27,125.84,0.001
37.30,126.00,0.001
37.34,126.16,0.001
37.37,126.32,0.001
37.40,126.48,0.001
37.43,126.63,0.001
37.46,126.79,0.001
37.49,126.95,0.001
37.53,127.11,0.001
37.56,127.27,0.001
37.59,127.43,0.001
37.62,127.59,0.001
37.65,127.74,0.001
37.68,127.90,0.001
37.71,128.06,0.001
37.75,128.22,0.001
37.78,128.38,0.001
37.81,128.54,0.001
37.84,128.70,0.001
37.87,128.85,0.001
37.91,129.01,0.001
37.94,129.17,0.001
37.97,129.33,0.001
38.00,129.49,0.001
38.03,129.64,0.001
38.06,129.80,0.001
38.09,129.96,0.001
38.13,130.12,0.001
38.16,130.28,0.001
38.19,130.44,0.001
38.22,130.59,0.001
38.25,130.75,0.001
38.29,130.91,0.001
38.32,131.07,0.001
38.35,131.23,0.001
38.38,131.39,0.001
38.41,131.55,0.001
38.44,131.70,0.001
38.48,131.86,0.001
38.51,132.02,0.001
38.54,132.18,0.001
38.57,132.34,0.001
38.60,132.50,0.001
38.63,132.65,0.001
38.66,132.81,0.001
38.70,132.97,0.001
38.73,133.13,0.001
38.76,133.29,0.001
38.79,133.45,0.001
38.82,133.61,0.001
38.86,133.76,0.001
38.89,133.92,0.001
38.92,134.08,0.001
38.95,134.24,0.001
38.98,134.40,0.001
39.01,134.56,0.001
39.04,134.71,0.001
39.08,134.87,0.001
39.11,135.03,0.001
39.14,135.19,0.001
39.17,135.35,0.001
39.20,135.51,0.001
39.24,135.66,0.001
39.27,135.82,0.001
39.30,135.98,0.001
39.33,136.14,0.001
39.36,136.30,0.001
39.39,136.45,0.001
39.43,136.61,0.001
39.46,136.77,0.001
39.49,136.93,0.001
39.52,137.09,0.001
39.55,137.25,0.001
39.58,137.41,0.001
39.61,137.56,0.001
39.65,137.72,0.001
39.68,137.88,0.001
39.71,138.04,0.001
39.74,138.20,0.001
39.77,138.36,0.001
39.81,138.51,0.001
39.84,138.67,0.001
39.87,138.83,0.001
39.90,138.99,0.001
39.93,139.15,0.001
39.96,139.31,0.001
39.99,139.47,0.001
40.03,139.62,0.001
40.06,139.78,0.001
40.09,139.94,0.001
40.12,140.10,0.001
40.15,140.26,0.001
40.19,140.42,0.001
40.22,140.57,0.001
40.25,140.73,0.001
40.28,140.89,0.001
40.31,141.05,0.001
40.34,141.21,0.001
40.38,141.37,0.001
40.41,141.52,0.001
40.44,141.68,0.001
40.47,141.84,0.001
40.50,142.00,0.001
40.53,142.16,0.001
40.56,142.32,0.001
40.60,142.47,0.001
40.63,142.63,0.001
40.66,142.79,0.001
40.69,142.95,0.001
40.72,143.11,0.001
40.76,143.27,0.001
40.79,143.43,0.001
40.82,143.58,0.001
40.85,143.74,0.001
40.88,143.90,0.001
40.91,144.06,0.001
40.94,144.22,0.001
40.98,144.38,0.001
41.01,144.53,0.001
41.04,144.69,0.001
41.07,144.85,0.001
41.10,145.01,0.001
41.14,145.17,0.001
41.17,145.33,0.001
41.20,145.49,0.001
41.23,145.64,0.001
41.26,145.80,0.001
41.29,145.96,0.001
41.33,146.12,0.001
41.36,146.28,0.001
41.39,146.44,0.001
41.42,146.59,0.001
41.45,146.75,0.001
41.48,146.91,0.001
41.51,147.07,0.001
41.55,147.23,0.001
41.58,147.39,0.001
41.61,147.54,0.001
41.64,147.70,0.001
41.67,147.86,0.001
41.71,148.02,0.001
41.74,148.18,0.001
41.77,148.34,0.001
41.80,148.49,0.001
41.83,148.65,0.001
41.86,148.81,0.001
41.89,148.97,0.001
41.93,149.13,0.001
41.96,149.29,0.001
41.99,149.44,0.001
42.02,149.60,0.001
42.05,149.76,0.001
42.09,149.92,0.001
42.12,150.08,0.001
42.15,150.24,0.001
42.18,150.40,0.001
42.21,150.55,0.001
42.24,150.71,0.001
42.28,150.87,0.001
42.31,151.03,0.001
42.34,151.19,0.001
42.37,151.35,0.001
42.40,151.50,0.001
42.43,151.66,0.001
42.46,151.82,0.001
42.50,151.98,0.001
42.53,152.14,0.001
42.56,152.30,0.001
42.59,152.46,0.001
42.62,152.61,0.001
42.66,152.77,0.001
42.69,152.93,0.001
42.72,153.09,0.001
42.75,153.25,0.001
42.78,153.41,0.001
42.81,153.56,0.001
42.84,153.72,0.001
42.88,153.88,0.001
42.91,154.04,0.001
42.94,154.20,0.001
42.97,154.36,0.001
43.00,154.51,0.001
43.04,154.67,0.001
43.07,154.83,0.001
43.10,154.99,0.001
43.13,155.15,0.001
43.16,155.31,0.001
43.19,155.46,0.001
43.23,155.62,0.001
43.26,155.78,0.001
43.29,155.94,0.001
43.32,156.10,0.001
43.35,156.26,0.001
43.38,156.41,0.001
43.41,156.57,0.001
43.45,156.73,0.001
43.48,156.89,0.001
43.51,157.05,0.001
43.54,157.21,0.001
43.57,157.37,0.001
43.61,157.52,0.001
43.64,157.68,0.001
43.67,157.84,0.001
43.70,158.00,0.001
43.73,158.16,0.001
43.76,158.32,0.001
43.79,158.47,0.001
43.83,158.63,0.001
43.86,158.79,0.001
43.89,158.95,0.001
43.92,159.11,0.001
43.95,159.27,0.001
43.99,159.42,0.001
44.02,159.58,0.001
44.05,159.74,0.001
44.08,159.90,0.001
44.11,160.06,0.001
44.14,160.22,0.001
44.18,160.37,0.001
44.21,160.53,0.001
44.24,160.69,0.001
44.27,160.85,0.001
44.30,161.01,0.001
44.33,161.17,0.001
44.36,161.32,0.001
44.40,161.48,0.001
44.43,161.64,0.001
44.46,161.80,0.001
44.49,161.96,0.001
44.52,162.12,0.001
44.56,162.27,0.001
44.59,162.43,0.001
44.62,162.59,0.001
44.65,162.75,0.001
44.68,162.91,0.001
44.71,163.07,0.001
44.74,163.22,0.001
44.78,163.38,0.001
44.81,163.54,0.001
44.84,163.70,0.001
44.87,163.86,0.001
44.90,164.02,0.001
44.94,164.18,0.001
44.97,164.33,0.001
45.00,164.49,0.001
45.03,164.65,0.001
45.06,164.81,0.001
45.09,164.97,0.001
45.13,165.12,0.001
45.16,165.28,0.001
45.19,165.44,0.001
45.22,165.60,0.001
45.25,165.76,0.001
45.28,165.92,0.001
45.31,166.08,0.001
45.35,166.23,0.001
45.38,166.39,0.001
45.41,166.55,0.001
45.44,166.71,0.001
45.47,166.87,0.001
45.51,167.02,0.001
45.54,167.18,0.001
45.57,167.34,0.001
45.60,167.50,0.001
45.63,167.66,0.001
45.66,167.82,0.001
45.69,167.97,0.001
45.73,168.13,0.001
45.76,168.29,0.001
45.79,168.45,0.001
45.82,168.61,0.001
45.85,168.77,0.001
45.89,168.93,0.001
45.92,169.08,0.001
45.95,169.24,
45.98,,
45.98,,

[step]
Ramp 5.00 °C/min to -60.00 °C
Time,Temperature,Heat Flow (Normalized)
min,°C,W/g
46.99,170.12,-0.001
47.02,170.12,-0.001
47.05,170.11,-0.001
47.08,170.07,-0.001
47.11,170.00,-0.001
47.14,169.90,-0.001
47.18,169.79,-0.001
47.21,169.67,-0.002
47.24,169.53,-0.002
47.27,169.40,-0.002
47.30,169.25,-0.002
47.33,169.11,-0.002
47.36,168.96,-0.002
47.40,168.81,-0.002
47.43,168.66,-0.002
47.46,168.51,-0.002
47.49,168.35,-0.002
47.52,168.20,-0.002
47.56,168.04,-0.002
47.59,167.89,-0.002
47.62,167.73,-0.002
47.65,167.58,-0.002
47.68,167.42,-0.002
47.71,167.26,-0.002
47.74,167.11,-0.002
47.78,166.95,-0.002
47.81,166.80,-0.002
47.84,166.64,-0.002
47.87,166.48,-0.002
47.90,166.32,-0.002
47.94,166.17,-0.002
47.97,166.01,-0.002
48.00,165.85,-0.002
48.03,165.70,-0.002
48.06,165.54,-0.002
48.09,165.38,-0.002
48.13,165.22,-0.002
48.16,165.06,-0.002
48.19,164.91,-0.002
48.22,164.75,-0.002
48.25,164.59,-0.002
48.28,164.43,-0.002
48.31,164.28,-0.002
48.35,164.12,-0.002
48.38,163.96,-0.002
48.41,163.80,-0.002
48.44,163.64,-0.002
48.47,163.49,-0.002
48.51,163.33,-0.002
48.54,163.17,-0.002
48.57,163.01,-0.002
48.60,162.85,-0.002
48.63,162.70,-0.002
48.66,162.54,-0.002
48.69,162.38,-0.002
48.73,162.22,-0.002
48.76,162.06,-0.002
48.79,161.90,-0.002
48.82,161.75,-0.002
48.85,161.59,-0.002
48.89,161.43,-0.002
48.92,161.27,-0.002
48.95,161.11,-0.002
48.98,160.95,-0.002
49.01,160.80,-0.002
49.04,160.64,-0.002
49.08,160.48,-0.002
49.11,160.32,-0.002
49.14,160.16,-0.002
49.17,160.01,-0.002
49.20,159.85,-0.002
49.23,159.69,-0.002
49.26,159.53,-0.002
49.30,159.37,-0.002
49.33,159.21,-0.002
49.36,159.06,-0.002
49.39,158.90,-0.002
49.42,158.74,-0.002
49.46,158.58,-0.002
49.49,158.42,-0.002
49.52,158.27,-0.002
49.55,158.11,-0.002
49.58,157.95,-0.002
49.61,157.79,-0.002
49.64,157.63,-0.002
49.68,157.47,-0.002
49.71,157.32,-0.002
49.74,157.16,-0.002
49.77,157.00,-0.002
49.80,156.84,-0.002
49.84,156.68,-0.002
49.87,156.52,-0.002
49.90,156.37,-0.002
49.93,156.21,-0.002
49.96,156.05,-0.002
49.99,155.89,-0.002
50.03,155.73,-0.002
50.06,155.57,-0.002
50.09,155.42,-0.002
50.12,155.26,-0.002
50.15,155.10,-0.002
50.18,154.94,-0.002
50.21,154.78,-0.002
50.25,154.63,-0.002
50.28,154.47,-0.002
50.31,154.31,-0.002
50.34,154.15,-0.002
50.37,153.99,-0.002
50.41,153.83,-0.002
50.44,153.68,-0.002
50.47,153.52,-0.002
50.50,153.36,-0.002
50.53,153.20,-0.002
50.56,153.04,-0.002
50.59,152.88,-0.002
50.63,152.73,-0.002
50.66,152.57,-0.002
50.69,152.41,-0.002
50.72,152.25,-0.002
50.75,152.09,-0.002
50.79,151.93,-0.002
50.82,151.77,-0.002
50.85,151.62,-0.002
50.88,151.46,-0.002
50.91,151.30,-0.002
50.94,151.15,-0.002
50.98,150.99,-0.002
51.01,150.83,-0.002
51.04,150.67,-0.002
51.07,150.51,-0.002
51.10,150.35,-0.002
51.13,150.20,-0.002
51.16,150.04,-0.002
51.20,149.88,-0.002
51.23,149.72,-0.002
51.26,149.56,-0.002
51.29,149.41,-0.002
51.32,149.25,-0.002
51.36,149.09,-0.002
51.39,148.93,-0.002
51.42,148.77,-0.002
51.45,148.61,-0.002
51.48,148.45,-0.002
51.51,148.29,-0.002
51.54,148.14,-0.002
51.58,147.98,-0.002
51.61,147.82,-0.002
51.64,147.66,-0.002
51.67,147.51,-0.002
51.70,147.35,-0.002
51.74,147.19,-0.002
51.77,147.03,-0.002
51.80,146.87,-0.002
51.83,146.71,-0.002
51.86,146.55,-0.002
51.89,146.39,-0.002
51.93,146.24,-0.002
51.96,146.08,-0.002
51.99,145.92,-0.002
52.02,145.76,-0.002
52.05,145.60,-0.002
52.08,145.44,-0.002
52.11,145.29,-0.002
52.15,145.13,-0.002
52.18,144.97,-0.002
52.21,144.81,-0.002
52.24,144.65,-0.002
52.27,144.50,-0.002
52.31,144.34,-0.002
52.34,144.18,-0.002
52.37,144.02,-0.002
52.40,143.86,-0.002
52.43,143.70,-0.002
52.46,143.55,-0.002
52.49,143.39,-0.002
52.53,143.23,-0.002
52.56,143.07,-0.002
52.59,142.91,-0.002
52.62,142.76,-0.002
52.65,142.60,-0.002
52.69,142.44,-0.002
52.72,142.28,-0.002
52.75,142.12,-0.002
52.78,141.97,-0.002
52.81,141.81,-0.002
52.84,141.65,-0.002
52.88,141.49,-0.002
52.91,141.33,-0.002
52.94,141.17,-0.002
52.97,141.02,-0.002
53.00,140.86,-0.002
53.03,140.70,-0.002
53.06,140.54,-0.002
53.10,140.38,-0.002
53.13,140.23,-0.002
53.16,140.07,-0.002
53.19,139.91,-0.002
53.22,139.75,-0.002
53.26,139.59,-0.002
53.29,139.43,-0.002
53.32,139.28,-0.002
53.35,139.12,-0.002
53.38,138.96,-0.002
53.41,138.80,-0.002
53.44,138.64,-0.002
53.48,138.48,-0.002
53.51,138.33,-0.002
53.54,138.17,-0.002
53.57,138.01,-0.002
53.60,137.85,-0.002
53.64,137.69,-0.002
53.67,137.54,-0.002
53.70,137.38,-0.002
53.73,137.22,-0.002
53.76,137.06,-0.002
53.79,136.90,-0.002
53.83,136.74,-0.002
53.86,136.59,-0.002
53.89,136.43,-0.002
53.92,136.27,-0.002
53.95,136.11,-0.002
53.98,135.95,-0.002
54.01,135.80,-0.002
54.05,135.64,-0.002
54.08,135.48,-0.002
54.11,135.32,-0.002
54.14,135.16,-0.002
54.17,135.00,-0.002
54.21,134.85,-0.002
54.24,134.69,-0.002
54.27,134.53,-0.002
54.30,134.37,-0.002
54.33,134.21,-0.002
54.36,134.05,-0.002
54.39,133.90,-0.002
54.43,133.74,-0.002
54.46,133.58,-0.002
54.49,133.42,-0.002
54.52,133.26,-0.002
54.55,133.10,-0.002
54.59,132.95,-0.002
54.62,132.79,-0.002
54.65,132.63,-0.002
54.68,132.47,-0.002
54.71,132.31,-0.002
54.74,132.15,-0.002
54.78,132.00,-0.002
54.81,131.84,-0.002
54.84,131.68,-0.002
54.87,131.52,-0.002
54.90,131.36,-0.002
54.93,131.21,-0.002
54.96,131.05,-0.002
55.00,130.89,-0.002
55.03,130.73,-0.002
55.06,130.57,-0.002
55.09,130.42,-0.002
55.12,130.26,-0.002
55.16,130.10,-0.002
55.19,129.94,-0.002
55.22,129.78,-0.002
55.25,129.62,-0.002
55.28,129.47,-0.002
55.31,129.31,-0.002
55.34,129.15,-0.002
55.38,128.99,-0.002
55.41,128.83,-0.002
55.44,128.68,-0.002
55.47,128.52,-0.002
55.50,128.36,-0.002
55.54,128.20,-0.002
55.57,128.04,-0.002
55.60,127.88,-0.002
55.63,127.72,-0.002
55.66,127.57,-0.002
55.69,127.41,-0.002
55.73,127.25,-0.002
55.76,127.09,-0.002
55.79,126.93,-0.002
55.82,126.78,-0.002
55.85,126.62,-0.002
55.88,126.46,-0.002
55.91,126.30,-0.002
55.95,126.14,-0.002
55.98,125.98,-0.002
56.01,125.83,-0.002
56.04,125.67,-0.002
56.07,125.51,-0.002
56.11,125.35,-0.002
56.14,125.19,-0.002
56.17,125.03,-0.002
56.20,124.88,-0.002
56.23,124.72,-0.002
56.26,124.56,-0.002
56.29,124.40,-0.002
56.33,124.24,-0.002
56.36,124.09,-0.002
56.39,123.93,-0.002
56.42,123.77,-0.002
56.45,123.61,-0.002
56.49,123.45,-0.002
56.52,123.29,-0.002
56.55,123.14,-0.002
56.58,122.98,-0.002
56.61,122.82,-0.002
56.64,122.66,-0.002
56.68,122.50,-0.002
56.71,122.34,-0.002
56.74,122.19,-0.002
56.77,122.03,-0.002
56.80,121.87,-0.002
56.83,121.71,-0.002
56.86,121.55,-0.002
56.90,121.39,-0.002
56.93,121.24,-0.002
56.96,121.08,-0.002
56.99,120.92,-0.002
57.02,120.76,-0.002
57.06,120.60,-0.002
57.09,120.44,-0.002
57.12,120.29,-0.002
57.15,120.13,-0.002
57.18,119.97,-0.002
57.21,119.81,-0.002
57.24,119.66,-0.002
57.28,119.50,-0.002
57.31,119.34,-0.002
57.34,119.18,-0.002
57.37,119.02,-0.002
57.40,118.86,-0.002
57.44,118.70,-0.002
57.47,118.55,-0.002
57.50,118.39,-0.002
57.53,118.23,-0.002
57.56,118.07,-0.002
57.59,117.91,-0.002
57.63,117.75,-0.002
57.66,117.60,-0.002
57.69,117.44,-0.002
57.72,117.28,-0.002
57.75,117.12,-0.002
57.78,116.96,-0.002
57.81,116.80,-0.002
57.85,116.65,-0.002
57.88,116.49,-0.002
57.91,116.33,-0.002
57.94,116.17,-0.002
57.97,116.01,-0.002
58.01,115.85,-0.002
58.04,115.70,-0.002
58.07,115.54,-0.002
58.10,115.38,-0.002
58.13,115.22,-0.002
58.16,115.06,-0.002
58.19,114.91,-0.002
58.23,114.75,-0.002
58.26,114.59,-0.002
58.29,114.43,-0.002
[...]
192.16,-39.89,0.001
192.17,-39.82,0.001
192.18,-39.75,0.001
192.20,-39.69,0.001
192.21,-39.62,0.001
192.23,-39.55,0.001
192.24,-39.49,0.001
192.25,-39.42,0.001
192.27,-39.35,0.001
192.28,-39.29,0.001
192.29,-39.22,0.001
192.30,-39.15,0.001
192.32,-39.08,0.001
192.33,-39.02,0.001
192.35,-38.95,0.001
192.36,-38.88,0.001
192.37,-38.82,0.001
192.38,-38.75,0.001
192.40,-38.68,0.001
192.41,-38.62,0.001
192.43,-38.55,0.001
192.44,-38.48,0.001
192.45,-38.42,0.001
192.47,-38.35,0.001
192.48,-38.28,0.001
192.49,-38.22,0.001
192.50,-38.15,0.001
192.52,-38.08,0.001
192.53,-38.02,0.001
192.55,-37.95,0.001
192.56,-37.88,0.001
192.57,-37.82,0.001
192.58,-37.75,0.001
192.60,-37.68,0.001
192.61,-37.62,0.001
192.63,-37.55,0.001
192.64,-37.48,0.001
192.65,-37.42,0.001
192.67,-37.35,0.001
192.68,-37.28,0.001
192.69,-37.22,0.001
192.70,-37.15,0.001
192.72,-37.08,0.001
192.73,-37.01,0.001
192.75,-36.95,0.001
192.76,-36.88,0.001
192.77,-36.82,0.001
192.78,-36.75,0.001
192.80,-36.68,0.001
192.81,-36.62,0.001
192.83,-36.55,0.001
192.84,-36.48,0.001
192.85,-36.42,0.001
192.87,-36.35,0.001
192.88,-36.28,0.001
192.89,-36.21,0.001
192.90,-36.15,0.001
192.92,-36.08,0.001
192.93,-36.02,0.001
192.95,-35.95,0.001
192.96,-35.88,0.001
192.97,-35.82,0.001
192.98,-35.75,0.001
193.00,-35.68,0.001
193.01,-35.62,0.001
193.03,-35.55,0.001
193.04,-35.48,0.001
193.05,-35.41,0.001
193.07,-35.35,0.001
193.08,-35.28,0.001
193.09,-35.21,0.001
193.10,-35.15,0.001
193.12,-35.08,0.001
193.13,-35.01,0.001
193.15,-34.95,0.001
193.16,-34.88,0.001
193.17,-34.81,0.001
193.18,-34.75,0.001
193.20,-34.68,0.001
193.21,-34.61,0.001
193.23,-34.55,0.001
193.24,-34.48,0.001
193.25,-34.41,0.001
193.27,-34.35,0.001
193.28,-34.28,0.001
193.29,-34.21,0.001
193.30,-34.15,0.001
193.32,-34.08,0.001
193.33,-34.01,0.001
193.35,-33.95,0.001
193.36,-33.88,0.001
193.37,-33.81,0.001
193.38,-33.75,0.001
193.40,-33.68,0.001
193.41,-33.61,0.001
193.43,-33.55,0.001
193.44,-33.48,0.001
193.45,-33.41,0.001
193.47,-33.35,0.001
193.48,-33.28,0.001
193.49,-33.21,0.001
193.50,-33.15,0.001
193.52,-33.08,0.001
193.53,-33.01,0.001
193.55,-32.94,0.001
193.56,-32.88,0.001
193.57,-32.81,0.001
193.58,-32.75,0.001
193.60,-32.68,0.001
193.61,-32.61,0.001
193.63,-32.55,0.001
193.64,-32.48,0.001
193.65,-32.41,0.001
193.67,-32.35,0.001
193.68,-32.28,0.001
193.69,-32.21,0.001
193.70,-32.14,0.001
193.72,-32.08,0.001
193.73,-32.01,0.001
193.75,-31.94,0.001
193.76,-31.88,0.001
193.77,-31.81,0.001
193.78,-31.74,0.001
193.80,-31.68,0.001
193.81,-31.61,0.001
193.83,-31.54,0.001
193.84,-31.48,0.001
193.85,-31.41,0.001
193.87,-31.34,0.001
193.88,-31.28,0.001
193.89,-31.21,0.001
193.90,-31.14,0.001
193.92,-31.08,0.001
193.93,-31.01,0.001
193.95,-30.94,0.001
193.96,-30.88,0.001
193.97,-30.81,0.001
193.98,-30.74,0.001
194.00,-30.68,0.001
194.01,-30.61,0.001
194.03,-30.54,0.001
194.04,-30.48,0.001
194.05,-30.41,0.001
194.07,-30.34,0.001
194.08,-30.28,0.001
194.09,-30.21,0.001
194.10,-30.14,0.001
194.12,-30.08,0.001
194.13,-30.01,0.001
194.15,-29.94,0.001
194.16,-29.88,0.001
194.17,-29.81,0.001
194.18,-29.74,0.001
194.20,-29.67,0.001
194.21,-29.61,0.001
194.23,-29.54,0.001
194.24,-29.48,0.001
194.25,-29.41,0.001
194.27,-29.34,0.001
194.28,-29.27,0.001
194.29,-29.21,0.001
194.30,-29.14,0.001
194.32,-29.07,0.001
194.33,-29.01,0.001
194.35,-28.94,0.001
194.36,-28.87,0.001
194.37,-28.81,0.001
194.38,-28.74,0.001
194.40,-28.67,0.001
194.41,-28.61,0.001
194.43,-28.54,0.001
194.44,-28.47,0.001
194.45,-28.41,0.001
194.47,-28.34,0.001
194.48,-28.27,0.001
194.49,-28.21,0.001
194.50,-28.14,0.001
194.52,-28.07,0.001
194.53,-28.01,0.001
194.55,-27.94,0.001
194.56,-27.87,0.001
194.57,-27.81,0.001
194.58,-27.74,0.001
194.60,-27.68,0.001
194.61,-27.61,0.001
194.63,-27.54,0.001
194.64,-27.47,0.001
194.65,-27.41,0.001
194.67,-27.34,0.001
194.68,-27.27,0.001
194.69,-27.21,0.001
194.70,-27.14,0.001
194.72,-27.07,0.001
194.73,-27.01,0.001
194.75,-26.94,0.001
194.76,-26.87,0.001
194.77,-26.81,0.001
194.78,-26.74,0.001
194.80,-26.67,0.001
194.81,-26.60,0.001
194.83,-26.54,0.001
194.84,-26.47,0.001
194.85,-26.41,0.001
194.87,-26.34,0.001
194.88,-26.27,0.001
194.89,-26.21,0.001
194.90,-26.14,0.001
194.92,-26.07,0.001
194.93,-26.01,0.001
194.95,-25.94,0.001
194.96,-25.87,0.001
194.97,-25.80,0.001
194.98,-25.74,0.001
195.00,-25.67,0.001
195.01,-25.60,0.001
195.03,-25.54,0.001
195.04,-25.47,0.001
195.05,-25.40,0.001
195.07,-25.34,0.001
195.08,-25.27,0.001
195.09,-25.20,0.001
195.10,-25.14,0.001
195.12,-25.07,0.001
195.13,-25.00,0.001
195.15,-24.94,0.001
195.16,-24.87,0.001
195.17,-24.80,0.001
195.18,-24.74,0.001
195.20,-24.67,0.001
195.21,-24.60,0.001
195.23,-24.54,0.001
195.24,-24.47,0.001
195.25,-24.40,0.001
195.27,-24.34,0.001
195.28,-24.27,0.001
195.29,-24.20,0.001
195.30,-24.14,0.001
195.32,-24.07,0.001
195.33,-24.00,0.001
195.35,-23.94,0.001
195.36,-23.87,0.001
195.37,-23.80,0.001
195.38,-23.74,0.001
195.40,-23.67,0.001
195.41,-23.60,0.001
195.43,-23.54,0.001
195.44,-23.47,0.001
195.45,-23.40,0.001
195.47,-23.33,0.001
195.48,-23.27,0.001
195.49,-23.20,0.001
195.50,-23.13,0.001
195.52,-23.07,0.001
195.53,-23.00,0.001
195.55,-22.94,0.001
195.56,-22.87,0.001
195.57,-22.80,0.001
195.58,-22.73,0.001
195.60,-22.67,0.001
195.61,-22.60,0.001
195.63,-22.54,0.001
195.64,-22.47,0.001
195.65,-22.40,0.001
195.67,-22.33,0.001
195.68,-22.27,0.001
195.69,-22.20,0.001
195.70,-22.13,0.001
195.72,-22.07,0.001
195.73,-22.00,0.001
195.75,-21.93,0.001
195.76,-21.87,0.001
195.77,-21.80,0.001
195.78,-21.73,0.001
195.80,-21.67,0.001
195.81,-21.60,0.001
195.83,-21.53,0.001
195.84,-21.47,0.001
195.85,-21.40,0.001
195.87,-21.33,0.001
195.88,-21.27,0.001
195.89,-21.20,0.001
195.90,-21.13,0.001
195.92,-21.07,0.001
195.93,-21.00,0.001
195.95,-20.93,0.001
195.96,-20.87,0.001
195.97,-20.80,0.001
195.98,-20.73,0.001
196.00,-20.67,0.001
196.01,-20.60,0.001
196.03,-20.53,0.001
196.04,-20.47,0.001
196.05,-20.40,0.001
196.07,-20.33,0.001
196.08,-20.27,0.001
196.09,-20.20,0.001
196.10,-20.13,0.001
196.12,-20.07,0.001
196.13,-20.00,0.001
196.15,-19.93,0.001
196.16,-19.87,0.001
196.17,-19.80,0.001
196.18,-19.73,0.001
196.20,-19.67,0.001
196.21,-19.60,0.001
196.23,-19.53,0.001
196.24,-19.47,0.001
196.25,-19.40,0.001
196.27,-19.33,0.001
196.28,-19.27,0.001
196.29,-19.20,0.001
196.30,-19.13,0.001
196.32,-19.06,0.001
196.33,-19.00,0.001
196.35,-18.93,0.001
196.36,-18.87,0.001
196.37,-18.80,0.001
196.38,-18.73,0.001
196.40,-18.66,0.001
196.41,-18.60,0.001
196.43,-18.53,0.001
196.44,-18.47,0.001
196.45,-18.40,0.001
196.47,-18.33,0.001
196.48,-18.26,0.001
196.49,-18.20,0.001
196.50,-18.13,0.001
196.52,-18.06,0.001
196.53,-18.00,0.001
196.55,-17.93,0.001
196.56,-17.86,0.001
196.57,-17.80,0.001
196.58,-17.73,0.001
196.60,-17.66,0.001
196.61,-17.59,0.001
196.63,-17.53,0.001
196.64,-17.46,0.001
196.65,-17.39,0.001
196.67,-17.33,0.001
196.68,-17.26,0.001
196.69,-17.19,0.001
196.70,-17.12,0.001
196.72,-17.06,0.001
196.73,-16.99,0.001
196.75,-16.92,0.001
196.76,-16.86,0.001
196.77,-16.79,0.001
196.78,-16.73,0.001
196.80,-16.66,0.001
196.81,-16.59,0.001
196.83,-16.52,0.001
196.84,-16.46,0.001
196.85,-16.39,0.001
196.87,-16.33,0.001
196.88,-16.26,0.001
196.89,-16.19,0.001
196.90,-16.13,0.001
196.92,-16.06,0.001
196.93,-15.99,0.001
196.95,-15.93,0.001
196.96,-15.86,0.001
196.97,-15.79,0.001
196.98,-15.73,0.001
197.00,-15.66,0.001
197.01,-15.59,0.001
197.03,-15.53,0.001
197.04,-15.46,0.001
197.05,-15.39,0.001
197.07,-15.33,0.001
197.08,-15.26,0.001
197.09,-15.19,0.001
197.10,-15.13,0.001
197.12,-15.06,0.001
197.13,-14.99,0.001
197.15,-14.93,0.001
197.16,-14.86,0.001
197.17,-14.79,0.001
197.18,-14.73,0.001
197.20,-14.66,0.001
197.21,-14.60,0.001
197.23,-14.53,0.001
197.24,-14.46,0.001
197.25,-14.39,0.001
197.27,-14.33,0.001
197.28,-14.26,0.001
197.29,-14.19,0.001
197.30,-14.13,0.001
197.32,-14.06,0.001
197.33,-13.99,0.001
197.35,-13.93,0.001
197.36,-13.86,0.001
197.37,-13.79,0.001
197.38,-13.73,0.001
197.40,-13.66,0.001
197.41,-13.59,0.001
197.43,-13.53,0.001
197.44,-13.46,0.001
197.45,-13.39,0.001
197.47,-13.33,0.001
197.48,-13.26,0.001
197.49,-13.19,0.001
197.50,-13.13,0.001
197.52,-13.06,0.001
197.53,-12.99,0.001
197.55,-12.93,0.001
197.56,-12.86,0.001
197.57,-12.79,0.001
197.58,-12.73,0.001
197.60,-12.66,0.001
197.61,-12.59,0.001
197.63,-12.53,0.001
197.64,-12.46,0.001
197.65,-12.39,0.001
197.67,-12.33,0.001
197.68,-12.26,0.001
197.69,-12.19,0.001
197.70,-12.12,0.001
197.72,-12.06,0.001
197.73,-11.99,0.001
197.75,-11.93,0.001
197.76,-11.86,0.001
197.77,-11.79,0.001
197.78,-11.73,0.001
197.80,-11.66,0.001
197.81,-11.59,0.001
197.83,-11.53,0.001
197.84,-11.46,0.001
197.85,-11.39,0.001
197.87,-11.33,0.001
197.88,-11.26,0.001
197.89,-11.19,0.001
197.90,-11.13,0.001
197.92,-11.06,0.001
197.93,-10.99,0.001
197.95,-10.92,0.001
197.96,-10.86,0.001
197.97,-10.79,0.001
197.98,-10.73,0.001
198.00,-10.66,0.001
198.01,-10.59,0.001
198.03,-10.53,0.001
198.04,-10.46,0.001
198.05,-10.39,0.001
198.07,-10.33,0.001
198.08,-10.26,0.001
198.09,-10.19,0.001
198.10,-10.13,0.001
198.12,-10.06,0.001
198.13,-9.99,0.001
198.15,-9.93,0.001
198.16,-9.86,0.001
198.17,-9.79,0.001
198.18,-9.72,0.001
198.20,-9.66,0.001
198.21,-9.59,0.001
198.23,-9.52,0.001
198.24,-9.46,0.001
198.25,-9.39,0.001
198.27,-9.32,0.001
198.28,-9.26,0.001
198.29,-9.19,0.001
198.30,-9.12,0.001
198.32,-9.06,0.001
198.33,-8.99,0.001
198.35,-8.93,0.001
198.36,-8.86,0.001
198.37,-8.79,0.001
198.38,-8.72,0.001
198.40,-8.66,0.001
198.41,-8.59,0.001
198.43,-8.52,0.001
198.44,-8.46,0.001
198.45,-8.39,0.001
198.47,-8.33,0.001
198.48,-8.26,0.001
198.49,-8.19,0.001
198.50,-8.13,0.001
198.52,-8.06,0.001
198.53,-7.99,0.001
198.55,-7.92,0.001
198.56,-7.86,0.001
198.57,-7.79,0.001
198.58,-7.72,0.001
198.60,-7.66,0.001
198.61,-7.59,0.001
198.63,-7.52,0.001
198.64,-7.46,0.001
198.65,-7.39,0.001
198.67,-7.32,0.001
198.68,-7.26,0.001
198.69,-7.19,0.001
198.70,-7.12,0.001
198.72,-7.06,0.001
198.73,-6.99,0.001
198.75,-6.93,0.001
198.76,-6.86,0.001
198.77,-6.79,0.001
198.78,-6.72,0.001
198.80,-6.66,0.001
198.81,-6.59,0.001
198.83,-6.52,0.001
198.84,-6.46,0.001
198.85,-6.39,0.001
198.87,-6.32,0.001
198.88,-6.26,0.001
198.89,-6.19,0.001
198.90,-6.12,0.001
198.92,-6.06,0.001
198.93,-5.99,0.001
198.95,-5.92,0.001
198.96,-5.86,0.001
198.97,-5.79,0.001
198.98,-5.72,0.001
199.00,-5.66,0.001
199.01,-5.59,0.001
199.03,-5.52,0.001
199.04,-5.46,0.001
199.05,-5.39,0.001
199.07,-5.32,0.001
199.08,-5.26,0.001
199.09,-5.19,0.001
199.10,-5.12,0.001
199.12,-5.06,0.001
199.13,-4.99,0.001
199.15,-4.92,0.001
199.16,-4.86,0.001
199.17,-4.79,0.001
199.18,-4.72,0.001
199.20,-4.66,0.001
199.21,-4.59,0.001
199.23,-4.52,0.001
199.24,-4.46,0.001
199.25,-4.39,0.001
199.27,-4.32,0.001
199.28,-4.26,0.001
199.29,-4.19,0.001
199.30,-4.12,0.001
199.32,-4.06,0.001
199.33,-3.99,0.001
199.35,-3.92,0.001
199.36,-3.86,0.001
199.37,-3.79,0.001
199.38,-3.72,0.001
199.40,-3.66,0.001
199.41,-3.59,0.001
199.43,-3.52,0.001
199.44,-3.46,0.001
199.45,-3.39,0.001
199.47,-3.32,0.001
199.48,-3.26,0.001
199.49,-3.19,0.001
199.50,-3.12,0.001
199.52,-3.06,0.001
199.53,-2.99,0.001
199.55,-2.92,0.001
199.56,-2.86,0.001
199.57,-2.79,0.001
199.58,-2.72,0.001
199.60,-2.66,0.001
199.61,-2.59,0.001
199.63,-2.53,0.001
199.64,-2.46,0.001
199.65,-2.39,0.001
199.67,-2.33,0.001
199.68,-2.26,0.001
199.69,-2.19,0.001
199.70,-2.13,0.001
199.72,-2.06,0.001
199.73,-1.99,0.001
199.75,-1.92,0.001
199.76,-1.86,0.001
199.77,-1.79,0.001
199.78,-1.73,0.001
199.80,-1.66,0.001
199.81,-1.59,0.001
199.83,-1.53,0.001
199.84,-1.46,0.001
199.85,-1.39,0.001
199.87,-1.33,0.001
199.88,-1.26,0.001
199.89,-1.19,0.001
199.90,-1.13,0.001
199.92,-1.06,0.001
199.93,-1.00,0.001
199.95,-0.93,0.001
199.96,-0.86,0.001
199.97,-0.79,0.001
199.98,-0.73,0.001
200.00,-0.66,0.001
200.01,-0.60,0.001
200.03,-0.53,0.001
200.04,-0.46,0.001
200.05,-0.40,0.001
200.07,-0.33,0.001
200.08,-0.26,0.001
200.09,-0.20,0.001
200.10,-0.13,0.001
200.12,-0.06,0.001
200.13,0.00,0.001
200.15,0.07,0.001
200.16,0.14,0.001
200.17,0.20,0.001
200.18,0.27,0.001
200.20,0.34,0.001
200.21,0.40,0.001
200.23,0.47,0.001
200.24,0.54,0.001
200.25,0.60,0.001
200.27,0.67,0.001
200.28,0.74,0.001
200.29,0.80,0.001
200.30,0.87,0.001
200.32,0.93,0.001
200.33,1.00,0.001
200.35,1.07,0.001
200.36,1.13,0.001
200.37,1.20,0.001
200.38,1.27,0.001
200.40,1.33,0.001
200.41,1.40,0.001
200.43,1.47,0.001
200.44,1.53,0.001
200.45,1.60,0.001
200.47,1.67,0.001
200.48,1.73,0.001
200.49,1.80,0.001
200.50,1.87,0.001
200.52,1.93,0.001
200.53,2.00,0.001
200.55,2.07,0.001
200.56,2.13,0.001
200.57,2.20,0.001
200.58,2.27,0.001
200.60,2.33,0.001
200.61,2.40,0.001
200.63,2.47,0.001
200.64,2.53,0.001
200.65,2.60,0.001
200.67,2.67,0.001
200.68,2.73,0.001
200.69,2.80,0.001
200.70,2.87,0.001
200.72,2.93,0.001
200.73,3.00,0.001
200.75,3.07,0.001
200.76,3.14,0.001
200.77,3.20,0.001
200.78,3.27,0.001
200.80,3.34,0.001
200.81,3.40,0.001
200.83,3.47,0.001
200.84,3.54,0.001
200.85,3.60,0.001
200.87,3.67,0.001
200.88,3.74,0.001
200.89,3.80,0.001
200.90,3.87,0.001
200.92,3.94,0.001
200.93,4.00,0.001
200.95,4.07,0.001
200.96,4.14,0.001
200.97,4.20,0.001
200.98,4.27,0.001
201.00,4.34,0.001
201.01,4.41,0.001
201.03,4.47,0.001
201.04,4.54,0.001
201.05,4.61,0.001
201.07,4.67,0.001
201.08,4.74,0.001
201.09,4.81,0.001
201.10,4.87,0.001
201.12,4.94,0.001
201.13,5.01,0.001
201.15,5.07,0.001
201.16,5.14,0.001
201.17,5.21,0.001
201.18,5.28,0.001
201.20,5.34,0.001
201.21,5.41,0.001
201.23,5.48,0.001
201.24,5.54,0.001
201.25,5.61,0.001
201.27,5.68,0.001
201.28,5.74,0.001
201.29,5.81,0.001
201.30,5.88,0.001
201.32,5.94,0.001
201.33,6.01,0.001
201.35,6.08,0.001
201.36,6.14,0.001
201.37,6.21,0.001
201.38,6.28,0.001
201.40,6.34,0.001
201.41,6.41,0.001
201.43,6.48,0.001
201.44,6.54,0.001
201.45,6.61,0.001
201.47,6.68,0.001
201.48,6.74,0.001
201.49,6.81,0.001
201.50,6.88,0.001
201.52,6.94,0.001
201.53,7.01,0.001
201.55,7.08,0.001
201.56,7.14,0.001
201.57,7.21,0.001
201.58,7.28,0.001
201.60,7.34,0.001
201.61,7.41,0.001
201.63,7.48,0.001
201.64,7.54,0.001
201.65,7.61,0.001
201.67,7.68,0.001
201.68,7.75,0.001
201.69,7.81,0.001
201.70,7.88,0.001
201.72,7.94,0.001
201.73,8.01,0.001
201.75,8.08,0.001
201.76,8.14,0.001
201.77,8.21,0.001
201.78,8.28,0.001
201.80,8.34,0.001
201.81,8.41,0.001
201.83,8.48,0.001
201.84,8.55,0.001
201.85,8.61,0.001
201.87,8.68,0.001
201.88,8.74,0.001
201.89,8.81,0.001
201.90,8.88,0.001
201.92,8.95,0.001
201.93,9.01,0.001
201.95,9.08,0.001
201.96,9.15,0.001
201.97,9.21,0.001
201.98,9.28,0.001
202.00,9.35,0.001
202.01,9.41,0.001
202.03,9.48,0.001
202.04,9.55,0.001
202.05,9.61,0.001
202.07,9.68,0.001
202.08,9.75,0.001
202.09,9.81,0.001
202.10,9.88,0.001
202.12,9.95,0.001
202.13,10.01,0.001
202.15,10.08,0.001
202.16,10.15,0.001
202.17,10.21,0.001
202.18,10.28,0.001
202.20,10.35,0.001
202.21,10.41,0.001
202.23,10.48,0.001
202.24,10.55,0.001
202.25,10.61,0.001
202.27,10.68,0.001
202.28,10.75,0.001
202.29,10.81,0.001
202.30,10.88,0.001
202.32,10.95,0.001
202.33,11.01,0.001
202.35,11.08,0.001
202.36,11.15,0.001
202.37,11.21,0.001
202.38,11.28,0.001
202.40,11.35,0.001
202.41,11.41,0.001
202.43,11.48,0.001
202.44,11.55,0.001
202.45,11.61,0.001
202.47,11.68,0.001
202.48,11.75,0.001
202.49,11.82,0.001
202.50,11.88,0.001
202.52,11.95,0.001
202.53,12.01,0.001
202.55,12.08,0.001
202.56,12.15,0.001
202.57,12.21,0.001
202.58,12.28,0.001
202.60,12.35,0.001
202.61,12.41,0.001
202.63,12.48,0.001
202.64,12.55,0.001
202.65,12.61,0.001
202.67,12.68,0.001
202.68,12.75,0.001
202.69,12.81,0.001
202.70,12.88,0.001
202.72,12.95,0.001
202.73,13.01,0.001
202.75,13.08,0.001
202.76,13.15,0.001
202.77,13.21,0.001
202.78,13.28,0.001
202.80,13.35,0.001
202.81,13.41,0.001
202.83,13.48,0.001
202.84,13.55,0.001
202.85,13.62,0.001
202.87,13.68,0.001
202.88,13.75,0.001
202.89,13.82,0.001
202.90,13.88,0.001
202.92,13.95,0.001
202.93,14.02,0.001
202.95,14.08,0.001
202.96,14.15,0.001
202.97,14.22,0.001
202.98,14.28,0.001
203.00,14.35,0.001
203.01,14.42,0.001
203.03,14.48,0.001
203.04,14.55,0.001
203.05,14.61,0.001
203.07,14.68,0.001
203.08,14.75,0.001
203.09,14.82,0.001
203.10,14.88,0.001
203.12,14.95,0.001
203.13,15.02,0.001
203.15,15.08,0.001
203.16,15.15,0.001
203.17,15.22,0.001
203.18,15.28,0.001
203.20,15.35,0.001
203.21,15.42,0.001
203.23,15.48,0.001
203.24,15.55,0.001
203.25,15.62,0.001
203.27,15.68,0.001
203.28,15.75,0.001
203.29,15.82,0.001
203.30,15.88,0.001
203.32,15.95,0.001
203.33,16.02,0.001
203.35,16.08,0.001
203.36,16.15,0.001
203.37,16.22,0.001
203.38,16.28,0.001
203.40,16.35,0.001
203.41,16.42,0.001
203.43,16.48,0.001
203.44,16.55,0.001
203.45,16.62,0.001
203.47,16.69,0.001
203.48,16.75,0.001
203.49,16.82,0.001
203.50,16.88,0.001
203.52,16.95,0.001
203.53,17.02,0.001
203.55,17.09,0.001
203.56,17.15,0.001
203.57,17.22,0.001
203.58,17.29,0.001
203.60,17.35,0.001
203.61,17.42,0.001
203.63,17.48,0.001
203.64,17.55,0.001
203.65,17.62,0.001
203.67,17.68,0.001
203.68,17.75,0.001
203.69,17.82,0.001
203.70,17.89,0.001
203.72,17.95,0.001
203.73,18.02,0.001
203.75,18.09,0.001
203.76,18.15,0.001
203.77,18.22,0.001
203.78,18.29,0.001
203.80,18.35,0.001
203.81,18.42,0.001
203.83,18.49,0.001
203.84,18.55,0.001
203.85,18.62,0.001
203.87,18.69,0.001
203.88,18.75,0.001
203.89,18.82,0.001
203.90,18.89,0.001
203.92,18.95,0.001
203.93,19.02,0.001
203.95,19.09,0.001
203.96,19.15,0.001
203.97,19.22,0.001
203.98,19.29,0.001
204.00,19.35,0.001
204.01,19.42,0.001
204.03,19.49,0.001
204.04,19.55,0.001
204.05,19.62,0.001
204.07,19.69,0.001
204.08,19.75,0.001
204.09,19.82,0.001
204.10,19.89,0.001
204.12,19.95,0.001
204.13,20.02,0.001
204.15,20.09,0.001
204.16,20.15,0.001
204.17,20.22,0.001
204.18,20.29,0.001
204.20,20.35,0.001
204.21,20.42,0.001
204.23,20.49,0.001
204.24,20.55,0.001
204.25,20.62,0.001
204.27,20.69,0.001
204.28,20.75,0.001
204.29,20.82,0.001
204.30,20.89,0.001
204.32,20.95,0.001
204.33,21.02,0.001
204.35,21.09,0.001
204.36,21.15,0.001
204.37,21.22,0.001
204.38,21.29,0.001
204.40,21.35,0.001
204.41,21.42,0.001
204.43,21.49,0.001
204.44,21.55,0.001
204.45,21.62,0.001
204.47,21.69,0.001
204.48,21.75,0.001
204.49,21.82,0.001
204.50,21.89,0.001
204.52,21.96,0.001
204.53,22.02,0.001
204.55,22.09,0.001
204.56,22.16,0.001
204.57,22.22,0.001
204.58,22.29,0.001
204.60,22.36,0.001
204.61,22.42,0.001
204.63,22.49,0.001
204.64,22.56,0.001
204.65,22.62,0.001
204.67,22.69,0.001
204.68,22.76,0.001
204.69,22.82,0.001
204.70,22.89,0.001
204.72,22.96,0.001
204.73,23.02,0.001
204.75,23.09,0.001
204.76,23.16,0.001
204.77,23.22,0.001
204.78,23.29,0.001
204.80,23.36,0.001
204.81,23.42,0.001
204.83,23.49,0.001
204.84,23.56,0.001
204.85,23.62,0.001
204.87,23.69,0.001
204.88,23.76,0.001
204.89,23.82,0.001
204.90,23.89,0.001
204.92,23.96,0.001
204.93,24.02,0.001
204.95,24.09,0.001
204.96,24.16,0.001
204.97,24.22,0.001
204.98,24.29,0.001
205.00,24.36,0.001
205.01,24.42,0.001
205.03,24.49,0.001
205.04,24.56,0.001
205.05,24.62,0.001
205.07,24.69,0.001
205.08,24.76,0.001
205.09,24.82,0.001
205.10,24.89,0.001
205.12,24.96,0.001
205.13,25.02,0.001
205.15,25.09,0.001
205.16,25.16,0.001
205.17,25.22,0.001
205.18,25.29,0.001
205.20,25.36,0.001
205.21,25.42,0.001
205.23,25.49,0.001
205.24,25.56,0.001
205.25,25.63,0.001
205.27,25.69,0.001
205.28,25.76,0.001
205.29,25.82,0.001
205.30,25.89,0.001
205.32,25.96,0.001
205.33,26.03,0.001
205.35,26.09,0.001
205.36,26.16,0.001
205.37,26.23,0.001
205.38,26.29,0.001
205.40,26.36,0.001
205.41,26.42,0.001
205.43,26.49,0.001
205.44,26.56,0.001
205.45,26.62,0.001
205.47,26.69,0.001
205.48,26.76,0.001
205.49,26.82,0.001
205.50,26.89,0.001
205.52,26.96,0.001
205.53,27.02,0.001
205.55,27.09,0.001
205.56,27.16,0.001
205.57,27.23,0.001
205.58,27.29,0.001
205.60,27.36,0.001
205.61,27.42,0.001
205.63,27.49,0.001
205.64,27.56,0.001
205.65,27.62,0.001
205.67,27.69,0.001
205.68,27.76,0.001
205.69,27.83,0.001
205.70,27.89,0.001
205.72,27.96,0.001
205.73,28.03,0.001
205.75,28.09,0.001
205.76,28.16,0.001
205.77,28.23,0.001
205.78,28.29,0.001
205.80,28.36,0.001
205.81,28.43,0.001
205.83,28.49,0.001
205.84,28.56,0.001
205.85,28.63,0.001
205.87,28.69,0.001
205.88,28.76,0.001
205.89,28.83,0.001
205.90,28.89,0.001
205.92,28.96,0.001
205.93,29.03,
205.95,29.09,
205.96,29.16,
205.97,29.23,
205.98,,