File: DSC/2025_02_10_Benzoic_Acid_Std_DSC.txt
Filename	2025_02_10_Benzoic_Acid_Std_DSC
Instrument name	DSC2A-00468 (192.168.1.100)
Operator	JLY
rundate	2/10/2025
Sample name	2025_02_10_Benzoic_Acid_Std_DSC
proceduresegments	Data Off ; Equilibrate 30.00 °C; Data On ; Ramp 5.00 °C/min to 150.00 °C
[File Parameters]
Run date	2/10/2025 4:18:41 PM
Trios version	5.1.1.46572
Original File Name
Current File Name	D:\DSC2500\CHM343\2025_02_10_Benzoic_Acid_Std_DSC.tri
[Procedure]
Procedure Name	Benzoic Acid Std Melting
Sample Name	2025_02_10_Benzoic_Acid_Std_DSC
Sample Mass	2.94 mg
Reference Sample Mass	0 mg
Pan Mass	54.23 mg
Pan Number	20
Reference Pan Mass	54 mg
Reference Pan Number	19
Pan Type	Tzero Aluminum Hermetic
Comments	Al Hermetic Sealed Pan, with ref Al pan - Benzoic Acid Std DSC Sample.
Project Name
Operator	JLY
Test	Custom
Unload Max Temperature	30
Unload Min Temperature	30
Load Max Temperature	30
Load Min Temperature	30
Stop on Gas Flow Error	Yes
[Signal List]
Signal #1	Time (min)
Signal #2	Temperature (°C)
Signal #3	Heat Flow (mW)
Signal #4	Delta T (µV)
Signal #5	Delta Tzero (µV)
Signal #6	Tzero Temperature (°C)
Signal #7	Cell Purge (mL/min)
Signal #8	Heater Temp (°C)
Signal #9	Power Delivered (W)
Signal #10	Reference Junction Temperature (°C)
Signal #11	Flange Temperature (°C)
Signal #12	Heat Flow Phase (rad)
Signal #13	Total Heat Capacity (J/°C)
Signal #14	Heat Capacity (J/°C)
[Configuration]
Company Name	ASU
Instrument Name	DSC2A-00468
Instrument Type	DSC2500
Serial Number	DSC2A-00468
IP	192.168.1.100
Location of Instrument	MRRC
DisplayType	Unknown
Sample Interval 	0.1 s/pt
Selected Heat Flow	T4P
Exotherm Direction	Down
Cell Serial	DRC2-00792
Lid Type	Standard
Cooler	RCS 90
Leave Cooler on at End of Sequence	On
Gas 2	Nitrogen
Gas Selected	Channel 1
Flow Rate	50 mL/min
Secondary Purge	On
Licensed Heat Flow	Heat Flow T4P
Modulation Licensed	Yes
[Versions]
Common IDD Version	1
Cortex Version	VER 2.10.2.31
Driver	5.0.0.6
GDM Version	1.0.3.3
TouchscreenVersion	1.0.0.16145
FEP Version	1.2.1.21
FEP Bootloader	2.0.0.5
AutoSampler Version	2.1.1.26
Auto Sampler Bootloader	2.0.0.5
FCM Version	1.1.0.3
FCM Bootloader	2.0.0.5
[Experiment Logs]
Experiment Log Entry # 1	Data On set to 0
Experiment Log Entry # 3	Equilibrate Segment 30 (C) Started
Experiment Log Entry # 5	Data On set to 1
Experiment Log Entry # 7	Ramp Segment 5 C/min to 150 Started
[Method Log]
Method Log Entry # 1	Data Off
Method Log Entry # 2	Equilibrate 30 °C
Method Log Entry # 3	Data On
Method Log Entry # 4	(Ramp 7456) Ramp 5 °C/minute to 150 °C
Cell Serial	DRC2-00792
[T1 Calibration]
Slope	-0.008529666
Offset	9.636258
Initial Temperature	98.23
GUID	f8bfdadc-4977-4fdf-ba6d-0ba9134940c3
[TZero Calibration]
Date Applied	11/29/2022 4:06:13 PM
Description	From -89.059 °C to 396.009 °C at 20.000°C/min
Gas Type	Nitrogen
Pan Type	None
Source Files 1	C:\Users\yargerlab\Desktop\DSC Data\General\TZero_calibration_11_29_22_2nd(2).tri
Source Files 2	C:\Users\yargerlab\Desktop\DSC Data\General\TZero_calibration_11_29_22_2nd(3).tri
Delta T Offset	13.05235
Delta T Slope	-0.007271007
Delta T0 Offset	-13.69128
Delta T0 Slope	0.06063341
[Temperature Calibration]
Date Applied	11/29/2022 7:12:28 PM
Description	From 106.590 °C to 186.590 °C at 10.000°C/min
Gas Type	Nitrogen
Pan Type	Tzero Aluminum Hermetic
Source Files 1	C:\Users\yargerlab\Desktop\DSC Data\General\Indium(6).tri
Measured 1	157.391
Known 1	156.598
[Cell Constant Calibration]
Date Applied	11/29/2022 7:12:29 PM
Description	From 106.590 °C to 186.590 °C at 10.000°C/min
Gas Type	Nitrogen
Pan Type	Tzero Aluminum Hermetic
Source Files 1	C:\Users\yargerlab\Desktop\DSC Data\General\Indium(6).tri
T4P KCell	1.006051
Onset Slope	63.26126 mW/°C
[Direct Cp Calibration]
Date Applied	11/30/2022 11:04:51 AM
Description	From -79.983 °C to 298.409 °C at 10.000°C/min
Gas Type	Nitrogen
Pan Type	Tzero Aluminum Hermetic
Source Files 1	C:\Users\yargerlab\Desktop\DSC Data\General\Sapphire_Heat_Capacity_11_30_22.tri
[Rev Cp Calibration]
Date Applied	11/30/2022 1:58:51 PM
Description	From -79.996 °C to 292.812 °C at 3.000°C/min
Gas Type	Nitrogen
Pan Type	Tzero Aluminum Hermetic
Source Files 1	C:\Users\yargerlab\Desktop\DSC Data\General\Sapphire_MDSC_Calibration_11_30_22.tri
[step]
Ramp 5.00 °C/min to 150.00 °C
Time	Temperature	Heat Flow (Normalized)
min	°C	W/g
0.00	29.93	0.003
0.02	29.94	0.001
0.03	29.96	0.000
0.05	29.97	-0.002
0.07	29.99	-0.002
0.08	30.02	-0.002
0.10	30.06	-0.001
0.12	30.10	0.006
0.13	30.15	0.023
0.15	30.21	0.036
0.17	30.28	0.049
0.18	30.35	0.057
0.20	30.42	0.067
0.22	30.49	0.074
0.23	30.56	0.079
0.25	30.64	0.081
0.27	30.72	0.090
0.28	30.80	0.090
0.30	30.88	0.093
0.32	30.96	0.097
0.33	31.04	0.098
0.35	31.12	0.100
0.37	31.20	0.101
0.38	31.29	0.102
0.40	31.37	0.103
0.42	31.45	0.104
0.43	31.54	0.105
0.45	31.62	0.105
0.47	31.71	0.105
0.48	31.79	0.106
0.50	31.87	0.106
0.52	31.96	0.107
0.53	32.04	0.107
0.55	32.12	0.107
0.57	32.21	0.108
0.58	32.29	0.108
0.60	32.38	0.108
0.62	32.46	0.108
0.63	32.54	0.109
0.65	32.63	0.109
0.67	32.71	0.109
0.68	32.79	0.109
0.70	32.88	0.109
0.72	32.96	0.110
0.73	33.05	0.110
0.75	33.13	0.110
0.77	33.21	0.110
0.78	33.30	0.110
0.80	33.38	0.110
0.82	33.46	0.110
0.83	33.55	0.110
0.85	33.63	0.110
0.87	33.71	0.110
0.88	33.80	0.110
0.90	33.88	0.110
0.92	33.96	0.110
0.93	34.05	0.110
0.95	34.13	0.110
0.97	34.21	0.110
0.98	34.30	0.110
1.00	34.38	0.110
1.02	34.46	0.110
1.03	34.55	0.110
1.05	34.63	0.110
1.07	34.72	0.110
1.08	34.80	0.110
1.10	34.88	0.110
1.12	34.97	0.110
1.13	35.05	0.110
1.15	35.13	0.110
1.17	35.22	0.110
1.18	35.30	0.110
1.20	35.38	0.110
1.22	35.46	0.110
1.23	35.55	0.110
1.25	35.63	0.110
1.27	35.72	0.110
1.28	35.80	0.110
1.30	35.88	0.110
1.32	35.96	0.110
1.33	36.05	0.110
1.35	36.13	0.110
1.37	36.21	0.110
1.38	36.30	0.110
1.40	36.38	0.110
1.42	36.47	0.110
1.43	36.55	0.110
1.45	36.63	0.110
1.47	36.72	0.110
1.48	36.80	0.110
1.50	36.88	0.110
1.52	36.96	0.110
1.53	37.05	0.110
1.55	37.13	0.110
1.57	37.21	0.110
1.58	37.30	0.110
1.60	37.38	0.110
1.62	37.47	0.110
1.63	37.55	0.109
1.65	37.63	0.110
1.67	37.71	0.109
1.68	37.80	0.109
1.70	37.88	0.109
1.72	37.96	0.109
1.73	38.05	0.109
1.75	38.13	0.109
1.77	38.22	0.109
1.78	38.30	0.109
1.80	38.38	0.109
1.82	38.47	0.109
1.83	38.55	0.109
1.85	38.63	0.109
1.87	38.72	0.109
1.88	38.80	0.109
1.90	38.88	0.109
1.92	38.97	0.109
1.93	39.05	0.109
1.95	39.13	0.109
1.97	39.22	0.109
1.98	39.30	0.109
2.00	39.38	0.109
2.02	39.47	0.109
2.03	39.55	0.109
2.05	39.63	0.109
2.07	39.72	0.109
2.08	39.80	0.109
2.10	39.88	0.109
2.12	39.97	0.109
2.13	40.05	0.109
2.15	40.13	0.109
2.17	40.22	0.109
2.18	40.30	0.109
2.20	40.38	0.109
2.22	40.47	0.109
2.23	40.55	0.109
2.25	40.63	0.109
2.27	40.72	0.109
2.28	40.80	0.109
2.30	40.88	0.109
2.32	40.97	0.109
2.33	41.05	0.109
2.35	41.13	0.109
2.37	41.22	0.110
2.38	41.30	0.109
2.40	41.38	0.110
2.42	41.47	0.110
2.43	41.55	0.110
2.45	41.63	0.110
2.47	41.72	0.110
2.48	41.80	0.110
2.50	41.88	0.110
2.52	41.97	0.110
2.53	42.05	0.110
2.55	42.13	0.110
2.57	42.22	0.110
2.58	42.30	0.110
2.60	42.38	0.110
2.62	42.47	0.110
2.63	42.55	0.110
2.65	42.63	0.110
2.67	42.72	0.110
2.68	42.80	0.110
2.70	42.88	0.110
2.72	42.97	0.110
2.73	43.05	0.110
2.75	43.13	0.110
2.77	43.22	0.110
2.78	43.30	0.110
2.80	43.38	0.110
2.82	43.47	0.110
2.83	43.55	0.110
2.85	43.63	0.110
2.87	43.72	0.110
2.88	43.80	0.110
2.90	43.88	0.110
2.92	43.97	0.110
2.93	44.05	0.110
2.95	44.13	0.110
2.97	44.22	0.110
2.98	44.30	0.110
3.00	44.38	0.110
3.02	44.47	0.110
3.03	44.55	0.110
3.05	44.63	0.110
3.07	44.72	0.110
3.08	44.80	0.110
3.10	44.89	0.110
3.12	44.97	0.110
3.13	45.05	0.110
3.15	45.13	0.110
3.17	45.22	0.110
3.18	45.30	0.110
3.20	45.38	0.110
3.22	45.47	0.110
3.23	45.55	0.110
3.25	45.64	0.110
3.27	45.72	0.110
3.28	45.80	0.110
3.30	45.89	0.110
3.32	45.97	0.110
3.33	46.05	0.110
3.35	46.14	0.110
3.37	46.22	0.110
3.38	46.30	0.110
3.40	46.39	0.111
3.42	46.47	0.111
3.43	46.55	0.111
3.45	46.64	0.111
3.47	46.72	0.111
3.48	46.80	0.111
3.50	46.89	0.111
3.52	46.97	0.111
3.53	47.05	0.111
3.55	47.14	0.111
3.57	47.22	0.111
3.58	47.30	0.111
3.60	47.39	0.111
3.62	47.47	0.111
3.63	47.55	0.111
3.65	47.64	0.111
3.67	47.72	0.111
3.68	47.80	0.111
3.70	47.89	0.111
3.72	47.97	0.111
3.73	48.05	0.111
3.75	48.14	0.111
3.77	48.22	0.111
3.78	48.30	0.111
3.80	48.39	0.111
3.82	48.47	0.111
3.83	48.56	0.111
3.85	48.64	0.111
3.87	48.72	0.111
3.88	48.80	0.111
3.90	48.89	0.111
3.92	48.97	0.111
3.93	49.05	0.111
3.95	49.14	0.111
3.97	49.22	0.111
3.98	49.30	0.111
4.00	49.39	0.111
4.02	49.47	0.111
4.03	49.55	0.111
4.05	49.64	0.111
4.07	49.72	0.111
4.08	49.80	0.111
4.10	49.89	0.111
4.12	49.97	0.111
4.13	50.05	0.111
4.15	50.14	0.112
4.17	50.22	0.111
4.18	50.31	0.111
4.20	50.39	0.111
4.22	50.47	0.111
4.23	50.56	0.112
4.25	50.64	0.112
4.27	50.72	0.112
4.28	50.81	0.112
4.30	50.89	0.112
4.32	50.97	0.112
4.33	51.06	0.112
4.35	51.14	0.112
4.37	51.22	0.112
4.38	51.31	0.112
4.40	51.39	0.112
4.42	51.47	0.112
4.43	51.56	0.112
4.45	51.64	0.112
4.47	51.72	0.112
4.48	51.81	0.112
4.50	51.89	0.112
4.52	51.97	0.112
4.53	52.06	0.112
4.55	52.14	0.112
4.57	52.22	0.112
4.58	52.31	0.112
4.60	52.39	0.112
4.62	52.47	0.112
4.63	52.56	0.112
4.65	52.64	0.112
4.67	52.72	0.112
4.68	52.81	0.112
4.70	52.89	0.112
4.72	52.97	0.112
4.73	53.06	0.112
4.75	53.14	0.112
4.77	53.22	0.112
4.78	53.31	0.112
4.80	53.39	0.113
4.82	53.47	0.112
4.83	53.56	0.113
4.85	53.64	0.113
4.87	53.72	0.113
4.88	53.81	0.113
4.90	53.89	0.113
4.92	53.97	0.113
4.93	54.06	0.113
4.95	54.14	0.113
4.97	54.22	0.113
4.98	54.31	0.113
5.00	54.39	0.113
5.02	54.47	0.113
5.03	54.56	0.113
5.05	54.64	0.113
5.07	54.72	0.113
5.08	54.81	0.113
5.10	54.89	0.113
5.12	54.97	0.113
5.13	55.06	0.113
5.15	55.14	0.113
5.17	55.22	0.113
5.18	55.31	0.113
5.20	55.39	0.113
5.22	55.47	0.113
5.23	55.56	0.113
5.25	55.64	0.113
5.27	55.73	0.113
5.28	55.81	0.113
5.30	55.89	0.113
5.32	55.97	0.113
5.33	56.06	0.113
5.35	56.14	0.113
5.37	56.22	0.113
5.38	56.31	0.113
5.40	56.39	0.113
5.42	56.47	0.113
5.43	56.56	0.113
5.45	56.64	0.113
5.47	56.73	0.113
5.48	56.81	0.113
5.50	56.89	0.113
5.52	56.98	0.113
5.53	57.06	0.113
5.55	57.14	0.113
5.57	57.23	0.114
5.58	57.31	0.114
5.60	57.39	0.114
5.62	57.48	0.114
5.63	57.56	0.114
5.65	57.64	0.114
5.67	57.73	0.114
5.68	57.81	0.114
5.70	57.89	0.114
5.72	57.98	0.114
5.73	58.06	0.114
5.75	58.14	0.114
5.77	58.23	0.114
5.78	58.31	0.114
5.80	58.39	0.114
5.82	58.48	0.114
5.83	58.56	0.114
5.85	58.64	0.114
5.87	58.73	0.114
5.88	58.81	0.114
5.90	58.89	0.114
5.92	58.98	0.114
5.93	59.06	0.114
5.95	59.14	0.114
5.97	59.23	0.114
5.98	59.31	0.114
6.00	59.39	0.114
6.02	59.48	0.114
6.03	59.56	0.114
6.05	59.64	0.114
6.07	59.73	0.114
6.08	59.81	0.114
6.10	59.89	0.114
6.12	59.98	0.115
6.13	60.06	0.115
6.15	60.14	0.115
6.17	60.23	0.115
6.18	60.31	0.115
6.20	60.39	0.115
6.22	60.48	0.115
6.23	60.56	0.115
6.25	60.64	0.115
6.27	60.73	0.115
6.28	60.81	0.115
6.30	60.89	0.115
6.32	60.98	0.115
6.33	61.06	0.115
6.35	61.15	0.115
6.37	61.23	0.115
6.38	61.31	0.115
6.40	61.39	0.115
6.42	61.48	0.115
6.43	61.56	0.115
6.45	61.65	0.115
6.47	61.73	0.115
6.48	61.81	0.115
6.50	61.90	0.115
6.52	61.98	0.115
6.53	62.06	0.115
6.55	62.15	0.115
6.57	62.23	0.115
6.58	62.31	0.115
6.60	62.40	0.115
6.62	62.48	0.115
6.63	62.56	0.115
6.65	62.65	0.115
6.67	62.73	0.115
6.68	62.81	0.115
6.70	62.90	0.115
6.72	62.98	0.115
6.73	63.06	0.115
6.75	63.15	0.115
6.77	63.23	0.115
6.78	63.31	0.115
6.80	63.39	0.115
6.82	63.48	0.115
6.83	63.56	0.115
6.85	63.64	0.115
6.87	63.73	0.115
6.88	63.81	0.116
6.90	63.90	0.116
6.92	63.98	0.116
6.93	64.06	0.116
6.95	64.15	0.116
6.97	64.23	0.116
6.98	64.31	0.116
7.00	64.40	0.116
7.02	64.48	0.116
7.03	64.56	0.116
7.05	64.65	0.116
7.07	64.73	0.116
7.08	64.81	0.116
7.10	64.90	0.116
7.12	64.98	0.116
7.13	65.06	0.116
7.15	65.15	0.116
7.17	65.23	0.116
7.18	65.31	0.116
7.20	65.40	0.116
7.22	65.48	0.116
7.23	65.56	0.116
7.25	65.65	0.116
7.27	65.73	0.116
7.28	65.81	0.116
7.30	65.90	0.116
7.32	65.98	0.116
7.33	66.06	0.116
7.35	66.15	0.116
7.37	66.23	0.116
7.38	66.31	0.116
7.40	66.40	0.116
7.42	66.48	0.116
7.43	66.56	0.116
7.45	66.65	0.116
7.47	66.73	0.116
7.48	66.81	0.117
7.50	66.90	0.116
7.52	66.98	0.117
7.53	67.06	0.117
7.55	67.15	0.117
7.57	67.23	0.117
7.58	67.31	0.117
7.60	67.40	0.117
7.62	67.48	0.117
7.63	67.56	0.117
7.65	67.65	0.117
7.67	67.73	0.117
7.68	67.81	0.117
7.70	67.90	0.117
7.72	67.98	0.117
7.73	68.06	0.117
7.75	68.15	0.117
7.77	68.23	0.117
7.78	68.31	0.117
7.80	68.40	0.117
7.82	68.48	0.117
7.83	68.56	0.117
7.85	68.65	0.117
7.87	68.73	0.117
7.88	68.81	0.117
7.90	68.90	0.117
7.92	68.98	0.117
7.93	69.06	0.117
7.95	69.15	0.117
7.97	69.23	0.117
7.98	69.31	0.117
8.00	69.40	0.117
8.02	69.48	0.117
8.03	69.57	0.117
8.05	69.65	0.117
8.07	69.73	0.118
8.08	69.82	0.118
8.10	69.90	0.118
8.12	69.98	0.118
8.13	70.07	0.118
8.15	70.15	0.118
8.17	70.23	0.118
8.18	70.32	0.118
8.20	70.40	0.118
8.22	70.48	0.118
8.23	70.57	0.118
8.25	70.65	0.118
8.27	70.73	0.118
8.28	70.82	0.118
8.30	70.90	0.118
8.32	70.98	0.118
8.33	71.07	0.118
8.35	71.15	0.118
8.37	71.23	0.118
8.38	71.32	0.118
8.40	71.40	0.118
8.42	71.48	0.118
8.43	71.57	0.118
8.45	71.65	0.118
8.47	71.73	0.118
8.48	71.82	0.118
8.50	71.90	0.118
8.52	71.98	0.118
8.53	72.07	0.118
8.55	72.15	0.118
8.57	72.23	0.118
8.58	72.32	0.118
8.60	72.40	0.118
8.62	72.48	0.118
8.63	72.57	0.118
8.65	72.65	0.118
8.67	72.73	0.118
8.68	72.82	0.119
8.70	72.90	0.119
8.72	72.98	0.119
8.73	73.07	0.119
8.75	73.15	0.119
8.77	73.24	0.119
8.78	73.32	0.119
8.80	73.40	0.119
8.82	73.48	0.119
8.83	73.57	0.119
8.85	73.65	0.119
8.87	73.73	0.119
8.88	73.82	0.119
8.90	73.90	0.119
8.92	73.98	0.119
8.93	74.07	0.119
8.95	74.15	0.119
8.97	74.23	0.119
8.98	74.32	0.119
9.00	74.40	0.119
9.02	74.48	0.119
9.03	74.57	0.119
9.05	74.65	0.119
9.07	74.74	0.119
9.08	74.82	0.119
9.10	74.90	0.119
9.12	74.98	0.119
9.13	75.07	0.119
9.15	75.15	0.119
9.17	75.23	0.119
9.18	75.32	0.119
9.20	75.40	0.119
9.22	75.49	0.119
9.23	75.57	0.119
9.25	75.65	0.119
9.27	75.74	0.119
9.28	75.82	0.119
9.30	75.90	0.119
9.32	75.98	0.119
9.33	76.07	0.119
9.35	76.15	0.119
9.37	76.24	0.120
9.38	76.32	0.120
9.40	76.40	0.120
9.42	76.49	0.119
9.43	76.57	0.120
9.45	76.65	0.120
9.47	76.74	0.120
9.48	76.82	0.120
9.50	76.90	0.120
9.52	76.98	0.120
9.53	77.07	0.120
9.55	77.15	0.120
9.57	77.24	0.120
9.58	77.32	0.120
9.60	77.40	0.120
9.62	77.49	0.120
9.63	77.57	0.120
9.65	77.65	0.120
9.67	77.74	0.120
9.68	77.82	0.120
9.70	77.90	0.120
9.72	77.99	0.120
9.73	78.07	0.120
9.75	78.15	0.120
9.77	78.24	0.120
9.78	78.32	0.120
9.80	78.40	0.120
9.82	78.49	0.120
9.83	78.57	0.120
9.85	78.65	0.120
9.87	78.74	0.120
9.88	78.82	0.120
9.90	78.90	0.120
9.92	78.99	0.120
9.93	79.07	0.120
9.95	79.15	0.120
9.97	79.24	0.120
9.98	79.32	0.120
10.00	79.40	0.121
10.02	79.49	0.121
10.03	79.57	0.121
10.05	79.66	0.121
10.07	79.74	0.121
10.08	79.82	0.121
10.10	79.91	0.121
10.12	79.99	0.121
10.13	80.07	0.121
10.15	80.15	0.121
10.17	80.24	0.121
10.18	80.32	0.121
10.20	80.41	0.121
10.22	80.49	0.121
10.23	80.57	0.121
10.25	80.66	0.121
10.27	80.74	0.121
10.28	80.82	0.121
10.30	80.90	0.121
10.32	80.99	0.121
10.33	81.07	0.121
10.35	81.15	0.121
10.37	81.24	0.121
10.38	81.32	0.121
10.40	81.41	0.121
10.42	81.49	0.121
10.43	81.57	0.121
10.45	81.66	0.121
10.47	81.74	0.121
10.48	81.82	0.121
10.50	81.91	0.121
10.52	81.99	0.121
10.53	82.07	0.121
10.55	82.16	0.121
10.57	82.24	0.121
10.58	82.32	0.121
10.60	82.41	0.121
10.62	82.49	0.121
10.63	82.57	0.121
10.65	82.66	0.121
10.67	82.74	0.121
10.68	82.82	0.121
10.70	82.91	0.121
10.72	82.99	0.121
10.73	83.07	0.121
10.75	83.16	0.121
10.77	83.24	0.121
10.78	83.32	0.121
10.80	83.41	0.121
10.82	83.49	0.121
10.83	83.57	0.121
10.85	83.66	0.121
10.87	83.74	0.121
10.88	83.82	0.121
10.90	83.91	0.121
10.92	83.99	0.121
10.93	84.07	0.121
10.95	84.16	0.121
10.97	84.24	0.121
10.98	84.32	0.121
11.00	84.41	0.121
11.02	84.49	0.122
11.03	84.57	0.122
11.05	84.66	0.122
11.07	84.74	0.122
11.08	84.82	0.122
11.10	84.91	0.122
11.12	84.99	0.122
11.13	85.07	0.122
11.15	85.16	0.122
11.17	85.24	0.122
11.18	85.32	0.122
11.20	85.41	0.122
11.22	85.49	0.122
11.23	85.57	0.122
11.25	85.66	0.122
11.27	85.74	0.122
11.28	85.82	0.122
11.30	85.91	0.122
11.32	85.99	0.122
11.33	86.07	0.122
11.35	86.16	0.122
11.37	86.24	0.122
11.38	86.32	0.122
11.40	86.41	0.122
11.42	86.49	0.122
11.43	86.57	0.122
11.45	86.66	0.122
11.47	86.74	0.122
11.48	86.82	0.122
11.50	86.91	0.122
11.52	86.99	0.122
11.53	87.07	0.122
11.55	87.16	0.122
11.57	87.24	0.122
11.58	87.32	0.122
11.60	87.41	0.122
11.62	87.49	0.122
11.63	87.57	0.122
11.65	87.66	0.122
11.67	87.74	0.122
11.68	87.82	0.122
11.70	87.91	0.122
11.72	87.99	0.122
11.73	88.08	0.122
11.75	88.16	0.122
11.77	88.24	0.122
11.78	88.32	0.123
11.80	88.41	0.123
11.82	88.49	0.123
11.83	88.57	0.123
11.85	88.66	0.123
11.87	88.74	0.123
11.88	88.82	0.123
11.90	88.91	0.123
11.92	88.99	0.123
11.93	89.07	0.123
11.95	89.16	0.123
11.97	89.24	0.123
11.98	89.32	0.123
12.00	89.41	0.123
12.02	89.49	0.123
12.03	89.58	0.123
12.05	89.66	0.123
12.07	89.74	0.123
12.08	89.83	0.123
12.10	89.91	0.123
12.12	89.99	0.123
12.13	90.08	0.123
12.15	90.16	0.123
12.17	90.24	0.123
12.18	90.33	0.123
12.20	90.41	0.123
12.22	90.49	0.123
12.23	90.58	0.123
12.25	90.66	0.123
12.27	90.74	0.123
12.28	90.83	0.123
12.30	90.91	0.124
12.32	90.99	0.124
12.33	91.08	0.124
12.35	91.16	0.124
12.37	91.24	0.124
12.38	91.33	0.124
12.40	91.41	0.124
12.42	91.49	0.124
12.43	91.58	0.124
12.45	91.66	0.124
12.47	91.74	0.124
12.48	91.83	0.124
12.50	91.91	0.124
12.52	91.99	0.124
12.53	92.08	0.124
12.55	92.16	0.124
12.57	92.24	0.124
12.58	92.33	0.124
12.60	92.41	0.124
12.62	92.49	0.124
12.63	92.58	0.124
12.65	92.66	0.124
12.67	92.74	0.124
12.68	92.83	0.124
12.70	92.91	0.124
12.72	92.99	0.124
12.73	93.08	0.125
12.75	93.16	0.125
12.77	93.24	0.125
12.78	93.33	0.125
12.80	93.41	0.125
12.82	93.49	0.125
12.83	93.58	0.125
12.85	93.66	0.125
12.87	93.74	0.125
12.88	93.83	0.125
12.90	93.91	0.125
12.92	93.99	0.125
12.93	94.08	0.125
12.95	94.16	0.125
12.97	94.24	0.125
12.98	94.33	0.125
13.00	94.41	0.125
13.02	94.49	0.125
13.03	94.58	0.125
13.05	94.66	0.125
13.07	94.74	0.125
13.08	94.83	0.125
13.10	94.91	0.125
13.12	94.99	0.125
13.13	95.08	0.125
13.15	95.16	0.125
13.17	95.24	0.125
13.18	95.33	0.125
13.20	95.41	0.125
13.22	95.49	0.125
13.23	95.58	0.125
13.25	95.66	0.125
13.27	95.75	0.125
13.28	95.83	0.125
13.30	95.91	0.125
13.32	95.99	0.125
13.33	96.08	0.125
13.35	96.16	0.125
13.37	96.24	0.125
13.38	96.33	0.126
13.40	96.41	0.126
13.42	96.50	0.126
13.43	96.58	0.126
13.45	96.66	0.126
13.47	96.74	0.126
13.48	96.83	0.126
13.50	96.91	0.126
13.52	97.00	0.126
13.53	97.08	0.126
13.55	97.16	0.126
13.57	97.25	0.126
13.58	97.33	0.126
13.60	97.41	0.126
13.62	97.50	0.126
13.63	97.58	0.126
13.65	97.66	0.126
13.67	97.75	0.126
13.68	97.83	0.126
13.70	97.91	0.126
13.72	98.00	0.126
13.73	98.08	0.126
13.75	98.16	0.126
13.77	98.25	0.126
13.78	98.33	0.126
13.80	98.41	0.126
13.82	98.50	0.126
13.83	98.58	0.126
13.85	98.66	0.126
13.87	98.75	0.126
13.88	98.83	0.126
13.90	98.91	0.126
13.92	99.00	0.127
13.93	99.08	0.127
13.95	99.16	0.127
13.97	99.25	0.127
13.98	99.33	0.127
14.00	99.41	0.127
14.02	99.50	0.127
14.03	99.58	0.127
14.05	99.66	0.127
14.07	99.75	0.127
14.08	99.83	0.127
14.10	99.91	0.127
14.12	100.00	0.127
14.13	100.08	0.127
14.15	100.16	0.127
14.17	100.25	0.127
14.18	100.33	0.127
14.20	100.41	0.127
14.22	100.50	0.127
14.23	100.58	0.127
14.25	100.66	0.127
14.27	100.75	0.127
14.28	100.83	0.127
14.30	100.91	0.127
14.32	101.00	0.127
14.33	101.08	0.127
14.35	101.16	0.127
14.37	101.25	0.127
14.38	101.33	0.127
14.40	101.41	0.127
14.42	101.50	0.128
14.43	101.58	0.128
14.45	101.66	0.128
14.47	101.75	0.128
14.48	101.83	0.128
14.50	101.91	0.128
14.52	102.00	0.128
14.53	102.08	0.128
14.55	102.16	0.128
14.57	102.25	0.128
14.58	102.33	0.128
14.60	102.41	0.128
14.62	102.50	0.128
14.63	102.58	0.128
14.65	102.66	0.128
14.67	102.75	0.128
14.68	102.83	0.128
14.70	102.91	0.128
14.72	103.00	0.128
14.73	103.08	0.128
14.75	103.16	0.128
14.77	103.25	0.128
14.78	103.33	0.128
14.80	103.42	0.128
14.82	103.50	0.128
14.83	103.58	0.128
14.85	103.67	0.129
14.87	103.75	0.128
14.88	103.83	0.128
14.90	103.91	0.128
14.92	104.00	0.129
14.93	104.08	0.129
14.95	104.16	0.129
14.97	104.25	0.129
14.98	104.33	0.129
15.00	104.41	0.129
15.02	104.50	0.129
15.03	104.58	0.129
15.05	104.66	0.129
15.07	104.75	0.129
15.08	104.83	0.129
15.10	104.92	0.129
15.12	105.00	0.129
15.13	105.08	0.129
15.15	105.16	0.129
15.17	105.25	0.129
15.18	105.33	0.129
15.20	105.42	0.129
15.22	105.50	0.129
15.23	105.58	0.129
15.25	105.67	0.129
15.27	105.75	0.129
15.28	105.83	0.129
15.30	105.92	0.129
15.32	106.00	0.129
15.33	106.08	0.130
15.35	106.17	0.130
15.37	106.25	0.130
15.38	106.33	0.130
15.40	106.42	0.130
15.42	106.50	0.130
15.43	106.58	0.130
15.45	106.67	0.130
15.47	106.75	0.130
15.48	106.83	0.130
15.50	106.92	0.130
15.52	107.00	0.130
15.53	107.08	0.130
15.55	107.17	0.130
15.57	107.25	0.130
15.58	107.33	0.130
15.60	107.42	0.130
15.62	107.50	0.130
15.63	107.58	0.130
15.65	107.67	0.130
15.67	107.75	0.130
15.68	107.83	0.130
15.70	107.92	0.130
15.72	108.00	0.131
15.73	108.08	0.130
15.75	108.17	0.131
15.77	108.25	0.131
15.78	108.33	0.131
15.80	108.42	0.131
15.82	108.50	0.131
15.83	108.58	0.131
15.85	108.67	0.131
15.87	108.75	0.131
15.88	108.83	0.131
15.90	108.92	0.131
15.92	109.00	0.131
15.93	109.08	0.131
15.95	109.17	0.131
15.97	109.25	0.131
15.98	109.33	0.131
16.00	109.42	0.131
16.02	109.50	0.131
16.03	109.58	0.131
16.05	109.67	0.131
16.07	109.75	0.131
16.08	109.83	0.131
16.10	109.92	0.131
16.12	110.00	0.131
16.13	110.08	0.131
16.15	110.17	0.131
16.17	110.25	0.131
16.18	110.33	0.131
16.20	110.42	0.131
16.22	110.50	0.131
16.23	110.58	0.131
16.25	110.67	0.131
16.27	110.75	0.131
16.28	110.83	0.131
16.30	110.92	0.131
16.32	111.00	0.132
16.33	111.08	0.132
16.35	111.17	0.132
16.37	111.25	0.132
16.38	111.33	0.132
16.40	111.42	0.132
16.42	111.50	0.132
16.43	111.58	0.132
16.45	111.67	0.132
16.47	111.75	0.132
16.48	111.83	0.132
16.50	111.92	0.132
16.52	112.00	0.132
16.53	112.08	0.132
16.55	112.17	0.132
16.57	112.25	0.132
16.58	112.33	0.132
16.60	112.42	0.133
16.62	112.50	0.133
16.63	112.58	0.133
16.65	112.67	0.133
16.67	112.75	0.133
16.68	112.83	0.133
16.70	112.92	0.133
16.72	113.00	0.133
16.73	113.08	0.133
16.75	113.17	0.133
16.77	113.25	0.133
16.78	113.33	0.133
16.80	113.42	0.133
16.82	113.50	0.133
16.83	113.59	0.133
16.85	113.67	0.133
16.87	113.75	0.133
16.88	113.83	0.133
16.90	113.92	0.133
16.92	114.00	0.133
16.93	114.08	0.133
16.95	114.17	0.134
16.97	114.25	0.134
16.98	114.33	0.134
17.00	114.42	0.134
17.02	114.50	0.134
17.03	114.59	0.134
17.05	114.67	0.134
17.07	114.75	0.134
17.08	114.83	0.134
17.10	114.92	0.134
17.12	115.00	0.134
17.13	115.09	0.134
17.15	115.17	0.134
17.17	115.25	0.134
17.18	115.34	0.134
17.20	115.42	0.135
17.22	115.50	0.135
17.23	115.59	0.135
17.25	115.67	0.135
17.27	115.75	0.135
17.28	115.83	0.135
17.30	115.92	0.135
17.32	116.00	0.135
17.33	116.09	0.135
17.35	116.17	0.135
17.37	116.25	0.136
17.38	116.34	0.136
17.40	116.42	0.136
17.42	116.50	0.136
17.43	116.59	0.136
17.45	116.67	0.136
17.47	116.75	0.136
17.48	116.84	0.136
17.50	116.92	0.136
17.52	117.00	0.137
17.53	117.08	0.137
17.55	117.17	0.137
17.57	117.25	0.137
17.58	117.34	0.137
17.60	117.42	0.137
17.62	117.50	0.138
17.63	117.58	0.138
17.65	117.67	0.138
17.67	117.75	0.138
17.68	117.84	0.139
17.70	117.92	0.139
17.72	118.00	0.139
17.73	118.09	0.139
17.75	118.17	0.140
17.77	118.25	0.140
17.78	118.34	0.140
17.80	118.42	0.141
17.82	118.50	0.141
17.83	118.59	0.141
17.85	118.67	0.142
17.87	118.75	0.142
17.88	118.83	0.142
17.90	118.92	0.143
17.92	119.00	0.143
17.93	119.08	0.143
17.95	119.17	0.144
17.97	119.25	0.144
17.98	119.33	0.145
18.00	119.42	0.146
18.02	119.50	0.147
18.03	119.58	0.148
18.05	119.67	0.149
18.07	119.75	0.150
18.08	119.83	0.152
18.10	119.92	0.153
18.12	120.00	0.156
18.13	120.08	0.158
18.15	120.17	0.162
18.17	120.25	0.167
18.18	120.33	0.171
18.20	120.41	0.178
18.22	120.50	0.184
18.23	120.58	0.194
18.25	120.66	0.202
18.27	120.74	0.212
18.28	120.82	0.226
18.30	120.91	0.241
18.32	120.99	0.260
18.33	121.07	0.280
18.35	121.15	0.308
18.37	121.23	0.340
18.38	121.30	0.385
18.40	121.38	0.443
18.42	121.46	0.514
18.43	121.53	0.608
18.45	121.60	0.725
18.47	121.67	0.864
18.48	121.73	1.023
18.50	121.79	1.189
18.52	121.85	1.353
18.53	121.90	1.544
18.55	121.95	1.806
18.57	122.00	2.092
18.58	122.04	2.394
18.60	122.08	2.668
18.62	122.11	2.963
18.63	122.15	3.247
18.65	122.18	3.524
18.67	122.21	3.786
18.68	122.25	4.023
18.70	122.29	4.237
18.72	122.32	4.441
18.73	122.37	4.613
18.75	122.41	4.785
18.77	122.46	4.897
18.78	122.52	4.996
18.80	122.57	5.109
18.82	122.63	5.137
18.83	122.70	5.208
18.85	122.77	5.212
18.87	122.84	5.197
18.88	122.92	5.167
18.90	123.00	5.185
18.92	123.08	5.194
18.93	123.16	5.234
18.95	123.24	5.135
18.97	123.33	5.028
18.98	123.42	5.060
19.00	123.51	4.872
19.02	123.62	4.487
19.03	123.75	3.732
19.05	123.93	2.616
19.07	124.12	1.884
19.08	124.32	1.495
19.10	124.49	1.253
19.12	124.64	1.060
19.13	124.79	0.913
19.15	124.92	0.783
19.17	125.05	0.674
19.18	125.17	0.588
19.20	125.28	0.519
19.22	125.39	0.457
19.23	125.49	0.410
19.25	125.59	0.368
19.27	125.69	0.334
19.28	125.78	0.306
19.30	125.87	0.284
19.32	125.96	0.263
19.33	126.05	0.251
19.35	126.14	0.236
19.37	126.23	0.226
19.38	126.32	0.217
19.40	126.40	0.212
19.42	126.49	0.203
19.43	126.57	0.202
19.45	126.66	0.197
19.47	126.74	0.194
19.48	126.83	0.192
19.50	126.91	0.190
19.52	126.99	0.189
19.53	127.08	0.187
19.55	127.16	0.186
19.57	127.25	0.185
19.58	127.33	0.185
19.60	127.41	0.184
19.62	127.50	0.184
19.63	127.58	0.183
19.65	127.66	0.183
19.67	127.75	0.183
19.68	127.83	0.182
19.70	127.92	0.182
19.72	128.00	0.182
19.73	128.08	0.182
19.75	128.17	0.181
19.77	128.25	0.181
19.78	128.33	0.181
19.80	128.42	0.181
19.82	128.50	0.180
19.83	128.58	0.180
19.85	128.67	0.180
19.87	128.75	0.180
19.88	128.83	0.180
19.90	128.92	0.180
19.92	129.00	0.179
19.93	129.08	0.179
19.95	129.17	0.179
19.97	129.25	0.179
19.98	129.33	0.179
20.00	129.42	0.179
20.02	129.50	0.179
20.03	129.58	0.179
20.05	129.67	0.178
20.07	129.75	0.178
20.08	129.83	0.178
20.10	129.92	0.178
20.12	130.00	0.178
20.13	130.08	0.178
20.15	130.17	0.178
20.17	130.25	0.178
20.18	130.33	0.178
20.20	130.42	0.178
20.22	130.50	0.178
20.23	130.58	0.178
20.25	130.67	0.178
20.27	130.75	0.178
20.28	130.83	0.178
20.30	130.92	0.178
20.32	131.00	0.178
20.33	131.08	0.178
20.35	131.17	0.178
20.37	131.25	0.178
20.38	131.33	0.178
20.40	131.42	0.178
20.42	131.50	0.178
20.43	131.58	0.178
20.45	131.67	0.178
20.47	131.75	0.178
20.48	131.83	0.178
20.50	131.92	0.178
20.52	132.00	0.179
20.53	132.08	0.179
20.55	132.17	0.179
20.57	132.25	0.179
20.58	132.33	0.179
20.60	132.42	0.179
20.62	132.50	0.179
20.63	132.58	0.179
20.65	132.67	0.179
20.67	132.75	0.179
20.68	132.83	0.179
20.70	132.92	0.179
20.72	133.00	0.179
20.73	133.08	0.179
20.75	133.17	0.179
20.77	133.25	0.179
20.78	133.33	0.179
20.80	133.42	0.179
20.82	133.50	0.179
20.83	133.58	0.179
20.85	133.67	0.179
20.87	133.75	0.179
20.88	133.83	0.179
20.90	133.92	0.179
20.92	134.00	0.179
20.93	134.08	0.180
20.95	134.17	0.180
20.97	134.25	0.180
20.98	134.34	0.180
21.00	134.42	0.180
21.02	134.50	0.180
21.03	134.58	0.180
21.05	134.67	0.180
21.07	134.75	0.180
21.08	134.83	0.180
21.10	134.92	0.180
21.12	135.00	0.180
21.13	135.08	0.180
21.15	135.17	0.180
21.17	135.25	0.180
21.18	135.33	0.180
21.20	135.42	0.180
21.22	135.50	0.180
21.23	135.58	0.180
21.25	135.67	0.180
21.27	135.75	0.180
21.28	135.84	0.180
21.30	135.92	0.180
21.32	136.00	0.180
21.33	136.08	0.181
21.35	136.17	0.181
21.37	136.25	0.181
21.38	136.33	0.181
21.40	136.42	0.181
21.42	136.50	0.181
21.43	136.59	0.181
21.45	136.67	0.181
21.47	136.75	0.181
21.48	136.83	0.181
21.50	136.92	0.181
21.52	137.00	0.181
21.53	137.08	0.181
21.55	137.17	0.181
21.57	137.25	0.181
21.58	137.33	0.181
21.60	137.42	0.181
21.62	137.50	0.181
21.63	137.58	0.182
21.65	137.67	0.182
21.67	137.75	0.182
21.68	137.84	0.182
21.70	137.92	0.182
21.72	138.00	0.182
21.73	138.09	0.182
21.75	138.17	0.182
21.77	138.25	0.182
21.78	138.33	0.182
21.80	138.42	0.182
21.82	138.50	0.182
21.83	138.58	0.182
21.85	138.67	0.182
21.87	138.75	0.182
21.88	138.83	0.182
21.90	138.92	0.182
21.92	139.00	0.182
21.93	139.09	0.182
21.95	139.17	0.182
21.97	139.25	0.183
21.98	139.33	0.183
22.00	139.42	0.183
22.02	139.50	0.183
22.03	139.58	0.183
22.05	139.67	0.183
22.07	139.75	0.183
22.08	139.84	0.183
22.10	139.92	0.183
22.12	140.00	0.183
22.13	140.09	0.183
22.15	140.17	0.183
22.17	140.25	0.183
22.18	140.34	0.183
22.20	140.42	0.183
22.22	140.50	0.183
22.23	140.58	0.183
22.25	140.67	0.183
22.27	140.75	0.183
22.28	140.84	0.183
22.30	140.92	0.183
22.32	141.00	0.183
22.33	141.09	0.184
22.35	141.17	0.184
22.37	141.25	0.184
22.38	141.34	0.184
22.40	141.42	0.184
22.42	141.50	0.184
22.43	141.59	0.184
22.45	141.67	0.184
22.47	141.75	0.184
22.48	141.84	0.184
22.50	141.92	0.184
22.52	142.00	0.184
22.53	142.09	0.184
22.55	142.17	0.184
22.57	142.25	0.184
22.58	142.34	0.184
22.60	142.42	0.184
22.62	142.50	0.184
22.63	142.59	0.184
22.65	142.67	0.184
22.67	142.75	0.184
22.68	142.84	0.184
22.70	142.92	0.185
22.72	143.00	0.185
22.73	143.08	0.185
22.75	143.17	0.185
22.77	143.25	0.185
22.78	143.34	0.185
22.80	143.42	0.185
22.82	143.50	0.185
22.83	143.59	0.185
22.85	143.67	0.185
22.87	143.75	0.185
22.88	143.84	0.185
22.90	143.92	0.185
22.92	144.00	0.185
22.93	144.09	0.185
22.95	144.17	0.185
22.97	144.25	0.185
22.98	144.34	0.185
23.00	144.42	0.185
23.02	144.50	0.186
23.03	144.59	0.186
23.05	144.67	0.186
23.07	144.75	0.186
23.08	144.84	0.186
23.10	144.92	0.186
23.12	145.00	0.186
23.13	145.09	0.186
23.15	145.17	0.186
23.17	145.25	0.186
23.18	145.34	0.186
23.20	145.42	0.186
23.22	145.50	0.186
23.23	145.59	0.186
23.25	145.67	0.186
23.27	145.75	0.186
23.28	145.84	0.186
23.30	145.92	0.186
23.32	146.00	0.186
23.33	146.09	0.186
23.35	146.17	0.186
23.37	146.25	0.186
23.38	146.34	0.187
23.40	146.42	0.187
23.42	146.50	0.187
23.43	146.59	0.187
23.45	146.67	0.187
23.47	146.75	0.187
23.48	146.84	0.187
23.50	146.92	0.187
23.52	147.00	0.187
23.53	147.09	0.187
23.55	147.17	0.187
23.57	147.25	0.187
23.58	147.34	0.187
23.60	147.42	0.187
23.62	147.50	0.187
23.63	147.59	0.187
23.65	147.67	0.187
23.67	147.75	0.187
23.68	147.84	0.187
23.70	147.92	0.187
23.72	148.00	0.188
23.73	148.09	0.188
23.75	148.17	0.188
23.77	148.25	0.188
23.78	148.34	0.188
23.80	148.42	0.188
23.82	148.50	0.188
23.83	148.59	0.188
23.85	148.67	0.188
23.87	148.75	0.188
23.88	148.84	0.188
23.90	148.92	0.188
23.92	149.00	0.188
23.93	149.09	0.188
23.95	149.17
23.97	149.25
23.98	149.34
24.00