File: DSC/2025_05_01_CBN_AscorbicAcid_MC_n60C_200C_5Cmin_x3.csv
Filename,2025_05_01_CBN_AscorbicAcid_MC_n60C_200C_5Cmin_x3
Instrument name,DSC2A-00468 (192.168.1.100)
Operator,Yarger
rundate,5/1/2025
Sample name,2025_05_01_CBN_AscorbicAcid_MC_n60C_200C_5Cmin_x3
proceduresegments,Data Off ; Equilibrate -60.00 °C; Data On ; Ramp 5.00 °C/min to 200.00 °C; Data Off ; Isothermal 1.0 min; Data On ; Ramp 5.00 °C/min to -60.00 °C; Data Off ; Isothermal 1.0 min; Data On ; Ramp 5.00 °C/min to 200.00 °C; Data Off ; Isothermal 1.0 min; Data On ; Ramp 5.00 °C/min to -60.00 °C; Data Off ; Isothermal 1.0 min; Data On ; Ramp 5.00 °C/min to 200.00 °C
[File Parameters]
Run date,5/1/2025 3:59:33 PM
Trios version,5.1.1.46572
Original File Name,
Current File Name,D:\DSC2500\JYarger\2025_05_01_CBN_AscorbicAcid_MC_n60C_200C_5Cmin_x3.tri
[Procedure]
Procedure Name,CBN_AA_n60C_200C_5Cmin_x3
Sample Name,2025_05_01_CBN_AscorbicAcid_MC_n60C_200C_5Cmin_x3
Sample Mass,5.12 mg
Reference Sample Mass,0 mg
Pan Mass,53.73 mg
Pan Number,18
Reference Pan Mass,53.35 mg
Reference Pan Number,1
Pan Type,Tzero Aluminum Hermetic
Comments,Al Hermetic DSC Consumables sealed Pan/Lid. Y2 Tray (Google Sheet: DSC_Samples_Vext_Y2_Tray_May2025)
Project Name,CA
Operator,Yarger
Test,Custom
Unload Max Temperature,30
Unload Min Temperature,30
Load Max Temperature,30
Load Min Temperature,30
Stop on Gas Flow Error,Yes
[Signal List]
Signal #1,Time (min)
Signal #2,Temperature (°C)
Signal #3,Heat Flow (mW)
Signal #4,Delta T (µV)
Signal #5,Delta Tzero (µV)
Signal #6,Tzero Temperature (°C)
Signal #7,Cell Purge (mL/min)
Signal #8,Heater Temp (°C)
Signal #9,Power Delivered (W)
Signal #10,Reference Junction Temperature (°C)
Signal #11,Flange Temperature (°C)
Signal #12,Heat Flow Phase (rad)
Signal #13,Total Heat Capacity (J/°C)
Signal #14,Heat Capacity (J/°C)
[Configuration]
Company Name,ASU
Instrument Name,DSC2A-00468
Instrument Type,DSC2500
Serial Number,DSC2A-00468
IP,192.168.1.100
Location of Instrument,MRRC
DisplayType,Unknown
Sample Interval ,0.1 s/pt
Selected Heat Flow,T4P
Exotherm Direction,Down
Cell Serial,DRC2-00792
Lid Type,Standard
Cooler,RCS 90
Leave Cooler on at End of Sequence,On
Gas 2,Nitrogen
Gas Selected,Channel 1
Flow Rate,50 mL/min
Secondary Purge,On
Licensed Heat Flow,Heat Flow T4P
Modulation Licensed,Yes
[Versions]
Common IDD Version,1
Cortex Version,VER 2.10.2.31
Driver,5.0.0.6
GDM Version,1.0.3.3
TouchscreenVersion,1.0.0.16145
FEP Version,1.2.1.21
FEP Bootloader,2.0.0.5
AutoSampler Version,2.1.1.26
Auto Sampler Bootloader,2.0.0.5
FCM Version,1.1.0.3
FCM Bootloader,2.0.0.5
[Experiment Logs]
Experiment Log Entry # 1,Data On set to 0
Experiment Log Entry # 3,Equilibrate Segment -60 (C) Started
Experiment Log Entry # 5,Data On set to 1
Experiment Log Entry # 7,Ramp Segment 5 C/min to 200 Started
Experiment Log Entry # 9,Auto sampler has detected that GDM has gone offline
Experiment Log Entry # 11,Data On set to 0
Experiment Log Entry # 13,Isothermal Segment 1 min started
Experiment Log Entry # 15,Data On set to 1
Experiment Log Entry # 17,Ramp Segment 5 C/min to -60 Started
Experiment Log Entry # 19,Data On set to 0
Experiment Log Entry # 21,Isothermal Segment 1 min started
Experiment Log Entry # 23,Data On set to 1
Experiment Log Entry # 25,Ramp Segment 5 C/min to 200 Started
Experiment Log Entry # 27,Data On set to 0
Experiment Log Entry # 29,Isothermal Segment 1 min started
Experiment Log Entry # 31,Data On set to 1
Experiment Log Entry # 33,Ramp Segment 5 C/min to -60 Started
Experiment Log Entry # 35,Data On set to 0
Experiment Log Entry # 37,Isothermal Segment 1 min started
Experiment Log Entry # 39,Data On set to 1
Experiment Log Entry # 41,Ramp Segment 5 C/min to 200 Started
[Method Log]
Method Log Entry # 1,Data Off
Method Log Entry # 2,Equilibrate -60 °C
Method Log Entry # 3,Data On
Method Log Entry # 4,(Ramp 296150) Ramp 5 °C/minute to 200 °C
Method Log Entry # 5,Data Off
Method Log Entry # 6,Isothermal 1 minutes
Method Log Entry # 7,Data On
Method Log Entry # 8,(Ramp 296154) Ramp 5 °C/minute to -60 °C
Method Log Entry # 9,Data Off
Method Log Entry # 10,Isothermal 1 minutes
Method Log Entry # 11,Data On
Method Log Entry # 12,(Ramp 296158) Ramp 5 °C/minute to 200 °C
Method Log Entry # 13,Data Off
Method Log Entry # 14,Isothermal 1 minutes
Method Log Entry # 15,Data On
Method Log Entry # 16,(Ramp 296162) Ramp 5 °C/minute to -60 °C
Method Log Entry # 17,Data Off
Method Log Entry # 18,Isothermal 1 minutes
Method Log Entry # 19,Data On
Method Log Entry # 20,(Ramp 296166) Ramp 5 °C/minute to 200 °C
Cell Serial,DRC2-00792
[T1 Calibration]
Slope,-0.008529666
Offset,9.636258
Initial Temperature,98.23
GUID,f8bfdadc-4977-4fdf-ba6d-0ba9134940c3
[TZero Calibration]
Date Applied,11/29/2022 4:06:13 PM
Description,From -89.059 °C to 396.009 °C at 20.000°C/min
Gas Type,Nitrogen
Pan Type,None
Source Files 1,C:\Users\yargerlab\Desktop\DSC Data\General\TZero_calibration_11_29_22_2nd(2).tri
Source Files 2,C:\Users\yargerlab\Desktop\DSC Data\General\TZero_calibration_11_29_22_2nd(3).tri
Delta T Offset,13.05235
Delta T Slope,-0.007271007
Delta T0 Offset,-13.69128
Delta T0 Slope,0.06063341
[Temperature Calibration]
Date Applied,11/29/2022 7:12:28 PM
Description,From 106.590 °C to 186.590 °C at 10.000°C/min
Gas Type,Nitrogen
Pan Type,Tzero Aluminum Hermetic
Source Files 1,C:\Users\yargerlab\Desktop\DSC Data\General\Indium(6).tri
Measured 1,157.391
Known 1,156.598
[Cell Constant Calibration]
Date Applied,11/29/2022 7:12:29 PM
Description,From 106.590 °C to 186.590 °C at 10.000°C/min
Gas Type,Nitrogen
Pan Type,Tzero Aluminum Hermetic
Source Files 1,C:\Users\yargerlab\Desktop\DSC Data\General\Indium(6).tri
T4P KCell,1.006051
Onset Slope,63.26126 mW/°C
[Direct Cp Calibration]
Date Applied,11/30/2022 11:04:51 AM
Description,From -79.983 °C to 298.409 °C at 10.000°C/min
Gas Type,Nitrogen
Pan Type,Tzero Aluminum Hermetic
Source Files 1,C:\Users\yargerlab\Desktop\DSC Data\General\Sapphire_Heat_Capacity_11_30_22.tri
[Rev Cp Calibration]
Date Applied,11/30/2022 1:58:51 PM
Description,From -79.996 °C to 292.812 °C at 3.000°C/min
Gas Type,Nitrogen
Pan Type,Tzero Aluminum Hermetic
Source Files 1,C:\Users\yargerlab\Desktop\DSC Data\General\Sapphire_MDSC_Calibration_11_30_22.tri
[step]
Ramp 5.00 °C/min to 200.00 °C
Time,Temperature,Heat Flow (Normalized)
min,°C,W/g
0.00,-59.68,-0.073
0.03,-59.70,-0.066
0.07,-59.69,-0.064
0.11,-59.63,-0.078
0.14,-59.53,-0.087
0.18,-59.41,-0.078
0.21,-59.28,-0.048
0.24,-59.15,-0.025
0.28,-59.00,-0.008
0.31,-58.85,0.007
0.35,-58.70,0.015
0.39,-58.54,0.025
0.42,-58.38,0.033
0.45,-58.21,0.039
0.49,-58.05,0.043
0.53,-57.88,0.046
0.56,-57.72,0.049
0.60,-57.55,0.051
0.63,-57.38,0.053
0.67,-57.21,0.054
0.70,-57.04,0.055
0.73,-56.87,0.056
0.77,-56.70,0.057
0.80,-56.53,0.057
0.84,-56.35,0.058
0.88,-56.18,0.059
0.91,-56.01,0.059
0.95,-55.84,0.060
0.98,-55.66,0.060
1.02,-55.49,0.061
1.05,-55.32,0.061
1.08,-55.15,0.062
1.12,-54.97,0.062
1.16,-54.80,0.062
1.19,-54.62,0.063
1.23,-54.45,0.063
1.26,-54.28,0.063
1.29,-54.10,0.063
1.33,-53.93,0.064
1.37,-53.76,0.064
1.40,-53.58,0.064
1.43,-53.41,0.064
1.47,-53.23,0.064
1.51,-53.06,0.064
1.54,-52.88,0.064
1.58,-52.71,0.064
1.61,-52.54,0.064
1.64,-52.36,0.064
1.68,-52.19,0.064
1.72,-52.01,0.064
1.75,-51.84,0.064
1.78,-51.66,0.064
1.82,-51.49,0.064
1.86,-51.31,0.064
1.89,-51.14,0.064
1.93,-50.96,0.064
1.96,-50.79,0.064
1.99,-50.62,0.064
2.03,-50.44,0.064
2.07,-50.27,0.064
2.10,-50.09,0.064
2.14,-49.92,0.064
2.17,-49.74,0.064
2.21,-49.57,0.064
2.24,-49.39,0.064
2.28,-49.22,0.064
2.31,-49.04,0.064
2.34,-48.87,0.064
2.38,-48.69,0.064
2.41,-48.52,0.064
2.45,-48.34,0.064
2.49,-48.17,0.064
2.52,-47.99,0.064
2.56,-47.82,0.064
2.59,-47.64,0.064
2.63,-47.47,0.064
2.66,-47.30,0.064
2.69,-47.12,0.064
2.73,-46.94,0.064
2.76,-46.77,0.064
2.80,-46.60,0.064
2.84,-46.42,0.064
2.87,-46.24,0.064
2.91,-46.07,0.064
2.94,-45.90,0.064
2.98,-45.72,0.064
3.01,-45.55,0.064
3.04,-45.37,0.064
3.08,-45.20,0.064
3.11,-45.02,0.064
3.15,-44.85,0.064
3.19,-44.67,0.064
3.22,-44.50,0.064
3.26,-44.32,0.064
3.29,-44.15,0.064
3.33,-43.97,0.064
3.36,-43.80,0.064
3.39,-43.62,0.064
3.43,-43.45,0.064
3.46,-43.27,0.063
3.50,-43.10,0.063
3.54,-42.92,0.063
3.57,-42.75,0.063
3.61,-42.57,0.063
3.64,-42.39,0.063
3.68,-42.22,0.063
3.71,-42.04,0.063
3.74,-41.87,0.063
3.78,-41.70,0.064
3.81,-41.52,0.064
3.85,-41.35,0.064
3.89,-41.17,0.063
3.92,-40.99,0.063
3.96,-40.82,0.064
3.99,-40.64,0.064
4.03,-40.47,0.064
4.06,-40.30,0.064
4.09,-40.12,0.064
4.13,-39.94,0.064
4.16,-39.77,0.063
4.20,-39.59,0.063
4.24,-39.42,0.063
4.27,-39.24,0.063
4.30,-39.07,0.064
4.34,-38.90,0.064
4.38,-38.72,0.064
4.41,-38.55,0.063
4.45,-38.37,0.063
4.48,-38.20,0.063
4.51,-38.02,0.063
4.55,-37.85,0.063
4.59,-37.67,0.063
4.62,-37.50,0.063
4.65,-37.32,0.063
4.69,-37.14,0.063
4.73,-36.97,0.063
4.76,-36.79,0.063
4.80,-36.62,0.063
4.83,-36.44,0.063
4.86,-36.27,0.063
4.90,-36.09,0.063
4.94,-35.92,0.063
4.97,-35.74,0.063
5.00,-35.57,0.063
5.04,-35.39,0.064
5.08,-35.21,0.064
5.11,-35.04,0.063
5.15,-34.86,0.063
5.18,-34.69,0.063
5.21,-34.51,0.063
5.25,-34.34,0.063
5.29,-34.16,0.063
5.32,-33.99,0.063
5.35,-33.81,0.063
5.39,-33.64,0.063
5.43,-33.46,0.063
5.46,-33.29,0.063
5.50,-33.11,0.063
5.53,-32.94,0.063
5.56,-32.76,0.063
5.60,-32.58,0.063
5.64,-32.41,0.063
5.67,-32.24,0.063
5.70,-32.06,0.063
5.74,-31.88,0.063
5.78,-31.71,0.063
5.81,-31.53,0.063
5.85,-31.36,0.063
5.88,-31.18,0.063
5.91,-31.01,0.063
5.95,-30.83,0.063
5.99,-30.66,0.063
6.02,-30.48,0.063
6.05,-30.31,0.063
6.09,-30.13,0.064
6.13,-29.96,0.064
6.16,-29.78,0.064
6.20,-29.61,0.064
6.23,-29.43,0.064
6.26,-29.25,0.064
6.30,-29.08,0.064
6.34,-28.91,0.064
6.37,-28.73,0.064
6.40,-28.55,0.064
6.44,-28.38,0.064
6.48,-28.21,0.064
6.51,-28.03,0.064
6.55,-27.86,0.064
6.58,-27.68,0.064
6.61,-27.50,0.064
6.65,-27.33,0.064
6.69,-27.15,0.064
6.72,-26.98,0.064
6.75,-26.80,0.064
6.79,-26.63,0.064
6.83,-26.45,0.064
6.86,-26.28,0.064
6.90,-26.10,0.064
6.93,-25.93,0.064
6.96,-25.75,0.064
7.00,-25.58,0.064
7.04,-25.40,0.064
7.07,-25.23,0.064
7.10,-25.05,0.064
7.14,-24.88,0.064
7.18,-24.70,0.064
7.21,-24.53,0.064
7.25,-24.35,0.064
7.28,-24.18,0.064
7.31,-24.00,0.064
7.35,-23.83,0.064
7.39,-23.65,0.064
7.42,-23.48,0.064
7.45,-23.30,0.064
7.49,-23.13,0.064
7.53,-22.95,0.064
7.56,-22.78,0.064
7.60,-22.60,0.064
7.63,-22.42,0.064
7.66,-22.25,0.064
7.70,-22.07,0.064
7.74,-21.90,0.064
7.77,-21.72,0.064
7.80,-21.55,0.064
7.84,-21.37,0.064
7.88,-21.20,0.064
7.91,-21.02,0.064
7.95,-20.85,0.064
7.98,-20.67,0.064
8.01,-20.50,0.064
8.05,-20.32,0.064
8.09,-20.14,0.064
8.12,-19.97,0.064
8.15,-19.79,0.064
8.19,-19.62,0.064
8.23,-19.44,0.064
8.26,-19.27,0.064
8.30,-19.09,0.065
8.33,-18.92,0.065
8.36,-18.74,0.064
8.40,-18.57,0.064
8.44,-18.39,0.064
8.47,-18.22,0.064
8.50,-18.04,0.064
8.54,-17.87,0.064
8.58,-17.70,0.064
8.61,-17.52,0.064
8.65,-17.35,0.064
8.68,-17.17,0.064
8.72,-16.99,0.064
8.75,-16.82,0.064
8.78,-16.64,0.064
8.82,-16.47,0.064
8.85,-16.29,0.064
8.89,-16.12,0.064
8.93,-15.94,0.064
8.96,-15.77,0.064
9.00,-15.59,0.064
9.03,-15.42,0.064
9.07,-15.24,0.064
9.10,-15.07,0.064
9.13,-14.89,0.064
9.17,-14.72,0.064
9.20,-14.54,0.064
9.24,-14.37,0.064
9.28,-14.19,0.064
9.31,-14.02,0.064
9.35,-13.84,0.064
9.38,-13.67,0.064
9.42,-13.49,0.064
9.45,-13.32,0.064
9.48,-13.14,0.064
9.52,-12.97,0.064
9.55,-12.79,0.065
9.59,-12.62,0.065
9.63,-12.44,0.065
9.66,-12.27,0.065
9.70,-12.09,0.065
9.73,-11.92,0.065
9.77,-11.74,0.065
9.80,-11.57,0.065
9.83,-11.39,0.065
9.87,-11.22,0.065
9.90,-11.04,0.065
9.94,-10.87,0.065
9.98,-10.69,0.065
10.01,-10.52,0.065
10.05,-10.34,0.065
10.08,-10.17,0.065
10.12,-9.99,0.065
10.15,-9.82,0.065
10.18,-9.64,0.065
10.22,-9.47,0.065
10.25,-9.29,0.065
10.29,-9.11,0.065
10.33,-8.94,0.065
10.36,-8.77,0.065
10.40,-8.59,0.065
10.43,-8.41,0.065
10.47,-8.24,0.065
10.50,-8.06,0.065
10.53,-7.89,0.065
10.57,-7.71,0.065
10.60,-7.54,0.065
10.64,-7.36,0.065
10.68,-7.19,0.065
10.71,-7.02,0.065
10.75,-6.84,0.065
10.78,-6.66,0.065
10.82,-6.49,0.065
10.85,-6.31,0.065
10.88,-6.14,0.065
10.92,-5.96,0.065
10.95,-5.79,0.065
10.99,-5.61,0.066
11.03,-5.44,0.066
11.06,-5.26,0.066
11.10,-5.09,0.066
11.13,-4.91,0.066
11.17,-4.74,0.066
11.20,-4.56,0.066
11.23,-4.39,0.066
11.27,-4.21,0.066
11.30,-4.04,0.066
11.34,-3.86,0.066
11.38,-3.69,0.066
11.41,-3.51,0.066
11.45,-3.33,0.066
11.48,-3.16,0.066
11.52,-2.98,0.066
11.55,-2.81,0.066
11.58,-2.63,0.066
11.62,-2.46,0.066
11.65,-2.28,0.066
11.69,-2.11,0.066
11.73,-1.93,0.066
11.76,-1.76,0.066
11.80,-1.58,0.066
11.83,-1.41,0.066
11.87,-1.23,0.066
11.90,-1.06,0.066
11.93,-0.88,0.066
11.97,-0.71,0.066
12.00,-0.53,0.066
12.04,-0.36,0.066
12.08,-0.18,0.066
12.11,-0.01,0.066
12.15,0.17,0.066
12.18,0.34,0.066
12.22,0.52,0.067
12.25,0.69,0.066
12.28,0.87,0.066
12.32,1.04,0.066
12.35,1.22,0.067
12.39,1.39,0.067
12.43,1.57,0.067
12.46,1.74,0.067
12.50,1.92,0.067
12.53,2.10,0.067
12.57,2.27,0.067
12.60,2.45,0.067
12.63,2.62,0.067
12.67,2.79,0.067
12.70,2.97,0.067
12.74,3.15,0.067
12.78,3.32,0.067
12.81,3.50,0.067
12.85,3.67,0.067
12.88,3.85,0.067
12.92,4.02,0.067
12.95,4.19,0.067
12.98,4.37,0.067
13.02,4.55,0.067
13.05,4.72,0.067
13.09,4.90,0.067
13.13,5.07,0.067
13.16,5.25,0.067
13.20,5.42,0.067
13.23,5.60,0.067
13.27,5.77,0.067
13.30,5.95,0.067
13.33,6.12,0.067
13.37,6.30,0.067
13.40,6.47,0.068
13.44,6.65,0.067
13.48,6.82,0.068
13.51,7.00,0.068
13.55,7.17,0.068
13.58,7.35,0.068
13.62,7.52,0.068
13.65,7.70,0.068
13.68,7.87,0.068
13.72,8.05,0.068
13.75,8.22,0.068
13.79,8.40,0.068
13.83,8.57,0.068
13.86,8.75,0.068
13.90,8.92,0.068
13.93,9.10,0.068
13.97,9.27,0.068
14.00,9.45,0.068
14.03,9.62,0.068
14.07,9.80,0.068
14.10,9.97,0.068
14.14,10.15,0.068
14.18,10.33,0.068
14.21,10.50,0.068
14.25,10.67,0.068
14.28,10.85,0.068
14.32,11.02,0.068
14.35,11.20,0.068
14.38,11.38,0.068
14.42,11.55,0.068
14.45,11.73,0.068
14.49,11.90,0.069
14.53,12.07,0.069
14.56,12.25,0.069
14.60,12.43,0.069
14.63,12.60,0.069
14.67,12.78,0.069
14.70,12.95,0.069
14.73,13.13,0.069
14.77,13.30,0.069
14.80,13.48,0.069
14.84,13.65,0.069
14.88,13.83,0.069
14.91,14.00,0.069
14.95,14.18,0.069
14.98,14.35,0.069
15.02,14.53,0.069
15.05,14.70,0.069
15.08,14.88,0.069
15.12,15.05,0.069
15.15,15.23,0.069
15.19,15.40,0.069
15.23,15.58,0.069
15.26,15.76,0.069
15.30,15.93,0.069
15.33,16.10,0.069
15.37,16.28,0.069
15.40,16.45,0.069
15.43,16.63,0.069
15.47,16.80,0.069
15.50,16.98,0.069
15.54,17.15,0.069
15.58,17.33,0.069
15.61,17.50,0.069
15.65,17.68,0.069
15.68,17.86,0.069
15.72,18.03,0.070
15.75,18.21,0.070
15.78,18.38,0.070
15.82,18.56,0.070
15.85,18.73,0.070
15.89,18.91,0.070
15.93,19.08,0.070
15.96,19.26,0.070
16.00,19.43,0.070
16.03,19.61,0.070
16.07,19.78,0.070
16.10,19.96,0.070
16.13,20.13,0.070
16.17,20.31,0.070
16.20,20.48,0.070
16.24,20.66,0.070
16.28,20.83,0.071
16.31,21.01,0.071
16.35,21.18,0.071
16.38,21.36,0.071
16.42,21.53,0.071
16.45,21.71,0.071
16.48,21.88,0.071
16.52,22.06,0.071
16.55,22.23,0.071
16.59,22.41,0.071
16.63,22.58,0.071
16.66,22.76,0.071
16.70,22.93,0.071
16.73,23.11,0.071
16.77,23.28,0.071
16.80,23.46,0.071
16.83,23.63,0.071
16.87,23.81,0.071
16.90,23.98,0.071
16.94,24.16,0.071
16.98,24.33,0.071
17.01,24.51,0.071
17.05,24.68,0.071
17.08,24.86,0.071
17.12,25.03,0.071
17.15,25.21,0.071
17.18,25.38,0.072
17.22,25.56,0.072
17.26,25.74,0.072
17.29,25.91,0.072
17.33,26.09,0.072
17.36,26.26,0.072
17.39,26.44,0.072
17.43,26.61,0.072
17.47,26.79,0.072
17.50,26.96,0.072
17.53,27.14,0.072
17.57,27.31,0.072
17.61,27.49,0.072
17.64,27.66,0.072
17.68,27.84,0.072
17.71,28.01,0.072
17.74,28.19,0.072
17.78,28.36,0.072
17.82,28.54,0.073
17.85,28.71,0.073
17.88,28.89,0.073
17.92,29.06,0.073
17.96,29.24,0.073
17.99,29.41,0.073
18.03,29.59,0.073
18.06,29.76,0.073
18.09,29.94,0.073
18.13,30.11,0.073
18.17,30.29,0.073
18.20,30.46,0.073
18.23,30.64,0.073
18.27,30.81,0.073
18.31,30.99,0.073
18.34,31.16,0.073
18.38,31.34,0.073
18.41,31.51,0.073
18.44,31.69,0.073
18.48,31.86,0.073
18.52,32.04,0.074
18.55,32.22,0.074
18.58,32.39,0.074
18.62,32.56,0.074
18.66,32.74,0.074
18.69,32.91,0.074
18.73,33.09,0.074
18.76,33.27,0.074
18.79,33.44,0.074
18.83,33.62,0.074
18.87,33.79,0.074
18.90,33.96,0.074
18.93,34.14,0.074
18.97,34.32,0.074
19.01,34.49,0.074
19.04,34.67,0.074
19.08,34.84,0.074
19.11,35.02,0.074
19.14,35.19,0.074
19.18,35.37,0.074
19.22,35.54,0.075
19.25,35.72,0.075
19.28,35.89,0.075
19.32,36.07,0.075
19.36,36.24,0.075
19.39,36.42,0.075
19.43,36.59,0.075
19.46,36.77,0.075
19.49,36.94,0.075
19.53,37.12,0.075
19.57,37.29,0.075
19.60,37.47,0.075
19.63,37.64,0.075
19.67,37.82,0.075
19.71,37.99,0.075
19.74,38.17,0.075
19.78,38.34,0.075
19.81,38.52,0.075
19.84,38.69,0.076
19.88,38.87,0.076
19.92,39.04,0.076
19.95,39.22,0.076
19.98,39.39,0.076
20.02,39.57,0.076
20.06,39.75,0.076
20.09,39.92,0.076
20.13,40.09,0.076
20.16,40.27,0.076
20.19,40.45,0.076
20.23,40.62,0.076
20.27,40.80,0.076
20.30,40.97,0.076
20.33,41.15,0.076
20.37,41.32,0.076
20.41,41.50,0.076
20.44,41.67,0.077
20.48,41.85,0.077
20.51,42.02,0.077
20.54,42.20,0.077
20.58,42.37,0.077
20.62,42.55,0.077
20.65,42.72,0.077
20.68,42.90,0.077
20.72,43.07,0.077
20.76,43.25,0.077
20.79,43.42,0.077
20.83,43.60,0.077
20.86,43.77,0.077
20.89,43.95,0.077
20.93,44.12,0.077
20.97,44.30,0.077
21.00,44.47,0.077
21.03,44.65,0.077
21.07,44.82,0.077
21.11,45.00,0.077
21.14,45.17,0.077
21.18,45.35,0.077
21.21,45.52,0.077
21.24,45.70,0.077
21.28,45.87,0.078
21.32,46.05,0.078
21.35,46.22,0.078
21.38,46.40,0.078
21.42,46.57,0.078
21.46,46.75,0.078
21.49,46.92,0.078
21.53,47.10,0.078
21.56,47.27,0.078
21.59,47.45,0.078
21.63,47.62,0.078
21.67,47.80,0.078
21.70,47.98,0.078
21.73,48.15,0.078
21.77,48.32,0.078
21.81,48.50,0.078
21.84,48.67,0.078
21.88,48.85,0.079
21.91,49.02,0.079
21.94,49.20,0.079
21.98,49.38,0.079
22.02,49.55,0.079
22.05,49.72,0.079
22.08,49.90,0.079
22.12,50.08,0.079
22.16,50.25,0.079
22.19,50.43,0.079
22.23,50.60,0.079
22.26,50.78,0.079
22.29,50.95,0.079
22.33,51.13,0.079
22.37,51.30,0.080
22.40,51.48,0.080
22.43,51.65,0.080
22.47,51.83,0.080
22.51,52.00,0.080
22.54,52.18,0.080
22.58,52.35,0.080
22.61,52.53,0.080
22.64,52.70,0.080
22.68,52.88,0.080
22.72,53.05,0.080
22.75,53.23,0.080
22.78,53.40,0.080
22.82,53.58,0.080
22.86,53.75,0.080
22.89,53.93,0.080
22.93,54.10,0.080
22.96,54.28,0.080
22.99,54.45,0.080
23.03,54.63,0.081
23.07,54.80,0.081
23.10,54.98,0.081
23.13,55.15,0.081
23.17,55.33,0.081
23.21,55.50,0.081
23.24,55.68,0.081
23.28,55.85,0.081
23.31,56.03,0.081
23.34,56.20,0.081
23.38,56.38,0.081
23.42,56.55,0.081
23.45,56.73,0.082
23.48,56.90,0.082
23.52,57.08,0.082
23.56,57.25,0.082
23.59,57.43,0.082
23.63,57.61,0.082
23.66,57.78,0.082
23.69,57.95,0.082
23.73,58.13,0.082
23.77,58.31,0.082
23.80,58.48,0.082
23.83,58.66,0.082
23.87,58.83,0.083
23.91,59.01,0.083
23.94,59.18,0.083
23.98,59.36,0.083
24.01,59.53,0.083
24.04,59.71,0.083
24.08,59.88,0.083
24.12,60.06,0.083
24.15,60.23,0.084
24.18,60.40,0.084
24.22,60.58,0.084
24.26,60.76,0.084
24.29,60.93,0.084
24.33,61.11,0.084
24.36,61.28,0.084
24.39,61.46,0.084
24.43,61.63,0.085
24.47,61.80,0.085
24.50,61.98,0.085
24.53,62.16,0.085
24.57,62.33,0.085
24.61,62.51,0.085
24.64,62.68,0.086
24.68,62.86,0.086
24.71,63.03,0.086
24.74,63.21,0.086
24.78,63.38,0.087
24.82,63.56,0.087
24.85,63.73,0.087
24.88,63.91,0.087
24.92,64.08,0.088
24.96,64.26,0.088
24.99,64.43,0.088
25.03,64.61,0.088
25.06,64.78,0.089
25.09,64.96,0.089
25.13,65.13,0.089
25.17,65.31,0.090
25.20,65.48,0.090
25.23,65.66,0.091
25.27,65.83,0.091
25.31,66.01,0.091
25.34,66.18,0.092
25.38,66.36,0.092
25.41,66.53,0.093
25.44,66.71,0.093
25.48,66.88,0.094
25.52,67.05,0.095
25.55,67.23,0.095
25.58,67.41,0.096
25.62,67.58,0.097
25.66,67.75,0.097
25.69,67.93,0.098
25.73,68.10,0.099
25.76,68.28,0.100
25.79,68.45,0.102
25.83,68.63,0.103
25.87,68.80,0.104
25.90,68.98,0.105
25.93,69.15,0.107
25.97,69.33,0.109
26.01,69.50,0.111
26.04,69.68,0.113
26.08,69.85,0.115
26.11,70.03,0.119
26.14,70.20,0.123
26.18,70.37,0.126
26.22,70.55,0.130
26.25,70.72,0.135
26.28,70.90,0.139
26.32,71.07,0.145
26.36,71.24,0.151
26.39,71.41,0.157
26.43,71.59,0.163
26.46,71.76,0.171
26.49,71.93,0.179
26.53,72.11,0.189
26.57,72.28,0.199
26.60,72.45,0.211
26.63,72.62,0.224
26.67,72.79,0.240
26.71,72.96,0.255
26.74,73.13,0.273
26.78,73.30,0.294
26.81,73.47,0.315
26.84,73.63,0.341
26.88,73.80,0.370
26.92,73.97,0.402
26.95,74.13,0.439
26.98,74.29,0.483
27.02,74.45,0.533
27.06,74.61,0.595
27.09,74.77,0.668
27.13,74.92,0.759
27.16,75.06,0.866
27.19,75.20,0.958
27.23,75.34,1.038
27.27,75.49,1.090
27.30,75.65,1.126
27.33,75.81,1.171
27.37,75.96,1.229
27.41,76.12,1.254
27.44,76.29,1.215
27.48,76.48,1.092
27.51,76.69,0.913
27.54,76.92,0.707
27.58,77.15,0.521
27.62,77.39,0.390
27.65,77.61,0.309
27.68,77.82,0.252
27.72,78.02,0.213
27.76,78.21,0.182
27.79,78.40,0.160
27.83,78.58,0.143
27.86,78.77,0.133
27.89,78.95,0.124
27.93,79.13,0.118
27.97,79.30,0.114
28.00,79.48,0.112
28.03,79.66,0.109
28.07,79.83,0.108
28.11,80.01,0.106
28.14,80.19,0.105
28.18,80.36,0.105
28.21,80.54,0.104
28.24,80.71,0.103
28.28,80.89,0.103
28.32,81.06,0.102
28.35,81.24,0.102
28.38,81.41,0.102
28.42,81.59,0.101
28.46,81.76,0.101
28.49,81.94,0.101
28.53,82.11,0.101
28.56,82.29,0.101
28.59,82.46,0.100
28.63,82.64,0.100
28.67,82.81,0.100
28.70,82.99,0.100
28.73,83.16,0.100
28.77,83.34,0.100
28.81,83.51,0.100
28.84,83.69,0.100
28.88,83.87,0.100
28.91,84.04,0.100
28.94,84.22,0.100
28.98,84.39,0.100
29.02,84.57,0.100
29.05,84.74,0.100
29.08,84.92,0.100
29.12,85.09,0.100
29.16,85.27,0.100
29.19,85.44,0.100
29.23,85.62,0.100
29.26,85.79,0.100
29.29,85.96,0.100
29.33,86.14,0.100
29.37,86.32,0.100
29.40,86.49,0.100
29.43,86.67,0.100
29.47,86.84,0.100
29.51,87.02,0.100
29.54,87.19,0.100
29.58,87.37,0.100
29.61,87.54,0.100
29.64,87.72,0.100
29.68,87.89,0.100
29.72,88.07,0.100
29.75,88.24,0.100
29.78,88.42,0.100
29.82,88.59,0.100
29.86,88.77,0.100
29.89,88.94,0.100
29.93,89.12,0.100
29.96,89.29,0.100
29.99,89.47,0.100
30.03,89.64,0.100
30.07,89.82,0.100
30.10,89.99,0.100
30.13,90.17,0.100
30.17,90.34,0.100
30.21,90.52,0.100
30.24,90.69,0.100
30.28,90.87,0.100
30.31,91.04,0.100
30.34,91.22,0.101
30.38,91.39,0.101
30.42,91.57,0.101
30.45,91.74,0.101
30.48,91.92,0.101
30.52,92.10,0.101
30.56,92.27,0.101
30.59,92.45,0.101
30.63,92.62,0.101
30.66,92.80,0.101
30.69,92.97,0.101
30.73,93.14,0.101
30.77,93.32,0.101
30.80,93.50,0.101
30.83,93.67,0.101
30.87,93.85,0.101
30.91,94.02,0.101
30.94,94.19,0.101
30.98,94.37,0.101
31.01,94.55,0.101
31.04,94.72,0.101
31.08,94.90,0.101
31.12,95.07,0.101
31.15,95.25,0.101
31.18,95.42,0.101
31.22,95.60,0.101
31.26,95.77,0.101
31.29,95.94,0.101
31.33,96.12,0.101
31.36,96.30,0.101
31.39,96.47,0.102
31.43,96.65,0.102
31.47,96.82,0.102
31.50,97.00,0.102
31.53,97.17,0.102
31.57,97.35,0.102
31.61,97.52,0.102
31.64,97.70,0.102
31.68,97.87,0.102
31.71,98.05,0.102
31.74,98.22,0.102
31.78,98.40,0.102
31.82,98.57,0.102
31.85,98.75,0.102
31.88,98.92,0.102
31.92,99.10,0.102
31.96,99.27,0.102
31.99,99.45,0.102
32.03,99.62,0.102
32.06,99.80,0.102
32.09,99.97,0.102
32.13,100.15,0.102
32.17,100.32,0.102
32.20,100.50,0.102
32.23,100.67,0.102
32.27,100.85,0.102
32.31,101.02,0.102
32.34,101.20,0.102
32.38,101.37,0.102
32.41,101.55,0.102
32.44,101.72,0.102
32.48,101.90,0.102
32.52,102.07,0.102
32.55,102.25,0.103
32.58,102.43,0.103
32.62,102.60,0.103
32.66,102.78,0.103
32.69,102.95,0.103
32.73,103.13,0.103
32.76,103.30,0.103
32.79,103.47,0.103
32.83,103.65,0.103
32.87,103.82,0.103
32.90,104.00,0.103
32.93,104.17,0.103
32.97,104.35,0.103
33.01,104.53,0.103
33.04,104.70,0.103
33.08,104.88,0.103
33.11,105.05,0.103
33.14,105.23,0.103
33.18,105.40,0.103
33.22,105.58,0.103
33.25,105.75,0.103
33.28,105.93,0.103
33.32,106.10,0.103
33.36,106.28,0.103
33.39,106.45,0.103
33.43,106.63,0.103
33.46,106.80,0.103
33.49,106.98,0.103
33.53,107.15,0.103
33.57,107.33,0.103
33.60,107.50,0.103
33.63,107.68,0.103
33.67,107.85,0.103
33.71,108.03,0.103
33.74,108.20,0.103
33.78,108.38,0.103
33.81,108.55,0.103
33.84,108.73,0.103
33.88,108.90,0.104
33.92,109.08,0.103
33.95,109.25,0.103
33.98,109.43,0.103
34.02,109.60,0.103
34.06,109.78,0.103
34.09,109.95,0.104
34.13,110.13,0.104
34.16,110.30,0.104
34.19,110.48,0.104
34.23,110.65,0.104
34.26,110.83,0.104
34.30,111.00,0.104
34.34,111.18,0.104
34.37,111.35,0.104
34.41,111.53,0.104
34.44,111.70,0.104
34.48,111.88,0.104
34.51,112.05,0.104
34.54,112.23,0.104
34.58,112.40,0.104
34.61,112.58,0.104
34.65,112.75,0.104
34.69,112.93,0.104
34.72,113.10,0.104
34.76,113.28,0.104
34.79,113.45,0.104
34.83,113.63,0.104
34.86,113.80,0.104
34.89,113.98,0.104
34.93,114.15,0.104
34.96,114.33,0.105
35.00,114.50,0.105
35.04,114.68,0.105
35.07,114.85,0.105
35.11,115.03,0.105
35.14,115.21,0.105
35.18,115.38,0.105
35.21,115.56,0.105
35.24,115.73,0.105
35.28,115.91,0.105
35.31,116.08,0.105
35.35,116.26,0.105
35.39,116.43,0.105
35.42,116.61,0.105
35.46,116.78,0.105
35.49,116.96,0.105
35.53,117.13,0.105
35.56,117.31,0.105
35.59,117.48,0.105
35.63,117.66,0.105
35.66,117.83,0.105
35.70,118.01,0.105
35.74,118.18,0.105
35.77,118.36,0.105
35.81,118.53,0.105
35.84,118.71,0.105
35.88,118.88,0.105
35.91,119.05,0.105
35.94,119.23,0.105
35.98,119.41,0.105
36.01,119.58,0.105
36.05,119.76,0.105
36.09,119.93,0.105
36.12,120.11,0.105
36.16,120.28,0.105
36.19,120.46,0.106
36.23,120.63,0.106
36.26,120.81,0.105
36.29,120.98,0.105
36.33,121.16,0.106
36.36,121.33,0.106
36.40,121.51,0.106
36.44,121.68,0.106
36.47,121.86,0.106
36.51,122.03,0.106
36.54,122.21,0.106
36.58,122.38,0.106
36.61,122.56,0.106
36.64,122.73,0.106
36.68,122.91,0.106
36.71,123.08,0.106
36.75,123.26,0.106
36.79,123.43,0.106
36.82,123.61,0.106
36.86,123.78,0.106
36.89,123.96,0.106
36.93,124.13,0.106
36.96,124.31,0.106
36.99,124.48,0.106
37.03,124.66,0.106
37.06,124.83,0.106
37.10,125.01,0.106
37.14,125.18,0.106
37.17,125.36,0.106
37.21,125.53,0.106
37.24,125.71,0.106
37.28,125.88,0.106
37.31,126.06,0.106
37.34,126.23,0.107
37.38,126.41,0.107
37.41,126.58,0.106
37.45,126.75,0.106
37.49,126.93,0.106
37.52,127.10,0.106
37.56,127.28,0.106
37.59,127.46,0.106
37.63,127.63,0.106
37.66,127.81,0.107
37.69,127.99,0.107
37.73,128.16,0.107
37.76,128.34,0.107
37.80,128.51,0.107
37.84,128.69,0.108
37.87,128.86,0.108
37.91,129.04,0.108
37.94,129.21,0.108
37.98,129.39,0.108
38.01,129.56,0.108
38.04,129.74,0.107
38.08,129.91,0.107
38.11,130.09,0.107
38.15,130.26,0.107
38.19,130.43,0.107
38.22,130.61,0.107
38.26,130.79,0.107
38.29,130.96,0.107
38.33,131.14,0.107
38.36,131.31,0.107
38.39,131.49,0.107
38.43,131.66,0.107
38.46,131.84,0.108
38.50,132.01,0.108
38.54,132.19,0.108
38.57,132.36,0.108
38.61,132.54,0.108
38.64,132.71,0.108
38.68,132.89,0.108
38.71,133.06,0.108
38.74,133.24,0.108
38.78,133.41,0.108
38.81,133.59,0.108
38.85,133.76,0.108
38.89,133.94,0.108
38.92,134.11,0.108
38.96,134.29,0.108
38.99,134.46,0.108
39.03,134.64,0.108
39.06,134.81,0.108
39.09,134.99,0.108
39.13,135.16,0.108
39.16,135.34,0.108
39.20,135.51,0.108
39.24,135.69,0.108
39.27,135.86,0.108
39.31,136.04,0.108
39.34,136.21,0.108
39.38,136.39,0.108
39.41,136.56,0.108
39.44,136.74,0.108
39.48,136.91,0.108
39.51,137.09,0.108
39.55,137.26,0.108
39.59,137.44,0.108
39.62,137.61,0.108
39.66,137.79,0.108
39.69,137.96,0.108
39.73,138.14,0.108
39.76,138.31,0.108
39.79,138.49,0.108
39.83,138.66,0.108
39.86,138.84,0.108
39.90,139.01,0.108
39.94,139.19,0.108
39.97,139.36,0.109
40.01,139.54,0.109
40.04,139.71,0.109
40.08,139.89,0.109
40.11,140.06,0.109
40.14,140.24,0.109
40.18,140.41,0.109
40.21,140.59,0.109
40.25,140.76,0.109
40.29,140.94,0.109
40.32,141.11,0.109
40.36,141.29,0.109
40.39,141.47,0.109
40.43,141.64,0.109
40.46,141.82,0.109
40.49,141.99,0.109
40.53,142.16,0.109
40.56,142.34,0.109
40.60,142.52,0.109
40.64,142.69,0.109
40.67,142.87,0.109
40.71,143.04,0.109
40.74,143.21,0.109
40.78,143.39,0.109
40.81,143.56,0.109
40.84,143.74,0.109
40.88,143.91,0.109
40.91,144.09,0.109
40.95,144.27,0.109
40.99,144.44,0.109
41.02,144.62,0.109
41.06,144.79,0.109
41.09,144.97,0.109
41.13,145.14,0.109
41.16,145.32,0.109
41.19,145.49,0.109
41.23,145.66,0.109
41.26,145.84,0.109
41.30,146.02,0.109
41.34,146.19,0.109
41.37,146.37,0.109
41.41,146.54,0.109
41.44,146.72,0.109
41.48,146.89,0.109
41.51,147.07,0.110
41.54,147.24,0.110
41.58,147.42,0.110
41.61,147.59,0.110
41.65,147.76,0.110
41.69,147.94,0.110
41.72,148.11,0.110
41.76,148.29,0.110
41.79,148.47,0.110
41.83,148.64,0.110
41.86,148.82,0.110
41.89,148.99,0.110
41.93,149.17,0.110
41.96,149.34,0.110
42.00,149.52,0.110
42.04,149.69,0.110
42.07,149.87,0.110
42.11,150.04,0.110
42.14,150.22,0.110
42.18,150.39,0.110
42.21,150.57,0.110
42.24,150.74,0.110
42.28,150.92,0.110
42.31,151.09,0.110
42.35,151.27,0.110
42.39,151.44,0.110
42.42,151.62,0.110
42.46,151.79,0.110
42.49,151.97,0.110
42.53,152.14,0.110
42.56,152.32,0.110
42.59,152.49,0.110
42.63,152.67,0.110
42.66,152.84,0.110
42.70,153.02,0.110
42.74,153.20,0.110
42.77,153.37,0.110
42.81,153.54,0.110
42.84,153.72,0.110
42.88,153.89,0.110
42.91,154.07,0.110
42.94,154.24,0.110
42.98,154.42,0.110
43.01,154.59,0.110
43.05,154.77,0.110
43.09,154.94,0.110
43.12,155.12,0.110
43.16,155.29,0.110
43.19,155.47,0.110
43.23,155.64,0.110
43.26,155.82,0.110
43.29,155.99,0.110
43.33,156.17,0.110
43.36,156.34,0.110
43.40,156.52,0.110
43.44,156.69,0.110
43.47,156.87,0.110
43.51,157.04,0.110
43.54,157.22,0.110
43.58,157.39,0.110
43.61,157.57,0.110
43.64,157.74,0.110
43.68,157.92,0.110
43.71,158.09,0.110
43.75,158.27,0.110
43.79,158.44,0.110
43.82,158.62,0.110
43.86,158.79,0.110
43.89,158.97,0.110
43.93,159.14,0.110
43.96,159.32,0.110
43.99,159.49,0.110
44.03,159.67,0.110
44.06,159.84,0.111
44.10,160.02,0.111
44.14,160.19,0.111
44.17,160.37,0.111
44.21,160.54,0.111
44.24,160.72,0.110
44.28,160.89,0.110
44.31,161.07,0.110
44.34,161.25,0.110
44.38,161.42,0.111
44.41,161.60,0.111
44.45,161.77,0.111
44.49,161.95,0.111
44.52,162.12,0.111
44.56,162.30,0.111
44.59,162.47,0.111
44.63,162.64,0.111
44.66,162.82,0.111
44.69,162.99,0.111
44.73,163.17,0.111
44.76,163.34,0.111
44.80,163.52,0.111
44.84,163.69,0.111
44.87,163.87,0.111
44.91,164.04,0.111
44.94,164.22,0.111
44.98,164.39,0.111
45.01,164.57,0.111
45.04,164.75,0.111
45.08,164.92,0.111
45.11,165.09,0.111
45.15,165.27,0.111
45.19,165.44,0.111
45.22,165.62,0.111
45.26,165.80,0.111
45.29,165.97,0.111
45.33,166.15,0.111
45.36,166.32,0.111
45.39,166.50,0.111
45.43,166.67,0.111
45.46,166.85,0.111
45.50,167.02,0.112
45.54,167.20,0.112
45.57,167.37,0.112
45.61,167.55,0.112
45.64,167.72,0.112
45.68,167.90,0.112
45.71,168.07,0.112
45.74,168.25,0.112
45.78,168.42,0.112
45.81,168.60,0.112
45.85,168.77,0.112
45.89,168.95,0.112
45.92,169.12,0.112
45.96,169.30,0.112
45.99,169.47,0.112
46.03,169.65,0.112
46.06,169.82,0.112
46.09,170.00,0.112
46.13,170.17,0.112
46.16,170.35,0.112
46.20,170.52,0.112
46.24,170.70,0.112
46.27,170.87,0.112
46.31,171.05,0.112
46.34,171.22,0.112
46.38,171.40,0.112
46.41,171.57,0.112
46.44,171.75,0.112
46.48,171.92,0.112
46.51,172.10,0.112
46.55,172.27,0.112
46.59,172.45,0.112
46.62,172.62,0.112
46.66,172.80,0.112
46.69,172.97,0.112
46.73,173.15,0.112
46.76,173.32,0.112
46.79,173.50,0.112
46.83,173.67,0.112
46.86,173.85,0.112
46.90,174.02,0.112
46.94,174.20,0.112
46.97,174.37,0.113
47.01,174.55,0.113
47.04,174.72,0.113
47.08,174.90,0.112
47.11,175.07,0.112
47.14,175.25,0.112
47.18,175.42,0.113
47.21,175.60,0.113
47.25,175.77,0.113
47.29,175.95,0.113
47.32,176.12,0.113
47.36,176.30,0.113
47.39,176.47,0.113
47.43,176.65,0.113
47.46,176.82,0.113
47.49,177.00,0.113
47.53,177.17,0.113
47.56,177.35,0.113
47.60,177.52,0.113
47.64,177.70,0.113
47.67,177.87,0.113
47.71,178.05,0.113
47.74,178.22,0.113
47.78,178.40,0.113
47.81,178.57,0.113
47.84,178.75,0.113
47.88,178.92,0.113
47.91,179.10,0.113
47.95,179.27,0.113
47.99,179.45,0.114
48.02,179.62,0.114
48.06,179.80,0.114
48.09,179.97,0.114
48.13,180.15,0.114
48.16,180.32,0.114
48.19,180.50,0.114
48.23,180.67,0.114
48.26,180.85,0.114
48.30,181.03,0.114
48.34,181.20,0.114
48.37,181.37,0.115
48.41,181.55,0.115
48.44,181.72,0.115
48.48,181.90,0.115
48.51,182.07,0.115
48.54,182.25,0.115
48.58,182.42,0.115
48.61,182.60,0.115
48.65,182.77,0.115
48.69,182.95,0.115
48.72,183.12,0.116
48.76,183.30,0.116
48.79,183.47,0.116
48.83,183.65,0.116
48.86,183.82,0.116
48.89,184.00,0.117
48.93,184.17,0.117
48.96,184.35,0.117
49.00,184.52,0.117
49.04,184.70,0.118
49.07,184.87,0.118
49.11,185.05,0.118
49.14,185.22,0.119
49.18,185.40,0.119
49.21,185.57,0.120
49.24,185.75,0.120
49.28,185.92,0.121
49.31,186.10,0.121
49.35,186.27,0.122
49.39,186.45,0.122
49.42,186.62,0.123
49.46,186.80,0.124
49.49,186.97,0.125
49.53,187.15,0.126
49.56,187.32,0.128
49.59,187.50,0.129
49.63,187.67,0.131
49.66,187.84,0.135
49.70,188.02,0.139
49.74,188.19,0.142
49.77,188.36,0.146
49.81,188.54,0.149
49.84,188.71,0.155
49.88,188.88,0.163
49.91,189.06,0.170
49.94,189.23,0.176
49.98,189.41,0.186
50.01,189.58,0.198
50.05,189.75,0.211
50.09,189.92,0.224
50.12,190.09,0.243
50.16,190.26,0.266
50.19,190.43,0.293
50.23,190.60,0.329
50.26,190.76,0.372
50.29,190.92,0.428
50.33,191.08,0.497
50.36,191.24,0.587
50.40,191.39,0.696
50.44,191.53,0.828
50.47,191.67,0.986
50.51,191.80,1.171
50.54,191.92,1.380
50.58,192.03,1.622
50.61,192.14,1.891
50.64,192.24,2.184
50.68,192.33,2.490
50.71,192.42,2.786
50.75,192.51,3.046
50.79,192.61,3.272
50.82,192.72,3.425
50.86,192.85,3.459
50.89,193.02,3.332
50.93,193.23,2.999
50.96,193.50,2.369
50.99,193.84,1.493
51.03,194.21,0.985
51.06,194.52,0.704
51.10,194.80,0.511
51.14,195.05,0.371
51.17,195.28,0.268
51.21,195.49,0.195
51.24,195.69,0.140
51.28,195.88,0.099
51.31,196.07,0.068
51.34,196.26,0.042
51.38,196.44,0.023
51.41,196.63,0.006
51.45,196.81,-0.008
51.49,196.99,-0.019
51.52,197.16,-0.030
51.56,197.34,-0.040
51.59,197.52,-0.051
51.63,197.70,-0.063
51.66,197.88,-0.078
51.69,198.06,-0.089
51.73,198.24,-0.099
51.76,198.41,-0.107
51.80,198.59,-0.109
51.84,198.77,-0.107
51.87,198.94,-0.097
51.91,199.12,-0.100
51.94,199.29,
51.98,199.47,
51.99,,

[step]
Ramp 5.00 °C/min to -60.00 °C
Time,Temperature,Heat Flow (Normalized)
min,°C,W/g
52.99,200.19,-0.307
53.02,200.19,-0.318
53.06,200.18,-0.324
53.09,200.13,-0.302
53.13,200.04,-0.303
53.16,199.92,-0.348
53.20,199.78,-0.387
53.23,199.64,-0.418
53.27,199.48,-0.443
53.30,199.32,-0.458
53.34,199.16,-0.448
53.37,199.00,-0.463
53.41,198.83,-0.468
53.44,198.66,-0.465
53.48,198.49,-0.464
53.51,198.31,-0.466
53.55,198.14,-0.483
53.58,197.97,-0.460
53.62,197.80,-0.462
53.65,197.62,-0.461
53.69,197.45,-0.469
53.72,197.28,-0.469
53.76,197.10,-0.468
53.79,196.93,-0.469
53.83,196.76,-0.468
53.86,196.58,-0.462
53.90,196.41,-0.467
53.93,196.24,-0.469
53.97,196.06,-0.458
54.00,195.89,-0.457
54.04,195.71,-0.456
54.07,195.54,-0.450
54.11,195.36,-0.453
54.14,195.19,-0.450
54.18,195.01,-0.450
54.21,194.84,-0.448
54.25,194.66,-0.437
54.28,194.49,-0.438
54.32,194.31,-0.438
54.35,194.14,-0.434
54.39,193.96,-0.428
54.42,193.79,-0.425
54.46,193.61,-0.422
54.49,193.44,-0.421
54.53,193.26,-0.420
54.56,193.09,-0.414
54.60,192.91,-0.406
54.63,192.73,-0.408
54.67,192.56,-0.401
54.70,192.38,-0.399
54.74,192.21,-0.389
54.77,192.03,-0.386
54.81,191.86,-0.387
54.84,191.68,-0.386
54.88,191.51,-0.386
54.91,191.33,-0.381
54.95,191.15,-0.368
54.98,190.98,-0.370
55.02,190.80,-0.370
55.05,190.63,-0.369
55.09,190.45,-0.358
55.12,190.28,-0.356
55.16,190.10,-0.354
55.19,189.92,-0.353
55.23,189.75,-0.351
55.26,189.57,-0.344
55.30,189.40,-0.345
55.33,189.22,-0.345
55.37,189.05,-0.343
55.40,188.87,-0.335
55.44,188.69,-0.335
55.47,188.52,-0.333
55.51,188.34,-0.331
55.54,188.17,-0.331
55.58,187.99,-0.329
55.61,187.82,-0.323
55.65,187.64,-0.322
55.68,187.47,-0.322
55.72,187.29,-0.318
55.75,187.11,-0.314
55.79,186.94,-0.304
55.82,186.76,-0.273
55.86,186.58,-0.233
55.89,186.40,-0.188
55.93,186.21,-0.151
55.96,186.03,-0.112
56.00,185.84,-0.086
56.03,185.66,-0.067
56.07,185.47,-0.051
56.10,185.29,-0.032
56.14,185.11,-0.014
56.17,184.93,-0.006
56.21,184.75,0.005
56.24,184.57,0.016
56.28,184.39,0.030
56.31,184.21,0.037
56.35,184.04,0.050
56.38,183.86,0.060
56.42,183.68,0.067
56.45,183.51,0.054
56.49,183.33,0.093
56.52,183.15,0.077
56.56,182.97,0.076
56.59,182.80,0.080
56.63,182.62,0.093
56.66,182.45,0.075
56.70,182.28,0.052
56.73,182.10,0.078
56.77,181.92,0.143
56.80,181.74,0.107
56.84,181.57,0.134
56.87,181.39,0.073
56.91,181.22,0.032
56.94,181.05,0.051
56.98,180.88,0.099
57.01,180.70,0.089
57.05,180.52,0.072
57.08,180.35,0.118
57.12,180.17,0.083
57.15,180.00,0.044
57.19,179.83,0.058
57.22,179.66,0.030
57.26,179.48,0.040
57.29,179.31,0.025
57.33,179.14,0.027
57.36,178.96,0.023
57.40,178.79,0.020
57.43,178.61,0.036
57.47,178.44,0.016
57.50,178.27,0.008
57.54,178.09,0.047
57.57,177.92,0.031
57.61,177.74,0.005
57.64,177.57,-0.003
57.68,177.40,-0.001
57.71,177.22,-0.017
57.75,177.05,-0.029
57.78,176.88,-0.027
57.82,176.71,-0.016
57.85,176.53,-0.006
57.89,176.35,0.002
57.92,176.18,-0.008
57.96,176.00,-0.033
57.99,175.83,-0.029
58.03,175.66,-0.021
58.06,175.48,-0.016
58.10,175.31,-0.028
58.13,175.13,-0.031
58.17,174.96,-0.031
58.20,174.79,-0.031
58.24,174.61,-0.026
58.27,174.44,-0.025
58.31,174.26,-0.038
58.34,174.09,-0.044
58.38,173.92,-0.045
58.41,173.74,-0.047
58.45,173.57,-0.055
58.48,173.40,-0.056
58.52,173.22,-0.041
58.55,173.04,-0.010
58.59,172.86,-0.047
58.62,172.69,-0.061
58.66,172.52,-0.061
58.69,172.35,-0.063
58.73,172.17,-0.064
58.76,172.00,-0.064
58.80,171.82,-0.066
58.83,171.65,-0.062
58.87,171.47,-0.063
58.90,171.30,-0.057
58.94,171.12,-0.056
58.97,170.95,-0.060
59.01,170.77,-0.078
59.04,170.60,-0.078
59.08,170.43,-0.079
59.11,170.25,-0.080
59.15,170.08,-0.080
59.18,169.90,-0.082
59.22,169.73,-0.082
59.25,169.55,-0.082
59.29,169.38,-0.082
59.32,169.20,-0.082
59.36,169.03,-0.082
59.39,168.85,-0.082
59.43,168.68,-0.082
59.46,168.50,-0.082
59.50,168.33,-0.079
59.53,168.16,-0.079
59.57,167.98,-0.079
59.60,167.81,-0.079
59.64,167.63,-0.078
59.67,167.46,-0.078
59.71,167.28,-0.077
59.74,167.11,-0.078
59.78,166.93,-0.078
59.81,166.76,-0.078
59.85,166.58,-0.078
59.88,166.41,-0.078
59.92,166.23,-0.079
59.95,166.06,-0.081
59.99,165.88,-0.083
60.02,165.71,-0.084
60.06,165.53,-0.084
60.09,165.36,-0.084
60.13,165.19,-0.084
60.16,165.01,-0.084
60.20,164.84,-0.084
60.23,164.66,-0.084
60.27,164.49,-0.084
60.30,164.31,-0.085
60.34,164.14,-0.085
60.37,163.96,-0.086
60.41,163.79,-0.086
60.44,163.61,-0.087
60.48,163.44,-0.087
60.51,163.26,-0.087
60.55,163.09,-0.087
60.58,162.91,-0.087
60.62,162.74,-0.087
60.65,162.56,-0.088
60.69,162.39,-0.087
60.72,162.21,-0.088
60.76,162.04,-0.088
60.79,161.86,-0.089
60.83,161.69,-0.089
60.86,161.52,-0.089
60.90,161.34,-0.088
60.93,161.17,-0.088
60.97,160.99,-0.089
61.00,160.81,-0.089
61.04,160.64,-0.089
61.07,160.47,-0.089
61.11,160.29,-0.089
61.14,160.12,-0.089
61.18,159.94,-0.090
61.21,159.77,-0.090
61.25,159.59,-0.091
61.28,159.42,-0.090
61.32,159.24,-0.090
61.35,159.06,-0.090
61.39,158.89,-0.091
61.42,158.72,-0.091
61.46,158.54,-0.091
61.49,158.37,-0.091
61.53,158.19,-0.092
61.56,158.02,-0.092
61.60,157.84,-0.092
61.63,157.67,-0.092
61.67,157.49,-0.092
61.70,157.32,-0.092
61.74,157.14,-0.092
61.77,156.97,-0.092
61.81,156.79,-0.092
61.84,156.62,-0.092
61.88,156.45,-0.092
61.91,156.27,-0.091
61.95,156.09,-0.091
61.98,155.92,-0.091
62.02,155.74,-0.092
62.05,155.57,-0.092
62.09,155.39,-0.092
62.12,155.22,-0.092
62.16,155.04,-0.093
62.19,154.87,-0.094
62.23,154.69,-0.093
62.26,154.52,-0.093
62.30,154.34,-0.093
62.33,154.17,-0.093
62.37,153.99,-0.093
62.40,153.82,-0.093
62.44,153.64,-0.093
62.47,153.47,-0.094
62.51,153.30,-0.095
62.54,153.12,-0.095
62.58,152.95,-0.095
62.61,152.77,-0.095
62.65,152.60,-0.096
62.68,152.42,-0.095
62.72,152.25,-0.095
62.75,152.07,-0.095
62.79,151.89,-0.097
62.82,151.72,-0.097
62.86,151.55,-0.097
62.89,151.37,-0.097
62.93,151.19,-0.097
62.96,151.02,-0.097
63.00,150.85,-0.097
63.03,150.67,-0.098
63.07,150.50,-0.098
63.10,150.32,-0.097
63.14,150.15,-0.097
63.17,149.97,-0.097
63.21,149.80,-0.097
63.24,149.62,-0.097
63.28,149.45,-0.097
63.31,149.27,-0.097
63.35,149.10,-0.097
63.38,148.92,-0.097
63.42,148.75,-0.097
63.45,148.57,-0.097
63.49,148.40,-0.097
63.52,148.22,-0.097
63.56,148.05,-0.097
63.59,147.87,-0.098
63.63,147.70,-0.097
63.66,147.52,-0.097
63.70,147.35,-0.097
63.73,147.17,-0.096
63.77,147.00,-0.096
63.80,146.82,-0.096
63.84,146.65,-0.097
63.87,146.47,-0.097
63.91,146.30,-0.097
63.94,146.13,-0.097
63.98,145.95,-0.097
64.01,145.77,-0.096
64.05,145.60,-0.096
64.08,145.43,-0.096
64.12,145.25,-0.096
64.15,145.08,-0.096
64.19,144.90,-0.096
[...]
228.23,20.55,0.017
228.26,20.72,0.017
228.30,20.90,0.017
228.33,21.07,0.017
228.37,21.25,0.017
228.40,21.42,0.018
228.44,21.60,0.018
228.47,21.77,0.018
228.51,21.95,0.017
228.54,22.12,0.017
228.58,22.30,0.017
228.61,22.47,0.017
228.65,22.65,0.018
228.68,22.82,0.018
228.72,23.00,0.018
228.75,23.17,0.018
228.79,23.35,0.018
228.82,23.52,0.018
228.86,23.70,0.018
228.89,23.88,0.018
228.93,24.05,0.018
228.96,24.23,0.018
229.00,24.40,0.018
229.03,24.58,0.018
229.07,24.75,0.018
229.10,24.93,0.018
229.14,25.10,0.018
229.17,25.28,0.018
229.21,25.45,0.018
229.24,25.63,0.018
229.28,25.80,0.018
229.31,25.98,0.018
229.35,26.15,0.019
229.38,26.33,0.019
229.42,26.50,0.019
229.45,26.68,0.019
229.49,26.85,0.019
229.52,27.03,0.019
229.56,27.20,0.019
229.59,27.38,0.019
229.63,27.55,0.019
229.66,27.73,0.019
229.70,27.90,0.019
229.73,28.08,0.019
229.77,28.25,0.019
229.80,28.43,0.019
229.84,28.60,0.019
229.87,28.78,0.019
229.91,28.95,0.019
229.94,29.13,0.019
229.98,29.30,0.019
230.01,29.48,0.019
230.05,29.65,0.019
230.08,29.83,0.019
230.12,30.00,0.020
230.15,30.18,0.020
230.19,30.35,0.020
230.22,30.53,0.020
230.26,30.71,0.020
230.29,30.88,0.020
230.33,31.05,0.020
230.36,31.23,0.020
230.40,31.40,0.020
230.43,31.58,0.020
230.47,31.76,0.020
230.50,31.93,0.020
230.54,32.11,0.020
230.57,32.28,0.020
230.61,32.45,0.020
230.64,32.63,0.020
230.68,32.81,0.020
230.71,32.98,0.020
230.75,33.16,0.020
230.78,33.33,0.020
230.82,33.51,0.020
230.85,33.68,0.020
230.89,33.86,0.020
230.92,34.03,0.020
230.96,34.21,0.021
230.99,34.38,0.021
231.03,34.56,0.021
231.06,34.73,0.021
231.10,34.91,0.021
231.13,35.08,0.021
231.17,35.26,0.021
231.20,35.43,0.021
231.24,35.61,0.021
231.27,35.78,0.021
231.31,35.96,0.021
231.34,36.13,0.021
231.38,36.31,0.021
231.41,36.48,0.021
231.45,36.66,0.021
231.48,36.83,0.021
231.52,37.01,0.021
231.55,37.18,0.021
231.59,37.36,0.021
231.62,37.53,0.021
231.66,37.71,0.022
231.69,37.88,0.021
231.73,38.06,0.021
231.76,38.23,0.021
231.80,38.41,0.022
231.83,38.58,0.022
231.87,38.76,0.022
231.90,38.93,0.022
231.94,39.11,0.022
231.97,39.28,0.022
232.01,39.46,0.022
232.04,39.63,0.022
232.08,39.81,0.022
232.11,39.98,0.022
232.15,40.16,0.022
232.18,40.34,0.022
232.22,40.51,0.022
232.25,40.69,0.022
232.29,40.86,0.022
232.32,41.04,0.023
232.36,41.21,0.023
232.39,41.39,0.023
232.43,41.56,0.023
232.46,41.74,0.022
232.50,41.91,0.023
232.53,42.09,0.023
232.57,42.26,0.023
232.60,42.44,0.023
232.64,42.61,0.023
232.67,42.79,0.023
232.71,42.96,0.023
232.74,43.14,0.023
232.78,43.31,0.023
232.81,43.49,0.023
232.85,43.66,0.023
232.88,43.84,0.023
232.92,44.01,0.023
232.95,44.19,0.023
232.99,44.36,0.023
233.02,44.54,0.023
233.06,44.71,0.024
233.09,44.89,0.024
233.13,45.06,0.024
233.16,45.24,0.024
233.20,45.41,0.024
233.23,45.59,0.024
233.27,45.76,0.024
233.30,45.94,0.024
233.34,46.11,0.024
233.37,46.29,0.024
233.41,46.46,0.024
233.44,46.64,0.024
233.48,46.81,0.024
233.51,46.99,0.024
233.55,47.16,0.024
233.58,47.34,0.024
233.62,47.51,0.024
233.65,47.69,0.024
233.69,47.87,0.024
233.72,48.04,0.024
233.76,48.22,0.025
233.79,48.39,0.025
233.83,48.57,0.025
233.86,48.74,0.025
233.90,48.91,0.025
233.93,49.09,0.025
233.97,49.27,0.024
234.00,49.44,0.025
234.04,49.62,0.025
234.07,49.79,0.025
234.11,49.97,0.025
234.14,50.14,0.025
234.18,50.32,0.025
234.21,50.49,0.025
234.25,50.67,0.025
234.28,50.84,0.025
234.32,51.02,0.025
234.35,51.19,0.025
234.39,51.37,0.025
234.42,51.54,0.025
234.46,51.72,0.025
234.49,51.89,0.026
234.53,52.07,0.026
234.56,52.24,0.026
234.60,52.42,0.026
234.63,52.59,0.026
234.67,52.77,0.026
234.70,52.94,0.026
234.74,53.12,0.026
234.77,53.29,0.026
234.81,53.47,0.026
234.84,53.64,0.026
234.88,53.82,0.026
234.91,53.99,0.026
234.95,54.17,0.026
234.98,54.34,0.026
235.02,54.52,0.026
235.05,54.69,0.026
235.09,54.87,0.026
235.12,55.04,0.026
235.16,55.22,0.026
235.19,55.40,0.026
235.23,55.57,0.026
235.26,55.74,0.027
235.30,55.92,0.027
235.33,56.09,0.027
235.37,56.27,0.027
235.40,56.44,0.027
235.44,56.62,0.027
235.47,56.80,0.027
235.51,56.97,0.027
235.54,57.14,0.027
235.58,57.32,0.027
235.61,57.50,0.027
235.65,57.67,0.027
235.68,57.85,0.027
235.72,58.02,0.027
235.75,58.20,0.027
235.79,58.37,0.027
235.82,58.55,0.027
235.86,58.72,0.027
235.89,58.90,0.027
235.93,59.07,0.028
235.96,59.25,0.028
236.00,59.42,0.028
236.03,59.60,0.028
236.07,59.77,0.028
236.10,59.95,0.028
236.14,60.12,0.028
236.17,60.30,0.028
236.21,60.47,0.028
236.24,60.65,0.028
236.28,60.82,0.028
236.31,61.00,0.028
236.35,61.17,0.028
236.38,61.35,0.028
236.42,61.52,0.028
236.45,61.70,0.028
236.49,61.87,0.028
236.52,62.05,0.028
236.56,62.22,0.028
236.59,62.40,0.028
236.63,62.57,0.028
236.66,62.75,0.029
236.70,62.92,0.029
236.73,63.10,0.029
236.77,63.27,0.029
236.80,63.45,0.029
236.84,63.62,0.029
236.87,63.80,0.029
236.91,63.97,0.029
236.94,64.15,0.029
236.98,64.32,0.029
237.01,64.50,0.029
237.05,64.67,0.029
237.08,64.85,0.029
237.12,65.03,0.029
237.15,65.20,0.029
237.19,65.37,0.030
237.22,65.55,0.030
237.26,65.72,0.030
237.29,65.90,0.030
237.33,66.07,0.030
237.36,66.25,0.029
237.40,66.43,0.029
237.43,66.60,0.030
237.47,66.78,0.030
237.50,66.95,0.030
237.54,67.13,0.030
237.57,67.30,0.030
237.61,67.48,0.030
237.64,67.65,0.030
237.68,67.83,0.030
237.71,68.00,0.030
237.75,68.18,0.031
237.78,68.35,0.030
237.82,68.53,0.030
237.85,68.70,0.030
237.89,68.88,0.031
237.92,69.05,0.031
237.96,69.23,0.031
237.99,69.40,0.031
238.03,69.58,0.031
238.06,69.75,0.031
238.10,69.93,0.031
238.13,70.10,0.031
238.17,70.28,0.031
238.20,70.45,0.031
238.24,70.63,0.031
238.27,70.80,0.032
238.31,70.98,0.031
238.34,71.15,0.031
238.38,71.33,0.032
238.41,71.50,0.032
238.45,71.68,0.032
238.48,71.85,0.032
238.52,72.03,0.032
238.55,72.20,0.032
238.59,72.38,0.032
238.62,72.55,0.032
238.66,72.73,0.032
238.69,72.90,0.032
238.73,73.08,0.032
238.76,73.25,0.032
238.80,73.43,0.032
238.83,73.60,0.032
238.87,73.78,0.032
238.90,73.95,0.033
238.94,74.13,0.033
238.97,74.30,0.033
239.01,74.48,0.033
239.04,74.65,0.033
239.08,74.83,0.033
239.11,75.00,0.033
239.15,75.18,0.033
239.18,75.35,0.033
239.22,75.53,0.033
239.25,75.71,0.033
239.29,75.88,0.033
239.32,76.06,0.033
239.36,76.23,0.033
239.39,76.41,0.033
239.43,76.58,0.033
239.46,76.76,0.033
239.50,76.93,0.033
239.53,77.11,0.034
239.57,77.28,0.034
239.60,77.46,0.034
239.64,77.63,0.034
239.67,77.81,0.034
239.71,77.98,0.034
239.74,78.16,0.034
239.78,78.33,0.034
239.81,78.51,0.034
239.85,78.68,0.034
239.88,78.85,0.034
239.92,79.03,0.034
239.95,79.21,0.034
239.99,79.38,0.034
240.02,79.56,0.035
240.06,79.73,0.034
240.09,79.91,0.034
240.13,80.08,0.034
240.16,80.26,0.035
240.20,80.43,0.034
240.23,80.61,0.034
240.27,80.78,0.035
240.30,80.96,0.035
240.34,81.13,0.035
240.37,81.31,0.035
240.41,81.48,0.035
240.44,81.66,0.035
240.48,81.83,0.035
240.51,82.01,0.035
240.55,82.18,0.035
240.58,82.36,0.035
240.62,82.53,0.035
240.65,82.71,0.035
240.69,82.88,0.035
240.72,83.06,0.036
240.76,83.23,0.036
240.79,83.41,0.036
240.83,83.58,0.036
240.86,83.76,0.036
240.90,83.93,0.036
240.93,84.11,0.036
240.97,84.28,0.036
241.00,84.46,0.036
241.04,84.63,0.036
241.07,84.81,0.036
241.11,84.98,0.036
241.14,85.16,0.036
241.18,85.33,0.036
241.21,85.51,0.036
241.25,85.68,0.036
241.28,85.86,0.037
241.32,86.03,0.037
241.35,86.21,0.037
241.39,86.38,0.037
241.42,86.56,0.037
241.46,86.73,0.037
241.49,86.91,0.037
241.53,87.08,0.037
241.56,87.26,0.037
241.60,87.43,0.037
241.63,87.61,0.037
241.67,87.78,0.037
241.70,87.96,0.037
241.74,88.13,0.037
241.77,88.31,0.037
241.81,88.48,0.037
241.84,88.66,0.037
241.88,88.84,0.037
241.91,89.01,0.038
241.95,89.18,0.038
241.98,89.36,0.037
242.02,89.54,0.037
242.05,89.71,0.038
242.09,89.89,0.038
242.12,90.06,0.038
242.16,90.24,0.038
242.19,90.41,0.038
242.23,90.59,0.038
242.26,90.76,0.038
242.30,90.94,0.038
242.33,91.11,0.039
242.37,91.29,0.039
242.40,91.46,0.039
242.44,91.64,0.039
242.47,91.81,0.039
242.51,91.99,0.039
242.54,92.16,0.039
242.58,92.34,0.039
242.61,92.51,0.039
242.65,92.69,0.039
242.68,92.86,0.039
242.72,93.04,0.039
242.75,93.21,0.039
242.79,93.39,0.039
242.82,93.56,0.040
242.86,93.74,0.040
242.89,93.91,0.040
242.93,94.09,0.040
242.96,94.26,0.040
243.00,94.44,0.040
243.03,94.61,0.040
243.07,94.79,0.040
243.10,94.96,0.040
243.14,95.14,0.040
243.17,95.31,0.040
243.21,95.49,0.040
243.24,95.66,0.040
243.28,95.84,0.040
243.31,96.01,0.041
243.35,96.19,0.041
243.38,96.36,0.041
243.42,96.54,0.041
243.45,96.71,0.041
243.49,96.89,0.041
243.52,97.06,0.041
243.56,97.24,0.041
243.59,97.41,0.041
243.63,97.59,0.041
243.66,97.76,0.041
243.70,97.94,0.041
243.73,98.11,0.041
243.77,98.29,0.041
243.80,98.46,0.041
243.84,98.64,0.042
243.87,98.81,0.042
243.91,98.99,0.042
243.94,99.16,0.042
243.98,99.34,0.042
244.01,99.51,0.042
244.05,99.69,0.042
244.08,99.86,0.042
244.12,100.04,0.042
244.15,100.21,0.042
244.19,100.39,0.042
244.22,100.56,0.042
244.26,100.74,0.042
244.29,100.91,0.042
244.33,101.09,0.042
244.36,101.26,0.042
244.40,101.44,0.043
244.43,101.61,0.043
244.47,101.79,0.043
244.50,101.96,0.043
244.54,102.14,0.043
244.57,102.32,0.043
244.61,102.49,0.043
244.64,102.67,0.043
244.68,102.84,0.043
244.71,103.02,0.043
244.75,103.19,0.043
244.78,103.37,0.043
244.82,103.54,0.043
244.85,103.72,0.043
244.89,103.90,0.043
244.92,104.07,0.044
244.96,104.24,0.044
244.99,104.42,0.044
245.03,104.59,0.044
245.06,104.77,0.044
245.10,104.94,0.044
245.13,105.12,0.044
245.17,105.29,0.044
245.20,105.47,0.045
245.24,105.64,0.045
245.27,105.81,0.045
245.31,105.99,0.045
245.34,106.16,0.044
245.38,106.34,0.044
245.41,106.51,0.044
245.45,106.69,0.044
245.48,106.86,0.044
245.52,107.04,0.044
245.55,107.22,0.044
245.59,107.39,0.044
245.62,107.57,0.044
245.66,107.74,0.045
245.69,107.91,0.045
245.73,108.09,0.045
245.76,108.27,0.045
245.80,108.44,0.045
245.83,108.62,0.045
245.87,108.79,0.045
245.90,108.97,0.045
245.94,109.14,0.046
245.97,109.32,0.046
246.01,109.49,0.046
246.04,109.67,0.046
246.08,109.84,0.046
246.11,110.02,0.046
246.15,110.19,0.046
246.18,110.37,0.046
246.22,110.54,0.045
246.25,110.72,0.046
246.29,110.89,0.046
246.32,111.07,0.046
246.36,111.24,0.047
246.39,111.42,0.046
246.43,111.59,0.046
246.46,111.77,0.047
246.50,111.94,0.047
246.53,112.12,0.047
246.57,112.29,0.047
246.60,112.47,0.047
246.64,112.64,0.047
246.67,112.82,0.047
246.71,112.99,0.047
246.74,113.17,0.047
246.78,113.34,0.047
246.81,113.52,0.047
246.85,113.69,0.047
246.88,113.87,0.047
246.92,114.04,0.047
246.95,114.22,0.047
246.99,114.39,0.047
247.02,114.57,0.048
247.06,114.75,0.048
247.09,114.92,0.048
247.13,115.09,0.048
247.16,115.27,0.048
247.20,115.44,0.048
247.23,115.62,0.048
247.27,115.79,0.048
247.30,115.97,0.048
247.34,116.14,0.048
247.37,116.32,0.048
247.41,116.49,0.048
247.44,116.67,0.048
247.48,116.84,0.048
247.51,117.02,0.049
247.55,117.19,0.049
247.58,117.37,0.049
247.62,117.54,0.049
247.65,117.72,0.049
247.69,117.89,0.049
247.72,118.07,0.049
247.76,118.24,0.049
247.79,118.42,0.049
247.83,118.60,0.049
247.86,118.77,0.049
247.90,118.95,0.050
247.93,119.12,0.050
247.97,119.30,0.050
248.00,119.47,0.050
248.04,119.65,0.050
248.07,119.82,0.050
248.11,120.00,0.050
248.14,120.17,0.050
248.18,120.35,0.050
248.21,120.52,0.050
248.25,120.70,0.050
248.28,120.87,0.050
248.32,121.05,0.050
248.35,121.22,0.050
248.39,121.40,0.050
248.42,121.57,0.050
248.46,121.75,0.051
248.49,121.92,0.051
248.53,122.10,0.051
248.56,122.27,0.051
248.60,122.45,0.051
248.63,122.62,0.051
248.67,122.80,0.051
248.70,122.97,0.051
248.74,123.15,0.051
248.77,123.32,0.051
248.81,123.50,0.051
248.84,123.67,0.051
248.88,123.85,0.051
248.91,124.02,0.051
248.95,124.20,0.051
248.98,124.37,0.051
249.02,124.55,0.051
249.05,124.72,0.051
249.09,124.90,0.051
249.12,125.07,0.051
249.16,125.25,0.051
249.19,125.42,0.052
249.23,125.60,0.052
249.26,125.77,0.052
249.30,125.95,0.052
249.33,126.12,0.052
249.37,126.30,0.052
249.40,126.47,0.052
249.44,126.65,0.052
249.47,126.82,0.052
249.51,127.00,0.052
249.54,127.17,0.052
249.58,127.35,0.052
249.61,127.52,0.052
249.65,127.70,0.053
249.68,127.87,0.053
249.72,128.05,0.053
249.75,128.22,0.053
249.79,128.40,0.053
249.82,128.57,0.053
249.86,128.75,0.053
249.89,128.92,0.053
249.93,129.10,0.053
249.96,129.27,0.053
250.00,129.45,0.053
250.03,129.62,0.053
250.07,129.80,0.053
250.10,129.97,0.053
250.14,130.15,0.053
250.17,130.33,0.053
250.21,130.50,0.053
250.24,130.68,0.053
250.28,130.85,0.054
250.31,131.03,0.054
250.35,131.20,0.054
250.38,131.38,0.054
250.42,131.55,0.054
250.45,131.73,0.054
250.49,131.90,0.054
250.52,132.08,0.054
250.56,132.25,0.054
250.59,132.43,0.054
250.63,132.60,0.054
250.66,132.78,0.054
250.70,132.95,0.054
250.73,133.13,0.054
250.77,133.30,0.054
250.80,133.48,0.054
250.84,133.65,0.054
250.87,133.83,0.054
250.91,134.00,0.054
250.94,134.18,0.054
250.98,134.35,0.054
251.01,134.53,0.054
251.05,134.70,0.054
251.08,134.87,0.054
251.12,135.05,0.054
251.15,135.23,0.054
251.19,135.40,0.054
251.22,135.58,0.054
251.26,135.75,0.054
251.29,135.93,0.054
251.33,136.10,0.054
251.36,136.28,0.054
251.40,136.45,0.054
251.43,136.63,0.054
251.47,136.80,0.054
251.50,136.98,0.054
251.54,137.15,0.054
251.57,137.32,0.054
251.61,137.50,0.055
251.64,137.67,0.054
251.68,137.85,0.054
251.71,138.03,0.054
251.75,138.20,0.054
251.78,138.38,0.055
251.82,138.55,0.055
251.85,138.73,0.055
251.89,138.90,0.055
251.92,139.08,0.055
251.96,139.25,0.055
251.99,139.43,0.055
252.03,139.60,0.055
252.06,139.78,0.055
252.10,139.95,0.055
252.13,140.13,0.055
252.17,140.30,0.055
252.20,140.48,0.055
252.24,140.65,0.055
252.27,140.83,0.055
252.31,141.00,0.055
252.34,141.18,0.055
252.38,141.35,0.055
252.41,141.53,0.056
252.45,141.70,0.056
252.48,141.88,0.056
252.52,142.05,0.056
252.55,142.23,0.056
252.59,142.40,0.056
252.62,142.58,0.056
252.66,142.75,0.056
252.69,142.93,0.056
252.73,143.10,0.056
252.76,143.27,0.056
252.80,143.45,0.056
252.83,143.62,0.056
252.87,143.80,0.056
252.90,143.98,0.056
252.94,144.15,0.056
252.97,144.33,0.056
253.01,144.50,0.056
253.04,144.68,0.056
253.08,144.85,0.056
253.11,145.03,0.057
253.15,145.20,0.057
253.18,145.38,0.057
253.22,145.55,0.057
253.25,145.73,0.057
253.29,145.90,0.057
253.32,146.08,0.057
253.36,146.25,0.057
253.39,146.43,0.057
253.43,146.60,0.057
253.46,146.78,0.057
253.50,146.95,0.057
253.53,147.13,0.057
253.57,147.30,0.057
253.60,147.48,0.057
253.64,147.65,0.057
253.67,147.83,0.058
253.71,148.00,0.058
253.74,148.18,0.058
253.78,148.35,0.058
253.81,148.53,0.058
253.85,148.70,0.058
253.88,148.88,0.058
253.92,149.05,0.058
253.95,149.23,0.058
253.99,149.40,0.058
254.02,149.58,0.058
254.06,149.75,0.058
254.09,149.93,0.058
254.13,150.10,0.058
254.16,150.28,0.058
254.20,150.45,0.059
254.23,150.63,0.058
254.27,150.80,0.058
254.30,150.98,0.058
254.34,151.15,0.058
254.37,151.33,0.058
254.41,151.50,0.058
254.44,151.68,0.058
254.48,151.85,0.058
254.51,152.03,0.058
254.55,152.21,0.059
254.58,152.38,0.059
254.62,152.55,0.059
254.65,152.73,0.059
254.69,152.90,0.059
254.72,153.08,0.059
254.76,153.25,0.059
254.79,153.43,0.059
254.83,153.60,0.059
254.86,153.78,0.059
254.90,153.95,0.059
254.93,154.13,0.059
254.97,154.31,0.059
255.00,154.48,0.059
255.04,154.66,0.059
255.07,154.83,0.059
255.11,155.01,0.059
255.14,155.18,0.059
255.18,155.35,0.059
255.21,155.53,0.059
255.25,155.70,0.060
255.28,155.88,0.060
255.32,156.05,0.059
255.35,156.23,0.059
255.39,156.40,0.059
255.42,156.58,0.059
255.46,156.75,0.059
255.49,156.93,0.059
255.53,157.10,0.059
255.56,157.28,0.059
255.60,157.45,0.059
255.63,157.63,0.059
255.67,157.81,0.059
255.70,157.98,0.059
255.74,158.16,0.059
255.77,158.33,0.059
255.81,158.50,0.059
255.84,158.68,0.059
255.88,158.86,0.059
255.91,159.03,0.059
255.95,159.21,0.059
255.98,159.38,0.059
256.02,159.56,0.059
256.05,159.73,0.059
256.09,159.91,0.060
256.12,160.08,0.060
256.16,160.26,0.060
256.19,160.43,0.059
256.23,160.61,0.059
256.26,160.78,0.059
256.30,160.96,0.059
256.33,161.13,0.059
256.37,161.31,0.059
256.40,161.48,0.060
256.44,161.66,0.060
256.47,161.83,0.060
256.51,162.01,0.060
256.54,162.18,0.060
256.58,162.35,0.060
256.61,162.53,0.060
256.65,162.71,0.059
256.68,162.88,0.059
256.72,163.06,0.060
256.75,163.23,0.060
256.79,163.40,0.060
256.82,163.58,0.060
256.86,163.76,0.060
256.89,163.93,0.060
256.93,164.11,0.060
256.96,164.28,0.060
257.00,164.46,0.060
257.03,164.63,0.060
257.07,164.81,0.060
257.10,164.98,0.060
257.14,165.16,0.060
257.17,165.33,0.059
257.21,165.51,0.060
257.24,165.68,0.060
257.28,165.86,0.060
257.31,166.03,0.060
257.35,166.21,0.060
257.38,166.38,0.060
257.42,166.56,0.060
257.45,166.73,0.060
257.49,166.91,0.060
257.52,167.08,0.060
257.56,167.26,0.060
257.59,167.43,0.060
257.63,167.61,0.060
257.66,167.78,0.060
257.70,167.96,0.060
257.73,168.13,0.060
257.77,168.31,0.060
257.80,168.48,0.060
257.84,168.66,0.060
257.87,168.83,0.060
257.91,169.01,0.060
257.94,169.18,0.060
257.98,169.36,0.060
258.01,169.53,0.060
258.05,169.71,0.060
258.08,169.88,0.060
258.12,170.06,0.060
258.15,170.23,0.060
258.19,170.41,0.060
258.22,170.58,0.060
258.26,170.76,0.060
258.29,170.93,0.060
258.33,171.11,0.060
258.36,171.28,0.060
258.40,171.46,0.060
258.43,171.63,0.060
258.47,171.81,0.060
258.50,171.98,0.060
258.54,172.16,0.060
258.57,172.33,0.060
258.61,172.51,0.060
258.64,172.68,0.060
258.68,172.86,0.060
258.71,173.03,0.060
258.75,173.21,0.060
258.78,173.38,0.060
258.82,173.56,0.060
258.85,173.73,0.060
258.89,173.91,0.060
258.92,174.08,0.060
258.96,174.26,0.060
258.99,174.43,0.060
259.03,174.61,0.060
259.06,174.78,0.060
259.10,174.96,0.060
259.13,175.13,0.060
259.17,175.31,0.060
259.20,175.48,0.060
259.24,175.66,0.060
259.27,175.83,0.060
259.31,176.01,0.060
259.34,176.18,0.060
259.38,176.36,0.060
259.41,176.53,0.059
259.45,176.71,0.059
259.48,176.88,0.059
259.52,177.06,0.059
259.55,177.23,0.059
259.59,177.41,0.060
259.62,177.58,0.060
259.66,177.76,0.060
259.69,177.93,0.060
259.73,178.11,0.060
259.76,178.28,0.059
259.80,178.46,0.059
259.83,178.64,0.059
259.87,178.81,0.059
259.90,178.99,0.059
259.94,179.16,0.059
259.97,179.34,0.059
260.01,179.51,0.059
260.04,179.69,0.059
260.08,179.86,0.060
260.11,180.03,0.060
260.15,180.21,0.059
260.18,180.39,0.059
260.22,180.56,0.059
260.25,180.74,0.059
260.29,180.91,0.059
260.32,181.08,0.059
260.36,181.26,0.059
260.39,181.44,0.059
260.43,181.61,0.059
260.46,181.78,0.059
260.50,181.96,0.059
260.53,182.14,0.059
260.57,182.31,0.059
260.60,182.49,0.058
260.64,182.66,0.058
260.67,182.84,0.058
260.71,183.01,0.058
260.74,183.19,0.059
260.78,183.36,0.058
260.81,183.54,0.058
260.85,183.71,0.058
260.88,183.89,0.058
260.92,184.06,0.058
260.95,184.24,0.058
260.99,184.41,0.058
261.02,184.59,0.058
261.06,184.76,0.058
261.09,184.94,0.058
261.13,185.11,0.058
261.16,185.29,0.058
261.20,185.46,0.058
261.23,185.64,0.058
261.27,185.81,0.058
261.30,185.99,0.058
261.34,186.16,0.058
261.37,186.34,0.058
261.41,186.51,0.058
261.44,186.69,0.058
261.48,186.86,0.058
261.51,187.04,0.058
261.55,187.21,0.058
261.58,187.39,0.057
261.62,187.56,0.057
261.65,187.74,0.057
261.69,187.91,0.057
261.72,188.09,0.057
261.76,188.26,0.057
261.79,188.44,0.057
261.83,188.61,0.058
261.86,188.79,0.059
261.90,188.96,0.060
261.93,189.13,0.061
261.97,189.31,0.062
262.00,189.48,0.063
262.04,189.66,0.063
262.07,189.83,0.063
262.11,190.01,0.064
262.14,190.18,0.064
262.18,190.36,0.065
262.21,190.53,0.065
262.25,190.71,0.065
262.28,190.89,0.065
262.32,191.06,0.066
262.35,191.24,0.066
262.39,191.41,0.066
262.42,191.58,0.067
262.46,191.76,0.067
262.49,191.93,0.067
262.53,192.11,0.067
262.56,192.28,0.067
262.60,192.46,0.067
262.63,192.63,0.067
262.67,192.81,0.067
262.70,192.99,0.067
262.74,193.16,0.067
262.77,193.34,0.067
262.81,193.51,0.067
262.84,193.69,0.067
262.88,193.86,0.068
262.91,194.03,0.068
262.95,194.21,0.067
262.98,194.38,0.067
263.02,194.56,0.067
263.05,194.74,0.067
263.09,194.91,0.067
263.12,195.09,0.066
263.16,195.26,0.066
263.19,195.44,0.066
263.23,195.61,0.066
263.26,195.79,0.067
263.30,195.96,0.067
263.33,196.14,0.067
263.37,196.31,0.067
263.40,196.49,0.066
263.44,196.66,0.066
263.47,196.84,0.066
263.51,197.01,0.066
263.54,197.19,0.065
263.58,197.36,0.065
263.61,197.54,0.065
263.65,197.71,0.065
263.68,197.89,0.065
263.72,198.06,0.065
263.75,198.24,0.065
263.79,198.41,0.065
263.82,198.59,0.065
263.86,198.76,0.065
263.89,198.94,0.065
263.93,199.11,
263.96,199.29,
263.98,,