File: DSC/2025_04_21_CBG_n60C_80C_5Cmin_x3.csv
Filename,2025_04_21_CBG_n60C_80C_5Cmin_x3
Instrument name,DSC2A-00468 (192.168.1.100)
Operator,Yarger
rundate,4/21/2025
Sample name,2025_04_21_CBG_n60C_80C_5Cmin_x3
proceduresegments,Data Off ; Equilibrate -60.00 °C; Data On ; Ramp 5.00 °C/min to 80.00 °C; Data Off ; Isothermal 1.0 min; Data On ; Ramp 50.00 °C/min to -60.00 °C; Data Off ; Isothermal 1.0 min; Data On ; Ramp 5.00 °C/min to 80.00 °C; Data Off ; Isothermal 1.0 min; Data On ; Ramp 50.00 °C/min to -60.00 °C; Data Off ; Isothermal 1.0 min; Data On ; Ramp 5.00 °C/min to 80.00 °C
[File Parameters]
Run date,4/21/2025 12:10:56 PM
Trios version,5.1.1.46572
Original File Name,
Current File Name,D:\DSC2500\JYarger\2025_04_21_CBG_n60C_80C_5Cmin_x3.tri
[Procedure]
Procedure Name,CBG_n60_80C_5Cmin_x3
Sample Name,2025_04_21_CBG_n60C_80C_5Cmin_x3
Sample Mass,5.22 mg
Reference Sample Mass,0 mg
Pan Mass,51.33 mg
Pan Number,14
Reference Pan Mass,52.66 mg
Reference Pan Number,19
Pan Type,Tzero Aluminum Hermetic
Comments,Al Hermetic DSC Consumables sealed Pan/Lid.
Project Name,CA
Operator,Yarger
Test,Custom
Unload Max Temperature,30
Unload Min Temperature,30
Load Max Temperature,30
Load Min Temperature,30
Stop on Gas Flow Error,Yes
[Signal List]
Signal #1,Time (min)
Signal #2,Temperature (°C)
Signal #3,Heat Flow (mW)
Signal #4,Delta T (µV)
Signal #5,Delta Tzero (µV)
Signal #6,Tzero Temperature (°C)
Signal #7,Cell Purge (mL/min)
Signal #8,Heater Temp (°C)
Signal #9,Power Delivered (W)
Signal #10,Reference Junction Temperature (°C)
Signal #11,Flange Temperature (°C)
Signal #12,Heat Flow Phase (rad)
Signal #13,Total Heat Capacity (J/°C)
Signal #14,Heat Capacity (J/°C)
[Configuration]
Company Name,ASU
Instrument Name,DSC2A-00468
Instrument Type,DSC2500
Serial Number,DSC2A-00468
IP,192.168.1.100
Location of Instrument,MRRC
DisplayType,Unknown
Sample Interval ,0.1 s/pt
Selected Heat Flow,T4P
Exotherm Direction,Down
Cell Serial,DRC2-00792
Lid Type,Standard
Cooler,RCS 90
Leave Cooler on at End of Sequence,On
Gas 2,Nitrogen
Gas Selected,Channel 1
Flow Rate,50 mL/min
Secondary Purge,On
Licensed Heat Flow,Heat Flow T4P
Modulation Licensed,Yes
[Versions]
Common IDD Version,1
Cortex Version,VER 2.10.2.31
Driver,5.0.0.6
GDM Version,1.0.3.3
TouchscreenVersion,1.0.0.16145
FEP Version,1.2.1.21
FEP Bootloader,2.0.0.5
AutoSampler Version,2.1.1.26
Auto Sampler Bootloader,2.0.0.5
FCM Version,1.1.0.3
FCM Bootloader,2.0.0.5
[Experiment Logs]
Experiment Log Entry # 1,Data On set to 0
Experiment Log Entry # 3,Equilibrate Segment -60 (C) Started
Experiment Log Entry # 5,Air Cool is off.
Experiment Log Entry # 7,Data On set to 1
Experiment Log Entry # 9,Ramp Segment 5 C/min to 80 Started
Experiment Log Entry # 11,Data On set to 0
Experiment Log Entry # 13,Isothermal Segment 1 min started
Experiment Log Entry # 15,Data On set to 1
Experiment Log Entry # 17,Ramp Segment 50 C/min to -60 Started
Experiment Log Entry # 19,Data On set to 0
Experiment Log Entry # 21,Isothermal Segment 1 min started
Experiment Log Entry # 23,Data On set to 1
Experiment Log Entry # 25,Ramp Segment 5 C/min to 80 Started
Experiment Log Entry # 27,Data On set to 0
Experiment Log Entry # 29,Isothermal Segment 1 min started
Experiment Log Entry # 31,Data On set to 1
Experiment Log Entry # 33,Ramp Segment 50 C/min to -60 Started
Experiment Log Entry # 35,Data On set to 0
Experiment Log Entry # 37,Isothermal Segment 1 min started
Experiment Log Entry # 39,Data On set to 1
Experiment Log Entry # 41,Ramp Segment 5 C/min to 80 Started
[Method Log]
Method Log Entry # 1,Data Off
Method Log Entry # 2,Equilibrate -60 °C
Method Log Entry # 3,Data On
Method Log Entry # 4,(Ramp 715964) Ramp 5 °C/minute to 80 °C
Method Log Entry # 5,Data Off
Method Log Entry # 6,Isothermal 1 minutes
Method Log Entry # 7,Data On
Method Log Entry # 8,(Ramp 715968) Ramp 50 °C/minute to -60 °C
Method Log Entry # 9,Data Off
Method Log Entry # 10,Isothermal 1 minutes
Method Log Entry # 11,Data On
Method Log Entry # 12,(Ramp 715972) Ramp 5 °C/minute to 80 °C
Method Log Entry # 13,Data Off
Method Log Entry # 14,Isothermal 1 minutes
Method Log Entry # 15,Data On
Method Log Entry # 16,(Ramp 715976) Ramp 50 °C/minute to -60 °C
Method Log Entry # 17,Data Off
Method Log Entry # 18,Isothermal 1 minutes
Method Log Entry # 19,Data On
Method Log Entry # 20,(Ramp 715980) Ramp 5 °C/minute to 80 °C
Cell Serial,DRC2-00792
[T1 Calibration]
Slope,-0.008529666
Offset,9.636258
Initial Temperature,98.23
GUID,f8bfdadc-4977-4fdf-ba6d-0ba9134940c3
[TZero Calibration]
Date Applied,11/29/2022 4:06:13 PM
Description,From -89.059 °C to 396.009 °C at 20.000°C/min
Gas Type,Nitrogen
Pan Type,None
Source Files 1,C:\Users\yargerlab\Desktop\DSC Data\General\TZero_calibration_11_29_22_2nd(2).tri
Source Files 2,C:\Users\yargerlab\Desktop\DSC Data\General\TZero_calibration_11_29_22_2nd(3).tri
Delta T Offset,13.05235
Delta T Slope,-0.007271007
Delta T0 Offset,-13.69128
Delta T0 Slope,0.06063341
[Temperature Calibration]
Date Applied,11/29/2022 7:12:28 PM
Description,From 106.590 °C to 186.590 °C at 10.000°C/min
Gas Type,Nitrogen
Pan Type,Tzero Aluminum Hermetic
Source Files 1,C:\Users\yargerlab\Desktop\DSC Data\General\Indium(6).tri
Measured 1,157.391
Known 1,156.598
[Cell Constant Calibration]
Date Applied,11/29/2022 7:12:29 PM
Description,From 106.590 °C to 186.590 °C at 10.000°C/min
Gas Type,Nitrogen
Pan Type,Tzero Aluminum Hermetic
Source Files 1,C:\Users\yargerlab\Desktop\DSC Data\General\Indium(6).tri
T4P KCell,1.006051
Onset Slope,63.26126 mW/°C
[Direct Cp Calibration]
Date Applied,11/30/2022 11:04:51 AM
Description,From -79.983 °C to 298.409 °C at 10.000°C/min
Gas Type,Nitrogen
Pan Type,Tzero Aluminum Hermetic
Source Files 1,C:\Users\yargerlab\Desktop\DSC Data\General\Sapphire_Heat_Capacity_11_30_22.tri
[Rev Cp Calibration]
Date Applied,11/30/2022 1:58:51 PM
Description,From -79.996 °C to 292.812 °C at 3.000°C/min
Gas Type,Nitrogen
Pan Type,Tzero Aluminum Hermetic
Source Files 1,C:\Users\yargerlab\Desktop\DSC Data\General\Sapphire_MDSC_Calibration_11_30_22.tri
[step]
Ramp 5.00 °C/min to 80.00 °C
Time,Temperature,Heat Flow (Normalized)
min,°C,W/g
0.00,-59.67,-0.093
0.02,-59.69,-0.096
0.04,-59.69,-0.086
0.06,-59.69,-0.082
0.08,-59.68,-0.083
0.10,-59.65,-0.085
0.12,-59.60,-0.085
0.14,-59.54,-0.081
0.16,-59.48,-0.064
0.18,-59.41,-0.048
0.20,-59.33,-0.030
0.22,-59.26,-0.014
0.24,-59.18,0.001
0.26,-59.09,0.012
0.28,-59.01,0.022
0.30,-58.92,0.031
0.32,-58.84,0.038
0.34,-58.75,0.043
0.36,-58.66,0.051
0.38,-58.57,0.054
0.40,-58.47,0.059
0.42,-58.38,0.063
0.44,-58.29,0.066
0.46,-58.19,0.070
0.48,-58.10,0.071
0.50,-58.01,0.074
0.52,-57.91,0.075
0.54,-57.82,0.077
0.56,-57.72,0.078
0.58,-57.62,0.079
0.60,-57.53,0.080
0.62,-57.43,0.081
0.64,-57.33,0.082
0.66,-57.24,0.082
0.68,-57.14,0.083
0.70,-57.04,0.084
0.72,-56.94,0.084
0.74,-56.85,0.085
0.76,-56.75,0.085
0.78,-56.65,0.086
0.80,-56.55,0.086
0.82,-56.46,0.086
0.84,-56.36,0.087
0.86,-56.26,0.087
0.88,-56.16,0.088
0.90,-56.06,0.088
0.92,-55.96,0.088
0.94,-55.86,0.090
0.96,-55.77,0.090
0.98,-55.67,0.090
1.00,-55.57,0.091
1.02,-55.47,0.091
1.04,-55.37,0.091
1.06,-55.27,0.091
1.08,-55.17,0.092
1.10,-55.07,0.092
1.12,-54.98,0.092
1.14,-54.88,0.092
1.16,-54.78,0.093
1.18,-54.68,0.093
1.20,-54.58,0.093
1.22,-54.48,0.093
1.24,-54.38,0.093
1.26,-54.28,0.094
1.28,-54.18,0.094
1.30,-54.08,0.094
1.32,-53.98,0.094
1.34,-53.88,0.094
1.36,-53.78,0.094
1.38,-53.68,0.095
1.40,-53.59,0.095
1.42,-53.49,0.095
1.44,-53.39,0.095
1.46,-53.29,0.095
1.48,-53.19,0.095
1.50,-53.09,0.095
1.52,-52.99,0.095
1.54,-52.89,0.095
1.56,-52.79,0.096
1.58,-52.69,0.096
1.60,-52.59,0.096
1.62,-52.49,0.096
1.64,-52.39,0.096
1.66,-52.29,0.096
1.68,-52.19,0.096
1.70,-52.09,0.096
1.72,-51.99,0.096
1.74,-51.89,0.096
1.76,-51.79,0.096
1.78,-51.69,0.096
1.80,-51.59,0.096
1.82,-51.49,0.097
1.84,-51.39,0.096
1.86,-51.29,0.097
1.88,-51.19,0.097
1.90,-51.09,0.097
1.92,-50.99,0.097
1.94,-50.90,0.097
1.96,-50.79,0.097
1.98,-50.70,0.097
2.00,-50.59,0.097
2.02,-50.50,0.097
2.04,-50.40,0.097
2.06,-50.30,0.097
2.08,-50.19,0.097
2.10,-50.10,0.097
2.12,-50.00,0.097
2.14,-49.90,0.097
2.16,-49.80,0.097
2.18,-49.70,0.097
2.20,-49.60,0.097
2.22,-49.50,0.097
2.24,-49.40,0.097
2.26,-49.30,0.097
2.28,-49.20,0.097
2.30,-49.10,0.097
2.32,-49.00,0.097
2.34,-48.90,0.097
2.36,-48.80,0.097
2.38,-48.70,0.097
2.40,-48.60,0.097
2.42,-48.50,0.097
2.44,-48.40,0.097
2.46,-48.30,0.097
2.48,-48.20,0.097
2.50,-48.10,0.097
2.52,-48.00,0.097
2.54,-47.90,0.097
2.56,-47.80,0.097
2.58,-47.70,0.097
2.60,-47.60,0.097
2.62,-47.50,0.097
2.64,-47.40,0.097
2.66,-47.30,0.097
2.68,-47.20,0.097
2.70,-47.10,0.097
2.72,-47.00,0.097
2.74,-46.90,0.097
2.76,-46.80,0.097
2.78,-46.70,0.097
2.80,-46.60,0.097
2.82,-46.50,0.097
2.84,-46.40,0.097
2.86,-46.30,0.097
2.88,-46.20,0.097
2.90,-46.10,0.098
2.92,-46.00,0.098
2.94,-45.90,0.098
2.96,-45.80,0.098
2.98,-45.70,0.098
3.00,-45.60,0.098
3.02,-45.50,0.098
3.04,-45.40,0.098
3.06,-45.30,0.098
3.08,-45.20,0.098
3.10,-45.10,0.098
3.12,-45.00,0.098
3.14,-44.90,0.098
3.16,-44.80,0.098
3.18,-44.70,0.098
3.20,-44.60,0.098
3.22,-44.50,0.098
3.24,-44.40,0.098
3.26,-44.30,0.098
3.28,-44.20,0.098
3.30,-44.10,0.098
3.32,-44.00,0.098
3.34,-43.90,0.098
3.36,-43.80,0.098
3.38,-43.70,0.098
3.40,-43.60,0.098
3.42,-43.50,0.098
3.44,-43.40,0.098
3.46,-43.30,0.098
3.48,-43.20,0.098
3.50,-43.10,0.098
3.52,-43.00,0.098
3.54,-42.90,0.098
3.56,-42.80,0.098
3.58,-42.70,0.098
3.60,-42.60,0.098
3.62,-42.50,0.098
3.64,-42.40,0.098
3.66,-42.30,0.098
3.68,-42.20,0.098
3.70,-42.10,0.098
3.72,-42.00,0.098
3.74,-41.90,0.098
3.76,-41.80,0.098
3.78,-41.70,0.098
3.80,-41.60,0.098
3.82,-41.50,0.098
3.84,-41.40,0.098
3.86,-41.30,0.098
3.88,-41.20,0.098
3.90,-41.10,0.098
3.92,-41.00,0.098
3.94,-40.90,0.098
3.96,-40.80,0.098
3.98,-40.70,0.098
4.00,-40.60,0.098
4.02,-40.50,0.098
4.04,-40.40,0.098
4.06,-40.30,0.098
4.08,-40.20,0.098
4.10,-40.10,0.098
4.12,-40.00,0.099
4.14,-39.90,0.099
4.16,-39.80,0.099
4.18,-39.70,0.099
4.20,-39.60,0.099
4.22,-39.50,0.099
4.24,-39.40,0.099
4.26,-39.30,0.099
4.28,-39.20,0.099
4.30,-39.10,0.099
4.32,-39.00,0.099
4.34,-38.90,0.099
4.36,-38.80,0.099
4.38,-38.70,0.099
4.40,-38.60,0.099
4.42,-38.50,0.099
4.44,-38.40,0.099
4.46,-38.30,0.099
4.48,-38.20,0.099
4.50,-38.10,0.099
4.52,-37.99,0.099
4.54,-37.89,0.099
4.56,-37.80,0.099
4.58,-37.69,0.099
4.60,-37.59,0.099
4.62,-37.49,0.099
4.64,-37.39,0.099
4.66,-37.30,0.099
4.68,-37.20,0.099
4.70,-37.09,0.099
4.72,-36.99,0.099
4.74,-36.89,0.099
4.76,-36.79,0.099
4.78,-36.69,0.099
4.80,-36.59,0.099
4.82,-36.49,0.099
4.84,-36.39,0.100
4.86,-36.29,0.100
4.88,-36.19,0.100
4.90,-36.09,0.100
4.92,-36.00,0.100
4.94,-35.90,0.100
4.96,-35.80,0.100
4.98,-35.70,0.100
5.00,-35.60,0.100
5.02,-35.50,0.099
5.04,-35.40,0.099
5.06,-35.30,0.099
5.08,-35.20,0.099
5.10,-35.10,0.099
5.12,-35.00,0.099
5.14,-34.90,0.099
5.16,-34.80,0.099
5.18,-34.70,0.099
5.20,-34.60,0.099
5.22,-34.50,0.099
5.24,-34.40,0.099
5.26,-34.30,0.099
5.28,-34.19,0.099
5.30,-34.10,0.100
5.32,-33.99,0.100
5.34,-33.89,0.100
5.36,-33.79,0.100
5.38,-33.69,0.100
5.40,-33.59,0.100
5.42,-33.49,0.100
5.44,-33.39,0.100
5.46,-33.29,0.100
5.48,-33.19,0.100
5.50,-33.09,0.100
5.52,-32.99,0.100
5.54,-32.89,0.100
5.56,-32.79,0.100
5.58,-32.69,0.100
5.60,-32.59,0.100
5.62,-32.49,0.100
5.64,-32.39,0.100
5.66,-32.29,0.100
5.68,-32.19,0.100
5.70,-32.09,0.100
5.72,-31.99,0.100
5.74,-31.89,0.100
5.76,-31.79,0.101
5.78,-31.69,0.101
5.80,-31.59,0.101
5.82,-31.49,0.101
5.84,-31.39,0.101
5.86,-31.29,0.101
5.88,-31.19,0.101
5.90,-31.09,0.101
5.92,-30.99,0.101
5.94,-30.89,0.101
5.96,-30.79,0.101
5.98,-30.69,0.101
6.00,-30.59,0.101
6.02,-30.49,0.101
6.04,-30.39,0.101
6.06,-30.29,0.101
6.08,-30.19,0.101
6.10,-30.09,0.101
6.12,-29.99,0.101
6.14,-29.89,0.101
6.16,-29.79,0.101
6.18,-29.69,0.101
6.20,-29.59,0.101
6.22,-29.49,0.101
6.24,-29.39,0.101
6.26,-29.29,0.101
6.28,-29.19,0.101
6.30,-29.09,0.101
6.32,-28.99,0.101
6.34,-28.89,0.101
6.36,-28.79,0.101
6.38,-28.69,0.101
6.40,-28.59,0.101
6.42,-28.49,0.101
6.44,-28.39,0.101
6.46,-28.29,0.101
6.48,-28.19,0.102
6.50,-28.09,0.102
6.52,-27.98,0.102
6.54,-27.88,0.102
6.56,-27.79,0.102
6.58,-27.68,0.102
6.60,-27.58,0.102
6.62,-27.48,0.102
6.64,-27.38,0.102
6.66,-27.28,0.102
6.68,-27.18,0.102
6.70,-27.08,0.102
6.72,-26.98,0.102
6.74,-26.88,0.102
6.76,-26.78,0.102
6.78,-26.68,0.102
6.80,-26.58,0.102
6.82,-26.48,0.102
6.84,-26.38,0.102
6.86,-26.28,0.102
6.88,-26.18,0.102
6.90,-26.08,0.102
6.92,-25.98,0.102
6.94,-25.88,0.102
6.96,-25.78,0.102
6.98,-25.68,0.102
7.00,-25.58,0.102
7.02,-25.48,0.102
7.04,-25.38,0.102
7.06,-25.28,0.102
7.08,-25.18,0.102
7.10,-25.08,0.102
7.12,-24.98,0.102
7.14,-24.88,0.102
7.16,-24.78,0.102
7.18,-24.68,0.102
7.20,-24.58,0.102
7.22,-24.48,0.103
7.24,-24.38,0.103
7.26,-24.28,0.103
7.28,-24.18,0.103
7.30,-24.08,0.103
7.32,-23.98,0.103
7.34,-23.88,0.103
7.36,-23.78,0.103
7.38,-23.68,0.103
7.40,-23.58,0.103
7.42,-23.48,0.103
7.44,-23.38,0.103
7.46,-23.28,0.103
7.48,-23.18,0.103
7.50,-23.08,0.103
7.52,-22.98,0.103
7.54,-22.88,0.103
7.56,-22.78,0.103
7.58,-22.68,0.103
7.60,-22.58,0.103
7.62,-22.48,0.103
7.64,-22.38,0.103
7.66,-22.28,0.103
7.68,-22.18,0.103
7.70,-22.08,0.103
7.72,-21.98,0.103
7.74,-21.88,0.103
7.76,-21.78,0.103
7.78,-21.68,0.103
7.80,-21.58,0.103
7.82,-21.48,0.104
7.84,-21.38,0.104
7.86,-21.28,0.104
7.88,-21.18,0.104
7.90,-21.08,0.104
7.92,-20.98,0.104
7.94,-20.88,0.104
7.96,-20.78,0.104
7.98,-20.68,0.104
8.00,-20.58,0.104
8.02,-20.48,0.104
8.04,-20.38,0.104
8.06,-20.28,0.104
8.08,-20.18,0.104
8.10,-20.08,0.104
8.12,-19.98,0.104
8.14,-19.88,0.104
8.16,-19.78,0.104
8.18,-19.68,0.104
8.20,-19.58,0.104
8.22,-19.48,0.104
8.24,-19.38,0.104
8.26,-19.28,0.104
8.28,-19.18,0.104
8.30,-19.08,0.104
8.32,-18.98,0.104
8.34,-18.88,0.104
8.36,-18.78,0.104
8.38,-18.68,0.105
8.40,-18.58,0.105
8.42,-18.48,0.105
8.44,-18.38,0.105
8.46,-18.28,0.105
8.48,-18.18,0.105
8.50,-18.08,0.105
8.52,-17.98,0.105
8.54,-17.88,0.105
8.56,-17.78,0.105
8.58,-17.68,0.105
8.60,-17.58,0.105
8.62,-17.48,0.105
8.64,-17.38,0.105
8.66,-17.28,0.105
8.68,-17.18,0.105
8.70,-17.08,0.105
8.72,-16.98,0.105
8.74,-16.88,0.105
8.76,-16.78,0.105
8.78,-16.68,0.105
8.80,-16.57,0.105
8.82,-16.48,0.105
8.84,-16.37,0.105
8.86,-16.27,0.105
8.88,-16.18,0.105
8.90,-16.08,0.105
8.92,-15.98,0.105
8.94,-15.88,0.105
8.96,-15.78,0.106
8.98,-15.68,0.106
9.00,-15.58,0.106
9.02,-15.48,0.106
9.04,-15.38,0.106
9.06,-15.28,0.106
9.08,-15.17,0.106
9.10,-15.08,0.106
9.12,-14.97,0.106
9.14,-14.87,0.106
9.16,-14.77,0.106
9.18,-14.67,0.106
9.20,-14.57,0.106
9.22,-14.48,0.106
9.24,-14.38,0.106
9.26,-14.27,0.106
9.28,-14.18,0.106
9.30,-14.07,0.106
9.32,-13.97,0.106
9.34,-13.87,0.106
9.36,-13.77,0.106
9.38,-13.67,0.106
9.40,-13.57,0.106
9.42,-13.47,0.106
9.44,-13.37,0.107
9.46,-13.27,0.107
9.48,-13.17,0.107
9.50,-13.07,0.107
9.52,-12.97,0.107
9.54,-12.87,0.107
9.56,-12.77,0.107
9.58,-12.67,0.107
9.60,-12.57,0.107
9.62,-12.47,0.107
9.64,-12.37,0.107
9.66,-12.27,0.107
9.68,-12.17,0.107
9.70,-12.07,0.107
9.72,-11.97,0.107
9.74,-11.87,0.107
9.76,-11.77,0.107
9.78,-11.67,0.107
9.80,-11.57,0.107
9.82,-11.47,0.107
9.84,-11.37,0.107
9.86,-11.27,0.107
9.88,-11.17,0.107
9.90,-11.07,0.107
9.92,-10.97,0.107
9.94,-10.87,0.107
9.96,-10.77,0.107
9.98,-10.67,0.108
10.00,-10.57,0.108
10.02,-10.47,0.108
10.04,-10.37,0.108
10.06,-10.27,0.108
10.08,-10.17,0.108
10.10,-10.07,0.107
10.12,-9.97,0.107
10.14,-9.87,0.107
10.16,-9.77,0.108
10.18,-9.66,0.108
10.20,-9.56,0.108
10.22,-9.46,0.108
10.24,-9.36,0.108
10.26,-9.26,0.109
10.28,-9.16,0.109
10.30,-9.06,0.109
10.32,-8.97,0.109
10.34,-8.86,0.109
10.36,-8.76,0.109
10.38,-8.67,0.109
10.40,-8.57,0.109
10.42,-8.47,0.109
10.44,-8.37,0.109
10.46,-8.27,0.109
10.48,-8.17,0.109
10.50,-8.07,0.109
10.52,-7.97,0.109
10.54,-7.87,0.109
10.56,-7.77,0.109
10.58,-7.67,0.109
10.60,-7.57,0.109
10.62,-7.47,0.109
10.64,-7.37,0.109
10.66,-7.27,0.109
10.68,-7.17,0.109
10.70,-7.07,0.109
10.72,-6.97,0.109
10.74,-6.87,0.109
10.76,-6.77,0.109
10.78,-6.67,0.109
10.80,-6.57,0.109
10.82,-6.47,0.109
10.84,-6.37,0.109
10.86,-6.27,0.109
10.88,-6.17,0.109
10.90,-6.07,0.109
10.92,-5.97,0.109
10.94,-5.87,0.109
10.96,-5.77,0.109
10.98,-5.67,0.109
11.00,-5.57,0.109
11.02,-5.47,0.109
11.04,-5.37,0.109
11.06,-5.27,0.109
11.08,-5.17,0.109
11.10,-5.07,0.109
11.12,-4.97,0.110
11.14,-4.87,0.110
11.16,-4.77,0.110
11.18,-4.67,0.110
11.20,-4.57,0.110
11.22,-4.47,0.110
11.24,-4.37,0.110
11.26,-4.27,0.110
11.28,-4.17,0.110
11.30,-4.07,0.110
11.32,-3.97,0.110
11.34,-3.87,0.110
11.36,-3.77,0.110
11.38,-3.67,0.110
11.40,-3.57,0.110
11.42,-3.47,0.110
11.44,-3.37,0.110
11.46,-3.27,0.110
11.48,-3.17,0.110
11.50,-3.07,0.110
11.52,-2.96,0.110
11.54,-2.87,0.110
11.56,-2.76,0.110
11.58,-2.67,0.111
11.60,-2.56,0.111
11.62,-2.47,0.111
11.64,-2.37,0.111
11.66,-2.26,0.111
11.68,-2.16,0.111
11.70,-2.06,0.111
11.72,-1.96,0.111
11.74,-1.87,0.111
11.76,-1.77,0.111
11.78,-1.67,0.111
11.80,-1.57,0.111
11.82,-1.46,0.111
11.84,-1.36,0.111
11.86,-1.26,0.111
11.88,-1.16,0.111
11.90,-1.07,0.111
11.92,-0.96,0.111
11.94,-0.87,0.111
11.96,-0.76,0.111
11.98,-0.66,0.111
12.00,-0.57,0.111
12.02,-0.46,0.111
12.04,-0.36,0.111
12.06,-0.26,0.112
12.08,-0.16,0.112
12.10,-0.06,0.112
12.12,0.04,0.112
12.14,0.14,0.112
12.16,0.24,0.112
12.18,0.34,0.112
12.20,0.44,0.112
12.22,0.54,0.112
12.24,0.64,0.112
12.26,0.74,0.112
12.28,0.84,0.112
12.30,0.94,0.112
12.32,1.04,0.112
12.34,1.14,0.112
12.36,1.24,0.112
12.38,1.34,0.112
12.40,1.44,0.112
12.42,1.54,0.112
12.44,1.64,0.112
12.46,1.74,0.112
12.48,1.84,0.112
12.50,1.94,0.112
12.52,2.04,0.112
12.54,2.14,0.112
12.56,2.24,0.113
12.58,2.34,0.113
12.60,2.44,0.113
12.62,2.54,0.113
12.64,2.64,0.113
12.66,2.74,0.113
12.68,2.84,0.113
12.70,2.94,0.113
12.72,3.04,0.113
12.74,3.14,0.113
12.76,3.24,0.113
12.78,3.34,0.113
12.80,3.44,0.113
12.82,3.54,0.113
12.84,3.64,0.113
12.86,3.74,0.113
12.88,3.84,0.113
12.90,3.94,0.113
12.92,4.04,0.113
12.94,4.14,0.113
12.96,4.24,0.113
12.98,4.34,0.114
13.00,4.44,0.114
13.02,4.54,0.114
13.04,4.64,0.114
13.06,4.74,0.114
13.08,4.84,0.114
13.10,4.94,0.114
13.12,5.04,0.114
13.14,5.14,0.114
13.16,5.24,0.114
13.18,5.34,0.114
13.20,5.44,0.114
13.22,5.54,0.114
13.24,5.64,0.114
13.26,5.74,0.114
13.28,5.84,0.114
13.30,5.94,0.114
13.32,6.04,0.114
13.34,6.14,0.114
13.36,6.24,0.114
13.38,6.34,0.114
13.40,6.44,0.114
13.42,6.54,0.114
13.44,6.64,0.114
13.46,6.74,0.114
13.48,6.84,0.115
13.50,6.94,0.115
13.52,7.04,0.115
13.54,7.14,0.115
13.56,7.24,0.115
13.58,7.34,0.115
13.60,7.44,0.115
13.62,7.54,0.115
13.64,7.64,0.115
13.66,7.74,0.115
13.68,7.84,0.115
13.70,7.94,0.115
13.72,8.04,0.115
13.74,8.14,0.115
13.76,8.24,0.115
13.78,8.34,0.115
13.80,8.44,0.115
13.82,8.54,0.115
13.84,8.64,0.115
13.86,8.74,0.115
13.88,8.84,0.115
13.90,8.94,0.115
13.92,9.04,0.115
13.94,9.14,0.115
13.96,9.24,0.115
13.98,9.34,0.115
14.00,9.44,0.115
14.02,9.54,0.115
14.04,9.64,0.115
14.06,9.74,0.116
14.08,9.84,0.116
14.10,9.94,0.116
14.12,10.04,0.116
14.14,10.14,0.116
14.16,10.24,0.116
14.18,10.34,0.116
14.20,10.44,0.116
14.22,10.55,0.116
14.24,10.64,0.116
14.26,10.74,0.116
14.28,10.84,0.116
14.30,10.94,0.116
14.32,11.04,0.116
14.34,11.14,0.116
14.36,11.24,0.116
14.38,11.34,0.116
14.40,11.44,0.116
14.42,11.54,0.117
14.44,11.64,0.117
14.46,11.74,0.117
14.48,11.84,0.117
14.50,11.94,0.117
14.52,12.04,0.117
14.54,12.14,0.117
14.56,12.24,0.117
14.58,12.34,0.117
14.60,12.45,0.117
14.62,12.54,0.117
14.64,12.65,0.117
14.66,12.74,0.117
14.68,12.84,0.117
14.70,12.94,0.117
14.72,13.04,0.117
14.74,13.14,0.117
14.76,13.24,0.117
14.78,13.34,0.117
14.80,13.45,0.117
14.82,13.54,0.117
14.84,13.64,0.118
14.86,13.74,0.118
14.88,13.85,0.118
14.90,13.95,0.118
14.92,14.04,0.118
14.94,14.15,0.118
14.96,14.25,0.118
14.98,14.35,0.118
15.00,14.45,0.118
15.02,14.55,0.118
15.04,14.65,0.118
15.06,14.75,0.118
15.08,14.85,0.118
15.10,14.95,0.118
15.12,15.05,0.118
15.14,15.15,0.118
15.16,15.25,0.118
15.18,15.35,0.118
15.20,15.45,0.118
15.22,15.55,0.119
15.24,15.65,0.119
15.26,15.75,0.119
15.28,15.85,0.119
15.30,15.95,0.119
15.32,16.05,0.119
15.34,16.15,0.119
15.36,16.25,0.119
15.38,16.35,0.119
15.40,16.45,0.119
15.42,16.55,0.119
15.44,16.65,0.119
15.46,16.75,0.119
15.48,16.85,0.119
15.50,16.95,0.119
15.52,17.05,0.119
15.54,17.15,0.119
15.56,17.25,0.119
15.58,17.35,0.119
15.60,17.45,0.119
15.62,17.55,0.120
15.64,17.65,0.120
15.66,17.75,0.120
15.68,17.85,0.120
15.70,17.95,0.120
15.72,18.05,0.120
15.74,18.15,0.120
15.76,18.25,0.120
15.78,18.35,0.120
15.80,18.45,0.120
15.82,18.55,0.120
15.84,18.65,0.120
15.86,18.75,0.120
15.88,18.85,0.120
15.90,18.95,0.120
15.92,19.05,0.120
15.94,19.15,0.120
15.96,19.25,0.120
15.98,19.35,0.120
16.00,19.45,0.120
16.02,19.55,0.121
16.04,19.65,0.121
16.06,19.75,0.121
16.08,19.85,0.121
16.10,19.95,0.121
16.12,20.05,0.121
16.14,20.15,0.121
16.16,20.25,0.121
16.18,20.35,0.121
16.20,20.45,0.121
16.22,20.55,0.121
16.24,20.65,0.121
16.26,20.75,0.121
16.28,20.85,0.121
16.30,20.95,0.121
16.32,21.05,0.121
16.34,21.15,0.121
16.36,21.25,0.121
16.38,21.35,0.121
16.40,21.45,0.121
16.42,21.55,0.122
16.44,21.65,0.122
16.46,21.75,0.122
16.48,21.85,0.122
16.50,21.95,0.122
16.52,22.05,0.122
16.54,22.15,0.122
16.56,22.25,0.122
16.58,22.35,0.122
16.60,22.45,0.122
16.62,22.55,0.122
16.64,22.65,0.122
16.66,22.75,0.122
16.68,22.85,0.122
16.70,22.95,0.122
16.72,23.05,0.123
16.74,23.15,0.123
16.76,23.25,0.123
16.78,23.35,0.123
16.80,23.45,0.123
16.82,23.55,0.123
16.84,23.65,0.123
16.86,23.75,0.123
16.88,23.85,0.123
16.90,23.95,0.123
16.92,24.05,0.123
16.94,24.15,0.123
16.96,24.25,0.123
16.98,24.35,0.123
17.00,24.45,0.123
17.02,24.55,0.124
17.04,24.65,0.124
17.06,24.75,0.124
17.08,24.85,0.124
17.10,24.95,0.124
17.12,25.05,0.124
17.14,25.15,0.124
17.16,25.25,0.124
17.18,25.35,0.124
17.20,25.45,0.124
17.22,25.55,0.124
17.24,25.65,0.124
17.26,25.75,0.124
17.28,25.85,0.124
17.30,25.95,0.124
17.32,26.05,0.124
17.34,26.15,0.124
17.36,26.25,0.124
17.38,26.35,0.124
17.40,26.45,0.124
17.42,26.56,0.124
17.44,26.65,0.124
17.46,26.75,0.124
17.48,26.85,0.124
17.50,26.95,0.124
17.52,27.05,0.124
17.54,27.15,0.124
17.56,27.25,0.124
17.58,27.35,0.125
17.60,27.45,0.125
17.62,27.55,0.125
17.64,27.65,0.125
17.66,27.75,0.125
17.68,27.85,0.125
17.70,27.95,0.125
17.72,28.05,0.125
17.74,28.15,0.125
17.76,28.25,0.125
17.78,28.35,0.125
17.80,28.45,0.125
17.82,28.55,0.125
17.84,28.65,0.125
17.86,28.75,0.125
17.88,28.85,0.126
17.90,28.95,0.126
17.92,29.05,0.126
17.94,29.15,0.126
17.96,29.26,0.126
17.98,29.35,0.126
18.00,29.45,0.126
18.02,29.55,0.126
18.04,29.65,0.126
18.06,29.75,0.126
18.08,29.86,0.126
18.10,29.96,0.126
18.12,30.05,0.126
18.14,30.16,0.127
18.16,30.25,0.127
18.18,30.36,0.127
18.20,30.45,0.127
18.22,30.56,0.127
18.24,30.66,0.127
18.26,30.76,0.127
18.28,30.86,0.127
18.30,30.95,0.127
18.32,31.06,0.127
18.34,31.15,0.127
18.36,31.26,0.128
18.38,31.35,0.128
18.40,31.45,0.128
18.42,31.55,0.128
18.44,31.66,0.128
18.46,31.75,0.128
18.48,31.86,0.128
18.50,31.95,0.128
18.52,32.06,0.128
18.54,32.16,0.128
18.56,32.26,0.129
18.58,32.36,0.129
18.60,32.45,0.129
18.62,32.56,0.129
18.64,32.66,0.129
18.66,32.76,0.129
18.68,32.86,0.129
18.70,32.95,0.129
18.72,33.06,0.129
18.74,33.16,0.130
18.76,33.25,0.130
18.78,33.36,0.130
18.80,33.46,0.130
18.82,33.56,0.130
18.84,33.66,0.130
18.86,33.76,0.130
18.88,33.86,0.130
18.90,33.96,0.130
18.92,34.06,0.131
18.94,34.16,0.131
18.96,34.26,0.131
18.98,34.36,0.131
19.00,34.46,0.131
19.02,34.56,0.131
19.04,34.66,0.131
19.06,34.76,0.132
19.08,34.86,0.132
19.10,34.96,0.132
19.12,35.06,0.132
19.14,35.16,0.132
19.16,35.26,0.132
19.18,35.36,0.132
19.20,35.46,0.132
19.22,35.56,0.133
19.24,35.66,0.133
19.26,35.76,0.133
19.28,35.86,0.133
19.30,35.96,0.133
19.32,36.06,0.133
19.34,36.16,0.133
19.36,36.26,0.133
19.38,36.36,0.133
19.40,36.46,0.133
19.42,36.56,0.134
19.44,36.66,0.134
19.46,36.76,0.134
19.48,36.86,0.134
19.50,36.96,0.134
19.52,37.06,0.134
19.54,37.16,0.134
19.56,37.26,0.135
19.58,37.36,0.135
19.60,37.46,0.135
19.62,37.56,0.135
19.64,37.66,0.135
19.66,37.76,0.135
19.68,37.86,0.135
19.70,37.96,0.135
19.72,38.06,0.135
19.74,38.16,0.136
19.76,38.26,0.136
19.78,38.36,0.136
19.80,38.46,0.136
19.82,38.56,0.136
19.84,38.66,0.136
19.86,38.76,0.136
19.88,38.86,0.137
19.90,38.96,0.137
19.92,39.06,0.137
19.94,39.16,0.137
19.96,39.26,0.137
19.98,39.36,0.137
20.00,39.46,0.137
20.02,39.56,0.138
20.04,39.66,0.138
20.06,39.76,0.138
20.08,39.86,0.138
20.10,39.96,0.138
20.12,40.06,0.138
20.14,40.16,0.139
20.16,40.26,0.139
20.18,40.36,0.139
20.20,40.46,0.139
20.22,40.56,0.139
20.24,40.66,0.140
20.26,40.76,0.140
20.28,40.86,0.140
20.30,40.96,0.140
20.32,41.06,0.140
20.34,41.16,0.141
20.36,41.26,0.141
20.38,41.36,0.141
20.40,41.46,0.141
20.42,41.56,0.141
20.44,41.66,0.142
20.46,41.76,0.142
20.48,41.86,0.142
20.50,41.96,0.142
20.52,42.06,0.143
20.54,42.16,0.143
20.56,42.26,0.143
20.58,42.36,0.143
20.60,42.46,0.144
20.62,42.56,0.144
20.64,42.66,0.144
20.66,42.76,0.145
20.68,42.86,0.145
20.70,42.96,0.145
20.72,43.06,0.146
20.74,43.16,0.146
20.76,43.26,0.146
20.78,43.36,0.147
20.80,43.46,0.147
20.82,43.56,0.147
20.84,43.66,0.148
20.86,43.76,0.148
20.88,43.86,0.149
20.90,43.96,0.149
20.92,44.06,0.149
20.94,44.16,0.150
20.96,44.26,0.150
20.98,44.36,0.151
21.00,44.45,0.151
21.02,44.56,0.151
21.04,44.66,0.152
21.06,44.75,0.153
21.08,44.86,0.153
21.10,44.95,0.154
21.12,45.06,0.154
21.14,45.15,0.155
21.16,45.25,0.155
21.18,45.35,0.156
21.20,45.45,0.157
21.22,45.55,0.157
21.24,45.65,0.158
21.26,45.75,0.159
21.28,45.85,0.160
21.30,45.95,0.161
21.32,46.05,0.162
21.34,46.15,0.163
21.36,46.25,0.164
21.38,46.35,0.165
21.40,46.45,0.167
21.42,46.55,0.168
21.44,46.65,0.170
21.46,46.75,0.171
21.48,46.85,0.173
21.50,46.95,0.174
21.52,47.05,0.175
21.54,47.15,0.177
21.56,47.25,0.179
21.58,47.35,0.181
21.60,47.45,0.184
21.62,47.55,0.186
21.64,47.65,0.188
21.66,47.75,0.190
21.68,47.85,0.192
21.70,47.94,0.196
21.72,48.04,0.199
21.74,48.14,0.203
21.76,48.24,0.205
21.78,48.34,0.208
21.80,48.44,0.211
21.82,48.54,0.216
21.84,48.64,0.219
21.86,48.74,0.223
21.88,48.83,0.228
21.90,48.93,0.232
21.92,49.03,0.237
21.94,49.13,0.242
21.96,49.23,0.250
21.98,49.33,0.255
22.00,49.43,0.261
22.02,49.52,0.267
22.04,49.62,0.274
22.06,49.72,0.282
22.08,49.82,0.289
22.10,49.91,0.300
22.12,50.01,0.309
22.14,50.11,0.319
22.16,50.20,0.330
22.18,50.30,0.343
22.20,50.40,0.354
22.22,50.49,0.367
22.24,50.59,0.382
22.26,50.68,0.398
22.28,50.78,0.415
22.30,50.87,0.433
22.32,50.97,0.454
22.34,51.06,0.475
22.36,51.15,0.499
22.38,51.24,0.523
22.40,51.33,0.552
22.42,51.43,0.581
22.44,51.52,0.613
22.46,51.60,0.649
22.48,51.69,0.687
22.50,51.78,0.730
22.52,51.86,0.777
22.54,51.95,0.829
22.56,52.03,0.887
22.58,52.11,0.956
22.60,52.19,1.035
22.62,52.26,1.130
22.64,52.33,1.246
22.66,52.40,1.366
22.68,52.46,1.494
22.70,52.52,1.606
22.72,52.58,1.747
22.74,52.63,1.909
22.76,52.68,2.087
22.78,52.72,2.210
22.80,52.77,2.315
22.82,52.82,2.458
22.84,52.88,2.582
22.86,52.93,2.728
22.88,52.98,2.871
22.90,53.03,2.950
22.92,53.09,3.034
22.94,53.15,3.150
22.96,53.20,3.365
22.98,53.24,3.589
23.00,53.28,3.691
23.02,53.34,3.719
23.04,53.41,3.726
23.06,53.50,3.567
23.08,53.61,3.535
23.10,53.71,3.551
23.12,53.81,3.496
23.14,53.93,3.346
23.16,54.07,3.034
23.18,54.24,2.713
23.20,54.43,2.364
23.22,54.63,1.999
23.24,54.84,1.651
23.26,55.05,1.348
23.28,55.27,1.087
23.30,55.46,0.916
23.32,55.65,0.790
23.34,55.81,0.685
23.36,55.97,0.598
23.38,56.12,0.527
23.40,56.26,0.469
23.42,56.39,0.418
23.44,56.52,0.379
23.46,56.64,0.346
23.48,56.76,0.316
23.50,56.88,0.292
23.52,56.99,0.272
23.54,57.10,0.256
23.56,57.21,0.242
23.58,57.32,0.231
23.60,57.43,0.221
23.62,57.53,0.214
23.64,57.64,0.206
23.66,57.74,0.202
23.68,57.84,0.197
23.70,57.94,0.193
23.72,58.05,0.191
23.74,58.15,0.189
23.76,58.25,0.187
23.78,58.35,0.185
23.80,58.45,0.184
23.82,58.55,0.183
23.84,58.65,0.182
23.86,58.75,0.181
23.88,58.86,0.181
23.90,58.96,0.180
23.92,59.06,0.180
23.94,59.16,0.179
23.96,59.26,0.179
23.98,59.36,0.179
24.00,59.46,0.178
24.02,59.56,0.178
24.04,59.66,0.178
24.06,59.76,0.178
24.08,59.86,0.178
24.10,59.96,0.178
24.12,60.06,0.177
24.14,60.16,0.177
24.16,60.26,0.177
24.18,60.36,0.177
24.20,60.46,0.177
24.22,60.56,0.177
24.24,60.66,0.177
24.26,60.76,0.177
24.28,60.86,0.176
24.30,60.96,0.176
24.32,61.06,0.176
24.34,61.16,0.176
24.36,61.26,0.176
24.38,61.36,0.176
24.40,61.46,0.176
24.42,61.56,0.176
24.44,61.66,0.176
24.46,61.76,0.176
24.48,61.86,0.176
24.50,61.96,0.176
24.52,62.06,0.176
24.54,62.16,0.176
24.56,62.26,0.176
24.58,62.36,0.176
24.60,62.46,0.175
24.62,62.56,0.175
24.64,62.66,0.175
24.66,62.76,0.175
24.68,62.86,0.175
24.70,62.96,0.175
24.72,63.06,0.175
24.74,63.16,0.175
24.76,63.26,0.175
24.78,63.36,0.175
24.80,63.46,0.175
24.82,63.56,0.175
24.84,63.66,0.175
24.86,63.76,0.175
24.88,63.86,0.175
24.90,63.96,0.175
24.92,64.06,0.175
24.94,64.16,0.175
24.96,64.26,0.175
24.98,64.36,0.176
25.00,64.46,0.176
25.02,64.56,0.176
25.04,64.66,0.176
25.06,64.76,0.176
25.08,64.86,0.176
25.10,64.96,0.176
25.12,65.06,0.176
25.14,65.16,0.176
25.16,65.26,0.176
25.18,65.36,0.176
25.20,65.46,0.176
25.22,65.56,0.176
25.24,65.66,0.176
25.26,65.76,0.176
25.28,65.86,0.176
25.30,65.96,0.176
25.32,66.06,0.176
25.34,66.16,0.176
25.36,66.26,0.176
25.38,66.36,0.176
25.40,66.46,0.176
25.42,66.56,0.176
25.44,66.66,0.176
25.46,66.76,0.176
25.48,66.86,0.176
25.50,66.96,0.176
25.52,67.06,0.176
25.54,67.16,0.176
25.56,67.26,0.176
25.58,67.36,0.176
25.60,67.46,0.176
25.62,67.56,0.176
25.64,67.66,0.176
25.66,67.76,0.176
25.68,67.86,0.177
25.70,67.96,0.177
25.72,68.06,0.177
25.74,68.16,0.177
25.76,68.26,0.177
25.78,68.36,0.177
25.80,68.46,0.177
25.82,68.56,0.177
25.84,68.66,0.177
25.86,68.76,0.177
25.88,68.86,0.177
25.90,68.96,0.177
25.92,69.06,0.177
25.94,69.16,0.177
25.96,69.27,0.177
25.98,69.37,0.177
26.00,69.46,0.177
26.02,69.56,0.177
26.04,69.66,0.177
26.06,69.76,0.177
26.08,69.86,0.177
26.10,69.96,0.177
26.12,70.06,0.177
26.14,70.16,0.177
26.16,70.26,0.177
26.18,70.36,0.177
26.20,70.46,0.177
26.22,70.56,0.177
26.24,70.66,0.177
26.26,70.76,0.177
26.28,70.86,0.177
26.30,70.97,0.177
26.32,71.07,0.177
26.34,71.17,0.177
26.36,71.26,0.177
26.38,71.37,0.177
26.40,71.47,0.177
26.42,71.56,0.177
26.44,71.67,0.177
26.46,71.77,0.177
26.48,71.86,0.177
26.50,71.97,0.177
26.52,72.07,0.177
26.54,72.16,0.177
26.56,72.27,0.177
26.58,72.36,0.178
26.60,72.47,0.178
26.62,72.57,0.178
26.64,72.67,0.178
26.66,72.77,0.178
26.68,72.87,0.178
26.70,72.97,0.178
26.72,73.07,0.178
26.74,73.17,0.178
26.76,73.27,0.178
26.78,73.37,0.178
26.80,73.47,0.178
26.82,73.57,0.178
26.84,73.67,0.178
26.86,73.77,0.178
26.88,73.87,0.178
26.90,73.97,0.178
26.92,74.07,0.178
26.94,74.17,0.178
26.96,74.27,0.178
26.98,74.37,0.178
27.00,74.47,0.178
27.02,74.57,0.178
27.04,74.67,0.178
27.06,74.77,0.178
27.08,74.87,0.178
27.10,74.97,0.178
27.12,75.07,0.178
27.14,75.17,0.178
27.16,75.27,0.178
27.18,75.37,0.178
27.20,75.47,0.178
27.22,75.57,0.178
27.24,75.67,0.178
27.26,75.77,0.178
27.28,75.87,0.178
27.30,75.97,0.178
27.32,76.07,0.178
27.34,76.17,0.178
27.36,76.27,0.178
27.38,76.37,0.178
27.40,76.47,0.178
27.42,76.57,0.178
27.44,76.67,0.179
27.46,76.77,0.179
27.48,76.87,0.179
27.50,76.97,0.179
27.52,77.07,0.179
27.54,77.17,0.179
27.56,77.27,0.179
27.58,77.37,0.179
27.60,77.47,0.179
27.62,77.57,0.179
27.64,77.67,0.179
27.66,77.77,0.179
27.68,77.87,0.179
27.70,77.97,0.179
27.72,78.07,0.179
27.74,78.17,0.179
27.76,78.27,0.179
27.78,78.37,0.179
27.80,78.47,0.179
27.82,78.57,0.179
27.84,78.67,0.179
27.86,78.77,0.179
27.88,78.87,0.179
27.90,78.97,0.179
27.92,79.07,0.179
27.94,79.17,
27.96,79.27,
27.98,,
27.98,,

[step]
Ramp 50.00 °C/min to -60.00 °C
Time,Temperature,Heat Flow (Normalized)
min,°C,W/g
28.98,80.12,-0.033
28.99,80.12,-0.034
28.99,80.12,-0.034
28.99,80.12,-0.034
29.00,80.12,-0.034
29.00,80.11,-0.034
29.01,80.11,-0.034
29.01,80.11,-0.034
29.01,80.11,-0.034
29.02,80.10,-0.034
29.02,80.10,-0.033
29.02,80.09,-0.033
29.03,80.09,-0.030
29.03,80.08,-0.022
29.03,80.07,-0.014
29.03,80.06,-0.007
29.04,80.05,0.000
29.04,80.03,0.008
29.04,80.02,0.017
29.05,80.00,0.026
29.05,79.98,0.034
29.06,79.96,0.042
29.06,79.93,0.050
29.06,79.91,0.056
29.07,79.88,0.062
29.07,79.85,0.066
29.07,79.81,0.068
29.08,79.77,0.068
29.08,79.74,0.068
29.08,79.69,0.065
29.08,79.65,0.062
29.09,79.60,0.057
29.09,79.55,0.050
29.09,79.50,0.043
29.10,79.45,0.033
29.10,79.39,0.020
29.11,79.34,0.007
29.11,79.28,-0.007
29.11,79.21,-0.022
29.12,79.15,-0.038
29.12,79.08,-0.056
29.12,79.01,-0.075
29.13,78.94,-0.095
29.13,78.87,-0.115
29.13,78.80,-0.137
29.13,78.72,-0.159
29.14,78.64,-0.183
29.14,78.56,-0.207
29.14,78.48,-0.231
29.15,78.39,-0.256
29.15,78.31,-0.280
29.16,78.22,-0.306
29.16,78.13,-0.331
29.16,78.04,-0.357
29.17,77.95,-0.384
29.17,77.86,-0.411
29.17,77.76,-0.438
29.18,77.67,-0.465
29.18,77.57,-0.492
29.18,77.47,-0.518
29.18,77.37,-0.544
29.19,77.26,-0.571
29.19,77.16,-0.598
29.19,77.06,-0.624
29.20,76.95,-0.650
29.20,76.84,-0.676
29.21,76.74,-0.702
29.21,76.63,-0.727
29.21,76.51,-0.753
29.22,76.40,-0.778
29.22,76.29,-0.803
29.22,76.18,-0.827
29.23,76.06,-0.851
29.23,75.95,-0.875
29.23,75.83,-0.899
29.23,75.71,-0.922
29.24,75.59,-0.945
29.24,75.47,-0.967
29.24,75.35,-0.988
29.25,75.23,-1.010
29.25,75.11,-1.031
29.26,74.99,-1.052
29.26,74.86,-1.073
29.26,74.74,-1.094
29.27,74.61,-1.113
29.27,74.49,-1.133
29.27,74.36,-1.153
29.28,74.23,-1.172
29.28,74.11,-1.192
29.28,73.98,-1.209
29.28,73.85,-1.226
29.29,73.72,-1.243
29.29,73.59,-1.260
29.29,73.46,-1.276
29.30,73.32,-1.292
29.30,73.19,-1.308
29.31,73.06,-1.324
29.31,72.93,-1.339
29.31,72.79,-1.353
29.32,72.66,-1.368
29.32,72.52,-1.382
29.32,72.39,-1.396
29.33,72.25,-1.409
29.33,72.12,-1.423
29.33,71.98,-1.436
29.33,71.84,-1.449
29.34,71.71,-1.462
29.34,71.57,-1.476
29.34,71.43,-1.488
29.35,71.29,-1.500
29.35,71.16,-1.510
29.36,71.02,-1.520
29.36,70.88,-1.530
29.36,70.74,-1.541
29.37,70.60,-1.551
29.37,70.46,-1.560
29.37,70.32,-1.571
29.38,70.17,-1.580
29.38,70.03,-1.590
29.38,69.89,-1.598
29.38,69.75,-1.606
29.39,69.61,-1.615
29.39,69.47,-1.624
29.39,69.32,-1.632
29.40,69.18,-1.641
29.40,69.04,-1.649
29.41,68.90,-1.657
29.41,68.75,-1.665
29.41,68.61,-1.672
29.42,68.47,-1.678
29.42,68.32,-1.685
29.42,68.18,-1.691
29.43,68.03,-1.697
29.43,67.89,-1.703
29.43,67.74,-1.710
29.43,67.60,-1.715
29.44,67.45,-1.721
29.44,67.31,-1.726
29.44,67.16,-1.731
29.45,67.02,-1.737
29.45,66.87,-1.743
29.46,66.73,-1.748
29.46,66.58,-1.754
29.46,66.44,-1.759
29.47,66.29,-1.763
29.47,66.15,-1.768
29.47,66.00,-1.771
29.48,65.85,-1.776
29.48,65.71,-1.780
29.48,65.56,-1.784
29.48,65.42,-1.787
29.49,65.27,-1.790
29.49,65.12,-1.792
29.49,64.98,-1.796
29.50,64.83,-1.800
29.50,64.68,-1.803
29.51,64.54,-1.805
29.51,64.39,-1.809
29.51,64.24,-1.813
29.52,64.10,-1.817
29.52,63.95,-1.821
29.52,63.80,-1.823
29.53,63.66,-1.825
29.53,63.51,-1.828
29.53,63.36,-1.830
29.53,63.22,-1.831
29.54,63.07,-1.832
29.54,62.92,-1.834
29.54,62.77,-1.837
29.55,62.63,-1.839
29.55,62.48,-1.840
29.56,62.33,-1.841
29.56,62.19,-1.843
29.56,62.04,-1.846
29.57,61.89,-1.848
29.57,61.75,-1.849
29.57,61.60,-1.850
29.58,61.45,-1.853
29.58,61.30,-1.855
29.58,61.16,-1.857
29.58,61.01,-1.858
29.59,60.86,-1.858
29.59,60.71,-1.859
29.59,60.57,-1.860
29.60,60.42,-1.861
29.60,60.27,-1.862
29.61,60.13,-1.862
29.61,59.98,-1.863
29.61,59.83,-1.864
29.62,59.69,-1.865
29.62,59.54,-1.866
29.62,59.39,-1.866
29.63,59.24,-1.867
29.63,59.10,-1.867
29.63,58.95,-1.868
29.63,58.80,-1.870
29.64,58.66,-1.872
29.64,58.51,-1.873
29.64,58.36,-1.873
29.65,58.22,-1.873
29.65,58.07,-1.873
29.66,57.92,-1.872
29.66,57.78,-1.872
29.66,57.63,-1.872
29.67,57.48,-1.873
29.67,57.34,-1.873
29.67,57.19,-1.873
29.68,57.05,-1.873
29.68,56.90,-1.872
29.68,56.75,-1.872
29.68,56.61,-1.872
29.69,56.46,-1.872
29.69,56.32,-1.872
29.69,56.17,-1.873
29.70,56.02,-1.873
29.70,55.88,-1.873
29.71,55.73,-1.873
29.71,55.58,-1.873
29.71,55.44,-1.873
29.72,55.29,-1.874
29.72,55.15,-1.874
29.72,55.00,-1.874
29.73,54.86,-1.873
29.73,54.71,-1.873
29.73,54.57,-1.872
29.73,54.42,-1.871
29.74,54.28,-1.871
29.74,54.13,-1.871
29.74,53.99,-1.871
29.75,53.84,-1.871
29.75,53.70,-1.870
29.76,53.55,-1.870
29.76,53.41,-1.869
29.76,53.26,-1.869
29.77,53.12,-1.869
29.77,52.97,-1.869
29.77,52.83,-1.869
29.78,52.68,-1.869
29.78,52.54,-1.868
29.78,52.40,-1.867
29.78,52.25,-1.866
29.79,52.11,-1.865
29.79,51.97,-1.864
29.79,51.82,-1.863
29.80,51.68,-1.862
29.80,51.53,-1.861
29.81,51.39,-1.859
29.81,51.25,-1.858
29.81,51.10,-1.857
29.82,50.96,-1.856
29.82,50.82,-1.855
29.82,50.67,-1.854
29.83,50.53,-1.853
29.83,50.39,-1.852
29.83,50.24,-1.851
29.83,50.10,-1.850
29.84,49.96,-1.850
29.84,49.82,-1.849
29.84,49.67,-1.849
29.85,49.53,-1.848
29.85,49.39,-1.847
29.86,49.25,-1.845
29.86,49.10,-1.844
29.86,48.96,-1.843
29.87,48.82,-1.843
29.87,48.68,-1.842
29.87,48.53,-1.840
29.88,48.39,-1.838
29.88,48.25,-1.836
29.88,48.11,-1.835
29.88,47.97,-1.834
29.89,47.83,-1.832
29.89,47.69,-1.831
29.89,47.54,-1.829
29.90,47.40,-1.828
29.90,47.26,-1.827
29.91,47.12,-1.826
29.91,46.98,-1.825
29.91,46.84,-1.824
29.92,46.70,-1.824
29.92,46.56,-1.824
29.92,46.42,-1.823
29.93,46.28,-1.822
29.93,46.14,-1.821
29.93,46.00,-1.819
29.93,45.86,-1.815
29.94,45.72,-1.813
29.94,45.58,-1.811
29.94,45.43,-1.810
29.95,45.30,-1.809
29.95,45.16,-1.809
29.96,45.02,-1.807
29.96,44.88,-1.806
29.96,44.74,-1.805
29.97,44.60,-1.803
29.97,44.46,-1.802
29.97,44.32,-1.800
29.98,44.18,-1.799
29.98,44.04,-1.798
29.98,43.90,-1.796
29.98,43.77,-1.794
29.99,43.63,-1.792
29.99,43.49,-1.791
29.99,43.35,-1.790
30.00,43.21,-1.790
30.00,43.07,-1.789
30.01,42.93,-1.788
30.01,42.80,-1.788
30.01,42.66,-1.787
30.02,42.52,-1.785
30.02,42.39,-1.782
30.02,42.25,-1.780
30.03,42.11,-1.778
30.03,41.97,-1.778
30.03,41.84,-1.776
30.03,41.70,-1.774
30.04,41.56,-1.772
30.04,41.42,-1.770
30.04,41.29,-1.769
30.05,41.15,-1.768
30.05,41.01,-1.766
30.06,40.88,-1.764
30.06,40.74,-1.762
30.06,40.60,-1.761
30.07,40.47,-1.759
30.07,40.33,-1.757
30.07,40.20,-1.756
30.08,40.06,-1.754
30.08,39.92,-1.753
30.08,39.79,-1.752
30.08,39.65,-1.751
30.09,39.52,-1.751
30.09,39.38,-1.750
30.09,39.25,-1.749
30.10,39.11,-1.749
30.10,38.98,-1.748
30.11,38.84,-1.746
30.11,38.71,-1.743
30.11,38.57,-1.742
30.12,38.44,-1.739
30.12,38.31,-1.737
30.12,38.17,-1.734
30.13,38.04,-1.732
30.13,37.90,-1.730
30.13,37.77,-1.730
30.13,37.63,-1.728
30.14,37.50,-1.727
30.14,37.37,-1.726
30.14,37.23,-1.723
30.15,37.10,-1.722
30.15,36.97,-1.720
30.16,36.83,-1.718
30.16,36.70,-1.717
30.16,36.57,-1.716
30.17,36.43,-1.714
30.17,36.30,-1.713
30.17,36.17,-1.711
30.18,36.03,-1.709
30.18,35.90,-1.707
30.18,35.77,-1.705
30.18,35.64,-1.705
30.19,35.50,-1.704
30.19,35.37,-1.703
30.19,35.24,-1.702
30.20,35.11,-1.701
30.20,34.98,-1.700
30.21,34.84,-1.699
30.21,34.71,-1.697
30.21,34.58,-1.695
30.22,34.45,-1.693
30.22,34.32,-1.691
30.22,34.19,-1.689
30.23,34.06,-1.686
30.23,33.93,-1.684
30.23,33.80,-1.682
30.23,33.66,-1.681
30.24,33.53,-1.680
30.24,33.40,-1.678
30.24,33.27,-1.675
30.25,33.14,-1.674
30.25,33.01,-1.673
30.26,32.88,-1.672
30.26,32.75,-1.670
30.26,32.62,-1.668
30.27,32.49,-1.666
30.27,32.36,-1.665
30.27,32.23,-1.662
30.28,32.10,-1.660
30.28,31.98,-1.659
30.28,31.85,-1.658
30.28,31.72,-1.657
30.29,31.59,-1.655
30.29,31.46,-1.653
30.29,31.33,-1.651
30.30,31.20,-1.649
30.30,31.07,-1.648
30.31,30.94,-1.646
30.31,30.82,-1.646
30.31,30.69,-1.646
30.32,30.56,-1.646
30.32,30.43,-1.645
30.32,30.30,-1.643
30.33,30.17,-1.639
30.33,30.05,-1.637
30.33,29.92,-1.635
30.33,29.79,-1.633
30.34,29.67,-1.630
30.34,29.54,-1.628
30.34,29.41,-1.627
30.35,29.28,-1.625
30.35,29.16,-1.622
30.36,29.03,-1.621
30.36,28.90,-1.619
30.36,28.78,-1.617
30.37,28.65,-1.616
30.37,28.52,-1.614
30.37,28.40,-1.613
30.38,28.27,-1.612
30.38,28.15,-1.609
30.38,28.02,-1.607
30.38,27.89,-1.607
30.39,27.77,-1.606
30.39,27.64,-1.604
30.39,27.52,-1.602
30.40,27.39,-1.599
30.40,27.27,-1.598
30.41,27.14,-1.596
30.41,27.02,-1.594
30.41,26.89,-1.592
30.42,26.77,-1.591
30.42,26.64,-1.590
30.42,26.52,-1.588
30.43,26.39,-1.585
30.43,26.27,-1.584
30.43,26.14,-1.583
30.43,26.02,-1.583
30.44,25.89,-1.584
30.44,25.77,-1.583
30.44,25.65,-1.581
30.45,25.52,-1.578
30.45,25.40,-1.576
30.46,25.28,-1.573
30.46,25.15,-1.571
30.46,25.03,-1.568
30.47,24.91,-1.566
30.47,24.78,-1.565
30.47,24.66,-1.564
30.48,24.54,-1.563
30.48,24.41,-1.561
30.48,24.29,-1.558
30.48,24.17,-1.556
30.49,24.04,-1.554
30.49,23.92,-1.552
30.49,23.80,-1.552
30.50,23.68,-1.549
30.50,23.56,-1.548
30.51,23.44,-1.546
30.51,23.31,-1.544
30.51,23.19,-1.543
30.52,23.07,-1.542
[...]
67.23,-13.83,-0.014
67.25,-13.76,0.000
67.26,-13.68,0.015
67.28,-13.61,0.026
67.30,-13.53,0.036
67.31,-13.45,0.045
67.33,-13.37,0.053
67.35,-13.30,0.060
67.36,-13.22,0.066
67.38,-13.14,0.069
67.40,-13.06,0.073
67.41,-12.97,0.077
67.43,-12.90,0.081
67.45,-12.81,0.084
67.46,-12.73,0.084
67.48,-12.65,0.087
67.50,-12.57,0.088
67.51,-12.49,0.090
67.53,-12.40,0.091
67.55,-12.32,0.092
67.56,-12.24,0.093
67.58,-12.16,0.093
67.60,-12.07,0.094
67.61,-11.99,0.095
67.63,-11.91,0.095
67.65,-11.82,0.095
67.66,-11.74,0.096
67.68,-11.66,0.097
67.70,-11.58,0.097
67.71,-11.49,0.097
67.73,-11.41,0.097
67.75,-11.32,0.098
67.76,-11.24,0.098
67.78,-11.16,0.098
67.80,-11.07,0.099
67.81,-10.99,0.099
67.83,-10.91,0.099
67.85,-10.83,0.100
67.86,-10.74,0.100
67.88,-10.66,0.100
67.90,-10.58,0.100
67.91,-10.49,0.101
67.93,-10.41,0.101
67.95,-10.32,0.101
67.96,-10.24,0.101
67.98,-10.16,0.101
68.00,-10.08,0.102
68.01,-9.99,0.102
68.03,-9.91,0.102
68.05,-9.83,0.102
68.06,-9.74,0.102
68.08,-9.66,0.103
68.10,-9.58,0.103
68.11,-9.49,0.103
68.13,-9.41,0.103
68.15,-9.33,0.103
68.16,-9.24,0.103
68.18,-9.16,0.104
68.20,-9.08,0.104
68.21,-8.99,0.104
68.23,-8.91,0.104
68.25,-8.83,0.104
68.26,-8.74,0.104
68.28,-8.66,0.104
68.30,-8.58,0.104
68.31,-8.49,0.105
68.33,-8.41,0.105
68.35,-8.33,0.105
68.36,-8.24,0.105
68.38,-8.16,0.105
68.40,-8.08,0.105
68.41,-7.99,0.105
68.43,-7.91,0.105
68.45,-7.83,0.105
68.46,-7.74,0.105
68.48,-7.66,0.105
68.50,-7.58,0.106
68.51,-7.49,0.106
68.53,-7.41,0.106
68.55,-7.33,0.106
68.56,-7.24,0.106
68.58,-7.16,0.106
68.60,-7.08,0.106
68.61,-6.99,0.106
68.63,-6.91,0.106
68.65,-6.83,0.106
68.66,-6.74,0.106
68.68,-6.66,0.106
68.70,-6.57,0.107
68.71,-6.49,0.107
68.73,-6.41,0.107
68.75,-6.33,0.107
68.76,-6.24,0.107
68.78,-6.16,0.107
68.80,-6.07,0.107
68.81,-5.99,0.107
68.83,-5.91,0.107
68.85,-5.83,0.107
68.86,-5.74,0.107
68.88,-5.66,0.107
68.90,-5.57,0.107
68.91,-5.49,0.107
68.93,-5.41,0.107
68.95,-5.32,0.107
68.96,-5.24,0.107
68.98,-5.16,0.107
69.00,-5.07,0.107
69.01,-4.99,0.108
69.03,-4.91,0.108
69.05,-4.82,0.108
69.06,-4.74,0.108
69.08,-4.66,0.108
69.10,-4.57,0.108
69.11,-4.49,0.108
69.13,-4.41,0.108
69.15,-4.32,0.108
69.16,-4.24,0.108
69.18,-4.16,0.108
69.20,-4.07,0.108
69.21,-3.99,0.108
69.23,-3.91,0.108
69.25,-3.82,0.108
69.26,-3.74,0.108
69.28,-3.66,0.108
69.30,-3.57,0.108
69.31,-3.49,0.108
69.33,-3.41,0.108
69.35,-3.32,0.109
69.36,-3.24,0.109
69.38,-3.16,0.109
69.40,-3.07,0.109
69.41,-2.99,0.109
69.43,-2.91,0.109
69.45,-2.82,0.109
69.46,-2.74,0.109
69.48,-2.66,0.109
69.50,-2.57,0.109
69.51,-2.49,0.109
69.53,-2.41,0.109
69.55,-2.32,0.109
69.56,-2.24,0.109
69.58,-2.16,0.109
69.60,-2.07,0.109
69.61,-1.99,0.109
69.63,-1.91,0.109
69.65,-1.82,0.109
69.66,-1.74,0.109
69.68,-1.66,0.109
69.70,-1.57,0.109
69.71,-1.49,0.109
69.73,-1.40,0.109
69.75,-1.32,0.109
69.76,-1.24,0.109
69.78,-1.16,0.110
69.80,-1.07,0.110
69.81,-0.99,0.110
69.83,-0.90,0.110
69.85,-0.82,0.110
69.86,-0.74,0.110
69.88,-0.65,0.110
69.90,-0.57,0.110
69.91,-0.49,0.110
69.93,-0.40,0.110
69.95,-0.32,0.110
69.96,-0.24,0.110
69.98,-0.15,0.110
70.00,-0.07,0.110
70.01,0.01,0.110
70.03,0.10,0.110
70.05,0.18,0.110
70.06,0.26,0.110
70.08,0.35,0.110
70.10,0.43,0.110
70.11,0.51,0.110
70.13,0.60,0.110
70.15,0.68,0.110
70.16,0.76,0.111
70.18,0.85,0.111
70.20,0.93,0.111
70.21,1.01,0.111
70.23,1.10,0.111
70.25,1.18,0.111
70.26,1.26,0.111
70.28,1.35,0.111
70.30,1.43,0.111
70.31,1.51,0.111
70.33,1.60,0.111
70.35,1.68,0.111
70.36,1.76,0.111
70.38,1.85,0.111
70.40,1.93,0.111
70.41,2.02,0.111
70.43,2.10,0.111
70.45,2.18,0.111
70.46,2.26,0.111
70.48,2.35,0.111
70.50,2.43,0.111
70.51,2.51,0.111
70.53,2.60,0.111
70.55,2.68,0.111
70.56,2.76,0.111
70.58,2.85,0.112
70.60,2.93,0.112
70.61,3.02,0.112
70.63,3.10,0.112
70.65,3.18,0.112
70.66,3.26,0.112
70.68,3.35,0.112
70.70,3.43,0.112
70.71,3.51,0.112
70.73,3.60,0.112
70.75,3.68,0.112
70.76,3.76,0.112
70.78,3.85,0.112
70.80,3.93,0.112
70.81,4.02,0.112
70.83,4.10,0.112
70.85,4.18,0.112
70.86,4.26,0.112
70.88,4.35,0.112
70.90,4.43,0.112
70.91,4.51,0.112
70.93,4.60,0.112
70.95,4.68,0.112
70.96,4.76,0.113
70.98,4.85,0.113
71.00,4.93,0.113
71.01,5.02,0.113
71.03,5.10,0.113
71.05,5.18,0.113
71.06,5.27,0.113
71.08,5.35,0.113
71.10,5.43,0.113
71.11,5.52,0.113
71.13,5.60,0.113
71.15,5.68,0.113
71.16,5.77,0.113
71.18,5.85,0.113
71.20,5.93,0.113
71.21,6.02,0.113
71.23,6.10,0.113
71.25,6.18,0.113
71.26,6.27,0.113
71.28,6.35,0.113
71.30,6.43,0.114
71.31,6.52,0.114
71.33,6.60,0.114
71.35,6.69,0.114
71.36,6.77,0.114
71.38,6.85,0.114
71.40,6.93,0.114
71.41,7.02,0.114
71.43,7.10,0.114
71.45,7.18,0.114
71.46,7.27,0.114
71.48,7.35,0.114
71.50,7.43,0.114
71.51,7.52,0.114
71.53,7.60,0.114
71.55,7.68,0.114
71.56,7.77,0.114
71.58,7.85,0.114
71.60,7.93,0.114
71.61,8.02,0.114
71.63,8.10,0.114
71.65,8.19,0.114
71.66,8.27,0.114
71.68,8.35,0.114
71.70,8.43,0.114
71.71,8.52,0.114
71.73,8.60,0.114
71.75,8.68,0.115
71.76,8.77,0.115
71.78,8.85,0.115
71.80,8.93,0.115
71.81,9.02,0.115
71.83,9.10,0.115
71.85,9.18,0.115
71.86,9.27,0.115
71.88,9.35,0.115
71.90,9.43,0.115
71.91,9.52,0.115
71.93,9.60,0.115
71.95,9.68,0.115
71.96,9.77,0.115
71.98,9.85,0.115
72.00,9.93,0.115
72.01,10.02,0.115
72.03,10.10,0.115
72.05,10.19,0.115
72.06,10.27,0.115
72.08,10.35,0.115
72.10,10.44,0.115
72.11,10.52,0.116
72.13,10.60,0.116
72.15,10.69,0.116
72.16,10.77,0.116
72.18,10.85,0.116
72.20,10.94,0.116
72.21,11.02,0.116
72.23,11.10,0.116
72.25,11.19,0.116
72.26,11.27,0.116
72.28,11.35,0.116
72.30,11.44,0.116
72.31,11.52,0.116
72.33,11.60,0.116
72.35,11.69,0.116
72.36,11.77,0.116
72.38,11.85,0.116
72.40,11.94,0.116
72.41,12.02,0.116
72.43,12.10,0.116
72.45,12.19,0.117
72.46,12.27,0.117
72.48,12.35,0.117
72.50,12.44,0.117
72.51,12.52,0.117
72.53,12.60,0.117
72.55,12.69,0.117
72.56,12.77,0.117
72.58,12.85,0.117
72.60,12.94,0.117
72.61,13.02,0.117
72.63,13.10,0.117
72.65,13.19,0.117
72.66,13.27,0.117
72.68,13.35,0.117
72.70,13.44,0.117
72.71,13.52,0.117
72.73,13.60,0.117
72.75,13.69,0.117
72.76,13.77,0.117
72.78,13.85,0.117
72.80,13.94,0.118
72.81,14.02,0.118
72.83,14.10,0.118
72.85,14.19,0.118
72.86,14.27,0.118
72.88,14.35,0.118
72.90,14.44,0.118
72.91,14.52,0.118
72.93,14.60,0.118
72.95,14.69,0.118
72.96,14.77,0.118
72.98,14.86,0.118
73.00,14.94,0.118
73.01,15.02,0.118
73.03,15.11,0.118
73.05,15.19,0.118
73.06,15.27,0.118
73.08,15.36,0.118
73.10,15.44,0.118
73.11,15.52,0.118
73.13,15.61,0.118
73.15,15.69,0.118
73.16,15.77,0.119
73.18,15.86,0.119
73.20,15.94,0.119
73.21,16.02,0.119
73.23,16.11,0.119
73.25,16.19,0.119
73.26,16.27,0.119
73.28,16.36,0.119
73.30,16.44,0.119
73.31,16.52,0.119
73.33,16.61,0.119
73.35,16.69,0.119
73.36,16.77,0.119
73.38,16.86,0.119
73.40,16.94,0.119
73.41,17.02,0.119
73.43,17.11,0.119
73.45,17.19,0.119
73.46,17.27,0.119
73.48,17.36,0.119
73.50,17.44,0.119
73.51,17.52,0.119
73.53,17.61,0.119
73.55,17.69,0.119
73.56,17.77,0.119
73.58,17.86,0.119
73.60,17.94,0.119
73.61,18.02,0.119
73.63,18.11,0.120
73.65,18.19,0.120
73.66,18.27,0.120
73.68,18.36,0.120
73.70,18.44,0.120
73.71,18.52,0.120
73.73,18.61,0.120
73.75,18.69,0.120
73.76,18.78,0.120
73.78,18.86,0.120
73.80,18.94,0.120
73.81,19.02,0.120
73.83,19.11,0.120
73.85,19.19,0.120
73.86,19.27,0.120
73.88,19.36,0.120
73.90,19.44,0.120
73.91,19.53,0.120
73.93,19.61,0.120
73.95,19.69,0.120
73.96,19.78,0.120
73.98,19.86,0.120
74.00,19.94,0.120
74.01,20.03,0.119
74.03,20.11,0.119
74.05,20.19,0.119
74.06,20.28,0.119
74.08,20.36,0.119
74.10,20.44,0.119
74.11,20.53,0.119
74.13,20.61,0.119
74.15,20.69,0.119
74.16,20.78,0.119
74.18,20.86,0.119
74.20,20.94,0.119
74.21,21.03,0.119
74.23,21.11,0.119
74.25,21.19,0.119
74.26,21.28,0.118
74.28,21.36,0.118
74.30,21.44,0.118
74.31,21.53,0.118
74.33,21.61,0.118
74.35,21.69,0.118
74.36,21.78,0.118
74.38,21.86,0.117
74.40,21.94,0.117
74.41,22.03,0.117
74.43,22.11,0.117
74.45,22.19,0.117
74.46,22.28,0.116
74.48,22.36,0.116
74.50,22.45,0.116
74.51,22.53,0.115
74.53,22.61,0.115
74.55,22.70,0.115
74.56,22.78,0.114
74.58,22.86,0.114
74.60,22.95,0.114
74.61,23.03,0.113
74.63,23.11,0.113
74.65,23.20,0.112
74.66,23.28,0.112
74.68,23.37,0.111
74.70,23.45,0.110
74.71,23.53,0.109
74.73,23.62,0.108
74.75,23.70,0.108
74.76,23.78,0.107
74.78,23.87,0.106
74.80,23.95,0.105
74.81,24.04,0.104
74.83,24.12,0.102
74.85,24.20,0.101
74.86,24.29,0.100
74.88,24.37,0.098
74.90,24.45,0.097
74.91,24.54,0.096
74.93,24.62,0.095
74.95,24.71,0.092
74.96,24.79,0.091
74.98,24.87,0.090
75.00,24.96,0.089
75.01,25.04,0.088
75.03,25.13,0.087
75.05,25.21,0.086
75.06,25.29,0.084
75.08,25.38,0.083
75.10,25.46,0.082
75.11,25.54,0.081
75.13,25.63,0.080
75.15,25.71,0.080
75.16,25.80,0.079
75.18,25.88,0.079
75.20,25.96,0.078
75.21,26.05,0.078
75.23,26.13,0.077
75.25,26.21,0.077
75.26,26.30,0.077
75.28,26.38,0.076
75.30,26.47,0.076
75.31,26.55,0.076
75.33,26.63,0.076
75.35,26.71,0.076
75.36,26.80,0.076
75.38,26.88,0.076
75.40,26.96,0.076
75.41,27.05,0.077
75.43,27.13,0.077
75.45,27.21,0.079
75.46,27.30,0.080
75.48,27.38,0.081
75.50,27.46,0.084
75.51,27.54,0.085
75.53,27.63,0.087
75.55,27.71,0.089
75.56,27.79,0.091
75.58,27.87,0.094
75.60,27.96,0.096
75.61,28.04,0.097
75.63,28.12,0.099
75.65,28.21,0.101
75.66,28.29,0.103
75.68,28.37,0.106
75.70,28.45,0.108
75.71,28.54,0.110
75.73,28.62,0.112
75.75,28.70,0.114
75.76,28.78,0.115
75.78,28.87,0.118
75.80,28.95,0.120
75.81,29.03,0.121
75.83,29.11,0.123
75.85,29.20,0.124
75.86,29.28,0.126
75.88,29.36,0.128
75.90,29.44,0.130
75.91,29.53,0.132
75.93,29.61,0.133
75.95,29.69,0.134
75.96,29.78,0.135
75.98,29.86,0.137
76.00,29.94,0.139
76.01,30.02,0.141
76.03,30.11,0.142
76.05,30.19,0.144
76.06,30.27,0.145
76.08,30.36,0.148
76.10,30.44,0.150
76.11,30.52,0.152
76.13,30.60,0.155
76.15,30.69,0.156
76.16,30.77,0.158
76.18,30.85,0.162
76.20,30.93,0.164
76.21,31.02,0.166
76.23,31.10,0.168
76.25,31.18,0.172
76.26,31.26,0.175
76.28,31.35,0.178
76.30,31.43,0.182
76.31,31.51,0.185
76.33,31.59,0.187
76.35,31.68,0.190
76.36,31.76,0.194
76.38,31.84,0.197
76.40,31.92,0.201
76.41,32.00,0.205
76.43,32.09,0.208
76.45,32.17,0.213
76.46,32.25,0.216
76.48,32.33,0.220
76.50,32.41,0.224
76.51,32.50,0.229
76.53,32.58,0.234
76.55,32.66,0.238
76.56,32.74,0.243
76.58,32.82,0.247
76.60,32.90,0.253
76.61,32.99,0.256
76.63,33.07,0.264
76.65,33.15,0.269
76.66,33.23,0.277
76.68,33.31,0.282
76.70,33.39,0.289
76.71,33.47,0.297
76.73,33.56,0.303
76.75,33.64,0.312
76.76,33.72,0.320
76.78,33.80,0.328
76.80,33.88,0.338
76.81,33.96,0.349
76.83,34.04,0.358
76.85,34.12,0.369
76.86,34.20,0.380
76.88,34.28,0.393
76.90,34.36,0.406
76.91,34.43,0.420
76.93,34.51,0.433
76.95,34.59,0.449
76.96,34.67,0.466
76.98,34.75,0.483
77.00,34.82,0.500
77.01,34.90,0.521
77.03,34.98,0.539
77.05,35.06,0.562
77.06,35.13,0.585
77.08,35.21,0.609
77.10,35.28,0.633
77.11,35.36,0.661
77.13,35.43,0.690
77.15,35.50,0.718
77.16,35.58,0.749
77.18,35.65,0.783
77.20,35.72,0.817
77.21,35.79,0.854
77.23,35.86,0.892
77.25,35.93,0.932
77.26,36.00,0.972
77.28,36.07,1.016
77.30,36.14,1.062
77.31,36.21,1.109
77.33,36.27,1.158
77.35,36.34,1.207
77.36,36.40,1.257
77.38,36.47,1.312
77.40,36.54,1.369
77.41,36.60,1.421
77.43,36.66,1.475
77.45,36.73,1.530
77.46,36.79,1.580
77.48,36.85,1.626
77.50,36.92,1.666
77.51,36.98,1.699
77.53,37.05,1.714
77.55,37.13,1.708
77.56,37.21,1.663
77.58,37.30,1.550
77.60,37.40,1.315
77.61,37.54,0.849
77.63,37.74,0.012
77.65,38.03,-1.206
77.66,38.40,-2.618
77.68,38.84,-3.922
77.70,39.28,-4.751
77.71,39.67,-5.007
77.73,39.97,-4.850
77.75,40.18,-4.488
77.76,40.30,-4.055
77.78,40.37,-3.620
77.80,40.40,-3.210
77.81,40.40,-2.835
77.83,40.39,-2.498
77.85,40.37,-2.197
77.86,40.35,-1.930
77.88,40.34,-1.692
77.90,40.33,-1.482
77.91,40.32,-1.294
77.93,40.32,-1.131
77.95,40.33,-0.984
77.96,40.35,-0.857
77.98,40.37,-0.744
78.00,40.40,-0.643
78.01,40.43,-0.555
78.03,40.47,-0.478
78.05,40.52,-0.409
78.06,40.56,-0.348
78.08,40.62,-0.294
78.10,40.67,-0.247
78.11,40.73,-0.206
78.13,40.79,-0.168
78.15,40.86,-0.136
78.16,40.92,-0.106
78.18,40.99,-0.081
78.20,41.06,-0.058
78.21,41.13,-0.038
78.23,41.21,-0.019
78.25,41.28,-0.004
78.26,41.36,0.010
78.28,41.43,0.023
78.30,41.51,0.033
78.31,41.58,0.044
78.33,41.66,0.052
78.35,41.74,0.062
78.36,41.82,0.068
78.38,41.90,0.074
78.40,41.98,0.082
78.41,42.06,0.085
78.43,42.14,0.091
78.45,42.22,0.094
78.46,42.30,0.099
78.48,42.39,0.103
78.50,42.47,0.106
78.51,42.55,0.108
78.53,42.63,0.111
78.55,42.71,0.115
78.56,42.80,0.116
78.58,42.88,0.120
78.60,42.96,0.121
78.61,43.04,0.123
78.63,43.13,0.126
78.65,43.21,0.127
78.66,43.29,0.129
78.68,43.37,0.131
78.70,43.46,0.132
78.71,43.54,0.134
78.73,43.62,0.136
78.75,43.70,0.138
78.76,43.79,0.139
78.78,43.87,0.141
78.80,43.95,0.143
78.81,44.03,0.145
78.83,44.12,0.146
78.85,44.20,0.148
78.86,44.28,0.150
78.88,44.36,0.153
78.90,44.45,0.154
78.91,44.53,0.157
78.93,44.61,0.159
78.95,44.70,0.160
78.96,44.78,0.163
78.98,44.86,0.165
79.00,44.94,0.169
79.01,45.02,0.171
79.03,45.11,0.174
79.05,45.19,0.176
79.06,45.27,0.178
79.08,45.36,0.182
79.10,45.44,0.185
79.11,45.52,0.189
79.13,45.60,0.191
79.15,45.68,0.196
79.16,45.77,0.198
79.18,45.85,0.203
79.20,45.93,0.207
79.21,46.01,0.212
79.23,46.09,0.216
79.25,46.18,0.221
79.26,46.26,0.225
79.28,46.34,0.231
79.30,46.42,0.235
79.31,46.50,0.242
79.33,46.59,0.248
79.35,46.67,0.254
79.36,46.75,0.261
79.38,46.83,0.268
79.40,46.91,0.275
79.41,46.99,0.284
79.43,47.07,0.292
79.45,47.15,0.301
79.46,47.24,0.311
79.48,47.32,0.319
79.50,47.39,0.331
79.51,47.47,0.340
79.53,47.55,0.352
79.55,47.64,0.365
79.56,47.71,0.376
79.58,47.79,0.389
79.60,47.87,0.403
79.61,47.95,0.418
79.63,48.03,0.433
79.65,48.11,0.451
79.66,48.18,0.468
79.68,48.26,0.485
79.70,48.34,0.504
79.71,48.42,0.525
79.73,48.49,0.547
79.75,48.57,0.571
79.76,48.65,0.593
79.78,48.72,0.619
79.80,48.79,0.645
79.81,48.87,0.671
79.83,48.94,0.701
79.85,49.02,0.732
79.86,49.09,0.765
79.88,49.16,0.798
79.90,49.23,0.833
79.91,49.31,0.868
79.93,49.37,0.907
79.95,49.45,0.945
79.96,49.52,0.987
79.98,49.59,1.030
80.00,49.65,1.075
80.01,49.72,1.123
80.03,49.79,1.171
80.05,49.86,1.219
80.06,49.92,1.269
80.08,49.99,1.328
80.10,50.05,1.384
80.11,50.11,1.436
80.13,50.18,1.497
80.15,50.24,1.559
80.16,50.30,1.622
80.18,50.37,1.687
80.20,50.43,1.754
80.21,50.48,1.823
80.23,50.54,1.893
80.25,50.60,1.966
80.26,50.66,2.040
80.28,50.72,2.115
80.30,50.77,2.205
80.31,50.83,2.279
80.33,50.88,2.356
80.35,50.94,2.437
80.36,50.99,2.517
80.38,51.05,2.597
80.40,51.10,2.677
80.41,51.16,2.756
80.43,51.21,2.831
80.45,51.27,2.893
80.46,51.32,2.942
80.48,51.38,2.966
80.50,51.45,2.953
80.51,51.53,2.910
80.53,51.61,2.846
80.55,51.70,2.777
80.56,51.80,2.700
80.58,51.90,2.614
80.60,52.01,2.516
80.61,52.12,2.401
80.63,52.24,2.265
80.65,52.36,2.096
80.66,52.50,1.861
80.68,52.65,1.545
80.70,52.81,1.230
80.71,52.98,1.015
80.73,53.14,0.882
80.75,53.29,0.781
80.76,53.43,0.690
80.78,53.56,0.615
80.80,53.69,0.556
80.81,53.81,0.502
80.83,53.93,0.454
80.85,54.04,0.414
80.86,54.14,0.381
80.88,54.24,0.351
80.90,54.35,0.325
80.91,54.44,0.304
80.93,54.54,0.286
80.95,54.63,0.270
80.96,54.72,0.257
80.98,54.82,0.245
81.00,54.91,0.234
81.01,54.99,0.225
81.03,55.08,0.217
81.05,55.17,0.212
81.06,55.26,0.207
81.08,55.34,0.202
81.10,55.43,0.199
81.11,55.52,0.195
81.13,55.60,0.193
81.15,55.69,0.190
81.16,55.77,0.188
81.18,55.86,0.186
81.20,55.94,0.185
81.21,56.02,0.184
81.23,56.11,0.183
81.25,56.19,0.182
81.26,56.28,0.182
81.28,56.36,0.181
81.30,56.44,0.181
81.31,56.53,0.180
81.33,56.61,0.180
81.35,56.70,0.180
81.36,56.78,0.180
81.38,56.86,0.180
81.40,56.95,0.179
81.41,57.03,0.179
81.43,57.11,0.179
81.45,57.20,0.179
81.46,57.28,0.178
81.48,57.36,0.178
81.50,57.45,0.178
81.51,57.53,0.178
81.53,57.61,0.178
81.55,57.70,0.177
81.56,57.78,0.177
81.58,57.86,0.177
81.60,57.95,0.177
81.61,58.03,0.177
81.63,58.12,0.177
81.65,58.20,0.177
81.66,58.28,0.176
81.68,58.37,0.176
81.70,58.45,0.176
81.71,58.53,0.176
81.73,58.61,0.176
81.75,58.70,0.176
81.76,58.78,0.176
81.78,58.87,0.176
81.80,58.95,0.176
81.81,59.03,0.176
81.83,59.12,0.175
81.85,59.20,0.175
81.86,59.28,0.175
81.88,59.37,0.175
81.90,59.45,0.175
81.91,59.53,0.175
81.93,59.62,0.175
81.95,59.70,0.175
81.96,59.78,0.175
81.98,59.87,0.175
82.00,59.95,0.175
82.01,60.03,0.175
82.03,60.12,0.175
82.05,60.20,0.175
82.06,60.28,0.175
82.08,60.37,0.175
82.10,60.45,0.175
82.11,60.53,0.175
82.13,60.62,0.175
82.15,60.70,0.175
82.16,60.78,0.175
82.18,60.87,0.175
82.20,60.95,0.175
82.21,61.04,0.175
82.23,61.12,0.175
82.25,61.20,0.175
82.26,61.28,0.175
82.28,61.37,0.175
82.30,61.45,0.175
82.31,61.53,0.175
82.33,61.62,0.175
82.35,61.70,0.175
82.36,61.78,0.175
82.38,61.87,0.175
82.40,61.95,0.175
82.41,62.03,0.175
82.43,62.12,0.175
82.45,62.20,0.175
82.46,62.28,0.175
82.48,62.37,0.175
82.50,62.45,0.175
82.51,62.53,0.175
82.53,62.62,0.175
82.55,62.70,0.175
82.56,62.78,0.175
82.58,62.87,0.175
82.60,62.95,0.175
82.61,63.03,0.175
82.63,63.12,0.175
82.65,63.20,0.175
82.66,63.28,0.175
82.68,63.37,0.175
82.70,63.45,0.175
82.71,63.53,0.175
82.73,63.62,0.175
82.75,63.70,0.175
82.76,63.78,0.175
82.78,63.87,0.175
82.80,63.95,0.175
82.81,64.03,0.175
82.83,64.12,0.175
82.85,64.20,0.175
82.86,64.29,0.175
82.88,64.37,0.175
82.90,64.45,0.175
82.91,64.53,0.175
82.93,64.62,0.175
82.95,64.70,0.175
82.96,64.78,0.176
82.98,64.87,0.176
83.00,64.95,0.176
83.01,65.03,0.176
83.03,65.12,0.176
83.05,65.20,0.176
83.06,65.29,0.176
83.08,65.37,0.176
83.10,65.45,0.176
83.11,65.54,0.176
83.13,65.62,0.176
83.15,65.70,0.176
83.16,65.79,0.176
83.18,65.87,0.176
83.20,65.95,0.176
83.21,66.04,0.176
83.23,66.12,0.176
83.25,66.20,0.176
83.26,66.29,0.176
83.28,66.37,0.176
83.30,66.46,0.176
83.31,66.54,0.176
83.33,66.62,0.176
83.35,66.70,0.176
83.36,66.79,0.176
83.38,66.87,0.176
83.40,66.95,0.177
83.41,67.04,0.177
83.43,67.12,0.177
83.45,67.20,0.177
83.46,67.29,0.177
83.48,67.37,0.177
83.50,67.45,0.177
83.51,67.54,0.177
83.53,67.62,0.177
83.55,67.70,0.177
83.56,67.79,0.177
83.58,67.87,0.177
83.60,67.95,0.177
83.61,68.04,0.177
83.63,68.12,0.177
83.65,68.20,0.177
83.66,68.29,0.177
83.68,68.37,0.177
83.70,68.45,0.177
83.71,68.54,0.177
83.73,68.62,0.177
83.75,68.70,0.177
83.76,68.79,0.177
83.78,68.87,0.177
83.80,68.95,0.177
83.81,69.04,0.177
83.83,69.12,0.177
83.85,69.20,0.177
83.86,69.29,0.177
83.88,69.37,0.177
83.90,69.45,0.177
83.91,69.54,0.177
83.93,69.62,0.177
83.95,69.71,0.177
83.96,69.79,0.177
83.98,69.87,0.177
84.00,69.95,0.177
84.01,70.04,0.177
84.03,70.12,0.177
84.05,70.20,0.177
84.06,70.29,0.177
84.08,70.37,0.177
84.10,70.46,0.177
84.11,70.54,0.177
84.13,70.62,0.177
84.15,70.71,0.177
84.16,70.79,0.177
84.18,70.87,0.177
84.20,70.96,0.177
84.21,71.04,0.177
84.23,71.12,0.177
84.25,71.21,0.177
84.26,71.29,0.177
84.28,71.37,0.177
84.30,71.46,0.177
84.31,71.54,0.178
84.33,71.62,0.177
84.35,71.71,0.177
84.36,71.79,0.177
84.38,71.87,0.177
84.40,71.96,0.177
84.41,72.04,0.177
84.43,72.12,0.177
84.45,72.21,0.177
84.46,72.29,0.177
84.48,72.37,0.177
84.50,72.46,0.177
84.51,72.54,0.178
84.53,72.62,0.178
84.55,72.71,0.178
84.56,72.79,0.178
84.58,72.87,0.178
84.60,72.96,0.178
84.61,73.04,0.178
84.63,73.12,0.178
84.65,73.21,0.178
84.66,73.29,0.178
84.68,73.37,0.178
84.70,73.46,0.178
84.71,73.54,0.178
84.73,73.63,0.178
84.75,73.71,0.178
84.76,73.79,0.178
84.78,73.88,0.178
84.80,73.96,0.178
84.81,74.04,0.178
84.83,74.12,0.178
84.85,74.21,0.178
84.86,74.29,0.178
84.88,74.37,0.178
84.90,74.46,0.178
84.91,74.54,0.178
84.93,74.62,0.178
84.95,74.71,0.178
84.96,74.79,0.178
84.98,74.88,0.178
85.00,74.96,0.178
85.01,75.04,0.178
85.03,75.12,0.178
85.05,75.21,0.178
85.06,75.29,0.178
85.08,75.38,0.178
85.10,75.46,0.178
85.11,75.54,0.178
85.13,75.63,0.178
85.15,75.71,0.178
85.16,75.79,0.178
85.18,75.88,0.178
85.20,75.96,0.178
85.21,76.04,0.178
85.23,76.13,0.178
85.25,76.21,0.178
85.26,76.29,0.178
85.28,76.37,0.178
85.30,76.46,0.178
85.31,76.54,0.178
85.33,76.63,0.178
85.35,76.71,0.179
85.36,76.79,0.179
85.38,76.88,0.179
85.40,76.96,0.179
85.41,77.04,0.179
85.43,77.13,0.179
85.45,77.21,0.179
85.46,77.29,0.179
85.48,77.38,0.179
85.50,77.46,0.179
85.51,77.54,0.179
85.53,77.63,0.179
85.55,77.71,0.179
85.56,77.79,0.179
85.58,77.88,0.179
85.60,77.96,0.179
85.61,78.04,0.179
85.63,78.13,0.179
85.65,78.21,0.179
85.66,78.29,0.179
85.68,78.38,0.179
85.70,78.46,0.179
85.71,78.54,0.179
85.73,78.63,
85.75,78.71,
85.76,78.79,
85.78,,