File: DSC/2025_06_03_Felodipine2_0C_165C_10Cmin_x3.csv
Filename,2025_06_03_Felodipine2_0C_165C_10Cmin_x3
Instrument name,DSC2A-00468 (192.168.1.100)
Operator,Yarger
rundate,6/3/2025
Sample name,2025_06_03_Felodipine2_0C_165C_10Cmin_x3
proceduresegments,Data Off ; Equilibrate 0.00 °C; Data On ; Ramp 10.00 °C/min to 165.00 °C; Data Off ; Isothermal 1.0 min; Data On ; Ramp 10.00 °C/min to 0.00 °C; Data Off ; Isothermal 1.0 min; Data On ; Ramp 10.00 °C/min to 165.00 °C; Data Off ; Isothermal 1.0 min; Data On ; Ramp 10.00 °C/min to 0.00 °C; Data Off ; Isothermal 1.0 min; Data On ; Ramp 10.00 °C/min to 30.00 °C
[File Parameters]
Run date,6/3/2025 11:47:00 AM
Trios version,5.1.1.46572
Original File Name,
Current File Name,D:\DSC2500\JYarger\2025_06_03_Felodipine2_0C_165C_10Cmin_x3.tri
[Procedure]
Procedure Name,FEL_0C_165C_10Cmin_x3
Sample Name,2025_06_03_Felodipine2_0C_165C_10Cmin_x3
Sample Mass,10.19 mg
Reference Sample Mass,0 mg
Pan Mass,56.62 mg
Pan Number,21
Reference Pan Mass,56.96 mg
Reference Pan Number,10
Pan Type,Tzero Aluminum Hermetic
Comments,Al Hermetic DSC Consumables sealed Pan/Lid. A2 Tray (Google Sheet: DSC_Samples_A2_Tray_May2025)
Project Name,CA
Operator,Yarger
Test,Custom
Unload Max Temperature,30
Unload Min Temperature,30
Load Max Temperature,30
Load Min Temperature,30
Stop on Gas Flow Error,Yes
[Signal List]
Signal #1,Time (min)
Signal #2,Temperature (°C)
Signal #3,Heat Flow (mW)
Signal #4,Delta T (µV)
Signal #5,Delta Tzero (µV)
Signal #6,Tzero Temperature (°C)
Signal #7,Cell Purge (mL/min)
Signal #8,Heater Temp (°C)
Signal #9,Power Delivered (W)
Signal #10,Reference Junction Temperature (°C)
Signal #11,Flange Temperature (°C)
Signal #12,Heat Flow Phase (rad)
Signal #13,Total Heat Capacity (J/°C)
Signal #14,Heat Capacity (J/°C)
[Configuration]
Company Name,ASU
Instrument Name,DSC2A-00468
Instrument Type,DSC2500
Serial Number,DSC2A-00468
IP,192.168.1.100
Location of Instrument,MRRC
DisplayType,Unknown
Sample Interval ,0.1 s/pt
Selected Heat Flow,T4P
Exotherm Direction,Down
Cell Serial,DRC2-00792
Lid Type,Standard
Cooler,RCS 90
Leave Cooler on at End of Sequence,On
Gas 2,Nitrogen
Gas Selected,Channel 1
Flow Rate,50 mL/min
Secondary Purge,On
Licensed Heat Flow,Heat Flow T4P
Modulation Licensed,Yes
[Versions]
Common IDD Version,1
Cortex Version,VER 2.10.2.31
Driver,5.0.0.6
GDM Version,1.0.3.3
TouchscreenVersion,1.0.0.16145
FEP Version,1.2.1.21
FEP Bootloader,2.0.0.5
AutoSampler Version,2.1.1.26
Auto Sampler Bootloader,2.0.0.5
FCM Version,1.1.0.3
FCM Bootloader,2.0.0.5
[Experiment Logs]
Experiment Log Entry # 1,Data On set to 0
Experiment Log Entry # 3,Equilibrate Segment 0 (C) Started
Experiment Log Entry # 5,Air Cool is off.
Experiment Log Entry # 7,Data On set to 1
Experiment Log Entry # 9,Ramp Segment 10 C/min to 165 Started
Experiment Log Entry # 11,Data On set to 0
Experiment Log Entry # 13,Isothermal Segment 1 min started
Experiment Log Entry # 15,Data On set to 1
Experiment Log Entry # 17,Ramp Segment 10 C/min to 0 Started
Experiment Log Entry # 19,Data On set to 0
Experiment Log Entry # 21,Isothermal Segment 1 min started
Experiment Log Entry # 23,Data On set to 1
Experiment Log Entry # 25,Ramp Segment 10 C/min to 165 Started
Experiment Log Entry # 27,Data On set to 0
Experiment Log Entry # 29,Isothermal Segment 1 min started
Experiment Log Entry # 31,Data On set to 1
Experiment Log Entry # 33,Ramp Segment 10 C/min to 0 Started
Experiment Log Entry # 35,Data On set to 0
Experiment Log Entry # 37,Isothermal Segment 1 min started
Experiment Log Entry # 39,Data On set to 1
Experiment Log Entry # 41,Ramp Segment 10 C/min to 30 Started
[Method Log]
Method Log Entry # 1,Data Off
Method Log Entry # 2,Equilibrate 0 °C
Method Log Entry # 3,Data On
Method Log Entry # 4,(Ramp 843489) Ramp 10 °C/minute to 165 °C
Method Log Entry # 5,Data Off
Method Log Entry # 6,Isothermal 1 minutes
Method Log Entry # 7,Data On
Method Log Entry # 8,(Ramp 843493) Ramp 10 °C/minute to 0 °C
Method Log Entry # 9,Data Off
Method Log Entry # 10,Isothermal 1 minutes
Method Log Entry # 11,Data On
Method Log Entry # 12,(Ramp 843497) Ramp 10 °C/minute to 165 °C
Method Log Entry # 13,Data Off
Method Log Entry # 14,Isothermal 1 minutes
Method Log Entry # 15,Data On
Method Log Entry # 16,(Ramp 843501) Ramp 10 °C/minute to 0 °C
Method Log Entry # 17,Data Off
Method Log Entry # 18,Isothermal 1 minutes
Method Log Entry # 19,Data On
Method Log Entry # 20,(Ramp 843505) Ramp 10 °C/minute to 30 °C
Cell Serial,DRC2-00792
[T1 Calibration]
Slope,-0.008529666
Offset,9.636258
Initial Temperature,98.23
GUID,f8bfdadc-4977-4fdf-ba6d-0ba9134940c3
[TZero Calibration]
Date Applied,11/29/2022 4:06:13 PM
Description,From -89.059 °C to 396.009 °C at 20.000°C/min
Gas Type,Nitrogen
Pan Type,None
Source Files 1,C:\Users\yargerlab\Desktop\DSC Data\General\TZero_calibration_11_29_22_2nd(2).tri
Source Files 2,C:\Users\yargerlab\Desktop\DSC Data\General\TZero_calibration_11_29_22_2nd(3).tri
Delta T Offset,13.05235
Delta T Slope,-0.007271007
Delta T0 Offset,-13.69128
Delta T0 Slope,0.06063341
[Temperature Calibration]
Date Applied,11/29/2022 7:12:28 PM
Description,From 106.590 °C to 186.590 °C at 10.000°C/min
Gas Type,Nitrogen
Pan Type,Tzero Aluminum Hermetic
Source Files 1,C:\Users\yargerlab\Desktop\DSC Data\General\Indium(6).tri
Measured 1,157.391
Known 1,156.598
[Cell Constant Calibration]
Date Applied,11/29/2022 7:12:29 PM
Description,From 106.590 °C to 186.590 °C at 10.000°C/min
Gas Type,Nitrogen
Pan Type,Tzero Aluminum Hermetic
Source Files 1,C:\Users\yargerlab\Desktop\DSC Data\General\Indium(6).tri
T4P KCell,1.006051
Onset Slope,63.26126 mW/°C
[Direct Cp Calibration]
Date Applied,11/30/2022 11:04:51 AM
Description,From -79.983 °C to 298.409 °C at 10.000°C/min
Gas Type,Nitrogen
Pan Type,Tzero Aluminum Hermetic
Source Files 1,C:\Users\yargerlab\Desktop\DSC Data\General\Sapphire_Heat_Capacity_11_30_22.tri
[Rev Cp Calibration]
Date Applied,11/30/2022 1:58:51 PM
Description,From -79.996 °C to 292.812 °C at 3.000°C/min
Gas Type,Nitrogen
Pan Type,Tzero Aluminum Hermetic
Source Files 1,C:\Users\yargerlab\Desktop\DSC Data\General\Sapphire_MDSC_Calibration_11_30_22.tri
[step]
Ramp 10.00 °C/min to 165.00 °C
Time,Temperature,Heat Flow (Normalized)
min,°C,W/g
0.00,0.15,-0.043
0.01,0.14,-0.043
0.02,0.14,-0.041
0.03,0.14,-0.038
0.05,0.14,-0.036
0.06,0.14,-0.035
0.07,0.16,-0.034
0.08,0.17,-0.035
0.09,0.20,-0.036
0.11,0.23,-0.036
0.12,0.27,-0.036
0.13,0.32,-0.033
0.14,0.38,-0.023
0.15,0.44,-0.015
0.16,0.52,-0.004
0.18,0.59,0.007
0.19,0.67,0.018
0.20,0.75,0.030
0.21,0.83,0.040
0.22,0.92,0.050
0.23,1.01,0.059
0.24,1.10,0.067
0.26,1.19,0.074
0.27,1.28,0.082
0.28,1.38,0.088
0.29,1.48,0.094
0.30,1.58,0.100
0.31,1.68,0.105
0.33,1.78,0.110
0.34,1.88,0.115
0.35,1.99,0.120
0.36,2.09,0.124
0.37,2.20,0.127
0.39,2.31,0.132
0.40,2.41,0.135
0.41,2.52,0.138
0.42,2.63,0.140
0.43,2.74,0.143
0.44,2.85,0.145
0.45,2.96,0.147
0.47,3.07,0.149
0.48,3.18,0.151
0.49,3.29,0.154
0.50,3.40,0.154
0.51,3.52,0.155
0.53,3.63,0.157
0.54,3.74,0.158
0.55,3.85,0.159
0.56,3.96,0.160
0.57,4.08,0.161
0.58,4.19,0.162
0.60,4.30,0.163
0.61,4.42,0.163
0.62,4.53,0.164
0.63,4.65,0.165
0.64,4.76,0.165
0.65,4.87,0.166
0.67,4.99,0.166
0.68,5.10,0.166
0.69,5.22,0.167
0.70,5.33,0.168
0.71,5.45,0.168
0.72,5.56,0.168
0.73,5.68,0.169
0.75,5.79,0.169
0.76,5.91,0.170
0.77,6.02,0.170
0.78,6.14,0.170
0.79,6.25,0.170
0.80,6.37,0.170
0.82,6.48,0.171
0.83,6.60,0.171
0.84,6.71,0.171
0.85,6.83,0.171
0.86,6.95,0.171
0.88,7.06,0.172
0.89,7.18,0.172
0.90,7.29,0.172
0.91,7.41,0.172
0.92,7.52,0.172
0.93,7.64,0.172
0.95,7.76,0.173
0.96,7.87,0.173
0.97,7.99,0.173
0.98,8.10,0.173
0.99,8.22,0.173
1.00,8.33,0.173
1.02,8.45,0.173
1.03,8.57,0.173
1.04,8.68,0.174
1.05,8.80,0.174
1.06,8.91,0.174
1.07,9.03,0.174
1.08,9.15,0.174
1.10,9.26,0.174
1.11,9.38,0.174
1.12,9.50,0.174
1.13,9.61,0.175
1.14,9.73,0.175
1.16,9.84,0.175
1.17,9.96,0.175
1.18,10.08,0.175
1.19,10.19,0.175
1.20,10.31,0.175
1.21,10.43,0.175
1.23,10.54,0.175
1.24,10.66,0.176
1.25,10.78,0.176
1.26,10.89,0.176
1.27,11.01,0.176
1.28,11.12,0.176
1.29,11.24,0.176
1.31,11.36,0.176
1.32,11.47,0.176
1.33,11.59,0.176
1.34,11.71,0.176
1.35,11.82,0.176
1.37,11.94,0.176
1.38,12.05,0.177
1.39,12.17,0.177
1.40,12.29,0.177
1.41,12.40,0.177
1.42,12.52,0.177
1.43,12.64,0.177
1.45,12.75,0.177
1.46,12.87,0.177
1.47,12.99,0.177
1.48,13.10,0.177
1.49,13.22,0.177
1.51,13.34,0.178
1.52,13.45,0.178
1.53,13.57,0.178
1.54,13.69,0.178
1.55,13.80,0.178
1.56,13.92,0.178
1.58,14.04,0.178
1.59,14.15,0.178
1.60,14.27,0.178
1.61,14.39,0.178
1.62,14.50,0.178
1.63,14.62,0.178
1.64,14.73,0.178
1.66,14.85,0.178
1.67,14.97,0.179
1.68,15.09,0.179
1.69,15.20,0.179
1.70,15.32,0.179
1.72,15.43,0.179
1.73,15.55,0.179
1.74,15.67,0.179
1.75,15.78,0.179
1.76,15.90,0.179
1.77,16.02,0.179
1.78,16.13,0.179
1.80,16.25,0.179
1.81,16.37,0.179
1.82,16.48,0.179
1.83,16.60,0.180
1.84,16.72,0.180
1.86,16.84,0.180
1.87,16.95,0.180
1.88,17.07,0.180
1.89,17.19,0.180
1.90,17.30,0.180
1.91,17.42,0.180
1.93,17.54,0.180
1.94,17.65,0.180
1.95,17.77,0.180
1.96,17.89,0.180
1.97,18.00,0.180
1.98,18.12,0.180
1.99,18.24,0.180
2.01,18.35,0.180
2.02,18.47,0.180
2.03,18.59,0.180
2.04,18.70,0.181
2.05,18.82,0.181
2.07,18.94,0.181
2.08,19.05,0.181
2.09,19.17,0.181
2.10,19.29,0.181
2.11,19.40,0.181
2.12,19.52,0.181
2.14,19.64,0.181
2.15,19.75,0.181
2.16,19.87,0.181
2.17,19.99,0.181
2.18,20.10,0.181
2.19,20.22,0.181
2.21,20.34,0.181
2.22,20.45,0.181
2.23,20.57,0.181
2.24,20.69,0.181
2.25,20.80,0.182
2.26,20.92,0.182
2.28,21.04,0.182
2.29,21.15,0.182
2.30,21.27,0.182
2.31,21.39,0.182
2.32,21.50,0.182
2.33,21.62,0.182
2.34,21.74,0.182
2.36,21.85,0.182
2.37,21.97,0.182
2.38,22.09,0.182
2.39,22.20,0.182
2.40,22.32,0.182
2.41,22.44,0.182
2.43,22.56,0.182
2.44,22.67,0.182
2.45,22.79,0.182
2.46,22.91,0.182
2.47,23.02,0.183
2.49,23.14,0.183
2.50,23.26,0.183
2.51,23.37,0.183
2.52,23.49,0.183
2.53,23.61,0.183
2.54,23.72,0.183
2.56,23.84,0.183
2.57,23.96,0.183
2.58,24.07,0.183
2.59,24.19,0.183
2.60,24.31,0.183
2.61,24.42,0.183
2.63,24.54,0.183
2.64,24.66,0.183
2.65,24.77,0.183
2.66,24.89,0.183
2.67,25.01,0.183
2.68,25.12,0.183
2.69,25.24,0.184
2.71,25.36,0.184
2.72,25.47,0.184
2.73,25.59,0.184
2.74,25.71,0.184
2.75,25.83,0.184
2.76,25.94,0.184
2.78,26.06,0.184
2.79,26.18,0.184
2.80,26.29,0.184
2.81,26.41,0.184
2.82,26.53,0.184
2.84,26.64,0.184
2.85,26.76,0.184
2.86,26.88,0.184
2.87,26.99,0.184
2.88,27.11,0.184
2.89,27.23,0.184
2.91,27.34,0.184
2.92,27.46,0.184
2.93,27.58,0.185
2.94,27.69,0.185
2.95,27.81,0.185
2.96,27.93,0.185
2.98,28.04,0.185
2.99,28.16,0.185
3.00,28.28,0.185
3.01,28.39,0.185
3.02,28.51,0.185
3.03,28.63,0.185
3.04,28.75,0.185
3.06,28.86,0.185
3.07,28.98,0.185
3.08,29.10,0.185
3.09,29.21,0.185
3.10,29.33,0.185
3.11,29.44,0.186
3.13,29.56,0.186
3.14,29.68,0.186
3.15,29.79,0.186
3.16,29.91,0.186
3.17,30.03,0.186
3.19,30.15,0.186
3.20,30.26,0.186
3.21,30.38,0.186
3.22,30.50,0.186
3.23,30.61,0.186
3.24,30.73,0.186
3.26,30.85,0.186
3.27,30.96,0.186
3.28,31.08,0.186
3.29,31.20,0.186
3.30,31.31,0.186
3.31,31.43,0.186
3.33,31.55,0.186
3.34,31.66,0.186
3.35,31.78,0.187
3.36,31.90,0.187
3.37,32.02,0.187
3.38,32.13,0.187
3.39,32.25,0.187
3.41,32.36,0.187
3.42,32.48,0.187
3.43,32.60,0.187
3.44,32.72,0.187
3.45,32.83,0.187
3.46,32.95,0.187
3.48,33.07,0.187
3.49,33.18,0.187
3.50,33.30,0.187
3.51,33.42,0.187
3.52,33.53,0.187
3.54,33.65,0.187
3.55,33.77,0.187
3.56,33.88,0.187
3.57,34.00,0.187
3.58,34.12,0.187
3.59,34.23,0.188
3.61,34.35,0.188
3.62,34.47,0.188
3.63,34.58,0.188
3.64,34.70,0.188
3.65,34.82,0.188
3.66,34.94,0.188
3.68,35.05,0.188
3.69,35.17,0.188
3.70,35.29,0.188
3.71,35.40,0.188
3.72,35.52,0.188
3.73,35.63,0.188
3.74,35.75,0.188
3.76,35.87,0.188
3.77,35.99,0.188
3.78,36.10,0.188
3.79,36.22,0.188
3.80,36.34,0.188
3.81,36.45,0.188
3.83,36.57,0.189
3.84,36.69,0.189
3.85,36.80,0.189
3.86,36.92,0.189
3.87,37.04,0.189
3.89,37.15,0.189
3.90,37.27,0.189
3.91,37.39,0.189
3.92,37.50,0.189
3.93,37.62,0.189
3.94,37.74,0.189
3.96,37.86,0.189
3.97,37.97,0.189
3.98,38.09,0.189
3.99,38.20,0.189
4.00,38.32,0.189
4.01,38.44,0.189
4.03,38.55,0.189
4.04,38.67,0.189
4.05,38.79,0.190
4.06,38.91,0.190
4.07,39.02,0.190
4.08,39.14,0.190
4.09,39.26,0.190
4.11,39.37,0.190
4.12,39.49,0.190
4.13,39.61,0.190
4.14,39.72,0.190
4.15,39.84,0.190
4.16,39.96,0.190
4.18,40.07,0.190
4.19,40.19,0.190
4.20,40.31,0.190
4.21,40.42,0.190
4.22,40.54,0.190
4.24,40.66,0.190
4.25,40.77,0.190
4.26,40.89,0.190
4.27,41.01,0.190
4.28,41.12,0.191
4.29,41.24,0.191
4.30,41.36,0.191
4.32,41.47,0.191
4.33,41.59,0.191
4.34,41.71,0.191
4.35,41.83,0.191
4.36,41.94,0.191
4.38,42.06,0.191
4.39,42.18,0.191
4.40,42.29,0.191
4.41,42.41,0.191
4.42,42.53,0.191
4.43,42.64,0.191
4.45,42.76,0.191
4.46,42.88,0.191
4.47,42.99,0.191
4.48,43.11,0.192
4.49,43.23,0.192
4.50,43.34,0.192
4.51,43.46,0.192
4.53,43.58,0.192
4.54,43.69,0.192
4.55,43.81,0.192
4.56,43.93,0.192
4.57,44.04,0.192
4.59,44.16,0.192
4.60,44.28,0.192
4.61,44.39,0.192
4.62,44.51,0.192
4.63,44.63,0.192
4.64,44.74,0.192
4.65,44.86,0.192
4.67,44.98,0.192
4.68,45.09,0.192
4.69,45.21,0.193
4.70,45.33,0.193
4.71,45.45,0.193
4.73,45.56,0.193
4.74,45.68,0.193
4.75,45.80,0.193
4.76,45.91,0.193
4.77,46.03,0.193
4.78,46.15,0.193
4.80,46.26,0.193
4.81,46.38,0.193
4.82,46.50,0.193
4.83,46.61,0.193
4.84,46.73,0.193
4.85,46.85,0.193
4.86,46.96,0.193
4.88,47.08,0.193
4.89,47.20,0.193
4.90,47.31,0.194
4.91,47.43,0.194
4.92,47.55,0.194
4.94,47.67,0.194
4.95,47.78,0.194
4.96,47.90,0.194
4.97,48.02,0.194
4.98,48.13,0.194
4.99,48.25,0.194
5.00,48.37,0.194
5.02,48.48,0.194
5.03,48.60,0.194
5.04,48.72,0.194
5.05,48.83,0.194
5.06,48.95,0.194
5.08,49.07,0.194
5.09,49.18,0.194
5.10,49.30,0.195
5.11,49.42,0.195
5.12,49.53,0.195
5.13,49.65,0.195
5.15,49.77,0.195
5.16,49.88,0.195
5.17,50.00,0.195
5.18,50.12,0.195
5.19,50.24,0.195
5.20,50.35,0.195
5.21,50.47,0.195
5.23,50.59,0.195
5.24,50.70,0.195
5.25,50.82,0.195
5.26,50.94,0.195
5.27,51.05,0.195
5.29,51.17,0.196
5.30,51.29,0.196
5.31,51.40,0.196
5.32,51.52,0.196
5.33,51.63,0.196
5.34,51.75,0.196
5.35,51.87,0.196
5.37,51.99,0.196
5.38,52.10,0.196
5.39,52.22,0.196
5.40,52.34,0.196
5.41,52.45,0.196
5.43,52.57,0.196
5.44,52.69,0.196
5.45,52.80,0.196
5.46,52.92,0.196
5.47,53.04,0.196
5.48,53.15,0.196
5.50,53.27,0.196
5.51,53.39,0.196
5.52,53.50,0.196
5.53,53.62,0.197
5.54,53.74,0.197
5.55,53.85,0.197
5.56,53.97,0.197
5.58,54.09,0.197
5.59,54.21,0.197
5.60,54.32,0.197
5.61,54.44,0.197
5.62,54.56,0.197
5.64,54.67,0.197
5.65,54.79,0.197
5.66,54.91,0.197
5.67,55.02,0.197
5.68,55.14,0.197
5.69,55.26,0.197
5.70,55.37,0.197
5.72,55.49,0.197
5.73,55.61,0.198
5.74,55.72,0.198
5.75,55.84,0.198
5.76,55.96,0.198
5.78,56.07,0.198
5.79,56.19,0.198
5.80,56.31,0.198
5.81,56.42,0.198
5.82,56.54,0.198
5.83,56.66,0.198
5.85,56.77,0.198
5.86,56.89,0.198
5.87,57.01,0.198
5.88,57.12,0.198
5.89,57.24,0.198
5.90,57.36,0.198
5.91,57.48,0.198
5.93,57.59,0.198
5.94,57.71,0.199
5.95,57.82,0.199
5.96,57.94,0.199
5.97,58.06,0.199
5.99,58.18,0.199
6.00,58.29,0.199
6.01,58.41,0.199
6.02,58.53,0.199
6.03,58.64,0.199
6.04,58.76,0.199
6.05,58.88,0.199
6.07,58.99,0.199
6.08,59.11,0.199
6.09,59.23,0.199
6.10,59.34,0.199
6.11,59.46,0.199
6.13,59.58,0.199
6.14,59.69,0.199
6.15,59.81,0.200
6.16,59.93,0.200
6.17,60.04,0.200
6.18,60.16,0.200
6.20,60.28,0.200
6.21,60.40,0.200
6.22,60.51,0.200
6.23,60.63,0.200
6.24,60.75,0.200
6.25,60.86,0.200
6.26,60.98,0.200
6.28,61.10,0.200
6.29,61.21,0.200
6.30,61.33,0.200
6.31,61.45,0.200
6.32,61.56,0.200
6.34,61.68,0.200
6.35,61.80,0.200
6.36,61.91,0.201
6.37,62.03,0.201
6.38,62.15,0.201
6.39,62.26,0.201
6.40,62.38,0.201
6.42,62.50,0.201
6.43,62.61,0.201
6.44,62.73,0.201
6.45,62.85,0.201
6.46,62.96,0.201
6.48,63.08,0.201
6.49,63.20,0.201
6.50,63.31,0.201
6.51,63.43,0.201
6.52,63.55,0.201
6.53,63.66,0.201
6.55,63.78,0.201
6.56,63.90,0.201
6.57,64.01,0.201
6.58,64.13,0.202
6.59,64.25,0.202
6.60,64.36,0.202
6.61,64.48,0.202
6.63,64.60,0.202
6.64,64.72,0.202
6.65,64.83,0.202
6.66,64.95,0.202
6.67,65.07,0.202
6.69,65.18,0.202
6.70,65.30,0.202
6.71,65.42,0.202
6.72,65.53,0.202
6.73,65.65,0.202
6.74,65.77,0.202
6.75,65.88,0.202
6.77,66.00,0.202
6.78,66.12,0.202
6.79,66.23,0.203
6.80,66.35,0.203
6.81,66.47,0.203
6.83,66.58,0.203
6.84,66.70,0.203
6.85,66.82,0.203
6.86,66.93,0.203
6.87,67.05,0.203
6.88,67.17,0.203
6.90,67.28,0.203
6.91,67.40,0.203
6.92,67.52,0.203
6.93,67.64,0.203
6.94,67.75,0.203
6.95,67.87,0.203
6.96,67.99,0.203
6.98,68.10,0.203
6.99,68.22,0.203
7.00,68.34,0.203
7.01,68.45,0.203
7.02,68.57,0.203
7.04,68.69,0.204
7.05,68.80,0.204
7.06,68.92,0.204
7.07,69.04,0.204
7.08,69.15,0.204
7.09,69.27,0.204
7.10,69.39,0.204
7.12,69.50,0.204
7.13,69.62,0.204
7.14,69.74,0.204
7.15,69.85,0.204
7.16,69.97,0.204
7.18,70.09,0.204
7.19,70.21,0.204
7.20,70.32,0.204
7.21,70.44,0.204
7.22,70.56,0.204
7.23,70.67,0.204
7.25,70.79,0.204
7.26,70.91,0.204
7.27,71.02,0.204
7.28,71.14,0.205
7.29,71.26,0.205
7.30,71.37,0.205
7.31,71.49,0.205
7.33,71.61,0.205
7.34,71.72,0.205
7.35,71.84,0.205
7.36,71.96,0.205
7.37,72.07,0.205
7.39,72.19,0.205
7.40,72.31,0.205
7.41,72.42,0.205
7.42,72.54,0.205
7.43,72.66,0.205
7.44,72.77,0.205
7.45,72.89,0.205
7.47,73.01,0.205
7.48,73.12,0.205
7.49,73.24,0.205
7.50,73.36,0.205
7.51,73.48,0.206
7.53,73.59,0.206
7.54,73.71,0.206
7.55,73.82,0.206
7.56,73.94,0.206
7.57,74.06,0.206
7.58,74.18,0.206
7.60,74.29,0.206
7.61,74.41,0.206
7.62,74.53,0.206
7.63,74.64,0.206
7.64,74.76,0.206
7.65,74.88,0.206
7.66,74.99,0.206
7.68,75.11,0.206
7.69,75.23,0.206
7.70,75.34,0.206
7.71,75.46,0.206
7.72,75.58,0.207
7.74,75.69,0.207
7.75,75.81,0.207
7.76,75.93,0.207
7.77,76.04,0.207
7.78,76.16,0.207
7.79,76.28,0.207
7.80,76.39,0.207
7.82,76.51,0.207
7.83,76.63,0.207
7.84,76.75,0.207
7.85,76.86,0.207
7.86,76.98,0.207
7.88,77.09,0.207
7.89,77.21,0.207
7.90,77.33,0.207
7.91,77.45,0.207
7.92,77.56,0.207
7.93,77.68,0.207
7.95,77.80,0.207
7.96,77.91,0.208
7.97,78.03,0.208
7.98,78.15,0.208
7.99,78.26,0.208
8.00,78.38,0.208
8.01,78.50,0.208
8.03,78.61,0.208
8.04,78.73,0.208
8.05,78.85,0.208
8.06,78.96,0.208
8.07,79.08,0.208
8.09,79.20,0.208
8.10,79.31,0.208
8.11,79.43,0.208
8.12,79.55,0.208
8.13,79.66,0.208
8.14,79.78,0.209
8.15,79.90,0.209
8.17,80.01,0.209
8.18,80.13,0.209
8.19,80.25,0.209
8.20,80.37,0.209
8.21,80.48,0.209
8.23,80.60,0.209
8.24,80.72,0.209
8.25,80.83,0.209
8.26,80.95,0.209
8.27,81.07,0.209
8.28,81.18,0.209
8.30,81.30,0.209
8.31,81.42,0.209
8.32,81.53,0.209
8.33,81.65,0.209
8.34,81.77,0.210
8.35,81.88,0.210
8.36,82.00,0.210
8.38,82.12,0.210
8.39,82.23,0.210
8.40,82.35,0.210
8.41,82.47,0.210
8.42,82.58,0.210
8.44,82.70,0.210
8.45,82.82,0.210
8.46,82.93,0.210
8.47,83.05,0.210
8.48,83.17,0.210
8.49,83.28,0.210
8.50,83.40,0.210
8.52,83.52,0.210
8.53,83.63,0.210
8.54,83.75,0.210
8.55,83.87,0.210
8.56,83.98,0.210
8.58,84.10,0.210
8.59,84.22,0.210
8.60,84.34,0.210
8.61,84.45,0.210
8.62,84.57,0.210
8.63,84.69,0.210
8.65,84.80,0.211
8.66,84.92,0.211
8.67,85.04,0.211
8.68,85.15,0.211
8.69,85.27,0.211
8.70,85.39,0.211
8.72,85.50,0.211
8.73,85.62,0.211
8.74,85.74,0.211
8.75,85.85,0.211
8.76,85.97,0.211
8.77,86.09,0.211
8.78,86.20,0.211
8.80,86.32,0.211
8.81,86.44,0.211
8.82,86.55,0.211
8.83,86.67,0.211
8.84,86.79,0.211
8.85,86.90,0.211
8.87,87.02,0.211
8.88,87.14,0.211
8.89,87.26,0.211
8.90,87.37,0.212
8.91,87.49,0.212
8.93,87.61,0.212
8.94,87.72,0.212
8.95,87.84,0.212
8.96,87.96,0.212
8.97,88.07,0.212
8.98,88.19,0.212
9.00,88.31,0.212
9.01,88.42,0.212
9.02,88.54,0.212
9.03,88.66,0.212
9.04,88.77,0.212
9.05,88.89,0.212
9.07,89.01,0.212
9.08,89.12,0.212
9.09,89.24,0.212
9.10,89.36,0.212
9.11,89.47,0.212
9.12,89.59,0.212
9.13,89.71,0.213
9.15,89.82,0.213
9.16,89.94,0.213
9.17,90.06,0.213
9.18,90.17,0.213
9.19,90.29,0.213
9.20,90.41,0.213
9.22,90.52,0.213
9.23,90.64,0.213
9.24,90.76,0.213
9.25,90.87,0.213
9.26,90.99,0.213
9.28,91.11,0.213
9.29,91.23,0.213
9.30,91.34,0.213
9.31,91.46,0.214
9.32,91.58,0.214
9.33,91.69,0.214
9.35,91.81,0.214
9.36,91.93,0.214
9.37,92.04,0.214
9.38,92.16,0.214
9.39,92.28,0.214
9.40,92.39,0.214
9.42,92.51,0.214
9.43,92.63,0.214
9.44,92.74,0.214
9.45,92.86,0.214
9.46,92.98,0.214
9.47,93.09,0.214
9.48,93.21,0.214
9.50,93.33,0.215
9.51,93.44,0.215
9.52,93.56,0.215
9.53,93.68,0.215
9.54,93.79,0.215
9.55,93.91,0.215
9.57,94.03,0.215
9.58,94.14,0.215
9.59,94.26,0.215
9.60,94.38,0.215
9.61,94.50,0.215
9.63,94.61,0.215
9.64,94.73,0.215
9.65,94.84,0.215
9.66,94.96,0.215
9.67,95.08,0.215
9.68,95.19,0.215
9.70,95.31,0.216
9.71,95.43,0.216
9.72,95.55,0.216
9.73,95.66,0.216
9.74,95.78,0.216
9.75,95.90,0.216
9.77,96.01,0.216
9.78,96.13,0.216
9.79,96.25,0.216
9.80,96.36,0.216
9.81,96.48,0.216
9.82,96.60,0.216
9.83,96.71,0.216
9.85,96.83,0.216
9.86,96.95,0.216
9.87,97.06,0.216
9.88,97.18,0.216
9.89,97.30,0.217
9.90,97.41,0.217
9.92,97.53,0.217
9.93,97.65,0.217
9.94,97.77,0.217
9.95,97.88,0.217
9.96,98.00,0.217
9.98,98.12,0.217
9.99,98.23,0.217
10.00,98.35,0.217
10.01,98.47,0.217
10.02,98.58,0.217
10.03,98.70,0.217
10.05,98.82,0.217
10.06,98.93,0.217
10.07,99.05,0.217
10.08,99.17,0.218
10.09,99.28,0.218
10.10,99.40,0.218
10.12,99.52,0.218
10.13,99.63,0.218
10.14,99.75,0.218
10.15,99.87,0.218
10.16,99.98,0.218
10.17,100.10,0.218
10.18,100.22,0.218
10.20,100.33,0.218
10.21,100.45,0.218
10.22,100.57,0.218
10.23,100.68,0.218
10.24,100.80,0.218
10.25,100.92,0.218
10.27,101.03,0.218
10.28,101.15,0.218
10.29,101.27,0.218
10.30,101.38,0.218
10.31,101.50,0.219
10.33,101.62,0.219
10.34,101.74,0.219
10.35,101.85,0.219
10.36,101.97,0.219
10.37,102.08,0.219
10.38,102.20,0.219
10.40,102.32,0.219
10.41,102.43,0.219
10.42,102.55,0.219
10.43,102.67,0.219
10.44,102.79,0.219
10.45,102.90,0.219
10.47,103.02,0.219
10.48,103.14,0.219
10.49,103.25,0.219
10.50,103.37,0.219
10.51,103.49,0.219
10.52,103.60,0.220
10.53,103.72,0.220
10.55,103.84,0.220
10.56,103.95,0.220
10.57,104.07,0.220
10.58,104.19,0.220
10.59,104.30,0.220
10.60,104.42,0.220
10.62,104.54,0.220
10.63,104.65,0.220
10.64,104.77,0.220
10.65,104.89,0.220
10.66,105.00,0.220
10.68,105.12,0.220
10.69,105.24,0.220
10.70,105.36,0.220
10.71,105.47,0.220
10.72,105.59,0.220
10.73,105.71,0.221
10.75,105.82,0.221
10.76,105.94,0.221
10.77,106.06,0.221
10.78,106.17,0.221
10.79,106.29,0.221
10.80,106.41,0.221
10.82,106.52,0.221
10.83,106.64,0.221
10.84,106.76,0.221
10.85,106.87,0.221
10.86,106.99,0.221
10.87,107.11,0.221
10.88,107.22,0.221
10.90,107.34,0.221
10.91,107.46,0.221
10.92,107.58,0.221
10.93,107.69,0.221
10.94,107.81,0.221
10.95,107.93,0.222
10.97,108.05,0.222
10.98,108.16,0.222
10.99,108.28,0.222
11.00,108.40,0.222
11.01,108.52,0.222
11.03,108.63,0.222
11.04,108.75,0.222
11.05,108.87,0.223
11.06,108.98,0.223
11.07,109.10,0.223
11.08,109.22,0.223
11.10,109.33,0.223
11.11,109.45,0.223
11.12,109.57,0.223
11.13,109.68,0.223
11.14,109.80,0.223
11.15,109.92,0.223
11.17,110.03,0.223
11.18,110.15,0.223
11.19,110.26,0.223
11.20,110.38,0.223
11.21,110.50,0.223
11.22,110.62,0.223
11.23,110.73,0.223
11.25,110.85,0.223
11.26,110.96,0.223
11.27,111.08,0.223
11.28,111.20,0.223
11.29,111.31,0.223
11.30,111.43,0.223
11.32,111.55,0.223
11.33,111.66,0.223
11.34,111.78,0.223
11.35,111.90,0.223
11.36,112.01,0.223
11.38,112.13,0.223
11.39,112.25,0.223
11.40,112.36,0.223
11.41,112.48,0.223
11.42,112.59,0.223
11.43,112.71,0.223
11.45,112.83,0.223
11.46,112.95,0.223
11.47,113.06,0.223
11.48,113.18,0.223
11.49,113.29,0.223
11.50,113.41,0.223
11.52,113.53,0.223
11.53,113.65,0.223
11.54,113.76,0.223
11.55,113.88,0.224
11.56,114.00,0.224
11.57,114.11,0.224
11.58,114.23,0.224
11.60,114.35,0.224
11.61,114.46,0.224
11.62,114.58,0.224
11.63,114.70,0.224
11.64,114.81,0.224
11.65,114.93,0.224
11.67,115.05,0.224
11.68,115.16,0.224
11.69,115.28,0.224
11.70,115.40,0.224
11.71,115.51,0.224
11.73,115.63,0.224
11.74,115.75,0.224
11.75,115.86,0.225
11.76,115.98,0.225
11.77,116.10,0.225
11.78,116.21,0.225
11.80,116.33,0.225
11.81,116.45,0.225
11.82,116.56,0.225
11.83,116.68,0.225
11.84,116.80,0.225
11.85,116.91,0.225
11.87,117.03,0.225
11.88,117.15,0.225
11.89,117.26,0.225
11.90,117.38,0.225
11.91,117.50,0.225
11.92,117.61,0.225
11.93,117.73,0.225
11.95,117.85,0.225
11.96,117.96,0.225
11.97,118.08,0.225
11.98,118.20,0.226
11.99,118.32,0.226
12.00,118.43,0.226
12.02,118.55,0.226
12.03,118.67,0.226
12.04,118.78,0.226
12.05,118.90,0.226
12.06,119.02,0.226
12.08,119.13,0.226
12.09,119.25,0.226
12.10,119.37,0.226
12.11,119.48,0.226
12.12,119.60,0.226
12.13,119.72,0.226
12.15,119.84,0.226
12.16,119.95,0.226
12.17,120.07,0.226
12.18,120.19,0.227
12.19,120.30,0.227
12.20,120.42,0.227
12.22,120.53,0.227
12.23,120.65,0.227
12.24,120.77,0.227
12.25,120.88,0.227
12.26,121.00,0.227
12.27,121.12,0.227
12.28,121.24,0.227
12.30,121.35,0.227
12.31,121.47,0.227
12.32,121.59,0.227
12.33,121.70,0.227
12.34,121.82,0.227
12.35,121.94,0.227
12.37,122.05,0.227
12.38,122.17,0.227
12.39,122.29,0.227
12.40,122.40,0.227
12.41,122.52,0.227
12.43,122.64,0.227
12.44,122.75,0.227
12.45,122.87,0.228
12.46,122.99,0.228
12.47,123.10,0.228
12.48,123.22,0.228
12.50,123.34,0.228
12.51,123.45,0.228
12.52,123.57,0.228
12.53,123.69,0.228
12.54,123.80,0.228
12.55,123.92,0.228
12.57,124.04,0.228
12.58,124.15,0.228
12.59,124.27,0.228
12.60,124.39,0.228
12.61,124.51,0.228
12.62,124.62,0.228
12.63,124.74,0.228
12.65,124.86,0.228
12.66,124.97,0.228
12.67,125.09,0.229
12.68,125.21,0.229
12.69,125.32,0.229
12.70,125.44,0.229
12.72,125.56,0.229
12.73,125.67,0.229
12.74,125.79,0.229
12.75,125.91,0.229
12.76,126.02,0.229
12.78,126.14,0.229
12.79,126.26,0.229
12.80,126.37,0.229
12.81,126.49,0.229
12.82,126.61,0.229
12.83,126.72,0.229
12.85,126.84,0.229
12.86,126.96,0.229
12.87,127.07,0.229
12.88,127.19,0.230
12.89,127.31,0.230
12.90,127.42,0.230
12.92,127.54,0.230
12.93,127.66,0.230
12.94,127.77,0.230
12.95,127.89,0.230
12.96,128.01,0.230
12.97,128.12,0.230
12.98,128.24,0.230
13.00,128.36,0.230
13.01,128.48,0.230
13.02,128.59,0.230
13.03,128.71,0.230
13.04,128.83,0.230
13.05,128.94,0.230
13.07,129.06,0.230
13.08,129.18,0.230
13.09,129.29,0.231
13.10,129.41,0.231
13.11,129.53,0.231
13.13,129.64,0.231
13.14,129.76,0.231
13.15,129.88,0.231
13.16,129.99,0.231
13.17,130.11,0.231
13.18,130.23,0.231
13.20,130.34,0.231
13.21,130.46,0.231
13.22,130.57,0.231
13.23,130.69,0.231
13.24,130.81,0.231
13.25,130.92,0.232
13.27,131.04,0.232
13.28,131.16,0.232
13.29,131.27,0.232
13.30,131.39,0.232
13.31,131.51,0.232
13.32,131.63,0.232
13.33,131.74,0.232
13.35,131.86,0.232
13.36,131.98,0.232
13.37,132.09,0.232
13.38,132.21,0.232
13.39,132.33,0.232
13.40,132.44,0.233
13.42,132.56,0.233
13.43,132.68,0.233
13.44,132.79,0.233
13.45,132.91,0.233
13.46,133.03,0.233
13.48,133.14,0.233
13.49,133.26,0.233
13.50,133.38,0.233
13.51,133.49,0.233
13.52,133.61,0.234
13.53,133.73,0.234
13.55,133.84,0.234
13.56,133.96,0.234
13.57,134.08,0.234
13.58,134.19,0.234
13.59,134.31,0.234
13.60,134.43,0.235
13.62,134.54,0.235
13.63,134.66,0.235
13.64,134.78,0.235
13.65,134.89,0.235
13.66,135.01,0.235
13.67,135.13,0.235
13.68,135.24,0.236
13.70,135.36,0.236
13.71,135.48,0.236
13.72,135.59,0.236
13.73,135.71,0.237
13.74,135.83,0.237
13.75,135.94,0.237
13.77,136.06,0.238
13.78,136.18,0.238
13.79,136.29,0.239
13.80,136.41,0.240
13.81,136.53,0.241
13.83,136.64,0.241
13.84,136.76,0.242
13.85,136.88,0.244
13.86,136.99,0.244
13.87,137.11,0.245
13.88,137.23,0.246
13.90,137.34,0.247
13.91,137.46,0.248
13.92,137.57,0.249
13.93,137.69,0.251
13.94,137.81,0.252
13.95,137.92,0.254
13.97,138.04,0.256
13.98,138.15,0.257
13.99,138.27,0.259
14.00,138.39,0.261
14.01,138.50,0.264
14.02,138.62,0.267
14.03,138.73,0.269
14.05,138.85,0.272
14.06,138.96,0.276
14.07,139.08,0.279
14.08,139.19,0.284
14.09,139.31,0.288
14.10,139.42,0.293
14.12,139.54,0.299
14.13,139.65,0.305
14.14,139.77,0.312
14.15,139.88,0.319
14.16,139.99,0.328
14.18,140.10,0.337
14.19,140.22,0.348
14.20,140.33,0.360
14.21,140.44,0.373
14.22,140.55,0.387
14.23,140.66,0.404
14.25,140.77,0.422
14.26,140.88,0.442
14.27,140.99,0.465
14.28,141.09,0.488
14.29,141.20,0.515
14.30,141.30,0.542
14.32,141.40,0.574
14.33,141.50,0.607
14.34,141.61,0.644
14.35,141.70,0.683
14.36,141.80,0.722
14.37,141.90,0.768
14.38,141.99,0.816
14.40,142.09,0.859
14.41,142.18,0.910
14.42,142.27,0.957
14.43,142.36,1.005
14.44,142.45,1.052
14.45,142.54,1.099
14.47,142.63,1.145
14.48,142.71,1.191
14.49,142.80,1.237
14.50,142.89,1.284
14.51,142.98,1.334
14.53,143.07,1.386
14.54,143.15,1.440
14.55,143.24,1.496
14.56,143.32,1.554
14.57,143.41,1.613
14.58,143.49,1.674
14.60,143.57,1.736
14.61,143.66,1.798
14.62,143.74,1.860
14.63,143.82,1.917
14.64,143.90,1.969
14.65,143.98,2.010
14.67,144.07,2.041
14.68,144.15,2.065
14.69,144.25,2.086
14.70,144.34,2.109
14.71,144.44,2.137
14.72,144.53,2.172
14.73,144.62,2.213
14.75,144.72,2.262
14.76,144.81,2.315
14.77,144.90,2.371
14.78,144.99,2.428
14.79,145.08,2.479
14.80,145.16,2.523
14.82,145.25,2.563
14.83,145.34,2.601
14.84,145.43,2.627
14.85,145.53,2.639
14.86,145.62,2.642
14.88,145.73,2.638
14.89,145.83,2.625
14.90,145.94,2.605
14.91,146.06,2.578
14.92,146.18,2.547
14.93,146.30,2.512
14.95,146.43,2.467
14.96,146.56,2.411
14.97,146.69,2.342
14.98,146.83,2.257
14.99,146.98,2.163
15.00,147.14,2.061
15.02,147.29,1.953
15.03,147.46,1.842
15.04,147.63,1.728
15.05,147.80,1.611
15.06,147.98,1.493
15.07,148.16,1.376
15.08,148.34,1.260
15.10,148.52,1.147
15.11,148.70,1.041
15.12,148.88,0.942
15.13,149.06,0.856
15.14,149.24,0.782
15.15,149.41,0.721
15.17,149.58,0.670
15.18,149.75,0.629
15.19,149.91,0.591
15.20,150.06,0.559
15.21,150.21,0.530
15.23,150.36,0.505
15.24,150.51,0.484
15.25,150.65,0.459
15.26,150.79,0.443
15.27,150.92,0.429
15.28,151.06,0.411
15.30,151.19,0.398
15.31,151.32,0.386
15.32,151.45,0.376
15.33,151.58,0.366
15.34,151.71,0.357
15.35,151.83,0.350
15.37,151.96,0.342
15.38,152.08,0.336
15.39,152.21,0.330
15.40,152.33,0.325
15.41,152.45,0.321
15.42,152.57,0.317
15.43,152.69,0.313
15.45,152.82,0.310
15.46,152.94,0.307
15.47,153.06,0.305
15.48,153.18,0.302
15.49,153.30,0.300
15.50,153.41,0.298
15.52,153.53,0.297
15.53,153.65,0.296
15.54,153.77,0.294
15.55,153.89,0.293
15.56,154.01,0.292
15.58,154.12,0.291
15.59,154.24,0.290
15.60,154.36,0.289
15.61,154.48,0.288
15.62,154.60,0.288
15.63,154.71,0.287
15.65,154.83,0.287
15.66,154.95,0.286
15.67,155.07,0.286
15.68,155.18,0.286
15.69,155.30,0.285
15.70,155.42,0.285
15.72,155.53,0.285
15.73,155.65,0.285
15.74,155.77,0.285
15.75,155.88,0.284
15.76,156.00,0.284
15.77,156.12,0.284
15.78,156.24,0.284
15.80,156.35,0.284
15.81,156.47,0.284
15.82,156.59,0.283
15.83,156.70,0.283
15.84,156.82,0.283
15.85,156.94,0.283
15.87,157.05,0.283
15.88,157.17,0.283
15.89,157.29,0.283
15.90,157.40,0.283
15.91,157.52,0.283
15.93,157.64,0.283
15.94,157.76,0.283
15.95,157.87,0.282
15.96,157.99,0.282
15.97,158.11,0.282
15.98,158.22,0.282
16.00,158.34,0.282
16.01,158.46,0.282
16.02,158.57,0.282
16.03,158.69,0.282
16.04,158.81,0.282
16.05,158.92,0.282
16.07,159.04,0.282
16.08,159.16,0.282
16.09,159.27,0.282
16.10,159.39,0.281
16.11,159.51,0.281
16.12,159.62,0.281
16.13,159.74,0.281
16.15,159.86,0.281
16.16,159.97,0.281
16.17,160.09,0.281
16.18,160.21,0.281
16.19,160.32,0.281
16.20,160.44,0.281
16.22,160.56,0.281
16.23,160.67,0.281
16.24,160.79,0.281
16.25,160.91,0.281
16.26,161.02,0.281
16.28,161.14,0.281
16.29,161.26,0.281
16.30,161.37,0.281
16.31,161.49,0.281
16.32,161.61,0.281
16.33,161.73,0.281
16.35,161.84,0.281
16.36,161.96,0.280
16.37,162.07,0.280
16.38,162.19,0.280
16.39,162.31,0.280
16.40,162.43,0.280
16.42,162.54,0.280
16.43,162.66,0.280
16.44,162.78,0.280
16.45,162.89,
16.46,163.01,
16.47,163.13,
16.48,163.24,
16.50,,
16.50,,

[step]
Ramp 10.00 °C/min to 0.00 °C
Time,Temperature,Heat Flow (Normalized)
min,°C,W/g
17.51,165.11,-0.031
17.52,165.11,-0.031
17.53,165.10,-0.031
17.54,165.10,-0.031
17.55,165.10,-0.031
17.56,165.09,-0.031
17.58,165.07,-0.030
17.59,165.05,-0.029
17.60,165.02,-0.029
17.61,164.98,-0.037
17.62,164.93,-0.050
17.63,164.88,-0.065
17.64,164.82,-0.083
17.66,164.75,-0.104
17.67,164.67,-0.125
17.68,164.59,-0.145
17.69,164.51,-0.165
17.70,164.43,-0.183
17.72,164.34,-0.199
17.73,164.25,-0.213
17.74,164.15,-0.226
17.75,164.06,-0.237
17.76,163.96,-0.247
17.77,163.86,-0.257
17.78,163.76,-0.265
17.80,163.66,-0.272
17.81,163.55,-0.279
17.82,163.45,-0.285
17.83,163.34,-0.290
17.84,163.24,-0.295
17.86,163.13,-0.300
17.87,163.02,-0.304
17.88,162.91,-0.308
17.89,162.80,-0.312
17.90,162.69,-0.314
17.91,162.58,-0.316
17.93,162.47,-0.320
17.94,162.36,-0.322
17.95,162.25,-0.324
17.96,162.13,-0.325
17.97,162.02,-0.327
17.98,161.91,-0.328
17.99,161.80,-0.329
18.01,161.68,-0.330
18.02,161.57,-0.332
18.03,161.46,-0.332
18.04,161.34,-0.333
18.05,161.23,-0.334
18.07,161.12,-0.335
18.08,161.00,-0.335
18.09,160.89,-0.335
18.10,160.77,-0.336
18.11,160.66,-0.336
18.12,160.54,-0.336
18.13,160.43,-0.337
18.15,160.31,-0.337
18.16,160.20,-0.338
18.17,160.08,-0.338
18.18,159.97,-0.338
18.19,159.85,-0.338
18.21,159.74,-0.338
18.22,159.62,-0.338
18.23,159.51,-0.339
18.24,159.39,-0.339
18.25,159.28,-0.339
18.26,159.16,-0.339
18.28,159.04,-0.339
18.29,158.93,-0.339
18.30,158.81,-0.339
18.31,158.70,-0.339
18.32,158.58,-0.339
18.33,158.47,-0.339
18.34,158.35,-0.339
18.36,158.24,-0.340
18.37,158.12,-0.340
18.38,158.00,-0.340
18.39,157.89,-0.340
18.40,157.77,-0.340
18.42,157.66,-0.340
18.43,157.54,-0.340
18.44,157.42,-0.340
18.45,157.31,-0.340
18.46,157.19,-0.340
18.47,157.08,-0.340
18.48,156.96,-0.340
18.50,156.84,-0.340
18.51,156.73,-0.340
18.52,156.61,-0.340
18.53,156.50,-0.340
18.54,156.38,-0.340
18.56,156.26,-0.340
18.57,156.15,-0.340
18.58,156.03,-0.340
18.59,155.92,-0.340
18.60,155.80,-0.340
18.61,155.68,-0.340
18.63,155.57,-0.340
18.64,155.45,-0.340
18.65,155.34,-0.340
18.66,155.22,-0.340
18.67,155.10,-0.340
18.68,154.99,-0.340
18.69,154.87,-0.340
18.71,154.75,-0.340
18.72,154.64,-0.340
18.73,154.52,-0.340
18.74,154.40,-0.340
18.75,154.29,-0.340
18.77,154.17,-0.340
18.78,154.06,-0.340
18.79,153.94,-0.340
18.80,153.82,-0.340
18.81,153.71,-0.340
18.82,153.59,-0.340
18.83,153.47,-0.340
18.85,153.36,-0.339
18.86,153.24,-0.339
18.87,153.12,-0.339
18.88,153.01,-0.339
18.89,152.89,-0.339
18.91,152.78,-0.339
18.92,152.66,-0.339
18.93,152.54,-0.339
18.94,152.43,-0.339
18.95,152.31,-0.339
18.96,152.19,-0.339
18.98,152.08,-0.338
18.99,151.96,-0.333
19.00,151.85,-0.333
19.01,151.73,-0.334
19.02,151.61,-0.334
19.03,151.50,-0.334
19.04,151.38,-0.334
19.06,151.26,-0.334
19.07,151.15,-0.334
19.08,151.03,-0.335
19.09,150.91,-0.335
19.10,150.80,-0.335
19.12,150.68,-0.335
19.13,150.57,-0.335
19.14,150.45,-0.335
19.15,150.33,-0.335
19.16,150.21,-0.335
19.17,150.10,-0.335
19.18,149.98,-0.335
19.20,149.87,-0.335
19.21,149.75,-0.335
19.22,149.63,-0.335
19.23,149.52,-0.335
19.24,149.40,-0.335
19.26,149.28,-0.335
19.27,149.17,-0.335
19.28,149.05,-0.335
19.29,148.93,-0.335
19.30,148.82,-0.335
19.31,148.70,-0.335
19.33,148.59,-0.335
19.34,148.47,-0.335
19.35,148.35,-0.335
19.36,148.24,-0.335
19.37,148.12,-0.335
19.38,148.00,-0.335
19.39,147.89,-0.335
19.41,147.77,-0.335
19.42,147.65,-0.335
19.43,147.54,-0.335
19.44,147.42,-0.335
19.45,147.30,-0.335
19.47,147.19,-0.335
19.48,147.07,-0.335
19.49,146.95,-0.335
19.50,146.84,-0.335
19.51,146.72,-0.335
19.52,146.61,-0.335
19.53,146.49,-0.334
19.55,146.37,-0.334
19.56,146.26,-0.334
19.57,146.14,-0.334
19.58,146.02,-0.334
19.59,145.91,-0.334
19.61,145.79,-0.334
19.62,145.67,-0.334
19.63,145.56,-0.334
19.64,145.44,-0.334
19.65,145.32,-0.334
19.66,145.21,-0.334
19.68,145.09,-0.334
19.69,144.97,-0.334
19.70,144.86,-0.334
19.71,144.74,-0.334
19.72,144.62,-0.334
19.73,144.50,-0.333
19.74,144.39,-0.333
19.76,144.27,-0.333
19.77,144.15,-0.333
19.78,144.04,-0.333
19.79,143.92,-0.333
19.80,143.80,-0.333
19.82,143.69,-0.333
19.83,143.57,-0.333
19.84,143.45,-0.333
19.85,143.34,-0.333
19.86,143.22,-0.333
19.87,143.10,-0.333
19.88,142.99,-0.333
19.90,142.87,-0.333
19.91,142.76,-0.332
19.92,142.64,-0.332
19.93,142.52,-0.332
19.94,142.40,-0.332
19.96,142.29,-0.332
19.97,142.17,-0.332
19.98,142.06,-0.332
19.99,141.94,-0.332
20.00,141.82,-0.332
20.01,141.71,-0.332
20.03,141.59,-0.331
20.04,141.48,-0.331
20.05,141.36,-0.331
20.06,141.24,-0.331
20.07,141.13,-0.331
20.08,141.01,-0.331
20.09,140.89,-0.331
20.11,140.78,-0.331
20.12,140.66,-0.331
20.13,140.54,-0.331
20.14,140.43,-0.330
20.15,140.31,-0.330
20.17,140.19,-0.330
20.18,140.08,-0.330
20.19,139.96,-0.330
20.20,139.84,-0.330
20.21,139.73,-0.330
20.22,139.61,-0.330
20.23,139.49,-0.330
20.25,139.38,-0.330
20.26,139.26,-0.330
20.27,139.15,-0.330
20.28,139.03,-0.330
20.29,138.91,-0.329
20.31,138.80,-0.329
20.32,138.68,-0.329
20.33,138.56,-0.329
20.34,138.45,-0.329
20.35,138.33,-0.329
20.36,138.21,-0.329
20.38,138.10,-0.329
20.39,137.98,-0.329
20.40,137.86,-0.329
20.41,137.75,-0.329
20.42,137.63,-0.329
20.43,137.51,-0.329
20.44,137.40,-0.329
20.46,137.28,-0.328
20.47,137.16,-0.328
20.48,137.05,-0.328
20.49,136.93,-0.328
20.50,136.81,-0.328
20.52,136.70,-0.328
20.53,136.58,-0.328
20.54,136.47,-0.328
20.55,136.35,-0.328
20.56,136.23,-0.328
20.57,136.12,-0.328
20.58,136.00,-0.328
20.60,135.88,-0.328
20.61,135.77,-0.328
20.62,135.65,-0.328
20.63,135.53,-0.328
20.64,135.42,-0.328
20.66,135.30,-0.327
20.67,135.18,-0.327
20.68,135.07,-0.327
20.69,134.95,-0.327
20.70,134.83,-0.327
20.71,134.72,-0.327
20.73,134.60,-0.327
20.74,134.49,-0.327
20.75,134.37,-0.327
20.76,134.25,-0.327
20.77,134.13,-0.327
20.78,134.02,-0.327
20.79,133.90,-0.327
20.81,133.79,-0.326
20.82,133.67,-0.326
20.83,133.55,-0.326
20.84,133.44,-0.326
20.85,133.32,-0.326
20.87,133.20,-0.326
20.88,133.09,-0.326
20.89,132.97,-0.326
20.90,132.85,-0.326
20.91,132.74,-0.326
20.92,132.62,-0.326
20.93,132.50,-0.326
20.95,132.39,-0.326
20.96,132.27,-0.326
20.97,132.15,-0.326
20.98,132.04,-0.326
20.99,131.92,-0.326
21.01,131.80,-0.326
21.02,131.69,-0.326
21.03,131.57,-0.325
21.04,131.45,-0.325
21.05,131.34,-0.325
21.06,131.22,-0.325
21.08,131.11,-0.325
21.09,130.99,-0.325
21.10,130.87,-0.325
21.11,130.76,-0.325
21.12,130.64,-0.325
21.13,130.52,-0.325
21.14,130.41,-0.325
21.16,130.29,-0.325
21.17,130.17,-0.325
21.18,130.06,-0.325
21.19,129.94,-0.325
21.20,129.82,-0.325
21.22,129.71,-0.325
21.23,129.59,-0.324
21.24,129.47,-0.324
21.25,129.36,-0.324
21.26,129.24,-0.324
21.27,129.12,-0.324
21.28,129.01,-0.324
21.30,128.89,-0.324
21.31,128.77,-0.324
21.32,128.66,-0.324
21.33,128.54,-0.324
21.34,128.42,-0.324
21.36,128.31,-0.324
21.37,128.19,-0.324
21.38,128.07,-0.324
21.39,127.96,-0.324
21.40,127.84,-0.324
21.41,127.72,-0.323
21.43,127.61,-0.323
21.44,127.49,-0.323
21.45,127.38,-0.323
21.46,127.26,-0.323
21.47,127.14,-0.323
21.48,127.03,-0.323
21.49,126.91,-0.323
21.51,126.79,-0.323
21.52,126.68,-0.323
21.53,126.56,-0.323
21.54,126.44,-0.323
21.55,126.33,-0.323
21.57,126.21,-0.323
21.58,126.09,-0.323
21.59,125.98,-0.323
21.60,125.86,-0.323
21.61,125.74,-0.323
21.62,125.63,-0.323
21.63,125.51,-0.323
21.65,125.40,-0.322
21.66,125.28,-0.322
21.67,125.16,-0.322
21.68,125.04,-0.322
21.69,124.93,-0.322
21.71,124.81,-0.322
21.72,124.70,-0.322
21.73,124.58,-0.322
21.74,124.46,-0.322
21.75,124.35,-0.322
21.76,124.23,-0.322
21.78,124.11,-0.322
21.79,124.00,-0.322
21.80,123.88,-0.322
21.81,123.76,-0.322
21.82,123.65,-0.322
21.83,123.53,-0.322
21.84,123.41,-0.321
21.86,123.30,-0.321
21.87,123.18,-0.321
21.88,123.06,-0.321
21.89,122.95,-0.321
21.90,122.83,-0.321
21.92,122.72,-0.321
21.93,122.60,-0.321
21.94,122.48,-0.321
21.95,122.37,-0.321
21.96,122.25,-0.321
21.97,122.13,-0.321
21.98,122.02,-0.321
22.00,121.90,-0.321
22.01,121.78,-0.321
22.02,121.67,-0.321
22.03,121.55,-0.321
22.04,121.43,-0.321
22.06,121.32,-0.320
22.07,121.20,-0.320
22.08,121.08,-0.320
22.09,120.97,-0.320
22.10,120.85,-0.320
22.11,120.73,-0.320
22.13,120.62,-0.320
22.14,120.50,-0.320
22.15,120.38,-0.320
22.16,120.27,-0.320
22.17,120.15,-0.320
22.18,120.03,-0.320
22.19,119.92,-0.320
22.21,119.80,-0.320
22.22,119.68,-0.320
22.23,119.57,-0.320
22.24,119.45,-0.320
22.25,119.33,-0.320
22.27,119.22,-0.320
22.28,119.10,-0.320
22.29,118.99,-0.320
22.30,118.87,-0.320
22.31,118.75,-0.319
22.32,118.64,-0.319
22.33,118.52,-0.319
22.35,118.40,-0.319
22.36,118.29,-0.319
22.37,118.17,-0.319
22.38,118.05,-0.319
22.39,117.94,-0.319
22.41,117.82,-0.319
22.42,117.70,-0.319
22.43,117.59,-0.319
22.44,117.47,-0.319
22.45,117.35,-0.319
22.46,117.24,-0.319
22.48,117.12,-0.319
22.49,117.01,-0.319
22.50,116.89,-0.318
22.51,116.77,-0.318
22.52,116.66,-0.318
22.53,116.54,-0.318
22.54,116.42,-0.318
22.56,116.31,-0.318
[...]
66.44,27.59,-0.229
66.45,27.47,-0.229
66.46,27.36,-0.229
66.47,27.24,-0.229
66.48,27.12,-0.228
66.49,27.01,-0.228
66.51,26.89,-0.228
66.52,26.77,-0.227
66.53,26.66,-0.227
66.54,26.54,-0.227
66.55,26.42,-0.227
66.56,26.31,-0.227
66.58,26.19,-0.227
66.59,26.08,-0.226
66.60,25.96,-0.226
66.61,25.84,-0.226
66.62,25.73,-0.226
66.64,25.61,-0.225
66.65,25.49,-0.225
66.66,25.38,-0.225
66.67,25.26,-0.225
66.68,25.14,-0.224
66.69,25.02,-0.224
66.71,24.91,-0.224
66.72,24.79,-0.224
66.73,24.68,-0.223
66.74,24.56,-0.223
66.75,24.44,-0.223
66.76,24.32,-0.223
66.78,24.21,-0.223
66.79,24.09,-0.223
66.80,23.98,-0.222
66.81,23.86,-0.222
66.82,23.74,-0.222
66.83,23.62,-0.221
66.84,23.51,-0.221
66.86,23.39,-0.221
66.87,23.27,-0.220
66.88,23.16,-0.220
66.89,23.04,-0.220
66.90,22.92,-0.220
66.91,22.81,-0.220
66.93,22.69,-0.219
66.94,22.58,-0.219
66.95,22.46,-0.219
66.96,22.34,-0.219
66.97,22.23,-0.219
66.99,22.11,-0.219
67.00,21.99,-0.218
67.01,21.87,-0.218
67.02,21.76,-0.218
67.03,21.64,-0.218
67.04,21.52,-0.218
67.06,21.41,-0.218
67.07,21.29,-0.217
67.08,21.17,-0.217
67.09,21.06,-0.217
67.10,20.94,-0.217
67.11,20.82,-0.217
67.13,20.71,-0.217
67.14,20.59,-0.216
67.15,20.47,-0.216
67.16,20.36,-0.216
67.17,20.24,-0.216
67.18,20.12,-0.216
67.19,20.01,-0.216
67.21,19.89,-0.215
67.22,19.77,-0.215
67.23,19.65,-0.215
67.24,19.54,-0.215
67.25,19.42,-0.215
67.26,19.30,-0.215
67.28,19.19,-0.215
67.29,19.07,-0.214
67.30,18.95,-0.214
67.31,18.84,-0.214
67.32,18.72,-0.214
67.34,18.60,-0.213
67.35,18.49,-0.213
67.36,18.37,-0.213
67.37,18.25,-0.213
67.38,18.14,-0.212
67.39,18.02,-0.212
67.41,17.91,-0.212
67.42,17.79,-0.212
67.43,17.67,-0.212
67.44,17.56,-0.212
67.45,17.44,-0.212
67.46,17.32,-0.211
67.48,17.21,-0.211
67.49,17.09,-0.211
67.50,16.98,-0.211
67.51,16.86,-0.211
67.52,16.74,-0.210
67.53,16.62,-0.210
67.54,16.51,-0.210
67.56,16.39,-0.210
67.57,16.28,-0.210
67.58,16.16,-0.210
67.59,16.04,-0.210
67.60,15.93,-0.210
67.61,15.81,-0.209
67.63,15.69,-0.209
67.64,15.58,-0.209
67.65,15.46,-0.209
67.66,15.34,-0.209
67.67,15.23,-0.209
67.69,15.11,-0.209
67.70,14.99,-0.209
67.71,14.88,-0.208
67.72,14.76,-0.208
67.73,14.64,-0.208
67.74,14.53,-0.208
67.76,14.41,-0.208
67.77,14.29,-0.208
67.78,14.18,-0.207
67.79,14.06,-0.207
67.80,13.94,-0.207
67.81,13.83,-0.207
67.83,13.71,-0.207
67.84,13.60,-0.207
67.85,13.48,-0.206
67.86,13.36,-0.206
67.87,13.25,-0.206
67.88,13.13,-0.206
67.89,13.01,-0.206
67.91,12.90,-0.206
67.92,12.78,-0.206
67.93,12.66,-0.206
67.94,12.55,-0.205
67.95,12.43,-0.205
67.96,12.31,-0.205
67.98,12.20,-0.205
67.99,12.08,-0.205
68.00,11.97,-0.204
68.01,11.85,-0.204
68.02,11.73,-0.204
68.04,11.62,-0.204
68.05,11.50,-0.204
68.06,11.38,-0.204
68.07,11.27,-0.204
68.08,11.15,-0.204
68.09,11.03,-0.204
68.11,10.92,-0.203
68.12,10.80,-0.203
68.13,10.68,-0.203
68.14,10.57,-0.203
68.15,10.45,-0.203
68.16,10.33,-0.202
68.18,10.22,-0.202
68.19,10.10,-0.202
68.20,9.98,-0.202
68.21,9.87,-0.202
68.22,9.75,-0.202
68.23,9.63,-0.202
68.24,9.52,-0.202
68.26,9.40,-0.202
68.27,9.29,-0.201
68.28,9.17,-0.201
68.29,9.05,-0.201
68.30,8.94,-0.201
68.31,8.82,-0.201
68.33,8.70,-0.201
68.34,8.59,-0.201
68.35,8.47,-0.201
68.36,8.35,-0.200
68.37,8.24,-0.200
68.39,8.12,-0.200
68.40,8.00,-0.200
68.41,7.89,-0.200
68.42,7.77,-0.200
68.43,7.65,-0.200
68.44,7.54,-0.199
68.45,7.42,-0.199
68.47,7.30,-0.199
68.48,7.19,-0.199
68.49,7.07,-0.199
68.50,6.95,-0.199
68.51,6.84,-0.199
68.53,6.72,-0.199
68.54,6.61,-0.198
68.55,6.49,-0.198
68.56,6.37,-0.198
68.57,6.26,-0.198
68.58,6.14,-0.198
68.60,6.02,-0.198
68.61,5.91,-0.198
68.62,5.79,-0.197
68.63,5.67,-0.197
68.64,5.56,-0.197
68.65,5.44,-0.197
68.66,5.32,-0.197
68.68,5.21,-0.197
68.69,5.09,-0.197
68.70,4.97,-0.197
68.71,4.86,-0.196
68.72,4.74,-0.196
68.74,4.62,-0.196
68.75,4.51,-0.196
68.76,4.39,-0.196
68.77,4.27,-0.196
68.78,4.16,-0.196
68.79,4.04,-0.196
68.80,3.92,-0.195
68.82,3.81,-0.195
68.83,3.69,-0.195
68.84,3.57,-0.195
68.85,3.46,-0.195
68.86,3.34,-0.195
68.88,3.22,-0.195
68.89,3.11,-0.195
68.90,2.99,-0.195
68.91,2.87,-0.194
68.92,2.76,-0.194
68.93,2.64,-0.194
68.95,2.52,-0.194
68.96,2.41,
68.97,2.29,
68.98,2.17,
68.99,2.06,
69.00,,
69.00,,

[step]
Ramp 10.00 °C/min to 30.00 °C
Time,Temperature,Heat Flow (Normalized)
min,°C,W/g
70.01,0.13,-0.013
70.01,0.12,-0.013
70.01,0.13,-0.013
70.02,0.12,-0.013
70.02,0.12,-0.013
70.02,0.12,-0.013
70.03,0.12,-0.013
70.03,0.13,-0.013
70.03,0.13,-0.013
70.04,0.13,-0.013
70.04,0.13,-0.013
70.04,0.13,-0.013
70.05,0.13,-0.013
70.05,0.13,-0.013
70.05,0.13,-0.013
70.06,0.14,-0.013
70.06,0.14,-0.013
70.06,0.14,-0.013
70.07,0.14,-0.013
70.07,0.15,-0.013
70.07,0.15,-0.013
70.08,0.16,-0.013
70.08,0.16,-0.013
70.08,0.17,-0.013
70.09,0.17,-0.013
70.09,0.18,-0.013
70.09,0.19,-0.013
70.10,0.20,-0.013
70.10,0.21,-0.013
70.10,0.22,-0.013
70.11,0.23,-0.013
70.11,0.24,-0.013
70.11,0.25,-0.013
70.12,0.26,-0.012
70.12,0.28,-0.012
70.12,0.29,-0.010
70.13,0.30,-0.007
70.13,0.32,-0.004
70.13,0.33,-0.001
70.14,0.35,0.001
70.14,0.37,0.003
70.14,0.39,0.006
70.15,0.40,0.008
70.15,0.42,0.011
70.15,0.44,0.014
70.16,0.46,0.017
70.16,0.48,0.020
70.16,0.50,0.024
70.17,0.52,0.027
70.17,0.54,0.029
70.17,0.56,0.032
70.18,0.58,0.035
70.18,0.61,0.039
70.18,0.63,0.043
70.19,0.65,0.045
70.19,0.67,0.048
70.19,0.70,0.051
70.20,0.72,0.053
70.20,0.75,0.056
70.20,0.77,0.059
70.21,0.79,0.062
70.21,0.82,0.065
70.21,0.84,0.067
70.22,0.87,0.069
70.22,0.89,0.072
70.22,0.92,0.074
70.23,0.94,0.076
70.23,0.97,0.079
70.23,0.99,0.081
70.24,1.02,0.083
70.24,1.05,0.085
70.24,1.07,0.087
70.25,1.10,0.089
70.25,1.13,0.090
70.25,1.15,0.092
70.26,1.18,0.094
70.26,1.21,0.096
70.26,1.23,0.098
70.27,1.26,0.099
70.27,1.29,0.100
70.27,1.32,0.102
70.28,1.35,0.104
70.28,1.37,0.106
70.28,1.40,0.107
70.29,1.43,0.108
70.29,1.46,0.109
70.29,1.49,0.110
70.30,1.51,0.112
70.30,1.54,0.113
70.30,1.57,0.115
70.31,1.60,0.117
70.31,1.63,0.117
70.31,1.66,0.119
70.32,1.69,0.120
70.32,1.72,0.121
70.32,1.75,0.122
70.33,1.78,0.124
70.33,1.81,0.124
70.33,1.84,0.126
70.34,1.87,0.127
70.34,1.90,0.128
70.34,1.93,0.129
70.35,1.96,0.130
70.35,1.99,0.131
70.35,2.02,0.132
70.36,2.05,0.133
70.36,2.08,0.134
70.36,2.11,0.136
70.37,2.14,0.136
70.37,2.17,0.137
70.37,2.20,0.137
70.38,2.23,0.137
70.38,2.26,0.139
70.38,2.29,0.140
70.39,2.32,0.140
70.39,2.36,0.141
70.39,2.38,0.141
70.40,2.42,0.142
70.40,2.45,0.143
70.40,2.48,0.144
70.41,2.51,0.144
70.41,2.54,0.145
70.41,2.57,0.146
70.42,2.60,0.146
70.42,2.64,0.147
70.42,2.67,0.147
70.43,2.70,0.148
70.43,2.73,0.148
70.43,2.76,0.148
70.44,2.79,0.149
70.44,2.82,0.150
70.44,2.85,0.150
70.45,2.89,0.151
70.45,2.92,0.151
70.45,2.95,0.151
70.46,2.98,0.152
70.46,3.01,0.152
70.46,3.05,0.153
70.47,3.08,0.153
70.47,3.11,0.154
70.47,3.14,0.154
70.48,3.17,0.154
70.48,3.21,0.155
70.48,3.24,0.155
70.49,3.27,0.155
70.49,3.30,0.156
70.49,3.33,0.156
70.50,3.37,0.157
70.50,3.40,0.157
70.50,3.43,0.157
70.51,3.46,0.157
70.51,3.49,0.157
70.51,3.53,0.158
70.52,3.56,0.158
70.52,3.59,0.159
70.52,3.62,0.159
70.53,3.66,0.159
70.53,3.69,0.159
70.53,3.72,0.160
70.54,3.75,0.160
70.54,3.78,0.160
70.54,3.82,0.160
70.55,3.85,0.160
70.55,3.88,0.160
70.55,3.91,0.161
70.56,3.95,0.161
70.56,3.98,0.161
70.56,4.01,0.161
70.57,4.04,0.161
70.57,4.08,0.162
70.57,4.11,0.162
70.58,4.14,0.162
70.58,4.17,0.162
70.58,4.21,0.162
70.59,4.24,0.163
70.59,4.27,0.163
70.59,4.30,0.163
70.60,4.34,0.163
70.60,4.37,0.163
70.60,4.40,0.163
70.61,4.43,0.163
70.61,4.47,0.163
70.61,4.50,0.163
70.62,4.53,0.164
70.62,4.56,0.164
70.62,4.60,0.164
70.63,4.63,0.165
70.63,4.66,0.165
70.63,4.69,0.165
70.64,4.73,0.165
70.64,4.76,0.165
70.64,4.79,0.165
70.65,4.83,0.165
70.65,4.86,0.165
70.65,4.89,0.165
70.66,4.92,0.165
70.66,4.96,0.165
70.66,4.99,0.165
70.67,5.02,0.165
70.67,5.05,0.165
70.67,5.09,0.166
70.68,5.12,0.166
70.68,5.15,0.166
70.68,5.19,0.166
70.69,5.22,0.166
70.69,5.25,0.166
70.69,5.28,0.166
70.70,5.32,0.166
70.70,5.35,0.166
70.70,5.38,0.166
70.71,5.42,0.166
70.71,5.45,0.166
70.71,5.48,0.167
70.72,5.51,0.167
70.72,5.55,0.167
70.72,5.58,0.167
70.73,5.61,0.167
70.73,5.64,0.167
70.73,5.68,0.167
70.74,5.71,0.167
70.74,5.75,0.167
70.74,5.78,0.167
70.75,5.81,0.167
70.75,5.84,0.167
70.75,5.88,0.167
70.76,5.91,0.167
70.76,5.94,0.167
70.76,5.98,0.168
70.77,6.01,0.168
70.77,6.04,0.168
70.77,6.07,0.168
70.78,6.11,0.168
70.78,6.14,0.168
70.78,6.17,0.168
70.79,6.21,0.168
70.79,6.24,0.168
70.79,6.27,0.168
70.80,6.31,0.168
70.80,6.34,0.169
70.80,6.37,0.169
70.81,6.40,0.169
70.81,6.44,0.169
70.81,6.47,0.169
70.82,6.50,0.169
70.82,6.54,0.169
70.82,6.57,0.169
70.83,6.60,0.169
70.83,6.63,0.169
70.83,6.67,0.169
70.84,6.70,0.169
70.84,6.73,0.169
70.84,6.77,0.169
70.85,6.80,0.169
70.85,6.83,0.169
70.85,6.87,0.169
70.86,6.90,0.169
70.86,6.93,0.169
70.86,6.97,0.169
70.87,7.00,0.169
70.87,7.03,0.169
70.87,7.06,0.169
70.88,7.10,0.170
70.88,7.13,0.170
70.88,7.16,0.170
70.89,7.20,0.170
70.89,7.23,0.170
70.89,7.26,0.170
70.90,7.30,0.170
70.90,7.33,0.170
70.90,7.36,0.170
70.91,7.39,0.170
70.91,7.43,0.170
70.91,7.46,0.170
70.92,7.49,0.170
70.92,7.53,0.170
70.92,7.56,0.170
70.93,7.59,0.170
70.93,7.63,0.170
70.93,7.66,0.170
70.94,7.69,0.170
70.94,7.73,0.170
70.94,7.76,0.170
70.95,7.79,0.170
70.95,7.83,0.170
70.95,7.86,0.171
70.96,7.89,0.171
70.96,7.92,0.171
70.96,7.96,0.171
70.97,7.99,0.171
70.97,8.02,0.171
70.97,8.06,0.171
70.98,8.09,0.171
70.98,8.12,0.171
70.98,8.16,0.171
70.99,8.19,0.171
70.99,8.22,0.171
70.99,8.26,0.171
71.00,8.29,0.171
71.00,8.32,0.171
71.00,8.36,0.171
71.01,8.39,0.171
71.01,8.42,0.171
71.01,8.46,0.171
71.02,8.49,0.171
71.02,8.52,0.171
71.02,8.55,0.171
71.03,8.59,0.171
71.03,8.62,0.171
71.03,8.65,0.172
71.04,8.69,0.172
71.04,8.72,0.172
71.04,8.75,0.172
71.05,8.79,0.172
71.05,8.82,0.172
71.05,8.85,0.172
71.06,8.89,0.172
71.06,8.92,0.172
71.06,8.95,0.172
71.07,8.99,0.172
71.07,9.02,0.172
71.07,9.05,0.172
71.08,9.09,0.172
71.08,9.12,0.172
71.08,9.15,0.172
71.09,9.18,0.172
71.09,9.22,0.172
71.09,9.25,0.172
71.10,9.29,0.172
71.10,9.32,0.172
71.10,9.35,0.172
71.11,9.38,0.172
71.11,9.42,0.172
71.11,9.45,0.172
71.12,9.49,0.172
71.12,9.52,0.173
71.12,9.55,0.173
71.13,9.58,0.173
71.13,9.62,0.173
71.13,9.65,0.173
71.14,9.68,0.173
71.14,9.72,0.173
71.14,9.75,0.173
71.15,9.78,0.173
71.15,9.82,0.173
71.15,9.85,0.173
71.16,9.88,0.173
71.16,9.92,0.173
71.16,9.95,0.173
71.17,9.98,0.173
71.17,10.01,0.173
71.17,10.05,0.173
71.18,10.08,0.173
71.18,10.12,0.173
71.18,10.15,0.173
71.19,10.18,0.173
71.19,10.22,0.173
71.19,10.25,0.173
71.20,10.28,0.173
71.20,10.31,0.173
71.20,10.35,0.173
71.21,10.38,0.173
71.21,10.41,0.173
71.21,10.45,0.174
71.22,10.48,0.174
71.22,10.51,0.174
71.22,10.55,0.174
71.23,10.58,0.174
71.23,10.61,0.174
71.23,10.65,0.174
71.24,10.68,0.174
71.24,10.71,0.174
71.24,10.75,0.174
71.25,10.78,0.174
71.25,10.81,0.174
71.25,10.85,0.174
71.26,10.88,0.174
71.26,10.91,0.174
71.26,10.95,0.174
71.27,10.98,0.174
71.27,11.01,0.174
71.27,11.05,0.174
71.28,11.08,0.174
71.28,11.11,0.174
71.28,11.14,0.174
71.29,11.18,0.174
71.29,11.21,0.174
71.29,11.25,0.174
71.30,11.28,0.174
71.30,11.31,0.174
71.30,11.34,0.174
71.31,11.38,0.175
71.31,11.41,0.175
71.31,11.44,0.175
71.32,11.48,0.175
71.32,11.51,0.175
71.32,11.54,0.175
71.33,11.58,0.175
71.33,11.61,0.175
71.33,11.64,0.175
71.34,11.68,0.175
71.34,11.71,0.175
71.34,11.74,0.175
71.35,11.78,0.175
71.35,11.81,0.175
71.35,11.84,0.175
71.36,11.88,0.175
71.36,11.91,0.175
71.36,11.94,0.175
71.37,11.98,0.175
71.37,12.01,0.175
71.37,12.04,0.175
71.38,12.08,0.175
71.38,12.11,0.175
71.38,12.14,0.175
71.39,12.18,0.175
71.39,12.21,0.175
71.39,12.24,0.175
71.40,12.27,0.175
71.40,12.31,0.175
71.40,12.34,0.175
71.41,12.38,0.175
71.41,12.41,0.175
71.41,12.44,0.175
71.42,12.48,0.176
71.42,12.51,0.176
71.42,12.54,0.176
71.43,12.58,0.176
71.43,12.61,0.176
71.43,12.64,0.176
71.44,12.68,0.176
71.44,12.71,0.176
71.44,12.74,0.176
71.45,12.78,0.176
71.45,12.81,0.176
71.45,12.84,0.176
71.46,12.88,0.176
71.46,12.91,0.176
71.46,12.94,0.176
71.47,12.97,0.176
71.47,13.01,0.176
71.47,13.04,0.176
71.48,13.07,0.176
71.48,13.11,0.176
71.48,13.14,0.176
71.49,13.17,0.176
71.49,13.21,0.176
71.49,13.24,0.176
71.50,13.28,0.176
71.50,13.31,0.176
71.50,13.34,0.176
71.51,13.37,0.176
71.51,13.41,0.176
71.51,13.44,0.176
71.52,13.47,0.176
71.52,13.51,0.176
71.52,13.54,0.176
71.53,13.58,0.177
71.53,13.61,0.177
71.53,13.64,0.177
71.54,13.67,0.177
71.54,13.71,0.177
71.54,13.74,0.177
71.55,13.78,0.177
71.55,13.81,0.177
71.55,13.84,0.177
71.56,13.88,0.177
71.56,13.91,0.177
71.56,13.94,0.177
71.57,13.97,0.177
71.57,14.01,0.177
71.57,14.04,0.177
71.58,14.07,0.177
71.58,14.11,0.177
71.58,14.14,0.177
71.59,14.17,0.177
71.59,14.21,0.177
71.59,14.24,0.177
71.60,14.27,0.177
71.60,14.31,0.177
71.60,14.34,0.177
71.61,14.37,0.177
71.61,14.41,0.177
71.61,14.44,0.177
71.62,14.47,0.177
71.62,14.51,0.177
71.62,14.54,0.177
71.63,14.57,0.177
71.63,14.61,0.177
71.63,14.64,0.177
71.64,14.67,0.178
71.64,14.71,0.178
71.64,14.74,0.178
71.65,14.77,0.178
71.65,14.81,0.178
71.65,14.84,0.178
71.66,14.87,0.178
71.66,14.91,0.178
71.66,14.94,0.178
71.67,14.97,0.178
71.67,15.01,0.178
71.67,15.04,0.178
71.68,15.07,0.178
71.68,15.11,0.178
71.68,15.14,0.178
71.69,15.17,0.178
71.69,15.21,0.178
71.69,15.24,0.178
71.70,15.27,0.178
71.70,15.31,0.178
71.70,15.34,0.178
71.71,15.37,0.178
71.71,15.41,0.178
71.71,15.44,0.178
71.72,15.47,0.178
71.72,15.51,0.178
71.72,15.54,0.178
71.73,15.57,0.178
71.73,15.61,0.178
71.73,15.64,0.178
71.74,15.67,0.178
71.74,15.71,0.178
71.74,15.74,0.178
71.75,15.77,0.179
71.75,15.81,0.179
71.75,15.84,0.179
71.76,15.87,0.179
71.76,15.91,0.179
71.76,15.94,0.179
71.77,15.97,0.179
71.77,16.01,0.179
71.77,16.04,0.179
71.78,16.07,0.179
71.78,16.11,0.179
71.78,16.14,0.179
71.79,16.17,0.179
71.79,16.21,0.179
71.79,16.24,0.179
71.80,16.27,0.179
71.80,16.31,0.179
71.80,16.34,0.179
71.81,16.37,0.179
71.81,16.41,0.179
71.81,16.44,0.179
71.82,16.47,0.179
71.82,16.51,0.179
71.82,16.54,0.179
71.83,16.57,0.179
71.83,16.61,0.179
71.83,16.64,0.179
71.84,16.67,0.179
71.84,16.70,0.179
71.84,16.74,0.179
71.85,16.77,0.179
71.85,16.81,0.179
71.85,16.84,0.179
71.86,16.87,0.179
71.86,16.91,0.179
71.86,16.94,0.179
71.87,16.97,0.179
71.87,17.01,0.180
71.87,17.04,0.180
71.88,17.07,0.180
71.88,17.11,0.180
71.88,17.14,0.180
71.89,17.17,0.180
71.89,17.21,0.180
71.89,17.24,0.180
71.90,17.27,0.180
71.90,17.31,0.180
71.90,17.34,0.180
71.91,17.37,0.180
71.91,17.41,0.180
71.91,17.44,0.180
71.92,17.47,0.180
71.92,17.51,0.180
71.92,17.54,0.180
71.93,17.57,0.180
71.93,17.61,0.180
71.93,17.64,0.180
71.94,17.67,0.180
71.94,17.71,0.180
71.94,17.74,0.180
71.95,17.77,0.180
71.95,17.81,0.180
71.95,17.84,0.180
71.96,17.87,0.180
71.96,17.91,0.180
71.96,17.94,0.180
71.97,17.97,0.180
71.97,18.01,0.180
71.97,18.04,0.180
71.98,18.07,0.180
71.98,18.11,0.180
71.98,18.14,0.181
71.99,18.17,0.181
71.99,18.21,0.181
71.99,18.24,0.181
72.00,18.27,0.181
72.00,18.31,0.181
72.00,18.34,0.181
72.01,18.37,0.181
72.01,18.41,0.181
72.01,18.44,0.181
72.02,18.47,0.181
72.02,18.51,0.181
72.02,18.54,0.181
72.03,18.57,0.181
72.03,18.61,0.181
72.03,18.64,0.181
72.04,18.67,0.181
72.04,18.71,0.181
72.04,18.74,0.181
72.05,18.77,0.181
72.05,18.81,0.181
72.05,18.84,0.181
72.06,18.87,0.181
72.06,18.91,0.181
72.06,18.94,0.181
72.07,18.97,0.181
72.07,19.01,0.181
72.07,19.04,0.181
72.08,19.07,0.181
72.08,19.11,0.181
72.08,19.14,0.181
72.09,19.17,0.181
72.09,19.21,0.181
72.09,19.24,0.181
72.10,19.27,0.181
72.10,19.31,0.181
72.10,19.34,0.181
72.11,19.37,0.181
72.11,19.41,0.181
72.11,19.44,0.181
72.12,19.47,0.181
72.12,19.51,0.182
72.12,19.54,0.182
72.13,19.57,0.182
72.13,19.61,0.182
72.13,19.64,0.182
72.14,19.67,0.182
72.14,19.71,0.182
72.14,19.74,0.182
72.15,19.77,0.182
72.15,19.81,0.182
72.15,19.84,0.182
72.16,19.87,0.182
72.16,19.91,0.182
72.16,19.94,0.182
72.17,19.97,0.182
72.17,20.01,0.182
72.17,20.04,0.182
72.18,20.07,0.182
72.18,20.11,0.182
72.18,20.14,0.182
72.19,20.17,0.182
72.19,20.21,0.182
72.19,20.24,0.182
72.20,20.28,0.182
72.20,20.31,0.182
72.20,20.34,0.182
72.21,20.37,0.182
72.21,20.41,0.182
72.21,20.44,0.182
72.22,20.47,0.182
72.22,20.51,0.182
72.22,20.54,0.182
72.23,20.57,0.182
72.23,20.61,0.182
72.23,20.64,0.182
72.24,20.67,0.182
72.24,20.71,0.182
72.24,20.74,0.183
72.25,20.77,0.183
72.25,20.81,0.183
72.25,20.84,0.183
72.26,20.87,0.183
72.26,20.91,0.183
72.26,20.94,0.183
72.27,20.97,0.183
72.27,21.01,0.183
72.27,21.04,0.183
72.28,21.07,0.183
72.28,21.11,0.183
72.28,21.14,0.183
72.29,21.17,0.183
72.29,21.21,0.183
72.29,21.24,0.183
72.30,21.27,0.183
72.30,21.31,0.183
72.30,21.34,0.183
72.31,21.37,0.183
72.31,21.41,0.183
72.31,21.44,0.183
72.32,21.47,0.183
72.32,21.51,0.183
72.32,21.54,0.183
72.33,21.57,0.183
72.33,21.61,0.183
72.33,21.64,0.183
72.34,21.68,0.183
72.34,21.71,0.183
72.34,21.74,0.183
72.35,21.77,0.183
72.35,21.81,0.184
72.35,21.84,0.184
72.36,21.87,0.184
72.36,21.91,0.184
72.36,21.94,0.184
72.37,21.97,0.184
72.37,22.01,0.184
72.37,22.04,0.184
72.38,22.08,0.184
72.38,22.11,0.184
72.38,22.14,0.184
72.39,22.17,0.184
72.39,22.21,0.184
72.39,22.24,0.184
72.40,22.28,0.184
72.40,22.31,0.184
72.40,22.34,0.184
72.41,22.37,0.184
72.41,22.41,0.184
72.41,22.44,0.184
72.42,22.47,0.184
72.42,22.51,0.184
72.42,22.54,0.184
72.43,22.57,0.184
72.43,22.61,0.184
72.43,22.64,0.184
72.44,22.67,0.184
72.44,22.71,0.184
72.44,22.74,0.184
72.45,22.78,0.184
72.45,22.81,0.184
72.45,22.84,0.184
72.46,22.87,0.184
72.46,22.91,0.184
72.46,22.94,0.184
72.47,22.98,0.184
72.47,23.01,0.185
72.47,23.04,0.185
72.48,23.07,0.185
72.48,23.11,0.185
72.48,23.14,0.185
72.49,23.17,0.185
72.49,23.21,0.185
72.49,23.24,0.185
72.50,23.28,0.185
72.50,23.31,0.185
72.50,23.34,0.185
72.51,23.37,0.185
72.51,23.41,0.185
72.51,23.44,0.185
72.52,23.48,0.185
72.52,23.51,0.185
72.52,23.54,0.185
72.53,23.58,0.185
72.53,23.61,0.185
72.53,23.64,0.185
72.54,23.68,0.185
72.54,23.71,0.185
72.54,23.74,0.185
72.55,23.77,0.185
72.55,23.81,0.185
72.55,23.84,0.185
72.56,23.88,0.185
72.56,23.91,0.185
72.56,23.94,0.185
72.57,23.98,0.185
72.57,24.01,0.185
72.57,24.04,0.186
72.58,24.08,0.186
72.58,24.11,0.186
72.58,24.14,0.186
72.59,24.18,0.186
72.59,24.21,0.186
72.59,24.24,0.186
72.60,24.28,0.186
72.60,24.31,0.186
72.60,24.34,0.186
72.61,24.38,0.186
72.61,24.41,0.186
72.61,24.44,0.186
72.62,24.48,0.186
72.62,24.51,0.186
72.62,24.54,0.186
72.63,24.58,0.186
72.63,24.61,0.186
72.63,24.64,0.186
72.64,24.68,0.186
72.64,24.71,0.186
72.64,24.74,0.186
72.65,24.78,0.186
72.65,24.81,0.186
72.65,24.84,0.186
72.66,24.88,0.186
72.66,24.91,0.186
72.66,24.94,0.186
72.67,24.98,0.186
72.67,25.01,0.186
72.67,25.04,0.186
72.68,25.08,0.186
72.68,25.11,0.186
72.68,25.14,0.186
72.69,25.18,0.186
72.69,25.21,0.186
72.69,25.24,0.186
72.70,25.28,0.187
72.70,25.31,0.187
72.70,25.34,0.187
72.71,25.38,0.187
72.71,25.41,0.187
72.71,25.44,0.187
72.72,25.48,0.187
72.72,25.51,0.187
72.72,25.54,0.187
72.73,25.58,0.187
72.73,25.61,0.187
72.73,25.64,0.187
72.74,25.68,0.187
72.74,25.71,0.187
72.74,25.74,0.187
72.75,25.78,0.187
72.75,25.81,0.187
72.75,25.84,0.187
72.76,25.88,0.187
72.76,25.91,0.187
72.76,25.94,0.187
72.77,25.98,0.187
72.77,26.01,0.187
72.77,26.04,0.187
72.78,26.08,0.187
72.78,26.11,0.187
72.78,26.14,0.187
72.79,26.18,0.187
72.79,26.21,0.187
72.79,26.24,0.187
72.80,26.28,0.187
72.80,26.31,0.187
72.80,26.34,0.187
72.81,26.38,0.187
72.81,26.41,0.188
72.81,26.44,0.188
72.82,26.48,0.188
72.82,26.51,0.188
72.82,26.54,0.188
72.83,26.58,0.188
72.83,26.61,0.188
72.83,26.64,0.188
72.84,26.68,0.188
72.84,26.71,0.188
72.84,26.74,0.188
72.85,26.78,0.188
72.85,26.81,0.188
72.85,26.84,0.188
72.86,26.88,0.188
72.86,26.91,0.188
72.86,26.94,0.188
72.87,26.98,0.188
72.87,27.01,0.188
72.87,27.04,0.188
72.88,27.08,0.188
72.88,27.11,0.188
72.88,27.14,0.188
72.89,27.18,0.188
72.89,27.21,0.188
72.89,27.24,0.188
72.90,27.28,0.188
72.90,27.31,0.188
72.90,27.34,0.189
72.91,27.38,0.189
72.91,27.41,0.189
72.91,27.44,0.189
72.92,27.48,0.189
72.92,27.51,0.189
72.92,27.54,0.189
72.93,27.58,0.189
72.93,27.61,0.189
72.93,27.64,0.189
72.94,27.68,0.189
72.94,27.71,0.189
72.94,27.74,0.189
72.95,27.78,0.189
72.95,27.81,
72.95,27.84,
72.96,27.88,
72.96,27.91,
72.96,27.94,
72.97,27.98,
72.97,28.01,
72.97,28.04,
72.98,28.08,
72.98,28.11,
72.98,28.14,
72.99,28.18,
72.99,28.21,
72.99,28.24,
73.00,28.28,
73.00,,
73.00,,
73.01,,