File: DSC/2025_06_14_CBN_Saccharin_MC_n60C_200C_10Cmin_x3.csv
Filename,2025_06_14_CBN_Saccharin_MC_n60C_200C_10Cmin_x3
Instrument name,DSC2A-00468 (192.168.1.100)
Operator,Yarger
rundate,6/14/2025
Sample name,2025_06_14_CBN_Saccharin_MC_n60C_200C_10Cmin_x3
proceduresegments,Data Off ; Equilibrate -60.00 °C; Data On ; Ramp 10.00 °C/min to 200.00 °C; Data Off ; Isothermal 2.0 min; Data On ; Ramp 10.00 °C/min to -60.00 °C; Data Off ; Isothermal 2.0 min; Data On ; Ramp 10.00 °C/min to 200.00 °C; Data Off ; Isothermal 2.0 min; Data On ; Ramp 10.00 °C/min to -60.00 °C; Data Off ; Isothermal 2.0 min; Data On ; Ramp 10.00 °C/min to 30.00 °C
[File Parameters]
Run date,6/14/2025 8:52:39 PM
Trios version,5.1.1.46572
Original File Name,
Current File Name,D:\DSC2500\JYarger\2025_06_14_CBN_Saccharin_MC_n60C_200C_10Cmin_x3.tri
[Procedure]
Procedure Name,CBN_Saccharin_n60C_200C_10Cmin_x3
Sample Name,2025_06_14_CBN_Saccharin_MC_n60C_200C_10Cmin_x3
Sample Mass,4.24 mg
Reference Sample Mass,0 mg
Pan Mass,57.59 mg
Pan Number,31
Reference Pan Mass,57.05 mg
Reference Pan Number,28
Pan Type,Tzero Aluminum Hermetic
Comments,Al Hermetic DSC Consumables sealed Pan/Lid. A2 Tray (Google Sheet: DSC_Samples_A2_Tray_May2025)
Project Name,CA
Operator,Yarger
Test,Custom
Unload Max Temperature,30
Unload Min Temperature,30
Load Max Temperature,30
Load Min Temperature,30
Stop on Gas Flow Error,Yes
[Signal List]
Signal #1,Time (min)
Signal #2,Temperature (°C)
Signal #3,Heat Flow (mW)
Signal #4,Delta T (µV)
Signal #5,Delta Tzero (µV)
Signal #6,Tzero Temperature (°C)
Signal #7,Cell Purge (mL/min)
Signal #8,Heater Temp (°C)
Signal #9,Power Delivered (W)
Signal #10,Reference Junction Temperature (°C)
Signal #11,Flange Temperature (°C)
Signal #12,Heat Flow Phase (rad)
Signal #13,Total Heat Capacity (J/°C)
Signal #14,Heat Capacity (J/°C)
[Configuration]
Company Name,ASU
Instrument Name,DSC2A-00468
Instrument Type,DSC2500
Serial Number,DSC2A-00468
IP,192.168.1.100
Location of Instrument,MRRC
DisplayType,Unknown
Sample Interval ,0.1 s/pt
Selected Heat Flow,T4P
Exotherm Direction,Down
Cell Serial,DRC2-00792
Lid Type,Standard
Cooler,RCS 90
Leave Cooler on at End of Sequence,On
Gas 2,Nitrogen
Gas Selected,Channel 1
Flow Rate,50 mL/min
Secondary Purge,On
Licensed Heat Flow,Heat Flow T4P
Modulation Licensed,Yes
[Versions]
Common IDD Version,1
Cortex Version,VER 2.10.2.31
Driver,5.0.0.6
GDM Version,1.0.3.3
TouchscreenVersion,1.0.0.16145
FEP Version,1.2.1.21
FEP Bootloader,2.0.0.5
AutoSampler Version,2.1.1.26
Auto Sampler Bootloader,2.0.0.5
FCM Version,1.1.0.3
FCM Bootloader,2.0.0.5
[Experiment Logs]
Experiment Log Entry # 1,Data On set to 0
Experiment Log Entry # 3,Equilibrate Segment -60 (C) Started
Experiment Log Entry # 5,Air Cool is off.
Experiment Log Entry # 7,Data On set to 1
Experiment Log Entry # 9,Ramp Segment 10 C/min to 200 Started
Experiment Log Entry # 11,Data On set to 0
Experiment Log Entry # 13,Isothermal Segment 2 min started
Experiment Log Entry # 15,Data On set to 1
Experiment Log Entry # 17,Ramp Segment 10 C/min to -60 Started
Experiment Log Entry # 19,Data On set to 0
Experiment Log Entry # 21,Isothermal Segment 2 min started
Experiment Log Entry # 23,Data On set to 1
Experiment Log Entry # 25,Ramp Segment 10 C/min to 200 Started
Experiment Log Entry # 27,Data On set to 0
Experiment Log Entry # 29,Isothermal Segment 2 min started
Experiment Log Entry # 31,Data On set to 1
Experiment Log Entry # 33,Ramp Segment 10 C/min to -60 Started
Experiment Log Entry # 35,Data On set to 0
Experiment Log Entry # 37,Isothermal Segment 2 min started
Experiment Log Entry # 39,Data On set to 1
Experiment Log Entry # 41,Ramp Segment 10 C/min to 30 Started
[Method Log]
Method Log Entry # 1,Data Off
Method Log Entry # 2,Equilibrate -60 °C
Method Log Entry # 3,Data On
Method Log Entry # 4,(Ramp 192286) Ramp 10 °C/minute to 200 °C
Method Log Entry # 5,Data Off
Method Log Entry # 6,Isothermal 2 minutes
Method Log Entry # 7,Data On
Method Log Entry # 8,(Ramp 192290) Ramp 10 °C/minute to -60 °C
Method Log Entry # 9,Data Off
Method Log Entry # 10,Isothermal 2 minutes
Method Log Entry # 11,Data On
Method Log Entry # 12,(Ramp 192294) Ramp 10 °C/minute to 200 °C
Method Log Entry # 13,Data Off
Method Log Entry # 14,Isothermal 2 minutes
Method Log Entry # 15,Data On
Method Log Entry # 16,(Ramp 192298) Ramp 10 °C/minute to -60 °C
Method Log Entry # 17,Data Off
Method Log Entry # 18,Isothermal 2 minutes
Method Log Entry # 19,Data On
Method Log Entry # 20,(Ramp 192302) Ramp 10 °C/minute to 30 °C
Cell Serial,DRC2-00792
[T1 Calibration]
Slope,-0.008529666
Offset,9.636258
Initial Temperature,98.23
GUID,f8bfdadc-4977-4fdf-ba6d-0ba9134940c3
[TZero Calibration]
Date Applied,11/29/2022 4:06:13 PM
Description,From -89.059 °C to 396.009 °C at 20.000°C/min
Gas Type,Nitrogen
Pan Type,None
Source Files 1,C:\Users\yargerlab\Desktop\DSC Data\General\TZero_calibration_11_29_22_2nd(2).tri
Source Files 2,C:\Users\yargerlab\Desktop\DSC Data\General\TZero_calibration_11_29_22_2nd(3).tri
Delta T Offset,13.05235
Delta T Slope,-0.007271007
Delta T0 Offset,-13.69128
Delta T0 Slope,0.06063341
[Temperature Calibration]
Date Applied,11/29/2022 7:12:28 PM
Description,From 106.590 °C to 186.590 °C at 10.000°C/min
Gas Type,Nitrogen
Pan Type,Tzero Aluminum Hermetic
Source Files 1,C:\Users\yargerlab\Desktop\DSC Data\General\Indium(6).tri
Measured 1,157.391
Known 1,156.598
[Cell Constant Calibration]
Date Applied,11/29/2022 7:12:29 PM
Description,From 106.590 °C to 186.590 °C at 10.000°C/min
Gas Type,Nitrogen
Pan Type,Tzero Aluminum Hermetic
Source Files 1,C:\Users\yargerlab\Desktop\DSC Data\General\Indium(6).tri
T4P KCell,1.006051
Onset Slope,63.26126 mW/°C
[Direct Cp Calibration]
Date Applied,11/30/2022 11:04:51 AM
Description,From -79.983 °C to 298.409 °C at 10.000°C/min
Gas Type,Nitrogen
Pan Type,Tzero Aluminum Hermetic
Source Files 1,C:\Users\yargerlab\Desktop\DSC Data\General\Sapphire_Heat_Capacity_11_30_22.tri
[Rev Cp Calibration]
Date Applied,11/30/2022 1:58:51 PM
Description,From -79.996 °C to 292.812 °C at 3.000°C/min
Gas Type,Nitrogen
Pan Type,Tzero Aluminum Hermetic
Source Files 1,C:\Users\yargerlab\Desktop\DSC Data\General\Sapphire_MDSC_Calibration_11_30_22.tri
[step]
Ramp 10.00 °C/min to 200.00 °C
Time,Temperature,Heat Flow (Normalized)
min,°C,W/g
0.00,-59.68,-0.079
0.02,-59.69,-0.078
0.04,-59.69,-0.070
0.05,-59.69,-0.066
0.07,-59.67,-0.068
0.09,-59.63,-0.071
0.11,-59.57,-0.075
0.13,-59.50,-0.079
0.15,-59.40,-0.079
0.16,-59.29,-0.066
0.18,-59.17,-0.045
0.20,-59.03,-0.025
0.22,-58.90,-0.003
0.24,-58.75,0.017
0.26,-58.60,0.036
0.28,-58.45,0.053
0.29,-58.29,0.069
0.31,-58.13,0.080
0.33,-57.97,0.094
0.35,-57.80,0.105
0.37,-57.64,0.113
0.39,-57.47,0.121
0.40,-57.30,0.127
0.42,-57.13,0.133
0.44,-56.96,0.140
0.46,-56.79,0.141
0.48,-56.61,0.146
0.50,-56.44,0.150
0.51,-56.26,0.153
0.53,-56.09,0.155
0.55,-55.91,0.158
0.57,-55.73,0.161
0.59,-55.56,0.162
0.60,-55.38,0.165
0.62,-55.20,0.165
0.64,-55.02,0.166
0.66,-54.85,0.167
0.68,-54.67,0.168
0.70,-54.49,0.169
0.72,-54.31,0.170
0.73,-54.13,0.170
0.75,-53.95,0.171
0.77,-53.77,0.171
0.79,-53.59,0.172
0.81,-53.41,0.173
0.83,-53.23,0.173
0.84,-53.05,0.174
0.86,-52.87,0.174
0.88,-52.69,0.175
0.90,-52.51,0.175
0.92,-52.33,0.176
0.93,-52.14,0.176
0.95,-51.96,0.177
0.97,-51.78,0.177
0.99,-51.60,0.177
1.01,-51.42,0.179
1.03,-51.24,0.179
1.05,-51.06,0.179
1.06,-50.87,0.179
1.08,-50.69,0.180
1.10,-50.51,0.180
1.12,-50.33,0.181
1.14,-50.15,0.181
1.16,-49.97,0.182
1.17,-49.78,0.182
1.19,-49.60,0.182
1.21,-49.42,0.182
1.23,-49.24,0.183
1.25,-49.06,0.183
1.27,-48.87,0.183
1.28,-48.69,0.183
1.30,-48.51,0.183
1.32,-48.32,0.183
1.34,-48.14,0.183
1.36,-47.96,0.184
1.38,-47.77,0.184
1.39,-47.59,0.184
1.41,-47.41,0.184
1.43,-47.22,0.184
1.45,-47.04,0.185
1.47,-46.86,0.185
1.48,-46.67,0.185
1.50,-46.49,0.185
1.52,-46.31,0.186
1.54,-46.12,0.186
1.56,-45.94,0.186
1.58,-45.76,0.186
1.59,-45.57,0.186
1.61,-45.39,0.186
1.63,-45.21,0.186
1.65,-45.02,0.186
1.67,-44.84,0.186
1.69,-44.66,0.187
1.71,-44.48,0.187
1.72,-44.29,0.187
1.74,-44.11,0.187
1.76,-43.93,0.187
1.78,-43.74,0.187
1.80,-43.56,0.187
1.82,-43.38,0.187
1.83,-43.20,0.187
1.85,-43.01,0.187
1.87,-42.83,0.187
1.89,-42.64,0.187
1.91,-42.46,0.187
1.93,-42.28,0.187
1.94,-42.09,0.187
1.96,-41.91,0.188
1.98,-41.73,0.188
2.00,-41.54,0.188
2.02,-41.36,0.188
2.03,-41.18,0.188
2.05,-40.99,0.188
2.07,-40.81,0.188
2.09,-40.63,0.188
2.11,-40.44,0.188
2.13,-40.26,0.188
2.14,-40.08,0.188
2.16,-39.89,0.189
2.18,-39.71,0.189
2.20,-39.52,0.189
2.22,-39.34,0.189
2.24,-39.16,0.189
2.26,-38.97,0.189
2.27,-38.79,0.189
2.29,-38.61,0.189
2.31,-38.42,0.189
2.33,-38.24,0.189
2.35,-38.06,0.189
2.36,-37.87,0.189
2.38,-37.69,0.189
2.40,-37.50,0.189
2.42,-37.32,0.190
2.44,-37.14,0.190
2.46,-36.95,0.190
2.48,-36.77,0.190
2.49,-36.59,0.190
2.51,-36.40,0.190
2.53,-36.22,0.190
2.55,-36.04,0.190
2.57,-35.86,0.190
2.59,-35.67,0.190
2.60,-35.49,0.190
2.62,-35.31,0.190
2.64,-35.12,0.190
2.66,-34.94,0.190
2.68,-34.76,0.190
2.69,-34.57,0.190
2.71,-34.39,0.190
2.73,-34.20,0.190
2.75,-34.02,0.190
2.77,-33.84,0.190
2.79,-33.65,0.191
2.81,-33.47,0.191
2.82,-33.28,0.191
2.84,-33.10,0.191
2.86,-32.92,0.191
2.88,-32.73,0.191
2.90,-32.55,0.191
2.91,-32.37,0.191
2.93,-32.18,0.191
2.95,-32.00,0.192
2.97,-31.81,0.192
2.99,-31.63,0.192
3.01,-31.45,0.192
3.03,-31.26,0.192
3.04,-31.08,0.192
3.06,-30.90,0.192
3.08,-30.71,0.192
3.10,-30.53,0.192
3.12,-30.35,0.192
3.14,-30.16,0.192
3.15,-29.98,0.192
3.17,-29.79,0.192
3.19,-29.61,0.193
3.21,-29.43,0.193
3.23,-29.24,0.193
3.24,-29.06,0.193
3.26,-28.88,0.193
3.28,-28.69,0.193
3.30,-28.51,0.193
3.32,-28.33,0.193
3.34,-28.14,0.193
3.36,-27.96,0.193
3.37,-27.77,0.193
3.39,-27.59,0.193
3.41,-27.41,0.193
3.43,-27.22,0.193
3.45,-27.04,0.194
3.46,-26.86,0.194
3.48,-26.67,0.194
3.50,-26.49,0.194
3.52,-26.30,0.194
3.54,-26.12,0.194
3.56,-25.94,0.194
3.58,-25.75,0.194
3.59,-25.57,0.194
3.61,-25.39,0.194
3.63,-25.20,0.194
3.65,-25.02,0.194
3.67,-24.83,0.194
3.69,-24.65,0.194
3.70,-24.47,0.195
3.72,-24.29,0.195
3.74,-24.10,0.195
3.76,-23.92,0.195
3.78,-23.73,0.195
3.79,-23.55,0.195
3.81,-23.37,0.195
3.83,-23.18,0.195
3.85,-23.00,0.195
3.87,-22.82,0.195
3.89,-22.63,0.195
3.91,-22.45,0.195
3.92,-22.26,0.195
3.94,-22.08,0.195
3.96,-21.89,0.195
3.98,-21.71,0.196
4.00,-21.52,0.196
4.01,-21.34,0.196
4.03,-21.16,0.196
4.05,-20.97,0.196
4.07,-20.79,0.197
4.09,-20.61,0.197
4.11,-20.42,0.197
4.13,-20.24,0.197
4.14,-20.06,0.197
4.16,-19.87,0.197
4.18,-19.69,0.197
4.20,-19.51,0.197
4.22,-19.32,0.197
4.24,-19.14,0.197
4.25,-18.96,0.197
4.27,-18.77,0.197
4.29,-18.59,0.197
4.31,-18.41,0.197
4.33,-18.22,0.198
4.35,-18.04,0.198
4.36,-17.86,0.198
4.38,-17.67,0.198
4.40,-17.49,0.198
4.42,-17.31,0.198
4.44,-17.12,0.198
4.45,-16.94,0.198
4.47,-16.76,0.198
4.49,-16.57,0.198
4.51,-16.39,0.198
4.53,-16.21,0.198
4.55,-16.02,0.198
4.56,-15.84,0.199
4.58,-15.66,0.199
4.60,-15.47,0.199
4.62,-15.29,0.199
4.64,-15.10,0.199
4.66,-14.92,0.199
4.68,-14.74,0.199
4.69,-14.55,0.199
4.71,-14.37,0.199
4.73,-14.19,0.199
4.75,-14.00,0.199
4.77,-13.82,0.199
4.79,-13.64,0.200
4.80,-13.45,0.200
4.82,-13.27,0.200
4.84,-13.09,0.200
4.86,-12.90,0.200
4.88,-12.72,0.200
4.90,-12.53,0.200
4.91,-12.35,0.200
4.93,-12.17,0.200
4.95,-11.98,0.200
4.97,-11.80,0.201
4.99,-11.62,0.201
5.00,-11.43,0.201
5.02,-11.25,0.201
5.04,-11.07,0.201
5.06,-10.88,0.201
5.08,-10.70,0.201
5.10,-10.52,0.201
5.11,-10.33,0.201
5.13,-10.15,0.201
5.15,-9.97,0.201
5.17,-9.78,0.201
5.19,-9.60,0.201
5.21,-9.42,0.202
5.23,-9.23,0.202
5.24,-9.05,0.202
5.26,-8.87,0.202
5.28,-8.68,0.202
5.30,-8.50,0.202
5.32,-8.32,0.202
5.34,-8.13,0.202
5.35,-7.95,0.202
5.37,-7.76,0.202
5.39,-7.58,0.203
5.41,-7.40,0.203
5.43,-7.21,0.203
5.45,-7.03,0.203
5.46,-6.85,0.203
5.48,-6.66,0.203
5.50,-6.48,0.203
5.52,-6.30,0.204
5.54,-6.11,0.204
5.55,-5.93,0.204
5.57,-5.75,0.204
5.59,-5.56,0.204
5.61,-5.38,0.204
5.63,-5.19,0.204
5.65,-5.01,0.204
5.66,-4.83,0.204
5.68,-4.64,0.204
5.70,-4.46,0.205
5.72,-4.28,0.205
5.74,-4.09,0.205
5.76,-3.91,0.205
5.78,-3.73,0.205
5.79,-3.54,0.205
5.81,-3.36,0.205
5.83,-3.17,0.206
5.85,-2.99,0.206
5.87,-2.81,0.206
5.89,-2.63,0.206
5.90,-2.44,0.206
5.92,-2.26,0.206
5.94,-2.07,0.206
5.96,-1.89,0.207
5.98,-1.71,0.207
6.00,-1.52,0.207
6.01,-1.34,0.207
6.03,-1.15,0.207
6.05,-0.97,0.207
6.07,-0.79,0.207
6.09,-0.61,0.208
6.10,-0.42,0.208
6.12,-0.24,0.208
6.14,-0.05,0.208
6.16,0.13,0.208
6.18,0.31,0.208
6.20,0.50,0.208
6.21,0.68,0.208
6.23,0.86,0.208
6.25,1.05,0.208
6.27,1.23,0.209
6.29,1.41,0.209
6.31,1.60,0.209
6.33,1.78,0.209
6.34,1.96,0.209
6.36,2.15,0.209
6.38,2.33,0.209
6.40,2.52,0.209
6.42,2.70,0.209
6.44,2.88,0.209
6.45,3.07,0.209
6.47,3.25,0.210
6.49,3.43,0.210
6.51,3.62,0.210
6.53,3.80,0.210
6.55,3.99,0.210
6.56,4.17,0.210
6.58,4.35,0.211
6.60,4.54,0.211
6.62,4.72,0.211
6.64,4.90,0.211
6.65,5.09,0.211
6.67,5.27,0.211
6.69,5.45,0.211
6.71,5.64,0.211
6.73,5.82,0.211
6.75,6.00,0.212
6.76,6.19,0.212
6.78,6.37,0.212
6.80,6.55,0.212
6.82,6.74,0.212
6.84,6.92,0.212
6.86,7.11,0.212
6.88,7.29,0.212
6.89,7.47,0.213
6.91,7.66,0.213
6.93,7.84,0.213
6.95,8.02,0.213
6.97,8.21,0.213
6.99,8.39,0.213
7.00,8.57,0.214
7.02,8.76,0.214
7.04,8.94,0.214
7.06,9.12,0.214
7.08,9.31,0.214
7.10,9.49,0.214
7.11,9.67,0.214
7.13,9.86,0.215
7.15,10.04,0.215
7.17,10.23,0.215
7.19,10.41,0.215
7.20,10.59,0.215
7.22,10.78,0.215
7.24,10.96,0.215
7.26,11.14,0.216
7.28,11.33,0.216
7.30,11.51,0.216
7.31,11.69,0.216
7.33,11.88,0.216
7.35,12.06,0.216
7.37,12.24,0.216
7.39,12.43,0.216
7.41,12.61,0.217
7.43,12.80,0.217
7.44,12.98,0.217
7.46,13.16,0.217
7.48,13.35,0.217
7.50,13.53,0.217
7.52,13.71,0.218
7.54,13.90,0.218
7.55,14.08,0.218
7.57,14.26,0.218
7.59,14.45,0.218
7.61,14.63,0.218
7.63,14.81,0.218
7.65,15.00,0.219
7.66,15.18,0.219
7.68,15.36,0.219
7.70,15.55,0.219
7.72,15.73,0.219
7.74,15.91,0.219
7.75,16.10,0.219
7.77,16.28,0.220
7.79,16.47,0.220
7.81,16.65,0.220
7.83,16.83,0.220
7.85,17.02,0.220
7.86,17.20,0.220
7.88,17.38,0.220
7.90,17.57,0.221
7.92,17.75,0.221
7.94,17.93,0.221
7.96,18.12,0.221
7.98,18.30,0.221
7.99,18.48,0.221
8.01,18.67,0.222
8.03,18.85,0.222
8.05,19.04,0.222
8.07,19.22,0.222
8.09,19.40,0.222
8.10,19.59,0.222
8.12,19.77,0.222
8.14,19.95,0.222
8.16,20.14,0.222
8.18,20.32,0.223
8.20,20.50,0.223
8.21,20.69,0.223
8.23,20.87,0.223
8.25,21.05,0.223
8.27,21.24,0.223
8.29,21.42,0.223
8.30,21.60,0.223
8.32,21.79,0.224
8.34,21.97,0.224
8.36,22.16,0.224
8.38,22.34,0.224
8.40,22.52,0.224
8.41,22.71,0.224
8.43,22.89,0.225
8.45,23.07,0.225
8.47,23.26,0.225
8.49,23.44,0.225
8.51,23.62,0.225
8.53,23.81,0.226
8.54,23.99,0.226
8.56,24.17,0.226
8.58,24.36,0.226
8.60,24.54,0.226
8.62,24.72,0.226
8.63,24.91,0.227
8.65,25.09,0.227
8.67,25.28,0.227
8.69,25.46,0.227
8.71,25.64,0.227
8.73,25.83,0.227
8.75,26.01,0.228
8.76,26.19,0.228
8.78,26.38,0.228
8.80,26.56,0.228
8.82,26.74,0.228
8.84,26.93,0.228
8.85,27.11,0.228
8.87,27.29,0.229
8.89,27.48,0.229
8.91,27.66,0.229
8.93,27.84,0.229
8.95,28.03,0.229
8.97,28.21,0.229
8.98,28.39,0.229
9.00,28.58,0.230
9.02,28.76,0.230
9.04,28.94,0.230
9.06,29.13,0.230
9.08,29.31,0.230
9.09,29.50,0.230
9.11,29.68,0.230
9.13,29.86,0.231
9.15,30.05,0.231
9.17,30.23,0.231
9.18,30.41,0.231
9.20,30.60,0.231
9.22,30.78,0.231
9.24,30.97,0.231
9.26,31.15,0.232
9.28,31.33,0.232
9.30,31.52,0.232
9.31,31.70,0.232
9.33,31.88,0.232
9.35,32.07,0.232
9.37,32.25,0.233
9.39,32.43,0.233
9.40,32.62,0.233
9.42,32.80,0.233
9.44,32.98,0.233
9.46,33.17,0.234
9.48,33.35,0.234
9.50,33.53,0.234
9.52,33.72,0.234
9.53,33.90,0.234
9.55,34.09,0.234
9.57,34.27,0.234
9.59,34.45,0.234
9.61,34.63,0.235
9.63,34.82,0.235
9.64,35.00,0.235
9.66,35.19,0.235
9.68,35.37,0.235
9.70,35.55,0.235
9.72,35.74,0.236
9.73,35.92,0.236
9.75,36.10,0.236
9.77,36.29,0.236
9.79,36.47,0.236
9.81,36.66,0.236
9.83,36.84,0.237
9.85,37.02,0.237
9.86,37.20,0.237
9.88,37.39,0.237
9.90,37.57,0.237
9.92,37.76,0.237
9.94,37.94,0.237
9.95,38.12,0.238
9.97,38.31,0.238
9.99,38.49,0.238
10.01,38.67,0.238
10.03,38.86,0.238
10.05,39.04,0.238
10.07,39.22,0.238
10.08,39.41,0.239
10.10,39.59,0.239
10.12,39.77,0.239
10.14,39.96,0.239
10.16,40.14,0.239
10.18,40.32,0.239
10.19,40.51,0.239
10.21,40.69,0.239
10.23,40.87,0.239
10.25,41.06,0.240
10.27,41.24,0.240
10.28,41.43,0.240
10.30,41.61,0.240
10.32,41.79,0.240
10.34,41.98,0.240
10.36,42.16,0.241
10.38,42.34,0.241
10.40,42.53,0.241
10.41,42.71,0.241
10.43,42.89,0.241
10.45,43.08,0.241
10.47,43.26,0.242
10.49,43.44,0.242
10.50,43.63,0.242
10.52,43.81,0.242
10.54,43.99,0.242
10.56,44.18,0.242
10.58,44.36,0.242
10.60,44.54,0.243
10.62,44.73,0.243
10.63,44.91,0.243
10.65,45.09,0.243
10.67,45.28,0.243
10.69,45.46,0.243
10.71,45.65,0.243
10.73,45.83,0.244
10.74,46.01,0.244
10.76,46.20,0.244
10.78,46.38,0.244
10.80,46.56,0.244
10.82,46.74,0.244
10.83,46.93,0.244
10.85,47.11,0.245
10.87,47.30,0.245
10.89,47.48,0.245
10.91,47.66,0.245
10.93,47.85,0.245
10.95,48.03,0.245
10.96,48.21,0.246
10.98,48.40,0.246
11.00,48.58,0.246
11.02,48.76,0.246
11.04,48.95,0.246
11.05,49.13,0.246
11.07,49.32,0.246
11.09,49.50,0.247
11.11,49.68,0.247
11.13,49.87,0.247
11.15,50.05,0.247
11.17,50.23,0.247
11.18,50.42,0.247
11.20,50.60,0.247
11.22,50.78,0.248
11.24,50.97,0.248
11.26,51.15,0.248
11.28,51.33,0.248
11.29,51.52,0.248
11.31,51.70,0.248
11.33,51.88,0.248
11.35,52.07,0.249
11.37,52.25,0.249
11.38,52.44,0.249
11.40,52.62,0.249
11.42,52.80,0.249
11.44,52.99,0.249
11.46,53.17,0.250
11.48,53.36,0.250
11.50,53.54,0.250
11.51,53.72,0.250
11.53,53.90,0.250
11.55,54.09,0.250
11.57,54.27,0.251
11.59,54.46,0.251
11.60,54.64,0.251
11.62,54.82,0.251
11.64,55.01,0.251
11.66,55.19,0.251
11.68,55.37,0.251
11.70,55.56,0.252
11.72,55.74,0.252
11.73,55.93,0.252
11.75,56.11,0.252
11.77,56.29,0.252
11.79,56.48,0.252
11.81,56.66,0.252
11.83,56.84,0.253
11.84,57.03,0.253
11.86,57.21,0.253
11.88,57.39,0.253
11.90,57.58,0.253
11.92,57.76,0.253
11.93,57.94,0.254
11.95,58.13,0.254
11.97,58.31,0.254
11.99,58.49,0.254
12.01,58.68,0.254
12.03,58.86,0.254
12.05,59.04,0.255
12.06,59.23,0.255
12.08,59.41,0.255
12.10,59.60,0.255
12.12,59.78,0.255
12.14,59.96,0.255
12.15,60.14,0.256
12.17,60.33,0.256
12.19,60.51,0.256
12.21,60.70,0.256
12.23,60.88,0.256
12.25,61.06,0.256
12.27,61.25,0.257
12.28,61.43,0.257
12.30,61.61,0.257
12.32,61.80,0.257
12.34,61.98,0.258
12.36,62.16,0.258
12.38,62.35,0.258
12.39,62.53,0.258
12.41,62.71,0.259
12.43,62.90,0.259
12.45,63.08,0.259
12.47,63.26,0.259
12.48,63.45,0.260
12.50,63.63,0.260
12.52,63.81,0.260
12.54,64.00,0.260
12.56,64.18,0.261
12.58,64.37,0.261
12.60,64.55,0.261
12.61,64.73,0.262
12.63,64.92,0.262
12.65,65.10,0.262
12.67,65.28,0.263
12.69,65.47,0.263
12.70,65.65,0.263
12.72,65.83,0.264
12.74,66.02,0.264
12.76,66.20,0.265
12.78,66.38,0.265
12.80,66.57,0.266
12.82,66.75,0.266
12.83,66.93,0.267
12.85,67.12,0.268
12.87,67.30,0.269
12.89,67.48,0.270
12.91,67.67,0.271
12.93,67.85,0.273
12.94,68.03,0.274
12.96,68.22,0.275
12.98,68.40,0.277
13.00,68.58,0.280
13.02,68.77,0.282
13.03,68.95,0.285
13.05,69.13,0.288
13.07,69.32,0.290
13.09,69.50,0.294
13.11,69.68,0.298
13.13,69.86,0.304
13.15,70.05,0.309
13.16,70.23,0.313
13.18,70.41,0.319
13.20,70.60,0.326
13.22,70.78,0.335
13.24,70.96,0.343
13.25,71.14,0.353
13.27,71.32,0.366
13.29,71.50,0.378
13.31,71.68,0.394
13.33,71.86,0.412
13.35,72.04,0.433
13.37,72.22,0.459
13.38,72.40,0.488
13.40,72.58,0.520
13.42,72.75,0.560
13.44,72.93,0.605
13.46,73.10,0.658
13.48,73.27,0.711
13.49,73.44,0.774
13.51,73.61,0.843
13.53,73.78,0.915
13.55,73.94,0.994
13.57,74.11,1.084
13.58,74.27,1.181
13.60,74.43,1.284
13.62,74.58,1.398
13.64,74.74,1.521
13.66,74.89,1.644
13.68,75.04,1.789
13.70,75.19,1.928
13.71,75.34,2.051
13.73,75.49,2.164
13.75,75.64,2.212
13.77,75.80,2.202
13.79,75.97,2.203
13.80,76.14,2.221
13.82,76.31,2.231
13.84,76.49,2.183
13.86,76.67,2.071
13.88,76.87,1.901
13.90,77.08,1.702
13.92,77.30,1.498
13.93,77.52,1.297
13.95,77.75,1.118
13.97,77.98,0.948
13.99,78.21,0.831
14.01,78.43,0.728
14.03,78.65,0.654
14.04,78.87,0.594
14.06,79.08,0.548
14.08,79.28,0.510
14.10,79.49,0.478
14.12,79.68,0.450
14.13,79.88,0.427
14.15,80.08,0.406
14.17,80.27,0.390
14.19,80.46,0.377
14.21,80.65,0.365
14.23,80.84,0.356
14.25,81.03,0.347
14.26,81.22,0.342
14.28,81.40,0.336
14.30,81.59,0.331
14.32,81.78,0.327
14.34,81.96,0.325
14.35,82.15,0.322
14.37,82.33,0.319
14.39,82.52,0.318
14.41,82.70,0.315
14.43,82.89,0.314
14.45,83.07,0.314
14.47,83.26,0.313
14.48,83.44,0.312
14.50,83.62,0.312
14.52,83.81,0.311
14.54,83.99,0.311
14.56,84.17,0.310
14.58,84.36,0.310
14.59,84.54,0.310
14.61,84.73,0.309
14.63,84.91,0.309
14.65,85.09,0.309
14.67,85.28,0.308
14.68,85.46,0.308
14.70,85.64,0.308
14.72,85.83,0.308
14.74,86.01,0.308
14.76,86.20,0.307
14.78,86.38,0.307
14.80,86.56,0.307
14.81,86.75,0.307
14.83,86.93,0.307
14.85,87.12,0.307
14.87,87.30,0.306
14.89,87.48,0.306
14.90,87.67,0.306
14.92,87.85,0.306
14.94,88.03,0.306
14.96,88.22,0.306
14.98,88.40,0.306
15.00,88.58,0.306
15.02,88.77,0.306
15.03,88.95,0.306
15.05,89.13,0.306
15.07,89.32,0.306
15.09,89.50,0.306
15.11,89.68,0.306
15.13,89.87,0.306
15.14,90.05,0.306
15.16,90.23,0.306
15.18,90.42,0.306
15.20,90.60,0.306
15.22,90.78,0.306
15.23,90.97,0.306
15.25,91.15,0.306
15.27,91.34,0.306
15.29,91.52,0.306
15.31,91.70,0.306
15.33,91.89,0.306
15.35,92.07,0.306
15.36,92.25,0.306
15.38,92.44,0.306
15.40,92.62,0.306
15.42,92.80,0.306
15.44,92.99,0.307
15.45,93.17,0.307
15.47,93.35,0.307
15.49,93.54,0.307
15.51,93.72,0.307
15.53,93.90,0.307
15.55,94.09,0.307
15.57,94.27,0.307
15.58,94.46,0.307
15.60,94.64,0.308
15.62,94.82,0.308
15.64,95.01,0.308
15.66,95.19,0.308
15.68,95.37,0.308
15.69,95.56,0.308
15.71,95.74,0.308
15.73,95.92,0.308
15.75,96.11,0.308
15.77,96.29,0.308
15.78,96.47,0.308
15.80,96.66,0.309
15.82,96.84,0.309
15.84,97.03,0.309
15.86,97.21,0.309
15.88,97.39,0.309
15.90,97.58,0.309
15.91,97.76,0.309
15.93,97.94,0.309
15.95,98.12,0.309
15.97,98.31,0.309
15.99,98.49,0.310
16.00,98.68,0.310
16.02,98.86,0.310
16.04,99.04,0.310
16.06,99.23,0.310
16.08,99.41,0.310
16.10,99.59,0.310
16.12,99.78,0.310
16.13,99.96,0.311
16.15,100.14,0.311
16.17,100.33,0.311
16.19,100.51,0.311
16.21,100.69,0.311
16.23,100.88,0.311
16.24,101.06,0.311
16.26,101.24,0.311
16.28,101.43,0.311
16.30,101.61,0.312
16.32,101.80,0.312
16.33,101.98,0.312
16.35,102.16,0.312
16.37,102.35,0.312
16.39,102.53,0.312
16.41,102.71,0.312
16.43,102.90,0.313
16.45,103.08,0.313
16.46,103.26,0.313
16.48,103.45,0.313
16.50,103.63,0.313
16.52,103.81,0.313
16.54,104.00,0.313
16.55,104.18,0.313
16.57,104.37,0.314
16.59,104.55,0.314
16.61,104.73,0.314
16.63,104.92,0.314
16.65,105.10,0.314
16.67,105.28,0.314
16.68,105.47,0.314
16.70,105.65,0.315
16.72,105.83,0.315
16.74,106.02,0.315
16.76,106.20,0.315
16.78,106.38,0.315
16.79,106.57,0.315
16.81,106.75,0.315
16.83,106.93,0.316
16.85,107.12,0.316
16.87,107.30,0.316
16.88,107.48,0.316
16.90,107.67,0.316
16.92,107.85,0.316
16.94,108.03,0.317
16.96,108.22,0.317
16.98,108.40,0.317
17.00,108.58,0.317
17.01,108.77,0.317
17.03,108.95,0.317
17.05,109.14,0.318
17.07,109.32,0.318
17.09,109.50,0.318
17.11,109.69,0.318
17.12,109.87,0.318
17.14,110.05,0.318
17.16,110.24,0.319
17.18,110.42,0.319
17.20,110.60,0.319
17.22,110.78,0.319
17.23,110.97,0.319
17.25,111.15,0.319
17.27,111.34,0.320
17.29,111.52,0.320
17.31,111.70,0.320
17.33,111.89,0.320
17.34,112.07,0.320
17.36,112.26,0.320
17.38,112.44,0.321
17.40,112.62,0.321
17.42,112.81,0.321
17.43,112.99,0.321
17.45,113.17,0.321
17.47,113.36,0.321
17.49,113.54,0.322
17.51,113.72,0.322
17.53,113.91,0.322
17.54,114.09,0.322
17.56,114.27,0.322
17.58,114.46,0.322
17.60,114.64,0.322
17.62,114.82,0.322
17.64,115.01,0.323
17.66,115.19,0.323
17.67,115.37,0.323
17.69,115.56,0.323
17.71,115.74,0.323
17.73,115.92,0.323
17.75,116.11,0.324
17.77,116.29,0.324
17.78,116.47,0.324
17.80,116.66,0.324
17.82,116.84,0.324
17.84,117.03,0.324
17.86,117.21,0.325
17.88,117.39,0.325
17.89,117.58,0.325
17.91,117.76,0.325
17.93,117.94,0.325
17.95,118.13,0.326
17.97,118.31,0.326
17.98,118.49,0.326
18.00,118.68,0.326
18.02,118.86,0.327
18.04,119.04,0.327
18.06,119.23,0.327
18.08,119.41,0.327
18.09,119.59,0.327
18.11,119.78,0.328
18.13,119.96,0.328
18.15,120.14,0.328
18.17,120.33,0.328
18.19,120.51,0.328
18.21,120.69,0.329
18.22,120.88,0.329
18.24,121.06,0.329
18.26,121.24,0.329
18.28,121.43,0.329
18.30,121.61,0.330
18.32,121.79,0.330
18.33,121.98,0.330
18.35,122.16,0.330
18.37,122.34,0.330
18.39,122.53,0.330
18.41,122.71,0.331
18.43,122.89,0.331
18.44,123.08,0.331
18.46,123.26,0.331
18.48,123.45,0.331
18.50,123.63,0.331
18.52,123.81,0.332
18.53,124.00,0.332
18.55,124.18,0.332
18.57,124.36,0.332
18.59,124.55,0.332
18.61,124.73,0.332
18.63,124.91,0.332
18.64,125.10,0.332
18.66,125.28,0.333
18.68,125.46,0.333
18.70,125.65,0.333
18.72,125.83,0.333
18.74,126.01,0.333
18.76,126.20,0.333
18.77,126.38,0.334
18.79,126.57,0.334
18.81,126.75,0.334
18.83,126.93,0.334
18.85,127.12,0.334
18.87,127.30,0.334
18.88,127.48,0.335
18.90,127.67,0.335
18.92,127.85,0.335
18.94,128.03,0.335
18.96,128.22,0.335
18.98,128.40,0.335
18.99,128.58,0.335
19.01,128.77,0.336
19.03,128.95,0.336
19.05,129.13,0.336
19.07,129.32,0.336
19.08,129.50,0.336
19.10,129.68,0.336
19.12,129.87,0.336
19.14,130.05,0.336
19.16,130.23,0.337
19.18,130.42,0.337
19.19,130.60,0.337
19.21,130.79,0.337
19.23,130.97,0.337
19.25,131.15,0.337
19.27,131.34,0.338
19.29,131.52,0.338
19.31,131.70,0.338
19.32,131.89,0.338
19.34,132.07,0.338
19.36,132.25,0.338
19.38,132.44,0.338
19.40,132.62,0.338
19.42,132.80,0.339
19.43,132.99,0.339
19.45,133.17,0.339
19.47,133.35,0.339
19.49,133.54,0.339
19.51,133.72,0.340
19.53,133.91,0.340
19.54,134.09,0.340
19.56,134.27,0.340
19.58,134.46,0.340
19.60,134.65,0.340
19.62,134.83,0.341
19.63,135.02,0.341
19.65,135.20,0.342
19.67,135.38,0.342
19.69,135.57,0.342
19.71,135.75,0.342
19.73,135.93,0.343
19.74,136.12,0.343
19.76,136.30,0.343
19.78,136.48,0.343
19.80,136.67,0.343
19.82,136.85,0.343
19.84,137.03,0.343
19.86,137.22,0.343
19.87,137.40,0.343
19.89,137.58,0.343
19.91,137.77,0.343
19.93,137.95,0.343
19.95,138.13,0.343
19.97,138.31,0.343
19.98,138.50,0.343
20.00,138.68,0.343
20.02,138.86,0.343
20.04,139.05,0.343
20.06,139.23,0.343
20.08,139.41,0.343
20.09,139.60,0.344
20.11,139.78,0.344
20.13,139.96,0.344
20.15,140.15,0.344
20.17,140.33,0.344
20.18,140.51,0.344
20.20,140.70,0.344
20.22,140.88,0.344
20.24,141.06,0.345
20.26,141.25,0.345
20.28,141.43,0.345
20.29,141.61,0.345
20.31,141.80,0.345
20.33,141.98,0.346
20.35,142.16,0.346
20.37,142.35,0.346
20.39,142.53,0.346
20.41,142.71,0.346
20.42,142.90,0.347
20.44,143.08,0.347
20.46,143.26,0.347
20.48,143.45,0.347
20.50,143.63,0.347
20.52,143.81,0.347
20.53,144.00,0.348
20.55,144.18,0.348
20.57,144.36,0.348
20.59,144.55,0.348
20.61,144.73,0.349
20.63,144.91,0.349
20.64,145.10,0.349
20.66,145.28,0.349
20.68,145.46,0.349
20.70,145.65,0.349
20.72,145.83,0.350
20.73,146.02,0.350
20.75,146.20,0.350
20.77,146.38,0.350
20.79,146.57,0.351
20.81,146.75,0.351
20.83,146.93,0.351
20.84,147.12,0.351
20.86,147.30,0.351
20.88,147.48,0.352
20.90,147.67,0.352
20.92,147.85,0.352
20.94,148.03,0.352
20.96,148.21,0.352
20.97,148.40,0.352
20.99,148.58,0.353
21.01,148.76,0.353
21.03,148.95,0.353
21.05,149.13,0.353
21.07,149.32,0.353
21.08,149.50,0.354
21.10,149.68,0.354
21.12,149.87,0.354
21.14,150.05,0.354
21.16,150.23,0.354
21.18,150.42,0.355
21.19,150.60,0.355
21.21,150.78,0.355
21.23,150.97,0.355
21.25,151.15,0.356
21.27,151.33,0.356
21.28,151.52,0.356
21.30,151.70,0.356
21.32,151.88,0.356
21.34,152.07,0.356
21.36,152.25,0.357
21.38,152.44,0.357
21.39,152.62,0.357
21.41,152.80,0.357
21.43,152.99,0.357
21.45,153.17,0.358
21.47,153.35,0.358
21.49,153.54,0.358
21.51,153.72,0.358
21.52,153.90,0.358
21.54,154.09,0.359
21.56,154.27,0.359
21.58,154.45,0.359
21.60,154.64,0.359
21.62,154.82,0.359
21.63,155.00,0.360
21.65,155.19,0.360
21.67,155.37,0.360
21.69,155.55,0.360
21.71,155.74,0.360
21.73,155.92,0.360
21.74,156.10,0.361
21.76,156.29,0.361
21.78,156.47,0.370
21.80,156.65,0.374
21.82,156.83,0.373
21.83,157.02,0.373
21.85,157.20,0.372
21.87,157.39,0.372
21.89,157.57,0.371
21.91,157.75,0.371
21.93,157.94,0.370
21.94,158.12,0.370
21.96,158.30,0.370
21.98,158.49,0.370
22.00,158.67,0.369
22.02,158.85,0.369
22.04,159.04,0.369
22.06,159.22,0.369
22.07,159.40,0.369
22.09,159.59,0.369
22.11,159.77,0.369
22.13,159.95,0.369
22.15,160.14,0.369
22.17,160.32,0.369
22.18,160.50,0.369
22.20,160.69,0.369
22.22,160.87,0.369
22.24,161.06,0.369
22.26,161.24,0.369
22.28,161.42,0.369
22.29,161.61,0.369
22.31,161.79,0.370
22.33,161.97,0.370
22.35,162.15,0.370
22.37,162.34,0.370
22.38,162.52,0.370
22.40,162.70,0.370
22.42,162.89,0.370
22.44,163.07,0.371
22.46,163.25,0.371
22.48,163.44,0.371
22.49,163.62,0.372
22.51,163.80,0.372
22.53,163.99,0.372
22.55,164.17,0.372
22.57,164.36,0.373
22.59,164.54,0.373
22.61,164.72,0.373
22.62,164.91,0.374
22.64,165.09,0.374
22.66,165.27,0.374
22.68,165.46,0.374
22.70,165.64,0.375
22.72,165.82,0.375
22.73,166.01,0.375
22.75,166.19,0.376
22.77,166.37,0.376
22.79,166.56,0.376
22.81,166.74,0.377
22.83,166.92,0.377
22.84,167.11,0.377
22.86,167.29,0.378
22.88,167.47,0.378
22.90,167.66,0.378
22.92,167.84,0.379
22.93,168.02,0.379
22.95,168.21,0.379
22.97,168.39,0.380
22.99,168.57,0.380
23.01,168.76,0.381
23.03,168.94,0.381
23.04,169.12,0.381
23.06,169.31,0.382
23.08,169.49,0.382
23.10,169.67,0.382
23.12,169.86,0.383
23.14,170.04,0.383
23.16,170.22,0.384
23.17,170.40,0.384
23.19,170.59,0.384
23.21,170.77,0.385
23.23,170.96,0.385
23.25,171.14,0.386
23.27,171.32,0.386
23.28,171.51,0.386
23.30,171.69,0.387
23.32,171.87,0.387
23.34,172.06,0.388
23.36,172.24,0.389
23.38,172.42,0.389
23.39,172.61,0.390
23.41,172.79,0.390
23.43,172.97,0.390
23.45,173.16,0.391
23.47,173.34,0.391
23.48,173.52,0.392
23.50,173.71,0.392
23.52,173.89,0.393
23.54,174.07,0.393
23.56,174.26,0.394
23.58,174.44,0.394
23.59,174.62,0.395
23.61,174.81,0.396
23.63,174.99,0.396
23.65,175.18,0.397
23.67,175.36,0.398
23.69,175.54,0.399
23.71,175.73,0.399
23.72,175.91,0.400
23.74,176.09,0.400
23.76,176.27,0.401
23.78,176.46,0.401
23.80,176.64,0.402
23.82,176.82,0.403
23.83,177.01,0.403
23.85,177.19,0.404
23.87,177.37,0.404
23.89,177.56,0.406
23.91,177.74,0.406
23.93,177.92,0.407
23.94,178.11,0.408
23.96,178.29,0.408
23.98,178.47,0.409
24.00,178.66,0.409
24.02,178.84,0.410
24.03,179.02,0.411
24.05,179.21,0.411
24.07,179.39,0.412
24.09,179.58,0.413
24.11,179.76,0.414
24.13,179.94,0.414
24.14,180.12,0.415
24.16,180.31,0.416
24.18,180.49,0.416
24.20,180.67,0.417
24.22,180.86,0.418
24.24,181.04,0.419
24.26,181.22,0.420
24.27,181.41,0.420
24.29,181.59,0.421
24.31,181.77,0.422
24.33,181.96,0.423
24.35,182.14,0.424
24.37,182.32,0.424
24.38,182.51,0.425
24.40,182.69,0.426
24.42,182.87,0.427
24.44,183.06,0.428
24.46,183.24,0.429
24.48,183.42,0.430
24.49,183.61,0.431
24.51,183.79,0.432
24.53,183.97,0.433
24.55,184.16,0.433
24.57,184.34,0.434
24.58,184.52,0.435
24.60,184.70,0.436
24.62,184.89,0.437
24.64,185.07,0.438
24.66,185.25,0.439
24.68,185.44,0.440
24.69,185.62,0.441
24.71,185.80,0.441
24.73,185.99,0.443
24.75,186.17,0.443
24.77,186.35,0.444
24.79,186.54,0.446
24.81,186.72,0.447
24.82,186.91,0.449
24.84,187.09,0.449
24.86,187.27,0.451
24.88,187.45,0.451
24.90,187.64,0.452
24.92,187.82,0.453
24.93,188.00,0.454
24.95,188.19,0.455
24.97,188.37,0.456
24.99,188.55,0.457
25.01,188.74,0.458
25.03,188.92,0.458
25.04,189.10,0.459
25.06,189.29,0.460
25.08,189.47,0.461
25.10,189.65,0.462
25.12,189.84,0.464
25.13,190.02,0.464
25.15,190.20,0.467
25.17,190.39,0.467
25.19,190.57,0.468
25.21,190.75,0.470
25.23,190.94,0.471
25.24,191.12,0.472
25.26,191.30,0.474
25.28,191.48,0.475
25.30,191.67,0.475
25.32,191.85,0.477
25.34,192.03,0.478
25.36,192.22,0.479
25.37,192.40,0.480
25.39,192.58,0.481
25.41,192.77,0.483
25.43,192.95,0.484
25.45,193.13,0.485
25.47,193.32,0.487
25.48,193.50,0.488
25.50,193.68,0.489
25.52,193.87,0.491
25.54,194.05,0.492
25.56,194.23,0.493
25.58,194.41,0.494
25.59,194.60,0.496
25.61,194.78,0.498
25.63,194.96,0.498
25.65,195.15,0.500
25.67,195.33,0.501
25.68,195.51,0.502
25.70,195.70,0.503
25.72,195.88,0.504
25.74,196.06,0.505
25.76,196.25,0.506
25.78,196.43,0.507
25.79,196.61,0.508
25.81,196.79,0.509
25.83,196.98,0.510
25.85,197.16,0.512
25.87,197.35,0.512
25.89,197.53,0.513
25.91,197.71,0.514
25.92,197.90,0.515
25.94,198.08,
25.96,198.26,
25.98,198.44,
25.99,,

[step]
Ramp 10.00 °C/min to -60.00 °C
Time,Temperature,Heat Flow (Normalized)
min,°C,W/g
27.99,200.11,-0.033
28.01,200.11,-0.033
28.03,200.10,-0.033
28.05,200.09,-0.033
28.07,200.07,-0.030
28.08,200.02,-0.025
28.10,199.96,-0.025
28.12,199.87,-0.056
28.14,199.76,-0.095
28.16,199.64,-0.143
28.18,199.51,-0.193
28.19,199.37,-0.241
28.21,199.22,-0.282
28.23,199.07,-0.319
28.25,198.91,-0.350
28.27,198.75,-0.375
28.29,198.59,-0.395
28.31,198.42,-0.416
28.32,198.25,-0.432
28.34,198.08,-0.445
28.36,197.91,-0.457
28.38,197.74,-0.468
28.40,197.56,-0.480
28.42,197.39,-0.485
28.43,197.21,-0.492
28.45,197.03,-0.499
28.47,196.85,-0.503
28.49,196.68,-0.508
28.51,196.50,-0.512
28.53,196.32,-0.515
28.54,196.14,-0.518
28.56,195.96,-0.520
28.58,195.78,-0.523
28.60,195.60,-0.525
28.62,195.42,-0.527
28.63,195.24,-0.529
28.65,195.06,-0.530
28.67,194.88,-0.530
28.69,194.69,-0.532
28.71,194.51,-0.532
28.73,194.33,-0.533
28.74,194.15,-0.534
28.76,193.97,-0.534
28.78,193.79,-0.537
28.80,193.61,-0.542
28.82,193.43,-0.547
28.84,193.24,-0.550
28.86,193.06,-0.554
28.87,192.88,-0.558
28.89,192.70,-0.564
28.91,192.52,-0.572
28.93,192.34,-0.575
28.95,192.16,-0.578
28.97,191.98,-0.581
28.98,191.79,-0.581
29.00,191.61,-0.583
29.02,191.43,-0.586
29.04,191.25,-0.590
29.06,191.07,-0.594
29.08,190.89,-0.595
29.09,190.70,-0.596
29.11,190.52,-0.598
29.13,190.34,-0.599
29.15,190.16,-0.602
29.17,189.98,-0.604
29.18,189.79,-0.606
29.20,189.61,-0.608
29.22,189.43,-0.608
29.24,189.25,-0.610
29.26,189.06,-0.612
29.28,188.88,-0.614
29.29,188.70,-0.614
29.31,188.52,-0.616
29.33,188.34,-0.619
29.35,188.15,-0.620
29.37,187.97,-0.621
29.39,187.79,-0.622
29.41,187.61,-0.623
29.42,187.42,-0.626
29.44,187.24,-0.627
29.46,187.06,-0.628
29.48,186.88,-0.630
29.50,186.69,-0.632
29.52,186.51,-0.633
29.53,186.33,-0.638
29.55,186.15,-0.642
29.57,185.97,-0.646
29.59,185.78,-0.648
29.61,185.60,-0.650
29.63,185.42,-0.654
29.64,185.24,-0.655
29.66,185.05,-0.657
29.68,184.87,-0.659
29.70,184.69,-0.659
29.72,184.50,-0.660
29.73,184.32,-0.660
29.75,184.14,-0.660
29.77,183.96,-0.660
29.79,183.77,-0.659
29.81,183.59,-0.659
29.83,183.41,-0.659
29.84,183.22,-0.655
29.86,183.04,-0.649
29.88,182.86,-0.644
29.90,182.67,-0.642
29.92,182.49,-0.636
29.94,182.30,-0.631
29.96,182.12,-0.628
29.97,181.94,-0.625
29.99,181.75,-0.621
30.01,181.57,-0.613
30.03,181.39,-0.609
30.05,181.20,-0.606
30.07,181.02,-0.598
30.08,180.83,-0.595
30.10,180.65,-0.592
30.12,180.46,-0.588
30.14,180.28,-0.584
30.16,180.10,-0.580
30.18,179.91,-0.575
30.19,179.73,-0.573
30.21,179.55,-0.571
30.23,179.36,-0.568
30.25,179.18,-0.564
30.27,178.99,-0.562
30.28,178.81,-0.560
30.30,178.63,-0.557
30.32,178.44,-0.553
30.34,178.26,-0.552
30.36,178.07,-0.549
30.38,177.89,-0.546
30.39,177.71,-0.544
30.41,177.52,-0.543
30.43,177.34,-0.541
30.45,177.16,-0.539
30.47,176.97,-0.539
30.49,176.79,-0.535
30.51,176.61,-0.533
30.52,176.42,-0.532
30.54,176.24,-0.530
30.56,176.06,-0.529
30.58,175.87,-0.527
30.60,175.69,-0.526
30.62,175.51,-0.524
30.63,175.32,-0.523
30.65,175.14,-0.522
30.67,174.96,-0.521
30.69,174.77,-0.520
30.71,174.59,-0.518
30.73,174.40,-0.517
30.74,174.22,-0.517
30.76,174.04,-0.516
30.78,173.85,-0.515
30.80,173.67,-0.514
30.82,173.49,-0.512
30.83,173.30,-0.511
30.85,173.12,-0.509
30.87,172.94,-0.509
30.89,172.75,-0.508
30.91,172.57,-0.506
30.93,172.39,-0.506
30.94,172.20,-0.505
30.96,172.02,-0.504
30.98,171.84,-0.503
31.00,171.65,-0.502
31.02,171.47,-0.501
31.04,171.29,-0.500
31.06,171.10,-0.499
31.07,170.92,-0.498
31.09,170.74,-0.498
31.11,170.55,-0.497
31.13,170.37,-0.496
31.15,170.19,-0.495
31.17,170.00,-0.494
31.18,169.82,-0.493
31.20,169.64,-0.492
31.22,169.45,-0.491
31.24,169.27,-0.491
31.26,169.09,-0.490
31.28,168.90,-0.489
31.29,168.72,-0.488
31.31,168.53,-0.487
31.33,168.35,-0.486
31.35,168.17,-0.485
31.37,167.99,-0.485
31.38,167.80,-0.484
31.40,167.62,-0.484
31.42,167.43,-0.483
31.44,167.25,-0.482
31.46,167.07,-0.481
31.48,166.89,-0.481
31.49,166.70,-0.480
31.51,166.52,-0.479
31.53,166.34,-0.479
31.55,166.15,-0.478
31.57,165.97,-0.477
31.59,165.79,-0.477
31.61,165.60,-0.476
31.62,165.42,-0.475
31.64,165.24,-0.474
31.66,165.05,-0.473
31.68,164.87,-0.473
31.70,164.69,-0.472
31.72,164.50,-0.472
31.73,164.32,-0.471
31.75,164.14,-0.471
31.77,163.95,-0.470
31.79,163.77,-0.470
31.81,163.59,-0.469
31.83,163.41,-0.468
31.84,163.22,-0.468
31.86,163.04,-0.467
31.88,162.85,-0.466
31.90,162.67,-0.466
31.92,162.49,-0.465
31.93,162.31,-0.465
31.95,162.12,-0.464
31.97,161.94,-0.464
31.99,161.76,-0.463
32.01,161.57,-0.462
32.03,161.39,-0.462
32.04,161.20,-0.461
32.06,161.02,-0.461
32.08,160.84,-0.460
32.10,160.66,-0.460
32.12,160.47,-0.459
32.14,160.29,-0.459
32.16,160.11,-0.458
32.17,159.92,-0.458
32.19,159.74,-0.457
32.21,159.56,-0.456
32.23,159.37,-0.456
32.25,159.19,-0.455
32.27,159.01,-0.455
32.28,158.82,-0.455
32.30,158.64,-0.454
32.32,158.46,-0.453
32.34,158.27,-0.453
32.36,158.09,-0.453
32.38,157.91,-0.452
32.39,157.72,-0.452
32.41,157.54,-0.451
32.43,157.36,-0.451
32.45,157.17,-0.450
32.47,156.99,-0.450
32.48,156.81,-0.449
32.50,156.62,-0.449
32.52,156.44,-0.448
32.54,156.26,-0.448
32.56,156.07,-0.448
32.58,155.89,-0.447
32.59,155.71,-0.447
32.61,155.52,-0.446
32.63,155.34,-0.446
32.65,155.16,-0.445
32.67,154.97,-0.445
32.69,154.79,-0.444
32.71,154.61,-0.444
32.72,154.43,-0.444
32.74,154.24,-0.443
32.76,154.06,-0.443
32.78,153.88,-0.442
32.80,153.69,-0.442
32.82,153.51,-0.442
32.83,153.33,-0.441
32.85,153.14,-0.441
32.87,152.96,-0.440
32.89,152.78,-0.439
32.91,152.59,-0.439
32.93,152.41,-0.439
32.94,152.23,-0.438
32.96,152.05,-0.438
32.98,151.86,-0.438
33.00,151.68,-0.437
33.02,151.50,-0.437
33.03,151.31,-0.437
33.05,151.13,-0.436
33.07,150.95,-0.436
33.09,150.76,-0.435
33.11,150.58,-0.435
33.13,150.40,-0.435
33.14,150.21,-0.434
33.16,150.03,-0.434
33.18,149.85,-0.434
33.20,149.66,-0.433
33.22,149.48,-0.433
33.24,149.30,-0.433
33.26,149.11,-0.432
33.27,148.93,-0.432
33.29,148.75,-0.432
33.31,148.56,-0.431
33.33,148.38,-0.431
33.35,148.20,-0.431
33.37,148.01,-0.430
33.38,147.83,-0.430
33.40,147.65,-0.430
33.42,147.46,-0.430
33.44,147.28,-0.429
33.46,147.10,-0.429
33.48,146.92,-0.429
33.49,146.73,-0.428
33.51,146.55,-0.428
33.53,146.37,-0.427
33.55,146.18,-0.427
33.57,146.00,-0.427
33.58,145.82,-0.427
33.60,145.63,-0.427
33.62,145.45,-0.426
33.64,145.27,-0.426
33.66,145.08,-0.426
33.68,144.90,-0.426
33.69,144.72,-0.425
33.71,144.53,-0.425
33.73,144.35,-0.425
33.75,144.16,-0.425
33.77,143.98,-0.424
33.79,143.80,-0.424
33.81,143.62,-0.424
33.82,143.43,-0.424
33.84,143.25,-0.423
33.86,143.07,-0.423
33.88,142.88,-0.423
33.90,142.70,-0.422
33.92,142.52,-0.422
33.93,142.33,-0.422
33.95,142.15,-0.422
33.97,141.97,-0.421
33.99,141.78,-0.421
34.01,141.60,-0.421
34.03,141.42,-0.420
34.04,141.23,-0.420
34.06,141.05,-0.420
34.08,140.87,-0.420
34.10,140.68,-0.419
34.12,140.50,-0.419
34.14,140.32,-0.419
34.15,140.13,-0.419
34.17,139.95,-0.418
34.19,139.77,-0.418
34.21,139.59,-0.418
34.23,139.40,-0.417
34.24,139.22,-0.417
34.26,139.04,-0.417
34.28,138.85,-0.417
34.30,138.67,-0.416
34.32,138.49,-0.416
34.34,138.30,-0.416
34.36,138.12,-0.415
34.37,137.94,-0.415
34.39,137.75,-0.415
34.41,137.57,-0.415
34.43,137.39,-0.415
34.45,137.20,-0.414
34.46,137.02,-0.414
34.48,136.84,-0.414
34.50,136.65,-0.414
34.52,136.47,-0.413
34.54,136.29,-0.413
34.56,136.10,-0.413
34.58,135.92,-0.413
34.59,135.74,-0.413
34.61,135.55,-0.412
34.63,135.37,-0.412
34.65,135.19,-0.412
34.67,135.00,-0.412
34.69,134.82,-0.412
34.70,134.64,-0.411
34.72,134.46,-0.411
34.74,134.27,-0.410
34.76,134.09,-0.410
34.78,133.91,-0.410
34.79,133.72,-0.410
34.81,133.54,-0.409
34.83,133.36,-0.409
34.85,133.17,-0.409
34.87,132.99,-0.409
34.89,132.81,-0.409
34.91,132.62,-0.408
34.92,132.44,-0.408
34.94,132.26,-0.408
34.96,132.07,-0.408
34.98,131.89,-0.408
35.00,131.71,-0.408
35.01,131.53,-0.407
35.03,131.34,-0.407
35.05,131.16,-0.407
35.07,130.98,-0.406
35.09,130.80,-0.406
35.11,130.61,-0.406
35.13,130.43,-0.406
35.14,130.25,-0.406
35.16,130.06,-0.406
35.18,129.88,-0.405
35.20,129.70,-0.405
35.22,129.51,-0.405
35.24,129.33,-0.405
[...]
114.07,-40.88,0.190
114.08,-40.81,0.190
114.09,-40.74,0.190
114.09,-40.68,0.190
114.10,-40.61,0.190
114.11,-40.54,0.190
114.11,-40.48,0.190
114.12,-40.41,0.190
114.13,-40.34,0.190
114.13,-40.28,0.190
114.14,-40.21,0.191
114.15,-40.14,0.191
114.15,-40.08,0.191
114.16,-40.01,0.191
114.17,-39.94,0.191
114.17,-39.88,0.191
114.18,-39.81,0.191
114.19,-39.74,0.191
114.19,-39.68,0.191
114.20,-39.61,0.191
114.21,-39.54,0.191
114.21,-39.48,0.191
114.22,-39.41,0.191
114.23,-39.34,0.191
114.23,-39.28,0.191
114.24,-39.21,0.191
114.25,-39.14,0.191
114.25,-39.08,0.191
114.26,-39.01,0.191
114.27,-38.94,0.191
114.27,-38.87,0.191
114.28,-38.81,0.191
114.29,-38.74,0.191
114.29,-38.68,0.191
114.30,-38.61,0.191
114.31,-38.54,0.191
114.31,-38.47,0.191
114.32,-38.41,0.191
114.33,-38.34,0.191
114.33,-38.28,0.191
114.34,-38.21,0.191
114.35,-38.14,0.191
114.35,-38.08,0.192
114.36,-38.01,0.192
114.37,-37.94,0.192
114.37,-37.87,0.192
114.38,-37.81,0.192
114.39,-37.74,0.192
114.39,-37.67,0.192
114.40,-37.61,0.192
114.41,-37.54,0.192
114.41,-37.47,0.192
114.42,-37.41,0.192
114.43,-37.34,0.192
114.43,-37.27,0.192
114.44,-37.21,0.192
114.45,-37.14,0.192
114.45,-37.07,0.192
114.46,-37.01,0.192
114.47,-36.94,0.192
114.47,-36.87,0.192
114.48,-36.81,0.192
114.49,-36.74,0.192
114.49,-36.67,0.192
114.50,-36.60,0.192
114.51,-36.54,0.192
114.51,-36.47,0.192
114.52,-36.41,0.192
114.53,-36.34,0.192
114.53,-36.27,0.192
114.54,-36.21,0.192
114.55,-36.14,0.192
114.55,-36.07,0.192
114.56,-36.00,0.193
114.57,-35.94,0.193
114.57,-35.87,0.193
114.58,-35.80,0.193
114.59,-35.74,0.193
114.59,-35.67,0.193
114.60,-35.60,0.193
114.61,-35.54,0.193
114.61,-35.47,0.193
114.62,-35.40,0.193
114.63,-35.34,0.193
114.63,-35.27,0.193
114.64,-35.20,0.193
114.65,-35.14,0.193
114.65,-35.07,0.193
114.66,-35.00,0.193
114.67,-34.94,0.193
114.67,-34.87,0.193
114.68,-34.80,0.193
114.69,-34.74,0.193
114.69,-34.67,0.193
114.70,-34.60,0.193
114.71,-34.54,0.193
114.71,-34.47,0.193
114.72,-34.40,0.193
114.73,-34.34,0.193
114.73,-34.27,0.193
114.74,-34.20,0.193
114.75,-34.14,0.193
114.75,-34.07,0.193
114.76,-34.00,0.193
114.77,-33.93,0.193
114.77,-33.87,0.193
114.78,-33.80,0.193
114.79,-33.73,0.193
114.79,-33.67,0.194
114.80,-33.60,0.194
114.81,-33.53,0.194
114.81,-33.47,0.194
114.82,-33.40,0.194
114.83,-33.33,0.194
114.83,-33.27,0.194
114.84,-33.20,0.194
114.85,-33.13,0.194
114.85,-33.07,0.194
114.86,-33.00,0.194
114.87,-32.93,0.194
114.87,-32.87,0.194
114.88,-32.80,0.194
114.89,-32.73,0.194
114.89,-32.67,0.194
114.90,-32.60,0.194
114.91,-32.53,0.194
114.91,-32.47,0.194
114.92,-32.40,0.194
114.93,-32.33,0.194
114.93,-32.27,0.194
114.94,-32.20,0.194
114.95,-32.13,0.194
114.95,-32.07,0.194
114.96,-32.00,0.194
114.97,-31.93,0.194
114.97,-31.87,0.194
114.98,-31.80,0.194
114.99,-31.73,0.194
114.99,-31.67,0.194
115.00,-31.60,0.194
115.01,-31.53,0.195
115.01,-31.47,0.195
115.02,-31.40,0.195
115.03,-31.33,0.195
115.03,-31.26,0.195
115.04,-31.20,0.195
115.05,-31.13,0.195
115.05,-31.06,0.195
115.06,-31.00,0.195
115.07,-30.93,0.195
115.07,-30.86,0.195
115.08,-30.80,0.195
115.09,-30.73,0.195
115.09,-30.66,0.195
115.10,-30.60,0.195
115.11,-30.53,0.195
115.11,-30.46,0.195
115.12,-30.40,0.195
115.13,-30.33,0.195
115.13,-30.26,0.195
115.14,-30.20,0.195
115.15,-30.13,0.195
115.15,-30.06,0.195
115.16,-30.00,0.195
115.17,-29.93,0.195
115.17,-29.86,0.195
115.18,-29.80,0.195
115.19,-29.73,0.195
115.19,-29.66,0.195
115.20,-29.60,0.195
115.21,-29.53,0.195
115.21,-29.46,0.195
115.22,-29.40,0.195
115.23,-29.33,0.195
115.23,-29.26,0.195
115.24,-29.19,0.195
115.25,-29.13,0.195
115.25,-29.06,0.195
115.26,-28.99,0.195
115.27,-28.93,0.196
115.27,-28.86,0.196
115.28,-28.79,0.196
115.29,-28.73,0.196
115.29,-28.66,0.196
115.30,-28.59,0.196
115.31,-28.53,0.196
115.31,-28.46,0.196
115.32,-28.39,0.196
115.33,-28.33,0.196
115.33,-28.26,0.196
115.34,-28.19,0.196
115.35,-28.13,0.196
115.35,-28.06,0.196
115.36,-27.99,0.196
115.37,-27.93,0.196
115.37,-27.86,0.196
115.38,-27.79,0.196
115.39,-27.72,0.196
115.39,-27.66,0.196
115.40,-27.59,0.196
115.41,-27.53,0.196
115.41,-27.46,0.196
115.42,-27.39,0.196
115.43,-27.33,0.196
115.43,-27.26,0.196
115.44,-27.19,0.196
115.45,-27.12,0.196
115.45,-27.06,0.196
115.46,-26.99,0.196
115.47,-26.93,0.197
115.47,-26.86,0.197
115.48,-26.79,0.197
115.49,-26.72,0.197
115.49,-26.66,0.197
115.50,-26.59,0.197
115.51,-26.52,0.197
115.51,-26.46,0.197
115.52,-26.39,0.197
115.53,-26.32,0.197
115.53,-26.26,0.197
115.54,-26.19,0.197
115.55,-26.12,0.197
115.55,-26.06,0.197
115.56,-25.99,0.197
115.57,-25.92,0.197
115.57,-25.86,0.197
115.58,-25.79,0.197
115.59,-25.72,0.197
115.59,-25.66,0.197
115.60,-25.59,0.197
115.61,-25.52,0.197
115.61,-25.46,0.197
115.62,-25.39,0.197
115.63,-25.32,0.197
115.63,-25.26,0.197
115.64,-25.19,0.197
115.65,-25.12,0.197
115.65,-25.06,0.197
115.66,-24.99,0.197
115.67,-24.92,0.197
115.67,-24.85,0.197
115.68,-24.79,0.197
115.69,-24.72,0.198
115.69,-24.66,0.198
115.70,-24.59,0.198
115.71,-24.52,0.198
115.71,-24.45,0.198
115.72,-24.39,0.198
115.73,-24.32,0.198
115.73,-24.25,0.198
115.74,-24.19,0.198
115.75,-24.12,0.198
115.75,-24.06,0.198
115.76,-23.99,0.198
115.77,-23.92,0.198
115.77,-23.85,0.198
115.78,-23.79,0.198
115.79,-23.72,0.198
115.79,-23.65,0.198
115.80,-23.59,0.198
115.81,-23.52,0.198
115.81,-23.45,0.198
115.82,-23.39,0.198
115.83,-23.32,0.198
115.83,-23.25,0.198
115.84,-23.19,0.198
115.85,-23.12,0.198
115.85,-23.05,0.198
115.86,-22.99,0.198
115.87,-22.92,0.198
115.87,-22.85,0.198
115.88,-22.79,0.199
115.89,-22.72,0.199
115.89,-22.65,0.199
115.90,-22.59,0.199
115.91,-22.52,0.199
115.91,-22.45,0.199
115.92,-22.39,0.199
115.93,-22.32,0.199
115.93,-22.25,0.199
115.94,-22.19,0.199
115.95,-22.12,0.199
115.95,-22.05,0.199
115.96,-21.98,0.199
115.97,-21.92,0.199
115.97,-21.85,0.199
115.98,-21.78,0.199
115.99,-21.72,0.199
115.99,-21.65,0.199
116.00,-21.58,0.199
116.01,-21.52,0.199
116.01,-21.45,0.199
116.02,-21.38,0.199
116.03,-21.32,0.199
116.03,-21.25,0.199
116.04,-21.18,0.199
116.05,-21.12,0.199
116.05,-21.05,0.199
116.06,-20.98,0.199
116.07,-20.92,0.199
116.07,-20.85,0.199
116.08,-20.78,0.200
116.09,-20.72,0.200
116.09,-20.65,0.200
116.10,-20.58,0.200
116.11,-20.52,0.200
116.11,-20.45,0.200
116.12,-20.38,0.200
116.13,-20.32,0.200
116.13,-20.25,0.200
116.14,-20.18,0.200
116.15,-20.12,0.200
116.15,-20.05,0.200
116.16,-19.98,0.200
116.17,-19.92,0.200
116.17,-19.85,0.200
116.18,-19.78,0.200
116.19,-19.71,0.200
116.19,-19.65,0.200
116.20,-19.58,0.200
116.21,-19.52,0.200
116.21,-19.45,0.200
116.22,-19.38,0.200
116.23,-19.32,0.200
116.23,-19.25,0.200
116.24,-19.18,0.200
116.25,-19.11,0.200
116.25,-19.05,0.201
116.26,-18.98,0.201
116.27,-18.91,0.201
116.27,-18.85,0.201
116.28,-18.78,0.201
116.29,-18.71,0.201
116.29,-18.65,0.201
116.30,-18.58,0.201
116.31,-18.51,0.201
116.31,-18.45,0.201
116.32,-18.38,0.201
116.33,-18.31,0.201
116.33,-18.25,0.201
116.34,-18.18,0.201
116.35,-18.11,0.201
116.35,-18.05,0.201
116.36,-17.98,0.201
116.37,-17.91,0.201
116.37,-17.85,0.201
116.38,-17.78,0.201
116.39,-17.71,0.201
116.39,-17.65,0.201
116.40,-17.58,0.201
116.41,-17.51,0.201
116.41,-17.45,0.201
116.42,-17.38,0.201
116.43,-17.31,0.202
116.43,-17.25,0.202
116.44,-17.18,0.202
116.45,-17.11,0.202
116.45,-17.05,0.202
116.46,-16.98,0.202
116.47,-16.91,0.202
116.47,-16.84,0.202
116.48,-16.78,0.202
116.49,-16.71,0.202
116.49,-16.64,0.202
116.50,-16.58,0.202
116.51,-16.51,0.202
116.51,-16.44,0.202
116.52,-16.38,0.202
116.53,-16.31,0.202
116.53,-16.24,0.202
116.54,-16.18,0.202
116.55,-16.11,0.202
116.55,-16.04,0.202
116.56,-15.97,0.202
116.57,-15.91,0.202
116.57,-15.84,0.202
116.58,-15.77,0.202
116.59,-15.70,0.203
116.59,-15.64,0.203
116.60,-15.57,0.203
116.61,-15.51,0.203
116.61,-15.44,0.203
116.62,-15.37,0.203
116.63,-15.30,0.203
116.63,-15.24,0.203
116.64,-15.17,0.203
116.65,-15.10,0.203
116.65,-15.04,0.203
116.66,-14.97,0.203
116.67,-14.91,0.204
116.67,-14.84,0.204
116.68,-14.77,0.204
116.69,-14.70,0.204
116.69,-14.64,0.204
116.70,-14.57,0.204
116.71,-14.50,0.204
116.71,-14.44,0.204
116.72,-14.37,0.204
116.73,-14.30,0.204
116.73,-14.24,0.204
116.74,-14.17,0.204
116.75,-14.10,0.204
116.75,-14.04,0.204
116.76,-13.97,0.204
116.77,-13.90,0.204
116.77,-13.84,0.204
116.78,-13.77,0.204
116.79,-13.70,0.204
116.79,-13.64,0.204
116.80,-13.57,0.204
116.81,-13.50,0.204
116.81,-13.44,0.204
116.82,-13.37,0.204
116.83,-13.30,0.205
116.83,-13.24,0.205
116.84,-13.17,0.205
116.85,-13.10,0.205
116.85,-13.04,0.205
116.86,-12.97,0.205
116.87,-12.90,0.205
116.87,-12.84,0.205
116.88,-12.77,0.205
116.89,-12.70,0.205
116.89,-12.64,0.205
116.90,-12.57,0.205
116.91,-12.50,0.205
116.91,-12.44,0.205
116.92,-12.37,0.205
116.93,-12.30,0.205
116.93,-12.24,0.205
116.94,-12.17,0.206
116.95,-12.10,0.206
116.95,-12.04,0.206
116.96,-11.97,0.206
116.97,-11.90,0.206
116.97,-11.84,0.206
116.98,-11.77,0.206
116.99,-11.70,0.206
116.99,-11.64,0.206
117.00,-11.57,0.206
117.01,-11.50,0.206
117.01,-11.44,0.206
117.02,-11.37,0.206
117.03,-11.30,0.206
117.03,-11.24,0.206
117.04,-11.17,0.206
117.05,-11.10,0.206
117.05,-11.04,0.206
117.06,-10.97,0.206
117.07,-10.90,0.206
117.07,-10.84,0.206
117.08,-10.77,0.207
117.09,-10.70,0.207
117.09,-10.64,0.207
117.10,-10.57,0.207
117.11,-10.50,0.207
117.11,-10.43,0.207
117.12,-10.37,0.207
117.13,-10.30,0.207
117.13,-10.24,0.207
117.14,-10.17,0.207
117.15,-10.10,0.207
117.15,-10.04,0.207
117.16,-9.97,0.207
117.17,-9.90,0.207
117.17,-9.84,0.207
117.18,-9.77,0.208
117.19,-9.70,0.208
117.19,-9.64,0.208
117.20,-9.57,0.208
117.21,-9.50,0.208
117.21,-9.44,0.208
117.22,-9.37,0.208
117.23,-9.30,0.208
117.23,-9.24,0.208
117.24,-9.17,0.208
117.25,-9.10,0.208
117.25,-9.04,0.208
117.26,-8.97,0.209
117.27,-8.90,0.209
117.27,-8.83,0.209
117.28,-8.77,0.209
117.29,-8.70,0.209
117.29,-8.63,0.209
117.30,-8.57,0.209
117.31,-8.50,0.209
117.31,-8.44,0.209
117.32,-8.37,0.209
117.33,-8.30,0.209
117.33,-8.24,0.210
117.34,-8.17,0.210
117.35,-8.10,0.210
117.35,-8.03,0.210
117.36,-7.97,0.210
117.37,-7.90,0.210
117.37,-7.83,0.210
117.38,-7.77,0.210
117.39,-7.70,0.211
117.39,-7.64,0.211
117.40,-7.57,0.211
117.41,-7.50,0.211
117.41,-7.44,0.211
117.42,-7.37,0.211
117.43,-7.30,0.211
117.43,-7.23,0.211
117.44,-7.17,0.212
117.45,-7.10,0.212
117.45,-7.04,0.212
117.46,-6.97,0.212
117.47,-6.90,0.212
117.47,-6.84,0.212
117.48,-6.77,0.212
117.49,-6.70,0.213
117.49,-6.64,0.213
117.50,-6.57,0.213
117.51,-6.50,0.213
117.51,-6.44,0.213
117.52,-6.37,0.214
117.53,-6.30,0.214
117.53,-6.24,0.214
117.54,-6.17,0.214
117.55,-6.10,0.215
117.55,-6.04,0.215
117.56,-5.97,0.215
117.57,-5.90,0.215
117.57,-5.84,0.215
117.58,-5.77,0.215
117.59,-5.70,0.216
117.59,-5.63,0.216
117.60,-5.57,0.216
117.61,-5.50,0.216
117.61,-5.43,0.216
117.62,-5.37,0.217
117.63,-5.30,0.217
117.63,-5.23,0.217
117.64,-5.17,0.217
117.65,-5.10,0.217
117.65,-5.04,0.218
117.66,-4.97,0.218
117.67,-4.90,0.218
117.67,-4.84,0.219
117.68,-4.77,0.219
117.69,-4.70,0.219
117.69,-4.63,0.219
117.70,-4.57,0.219
117.71,-4.50,0.220
117.71,-4.44,0.220
117.72,-4.37,0.220
117.73,-4.30,0.221
117.73,-4.23,0.221
117.74,-4.17,0.221
117.75,-4.10,0.222
117.75,-4.03,0.222
117.76,-3.97,0.222
117.77,-3.90,0.223
117.77,-3.84,0.223
117.78,-3.77,0.224
117.79,-3.70,0.224
117.79,-3.64,0.224
117.80,-3.57,0.224
117.81,-3.50,0.225
117.81,-3.43,0.225
117.82,-3.37,0.225
117.83,-3.30,0.226
117.83,-3.24,0.226
117.84,-3.17,0.227
117.85,-3.10,0.227
117.85,-3.04,0.227
117.86,-2.97,0.228
117.87,-2.90,0.229
117.87,-2.84,0.229
117.88,-2.77,0.230
117.89,-2.70,0.231
117.89,-2.64,0.231
117.90,-2.57,0.231
117.91,-2.50,0.232
117.91,-2.44,0.234
117.92,-2.37,0.235
117.93,-2.30,0.236
117.93,-2.24,0.236
117.94,-2.17,0.237
117.95,-2.10,0.238
117.95,-2.03,0.238
117.96,-1.97,0.238
117.97,-1.90,0.239
117.97,-1.84,0.239
117.98,-1.77,0.240
117.99,-1.70,0.241
117.99,-1.64,0.242
118.00,-1.57,0.242
118.01,-1.50,0.243
118.01,-1.44,0.244
118.02,-1.37,0.245
118.03,-1.30,0.245
118.03,-1.24,0.246
118.04,-1.17,0.247
118.05,-1.10,0.248
118.05,-1.04,0.248
118.06,-0.97,0.250
118.07,-0.90,0.251
118.07,-0.84,0.251
118.08,-0.77,0.252
118.09,-0.70,0.253
118.09,-0.64,0.253
118.10,-0.57,0.254
118.11,-0.50,0.255
118.11,-0.44,0.256
118.12,-0.37,0.256
118.13,-0.30,0.257
118.13,-0.24,0.257
118.14,-0.17,0.258
118.15,-0.11,0.258
118.15,-0.04,0.259
118.16,0.03,0.260
118.17,0.09,0.261
118.17,0.16,0.261
118.18,0.23,0.261
118.19,0.30,0.262
118.19,0.36,0.262
118.20,0.43,0.263
118.21,0.49,0.263
118.21,0.56,0.264
118.22,0.63,0.265
118.23,0.69,0.265
118.23,0.76,0.265
118.24,0.83,0.266
118.25,0.89,0.266
118.25,0.96,0.267
118.26,1.03,0.267
118.27,1.09,0.268
118.27,1.16,0.269
118.28,1.23,0.269
118.29,1.29,0.269
118.29,1.36,0.269
118.30,1.43,0.270
118.31,1.49,0.270
118.31,1.56,0.270
118.32,1.63,0.270
118.33,1.69,0.271
118.33,1.76,0.272
118.34,1.83,0.272
118.35,1.89,0.272
118.35,1.96,0.272
118.36,2.03,0.272
118.37,2.09,0.272
118.37,2.16,0.272
118.38,2.23,0.273
118.39,2.29,0.273
118.39,2.36,0.273
118.40,2.43,0.273
118.41,2.49,0.273
118.41,2.56,0.273
118.42,2.63,0.273
118.43,2.69,0.273
118.43,2.76,0.273
118.44,2.83,0.274
118.45,2.89,0.274
118.45,2.96,0.274
118.46,3.03,0.274
118.47,3.09,0.274
118.47,3.16,0.274
118.48,3.23,0.274
118.49,3.29,0.274
118.49,3.36,0.274
118.50,3.43,0.274
118.51,3.49,0.274
118.51,3.56,0.274
118.52,3.63,0.274
118.53,3.70,0.274
118.53,3.76,0.273
118.54,3.83,0.273
118.55,3.90,0.273
118.55,3.96,0.273
118.56,4.03,0.273
118.57,4.10,0.273
118.57,4.16,0.273
118.58,4.23,0.273
118.59,4.30,0.273
118.59,4.36,0.272
118.60,4.43,0.272
118.61,4.50,0.272
118.61,4.56,0.272
118.62,4.63,0.272
118.63,4.70,0.272
118.63,4.76,0.272
118.64,4.83,0.272
118.65,4.90,0.271
118.65,4.96,0.271
118.66,5.03,0.271
118.67,5.10,0.271
118.67,5.16,0.271
118.68,5.23,0.271
118.69,5.30,0.271
118.69,5.37,0.271
118.70,5.43,0.270
118.71,5.50,0.270
118.71,5.57,0.270
118.72,5.63,0.270
118.73,5.70,0.270
118.73,5.77,0.270
118.74,5.83,0.269
118.75,5.90,0.269
118.75,5.97,0.269
118.76,6.03,0.269
118.77,6.10,0.269
118.77,6.17,0.269
118.78,6.23,0.269
118.79,6.30,0.269
118.79,6.37,0.268
118.80,6.44,0.268
118.81,6.50,0.268
118.81,6.57,0.268
118.82,6.63,0.268
118.83,6.70,0.268
118.83,6.77,0.268
118.84,6.84,0.268
118.85,6.90,0.268
118.85,6.97,0.267
118.86,7.04,0.267
118.87,7.10,0.267
118.87,7.17,0.267
118.88,7.24,0.267
118.89,7.30,0.267
118.89,7.37,0.267
118.90,7.44,0.267
118.91,7.50,0.267
118.91,7.57,0.267
118.92,7.64,0.267
118.93,7.70,0.266
118.93,7.77,0.266
118.94,7.84,0.266
118.95,7.90,0.266
118.95,7.97,0.266
118.96,8.04,0.266
118.97,8.10,0.266
118.97,8.17,0.266
118.98,8.24,0.266
118.99,8.30,0.266
118.99,8.37,0.266
119.00,8.44,0.266
119.01,8.50,0.266
119.01,8.57,0.266
119.02,8.64,0.266
119.03,8.71,0.266
119.03,8.77,0.266
119.04,8.84,0.266
119.05,8.91,0.266
119.05,8.97,0.265
119.06,9.04,0.265
119.07,9.11,0.265
119.07,9.17,0.265
119.08,9.24,0.265
119.09,9.31,0.265
119.09,9.37,0.265
119.10,9.44,0.265
119.11,9.51,0.265
119.11,9.57,0.265
119.12,9.64,0.265
119.13,9.71,0.265
119.13,9.77,0.265
119.14,9.84,0.265
119.15,9.91,0.265
119.15,9.97,0.265
119.16,10.04,0.265
119.17,10.11,0.265
119.17,10.17,0.265
119.18,10.24,0.265
119.19,10.31,0.265
119.19,10.37,0.265
119.20,10.44,0.265
119.21,10.51,0.265
119.21,10.57,0.265
119.22,10.64,0.265
119.23,10.71,0.265
119.23,10.77,0.265
119.24,10.84,0.265
119.25,10.91,0.265
119.25,10.98,0.265
119.26,11.04,0.265
119.27,11.11,0.265
119.27,11.18,0.265
119.28,11.24,0.265
119.29,11.31,0.265
119.29,11.38,0.265
119.30,11.44,0.265
119.31,11.51,0.265
119.31,11.58,0.265
119.32,11.64,0.265
119.33,11.71,0.265
119.33,11.77,0.265
119.34,11.84,0.265
119.35,11.91,0.265
119.35,11.98,0.265
119.36,12.04,0.265
119.37,12.11,0.265
119.37,12.18,0.265
119.38,12.24,0.265
119.39,12.31,0.265
119.39,12.38,0.265
119.40,12.44,0.265
119.41,12.51,0.265
119.41,12.58,0.265
119.42,12.64,0.265
119.43,12.71,0.265
119.43,12.78,0.265
119.44,12.84,0.265
119.45,12.91,0.265
119.45,12.98,0.265
119.46,13.04,0.266
119.47,13.11,0.266
119.47,13.18,0.266
119.48,13.24,0.266
119.49,13.31,0.266
119.49,13.38,0.266
119.50,13.45,0.266
119.51,13.51,0.266
119.51,13.58,0.266
119.52,13.64,0.266
119.53,13.71,0.266
119.53,13.78,0.266
119.54,13.85,0.266
119.55,13.91,0.266
119.55,13.98,0.266
119.56,14.04,0.266
119.57,14.11,0.266
119.57,14.18,0.266
119.58,14.25,0.266
119.59,14.31,0.266
119.59,14.38,0.266
119.60,14.45,0.266
119.61,14.51,0.266
119.61,14.58,0.266
119.62,14.65,0.266
119.63,14.71,0.266
119.63,14.78,0.266
119.64,14.85,0.266
119.65,14.91,0.266
119.65,14.98,0.266
119.66,15.05,0.266
119.67,15.11,0.266
119.67,15.18,0.266
119.68,15.25,0.266
119.69,15.31,0.266
119.69,15.38,0.266
119.70,15.45,0.267
119.71,15.51,0.267
119.71,15.58,0.267
119.72,15.65,0.267
119.73,15.71,0.267
119.73,15.78,0.267
119.74,15.85,0.267
119.75,15.91,0.267
119.75,15.98,0.267
119.76,16.05,0.267
119.77,16.11,0.267
119.77,16.18,0.267
119.78,16.25,0.267
119.79,16.32,0.267
119.79,16.38,0.267
119.80,16.45,0.267
119.81,16.51,0.267
119.81,16.58,0.267
119.82,16.65,0.267
119.83,16.72,0.267
119.83,16.78,0.267
119.84,16.85,0.267
119.85,16.92,0.267
119.85,16.98,0.267
119.86,17.05,0.267
119.87,17.12,0.267
119.87,17.18,0.267
119.88,17.25,0.268
119.89,17.32,0.268
119.89,17.38,0.268
119.90,17.45,0.268
119.91,17.52,0.268
119.91,17.58,0.268
119.92,17.65,0.268
119.93,17.72,0.268
119.93,17.78,0.268
119.94,17.85,0.268
119.95,17.92,0.268
119.95,17.98,0.268
119.96,18.05,0.268
119.97,18.12,0.268
119.97,18.18,0.268
119.98,18.25,0.268
119.99,18.32,0.268
119.99,18.38,0.268
120.00,18.45,0.268
120.01,18.52,0.268
120.01,18.58,0.268
120.02,18.65,0.268
120.03,18.72,0.268
120.03,18.79,0.268
120.04,18.85,0.269
120.05,18.92,0.269
120.05,18.98,0.269
120.06,19.05,0.269
120.07,19.12,0.269
120.07,19.19,0.269
120.08,19.25,0.269
120.09,19.32,0.269
120.09,19.39,0.269
120.10,19.45,0.269
120.11,19.52,0.269
120.11,19.59,0.269
120.12,19.65,0.269
120.13,19.72,0.269
120.13,19.79,0.269
120.14,19.85,0.269
120.15,19.92,0.269
120.15,19.99,0.269
120.16,20.05,0.269
120.17,20.12,0.269
120.17,20.19,0.269
120.18,20.25,0.269
120.19,20.32,0.269
120.19,20.39,0.269
120.20,20.45,0.269
120.21,20.52,0.270
120.21,20.59,0.270
120.22,20.65,0.270
120.23,20.72,0.270
120.23,20.79,0.270
120.24,20.85,0.270
120.25,20.92,0.270
120.25,20.99,0.270
120.26,21.05,0.270
120.27,21.12,0.270
120.27,21.19,0.270
120.28,21.25,0.270
120.29,21.32,0.270
120.29,21.39,0.270
120.30,21.45,0.270
120.31,21.52,0.270
120.31,21.59,0.270
120.32,21.65,0.270
120.33,21.72,0.270
120.33,21.79,0.270
120.34,21.85,0.270
120.35,21.92,0.270
120.35,21.99,0.271
120.36,22.05,0.271
120.37,22.12,0.271
120.37,22.19,0.271
120.38,22.25,0.271
120.39,22.32,0.271
120.39,22.39,0.271
120.40,22.46,0.271
120.41,22.52,0.271
120.41,22.59,0.271
120.42,22.65,0.271
120.43,22.72,0.271
120.43,22.79,0.271
120.44,22.86,0.271
120.45,22.92,0.271
120.45,22.99,0.271
120.46,23.06,0.271
120.47,23.12,0.271
120.47,23.19,0.271
120.48,23.26,0.271
120.49,23.32,0.271
120.49,23.39,0.271
120.50,23.46,0.271
120.51,23.52,0.272
120.51,23.59,0.272
120.52,23.66,0.272
120.53,23.72,0.272
120.53,23.79,0.272
120.54,23.86,0.272
120.55,23.92,0.272
120.55,23.99,0.272
120.56,24.06,0.272
120.57,24.12,0.272
120.57,24.19,0.272
120.58,24.26,0.272
120.59,24.32,0.272
120.59,24.39,0.272
120.60,24.46,0.272
120.61,24.52,0.272
120.61,24.59,0.272
120.62,24.66,0.272
120.63,24.72,0.272
120.63,24.79,0.273
120.64,24.86,0.273
120.65,24.92,0.273
120.65,24.99,0.273
120.66,25.06,0.273
120.67,25.13,0.273
120.67,25.19,0.273
120.68,25.26,0.273
120.69,25.33,0.273
120.69,25.39,0.273
120.70,25.46,0.273
120.71,25.53,0.273
120.71,25.59,0.273
120.72,25.66,0.273
120.73,25.73,0.273
120.73,25.79,0.273
120.74,25.86,0.273
120.75,25.92,0.273
120.75,25.99,0.273
120.76,26.06,0.273
120.77,26.13,0.273
120.77,26.19,0.273
120.78,26.26,0.273
120.79,26.33,0.273
120.79,26.39,0.274
120.80,26.46,0.274
120.81,26.53,0.274
120.81,26.59,0.274
120.82,26.66,0.274
120.83,26.73,0.274
120.83,26.79,0.274
120.84,26.86,0.274
120.85,26.93,0.274
120.85,26.99,0.274
120.86,27.06,0.274
120.87,27.13,0.274
120.87,27.19,0.274
120.88,27.26,0.274
120.89,27.33,0.274
120.89,27.39,0.274
120.90,27.46,0.274
120.91,27.53,0.274
120.91,27.59,0.274
120.92,27.66,0.274
120.93,27.73,0.274
120.93,27.79,0.274
120.94,27.86,
120.95,27.93,
120.95,28.00,
120.96,28.06,
120.97,28.13,
120.97,28.20,
120.98,28.26,
120.99,,
120.99,,