File: DSC/2025_02_13_CBN_FluoroWorks_Recrystallized_DSC.txt
Filename	2025_02_13_CBN_FluoroWorks_Recrystallized_DSC
Instrument name	DSC2A-00468 (192.168.1.100)
Operator	JLY
rundate	2/14/2025
Sample name	2025_02_13_CBN_FluoroWorks_Recrystallized_DSC
proceduresegments	Data Off ; Equilibrate -40.00 °C; Data On ; Ramp 5.00 °C/min to 120.00 °C; Data Off ; Isothermal 1.0 min; Data On ; Ramp 5.00 °C/min to -40.00 °C; Data Off ; Isothermal 1.0 min; Data On ; Ramp 5.00 °C/min to 120.00 °C; Data Off ; Isothermal 1.0 min; Data On ; Ramp 5.00 °C/min to -40.00 °C; Data Off ; Isothermal 1.0 min; Data On ; Ramp 5.00 °C/min to 120.00 °C
[File Parameters]
Run date	2/14/2025 12:08:01 AM
Trios version	5.1.1.46572
Original File Name
Current File Name	D:\DSC2500\CHM343\2025_02_13_CBN_FluoroWorks_Recrystallized_DSC.tri
[Procedure]
Procedure Name	CBN Melting x3
Sample Name	2025_02_13_CBN_FluoroWorks_Recrystallized_DSC
Sample Mass	3.81 mg
Reference Sample Mass	0 mg
Pan Mass	53.38 mg
Pan Number	15
Reference Pan Mass	54 mg
Reference Pan Number	19
Pan Type	Tzero Aluminum Hermetic
Comments	Al Hermetic Sealed Pan, with ref Al pan.  FloroWorks CBN, recrystallized.
Project Name
Operator	JLY
Test	Custom
Unload Max Temperature	30
Unload Min Temperature	30
Load Max Temperature	30
Load Min Temperature	30
Stop on Gas Flow Error	Yes
[Signal List]
Signal #1	Time (min)
Signal #2	Temperature (°C)
Signal #3	Heat Flow (mW)
Signal #4	Delta T (µV)
Signal #5	Delta Tzero (µV)
Signal #6	Tzero Temperature (°C)
Signal #7	Cell Purge (mL/min)
Signal #8	Heater Temp (°C)
Signal #9	Power Delivered (W)
Signal #10	Reference Junction Temperature (°C)
Signal #11	Flange Temperature (°C)
Signal #12	Heat Flow Phase (rad)
Signal #13	Total Heat Capacity (J/°C)
Signal #14	Heat Capacity (J/°C)
[Configuration]
Company Name	ASU
Instrument Name	DSC2A-00468
Instrument Type	DSC2500
Serial Number	DSC2A-00468
IP	192.168.1.100
Location of Instrument	MRRC
DisplayType	Unknown
Sample Interval 	0.1 s/pt
Selected Heat Flow	T4P
Exotherm Direction	Down
Cell Serial	DRC2-00792
Lid Type	Standard
Cooler	RCS 90
Leave Cooler on at End of Sequence	On
Gas 2	Nitrogen
Gas Selected	Channel 1
Flow Rate	50 mL/min
Secondary Purge	On
Licensed Heat Flow	Heat Flow T4P
Modulation Licensed	Yes
[Versions]
Common IDD Version	1
Cortex Version	VER 2.10.2.31
Driver	5.0.0.6
GDM Version	1.0.3.3
TouchscreenVersion	1.0.0.16145
FEP Version	1.2.1.21
FEP Bootloader	2.0.0.5
AutoSampler Version	2.1.1.26
Auto Sampler Bootloader	2.0.0.5
FCM Version	1.1.0.3
FCM Bootloader	2.0.0.5
[Experiment Logs]
Experiment Log Entry # 1	Air Cool is off.
Experiment Log Entry # 3	Data On set to 0
Experiment Log Entry # 5	Equilibrate Segment -40 (C) Started
Experiment Log Entry # 7	Data On set to 1
Experiment Log Entry # 9	Ramp Segment 5 C/min to 120 Started
Experiment Log Entry # 11	Data On set to 0
Experiment Log Entry # 13	Isothermal Segment 1 min started
Experiment Log Entry # 15	Data On set to 1
Experiment Log Entry # 17	Ramp Segment 5 C/min to -40 Started
Experiment Log Entry # 19	Data On set to 0
Experiment Log Entry # 21	Isothermal Segment 1 min started
Experiment Log Entry # 23	Data On set to 1
Experiment Log Entry # 25	Ramp Segment 5 C/min to 120 Started
Experiment Log Entry # 27	Data On set to 0
Experiment Log Entry # 29	Isothermal Segment 1 min started
Experiment Log Entry # 31	Data On set to 1
Experiment Log Entry # 33	Ramp Segment 5 C/min to -40 Started
Experiment Log Entry # 35	Data On set to 0
Experiment Log Entry # 37	Isothermal Segment 1 min started
Experiment Log Entry # 39	Data On set to 1
Experiment Log Entry # 41	Ramp Segment 5 C/min to 120 Started
[Method Log]
Method Log Entry # 1	Data Off
Method Log Entry # 2	Equilibrate -40 °C
Method Log Entry # 3	Data On
Method Log Entry # 4	(Ramp 101762) Ramp 5 °C/minute to 120 °C
Method Log Entry # 5	Data Off
Method Log Entry # 6	Isothermal 1 minutes
Method Log Entry # 7	Data On
Method Log Entry # 8	(Ramp 101766) Ramp 5 °C/minute to -40 °C
Method Log Entry # 9	Data Off
Method Log Entry # 10	Isothermal 1 minutes
Method Log Entry # 11	Data On
Method Log Entry # 12	(Ramp 101770) Ramp 5 °C/minute to 120 °C
Method Log Entry # 13	Data Off
Method Log Entry # 14	Isothermal 1 minutes
Method Log Entry # 15	Data On
Method Log Entry # 16	(Ramp 101774) Ramp 5 °C/minute to -40 °C
Method Log Entry # 17	Data Off
Method Log Entry # 18	Isothermal 1 minutes
Method Log Entry # 19	Data On
Method Log Entry # 20	(Ramp 101778) Ramp 5 °C/minute to 120 °C
Cell Serial	DRC2-00792
[T1 Calibration]
Slope	-0.008529666
Offset	9.636258
Initial Temperature	98.23
GUID	f8bfdadc-4977-4fdf-ba6d-0ba9134940c3
[TZero Calibration]
Date Applied	11/29/2022 4:06:13 PM
Description	From -89.059 °C to 396.009 °C at 20.000°C/min
Gas Type	Nitrogen
Pan Type	None
Source Files 1	C:\Users\yargerlab\Desktop\DSC Data\General\TZero_calibration_11_29_22_2nd(2).tri
Source Files 2	C:\Users\yargerlab\Desktop\DSC Data\General\TZero_calibration_11_29_22_2nd(3).tri
Delta T Offset	13.05235
Delta T Slope	-0.007271007
Delta T0 Offset	-13.69128
Delta T0 Slope	0.06063341
[Temperature Calibration]
Date Applied	11/29/2022 7:12:28 PM
Description	From 106.590 °C to 186.590 °C at 10.000°C/min
Gas Type	Nitrogen
Pan Type	Tzero Aluminum Hermetic
Source Files 1	C:\Users\yargerlab\Desktop\DSC Data\General\Indium(6).tri
Measured 1	157.391
Known 1	156.598
[Cell Constant Calibration]
Date Applied	11/29/2022 7:12:29 PM
Description	From 106.590 °C to 186.590 °C at 10.000°C/min
Gas Type	Nitrogen
Pan Type	Tzero Aluminum Hermetic
Source Files 1	C:\Users\yargerlab\Desktop\DSC Data\General\Indium(6).tri
T4P KCell	1.006051
Onset Slope	63.26126 mW/°C
[Direct Cp Calibration]
Date Applied	11/30/2022 11:04:51 AM
Description	From -79.983 °C to 298.409 °C at 10.000°C/min
Gas Type	Nitrogen
Pan Type	Tzero Aluminum Hermetic
Source Files 1	C:\Users\yargerlab\Desktop\DSC Data\General\Sapphire_Heat_Capacity_11_30_22.tri
[Rev Cp Calibration]
Date Applied	11/30/2022 1:58:51 PM
Description	From -79.996 °C to 292.812 °C at 3.000°C/min
Gas Type	Nitrogen
Pan Type	Tzero Aluminum Hermetic
Source Files 1	C:\Users\yargerlab\Desktop\DSC Data\General\Sapphire_MDSC_Calibration_11_30_22.tri
[step]
Ramp 5.00 °C/min to 120.00 °C
Time	Temperature	Heat Flow (Normalized)
min	°C	W/g
0.00	-39.73	-0.059
0.02	-39.74	-0.060
0.04	-39.75	-0.052
0.07	-39.75	-0.046
0.09	-39.74	-0.041
0.11	-39.72	-0.037
0.13	-39.69	-0.031
0.15	-39.64	-0.021
0.17	-39.58	-0.012
0.19	-39.51	0.002
0.22	-39.43	0.016
0.24	-39.35	0.028
0.26	-39.26	0.036
0.28	-39.17	0.046
0.30	-39.08	0.054
0.33	-38.98	0.060
0.35	-38.88	0.065
0.37	-38.79	0.069
0.39	-38.68	0.071
0.41	-38.58	0.074
0.43	-38.48	0.075
0.45	-38.38	0.077
0.48	-38.28	0.079
0.50	-38.17	0.079
0.52	-38.07	0.080
0.54	-37.97	0.081
0.56	-37.86	0.081
0.58	-37.76	0.082
0.61	-37.65	0.082
0.63	-37.55	0.083
0.65	-37.44	0.083
0.67	-37.34	0.084
0.69	-37.23	0.084
0.72	-37.13	0.085
0.74	-37.02	0.085
0.76	-36.92	0.085
0.78	-36.81	0.086
0.80	-36.70	0.086
0.82	-36.60	0.086
0.85	-36.49	0.087
0.87	-36.38	0.087
0.89	-36.28	0.087
0.91	-36.17	0.087
0.93	-36.06	0.088
0.95	-35.96	0.088
0.98	-35.85	0.088
1.00	-35.74	0.088
1.02	-35.63	0.088
1.04	-35.53	0.088
1.06	-35.42	0.088
1.08	-35.31	0.089
1.11	-35.21	0.089
1.13	-35.10	0.089
1.15	-34.99	0.089
1.17	-34.88	0.089
1.19	-34.78	0.089
1.21	-34.67	0.089
1.23	-34.56	0.089
1.26	-34.45	0.089
1.28	-34.35	0.089
1.30	-34.24	0.089
1.32	-34.13	0.089
1.34	-34.02	0.089
1.37	-33.92	0.089
1.39	-33.81	0.089
1.41	-33.70	0.089
1.43	-33.59	0.089
1.45	-33.48	0.089
1.47	-33.38	0.089
1.49	-33.27	0.089
1.52	-33.16	0.089
1.54	-33.05	0.089
1.56	-32.95	0.089
1.58	-32.84	0.089
1.60	-32.73	0.089
1.63	-32.62	0.089
1.65	-32.51	0.089
1.67	-32.41	0.089
1.69	-32.30	0.088
1.71	-32.19	0.088
1.73	-32.08	0.088
1.76	-31.97	0.088
1.78	-31.86	0.088
1.80	-31.76	0.088
1.82	-31.65	0.088
1.84	-31.54	0.088
1.86	-31.43	0.088
1.88	-31.32	0.088
1.91	-31.21	0.088
1.93	-31.11	0.088
1.95	-31.00	0.088
1.97	-30.89	0.088
1.99	-30.78	0.088
2.02	-30.67	0.088
2.04	-30.57	0.088
2.06	-30.46	0.088
2.08	-30.35	0.088
2.10	-30.24	0.088
2.12	-30.13	0.088
2.14	-30.02	0.088
2.17	-29.92	0.088
2.19	-29.81	0.088
2.21	-29.70	0.087
2.23	-29.59	0.087
2.25	-29.48	0.087
2.28	-29.37	0.087
2.30	-29.26	0.087
2.32	-29.16	0.087
2.34	-29.05	0.087
2.36	-28.94	0.087
2.38	-28.83	0.087
2.41	-28.72	0.087
2.43	-28.61	0.087
2.45	-28.51	0.087
2.47	-28.40	0.087
2.49	-28.29	0.087
2.51	-28.18	0.087
2.54	-28.07	0.087
2.56	-27.96	0.087
2.58	-27.86	0.087
2.60	-27.74	0.087
2.62	-27.64	0.087
2.64	-27.53	0.087
2.66	-27.42	0.087
2.69	-27.31	0.087
2.71	-27.21	0.087
2.73	-27.10	0.087
2.75	-26.99	0.087
2.77	-26.88	0.087
2.79	-26.77	0.086
2.82	-26.66	0.086
2.84	-26.55	0.086
2.86	-26.45	0.086
2.88	-26.34	0.086
2.90	-26.23	0.086
2.93	-26.12	0.086
2.95	-26.01	0.086
2.97	-25.90	0.086
2.99	-25.80	0.086
3.01	-25.69	0.086
3.03	-25.58	0.086
3.06	-25.47	0.086
3.08	-25.36	0.086
3.10	-25.25	0.086
3.12	-25.15	0.086
3.14	-25.04	0.086
3.16	-24.93	0.086
3.19	-24.82	0.086
3.21	-24.71	0.086
3.23	-24.60	0.086
3.25	-24.50	0.086
3.27	-24.39	0.086
3.29	-24.28	0.086
3.31	-24.17	0.086
3.34	-24.06	0.086
3.36	-23.95	0.086
3.38	-23.84	0.086
3.40	-23.74	0.086
3.42	-23.63	0.086
3.44	-23.52	0.086
3.47	-23.41	0.086
3.49	-23.30	0.086
3.51	-23.19	0.086
3.53	-23.09	0.086
3.55	-22.98	0.086
3.58	-22.87	0.086
3.60	-22.76	0.086
3.62	-22.65	0.086
3.64	-22.54	0.086
3.66	-22.43	0.086
3.68	-22.33	0.086
3.71	-22.22	0.086
3.73	-22.11	0.086
3.75	-22.00	0.086
3.77	-21.89	0.086
3.79	-21.78	0.086
3.81	-21.68	0.086
3.84	-21.57	0.086
3.86	-21.46	0.086
3.88	-21.35	0.086
3.90	-21.24	0.086
3.92	-21.14	0.086
3.94	-21.03	0.086
3.96	-20.92	0.086
3.99	-20.81	0.086
4.01	-20.70	0.086
4.03	-20.59	0.086
4.05	-20.49	0.086
4.07	-20.37	0.086
4.09	-20.27	0.086
4.12	-20.16	0.086
4.14	-20.05	0.086
4.16	-19.94	0.086
4.18	-19.83	0.086
4.20	-19.73	0.086
4.23	-19.62	0.086
4.25	-19.51	0.086
4.27	-19.40	0.086
4.29	-19.29	0.086
4.31	-19.18	0.086
4.33	-19.08	0.086
4.35	-18.97	0.086
4.38	-18.86	0.086
4.40	-18.75	0.086
4.42	-18.64	0.086
4.44	-18.53	0.086
4.46	-18.42	0.086
4.49	-18.32	0.086
4.51	-18.21	0.086
4.53	-18.10	0.086
4.55	-17.99	0.086
4.57	-17.88	0.086
4.59	-17.77	0.086
4.61	-17.66	0.086
4.64	-17.56	0.086
4.66	-17.45	0.086
4.68	-17.34	0.086
4.70	-17.23	0.086
4.72	-17.12	0.086
4.75	-17.01	0.086
4.77	-16.91	0.086
4.79	-16.80	0.086
4.81	-16.69	0.086
4.83	-16.58	0.086
4.85	-16.47	0.086
4.88	-16.36	0.086
4.90	-16.26	0.086
4.92	-16.15	0.086
4.94	-16.04	0.086
4.96	-15.93	0.086
4.98	-15.82	0.086
5.00	-15.71	0.086
5.03	-15.60	0.086
5.05	-15.50	0.086
5.07	-15.39	0.086
5.09	-15.28	0.086
5.11	-15.17	0.086
5.14	-15.06	0.086
5.16	-14.95	0.086
5.18	-14.85	0.086
5.20	-14.74	0.086
5.22	-14.63	0.086
5.24	-14.52	0.086
5.26	-14.41	0.086
5.29	-14.30	0.086
5.31	-14.20	0.086
5.33	-14.09	0.086
5.35	-13.98	0.086
5.37	-13.87	0.086
5.40	-13.76	0.086
5.42	-13.65	0.086
5.44	-13.55	0.086
5.46	-13.44	0.086
5.48	-13.33	0.086
5.50	-13.22	0.086
5.53	-13.11	0.086
5.55	-13.00	0.086
5.57	-12.89	0.086
5.59	-12.79	0.086
5.61	-12.68	0.086
5.63	-12.57	0.086
5.65	-12.46	0.086
5.68	-12.35	0.086
5.70	-12.24	0.086
5.72	-12.14	0.086
5.74	-12.03	0.086
5.76	-11.92	0.086
5.79	-11.81	0.086
5.81	-11.70	0.086
5.83	-11.59	0.086
5.85	-11.49	0.086
5.87	-11.38	0.086
5.89	-11.27	0.086
5.91	-11.16	0.086
5.94	-11.05	0.087
5.96	-10.94	0.087
5.98	-10.83	0.087
6.00	-10.73	0.087
6.02	-10.62	0.087
6.05	-10.51	0.087
6.07	-10.40	0.087
6.09	-10.29	0.087
6.11	-10.18	0.087
6.13	-10.08	0.087
6.15	-9.97	0.087
6.18	-9.86	0.087
6.20	-9.75	0.087
6.22	-9.64	0.087
6.24	-9.53	0.087
6.26	-9.43	0.087
6.28	-9.32	0.087
6.30	-9.21	0.087
6.33	-9.10	0.087
6.35	-8.99	0.087
6.37	-8.88	0.087
6.39	-8.77	0.087
6.41	-8.67	0.087
6.44	-8.56	0.087
6.46	-8.45	0.087
6.48	-8.34	0.087
6.50	-8.23	0.087
6.52	-8.13	0.087
6.54	-8.02	0.087
6.56	-7.91	0.087
6.59	-7.80	0.087
6.61	-7.69	0.087
6.63	-7.58	0.087
6.65	-7.47	0.087
6.67	-7.37	0.087
6.70	-7.26	0.087
6.72	-7.15	0.087
6.74	-7.04	0.087
6.76	-6.93	0.087
6.78	-6.82	0.087
6.80	-6.72	0.087
6.83	-6.61	0.087
6.85	-6.50	0.088
6.87	-6.39	0.087
6.89	-6.28	0.087
6.91	-6.17	0.088
6.93	-6.07	0.088
6.95	-5.96	0.088
6.98	-5.85	0.088
7.00	-5.74	0.088
7.02	-5.63	0.088
7.04	-5.52	0.088
7.06	-5.41	0.088
7.09	-5.31	0.088
7.11	-5.20	0.088
7.13	-5.09	0.088
7.15	-4.98	0.088
7.17	-4.87	0.088
7.19	-4.76	0.088
7.21	-4.66	0.088
7.24	-4.55	0.088
7.26	-4.44	0.088
7.28	-4.33	0.088
7.30	-4.22	0.088
7.32	-4.11	0.088
7.35	-4.01	0.088
7.37	-3.90	0.088
7.39	-3.79	0.088
7.41	-3.68	0.088
7.43	-3.57	0.088
7.45	-3.46	0.088
7.48	-3.36	0.088
7.50	-3.25	0.088
7.52	-3.14	0.088
7.54	-3.03	0.088
7.56	-2.92	0.088
7.58	-2.81	0.088
7.60	-2.70	0.088
7.63	-2.60	0.088
7.65	-2.49	0.088
7.67	-2.38	0.088
7.69	-2.27	0.088
7.71	-2.16	0.088
7.74	-2.05	0.088
7.76	-1.95	0.089
7.78	-1.84	0.088
7.80	-1.73	0.088
7.82	-1.62	0.089
7.84	-1.51	0.089
7.86	-1.40	0.089
7.89	-1.30	0.089
7.91	-1.19	0.089
7.93	-1.08	0.089
7.95	-0.97	0.089
7.97	-0.86	0.089
8.00	-0.75	0.089
8.02	-0.64	0.089
8.04	-0.54	0.089
8.06	-0.43	0.089
8.08	-0.32	0.089
8.10	-0.21	0.089
8.13	-0.10	0.089
8.15	0.01	0.089
8.17	0.11	0.089
8.19	0.22	0.089
8.21	0.33	0.089
8.23	0.44	0.089
8.25	0.55	0.089
8.28	0.65	0.089
8.30	0.76	0.089
8.32	0.87	0.089
8.34	0.98	0.089
8.36	1.09	0.089
8.39	1.20	0.089
8.41	1.31	0.089
8.43	1.41	0.089
8.45	1.52	0.089
8.47	1.63	0.089
8.49	1.74	0.089
8.51	1.85	0.089
8.54	1.96	0.089
8.56	2.07	0.089
8.58	2.17	0.089
8.60	2.28	0.089
8.62	2.39	0.089
8.65	2.50	0.089
8.67	2.61	0.089
8.69	2.72	0.089
8.71	2.82	0.090
8.73	2.93	0.090
8.75	3.04	0.090
8.78	3.15	0.090
8.80	3.26	0.090
8.82	3.37	0.090
8.84	3.48	0.090
8.86	3.58	0.090
8.88	3.69	0.090
8.90	3.80	0.090
8.93	3.91	0.090
8.95	4.02	0.090
8.97	4.13	0.090
8.99	4.23	0.090
9.01	4.34	0.090
9.03	4.45	0.090
9.06	4.56	0.090
9.08	4.67	0.090
9.10	4.78	0.090
9.12	4.89	0.090
9.14	4.99	0.090
9.17	5.10	0.090
9.19	5.21	0.090
9.21	5.32	0.090
9.23	5.43	0.090
9.25	5.54	0.090
9.27	5.64	0.090
9.30	5.75	0.090
9.32	5.86	0.090
9.34	5.97	0.090
9.36	6.08	0.090
9.38	6.19	0.090
9.40	6.29	0.090
9.43	6.40	0.091
9.45	6.51	0.091
9.47	6.62	0.091
9.49	6.73	0.091
9.51	6.84	0.091
9.53	6.94	0.091
9.55	7.05	0.091
9.58	7.16	0.091
9.60	7.27	0.091
9.62	7.38	0.091
9.64	7.49	0.091
9.66	7.60	0.091
9.68	7.71	0.091
9.71	7.81	0.091
9.73	7.92	0.091
9.75	8.03	0.091
9.77	8.14	0.091
9.79	8.24	0.091
9.82	8.35	0.091
9.84	8.46	0.091
9.86	8.57	0.091
9.88	8.68	0.091
9.90	8.79	0.091
9.92	8.90	0.091
9.95	9.00	0.091
9.97	9.11	0.091
9.99	9.22	0.091
10.01	9.33	0.091
10.03	9.44	0.091
10.05	9.55	0.091
10.08	9.66	0.091
10.10	9.76	0.091
10.12	9.87	0.091
10.14	9.98	0.092
10.16	10.09	0.092
10.18	10.20	0.092
10.20	10.31	0.092
10.23	10.41	0.092
10.25	10.52	0.092
10.27	10.63	0.092
10.29	10.74	0.092
10.31	10.85	0.092
10.33	10.96	0.092
10.36	11.06	0.092
10.38	11.17	0.092
10.40	11.28	0.092
10.42	11.39	0.092
10.44	11.50	0.092
10.47	11.61	0.092
10.49	11.72	0.092
10.51	11.82	0.092
10.53	11.93	0.092
10.55	12.04	0.092
10.57	12.15	0.092
10.60	12.26	0.092
10.62	12.37	0.092
10.64	12.47	0.092
10.66	12.58	0.092
10.68	12.69	0.092
10.70	12.80	0.092
10.73	12.91	0.092
10.75	13.02	0.093
10.77	13.12	0.093
10.79	13.23	0.093
10.81	13.34	0.093
10.83	13.45	0.093
10.85	13.56	0.093
10.88	13.67	0.093
10.90	13.77	0.093
10.92	13.88	0.093
10.94	13.99	0.093
10.96	14.10	0.093
10.98	14.21	0.093
11.01	14.32	0.093
11.03	14.42	0.093
11.05	14.53	0.093
11.07	14.64	0.093
11.09	14.75	0.093
11.12	14.86	0.093
11.14	14.97	0.093
11.16	15.07	0.093
11.18	15.18	0.093
11.20	15.29	0.093
11.22	15.40	0.093
11.25	15.51	0.093
11.27	15.62	0.093
11.29	15.73	0.093
11.31	15.83	0.093
11.33	15.94	0.093
11.35	16.05	0.093
11.38	16.16	0.093
11.40	16.27	0.093
11.42	16.38	0.094
11.44	16.48	0.094
11.46	16.59	0.094
11.48	16.70	0.094
11.50	16.81	0.094
11.53	16.92	0.094
11.55	17.03	0.094
11.57	17.13	0.094
11.59	17.24	0.094
11.61	17.35	0.094
11.63	17.46	0.094
11.66	17.57	0.094
11.68	17.68	0.094
11.70	17.79	0.094
11.72	17.89	0.094
11.74	18.00	0.094
11.77	18.11	0.094
11.79	18.22	0.094
11.81	18.33	0.094
11.83	18.43	0.094
11.85	18.54	0.094
11.87	18.65	0.094
11.90	18.76	0.094
11.92	18.87	0.094
11.94	18.98	0.094
11.96	19.09	0.094
11.98	19.19	0.094
12.00	19.30	0.094
12.03	19.41	0.095
12.05	19.52	0.095
12.07	19.63	0.095
12.09	19.74	0.095
12.11	19.84	0.095
12.13	19.95	0.095
12.15	20.06	0.095
12.18	20.17	0.095
12.20	20.28	0.095
12.22	20.39	0.095
12.24	20.49	0.095
12.26	20.60	0.095
12.28	20.71	0.095
12.31	20.82	0.095
12.33	20.93	0.095
12.35	21.04	0.095
12.37	21.15	0.095
12.39	21.25	0.095
12.42	21.36	0.095
12.44	21.47	0.095
12.46	21.58	0.095
12.48	21.69	0.095
12.50	21.80	0.095
12.52	21.90	0.095
12.55	22.01	0.095
12.57	22.12	0.095
12.59	22.23	0.095
12.61	22.34	0.095
12.63	22.45	0.095
12.65	22.55	0.095
12.68	22.66	0.095
12.70	22.77	0.096
12.72	22.88	0.096
12.74	22.99	0.096
12.76	23.10	0.096
12.78	23.21	0.096
12.80	23.31	0.096
12.83	23.42	0.096
12.85	23.53	0.096
12.87	23.64	0.096
12.89	23.75	0.096
12.91	23.85	0.096
12.93	23.96	0.096
12.96	24.07	0.096
12.98	24.18	0.096
13.00	24.29	0.096
13.02	24.40	0.096
13.04	24.51	0.096
13.07	24.61	0.096
13.09	24.72	0.096
13.11	24.83	0.096
13.13	24.94	0.096
13.15	25.05	0.096
13.17	25.16	0.096
13.20	25.27	0.096
13.22	25.37	0.096
13.24	25.48	0.096
13.26	25.59	0.096
13.28	25.70	0.097
13.30	25.81	0.096
13.33	25.92	0.097
13.35	26.02	0.097
13.37	26.13	0.097
13.39	26.24	0.097
13.41	26.35	0.097
13.43	26.46	0.097
13.45	26.57	0.097
13.48	26.67	0.097
13.50	26.78	0.097
13.52	26.89	0.097
13.54	27.00	0.097
13.56	27.11	0.097
13.58	27.22	0.097
13.61	27.32	0.097
13.63	27.43	0.097
13.65	27.54	0.097
13.67	27.65	0.097
13.69	27.76	0.097
13.72	27.87	0.097
13.74	27.97	0.097
13.76	28.08	0.098
13.78	28.19	0.098
13.80	28.30	0.098
13.82	28.41	0.098
13.85	28.52	0.098
13.87	28.63	0.098
13.89	28.73	0.098
13.91	28.84	0.098
13.93	28.95	0.098
13.95	29.06	0.098
13.98	29.17	0.098
14.00	29.28	0.098
14.02	29.39	0.098
14.04	29.49	0.098
14.06	29.60	0.098
14.08	29.71	0.098
14.10	29.82	0.098
14.13	29.93	0.099
14.15	30.03	0.099
14.17	30.14	0.099
14.19	30.25	0.099
14.21	30.36	0.099
14.23	30.47	0.099
14.26	30.58	0.099
14.28	30.69	0.099
14.30	30.79	0.099
14.32	30.90	0.099
14.34	31.01	0.099
14.37	31.12	0.099
14.39	31.23	0.099
14.41	31.33	0.099
14.43	31.44	0.099
14.45	31.55	0.099
14.47	31.66	0.099
14.50	31.77	0.100
14.52	31.88	0.100
14.54	31.98	0.100
14.56	32.09	0.100
14.58	32.20	0.100
14.60	32.31	0.100
14.63	32.42	0.100
14.65	32.53	0.100
14.67	32.63	0.100
14.69	32.74	0.100
14.71	32.85	0.100
14.73	32.96	0.100
14.75	33.07	0.100
14.78	33.18	0.100
14.80	33.29	0.100
14.82	33.39	0.100
14.84	33.50	0.100
14.86	33.61	0.100
14.88	33.72	0.101
14.91	33.83	0.101
14.93	33.94	0.101
14.95	34.04	0.101
14.97	34.15	0.101
14.99	34.26	0.101
15.02	34.37	0.101
15.04	34.48	0.101
15.06	34.59	0.101
15.08	34.69	0.101
15.10	34.80	0.101
15.12	34.91	0.101
15.15	35.02	0.101
15.17	35.13	0.101
15.19	35.24	0.101
15.21	35.35	0.101
15.23	35.45	0.101
15.25	35.56	0.101
15.28	35.67	0.101
15.30	35.78	0.101
15.32	35.89	0.101
15.34	36.00	0.101
15.36	36.10	0.102
15.38	36.21	0.102
15.40	36.32	0.102
15.43	36.43	0.102
15.45	36.54	0.102
15.47	36.65	0.102
15.49	36.76	0.102
15.51	36.86	0.102
15.53	36.97	0.102
15.56	37.08	0.102
15.58	37.19	0.102
15.60	37.30	0.102
15.62	37.40	0.102
15.64	37.51	0.102
15.67	37.62	0.102
15.69	37.73	0.102
15.71	37.84	0.102
15.73	37.95	0.102
15.75	38.06	0.102
15.77	38.16	0.103
15.80	38.27	0.103
15.82	38.38	0.103
15.84	38.49	0.103
15.86	38.60	0.103
15.88	38.71	0.103
15.90	38.81	0.103
15.93	38.92	0.103
15.95	39.03	0.103
15.97	39.14	0.103
15.99	39.25	0.103
16.01	39.36	0.103
16.03	39.46	0.103
16.05	39.57	0.103
16.08	39.68	0.103
16.10	39.79	0.103
16.12	39.90	0.103
16.14	40.01	0.103
16.16	40.11	0.103
16.18	40.22	0.103
16.21	40.33	0.103
16.23	40.44	0.103
16.25	40.55	0.104
16.27	40.66	0.103
16.29	40.77	0.104
16.32	40.87	0.104
16.34	40.98	0.104
16.36	41.09	0.104
16.38	41.20	0.104
16.40	41.31	0.104
16.42	41.42	0.104
16.45	41.52	0.104
16.47	41.63	0.104
16.49	41.74	0.104
16.51	41.85	0.104
16.53	41.96	0.104
16.55	42.07	0.104
16.58	42.17	0.104
16.60	42.28	0.104
16.62	42.39	0.104
16.64	42.50	0.104
16.66	42.61	0.104
16.68	42.72	0.104
16.70	42.82	0.104
16.73	42.93	0.104
16.75	43.04	0.105
16.77	43.15	0.105
16.79	43.26	0.105
16.81	43.37	0.105
16.83	43.47	0.105
16.86	43.58	0.105
16.88	43.69	0.105
16.90	43.80	0.105
16.92	43.91	0.105
16.94	44.02	0.105
16.97	44.13	0.105
16.99	44.23	0.105
17.01	44.34	0.105
17.03	44.45	0.105
17.05	44.56	0.105
17.07	44.67	0.105
17.09	44.78	0.105
17.12	44.88	0.105
17.14	44.99	0.105
17.16	45.10	0.105
17.18	45.21	0.105
17.20	45.32	0.105
17.23	45.43	0.105
17.25	45.54	0.106
17.27	45.64	0.106
17.29	45.75	0.106
17.31	45.86	0.106
17.33	45.97	0.106
17.36	46.08	0.106
17.38	46.18	0.106
17.40	46.29	0.106
17.42	46.40	0.106
17.44	46.51	0.106
17.46	46.62	0.106
17.48	46.73	0.106
17.51	46.84	0.106
17.53	46.94	0.106
17.55	47.05	0.106
17.57	47.16	0.106
17.59	47.27	0.106
17.62	47.38	0.106
17.64	47.49	0.106
17.66	47.60	0.106
17.68	47.70	0.106
17.70	47.81	0.106
17.72	47.92	0.106
17.74	48.03	0.106
17.77	48.14	0.107
17.79	48.24	0.107
17.81	48.35	0.107
17.83	48.46	0.107
17.85	48.57	0.107
17.88	48.68	0.107
17.90	48.79	0.107
17.92	48.89	0.107
17.94	49.00	0.107
17.96	49.11	0.107
17.98	49.22	0.107
18.01	49.33	0.107
18.03	49.44	0.107
18.05	49.54	0.107
18.07	49.65	0.107
18.09	49.76	0.107
18.11	49.87	0.107
18.13	49.98	0.107
18.16	50.09	0.107
18.18	50.20	0.107
18.20	50.30	0.107
18.22	50.41	0.107
18.24	50.52	0.107
18.27	50.63	0.108
18.29	50.74	0.108
18.31	50.85	0.108
18.33	50.96	0.108
18.35	51.06	0.108
18.37	51.17	0.108
18.39	51.28	0.108
18.42	51.39	0.108
18.44	51.50	0.108
18.46	51.60	0.108
18.48	51.71	0.108
18.50	51.82	0.108
18.53	51.93	0.108
18.55	52.04	0.108
18.57	52.15	0.108
18.59	52.26	0.108
18.61	52.36	0.108
18.63	52.47	0.108
18.66	52.58	0.108
18.68	52.69	0.108
18.70	52.80	0.109
18.72	52.90	0.109
18.74	53.01	0.108
18.76	53.12	0.109
18.78	53.23	0.109
18.81	53.34	0.109
18.83	53.45	0.109
18.85	53.56	0.109
18.87	53.66	0.109
18.89	53.77	0.109
18.92	53.88	0.109
18.94	53.99	0.109
18.96	54.10	0.109
18.98	54.21	0.109
19.00	54.31	0.109
19.02	54.42	0.109
19.04	54.53	0.109
19.07	54.64	0.109
19.09	54.75	0.109
19.11	54.86	0.109
19.13	54.96	0.109
19.15	55.07	0.109
19.18	55.18	0.110
19.20	55.29	0.109
19.22	55.40	0.110
19.24	55.51	0.110
19.26	55.62	0.110
19.28	55.72	0.110
19.31	55.83	0.110
19.33	55.94	0.110
19.35	56.05	0.110
19.37	56.16	0.110
19.39	56.27	0.110
19.41	56.37	0.110
19.43	56.48	0.110
19.46	56.59	0.110
19.48	56.70	0.110
19.50	56.81	0.110
19.52	56.92	0.110
19.54	57.02	0.110
19.57	57.13	0.110
19.59	57.24	0.111
19.61	57.35	0.111
19.63	57.46	0.111
19.65	57.57	0.111
19.67	57.67	0.111
19.69	57.78	0.111
19.72	57.89	0.111
19.74	58.00	0.111
19.76	58.11	0.111
19.78	58.22	0.111
19.80	58.32	0.111
19.83	58.43	0.111
19.85	58.54	0.111
19.87	58.65	0.111
19.89	58.76	0.111
19.91	58.87	0.111
19.93	58.98	0.111
19.96	59.08	0.111
19.98	59.19	0.112
20.00	59.30	0.112
20.02	59.41	0.112
20.04	59.52	0.112
20.06	59.62	0.112
20.08	59.73	0.112
20.11	59.84	0.112
20.13	59.95	0.112
20.15	60.06	0.112
20.17	60.17	0.112
20.19	60.28	0.112
20.22	60.38	0.112
20.24	60.49	0.112
20.26	60.60	0.112
20.28	60.71	0.112
20.30	60.82	0.112
20.32	60.93	0.112
20.34	61.03	0.113
20.37	61.14	0.113
20.39	61.25	0.113
20.41	61.36	0.113
20.43	61.47	0.113
20.45	61.58	0.113
20.48	61.69	0.113
20.50	61.79	0.113
20.52	61.90	0.113
20.54	62.01	0.113
20.56	62.12	0.113
20.58	62.23	0.113
20.61	62.33	0.114
20.63	62.44	0.114
20.65	62.55	0.114
20.67	62.66	0.114
20.69	62.77	0.114
20.71	62.88	0.114
20.73	62.99	0.114
20.76	63.09	0.114
20.78	63.20	0.114
20.80	63.31	0.114
20.82	63.42	0.114
20.84	63.53	0.114
20.87	63.64	0.114
20.89	63.74	0.115
20.91	63.85	0.115
20.93	63.96	0.115
20.95	64.07	0.115
20.97	64.18	0.115
20.99	64.29	0.115
21.02	64.39	0.115
21.04	64.50	0.115
21.06	64.61	0.115
21.08	64.72	0.115
21.10	64.83	0.116
21.13	64.93	0.116
21.15	65.04	0.116
21.17	65.15	0.116
21.19	65.26	0.116
21.21	65.37	0.116
21.23	65.48	0.116
21.26	65.59	0.116
21.28	65.70	0.117
21.30	65.80	0.117
21.32	65.91	0.117
21.34	66.02	0.117
21.36	66.13	0.117
21.38	66.24	0.117
21.41	66.34	0.117
21.43	66.45	0.118
21.45	66.56	0.118
21.47	66.67	0.118
21.49	66.78	0.118
21.52	66.89	0.118
21.54	67.00	0.119
21.56	67.10	0.119
21.58	67.21	0.119
21.60	67.32	0.119
21.62	67.43	0.119
21.64	67.54	0.120
21.67	67.64	0.120
21.69	67.75	0.120
21.71	67.86	0.120
21.73	67.97	0.121
21.75	68.08	0.121
21.78	68.19	0.121
21.80	68.30	0.121
21.82	68.40	0.122
21.84	68.51	0.122
21.86	68.62	0.122
21.88	68.73	0.123
21.91	68.84	0.123
21.93	68.95	0.123
21.95	69.05	0.124
21.97	69.16	0.124
21.99	69.27	0.124
22.01	69.38	0.125
22.03	69.49	0.125
22.06	69.59	0.126
22.08	69.70	0.126
22.10	69.81	0.127
22.12	69.92	0.127
22.14	70.03	0.128
22.17	70.14	0.129
22.19	70.24	0.129
22.21	70.35	0.130
22.23	70.46	0.131
22.25	70.57	0.132
22.27	70.68	0.132
22.29	70.78	0.133
22.32	70.89	0.134
22.34	71.00	0.135
22.36	71.11	0.136
22.38	71.22	0.138
22.40	71.33	0.139
22.43	71.43	0.141
22.45	71.54	0.143
22.47	71.65	0.145
22.49	71.76	0.148
22.51	71.86	0.151
22.53	71.97	0.155
22.56	72.08	0.158
22.58	72.19	0.162
22.60	72.29	0.166
22.62	72.40	0.171
22.64	72.51	0.176
22.66	72.62	0.181
22.68	72.72	0.187
22.71	72.83	0.192
22.73	72.94	0.200
22.75	73.05	0.208
22.77	73.15	0.217
22.79	73.26	0.226
22.82	73.36	0.236
22.84	73.47	0.249
22.86	73.58	0.263
22.88	73.68	0.278
22.90	73.79	0.295
22.92	73.89	0.315
22.94	73.99	0.336
22.97	74.10	0.362
22.99	74.20	0.392
23.01	74.30	0.426
23.03	74.40	0.468
23.05	74.50	0.514
23.08	74.60	0.569
23.10	74.70	0.630
23.12	74.79	0.701
23.14	74.88	0.780
23.16	74.97	0.870
23.18	75.06	0.969
23.21	75.15	1.074
23.23	75.23	1.179
23.25	75.31	1.292
23.27	75.39	1.409
23.29	75.47	1.532
23.31	75.55	1.660
23.33	75.63	1.773
23.36	75.71	1.903
23.38	75.78	2.021
23.40	75.86	2.146
23.42	75.94	2.264
23.44	76.02	2.344
23.47	76.10	2.406
23.49	76.19	2.423
23.51	76.29	2.435
23.53	76.38	2.475
23.55	76.48	2.476
23.57	76.59	2.396
23.59	76.71	2.238
23.62	76.84	2.055
23.64	76.98	1.868
23.66	77.13	1.682
23.68	77.28	1.504
23.70	77.43	1.340
23.73	77.58	1.166
23.75	77.73	1.008
23.77	77.88	0.870
23.79	78.03	0.744
23.81	78.17	0.630
23.83	78.31	0.530
23.86	78.45	0.450
23.88	78.58	0.389
23.90	78.71	0.342
23.92	78.84	0.303
23.94	78.96	0.274
23.96	79.08	0.247
23.98	79.20	0.223
24.01	79.31	0.205
24.03	79.43	0.192
24.05	79.54	0.181
24.07	79.65	0.173
24.09	79.77	0.168
24.12	79.88	0.162
24.14	79.99	0.160
24.16	80.10	0.157
24.18	80.21	0.155
24.20	80.32	0.154
24.22	80.43	0.153
24.24	80.53	0.152
24.27	80.64	0.151
24.29	80.75	0.150
24.31	80.86	0.150
24.33	80.97	0.149
24.35	81.08	0.149
24.38	81.19	0.149
24.40	81.30	0.148
24.42	81.41	0.148
24.44	81.51	0.147
24.46	81.62	0.147
24.48	81.73	0.147
24.51	81.84	0.146
24.53	81.95	0.146
24.55	82.06	0.146
24.57	82.16	0.146
24.59	82.27	0.145
24.61	82.38	0.145
24.63	82.49	0.145
24.66	82.60	0.145
24.68	82.71	0.145
24.70	82.81	0.145
24.72	82.92	0.145
24.74	83.03	0.144
24.77	83.14	0.144
24.79	83.25	0.144
24.81	83.36	0.144
24.83	83.47	0.144
24.85	83.57	0.144
24.87	83.68	0.144
24.89	83.79	0.144
24.92	83.90	0.144
24.94	84.01	0.144
24.96	84.12	0.144
24.98	84.22	0.144
25.00	84.33	0.144
25.03	84.44	0.144
25.05	84.55	0.144
25.07	84.66	0.144
25.09	84.77	0.144
25.11	84.87	0.144
25.13	84.98	0.143
25.16	85.09	0.143
25.18	85.20	0.143
25.20	85.31	0.143
25.22	85.42	0.143
25.24	85.52	0.143
25.26	85.63	0.143
25.28	85.74	0.143
25.31	85.85	0.144
25.33	85.96	0.143
25.35	86.07	0.144
25.37	86.17	0.144
25.39	86.28	0.144
25.42	86.39	0.144
25.44	86.50	0.144
25.46	86.61	0.144
25.48	86.72	0.144
25.50	86.83	0.144
25.52	86.93	0.144
25.54	87.04	0.144
25.57	87.15	0.144
25.59	87.26	0.144
25.61	87.37	0.144
25.63	87.47	0.144
25.65	87.58	0.144
25.68	87.69	0.144
25.70	87.80	0.144
25.72	87.91	0.144
25.74	88.02	0.144
25.76	88.12	0.144
25.78	88.23	0.144
25.81	88.34	0.144
25.83	88.45	0.144
25.85	88.56	0.144
25.87	88.67	0.144
25.89	88.77	0.144
25.91	88.88	0.144
25.93	88.99	0.144
25.96	89.10	0.144
25.98	89.21	0.144
26.00	89.32	0.144
26.02	89.43	0.144
26.04	89.53	0.144
26.07	89.64	0.144
26.09	89.75	0.144
26.11	89.86	0.144
26.13	89.97	0.144
26.15	90.08	0.144
26.17	90.18	0.144
26.19	90.29	0.144
26.22	90.40	0.144
26.24	90.51	0.144
26.26	90.62	0.144
26.28	90.73	0.144
26.30	90.83	0.144
26.33	90.94	0.144
26.35	91.05	0.144
26.37	91.16	0.144
26.39	91.27	0.144
26.41	91.38	0.145
26.43	91.48	0.145
26.46	91.59	0.145
26.48	91.70	0.145
26.50	91.81	0.145
26.52	91.92	0.145
26.54	92.03	0.145
26.56	92.14	0.145
26.58	92.24	0.145
26.61	92.35	0.145
26.63	92.46	0.145
26.65	92.57	0.145
26.67	92.68	0.145
26.69	92.79	0.145
26.72	92.89	0.145
26.74	93.00	0.145
26.76	93.11	0.145
26.78	93.22	0.145
26.80	93.33	0.145
26.82	93.44	0.145
26.84	93.54	0.145
26.87	93.65	0.145
26.89	93.76	0.145
26.91	93.87	0.145
26.93	93.98	0.145
26.95	94.09	0.145
26.98	94.19	0.145
27.00	94.30	0.145
27.02	94.41	0.145
27.04	94.52	0.145
27.06	94.63	0.145
27.08	94.74	0.145
27.11	94.85	0.146
27.13	94.95	0.146
27.15	95.06	0.146
27.17	95.17	0.146
27.19	95.28	0.146
27.21	95.39	0.146
27.23	95.50	0.146
27.26	95.60	0.146
27.28	95.71	0.146
27.30	95.82	0.146
27.32	95.93	0.146
27.34	96.04	0.146
27.37	96.15	0.146
27.39	96.25	0.146
27.41	96.36	0.146
27.43	96.47	0.146
27.45	96.58	0.146
27.47	96.69	0.146
27.49	96.80	0.146
27.52	96.90	0.146
27.54	97.01	0.146
27.56	97.12	0.146
27.58	97.23	0.146
27.60	97.34	0.146
27.63	97.45	0.146
27.65	97.55	0.146
27.67	97.66	0.146
27.69	97.77	0.146
27.71	97.88	0.146
27.73	97.99	0.146
27.76	98.10	0.146
27.78	98.20	0.146
27.80	98.31	0.146
27.82	98.42	0.146
27.84	98.53	0.146
27.86	98.64	0.146
27.88	98.75	0.146
27.91	98.85	0.146
27.93	98.96	0.146
27.95	99.07	0.147
27.97	99.18	0.147
27.99	99.29	0.147
28.02	99.40	0.147
28.04	99.50	0.147
28.06	99.61	0.147
28.08	99.72	0.147
28.10	99.83	0.147
28.12	99.94	0.147
28.14	100.05	0.147
28.17	100.15	0.147
28.19	100.26	0.147
28.21	100.37	0.147
28.23	100.48	0.147
28.25	100.59	0.147
28.28	100.70	0.147
28.30	100.81	0.147
28.32	100.92	0.147
28.34	101.02	0.147
28.36	101.13	0.147
28.38	101.24	0.147
28.41	101.35	0.147
28.43	101.46	0.147
28.45	101.57	0.147
28.47	101.67	0.147
28.49	101.78	0.147
28.51	101.89	0.147
28.53	102.00	0.147
28.56	102.11	0.147
28.58	102.21	0.147
28.60	102.32	0.147
28.62	102.43	0.147
28.64	102.54	0.147
28.67	102.65	0.147
28.69	102.76	0.148
28.71	102.87	0.148
28.73	102.98	0.148
28.75	103.08	0.148
28.77	103.19	0.148
28.79	103.30	0.148
28.82	103.41	0.148
28.84	103.52	0.148
28.86	103.63	0.148
28.88	103.73	0.148
28.90	103.84	0.148
28.93	103.95	0.148
28.95	104.06	0.148
28.97	104.17	0.148
28.99	104.27	0.148
29.01	104.38	0.148
29.03	104.49	0.148
29.06	104.60	0.148
29.08	104.71	0.148
29.10	104.82	0.148
29.12	104.92	0.148
29.14	105.03	0.148
29.16	105.14	0.148
29.18	105.25	0.148
29.21	105.36	0.148
29.23	105.47	0.148
29.25	105.58	0.148
29.27	105.68	0.148
29.29	105.79	0.148
29.32	105.90	0.148
29.34	106.01	0.148
29.36	106.12	0.148
29.38	106.22	0.148
29.40	106.33	0.148
29.42	106.44	0.148
29.44	106.55	0.148
29.47	106.66	0.148
29.49	106.77	0.148
29.51	106.87	0.148
29.53	106.98	0.148
29.55	107.09	0.148
29.58	107.20	0.148
29.60	107.31	0.148
29.62	107.42	0.148
29.64	107.53	0.148
29.66	107.63	0.149
29.68	107.74	0.149
29.71	107.85	0.149
29.73	107.96	0.149
29.75	108.07	0.149
29.77	108.18	0.149
29.79	108.28	0.149
29.81	108.39	0.149
29.83	108.50	0.149
29.86	108.61	0.149
29.88	108.72	0.149
29.90	108.82	0.149
29.92	108.93	0.149
29.94	109.04	0.149
29.97	109.15	0.149
29.99	109.26	0.149
30.01	109.37	0.149
30.03	109.48	0.149
30.05	109.58	0.149
30.07	109.69	0.149
30.09	109.80	0.149
30.12	109.91	0.149
30.14	110.02	0.149
30.16	110.13	0.149
30.18	110.23	0.149
30.20	110.34	0.149
30.23	110.45	0.149
30.25	110.56	0.149
30.27	110.67	0.149
30.29	110.78	0.149
30.31	110.89	0.149
30.33	110.99	0.149
30.36	111.10	0.149
30.38	111.21	0.149
30.40	111.32	0.149
30.42	111.43	0.149
30.44	111.54	0.149
30.46	111.64	0.149
30.48	111.75	0.149
30.51	111.86	0.149
30.53	111.97	0.149
30.55	112.08	0.149
30.57	112.18	0.149
30.59	112.29	0.149
30.62	112.40	0.149
30.64	112.51	0.149
30.66	112.62	0.149
30.68	112.73	0.149
30.70	112.83	0.149
30.72	112.94	0.149
30.74	113.05	0.149
30.77	113.16	0.149
30.79	113.27	0.149
30.81	113.38	0.149
30.83	113.49	0.149
30.85	113.60	0.149
30.88	113.70	0.149
30.90	113.81	0.150
30.92	113.92	0.150
30.94	114.03	0.150
30.96	114.14	0.150
30.98	114.25	0.150
31.01	114.35	0.150
31.03	114.46	0.150
31.05	114.57	0.150
31.07	114.68	0.150
31.09	114.79	0.150
31.11	114.90	0.150
31.13	115.00	0.150
31.16	115.11	0.150
31.18	115.22	0.150
31.20	115.33	0.150
31.22	115.44	0.150
31.24	115.55	0.150
31.27	115.65	0.150
31.29	115.76	0.150
31.31	115.87	0.150
31.33	115.98	0.150
31.35	116.09	0.150
31.37	116.20	0.150
31.39	116.30	0.150
31.42	116.41	0.150
31.44	116.52	0.150
31.46	116.63	0.150
31.48	116.74	0.150
31.50	116.85	0.150
31.53	116.95	0.150
31.55	117.06	0.150
31.57	117.17	0.150
31.59	117.28	0.150
31.61	117.39	0.150
31.63	117.50	0.150
31.66	117.60	0.150
31.68	117.71	0.150
31.70	117.82	0.150
31.72	117.93	0.150
31.74	118.04	0.150
31.76	118.15	0.150
31.78	118.25	0.150
31.81	118.36	0.150
31.83	118.47	0.150
31.85	118.58	0.150
31.87	118.69	0.150
31.89	118.80	0.150
31.92	118.90	0.150
31.94	119.01
31.96	119.12
31.98	119.23
31.99

[step]
Ramp 5.00 °C/min to -40.00 °C
Time	Temperature	Heat Flow (Normalized)
min	°C	W/g
32.99	120.11	-0.050
33.02	120.11	-0.050
33.04	120.10	-0.051
33.06	120.09	-0.051
33.08	120.07	-0.058
33.10	120.03	-0.081
33.12	119.98	-0.107
33.14	119.91	-0.135
33.17	119.84	-0.159
33.19	119.76	-0.181
33.21	119.67	-0.195
33.23	119.58	-0.207
33.25	119.48	-0.216
33.28	119.39	-0.224
33.30	119.29	-0.228
33.32	119.19	-0.234
33.34	119.09	-0.237
33.36	118.98	-0.241
33.38	118.88	-0.242
33.41	118.78	-0.245
33.43	118.67	-0.245
33.45	118.57	-0.247
33.47	118.46	-0.248
33.49	118.35	-0.248
33.51	118.25	-0.249
33.53	118.14	-0.249
33.56	118.04	-0.250
33.58	117.93	-0.250
33.60	117.82	-0.251
33.62	117.72	-0.251
33.64	117.61	-0.252
33.67	117.50	-0.252
33.69	117.39	-0.252
33.71	117.29	-0.253
33.73	117.18	-0.253
33.75	117.07	-0.254
33.77	116.97	-0.254
33.79	116.86	-0.254
33.82	116.75	-0.254
33.84	116.64	-0.255
33.86	116.54	-0.255
33.88	116.43	-0.255
33.90	116.32	-0.255
33.93	116.21	-0.255
33.95	116.11	-0.255
33.97	116.00	-0.256
33.99	115.89	-0.256
34.01	115.78	-0.256
34.03	115.67	-0.256
34.06	115.57	-0.256
34.08	115.46	-0.256
34.10	115.35	-0.256
34.12	115.24	-0.256
34.14	115.14	-0.256
34.16	115.03	-0.256
34.19	114.92	-0.256
34.21	114.81	-0.256
34.23	114.70	-0.256
34.25	114.60	-0.256
34.27	114.49	-0.256
34.29	114.38	-0.256
34.31	114.27	-0.256
34.34	114.16	-0.256
34.36	114.06	-0.256
34.38	113.95	-0.256
34.40	113.84	-0.256
34.42	113.73	-0.256
34.44	113.62	-0.256
34.47	113.51	-0.256
34.49	113.41	-0.256
34.51	113.30	-0.256
34.53	113.19	-0.256
34.55	113.08	-0.256
34.58	112.97	-0.256
34.60	112.87	-0.256
34.62	112.76	-0.256
34.64	112.65	-0.256
34.66	112.54	-0.256
34.68	112.43	-0.256
34.71	112.33	-0.256
34.73	112.22	-0.256
34.75	112.11	-0.256
34.77	112.00	-0.256
34.79	111.89	-0.255
34.81	111.78	-0.255
34.84	111.68	-0.255
34.86	111.57	-0.255
34.88	111.46	-0.255
34.90	111.35	-0.255
34.92	111.24	-0.255
34.94	111.14	-0.255
34.96	111.03	-0.255
34.99	110.92	-0.255
35.01	110.81	-0.255
35.03	110.70	-0.255
35.05	110.59	-0.255
35.07	110.49	-0.255
35.09	110.38	-0.255
35.12	110.27	-0.254
35.14	110.16	-0.254
35.16	110.05	-0.254
35.18	109.95	-0.254
35.20	109.84	-0.254
35.23	109.73	-0.254
35.25	109.62	-0.254
35.27	109.51	-0.254
35.29	109.40	-0.254
35.31	109.30	-0.254
35.33	109.19	-0.254
35.36	109.08	-0.254
35.38	108.97	-0.254
35.40	108.86	-0.254
35.42	108.75	-0.254
35.44	108.65	-0.254
35.46	108.54	-0.253
35.49	108.43	-0.253
35.51	108.32	-0.253
35.53	108.21	-0.253
35.55	108.10	-0.253
35.57	108.00	-0.253
35.59	107.89	-0.253
35.61	107.78	-0.253
35.64	107.67	-0.253
35.66	107.56	-0.253
35.68	107.45	-0.253
35.70	107.35	-0.253
35.72	107.24	-0.253
35.74	107.13	-0.253
35.77	107.02	-0.253
35.79	106.91	-0.253
35.81	106.80	-0.252
35.83	106.70	-0.252
35.85	106.59	-0.252
35.88	106.48	-0.252
35.90	106.37	-0.252
35.92	106.26	-0.252
35.94	106.16	-0.252
35.96	106.05	-0.252
35.98	105.94	-0.252
36.01	105.83	-0.252
36.03	105.72	-0.252
36.05	105.61	-0.252
36.07	105.51	-0.252
36.09	105.40	-0.252
36.11	105.29	-0.252
36.14	105.18	-0.251
36.16	105.07	-0.251
36.18	104.97	-0.251
36.20	104.86	-0.251
36.22	104.75	-0.251
36.24	104.64	-0.251
36.26	104.53	-0.251
36.29	104.42	-0.251
36.31	104.31	-0.251
36.33	104.21	-0.251
36.35	104.10	-0.251
36.37	103.99	-0.251
36.39	103.88	-0.251
36.42	103.77	-0.251
36.44	103.66	-0.251
36.46	103.56	-0.251
36.48	103.45	-0.250
36.50	103.34	-0.250
36.53	103.23	-0.250
36.55	103.12	-0.250
36.57	103.02	-0.250
36.59	102.91	-0.250
36.61	102.80	-0.250
36.63	102.69	-0.250
36.66	102.58	-0.250
36.68	102.47	-0.250
36.70	102.37	-0.250
36.72	102.26	-0.250
36.74	102.15	-0.250
36.76	102.04	-0.250
36.79	101.93	-0.250
36.81	101.83	-0.249
36.83	101.72	-0.249
36.85	101.61	-0.249
36.87	101.50	-0.249
36.89	101.39	-0.249
36.91	101.28	-0.249
36.94	101.18	-0.249
36.96	101.07	-0.249
36.98	100.96	-0.249
37.00	100.85	-0.249
37.02	100.74	-0.249
37.04	100.63	-0.249
37.07	100.53	-0.249
37.09	100.42	-0.249
37.11	100.31	-0.249
37.13	100.20	-0.249
37.15	100.09	-0.249
37.18	99.98	-0.248
37.20	99.88	-0.248
37.22	99.77	-0.248
37.24	99.66	-0.248
37.26	99.55	-0.248
37.28	99.44	-0.248
37.31	99.34	-0.248
37.33	99.23	-0.248
37.35	99.12	-0.248
37.37	99.01	-0.248
37.39	98.90	-0.248
37.41	98.79	-0.248
37.44	98.69	-0.248
37.46	98.58	-0.248
37.48	98.47	-0.248
37.50	98.36	-0.248
37.52	98.25	-0.248
37.54	98.14	-0.248
37.56	98.04	-0.248
37.59	97.93	-0.247
37.61	97.82	-0.248
37.63	97.71	-0.248
37.65	97.60	-0.247
37.67	97.50	-0.247
37.69	97.39	-0.247
37.72	97.28	-0.247
37.74	97.17	-0.247
37.76	97.06	-0.247
37.78	96.95	-0.247
37.80	96.85	-0.247
37.83	96.74	-0.247
37.85	96.63	-0.247
37.87	96.52	-0.247
37.89	96.41	-0.247
37.91	96.30	-0.247
37.93	96.19	-0.247
37.96	96.09	-0.247
37.98	95.98	-0.247
38.00	95.87	-0.247
38.02	95.76	-0.247
38.04	95.65	-0.246
38.06	95.55	-0.246
38.09	95.44	-0.246
38.11	95.33	-0.246
38.13	95.22	-0.246
38.15	95.11	-0.246
38.17	95.00	-0.246
38.19	94.90	-0.246
38.21	94.79	-0.246
38.24	94.68	-0.246
38.26	94.57	-0.246
38.28	94.46	-0.246
38.30	94.35	-0.246
38.32	94.25	-0.246
38.34	94.14	-0.246
38.37	94.03	-0.246
38.39	93.92	-0.245
38.41	93.81	-0.245
38.43	93.71	-0.245
38.45	93.60	-0.245
38.48	93.49	-0.245
38.50	93.38	-0.245
38.52	93.27	-0.245
38.54	93.16	-0.245
38.56	93.05	-0.245
38.58	92.95	-0.245
38.61	92.84	-0.245
38.63	92.73	-0.245
38.65	92.62	-0.245
38.67	92.51	-0.245
38.69	92.40	-0.245
38.71	92.30	-0.245
38.74	92.19	-0.245
38.76	92.08	-0.244
38.78	91.97	-0.244
38.80	91.86	-0.244
38.82	91.76	-0.244
38.84	91.65	-0.244
38.86	91.54	-0.244
38.89	91.43	-0.244
38.91	91.32	-0.244
38.93	91.21	-0.244
38.95	91.11	-0.244
38.97	91.00	-0.244
38.99	90.89	-0.244
39.02	90.78	-0.244
39.04	90.67	-0.244
39.06	90.57	-0.244
39.08	90.46	-0.244
39.10	90.35	-0.244
39.13	90.24	-0.244
39.15	90.13	-0.244
39.17	90.02	-0.244
39.19	89.92	-0.243
39.21	89.81	-0.243
39.23	89.70	-0.243
39.26	89.59	-0.243
39.28	89.48	-0.243
39.30	89.37	-0.243
39.32	89.27	-0.243
39.34	89.16	-0.243
39.36	89.05	-0.243
39.39	88.94	-0.243
39.41	88.83	-0.243
39.43	88.72	-0.243
39.45	88.62	-0.243
39.47	88.51	-0.243
39.49	88.40	-0.243
39.51	88.29	-0.243
39.54	88.18	-0.242
39.56	88.07	-0.243
39.58	87.96	-0.242
39.60	87.86	-0.242
39.62	87.75	-0.242
39.64	87.64	-0.242
39.67	87.53	-0.242
39.69	87.42	-0.242
39.71	87.32	-0.242
39.73	87.21	-0.242
39.75	87.10	-0.242
39.78	86.99	-0.242
39.80	86.88	-0.242
39.82	86.77	-0.242
39.84	86.67	-0.242
39.86	86.56	-0.242
39.88	86.45	-0.242
39.91	86.34	-0.242
39.93	86.23	-0.241
39.95	86.13	-0.241
39.97	86.02	-0.241
39.99	85.91	-0.241
40.01	85.80	-0.241
40.04	85.69	-0.241
40.06	85.58	-0.241
40.08	85.48	-0.241
40.10	85.37	-0.241
40.12	85.26	-0.241
40.14	85.15	-0.241
40.16	85.04	-0.241
40.19	84.94	-0.241
40.21	84.83	-0.240
40.23	84.72	-0.240
40.25	84.61	-0.240
40.27	84.50	-0.240
40.29	84.39	-0.240
40.32	84.28	-0.240
40.34	84.18	-0.240
40.36	84.07	-0.240
40.38	83.96	-0.240
40.40	83.85	-0.240
40.43	83.74	-0.241
40.45	83.63	-0.241
40.47	83.53	-0.240
40.49	83.42	-0.240
40.51	83.31	-0.240
40.53	83.20	-0.240
40.56	83.09	-0.240
40.58	82.99	-0.240
40.60	82.88	-0.240
40.62	82.77	-0.240
40.64	82.66	-0.240
40.66	82.55	-0.240
40.69	82.44	-0.240
40.71	82.34	-0.240
40.73	82.23	-0.240
40.75	82.12	-0.240
40.77	82.01	-0.240
40.79	81.90	-0.240
40.81	81.79	-0.240
40.84	81.69	-0.240
40.86	81.58	-0.240
40.88	81.47	-0.240
40.90	81.36	-0.240
40.92	81.25	-0.240
40.94	81.15	-0.240
40.97	81.04	-0.240
40.99	80.93	-0.240
41.01	80.82	-0.240
41.03	80.71	-0.240
[...]
141.35	6.00	0.125
141.37	6.11	0.125
141.40	6.22	0.125
141.42	6.32	0.125
141.44	6.43	0.124
141.46	6.54	0.124
141.48	6.65	0.124
141.50	6.76	0.124
141.53	6.87	0.124
141.55	6.98	0.124
141.57	7.08	0.124
141.59	7.19	0.124
141.61	7.30	0.124
141.63	7.41	0.124
141.65	7.52	0.124
141.68	7.63	0.124
141.70	7.73	0.124
141.72	7.84	0.124
141.74	7.95	0.124
141.76	8.06	0.124
141.78	8.17	0.124
141.81	8.28	0.124
141.83	8.39	0.124
141.85	8.49	0.124
141.87	8.60	0.124
141.89	8.71	0.124
141.92	8.82	0.124
141.94	8.93	0.124
141.96	9.04	0.124
141.98	9.14	0.124
142.00	9.25	0.124
142.02	9.36	0.124
142.05	9.47	0.124
142.07	9.58	0.124
142.09	9.69	0.124
142.11	9.79	0.124
142.13	9.90	0.124
142.15	10.01	0.124
142.18	10.12	0.124
142.20	10.23	0.124
142.22	10.34	0.124
142.24	10.45	0.124
142.26	10.55	0.124
142.28	10.66	0.124
142.30	10.77	0.124
142.33	10.88	0.124
142.35	10.99	0.124
142.37	11.10	0.124
142.39	11.21	0.124
142.41	11.31	0.124
142.43	11.42	0.124
142.46	11.53	0.124
142.48	11.64	0.124
142.50	11.75	0.124
142.52	11.85	0.124
142.54	11.96	0.124
142.57	12.07	0.124
142.59	12.18	0.124
142.61	12.29	0.124
142.63	12.40	0.124
142.65	12.50	0.124
142.67	12.61	0.124
142.70	12.72	0.125
142.72	12.83	0.124
142.74	12.94	0.125
142.76	13.05	0.125
142.78	13.16	0.125
142.80	13.26	0.125
142.83	13.37	0.125
142.85	13.48	0.125
142.87	13.59	0.125
142.89	13.70	0.125
142.91	13.81	0.125
142.93	13.91	0.125
142.95	14.02	0.125
142.98	14.13	0.125
143.00	14.24	0.125
143.02	14.35	0.125
143.04	14.46	0.125
143.06	14.56	0.125
143.08	14.67	0.125
143.11	14.78	0.125
143.13	14.89	0.125
143.15	15.00	0.125
143.17	15.11	0.125
143.19	15.22	0.125
143.22	15.32	0.125
143.24	15.43	0.125
143.26	15.54	0.125
143.28	15.65	0.125
143.30	15.76	0.125
143.32	15.86	0.125
143.35	15.97	0.125
143.37	16.08	0.125
143.39	16.19	0.125
143.41	16.30	0.125
143.43	16.41	0.125
143.45	16.51	0.125
143.48	16.62	0.125
143.50	16.73	0.125
143.52	16.84	0.125
143.54	16.95	0.125
143.56	17.06	0.125
143.58	17.17	0.125
143.60	17.27	0.126
143.63	17.38	0.126
143.65	17.49	0.126
143.67	17.60	0.126
143.69	17.71	0.126
143.71	17.82	0.126
143.73	17.92	0.126
143.76	18.03	0.126
143.78	18.14	0.126
143.80	18.25	0.126
143.82	18.36	0.126
143.84	18.47	0.126
143.87	18.58	0.126
143.89	18.68	0.126
143.91	18.79	0.126
143.93	18.90	0.126
143.95	19.01	0.126
143.97	19.12	0.126
144.00	19.23	0.126
144.02	19.33	0.126
144.04	19.44	0.126
144.06	19.55	0.126
144.08	19.66	0.126
144.10	19.77	0.126
144.13	19.88	0.126
144.15	19.98	0.126
144.17	20.09	0.126
144.19	20.20	0.126
144.21	20.31	0.126
144.23	20.42	0.126
144.25	20.53	0.126
144.28	20.64	0.126
144.30	20.74	0.126
144.32	20.85	0.126
144.34	20.96	0.126
144.36	21.07	0.127
144.38	21.18	0.127
144.41	21.28	0.127
144.43	21.39	0.127
144.45	21.50	0.127
144.47	21.61	0.127
144.49	21.72	0.127
144.52	21.83	0.127
144.54	21.94	0.127
144.56	22.04	0.127
144.58	22.15	0.127
144.60	22.26	0.127
144.62	22.37	0.127
144.65	22.48	0.127
144.67	22.59	0.127
144.69	22.69	0.127
144.71	22.80	0.127
144.73	22.91	0.127
144.75	23.02	0.127
144.78	23.13	0.127
144.80	23.24	0.127
144.82	23.34	0.127
144.84	23.45	0.127
144.86	23.56	0.127
144.88	23.67	0.127
144.90	23.78	0.127
144.93	23.89	0.127
144.95	24.00	0.127
144.97	24.10	0.127
144.99	24.21	0.127
145.01	24.32	0.127
145.03	24.43	0.127
145.06	24.54	0.127
145.08	24.65	0.127
145.10	24.76	0.127
145.12	24.86	0.127
145.14	24.97	0.127
145.17	25.08	0.127
145.19	25.19	0.127
145.21	25.30	0.127
145.23	25.41	0.127
145.25	25.51	0.127
145.27	25.62	0.127
145.30	25.73	0.127
145.32	25.84	0.127
145.34	25.95	0.127
145.36	26.05	0.127
145.38	26.16	0.127
145.40	26.27	0.127
145.43	26.38	0.127
145.45	26.49	0.127
145.47	26.60	0.128
145.49	26.71	0.128
145.51	26.82	0.128
145.53	26.92	0.128
145.55	27.03	0.128
145.58	27.14	0.128
145.60	27.25	0.128
145.62	27.36	0.128
145.64	27.47	0.128
145.66	27.57	0.128
145.68	27.68	0.128
145.71	27.79	0.128
145.73	27.90	0.128
145.75	28.01	0.128
145.77	28.12	0.128
145.79	28.22	0.128
145.82	28.33	0.128
145.84	28.44	0.128
145.86	28.55	0.128
145.88	28.66	0.128
145.90	28.77	0.128
145.92	28.87	0.128
145.95	28.98	0.128
145.97	29.09	0.128
145.99	29.20	0.128
146.01	29.31	0.128
146.03	29.42	0.128
146.05	29.52	0.129
146.08	29.63	0.129
146.10	29.74	0.129
146.12	29.85	0.129
146.14	29.96	0.129
146.16	30.07	0.129
146.18	30.18	0.129
146.20	30.28	0.129
146.23	30.39	0.129
146.25	30.50	0.129
146.27	30.61	0.129
146.29	30.72	0.129
146.31	30.83	0.129
146.33	30.93	0.129
146.36	31.04	0.129
146.38	31.15	0.129
146.40	31.26	0.129
146.42	31.37	0.129
146.44	31.48	0.130
146.47	31.59	0.130
146.49	31.69	0.130
146.51	31.80	0.130
146.53	31.91	0.130
146.55	32.02	0.130
146.57	32.13	0.130
146.60	32.23	0.130
146.62	32.34	0.130
146.64	32.45	0.130
146.66	32.56	0.130
146.68	32.67	0.130
146.70	32.78	0.130
146.73	32.89	0.130
146.75	32.99	0.130
146.77	33.10	0.130
146.79	33.21	0.130
146.81	33.32	0.130
146.83	33.43	0.130
146.85	33.54	0.130
146.88	33.64	0.130
146.90	33.75	0.130
146.92	33.86	0.130
146.94	33.97	0.130
146.96	34.08	0.130
146.98	34.19	0.130
147.01	34.29	0.130
147.03	34.40	0.130
147.05	34.51	0.130
147.07	34.62	0.130
147.09	34.73	0.130
147.12	34.84	0.130
147.14	34.94	0.130
147.16	35.05	0.131
147.18	35.16	0.131
147.20	35.27	0.131
147.22	35.38	0.131
147.25	35.49	0.131
147.27	35.59	0.131
147.29	35.70	0.131
147.31	35.81	0.131
147.33	35.92	0.131
147.35	36.03	0.131
147.38	36.14	0.131
147.40	36.25	0.131
147.42	36.35	0.131
147.44	36.46	0.131
147.46	36.57	0.131
147.48	36.68	0.131
147.50	36.79	0.131
147.53	36.90	0.131
147.55	37.00	0.131
147.57	37.11	0.131
147.59	37.22	0.131
147.61	37.33	0.131
147.63	37.44	0.131
147.66	37.55	0.131
147.68	37.66	0.131
147.70	37.76	0.131
147.72	37.87	0.131
147.74	37.98	0.131
147.77	38.09	0.131
147.79	38.20	0.131
147.81	38.30	0.131
147.83	38.41	0.131
147.85	38.52	0.131
147.87	38.63	0.131
147.90	38.74	0.131
147.92	38.85	0.132
147.94	38.96	0.132
147.96	39.06	0.132
147.98	39.17	0.132
148.00	39.28	0.132
148.03	39.39	0.132
148.05	39.50	0.132
148.07	39.61	0.132
148.09	39.72	0.132
148.11	39.82	0.132
148.13	39.93	0.132
148.15	40.04	0.132
148.18	40.15	0.132
148.20	40.26	0.132
148.22	40.37	0.132
148.24	40.47	0.132
148.26	40.58	0.132
148.28	40.69	0.132
148.31	40.80	0.132
148.33	40.91	0.132
148.35	41.02	0.132
148.37	41.12	0.132
148.39	41.23	0.132
148.42	41.34	0.132
148.44	41.45	0.132
148.46	41.56	0.132
148.48	41.67	0.132
148.50	41.77	0.132
148.52	41.88	0.132
148.55	41.99	0.132
148.57	42.10	0.132
148.59	42.21	0.132
148.61	42.32	0.132
148.63	42.42	0.132
148.65	42.53	0.132
148.68	42.64	0.132
148.70	42.75	0.133
148.72	42.86	0.133
148.74	42.97	0.133
148.76	43.08	0.133
148.78	43.18	0.133
148.80	43.29	0.133
148.83	43.40	0.133
148.85	43.51	0.133
148.87	43.62	0.133
148.89	43.73	0.133
148.91	43.83	0.133
148.93	43.94	0.133
148.96	44.05	0.133
148.98	44.16	0.133
149.00	44.27	0.133
149.02	44.38	0.133
149.04	44.48	0.133
149.07	44.59	0.133
149.09	44.70	0.133
149.11	44.81	0.133
149.13	44.92	0.133
149.15	45.03	0.133
149.17	45.14	0.133
149.20	45.24	0.133
149.22	45.35	0.133
149.24	45.46	0.133
149.26	45.57	0.133
149.28	45.68	0.133
149.30	45.79	0.133
149.33	45.89	0.133
149.35	46.00	0.133
149.37	46.11	0.133
149.39	46.22	0.133
149.41	46.33	0.133
149.43	46.44	0.133
149.45	46.54	0.133
149.48	46.65	0.133
149.50	46.76	0.133
149.52	46.87	0.133
149.54	46.98	0.133
149.56	47.09	0.134
149.58	47.19	0.133
149.61	47.30	0.134
149.63	47.41	0.134
149.65	47.52	0.134
149.67	47.63	0.134
149.69	47.74	0.134
149.72	47.85	0.134
149.74	47.95	0.134
149.76	48.06	0.134
149.78	48.17	0.134
149.80	48.28	0.134
149.82	48.39	0.134
149.85	48.50	0.134
149.87	48.60	0.134
149.89	48.71	0.134
149.91	48.82	0.134
149.93	48.93	0.134
149.95	49.04	0.134
149.98	49.15	0.134
150.00	49.25	0.134
150.02	49.36	0.134
150.04	49.47	0.134
150.06	49.58	0.134
150.08	49.69	0.134
150.10	49.80	0.134
150.13	49.90	0.134
150.15	50.01	0.134
150.17	50.12	0.134
150.19	50.23	0.134
150.21	50.34	0.134
150.23	50.45	0.134
150.26	50.56	0.134
150.28	50.66	0.134
150.30	50.77	0.134
150.32	50.88	0.134
150.34	50.99	0.134
150.37	51.10	0.134
150.39	51.21	0.135
150.41	51.32	0.134
150.43	51.42	0.134
150.45	51.53	0.134
150.47	51.64	0.135
150.50	51.75	0.135
150.52	51.86	0.135
150.54	51.97	0.135
150.56	52.07	0.135
150.58	52.18	0.135
150.60	52.29	0.135
150.63	52.40	0.135
150.65	52.51	0.135
150.67	52.62	0.135
150.69	52.72	0.135
150.71	52.83	0.135
150.73	52.94	0.135
150.75	53.05	0.135
150.78	53.16	0.135
150.80	53.27	0.135
150.82	53.37	0.135
150.84	53.48	0.135
150.86	53.59	0.135
150.88	53.70	0.135
150.91	53.81	0.135
150.93	53.91	0.135
150.95	54.02	0.135
150.97	54.13	0.135
150.99	54.24	0.135
151.02	54.35	0.135
151.04	54.46	0.135
151.06	54.57	0.135
151.08	54.68	0.135
151.10	54.78	0.136
151.12	54.89	0.136
151.15	55.00	0.136
151.17	55.11	0.135
151.19	55.22	0.136
151.21	55.32	0.136
151.23	55.43	0.136
151.25	55.54	0.136
151.28	55.65	0.136
151.30	55.76	0.136
151.32	55.87	0.136
151.34	55.97	0.136
151.36	56.08	0.136
151.38	56.19	0.136
151.40	56.30	0.136
151.43	56.41	0.136
151.45	56.52	0.136
151.47	56.62	0.136
151.49	56.73	0.136
151.51	56.84	0.136
151.53	56.95	0.136
151.56	57.06	0.136
151.58	57.17	0.136
151.60	57.28	0.136
151.62	57.38	0.136
151.64	57.49	0.136
151.67	57.60	0.136
151.69	57.71	0.136
151.71	57.82	0.136
151.73	57.93	0.136
151.75	58.03	0.136
151.77	58.14	0.136
151.80	58.25	0.136
151.82	58.36	0.136
151.84	58.47	0.136
151.86	58.58	0.136
151.88	58.68	0.136
151.90	58.79	0.136
151.93	58.90	0.136
151.95	59.01	0.136
151.97	59.12	0.136
151.99	59.23	0.136
152.01	59.34	0.137
152.03	59.44	0.137
152.05	59.55	0.137
152.08	59.66	0.137
152.10	59.77	0.137
152.12	59.88	0.137
152.14	59.99	0.137
152.16	60.09	0.137
152.18	60.20	0.137
152.21	60.31	0.137
152.23	60.42	0.137
152.25	60.53	0.137
152.27	60.64	0.137
152.29	60.75	0.137
152.32	60.85	0.137
152.34	60.96	0.137
152.36	61.07	0.137
152.38	61.18	0.137
152.40	61.29	0.137
152.42	61.40	0.137
152.45	61.50	0.137
152.47	61.61	0.137
152.49	61.72	0.137
152.51	61.83	0.137
152.53	61.94	0.137
152.55	62.05	0.137
152.58	62.15	0.137
152.60	62.26	0.137
152.62	62.37	0.137
152.64	62.48	0.137
152.66	62.59	0.137
152.68	62.70	0.137
152.70	62.80	0.137
152.73	62.91	0.137
152.75	63.02	0.137
152.77	63.13	0.137
152.79	63.24	0.137
152.81	63.35	0.137
152.83	63.45	0.137
152.86	63.56	0.137
152.88	63.67	0.137
152.90	63.78	0.137
152.92	63.89	0.138
152.94	64.00	0.138
152.97	64.10	0.138
152.99	64.21	0.138
153.01	64.32	0.138
153.03	64.43	0.138
153.05	64.54	0.138
153.07	64.65	0.138
153.10	64.76	0.138
153.12	64.86	0.138
153.14	64.97	0.138
153.16	65.08	0.138
153.18	65.19	0.138
153.20	65.30	0.138
153.23	65.40	0.138
153.25	65.51	0.138
153.27	65.62	0.138
153.29	65.73	0.138
153.31	65.84	0.138
153.33	65.95	0.138
153.35	66.06	0.138
153.38	66.16	0.138
153.40	66.27	0.138
153.42	66.38	0.138
153.44	66.49	0.138
153.46	66.60	0.138
153.48	66.71	0.138
153.51	66.81	0.138
153.53	66.92	0.138
153.55	67.03	0.138
153.57	67.14	0.138
153.59	67.25	0.138
153.62	67.36	0.138
153.64	67.47	0.138
153.66	67.57	0.138
153.68	67.68	0.138
153.70	67.79	0.138
153.72	67.90	0.138
153.75	68.01	0.139
153.77	68.12	0.139
153.79	68.22	0.139
153.81	68.33	0.139
153.83	68.44	0.139
153.85	68.55	0.139
153.88	68.66	0.139
153.90	68.77	0.139
153.92	68.87	0.139
153.94	68.98	0.139
153.96	69.09	0.139
153.98	69.20	0.139
154.00	69.31	0.139
154.03	69.42	0.139
154.05	69.52	0.139
154.07	69.63	0.139
154.09	69.74	0.139
154.11	69.85	0.139
154.13	69.96	0.139
154.16	70.07	0.139
154.18	70.18	0.139
154.20	70.28	0.139
154.22	70.39	0.139
154.24	70.50	0.139
154.27	70.61	0.139
154.29	70.72	0.139
154.31	70.83	0.139
154.33	70.93	0.139
154.35	71.04	0.139
154.37	71.15	0.139
154.40	71.26	0.139
154.42	71.37	0.139
154.44	71.48	0.139
154.46	71.58	0.139
154.48	71.69	0.139
154.50	71.80	0.139
154.53	71.91	0.139
154.55	72.02	0.139
154.57	72.13	0.139
154.59	72.24	0.139
154.61	72.34	0.139
154.63	72.45	0.139
154.65	72.56	0.139
154.68	72.67	0.139
154.70	72.78	0.139
154.72	72.88	0.140
154.74	72.99	0.139
154.76	73.10	0.140
154.78	73.21	0.140
154.81	73.32	0.140
154.83	73.43	0.140
154.85	73.53	0.140
154.87	73.64	0.140
154.89	73.75	0.140
154.92	73.86	0.140
154.94	73.97	0.140
154.96	74.08	0.140
154.98	74.19	0.140
155.00	74.29	0.140
155.02	74.40	0.140
155.05	74.51	0.140
155.07	74.62	0.140
155.09	74.73	0.140
155.11	74.84	0.140
155.13	74.95	0.140
155.15	75.05	0.140
155.18	75.16	0.140
155.20	75.27	0.140
155.22	75.38	0.140
155.24	75.49	0.140
155.26	75.59	0.140
155.28	75.70	0.140
155.30	75.81	0.140
155.33	75.92	0.140
155.35	76.03	0.140
155.37	76.14	0.140
155.39	76.24	0.140
155.41	76.35	0.140
155.43	76.46	0.140
155.46	76.57	0.140
155.48	76.68	0.140
155.50	76.79	0.140
155.52	76.89	0.141
155.54	77.00	0.141
155.57	77.11	0.141
155.59	77.22	0.141
155.61	77.33	0.141
155.63	77.44	0.141
155.65	77.55	0.141
155.67	77.65	0.141
155.70	77.76	0.141
155.72	77.87	0.141
155.74	77.98	0.141
155.76	78.09	0.141
155.78	78.20	0.141
155.80	78.31	0.141
155.83	78.41	0.141
155.85	78.52	0.141
155.87	78.63	0.141
155.89	78.74	0.141
155.91	78.85	0.141
155.93	78.96	0.141
155.95	79.06	0.141
155.98	79.17	0.141
156.00	79.28	0.141
156.02	79.39	0.141
156.04	79.50	0.141
156.06	79.61	0.141
156.08	79.71	0.141
156.11	79.82	0.141
156.13	79.93	0.141
156.15	80.04	0.141
156.17	80.15	0.141
156.19	80.26	0.141
156.22	80.36	0.141
156.24	80.47	0.141
156.26	80.58	0.141
156.28	80.69	0.141
156.30	80.80	0.141
156.32	80.91	0.142
156.35	81.01	0.142
156.37	81.12	0.142
156.39	81.23	0.142
156.41	81.34	0.142
156.43	81.45	0.142
156.45	81.56	0.142
156.48	81.66	0.142
156.50	81.77	0.142
156.52	81.88	0.142
156.54	81.99	0.142
156.56	82.10	0.142
156.58	82.21	0.142
156.60	82.32	0.142
156.63	82.42	0.142
156.65	82.53	0.142
156.67	82.64	0.142
156.69	82.75	0.142
156.71	82.86	0.142
156.73	82.96	0.142
156.76	83.07	0.142
156.78	83.18	0.142
156.80	83.29	0.142
156.82	83.40	0.142
156.84	83.51	0.142
156.87	83.62	0.142
156.89	83.72	0.142
156.91	83.83	0.142
156.93	83.94	0.142
156.95	84.05	0.142
156.97	84.16	0.142
157.00	84.27	0.142
157.02	84.37	0.142
157.04	84.48	0.142
157.06	84.59	0.142
157.08	84.70	0.142
157.10	84.81	0.142
157.13	84.91	0.142
157.15	85.02	0.142
157.17	85.13	0.142
157.19	85.24	0.142
157.21	85.35	0.142
157.23	85.46	0.142
157.25	85.57	0.142
157.28	85.67	0.142
157.30	85.78	0.142
157.32	85.89	0.142
157.34	86.00	0.142
157.36	86.11	0.142
157.38	86.22	0.142
157.41	86.33	0.142
157.43	86.43	0.142
157.45	86.54	0.142
157.47	86.65	0.142
157.49	86.76	0.142
157.52	86.87	0.142
157.54	86.97	0.142
157.56	87.08	0.142
157.58	87.19	0.142
157.60	87.30	0.142
157.62	87.41	0.142
157.65	87.52	0.142
157.67	87.63	0.142
157.69	87.73	0.142
157.71	87.84	0.142
157.73	87.95	0.142
157.75	88.06	0.142
157.78	88.17	0.142
157.80	88.28	0.142
157.82	88.38	0.143
157.84	88.49	0.142
157.86	88.60	0.142
157.88	88.71	0.143
157.90	88.82	0.143
157.93	88.93	0.143
157.95	89.03	0.143
157.97	89.14	0.143
157.99	89.25	0.143
158.01	89.36	0.143
158.03	89.47	0.143
158.06	89.58	0.143
158.08	89.69	0.143
158.10	89.79	0.143
158.12	89.90	0.143
158.14	90.01	0.143
158.17	90.12	0.143
158.19	90.23	0.143
158.21	90.33	0.143
158.23	90.44	0.143
158.25	90.55	0.143
158.27	90.66	0.143
158.30	90.77	0.143
158.32	90.88	0.143
158.34	90.99	0.143
158.36	91.09	0.143
158.38	91.20	0.143
158.40	91.31	0.143
158.43	91.42	0.143
158.45	91.53	0.143
158.47	91.64	0.143
158.49	91.74	0.143
158.51	91.85	0.143
158.53	91.96	0.144
158.55	92.07	0.144
158.58	92.18	0.144
158.60	92.29	0.144
158.62	92.39	0.144
158.64	92.50	0.144
158.66	92.61	0.144
158.68	92.72	0.144
158.71	92.83	0.144
158.73	92.94	0.144
158.75	93.04	0.144
158.77	93.15	0.144
158.79	93.26	0.144
158.82	93.37	0.144
158.84	93.48	0.144
158.86	93.59	0.144
158.88	93.70	0.144
158.90	93.80	0.144
158.92	93.91	0.144
158.95	94.02	0.144
158.97	94.13	0.144
158.99	94.24	0.144
159.01	94.35	0.144
159.03	94.45	0.144
159.05	94.56	0.144
159.08	94.67	0.144
159.10	94.78	0.144
159.12	94.89	0.144
159.14	95.00	0.144
159.16	95.10	0.144
159.18	95.21	0.144
159.20	95.32	0.144
159.23	95.43	0.144
159.25	95.54	0.144
159.27	95.64	0.145
159.29	95.75	0.145
159.31	95.86	0.145
159.33	95.97	0.145
159.36	96.08	0.145
159.38	96.19	0.145
159.40	96.30	0.145
159.42	96.40	0.145
159.44	96.51	0.145
159.47	96.62	0.145
159.49	96.73	0.145
159.51	96.84	0.145
159.53	96.95	0.145
159.55	97.06	0.145
159.57	97.16	0.145
159.60	97.27	0.145
159.62	97.38	0.145
159.64	97.49	0.145
159.66	97.60	0.145
159.68	97.70	0.145
159.70	97.81	0.145
159.73	97.92	0.145
159.75	98.03	0.145
159.77	98.14	0.145
159.79	98.25	0.145
159.81	98.36	0.145
159.83	98.46	0.145
159.85	98.57	0.145
159.88	98.68	0.145
159.90	98.79	0.145
159.92	98.90	0.145
159.94	99.01	0.145
159.96	99.11	0.145
159.98	99.22	0.145
160.01	99.33	0.145
160.03	99.44	0.145
160.05	99.55	0.145
160.07	99.66	0.145
160.09	99.76	0.145
160.12	99.87	0.145
160.14	99.98	0.145
160.16	100.09	0.145
160.18	100.20	0.145
160.20	100.31	0.146
160.22	100.41	0.146
160.25	100.52	0.146
160.27	100.63	0.146
160.29	100.74	0.146
160.31	100.85	0.146
160.33	100.96	0.146
160.35	101.07	0.146
160.38	101.17	0.146
160.40	101.28	0.146
160.42	101.39	0.146
160.44	101.50	0.146
160.46	101.61	0.146
160.48	101.72	0.146
160.50	101.82	0.146
160.53	101.93	0.146
160.55	102.04	0.146
160.57	102.15	0.146
160.59	102.26	0.146
160.61	102.37	0.146
160.63	102.47	0.146
160.66	102.58	0.146
160.68	102.69	0.146
160.70	102.80	0.146
160.72	102.91	0.146
160.74	103.02	0.146
160.77	103.12	0.146
160.79	103.23	0.146
160.81	103.34	0.146
160.83	103.45	0.146
160.85	103.56	0.146
160.87	103.66	0.146
160.90	103.77	0.146
160.92	103.88	0.146
160.94	103.99	0.146
160.96	104.10	0.146
160.98	104.21	0.146
161.00	104.31	0.146
161.03	104.42	0.146
161.05	104.53	0.146
161.07	104.64	0.146
161.09	104.75	0.146
161.11	104.86	0.146
161.13	104.97	0.146
161.15	105.07	0.146
161.18	105.18	0.146
161.20	105.29	0.146
161.22	105.40	0.146
161.24	105.51	0.147
161.26	105.62	0.147
161.28	105.73	0.147
161.31	105.83	0.147
161.33	105.94	0.147
161.35	106.05	0.147
161.37	106.16	0.147
161.39	106.27	0.147
161.42	106.38	0.147
161.44	106.48	0.147
161.46	106.59	0.147
161.48	106.70	0.147
161.50	106.81	0.147
161.52	106.92	0.147
161.55	107.03	0.147
161.57	107.13	0.147
161.59	107.24	0.147
161.61	107.35	0.147
161.63	107.46	0.147
161.65	107.57	0.147
161.68	107.68	0.147
161.70	107.78	0.147
161.72	107.89	0.147
161.74	108.00	0.147
161.76	108.11	0.147
161.78	108.22	0.147
161.80	108.33	0.147
161.83	108.43	0.147
161.85	108.54	0.147
161.87	108.65	0.147
161.89	108.76	0.147
161.91	108.87	0.147
161.93	108.98	0.147
161.96	109.08	0.147
161.98	109.19	0.147
162.00	109.30	0.148
162.02	109.41	0.147
162.04	109.52	0.147
162.07	109.63	0.147
162.09	109.74	0.148
162.11	109.85	0.148
162.13	109.95	0.148
162.15	110.06	0.148
162.17	110.17	0.148
162.20	110.28	0.148
162.22	110.39	0.148
162.24	110.49	0.148
162.26	110.60	0.148
162.28	110.71	0.148
162.30	110.82	0.148
162.33	110.93	0.148
162.35	111.04	0.148
162.37	111.14	0.148
162.39	111.25	0.148
162.41	111.36	0.148
162.43	111.47	0.148
162.45	111.58	0.148
162.48	111.69	0.148
162.50	111.80	0.148
162.52	111.90	0.148
162.54	112.01	0.148
162.56	112.12	0.148
162.58	112.23	0.148
162.61	112.34	0.148
162.63	112.45	0.148
162.65	112.55	0.148
162.67	112.66	0.148
162.69	112.77	0.148
162.72	112.88	0.148
162.74	112.99	0.148
162.76	113.09	0.148
162.78	113.20	0.148
162.80	113.31	0.148
162.82	113.42	0.148
162.85	113.53	0.148
162.87	113.64	0.148
162.89	113.75	0.148
162.91	113.85	0.148
162.93	113.96	0.148
162.95	114.07	0.148
162.98	114.18	0.148
163.00	114.29	0.148
163.02	114.40	0.148
163.04	114.50	0.148
163.06	114.61	0.148
163.08	114.72	0.148
163.10	114.83	0.148
163.13	114.94	0.148
163.15	115.05	0.148
163.17	115.15	0.149
163.19	115.26	0.149
163.21	115.37	0.149
163.23	115.48	0.149
163.26	115.59	0.149
163.28	115.70	0.149
163.30	115.80	0.149
163.32	115.91	0.149
163.34	116.02	0.149
163.37	116.13	0.149
163.39	116.24	0.149
163.41	116.35	0.149
163.43	116.45	0.149
163.45	116.56	0.149
163.47	116.67	0.149
163.50	116.78	0.149
163.52	116.89	0.149
163.54	117.00	0.149
163.56	117.10	0.149
163.58	117.21	0.149
163.60	117.32	0.149
163.63	117.43	0.149
163.65	117.54	0.149
163.67	117.65	0.149
163.69	117.75	0.149
163.71	117.86	0.149
163.73	117.97	0.149
163.75	118.08	0.149
163.78	118.19	0.149
163.80	118.30	0.149
163.82	118.40	0.149
163.84	118.51	0.149
163.86	118.62	0.149
163.88	118.73	0.149
163.91	118.84	0.149
163.93	118.95	0.149
163.95	119.06
163.97	119.16
163.99