File: DSC/2025_04_20_aTHCa_n60C_100C_10Cmin_x3.csv
Filename,2025_04_20_aTHCa_n60C_100C_10Cmin_x3
Instrument name,DSC2A-00468 (192.168.1.100)
Operator,Yarger
rundate,4/21/2025
Sample name,2025_04_20_aTHCa_n60C_100C_10Cmin_x3
proceduresegments,Data Off ; Equilibrate -60.00 °C; Data On ; Ramp 10.00 °C/min to 100.00 °C; Data Off ; Isothermal 1.0 min; Data On ; Ramp 10.00 °C/min to -60.00 °C; Data Off ; Isothermal 1.0 min; Data On ; Ramp 10.00 °C/min to 100.00 °C; Data Off ; Isothermal 1.0 min; Data On ; Ramp 10.00 °C/min to -60.00 °C; Data Off ; Isothermal 1.0 min; Data On ; Ramp 10.00 °C/min to 100.00 °C
[File Parameters]
Run date,4/21/2025 12:17:21 AM
Trios version,5.1.1.46572
Original File Name,
Current File Name,D:\DSC2500\JYarger\2025_04_20_aTHCa_n60C_100C_10Cmin_x3.tri
[Procedure]
Procedure Name,aTHCa_n60_100C_10Cmin_x3
Sample Name,2025_04_20_aTHCa_n60C_100C_10Cmin_x3
Sample Mass,0.89 mg
Reference Sample Mass,0 mg
Pan Mass,25.27 mg
Pan Number,30
Reference Pan Mass,25.8 mg
Reference Pan Number,28
Pan Type,Tzero Aluminum
Comments,"Al Pan/Lid, Not sealed."
Project Name,CA
Operator,Yarger
Test,Custom
Unload Max Temperature,30
Unload Min Temperature,30
Load Max Temperature,30
Load Min Temperature,30
Stop on Gas Flow Error,Yes
[Signal List]
Signal #1,Time (min)
Signal #2,Temperature (°C)
Signal #3,Heat Flow (mW)
Signal #4,Delta T (µV)
Signal #5,Delta Tzero (µV)
Signal #6,Tzero Temperature (°C)
Signal #7,Cell Purge (mL/min)
Signal #8,Heater Temp (°C)
Signal #9,Power Delivered (W)
Signal #10,Reference Junction Temperature (°C)
Signal #11,Flange Temperature (°C)
Signal #12,Heat Flow Phase (rad)
Signal #13,Total Heat Capacity (J/°C)
Signal #14,Heat Capacity (J/°C)
[Configuration]
Company Name,ASU
Instrument Name,DSC2A-00468
Instrument Type,DSC2500
Serial Number,DSC2A-00468
IP,192.168.1.100
Location of Instrument,MRRC
DisplayType,Unknown
Sample Interval ,0.1 s/pt
Selected Heat Flow,T4P
Exotherm Direction,Down
Cell Serial,DRC2-00792
Lid Type,Standard
Cooler,RCS 90
Leave Cooler on at End of Sequence,On
Gas 2,Nitrogen
Gas Selected,Channel 1
Flow Rate,50 mL/min
Secondary Purge,On
Licensed Heat Flow,Heat Flow T4P
Modulation Licensed,Yes
[Versions]
Common IDD Version,1
Cortex Version,VER 2.10.2.31
Driver,5.0.0.6
GDM Version,1.0.3.3
TouchscreenVersion,1.0.0.16145
FEP Version,1.2.1.21
FEP Bootloader,2.0.0.5
AutoSampler Version,2.1.1.26
Auto Sampler Bootloader,2.0.0.5
FCM Version,1.1.0.3
FCM Bootloader,2.0.0.5
[Experiment Logs]
Experiment Log Entry # 1,Data On set to 0
Experiment Log Entry # 3,Equilibrate Segment -60 (C) Started
Experiment Log Entry # 5,Data On set to 1
Experiment Log Entry # 7,Ramp Segment 10 C/min to 100 Started
Experiment Log Entry # 9,Data On set to 0
Experiment Log Entry # 11,Isothermal Segment 1 min started
Experiment Log Entry # 13,Data On set to 1
Experiment Log Entry # 15,Ramp Segment 10 C/min to -60 Started
Experiment Log Entry # 17,Data On set to 0
Experiment Log Entry # 19,Isothermal Segment 1 min started
Experiment Log Entry # 21,Data On set to 1
Experiment Log Entry # 23,Ramp Segment 10 C/min to 100 Started
Experiment Log Entry # 25,Data On set to 0
Experiment Log Entry # 27,Isothermal Segment 1 min started
Experiment Log Entry # 29,Data On set to 1
Experiment Log Entry # 31,Ramp Segment 10 C/min to -60 Started
Experiment Log Entry # 33,Data On set to 0
Experiment Log Entry # 35,Isothermal Segment 1 min started
Experiment Log Entry # 37,Data On set to 1
Experiment Log Entry # 39,Ramp Segment 10 C/min to 100 Started
[Method Log]
Method Log Entry # 1,Data Off
Method Log Entry # 2,Equilibrate -60 °C
Method Log Entry # 3,Data On
Method Log Entry # 4,(Ramp 664510) Ramp 10 °C/minute to 100 °C
Method Log Entry # 5,Data Off
Method Log Entry # 6,Isothermal 1 minutes
Method Log Entry # 7,Data On
Method Log Entry # 8,(Ramp 664514) Ramp 10 °C/minute to -60 °C
Method Log Entry # 9,Data Off
Method Log Entry # 10,Isothermal 1 minutes
Method Log Entry # 11,Data On
Method Log Entry # 12,(Ramp 664518) Ramp 10 °C/minute to 100 °C
Method Log Entry # 13,Data Off
Method Log Entry # 14,Isothermal 1 minutes
Method Log Entry # 15,Data On
Method Log Entry # 16,(Ramp 664522) Ramp 10 °C/minute to -60 °C
Method Log Entry # 17,Data Off
Method Log Entry # 18,Isothermal 1 minutes
Method Log Entry # 19,Data On
Method Log Entry # 20,(Ramp 664526) Ramp 10 °C/minute to 100 °C
Cell Serial,DRC2-00792
[T1 Calibration]
Slope,-0.008529666
Offset,9.636258
Initial Temperature,98.23
GUID,f8bfdadc-4977-4fdf-ba6d-0ba9134940c3
[TZero Calibration]
Date Applied,11/29/2022 4:06:13 PM
Description,From -89.059 °C to 396.009 °C at 20.000°C/min
Gas Type,Nitrogen
Pan Type,None
Source Files 1,C:\Users\yargerlab\Desktop\DSC Data\General\TZero_calibration_11_29_22_2nd(2).tri
Source Files 2,C:\Users\yargerlab\Desktop\DSC Data\General\TZero_calibration_11_29_22_2nd(3).tri
Delta T Offset,13.05235
Delta T Slope,-0.007271007
Delta T0 Offset,-13.69128
Delta T0 Slope,0.06063341
[Temperature Calibration]
Date Applied,11/29/2022 7:12:28 PM
Description,From 106.590 °C to 186.590 °C at 10.000°C/min
Gas Type,Nitrogen
Pan Type,Tzero Aluminum Hermetic
Source Files 1,C:\Users\yargerlab\Desktop\DSC Data\General\Indium(6).tri
Measured 1,157.391
Known 1,156.598
[Cell Constant Calibration]
Date Applied,11/29/2022 7:12:29 PM
Description,From 106.590 °C to 186.590 °C at 10.000°C/min
Gas Type,Nitrogen
Pan Type,Tzero Aluminum Hermetic
Source Files 1,C:\Users\yargerlab\Desktop\DSC Data\General\Indium(6).tri
T4P KCell,1.006051
Onset Slope,63.26126 mW/°C
[Direct Cp Calibration]
Date Applied,11/30/2022 11:04:51 AM
Description,From -79.983 °C to 298.409 °C at 10.000°C/min
Gas Type,Nitrogen
Pan Type,Tzero Aluminum Hermetic
Source Files 1,C:\Users\yargerlab\Desktop\DSC Data\General\Sapphire_Heat_Capacity_11_30_22.tri
[Rev Cp Calibration]
Date Applied,11/30/2022 1:58:51 PM
Description,From -79.996 °C to 292.812 °C at 3.000°C/min
Gas Type,Nitrogen
Pan Type,Tzero Aluminum Hermetic
Source Files 1,C:\Users\yargerlab\Desktop\DSC Data\General\Sapphire_MDSC_Calibration_11_30_22.tri
[step]
Ramp 10.00 °C/min to 100.00 °C
Time,Temperature,Heat Flow (Normalized)
min,°C,W/g
0.00,-59.80,-0.190
0.01,-59.80,-0.188
0.02,-59.81,-0.187
0.03,-59.81,-0.184
0.05,-59.80,-0.177
0.06,-59.79,-0.151
0.07,-59.77,-0.113
0.08,-59.74,-0.076
0.09,-59.70,-0.034
0.11,-59.65,0.007
0.12,-59.59,0.034
0.13,-59.52,0.068
0.14,-59.44,0.106
0.15,-59.35,0.127
0.16,-59.26,0.151
0.18,-59.16,0.169
0.19,-59.06,0.190
0.20,-58.95,0.204
0.21,-58.84,0.212
0.22,-58.73,0.222
0.23,-58.62,0.230
0.24,-58.51,0.237
0.26,-58.40,0.241
0.27,-58.28,0.244
0.28,-58.17,0.247
0.29,-58.05,0.249
0.30,-57.94,0.252
0.31,-57.83,0.253
0.33,-57.71,0.255
0.34,-57.60,0.255
0.35,-57.49,0.257
0.36,-57.37,0.258
0.37,-57.26,0.260
0.39,-57.14,0.261
0.40,-57.03,0.262
0.41,-56.92,0.263
0.42,-56.80,0.264
0.43,-56.69,0.266
0.44,-56.57,0.268
0.45,-56.46,0.269
0.47,-56.34,0.270
0.48,-56.23,0.272
0.49,-56.12,0.273
0.50,-56.00,0.274
0.51,-55.89,0.276
0.53,-55.77,0.277
0.54,-55.66,0.278
0.55,-55.54,0.279
0.56,-55.43,0.281
0.57,-55.32,0.282
0.58,-55.20,0.283
0.60,-55.09,0.284
0.61,-54.97,0.286
0.62,-54.86,0.287
0.63,-54.74,0.288
0.64,-54.63,0.289
0.65,-54.51,0.290
0.67,-54.40,0.292
0.68,-54.28,0.293
0.69,-54.17,0.294
0.70,-54.05,0.295
0.71,-53.94,0.296
0.72,-53.82,0.298
0.73,-53.71,0.299
0.75,-53.59,0.300
0.76,-53.47,0.301
0.77,-53.36,0.302
0.78,-53.24,0.303
0.79,-53.13,0.304
0.80,-53.01,0.305
0.82,-52.90,0.306
0.83,-52.78,0.307
0.84,-52.67,0.308
0.85,-52.55,0.309
0.86,-52.44,0.310
0.88,-52.32,0.310
0.89,-52.21,0.311
0.90,-52.09,0.312
0.91,-51.98,0.313
0.92,-51.86,0.314
0.93,-51.74,0.314
0.95,-51.63,0.315
0.96,-51.51,0.316
0.97,-51.40,0.317
0.98,-51.28,0.317
0.99,-51.16,0.318
1.00,-51.05,0.319
1.02,-50.93,0.319
1.03,-50.82,0.320
1.04,-50.70,0.321
1.05,-50.59,0.322
1.06,-50.47,0.322
1.07,-50.35,0.323
1.08,-50.24,0.324
1.10,-50.12,0.324
1.11,-50.00,0.325
1.12,-49.89,0.325
1.13,-49.77,0.326
1.14,-49.66,0.326
1.16,-49.54,0.327
1.17,-49.42,0.327
1.18,-49.31,0.328
1.19,-49.19,0.328
1.20,-49.08,0.328
1.21,-48.96,0.329
1.23,-48.84,0.329
1.24,-48.73,0.330
1.25,-48.61,0.330
1.26,-48.50,0.330
1.27,-48.38,0.330
1.28,-48.26,0.331
1.29,-48.15,0.331
1.31,-48.03,0.331
1.32,-47.91,0.332
1.33,-47.80,0.332
1.34,-47.68,0.333
1.35,-47.56,0.333
1.37,-47.45,0.333
1.38,-47.33,0.333
1.39,-47.21,0.333
1.40,-47.10,0.334
1.41,-46.98,0.334
1.42,-46.86,0.334
1.43,-46.75,0.334
1.45,-46.63,0.334
1.46,-46.52,0.334
1.47,-46.40,0.335
1.48,-46.28,0.335
1.49,-46.16,0.335
1.51,-46.05,0.335
1.52,-45.93,0.335
1.53,-45.82,0.335
1.54,-45.70,0.336
1.55,-45.58,0.336
1.56,-45.47,0.336
1.58,-45.35,0.336
1.59,-45.23,0.336
1.60,-45.12,0.336
1.61,-45.00,0.336
1.62,-44.88,0.336
1.63,-44.77,0.336
1.64,-44.65,0.336
1.66,-44.53,0.336
1.67,-44.42,0.336
1.68,-44.30,0.337
1.69,-44.18,0.336
1.70,-44.07,0.336
1.72,-43.95,0.336
1.73,-43.83,0.336
1.74,-43.72,0.336
1.75,-43.60,0.336
1.76,-43.48,0.336
1.77,-43.37,0.336
1.78,-43.25,0.336
1.80,-43.13,0.336
1.81,-43.02,0.336
1.82,-42.90,0.336
1.83,-42.78,0.336
1.84,-42.67,0.336
1.86,-42.55,0.336
1.87,-42.43,0.336
1.88,-42.32,0.336
1.89,-42.20,0.336
1.90,-42.08,0.335
1.91,-41.97,0.335
1.93,-41.85,0.335
1.94,-41.73,0.336
1.95,-41.62,0.335
1.96,-41.50,0.335
1.97,-41.38,0.335
1.98,-41.27,0.335
1.99,-41.15,0.335
2.01,-41.03,0.335
2.02,-40.92,0.335
2.03,-40.80,0.335
2.04,-40.68,0.335
2.05,-40.57,0.334
2.07,-40.45,0.334
2.08,-40.33,0.334
2.09,-40.22,0.334
2.10,-40.10,0.334
2.11,-39.98,0.334
2.12,-39.86,0.334
2.14,-39.75,0.334
2.15,-39.63,0.334
2.16,-39.52,0.334
2.17,-39.40,0.334
2.18,-39.28,0.334
2.19,-39.16,0.333
2.21,-39.05,0.333
2.22,-38.93,0.333
2.23,-38.81,0.333
2.24,-38.70,0.333
2.25,-38.58,0.333
2.26,-38.46,0.333
2.28,-38.35,0.333
2.29,-38.23,0.332
2.30,-38.11,0.332
2.31,-38.00,0.332
2.32,-37.88,0.332
2.33,-37.76,0.332
2.34,-37.65,0.331
2.36,-37.53,0.331
2.37,-37.41,0.331
2.38,-37.30,0.331
2.39,-37.18,0.331
2.40,-37.06,0.331
2.41,-36.94,0.331
2.43,-36.83,0.330
2.44,-36.71,0.330
2.45,-36.59,0.330
2.46,-36.48,0.330
2.47,-36.36,0.330
2.49,-36.24,0.330
2.50,-36.13,0.329
2.51,-36.01,0.329
2.52,-35.89,0.329
2.53,-35.78,0.329
2.54,-35.66,0.329
2.56,-35.54,0.329
2.57,-35.43,0.328
2.58,-35.31,0.328
2.59,-35.19,0.328
2.60,-35.07,0.328
2.61,-34.96,0.328
2.63,-34.84,0.328
2.64,-34.72,0.328
2.65,-34.61,0.327
2.66,-34.49,0.327
2.67,-34.37,0.327
2.68,-34.26,0.327
2.69,-34.14,0.327
2.71,-34.02,0.327
2.72,-33.91,0.326
2.73,-33.79,0.326
2.74,-33.67,0.326
2.75,-33.56,0.326
2.76,-33.44,0.326
2.78,-33.32,0.326
2.79,-33.21,0.325
2.80,-33.09,0.325
2.81,-32.98,0.325
2.82,-32.86,0.325
2.84,-32.74,0.325
2.85,-32.62,0.325
2.86,-32.51,0.324
2.87,-32.39,0.324
2.88,-32.27,0.324
2.89,-32.16,0.324
2.91,-32.04,0.324
2.92,-31.92,0.323
2.93,-31.81,0.323
2.94,-31.69,0.323
2.95,-31.57,0.323
2.96,-31.46,0.323
2.98,-31.34,0.323
2.99,-31.22,0.323
3.00,-31.10,0.322
3.01,-30.99,0.322
3.02,-30.87,0.322
3.03,-30.75,0.322
3.04,-30.64,0.322
3.06,-30.52,0.322
3.07,-30.40,0.321
3.08,-30.29,0.321
3.09,-30.17,0.321
3.10,-30.05,0.321
3.11,-29.94,0.321
3.13,-29.82,0.321
3.14,-29.70,0.320
3.15,-29.59,0.320
3.16,-29.47,0.320
3.17,-29.35,0.320
3.19,-29.24,0.319
3.20,-29.12,0.319
3.21,-29.00,0.319
3.22,-28.89,0.319
3.23,-28.77,0.319
3.24,-28.65,0.319
3.26,-28.53,0.318
3.27,-28.42,0.318
3.28,-28.30,0.318
3.29,-28.19,0.318
3.30,-28.07,0.318
3.31,-27.95,0.317
3.33,-27.83,0.317
3.34,-27.72,0.317
3.35,-27.60,0.317
3.36,-27.48,0.317
3.37,-27.37,0.317
3.38,-27.25,0.317
3.39,-27.13,0.316
3.41,-27.02,0.316
3.42,-26.90,0.316
3.43,-26.78,0.316
3.44,-26.67,0.316
3.45,-26.55,0.316
3.46,-26.43,0.316
3.48,-26.31,0.316
3.49,-26.20,0.315
3.50,-26.08,0.315
3.51,-25.96,0.315
3.52,-25.85,0.315
3.54,-25.73,0.315
3.55,-25.61,0.315
3.56,-25.50,0.315
3.57,-25.38,0.315
3.58,-25.26,0.315
3.59,-25.15,0.314
3.61,-25.03,0.314
3.62,-24.91,0.314
3.63,-24.80,0.314
3.64,-24.68,0.314
3.65,-24.56,0.314
3.66,-24.45,0.314
3.68,-24.33,0.314
3.69,-24.21,0.313
3.70,-24.10,0.313
3.71,-23.98,0.313
3.72,-23.86,0.313
3.73,-23.75,0.313
3.74,-23.63,0.313
3.76,-23.51,0.313
3.77,-23.39,0.313
3.78,-23.28,0.313
3.79,-23.16,0.313
3.80,-23.04,0.313
3.81,-22.93,0.312
3.83,-22.81,0.312
3.84,-22.69,0.312
3.85,-22.58,0.312
3.86,-22.46,0.312
3.87,-22.34,0.312
3.89,-22.23,0.312
3.90,-22.11,0.312
3.91,-21.99,0.312
3.92,-21.88,0.312
3.93,-21.76,0.311
3.94,-21.64,0.311
3.96,-21.53,0.311
3.97,-21.41,0.311
3.98,-21.29,0.311
3.99,-21.18,0.311
4.00,-21.06,0.311
4.01,-20.94,0.311
4.03,-20.83,0.310
4.04,-20.71,0.310
4.05,-20.59,0.310
4.06,-20.48,0.310
4.07,-20.36,0.310
4.08,-20.24,0.310
4.09,-20.13,0.310
4.11,-20.01,0.310
4.12,-19.89,0.310
4.13,-19.77,0.309
4.14,-19.66,0.309
4.15,-19.54,0.309
4.16,-19.42,0.309
4.18,-19.31,0.309
4.19,-19.19,0.309
4.20,-19.07,0.309
4.21,-18.96,0.309
4.22,-18.84,0.309
4.24,-18.72,0.309
4.25,-18.60,0.308
4.26,-18.49,0.308
4.27,-18.37,0.308
4.28,-18.26,0.308
4.29,-18.14,0.308
4.30,-18.02,0.307
4.32,-17.91,0.307
4.33,-17.79,0.307
4.34,-17.67,0.307
4.35,-17.56,0.307
4.36,-17.44,0.307
4.38,-17.32,0.307
4.39,-17.20,0.306
4.40,-17.09,0.307
4.41,-16.97,0.306
4.42,-16.85,0.306
4.43,-16.74,0.306
4.45,-16.62,0.306
4.46,-16.50,0.306
4.47,-16.39,0.306
4.48,-16.27,0.306
4.49,-16.15,0.306
4.50,-16.04,0.306
4.51,-15.92,0.306
4.53,-15.80,0.306
4.54,-15.69,0.306
4.55,-15.57,0.305
4.56,-15.45,0.305
4.57,-15.34,0.305
4.59,-15.22,0.305
4.60,-15.10,0.305
4.61,-14.99,0.305
4.62,-14.87,0.305
4.63,-14.75,0.305
4.64,-14.63,0.305
4.65,-14.52,0.305
4.67,-14.40,0.304
4.68,-14.28,0.305
4.69,-14.17,0.304
4.70,-14.05,0.304
4.71,-13.93,0.304
4.73,-13.82,0.304
4.74,-13.70,0.304
4.75,-13.58,0.304
4.76,-13.47,0.304
4.77,-13.35,0.304
4.78,-13.23,0.303
4.80,-13.12,0.303
4.81,-13.00,0.303
4.82,-12.88,0.303
4.83,-12.77,0.303
4.84,-12.65,0.303
4.85,-12.53,0.303
4.86,-12.42,0.303
4.88,-12.30,0.303
4.89,-12.18,0.303
4.90,-12.06,0.303
4.91,-11.95,0.302
4.92,-11.83,0.302
4.94,-11.72,0.302
4.95,-11.60,0.302
4.96,-11.48,0.302
4.97,-11.36,0.302
4.98,-11.25,0.302
4.99,-11.13,0.302
5.00,-11.01,0.302
5.02,-10.90,0.302
5.03,-10.78,0.302
5.04,-10.66,0.302
5.05,-10.55,0.302
5.06,-10.43,0.302
5.08,-10.31,0.302
5.09,-10.20,0.302
5.10,-10.08,0.302
5.11,-9.96,0.302
5.12,-9.85,0.302
5.13,-9.73,0.302
5.15,-9.61,0.302
5.16,-9.50,0.302
5.17,-9.38,0.302
5.18,-9.26,0.302
5.19,-9.15,0.302
5.20,-9.03,0.302
5.21,-8.91,0.302
5.23,-8.80,0.301
5.24,-8.68,0.301
5.25,-8.56,0.301
5.26,-8.44,0.301
5.27,-8.33,0.301
5.29,-8.21,0.301
5.30,-8.10,0.301
5.31,-7.98,0.301
5.32,-7.86,0.301
5.33,-7.74,0.301
5.34,-7.63,0.301
5.35,-7.51,0.301
5.37,-7.39,0.301
5.38,-7.28,0.301
5.39,-7.16,0.301
5.40,-7.04,0.301
5.41,-6.93,0.301
5.43,-6.81,0.301
5.44,-6.69,0.301
5.45,-6.58,0.301
5.46,-6.46,0.301
5.47,-6.34,0.301
5.48,-6.23,0.301
5.50,-6.11,0.301
5.51,-5.99,0.301
5.52,-5.87,0.300
5.53,-5.76,0.300
5.54,-5.64,0.300
5.55,-5.53,0.301
5.56,-5.41,0.300
5.58,-5.29,0.301
5.59,-5.18,0.301
5.60,-5.06,0.300
5.61,-4.94,0.300
5.62,-4.82,0.300
5.64,-4.71,0.300
5.65,-4.59,0.300
5.66,-4.47,0.300
5.67,-4.36,0.300
5.68,-4.24,0.300
5.69,-4.12,0.300
5.70,-4.01,0.300
5.72,-3.89,0.300
5.73,-3.77,0.300
5.74,-3.66,0.300
5.75,-3.54,0.300
5.76,-3.42,0.300
5.78,-3.31,0.299
5.79,-3.19,0.299
5.80,-3.07,0.299
5.81,-2.96,0.299
5.82,-2.84,0.299
5.83,-2.72,0.299
5.85,-2.61,0.299
5.86,-2.49,0.299
5.87,-2.37,0.299
5.88,-2.25,0.299
5.89,-2.14,0.299
5.90,-2.02,0.299
5.91,-1.90,0.299
5.93,-1.79,0.299
5.94,-1.67,0.299
5.95,-1.55,0.299
5.96,-1.44,0.299
5.97,-1.32,0.299
5.99,-1.20,0.299
6.00,-1.09,0.299
6.01,-0.97,0.299
6.02,-0.85,0.299
6.03,-0.73,0.299
6.04,-0.62,0.299
6.05,-0.50,0.299
6.07,-0.39,0.299
6.08,-0.27,0.299
6.09,-0.15,0.299
6.10,-0.04,0.299
6.11,0.08,0.299
6.13,0.20,0.299
6.14,0.32,0.299
6.15,0.43,0.298
6.16,0.55,0.299
6.17,0.67,0.299
6.18,0.78,0.298
6.20,0.90,0.299
6.21,1.02,0.299
6.22,1.13,0.299
6.23,1.25,0.299
6.24,1.37,0.299
6.25,1.48,0.299
6.26,1.60,0.299
6.28,1.72,0.298
6.29,1.83,0.298
6.30,1.95,0.298
6.31,2.07,0.298
6.32,2.18,0.298
6.34,2.30,0.298
6.35,2.42,0.298
6.36,2.53,0.298
6.37,2.65,0.298
6.38,2.77,0.298
6.39,2.88,0.298
6.40,3.00,0.298
6.42,3.12,0.298
6.43,3.24,0.298
6.44,3.35,0.298
6.45,3.47,0.298
6.46,3.59,0.298
6.48,3.70,0.298
6.49,3.82,0.298
6.50,3.94,0.298
6.51,4.05,0.298
6.52,4.17,0.298
6.53,4.29,0.298
6.55,4.40,0.298
6.56,4.52,0.298
6.57,4.64,0.298
6.58,4.75,0.298
6.59,4.87,0.298
6.60,4.99,0.298
6.61,5.10,0.298
6.63,5.22,0.298
6.64,5.34,0.298
6.65,5.45,0.298
6.66,5.57,0.298
6.67,5.69,0.298
6.69,5.80,0.298
6.70,5.92,0.298
6.71,6.04,0.298
6.72,6.15,0.298
6.73,6.27,0.298
6.74,6.39,0.298
6.75,6.51,0.298
6.77,6.62,0.298
6.78,6.74,0.298
6.79,6.86,0.298
6.80,6.97,0.298
6.81,7.09,0.298
6.83,7.21,0.298
6.84,7.32,0.298
6.85,7.44,0.298
6.86,7.56,0.298
6.87,7.67,0.298
6.88,7.79,0.298
6.90,7.91,0.298
6.91,8.02,0.298
6.92,8.14,0.298
6.93,8.26,0.298
6.94,8.37,0.298
6.95,8.49,0.298
6.96,8.61,0.298
6.98,8.72,0.298
6.99,8.84,0.298
7.00,8.96,0.298
7.01,9.07,0.298
7.02,9.19,0.298
7.04,9.31,0.298
7.05,9.43,0.298
7.06,9.54,0.298
7.07,9.66,0.298
7.08,9.78,0.298
7.09,9.89,0.298
7.10,10.01,0.298
7.12,10.13,0.298
7.13,10.24,0.298
7.14,10.36,0.298
7.15,10.48,0.298
7.16,10.59,0.298
7.18,10.71,0.298
7.19,10.83,0.298
7.20,10.94,0.298
7.21,11.06,0.298
7.22,11.18,0.298
7.23,11.29,0.298
7.25,11.41,0.298
7.26,11.53,0.298
7.27,11.64,0.298
7.28,11.76,0.298
7.29,11.88,0.298
7.30,11.99,0.298
7.31,12.11,0.298
7.33,12.23,0.298
7.34,12.34,0.298
7.35,12.46,0.298
7.36,12.58,0.298
7.37,12.69,0.298
7.39,12.81,0.298
7.40,12.93,0.298
7.41,13.05,0.299
7.42,13.16,0.299
7.43,13.28,0.298
7.44,13.40,0.298
7.45,13.51,0.298
7.47,13.63,0.298
7.48,13.75,0.298
7.49,13.86,0.298
7.50,13.98,0.298
7.51,14.10,0.298
7.53,14.21,0.298
7.54,14.33,0.298
7.55,14.45,0.298
7.56,14.56,0.298
7.57,14.68,0.298
7.58,14.80,0.298
7.60,14.91,0.298
7.61,15.03,0.298
7.62,15.15,0.298
7.63,15.26,0.298
7.64,15.38,0.298
7.65,15.50,0.298
7.66,15.61,0.298
7.68,15.73,0.298
7.69,15.85,0.298
7.70,15.97,0.299
7.71,16.08,0.299
7.72,16.20,0.299
7.74,16.32,0.299
7.75,16.43,0.299
7.76,16.55,0.298
7.77,16.67,0.298
7.78,16.78,0.298
7.79,16.90,0.298
7.80,17.02,0.299
7.82,17.13,0.299
7.83,17.25,0.298
7.84,17.37,0.298
7.85,17.48,0.298
7.86,17.60,0.298
7.88,17.72,0.298
7.89,17.83,0.299
7.90,17.95,0.298
7.91,18.07,0.299
7.92,18.18,0.298
7.93,18.30,0.299
7.95,18.42,0.299
7.96,18.53,0.299
7.97,18.65,0.299
7.98,18.77,0.299
7.99,18.88,0.299
8.00,19.00,0.299
8.01,19.12,0.299
8.03,19.23,0.299
8.04,19.35,0.299
8.05,19.47,0.299
8.06,19.59,0.299
8.07,19.70,0.299
8.09,19.82,0.299
8.10,19.94,0.299
8.11,20.05,0.299
8.12,20.17,0.299
8.13,20.29,0.299
8.14,20.40,0.299
8.15,20.52,0.299
8.17,20.64,0.299
8.18,20.75,0.299
8.19,20.87,0.299
8.20,20.99,0.299
8.21,21.10,0.299
8.23,21.22,0.299
8.24,21.34,0.300
8.25,21.45,0.300
8.26,21.57,0.300
8.27,21.69,0.300
8.28,21.80,0.300
8.30,21.92,0.300
8.31,22.04,0.300
8.32,22.15,0.300
8.33,22.27,0.300
8.34,22.39,0.300
8.35,22.50,0.300
8.36,22.62,0.300
8.38,22.74,0.300
8.39,22.86,0.300
8.40,22.97,0.300
8.41,23.09,0.300
8.42,23.21,0.300
8.44,23.32,0.300
8.45,23.44,0.300
8.46,23.56,0.300
8.47,23.67,0.300
8.48,23.79,0.300
8.49,23.90,0.300
8.50,24.02,0.300
8.52,24.14,0.300
8.53,24.26,0.300
8.54,24.37,0.300
8.55,24.49,0.300
8.56,24.61,0.301
8.58,24.72,0.301
8.59,24.84,0.301
8.60,24.96,0.301
8.61,25.07,0.301
8.62,25.19,0.301
8.63,25.31,0.301
8.65,25.42,0.301
8.66,25.54,0.301
8.67,25.66,0.301
8.68,25.77,0.301
8.69,25.89,0.301
8.70,26.01,0.301
8.72,26.12,0.301
8.73,26.24,0.301
8.74,26.36,0.301
8.75,26.47,0.301
8.76,26.59,0.301
8.77,26.71,0.301
8.78,26.83,0.301
8.80,26.94,0.301
8.81,27.06,0.301
8.82,27.18,0.301
8.83,27.29,0.301
8.84,27.41,0.301
8.85,27.53,0.301
8.87,27.64,0.301
8.88,27.76,0.301
8.89,27.88,0.302
8.90,27.99,0.301
8.91,28.11,0.302
8.93,28.23,0.302
8.94,28.34,0.302
8.95,28.46,0.302
8.96,28.58,0.302
8.97,28.69,0.302
8.98,28.81,0.302
9.00,28.93,0.302
9.01,29.04,0.302
9.02,29.16,0.302
9.03,29.28,0.302
9.04,29.40,0.301
9.05,29.51,0.300
9.07,29.63,0.300
9.08,29.74,0.300
9.09,29.86,0.300
9.10,29.98,0.300
9.11,30.10,0.300
9.12,30.21,0.300
9.13,30.33,0.300
9.15,30.45,0.300
9.16,30.56,0.301
9.17,30.68,0.301
9.18,30.80,0.301
9.19,30.91,0.301
9.20,31.03,0.301
9.22,31.15,0.302
9.23,31.26,0.301
9.24,31.38,0.301
9.25,31.50,0.302
9.26,31.61,0.302
9.28,31.73,0.302
9.29,31.85,0.302
9.30,31.96,0.302
9.31,32.08,0.302
9.32,32.20,0.302
9.33,32.31,0.302
9.35,32.43,0.302
9.36,32.55,0.303
9.37,32.67,0.303
9.38,32.78,0.303
9.39,32.90,0.303
9.40,33.02,0.303
9.42,33.13,0.303
9.43,33.25,0.303
9.44,33.37,0.303
9.45,33.48,0.303
9.46,33.60,0.303
9.47,33.72,0.303
9.48,33.83,0.303
9.50,33.95,0.303
9.51,34.07,0.303
9.52,34.18,0.303
9.53,34.30,0.303
9.54,34.41,0.303
9.55,34.53,0.304
9.57,34.65,0.304
9.58,34.77,0.304
9.59,34.88,0.304
9.60,35.00,0.304
9.61,35.12,0.304
9.63,35.23,0.304
9.64,35.35,0.304
9.65,35.47,0.304
9.66,35.58,0.304
9.67,35.70,0.304
9.68,35.82,0.305
9.70,35.93,0.305
9.71,36.05,0.305
9.72,36.17,0.305
9.73,36.28,0.305
9.74,36.40,0.305
9.75,36.52,0.305
9.77,36.63,0.305
9.78,36.75,0.305
9.79,36.87,0.305
9.80,36.98,0.305
9.81,37.10,0.305
9.82,37.22,0.305
9.83,37.34,0.305
9.85,37.45,0.305
9.86,37.57,0.305
9.87,37.68,0.306
9.88,37.80,0.305
9.89,37.92,0.306
9.90,38.04,0.306
9.92,38.15,0.306
9.93,38.27,0.306
9.94,38.39,0.306
9.95,38.50,0.306
9.96,38.62,0.306
9.98,38.74,0.306
9.99,38.85,0.306
10.00,38.97,0.306
10.01,39.09,0.306
10.02,39.20,0.306
10.03,39.32,0.306
10.05,39.44,0.306
10.06,39.55,0.306
10.07,39.67,0.306
10.08,39.79,0.306
10.09,39.90,0.306
10.10,40.02,0.306
10.12,40.14,0.306
10.13,40.25,0.306
10.14,40.37,0.306
10.15,40.49,0.306
10.16,40.60,0.307
10.17,40.72,0.307
10.18,40.84,0.306
10.20,40.95,0.306
10.21,41.07,0.306
10.22,41.19,0.307
10.23,41.31,0.307
10.24,41.42,0.307
10.25,41.54,0.307
10.27,41.65,0.307
10.28,41.77,0.307
10.29,41.89,0.307
10.30,42.00,0.307
10.31,42.12,0.307
10.33,42.24,0.307
10.34,42.36,0.307
10.35,42.47,0.308
10.36,42.59,0.307
10.37,42.71,0.307
10.38,42.82,0.308
10.40,42.94,0.308
10.41,43.06,0.308
10.42,43.17,0.308
10.43,43.29,0.308
10.44,43.41,0.308
10.45,43.52,0.308
10.47,43.64,0.308
10.48,43.76,0.308
10.49,43.87,0.308
10.50,43.99,0.308
10.51,44.11,0.309
10.52,44.22,0.309
10.53,44.34,0.309
10.55,44.46,0.309
10.56,44.57,0.309
10.57,44.69,0.310
10.58,44.81,0.310
10.59,44.92,0.310
10.60,45.04,0.310
10.62,45.16,0.310
10.63,45.28,0.310
10.64,45.39,0.310
10.65,45.51,0.310
10.66,45.63,0.310
10.68,45.74,0.310
10.69,45.86,0.310
10.70,45.98,0.310
10.71,46.09,0.310
10.72,46.21,0.310
10.73,46.33,0.311
10.75,46.44,0.311
10.76,46.56,0.311
10.77,46.68,0.311
10.78,46.79,0.311
10.79,46.91,0.311
10.80,47.03,0.312
10.82,47.14,0.312
10.83,47.26,0.312
10.84,47.38,0.312
10.85,47.49,0.312
10.86,47.61,0.312
10.87,47.73,0.312
10.88,47.85,0.312
10.90,47.96,0.312
10.91,48.08,0.313
10.92,48.19,0.313
10.93,48.31,0.313
10.94,48.43,0.313
10.95,48.54,0.313
10.97,48.66,0.313
10.98,48.78,0.313
10.99,48.90,0.313
11.00,49.01,0.313
11.01,49.13,0.313
11.03,49.25,0.314
11.04,49.36,0.314
11.05,49.48,0.314
11.06,49.60,0.314
11.07,49.71,0.315
11.08,49.83,0.315
11.10,49.95,0.314
11.11,50.06,0.315
11.12,50.18,0.315
11.13,50.30,0.315
11.14,50.41,0.315
11.15,50.53,0.315
11.17,50.65,0.315
11.18,50.76,0.315
11.19,50.88,0.315
11.20,51.00,0.315
11.21,51.11,0.315
11.22,51.23,0.315
11.23,51.35,0.315
11.25,51.47,0.316
11.26,51.58,0.316
11.27,51.70,0.316
11.28,51.81,0.316
11.29,51.93,0.316
11.30,52.05,0.316
11.32,52.17,0.316
11.33,52.28,0.316
11.34,52.40,0.316
11.35,52.51,0.317
11.36,52.63,0.317
11.38,52.75,0.317
11.39,52.87,0.317
11.40,52.98,0.317
11.41,53.10,0.317
11.42,53.22,0.317
11.43,53.33,0.317
11.45,53.45,0.317
11.46,53.57,0.317
11.47,53.68,0.317
11.48,53.80,0.317
11.49,53.92,0.317
11.50,54.03,0.318
11.52,54.15,0.318
11.53,54.27,0.318
11.54,54.38,0.318
11.55,54.50,0.318
11.56,54.62,0.318
11.57,54.73,0.318
11.58,54.85,0.319
11.60,54.97,0.319
11.61,55.09,0.319
11.62,55.20,0.319
11.63,55.32,0.319
11.64,55.43,0.319
11.65,55.55,0.319
11.67,55.67,0.319
11.68,55.79,0.319
11.69,55.90,0.320
11.70,56.02,0.320
11.71,56.13,0.320
11.73,56.25,0.320
11.74,56.37,0.320
11.75,56.49,0.320
11.76,56.60,0.321
11.77,56.72,0.321
11.78,56.84,0.321
11.80,56.95,0.321
11.81,57.07,0.321
11.82,57.18,0.322
11.83,57.30,0.322
11.84,57.42,0.322
11.85,57.54,0.322
11.87,57.65,0.323
11.88,57.77,0.323
11.89,57.89,0.323
11.90,58.00,0.323
11.91,58.12,0.323
11.92,58.24,0.323
11.93,58.35,0.324
11.95,58.47,0.324
11.96,58.59,0.324
11.97,58.70,0.325
11.98,58.82,0.325
11.99,58.94,0.325
12.00,59.06,0.325
12.02,59.17,0.326
12.03,59.29,0.326
12.04,59.41,0.326
12.05,59.52,0.326
12.06,59.64,0.327
12.08,59.76,0.327
12.09,59.87,0.327
12.10,59.99,0.327
12.11,60.10,0.328
12.12,60.22,0.328
12.13,60.34,0.328
12.15,60.46,0.329
12.16,60.57,0.329
12.17,60.69,0.329
12.18,60.81,0.330
12.19,60.92,0.330
12.20,61.04,0.331
12.22,61.16,0.331
12.23,61.27,0.332
12.24,61.39,0.332
12.25,61.51,0.333
12.26,61.62,0.333
12.27,61.74,0.334
12.28,61.86,0.334
12.30,61.97,0.335
12.31,62.09,0.336
12.32,62.21,0.336
12.33,62.32,0.337
12.34,62.44,0.338
12.35,62.56,0.338
12.37,62.68,0.339
12.38,62.79,0.340
12.39,62.91,0.340
12.40,63.03,0.341
12.41,63.14,0.342
12.43,63.26,0.343
12.44,63.37,0.344
12.45,63.49,0.345
12.46,63.61,0.347
12.47,63.72,0.348
12.48,63.84,0.350
12.50,63.96,0.351
12.51,64.07,0.353
12.52,64.19,0.356
12.53,64.31,0.358
12.54,64.42,0.363
12.55,64.54,0.367
12.57,64.66,0.374
12.58,64.77,0.382
12.59,64.89,0.392
12.60,65.01,0.404
12.61,65.12,0.416
12.62,65.24,0.437
12.63,65.35,0.457
12.65,65.47,0.478
12.66,65.59,0.502
12.67,65.70,0.528
12.68,65.82,0.551
12.69,65.93,0.587
12.70,66.05,0.617
12.72,66.16,0.652
12.73,66.28,0.692
12.74,66.39,0.736
12.75,66.51,0.777
12.76,66.62,0.824
12.78,66.74,0.869
12.79,66.85,0.915
12.80,66.97,0.959
12.81,67.08,0.995
12.82,67.19,1.042
12.83,67.31,1.072
12.85,67.42,1.095
12.86,67.54,1.102
12.87,67.65,1.107
12.88,67.77,1.088
12.89,67.89,1.070
12.90,68.00,1.027
12.92,68.12,0.948
12.93,68.24,0.883
12.94,68.36,0.809
12.95,68.48,0.748
12.96,68.60,0.679
12.97,68.72,0.623
12.98,68.84,0.574
13.00,68.96,0.538
13.01,69.08,0.503
13.02,69.20,0.478
13.03,69.32,0.462
13.04,69.43,0.448
13.05,69.55,0.439
13.07,69.67,0.429
13.08,69.79,0.420
13.09,69.91,0.415
13.10,70.02,0.413
13.11,70.14,0.407
13.13,70.26,0.404
13.14,70.38,0.402
13.15,70.49,0.400
13.16,70.61,0.398
13.17,70.73,0.397
13.18,70.84,0.396
13.20,70.96,0.395
13.21,71.08,0.393
13.22,71.20,0.393
13.23,71.31,0.392
13.24,71.43,0.391
13.25,71.55,0.391
13.27,71.66,0.390
13.28,71.78,0.389
13.29,71.90,0.389
13.30,72.01,0.388
13.31,72.13,0.388
13.32,72.25,0.387
13.33,72.36,0.386
13.35,72.48,0.386
13.36,72.60,0.385
13.37,72.71,0.385
13.38,72.83,0.384
13.39,72.95,0.384
13.40,73.06,0.383
13.42,73.18,0.383
13.43,73.30,0.382
13.44,73.41,0.382
13.45,73.53,0.381
13.46,73.65,0.381
13.48,73.76,0.381
13.49,73.88,0.380
13.50,74.00,0.380
13.51,74.11,0.380
13.52,74.23,0.379
13.53,74.35,0.379
13.55,74.47,0.379
13.56,74.58,0.378
13.57,74.70,0.378
13.58,74.82,0.378
13.59,74.93,0.377
13.60,75.05,0.377
13.62,75.17,0.377
13.63,75.28,0.377
13.64,75.40,0.377
13.65,75.52,0.376
13.66,75.63,0.376
13.67,75.75,0.376
13.68,75.87,0.375
13.70,75.98,0.375
13.71,76.10,0.375
13.72,76.22,0.375
13.73,76.33,0.375
13.74,76.45,0.375
13.75,76.57,0.375
13.77,76.68,0.374
13.78,76.80,0.374
13.79,76.92,0.374
13.80,77.03,0.374
13.81,77.15,0.374
13.83,77.27,0.374
13.84,77.38,0.374
13.85,77.50,0.374
13.86,77.62,0.373
13.87,77.73,0.373
13.88,77.85,0.373
13.90,77.97,0.373
13.91,78.08,0.373
13.92,78.20,0.373
13.93,78.32,0.373
13.94,78.44,0.373
13.95,78.55,0.372
13.97,78.67,0.373
13.98,78.79,0.372
13.99,78.90,0.372
14.00,79.02,0.372
14.01,79.14,0.372
14.02,79.25,0.372
14.03,79.37,0.372
14.05,79.49,0.372
14.06,79.60,0.372
14.07,79.72,0.372
14.08,79.84,0.372
14.09,79.95,0.372
14.10,80.07,0.371
14.12,80.19,0.371
14.13,80.30,0.371
14.14,80.42,0.371
14.15,80.54,0.371
14.16,80.66,0.371
14.18,80.77,0.371
14.19,80.89,0.371
14.20,81.00,0.371
14.21,81.12,0.371
14.22,81.24,0.371
14.23,81.36,0.371
14.25,81.47,0.370
14.26,81.59,0.370
14.27,81.70,0.370
14.28,81.82,0.370
14.29,81.94,0.370
14.30,82.06,0.370
14.32,82.17,0.370
14.33,82.29,0.370
14.34,82.40,0.369
14.35,82.52,0.369
14.36,82.64,0.369
14.37,82.76,0.369
14.38,82.87,0.369
14.40,82.99,0.369
14.41,83.11,0.369
14.42,83.22,0.369
14.43,83.34,0.369
14.44,83.46,0.369
14.45,83.57,0.369
14.47,83.69,0.369
14.48,83.81,0.369
14.49,83.92,0.369
14.50,84.04,0.369
14.51,84.16,0.369
14.53,84.27,0.369
14.54,84.39,0.370
14.55,84.51,0.370
14.56,84.62,0.370
14.57,84.74,0.370
14.58,84.86,0.369
14.60,84.97,0.369
14.61,85.09,0.369
14.62,85.21,0.369
14.63,85.33,0.369
14.64,85.44,0.369
14.65,85.56,0.369
14.67,85.68,0.369
14.68,85.79,0.369
14.69,85.91,0.369
14.70,86.03,0.369
14.71,86.14,0.369
14.72,86.26,0.368
14.73,86.38,0.368
14.75,86.49,0.368
14.76,86.61,0.368
14.77,86.73,0.368
14.78,86.84,0.368
14.79,86.96,0.368
14.80,87.08,0.368
14.82,87.19,0.368
14.83,87.31,0.368
14.84,87.43,0.368
14.85,87.54,0.368
14.86,87.66,0.368
14.88,87.78,0.367
14.89,87.89,0.367
14.90,88.01,0.367
14.91,88.13,0.367
14.92,88.24,0.367
14.93,88.36,0.367
14.95,88.48,0.367
14.96,88.60,0.367
14.97,88.71,0.367
14.98,88.83,0.367
14.99,88.94,0.367
15.00,89.06,0.367
15.02,89.18,0.366
15.03,89.29,0.366
15.04,89.41,0.366
15.05,89.53,0.366
15.06,89.64,0.366
15.07,89.76,0.366
15.08,89.88,0.366
15.10,90.00,0.366
15.11,90.11,0.366
15.12,90.23,0.366
15.13,90.35,0.366
15.14,90.46,0.366
15.15,90.58,0.366
15.17,90.70,0.365
15.18,90.81,0.365
15.19,90.93,0.365
15.20,91.05,0.365
15.21,91.16,0.365
15.23,91.28,0.365
15.24,91.39,0.365
15.25,91.51,0.365
15.26,91.63,0.365
15.27,91.75,0.365
15.28,91.86,0.365
15.30,91.98,0.365
15.31,92.10,0.365
15.32,92.21,0.365
15.33,92.33,0.365
15.34,92.45,0.365
15.35,92.56,0.365
15.37,92.68,0.365
15.38,92.80,0.365
15.39,92.91,0.365
15.40,93.03,0.365
15.41,93.15,0.365
15.42,93.27,0.365
15.43,93.38,0.365
15.45,93.50,0.365
15.46,93.62,0.365
15.47,93.73,0.365
15.48,93.85,0.365
15.49,93.97,0.365
15.50,94.08,0.365
15.52,94.20,0.365
15.53,94.31,0.365
15.54,94.43,0.365
15.55,94.55,0.365
15.56,94.67,0.365
15.58,94.78,0.365
15.59,94.90,0.365
15.60,95.02,0.365
15.61,95.13,0.365
15.62,95.25,0.365
15.63,95.37,0.365
15.65,95.48,0.365
15.66,95.60,0.365
15.67,95.71,0.365
15.68,95.83,0.365
15.69,95.95,0.365
15.70,96.07,0.365
15.72,96.18,0.366
15.73,96.30,0.366
15.74,96.42,0.366
15.75,96.53,0.366
15.76,96.65,0.366
15.77,96.77,0.366
15.78,96.88,0.366
15.80,97.00,0.366
15.81,97.12,0.366
15.82,97.23,0.366
15.83,97.35,0.367
15.84,97.47,0.367
15.85,97.58,0.366
15.87,97.70,0.366
15.88,97.82,0.367
15.89,97.93,0.367
15.90,98.05,0.367
15.91,98.17,0.367
15.93,98.28,0.367
15.94,98.40,
15.95,98.52,
15.96,98.64,
15.97,98.75,
15.98,98.87,
15.99,,

[step]
Ramp 10.00 °C/min to -60.00 °C
Time,Temperature,Heat Flow (Normalized)
min,°C,W/g
16.99,100.12,-0.236
17.00,100.12,-0.236
17.02,100.12,-0.237
17.03,100.12,-0.237
17.04,100.11,-0.240
17.05,100.10,-0.260
17.06,100.07,-0.317
17.08,100.04,-0.374
17.09,99.99,-0.428
17.10,99.93,-0.486
17.11,99.86,-0.538
17.12,99.78,-0.586
17.13,99.69,-0.621
17.14,99.59,-0.666
17.16,99.49,-0.683
17.17,99.39,-0.705
17.18,99.28,-0.728
17.19,99.18,-0.731
17.20,99.07,-0.745
17.22,98.96,-0.749
17.23,98.85,-0.760
17.24,98.74,-0.764
17.25,98.63,-0.769
17.26,98.51,-0.774
17.27,98.40,-0.778
17.28,98.29,-0.780
17.30,98.17,-0.783
17.31,98.06,-0.786
17.32,97.94,-0.787
17.33,97.83,-0.789
17.34,97.72,-0.790
17.36,97.60,-0.792
17.37,97.48,-0.794
17.38,97.37,-0.795
17.39,97.25,-0.796
17.40,97.14,-0.797
17.41,97.03,-0.798
17.43,96.91,-0.799
17.44,96.79,-0.800
17.45,96.68,-0.801
17.46,96.56,-0.802
17.47,96.45,-0.803
17.48,96.33,-0.804
17.49,96.22,-0.805
17.51,96.10,-0.806
17.52,95.99,-0.807
17.53,95.87,-0.808
17.54,95.76,-0.809
17.55,95.64,-0.810
17.57,95.53,-0.811
17.58,95.41,-0.812
17.59,95.29,-0.813
17.60,95.18,-0.814
17.61,95.06,-0.815
17.62,94.95,-0.816
17.63,94.83,-0.817
17.65,94.71,-0.817
17.66,94.60,-0.818
17.67,94.48,-0.819
17.68,94.37,-0.819
17.69,94.25,-0.820
17.71,94.14,-0.821
17.72,94.02,-0.822
17.73,93.90,-0.822
17.74,93.79,-0.823
17.75,93.67,-0.823
17.76,93.55,-0.824
17.78,93.44,-0.824
17.79,93.32,-0.825
17.80,93.21,-0.825
17.81,93.09,-0.825
17.82,92.98,-0.826
17.83,92.86,-0.826
17.84,92.74,-0.826
17.86,92.63,-0.826
17.87,92.51,-0.827
17.88,92.39,-0.827
17.89,92.28,-0.827
17.90,92.16,-0.827
17.92,92.05,-0.827
17.93,91.93,-0.828
17.94,91.81,-0.828
17.95,91.70,-0.828
17.96,91.58,-0.828
17.97,91.46,-0.828
17.98,91.35,-0.828
18.00,91.23,-0.828
18.01,91.12,-0.828
18.02,91.00,-0.828
18.03,90.88,-0.828
18.04,90.77,-0.828
18.06,90.65,-0.828
18.07,90.53,-0.828
18.08,90.42,-0.828
18.09,90.30,-0.828
18.10,90.19,-0.828
18.11,90.07,-0.828
18.13,89.95,-0.828
18.14,89.84,-0.828
18.15,89.72,-0.828
18.16,89.60,-0.828
18.17,89.49,-0.828
18.18,89.37,-0.828
18.19,89.26,-0.827
18.21,89.14,-0.827
18.22,89.02,-0.827
18.23,88.91,-0.827
18.24,88.79,-0.827
18.25,88.67,-0.826
18.27,88.56,-0.826
18.28,88.44,-0.826
18.29,88.32,-0.826
18.30,88.21,-0.826
18.31,88.09,-0.825
18.32,87.97,-0.825
18.33,87.86,-0.825
18.35,87.74,-0.825
18.36,87.62,-0.824
18.37,87.51,-0.824
18.38,87.39,-0.824
18.39,87.28,-0.823
18.41,87.16,-0.823
18.42,87.04,-0.823
18.43,86.93,-0.823
18.44,86.81,-0.822
18.45,86.69,-0.822
18.46,86.58,-0.822
18.48,86.46,-0.822
18.49,86.34,-0.821
18.50,86.23,-0.821
18.51,86.11,-0.821
18.52,85.99,-0.820
18.53,85.88,-0.820
18.54,85.76,-0.820
18.56,85.64,-0.819
18.57,85.53,-0.819
18.58,85.41,-0.819
18.59,85.29,-0.819
18.60,85.18,-0.819
18.62,85.06,-0.818
18.63,84.94,-0.818
18.64,84.83,-0.818
18.65,84.71,-0.817
18.66,84.60,-0.817
18.67,84.48,-0.817
18.68,84.36,-0.816
18.70,84.25,-0.816
18.71,84.13,-0.816
18.72,84.01,-0.816
18.73,83.90,-0.815
18.74,83.78,-0.815
18.76,83.66,-0.815
18.77,83.55,-0.815
18.78,83.43,-0.814
18.79,83.31,-0.814
18.80,83.20,-0.814
18.81,83.08,-0.814
18.83,82.96,-0.814
18.84,82.85,-0.813
18.85,82.73,-0.813
18.86,82.61,-0.813
18.87,82.50,-0.813
18.88,82.38,-0.813
18.89,82.26,-0.812
18.91,82.15,-0.812
18.92,82.03,-0.812
18.93,81.91,-0.812
18.94,81.80,-0.812
18.95,81.68,-0.812
18.97,81.56,-0.811
18.98,81.45,-0.811
18.99,81.33,-0.811
19.00,81.21,-0.811
19.01,81.10,-0.811
19.02,80.98,-0.810
19.03,80.87,-0.810
19.05,80.75,-0.810
19.06,80.63,-0.809
19.07,80.51,-0.809
19.08,80.40,-0.809
19.09,80.28,-0.809
19.11,80.16,-0.809
19.12,80.05,-0.809
19.13,79.93,-0.808
19.14,79.81,-0.808
19.15,79.70,-0.808
19.16,79.58,-0.808
19.18,79.46,-0.807
19.19,79.35,-0.807
19.20,79.23,-0.807
19.21,79.12,-0.807
19.22,79.00,-0.807
19.23,78.88,-0.806
19.24,78.77,-0.806
19.26,78.65,-0.806
19.27,78.53,-0.806
19.28,78.41,-0.806
19.29,78.30,-0.805
19.30,78.18,-0.805
19.32,78.07,-0.805
19.33,77.95,-0.805
19.34,77.83,-0.804
19.35,77.72,-0.804
19.36,77.60,-0.804
19.37,77.48,-0.804
19.38,77.37,-0.803
19.40,77.25,-0.803
19.41,77.13,-0.803
19.42,77.02,-0.803
19.43,76.90,-0.802
19.44,76.78,-0.802
19.46,76.67,-0.802
19.47,76.55,-0.802
19.48,76.43,-0.801
19.49,76.32,-0.801
19.50,76.20,-0.801
19.51,76.08,-0.801
19.53,75.96,-0.800
19.54,75.85,-0.800
19.55,75.73,-0.800
19.56,75.62,-0.800
19.57,75.50,-0.799
19.58,75.38,-0.799
19.59,75.27,-0.799
19.61,75.15,-0.798
19.62,75.03,-0.798
19.63,74.92,-0.798
19.64,74.80,-0.798
19.65,74.68,-0.798
19.67,74.57,-0.797
19.68,74.45,-0.797
19.69,74.33,-0.797
19.70,74.22,-0.797
19.71,74.10,-0.796
19.72,73.98,-0.796
19.73,73.87,-0.796
19.75,73.75,-0.796
19.76,73.63,-0.796
19.77,73.52,-0.795
19.78,73.40,-0.795
19.79,73.28,-0.795
19.81,73.17,-0.795
19.82,73.05,-0.794
19.83,72.93,-0.794
19.84,72.82,-0.794
19.85,72.70,-0.794
19.86,72.58,-0.793
19.88,72.47,-0.793
19.89,72.35,-0.793
19.90,72.23,-0.793
19.91,72.12,-0.792
19.92,72.00,-0.792
19.93,71.88,-0.792
19.94,71.77,-0.791
19.96,71.65,-0.791
19.97,71.53,-0.791
19.98,71.42,-0.791
19.99,71.30,-0.791
20.00,71.18,-0.790
20.02,71.07,-0.790
20.03,70.95,-0.790
20.04,70.83,-0.790
20.05,70.72,-0.790
20.06,70.60,-0.789
20.07,70.48,-0.789
20.08,70.37,-0.789
20.10,70.25,-0.789
20.11,70.13,-0.788
20.12,70.02,-0.788
20.13,69.90,-0.788
20.14,69.78,-0.787
20.16,69.67,-0.788
20.17,69.55,-0.787
20.18,69.43,-0.787
20.19,69.32,-0.787
20.20,69.20,-0.786
20.21,69.08,-0.786
20.23,68.97,-0.786
20.24,68.85,-0.786
20.25,68.73,-0.785
20.26,68.62,-0.785
20.27,68.50,-0.785
20.28,68.39,-0.785
20.29,68.27,-0.785
20.31,68.15,-0.784
20.32,68.03,-0.784
20.33,67.92,-0.784
20.34,67.80,-0.784
20.35,67.68,-0.784
20.37,67.57,-0.783
20.38,67.45,-0.783
20.39,67.34,-0.783
20.40,67.22,-0.783
20.41,67.10,-0.782
20.42,66.99,-0.782
20.43,66.87,-0.782
20.45,66.75,-0.782
20.46,66.64,-0.782
20.47,66.52,-0.782
20.48,66.40,-0.781
20.49,66.28,-0.781
20.51,66.17,-0.781
20.52,66.05,-0.780
20.53,65.94,-0.780
20.54,65.82,-0.780
20.55,65.70,-0.780
20.56,65.59,-0.780
20.58,65.47,-0.779
20.59,65.35,-0.779
20.60,65.24,-0.779
20.61,65.12,-0.778
20.62,65.00,-0.778
20.63,64.89,-0.778
20.64,64.77,-0.778
20.66,64.65,-0.777
20.67,64.54,-0.777
20.68,64.42,-0.777
20.69,64.30,-0.777
20.70,64.19,-0.777
20.72,64.07,-0.777
20.73,63.95,-0.777
20.74,63.84,-0.776
20.75,63.72,-0.776
20.76,63.60,-0.776
20.77,63.49,-0.775
20.78,63.37,-0.775
20.80,63.25,-0.775
20.81,63.14,-0.775
20.82,63.02,-0.775
20.83,62.90,-0.774
20.84,62.79,-0.774
20.86,62.67,-0.774
20.87,62.55,-0.774
20.88,62.44,-0.774
20.89,62.32,-0.773
20.90,62.20,-0.773
20.91,62.09,-0.773
20.93,61.97,-0.773
20.94,61.85,-0.772
20.95,61.74,-0.772
20.96,61.62,-0.772
20.97,61.50,-0.772
20.98,61.39,-0.772
20.99,61.27,-0.772
21.01,61.15,-0.771
21.02,61.04,-0.771
21.03,60.92,-0.771
21.04,60.80,-0.770
21.05,60.69,-0.770
21.07,60.57,-0.770
21.08,60.45,-0.770
21.09,60.34,-0.769
21.10,60.22,-0.769
21.11,60.10,-0.769
21.12,59.99,-0.769
21.13,59.87,-0.768
21.15,59.75,-0.768
21.16,59.64,-0.768
21.17,59.52,-0.767
21.18,59.40,-0.767
21.19,59.29,-0.767
21.21,59.17,-0.767
21.22,59.05,-0.766
21.23,58.94,-0.766
21.24,58.82,-0.765
21.25,58.70,-0.765
21.26,58.59,-0.765
21.28,58.47,-0.764
21.29,58.36,-0.764
21.30,58.24,-0.764
21.31,58.12,-0.763
21.32,58.00,-0.763
21.33,57.89,-0.762
21.34,57.77,-0.762
21.36,57.65,-0.762
21.37,57.54,-0.761
21.38,57.42,-0.761
21.39,57.30,-0.760
21.40,57.19,-0.760
21.42,57.07,-0.760
21.43,56.95,-0.759
21.44,56.84,-0.759
21.45,56.72,-0.758
21.46,56.60,-0.758
21.47,56.49,-0.757
21.48,56.37,-0.757
21.50,56.25,-0.757
21.51,56.14,-0.756
21.52,56.02,-0.756
21.53,55.91,-0.755
21.54,55.79,-0.755
21.56,55.67,-0.754
21.57,55.55,-0.754
21.58,55.44,-0.753
21.59,55.32,-0.753
21.60,55.20,-0.752
21.61,55.09,-0.752
21.63,54.97,-0.751
21.64,54.85,-0.751
21.65,54.74,-0.750
21.66,54.62,-0.750
21.67,54.51,-0.749
21.68,54.39,-0.749
21.69,54.27,-0.748
21.71,54.16,-0.747
21.72,54.04,-0.747
21.73,53.92,-0.747
21.74,53.80,-0.746
21.75,53.69,-0.745
21.77,53.57,-0.745
21.78,53.46,-0.744
21.79,53.34,-0.744
21.80,53.22,-0.743
21.81,53.11,-0.743
21.82,52.99,-0.742
21.83,52.87,-0.742
21.85,52.76,-0.741
21.86,52.64,-0.741
21.87,52.52,-0.740
21.88,52.41,-0.740
21.89,52.29,-0.739
21.91,52.17,-0.739
21.92,52.06,-0.738
21.93,51.94,-0.738
21.94,51.82,-0.737
21.95,51.70,-0.737
21.96,51.59,-0.736
21.98,51.47,-0.736
21.99,51.35,-0.735
22.00,51.24,-0.734
22.01,51.12,-0.734
22.02,51.01,-0.734
22.03,50.89,-0.733
22.04,50.77,-0.732
22.06,50.65,-0.732
22.07,50.54,-0.731
22.08,50.42,-0.731
22.09,50.31,-0.731
22.10,50.19,-0.730
22.12,50.07,-0.730
22.13,49.96,-0.729
22.14,49.84,-0.729
22.15,49.72,-0.728
22.16,49.61,-0.728
22.17,49.49,-0.727
22.18,49.37,-0.727
22.20,49.26,-0.726
22.21,49.14,-0.726
22.22,49.02,-0.725
22.23,48.91,-0.725
22.24,48.79,-0.724
22.26,48.67,-0.724
22.27,48.56,-0.723
22.28,48.44,-0.723
22.29,48.32,-0.722
22.30,48.21,-0.722
22.31,48.09,-0.722
22.33,47.97,-0.721
22.34,47.86,-0.721
22.35,47.74,-0.720
22.36,47.62,-0.719
22.37,47.51,-0.719
22.38,47.39,-0.718
22.39,47.27,-0.718
22.41,47.16,-0.718
22.42,47.04,-0.717
22.43,46.92,-0.717
22.44,46.81,-0.716
22.45,46.69,-0.716
22.47,46.57,-0.715
22.48,46.46,-0.715
22.49,46.34,-0.714
22.50,46.22,-0.714
22.51,46.11,-0.714
22.52,45.99,-0.713
22.53,45.87,-0.713
22.55,45.76,-0.712
22.56,45.64,-0.712
22.57,45.52,-0.712
22.58,45.41,-0.710
22.59,45.29,-0.710
22.61,45.17,-0.710
22.62,45.06,-0.709
22.63,44.94,-0.709
22.64,44.82,-0.708
22.65,44.71,-0.708
22.66,44.59,-0.708
22.68,44.47,-0.707
22.69,44.36,-0.707
22.70,44.24,-0.707
22.71,44.12,-0.706
22.72,44.01,-0.706
22.73,43.89,-0.705
22.74,43.77,-0.705
22.76,43.66,-0.705
22.77,43.54,-0.704
22.78,43.42,-0.704
22.79,43.31,-0.703
22.80,43.19,-0.703
22.82,43.07,-0.703
22.83,42.96,-0.702
22.84,42.84,-0.702
22.85,42.72,-0.702
22.86,42.61,-0.701
22.87,42.49,-0.701
22.88,42.37,-0.701
22.90,42.26,-0.700
22.91,42.14,-0.700
22.92,42.02,-0.700
[...]
71.09,-30.29,0.319
71.10,-30.17,0.319
71.11,-30.06,0.319
71.12,-29.94,0.318
71.13,-29.83,0.318
71.14,-29.71,0.318
71.15,-29.59,0.318
71.17,-29.48,0.318
71.18,-29.36,0.318
71.19,-29.24,0.318
71.20,-29.12,0.318
71.21,-29.01,0.318
71.23,-28.89,0.317
71.24,-28.77,0.317
71.25,-28.66,0.317
71.26,-28.54,0.317
71.27,-28.42,0.317
71.28,-28.31,0.317
71.30,-28.19,0.317
71.31,-28.07,0.317
71.32,-27.96,0.316
71.33,-27.84,0.316
71.34,-27.72,0.316
71.35,-27.61,0.316
71.36,-27.49,0.316
71.38,-27.37,0.316
71.39,-27.26,0.316
71.40,-27.14,0.316
71.41,-27.02,0.316
71.42,-26.90,0.316
71.44,-26.79,0.316
71.45,-26.67,0.315
71.46,-26.55,0.315
71.47,-26.44,0.315
71.48,-26.32,0.315
71.49,-26.20,0.315
71.50,-26.09,0.315
71.52,-25.97,0.315
71.53,-25.85,0.315
71.54,-25.74,0.315
71.55,-25.62,0.315
71.56,-25.50,0.315
71.58,-25.39,0.314
71.59,-25.27,0.314
71.60,-25.15,0.314
71.61,-25.04,0.314
71.62,-24.92,0.314
71.63,-24.80,0.314
71.65,-24.68,0.314
71.66,-24.57,0.314
71.67,-24.45,0.313
71.68,-24.33,0.313
71.69,-24.22,0.313
71.70,-24.10,0.313
71.71,-23.98,0.313
71.73,-23.87,0.313
71.74,-23.75,0.313
71.75,-23.63,0.312
71.76,-23.52,0.312
71.77,-23.40,0.312
71.79,-23.28,0.312
71.80,-23.17,0.312
71.81,-23.05,0.312
71.82,-22.93,0.312
71.83,-22.82,0.312
71.84,-22.70,0.311
71.85,-22.58,0.311
71.87,-22.47,0.311
71.88,-22.35,0.311
71.89,-22.23,0.311
71.90,-22.12,0.311
71.91,-22.00,0.311
71.93,-21.88,0.311
71.94,-21.77,0.311
71.95,-21.65,0.311
71.96,-21.53,0.311
71.97,-21.41,0.310
71.98,-21.30,0.310
72.00,-21.18,0.310
72.01,-21.06,0.310
72.02,-20.95,0.310
72.03,-20.83,0.310
72.04,-20.71,0.310
72.05,-20.60,0.309
72.06,-20.48,0.309
72.08,-20.36,0.309
72.09,-20.25,0.309
72.10,-20.13,0.309
72.11,-20.01,0.309
72.12,-19.90,0.309
72.14,-19.78,0.309
72.15,-19.66,0.309
72.16,-19.54,0.309
72.17,-19.43,0.309
72.18,-19.31,0.308
72.19,-19.20,0.308
72.20,-19.08,0.308
72.22,-18.96,0.308
72.23,-18.85,0.308
72.24,-18.73,0.308
72.25,-18.61,0.308
72.26,-18.50,0.308
72.28,-18.38,0.308
72.29,-18.26,0.308
72.30,-18.14,0.307
72.31,-18.03,0.307
72.32,-17.91,0.307
72.33,-17.79,0.307
72.35,-17.68,0.307
72.36,-17.56,0.307
72.37,-17.44,0.307
72.38,-17.33,0.307
72.39,-17.21,0.307
72.40,-17.09,0.307
72.41,-16.98,0.307
72.43,-16.86,0.307
72.44,-16.74,0.306
72.45,-16.63,0.306
72.46,-16.51,0.306
72.47,-16.39,0.306
72.49,-16.28,0.306
72.50,-16.16,0.306
72.51,-16.04,0.306
72.52,-15.92,0.306
72.53,-15.81,0.306
72.54,-15.69,0.306
72.55,-15.58,0.306
72.57,-15.46,0.306
72.58,-15.34,0.306
72.59,-15.22,0.306
72.60,-15.11,0.306
72.61,-14.99,0.306
72.63,-14.87,0.306
72.64,-14.76,0.305
72.65,-14.64,0.305
72.66,-14.52,0.305
72.67,-14.41,0.305
72.68,-14.29,0.305
72.70,-14.17,0.305
72.71,-14.06,0.305
72.72,-13.94,0.305
72.73,-13.82,0.305
72.74,-13.71,0.305
72.75,-13.59,0.305
72.76,-13.47,0.305
72.78,-13.36,0.305
72.79,-13.24,0.305
72.80,-13.12,0.305
72.81,-13.01,0.305
72.82,-12.89,0.304
72.84,-12.77,0.304
72.85,-12.66,0.304
72.86,-12.54,0.304
72.87,-12.42,0.304
72.88,-12.30,0.304
72.89,-12.19,0.304
72.90,-12.07,0.303
72.92,-11.95,0.303
72.93,-11.84,0.303
72.94,-11.72,0.303
72.95,-11.60,0.303
72.96,-11.49,0.303
72.98,-11.37,0.303
72.99,-11.25,0.303
73.00,-11.14,0.303
73.01,-11.02,0.303
73.02,-10.90,0.303
73.03,-10.79,0.302
73.05,-10.67,0.303
73.06,-10.55,0.302
73.07,-10.44,0.302
73.08,-10.32,0.302
73.09,-10.20,0.302
73.10,-10.09,0.302
73.11,-9.97,0.302
73.13,-9.85,0.302
73.14,-9.73,0.302
73.15,-9.62,0.302
73.16,-9.50,0.302
73.17,-9.38,0.302
73.19,-9.27,0.302
73.20,-9.15,0.302
73.21,-9.03,0.302
73.22,-8.92,0.301
73.23,-8.80,0.301
73.24,-8.68,0.301
73.25,-8.57,0.301
73.27,-8.45,0.301
73.28,-8.33,0.301
73.29,-8.22,0.301
73.30,-8.10,0.301
73.31,-7.98,0.301
73.33,-7.87,0.301
73.34,-7.75,0.301
73.35,-7.63,0.301
73.36,-7.52,0.301
73.37,-7.40,0.301
73.38,-7.28,0.301
73.40,-7.16,0.301
73.41,-7.05,0.301
73.42,-6.93,0.301
73.43,-6.81,0.301
73.44,-6.70,0.301
73.45,-6.58,0.300
73.46,-6.46,0.301
73.48,-6.35,0.300
73.49,-6.23,0.300
73.50,-6.11,0.300
73.51,-6.00,0.300
73.52,-5.88,0.300
73.54,-5.76,0.300
73.55,-5.65,0.300
73.56,-5.53,0.300
73.57,-5.41,0.300
73.58,-5.30,0.300
73.59,-5.18,0.300
73.60,-5.06,0.300
73.62,-4.95,0.300
73.63,-4.83,0.300
73.64,-4.71,0.300
73.65,-4.60,0.300
73.66,-4.48,0.300
73.68,-4.36,0.300
73.69,-4.25,0.300
73.70,-4.13,0.300
73.71,-4.01,0.300
73.72,-3.90,0.299
73.73,-3.78,0.299
73.75,-3.66,0.299
73.76,-3.55,0.299
73.77,-3.43,0.299
73.78,-3.31,0.299
73.79,-3.19,0.299
73.80,-3.08,0.299
73.81,-2.96,0.299
73.83,-2.84,0.299
73.84,-2.73,0.299
73.85,-2.61,0.299
73.86,-2.49,0.299
73.87,-2.38,0.299
73.89,-2.26,0.299
73.90,-2.14,0.298
73.91,-2.03,0.298
73.92,-1.91,0.298
73.93,-1.79,0.298
73.94,-1.67,0.298
73.95,-1.56,0.298
73.97,-1.44,0.298
73.98,-1.32,0.298
73.99,-1.21,0.298
74.00,-1.09,0.298
74.01,-0.97,0.298
74.03,-0.86,0.298
74.04,-0.74,0.298
74.05,-0.63,0.298
74.06,-0.51,0.298
74.07,-0.39,0.298
74.08,-0.27,0.298
74.10,-0.16,0.298
74.11,-0.04,0.298
74.12,0.08,0.297
74.13,0.19,0.297
74.14,0.31,0.297
74.15,0.43,0.297
74.16,0.54,0.297
74.18,0.66,0.297
74.19,0.78,0.297
74.20,0.89,0.297
74.21,1.01,0.297
74.22,1.13,0.297
74.24,1.25,0.297
74.25,1.36,0.297
74.26,1.48,0.297
74.27,1.60,0.297
74.28,1.71,0.297
74.29,1.83,0.297
74.30,1.95,0.297
74.32,2.06,0.297
74.33,2.18,0.297
74.34,2.30,0.297
74.35,2.41,0.296
74.36,2.53,0.297
74.38,2.65,0.297
74.39,2.76,0.297
74.40,2.88,0.297
74.41,3.00,0.297
74.42,3.11,0.297
74.43,3.23,0.297
74.45,3.35,0.296
74.46,3.46,0.296
74.47,3.58,0.296
74.48,3.70,0.296
74.49,3.82,0.296
74.50,3.93,0.296
74.51,4.05,0.296
74.53,4.16,0.296
74.54,4.28,0.296
74.55,4.40,0.296
74.56,4.52,0.296
74.57,4.63,0.296
74.59,4.75,0.296
74.60,4.86,0.296
74.61,4.98,0.296
74.62,5.10,0.296
74.63,5.22,0.296
74.64,5.33,0.296
74.65,5.45,0.296
74.67,5.57,0.296
74.68,5.68,0.296
74.69,5.80,0.296
74.70,5.92,0.296
74.71,6.03,0.296
74.73,6.15,0.296
74.74,6.27,0.296
74.75,6.38,0.296
74.76,6.50,0.296
74.77,6.62,0.296
74.78,6.73,0.296
74.80,6.85,0.296
74.81,6.97,0.296
74.82,7.08,0.296
74.83,7.20,0.296
74.84,7.32,0.296
74.85,7.43,0.296
74.86,7.55,0.296
74.88,7.67,0.296
74.89,7.79,0.296
74.90,7.90,0.296
74.91,8.02,0.296
74.92,8.14,0.296
74.94,8.25,0.296
74.95,8.37,0.296
74.96,8.49,0.296
74.97,8.60,0.296
74.98,8.72,0.296
74.99,8.84,0.296
75.00,8.95,0.296
75.02,9.07,0.296
75.03,9.19,0.296
75.04,9.30,0.296
75.05,9.42,0.296
75.06,9.54,0.296
75.08,9.66,0.296
75.09,9.77,0.296
75.10,9.89,0.296
75.11,10.00,0.296
75.12,10.12,0.296
75.13,10.24,0.296
75.15,10.35,0.296
75.16,10.47,0.296
75.17,10.59,0.296
75.18,10.70,0.296
75.19,10.82,0.296
75.20,10.94,0.296
75.21,11.05,0.296
75.23,11.17,0.296
75.24,11.29,0.296
75.25,11.40,0.296
75.26,11.52,0.296
75.27,11.64,0.296
75.29,11.75,0.296
75.30,11.87,0.296
75.31,11.99,0.296
75.32,12.11,0.296
75.33,12.22,0.296
75.34,12.34,0.296
75.35,12.46,0.296
75.37,12.57,0.296
75.38,12.69,0.296
75.39,12.81,0.296
75.40,12.92,0.296
75.41,13.04,0.296
75.43,13.16,0.296
75.44,13.27,0.296
75.45,13.39,0.296
75.46,13.51,0.296
75.47,13.62,0.296
75.48,13.74,0.296
75.50,13.86,0.295
75.51,13.97,0.296
75.52,14.09,0.295
75.53,14.21,0.295
75.54,14.33,0.295
75.55,14.44,0.295
75.56,14.56,0.295
75.58,14.67,0.295
75.59,14.79,0.295
75.60,14.91,0.296
75.61,15.03,0.295
75.62,15.14,0.295
75.64,15.26,0.296
75.65,15.38,0.295
75.66,15.49,0.296
75.67,15.61,0.296
75.68,15.73,0.296
75.69,15.84,0.296
75.70,15.96,0.296
75.72,16.08,0.296
75.73,16.19,0.296
75.74,16.31,0.296
75.75,16.43,0.296
75.76,16.54,0.296
75.78,16.66,0.296
75.79,16.78,0.296
75.80,16.89,0.296
75.81,17.01,0.296
75.82,17.13,0.296
75.83,17.24,0.296
75.85,17.36,0.296
75.86,17.48,0.296
75.87,17.59,0.296
75.88,17.71,0.296
75.89,17.83,0.296
75.90,17.94,0.296
75.91,18.06,0.296
75.93,18.18,0.296
75.94,18.30,0.296
75.95,18.41,0.296
75.96,18.53,0.296
75.97,18.65,0.296
75.99,18.76,0.296
76.00,18.88,0.296
76.01,19.00,0.296
76.02,19.11,0.296
76.03,19.23,0.296
76.04,19.35,0.296
76.05,19.46,0.296
76.07,19.58,0.296
76.08,19.70,0.296
76.09,19.81,0.296
76.10,19.93,0.296
76.11,20.05,0.296
76.13,20.17,0.296
76.14,20.28,0.296
76.15,20.40,0.296
76.16,20.51,0.296
76.17,20.63,0.296
76.18,20.75,0.296
76.20,20.87,0.296
76.21,20.98,0.296
76.22,21.10,0.296
76.23,21.22,0.296
76.24,21.33,0.296
76.25,21.45,0.296
76.26,21.57,0.296
76.28,21.68,0.296
76.29,21.80,0.296
76.30,21.92,0.296
76.31,22.03,0.296
76.32,22.15,0.296
76.34,22.27,0.296
76.35,22.38,0.296
76.36,22.50,0.296
76.37,22.62,0.296
76.38,22.73,0.296
76.39,22.85,0.296
76.40,22.97,0.296
76.42,23.08,0.296
76.43,23.20,0.296
76.44,23.32,0.296
76.45,23.43,0.296
76.46,23.55,0.296
76.48,23.67,0.296
76.49,23.78,0.296
76.50,23.90,0.296
76.51,24.02,0.296
76.52,24.13,0.296
76.53,24.25,0.297
76.55,24.37,0.297
76.56,24.48,0.296
76.57,24.60,0.297
76.58,24.72,0.297
76.59,24.84,0.297
76.60,24.95,0.297
76.61,25.07,0.297
76.63,25.19,0.297
76.64,25.30,0.297
76.65,25.42,0.297
76.66,25.54,0.297
76.67,25.65,0.297
76.69,25.77,0.297
76.70,25.89,0.297
76.71,26.00,0.297
76.72,26.12,0.297
76.73,26.24,0.297
76.74,26.35,0.297
76.75,26.47,0.297
76.77,26.59,0.297
76.78,26.70,0.297
76.79,26.82,0.297
76.80,26.94,0.297
76.81,27.06,0.297
76.83,27.17,0.297
76.84,27.29,0.297
76.85,27.40,0.297
76.86,27.52,0.297
76.87,27.64,0.297
76.88,27.75,0.297
76.90,27.87,0.297
76.91,27.99,0.297
76.92,28.10,0.297
76.93,28.22,0.297
76.94,28.34,0.297
76.95,28.46,0.298
76.96,28.57,0.298
76.98,28.69,0.297
76.99,28.81,0.297
77.00,28.92,0.297
77.01,29.04,0.297
77.02,29.16,0.297
77.04,29.27,0.297
77.05,29.39,0.298
77.06,29.51,0.298
77.07,29.62,0.298
77.08,29.74,0.298
77.09,29.86,0.298
77.10,29.97,0.298
77.12,30.09,0.298
77.13,30.21,0.298
77.14,30.32,0.298
77.15,30.44,0.298
77.16,30.56,0.298
77.18,30.67,0.298
77.19,30.79,0.298
77.20,30.91,0.298
77.21,31.02,0.298
77.22,31.14,0.298
77.23,31.26,0.299
77.25,31.38,0.299
77.26,31.49,0.299
77.27,31.61,0.299
77.28,31.73,0.298
77.29,31.84,0.298
77.30,31.96,0.298
77.31,32.08,0.299
77.33,32.19,0.299
77.34,32.31,0.299
77.35,32.43,0.299
77.36,32.54,0.299
77.37,32.66,0.299
77.39,32.78,0.299
77.40,32.89,0.299
77.41,33.01,0.299
77.42,33.13,0.299
77.43,33.24,0.299
77.44,33.36,0.300
77.45,33.48,0.300
77.47,33.59,0.300
77.48,33.71,0.300
77.49,33.83,0.300
77.50,33.94,0.300
77.51,34.06,0.300
77.53,34.18,0.300
77.54,34.29,0.300
77.55,34.41,0.300
77.56,34.53,0.300
77.57,34.64,0.300
77.58,34.76,0.300
77.60,34.88,0.300
77.61,35.00,0.300
77.62,35.11,0.300
77.63,35.23,0.300
77.64,35.34,0.300
77.65,35.46,0.300
77.66,35.58,0.300
77.68,35.70,0.300
77.69,35.81,0.300
77.70,35.93,0.300
77.71,36.05,0.300
77.72,36.16,0.301
77.74,36.28,0.301
77.75,36.40,0.301
77.76,36.51,0.301
77.77,36.63,0.301
77.78,36.75,0.301
77.79,36.86,0.301
77.80,36.98,0.301
77.82,37.10,0.301
77.83,37.21,0.301
77.84,37.33,0.301
77.85,37.45,0.301
77.86,37.56,0.301
77.88,37.68,0.301
77.89,37.80,0.301
77.90,37.91,0.301
77.91,38.03,0.301
77.92,38.15,0.302
77.93,38.26,0.302
77.95,38.38,0.302
77.96,38.50,0.302
77.97,38.62,0.302
77.98,38.73,0.302
77.99,38.85,0.302
78.00,38.96,0.302
78.01,39.08,0.303
78.03,39.20,0.303
78.04,39.32,0.303
78.05,39.43,0.303
78.06,39.55,0.303
78.07,39.67,0.303
78.09,39.78,0.303
78.10,39.90,0.303
78.11,40.02,0.303
78.12,40.13,0.303
78.13,40.25,0.303
78.14,40.37,0.304
78.15,40.48,0.304
78.17,40.60,0.304
78.18,40.72,0.304
78.19,40.83,0.304
78.20,40.95,0.304
78.21,41.07,0.304
78.23,41.18,0.304
78.24,41.30,0.304
78.25,41.42,0.305
78.26,41.53,0.305
78.27,41.65,0.305
78.28,41.77,0.305
78.30,41.88,0.305
78.31,42.00,0.305
78.32,42.12,0.305
78.33,42.24,0.305
78.34,42.35,0.305
78.35,42.47,0.306
78.36,42.59,0.306
78.38,42.70,0.306
78.39,42.82,0.306
78.40,42.93,0.306
78.41,43.05,0.306
78.42,43.17,0.306
78.44,43.29,0.307
78.45,43.40,0.306
78.46,43.52,0.306
78.47,43.64,0.307
78.48,43.75,0.307
78.49,43.87,0.307
78.50,43.99,0.307
78.52,44.10,0.307
78.53,44.22,0.307
78.54,44.34,0.307
78.55,44.45,0.307
78.56,44.57,0.308
78.58,44.69,0.308
78.59,44.80,0.308
78.60,44.92,0.308
78.61,45.04,0.308
78.62,45.15,0.308
78.63,45.27,0.308
78.65,45.39,0.308
78.66,45.50,0.308
78.67,45.62,0.309
78.68,45.74,0.309
78.69,45.85,0.309
78.70,45.97,0.309
78.71,46.09,0.309
78.73,46.20,0.309
78.74,46.32,0.309
78.75,46.44,0.310
78.76,46.56,0.310
78.77,46.67,0.310
78.79,46.79,0.310
78.80,46.91,0.310
78.81,47.02,0.310
78.82,47.14,0.311
78.83,47.26,0.311
78.84,47.37,0.311
78.85,47.49,0.311
78.87,47.61,0.311
78.88,47.72,0.311
78.89,47.84,0.312
78.90,47.96,0.312
78.91,48.07,0.312
78.93,48.19,0.312
78.94,48.31,0.312
78.95,48.42,0.312
78.96,48.54,0.313
78.97,48.66,0.313
78.98,48.77,0.313
79.00,48.89,0.313
79.01,49.01,0.314
79.02,49.12,0.314
79.03,49.24,0.314
79.04,49.36,0.315
79.05,49.47,0.315
79.06,49.59,0.315
79.08,49.71,0.315
79.09,49.82,0.315
79.10,49.94,0.316
79.11,50.06,0.316
79.12,50.17,0.316
79.14,50.29,0.316
79.15,50.41,0.316
79.16,50.52,0.317
79.17,50.64,0.317
79.18,50.76,0.317
79.19,50.87,0.317
79.20,50.99,0.318
79.22,51.11,0.318
79.23,51.22,0.318
79.24,51.34,0.319
79.25,51.46,0.319
79.26,51.58,0.320
79.28,51.69,0.320
79.29,51.81,0.320
79.30,51.92,0.321
79.31,52.04,0.321
79.32,52.16,0.322
79.33,52.27,0.322
79.35,52.39,0.323
79.36,52.51,0.323
79.37,52.63,0.324
79.38,52.74,0.324
79.39,52.86,0.325
79.40,52.98,0.325
79.41,53.09,0.326
79.43,53.21,0.327
79.44,53.33,0.327
79.45,53.44,0.327
79.46,53.56,0.328
79.47,53.68,0.329
79.49,53.79,0.329
79.50,53.91,0.330
79.51,54.03,0.330
79.52,54.14,0.331
79.53,54.26,0.331
79.54,54.38,0.332
79.55,54.49,0.333
79.57,54.61,0.333
79.58,54.73,0.334
79.59,54.84,0.335
79.60,54.96,0.335
79.61,55.08,0.336
79.63,55.20,0.337
79.64,55.31,0.338
79.65,55.43,0.339
79.66,55.55,0.340
79.67,55.66,0.340
79.68,55.78,0.341
79.70,55.89,0.342
79.71,56.01,0.343
79.72,56.13,0.344
79.73,56.25,0.345
79.74,56.36,0.346
79.75,56.48,0.347
79.76,56.59,0.348
79.78,56.71,0.349
79.79,56.83,0.350
79.80,56.95,0.351
79.81,57.06,0.352
79.82,57.18,0.353
79.84,57.30,0.354
79.85,57.41,0.355
79.86,57.53,0.356
79.87,57.65,0.357
79.88,57.76,0.358
79.89,57.88,0.360
79.90,58.00,0.361
79.92,58.11,0.362
79.93,58.23,0.363
79.94,58.35,0.364
79.95,58.46,0.365
79.96,58.58,0.367
79.98,58.70,0.368
79.99,58.81,0.369
80.00,58.93,0.370
80.01,59.05,0.371
80.02,59.16,0.372
80.03,59.28,0.373
80.05,59.40,0.374
80.06,59.51,0.375
80.07,59.63,0.376
80.08,59.75,0.376
80.09,59.87,0.377
80.10,59.98,0.378
80.11,60.10,0.379
80.13,60.21,0.380
80.14,60.33,0.380
80.15,60.45,0.381
80.16,60.57,0.381
80.17,60.68,0.382
80.19,60.80,0.382
80.20,60.92,0.383
80.21,61.03,0.383
80.22,61.15,0.384
80.23,61.27,0.384
80.24,61.38,0.384
80.25,61.50,0.384
80.27,61.62,0.385
80.28,61.73,0.385
80.29,61.85,0.385
80.30,61.97,0.385
80.31,62.08,0.385
80.33,62.20,0.385
80.34,62.32,0.385
80.35,62.43,0.384
80.36,62.55,0.384
80.37,62.67,0.384
80.38,62.78,0.384
80.40,62.90,0.384
80.41,63.02,0.384
80.42,63.13,0.384
80.43,63.25,0.383
80.44,63.37,0.383
80.45,63.49,0.383
80.46,63.60,0.383
80.48,63.72,0.383
80.49,63.83,0.382
80.50,63.95,0.382
80.51,64.07,0.382
80.52,64.19,0.381
80.54,64.30,0.381
80.55,64.42,0.381
80.56,64.54,0.380
80.57,64.65,0.380
80.58,64.77,0.380
80.59,64.89,0.380
80.60,65.00,0.379
80.62,65.12,0.379
80.63,65.24,0.379
80.64,65.35,0.378
80.65,65.47,0.378
80.66,65.59,0.378
80.68,65.70,0.378
80.69,65.82,0.377
80.70,65.94,0.377
80.71,66.05,0.377
80.72,66.17,0.377
80.73,66.29,0.377
80.75,66.40,0.377
80.76,66.52,0.376
80.77,66.64,0.376
80.78,66.75,0.376
80.79,66.87,0.376
80.80,66.99,0.376
80.81,67.10,0.376
80.83,67.22,0.376
80.84,67.34,0.376
80.85,67.45,0.376
80.86,67.57,0.376
80.87,67.69,0.376
80.89,67.80,0.376
80.90,67.92,0.375
80.91,68.04,0.375
80.92,68.16,0.375
80.93,68.27,0.375
80.94,68.39,0.375
80.95,68.51,0.375
80.97,68.62,0.375
80.98,68.74,0.375
80.99,68.86,0.375
81.00,68.97,0.375
81.01,69.09,0.375
81.03,69.21,0.375
81.04,69.32,0.375
81.05,69.44,0.375
81.06,69.56,0.375
81.07,69.67,0.375
81.08,69.79,0.375
81.10,69.91,0.375
81.11,70.02,0.375
81.12,70.14,0.375
81.13,70.26,0.375
81.14,70.37,0.375
81.15,70.49,0.375
81.16,70.61,0.375
81.18,70.72,0.375
81.19,70.84,0.375
81.20,70.96,0.375
81.21,71.07,0.375
81.22,71.19,0.375
81.24,71.31,0.375
81.25,71.42,0.375
81.26,71.54,0.375
81.27,71.66,0.375
81.28,71.77,0.375
81.29,71.89,0.375
81.30,72.01,0.375
81.32,72.13,0.375
81.33,72.24,0.375
81.34,72.36,0.375
81.35,72.47,0.375
81.36,72.59,0.375
81.38,72.71,0.375
81.39,72.83,0.375
81.40,72.94,0.375
81.41,73.06,0.375
81.42,73.17,0.375
81.43,73.29,0.375
81.45,73.41,0.375
81.46,73.53,0.375
81.47,73.64,0.375
81.48,73.76,0.375
81.49,73.88,0.375
81.50,73.99,0.375
81.51,74.11,0.375
81.53,74.23,0.375
81.54,74.34,0.375
81.55,74.46,0.375
81.56,74.58,0.375
81.57,74.69,0.375
81.59,74.81,0.376
81.60,74.93,0.375
81.61,75.04,0.376
81.62,75.16,0.376
81.63,75.28,0.376
81.64,75.39,0.376
81.65,75.51,0.376
81.67,75.63,0.376
81.68,75.74,0.376
81.69,75.86,0.376
81.70,75.98,0.376
81.71,76.09,0.376
81.73,76.21,0.376
81.74,76.33,0.376
81.75,76.44,0.376
81.76,76.56,0.376
81.77,76.68,0.377
81.78,76.80,0.376
81.80,76.91,0.376
81.81,77.03,0.377
81.82,77.14,0.377
81.83,77.26,0.377
81.84,77.38,0.377
81.85,77.50,0.377
81.86,77.61,0.377
81.88,77.73,0.377
81.89,77.85,0.377
81.90,77.96,0.377
81.91,78.08,0.377
81.92,78.20,0.377
81.94,78.31,0.377
81.95,78.43,0.377
81.96,78.55,0.377
81.97,78.66,0.377
81.98,78.78,0.377
81.99,78.90,0.377
82.00,79.01,0.377
82.02,79.13,0.378
82.03,79.25,0.378
82.04,79.37,0.378
82.05,79.48,0.378
82.06,79.60,0.378
82.08,79.71,0.378
82.09,79.83,0.378
82.10,79.95,0.378
82.11,80.07,0.378
82.12,80.18,0.378
82.13,80.30,0.378
82.15,80.42,0.378
82.16,80.53,0.378
82.17,80.65,0.378
82.18,80.77,0.378
82.19,80.88,0.378
82.20,81.00,0.378
82.21,81.12,0.378
82.23,81.23,0.378
82.24,81.35,0.378
82.25,81.47,0.378
82.26,81.58,0.378
82.27,81.70,0.378
82.29,81.81,0.378
82.30,81.93,0.378
82.31,82.05,0.379
82.32,82.17,0.379
82.33,82.28,0.379
82.34,82.40,0.379
82.35,82.52,0.379
82.37,82.63,0.379
82.38,82.75,0.379
82.39,82.87,0.379
82.40,82.99,0.379
82.41,83.10,0.379
82.43,83.22,0.379
82.44,83.34,0.379
82.45,83.45,0.379
82.46,83.57,0.379
82.47,83.69,0.379
82.48,83.80,0.379
82.50,83.92,0.379
82.51,84.03,0.379
82.52,84.15,0.379
82.53,84.27,0.379
82.54,84.39,0.379
82.55,84.50,0.379
82.56,84.62,0.379
82.58,84.74,0.379
82.59,84.85,0.379
82.60,84.97,0.379
82.61,85.09,0.379
82.62,85.20,0.380
82.64,85.32,0.380
82.65,85.44,0.380
82.66,85.55,0.380
82.67,85.67,0.380
82.68,85.79,0.380
82.69,85.90,0.380
82.70,86.02,0.380
82.72,86.14,0.380
82.73,86.25,0.380
82.74,86.37,0.380
82.75,86.49,0.380
82.76,86.61,0.380
82.78,86.72,0.381
82.79,86.84,0.381
82.80,86.95,0.381
82.81,87.07,0.381
82.82,87.19,0.381
82.83,87.30,0.381
82.85,87.42,0.381
82.86,87.54,0.381
82.87,87.65,0.381
82.88,87.77,0.381
82.89,87.89,0.381
82.90,88.00,0.381
82.91,88.12,0.381
82.93,88.24,0.381
82.94,88.35,0.381
82.95,88.47,0.381
82.96,88.59,0.381
82.97,88.70,0.381
82.99,88.82,0.381
83.00,88.94,0.381
83.01,89.05,0.381
83.02,89.17,0.381
83.03,89.29,0.382
83.04,89.40,0.382
83.05,89.52,0.382
83.07,89.64,0.382
83.08,89.76,0.382
83.09,89.87,0.382
83.10,89.99,0.382
83.11,90.11,0.383
83.13,90.22,0.383
83.14,90.34,0.383
83.15,90.46,0.383
83.16,90.58,0.383
83.17,90.69,0.383
83.18,90.81,0.383
83.20,90.92,0.383
83.21,91.04,0.383
83.22,91.16,0.383
83.23,91.27,0.383
83.24,91.39,0.383
83.25,91.51,0.383
83.26,91.62,0.384
83.28,91.74,0.383
83.29,91.86,0.383
83.30,91.97,0.384
83.31,92.09,0.384
83.32,92.21,0.384
83.34,92.32,0.384
83.35,92.44,0.384
83.36,92.56,0.384
83.37,92.67,0.384
83.38,92.79,0.384
83.39,92.91,0.384
83.40,93.02,0.384
83.42,93.14,0.385
83.43,93.26,0.385
83.44,93.37,0.385
83.45,93.49,0.385
83.46,93.61,0.385
83.48,93.72,0.385
83.49,93.84,0.385
83.50,93.96,0.385
83.51,94.08,0.385
83.52,94.19,0.385
83.53,94.31,0.385
83.55,94.43,0.385
83.56,94.54,0.385
83.57,94.66,0.386
83.58,94.78,0.386
83.59,94.89,0.386
83.60,95.01,0.386
83.61,95.13,0.386
83.63,95.24,0.386
83.64,95.36,0.386
83.65,95.48,0.386
83.66,95.59,0.386
83.67,95.71,0.386
83.69,95.83,0.386
83.70,95.94,0.386
83.71,96.06,0.386
83.72,96.18,0.386
83.73,96.29,0.387
83.74,96.41,0.387
83.75,96.53,0.387
83.77,96.64,0.387
83.78,96.76,0.387
83.79,96.88,0.387
83.80,96.99,0.387
83.81,97.11,0.387
83.83,97.23,0.387
83.84,97.35,0.387
83.85,97.46,0.387
83.86,97.58,0.387
83.87,97.69,0.387
83.88,97.81,0.387
83.90,97.93,0.387
83.91,98.04,0.387
83.92,98.16,0.387
83.93,98.28,0.388
83.94,98.39,
83.95,98.51,
83.96,98.63,
83.98,98.75,
83.99,,
83.99,,