File: DSC/2025_06_27_CBD_2PA_n60_150_10C_min_x4.csv
Filename,2025_06_27_CBD_2PA_n60_150_10C_min_x4
Instrument name,DSC2A-00468 (192.168.1.100)
Operator,Gibbons
rundate,6/27/2025
Sample name,2025_06_27_CBD_2PA_n60_150_10C_min_x4
proceduresegments,Data Off ; Equilibrate -60.00 °C; Data On ; Ramp 10.00 °C/min to 150.00 °C; Data Off ; Isothermal 2.0 min; Data On ; Ramp 10.00 °C/min to -60.00 °C; Data Off ; Isothermal 2.0 min; Data On ; Ramp 10.00 °C/min to 150.00 °C; Data Off ; Isothermal 2.0 min; Data On ; Ramp 10.00 °C/min to -60.00 °C; Data Off ; Isothermal 2.0 min; Data On ; Ramp 10.00 °C/min to 150.00 °C; Data Off ; Isothermal 2.0 min; Data On ; Ramp 10.00 °C/min to -60.00 °C; Data Off ; Isothermal 2.0 min; Data On ; Ramp 10.00 °C/min to 30.00 °C
[File Parameters]
Run date,6/27/2025 4:02:13 PM
Trios version,5.1.1.46572
Original File Name,
Current File Name,D:\DSC2500\Gibbons\2025_06_27_CBD_2PA_n60_150_10C_min_x4.tri
[Procedure]
Procedure Name,CBD_PA_n60_150C_10Cmin_x4
Sample Name,2025_06_27_CBD_2PA_n60_150_10C_min_x4
Sample Mass,6.99 mg
Reference Sample Mass,0 mg
Pan Mass,56.6 mg
Pan Number,20
Reference Pan Mass,56.76 mg
Reference Pan Number,10
Pan Type,Tzero Aluminum Hermetic
Comments,Al Hermetic DSC Consumables sealed Pan/Lid. Y1 Tray (Google Sheet: DSC_Samples_Y1_Tray_June2025)
Project Name,CA
Operator,Gibbons
Test,Custom
Unload Max Temperature,30
Unload Min Temperature,30
Load Max Temperature,30
Load Min Temperature,30
Stop on Gas Flow Error,Yes
[Signal List]
Signal #1,Time (min)
Signal #2,Temperature (°C)
Signal #3,Heat Flow (mW)
Signal #4,Delta T (µV)
Signal #5,Delta Tzero (µV)
Signal #6,Tzero Temperature (°C)
Signal #7,Cell Purge (mL/min)
Signal #8,Heater Temp (°C)
Signal #9,Power Delivered (W)
Signal #10,Reference Junction Temperature (°C)
Signal #11,Flange Temperature (°C)
Signal #12,Heat Flow Phase (rad)
Signal #13,Total Heat Capacity (J/°C)
Signal #14,Heat Capacity (J/°C)
[Configuration]
Company Name,ASU
Instrument Name,DSC2A-00468
Instrument Type,DSC2500
Serial Number,DSC2A-00468
IP,192.168.1.100
Location of Instrument,MRRC
DisplayType,Unknown
Sample Interval ,0.1 s/pt
Selected Heat Flow,T4P
Exotherm Direction,Down
Cell Serial,DRC2-00792
Lid Type,Standard
Cooler,RCS 90
Leave Cooler on at End of Sequence,On
Gas 2,Nitrogen
Gas Selected,Channel 1
Flow Rate,50 mL/min
Secondary Purge,On
Licensed Heat Flow,Heat Flow T4P
Modulation Licensed,Yes
[Versions]
Common IDD Version,1
Cortex Version,VER 2.10.2.31
Driver,5.0.0.6
GDM Version,1.0.3.3
TouchscreenVersion,1.0.0.16145
FEP Version,1.2.1.21
FEP Bootloader,2.0.0.5
AutoSampler Version,2.1.1.26
Auto Sampler Bootloader,2.0.0.5
FCM Version,1.1.0.3
FCM Bootloader,2.0.0.5
[Experiment Logs]
Experiment Log Entry # 1,Data On set to 0
Experiment Log Entry # 3,Equilibrate Segment -60 (C) Started
Experiment Log Entry # 5,Air Cool is off.
Experiment Log Entry # 7,Data On set to 1
Experiment Log Entry # 9,Ramp Segment 10 C/min to 150 Started
Experiment Log Entry # 11,Data On set to 0
Experiment Log Entry # 13,Isothermal Segment 2 min started
Experiment Log Entry # 15,Data On set to 1
Experiment Log Entry # 17,Ramp Segment 10 C/min to -60 Started
Experiment Log Entry # 19,Data On set to 0
Experiment Log Entry # 21,Isothermal Segment 2 min started
Experiment Log Entry # 23,Data On set to 1
Experiment Log Entry # 25,Ramp Segment 10 C/min to 150 Started
Experiment Log Entry # 27,Data On set to 0
Experiment Log Entry # 29,Isothermal Segment 2 min started
Experiment Log Entry # 31,Data On set to 1
Experiment Log Entry # 33,Ramp Segment 10 C/min to -60 Started
Experiment Log Entry # 35,Data On set to 0
Experiment Log Entry # 37,Isothermal Segment 2 min started
Experiment Log Entry # 39,Data On set to 1
Experiment Log Entry # 41,Ramp Segment 10 C/min to 150 Started
Experiment Log Entry # 43,Data On set to 0
Experiment Log Entry # 45,Isothermal Segment 2 min started
Experiment Log Entry # 47,Data On set to 1
Experiment Log Entry # 49,Ramp Segment 10 C/min to -60 Started
Experiment Log Entry # 51,Data On set to 0
Experiment Log Entry # 53,Isothermal Segment 2 min started
Experiment Log Entry # 55,Data On set to 1
Experiment Log Entry # 57,Ramp Segment 10 C/min to 30 Started
[Method Log]
Method Log Entry # 1,Data Off
Method Log Entry # 2,Equilibrate -60 °C
Method Log Entry # 3,Data On
Method Log Entry # 4,(Ramp 443728) Ramp 10 °C/minute to 150 °C
Method Log Entry # 5,Data Off
Method Log Entry # 6,Isothermal 2 minutes
Method Log Entry # 7,Data On
Method Log Entry # 8,(Ramp 443732) Ramp 10 °C/minute to -60 °C
Method Log Entry # 9,Data Off
Method Log Entry # 10,Isothermal 2 minutes
Method Log Entry # 11,Data On
Method Log Entry # 12,(Ramp 443736) Ramp 10 °C/minute to 150 °C
Method Log Entry # 13,Data Off
Method Log Entry # 14,Isothermal 2 minutes
Method Log Entry # 15,Data On
Method Log Entry # 16,(Ramp 443740) Ramp 10 °C/minute to -60 °C
Method Log Entry # 17,Data Off
Method Log Entry # 18,Isothermal 2 minutes
Method Log Entry # 19,Data On
Method Log Entry # 20,(Ramp 443744) Ramp 10 °C/minute to 150 °C
Method Log Entry # 21,Data Off
Method Log Entry # 22,Isothermal 2 minutes
Method Log Entry # 23,Data On
Method Log Entry # 24,(Ramp 443748) Ramp 10 °C/minute to -60 °C
Method Log Entry # 25,Data Off
Method Log Entry # 26,Isothermal 2 minutes
Method Log Entry # 27,Data On
Method Log Entry # 28,(Ramp 443752) Ramp 10 °C/minute to 30 °C
Cell Serial,DRC2-00792
[T1 Calibration]
Slope,-0.008529666
Offset,9.636258
Initial Temperature,98.23
GUID,f8bfdadc-4977-4fdf-ba6d-0ba9134940c3
[TZero Calibration]
Date Applied,11/29/2022 4:06:13 PM
Description,From -89.059 °C to 396.009 °C at 20.000°C/min
Gas Type,Nitrogen
Pan Type,None
Source Files 1,C:\Users\yargerlab\Desktop\DSC Data\General\TZero_calibration_11_29_22_2nd(2).tri
Source Files 2,C:\Users\yargerlab\Desktop\DSC Data\General\TZero_calibration_11_29_22_2nd(3).tri
Delta T Offset,13.05235
Delta T Slope,-0.007271007
Delta T0 Offset,-13.69128
Delta T0 Slope,0.06063341
[Temperature Calibration]
Date Applied,11/29/2022 7:12:28 PM
Description,From 106.590 °C to 186.590 °C at 10.000°C/min
Gas Type,Nitrogen
Pan Type,Tzero Aluminum Hermetic
Source Files 1,C:\Users\yargerlab\Desktop\DSC Data\General\Indium(6).tri
Measured 1,157.391
Known 1,156.598
[Cell Constant Calibration]
Date Applied,11/29/2022 7:12:29 PM
Description,From 106.590 °C to 186.590 °C at 10.000°C/min
Gas Type,Nitrogen
Pan Type,Tzero Aluminum Hermetic
Source Files 1,C:\Users\yargerlab\Desktop\DSC Data\General\Indium(6).tri
T4P KCell,1.006051
Onset Slope,63.26126 mW/°C
[Direct Cp Calibration]
Date Applied,11/30/2022 11:04:51 AM
Description,From -79.983 °C to 298.409 °C at 10.000°C/min
Gas Type,Nitrogen
Pan Type,Tzero Aluminum Hermetic
Source Files 1,C:\Users\yargerlab\Desktop\DSC Data\General\Sapphire_Heat_Capacity_11_30_22.tri
[Rev Cp Calibration]
Date Applied,11/30/2022 1:58:51 PM
Description,From -79.996 °C to 292.812 °C at 3.000°C/min
Gas Type,Nitrogen
Pan Type,Tzero Aluminum Hermetic
Source Files 1,C:\Users\yargerlab\Desktop\DSC Data\General\Sapphire_MDSC_Calibration_11_30_22.tri
[step]
Ramp 10.00 °C/min to 150.00 °C
Time,Temperature,Heat Flow (Normalized)
min,°C,W/g
0.00,-59.68,-0.052
0.01,-59.69,-0.051
0.03,-59.70,-0.048
0.05,-59.70,-0.044
0.06,-59.70,-0.041
0.08,-59.68,-0.040
0.09,-59.65,-0.038
0.11,-59.61,-0.035
0.12,-59.55,-0.030
0.14,-59.48,-0.023
0.15,-59.40,-0.013
0.16,-59.31,-0.002
0.18,-59.22,0.011
0.19,-59.11,0.024
0.21,-59.00,0.036
0.23,-58.89,0.051
0.24,-58.77,0.062
0.26,-58.65,0.074
0.27,-58.53,0.083
0.29,-58.40,0.094
0.30,-58.27,0.102
0.31,-58.14,0.109
0.33,-58.01,0.116
0.35,-57.88,0.123
0.36,-57.74,0.128
0.38,-57.60,0.134
0.39,-57.47,0.137
0.40,-57.33,0.143
0.42,-57.19,0.144
0.44,-57.05,0.149
0.45,-56.91,0.151
0.46,-56.77,0.154
0.48,-56.63,0.156
0.50,-56.49,0.159
0.51,-56.34,0.160
0.53,-56.20,0.162
0.54,-56.05,0.164
0.55,-55.91,0.166
0.57,-55.77,0.166
0.58,-55.62,0.167
0.60,-55.48,0.168
0.62,-55.33,0.169
0.63,-55.19,0.170
0.65,-55.04,0.171
0.66,-54.89,0.172
0.68,-54.75,0.172
0.69,-54.60,0.173
0.70,-54.46,0.173
0.72,-54.31,0.174
0.73,-54.16,0.175
0.75,-54.01,0.175
0.77,-53.87,0.176
0.78,-53.72,0.176
0.80,-53.57,0.176
0.81,-53.42,0.176
0.83,-53.28,0.176
0.84,-53.13,0.177
0.85,-52.98,0.177
0.87,-52.83,0.177
0.88,-52.69,0.178
0.90,-52.54,0.178
0.92,-52.39,0.178
0.93,-52.24,0.179
0.95,-52.09,0.179
0.96,-51.94,0.179
0.98,-51.80,0.179
0.99,-51.65,0.179
1.00,-51.50,0.180
1.02,-51.35,0.180
1.03,-51.20,0.180
1.05,-51.05,0.180
1.07,-50.90,0.180
1.08,-50.76,0.180
1.09,-50.61,0.181
1.11,-50.46,0.181
1.13,-50.31,0.181
1.14,-50.16,0.181
1.16,-50.01,0.181
1.17,-49.86,0.182
1.18,-49.71,0.182
1.20,-49.56,0.182
1.22,-49.41,0.182
1.23,-49.26,0.182
1.24,-49.11,0.182
1.26,-48.96,0.183
1.28,-48.82,0.183
1.29,-48.67,0.183
1.31,-48.52,0.183
1.32,-48.37,0.183
1.33,-48.22,0.183
1.35,-48.07,0.183
1.37,-47.92,0.184
1.38,-47.77,0.184
1.39,-47.62,0.184
1.41,-47.47,0.184
1.43,-47.32,0.184
1.44,-47.17,0.184
1.46,-47.02,0.184
1.47,-46.87,0.184
1.48,-46.72,0.185
1.50,-46.57,0.185
1.52,-46.42,0.185
1.53,-46.27,0.185
1.54,-46.12,0.185
1.56,-45.97,0.185
1.58,-45.82,0.185
1.59,-45.67,0.185
1.61,-45.52,0.185
1.62,-45.37,0.186
1.63,-45.22,0.186
1.65,-45.07,0.186
1.67,-44.92,0.186
1.68,-44.77,0.186
1.69,-44.62,0.186
1.71,-44.47,0.186
1.73,-44.32,0.186
1.74,-44.17,0.186
1.76,-44.02,0.186
1.77,-43.87,0.187
1.78,-43.72,0.187
1.80,-43.57,0.187
1.82,-43.42,0.187
1.83,-43.27,0.187
1.84,-43.12,0.187
1.86,-42.97,0.187
1.88,-42.82,0.187
1.89,-42.67,0.187
1.91,-42.52,0.187
1.92,-42.37,0.187
1.93,-42.22,0.187
1.95,-42.07,0.187
1.97,-41.92,0.187
1.98,-41.77,0.187
1.99,-41.62,0.188
2.01,-41.47,0.188
2.03,-41.32,0.188
2.04,-41.17,0.188
2.06,-41.02,0.188
2.07,-40.87,0.188
2.08,-40.72,0.188
2.10,-40.57,0.188
2.12,-40.42,0.188
2.13,-40.27,0.188
2.14,-40.12,0.188
2.16,-39.97,0.188
2.18,-39.82,0.188
2.19,-39.67,0.188
2.21,-39.52,0.188
2.22,-39.37,0.188
2.24,-39.22,0.189
2.25,-39.07,0.189
2.26,-38.92,0.189
2.28,-38.77,0.189
2.29,-38.62,0.189
2.31,-38.47,0.189
2.33,-38.32,0.189
2.34,-38.17,0.189
2.36,-38.02,0.189
2.37,-37.87,0.189
2.39,-37.72,0.189
2.40,-37.56,0.189
2.41,-37.42,0.189
2.43,-37.26,0.189
2.44,-37.11,0.189
2.46,-36.96,0.190
2.48,-36.81,0.190
2.49,-36.66,0.190
2.51,-36.51,0.190
2.52,-36.36,0.190
2.54,-36.21,0.190
2.55,-36.06,0.190
2.56,-35.91,0.190
2.58,-35.76,0.190
2.59,-35.61,0.190
2.61,-35.46,0.190
2.63,-35.31,0.190
2.64,-35.16,0.190
2.66,-35.01,0.190
2.67,-34.86,0.190
2.69,-34.71,0.191
2.70,-34.56,0.191
2.71,-34.41,0.191
2.73,-34.26,0.191
2.74,-34.11,0.191
2.76,-33.96,0.191
2.78,-33.81,0.191
2.79,-33.66,0.191
2.81,-33.51,0.191
2.82,-33.36,0.191
2.84,-33.21,0.191
2.85,-33.06,0.191
2.86,-32.91,0.191
2.88,-32.76,0.191
2.89,-32.61,0.191
2.91,-32.46,0.192
2.93,-32.31,0.192
2.94,-32.16,0.192
2.96,-32.01,0.192
2.97,-31.86,0.192
2.99,-31.71,0.192
3.00,-31.56,0.192
3.01,-31.41,0.192
3.03,-31.26,0.192
3.04,-31.11,0.192
3.06,-30.95,0.192
3.08,-30.81,0.192
3.09,-30.65,0.192
3.11,-30.51,0.192
3.12,-30.35,0.192
3.14,-30.20,0.193
3.15,-30.06,0.193
3.16,-29.90,0.193
3.18,-29.75,0.193
3.19,-29.60,0.193
3.21,-29.45,0.193
3.23,-29.30,0.193
3.24,-29.15,0.193
3.26,-29.00,0.193
3.27,-28.85,0.193
3.29,-28.70,0.193
3.30,-28.55,0.193
3.31,-28.40,0.193
3.33,-28.25,0.193
3.34,-28.10,0.193
3.36,-27.95,0.193
3.38,-27.80,0.193
3.39,-27.65,0.194
3.41,-27.50,0.194
3.42,-27.35,0.194
3.44,-27.20,0.194
3.45,-27.05,0.194
3.46,-26.90,0.194
3.48,-26.75,0.194
3.49,-26.60,0.194
3.51,-26.45,0.194
3.53,-26.30,0.194
3.54,-26.15,0.194
3.56,-26.00,0.194
3.57,-25.85,0.194
3.59,-25.70,0.194
3.60,-25.55,0.194
3.61,-25.40,0.194
3.63,-25.25,0.194
3.64,-25.10,0.195
3.66,-24.95,0.195
3.68,-24.80,0.195
3.69,-24.65,0.195
3.71,-24.50,0.195
3.72,-24.35,0.195
3.74,-24.20,0.195
3.75,-24.05,0.195
3.76,-23.90,0.195
3.78,-23.75,0.195
3.79,-23.60,0.195
3.81,-23.45,0.195
3.83,-23.30,0.195
3.84,-23.15,0.195
3.86,-23.00,0.196
3.87,-22.84,0.196
3.89,-22.69,0.196
3.90,-22.55,0.196
3.91,-22.39,0.196
3.93,-22.24,0.196
3.94,-22.09,0.196
3.96,-21.95,0.196
3.98,-21.79,0.196
3.99,-21.64,0.196
4.01,-21.49,0.196
4.02,-21.34,0.196
4.04,-21.19,0.196
4.05,-21.04,0.196
4.06,-20.89,0.196
4.08,-20.74,0.197
4.09,-20.59,0.197
4.11,-20.44,0.197
4.13,-20.29,0.197
4.14,-20.14,0.197
4.16,-19.99,0.197
4.17,-19.84,0.197
4.19,-19.69,0.197
4.20,-19.54,0.197
4.21,-19.39,0.197
4.23,-19.24,0.197
4.24,-19.09,0.197
4.26,-18.94,0.197
4.28,-18.79,0.197
4.29,-18.64,0.197
4.30,-18.49,0.198
4.32,-18.34,0.198
4.34,-18.19,0.198
4.35,-18.04,0.198
4.36,-17.89,0.198
4.38,-17.74,0.198
4.40,-17.59,0.198
4.41,-17.44,0.198
4.43,-17.29,0.198
4.44,-17.14,0.198
4.45,-16.99,0.198
4.47,-16.84,0.198
4.49,-16.69,0.199
4.50,-16.54,0.199
4.51,-16.39,0.199
4.53,-16.24,0.199
4.55,-16.09,0.199
4.56,-15.93,0.199
4.58,-15.79,0.199
4.59,-15.64,0.199
4.60,-15.49,0.199
4.62,-15.33,0.199
4.64,-15.18,0.199
4.65,-15.03,0.199
4.66,-14.88,0.199
4.68,-14.73,0.199
4.70,-14.58,0.199
4.71,-14.43,0.199
4.73,-14.28,0.200
4.74,-14.13,0.200
4.75,-13.98,0.200
4.77,-13.83,0.200
4.79,-13.68,0.200
4.80,-13.53,0.200
4.81,-13.38,0.200
4.83,-13.23,0.200
4.85,-13.08,0.200
4.86,-12.93,0.200
4.88,-12.78,0.200
4.89,-12.63,0.200
4.90,-12.48,0.200
4.92,-12.33,0.200
4.94,-12.18,0.200
4.95,-12.03,0.201
4.96,-11.88,0.201
4.98,-11.73,0.201
5.00,-11.58,0.201
5.01,-11.43,0.201
5.03,-11.28,0.201
5.04,-11.13,0.201
5.05,-10.98,0.201
5.07,-10.83,0.201
5.09,-10.68,0.201
5.10,-10.53,0.201
5.11,-10.38,0.201
5.13,-10.23,0.201
5.15,-10.08,0.201
5.16,-9.93,0.202
5.18,-9.78,0.202
5.19,-9.63,0.202
5.20,-9.48,0.202
5.22,-9.33,0.202
5.24,-9.18,0.202
5.25,-9.03,0.202
5.26,-8.88,0.202
5.28,-8.73,0.202
5.30,-8.58,0.202
5.31,-8.43,0.202
5.33,-8.28,0.202
5.34,-8.13,0.203
5.35,-7.98,0.203
5.37,-7.83,0.203
5.39,-7.68,0.203
5.40,-7.53,0.203
5.41,-7.37,0.203
5.43,-7.23,0.203
5.45,-7.07,0.203
5.46,-6.92,0.203
5.48,-6.77,0.203
5.49,-6.62,0.204
5.50,-6.47,0.204
5.52,-6.32,0.204
5.54,-6.17,0.204
5.55,-6.02,0.204
5.56,-5.87,0.204
5.58,-5.72,0.204
5.60,-5.57,0.204
5.61,-5.42,0.204
5.63,-5.27,0.204
5.64,-5.12,0.204
5.65,-4.97,0.205
5.67,-4.82,0.205
5.69,-4.67,0.205
5.70,-4.52,0.205
5.71,-4.37,0.205
5.73,-4.22,0.205
5.75,-4.07,0.205
5.76,-3.92,0.205
5.78,-3.77,0.205
5.79,-3.62,0.205
5.80,-3.47,0.205
5.82,-3.32,0.205
5.84,-3.17,0.206
5.85,-3.02,0.206
5.86,-2.87,0.206
5.88,-2.72,0.206
5.90,-2.57,0.206
5.91,-2.42,0.206
5.93,-2.27,0.206
5.94,-2.12,0.206
5.95,-1.97,0.206
5.97,-1.82,0.206
5.99,-1.67,0.206
6.00,-1.52,0.206
6.01,-1.37,0.207
6.03,-1.22,0.207
6.05,-1.07,0.207
6.06,-0.92,0.207
6.08,-0.77,0.207
6.09,-0.62,0.207
6.10,-0.47,0.207
6.12,-0.32,0.207
6.14,-0.17,0.207
6.15,-0.02,0.207
6.16,0.13,0.207
6.18,0.29,0.207
6.20,0.43,0.208
6.21,0.59,0.208
6.23,0.74,0.208
6.24,0.89,0.208
6.25,1.03,0.208
6.27,1.19,0.208
6.29,1.34,0.208
6.30,1.49,0.208
6.31,1.64,0.208
6.33,1.79,0.208
6.35,1.94,0.209
6.36,2.09,0.209
6.38,2.24,0.209
6.39,2.39,0.209
6.40,2.54,0.209
6.42,2.69,0.209
6.44,2.84,0.209
6.45,2.99,0.209
6.46,3.14,0.209
6.48,3.29,0.209
6.50,3.44,0.209
6.51,3.59,0.209
6.53,3.74,0.210
6.54,3.89,0.210
6.55,4.04,0.210
6.57,4.19,0.210
6.59,4.34,0.210
6.60,4.49,0.210
6.61,4.64,0.210
6.63,4.79,0.210
6.65,4.94,0.210
6.66,5.09,0.210
6.68,5.24,0.211
6.69,5.39,0.211
6.70,5.54,0.211
6.72,5.69,0.211
6.74,5.84,0.211
6.75,5.99,0.211
6.76,6.14,0.211
6.78,6.29,0.211
6.80,6.44,0.211
6.81,6.59,0.211
6.83,6.74,0.212
6.84,6.89,0.212
6.85,7.04,0.212
6.87,7.19,0.212
6.89,7.34,0.212
6.90,7.49,0.212
6.91,7.64,0.212
6.93,7.79,0.212
6.95,7.94,0.212
6.96,8.09,0.212
6.98,8.24,0.213
6.99,8.39,0.213
7.00,8.54,0.213
7.02,8.69,0.213
7.04,8.85,0.213
7.05,8.99,0.213
7.06,9.14,0.213
7.08,9.30,0.213
7.10,9.45,0.213
7.11,9.60,0.213
7.13,9.75,0.214
7.14,9.90,0.214
7.15,10.05,0.214
7.17,10.20,0.214
7.19,10.35,0.214
7.20,10.50,0.214
7.21,10.65,0.214
7.23,10.80,0.214
7.25,10.95,0.214
7.26,11.10,0.214
7.28,11.25,0.214
7.29,11.40,0.215
7.30,11.55,0.215
7.32,11.70,0.215
7.34,11.85,0.215
7.35,12.00,0.215
7.36,12.15,0.215
7.38,12.30,0.215
7.40,12.45,0.215
7.41,12.60,0.215
7.43,12.75,0.215
7.44,12.90,0.216
7.45,13.05,0.216
7.47,13.20,0.216
7.49,13.35,0.216
7.50,13.50,0.216
7.51,13.65,0.216
7.53,13.80,0.216
7.55,13.95,0.216
7.56,14.10,0.216
7.58,14.25,0.216
7.59,14.40,0.216
7.60,14.55,0.217
7.62,14.70,0.217
7.64,14.85,0.217
7.65,15.00,0.217
7.66,15.15,0.217
7.68,15.30,0.217
7.70,15.45,0.217
7.71,15.60,0.217
7.73,15.75,0.217
7.74,15.90,0.217
7.75,16.05,0.218
7.77,16.20,0.218
7.79,16.35,0.218
7.80,16.50,0.218
7.81,16.65,0.218
7.83,16.80,0.218
7.85,16.95,0.218
7.86,17.10,0.218
7.88,17.25,0.218
7.89,17.40,0.218
7.90,17.55,0.219
7.92,17.70,0.219
7.94,17.85,0.219
7.95,18.00,0.219
7.96,18.15,0.219
7.98,18.30,0.219
8.00,18.45,0.219
8.01,18.60,0.219
8.03,18.75,0.219
8.04,18.90,0.219
8.05,19.05,0.220
8.07,19.20,0.220
8.09,19.35,0.220
8.10,19.50,0.220
8.11,19.65,0.220
8.13,19.80,0.220
8.15,19.95,0.220
8.16,20.11,0.220
8.18,20.25,0.220
8.19,20.41,0.220
8.20,20.56,0.221
8.22,20.71,0.221
8.24,20.86,0.221
8.25,21.01,0.221
8.26,21.16,0.221
8.28,21.31,0.221
8.30,21.46,0.221
8.31,21.61,0.221
8.33,21.76,0.221
8.34,21.91,0.222
8.35,22.06,0.222
8.37,22.21,0.222
8.39,22.36,0.222
8.40,22.51,0.222
8.41,22.66,0.222
8.43,22.81,0.222
8.45,22.96,0.222
8.46,23.11,0.223
8.48,23.26,0.223
8.49,23.41,0.223
8.50,23.56,0.223
8.52,23.71,0.223
8.53,23.86,0.223
8.55,24.01,0.223
8.57,24.16,0.223
8.58,24.31,0.223
8.60,24.46,0.224
8.61,24.61,0.224
8.63,24.76,0.224
8.64,24.91,0.224
8.65,25.06,0.224
8.67,25.21,0.224
8.68,25.36,0.224
8.70,25.51,0.224
8.72,25.66,0.224
8.73,25.81,0.224
8.75,25.96,0.225
8.76,26.11,0.225
8.78,26.26,0.225
8.79,26.41,0.225
8.80,26.56,0.225
8.82,26.71,0.225
8.83,26.86,0.225
8.85,27.01,0.225
8.87,27.16,0.225
8.88,27.31,0.226
8.90,27.46,0.226
8.91,27.61,0.226
8.93,27.76,0.226
8.94,27.91,0.226
8.95,28.06,0.226
8.97,28.21,0.226
8.98,28.36,0.226
9.00,28.52,0.227
9.02,28.66,0.227
9.03,28.81,0.227
9.05,28.96,0.227
9.06,29.12,0.227
9.08,29.27,0.227
9.09,29.42,0.227
9.10,29.57,0.227
9.12,29.72,0.227
9.13,29.87,0.228
9.15,30.02,0.228
9.17,30.17,0.228
9.18,30.32,0.228
9.20,30.47,0.228
9.21,30.62,0.228
9.23,30.77,0.228
9.24,30.92,0.228
9.25,31.07,0.228
9.27,31.22,0.229
9.28,31.37,0.229
9.30,31.52,0.229
9.32,31.67,0.229
9.33,31.82,0.229
9.35,31.97,0.229
9.36,32.12,0.229
9.38,32.27,0.229
9.39,32.42,0.230
9.40,32.57,0.230
9.42,32.72,0.230
9.43,32.87,0.230
9.45,33.02,0.230
9.47,33.17,0.230
9.48,33.32,0.230
9.50,33.47,0.230
9.51,33.62,0.230
9.53,33.77,0.231
9.54,33.92,0.231
9.55,34.07,0.231
9.57,34.22,0.231
9.58,34.37,0.231
9.60,34.52,0.231
9.62,34.67,0.231
9.63,34.82,0.231
9.65,34.97,0.232
9.66,35.12,0.232
9.68,35.27,0.232
9.69,35.42,0.232
9.70,35.57,0.232
9.72,35.72,0.232
9.73,35.87,0.232
9.75,36.02,0.232
9.77,36.17,0.232
9.78,36.32,0.233
9.80,36.47,0.233
9.81,36.62,0.233
9.83,36.77,0.233
9.84,36.92,0.233
9.85,37.07,0.233
9.87,37.22,0.233
9.88,37.38,0.233
9.90,37.53,0.234
9.92,37.67,0.234
9.93,37.83,0.234
9.95,37.97,0.234
9.96,38.13,0.234
9.98,38.28,0.234
9.99,38.43,0.234
10.00,38.58,0.234
10.02,38.73,0.235
10.03,38.88,0.235
10.05,39.03,0.235
10.07,39.18,0.235
10.08,39.33,0.235
10.10,39.48,0.235
10.11,39.63,0.235
10.13,39.78,0.235
10.14,39.93,0.236
10.15,40.08,0.236
10.17,40.23,0.236
10.18,40.38,0.236
10.20,40.53,0.236
10.22,40.68,0.236
10.23,40.83,0.236
10.25,40.98,0.237
10.26,41.13,0.237
10.28,41.28,0.237
10.29,41.43,0.237
10.30,41.58,0.237
10.32,41.73,0.237
10.33,41.88,0.237
10.35,42.03,0.238
10.37,42.18,0.238
10.38,42.33,0.238
10.40,42.48,0.238
10.41,42.63,0.238
10.43,42.78,0.238
10.44,42.93,0.239
10.45,43.08,0.239
10.47,43.23,0.239
10.48,43.38,0.239
10.50,43.53,0.239
10.52,43.68,0.239
10.53,43.83,0.240
10.55,43.98,0.240
10.56,44.13,0.240
10.58,44.28,0.240
10.59,44.43,0.240
10.60,44.58,0.241
10.62,44.73,0.241
10.63,44.88,0.241
10.65,45.03,0.241
10.67,45.18,0.241
10.68,45.33,0.241
10.70,45.48,0.242
10.71,45.63,0.242
10.73,45.78,0.242
10.74,45.93,0.242
10.75,46.08,0.242
10.77,46.23,0.243
10.78,46.38,0.243
10.80,46.53,0.243
10.82,46.68,0.243
10.83,46.83,0.244
10.85,46.98,0.244
10.86,47.13,0.244
10.88,47.28,0.244
10.89,47.43,0.244
10.90,47.58,0.245
10.92,47.73,0.245
10.93,47.88,0.245
10.95,48.03,0.246
10.97,48.18,0.246
10.98,48.33,0.246
11.00,48.48,0.246
11.01,48.63,0.247
11.03,48.78,0.247
11.04,48.93,0.247
11.05,49.08,0.248
11.07,49.23,0.248
11.08,49.38,0.249
11.10,49.53,0.249
11.12,49.68,0.249
11.13,49.83,0.249
11.15,49.98,0.250
11.16,50.13,0.250
11.18,50.28,0.251
11.19,50.43,0.251
11.20,50.58,0.251
11.22,50.73,0.252
11.23,50.88,0.252
11.25,51.03,0.253
11.27,51.18,0.253
11.28,51.33,0.254
11.30,51.48,0.255
11.31,51.63,0.255
11.33,51.78,0.256
11.34,51.93,0.257
11.35,52.08,0.258
11.37,52.23,0.259
11.38,52.38,0.260
11.40,52.53,0.260
11.42,52.68,0.262
11.43,52.83,0.262
11.45,52.98,0.264
11.46,53.13,0.264
11.48,53.28,0.265
11.49,53.43,0.266
11.50,53.58,0.268
11.52,53.73,0.271
11.53,53.88,0.272
11.55,54.03,0.273
11.57,54.18,0.275
11.58,54.33,0.276
11.60,54.48,0.278
11.61,54.63,0.280
11.63,54.78,0.282
11.64,54.93,0.284
11.65,55.08,0.286
11.67,55.23,0.289
11.68,55.37,0.291
11.70,55.52,0.293
11.72,55.67,0.297
11.73,55.82,0.299
11.75,55.97,0.302
11.76,56.12,0.305
11.78,56.27,0.309
11.79,56.42,0.313
11.80,56.57,0.316
11.82,56.72,0.320
11.83,56.86,0.326
11.85,57.01,0.331
11.87,57.16,0.335
11.88,57.31,0.341
11.90,57.46,0.346
11.91,57.60,0.354
11.93,57.75,0.360
11.94,57.90,0.367
11.95,58.05,0.375
11.97,58.19,0.383
11.98,58.34,0.392
12.00,58.49,0.402
12.02,58.63,0.412
12.03,58.78,0.423
12.05,58.92,0.435
12.06,59.07,0.446
12.08,59.21,0.460
12.09,59.36,0.473
12.10,59.50,0.488
12.12,59.65,0.503
12.13,59.79,0.518
12.15,59.93,0.533
12.17,60.08,0.548
12.18,60.22,0.561
12.20,60.37,0.574
12.21,60.51,0.586
12.23,60.65,0.597
12.24,60.80,0.608
12.25,60.94,0.618
12.27,61.09,0.627
12.28,61.23,0.639
12.30,61.38,0.651
12.32,61.52,0.664
12.33,61.66,0.679
12.35,61.81,0.698
12.36,61.95,0.714
12.38,62.09,0.734
12.39,62.24,0.754
12.40,62.38,0.773
12.42,62.52,0.793
12.43,62.66,0.814
12.45,62.80,0.835
12.47,62.94,0.858
12.48,63.08,0.876
12.50,63.22,0.898
12.51,63.36,0.924
12.53,63.50,0.945
12.54,63.64,0.969
12.55,63.78,0.987
12.57,63.92,1.007
12.58,64.06,1.023
12.60,64.21,1.038
12.62,64.35,1.053
12.63,64.49,1.067
12.65,64.63,1.084
12.66,64.77,1.098
12.68,64.92,1.101
12.69,65.06,1.103
12.70,65.21,1.109
12.72,65.35,1.119
12.73,65.50,1.125
12.75,65.64,1.139
12.77,65.79,1.141
12.78,65.94,1.132
12.80,66.09,1.114
12.81,66.24,1.113
12.83,66.39,1.107
12.84,66.54,1.109
12.85,66.69,1.083
12.87,66.85,1.049
12.88,67.01,1.002
12.90,67.17,0.943
12.92,67.34,0.889
12.93,67.51,0.847
12.95,67.67,0.828
12.96,67.84,0.820
12.98,68.00,0.816
12.99,68.16,0.825
13.00,68.31,0.826
13.02,68.47,0.796
13.03,68.63,0.759
13.05,68.79,0.727
13.07,68.95,0.695
13.08,69.11,0.667
13.10,69.28,0.645
13.11,69.44,0.623
13.13,69.60,0.599
13.14,69.76,0.573
13.15,69.93,0.547
13.17,70.09,0.523
13.18,70.25,0.497
13.20,70.41,0.475
13.22,70.57,0.455
13.23,70.73,0.439
13.25,70.90,0.424
13.26,71.05,0.411
13.28,71.21,0.402
13.29,71.37,0.394
13.30,71.53,0.386
13.32,71.68,0.381
13.33,71.84,0.376
13.35,71.99,0.370
13.37,72.14,0.367
13.38,72.30,0.362
13.40,72.45,0.360
13.41,72.60,0.357
13.43,72.76,0.355
13.44,72.91,0.353
13.45,73.06,0.351
13.47,73.21,0.349
13.48,73.36,0.348
13.50,73.52,0.348
13.52,73.67,0.347
13.53,73.82,0.346
13.55,73.97,0.345
13.56,74.12,0.344
13.58,74.27,0.344
13.59,74.42,0.344
13.60,74.57,0.344
13.62,74.72,0.343
13.63,74.87,0.343
13.65,75.02,0.343
13.67,75.18,0.343
13.68,75.33,0.343
13.70,75.48,0.342
13.71,75.63,0.342
13.73,75.78,0.342
13.74,75.93,0.342
13.75,76.08,0.342
13.77,76.23,0.342
13.78,76.38,0.342
13.80,76.53,0.342
13.82,76.68,0.342
13.83,76.83,0.342
13.85,76.98,0.342
13.86,77.13,0.342
13.88,77.28,0.342
13.89,77.43,0.342
13.90,77.58,0.342
13.92,77.73,0.342
13.93,77.88,0.342
13.95,78.03,0.342
13.97,78.18,0.343
13.98,78.33,0.343
14.00,78.48,0.343
14.01,78.63,0.343
14.03,78.78,0.343
14.04,78.94,0.344
14.05,79.09,0.344
14.07,79.24,0.344
14.08,79.39,0.345
14.10,79.54,0.345
14.12,79.69,0.345
14.13,79.84,0.345
14.15,79.99,0.345
14.16,80.14,0.346
14.18,80.29,0.346
14.19,80.43,0.346
14.20,80.58,0.346
14.22,80.73,0.346
14.23,80.88,0.346
14.25,81.03,0.347
14.27,81.18,0.347
14.28,81.33,0.347
14.30,81.48,0.347
14.31,81.63,0.347
14.33,81.78,0.348
14.34,81.93,0.348
14.35,82.08,0.348
14.37,82.23,0.349
14.38,82.38,0.350
14.40,82.53,0.350
14.42,82.68,0.350
14.43,82.83,0.351
14.45,82.98,0.351
14.46,83.13,0.351
14.48,83.28,0.352
14.49,83.43,0.352
14.50,83.58,0.352
14.52,83.73,0.353
14.53,83.88,0.353
14.55,84.03,0.353
14.57,84.18,0.354
14.58,84.33,0.354
14.60,84.48,0.355
14.61,84.63,0.355
14.63,84.78,0.355
14.64,84.93,0.356
14.65,85.08,0.356
14.67,85.23,0.357
14.68,85.38,0.357
14.70,85.53,0.357
14.72,85.68,0.358
14.73,85.83,0.359
14.75,85.98,0.359
14.76,86.13,0.360
14.78,86.28,0.360
14.79,86.43,0.360
14.80,86.58,0.361
14.82,86.73,0.361
14.83,86.88,0.362
14.85,87.03,0.363
14.87,87.18,0.363
14.88,87.33,0.364
14.90,87.48,0.365
14.91,87.63,0.366
14.93,87.78,0.366
14.94,87.93,0.367
14.95,88.08,0.367
14.97,88.23,0.368
14.98,88.38,0.368
15.00,88.53,0.369
15.02,88.68,0.370
15.03,88.83,0.370
15.05,88.98,0.371
15.06,89.13,0.372
15.08,89.28,0.372
15.09,89.43,0.373
15.10,89.58,0.373
15.12,89.73,0.374
15.13,89.88,0.375
15.15,90.03,0.375
15.17,90.18,0.376
15.18,90.33,0.377
15.20,90.48,0.378
15.21,90.63,0.378
15.23,90.78,0.379
15.24,90.93,0.380
15.25,91.08,0.380
15.27,91.23,0.381
15.28,91.38,0.382
15.30,91.53,0.382
15.32,91.68,0.384
15.33,91.83,0.385
15.35,91.98,0.385
15.36,92.13,0.386
15.38,92.28,0.386
15.39,92.43,0.387
15.40,92.58,0.387
15.42,92.73,0.388
15.43,92.88,0.389
15.45,93.03,0.390
15.47,93.18,0.390
15.48,93.33,0.391
15.50,93.48,0.392
15.51,93.63,0.393
15.53,93.78,0.394
15.54,93.92,0.394
15.55,94.07,0.395
15.57,94.22,0.396
15.58,94.37,0.396
15.60,94.52,0.397
15.62,94.67,0.398
15.63,94.82,0.399
15.65,94.97,0.400
15.66,95.12,0.401
15.68,95.27,0.403
15.69,95.42,0.403
15.70,95.57,0.404
15.72,95.72,0.405
15.73,95.87,0.406
15.75,96.02,0.407
15.77,96.17,0.408
15.78,96.32,0.409
15.80,96.47,0.409
15.81,96.62,0.411
15.83,96.77,0.412
15.84,96.92,0.413
15.85,97.07,0.414
15.87,97.22,0.415
15.88,97.37,0.416
15.90,97.52,0.417
15.92,97.67,0.418
15.93,97.82,0.419
15.95,97.97,0.420
15.96,98.12,0.421
15.98,98.27,0.423
15.99,98.42,0.424
16.00,98.57,0.425
16.02,98.72,0.426
16.03,98.87,0.428
16.05,99.02,0.429
16.07,99.17,0.430
16.08,99.32,0.431
16.10,99.47,0.432
16.11,99.61,0.433
16.13,99.76,0.434
16.14,99.91,0.435
16.15,100.06,0.436
16.17,100.21,0.438
16.18,100.36,0.439
16.20,100.51,0.440
16.22,100.66,0.442
16.23,100.81,0.444
16.25,100.96,0.445
16.26,101.11,0.446
16.28,101.26,0.449
16.29,101.41,0.449
16.30,101.56,0.451
16.32,101.71,0.452
16.33,101.86,0.454
16.35,102.01,0.455
16.37,102.16,0.456
16.38,102.31,0.458
16.40,102.46,0.460
16.41,102.60,0.461
16.43,102.76,0.463
16.44,102.90,0.464
16.45,103.05,0.466
16.47,103.20,0.468
16.48,103.35,0.469
16.50,103.50,0.471
16.52,103.65,0.473
16.53,103.80,0.475
16.55,103.95,0.477
16.56,104.10,0.479
16.58,104.25,0.481
16.59,104.40,0.482
16.60,104.55,0.484
16.62,104.70,0.485
16.63,104.85,0.488
16.65,105.00,0.489
16.67,105.15,0.491
16.68,105.30,0.493
16.70,105.45,0.495
16.71,105.60,0.497
16.73,105.74,0.499
16.74,105.89,0.501
16.75,106.04,0.503
16.77,106.19,0.506
16.78,106.34,0.508
16.80,106.49,0.510
16.82,106.64,0.512
16.83,106.79,0.515
16.85,106.94,0.516
16.86,107.09,0.519
16.88,107.24,0.521
16.89,107.39,0.523
16.90,107.54,0.526
16.92,107.68,0.528
16.93,107.83,0.530
16.95,107.98,0.533
16.97,108.13,0.535
16.98,108.28,0.538
17.00,108.43,0.540
17.01,108.58,0.542
17.03,108.73,0.545
17.04,108.88,0.549
17.05,109.03,0.549
17.07,109.18,0.552
17.08,109.33,0.555
17.10,109.47,0.558
17.12,109.62,0.561
17.13,109.77,0.563
17.14,109.92,0.566
17.16,110.07,0.568
17.18,110.22,0.572
17.19,110.37,0.574
17.21,110.52,0.578
17.22,110.66,0.580
17.23,110.81,0.583
17.25,110.96,0.586
17.27,111.11,0.589
17.28,111.26,0.593
17.29,111.41,0.595
17.31,111.56,0.600
17.33,111.71,0.603
17.34,111.85,0.606
17.36,112.00,0.610
17.37,112.15,0.614
17.38,112.30,0.617
17.40,112.45,0.620
17.42,112.60,0.624
17.43,112.75,0.627
17.44,112.89,0.631
17.46,113.04,0.635
17.48,113.19,0.638
17.49,113.34,0.641
17.51,113.49,0.645
17.52,113.64,0.649
17.53,113.79,0.653
17.55,113.94,0.658
17.57,114.08,0.661
17.58,114.23,0.665
17.59,114.38,0.669
17.61,114.53,0.672
17.63,114.68,0.677
17.64,114.83,0.682
17.66,114.98,0.685
17.67,115.12,0.691
17.68,115.27,0.694
17.70,115.42,0.698
17.72,115.57,0.703
17.73,115.72,0.707
17.74,115.87,0.712
17.76,116.01,0.717
17.78,116.16,0.722
17.79,116.31,0.728
17.81,116.46,0.732
17.82,116.61,0.738
17.83,116.75,0.744
17.85,116.90,0.749
17.87,117.05,0.754
17.88,117.20,0.760
17.89,117.35,0.766
17.91,117.49,0.772
17.93,117.64,0.777
17.94,117.79,0.784
17.96,117.94,0.791
17.97,118.08,0.795
17.98,118.23,0.803
18.00,118.38,0.810
18.02,118.53,0.815
18.03,118.67,0.823
18.04,118.82,0.830
18.06,118.97,0.837
18.08,119.11,0.843
18.09,119.26,0.851
18.11,119.41,0.858
18.12,119.56,0.865
18.13,119.70,0.874
18.15,119.85,0.882
18.17,120.00,0.888
18.18,120.15,0.896
18.19,120.29,0.905
18.21,120.44,0.914
18.23,120.59,0.920
18.24,120.73,0.930
18.26,120.88,0.937
18.27,121.03,0.944
18.28,121.17,0.952
18.30,121.32,0.959
18.32,121.47,0.967
18.33,121.61,0.974
18.34,121.76,0.981
18.36,121.91,0.989
18.38,122.05,0.997
18.39,122.20,1.003
18.41,122.35,1.010
18.42,122.50,1.018
18.43,122.64,1.025
18.45,122.79,1.034
18.47,122.94,1.041
18.48,123.08,1.048
18.49,123.23,1.055
18.51,123.38,1.062
18.53,123.53,1.070
18.54,123.67,1.077
18.56,123.82,1.083
18.57,123.97,1.089
18.58,124.12,1.096
18.60,124.26,1.102
18.62,124.41,1.107
18.63,124.56,1.112
18.64,124.71,1.117
18.66,124.85,1.119
18.68,125.00,1.123
18.69,125.15,1.125
18.71,125.30,1.127
18.72,125.45,1.128
18.73,125.60,1.128
18.75,125.75,1.128
18.77,125.89,1.127
18.78,126.04,1.122
18.79,126.20,1.112
18.81,126.35,1.101
18.83,126.50,1.088
18.84,126.65,1.072
18.86,126.81,1.052
18.87,126.97,1.027
18.88,127.12,0.995
18.90,127.28,0.963
18.92,127.44,0.923
18.93,127.61,0.881
18.94,127.77,0.838
18.96,127.94,0.788
18.98,128.10,0.745
18.99,128.27,0.710
19.01,128.44,0.673
19.02,128.60,0.639
19.03,128.77,0.611
19.05,128.93,0.586
19.07,129.10,0.564
19.08,129.26,0.545
19.09,129.42,0.529
19.11,129.58,0.512
19.13,129.74,0.499
19.14,129.90,0.487
19.16,130.06,0.477
19.17,130.21,0.468
19.18,130.37,0.459
19.20,130.52,0.451
19.22,130.68,0.445
19.23,130.83,0.439
19.24,130.99,0.433
19.26,131.14,0.430
19.28,131.29,0.425
19.29,131.45,0.421
19.31,131.60,0.418
19.32,131.75,0.414
19.33,131.90,0.411
19.35,132.06,0.409
19.37,132.21,0.407
19.38,132.36,0.405
19.39,132.51,0.404
19.41,132.66,0.402
19.43,132.81,0.401
19.44,132.97,0.400
19.46,133.12,0.399
19.47,133.27,0.398
19.48,133.42,0.398
19.50,133.57,0.396
19.52,133.72,0.396
19.53,133.87,0.395
19.54,134.02,0.395
19.56,134.17,0.394
19.58,134.32,0.393
19.59,134.47,0.393
19.61,134.62,0.393
19.62,134.77,0.392
19.63,134.92,0.392
19.65,135.07,0.392
19.67,135.22,0.391
19.68,135.37,0.391
19.69,135.52,0.391
19.71,135.67,0.390
19.73,135.82,0.390
19.74,135.97,0.390
19.76,136.12,0.389
19.77,136.28,0.389
19.78,136.43,0.389
19.80,136.58,0.389
19.82,136.73,0.389
19.83,136.88,0.388
19.84,137.03,0.388
19.86,137.18,0.387
19.88,137.33,0.387
19.89,137.48,0.387
19.91,137.63,0.386
19.92,137.78,0.386
19.93,137.93,0.386
19.95,138.08,0.386
19.97,138.23,0.385
19.98,138.38,0.385
19.99,138.53,0.385
20.01,138.68,0.385
20.03,138.83,0.384
20.04,138.98,0.384
20.06,139.13,0.384
20.07,139.28,0.384
20.08,139.43,0.383
20.10,139.58,0.383
20.12,139.73,0.383
20.13,139.88,0.383
20.14,140.03,0.382
20.16,140.18,0.382
20.18,140.33,0.382
20.19,140.48,0.381
20.21,140.64,0.381
20.22,140.79,0.381
20.23,140.94,0.381
20.25,141.09,0.380
20.27,141.24,0.380
20.28,141.39,0.380
20.29,141.54,0.379
20.31,141.69,0.379
20.33,141.84,0.379
20.34,141.99,0.378
20.36,142.14,0.378
20.37,142.29,0.378
20.38,142.44,0.377
20.40,142.59,0.377
20.42,142.74,0.377
20.43,142.89,0.376
20.44,143.04,0.376
20.46,143.19,0.375
20.48,143.34,0.375
20.49,143.49,0.375
20.51,143.64,0.375
20.52,143.79,0.374
20.53,143.94,0.374
20.55,144.09,0.374
20.57,144.24,0.373
20.58,144.39,0.373
20.59,144.54,0.372
20.61,144.69,0.372
20.63,144.84,0.371
20.64,144.99,0.371
20.66,145.14,0.371
20.67,145.29,0.370
20.68,145.44,0.370
20.70,145.59,0.369
20.72,145.74,0.369
20.73,145.90,0.368
20.74,146.04,0.368
20.76,146.20,0.368
20.78,146.35,0.367
20.79,146.50,0.367
20.81,146.65,0.367
20.82,146.80,0.366
20.83,146.95,0.366
20.85,147.10,0.366
20.87,147.25,0.365
20.88,147.40,0.365
20.89,147.55,0.365
20.91,147.70,0.364
20.93,147.85,0.364
20.94,148.00,
20.96,148.15,
20.97,148.30,
20.98,,
20.99,,

[step]
Ramp 10.00 °C/min to -60.00 °C
Time,Temperature,Heat Flow (Normalized)
min,°C,W/g
22.99,150.15,-0.091
23.01,150.15,-0.091
23.02,150.14,-0.091
23.04,150.14,-0.091
23.05,150.12,-0.091
23.07,150.10,-0.091
23.08,150.06,-0.099
23.10,150.01,-0.116
23.11,149.95,-0.140
23.13,149.87,-0.171
23.14,149.78,-0.205
23.16,149.69,-0.241
23.17,149.58,-0.274
23.19,149.48,-0.305
23.20,149.36,-0.330
23.22,149.24,-0.353
23.23,149.12,-0.373
23.25,149.00,-0.390
23.26,148.87,-0.405
23.28,148.74,-0.419
23.29,148.61,-0.431
23.31,148.47,-0.443
23.32,148.34,-0.451
23.34,148.20,-0.460
23.35,148.06,-0.468
23.37,147.92,-0.473
23.38,147.78,-0.478
23.40,147.64,-0.484
23.41,147.49,-0.487
23.43,147.35,-0.491
23.44,147.21,-0.493
23.46,147.06,-0.496
23.47,146.92,-0.499
23.49,146.77,-0.500
23.50,146.63,-0.503
23.52,146.48,-0.505
23.53,146.33,-0.505
23.55,146.19,-0.506
23.56,146.04,-0.508
23.58,145.89,-0.508
23.59,145.75,-0.508
23.61,145.60,-0.509
23.62,145.45,-0.509
23.64,145.30,-0.509
23.65,145.15,-0.510
23.67,145.01,-0.510
23.68,144.86,-0.510
23.70,144.71,-0.510
23.71,144.56,-0.510
23.73,144.41,-0.511
23.74,144.26,-0.511
23.76,144.11,-0.511
23.77,143.97,-0.511
23.79,143.82,-0.511
23.80,143.67,-0.511
23.82,143.52,-0.511
23.83,143.37,-0.511
23.85,143.22,-0.511
23.86,143.07,-0.511
23.88,142.92,-0.511
23.89,142.77,-0.511
23.91,142.62,-0.511
23.92,142.48,-0.511
23.94,142.33,-0.511
23.95,142.18,-0.511
23.97,142.03,-0.511
23.98,141.88,-0.511
24.00,141.73,-0.511
24.01,141.58,-0.510
24.03,141.43,-0.510
24.04,141.28,-0.510
24.06,141.13,-0.510
24.07,140.98,-0.510
24.09,140.84,-0.510
24.10,140.69,-0.510
24.12,140.54,-0.509
24.13,140.39,-0.509
24.15,140.24,-0.509
24.16,140.09,-0.509
24.18,139.94,-0.508
24.19,139.79,-0.508
24.21,139.64,-0.508
24.22,139.49,-0.508
24.24,139.34,-0.508
24.25,139.19,-0.508
24.27,139.04,-0.507
24.28,138.89,-0.507
24.30,138.74,-0.507
24.31,138.59,-0.507
24.33,138.44,-0.507
24.34,138.29,-0.506
24.36,138.14,-0.506
24.37,137.99,-0.506
24.39,137.84,-0.505
24.40,137.69,-0.505
24.42,137.54,-0.505
24.43,137.39,-0.505
24.45,137.24,-0.504
24.46,137.09,-0.504
24.48,136.94,-0.504
24.49,136.79,-0.504
24.51,136.64,-0.504
24.52,136.49,-0.503
24.54,136.35,-0.503
24.55,136.19,-0.503
24.57,136.05,-0.503
24.58,135.90,-0.502
24.60,135.75,-0.502
24.61,135.60,-0.502
24.63,135.45,-0.502
24.64,135.30,-0.501
24.66,135.15,-0.501
24.67,135.00,-0.501
24.69,134.85,-0.501
24.70,134.70,-0.500
24.72,134.55,-0.500
24.73,134.40,-0.500
24.75,134.25,-0.500
24.76,134.10,-0.499
24.78,133.95,-0.499
24.79,133.80,-0.499
24.81,133.65,-0.498
24.82,133.50,-0.498
24.84,133.35,-0.498
24.85,133.20,-0.498
24.87,133.05,-0.497
24.88,132.90,-0.497
24.90,132.75,-0.497
24.91,132.60,-0.497
24.93,132.45,-0.497
24.94,132.30,-0.496
24.96,132.15,-0.496
24.97,132.00,-0.496
24.99,131.85,-0.496
25.00,131.70,-0.496
25.02,131.55,-0.495
25.03,131.40,-0.495
25.05,131.25,-0.495
25.06,131.10,-0.495
25.08,130.95,-0.494
25.09,130.80,-0.494
25.11,130.65,-0.493
25.12,130.50,-0.493
25.14,130.35,-0.493
25.15,130.20,-0.493
25.17,130.05,-0.493
25.18,129.90,-0.493
25.20,129.75,-0.492
25.21,129.60,-0.492
25.23,129.45,-0.492
25.24,129.30,-0.492
25.26,129.15,-0.491
25.27,129.00,-0.491
25.29,128.85,-0.491
25.30,128.70,-0.491
25.32,128.55,-0.491
25.33,128.40,-0.490
25.35,128.25,-0.490
25.36,128.10,-0.490
25.38,127.95,-0.490
25.39,127.80,-0.490
25.41,127.65,-0.489
25.42,127.50,-0.489
25.44,127.35,-0.489
25.45,127.20,-0.489
25.47,127.05,-0.489
25.48,126.90,-0.488
25.50,126.76,-0.488
25.51,126.60,-0.488
25.53,126.45,-0.488
25.54,126.31,-0.488
25.56,126.16,-0.488
25.57,126.00,-0.487
25.59,125.85,-0.487
25.60,125.70,-0.487
25.62,125.56,-0.487
25.63,125.40,-0.487
25.65,125.25,-0.486
25.66,125.10,-0.486
25.68,124.95,-0.486
25.69,124.80,-0.486
25.71,124.65,-0.486
25.72,124.50,-0.486
25.74,124.35,-0.485
25.75,124.20,-0.485
25.77,124.05,-0.485
25.78,123.90,-0.485
25.80,123.75,-0.485
25.81,123.61,-0.485
25.83,123.45,-0.484
25.84,123.30,-0.484
25.86,123.15,-0.484
25.87,123.00,-0.483
25.89,122.85,-0.483
25.90,122.70,-0.483
25.92,122.56,-0.483
25.93,122.40,-0.483
25.95,122.25,-0.482
25.96,122.11,-0.482
25.98,121.96,-0.482
25.99,121.81,-0.482
26.01,121.66,-0.482
26.02,121.51,-0.481
26.04,121.36,-0.481
26.05,121.21,-0.481
26.07,121.06,-0.481
26.08,120.91,-0.481
26.10,120.76,-0.480
26.11,120.61,-0.480
26.13,120.46,-0.480
26.14,120.31,-0.480
26.16,120.16,-0.479
26.17,120.01,-0.479
26.19,119.86,-0.479
26.20,119.71,-0.479
26.22,119.56,-0.478
26.23,119.41,-0.478
26.25,119.26,-0.478
26.26,119.11,-0.478
26.28,118.96,-0.478
26.29,118.81,-0.478
26.31,118.66,-0.477
26.32,118.51,-0.477
26.34,118.36,-0.477
26.35,118.21,-0.477
26.37,118.06,-0.477
26.38,117.91,-0.477
26.40,117.76,-0.476
26.41,117.61,-0.476
26.43,117.46,-0.476
26.44,117.31,-0.476
26.46,117.16,-0.476
26.47,117.01,-0.476
26.49,116.86,-0.475
26.50,116.71,-0.475
26.52,116.56,-0.475
26.53,116.41,-0.475
26.55,116.26,-0.475
26.56,116.11,-0.475
26.58,115.97,-0.474
26.59,115.82,-0.474
26.61,115.66,-0.474
26.62,115.52,-0.474
26.64,115.36,-0.474
26.65,115.21,-0.473
26.67,115.07,-0.473
26.68,114.92,-0.473
26.70,114.77,-0.473
26.71,114.62,-0.473
26.73,114.47,-0.473
26.74,114.32,-0.473
26.76,114.17,-0.472
26.77,114.02,-0.472
26.79,113.87,-0.472
26.80,113.72,-0.472
26.82,113.57,-0.472
26.83,113.42,-0.472
26.85,113.27,-0.472
26.86,113.12,-0.471
26.88,112.97,-0.471
26.89,112.82,-0.471
26.91,112.67,-0.471
26.92,112.52,-0.471
26.94,112.37,-0.471
26.95,112.22,-0.470
26.97,112.07,-0.470
26.98,111.92,-0.470
27.00,111.77,-0.470
27.01,111.62,-0.470
27.03,111.47,-0.470
27.04,111.32,-0.469
27.06,111.17,-0.469
27.07,111.02,-0.469
27.09,110.87,-0.469
27.10,110.72,-0.469
27.12,110.57,-0.469
27.13,110.42,-0.468
27.15,110.27,-0.468
27.16,110.12,-0.468
27.18,109.97,-0.468
27.19,109.82,-0.468
27.21,109.67,-0.468
27.22,109.52,-0.468
27.24,109.37,-0.467
27.25,109.22,-0.467
27.27,109.07,-0.467
27.28,108.92,-0.467
27.30,108.77,-0.467
27.31,108.62,-0.467
27.33,108.47,-0.467
27.34,108.32,-0.466
27.36,108.17,-0.466
27.37,108.02,-0.466
27.39,107.87,-0.466
27.40,107.72,-0.466
27.42,107.57,-0.466
27.43,107.42,-0.465
27.45,107.27,-0.465
27.46,107.12,-0.465
27.48,106.97,-0.465
27.49,106.82,-0.465
27.51,106.67,-0.465
27.52,106.52,-0.464
27.54,106.37,-0.464
27.55,106.22,-0.464
27.57,106.07,-0.464
27.58,105.92,-0.464
27.60,105.77,-0.464
27.61,105.62,-0.463
27.63,105.47,-0.463
27.64,105.32,-0.463
27.66,105.17,-0.463
27.67,105.02,-0.463
27.69,104.87,-0.463
27.70,104.72,-0.462
27.72,104.57,-0.462
27.73,104.43,-0.462
27.75,104.27,-0.462
27.76,104.12,-0.462
27.78,103.97,-0.462
27.79,103.82,-0.461
27.81,103.68,-0.461
27.82,103.53,-0.461
27.84,103.37,-0.461
27.85,103.23,-0.461
27.87,103.08,-0.461
27.88,102.93,-0.460
27.90,102.77,-0.460
27.91,102.63,-0.460
27.93,102.48,-0.460
27.94,102.33,-0.460
27.96,102.18,-0.460
27.97,102.03,-0.460
27.99,101.88,-0.459
28.00,101.73,-0.459
28.02,101.58,-0.459
28.03,101.43,-0.459
28.05,101.28,-0.459
28.06,101.13,-0.459
28.08,100.98,-0.458
28.09,100.83,-0.458
28.11,100.68,-0.458
28.12,100.53,-0.458
28.14,100.38,-0.458
28.15,100.23,-0.458
28.17,100.08,-0.458
28.18,99.93,-0.457
28.20,99.78,-0.457
28.21,99.63,-0.457
28.23,99.48,-0.457
28.24,99.33,-0.457
28.26,99.18,-0.457
28.27,99.03,-0.456
28.29,98.88,-0.456
28.30,98.73,-0.456
28.32,98.58,-0.456
28.33,98.43,-0.456
28.35,98.28,-0.456
28.36,98.13,-0.455
28.38,97.98,-0.455
28.39,97.83,-0.455
28.41,97.68,-0.455
28.42,97.53,-0.455
28.44,97.38,-0.455
28.45,97.23,-0.454
28.47,97.08,-0.454
28.48,96.93,-0.454
28.50,96.78,-0.454
28.51,96.63,-0.454
28.53,96.48,-0.454
28.54,96.33,-0.454
28.56,96.18,-0.453
28.57,96.03,-0.453
28.59,95.88,-0.453
28.60,95.73,-0.453
28.62,95.58,-0.453
28.63,95.43,-0.453
28.65,95.28,-0.452
28.66,95.13,-0.452
28.68,94.98,-0.452
28.69,94.83,-0.452
28.71,94.68,-0.452
28.72,94.53,-0.451
28.74,94.38,-0.451
28.75,94.23,-0.451
28.77,94.08,-0.451
28.78,93.94,-0.451
[...]
140.08,-40.92,0.175
140.08,-40.85,0.176
140.09,-40.79,0.176
140.10,-40.72,0.176
140.10,-40.65,0.176
140.11,-40.59,0.176
140.12,-40.52,0.176
140.12,-40.45,0.176
140.13,-40.39,0.176
140.14,-40.32,0.176
140.14,-40.25,0.176
140.15,-40.19,0.176
140.16,-40.12,0.176
140.16,-40.05,0.176
140.17,-39.99,0.176
140.18,-39.92,0.176
140.18,-39.85,0.176
140.19,-39.79,0.176
140.20,-39.72,0.176
140.20,-39.65,0.176
140.21,-39.59,0.176
140.22,-39.52,0.176
140.22,-39.45,0.176
140.23,-39.39,0.176
140.24,-39.32,0.176
140.24,-39.25,0.176
140.25,-39.19,0.176
140.26,-39.12,0.176
140.26,-39.05,0.176
140.27,-38.99,0.176
140.28,-38.92,0.177
140.28,-38.85,0.177
140.29,-38.78,0.177
140.30,-38.72,0.177
140.30,-38.65,0.177
140.31,-38.59,0.177
140.32,-38.52,0.177
140.32,-38.45,0.177
140.33,-38.38,0.177
140.34,-38.32,0.177
140.34,-38.25,0.177
140.35,-38.18,0.177
140.36,-38.12,0.177
140.36,-38.05,0.177
140.37,-37.98,0.177
140.38,-37.92,0.177
140.38,-37.85,0.177
140.39,-37.78,0.177
140.40,-37.72,0.177
140.40,-37.65,0.177
140.41,-37.58,0.177
140.42,-37.52,0.177
140.42,-37.45,0.177
140.43,-37.38,0.177
140.44,-37.32,0.177
140.44,-37.25,0.177
140.45,-37.18,0.177
140.46,-37.12,0.177
140.46,-37.05,0.177
140.47,-36.98,0.177
140.48,-36.92,0.177
140.48,-36.85,0.178
140.49,-36.78,0.178
140.50,-36.72,0.178
140.50,-36.65,0.178
140.51,-36.58,0.178
140.52,-36.52,0.178
140.52,-36.45,0.178
140.53,-36.38,0.178
140.54,-36.32,0.178
140.54,-36.25,0.178
140.55,-36.18,0.178
140.56,-36.11,0.178
140.56,-36.05,0.178
140.57,-35.98,0.178
140.58,-35.91,0.178
140.58,-35.85,0.178
140.59,-35.78,0.178
140.60,-35.71,0.178
140.60,-35.65,0.178
140.61,-35.58,0.178
140.62,-35.51,0.178
140.62,-35.45,0.178
140.63,-35.38,0.178
140.64,-35.31,0.178
140.64,-35.25,0.178
140.65,-35.18,0.179
140.66,-35.11,0.179
140.66,-35.05,0.179
140.67,-34.98,0.179
140.68,-34.91,0.179
140.68,-34.85,0.179
140.69,-34.78,0.179
140.70,-34.71,0.179
140.70,-34.65,0.179
140.71,-34.58,0.179
140.72,-34.51,0.179
140.72,-34.45,0.179
140.73,-34.38,0.179
140.74,-34.31,0.179
140.74,-34.25,0.179
140.75,-34.18,0.179
140.76,-34.11,0.179
140.76,-34.04,0.179
140.77,-33.98,0.179
140.78,-33.91,0.179
140.78,-33.84,0.179
140.79,-33.78,0.179
140.80,-33.71,0.179
140.80,-33.64,0.179
140.81,-33.58,0.179
140.82,-33.51,0.179
140.82,-33.44,0.180
140.83,-33.38,0.180
140.84,-33.31,0.180
140.84,-33.24,0.180
140.85,-33.18,0.180
140.86,-33.11,0.180
140.86,-33.04,0.180
140.87,-32.98,0.180
140.88,-32.91,0.180
140.88,-32.84,0.180
140.89,-32.78,0.180
140.90,-32.71,0.180
140.90,-32.64,0.180
140.91,-32.58,0.180
140.92,-32.51,0.180
140.92,-32.44,0.180
140.93,-32.38,0.180
140.94,-32.31,0.180
140.94,-32.24,0.180
140.95,-32.17,0.180
140.96,-32.11,0.180
140.96,-32.04,0.180
140.97,-31.97,0.180
140.98,-31.91,0.180
140.98,-31.84,0.180
140.99,-31.77,0.180
141.00,-31.71,0.180
141.00,-31.64,0.180
141.01,-31.57,0.180
141.02,-31.51,0.180
141.02,-31.44,0.181
141.03,-31.37,0.181
141.04,-31.31,0.181
141.04,-31.24,0.181
141.05,-31.17,0.181
141.06,-31.11,0.181
141.06,-31.04,0.181
141.07,-30.97,0.181
141.08,-30.91,0.181
141.08,-30.84,0.181
141.09,-30.77,0.181
141.10,-30.71,0.181
141.10,-30.64,0.181
141.11,-30.57,0.181
141.12,-30.51,0.181
141.12,-30.44,0.181
141.13,-30.37,0.181
141.14,-30.31,0.181
141.14,-30.24,0.181
141.15,-30.17,0.181
141.16,-30.11,0.181
141.16,-30.04,0.181
141.17,-29.97,0.181
141.18,-29.90,0.181
141.18,-29.84,0.181
141.19,-29.77,0.181
141.20,-29.71,0.181
141.20,-29.64,0.182
141.21,-29.57,0.182
141.22,-29.51,0.182
141.22,-29.44,0.182
141.23,-29.37,0.182
141.24,-29.30,0.182
141.24,-29.24,0.182
141.25,-29.17,0.182
141.26,-29.10,0.182
141.26,-29.04,0.182
141.27,-28.97,0.182
141.28,-28.90,0.182
141.28,-28.84,0.182
141.29,-28.77,0.182
141.30,-28.70,0.182
141.30,-28.64,0.182
141.31,-28.57,0.182
141.32,-28.50,0.182
141.32,-28.44,0.182
141.33,-28.37,0.182
141.34,-28.30,0.182
141.34,-28.24,0.182
141.35,-28.17,0.182
141.36,-28.10,0.182
141.36,-28.04,0.182
141.37,-27.97,0.182
141.38,-27.90,0.182
141.38,-27.84,0.182
141.39,-27.77,0.182
141.40,-27.70,0.183
141.40,-27.64,0.183
141.41,-27.57,0.183
141.42,-27.50,0.183
141.42,-27.44,0.183
141.43,-27.37,0.183
141.44,-27.30,0.183
141.44,-27.24,0.183
141.45,-27.17,0.183
141.46,-27.10,0.183
141.46,-27.04,0.183
141.47,-26.97,0.183
141.48,-26.90,0.183
141.48,-26.83,0.183
141.49,-26.77,0.183
141.50,-26.70,0.183
141.50,-26.64,0.183
141.51,-26.57,0.183
141.52,-26.50,0.183
141.52,-26.44,0.183
141.53,-26.37,0.183
141.54,-26.30,0.183
141.54,-26.23,0.183
141.55,-26.17,0.183
141.56,-26.10,0.183
141.56,-26.04,0.184
141.57,-25.97,0.184
141.58,-25.90,0.184
141.58,-25.83,0.184
141.59,-25.77,0.184
141.60,-25.70,0.184
141.60,-25.64,0.184
141.61,-25.57,0.184
141.62,-25.50,0.184
141.62,-25.44,0.184
141.63,-25.37,0.184
141.64,-25.30,0.184
141.64,-25.23,0.184
141.65,-25.17,0.184
141.66,-25.10,0.184
141.66,-25.03,0.184
141.67,-24.97,0.184
141.68,-24.90,0.184
141.68,-24.83,0.184
141.69,-24.77,0.184
141.70,-24.70,0.184
141.70,-24.63,0.184
141.71,-24.57,0.184
141.72,-24.50,0.184
141.72,-24.43,0.184
141.73,-24.37,0.184
141.74,-24.30,0.184
141.74,-24.23,0.184
141.75,-24.17,0.185
141.76,-24.10,0.185
141.76,-24.03,0.185
141.77,-23.97,0.185
141.78,-23.90,0.185
141.78,-23.83,0.185
141.79,-23.77,0.185
141.80,-23.70,0.185
141.80,-23.63,0.185
141.81,-23.56,0.185
141.82,-23.50,0.185
141.82,-23.43,0.185
141.83,-23.37,0.185
141.84,-23.30,0.185
141.84,-23.23,0.185
141.85,-23.16,0.185
141.86,-23.10,0.185
141.86,-23.03,0.185
141.87,-22.96,0.185
141.88,-22.90,0.185
141.88,-22.83,0.185
141.89,-22.76,0.185
141.90,-22.70,0.185
141.90,-22.63,0.185
141.91,-22.56,0.186
141.92,-22.50,0.186
141.92,-22.43,0.186
141.93,-22.36,0.186
141.94,-22.30,0.186
141.94,-22.23,0.186
141.95,-22.16,0.186
141.96,-22.10,0.186
141.96,-22.03,0.186
141.97,-21.96,0.186
141.98,-21.90,0.186
141.98,-21.83,0.186
141.99,-21.76,0.186
142.00,-21.70,0.186
142.00,-21.63,0.186
142.01,-21.56,0.186
142.02,-21.50,0.186
142.02,-21.43,0.186
142.03,-21.36,0.186
142.04,-21.29,0.186
142.04,-21.23,0.186
142.05,-21.16,0.186
142.06,-21.09,0.186
142.06,-21.03,0.187
142.07,-20.96,0.187
142.08,-20.89,0.187
142.08,-20.83,0.187
142.09,-20.76,0.187
142.10,-20.69,0.187
142.10,-20.63,0.187
142.11,-20.56,0.187
142.12,-20.49,0.187
142.12,-20.43,0.187
142.13,-20.36,0.187
142.14,-20.29,0.187
142.14,-20.23,0.187
142.15,-20.16,0.187
142.16,-20.09,0.187
142.16,-20.03,0.187
142.17,-19.96,0.187
142.18,-19.89,0.187
142.18,-19.83,0.187
142.19,-19.76,0.187
142.20,-19.69,0.187
142.20,-19.63,0.187
142.21,-19.56,0.187
142.22,-19.49,0.187
142.22,-19.43,0.188
142.23,-19.36,0.188
142.24,-19.29,0.188
142.24,-19.23,0.188
142.25,-19.16,0.188
142.26,-19.09,0.188
142.26,-19.03,0.188
142.27,-18.96,0.188
142.28,-18.89,0.188
142.28,-18.83,0.188
142.29,-18.76,0.188
142.30,-18.69,0.188
142.30,-18.63,0.188
142.31,-18.56,0.188
142.32,-18.49,0.188
142.32,-18.42,0.188
142.33,-18.36,0.188
142.34,-18.29,0.188
142.34,-18.22,0.188
142.35,-18.16,0.188
142.36,-18.09,0.188
142.36,-18.02,0.188
142.37,-17.96,0.188
142.38,-17.89,0.188
142.38,-17.82,0.188
142.39,-17.76,0.189
142.40,-17.69,0.189
142.40,-17.62,0.189
142.41,-17.56,0.189
142.42,-17.49,0.189
142.42,-17.42,0.189
142.43,-17.36,0.189
142.44,-17.29,0.189
142.44,-17.22,0.189
142.45,-17.16,0.189
142.46,-17.09,0.189
142.46,-17.02,0.189
142.47,-16.96,0.189
142.48,-16.89,0.189
142.48,-16.82,0.189
142.49,-16.76,0.189
142.50,-16.69,0.189
142.50,-16.62,0.189
142.51,-16.56,0.189
142.52,-16.49,0.189
142.52,-16.42,0.189
142.53,-16.36,0.189
142.54,-16.29,0.189
142.54,-16.22,0.189
142.55,-16.16,0.190
142.56,-16.09,0.190
142.56,-16.02,0.190
142.57,-15.95,0.190
142.58,-15.89,0.190
142.58,-15.82,0.190
142.59,-15.75,0.190
142.60,-15.69,0.190
142.60,-15.62,0.190
142.61,-15.55,0.190
142.62,-15.49,0.190
142.62,-15.42,0.190
142.63,-15.35,0.190
142.64,-15.29,0.190
142.64,-15.22,0.190
142.65,-15.15,0.190
142.66,-15.09,0.190
142.66,-15.02,0.190
142.67,-14.96,0.190
142.68,-14.89,0.190
142.68,-14.82,0.190
142.69,-14.75,0.190
142.70,-14.69,0.190
142.70,-14.62,0.190
142.71,-14.55,0.191
142.72,-14.49,0.191
142.72,-14.42,0.191
142.73,-14.35,0.191
142.74,-14.29,0.191
142.74,-14.22,0.191
142.75,-14.15,0.191
142.76,-14.09,0.191
142.76,-14.02,0.191
142.77,-13.95,0.191
142.78,-13.89,0.191
142.78,-13.82,0.191
142.79,-13.75,0.191
142.80,-13.69,0.191
142.80,-13.62,0.191
142.81,-13.55,0.191
142.82,-13.49,0.191
142.82,-13.42,0.191
142.83,-13.35,0.191
142.84,-13.29,0.191
142.84,-13.22,0.191
142.85,-13.15,0.192
142.86,-13.09,0.192
142.86,-13.02,0.192
142.87,-12.95,0.192
142.88,-12.89,0.192
142.88,-12.82,0.192
142.89,-12.75,0.192
142.90,-12.69,0.192
142.90,-12.62,0.192
142.91,-12.55,0.192
142.92,-12.49,0.192
142.92,-12.42,0.192
142.93,-12.35,0.192
142.94,-12.29,0.192
142.94,-12.22,0.192
142.95,-12.15,0.192
142.96,-12.09,0.192
142.96,-12.02,0.192
142.97,-11.95,0.192
142.98,-11.89,0.192
142.98,-11.82,0.192
142.99,-11.75,0.192
143.00,-11.69,0.192
143.00,-11.62,0.192
143.01,-11.55,0.192
143.02,-11.48,0.192
143.02,-11.42,0.193
143.03,-11.35,0.193
143.04,-11.28,0.193
143.04,-11.22,0.193
143.05,-11.15,0.193
143.06,-11.08,0.193
143.06,-11.02,0.193
143.07,-10.95,0.193
143.08,-10.88,0.193
143.08,-10.82,0.193
143.09,-10.75,0.193
143.10,-10.68,0.193
143.10,-10.62,0.193
143.11,-10.55,0.193
143.12,-10.48,0.193
143.12,-10.42,0.193
143.13,-10.35,0.193
143.14,-10.28,0.193
143.14,-10.22,0.194
143.15,-10.15,0.194
143.16,-10.08,0.194
143.16,-10.02,0.194
143.17,-9.95,0.194
143.18,-9.88,0.194
143.18,-9.82,0.194
143.19,-9.75,0.194
143.20,-9.68,0.194
143.20,-9.62,0.194
143.21,-9.55,0.194
143.22,-9.48,0.194
143.22,-9.42,0.194
143.23,-9.35,0.194
143.24,-9.28,0.194
143.24,-9.22,0.194
143.25,-9.15,0.194
143.26,-9.08,0.195
143.26,-9.01,0.195
143.27,-8.95,0.195
143.28,-8.88,0.195
143.28,-8.81,0.195
143.29,-8.75,0.195
143.30,-8.68,0.195
143.30,-8.61,0.195
143.31,-8.55,0.195
143.32,-8.48,0.195
143.32,-8.42,0.195
143.33,-8.35,0.195
143.34,-8.28,0.195
143.34,-8.22,0.195
143.35,-8.15,0.195
143.36,-8.08,0.195
143.36,-8.01,0.195
143.37,-7.95,0.195
143.38,-7.88,0.196
143.38,-7.81,0.196
143.39,-7.75,0.196
143.40,-7.68,0.196
143.40,-7.61,0.196
143.41,-7.55,0.196
143.42,-7.48,0.196
143.42,-7.41,0.196
143.43,-7.35,0.196
143.44,-7.28,0.196
143.44,-7.21,0.196
143.45,-7.15,0.196
143.46,-7.08,0.196
143.46,-7.01,0.196
143.47,-6.95,0.196
143.48,-6.88,0.196
143.48,-6.81,0.196
143.49,-6.75,0.197
143.50,-6.68,0.197
143.50,-6.61,0.197
143.51,-6.55,0.197
143.52,-6.48,0.197
143.52,-6.41,0.197
143.53,-6.35,0.197
143.54,-6.28,0.197
143.54,-6.21,0.197
143.55,-6.14,0.197
143.56,-6.08,0.197
143.56,-6.01,0.197
143.57,-5.94,0.198
143.58,-5.88,0.198
143.58,-5.81,0.198
143.59,-5.75,0.198
143.60,-5.68,0.198
143.60,-5.61,0.198
143.61,-5.55,0.198
143.62,-5.48,0.198
143.62,-5.41,0.198
143.63,-5.34,0.198
143.64,-5.28,0.198
143.64,-5.21,0.198
143.65,-5.14,0.198
143.66,-5.08,0.198
143.66,-5.01,0.199
143.67,-4.94,0.199
143.68,-4.88,0.199
143.68,-4.81,0.199
143.69,-4.74,0.199
143.70,-4.68,0.199
143.70,-4.61,0.199
143.71,-4.55,0.199
143.72,-4.48,0.199
143.72,-4.41,0.199
143.73,-4.34,0.199
143.74,-4.28,0.199
143.74,-4.21,0.199
143.75,-4.14,0.199
143.76,-4.08,0.200
143.76,-4.01,0.200
143.77,-3.94,0.200
143.78,-3.88,0.200
143.78,-3.81,0.200
143.79,-3.74,0.200
143.80,-3.68,0.200
143.80,-3.61,0.200
143.81,-3.54,0.200
143.82,-3.48,0.200
143.82,-3.41,0.201
143.83,-3.34,0.201
143.84,-3.28,0.201
143.84,-3.21,0.201
143.85,-3.14,0.201
143.86,-3.08,0.201
143.86,-3.01,0.201
143.87,-2.94,0.201
143.88,-2.88,0.201
143.88,-2.81,0.201
143.89,-2.74,0.202
143.90,-2.68,0.202
143.90,-2.61,0.202
143.91,-2.54,0.202
143.92,-2.48,0.202
143.92,-2.41,0.202
143.93,-2.34,0.202
143.94,-2.28,0.202
143.94,-2.21,0.202
143.95,-2.14,0.202
143.96,-2.08,0.202
143.96,-2.01,0.203
143.97,-1.94,0.203
143.98,-1.87,0.203
143.98,-1.81,0.203
143.99,-1.74,0.204
144.00,-1.67,0.204
144.00,-1.61,0.204
144.01,-1.54,0.204
144.02,-1.47,0.204
144.02,-1.41,0.204
144.03,-1.34,0.204
144.04,-1.27,0.204
144.04,-1.21,0.205
144.05,-1.14,0.205
144.06,-1.08,0.205
144.06,-1.01,0.205
144.07,-0.94,0.205
144.08,-0.87,0.205
144.08,-0.81,0.205
144.09,-0.74,0.205
144.10,-0.68,0.206
144.10,-0.61,0.206
144.11,-0.54,0.206
144.12,-0.47,0.206
144.12,-0.41,0.206
144.13,-0.34,0.206
144.14,-0.28,0.206
144.14,-0.21,0.207
144.15,-0.14,0.207
144.16,-0.07,0.207
144.16,-0.01,0.207
144.17,0.06,0.207
144.18,0.13,0.208
144.18,0.19,0.208
144.19,0.26,0.208
144.20,0.32,0.208
144.20,0.39,0.208
144.21,0.46,0.209
144.22,0.53,0.209
144.22,0.59,0.209
144.23,0.66,0.209
144.24,0.73,0.210
144.24,0.79,0.210
144.25,0.86,0.210
144.26,0.93,0.210
144.26,0.99,0.210
144.27,1.06,0.210
144.28,1.13,0.211
144.28,1.19,0.211
144.29,1.26,0.211
144.30,1.32,0.211
144.30,1.39,0.212
144.31,1.46,0.212
144.32,1.53,0.212
144.32,1.59,0.213
144.33,1.66,0.213
144.34,1.73,0.213
144.34,1.79,0.214
144.35,1.86,0.214
144.36,1.93,0.214
144.36,1.99,0.215
144.37,2.06,0.215
144.38,2.13,0.215
144.38,2.19,0.215
144.39,2.26,0.216
144.40,2.32,0.216
144.40,2.39,0.217
144.41,2.46,0.218
144.42,2.52,0.218
144.42,2.59,0.218
144.43,2.66,0.219
144.44,2.72,0.219
144.44,2.79,0.220
144.45,2.86,0.220
144.46,2.92,0.220
144.46,2.99,0.221
144.47,3.06,0.221
144.48,3.12,0.222
144.48,3.19,0.222
144.49,3.26,0.223
144.50,3.32,0.224
144.50,3.39,0.224
144.51,3.45,0.225
144.52,3.52,0.225
144.52,3.59,0.226
144.53,3.65,0.226
144.54,3.72,0.227
144.54,3.79,0.227
144.55,3.85,0.228
144.56,3.92,0.229
144.56,3.99,0.229
144.57,4.05,0.230
144.58,4.12,0.231
144.58,4.19,0.232
144.59,4.25,0.232
144.60,4.32,0.233
144.60,4.39,0.234
144.61,4.45,0.236
144.62,4.52,0.236
144.62,4.58,0.236
144.63,4.65,0.238
144.64,4.72,0.238
144.64,4.78,0.239
144.65,4.85,0.240
144.66,4.92,0.240
144.66,4.98,0.241
144.67,5.05,0.242
144.68,5.12,0.242
144.68,5.18,0.242
144.69,5.25,0.244
144.70,5.32,0.246
144.70,5.38,0.247
144.71,5.45,0.248
144.72,5.52,0.248
144.72,5.58,0.250
144.73,5.65,0.250
144.74,5.71,0.251
144.74,5.78,0.251
144.75,5.85,0.252
144.76,5.91,0.254
144.76,5.98,0.256
144.77,6.05,0.257
144.78,6.11,0.257
144.78,6.18,0.258
144.79,6.24,0.259
144.80,6.31,0.260
144.80,6.38,0.261
144.81,6.44,0.262
144.82,6.51,0.264
144.82,6.58,0.265
144.83,6.64,0.266
144.84,6.71,0.267
144.84,6.77,0.269
144.85,6.84,0.270
144.86,6.90,0.270
144.86,6.97,0.272
144.87,7.04,0.274
144.88,7.11,0.275
144.88,7.17,0.276
144.89,7.24,0.278
144.90,7.30,0.279
144.90,7.37,0.280
144.91,7.44,0.281
144.92,7.50,0.283
144.92,7.57,0.286
144.93,7.63,0.287
144.94,7.70,0.288
144.94,7.77,0.289
144.95,7.83,0.291
144.96,7.90,0.293
144.96,7.96,0.293
144.97,8.03,0.295
144.98,8.09,0.298
144.98,8.16,0.299
144.99,8.23,0.300
145.00,8.29,0.302
145.00,8.36,0.303
145.01,8.42,0.305
145.02,8.49,0.308
145.02,8.56,0.309
145.03,8.62,0.310
145.04,8.69,0.311
145.04,8.76,0.313
145.05,8.82,0.315
145.06,8.89,0.317
145.06,8.95,0.318
145.07,9.02,0.320
145.08,9.08,0.321
145.08,9.15,0.323
145.09,9.22,0.325
145.10,9.28,0.326
145.10,9.35,0.328
145.11,9.41,0.330
145.12,9.48,0.331
145.12,9.55,0.333
145.13,9.61,0.334
145.14,9.68,0.335
145.14,9.74,0.337
145.15,9.81,0.339
145.16,9.88,0.339
145.16,9.94,0.341
145.17,10.01,0.343
145.18,10.07,0.344
145.18,10.14,0.345
145.19,10.20,0.346
145.20,10.27,0.347
145.20,10.34,0.348
145.21,10.40,0.349
145.22,10.47,0.349
145.22,10.54,0.350
145.23,10.60,0.352
145.24,10.67,0.352
145.24,10.73,0.353
145.25,10.80,0.353
145.26,10.87,0.354
145.26,10.93,0.354
145.27,11.00,0.354
145.28,11.06,0.354
145.28,11.13,0.355
145.29,11.20,0.355
145.30,11.26,0.355
145.30,11.33,0.355
145.31,11.40,0.355
145.32,11.46,0.355
145.32,11.53,0.355
145.33,11.60,0.355
145.34,11.66,0.355
145.34,11.73,0.355
145.35,11.80,0.355
145.36,11.86,0.355
145.36,11.93,0.355
145.37,12.00,0.355
145.38,12.06,0.354
145.38,12.13,0.354
145.39,12.20,0.353
145.40,12.26,0.353
145.40,12.33,0.352
145.41,12.40,0.351
145.42,12.47,0.350
145.42,12.53,0.350
145.43,12.60,0.349
145.44,12.67,0.347
145.44,12.74,0.346
145.45,12.80,0.346
145.46,12.87,0.344
145.46,12.94,0.342
145.47,13.00,0.342
145.48,13.07,0.341
145.48,13.14,0.340
145.49,13.20,0.339
145.50,13.27,0.338
145.50,13.34,0.338
145.51,13.41,0.337
145.52,13.47,0.336
145.52,13.54,0.336
145.53,13.61,0.335
145.54,13.68,0.335
145.54,13.74,0.334
145.55,13.81,0.334
145.56,13.88,0.333
145.56,13.94,0.332
145.57,14.01,0.332
145.58,14.08,0.332
145.58,14.15,0.331
145.59,14.21,0.330
145.60,14.28,0.330
145.60,14.35,0.330
145.61,14.41,0.330
145.62,14.48,0.329
145.62,14.55,0.329
145.63,14.62,0.329
145.64,14.68,0.329
145.64,14.75,0.328
145.65,14.82,0.328
145.66,14.88,0.328
145.66,14.95,0.328
145.67,15.02,0.327
145.68,15.08,0.327
145.68,15.15,0.327
145.69,15.22,0.327
145.70,15.29,0.327
145.70,15.35,0.327
145.71,15.42,0.326
145.72,15.49,0.326
145.72,15.55,0.326
145.73,15.62,0.326
145.74,15.69,0.326
145.74,15.75,0.326
145.75,15.82,0.326
145.76,15.89,0.326
145.76,15.95,0.325
145.77,16.02,0.325
145.78,16.09,0.325
145.78,16.15,0.325
145.79,16.22,0.325
145.80,16.29,0.325
145.80,16.36,0.325
145.81,16.42,0.325
145.82,16.49,0.325
145.82,16.56,0.325
145.83,16.62,0.325
145.84,16.69,0.324
145.84,16.76,0.324
145.85,16.82,0.324
145.86,16.89,0.324
145.86,16.96,0.324
145.87,17.02,0.324
145.88,17.09,0.324
145.88,17.16,0.324
145.89,17.22,0.324
145.90,17.29,0.324
145.90,17.36,0.324
145.91,17.42,0.324
145.92,17.49,0.324
145.92,17.56,0.324
145.93,17.62,0.323
145.94,17.69,0.323
145.94,17.76,0.323
145.95,17.83,0.323
145.96,17.89,0.323
145.96,17.96,0.323
145.97,18.03,0.323
145.98,18.09,0.323
145.98,18.16,0.323
145.99,18.23,0.323
146.00,18.29,0.323
146.00,18.36,0.323
146.01,18.43,0.323
146.02,18.49,0.323
146.02,18.56,0.323
146.03,18.63,0.323
146.04,18.69,0.323
146.04,18.76,0.323
146.05,18.83,0.323
146.06,18.89,0.323
146.06,18.96,0.322
146.07,19.03,0.322
146.08,19.09,0.322
146.08,19.16,0.322
146.09,19.23,0.322
146.10,19.29,0.322
146.10,19.36,0.322
146.11,19.43,0.322
146.12,19.49,0.322
146.12,19.56,0.322
146.13,19.63,0.322
146.14,19.70,0.322
146.14,19.76,0.322
146.15,19.83,0.322
146.16,19.90,0.322
146.16,19.96,0.322
146.17,20.03,0.322
146.18,20.10,0.322
146.18,20.16,0.322
146.19,20.23,0.322
146.20,20.30,0.322
146.20,20.36,0.322
146.21,20.43,0.322
146.22,20.50,0.322
146.22,20.56,0.322
146.23,20.63,0.322
146.24,20.70,0.322
146.24,20.76,0.322
146.25,20.83,0.322
146.26,20.90,0.322
146.26,20.96,0.322
146.27,21.03,0.322
146.28,21.10,0.322
146.28,21.16,0.322
146.29,21.23,0.322
146.30,21.30,0.322
146.30,21.36,0.322
146.31,21.43,0.322
146.32,21.50,0.322
146.32,21.56,0.322
146.33,21.63,0.322
146.34,21.70,0.322
146.34,21.76,0.322
146.35,21.83,0.322
146.36,21.90,0.322
146.36,21.97,0.322
146.37,22.03,0.322
146.38,22.10,0.323
146.38,22.17,0.323
146.39,22.23,0.323
146.40,22.30,0.323
146.40,22.37,0.323
146.41,22.43,0.323
146.42,22.50,0.323
146.42,22.57,0.323
146.43,22.63,0.323
146.44,22.70,0.323
146.44,22.77,0.323
146.45,22.83,0.323
146.46,22.90,0.323
146.46,22.97,0.323
146.47,23.03,0.323
146.48,23.10,0.323
146.48,23.17,0.323
146.49,23.23,0.323
146.50,23.30,0.323
146.50,23.37,0.323
146.51,23.43,0.323
146.52,23.50,0.323
146.52,23.57,0.323
146.53,23.63,0.323
146.54,23.70,0.323
146.54,23.77,0.323
146.55,23.83,0.323
146.56,23.90,0.323
146.56,23.97,0.323
146.57,24.03,0.323
146.58,24.10,0.323
146.58,24.17,0.323
146.59,24.23,0.323
146.60,24.30,0.323
146.60,24.37,0.324
146.61,24.44,0.324
146.62,24.50,0.324
146.62,24.57,0.324
146.63,24.63,0.324
146.64,24.70,0.324
146.64,24.77,0.324
146.65,24.83,0.324
146.66,24.90,0.324
146.66,24.97,0.324
146.67,25.03,0.324
146.68,25.10,0.324
146.68,25.17,0.324
146.69,25.24,0.324
146.70,25.30,0.324
146.70,25.37,0.324
146.71,25.43,0.324
146.72,25.50,0.324
146.72,25.57,0.324
146.73,25.64,0.324
146.74,25.70,0.324
146.74,25.77,0.324
146.75,25.84,0.324
146.76,25.90,0.324
146.76,25.97,0.325
146.77,26.04,0.325
146.78,26.10,0.325
146.78,26.17,0.325
146.79,26.24,0.325
146.80,26.30,0.325
146.80,26.37,0.325
146.81,26.44,0.325
146.82,26.50,0.325
146.82,26.57,0.325
146.83,26.64,0.325
146.84,26.70,0.325
146.84,26.77,0.325
146.85,26.84,0.325
146.86,26.90,0.325
146.86,26.97,0.325
146.87,27.04,0.325
146.88,27.10,0.325
146.88,27.17,0.325
146.89,27.24,0.325
146.90,27.31,0.325
146.90,27.37,0.326
146.91,27.44,0.326
146.92,27.51,0.326
146.92,27.57,0.326
146.93,27.64,0.326
146.94,27.71,0.326
146.94,27.77,
146.95,27.84,
146.96,27.91,
146.96,27.97,
146.97,28.04,
146.98,28.11,
146.98,28.17,
146.99,,
147.00,,