File: DSC/2025_06_19_Sorbic_Acid_n60_160C_5Cmin_x3.csv
Filename,2025_06_19_Sorbic_Acid_n60_160C_5Cmin_x3
Instrument name,DSC2A-00468 (192.168.1.100)
Operator,Gibbons
rundate,6/20/2025
Sample name,2025_06_19_Sorbic_Acid_n60_160C_5Cmin_x3
proceduresegments,Data Off ; Equilibrate -60.00 °C; Data On ; Ramp 5.00 °C/min to 160.00 °C; Data Off ; Isothermal 1.0 min; Data On ; Ramp 5.00 °C/min to -60.00 °C; Data Off ; Isothermal 1.0 min; Data On ; Ramp 5.00 °C/min to 160.00 °C; Data Off ; Isothermal 1.0 min; Data On ; Ramp 5.00 °C/min to -60.00 °C; Data Off ; Isothermal 1.0 min; Data On ; Ramp 5.00 °C/min to 160.00 °C; Data Off ; Isothermal 1.0 min; Data On ; Ramp 5.00 °C/min to 30.00 °C
[File Parameters]
Run date,6/20/2025 11:40:47 AM
Trios version,5.1.1.46572
Original File Name,
Current File Name,D:\DSC2500\Gibbons\2025_06_19_Sorbic_Acid_n60_160C_5Cmin_x3.tri
[Procedure]
Procedure Name,Sorbic_Acid_n60_160C_5Cmin_x3
Sample Name,2025_06_19_Sorbic_Acid_n60_160C_5Cmin_x3
Sample Mass,4.13 mg
Reference Sample Mass,0 mg
Pan Mass,55.98 mg
Pan Number,52
Reference Pan Mass,55.79 mg
Reference Pan Number,1
Pan Type,Tzero Aluminum Hermetic
Comments,Al Hermetic DSC Consumables sealed Pan/Lid. A2 Tray (Google Sheet: DSC_Samples_A2_Tray_May2025)
Project Name,CA
Operator,Gibbons
Test,Custom
Unload Max Temperature,30
Unload Min Temperature,30
Load Max Temperature,30
Load Min Temperature,30
Stop on Gas Flow Error,Yes
[Signal List]
Signal #1,Time (min)
Signal #2,Temperature (°C)
Signal #3,Heat Flow (mW)
Signal #4,Delta T (µV)
Signal #5,Delta Tzero (µV)
Signal #6,Tzero Temperature (°C)
Signal #7,Cell Purge (mL/min)
Signal #8,Heater Temp (°C)
Signal #9,Power Delivered (W)
Signal #10,Reference Junction Temperature (°C)
Signal #11,Flange Temperature (°C)
Signal #12,Heat Flow Phase (rad)
Signal #13,Total Heat Capacity (J/°C)
Signal #14,Heat Capacity (J/°C)
[Configuration]
Company Name,ASU
Instrument Name,DSC2A-00468
Instrument Type,DSC2500
Serial Number,DSC2A-00468
IP,192.168.1.100
Location of Instrument,MRRC
DisplayType,Unknown
Sample Interval ,0.1 s/pt
Selected Heat Flow,T4P
Exotherm Direction,Down
Cell Serial,DRC2-00792
Lid Type,Standard
Cooler,RCS 90
Leave Cooler on at End of Sequence,On
Gas 2,Nitrogen
Gas Selected,Channel 1
Flow Rate,50 mL/min
Secondary Purge,On
Licensed Heat Flow,Heat Flow T4P
Modulation Licensed,Yes
[Versions]
Common IDD Version,1
Cortex Version,VER 2.10.2.31
Driver,5.0.0.6
GDM Version,1.0.3.3
TouchscreenVersion,1.0.0.16145
FEP Version,1.2.1.21
FEP Bootloader,2.0.0.5
AutoSampler Version,2.1.1.26
Auto Sampler Bootloader,2.0.0.5
FCM Version,1.1.0.3
FCM Bootloader,2.0.0.5
[Experiment Logs]
Experiment Log Entry # 1,Data On set to 0
Experiment Log Entry # 3,Equilibrate Segment -60 (C) Started
Experiment Log Entry # 5,Air Cool is off.
Experiment Log Entry # 7,Data On set to 1
Experiment Log Entry # 9,Ramp Segment 5 C/min to 160 Started
Experiment Log Entry # 11,Data On set to 0
Experiment Log Entry # 13,Isothermal Segment 1 min started
Experiment Log Entry # 15,Data On set to 1
Experiment Log Entry # 17,Ramp Segment 5 C/min to -60 Started
Experiment Log Entry # 19,Data On set to 0
Experiment Log Entry # 21,Isothermal Segment 1 min started
Experiment Log Entry # 23,Data On set to 1
Experiment Log Entry # 25,Ramp Segment 5 C/min to 160 Started
Experiment Log Entry # 27,FEP has detected that GDM has gone offline
Experiment Log Entry # 29,Data On set to 0
Experiment Log Entry # 31,Isothermal Segment 1 min started
Experiment Log Entry # 33,Data On set to 1
Experiment Log Entry # 35,Ramp Segment 5 C/min to -60 Started
Experiment Log Entry # 37,Auto sampler has detected that FEP has gone offline
Experiment Log Entry # 39,Data On set to 0
Experiment Log Entry # 41,Isothermal Segment 1 min started
Experiment Log Entry # 43,Data On set to 1
Experiment Log Entry # 45,Ramp Segment 5 C/min to 160 Started
Experiment Log Entry # 47,Data On set to 0
Experiment Log Entry # 49,Isothermal Segment 1 min started
Experiment Log Entry # 51,Data On set to 1
Experiment Log Entry # 53,Ramp Segment 5 C/min to 30 Started
[Method Log]
Method Log Entry # 1,Data Off
Method Log Entry # 2,Equilibrate -60 °C
Method Log Entry # 3,Data On
Method Log Entry # 4,(Ramp 649741) Ramp 5 °C/minute to 160 °C
Method Log Entry # 5,Data Off
Method Log Entry # 6,Isothermal 1 minutes
Method Log Entry # 7,Data On
Method Log Entry # 8,(Ramp 649745) Ramp 5 °C/minute to -60 °C
Method Log Entry # 9,Data Off
Method Log Entry # 10,Isothermal 1 minutes
Method Log Entry # 11,Data On
Method Log Entry # 12,(Ramp 649749) Ramp 5 °C/minute to 160 °C
Method Log Entry # 13,Data Off
Method Log Entry # 14,Isothermal 1 minutes
Method Log Entry # 15,Data On
Method Log Entry # 16,(Ramp 649753) Ramp 5 °C/minute to -60 °C
Method Log Entry # 17,Data Off
Method Log Entry # 18,Isothermal 1 minutes
Method Log Entry # 19,Data On
Method Log Entry # 20,(Ramp 649757) Ramp 5 °C/minute to 160 °C
Method Log Entry # 21,Data Off
Method Log Entry # 22,Isothermal 1 minutes
Method Log Entry # 23,Data On
Method Log Entry # 24,(Ramp 649761) Ramp 5 °C/minute to 30 °C
Cell Serial,DRC2-00792
[T1 Calibration]
Slope,-0.008529666
Offset,9.636258
Initial Temperature,98.23
GUID,f8bfdadc-4977-4fdf-ba6d-0ba9134940c3
[TZero Calibration]
Date Applied,11/29/2022 4:06:13 PM
Description,From -89.059 °C to 396.009 °C at 20.000°C/min
Gas Type,Nitrogen
Pan Type,None
Source Files 1,C:\Users\yargerlab\Desktop\DSC Data\General\TZero_calibration_11_29_22_2nd(2).tri
Source Files 2,C:\Users\yargerlab\Desktop\DSC Data\General\TZero_calibration_11_29_22_2nd(3).tri
Delta T Offset,13.05235
Delta T Slope,-0.007271007
Delta T0 Offset,-13.69128
Delta T0 Slope,0.06063341
[Temperature Calibration]
Date Applied,11/29/2022 7:12:28 PM
Description,From 106.590 °C to 186.590 °C at 10.000°C/min
Gas Type,Nitrogen
Pan Type,Tzero Aluminum Hermetic
Source Files 1,C:\Users\yargerlab\Desktop\DSC Data\General\Indium(6).tri
Measured 1,157.391
Known 1,156.598
[Cell Constant Calibration]
Date Applied,11/29/2022 7:12:29 PM
Description,From 106.590 °C to 186.590 °C at 10.000°C/min
Gas Type,Nitrogen
Pan Type,Tzero Aluminum Hermetic
Source Files 1,C:\Users\yargerlab\Desktop\DSC Data\General\Indium(6).tri
T4P KCell,1.006051
Onset Slope,63.26126 mW/°C
[Direct Cp Calibration]
Date Applied,11/30/2022 11:04:51 AM
Description,From -79.983 °C to 298.409 °C at 10.000°C/min
Gas Type,Nitrogen
Pan Type,Tzero Aluminum Hermetic
Source Files 1,C:\Users\yargerlab\Desktop\DSC Data\General\Sapphire_Heat_Capacity_11_30_22.tri
[Rev Cp Calibration]
Date Applied,11/30/2022 1:58:51 PM
Description,From -79.996 °C to 292.812 °C at 3.000°C/min
Gas Type,Nitrogen
Pan Type,Tzero Aluminum Hermetic
Source Files 1,C:\Users\yargerlab\Desktop\DSC Data\General\Sapphire_MDSC_Calibration_11_30_22.tri
[step]
Ramp 5.00 °C/min to 160.00 °C
Time,Temperature,Heat Flow (Normalized)
min,°C,W/g
0.00,-59.68,-0.062
0.03,-59.70,-0.058
0.06,-59.70,-0.056
0.09,-59.67,-0.084
0.12,-59.61,-0.098
0.15,-59.52,-0.096
0.18,-59.42,-0.063
0.21,-59.31,-0.032
0.24,-59.19,-0.008
0.27,-59.06,0.010
0.30,-58.94,0.022
0.33,-58.80,0.033
0.36,-58.67,0.041
0.39,-58.53,0.048
0.42,-58.39,0.053
0.45,-58.25,0.056
0.48,-58.11,0.060
0.51,-57.97,0.061
0.54,-57.82,0.063
0.57,-57.68,0.064
0.60,-57.53,0.066
0.63,-57.39,0.066
0.66,-57.24,0.067
0.69,-57.10,0.067
0.72,-56.95,0.068
0.75,-56.80,0.069
0.78,-56.66,0.069
0.81,-56.51,0.070
0.84,-56.36,0.070
0.87,-56.21,0.070
0.90,-56.07,0.071
0.93,-55.92,0.071
0.96,-55.77,0.071
0.99,-55.62,0.072
1.02,-55.47,0.072
1.05,-55.33,0.072
1.08,-55.18,0.072
1.11,-55.03,0.072
1.14,-54.88,0.072
1.17,-54.73,0.073
1.20,-54.58,0.073
1.23,-54.43,0.073
1.26,-54.28,0.073
1.29,-54.13,0.073
1.32,-53.99,0.073
1.35,-53.84,0.073
1.38,-53.69,0.073
1.41,-53.54,0.073
1.44,-53.39,0.073
1.47,-53.24,0.073
1.50,-53.09,0.073
1.53,-52.94,0.072
1.56,-52.79,0.072
1.59,-52.64,0.072
1.62,-52.49,0.072
1.65,-52.34,0.072
1.68,-52.19,0.072
1.71,-52.04,0.072
1.74,-51.89,0.072
1.77,-51.74,0.072
1.80,-51.59,0.072
1.83,-51.44,0.072
1.86,-51.29,0.072
1.89,-51.14,0.072
1.92,-51.00,0.072
1.95,-50.84,0.072
1.98,-50.69,0.072
2.01,-50.54,0.072
2.04,-50.40,0.072
2.07,-50.25,0.072
2.10,-50.10,0.072
2.13,-49.95,0.072
2.16,-49.80,0.072
2.19,-49.65,0.071
2.22,-49.50,0.071
2.25,-49.35,0.071
2.28,-49.20,0.071
2.31,-49.05,0.071
2.34,-48.90,0.071
2.37,-48.75,0.071
2.40,-48.60,0.071
2.43,-48.45,0.071
2.46,-48.30,0.071
2.49,-48.15,0.071
2.52,-48.00,0.071
2.55,-47.85,0.071
2.58,-47.70,0.070
2.61,-47.55,0.070
2.64,-47.40,0.070
2.67,-47.25,0.070
2.70,-47.10,0.070
2.73,-46.95,0.070
2.76,-46.80,0.070
2.79,-46.65,0.070
2.82,-46.50,0.070
2.85,-46.35,0.070
2.88,-46.20,0.070
2.91,-46.05,0.070
2.94,-45.90,0.070
2.97,-45.75,0.070
3.00,-45.60,0.070
3.03,-45.45,0.070
3.06,-45.30,0.070
3.09,-45.15,0.070
3.12,-45.00,0.070
3.15,-44.85,0.070
3.18,-44.70,0.070
3.21,-44.55,0.070
3.24,-44.40,0.070
3.27,-44.25,0.070
3.30,-44.10,0.070
3.33,-43.95,0.070
3.36,-43.80,0.070
3.39,-43.65,0.070
3.42,-43.50,0.069
3.45,-43.35,0.069
3.48,-43.20,0.069
3.51,-43.05,0.069
3.54,-42.90,0.069
3.57,-42.75,0.069
3.60,-42.60,0.069
3.63,-42.45,0.069
3.66,-42.30,0.069
3.69,-42.15,0.069
3.72,-42.00,0.069
3.75,-41.85,0.069
3.78,-41.70,0.069
3.81,-41.55,0.069
3.84,-41.40,0.069
3.87,-41.25,0.069
3.90,-41.10,0.069
3.93,-40.95,0.069
3.96,-40.80,0.069
3.99,-40.65,0.069
4.02,-40.50,0.069
4.05,-40.35,0.069
4.08,-40.20,0.069
4.11,-40.05,0.069
4.14,-39.90,0.069
4.17,-39.75,0.069
4.20,-39.60,0.069
4.23,-39.45,0.069
4.26,-39.30,0.068
4.29,-39.15,0.069
4.32,-39.00,0.069
4.35,-38.85,0.069
4.38,-38.70,0.069
4.41,-38.55,0.069
4.44,-38.40,0.068
4.47,-38.25,0.068
4.50,-38.10,0.068
4.53,-37.95,0.068
4.56,-37.80,0.068
4.59,-37.65,0.068
4.62,-37.50,0.068
4.65,-37.35,0.068
4.68,-37.19,0.068
4.71,-37.04,0.068
4.74,-36.89,0.068
4.77,-36.74,0.068
4.80,-36.59,0.068
4.83,-36.44,0.068
4.86,-36.29,0.068
4.89,-36.14,0.068
4.92,-35.99,0.068
4.95,-35.84,0.068
4.98,-35.69,0.068
5.01,-35.54,0.068
5.04,-35.39,0.068
5.07,-35.24,0.068
5.10,-35.09,0.068
5.13,-34.94,0.068
5.16,-34.79,0.068
5.19,-34.64,0.068
5.22,-34.49,0.068
5.25,-34.34,0.068
5.28,-34.19,0.068
5.31,-34.04,0.068
5.34,-33.89,0.068
5.37,-33.74,0.068
5.40,-33.59,0.068
5.43,-33.44,0.068
5.46,-33.29,0.068
5.49,-33.14,0.068
5.52,-32.99,0.068
5.55,-32.84,0.068
5.58,-32.69,0.068
5.61,-32.54,0.068
5.64,-32.39,0.068
5.67,-32.24,0.068
5.70,-32.09,0.068
5.73,-31.94,0.068
5.76,-31.79,0.068
5.79,-31.64,0.068
5.82,-31.49,0.068
5.85,-31.34,0.068
5.88,-31.19,0.068
5.91,-31.04,0.068
5.94,-30.89,0.068
5.97,-30.74,0.067
6.00,-30.59,0.067
6.03,-30.44,0.068
6.06,-30.29,0.068
6.09,-30.14,0.068
6.12,-29.99,0.068
6.15,-29.83,0.067
6.18,-29.68,0.067
6.21,-29.54,0.067
6.24,-29.38,0.068
6.27,-29.23,0.068
6.30,-29.08,0.068
6.33,-28.94,0.068
6.36,-28.79,0.067
6.39,-28.63,0.067
6.42,-28.48,0.067
6.45,-28.33,0.067
6.48,-28.18,0.067
6.51,-28.03,0.067
6.54,-27.88,0.067
6.57,-27.73,0.067
6.60,-27.58,0.067
6.63,-27.43,0.067
6.66,-27.28,0.067
6.69,-27.13,0.067
6.72,-26.98,0.067
6.75,-26.83,0.067
6.78,-26.68,0.067
6.81,-26.53,0.067
6.84,-26.38,0.067
6.87,-26.23,0.067
6.90,-26.08,0.067
6.93,-25.93,0.067
6.96,-25.78,0.067
6.99,-25.63,0.067
7.02,-25.48,0.067
7.05,-25.33,0.067
7.08,-25.18,0.067
7.11,-25.03,0.067
7.14,-24.88,0.067
7.17,-24.73,0.067
7.20,-24.58,0.067
7.23,-24.43,0.067
7.26,-24.28,0.067
7.29,-24.13,0.067
7.32,-23.98,0.067
7.35,-23.83,0.067
7.38,-23.68,0.067
7.41,-23.53,0.067
7.44,-23.38,0.067
7.47,-23.23,0.067
7.50,-23.08,0.067
7.53,-22.93,0.067
7.56,-22.78,0.067
7.59,-22.63,0.067
7.62,-22.48,0.067
7.65,-22.33,0.067
7.68,-22.18,0.067
7.71,-22.03,0.067
7.74,-21.88,0.067
7.77,-21.73,0.067
7.80,-21.58,0.067
7.83,-21.43,0.067
7.86,-21.28,0.067
7.89,-21.13,0.067
7.92,-20.98,0.067
7.95,-20.83,0.067
7.98,-20.68,0.067
8.01,-20.53,0.067
8.04,-20.38,0.067
8.07,-20.23,0.067
8.10,-20.08,0.067
8.13,-19.93,0.067
8.16,-19.78,0.067
8.19,-19.63,0.067
8.22,-19.47,0.067
8.25,-19.33,0.067
8.28,-19.18,0.067
8.31,-19.03,0.066
8.34,-18.87,0.067
8.37,-18.72,0.067
8.40,-18.58,0.067
8.43,-18.43,0.066
8.46,-18.28,0.066
8.49,-18.12,0.067
8.52,-17.97,0.066
8.55,-17.82,0.066
8.58,-17.68,0.066
8.61,-17.53,0.066
8.64,-17.37,0.066
8.67,-17.22,0.066
8.70,-17.07,0.066
8.73,-16.93,0.066
8.76,-16.77,0.066
8.79,-16.62,0.066
8.82,-16.47,0.066
8.85,-16.32,0.066
8.88,-16.17,0.066
8.91,-16.02,0.066
8.94,-15.87,0.066
8.97,-15.72,0.066
9.00,-15.57,0.066
9.03,-15.42,0.066
9.06,-15.27,0.066
9.09,-15.12,0.066
9.12,-14.97,0.066
9.15,-14.82,0.066
9.18,-14.67,0.066
9.21,-14.52,0.067
9.24,-14.37,0.067
9.27,-14.22,0.066
9.30,-14.07,0.066
9.33,-13.92,0.067
9.36,-13.77,0.066
9.39,-13.62,0.066
9.42,-13.47,0.066
9.45,-13.32,0.066
9.48,-13.17,0.066
9.51,-13.02,0.066
9.54,-12.87,0.066
9.57,-12.72,0.066
9.60,-12.57,0.066
9.63,-12.42,0.066
9.66,-12.27,0.067
9.69,-12.12,0.067
9.72,-11.97,0.067
9.75,-11.82,0.067
9.78,-11.67,0.067
9.81,-11.52,0.066
9.84,-11.37,0.066
9.87,-11.22,0.067
9.90,-11.07,0.067
9.93,-10.92,0.067
9.96,-10.77,0.067
9.99,-10.62,0.067
10.02,-10.47,0.067
10.05,-10.32,0.067
10.08,-10.17,0.067
10.11,-10.02,0.067
10.14,-9.87,0.067
10.17,-9.72,0.067
10.20,-9.57,0.067
10.23,-9.42,0.067
10.26,-9.27,0.067
10.29,-9.12,0.067
10.32,-8.97,0.067
10.35,-8.82,0.067
10.38,-8.67,0.067
10.41,-8.52,0.067
10.44,-8.37,0.067
10.47,-8.22,0.067
10.50,-8.06,0.067
10.53,-7.91,0.067
10.56,-7.77,0.067
10.59,-7.61,0.067
10.62,-7.46,0.067
10.65,-7.31,0.067
10.68,-7.17,0.067
10.71,-7.01,0.067
10.74,-6.86,0.067
10.77,-6.71,0.067
10.80,-6.56,0.067
10.83,-6.41,0.067
10.86,-6.26,0.067
10.89,-6.11,0.066
10.92,-5.96,0.066
10.95,-5.81,0.066
10.98,-5.66,0.066
11.01,-5.51,0.066
11.04,-5.36,0.066
11.07,-5.21,0.066
11.10,-5.06,0.066
11.13,-4.91,0.066
11.16,-4.76,0.066
11.19,-4.61,0.066
11.22,-4.46,0.066
11.25,-4.31,0.067
11.28,-4.16,0.067
11.31,-4.01,0.067
11.34,-3.86,0.067
11.37,-3.71,0.067
11.40,-3.56,0.067
11.43,-3.41,0.067
11.46,-3.26,0.067
11.49,-3.11,0.067
11.52,-2.96,0.067
11.55,-2.81,0.067
11.58,-2.66,0.067
11.61,-2.51,0.067
11.64,-2.36,0.067
11.67,-2.21,0.067
11.70,-2.06,0.067
11.73,-1.91,0.067
11.76,-1.76,0.067
11.79,-1.61,0.067
11.82,-1.46,0.067
11.85,-1.31,0.067
11.88,-1.16,0.067
11.91,-1.01,0.067
11.94,-0.86,0.067
11.97,-0.71,0.067
12.00,-0.56,0.067
12.03,-0.41,0.067
12.06,-0.26,0.067
12.09,-0.11,0.067
12.12,0.04,0.067
12.15,0.19,0.067
12.18,0.34,0.067
12.21,0.49,0.067
12.24,0.64,0.067
12.27,0.79,0.067
12.30,0.94,0.067
12.33,1.09,0.067
12.36,1.24,0.067
12.39,1.39,0.067
12.42,1.54,0.067
12.45,1.69,0.067
12.48,1.84,0.067
12.51,1.99,0.067
12.54,2.14,0.067
12.57,2.29,0.067
12.60,2.44,0.067
12.63,2.59,0.067
12.66,2.74,0.067
12.69,2.89,0.067
12.72,3.04,0.067
12.75,3.19,0.067
12.78,3.34,0.067
12.81,3.50,0.067
12.84,3.65,0.067
12.87,3.80,0.066
12.90,3.95,0.066
12.93,4.10,0.066
12.96,4.25,0.067
12.99,4.40,0.068
13.02,4.55,0.068
13.05,4.70,0.068
13.08,4.85,0.068
13.11,5.00,0.068
13.14,5.15,0.068
13.17,5.30,0.068
13.20,5.45,0.068
13.23,5.60,0.067
13.26,5.75,0.067
13.29,5.90,0.067
13.32,6.05,0.068
13.35,6.20,0.067
13.38,6.35,0.068
13.41,6.50,0.067
13.44,6.65,0.067
13.47,6.80,0.067
13.50,6.95,0.067
13.53,7.10,0.067
13.56,7.25,0.067
13.59,7.40,0.067
13.62,7.55,0.067
13.65,7.70,0.067
13.68,7.85,0.067
13.71,8.00,0.067
13.74,8.15,0.067
13.77,8.30,0.067
13.80,8.45,0.067
13.83,8.60,0.067
13.86,8.75,0.067
13.89,8.90,0.067
13.92,9.05,0.067
13.95,9.20,0.067
13.98,9.35,0.067
14.01,9.50,0.067
14.04,9.65,0.067
14.07,9.80,0.067
14.10,9.95,0.067
14.13,10.10,0.067
14.16,10.25,0.067
14.19,10.40,0.067
14.22,10.55,0.067
14.25,10.70,0.067
14.28,10.85,0.067
14.31,11.00,0.067
14.34,11.15,0.067
14.37,11.30,0.067
14.40,11.45,0.067
14.43,11.60,0.067
14.46,11.75,0.067
14.49,11.90,0.067
14.52,12.05,0.067
14.55,12.20,0.067
14.58,12.35,0.067
14.61,12.50,0.067
14.64,12.65,0.068
14.67,12.80,0.068
14.70,12.95,0.067
14.73,13.10,0.068
14.76,13.25,0.068
14.79,13.40,0.068
14.82,13.55,0.068
14.85,13.70,0.068
14.88,13.85,0.068
14.91,14.00,0.068
14.94,14.15,0.068
14.97,14.30,0.068
15.00,14.45,0.068
15.03,14.60,0.068
15.06,14.75,0.068
15.09,14.90,0.068
15.12,15.05,0.068
15.15,15.20,0.068
15.18,15.35,0.068
15.21,15.50,0.068
15.24,15.65,0.068
15.27,15.81,0.068
15.30,15.95,0.068
15.33,16.11,0.068
15.36,16.25,0.068
15.39,16.41,0.068
15.42,16.56,0.068
15.45,16.71,0.068
15.48,16.86,0.068
15.51,17.01,0.068
15.54,17.16,0.068
15.57,17.31,0.068
15.60,17.46,0.068
15.63,17.61,0.068
15.66,17.76,0.068
15.69,17.91,0.068
15.72,18.06,0.068
15.75,18.21,0.068
15.78,18.36,0.068
15.81,18.51,0.068
15.84,18.66,0.068
15.87,18.81,0.068
15.90,18.96,0.068
15.93,19.11,0.068
15.96,19.26,0.068
15.99,19.41,0.068
16.02,19.56,0.068
16.05,19.71,0.068
16.08,19.86,0.069
16.11,20.01,0.069
16.14,20.16,0.069
16.17,20.31,0.069
16.20,20.46,0.068
16.23,20.61,0.069
16.26,20.76,0.069
16.29,20.91,0.069
16.32,21.06,0.069
16.35,21.21,0.069
16.38,21.36,0.069
16.41,21.51,0.069
16.44,21.66,0.069
16.47,21.81,0.069
16.50,21.96,0.069
16.53,22.11,0.069
16.56,22.26,0.069
16.59,22.41,0.069
16.62,22.56,0.069
16.65,22.71,0.069
16.68,22.86,0.069
16.71,23.01,0.069
16.74,23.16,0.069
16.77,23.31,0.069
16.80,23.46,0.069
16.83,23.61,0.069
16.86,23.76,0.069
16.89,23.91,0.069
16.92,24.06,0.069
16.95,24.21,0.069
16.98,24.36,0.069
17.01,24.51,0.069
17.04,24.66,0.069
17.07,24.81,0.069
17.10,24.96,0.069
17.13,25.11,0.069
17.16,25.26,0.069
17.19,25.41,0.069
17.22,25.56,0.069
17.25,25.71,0.069
17.28,25.86,0.069
17.31,26.01,0.069
17.34,26.16,0.069
17.37,26.31,0.069
17.40,26.46,0.069
17.43,26.61,0.069
17.46,26.76,0.069
17.49,26.91,0.069
17.52,27.06,0.069
17.55,27.21,0.070
17.58,27.37,0.070
17.61,27.51,0.070
17.64,27.66,0.070
17.67,27.81,0.070
17.70,27.96,0.070
17.73,28.12,0.070
17.76,28.26,0.070
17.79,28.42,0.070
17.82,28.57,0.070
17.85,28.72,0.070
17.88,28.87,0.070
17.91,29.02,0.070
17.94,29.17,0.070
17.97,29.32,0.070
18.00,29.46,0.070
18.03,29.62,0.070
18.06,29.76,0.070
18.09,29.92,0.070
18.12,30.07,0.070
18.15,30.22,0.070
18.18,30.37,0.070
18.21,30.52,0.070
18.24,30.67,0.070
18.27,30.82,0.070
18.30,30.97,0.070
18.33,31.12,0.070
18.36,31.27,0.070
18.39,31.42,0.070
18.42,31.57,0.070
18.45,31.72,0.070
18.48,31.87,0.070
18.51,32.02,0.070
18.54,32.17,0.070
18.57,32.32,0.070
18.60,32.47,0.070
18.63,32.62,0.070
18.66,32.77,0.071
18.69,32.92,0.071
18.72,33.07,0.071
18.75,33.22,0.071
18.78,33.37,0.070
18.81,33.52,0.070
18.84,33.67,0.070
18.87,33.82,0.071
18.90,33.97,0.070
18.93,34.12,0.071
18.96,34.27,0.070
18.99,34.42,0.071
19.02,34.57,0.071
19.05,34.72,0.071
19.08,34.87,0.071
19.11,35.02,0.071
19.14,35.17,0.071
19.17,35.32,0.071
19.20,35.47,0.071
19.23,35.62,0.071
19.26,35.77,0.071
19.29,35.92,0.071
19.32,36.07,0.071
19.35,36.22,0.071
19.38,36.37,0.071
19.41,36.52,0.070
19.44,36.67,0.071
19.47,36.82,0.071
19.50,36.97,0.071
19.53,37.12,0.071
19.56,37.27,0.071
19.59,37.42,0.071
19.62,37.57,0.071
19.65,37.72,0.071
19.68,37.87,0.071
19.71,38.02,0.071
19.74,38.17,0.071
19.77,38.32,0.071
19.80,38.47,0.071
19.83,38.62,0.071
19.86,38.77,0.071
19.89,38.92,0.071
19.92,39.07,0.071
19.95,39.22,0.071
19.98,39.37,0.071
20.01,39.52,0.071
20.04,39.67,0.071
20.07,39.82,0.071
20.10,39.97,0.071
20.13,40.12,0.071
20.16,40.27,0.071
20.19,40.42,0.071
20.22,40.57,0.071
20.25,40.72,0.071
20.28,40.87,0.071
20.31,41.02,0.071
20.34,41.17,0.071
20.37,41.32,0.071
20.40,41.47,0.071
20.43,41.62,0.071
20.46,41.77,0.071
20.49,41.92,0.071
20.52,42.07,0.071
20.55,42.22,0.071
20.58,42.37,0.071
20.61,42.52,0.071
20.64,42.67,0.071
20.67,42.82,0.071
20.70,42.97,0.071
20.73,43.12,0.071
20.76,43.27,0.071
20.79,43.42,0.071
20.82,43.57,0.071
20.85,43.72,0.072
20.88,43.87,0.072
20.91,44.02,0.072
20.94,44.18,0.072
20.97,44.32,0.072
21.00,44.47,0.072
21.03,44.62,0.072
21.06,44.77,0.072
21.09,44.92,0.072
21.12,45.07,0.072
21.15,45.23,0.072
21.18,45.37,0.072
21.21,45.53,0.072
21.24,45.68,0.072
21.27,45.83,0.072
21.30,45.97,0.072
21.33,46.13,0.072
21.36,46.28,0.072
21.39,46.43,0.072
21.42,46.58,0.072
21.45,46.73,0.072
21.48,46.87,0.072
21.51,47.03,0.072
21.54,47.18,0.072
21.57,47.33,0.072
21.60,47.48,0.072
21.63,47.63,0.072
21.66,47.78,0.072
21.69,47.93,0.072
21.72,48.08,0.072
21.75,48.23,0.072
21.78,48.38,0.072
21.81,48.53,0.072
21.84,48.68,0.072
21.87,48.83,0.072
21.90,48.98,0.072
21.93,49.13,0.072
21.96,49.28,0.072
21.99,49.43,0.073
22.02,49.58,0.073
22.05,49.73,0.073
22.08,49.88,0.073
22.11,50.03,0.073
22.14,50.18,0.073
22.17,50.33,0.073
22.20,50.48,0.073
22.23,50.63,0.073
22.26,50.78,0.073
22.29,50.93,0.073
22.32,51.08,0.073
22.35,51.23,0.073
22.38,51.38,0.073
22.41,51.53,0.073
22.44,51.68,0.073
22.47,51.83,0.073
22.50,51.98,0.073
22.53,52.13,0.073
22.56,52.28,0.073
22.59,52.43,0.073
22.62,52.58,0.073
22.65,52.73,0.073
22.68,52.88,0.073
22.71,53.03,0.073
22.74,53.18,0.073
22.77,53.33,0.073
22.80,53.48,0.073
22.83,53.63,0.073
22.86,53.78,0.073
22.89,53.93,0.073
22.92,54.08,0.073
22.95,54.23,0.073
22.98,54.38,0.073
23.01,54.53,0.073
23.04,54.68,0.074
23.07,54.83,0.074
23.10,54.98,0.074
23.13,55.13,0.074
23.16,55.28,0.074
23.19,55.43,0.074
23.22,55.58,0.074
23.25,55.73,0.074
23.28,55.88,0.074
23.31,56.03,0.074
23.34,56.18,0.074
23.37,56.33,0.074
23.40,56.48,0.074
23.43,56.63,0.074
23.46,56.78,0.074
23.49,56.93,0.074
23.52,57.08,0.074
23.55,57.23,0.074
23.58,57.38,0.074
23.61,57.53,0.074
23.64,57.68,0.074
23.67,57.83,0.074
23.70,57.98,0.074
23.73,58.13,0.074
23.76,58.28,0.074
23.79,58.43,0.074
23.82,58.58,0.074
23.85,58.73,0.074
23.88,58.88,0.074
23.91,59.03,0.074
23.94,59.18,0.074
23.97,59.33,0.074
24.00,59.48,0.074
24.03,59.63,0.074
24.06,59.78,0.074
24.09,59.93,0.074
24.12,60.08,0.074
24.15,60.23,0.074
24.18,60.38,0.074
24.21,60.53,0.074
24.24,60.68,0.075
24.27,60.83,0.074
24.30,60.98,0.074
24.33,61.13,0.075
24.36,61.28,0.074
24.39,61.43,0.074
24.42,61.58,0.075
24.45,61.73,0.075
24.48,61.88,0.075
24.51,62.03,0.075
24.54,62.19,0.075
24.57,62.33,0.075
24.60,62.49,0.075
24.63,62.64,0.075
24.66,62.78,0.075
24.69,62.93,0.075
24.72,63.08,0.075
24.75,63.23,0.075
24.78,63.38,0.075
24.81,63.53,0.075
24.84,63.68,0.075
24.87,63.83,0.075
24.90,63.98,0.075
24.93,64.13,0.075
24.96,64.28,0.075
24.99,64.43,0.075
25.02,64.58,0.075
25.05,64.73,0.075
25.08,64.88,0.075
25.11,65.03,0.075
25.14,65.19,0.075
25.17,65.33,0.075
25.20,65.48,0.075
25.23,65.64,0.075
25.26,65.79,0.075
25.29,65.94,0.075
25.32,66.09,0.075
25.35,66.24,0.075
25.38,66.39,0.075
25.41,66.54,0.075
25.44,66.69,0.075
25.47,66.84,0.076
25.50,66.99,0.076
25.53,67.14,0.076
25.56,67.29,0.076
25.59,67.44,0.076
25.62,67.59,0.076
25.65,67.74,0.076
25.68,67.89,0.076
25.71,68.04,0.076
25.74,68.19,0.076
25.77,68.34,0.076
25.80,68.49,0.076
25.83,68.64,0.076
25.86,68.79,0.076
25.89,68.94,0.076
25.92,69.09,0.076
25.95,69.24,0.076
25.98,69.39,0.076
26.01,69.54,0.076
26.04,69.69,0.076
26.07,69.84,0.076
26.10,69.99,0.076
26.13,70.14,0.076
26.16,70.29,0.076
26.19,70.44,0.076
26.22,70.59,0.077
26.25,70.74,0.077
26.28,70.89,0.077
26.31,71.04,0.077
26.34,71.19,0.077
26.37,71.34,0.077
26.40,71.49,0.077
26.43,71.64,0.077
26.46,71.79,0.077
26.49,71.94,0.077
26.52,72.09,0.077
26.55,72.24,0.077
26.58,72.39,0.077
26.61,72.54,0.077
26.64,72.69,0.077
26.67,72.84,0.077
26.70,72.99,0.077
26.73,73.14,0.077
26.76,73.29,0.077
26.79,73.44,0.077
26.82,73.59,0.077
26.85,73.74,0.077
26.88,73.89,0.077
26.91,74.04,0.077
26.94,74.19,0.077
26.97,74.34,0.077
27.00,74.49,0.078
27.03,74.64,0.078
27.06,74.79,0.078
27.09,74.94,0.078
27.12,75.09,0.078
27.15,75.24,0.078
27.18,75.39,0.078
27.21,75.54,0.078
27.24,75.69,0.078
27.27,75.84,0.078
27.30,75.99,0.078
27.33,76.14,0.078
27.36,76.29,0.078
27.39,76.44,0.078
27.42,76.59,0.078
27.45,76.74,0.078
27.48,76.89,0.078
27.51,77.04,0.078
27.54,77.19,0.078
27.57,77.35,0.078
27.60,77.50,0.078
27.63,77.64,0.078
27.66,77.79,0.078
27.69,77.95,0.078
27.72,78.10,0.078
27.75,78.25,0.079
27.78,78.40,0.079
27.81,78.55,0.079
27.84,78.70,0.079
27.87,78.85,0.079
27.90,79.00,0.079
27.93,79.15,0.079
27.96,79.30,0.079
27.99,79.45,0.079
28.02,79.60,0.079
28.05,79.75,0.079
28.08,79.90,0.079
28.11,80.05,0.079
28.14,80.20,0.079
28.17,80.35,0.079
28.20,80.50,0.079
28.23,80.65,0.079
28.26,80.80,0.079
28.29,80.95,0.080
28.32,81.10,0.080
28.35,81.25,0.080
28.38,81.40,0.080
28.41,81.55,0.080
28.44,81.70,0.080
28.47,81.85,0.080
28.50,82.00,0.080
28.53,82.15,0.080
28.56,82.30,0.080
28.59,82.45,0.080
28.62,82.60,0.080
28.65,82.75,0.080
28.68,82.90,0.080
28.71,83.05,0.080
28.74,83.20,0.080
28.77,83.35,0.080
28.80,83.50,0.080
28.83,83.65,0.080
28.86,83.80,0.080
28.89,83.95,0.080
28.92,84.10,0.080
28.95,84.25,0.080
28.98,84.40,0.080
29.01,84.55,0.080
29.04,84.70,0.080
29.07,84.85,0.080
29.10,85.00,0.080
29.13,85.15,0.080
29.16,85.30,0.081
29.19,85.45,0.081
29.22,85.60,0.081
29.25,85.75,0.081
29.28,85.90,0.081
29.31,86.05,0.081
29.34,86.20,0.081
29.37,86.35,0.081
29.40,86.50,0.081
29.43,86.65,0.081
29.46,86.80,0.081
29.49,86.95,0.081
29.52,87.10,0.081
29.55,87.25,0.081
29.58,87.40,0.081
29.61,87.55,0.081
29.64,87.70,0.081
29.67,87.85,0.081
29.70,88.00,0.081
29.73,88.15,0.081
29.76,88.30,0.081
29.79,88.45,0.081
29.82,88.60,0.082
29.85,88.75,0.082
29.88,88.90,0.082
29.91,89.05,0.082
29.94,89.20,0.082
29.97,89.35,0.082
30.00,89.50,0.082
30.03,89.65,0.082
30.06,89.80,0.083
30.09,89.95,0.083
30.12,90.10,0.083
30.15,90.25,0.083
30.18,90.40,0.083
30.21,90.55,0.083
30.24,90.70,0.083
30.27,90.85,0.083
30.30,91.00,0.083
30.33,91.15,0.083
30.36,91.30,0.083
30.39,91.45,0.084
30.42,91.60,0.084
30.45,91.75,0.084
30.48,91.90,0.084
30.51,92.05,0.084
30.54,92.20,0.084
30.57,92.35,0.085
30.60,92.50,0.085
30.63,92.65,0.085
30.66,92.80,0.085
30.69,92.95,0.085
30.72,93.10,0.085
30.75,93.25,0.085
30.78,93.40,0.085
30.81,93.55,0.085
30.84,93.70,0.085
30.87,93.85,0.086
30.90,94.00,0.086
30.93,94.15,0.086
30.96,94.30,0.086
30.99,94.45,0.086
31.02,94.60,0.086
31.05,94.75,0.086
31.08,94.90,0.086
31.11,95.05,0.086
31.14,95.20,0.086
31.17,95.35,0.087
31.20,95.50,0.087
31.23,95.65,0.087
31.26,95.80,0.087
31.29,95.95,0.087
31.32,96.10,0.088
31.35,96.25,0.088
31.38,96.40,0.088
31.41,96.55,0.088
31.44,96.70,0.088
31.47,96.85,0.088
31.50,97.00,0.089
31.53,97.15,0.089
31.56,97.30,0.089
31.59,97.45,0.089
31.62,97.60,0.089
31.65,97.75,0.089
31.68,97.90,0.089
31.71,98.05,0.089
31.74,98.20,0.090
31.77,98.35,0.090
31.80,98.50,0.090
31.83,98.65,0.090
31.86,98.80,0.090
31.89,98.95,0.090
31.92,99.10,0.090
31.95,99.25,0.090
31.98,99.40,0.090
32.01,99.55,0.090
32.04,99.70,0.091
32.07,99.85,0.091
32.10,100.00,0.091
32.13,100.15,0.091
32.16,100.30,0.091
32.19,100.45,0.091
32.22,100.61,0.092
32.25,100.76,0.092
32.28,100.90,0.092
32.31,101.05,0.092
32.34,101.20,0.093
32.37,101.35,0.093
32.40,101.51,0.093
32.43,101.66,0.093
32.46,101.80,0.093
32.49,101.96,0.094
32.52,102.11,0.094
32.55,102.26,0.094
32.58,102.40,0.094
32.61,102.55,0.094
32.64,102.70,0.095
32.67,102.85,0.095
32.70,103.00,0.095
32.73,103.15,0.095
32.76,103.30,0.095
32.79,103.45,0.096
32.82,103.60,0.096
32.85,103.75,0.096
32.88,103.90,0.096
32.91,104.05,0.096
32.94,104.20,0.096
32.97,104.35,0.096
33.00,104.50,0.097
33.03,104.65,0.097
33.06,104.80,0.097
33.09,104.95,0.097
33.12,105.10,0.098
33.15,105.25,0.098
33.18,105.40,0.098
33.21,105.55,0.099
33.24,105.70,0.099
33.27,105.85,0.099
33.30,106.00,0.099
33.33,106.15,0.100
33.36,106.30,0.100
33.39,106.45,0.100
33.42,106.60,0.101
33.45,106.75,0.101
33.48,106.90,0.101
33.51,107.05,0.101
33.54,107.20,0.101
33.57,107.35,0.101
33.60,107.50,0.101
33.63,107.65,0.102
33.66,107.81,0.102
33.69,107.95,0.102
33.72,108.10,0.102
33.75,108.25,0.102
33.78,108.40,0.102
33.81,108.55,0.102
33.84,108.70,0.103
33.87,108.85,0.103
33.90,109.00,0.103
33.93,109.15,0.103
33.96,109.30,0.103
33.99,109.45,0.103
34.02,109.60,0.104
34.05,109.75,0.104
34.08,109.90,0.104
34.11,110.05,0.105
34.14,110.20,0.105
34.17,110.35,0.106
34.20,110.50,0.106
34.23,110.65,0.106
34.26,110.80,0.107
34.29,110.95,0.107
34.32,111.10,0.107
34.35,111.25,0.107
34.38,111.40,0.107
34.41,111.55,0.108
34.44,111.70,0.108
34.47,111.85,0.108
34.50,112.00,0.108
34.53,112.15,0.109
34.56,112.30,0.109
34.59,112.45,0.110
34.62,112.60,0.110
34.65,112.75,0.110
34.68,112.90,0.110
34.71,113.05,0.111
34.74,113.20,0.111
34.77,113.35,0.111
34.80,113.50,0.112
34.83,113.65,0.112
34.86,113.80,0.112
34.89,113.95,0.112
34.92,114.10,0.113
34.95,114.25,0.113
34.98,114.40,0.113
35.01,114.55,0.114
35.04,114.70,0.114
35.07,114.85,0.114
35.10,115.00,0.115
35.13,115.15,0.115
35.16,115.30,0.115
35.19,115.45,0.116
35.22,115.60,0.117
35.25,115.75,0.117
35.28,115.90,0.117
35.31,116.05,0.118
35.34,116.20,0.119
35.37,116.35,0.119
35.40,116.50,0.120
35.43,116.65,0.120
35.46,116.80,0.121
35.49,116.95,0.121
35.52,117.10,0.122
35.55,117.25,0.122
35.58,117.40,0.123
35.61,117.55,0.123
35.64,117.70,0.124
35.67,117.85,0.125
35.70,118.00,0.125
35.73,118.15,0.126
35.76,118.30,0.127
35.79,118.45,0.130
35.82,118.60,0.130
35.85,118.75,0.131
35.88,118.90,0.131
35.91,119.05,0.132
35.94,119.20,0.132
35.97,119.35,0.134
36.00,119.50,0.136
36.03,119.65,0.136
36.06,119.80,0.137
36.09,119.95,0.137
36.12,120.10,0.138
36.15,120.25,0.140
36.18,120.40,0.141
36.21,120.55,0.142
36.24,120.70,0.143
36.27,120.85,0.143
36.30,121.00,0.146
36.33,121.15,0.148
36.36,121.30,0.149
36.39,121.45,0.151
36.42,121.60,0.152
36.45,121.75,0.153
36.48,121.90,0.154
36.51,122.05,0.158
36.54,122.20,0.159
36.57,122.35,0.160
36.60,122.50,0.161
36.63,122.65,0.163
36.66,122.80,0.165
36.69,122.95,0.166
36.72,123.10,0.171
36.75,123.25,0.174
36.78,123.40,0.175
36.81,123.54,0.178
36.84,123.69,0.181
36.87,123.84,0.183
36.90,123.99,0.184
36.93,124.14,0.185
36.96,124.29,0.186
36.99,124.44,0.189
37.02,124.59,0.192
37.05,124.74,0.199
37.08,124.89,0.205
37.11,125.04,0.206
37.14,125.19,0.207
37.17,125.33,0.208
37.20,125.48,0.214
37.23,125.63,0.222
37.26,125.78,0.225
37.29,125.93,0.230
37.32,126.08,0.235
37.35,126.23,0.238
37.38,126.38,0.241
37.41,126.53,0.246
37.44,126.68,0.255
37.47,126.82,0.262
37.50,126.97,0.267
37.53,127.12,0.267
37.56,127.27,0.272
37.59,127.42,0.283
37.62,127.57,0.297
37.65,127.71,0.304
37.68,127.86,0.312
37.71,128.01,0.324
37.74,128.16,0.339
37.77,128.30,0.349
37.80,128.45,0.357
37.83,128.60,0.376
37.86,128.74,0.385
37.89,128.89,0.401
37.92,129.04,0.412
37.95,129.18,0.411
37.98,129.34,0.380
38.01,129.49,0.427
38.04,129.63,0.459
38.07,129.77,0.481
38.10,129.92,0.502
38.13,130.06,0.515
38.16,130.21,0.529
38.19,130.35,0.574
38.22,130.49,0.651
38.25,130.63,0.716
38.28,130.76,0.793
38.31,130.89,0.896
38.34,131.02,1.012
38.37,131.14,1.126
38.40,131.27,1.226
38.43,131.39,1.346
38.46,131.51,1.481
38.49,131.63,1.608
38.52,131.74,1.737
38.55,131.86,1.868
38.58,131.98,2.019
38.61,132.09,2.141
38.64,132.21,2.279
38.67,132.32,2.455
38.70,132.43,2.640
38.73,132.54,2.774
38.76,132.65,2.937
38.79,132.76,3.100
38.82,132.87,3.260
38.85,132.98,3.384
38.88,133.09,3.552
38.91,133.21,3.653
38.94,133.33,3.724
38.97,133.45,3.826
39.00,133.58,3.855
39.03,133.72,3.892
39.06,133.85,3.936
39.09,133.99,3.913
39.12,134.14,3.903
39.15,134.29,3.865
39.18,134.47,3.565
39.21,134.69,2.998
39.24,134.95,2.250
39.27,135.27,1.376
39.30,135.58,0.893
39.33,135.86,0.635
39.36,136.11,0.442
39.39,136.33,0.301
39.42,136.53,0.199
39.45,136.71,0.127
39.48,136.89,0.073
39.51,137.06,0.035
39.54,137.22,0.009
39.57,137.38,-0.010
39.60,137.54,-0.021
39.63,137.69,-0.030
39.66,137.85,-0.032
39.69,138.00,-0.034
39.72,138.15,-0.034
39.75,138.30,-0.034
39.78,138.45,-0.032
39.81,138.60,-0.031
39.84,138.75,-0.029
39.87,138.90,-0.026
39.90,139.05,-0.022
39.93,139.20,-0.018
39.96,139.35,-0.013
39.99,139.49,-0.009
40.02,139.64,-0.006
40.05,139.79,-0.003
40.08,139.94,0.001
40.11,140.09,0.005
40.14,140.24,0.008
40.17,140.39,0.010
40.20,140.54,0.014
40.23,140.69,0.018
40.26,140.84,0.020
40.29,140.99,0.022
40.32,141.14,0.024
40.35,141.29,0.026
40.38,141.43,0.028
40.41,141.58,0.030
40.44,141.73,0.031
40.47,141.88,0.033
40.50,142.03,0.034
40.53,142.18,0.036
40.56,142.33,0.037
40.59,142.48,0.039
40.62,142.63,0.041
40.65,142.78,0.042
40.68,142.93,0.043
40.71,143.08,0.044
40.74,143.23,0.045
40.77,143.38,0.046
40.80,143.53,0.047
40.83,143.68,0.048
40.86,143.83,0.050
40.89,143.98,0.051
40.92,144.13,0.052
40.95,144.28,0.053
40.98,144.43,0.054
41.01,144.58,0.055
41.04,144.73,0.055
41.07,144.88,0.056
41.10,145.03,0.057
41.13,145.18,0.058
41.16,145.33,0.059
41.19,145.48,0.059
41.22,145.63,0.060
41.25,145.78,0.060
41.28,145.93,0.061
41.31,146.08,0.061
41.34,146.23,0.062
41.37,146.38,0.062
41.40,146.53,0.062
41.43,146.68,0.063
41.46,146.83,0.063
41.49,146.98,0.063
41.52,147.13,0.064
41.55,147.28,0.064
41.58,147.43,0.064
41.61,147.58,0.064
41.64,147.73,0.064
41.67,147.88,0.064
41.70,148.03,0.065
41.73,148.18,0.065
41.76,148.33,0.065
41.79,148.48,0.065
41.82,148.63,0.065
41.85,148.78,0.065
41.88,148.93,0.065
41.91,149.08,0.065
41.94,149.23,0.065
41.97,149.38,0.065
42.00,149.53,0.065
42.03,149.68,0.066
42.06,149.83,0.066
42.09,149.98,0.066
42.12,150.13,0.066
42.15,150.28,0.066
42.18,150.43,0.066
42.21,150.58,0.066
42.24,150.73,0.066
42.27,150.88,0.066
42.30,151.03,0.066
42.33,151.18,0.066
42.36,151.33,0.065
42.39,151.48,0.066
42.42,151.63,0.066
42.45,151.78,0.066
42.48,151.93,0.066
42.51,152.08,0.066
42.54,152.23,0.066
42.57,152.38,0.066
42.60,152.53,0.066
42.63,152.68,0.066
42.66,152.83,0.066
42.69,152.98,0.065
42.72,153.13,0.066
42.75,153.28,0.066
42.78,153.43,0.066
42.81,153.58,0.066
42.84,153.73,0.066
42.87,153.88,0.066
42.90,154.03,0.065
42.93,154.18,0.065
42.96,154.33,0.065
42.99,154.48,0.065
43.02,154.63,0.065
43.05,154.78,0.065
43.08,154.93,0.065
43.11,155.08,0.065
43.14,155.23,0.065
43.17,155.38,0.065
43.20,155.53,0.065
43.23,155.68,0.065
43.26,155.83,0.065
43.29,155.98,0.065
43.32,156.13,0.065
43.35,156.28,0.065
43.38,156.43,0.064
43.41,156.58,0.064
43.44,156.73,0.064
43.47,156.88,0.064
43.50,157.03,0.064
43.53,157.18,0.064
43.56,157.33,0.064
43.59,157.48,0.064
43.62,157.63,0.064
43.65,157.78,0.064
43.68,157.93,0.064
43.71,158.08,0.064
43.74,158.23,0.064
43.77,158.38,0.064
43.80,158.53,0.064
43.83,158.68,0.063
43.86,158.83,0.063
43.89,158.98,0.063
43.92,159.13,0.063
43.95,159.28,
43.98,,
43.98,,

[step]
Ramp 5.00 °C/min to -60.00 °C
Time,Temperature,Heat Flow (Normalized)
min,°C,W/g
44.99,160.14,-0.137
45.01,160.14,-0.136
45.04,160.13,-0.128
45.08,160.10,-0.097
45.11,160.04,-0.092
45.14,159.95,-0.122
45.16,159.85,-0.171
45.19,159.74,-0.214
45.23,159.61,-0.247
45.26,159.48,-0.266
45.29,159.35,-0.284
45.31,159.21,-0.293
45.34,159.07,-0.299
45.38,158.93,-0.306
45.41,158.78,-0.311
45.44,158.64,-0.313
45.46,158.49,-0.314
45.49,158.35,-0.315
45.53,158.20,-0.316
45.56,158.05,-0.316
45.59,157.91,-0.317
45.61,157.76,-0.317
45.64,157.61,-0.317
45.68,157.46,-0.318
45.71,157.31,-0.318
45.74,157.16,-0.318
45.76,157.01,-0.318
45.79,156.87,-0.318
45.83,156.72,-0.318
45.86,156.57,-0.318
45.89,156.42,-0.317
45.91,156.27,-0.317
45.94,156.12,-0.317
45.98,155.97,-0.316
46.01,155.82,-0.316
46.04,155.67,-0.316
46.06,155.52,-0.315
46.09,155.37,-0.315
46.13,155.22,-0.314
46.16,155.07,-0.314
46.19,154.93,-0.313
46.21,154.78,-0.313
46.24,154.63,-0.311
46.28,154.48,-0.310
46.31,154.33,-0.310
46.34,154.17,-0.309
46.36,154.02,-0.309
46.39,153.87,-0.309
46.43,153.73,-0.309
46.46,153.58,-0.308
46.49,153.43,-0.308
46.51,153.28,-0.306
46.54,153.13,-0.305
46.58,152.98,-0.305
46.61,152.83,-0.305
46.64,152.68,-0.304
46.66,152.53,-0.304
46.69,152.38,-0.303
46.73,152.23,-0.303
46.76,152.08,-0.302
46.79,151.93,-0.302
46.81,151.78,-0.302
46.84,151.63,-0.301
46.88,151.48,-0.301
46.91,151.33,-0.300
46.94,151.18,-0.299
46.96,151.03,-0.299
46.99,150.88,-0.299
47.03,150.73,-0.298
47.06,150.58,-0.298
47.09,150.43,-0.297
47.11,150.28,-0.297
47.14,150.13,-0.297
47.18,149.98,-0.296
47.21,149.83,-0.296
47.24,149.68,-0.295
47.26,149.53,-0.295
47.29,149.38,-0.294
47.33,149.23,-0.294
47.36,149.08,-0.293
47.39,148.93,-0.293
47.41,148.78,-0.292
47.44,148.63,-0.292
47.48,148.48,-0.292
47.51,148.33,-0.291
47.54,148.18,-0.291
47.56,148.03,-0.290
47.59,147.88,-0.289
47.63,147.73,-0.289
47.66,147.58,-0.289
47.69,147.43,-0.288
47.71,147.28,-0.288
47.74,147.13,-0.287
47.78,146.98,-0.287
47.81,146.83,-0.287
47.84,146.68,-0.286
47.86,146.53,-0.286
47.89,146.38,-0.286
47.93,146.23,-0.285
47.96,146.08,-0.285
47.99,145.93,-0.284
48.01,145.78,-0.284
48.04,145.63,-0.284
48.08,145.48,-0.283
48.11,145.33,-0.283
48.14,145.18,-0.282
48.16,145.03,-0.282
48.19,144.88,-0.282
48.23,144.73,-0.282
48.26,144.58,-0.282
48.29,144.43,-0.281
48.31,144.28,-0.280
48.34,144.13,-0.280
48.38,143.98,-0.280
48.41,143.83,-0.280
48.44,143.68,-0.280
48.46,143.53,-0.280
48.49,143.38,-0.279
48.53,143.23,-0.279
48.56,143.08,-0.278
48.59,142.93,-0.278
48.61,142.78,-0.278
48.64,142.63,-0.277
48.68,142.48,-0.277
48.71,142.33,-0.277
48.74,142.18,-0.276
48.76,142.03,-0.276
48.79,141.88,-0.276
48.83,141.73,-0.275
48.86,141.58,-0.275
48.89,141.43,-0.275
48.91,141.28,-0.275
48.94,141.13,-0.274
48.98,140.98,-0.274
49.01,140.83,-0.273
49.04,140.68,-0.273
49.06,140.53,-0.273
49.09,140.38,-0.273
49.13,140.23,-0.273
49.16,140.08,-0.273
49.19,139.93,-0.272
49.21,139.78,-0.272
49.24,139.63,-0.272
49.28,139.48,-0.271
49.31,139.33,-0.270
49.34,139.18,-0.270
49.36,139.03,-0.269
49.39,138.88,-0.269
49.43,138.73,-0.269
49.46,138.59,-0.269
49.49,138.43,-0.269
49.51,138.28,-0.269
49.54,138.13,-0.268
49.58,137.99,-0.268
49.61,137.83,-0.268
49.64,137.69,-0.268
49.66,137.54,-0.268
49.69,137.38,-0.267
49.73,137.24,-0.267
49.76,137.09,-0.267
49.79,136.94,-0.267
49.81,136.79,-0.267
49.84,136.64,-0.266
49.88,136.48,-0.266
49.91,136.33,-0.266
49.94,136.18,-0.266
49.96,136.03,-0.266
49.99,135.88,-0.265
50.03,135.73,-0.265
50.06,135.58,-0.265
50.09,135.43,-0.265
50.11,135.28,-0.265
50.14,135.13,-0.264
50.18,134.98,-0.264
50.21,134.83,-0.264
50.24,134.69,-0.263
50.26,134.53,-0.263
50.29,134.38,-0.263
50.33,134.23,-0.263
50.36,134.08,-0.262
50.39,133.93,-0.262
50.41,133.78,-0.262
50.44,133.63,-0.262
50.48,133.49,-0.262
50.51,133.33,-0.261
50.54,133.18,-0.261
50.56,133.03,-0.261
50.59,132.88,-0.261
50.63,132.73,-0.261
50.66,132.58,-0.261
50.69,132.44,-0.260
50.71,132.28,-0.260
50.74,132.14,-0.259
50.78,131.99,-0.259
50.81,131.84,-0.259
50.84,131.69,-0.259
50.86,131.54,-0.259
50.89,131.39,-0.259
50.93,131.24,-0.258
50.96,131.09,-0.258
50.99,130.94,-0.258
51.01,130.79,-0.258
51.04,130.64,-0.258
51.08,130.49,-0.258
51.11,130.34,-0.258
51.14,130.19,-0.258
51.16,130.04,-0.257
51.19,129.89,-0.257
51.23,129.74,-0.257
51.26,129.59,-0.257
51.29,129.44,-0.257
51.31,129.29,-0.256
51.34,129.14,-0.256
51.38,128.99,-0.256
51.41,128.84,-0.256
51.44,128.69,-0.256
51.46,128.54,-0.256
51.49,128.39,-0.255
51.53,128.24,-0.255
51.56,128.09,-0.255
51.59,127.94,-0.255
51.61,127.79,-0.254
51.64,127.64,-0.254
51.68,127.49,-0.254
51.71,127.34,-0.254
51.74,127.19,-0.254
51.76,127.04,-0.254
51.79,126.89,-0.254
51.83,126.74,-0.254
51.86,126.59,-0.254
51.89,126.44,-0.253
51.91,126.29,-0.253
51.94,126.14,-0.253
51.98,125.99,-0.354
52.01,125.85,-0.394
52.04,125.71,-0.388
52.06,125.56,-0.307
52.09,125.41,-0.287
52.13,125.25,-0.281
52.16,125.10,-0.278
52.19,124.95,-0.421
52.21,125.27,-14.281
52.24,126.24,-12.162
52.28,126.36,-8.512
52.31,126.23,-7.264
52.34,126.02,-6.581
52.36,125.77,-5.775
52.39,125.48,-5.018
52.43,125.18,-4.210
52.46,124.85,-3.498
52.49,124.53,-2.850
52.51,124.22,-2.341
52.54,123.92,-2.000
52.58,123.65,-1.641
52.61,123.39,-1.394
52.64,123.14,-1.203
52.66,122.92,-1.056
52.69,122.71,-0.934
52.73,122.50,-0.838
52.76,122.31,-0.759
52.79,122.13,-0.695
52.81,121.95,-0.641
52.84,121.78,-0.596
52.88,121.61,-0.564
52.91,121.45,-0.532
52.94,121.28,-0.509
52.96,121.12,-0.486
52.99,120.97,-0.470
53.03,120.81,-0.455
53.06,120.65,-0.442
53.09,120.50,-0.430
53.11,120.35,-0.421
53.14,120.19,-0.413
53.18,120.04,-0.404
53.21,119.89,-0.393
53.24,119.73,-0.388
53.26,119.58,-0.384
53.29,119.43,-0.380
53.33,119.28,-0.376
53.36,119.13,-0.366
53.39,118.97,-0.363
53.41,118.82,-0.357
53.44,118.67,-0.354
53.48,118.52,-0.349
53.51,118.37,-0.344
53.54,118.22,-0.339
53.56,118.07,-0.336
53.59,117.92,-0.334
53.63,117.77,-0.333
53.66,117.62,-0.330
53.69,117.47,-0.327
53.71,117.31,-0.323
53.74,117.16,-0.320
53.78,117.01,-0.318
53.81,116.86,-0.315
53.84,116.71,-0.314
53.86,116.56,-0.311
53.89,116.41,-0.309
53.93,116.26,-0.307
53.96,116.11,-0.304
53.99,115.96,-0.303
54.01,115.81,-0.301
54.04,115.66,-0.299
54.08,115.51,-0.297
54.11,115.36,-0.295
54.14,115.21,-0.294
54.16,115.06,-0.293
54.19,114.90,-0.290
54.23,114.75,-0.288
54.26,114.60,-0.287
54.29,114.45,-0.286
54.31,114.30,-0.284
54.34,114.15,-0.281
54.38,114.00,-0.280
54.41,113.85,-0.279
54.44,113.70,-0.277
54.46,113.55,-0.276
54.49,113.40,-0.275
54.53,113.25,-0.273
[...]
232.87,121.52,-0.243
232.89,121.42,-0.243
232.90,121.33,-0.242
232.92,121.24,-0.242
232.94,121.15,-0.242
232.96,121.06,-0.242
232.98,120.97,-0.242
233.00,120.88,-0.242
233.02,120.78,-0.242
233.03,120.69,-0.242
233.05,120.60,-0.242
233.07,120.51,-0.242
233.09,120.42,-0.242
233.11,120.33,-0.242
233.13,120.23,-0.242
233.14,120.14,-0.241
233.16,120.05,-0.241
233.18,119.96,-0.241
233.20,119.87,-0.241
233.22,119.78,-0.241
233.23,119.68,-0.241
233.25,119.59,-0.241
233.27,119.50,-0.241
233.29,119.41,-0.241
233.31,119.32,-0.241
233.33,119.23,-0.240
233.35,119.13,-0.240
233.36,119.04,-0.240
233.38,118.95,-0.240
233.40,118.86,-0.240
233.42,118.77,-0.240
233.44,118.68,-0.240
233.45,118.59,-0.240
233.47,118.49,-0.240
233.49,118.40,-0.240
233.51,118.31,-0.240
233.53,118.22,-0.719
233.55,118.63,-20.950
233.57,120.24,-29.114
233.58,120.79,-14.920
233.60,120.67,-8.788
233.62,120.35,-6.063
233.64,119.97,-4.499
233.66,119.59,-3.613
233.68,119.24,-3.038
233.69,118.92,-2.612
233.71,118.62,-2.275
233.73,118.35,-1.992
233.75,118.11,-1.754
233.77,117.88,-1.550
233.78,117.67,-1.376
233.80,117.48,-1.230
233.82,117.30,-1.111
233.84,117.14,-1.005
233.86,116.99,-0.912
233.88,116.84,-0.835
233.90,116.70,-0.767
233.91,116.57,-0.713
233.93,116.44,-0.666
233.95,116.32,-0.625
233.97,116.21,-0.585
233.99,116.09,-0.555
234.00,115.98,-0.531
234.02,115.87,-0.502
234.04,115.77,-0.486
234.06,115.67,-0.467
234.08,115.56,-0.448
234.10,115.46,-0.438
234.12,115.36,-0.426
234.13,115.27,-0.418
234.15,115.17,-0.408
234.17,115.07,-0.401
234.19,114.98,-0.394
234.21,114.88,-0.387
234.23,114.79,-0.382
234.24,114.69,-0.376
234.26,114.60,-0.372
234.28,114.50,-0.367
234.30,114.41,-0.364
234.32,114.32,-0.362
234.33,114.22,-0.361
234.35,114.13,-0.359
234.37,114.04,-0.356
234.39,113.94,-0.353
234.41,113.85,-0.349
234.43,113.76,-0.345
234.45,113.67,-0.344
234.46,113.58,-0.342
234.48,113.48,-0.340
234.50,113.39,-0.339
234.52,113.30,-0.338
234.54,113.21,-0.337
234.55,113.11,-0.336
234.57,113.02,-0.335
234.59,112.93,-0.333
234.61,112.84,-0.332
234.63,112.75,-0.330
234.65,112.65,-0.329
234.67,112.56,-0.327
234.68,112.47,-0.325
234.70,112.38,-0.324
234.72,112.29,-0.323
234.74,112.19,-0.322
234.76,112.10,-0.320
234.78,112.01,-0.319
234.79,111.92,-0.318
234.81,111.83,-0.318
234.83,111.74,-0.316
234.85,111.64,-0.315
234.87,111.55,-0.313
234.88,111.46,-0.312
234.90,111.37,-0.312
234.92,111.27,-0.310
234.94,111.18,-0.309
234.96,111.09,-0.308
234.98,111.00,-0.308
235.00,110.91,-0.306
235.01,110.81,-0.305
235.03,110.72,-0.304
235.05,110.63,-0.304
235.07,110.54,-0.302
235.09,110.45,-0.301
235.10,110.35,-0.301
235.12,110.26,-0.300
235.14,110.17,-0.299
235.16,110.08,-0.298
235.18,109.98,-0.297
235.20,109.89,-0.296
235.22,109.80,-0.295
235.23,109.71,-0.294
235.25,109.62,-0.293
235.27,109.53,-0.292
235.29,109.44,-0.291
235.31,109.34,-0.290
235.33,109.25,-0.289
235.34,109.16,-0.288
235.36,109.07,-0.287
235.38,108.98,-0.286
235.40,108.89,-0.285
235.42,108.79,-0.283
235.43,108.70,-0.283
235.45,108.61,-0.282
235.47,108.52,-0.282
235.49,108.43,-0.281
235.51,108.33,-0.281
235.53,108.24,-0.279
235.55,108.15,-0.279
235.56,108.06,-0.278
235.58,107.97,-0.278
235.60,107.87,-0.277
235.62,107.78,-0.276
235.64,107.69,-0.276
235.65,107.60,-0.275
235.67,107.51,-0.274
235.69,107.42,-0.273
235.71,107.33,-0.272
235.73,107.23,-0.272
235.75,107.14,-0.271
235.77,107.05,-0.270
235.78,106.96,-0.270
235.80,106.87,-0.269
235.82,106.77,-0.269
235.84,106.68,-0.267
235.86,106.59,-0.267
235.88,106.50,-0.266
235.89,106.41,-0.265
235.91,106.31,-0.265
235.93,106.22,-0.264
235.95,106.13,-0.264
235.97,106.04,-0.263
235.98,105.95,-0.261
236.00,105.86,-0.260
236.02,105.76,-0.260
236.04,105.67,-0.260
236.06,105.58,-0.259
236.08,105.49,-0.258
236.10,105.40,-0.258
236.11,105.31,-0.257
236.13,105.21,-0.257
236.15,105.12,-0.256
236.17,105.03,-0.256
236.19,104.94,-0.255
236.20,104.85,-0.255
236.22,104.75,-0.255
236.24,104.66,-0.254
236.26,104.57,-0.254
236.28,104.48,-0.254
236.30,104.39,-0.253
236.32,104.30,-0.253
236.33,104.20,-0.253
236.35,104.11,-0.252
236.37,104.02,-0.252
236.39,103.93,-0.252
236.41,103.84,-0.251
236.43,103.75,-0.251
236.44,103.66,-0.250
236.46,103.56,-0.250
236.48,103.47,-0.250
236.50,103.38,-0.249
236.52,103.29,-0.249
236.53,103.20,-0.249
236.55,103.10,-0.248
236.57,103.01,-0.248
236.59,102.92,-0.248
236.61,102.83,-0.248
236.63,102.74,-0.247
236.65,102.65,-0.247
236.66,102.56,-0.246
236.68,102.46,-0.246
236.70,102.37,-0.245
236.72,102.28,-0.245
236.74,102.19,-0.244
236.75,102.10,-0.244
236.77,102.01,-0.243
236.79,101.91,-0.243
236.81,101.82,-0.243
236.83,101.73,-0.242
236.85,101.64,-0.242
236.87,101.55,-0.242
236.88,101.45,-0.242
236.90,101.36,-0.241
236.92,101.27,-0.241
236.94,101.18,-0.241
236.96,101.09,-0.240
236.98,101.00,-0.240
236.99,100.90,-0.240
237.01,100.81,-0.240
237.03,100.72,-0.239
237.05,100.63,-0.239
237.07,100.54,-0.239
237.08,100.45,-0.238
237.10,100.35,-0.238
237.12,100.26,-0.238
237.14,100.17,-0.237
237.16,100.08,-0.237
237.18,99.99,-0.237
237.20,99.89,-0.236
237.21,99.80,-0.236
237.23,99.71,-0.236
237.25,99.62,-0.235
237.27,99.53,-0.235
237.29,99.44,-0.235
237.30,99.34,-0.235
237.32,99.25,-0.234
237.34,99.16,-0.234
237.36,99.07,-0.234
237.38,98.98,-0.233
237.40,98.89,-0.233
237.42,98.80,-0.233
237.43,98.70,-0.232
237.45,98.61,-0.232
237.47,98.52,-0.232
237.49,98.43,-0.232
237.51,98.34,-0.231
237.53,98.24,-0.231
237.54,98.15,-0.231
237.56,98.06,-0.230
237.58,97.97,-0.230
237.60,97.88,-0.230
237.62,97.79,-0.230
237.63,97.70,-0.229
237.65,97.60,-0.229
237.67,97.51,-0.229
237.69,97.42,-0.229
237.71,97.33,-0.228
237.73,97.24,-0.228
237.75,97.14,-0.228
237.76,97.05,-0.228
237.78,96.96,-0.228
237.80,96.87,-0.227
237.82,96.78,-0.227
237.84,96.69,-0.227
237.85,96.59,-0.227
237.87,96.50,-0.227
237.89,96.41,-0.226
237.91,96.32,-0.226
237.93,96.23,-0.226
237.95,96.13,-0.225
237.97,96.04,-0.225
237.98,95.95,-0.225
238.00,95.86,-0.224
238.02,95.77,-0.224
238.04,95.68,-0.224
238.06,95.59,-0.224
238.08,95.49,-0.224
238.09,95.40,-0.223
238.11,95.31,-0.223
238.13,95.22,-0.223
238.15,95.13,-0.223
238.17,95.04,-0.222
238.18,94.94,-0.222
238.20,94.85,-0.222
238.22,94.76,-0.221
238.24,94.67,-0.221
238.26,94.58,-0.221
238.28,94.49,-0.221
238.30,94.39,-0.220
238.31,94.30,-0.220
238.33,94.21,-0.220
238.35,94.12,-0.220
238.37,94.03,-0.220
238.39,93.94,-0.220
238.40,93.84,-0.219
238.42,93.75,-0.219
238.44,93.66,-0.219
238.46,93.57,-0.219
238.48,93.48,-0.219
238.50,93.39,-0.219
238.52,93.29,-0.219
238.53,93.20,-0.219
238.55,93.11,-0.219
238.57,93.02,-0.218
238.59,92.93,-0.218
238.61,92.84,-0.217
238.63,92.75,-0.217
238.64,92.65,-0.217
238.66,92.56,-0.217
238.68,92.47,-0.217
238.70,92.38,-0.217
238.72,92.29,-0.217
238.73,92.19,-0.217
238.75,92.10,-0.217
238.77,92.01,-0.216
238.79,91.92,-0.216
238.81,91.83,-0.216
238.83,91.74,-0.216
238.85,91.64,-0.215
238.86,91.55,-0.215
238.88,91.46,-0.215
238.90,91.37,-0.215
238.92,91.28,-0.215
238.94,91.19,-0.215
238.95,91.09,-0.215
238.97,91.00,-0.214
238.99,90.91,-0.214
239.01,90.82,-0.214
239.03,90.73,-0.214
239.05,90.64,-0.214
239.07,90.55,-0.214
239.08,90.45,-0.213
239.10,90.36,-0.213
239.12,90.27,-0.213
239.14,90.18,-0.213
239.16,90.09,-0.212
239.18,90.00,-0.212
239.19,89.90,-0.212
239.21,89.81,-0.212
239.23,89.72,-0.212
239.25,89.63,-0.211
239.27,89.54,-0.211
239.28,89.45,-0.211
239.30,89.35,-0.211
239.32,89.26,-0.211
239.34,89.17,-0.211
239.36,89.08,-0.211
239.38,88.99,-0.210
239.40,88.90,-0.210
239.41,88.80,-0.210
239.43,88.71,-0.210
239.45,88.62,-0.210
239.47,88.53,-0.210
239.49,88.44,-0.210
239.50,88.35,-0.210
239.52,88.25,-0.209
239.54,88.16,-0.209
239.56,88.07,-0.209
239.58,87.98,-0.209
239.60,87.89,-0.209
239.62,87.80,-0.209
239.63,87.70,-0.208
239.65,87.61,-0.208
239.67,87.52,-0.208
239.69,87.43,-0.208
239.71,87.34,-0.208
239.73,87.24,-0.208
239.74,87.15,-0.208
239.76,87.06,-0.208
239.78,86.97,-0.207
239.80,86.88,-0.207
239.82,86.79,-0.207
239.83,86.70,-0.207
239.85,86.60,-0.206
239.87,86.51,-0.206
239.89,86.42,-0.206
239.91,86.33,-0.206
239.93,86.24,-0.206
239.95,86.15,-0.206
239.96,86.05,-0.206
239.98,85.96,-0.206
240.00,85.87,-0.205
240.02,85.78,-0.205
240.04,85.69,-0.205
240.05,85.60,-0.205
240.07,85.50,-0.205
240.09,85.41,-0.205
240.11,85.32,-0.205
240.13,85.23,-0.205
240.15,85.14,-0.205
240.17,85.04,-0.204
240.18,84.95,-0.204
240.20,84.86,-0.204
240.22,84.77,-0.204
240.24,84.68,-0.204
240.26,84.59,-0.204
240.28,84.50,-0.203
240.29,84.40,-0.204
240.31,84.31,-0.203
240.33,84.22,-0.203
240.35,84.13,-0.203
240.37,84.04,-0.203
240.38,83.95,-0.203
240.40,83.85,-0.203
240.42,83.76,-0.203
240.44,83.67,-0.203
240.46,83.58,-0.202
240.48,83.49,-0.202
240.50,83.40,-0.202
240.51,83.30,-0.202
240.53,83.21,-0.202
240.55,83.12,-0.202
240.57,83.03,-0.202
240.59,82.94,-0.201
240.60,82.85,-0.201
240.62,82.76,-0.201
240.64,82.66,-0.201
240.66,82.57,-0.201
240.68,82.48,-0.201
240.70,82.39,-0.201
240.72,82.30,-0.201
240.73,82.21,-0.201
240.75,82.11,-0.200
240.77,82.02,-0.200
240.79,81.93,-0.200
240.81,81.84,-0.200
240.83,81.75,-0.200
240.84,81.66,-0.200
240.86,81.56,-0.200
240.88,81.47,-0.200
240.90,81.38,-0.200
240.92,81.29,-0.200
240.93,81.20,-0.200
240.95,81.11,-0.200
240.97,81.01,-0.200
240.99,80.92,-0.199
241.01,80.83,-0.199
241.03,80.74,-0.199
241.05,80.65,-0.199
241.06,80.55,-0.199
241.08,80.46,-0.199
241.10,80.37,-0.199
241.12,80.28,-0.199
241.14,80.19,-0.199
241.15,80.10,-0.198
241.17,80.01,-0.198
241.19,79.91,-0.198
241.21,79.82,-0.198
241.23,79.73,-0.198
241.25,79.64,-0.198
241.27,79.55,-0.198
241.28,79.45,-0.198
241.30,79.36,-0.198
241.32,79.27,-0.198
241.34,79.18,-0.198
241.36,79.09,-0.198
241.38,78.99,-0.198
241.39,78.90,-0.198
241.41,78.81,-0.198
241.43,78.72,-0.197
241.45,78.63,-0.197
241.47,78.54,-0.197
241.48,78.44,-0.197
241.50,78.35,-0.197
241.52,78.26,-0.197
241.54,78.17,-0.197
241.56,78.08,-0.197
241.58,77.99,-0.197
241.60,77.89,-0.197
241.61,77.80,-0.196
241.63,77.71,-0.196
241.65,77.62,-0.196
241.67,77.53,-0.196
241.69,77.44,-0.196
241.70,77.34,-0.196
241.72,77.25,-0.196
241.74,77.16,-0.196
241.76,77.07,-0.195
241.78,76.98,-0.195
241.80,76.89,-0.195
241.82,76.79,-0.195
241.83,76.70,-0.195
241.85,76.61,-0.195
241.87,76.52,-0.195
241.89,76.43,-0.195
241.91,76.34,-0.195
241.93,76.24,-0.194
241.94,76.15,-0.194
241.96,76.06,-0.194
241.98,75.97,-0.194
242.00,75.88,-0.194
242.02,75.79,-0.194
242.03,75.70,-0.194
242.05,75.60,-0.193
242.07,75.51,-0.193
242.09,75.42,-0.193
242.11,75.33,-0.193
242.13,75.24,-0.193
242.15,75.15,-0.193
242.16,75.06,-0.193
242.18,74.96,-0.193
242.20,74.87,-0.193
242.22,74.78,-0.193
242.24,74.69,-0.193
242.25,74.60,-0.192
242.27,74.51,-0.192
242.29,74.41,-0.192
242.31,74.32,-0.192
242.33,74.23,-0.192
242.35,74.14,-0.192
242.37,74.05,-0.192
242.38,73.96,-0.192
242.40,73.86,-0.192
242.42,73.77,-0.191
242.44,73.68,-0.191
242.46,73.59,-0.191
242.48,73.50,-0.191
242.49,73.41,-0.192
242.51,73.31,-0.192
242.53,73.22,-0.192
242.55,73.13,-0.191
242.57,73.04,-0.191
242.58,72.95,-0.191
242.60,72.86,-0.191
242.62,72.77,-0.190
242.64,72.67,-0.190
242.66,72.58,-0.190
242.68,72.49,-0.190
242.70,72.40,-0.190
242.71,72.31,-0.190
242.73,72.22,-0.190
242.75,72.12,-0.190
242.77,72.03,-0.190
242.79,71.94,-0.189
242.80,71.85,-0.189
242.82,71.76,-0.189
242.84,71.67,-0.189
242.86,71.57,-0.189
242.88,71.48,-0.189
242.90,71.39,-0.189
242.92,71.30,-0.189
242.93,71.21,-0.189
242.95,71.12,-0.189
242.97,71.03,-0.189
242.99,70.93,-0.188
243.01,70.84,-0.188
243.03,70.75,-0.188
243.04,70.66,-0.188
243.06,70.57,-0.188
243.08,70.48,-0.188
243.10,70.38,-0.188
243.12,70.29,-0.188
243.13,70.20,-0.188
243.15,70.11,-0.188
243.17,70.02,-0.187
243.19,69.93,-0.187
243.21,69.83,-0.187
243.23,69.74,-0.187
243.25,69.65,-0.187
243.26,69.56,-0.187
243.28,69.47,-0.187
243.30,69.38,-0.187
243.32,69.28,-0.187
243.34,69.19,-0.186
243.35,69.10,-0.186
243.37,69.01,-0.186
243.39,68.92,-0.186
243.41,68.82,-0.186
243.43,68.73,-0.186
243.45,68.64,-0.186
243.47,68.55,-0.186
243.48,68.46,-0.186
243.50,68.37,-0.185
243.52,68.28,-0.185
243.54,68.18,-0.185
243.56,68.09,-0.185
243.58,68.00,-0.185
243.59,67.91,-0.185
243.61,67.82,-0.185
243.63,67.73,-0.185
243.65,67.63,-0.185
243.67,67.54,-0.185
243.68,67.45,-0.184
243.70,67.36,-0.184
243.72,67.27,-0.184
243.74,67.18,-0.184
243.76,67.09,-0.184
243.78,66.99,-0.184
243.80,66.90,-0.184
243.81,66.81,-0.184
243.83,66.72,-0.184
243.85,66.63,-0.184
243.87,66.53,-0.183
243.89,66.44,-0.183
243.90,66.35,-0.183
243.92,66.26,-0.183
243.94,66.17,-0.183
243.96,66.08,-0.183
243.98,65.99,-0.183
244.00,65.89,-0.183
244.02,65.80,-0.183
244.03,65.71,-0.183
244.05,65.62,-0.183
244.07,65.53,-0.182
244.09,65.44,-0.182
244.11,65.34,-0.182
244.13,65.25,-0.182
244.14,65.16,-0.182
244.16,65.07,-0.182
244.18,64.98,-0.182
244.20,64.89,-0.182
244.22,64.79,-0.182
244.23,64.70,-0.182
244.25,64.61,-0.181
244.27,64.52,-0.181
244.29,64.43,-0.181
244.31,64.34,-0.181
244.33,64.25,-0.181
244.35,64.15,-0.181
244.36,64.06,-0.181
244.38,63.97,-0.181
244.40,63.88,-0.181
244.42,63.79,-0.181
244.44,63.70,-0.180
244.45,63.61,-0.180
244.47,63.51,-0.180
244.49,63.42,-0.180
244.51,63.33,-0.180
244.53,63.24,-0.180
244.55,63.15,-0.180
244.57,63.06,-0.180
244.58,62.96,-0.180
244.60,62.87,-0.179
244.62,62.78,-0.179
244.64,62.69,-0.179
244.66,62.60,-0.179
244.68,62.50,-0.179
244.69,62.41,-0.179
244.71,62.32,-0.179
244.73,62.23,-0.179
244.75,62.14,-0.179
244.77,62.05,-0.179
244.78,61.96,-0.179
244.80,61.86,-0.179
244.82,61.77,-0.178
244.84,61.68,-0.178
244.86,61.59,-0.178
244.88,61.50,-0.178
244.90,61.41,-0.178
244.91,61.31,-0.178
244.93,61.22,-0.178
244.95,61.13,-0.178
244.97,61.04,-0.178
244.99,60.95,-0.178
245.00,60.85,-0.178
245.02,60.76,-0.178
245.04,60.67,-0.177
245.06,60.58,-0.177
245.08,60.49,-0.177
245.10,60.40,-0.177
245.12,60.30,-0.177
245.13,60.21,-0.177
245.15,60.12,-0.177
245.17,60.03,-0.177
245.19,59.94,-0.177
245.21,59.85,-0.177
245.23,59.75,-0.176
245.24,59.66,-0.177
245.26,59.57,-0.176
245.28,59.48,-0.176
245.30,59.39,-0.176
245.32,59.30,-0.176
245.33,59.20,-0.176
245.35,59.11,-0.176
245.37,59.02,-0.176
245.39,58.93,-0.176
245.41,58.84,-0.176
245.43,58.75,-0.176
245.45,58.65,-0.175
245.46,58.56,-0.175
245.48,58.47,-0.175
245.50,58.38,-0.175
245.52,58.29,-0.175
245.54,58.20,-0.175
245.55,58.10,-0.175
245.57,58.01,-0.175
245.59,57.92,-0.175
245.61,57.83,-0.175
245.63,57.74,-0.174
245.65,57.65,-0.174
245.67,57.55,-0.174
245.68,57.46,-0.174
245.70,57.37,-0.174
245.72,57.28,-0.174
245.74,57.19,-0.174
245.76,57.10,-0.174
245.78,57.00,-0.174
245.79,56.91,-0.174
245.81,56.82,-0.174
245.83,56.73,-0.173
245.85,56.64,-0.173
245.87,56.55,-0.173
245.88,56.46,-0.173
245.90,56.36,-0.173
245.92,56.27,-0.173
245.94,56.18,-0.173
245.96,56.09,-0.173
245.98,56.00,-0.173
246.00,55.91,-0.173
246.01,55.81,-0.172
246.03,55.72,-0.172
246.05,55.63,-0.172
246.07,55.54,-0.172
246.09,55.45,-0.172
246.10,55.35,-0.172
246.12,55.26,-0.172
246.14,55.17,-0.172
246.16,55.08,-0.172
246.18,54.99,-0.172
246.20,54.90,-0.172
246.22,54.80,-0.171
246.23,54.71,-0.171
246.25,54.62,-0.171
246.27,54.53,-0.171
246.29,54.44,-0.171
246.31,54.35,-0.171
246.33,54.25,-0.171
246.34,54.16,-0.170
246.36,54.07,-0.170
246.38,53.98,-0.170
246.40,53.89,-0.170
246.42,53.80,-0.170
246.43,53.70,-0.170
246.45,53.61,-0.170
246.47,53.52,-0.170
246.49,53.43,-0.170
246.51,53.34,-0.170
246.53,53.25,-0.170
246.55,53.15,-0.170
246.56,53.06,-0.169
246.58,52.97,-0.169
246.60,52.88,-0.169
246.62,52.79,-0.169
246.64,52.70,-0.169
246.65,52.60,-0.169
246.67,52.51,-0.169
246.69,52.42,-0.169
246.71,52.33,-0.169
246.73,52.24,-0.169
246.75,52.15,-0.168
246.77,52.05,-0.168
246.78,51.96,-0.168
246.80,51.87,-0.168
246.82,51.78,-0.168
246.84,51.69,-0.168
246.86,51.60,-0.168
246.88,51.50,-0.168
246.89,51.41,-0.168
246.91,51.32,-0.168
246.93,51.23,-0.168
246.95,51.14,-0.167
246.97,51.05,-0.167
246.98,50.95,-0.167
247.00,50.86,-0.167
247.02,50.77,-0.167
247.04,50.68,-0.167
247.06,50.59,-0.167
247.08,50.50,-0.167
247.10,50.41,-0.167
247.11,50.31,-0.167
247.13,50.22,-0.167
247.15,50.13,-0.167
247.17,50.04,-0.166
247.19,49.95,-0.166
247.20,49.86,-0.166
247.22,49.77,-0.166
247.24,49.67,-0.166
247.26,49.58,-0.166
247.28,49.49,-0.166
247.30,49.40,-0.165
247.32,49.31,-0.165
247.33,49.22,-0.165
247.35,49.13,-0.165
247.37,49.03,-0.165
247.39,48.94,-0.165
247.41,48.85,-0.165
247.43,48.76,-0.165
247.44,48.67,-0.165
247.46,48.57,-0.165
247.48,48.48,-0.165
247.50,48.39,-0.164
247.52,48.30,-0.164
247.53,48.21,-0.164
247.55,48.12,-0.164
247.57,48.02,-0.164
247.59,47.93,-0.164
247.61,47.84,-0.164
247.63,47.75,-0.164
247.65,47.66,-0.164
247.66,47.57,-0.164
247.68,47.47,-0.163
247.70,47.38,-0.163
247.72,47.29,-0.163
247.74,47.20,-0.163
247.75,47.11,-0.163
247.77,47.02,-0.163
247.79,46.92,-0.163
247.81,46.83,-0.163
247.83,46.74,-0.163
247.85,46.65,-0.163
247.87,46.56,-0.162
247.88,46.47,-0.162
247.90,46.37,-0.162
247.92,46.28,-0.162
247.94,46.19,-0.162
247.96,46.10,-0.162
247.98,46.01,-0.162
247.99,45.92,-0.162
248.01,45.82,-0.162
248.03,45.73,-0.161
248.05,45.64,-0.161
248.07,45.55,-0.161
248.08,45.46,-0.161
248.10,45.36,-0.161
248.12,45.27,-0.161
248.14,45.18,-0.161
248.16,45.09,-0.161
248.18,45.00,-0.161
248.20,44.91,-0.161
248.21,44.81,-0.160
248.23,44.72,-0.160
248.25,44.63,-0.160
248.27,44.54,-0.160
248.29,44.45,-0.160
248.30,44.36,-0.160
248.32,44.27,-0.160
248.34,44.17,-0.160
248.36,44.08,-0.159
248.38,43.99,-0.159
248.40,43.90,-0.159
248.42,43.80,-0.159
248.43,43.71,-0.160
248.45,43.62,-0.159
248.47,43.53,-0.159
248.49,43.44,-0.159
248.51,43.35,-0.159
248.53,43.26,-0.159
248.54,43.16,-0.159
248.56,43.07,-0.159
248.58,42.98,-0.159
248.60,42.89,-0.159
248.62,42.80,-0.159
248.63,42.71,-0.159
248.65,42.61,-0.158
248.67,42.52,-0.158
248.69,42.43,-0.158
248.71,42.34,-0.158
248.73,42.25,-0.158
248.75,42.16,-0.158
248.76,42.07,-0.158
248.78,41.97,-0.158
248.80,41.88,-0.157
248.82,41.79,-0.157
248.84,41.70,-0.157
248.85,41.61,-0.157
248.87,41.52,-0.157
248.89,41.42,-0.157
248.91,41.33,-0.157
248.93,41.24,-0.157
248.95,41.15,-0.157
248.97,41.06,-0.157
248.98,40.97,-0.156
249.00,40.87,-0.156
249.02,40.78,-0.156
249.04,40.69,-0.156
249.06,40.60,-0.156
249.08,40.51,-0.156
249.09,40.42,-0.156
249.11,40.33,-0.156
249.13,40.23,-0.155
249.15,40.14,-0.155
249.17,40.05,-0.155
249.18,39.96,-0.155
249.20,39.87,-0.155
249.22,39.78,-0.155
249.24,39.68,-0.155
249.26,39.59,-0.155
249.28,39.50,-0.155
249.30,39.41,-0.155
249.31,39.32,-0.155
249.33,39.22,-0.154
249.35,39.13,-0.154
249.37,39.04,-0.154
249.39,38.95,-0.154
249.40,38.86,-0.154
249.42,38.77,-0.154
249.44,38.68,-0.154
249.46,38.58,-0.154
249.48,38.49,-0.154
249.50,38.40,-0.154
249.52,38.31,-0.154
249.53,38.22,-0.154
249.55,38.13,-0.153
249.57,38.03,-0.153
249.59,37.94,-0.153
249.61,37.85,-0.153
249.63,37.76,-0.153
249.64,37.67,-0.153
249.66,37.58,-0.153
249.68,37.48,-0.152
249.70,37.39,-0.152
249.72,37.30,-0.152
249.73,37.21,-0.152
249.75,37.12,-0.152
249.77,37.03,-0.152
249.79,36.93,-0.152
249.81,36.84,-0.152
249.83,36.75,-0.152
249.85,36.66,-0.152
249.86,36.57,-0.152
249.88,36.47,-0.152
249.90,36.38,-0.152
249.92,36.29,-0.151
249.94,36.20,-0.151
249.95,36.11,-0.151
249.97,36.02,-0.151
249.99,35.93,-0.151
250.01,35.83,-0.151
250.03,35.74,-0.151
250.05,35.65,-0.151
250.07,35.56,-0.151
250.08,35.47,-0.151
250.10,35.38,-0.151
250.12,35.28,-0.151
250.14,35.19,-0.151
250.16,35.10,-0.151
250.18,35.01,-0.151
250.19,34.92,-0.151
250.21,34.83,-0.150
250.23,34.73,-0.150
250.25,34.64,-0.150
250.27,34.55,-0.150
250.28,34.46,-0.150
250.30,34.37,-0.150
250.32,34.28,-0.150
250.34,34.19,-0.150
250.36,34.09,-0.150
250.38,34.00,-0.150
250.40,33.91,-0.150
250.41,33.82,-0.149
250.43,33.72,-0.149
250.45,33.63,-0.149
250.47,33.54,-0.149
250.49,33.45,-0.149
250.50,33.36,-0.149
250.52,33.27,-0.149
250.54,33.18,-0.149
250.56,33.08,-0.149
250.58,32.99,-0.149
250.60,32.90,-0.148
250.62,32.81,-0.148
250.63,32.72,-0.148
250.65,32.62,-0.148
250.67,32.53,-0.148
250.69,32.44,-0.148
250.71,32.35,-0.148
250.73,32.26,-0.148
250.74,32.17,-0.148
250.76,32.08,-0.148
250.78,31.98,-0.148
250.80,31.89,-0.148
250.82,31.80,-0.148
250.83,31.71,-0.147
250.85,31.62,-0.147
250.87,31.52,-0.147
250.89,31.43,-0.147
250.91,31.34,-0.147
250.93,31.25,
250.95,31.16,
250.96,31.07,
250.98,,
250.98,,