File: DSC/2025_07_01_PVP_10kDa_Std_Al_Pan_n60C_200C_10Cmin_x4.csv
Filename,2025_07_01_PVP_10kDa_Std_Al_Pan_n60C_200C_10Cmin_x4
Instrument name,DSC2A-00468 (192.168.1.100)
Operator,Gibbons
rundate,7/1/2025
Sample name,2025_07_01_PVP_10kDa_Std_Al_Pan_n60C_200C_10Cmin_x4
proceduresegments,Data Off ; Equilibrate -60.00 °C; Data On ; Ramp 10.00 °C/min to 200.00 °C; Data Off ; Isothermal 2.0 min; Data On ; Ramp 10.00 °C/min to -60.00 °C; Data Off ; Isothermal 2.0 min; Data On ; Ramp 10.00 °C/min to 200.00 °C; Data Off ; Isothermal 2.0 min; Data On ; Ramp 10.00 °C/min to -60.00 °C; Data Off ; Isothermal 2.0 min; Data On ; Ramp 10.00 °C/min to 200.00 °C; Data Off ; Isothermal 2.0 min; Data On ; Ramp 10.00 °C/min to -60.00 °C; Data Off ; Isothermal 2.0 min; Data On ; Ramp 10.00 °C/min to 30.00 °C
[File Parameters]
Run date,7/1/2025 3:19:18 PM
Trios version,5.1.1.46572
Original File Name,
Current File Name,D:\DSC2500\Gibbons\2025_07_01_PVP_10kDa_Std_Al_Pan_n60C_200C_10Cmin_x4.tri
[Procedure]
Procedure Name,PVP_n60C_200C_10Cmin_x4
Sample Name,2025_07_01_PVP_10kDa_Std_Al_Pan_n60C_200C_10Cmin_x4
Sample Mass,2.06 mg
Reference Sample Mass,0 mg
Pan Mass,21.96 mg
Pan Number,47
Reference Pan Mass,20 mg
Reference Pan Number,46
Pan Type,Aluminum
Comments,Al Pan/Lid Std. Y1 Tray (Google Sheet: DSC_Samples_Y1_Tray_June2025).
Project Name,Pharma - Cocrystals
Operator,Gibbons
Test,Custom
Unload Max Temperature,30
Unload Min Temperature,30
Load Max Temperature,30
Load Min Temperature,30
Stop on Gas Flow Error,Yes
[Signal List]
Signal #1,Time (min)
Signal #2,Temperature (°C)
Signal #3,Heat Flow (mW)
Signal #4,Delta T (µV)
Signal #5,Delta Tzero (µV)
Signal #6,Tzero Temperature (°C)
Signal #7,Cell Purge (mL/min)
Signal #8,Heater Temp (°C)
Signal #9,Power Delivered (W)
Signal #10,Reference Junction Temperature (°C)
Signal #11,Flange Temperature (°C)
Signal #12,Heat Flow Phase (rad)
Signal #13,Total Heat Capacity (J/°C)
Signal #14,Heat Capacity (J/°C)
[Configuration]
Company Name,ASU
Instrument Name,DSC2A-00468
Instrument Type,DSC2500
Serial Number,DSC2A-00468
IP,192.168.1.100
Location of Instrument,MRRC
DisplayType,Unknown
Sample Interval ,0.1 s/pt
Selected Heat Flow,T4P
Exotherm Direction,Down
Cell Serial,DRC2-00792
Lid Type,Standard
Cooler,RCS 90
Leave Cooler on at End of Sequence,On
Gas 2,Nitrogen
Gas Selected,Channel 1
Flow Rate,50 mL/min
Secondary Purge,On
Licensed Heat Flow,Heat Flow T4P
Modulation Licensed,Yes
[Versions]
Common IDD Version,1
Cortex Version,VER 2.10.2.31
Driver,5.0.0.6
GDM Version,1.0.3.3
TouchscreenVersion,1.0.0.16145
FEP Version,1.2.1.21
FEP Bootloader,2.0.0.5
AutoSampler Version,2.1.1.26
Auto Sampler Bootloader,2.0.0.5
FCM Version,1.1.0.3
FCM Bootloader,2.0.0.5
[Experiment Logs]
Experiment Log Entry # 1,Data On set to 0
Experiment Log Entry # 3,Equilibrate Segment -60 (C) Started
Experiment Log Entry # 5,Air Cool is off.
Experiment Log Entry # 7,Data On set to 1
Experiment Log Entry # 9,Ramp Segment 10 C/min to 200 Started
Experiment Log Entry # 11,Data On set to 0
Experiment Log Entry # 13,Isothermal Segment 2 min started
Experiment Log Entry # 15,Data On set to 1
Experiment Log Entry # 17,Ramp Segment 10 C/min to -60 Started
Experiment Log Entry # 19,Data On set to 0
Experiment Log Entry # 21,Isothermal Segment 2 min started
Experiment Log Entry # 23,Data On set to 1
Experiment Log Entry # 25,Ramp Segment 10 C/min to 200 Started
Experiment Log Entry # 27,Data On set to 0
Experiment Log Entry # 29,Isothermal Segment 2 min started
Experiment Log Entry # 31,Data On set to 1
Experiment Log Entry # 33,Ramp Segment 10 C/min to -60 Started
Experiment Log Entry # 35,Data On set to 0
Experiment Log Entry # 37,Isothermal Segment 2 min started
Experiment Log Entry # 39,Data On set to 1
Experiment Log Entry # 41,Ramp Segment 10 C/min to 200 Started
Experiment Log Entry # 43,Data On set to 0
Experiment Log Entry # 45,Isothermal Segment 2 min started
Experiment Log Entry # 47,Data On set to 1
Experiment Log Entry # 49,Ramp Segment 10 C/min to -60 Started
Experiment Log Entry # 51,Data On set to 0
Experiment Log Entry # 53,Isothermal Segment 2 min started
Experiment Log Entry # 55,Data On set to 1
Experiment Log Entry # 57,Ramp Segment 10 C/min to 30 Started
[Method Log]
Method Log Entry # 1,Data Off
Method Log Entry # 2,Equilibrate -60 °C
Method Log Entry # 3,Data On
Method Log Entry # 4,(Ramp 952602) Ramp 10 °C/minute to 200 °C
Method Log Entry # 5,Data Off
Method Log Entry # 6,Isothermal 2 minutes
Method Log Entry # 7,Data On
Method Log Entry # 8,(Ramp 952606) Ramp 10 °C/minute to -60 °C
Method Log Entry # 9,Data Off
Method Log Entry # 10,Isothermal 2 minutes
Method Log Entry # 11,Data On
Method Log Entry # 12,(Ramp 952610) Ramp 10 °C/minute to 200 °C
Method Log Entry # 13,Data Off
Method Log Entry # 14,Isothermal 2 minutes
Method Log Entry # 15,Data On
Method Log Entry # 16,(Ramp 952614) Ramp 10 °C/minute to -60 °C
Method Log Entry # 17,Data Off
Method Log Entry # 18,Isothermal 2 minutes
Method Log Entry # 19,Data On
Method Log Entry # 20,(Ramp 952618) Ramp 10 °C/minute to 200 °C
Method Log Entry # 21,Data Off
Method Log Entry # 22,Isothermal 2 minutes
Method Log Entry # 23,Data On
Method Log Entry # 24,(Ramp 952622) Ramp 10 °C/minute to -60 °C
Method Log Entry # 25,Data Off
Method Log Entry # 26,Isothermal 2 minutes
Method Log Entry # 27,Data On
Method Log Entry # 28,(Ramp 952626) Ramp 10 °C/minute to 30 °C
Cell Serial,DRC2-00792
[T1 Calibration]
Slope,-0.008529666
Offset,9.636258
Initial Temperature,98.23
GUID,f8bfdadc-4977-4fdf-ba6d-0ba9134940c3
[TZero Calibration]
Date Applied,11/29/2022 4:06:13 PM
Description,From -89.059 °C to 396.009 °C at 20.000°C/min
Gas Type,Nitrogen
Pan Type,None
Source Files 1,C:\Users\yargerlab\Desktop\DSC Data\General\TZero_calibration_11_29_22_2nd(2).tri
Source Files 2,C:\Users\yargerlab\Desktop\DSC Data\General\TZero_calibration_11_29_22_2nd(3).tri
Delta T Offset,13.05235
Delta T Slope,-0.007271007
Delta T0 Offset,-13.69128
Delta T0 Slope,0.06063341
[Temperature Calibration]
Date Applied,11/29/2022 7:12:28 PM
Description,From 106.590 °C to 186.590 °C at 10.000°C/min
Gas Type,Nitrogen
Pan Type,Tzero Aluminum Hermetic
Source Files 1,C:\Users\yargerlab\Desktop\DSC Data\General\Indium(6).tri
Measured 1,157.391
Known 1,156.598
[Cell Constant Calibration]
Date Applied,11/29/2022 7:12:29 PM
Description,From 106.590 °C to 186.590 °C at 10.000°C/min
Gas Type,Nitrogen
Pan Type,Tzero Aluminum Hermetic
Source Files 1,C:\Users\yargerlab\Desktop\DSC Data\General\Indium(6).tri
T4P KCell,1.006051
Onset Slope,63.26126 mW/°C
[Direct Cp Calibration]
Date Applied,11/30/2022 11:04:51 AM
Description,From -79.983 °C to 298.409 °C at 10.000°C/min
Gas Type,Nitrogen
Pan Type,Tzero Aluminum Hermetic
Source Files 1,C:\Users\yargerlab\Desktop\DSC Data\General\Sapphire_Heat_Capacity_11_30_22.tri
[Rev Cp Calibration]
Date Applied,11/30/2022 1:58:51 PM
Description,From -79.996 °C to 292.812 °C at 3.000°C/min
Gas Type,Nitrogen
Pan Type,Tzero Aluminum Hermetic
Source Files 1,C:\Users\yargerlab\Desktop\DSC Data\General\Sapphire_MDSC_Calibration_11_30_22.tri
[step]
Ramp 10.00 °C/min to 200.00 °C
Time,Temperature,Heat Flow (Normalized)
min,°C,W/g
0.00,-59.82,-0.047
0.02,-59.82,-0.046
0.04,-59.82,-0.039
0.05,-59.81,-0.033
0.07,-59.77,-0.022
0.09,-59.71,-0.009
0.11,-59.63,0.012
0.13,-59.51,0.034
0.15,-59.38,0.060
0.16,-59.23,0.081
0.18,-59.07,0.100
0.20,-58.89,0.118
0.22,-58.72,0.133
0.24,-58.54,0.141
0.26,-58.36,0.148
0.28,-58.18,0.152
0.29,-58.00,0.158
0.31,-57.82,0.161
0.33,-57.64,0.161
0.35,-57.46,0.162
0.37,-57.28,0.163
0.39,-57.10,0.163
0.40,-56.92,0.164
0.42,-56.74,0.164
0.44,-56.56,0.165
0.46,-56.38,0.165
0.48,-56.20,0.165
0.50,-56.02,0.166
0.51,-55.84,0.166
0.53,-55.66,0.167
0.55,-55.48,0.167
0.57,-55.30,0.168
0.59,-55.12,0.168
0.60,-54.94,0.168
0.62,-54.76,0.169
0.64,-54.57,0.169
0.66,-54.39,0.170
0.68,-54.21,0.170
0.70,-54.03,0.170
0.72,-53.85,0.171
0.73,-53.67,0.171
0.75,-53.49,0.171
0.77,-53.31,0.172
0.79,-53.12,0.172
0.81,-52.94,0.172
0.83,-52.76,0.173
0.84,-52.58,0.173
0.86,-52.40,0.173
0.88,-52.22,0.173
0.90,-52.04,0.173
0.92,-51.85,0.174
0.93,-51.67,0.174
0.95,-51.49,0.174
0.97,-51.31,0.174
0.99,-51.13,0.174
1.01,-50.95,0.175
1.03,-50.76,0.175
1.05,-50.58,0.175
1.06,-50.40,0.175
1.08,-50.22,0.175
1.10,-50.03,0.176
1.12,-49.85,0.176
1.14,-49.67,0.176
1.16,-49.49,0.176
1.17,-49.30,0.176
1.19,-49.12,0.177
1.21,-48.93,0.177
1.23,-48.75,0.177
1.25,-48.57,0.177
1.27,-48.39,0.177
1.28,-48.20,0.177
1.30,-48.02,0.177
1.32,-47.84,0.177
1.34,-47.65,0.178
1.36,-47.47,0.178
1.38,-47.29,0.178
1.39,-47.10,0.178
1.41,-46.92,0.178
1.43,-46.73,0.178
1.45,-46.55,0.178
1.47,-46.37,0.178
1.48,-46.19,0.178
1.50,-46.00,0.178
1.52,-45.82,0.178
1.54,-45.64,0.178
1.56,-45.45,0.179
1.58,-45.27,0.179
1.59,-45.09,0.179
1.61,-44.90,0.179
1.63,-44.72,0.179
1.65,-44.53,0.179
1.67,-44.35,0.179
1.69,-44.17,0.179
1.71,-43.98,0.179
1.72,-43.80,0.179
1.74,-43.62,0.179
1.76,-43.43,0.179
1.78,-43.25,0.179
1.80,-43.07,0.179
1.82,-42.88,0.179
1.83,-42.70,0.179
1.85,-42.52,0.179
1.87,-42.33,0.179
1.89,-42.15,0.179
1.91,-41.97,0.179
1.93,-41.78,0.179
1.94,-41.60,0.179
1.96,-41.41,0.179
1.98,-41.23,0.179
2.00,-41.04,0.179
2.02,-40.86,0.179
2.03,-40.68,0.179
2.05,-40.49,0.179
2.07,-40.31,0.179
2.09,-40.13,0.179
2.11,-39.94,0.179
2.13,-39.76,0.179
2.14,-39.58,0.179
2.16,-39.39,0.179
2.18,-39.21,0.179
2.20,-39.03,0.179
2.22,-38.84,0.179
2.24,-38.66,0.179
2.26,-38.48,0.179
2.27,-38.29,0.179
2.29,-38.11,0.179
2.31,-37.93,0.179
2.33,-37.74,0.179
2.35,-37.56,0.179
2.36,-37.38,0.179
2.38,-37.19,0.179
2.40,-37.01,0.179
2.42,-36.83,0.179
2.44,-36.64,0.179
2.46,-36.46,0.179
2.48,-36.27,0.179
2.49,-36.09,0.179
2.51,-35.91,0.179
2.53,-35.72,0.179
2.55,-35.54,0.179
2.57,-35.36,0.179
2.59,-35.17,0.179
2.60,-34.99,0.179
2.62,-34.81,0.179
2.64,-34.63,0.179
2.66,-34.44,0.179
2.68,-34.26,0.179
2.69,-34.08,0.179
2.71,-33.89,0.179
2.73,-33.71,0.179
2.75,-33.52,0.179
2.77,-33.34,0.179
2.79,-33.16,0.179
2.81,-32.97,0.179
2.82,-32.79,0.179
2.84,-32.61,0.179
2.86,-32.42,0.179
2.88,-32.24,0.179
2.90,-32.05,0.179
2.91,-31.87,0.179
2.93,-31.69,0.179
2.95,-31.50,0.179
2.97,-31.32,0.179
2.99,-31.14,0.179
3.01,-30.95,0.179
3.03,-30.77,0.179
3.04,-30.59,0.179
3.06,-30.40,0.179
3.08,-30.22,0.179
3.10,-30.04,0.179
3.12,-29.85,0.179
3.14,-29.67,0.179
3.15,-29.49,0.179
3.17,-29.30,0.179
3.19,-29.12,0.179
3.21,-28.93,0.179
3.23,-28.75,0.179
3.24,-28.57,0.179
3.26,-28.38,0.179
3.28,-28.20,0.179
3.30,-28.02,0.180
3.32,-27.83,0.179
3.34,-27.65,0.180
3.36,-27.47,0.179
3.37,-27.28,0.180
3.39,-27.10,0.180
3.41,-26.92,0.180
3.43,-26.73,0.180
3.45,-26.55,0.180
3.46,-26.37,0.180
3.48,-26.18,0.180
3.50,-26.00,0.180
3.52,-25.81,0.180
3.54,-25.63,0.180
3.56,-25.45,0.180
3.58,-25.26,0.180
3.59,-25.08,0.180
3.61,-24.89,0.180
3.63,-24.71,0.180
3.65,-24.52,0.180
3.67,-24.34,0.180
3.69,-24.15,0.180
3.70,-23.97,0.181
3.72,-23.79,0.181
3.74,-23.60,0.181
3.76,-23.42,0.181
3.78,-23.24,0.181
3.79,-23.05,0.181
3.81,-22.87,0.181
3.83,-22.69,0.181
3.85,-22.50,0.181
3.87,-22.32,0.181
3.89,-22.14,0.182
3.91,-21.95,0.182
3.92,-21.77,0.181
3.94,-21.59,0.182
3.96,-21.40,0.182
3.98,-21.22,0.182
4.00,-21.04,0.182
4.01,-20.85,0.182
4.03,-20.67,0.182
4.05,-20.49,0.182
4.07,-20.30,0.182
4.09,-20.12,0.182
4.11,-19.94,0.182
4.13,-19.75,0.182
4.14,-19.57,0.182
4.16,-19.39,0.182
4.18,-19.20,0.182
4.20,-19.02,0.182
4.22,-18.84,0.182
4.24,-18.65,0.182
4.25,-18.47,0.183
4.27,-18.29,0.183
4.29,-18.10,0.183
4.31,-17.92,0.183
4.33,-17.74,0.183
4.35,-17.55,0.183
4.36,-17.37,0.183
4.38,-17.18,0.183
4.40,-17.00,0.183
4.42,-16.82,0.183
4.44,-16.63,0.184
4.45,-16.45,0.184
4.47,-16.27,0.184
4.49,-16.08,0.184
4.51,-15.90,0.184
4.53,-15.72,0.184
4.55,-15.53,0.184
4.56,-15.35,0.184
4.58,-15.17,0.185
4.60,-14.98,0.185
4.62,-14.80,0.185
4.64,-14.62,0.185
4.66,-14.43,0.185
4.68,-14.25,0.185
4.69,-14.07,0.185
4.71,-13.88,0.185
4.73,-13.70,0.185
4.75,-13.51,0.186
4.77,-13.33,0.186
4.79,-13.15,0.186
4.80,-12.96,0.186
4.82,-12.78,0.186
4.84,-12.60,0.186
4.86,-12.41,0.186
4.88,-12.23,0.186
4.90,-12.05,0.187
4.91,-11.87,0.187
4.93,-11.68,0.187
4.95,-11.50,0.187
4.97,-11.31,0.187
4.99,-11.13,0.187
5.00,-10.95,0.188
5.02,-10.76,0.188
5.04,-10.58,0.188
5.06,-10.40,0.188
5.08,-10.21,0.188
5.10,-10.03,0.189
5.11,-9.85,0.189
5.13,-9.66,0.189
5.15,-9.48,0.189
5.17,-9.29,0.189
5.19,-9.11,0.190
5.21,-8.93,0.190
5.23,-8.75,0.190
5.24,-8.56,0.190
5.26,-8.38,0.190
5.28,-8.19,0.191
5.30,-8.01,0.191
5.32,-7.83,0.191
5.34,-7.64,0.191
5.35,-7.46,0.191
5.37,-7.28,0.192
5.39,-7.09,0.192
5.41,-6.91,0.192
5.43,-6.73,0.192
5.45,-6.54,0.192
5.46,-6.36,0.193
5.48,-6.17,0.193
5.50,-5.99,0.193
5.52,-5.81,0.193
5.54,-5.62,0.194
5.55,-5.44,0.194
5.57,-5.26,0.194
5.59,-5.07,0.194
5.61,-4.89,0.194
5.63,-4.71,0.195
5.65,-4.52,0.195
5.66,-4.34,0.195
5.68,-4.16,0.196
5.70,-3.97,0.196
5.72,-3.79,0.196
5.74,-3.61,0.197
5.76,-3.42,0.197
5.78,-3.24,0.197
5.79,-3.06,0.197
5.81,-2.87,0.198
5.83,-2.69,0.198
5.85,-2.50,0.198
5.87,-2.32,0.199
5.89,-2.14,0.199
5.90,-1.96,0.199
5.92,-1.77,0.200
5.94,-1.59,0.200
5.96,-1.40,0.200
5.98,-1.22,0.201
6.00,-1.04,0.201
6.01,-0.85,0.201
6.03,-0.67,0.201
6.05,-0.49,0.202
6.07,-0.30,0.202
6.09,-0.12,0.203
6.10,0.06,0.203
6.12,0.25,0.203
6.14,0.43,0.203
6.16,0.61,0.204
6.18,0.80,0.204
6.20,0.98,0.205
6.21,1.16,0.205
6.23,1.35,0.205
6.25,1.53,0.206
6.27,1.72,0.206
6.29,1.90,0.207
6.31,2.08,0.207
6.33,2.27,0.207
6.34,2.45,0.208
6.36,2.63,0.208
6.38,2.81,0.209
6.40,3.00,0.209
6.42,3.18,0.209
6.44,3.37,0.210
6.45,3.55,0.210
6.47,3.73,0.211
6.49,3.92,0.211
6.51,4.10,0.212
6.53,4.28,0.212
6.55,4.47,0.213
6.56,4.65,0.213
6.58,4.83,0.214
6.60,5.02,0.214
6.62,5.20,0.215
6.64,5.38,0.215
6.65,5.57,0.216
6.67,5.75,0.216
6.69,5.94,0.217
6.71,6.12,0.217
6.73,6.30,0.218
6.75,6.48,0.218
6.76,6.67,0.219
6.78,6.85,0.219
6.80,7.04,0.220
6.82,7.22,0.221
6.84,7.40,0.221
6.86,7.59,0.222
6.88,7.77,0.222
6.89,7.95,0.223
6.91,8.14,0.223
6.93,8.32,0.224
6.95,8.50,0.225
6.97,8.69,0.225
6.99,8.87,0.226
7.00,9.05,0.226
7.02,9.24,0.227
7.04,9.42,0.228
7.06,9.60,0.228
7.08,9.79,0.229
7.10,9.97,0.229
7.11,10.15,0.230
7.13,10.34,0.231
7.15,10.52,0.231
7.17,10.70,0.232
7.19,10.89,0.233
7.20,11.07,0.233
7.22,11.25,0.234
7.24,11.44,0.235
7.26,11.62,0.236
7.28,11.81,0.236
7.30,11.99,0.237
7.31,12.17,0.238
7.33,12.36,0.238
7.35,12.54,0.239
7.37,12.72,0.240
7.39,12.91,0.241
7.41,13.09,0.242
7.43,13.28,0.242
7.44,13.46,0.243
7.46,13.64,0.244
7.48,13.82,0.245
7.50,14.01,0.245
7.52,14.19,0.246
7.54,14.37,0.247
7.55,14.56,0.248
7.57,14.74,0.249
7.59,14.92,0.250
7.61,15.11,0.251
7.63,15.29,0.251
7.65,15.48,0.253
7.66,15.66,0.253
7.68,15.84,0.254
7.70,16.02,0.255
7.72,16.21,0.256
7.74,16.39,0.257
7.75,16.57,0.258
7.77,16.76,0.259
7.79,16.94,0.260
7.81,17.12,0.261
7.83,17.31,0.262
7.85,17.49,0.263
7.86,17.67,0.264
7.88,17.86,0.265
7.90,18.04,0.266
7.92,18.22,0.267
7.94,18.41,0.268
7.96,18.59,0.269
7.98,18.77,0.270
7.99,18.96,0.271
8.01,19.14,0.272
8.03,19.32,0.273
8.05,19.51,0.274
8.07,19.69,0.275
8.09,19.87,0.276
8.10,20.06,0.277
8.12,20.24,0.279
8.14,20.42,0.280
8.16,20.61,0.281
8.18,20.79,0.283
8.20,20.97,0.284
8.21,21.16,0.285
8.23,21.34,0.286
8.25,21.52,0.287
8.27,21.71,0.288
8.29,21.89,0.290
8.30,22.07,0.291
8.32,22.26,0.292
8.34,22.44,0.293
8.36,22.62,0.295
8.38,22.81,0.296
8.40,22.99,0.297
8.41,23.17,0.299
8.43,23.36,0.301
8.45,23.54,0.302
8.47,23.72,0.303
8.49,23.90,0.304
8.51,24.09,0.306
8.53,24.27,0.308
8.54,24.45,0.309
8.56,24.64,0.310
8.58,24.82,0.312
8.60,25.00,0.313
8.62,25.19,0.315
8.63,25.37,0.316
8.65,25.55,0.318
8.67,25.74,0.320
8.69,25.92,0.322
8.71,26.11,0.323
8.73,26.29,0.325
8.75,26.47,0.326
8.76,26.65,0.328
8.78,26.84,0.330
8.80,27.02,0.332
8.82,27.20,0.333
8.84,27.39,0.335
8.85,27.57,0.336
8.87,27.76,0.338
8.89,27.94,0.340
8.91,28.12,0.342
8.93,28.30,0.343
8.95,28.49,0.345
8.97,28.67,0.347
8.98,28.85,0.349
9.00,29.04,0.351
9.02,29.22,0.353
9.04,29.41,0.355
9.06,29.59,0.357
9.08,29.77,0.359
9.09,29.95,0.361
9.11,30.14,0.363
9.13,30.32,0.365
9.15,30.50,0.368
9.17,30.69,0.369
9.18,30.87,0.372
9.20,31.05,0.374
9.22,31.24,0.377
9.24,31.42,0.379
9.26,31.60,0.381
9.28,31.79,0.384
9.30,31.97,0.386
9.31,32.15,0.388
9.33,32.34,0.391
9.35,32.52,0.393
9.37,32.70,0.394
9.39,32.89,0.397
9.40,33.07,0.400
9.42,33.25,0.402
9.44,33.44,0.405
9.46,33.62,0.408
9.48,33.80,0.410
9.50,33.99,0.413
9.52,34.17,0.415
9.53,34.35,0.418
9.55,34.54,0.420
9.57,34.72,0.423
9.59,34.90,0.425
9.61,35.09,0.430
9.63,35.27,0.432
9.64,35.45,0.434
9.66,35.63,0.437
9.68,35.82,0.442
9.70,36.00,0.443
9.72,36.18,0.447
9.73,36.37,0.452
9.75,36.55,0.454
9.77,36.73,0.456
9.79,36.92,0.460
9.81,37.10,0.462
9.83,37.28,0.465
9.85,37.47,0.467
9.86,37.65,0.471
9.88,37.83,0.473
9.90,38.02,0.476
9.92,38.20,0.480
9.94,38.38,0.482
9.95,38.57,0.485
9.97,38.75,0.488
9.99,38.93,0.491
10.01,39.11,0.495
10.03,39.30,0.497
10.05,39.48,0.500
10.07,39.66,0.503
10.08,39.85,0.506
10.10,40.03,0.509
10.12,40.21,0.511
10.14,40.40,0.515
10.16,40.58,0.519
10.18,40.76,0.521
10.19,40.95,0.523
10.21,41.13,0.527
10.23,41.31,0.530
10.25,41.49,0.533
10.27,41.68,0.538
10.28,41.86,0.540
10.30,42.04,0.544
10.32,42.23,0.546
10.34,42.41,0.550
10.36,42.59,0.553
10.38,42.78,0.556
10.40,42.96,0.561
10.41,43.14,0.563
10.43,43.33,0.566
10.45,43.51,0.569
10.47,43.69,0.572
10.49,43.87,0.579
10.50,44.06,0.581
10.52,44.24,0.584
10.54,44.42,0.588
10.56,44.61,0.591
10.58,44.79,0.594
10.60,44.97,0.597
10.62,45.16,0.600
10.63,45.34,0.605
10.65,45.52,0.607
10.67,45.71,0.611
10.69,45.89,0.615
10.71,46.07,0.618
10.73,46.25,0.622
10.74,46.44,0.626
10.76,46.62,0.629
10.78,46.80,0.632
10.80,46.99,0.635
10.82,47.17,0.639
10.83,47.35,0.643
10.85,47.54,0.646
10.87,47.72,0.649
10.89,47.90,0.654
10.91,48.08,0.656
10.93,48.27,0.660
10.95,48.45,0.665
10.96,48.63,0.666
10.98,48.82,0.672
11.00,49.00,0.675
11.02,49.18,0.680
11.04,49.37,0.682
11.05,49.55,0.686
11.07,49.73,0.689
11.09,49.91,0.692
11.11,50.10,0.696
11.13,50.28,0.702
11.15,50.46,0.704
11.17,50.65,0.708
11.18,50.83,0.713
11.20,51.01,0.717
11.22,51.20,0.720
11.24,51.38,0.724
11.26,51.56,0.727
11.28,51.75,0.730
11.29,51.93,0.734
11.31,52.11,0.739
11.33,52.29,0.742
11.35,52.48,0.746
11.37,52.66,0.750
11.38,52.84,0.753
11.40,53.03,0.756
11.42,53.21,0.762
11.44,53.39,0.765
11.46,53.57,0.769
11.48,53.76,0.773
11.50,53.94,0.776
11.51,54.12,0.779
11.53,54.31,0.783
11.55,54.49,0.788
11.57,54.67,0.792
11.59,54.86,0.795
11.60,55.04,0.799
11.62,55.22,0.804
11.64,55.41,0.807
11.66,55.59,0.811
11.68,55.77,0.816
11.70,55.95,0.819
11.72,56.14,0.822
11.73,56.32,0.826
11.75,56.50,0.830
11.77,56.69,0.835
11.79,56.87,0.837
11.81,57.05,0.841
11.83,57.24,0.845
11.84,57.42,0.849
11.86,57.60,0.853
11.88,57.78,0.856
11.90,57.97,0.861
11.92,58.15,0.866
11.93,58.33,0.869
11.95,58.52,0.872
11.97,58.70,0.876
11.99,58.88,0.880
12.01,59.07,0.883
12.03,59.25,0.888
12.05,59.43,0.892
12.06,59.61,0.896
12.08,59.80,0.899
12.10,59.98,0.903
12.12,60.16,0.907
12.14,60.35,0.910
12.15,60.53,0.913
12.17,60.71,0.917
12.19,60.90,0.920
12.21,61.08,0.924
12.23,61.26,0.927
12.25,61.44,0.931
12.27,61.63,0.935
12.28,61.81,0.938
12.30,61.99,0.941
12.32,62.18,0.944
12.34,62.36,0.948
12.36,62.54,0.951
12.38,62.73,0.954
12.39,62.91,0.956
12.41,63.09,0.960
12.43,63.28,0.964
12.45,63.46,0.967
12.47,63.64,0.972
12.48,63.83,0.974
12.50,64.01,0.977
12.52,64.19,0.979
12.54,64.37,0.981
12.56,64.56,0.986
12.58,64.74,0.987
12.60,64.92,0.990
12.61,65.11,0.993
12.63,65.29,0.996
12.65,65.47,0.997
12.67,65.66,1.000
12.69,65.84,1.002
12.70,66.02,1.005
12.72,66.21,1.007
12.74,66.39,1.009
12.76,66.57,1.011
12.78,66.75,1.014
12.80,66.94,1.017
12.82,67.12,1.018
12.83,67.30,1.021
12.85,67.49,1.022
12.87,67.67,1.024
12.89,67.86,1.027
12.91,68.04,1.029
12.93,68.22,1.032
12.94,68.41,1.033
12.96,68.59,1.035
12.98,68.77,1.037
13.00,68.95,1.039
13.02,69.14,1.040
13.03,69.32,1.042
13.05,69.50,1.043
13.07,69.69,1.045
13.09,69.87,1.047
13.11,70.05,1.048
13.13,70.24,1.050
13.15,70.42,1.051
13.16,70.60,1.052
13.18,70.79,1.054
13.20,70.97,1.055
13.22,71.15,1.056
13.24,71.34,1.058
13.25,71.52,1.059
13.27,71.71,1.060
13.29,71.89,1.061
13.31,72.07,1.062
13.33,72.26,1.063
13.35,72.44,1.064
13.37,72.62,1.065
13.38,72.81,1.066
13.40,72.99,1.067
13.42,73.17,1.068
13.44,73.36,1.068
13.46,73.54,1.069
13.48,73.72,1.070
13.49,73.91,1.070
13.51,74.09,1.071
13.53,74.28,1.071
13.55,74.46,1.072
13.57,74.65,1.072
13.58,74.83,1.072
13.60,75.01,1.072
13.62,75.20,1.073
13.64,75.38,1.073
13.66,75.57,1.073
13.68,75.75,1.073
13.70,75.93,1.072
13.71,76.12,1.072
13.73,76.30,1.072
13.75,76.48,1.071
13.77,76.67,1.070
13.79,76.85,1.070
13.80,77.03,1.069
13.82,77.22,1.068
13.84,77.40,1.068
13.86,77.58,1.067
13.88,77.76,1.066
13.90,77.95,1.065
13.92,78.13,1.064
13.93,78.32,1.063
13.95,78.50,1.061
13.97,78.68,1.060
13.99,78.87,1.059
14.01,79.05,1.058
14.03,79.23,1.056
14.04,79.42,1.054
14.06,79.60,1.052
14.08,79.79,1.049
14.10,79.97,1.047
14.12,80.16,1.045
14.13,80.34,1.042
14.15,80.52,1.040
14.17,80.71,1.036
14.19,80.89,1.034
14.21,81.08,1.030
14.23,81.26,1.027
14.25,81.44,1.022
14.26,81.63,1.018
14.28,81.81,1.015
14.30,81.99,1.011
14.32,82.18,1.007
14.34,82.36,1.004
14.35,82.55,1.001
14.37,82.73,0.998
14.39,82.91,0.993
14.41,83.10,0.990
14.43,83.28,0.986
14.45,83.47,0.981
14.47,83.65,0.979
14.48,83.83,0.975
14.50,84.02,0.971
14.52,84.20,0.965
14.54,84.39,0.962
14.56,84.57,0.958
14.58,84.76,0.954
14.59,84.94,0.950
14.61,85.12,0.946
14.63,85.31,0.941
14.65,85.49,0.936
14.67,85.68,0.932
14.68,85.86,0.927
14.70,86.04,0.922
14.72,86.23,0.919
14.74,86.41,0.914
14.76,86.60,0.909
14.78,86.78,0.905
14.80,86.96,0.900
14.81,87.15,0.896
14.83,87.33,0.891
14.85,87.52,0.887
14.87,87.70,0.882
14.89,87.88,0.877
14.90,88.07,0.872
14.92,88.25,0.866
14.94,88.44,0.862
14.96,88.62,0.857
14.98,88.81,0.852
15.00,88.99,0.847
15.02,89.17,0.842
15.03,89.36,0.838
15.05,89.54,0.833
15.07,89.73,0.829
15.09,89.91,0.824
15.11,90.09,0.817
15.13,90.28,0.813
15.14,90.46,0.807
15.16,90.65,0.803
15.18,90.83,0.798
15.20,91.01,0.792
15.22,91.20,0.788
15.23,91.38,0.782
15.25,91.57,0.777
15.27,91.75,0.772
15.29,91.94,0.766
15.31,92.12,0.761
15.33,92.30,0.755
15.35,92.49,0.752
15.36,92.67,0.745
15.38,92.86,0.741
15.40,93.04,0.735
15.42,93.22,0.729
15.44,93.41,0.725
15.45,93.59,0.720
15.47,93.78,0.715
15.49,93.96,0.708
15.51,94.14,0.704
15.53,94.33,0.699
15.55,94.51,0.692
15.57,94.70,0.688
15.58,94.88,0.683
15.60,95.07,0.677
15.62,95.25,0.671
15.64,95.43,0.667
15.66,95.62,0.663
15.68,95.80,0.656
15.69,95.99,0.651
15.71,96.17,0.647
15.73,96.35,0.641
15.75,96.54,0.637
15.77,96.72,0.632
15.78,96.91,0.626
15.80,97.09,0.620
15.82,97.28,0.615
15.84,97.46,0.611
15.86,97.64,0.607
15.88,97.83,0.600
15.90,98.01,0.596
15.91,98.20,0.591
15.93,98.38,0.586
15.95,98.56,0.582
15.97,98.75,0.575
15.99,98.93,0.571
16.00,99.12,0.566
16.02,99.30,0.563
16.04,99.49,0.557
16.06,99.67,0.552
16.08,99.85,0.547
16.10,100.04,0.542
16.12,100.22,0.538
16.13,100.40,0.532
16.15,100.59,0.529
16.17,100.77,0.523
16.19,100.96,0.518
16.21,101.14,0.514
16.23,101.33,0.510
16.24,101.51,0.506
16.26,101.69,0.502
16.28,101.88,0.497
16.30,102.06,0.493
16.32,102.25,0.489
16.33,102.43,0.484
16.35,102.61,0.480
16.37,102.80,0.475
16.39,102.98,0.471
16.41,103.17,0.465
16.43,103.35,0.462
16.45,103.54,0.458
16.46,103.72,0.454
16.48,103.90,0.449
16.50,104.09,0.446
16.52,104.27,0.441
16.54,104.45,0.437
16.55,104.64,0.434
16.57,104.82,0.430
16.59,105.01,0.426
16.61,105.19,0.423
16.63,105.37,0.419
16.65,105.56,0.416
16.67,105.74,0.410
16.68,105.93,0.407
16.70,106.11,0.404
16.72,106.29,0.400
16.74,106.48,0.396
16.76,106.66,0.392
16.78,106.84,0.389
16.79,107.03,0.385
16.81,107.21,0.383
16.83,107.40,0.379
16.85,107.58,0.377
16.87,107.77,0.374
16.88,107.95,0.370
16.90,108.13,0.368
16.92,108.32,0.364
16.94,108.50,0.361
16.96,108.69,0.358
16.98,108.87,0.354
17.00,109.05,0.352
17.01,109.24,0.349
17.03,109.42,0.346
17.05,109.60,0.344
17.07,109.79,0.342
17.09,109.97,0.340
17.11,110.16,0.336
17.12,110.34,0.335
17.14,110.52,0.331
17.16,110.71,0.329
17.18,110.89,0.326
17.20,111.08,0.325
17.22,111.26,0.322
17.23,111.44,0.320
17.25,111.63,0.318
17.27,111.81,0.316
17.29,111.99,0.314
17.31,112.18,0.312
17.33,112.36,0.309
17.34,112.55,0.307
17.36,112.73,0.304
17.38,112.91,0.303
17.40,113.10,0.301
17.42,113.28,0.299
17.43,113.46,0.298
17.45,113.65,0.296
17.47,113.83,0.295
17.49,114.01,0.293
17.51,114.20,0.292
17.53,114.38,0.290
17.54,114.57,0.289
17.56,114.75,0.287
17.58,114.93,0.285
17.60,115.12,0.283
17.62,115.30,0.281
17.64,115.49,0.280
17.66,115.67,0.278
17.67,115.85,0.276
17.69,116.04,0.275
17.71,116.22,0.274
17.73,116.40,0.272
17.75,116.59,0.271
17.77,116.77,0.269
17.78,116.95,0.268
17.80,117.14,0.267
17.82,117.32,0.265
17.84,117.51,0.264
17.86,117.69,0.263
17.88,117.87,0.261
17.89,118.06,0.260
17.91,118.24,0.259
17.93,118.42,0.258
17.95,118.61,0.257
17.97,118.79,0.256
17.98,118.97,0.255
18.00,119.16,0.254
18.02,119.34,0.253
18.04,119.53,0.252
18.06,119.71,0.251
18.08,119.89,0.250
18.09,120.08,0.249
18.11,120.26,0.249
18.13,120.44,0.248
18.15,120.63,0.247
18.17,120.81,0.246
18.19,120.99,0.246
18.21,121.18,0.245
18.22,121.36,0.244
18.24,121.54,0.244
18.26,121.73,0.243
18.28,121.91,0.242
18.30,122.09,0.242
18.32,122.28,0.241
18.33,122.46,0.241
18.35,122.64,0.240
18.37,122.83,0.240
18.39,123.01,0.239
18.41,123.20,0.239
18.43,123.38,0.238
18.44,123.56,0.238
18.46,123.75,0.238
18.48,123.93,0.237
18.50,124.11,0.237
18.52,124.30,0.237
18.53,124.48,0.236
18.55,124.66,0.236
18.57,124.85,0.236
18.59,125.03,0.236
18.61,125.21,0.235
18.63,125.40,0.235
18.64,125.58,0.235
18.66,125.76,0.235
18.68,125.95,0.235
18.70,126.13,0.235
18.72,126.31,0.235
18.74,126.50,0.235
18.76,126.68,0.235
18.77,126.86,0.235
18.79,127.05,0.235
18.81,127.23,0.235
18.83,127.41,0.235
18.85,127.60,0.235
18.87,127.78,0.235
18.88,127.96,0.236
18.90,128.15,0.236
18.92,128.33,0.236
18.94,128.51,0.236
18.96,128.70,0.236
18.98,128.88,0.236
18.99,129.06,0.236
19.01,129.25,0.236
19.03,129.43,0.237
19.05,129.61,0.237
19.07,129.80,0.237
19.08,129.98,0.237
19.10,130.16,0.237
19.12,130.35,0.237
19.14,130.53,0.238
19.16,130.72,0.238
19.18,130.90,0.238
19.19,131.08,0.238
19.21,131.27,0.239
19.23,131.45,0.239
19.25,131.63,0.239
19.27,131.82,0.239
19.29,132.00,0.240
19.31,132.18,0.240
19.32,132.37,0.240
19.34,132.55,0.240
19.36,132.73,0.241
19.38,132.92,0.241
19.40,133.10,0.241
19.42,133.28,0.242
19.43,133.47,0.242
19.45,133.65,0.242
19.47,133.83,0.243
19.49,134.02,0.243
19.51,134.20,0.244
19.53,134.39,0.244
19.54,134.57,0.244
19.56,134.75,0.245
19.58,134.94,0.245
19.60,135.12,0.246
19.62,135.30,0.246
19.63,135.49,0.246
19.65,135.67,0.247
19.67,135.85,0.247
19.69,136.04,0.248
19.71,136.22,0.248
19.73,136.40,0.248
19.74,136.59,0.249
19.76,136.77,0.249
19.78,136.95,0.250
19.80,137.14,0.250
19.82,137.32,0.251
19.84,137.50,0.251
19.86,137.69,0.252
19.87,137.87,0.252
19.89,138.05,0.253
19.91,138.24,0.254
19.93,138.42,0.254
19.95,138.60,0.255
19.97,138.79,0.255
19.98,138.97,0.256
20.00,139.15,0.257
20.02,139.34,0.258
20.04,139.52,0.258
20.06,139.70,0.259
20.08,139.89,0.260
20.09,140.07,0.260
20.11,140.25,0.261
20.13,140.44,0.262
20.15,140.62,0.263
20.17,140.80,0.263
20.18,140.99,0.264
20.20,141.17,0.265
20.22,141.35,0.266
20.24,141.54,0.267
20.26,141.72,0.267
20.28,141.90,0.268
20.29,142.09,0.269
20.31,142.27,0.270
20.33,142.45,0.271
20.35,142.64,0.272
20.37,142.82,0.273
20.39,143.00,0.274
20.41,143.19,0.275
20.42,143.37,0.276
20.44,143.55,0.277
20.46,143.74,0.278
20.48,143.92,0.279
20.50,144.10,0.280
20.52,144.29,0.281
20.53,144.47,0.282
20.55,144.65,0.282
20.57,144.84,0.283
20.59,145.02,0.284
20.61,145.20,0.285
20.63,145.39,0.286
20.64,145.57,0.287
20.66,145.75,0.288
20.68,145.94,0.289
20.70,146.12,0.290
20.72,146.30,0.291
20.73,146.49,0.291
20.75,146.67,0.292
20.77,146.85,0.293
20.79,147.04,0.294
20.81,147.22,0.295
20.83,147.40,0.295
20.84,147.59,0.296
20.86,147.77,0.297
20.88,147.96,0.298
20.90,148.14,0.298
20.92,148.32,0.299
20.94,148.51,0.300
20.96,148.69,0.300
20.97,148.87,0.301
20.99,149.06,0.302
21.01,149.24,0.302
21.03,149.42,0.303
21.05,149.61,0.303
21.07,149.79,0.304
21.08,149.97,0.304
21.10,150.16,0.305
21.12,150.34,0.305
21.14,150.52,0.306
21.16,150.71,0.306
21.18,150.89,0.306
21.19,151.08,0.307
21.21,151.26,0.307
21.23,151.44,0.307
21.25,151.63,0.308
21.27,151.81,0.308
21.28,151.99,0.308
21.30,152.18,0.309
21.32,152.36,0.309
21.34,152.54,0.309
21.36,152.73,0.309
21.38,152.91,0.309
21.39,153.09,0.310
21.41,153.28,0.310
21.43,153.46,0.310
21.45,153.64,0.310
21.47,153.83,0.310
21.49,154.01,0.310
21.51,154.19,0.310
21.52,154.38,0.311
21.54,154.56,0.311
21.56,154.74,0.311
21.58,154.93,0.311
21.60,155.11,0.311
21.62,155.29,0.311
21.63,155.48,0.311
21.65,155.66,0.311
21.67,155.84,0.311
21.69,156.03,0.312
21.71,156.21,0.312
21.73,156.39,0.312
21.74,156.58,0.312
21.76,156.76,0.312
21.78,156.94,0.312
21.80,157.13,0.313
21.82,157.31,0.313
21.83,157.49,0.313
21.85,157.68,0.313
21.87,157.86,0.314
21.89,158.04,0.314
21.91,158.23,0.314
21.93,158.41,0.314
21.94,158.59,0.314
21.96,158.78,0.315
21.98,158.96,0.315
22.00,159.14,0.315
22.02,159.33,0.315
22.04,159.51,0.316
22.06,159.70,0.316
22.07,159.88,0.316
22.09,160.06,0.316
22.11,160.25,0.316
22.13,160.43,0.317
22.15,160.61,0.317
22.17,160.80,0.317
22.18,160.98,0.317
22.20,161.16,0.317
22.22,161.35,0.318
22.24,161.53,0.318
22.26,161.71,0.318
22.28,161.90,0.318
22.29,162.08,0.318
22.31,162.26,0.319
22.33,162.44,0.319
22.35,162.63,0.319
22.37,162.81,0.319
22.38,163.00,0.320
22.40,163.18,0.320
22.42,163.36,0.320
22.44,163.55,0.320
22.46,163.73,0.320
22.48,163.91,0.321
22.49,164.10,0.321
22.51,164.28,0.321
22.53,164.46,0.321
22.55,164.65,0.321
22.57,164.83,0.322
22.59,165.01,0.322
22.61,165.20,0.322
22.62,165.38,0.322
22.64,165.57,0.322
22.66,165.75,0.322
22.68,165.93,0.323
22.70,166.12,0.323
22.72,166.30,0.323
22.73,166.48,0.323
22.75,166.67,0.324
22.77,166.85,0.324
22.79,167.03,0.324
22.81,167.22,0.324
22.83,167.40,0.325
22.84,167.58,0.325
22.86,167.76,0.325
22.88,167.95,0.325
22.90,168.13,0.326
22.92,168.32,0.326
22.93,168.50,0.326
22.95,168.68,0.326
22.97,168.87,0.327
22.99,169.05,0.327
23.01,169.24,0.327
23.03,169.42,0.327
23.04,169.60,0.328
23.06,169.79,0.328
23.08,169.97,0.328
23.10,170.15,0.328
23.12,170.34,0.328
23.14,170.52,0.329
23.16,170.70,0.329
23.17,170.89,0.329
23.19,171.07,0.329
23.21,171.25,0.330
23.23,171.43,0.330
23.25,171.62,0.330
23.27,171.80,0.330
23.28,171.98,0.331
23.30,172.17,0.331
23.32,172.35,0.331
23.34,172.53,0.332
23.36,172.72,0.332
23.38,172.90,0.333
23.39,173.08,0.333
23.41,173.27,0.333
23.43,173.45,0.333
23.45,173.63,0.334
23.47,173.82,0.334
23.48,174.00,0.334
23.50,174.19,0.335
23.52,174.37,0.335
23.54,174.55,0.336
23.56,174.74,0.336
23.58,174.92,0.336
23.59,175.10,0.337
23.61,175.29,0.337
23.63,175.47,0.338
23.65,175.65,0.338
23.67,175.84,0.338
23.69,176.02,0.339
23.71,176.20,0.339
23.72,176.39,0.340
23.74,176.57,0.340
23.76,176.75,0.340
23.78,176.94,0.341
23.80,177.12,0.341
23.82,177.30,0.342
23.83,177.49,0.342
23.85,177.67,0.343
23.87,177.85,0.343
23.89,178.04,0.343
23.91,178.22,0.344
23.93,178.40,0.344
23.94,178.59,0.345
23.96,178.77,0.345
23.98,178.95,0.346
24.00,179.14,0.346
24.02,179.32,0.347
24.03,179.51,0.347
24.05,179.69,0.348
24.07,179.87,0.348
24.09,180.06,0.349
24.11,180.24,0.349
24.13,180.42,0.350
24.14,180.60,0.350
24.16,180.79,0.351
24.18,180.97,0.352
24.20,181.15,0.352
24.22,181.34,0.353
24.24,181.52,0.353
24.26,181.71,0.354
24.27,181.89,0.354
24.29,182.07,0.355
24.31,182.26,0.355
24.33,182.44,0.356
24.35,182.62,0.356
24.37,182.81,0.357
24.38,182.99,0.357
24.40,183.17,0.358
24.42,183.36,0.359
24.44,183.54,0.359
24.46,183.72,0.360
24.48,183.91,0.360
24.49,184.09,0.361
24.51,184.27,0.362
24.53,184.46,0.362
24.55,184.64,0.363
24.57,184.82,0.364
24.58,185.00,0.364
24.60,185.19,0.365
24.62,185.37,0.366
24.64,185.56,0.366
24.66,185.74,0.367
24.68,185.92,0.368
24.69,186.10,0.368
24.71,186.29,0.369
24.73,186.47,0.369
24.75,186.66,0.370
24.77,186.84,0.371
24.79,187.02,0.371
24.81,187.21,0.372
24.82,187.39,0.373
24.84,187.57,0.373
24.86,187.76,0.374
24.88,187.94,0.374
24.90,188.12,0.375
24.92,188.31,0.376
24.93,188.49,0.376
24.95,188.67,0.377
24.97,188.86,0.377
24.99,189.04,0.378
25.01,189.22,0.379
25.03,189.41,0.379
25.04,189.59,0.380
25.06,189.77,0.380
25.08,189.96,0.381
25.10,190.14,0.381
25.12,190.32,0.382
25.13,190.51,0.382
25.15,190.69,0.383
25.17,190.87,0.384
25.19,191.06,0.384
25.21,191.24,0.385
25.23,191.42,0.385
25.24,191.61,0.386
25.26,191.79,0.387
25.28,191.98,0.387
25.30,192.16,0.388
25.32,192.34,0.389
25.34,192.52,0.390
25.36,192.71,0.390
25.37,192.89,0.391
25.39,193.07,0.392
25.41,193.26,0.393
25.43,193.44,0.394
25.45,193.63,0.395
25.47,193.81,0.395
25.48,193.99,0.396
25.50,194.17,0.397
25.52,194.36,0.398
25.54,194.54,0.399
25.56,194.72,0.400
25.58,194.91,0.401
25.59,195.09,0.402
25.61,195.27,0.403
25.63,195.46,0.404
25.65,195.64,0.405
25.67,195.83,0.406
25.68,196.01,0.407
25.70,196.19,0.408
25.72,196.37,0.410
25.74,196.56,0.411
25.76,196.74,0.412
25.78,196.93,0.413
25.79,197.11,0.414
25.81,197.29,0.415
25.83,197.48,0.416
25.85,197.66,0.417
25.87,197.84,0.418
25.89,198.03,0.419
25.91,198.21,0.421
25.92,198.39,0.422
25.94,198.57,
25.96,198.76,
25.98,198.94,
25.99,,

[step]
Ramp 10.00 °C/min to -60.00 °C
Time,Temperature,Heat Flow (Normalized)
min,°C,W/g
27.99,200.16,0.126
28.01,200.16,0.125
28.03,200.16,0.122
28.05,200.14,0.116
28.07,200.11,0.086
28.08,200.06,0.048
28.10,199.97,0.006
28.12,199.86,-0.038
28.14,199.72,-0.082
28.16,199.56,-0.113
28.18,199.40,-0.139
28.19,199.22,-0.158
28.21,199.04,-0.166
28.23,198.86,-0.171
28.25,198.68,-0.175
28.27,198.50,-0.174
28.29,198.32,-0.175
28.31,198.14,-0.176
28.32,197.96,-0.177
28.34,197.78,-0.177
28.36,197.60,-0.178
28.38,197.41,-0.179
28.40,197.23,-0.179
28.42,197.05,-0.180
28.43,196.87,-0.180
28.45,196.69,-0.181
28.47,196.50,-0.181
28.49,196.32,-0.182
28.51,196.14,-0.182
28.53,195.96,-0.183
28.54,195.78,-0.183
28.56,195.60,-0.184
28.58,195.41,-0.184
28.60,195.23,-0.185
28.62,195.05,-0.185
28.63,194.87,-0.186
28.65,194.69,-0.187
28.67,194.50,-0.187
28.69,194.32,-0.188
28.71,194.14,-0.188
28.73,193.96,-0.189
28.74,193.77,-0.189
28.76,193.59,-0.190
28.78,193.41,-0.190
28.80,193.23,-0.191
28.82,193.04,-0.191
28.84,192.86,-0.192
28.86,192.68,-0.192
28.87,192.50,-0.193
28.89,192.32,-0.193
28.91,192.13,-0.193
28.93,191.95,-0.194
28.95,191.77,-0.194
28.97,191.59,-0.195
28.98,191.40,-0.195
29.00,191.22,-0.195
29.02,191.04,-0.196
29.04,190.85,-0.196
29.06,190.67,-0.197
29.08,190.49,-0.197
29.09,190.31,-0.197
29.11,190.12,-0.198
29.13,189.94,-0.198
29.15,189.76,-0.199
29.17,189.57,-0.199
29.18,189.39,-0.199
29.20,189.21,-0.199
29.22,189.02,-0.200
29.24,188.84,-0.200
29.26,188.66,-0.200
29.28,188.48,-0.200
29.29,188.29,-0.201
29.31,188.11,-0.201
29.33,187.93,-0.201
29.35,187.74,-0.202
29.37,187.56,-0.202
29.39,187.38,-0.202
29.41,187.20,-0.202
29.42,187.01,-0.202
29.44,186.83,-0.202
29.46,186.65,-0.203
29.48,186.46,-0.203
29.50,186.28,-0.203
29.52,186.10,-0.203
29.53,185.91,-0.204
29.55,185.73,-0.204
29.57,185.55,-0.204
29.59,185.37,-0.204
29.61,185.18,-0.204
29.63,185.00,-0.204
29.64,184.82,-0.205
29.66,184.63,-0.205
29.68,184.45,-0.205
29.70,184.27,-0.205
29.72,184.08,-0.205
29.73,183.90,-0.205
29.75,183.72,-0.205
29.77,183.53,-0.206
29.79,183.35,-0.206
29.81,183.17,-0.206
29.83,182.98,-0.206
29.84,182.80,-0.206
29.86,182.62,-0.206
29.88,182.43,-0.206
29.90,182.25,-0.206
29.92,182.07,-0.206
29.94,181.88,-0.206
29.96,181.70,-0.206
29.97,181.52,-0.207
29.99,181.33,-0.207
30.01,181.15,-0.207
30.03,180.97,-0.207
30.05,180.78,-0.207
30.07,180.60,-0.207
30.08,180.42,-0.207
30.10,180.23,-0.207
30.12,180.05,-0.207
30.14,179.87,-0.207
30.16,179.69,-0.207
30.18,179.50,-0.207
30.19,179.32,-0.207
30.21,179.14,-0.207
30.23,178.95,-0.207
30.25,178.77,-0.207
30.27,178.59,-0.208
30.28,178.40,-0.208
30.30,178.22,-0.208
30.32,178.04,-0.208
30.34,177.85,-0.208
30.36,177.67,-0.208
30.38,177.49,-0.208
30.39,177.30,-0.208
30.41,177.12,-0.208
30.43,176.94,-0.208
30.45,176.75,-0.208
30.47,176.57,-0.208
30.49,176.39,-0.208
30.51,176.20,-0.208
30.52,176.02,-0.208
30.54,175.84,-0.209
30.56,175.65,-0.209
30.58,175.47,-0.209
30.60,175.29,-0.209
30.62,175.10,-0.209
30.63,174.92,-0.209
30.65,174.74,-0.209
30.67,174.55,-0.209
30.69,174.37,-0.209
30.71,174.19,-0.209
30.73,174.01,-0.209
30.74,173.82,-0.209
30.76,173.64,-0.209
30.78,173.46,-0.209
30.80,173.27,-0.209
30.82,173.09,-0.209
30.83,172.91,-0.209
30.85,172.72,-0.209
30.87,172.54,-0.209
30.89,172.36,-0.209
30.91,172.17,-0.209
30.93,171.99,-0.209
30.94,171.80,-0.209
30.96,171.62,-0.209
30.98,171.44,-0.209
31.00,171.25,-0.209
31.02,171.07,-0.209
31.04,170.89,-0.209
31.06,170.70,-0.209
31.07,170.52,-0.209
31.09,170.34,-0.209
31.11,170.15,-0.209
31.13,169.97,-0.209
31.15,169.79,-0.209
31.17,169.60,-0.209
31.18,169.42,-0.209
31.20,169.24,-0.209
31.22,169.05,-0.209
31.24,168.87,-0.209
31.26,168.69,-0.209
31.28,168.50,-0.209
31.29,168.32,-0.209
31.31,168.14,-0.209
31.33,167.95,-0.209
31.35,167.77,-0.209
31.37,167.59,-0.209
31.38,167.41,-0.209
31.40,167.22,-0.209
31.42,167.04,-0.209
31.44,166.86,-0.209
31.46,166.67,-0.209
31.48,166.49,-0.209
31.49,166.31,-0.209
31.51,166.12,-0.209
31.53,165.94,-0.209
31.55,165.76,-0.209
31.57,165.57,-0.209
31.59,165.39,-0.209
31.61,165.21,-0.209
31.62,165.02,-0.210
31.64,164.84,-0.210
31.66,164.66,-0.210
31.68,164.47,-0.210
31.70,164.29,-0.210
31.72,164.11,-0.210
31.73,163.92,-0.210
31.75,163.74,-0.210
31.77,163.56,-0.210
31.79,163.37,-0.210
31.81,163.19,-0.210
31.83,163.00,-0.210
31.84,162.82,-0.210
31.86,162.64,-0.210
31.88,162.45,-0.210
31.90,162.27,-0.210
31.92,162.09,-0.210
31.93,161.91,-0.210
31.95,161.72,-0.210
31.97,161.54,-0.210
31.99,161.36,-0.210
32.01,161.17,-0.210
32.03,160.99,-0.210
32.04,160.81,-0.210
32.06,160.62,-0.210
32.08,160.44,-0.210
32.10,160.26,-0.210
32.12,160.07,-0.210
32.14,159.89,-0.210
32.16,159.71,-0.210
32.17,159.52,-0.210
32.19,159.34,-0.210
32.21,159.16,-0.211
32.23,158.97,-0.211
32.25,158.79,-0.211
32.27,158.61,-0.211
32.28,158.42,-0.211
32.30,158.24,-0.211
32.32,158.06,-0.211
32.34,157.87,-0.211
32.36,157.69,-0.211
32.38,157.51,-0.211
32.39,157.32,-0.211
32.41,157.14,-0.211
32.43,156.96,-0.211
32.45,156.77,-0.211
32.47,156.59,-0.211
32.48,156.41,-0.211
32.50,156.22,-0.211
32.52,156.04,-0.211
32.54,155.86,-0.211
32.56,155.67,-0.211
32.58,155.49,-0.211
32.59,155.31,-0.211
32.61,155.13,-0.211
32.63,154.94,-0.211
32.65,154.76,-0.211
32.67,154.57,-0.211
32.69,154.39,-0.211
32.71,154.21,-0.211
32.72,154.02,-0.211
32.74,153.84,-0.211
32.76,153.66,-0.211
32.78,153.47,-0.211
32.80,153.29,-0.211
32.82,153.11,-0.211
32.83,152.92,-0.211
32.85,152.74,-0.211
32.87,152.56,-0.211
32.89,152.37,-0.211
32.91,152.19,-0.211
32.93,152.01,-0.211
32.94,151.82,-0.211
32.96,151.64,-0.211
32.98,151.46,-0.211
33.00,151.27,-0.211
33.02,151.09,-0.211
33.03,150.91,-0.211
33.05,150.72,-0.211
33.07,150.54,-0.211
33.09,150.36,-0.211
33.11,150.17,-0.211
33.13,149.99,-0.211
33.14,149.81,-0.211
33.16,149.62,-0.211
33.18,149.44,-0.211
33.20,149.26,-0.211
33.22,149.07,-0.211
33.24,148.89,-0.210
33.26,148.71,-0.210
33.27,148.52,-0.211
33.29,148.34,-0.211
33.31,148.16,-0.211
33.33,147.97,-0.211
33.35,147.79,-0.211
33.37,147.61,-0.211
33.38,147.43,-0.210
33.40,147.24,-0.210
33.42,147.06,-0.210
33.44,146.87,-0.210
33.46,146.69,-0.210
33.48,146.51,-0.210
33.49,146.32,-0.210
33.51,146.14,-0.210
33.53,145.96,-0.210
33.55,145.77,-0.210
33.57,145.59,-0.210
33.58,145.41,-0.210
33.60,145.22,-0.209
33.62,145.04,-0.209
33.64,144.86,-0.209
33.66,144.67,-0.209
33.68,144.49,-0.209
33.69,144.31,-0.209
33.71,144.12,-0.209
33.73,143.94,-0.209
33.75,143.76,-0.208
33.77,143.57,-0.208
33.79,143.39,-0.208
33.81,143.21,-0.208
33.82,143.02,-0.208
33.84,142.84,-0.208
33.86,142.66,-0.208
33.88,142.47,-0.208
33.90,142.29,-0.207
33.92,142.11,-0.207
33.93,141.92,-0.207
33.95,141.74,-0.207
33.97,141.56,-0.207
33.99,141.37,-0.206
34.01,141.19,-0.206
34.03,141.01,-0.206
34.04,140.83,-0.206
34.06,140.64,-0.206
34.08,140.46,-0.205
34.10,140.28,-0.205
34.12,140.09,-0.205
34.14,139.91,-0.205
34.15,139.72,-0.204
34.17,139.54,-0.204
34.19,139.36,-0.204
34.21,139.17,-0.203
34.23,138.99,-0.203
34.24,138.81,-0.203
34.26,138.62,-0.203
34.28,138.44,-0.202
34.30,138.26,-0.202
34.32,138.07,-0.202
34.34,137.89,-0.201
34.36,137.71,-0.201
34.37,137.52,-0.201
34.39,137.34,-0.200
34.41,137.16,-0.200
34.43,136.97,-0.200
34.45,136.79,-0.200
[...]
170.08,-40.37,0.149
170.08,-40.31,0.149
170.09,-40.24,0.149
170.10,-40.17,0.149
170.10,-40.11,0.150
170.11,-40.04,0.149
170.12,-39.97,0.149
170.13,-39.91,0.149
170.13,-39.84,0.150
170.14,-39.77,0.150
170.15,-39.71,0.149
170.15,-39.64,0.149
170.16,-39.57,0.149
170.17,-39.51,0.149
170.17,-39.44,0.149
170.18,-39.37,0.149
170.18,-39.31,0.149
170.19,-39.24,0.149
170.20,-39.17,0.149
170.20,-39.11,0.149
170.21,-39.04,0.149
170.22,-38.97,0.149
170.23,-38.91,0.149
170.23,-38.84,0.149
170.24,-38.77,0.149
170.25,-38.71,0.149
170.25,-38.64,0.149
170.26,-38.57,0.149
170.27,-38.51,0.149
170.27,-38.44,0.149
170.28,-38.37,0.149
170.28,-38.30,0.149
170.29,-38.24,0.149
170.30,-38.17,0.149
170.30,-38.11,0.149
170.31,-38.04,0.149
170.32,-37.97,0.149
170.33,-37.91,0.149
170.33,-37.84,0.149
170.34,-37.77,0.149
170.35,-37.70,0.149
170.35,-37.64,0.149
170.36,-37.57,0.149
170.37,-37.50,0.149
170.37,-37.44,0.149
170.38,-37.37,0.149
170.38,-37.30,0.149
170.39,-37.24,0.149
170.40,-37.17,0.149
170.40,-37.10,0.149
170.41,-37.04,0.149
170.42,-36.97,0.149
170.43,-36.90,0.149
170.43,-36.84,0.149
170.44,-36.77,0.149
170.45,-36.70,0.149
170.45,-36.64,0.149
170.46,-36.57,0.149
170.47,-36.50,0.149
170.47,-36.44,0.149
170.48,-36.37,0.149
170.48,-36.30,0.149
170.49,-36.24,0.149
170.50,-36.17,0.149
170.50,-36.10,0.149
170.51,-36.04,0.149
170.52,-35.97,0.149
170.53,-35.90,0.149
170.53,-35.84,0.149
170.54,-35.77,0.149
170.55,-35.70,0.149
170.55,-35.63,0.149
170.56,-35.57,0.149
170.57,-35.50,0.149
170.57,-35.43,0.149
170.58,-35.37,0.149
170.58,-35.30,0.149
170.59,-35.23,0.149
170.60,-35.17,0.149
170.60,-35.10,0.149
170.61,-35.03,0.149
170.62,-34.97,0.149
170.63,-34.90,0.149
170.63,-34.83,0.149
170.64,-34.77,0.149
170.65,-34.70,0.149
170.65,-34.63,0.149
170.66,-34.57,0.149
170.67,-34.50,0.149
170.67,-34.43,0.149
170.68,-34.37,0.149
170.68,-34.30,0.149
170.69,-34.23,0.149
170.70,-34.17,0.149
170.70,-34.10,0.149
170.71,-34.03,0.149
170.72,-33.97,0.149
170.73,-33.90,0.149
170.73,-33.83,0.149
170.74,-33.77,0.149
170.75,-33.70,0.149
170.75,-33.63,0.149
170.76,-33.57,0.149
170.77,-33.50,0.149
170.77,-33.43,0.149
170.78,-33.36,0.149
170.78,-33.30,0.149
170.79,-33.23,0.149
170.80,-33.16,0.149
170.80,-33.10,0.149
170.81,-33.03,0.149
170.82,-32.96,0.149
170.83,-32.90,0.149
170.83,-32.83,0.149
170.84,-32.76,0.149
170.85,-32.70,0.149
170.85,-32.63,0.149
170.86,-32.56,0.149
170.87,-32.50,0.149
170.87,-32.43,0.149
170.88,-32.36,0.149
170.88,-32.30,0.149
170.89,-32.23,0.149
170.90,-32.16,0.149
170.90,-32.10,0.149
170.91,-32.03,0.149
170.92,-31.96,0.149
170.93,-31.90,0.149
170.93,-31.83,0.149
170.94,-31.76,0.149
170.95,-31.70,0.149
170.95,-31.63,0.149
170.96,-31.56,0.149
170.97,-31.50,0.149
170.97,-31.43,0.149
170.98,-31.36,0.149
170.98,-31.29,0.149
170.99,-31.23,0.149
171.00,-31.16,0.149
171.00,-31.09,0.149
171.01,-31.03,0.149
171.02,-30.96,0.149
171.03,-30.90,0.149
171.03,-30.83,0.148
171.04,-30.76,0.148
171.05,-30.70,0.149
171.05,-30.63,0.148
171.06,-30.56,0.149
171.07,-30.49,0.149
171.07,-30.43,0.149
171.08,-30.36,0.149
171.08,-30.29,0.148
171.09,-30.23,0.148
171.10,-30.16,0.148
171.10,-30.09,0.148
171.11,-30.03,0.148
171.12,-29.96,0.148
171.13,-29.89,0.148
171.13,-29.83,0.148
171.14,-29.76,0.148
171.15,-29.69,0.148
171.15,-29.63,0.148
171.16,-29.56,0.148
171.17,-29.49,0.148
171.17,-29.43,0.148
171.18,-29.36,0.148
171.18,-29.29,0.148
171.19,-29.23,0.148
171.20,-29.16,0.148
171.20,-29.09,0.148
171.21,-29.03,0.148
171.22,-28.96,0.148
171.23,-28.89,0.148
171.23,-28.83,0.148
171.24,-28.76,0.148
171.25,-28.69,0.148
171.25,-28.63,0.148
171.26,-28.56,0.148
171.27,-28.49,0.148
171.27,-28.42,0.148
171.28,-28.36,0.148
171.28,-28.29,0.148
171.29,-28.23,0.148
171.30,-28.16,0.148
171.30,-28.09,0.148
171.31,-28.02,0.148
171.32,-27.96,0.148
171.33,-27.89,0.148
171.33,-27.82,0.148
171.34,-27.76,0.148
171.35,-27.69,0.148
171.35,-27.62,0.148
171.36,-27.56,0.148
171.37,-27.49,0.148
171.37,-27.42,0.148
171.38,-27.36,0.148
171.38,-27.29,0.148
171.39,-27.23,0.148
171.40,-27.16,0.148
171.40,-27.09,0.148
171.41,-27.02,0.148
171.42,-26.96,0.148
171.43,-26.89,0.148
171.43,-26.82,0.148
171.44,-26.76,0.148
171.45,-26.69,0.148
171.45,-26.62,0.148
171.46,-26.56,0.148
171.47,-26.49,0.148
171.47,-26.42,0.148
171.48,-26.36,0.148
171.48,-26.29,0.148
171.49,-26.22,0.148
171.50,-26.15,0.148
171.50,-26.09,0.148
171.51,-26.02,0.148
171.52,-25.95,0.148
171.53,-25.89,0.148
171.53,-25.82,0.148
171.54,-25.75,0.148
171.55,-25.69,0.148
171.55,-25.62,0.148
171.56,-25.55,0.148
171.57,-25.49,0.148
171.57,-25.42,0.148
171.58,-25.35,0.148
171.58,-25.29,0.148
171.59,-25.22,0.148
171.60,-25.16,0.147
171.60,-25.09,0.147
171.61,-25.02,0.148
171.62,-24.95,0.148
171.63,-24.89,0.148
171.63,-24.82,0.148
171.64,-24.75,0.148
171.65,-24.69,0.148
171.65,-24.62,0.148
171.66,-24.55,0.148
171.67,-24.49,0.147
171.67,-24.42,0.147
171.68,-24.35,0.147
171.68,-24.29,0.147
171.69,-24.22,0.147
171.70,-24.15,0.147
171.70,-24.09,0.147
171.71,-24.02,0.147
171.72,-23.95,0.147
171.73,-23.89,0.147
171.73,-23.82,0.147
171.74,-23.75,0.147
171.75,-23.69,0.147
171.75,-23.62,0.147
171.76,-23.55,0.147
171.77,-23.48,0.147
171.77,-23.42,0.147
171.78,-23.35,0.147
171.78,-23.29,0.147
171.79,-23.22,0.147
171.80,-23.15,0.147
171.80,-23.08,0.147
171.81,-23.02,0.147
171.82,-22.95,0.147
171.83,-22.88,0.147
171.83,-22.82,0.147
171.84,-22.75,0.147
171.85,-22.68,0.147
171.85,-22.62,0.147
171.86,-22.55,0.147
171.87,-22.48,0.147
171.87,-22.42,0.147
171.88,-22.35,0.147
171.88,-22.28,0.147
171.89,-22.22,0.147
171.90,-22.15,0.147
171.90,-22.08,0.147
171.91,-22.02,0.147
171.92,-21.95,0.147
171.93,-21.88,0.147
171.93,-21.82,0.147
171.94,-21.75,0.147
171.95,-21.68,0.147
171.95,-21.62,0.147
171.96,-21.55,0.147
171.97,-21.48,0.147
171.97,-21.42,0.147
171.98,-21.35,0.147
171.98,-21.28,0.147
171.99,-21.22,0.147
172.00,-21.15,0.147
172.00,-21.08,0.147
172.01,-21.01,0.147
172.02,-20.95,0.147
172.03,-20.88,0.147
172.03,-20.81,0.147
172.04,-20.75,0.147
172.05,-20.68,0.147
172.05,-20.62,0.147
172.06,-20.55,0.147
172.07,-20.48,0.147
172.07,-20.42,0.147
172.08,-20.35,0.147
172.08,-20.28,0.147
172.09,-20.21,0.147
172.10,-20.15,0.147
172.10,-20.08,0.147
172.11,-20.01,0.147
172.12,-19.95,0.147
172.13,-19.88,0.147
172.13,-19.81,0.147
172.14,-19.75,0.147
172.15,-19.68,0.147
172.15,-19.61,0.147
172.16,-19.55,0.147
172.17,-19.48,0.147
172.17,-19.41,0.147
172.18,-19.35,0.147
172.18,-19.28,0.147
172.19,-19.21,0.147
172.20,-19.15,0.147
172.20,-19.08,0.147
172.21,-19.01,0.147
172.22,-18.95,0.147
172.23,-18.88,0.147
172.23,-18.81,0.147
172.24,-18.75,0.147
172.25,-18.68,0.147
172.25,-18.61,0.147
172.26,-18.54,0.147
172.27,-18.48,0.147
172.27,-18.41,0.147
172.28,-18.35,0.147
172.28,-18.28,0.147
172.29,-18.21,0.147
172.30,-18.15,0.147
172.30,-18.08,0.147
172.31,-18.01,0.147
172.32,-17.95,0.147
172.33,-17.88,0.147
172.33,-17.81,0.147
172.34,-17.74,0.147
172.35,-17.68,0.147
172.35,-17.61,0.147
172.36,-17.54,0.147
172.37,-17.48,0.147
172.37,-17.41,0.147
172.38,-17.34,0.147
172.38,-17.28,0.147
172.39,-17.21,0.147
172.40,-17.15,0.147
172.40,-17.08,0.147
172.41,-17.01,0.147
172.42,-16.94,0.147
172.43,-16.88,0.147
172.43,-16.81,0.147
172.44,-16.74,0.147
172.45,-16.68,0.147
172.45,-16.61,0.147
172.46,-16.54,0.147
172.47,-16.48,0.147
172.47,-16.41,0.147
172.48,-16.34,0.147
172.48,-16.28,0.147
172.49,-16.21,0.147
172.50,-16.14,0.147
172.50,-16.08,0.147
172.51,-16.01,0.147
172.52,-15.94,0.147
172.53,-15.88,0.147
172.53,-15.81,0.147
172.54,-15.74,0.147
172.55,-15.68,0.147
172.55,-15.61,0.147
172.56,-15.54,0.147
172.57,-15.48,0.147
172.57,-15.41,0.147
172.58,-15.34,0.147
172.58,-15.28,0.147
172.59,-15.21,0.147
172.60,-15.14,0.147
172.60,-15.08,0.147
172.61,-15.01,0.147
172.62,-14.94,0.147
172.63,-14.88,0.147
172.63,-14.81,0.147
172.64,-14.74,0.147
172.65,-14.67,0.147
172.65,-14.61,0.147
172.66,-14.54,0.147
172.67,-14.47,0.147
172.67,-14.41,0.147
172.68,-14.34,0.147
172.68,-14.27,0.147
172.69,-14.21,0.147
172.70,-14.14,0.147
172.70,-14.07,0.147
172.71,-14.01,0.147
172.72,-13.94,0.147
172.73,-13.87,0.147
172.73,-13.81,0.147
172.74,-13.74,0.147
172.75,-13.67,0.147
172.75,-13.61,0.147
172.76,-13.54,0.147
172.77,-13.47,0.147
172.77,-13.41,0.147
172.78,-13.34,0.147
172.78,-13.27,0.147
172.79,-13.21,0.147
172.80,-13.14,0.147
172.80,-13.07,0.147
172.81,-13.01,0.147
172.82,-12.94,0.147
172.83,-12.87,0.147
172.83,-12.81,0.147
172.84,-12.74,0.147
172.85,-12.67,0.147
172.85,-12.61,0.147
172.86,-12.54,0.147
172.87,-12.47,0.147
172.87,-12.41,0.147
172.88,-12.34,0.147
172.88,-12.27,0.147
172.89,-12.20,0.147
172.90,-12.14,0.147
172.90,-12.07,0.147
172.91,-12.00,0.147
172.92,-11.94,0.147
172.93,-11.87,0.148
172.93,-11.80,0.148
172.94,-11.74,0.148
172.95,-11.67,0.148
172.95,-11.60,0.148
172.96,-11.54,0.148
172.97,-11.47,0.148
172.97,-11.40,0.148
172.98,-11.34,0.148
172.98,-11.27,0.148
172.99,-11.20,0.148
173.00,-11.14,0.148
173.00,-11.07,0.148
173.01,-11.00,0.148
173.02,-10.94,0.148
173.03,-10.87,0.148
173.03,-10.80,0.148
173.04,-10.74,0.148
173.05,-10.67,0.148
173.05,-10.60,0.148
173.06,-10.54,0.148
173.07,-10.47,0.148
173.07,-10.40,0.148
173.08,-10.34,0.148
173.08,-10.27,0.148
173.09,-10.20,0.148
173.10,-10.14,0.148
173.10,-10.07,0.148
173.11,-10.00,0.148
173.12,-9.94,0.148
173.13,-9.87,0.148
173.13,-9.80,0.148
173.14,-9.74,0.148
173.15,-9.67,0.148
173.15,-9.60,0.148
173.16,-9.54,0.148
173.17,-9.47,0.148
173.17,-9.40,0.148
173.18,-9.33,0.148
173.18,-9.27,0.148
173.19,-9.20,0.148
173.20,-9.13,0.148
173.20,-9.07,0.148
173.21,-9.00,0.148
173.22,-8.93,0.148
173.23,-8.87,0.148
173.23,-8.80,0.148
173.24,-8.73,0.148
173.25,-8.67,0.148
173.25,-8.60,0.148
173.26,-8.54,0.148
173.27,-8.47,0.148
173.27,-8.40,0.148
173.28,-8.34,0.148
173.28,-8.27,0.148
173.29,-8.20,0.148
173.30,-8.14,0.148
173.30,-8.07,0.148
173.31,-8.00,0.148
173.32,-7.93,0.148
173.33,-7.87,0.148
173.33,-7.80,0.148
173.34,-7.73,0.148
173.35,-7.67,0.148
173.35,-7.60,0.148
173.36,-7.53,0.148
173.37,-7.47,0.148
173.37,-7.40,0.148
173.38,-7.33,0.148
173.38,-7.27,0.148
173.39,-7.20,0.148
173.40,-7.13,0.148
173.40,-7.07,0.148
173.41,-7.00,0.148
173.42,-6.93,0.148
173.43,-6.87,0.148
173.43,-6.80,0.148
173.44,-6.73,0.148
173.45,-6.67,0.148
173.45,-6.60,0.148
173.46,-6.53,0.148
173.47,-6.47,0.148
173.47,-6.40,0.148
173.48,-6.33,0.148
173.48,-6.26,0.148
173.49,-6.20,0.148
173.50,-6.13,0.148
173.50,-6.07,0.148
173.51,-6.00,0.148
173.52,-5.93,0.148
173.53,-5.87,0.148
173.53,-5.80,0.148
173.54,-5.73,0.148
173.55,-5.66,0.148
173.55,-5.60,0.148
173.56,-5.53,0.148
173.57,-5.46,0.148
173.57,-5.40,0.148
173.58,-5.33,0.148
173.58,-5.27,0.148
173.59,-5.20,0.148
173.60,-5.13,0.148
173.60,-5.06,0.148
173.61,-5.00,0.148
173.62,-4.93,0.148
173.63,-4.86,0.148
173.63,-4.80,0.148
173.64,-4.73,0.148
173.65,-4.66,0.148
173.65,-4.60,0.148
173.66,-4.53,0.148
173.67,-4.46,0.148
173.67,-4.40,0.148
173.68,-4.33,0.148
173.68,-4.26,0.149
173.69,-4.20,0.148
173.70,-4.13,0.148
173.70,-4.06,0.149
173.71,-4.00,0.148
173.72,-3.93,0.148
173.73,-3.86,0.148
173.73,-3.80,0.148
173.74,-3.73,0.149
173.75,-3.66,0.149
173.75,-3.60,0.149
173.76,-3.53,0.149
173.77,-3.46,0.149
173.77,-3.40,0.149
173.78,-3.33,0.149
173.78,-3.26,0.149
173.79,-3.20,0.149
173.80,-3.13,0.149
173.80,-3.06,0.149
173.81,-3.00,0.149
173.82,-2.93,0.149
173.83,-2.86,0.149
173.83,-2.79,0.149
173.84,-2.73,0.149
173.85,-2.66,0.149
173.85,-2.60,0.149
173.86,-2.53,0.149
173.87,-2.46,0.149
173.87,-2.39,0.149
173.88,-2.33,0.149
173.88,-2.26,0.149
173.89,-2.19,0.149
173.90,-2.13,0.149
173.90,-2.06,0.149
173.91,-1.99,0.149
173.92,-1.93,0.149
173.93,-1.86,0.149
173.93,-1.79,0.149
173.94,-1.73,0.149
173.95,-1.66,0.149
173.95,-1.59,0.149
173.96,-1.53,0.149
173.97,-1.46,0.149
173.97,-1.39,0.149
173.98,-1.33,0.149
173.98,-1.26,0.149
173.99,-1.19,0.149
174.00,-1.13,0.149
174.00,-1.06,0.149
174.01,-0.99,0.149
174.02,-0.93,0.149
174.03,-0.86,0.149
174.03,-0.79,0.149
174.04,-0.73,0.149
174.05,-0.66,0.149
174.05,-0.59,0.149
174.06,-0.53,0.149
174.07,-0.46,0.149
174.07,-0.39,0.149
174.08,-0.32,0.150
174.08,-0.26,0.150
174.09,-0.19,0.150
174.10,-0.13,0.150
174.10,-0.06,0.150
174.11,0.01,0.150
174.12,0.07,0.150
174.13,0.14,0.150
174.13,0.21,0.150
174.14,0.28,0.150
174.15,0.34,0.150
174.15,0.41,0.150
174.16,0.47,0.150
174.17,0.54,0.150
174.17,0.61,0.150
174.18,0.68,0.150
174.18,0.74,0.150
174.19,0.81,0.150
174.20,0.88,0.150
174.20,0.94,0.150
174.21,1.01,0.150
174.22,1.08,0.150
174.23,1.14,0.150
174.23,1.21,0.150
174.24,1.28,0.150
174.25,1.34,0.150
174.25,1.41,0.150
174.26,1.48,0.150
174.27,1.54,0.150
174.27,1.61,0.150
174.28,1.68,0.150
174.28,1.74,0.150
174.29,1.81,0.150
174.30,1.88,0.150
174.30,1.94,0.150
174.31,2.01,0.151
174.32,2.08,0.151
174.33,2.14,0.151
174.33,2.21,0.151
174.34,2.28,0.151
174.35,2.34,0.151
174.35,2.41,0.151
174.36,2.48,0.151
174.37,2.54,0.151
174.37,2.61,0.151
174.38,2.68,0.151
174.38,2.74,0.151
174.39,2.81,0.151
174.40,2.88,0.151
174.40,2.95,0.151
174.41,3.01,0.151
174.42,3.08,0.151
174.43,3.15,0.151
174.43,3.21,0.151
174.44,3.28,0.151
174.45,3.35,0.151
174.45,3.41,0.151
174.46,3.48,0.151
174.47,3.55,0.151
174.47,3.61,0.151
174.48,3.68,0.151
174.48,3.75,0.151
174.49,3.81,0.151
174.50,3.88,0.151
174.50,3.95,0.151
174.51,4.01,0.151
174.52,4.08,0.151
174.53,4.15,0.151
174.53,4.21,0.151
174.54,4.28,0.151
174.55,4.35,0.151
174.55,4.41,0.151
174.56,4.48,0.151
174.57,4.55,0.151
174.57,4.61,0.151
174.58,4.68,0.151
174.58,4.75,0.151
174.59,4.81,0.151
174.60,4.88,0.151
174.60,4.95,0.151
174.61,5.01,0.151
174.62,5.08,0.151
174.63,5.15,0.152
174.63,5.21,0.152
174.64,5.28,0.152
174.65,5.35,0.152
174.65,5.41,0.152
174.66,5.48,0.152
174.67,5.55,0.152
174.67,5.61,0.152
174.68,5.68,0.152
174.68,5.75,0.152
174.69,5.81,0.152
174.70,5.88,0.152
174.70,5.95,0.152
174.71,6.01,0.152
174.72,6.08,0.152
174.73,6.15,0.152
174.73,6.22,0.152
174.74,6.28,0.152
174.75,6.35,0.152
174.75,6.41,0.152
174.76,6.48,0.152
174.77,6.55,0.152
174.77,6.62,0.152
174.78,6.68,0.152
174.78,6.75,0.152
174.79,6.82,0.152
174.80,6.88,0.152
174.80,6.95,0.152
174.81,7.02,0.152
174.82,7.08,0.152
174.83,7.15,0.152
174.83,7.22,0.153
174.84,7.28,0.153
174.85,7.35,0.153
174.85,7.42,0.153
174.86,7.48,0.153
174.87,7.55,0.153
174.87,7.62,0.153
174.88,7.68,0.153
174.88,7.75,0.153
174.89,7.82,0.153
174.90,7.88,0.153
174.90,7.95,0.153
174.91,8.02,0.153
174.92,8.08,0.153
174.93,8.15,0.153
174.93,8.22,0.153
174.94,8.28,0.153
174.95,8.35,0.153
174.95,8.42,0.153
174.96,8.48,0.153
174.97,8.55,0.153
174.97,8.62,0.153
174.98,8.68,0.153
174.98,8.75,0.153
174.99,8.82,0.153
175.00,8.88,0.153
175.00,8.95,0.154
175.01,9.02,0.154
175.02,9.08,0.154
175.03,9.15,0.154
175.03,9.22,0.154
175.04,9.29,0.154
175.05,9.35,0.154
175.05,9.42,0.154
175.06,9.49,0.154
175.07,9.55,0.154
175.07,9.62,0.154
175.08,9.69,0.154
175.08,9.75,0.154
175.09,9.82,0.154
175.10,9.89,0.154
175.10,9.95,0.154
175.11,10.02,0.154
175.12,10.09,0.154
175.13,10.15,0.154
175.13,10.22,0.154
175.14,10.29,0.155
175.15,10.35,0.155
175.15,10.42,0.155
175.16,10.49,0.155
175.17,10.55,0.155
175.17,10.62,0.155
175.18,10.69,0.155
175.18,10.75,0.155
175.19,10.82,0.155
175.20,10.89,0.155
175.20,10.95,0.155
175.21,11.02,0.155
175.22,11.09,0.155
175.23,11.15,0.155
175.23,11.22,0.155
175.24,11.29,0.155
175.25,11.35,0.155
175.25,11.42,0.155
175.26,11.49,0.155
175.27,11.55,0.155
175.27,11.62,0.155
175.28,11.69,0.155
175.28,11.75,0.155
175.29,11.82,0.155
175.30,11.89,0.155
175.30,11.95,0.155
175.31,12.02,0.155
175.32,12.09,0.155
175.33,12.15,0.155
175.33,12.22,0.155
175.34,12.29,0.155
175.35,12.35,0.155
175.35,12.42,0.155
175.36,12.49,0.156
175.37,12.55,0.155
175.37,12.62,0.156
175.38,12.69,0.156
175.38,12.75,0.156
175.39,12.82,0.156
175.40,12.89,0.156
175.40,12.95,0.156
175.41,13.02,0.156
175.42,13.09,0.156
175.43,13.15,0.156
175.43,13.22,0.156
175.44,13.29,0.156
175.45,13.35,0.156
175.45,13.42,0.156
175.46,13.49,0.156
175.47,13.55,0.156
175.47,13.62,0.156
175.48,13.69,0.156
175.48,13.75,0.156
175.49,13.82,0.156
175.50,13.89,0.156
175.50,13.95,0.156
175.51,14.02,0.156
175.52,14.09,0.156
175.53,14.15,0.156
175.53,14.22,0.156
175.54,14.29,0.157
175.55,14.35,0.157
175.55,14.42,0.157
175.56,14.49,0.157
175.57,14.56,0.157
175.57,14.62,0.157
175.58,14.69,0.157
175.58,14.76,0.157
175.59,14.82,0.157
175.60,14.89,0.157
175.60,14.96,0.157
175.61,15.02,0.157
175.62,15.09,0.157
175.63,15.16,0.157
175.63,15.22,0.157
175.64,15.29,0.157
175.65,15.36,0.157
175.65,15.42,0.157
175.66,15.49,0.157
175.67,15.56,0.157
175.67,15.62,0.157
175.68,15.69,0.157
175.68,15.76,0.157
175.69,15.82,0.157
175.70,15.89,0.157
175.70,15.96,0.158
175.71,16.03,0.158
175.72,16.09,0.158
175.73,16.16,0.158
175.73,16.23,0.158
175.74,16.29,0.158
175.75,16.36,0.158
175.75,16.43,0.158
175.76,16.49,0.158
175.77,16.56,0.158
175.77,16.63,0.158
175.78,16.69,0.158
175.78,16.76,0.158
175.79,16.83,0.158
175.80,16.89,0.158
175.80,16.96,0.158
175.81,17.03,0.158
175.82,17.09,0.158
175.83,17.16,0.158
175.83,17.23,0.158
175.84,17.29,0.158
175.85,17.36,0.158
175.85,17.43,0.159
175.86,17.50,0.159
175.87,17.56,0.159
175.87,17.63,0.159
175.88,17.69,0.159
175.88,17.76,0.159
175.89,17.83,0.159
175.90,17.89,0.159
175.90,17.96,0.159
175.91,18.03,0.159
175.92,18.09,0.159
175.93,18.16,0.159
175.93,18.23,0.159
175.94,18.29,0.159
175.95,18.36,0.159
175.95,18.43,0.159
175.96,18.49,0.159
175.97,18.56,0.159
175.97,18.63,0.159
175.98,18.69,0.159
175.98,18.76,0.159
175.99,18.83,0.159
176.00,18.89,0.159
176.00,18.96,0.159
176.01,19.03,0.159
176.02,19.10,0.159
176.03,19.16,0.159
176.03,19.23,0.159
176.04,19.30,0.159
176.05,19.36,0.159
176.05,19.43,0.159
176.06,19.50,0.160
176.07,19.56,0.160
176.07,19.63,0.160
176.08,19.70,0.160
176.08,19.76,0.159
176.09,19.83,0.159
176.10,19.90,0.160
176.10,19.96,0.160
176.11,20.03,0.160
176.12,20.09,0.160
176.13,20.16,0.160
176.13,20.23,0.160
176.14,20.30,0.160
176.15,20.36,0.160
176.15,20.43,0.160
176.16,20.50,0.160
176.17,20.56,0.160
176.17,20.63,0.160
176.18,20.70,0.160
176.18,20.76,0.160
176.19,20.83,0.160
176.20,20.90,0.160
176.20,20.96,0.160
176.21,21.03,0.160
176.22,21.10,0.160
176.23,21.16,0.160
176.23,21.23,0.160
176.24,21.30,0.160
176.25,21.36,0.160
176.25,21.43,0.160
176.26,21.50,0.160
176.27,21.56,0.160
176.27,21.63,0.160
176.28,21.70,0.161
176.28,21.77,0.161
176.29,21.83,0.161
176.30,21.90,0.161
176.30,21.97,0.161
176.31,22.03,0.161
176.32,22.10,0.161
176.33,22.17,0.161
176.33,22.23,0.161
176.34,22.30,0.161
176.35,22.37,0.161
176.35,22.43,0.161
176.36,22.50,0.161
176.37,22.57,0.161
176.37,22.63,0.161
176.38,22.70,0.161
176.38,22.77,0.161
176.39,22.83,0.161
176.40,22.90,0.161
176.40,22.97,0.161
176.41,23.03,0.161
176.42,23.10,0.161
176.43,23.17,0.161
176.43,23.23,0.161
176.44,23.30,0.161
176.45,23.37,0.161
176.45,23.43,0.161
176.46,23.50,0.161
176.47,23.57,0.161
176.47,23.63,0.162
176.48,23.70,0.162
176.48,23.77,0.162
176.49,23.83,0.162
176.50,23.90,0.162
176.50,23.97,0.162
176.51,24.03,0.162
176.52,24.10,0.162
176.53,24.17,0.162
176.53,24.23,0.162
176.54,24.30,0.162
176.55,24.37,0.162
176.55,24.43,0.162
176.56,24.50,0.162
176.57,24.57,0.162
176.57,24.63,0.162
176.58,24.70,0.162
176.58,24.77,0.162
176.59,24.83,0.162
176.60,24.90,0.162
176.60,24.97,0.162
176.61,25.03,0.162
176.62,25.10,0.162
176.63,25.17,0.162
176.63,25.24,0.162
176.64,25.30,0.162
176.65,25.37,0.162
176.65,25.44,0.162
176.66,25.50,0.162
176.67,25.57,0.162
176.67,25.63,0.163
176.68,25.70,0.163
176.68,25.77,0.163
176.69,25.84,0.163
176.70,25.90,0.163
176.70,25.97,0.163
176.71,26.03,0.163
176.72,26.10,0.163
176.73,26.17,0.163
176.73,26.24,0.163
176.74,26.30,0.163
176.75,26.37,0.163
176.75,26.44,0.163
176.76,26.50,0.163
176.77,26.57,0.163
176.77,26.64,0.163
176.78,26.70,0.163
176.78,26.77,0.163
176.79,26.84,0.163
176.80,26.90,0.163
176.80,26.97,0.163
176.81,27.04,0.164
176.82,27.10,0.164
176.83,27.17,0.164
176.83,27.24,0.164
176.84,27.30,0.164
176.85,27.37,0.164
176.85,27.44,0.164
176.86,27.50,0.164
176.87,27.57,0.164
176.87,27.64,0.164
176.88,27.70,0.164
176.88,27.77,0.164
176.89,27.84,0.164
176.90,27.90,0.164
176.90,27.97,0.164
176.91,28.04,0.164
176.92,28.10,0.164
176.93,28.17,0.164
176.93,28.24,0.164
176.94,28.30,0.164
176.95,28.37,
176.95,28.44,
176.96,28.50,
176.97,28.57,
176.97,28.64,
176.98,28.70,
176.98,28.77,
176.99,,
177.00,,