File: DSC/2025_06_28_Benzoic_Acid_n60C_150C_10Cmin_x4.csv
Filename,2025_06_28_Benzoic_Acid_n60C_150C_10Cmin_x4
Instrument name,DSC2A-00468 (192.168.1.100)
Operator,Yarger
rundate,6/29/2025
Sample name,2025_06_28_Benzoic_Acid_n60C_150C_10Cmin_x4
proceduresegments,Data Off ; Equilibrate -60.00 °C; Data On ; Ramp 10.00 °C/min to 150.00 °C; Data Off ; Isothermal 2.0 min; Data On ; Ramp 10.00 °C/min to -60.00 °C; Data Off ; Isothermal 2.0 min; Data On ; Ramp 10.00 °C/min to 150.00 °C; Data Off ; Isothermal 2.0 min; Data On ; Ramp 10.00 °C/min to -60.00 °C; Data Off ; Isothermal 2.0 min; Data On ; Ramp 10.00 °C/min to 150.00 °C; Data Off ; Isothermal 2.0 min; Data On ; Ramp 10.00 °C/min to -60.00 °C; Data Off ; Isothermal 2.0 min; Data On ; Ramp 10.00 °C/min to 30.00 °C
[File Parameters]
Run date,6/29/2025 2:36:02 PM
Trios version,5.1.1.46572
Original File Name,
Current File Name,D:\DSC2500\Gibbons\2025_06_28_Benzoic_Acid_n60C_150C_10Cmin_x4.tri
[Procedure]
Procedure Name,Benzoic_Acid_n60C_150C_10Cmin_x4
Sample Name,2025_06_28_Benzoic_Acid_n60C_150C_10Cmin_x4
Sample Mass,14.16 mg
Reference Sample Mass,0 mg
Pan Mass,56.79 mg
Pan Number,4
Reference Pan Mass,56.76 mg
Reference Pan Number,10
Pan Type,Tzero Aluminum Hermetic
Comments,Al Hermetic DSC Consumables sealed Pan/Lid. Y1 Tray (Google Sheet: DSC_Samples_Y1_Tray_June2025). Run AFTER failed/leaked DSC pan #25 was removed and DSC was cleaned and baseline and stds checked.
Project Name,CA
Operator,Yarger
Test,Custom
Unload Max Temperature,30
Unload Min Temperature,30
Load Max Temperature,30
Load Min Temperature,30
Stop on Gas Flow Error,Yes
[Signal List]
Signal #1,Time (min)
Signal #2,Temperature (°C)
Signal #3,Heat Flow (mW)
Signal #4,Delta T (µV)
Signal #5,Delta Tzero (µV)
Signal #6,Tzero Temperature (°C)
Signal #7,Cell Purge (mL/min)
Signal #8,Heater Temp (°C)
Signal #9,Power Delivered (W)
Signal #10,Reference Junction Temperature (°C)
Signal #11,Flange Temperature (°C)
Signal #12,Heat Flow Phase (rad)
Signal #13,Total Heat Capacity (J/°C)
Signal #14,Heat Capacity (J/°C)
[Configuration]
Company Name,ASU
Instrument Name,DSC2A-00468
Instrument Type,DSC2500
Serial Number,DSC2A-00468
IP,192.168.1.100
Location of Instrument,MRRC
DisplayType,Unknown
Sample Interval ,0.1 s/pt
Selected Heat Flow,T4P
Exotherm Direction,Down
Cell Serial,DRC2-00792
Lid Type,Standard
Cooler,RCS 90
Leave Cooler on at End of Sequence,On
Gas 2,Nitrogen
Gas Selected,Channel 1
Flow Rate,50 mL/min
Secondary Purge,On
Licensed Heat Flow,Heat Flow T4P
Modulation Licensed,Yes
[Versions]
Common IDD Version,1
Cortex Version,VER 2.10.2.31
Driver,5.0.0.6
GDM Version,1.0.3.3
TouchscreenVersion,1.0.0.16145
FEP Version,1.2.1.21
FEP Bootloader,2.0.0.5
AutoSampler Version,2.1.1.26
Auto Sampler Bootloader,2.0.0.5
FCM Version,1.1.0.3
FCM Bootloader,2.0.0.5
[Experiment Logs]
Experiment Log Entry # 1,Data On set to 0
Experiment Log Entry # 3,Equilibrate Segment -60 (C) Started
Experiment Log Entry # 5,Air Cool is off.
Experiment Log Entry # 7,Data On set to 1
Experiment Log Entry # 9,Ramp Segment 10 C/min to 150 Started
Experiment Log Entry # 11,Data On set to 0
Experiment Log Entry # 13,Isothermal Segment 2 min started
Experiment Log Entry # 15,Data On set to 1
Experiment Log Entry # 17,Ramp Segment 10 C/min to -60 Started
Experiment Log Entry # 19,Data On set to 0
Experiment Log Entry # 21,Isothermal Segment 2 min started
Experiment Log Entry # 23,Data On set to 1
Experiment Log Entry # 25,Ramp Segment 10 C/min to 150 Started
Experiment Log Entry # 27,Data On set to 0
Experiment Log Entry # 29,Isothermal Segment 2 min started
Experiment Log Entry # 31,Data On set to 1
Experiment Log Entry # 33,Ramp Segment 10 C/min to -60 Started
Experiment Log Entry # 35,Data On set to 0
Experiment Log Entry # 37,Isothermal Segment 2 min started
Experiment Log Entry # 39,Data On set to 1
Experiment Log Entry # 41,Ramp Segment 10 C/min to 150 Started
Experiment Log Entry # 43,Data On set to 0
Experiment Log Entry # 45,Isothermal Segment 2 min started
Experiment Log Entry # 47,Data On set to 1
Experiment Log Entry # 49,Ramp Segment 10 C/min to -60 Started
Experiment Log Entry # 51,Data On set to 0
Experiment Log Entry # 53,Isothermal Segment 2 min started
Experiment Log Entry # 55,Data On set to 1
Experiment Log Entry # 57,Ramp Segment 10 C/min to 30 Started
[Method Log]
Method Log Entry # 1,Data Off
Method Log Entry # 2,Equilibrate -60 °C
Method Log Entry # 3,Data On
Method Log Entry # 4,(Ramp 672502) Ramp 10 °C/minute to 150 °C
Method Log Entry # 5,Data Off
Method Log Entry # 6,Isothermal 2 minutes
Method Log Entry # 7,Data On
Method Log Entry # 8,(Ramp 672506) Ramp 10 °C/minute to -60 °C
Method Log Entry # 9,Data Off
Method Log Entry # 10,Isothermal 2 minutes
Method Log Entry # 11,Data On
Method Log Entry # 12,(Ramp 672510) Ramp 10 °C/minute to 150 °C
Method Log Entry # 13,Data Off
Method Log Entry # 14,Isothermal 2 minutes
Method Log Entry # 15,Data On
Method Log Entry # 16,(Ramp 672514) Ramp 10 °C/minute to -60 °C
Method Log Entry # 17,Data Off
Method Log Entry # 18,Isothermal 2 minutes
Method Log Entry # 19,Data On
Method Log Entry # 20,(Ramp 672518) Ramp 10 °C/minute to 150 °C
Method Log Entry # 21,Data Off
Method Log Entry # 22,Isothermal 2 minutes
Method Log Entry # 23,Data On
Method Log Entry # 24,(Ramp 672522) Ramp 10 °C/minute to -60 °C
Method Log Entry # 25,Data Off
Method Log Entry # 26,Isothermal 2 minutes
Method Log Entry # 27,Data On
Method Log Entry # 28,(Ramp 672526) Ramp 10 °C/minute to 30 °C
Cell Serial,DRC2-00792
[T1 Calibration]
Slope,-0.008529666
Offset,9.636258
Initial Temperature,98.23
GUID,f8bfdadc-4977-4fdf-ba6d-0ba9134940c3
[TZero Calibration]
Date Applied,11/29/2022 4:06:13 PM
Description,From -89.059 °C to 396.009 °C at 20.000°C/min
Gas Type,Nitrogen
Pan Type,None
Source Files 1,C:\Users\yargerlab\Desktop\DSC Data\General\TZero_calibration_11_29_22_2nd(2).tri
Source Files 2,C:\Users\yargerlab\Desktop\DSC Data\General\TZero_calibration_11_29_22_2nd(3).tri
Delta T Offset,13.05235
Delta T Slope,-0.007271007
Delta T0 Offset,-13.69128
Delta T0 Slope,0.06063341
[Temperature Calibration]
Date Applied,11/29/2022 7:12:28 PM
Description,From 106.590 °C to 186.590 °C at 10.000°C/min
Gas Type,Nitrogen
Pan Type,Tzero Aluminum Hermetic
Source Files 1,C:\Users\yargerlab\Desktop\DSC Data\General\Indium(6).tri
Measured 1,157.391
Known 1,156.598
[Cell Constant Calibration]
Date Applied,11/29/2022 7:12:29 PM
Description,From 106.590 °C to 186.590 °C at 10.000°C/min
Gas Type,Nitrogen
Pan Type,Tzero Aluminum Hermetic
Source Files 1,C:\Users\yargerlab\Desktop\DSC Data\General\Indium(6).tri
T4P KCell,1.006051
Onset Slope,63.26126 mW/°C
[Direct Cp Calibration]
Date Applied,11/30/2022 11:04:51 AM
Description,From -79.983 °C to 298.409 °C at 10.000°C/min
Gas Type,Nitrogen
Pan Type,Tzero Aluminum Hermetic
Source Files 1,C:\Users\yargerlab\Desktop\DSC Data\General\Sapphire_Heat_Capacity_11_30_22.tri
[Rev Cp Calibration]
Date Applied,11/30/2022 1:58:51 PM
Description,From -79.996 °C to 292.812 °C at 3.000°C/min
Gas Type,Nitrogen
Pan Type,Tzero Aluminum Hermetic
Source Files 1,C:\Users\yargerlab\Desktop\DSC Data\General\Sapphire_MDSC_Calibration_11_30_22.tri
[step]
Ramp 10.00 °C/min to 150.00 °C
Time,Temperature,Heat Flow (Normalized)
min,°C,W/g
0.00,-59.67,-0.040
0.01,-59.69,-0.039
0.03,-59.69,-0.036
0.05,-59.70,-0.033
0.06,-59.70,-0.031
0.08,-59.68,-0.029
0.09,-59.65,-0.026
0.11,-59.61,-0.022
0.12,-59.56,-0.017
0.14,-59.49,-0.011
0.15,-59.42,-0.003
0.16,-59.33,0.006
0.18,-59.24,0.015
0.19,-59.14,0.026
0.21,-59.03,0.035
0.23,-58.92,0.046
0.24,-58.81,0.055
0.26,-58.69,0.063
0.27,-58.57,0.071
0.29,-58.44,0.078
0.30,-58.32,0.085
0.31,-58.19,0.092
0.33,-58.06,0.096
0.35,-57.93,0.102
0.36,-57.80,0.106
0.38,-57.66,0.111
0.39,-57.53,0.114
0.40,-57.39,0.118
0.42,-57.26,0.120
0.44,-57.12,0.123
0.45,-56.98,0.126
0.46,-56.84,0.128
0.48,-56.70,0.130
0.50,-56.56,0.132
0.51,-56.41,0.134
0.53,-56.27,0.136
0.54,-56.13,0.136
0.55,-55.99,0.139
0.57,-55.84,0.139
0.58,-55.70,0.141
0.60,-55.55,0.141
0.62,-55.41,0.142
0.63,-55.26,0.143
0.65,-55.12,0.144
0.66,-54.97,0.145
0.68,-54.82,0.145
0.69,-54.68,0.146
0.70,-54.53,0.146
0.72,-54.39,0.147
0.73,-54.24,0.147
0.75,-54.09,0.147
0.77,-53.94,0.148
0.78,-53.80,0.148
0.80,-53.65,0.149
0.81,-53.50,0.149
0.83,-53.35,0.149
0.84,-53.21,0.150
0.85,-53.06,0.150
0.87,-52.91,0.150
0.88,-52.76,0.150
0.90,-52.62,0.150
0.92,-52.47,0.150
0.93,-52.32,0.150
0.95,-52.17,0.151
0.96,-52.02,0.151
0.98,-51.87,0.151
0.99,-51.72,0.151
1.00,-51.58,0.151
1.02,-51.43,0.151
1.03,-51.28,0.151
1.05,-51.13,0.151
1.07,-50.98,0.152
1.08,-50.83,0.152
1.09,-50.68,0.152
1.11,-50.53,0.152
1.13,-50.38,0.152
1.14,-50.23,0.152
1.16,-50.08,0.152
1.17,-49.94,0.153
1.18,-49.79,0.153
1.20,-49.64,0.153
1.22,-49.49,0.153
1.23,-49.34,0.153
1.24,-49.19,0.153
1.26,-49.04,0.153
1.28,-48.89,0.153
1.29,-48.74,0.154
1.31,-48.59,0.154
1.32,-48.44,0.154
1.33,-48.29,0.154
1.35,-48.14,0.154
1.37,-47.99,0.154
1.38,-47.84,0.154
1.39,-47.69,0.154
1.41,-47.54,0.154
1.43,-47.39,0.154
1.44,-47.24,0.155
1.46,-47.09,0.155
1.47,-46.94,0.155
1.48,-46.79,0.155
1.50,-46.64,0.155
1.52,-46.49,0.155
1.53,-46.34,0.155
1.54,-46.19,0.155
1.56,-46.04,0.155
1.58,-45.89,0.155
1.59,-45.74,0.156
1.61,-45.60,0.156
1.62,-45.44,0.156
1.63,-45.29,0.156
1.65,-45.14,0.156
1.67,-44.99,0.156
1.68,-44.84,0.156
1.69,-44.69,0.156
1.71,-44.55,0.156
1.73,-44.40,0.156
1.74,-44.24,0.156
1.76,-44.09,0.156
1.77,-43.94,0.156
1.78,-43.80,0.157
1.80,-43.64,0.157
1.82,-43.49,0.157
1.83,-43.34,0.157
1.84,-43.20,0.157
1.86,-43.04,0.157
1.88,-42.89,0.157
1.89,-42.75,0.157
1.91,-42.59,0.157
1.92,-42.44,0.157
1.93,-42.29,0.157
1.95,-42.14,0.157
1.97,-41.99,0.157
1.98,-41.84,0.158
1.99,-41.69,0.158
2.01,-41.54,0.158
2.03,-41.39,0.158
2.04,-41.24,0.158
2.06,-41.09,0.158
2.07,-40.94,0.158
2.08,-40.79,0.158
2.10,-40.64,0.158
2.12,-40.49,0.158
2.13,-40.34,0.158
2.14,-40.19,0.158
2.16,-40.04,0.158
2.18,-39.89,0.158
2.19,-39.74,0.159
2.21,-39.59,0.159
2.22,-39.44,0.159
2.24,-39.29,0.159
2.25,-39.14,0.159
2.26,-38.99,0.159
2.28,-38.84,0.159
2.29,-38.69,0.159
2.31,-38.54,0.159
2.33,-38.39,0.159
2.34,-38.24,0.159
2.36,-38.09,0.159
2.37,-37.94,0.159
2.39,-37.79,0.159
2.40,-37.64,0.159
2.41,-37.49,0.159
2.43,-37.34,0.160
2.44,-37.19,0.160
2.46,-37.04,0.160
2.48,-36.89,0.160
2.49,-36.74,0.160
2.51,-36.59,0.160
2.52,-36.44,0.160
2.54,-36.29,0.160
2.55,-36.14,0.160
2.56,-35.99,0.160
2.58,-35.84,0.160
2.59,-35.68,0.160
2.61,-35.54,0.160
2.63,-35.38,0.160
2.64,-35.23,0.160
2.66,-35.09,0.160
2.67,-34.93,0.161
2.69,-34.79,0.161
2.70,-34.64,0.161
2.71,-34.48,0.161
2.73,-34.33,0.161
2.74,-34.18,0.161
2.76,-34.03,0.161
2.78,-33.88,0.161
2.79,-33.73,0.161
2.81,-33.58,0.161
2.82,-33.43,0.161
2.84,-33.28,0.161
2.85,-33.13,0.161
2.86,-32.98,0.161
2.88,-32.83,0.161
2.89,-32.68,0.162
2.91,-32.53,0.162
2.93,-32.38,0.162
2.94,-32.23,0.162
2.96,-32.08,0.162
2.97,-31.93,0.162
2.99,-31.78,0.162
3.00,-31.63,0.162
3.01,-31.48,0.162
3.03,-31.33,0.162
3.04,-31.18,0.162
3.06,-31.03,0.162
3.08,-30.88,0.162
3.09,-30.73,0.162
3.11,-30.58,0.162
3.12,-30.43,0.162
3.14,-30.28,0.163
3.15,-30.13,0.163
3.16,-29.98,0.163
3.18,-29.83,0.163
3.19,-29.68,0.163
3.21,-29.53,0.163
3.23,-29.38,0.163
3.24,-29.23,0.163
3.26,-29.08,0.163
3.27,-28.93,0.163
3.29,-28.78,0.163
3.30,-28.63,0.163
3.31,-28.48,0.163
3.33,-28.33,0.163
3.34,-28.17,0.163
3.36,-28.02,0.163
3.38,-27.87,0.164
3.39,-27.72,0.164
3.41,-27.57,0.164
3.42,-27.42,0.164
3.44,-27.27,0.164
3.45,-27.12,0.164
3.46,-26.97,0.164
3.48,-26.82,0.164
3.49,-26.67,0.164
3.51,-26.52,0.164
3.53,-26.37,0.164
3.54,-26.22,0.164
3.56,-26.07,0.164
3.57,-25.92,0.164
3.59,-25.77,0.165
3.60,-25.62,0.165
3.61,-25.47,0.165
3.63,-25.32,0.165
3.64,-25.17,0.165
3.66,-25.02,0.165
3.68,-24.87,0.165
3.69,-24.72,0.165
3.71,-24.57,0.165
3.72,-24.42,0.165
3.74,-24.27,0.165
3.75,-24.12,0.165
3.76,-23.97,0.165
3.78,-23.82,0.165
3.79,-23.67,0.166
3.81,-23.52,0.166
3.83,-23.37,0.166
3.84,-23.22,0.166
3.86,-23.07,0.166
3.87,-22.92,0.166
3.89,-22.77,0.166
3.90,-22.62,0.166
3.91,-22.47,0.166
3.93,-22.32,0.166
3.94,-22.17,0.166
3.96,-22.02,0.166
3.98,-21.87,0.166
3.99,-21.72,0.167
4.01,-21.57,0.167
4.02,-21.42,0.167
4.04,-21.27,0.167
4.05,-21.12,0.167
4.06,-20.97,0.167
4.08,-20.82,0.167
4.09,-20.67,0.167
4.11,-20.52,0.167
4.13,-20.37,0.167
4.14,-20.21,0.167
4.16,-20.07,0.167
4.17,-19.91,0.167
4.19,-19.76,0.167
4.20,-19.61,0.167
4.21,-19.46,0.168
4.23,-19.31,0.168
4.24,-19.16,0.168
4.26,-19.01,0.168
4.28,-18.86,0.168
4.29,-18.71,0.168
4.30,-18.56,0.168
4.32,-18.41,0.168
4.34,-18.26,0.168
4.35,-18.11,0.168
4.36,-17.96,0.168
4.38,-17.81,0.168
4.40,-17.66,0.168
4.41,-17.51,0.168
4.43,-17.36,0.169
4.44,-17.21,0.169
4.45,-17.06,0.169
4.47,-16.91,0.169
4.49,-16.76,0.169
4.50,-16.61,0.169
4.51,-16.46,0.169
4.53,-16.31,0.169
4.55,-16.16,0.169
4.56,-16.01,0.169
4.58,-15.86,0.169
4.59,-15.71,0.169
4.60,-15.56,0.169
4.62,-15.41,0.169
4.64,-15.26,0.170
4.65,-15.11,0.170
4.66,-14.96,0.170
4.68,-14.81,0.170
4.70,-14.66,0.170
4.71,-14.51,0.170
4.73,-14.36,0.170
4.74,-14.21,0.170
4.75,-14.06,0.170
4.77,-13.91,0.170
4.79,-13.76,0.170
4.80,-13.61,0.170
4.81,-13.46,0.170
4.83,-13.31,0.170
4.85,-13.16,0.171
4.86,-13.01,0.171
4.88,-12.86,0.171
4.89,-12.71,0.171
4.90,-12.55,0.171
4.92,-12.41,0.171
4.94,-12.26,0.171
4.95,-12.10,0.171
4.96,-11.96,0.171
4.98,-11.81,0.171
5.00,-11.66,0.171
5.01,-11.50,0.172
5.03,-11.35,0.172
5.04,-11.20,0.172
5.05,-11.06,0.172
5.07,-10.90,0.172
5.09,-10.76,0.172
5.10,-10.60,0.172
5.11,-10.45,0.172
5.13,-10.30,0.172
5.15,-10.15,0.172
5.16,-10.00,0.172
5.18,-9.85,0.172
5.19,-9.70,0.172
5.20,-9.55,0.172
5.22,-9.40,0.172
5.24,-9.25,0.173
5.25,-9.10,0.173
5.26,-8.95,0.173
5.28,-8.80,0.173
5.30,-8.65,0.173
5.31,-8.50,0.173
5.33,-8.35,0.173
5.34,-8.20,0.173
5.35,-8.05,0.173
5.37,-7.90,0.173
5.39,-7.75,0.173
5.40,-7.60,0.173
5.41,-7.45,0.173
5.43,-7.30,0.174
5.45,-7.15,0.174
5.46,-7.00,0.174
5.48,-6.85,0.174
5.49,-6.70,0.174
5.50,-6.55,0.174
5.52,-6.40,0.174
5.54,-6.25,0.174
5.55,-6.10,0.174
5.56,-5.95,0.174
5.58,-5.80,0.174
5.60,-5.65,0.174
5.61,-5.50,0.174
5.63,-5.35,0.174
5.64,-5.20,0.175
5.65,-5.05,0.175
5.67,-4.90,0.175
5.69,-4.75,0.175
5.70,-4.60,0.175
5.71,-4.45,0.175
5.73,-4.30,0.175
5.75,-4.15,0.175
5.76,-4.00,0.175
5.78,-3.85,0.175
5.79,-3.70,0.175
5.80,-3.55,0.176
5.82,-3.40,0.176
5.84,-3.25,0.176
5.85,-3.10,0.176
5.86,-2.95,0.176
5.88,-2.80,0.176
5.90,-2.65,0.176
5.91,-2.49,0.176
5.93,-2.34,0.176
5.94,-2.19,0.176
5.95,-2.04,0.176
5.97,-1.89,0.176
5.99,-1.74,0.177
6.00,-1.59,0.177
6.01,-1.44,0.177
6.03,-1.29,0.177
6.05,-1.14,0.177
6.06,-0.99,0.177
6.08,-0.84,0.177
6.09,-0.69,0.177
6.10,-0.54,0.177
6.12,-0.39,0.177
6.14,-0.24,0.177
6.15,-0.09,0.177
6.16,0.06,0.178
6.18,0.21,0.178
6.20,0.36,0.178
6.21,0.51,0.178
6.23,0.66,0.178
6.24,0.81,0.178
6.25,0.96,0.178
6.27,1.11,0.178
6.29,1.26,0.178
6.30,1.41,0.179
6.31,1.56,0.179
6.33,1.71,0.179
6.35,1.86,0.179
6.36,2.01,0.179
6.38,2.16,0.179
6.39,2.31,0.179
6.40,2.46,0.179
6.42,2.61,0.179
6.44,2.76,0.179
6.45,2.91,0.179
6.46,3.06,0.179
6.48,3.21,0.179
6.50,3.36,0.179
6.51,3.51,0.180
6.53,3.66,0.180
6.54,3.81,0.180
6.55,3.96,0.180
6.57,4.11,0.180
6.59,4.27,0.180
6.60,4.41,0.180
6.61,4.56,0.180
6.63,4.71,0.180
6.65,4.86,0.180
6.66,5.01,0.180
6.68,5.17,0.180
6.69,5.32,0.180
6.70,5.47,0.181
6.72,5.62,0.181
6.74,5.77,0.181
6.75,5.92,0.181
6.76,6.07,0.181
6.78,6.22,0.181
6.80,6.37,0.181
6.81,6.52,0.181
6.83,6.67,0.181
6.84,6.82,0.181
6.85,6.97,0.181
6.87,7.12,0.182
6.89,7.27,0.182
6.90,7.42,0.182
6.91,7.57,0.182
6.93,7.72,0.182
6.95,7.87,0.182
6.96,8.02,0.182
6.98,8.17,0.182
6.99,8.32,0.182
7.00,8.47,0.182
7.02,8.62,0.182
7.04,8.77,0.183
7.05,8.92,0.183
7.06,9.07,0.183
7.08,9.22,0.183
7.10,9.37,0.183
7.11,9.52,0.183
7.13,9.67,0.183
7.14,9.82,0.183
7.15,9.97,0.183
7.17,10.12,0.183
7.19,10.27,0.183
7.20,10.42,0.184
7.21,10.57,0.184
7.23,10.72,0.184
7.25,10.87,0.184
7.26,11.02,0.184
7.28,11.17,0.184
7.29,11.32,0.184
7.30,11.47,0.184
7.32,11.62,0.184
7.34,11.77,0.184
7.35,11.92,0.184
7.36,12.07,0.185
7.38,12.22,0.185
7.40,12.37,0.185
7.41,12.52,0.185
7.43,12.67,0.185
7.44,12.82,0.185
7.45,12.97,0.185
7.47,13.12,0.185
7.49,13.27,0.185
7.50,13.43,0.185
7.51,13.57,0.186
7.53,13.72,0.186
7.55,13.87,0.186
7.56,14.03,0.186
7.58,14.18,0.186
7.59,14.33,0.186
7.60,14.48,0.186
7.62,14.63,0.186
7.64,14.78,0.186
7.65,14.93,0.186
7.66,15.08,0.187
7.68,15.23,0.187
7.70,15.38,0.187
7.71,15.53,0.187
7.73,15.68,0.187
7.74,15.83,0.187
7.75,15.98,0.187
7.77,16.13,0.187
7.79,16.28,0.187
7.80,16.43,0.187
7.81,16.58,0.187
7.83,16.73,0.187
7.85,16.88,0.188
7.86,17.03,0.188
7.88,17.18,0.188
7.89,17.33,0.188
7.90,17.48,0.188
7.92,17.63,0.188
7.94,17.78,0.188
7.95,17.93,0.188
7.96,18.08,0.188
7.98,18.23,0.188
8.00,18.38,0.189
8.01,18.53,0.189
8.03,18.68,0.189
8.04,18.83,0.189
8.05,18.98,0.189
8.07,19.13,0.189
8.09,19.28,0.189
8.10,19.43,0.189
8.11,19.58,0.189
8.13,19.73,0.189
8.15,19.88,0.190
8.16,20.03,0.190
8.18,20.18,0.190
8.19,20.33,0.190
8.20,20.48,0.190
8.22,20.63,0.190
8.24,20.78,0.190
8.25,20.93,0.190
8.26,21.08,0.190
8.28,21.23,0.190
8.30,21.38,0.191
8.31,21.53,0.191
8.33,21.68,0.191
8.34,21.83,0.191
8.35,21.98,0.191
8.37,22.13,0.191
8.39,22.28,0.191
8.40,22.43,0.191
8.41,22.58,0.191
8.43,22.73,0.191
8.45,22.88,0.191
8.46,23.03,0.191
8.48,23.18,0.192
8.49,23.33,0.192
8.50,23.48,0.192
8.52,23.63,0.192
8.53,23.78,0.192
8.55,23.93,0.192
8.57,24.08,0.192
8.58,24.23,0.192
8.60,24.38,0.193
8.61,24.53,0.193
8.63,24.68,0.193
8.64,24.83,0.193
8.65,24.98,0.193
8.67,25.13,0.193
8.68,25.28,0.193
8.70,25.43,0.193
8.72,25.58,0.193
8.73,25.73,0.193
8.75,25.88,0.193
8.76,26.03,0.194
8.78,26.18,0.194
8.79,26.33,0.194
8.80,26.48,0.194
8.82,26.63,0.194
8.83,26.79,0.194
8.85,26.94,0.194
8.87,27.09,0.194
8.88,27.24,0.194
8.90,27.39,0.195
8.91,27.54,0.195
8.93,27.69,0.195
8.94,27.84,0.195
8.95,27.99,0.195
8.97,28.14,0.195
8.98,28.29,0.195
9.00,28.44,0.195
9.02,28.59,0.195
9.03,28.74,0.195
9.05,28.89,0.195
9.06,29.04,0.196
9.08,29.19,0.196
9.09,29.34,0.196
9.10,29.49,0.196
9.12,29.64,0.196
9.13,29.79,0.196
9.15,29.94,0.196
9.17,30.09,0.196
9.18,30.24,0.196
9.20,30.39,0.196
9.21,30.54,0.196
9.23,30.69,0.197
9.24,30.84,0.197
9.25,30.99,0.197
9.27,31.14,0.197
9.28,31.29,0.197
9.30,31.44,0.197
9.32,31.59,0.197
9.33,31.74,0.197
9.35,31.89,0.197
9.36,32.04,0.197
9.38,32.19,0.197
9.39,32.34,0.198
9.40,32.49,0.198
9.42,32.64,0.198
9.43,32.79,0.198
9.45,32.94,0.198
9.47,33.09,0.198
9.48,33.24,0.198
9.50,33.39,0.198
9.51,33.54,0.198
9.53,33.69,0.198
9.54,33.84,0.198
9.55,33.99,0.199
9.57,34.14,0.199
9.58,34.29,0.199
9.60,34.44,0.199
9.62,34.59,0.199
9.63,34.74,0.199
9.65,34.89,0.199
9.66,35.05,0.199
9.68,35.20,0.199
9.69,35.34,0.199
9.70,35.50,0.199
9.72,35.64,0.200
9.73,35.80,0.200
9.75,35.95,0.200
9.77,36.10,0.200
9.78,36.25,0.200
9.80,36.40,0.200
9.81,36.55,0.200
9.83,36.70,0.200
9.84,36.85,0.200
9.85,37.00,0.200
9.87,37.15,0.200
9.88,37.30,0.201
9.90,37.45,0.201
9.92,37.60,0.201
9.93,37.75,0.201
9.95,37.90,0.201
9.96,38.05,0.201
9.98,38.20,0.201
9.99,38.35,0.201
10.00,38.50,0.201
10.02,38.65,0.201
10.03,38.80,0.201
10.05,38.95,0.202
10.07,39.10,0.202
10.08,39.25,0.202
10.10,39.40,0.202
10.11,39.55,0.202
10.13,39.70,0.202
10.14,39.85,0.202
10.15,40.00,0.202
10.17,40.15,0.202
10.18,40.30,0.202
10.20,40.45,0.202
10.22,40.60,0.203
10.23,40.75,0.203
10.25,40.90,0.203
10.26,41.05,0.203
10.28,41.20,0.203
10.29,41.35,0.203
10.30,41.50,0.203
10.32,41.65,0.203
10.33,41.80,0.203
10.35,41.95,0.203
10.37,42.10,0.203
10.38,42.25,0.204
10.40,42.40,0.204
10.41,42.55,0.204
10.43,42.70,0.204
10.44,42.85,0.204
10.45,43.00,0.204
10.47,43.15,0.204
10.48,43.30,0.204
10.50,43.45,0.204
10.52,43.60,0.204
10.53,43.75,0.204
10.55,43.90,0.205
10.56,44.05,0.205
10.58,44.21,0.205
10.59,44.35,0.205
10.60,44.51,0.205
10.62,44.65,0.205
10.63,44.80,0.205
10.65,44.95,0.205
10.67,45.11,0.205
10.68,45.25,0.205
10.70,45.41,0.205
10.71,45.56,0.206
10.73,45.71,0.206
10.74,45.86,0.206
10.75,46.01,0.206
10.77,46.16,0.206
10.78,46.31,0.206
10.80,46.46,0.206
10.82,46.61,0.206
10.83,46.76,0.206
10.85,46.91,0.206
10.86,47.06,0.207
10.88,47.21,0.207
10.89,47.36,0.207
10.90,47.51,0.207
10.92,47.66,0.207
10.93,47.81,0.207
10.95,47.96,0.207
10.97,48.11,0.207
10.98,48.26,0.207
11.00,48.41,0.207
11.01,48.56,0.207
11.03,48.71,0.208
11.04,48.86,0.208
11.05,49.01,0.208
11.07,49.16,0.208
11.08,49.31,0.208
11.10,49.46,0.208
11.12,49.61,0.208
11.13,49.76,0.208
11.15,49.91,0.208
11.16,50.06,0.208
11.18,50.21,0.208
11.19,50.36,0.209
11.20,50.51,0.209
11.22,50.66,0.209
11.23,50.81,0.209
11.25,50.96,0.209
11.27,51.11,0.209
11.28,51.26,0.209
11.30,51.41,0.209
11.31,51.56,0.209
11.33,51.71,0.209
11.34,51.86,0.209
11.35,52.01,0.210
11.37,52.16,0.210
11.38,52.31,0.210
11.40,52.46,0.210
11.42,52.61,0.210
11.43,52.76,0.210
11.45,52.91,0.210
11.46,53.06,0.210
11.48,53.21,0.210
11.49,53.36,0.210
11.50,53.51,0.210
11.52,53.66,0.210
11.53,53.81,0.211
11.55,53.96,0.211
11.57,54.12,0.211
11.58,54.26,0.211
11.60,54.42,0.211
11.61,54.56,0.211
11.63,54.72,0.211
11.64,54.87,0.211
11.65,55.01,0.211
11.67,55.17,0.211
11.68,55.31,0.211
11.70,55.47,0.212
11.72,55.62,0.212
11.73,55.77,0.212
11.75,55.92,0.212
11.76,56.07,0.212
11.78,56.22,0.212
11.79,56.37,0.212
11.80,56.52,0.212
11.82,56.67,0.212
11.83,56.82,0.212
11.85,56.97,0.213
11.87,57.12,0.213
11.88,57.27,0.213
11.90,57.42,0.213
11.91,57.57,0.213
11.93,57.72,0.213
11.94,57.87,0.213
11.95,58.02,0.213
11.97,58.17,0.213
11.98,58.32,0.213
12.00,58.47,0.213
12.02,58.62,0.213
12.03,58.77,0.213
12.05,58.92,0.214
12.06,59.07,0.214
12.08,59.22,0.214
12.09,59.37,0.214
12.10,59.52,0.214
12.12,59.67,0.214
12.13,59.82,0.214
12.15,59.97,0.214
12.17,60.12,0.214
12.18,60.27,0.214
12.20,60.42,0.214
12.21,60.57,0.215
12.23,60.72,0.215
12.24,60.87,0.215
12.25,61.02,0.215
12.27,61.17,0.215
12.28,61.32,0.215
12.30,61.47,0.215
12.32,61.62,0.215
12.33,61.77,0.215
12.35,61.92,0.215
12.36,62.07,0.215
12.38,62.22,0.215
12.39,62.37,0.215
12.40,62.52,0.216
12.42,62.67,0.216
12.43,62.82,0.216
12.45,62.97,0.216
12.47,63.12,0.216
12.48,63.27,0.216
12.50,63.42,0.216
12.51,63.57,0.216
12.53,63.72,0.216
12.54,63.87,0.216
12.55,64.02,0.216
12.57,64.17,0.217
12.58,64.32,0.217
12.60,64.47,0.217
12.62,64.62,0.217
12.63,64.77,0.217
12.65,64.92,0.217
12.66,65.07,0.217
12.68,65.23,0.217
12.69,65.38,0.217
12.70,65.53,0.217
12.72,65.68,0.217
12.73,65.83,0.218
12.75,65.98,0.218
12.77,66.13,0.218
12.78,66.28,0.218
12.80,66.43,0.218
12.81,66.58,0.218
12.83,66.73,0.218
12.84,66.88,0.218
12.85,67.03,0.218
12.87,67.18,0.218
12.88,67.33,0.218
12.90,67.48,0.218
12.92,67.63,0.219
12.93,67.78,0.219
12.95,67.93,0.219
12.96,68.08,0.219
12.98,68.23,0.219
12.99,68.38,0.219
13.00,68.53,0.219
13.02,68.68,0.219
13.03,68.83,0.219
13.05,68.98,0.219
13.07,69.13,0.219
13.08,69.28,0.219
13.10,69.43,0.220
13.11,69.58,0.220
13.13,69.73,0.220
13.14,69.88,0.220
13.15,70.03,0.220
13.17,70.18,0.220
13.18,70.33,0.220
13.20,70.48,0.220
13.22,70.63,0.220
13.23,70.78,0.220
13.25,70.93,0.220
13.26,71.08,0.221
13.28,71.23,0.221
13.29,71.38,0.221
13.30,71.53,0.221
13.32,71.68,0.221
13.33,71.83,0.221
13.35,71.98,0.221
13.37,72.13,0.221
13.38,72.28,0.221
13.40,72.43,0.221
13.41,72.58,0.221
13.43,72.73,0.222
13.44,72.88,0.222
13.45,73.03,0.222
13.47,73.18,0.222
13.48,73.33,0.222
13.50,73.48,0.222
13.52,73.63,0.222
13.53,73.78,0.222
13.55,73.93,0.222
13.56,74.08,0.222
13.58,74.23,0.222
13.59,74.38,0.222
13.60,74.53,0.223
13.62,74.68,0.223
13.63,74.83,0.223
13.65,74.99,0.223
13.67,75.14,0.223
13.68,75.28,0.223
13.70,75.43,0.223
13.71,75.59,0.223
13.73,75.74,0.223
13.74,75.89,0.223
13.75,76.04,0.224
13.77,76.19,0.224
13.78,76.34,0.224
13.80,76.49,0.224
13.82,76.64,0.224
13.83,76.79,0.224
13.85,76.94,0.224
13.86,77.09,0.224
13.88,77.24,0.224
13.89,77.39,0.224
13.90,77.54,0.225
13.92,77.69,0.225
13.93,77.84,0.225
13.95,77.99,0.225
13.97,78.14,0.225
13.98,78.29,0.225
14.00,78.44,0.225
14.01,78.59,0.225
14.03,78.74,0.225
14.04,78.89,0.225
14.05,79.04,0.226
14.07,79.19,0.226
14.08,79.34,0.226
14.10,79.49,0.226
14.12,79.64,0.226
14.13,79.79,0.226
14.15,79.94,0.226
14.16,80.09,0.226
14.18,80.24,0.226
14.19,80.39,0.226
14.20,80.54,0.226
14.22,80.69,0.226
14.23,80.84,0.226
14.25,80.99,0.227
14.27,81.14,0.227
14.28,81.29,0.227
14.30,81.44,0.227
14.31,81.59,0.227
14.33,81.74,0.227
14.34,81.89,0.227
14.35,82.04,0.227
14.37,82.19,0.227
14.38,82.34,0.227
14.40,82.49,0.227
14.42,82.64,0.227
14.43,82.79,0.227
14.45,82.94,0.228
14.46,83.09,0.228
14.48,83.24,0.228
14.49,83.39,0.228
14.50,83.54,0.228
14.52,83.69,0.228
14.53,83.84,0.228
14.55,83.99,0.228
14.57,84.15,0.228
14.58,84.30,0.228
14.60,84.45,0.228
14.61,84.60,0.228
14.63,84.75,0.228
14.64,84.90,0.228
14.65,85.04,0.228
14.67,85.19,0.229
14.68,85.34,0.229
14.70,85.49,0.229
14.72,85.64,0.229
14.73,85.79,0.229
14.75,85.95,0.229
14.76,86.10,0.229
14.78,86.25,0.229
14.79,86.40,0.229
14.80,86.55,0.229
14.82,86.70,0.229
14.83,86.85,0.229
14.85,87.00,0.229
14.87,87.15,0.230
14.88,87.30,0.230
14.90,87.45,0.230
14.91,87.60,0.230
14.93,87.75,0.230
14.94,87.90,0.230
14.95,88.05,0.230
14.97,88.20,0.230
14.98,88.35,0.230
15.00,88.50,0.230
15.02,88.65,0.230
15.03,88.80,0.231
15.05,88.95,0.231
15.06,89.10,0.231
15.08,89.25,0.231
15.09,89.40,0.231
15.10,89.55,0.231
15.12,89.70,0.231
15.13,89.85,0.231
15.15,90.00,0.231
15.17,90.15,0.231
15.18,90.30,0.231
15.20,90.45,0.231
15.21,90.60,0.232
15.23,90.75,0.232
15.24,90.90,0.232
15.25,91.05,0.232
15.27,91.20,0.232
15.28,91.35,0.232
15.30,91.50,0.232
15.32,91.65,0.232
15.33,91.80,0.232
15.35,91.95,0.232
15.36,92.10,0.233
15.38,92.25,0.233
15.39,92.40,0.233
15.40,92.55,0.233
15.42,92.70,0.233
15.43,92.85,0.233
15.45,93.01,0.233
15.47,93.16,0.233
15.48,93.31,0.234
15.50,93.46,0.234
15.51,93.61,0.234
15.53,93.76,0.234
15.54,93.91,0.234
15.55,94.06,0.234
15.57,94.21,0.234
15.58,94.36,0.234
15.60,94.51,0.234
15.62,94.66,0.234
15.63,94.81,0.235
15.65,94.96,0.235
15.66,95.11,0.235
15.68,95.26,0.235
15.69,95.41,0.235
15.70,95.56,0.235
15.72,95.71,0.235
15.73,95.86,0.235
15.75,96.01,0.235
15.77,96.16,0.235
15.78,96.31,0.235
15.80,96.46,0.235
15.81,96.61,0.235
15.83,96.76,0.235
15.84,96.91,0.235
15.85,97.06,0.235
15.87,97.21,0.235
15.88,97.36,0.236
15.90,97.51,0.236
15.92,97.66,0.236
15.93,97.81,0.236
15.95,97.96,0.236
15.96,98.11,0.236
15.98,98.26,0.236
15.99,98.41,0.236
16.00,98.56,0.236
16.02,98.71,0.236
16.03,98.86,0.236
16.05,99.00,0.236
16.07,99.16,0.236
16.08,99.31,0.236
16.10,99.45,0.236
16.11,99.61,0.237
16.13,99.76,0.237
16.14,99.91,0.237
16.15,100.06,0.237
16.17,100.21,0.237
16.18,100.36,0.237
16.20,100.51,0.237
16.22,100.66,0.237
16.23,100.81,0.237
16.25,100.96,0.238
16.26,101.11,0.238
16.28,101.25,0.238
16.29,101.41,0.238
16.30,101.56,0.238
16.32,101.71,0.238
16.33,101.86,0.238
16.35,102.01,0.238
16.37,102.16,0.238
16.38,102.31,0.238
16.40,102.46,0.239
16.41,102.61,0.239
16.43,102.76,0.239
16.44,102.91,0.239
16.45,103.06,0.239
16.47,103.21,0.239
16.48,103.36,0.239
16.50,103.51,0.239
16.52,103.66,0.239
16.53,103.81,0.239
16.55,103.96,0.239
16.56,104.11,0.240
16.58,104.26,0.240
16.59,104.41,0.240
16.60,104.56,0.240
16.62,104.71,0.240
16.63,104.86,0.240
16.65,105.01,0.240
16.67,105.16,0.240
16.68,105.31,0.240
16.70,105.46,0.240
16.71,105.61,0.240
16.73,105.76,0.241
16.74,105.91,0.241
16.75,106.06,0.241
16.77,106.21,0.241
16.78,106.36,0.241
16.80,106.51,0.241
16.82,106.66,0.241
16.83,106.81,0.241
16.85,106.96,0.241
16.86,107.11,0.241
16.88,107.26,0.241
16.89,107.41,0.241
16.90,107.56,0.242
16.92,107.71,0.242
16.93,107.86,0.242
16.95,108.01,0.242
16.97,108.16,0.242
16.98,108.31,0.242
17.00,108.46,0.242
17.01,108.61,0.242
17.03,108.76,0.242
17.04,108.91,0.242
17.05,109.06,0.242
17.07,109.21,0.243
17.08,109.36,0.243
17.10,109.51,0.243
17.12,109.66,0.243
17.13,109.81,0.243
17.14,109.96,0.243
17.16,110.11,0.243
17.18,110.26,0.243
17.19,110.42,0.243
17.21,110.56,0.243
17.22,110.71,0.243
17.23,110.86,0.244
17.25,111.01,0.244
17.27,111.17,0.244
17.28,111.31,0.244
17.29,111.46,0.244
17.31,111.62,0.244
17.33,111.77,0.244
17.34,111.92,0.244
17.36,112.07,0.244
17.37,112.22,0.244
17.38,112.37,0.245
17.40,112.52,0.245
17.42,112.67,0.245
17.43,112.82,0.245
17.44,112.97,0.245
17.46,113.12,0.245
17.48,113.27,0.245
17.49,113.42,0.245
17.51,113.57,0.245
17.52,113.72,0.245
17.53,113.87,0.245
17.55,114.02,0.246
17.57,114.17,0.246
17.58,114.32,0.246
17.59,114.47,0.246
17.61,114.62,0.246
17.63,114.77,0.246
17.64,114.92,0.246
17.66,115.07,0.246
17.67,115.22,0.246
17.68,115.37,0.246
17.70,115.52,0.246
17.72,115.67,0.247
17.73,115.82,0.247
17.74,115.97,0.247
17.76,116.12,0.247
17.78,116.27,0.247
17.79,116.42,0.247
17.81,116.57,0.247
17.82,116.72,0.247
17.83,116.87,0.247
17.85,117.02,0.247
17.87,117.17,0.247
17.88,117.32,0.248
17.89,117.47,0.248
17.91,117.62,0.248
17.93,117.77,0.248
17.94,117.92,0.248
17.96,118.07,0.248
17.97,118.22,0.248
17.98,118.37,0.248
18.00,118.52,0.248
18.02,118.67,0.248
18.03,118.82,0.248
18.04,118.97,0.249
18.06,119.12,0.249
18.08,119.27,0.249
18.09,119.42,0.249
18.11,119.57,0.249
18.12,119.72,0.249
18.13,119.87,0.249
18.15,120.02,0.250
18.17,120.17,0.250
18.18,120.32,0.250
18.19,120.47,0.250
18.21,120.62,0.250
18.23,120.77,0.251
18.24,120.92,0.251
18.26,121.07,0.251
18.27,121.22,0.253
18.28,121.37,0.253
18.30,121.52,0.254
18.32,121.67,0.257
18.33,121.82,0.260
18.34,121.97,0.266
18.36,122.11,0.277
18.38,122.25,0.338
18.39,122.37,0.512
18.41,122.44,0.768
18.42,122.48,0.961
18.43,122.51,1.095
18.45,122.55,1.223
18.47,122.58,1.345
18.48,122.62,1.468
18.49,122.66,1.584
18.51,122.70,1.702
18.53,122.74,1.842
18.54,122.78,1.962
18.56,122.82,2.084
18.57,122.85,2.220
18.58,122.89,2.328
18.60,122.94,2.444
18.62,122.98,2.552
18.63,123.02,2.720
18.64,123.06,2.849
18.66,123.10,2.939
18.68,123.14,3.036
18.69,123.19,3.144
18.71,123.25,3.208
18.72,123.31,3.318
18.73,123.36,3.505
18.75,123.40,3.620
18.77,123.44,3.715
18.78,123.50,3.796
18.79,123.55,3.897
18.81,123.63,3.912
18.83,123.70,4.001
18.84,123.79,3.984
18.86,123.90,3.963
18.87,124.02,4.072
18.88,124.10,4.201
18.90,124.19,4.267
18.92,124.28,4.249
18.93,124.38,4.409
18.94,124.47,4.378
18.96,124.59,4.345
18.98,124.73,4.303
18.99,124.87,4.307
19.01,125.03,4.111
19.02,125.24,4.011
19.03,125.45,3.869
19.05,125.66,3.836
19.07,125.88,3.710
19.08,126.10,3.676
19.09,126.30,3.670
19.11,126.49,3.628
19.13,126.70,3.506
19.14,126.93,3.267
19.16,127.21,2.960
19.17,127.53,2.578
19.18,127.89,2.269
19.20,128.26,1.984
19.22,128.63,1.706
19.23,129.00,1.521
19.24,129.35,1.385
19.26,129.67,1.268
19.28,129.98,1.166
19.29,130.27,1.074
19.31,130.54,0.994
19.32,130.80,0.922
19.33,131.04,0.858
19.35,131.28,0.800
19.37,131.51,0.750
19.38,131.72,0.704
19.39,131.93,0.664
19.41,132.14,0.628
19.43,132.33,0.596
19.44,132.53,0.568
19.46,132.71,0.542
19.47,132.90,0.520
19.48,133.08,0.499
19.50,133.25,0.482
19.52,133.42,0.466
19.53,133.60,0.452
19.54,133.76,0.439
19.56,133.93,0.429
19.58,134.09,0.419
19.59,134.26,0.410
19.61,134.42,0.401
19.62,134.58,0.394
19.63,134.74,0.390
19.65,134.90,0.384
19.67,135.05,0.380
19.68,135.21,0.375
19.69,135.37,0.372
19.71,135.52,0.368
19.73,135.68,0.365
19.74,135.83,0.363
19.76,135.98,0.360
19.77,136.14,0.358
19.78,136.29,0.357
19.80,136.44,0.355
19.82,136.59,0.354
19.83,136.75,0.352
19.84,136.90,0.352
19.86,137.05,0.350
19.88,137.20,0.350
19.89,137.35,0.349
19.91,137.51,0.348
19.92,137.66,0.348
19.93,137.81,0.348
19.95,137.96,0.347
19.97,138.11,0.347
19.98,138.26,0.347
19.99,138.41,0.346
20.01,138.56,0.346
20.03,138.71,0.346
20.04,138.86,0.346
20.06,139.01,0.346
20.07,139.16,0.346
20.08,139.31,0.346
20.10,139.46,0.346
20.12,139.61,0.345
20.13,139.76,0.345
20.14,139.91,0.345
20.16,140.06,0.345
20.18,140.22,0.345
20.19,140.37,0.345
20.21,140.52,0.345
20.22,140.67,0.345
20.23,140.82,0.345
20.25,140.97,0.345
20.27,141.12,0.345
20.28,141.27,0.345
20.29,141.42,0.345
20.31,141.57,0.345
20.33,141.72,0.345
20.34,141.87,0.345
20.36,142.02,0.345
20.37,142.17,0.345
20.38,142.32,0.345
20.40,142.47,0.345
20.42,142.62,0.345
20.43,142.77,0.345
20.44,142.92,0.345
20.46,143.07,0.345
20.48,143.22,0.345
20.49,143.37,0.345
20.51,143.52,0.345
20.52,143.67,0.345
20.53,143.82,0.345
20.55,143.97,0.345
20.57,144.12,0.346
20.58,144.27,0.346
20.59,144.42,0.346
20.61,144.57,0.346
20.63,144.72,0.346
20.64,144.87,0.346
20.66,145.02,0.346
20.67,145.17,0.346
20.68,145.32,0.346
20.70,145.47,0.346
20.72,145.62,0.346
20.73,145.77,0.347
20.74,145.92,0.347
20.76,146.07,0.347
20.78,146.22,0.347
20.79,146.37,0.347
20.81,146.52,0.347
20.82,146.67,0.347
20.83,146.82,0.347
20.85,146.97,0.347
20.87,147.12,0.347
20.88,147.27,0.347
20.89,147.42,0.348
20.91,147.57,0.348
20.93,147.72,0.348
20.94,147.87,
20.96,148.02,
20.97,148.17,
20.98,,
20.99,,

[step]
Ramp 10.00 °C/min to -60.00 °C
Time,Temperature,Heat Flow (Normalized)
min,°C,W/g
22.99,150.14,-0.018
23.01,150.13,-0.018
23.02,150.13,-0.018
23.04,150.13,-0.018
23.05,150.11,-0.019
23.07,150.09,-0.023
23.08,150.06,-0.032
23.10,150.01,-0.046
23.11,149.95,-0.064
23.13,149.88,-0.087
23.14,149.80,-0.113
23.16,149.71,-0.138
23.17,149.61,-0.164
23.19,149.51,-0.187
23.20,149.40,-0.208
23.22,149.29,-0.227
23.23,149.17,-0.244
23.25,149.05,-0.259
23.26,148.93,-0.273
23.28,148.80,-0.284
23.29,148.67,-0.295
23.31,148.54,-0.305
23.32,148.41,-0.314
23.34,148.28,-0.322
23.35,148.14,-0.328
23.37,148.00,-0.334
23.38,147.87,-0.340
23.40,147.73,-0.345
23.41,147.59,-0.349
23.43,147.45,-0.352
23.44,147.30,-0.356
23.46,147.16,-0.359
23.47,147.02,-0.362
23.49,146.87,-0.363
23.50,146.73,-0.366
23.52,146.59,-0.368
23.53,146.44,-0.369
23.55,146.30,-0.371
23.56,146.15,-0.372
23.58,146.00,-0.373
23.59,145.86,-0.374
23.61,145.71,-0.374
23.62,145.56,-0.376
23.64,145.42,-0.376
23.65,145.27,-0.377
23.67,145.12,-0.377
23.68,144.97,-0.378
23.70,144.83,-0.379
23.71,144.68,-0.379
23.73,144.53,-0.379
23.74,144.38,-0.380
23.76,144.23,-0.380
23.77,144.08,-0.380
23.79,143.93,-0.380
23.80,143.79,-0.380
23.82,143.64,-0.380
23.83,143.49,-0.380
23.85,143.34,-0.380
23.86,143.19,-0.380
23.88,143.04,-0.380
23.89,142.89,-0.380
23.91,142.74,-0.381
23.92,142.59,-0.381
23.94,142.45,-0.381
23.95,142.30,-0.381
23.97,142.15,-0.381
23.98,142.00,-0.381
24.00,141.85,-0.381
24.01,141.70,-0.381
24.03,141.55,-0.381
24.04,141.40,-0.381
24.06,141.25,-0.381
24.07,141.10,-0.381
24.09,140.95,-0.381
24.10,140.80,-0.381
24.12,140.65,-0.381
24.13,140.50,-0.381
24.15,140.35,-0.381
24.16,140.20,-0.381
24.18,140.05,-0.381
24.19,139.91,-0.381
24.21,139.76,-0.381
24.22,139.61,-0.381
24.24,139.46,-0.381
24.25,139.31,-0.381
24.27,139.16,-0.381
24.28,139.01,-0.381
24.30,138.86,-0.381
24.31,138.71,-0.380
24.33,138.56,-0.380
24.34,138.41,-0.380
24.36,138.26,-0.380
24.37,138.11,-0.380
24.39,137.96,-0.380
24.40,137.81,-0.380
24.42,137.66,-0.380
24.43,137.51,-0.380
24.45,137.36,-0.380
24.46,137.21,-0.380
24.48,137.06,-0.380
24.49,136.91,-0.380
24.51,136.76,-0.379
24.52,136.61,-0.379
24.54,136.46,-0.379
24.55,136.31,-0.379
24.57,136.16,-0.379
24.58,136.01,-0.379
24.60,135.86,-0.378
24.61,135.71,-0.378
24.63,135.56,-0.378
24.64,135.41,-0.378
24.66,135.26,-0.378
24.67,135.11,-0.378
24.69,134.96,-0.378
24.70,134.81,-0.378
24.72,134.66,-0.378
24.73,134.52,-0.378
24.75,134.36,-0.377
24.76,134.21,-0.377
24.78,134.06,-0.377
24.79,133.91,-0.377
24.81,133.76,-0.377
24.82,133.61,-0.377
24.84,133.46,-0.377
24.85,133.31,-0.377
24.87,133.16,-0.377
24.88,133.02,-0.376
24.90,132.87,-0.376
24.91,132.72,-0.376
24.93,132.57,-0.375
24.94,132.42,-0.375
24.96,132.27,-0.375
24.97,132.12,-0.375
24.99,131.97,-0.374
25.00,131.82,-0.374
25.02,131.67,-0.374
25.03,131.52,-0.374
25.05,131.37,-0.374
25.06,131.22,-0.374
25.08,131.07,-0.374
25.09,130.92,-0.374
25.11,130.77,-0.374
25.12,130.62,-0.374
25.14,130.47,-0.373
25.15,130.32,-0.373
25.17,130.17,-0.373
25.18,130.02,-0.373
25.20,129.87,-0.373
25.21,129.72,-0.373
25.23,129.57,-0.373
25.24,129.42,-0.373
25.26,129.27,-0.373
25.27,129.12,-0.373
25.29,128.97,-0.372
25.30,128.82,-0.372
25.32,128.67,-0.372
25.33,128.52,-0.372
25.35,128.37,-0.372
25.36,128.22,-0.372
25.38,128.07,-0.372
25.39,127.92,-0.372
25.41,127.77,-0.372
25.42,127.62,-0.371
25.44,127.47,-0.371
25.45,127.32,-0.371
25.47,127.17,-0.371
25.48,127.02,-0.371
25.50,126.87,-0.371
25.51,126.72,-0.371
25.53,126.57,-0.371
25.54,126.42,-0.370
25.56,126.27,-0.370
25.57,126.12,-0.370
25.59,125.97,-0.370
25.60,125.82,-0.370
25.62,125.67,-0.370
25.63,125.52,-0.370
25.65,125.37,-0.369
25.66,125.22,-0.369
25.68,125.07,-0.369
25.69,124.92,-0.369
25.71,124.77,-0.369
25.72,124.62,-0.369
25.74,124.47,-0.369
25.75,124.32,-0.368
25.77,124.17,-0.368
25.78,124.02,-0.368
25.80,123.87,-0.368
25.81,123.72,-0.368
25.83,123.57,-0.367
25.84,123.42,-0.367
25.86,123.27,-0.367
25.87,123.12,-0.367
25.89,122.97,-0.367
25.90,122.82,-0.367
25.92,122.67,-0.367
25.93,122.53,-0.367
25.95,122.37,-0.366
25.96,122.22,-0.366
25.98,122.07,-0.366
25.99,121.92,-0.366
26.01,121.77,-0.366
26.02,121.63,-0.366
26.04,121.48,-0.365
26.05,121.33,-0.365
26.07,121.18,-0.365
26.08,121.03,-0.365
26.10,120.88,-0.365
26.11,120.73,-0.365
26.13,120.58,-0.364
26.14,120.43,-0.364
26.16,120.28,-0.364
26.17,120.13,-0.364
26.19,119.98,-0.364
26.20,119.83,-0.363
26.22,119.68,-0.363
26.23,119.53,-0.363
26.25,119.38,-0.363
26.26,119.23,-0.363
26.28,119.08,-0.363
26.29,118.93,-0.363
26.31,118.78,-0.363
26.32,118.63,-0.363
26.34,118.48,-0.363
26.35,118.33,-0.363
26.37,118.18,-0.362
26.38,118.03,-0.362
26.40,117.88,-0.362
26.41,117.73,-0.362
26.43,117.58,-0.362
26.44,117.43,-0.362
26.46,117.28,-0.362
26.47,117.13,-0.362
26.49,116.98,-0.362
26.50,116.83,-0.361
26.52,116.68,-0.361
26.53,116.53,-0.361
26.55,116.38,-0.361
26.56,116.23,-0.361
26.58,116.08,-0.361
26.59,115.93,-0.361
26.61,115.78,-0.361
26.62,115.63,-0.360
26.64,115.48,-0.360
26.65,115.33,-0.360
26.67,115.18,-0.360
26.68,115.03,-0.360
26.70,114.88,-0.360
26.71,114.73,-0.359
26.73,114.58,-0.359
26.74,114.43,-0.359
26.76,114.28,-0.359
26.77,114.13,-0.359
26.79,113.98,-0.359
26.80,113.83,-0.359
26.82,113.68,-0.358
26.83,113.53,-0.358
26.85,113.38,-0.358
26.86,113.23,-0.358
26.88,113.08,-0.358
26.89,112.93,-0.358
26.91,112.78,-0.358
26.92,112.63,-0.358
26.94,112.48,-0.357
26.95,112.33,-0.357
26.97,112.18,-0.357
26.98,112.03,-0.357
27.00,111.88,-0.357
27.01,111.73,-0.357
27.03,111.58,-0.357
27.04,111.43,-0.356
27.06,111.28,-0.356
27.07,111.13,-0.356
27.09,110.98,-0.356
27.10,110.83,-0.355
27.12,110.68,-0.355
27.13,110.53,-0.355
27.15,110.38,-0.355
27.16,110.23,-0.355
27.18,110.08,-0.355
27.19,109.93,-0.355
27.21,109.78,-0.355
27.22,109.63,-0.354
27.24,109.48,-0.354
27.25,109.33,-0.354
27.27,109.18,-0.354
27.28,109.03,-0.354
27.30,108.88,-0.353
27.31,108.73,-0.353
27.33,108.58,-0.353
27.34,108.43,-0.353
27.36,108.28,-0.353
27.37,108.13,-0.353
27.39,107.98,-0.353
27.40,107.83,-0.352
27.42,107.68,-0.352
27.43,107.53,-0.352
27.45,107.38,-0.352
27.46,107.23,-0.352
27.48,107.08,-0.352
27.49,106.93,-0.352
27.51,106.78,-0.352
27.52,106.63,-0.351
27.54,106.48,-0.351
27.55,106.33,-0.351
27.57,106.18,-0.351
27.58,106.03,-0.351
27.60,105.88,-0.351
27.61,105.73,-0.351
27.63,105.58,-0.351
27.64,105.43,-0.350
27.66,105.29,-0.350
27.67,105.13,-0.350
27.69,104.98,-0.350
27.70,104.83,-0.350
27.72,104.68,-0.350
27.73,104.54,-0.349
27.75,104.39,-0.349
27.76,104.24,-0.349
27.78,104.09,-0.349
27.79,103.94,-0.349
27.81,103.79,-0.349
27.82,103.64,-0.349
27.84,103.49,-0.349
27.85,103.34,-0.348
27.87,103.19,-0.348
27.88,103.04,-0.348
27.90,102.89,-0.348
27.91,102.74,-0.348
27.93,102.59,-0.348
27.94,102.44,-0.348
27.96,102.29,-0.348
27.97,102.14,-0.347
27.99,101.99,-0.347
28.00,101.84,-0.347
28.02,101.69,-0.347
28.03,101.54,-0.347
28.05,101.39,-0.347
28.06,101.24,-0.347
28.08,101.09,-0.346
28.09,100.94,-0.346
28.11,100.79,-0.346
28.12,100.64,-0.346
28.14,100.49,-0.346
28.15,100.34,-0.346
28.17,100.19,-0.346
28.18,100.04,-0.345
28.20,99.89,-0.345
28.21,99.74,-0.345
28.23,99.59,-0.345
28.24,99.44,-0.345
28.26,99.29,-0.345
28.27,99.14,-0.344
28.29,98.99,-0.344
28.30,98.84,-0.344
28.32,98.69,-0.344
28.33,98.54,-0.344
28.35,98.39,-0.344
28.36,98.24,-0.344
28.38,98.09,-0.343
28.39,97.94,-0.343
28.41,97.79,-0.343
28.42,97.64,-0.343
28.44,97.49,-0.343
28.45,97.34,-0.343
28.47,97.19,-0.343
28.48,97.04,-0.343
28.50,96.89,-0.343
28.51,96.74,-0.342
28.53,96.59,-0.342
28.54,96.44,-0.342
28.56,96.29,-0.342
28.57,96.14,-0.342
28.59,95.99,-0.342
28.60,95.84,-0.341
28.62,95.69,-0.341
28.63,95.54,-0.341
28.65,95.39,-0.341
28.66,95.24,-0.341
28.68,95.09,-0.341
[...]
140.08,-40.93,0.156
140.09,-40.87,0.156
140.10,-40.80,0.156
140.10,-40.73,0.156
140.11,-40.67,0.156
140.12,-40.60,0.156
140.13,-40.53,0.156
140.13,-40.47,0.156
140.14,-40.40,0.156
140.15,-40.33,0.157
140.15,-40.27,0.157
140.16,-40.20,0.157
140.17,-40.13,0.157
140.17,-40.07,0.157
140.18,-40.00,0.157
140.18,-39.93,0.157
140.19,-39.87,0.157
140.20,-39.80,0.157
140.20,-39.73,0.157
140.21,-39.67,0.157
140.22,-39.60,0.157
140.23,-39.53,0.157
140.23,-39.47,0.157
140.24,-39.40,0.157
140.25,-39.33,0.157
140.25,-39.26,0.157
140.26,-39.20,0.157
140.27,-39.13,0.157
140.27,-39.07,0.157
140.28,-39.00,0.157
140.28,-38.93,0.157
140.29,-38.86,0.157
140.30,-38.80,0.157
140.30,-38.73,0.157
140.31,-38.66,0.157
140.32,-38.60,0.157
140.33,-38.53,0.157
140.33,-38.46,0.157
140.34,-38.40,0.157
140.35,-38.33,0.157
140.35,-38.26,0.157
140.36,-38.20,0.157
140.37,-38.13,0.158
140.37,-38.06,0.158
140.38,-38.00,0.158
140.38,-37.93,0.158
140.39,-37.86,0.158
140.40,-37.80,0.158
140.40,-37.73,0.158
140.41,-37.66,0.158
140.42,-37.60,0.158
140.43,-37.53,0.158
140.43,-37.46,0.158
140.44,-37.39,0.158
140.45,-37.33,0.158
140.45,-37.26,0.158
140.46,-37.19,0.158
140.47,-37.13,0.158
140.47,-37.06,0.158
140.48,-37.00,0.158
140.48,-36.93,0.158
140.49,-36.86,0.158
140.50,-36.80,0.158
140.50,-36.73,0.158
140.51,-36.66,0.158
140.52,-36.59,0.158
140.53,-36.53,0.158
140.53,-36.46,0.158
140.54,-36.39,0.158
140.55,-36.33,0.158
140.55,-36.26,0.159
140.56,-36.19,0.159
140.57,-36.13,0.159
140.57,-36.06,0.159
140.58,-35.99,0.159
140.58,-35.93,0.159
140.59,-35.86,0.159
140.60,-35.79,0.159
140.60,-35.73,0.159
140.61,-35.66,0.159
140.62,-35.59,0.159
140.63,-35.53,0.159
140.63,-35.46,0.159
140.64,-35.39,0.159
140.65,-35.33,0.159
140.65,-35.26,0.159
140.66,-35.19,0.159
140.67,-35.12,0.159
140.67,-35.06,0.159
140.68,-34.99,0.159
140.68,-34.93,0.159
140.69,-34.86,0.159
140.70,-34.79,0.159
140.70,-34.72,0.159
140.71,-34.66,0.159
140.72,-34.59,0.159
140.73,-34.52,0.159
140.73,-34.46,0.159
140.74,-34.39,0.159
140.75,-34.32,0.159
140.75,-34.26,0.159
140.76,-34.19,0.159
140.77,-34.12,0.159
140.77,-34.06,0.160
140.78,-33.99,0.160
140.78,-33.92,0.160
140.79,-33.86,0.160
140.80,-33.79,0.160
140.80,-33.73,0.160
140.81,-33.66,0.160
140.82,-33.59,0.160
140.83,-33.52,0.160
140.83,-33.46,0.160
140.84,-33.39,0.160
140.85,-33.32,0.160
140.85,-33.26,0.160
140.86,-33.19,0.160
140.87,-33.12,0.160
140.87,-33.06,0.160
140.88,-32.99,0.160
140.88,-32.92,0.160
140.89,-32.86,0.160
140.90,-32.79,0.160
140.90,-32.72,0.160
140.91,-32.66,0.160
140.92,-32.59,0.160
140.93,-32.52,0.160
140.93,-32.46,0.160
140.94,-32.39,0.160
140.95,-32.32,0.160
140.95,-32.25,0.160
140.96,-32.19,0.160
140.97,-32.12,0.160
140.97,-32.05,0.160
140.98,-31.99,0.161
140.98,-31.92,0.161
140.99,-31.86,0.161
141.00,-31.79,0.161
141.00,-31.72,0.161
141.01,-31.65,0.161
141.02,-31.59,0.161
141.03,-31.52,0.161
141.03,-31.45,0.161
141.04,-31.39,0.161
141.05,-31.32,0.161
141.05,-31.25,0.161
141.06,-31.19,0.161
141.07,-31.12,0.161
141.07,-31.05,0.161
141.08,-30.99,0.161
141.08,-30.92,0.161
141.09,-30.85,0.161
141.10,-30.79,0.161
141.10,-30.72,0.161
141.11,-30.65,0.161
141.12,-30.58,0.161
141.13,-30.52,0.161
141.13,-30.45,0.161
141.14,-30.38,0.161
141.15,-30.32,0.161
141.15,-30.25,0.161
141.16,-30.18,0.161
141.17,-30.12,0.161
141.17,-30.05,0.161
141.18,-29.98,0.161
141.18,-29.92,0.161
141.19,-29.85,0.161
141.20,-29.78,0.162
141.20,-29.72,0.162
141.21,-29.65,0.162
141.22,-29.58,0.162
141.23,-29.52,0.162
141.23,-29.45,0.162
141.24,-29.38,0.162
141.25,-29.32,0.162
141.25,-29.25,0.162
141.26,-29.18,0.162
141.27,-29.12,0.162
141.27,-29.05,0.162
141.28,-28.98,0.162
141.28,-28.92,0.162
141.29,-28.85,0.162
141.30,-28.78,0.162
141.30,-28.72,0.162
141.31,-28.65,0.162
141.32,-28.58,0.162
141.33,-28.52,0.162
141.33,-28.45,0.162
141.34,-28.38,0.162
141.35,-28.32,0.162
141.35,-28.25,0.162
141.36,-28.18,0.162
141.37,-28.12,0.162
141.37,-28.05,0.162
141.38,-27.98,0.162
141.38,-27.92,0.162
141.39,-27.85,0.162
141.40,-27.78,0.162
141.40,-27.71,0.163
141.41,-27.65,0.163
141.42,-27.58,0.163
141.43,-27.51,0.163
141.43,-27.45,0.163
141.44,-27.38,0.163
141.45,-27.31,0.163
141.45,-27.25,0.163
141.46,-27.18,0.163
141.47,-27.11,0.163
141.47,-27.05,0.163
141.48,-26.98,0.163
141.48,-26.91,0.163
141.49,-26.85,0.163
141.50,-26.78,0.163
141.50,-26.71,0.163
141.51,-26.65,0.163
141.52,-26.58,0.163
141.53,-26.51,0.163
141.53,-26.45,0.163
141.54,-26.38,0.163
141.55,-26.31,0.163
141.55,-26.25,0.163
141.56,-26.18,0.163
141.57,-26.11,0.163
141.57,-26.05,0.163
141.58,-25.98,0.163
141.58,-25.91,0.163
141.59,-25.84,0.163
141.60,-25.78,0.163
141.60,-25.71,0.163
141.61,-25.64,0.164
141.62,-25.58,0.164
141.63,-25.51,0.164
141.63,-25.44,0.164
141.64,-25.38,0.164
141.65,-25.31,0.164
141.65,-25.24,0.164
141.66,-25.18,0.164
141.67,-25.11,0.164
141.67,-25.04,0.164
141.68,-24.98,0.164
141.68,-24.91,0.164
141.69,-24.85,0.164
141.70,-24.78,0.164
141.70,-24.71,0.164
141.71,-24.64,0.164
141.72,-24.58,0.164
141.73,-24.51,0.164
141.73,-24.44,0.164
141.74,-24.38,0.164
141.75,-24.31,0.164
141.75,-24.24,0.164
141.76,-24.18,0.164
141.77,-24.11,0.164
141.77,-24.04,0.164
141.78,-23.98,0.164
141.78,-23.91,0.164
141.79,-23.84,0.164
141.80,-23.78,0.164
141.80,-23.71,0.164
141.81,-23.64,0.164
141.82,-23.58,0.165
141.83,-23.51,0.165
141.83,-23.44,0.165
141.84,-23.37,0.165
141.85,-23.31,0.165
141.85,-23.24,0.165
141.86,-23.18,0.165
141.87,-23.11,0.165
141.87,-23.04,0.165
141.88,-22.97,0.165
141.88,-22.91,0.165
141.89,-22.84,0.165
141.90,-22.78,0.165
141.90,-22.71,0.165
141.91,-22.64,0.165
141.92,-22.57,0.165
141.93,-22.51,0.165
141.93,-22.44,0.165
141.94,-22.37,0.165
141.95,-22.31,0.165
141.95,-22.24,0.165
141.96,-22.18,0.165
141.97,-22.11,0.165
141.97,-22.04,0.165
141.98,-21.97,0.165
141.98,-21.91,0.165
141.99,-21.84,0.165
142.00,-21.77,0.165
142.00,-21.71,0.165
142.01,-21.64,0.166
142.02,-21.57,0.166
142.03,-21.51,0.166
142.03,-21.44,0.166
142.04,-21.37,0.166
142.05,-21.31,0.166
142.05,-21.24,0.166
142.06,-21.17,0.166
142.07,-21.11,0.166
142.07,-21.04,0.166
142.08,-20.97,0.166
142.08,-20.91,0.166
142.09,-20.84,0.166
142.10,-20.77,0.166
142.10,-20.70,0.166
142.11,-20.64,0.166
142.12,-20.57,0.166
142.13,-20.51,0.166
142.13,-20.44,0.166
142.14,-20.37,0.166
142.15,-20.31,0.166
142.15,-20.24,0.166
142.16,-20.17,0.166
142.17,-20.11,0.166
142.17,-20.04,0.166
142.18,-19.97,0.166
142.18,-19.91,0.166
142.19,-19.84,0.166
142.20,-19.77,0.166
142.20,-19.71,0.166
142.21,-19.64,0.166
142.22,-19.57,0.167
142.23,-19.50,0.167
142.23,-19.44,0.167
142.24,-19.37,0.167
142.25,-19.30,0.167
142.25,-19.24,0.167
142.26,-19.17,0.167
142.27,-19.10,0.167
142.27,-19.04,0.167
142.28,-18.97,0.167
142.28,-18.90,0.167
142.29,-18.84,0.167
142.30,-18.77,0.167
142.30,-18.71,0.167
142.31,-18.64,0.167
142.32,-18.57,0.167
142.33,-18.50,0.167
142.33,-18.44,0.167
142.34,-18.37,0.167
142.35,-18.30,0.167
142.35,-18.24,0.167
142.36,-18.17,0.167
142.37,-18.10,0.167
142.37,-18.04,0.167
142.38,-17.97,0.167
142.38,-17.90,0.167
142.39,-17.84,0.167
142.40,-17.77,0.167
142.40,-17.70,0.167
142.41,-17.64,0.167
142.42,-17.57,0.167
142.43,-17.50,0.168
142.43,-17.44,0.168
142.44,-17.37,0.168
142.45,-17.30,0.168
142.45,-17.24,0.168
142.46,-17.17,0.168
142.47,-17.10,0.168
142.47,-17.04,0.168
142.48,-16.97,0.168
142.48,-16.90,0.168
142.49,-16.83,0.168
142.50,-16.77,0.168
142.50,-16.70,0.168
142.51,-16.64,0.168
142.52,-16.57,0.168
142.53,-16.50,0.168
142.53,-16.44,0.168
142.54,-16.37,0.168
142.55,-16.30,0.168
142.55,-16.23,0.168
142.56,-16.17,0.168
142.57,-16.10,0.168
142.57,-16.03,0.168
142.58,-15.97,0.168
142.58,-15.90,0.168
142.59,-15.83,0.168
142.60,-15.77,0.168
142.60,-15.70,0.169
142.61,-15.63,0.169
142.62,-15.57,0.169
142.63,-15.50,0.169
142.63,-15.43,0.169
142.64,-15.37,0.169
142.65,-15.30,0.169
142.65,-15.23,0.169
142.66,-15.17,0.169
142.67,-15.10,0.169
142.67,-15.03,0.169
142.68,-14.97,0.169
142.68,-14.90,0.169
142.69,-14.83,0.169
142.70,-14.77,0.169
142.70,-14.70,0.169
142.71,-14.63,0.169
142.72,-14.56,0.169
142.73,-14.50,0.169
142.73,-14.43,0.169
142.74,-14.37,0.169
142.75,-14.30,0.169
142.75,-14.23,0.169
142.76,-14.16,0.169
142.77,-14.10,0.169
142.77,-14.03,0.169
142.78,-13.96,0.169
142.78,-13.90,0.169
142.79,-13.83,0.169
142.80,-13.77,0.169
142.80,-13.70,0.169
142.81,-13.63,0.169
142.82,-13.56,0.169
142.83,-13.50,0.170
142.83,-13.43,0.170
142.84,-13.36,0.170
142.85,-13.30,0.170
142.85,-13.23,0.170
142.86,-13.16,0.170
142.87,-13.10,0.170
142.87,-13.03,0.170
142.88,-12.96,0.170
142.88,-12.90,0.170
142.89,-12.83,0.170
142.90,-12.76,0.170
142.90,-12.70,0.170
142.91,-12.63,0.170
142.92,-12.56,0.170
142.93,-12.50,0.170
142.93,-12.43,0.170
142.94,-12.36,0.170
142.95,-12.30,0.170
142.95,-12.23,0.170
142.96,-12.16,0.170
142.97,-12.10,0.170
142.97,-12.03,0.170
142.98,-11.96,0.170
142.98,-11.90,0.170
142.99,-11.83,0.170
143.00,-11.76,0.170
143.00,-11.69,0.171
143.01,-11.63,0.171
143.02,-11.56,0.171
143.03,-11.50,0.171
143.03,-11.43,0.171
143.04,-11.36,0.171
143.05,-11.29,0.171
143.05,-11.23,0.171
143.06,-11.16,0.171
143.07,-11.09,0.171
143.07,-11.03,0.171
143.08,-10.96,0.171
143.08,-10.89,0.171
143.09,-10.83,0.171
143.10,-10.76,0.171
143.10,-10.69,0.171
143.11,-10.63,0.171
143.12,-10.56,0.171
143.13,-10.49,0.171
143.13,-10.43,0.171
143.14,-10.36,0.171
143.15,-10.29,0.171
143.15,-10.23,0.171
143.16,-10.16,0.171
143.17,-10.09,0.171
143.17,-10.03,0.171
143.18,-9.96,0.171
143.18,-9.89,0.171
143.19,-9.83,0.171
143.20,-9.76,0.171
143.20,-9.69,0.171
143.21,-9.63,0.171
143.22,-9.56,0.172
143.23,-9.49,0.172
143.23,-9.43,0.172
143.24,-9.36,0.172
143.25,-9.29,0.172
143.25,-9.22,0.172
143.26,-9.16,0.172
143.27,-9.09,0.172
143.27,-9.03,0.172
143.28,-8.96,0.172
143.28,-8.89,0.172
143.29,-8.83,0.172
143.30,-8.76,0.172
143.30,-8.69,0.172
143.31,-8.62,0.172
143.32,-8.56,0.172
143.33,-8.49,0.172
143.33,-8.43,0.172
143.34,-8.36,0.172
143.35,-8.29,0.172
143.35,-8.22,0.172
143.36,-8.16,0.172
143.37,-8.09,0.172
143.37,-8.02,0.172
143.38,-7.96,0.172
143.38,-7.89,0.172
143.39,-7.83,0.172
143.40,-7.76,0.172
143.40,-7.69,0.172
143.41,-7.62,0.172
143.42,-7.56,0.173
143.43,-7.49,0.173
143.43,-7.42,0.173
143.44,-7.36,0.173
143.45,-7.29,0.173
143.45,-7.22,0.173
143.46,-7.16,0.173
143.47,-7.09,0.173
143.47,-7.02,0.173
143.48,-6.96,0.173
143.48,-6.89,0.173
143.49,-6.82,0.173
143.50,-6.76,0.173
143.50,-6.69,0.173
143.51,-6.62,0.173
143.52,-6.56,0.173
143.53,-6.49,0.173
143.53,-6.42,0.173
143.54,-6.36,0.173
143.55,-6.29,0.173
143.55,-6.22,0.173
143.56,-6.16,0.173
143.57,-6.09,0.173
143.57,-6.02,0.173
143.58,-5.96,0.173
143.58,-5.89,0.173
143.59,-5.82,0.173
143.60,-5.75,0.174
143.60,-5.69,0.174
143.61,-5.62,0.174
143.62,-5.55,0.174
143.63,-5.49,0.174
143.63,-5.42,0.174
143.64,-5.35,0.174
143.65,-5.29,0.174
143.65,-5.22,0.174
143.66,-5.16,0.174
143.67,-5.09,0.174
143.67,-5.02,0.174
143.68,-4.95,0.174
143.68,-4.89,0.174
143.69,-4.82,0.174
143.70,-4.76,0.174
143.70,-4.69,0.174
143.71,-4.62,0.174
143.72,-4.55,0.174
143.73,-4.49,0.174
143.73,-4.42,0.174
143.74,-4.35,0.174
143.75,-4.29,0.174
143.75,-4.22,0.174
143.76,-4.15,0.174
143.77,-4.09,0.174
143.77,-4.02,0.174
143.78,-3.95,0.175
143.78,-3.89,0.175
143.79,-3.82,0.175
143.80,-3.75,0.175
143.80,-3.68,0.175
143.81,-3.62,0.175
143.82,-3.55,0.175
143.83,-3.49,0.175
143.83,-3.42,0.175
143.84,-3.35,0.175
143.85,-3.29,0.175
143.85,-3.22,0.175
143.86,-3.15,0.175
143.87,-3.08,0.175
143.87,-3.02,0.175
143.88,-2.95,0.175
143.88,-2.89,0.175
143.89,-2.82,0.175
143.90,-2.75,0.175
143.90,-2.69,0.175
143.91,-2.62,0.175
143.92,-2.55,0.175
143.93,-2.49,0.175
143.93,-2.42,0.175
143.94,-2.35,0.175
143.95,-2.28,0.175
143.95,-2.22,0.175
143.96,-2.15,0.175
143.97,-2.08,0.176
143.97,-2.02,0.176
143.98,-1.95,0.176
143.98,-1.88,0.176
143.99,-1.82,0.176
144.00,-1.75,0.176
144.00,-1.68,0.176
144.01,-1.62,0.176
144.02,-1.55,0.176
144.03,-1.48,0.176
144.03,-1.42,0.176
144.04,-1.35,0.176
144.05,-1.28,0.176
144.05,-1.22,0.176
144.06,-1.15,0.176
144.07,-1.08,0.176
144.07,-1.02,0.176
144.08,-0.95,0.176
144.08,-0.88,0.176
144.09,-0.82,0.176
144.10,-0.75,0.176
144.10,-0.68,0.176
144.11,-0.61,0.176
144.12,-0.55,0.176
144.13,-0.48,0.176
144.13,-0.41,0.176
144.14,-0.35,0.176
144.15,-0.28,0.177
144.15,-0.22,0.177
144.16,-0.15,0.177
144.17,-0.08,0.177
144.17,-0.02,0.177
144.18,0.05,0.177
144.18,0.12,0.177
144.19,0.18,0.177
144.20,0.25,0.177
144.20,0.32,0.177
144.21,0.39,0.177
144.22,0.45,0.177
144.23,0.52,0.177
144.23,0.59,0.177
144.24,0.65,0.177
144.25,0.72,0.177
144.25,0.79,0.177
144.26,0.85,0.177
144.27,0.92,0.177
144.27,0.99,0.177
144.28,1.05,0.177
144.28,1.12,0.177
144.29,1.19,0.177
144.30,1.25,0.177
144.30,1.32,0.177
144.31,1.39,0.177
144.32,1.45,0.177
144.33,1.52,0.178
144.33,1.59,0.178
144.34,1.66,0.178
144.35,1.72,0.178
144.35,1.79,0.178
144.36,1.85,0.178
144.37,1.92,0.178
144.37,1.99,0.178
144.38,2.05,0.178
144.38,2.12,0.178
144.39,2.19,0.178
144.40,2.26,0.178
144.40,2.32,0.178
144.41,2.39,0.178
144.42,2.45,0.178
144.43,2.52,0.178
144.43,2.59,0.178
144.44,2.65,0.178
144.45,2.72,0.178
144.45,2.79,0.178
144.46,2.86,0.178
144.47,2.92,0.178
144.47,2.99,0.178
144.48,3.06,0.178
144.48,3.12,0.178
144.49,3.19,0.178
144.50,3.26,0.178
144.50,3.32,0.179
144.51,3.39,0.179
144.52,3.46,0.179
144.53,3.52,0.179
144.53,3.59,0.179
144.54,3.66,0.179
144.55,3.72,0.179
144.55,3.79,0.179
144.56,3.86,0.179
144.57,3.92,0.179
144.57,3.99,0.179
144.58,4.06,0.179
144.58,4.12,0.179
144.59,4.19,0.179
144.60,4.26,0.179
144.60,4.32,0.179
144.61,4.39,0.179
144.62,4.46,0.179
144.63,4.53,0.179
144.63,4.59,0.179
144.64,4.66,0.179
144.65,4.72,0.179
144.65,4.79,0.179
144.66,4.86,0.179
144.67,4.92,0.179
144.67,4.99,0.179
144.68,5.06,0.180
144.68,5.12,0.180
144.69,5.19,0.180
144.70,5.26,0.180
144.70,5.32,0.180
144.71,5.39,0.180
144.72,5.46,0.180
144.73,5.53,0.180
144.73,5.59,0.180
144.74,5.66,0.180
144.75,5.73,0.180
144.75,5.79,0.180
144.76,5.86,0.180
144.77,5.93,0.180
144.77,5.99,0.180
144.78,6.06,0.180
144.78,6.13,0.180
144.79,6.19,0.180
144.80,6.26,0.180
144.80,6.33,0.180
144.81,6.39,0.180
144.82,6.46,0.180
144.83,6.53,0.180
144.83,6.59,0.180
144.84,6.66,0.180
144.85,6.73,0.180
144.85,6.79,0.181
144.86,6.86,0.181
144.87,6.93,0.181
144.87,6.99,0.181
144.88,7.06,0.181
144.88,7.13,0.181
144.89,7.19,0.181
144.90,7.26,0.181
144.90,7.33,0.181
144.91,7.39,0.181
144.92,7.46,0.181
144.93,7.53,0.181
144.93,7.59,0.181
144.94,7.66,0.181
144.95,7.73,0.181
144.95,7.80,0.181
144.96,7.86,0.181
144.97,7.93,0.181
144.97,7.99,0.181
144.98,8.06,0.181
144.98,8.13,0.181
144.99,8.20,0.181
145.00,8.26,0.181
145.00,8.33,0.181
145.01,8.40,0.182
145.02,8.46,0.182
145.03,8.53,0.182
145.03,8.60,0.182
145.04,8.66,0.182
145.05,8.73,0.182
145.05,8.80,0.182
145.06,8.86,0.182
145.07,8.93,0.182
145.07,9.00,0.182
145.08,9.06,0.182
145.08,9.13,0.182
145.09,9.20,0.182
145.10,9.26,0.182
145.10,9.33,0.182
145.11,9.40,0.182
145.12,9.46,0.182
145.13,9.53,0.182
145.13,9.60,0.182
145.14,9.66,0.182
145.15,9.73,0.182
145.15,9.80,0.182
145.16,9.86,0.182
145.17,9.93,0.183
145.17,10.00,0.183
145.18,10.06,0.183
145.18,10.13,0.183
145.19,10.20,0.183
145.20,10.26,0.183
145.20,10.33,0.183
145.21,10.40,0.183
145.22,10.47,0.183
145.23,10.53,0.183
145.23,10.60,0.183
145.24,10.67,0.183
145.25,10.73,0.183
145.25,10.80,0.183
145.26,10.87,0.183
145.27,10.93,0.183
145.27,11.00,0.183
145.28,11.06,0.183
145.28,11.13,0.183
145.29,11.20,0.183
145.30,11.27,0.183
145.30,11.33,0.183
145.31,11.40,0.184
145.32,11.47,0.184
145.33,11.53,0.184
145.33,11.60,0.184
145.34,11.67,0.184
145.35,11.73,0.184
145.35,11.80,0.184
145.36,11.87,0.184
145.37,11.93,0.184
145.37,12.00,0.184
145.38,12.07,0.184
145.38,12.13,0.184
145.39,12.20,0.184
145.40,12.27,0.184
145.40,12.33,0.184
145.41,12.40,0.184
145.42,12.47,0.184
145.43,12.53,0.184
145.43,12.60,0.184
145.44,12.67,0.184
145.45,12.73,0.184
145.45,12.80,0.184
145.46,12.87,0.184
145.47,12.93,0.184
145.47,13.00,0.184
145.48,13.07,0.185
145.48,13.13,0.185
145.49,13.20,0.185
145.50,13.27,0.185
145.50,13.33,0.185
145.51,13.40,0.185
145.52,13.47,0.185
145.53,13.54,0.185
145.53,13.60,0.185
145.54,13.67,0.185
145.55,13.73,0.185
145.55,13.80,0.185
145.56,13.87,0.185
145.57,13.94,0.185
145.57,14.00,0.185
145.58,14.07,0.185
145.58,14.13,0.185
145.59,14.20,0.185
145.60,14.27,0.185
145.60,14.34,0.185
145.61,14.40,0.185
145.62,14.47,0.185
145.63,14.54,0.185
145.63,14.60,0.185
145.64,14.67,0.185
145.65,14.73,0.185
145.65,14.80,0.186
145.66,14.87,0.186
145.67,14.94,0.186
145.67,15.00,0.186
145.68,15.07,0.186
145.68,15.14,0.186
145.69,15.20,0.186
145.70,15.27,0.186
145.70,15.34,0.186
145.71,15.40,0.186
145.72,15.47,0.186
145.73,15.54,0.186
145.73,15.60,0.186
145.74,15.67,0.186
145.75,15.74,0.186
145.75,15.80,0.186
145.76,15.87,0.186
145.77,15.93,0.186
145.77,16.00,0.186
145.78,16.07,0.186
145.78,16.14,0.186
145.79,16.20,0.186
145.80,16.27,0.186
145.80,16.34,0.186
145.81,16.40,0.186
145.82,16.47,0.187
145.83,16.54,0.187
145.83,16.60,0.187
145.84,16.67,0.187
145.85,16.74,0.187
145.85,16.80,0.187
145.86,16.87,0.187
145.87,16.94,0.187
145.87,17.00,0.187
145.88,17.07,0.187
145.88,17.14,0.187
145.89,17.20,0.187
145.90,17.27,0.187
145.90,17.34,0.187
145.91,17.40,0.187
145.92,17.47,0.187
145.93,17.54,0.187
145.93,17.60,0.187
145.94,17.67,0.187
145.95,17.74,0.187
145.95,17.80,0.187
145.96,17.87,0.187
145.97,17.94,0.187
145.97,18.00,0.188
145.98,18.07,0.188
145.98,18.14,0.188
145.99,18.21,0.188
146.00,18.27,0.188
146.00,18.34,0.188
146.01,18.40,0.188
146.02,18.47,0.188
146.03,18.54,0.188
146.03,18.60,0.188
146.04,18.67,0.188
146.05,18.74,0.188
146.05,18.81,0.188
146.06,18.87,0.188
146.07,18.94,0.188
146.07,19.01,0.188
146.08,19.07,0.188
146.08,19.14,0.188
146.09,19.21,0.188
146.10,19.27,0.188
146.10,19.34,0.188
146.11,19.41,0.188
146.12,19.47,0.188
146.13,19.54,0.188
146.13,19.61,0.188
146.14,19.67,0.189
146.15,19.74,0.189
146.15,19.81,0.189
146.16,19.87,0.189
146.17,19.94,0.189
146.17,20.01,0.189
146.18,20.07,0.189
146.18,20.14,0.189
146.19,20.21,0.189
146.20,20.27,0.189
146.20,20.34,0.189
146.21,20.41,0.189
146.22,20.47,0.189
146.23,20.54,0.189
146.23,20.61,0.189
146.24,20.67,0.189
146.25,20.74,0.189
146.25,20.81,0.189
146.26,20.87,0.189
146.27,20.94,0.189
146.27,21.01,0.189
146.28,21.07,0.189
146.28,21.14,0.189
146.29,21.21,0.189
146.30,21.27,0.190
146.30,21.34,0.190
146.31,21.41,0.190
146.32,21.47,0.190
146.33,21.54,0.190
146.33,21.61,0.190
146.34,21.67,0.190
146.35,21.74,0.190
146.35,21.81,0.190
146.36,21.87,0.190
146.37,21.94,0.190
146.37,22.01,0.190
146.38,22.07,0.190
146.38,22.14,0.190
146.39,22.21,0.190
146.40,22.27,0.190
146.40,22.34,0.190
146.41,22.41,0.190
146.42,22.47,0.190
146.43,22.54,0.190
146.43,22.61,0.191
146.44,22.67,0.191
146.45,22.74,0.191
146.45,22.81,0.191
146.46,22.87,0.191
146.47,22.94,0.191
146.47,23.01,0.191
146.48,23.08,0.191
146.48,23.14,0.191
146.49,23.21,0.191
146.50,23.28,0.191
146.50,23.34,0.191
146.51,23.41,0.191
146.52,23.48,0.191
146.53,23.54,0.191
146.53,23.61,0.191
146.54,23.68,0.191
146.55,23.74,0.191
146.55,23.81,0.191
146.56,23.88,0.191
146.57,23.94,0.191
146.57,24.01,0.191
146.58,24.08,0.191
146.58,24.14,0.191
146.59,24.21,0.191
146.60,24.28,0.191
146.60,24.34,0.192
146.61,24.41,0.192
146.62,24.48,0.192
146.63,24.54,0.192
146.63,24.61,0.192
146.64,24.68,0.192
146.65,24.74,0.192
146.65,24.81,0.192
146.66,24.88,0.192
146.67,24.94,0.192
146.67,25.01,0.192
146.68,25.08,0.192
146.68,25.14,0.192
146.69,25.21,0.192
146.70,25.28,0.192
146.70,25.34,0.192
146.71,25.41,0.192
146.72,25.48,0.192
146.73,25.55,0.192
146.73,25.61,0.192
146.74,25.68,0.192
146.75,25.75,0.192
146.75,25.81,0.192
146.76,25.88,0.193
146.77,25.95,0.193
146.77,26.01,0.193
146.78,26.08,0.193
146.78,26.15,0.193
146.79,26.21,0.193
146.80,26.28,0.193
146.80,26.35,0.193
146.81,26.41,0.193
146.82,26.48,0.193
146.83,26.55,0.193
146.83,26.61,0.193
146.84,26.68,0.193
146.85,26.75,0.193
146.85,26.81,0.193
146.86,26.88,0.193
146.87,26.95,0.193
146.87,27.01,0.193
146.88,27.08,0.193
146.88,27.15,0.193
146.89,27.21,0.193
146.90,27.28,0.193
146.90,27.35,0.193
146.91,27.41,0.193
146.92,27.48,0.194
146.93,27.55,0.194
146.93,27.61,0.194
146.94,27.68,0.194
146.95,27.75,
146.95,27.81,
146.96,27.88,
146.97,27.95,
146.97,28.02,
146.98,28.08,
146.98,28.15,
146.99,,
147.00,,