File: DSC/2025_04_24_CBG_Nicotinamide_MC_n60C_150C_5Cmin_x3.csv
Filename,2025_04_24_CBG_Nicotinamide_MC_n60C_150C_5Cmin_x3
Instrument name,DSC2A-00468 (192.168.1.100)
Operator,Yarger
rundate,4/24/2025
Sample name,2025_04_24_CBG_Nicotinamide_MC_n60C_150C_5Cmin_x3
proceduresegments,Data Off ; Equilibrate -60.00 °C; Data On ; Ramp 5.00 °C/min to 150.00 °C; Data Off ; Isothermal 1.0 min; Data On ; Ramp 5.00 °C/min to -60.00 °C; Data Off ; Isothermal 1.0 min; Data On ; Ramp 5.00 °C/min to 150.00 °C; Data Off ; Isothermal 1.0 min; Data On ; Ramp 5.00 °C/min to -60.00 °C; Data Off ; Isothermal 1.0 min; Data On ; Ramp 5.00 °C/min to 150.00 °C
[File Parameters]
Run date,4/24/2025 5:59:22 AM
Trios version,5.1.1.46572
Original File Name,
Current File Name,D:\DSC2500\JYarger\2025_04_24_CBG_Nicotinamide_MC_n60C_150C_5Cmin_x3.tri
[Procedure]
Procedure Name,CBG_NA_n60_150C_5Cmin_x3
Sample Name,2025_04_24_CBG_Nicotinamide_MC_n60C_150C_5Cmin_x3
Sample Mass,6.3 mg
Reference Sample Mass,0 mg
Pan Mass,52.5 mg
Pan Number,34
Reference Pan Mass,52.66 mg
Reference Pan Number,19
Pan Type,Tzero Aluminum Hermetic
Comments,Al Hermetic DSC Consumables sealed Pan/Lid.
Project Name,CA
Operator,Yarger
Test,Custom
Unload Max Temperature,30
Unload Min Temperature,30
Load Max Temperature,30
Load Min Temperature,30
Stop on Gas Flow Error,Yes
[Signal List]
Signal #1,Time (min)
Signal #2,Temperature (°C)
Signal #3,Heat Flow (mW)
Signal #4,Delta T (µV)
Signal #5,Delta Tzero (µV)
Signal #6,Tzero Temperature (°C)
Signal #7,Cell Purge (mL/min)
Signal #8,Heater Temp (°C)
Signal #9,Power Delivered (W)
Signal #10,Reference Junction Temperature (°C)
Signal #11,Flange Temperature (°C)
Signal #12,Heat Flow Phase (rad)
Signal #13,Total Heat Capacity (J/°C)
Signal #14,Heat Capacity (J/°C)
[Configuration]
Company Name,ASU
Instrument Name,DSC2A-00468
Instrument Type,DSC2500
Serial Number,DSC2A-00468
IP,192.168.1.100
Location of Instrument,MRRC
DisplayType,Unknown
Sample Interval ,0.1 s/pt
Selected Heat Flow,T4P
Exotherm Direction,Down
Cell Serial,DRC2-00792
Lid Type,Standard
Cooler,RCS 90
Leave Cooler on at End of Sequence,On
Gas 2,Nitrogen
Gas Selected,Channel 1
Flow Rate,50 mL/min
Secondary Purge,On
Licensed Heat Flow,Heat Flow T4P
Modulation Licensed,Yes
[Versions]
Common IDD Version,1
Cortex Version,VER 2.10.2.31
Driver,5.0.0.6
GDM Version,1.0.3.3
TouchscreenVersion,1.0.0.16145
FEP Version,1.2.1.21
FEP Bootloader,2.0.0.5
AutoSampler Version,2.1.1.26
Auto Sampler Bootloader,2.0.0.5
FCM Version,1.1.0.3
FCM Bootloader,2.0.0.5
[Experiment Logs]
Experiment Log Entry # 1,Data On set to 0
Experiment Log Entry # 3,Equilibrate Segment -60 (C) Started
Experiment Log Entry # 5,Air Cool is off.
Experiment Log Entry # 7,Data On set to 1
Experiment Log Entry # 9,Ramp Segment 5 C/min to 150 Started
Experiment Log Entry # 11,Auto sampler has detected that GDM has gone offline
Experiment Log Entry # 13,Data On set to 0
Experiment Log Entry # 15,Isothermal Segment 1 min started
Experiment Log Entry # 17,Data On set to 1
Experiment Log Entry # 19,Ramp Segment 5 C/min to -60 Started
Experiment Log Entry # 21,Data On set to 0
Experiment Log Entry # 23,Isothermal Segment 1 min started
Experiment Log Entry # 25,Data On set to 1
Experiment Log Entry # 27,Ramp Segment 5 C/min to 150 Started
Experiment Log Entry # 29,Data On set to 0
Experiment Log Entry # 31,Isothermal Segment 1 min started
Experiment Log Entry # 33,Data On set to 1
Experiment Log Entry # 35,Ramp Segment 5 C/min to -60 Started
Experiment Log Entry # 37,Data On set to 0
Experiment Log Entry # 39,Isothermal Segment 1 min started
Experiment Log Entry # 41,Data On set to 1
Experiment Log Entry # 43,Ramp Segment 5 C/min to 150 Started
[Method Log]
Method Log Entry # 1,Data Off
Method Log Entry # 2,Equilibrate -60 °C
Method Log Entry # 3,Data On
Method Log Entry # 4,(Ramp 213492) Ramp 5 °C/minute to 150 °C
Method Log Entry # 5,Data Off
Method Log Entry # 6,Isothermal 1 minutes
Method Log Entry # 7,Data On
Method Log Entry # 8,(Ramp 213496) Ramp 5 °C/minute to -60 °C
Method Log Entry # 9,Data Off
Method Log Entry # 10,Isothermal 1 minutes
Method Log Entry # 11,Data On
Method Log Entry # 12,(Ramp 213500) Ramp 5 °C/minute to 150 °C
Method Log Entry # 13,Data Off
Method Log Entry # 14,Isothermal 1 minutes
Method Log Entry # 15,Data On
Method Log Entry # 16,(Ramp 213504) Ramp 5 °C/minute to -60 °C
Method Log Entry # 17,Data Off
Method Log Entry # 18,Isothermal 1 minutes
Method Log Entry # 19,Data On
Method Log Entry # 20,(Ramp 213508) Ramp 5 °C/minute to 150 °C
Cell Serial,DRC2-00792
[T1 Calibration]
Slope,-0.008529666
Offset,9.636258
Initial Temperature,98.23
GUID,f8bfdadc-4977-4fdf-ba6d-0ba9134940c3
[TZero Calibration]
Date Applied,11/29/2022 4:06:13 PM
Description,From -89.059 °C to 396.009 °C at 20.000°C/min
Gas Type,Nitrogen
Pan Type,None
Source Files 1,C:\Users\yargerlab\Desktop\DSC Data\General\TZero_calibration_11_29_22_2nd(2).tri
Source Files 2,C:\Users\yargerlab\Desktop\DSC Data\General\TZero_calibration_11_29_22_2nd(3).tri
Delta T Offset,13.05235
Delta T Slope,-0.007271007
Delta T0 Offset,-13.69128
Delta T0 Slope,0.06063341
[Temperature Calibration]
Date Applied,11/29/2022 7:12:28 PM
Description,From 106.590 °C to 186.590 °C at 10.000°C/min
Gas Type,Nitrogen
Pan Type,Tzero Aluminum Hermetic
Source Files 1,C:\Users\yargerlab\Desktop\DSC Data\General\Indium(6).tri
Measured 1,157.391
Known 1,156.598
[Cell Constant Calibration]
Date Applied,11/29/2022 7:12:29 PM
Description,From 106.590 °C to 186.590 °C at 10.000°C/min
Gas Type,Nitrogen
Pan Type,Tzero Aluminum Hermetic
Source Files 1,C:\Users\yargerlab\Desktop\DSC Data\General\Indium(6).tri
T4P KCell,1.006051
Onset Slope,63.26126 mW/°C
[Direct Cp Calibration]
Date Applied,11/30/2022 11:04:51 AM
Description,From -79.983 °C to 298.409 °C at 10.000°C/min
Gas Type,Nitrogen
Pan Type,Tzero Aluminum Hermetic
Source Files 1,C:\Users\yargerlab\Desktop\DSC Data\General\Sapphire_Heat_Capacity_11_30_22.tri
[Rev Cp Calibration]
Date Applied,11/30/2022 1:58:51 PM
Description,From -79.996 °C to 292.812 °C at 3.000°C/min
Gas Type,Nitrogen
Pan Type,Tzero Aluminum Hermetic
Source Files 1,C:\Users\yargerlab\Desktop\DSC Data\General\Sapphire_MDSC_Calibration_11_30_22.tri
[step]
Ramp 5.00 °C/min to 150.00 °C
Time,Temperature,Heat Flow (Normalized)
min,°C,W/g
0.00,-59.67,-0.061
0.03,-59.69,-0.060
0.06,-59.69,-0.052
0.08,-59.67,-0.051
0.11,-59.62,-0.050
0.14,-59.55,-0.037
0.17,-59.46,-0.018
0.20,-59.36,0.003
0.23,-59.25,0.021
0.26,-59.13,0.035
0.28,-59.01,0.047
0.31,-58.89,0.054
0.34,-58.76,0.061
0.37,-58.63,0.067
0.40,-58.51,0.071
0.43,-58.37,0.075
0.45,-58.24,0.077
0.48,-58.10,0.080
0.51,-57.97,0.082
0.54,-57.83,0.083
0.57,-57.70,0.084
0.60,-57.56,0.085
0.62,-57.43,0.085
0.65,-57.29,0.086
0.68,-57.15,0.086
0.71,-57.01,0.087
0.74,-56.87,0.087
0.77,-56.74,0.088
0.79,-56.60,0.088
0.82,-56.46,0.089
0.85,-56.32,0.089
0.88,-56.18,0.089
0.91,-56.04,0.090
0.93,-55.90,0.090
0.96,-55.76,0.090
0.99,-55.62,0.090
1.02,-55.48,0.091
1.05,-55.34,0.091
1.08,-55.20,0.091
1.11,-55.06,0.091
1.13,-54.92,0.092
1.16,-54.78,0.092
1.19,-54.64,0.092
1.22,-54.50,0.092
1.25,-54.36,0.092
1.28,-54.22,0.092
1.30,-54.08,0.092
1.33,-53.94,0.093
1.36,-53.80,0.093
1.39,-53.66,0.093
1.42,-53.51,0.093
1.44,-53.37,0.093
1.47,-53.23,0.093
1.50,-53.09,0.093
1.53,-52.95,0.093
1.56,-52.81,0.093
1.59,-52.67,0.093
1.62,-52.53,0.093
1.64,-52.39,0.093
1.67,-52.24,0.093
1.70,-52.10,0.093
1.73,-51.96,0.093
1.76,-51.82,0.093
1.78,-51.68,0.093
1.81,-51.54,0.093
1.84,-51.40,0.093
1.87,-51.26,0.093
1.90,-51.11,0.093
1.93,-50.97,0.093
1.96,-50.83,0.093
1.98,-50.69,0.093
2.01,-50.55,0.093
2.04,-50.41,0.094
2.07,-50.27,0.093
2.10,-50.13,0.094
2.13,-49.98,0.094
2.15,-49.84,0.094
2.18,-49.70,0.094
2.21,-49.56,0.094
2.24,-49.42,0.094
2.27,-49.28,0.094
2.29,-49.13,0.094
2.32,-48.99,0.094
2.35,-48.85,0.094
2.38,-48.71,0.094
2.41,-48.57,0.094
2.44,-48.43,0.094
2.46,-48.29,0.094
2.49,-48.14,0.094
2.52,-48.00,0.094
2.55,-47.86,0.094
2.58,-47.72,0.094
2.61,-47.58,0.094
2.64,-47.44,0.093
2.66,-47.29,0.094
2.69,-47.15,0.094
2.72,-47.01,0.094
2.75,-46.87,0.094
2.78,-46.73,0.094
2.81,-46.59,0.094
2.83,-46.45,0.094
2.86,-46.30,0.094
2.89,-46.16,0.094
2.92,-46.02,0.094
2.95,-45.88,0.094
2.98,-45.74,0.094
3.00,-45.60,0.094
3.03,-45.46,0.094
3.06,-45.31,0.094
3.09,-45.17,0.094
3.12,-45.03,0.094
3.14,-44.89,0.094
3.17,-44.75,0.094
3.20,-44.61,0.094
3.23,-44.46,0.094
3.26,-44.32,0.094
3.29,-44.18,0.094
3.31,-44.04,0.094
3.34,-43.90,0.094
3.37,-43.76,0.094
3.40,-43.61,0.094
3.43,-43.47,0.094
3.46,-43.33,0.094
3.49,-43.19,0.094
3.51,-43.05,0.094
3.54,-42.91,0.094
3.57,-42.76,0.094
3.60,-42.62,0.094
3.63,-42.48,0.094
3.66,-42.34,0.094
3.68,-42.20,0.094
3.71,-42.06,0.094
3.74,-41.91,0.094
3.77,-41.77,0.094
3.80,-41.63,0.094
3.83,-41.49,0.094
3.85,-41.35,0.094
3.88,-41.20,0.094
3.91,-41.06,0.094
3.94,-40.92,0.094
3.97,-40.78,0.094
3.99,-40.64,0.094
4.02,-40.49,0.094
4.05,-40.35,0.094
4.08,-40.21,0.094
4.11,-40.07,0.094
4.14,-39.93,0.094
4.16,-39.79,0.094
4.19,-39.64,0.094
4.22,-39.50,0.094
4.25,-39.36,0.094
4.28,-39.22,0.094
4.31,-39.08,0.094
4.34,-38.93,0.094
4.36,-38.79,0.094
4.39,-38.65,0.094
4.42,-38.51,0.094
4.45,-38.37,0.094
4.48,-38.23,0.094
4.50,-38.08,0.094
4.53,-37.94,0.094
4.56,-37.80,0.094
4.59,-37.66,0.094
4.62,-37.52,0.095
4.65,-37.37,0.095
4.68,-37.23,0.095
4.70,-37.09,0.095
4.73,-36.95,0.095
4.76,-36.81,0.095
4.79,-36.67,0.095
4.82,-36.52,0.095
4.85,-36.38,0.095
4.87,-36.24,0.095
4.90,-36.10,0.095
4.93,-35.96,0.095
4.96,-35.81,0.095
4.99,-35.67,0.095
5.01,-35.53,0.095
5.04,-35.39,0.095
5.07,-35.25,0.095
5.10,-35.11,0.095
5.13,-34.96,0.095
5.16,-34.82,0.095
5.19,-34.68,0.095
5.21,-34.54,0.095
5.24,-34.40,0.095
5.27,-34.26,0.095
5.30,-34.12,0.095
5.33,-33.97,0.095
5.35,-33.83,0.095
5.38,-33.69,0.095
5.41,-33.55,0.095
5.44,-33.40,0.095
5.47,-33.26,0.095
5.50,-33.12,0.095
5.53,-32.98,0.095
5.55,-32.84,0.095
5.58,-32.70,0.096
5.61,-32.55,0.096
5.64,-32.41,0.096
5.67,-32.27,0.096
5.70,-32.13,0.096
5.72,-31.99,0.096
5.75,-31.84,0.096
5.78,-31.70,0.096
5.81,-31.56,0.096
5.84,-31.42,0.096
5.86,-31.28,0.096
5.89,-31.14,0.096
5.92,-30.99,0.096
5.95,-30.85,0.096
5.98,-30.71,0.096
6.01,-30.57,0.096
6.04,-30.43,0.096
6.06,-30.28,0.096
6.09,-30.14,0.097
6.12,-30.00,0.097
6.15,-29.86,0.097
6.18,-29.72,0.097
6.20,-29.58,0.097
6.23,-29.43,0.097
6.26,-29.29,0.097
6.29,-29.15,0.097
6.32,-29.01,0.097
6.35,-28.87,0.097
6.38,-28.72,0.097
6.40,-28.58,0.097
6.43,-28.44,0.097
6.46,-28.30,0.098
6.49,-28.16,0.098
6.52,-28.02,0.098
6.55,-27.87,0.098
6.57,-27.73,0.098
6.60,-27.59,0.098
6.63,-27.45,0.098
6.66,-27.31,0.098
6.69,-27.17,0.098
6.71,-27.02,0.099
6.74,-26.88,0.099
6.77,-26.74,0.099
6.80,-26.60,0.099
6.83,-26.46,0.099
6.86,-26.32,0.099
6.89,-26.17,0.099
6.91,-26.03,0.100
6.94,-25.89,0.100
6.97,-25.75,0.100
7.00,-25.61,0.100
7.03,-25.47,0.100
7.05,-25.32,0.100
7.08,-25.18,0.101
7.11,-25.04,0.101
7.14,-24.90,0.101
7.17,-24.76,0.101
7.20,-24.62,0.102
7.23,-24.48,0.102
7.25,-24.33,0.102
7.28,-24.19,0.102
7.31,-24.05,0.102
7.34,-23.91,0.103
7.37,-23.77,0.103
7.40,-23.62,0.103
7.42,-23.48,0.103
7.45,-23.34,0.104
7.48,-23.20,0.104
7.51,-23.06,0.104
7.54,-22.92,0.104
7.56,-22.77,0.105
7.59,-22.63,0.105
7.62,-22.49,0.105
7.65,-22.35,0.105
7.68,-22.21,0.106
7.71,-22.06,0.106
7.74,-21.92,0.106
7.76,-21.78,0.106
7.79,-21.64,0.106
7.82,-21.50,0.106
7.85,-21.35,0.107
7.88,-21.21,0.107
7.90,-21.07,0.107
7.93,-20.93,0.107
7.96,-20.79,0.107
7.99,-20.65,0.107
8.02,-20.51,0.107
8.05,-20.36,0.107
8.08,-20.22,0.107
8.10,-20.08,0.107
8.13,-19.94,0.107
8.16,-19.80,0.107
8.19,-19.66,0.107
8.22,-19.51,0.107
8.25,-19.37,0.107
8.27,-19.23,0.107
8.30,-19.09,0.107
8.33,-18.94,0.107
8.36,-18.80,0.107
8.39,-18.66,0.107
8.41,-18.52,0.107
8.44,-18.38,0.107
8.47,-18.24,0.107
8.50,-18.10,0.107
8.53,-17.95,0.107
8.56,-17.81,0.107
8.58,-17.67,0.107
8.61,-17.53,0.107
8.64,-17.39,0.107
8.67,-17.25,0.107
8.70,-17.11,0.107
8.73,-16.96,0.107
8.75,-16.82,0.107
8.78,-16.68,0.107
8.81,-16.54,0.107
8.84,-16.39,0.107
8.87,-16.25,0.107
8.90,-16.11,0.107
8.93,-15.97,0.107
8.95,-15.83,0.107
8.98,-15.69,0.107
9.01,-15.54,0.107
9.04,-15.40,0.107
9.07,-15.26,0.107
9.10,-15.12,0.107
9.12,-14.98,0.107
9.15,-14.83,0.107
9.18,-14.69,0.107
9.21,-14.55,0.107
9.24,-14.41,0.107
9.27,-14.27,0.107
9.29,-14.12,0.107
9.32,-13.98,0.107
9.35,-13.84,0.107
9.38,-13.70,0.108
9.41,-13.56,0.108
9.43,-13.42,0.108
9.46,-13.28,0.108
9.49,-13.13,0.108
9.52,-12.99,0.108
9.55,-12.85,0.108
9.58,-12.71,0.108
9.60,-12.57,0.108
9.63,-12.43,0.108
9.66,-12.28,0.108
9.69,-12.14,0.108
9.72,-12.00,0.108
9.75,-11.86,0.108
9.78,-11.72,0.108
9.80,-11.57,0.108
9.83,-11.43,0.108
9.86,-11.29,0.108
9.89,-11.15,0.108
9.92,-11.01,0.108
9.95,-10.86,0.108
9.97,-10.72,0.108
10.00,-10.58,0.108
10.03,-10.44,0.108
10.06,-10.30,0.108
10.09,-10.16,0.109
10.12,-10.02,0.109
10.14,-9.87,0.109
10.17,-9.73,0.109
10.20,-9.59,0.109
10.23,-9.45,0.109
10.26,-9.30,0.109
10.28,-9.16,0.109
10.31,-9.02,0.109
10.34,-8.88,0.109
10.37,-8.74,0.109
10.40,-8.60,0.109
10.43,-8.46,0.109
10.45,-8.31,0.109
10.48,-8.17,0.109
10.51,-8.03,0.109
10.54,-7.89,0.109
10.57,-7.75,0.109
10.60,-7.61,0.109
10.63,-7.46,0.109
10.65,-7.32,0.109
10.68,-7.18,0.109
10.71,-7.04,0.109
10.74,-6.90,0.109
10.77,-6.75,0.109
10.80,-6.61,0.109
10.82,-6.47,0.110
10.85,-6.33,0.110
10.88,-6.19,0.110
10.91,-6.04,0.110
10.94,-5.90,0.110
10.97,-5.76,0.110
10.99,-5.62,0.110
11.02,-5.48,0.110
11.05,-5.34,0.110
11.08,-5.19,0.110
11.11,-5.05,0.110
11.13,-4.91,0.110
11.16,-4.77,0.110
11.19,-4.63,0.110
11.22,-4.49,0.110
11.25,-4.34,0.110
11.28,-4.20,0.110
11.30,-4.06,0.110
11.33,-3.92,0.110
11.36,-3.78,0.110
11.39,-3.63,0.110
11.42,-3.49,0.110
11.45,-3.35,0.110
11.48,-3.21,0.110
11.50,-3.07,0.110
11.53,-2.93,0.110
11.56,-2.78,0.111
11.59,-2.64,0.111
11.62,-2.50,0.111
11.65,-2.36,0.111
11.67,-2.22,0.111
11.70,-2.08,0.111
11.73,-1.93,0.111
11.76,-1.79,0.111
11.79,-1.65,0.111
11.82,-1.51,0.111
11.84,-1.37,0.111
11.87,-1.22,0.111
11.90,-1.08,0.111
11.93,-0.94,0.111
11.96,-0.80,0.111
11.98,-0.66,0.111
12.01,-0.52,0.111
12.04,-0.37,0.111
12.07,-0.23,0.111
12.10,-0.09,0.111
12.13,0.05,0.111
12.15,0.19,0.111
12.18,0.33,0.111
12.21,0.48,0.111
12.24,0.62,0.111
12.27,0.76,0.111
12.30,0.90,0.111
12.33,1.04,0.111
12.35,1.19,0.112
12.38,1.33,0.112
12.41,1.47,0.112
12.44,1.61,0.112
12.47,1.75,0.112
12.50,1.89,0.112
12.52,2.04,0.112
12.55,2.18,0.112
12.58,2.32,0.112
12.61,2.46,0.112
12.64,2.60,0.112
12.67,2.75,0.112
12.69,2.89,0.112
12.72,3.03,0.112
12.75,3.17,0.112
12.78,3.31,0.112
12.81,3.45,0.112
12.83,3.60,0.112
12.86,3.74,0.112
12.89,3.88,0.112
12.92,4.02,0.112
12.95,4.16,0.112
12.98,4.30,0.112
13.00,4.45,0.112
13.03,4.59,0.112
13.06,4.73,0.112
13.09,4.87,0.112
13.12,5.01,0.112
13.15,5.15,0.112
13.18,5.30,0.112
13.20,5.44,0.112
13.23,5.58,0.112
13.26,5.72,0.112
13.29,5.86,0.112
13.32,6.01,0.113
13.35,6.15,0.113
13.37,6.29,0.113
13.40,6.43,0.113
13.43,6.57,0.113
13.46,6.71,0.113
13.49,6.86,0.113
13.52,7.00,0.113
13.54,7.14,0.113
13.57,7.28,0.113
13.60,7.42,0.113
13.63,7.56,0.113
13.66,7.71,0.113
13.68,7.85,0.113
13.71,7.99,0.113
13.74,8.13,0.113
13.77,8.27,0.113
13.80,8.42,0.113
13.83,8.56,0.113
13.85,8.70,0.113
13.88,8.84,0.113
13.91,8.98,0.113
13.94,9.12,0.113
13.97,9.27,0.113
14.00,9.41,0.113
14.03,9.55,0.113
14.05,9.69,0.113
14.08,9.83,0.113
14.11,9.98,0.113
14.14,10.12,0.113
14.17,10.26,0.113
14.20,10.40,0.113
14.22,10.54,0.113
14.25,10.68,0.113
14.28,10.83,0.113
14.31,10.97,0.113
14.34,11.11,0.113
14.37,11.25,0.113
14.39,11.39,0.113
14.42,11.53,0.113
14.45,11.68,0.113
14.48,11.82,0.113
14.51,11.96,0.113
14.53,12.10,0.113
14.56,12.24,0.113
14.59,12.39,0.113
14.62,12.53,0.113
14.65,12.67,0.113
14.68,12.81,0.113
14.70,12.95,0.113
14.73,13.10,0.113
14.76,13.24,0.113
14.79,13.38,0.114
14.82,13.52,0.114
14.85,13.66,0.114
14.88,13.80,0.114
14.90,13.94,0.114
14.93,14.09,0.114
14.96,14.23,0.114
14.99,14.37,0.114
15.02,14.51,0.114
15.05,14.65,0.114
15.07,14.80,0.114
15.10,14.94,0.114
15.13,15.08,0.114
15.16,15.22,0.114
15.19,15.36,0.114
15.22,15.50,0.114
15.24,15.65,0.114
15.27,15.79,0.114
15.30,15.93,0.114
15.33,16.07,0.114
15.36,16.21,0.114
15.38,16.35,0.114
15.41,16.50,0.114
15.44,16.64,0.114
15.47,16.78,0.114
15.50,16.92,0.114
15.53,17.06,0.115
15.55,17.21,0.115
15.58,17.35,0.115
15.61,17.49,0.115
15.64,17.63,0.115
15.67,17.77,0.115
15.70,17.91,0.115
15.73,18.06,0.115
15.75,18.20,0.115
15.78,18.34,0.115
15.81,18.48,0.115
15.84,18.62,0.115
15.87,18.77,0.115
15.90,18.91,0.115
15.92,19.05,0.115
15.95,19.19,0.116
15.98,19.33,0.116
16.01,19.47,0.116
16.04,19.61,0.116
16.07,19.76,0.116
16.09,19.90,0.116
16.12,20.04,0.116
16.15,20.18,0.116
16.18,20.32,0.116
16.21,20.46,0.116
16.23,20.61,0.116
16.26,20.75,0.116
16.29,20.89,0.117
16.32,21.03,0.117
16.35,21.17,0.117
16.38,21.31,0.117
16.40,21.46,0.117
16.43,21.60,0.117
16.46,21.74,0.117
16.49,21.88,0.117
16.52,22.02,0.118
16.55,22.17,0.118
16.58,22.31,0.118
16.60,22.45,0.118
16.63,22.59,0.118
16.66,22.73,0.118
16.69,22.87,0.119
16.72,23.02,0.119
16.75,23.16,0.119
16.77,23.30,0.119
16.80,23.44,0.119
16.83,23.58,0.120
16.86,23.72,0.120
16.89,23.87,0.120
16.92,24.01,0.120
16.94,24.15,0.120
16.97,24.29,0.121
17.00,24.43,0.121
17.03,24.57,0.121
17.06,24.72,0.121
17.08,24.86,0.121
17.11,25.00,0.122
17.14,25.14,0.122
17.17,25.28,0.122
17.20,25.42,0.123
17.23,25.57,0.123
17.26,25.71,0.123
17.28,25.85,0.124
17.31,25.99,0.124
17.34,26.13,0.124
17.37,26.27,0.125
17.40,26.41,0.125
17.43,26.56,0.126
17.45,26.70,0.126
17.48,26.84,0.127
17.51,26.98,0.127
17.54,27.12,0.127
17.57,27.26,0.128
17.59,27.40,0.129
17.62,27.55,0.130
17.65,27.69,0.131
17.68,27.83,0.132
17.71,27.97,0.133
17.74,28.11,0.134
17.77,28.25,0.135
17.79,28.39,0.136
17.82,28.53,0.138
17.85,28.68,0.139
17.88,28.82,0.141
17.91,28.96,0.142
17.93,29.10,0.144
17.96,29.24,0.145
17.99,29.38,0.145
18.02,29.53,0.146
18.05,29.67,0.147
18.08,29.81,0.147
18.11,29.95,0.148
18.13,30.09,0.149
18.16,30.23,0.149
18.19,30.37,0.150
18.22,30.52,0.151
18.25,30.66,0.152
18.28,30.80,0.153
18.30,30.94,0.153
18.33,31.08,0.154
18.36,31.22,0.156
18.39,31.36,0.158
18.42,31.50,0.159
18.44,31.64,0.161
18.47,31.79,0.163
18.50,31.93,0.164
18.53,32.07,0.166
18.56,32.21,0.168
18.59,32.35,0.170
18.62,32.49,0.172
18.64,32.63,0.174
18.67,32.77,0.176
18.70,32.91,0.177
18.73,33.06,0.179
18.76,33.20,0.181
18.78,33.34,0.183
18.81,33.48,0.185
18.84,33.62,0.188
18.87,33.76,0.189
18.90,33.90,0.192
18.93,34.04,0.194
18.96,34.18,0.197
18.98,34.32,0.199
19.01,34.46,0.202
19.04,34.60,0.203
19.07,34.74,0.207
19.10,34.88,0.210
19.13,35.02,0.214
19.15,35.17,0.217
19.18,35.31,0.221
19.21,35.45,0.225
19.24,35.59,0.229
19.27,35.73,0.234
19.29,35.87,0.238
19.32,36.01,0.243
19.35,36.15,0.248
19.38,36.28,0.253
19.41,36.42,0.260
19.44,36.56,0.264
19.47,36.70,0.269
19.49,36.84,0.276
19.52,36.98,0.282
19.55,37.12,0.288
19.58,37.26,0.295
19.61,37.40,0.301
19.63,37.54,0.307
19.66,37.68,0.314
19.69,37.82,0.321
19.72,37.95,0.327
19.75,38.09,0.333
19.78,38.23,0.341
19.81,38.37,0.347
19.83,38.51,0.353
19.86,38.65,0.360
19.89,38.79,0.367
19.92,38.93,0.372
19.95,39.07,0.378
19.98,39.20,0.385
20.00,39.34,0.392
20.03,39.48,0.397
20.06,39.62,0.402
20.09,39.76,0.408
20.12,39.90,0.414
20.14,40.04,0.420
20.17,40.18,0.425
20.20,40.32,0.429
20.23,40.46,0.434
20.26,40.60,0.439
20.29,40.74,0.444
20.32,40.87,0.448
20.34,41.01,0.452
20.37,41.15,0.456
20.40,41.29,0.460
20.43,41.43,0.464
20.46,41.57,0.467
20.48,41.71,0.471
20.51,41.86,0.474
20.54,41.99,0.477
20.57,42.13,0.482
20.60,42.27,0.484
20.63,42.41,0.487
20.66,42.55,0.490
20.68,42.70,0.494
20.71,42.84,0.497
20.74,42.98,0.501
20.77,43.12,0.503
20.80,43.26,0.507
20.83,43.40,0.511
20.85,43.54,0.515
20.88,43.68,0.518
20.91,43.82,0.522
20.94,43.96,0.526
20.97,44.10,0.531
20.99,44.24,0.536
21.02,44.38,0.540
21.05,44.52,0.546
21.08,44.66,0.551
21.11,44.80,0.558
21.14,44.94,0.564
21.17,45.07,0.571
21.19,45.21,0.588
21.22,45.35,0.594
21.25,45.49,0.609
21.28,45.62,0.613
21.31,45.76,0.617
21.33,45.90,0.621
21.36,46.04,0.628
21.39,46.18,0.636
21.42,46.32,0.643
21.45,46.46,0.661
21.48,46.59,0.688
21.51,46.73,0.700
21.53,46.86,0.715
21.56,47.00,0.726
21.59,47.13,0.732
21.62,47.27,0.738
21.65,47.41,0.751
21.68,47.55,0.753
21.70,47.69,0.756
21.73,47.83,0.758
21.76,47.97,0.758
21.79,48.11,0.758
21.82,48.25,0.749
21.84,48.39,0.740
21.87,48.54,0.741
21.90,48.68,0.741
21.93,48.82,0.735
21.96,48.97,0.705
21.99,49.12,0.660
22.02,49.28,0.607
22.04,49.44,0.552
22.07,49.60,0.501
22.10,49.77,0.453
22.13,49.93,0.408
22.16,50.09,0.368
22.18,50.25,0.330
22.21,50.41,0.299
22.24,50.57,0.272
22.27,50.72,0.250
22.30,50.88,0.232
22.33,51.03,0.219
22.36,51.18,0.209
22.38,51.33,0.201
22.41,51.47,0.195
22.44,51.62,0.192
22.47,51.76,0.188
22.50,51.91,0.186
22.53,52.05,0.184
22.55,52.19,0.183
22.58,52.33,0.182
22.61,52.48,0.182
22.64,52.62,0.181
22.67,52.76,0.180
22.69,52.90,0.180
22.72,53.05,0.180
22.75,53.19,0.179
22.78,53.33,0.179
22.81,53.47,0.179
22.84,53.61,0.179
22.87,53.75,0.178
22.89,53.90,0.178
22.92,54.04,0.178
22.95,54.18,0.178
22.98,54.32,0.178
23.01,54.47,0.178
23.03,54.61,0.177
23.06,54.75,0.177
23.09,54.89,0.177
23.12,55.03,0.177
23.15,55.17,0.177
23.18,55.32,0.177
23.21,55.46,0.177
23.23,55.60,0.177
23.26,55.74,0.177
23.29,55.88,0.177
23.32,56.02,0.177
23.35,56.17,0.177
23.38,56.31,0.178
23.40,56.45,0.178
23.43,56.59,0.178
23.46,56.73,0.178
23.49,56.87,0.178
23.52,57.02,0.178
23.54,57.16,0.178
23.57,57.30,0.178
23.60,57.44,0.178
23.63,57.58,0.178
23.66,57.72,0.178
23.69,57.86,0.178
23.72,58.01,0.178
23.74,58.15,0.178
23.77,58.29,0.178
23.80,58.43,0.178
23.83,58.57,0.178
23.86,58.72,0.179
23.88,58.86,0.179
23.91,59.00,0.179
23.94,59.14,0.179
23.97,59.28,0.179
24.00,59.42,0.179
24.03,59.57,0.179
24.06,59.71,0.179
24.08,59.85,0.179
24.11,59.99,0.179
24.14,60.13,0.179
24.17,60.27,0.180
24.20,60.42,0.180
24.23,60.56,0.180
24.25,60.70,0.180
24.28,60.84,0.180
24.31,60.98,0.180
24.34,61.13,0.180
24.37,61.27,0.180
24.39,61.41,0.180
24.42,61.55,0.180
24.45,61.69,0.180
24.48,61.83,0.181
24.51,61.98,0.181
24.54,62.12,0.181
24.57,62.26,0.181
24.59,62.40,0.181
24.62,62.54,0.181
24.65,62.68,0.181
24.68,62.83,0.181
24.71,62.97,0.181
24.73,63.11,0.181
24.76,63.25,0.182
24.79,63.39,0.182
24.82,63.53,0.182
24.85,63.68,0.182
24.88,63.82,0.182
24.91,63.96,0.182
24.93,64.10,0.182
24.96,64.24,0.182
24.99,64.38,0.182
25.02,64.53,0.182
25.05,64.67,0.183
25.08,64.81,0.183
25.10,64.95,0.183
25.13,65.10,0.183
25.16,65.24,0.183
25.19,65.38,0.183
25.22,65.52,0.183
25.24,65.66,0.183
25.27,65.80,0.183
25.30,65.94,0.183
25.33,66.09,0.183
25.36,66.23,0.184
25.39,66.37,0.184
25.42,66.51,0.184
25.44,66.65,0.184
25.47,66.80,0.184
25.50,66.94,0.184
25.53,67.08,0.184
25.56,67.22,0.184
25.58,67.36,0.184
25.61,67.50,0.184
25.64,67.65,0.184
25.67,67.79,0.184
25.70,67.93,0.184
25.73,68.07,0.184
25.76,68.21,0.185
25.78,68.35,0.185
25.81,68.50,0.185
25.84,68.64,0.185
25.87,68.78,0.185
25.90,68.92,0.185
25.93,69.06,0.185
25.95,69.20,0.185
25.98,69.34,0.185
26.01,69.49,0.185
26.04,69.63,0.185
26.07,69.77,0.186
26.09,69.91,0.186
26.12,70.05,0.186
26.15,70.20,0.186
26.18,70.34,0.186
26.21,70.48,0.186
26.24,70.62,0.186
26.27,70.76,0.186
26.29,70.90,0.186
26.32,71.05,0.186
26.35,71.19,0.186
26.38,71.33,0.186
26.41,71.47,0.187
26.43,71.61,0.187
26.46,71.75,0.187
26.49,71.90,0.187
26.52,72.04,0.187
26.55,72.18,0.187
26.58,72.32,0.187
26.61,72.46,0.187
26.63,72.60,0.187
26.66,72.75,0.187
26.69,72.89,0.187
26.72,73.03,0.187
26.75,73.17,0.187
26.78,73.31,0.188
26.80,73.46,0.188
26.83,73.60,0.188
26.86,73.74,0.188
26.89,73.88,0.188
26.92,74.02,0.188
26.94,74.17,0.188
26.97,74.31,0.188
27.00,74.45,0.189
27.03,74.59,0.189
27.06,74.73,0.189
27.09,74.87,0.189
27.12,75.01,0.189
27.14,75.16,0.189
27.17,75.30,0.189
27.20,75.44,0.189
27.23,75.58,0.189
27.26,75.72,0.189
27.28,75.86,0.189
27.31,76.01,0.190
27.34,76.15,0.190
27.37,76.29,0.190
27.40,76.43,0.190
27.43,76.57,0.190
27.46,76.72,0.190
27.48,76.86,0.191
27.51,77.00,0.191
27.54,77.14,0.191
27.57,77.28,0.191
27.60,77.42,0.191
27.63,77.56,0.191
27.65,77.70,0.191
27.68,77.84,0.191
27.71,77.99,0.192
27.74,78.13,0.192
27.77,78.27,0.192
27.79,78.41,0.192
27.82,78.55,0.192
27.85,78.70,0.193
27.88,78.84,0.193
27.91,78.98,0.193
27.94,79.12,0.193
27.97,79.26,0.193
27.99,79.40,0.193
28.02,79.55,0.194
28.05,79.69,0.194
28.08,79.83,0.194
28.11,79.97,0.194
28.13,80.12,0.194
28.16,80.26,0.195
28.19,80.40,0.195
28.22,80.54,0.195
28.25,80.69,0.195
28.28,80.83,0.195
28.31,80.97,0.195
28.33,81.11,0.195
28.36,81.25,0.195
28.39,81.39,0.195
28.42,81.54,0.195
28.45,81.68,0.195
28.48,81.82,0.195
28.50,81.96,0.196
28.53,82.10,0.196
28.56,82.24,0.196
28.59,82.38,0.196
28.62,82.53,0.196
28.64,82.67,0.196
28.67,82.81,0.196
28.70,82.95,0.196
28.73,83.09,0.196
28.76,83.23,0.196
28.79,83.38,0.197
28.82,83.52,0.197
28.84,83.66,0.197
28.87,83.80,0.197
28.90,83.94,0.197
28.93,84.08,0.197
28.96,84.23,0.197
28.98,84.37,0.197
29.01,84.51,0.198
29.04,84.65,0.198
29.07,84.79,0.198
29.10,84.93,0.198
29.13,85.07,0.198
29.16,85.22,0.198
29.18,85.36,0.199
29.21,85.50,0.199
29.24,85.64,0.199
29.27,85.78,0.199
29.30,85.92,0.199
29.33,86.07,0.199
29.35,86.21,0.200
29.38,86.35,0.200
29.41,86.49,0.200
29.44,86.63,0.200
29.47,86.78,0.200
29.49,86.92,0.200
29.52,87.06,0.201
29.55,87.20,0.201
29.58,87.34,0.201
29.61,87.48,0.201
29.64,87.62,0.201
29.67,87.77,0.201
29.69,87.91,0.202
29.72,88.05,0.202
29.75,88.19,0.202
29.78,88.33,0.202
29.81,88.47,0.202
29.83,88.62,0.202
29.86,88.76,0.203
29.89,88.90,0.203
29.92,89.04,0.203
29.95,89.18,0.203
29.98,89.33,0.203
30.01,89.47,0.204
30.03,89.61,0.204
30.06,89.75,0.204
30.09,89.89,0.204
30.12,90.03,0.204
30.15,90.17,0.205
30.18,90.32,0.205
30.20,90.46,0.205
30.23,90.60,0.205
30.26,90.74,0.205
30.29,90.88,0.206
30.32,91.02,0.206
30.34,91.17,0.206
30.37,91.31,0.206
30.40,91.45,0.206
30.43,91.59,0.207
30.46,91.73,0.207
30.49,91.88,0.207
30.52,92.02,0.207
30.54,92.16,0.208
30.57,92.30,0.208
30.60,92.44,0.208
30.63,92.58,0.208
30.66,92.72,0.208
30.68,92.87,0.209
30.71,93.01,0.209
30.74,93.15,0.209
30.77,93.29,0.209
30.80,93.43,0.209
30.83,93.58,0.210
30.86,93.72,0.210
30.88,93.86,0.210
30.91,94.00,0.210
30.94,94.14,0.211
30.97,94.28,0.211
31.00,94.43,0.211
31.03,94.57,0.211
31.05,94.71,0.211
31.08,94.85,0.212
31.11,94.99,0.212
31.14,95.13,0.212
31.17,95.28,0.212
31.19,95.42,0.213
31.22,95.56,0.213
31.25,95.70,0.213
31.28,95.84,0.213
31.31,95.98,0.214
31.34,96.13,0.214
31.37,96.27,0.214
31.39,96.41,0.214
31.42,96.55,0.215
31.45,96.69,0.215
31.48,96.83,0.215
31.51,96.97,0.215
31.53,97.12,0.215
31.56,97.26,0.216
31.59,97.40,0.216
31.62,97.54,0.216
31.65,97.68,0.216
31.68,97.82,0.217
31.71,97.97,0.217
31.73,98.11,0.217
31.76,98.25,0.217
31.79,98.39,0.218
31.82,98.53,0.218
31.85,98.68,0.218
31.88,98.82,0.219
31.90,98.96,0.219
31.93,99.10,0.219
31.96,99.24,0.219
31.99,99.38,0.220
32.02,99.52,0.220
32.04,99.67,0.220
32.07,99.81,0.220
32.10,99.95,0.220
32.13,100.09,0.221
32.16,100.23,0.221
32.19,100.37,0.221
32.22,100.52,0.221
32.24,100.66,0.222
32.27,100.80,0.222
32.30,100.94,0.222
32.33,101.08,0.222
32.36,101.22,0.223
32.38,101.37,0.223
32.41,101.51,0.223
32.44,101.65,0.223
32.47,101.79,0.224
32.50,101.93,0.224
32.53,102.07,0.224
32.56,102.21,0.225
32.58,102.36,0.225
32.61,102.50,0.225
32.64,102.64,0.225
32.67,102.78,0.225
32.70,102.92,0.225
32.73,103.06,0.226
32.75,103.21,0.226
32.78,103.35,0.226
32.81,103.49,0.226
32.84,103.63,0.226
32.87,103.77,0.227
32.89,103.92,0.227
32.92,104.06,0.227
32.95,104.20,0.227
32.98,104.34,0.227
33.01,104.48,0.228
33.04,104.62,0.228
33.07,104.77,0.228
33.09,104.91,0.228
33.12,105.05,0.228
33.15,105.19,0.228
33.18,105.33,0.229
33.21,105.47,0.229
33.23,105.62,0.229
33.26,105.76,0.229
33.29,105.90,0.229
33.32,106.04,0.229
33.35,106.18,0.229
33.38,106.32,0.229
33.41,106.47,0.229
33.43,106.61,0.229
33.46,106.75,0.229
33.49,106.89,0.229
33.52,107.03,0.229
33.55,107.18,0.229
33.58,107.32,0.229
33.60,107.46,0.229
33.63,107.60,0.229
33.66,107.74,0.229
33.69,107.88,0.229
33.72,108.03,0.229
33.74,108.17,0.229
33.77,108.31,0.229
33.80,108.45,0.229
33.83,108.60,0.229
33.86,108.74,0.229
33.89,108.88,0.228
33.92,109.02,0.228
33.94,109.16,0.228
33.97,109.30,0.228
34.00,109.45,0.227
34.03,109.59,0.227
34.06,109.73,0.227
34.08,109.87,0.226
34.11,110.01,0.226
34.14,110.15,0.226
34.17,110.30,0.225
34.20,110.44,0.225
34.23,110.58,0.225
34.26,110.72,0.224
34.28,110.86,0.224
34.31,111.01,0.223
34.34,111.15,0.223
34.37,111.29,0.222
34.40,111.43,0.222
34.43,111.57,0.221
34.45,111.71,0.220
34.48,111.86,0.220
34.51,112.00,0.219
34.54,112.14,0.219
34.57,112.28,0.218
34.59,112.42,0.218
34.62,112.57,0.217
34.65,112.71,0.217
34.68,112.85,0.216
34.71,112.99,0.215
34.74,113.14,0.215
34.76,113.28,0.214
34.79,113.42,0.213
34.82,113.56,0.213
34.85,113.70,0.212
34.88,113.85,0.211
34.91,113.99,0.210
34.94,114.13,0.209
34.96,114.27,0.208
34.99,114.41,0.207
35.02,114.56,0.207
35.05,114.70,0.206
35.08,114.84,0.205
35.11,114.98,0.204
35.13,115.12,0.203
35.16,115.27,0.202
35.19,115.41,0.202
35.22,115.55,0.200
35.25,115.69,0.199
35.28,115.83,0.198
35.30,115.98,0.198
35.33,116.12,0.197
35.36,116.26,0.196
35.39,116.40,0.195
35.42,116.54,0.195
35.44,116.69,0.194
35.47,116.83,0.193
35.50,116.97,0.193
35.53,117.11,0.192
35.56,117.25,0.191
35.59,117.40,0.191
35.61,117.54,0.190
35.64,117.68,0.190
35.67,117.82,0.189
35.70,117.96,0.189
35.73,118.11,0.188
35.76,118.25,0.188
35.79,118.39,0.188
35.81,118.53,0.187
35.84,118.67,0.187
35.87,118.82,0.186
35.90,118.96,0.186
35.93,119.10,0.186
35.96,119.24,0.185
35.98,119.38,0.185
36.01,119.52,0.185
36.04,119.67,0.184
36.07,119.81,0.184
36.10,119.95,0.184
36.13,120.09,0.183
36.15,120.23,0.183
36.18,120.38,0.183
36.21,120.52,0.183
36.24,120.66,0.183
36.27,120.80,0.183
36.29,120.94,0.182
36.32,121.08,0.182
36.35,121.23,0.182
36.38,121.37,0.182
36.41,121.51,0.182
36.44,121.65,0.181
36.46,121.79,0.181
36.49,121.94,0.181
36.52,122.08,0.181
36.55,122.22,0.181
36.58,122.36,0.181
36.61,122.50,0.180
36.64,122.64,0.180
36.66,122.79,0.180
36.69,122.93,0.180
36.72,123.07,0.180
36.75,123.21,0.179
36.78,123.35,0.179
36.81,123.50,0.179
36.83,123.64,0.179
36.86,123.78,0.179
36.89,123.92,0.179
36.92,124.06,0.178
36.95,124.20,0.178
36.98,124.34,0.178
37.00,124.49,0.178
37.03,124.63,0.178
37.06,124.77,0.177
37.09,124.91,0.177
37.12,125.05,0.177
37.14,125.19,0.177
37.17,125.34,0.177
37.20,125.48,0.176
37.23,125.62,0.176
37.26,125.76,0.176
37.29,125.90,0.176
37.31,126.05,0.176
37.34,126.19,0.176
37.37,126.33,0.175
37.40,126.47,0.175
37.43,126.61,0.175
37.46,126.76,0.175
37.49,126.90,0.175
37.51,127.04,0.175
37.54,127.18,0.174
37.57,127.32,0.174
37.60,127.47,0.174
37.63,127.61,0.174
37.66,127.75,0.173
37.68,127.89,0.173
37.71,128.03,0.173
37.74,128.17,0.173
37.77,128.32,0.172
37.80,128.46,0.172
37.83,128.60,0.172
37.85,128.74,0.172
37.88,128.88,0.172
37.91,129.03,0.171
37.94,129.17,0.171
37.97,129.31,0.171
37.99,129.45,0.171
38.02,129.59,0.171
38.05,129.73,0.171
38.08,129.88,0.171
38.11,130.02,0.170
38.14,130.16,0.170
38.16,130.30,0.170
38.19,130.44,0.170
38.22,130.59,0.170
38.25,130.73,0.170
38.28,130.87,0.169
38.31,131.01,0.169
38.34,131.15,0.169
38.36,131.29,0.169
38.39,131.44,0.169
38.42,131.58,0.169
38.45,131.72,0.169
38.48,131.86,0.168
38.51,132.00,0.168
38.53,132.14,0.168
38.56,132.29,0.168
38.59,132.43,0.168
38.62,132.57,0.168
38.65,132.71,0.168
38.68,132.85,0.167
38.70,132.99,0.167
38.73,133.14,0.167
38.76,133.28,0.167
38.79,133.42,0.167
38.82,133.56,0.167
38.84,133.70,0.167
38.87,133.85,0.167
38.90,133.99,0.167
38.93,134.13,0.167
38.96,134.27,0.166
38.99,134.41,0.166
39.01,134.55,0.166
39.04,134.70,0.166
39.07,134.84,0.166
39.10,134.98,0.166
39.13,135.12,0.166
39.16,135.26,0.166
39.19,135.41,0.166
39.21,135.55,0.166
39.24,135.69,0.166
39.27,135.83,0.166
39.30,135.97,0.166
39.33,136.11,0.166
39.36,136.25,0.165
39.38,136.40,0.165
39.41,136.54,0.165
39.44,136.68,0.165
39.47,136.82,0.165
39.50,136.96,0.165
39.53,137.10,0.165
39.55,137.25,0.165
39.58,137.39,0.165
39.61,137.53,0.165
39.64,137.67,0.165
39.67,137.81,0.165
39.69,137.96,0.165
39.72,138.10,0.165
39.75,138.24,0.165
39.78,138.38,0.165
39.81,138.52,0.165
39.84,138.66,0.165
39.86,138.81,0.165
39.89,138.95,0.165
39.92,139.09,0.165
39.95,139.23,0.165
39.98,139.37,0.165
40.01,139.51,0.165
40.04,139.66,0.165
40.06,139.80,0.165
40.09,139.94,0.165
40.12,140.08,0.165
40.15,140.22,0.165
40.18,140.36,0.165
40.21,140.51,0.165
40.23,140.65,0.165
40.26,140.79,0.165
40.29,140.93,0.165
40.32,141.07,0.165
40.35,141.21,0.166
40.38,141.36,0.166
40.40,141.50,0.166
40.43,141.64,0.166
40.46,141.78,0.166
40.49,141.92,0.166
40.52,142.07,0.166
40.54,142.21,0.166
40.57,142.35,0.166
40.60,142.49,0.166
40.63,142.63,0.166
40.66,142.77,0.166
40.69,142.91,0.166
40.71,143.06,0.166
40.74,143.20,0.166
40.77,143.34,0.166
40.80,143.48,0.167
40.83,143.62,0.167
40.86,143.77,0.167
40.89,143.91,0.167
40.91,144.05,0.167
40.94,144.19,0.167
40.97,144.33,0.167
41.00,144.47,0.167
41.03,144.62,0.168
41.06,144.76,0.168
41.08,144.90,0.168
41.11,145.04,0.168
41.14,145.18,0.168
41.17,145.32,0.168
41.20,145.47,0.168
41.23,145.61,0.168
41.25,145.75,0.169
41.28,145.89,0.169
41.31,146.03,0.169
41.34,146.17,0.169
41.37,146.32,0.169
41.39,146.46,0.169
41.42,146.60,0.170
41.45,146.74,0.170
41.48,146.88,0.170
41.51,147.02,0.170
41.54,147.16,0.170
41.56,147.31,0.170
41.59,147.45,0.170
41.62,147.59,0.170
41.65,147.73,0.171
41.68,147.87,0.171
41.71,148.01,0.171
41.74,148.16,0.171
41.76,148.30,0.171
41.79,148.44,0.172
41.82,148.58,0.172
41.85,148.72,0.172
41.88,148.86,0.172
41.91,149.01,0.172
41.93,149.15,
41.96,149.29,
41.99,,

[step]
Ramp 5.00 °C/min to -60.00 °C
Time,Temperature,Heat Flow (Normalized)
min,°C,W/g
42.99,150.12,-0.047
43.01,150.12,-0.047
43.04,150.11,-0.047
43.07,150.09,-0.046
43.10,150.04,-0.064
43.13,149.97,-0.099
43.16,149.88,-0.140
43.19,149.78,-0.175
43.21,149.66,-0.199
43.24,149.54,-0.215
43.27,149.42,-0.228
43.30,149.29,-0.237
43.33,149.16,-0.244
43.36,149.03,-0.249
43.38,148.89,-0.252
43.41,148.76,-0.255
43.44,148.62,-0.257
43.47,148.48,-0.258
43.50,148.34,-0.259
43.53,148.20,-0.260
43.55,148.06,-0.261
43.58,147.93,-0.261
43.61,147.79,-0.261
43.64,147.65,-0.262
43.67,147.51,-0.262
43.69,147.37,-0.262
43.72,147.23,-0.262
43.75,147.09,-0.263
43.78,146.95,-0.263
43.81,146.80,-0.263
43.84,146.66,-0.264
43.86,146.52,-0.264
43.89,146.38,-0.264
43.92,146.24,-0.264
43.95,146.10,-0.264
43.98,145.96,-0.264
44.01,145.82,-0.264
44.04,145.68,-0.264
44.06,145.54,-0.264
44.09,145.40,-0.264
44.12,145.25,-0.264
44.15,145.11,-0.264
44.18,144.97,-0.264
44.21,144.83,-0.264
44.23,144.69,-0.264
44.26,144.55,-0.264
44.29,144.41,-0.264
44.32,144.27,-0.264
44.35,144.13,-0.263
44.38,143.98,-0.263
44.40,143.84,-0.263
44.43,143.70,-0.263
44.46,143.56,-0.263
44.49,143.42,-0.263
44.52,143.28,-0.263
44.54,143.13,-0.262
44.57,143.00,-0.262
44.60,142.85,-0.262
44.63,142.71,-0.262
44.66,142.57,-0.262
44.69,142.43,-0.262
44.71,142.29,-0.262
44.74,142.15,-0.261
44.77,142.00,-0.261
44.80,141.86,-0.261
44.83,141.72,-0.261
44.86,141.58,-0.261
44.89,141.44,-0.261
44.91,141.30,-0.261
44.94,141.16,-0.261
44.97,141.01,-0.261
45.00,140.87,-0.260
45.03,140.73,-0.260
45.06,140.59,-0.260
45.08,140.45,-0.260
45.11,140.31,-0.260
45.14,140.16,-0.260
45.17,140.02,-0.260
45.20,139.88,-0.260
45.23,139.74,-0.259
45.25,139.60,-0.259
45.28,139.46,-0.259
45.31,139.32,-0.259
45.34,139.17,-0.259
45.37,139.03,-0.259
45.39,138.89,-0.259
45.42,138.75,-0.259
45.45,138.61,-0.259
45.48,138.47,-0.259
45.51,138.32,-0.258
45.54,138.18,-0.258
45.56,138.04,-0.258
45.59,137.90,-0.258
45.62,137.76,-0.258
45.65,137.62,-0.258
45.68,137.47,-0.257
45.71,137.33,-0.257
45.74,137.19,-0.257
45.76,137.05,-0.257
45.79,136.91,-0.257
45.82,136.77,-0.257
45.85,136.63,-0.257
45.88,136.48,-0.257
45.91,136.34,-0.257
45.93,136.20,-0.257
45.96,136.06,-0.257
45.99,135.92,-0.257
46.02,135.78,-0.256
46.05,135.63,-0.256
46.08,135.49,-0.256
46.10,135.35,-0.256
46.13,135.21,-0.256
46.16,135.07,-0.256
46.19,134.93,-0.256
46.22,134.78,-0.256
46.24,134.64,-0.256
46.27,134.50,-0.255
46.30,134.36,-0.255
46.33,134.22,-0.255
46.36,134.08,-0.255
46.39,133.94,-0.255
46.41,133.79,-0.255
46.44,133.65,-0.255
46.47,133.51,-0.255
46.50,133.37,-0.255
46.53,133.23,-0.255
46.56,133.08,-0.255
46.59,132.94,-0.255
46.61,132.80,-0.255
46.64,132.66,-0.255
46.67,132.52,-0.255
46.70,132.38,-0.254
46.73,132.24,-0.254
46.76,132.09,-0.254
46.78,131.95,-0.254
46.81,131.81,-0.254
46.84,131.67,-0.254
46.87,131.53,-0.254
46.90,131.39,-0.254
46.93,131.24,-0.254
46.95,131.10,-0.254
46.98,130.96,-0.254
47.01,130.82,-0.254
47.04,130.68,-0.254
47.07,130.54,-0.253
47.09,130.39,-0.254
47.12,130.25,-0.253
47.15,130.11,-0.253
47.18,129.97,-0.253
47.21,129.83,-0.253
47.24,129.69,-0.253
47.26,129.54,-0.253
47.29,129.40,-0.253
47.32,129.26,-0.253
47.35,129.12,-0.253
47.38,128.98,-0.253
47.41,128.84,-0.252
47.44,128.70,-0.252
47.46,128.56,-0.252
47.49,128.41,-0.252
47.52,128.27,-0.252
47.55,128.13,-0.252
47.58,127.99,-0.252
47.61,127.85,-0.252
47.63,127.71,-0.252
47.66,127.56,-0.252
47.69,127.42,-0.252
47.72,127.28,-0.252
47.75,127.14,-0.252
47.78,127.00,-0.252
47.80,126.86,-0.252
47.83,126.72,-0.252
47.86,126.57,-0.252
47.89,126.43,-0.252
47.92,126.29,-0.252
47.94,126.15,-0.252
47.97,126.01,-0.252
48.00,125.87,-0.252
48.03,125.73,-0.251
48.06,125.58,-0.251
48.09,125.44,-0.251
48.11,125.30,-0.251
48.14,125.16,-0.251
48.17,125.02,-0.251
48.20,124.87,-0.251
48.23,124.73,-0.251
48.26,124.59,-0.251
48.29,124.45,-0.251
48.31,124.31,-0.251
48.34,124.17,-0.251
48.37,124.02,-0.251
48.40,123.88,-0.251
48.43,123.74,-0.251
48.46,123.60,-0.251
48.48,123.46,-0.251
48.51,123.32,-0.251
48.54,123.17,-0.250
48.57,123.03,-0.250
48.60,122.89,-0.250
48.63,122.75,-0.250
48.65,122.61,-0.250
48.68,122.47,-0.250
48.71,122.32,-0.250
48.74,122.18,-0.250
48.77,122.04,-0.250
48.79,121.90,-0.250
48.82,121.76,-0.250
48.85,121.62,-0.250
48.88,121.48,-0.250
48.91,121.33,-0.250
48.94,121.19,-0.250
48.96,121.05,-0.250
48.99,120.91,-0.250
49.02,120.77,-0.250
49.05,120.63,-0.249
49.08,120.49,-0.249
49.11,120.34,-0.249
49.14,120.20,-0.249
49.16,120.06,-0.249
49.19,119.92,-0.249
49.22,119.78,-0.249
49.25,119.64,-0.249
49.28,119.49,-0.249
49.31,119.35,-0.249
49.33,119.21,-0.249
49.36,119.07,-0.249
49.39,118.93,-0.249
49.42,118.79,-0.249
49.45,118.64,-0.249
49.48,118.50,-0.249
49.50,118.36,-0.249
49.53,118.22,-0.249
49.56,118.08,-0.249
49.59,117.94,-0.249
49.62,117.80,-0.249
49.64,117.65,-0.249
49.67,117.51,-0.248
49.70,117.37,-0.248
49.73,117.23,-0.248
49.76,117.09,-0.248
49.79,116.95,-0.248
49.81,116.80,-0.248
49.84,116.66,-0.248
49.87,116.52,-0.248
49.90,116.38,-0.248
49.93,116.24,-0.248
49.96,116.10,-0.248
49.99,115.96,-0.248
50.01,115.81,-0.248
50.04,115.67,-0.248
50.07,115.53,-0.248
50.10,115.39,-0.248
50.13,115.25,-0.248
50.16,115.10,-0.248
50.18,114.96,-0.248
50.21,114.82,-0.248
50.24,114.68,-0.248
50.27,114.54,-0.248
50.30,114.39,-0.248
50.33,114.25,-0.247
50.35,114.11,-0.247
50.38,113.97,-0.247
50.41,113.83,-0.247
50.44,113.69,-0.247
50.47,113.55,-0.247
50.49,113.40,-0.247
50.52,113.26,-0.247
50.55,113.12,-0.246
50.58,112.98,-0.246
50.61,112.84,-0.246
50.64,112.70,-0.246
50.66,112.56,-0.246
50.69,112.41,-0.246
50.72,112.27,-0.246
50.75,112.13,-0.246
50.78,111.99,-0.246
50.81,111.85,-0.246
50.84,111.71,-0.246
50.86,111.56,-0.246
50.89,111.42,-0.246
50.92,111.28,-0.246
50.95,111.14,-0.246
50.98,111.00,-0.246
51.01,110.86,-0.246
51.03,110.72,-0.246
51.06,110.57,-0.246
51.09,110.43,-0.246
51.12,110.29,-0.246
51.15,110.15,-0.246
51.18,110.01,-0.246
51.20,109.87,-0.245
51.23,109.73,-0.245
51.26,109.58,-0.245
51.29,109.44,-0.245
51.32,109.30,-0.245
51.34,109.16,-0.245
51.37,109.02,-0.245
51.40,108.88,-0.245
51.43,108.73,-0.245
51.46,108.59,-0.245
51.49,108.45,-0.245
51.51,108.31,-0.245
51.54,108.17,-0.245
51.57,108.03,-0.245
51.60,107.88,-0.245
51.63,107.74,-0.245
51.66,107.60,-0.245
51.69,107.46,-0.245
51.71,107.32,-0.245
51.74,107.18,-0.245
51.77,107.03,-0.245
51.80,106.89,-0.245
51.83,106.75,-0.245
51.86,106.61,-0.245
51.88,106.47,-0.245
51.91,106.33,-0.245
51.94,106.18,-0.245
51.97,106.04,-0.244
52.00,105.90,-0.244
52.03,105.76,-0.244
52.05,105.62,-0.244
52.08,105.48,-0.244
52.11,105.34,-0.244
52.14,105.19,-0.244
52.17,105.05,-0.244
52.19,104.91,-0.244
52.22,104.77,-0.244
52.25,104.63,-0.244
52.28,104.49,-0.244
52.31,104.34,-0.244
52.34,104.20,-0.244
52.36,104.06,-0.244
52.39,103.92,-0.244
52.42,103.78,-0.244
52.45,103.64,-0.244
[...]
184.63,2.45,0.157
184.65,2.59,0.157
184.68,2.73,0.157
184.71,2.87,0.157
184.74,3.02,0.157
184.77,3.16,0.157
184.80,3.30,0.157
184.82,3.44,0.157
184.85,3.58,0.157
184.88,3.72,0.157
184.91,3.87,0.157
184.94,4.01,0.157
184.97,4.15,0.157
184.99,4.29,0.157
185.02,4.43,0.157
185.05,4.58,0.157
185.08,4.72,0.157
185.11,4.86,0.158
185.13,5.00,0.158
185.16,5.14,0.158
185.19,5.28,0.158
185.22,5.43,0.158
185.25,5.57,0.158
185.28,5.71,0.158
185.30,5.85,0.158
185.33,5.99,0.158
185.36,6.13,0.158
185.39,6.28,0.158
185.42,6.42,0.158
185.45,6.56,0.158
185.48,6.70,0.158
185.50,6.84,0.158
185.53,6.99,0.158
185.56,7.13,0.158
185.59,7.27,0.158
185.62,7.41,0.158
185.65,7.55,0.158
185.67,7.69,0.158
185.70,7.84,0.158
185.73,7.98,0.158
185.76,8.12,0.158
185.79,8.26,0.158
185.82,8.40,0.158
185.84,8.54,0.158
185.87,8.69,0.158
185.90,8.83,0.158
185.93,8.97,0.159
185.96,9.11,0.159
185.98,9.25,0.159
186.01,9.39,0.159
186.04,9.54,0.159
186.07,9.68,0.159
186.10,9.82,0.159
186.13,9.96,0.159
186.15,10.10,0.159
186.18,10.25,0.159
186.21,10.39,0.159
186.24,10.53,0.159
186.27,10.67,0.159
186.30,10.81,0.159
186.33,10.96,0.159
186.35,11.10,0.159
186.38,11.24,0.159
186.41,11.38,0.159
186.44,11.52,0.159
186.47,11.66,0.159
186.50,11.81,0.160
186.52,11.95,0.160
186.55,12.09,0.160
186.58,12.23,0.160
186.61,12.37,0.160
186.64,12.51,0.160
186.67,12.66,0.160
186.69,12.80,0.160
186.72,12.94,0.160
186.75,13.08,0.160
186.78,13.22,0.160
186.81,13.37,0.160
186.83,13.51,0.160
186.86,13.65,0.160
186.89,13.79,0.160
186.92,13.93,0.160
186.95,14.08,0.160
186.98,14.22,0.160
187.00,14.36,0.160
187.03,14.50,0.160
187.06,14.64,0.160
187.09,14.78,0.160
187.12,14.93,0.161
187.15,15.07,0.161
187.18,15.21,0.161
187.20,15.35,0.161
187.23,15.49,0.161
187.26,15.64,0.161
187.29,15.78,0.161
187.32,15.92,0.161
187.35,16.06,0.161
187.37,16.20,0.161
187.40,16.34,0.161
187.43,16.48,0.161
187.46,16.63,0.161
187.49,16.77,0.161
187.52,16.91,0.161
187.54,17.05,0.161
187.57,17.19,0.161
187.60,17.33,0.161
187.63,17.47,0.161
187.66,17.62,0.161
187.68,17.76,0.161
187.71,17.90,0.161
187.74,18.04,0.161
187.77,18.18,0.162
187.80,18.33,0.162
187.83,18.47,0.162
187.85,18.61,0.162
187.88,18.75,0.162
187.91,18.89,0.162
187.94,19.04,0.162
187.97,19.18,0.162
188.00,19.32,0.162
188.03,19.46,0.162
188.05,19.60,0.162
188.08,19.74,0.162
188.11,19.89,0.162
188.14,20.03,0.162
188.17,20.17,0.162
188.20,20.31,0.162
188.22,20.45,0.162
188.25,20.60,0.162
188.28,20.74,0.162
188.31,20.88,0.162
188.34,21.02,0.163
188.37,21.16,0.163
188.39,21.31,0.163
188.42,21.45,0.163
188.45,21.59,0.163
188.48,21.73,0.163
188.51,21.87,0.163
188.53,22.01,0.163
188.56,22.16,0.163
188.59,22.30,0.163
188.62,22.44,0.163
188.65,22.58,0.163
188.68,22.72,0.163
188.70,22.86,0.163
188.73,23.01,0.163
188.76,23.15,0.163
188.79,23.29,0.163
188.82,23.43,0.163
188.85,23.57,0.164
188.88,23.72,0.164
188.90,23.86,0.164
188.93,24.00,0.164
188.96,24.14,0.164
188.99,24.28,0.164
189.02,24.42,0.164
189.05,24.56,0.164
189.07,24.71,0.164
189.10,24.85,0.164
189.13,24.99,0.164
189.16,25.13,0.164
189.19,25.27,0.164
189.22,25.42,0.164
189.24,25.56,0.164
189.27,25.70,0.164
189.30,25.84,0.164
189.33,25.98,0.164
189.36,26.12,0.164
189.38,26.27,0.164
189.41,26.41,0.164
189.44,26.55,0.164
189.47,26.69,0.165
189.50,26.83,0.165
189.53,26.97,0.165
189.55,27.12,0.165
189.58,27.26,0.165
189.61,27.40,0.165
189.64,27.54,0.165
189.67,27.68,0.165
189.70,27.82,0.165
189.73,27.97,0.165
189.75,28.11,0.165
189.78,28.25,0.165
189.81,28.39,0.165
189.84,28.53,0.165
189.87,28.68,0.165
189.90,28.82,0.165
189.92,28.96,0.165
189.95,29.10,0.165
189.98,29.24,0.166
190.01,29.38,0.166
190.04,29.53,0.166
190.07,29.67,0.166
190.09,29.81,0.166
190.12,29.95,0.166
190.15,30.09,0.166
190.18,30.24,0.166
190.21,30.38,0.166
190.23,30.52,0.166
190.26,30.66,0.166
190.29,30.80,0.166
190.32,30.94,0.166
190.35,31.09,0.166
190.38,31.23,0.166
190.40,31.37,0.166
190.43,31.51,0.166
190.46,31.65,0.166
190.49,31.79,0.166
190.52,31.94,0.166
190.55,32.08,0.166
190.58,32.22,0.167
190.60,32.36,0.167
190.63,32.50,0.167
190.66,32.65,0.167
190.69,32.79,0.167
190.72,32.93,0.167
190.75,33.07,0.167
190.77,33.21,0.167
190.80,33.36,0.167
190.83,33.50,0.167
190.86,33.64,0.167
190.89,33.78,0.167
190.92,33.92,0.167
190.94,34.06,0.167
190.97,34.20,0.167
191.00,34.35,0.167
191.03,34.49,0.167
191.06,34.63,0.167
191.08,34.77,0.167
191.11,34.91,0.167
191.14,35.05,0.167
191.17,35.20,0.167
191.20,35.34,0.167
191.23,35.48,0.167
191.25,35.62,0.167
191.28,35.76,0.168
191.31,35.90,0.168
191.34,36.05,0.168
191.37,36.19,0.168
191.40,36.33,0.168
191.43,36.47,0.168
191.45,36.61,0.168
191.48,36.76,0.168
191.51,36.90,0.168
191.54,37.04,0.168
191.57,37.18,0.168
191.60,37.32,0.168
191.62,37.47,0.168
191.65,37.61,0.168
191.68,37.75,0.168
191.71,37.89,0.168
191.74,38.03,0.169
191.77,38.17,0.169
191.79,38.32,0.169
191.82,38.46,0.169
191.85,38.60,0.169
191.88,38.74,0.169
191.91,38.88,0.169
191.93,39.03,0.169
191.96,39.17,0.169
191.99,39.31,0.169
192.02,39.45,0.169
192.05,39.59,0.169
192.08,39.73,0.169
192.10,39.87,0.169
192.13,40.02,0.169
192.16,40.16,0.169
192.19,40.30,0.169
192.22,40.44,0.169
192.25,40.58,0.169
192.28,40.72,0.169
192.30,40.87,0.169
192.33,41.01,0.169
192.36,41.15,0.169
192.39,41.29,0.169
192.42,41.43,0.169
192.45,41.58,0.170
192.47,41.72,0.170
192.50,41.86,0.170
192.53,42.00,0.170
192.56,42.14,0.170
192.59,42.29,0.170
192.62,42.43,0.170
192.64,42.57,0.170
192.67,42.71,0.170
192.70,42.85,0.170
192.73,42.99,0.170
192.76,43.14,0.170
192.78,43.28,0.170
192.81,43.42,0.170
192.84,43.56,0.170
192.87,43.70,0.170
192.90,43.84,0.170
192.93,43.98,0.170
192.95,44.13,0.170
192.98,44.27,0.170
193.01,44.41,0.170
193.04,44.55,0.170
193.07,44.69,0.171
193.10,44.84,0.171
193.13,44.98,0.171
193.15,45.12,0.171
193.18,45.26,0.171
193.21,45.40,0.171
193.24,45.55,0.171
193.27,45.69,0.171
193.30,45.83,0.171
193.32,45.97,0.171
193.35,46.11,0.171
193.38,46.25,0.171
193.41,46.40,0.171
193.44,46.54,0.171
193.47,46.68,0.171
193.49,46.82,0.171
193.52,46.96,0.171
193.55,47.11,0.171
193.58,47.25,0.171
193.61,47.39,0.171
193.63,47.53,0.171
193.66,47.67,0.171
193.69,47.81,0.171
193.72,47.96,0.171
193.75,48.10,0.172
193.78,48.24,0.172
193.80,48.38,0.172
193.83,48.52,0.172
193.86,48.66,0.172
193.89,48.81,0.172
193.92,48.95,0.172
193.95,49.09,0.172
193.98,49.23,0.172
194.00,49.37,0.172
194.03,49.52,0.172
194.06,49.66,0.172
194.09,49.80,0.172
194.12,49.94,0.172
194.15,50.08,0.172
194.17,50.23,0.172
194.20,50.37,0.172
194.23,50.51,0.172
194.26,50.65,0.172
194.29,50.79,0.172
194.32,50.93,0.172
194.34,51.08,0.172
194.37,51.22,0.173
194.40,51.36,0.173
194.43,51.50,0.173
194.46,51.64,0.173
194.48,51.78,0.173
194.51,51.93,0.173
194.54,52.07,0.173
194.57,52.21,0.173
194.60,52.35,0.173
194.63,52.49,0.173
194.65,52.63,0.173
194.68,52.78,0.173
194.71,52.92,0.173
194.74,53.06,0.173
194.77,53.20,0.173
194.80,53.34,0.173
194.83,53.48,0.173
194.85,53.63,0.173
194.88,53.77,0.173
194.91,53.91,0.173
194.94,54.05,0.173
194.97,54.19,0.173
195.00,54.34,0.173
195.02,54.48,0.173
195.05,54.62,0.173
195.08,54.76,0.173
195.11,54.90,0.173
195.14,55.04,0.173
195.17,55.19,0.174
195.19,55.33,0.174
195.22,55.47,0.174
195.25,55.61,0.174
195.28,55.75,0.174
195.31,55.89,0.174
195.33,56.03,0.174
195.36,56.18,0.174
195.39,56.32,0.174
195.42,56.46,0.174
195.45,56.60,0.174
195.48,56.74,0.174
195.50,56.89,0.174
195.53,57.03,0.174
195.56,57.17,0.174
195.59,57.31,0.174
195.62,57.45,0.174
195.65,57.59,0.174
195.68,57.74,0.174
195.70,57.88,0.174
195.73,58.02,0.174
195.76,58.16,0.174
195.79,58.30,0.174
195.82,58.45,0.175
195.85,58.59,0.175
195.87,58.73,0.175
195.90,58.87,0.175
195.93,59.01,0.175
195.96,59.15,0.175
195.99,59.29,0.175
196.02,59.44,0.175
196.04,59.58,0.175
196.07,59.72,0.175
196.10,59.86,0.175
196.13,60.00,0.175
196.16,60.15,0.175
196.18,60.29,0.175
196.21,60.43,0.175
196.24,60.57,0.175
196.27,60.71,0.175
196.30,60.86,0.175
196.33,61.00,0.175
196.35,61.14,0.175
196.38,61.28,0.175
196.41,61.42,0.175
196.44,61.56,0.175
196.47,61.70,0.175
196.50,61.85,0.175
196.53,61.99,0.175
196.55,62.13,0.175
196.58,62.27,0.175
196.61,62.41,0.175
196.64,62.56,0.175
196.67,62.70,0.175
196.70,62.84,0.176
196.72,62.98,0.176
196.75,63.12,0.176
196.78,63.26,0.176
196.81,63.41,0.176
196.84,63.55,0.176
196.87,63.69,0.176
196.89,63.83,0.176
196.92,63.97,0.176
196.95,64.11,0.176
196.98,64.26,0.176
197.01,64.40,0.176
197.03,64.54,0.176
197.06,64.68,0.176
197.09,64.82,0.176
197.12,64.97,0.176
197.15,65.11,0.176
197.18,65.25,0.176
197.20,65.39,0.176
197.23,65.53,0.176
197.26,65.67,0.176
197.29,65.82,0.176
197.32,65.96,0.176
197.35,66.10,0.176
197.38,66.24,0.177
197.40,66.38,0.177
197.43,66.52,0.177
197.46,66.67,0.177
197.49,66.81,0.177
197.52,66.95,0.177
197.55,67.09,0.177
197.57,67.23,0.177
197.60,67.37,0.177
197.63,67.52,0.177
197.66,67.66,0.177
197.69,67.80,0.177
197.72,67.94,0.177
197.74,68.08,0.177
197.77,68.22,0.177
197.80,68.37,0.177
197.83,68.51,0.177
197.86,68.65,0.177
197.88,68.79,0.177
197.91,68.93,0.177
197.94,69.08,0.177
197.97,69.22,0.177
198.00,69.36,0.177
198.03,69.50,0.177
198.05,69.64,0.178
198.08,69.78,0.178
198.11,69.93,0.178
198.14,70.07,0.178
198.17,70.21,0.178
198.20,70.35,0.178
198.23,70.49,0.178
198.25,70.64,0.178
198.28,70.78,0.178
198.31,70.92,0.178
198.34,71.06,0.178
198.37,71.20,0.178
198.40,71.34,0.178
198.42,71.49,0.178
198.45,71.63,0.178
198.48,71.77,0.178
198.51,71.91,0.178
198.54,72.05,0.178
198.57,72.19,0.178
198.59,72.34,0.178
198.62,72.48,0.178
198.65,72.62,0.178
198.68,72.76,0.178
198.71,72.90,0.178
198.73,73.04,0.178
198.76,73.19,0.178
198.79,73.33,0.178
198.82,73.47,0.178
198.85,73.61,0.178
198.88,73.75,0.178
198.90,73.90,0.178
198.93,74.04,0.179
198.96,74.18,0.179
198.99,74.32,0.179
199.02,74.46,0.179
199.05,74.60,0.179
199.08,74.75,0.179
199.10,74.89,0.179
199.13,75.03,0.179
199.16,75.17,0.179
199.19,75.31,0.179
199.22,75.46,0.179
199.25,75.60,0.179
199.27,75.74,0.179
199.30,75.88,0.179
199.33,76.02,0.179
199.36,76.16,0.179
199.39,76.31,0.179
199.42,76.45,0.179
199.44,76.59,0.179
199.47,76.73,0.179
199.50,76.87,0.180
199.53,77.02,0.180
199.56,77.16,0.180
199.58,77.30,0.180
199.61,77.44,0.180
199.64,77.58,0.180
199.67,77.72,0.180
199.70,77.87,0.180
199.73,78.01,0.180
199.75,78.15,0.180
199.78,78.29,0.180
199.81,78.43,0.180
199.84,78.57,0.180
199.87,78.72,0.180
199.90,78.86,0.180
199.93,79.00,0.180
199.95,79.14,0.180
199.98,79.29,0.180
200.01,79.43,0.180
200.04,79.57,0.180
200.07,79.71,0.180
200.10,79.85,0.180
200.12,79.99,0.180
200.15,80.13,0.180
200.18,80.28,0.180
200.21,80.42,0.180
200.24,80.56,0.180
200.27,80.70,0.180
200.29,80.84,0.180
200.32,80.98,0.180
200.35,81.13,0.180
200.38,81.27,0.180
200.41,81.41,0.180
200.43,81.55,0.180
200.46,81.69,0.180
200.49,81.83,0.180
200.52,81.98,0.180
200.55,82.12,0.180
200.58,82.26,0.180
200.60,82.40,0.180
200.63,82.54,0.180
200.66,82.68,0.180
200.69,82.83,0.180
200.72,82.97,0.180
200.75,83.11,0.180
200.78,83.25,0.180
200.80,83.39,0.180
200.83,83.53,0.180
200.86,83.67,0.180
200.89,83.82,0.180
200.92,83.96,0.180
200.95,84.10,0.180
200.97,84.24,0.180
201.00,84.38,0.180
201.03,84.53,0.180
201.06,84.67,0.180
201.09,84.81,0.180
201.12,84.95,0.180
201.14,85.09,0.180
201.17,85.23,0.180
201.20,85.38,0.181
201.23,85.52,0.181
201.26,85.66,0.181
201.28,85.80,0.181
201.31,85.94,0.181
201.34,86.09,0.181
201.37,86.23,0.181
201.40,86.37,0.181
201.43,86.51,0.181
201.45,86.65,0.181
201.48,86.80,0.181
201.51,86.94,0.181
201.54,87.08,0.181
201.57,87.22,0.181
201.60,87.36,0.181
201.63,87.51,0.181
201.65,87.65,0.181
201.68,87.79,0.181
201.71,87.93,0.181
201.74,88.07,0.181
201.77,88.21,0.181
201.80,88.35,0.181
201.82,88.50,0.181
201.85,88.64,0.181
201.88,88.78,0.181
201.91,88.92,0.181
201.94,89.06,0.181
201.97,89.20,0.181
201.99,89.35,0.181
202.02,89.49,0.181
202.05,89.63,0.181
202.08,89.77,0.181
202.11,89.91,0.182
202.13,90.05,0.182
202.16,90.20,0.182
202.19,90.34,0.182
202.22,90.48,0.182
202.25,90.62,0.182
202.28,90.76,0.182
202.30,90.90,0.182
202.33,91.05,0.182
202.36,91.19,0.182
202.39,91.33,0.182
202.42,91.47,0.182
202.45,91.61,0.182
202.48,91.75,0.182
202.50,91.90,0.182
202.53,92.04,0.182
202.56,92.18,0.182
202.59,92.32,0.182
202.62,92.46,0.182
202.65,92.61,0.182
202.67,92.75,0.182
202.70,92.89,0.183
202.73,93.03,0.183
202.76,93.17,0.183
202.79,93.31,0.183
202.82,93.46,0.183
202.84,93.60,0.183
202.87,93.74,0.183
202.90,93.88,0.183
202.93,94.02,0.183
202.96,94.16,0.183
202.98,94.31,0.183
203.01,94.45,0.183
203.04,94.59,0.183
203.07,94.73,0.183
203.10,94.87,0.183
203.13,95.01,0.183
203.15,95.16,0.183
203.18,95.30,0.183
203.21,95.44,0.183
203.24,95.58,0.183
203.27,95.72,0.183
203.30,95.86,0.183
203.33,96.01,0.183
203.35,96.15,0.183
203.38,96.29,0.183
203.41,96.43,0.183
203.44,96.57,0.183
203.47,96.71,0.183
203.50,96.86,0.183
203.52,97.00,0.184
203.55,97.14,0.184
203.58,97.28,0.184
203.61,97.42,0.184
203.64,97.57,0.184
203.67,97.71,0.184
203.69,97.85,0.184
203.72,97.99,0.184
203.75,98.13,0.184
203.78,98.27,0.184
203.81,98.42,0.184
203.83,98.56,0.184
203.86,98.70,0.184
203.89,98.84,0.184
203.92,98.98,0.184
203.95,99.12,0.184
203.98,99.27,0.184
204.00,99.41,0.184
204.03,99.55,0.184
204.06,99.69,0.184
204.09,99.83,0.184
204.12,99.98,0.184
204.15,100.12,0.184
204.18,100.26,0.184
204.20,100.40,0.184
204.23,100.54,0.184
204.26,100.68,0.184
204.29,100.83,0.184
204.32,100.97,0.185
204.35,101.11,0.185
204.37,101.25,0.185
204.40,101.39,0.185
204.43,101.53,0.185
204.46,101.68,0.185
204.49,101.82,0.185
204.52,101.96,0.185
204.54,102.10,0.185
204.57,102.24,0.185
204.60,102.39,0.185
204.63,102.53,0.185
204.66,102.67,0.185
204.68,102.81,0.185
204.71,102.95,0.185
204.74,103.09,0.185
204.77,103.23,0.185
204.80,103.38,0.185
204.83,103.52,0.185
204.85,103.66,0.185
204.88,103.80,0.185
204.91,103.94,0.185
204.94,104.08,0.185
204.97,104.23,0.185
205.00,104.37,0.185
205.03,104.51,0.185
205.05,104.65,0.185
205.08,104.79,0.185
205.11,104.93,0.185
205.14,105.08,0.185
205.17,105.22,0.185
205.20,105.36,0.185
205.22,105.50,0.185
205.25,105.64,0.185
205.28,105.79,0.185
205.31,105.93,0.185
205.34,106.07,0.186
205.37,106.21,0.186
205.39,106.35,0.186
205.42,106.49,0.186
205.45,106.64,0.186
205.48,106.78,0.186
205.51,106.92,0.186
205.53,107.06,0.186
205.56,107.20,0.186
205.59,107.35,0.186
205.62,107.49,0.186
205.65,107.63,0.186
205.68,107.77,0.186
205.70,107.91,0.186
205.73,108.05,0.186
205.76,108.20,0.186
205.79,108.34,0.186
205.82,108.48,0.186
205.85,108.62,0.186
205.88,108.76,0.186
205.90,108.90,0.186
205.93,109.04,0.186
205.96,109.19,0.186
205.99,109.33,0.186
206.02,109.47,0.186
206.05,109.61,0.186
206.07,109.75,0.186
206.10,109.90,0.186
206.13,110.04,0.186
206.16,110.18,0.186
206.19,110.32,0.186
206.22,110.46,0.186
206.24,110.61,0.186
206.27,110.75,0.186
206.30,110.89,0.186
206.33,111.03,0.186
206.36,111.17,0.186
206.38,111.31,0.186
206.41,111.45,0.186
206.44,111.60,0.186
206.47,111.74,0.186
206.50,111.88,0.186
206.53,112.02,0.186
206.55,112.16,0.187
206.58,112.31,0.187
206.61,112.45,0.187
206.64,112.59,0.187
206.67,112.73,0.187
206.70,112.87,0.187
206.73,113.01,0.187
206.75,113.16,0.187
206.78,113.30,0.187
206.81,113.44,0.187
206.84,113.58,0.187
206.87,113.72,0.187
206.90,113.86,0.187
206.92,114.01,0.187
206.95,114.15,0.187
206.98,114.29,0.187
207.01,114.43,0.187
207.04,114.57,0.187
207.07,114.71,0.187
207.09,114.86,0.187
207.12,115.00,0.187
207.15,115.14,0.187
207.18,115.28,0.187
207.21,115.42,0.187
207.23,115.56,0.187
207.26,115.71,0.187
207.29,115.85,0.187
207.32,115.99,0.187
207.35,116.13,0.187
207.38,116.27,0.187
207.40,116.42,0.188
207.43,116.56,0.188
207.46,116.70,0.188
207.49,116.84,0.188
207.52,116.98,0.188
207.55,117.12,0.188
207.58,117.27,0.188
207.60,117.41,0.188
207.63,117.55,0.188
207.66,117.69,0.188
207.69,117.83,0.188
207.72,117.98,0.188
207.75,118.12,0.188
207.77,118.26,0.188
207.80,118.40,0.188
207.83,118.54,0.188
207.86,118.68,0.188
207.89,118.82,0.188
207.92,118.97,0.188
207.94,119.11,0.188
207.97,119.25,0.188
208.00,119.39,0.188
208.03,119.53,0.188
208.06,119.68,0.188
208.08,119.82,0.188
208.11,119.96,0.188
208.14,120.10,0.188
208.17,120.24,0.188
208.20,120.38,0.188
208.23,120.52,0.188
208.25,120.67,0.188
208.28,120.81,0.188
208.31,120.95,0.188
208.34,121.09,0.188
208.37,121.23,0.188
208.40,121.37,0.188
208.43,121.52,0.188
208.45,121.66,0.188
208.48,121.80,0.188
208.51,121.94,0.188
208.54,122.08,0.188
208.57,122.23,0.188
208.60,122.37,0.188
208.62,122.51,0.188
208.65,122.65,0.188
208.68,122.79,0.188
208.71,122.94,0.188
208.74,123.08,0.188
208.77,123.22,0.189
208.79,123.36,0.189
208.82,123.50,0.189
208.85,123.65,0.189
208.88,123.79,0.189
208.91,123.93,0.189
208.93,124.07,0.189
208.96,124.21,0.189
208.99,124.35,0.189
209.02,124.49,0.189
209.05,124.64,0.189
209.08,124.78,0.189
209.10,124.92,0.189
209.13,125.06,0.189
209.16,125.20,0.189
209.19,125.34,0.189
209.22,125.49,0.189
209.25,125.63,0.189
209.28,125.77,0.189
209.30,125.91,0.189
209.33,126.05,0.189
209.36,126.19,0.189
209.39,126.34,0.189
209.42,126.48,0.189
209.45,126.62,0.189
209.47,126.76,0.189
209.50,126.90,0.189
209.53,127.04,0.189
209.56,127.19,0.189
209.59,127.33,0.189
209.62,127.47,0.189
209.64,127.61,0.189
209.67,127.75,0.189
209.70,127.89,0.189
209.73,128.04,0.189
209.76,128.18,0.189
209.78,128.32,0.189
209.81,128.46,0.189
209.84,128.60,0.189
209.87,128.75,0.189
209.90,128.89,0.189
209.93,129.03,0.189
209.95,129.17,0.189
209.98,129.31,0.189
210.01,129.45,0.189
210.04,129.60,0.189
210.07,129.74,0.189
210.10,129.88,0.189
210.13,130.02,0.189
210.15,130.16,0.189
210.18,130.30,0.189
210.21,130.45,0.189
210.24,130.59,0.189
210.27,130.73,0.189
210.30,130.87,0.189
210.32,131.01,0.189
210.35,131.15,0.189
210.38,131.30,0.190
210.41,131.44,0.189
210.44,131.58,0.190
210.47,131.72,0.190
210.49,131.86,0.190
210.52,132.00,0.190
210.55,132.15,0.190
210.58,132.29,0.190
210.61,132.43,0.190
210.63,132.57,0.190
210.66,132.71,0.190
210.69,132.85,0.190
210.72,133.00,0.190
210.75,133.14,0.190
210.78,133.28,0.190
210.80,133.42,0.190
210.83,133.56,0.190
210.86,133.71,0.190
210.89,133.85,0.190
210.92,133.99,0.190
210.95,134.13,0.190
210.98,134.27,0.190
211.00,134.41,0.190
211.03,134.56,0.190
211.06,134.70,0.190
211.09,134.84,0.190
211.12,134.98,0.190
211.15,135.12,0.190
211.17,135.26,0.190
211.20,135.41,0.190
211.23,135.55,0.190
211.26,135.69,0.190
211.29,135.83,0.190
211.32,135.97,0.190
211.34,136.11,0.190
211.37,136.26,0.190
211.40,136.40,0.190
211.43,136.54,0.190
211.46,136.68,0.190
211.48,136.82,0.190
211.51,136.96,0.190
211.54,137.11,0.190
211.57,137.25,0.190
211.60,137.39,0.190
211.63,137.53,0.190
211.65,137.67,0.190
211.68,137.81,0.190
211.71,137.96,0.190
211.74,138.10,0.190
211.77,138.24,0.190
211.80,138.38,0.190
211.83,138.52,0.190
211.85,138.67,0.190
211.88,138.81,0.190
211.91,138.95,0.190
211.94,139.09,0.190
211.97,139.23,0.190
212.00,139.37,0.190
212.02,139.52,0.190
212.05,139.66,0.190
212.08,139.80,0.190
212.11,139.94,0.190
212.14,140.08,0.190
212.17,140.22,0.190
212.19,140.37,0.190
212.22,140.51,0.190
212.25,140.65,0.190
212.28,140.79,0.190
212.31,140.93,0.190
212.33,141.07,0.191
212.36,141.22,0.190
212.39,141.36,0.190
212.42,141.50,0.191
212.45,141.64,0.190
212.48,141.78,0.190
212.50,141.92,0.190
212.53,142.07,0.190
212.56,142.21,0.191
212.59,142.35,0.191
212.62,142.49,0.191
212.65,142.63,0.191
212.68,142.78,0.191
212.70,142.92,0.191
212.73,143.06,0.191
212.76,143.20,0.191
212.79,143.34,0.191
212.82,143.48,0.191
212.85,143.63,0.191
212.87,143.77,0.191
212.90,143.91,0.191
212.93,144.05,0.191
212.96,144.19,0.191
212.99,144.34,0.191
213.02,144.48,0.191
213.04,144.62,0.191
213.07,144.76,0.191
213.10,144.90,0.191
213.13,145.04,0.191
213.16,145.18,0.191
213.18,145.33,0.191
213.21,145.47,0.191
213.24,145.61,0.191
213.27,145.75,0.191
213.30,145.89,0.191
213.33,146.03,0.191
213.35,146.17,0.191
213.38,146.32,0.191
213.41,146.46,0.191
213.44,146.60,0.191
213.47,146.74,0.191
213.50,146.88,0.191
213.53,147.02,0.191
213.55,147.17,0.191
213.58,147.31,0.191
213.61,147.45,0.191
213.64,147.59,0.191
213.67,147.73,0.191
213.70,147.88,0.191
213.72,148.02,0.192
213.75,148.16,0.192
213.78,148.30,0.192
213.81,148.44,0.192
213.84,148.59,0.192
213.87,148.73,0.192
213.89,148.87,0.192
213.92,149.01,0.192
213.95,149.15,
213.98,149.29,
213.99,,