File: DSC/2025_07_02_Ibuprofen_n80C_100C_5Cmin_x4.csv
Filename,2025_07_02_Ibuprofen_n80C_100C_5Cmin_x4
Instrument name,DSC2A-00468 (192.168.1.100)
Operator,Gibbons
rundate,7/3/2025
Sample name,2025_07_02_Ibuprofen_n80C_100C_5Cmin_x4
proceduresegments,Data Off ; Equilibrate -80.00 °C; Data On ; Ramp 5.00 °C/min to 100.00 °C; Data Off ; Isothermal 2.0 min; Data On ; Ramp 5.00 °C/min to -80.00 °C; Data Off ; Isothermal 2.0 min; Data On ; Ramp 5.00 °C/min to 100.00 °C; Data Off ; Isothermal 2.0 min; Data On ; Ramp 5.00 °C/min to -80.00 °C; Data Off ; Isothermal 2.0 min; Data On ; Ramp 5.00 °C/min to 100.00 °C; Data Off ; Isothermal 2.0 min; Data On ; Ramp 5.00 °C/min to -80.00 °C; Data Off ; Isothermal 2.0 min; Data On ; Ramp 5.00 °C/min to 30.00 °C
[File Parameters]
Run date,7/3/2025 4:59:32 PM
Trios version,5.1.1.46572
Original File Name,
Current File Name,D:\DSC2500\Gibbons\2025_07_02_Ibuprofen_n80C_100C_5Cmin_x4.tri
[Procedure]
Procedure Name,Ibuprofen_n80C_100C_5Cmin_x4
Sample Name,2025_07_02_Ibuprofen_n80C_100C_5Cmin_x4
Sample Mass,7.98 mg
Reference Sample Mass,0 mg
Pan Mass,56.41 mg
Pan Number,34
Reference Pan Mass,56.76 mg
Reference Pan Number,10
Pan Type,Tzero Aluminum Hermetic
Comments,DSC Consumables Al Hermetically Sealed Pan. Y1 Tray (Google Sheet: DSC_Samples_Y1_Tray_June2025).
Project Name,Pharma - Cocrystals
Operator,Gibbons
Test,Custom
Unload Max Temperature,30
Unload Min Temperature,30
Load Max Temperature,30
Load Min Temperature,30
Stop on Gas Flow Error,Yes
[Signal List]
Signal #1,Time (min)
Signal #2,Temperature (°C)
Signal #3,Heat Flow (mW)
Signal #4,Delta T (µV)
Signal #5,Delta Tzero (µV)
Signal #6,Tzero Temperature (°C)
Signal #7,Cell Purge (mL/min)
Signal #8,Heater Temp (°C)
Signal #9,Power Delivered (W)
Signal #10,Reference Junction Temperature (°C)
Signal #11,Flange Temperature (°C)
Signal #12,Heat Flow Phase (rad)
Signal #13,Total Heat Capacity (J/°C)
Signal #14,Heat Capacity (J/°C)
[Configuration]
Company Name,ASU
Instrument Name,DSC2A-00468
Instrument Type,DSC2500
Serial Number,DSC2A-00468
IP,192.168.1.100
Location of Instrument,MRRC
DisplayType,Unknown
Sample Interval ,0.1 s/pt
Selected Heat Flow,T4P
Exotherm Direction,Down
Cell Serial,DRC2-00792
Lid Type,Standard
Cooler,RCS 90
Leave Cooler on at End of Sequence,On
Gas 2,Nitrogen
Gas Selected,Channel 1
Flow Rate,50 mL/min
Secondary Purge,On
Licensed Heat Flow,Heat Flow T4P
Modulation Licensed,Yes
[Versions]
Common IDD Version,1
Cortex Version,VER 2.10.2.31
Driver,5.0.0.6
GDM Version,1.0.3.3
TouchscreenVersion,1.0.0.16145
FEP Version,1.2.1.21
FEP Bootloader,2.0.0.5
AutoSampler Version,2.1.1.26
Auto Sampler Bootloader,2.0.0.5
FCM Version,1.1.0.3
FCM Bootloader,2.0.0.5
[Experiment Logs]
Experiment Log Entry # 1,Data On set to 0
Experiment Log Entry # 3,Equilibrate Segment -80 (C) Started
Experiment Log Entry # 5,Air Cool is off.
Experiment Log Entry # 7,Data On set to 1
Experiment Log Entry # 9,Ramp Segment 5 C/min to 100 Started
Experiment Log Entry # 11,Data On set to 0
Experiment Log Entry # 13,Isothermal Segment 2 min started
Experiment Log Entry # 15,Data On set to 1
Experiment Log Entry # 17,Ramp Segment 5 C/min to -80 Started
Experiment Log Entry # 19,Data On set to 0
Experiment Log Entry # 21,Isothermal Segment 2 min started
Experiment Log Entry # 23,Data On set to 1
Experiment Log Entry # 25,Ramp Segment 5 C/min to 100 Started
Experiment Log Entry # 27,Data On set to 0
Experiment Log Entry # 29,Isothermal Segment 2 min started
Experiment Log Entry # 31,Data On set to 1
Experiment Log Entry # 33,Ramp Segment 5 C/min to -80 Started
Experiment Log Entry # 35,Data On set to 0
Experiment Log Entry # 37,Isothermal Segment 2 min started
Experiment Log Entry # 39,Data On set to 1
Experiment Log Entry # 41,Ramp Segment 5 C/min to 100 Started
Experiment Log Entry # 43,Data On set to 0
Experiment Log Entry # 45,Isothermal Segment 2 min started
Experiment Log Entry # 47,Data On set to 1
Experiment Log Entry # 49,Ramp Segment 5 C/min to -80 Started
Experiment Log Entry # 51,Data On set to 0
Experiment Log Entry # 53,Isothermal Segment 2 min started
Experiment Log Entry # 55,Data On set to 1
Experiment Log Entry # 57,Ramp Segment 5 C/min to 30 Started
[Method Log]
Method Log Entry # 1,Data Off
Method Log Entry # 2,Equilibrate -80 °C
Method Log Entry # 3,Data On
Method Log Entry # 4,(Ramp 1381482) Ramp 5 °C/minute to 100 °C
Method Log Entry # 5,Data Off
Method Log Entry # 6,Isothermal 2 minutes
Method Log Entry # 7,Data On
Method Log Entry # 8,(Ramp 1381486) Ramp 5 °C/minute to -80 °C
Method Log Entry # 9,Data Off
Method Log Entry # 10,Isothermal 2 minutes
Method Log Entry # 11,Data On
Method Log Entry # 12,(Ramp 1381490) Ramp 5 °C/minute to 100 °C
Method Log Entry # 13,Data Off
Method Log Entry # 14,Isothermal 2 minutes
Method Log Entry # 15,Data On
Method Log Entry # 16,(Ramp 1381494) Ramp 5 °C/minute to -80 °C
Method Log Entry # 17,Data Off
Method Log Entry # 18,Isothermal 2 minutes
Method Log Entry # 19,Data On
Method Log Entry # 20,(Ramp 1381498) Ramp 5 °C/minute to 100 °C
Method Log Entry # 21,Data Off
Method Log Entry # 22,Isothermal 2 minutes
Method Log Entry # 23,Data On
Method Log Entry # 24,(Ramp 1381502) Ramp 5 °C/minute to -80 °C
Method Log Entry # 25,Data Off
Method Log Entry # 26,Isothermal 2 minutes
Method Log Entry # 27,Data On
Method Log Entry # 28,(Ramp 1381506) Ramp 5 °C/minute to 30 °C
Cell Serial,DRC2-00792
[T1 Calibration]
Slope,-0.008529666
Offset,9.636258
Initial Temperature,98.23
GUID,f8bfdadc-4977-4fdf-ba6d-0ba9134940c3
[TZero Calibration]
Date Applied,11/29/2022 4:06:13 PM
Description,From -89.059 °C to 396.009 °C at 20.000°C/min
Gas Type,Nitrogen
Pan Type,None
Source Files 1,C:\Users\yargerlab\Desktop\DSC Data\General\TZero_calibration_11_29_22_2nd(2).tri
Source Files 2,C:\Users\yargerlab\Desktop\DSC Data\General\TZero_calibration_11_29_22_2nd(3).tri
Delta T Offset,13.05235
Delta T Slope,-0.007271007
Delta T0 Offset,-13.69128
Delta T0 Slope,0.06063341
[Temperature Calibration]
Date Applied,11/29/2022 7:12:28 PM
Description,From 106.590 °C to 186.590 °C at 10.000°C/min
Gas Type,Nitrogen
Pan Type,Tzero Aluminum Hermetic
Source Files 1,C:\Users\yargerlab\Desktop\DSC Data\General\Indium(6).tri
Measured 1,157.391
Known 1,156.598
[Cell Constant Calibration]
Date Applied,11/29/2022 7:12:29 PM
Description,From 106.590 °C to 186.590 °C at 10.000°C/min
Gas Type,Nitrogen
Pan Type,Tzero Aluminum Hermetic
Source Files 1,C:\Users\yargerlab\Desktop\DSC Data\General\Indium(6).tri
T4P KCell,1.006051
Onset Slope,63.26126 mW/°C
[Direct Cp Calibration]
Date Applied,11/30/2022 11:04:51 AM
Description,From -79.983 °C to 298.409 °C at 10.000°C/min
Gas Type,Nitrogen
Pan Type,Tzero Aluminum Hermetic
Source Files 1,C:\Users\yargerlab\Desktop\DSC Data\General\Sapphire_Heat_Capacity_11_30_22.tri
[Rev Cp Calibration]
Date Applied,11/30/2022 1:58:51 PM
Description,From -79.996 °C to 292.812 °C at 3.000°C/min
Gas Type,Nitrogen
Pan Type,Tzero Aluminum Hermetic
Source Files 1,C:\Users\yargerlab\Desktop\DSC Data\General\Sapphire_MDSC_Calibration_11_30_22.tri
[step]
Ramp 5.00 °C/min to 100.00 °C
Time,Temperature,Heat Flow (Normalized)
min,°C,W/g
0.00,-79.74,-0.032
0.03,-79.75,-0.032
0.05,-79.75,-0.028
0.08,-79.73,-0.027
0.10,-79.69,-0.026
0.13,-79.62,-0.013
0.15,-79.55,0.002
0.18,-79.47,0.016
0.20,-79.38,0.028
0.23,-79.29,0.035
0.25,-79.19,0.044
0.28,-79.08,0.051
0.30,-78.98,0.058
0.33,-78.87,0.064
0.35,-78.76,0.068
0.38,-78.64,0.072
0.40,-78.53,0.075
0.43,-78.41,0.077
0.45,-78.29,0.079
0.48,-78.17,0.081
0.50,-78.05,0.082
0.53,-77.93,0.083
0.55,-77.81,0.084
0.58,-77.69,0.085
0.60,-77.57,0.085
0.63,-77.45,0.086
0.65,-77.33,0.086
0.68,-77.20,0.086
0.70,-77.08,0.087
0.73,-76.96,0.087
0.75,-76.83,0.087
0.78,-76.71,0.088
0.80,-76.59,0.088
0.83,-76.47,0.088
0.85,-76.34,0.088
0.88,-76.22,0.089
0.90,-76.09,0.089
0.93,-75.97,0.089
0.95,-75.85,0.089
0.98,-75.72,0.089
1.00,-75.60,0.089
1.03,-75.48,0.090
1.05,-75.35,0.090
1.08,-75.23,0.090
1.10,-75.10,0.090
1.13,-74.98,0.090
1.15,-74.85,0.090
1.18,-74.73,0.090
1.20,-74.60,0.090
1.23,-74.48,0.090
1.25,-74.35,0.090
1.28,-74.23,0.090
1.30,-74.10,0.090
1.33,-73.98,0.091
1.35,-73.86,0.090
1.38,-73.73,0.091
1.40,-73.61,0.091
1.43,-73.48,0.091
1.45,-73.36,0.091
1.48,-73.23,0.091
1.50,-73.11,0.091
1.53,-72.98,0.091
1.55,-72.86,0.091
1.58,-72.73,0.091
1.60,-72.61,0.091
1.63,-72.48,0.091
1.65,-72.36,0.091
1.68,-72.23,0.091
1.70,-72.11,0.091
1.73,-71.98,0.091
1.75,-71.86,0.091
1.78,-71.73,0.091
1.80,-71.61,0.091
1.83,-71.48,0.091
1.85,-71.36,0.091
1.88,-71.23,0.091
1.90,-71.11,0.091
1.93,-70.98,0.091
1.95,-70.86,0.091
1.98,-70.73,0.091
2.00,-70.61,0.091
2.03,-70.48,0.091
2.05,-70.36,0.091
2.08,-70.23,0.091
2.10,-70.11,0.091
2.13,-69.98,0.091
2.15,-69.86,0.091
2.18,-69.73,0.091
2.20,-69.61,0.091
2.23,-69.48,0.091
2.25,-69.36,0.091
2.28,-69.23,0.091
2.30,-69.11,0.091
2.33,-68.98,0.091
2.35,-68.86,0.091
2.38,-68.73,0.091
2.40,-68.61,0.091
2.43,-68.48,0.091
2.45,-68.36,0.091
2.48,-68.23,0.091
2.50,-68.11,0.091
2.53,-67.98,0.091
2.55,-67.86,0.091
2.58,-67.73,0.091
2.60,-67.61,0.091
2.63,-67.48,0.091
2.65,-67.36,0.091
2.68,-67.23,0.091
2.70,-67.11,0.091
2.73,-66.98,0.091
2.75,-66.86,0.091
2.78,-66.73,0.091
2.80,-66.61,0.091
2.83,-66.48,0.091
2.85,-66.36,0.091
2.88,-66.23,0.091
2.90,-66.10,0.091
2.93,-65.98,0.091
2.95,-65.86,0.091
2.98,-65.73,0.091
3.00,-65.61,0.091
3.03,-65.48,0.091
3.05,-65.36,0.091
3.08,-65.23,0.091
3.10,-65.11,0.091
3.13,-64.98,0.091
3.15,-64.86,0.091
3.18,-64.73,0.091
3.20,-64.60,0.091
3.23,-64.48,0.091
3.25,-64.36,0.091
3.28,-64.23,0.091
3.30,-64.10,0.091
3.33,-63.98,0.091
3.35,-63.85,0.091
3.38,-63.73,0.091
3.40,-63.61,0.091
3.43,-63.48,0.091
3.45,-63.35,0.091
3.48,-63.23,0.091
3.50,-63.10,0.091
3.53,-62.98,0.091
3.55,-62.85,0.091
3.58,-62.73,0.091
3.60,-62.60,0.091
3.63,-62.48,0.091
3.65,-62.35,0.092
3.68,-62.23,0.092
3.70,-62.10,0.092
3.73,-61.98,0.092
3.75,-61.85,0.092
3.78,-61.73,0.092
3.80,-61.60,0.092
3.83,-61.48,0.092
3.85,-61.35,0.092
3.88,-61.23,0.092
3.90,-61.10,0.092
3.93,-60.98,0.092
3.95,-60.85,0.092
3.98,-60.73,0.092
4.00,-60.60,0.092
4.03,-60.48,0.092
4.05,-60.35,0.092
4.08,-60.23,0.092
4.10,-60.10,0.092
4.13,-59.98,0.092
4.15,-59.85,0.092
4.18,-59.73,0.092
4.20,-59.60,0.092
4.23,-59.48,0.092
4.25,-59.35,0.092
4.28,-59.23,0.092
4.30,-59.10,0.092
4.33,-58.98,0.092
4.35,-58.85,0.092
4.38,-58.73,0.092
4.40,-58.60,0.092
4.43,-58.48,0.092
4.45,-58.35,0.092
4.48,-58.23,0.092
4.50,-58.10,0.092
4.53,-57.98,0.092
4.55,-57.85,0.092
4.58,-57.73,0.092
4.60,-57.60,0.092
4.63,-57.48,0.092
4.65,-57.35,0.092
4.68,-57.23,0.092
4.70,-57.10,0.092
4.73,-56.98,0.092
4.75,-56.85,0.092
4.78,-56.73,0.092
4.80,-56.60,0.093
4.83,-56.48,0.093
4.85,-56.35,0.093
4.88,-56.23,0.093
4.90,-56.10,0.093
4.93,-55.98,0.093
4.95,-55.85,0.093
4.98,-55.73,0.093
5.00,-55.60,0.093
5.03,-55.48,0.093
5.05,-55.35,0.093
5.08,-55.23,0.093
5.10,-55.10,0.093
5.13,-54.98,0.093
5.15,-54.85,0.093
5.18,-54.73,0.093
5.20,-54.60,0.093
5.23,-54.48,0.093
5.25,-54.35,0.093
5.28,-54.23,0.093
5.30,-54.10,0.093
5.33,-53.97,0.093
5.35,-53.85,0.093
5.38,-53.73,0.093
5.40,-53.60,0.093
5.43,-53.48,0.093
5.45,-53.35,0.093
5.48,-53.23,0.093
5.50,-53.10,0.093
5.53,-52.98,0.093
5.55,-52.85,0.093
5.58,-52.73,0.093
5.60,-52.60,0.093
5.63,-52.48,0.093
5.65,-52.35,0.093
5.68,-52.23,0.093
5.70,-52.10,0.093
5.73,-51.98,0.093
5.75,-51.85,0.093
5.78,-51.73,0.093
5.80,-51.60,0.094
5.83,-51.48,0.094
5.85,-51.35,0.094
5.88,-51.23,0.094
5.90,-51.10,0.094
5.93,-50.98,0.094
5.95,-50.85,0.094
5.98,-50.73,0.094
6.00,-50.60,0.094
6.03,-50.48,0.094
6.05,-50.35,0.094
6.08,-50.23,0.094
6.10,-50.10,0.094
6.13,-49.98,0.094
6.15,-49.85,0.094
6.18,-49.73,0.094
6.20,-49.60,0.094
6.23,-49.48,0.094
6.25,-49.35,0.094
6.28,-49.23,0.094
6.30,-49.10,0.094
6.33,-48.98,0.094
6.35,-48.85,0.094
6.38,-48.73,0.094
6.40,-48.60,0.094
6.43,-48.48,0.094
6.45,-48.35,0.094
6.48,-48.23,0.094
6.50,-48.10,0.094
6.53,-47.98,0.094
6.55,-47.85,0.094
6.58,-47.73,0.094
6.60,-47.60,0.094
6.63,-47.48,0.095
6.65,-47.35,0.095
6.68,-47.23,0.095
6.70,-47.10,0.095
6.73,-46.98,0.095
6.75,-46.86,0.095
6.78,-46.73,0.095
6.80,-46.60,0.095
6.83,-46.48,0.095
6.85,-46.36,0.095
6.88,-46.23,0.095
6.90,-46.10,0.095
6.93,-45.98,0.095
6.95,-45.85,0.095
6.98,-45.73,0.095
7.00,-45.60,0.095
7.03,-45.48,0.095
7.05,-45.35,0.095
7.08,-45.23,0.095
7.10,-45.10,0.095
7.13,-44.98,0.095
7.15,-44.85,0.095
7.18,-44.73,0.095
7.20,-44.60,0.095
7.23,-44.48,0.095
7.25,-44.35,0.095
7.28,-44.23,0.095
7.30,-44.11,0.095
7.33,-43.98,0.095
7.35,-43.85,0.095
7.38,-43.73,0.095
7.40,-43.61,0.095
7.43,-43.48,0.095
7.45,-43.36,0.095
7.48,-43.23,0.095
7.50,-43.11,0.095
7.53,-42.98,0.096
7.55,-42.86,0.096
7.58,-42.73,0.096
7.60,-42.60,0.096
7.63,-42.48,0.096
7.65,-42.36,0.096
7.68,-42.23,0.096
7.70,-42.11,0.096
7.73,-41.98,0.096
7.75,-41.86,0.096
7.78,-41.73,0.096
7.80,-41.61,0.096
7.83,-41.48,0.096
7.85,-41.35,0.096
7.88,-41.23,0.096
7.90,-41.11,0.096
7.93,-40.98,0.096
7.95,-40.86,0.096
7.98,-40.73,0.096
8.00,-40.60,0.096
8.03,-40.48,0.096
8.05,-40.35,0.096
8.08,-40.23,0.096
8.10,-40.10,0.096
8.13,-39.98,0.096
8.15,-39.85,0.096
8.18,-39.73,0.096
8.20,-39.60,0.097
8.23,-39.48,0.097
8.25,-39.35,0.097
8.28,-39.23,0.097
8.30,-39.10,0.097
8.33,-38.98,0.097
8.35,-38.85,0.097
8.38,-38.73,0.097
8.40,-38.60,0.097
8.43,-38.48,0.097
8.45,-38.35,0.097
8.48,-38.23,0.097
8.50,-38.10,0.097
8.53,-37.98,0.097
8.55,-37.85,0.097
8.58,-37.72,0.097
8.60,-37.60,0.097
8.63,-37.47,0.097
8.65,-37.35,0.097
8.68,-37.23,0.097
8.70,-37.10,0.097
8.73,-36.97,0.097
8.75,-36.85,0.097
8.78,-36.72,0.097
8.80,-36.60,0.097
8.83,-36.48,0.097
8.85,-36.35,0.097
8.88,-36.22,0.097
8.90,-36.10,0.097
8.93,-35.97,0.097
8.95,-35.85,0.097
8.98,-35.72,0.097
9.00,-35.60,0.097
9.03,-35.47,0.097
9.05,-35.35,0.097
9.08,-35.22,0.097
9.10,-35.10,0.097
9.13,-34.97,0.097
9.15,-34.85,0.098
9.18,-34.72,0.098
9.20,-34.60,0.098
9.23,-34.47,0.098
9.25,-34.35,0.098
9.28,-34.22,0.098
9.30,-34.09,0.098
9.33,-33.97,0.098
9.35,-33.84,0.098
9.38,-33.72,0.098
9.40,-33.59,0.098
9.43,-33.47,0.098
9.45,-33.34,0.098
9.48,-33.22,0.098
9.50,-33.09,0.098
9.53,-32.97,0.098
9.55,-32.84,0.098
9.58,-32.72,0.098
9.60,-32.59,0.098
9.63,-32.47,0.098
9.65,-32.34,0.098
9.68,-32.22,0.098
9.70,-32.09,0.098
9.73,-31.97,0.098
9.75,-31.84,0.098
9.78,-31.72,0.098
9.80,-31.59,0.098
9.83,-31.47,0.098
9.85,-31.34,0.098
9.88,-31.22,0.098
9.90,-31.09,0.098
9.93,-30.97,0.098
9.95,-30.84,0.098
9.98,-30.71,0.099
10.00,-30.59,0.099
10.03,-30.47,0.099
10.05,-30.34,0.099
10.08,-30.21,0.099
10.10,-30.09,0.099
10.13,-29.96,0.099
10.15,-29.84,0.099
10.18,-29.72,0.099
10.20,-29.59,0.099
10.23,-29.46,0.099
10.25,-29.34,0.099
10.28,-29.21,0.099
10.30,-29.09,0.099
10.33,-28.96,0.099
10.35,-28.84,0.099
10.38,-28.71,0.099
10.40,-28.59,0.099
10.43,-28.46,0.099
10.45,-28.34,0.099
10.48,-28.21,0.099
10.50,-28.09,0.099
10.53,-27.96,0.099
10.55,-27.84,0.099
10.58,-27.71,0.099
10.60,-27.59,0.099
10.63,-27.46,0.099
10.65,-27.34,0.099
10.68,-27.21,0.099
10.70,-27.09,0.099
10.73,-26.96,0.099
10.75,-26.84,0.099
10.78,-26.71,0.099
10.80,-26.59,0.100
10.83,-26.46,0.100
10.85,-26.34,0.100
10.88,-26.21,0.100
10.90,-26.09,0.100
10.93,-25.96,0.100
10.95,-25.84,0.100
10.98,-25.71,0.100
11.00,-25.59,0.100
11.03,-25.46,0.100
11.05,-25.34,0.100
11.08,-25.21,0.100
11.10,-25.09,0.100
11.13,-24.96,0.100
11.15,-24.83,0.100
11.18,-24.71,0.100
11.20,-24.58,0.100
11.23,-24.46,0.100
11.25,-24.33,0.100
11.28,-24.21,0.100
11.30,-24.08,0.100
11.33,-23.96,0.100
11.35,-23.83,0.100
11.38,-23.71,0.100
11.40,-23.58,0.100
11.43,-23.46,0.100
11.45,-23.33,0.100
11.48,-23.21,0.100
11.50,-23.08,0.100
11.53,-22.96,0.101
11.55,-22.83,0.101
11.58,-22.71,0.101
11.60,-22.58,0.101
11.63,-22.46,0.101
11.65,-22.33,0.101
11.68,-22.21,0.101
11.70,-22.08,0.101
11.73,-21.96,0.101
11.75,-21.83,0.101
11.78,-21.71,0.101
11.80,-21.58,0.101
11.83,-21.46,0.101
11.85,-21.33,0.101
11.88,-21.21,0.101
11.90,-21.08,0.101
11.93,-20.95,0.101
11.95,-20.83,0.101
11.98,-20.70,0.101
12.00,-20.58,0.101
12.03,-20.46,0.101
12.05,-20.33,0.101
12.08,-20.21,0.101
12.10,-20.08,0.101
12.13,-19.96,0.101
12.15,-19.83,0.101
12.18,-19.70,0.101
12.20,-19.58,0.101
12.23,-19.45,0.101
12.25,-19.33,0.101
12.28,-19.20,0.101
12.30,-19.08,0.101
12.33,-18.95,0.102
12.35,-18.83,0.102
12.38,-18.70,0.102
12.40,-18.58,0.102
12.43,-18.45,0.102
12.45,-18.33,0.102
12.48,-18.20,0.102
12.50,-18.08,0.102
12.53,-17.95,0.102
12.55,-17.83,0.102
12.58,-17.70,0.102
12.60,-17.58,0.102
12.63,-17.45,0.102
12.65,-17.32,0.102
12.68,-17.20,0.102
12.70,-17.08,0.102
12.73,-16.95,0.102
12.75,-16.83,0.102
12.78,-16.70,0.102
12.80,-16.58,0.102
12.83,-16.45,0.102
12.85,-16.33,0.102
12.88,-16.20,0.102
12.90,-16.08,0.102
12.93,-15.95,0.102
12.95,-15.83,0.102
12.98,-15.70,0.102
13.00,-15.57,0.102
13.03,-15.45,0.102
13.05,-15.32,0.102
13.08,-15.20,0.103
13.10,-15.08,0.103
13.13,-14.95,0.103
13.15,-14.82,0.103
13.18,-14.70,0.103
13.20,-14.57,0.103
13.23,-14.45,0.103
13.25,-14.32,0.103
13.28,-14.20,0.103
13.30,-14.07,0.103
13.33,-13.95,0.103
13.35,-13.82,0.103
13.38,-13.70,0.103
13.40,-13.57,0.103
13.43,-13.45,0.103
13.45,-13.32,0.103
13.48,-13.19,0.103
13.50,-13.07,0.103
13.53,-12.94,0.103
13.55,-12.82,0.103
13.58,-12.69,0.103
13.60,-12.57,0.103
13.63,-12.45,0.103
13.65,-12.32,0.103
13.68,-12.19,0.103
13.70,-12.07,0.103
13.73,-11.94,0.103
13.75,-11.82,0.103
13.78,-11.70,0.103
13.80,-11.57,0.103
13.83,-11.45,0.103
13.85,-11.32,0.103
13.88,-11.20,0.103
13.90,-11.07,0.103
13.93,-10.95,0.103
13.95,-10.82,0.103
13.98,-10.69,0.104
14.00,-10.57,0.104
14.03,-10.44,0.104
14.05,-10.32,0.104
14.08,-10.19,0.104
14.10,-10.07,0.104
14.13,-9.94,0.104
14.15,-9.82,0.104
14.18,-9.69,0.104
14.20,-9.57,0.104
14.23,-9.45,0.104
14.25,-9.32,0.104
14.28,-9.19,0.104
14.30,-9.07,0.104
14.33,-8.94,0.104
14.35,-8.82,0.104
14.38,-8.69,0.104
14.40,-8.57,0.104
14.43,-8.44,0.104
14.45,-8.32,0.104
14.48,-8.19,0.104
14.50,-8.07,0.104
14.53,-7.94,0.104
14.55,-7.82,0.104
14.58,-7.69,0.104
14.60,-7.57,0.104
14.63,-7.44,0.104
14.65,-7.32,0.104
14.68,-7.19,0.104
14.70,-7.07,0.105
14.73,-6.94,0.105
14.75,-6.82,0.105
14.78,-6.69,0.105
14.80,-6.57,0.105
14.83,-6.44,0.105
14.85,-6.32,0.105
14.88,-6.19,0.105
14.90,-6.07,0.105
14.93,-5.94,0.105
14.95,-5.82,0.105
14.98,-5.69,0.105
15.00,-5.57,0.105
15.03,-5.44,0.105
15.05,-5.32,0.105
15.08,-5.19,0.105
15.10,-5.07,0.105
15.13,-4.94,0.105
15.15,-4.82,0.105
15.18,-4.69,0.105
15.20,-4.57,0.105
15.23,-4.44,0.105
15.25,-4.32,0.105
15.28,-4.19,0.105
15.30,-4.07,0.105
15.33,-3.94,0.105
15.35,-3.82,0.106
15.38,-3.69,0.106
15.40,-3.57,0.106
15.43,-3.44,0.106
15.45,-3.31,0.106
15.48,-3.19,0.106
15.50,-3.06,0.106
15.53,-2.94,0.106
15.55,-2.81,0.106
15.58,-2.69,0.106
15.60,-2.56,0.106
15.63,-2.44,0.106
15.65,-2.31,0.106
15.68,-2.19,0.106
15.70,-2.06,0.106
15.73,-1.94,0.106
15.75,-1.81,0.106
15.78,-1.69,0.106
15.80,-1.56,0.106
15.83,-1.44,0.106
15.85,-1.31,0.106
15.88,-1.19,0.106
15.90,-1.06,0.107
15.93,-0.94,0.107
15.95,-0.81,0.107
15.98,-0.69,0.107
16.00,-0.56,0.107
16.03,-0.44,0.107
16.05,-0.31,0.107
16.08,-0.19,0.107
16.10,-0.06,0.107
16.13,0.06,0.107
16.15,0.19,0.107
16.18,0.31,0.107
16.20,0.44,0.107
16.23,0.56,0.107
16.25,0.69,0.107
16.28,0.81,0.107
16.30,0.94,0.107
16.33,1.06,0.107
16.35,1.19,0.107
16.38,1.31,0.107
16.40,1.44,0.107
16.43,1.56,0.107
16.45,1.69,0.107
16.48,1.81,0.107
16.50,1.94,0.107
16.53,2.06,0.107
16.55,2.19,0.107
16.58,2.31,0.107
16.60,2.44,0.107
16.63,2.56,0.108
16.65,2.69,0.108
16.68,2.81,0.108
16.70,2.94,0.108
16.73,3.06,0.108
16.75,3.19,0.108
16.78,3.31,0.108
16.80,3.44,0.108
16.83,3.56,0.108
16.85,3.69,0.108
16.88,3.82,0.108
16.90,3.94,0.108
16.93,4.07,0.108
16.95,4.19,0.108
16.98,4.32,0.108
17.00,4.44,0.108
17.03,4.57,0.108
17.05,4.69,0.108
17.08,4.82,0.109
17.10,4.94,0.109
17.13,5.07,0.109
17.15,5.19,0.109
17.18,5.32,0.109
17.20,5.44,0.109
17.23,5.57,0.109
17.25,5.69,0.109
17.28,5.82,0.109
17.30,5.94,0.109
17.33,6.07,0.109
17.35,6.19,0.109
17.38,6.32,0.109
17.40,6.44,0.109
17.43,6.57,0.109
17.45,6.69,0.109
17.48,6.82,0.109
17.50,6.95,0.109
17.53,7.07,0.109
17.55,7.19,0.109
17.58,7.32,0.109
17.60,7.44,0.109
17.63,7.57,0.109
17.65,7.69,0.109
17.68,7.82,0.109
17.70,7.94,0.110
17.73,8.07,0.110
17.75,8.19,0.110
17.78,8.32,0.110
17.80,8.44,0.110
17.83,8.57,0.110
17.85,8.70,0.110
17.88,8.82,0.110
17.90,8.95,0.110
17.93,9.07,0.110
17.95,9.20,0.110
17.98,9.32,0.110
18.00,9.45,0.110
18.03,9.57,0.110
18.05,9.70,0.110
18.08,9.82,0.110
18.10,9.95,0.110
18.13,10.07,0.110
18.15,10.20,0.110
18.18,10.32,0.110
18.20,10.45,0.110
18.23,10.57,0.110
18.25,10.70,0.111
18.28,10.82,0.111
18.30,10.95,0.111
18.33,11.07,0.111
18.35,11.20,0.111
18.38,11.32,0.111
18.40,11.45,0.111
18.43,11.57,0.111
18.45,11.70,0.111
18.48,11.82,0.111
18.50,11.95,0.111
18.53,12.07,0.111
18.55,12.20,0.111
18.58,12.32,0.111
18.60,12.45,0.111
18.63,12.57,0.111
18.65,12.70,0.111
18.68,12.82,0.111
18.70,12.95,0.111
18.73,13.07,0.112
18.75,13.20,0.112
18.78,13.32,0.112
18.80,13.45,0.112
18.83,13.58,0.112
18.85,13.70,0.112
18.88,13.83,0.112
18.90,13.95,0.112
18.93,14.08,0.112
18.95,14.20,0.112
18.98,14.33,0.112
19.00,14.45,0.112
19.03,14.57,0.112
19.05,14.70,0.112
19.08,14.82,0.112
19.10,14.95,0.112
19.13,15.08,0.112
19.15,15.20,0.112
19.18,15.33,0.112
19.20,15.45,0.113
19.23,15.58,0.113
19.25,15.70,0.113
19.28,15.83,0.113
19.30,15.95,0.113
19.33,16.08,0.113
19.35,16.20,0.113
19.38,16.33,0.113
19.40,16.45,0.113
19.43,16.58,0.113
19.45,16.70,0.113
19.48,16.83,0.113
19.50,16.95,0.113
19.53,17.08,0.113
19.55,17.20,0.113
19.58,17.33,0.113
19.60,17.45,0.113
19.63,17.58,0.113
19.65,17.70,0.113
19.68,17.83,0.114
19.70,17.95,0.114
19.73,18.08,0.114
19.75,18.20,0.114
19.78,18.33,0.114
19.80,18.45,0.114
19.83,18.58,0.114
19.85,18.70,0.114
19.88,18.83,0.114
19.90,18.95,0.114
19.93,19.08,0.114
19.95,19.20,0.114
19.98,19.33,0.114
20.00,19.45,0.114
20.03,19.58,0.114
20.05,19.70,0.114
20.08,19.83,0.114
20.10,19.95,0.114
20.13,20.08,0.114
20.15,20.20,0.114
20.18,20.33,0.114
20.20,20.45,0.115
20.23,20.58,0.115
20.25,20.70,0.115
20.28,20.83,0.115
20.30,20.96,0.115
20.33,21.08,0.115
20.35,21.21,0.115
20.38,21.33,0.115
20.40,21.46,0.115
20.43,21.58,0.115
20.45,21.71,0.115
20.48,21.83,0.115
20.50,21.96,0.115
20.53,22.08,0.115
20.55,22.21,0.115
20.58,22.33,0.116
20.60,22.46,0.116
20.63,22.58,0.116
20.65,22.71,0.116
20.68,22.83,0.116
20.70,22.96,0.116
20.73,23.08,0.116
20.75,23.21,0.116
20.78,23.33,0.116
20.80,23.46,0.116
20.83,23.58,0.116
20.85,23.71,0.116
20.88,23.83,0.116
20.90,23.96,0.116
20.93,24.08,0.116
20.95,24.21,0.116
20.98,24.33,0.116
21.00,24.46,0.116
21.03,24.58,0.116
21.05,24.71,0.116
21.08,24.83,0.117
21.10,24.96,0.117
21.13,25.08,0.117
21.15,25.21,0.117
21.18,25.33,0.117
21.20,25.46,0.117
21.23,25.58,0.117
21.25,25.71,0.117
21.28,25.83,0.117
21.30,25.96,0.117
21.33,26.08,0.117
21.35,26.21,0.117
21.38,26.33,0.117
21.40,26.46,0.117
21.43,26.58,0.117
21.45,26.71,0.117
21.48,26.83,0.117
21.50,26.96,0.117
21.53,27.08,0.117
21.55,27.21,0.117
21.58,27.33,0.117
21.60,27.46,0.117
21.63,27.58,0.118
21.65,27.71,0.118
21.68,27.84,0.118
21.70,27.96,0.118
21.73,28.08,0.118
21.75,28.21,0.118
21.78,28.33,0.118
21.80,28.46,0.118
21.83,28.58,0.118
21.85,28.71,0.118
21.88,28.84,0.118
21.90,28.96,0.118
21.93,29.09,0.118
21.95,29.21,0.118
21.98,29.34,0.118
22.00,29.46,0.118
22.03,29.59,0.118
22.05,29.71,0.118
22.08,29.84,0.119
22.10,29.96,0.119
22.13,30.09,0.119
22.15,30.21,0.119
22.18,30.34,0.119
22.20,30.46,0.119
22.23,30.59,0.119
22.25,30.71,0.119
22.28,30.84,0.119
22.30,30.96,0.119
22.33,31.09,0.119
22.35,31.21,0.119
22.38,31.34,0.119
22.40,31.46,0.119
22.43,31.59,0.119
22.45,31.71,0.119
22.48,31.84,0.119
22.50,31.96,0.119
22.53,32.09,0.119
22.55,32.21,0.119
22.58,32.34,0.119
22.60,32.46,0.120
22.63,32.59,0.120
22.65,32.71,0.120
22.68,32.84,0.120
22.70,32.96,0.120
22.73,33.09,0.120
22.75,33.21,0.120
22.78,33.34,0.120
22.80,33.46,0.120
22.83,33.59,0.120
22.85,33.71,0.120
22.88,33.84,0.120
22.90,33.96,0.120
22.93,34.09,0.120
22.95,34.21,0.120
22.98,34.34,0.120
23.00,34.46,0.120
23.03,34.59,0.120
23.05,34.71,0.120
23.08,34.84,0.121
23.10,34.96,0.121
23.13,35.09,0.121
23.15,35.21,0.121
23.18,35.34,0.121
23.20,35.46,0.121
23.23,35.59,0.121
23.25,35.71,0.121
23.28,35.84,0.121
23.30,35.97,0.121
23.33,36.09,0.121
23.35,36.22,0.121
23.38,36.34,0.121
23.40,36.46,0.121
23.43,36.59,0.121
23.45,36.71,0.121
23.48,36.84,0.121
23.50,36.97,0.121
23.53,37.09,0.121
23.55,37.22,0.121
23.58,37.34,0.122
23.60,37.47,0.122
23.63,37.59,0.122
23.65,37.72,0.122
23.68,37.84,0.122
23.70,37.97,0.122
23.73,38.09,0.122
23.75,38.22,0.122
23.78,38.34,0.122
23.80,38.47,0.122
23.83,38.59,0.122
23.85,38.72,0.122
23.88,38.84,0.122
23.90,38.97,0.122
23.93,39.09,0.122
23.95,39.22,0.122
23.98,39.34,0.122
24.00,39.47,0.123
24.03,39.59,0.123
24.05,39.72,0.123
24.08,39.84,0.123
24.10,39.97,0.123
24.13,40.09,0.123
24.15,40.22,0.123
24.18,40.34,0.123
24.20,40.47,0.123
24.23,40.59,0.123
24.25,40.72,0.123
24.28,40.84,0.123
24.30,40.97,0.123
24.33,41.09,0.123
24.35,41.22,0.123
24.38,41.34,0.123
24.40,41.47,0.123
24.43,41.59,0.124
24.45,41.72,0.124
24.48,41.84,0.124
24.50,41.97,0.124
24.53,42.09,0.124
24.55,42.22,0.124
24.58,42.34,0.124
24.60,42.47,0.124
24.63,42.59,0.124
24.65,42.72,0.124
24.68,42.84,0.124
24.70,42.97,0.124
24.73,43.10,0.124
24.75,43.22,0.124
24.78,43.35,0.124
24.80,43.47,0.124
24.83,43.59,0.124
24.85,43.72,0.125
24.88,43.85,0.125
24.90,43.97,0.125
24.93,44.09,0.125
24.95,44.22,0.125
24.98,44.35,0.125
25.00,44.47,0.125
25.03,44.59,0.125
25.05,44.72,0.125
25.08,44.84,0.125
25.10,44.97,0.125
25.13,45.10,0.125
25.15,45.22,0.125
25.18,45.35,0.125
25.20,45.47,0.125
25.23,45.60,0.125
25.25,45.72,0.126
25.28,45.85,0.126
25.30,45.97,0.126
25.33,46.10,0.126
25.35,46.22,0.126
25.38,46.35,0.126
25.40,46.47,0.126
25.43,46.60,0.126
25.45,46.72,0.126
25.48,46.85,0.126
25.50,46.97,0.126
25.53,47.10,0.126
25.55,47.22,0.126
25.58,47.34,0.126
25.60,47.47,0.126
25.63,47.60,0.126
25.65,47.72,0.126
25.68,47.85,0.126
25.70,47.97,0.126
25.73,48.10,0.127
25.75,48.22,0.127
25.78,48.35,0.127
25.80,48.47,0.127
25.83,48.60,0.127
25.85,48.72,0.127
25.88,48.85,0.127
25.90,48.97,0.127
25.93,49.10,0.127
25.95,49.22,0.127
25.98,49.35,0.127
26.00,49.47,0.127
26.03,49.60,0.127
26.05,49.72,0.127
26.08,49.85,0.127
26.10,49.97,0.127
26.13,50.10,0.127
26.15,50.22,0.127
26.18,50.35,0.128
26.20,50.47,0.128
26.23,50.60,0.128
26.25,50.72,0.128
26.28,50.85,0.128
26.30,50.97,0.128
26.33,51.10,0.128
26.35,51.22,0.128
26.38,51.35,0.128
26.40,51.47,0.128
26.43,51.60,0.128
26.45,51.73,0.128
26.48,51.85,0.128
26.50,51.97,0.128
26.53,52.10,0.128
26.55,52.23,0.128
26.58,52.35,0.128
26.60,52.47,0.128
26.63,52.60,0.129
26.65,52.73,0.129
26.68,52.85,0.129
26.70,52.98,0.129
26.73,53.10,0.129
26.75,53.23,0.129
26.78,53.35,0.129
26.80,53.48,0.129
26.83,53.60,0.129
26.85,53.73,0.129
26.88,53.85,0.129
26.90,53.97,0.129
26.93,54.10,0.129
26.95,54.22,0.129
26.98,54.35,0.129
27.00,54.48,0.129
27.03,54.60,0.129
27.05,54.73,0.129
27.08,54.85,0.130
27.10,54.98,0.130
27.13,55.10,0.130
27.15,55.23,0.130
27.18,55.35,0.130
27.20,55.48,0.130
27.23,55.60,0.130
27.25,55.73,0.130
27.28,55.85,0.130
27.30,55.98,0.130
27.33,56.10,0.130
27.35,56.23,0.130
27.38,56.35,0.130
27.40,56.48,0.130
27.43,56.60,0.130
27.45,56.73,0.130
27.48,56.85,0.131
27.50,56.98,0.131
27.53,57.10,0.131
27.55,57.23,0.131
27.58,57.35,0.131
27.60,57.48,0.131
27.63,57.60,0.131
27.65,57.73,0.131
27.68,57.85,0.131
27.70,57.98,0.131
27.73,58.10,0.131
27.75,58.23,0.131
27.78,58.35,0.131
27.80,58.48,0.131
27.83,58.60,0.131
27.85,58.73,0.132
27.88,58.85,0.132
27.90,58.98,0.132
27.93,59.10,0.132
27.95,59.23,0.132
27.98,59.35,0.132
28.00,59.48,0.132
28.03,59.60,0.132
28.05,59.73,0.132
28.08,59.85,0.132
28.10,59.98,0.132
28.13,60.11,0.132
28.15,60.23,0.132
28.18,60.35,0.132
28.20,60.48,0.132
28.23,60.61,0.132
28.25,60.73,0.132
28.28,60.86,0.132
28.30,60.98,0.133
28.33,61.11,0.133
28.35,61.23,0.133
28.38,61.35,0.133
28.40,61.48,0.133
28.43,61.60,0.133
28.45,61.73,0.133
28.48,61.85,0.133
28.50,61.98,0.133
28.53,62.11,0.133
28.55,62.23,0.133
28.58,62.36,0.133
28.60,62.48,0.133
28.63,62.61,0.133
28.65,62.73,0.133
28.68,62.86,0.133
28.70,62.98,0.134
28.73,63.11,0.134
28.75,63.23,0.134
28.78,63.36,0.134
28.80,63.48,0.134
28.83,63.61,0.134
28.85,63.73,0.134
28.88,63.86,0.134
28.90,63.98,0.134
28.93,64.11,0.134
28.95,64.23,0.134
28.98,64.36,0.134
29.00,64.48,0.134
29.03,64.61,0.135
29.05,64.73,0.135
29.08,64.86,0.135
29.10,64.98,0.135
29.13,65.11,0.135
29.15,65.23,0.135
29.18,65.36,0.135
29.20,65.48,0.135
29.23,65.61,0.135
29.25,65.73,0.135
29.28,65.86,0.135
29.30,65.98,0.135
29.33,66.11,0.135
29.35,66.23,0.135
29.38,66.36,0.135
29.40,66.48,0.135
29.43,66.61,0.136
29.45,66.73,0.136
29.48,66.86,0.136
29.50,66.98,0.136
29.53,67.11,0.136
29.55,67.23,0.136
29.58,67.36,0.136
29.60,67.48,0.136
29.63,67.61,0.136
29.65,67.73,0.136
29.68,67.86,0.136
29.70,67.98,0.136
29.73,68.11,0.137
29.75,68.23,0.137
29.78,68.36,0.137
29.80,68.48,0.137
29.83,68.61,0.137
29.85,68.73,0.137
29.88,68.86,0.137
29.90,68.98,0.137
29.93,69.11,0.137
29.95,69.23,0.137
29.98,69.36,0.138
30.00,69.48,0.138
30.03,69.61,0.138
30.05,69.73,0.138
30.08,69.86,0.138
30.10,69.98,0.138
30.13,70.11,0.138
30.15,70.23,0.138
30.18,70.36,0.139
30.20,70.48,0.139
30.23,70.61,0.139
30.25,70.73,0.139
30.28,70.86,0.139
30.30,70.98,0.139
30.33,71.11,0.140
30.35,71.23,0.140
30.38,71.36,0.140
30.40,71.48,0.140
30.43,71.61,0.141
30.45,71.73,0.141
30.48,71.86,0.142
30.50,71.98,0.142
30.53,72.11,0.143
30.55,72.23,0.144
30.58,72.35,0.146
30.60,72.48,0.148
30.63,72.60,0.150
30.65,72.73,0.154
30.68,72.85,0.158
30.70,72.98,0.164
30.73,73.10,0.171
30.75,73.22,0.181
30.78,73.34,0.196
30.80,73.46,0.215
30.83,73.58,0.244
30.85,73.69,0.287
30.88,73.79,0.344
30.90,73.89,0.418
30.93,73.98,0.503
30.95,74.07,0.598
30.98,74.15,0.697
31.00,74.22,0.802
31.03,74.30,0.907
31.05,74.37,1.021
31.08,74.43,1.133
31.10,74.50,1.248
31.13,74.56,1.362
31.15,74.63,1.475
31.18,74.69,1.589
31.20,74.75,1.704
31.23,74.82,1.824
31.25,74.88,1.948
31.28,74.94,2.081
31.30,75.00,2.208
31.33,75.05,2.325
31.35,75.11,2.445
31.38,75.17,2.568
31.40,75.23,2.719
31.43,75.27,2.894
31.45,75.32,3.017
31.48,75.37,3.153
31.50,75.42,3.299
31.53,75.47,3.403
31.55,75.54,3.430
31.58,75.63,3.490
31.60,75.72,3.526
31.63,75.82,3.477
31.65,75.96,3.365
31.68,76.12,3.171
31.70,76.32,2.961
31.73,76.53,2.745
31.75,76.75,2.534
31.78,76.98,2.317
31.80,77.22,2.079
31.83,77.47,1.809
31.85,77.73,1.519
31.88,78.00,1.228
31.90,78.27,0.973
31.93,78.53,0.784
31.95,78.77,0.652
31.98,78.98,0.555
32.00,79.18,0.477
32.03,79.37,0.413
32.05,79.54,0.364
32.08,79.70,0.324
32.10,79.86,0.292
32.13,80.01,0.266
32.15,80.15,0.246
32.18,80.29,0.229
32.20,80.43,0.216
32.23,80.56,0.206
32.25,80.70,0.198
32.28,80.83,0.191
32.30,80.96,0.186
32.33,81.09,0.181
32.35,81.22,0.177
32.38,81.34,0.175
32.40,81.47,0.173
32.43,81.60,0.172
32.45,81.72,0.170
32.48,81.85,0.169
32.50,81.98,0.169
32.53,82.10,0.168
32.55,82.23,0.168
32.58,82.35,0.167
32.60,82.48,0.167
32.63,82.60,0.167
32.65,82.73,0.166
32.68,82.85,0.166
32.70,82.98,0.166
32.73,83.11,0.166
32.75,83.23,0.166
32.78,83.36,0.165
32.80,83.48,0.165
32.83,83.61,0.165
32.85,83.73,0.165
32.88,83.86,0.165
32.90,83.98,0.165
32.93,84.11,0.165
32.95,84.23,0.164
32.98,84.36,0.164
33.00,84.48,0.164
33.03,84.61,0.164
33.05,84.73,0.164
33.08,84.86,0.164
33.10,84.98,0.164
33.13,85.11,0.164
33.15,85.23,0.164
33.18,85.36,0.164
33.20,85.48,0.164
33.23,85.61,0.164
33.25,85.73,0.164
33.28,85.86,0.164
33.30,85.98,0.164
33.33,86.11,0.164
33.35,86.23,0.164
33.38,86.36,0.164
33.40,86.48,0.164
33.43,86.61,0.164
33.45,86.73,0.164
33.48,86.86,0.164
33.50,86.98,0.164
33.53,87.11,0.164
33.55,87.23,0.164
33.58,87.36,0.164
33.60,87.48,0.164
33.63,87.61,0.164
33.65,87.73,0.165
33.68,87.86,0.165
33.70,87.98,0.165
33.73,88.11,0.165
33.75,88.23,0.165
33.78,88.36,0.165
33.80,88.48,0.165
33.83,88.61,0.165
33.85,88.74,0.165
33.88,88.86,0.165
33.90,88.99,0.165
33.93,89.11,0.165
33.95,89.24,0.165
33.98,89.36,0.165
34.00,89.49,0.166
34.03,89.61,0.166
34.05,89.74,0.166
34.08,89.86,0.166
34.10,89.99,0.166
34.13,90.11,0.166
34.15,90.24,0.166
34.18,90.36,0.166
34.20,90.49,0.166
34.23,90.61,0.166
34.25,90.74,0.166
34.28,90.86,0.166
34.30,90.99,0.166
34.33,91.11,0.166
34.35,91.24,0.166
34.38,91.36,0.166
34.40,91.49,0.166
34.43,91.61,0.166
34.45,91.74,0.166
34.48,91.86,0.166
34.50,91.99,0.166
34.53,92.11,0.166
34.55,92.24,0.166
34.58,92.36,0.166
34.60,92.49,0.166
34.63,92.61,0.166
34.65,92.74,0.166
34.68,92.86,0.166
34.70,92.99,0.166
34.73,93.11,0.166
34.75,93.24,0.166
34.78,93.36,0.166
34.80,93.49,0.166
34.83,93.61,0.166
34.85,93.74,0.166
34.88,93.86,0.167
34.90,93.99,0.167
34.93,94.11,0.167
34.95,94.24,0.167
34.98,94.36,0.167
35.00,94.49,0.167
35.03,94.61,0.167
35.05,94.74,0.167
35.08,94.86,0.167
35.10,94.99,0.167
35.13,95.11,0.167
35.15,95.24,0.167
35.18,95.36,0.167
35.20,95.49,0.167
35.23,95.61,0.167
35.25,95.74,0.167
35.28,95.86,0.167
35.30,95.99,0.167
35.33,96.11,0.167
35.35,96.24,0.167
35.38,96.36,0.167
35.40,96.49,0.168
35.43,96.61,0.168
35.45,96.74,0.168
35.48,96.86,0.168
35.50,96.99,0.168
35.53,97.11,0.168
35.55,97.24,0.168
35.58,97.36,0.168
35.60,97.49,0.168
35.63,97.61,0.168
35.65,97.74,0.168
35.68,97.86,0.168
35.70,97.99,0.168
35.73,98.11,0.168
35.75,98.24,0.168
35.78,98.36,0.168
35.80,98.49,0.168
35.83,98.61,0.168
35.85,98.74,0.168
35.88,98.86,0.168
35.90,98.99,0.168
35.93,99.11,
35.95,99.24,
35.98,,
35.98,,

[step]
Ramp 5.00 °C/min to -80.00 °C
Time,Temperature,Heat Flow (Normalized)
min,°C,W/g
37.98,100.13,-0.028
38.01,100.13,-0.028
38.03,100.12,-0.028
38.06,100.11,-0.029
38.08,100.07,-0.042
38.11,100.02,-0.063
38.13,99.95,-0.090
38.16,99.87,-0.116
38.18,99.78,-0.138
38.21,99.68,-0.154
38.23,99.58,-0.167
38.26,99.48,-0.178
38.28,99.37,-0.187
38.31,99.26,-0.194
38.33,99.14,-0.199
38.36,99.03,-0.203
38.38,98.91,-0.208
38.41,98.79,-0.210
38.43,98.67,-0.212
38.46,98.55,-0.213
38.48,98.43,-0.215
38.51,98.31,-0.216
38.53,98.19,-0.217
38.56,98.06,-0.218
38.58,97.94,-0.218
38.61,97.82,-0.219
38.63,97.70,-0.219
38.66,97.57,-0.219
38.68,97.45,-0.220
38.71,97.33,-0.220
38.73,97.20,-0.220
38.76,97.08,-0.220
38.78,96.95,-0.220
38.81,96.83,-0.221
38.83,96.70,-0.221
38.86,96.58,-0.221
38.88,96.46,-0.221
38.91,96.33,-0.221
38.93,96.21,-0.222
38.96,96.08,-0.222
38.98,95.96,-0.222
39.01,95.83,-0.222
39.03,95.71,-0.222
39.06,95.58,-0.222
39.08,95.46,-0.222
39.11,95.34,-0.222
39.13,95.21,-0.222
39.16,95.09,-0.222
39.18,94.96,-0.222
39.21,94.84,-0.222
39.23,94.71,-0.222
39.26,94.59,-0.222
39.28,94.46,-0.222
39.31,94.34,-0.222
39.33,94.21,-0.222
39.36,94.09,-0.222
39.38,93.97,-0.222
39.41,93.84,-0.222
39.43,93.71,-0.222
39.46,93.59,-0.222
39.48,93.46,-0.222
39.51,93.34,-0.222
39.53,93.21,-0.222
39.56,93.09,-0.222
39.58,92.97,-0.221
39.61,92.84,-0.221
39.63,92.72,-0.221
39.66,92.59,-0.221
39.68,92.47,-0.221
39.71,92.34,-0.221
39.73,92.22,-0.221
39.76,92.09,-0.221
39.78,91.97,-0.221
39.81,91.84,-0.221
39.83,91.72,-0.221
39.86,91.59,-0.221
39.88,91.47,-0.221
39.91,91.34,-0.220
39.93,91.22,-0.220
39.96,91.09,-0.220
39.98,90.97,-0.220
40.01,90.84,-0.220
40.03,90.72,-0.220
40.06,90.59,-0.220
40.08,90.47,-0.218
40.11,90.34,-0.218
40.13,90.22,-0.218
40.16,90.09,-0.218
40.18,89.97,-0.218
40.21,89.84,-0.218
40.23,89.72,-0.218
40.26,89.59,-0.218
40.28,89.47,-0.218
40.31,89.34,-0.218
40.33,89.22,-0.218
40.36,89.09,-0.218
40.38,88.97,-0.218
40.41,88.84,-0.218
40.43,88.72,-0.218
40.46,88.59,-0.218
40.48,88.47,-0.218
40.51,88.34,-0.218
40.53,88.22,-0.218
40.56,88.09,-0.218
40.58,87.97,-0.218
40.61,87.84,-0.218
40.63,87.72,-0.218
40.66,87.59,-0.218
40.68,87.47,-0.218
40.71,87.34,-0.218
40.73,87.22,-0.218
40.76,87.09,-0.218
40.78,86.97,-0.217
40.81,86.84,-0.217
40.83,86.72,-0.217
40.86,86.59,-0.217
40.88,86.47,-0.217
40.91,86.35,-0.217
40.93,86.22,-0.217
40.96,86.09,-0.217
40.98,85.97,-0.217
41.01,85.84,-0.217
41.03,85.72,-0.217
41.06,85.59,-0.217
41.08,85.47,-0.217
41.11,85.34,-0.217
41.13,85.22,-0.216
41.16,85.09,-0.216
41.18,84.97,-0.216
41.21,84.85,-0.216
41.23,84.72,-0.216
41.26,84.59,-0.216
41.28,84.47,-0.216
41.31,84.35,-0.216
41.33,84.22,-0.216
41.36,84.10,-0.216
41.38,83.97,-0.216
41.41,83.85,-0.216
41.43,83.72,-0.216
41.46,83.60,-0.216
41.48,83.47,-0.215
41.51,83.35,-0.215
41.53,83.22,-0.215
41.56,83.09,-0.215
41.58,82.97,-0.215
41.61,82.85,-0.215
41.63,82.72,-0.215
41.66,82.60,-0.215
41.68,82.47,-0.215
41.71,82.35,-0.215
41.73,82.22,-0.215
41.76,82.10,-0.215
41.78,81.97,-0.215
41.81,81.85,-0.215
41.83,81.72,-0.215
41.86,81.60,-0.214
41.88,81.47,-0.214
41.91,81.35,-0.214
41.93,81.22,-0.214
41.96,81.10,-0.214
41.98,80.97,-0.214
42.01,80.85,-0.214
42.03,80.72,-0.214
42.06,80.60,-0.214
42.08,80.47,-0.214
42.11,80.35,-0.214
42.13,80.22,-0.214
42.16,80.10,-0.214
42.18,79.97,-0.214
42.21,79.85,-0.214
42.23,79.72,-0.214
42.26,79.60,-0.214
42.28,79.47,-0.214
42.31,79.35,-0.214
42.33,79.22,-0.214
42.36,79.10,-0.214
42.38,78.97,-0.214
42.41,78.85,-0.213
42.43,78.72,-0.213
42.46,78.60,-0.213
42.48,78.47,-0.213
42.51,78.35,-0.213
42.53,78.22,-0.213
42.56,78.10,-0.213
42.58,77.97,-0.213
42.61,77.85,-0.213
42.63,77.72,-0.213
42.66,77.60,-0.213
42.68,77.47,-0.213
42.71,77.35,-0.213
42.73,77.22,-0.213
42.76,77.10,-0.213
42.78,76.97,-0.212
42.81,76.85,-0.212
42.83,76.72,-0.212
42.86,76.60,-0.212
42.88,76.47,-0.212
42.91,76.35,-0.212
42.93,76.22,-0.212
42.96,76.10,-0.212
42.98,75.97,-0.212
43.01,75.85,-0.212
43.03,75.72,-0.212
43.06,75.60,-0.211
43.08,75.47,-0.211
43.11,75.35,-0.211
43.13,75.22,-0.211
43.16,75.10,-0.211
43.18,74.97,-0.211
43.21,74.85,-0.211
43.23,74.72,-0.211
43.26,74.60,-0.211
43.28,74.47,-0.211
43.31,74.35,-0.211
43.33,74.22,-0.211
43.36,74.10,-0.211
43.38,73.97,-0.211
43.41,73.85,-0.211
43.43,73.72,-0.211
43.46,73.60,-0.210
43.48,73.47,-0.210
43.51,73.35,-0.210
43.53,73.22,-0.210
43.56,73.10,-0.210
43.58,72.97,-0.210
43.61,72.85,-0.210
43.63,72.72,-0.210
43.66,72.60,-0.210
43.68,72.47,-0.210
43.71,72.35,-0.210
43.73,72.22,-0.210
43.76,72.10,-0.210
43.78,71.97,-0.210
43.81,71.85,-0.210
43.83,71.72,-0.209
43.86,71.60,-0.209
43.88,71.47,-0.209
43.91,71.35,-0.209
43.93,71.23,-0.209
43.96,71.10,-0.209
43.98,70.97,-0.209
44.01,70.85,-0.209
44.03,70.72,-0.209
44.06,70.60,-0.209
44.08,70.47,-0.209
44.11,70.35,-0.209
44.13,70.22,-0.209
44.16,70.10,-0.209
44.18,69.97,-0.209
44.21,69.85,-0.208
44.23,69.72,-0.208
44.26,69.60,-0.208
44.28,69.48,-0.208
44.31,69.35,-0.208
44.33,69.22,-0.208
44.36,69.10,-0.208
44.38,68.98,-0.208
44.41,68.85,-0.208
44.43,68.73,-0.208
44.46,68.60,-0.208
44.48,68.48,-0.208
44.51,68.35,-0.208
44.53,68.23,-0.208
44.56,68.10,-0.207
44.58,67.98,-0.207
44.61,67.85,-0.207
44.63,67.73,-0.207
44.66,67.60,-0.207
44.68,67.47,-0.207
44.71,67.35,-0.207
44.73,67.23,-0.207
44.76,67.10,-0.207
44.78,66.98,-0.207
44.81,66.85,-0.207
44.83,66.73,-0.207
44.86,66.60,-0.207
44.88,66.48,-0.207
44.91,66.35,-0.207
44.93,66.23,-0.206
44.96,66.10,-0.206
44.98,65.98,-0.206
45.01,65.85,-0.206
45.03,65.73,-0.206
45.06,65.60,-0.206
45.08,65.48,-0.206
45.11,65.35,-0.206
45.13,65.23,-0.206
45.16,65.10,-0.206
45.18,64.98,-0.206
45.21,64.85,-0.206
45.23,64.73,-0.206
45.26,64.60,-0.206
45.28,64.48,-0.206
45.31,64.35,-0.206
45.33,64.23,-0.205
45.36,64.10,-0.205
45.38,63.98,-0.205
45.41,63.85,-0.205
45.43,63.73,-0.205
45.46,63.60,-0.205
45.48,63.48,-0.205
45.51,63.35,-0.205
45.53,63.23,-0.205
45.56,63.10,-0.205
45.58,62.98,-0.205
45.61,62.85,-0.205
45.63,62.73,-0.205
45.66,62.60,-0.205
45.68,62.48,-0.205
45.71,62.35,-0.204
45.73,62.23,-0.204
45.76,62.10,-0.204
45.78,61.98,-0.204
45.81,61.85,-0.204
45.83,61.73,-0.204
45.86,61.60,-0.204
45.88,61.48,-0.204
45.91,61.35,-0.204
45.93,61.23,-0.204
45.96,61.10,-0.204
45.98,60.98,-0.204
46.01,60.85,-0.204
46.03,60.73,-0.204
46.06,60.60,-0.204
46.08,60.48,-0.203
46.11,60.35,-0.203
46.13,60.23,-0.203
46.16,60.10,-0.203
46.18,59.98,-0.203
46.21,59.85,-0.203
46.23,59.73,-0.203
46.26,59.60,-0.203
46.28,59.48,-0.203
46.31,59.35,-0.203
46.33,59.23,-0.203
46.36,59.10,-0.203
46.38,58.98,-0.203
46.41,58.85,-0.203
46.43,58.73,-0.202
46.46,58.60,-0.202
46.48,58.48,-0.202
46.51,58.35,-0.202
46.53,58.23,-0.202
46.56,58.10,-0.202
46.58,57.98,-0.202
46.61,57.85,-0.202
46.63,57.73,-0.202
46.66,57.60,-0.202
46.68,57.48,-0.202
46.71,57.35,-0.202
46.73,57.23,-0.202
46.76,57.10,-0.201
46.78,56.98,-0.201
46.81,56.85,-0.201
46.83,56.73,-0.201
46.86,56.60,-0.201
46.88,56.48,-0.201
46.91,56.36,-0.201
[...]
234.50,-48.23,0.108
234.51,-48.15,0.109
234.53,-48.08,0.109
234.54,-48.00,0.110
234.56,-47.93,0.110
234.57,-47.85,0.110
234.59,-47.78,0.111
234.60,-47.70,0.111
234.62,-47.63,0.112
234.63,-47.56,0.113
234.65,-47.48,0.113
234.66,-47.41,0.114
234.68,-47.33,0.114
234.69,-47.26,0.115
234.71,-47.18,0.116
234.72,-47.11,0.116
234.74,-47.03,0.116
234.75,-46.96,0.117
234.77,-46.88,0.118
234.78,-46.81,0.120
234.80,-46.73,0.120
234.81,-46.66,0.120
234.83,-46.59,0.122
234.84,-46.51,0.122
234.86,-46.44,0.123
234.87,-46.36,0.124
234.89,-46.29,0.125
234.90,-46.21,0.125
234.92,-46.14,0.127
234.93,-46.07,0.128
234.95,-45.99,0.128
234.96,-45.91,0.129
234.98,-45.84,0.130
234.99,-45.77,0.131
235.01,-45.69,0.132
235.02,-45.62,0.133
235.04,-45.54,0.134
235.05,-45.47,0.135
235.07,-45.40,0.136
235.08,-45.32,0.137
235.10,-45.25,0.137
235.11,-45.17,0.138
235.13,-45.10,0.139
235.14,-45.02,0.140
235.16,-44.95,0.140
235.17,-44.87,0.141
235.19,-44.80,0.142
235.20,-44.72,0.142
235.22,-44.65,0.143
235.23,-44.57,0.143
235.25,-44.50,0.144
235.26,-44.43,0.144
235.28,-44.35,0.144
235.29,-44.28,0.145
235.31,-44.20,0.145
235.32,-44.13,0.145
235.34,-44.05,0.145
235.35,-43.98,0.145
235.37,-43.90,0.145
235.38,-43.83,0.145
235.40,-43.75,0.146
235.41,-43.68,0.146
235.43,-43.60,0.146
235.44,-43.53,0.145
235.46,-43.45,0.145
235.47,-43.38,0.145
235.49,-43.30,0.144
235.50,-43.23,0.143
235.52,-43.15,0.143
235.53,-43.07,0.142
235.55,-43.00,0.142
235.56,-42.92,0.141
235.58,-42.85,0.141
235.59,-42.77,0.140
235.61,-42.70,0.140
235.62,-42.62,0.139
235.64,-42.54,0.138
235.65,-42.47,0.138
235.67,-42.39,0.137
235.68,-42.32,0.137
235.70,-42.24,0.136
235.71,-42.17,0.136
235.73,-42.09,0.135
235.74,-42.02,0.135
235.76,-41.94,0.134
235.77,-41.87,0.134
235.79,-41.79,0.134
235.80,-41.72,0.134
235.82,-41.64,0.134
235.83,-41.56,0.133
235.85,-41.49,0.133
235.86,-41.41,0.133
235.88,-41.34,0.133
235.89,-41.26,0.132
235.91,-41.19,0.132
235.92,-41.11,0.132
235.94,-41.04,0.132
235.95,-40.96,0.132
235.97,-40.89,0.132
235.98,-40.81,0.131
236.00,-40.74,0.131
236.01,-40.66,0.131
236.03,-40.59,0.131
236.04,-40.51,0.131
236.06,-40.44,0.131
236.07,-40.36,0.131
236.09,-40.29,0.131
236.10,-40.21,0.130
236.12,-40.14,0.130
236.13,-40.06,0.130
236.15,-39.98,0.130
236.16,-39.91,0.130
236.18,-39.83,0.130
236.19,-39.76,0.130
236.21,-39.69,0.130
236.22,-39.61,0.130
236.24,-39.54,0.130
236.25,-39.46,0.130
236.27,-39.38,0.130
236.28,-39.31,0.130
236.30,-39.24,0.130
236.31,-39.16,0.129
236.33,-39.08,0.129
236.34,-39.01,0.129
236.36,-38.93,0.129
236.37,-38.86,0.129
236.39,-38.78,0.129
236.40,-38.71,0.129
236.42,-38.63,0.129
236.43,-38.56,0.129
236.45,-38.48,0.129
236.46,-38.41,0.129
236.48,-38.33,0.129
236.49,-38.26,0.129
236.51,-38.18,0.129
236.52,-38.11,0.129
236.54,-38.03,0.129
236.55,-37.96,0.129
236.57,-37.88,0.129
236.58,-37.81,0.129
236.60,-37.73,0.129
236.61,-37.65,0.129
236.63,-37.58,0.129
236.64,-37.51,0.129
236.66,-37.43,0.129
236.67,-37.36,0.129
236.69,-37.28,0.129
236.70,-37.20,0.129
236.72,-37.13,0.129
236.73,-37.06,0.129
236.75,-36.98,0.129
236.76,-36.90,0.129
236.78,-36.83,0.129
236.79,-36.75,0.129
236.81,-36.68,0.129
236.82,-36.60,0.129
236.84,-36.53,0.129
236.85,-36.45,0.129
236.87,-36.38,0.129
236.88,-36.30,0.129
236.90,-36.23,0.129
236.91,-36.15,0.129
236.93,-36.08,0.129
236.94,-36.00,0.129
236.96,-35.93,0.129
236.97,-35.85,0.129
236.99,-35.78,0.129
237.00,-35.70,0.129
237.02,-35.63,0.129
237.03,-35.55,0.129
237.05,-35.48,0.129
237.06,-35.40,0.129
237.08,-35.33,0.129
237.09,-35.25,0.129
237.11,-35.18,0.129
237.12,-35.10,0.129
237.14,-35.03,0.129
237.15,-34.95,0.129
237.17,-34.88,0.129
237.18,-34.80,0.129
237.20,-34.73,0.129
237.21,-34.65,0.129
237.23,-34.58,0.129
237.24,-34.50,0.129
237.26,-34.43,0.129
237.27,-34.35,0.129
237.29,-34.28,0.129
237.30,-34.20,0.129
237.32,-34.13,0.129
237.33,-34.05,0.129
237.35,-33.98,0.129
237.36,-33.90,0.129
237.38,-33.82,0.129
237.39,-33.75,0.129
237.41,-33.67,0.129
237.42,-33.60,0.129
237.44,-33.52,0.129
237.45,-33.45,0.129
237.47,-33.37,0.129
237.48,-33.30,0.129
237.50,-33.22,0.129
237.51,-33.15,0.129
237.53,-33.07,0.129
237.54,-33.00,0.129
237.56,-32.92,0.129
237.57,-32.85,0.129
237.59,-32.77,0.129
237.60,-32.70,0.129
237.62,-32.62,0.129
237.63,-32.55,0.129
237.65,-32.47,0.129
237.66,-32.40,0.129
237.68,-32.32,0.129
237.69,-32.25,0.129
237.71,-32.17,0.129
237.72,-32.10,0.129
237.74,-32.02,0.129
237.75,-31.95,0.129
237.77,-31.87,0.129
237.78,-31.80,0.129
237.80,-31.72,0.129
237.81,-31.65,0.129
237.83,-31.57,0.129
237.84,-31.50,0.129
237.86,-31.42,0.129
237.87,-31.35,0.129
237.89,-31.27,0.129
237.90,-31.20,0.129
237.92,-31.12,0.129
237.93,-31.05,0.129
237.95,-30.97,0.129
237.96,-30.90,0.129
237.98,-30.82,0.129
237.99,-30.75,0.129
238.01,-30.67,0.129
238.02,-30.60,0.129
238.04,-30.52,0.129
238.05,-30.44,0.129
238.07,-30.37,0.129
238.08,-30.30,0.129
238.10,-30.22,0.129
238.11,-30.14,0.129
238.13,-30.07,0.129
238.14,-29.99,0.129
238.16,-29.92,0.129
238.17,-29.84,0.129
238.19,-29.77,0.129
238.20,-29.69,0.129
238.22,-29.62,0.129
238.23,-29.54,0.129
238.25,-29.47,0.129
238.26,-29.39,0.129
238.28,-29.32,0.129
238.29,-29.24,0.129
238.31,-29.17,0.129
238.32,-29.09,0.129
238.34,-29.02,0.129
238.35,-28.94,0.129
238.37,-28.87,0.129
238.38,-28.79,0.129
238.40,-28.72,0.129
238.41,-28.64,0.129
238.43,-28.57,0.129
238.44,-28.49,0.129
238.46,-28.42,0.129
238.47,-28.34,0.129
238.49,-28.27,0.129
238.50,-28.19,0.129
238.52,-28.12,0.129
238.53,-28.04,0.129
238.55,-27.97,0.129
238.56,-27.89,0.129
238.58,-27.82,0.129
238.59,-27.74,0.129
238.61,-27.67,0.129
238.62,-27.59,0.129
238.64,-27.52,0.129
238.65,-27.44,0.129
238.67,-27.37,0.129
238.68,-27.29,0.129
238.70,-27.22,0.129
238.71,-27.14,0.129
238.73,-27.07,0.129
238.74,-26.99,0.129
238.76,-26.92,0.129
238.77,-26.84,0.129
238.79,-26.77,0.129
238.80,-26.69,0.129
238.82,-26.62,0.129
238.83,-26.54,0.129
238.85,-26.47,0.129
238.86,-26.39,0.129
238.88,-26.31,0.129
238.89,-26.24,0.129
238.91,-26.17,0.129
238.92,-26.09,0.129
238.94,-26.02,0.129
238.95,-25.94,0.129
238.97,-25.86,0.129
238.98,-25.79,0.130
239.00,-25.71,0.129
239.01,-25.64,0.129
239.03,-25.57,0.129
239.04,-25.49,0.130
239.06,-25.41,0.130
239.07,-25.34,0.130
239.09,-25.26,0.130
239.10,-25.19,0.130
239.12,-25.11,0.130
239.13,-25.04,0.130
239.15,-24.96,0.130
239.16,-24.89,0.130
239.18,-24.81,0.130
239.19,-24.74,0.130
239.21,-24.66,0.130
239.22,-24.59,0.130
239.24,-24.51,0.130
239.25,-24.44,0.130
239.27,-24.36,0.130
239.28,-24.29,0.130
239.30,-24.21,0.130
239.31,-24.14,0.130
239.33,-24.06,0.130
239.34,-23.99,0.130
239.36,-23.91,0.130
239.37,-23.84,0.130
239.39,-23.76,0.130
239.40,-23.69,0.130
239.42,-23.61,0.130
239.43,-23.54,0.130
239.45,-23.46,0.130
239.46,-23.39,0.130
239.48,-23.31,0.130
239.49,-23.24,0.130
239.51,-23.16,0.130
239.52,-23.09,0.130
239.54,-23.01,0.130
239.55,-22.94,0.130
239.57,-22.86,0.130
239.58,-22.79,0.130
239.60,-22.71,0.130
239.61,-22.64,0.130
239.63,-22.56,0.130
239.64,-22.49,0.130
239.66,-22.41,0.130
239.67,-22.34,0.130
239.69,-22.26,0.130
239.70,-22.19,0.130
239.72,-22.11,0.130
239.73,-22.04,0.130
239.75,-21.96,0.130
239.76,-21.89,0.130
239.78,-21.81,0.130
239.79,-21.74,0.130
239.81,-21.66,0.130
239.82,-21.58,0.130
239.84,-21.51,0.130
239.85,-21.44,0.130
239.87,-21.36,0.130
239.88,-21.28,0.130
239.90,-21.21,0.130
239.91,-21.14,0.130
239.93,-21.06,0.130
239.94,-20.98,0.130
239.96,-20.91,0.130
239.97,-20.83,0.130
239.99,-20.76,0.130
240.00,-20.68,0.130
240.02,-20.61,0.130
240.03,-20.53,0.130
240.05,-20.46,0.130
240.06,-20.38,0.130
240.08,-20.31,0.130
240.09,-20.23,0.130
240.11,-20.16,0.130
240.12,-20.08,0.130
240.14,-20.01,0.130
240.15,-19.93,0.130
240.17,-19.86,0.130
240.18,-19.78,0.130
240.20,-19.71,0.130
240.21,-19.63,0.130
240.23,-19.56,0.130
240.24,-19.48,0.130
240.26,-19.41,0.130
240.27,-19.33,0.130
240.29,-19.26,0.130
240.30,-19.18,0.130
240.32,-19.11,0.130
240.33,-19.03,0.130
240.35,-18.96,0.130
240.36,-18.88,0.130
240.38,-18.81,0.130
240.39,-18.73,0.130
240.41,-18.66,0.130
240.42,-18.58,0.130
240.44,-18.51,0.130
240.45,-18.43,0.130
240.47,-18.36,0.130
240.48,-18.28,0.130
240.50,-18.21,0.130
240.51,-18.13,0.130
240.53,-18.06,0.130
240.54,-17.98,0.130
240.56,-17.91,0.130
240.57,-17.83,0.130
240.59,-17.75,0.130
240.60,-17.68,0.130
240.62,-17.61,0.130
240.63,-17.53,0.130
240.65,-17.46,0.130
240.66,-17.38,0.130
240.68,-17.31,0.130
240.69,-17.23,0.130
240.71,-17.16,0.130
240.72,-17.08,0.130
240.74,-17.01,0.130
240.75,-16.93,0.130
240.77,-16.86,0.131
240.78,-16.78,0.131
240.80,-16.71,0.131
240.81,-16.63,0.131
240.83,-16.56,0.131
240.84,-16.48,0.131
240.86,-16.40,0.131
240.87,-16.33,0.131
240.89,-16.25,0.131
240.90,-16.18,0.131
240.92,-16.10,0.131
240.93,-16.03,0.131
240.95,-15.95,0.131
240.96,-15.88,0.131
240.98,-15.80,0.131
240.99,-15.73,0.131
241.01,-15.65,0.131
241.02,-15.58,0.131
241.04,-15.50,0.131
241.05,-15.43,0.131
241.07,-15.35,0.131
241.08,-15.28,0.131
241.10,-15.20,0.131
241.11,-15.13,0.131
241.13,-15.05,0.131
241.14,-14.98,0.131
241.16,-14.90,0.131
241.17,-14.83,0.131
241.19,-14.75,0.131
241.20,-14.68,0.131
241.22,-14.60,0.131
241.23,-14.53,0.131
241.25,-14.45,0.131
241.26,-14.38,0.131
241.28,-14.30,0.131
241.29,-14.23,0.131
241.31,-14.15,0.131
241.32,-14.08,0.131
241.34,-14.00,0.131
241.35,-13.93,0.131
241.37,-13.85,0.131
241.38,-13.78,0.131
241.40,-13.70,0.131
241.41,-13.63,0.131
241.43,-13.55,0.131
241.44,-13.48,0.131
241.46,-13.40,0.131
241.47,-13.33,0.131
241.49,-13.25,0.131
241.50,-13.18,0.131
241.52,-13.10,0.131
241.53,-13.03,0.131
241.55,-12.95,0.131
241.56,-12.88,0.131
241.58,-12.80,0.131
241.59,-12.73,0.131
241.61,-12.65,0.131
241.62,-12.58,0.131
241.64,-12.50,0.131
241.65,-12.43,0.131
241.67,-12.35,0.131
241.68,-12.28,0.131
241.70,-12.20,0.131
241.71,-12.13,0.131
241.73,-12.05,0.131
241.74,-11.97,0.131
241.76,-11.90,0.131
241.77,-11.83,0.131
241.79,-11.75,0.131
241.80,-11.67,0.131
241.82,-11.60,0.131
241.83,-11.52,0.131
241.85,-11.45,0.131
241.86,-11.38,0.131
241.88,-11.30,0.131
241.89,-11.22,0.131
241.91,-11.15,0.131
241.92,-11.07,0.131
241.94,-11.00,0.131
241.95,-10.92,0.131
241.97,-10.85,0.131
241.98,-10.77,0.131
242.00,-10.70,0.131
242.01,-10.62,0.131
242.03,-10.55,0.131
242.04,-10.47,0.131
242.06,-10.40,0.131
242.07,-10.32,0.131
242.09,-10.25,0.131
242.10,-10.17,0.131
242.12,-10.10,0.131
242.13,-10.02,0.131
242.15,-9.95,0.131
242.16,-9.87,0.131
242.18,-9.80,0.131
242.19,-9.72,0.131
242.21,-9.65,0.132
242.22,-9.57,0.132
242.24,-9.50,0.131
242.25,-9.42,0.132
242.27,-9.35,0.132
242.28,-9.27,0.132
242.30,-9.20,0.132
242.31,-9.12,0.132
242.33,-9.05,0.132
242.34,-8.97,0.132
242.36,-8.90,0.132
242.37,-8.82,0.132
242.39,-8.75,0.132
242.40,-8.67,0.132
242.42,-8.60,0.132
242.43,-8.52,0.132
242.45,-8.45,0.132
242.46,-8.37,0.132
242.48,-8.30,0.132
242.49,-8.22,0.132
242.51,-8.15,0.132
242.52,-8.07,0.132
242.54,-8.00,0.132
242.55,-7.92,0.132
242.57,-7.85,0.132
242.58,-7.77,0.132
242.60,-7.70,0.132
242.61,-7.62,0.132
242.63,-7.55,0.132
242.64,-7.47,0.132
242.66,-7.40,0.132
242.67,-7.32,0.132
242.69,-7.25,0.132
242.70,-7.17,0.132
242.72,-7.10,0.132
242.73,-7.02,0.132
242.75,-6.95,0.132
242.76,-6.87,0.132
242.78,-6.80,0.132
242.79,-6.72,0.132
242.81,-6.65,0.132
242.82,-6.57,0.132
242.84,-6.50,0.132
242.85,-6.42,0.132
242.87,-6.35,0.132
242.88,-6.27,0.132
242.90,-6.19,0.132
242.91,-6.12,0.132
242.93,-6.04,0.132
242.94,-5.97,0.132
242.96,-5.89,0.132
242.97,-5.82,0.132
242.99,-5.75,0.132
243.00,-5.67,0.132
243.02,-5.59,0.132
243.03,-5.52,0.132
243.05,-5.44,0.132
243.06,-5.37,0.132
243.08,-5.29,0.132
243.09,-5.22,0.132
243.11,-5.14,0.132
243.12,-5.07,0.132
243.14,-4.99,0.132
243.15,-4.92,0.132
243.17,-4.84,0.132
243.18,-4.77,0.132
243.20,-4.69,0.132
243.21,-4.62,0.132
243.23,-4.54,0.132
243.24,-4.47,0.132
243.26,-4.39,0.132
243.27,-4.32,0.132
243.29,-4.24,0.132
243.30,-4.17,0.132
243.32,-4.09,0.132
243.33,-4.02,0.132
243.35,-3.94,0.132
243.36,-3.87,0.132
243.38,-3.79,0.132
243.39,-3.72,0.133
243.41,-3.64,0.133
243.42,-3.57,0.133
243.44,-3.49,0.133
243.45,-3.42,0.133
243.47,-3.34,0.133
243.48,-3.27,0.133
243.50,-3.19,0.133
243.51,-3.12,0.133
243.53,-3.04,0.133
243.54,-2.96,0.133
243.56,-2.89,0.133
243.57,-2.82,0.133
243.59,-2.74,0.133
243.60,-2.67,0.133
243.62,-2.59,0.133
243.63,-2.52,0.133
243.65,-2.44,0.133
243.66,-2.36,0.133
243.68,-2.29,0.133
243.69,-2.22,0.133
243.71,-2.14,0.133
243.72,-2.06,0.133
243.74,-1.99,0.133
243.75,-1.92,0.133
243.77,-1.84,0.133
243.78,-1.77,0.133
243.80,-1.69,0.133
243.81,-1.61,0.133
243.83,-1.54,0.133
243.84,-1.46,0.133
243.86,-1.39,0.133
243.87,-1.31,0.133
243.89,-1.24,0.133
243.90,-1.16,0.133
243.92,-1.09,0.133
243.93,-1.01,0.133
243.95,-0.94,0.133
243.96,-0.86,0.133
243.98,-0.79,0.133
243.99,-0.71,0.133
244.01,-0.64,0.133
244.02,-0.56,0.133
244.04,-0.49,0.133
244.05,-0.42,0.133
244.07,-0.34,0.133
244.08,-0.26,0.133
244.10,-0.19,0.133
244.11,-0.11,0.133
244.13,-0.04,0.133
244.14,0.04,0.133
244.16,0.11,0.133
244.17,0.19,0.133
244.19,0.26,0.133
244.20,0.34,0.133
244.22,0.41,0.133
244.23,0.49,0.133
244.25,0.56,0.133
244.26,0.64,0.133
244.28,0.71,0.133
244.29,0.79,0.133
244.31,0.86,0.133
244.32,0.94,0.133
244.34,1.01,0.133
244.35,1.09,0.133
244.37,1.16,0.133
244.38,1.24,0.133
244.40,1.31,0.133
244.41,1.39,0.133
244.43,1.46,0.133
244.44,1.53,0.134
244.46,1.61,0.134
244.47,1.69,0.134
244.49,1.76,0.134
244.50,1.84,0.134
244.52,1.91,0.134
244.53,1.99,0.134
244.55,2.06,0.134
244.56,2.14,0.134
244.58,2.21,0.134
244.59,2.29,0.134
244.61,2.36,0.134
244.62,2.44,0.134
244.64,2.51,0.134
244.65,2.59,0.134
244.67,2.66,0.134
244.68,2.74,0.134
244.70,2.81,0.134
244.71,2.89,0.134
244.73,2.96,0.134
244.74,3.04,0.134
244.76,3.11,0.134
244.77,3.19,0.134
244.79,3.26,0.134
244.80,3.34,0.134
244.82,3.41,0.134
244.83,3.49,0.134
244.85,3.56,0.134
244.86,3.64,0.134
244.88,3.71,0.134
244.89,3.79,0.134
244.91,3.86,0.134
244.92,3.94,0.134
244.94,4.02,0.134
244.95,4.09,0.134
244.97,4.17,0.134
244.98,4.24,0.134
245.00,4.31,0.134
245.01,4.39,0.134
245.03,4.47,0.134
245.04,4.54,0.134
245.06,4.62,0.134
245.07,4.69,0.134
245.09,4.77,0.134
245.10,4.84,0.134
245.12,4.91,0.134
245.13,4.99,0.134
245.15,5.07,0.134
245.16,5.14,0.134
245.18,5.21,0.134
245.19,5.29,0.134
245.21,5.37,0.134
245.22,5.44,0.134
245.24,5.52,0.134
245.25,5.59,0.134
245.27,5.67,0.134
245.28,5.74,0.134
245.30,5.82,0.135
245.31,5.89,0.135
245.33,5.97,0.135
245.34,6.04,0.135
245.36,6.12,0.135
245.37,6.19,0.135
245.39,6.27,0.135
245.40,6.34,0.135
245.42,6.42,0.135
245.43,6.49,0.135
245.45,6.57,0.135
245.46,6.64,0.135
245.48,6.72,0.135
245.49,6.79,0.135
245.51,6.87,0.135
245.52,6.94,0.135
245.54,7.02,0.135
245.55,7.09,0.135
245.57,7.17,0.135
245.58,7.24,0.135
245.60,7.32,0.135
245.61,7.39,0.135
245.63,7.47,0.135
245.64,7.54,0.135
245.66,7.62,0.135
245.67,7.69,0.135
245.69,7.77,0.135
245.70,7.84,0.135
245.72,7.92,0.135
245.73,7.99,0.135
245.75,8.07,0.135
245.76,8.14,0.135
245.78,8.22,0.135
245.79,8.29,0.135
245.81,8.37,0.135
245.82,8.44,0.135
245.84,8.52,0.135
245.85,8.59,0.135
245.87,8.67,0.135
245.88,8.74,0.135
245.90,8.82,0.135
245.91,8.89,0.135
245.93,8.97,0.135
245.94,9.04,0.135
245.96,9.12,0.135
245.97,9.19,0.135
245.99,9.27,0.135
246.00,9.34,0.135
246.02,9.42,0.135
246.03,9.49,0.135
246.05,9.57,0.135
246.06,9.65,0.135
246.08,9.72,0.135
246.09,9.79,0.135
246.11,9.87,0.135
246.12,9.94,0.135
246.14,10.02,0.135
246.15,10.10,0.135
246.17,10.17,0.136
246.18,10.25,0.136
246.20,10.32,0.136
246.21,10.40,0.136
246.23,10.47,0.136
246.24,10.55,0.136
246.26,10.62,0.136
246.27,10.70,0.136
246.29,10.77,0.136
246.30,10.85,0.136
246.32,10.92,0.136
246.33,11.00,0.136
246.35,11.07,0.136
246.36,11.15,0.136
246.38,11.22,0.136
246.39,11.30,0.136
246.41,11.37,0.136
246.42,11.45,0.136
246.44,11.52,0.136
246.45,11.60,0.136
246.47,11.67,0.136
246.48,11.75,0.136
246.50,11.82,0.136
246.51,11.90,0.136
246.53,11.97,0.136
246.54,12.05,0.136
246.56,12.12,0.136
246.57,12.20,0.136
246.59,12.27,0.136
246.60,12.35,0.136
246.62,12.42,0.136
246.63,12.50,0.136
246.65,12.57,0.136
246.66,12.65,0.136
246.68,12.72,0.136
246.69,12.80,0.136
246.71,12.87,0.136
246.72,12.95,0.136
246.74,13.02,0.136
246.75,13.10,0.136
246.77,13.17,0.136
246.78,13.25,0.136
246.80,13.32,0.136
246.81,13.40,0.136
246.83,13.47,0.136
246.84,13.55,0.136
246.86,13.62,0.136
246.87,13.70,0.136
246.89,13.78,0.136
246.90,13.85,0.136
246.92,13.93,0.136
246.93,14.00,0.136
246.95,14.08,0.136
246.96,14.15,0.137
246.98,14.23,0.137
246.99,14.30,0.137
247.01,14.38,0.137
247.02,14.45,0.137
247.04,14.53,0.137
247.05,14.60,0.137
247.07,14.67,0.137
247.08,14.75,0.137
247.10,14.83,0.137
247.11,14.90,0.137
247.13,14.98,0.137
247.14,15.05,0.137
247.16,15.12,0.137
247.17,15.20,0.137
247.19,15.28,0.137
247.20,15.35,0.137
247.22,15.42,0.137
247.23,15.50,0.137
247.25,15.58,0.137
247.26,15.65,0.137
247.28,15.73,0.137
247.29,15.80,0.137
247.31,15.88,0.137
247.32,15.95,0.137
247.34,16.03,0.137
247.35,16.10,0.137
247.37,16.18,0.137
247.38,16.25,0.137
247.40,16.33,0.137
247.41,16.40,0.137
247.43,16.48,0.137
247.44,16.55,0.137
247.46,16.63,0.137
247.47,16.70,0.137
247.49,16.78,0.137
247.50,16.85,0.137
247.52,16.93,0.137
247.53,17.00,0.137
247.55,17.08,0.137
247.56,17.15,0.137
247.58,17.23,0.137
247.59,17.30,0.137
247.61,17.38,0.137
247.62,17.45,0.137
247.64,17.53,0.137
247.65,17.60,0.137
247.67,17.68,0.137
247.68,17.75,0.137
247.70,17.83,0.138
247.71,17.90,0.138
247.73,17.98,0.138
247.74,18.05,0.138
247.76,18.13,0.138
247.77,18.21,0.138
247.79,18.28,0.138
247.80,18.36,0.138
247.82,18.43,0.138
247.83,18.51,0.138
247.85,18.58,0.138
247.86,18.66,0.138
247.88,18.73,0.138
247.89,18.81,0.138
247.91,18.88,0.138
247.92,18.96,0.138
247.94,19.03,0.138
247.95,19.11,0.138
247.97,19.18,0.138
247.98,19.26,0.138
248.00,19.33,0.138
248.01,19.41,0.138
248.03,19.48,0.138
248.04,19.56,0.138
248.06,19.63,0.138
248.07,19.71,0.138
248.09,19.78,0.138
248.10,19.86,0.138
248.12,19.93,0.138
248.13,20.01,0.138
248.15,20.08,0.138
248.16,20.16,0.138
248.18,20.23,0.138
248.19,20.31,0.138
248.21,20.38,0.138
248.22,20.46,0.138
248.24,20.53,0.138
248.25,20.61,0.138
248.27,20.68,0.138
248.28,20.76,0.138
248.30,20.83,0.138
248.31,20.91,0.138
248.33,20.98,0.138
248.34,21.06,0.138
248.36,21.13,0.138
248.37,21.21,0.138
248.39,21.28,0.138
248.40,21.35,0.138
248.42,21.43,0.138
248.43,21.50,0.138
248.45,21.58,0.138
248.46,21.66,0.138
248.48,21.73,0.138
248.49,21.81,0.138
248.51,21.88,0.138
248.52,21.96,0.138
248.54,22.03,0.138
248.55,22.11,0.138
248.57,22.18,0.139
248.58,22.26,0.139
248.60,22.33,0.139
248.61,22.41,0.139
248.63,22.48,0.139
248.64,22.56,0.139
248.66,22.63,0.139
248.67,22.71,0.139
248.69,22.78,0.139
248.70,22.86,0.139
248.72,22.93,0.139
248.73,23.01,0.139
248.75,23.08,0.139
248.76,23.16,0.139
248.78,23.23,0.139
248.79,23.31,0.139
248.81,23.38,0.139
248.82,23.46,0.139
248.84,23.53,0.139
248.85,23.61,0.139
248.87,23.68,0.139
248.88,23.76,0.139
248.90,23.83,0.139
248.91,23.91,0.139
248.93,23.99,0.139
248.94,24.06,0.139
248.96,24.14,0.139
248.97,24.21,0.139
248.99,24.29,0.139
249.00,24.36,0.139
249.02,24.44,0.139
249.03,24.51,0.140
249.05,24.59,0.140
249.06,24.66,0.140
249.08,24.74,0.140
249.09,24.81,0.140
249.11,24.88,0.140
249.12,24.96,0.140
249.14,25.03,0.140
249.15,25.11,0.140
249.17,25.18,0.140
249.18,25.26,0.140
249.20,25.34,0.140
249.21,25.41,0.140
249.23,25.48,0.140
249.24,25.56,0.140
249.26,25.63,0.140
249.27,25.71,0.140
249.29,25.78,0.140
249.30,25.86,0.140
249.32,25.93,0.140
249.33,26.01,0.140
249.35,26.09,0.140
249.36,26.16,0.140
249.38,26.23,0.140
249.39,26.31,0.140
249.41,26.39,0.140
249.42,26.46,0.140
249.44,26.54,0.140
249.45,26.61,0.140
249.47,26.68,0.140
249.48,26.76,0.140
249.50,26.84,0.140
249.51,26.91,0.140
249.53,26.98,0.140
249.54,27.06,0.140
249.56,27.14,0.140
249.57,27.21,0.140
249.59,27.28,0.140
249.60,27.36,0.140
249.62,27.44,0.140
249.63,27.51,0.140
249.65,27.59,0.140
249.66,27.66,0.140
249.68,27.74,0.140
249.69,27.81,0.140
249.71,27.89,0.140
249.72,27.96,0.140
249.74,28.04,0.140
249.75,28.11,0.140
249.77,28.19,0.140
249.78,28.26,0.140
249.80,28.34,0.140
249.81,28.41,0.140
249.83,28.49,0.141
249.84,28.56,0.141
249.86,28.64,0.141
249.87,28.71,0.141
249.89,28.79,0.141
249.90,28.86,0.141
249.92,28.94,0.141
249.93,29.01,
249.95,29.09,
249.96,29.16,
249.98,29.24,
249.99,,