File: DSC/2025_04_20_CBD_n60C_100C_10Cmin_x3.csv
Filename,2025_04_20_CBD_n60C_100C_10Cmin_x3
Instrument name,DSC2A-00468 (192.168.1.100)
Operator,Yarger
rundate,4/20/2025
Sample name,2025_04_20_CBD_n60C_100C_10Cmin_x3
proceduresegments,Data Off ; Equilibrate -60.00 °C; Data On ; Ramp 10.00 °C/min to 100.00 °C; Data Off ; Isothermal 1.0 min; Data On ; Ramp 10.00 °C/min to -60.00 °C; Data Off ; Isothermal 1.0 min; Data On ; Ramp 10.00 °C/min to 100.00 °C; Data Off ; Isothermal 1.0 min; Data On ; Ramp 10.00 °C/min to -60.00 °C; Data Off ; Isothermal 1.0 min; Data On ; Ramp 10.00 °C/min to 100.00 °C
[File Parameters]
Run date,4/20/2025 9:12:05 PM
Trios version,5.1.1.46572
Original File Name,
Current File Name,D:\DSC2500\JYarger\2025_04_20_CBD_n60C_100C_10Cmin_x3.tri
[Procedure]
Procedure Name,CBD_n60_100C_10Cmin_x3
Sample Name,2025_04_20_CBD_n60C_100C_10Cmin_x3
Sample Mass,1.22 mg
Reference Sample Mass,0 mg
Pan Mass,25.42 mg
Pan Number,36
Reference Pan Mass,25.8 mg
Reference Pan Number,28
Pan Type,Tzero Aluminum
Comments,"Al Pan/Lid, Not sealed."
Project Name,CA
Operator,Yarger
Test,Custom
Unload Max Temperature,30
Unload Min Temperature,30
Load Max Temperature,30
Load Min Temperature,30
Stop on Gas Flow Error,Yes
[Signal List]
Signal #1,Time (min)
Signal #2,Temperature (°C)
Signal #3,Heat Flow (mW)
Signal #4,Delta T (µV)
Signal #5,Delta Tzero (µV)
Signal #6,Tzero Temperature (°C)
Signal #7,Cell Purge (mL/min)
Signal #8,Heater Temp (°C)
Signal #9,Power Delivered (W)
Signal #10,Reference Junction Temperature (°C)
Signal #11,Flange Temperature (°C)
Signal #12,Heat Flow Phase (rad)
Signal #13,Total Heat Capacity (J/°C)
Signal #14,Heat Capacity (J/°C)
[Configuration]
Company Name,ASU
Instrument Name,DSC2A-00468
Instrument Type,DSC2500
Serial Number,DSC2A-00468
IP,192.168.1.100
Location of Instrument,MRRC
DisplayType,Unknown
Sample Interval ,0.1 s/pt
Selected Heat Flow,T4P
Exotherm Direction,Down
Cell Serial,DRC2-00792
Lid Type,Standard
Cooler,RCS 90
Leave Cooler on at End of Sequence,On
Gas 2,Nitrogen
Gas Selected,Channel 1
Flow Rate,50 mL/min
Secondary Purge,On
Licensed Heat Flow,Heat Flow T4P
Modulation Licensed,Yes
[Versions]
Common IDD Version,1
Cortex Version,VER 2.10.2.31
Driver,5.0.0.6
GDM Version,1.0.3.3
TouchscreenVersion,1.0.0.16145
FEP Version,1.2.1.21
FEP Bootloader,2.0.0.5
AutoSampler Version,2.1.1.26
Auto Sampler Bootloader,2.0.0.5
FCM Version,1.1.0.3
FCM Bootloader,2.0.0.5
[Experiment Logs]
Experiment Log Entry # 1,Data On set to 0
Experiment Log Entry # 3,Equilibrate Segment -60 (C) Started
Experiment Log Entry # 5,Air Cool is off.
Experiment Log Entry # 7,Data On set to 1
Experiment Log Entry # 9,Ramp Segment 10 C/min to 100 Started
Experiment Log Entry # 11,Data On set to 0
Experiment Log Entry # 13,Isothermal Segment 1 min started
Experiment Log Entry # 15,Data On set to 1
Experiment Log Entry # 17,Ramp Segment 10 C/min to -60 Started
Experiment Log Entry # 19,Data On set to 0
Experiment Log Entry # 21,Isothermal Segment 1 min started
Experiment Log Entry # 23,Data On set to 1
Experiment Log Entry # 25,Ramp Segment 10 C/min to 100 Started
Experiment Log Entry # 27,Data On set to 0
Experiment Log Entry # 29,Isothermal Segment 1 min started
Experiment Log Entry # 31,Data On set to 1
Experiment Log Entry # 33,Ramp Segment 10 C/min to -60 Started
Experiment Log Entry # 35,Data On set to 0
Experiment Log Entry # 37,Isothermal Segment 1 min started
Experiment Log Entry # 39,Data On set to 1
Experiment Log Entry # 41,Ramp Segment 10 C/min to 100 Started
[Method Log]
Method Log Entry # 1,Data Off
Method Log Entry # 2,Equilibrate -60 °C
Method Log Entry # 3,Data On
Method Log Entry # 4,(Ramp 624596) Ramp 10 °C/minute to 100 °C
Method Log Entry # 5,Data Off
Method Log Entry # 6,Isothermal 1 minutes
Method Log Entry # 7,Data On
Method Log Entry # 8,(Ramp 624600) Ramp 10 °C/minute to -60 °C
Method Log Entry # 9,Data Off
Method Log Entry # 10,Isothermal 1 minutes
Method Log Entry # 11,Data On
Method Log Entry # 12,(Ramp 624604) Ramp 10 °C/minute to 100 °C
Method Log Entry # 13,Data Off
Method Log Entry # 14,Isothermal 1 minutes
Method Log Entry # 15,Data On
Method Log Entry # 16,(Ramp 624608) Ramp 10 °C/minute to -60 °C
Method Log Entry # 17,Data Off
Method Log Entry # 18,Isothermal 1 minutes
Method Log Entry # 19,Data On
Method Log Entry # 20,(Ramp 624612) Ramp 10 °C/minute to 100 °C
Cell Serial,DRC2-00792
[T1 Calibration]
Slope,-0.008529666
Offset,9.636258
Initial Temperature,98.23
GUID,f8bfdadc-4977-4fdf-ba6d-0ba9134940c3
[TZero Calibration]
Date Applied,11/29/2022 4:06:13 PM
Description,From -89.059 °C to 396.009 °C at 20.000°C/min
Gas Type,Nitrogen
Pan Type,None
Source Files 1,C:\Users\yargerlab\Desktop\DSC Data\General\TZero_calibration_11_29_22_2nd(2).tri
Source Files 2,C:\Users\yargerlab\Desktop\DSC Data\General\TZero_calibration_11_29_22_2nd(3).tri
Delta T Offset,13.05235
Delta T Slope,-0.007271007
Delta T0 Offset,-13.69128
Delta T0 Slope,0.06063341
[Temperature Calibration]
Date Applied,11/29/2022 7:12:28 PM
Description,From 106.590 °C to 186.590 °C at 10.000°C/min
Gas Type,Nitrogen
Pan Type,Tzero Aluminum Hermetic
Source Files 1,C:\Users\yargerlab\Desktop\DSC Data\General\Indium(6).tri
Measured 1,157.391
Known 1,156.598
[Cell Constant Calibration]
Date Applied,11/29/2022 7:12:29 PM
Description,From 106.590 °C to 186.590 °C at 10.000°C/min
Gas Type,Nitrogen
Pan Type,Tzero Aluminum Hermetic
Source Files 1,C:\Users\yargerlab\Desktop\DSC Data\General\Indium(6).tri
T4P KCell,1.006051
Onset Slope,63.26126 mW/°C
[Direct Cp Calibration]
Date Applied,11/30/2022 11:04:51 AM
Description,From -79.983 °C to 298.409 °C at 10.000°C/min
Gas Type,Nitrogen
Pan Type,Tzero Aluminum Hermetic
Source Files 1,C:\Users\yargerlab\Desktop\DSC Data\General\Sapphire_Heat_Capacity_11_30_22.tri
[Rev Cp Calibration]
Date Applied,11/30/2022 1:58:51 PM
Description,From -79.996 °C to 292.812 °C at 3.000°C/min
Gas Type,Nitrogen
Pan Type,Tzero Aluminum Hermetic
Source Files 1,C:\Users\yargerlab\Desktop\DSC Data\General\Sapphire_MDSC_Calibration_11_30_22.tri
[step]
Ramp 10.00 °C/min to 100.00 °C
Time,Temperature,Heat Flow (Normalized)
min,°C,W/g
0.00,-59.80,-0.127
0.01,-59.81,-0.126
0.02,-59.81,-0.125
0.03,-59.81,-0.124
0.05,-59.80,-0.117
0.06,-59.79,-0.104
0.07,-59.77,-0.074
0.08,-59.74,-0.037
0.09,-59.70,-0.003
0.11,-59.65,0.030
0.12,-59.59,0.058
0.13,-59.52,0.091
0.14,-59.44,0.115
0.15,-59.36,0.143
0.16,-59.26,0.164
0.18,-59.17,0.178
0.19,-59.07,0.196
0.20,-58.96,0.205
0.21,-58.85,0.216
0.22,-58.74,0.223
0.23,-58.63,0.230
0.24,-58.52,0.234
0.26,-58.40,0.238
0.27,-58.29,0.240
0.28,-58.18,0.242
0.29,-58.06,0.243
0.30,-57.95,0.244
0.31,-57.84,0.245
0.33,-57.72,0.246
0.34,-57.61,0.247
0.35,-57.49,0.249
0.36,-57.38,0.249
0.37,-57.27,0.250
0.39,-57.15,0.251
0.40,-57.04,0.251
0.41,-56.93,0.252
0.42,-56.81,0.252
0.43,-56.70,0.253
0.44,-56.58,0.254
0.45,-56.47,0.254
0.47,-56.35,0.255
0.48,-56.24,0.256
0.49,-56.13,0.256
0.50,-56.01,0.257
0.51,-55.90,0.258
0.53,-55.78,0.258
0.54,-55.67,0.259
0.55,-55.55,0.260
0.56,-55.44,0.260
0.57,-55.32,0.261
0.58,-55.21,0.262
0.60,-55.09,0.262
0.61,-54.98,0.263
0.62,-54.86,0.263
0.63,-54.75,0.264
0.64,-54.63,0.265
0.65,-54.52,0.265
0.67,-54.41,0.266
0.68,-54.29,0.267
0.69,-54.17,0.267
0.70,-54.06,0.267
0.71,-53.94,0.268
0.72,-53.83,0.268
0.73,-53.71,0.269
0.75,-53.60,0.270
0.76,-53.48,0.270
0.77,-53.37,0.271
0.78,-53.25,0.271
0.79,-53.14,0.272
0.80,-53.02,0.272
0.82,-52.91,0.272
0.83,-52.79,0.273
0.84,-52.67,0.273
0.85,-52.56,0.274
0.86,-52.45,0.274
0.88,-52.33,0.275
0.89,-52.21,0.275
0.90,-52.10,0.275
0.91,-51.98,0.276
0.92,-51.87,0.276
0.93,-51.75,0.276
0.95,-51.63,0.277
0.96,-51.52,0.277
0.97,-51.40,0.277
0.98,-51.29,0.278
0.99,-51.17,0.278
1.00,-51.06,0.278
1.02,-50.94,0.278
1.03,-50.82,0.278
1.04,-50.71,0.279
1.05,-50.59,0.279
1.06,-50.48,0.279
1.07,-50.36,0.279
1.08,-50.24,0.280
1.10,-50.13,0.280
1.11,-50.01,0.280
1.12,-49.90,0.281
1.13,-49.78,0.281
1.14,-49.66,0.281
1.16,-49.55,0.281
1.17,-49.43,0.281
1.18,-49.32,0.281
1.19,-49.20,0.281
1.20,-49.08,0.282
1.21,-48.97,0.282
1.23,-48.85,0.282
1.24,-48.74,0.282
1.25,-48.62,0.282
1.26,-48.50,0.282
1.27,-48.39,0.283
1.28,-48.27,0.283
1.29,-48.15,0.283
1.31,-48.04,0.283
1.32,-47.92,0.283
1.33,-47.80,0.283
1.34,-47.69,0.283
1.35,-47.57,0.283
1.37,-47.45,0.283
1.38,-47.34,0.284
1.39,-47.22,0.284
1.40,-47.11,0.284
1.41,-46.99,0.284
1.42,-46.87,0.284
1.43,-46.76,0.284
1.45,-46.64,0.284
1.46,-46.52,0.284
1.47,-46.41,0.284
1.48,-46.29,0.284
1.49,-46.17,0.284
1.51,-46.06,0.284
1.52,-45.94,0.284
1.53,-45.82,0.284
1.54,-45.71,0.284
1.55,-45.59,0.284
1.56,-45.47,0.284
1.58,-45.36,0.284
1.59,-45.24,0.284
1.60,-45.12,0.284
1.61,-45.01,0.284
1.62,-44.89,0.284
1.63,-44.77,0.284
1.64,-44.66,0.284
1.66,-44.54,0.284
1.67,-44.42,0.284
1.68,-44.31,0.284
1.69,-44.19,0.284
1.70,-44.07,0.284
1.72,-43.96,0.284
1.73,-43.84,0.284
1.74,-43.72,0.284
1.75,-43.61,0.284
1.76,-43.49,0.284
1.77,-43.38,0.284
1.78,-43.26,0.284
1.80,-43.14,0.284
1.81,-43.03,0.284
1.82,-42.91,0.284
1.83,-42.79,0.284
1.84,-42.68,0.284
1.86,-42.56,0.284
1.87,-42.44,0.284
1.88,-42.33,0.284
1.89,-42.21,0.284
1.90,-42.09,0.284
1.91,-41.97,0.284
1.93,-41.86,0.284
1.94,-41.74,0.284
1.95,-41.62,0.284
1.96,-41.51,0.284
1.97,-41.39,0.284
1.98,-41.27,0.284
1.99,-41.16,0.284
2.01,-41.04,0.284
2.02,-40.92,0.284
2.03,-40.81,0.284
2.04,-40.69,0.284
2.05,-40.57,0.284
2.07,-40.46,0.283
2.08,-40.34,0.283
2.09,-40.22,0.283
2.10,-40.11,0.283
2.11,-39.99,0.283
2.12,-39.87,0.283
2.14,-39.76,0.283
2.15,-39.64,0.283
2.16,-39.52,0.283
2.17,-39.41,0.283
2.18,-39.29,0.283
2.19,-39.17,0.283
2.21,-39.05,0.282
2.22,-38.94,0.282
2.23,-38.82,0.282
2.24,-38.71,0.282
2.25,-38.59,0.282
2.26,-38.47,0.282
2.28,-38.35,0.282
2.29,-38.24,0.282
2.30,-38.12,0.282
2.31,-38.00,0.282
2.32,-37.89,0.282
2.33,-37.77,0.281
2.34,-37.65,0.281
2.36,-37.54,0.281
2.37,-37.42,0.281
2.38,-37.30,0.281
2.39,-37.19,0.281
2.40,-37.07,0.281
2.41,-36.95,0.281
2.43,-36.84,0.281
2.44,-36.72,0.280
2.45,-36.60,0.280
2.46,-36.49,0.280
2.47,-36.37,0.280
2.49,-36.25,0.280
2.50,-36.14,0.280
2.51,-36.02,0.280
2.52,-35.90,0.280
2.53,-35.78,0.280
2.54,-35.67,0.280
2.56,-35.55,0.279
2.57,-35.43,0.279
2.58,-35.32,0.279
2.59,-35.20,0.279
2.60,-35.08,0.279
2.61,-34.97,0.279
2.63,-34.85,0.279
2.64,-34.73,0.279
2.65,-34.62,0.279
2.66,-34.50,0.279
2.67,-34.38,0.278
2.68,-34.27,0.278
2.69,-34.15,0.278
2.71,-34.03,0.278
2.72,-33.92,0.278
2.73,-33.80,0.278
2.74,-33.68,0.278
2.75,-33.57,0.278
2.76,-33.45,0.277
2.78,-33.33,0.277
2.79,-33.22,0.277
2.80,-33.10,0.277
2.81,-32.98,0.277
2.82,-32.86,0.277
2.84,-32.75,0.277
2.85,-32.63,0.277
2.86,-32.51,0.277
2.87,-32.40,0.277
2.88,-32.28,0.277
2.89,-32.16,0.276
2.91,-32.05,0.277
2.92,-31.93,0.276
2.93,-31.81,0.276
2.94,-31.70,0.276
2.95,-31.58,0.276
2.96,-31.46,0.276
2.98,-31.35,0.276
2.99,-31.23,0.276
3.00,-31.11,0.276
3.01,-31.00,0.276
3.02,-30.88,0.276
3.03,-30.76,0.276
3.04,-30.65,0.275
3.06,-30.53,0.275
3.07,-30.41,0.275
3.08,-30.29,0.275
3.09,-30.18,0.275
3.10,-30.06,0.275
3.11,-29.94,0.275
3.13,-29.83,0.275
3.14,-29.71,0.275
3.15,-29.60,0.274
3.16,-29.48,0.275
3.17,-29.36,0.274
3.19,-29.24,0.274
3.20,-29.13,0.274
3.21,-29.01,0.274
3.22,-28.89,0.274
3.23,-28.78,0.274
3.24,-28.66,0.274
3.26,-28.54,0.274
3.27,-28.43,0.273
3.28,-28.31,0.273
3.29,-28.19,0.273
3.30,-28.07,0.273
3.31,-27.96,0.273
3.33,-27.84,0.273
3.34,-27.72,0.273
3.35,-27.61,0.273
3.36,-27.49,0.273
3.37,-27.37,0.272
3.38,-27.26,0.272
3.39,-27.14,0.272
3.41,-27.02,0.272
3.42,-26.91,0.272
3.43,-26.79,0.272
3.44,-26.67,0.272
3.45,-26.56,0.272
3.46,-26.44,0.272
3.48,-26.32,0.272
3.49,-26.21,0.272
3.50,-26.09,0.272
3.51,-25.97,0.271
3.52,-25.85,0.271
3.54,-25.74,0.271
3.55,-25.62,0.271
3.56,-25.51,0.271
3.57,-25.39,0.271
3.58,-25.27,0.271
3.59,-25.15,0.271
3.61,-25.04,0.271
3.62,-24.92,0.271
3.63,-24.80,0.271
3.64,-24.69,0.271
3.65,-24.57,0.271
3.66,-24.45,0.271
3.68,-24.34,0.270
3.69,-24.22,0.270
3.70,-24.10,0.271
3.71,-23.98,0.270
3.72,-23.87,0.270
3.73,-23.75,0.270
3.74,-23.64,0.270
3.76,-23.52,0.270
3.77,-23.40,0.270
3.78,-23.29,0.270
3.79,-23.17,0.270
3.80,-23.05,0.270
3.81,-22.93,0.270
3.83,-22.82,0.270
3.84,-22.70,0.270
3.85,-22.58,0.270
3.86,-22.47,0.270
3.87,-22.35,0.270
3.89,-22.23,0.269
3.90,-22.12,0.269
3.91,-22.00,0.269
3.92,-21.88,0.269
3.93,-21.77,0.269
3.94,-21.65,0.269
3.96,-21.53,0.269
3.97,-21.42,0.269
3.98,-21.30,0.269
3.99,-21.18,0.269
4.00,-21.07,0.269
4.01,-20.95,0.269
4.03,-20.83,0.269
4.04,-20.72,0.269
4.05,-20.60,0.269
4.06,-20.48,0.269
4.07,-20.37,0.269
4.08,-20.25,0.269
4.09,-20.13,0.269
4.11,-20.02,0.269
4.12,-19.90,0.268
4.13,-19.78,0.268
4.14,-19.66,0.268
4.15,-19.55,0.268
4.16,-19.43,0.268
4.18,-19.31,0.268
4.19,-19.20,0.268
4.20,-19.08,0.268
4.21,-18.96,0.268
4.22,-18.85,0.268
4.24,-18.73,0.268
4.25,-18.61,0.268
4.26,-18.50,0.268
4.27,-18.38,0.268
4.28,-18.26,0.268
4.29,-18.15,0.268
4.30,-18.03,0.268
4.32,-17.91,0.268
4.33,-17.80,0.268
4.34,-17.68,0.267
4.35,-17.56,0.267
4.36,-17.44,0.267
4.38,-17.33,0.267
4.39,-17.21,0.267
4.40,-17.09,0.267
4.41,-16.98,0.267
4.42,-16.86,0.267
4.43,-16.74,0.267
4.45,-16.63,0.267
4.46,-16.51,0.267
4.47,-16.39,0.267
4.48,-16.28,0.267
4.49,-16.16,0.267
4.50,-16.04,0.267
4.51,-15.93,0.267
4.53,-15.81,0.267
4.54,-15.69,0.267
4.55,-15.58,0.267
4.56,-15.46,0.266
4.57,-15.34,0.267
4.59,-15.23,0.266
4.60,-15.11,0.266
4.61,-14.99,0.266
4.62,-14.87,0.266
4.63,-14.76,0.266
4.64,-14.64,0.266
4.65,-14.53,0.266
4.67,-14.41,0.266
4.68,-14.29,0.266
4.69,-14.18,0.266
4.70,-14.06,0.266
4.71,-13.94,0.266
4.73,-13.83,0.266
4.74,-13.71,0.266
4.75,-13.59,0.266
4.76,-13.48,0.266
4.77,-13.36,0.266
4.78,-13.24,0.266
4.80,-13.13,0.266
4.81,-13.01,0.266
4.82,-12.89,0.266
4.83,-12.78,0.266
4.84,-12.66,0.265
4.85,-12.54,0.265
4.86,-12.42,0.265
4.88,-12.31,0.265
4.89,-12.19,0.265
4.90,-12.07,0.265
4.91,-11.96,0.265
4.92,-11.84,0.265
4.94,-11.72,0.265
4.95,-11.61,0.265
4.96,-11.49,0.265
4.97,-11.37,0.265
4.98,-11.26,0.265
4.99,-11.14,0.265
5.00,-11.02,0.265
5.02,-10.91,0.265
5.03,-10.79,0.265
5.04,-10.67,0.265
5.05,-10.56,0.265
5.06,-10.44,0.265
5.08,-10.32,0.265
5.09,-10.21,0.265
5.10,-10.09,0.265
5.11,-9.97,0.265
5.12,-9.85,0.265
5.13,-9.74,0.265
5.15,-9.62,0.265
5.16,-9.50,0.265
5.17,-9.39,0.265
5.18,-9.27,0.265
5.19,-9.15,0.265
5.20,-9.04,0.265
5.21,-8.92,0.265
5.23,-8.80,0.265
5.24,-8.69,0.265
5.25,-8.57,0.265
5.26,-8.45,0.265
5.27,-8.34,0.265
5.29,-8.22,0.265
5.30,-8.10,0.265
5.31,-7.99,0.265
5.32,-7.87,0.265
5.33,-7.75,0.265
5.34,-7.64,0.265
5.35,-7.52,0.265
5.37,-7.40,0.265
5.38,-7.29,0.265
5.39,-7.17,0.265
5.40,-7.05,0.265
5.41,-6.93,0.265
5.43,-6.82,0.265
5.44,-6.70,0.265
5.45,-6.58,0.265
5.46,-6.47,0.265
5.47,-6.35,0.265
5.48,-6.23,0.265
5.50,-6.12,0.265
5.51,-6.00,0.265
5.52,-5.88,0.265
5.53,-5.77,0.265
5.54,-5.65,0.265
5.55,-5.53,0.265
5.56,-5.42,0.265
5.58,-5.30,0.265
5.59,-5.18,0.265
5.60,-5.07,0.265
5.61,-4.95,0.265
5.62,-4.83,0.265
5.64,-4.72,0.265
5.65,-4.60,0.265
5.66,-4.48,0.265
5.67,-4.37,0.265
5.68,-4.25,0.265
5.69,-4.13,0.265
5.70,-4.01,0.265
5.72,-3.90,0.265
5.73,-3.78,0.265
5.74,-3.66,0.265
5.75,-3.55,0.265
5.76,-3.43,0.265
5.78,-3.31,0.265
5.79,-3.20,0.265
5.80,-3.08,0.265
5.81,-2.96,0.265
5.82,-2.85,0.265
5.83,-2.73,0.265
5.85,-2.61,0.265
5.86,-2.50,0.265
5.87,-2.38,0.264
5.88,-2.26,0.265
5.89,-2.15,0.265
5.90,-2.03,0.265
5.91,-1.91,0.265
5.93,-1.80,0.265
5.94,-1.68,0.265
5.95,-1.56,0.265
5.96,-1.44,0.264
5.97,-1.33,0.264
5.99,-1.21,0.264
6.00,-1.09,0.264
6.01,-0.98,0.264
6.02,-0.86,0.264
6.03,-0.75,0.264
6.04,-0.63,0.264
6.05,-0.51,0.264
6.07,-0.39,0.264
6.08,-0.28,0.264
6.09,-0.16,0.265
6.10,-0.04,0.265
6.11,0.07,0.264
6.13,0.19,0.264
6.14,0.31,0.264
6.15,0.42,0.264
6.16,0.54,0.265
6.17,0.66,0.265
6.18,0.77,0.265
6.20,0.89,0.265
6.21,1.01,0.265
6.22,1.12,0.265
6.23,1.24,0.265
6.24,1.36,0.265
6.25,1.47,0.265
6.26,1.59,0.265
6.28,1.71,0.265
6.29,1.82,0.265
6.30,1.94,0.265
6.31,2.06,0.265
6.32,2.17,0.265
6.34,2.29,0.265
6.35,2.41,0.265
6.36,2.53,0.265
6.37,2.64,0.265
6.38,2.76,0.265
6.39,2.88,0.265
6.40,2.99,0.265
6.42,3.11,0.266
6.43,3.23,0.266
6.44,3.34,0.266
6.45,3.46,0.266
6.46,3.58,0.266
6.48,3.69,0.266
6.49,3.81,0.266
6.50,3.93,0.266
6.51,4.04,0.266
6.52,4.16,0.266
6.53,4.28,0.266
6.55,4.39,0.266
6.56,4.51,0.266
6.57,4.63,0.266
6.58,4.75,0.266
6.59,4.86,0.266
6.60,4.98,0.267
6.61,5.10,0.267
6.63,5.21,0.267
6.64,5.33,0.267
6.65,5.45,0.267
6.66,5.56,0.267
6.67,5.68,0.267
6.69,5.80,0.267
6.70,5.91,0.267
6.71,6.03,0.267
6.72,6.15,0.267
6.73,6.26,0.267
6.74,6.38,0.267
6.75,6.50,0.267
6.77,6.61,0.267
6.78,6.73,0.267
6.79,6.85,0.267
6.80,6.96,0.267
6.81,7.08,0.267
6.83,7.20,0.268
6.84,7.32,0.268
6.85,7.43,0.268
6.86,7.55,0.268
6.87,7.67,0.268
6.88,7.78,0.268
6.90,7.90,0.268
6.91,8.02,0.268
6.92,8.13,0.268
6.93,8.25,0.268
6.94,8.37,0.268
6.95,8.48,0.268
6.96,8.60,0.268
6.98,8.72,0.268
6.99,8.83,0.268
7.00,8.95,0.269
7.01,9.07,0.269
7.02,9.18,0.269
7.04,9.30,0.269
7.05,9.42,0.269
7.06,9.53,0.269
7.07,9.65,0.269
7.08,9.77,0.269
7.09,9.88,0.269
7.10,10.00,0.269
7.12,10.12,0.269
7.13,10.23,0.269
7.14,10.35,0.269
7.15,10.47,0.269
7.16,10.58,0.270
7.18,10.70,0.270
7.19,10.82,0.270
7.20,10.94,0.270
7.21,11.05,0.270
7.22,11.17,0.270
7.23,11.29,0.270
7.25,11.40,0.270
7.26,11.52,0.270
7.27,11.64,0.270
7.28,11.75,0.270
7.29,11.87,0.271
7.30,11.98,0.271
7.31,12.10,0.271
7.33,12.22,0.271
7.34,12.34,0.271
7.35,12.45,0.271
7.36,12.57,0.271
7.37,12.69,0.271
7.39,12.80,0.271
7.40,12.92,0.271
7.41,13.04,0.271
7.42,13.15,0.271
7.43,13.27,0.272
7.44,13.39,0.272
7.45,13.50,0.272
7.47,13.62,0.272
7.48,13.74,0.272
7.49,13.85,0.272
7.50,13.97,0.272
7.51,14.09,0.272
7.53,14.20,0.272
7.54,14.32,0.272
7.55,14.44,0.272
7.56,14.56,0.272
7.57,14.67,0.273
7.58,14.79,0.273
7.60,14.91,0.273
7.61,15.02,0.273
7.62,15.14,0.273
7.63,15.26,0.273
7.64,15.37,0.273
7.65,15.49,0.273
7.66,15.61,0.273
7.68,15.72,0.273
7.69,15.84,0.273
7.70,15.96,0.273
7.71,16.07,0.273
7.72,16.19,0.273
7.74,16.31,0.273
7.75,16.42,0.274
7.76,16.54,0.274
7.77,16.66,0.274
7.78,16.77,0.274
7.79,16.89,0.274
7.80,17.01,0.274
7.82,17.12,0.274
7.83,17.24,0.274
7.84,17.36,0.274
7.85,17.48,0.275
7.86,17.59,0.275
7.88,17.71,0.275
7.89,17.83,0.275
7.90,17.94,0.275
7.91,18.06,0.275
7.92,18.18,0.275
7.93,18.29,0.275
7.95,18.41,0.275
7.96,18.53,0.275
7.97,18.64,0.275
7.98,18.76,0.275
7.99,18.88,0.275
8.00,18.99,0.276
8.01,19.11,0.276
8.03,19.23,0.276
8.04,19.34,0.276
8.05,19.46,0.276
8.06,19.58,0.276
8.07,19.69,0.276
8.09,19.81,0.276
8.10,19.93,0.276
8.11,20.04,0.276
8.12,20.16,0.277
8.13,20.28,0.276
8.14,20.39,0.276
8.15,20.51,0.277
8.17,20.63,0.277
8.18,20.74,0.277
8.19,20.86,0.277
8.20,20.98,0.277
8.21,21.09,0.277
8.23,21.21,0.277
8.24,21.33,0.277
8.25,21.44,0.277
8.26,21.56,0.278
8.27,21.68,0.278
8.28,21.79,0.278
8.30,21.91,0.278
8.31,22.03,0.278
8.32,22.15,0.278
8.33,22.26,0.278
8.34,22.38,0.278
8.35,22.50,0.278
8.36,22.61,0.278
8.38,22.73,0.278
8.39,22.85,0.278
8.40,22.96,0.278
8.41,23.08,0.278
8.42,23.20,0.278
8.44,23.31,0.279
8.45,23.43,0.279
8.46,23.55,0.279
8.47,23.66,0.279
8.48,23.78,0.279
8.49,23.90,0.279
8.50,24.01,0.279
8.52,24.13,0.279
8.53,24.25,0.279
8.54,24.36,0.279
8.55,24.48,0.280
8.56,24.60,0.280
8.58,24.71,0.280
8.59,24.83,0.280
8.60,24.95,0.280
8.61,25.06,0.280
8.62,25.18,0.280
8.63,25.30,0.280
8.65,25.42,0.280
8.66,25.53,0.280
8.67,25.65,0.280
8.68,25.77,0.281
8.69,25.88,0.281
8.70,26.00,0.281
8.72,26.12,0.281
8.73,26.23,0.281
8.74,26.35,0.281
8.75,26.47,0.281
8.76,26.58,0.281
8.77,26.70,0.281
8.78,26.82,0.282
8.80,26.93,0.282
8.81,27.05,0.282
8.82,27.17,0.282
8.83,27.29,0.282
8.84,27.40,0.282
8.85,27.52,0.282
8.87,27.64,0.282
8.88,27.75,0.283
8.89,27.87,0.283
8.90,27.99,0.283
8.91,28.10,0.283
8.93,28.22,0.283
8.94,28.34,0.283
8.95,28.45,0.283
8.96,28.57,0.283
8.97,28.69,0.283
8.98,28.80,0.283
9.00,28.92,0.284
9.01,29.04,0.284
9.02,29.15,0.284
9.03,29.27,0.284
9.04,29.38,0.284
9.05,29.50,0.284
9.07,29.62,0.284
9.08,29.74,0.284
9.09,29.85,0.284
9.10,29.97,0.284
9.11,30.09,0.284
9.12,30.20,0.284
9.13,30.32,0.284
9.15,30.44,0.285
9.16,30.55,0.285
9.17,30.67,0.285
9.18,30.79,0.285
9.19,30.90,0.285
9.20,31.02,0.285
9.22,31.14,0.285
9.23,31.25,0.285
9.24,31.37,0.285
9.25,31.49,0.285
9.26,31.60,0.286
9.28,31.72,0.286
9.29,31.84,0.286
9.30,31.95,0.286
9.31,32.07,0.286
9.32,32.19,0.286
9.33,32.30,0.287
9.35,32.42,0.287
9.36,32.54,0.287
9.37,32.65,0.287
9.38,32.77,0.287
9.39,32.89,0.287
9.40,33.01,0.287
9.42,33.12,0.287
9.43,33.24,0.288
9.44,33.36,0.288
9.45,33.47,0.288
9.46,33.59,0.288
9.47,33.71,0.288
9.48,33.82,0.288
9.50,33.94,0.288
9.51,34.06,0.288
9.52,34.17,0.288
9.53,34.29,0.289
9.54,34.41,0.289
9.55,34.52,0.289
9.57,34.64,0.289
9.58,34.76,0.289
9.59,34.87,0.289
9.60,34.99,0.289
9.61,35.11,0.289
9.63,35.22,0.290
9.64,35.34,0.290
9.65,35.46,0.290
9.66,35.57,0.290
9.67,35.69,0.290
9.68,35.81,0.290
9.70,35.92,0.291
9.71,36.04,0.291
9.72,36.16,0.291
9.73,36.28,0.291
9.74,36.39,0.291
9.75,36.51,0.291
9.77,36.63,0.291
9.78,36.74,0.291
9.79,36.86,0.292
9.80,36.98,0.292
9.81,37.09,0.292
9.82,37.21,0.292
9.83,37.33,0.292
9.85,37.44,0.292
9.86,37.56,0.292
9.87,37.68,0.293
9.88,37.79,0.293
9.89,37.91,0.293
9.90,38.03,0.293
9.92,38.14,0.293
9.93,38.26,0.294
9.94,38.38,0.294
9.95,38.49,0.294
9.96,38.61,0.294
9.98,38.73,0.294
9.99,38.84,0.295
10.00,38.96,0.295
10.01,39.08,0.295
10.02,39.19,0.295
10.03,39.31,0.296
10.05,39.43,0.296
10.06,39.54,0.297
10.07,39.66,0.297
10.08,39.78,0.297
10.09,39.90,0.297
10.10,40.01,0.297
10.12,40.13,0.297
10.13,40.24,0.298
10.14,40.36,0.298
10.15,40.48,0.298
10.16,40.59,0.298
10.17,40.71,0.299
10.18,40.83,0.299
10.20,40.95,0.299
10.21,41.06,0.299
10.22,41.18,0.299
10.23,41.30,0.299
10.24,41.41,0.300
10.25,41.53,0.300
10.27,41.65,0.300
10.28,41.76,0.300
10.29,41.88,0.300
10.30,42.00,0.300
10.31,42.11,0.300
10.33,42.23,0.300
10.34,42.35,0.301
10.35,42.46,0.301
10.36,42.58,0.301
10.37,42.70,0.301
10.38,42.81,0.301
10.40,42.93,0.301
10.41,43.05,0.302
10.42,43.16,0.302
10.43,43.28,0.302
10.44,43.40,0.302
10.45,43.52,0.302
10.47,43.63,0.303
10.48,43.75,0.303
10.49,43.87,0.303
10.50,43.98,0.303
10.51,44.10,0.303
10.52,44.22,0.304
10.53,44.33,0.304
10.55,44.45,0.304
10.56,44.57,0.304
10.57,44.68,0.304
10.58,44.80,0.305
10.59,44.92,0.305
10.60,45.03,0.305
10.62,45.15,0.305
10.63,45.27,0.305
10.64,45.38,0.305
10.65,45.50,0.305
10.66,45.61,0.306
10.68,45.73,0.306
10.69,45.85,0.306
10.70,45.97,0.306
10.71,46.08,0.307
10.72,46.20,0.307
10.73,46.32,0.307
10.75,46.43,0.307
10.76,46.55,0.308
10.77,46.67,0.308
10.78,46.78,0.308
10.79,46.90,0.308
10.80,47.02,0.309
10.82,47.13,0.309
10.83,47.25,0.309
10.84,47.37,0.310
10.85,47.49,0.310
10.86,47.60,0.310
10.87,47.72,0.311
10.88,47.84,0.311
10.90,47.95,0.311
10.91,48.07,0.312
10.92,48.19,0.312
10.93,48.30,0.312
10.94,48.42,0.312
10.95,48.54,0.313
10.97,48.65,0.313
10.98,48.77,0.313
10.99,48.89,0.313
11.00,49.00,0.314
11.01,49.12,0.314
11.03,49.24,0.314
11.04,49.35,0.315
11.05,49.47,0.315
11.06,49.59,0.315
11.07,49.70,0.316
11.08,49.82,0.316
11.10,49.94,0.316
11.11,50.05,0.317
11.12,50.17,0.317
11.13,50.29,0.318
11.14,50.41,0.318
11.15,50.52,0.318
11.17,50.64,0.319
11.18,50.75,0.319
11.19,50.87,0.319
11.20,50.99,0.320
11.21,51.10,0.320
11.22,51.22,0.321
11.23,51.34,0.321
11.25,51.45,0.321
11.26,51.57,0.322
11.27,51.69,0.322
11.28,51.80,0.323
11.29,51.92,0.323
11.30,52.04,0.324
11.32,52.15,0.324
11.33,52.27,0.325
11.34,52.39,0.326
11.35,52.50,0.326
11.36,52.62,0.327
11.38,52.74,0.327
11.39,52.85,0.328
11.40,52.97,0.329
11.41,53.09,0.329
11.42,53.20,0.330
11.43,53.32,0.331
11.45,53.44,0.332
11.46,53.56,0.332
11.47,53.67,0.333
11.48,53.79,0.334
11.49,53.90,0.335
11.50,54.02,0.335
11.52,54.14,0.336
11.53,54.25,0.337
11.54,54.37,0.338
11.55,54.49,0.339
11.56,54.60,0.340
11.57,54.72,0.341
11.58,54.84,0.341
11.60,54.95,0.343
11.61,55.07,0.344
11.62,55.19,0.344
11.63,55.30,0.345
11.64,55.42,0.347
11.65,55.54,0.348
11.67,55.65,0.349
11.68,55.77,0.350
11.69,55.89,0.351
11.70,56.00,0.352
11.71,56.12,0.354
11.73,56.24,0.355
11.74,56.35,0.357
11.75,56.47,0.358
11.76,56.59,0.360
11.77,56.70,0.361
11.78,56.82,0.363
11.80,56.94,0.364
11.81,57.05,0.366
11.82,57.17,0.368
11.83,57.29,0.371
11.84,57.40,0.374
11.85,57.52,0.376
11.87,57.64,0.379
11.88,57.75,0.383
11.89,57.87,0.386
11.90,57.99,0.387
11.91,58.10,0.391
11.92,58.22,0.395
11.93,58.34,0.400
11.95,58.45,0.403
11.96,58.57,0.407
11.97,58.68,0.412
11.98,58.80,0.417
11.99,58.92,0.423
12.00,59.04,0.427
12.02,59.15,0.433
12.03,59.27,0.439
12.04,59.38,0.444
12.05,59.50,0.450
12.06,59.62,0.458
12.08,59.73,0.463
12.09,59.85,0.471
12.10,59.97,0.479
12.11,60.08,0.486
12.12,60.20,0.493
12.13,60.32,0.503
12.15,60.43,0.511
12.16,60.55,0.524
12.17,60.67,0.530
12.18,60.78,0.540
12.19,60.90,0.553
12.20,61.01,0.563
12.22,61.13,0.574
12.23,61.25,0.583
12.24,61.36,0.597
12.25,61.48,0.611
12.26,61.59,0.624
12.27,61.71,0.636
12.28,61.82,0.653
12.30,61.94,0.670
12.31,62.06,0.681
12.32,62.17,0.702
12.33,62.29,0.723
12.34,62.40,0.739
12.35,62.52,0.762
12.37,62.63,0.786
12.38,62.75,0.810
12.39,62.86,0.835
12.40,62.98,0.868
12.41,63.09,0.902
12.43,63.21,0.933
12.44,63.32,0.973
12.45,63.43,1.016
12.46,63.55,1.058
12.47,63.66,1.111
12.48,63.77,1.167
12.50,63.89,1.234
12.51,64.00,1.308
12.52,64.11,1.385
12.53,64.22,1.473
12.54,64.33,1.575
12.55,64.44,1.689
12.57,64.55,1.820
12.58,64.66,1.963
12.59,64.77,2.115
12.60,64.87,2.287
12.61,64.98,2.466
12.62,65.08,2.667
12.63,65.19,2.875
12.65,65.29,3.095
12.66,65.39,3.311
12.67,65.49,3.506
12.68,65.59,3.679
12.69,65.69,3.801
12.70,65.80,3.865
12.72,65.91,3.867
12.73,66.02,3.809
12.74,66.13,3.680
12.75,66.25,3.477
12.76,66.38,3.222
12.78,66.51,2.929
12.79,66.64,2.609
12.80,66.77,2.277
12.81,66.91,1.943
12.82,67.05,1.640
12.83,67.19,1.373
12.85,67.33,1.150
12.86,67.46,0.978
12.87,67.60,0.845
12.88,67.73,0.744
12.89,67.86,0.665
12.90,67.98,0.606
12.92,68.11,0.560
12.93,68.23,0.528
12.94,68.35,0.502
12.95,68.48,0.478
12.96,68.60,0.463
12.97,68.72,0.444
12.98,68.84,0.436
13.00,68.95,0.427
13.01,69.07,0.419
13.02,69.19,0.415
13.03,69.31,0.409
13.04,69.43,0.407
13.05,69.54,0.404
13.07,69.66,0.401
13.08,69.78,0.400
13.09,69.90,0.399
13.10,70.01,0.398
13.11,70.13,0.396
13.13,70.25,0.396
13.14,70.37,0.394
13.15,70.48,0.394
13.16,70.60,0.393
13.17,70.72,0.393
13.18,70.83,0.392
13.20,70.95,0.392
13.21,71.07,0.392
13.22,71.18,0.391
13.23,71.30,0.391
13.24,71.42,0.391
13.25,71.53,0.390
13.27,71.65,0.390
13.28,71.77,0.390
13.29,71.88,0.390
13.30,72.00,0.390
13.31,72.12,0.390
13.32,72.24,0.389
13.33,72.35,0.389
13.35,72.47,0.389
13.36,72.58,0.389
13.37,72.70,0.389
13.38,72.82,0.389
13.39,72.94,0.388
13.40,73.05,0.388
13.42,73.17,0.388
13.43,73.29,0.388
13.44,73.40,0.388
13.45,73.52,0.388
13.46,73.64,0.388
13.48,73.75,0.388
13.49,73.87,0.388
13.50,73.99,0.388
13.51,74.10,0.388
13.52,74.22,0.388
13.53,74.34,0.388
13.55,74.45,0.388
13.56,74.57,0.388
13.57,74.69,0.388
13.58,74.80,0.388
13.59,74.92,0.388
13.60,75.04,0.388
13.62,75.15,0.388
13.63,75.27,0.388
13.64,75.39,0.388
13.65,75.50,0.388
13.66,75.62,0.388
13.67,75.74,0.388
13.68,75.85,0.388
13.70,75.97,0.388
13.71,76.09,0.388
13.72,76.20,0.388
13.73,76.32,0.388
13.74,76.44,0.388
13.75,76.55,0.388
13.77,76.67,0.388
13.78,76.79,0.389
13.79,76.90,0.389
13.80,77.02,0.389
13.81,77.14,0.389
13.83,77.26,0.389
13.84,77.37,0.389
13.85,77.49,0.389
13.86,77.61,0.389
13.87,77.72,0.389
13.88,77.84,0.389
13.90,77.96,0.390
13.91,78.07,0.390
13.92,78.19,0.390
13.93,78.31,0.390
13.94,78.42,0.390
13.95,78.54,0.390
13.97,78.66,0.390
13.98,78.77,0.390
13.99,78.89,0.390
14.00,79.01,0.390
14.01,79.12,0.391
14.02,79.24,0.391
14.03,79.36,0.391
14.05,79.47,0.391
14.06,79.59,0.391
14.07,79.71,0.391
14.08,79.82,0.391
14.09,79.94,0.391
14.10,80.06,0.391
14.12,80.17,0.391
14.13,80.29,0.391
14.14,80.41,0.391
14.15,80.52,0.391
14.16,80.64,0.391
14.18,80.76,0.391
14.19,80.87,0.392
14.20,80.99,0.392
14.21,81.11,0.392
14.22,81.22,0.392
14.23,81.34,0.392
14.25,81.46,0.392
14.26,81.57,0.392
14.27,81.69,0.392
14.28,81.81,0.392
14.29,81.93,0.392
14.30,82.04,0.392
14.32,82.16,0.392
14.33,82.28,0.392
14.34,82.39,0.392
14.35,82.51,0.393
14.36,82.63,0.392
14.37,82.74,0.393
14.38,82.86,0.393
14.40,82.98,0.393
14.41,83.09,0.393
14.42,83.21,0.393
14.43,83.33,0.393
14.44,83.44,0.393
14.45,83.56,0.393
14.47,83.68,0.393
14.48,83.79,0.393
14.49,83.91,0.393
14.50,84.03,0.393
14.51,84.14,0.394
14.53,84.26,0.394
14.54,84.38,0.394
14.55,84.49,0.394
14.56,84.61,0.394
14.57,84.73,0.394
14.58,84.84,0.394
14.60,84.96,0.394
14.61,85.08,0.394
14.62,85.19,0.394
14.63,85.31,0.394
14.64,85.43,0.394
14.65,85.54,0.394
14.67,85.66,0.394
14.68,85.78,0.394
14.69,85.89,0.395
14.70,86.01,0.395
14.71,86.13,0.395
14.72,86.24,0.395
14.73,86.36,0.395
14.75,86.48,0.395
14.76,86.59,0.395
14.77,86.71,0.395
14.78,86.83,0.395
14.79,86.95,0.395
14.80,87.06,0.396
14.82,87.18,0.396
14.83,87.30,0.396
14.84,87.41,0.396
14.85,87.53,0.396
14.86,87.65,0.396
14.88,87.76,0.396
14.89,87.88,0.396
14.90,88.00,0.396
14.91,88.11,0.396
14.92,88.23,0.396
14.93,88.35,0.396
14.95,88.46,0.396
14.96,88.58,0.396
14.97,88.70,0.397
14.98,88.81,0.397
14.99,88.93,0.397
15.00,89.05,0.397
15.02,89.16,0.397
15.03,89.28,0.397
15.04,89.40,0.397
15.05,89.51,0.397
15.06,89.63,0.398
15.07,89.75,0.398
15.08,89.86,0.398
15.10,89.98,0.398
15.11,90.10,0.398
15.12,90.22,0.398
15.13,90.33,0.398
15.14,90.45,0.399
15.15,90.57,0.399
15.17,90.68,0.399
15.18,90.80,0.399
15.19,90.92,0.399
15.20,91.03,0.399
15.21,91.15,0.399
15.23,91.27,0.399
15.24,91.38,0.400
15.25,91.50,0.399
15.26,91.62,0.400
15.27,91.73,0.400
15.28,91.85,0.400
15.30,91.97,0.400
15.31,92.08,0.400
15.32,92.20,0.400
15.33,92.32,0.401
15.34,92.43,0.401
15.35,92.55,0.401
15.37,92.67,0.401
15.38,92.78,0.401
15.39,92.90,0.401
15.40,93.02,0.401
15.41,93.13,0.401
15.42,93.25,0.402
15.43,93.37,0.402
15.45,93.48,0.401
15.46,93.60,0.402
15.47,93.72,0.402
15.48,93.83,0.402
15.49,93.95,0.402
15.50,94.07,0.402
15.52,94.18,0.402
15.53,94.30,0.402
15.54,94.42,0.402
15.55,94.53,0.402
15.56,94.65,0.402
15.58,94.77,0.402
15.59,94.89,0.402
15.60,95.00,0.403
15.61,95.12,0.403
15.62,95.24,0.403
15.63,95.35,0.403
15.65,95.47,0.403
15.66,95.59,0.403
15.67,95.70,0.403
15.68,95.82,0.403
15.69,95.94,0.404
15.70,96.05,0.404
15.72,96.17,0.404
15.73,96.29,0.404
15.74,96.40,0.404
15.75,96.52,0.404
15.76,96.64,0.404
15.77,96.75,0.404
15.78,96.87,0.404
15.80,96.99,0.404
15.81,97.10,0.404
15.82,97.22,0.404
15.83,97.34,0.405
15.84,97.45,0.405
15.85,97.57,0.405
15.87,97.69,0.405
15.88,97.80,0.405
15.89,97.92,0.405
15.90,98.04,0.405
15.91,98.15,0.405
15.93,98.27,0.406
15.94,98.39,
15.95,98.50,
15.96,98.62,
15.97,98.74,
15.98,98.85,
15.99,,

[step]
Ramp 10.00 °C/min to -60.00 °C
Time,Temperature,Heat Flow (Normalized)
min,°C,W/g
16.99,100.12,-0.139
17.00,100.12,-0.139
17.02,100.12,-0.140
17.03,100.12,-0.140
17.04,100.11,-0.142
17.05,100.10,-0.163
17.06,100.07,-0.209
17.08,100.04,-0.266
17.09,99.99,-0.315
17.10,99.93,-0.368
17.11,99.86,-0.421
17.12,99.78,-0.466
17.13,99.69,-0.509
17.14,99.60,-0.535
17.16,99.50,-0.560
17.17,99.40,-0.585
17.18,99.29,-0.592
17.19,99.19,-0.602
17.20,99.08,-0.612
17.22,98.97,-0.618
17.23,98.86,-0.624
17.24,98.75,-0.630
17.25,98.64,-0.633
17.26,98.52,-0.638
17.27,98.41,-0.644
17.28,98.30,-0.648
17.30,98.18,-0.649
17.31,98.07,-0.652
17.32,97.96,-0.653
17.33,97.84,-0.655
17.34,97.72,-0.656
17.36,97.61,-0.658
17.37,97.50,-0.659
17.38,97.38,-0.660
17.39,97.26,-0.662
17.40,97.15,-0.663
17.41,97.04,-0.664
17.43,96.92,-0.664
17.44,96.80,-0.665
17.45,96.69,-0.666
17.46,96.57,-0.666
17.47,96.46,-0.667
17.48,96.34,-0.668
17.49,96.23,-0.669
17.51,96.11,-0.670
17.52,96.00,-0.670
17.53,95.88,-0.671
17.54,95.77,-0.672
17.55,95.65,-0.673
17.57,95.53,-0.674
17.58,95.42,-0.674
17.59,95.30,-0.675
17.60,95.19,-0.676
17.61,95.07,-0.676
17.62,94.96,-0.677
17.63,94.84,-0.678
17.65,94.72,-0.678
17.66,94.61,-0.679
17.67,94.49,-0.680
17.68,94.38,-0.681
17.69,94.26,-0.681
17.71,94.15,-0.682
17.72,94.03,-0.682
17.73,93.91,-0.683
17.74,93.80,-0.683
17.75,93.68,-0.684
17.76,93.57,-0.684
17.78,93.45,-0.685
17.79,93.34,-0.685
17.80,93.22,-0.686
17.81,93.10,-0.686
17.82,92.99,-0.687
17.83,92.87,-0.687
17.84,92.75,-0.687
17.86,92.64,-0.687
17.87,92.52,-0.688
17.88,92.41,-0.688
17.89,92.29,-0.689
17.90,92.17,-0.689
17.92,92.06,-0.689
17.93,91.94,-0.690
17.94,91.82,-0.690
17.95,91.71,-0.690
17.96,91.59,-0.690
17.97,91.47,-0.690
17.98,91.36,-0.691
18.00,91.24,-0.691
18.01,91.13,-0.691
18.02,91.01,-0.691
18.03,90.89,-0.691
18.04,90.78,-0.692
18.06,90.66,-0.692
18.07,90.55,-0.692
18.08,90.43,-0.692
18.09,90.31,-0.692
18.10,90.19,-0.692
18.11,90.08,-0.692
18.13,89.96,-0.692
18.14,89.85,-0.692
18.15,89.73,-0.692
18.16,89.61,-0.692
18.17,89.50,-0.692
18.18,89.38,-0.692
18.19,89.27,-0.692
18.21,89.15,-0.692
18.22,89.03,-0.692
18.23,88.91,-0.692
18.24,88.80,-0.692
18.25,88.68,-0.692
18.27,88.57,-0.692
18.28,88.45,-0.692
18.29,88.33,-0.692
18.30,88.22,-0.692
18.31,88.10,-0.691
18.32,87.99,-0.691
18.33,87.87,-0.691
18.35,87.75,-0.691
18.36,87.63,-0.691
18.37,87.52,-0.691
18.38,87.40,-0.691
18.39,87.29,-0.691
18.41,87.17,-0.691
18.42,87.05,-0.690
18.43,86.94,-0.691
18.44,86.82,-0.690
18.45,86.70,-0.690
18.46,86.59,-0.690
18.48,86.47,-0.690
18.49,86.35,-0.690
18.50,86.24,-0.690
18.51,86.12,-0.690
18.52,86.00,-0.690
18.53,85.89,-0.690
18.54,85.77,-0.689
18.56,85.65,-0.689
18.57,85.54,-0.689
18.58,85.42,-0.689
18.59,85.30,-0.689
18.60,85.19,-0.689
18.62,85.07,-0.688
18.63,84.95,-0.688
18.64,84.84,-0.688
18.65,84.72,-0.688
18.66,84.60,-0.688
18.67,84.49,-0.688
18.68,84.37,-0.687
18.70,84.26,-0.687
18.71,84.14,-0.687
18.72,84.02,-0.687
18.73,83.91,-0.687
18.74,83.79,-0.687
18.76,83.67,-0.687
18.77,83.56,-0.686
18.78,83.44,-0.686
18.79,83.32,-0.686
18.80,83.21,-0.686
18.81,83.09,-0.686
18.83,82.97,-0.686
18.84,82.86,-0.686
18.85,82.74,-0.686
18.86,82.62,-0.685
18.87,82.51,-0.685
18.88,82.39,-0.685
18.89,82.27,-0.685
18.91,82.16,-0.685
18.92,82.04,-0.685
18.93,81.92,-0.685
18.94,81.81,-0.685
18.95,81.69,-0.685
18.97,81.57,-0.685
18.98,81.46,-0.684
18.99,81.34,-0.684
19.00,81.22,-0.684
19.01,81.11,-0.684
19.02,80.99,-0.684
19.03,80.87,-0.684
19.05,80.76,-0.684
19.06,80.64,-0.683
19.07,80.52,-0.683
19.08,80.41,-0.683
19.09,80.29,-0.683
19.11,80.18,-0.683
19.12,80.06,-0.683
19.13,79.94,-0.683
19.14,79.82,-0.683
19.15,79.71,-0.683
19.16,79.59,-0.682
19.18,79.48,-0.682
19.19,79.36,-0.682
19.20,79.24,-0.682
19.21,79.13,-0.682
19.22,79.01,-0.682
19.23,78.89,-0.682
19.24,78.78,-0.682
19.26,78.66,-0.682
19.27,78.54,-0.682
19.28,78.43,-0.682
19.29,78.31,-0.681
19.30,78.19,-0.681
19.32,78.08,-0.681
19.33,77.96,-0.681
19.34,77.84,-0.681
19.35,77.73,-0.680
19.36,77.61,-0.680
19.37,77.49,-0.680
19.38,77.38,-0.680
19.40,77.26,-0.680
19.41,77.14,-0.680
19.42,77.03,-0.680
19.43,76.91,-0.680
19.44,76.79,-0.679
19.46,76.68,-0.679
19.47,76.56,-0.679
19.48,76.44,-0.679
19.49,76.33,-0.679
19.50,76.21,-0.678
19.51,76.09,-0.678
19.53,75.98,-0.678
19.54,75.86,-0.678
19.55,75.74,-0.678
19.56,75.63,-0.678
19.57,75.51,-0.678
19.58,75.39,-0.677
19.59,75.28,-0.677
19.61,75.16,-0.677
19.62,75.04,-0.677
19.63,74.93,-0.677
19.64,74.81,-0.677
19.65,74.69,-0.677
19.67,74.58,-0.676
19.68,74.46,-0.676
19.69,74.34,-0.676
19.70,74.23,-0.676
19.71,74.11,-0.675
19.72,73.99,-0.675
19.73,73.88,-0.675
19.75,73.76,-0.675
19.76,73.64,-0.675
19.77,73.53,-0.675
19.78,73.41,-0.675
19.79,73.29,-0.674
19.81,73.18,-0.674
19.82,73.06,-0.674
19.83,72.94,-0.674
19.84,72.83,-0.674
19.85,72.71,-0.674
19.86,72.59,-0.673
19.88,72.48,-0.673
19.89,72.36,-0.673
19.90,72.24,-0.673
19.91,72.13,-0.673
19.92,72.01,-0.673
19.93,71.89,-0.673
19.94,71.78,-0.672
19.96,71.66,-0.672
19.97,71.54,-0.672
19.98,71.43,-0.672
19.99,71.31,-0.672
20.00,71.19,-0.672
20.02,71.08,-0.672
20.03,70.96,-0.671
20.04,70.85,-0.671
20.05,70.73,-0.671
20.06,70.61,-0.671
20.07,70.50,-0.671
20.08,70.38,-0.671
20.10,70.26,-0.671
20.11,70.15,-0.671
20.12,70.03,-0.670
20.13,69.91,-0.670
20.14,69.80,-0.670
20.16,69.68,-0.670
20.17,69.56,-0.670
20.18,69.44,-0.670
20.19,69.33,-0.669
20.20,69.21,-0.669
20.21,69.10,-0.669
20.23,68.98,-0.669
20.24,68.86,-0.669
20.25,68.75,-0.669
20.26,68.63,-0.668
20.27,68.51,-0.668
20.28,68.39,-0.668
20.29,68.28,-0.668
20.31,68.16,-0.668
20.32,68.05,-0.668
20.33,67.93,-0.668
20.34,67.81,-0.667
20.35,67.70,-0.667
20.37,67.58,-0.667
20.38,67.46,-0.667
20.39,67.35,-0.667
20.40,67.23,-0.667
20.41,67.11,-0.666
20.42,67.00,-0.666
20.43,66.88,-0.666
20.45,66.76,-0.666
20.46,66.65,-0.666
20.47,66.53,-0.666
20.48,66.41,-0.666
20.49,66.30,-0.665
20.51,66.18,-0.665
20.52,66.06,-0.665
20.53,65.95,-0.665
20.54,65.83,-0.665
20.55,65.71,-0.665
20.56,65.60,-0.665
20.58,65.48,-0.665
20.59,65.36,-0.664
20.60,65.25,-0.664
20.61,65.13,-0.664
20.62,65.01,-0.664
20.63,64.90,-0.664
20.64,64.78,-0.664
20.66,64.66,-0.663
20.67,64.55,-0.663
20.68,64.43,-0.663
20.69,64.32,-0.663
20.70,64.20,-0.663
20.72,64.08,-0.663
20.73,63.96,-0.663
20.74,63.85,-0.662
20.75,63.73,-0.660
20.76,63.61,-0.660
20.77,63.50,-0.660
20.78,63.38,-0.659
20.80,63.26,-0.659
20.81,63.15,-0.659
20.82,63.03,-0.659
20.83,62.91,-0.659
20.84,62.80,-0.659
20.86,62.68,-0.659
20.87,62.56,-0.659
20.88,62.45,-0.659
20.89,62.33,-0.659
20.90,62.21,-0.659
20.91,62.10,-0.659
20.93,61.98,-0.659
20.94,61.87,-0.659
20.95,61.75,-0.659
20.96,61.63,-0.658
20.97,61.51,-0.658
20.98,61.40,-0.658
20.99,61.28,-0.658
21.01,61.16,-0.658
21.02,61.05,-0.658
21.03,60.93,-0.658
21.04,60.82,-0.658
21.05,60.70,-0.658
21.07,60.58,-0.658
21.08,60.47,-0.658
21.09,60.35,-0.658
21.10,60.23,-0.658
21.11,60.11,-0.658
21.12,60.00,-0.658
21.13,59.88,-0.658
21.15,59.77,-0.657
21.16,59.65,-0.657
21.17,59.53,-0.657
21.18,59.42,-0.657
21.19,59.30,-0.657
21.21,59.18,-0.657
21.22,59.07,-0.657
21.23,58.95,-0.657
21.24,58.83,-0.656
21.25,58.72,-0.656
21.26,58.60,-0.656
21.28,58.48,-0.656
21.29,58.37,-0.656
21.30,58.25,-0.656
21.31,58.13,-0.656
21.32,58.02,-0.656
21.33,57.90,-0.655
21.34,57.78,-0.655
21.36,57.67,-0.655
21.37,57.55,-0.655
21.38,57.43,-0.655
21.39,57.32,-0.655
21.40,57.20,-0.655
21.42,57.08,-0.655
21.43,56.97,-0.654
21.44,56.85,-0.654
21.45,56.73,-0.654
21.46,56.62,-0.654
21.47,56.50,-0.654
21.48,56.38,-0.654
21.50,56.27,-0.654
21.51,56.15,-0.654
21.52,56.03,-0.654
21.53,55.92,-0.653
21.54,55.80,-0.653
21.56,55.68,-0.653
21.57,55.57,-0.653
21.58,55.45,-0.653
21.59,55.33,-0.653
21.60,55.22,-0.653
21.61,55.10,-0.653
21.63,54.98,-0.652
21.64,54.87,-0.652
21.65,54.75,-0.652
21.66,54.63,-0.652
21.67,54.52,-0.652
21.68,54.40,-0.652
21.69,54.28,-0.652
21.71,54.17,-0.652
21.72,54.05,-0.651
21.73,53.93,-0.651
21.74,53.82,-0.651
21.75,53.70,-0.651
21.77,53.58,-0.651
21.78,53.47,-0.651
21.79,53.35,-0.651
21.80,53.23,-0.651
21.81,53.12,-0.651
21.82,53.00,-0.650
21.83,52.88,-0.650
21.85,52.77,-0.650
21.86,52.65,-0.650
21.87,52.54,-0.650
21.88,52.42,-0.650
21.89,52.30,-0.650
21.91,52.18,-0.650
21.92,52.07,-0.650
21.93,51.95,-0.650
21.94,51.83,-0.649
21.95,51.72,-0.649
21.96,51.60,-0.649
21.98,51.48,-0.649
21.99,51.37,-0.649
22.00,51.25,-0.649
22.01,51.14,-0.649
22.02,51.02,-0.649
22.03,50.90,-0.648
22.04,50.79,-0.648
22.06,50.67,-0.648
22.07,50.55,-0.648
22.08,50.44,-0.648
22.09,50.32,-0.648
22.10,50.20,-0.648
22.12,50.08,-0.648
22.13,49.97,-0.648
22.14,49.85,-0.648
22.15,49.74,-0.647
22.16,49.62,-0.647
22.17,49.50,-0.647
22.18,49.39,-0.647
22.20,49.27,-0.647
22.21,49.15,-0.647
22.22,49.03,-0.647
22.23,48.92,-0.646
22.24,48.80,-0.644
22.26,48.68,-0.644
22.27,48.57,-0.644
22.28,48.45,-0.644
22.29,48.33,-0.644
22.30,48.22,-0.644
22.31,48.10,-0.644
22.33,47.98,-0.643
22.34,47.87,-0.643
22.35,47.75,-0.643
22.36,47.63,-0.643
22.37,47.52,-0.643
22.38,47.40,-0.643
22.39,47.29,-0.643
22.41,47.17,-0.643
22.42,47.05,-0.643
22.43,46.94,-0.643
22.44,46.82,-0.643
22.45,46.70,-0.643
22.47,46.59,-0.643
22.48,46.47,-0.643
22.49,46.35,-0.643
22.50,46.24,-0.643
22.51,46.12,-0.642
22.52,46.00,-0.642
22.53,45.89,-0.642
22.55,45.77,-0.642
22.56,45.65,-0.642
22.57,45.54,-0.642
22.58,45.42,-0.642
22.59,45.30,-0.642
22.61,45.19,-0.642
22.62,45.07,-0.641
22.63,44.95,-0.642
22.64,44.84,-0.641
22.65,44.72,-0.641
22.66,44.60,-0.641
22.68,44.49,-0.641
22.69,44.37,-0.641
22.70,44.25,-0.641
22.71,44.14,-0.641
22.72,44.02,-0.641
22.73,43.90,-0.641
22.74,43.79,-0.640
22.76,43.67,-0.640
22.77,43.55,-0.640
22.78,43.44,-0.640
22.79,43.32,-0.640
22.80,43.20,-0.640
22.82,43.09,-0.640
22.83,42.97,-0.640
22.84,42.85,-0.640
22.85,42.74,-0.639
22.86,42.62,-0.639
22.87,42.50,-0.639
22.88,42.39,-0.639
22.90,42.27,-0.639
22.91,42.15,-0.639
[...]
71.09,-30.30,0.273
71.10,-30.19,0.273
71.11,-30.07,0.273
71.12,-29.95,0.273
71.13,-29.84,0.273
71.14,-29.72,0.273
71.15,-29.60,0.273
71.17,-29.49,0.273
71.18,-29.37,0.273
71.19,-29.25,0.273
71.20,-29.14,0.273
71.21,-29.02,0.273
71.23,-28.90,0.273
71.24,-28.79,0.273
71.25,-28.67,0.273
71.26,-28.55,0.273
71.27,-28.44,0.273
71.28,-28.32,0.273
71.30,-28.20,0.273
71.31,-28.09,0.273
71.32,-27.97,0.273
71.33,-27.85,0.273
71.34,-27.73,0.273
71.35,-27.62,0.273
71.36,-27.50,0.273
71.38,-27.38,0.273
71.39,-27.27,0.273
71.40,-27.15,0.273
71.41,-27.03,0.273
71.42,-26.92,0.273
71.44,-26.80,0.273
71.45,-26.68,0.273
71.46,-26.57,0.273
71.47,-26.45,0.273
71.48,-26.33,0.273
71.49,-26.22,0.273
71.50,-26.10,0.273
71.52,-25.98,0.273
71.53,-25.87,0.273
71.54,-25.75,0.273
71.55,-25.63,0.273
71.56,-25.52,0.273
71.58,-25.40,0.273
71.59,-25.28,0.273
71.60,-25.17,0.273
71.61,-25.05,0.273
71.62,-24.93,0.273
71.63,-24.81,0.273
71.65,-24.70,0.273
71.66,-24.58,0.273
71.67,-24.46,0.273
71.68,-24.35,0.273
71.69,-24.23,0.273
71.70,-24.11,0.273
71.71,-24.00,0.273
71.73,-23.88,0.273
71.74,-23.76,0.273
71.75,-23.65,0.273
71.76,-23.53,0.273
71.77,-23.41,0.273
71.79,-23.30,0.273
71.80,-23.18,0.273
71.81,-23.06,0.273
71.82,-22.95,0.273
71.83,-22.83,0.273
71.84,-22.71,0.273
71.85,-22.60,0.273
71.87,-22.48,0.273
71.88,-22.36,0.273
71.89,-22.25,0.273
71.90,-22.13,0.274
71.91,-22.01,0.274
71.93,-21.90,0.274
71.94,-21.78,0.274
71.95,-21.66,0.274
71.96,-21.55,0.274
71.97,-21.43,0.274
71.98,-21.31,0.274
72.00,-21.19,0.274
72.01,-21.08,0.274
72.02,-20.96,0.275
72.03,-20.84,0.275
72.04,-20.73,0.275
72.05,-20.61,0.275
72.06,-20.49,0.275
72.08,-20.38,0.275
72.09,-20.26,0.275
72.10,-20.14,0.275
72.11,-20.03,0.276
72.12,-19.91,0.276
72.14,-19.79,0.276
72.15,-19.68,0.276
72.16,-19.56,0.276
72.17,-19.44,0.277
72.18,-19.33,0.277
72.19,-19.21,0.277
72.20,-19.09,0.277
72.22,-18.98,0.277
72.23,-18.86,0.277
72.24,-18.74,0.278
72.25,-18.63,0.278
72.26,-18.51,0.278
72.28,-18.39,0.278
72.29,-18.28,0.278
72.30,-18.16,0.279
72.31,-18.04,0.279
72.32,-17.93,0.279
72.33,-17.81,0.279
72.35,-17.69,0.279
72.36,-17.57,0.280
72.37,-17.46,0.280
72.38,-17.34,0.280
72.39,-17.22,0.281
72.40,-17.11,0.281
72.41,-16.99,0.281
72.43,-16.87,0.282
72.44,-16.76,0.282
72.45,-16.64,0.282
72.46,-16.53,0.283
72.47,-16.41,0.283
72.49,-16.29,0.284
72.50,-16.17,0.284
72.51,-16.06,0.284
72.52,-15.94,0.285
72.53,-15.82,0.285
72.54,-15.71,0.286
72.55,-15.59,0.286
72.57,-15.47,0.287
72.58,-15.36,0.287
72.59,-15.24,0.288
72.60,-15.12,0.288
72.61,-15.01,0.289
72.63,-14.89,0.290
72.64,-14.77,0.290
72.65,-14.66,0.291
72.66,-14.54,0.292
72.67,-14.42,0.292
72.68,-14.31,0.293
72.70,-14.19,0.294
72.71,-14.07,0.295
72.72,-13.96,0.296
72.73,-13.84,0.297
72.74,-13.72,0.298
72.75,-13.61,0.299
72.76,-13.49,0.300
72.78,-13.37,0.301
72.79,-13.26,0.302
72.80,-13.14,0.303
72.81,-13.02,0.304
72.82,-12.91,0.305
72.84,-12.79,0.306
72.85,-12.67,0.307
72.86,-12.56,0.309
72.87,-12.44,0.310
72.88,-12.32,0.311
72.89,-12.21,0.312
72.90,-12.09,0.314
72.92,-11.97,0.315
72.93,-11.86,0.316
72.94,-11.74,0.318
72.95,-11.62,0.319
72.96,-11.51,0.320
72.98,-11.39,0.322
72.99,-11.27,0.323
73.00,-11.16,0.324
73.01,-11.04,0.326
73.02,-10.92,0.327
73.03,-10.81,0.328
73.05,-10.69,0.330
73.06,-10.57,0.331
73.07,-10.46,0.332
73.08,-10.34,0.333
73.09,-10.22,0.334
73.10,-10.11,0.335
73.11,-9.99,0.336
73.13,-9.87,0.337
73.14,-9.76,0.338
73.15,-9.64,0.339
73.16,-9.52,0.340
73.17,-9.41,0.341
73.19,-9.29,0.341
73.20,-9.17,0.342
73.21,-9.06,0.343
73.22,-8.94,0.343
73.23,-8.82,0.344
73.24,-8.71,0.344
73.25,-8.59,0.344
73.27,-8.47,0.345
73.28,-8.35,0.345
73.29,-8.24,0.345
73.30,-8.12,0.346
73.31,-8.00,0.346
73.33,-7.89,0.346
73.34,-7.77,0.346
73.35,-7.65,0.346
73.36,-7.54,0.346
73.37,-7.42,0.346
73.38,-7.30,0.346
73.40,-7.19,0.346
73.41,-7.07,0.346
73.42,-6.95,0.346
73.43,-6.84,0.346
73.44,-6.72,0.346
73.45,-6.60,0.346
73.46,-6.49,0.346
73.48,-6.37,0.345
73.49,-6.25,0.345
73.50,-6.14,0.345
73.51,-6.02,0.345
73.52,-5.90,0.345
73.54,-5.79,0.345
73.55,-5.67,0.345
73.56,-5.55,0.345
73.57,-5.43,0.345
73.58,-5.32,0.345
73.59,-5.20,0.344
73.60,-5.08,0.344
73.62,-4.97,0.344
73.63,-4.85,0.344
73.64,-4.73,0.344
73.65,-4.62,0.344
73.66,-4.50,0.344
73.68,-4.38,0.343
73.69,-4.27,0.343
73.70,-4.15,0.343
73.71,-4.03,0.343
73.72,-3.92,0.343
73.73,-3.80,0.343
73.75,-3.68,0.343
73.76,-3.57,0.343
73.77,-3.45,0.343
73.78,-3.33,0.343
73.79,-3.21,0.343
73.80,-3.10,0.343
73.81,-2.98,0.343
73.83,-2.86,0.343
73.84,-2.75,0.343
73.85,-2.63,0.342
73.86,-2.51,0.342
73.87,-2.40,0.342
73.89,-2.28,0.342
73.90,-2.16,0.342
73.91,-2.05,0.342
73.92,-1.93,0.342
73.93,-1.81,0.342
73.94,-1.70,0.342
73.95,-1.58,0.342
73.97,-1.46,0.342
73.98,-1.35,0.342
73.99,-1.23,0.341
74.00,-1.11,0.342
74.01,-1.00,0.341
74.03,-0.88,0.341
74.04,-0.76,0.341
74.05,-0.65,0.341
74.06,-0.53,0.341
74.07,-0.41,0.341
74.08,-0.30,0.342
74.10,-0.18,0.341
74.11,-0.06,0.342
74.12,0.06,0.341
74.13,0.17,0.341
74.14,0.29,0.341
74.15,0.41,0.341
74.16,0.52,0.341
74.18,0.64,0.341
74.19,0.76,0.341
74.20,0.87,0.341
74.21,0.99,0.341
74.22,1.11,0.341
74.24,1.22,0.341
74.25,1.34,0.341
74.26,1.46,0.341
74.27,1.57,0.341
74.28,1.69,0.341
74.29,1.81,0.341
74.30,1.93,0.341
74.32,2.04,0.341
74.33,2.16,0.341
74.34,2.27,0.341
74.35,2.39,0.342
74.36,2.51,0.342
74.38,2.63,0.342
74.39,2.74,0.342
74.40,2.86,0.342
74.41,2.98,0.342
74.42,3.09,0.342
74.43,3.21,0.342
74.45,3.33,0.342
74.46,3.44,0.342
74.47,3.56,0.342
74.48,3.68,0.342
74.49,3.79,0.342
74.50,3.91,0.342
74.51,4.03,0.342
74.53,4.14,0.342
74.54,4.26,0.342
74.55,4.38,0.342
74.56,4.49,0.342
74.57,4.61,0.342
74.59,4.73,0.342
74.60,4.84,0.343
74.61,4.96,0.342
74.62,5.08,0.342
74.63,5.19,0.342
74.64,5.31,0.343
74.65,5.43,0.343
74.67,5.54,0.343
74.68,5.66,0.343
74.69,5.78,0.343
74.70,5.89,0.343
74.71,6.01,0.343
74.73,6.13,0.343
74.74,6.25,0.343
74.75,6.36,0.343
74.76,6.48,0.343
74.77,6.60,0.344
74.78,6.71,0.344
74.80,6.83,0.344
74.81,6.95,0.344
74.82,7.06,0.344
74.83,7.18,0.344
74.84,7.30,0.344
74.85,7.41,0.344
74.86,7.53,0.344
74.88,7.65,0.344
74.89,7.76,0.344
74.90,7.88,0.344
74.91,8.00,0.345
74.92,8.11,0.344
74.94,8.23,0.345
74.95,8.35,0.345
74.96,8.47,0.345
74.97,8.58,0.345
74.98,8.70,0.345
74.99,8.82,0.345
75.00,8.93,0.345
75.02,9.05,0.345
75.03,9.17,0.345
75.04,9.28,0.345
75.05,9.40,0.345
75.06,9.52,0.345
75.08,9.63,0.345
75.09,9.75,0.345
75.10,9.87,0.345
75.11,9.98,0.345
75.12,10.10,0.345
75.13,10.22,0.346
75.15,10.33,0.346
75.16,10.45,0.346
75.17,10.57,0.346
75.18,10.68,0.346
75.19,10.80,0.346
75.20,10.92,0.346
75.21,11.03,0.346
75.23,11.15,0.346
75.24,11.27,0.346
75.25,11.38,0.346
75.26,11.50,0.346
75.27,11.62,0.346
75.29,11.73,0.346
75.30,11.85,0.346
75.31,11.97,0.346
75.32,12.09,0.347
75.33,12.20,0.347
75.34,12.32,0.347
75.35,12.44,0.347
75.37,12.55,0.347
75.38,12.67,0.347
75.39,12.79,0.347
75.40,12.90,0.347
75.41,13.02,0.347
75.43,13.14,0.347
75.44,13.25,0.347
75.45,13.37,0.347
75.46,13.49,0.347
75.47,13.60,0.347
75.48,13.72,0.347
75.50,13.84,0.347
75.51,13.95,0.347
75.52,14.07,0.347
75.53,14.19,0.347
75.54,14.30,0.347
75.55,14.42,0.348
75.56,14.54,0.348
75.58,14.65,0.348
75.59,14.77,0.348
75.60,14.89,0.348
75.61,15.01,0.348
75.62,15.12,0.348
75.64,15.24,0.348
75.65,15.36,0.348
75.66,15.47,0.348
75.67,15.59,0.348
75.68,15.71,0.348
75.69,15.82,0.348
75.70,15.94,0.348
75.72,16.06,0.348
75.73,16.17,0.348
75.74,16.29,0.348
75.75,16.41,0.348
75.76,16.52,0.348
75.78,16.64,0.348
75.79,16.76,0.348
75.80,16.87,0.348
75.81,16.99,0.349
75.82,17.11,0.348
75.83,17.22,0.349
75.85,17.34,0.349
75.86,17.46,0.349
75.87,17.57,0.349
75.88,17.69,0.349
75.89,17.81,0.349
75.90,17.92,0.349
75.91,18.04,0.349
75.93,18.16,0.349
75.94,18.27,0.349
75.95,18.39,0.349
75.96,18.51,0.349
75.97,18.63,0.349
75.99,18.74,0.349
76.00,18.86,0.349
76.01,18.98,0.349
76.02,19.09,0.349
76.03,19.21,0.349
76.04,19.33,0.349
76.05,19.44,0.350
76.07,19.56,0.350
76.08,19.68,0.349
76.09,19.79,0.349
76.10,19.91,0.350
76.11,20.03,0.350
76.13,20.14,0.350
76.14,20.26,0.350
76.15,20.38,0.350
76.16,20.50,0.350
76.17,20.61,0.350
76.18,20.73,0.350
76.20,20.84,0.350
76.21,20.96,0.350
76.22,21.08,0.350
76.23,21.19,0.350
76.24,21.31,0.350
76.25,21.43,0.350
76.26,21.54,0.350
76.28,21.66,0.350
76.29,21.78,0.351
76.30,21.90,0.351
76.31,22.01,0.351
76.32,22.13,0.351
76.34,22.24,0.351
76.35,22.36,0.351
76.36,22.48,0.351
76.37,22.60,0.351
76.38,22.71,0.351
76.39,22.83,0.351
76.40,22.95,0.351
76.42,23.06,0.351
76.43,23.18,0.351
76.44,23.29,0.352
76.45,23.41,0.352
76.46,23.53,0.352
76.48,23.65,0.352
76.49,23.76,0.352
76.50,23.88,0.352
76.51,24.00,0.352
76.52,24.11,0.352
76.53,24.23,0.352
76.55,24.35,0.352
76.56,24.46,0.352
76.57,24.58,0.352
76.58,24.70,0.353
76.59,24.81,0.353
76.60,24.93,0.353
76.61,25.05,0.353
76.63,25.16,0.353
76.64,25.28,0.353
76.65,25.40,0.353
76.66,25.51,0.354
76.67,25.63,0.354
76.69,25.75,0.354
76.70,25.86,0.354
76.71,25.98,0.354
76.72,26.10,0.354
76.73,26.21,0.354
76.74,26.33,0.354
76.75,26.45,0.354
76.77,26.57,0.354
76.78,26.68,0.355
76.79,26.80,0.355
76.80,26.92,0.355
76.81,27.03,0.355
76.83,27.15,0.355
76.84,27.27,0.355
76.85,27.38,0.355
76.86,27.50,0.355
76.87,27.62,0.355
76.88,27.73,0.355
76.90,27.85,0.355
76.91,27.97,0.356
76.92,28.08,0.356
76.93,28.20,0.356
76.94,28.32,0.356
76.95,28.43,0.356
76.96,28.55,0.356
76.98,28.67,0.356
76.99,28.78,0.356
77.00,28.90,0.356
77.01,29.02,0.356
77.02,29.13,0.356
77.04,29.25,0.357
77.05,29.37,0.357
77.06,29.49,0.357
77.07,29.60,0.357
77.08,29.72,0.357
77.09,29.84,0.357
77.10,29.95,0.357
77.12,30.07,0.357
77.13,30.19,0.357
77.14,30.30,0.357
77.15,30.42,0.357
77.16,30.54,0.358
77.18,30.65,0.358
77.19,30.77,0.358
77.20,30.89,0.358
77.21,31.00,0.358
77.22,31.12,0.358
77.23,31.24,0.358
77.25,31.35,0.358
77.26,31.47,0.358
77.27,31.59,0.358
77.28,31.70,0.358
77.29,31.82,0.358
77.30,31.94,0.358
77.31,32.05,0.358
77.33,32.17,0.358
77.34,32.29,0.358
77.35,32.40,0.359
77.36,32.52,0.359
77.37,32.64,0.359
77.39,32.75,0.359
77.40,32.87,0.359
77.41,32.99,0.359
77.42,33.10,0.359
77.43,33.22,0.359
77.44,33.34,0.360
77.45,33.45,0.360
77.47,33.57,0.360
77.48,33.69,0.360
77.49,33.80,0.360
77.50,33.92,0.360
77.51,34.04,0.360
77.53,34.16,0.360
77.54,34.27,0.360
77.55,34.39,0.360
77.56,34.51,0.360
77.57,34.62,0.360
77.58,34.74,0.361
77.60,34.86,0.361
77.61,34.97,0.361
77.62,35.09,0.361
77.63,35.21,0.361
77.64,35.32,0.361
77.65,35.44,0.361
77.66,35.56,0.361
77.68,35.67,0.361
77.69,35.79,0.361
77.70,35.91,0.361
77.71,36.02,0.362
77.72,36.14,0.362
77.74,36.26,0.362
77.75,36.37,0.362
77.76,36.49,0.362
77.77,36.61,0.362
77.78,36.73,0.362
77.79,36.84,0.362
77.80,36.96,0.362
77.82,37.08,0.362
77.83,37.19,0.362
77.84,37.31,0.362
77.85,37.43,0.362
77.86,37.54,0.362
77.88,37.66,0.362
77.89,37.78,0.362
77.90,37.89,0.363
77.91,38.01,0.363
77.92,38.13,0.363
77.93,38.24,0.363
77.95,38.36,0.363
77.96,38.48,0.363
77.97,38.59,0.363
77.98,38.71,0.363
77.99,38.83,0.363
78.00,38.94,0.363
78.01,39.06,0.363
78.03,39.18,0.363
78.04,39.29,0.363
78.05,39.41,0.363
78.06,39.53,0.364
78.07,39.64,0.364
78.09,39.76,0.364
78.10,39.88,0.364
78.11,39.99,0.364
78.12,40.11,0.364
78.13,40.23,0.364
78.14,40.34,0.364
78.15,40.46,0.365
78.17,40.58,0.365
78.18,40.70,0.365
78.19,40.81,0.365
78.20,40.93,0.365
78.21,41.05,0.365
78.23,41.16,0.365
78.24,41.28,0.365
78.25,41.40,0.365
78.26,41.51,0.365
78.27,41.63,0.365
78.28,41.75,0.365
78.30,41.87,0.365
78.31,41.98,0.365
78.32,42.10,0.365
78.33,42.21,0.365
78.34,42.33,0.366
78.35,42.45,0.365
78.36,42.56,0.366
78.38,42.68,0.366
78.39,42.80,0.366
78.40,42.92,0.366
78.41,43.03,0.366
78.42,43.15,0.366
78.44,43.26,0.366
78.45,43.38,0.366
78.46,43.50,0.366
78.47,43.62,0.366
78.48,43.73,0.366
78.49,43.85,0.366
78.50,43.97,0.366
78.52,44.08,0.366
78.53,44.20,0.366
78.54,44.31,0.366
78.55,44.43,0.366
78.56,44.55,0.366
78.58,44.67,0.366
78.59,44.78,0.366
78.60,44.90,0.367
78.61,45.02,0.367
78.62,45.13,0.367
78.63,45.25,0.367
78.65,45.37,0.367
78.66,45.48,0.367
78.67,45.60,0.367
78.68,45.72,0.367
78.69,45.83,0.367
78.70,45.95,0.367
78.71,46.07,0.367
78.73,46.18,0.367
78.74,46.30,0.367
78.75,46.42,0.367
78.76,46.53,0.368
78.77,46.65,0.368
78.79,46.77,0.368
78.80,46.88,0.368
78.81,47.00,0.368
78.82,47.12,0.368
78.83,47.24,0.368
78.84,47.35,0.368
78.85,47.47,0.368
78.87,47.59,0.368
78.88,47.70,0.368
78.89,47.82,0.368
78.90,47.94,0.368
78.91,48.05,0.368
78.93,48.17,0.369
78.94,48.29,0.369
78.95,48.40,0.369
78.96,48.52,0.369
78.97,48.64,0.369
78.98,48.75,0.369
79.00,48.87,0.369
79.01,48.99,0.369
79.02,49.10,0.369
79.03,49.22,0.370
79.04,49.34,0.370
79.05,49.45,0.370
79.06,49.57,0.370
79.08,49.69,0.370
79.09,49.80,0.370
79.10,49.92,0.370
79.11,50.04,0.370
79.12,50.15,0.370
79.14,50.27,0.370
79.15,50.39,0.370
79.16,50.50,0.371
79.17,50.62,0.371
79.18,50.74,0.371
79.19,50.86,0.371
79.20,50.97,0.371
79.22,51.09,0.371
79.23,51.20,0.371
79.24,51.32,0.371
79.25,51.44,0.371
79.26,51.56,0.371
79.28,51.67,0.371
79.29,51.79,0.371
79.30,51.91,0.371
79.31,52.02,0.371
79.32,52.14,0.371
79.33,52.26,0.372
79.35,52.37,0.372
79.36,52.49,0.372
79.37,52.61,0.372
79.38,52.72,0.372
79.39,52.84,0.372
79.40,52.96,0.372
79.41,53.07,0.372
79.43,53.19,0.372
79.44,53.31,0.372
79.45,53.42,0.372
79.46,53.54,0.372
79.47,53.66,0.372
79.49,53.78,0.372
79.50,53.89,0.372
79.51,54.01,0.372
79.52,54.12,0.373
79.53,54.24,0.372
79.54,54.36,0.373
79.55,54.48,0.373
79.57,54.59,0.373
79.58,54.71,0.373
79.59,54.83,0.373
79.60,54.94,0.373
79.61,55.06,0.373
79.63,55.18,0.373
79.64,55.29,0.373
79.65,55.41,0.373
79.66,55.53,0.373
79.67,55.64,0.374
79.68,55.76,0.374
79.70,55.88,0.374
79.71,55.99,0.374
79.72,56.11,0.374
79.73,56.23,0.374
79.74,56.34,0.374
79.75,56.46,0.374
79.76,56.58,0.374
79.78,56.69,0.374
79.79,56.81,0.374
79.80,56.93,0.374
79.81,57.04,0.374
79.82,57.16,0.374
79.84,57.28,0.374
79.85,57.39,0.374
79.86,57.51,0.374
79.87,57.63,0.374
79.88,57.75,0.374
79.89,57.86,0.374
79.90,57.98,0.375
79.92,58.10,0.375
79.93,58.21,0.375
79.94,58.33,0.375
79.95,58.45,0.375
79.96,58.56,0.375
79.98,58.68,0.375
79.99,58.80,0.375
80.00,58.91,0.375
80.01,59.03,0.375
80.02,59.15,0.375
80.03,59.26,0.376
80.05,59.38,0.376
80.06,59.50,0.376
80.07,59.61,0.376
80.08,59.73,0.376
80.09,59.85,0.376
80.10,59.96,0.376
80.11,60.08,0.376
80.13,60.20,0.376
80.14,60.31,0.376
80.15,60.43,0.376
80.16,60.55,0.376
80.17,60.66,0.376
80.19,60.78,0.377
80.20,60.90,0.377
80.21,61.02,0.377
80.22,61.13,0.377
80.23,61.25,0.377
80.24,61.37,0.377
80.25,61.48,0.377
80.27,61.60,0.377
80.28,61.72,0.377
80.29,61.83,0.377
80.30,61.95,0.377
80.31,62.07,0.378
80.33,62.18,0.378
80.34,62.30,0.378
80.35,62.42,0.378
80.36,62.53,0.378
80.37,62.65,0.378
80.38,62.77,0.378
80.40,62.88,0.378
80.41,63.00,0.378
80.42,63.12,0.378
80.43,63.23,0.378
80.44,63.35,0.378
80.45,63.47,0.379
80.46,63.58,0.379
80.48,63.70,0.379
80.49,63.82,0.379
80.50,63.93,0.379
80.51,64.05,0.379
80.52,64.17,0.379
80.54,64.28,0.379
80.55,64.40,0.379
80.56,64.52,0.379
80.57,64.63,0.379
80.58,64.75,0.379
80.59,64.87,0.380
80.60,64.98,0.380
80.62,65.10,0.380
80.63,65.22,0.380
80.64,65.34,0.380
80.65,65.45,0.380
80.66,65.57,0.380
80.68,65.69,0.380
80.69,65.80,0.380
80.70,65.92,0.380
80.71,66.03,0.380
80.72,66.15,0.380
80.73,66.27,0.381
80.75,66.38,0.381
80.76,66.50,0.381
80.77,66.62,0.381
80.78,66.73,0.381
80.79,66.85,0.381
80.80,66.97,0.381
80.81,67.09,0.381
80.83,67.20,0.381
80.84,67.32,0.381
80.85,67.44,0.381
80.86,67.55,0.381
80.87,67.67,0.382
80.89,67.79,0.382
80.90,67.90,0.382
80.91,68.02,0.382
80.92,68.14,0.382
80.93,68.25,0.382
80.94,68.37,0.382
80.95,68.49,0.382
80.97,68.60,0.382
80.98,68.72,0.382
80.99,68.84,0.383
81.00,68.96,0.383
81.01,69.07,0.383
81.03,69.19,0.383
81.04,69.30,0.383
81.05,69.42,0.383
81.06,69.54,0.383
81.07,69.65,0.383
81.08,69.77,0.383
81.10,69.89,0.383
81.11,70.00,0.383
81.12,70.12,0.383
81.13,70.24,0.383
81.14,70.35,0.384
81.15,70.47,0.384
81.16,70.59,0.384
81.18,70.71,0.384
81.19,70.82,0.384
81.20,70.94,0.384
81.21,71.05,0.384
81.22,71.17,0.384
81.24,71.29,0.385
81.25,71.41,0.385
81.26,71.52,0.385
81.27,71.64,0.385
81.28,71.76,0.385
81.29,71.87,0.385
81.30,71.99,0.385
81.32,72.11,0.385
81.33,72.22,0.385
81.34,72.34,0.385
81.35,72.46,0.385
81.36,72.57,0.386
81.38,72.69,0.386
81.39,72.81,0.386
81.40,72.92,0.386
81.41,73.04,0.386
81.42,73.16,0.386
81.43,73.27,0.386
81.45,73.39,0.386
81.46,73.51,0.386
81.47,73.62,0.387
81.48,73.74,0.387
81.49,73.86,0.387
81.50,73.97,0.387
81.51,74.09,0.387
81.53,74.21,0.387
81.54,74.32,0.387
81.55,74.44,0.387
81.56,74.56,0.387
81.57,74.68,0.387
81.59,74.79,0.387
81.60,74.91,0.387
81.61,75.03,0.387
81.62,75.14,0.387
81.63,75.26,0.387
81.64,75.38,0.387
81.65,75.49,0.387
81.67,75.61,0.387
81.68,75.73,0.388
81.69,75.84,0.388
81.70,75.96,0.388
81.71,76.08,0.388
81.73,76.19,0.388
81.74,76.31,0.388
81.75,76.43,0.388
81.76,76.54,0.388
81.77,76.66,0.388
81.78,76.78,0.388
81.80,76.89,0.388
81.81,77.01,0.388
81.82,77.13,0.389
81.83,77.25,0.389
81.84,77.36,0.389
81.85,77.48,0.389
81.86,77.60,0.389
81.88,77.71,0.389
81.89,77.83,0.389
81.90,77.94,0.389
81.91,78.06,0.389
81.92,78.18,0.389
81.94,78.29,0.389
81.95,78.41,0.390
81.96,78.53,0.390
81.97,78.65,0.390
81.98,78.76,0.390
81.99,78.88,0.390
82.00,79.00,0.390
82.02,79.11,0.390
82.03,79.23,0.390
82.04,79.35,0.390
82.05,79.46,0.390
82.06,79.58,0.391
82.08,79.70,0.391
82.09,79.81,0.391
82.10,79.93,0.391
82.11,80.05,0.391
82.12,80.16,0.391
82.13,80.28,0.391
82.15,80.40,0.391
82.16,80.51,0.391
82.17,80.63,0.391
82.18,80.75,0.391
82.19,80.86,0.391
82.20,80.98,0.391
82.21,81.10,0.391
82.23,81.21,0.391
82.24,81.33,0.391
82.25,81.45,0.392
82.26,81.56,0.392
82.27,81.68,0.392
82.29,81.80,0.392
82.30,81.91,0.392
82.31,82.03,0.392
82.32,82.15,0.392
82.33,82.26,0.392
82.34,82.38,0.392
82.35,82.50,0.392
82.37,82.61,0.392
82.38,82.73,0.392
82.39,82.85,0.392
82.40,82.96,0.393
82.41,83.08,0.393
82.43,83.20,0.393
82.44,83.32,0.393
82.45,83.43,0.393
82.46,83.55,0.393
82.47,83.67,0.393
82.48,83.78,0.393
82.50,83.90,0.393
82.51,84.02,0.393
82.52,84.13,0.394
82.53,84.25,0.394
82.54,84.37,0.394
82.55,84.48,0.394
82.56,84.60,0.394
82.58,84.72,0.394
82.59,84.83,0.394
82.60,84.95,0.394
82.61,85.07,0.394
82.62,85.18,0.394
82.64,85.30,0.394
82.65,85.42,0.395
82.66,85.53,0.395
82.67,85.65,0.395
82.68,85.77,0.395
82.69,85.88,0.395
82.70,86.00,0.395
82.72,86.12,0.395
82.73,86.23,0.395
82.74,86.35,0.395
82.75,86.47,0.395
82.76,86.59,0.395
82.78,86.70,0.395
82.79,86.82,0.396
82.80,86.93,0.396
82.81,87.05,0.396
82.82,87.17,0.396
82.83,87.29,0.396
82.85,87.40,0.396
82.86,87.52,0.396
82.87,87.64,0.396
82.88,87.75,0.396
82.89,87.87,0.396
82.90,87.99,0.396
82.91,88.10,0.396
82.93,88.22,0.396
82.94,88.34,0.396
82.95,88.45,0.397
82.96,88.57,0.397
82.97,88.69,0.397
82.99,88.80,0.397
83.00,88.92,0.397
83.01,89.04,0.397
83.02,89.15,0.397
83.03,89.27,0.397
83.04,89.39,0.397
83.05,89.50,0.397
83.07,89.62,0.398
83.08,89.74,0.398
83.09,89.85,0.398
83.10,89.97,0.398
83.11,90.09,0.398
83.13,90.20,0.398
83.14,90.32,0.398
83.15,90.44,0.398
83.16,90.55,0.399
83.17,90.67,0.399
83.18,90.79,0.399
83.20,90.90,0.399
83.21,91.02,0.399
83.22,91.14,0.399
83.23,91.25,0.399
83.24,91.37,0.399
83.25,91.49,0.399
83.26,91.61,0.399
83.28,91.72,0.400
83.29,91.84,0.400
83.30,91.96,0.400
83.31,92.07,0.400
83.32,92.19,0.400
83.34,92.31,0.400
83.35,92.42,0.400
83.36,92.54,0.401
83.37,92.66,0.401
83.38,92.77,0.401
83.39,92.89,0.401
83.40,93.01,0.401
83.42,93.12,0.401
83.43,93.24,0.401
83.44,93.36,0.401
83.45,93.47,0.401
83.46,93.59,0.402
83.48,93.71,0.402
83.49,93.82,0.402
83.50,93.94,0.402
83.51,94.06,0.402
83.52,94.17,0.402
83.53,94.29,0.402
83.55,94.41,0.402
83.56,94.52,0.403
83.57,94.64,0.403
83.58,94.76,0.403
83.59,94.87,0.403
83.60,94.99,0.403
83.61,95.11,0.403
83.63,95.23,0.403
83.64,95.34,0.404
83.65,95.46,0.404
83.66,95.58,0.404
83.67,95.69,0.404
83.69,95.81,0.404
83.70,95.93,0.404
83.71,96.04,0.404
83.72,96.16,0.405
83.73,96.27,0.405
83.74,96.39,0.405
83.75,96.51,0.405
83.77,96.63,0.405
83.78,96.74,0.405
83.79,96.86,0.405
83.80,96.98,0.405
83.81,97.09,0.406
83.83,97.21,0.406
83.84,97.33,0.406
83.85,97.44,0.406
83.86,97.56,0.406
83.87,97.68,0.406
83.88,97.79,0.406
83.90,97.91,0.407
83.91,98.03,0.407
83.92,98.15,0.407
83.93,98.26,0.407
83.94,98.38,
83.95,98.49,
83.96,98.61,
83.98,98.73,
83.99,,
83.99,,