File: DSC/2025_05_21_THC_Sorbic_Acid_MC_n60C_150C_5Cmin_x3.csv
Filename,2025_05_21_THC_Sorbic_Acid_MC_n60C_150C_5Cmin_x3
Instrument name,DSC2A-00468 (192.168.1.100)
Operator,Yarger
rundate,5/21/2025
Sample name,2025_05_21_THC_Sorbic_Acid_MC_n60C_150C_5Cmin_x3
proceduresegments,Data Off ; Equilibrate -60.00 °C; Data On ; Ramp 5.00 °C/min to 150.00 °C; Data Off ; Isothermal 1.0 min; Data On ; Ramp 5.00 °C/min to -60.00 °C; Data Off ; Isothermal 1.0 min; Data On ; Ramp 5.00 °C/min to 150.00 °C; Data Off ; Isothermal 1.0 min; Data On ; Ramp 5.00 °C/min to -60.00 °C; Data Off ; Isothermal 1.0 min; Data On ; Ramp 5.00 °C/min to 30.00 °C
[File Parameters]
Run date,5/21/2025 11:24:03 AM
Trios version,5.1.1.46572
Original File Name,
Current File Name,D:\DSC2500\JYarger\2025_05_21_THC_Sorbic_Acid_MC_n60C_150C_5Cmin_x3.tri
[Procedure]
Procedure Name,THC_SA_n60C_150C_5Cmin_x3
Sample Name,2025_05_21_THC_Sorbic_Acid_MC_n60C_150C_5Cmin_x3
Sample Mass,5.88 mg
Reference Sample Mass,0 mg
Pan Mass,56.94 mg
Pan Number,50
Reference Pan Mass,57.13 mg
Reference Pan Number,37
Pan Type,Tzero Aluminum Hermetic
Comments,Al Hermetic DSC Consumables sealed Pan/Lid. Y2 Tray (Google Sheet: DSC_Samples_Vext_Y2_Tray_May2025)
Project Name,CA
Operator,Yarger
Test,Custom
Unload Max Temperature,30
Unload Min Temperature,30
Load Max Temperature,30
Load Min Temperature,30
Stop on Gas Flow Error,Yes
[Signal List]
Signal #1,Time (min)
Signal #2,Temperature (°C)
Signal #3,Heat Flow (mW)
Signal #4,Delta T (µV)
Signal #5,Delta Tzero (µV)
Signal #6,Tzero Temperature (°C)
Signal #7,Cell Purge (mL/min)
Signal #8,Heater Temp (°C)
Signal #9,Power Delivered (W)
Signal #10,Reference Junction Temperature (°C)
Signal #11,Flange Temperature (°C)
Signal #12,Heat Flow Phase (rad)
Signal #13,Total Heat Capacity (J/°C)
Signal #14,Heat Capacity (J/°C)
[Configuration]
Company Name,ASU
Instrument Name,DSC2A-00468
Instrument Type,DSC2500
Serial Number,DSC2A-00468
IP,192.168.1.100
Location of Instrument,MRRC
DisplayType,Unknown
Sample Interval ,0.1 s/pt
Selected Heat Flow,T4P
Exotherm Direction,Down
Cell Serial,DRC2-00792
Lid Type,Standard
Cooler,RCS 90
Leave Cooler on at End of Sequence,On
Gas 2,Nitrogen
Gas Selected,Channel 1
Flow Rate,50 mL/min
Secondary Purge,On
Licensed Heat Flow,Heat Flow T4P
Modulation Licensed,Yes
[Versions]
Common IDD Version,1
Cortex Version,VER 2.10.2.31
Driver,5.0.0.6
GDM Version,1.0.3.3
TouchscreenVersion,1.0.0.16145
FEP Version,1.2.1.21
FEP Bootloader,2.0.0.5
AutoSampler Version,2.1.1.26
Auto Sampler Bootloader,2.0.0.5
FCM Version,1.1.0.3
FCM Bootloader,2.0.0.5
[Experiment Logs]
Experiment Log Entry # 1,Data On set to 0
Experiment Log Entry # 3,Equilibrate Segment -60 (C) Started
Experiment Log Entry # 5,Air Cool is off.
Experiment Log Entry # 7,Data On set to 1
Experiment Log Entry # 9,Ramp Segment 5 C/min to 150 Started
Experiment Log Entry # 11,Data On set to 0
Experiment Log Entry # 13,Isothermal Segment 1 min started
Experiment Log Entry # 15,Data On set to 1
Experiment Log Entry # 17,Ramp Segment 5 C/min to -60 Started
Experiment Log Entry # 19,Data On set to 0
Experiment Log Entry # 21,Isothermal Segment 1 min started
Experiment Log Entry # 23,Data On set to 1
Experiment Log Entry # 25,Ramp Segment 5 C/min to 150 Started
Experiment Log Entry # 27,Data On set to 0
Experiment Log Entry # 29,Isothermal Segment 1 min started
Experiment Log Entry # 31,Data On set to 1
Experiment Log Entry # 33,Ramp Segment 5 C/min to -60 Started
Experiment Log Entry # 35,Data On set to 0
Experiment Log Entry # 37,Isothermal Segment 1 min started
Experiment Log Entry # 39,Data On set to 1
Experiment Log Entry # 41,Ramp Segment 5 C/min to 30 Started
[Method Log]
Method Log Entry # 1,Data Off
Method Log Entry # 2,Equilibrate -60 °C
Method Log Entry # 3,Data On
Method Log Entry # 4,(Ramp 257575) Ramp 5 °C/minute to 150 °C
Method Log Entry # 5,Data Off
Method Log Entry # 6,Isothermal 1 minutes
Method Log Entry # 7,Data On
Method Log Entry # 8,(Ramp 257579) Ramp 5 °C/minute to -60 °C
Method Log Entry # 9,Data Off
Method Log Entry # 10,Isothermal 1 minutes
Method Log Entry # 11,Data On
Method Log Entry # 12,(Ramp 257583) Ramp 5 °C/minute to 150 °C
Method Log Entry # 13,Data Off
Method Log Entry # 14,Isothermal 1 minutes
Method Log Entry # 15,Data On
Method Log Entry # 16,(Ramp 257587) Ramp 5 °C/minute to -60 °C
Method Log Entry # 17,Data Off
Method Log Entry # 18,Isothermal 1 minutes
Method Log Entry # 19,Data On
Method Log Entry # 20,(Ramp 257591) Ramp 5 °C/minute to 30 °C
Cell Serial,DRC2-00792
[T1 Calibration]
Slope,-0.008529666
Offset,9.636258
Initial Temperature,98.23
GUID,f8bfdadc-4977-4fdf-ba6d-0ba9134940c3
[TZero Calibration]
Date Applied,11/29/2022 4:06:13 PM
Description,From -89.059 °C to 396.009 °C at 20.000°C/min
Gas Type,Nitrogen
Pan Type,None
Source Files 1,C:\Users\yargerlab\Desktop\DSC Data\General\TZero_calibration_11_29_22_2nd(2).tri
Source Files 2,C:\Users\yargerlab\Desktop\DSC Data\General\TZero_calibration_11_29_22_2nd(3).tri
Delta T Offset,13.05235
Delta T Slope,-0.007271007
Delta T0 Offset,-13.69128
Delta T0 Slope,0.06063341
[Temperature Calibration]
Date Applied,11/29/2022 7:12:28 PM
Description,From 106.590 °C to 186.590 °C at 10.000°C/min
Gas Type,Nitrogen
Pan Type,Tzero Aluminum Hermetic
Source Files 1,C:\Users\yargerlab\Desktop\DSC Data\General\Indium(6).tri
Measured 1,157.391
Known 1,156.598
[Cell Constant Calibration]
Date Applied,11/29/2022 7:12:29 PM
Description,From 106.590 °C to 186.590 °C at 10.000°C/min
Gas Type,Nitrogen
Pan Type,Tzero Aluminum Hermetic
Source Files 1,C:\Users\yargerlab\Desktop\DSC Data\General\Indium(6).tri
T4P KCell,1.006051
Onset Slope,63.26126 mW/°C
[Direct Cp Calibration]
Date Applied,11/30/2022 11:04:51 AM
Description,From -79.983 °C to 298.409 °C at 10.000°C/min
Gas Type,Nitrogen
Pan Type,Tzero Aluminum Hermetic
Source Files 1,C:\Users\yargerlab\Desktop\DSC Data\General\Sapphire_Heat_Capacity_11_30_22.tri
[Rev Cp Calibration]
Date Applied,11/30/2022 1:58:51 PM
Description,From -79.996 °C to 292.812 °C at 3.000°C/min
Gas Type,Nitrogen
Pan Type,Tzero Aluminum Hermetic
Source Files 1,C:\Users\yargerlab\Desktop\DSC Data\General\Sapphire_MDSC_Calibration_11_30_22.tri
[step]
Ramp 5.00 °C/min to 150.00 °C
Time,Temperature,Heat Flow (Normalized)
min,°C,W/g
0.00,-59.69,-0.037
0.03,-59.70,-0.038
0.06,-59.71,-0.028
0.08,-59.69,-0.007
0.11,-59.64,0.017
0.14,-59.57,0.039
0.17,-59.48,0.056
0.20,-59.39,0.068
0.23,-59.28,0.077
0.26,-59.16,0.083
0.28,-59.05,0.089
0.31,-58.93,0.093
0.34,-58.80,0.098
0.37,-58.67,0.099
0.40,-58.54,0.102
0.43,-58.41,0.103
0.45,-58.28,0.105
0.48,-58.14,0.105
0.51,-58.01,0.106
0.54,-57.87,0.107
0.57,-57.74,0.108
0.60,-57.60,0.108
0.62,-57.46,0.108
0.65,-57.33,0.109
0.68,-57.19,0.109
0.71,-57.05,0.110
0.74,-56.91,0.110
0.77,-56.77,0.110
0.79,-56.63,0.111
0.82,-56.50,0.111
0.85,-56.36,0.111
0.88,-56.22,0.111
0.91,-56.08,0.111
0.93,-55.94,0.112
0.96,-55.80,0.112
0.99,-55.66,0.112
1.02,-55.52,0.112
1.05,-55.38,0.112
1.08,-55.24,0.112
1.11,-55.10,0.112
1.13,-54.96,0.112
1.16,-54.82,0.112
1.19,-54.68,0.112
1.22,-54.54,0.112
1.25,-54.40,0.112
1.28,-54.25,0.112
1.30,-54.11,0.113
1.33,-53.97,0.113
1.36,-53.83,0.113
1.39,-53.69,0.113
1.42,-53.55,0.113
1.44,-53.41,0.113
1.47,-53.27,0.113
1.50,-53.13,0.113
1.53,-52.98,0.113
1.56,-52.84,0.113
1.59,-52.70,0.113
1.62,-52.56,0.113
1.64,-52.42,0.113
1.67,-52.28,0.113
1.70,-52.14,0.113
1.73,-52.00,0.113
1.76,-51.86,0.113
1.78,-51.71,0.112
1.81,-51.57,0.113
1.84,-51.43,0.113
1.87,-51.29,0.113
1.90,-51.15,0.113
1.93,-51.01,0.113
1.96,-50.87,0.112
1.98,-50.73,0.113
2.01,-50.58,0.113
2.04,-50.44,0.113
2.07,-50.30,0.113
2.10,-50.16,0.113
2.13,-50.02,0.113
2.15,-49.87,0.113
2.18,-49.73,0.113
2.21,-49.59,0.113
2.24,-49.45,0.113
2.27,-49.31,0.113
2.29,-49.17,0.113
2.32,-49.02,0.113
2.35,-48.88,0.113
2.38,-48.74,0.113
2.41,-48.60,0.113
2.44,-48.46,0.112
2.46,-48.32,0.112
2.49,-48.18,0.112
2.52,-48.03,0.112
2.55,-47.89,0.112
2.58,-47.75,0.112
2.61,-47.61,0.112
2.64,-47.47,0.112
2.66,-47.33,0.112
2.69,-47.19,0.112
2.72,-47.04,0.112
2.75,-46.90,0.112
2.78,-46.76,0.112
2.81,-46.62,0.112
2.83,-46.48,0.112
2.86,-46.34,0.112
2.89,-46.20,0.112
2.92,-46.05,0.113
2.95,-45.91,0.112
2.98,-45.77,0.113
3.00,-45.63,0.112
3.03,-45.49,0.113
3.06,-45.35,0.113
3.09,-45.20,0.113
3.12,-45.06,0.113
3.14,-44.92,0.113
3.17,-44.78,0.113
3.20,-44.64,0.113
3.23,-44.50,0.113
3.26,-44.35,0.113
3.29,-44.21,0.113
3.31,-44.07,0.113
3.34,-43.93,0.113
3.37,-43.79,0.113
3.40,-43.65,0.113
3.43,-43.50,0.113
3.46,-43.36,0.113
3.49,-43.22,0.113
3.51,-43.08,0.113
3.54,-42.94,0.113
3.57,-42.80,0.113
3.60,-42.66,0.113
3.63,-42.51,0.113
3.66,-42.37,0.113
3.68,-42.23,0.113
3.71,-42.09,0.113
3.74,-41.95,0.113
3.77,-41.80,0.113
3.80,-41.66,0.113
3.83,-41.52,0.113
3.85,-41.38,0.113
3.88,-41.24,0.113
3.91,-41.09,0.113
3.94,-40.95,0.113
3.97,-40.81,0.113
3.99,-40.67,0.113
4.02,-40.53,0.113
4.05,-40.39,0.113
4.08,-40.24,0.113
4.11,-40.10,0.113
4.14,-39.96,0.113
4.16,-39.82,0.113
4.19,-39.68,0.113
4.22,-39.53,0.113
4.25,-39.39,0.113
4.28,-39.25,0.113
4.31,-39.11,0.113
4.34,-38.97,0.113
4.36,-38.83,0.113
4.39,-38.68,0.114
4.42,-38.54,0.114
4.45,-38.40,0.114
4.48,-38.26,0.114
4.50,-38.12,0.114
4.53,-37.97,0.114
4.56,-37.83,0.114
4.59,-37.69,0.114
4.62,-37.54,0.114
4.65,-37.40,0.114
4.68,-37.26,0.114
4.70,-37.12,0.114
4.73,-36.98,0.114
4.76,-36.84,0.114
4.79,-36.69,0.114
4.82,-36.55,0.114
4.85,-36.41,0.114
4.87,-36.27,0.114
4.90,-36.13,0.114
4.93,-35.99,0.114
4.96,-35.84,0.114
4.99,-35.70,0.114
5.01,-35.56,0.114
5.04,-35.42,0.114
5.07,-35.28,0.114
5.10,-35.14,0.114
5.13,-34.99,0.114
5.16,-34.85,0.114
5.19,-34.71,0.114
5.21,-34.57,0.114
5.24,-34.43,0.114
5.27,-34.28,0.114
5.30,-34.14,0.114
5.33,-34.00,0.114
5.35,-33.86,0.114
5.38,-33.72,0.114
5.41,-33.58,0.114
5.44,-33.43,0.114
5.47,-33.29,0.114
5.50,-33.15,0.114
5.53,-33.01,0.114
5.55,-32.87,0.114
5.58,-32.73,0.114
5.61,-32.58,0.114
5.64,-32.44,0.114
5.67,-32.30,0.114
5.70,-32.16,0.114
5.72,-32.02,0.114
5.75,-31.88,0.114
5.78,-31.73,0.115
5.81,-31.59,0.115
5.84,-31.45,0.115
5.86,-31.31,0.115
5.89,-31.17,0.115
5.92,-31.02,0.115
5.95,-30.88,0.115
5.98,-30.74,0.115
6.01,-30.60,0.115
6.04,-30.46,0.115
6.06,-30.31,0.115
6.09,-30.17,0.115
6.12,-30.03,0.115
6.15,-29.89,0.115
6.18,-29.75,0.115
6.20,-29.60,0.115
6.23,-29.46,0.115
6.26,-29.32,0.115
6.29,-29.18,0.115
6.32,-29.04,0.115
6.35,-28.89,0.115
6.38,-28.75,0.115
6.40,-28.61,0.115
6.43,-28.47,0.115
6.46,-28.33,0.115
6.49,-28.19,0.115
6.52,-28.05,0.115
6.55,-27.90,0.115
6.57,-27.76,0.115
6.60,-27.62,0.115
6.63,-27.48,0.115
6.66,-27.34,0.115
6.69,-27.19,0.115
6.71,-27.05,0.115
6.74,-26.91,0.116
6.77,-26.77,0.116
6.80,-26.63,0.116
6.83,-26.49,0.116
6.86,-26.34,0.116
6.89,-26.20,0.116
6.91,-26.06,0.116
6.94,-25.92,0.116
6.97,-25.78,0.116
7.00,-25.63,0.116
7.03,-25.49,0.116
7.05,-25.35,0.116
7.08,-25.21,0.116
7.11,-25.07,0.116
7.14,-24.92,0.116
7.17,-24.78,0.116
7.20,-24.64,0.116
7.23,-24.50,0.116
7.25,-24.36,0.116
7.28,-24.22,0.116
7.31,-24.07,0.116
7.34,-23.93,0.116
7.37,-23.79,0.116
7.40,-23.65,0.116
7.42,-23.51,0.116
7.45,-23.37,0.116
7.48,-23.22,0.116
7.51,-23.08,0.117
7.54,-22.94,0.117
7.56,-22.80,0.117
7.59,-22.66,0.117
7.62,-22.51,0.117
7.65,-22.37,0.117
7.68,-22.23,0.117
7.71,-22.09,0.117
7.74,-21.95,0.117
7.76,-21.80,0.117
7.79,-21.66,0.117
7.82,-21.52,0.117
7.85,-21.38,0.117
7.88,-21.24,0.117
7.90,-21.10,0.117
7.93,-20.95,0.117
7.96,-20.81,0.117
7.99,-20.67,0.117
8.02,-20.53,0.117
8.05,-20.39,0.117
8.08,-20.24,0.117
8.10,-20.10,0.117
8.13,-19.96,0.117
8.16,-19.82,0.117
8.19,-19.68,0.117
8.22,-19.54,0.117
8.25,-19.39,0.117
8.27,-19.25,0.117
8.30,-19.11,0.117
8.33,-18.97,0.117
8.36,-18.83,0.118
8.39,-18.69,0.118
8.41,-18.55,0.118
8.44,-18.40,0.118
8.47,-18.26,0.118
8.50,-18.12,0.118
8.53,-17.98,0.118
8.56,-17.84,0.118
8.58,-17.69,0.118
8.61,-17.55,0.118
8.64,-17.41,0.118
8.67,-17.27,0.118
8.70,-17.12,0.118
8.73,-16.98,0.118
8.75,-16.84,0.118
8.78,-16.70,0.119
8.81,-16.56,0.119
8.84,-16.42,0.119
8.87,-16.27,0.119
8.90,-16.13,0.119
8.93,-15.99,0.119
8.95,-15.85,0.119
8.98,-15.71,0.119
9.01,-15.57,0.119
9.04,-15.43,0.119
9.07,-15.28,0.119
9.10,-15.14,0.119
9.12,-15.00,0.119
9.15,-14.86,0.119
9.18,-14.71,0.119
9.21,-14.57,0.119
9.24,-14.43,0.119
9.27,-14.29,0.120
9.29,-14.15,0.120
9.32,-14.01,0.120
9.35,-13.87,0.120
9.38,-13.73,0.120
9.41,-13.58,0.120
9.43,-13.44,0.120
9.46,-13.30,0.120
9.49,-13.16,0.120
9.52,-13.02,0.120
9.55,-12.87,0.121
9.58,-12.73,0.121
9.60,-12.59,0.121
9.63,-12.45,0.121
9.66,-12.31,0.121
9.69,-12.17,0.121
9.72,-12.02,0.121
9.75,-11.88,0.121
9.78,-11.74,0.121
9.80,-11.60,0.122
9.83,-11.46,0.122
9.86,-11.31,0.122
9.89,-11.17,0.122
9.92,-11.03,0.122
9.95,-10.89,0.122
9.97,-10.75,0.123
10.00,-10.61,0.123
10.03,-10.47,0.123
10.06,-10.32,0.123
10.09,-10.18,0.123
10.12,-10.04,0.124
10.14,-9.90,0.124
10.17,-9.75,0.124
10.20,-9.61,0.124
10.23,-9.47,0.124
10.26,-9.33,0.125
10.28,-9.19,0.125
10.31,-9.05,0.125
10.34,-8.90,0.125
10.37,-8.76,0.126
10.40,-8.62,0.126
10.43,-8.48,0.126
10.45,-8.34,0.126
10.48,-8.20,0.127
10.51,-8.05,0.127
10.54,-7.91,0.127
10.57,-7.77,0.128
10.60,-7.63,0.128
10.63,-7.49,0.128
10.65,-7.35,0.128
10.68,-7.21,0.129
10.71,-7.06,0.129
10.74,-6.92,0.130
10.77,-6.78,0.130
10.80,-6.64,0.130
10.82,-6.50,0.131
10.85,-6.36,0.131
10.88,-6.22,0.132
10.91,-6.07,0.132
10.94,-5.93,0.133
10.97,-5.79,0.133
10.99,-5.65,0.134
11.02,-5.51,0.134
11.05,-5.37,0.134
11.08,-5.22,0.135
11.11,-5.08,0.136
11.13,-4.94,0.136
11.16,-4.80,0.137
11.19,-4.66,0.137
11.22,-4.52,0.138
11.25,-4.38,0.138
11.28,-4.23,0.139
11.30,-4.09,0.139
11.33,-3.95,0.140
11.36,-3.81,0.141
11.39,-3.67,0.141
11.42,-3.53,0.142
11.45,-3.38,0.143
11.48,-3.24,0.143
11.50,-3.10,0.144
11.53,-2.96,0.144
11.56,-2.82,0.145
11.59,-2.68,0.146
11.62,-2.54,0.146
11.65,-2.39,0.147
11.67,-2.25,0.147
11.70,-2.11,0.148
11.73,-1.97,0.148
11.76,-1.83,0.149
11.79,-1.69,0.149
11.82,-1.54,0.150
11.84,-1.40,0.150
11.87,-1.26,0.151
11.90,-1.12,0.151
11.93,-0.98,0.151
11.96,-0.84,0.152
11.98,-0.69,0.152
12.01,-0.55,0.152
12.04,-0.41,0.153
12.07,-0.27,0.153
12.10,-0.13,0.153
12.13,0.02,0.153
12.15,0.16,0.154
12.18,0.30,0.154
12.21,0.44,0.154
12.24,0.58,0.154
12.27,0.72,0.154
12.30,0.87,0.154
12.33,1.01,0.154
12.35,1.15,0.154
12.38,1.29,0.154
12.41,1.43,0.154
12.44,1.58,0.154
12.47,1.72,0.154
12.50,1.86,0.154
12.52,2.00,0.154
12.55,2.14,0.154
12.58,2.29,0.154
12.61,2.43,0.154
12.64,2.57,0.154
12.67,2.71,0.154
12.69,2.85,0.154
12.72,2.99,0.154
12.75,3.14,0.153
12.78,3.28,0.153
12.81,3.42,0.153
12.83,3.56,0.153
12.86,3.70,0.153
12.89,3.84,0.153
12.92,3.99,0.153
12.95,4.13,0.153
12.98,4.27,0.153
13.00,4.41,0.153
13.03,4.55,0.153
13.06,4.69,0.153
13.09,4.84,0.153
13.12,4.98,0.153
13.15,5.12,0.153
13.18,5.26,0.153
13.20,5.40,0.153
13.23,5.55,0.153
13.26,5.69,0.153
13.29,5.83,0.153
13.32,5.97,0.153
13.35,6.11,0.153
13.37,6.25,0.153
13.40,6.40,0.153
13.43,6.54,0.153
13.46,6.68,0.153
13.49,6.82,0.153
13.52,6.96,0.153
13.54,7.10,0.153
13.57,7.25,0.153
13.60,7.39,0.153
13.63,7.53,0.153
13.66,7.67,0.153
13.68,7.82,0.153
13.71,7.96,0.153
13.74,8.10,0.153
13.77,8.24,0.153
13.80,8.38,0.153
13.83,8.52,0.153
13.85,8.67,0.153
13.88,8.81,0.153
13.91,8.95,0.153
13.94,9.09,0.153
13.97,9.23,0.153
14.00,9.37,0.153
14.03,9.52,0.153
14.05,9.66,0.153
14.08,9.80,0.153
14.11,9.94,0.153
14.14,10.08,0.153
14.17,10.23,0.153
14.20,10.37,0.153
14.22,10.51,0.153
14.25,10.65,0.154
14.28,10.79,0.154
14.31,10.93,0.154
14.34,11.08,0.154
14.37,11.22,0.154
14.39,11.36,0.154
14.42,11.50,0.154
14.45,11.64,0.154
14.48,11.78,0.154
14.51,11.93,0.154
14.53,12.07,0.154
14.56,12.21,0.154
14.59,12.35,0.154
14.62,12.50,0.154
14.65,12.64,0.154
14.68,12.78,0.154
14.70,12.92,0.154
14.73,13.06,0.154
14.76,13.20,0.154
14.79,13.34,0.154
14.82,13.49,0.154
14.85,13.63,0.154
14.88,13.77,0.154
14.90,13.91,0.154
14.93,14.05,0.154
14.96,14.19,0.154
14.99,14.34,0.154
15.02,14.48,0.154
15.05,14.62,0.154
15.07,14.76,0.154
15.10,14.90,0.154
15.13,15.05,0.154
15.16,15.19,0.154
15.19,15.33,0.154
15.22,15.47,0.154
15.24,15.61,0.155
15.27,15.75,0.155
15.30,15.90,0.155
15.33,16.04,0.155
15.36,16.18,0.155
15.38,16.32,0.155
15.41,16.46,0.155
15.44,16.61,0.155
15.47,16.75,0.155
15.50,16.89,0.155
15.53,17.03,0.155
15.55,17.17,0.155
15.58,17.31,0.155
15.61,17.46,0.155
15.64,17.60,0.155
15.67,17.74,0.155
15.70,17.88,0.155
15.73,18.02,0.155
15.75,18.17,0.155
15.78,18.31,0.155
15.81,18.45,0.155
15.84,18.59,0.155
15.87,18.73,0.155
15.90,18.87,0.156
15.92,19.01,0.156
15.95,19.16,0.156
15.98,19.30,0.156
16.01,19.44,0.156
16.04,19.58,0.156
16.07,19.72,0.156
16.09,19.87,0.156
16.12,20.01,0.156
16.15,20.15,0.156
16.18,20.29,0.156
16.21,20.43,0.156
16.23,20.57,0.156
16.26,20.72,0.157
16.29,20.86,0.157
16.32,21.00,0.157
16.35,21.14,0.157
16.38,21.28,0.157
16.40,21.42,0.157
16.43,21.57,0.157
16.46,21.71,0.158
16.49,21.85,0.158
16.52,21.99,0.158
16.55,22.13,0.158
16.58,22.27,0.158
16.60,22.42,0.158
16.63,22.56,0.158
16.66,22.70,0.159
16.69,22.84,0.159
16.72,22.98,0.159
16.75,23.12,0.159
16.77,23.27,0.159
16.80,23.41,0.159
16.83,23.55,0.160
16.86,23.69,0.160
16.89,23.83,0.160
16.92,23.98,0.160
16.94,24.12,0.160
16.97,24.26,0.161
17.00,24.40,0.161
17.03,24.54,0.161
17.06,24.68,0.161
17.08,24.83,0.161
17.11,24.97,0.162
17.14,25.11,0.162
17.17,25.25,0.162
17.20,25.39,0.162
17.23,25.53,0.163
17.26,25.67,0.163
17.28,25.82,0.163
17.31,25.96,0.163
17.34,26.10,0.163
17.37,26.24,0.164
17.40,26.38,0.164
17.43,26.53,0.164
17.45,26.67,0.164
17.48,26.81,0.164
17.51,26.95,0.165
17.54,27.09,0.165
17.57,27.23,0.165
17.59,27.37,0.165
17.62,27.52,0.165
17.65,27.66,0.166
17.68,27.80,0.166
17.71,27.94,0.166
17.74,28.08,0.166
17.77,28.23,0.167
17.79,28.37,0.167
17.82,28.51,0.167
17.85,28.65,0.167
17.88,28.79,0.167
17.91,28.93,0.167
17.93,29.08,0.168
17.96,29.22,0.168
17.99,29.36,0.168
18.02,29.50,0.168
18.05,29.64,0.168
18.08,29.79,0.168
18.11,29.93,0.168
18.13,30.07,0.169
18.16,30.21,0.169
18.19,30.35,0.169
18.22,30.49,0.169
18.25,30.64,0.169
18.28,30.78,0.169
18.30,30.92,0.170
18.33,31.06,0.170
18.36,31.20,0.170
18.39,31.34,0.170
18.42,31.48,0.170
18.44,31.63,0.170
18.47,31.77,0.170
18.50,31.91,0.171
18.53,32.05,0.171
18.56,32.19,0.171
18.59,32.34,0.171
18.62,32.48,0.171
18.64,32.62,0.171
18.67,32.76,0.171
18.70,32.90,0.171
18.73,33.04,0.171
18.76,33.19,0.172
18.78,33.33,0.172
18.81,33.47,0.172
18.84,33.61,0.172
18.87,33.75,0.172
18.90,33.90,0.172
18.93,34.04,0.172
18.96,34.18,0.172
18.98,34.32,0.172
19.01,34.46,0.173
19.04,34.60,0.173
19.07,34.75,0.173
19.10,34.89,0.173
19.13,35.03,0.173
19.15,35.17,0.173
19.18,35.31,0.173
19.21,35.46,0.173
19.24,35.60,0.173
19.27,35.74,0.173
19.29,35.88,0.174
19.32,36.02,0.174
19.35,36.16,0.174
19.38,36.31,0.174
19.41,36.45,0.174
19.44,36.59,0.174
19.47,36.73,0.174
19.49,36.87,0.174
19.52,37.02,0.174
19.55,37.16,0.174
19.58,37.30,0.174
19.61,37.44,0.174
19.63,37.58,0.174
19.66,37.72,0.175
19.69,37.86,0.175
19.72,38.01,0.175
19.75,38.15,0.175
19.78,38.29,0.175
19.81,38.43,0.175
19.83,38.57,0.175
19.86,38.72,0.175
19.89,38.86,0.175
19.92,39.00,0.175
19.95,39.14,0.175
19.98,39.28,0.175
20.00,39.42,0.176
20.03,39.57,0.176
20.06,39.71,0.176
20.09,39.85,0.176
20.12,39.99,0.176
20.14,40.13,0.176
20.17,40.27,0.176
20.20,40.42,0.176
20.23,40.56,0.176
20.26,40.70,0.176
20.29,40.84,0.176
20.32,40.98,0.177
20.34,41.12,0.177
20.37,41.27,0.177
20.40,41.41,0.177
20.43,41.55,0.177
20.46,41.69,0.177
20.48,41.83,0.177
20.51,41.97,0.177
20.54,42.12,0.178
20.57,42.26,0.178
20.60,42.40,0.178
20.63,42.54,0.178
20.66,42.68,0.178
20.68,42.83,0.178
20.71,42.97,0.178
20.74,43.11,0.178
20.77,43.25,0.178
20.80,43.39,0.179
20.83,43.54,0.179
20.85,43.68,0.179
20.88,43.82,0.179
20.91,43.96,0.179
20.94,44.10,0.179
20.97,44.24,0.179
20.99,44.39,0.179
21.02,44.53,0.180
21.05,44.67,0.180
21.08,44.81,0.180
21.11,44.95,0.180
21.14,45.10,0.180
21.17,45.24,0.180
21.19,45.38,0.180
21.22,45.52,0.180
21.25,45.66,0.180
21.28,45.80,0.181
21.31,45.95,0.181
21.33,46.09,0.181
21.36,46.23,0.181
21.39,46.37,0.181
21.42,46.51,0.181
21.45,46.65,0.181
21.48,46.80,0.181
21.51,46.94,0.181
21.53,47.08,0.182
21.56,47.22,0.182
21.59,47.36,0.182
21.62,47.50,0.182
21.65,47.65,0.182
21.68,47.79,0.182
21.70,47.93,0.182
21.73,48.07,0.182
21.76,48.21,0.182
21.79,48.35,0.183
21.82,48.50,0.183
21.84,48.64,0.183
21.87,48.78,0.183
21.90,48.92,0.183
21.93,49.06,0.183
21.96,49.20,0.183
21.99,49.34,0.183
22.02,49.49,0.184
22.04,49.63,0.184
22.07,49.77,0.184
22.10,49.91,0.184
22.13,50.05,0.184
22.16,50.20,0.184
22.18,50.34,0.184
22.21,50.48,0.184
22.24,50.62,0.185
22.27,50.76,0.185
22.30,50.90,0.185
22.33,51.04,0.185
22.36,51.19,0.185
22.38,51.33,0.185
22.41,51.47,0.186
22.44,51.61,0.186
22.47,51.75,0.186
22.50,51.90,0.186
22.53,52.04,0.186
22.55,52.18,0.186
22.58,52.32,0.186
22.61,52.46,0.187
22.64,52.61,0.187
22.67,52.75,0.187
22.69,52.89,0.187
22.72,53.03,0.187
22.75,53.17,0.187
22.78,53.31,0.187
22.81,53.45,0.188
22.84,53.59,0.188
22.87,53.74,0.188
22.89,53.88,0.188
22.92,54.02,0.188
22.95,54.16,0.188
22.98,54.30,0.188
23.01,54.45,0.189
23.03,54.59,0.189
23.06,54.73,0.189
23.09,54.87,0.189
23.12,55.01,0.189
23.15,55.15,0.189
23.18,55.30,0.190
23.21,55.44,0.190
23.23,55.58,0.190
23.26,55.72,0.190
23.29,55.86,0.190
23.32,56.01,0.191
23.35,56.15,0.191
23.38,56.29,0.191
23.40,56.43,0.191
23.43,56.57,0.191
23.46,56.71,0.191
23.49,56.86,0.191
23.52,57.00,0.192
23.54,57.14,0.192
23.57,57.28,0.192
23.60,57.42,0.192
23.63,57.56,0.192
23.66,57.71,0.192
23.69,57.85,0.192
23.72,57.99,0.193
23.74,58.13,0.193
23.77,58.27,0.193
23.80,58.42,0.193
23.83,58.56,0.193
23.86,58.70,0.193
23.88,58.84,0.194
23.91,58.98,0.194
23.94,59.12,0.194
23.97,59.26,0.194
24.00,59.41,0.194
24.03,59.55,0.194
24.06,59.69,0.195
24.08,59.83,0.195
24.11,59.97,0.195
24.14,60.11,0.195
24.17,60.26,0.195
24.20,60.40,0.196
24.23,60.54,0.196
24.25,60.68,0.196
24.28,60.82,0.196
24.31,60.97,0.196
24.34,61.11,0.197
24.37,61.25,0.197
24.39,61.39,0.197
24.42,61.53,0.197
24.45,61.67,0.197
24.48,61.82,0.197
24.51,61.96,0.198
24.54,62.10,0.198
24.57,62.24,0.198
24.59,62.38,0.198
24.62,62.52,0.198
24.65,62.67,0.199
24.68,62.81,0.199
24.71,62.95,0.199
24.73,63.09,0.199
24.76,63.23,0.199
24.79,63.37,0.200
24.82,63.51,0.200
24.85,63.66,0.200
24.88,63.80,0.200
24.91,63.94,0.200
24.93,64.08,0.201
24.96,64.22,0.201
24.99,64.37,0.201
25.02,64.51,0.201
25.05,64.65,0.202
25.08,64.79,0.202
25.10,64.93,0.202
25.13,65.07,0.202
25.16,65.21,0.202
25.19,65.36,0.203
25.22,65.50,0.203
25.24,65.64,0.203
25.27,65.78,0.203
25.30,65.92,0.204
25.33,66.07,0.204
25.36,66.21,0.204
25.39,66.35,0.204
25.42,66.49,0.204
25.44,66.63,0.205
25.47,66.77,0.205
25.50,66.92,0.205
25.53,67.06,0.205
25.56,67.20,0.206
25.58,67.34,0.206
25.61,67.48,0.206
25.64,67.62,0.206
25.67,67.77,0.207
25.70,67.91,0.207
25.73,68.05,0.207
25.76,68.19,0.207
25.78,68.33,0.207
25.81,68.48,0.208
25.84,68.62,0.208
25.87,68.76,0.208
25.90,68.90,0.208
25.93,69.04,0.209
25.95,69.18,0.209
25.98,69.32,0.209
26.01,69.47,0.209
26.04,69.61,0.210
26.07,69.75,0.210
26.09,69.89,0.210
26.12,70.03,0.211
26.15,70.18,0.211
26.18,70.32,0.211
26.21,70.46,0.211
26.24,70.60,0.212
26.27,70.74,0.212
26.29,70.88,0.212
26.32,71.02,0.212
26.35,71.17,0.213
26.38,71.31,0.213
26.41,71.45,0.213
26.43,71.59,0.214
26.46,71.73,0.214
26.49,71.87,0.214
26.52,72.02,0.214
26.55,72.16,0.215
26.58,72.30,0.215
26.61,72.44,0.215
26.63,72.58,0.216
26.66,72.72,0.216
26.69,72.87,0.216
26.72,73.01,0.216
26.75,73.15,0.217
26.78,73.29,0.217
26.80,73.43,0.217
26.83,73.57,0.217
26.86,73.72,0.218
26.89,73.86,0.218
26.92,74.00,0.218
26.94,74.14,0.219
26.97,74.28,0.219
27.00,74.42,0.219
27.03,74.57,0.220
27.06,74.71,0.220
27.09,74.85,0.220
27.12,74.99,0.221
27.14,75.13,0.221
27.17,75.28,0.221
27.20,75.42,0.222
27.23,75.56,0.222
27.26,75.70,0.222
27.28,75.84,0.222
27.31,75.98,0.223
27.34,76.12,0.223
27.37,76.27,0.223
27.40,76.41,0.224
27.43,76.55,0.224
27.46,76.69,0.225
27.48,76.83,0.225
27.51,76.97,0.225
27.54,77.12,0.226
27.57,77.26,0.226
27.60,77.40,0.226
27.63,77.54,0.227
27.65,77.68,0.227
27.68,77.82,0.227
27.71,77.97,0.228
27.74,78.11,0.228
27.77,78.25,0.229
27.79,78.39,0.229
27.82,78.53,0.229
27.85,78.67,0.230
27.88,78.82,0.230
27.91,78.96,0.230
27.94,79.10,0.231
27.97,79.24,0.231
27.99,79.38,0.231
28.02,79.52,0.232
28.05,79.66,0.232
28.08,79.81,0.233
28.11,79.95,0.233
28.13,80.09,0.233
28.16,80.23,0.234
28.19,80.37,0.234
28.22,80.51,0.234
28.25,80.66,0.235
28.28,80.80,0.235
28.31,80.94,0.236
28.33,81.08,0.236
28.36,81.22,0.236
28.39,81.36,0.237
28.42,81.51,0.237
28.45,81.65,0.238
28.48,81.79,0.238
28.50,81.93,0.239
28.53,82.07,0.239
28.56,82.21,0.240
28.59,82.35,0.240
28.62,82.50,0.240
28.64,82.64,0.241
28.67,82.78,0.241
28.70,82.92,0.242
28.73,83.06,0.242
28.76,83.20,0.243
28.79,83.35,0.243
28.82,83.49,0.244
28.84,83.63,0.244
28.87,83.77,0.245
28.90,83.91,0.245
28.93,84.05,0.246
28.96,84.20,0.246
28.98,84.34,0.247
29.01,84.48,0.247
29.04,84.62,0.248
29.07,84.76,0.248
29.10,84.90,0.249
29.13,85.05,0.249
29.16,85.19,0.250
29.18,85.33,0.250
29.21,85.47,0.251
29.24,85.61,0.251
29.27,85.75,0.252
29.30,85.89,0.252
29.33,86.04,0.253
29.35,86.18,0.253
29.38,86.32,0.254
29.41,86.46,0.254
29.44,86.60,0.255
29.47,86.75,0.255
29.49,86.89,0.256
29.52,87.03,0.256
29.55,87.17,0.257
29.58,87.31,0.257
29.61,87.45,0.258
29.64,87.59,0.258
29.67,87.73,0.259
29.69,87.88,0.259
29.72,88.02,0.260
29.75,88.16,0.260
29.78,88.30,0.261
29.81,88.44,0.261
29.83,88.58,0.262
29.86,88.72,0.262
29.89,88.87,0.263
29.92,89.01,0.264
29.95,89.15,0.264
29.98,89.29,0.265
30.01,89.43,0.265
30.03,89.58,0.266
30.06,89.72,0.266
30.09,89.86,0.267
30.12,90.00,0.267
30.15,90.14,0.268
30.18,90.28,0.268
30.20,90.42,0.269
30.23,90.57,0.269
30.26,90.71,0.269
30.29,90.85,0.270
30.32,90.99,0.270
30.34,91.13,0.271
30.37,91.27,0.271
30.40,91.42,0.272
30.43,91.56,0.272
30.46,91.70,0.272
30.49,91.84,0.273
30.52,91.98,0.273
30.54,92.12,0.273
30.57,92.27,0.273
30.60,92.41,0.274
30.63,92.55,0.274
30.66,92.69,0.274
30.68,92.83,0.274
30.71,92.97,0.274
30.74,93.12,0.274
30.77,93.26,0.274
30.80,93.40,0.274
30.83,93.54,0.274
30.86,93.68,0.274
30.88,93.83,0.274
30.91,93.97,0.273
30.94,94.11,0.273
30.97,94.25,0.273
31.00,94.39,0.272
31.03,94.54,0.272
31.05,94.68,0.271
31.08,94.82,0.270
31.11,94.96,0.269
31.14,95.10,0.268
31.17,95.25,0.267
31.19,95.39,0.265
31.22,95.53,0.264
31.25,95.67,0.262
31.28,95.82,0.260
31.31,95.96,0.258
31.34,96.10,0.257
31.37,96.24,0.255
31.39,96.39,0.253
31.42,96.53,0.252
31.45,96.67,0.250
31.48,96.81,0.247
31.51,96.96,0.245
31.53,97.10,0.243
31.56,97.24,0.241
31.59,97.38,0.239
31.62,97.53,0.237
31.65,97.67,0.236
31.68,97.81,0.233
31.71,97.95,0.231
31.73,98.10,0.230
31.76,98.24,0.228
31.79,98.38,0.226
31.82,98.52,0.224
31.85,98.67,0.223
31.88,98.81,0.221
31.90,98.95,0.220
31.93,99.09,0.219
31.96,99.24,0.216
31.99,99.38,0.215
32.02,99.52,0.214
32.04,99.66,0.212
32.07,99.81,0.211
32.10,99.95,0.209
32.13,100.09,0.207
32.16,100.23,0.205
32.19,100.37,0.204
32.22,100.52,0.203
32.24,100.66,0.202
32.27,100.80,0.201
32.30,100.94,0.199
32.33,101.08,0.198
32.36,101.23,0.197
32.38,101.37,0.196
32.41,101.51,0.195
32.44,101.66,0.194
32.47,101.80,0.193
32.50,101.94,0.191
32.53,102.08,0.191
32.56,102.22,0.190
32.58,102.37,0.189
32.61,102.51,0.189
32.64,102.65,0.188
32.67,102.79,0.187
32.70,102.93,0.186
32.73,103.08,0.186
32.75,103.22,0.185
32.78,103.36,0.185
32.81,103.50,0.184
32.84,103.64,0.184
32.87,103.78,0.183
32.89,103.93,0.183
32.92,104.07,0.182
32.95,104.21,0.182
32.98,104.35,0.182
33.01,104.49,0.181
33.04,104.64,0.181
33.07,104.78,0.181
33.09,104.92,0.180
33.12,105.06,0.180
33.15,105.20,0.180
33.18,105.34,0.180
33.21,105.49,0.179
33.23,105.63,0.179
33.26,105.77,0.179
33.29,105.91,0.179
33.32,106.05,0.179
33.35,106.19,0.179
33.38,106.34,0.179
33.41,106.48,0.179
33.43,106.62,0.179
33.46,106.76,0.179
33.49,106.90,0.178
33.52,107.05,0.178
33.55,107.19,0.178
33.58,107.33,0.178
33.60,107.47,0.178
33.63,107.61,0.178
33.66,107.76,0.178
33.69,107.90,0.178
33.72,108.04,0.178
33.74,108.18,0.178
33.77,108.32,0.178
33.80,108.46,0.178
33.83,108.60,0.178
33.86,108.75,0.178
33.89,108.89,0.178
33.92,109.03,0.178
33.94,109.17,0.178
33.97,109.31,0.178
34.00,109.45,0.178
34.03,109.60,0.178
34.06,109.74,0.178
34.08,109.88,0.178
34.11,110.02,0.178
34.14,110.16,0.178
34.17,110.31,0.178
34.20,110.45,0.178
34.23,110.59,0.178
34.26,110.73,0.178
34.28,110.87,0.178
34.31,111.01,0.178
34.34,111.16,0.178
34.37,111.30,0.178
34.40,111.44,0.178
34.43,111.58,0.178
34.45,111.72,0.178
34.48,111.86,0.178
34.51,112.01,0.178
34.54,112.15,0.178
34.57,112.29,0.178
34.59,112.43,0.178
34.62,112.57,0.178
34.65,112.71,0.178
34.68,112.86,0.178
34.71,113.00,0.178
34.74,113.14,0.178
34.76,113.28,0.178
34.79,113.42,0.178
34.82,113.57,0.178
34.85,113.71,0.178
34.88,113.85,0.178
34.91,113.99,0.178
34.94,114.13,0.178
34.96,114.28,0.178
34.99,114.42,0.178
35.02,114.56,0.178
35.05,114.70,0.178
35.08,114.84,0.178
35.11,114.98,0.178
35.13,115.13,0.178
35.16,115.27,0.178
35.19,115.41,0.178
35.22,115.55,0.177
35.25,115.69,0.177
35.28,115.84,0.177
35.30,115.98,0.177
35.33,116.12,0.177
35.36,116.26,0.177
35.39,116.40,0.177
35.42,116.54,0.177
35.44,116.68,0.177
35.47,116.83,0.177
35.50,116.97,0.177
35.53,117.11,0.177
35.56,117.25,0.177
35.59,117.39,0.177
35.61,117.53,0.177
35.64,117.68,0.177
35.67,117.82,0.177
35.70,117.96,0.177
35.73,118.10,0.177
35.76,118.24,0.177
35.79,118.38,0.177
35.81,118.53,0.177
35.84,118.67,0.177
35.87,118.81,0.177
35.90,118.95,0.177
35.93,119.09,0.177
35.96,119.24,0.177
35.98,119.38,0.177
36.01,119.52,0.177
36.04,119.66,0.177
36.07,119.80,0.177
36.10,119.95,0.177
36.13,120.09,0.177
36.15,120.23,0.177
36.18,120.37,0.177
36.21,120.51,0.177
36.24,120.65,0.177
36.27,120.79,0.177
36.29,120.94,0.177
36.32,121.08,0.177
36.35,121.22,0.177
36.38,121.36,0.177
36.41,121.50,0.177
36.44,121.64,0.177
36.46,121.79,0.177
36.49,121.93,0.177
36.52,122.07,0.177
36.55,122.21,0.177
36.58,122.35,0.177
36.61,122.50,0.177
36.64,122.64,0.177
36.66,122.78,0.177
36.69,122.92,0.177
36.72,123.06,0.177
36.75,123.21,0.177
36.78,123.35,0.177
36.81,123.49,0.177
36.83,123.63,0.177
36.86,123.77,0.177
36.89,123.91,0.177
36.92,124.06,0.177
36.95,124.20,0.177
36.98,124.34,0.177
37.00,124.48,0.177
37.03,124.62,0.177
37.06,124.76,0.177
37.09,124.91,0.177
37.12,125.05,0.177
37.14,125.19,0.177
37.17,125.33,0.177
37.20,125.47,0.177
37.23,125.61,0.177
37.26,125.76,0.177
37.29,125.90,0.177
37.31,126.04,0.176
37.34,126.18,0.176
37.37,126.32,0.176
37.40,126.46,0.176
37.43,126.61,0.176
37.46,126.75,0.176
37.49,126.89,0.176
37.51,127.03,0.176
37.54,127.17,0.176
37.57,127.32,0.176
37.60,127.46,0.176
37.63,127.60,0.176
37.66,127.74,0.176
37.68,127.88,0.176
37.71,128.03,0.176
37.74,128.17,0.176
37.77,128.31,0.176
37.80,128.45,0.176
37.83,128.59,0.176
37.85,128.73,0.176
37.88,128.87,0.176
37.91,129.02,0.176
37.94,129.16,0.176
37.97,129.30,0.176
37.99,129.44,0.176
38.02,129.58,0.176
38.05,129.72,0.176
38.08,129.87,0.176
38.11,130.01,0.176
38.14,130.15,0.176
38.16,130.29,0.176
38.19,130.43,0.176
38.22,130.57,0.176
38.25,130.72,0.176
38.28,130.86,0.176
38.31,131.00,0.176
38.34,131.14,0.176
38.36,131.28,0.176
38.39,131.42,0.176
38.42,131.57,0.176
38.45,131.71,0.176
38.48,131.85,0.176
38.51,131.99,0.176
38.53,132.13,0.176
38.56,132.28,0.176
38.59,132.42,0.176
38.62,132.56,0.176
38.65,132.70,0.176
38.68,132.84,0.176
38.70,132.98,0.176
38.73,133.13,0.176
38.76,133.27,0.176
38.79,133.41,0.176
38.82,133.55,0.176
38.84,133.69,0.176
38.87,133.84,0.176
38.90,133.98,0.176
38.93,134.12,0.176
38.96,134.26,0.176
38.99,134.40,0.176
39.01,134.54,0.176
39.04,134.68,0.176
39.07,134.83,0.176
39.10,134.97,0.176
39.13,135.11,0.176
39.16,135.25,0.176
39.19,135.39,0.176
39.21,135.54,0.176
39.24,135.68,0.176
39.27,135.82,0.176
39.30,135.96,0.176
39.33,136.10,0.176
39.36,136.24,0.176
39.38,136.39,0.176
39.41,136.53,0.176
39.44,136.67,0.176
39.47,136.81,0.176
39.50,136.95,0.176
39.53,137.09,0.176
39.55,137.24,0.176
39.58,137.38,0.176
39.61,137.52,0.176
39.64,137.66,0.176
39.67,137.80,0.176
39.69,137.94,0.176
39.72,138.09,0.176
39.75,138.23,0.176
39.78,138.37,0.176
39.81,138.51,0.176
39.84,138.65,0.176
39.86,138.80,0.176
39.89,138.94,0.176
39.92,139.08,0.176
39.95,139.22,0.176
39.98,139.36,0.176
40.01,139.50,0.176
40.04,139.65,0.176
40.06,139.79,0.176
40.09,139.93,0.176
40.12,140.07,0.176
40.15,140.21,0.176
40.18,140.35,0.176
40.21,140.50,0.176
40.23,140.64,0.177
40.26,140.78,0.177
40.29,140.92,0.177
40.32,141.06,0.177
40.35,141.21,0.177
40.38,141.35,0.177
40.40,141.49,0.177
40.43,141.63,0.177
40.46,141.77,0.177
40.49,141.91,0.177
40.52,142.06,0.177
40.54,142.20,0.177
40.57,142.34,0.177
40.60,142.48,0.177
40.63,142.62,0.177
40.66,142.76,0.177
40.69,142.90,0.177
40.71,143.05,0.177
40.74,143.19,0.177
40.77,143.33,0.177
40.80,143.47,0.177
40.83,143.61,0.177
40.86,143.75,0.177
40.89,143.90,0.177
40.91,144.04,0.177
40.94,144.18,0.177
40.97,144.32,0.177
41.00,144.46,0.177
41.03,144.61,0.177
41.06,144.75,0.177
41.08,144.89,0.177
41.11,145.03,0.177
41.14,145.17,0.177
41.17,145.31,0.177
41.20,145.46,0.177
41.23,145.60,0.177
41.25,145.74,0.177
41.28,145.88,0.177
41.31,146.02,0.177
41.34,146.16,0.178
41.37,146.31,0.178
41.39,146.45,0.178
41.42,146.59,0.178
41.45,146.74,0.179
41.48,146.88,0.179
41.51,147.02,0.179
41.54,147.16,0.179
41.56,147.30,0.179
41.59,147.45,0.179
41.62,147.59,0.178
41.65,147.73,0.178
41.68,147.87,0.178
41.71,148.01,0.178
41.74,148.15,0.178
41.76,148.29,0.178
41.79,148.44,0.178
41.82,148.58,0.178
41.85,148.72,0.178
41.88,148.86,0.178
41.91,149.00,0.178
41.93,149.14,
41.96,149.28,
41.99,,

[step]
Ramp 5.00 °C/min to -60.00 °C
Time,Temperature,Heat Flow (Normalized)
min,°C,W/g
42.99,150.12,-0.050
43.01,150.12,-0.050
43.04,150.11,-0.052
43.07,150.09,-0.078
43.10,150.04,-0.113
43.13,149.97,-0.149
43.16,149.88,-0.177
43.19,149.77,-0.201
43.21,149.66,-0.218
43.24,149.54,-0.229
43.27,149.42,-0.242
43.30,149.29,-0.249
43.33,149.16,-0.253
43.36,149.03,-0.259
43.38,148.90,-0.261
43.41,148.76,-0.264
43.44,148.62,-0.266
43.47,148.49,-0.267
43.50,148.35,-0.269
43.53,148.21,-0.269
43.55,148.07,-0.270
43.58,147.93,-0.270
43.61,147.79,-0.271
43.64,147.65,-0.271
43.67,147.51,-0.271
43.69,147.37,-0.271
43.72,147.23,-0.272
43.75,147.09,-0.272
43.78,146.95,-0.272
43.81,146.81,-0.272
43.84,146.67,-0.272
43.86,146.53,-0.272
43.89,146.39,-0.272
43.92,146.25,-0.273
43.95,146.11,-0.273
43.98,145.97,-0.273
44.01,145.83,-0.273
44.04,145.68,-0.273
44.06,145.54,-0.273
44.09,145.40,-0.273
44.12,145.26,-0.272
44.15,145.12,-0.272
44.18,144.98,-0.272
44.21,144.84,-0.272
44.23,144.70,-0.272
44.26,144.56,-0.272
44.29,144.41,-0.272
44.32,144.27,-0.272
44.35,144.13,-0.271
44.38,143.99,-0.271
44.40,143.85,-0.271
44.43,143.71,-0.271
44.46,143.57,-0.271
44.49,143.42,-0.271
44.52,143.28,-0.271
44.54,143.14,-0.271
44.57,143.00,-0.270
44.60,142.86,-0.270
44.63,142.72,-0.270
44.66,142.57,-0.270
44.69,142.43,-0.270
44.71,142.29,-0.270
44.74,142.15,-0.269
44.77,142.01,-0.269
44.80,141.87,-0.269
44.83,141.73,-0.269
44.86,141.58,-0.269
44.89,141.44,-0.269
44.91,141.30,-0.268
44.94,141.16,-0.268
44.97,141.02,-0.268
45.00,140.88,-0.268
45.03,140.74,-0.268
45.06,140.59,-0.268
45.08,140.45,-0.267
45.11,140.31,-0.267
45.14,140.17,-0.267
45.17,140.03,-0.267
45.20,139.89,-0.267
45.23,139.74,-0.267
45.25,139.60,-0.266
45.28,139.46,-0.266
45.31,139.32,-0.266
45.34,139.18,-0.266
45.37,139.04,-0.266
45.39,138.89,-0.266
45.42,138.75,-0.266
45.45,138.61,-0.266
45.48,138.47,-0.265
45.51,138.33,-0.265
45.54,138.19,-0.265
45.56,138.04,-0.265
45.59,137.90,-0.265
45.62,137.76,-0.265
45.65,137.62,-0.264
45.68,137.48,-0.264
45.71,137.34,-0.264
45.74,137.20,-0.264
45.76,137.05,-0.264
45.79,136.91,-0.264
45.82,136.77,-0.264
45.85,136.63,-0.263
45.88,136.49,-0.263
45.91,136.35,-0.263
45.93,136.21,-0.263
45.96,136.06,-0.263
45.99,135.92,-0.263
46.02,135.78,-0.263
46.05,135.64,-0.263
46.08,135.50,-0.263
46.10,135.36,-0.263
46.13,135.21,-0.262
46.16,135.07,-0.262
46.19,134.93,-0.262
46.22,134.79,-0.262
46.24,134.65,-0.262
46.27,134.51,-0.262
46.30,134.36,-0.262
46.33,134.22,-0.262
46.36,134.08,-0.261
46.39,133.94,-0.261
46.41,133.80,-0.261
46.44,133.66,-0.261
46.47,133.51,-0.261
46.50,133.37,-0.261
46.53,133.23,-0.261
46.56,133.09,-0.261
46.59,132.95,-0.261
46.61,132.81,-0.260
46.64,132.66,-0.260
46.67,132.52,-0.260
46.70,132.38,-0.260
46.73,132.24,-0.260
46.76,132.10,-0.260
46.78,131.96,-0.260
46.81,131.82,-0.260
46.84,131.67,-0.260
46.87,131.53,-0.260
46.90,131.39,-0.259
46.93,131.25,-0.259
46.95,131.11,-0.259
46.98,130.97,-0.259
47.01,130.82,-0.259
47.04,130.68,-0.259
47.07,130.54,-0.259
47.09,130.40,-0.259
47.12,130.26,-0.259
47.15,130.12,-0.259
47.18,129.97,-0.258
47.21,129.83,-0.258
47.24,129.69,-0.258
47.26,129.55,-0.258
47.29,129.41,-0.258
47.32,129.27,-0.258
47.35,129.13,-0.258
47.38,128.98,-0.258
47.41,128.84,-0.258
47.44,128.70,-0.258
47.46,128.56,-0.257
47.49,128.42,-0.257
47.52,128.28,-0.257
47.55,128.13,-0.257
47.58,127.99,-0.257
47.61,127.85,-0.257
47.63,127.71,-0.257
47.66,127.57,-0.257
47.69,127.43,-0.257
47.72,127.28,-0.257
47.75,127.14,-0.257
47.78,127.00,-0.257
47.80,126.86,-0.257
47.83,126.72,-0.256
47.86,126.58,-0.256
47.89,126.44,-0.256
47.92,126.29,-0.256
47.94,126.15,-0.256
47.97,126.01,-0.256
48.00,125.87,-0.256
48.03,125.73,-0.256
48.06,125.59,-0.256
48.09,125.44,-0.256
48.11,125.30,-0.256
48.14,125.16,-0.255
48.17,125.02,-0.255
48.20,124.88,-0.255
48.23,124.74,-0.255
48.26,124.60,-0.255
48.29,124.45,-0.255
48.31,124.31,-0.255
48.34,124.17,-0.255
48.37,124.03,-0.255
48.40,123.89,-0.255
48.43,123.74,-0.255
48.46,123.60,-0.255
48.48,123.46,-0.255
48.51,123.32,-0.254
48.54,123.18,-0.254
48.57,123.04,-0.254
48.60,122.90,-0.254
48.63,122.75,-0.254
48.65,122.61,-0.254
48.68,122.47,-0.254
48.71,122.33,-0.254
48.74,122.19,-0.254
48.77,122.05,-0.254
48.79,121.90,-0.254
48.82,121.76,-0.253
48.85,121.62,-0.253
48.88,121.48,-0.253
48.91,121.34,-0.253
48.94,121.20,-0.253
48.96,121.06,-0.253
48.99,120.91,-0.253
49.02,120.77,-0.253
49.05,120.63,-0.253
49.08,120.49,-0.253
49.11,120.35,-0.253
49.14,120.20,-0.253
49.16,120.06,-0.253
49.19,119.92,-0.253
49.22,119.78,-0.253
49.25,119.64,-0.253
49.28,119.50,-0.253
49.31,119.36,-0.253
49.33,119.21,-0.252
49.36,119.07,-0.252
49.39,118.93,-0.252
49.42,118.79,-0.252
49.45,118.65,-0.252
49.48,118.51,-0.252
49.50,118.36,-0.252
49.53,118.22,-0.252
49.56,118.08,-0.252
49.59,117.94,-0.252
49.62,117.80,-0.252
49.64,117.66,-0.252
49.67,117.52,-0.252
49.70,117.37,-0.252
49.73,117.23,-0.252
49.76,117.09,-0.251
49.79,116.95,-0.251
49.81,116.81,-0.251
49.84,116.66,-0.251
49.87,116.52,-0.251
49.90,116.38,-0.251
49.93,116.24,-0.251
49.96,116.10,-0.251
49.99,115.96,-0.251
50.01,115.82,-0.251
50.04,115.67,-0.251
50.07,115.53,-0.251
50.10,115.39,-0.251
50.13,115.25,-0.251
50.16,115.11,-0.251
50.18,114.97,-0.251
50.21,114.82,-0.250
50.24,114.68,-0.250
50.27,114.54,-0.250
50.30,114.40,-0.250
50.33,114.26,-0.250
50.35,114.12,-0.250
50.38,113.97,-0.250
50.41,113.83,-0.250
50.44,113.69,-0.250
50.47,113.55,-0.250
50.49,113.41,-0.250
50.52,113.27,-0.250
50.55,113.13,-0.250
50.58,112.98,-0.250
50.61,112.84,-0.250
50.64,112.70,-0.250
50.66,112.56,-0.250
50.69,112.42,-0.249
50.72,112.28,-0.249
50.75,112.14,-0.249
50.78,111.99,-0.249
50.81,111.85,-0.249
50.84,111.71,-0.249
50.86,111.57,-0.249
50.89,111.43,-0.249
50.92,111.29,-0.249
50.95,111.14,-0.249
50.98,111.00,-0.249
51.01,110.86,-0.249
51.03,110.72,-0.249
51.06,110.58,-0.249
51.09,110.44,-0.249
51.12,110.29,-0.248
51.15,110.15,-0.248
51.18,110.01,-0.248
51.20,109.87,-0.248
51.23,109.73,-0.248
51.26,109.59,-0.248
51.29,109.45,-0.248
51.32,109.30,-0.248
51.34,109.16,-0.248
51.37,109.02,-0.248
51.40,108.88,-0.248
51.43,108.74,-0.248
51.46,108.59,-0.248
51.49,108.45,-0.248
51.51,108.31,-0.248
51.54,108.17,-0.248
51.57,108.03,-0.248
51.60,107.89,-0.247
51.63,107.75,-0.247
51.66,107.60,-0.247
51.69,107.46,-0.247
51.71,107.32,-0.247
51.74,107.18,-0.247
51.77,107.04,-0.247
51.80,106.90,-0.247
51.83,106.75,-0.247
51.86,106.61,-0.247
51.88,106.47,-0.247
51.91,106.33,-0.247
51.94,106.19,-0.247
51.97,106.05,-0.247
52.00,105.91,-0.247
52.03,105.76,-0.247
52.05,105.62,-0.247
52.08,105.48,-0.247
52.11,105.34,-0.247
52.14,105.20,-0.246
52.17,105.06,-0.246
52.19,104.91,-0.246
52.22,104.77,-0.246
52.25,104.63,-0.246
52.28,104.49,-0.246
52.31,104.35,-0.246
52.34,104.21,-0.246
52.36,104.06,-0.246
52.39,103.92,-0.246
52.42,103.78,-0.246
52.45,103.64,-0.246
52.48,103.50,-0.246
52.51,103.36,-0.246
[...]
176.16,-39.91,0.113
176.18,-39.84,0.113
176.19,-39.77,0.113
176.20,-39.71,0.113
176.22,-39.64,0.113
176.23,-39.57,0.114
176.24,-39.51,0.114
176.25,-39.44,0.113
176.27,-39.37,0.114
176.28,-39.30,0.114
176.30,-39.24,0.114
176.31,-39.17,0.114
176.32,-39.10,0.114
176.33,-39.04,0.114
176.35,-38.97,0.114
176.36,-38.90,0.114
176.38,-38.84,0.114
176.39,-38.77,0.114
176.40,-38.70,0.114
176.42,-38.64,0.114
176.43,-38.57,0.114
176.44,-38.50,0.114
176.45,-38.44,0.114
176.47,-38.37,0.114
176.48,-38.30,0.114
176.50,-38.24,0.114
176.51,-38.17,0.114
176.52,-38.10,0.114
176.53,-38.04,0.114
176.55,-37.97,0.114
176.56,-37.90,0.114
176.58,-37.84,0.114
176.59,-37.77,0.114
176.60,-37.70,0.114
176.62,-37.63,0.114
176.63,-37.57,0.114
176.64,-37.50,0.114
176.65,-37.44,0.114
176.67,-37.37,0.114
176.68,-37.30,0.114
176.70,-37.23,0.114
176.71,-37.17,0.114
176.72,-37.10,0.114
176.73,-37.03,0.114
176.75,-36.97,0.114
176.76,-36.90,0.114
176.78,-36.83,0.114
176.79,-36.77,0.114
176.80,-36.70,0.114
176.82,-36.63,0.114
176.83,-36.57,0.114
176.84,-36.50,0.114
176.85,-36.43,0.114
176.87,-36.36,0.114
176.88,-36.30,0.114
176.90,-36.23,0.114
176.91,-36.17,0.114
176.92,-36.10,0.114
176.93,-36.03,0.114
176.95,-35.97,0.114
176.96,-35.90,0.114
176.98,-35.83,0.114
176.99,-35.77,0.114
177.00,-35.70,0.114
177.02,-35.63,0.114
177.03,-35.57,0.114
177.04,-35.50,0.114
177.05,-35.43,0.114
177.07,-35.36,0.114
177.08,-35.30,0.114
177.10,-35.23,0.114
177.11,-35.17,0.114
177.12,-35.10,0.114
177.13,-35.03,0.115
177.15,-34.97,0.115
177.16,-34.90,0.115
177.18,-34.83,0.115
177.19,-34.77,0.115
177.20,-34.70,0.115
177.22,-34.63,0.115
177.23,-34.57,0.115
177.24,-34.50,0.115
177.25,-34.43,0.115
177.27,-34.36,0.115
177.28,-34.30,0.115
177.30,-34.23,0.115
177.31,-34.16,0.115
177.32,-34.10,0.115
177.33,-34.03,0.115
177.35,-33.96,0.115
177.36,-33.90,0.115
177.38,-33.83,0.115
177.39,-33.76,0.115
177.40,-33.70,0.115
177.42,-33.63,0.115
177.43,-33.56,0.115
177.44,-33.50,0.115
177.45,-33.43,0.115
177.47,-33.36,0.115
177.48,-33.30,0.115
177.50,-33.23,0.115
177.51,-33.16,0.115
177.52,-33.10,0.115
177.53,-33.03,0.115
177.55,-32.96,0.115
177.56,-32.90,0.115
177.58,-32.83,0.115
177.59,-32.76,0.115
177.60,-32.70,0.115
177.62,-32.63,0.115
177.63,-32.56,0.115
177.64,-32.50,0.115
177.65,-32.43,0.115
177.67,-32.36,0.115
177.68,-32.30,0.115
177.70,-32.23,0.115
177.71,-32.16,0.115
177.72,-32.10,0.115
177.73,-32.03,0.115
177.75,-31.96,0.115
177.76,-31.89,0.116
177.78,-31.83,0.115
177.79,-31.76,0.115
177.80,-31.70,0.116
177.82,-31.63,0.116
177.83,-31.56,0.116
177.84,-31.49,0.116
177.85,-31.43,0.116
177.87,-31.36,0.116
177.88,-31.30,0.116
177.90,-31.23,0.116
177.91,-31.16,0.116
177.92,-31.09,0.116
177.93,-31.03,0.116
177.95,-30.96,0.116
177.96,-30.89,0.116
177.98,-30.83,0.116
177.99,-30.76,0.116
178.00,-30.69,0.116
178.02,-30.63,0.116
178.03,-30.56,0.116
178.04,-30.49,0.116
178.05,-30.43,0.116
178.07,-30.36,0.116
178.08,-30.29,0.116
178.10,-30.23,0.116
178.11,-30.16,0.116
178.12,-30.09,0.116
178.13,-30.03,0.116
178.15,-29.96,0.116
178.16,-29.89,0.116
178.18,-29.83,0.116
178.19,-29.76,0.116
178.20,-29.69,0.116
178.22,-29.63,0.116
178.23,-29.56,0.116
178.24,-29.49,0.116
178.25,-29.43,0.116
178.27,-29.36,0.116
178.28,-29.29,0.116
178.30,-29.23,0.116
178.31,-29.16,0.116
178.32,-29.09,0.116
178.33,-29.03,0.116
178.35,-28.96,0.116
178.36,-28.89,0.116
178.38,-28.83,0.116
178.39,-28.76,0.116
178.40,-28.69,0.117
178.42,-28.63,0.117
178.43,-28.56,0.117
178.44,-28.49,0.117
178.45,-28.43,0.117
178.47,-28.36,0.117
178.48,-28.29,0.117
178.50,-28.23,0.117
178.51,-28.16,0.117
178.52,-28.09,0.117
178.53,-28.03,0.117
178.55,-27.96,0.117
178.56,-27.89,0.117
178.58,-27.82,0.117
178.59,-27.76,0.117
178.60,-27.69,0.117
178.62,-27.63,0.117
178.63,-27.56,0.117
178.64,-27.49,0.117
178.65,-27.43,0.117
178.67,-27.36,0.117
178.68,-27.29,0.117
178.70,-27.23,0.117
178.71,-27.16,0.117
178.72,-27.09,0.117
178.73,-27.03,0.117
178.75,-26.96,0.117
178.76,-26.89,0.117
178.78,-26.82,0.117
178.79,-26.76,0.117
178.80,-26.69,0.117
178.82,-26.62,0.117
178.83,-26.56,0.118
178.84,-26.49,0.118
178.85,-26.42,0.118
178.87,-26.36,0.118
178.88,-26.29,0.118
178.90,-26.22,0.118
178.91,-26.16,0.118
178.92,-26.09,0.118
178.93,-26.02,0.118
178.95,-25.96,0.118
178.96,-25.89,0.118
178.98,-25.82,0.118
178.99,-25.76,0.118
179.00,-25.69,0.118
179.02,-25.62,0.118
179.03,-25.56,0.118
179.04,-25.49,0.118
179.05,-25.42,0.118
179.07,-25.36,0.118
179.08,-25.29,0.118
179.10,-25.22,0.118
179.11,-25.16,0.118
179.12,-25.09,0.118
179.13,-25.02,0.118
179.15,-24.96,0.118
179.16,-24.89,0.118
179.18,-24.82,0.118
179.19,-24.76,0.118
179.20,-24.69,0.118
179.22,-24.62,0.118
179.23,-24.56,0.118
179.24,-24.49,0.118
179.25,-24.42,0.119
179.27,-24.36,0.119
179.28,-24.29,0.119
179.30,-24.22,0.119
179.31,-24.15,0.119
179.32,-24.09,0.119
179.33,-24.02,0.119
179.35,-23.96,0.119
179.36,-23.89,0.119
179.38,-23.82,0.119
179.39,-23.75,0.119
179.40,-23.69,0.119
179.42,-23.62,0.119
179.43,-23.56,0.119
179.44,-23.49,0.119
179.45,-23.42,0.119
179.47,-23.36,0.119
179.48,-23.29,0.119
179.50,-23.22,0.119
179.51,-23.16,0.119
179.52,-23.09,0.119
179.53,-23.02,0.120
179.55,-22.95,0.120
179.56,-22.89,0.120
179.58,-22.82,0.120
179.59,-22.76,0.120
179.60,-22.69,0.120
179.62,-22.62,0.120
179.63,-22.56,0.120
179.64,-22.49,0.120
179.65,-22.42,0.120
179.67,-22.36,0.120
179.68,-22.29,0.120
179.70,-22.22,0.120
179.71,-22.16,0.120
179.72,-22.09,0.120
179.73,-22.02,0.120
179.75,-21.95,0.121
179.76,-21.89,0.121
179.78,-21.82,0.121
179.79,-21.75,0.121
179.80,-21.69,0.121
179.82,-21.62,0.121
179.83,-21.55,0.121
179.84,-21.49,0.121
179.85,-21.42,0.121
179.87,-21.35,0.121
179.88,-21.29,0.121
179.90,-21.22,0.121
179.91,-21.15,0.121
179.92,-21.09,0.121
179.93,-21.02,0.121
179.95,-20.95,0.122
179.96,-20.89,0.122
179.98,-20.82,0.122
179.99,-20.75,0.122
180.00,-20.69,0.122
180.02,-20.62,0.122
180.03,-20.55,0.122
180.04,-20.49,0.122
180.05,-20.42,0.122
180.07,-20.35,0.122
180.08,-20.29,0.123
180.10,-20.22,0.123
180.11,-20.15,0.123
180.12,-20.09,0.123
180.13,-20.02,0.123
180.15,-19.95,0.123
180.16,-19.89,0.123
180.18,-19.82,0.123
180.19,-19.75,0.123
180.20,-19.69,0.123
180.22,-19.62,0.123
180.23,-19.55,0.123
180.24,-19.49,0.124
180.25,-19.42,0.124
180.27,-19.35,0.124
180.28,-19.29,0.124
180.30,-19.22,0.124
180.31,-19.15,0.124
180.32,-19.09,0.124
180.33,-19.02,0.124
180.35,-18.95,0.124
180.36,-18.89,0.124
180.38,-18.82,0.125
180.39,-18.75,0.125
180.40,-18.69,0.125
180.42,-18.62,0.125
180.43,-18.55,0.125
180.44,-18.49,0.125
180.45,-18.42,0.125
180.47,-18.35,0.125
180.48,-18.29,0.125
180.50,-18.22,0.125
180.51,-18.15,0.126
180.52,-18.09,0.126
180.53,-18.02,0.126
180.55,-17.95,0.126
180.56,-17.89,0.126
180.58,-17.82,0.126
180.59,-17.75,0.126
180.60,-17.69,0.126
180.62,-17.62,0.126
180.63,-17.55,0.127
180.64,-17.49,0.127
180.65,-17.42,0.127
180.67,-17.35,0.127
180.68,-17.29,0.127
180.70,-17.22,0.127
180.71,-17.15,0.127
180.72,-17.09,0.128
180.73,-17.02,0.128
180.75,-16.95,0.128
180.76,-16.89,0.128
180.78,-16.82,0.128
180.79,-16.75,0.128
180.80,-16.69,0.128
180.82,-16.62,0.129
180.83,-16.55,0.129
180.84,-16.49,0.129
180.85,-16.42,0.129
180.87,-16.35,0.129
180.88,-16.29,0.129
180.90,-16.22,0.129
180.91,-16.15,0.130
180.92,-16.09,0.130
180.93,-16.02,0.130
180.95,-15.95,0.130
180.96,-15.89,0.130
180.98,-15.82,0.130
180.99,-15.75,0.130
181.00,-15.69,0.131
181.02,-15.62,0.131
181.03,-15.55,0.131
181.04,-15.49,0.131
181.05,-15.42,0.131
181.07,-15.35,0.132
181.08,-15.29,0.132
181.10,-15.22,0.132
181.11,-15.15,0.132
181.12,-15.09,0.132
181.13,-15.02,0.132
181.15,-14.95,0.132
181.16,-14.89,0.133
181.18,-14.82,0.133
181.19,-14.75,0.133
181.20,-14.69,0.133
181.22,-14.62,0.133
181.23,-14.55,0.134
181.24,-14.49,0.134
181.25,-14.42,0.134
181.27,-14.35,0.134
181.28,-14.29,0.134
181.30,-14.22,0.134
181.31,-14.15,0.134
181.32,-14.09,0.135
181.33,-14.02,0.135
181.35,-13.96,0.135
181.36,-13.89,0.135
181.38,-13.82,0.135
181.39,-13.76,0.135
181.40,-13.69,0.136
181.42,-13.62,0.136
181.43,-13.55,0.136
181.44,-13.49,0.136
181.45,-13.42,0.136
181.47,-13.36,0.136
181.48,-13.29,0.137
181.50,-13.22,0.137
181.51,-13.15,0.137
181.52,-13.09,0.137
181.53,-13.02,0.137
181.55,-12.95,0.137
181.56,-12.89,0.138
181.58,-12.82,0.138
181.59,-12.75,0.138
181.60,-12.69,0.138
181.62,-12.62,0.138
181.63,-12.55,0.139
181.64,-12.49,0.139
181.65,-12.42,0.139
181.67,-12.35,0.140
181.68,-12.29,0.140
181.70,-12.22,0.140
181.71,-12.15,0.140
181.72,-12.09,0.140
181.73,-12.02,0.140
181.75,-11.96,0.141
181.76,-11.89,0.141
181.78,-11.82,0.141
181.79,-11.75,0.141
181.80,-11.69,0.141
181.82,-11.62,0.141
181.83,-11.56,0.142
181.84,-11.49,0.142
181.85,-11.42,0.142
181.87,-11.35,0.142
181.88,-11.29,0.142
181.90,-11.22,0.142
181.91,-11.15,0.143
181.92,-11.09,0.143
181.93,-11.02,0.143
181.95,-10.95,0.143
181.96,-10.89,0.143
181.98,-10.82,0.143
181.99,-10.75,0.144
182.00,-10.69,0.144
182.02,-10.62,0.144
182.03,-10.55,0.144
182.04,-10.49,0.144
182.05,-10.42,0.144
182.07,-10.35,0.145
182.08,-10.29,0.145
182.10,-10.22,0.145
182.11,-10.15,0.145
182.12,-10.08,0.146
182.13,-10.02,0.146
182.15,-9.95,0.146
182.16,-9.88,0.146
182.18,-9.82,0.146
182.19,-9.75,0.147
182.20,-9.68,0.147
182.22,-9.62,0.147
182.23,-9.55,0.147
182.24,-9.48,0.147
182.25,-9.42,0.147
182.27,-9.35,0.147
182.28,-9.28,0.148
182.30,-9.22,0.148
182.31,-9.15,0.148
182.32,-9.08,0.148
182.33,-9.02,0.148
182.35,-8.95,0.148
182.36,-8.88,0.148
182.38,-8.82,0.148
182.39,-8.75,0.149
182.40,-8.68,0.149
182.42,-8.62,0.149
182.43,-8.55,0.149
182.44,-8.49,0.149
182.45,-8.42,0.149
182.47,-8.35,0.149
182.48,-8.28,0.150
182.50,-8.22,0.150
182.51,-8.15,0.150
182.52,-8.09,0.150
182.53,-8.02,0.150
182.55,-7.95,0.150
182.56,-7.89,0.150
182.58,-7.82,0.150
182.59,-7.75,0.150
182.60,-7.69,0.151
182.62,-7.62,0.151
182.63,-7.55,0.151
182.64,-7.49,0.151
182.65,-7.42,0.151
182.67,-7.35,0.151
182.68,-7.29,0.151
182.70,-7.22,0.151
182.71,-7.15,0.152
182.72,-7.09,0.152
182.73,-7.02,0.152
182.75,-6.95,0.152
182.76,-6.89,0.152
182.78,-6.82,0.152
182.79,-6.75,0.152
182.80,-6.69,0.152
182.82,-6.62,0.152
182.83,-6.55,0.152
182.84,-6.49,0.153
182.85,-6.42,0.153
182.87,-6.35,0.153
182.88,-6.29,0.153
182.90,-6.22,0.153
182.91,-6.15,0.153
182.92,-6.09,0.153
182.93,-6.02,0.153
182.95,-5.95,0.153
182.96,-5.89,0.153
182.98,-5.82,0.153
182.99,-5.75,0.153
183.00,-5.69,0.153
183.02,-5.62,0.154
183.03,-5.55,0.154
183.04,-5.49,0.154
183.05,-5.42,0.154
183.07,-5.35,0.154
183.08,-5.29,0.154
183.10,-5.22,0.154
183.11,-5.15,0.154
183.12,-5.09,0.154
183.13,-5.02,0.154
183.15,-4.95,0.154
183.16,-4.89,0.154
183.18,-4.82,0.154
183.19,-4.75,0.154
183.20,-4.69,0.154
183.22,-4.62,0.154
183.23,-4.55,0.154
183.24,-4.49,0.154
183.25,-4.42,0.155
183.27,-4.35,0.155
183.28,-4.28,0.155
183.30,-4.22,0.155
183.31,-4.15,0.155
183.32,-4.08,0.155
183.33,-4.02,0.155
183.35,-3.95,0.155
183.36,-3.88,0.155
183.38,-3.82,0.155
183.39,-3.75,0.155
183.40,-3.68,0.155
183.42,-3.62,0.155
183.43,-3.55,0.155
183.44,-3.48,0.155
183.45,-3.42,0.155
183.47,-3.35,0.155
183.48,-3.28,0.155
183.50,-3.22,0.155
183.51,-3.15,0.155
183.52,-3.08,0.155
183.53,-3.02,0.155
183.55,-2.95,0.155
183.56,-2.88,0.155
183.58,-2.82,0.155
183.59,-2.75,0.155
183.60,-2.68,0.155
183.62,-2.62,0.155
183.63,-2.55,0.155
183.64,-2.48,0.155
183.65,-2.42,0.155
183.67,-2.35,0.155
183.68,-2.28,0.155
183.70,-2.22,0.154
183.71,-2.15,0.154
183.72,-2.08,0.154
183.73,-2.02,0.154
183.75,-1.95,0.154
183.76,-1.88,0.154
183.78,-1.82,0.154
183.79,-1.75,0.154
183.80,-1.68,0.154
183.82,-1.62,0.154
183.83,-1.55,0.154
183.84,-1.48,0.154
183.85,-1.42,0.154
183.87,-1.35,0.154
183.88,-1.28,0.154
183.90,-1.22,0.154
183.91,-1.15,0.154
183.92,-1.08,0.154
183.93,-1.01,0.154
183.95,-0.95,0.154
183.96,-0.88,0.154
183.98,-0.81,0.154
183.99,-0.75,0.154
184.00,-0.68,0.154
184.02,-0.61,0.154
184.03,-0.55,0.154
184.04,-0.48,0.154
184.05,-0.41,0.154
184.07,-0.35,0.154
184.08,-0.28,0.154
184.10,-0.21,0.154
184.11,-0.15,0.154
184.12,-0.08,0.154
184.13,-0.01,0.154
184.15,0.05,0.154
184.16,0.12,0.154
184.18,0.18,0.154
184.19,0.25,0.154
184.20,0.32,0.153
184.22,0.39,0.154
184.23,0.45,0.153
184.24,0.52,0.153
184.25,0.59,0.153
184.27,0.65,0.153
184.28,0.72,0.153
184.30,0.78,0.153
184.31,0.85,0.153
184.32,0.92,0.153
184.33,0.99,0.153
184.35,1.05,0.153
184.36,1.12,0.153
184.38,1.19,0.153
184.39,1.25,0.153
184.40,1.32,0.153
184.42,1.39,0.153
184.43,1.45,0.153
184.44,1.52,0.153
184.45,1.59,0.153
184.47,1.65,0.153
184.48,1.72,0.153
184.50,1.79,0.153
184.51,1.85,0.153
184.52,1.92,0.153
184.53,1.99,0.153
184.55,2.05,0.153
184.56,2.12,0.153
184.58,2.19,0.153
184.59,2.25,0.153
184.60,2.32,0.153
184.62,2.39,0.153
184.63,2.46,0.153
184.64,2.52,0.153
184.65,2.59,0.153
184.67,2.66,0.153
184.68,2.72,0.153
184.70,2.79,0.153
184.71,2.86,0.153
184.72,2.92,0.153
184.73,2.99,0.153
184.75,3.06,0.153
184.76,3.12,0.153
184.78,3.19,0.153
184.79,3.26,0.153
184.80,3.32,0.153
184.82,3.39,0.153
184.83,3.46,0.153
184.84,3.52,0.153
184.85,3.59,0.153
184.87,3.66,0.153
184.88,3.72,0.153
184.90,3.79,0.153
184.91,3.86,0.153
184.92,3.92,0.153
184.93,3.99,0.153
184.95,4.06,0.153
184.96,4.12,0.153
184.98,4.19,0.153
184.99,4.26,0.153
185.00,4.32,0.153
185.02,4.39,0.153
185.03,4.46,0.153
185.04,4.52,0.152
185.05,4.59,0.152
185.07,4.66,0.152
185.08,4.72,0.152
185.10,4.79,0.152
185.11,4.86,0.152
185.12,4.92,0.152
185.13,4.99,0.152
185.15,5.06,0.152
185.16,5.12,0.152
185.18,5.19,0.152
185.19,5.26,0.152
185.20,5.32,0.152
185.22,5.39,0.152
185.23,5.46,0.152
185.24,5.53,0.152
185.25,5.59,0.152
185.27,5.66,0.152
185.28,5.72,0.152
185.30,5.79,0.152
185.31,5.86,0.152
185.32,5.93,0.152
185.33,5.99,0.152
185.35,6.06,0.152
185.36,6.13,0.152
185.38,6.19,0.152
185.39,6.26,0.152
185.40,6.33,0.152
185.42,6.39,0.152
185.43,6.46,0.152
185.44,6.53,0.152
185.45,6.59,0.152
185.47,6.66,0.152
185.48,6.73,0.151
185.50,6.79,0.151
185.51,6.86,0.151
185.52,6.93,0.151
185.53,6.99,0.151
185.55,7.06,0.151
185.56,7.13,0.151
185.58,7.19,0.151
185.59,7.26,0.151
185.60,7.33,0.151
185.62,7.39,0.151
185.63,7.46,0.151
185.64,7.53,0.151
185.65,7.59,0.151
185.67,7.66,0.151
185.68,7.73,0.151
185.70,7.80,0.151
185.71,7.86,0.151
185.72,7.93,0.151
185.73,8.00,0.151
185.75,8.06,0.151
185.76,8.13,0.151
185.78,8.20,0.150
185.79,8.26,0.150
185.80,8.33,0.150
185.82,8.40,0.150
185.83,8.46,0.150
185.84,8.53,0.150
185.85,8.60,0.150
185.87,8.66,0.150
185.88,8.73,0.150
185.90,8.80,0.150
185.91,8.86,0.150
185.92,8.93,0.150
185.93,9.00,0.150
185.95,9.06,0.150
185.96,9.13,0.150
185.98,9.20,0.150
185.99,9.26,0.150
186.00,9.33,0.150
186.02,9.40,0.150
186.03,9.46,0.150
186.04,9.53,0.149
186.05,9.60,0.149
186.07,9.66,0.149
186.08,9.73,0.149
186.10,9.80,0.149
186.11,9.86,0.149
186.12,9.93,0.149
186.13,10.00,0.149
186.15,10.06,0.149
186.16,10.13,0.149
186.18,10.20,0.149
186.19,10.26,0.149
186.20,10.33,0.149
186.22,10.40,0.149
186.23,10.46,0.149
186.24,10.53,0.149
186.25,10.60,0.149
186.27,10.66,0.149
186.28,10.73,0.149
186.30,10.80,0.149
186.31,10.87,0.149
186.32,10.93,0.149
186.33,11.00,0.149
186.35,11.07,0.149
186.36,11.13,0.149
186.38,11.20,0.149
186.39,11.27,0.149
186.40,11.33,0.149
186.42,11.40,0.149
186.43,11.47,0.148
186.44,11.53,0.148
186.45,11.60,0.148
186.47,11.67,0.148
186.48,11.73,0.148
186.50,11.80,0.148
186.51,11.87,0.148
186.52,11.93,0.148
186.53,12.00,0.148
186.55,12.07,0.148
186.56,12.13,0.148
186.58,12.20,0.148
186.59,12.27,0.148
186.60,12.33,0.148
186.62,12.40,0.148
186.63,12.47,0.148
186.64,12.53,0.148
186.65,12.60,0.148
186.67,12.67,0.148
186.68,12.73,0.148
186.70,12.80,0.148
186.71,12.87,0.148
186.72,12.93,0.148
186.73,13.00,0.148
186.75,13.07,0.148
186.76,13.13,0.148
186.78,13.20,0.148
186.79,13.27,0.148
186.80,13.33,0.148
186.82,13.40,0.148
186.83,13.47,0.148
186.84,13.53,0.147
186.85,13.60,0.147
186.87,13.67,0.147
186.88,13.74,0.147
186.90,13.80,0.147
186.91,13.87,0.147
186.92,13.94,0.147
186.93,14.00,0.147
186.95,14.07,0.147
186.96,14.14,0.147
186.98,14.20,0.147
186.99,14.27,0.147
187.00,14.34,0.147
187.02,14.40,0.147
187.03,14.47,0.147
187.04,14.54,0.147
187.05,14.60,0.147
187.07,14.67,0.147
187.08,14.74,0.147
187.10,14.80,0.147
187.11,14.87,0.147
187.12,14.94,0.147
187.13,15.00,0.147
187.15,15.07,0.147
187.16,15.14,0.147
187.18,15.20,0.147
187.19,15.27,0.147
187.20,15.34,0.147
187.22,15.40,0.147
187.23,15.47,0.147
187.24,15.54,0.147
187.25,15.60,0.147
187.27,15.67,0.147
187.28,15.74,0.147
187.30,15.80,0.147
187.31,15.87,0.147
187.32,15.94,0.147
187.33,16.00,0.147
187.35,16.07,0.147
187.36,16.14,0.147
187.38,16.20,0.147
187.39,16.27,0.147
187.40,16.34,0.147
187.42,16.40,0.147
187.43,16.47,0.147
187.44,16.54,0.147
187.45,16.60,0.147
187.47,16.67,0.147
187.48,16.74,0.147
187.50,16.80,0.147
187.51,16.87,0.147
187.52,16.94,0.147
187.53,17.00,0.147
187.55,17.07,0.148
187.56,17.14,0.148
187.58,17.20,0.148
187.59,17.27,0.148
187.60,17.34,0.148
187.62,17.40,0.148
187.63,17.47,0.148
187.64,17.54,0.148
187.65,17.60,0.148
187.67,17.67,0.148
187.68,17.74,0.148
187.70,17.80,0.148
187.71,17.87,0.148
187.72,17.94,0.148
187.73,18.01,0.148
187.75,18.07,0.148
187.76,18.14,0.148
187.78,18.20,0.148
187.79,18.27,0.148
187.80,18.34,0.148
187.82,18.41,0.148
187.83,18.47,0.148
187.84,18.54,0.148
187.85,18.60,0.148
187.87,18.67,0.148
187.88,18.74,0.148
187.90,18.81,0.148
187.91,18.87,0.148
187.92,18.94,0.148
187.93,19.00,0.148
187.95,19.07,0.148
187.96,19.14,0.148
187.98,19.21,0.148
187.99,19.27,0.148
188.00,19.34,0.148
188.02,19.41,0.148
188.03,19.47,0.148
188.04,19.54,0.148
188.05,19.60,0.148
188.07,19.67,0.149
188.08,19.74,0.149
188.10,19.80,0.149
188.11,19.87,0.149
188.12,19.94,0.149
188.13,20.01,0.149
188.15,20.07,0.149
188.16,20.14,0.149
188.18,20.21,0.149
188.19,20.27,0.149
188.20,20.34,0.149
188.22,20.41,0.149
188.23,20.47,0.149
188.24,20.54,0.149
188.25,20.61,0.149
188.27,20.67,0.149
188.28,20.74,0.149
188.30,20.81,0.149
188.31,20.87,0.149
188.32,20.94,0.149
188.33,21.01,0.149
188.35,21.07,0.149
188.36,21.14,0.149
188.38,21.21,0.149
188.39,21.27,0.149
188.40,21.34,0.149
188.42,21.41,0.149
188.43,21.47,0.149
188.44,21.54,0.149
188.45,21.61,0.149
188.47,21.67,0.149
188.48,21.74,0.150
188.50,21.81,0.150
188.51,21.87,0.150
188.52,21.94,0.150
188.53,22.01,0.150
188.55,22.07,0.150
188.56,22.14,0.150
188.58,22.21,0.150
188.59,22.27,0.150
188.60,22.34,0.150
188.62,22.41,0.150
188.63,22.47,0.150
188.64,22.54,0.150
188.65,22.61,0.150
188.67,22.67,0.150
188.68,22.74,0.150
188.70,22.81,0.150
188.71,22.87,0.150
188.72,22.94,0.150
188.73,23.01,0.150
188.75,23.07,0.150
188.76,23.14,0.150
188.78,23.21,0.150
188.79,23.27,0.150
188.80,23.34,0.150
188.82,23.41,0.150
188.83,23.47,0.150
188.84,23.54,0.150
188.85,23.61,0.150
188.87,23.68,0.150
188.88,23.74,0.150
188.90,23.81,0.151
188.91,23.87,0.151
188.92,23.94,0.151
188.93,24.01,0.151
188.95,24.07,0.151
188.96,24.14,0.151
188.98,24.21,0.151
188.99,24.28,0.151
189.00,24.34,0.151
189.02,24.41,0.151
189.03,24.48,0.151
189.04,24.54,0.151
189.05,24.61,0.151
189.07,24.68,0.151
189.08,24.74,0.151
189.10,24.81,0.151
189.11,24.88,0.151
189.12,24.94,0.151
189.13,25.01,0.151
189.15,25.07,0.151
189.16,25.14,0.151
189.18,25.21,0.151
189.19,25.28,0.151
189.20,25.34,0.151
189.22,25.41,0.151
189.23,25.48,0.151
189.24,25.54,0.151
189.25,25.61,0.151
189.27,25.68,0.151
189.28,25.74,0.151
189.30,25.81,0.151
189.31,25.88,0.151
189.32,25.94,0.151
189.33,26.01,0.152
189.35,26.08,0.152
189.36,26.14,0.152
189.38,26.21,0.152
189.39,26.28,0.152
189.40,26.34,0.152
189.42,26.41,0.152
189.43,26.48,0.152
189.44,26.54,0.152
189.45,26.61,0.152
189.47,26.68,0.152
189.48,26.75,0.152
189.50,26.81,0.152
189.51,26.88,0.152
189.52,26.94,0.152
189.53,27.01,0.152
189.55,27.08,0.152
189.56,27.14,0.152
189.58,27.21,0.152
189.59,27.28,0.152
189.60,27.34,0.152
189.62,27.41,0.152
189.63,27.48,0.152
189.64,27.54,0.152
189.65,27.61,0.152
189.67,27.68,0.152
189.68,27.74,0.152
189.70,27.81,0.152
189.71,27.88,0.152
189.72,27.94,0.152
189.73,28.01,0.152
189.75,28.08,0.152
189.76,28.14,0.152
189.78,28.21,0.152
189.79,28.28,0.152
189.80,28.34,0.152
189.82,28.41,0.152
189.83,28.48,0.152
189.84,28.54,0.153
189.85,28.61,0.153
189.87,28.68,0.153
189.88,28.75,0.153
189.90,28.81,0.153
189.91,28.88,0.153
189.92,28.95,0.153
189.93,29.01,
189.95,29.08,
189.96,29.15,
189.98,29.21,
189.99,,