File: DSC/2025_06_03_Felodipine_0C_165C_10Cmin_x3.csv
Filename,2025_06_03_Felodipine_0C_165C_10Cmin_x3
Instrument name,DSC2A-00468 (192.168.1.100)
Operator,Yarger
rundate,6/3/2025
Sample name,2025_06_03_Felodipine_0C_165C_10Cmin_x3
proceduresegments,Data Off ; Equilibrate 0.00 °C; Data On ; Ramp 10.00 °C/min to 165.00 °C; Data Off ; Isothermal 1.0 min; Data On ; Ramp 10.00 °C/min to 0.00 °C; Data Off ; Isothermal 1.0 min; Data On ; Ramp 10.00 °C/min to 165.00 °C; Data Off ; Isothermal 1.0 min; Data On ; Ramp 10.00 °C/min to 0.00 °C; Data Off ; Isothermal 1.0 min; Data On ; Ramp 10.00 °C/min to 30.00 °C
[File Parameters]
Run date,6/3/2025 9:21:13 AM
Trios version,5.1.1.46572
Original File Name,
Current File Name,D:\DSC2500\JYarger\2025_06_03_Felodipine_0C_165C_10Cmin_x3.tri
[Procedure]
Procedure Name,FEL_0C_165C_10Cmin_x3
Sample Name,2025_06_03_Felodipine_0C_165C_10Cmin_x3
Sample Mass,14.49 mg
Reference Sample Mass,0 mg
Pan Mass,56.75 mg
Pan Number,20
Reference Pan Mass,56.96 mg
Reference Pan Number,10
Pan Type,Tzero Aluminum Hermetic
Comments,Al Hermetic DSC Consumables sealed Pan/Lid. A2 Tray (Google Sheet: DSC_Samples_A2_Tray_May2025)
Project Name,CA
Operator,Yarger
Test,Custom
Unload Max Temperature,30
Unload Min Temperature,30
Load Max Temperature,30
Load Min Temperature,30
Stop on Gas Flow Error,Yes
[Signal List]
Signal #1,Time (min)
Signal #2,Temperature (°C)
Signal #3,Heat Flow (mW)
Signal #4,Delta T (µV)
Signal #5,Delta Tzero (µV)
Signal #6,Tzero Temperature (°C)
Signal #7,Cell Purge (mL/min)
Signal #8,Heater Temp (°C)
Signal #9,Power Delivered (W)
Signal #10,Reference Junction Temperature (°C)
Signal #11,Flange Temperature (°C)
Signal #12,Heat Flow Phase (rad)
Signal #13,Total Heat Capacity (J/°C)
Signal #14,Heat Capacity (J/°C)
[Configuration]
Company Name,ASU
Instrument Name,DSC2A-00468
Instrument Type,DSC2500
Serial Number,DSC2A-00468
IP,192.168.1.100
Location of Instrument,MRRC
DisplayType,Unknown
Sample Interval ,0.1 s/pt
Selected Heat Flow,T4P
Exotherm Direction,Down
Cell Serial,DRC2-00792
Lid Type,Standard
Cooler,RCS 90
Leave Cooler on at End of Sequence,On
Gas 2,Nitrogen
Gas Selected,Channel 1
Flow Rate,50 mL/min
Secondary Purge,On
Licensed Heat Flow,Heat Flow T4P
Modulation Licensed,Yes
[Versions]
Common IDD Version,1
Cortex Version,VER 2.10.2.31
Driver,5.0.0.6
GDM Version,1.0.3.3
TouchscreenVersion,1.0.0.16145
FEP Version,1.2.1.21
FEP Bootloader,2.0.0.5
AutoSampler Version,2.1.1.26
Auto Sampler Bootloader,2.0.0.5
FCM Version,1.1.0.3
FCM Bootloader,2.0.0.5
[Experiment Logs]
Experiment Log Entry # 1,Data On set to 0
Experiment Log Entry # 3,Equilibrate Segment 0 (C) Started
Experiment Log Entry # 5,Air Cool is off.
Experiment Log Entry # 7,Data On set to 1
Experiment Log Entry # 9,Ramp Segment 10 C/min to 165 Started
Experiment Log Entry # 11,Data On set to 0
Experiment Log Entry # 13,Isothermal Segment 1 min started
Experiment Log Entry # 15,Data On set to 1
Experiment Log Entry # 17,Ramp Segment 10 C/min to 0 Started
Experiment Log Entry # 19,Data On set to 0
Experiment Log Entry # 21,Isothermal Segment 1 min started
Experiment Log Entry # 23,Data On set to 1
Experiment Log Entry # 25,Ramp Segment 10 C/min to 165 Started
Experiment Log Entry # 27,Data On set to 0
Experiment Log Entry # 29,Isothermal Segment 1 min started
Experiment Log Entry # 31,Data On set to 1
Experiment Log Entry # 33,Ramp Segment 10 C/min to 0 Started
Experiment Log Entry # 35,Data On set to 0
Experiment Log Entry # 37,Isothermal Segment 1 min started
Experiment Log Entry # 39,Data On set to 1
Experiment Log Entry # 41,Ramp Segment 10 C/min to 30 Started
[Method Log]
Method Log Entry # 1,Data Off
Method Log Entry # 2,Equilibrate 0 °C
Method Log Entry # 3,Data On
Method Log Entry # 4,(Ramp 826660) Ramp 10 °C/minute to 165 °C
Method Log Entry # 5,Data Off
Method Log Entry # 6,Isothermal 1 minutes
Method Log Entry # 7,Data On
Method Log Entry # 8,(Ramp 826664) Ramp 10 °C/minute to 0 °C
Method Log Entry # 9,Data Off
Method Log Entry # 10,Isothermal 1 minutes
Method Log Entry # 11,Data On
Method Log Entry # 12,(Ramp 826668) Ramp 10 °C/minute to 165 °C
Method Log Entry # 13,Data Off
Method Log Entry # 14,Isothermal 1 minutes
Method Log Entry # 15,Data On
Method Log Entry # 16,(Ramp 826672) Ramp 10 °C/minute to 0 °C
Method Log Entry # 17,Data Off
Method Log Entry # 18,Isothermal 1 minutes
Method Log Entry # 19,Data On
Method Log Entry # 20,(Ramp 826676) Ramp 10 °C/minute to 30 °C
Cell Serial,DRC2-00792
[T1 Calibration]
Slope,-0.008529666
Offset,9.636258
Initial Temperature,98.23
GUID,f8bfdadc-4977-4fdf-ba6d-0ba9134940c3
[TZero Calibration]
Date Applied,11/29/2022 4:06:13 PM
Description,From -89.059 °C to 396.009 °C at 20.000°C/min
Gas Type,Nitrogen
Pan Type,None
Source Files 1,C:\Users\yargerlab\Desktop\DSC Data\General\TZero_calibration_11_29_22_2nd(2).tri
Source Files 2,C:\Users\yargerlab\Desktop\DSC Data\General\TZero_calibration_11_29_22_2nd(3).tri
Delta T Offset,13.05235
Delta T Slope,-0.007271007
Delta T0 Offset,-13.69128
Delta T0 Slope,0.06063341
[Temperature Calibration]
Date Applied,11/29/2022 7:12:28 PM
Description,From 106.590 °C to 186.590 °C at 10.000°C/min
Gas Type,Nitrogen
Pan Type,Tzero Aluminum Hermetic
Source Files 1,C:\Users\yargerlab\Desktop\DSC Data\General\Indium(6).tri
Measured 1,157.391
Known 1,156.598
[Cell Constant Calibration]
Date Applied,11/29/2022 7:12:29 PM
Description,From 106.590 °C to 186.590 °C at 10.000°C/min
Gas Type,Nitrogen
Pan Type,Tzero Aluminum Hermetic
Source Files 1,C:\Users\yargerlab\Desktop\DSC Data\General\Indium(6).tri
T4P KCell,1.006051
Onset Slope,63.26126 mW/°C
[Direct Cp Calibration]
Date Applied,11/30/2022 11:04:51 AM
Description,From -79.983 °C to 298.409 °C at 10.000°C/min
Gas Type,Nitrogen
Pan Type,Tzero Aluminum Hermetic
Source Files 1,C:\Users\yargerlab\Desktop\DSC Data\General\Sapphire_Heat_Capacity_11_30_22.tri
[Rev Cp Calibration]
Date Applied,11/30/2022 1:58:51 PM
Description,From -79.996 °C to 292.812 °C at 3.000°C/min
Gas Type,Nitrogen
Pan Type,Tzero Aluminum Hermetic
Source Files 1,C:\Users\yargerlab\Desktop\DSC Data\General\Sapphire_MDSC_Calibration_11_30_22.tri
[step]
Ramp 10.00 °C/min to 165.00 °C
Time,Temperature,Heat Flow (Normalized)
min,°C,W/g
0.00,0.16,-0.042
0.01,0.16,-0.041
0.02,0.15,-0.039
0.03,0.15,-0.037
0.05,0.15,-0.034
0.06,0.16,-0.032
0.07,0.17,-0.032
0.08,0.18,-0.031
0.09,0.20,-0.031
0.11,0.24,-0.029
0.12,0.28,-0.026
0.13,0.33,-0.021
0.14,0.38,-0.014
0.15,0.44,-0.005
0.16,0.51,0.005
0.18,0.58,0.016
0.19,0.66,0.025
0.20,0.74,0.036
0.21,0.82,0.046
0.22,0.90,0.055
0.23,0.99,0.063
0.24,1.08,0.071
0.26,1.17,0.078
0.27,1.26,0.085
0.28,1.35,0.092
0.29,1.45,0.098
0.30,1.54,0.103
0.31,1.64,0.109
0.33,1.74,0.113
0.34,1.85,0.118
0.35,1.95,0.122
0.36,2.05,0.127
0.37,2.16,0.130
0.39,2.26,0.134
0.40,2.37,0.137
0.41,2.47,0.140
0.42,2.58,0.143
0.43,2.69,0.145
0.44,2.80,0.148
0.45,2.91,0.150
0.47,3.02,0.152
0.48,3.13,0.154
0.49,3.24,0.156
0.50,3.35,0.157
0.51,3.46,0.159
0.53,3.57,0.161
0.54,3.68,0.161
0.55,3.79,0.163
0.56,3.91,0.164
0.57,4.02,0.165
0.58,4.13,0.165
0.60,4.24,0.167
0.61,4.36,0.168
0.62,4.47,0.168
0.63,4.58,0.169
0.64,4.70,0.170
0.65,4.81,0.170
0.67,4.92,0.171
0.68,5.04,0.172
0.69,5.15,0.172
0.70,5.27,0.173
0.71,5.38,0.173
0.72,5.50,0.173
0.73,5.61,0.173
0.75,5.72,0.174
0.76,5.84,0.174
0.77,5.95,0.175
0.78,6.07,0.175
0.79,6.19,0.175
0.80,6.30,0.176
0.82,6.41,0.176
0.83,6.53,0.176
0.84,6.64,0.176
0.85,6.76,0.177
0.86,6.88,0.177
0.88,6.99,0.177
0.89,7.11,0.177
0.90,7.22,0.177
0.91,7.34,0.178
0.92,7.45,0.178
0.93,7.57,0.178
0.95,7.68,0.178
0.96,7.80,0.178
0.97,7.92,0.178
0.98,8.03,0.178
0.99,8.15,0.179
1.00,8.26,0.179
1.02,8.38,0.179
1.03,8.50,0.179
1.04,8.61,0.179
1.05,8.73,0.179
1.06,8.84,0.179
1.07,8.96,0.179
1.08,9.08,0.179
1.10,9.19,0.180
1.11,9.31,0.180
1.12,9.42,0.180
1.13,9.54,0.180
1.14,9.66,0.180
1.16,9.77,0.180
1.17,9.89,0.180
1.18,10.00,0.180
1.19,10.12,0.180
1.20,10.24,0.181
1.21,10.35,0.181
1.23,10.47,0.181
1.24,10.59,0.181
1.25,10.70,0.181
1.26,10.82,0.181
1.27,10.93,0.181
1.28,11.05,0.181
1.29,11.17,0.181
1.31,11.28,0.181
1.32,11.40,0.182
1.33,11.52,0.182
1.34,11.63,0.182
1.35,11.75,0.182
1.37,11.87,0.182
1.38,11.98,0.182
1.39,12.10,0.182
1.40,12.21,0.182
1.41,12.33,0.182
1.42,12.45,0.182
1.43,12.57,0.182
1.45,12.68,0.183
1.46,12.80,0.183
1.47,12.92,0.183
1.48,13.03,0.183
1.49,13.15,0.183
1.51,13.26,0.183
1.52,13.38,0.183
1.53,13.50,0.183
1.54,13.61,0.183
1.55,13.73,0.183
1.56,13.85,0.183
1.58,13.96,0.183
1.59,14.08,0.184
1.60,14.20,0.184
1.61,14.31,0.184
1.62,14.43,0.184
1.63,14.55,0.184
1.64,14.66,0.184
1.66,14.78,0.184
1.67,14.90,0.184
1.68,15.01,0.184
1.69,15.13,0.184
1.70,15.25,0.184
1.72,15.36,0.185
1.73,15.48,0.185
1.74,15.60,0.185
1.75,15.71,0.185
1.76,15.83,0.185
1.77,15.94,0.185
1.78,16.06,0.185
1.80,16.18,0.185
1.81,16.30,0.185
1.82,16.41,0.185
1.83,16.53,0.185
1.84,16.65,0.185
1.86,16.76,0.185
1.87,16.88,0.185
1.88,17.00,0.185
1.89,17.11,0.186
1.90,17.23,0.186
1.91,17.34,0.186
1.93,17.46,0.186
1.94,17.58,0.186
1.95,17.70,0.186
1.96,17.81,0.186
1.97,17.93,0.186
1.98,18.05,0.186
1.99,18.16,0.186
2.01,18.28,0.186
2.02,18.40,0.186
2.03,18.51,0.186
2.04,18.63,0.186
2.05,18.75,0.186
2.07,18.86,0.187
2.08,18.98,0.187
2.09,19.10,0.187
2.10,19.21,0.187
2.11,19.33,0.187
2.12,19.45,0.187
2.14,19.56,0.187
2.15,19.68,0.187
2.16,19.80,0.187
2.17,19.91,0.187
2.18,20.03,0.187
2.19,20.15,0.187
2.21,20.26,0.187
2.22,20.38,0.187
2.23,20.50,0.187
2.24,20.61,0.187
2.25,20.73,0.188
2.26,20.85,0.188
2.28,20.96,0.188
2.29,21.08,0.188
2.30,21.20,0.188
2.31,21.31,0.188
2.32,21.43,0.188
2.33,21.55,0.188
2.34,21.66,0.188
2.36,21.78,0.188
2.37,21.90,0.188
2.38,22.01,0.188
2.39,22.13,0.188
2.40,22.25,0.188
2.41,22.36,0.188
2.43,22.48,0.188
2.44,22.60,0.188
2.45,22.71,0.189
2.46,22.83,0.189
2.47,22.95,0.189
2.49,23.06,0.189
2.50,23.18,0.189
2.51,23.30,0.189
2.52,23.42,0.189
2.53,23.53,0.189
2.54,23.65,0.189
2.56,23.77,0.189
2.57,23.88,0.189
2.58,24.00,0.189
2.59,24.12,0.189
2.60,24.23,0.189
2.61,24.35,0.189
2.63,24.47,0.190
2.64,24.58,0.190
2.65,24.70,0.190
2.66,24.82,0.190
2.67,24.93,0.190
2.68,25.05,0.190
2.69,25.17,0.190
2.71,25.28,0.190
2.72,25.40,0.190
2.73,25.52,0.190
2.74,25.63,0.190
2.75,25.75,0.190
2.76,25.87,0.190
2.78,25.98,0.190
2.79,26.10,0.190
2.80,26.22,0.190
2.81,26.33,0.190
2.82,26.45,0.190
2.84,26.57,0.191
2.85,26.69,0.191
2.86,26.80,0.191
2.87,26.92,0.191
2.88,27.04,0.191
2.89,27.15,0.191
2.91,27.27,0.191
2.92,27.39,0.191
2.93,27.50,0.191
2.94,27.62,0.191
2.95,27.74,0.191
2.96,27.85,0.191
2.98,27.97,0.191
2.99,28.09,0.191
3.00,28.20,0.191
3.01,28.32,0.191
3.02,28.44,0.192
3.03,28.55,0.192
3.04,28.67,0.192
3.06,28.79,0.192
3.07,28.90,0.192
3.08,29.02,0.192
3.09,29.14,0.192
3.10,29.25,0.192
3.11,29.37,0.192
3.13,29.49,0.192
3.14,29.61,0.192
3.15,29.72,0.192
3.16,29.84,0.192
3.17,29.96,0.192
3.19,30.07,0.192
3.20,30.19,0.192
3.21,30.31,0.192
3.22,30.42,0.193
3.23,30.54,0.193
3.24,30.66,0.193
3.26,30.77,0.193
3.27,30.89,0.193
3.28,31.01,0.193
3.29,31.12,0.193
3.30,31.24,0.193
3.31,31.36,0.193
3.33,31.47,0.193
3.34,31.59,0.193
3.35,31.71,0.193
3.36,31.82,0.193
3.37,31.94,0.193
3.38,32.06,0.193
3.39,32.17,0.193
3.41,32.29,0.193
3.42,32.41,0.193
3.43,32.52,0.194
3.44,32.64,0.194
3.45,32.76,0.194
3.46,32.87,0.194
3.48,32.99,0.194
3.49,33.11,0.194
3.50,33.22,0.194
3.51,33.34,0.194
3.52,33.46,0.194
3.54,33.58,0.194
3.55,33.69,0.194
3.56,33.81,0.194
3.57,33.93,0.194
3.58,34.04,0.194
3.59,34.16,0.194
3.61,34.28,0.194
3.62,34.39,0.194
3.63,34.51,0.194
3.64,34.63,0.195
3.65,34.74,0.195
3.66,34.86,0.195
3.68,34.98,0.195
3.69,35.09,0.195
3.70,35.21,0.195
3.71,35.33,0.195
3.72,35.44,0.195
3.73,35.56,0.195
3.74,35.68,0.195
3.76,35.79,0.195
3.77,35.91,0.195
3.78,36.03,0.195
3.79,36.14,0.195
3.80,36.26,0.195
3.81,36.38,0.195
3.83,36.50,0.195
3.84,36.61,0.196
3.85,36.73,0.196
3.86,36.85,0.196
3.87,36.96,0.196
3.89,37.08,0.196
3.90,37.20,0.196
3.91,37.31,0.196
3.92,37.43,0.196
3.93,37.55,0.196
3.94,37.66,0.196
3.96,37.78,0.196
3.97,37.90,0.196
3.98,38.01,0.196
3.99,38.13,0.196
4.00,38.25,0.196
4.01,38.36,0.196
4.03,38.48,0.196
4.04,38.60,0.196
4.05,38.71,0.197
4.06,38.83,0.197
4.07,38.95,0.197
4.08,39.06,0.197
4.09,39.18,0.197
4.11,39.30,0.197
4.12,39.41,0.197
4.13,39.53,0.197
4.14,39.65,0.197
4.15,39.77,0.197
4.16,39.88,0.197
4.18,40.00,0.197
4.19,40.12,0.197
4.20,40.23,0.197
4.21,40.35,0.197
4.22,40.47,0.197
4.24,40.58,0.197
4.25,40.70,0.198
4.26,40.82,0.198
4.27,40.93,0.198
4.28,41.05,0.198
4.29,41.17,0.198
4.30,41.28,0.198
4.32,41.40,0.198
4.33,41.52,0.198
4.34,41.63,0.198
4.35,41.75,0.198
4.36,41.87,0.198
4.38,41.98,0.198
4.39,42.10,0.198
4.40,42.22,0.198
4.41,42.34,0.198
4.42,42.45,0.198
4.43,42.57,0.198
4.45,42.68,0.199
4.46,42.80,0.199
4.47,42.92,0.199
4.48,43.04,0.199
4.49,43.15,0.199
4.50,43.27,0.199
4.51,43.39,0.199
4.53,43.50,0.199
4.54,43.62,0.199
4.55,43.74,0.199
4.56,43.85,0.199
4.57,43.97,0.199
4.59,44.09,0.199
4.60,44.20,0.199
4.61,44.32,0.199
4.62,44.44,0.199
4.63,44.55,0.199
4.64,44.67,0.199
4.65,44.79,0.200
4.67,44.90,0.200
4.68,45.02,0.200
4.69,45.14,0.200
4.70,45.25,0.200
4.71,45.37,0.200
4.73,45.49,0.200
4.74,45.60,0.200
4.75,45.72,0.200
4.76,45.84,0.200
4.77,45.96,0.200
4.78,46.07,0.200
4.80,46.19,0.200
4.81,46.31,0.200
4.82,46.42,0.200
4.83,46.54,0.201
4.84,46.66,0.201
4.85,46.77,0.201
4.86,46.89,0.201
4.88,47.01,0.201
4.89,47.12,0.201
4.90,47.24,0.201
4.91,47.36,0.201
4.92,47.47,0.201
4.94,47.59,0.201
4.95,47.71,0.201
4.96,47.82,0.201
4.97,47.94,0.201
4.98,48.06,0.201
4.99,48.17,0.201
5.00,48.29,0.201
5.02,48.41,0.201
5.03,48.52,0.202
5.04,48.64,0.202
5.05,48.76,0.202
5.06,48.87,0.202
5.08,48.99,0.202
5.09,49.11,0.202
5.10,49.23,0.202
5.11,49.34,0.202
5.12,49.46,0.202
5.13,49.58,0.202
5.15,49.69,0.202
5.16,49.81,0.202
5.17,49.93,0.202
5.18,50.04,0.202
5.19,50.16,0.202
5.20,50.28,0.202
5.21,50.39,0.202
5.23,50.51,0.203
5.24,50.63,0.203
5.25,50.74,0.203
5.26,50.86,0.203
5.27,50.98,0.203
5.29,51.09,0.203
5.30,51.21,0.203
5.31,51.33,0.203
5.32,51.44,0.203
5.33,51.56,0.203
5.34,51.68,0.203
5.35,51.80,0.203
5.37,51.91,0.203
5.38,52.03,0.203
5.39,52.15,0.203
5.40,52.26,0.203
5.41,52.38,0.203
5.43,52.50,0.203
5.44,52.61,0.203
5.45,52.73,0.204
5.46,52.85,0.204
5.47,52.96,0.204
5.48,53.08,0.204
5.50,53.20,0.204
5.51,53.31,0.204
5.52,53.43,0.204
5.53,53.55,0.204
5.54,53.66,0.204
5.55,53.78,0.204
5.56,53.90,0.204
5.58,54.01,0.204
5.59,54.13,0.204
5.60,54.25,0.204
5.61,54.36,0.204
5.62,54.48,0.204
5.64,54.60,0.204
5.65,54.71,0.205
5.66,54.83,0.205
5.67,54.95,0.205
5.68,55.06,0.205
5.69,55.18,0.205
5.70,55.30,0.205
5.72,55.41,0.205
5.73,55.53,0.205
5.74,55.65,0.205
5.75,55.77,0.205
5.76,55.88,0.205
5.78,56.00,0.205
5.79,56.12,0.205
5.80,56.23,0.205
5.81,56.35,0.205
5.82,56.47,0.205
5.83,56.58,0.205
5.85,56.70,0.206
5.86,56.81,0.206
5.87,56.93,0.206
5.88,57.05,0.206
5.89,57.17,0.206
5.90,57.28,0.206
5.91,57.40,0.206
5.93,57.52,0.206
5.94,57.63,0.206
5.95,57.75,0.206
5.96,57.87,0.206
5.97,57.98,0.206
5.99,58.10,0.206
6.00,58.22,0.206
6.01,58.33,0.206
6.02,58.45,0.206
6.03,58.57,0.207
6.04,58.68,0.207
6.05,58.80,0.207
6.07,58.92,0.207
6.08,59.03,0.207
6.09,59.15,0.207
6.10,59.27,0.207
6.11,59.39,0.207
6.13,59.50,0.207
6.14,59.62,0.207
6.15,59.74,0.207
6.16,59.85,0.207
6.17,59.97,0.207
6.18,60.09,0.207
6.20,60.20,0.207
6.21,60.32,0.207
6.22,60.44,0.207
6.23,60.55,0.207
6.24,60.67,0.207
6.25,60.79,0.208
6.26,60.90,0.208
6.28,61.02,0.208
6.29,61.14,0.208
6.30,61.25,0.208
6.31,61.37,0.208
6.32,61.49,0.208
6.34,61.60,0.208
6.35,61.72,0.208
6.36,61.84,0.208
6.37,61.95,0.208
6.38,62.07,0.208
6.39,62.19,0.208
6.40,62.30,0.208
6.42,62.42,0.208
6.43,62.54,0.208
6.44,62.65,0.208
6.45,62.77,0.208
6.46,62.89,0.208
6.48,63.00,0.209
6.49,63.12,0.209
6.50,63.24,0.209
6.51,63.36,0.209
6.52,63.47,0.209
6.53,63.59,0.209
6.55,63.71,0.209
6.56,63.82,0.209
6.57,63.94,0.209
6.58,64.06,0.209
6.59,64.17,0.209
6.60,64.29,0.209
6.61,64.41,0.209
6.63,64.52,0.209
6.64,64.64,0.209
6.65,64.76,0.209
6.66,64.87,0.209
6.67,64.99,0.210
6.69,65.11,0.210
6.70,65.22,0.210
6.71,65.34,0.210
6.72,65.46,0.210
6.73,65.57,0.210
6.74,65.69,0.210
6.75,65.81,0.210
6.77,65.92,0.210
6.78,66.04,0.210
6.79,66.16,0.210
6.80,66.28,0.210
6.81,66.39,0.210
6.83,66.51,0.210
6.84,66.62,0.210
6.85,66.74,0.210
6.86,66.86,0.210
6.87,66.98,0.210
6.88,67.09,0.211
6.90,67.21,0.211
6.91,67.33,0.211
6.92,67.44,0.211
6.93,67.56,0.211
6.94,67.68,0.211
6.95,67.79,0.211
6.96,67.91,0.211
6.98,68.03,0.211
6.99,68.14,0.211
7.00,68.26,0.211
7.01,68.38,0.211
7.02,68.49,0.211
7.04,68.61,0.211
7.05,68.73,0.211
7.06,68.84,0.211
7.07,68.96,0.211
7.08,69.08,0.212
7.09,69.19,0.212
7.10,69.31,0.212
7.12,69.43,0.212
7.13,69.54,0.212
7.14,69.66,0.212
7.15,69.78,0.212
7.16,69.90,0.212
7.18,70.01,0.212
7.19,70.13,0.212
7.20,70.24,0.212
7.21,70.36,0.212
7.22,70.48,0.212
7.23,70.60,0.212
7.25,70.71,0.212
7.26,70.83,0.212
7.27,70.95,0.212
7.28,71.06,0.213
7.29,71.18,0.213
7.30,71.30,0.213
7.31,71.41,0.213
7.33,71.53,0.213
7.34,71.65,0.213
7.35,71.76,0.213
7.36,71.88,0.213
7.37,72.00,0.213
7.39,72.11,0.213
7.40,72.23,0.213
7.41,72.35,0.213
7.42,72.46,0.213
7.43,72.58,0.213
7.44,72.70,0.213
7.45,72.81,0.213
7.47,72.93,0.214
7.48,73.05,0.214
7.49,73.16,0.214
7.50,73.28,0.214
7.51,73.40,0.214
7.53,73.51,0.214
7.54,73.63,0.214
7.55,73.75,0.214
7.56,73.87,0.214
7.57,73.98,0.214
7.58,74.10,0.214
7.60,74.22,0.214
7.61,74.33,0.214
7.62,74.45,0.214
7.63,74.57,0.214
7.64,74.68,0.214
7.65,74.80,0.214
7.66,74.92,0.215
7.68,75.03,0.215
7.69,75.15,0.215
7.70,75.27,0.215
7.71,75.38,0.215
7.72,75.50,0.215
7.74,75.62,0.215
7.75,75.73,0.215
7.76,75.85,0.215
7.77,75.97,0.215
7.78,76.08,0.215
7.79,76.20,0.215
7.80,76.32,0.215
7.82,76.43,0.215
7.83,76.55,0.215
7.84,76.67,0.215
7.85,76.78,0.215
7.86,76.90,0.215
7.88,77.02,0.215
7.89,77.13,0.216
7.90,77.25,0.216
7.91,77.37,0.216
7.92,77.49,0.216
7.93,77.60,0.216
7.95,77.72,0.216
7.96,77.84,0.216
7.97,77.95,0.216
7.98,78.07,0.216
7.99,78.19,0.216
8.00,78.30,0.216
8.01,78.42,0.216
8.03,78.54,0.216
8.04,78.65,0.216
8.05,78.77,0.216
8.06,78.89,0.217
8.07,79.01,0.217
8.09,79.12,0.217
8.10,79.24,0.217
8.11,79.36,0.217
8.12,79.47,0.217
8.13,79.59,0.217
8.14,79.71,0.217
8.15,79.82,0.217
8.17,79.94,0.217
8.18,80.06,0.217
8.19,80.17,0.217
8.20,80.29,0.217
8.21,80.41,0.217
8.23,80.52,0.217
8.24,80.64,0.217
8.25,80.76,0.217
8.26,80.87,0.218
8.27,80.99,0.218
8.28,81.11,0.218
8.30,81.22,0.218
8.31,81.34,0.218
8.32,81.46,0.218
8.33,81.57,0.218
8.34,81.69,0.218
8.35,81.81,0.218
8.36,81.92,0.218
8.38,82.04,0.218
8.39,82.16,0.218
8.40,82.27,0.218
8.41,82.39,0.218
8.42,82.51,0.218
8.44,82.62,0.218
8.45,82.74,0.218
8.46,82.86,0.218
8.47,82.98,0.218
8.48,83.09,0.218
8.49,83.21,0.219
8.50,83.33,0.219
8.52,83.44,0.219
8.53,83.56,0.219
8.54,83.68,0.219
8.55,83.79,0.219
8.56,83.91,0.219
8.58,84.03,0.219
8.59,84.14,0.219
8.60,84.26,0.219
8.61,84.38,0.219
8.62,84.49,0.219
8.63,84.61,0.219
8.65,84.73,0.219
8.66,84.84,0.219
8.67,84.96,0.219
8.68,85.08,0.219
8.69,85.19,0.219
8.70,85.31,0.219
8.72,85.43,0.219
8.73,85.55,0.219
8.74,85.66,0.219
8.75,85.78,0.219
8.76,85.89,0.220
8.77,86.01,0.220
8.78,86.13,0.220
8.80,86.24,0.220
8.81,86.36,0.220
8.82,86.48,0.220
8.83,86.59,0.220
8.84,86.71,0.220
8.85,86.83,0.220
8.87,86.95,0.220
8.88,87.06,0.220
8.89,87.18,0.220
8.90,87.30,0.220
8.91,87.41,0.220
8.93,87.53,0.220
8.94,87.65,0.220
8.95,87.76,0.220
8.96,87.88,0.220
8.97,88.00,0.221
8.98,88.11,0.221
9.00,88.23,0.221
9.01,88.35,0.221
9.02,88.46,0.221
9.03,88.58,0.221
9.04,88.70,0.221
9.05,88.81,0.221
9.07,88.93,0.221
9.08,89.05,0.221
9.09,89.16,0.221
9.10,89.28,0.221
9.11,89.40,0.221
9.12,89.51,0.221
9.13,89.63,0.221
9.15,89.75,0.221
9.16,89.87,0.221
9.17,89.98,0.221
9.18,90.10,0.221
9.19,90.21,0.222
9.20,90.33,0.222
9.22,90.45,0.222
9.23,90.56,0.222
9.24,90.68,0.222
9.25,90.80,0.222
9.26,90.91,0.222
9.28,91.03,0.222
9.29,91.15,0.222
9.30,91.27,0.222
9.31,91.38,0.222
9.32,91.50,0.222
9.33,91.62,0.222
9.35,91.73,0.222
9.36,91.85,0.222
9.37,91.97,0.222
9.38,92.08,0.222
9.39,92.20,0.223
9.40,92.32,0.223
9.42,92.43,0.223
9.43,92.55,0.223
9.44,92.67,0.223
9.45,92.78,0.223
9.46,92.90,0.223
9.47,93.02,0.223
9.48,93.13,0.223
9.50,93.25,0.223
9.51,93.37,0.223
9.52,93.48,0.223
9.53,93.60,0.223
9.54,93.72,0.223
9.55,93.84,0.223
9.57,93.95,0.223
9.58,94.07,0.224
9.59,94.18,0.224
9.60,94.30,0.224
9.61,94.42,0.224
9.63,94.53,0.224
9.64,94.65,0.224
9.65,94.77,0.224
9.66,94.88,0.224
9.67,95.00,0.224
9.68,95.12,0.224
9.70,95.23,0.224
9.71,95.35,0.224
9.72,95.47,0.224
9.73,95.58,0.224
9.74,95.70,0.224
9.75,95.82,0.224
9.77,95.94,0.225
9.78,96.05,0.225
9.79,96.17,0.225
9.80,96.28,0.225
9.81,96.40,0.225
9.82,96.52,0.225
9.83,96.64,0.225
9.85,96.75,0.225
9.86,96.87,0.225
9.87,96.99,0.225
9.88,97.10,0.225
9.89,97.22,0.225
9.90,97.34,0.225
9.92,97.45,0.225
9.93,97.57,0.225
9.94,97.69,0.225
9.95,97.80,0.226
9.96,97.92,0.226
9.98,98.04,0.226
9.99,98.15,0.226
10.00,98.27,0.226
10.01,98.39,0.226
10.02,98.50,0.226
10.03,98.62,0.226
10.05,98.74,0.226
10.06,98.85,0.226
10.07,98.97,0.226
10.08,99.09,0.226
10.09,99.20,0.226
10.10,99.32,0.226
10.12,99.44,0.226
10.13,99.55,0.226
10.14,99.67,0.226
10.15,99.79,0.226
10.16,99.90,0.227
10.17,100.02,0.227
10.18,100.14,0.227
10.20,100.26,0.227
10.21,100.37,0.227
10.22,100.49,0.227
10.23,100.61,0.227
10.24,100.72,0.227
10.25,100.84,0.227
10.27,100.95,0.227
10.28,101.07,0.227
10.29,101.19,0.227
10.30,101.31,0.227
10.31,101.42,0.227
10.33,101.54,0.227
10.34,101.66,0.227
10.35,101.77,0.227
10.36,101.89,0.228
10.37,102.01,0.228
10.38,102.12,0.228
10.40,102.24,0.228
10.41,102.36,0.228
10.42,102.47,0.228
10.43,102.59,0.228
10.44,102.71,0.228
10.45,102.82,0.228
10.47,102.94,0.228
10.48,103.06,0.228
10.49,103.18,0.228
10.50,103.29,0.228
10.51,103.41,0.228
10.52,103.52,0.228
10.53,103.64,0.228
10.55,103.76,0.228
10.56,103.88,0.229
10.57,103.99,0.229
10.58,104.11,0.229
10.59,104.23,0.229
10.60,104.34,0.229
10.62,104.46,0.229
10.63,104.58,0.229
10.64,104.69,0.229
10.65,104.81,0.229
10.66,104.93,0.229
10.68,105.04,0.229
10.69,105.16,0.229
10.70,105.28,0.229
10.71,105.39,0.229
10.72,105.51,0.229
10.73,105.63,0.229
10.75,105.74,0.229
10.76,105.86,0.229
10.77,105.98,0.229
10.78,106.10,0.230
10.79,106.21,0.230
10.80,106.33,0.230
10.82,106.44,0.230
10.83,106.56,0.230
10.84,106.68,0.230
10.85,106.79,0.230
10.86,106.91,0.230
10.87,107.03,0.230
10.88,107.14,0.230
10.90,107.26,0.230
10.91,107.38,0.230
10.92,107.49,0.230
10.93,107.61,0.230
10.94,107.73,0.230
10.95,107.84,0.230
10.97,107.96,0.230
10.98,108.08,0.230
10.99,108.19,0.230
11.00,108.31,0.230
11.01,108.43,0.231
11.03,108.55,0.231
11.04,108.66,0.231
11.05,108.78,0.231
11.06,108.90,0.231
11.07,109.01,0.231
11.08,109.13,0.231
11.10,109.25,0.231
11.11,109.36,0.231
11.12,109.48,0.231
11.13,109.60,0.231
11.14,109.71,0.231
11.15,109.83,0.231
11.17,109.95,0.231
11.18,110.06,0.231
11.19,110.18,0.231
11.20,110.30,0.231
11.21,110.42,0.232
11.22,110.53,0.232
11.23,110.65,0.232
11.25,110.77,0.232
11.26,110.88,0.232
11.27,111.00,0.232
11.28,111.11,0.232
11.29,111.23,0.232
11.30,111.35,0.232
11.32,111.46,0.232
11.33,111.58,0.232
11.34,111.70,0.232
11.35,111.81,0.232
11.36,111.93,0.232
11.38,112.05,0.232
11.39,112.17,0.232
11.40,112.28,0.232
11.41,112.40,0.232
11.42,112.51,0.232
11.43,112.63,0.232
11.45,112.75,0.233
11.46,112.87,0.233
11.47,112.98,0.233
11.48,113.10,0.233
11.49,113.22,0.233
11.50,113.33,0.233
11.52,113.45,0.233
11.53,113.57,0.233
11.54,113.68,0.233
11.55,113.80,0.233
11.56,113.92,0.233
11.57,114.03,0.233
11.58,114.15,0.233
11.60,114.27,0.233
11.61,114.38,0.233
11.62,114.50,0.233
11.63,114.62,0.233
11.64,114.73,0.234
11.65,114.85,0.234
11.67,114.97,0.234
11.68,115.08,0.234
11.69,115.20,0.234
11.70,115.32,0.234
11.71,115.43,0.234
11.73,115.55,0.234
11.74,115.67,0.234
11.75,115.79,0.234
11.76,115.90,0.234
11.77,116.02,0.234
11.78,116.13,0.234
11.80,116.25,0.234
11.81,116.37,0.234
11.82,116.49,0.234
11.83,116.60,0.234
11.84,116.72,0.234
11.85,116.83,0.234
11.87,116.95,0.235
11.88,117.07,0.235
11.89,117.19,0.235
11.90,117.30,0.235
11.91,117.42,0.235
11.92,117.54,0.235
11.93,117.65,0.235
11.95,117.77,0.235
11.96,117.89,0.235
11.97,118.00,0.235
11.98,118.12,0.235
11.99,118.24,0.235
12.00,118.35,0.235
12.02,118.47,0.235
12.03,118.59,0.235
12.04,118.70,0.235
12.05,118.82,0.235
12.06,118.94,0.235
12.08,119.05,0.235
12.09,119.17,0.236
12.10,119.29,0.236
12.11,119.41,0.236
12.12,119.52,0.236
12.13,119.64,0.236
12.15,119.75,0.236
12.16,119.87,0.236
12.17,119.99,0.236
12.18,120.10,0.236
12.19,120.22,0.236
12.20,120.34,0.236
12.22,120.46,0.236
12.23,120.57,0.236
12.24,120.69,0.236
12.25,120.80,0.236
12.26,120.92,0.236
12.27,121.04,0.236
12.28,121.16,0.236
12.30,121.27,0.236
12.31,121.39,0.237
12.32,121.51,0.237
12.33,121.62,0.237
12.34,121.74,0.237
12.35,121.86,0.237
12.37,121.97,0.237
12.38,122.09,0.237
12.39,122.21,0.237
12.40,122.32,0.237
12.41,122.44,0.237
12.43,122.56,0.237
12.44,122.68,0.237
12.45,122.80,0.237
12.46,122.91,0.238
12.47,123.03,0.238
12.48,123.15,0.238
12.50,123.26,0.238
12.51,123.38,0.238
12.52,123.50,0.238
12.53,123.62,0.238
12.54,123.73,0.238
12.55,123.85,0.238
12.57,123.97,0.239
12.58,124.08,0.239
12.59,124.20,0.239
12.60,124.32,0.239
12.61,124.43,0.239
12.62,124.55,0.239
12.63,124.67,0.239
12.65,124.78,0.239
12.66,124.90,0.239
12.67,125.02,0.239
12.68,125.13,0.239
12.69,125.25,0.239
12.70,125.37,0.239
12.72,125.48,0.239
12.73,125.60,0.239
12.74,125.71,0.239
12.75,125.83,0.239
12.76,125.95,0.239
12.78,126.06,0.239
12.79,126.18,0.239
12.80,126.30,0.239
12.81,126.41,0.239
12.82,126.53,0.239
12.83,126.65,0.239
12.85,126.76,0.239
12.86,126.88,0.239
12.87,127.00,0.239
12.88,127.11,0.239
12.89,127.23,0.239
12.90,127.35,0.239
12.92,127.46,0.239
12.93,127.58,0.239
12.94,127.70,0.239
12.95,127.81,0.239
12.96,127.93,0.239
12.97,128.05,0.240
12.98,128.16,0.240
13.00,128.28,0.240
13.01,128.40,0.240
13.02,128.51,0.240
13.03,128.63,0.240
13.04,128.75,0.240
13.05,128.86,0.240
13.07,128.98,0.240
13.08,129.10,0.240
13.09,129.21,0.240
13.10,129.33,0.240
13.11,129.45,0.240
13.13,129.56,0.240
13.14,129.68,0.240
13.15,129.80,0.240
13.16,129.91,0.240
13.17,130.03,0.241
13.18,130.15,0.241
13.20,130.26,0.241
13.21,130.38,0.241
13.22,130.50,0.241
13.23,130.61,0.241
13.24,130.73,0.241
13.25,130.85,0.241
13.27,130.96,0.241
13.28,131.08,0.241
13.29,131.20,0.241
13.30,131.31,0.241
13.31,131.43,0.242
13.32,131.55,0.242
13.33,131.66,0.242
13.35,131.78,0.242
13.36,131.90,0.242
13.37,132.01,0.242
13.38,132.13,0.242
13.39,132.25,0.242
13.40,132.36,0.242
13.42,132.48,0.243
13.43,132.60,0.243
13.44,132.71,0.243
13.45,132.83,0.243
13.46,132.95,0.243
13.48,133.06,0.243
13.49,133.18,0.243
13.50,133.30,0.244
13.51,133.41,0.244
13.52,133.53,0.244
13.53,133.65,0.244
13.55,133.76,0.244
13.56,133.88,0.245
13.57,134.00,0.245
13.58,134.11,0.245
13.59,134.23,0.245
13.60,134.35,0.245
13.62,134.46,0.245
13.63,134.58,0.246
13.64,134.70,0.246
13.65,134.81,0.246
13.66,134.93,0.247
13.67,135.04,0.247
13.68,135.16,0.247
13.70,135.28,0.247
13.71,135.39,0.248
13.72,135.51,0.248
13.73,135.63,0.248
13.74,135.74,0.249
13.75,135.86,0.250
13.77,135.98,0.250
13.78,136.09,0.251
13.79,136.21,0.251
13.80,136.33,0.252
13.81,136.44,0.253
13.83,136.56,0.254
13.84,136.68,0.255
13.85,136.79,0.255
13.86,136.91,0.257
13.87,137.02,0.258
13.88,137.14,0.259
13.90,137.26,0.260
13.91,137.37,0.261
13.92,137.49,0.262
13.93,137.60,0.263
13.94,137.72,0.265
13.95,137.84,0.267
13.97,137.95,0.268
13.98,138.07,0.270
13.99,138.18,0.272
14.00,138.30,0.274
14.01,138.41,0.277
14.02,138.53,0.279
14.03,138.64,0.282
14.05,138.76,0.285
14.06,138.87,0.288
14.07,138.99,0.292
14.08,139.10,0.296
14.09,139.22,0.301
14.10,139.33,0.305
14.12,139.44,0.311
14.13,139.56,0.317
14.14,139.67,0.324
14.15,139.78,0.331
14.16,139.89,0.340
14.18,140.01,0.348
14.19,140.12,0.359
14.20,140.23,0.370
14.21,140.33,0.382
14.22,140.44,0.396
14.23,140.55,0.413
14.25,140.66,0.429
14.26,140.76,0.447
14.27,140.87,0.467
14.28,140.97,0.489
14.29,141.07,0.515
14.30,141.17,0.541
14.32,141.27,0.567
14.33,141.37,0.597
14.34,141.46,0.631
14.35,141.56,0.666
14.36,141.65,0.702
14.37,141.74,0.742
14.38,141.83,0.783
14.40,141.91,0.826
14.41,142.00,0.869
14.42,142.08,0.913
14.43,142.16,0.958
14.44,142.24,1.002
14.45,142.33,1.045
14.47,142.41,1.088
14.48,142.49,1.130
14.49,142.57,1.173
14.50,142.65,1.216
14.51,142.73,1.261
14.53,142.80,1.307
14.54,142.88,1.354
14.55,142.96,1.403
14.56,143.04,1.453
14.57,143.11,1.504
14.58,143.19,1.557
14.60,143.26,1.608
14.61,143.33,1.659
14.62,143.41,1.712
14.63,143.48,1.762
14.64,143.55,1.810
14.65,143.63,1.858
14.67,143.70,1.904
14.68,143.78,1.949
14.69,143.85,1.991
14.70,143.93,2.036
14.71,144.00,2.081
14.72,144.08,2.126
14.73,144.16,2.169
14.75,144.23,2.205
14.76,144.32,2.234
14.77,144.40,2.265
14.78,144.48,2.291
14.79,144.57,2.318
14.80,144.65,2.342
14.82,144.75,2.365
14.83,144.84,2.387
14.84,144.93,2.403
14.85,145.02,2.412
14.86,145.13,2.414
14.88,145.23,2.412
14.89,145.33,2.409
14.90,145.44,2.404
14.91,145.55,2.400
14.92,145.67,2.403
14.93,145.78,2.405
14.95,145.89,2.401
14.96,146.01,2.373
14.97,146.14,2.321
14.98,146.27,2.254
14.99,146.41,2.182
15.00,146.57,2.108
15.02,146.72,2.032
15.03,146.88,1.954
15.04,147.05,1.872
15.05,147.23,1.790
15.06,147.40,1.707
15.07,147.58,1.625
15.08,147.76,1.546
15.10,147.94,1.469
15.11,148.12,1.393
15.12,148.30,1.319
15.13,148.48,1.247
15.14,148.66,1.176
15.15,148.85,1.106
15.17,149.03,1.037
15.18,149.21,0.969
15.19,149.38,0.904
15.20,149.56,0.841
15.21,149.74,0.782
15.23,149.91,0.728
15.24,150.08,0.682
15.25,150.25,0.640
15.26,150.41,0.604
15.27,150.57,0.572
15.28,150.73,0.544
15.30,150.89,0.520
15.31,151.04,0.498
15.32,151.18,0.478
15.33,151.33,0.460
15.34,151.47,0.444
15.35,151.61,0.430
15.37,151.75,0.417
15.38,151.88,0.404
15.39,152.01,0.395
15.40,152.15,0.385
15.41,152.28,0.374
15.42,152.41,0.366
15.43,152.53,0.361
15.45,152.66,0.355
15.46,152.79,0.349
15.47,152.91,0.343
15.48,153.04,0.337
15.49,153.16,0.333
15.50,153.28,0.329
15.52,153.41,0.326
15.53,153.53,0.323
15.54,153.65,0.320
15.55,153.77,0.317
15.56,153.89,0.315
15.58,154.01,0.312
15.59,154.13,0.311
15.60,154.25,0.309
15.61,154.37,0.307
15.62,154.49,0.305
15.63,154.61,0.304
15.65,154.73,0.303
15.66,154.85,0.302
15.67,154.96,0.301
15.68,155.08,0.300
15.69,155.20,0.299
15.70,155.32,0.298
15.72,155.44,0.298
15.73,155.55,0.297
15.74,155.67,0.297
15.75,155.79,0.296
15.76,155.91,0.296
15.77,156.02,0.295
15.78,156.14,0.295
15.80,156.26,0.295
15.81,156.38,0.294
15.82,156.49,0.294
15.83,156.61,0.294
15.84,156.73,0.294
15.85,156.85,0.294
15.87,156.96,0.294
15.88,157.08,0.294
15.89,157.20,0.293
15.90,157.31,0.293
15.91,157.43,0.293
15.93,157.55,0.293
15.94,157.66,0.293
15.95,157.78,0.293
15.96,157.90,0.293
15.97,158.02,0.293
15.98,158.13,0.293
16.00,158.25,0.293
16.01,158.37,0.293
16.02,158.48,0.293
16.03,158.60,0.292
16.04,158.72,0.292
16.05,158.83,0.292
16.07,158.95,0.292
16.08,159.07,0.292
16.09,159.18,0.292
16.10,159.30,0.292
16.11,159.42,0.292
16.12,159.54,0.292
16.13,159.65,0.292
16.15,159.77,0.292
16.16,159.89,0.292
16.17,160.00,0.292
16.18,160.12,0.292
16.19,160.24,0.292
16.20,160.35,0.291
16.22,160.47,0.291
16.23,160.59,0.291
16.24,160.70,0.291
16.25,160.82,0.291
16.26,160.94,0.291
16.28,161.05,0.291
16.29,161.17,0.291
16.30,161.29,0.291
16.31,161.40,0.291
16.32,161.52,0.291
16.33,161.64,0.291
16.35,161.75,0.291
16.36,161.87,0.291
16.37,161.99,0.291
16.38,162.10,0.291
16.39,162.22,0.291
16.40,162.34,0.291
16.42,162.45,0.291
16.43,162.57,0.291
16.44,162.69,0.291
16.45,162.80,
16.46,162.92,
16.47,163.04,
16.48,163.15,
16.50,163.27,
16.50,,

[step]
Ramp 10.00 °C/min to 0.00 °C
Time,Temperature,Heat Flow (Normalized)
min,°C,W/g
17.51,165.10,-0.021
17.52,165.10,-0.021
17.53,165.10,-0.022
17.54,165.10,-0.022
17.55,165.09,-0.022
17.57,165.09,-0.022
17.58,165.07,-0.022
17.59,165.05,-0.022
17.60,165.02,-0.030
17.61,164.98,-0.038
17.62,164.93,-0.050
17.63,164.88,-0.065
17.65,164.82,-0.083
17.66,164.75,-0.102
17.67,164.68,-0.121
17.68,164.61,-0.140
17.69,164.53,-0.158
17.71,164.44,-0.174
17.72,164.36,-0.188
17.73,164.27,-0.202
17.74,164.18,-0.214
17.75,164.09,-0.225
17.76,163.99,-0.235
17.78,163.89,-0.243
17.79,163.80,-0.252
17.80,163.70,-0.259
17.81,163.60,-0.265
17.82,163.49,-0.271
17.83,163.39,-0.277
17.84,163.28,-0.282
17.86,163.18,-0.287
17.87,163.07,-0.292
17.88,162.97,-0.295
17.89,162.86,-0.299
17.90,162.75,-0.302
17.92,162.64,-0.305
17.93,162.53,-0.308
17.94,162.42,-0.310
17.95,162.31,-0.312
17.96,162.20,-0.314
17.97,162.09,-0.316
17.98,161.97,-0.318
18.00,161.86,-0.319
18.01,161.75,-0.320
18.02,161.64,-0.322
18.03,161.52,-0.323
18.04,161.41,-0.324
18.06,161.30,-0.324
18.07,161.18,-0.326
18.08,161.07,-0.326
18.09,160.96,-0.327
18.10,160.84,-0.328
18.11,160.73,-0.328
18.13,160.61,-0.328
18.14,160.50,-0.329
18.15,160.38,-0.329
18.16,160.27,-0.330
18.17,160.16,-0.330
18.18,160.04,-0.330
18.19,159.93,-0.330
18.21,159.81,-0.331
18.22,159.69,-0.331
18.23,159.58,-0.331
18.24,159.47,-0.331
18.25,159.35,-0.331
18.27,159.24,-0.331
18.28,159.12,-0.331
18.29,159.00,-0.331
18.30,158.89,-0.332
18.31,158.77,-0.332
18.32,158.66,-0.332
18.33,158.54,-0.332
18.35,158.42,-0.332
18.36,158.31,-0.332
18.37,158.19,-0.332
18.38,158.08,-0.332
18.39,157.96,-0.332
18.41,157.85,-0.332
18.42,157.73,-0.332
18.43,157.62,-0.332
18.44,157.50,-0.332
18.45,157.38,-0.332
18.46,157.27,-0.332
18.48,157.15,-0.332
18.49,157.04,-0.332
18.50,156.92,-0.332
18.51,156.80,-0.332
18.52,156.69,-0.333
18.53,156.57,-0.333
18.54,156.46,-0.333
18.56,156.34,-0.333
18.57,156.22,-0.333
18.58,156.11,-0.333
18.59,155.99,-0.333
18.60,155.88,-0.333
18.62,155.76,-0.333
18.63,155.64,-0.333
18.64,155.53,-0.333
18.65,155.41,-0.333
18.66,155.29,-0.333
18.67,155.18,-0.333
18.68,155.06,-0.333
18.70,154.95,-0.333
18.71,154.83,-0.333
18.72,154.71,-0.333
18.73,154.60,-0.333
18.74,154.48,-0.333
18.76,154.37,-0.333
18.77,154.25,-0.332
18.78,154.13,-0.332
18.79,154.02,-0.332
18.80,153.90,-0.332
18.81,153.78,-0.332
18.83,153.67,-0.332
18.84,153.55,-0.332
18.85,153.44,-0.332
18.86,153.32,-0.332
18.87,153.20,-0.332
18.88,153.09,-0.332
18.89,152.97,-0.332
18.91,152.85,-0.332
18.92,152.74,-0.332
18.93,152.62,-0.332
18.94,152.50,-0.332
18.95,152.39,-0.332
18.97,152.27,-0.332
18.98,152.16,-0.332
18.99,152.04,-0.332
19.00,151.92,-0.332
19.01,151.81,-0.332
19.02,151.69,-0.332
19.03,151.57,-0.331
19.05,151.46,-0.331
19.06,151.34,-0.331
19.07,151.22,-0.331
19.08,151.11,-0.331
19.09,150.99,-0.331
19.11,150.87,-0.331
19.12,150.76,-0.331
19.13,150.64,-0.331
19.14,150.52,-0.331
19.15,150.41,-0.331
19.16,150.29,-0.331
19.18,150.18,-0.331
19.19,150.06,-0.331
19.20,149.94,-0.331
19.21,149.83,-0.331
19.22,149.71,-0.331
19.23,149.59,-0.331
19.24,149.48,-0.330
19.26,149.36,-0.330
19.27,149.24,-0.330
19.28,149.13,-0.330
19.29,149.01,-0.330
19.30,148.89,-0.330
19.32,148.78,-0.330
19.33,148.66,-0.330
19.34,148.54,-0.330
19.35,148.43,-0.330
19.36,148.31,-0.330
19.37,148.19,-0.330
19.38,148.08,-0.330
19.40,147.96,-0.330
19.41,147.85,-0.329
19.42,147.73,-0.329
19.43,147.61,-0.329
19.44,147.50,-0.329
19.46,147.38,-0.329
19.47,147.26,-0.329
19.48,147.15,-0.329
19.49,147.03,-0.329
19.50,146.91,-0.329
19.51,146.80,-0.329
19.53,146.68,-0.329
19.54,146.56,-0.329
19.55,146.45,-0.328
19.56,146.33,-0.328
19.57,146.21,-0.328
19.58,146.10,-0.328
19.59,145.98,-0.328
19.61,145.87,-0.328
19.62,145.75,-0.328
19.63,145.63,-0.328
19.64,145.52,-0.328
19.65,145.40,-0.328
19.67,145.28,-0.328
19.68,145.17,-0.328
19.69,145.05,-0.328
19.70,144.94,-0.328
19.71,144.82,-0.328
19.72,144.70,-0.327
19.73,144.59,-0.327
19.75,144.47,-0.327
19.76,144.35,-0.327
19.77,144.23,-0.327
19.78,144.12,-0.327
19.79,144.00,-0.327
19.81,143.88,-0.327
19.82,143.77,-0.327
19.83,143.65,-0.327
19.84,143.53,-0.327
19.85,143.42,-0.327
19.86,143.30,-0.327
19.88,143.18,-0.327
19.89,143.07,-0.327
19.90,142.95,-0.327
19.91,142.83,-0.327
19.92,142.72,-0.327
19.93,142.60,-0.327
19.94,142.48,-0.327
19.96,142.37,-0.327
19.97,142.25,-0.326
19.98,142.13,-0.326
19.99,142.02,-0.326
20.00,141.90,-0.326
20.02,141.78,-0.326
20.03,141.67,-0.326
20.04,141.55,-0.326
20.05,141.44,-0.326
20.06,141.32,-0.326
20.07,141.20,-0.325
20.08,141.08,-0.325
20.10,140.97,-0.325
20.11,140.85,-0.325
20.12,140.74,-0.325
20.13,140.62,-0.325
20.14,140.50,-0.325
20.16,140.39,-0.325
20.17,140.27,-0.325
20.18,140.15,-0.325
20.19,140.04,-0.325
20.20,139.92,-0.325
20.21,139.80,-0.325
20.23,139.69,-0.325
20.24,139.57,-0.324
20.25,139.45,-0.324
20.26,139.34,-0.324
20.27,139.22,-0.324
20.28,139.11,-0.324
20.29,138.99,-0.324
20.31,138.87,-0.324
20.32,138.76,-0.324
20.33,138.64,-0.324
20.34,138.52,-0.324
20.35,138.41,-0.324
20.37,138.29,-0.324
20.38,138.17,-0.324
20.39,138.06,-0.324
20.40,137.94,-0.324
20.41,137.82,-0.324
20.42,137.71,-0.323
20.43,137.59,-0.323
20.45,137.48,-0.323
20.46,137.36,-0.323
20.47,137.24,-0.323
20.48,137.13,-0.323
20.49,137.01,-0.323
20.51,136.89,-0.323
20.52,136.78,-0.323
20.53,136.66,-0.323
20.54,136.54,-0.323
20.55,136.43,-0.323
20.56,136.31,-0.323
20.58,136.19,-0.323
20.59,136.08,-0.323
20.60,135.96,-0.323
20.61,135.84,-0.323
20.62,135.73,-0.323
20.63,135.61,-0.323
20.64,135.49,-0.323
20.66,135.38,-0.322
20.67,135.26,-0.322
20.68,135.15,-0.322
20.69,135.03,-0.322
20.70,134.91,-0.322
20.72,134.80,-0.322
20.73,134.68,-0.322
20.74,134.56,-0.322
20.75,134.45,-0.322
20.76,134.33,-0.322
20.77,134.21,-0.322
20.78,134.10,-0.322
20.80,133.98,-0.322
20.81,133.86,-0.322
20.82,133.75,-0.322
20.83,133.63,-0.322
20.84,133.51,-0.322
20.86,133.40,-0.322
20.87,133.28,-0.321
20.88,133.16,-0.321
20.89,133.05,-0.321
20.90,132.93,-0.321
20.91,132.82,-0.321
20.93,132.70,-0.321
20.94,132.58,-0.321
20.95,132.46,-0.321
20.96,132.35,-0.321
20.97,132.23,-0.321
20.98,132.12,-0.321
20.99,132.00,-0.321
21.01,131.88,-0.321
21.02,131.77,-0.321
21.03,131.65,-0.321
21.04,131.53,-0.321
21.05,131.42,-0.321
21.07,131.30,-0.321
21.08,131.18,-0.321
21.09,131.07,-0.321
21.10,130.95,-0.321
21.11,130.83,-0.321
21.12,130.72,-0.320
21.13,130.60,-0.320
21.15,130.48,-0.320
21.16,130.37,-0.320
21.17,130.25,-0.320
21.18,130.13,-0.320
21.19,130.02,-0.320
21.21,129.90,-0.320
21.22,129.78,-0.320
21.23,129.67,-0.320
21.24,129.55,-0.320
21.25,129.43,-0.320
21.26,129.32,-0.320
21.28,129.20,-0.320
21.29,129.09,-0.320
21.30,128.97,-0.320
21.31,128.85,-0.320
21.32,128.74,-0.320
21.33,128.62,-0.320
21.34,128.50,-0.320
21.36,128.39,-0.320
21.37,128.27,-0.319
21.38,128.15,-0.319
21.39,128.04,-0.319
21.40,127.92,-0.319
21.42,127.80,-0.319
21.43,127.69,-0.319
21.44,127.57,-0.319
21.45,127.45,-0.319
21.46,127.34,-0.319
21.47,127.22,-0.319
21.48,127.10,-0.319
21.50,126.99,-0.319
21.51,126.87,-0.319
21.52,126.76,-0.319
21.53,126.64,-0.319
21.54,126.52,-0.319
21.56,126.41,-0.319
21.57,126.29,-0.319
21.58,126.17,-0.319
21.59,126.06,-0.319
21.60,125.94,-0.319
21.61,125.82,-0.318
21.63,125.71,-0.318
21.64,125.59,-0.318
21.65,125.47,-0.318
21.66,125.36,-0.318
21.67,125.24,-0.318
21.68,125.12,-0.318
21.69,125.01,-0.318
21.71,124.89,-0.318
21.72,124.78,-0.318
21.73,124.66,-0.318
21.74,124.54,-0.318
21.75,124.42,-0.318
21.77,124.31,-0.318
21.78,124.19,-0.318
21.79,124.08,-0.318
21.80,123.96,-0.318
21.81,123.84,-0.318
21.82,123.73,-0.318
21.83,123.61,-0.317
21.85,123.49,-0.317
21.86,123.38,-0.317
21.87,123.26,-0.317
21.88,123.14,-0.317
21.89,123.03,-0.317
21.91,122.91,-0.317
21.92,122.79,-0.317
21.93,122.68,-0.317
21.94,122.56,-0.317
21.95,122.44,-0.317
21.96,122.33,-0.317
21.98,122.21,-0.317
21.99,122.09,-0.317
22.00,121.98,-0.317
22.01,121.86,-0.317
22.02,121.74,-0.317
22.03,121.63,-0.317
22.04,121.51,-0.317
22.06,121.39,-0.317
22.07,121.28,-0.317
22.08,121.16,-0.317
22.09,121.05,-0.316
22.10,120.93,-0.316
22.12,120.81,-0.316
22.13,120.70,-0.316
22.14,120.58,-0.316
22.15,120.46,-0.316
22.16,120.35,-0.316
22.17,120.23,-0.316
22.18,120.11,-0.316
22.20,120.00,-0.316
22.21,119.88,-0.316
22.22,119.76,-0.316
22.23,119.65,-0.316
22.24,119.53,-0.316
22.26,119.41,-0.316
22.27,119.30,-0.316
22.28,119.18,-0.316
22.29,119.06,-0.316
22.30,118.95,-0.315
22.31,118.83,-0.315
22.33,118.71,-0.315
22.34,118.60,-0.315
22.35,118.48,-0.315
22.36,118.36,-0.315
22.37,118.25,-0.315
22.38,118.13,-0.315
22.39,118.02,-0.315
22.41,117.90,-0.315
22.42,117.78,-0.315
22.43,117.67,-0.315
22.44,117.55,-0.315
22.45,117.43,-0.315
22.47,117.32,-0.315
22.48,117.20,-0.315
22.49,117.08,-0.315
22.50,116.97,-0.315
22.51,116.85,-0.315
22.52,116.73,-0.315
22.53,116.62,-0.315
22.55,116.50,-0.315
22.56,116.38,-0.315
[...]
70.15,0.41,0.028,0.321
70.15,0.42,0.031,0.344
70.16,0.44,0.034,0.369
70.16,0.46,0.037,0.390
70.16,0.48,0.040,0.408
70.17,0.50,0.043,0.429
70.17,0.52,0.046,0.448
70.18,0.54,0.049,0.469
70.18,0.56,0.052,0.490
70.18,0.58,0.055,0.507
70.19,0.60,0.058,0.522
70.19,0.63,0.061,0.538
70.19,0.65,0.063,0.550
70.20,0.67,0.066,0.563
70.20,0.69,0.069,0.577
70.20,0.72,0.071,0.588
70.20,0.74,0.073,0.598
70.21,0.76,0.076,0.610
70.21,0.79,0.078,0.621
70.21,0.81,0.081,0.634
70.22,0.83,0.083,0.644
70.22,0.86,0.086,0.653
70.23,0.88,0.087,0.659
70.23,0.91,0.089,0.666
70.23,0.93,0.091,0.673
70.24,0.96,0.093,0.681
70.24,0.98,0.095,0.690
70.24,1.01,0.098,0.699
70.25,1.04,0.099,0.705
70.25,1.06,0.101,0.713
70.25,1.09,0.103,0.718
70.25,1.11,0.104,0.722
70.26,1.14,0.106,0.728
70.26,1.17,0.108,0.735
70.26,1.19,0.109,0.741
70.27,1.22,0.111,0.748
70.27,1.25,0.113,0.755
70.28,1.28,0.115,0.761
70.28,1.31,0.116,0.766
70.28,1.33,0.117,0.771
70.29,1.36,0.119,0.776
70.29,1.39,0.120,0.782
70.29,1.42,0.122,0.785
70.30,1.44,0.123,0.789
70.30,1.47,0.124,0.796
70.30,1.50,0.126,0.801
70.30,1.53,0.127,0.806
70.31,1.56,0.129,0.811
70.31,1.59,0.130,0.814
70.31,1.62,0.131,0.817
70.32,1.65,0.132,0.821
70.32,1.67,0.133,0.822
70.33,1.70,0.134,0.826
70.33,1.73,0.135,0.831
70.33,1.76,0.136,0.835
70.34,1.79,0.137,0.839
70.34,1.82,0.138,0.842
70.34,1.85,0.139,0.845
70.35,1.88,0.140,0.848
70.35,1.91,0.141,0.850
70.35,1.94,0.142,0.855
70.35,1.97,0.143,0.857
70.36,2.00,0.143,0.858
70.36,2.03,0.144,0.861
70.36,2.06,0.145,0.861
70.37,2.09,0.146,0.864
70.37,2.12,0.147,0.870
70.38,2.15,0.148,0.873
70.38,2.18,0.148,0.874
70.38,2.22,0.149,0.876
70.39,2.25,0.149,0.876
70.39,2.28,0.150,0.877
70.39,2.31,0.151,0.881
70.40,2.34,0.152,0.885
70.40,2.37,0.152,0.886
70.40,2.40,0.153,0.887
70.40,2.43,0.153,0.889
70.41,2.46,0.153,0.888
70.41,2.49,0.154,0.891
70.41,2.52,0.154,0.891
70.42,2.55,0.155,0.894
70.42,2.59,0.156,0.897
70.43,2.62,0.157,0.899
70.43,2.65,0.157,0.901
70.43,2.68,0.158,0.903
70.44,2.71,0.158,0.905
70.44,2.74,0.159,0.908
70.44,2.77,0.159,0.907
70.45,2.80,0.159,0.906
70.45,2.84,0.159,0.906
70.45,2.87,0.160,0.909
70.45,2.90,0.161,0.913
70.46,2.93,0.161,0.914
70.46,2.96,0.162,0.915
70.46,2.99,0.162,0.914
70.47,3.03,0.162,0.915
70.47,3.06,0.162,0.916
70.48,3.09,0.163,0.918
70.48,3.12,0.163,0.920
70.48,3.15,0.164,0.922
70.49,3.18,0.164,0.922
70.49,3.22,0.164,0.923
70.49,3.25,0.164,0.922
70.50,3.28,0.164,0.922
70.50,3.31,0.165,0.924
70.50,3.34,0.165,0.926
70.50,3.38,0.166,0.926
70.51,3.41,0.166,0.926
70.51,3.44,0.166,0.928
70.51,3.47,0.166,0.929
70.52,3.51,0.167,0.930
70.52,3.54,0.167,0.931
70.53,3.57,0.167,0.932
70.53,3.60,0.168,0.933
70.53,3.63,0.168,0.933
70.54,3.67,0.168,0.933
70.54,3.70,0.168,0.933
70.54,3.73,0.168,0.935
70.55,3.76,0.169,0.936
70.55,3.79,0.169,0.937
70.55,3.83,0.169,0.937
70.55,3.86,0.169,0.937
70.56,3.89,0.169,0.937
70.56,3.92,0.169,0.937
70.56,3.96,0.170,0.938
70.57,3.99,0.170,0.938
70.57,4.02,0.170,0.938
70.58,4.05,0.170,0.939
70.58,4.09,0.170,0.940
70.58,4.12,0.171,0.941
70.59,4.15,0.171,0.942
70.59,4.18,0.171,0.944
70.59,4.22,0.172,0.944
70.60,4.25,0.172,0.945
70.60,4.28,0.172,0.945
70.60,4.31,0.172,0.945
70.60,4.35,0.172,0.945
70.61,4.38,0.172,0.945
70.61,4.41,0.172,0.945
70.61,4.44,0.172,0.945
70.62,4.48,0.172,0.945
70.62,4.51,0.173,0.946
70.63,4.54,0.173,0.947
70.63,4.57,0.173,0.948
70.63,4.61,0.173,0.949
70.64,4.64,0.173,0.951
70.64,4.67,0.174,0.951
70.64,4.70,0.174,0.951
70.65,4.74,0.174,0.951
70.65,4.77,0.174,0.951
70.65,4.80,0.174,0.950
70.65,4.83,0.174,0.950
70.66,4.87,0.174,0.950
70.66,4.90,0.174,0.951
70.66,4.93,0.174,0.952
70.67,4.97,0.174,0.953
70.67,5.00,0.175,0.953
70.68,5.03,0.175,0.953
70.68,5.06,0.175,0.953
70.68,5.10,0.175,0.953
70.69,5.13,0.175,0.953
70.69,5.16,0.175,0.953
70.69,5.19,0.175,0.953
70.70,5.23,0.175,0.952
70.70,5.26,0.175,0.953
70.70,5.29,0.175,0.954
70.70,5.33,0.175,0.954
70.71,5.36,0.175,0.955
70.71,5.39,0.176,0.956
70.71,5.42,0.176,0.956
70.72,5.46,0.176,0.956
70.72,5.49,0.176,0.956
70.73,5.52,0.176,0.956
70.73,5.56,0.176,0.956
70.73,5.59,0.176,0.956
70.74,5.62,0.176,0.956
70.74,5.65,0.176,0.956
70.74,5.68,0.176,0.956
70.75,5.72,0.176,0.957
70.75,5.75,0.176,0.957
70.75,5.78,0.176,0.957
70.75,5.82,0.176,0.957
70.76,5.85,0.176,0.957
70.76,5.88,0.176,0.957
70.76,5.92,0.176,0.957
70.77,5.95,0.176,0.957
70.77,5.98,0.177,0.958
70.78,6.01,0.177,0.958
70.78,6.05,0.177,0.958
70.78,6.08,0.177,0.958
70.79,6.11,0.177,0.958
70.79,6.15,0.177,0.958
70.79,6.18,0.177,0.958
70.80,6.21,0.177,0.958
70.80,6.25,0.177,0.959
70.80,6.28,0.177,0.959
70.80,6.31,0.177,0.959
70.81,6.35,0.177,0.959
70.81,6.38,0.177,0.959
70.81,6.41,0.177,0.959
70.82,6.44,0.177,0.960
70.82,6.48,0.177,0.960
70.83,6.51,0.177,0.960
70.83,6.54,0.177,0.960
70.83,6.58,0.177,0.960
70.84,6.61,0.177,0.960
70.84,6.64,0.177,0.959
70.84,6.68,0.177,0.959
70.85,6.71,0.177,0.959
70.85,6.74,0.178,0.959
70.85,6.77,0.178,0.960
70.85,6.81,0.178,0.960
70.86,6.84,0.178,0.960
70.86,6.87,0.178,0.960
70.86,6.91,0.178,0.960
70.87,6.94,0.178,0.960
70.87,6.97,0.178,0.960
70.88,7.01,0.178,0.961
70.88,7.04,0.178,0.961
70.88,7.07,0.178,0.961
70.89,7.10,0.178,0.962
70.89,7.14,0.178,0.962
70.89,7.17,0.178,0.962
70.90,7.20,0.178,0.962
70.90,7.24,0.178,0.962
70.90,7.27,0.178,0.962
70.90,7.30,0.178,0.962
70.91,7.34,0.178,0.962
70.91,7.37,0.178,0.962
70.91,7.40,0.178,0.962
70.92,7.44,0.178,0.962
70.92,7.47,0.178,0.962
70.93,7.50,0.178,0.962
70.93,7.54,0.178,0.962
70.93,7.57,0.179,0.962
70.94,7.60,0.179,0.963
70.94,7.63,0.179,0.963
70.94,7.67,0.179,0.963
70.95,7.70,0.179,0.963
70.95,7.73,0.179,0.963
70.95,7.77,0.179,0.963
70.95,7.80,0.179,0.963
70.96,7.83,0.179,0.964
70.96,7.86,0.179,0.964
70.96,7.90,0.179,0.964
70.97,7.93,0.179,0.964
70.97,7.97,0.179,0.964
70.98,8.00,0.179,0.964
70.98,8.03,0.179,0.964
70.98,8.06,0.179,0.964
70.99,8.10,0.179,0.964
70.99,8.13,0.179,0.964
70.99,8.16,0.179,0.964
71.00,8.20,0.179,0.965
71.00,8.23,0.179,0.965
71.00,8.26,0.179,0.965
71.00,8.30,0.179,0.965
71.01,8.33,0.179,0.965
71.01,8.36,0.179,0.965
71.01,8.39,0.179,0.965
71.02,8.43,0.179,0.965
71.02,8.46,0.179,0.965
71.03,8.49,0.179,0.965
71.03,8.53,0.179,0.965
71.03,8.56,0.179,0.965
71.04,8.59,0.179,0.965
71.04,8.63,0.179,0.965
71.04,8.66,0.179,0.965
71.05,8.69,0.179,0.966
71.05,8.73,0.179,0.966
71.05,8.76,0.179,0.966
71.05,8.79,0.180,0.966
71.06,8.83,0.180,0.966
71.06,8.86,0.180,0.966
71.06,8.89,0.180,0.966
71.07,8.93,0.180,0.967
71.07,8.96,0.180,0.967
71.08,8.99,0.180,0.967
71.08,9.03,0.180,0.967
71.08,9.06,0.180,0.967
71.09,9.09,0.180,0.967
71.09,9.12,0.180,0.967
71.09,9.16,0.180,0.968
71.10,9.19,0.180,0.968
71.10,9.22,0.180,0.968
71.10,9.26,0.180,0.968
71.10,9.29,0.180,0.968
71.11,9.32,0.180,0.968
71.11,9.36,0.180,0.969
71.11,9.39,0.180,0.970
71.12,9.42,0.180,0.970
71.12,9.46,0.180,0.970
71.13,9.49,0.180,0.970
71.13,9.52,0.180,0.970
71.13,9.56,0.180,0.970
71.14,9.59,0.181,0.971
71.14,9.62,0.181,0.971
71.14,9.66,0.181,0.971
71.15,9.69,0.181,0.971
71.15,9.72,0.181,0.971
71.15,9.76,0.181,0.971
71.15,9.79,0.181,0.971
71.16,9.82,0.181,0.971
71.16,9.86,0.181,0.971
71.16,9.89,0.181,0.971
71.17,9.92,0.181,0.971
71.17,9.96,0.181,0.971
71.18,9.99,0.181,0.971
71.18,10.02,0.181,0.971
71.18,10.05,0.181,0.971
71.19,10.09,0.181,0.971
71.19,10.12,0.181,0.971
71.19,10.15,0.181,0.971
71.20,10.19,0.181,0.972
71.20,10.22,0.181,0.972
71.20,10.25,0.181,0.972
71.20,10.29,0.181,0.972
71.21,10.32,0.181,0.972
71.21,10.35,0.181,0.972
71.21,10.39,0.181,0.972
71.22,10.42,0.181,0.973
71.22,10.45,0.181,0.973
71.23,10.49,0.181,0.973
71.23,10.52,0.181,0.973
71.23,10.55,0.181,0.973
71.24,10.59,0.181,0.973
71.24,10.62,0.181,0.973
71.24,10.65,0.181,0.973
71.25,10.69,0.181,0.973
71.25,10.72,0.181,0.973
71.25,10.75,0.181,0.973
71.25,10.79,0.181,0.973
71.26,10.82,0.181,0.974
71.26,10.85,0.181,0.974
71.26,10.89,0.181,0.974
71.27,10.92,0.182,0.974
71.27,10.95,0.182,0.974
71.28,10.98,0.182,0.974
71.28,11.02,0.182,0.974
71.28,11.05,0.182,0.974
71.29,11.09,0.182,0.974
71.29,11.12,0.182,0.974
71.29,11.15,0.182,0.975
71.30,11.19,0.182,0.975
71.30,11.22,0.182,0.975
71.30,11.25,0.182,0.975
71.30,11.28,0.182,0.975
71.31,11.32,0.182,0.975
71.31,11.35,0.182,0.975
71.31,11.38,0.182,0.975
71.32,11.42,0.182,0.975
71.32,11.45,0.182,0.976
71.33,11.48,0.182,0.976
71.33,11.52,0.182,0.976
71.33,11.55,0.182,0.976
71.34,11.58,0.182,0.976
71.34,11.62,0.182,0.976
71.34,11.65,0.182,0.977
71.35,11.68,0.182,0.977
71.35,11.72,0.182,0.977
71.35,11.75,0.182,0.977
71.35,11.78,0.182,0.977
71.36,11.82,0.182,0.977
71.36,11.85,0.182,0.977
71.36,11.88,0.182,0.977
71.37,11.92,0.182,0.977
71.37,11.95,0.182,0.978
71.38,11.98,0.182,0.978
71.38,12.02,0.182,0.978
71.38,12.05,0.182,0.978
71.39,12.08,0.182,0.978
71.39,12.12,0.182,0.978
71.39,12.15,0.182,0.978
71.40,12.18,0.183,0.979
71.40,12.22,0.183,0.979
71.40,12.25,0.183,0.979
71.40,12.28,0.183,0.979
71.41,12.32,0.183,0.979
71.41,12.35,0.183,0.979
71.41,12.38,0.183,0.979
71.42,12.42,0.183,0.979
71.42,12.45,0.183,0.980
71.43,12.48,0.183,0.980
71.43,12.52,0.183,0.980
71.43,12.55,0.183,0.981
71.44,12.58,0.183,0.981
71.44,12.62,0.183,0.980
71.44,12.65,0.183,0.981
71.45,12.68,0.183,0.981
71.45,12.72,0.183,0.981
71.45,12.75,0.183,0.981
71.45,12.78,0.183,0.981
71.46,12.82,0.183,0.981
71.46,12.85,0.183,0.981
71.46,12.88,0.183,0.982
71.47,12.92,0.183,0.982
71.47,12.95,0.183,0.982
71.48,12.98,0.183,0.982
71.48,13.01,0.183,0.982
71.48,13.05,0.183,0.982
71.49,13.08,0.183,0.982
71.49,13.12,0.183,0.982
71.49,13.15,0.183,0.982
71.50,13.18,0.183,0.982
71.50,13.21,0.183,0.982
71.50,13.25,0.183,0.982
71.50,13.28,0.183,0.982
71.51,13.31,0.183,0.983
71.51,13.35,0.183,0.983
71.51,13.38,0.183,0.983
71.52,13.42,0.183,0.983
71.52,13.45,0.183,0.983
71.53,13.48,0.183,0.983
71.53,13.51,0.184,0.983
71.53,13.55,0.184,0.983
71.54,13.58,0.184,0.983
71.54,13.61,0.184,0.983
71.54,13.65,0.184,0.983
71.55,13.68,0.184,0.983
71.55,13.71,0.184,0.984
71.55,13.75,0.184,0.984
71.55,13.78,0.184,0.984
71.56,13.81,0.184,0.984
71.56,13.85,0.184,0.984
71.56,13.88,0.184,0.984
71.57,13.91,0.184,0.984
71.57,13.95,0.184,0.984
71.58,13.98,0.184,0.985
71.58,14.02,0.184,0.985
71.58,14.05,0.184,0.985
71.59,14.08,0.184,0.985
71.59,14.11,0.184,0.985
71.59,14.15,0.184,0.985
71.60,14.18,0.184,0.985
71.60,14.21,0.184,0.986
71.60,14.25,0.184,0.986
71.60,14.28,0.184,0.986
71.61,14.31,0.184,0.986
71.61,14.35,0.184,0.986
71.61,14.38,0.184,0.986
71.62,14.41,0.184,0.986
71.62,14.45,0.184,0.986
71.63,14.48,0.184,0.986
71.63,14.51,0.184,0.986
71.63,14.55,0.184,0.986
71.64,14.58,0.184,0.986
71.64,14.61,0.184,0.987
71.64,14.65,0.184,0.987
71.65,14.68,0.184,0.987
71.65,14.71,0.184,0.987
71.65,14.75,0.184,0.987
71.65,14.78,0.184,0.987
71.66,14.81,0.184,0.987
71.66,14.85,0.184,0.987
71.66,14.88,0.184,0.987
71.67,14.91,0.184,0.987
71.67,14.95,0.185,0.988
71.68,14.98,0.185,0.988
71.68,15.01,0.185,0.988
71.68,15.05,0.185,0.988
71.69,15.08,0.185,0.988
71.69,15.11,0.185,0.988
71.69,15.15,0.185,0.988
71.70,15.18,0.185,0.988
71.70,15.21,0.185,0.989
71.70,15.25,0.185,0.989
71.70,15.28,0.185,0.989
71.71,15.31,0.185,0.989
71.71,15.35,0.185,0.989
71.71,15.38,0.185,0.989
71.72,15.41,0.185,0.989
71.72,15.45,0.185,0.989
71.73,15.48,0.185,0.990
71.73,15.51,0.185,0.990
71.73,15.55,0.185,0.990
71.74,15.58,0.185,0.990
71.74,15.61,0.185,0.990
71.74,15.65,0.185,0.990
71.75,15.68,0.185,0.990
71.75,15.71,0.185,0.990
71.75,15.75,0.185,0.990
71.75,15.78,0.185,0.990
71.76,15.81,0.185,0.990
71.76,15.85,0.185,0.991
71.76,15.88,0.185,0.991
71.77,15.91,0.185,0.991
71.77,15.95,0.185,0.991
71.78,15.98,0.185,0.991
71.78,16.01,0.185,0.991
71.78,16.05,0.185,0.991
71.79,16.08,0.185,0.991
71.79,16.11,0.185,0.991
71.79,16.15,0.185,0.992
71.80,16.18,0.185,0.992
71.80,16.21,0.185,0.992
71.80,16.25,0.185,0.992
71.80,16.28,0.185,0.992
71.81,16.31,0.185,0.992
71.81,16.35,0.185,0.993
71.81,16.38,0.186,0.993
71.82,16.41,0.186,0.993
71.82,16.45,0.186,0.993
71.83,16.48,0.186,0.993
71.83,16.51,0.186,0.993
71.83,16.55,0.186,0.994
71.84,16.58,0.186,0.994
71.84,16.61,0.186,0.994
71.84,16.65,0.186,0.994
71.85,16.68,0.186,0.994
71.85,16.71,0.186,0.994
71.85,16.75,0.186,0.994
71.85,16.78,0.186,0.994
71.86,16.81,0.186,0.994
71.86,16.85,0.186,0.994
71.86,16.88,0.186,0.994
71.87,16.91,0.186,0.994
71.87,16.95,0.186,0.994
71.88,16.98,0.186,0.994
71.88,17.01,0.186,0.994
71.88,17.05,0.186,0.995
71.89,17.08,0.186,0.995
71.89,17.11,0.186,0.995
71.89,17.15,0.186,0.995
71.90,17.18,0.186,0.995
71.90,17.21,0.186,0.995
71.90,17.25,0.186,0.995
71.90,17.28,0.186,0.995
71.91,17.31,0.186,0.995
71.91,17.35,0.186,0.996
71.91,17.38,0.186,0.996
71.92,17.41,0.186,0.996
71.92,17.45,0.186,0.996
71.93,17.48,0.186,0.996
71.93,17.51,0.186,0.996
71.93,17.55,0.186,0.996
71.94,17.58,0.186,0.996
71.94,17.61,0.186,0.996
71.94,17.65,0.186,0.997
71.95,17.68,0.186,0.997
71.95,17.71,0.186,0.997
71.95,17.75,0.186,0.997
71.95,17.78,0.186,0.997
71.96,17.81,0.186,0.997
71.96,17.85,0.186,0.997
71.96,17.88,0.186,0.997
71.97,17.91,0.186,0.997
71.97,17.95,0.186,0.997
71.98,17.98,0.186,0.998
71.98,18.01,0.187,0.998
71.98,18.05,0.187,0.998
71.99,18.08,0.187,0.998
71.99,18.11,0.187,0.998
71.99,18.15,0.187,0.998
72.00,18.18,0.187,0.998
72.00,18.22,0.187,0.998
72.00,18.25,0.187,0.999
72.00,18.28,0.187,0.999
72.01,18.31,0.187,0.999
72.01,18.35,0.187,0.999
72.01,18.38,0.187,0.999
72.02,18.41,0.187,0.999
72.02,18.45,0.187,0.999
72.03,18.48,0.187,0.999
72.03,18.51,0.187,1.000
72.03,18.55,0.187,1.000
72.04,18.58,0.187,1.000
72.04,18.61,0.187,1.000
72.04,18.65,0.187,1.000
72.05,18.68,0.187,1.000
72.05,18.71,0.187,1.000
72.05,18.75,0.187,1.000
72.05,18.78,0.187,1.000
72.06,18.82,0.187,1.000
72.06,18.85,0.187,1.000
72.06,18.88,0.187,1.000
72.07,18.91,0.187,1.000
72.07,18.95,0.187,1.001
72.08,18.98,0.187,1.001
72.08,19.01,0.187,1.001
72.08,19.05,0.187,1.001
72.09,19.08,0.187,1.001
72.09,19.11,0.187,1.001
72.09,19.15,0.187,1.001
72.10,19.18,0.187,1.001
72.10,19.21,0.187,1.002
72.10,19.25,0.187,1.002
72.10,19.28,0.187,1.002
72.11,19.32,0.187,1.002
72.11,19.35,0.187,1.002
72.11,19.38,0.187,1.002
72.12,19.42,0.187,1.002
72.12,19.45,0.187,1.002
72.13,19.48,0.187,1.002
72.13,19.52,0.187,1.003
72.13,19.55,0.187,1.003
72.14,19.58,0.187,1.003
72.14,19.61,0.188,1.003
72.14,19.65,0.188,1.003
72.15,19.68,0.188,1.003
72.15,19.72,0.188,1.003
72.15,19.75,0.188,1.003
72.15,19.78,0.188,1.003
72.16,19.81,0.188,1.004
72.16,19.85,0.188,1.004
72.16,19.88,0.188,1.004
72.17,19.92,0.188,1.004
72.17,19.95,0.188,1.004
72.18,19.98,0.188,1.004
72.18,20.02,0.188,1.004
72.18,20.05,0.188,1.004
72.19,20.08,0.188,1.004
72.19,20.12,0.188,1.004
72.19,20.15,0.188,1.004
72.20,20.18,0.188,1.005
72.20,20.22,0.188,1.005
72.20,20.25,0.188,1.005
72.20,20.28,0.188,1.005
72.21,20.32,0.188,1.005
72.21,20.35,0.188,1.005
72.21,20.38,0.188,1.005
72.22,20.42,0.188,1.005
72.22,20.45,0.188,1.006
72.23,20.48,0.188,1.006
72.23,20.52,0.188,1.006
72.23,20.55,0.188,1.006
72.24,20.58,0.188,1.006
72.24,20.62,0.188,1.006
72.24,20.65,0.188,1.006
72.25,20.68,0.188,1.006
72.25,20.72,0.188,1.007
72.25,20.75,0.188,1.007
72.25,20.78,0.188,1.007
72.26,20.82,0.188,1.007
72.26,20.85,0.188,1.007
72.26,20.88,0.188,1.007
72.27,20.92,0.188,1.007
72.27,20.95,0.188,1.007
72.28,20.98,0.188,1.008
72.28,21.02,0.188,1.008
72.28,21.05,0.188,1.008
72.29,21.08,0.188,1.008
72.29,21.12,0.189,1.009
72.29,21.15,0.189,1.009
72.30,21.18,0.189,1.009
72.30,21.22,0.189,1.009
72.30,21.25,0.189,1.009
72.30,21.28,0.189,1.009
72.31,21.32,0.189,1.009
72.31,21.35,0.189,1.009
72.31,21.38,0.189,1.009
72.32,21.42,0.189,1.009
72.32,21.45,0.189,1.009
72.33,21.48,0.189,1.009
72.33,21.52,0.189,1.010
72.33,21.55,0.189,1.010
72.34,21.58,0.189,1.010
72.34,21.62,0.189,1.010
72.34,21.65,0.189,1.011
72.35,21.68,0.189,1.011
72.35,21.72,0.189,1.011
72.35,21.75,0.189,1.010
72.35,21.78,0.189,1.010
72.36,21.82,0.189,1.010
72.36,21.85,0.189,1.011
72.36,21.88,0.189,1.011
72.37,21.92,0.189,1.011
72.37,21.95,0.189,1.012
72.38,21.98,0.189,1.012
72.38,22.02,0.189,1.012
72.38,22.05,0.189,1.011
72.39,22.08,0.189,1.011
72.39,22.12,0.189,1.011
72.39,22.15,0.189,1.012
72.40,22.18,0.189,1.012
72.40,22.22,0.189,1.012
72.40,22.25,0.189,1.012
72.40,22.28,0.189,1.012
72.41,22.32,0.189,1.012
72.41,22.35,0.189,1.013
72.41,22.38,0.189,1.013
72.42,22.42,0.189,1.013
72.42,22.45,0.189,1.013
72.43,22.48,0.189,1.013
72.43,22.52,0.189,1.013
72.43,22.55,0.189,1.013
72.44,22.58,0.189,1.013
72.44,22.62,0.189,1.013
72.44,22.65,0.189,1.014
72.45,22.68,0.189,1.014
72.45,22.72,0.190,1.014
72.45,22.75,0.190,1.014
72.45,22.78,0.190,1.014
72.46,22.82,0.190,1.014
72.46,22.85,0.190,1.014
72.46,22.88,0.190,1.014
72.47,22.92,0.190,1.014
72.47,22.95,0.190,1.014
72.48,22.98,0.190,1.015
72.48,23.02,0.190,1.015
72.48,23.05,0.190,1.015
72.49,23.08,0.190,1.015
72.49,23.12,0.190,1.015
72.49,23.15,0.190,1.015
72.50,23.18,0.190,1.015
72.50,23.22,0.190,1.015
72.50,23.25,0.190,1.015
72.50,23.28,0.190,1.015
72.51,23.32,0.190,1.016
72.51,23.35,0.190,1.016
72.51,23.38,0.190,1.016
72.52,23.42,0.190,1.016
72.52,23.45,0.190,1.016
72.53,23.48,0.190,1.016
72.53,23.52,0.190,1.016
72.53,23.55,0.190,1.016
72.54,23.58,0.190,1.016
72.54,23.62,0.190,1.016
72.54,23.65,0.190,1.016
72.55,23.68,0.190,1.016
72.55,23.72,0.190,1.017
72.55,23.75,0.190,1.017
72.55,23.78,0.190,1.017
72.56,23.82,0.190,1.017
72.56,23.85,0.190,1.017
72.56,23.88,0.190,1.017
72.57,23.92,0.190,1.017
72.57,23.95,0.190,1.017
72.58,23.98,0.190,1.018
72.58,24.02,0.190,1.018
72.58,24.05,0.190,1.018
72.59,24.08,0.190,1.018
72.59,24.12,0.190,1.018
72.59,24.15,0.190,1.019
72.60,24.18,0.190,1.019
72.60,24.22,0.190,1.019
72.60,24.25,0.190,1.019
72.60,24.28,0.191,1.019
72.61,24.32,0.191,1.019
72.61,24.35,0.191,1.019
72.61,24.38,0.191,1.019
72.62,24.42,0.191,1.019
72.62,24.45,0.191,1.020
72.63,24.48,0.191,1.020
72.63,24.52,0.191,1.020
72.63,24.55,0.191,1.020
72.64,24.59,0.191,1.020
72.64,24.62,0.191,1.020
72.64,24.65,0.191,1.020
72.65,24.68,0.191,1.020
72.65,24.72,0.191,1.020
72.65,24.75,0.191,1.021
72.65,24.79,0.191,1.021
72.66,24.82,0.191,1.021
72.66,24.85,0.191,1.021
72.66,24.88,0.191,1.021
72.67,24.92,0.191,1.021
72.67,24.95,0.191,1.021
72.68,24.98,0.191,1.021
72.68,25.02,0.191,1.022
72.68,25.05,0.191,1.022
72.69,25.09,0.191,1.022
72.69,25.12,0.191,1.022
72.69,25.15,0.191,1.023
72.70,25.18,0.191,1.023
72.70,25.22,0.191,1.023
72.70,25.25,0.191,1.023
72.70,25.29,0.191,1.023
72.71,25.32,0.191,1.022
72.71,25.35,0.191,1.023
72.71,25.39,0.191,1.023
72.72,25.42,0.191,1.023
72.72,25.45,0.191,1.023
72.73,25.48,0.191,1.023
72.73,25.52,0.191,1.023
72.73,25.55,0.191,1.024
72.74,25.58,0.191,1.024
72.74,25.62,0.191,1.024
72.74,25.65,0.191,1.024
72.75,25.69,0.191,1.024
72.75,25.72,0.191,1.024
72.75,25.75,0.192,1.024
72.75,25.78,0.192,1.025
72.76,25.82,0.192,1.025
72.76,25.85,0.192,1.025
72.76,25.89,0.192,1.025
72.77,25.92,0.192,1.025
72.77,25.95,0.192,1.025
72.78,25.99,0.192,1.025
72.78,26.02,0.192,1.026
72.78,26.05,0.192,1.026
72.79,26.09,0.192,1.026
72.79,26.12,0.192,1.026
72.79,26.15,0.192,1.026
72.80,26.19,0.192,1.025
72.80,26.22,0.192,1.026
72.80,26.25,0.192,1.026
72.80,26.29,0.192,1.026
72.81,26.32,0.192,1.027
72.81,26.35,0.192,1.027
72.81,26.39,0.192,1.027
72.82,26.42,0.192,1.027
72.82,26.45,0.192,1.027
72.83,26.49,0.192,1.027
72.83,26.52,0.192,1.027
72.83,26.55,0.192,1.027
72.84,26.58,0.192,1.027
72.84,26.62,0.192,1.028
72.84,26.65,0.192,1.028
72.85,26.69,0.192,1.028
72.85,26.72,0.192,1.028
72.85,26.75,0.192,1.028
72.85,26.79,0.192,1.028
72.86,26.82,0.192,1.029
72.86,26.85,0.192,1.029
72.86,26.89,0.192,1.029
72.87,26.92,0.192,1.029
72.87,26.95,0.193,1.029
72.88,26.99,0.193,1.029
72.88,27.02,0.193,1.029
72.88,27.05,0.193,1.029
72.89,27.09,0.193,1.030
72.89,27.12,0.193,1.030
72.89,27.15,0.193,
72.90,27.19,0.193,
72.90,27.22,0.193,
72.90,27.25,0.193,
72.90,27.29,0.193,
72.91,27.32,0.193,
72.91,27.35,0.193,
72.91,27.39,0.193,
72.92,27.42,0.193,
72.92,27.45,0.193,
72.93,27.49,0.193,
72.93,27.52,0.193,
72.93,27.55,0.193,
72.94,27.59,0.193,
72.94,27.62,0.193,
72.94,27.65,0.193,
72.95,27.69,0.193,
72.95,27.72,0.193,
72.95,27.75,,
72.95,27.79,,
72.96,27.82,,
72.96,27.85,,
72.96,27.89,,
72.97,27.92,,
72.97,27.95,,
72.98,27.99,,
72.98,28.02,,
72.98,28.05,,
72.99,28.09,,
72.99,28.12,,
72.99,28.15,,
73.00,28.19,,
73.00,28.22,,
73.00,,,
73.00,,,
73.01,,,