File: DSC/2025_04_25_CBG_Ascorbic_Acid_MC_n60C_150C_5Cmin_x3.csv
Filename,2025_04_25_CBG_Ascorbic_Acid_MC_n60C_150C_5Cmin_x3
Instrument name,DSC2A-00468 (192.168.1.100)
Operator,Yarger
rundate,4/25/2025
Sample name,2025_04_25_CBG_Ascorbic_Acid_MC_n60C_150C_5Cmin_x3
proceduresegments,Data Off ; Equilibrate -60.00 °C; Data On ; Ramp 5.00 °C/min to 150.00 °C; Data Off ; Isothermal 1.0 min; Data On ; Ramp 5.00 °C/min to -60.00 °C; Data Off ; Isothermal 1.0 min; Data On ; Ramp 5.00 °C/min to 150.00 °C; Data Off ; Isothermal 1.0 min; Data On ; Ramp 5.00 °C/min to -60.00 °C; Data Off ; Isothermal 1.0 min; Data On ; Ramp 5.00 °C/min to 150.00 °C
[File Parameters]
Run date,4/25/2025 9:27:41 AM
Trios version,5.1.1.46572
Original File Name,
Current File Name,D:\DSC2500\JYarger\2025_04_25_CBG_Ascorbic_Acid_MC_n60C_150C_5Cmin_x3.tri
[Procedure]
Procedure Name,CBG_AA_n60_150C_5Cmin_x3
Sample Name,2025_04_25_CBG_Ascorbic_Acid_MC_n60C_150C_5Cmin_x3
Sample Mass,5.7 mg
Reference Sample Mass,0 mg
Pan Mass,53.08 mg
Pan Number,43
Reference Pan Mass,52.66 mg
Reference Pan Number,19
Pan Type,Tzero Aluminum Hermetic
Comments,Al Hermetic DSC Consumables sealed Pan/Lid.
Project Name,CA
Operator,Yarger
Test,Custom
Unload Max Temperature,30
Unload Min Temperature,30
Load Max Temperature,30
Load Min Temperature,30
Stop on Gas Flow Error,Yes
[Signal List]
Signal #1,Time (min)
Signal #2,Temperature (°C)
Signal #3,Heat Flow (mW)
Signal #4,Delta T (µV)
Signal #5,Delta Tzero (µV)
Signal #6,Tzero Temperature (°C)
Signal #7,Cell Purge (mL/min)
Signal #8,Heater Temp (°C)
Signal #9,Power Delivered (W)
Signal #10,Reference Junction Temperature (°C)
Signal #11,Flange Temperature (°C)
Signal #12,Heat Flow Phase (rad)
Signal #13,Total Heat Capacity (J/°C)
Signal #14,Heat Capacity (J/°C)
[Configuration]
Company Name,ASU
Instrument Name,DSC2A-00468
Instrument Type,DSC2500
Serial Number,DSC2A-00468
IP,192.168.1.100
Location of Instrument,MRRC
DisplayType,Unknown
Sample Interval ,0.1 s/pt
Selected Heat Flow,T4P
Exotherm Direction,Down
Cell Serial,DRC2-00792
Lid Type,Standard
Cooler,RCS 90
Leave Cooler on at End of Sequence,On
Gas 2,Nitrogen
Gas Selected,Channel 1
Flow Rate,50 mL/min
Secondary Purge,On
Licensed Heat Flow,Heat Flow T4P
Modulation Licensed,Yes
[Versions]
Common IDD Version,1
Cortex Version,VER 2.10.2.31
Driver,5.0.0.6
GDM Version,1.0.3.3
TouchscreenVersion,1.0.0.16145
FEP Version,1.2.1.21
FEP Bootloader,2.0.0.5
AutoSampler Version,2.1.1.26
Auto Sampler Bootloader,2.0.0.5
FCM Version,1.1.0.3
FCM Bootloader,2.0.0.5
[Experiment Logs]
Experiment Log Entry # 1,Data On set to 0
Experiment Log Entry # 3,Equilibrate Segment -60 (C) Started
Experiment Log Entry # 5,Air Cool is off.
Experiment Log Entry # 7,Data On set to 1
Experiment Log Entry # 9,Ramp Segment 5 C/min to 150 Started
Experiment Log Entry # 11,Data On set to 0
Experiment Log Entry # 13,Isothermal Segment 1 min started
Experiment Log Entry # 15,Data On set to 1
Experiment Log Entry # 17,Ramp Segment 5 C/min to -60 Started
Experiment Log Entry # 19,Data On set to 0
Experiment Log Entry # 21,Isothermal Segment 1 min started
Experiment Log Entry # 23,Data On set to 1
Experiment Log Entry # 25,Ramp Segment 5 C/min to 150 Started
Experiment Log Entry # 27,Data On set to 0
Experiment Log Entry # 29,Isothermal Segment 1 min started
Experiment Log Entry # 31,Data On set to 1
Experiment Log Entry # 33,Ramp Segment 5 C/min to -60 Started
Experiment Log Entry # 35,Data On set to 0
Experiment Log Entry # 37,Isothermal Segment 1 min started
Experiment Log Entry # 39,Data On set to 1
Experiment Log Entry # 41,Ramp Segment 5 C/min to 150 Started
[Method Log]
Method Log Entry # 1,Data Off
Method Log Entry # 2,Equilibrate -60 °C
Method Log Entry # 3,Data On
Method Log Entry # 4,(Ramp 315882) Ramp 5 °C/minute to 150 °C
Method Log Entry # 5,Data Off
Method Log Entry # 6,Isothermal 1 minutes
Method Log Entry # 7,Data On
Method Log Entry # 8,(Ramp 315886) Ramp 5 °C/minute to -60 °C
Method Log Entry # 9,Data Off
Method Log Entry # 10,Isothermal 1 minutes
Method Log Entry # 11,Data On
Method Log Entry # 12,(Ramp 315890) Ramp 5 °C/minute to 150 °C
Method Log Entry # 13,Data Off
Method Log Entry # 14,Isothermal 1 minutes
Method Log Entry # 15,Data On
Method Log Entry # 16,(Ramp 315894) Ramp 5 °C/minute to -60 °C
Method Log Entry # 17,Data Off
Method Log Entry # 18,Isothermal 1 minutes
Method Log Entry # 19,Data On
Method Log Entry # 20,(Ramp 315898) Ramp 5 °C/minute to 150 °C
Cell Serial,DRC2-00792
[T1 Calibration]
Slope,-0.008529666
Offset,9.636258
Initial Temperature,98.23
GUID,f8bfdadc-4977-4fdf-ba6d-0ba9134940c3
[TZero Calibration]
Date Applied,11/29/2022 4:06:13 PM
Description,From -89.059 °C to 396.009 °C at 20.000°C/min
Gas Type,Nitrogen
Pan Type,None
Source Files 1,C:\Users\yargerlab\Desktop\DSC Data\General\TZero_calibration_11_29_22_2nd(2).tri
Source Files 2,C:\Users\yargerlab\Desktop\DSC Data\General\TZero_calibration_11_29_22_2nd(3).tri
Delta T Offset,13.05235
Delta T Slope,-0.007271007
Delta T0 Offset,-13.69128
Delta T0 Slope,0.06063341
[Temperature Calibration]
Date Applied,11/29/2022 7:12:28 PM
Description,From 106.590 °C to 186.590 °C at 10.000°C/min
Gas Type,Nitrogen
Pan Type,Tzero Aluminum Hermetic
Source Files 1,C:\Users\yargerlab\Desktop\DSC Data\General\Indium(6).tri
Measured 1,157.391
Known 1,156.598
[Cell Constant Calibration]
Date Applied,11/29/2022 7:12:29 PM
Description,From 106.590 °C to 186.590 °C at 10.000°C/min
Gas Type,Nitrogen
Pan Type,Tzero Aluminum Hermetic
Source Files 1,C:\Users\yargerlab\Desktop\DSC Data\General\Indium(6).tri
T4P KCell,1.006051
Onset Slope,63.26126 mW/°C
[Direct Cp Calibration]
Date Applied,11/30/2022 11:04:51 AM
Description,From -79.983 °C to 298.409 °C at 10.000°C/min
Gas Type,Nitrogen
Pan Type,Tzero Aluminum Hermetic
Source Files 1,C:\Users\yargerlab\Desktop\DSC Data\General\Sapphire_Heat_Capacity_11_30_22.tri
[Rev Cp Calibration]
Date Applied,11/30/2022 1:58:51 PM
Description,From -79.996 °C to 292.812 °C at 3.000°C/min
Gas Type,Nitrogen
Pan Type,Tzero Aluminum Hermetic
Source Files 1,C:\Users\yargerlab\Desktop\DSC Data\General\Sapphire_MDSC_Calibration_11_30_22.tri
[step]
Ramp 5.00 °C/min to 150.00 °C
Time,Temperature,Heat Flow (Normalized)
min,°C,W/g
0.00,-59.66,-0.096
0.03,-59.68,-0.092
0.06,-59.69,-0.086
0.08,-59.66,-0.103
0.11,-59.60,-0.128
0.14,-59.51,-0.135
0.17,-59.41,-0.130
0.20,-59.31,-0.103
0.23,-59.20,-0.077
0.26,-59.09,-0.057
0.28,-58.97,-0.041
0.31,-58.85,-0.026
0.34,-58.73,-0.013
0.37,-58.60,-0.005
0.40,-58.47,0.006
0.43,-58.34,0.012
0.45,-58.21,0.018
0.48,-58.08,0.025
0.51,-57.94,0.029
0.54,-57.81,0.032
0.57,-57.68,0.035
0.60,-57.54,0.037
0.62,-57.40,0.040
0.65,-57.27,0.042
0.68,-57.13,0.044
0.71,-56.99,0.044
0.74,-56.85,0.046
0.77,-56.72,0.046
0.79,-56.58,0.047
0.82,-56.44,0.048
0.85,-56.30,0.048
0.88,-56.16,0.049
0.91,-56.02,0.050
0.93,-55.88,0.050
0.96,-55.74,0.051
0.99,-55.61,0.051
1.02,-55.46,0.052
1.05,-55.33,0.052
1.08,-55.18,0.053
1.11,-55.05,0.053
1.13,-54.91,0.054
1.16,-54.77,0.054
1.19,-54.62,0.054
1.22,-54.48,0.054
1.25,-54.34,0.055
1.28,-54.20,0.055
1.30,-54.06,0.055
1.33,-53.92,0.056
1.36,-53.78,0.056
1.39,-53.64,0.056
1.42,-53.50,0.056
1.44,-53.36,0.056
1.47,-53.22,0.057
1.50,-53.08,0.057
1.53,-52.93,0.057
1.56,-52.80,0.057
1.59,-52.65,0.057
1.62,-52.51,0.057
1.64,-52.37,0.057
1.67,-52.23,0.058
1.70,-52.09,0.058
1.73,-51.95,0.058
1.76,-51.81,0.058
1.78,-51.66,0.058
1.81,-51.52,0.058
1.84,-51.38,0.058
1.87,-51.24,0.058
1.90,-51.10,0.058
1.93,-50.96,0.058
1.96,-50.81,0.058
1.98,-50.67,0.058
2.01,-50.53,0.058
2.04,-50.39,0.058
2.07,-50.25,0.058
2.10,-50.11,0.058
2.13,-49.97,0.058
2.15,-49.83,0.058
2.18,-49.69,0.058
2.21,-49.54,0.058
2.24,-49.40,0.058
2.27,-49.26,0.058
2.29,-49.12,0.058
2.32,-48.98,0.058
2.35,-48.84,0.058
2.38,-48.69,0.058
2.41,-48.55,0.058
2.44,-48.41,0.058
2.46,-48.27,0.058
2.49,-48.13,0.058
2.52,-47.99,0.058
2.55,-47.85,0.058
2.58,-47.70,0.058
2.61,-47.56,0.058
2.64,-47.42,0.058
2.66,-47.28,0.058
2.69,-47.14,0.058
2.72,-47.00,0.058
2.75,-46.86,0.058
2.78,-46.71,0.058
2.81,-46.57,0.058
2.83,-46.43,0.058
2.86,-46.29,0.058
2.89,-46.15,0.058
2.92,-46.01,0.058
2.95,-45.86,0.058
2.98,-45.72,0.058
3.00,-45.58,0.058
3.03,-45.44,0.058
3.06,-45.30,0.058
3.09,-45.16,0.058
3.12,-45.01,0.058
3.14,-44.87,0.058
3.17,-44.73,0.058
3.20,-44.59,0.058
3.23,-44.45,0.058
3.26,-44.31,0.058
3.29,-44.17,0.058
3.31,-44.02,0.058
3.34,-43.88,0.058
3.37,-43.74,0.058
3.40,-43.60,0.058
3.43,-43.46,0.058
3.46,-43.31,0.058
3.49,-43.17,0.058
3.51,-43.03,0.058
3.54,-42.89,0.058
3.57,-42.75,0.058
3.60,-42.61,0.058
3.63,-42.46,0.058
3.66,-42.32,0.058
3.68,-42.18,0.058
3.71,-42.04,0.058
3.74,-41.89,0.058
3.77,-41.75,0.058
3.80,-41.61,0.058
3.83,-41.47,0.058
3.85,-41.33,0.058
3.88,-41.19,0.058
3.91,-41.04,0.058
3.94,-40.90,0.058
3.97,-40.76,0.058
3.99,-40.62,0.058
4.02,-40.48,0.058
4.05,-40.34,0.058
4.08,-40.20,0.058
4.11,-40.05,0.058
4.14,-39.91,0.058
4.16,-39.77,0.058
4.19,-39.63,0.058
4.22,-39.49,0.058
4.25,-39.34,0.058
4.28,-39.20,0.058
4.31,-39.06,0.058
4.34,-38.92,0.058
4.36,-38.78,0.058
4.39,-38.63,0.058
4.42,-38.49,0.058
4.45,-38.35,0.058
4.48,-38.21,0.058
4.50,-38.07,0.058
4.53,-37.93,0.058
4.56,-37.78,0.058
4.59,-37.64,0.058
4.62,-37.50,0.059
4.65,-37.36,0.059
4.68,-37.21,0.059
4.70,-37.07,0.059
4.73,-36.93,0.059
4.76,-36.79,0.059
4.79,-36.65,0.059
4.82,-36.51,0.059
4.85,-36.36,0.059
4.87,-36.22,0.059
4.90,-36.08,0.059
4.93,-35.94,0.059
4.96,-35.80,0.059
4.99,-35.66,0.059
5.01,-35.51,0.059
5.04,-35.37,0.059
5.07,-35.23,0.059
5.10,-35.09,0.059
5.13,-34.95,0.059
5.16,-34.80,0.059
5.19,-34.66,0.059
5.21,-34.52,0.059
5.24,-34.38,0.059
5.27,-34.24,0.059
5.30,-34.10,0.059
5.33,-33.95,0.059
5.35,-33.81,0.059
5.38,-33.67,0.059
5.41,-33.53,0.059
5.44,-33.39,0.059
5.47,-33.24,0.059
5.50,-33.10,0.059
5.53,-32.96,0.059
5.55,-32.82,0.059
5.58,-32.68,0.059
5.61,-32.53,0.059
5.64,-32.39,0.059
5.67,-32.25,0.059
5.70,-32.11,0.059
5.72,-31.97,0.059
5.75,-31.82,0.059
5.78,-31.68,0.059
5.81,-31.54,0.059
5.84,-31.40,0.059
5.86,-31.26,0.059
5.89,-31.12,0.059
5.92,-30.98,0.059
5.95,-30.83,0.059
5.98,-30.69,0.059
6.01,-30.55,0.059
6.04,-30.41,0.059
6.06,-30.27,0.059
6.09,-30.12,0.059
6.12,-29.98,0.059
6.15,-29.84,0.059
6.18,-29.70,0.059
6.20,-29.56,0.059
6.23,-29.42,0.059
6.26,-29.27,0.059
6.29,-29.13,0.059
6.32,-28.99,0.059
6.35,-28.85,0.059
6.38,-28.71,0.059
6.40,-28.57,0.059
6.43,-28.42,0.059
6.46,-28.28,0.059
6.49,-28.14,0.059
6.52,-28.00,0.059
6.55,-27.86,0.059
6.57,-27.71,0.059
6.60,-27.57,0.059
6.63,-27.43,0.059
6.66,-27.29,0.059
6.69,-27.15,0.059
6.71,-27.01,0.060
6.74,-26.86,0.060
6.77,-26.72,0.060
6.80,-26.58,0.060
6.83,-26.44,0.060
6.86,-26.30,0.060
6.89,-26.15,0.060
6.91,-26.01,0.060
6.94,-25.87,0.060
6.97,-25.73,0.060
7.00,-25.59,0.060
7.03,-25.45,0.060
7.05,-25.30,0.060
7.08,-25.16,0.060
7.11,-25.02,0.060
7.14,-24.88,0.060
7.17,-24.74,0.060
7.20,-24.60,0.060
7.23,-24.45,0.060
7.25,-24.31,0.060
7.28,-24.17,0.060
7.31,-24.03,0.060
7.34,-23.89,0.060
7.37,-23.74,0.060
7.40,-23.60,0.060
7.42,-23.46,0.060
7.45,-23.32,0.060
7.48,-23.18,0.060
7.51,-23.04,0.060
7.54,-22.89,0.060
7.56,-22.75,0.060
7.59,-22.61,0.060
7.62,-22.47,0.060
7.65,-22.33,0.060
7.68,-22.19,0.060
7.71,-22.04,0.060
7.74,-21.90,0.060
7.76,-21.76,0.060
7.79,-21.62,0.060
7.82,-21.47,0.061
7.85,-21.33,0.061
7.88,-21.19,0.061
7.90,-21.05,0.061
7.93,-20.91,0.061
7.96,-20.77,0.061
7.99,-20.63,0.061
8.02,-20.48,0.061
8.05,-20.34,0.061
8.08,-20.20,0.061
8.10,-20.06,0.061
8.13,-19.92,0.061
8.16,-19.78,0.061
8.19,-19.63,0.061
8.22,-19.49,0.061
8.25,-19.35,0.061
8.27,-19.21,0.061
8.30,-19.07,0.061
8.33,-18.92,0.061
8.36,-18.78,0.061
8.39,-18.64,0.061
8.41,-18.50,0.061
8.44,-18.35,0.061
8.47,-18.21,0.061
8.50,-18.07,0.061
8.53,-17.93,0.061
8.56,-17.79,0.061
8.58,-17.65,0.061
8.61,-17.51,0.061
8.64,-17.36,0.061
8.67,-17.22,0.061
8.70,-17.08,0.061
8.73,-16.94,0.061
8.75,-16.80,0.061
8.78,-16.66,0.061
8.81,-16.51,0.061
8.84,-16.37,0.061
8.87,-16.23,0.061
8.90,-16.09,0.061
8.93,-15.95,0.061
8.95,-15.81,0.061
8.98,-15.66,0.061
9.01,-15.52,0.062
9.04,-15.38,0.062
9.07,-15.24,0.062
9.10,-15.10,0.062
9.12,-14.96,0.062
9.15,-14.81,0.062
9.18,-14.67,0.062
9.21,-14.53,0.062
9.24,-14.39,0.062
9.27,-14.25,0.062
9.29,-14.10,0.062
9.32,-13.96,0.062
9.35,-13.82,0.062
9.38,-13.68,0.062
9.41,-13.54,0.062
9.43,-13.39,0.062
9.46,-13.25,0.062
9.49,-13.11,0.062
9.52,-12.97,0.062
9.55,-12.83,0.062
9.58,-12.68,0.062
9.60,-12.54,0.062
9.63,-12.40,0.062
9.66,-12.26,0.063
9.69,-12.12,0.063
9.72,-11.98,0.063
9.75,-11.84,0.062
9.78,-11.69,0.062
9.80,-11.55,0.062
9.83,-11.41,0.062
9.86,-11.27,0.063
9.89,-11.13,0.063
9.92,-10.99,0.063
9.95,-10.84,0.063
9.97,-10.70,0.063
10.00,-10.56,0.063
10.03,-10.42,0.063
10.06,-10.28,0.063
10.09,-10.13,0.063
10.12,-9.99,0.063
10.14,-9.85,0.063
10.17,-9.71,0.063
10.20,-9.57,0.063
10.23,-9.43,0.063
10.26,-9.28,0.063
10.28,-9.14,0.063
10.31,-9.00,0.063
10.34,-8.86,0.063
10.37,-8.72,0.063
10.40,-8.57,0.063
10.43,-8.43,0.063
10.45,-8.29,0.063
10.48,-8.15,0.063
10.51,-8.01,0.063
10.54,-7.87,0.063
10.57,-7.72,0.063
10.60,-7.58,0.063
10.63,-7.44,0.063
10.65,-7.30,0.063
10.68,-7.16,0.063
10.71,-7.01,0.063
10.74,-6.87,0.063
10.77,-6.73,0.063
10.80,-6.59,0.063
10.82,-6.44,0.064
10.85,-6.30,0.064
10.88,-6.16,0.064
10.91,-6.02,0.064
10.94,-5.88,0.064
10.97,-5.74,0.064
10.99,-5.59,0.064
11.02,-5.45,0.064
11.05,-5.31,0.064
11.08,-5.17,0.064
11.11,-5.03,0.064
11.13,-4.89,0.064
11.16,-4.74,0.064
11.19,-4.60,0.064
11.22,-4.46,0.064
11.25,-4.32,0.064
11.28,-4.18,0.064
11.30,-4.04,0.064
11.33,-3.89,0.064
11.36,-3.75,0.064
11.39,-3.61,0.064
11.42,-3.47,0.064
11.45,-3.33,0.064
11.48,-3.19,0.064
11.50,-3.05,0.064
11.53,-2.90,0.064
11.56,-2.76,0.064
11.59,-2.62,0.064
11.62,-2.48,0.064
11.65,-2.34,0.064
11.67,-2.19,0.064
11.70,-2.05,0.064
11.73,-1.91,0.064
11.76,-1.77,0.064
11.79,-1.63,0.064
11.82,-1.49,0.064
11.84,-1.34,0.065
11.87,-1.20,0.065
11.90,-1.06,0.065
11.93,-0.92,0.065
11.96,-0.78,0.065
11.98,-0.64,0.065
12.01,-0.49,0.065
12.04,-0.35,0.065
12.07,-0.21,0.065
12.10,-0.07,0.065
12.13,0.07,0.065
12.15,0.22,0.065
12.18,0.36,0.065
12.21,0.50,0.065
12.24,0.64,0.065
12.27,0.78,0.065
12.30,0.92,0.065
12.33,1.07,0.065
12.35,1.21,0.065
12.38,1.35,0.065
12.41,1.49,0.065
12.44,1.63,0.065
12.47,1.78,0.065
12.50,1.92,0.065
12.52,2.06,0.066
12.55,2.20,0.066
12.58,2.34,0.066
12.61,2.48,0.066
12.64,2.63,0.066
12.67,2.77,0.066
12.69,2.91,0.066
12.72,3.05,0.066
12.75,3.19,0.066
12.78,3.33,0.066
12.81,3.48,0.066
12.83,3.62,0.066
12.86,3.76,0.066
12.89,3.90,0.066
12.92,4.05,0.066
12.95,4.19,0.066
12.98,4.33,0.066
13.00,4.47,0.066
13.03,4.61,0.066
13.06,4.75,0.066
13.09,4.90,0.066
13.12,5.04,0.066
13.15,5.18,0.066
13.18,5.32,0.066
13.20,5.46,0.066
13.23,5.60,0.066
13.26,5.75,0.066
13.29,5.89,0.066
13.32,6.03,0.066
13.35,6.17,0.066
13.37,6.31,0.066
13.40,6.45,0.066
13.43,6.60,0.066
13.46,6.74,0.066
13.49,6.88,0.066
13.52,7.02,0.066
13.54,7.16,0.067
13.57,7.30,0.067
13.60,7.45,0.067
13.63,7.59,0.067
13.66,7.73,0.067
13.68,7.87,0.067
13.71,8.01,0.067
13.74,8.15,0.067
13.77,8.30,0.067
13.80,8.44,0.067
13.83,8.58,0.067
13.85,8.72,0.067
13.88,8.86,0.067
13.91,9.01,0.067
13.94,9.15,0.067
13.97,9.29,0.067
14.00,9.43,0.067
14.03,9.57,0.068
14.05,9.71,0.068
14.08,9.86,0.068
14.11,10.00,0.067
14.14,10.14,0.067
14.17,10.28,0.067
14.20,10.42,0.068
14.22,10.57,0.068
14.25,10.71,0.068
14.28,10.85,0.068
14.31,10.99,0.068
14.34,11.13,0.068
14.37,11.27,0.068
14.39,11.42,0.068
14.42,11.56,0.068
14.45,11.70,0.068
14.48,11.84,0.068
14.51,11.98,0.068
14.53,12.12,0.068
14.56,12.27,0.068
14.59,12.41,0.068
14.62,12.55,0.068
14.65,12.69,0.068
14.68,12.84,0.068
14.70,12.98,0.068
14.73,13.12,0.068
14.76,13.26,0.068
14.79,13.40,0.069
14.82,13.54,0.069
14.85,13.68,0.069
14.88,13.83,0.069
14.90,13.97,0.069
14.93,14.11,0.069
14.96,14.25,0.069
14.99,14.39,0.069
15.02,14.54,0.069
15.05,14.68,0.069
15.07,14.82,0.069
15.10,14.96,0.069
15.13,15.10,0.069
15.16,15.24,0.069
15.19,15.39,0.069
15.22,15.53,0.069
15.24,15.67,0.069
15.27,15.81,0.069
15.30,15.95,0.069
15.33,16.10,0.069
15.36,16.24,0.070
15.38,16.38,0.070
15.41,16.52,0.070
15.44,16.66,0.070
15.47,16.80,0.070
15.50,16.95,0.070
15.53,17.09,0.070
15.55,17.23,0.070
15.58,17.37,0.070
15.61,17.51,0.070
15.64,17.65,0.070
15.67,17.79,0.070
15.70,17.94,0.070
15.73,18.08,0.070
15.75,18.22,0.070
15.78,18.36,0.070
15.81,18.50,0.070
15.84,18.64,0.070
15.87,18.79,0.070
15.90,18.93,0.070
15.92,19.07,0.070
15.95,19.21,0.070
15.98,19.36,0.070
16.01,19.50,0.070
16.04,19.64,0.070
16.07,19.78,0.070
16.09,19.92,0.070
16.12,20.06,0.071
16.15,20.21,0.071
16.18,20.35,0.071
16.21,20.49,0.071
16.23,20.63,0.071
16.26,20.77,0.071
16.29,20.91,0.071
16.32,21.05,0.071
16.35,21.20,0.071
16.38,21.34,0.071
16.40,21.48,0.071
16.43,21.62,0.071
16.46,21.76,0.071
16.49,21.91,0.071
16.52,22.05,0.071
16.55,22.19,0.071
16.58,22.33,0.071
16.60,22.47,0.072
16.63,22.61,0.072
16.66,22.76,0.072
16.69,22.90,0.072
16.72,23.04,0.072
16.75,23.18,0.072
16.77,23.32,0.072
16.80,23.47,0.072
16.83,23.61,0.072
16.86,23.75,0.072
16.89,23.89,0.072
16.92,24.03,0.072
16.94,24.17,0.072
16.97,24.32,0.072
17.00,24.46,0.072
17.03,24.60,0.072
17.06,24.74,0.073
17.08,24.88,0.073
17.11,25.03,0.073
17.14,25.17,0.073
17.17,25.31,0.073
17.20,25.45,0.073
17.23,25.59,0.073
17.26,25.73,0.073
17.28,25.88,0.073
17.31,26.02,0.073
17.34,26.16,0.073
17.37,26.30,0.073
17.40,26.44,0.073
17.43,26.58,0.073
17.45,26.73,0.073
17.48,26.87,0.073
17.51,27.01,0.073
17.54,27.15,0.074
17.57,27.29,0.074
17.59,27.43,0.074
17.62,27.58,0.074
17.65,27.72,0.074
17.68,27.86,0.074
17.71,28.00,0.074
17.74,28.14,0.074
17.77,28.28,0.074
17.79,28.43,0.074
17.82,28.57,0.074
17.85,28.71,0.074
17.88,28.85,0.074
17.91,28.99,0.074
17.93,29.13,0.075
17.96,29.28,0.075
17.99,29.42,0.075
18.02,29.56,0.075
18.05,29.70,0.075
18.08,29.84,0.075
18.11,29.98,0.075
18.13,30.13,0.075
18.16,30.27,0.075
18.19,30.41,0.075
18.22,30.55,0.075
18.25,30.69,0.075
18.28,30.84,0.076
18.30,30.98,0.076
18.33,31.12,0.076
18.36,31.26,0.076
18.39,31.40,0.076
18.42,31.54,0.076
18.44,31.69,0.076
18.47,31.83,0.076
18.50,31.97,0.077
18.53,32.11,0.077
18.56,32.25,0.077
18.59,32.39,0.077
18.62,32.54,0.077
18.64,32.68,0.077
18.67,32.82,0.077
18.70,32.96,0.077
18.73,33.10,0.078
18.76,33.25,0.078
18.78,33.39,0.078
18.81,33.53,0.078
18.84,33.67,0.078
18.87,33.81,0.078
18.90,33.95,0.078
18.93,34.10,0.079
18.96,34.24,0.079
18.98,34.38,0.079
19.01,34.52,0.079
19.04,34.66,0.079
19.07,34.80,0.079
19.10,34.95,0.079
19.13,35.09,0.079
19.15,35.23,0.079
19.18,35.37,0.080
19.21,35.51,0.080
19.24,35.65,0.080
19.27,35.80,0.080
19.29,35.94,0.080
19.32,36.08,0.080
19.35,36.22,0.080
19.38,36.36,0.080
19.41,36.51,0.080
19.44,36.65,0.080
19.47,36.79,0.081
19.49,36.93,0.081
19.52,37.07,0.081
19.55,37.21,0.081
19.58,37.36,0.081
19.61,37.50,0.081
19.63,37.64,0.081
19.66,37.78,0.081
19.69,37.92,0.082
19.72,38.06,0.082
19.75,38.21,0.082
19.78,38.35,0.082
19.81,38.49,0.082
19.83,38.63,0.082
19.86,38.77,0.082
19.89,38.91,0.083
19.92,39.06,0.083
19.95,39.20,0.083
19.98,39.34,0.083
20.00,39.48,0.083
20.03,39.62,0.083
20.06,39.76,0.083
20.09,39.91,0.084
20.12,40.05,0.084
20.14,40.19,0.084
20.17,40.33,0.084
20.20,40.47,0.084
20.23,40.61,0.084
20.26,40.76,0.085
20.29,40.90,0.085
20.32,41.04,0.085
20.34,41.18,0.085
20.37,41.32,0.085
20.40,41.46,0.086
20.43,41.61,0.086
20.46,41.75,0.086
20.48,41.89,0.086
20.51,42.03,0.087
20.54,42.17,0.087
20.57,42.31,0.087
20.60,42.46,0.088
20.63,42.60,0.088
20.66,42.74,0.088
20.68,42.88,0.088
20.71,43.02,0.089
20.74,43.16,0.089
20.77,43.31,0.090
20.80,43.45,0.090
20.83,43.59,0.090
20.85,43.73,0.091
20.88,43.87,0.091
20.91,44.01,0.092
20.94,44.15,0.092
20.97,44.30,0.092
20.99,44.44,0.093
21.02,44.58,0.093
21.05,44.72,0.094
21.08,44.86,0.094
21.11,45.00,0.095
21.14,45.15,0.095
21.17,45.29,0.096
21.19,45.43,0.097
21.22,45.57,0.097
21.25,45.71,0.098
21.28,45.85,0.098
21.31,45.99,0.099
21.33,46.14,0.100
21.36,46.28,0.101
21.39,46.42,0.102
21.42,46.56,0.103
21.45,46.70,0.105
21.48,46.84,0.106
21.51,46.98,0.107
21.53,47.12,0.108
21.56,47.27,0.110
21.59,47.41,0.112
21.62,47.55,0.113
21.65,47.69,0.116
21.68,47.83,0.118
21.70,47.97,0.121
21.73,48.11,0.122
21.76,48.25,0.127
21.79,48.39,0.129
21.82,48.53,0.131
21.84,48.67,0.136
21.87,48.82,0.140
21.90,48.96,0.143
21.93,49.10,0.147
21.96,49.24,0.153
21.99,49.38,0.158
22.02,49.52,0.161
22.04,49.66,0.167
22.07,49.80,0.172
22.10,49.94,0.180
22.13,50.08,0.185
22.16,50.21,0.194
22.18,50.35,0.201
22.21,50.49,0.210
22.24,50.63,0.220
22.27,50.77,0.232
22.30,50.91,0.243
22.33,51.04,0.256
22.36,51.18,0.269
22.38,51.32,0.284
22.41,51.45,0.300
22.44,51.59,0.318
22.47,51.72,0.338
22.50,51.86,0.360
22.53,51.99,0.385
22.55,52.12,0.413
22.58,52.25,0.450
22.61,52.38,0.509
22.64,52.50,0.604
22.67,52.61,0.727
22.69,52.71,0.858
22.72,52.81,0.909
22.75,52.92,1.052
22.78,53.02,1.094
22.81,53.14,1.093
22.84,53.26,1.178
22.87,53.36,1.356
22.89,53.46,1.513
22.92,53.54,1.636
22.95,53.66,1.552
22.98,53.79,1.570
23.01,53.91,1.640
23.03,54.04,1.595
23.06,54.19,1.581
23.09,54.34,1.508
23.12,54.49,1.471
23.15,54.65,1.430
23.18,54.80,1.424
23.21,54.93,1.566
23.23,55.06,1.534
23.26,55.21,1.481
23.29,55.35,1.494
23.32,55.50,1.414
23.35,55.68,1.180
23.38,55.90,0.807
23.40,56.13,0.627
23.43,56.35,0.511
23.46,56.55,0.427
23.49,56.74,0.359
23.52,56.92,0.306
23.54,57.08,0.264
23.57,57.25,0.230
23.60,57.41,0.203
23.63,57.57,0.183
23.66,57.72,0.166
23.69,57.87,0.155
23.72,58.02,0.144
23.74,58.17,0.136
23.77,58.31,0.129
23.80,58.46,0.125
23.83,58.60,0.121
23.86,58.75,0.119
23.88,58.89,0.117
23.91,59.03,0.115
23.94,59.17,0.114
23.97,59.32,0.112
24.00,59.46,0.111
24.03,59.60,0.111
24.06,59.74,0.110
24.08,59.89,0.110
24.11,60.03,0.109
24.14,60.17,0.109
24.17,60.31,0.109
24.20,60.45,0.108
24.23,60.59,0.108
24.25,60.74,0.108
24.28,60.88,0.108
24.31,61.02,0.107
24.34,61.16,0.107
24.37,61.30,0.107
24.39,61.44,0.107
24.42,61.59,0.107
24.45,61.73,0.107
24.48,61.87,0.107
24.51,62.01,0.106
24.54,62.16,0.106
24.57,62.30,0.106
24.59,62.44,0.106
24.62,62.58,0.106
24.65,62.72,0.106
24.68,62.86,0.106
24.71,63.01,0.106
24.73,63.15,0.106
24.76,63.29,0.106
24.79,63.43,0.106
24.82,63.57,0.106
24.85,63.71,0.106
24.88,63.85,0.106
24.91,64.00,0.106
24.93,64.14,0.106
24.96,64.28,0.106
24.99,64.42,0.106
25.02,64.56,0.106
25.05,64.71,0.106
25.08,64.85,0.106
25.10,64.99,0.106
25.13,65.13,0.106
25.16,65.27,0.107
25.19,65.41,0.107
25.22,65.56,0.107
25.24,65.70,0.107
25.27,65.84,0.107
25.30,65.98,0.107
25.33,66.12,0.107
25.36,66.26,0.107
25.39,66.41,0.107
25.42,66.55,0.107
25.44,66.69,0.107
25.47,66.83,0.107
25.50,66.97,0.107
25.53,67.12,0.107
25.56,67.26,0.107
25.58,67.40,0.107
25.61,67.54,0.107
25.64,67.68,0.107
25.67,67.82,0.107
25.70,67.97,0.107
25.73,68.11,0.107
25.76,68.25,0.107
25.78,68.39,0.107
25.81,68.53,0.107
25.84,68.68,0.108
25.87,68.82,0.108
25.90,68.96,0.108
25.93,69.10,0.108
25.95,69.24,0.108
25.98,69.38,0.108
26.01,69.53,0.108
26.04,69.67,0.108
26.07,69.81,0.108
26.09,69.95,0.108
26.12,70.09,0.108
26.15,70.23,0.108
26.18,70.38,0.108
26.21,70.52,0.108
26.24,70.66,0.108
26.27,70.80,0.108
26.29,70.94,0.109
26.32,71.08,0.109
26.35,71.22,0.109
26.38,71.37,0.109
26.41,71.51,0.109
26.43,71.65,0.109
26.46,71.79,0.109
26.49,71.93,0.109
26.52,72.08,0.109
26.55,72.22,0.109
26.58,72.36,0.110
26.61,72.50,0.110
26.63,72.64,0.110
26.66,72.78,0.110
26.69,72.93,0.110
26.72,73.07,0.110
26.75,73.21,0.110
26.78,73.35,0.111
26.80,73.49,0.112
26.83,73.63,0.112
26.86,73.77,0.112
26.89,73.92,0.112
26.92,74.06,0.112
26.94,74.20,0.113
26.97,74.34,0.113
27.00,74.48,0.113
27.03,74.63,0.113
27.06,74.77,0.113
27.09,74.91,0.113
27.12,75.05,0.113
27.14,75.19,0.113
27.17,75.33,0.113
27.20,75.48,0.113
27.23,75.62,0.113
27.26,75.76,0.113
27.28,75.90,0.113
27.31,76.04,0.113
27.34,76.19,0.113
27.37,76.33,0.113
27.40,76.47,0.113
27.43,76.61,0.113
27.46,76.75,0.113
27.48,76.89,0.113
27.51,77.04,0.113
27.54,77.18,0.113
27.57,77.32,0.113
27.60,77.46,0.113
27.63,77.60,0.113
27.65,77.74,0.113
27.68,77.89,0.113
27.71,78.03,0.113
27.74,78.17,0.113
27.77,78.31,0.113
27.79,78.45,0.113
27.82,78.60,0.113
27.85,78.74,0.113
27.88,78.88,0.113
27.91,79.02,0.113
27.94,79.16,0.113
27.97,79.30,0.113
27.99,79.45,0.113
28.02,79.59,0.113
28.05,79.73,0.113
28.08,79.87,0.113
28.11,80.01,0.113
28.13,80.15,0.113
28.16,80.30,0.113
28.19,80.44,0.113
28.22,80.58,0.113
28.25,80.72,0.114
28.28,80.86,0.114
28.31,81.01,0.114
28.33,81.15,0.114
28.36,81.29,0.114
28.39,81.43,0.114
28.42,81.57,0.114
28.45,81.71,0.114
28.48,81.85,0.114
28.50,82.00,0.114
28.53,82.14,0.114
28.56,82.28,0.114
28.59,82.42,0.114
28.62,82.56,0.114
28.64,82.71,0.114
28.67,82.85,0.114
28.70,82.99,0.114
28.73,83.13,0.114
28.76,83.27,0.114
28.79,83.41,0.114
28.82,83.56,0.114
28.84,83.70,0.114
28.87,83.84,0.114
28.90,83.98,0.114
28.93,84.12,0.114
28.96,84.27,0.114
28.98,84.41,0.114
29.01,84.55,0.114
29.04,84.69,0.114
29.07,84.83,0.114
29.10,84.97,0.114
29.13,85.12,0.114
29.16,85.26,0.114
29.18,85.40,0.114
29.21,85.54,0.115
29.24,85.68,0.115
29.27,85.82,0.115
29.30,85.96,0.115
29.33,86.11,0.115
29.35,86.25,0.115
29.38,86.39,0.115
29.41,86.53,0.115
29.44,86.67,0.115
29.47,86.82,0.115
29.49,86.96,0.115
29.52,87.10,0.115
29.55,87.24,0.115
29.58,87.39,0.115
29.61,87.53,0.115
29.64,87.67,0.115
29.67,87.81,0.115
29.69,87.95,0.115
29.72,88.09,0.115
29.75,88.23,0.115
29.78,88.38,0.115
29.81,88.52,0.115
29.83,88.66,0.115
29.86,88.80,0.115
29.89,88.94,0.115
29.92,89.08,0.115
29.95,89.23,0.115
29.98,89.37,0.116
30.01,89.51,0.116
30.03,89.65,0.116
30.06,89.79,0.116
30.09,89.93,0.116
30.12,90.08,0.116
30.15,90.22,0.116
30.18,90.36,0.116
30.20,90.50,0.116
30.23,90.64,0.116
30.26,90.78,0.116
30.29,90.93,0.116
30.32,91.07,0.116
30.34,91.21,0.116
30.37,91.35,0.116
30.40,91.49,0.116
30.43,91.63,0.116
30.46,91.78,0.116
30.49,91.92,0.116
30.52,92.06,0.116
30.54,92.20,0.116
30.57,92.34,0.116
30.60,92.48,0.116
30.63,92.63,0.117
30.66,92.77,0.117
30.68,92.91,0.117
30.71,93.05,0.117
30.74,93.20,0.117
30.77,93.34,0.117
30.80,93.48,0.117
30.83,93.62,0.117
30.86,93.76,0.117
30.88,93.90,0.117
30.91,94.04,0.117
30.94,94.19,0.117
30.97,94.33,0.117
31.00,94.47,0.117
31.03,94.61,0.117
31.05,94.75,0.117
31.08,94.89,0.117
31.11,95.03,0.117
31.14,95.18,0.117
31.17,95.32,0.117
31.19,95.46,0.117
31.22,95.60,0.117
31.25,95.75,0.118
31.28,95.89,0.118
31.31,96.03,0.118
31.34,96.17,0.118
31.37,96.31,0.118
31.39,96.45,0.118
31.42,96.59,0.118
31.45,96.74,0.118
31.48,96.88,0.118
31.51,97.02,0.118
31.53,97.16,0.118
31.56,97.30,0.118
31.59,97.45,0.118
31.62,97.59,0.118
31.65,97.73,0.118
31.68,97.87,0.118
31.71,98.01,0.118
31.73,98.16,0.118
31.76,98.30,0.118
31.79,98.44,0.119
31.82,98.58,0.119
31.85,98.72,0.119
31.88,98.86,0.119
31.90,99.00,0.119
31.93,99.15,0.119
31.96,99.29,0.119
31.99,99.43,0.119
32.02,99.57,0.119
32.04,99.71,0.119
32.07,99.85,0.119
32.10,100.00,0.119
32.13,100.14,0.119
32.16,100.28,0.119
32.19,100.42,0.119
32.22,100.56,0.119
32.24,100.70,0.119
32.27,100.85,0.119
32.30,100.99,0.119
32.33,101.13,0.119
32.36,101.27,0.119
32.38,101.42,0.119
32.41,101.56,0.120
32.44,101.70,0.120
32.47,101.84,0.120
32.50,101.98,0.120
32.53,102.12,0.120
32.56,102.27,0.120
32.58,102.41,0.120
32.61,102.55,0.120
32.64,102.69,0.120
32.67,102.83,0.120
32.70,102.97,0.120
32.73,103.12,0.120
32.75,103.26,0.121
32.78,103.40,0.121
32.81,103.54,0.121
32.84,103.68,0.121
32.87,103.82,0.121
32.89,103.96,0.121
32.92,104.11,0.121
32.95,104.25,0.121
32.98,104.39,0.121
33.01,104.53,0.121
33.04,104.67,0.121
33.07,104.81,0.121
33.09,104.96,0.121
33.12,105.10,0.121
33.15,105.24,0.121
33.18,105.38,0.121
33.21,105.52,0.121
33.23,105.67,0.121
33.26,105.81,0.121
33.29,105.95,0.121
33.32,106.09,0.121
33.35,106.23,0.121
33.38,106.37,0.121
33.41,106.52,0.122
33.43,106.66,0.122
33.46,106.80,0.122
33.49,106.94,0.122
33.52,107.08,0.122
33.55,107.22,0.122
33.58,107.37,0.122
33.60,107.51,0.122
33.63,107.65,0.122
33.66,107.79,0.122
33.69,107.93,0.122
33.72,108.07,0.122
33.74,108.22,0.122
33.77,108.36,0.122
33.80,108.50,0.122
33.83,108.64,0.122
33.86,108.78,0.122
33.89,108.92,0.122
33.92,109.07,0.122
33.94,109.21,0.122
33.97,109.35,0.122
34.00,109.49,0.122
34.03,109.63,0.122
34.06,109.77,0.122
34.08,109.92,0.122
34.11,110.06,0.122
34.14,110.20,0.122
34.17,110.34,0.122
34.20,110.48,0.122
34.23,110.63,0.122
34.26,110.77,0.122
34.28,110.91,0.122
34.31,111.05,0.123
34.34,111.19,0.123
34.37,111.34,0.123
34.40,111.48,0.123
34.43,111.62,0.123
34.45,111.76,0.123
34.48,111.90,0.123
34.51,112.04,0.123
34.54,112.18,0.123
34.57,112.32,0.123
34.59,112.47,0.123
34.62,112.61,0.123
34.65,112.75,0.123
34.68,112.89,0.123
34.71,113.03,0.123
34.74,113.18,0.123
34.76,113.32,0.123
34.79,113.46,0.123
34.82,113.60,0.123
34.85,113.74,0.123
34.88,113.89,0.123
34.91,114.03,0.123
34.94,114.17,0.123
34.96,114.31,0.123
34.99,114.45,0.124
35.02,114.59,0.124
35.05,114.73,0.124
35.08,114.88,0.124
35.11,115.02,0.124
35.13,115.16,0.124
35.16,115.30,0.124
35.19,115.44,0.124
35.22,115.58,0.124
35.25,115.73,0.124
35.28,115.87,0.124
35.30,116.01,0.124
35.33,116.15,0.124
35.36,116.29,0.124
35.39,116.43,0.124
35.42,116.58,0.124
35.44,116.72,0.124
35.47,116.86,0.124
35.50,117.00,0.124
35.53,117.14,0.124
35.56,117.29,0.124
35.59,117.43,0.124
35.61,117.57,0.124
35.64,117.71,0.124
35.67,117.85,0.124
35.70,118.00,0.124
35.73,118.14,0.124
35.76,118.28,0.124
35.79,118.42,0.124
35.81,118.56,0.124
35.84,118.70,0.124
35.87,118.84,0.125
35.90,118.99,0.125
35.93,119.13,0.125
35.96,119.27,0.125
35.98,119.41,0.125
36.01,119.55,0.125
36.04,119.69,0.125
36.07,119.84,0.125
36.10,119.98,0.125
36.13,120.12,0.125
36.15,120.26,0.125
36.18,120.40,0.125
36.21,120.55,0.125
36.24,120.69,0.125
36.27,120.83,0.125
36.29,120.97,0.125
36.32,121.11,0.125
36.35,121.25,0.125
36.38,121.40,0.125
36.41,121.54,0.125
36.44,121.68,0.125
36.46,121.82,0.125
36.49,121.96,0.125
36.52,122.10,0.125
36.55,122.24,0.125
36.58,122.39,0.125
36.61,122.53,0.125
36.64,122.67,0.125
36.66,122.81,0.125
36.69,122.95,0.125
36.72,123.10,0.125
36.75,123.24,0.126
36.78,123.38,0.126
36.81,123.52,0.126
36.83,123.66,0.125
36.86,123.80,0.126
36.89,123.95,0.126
36.92,124.09,0.126
36.95,124.23,0.126
36.98,124.37,0.126
37.00,124.51,0.126
37.03,124.66,0.126
37.06,124.80,0.126
37.09,124.94,0.126
37.12,125.08,0.126
37.14,125.22,0.126
37.17,125.36,0.126
37.20,125.50,0.126
37.23,125.65,0.126
37.26,125.79,0.126
37.29,125.93,0.126
37.31,126.07,0.126
37.34,126.21,0.126
37.37,126.36,0.126
37.40,126.50,0.126
37.43,126.64,0.126
37.46,126.78,0.126
37.49,126.92,0.126
37.51,127.07,0.126
37.54,127.21,0.127
37.57,127.35,0.127
37.60,127.49,0.127
37.63,127.63,0.127
37.66,127.77,0.127
37.68,127.91,0.127
37.71,128.06,0.127
37.74,128.20,0.127
37.77,128.34,0.127
37.80,128.48,0.127
37.83,128.62,0.127
37.85,128.76,0.127
37.88,128.91,0.127
37.91,129.05,0.127
37.94,129.19,0.127
37.97,129.33,0.127
37.99,129.47,0.127
38.02,129.61,0.127
38.05,129.76,0.127
38.08,129.90,0.127
38.11,130.04,0.127
38.14,130.18,0.127
38.16,130.32,0.127
38.19,130.46,0.127
38.22,130.61,0.127
38.25,130.75,0.127
38.28,130.89,0.128
38.31,131.03,0.128
38.34,131.17,0.128
38.36,131.31,0.128
38.39,131.46,0.128
38.42,131.60,0.128
38.45,131.74,0.128
38.48,131.88,0.128
38.51,132.02,0.128
38.53,132.16,0.128
38.56,132.31,0.128
38.59,132.45,0.128
38.62,132.59,0.128
38.65,132.73,0.128
38.68,132.87,0.128
38.70,133.01,0.128
38.73,133.16,0.128
38.76,133.30,0.128
38.79,133.44,0.128
38.82,133.58,0.128
38.84,133.73,0.128
38.87,133.87,0.128
38.90,134.01,0.128
38.93,134.15,0.128
38.96,134.29,0.129
38.99,134.43,0.129
39.01,134.58,0.129
39.04,134.72,0.128
39.07,134.86,0.129
39.10,135.00,0.129
39.13,135.14,0.129
39.16,135.28,0.129
39.19,135.43,0.129
39.21,135.57,0.129
39.24,135.71,0.129
39.27,135.85,0.129
39.30,135.99,0.129
39.33,136.13,0.129
39.36,136.28,0.129
39.38,136.42,0.129
39.41,136.56,0.129
39.44,136.70,0.129
39.47,136.84,0.129
39.50,136.98,0.129
39.53,137.13,0.129
39.55,137.27,0.129
39.58,137.41,0.129
39.61,137.55,0.129
39.64,137.69,0.129
39.67,137.83,0.129
39.69,137.98,0.129
39.72,138.12,0.129
39.75,138.26,0.129
39.78,138.40,0.129
39.81,138.54,0.129
39.84,138.68,0.129
39.86,138.83,0.129
39.89,138.97,0.129
39.92,139.11,0.129
39.95,139.25,0.129
39.98,139.39,0.129
40.01,139.54,0.129
40.04,139.68,0.129
40.06,139.82,0.129
40.09,139.96,0.129
40.12,140.10,0.129
40.15,140.24,0.129
40.18,140.39,0.129
40.21,140.53,0.129
40.23,140.67,0.129
40.26,140.81,0.129
40.29,140.95,0.129
40.32,141.09,0.129
40.35,141.24,0.129
40.38,141.38,0.130
40.40,141.52,0.130
40.43,141.66,0.130
40.46,141.80,0.129
40.49,141.94,0.129
40.52,142.08,0.129
40.54,142.23,0.129
40.57,142.37,0.130
40.60,142.51,0.130
40.63,142.65,0.130
40.66,142.79,0.130
40.69,142.94,0.130
40.71,143.08,0.130
40.74,143.22,0.130
40.77,143.36,0.130
40.80,143.50,0.130
40.83,143.64,0.130
40.86,143.79,0.130
40.89,143.93,0.130
40.91,144.07,0.130
40.94,144.21,0.130
40.97,144.35,0.130
41.00,144.49,0.130
41.03,144.63,0.130
41.06,144.78,0.130
41.08,144.92,0.130
41.11,145.06,0.130
41.14,145.20,0.130
41.17,145.34,0.130
41.20,145.49,0.130
41.23,145.63,0.130
41.25,145.77,0.130
41.28,145.91,0.130
41.31,146.05,0.130
41.34,146.19,0.130
41.37,146.34,0.130
41.39,146.48,0.130
41.42,146.62,0.130
41.45,146.76,0.130
41.48,146.90,0.130
41.51,147.05,0.130
41.54,147.19,0.130
41.56,147.33,0.130
41.59,147.47,0.130
41.62,147.61,0.130
41.65,147.75,0.130
41.68,147.90,0.130
41.71,148.04,0.130
41.74,148.18,0.131
41.76,148.32,0.131
41.79,148.46,0.131
41.82,148.60,0.131
41.85,148.75,0.131
41.88,148.89,0.131
41.91,149.03,0.131
41.93,149.17,
41.96,149.31,
41.99,,

[step]
Ramp 5.00 °C/min to -60.00 °C
Time,Temperature,Heat Flow (Normalized)
min,°C,W/g
42.99,150.12,-0.029
43.01,150.12,-0.029
43.04,150.11,-0.023
43.07,150.08,0.006
43.10,150.02,0.021
43.13,149.94,0.012
43.16,149.85,-0.026
43.19,149.74,-0.064
43.21,149.62,-0.093
43.24,149.51,-0.116
43.27,149.38,-0.129
43.30,149.25,-0.141
43.33,149.12,-0.152
43.36,148.99,-0.160
43.38,148.86,-0.165
43.41,148.72,-0.169
43.44,148.59,-0.173
43.47,148.45,-0.176
43.50,148.31,-0.177
43.53,148.17,-0.180
43.55,148.03,-0.181
43.58,147.90,-0.181
43.61,147.75,-0.182
43.64,147.62,-0.183
43.67,147.48,-0.183
43.69,147.34,-0.184
43.72,147.20,-0.184
43.75,147.06,-0.185
43.78,146.92,-0.185
43.81,146.77,-0.185
43.84,146.64,-0.186
43.86,146.49,-0.186
43.89,146.35,-0.186
43.92,146.21,-0.187
43.95,146.07,-0.187
43.98,145.93,-0.187
44.01,145.79,-0.187
44.04,145.65,-0.187
44.06,145.51,-0.188
44.09,145.37,-0.188
44.12,145.23,-0.188
44.15,145.09,-0.188
44.18,144.94,-0.188
44.21,144.80,-0.188
44.23,144.66,-0.188
44.26,144.52,-0.188
44.29,144.38,-0.188
44.32,144.24,-0.189
44.35,144.10,-0.189
44.38,143.96,-0.189
44.40,143.82,-0.189
44.43,143.67,-0.189
44.46,143.53,-0.189
44.49,143.39,-0.189
44.52,143.25,-0.189
44.54,143.11,-0.189
44.57,142.97,-0.189
44.60,142.82,-0.189
44.63,142.68,-0.189
44.66,142.54,-0.189
44.69,142.40,-0.189
44.71,142.26,-0.189
44.74,142.12,-0.189
44.77,141.98,-0.189
44.80,141.84,-0.188
44.83,141.69,-0.188
44.86,141.55,-0.188
44.89,141.41,-0.188
44.91,141.27,-0.188
44.94,141.13,-0.188
44.97,140.99,-0.188
45.00,140.84,-0.188
45.03,140.70,-0.188
45.06,140.56,-0.188
45.08,140.42,-0.188
45.11,140.28,-0.188
45.14,140.14,-0.188
45.17,140.00,-0.188
45.20,139.85,-0.188
45.23,139.71,-0.188
45.25,139.57,-0.188
45.28,139.43,-0.187
45.31,139.29,-0.187
45.34,139.14,-0.187
45.37,139.00,-0.187
45.39,138.86,-0.187
45.42,138.72,-0.187
45.45,138.58,-0.187
45.48,138.44,-0.187
45.51,138.30,-0.187
45.54,138.15,-0.187
45.56,138.01,-0.187
45.59,137.87,-0.187
45.62,137.73,-0.187
45.65,137.59,-0.187
45.68,137.45,-0.186
45.71,137.31,-0.186
45.74,137.16,-0.186
45.76,137.02,-0.186
45.79,136.88,-0.186
45.82,136.74,-0.186
45.85,136.60,-0.186
45.88,136.46,-0.186
45.91,136.31,-0.186
45.93,136.17,-0.186
45.96,136.03,-0.186
45.99,135.89,-0.186
46.02,135.75,-0.186
46.05,135.61,-0.186
46.08,135.47,-0.186
46.10,135.32,-0.186
46.13,135.18,-0.186
46.16,135.04,-0.186
46.19,134.90,-0.186
46.22,134.76,-0.186
46.24,134.61,-0.186
46.27,134.47,-0.186
46.30,134.33,-0.186
46.33,134.19,-0.185
46.36,134.05,-0.185
46.39,133.91,-0.185
46.41,133.77,-0.185
46.44,133.63,-0.185
46.47,133.48,-0.185
46.50,133.34,-0.185
46.53,133.20,-0.185
46.56,133.06,-0.185
46.59,132.92,-0.185
46.61,132.78,-0.185
46.64,132.63,-0.185
46.67,132.49,-0.185
46.70,132.35,-0.185
46.73,132.21,-0.185
46.76,132.07,-0.185
46.78,131.92,-0.185
46.81,131.78,-0.185
46.84,131.64,-0.185
46.87,131.50,-0.185
46.90,131.36,-0.185
46.93,131.22,-0.185
46.95,131.08,-0.185
46.98,130.93,-0.184
47.01,130.79,-0.184
47.04,130.65,-0.184
47.07,130.51,-0.184
47.09,130.37,-0.184
47.12,130.23,-0.184
47.15,130.08,-0.184
47.18,129.94,-0.184
47.21,129.80,-0.184
47.24,129.66,-0.184
47.26,129.52,-0.184
47.29,129.38,-0.184
47.32,129.24,-0.184
47.35,129.10,-0.184
47.38,128.95,-0.183
47.41,128.81,-0.183
47.44,128.67,-0.183
47.46,128.53,-0.183
47.49,128.39,-0.183
47.52,128.25,-0.183
47.55,128.10,-0.183
47.58,127.96,-0.183
47.61,127.82,-0.183
47.63,127.68,-0.183
47.66,127.54,-0.183
47.69,127.40,-0.183
47.72,127.25,-0.183
47.75,127.11,-0.183
47.78,126.97,-0.183
47.80,126.83,-0.183
47.83,126.69,-0.183
47.86,126.55,-0.183
47.89,126.41,-0.183
47.92,126.26,-0.183
47.94,126.12,-0.183
47.97,125.98,-0.183
48.00,125.84,-0.183
48.03,125.70,-0.183
48.06,125.55,-0.183
48.09,125.41,-0.183
48.11,125.27,-0.183
48.14,125.13,-0.183
48.17,124.99,-0.183
48.20,124.85,-0.183
48.23,124.70,-0.183
48.26,124.56,-0.183
48.29,124.42,-0.183
48.31,124.28,-0.183
48.34,124.14,-0.183
48.37,124.00,-0.183
48.40,123.86,-0.182
48.43,123.72,-0.182
48.46,123.57,-0.182
48.48,123.43,-0.182
48.51,123.29,-0.182
48.54,123.15,-0.182
48.57,123.01,-0.182
48.60,122.86,-0.182
48.63,122.72,-0.182
48.65,122.58,-0.182
48.68,122.44,-0.182
48.71,122.30,-0.182
48.74,122.16,-0.182
48.77,122.02,-0.182
48.79,121.88,-0.182
48.82,121.73,-0.182
48.85,121.59,-0.182
48.88,121.45,-0.182
48.91,121.31,-0.182
48.94,121.16,-0.182
48.96,121.02,-0.182
48.99,120.88,-0.182
49.02,120.74,-0.182
49.05,120.60,-0.182
49.08,120.46,-0.182
49.11,120.32,-0.182
49.14,120.17,-0.182
49.16,120.03,-0.182
49.19,119.89,-0.182
49.22,119.75,-0.182
49.25,119.61,-0.181
49.28,119.47,-0.181
49.31,119.33,-0.181
49.33,119.18,-0.181
49.36,119.04,-0.181
49.39,118.90,-0.181
49.42,118.76,-0.181
49.45,118.62,-0.181
49.48,118.48,-0.181
49.50,118.33,-0.181
49.53,118.19,-0.181
49.56,118.05,-0.181
49.59,117.91,-0.181
49.62,117.77,-0.181
49.64,117.63,-0.181
49.67,117.48,-0.181
49.70,117.34,-0.181
49.73,117.20,-0.181
49.76,117.06,-0.181
49.79,116.92,-0.181
49.81,116.78,-0.181
49.84,116.64,-0.181
49.87,116.49,-0.181
49.90,116.35,-0.181
49.93,116.21,-0.181
49.96,116.07,-0.180
49.99,115.93,-0.180
50.01,115.78,-0.180
50.04,115.64,-0.180
50.07,115.50,-0.180
50.10,115.36,-0.181
50.13,115.22,-0.180
50.16,115.08,-0.180
50.18,114.94,-0.180
50.21,114.79,-0.180
50.24,114.65,-0.180
50.27,114.51,-0.180
50.30,114.37,-0.180
50.33,114.23,-0.180
50.35,114.09,-0.180
50.38,113.94,-0.180
50.41,113.80,-0.180
50.44,113.66,-0.180
50.47,113.52,-0.180
50.49,113.38,-0.180
50.52,113.24,-0.180
50.55,113.10,-0.180
50.58,112.95,-0.179
50.61,112.81,-0.179
50.64,112.67,-0.179
50.66,112.53,-0.179
50.69,112.39,-0.179
50.72,112.25,-0.179
50.75,112.11,-0.179
50.78,111.96,-0.179
50.81,111.82,-0.179
50.84,111.68,-0.179
50.86,111.54,-0.179
50.89,111.40,-0.179
50.92,111.25,-0.179
50.95,111.11,-0.179
50.98,110.97,-0.179
51.01,110.83,-0.179
51.03,110.69,-0.179
51.06,110.55,-0.179
51.09,110.40,-0.179
51.12,110.26,-0.179
51.15,110.12,-0.179
51.18,109.98,-0.179
51.20,109.84,-0.179
51.23,109.70,-0.179
51.26,109.55,-0.179
51.29,109.41,-0.179
51.32,109.27,-0.179
51.34,109.13,-0.179
51.37,108.99,-0.179
51.40,108.85,-0.179
51.43,108.70,-0.179
51.46,108.56,-0.179
51.49,108.42,-0.179
51.51,108.28,-0.179
51.54,108.14,-0.179
51.57,108.00,-0.178
51.60,107.86,-0.178
51.63,107.71,-0.179
51.66,107.57,-0.179
51.69,107.43,-0.178
51.71,107.29,-0.178
51.74,107.15,-0.178
51.77,107.01,-0.178
51.80,106.86,-0.178
51.83,106.72,-0.178
51.86,106.58,-0.178
51.88,106.44,-0.178
51.91,106.30,-0.178
51.94,106.16,-0.178
51.97,106.02,-0.178
52.00,105.87,-0.178
52.03,105.73,-0.178
52.05,105.59,-0.178
52.08,105.45,-0.178
52.11,105.31,-0.178
52.14,105.17,-0.178
52.17,105.02,-0.178
52.19,104.88,-0.178
52.22,104.74,-0.178
52.25,104.60,-0.178
52.28,104.46,-0.178
52.31,104.32,-0.178
52.34,104.18,-0.178
52.36,104.03,-0.177
52.39,103.89,-0.177
52.42,103.75,-0.177
52.45,103.61,-0.177
52.48,103.47,-0.177
52.51,103.32,-0.177
52.54,103.18,-0.177
52.56,103.04,-0.177
[...]
184.68,2.77,0.077
184.71,2.91,0.077
184.74,3.06,0.077
184.77,3.20,0.077
184.80,3.34,0.077
184.82,3.48,0.077
184.85,3.62,0.077
184.88,3.77,0.077
184.91,3.91,0.077
184.94,4.05,0.077
184.97,4.19,0.077
184.99,4.33,0.077
185.02,4.48,0.077
185.05,4.62,0.077
185.08,4.76,0.077
185.11,4.90,0.077
185.13,5.04,0.078
185.16,5.18,0.078
185.19,5.33,0.078
185.22,5.47,0.078
185.25,5.61,0.078
185.28,5.75,0.078
185.30,5.89,0.078
185.33,6.04,0.078
185.36,6.18,0.078
185.39,6.32,0.078
185.42,6.46,0.078
185.45,6.60,0.078
185.48,6.75,0.078
185.50,6.89,0.078
185.53,7.03,0.078
185.56,7.17,0.078
185.59,7.31,0.078
185.62,7.45,0.078
185.65,7.59,0.078
185.67,7.74,0.078
185.70,7.88,0.078
185.73,8.02,0.078
185.76,8.16,0.078
185.79,8.30,0.078
185.82,8.44,0.078
185.84,8.58,0.078
185.87,8.73,0.078
185.90,8.87,0.078
185.93,9.01,0.079
185.96,9.15,0.079
185.98,9.29,0.079
186.01,9.44,0.079
186.04,9.58,0.079
186.07,9.72,0.079
186.10,9.86,0.079
186.13,10.00,0.079
186.15,10.15,0.079
186.18,10.29,0.079
186.21,10.43,0.079
186.24,10.57,0.079
186.27,10.71,0.079
186.30,10.85,0.079
186.33,11.00,0.079
186.35,11.14,0.079
186.38,11.28,0.079
186.41,11.42,0.079
186.44,11.56,0.079
186.47,11.71,0.079
186.50,11.85,0.079
186.52,11.99,0.079
186.55,12.13,0.079
186.58,12.27,0.079
186.61,12.41,0.079
186.64,12.56,0.079
186.67,12.70,0.080
186.69,12.84,0.080
186.72,12.98,0.080
186.75,13.12,0.080
186.78,13.26,0.080
186.81,13.41,0.080
186.83,13.55,0.080
186.86,13.69,0.080
186.89,13.83,0.080
186.92,13.97,0.080
186.95,14.11,0.080
186.98,14.26,0.080
187.00,14.40,0.080
187.03,14.54,0.081
187.06,14.68,0.081
187.09,14.82,0.081
187.12,14.96,0.081
187.15,15.11,0.081
187.18,15.25,0.081
187.20,15.39,0.081
187.23,15.53,0.081
187.26,15.67,0.081
187.29,15.82,0.081
187.32,15.96,0.081
187.35,16.10,0.081
187.37,16.24,0.081
187.40,16.38,0.081
187.43,16.52,0.082
187.46,16.67,0.082
187.49,16.81,0.082
187.52,16.95,0.082
187.54,17.09,0.082
187.57,17.23,0.082
187.60,17.38,0.082
187.63,17.52,0.082
187.66,17.66,0.082
187.68,17.80,0.082
187.71,17.94,0.083
187.74,18.08,0.083
187.77,18.22,0.083
187.80,18.37,0.083
187.83,18.51,0.083
187.85,18.65,0.083
187.88,18.79,0.083
187.91,18.94,0.083
187.94,19.08,0.083
187.97,19.22,0.083
188.00,19.36,0.083
188.03,19.50,0.084
188.05,19.64,0.084
188.08,19.79,0.084
188.11,19.93,0.084
188.14,20.07,0.084
188.17,20.21,0.084
188.20,20.35,0.084
188.22,20.49,0.084
188.25,20.64,0.085
188.28,20.78,0.085
188.31,20.92,0.085
188.34,21.06,0.085
188.37,21.20,0.085
188.39,21.34,0.085
188.42,21.49,0.085
188.45,21.63,0.086
188.48,21.77,0.086
188.51,21.91,0.086
188.53,22.05,0.086
188.56,22.19,0.087
188.59,22.34,0.087
188.62,22.48,0.087
188.65,22.62,0.087
188.68,22.76,0.088
188.70,22.90,0.088
188.73,23.04,0.088
188.76,23.19,0.089
188.79,23.33,0.089
188.82,23.47,0.089
188.85,23.61,0.089
188.88,23.75,0.090
188.90,23.89,0.090
188.93,24.03,0.090
188.96,24.18,0.091
188.99,24.32,0.091
189.02,24.46,0.091
189.05,24.60,0.092
189.07,24.74,0.092
189.10,24.88,0.093
189.13,25.02,0.093
189.16,25.17,0.093
189.19,25.31,0.094
189.22,25.45,0.095
189.24,25.59,0.095
189.27,25.73,0.095
189.30,25.87,0.096
189.33,26.02,0.096
189.36,26.16,0.097
189.38,26.30,0.098
189.41,26.44,0.099
189.44,26.58,0.100
189.47,26.72,0.100
189.50,26.87,0.101
189.53,27.01,0.103
189.55,27.15,0.104
189.58,27.29,0.105
189.61,27.43,0.106
189.64,27.57,0.107
189.67,27.71,0.108
189.70,27.85,0.110
189.73,28.00,0.112
189.75,28.14,0.115
189.78,28.28,0.117
189.81,28.42,0.119
189.84,28.56,0.122
189.87,28.70,0.125
189.90,28.84,0.128
189.92,28.98,0.132
189.95,29.12,0.134
189.98,29.26,0.138
190.01,29.40,0.142
190.04,29.54,0.148
190.07,29.68,0.152
190.09,29.82,0.156
190.12,29.96,0.163
190.15,30.10,0.168
190.18,30.24,0.175
190.21,30.38,0.183
190.23,30.52,0.189
190.26,30.66,0.198
190.29,30.80,0.209
190.32,30.94,0.217
190.35,31.07,0.229
190.38,31.21,0.241
190.40,31.35,0.255
190.43,31.48,0.268
190.46,31.62,0.286
190.49,31.76,0.303
190.52,31.89,0.326
190.55,32.02,0.349
190.58,32.16,0.374
190.60,32.29,0.402
190.63,32.42,0.433
190.66,32.55,0.466
190.69,32.68,0.501
190.72,32.80,0.538
190.75,32.93,0.578
190.77,33.06,0.620
190.80,33.18,0.659
190.83,33.31,0.699
190.86,33.43,0.735
190.89,33.56,0.764
190.92,33.69,0.788
190.94,33.82,0.806
190.97,33.95,0.815
191.00,34.09,0.818
191.03,34.23,0.816
191.06,34.37,0.810
191.08,34.51,0.805
191.11,34.65,0.800
191.14,34.80,0.798
191.17,34.94,0.797
191.20,35.08,0.797
191.23,35.22,0.797
191.25,35.37,0.790
191.28,35.51,0.770
191.31,35.66,0.743
191.34,35.81,0.703
191.37,35.97,0.647
191.40,36.13,0.574
191.43,36.30,0.482
191.45,36.47,0.371
191.48,36.65,0.245
191.51,36.84,0.111
191.54,37.04,-0.023
191.57,37.23,-0.157
191.60,37.43,-0.292
191.62,37.63,-0.437
191.65,37.83,-0.590
191.68,38.03,-0.762
191.71,38.24,-0.951
191.74,38.46,-1.152
191.77,38.67,-1.351
191.79,38.89,-1.521
191.82,39.11,-1.641
191.85,39.30,-1.693
191.88,39.48,-1.681
191.91,39.63,-1.616
191.93,39.76,-1.514
191.96,39.87,-1.387
191.99,39.98,-1.252
192.02,40.07,-1.113
192.05,40.16,-0.977
192.08,40.25,-0.849
192.10,40.34,-0.731
192.13,40.43,-0.625
192.16,40.53,-0.528
192.19,40.63,-0.442
192.22,40.73,-0.368
192.25,40.84,-0.303
192.28,40.95,-0.247
192.30,41.07,-0.198
192.33,41.19,-0.157
192.36,41.31,-0.122
192.39,41.43,-0.091
192.42,41.56,-0.064
192.45,41.69,-0.043
192.47,41.82,-0.024
192.50,41.95,-0.008
192.53,42.09,0.005
192.56,42.22,0.017
192.59,42.36,0.028
192.62,42.50,0.035
192.64,42.63,0.044
192.67,42.77,0.050
192.70,42.91,0.056
192.73,43.05,0.061
192.76,43.19,0.066
192.78,43.33,0.070
192.81,43.47,0.073
192.84,43.61,0.077
192.87,43.75,0.081
192.90,43.89,0.084
192.93,44.03,0.087
192.95,44.17,0.090
192.98,44.31,0.092
193.01,44.45,0.096
193.04,44.59,0.099
193.07,44.73,0.102
193.10,44.87,0.106
193.13,45.01,0.111
193.15,45.15,0.115
193.18,45.29,0.120
193.21,45.43,0.124
193.24,45.57,0.129
193.27,45.71,0.135
193.30,45.85,0.141
193.32,45.99,0.147
193.35,46.13,0.155
193.38,46.27,0.162
193.41,46.41,0.170
193.44,46.55,0.178
193.47,46.69,0.190
193.49,46.82,0.200
193.52,46.96,0.211
193.55,47.10,0.224
193.58,47.24,0.236
193.61,47.37,0.252
193.63,47.51,0.267
193.66,47.64,0.283
193.69,47.78,0.302
193.72,47.91,0.322
193.75,48.05,0.345
193.78,48.18,0.369
193.80,48.31,0.393
193.83,48.44,0.423
193.86,48.57,0.454
193.89,48.70,0.488
193.92,48.83,0.525
193.95,48.96,0.565
193.98,49.09,0.610
194.00,49.21,0.656
194.03,49.34,0.704
194.06,49.46,0.755
194.09,49.58,0.811
194.12,49.70,0.871
194.15,49.82,0.933
194.17,49.94,0.998
194.20,50.05,1.066
194.23,50.17,1.137
194.26,50.28,1.216
194.29,50.40,1.290
194.32,50.51,1.371
194.34,50.62,1.452
194.37,50.73,1.532
194.40,50.84,1.614
194.43,50.95,1.691
194.46,51.06,1.763
194.48,51.17,1.815
194.51,51.29,1.830
194.54,51.43,1.773
194.57,51.59,1.585
194.60,51.79,1.226
194.63,52.03,0.896
194.65,52.27,0.682
194.68,52.50,0.549
194.71,52.71,0.454
194.74,52.90,0.382
194.77,53.08,0.323
194.80,53.26,0.279
194.83,53.42,0.242
194.85,53.59,0.213
194.88,53.74,0.193
194.91,53.90,0.176
194.94,54.05,0.162
194.97,54.20,0.151
195.00,54.34,0.143
195.02,54.49,0.136
195.05,54.64,0.132
195.08,54.78,0.128
195.11,54.92,0.125
195.14,55.07,0.123
195.17,55.21,0.121
195.19,55.35,0.120
195.22,55.50,0.119
195.25,55.64,0.118
195.28,55.78,0.118
195.31,55.92,0.117
195.33,56.07,0.117
195.36,56.21,0.116
195.39,56.35,0.116
195.42,56.49,0.116
195.45,56.63,0.116
195.48,56.78,0.115
195.50,56.92,0.115
195.53,57.06,0.115
195.56,57.20,0.115
195.59,57.34,0.115
195.62,57.48,0.114
195.65,57.63,0.114
195.68,57.77,0.114
195.70,57.91,0.114
195.73,58.05,0.114
195.76,58.19,0.114
195.79,58.34,0.114
195.82,58.48,0.114
195.85,58.62,0.114
195.87,58.76,0.114
195.90,58.90,0.114
195.93,59.04,0.114
195.96,59.18,0.114
195.99,59.33,0.114
196.02,59.47,0.113
196.04,59.61,0.114
196.07,59.75,0.114
196.10,59.89,0.114
196.13,60.03,0.114
196.16,60.18,0.114
196.18,60.32,0.114
196.21,60.46,0.114
196.24,60.60,0.113
196.27,60.75,0.113
196.30,60.89,0.113
196.33,61.03,0.114
196.35,61.17,0.114
196.38,61.31,0.114
196.41,61.45,0.114
196.44,61.60,0.114
196.47,61.74,0.114
196.50,61.88,0.114
196.53,62.02,0.114
196.55,62.16,0.114
196.58,62.31,0.114
196.61,62.45,0.114
196.64,62.59,0.114
196.67,62.73,0.114
196.70,62.87,0.114
196.72,63.01,0.114
196.75,63.16,0.114
196.78,63.30,0.114
196.81,63.44,0.114
196.84,63.58,0.114
196.87,63.72,0.114
196.89,63.86,0.114
196.92,64.01,0.114
196.95,64.15,0.114
196.98,64.29,0.114
197.01,64.43,0.114
197.03,64.57,0.114
197.06,64.71,0.114
197.09,64.86,0.114
197.12,65.00,0.114
197.15,65.14,0.114
197.18,65.28,0.114
197.20,65.42,0.114
197.23,65.56,0.114
197.26,65.71,0.114
197.29,65.85,0.114
197.32,65.99,0.114
197.35,66.13,0.114
197.38,66.27,0.114
197.40,66.41,0.114
197.43,66.55,0.114
197.46,66.70,0.114
197.49,66.84,0.114
197.52,66.98,0.114
197.55,67.12,0.114
197.57,67.26,0.114
197.60,67.40,0.114
197.63,67.55,0.114
197.66,67.69,0.114
197.69,67.83,0.114
197.72,67.97,0.114
197.74,68.11,0.115
197.77,68.26,0.115
197.80,68.40,0.115
197.83,68.54,0.115
197.86,68.68,0.115
197.88,68.82,0.115
197.91,68.97,0.115
197.94,69.11,0.115
197.97,69.25,0.115
198.00,69.39,0.115
198.03,69.53,0.115
198.05,69.68,0.115
198.08,69.82,0.115
198.11,69.96,0.115
198.14,70.10,0.115
198.17,70.24,0.116
198.20,70.38,0.116
198.23,70.52,0.116
198.25,70.67,0.116
198.28,70.81,0.116
198.31,70.95,0.116
198.34,71.09,0.116
198.37,71.23,0.116
198.40,71.37,0.116
198.42,71.52,0.116
198.45,71.66,0.116
198.48,71.80,0.116
198.51,71.94,0.116
198.54,72.08,0.116
198.57,72.23,0.116
198.59,72.37,0.116
198.62,72.51,0.116
198.65,72.65,0.116
198.68,72.80,0.116
198.71,72.94,0.116
198.73,73.08,0.116
198.76,73.22,0.116
198.79,73.36,0.116
198.82,73.50,0.116
198.85,73.65,0.116
198.88,73.79,0.116
198.90,73.93,0.116
198.93,74.07,0.116
198.96,74.21,0.116
198.99,74.35,0.116
199.02,74.49,0.116
199.05,74.64,0.116
199.08,74.78,0.116
199.10,74.92,0.116
199.13,75.06,0.116
199.16,75.20,0.116
199.19,75.34,0.116
199.22,75.49,0.116
199.25,75.63,0.116
199.27,75.77,0.116
199.30,75.91,0.116
199.33,76.05,0.116
199.36,76.19,0.116
199.39,76.33,0.116
199.42,76.48,0.116
199.44,76.62,0.116
199.47,76.76,0.116
199.50,76.90,0.116
199.53,77.05,0.116
199.56,77.19,0.117
199.58,77.33,0.117
199.61,77.47,0.117
199.64,77.61,0.117
199.67,77.76,0.117
199.70,77.90,0.117
199.73,78.04,0.117
199.75,78.18,0.117
199.78,78.32,0.117
199.81,78.46,0.117
199.84,78.61,0.117
199.87,78.75,0.117
199.90,78.89,0.117
199.93,79.03,0.117
199.95,79.17,0.117
199.98,79.31,0.117
200.01,79.46,0.117
200.04,79.60,0.117
200.07,79.74,0.117
200.10,79.88,0.117
200.12,80.02,0.117
200.15,80.17,0.117
200.18,80.31,0.117
200.21,80.45,0.117
200.24,80.59,0.117
200.27,80.73,0.117
200.29,80.87,0.117
200.32,81.01,0.117
200.35,81.15,0.117
200.38,81.30,0.117
200.41,81.44,0.117
200.43,81.58,0.117
200.46,81.72,0.117
200.49,81.86,0.117
200.52,82.01,0.117
200.55,82.15,0.117
200.58,82.29,0.117
200.60,82.43,0.117
200.63,82.57,0.117
200.66,82.71,0.117
200.69,82.86,0.117
200.72,83.00,0.117
200.75,83.14,0.117
200.78,83.28,0.117
200.80,83.42,0.117
200.83,83.57,0.117
200.86,83.71,0.118
200.89,83.85,0.118
200.92,83.99,0.118
200.95,84.13,0.118
200.97,84.27,0.118
201.00,84.42,0.118
201.03,84.56,0.118
201.06,84.70,0.118
201.09,84.84,0.118
201.12,84.98,0.118
201.14,85.13,0.118
201.17,85.27,0.118
201.20,85.41,0.118
201.23,85.55,0.118
201.26,85.69,0.118
201.28,85.83,0.118
201.31,85.98,0.118
201.34,86.12,0.118
201.37,86.26,0.118
201.40,86.40,0.118
201.43,86.54,0.118
201.45,86.68,0.118
201.48,86.82,0.118
201.51,86.97,0.118
201.54,87.11,0.118
201.57,87.25,0.118
201.60,87.39,0.118
201.63,87.53,0.118
201.65,87.67,0.118
201.68,87.82,0.118
201.71,87.96,0.118
201.74,88.10,0.118
201.77,88.24,0.118
201.80,88.38,0.118
201.82,88.53,0.118
201.85,88.67,0.118
201.88,88.81,0.118
201.91,88.95,0.119
201.94,89.09,0.119
201.97,89.23,0.119
201.99,89.38,0.119
202.02,89.52,0.119
202.05,89.66,0.119
202.08,89.80,0.119
202.11,89.94,0.119
202.13,90.09,0.119
202.16,90.23,0.119
202.19,90.37,0.119
202.22,90.51,0.119
202.25,90.65,0.119
202.28,90.79,0.119
202.30,90.94,0.119
202.33,91.08,0.119
202.36,91.22,0.119
202.39,91.36,0.119
202.42,91.50,0.119
202.45,91.64,0.119
202.48,91.79,0.119
202.50,91.93,0.119
202.53,92.07,0.119
202.56,92.21,0.120
202.59,92.35,0.120
202.62,92.49,0.120
202.65,92.64,0.120
202.67,92.78,0.120
202.70,92.92,0.120
202.73,93.06,0.120
202.76,93.20,0.120
202.79,93.34,0.120
202.82,93.49,0.120
202.84,93.63,0.120
202.87,93.77,0.119
202.90,93.91,0.119
202.93,94.05,0.120
202.96,94.20,0.120
202.98,94.34,0.120
203.01,94.48,0.120
203.04,94.62,0.120
203.07,94.76,0.120
203.10,94.90,0.120
203.13,95.05,0.120
203.15,95.19,0.120
203.18,95.33,0.120
203.21,95.47,0.120
203.24,95.61,0.120
203.27,95.75,0.120
203.30,95.89,0.120
203.33,96.04,0.120
203.35,96.18,0.120
203.38,96.32,0.120
203.41,96.46,0.120
203.44,96.60,0.120
203.47,96.75,0.120
203.50,96.89,0.120
203.52,97.03,0.120
203.55,97.17,0.120
203.58,97.31,0.120
203.61,97.45,0.121
203.64,97.60,0.121
203.67,97.74,0.121
203.69,97.88,0.121
203.72,98.02,0.121
203.75,98.16,0.121
203.78,98.30,0.120
203.81,98.45,0.120
203.83,98.59,0.121
203.86,98.73,0.121
203.89,98.87,0.121
203.92,99.01,0.121
203.95,99.16,0.121
203.98,99.30,0.121
204.00,99.44,0.121
204.03,99.58,0.121
204.06,99.72,0.121
204.09,99.86,0.121
204.12,100.01,0.121
204.15,100.15,0.121
204.18,100.29,0.121
204.20,100.43,0.121
204.23,100.57,0.121
204.26,100.71,0.121
204.29,100.86,0.121
204.32,101.00,0.121
204.35,101.14,0.121
204.37,101.28,0.121
204.40,101.42,0.121
204.43,101.56,0.121
204.46,101.71,0.121
204.49,101.85,0.121
204.52,101.99,0.121
204.54,102.13,0.121
204.57,102.27,0.121
204.60,102.41,0.121
204.63,102.56,0.121
204.66,102.70,0.121
204.68,102.84,0.121
204.71,102.98,0.122
204.74,103.12,0.122
204.77,103.27,0.122
204.80,103.41,0.122
204.83,103.55,0.122
204.85,103.69,0.122
204.88,103.83,0.122
204.91,103.97,0.122
204.94,104.11,0.122
204.97,104.26,0.122
205.00,104.40,0.122
205.03,104.54,0.122
205.05,104.68,0.122
205.08,104.83,0.122
205.11,104.97,0.122
205.14,105.11,0.122
205.17,105.25,0.122
205.20,105.39,0.122
205.22,105.53,0.122
205.25,105.67,0.122
205.28,105.82,0.122
205.31,105.96,0.122
205.34,106.10,0.122
205.37,106.24,0.122
205.39,106.38,0.122
205.42,106.53,0.122
205.45,106.67,0.122
205.48,106.81,0.122
205.51,106.95,0.122
205.53,107.09,0.122
205.56,107.24,0.122
205.59,107.38,0.122
205.62,107.52,0.122
205.65,107.66,0.122
205.68,107.80,0.122
205.70,107.94,0.122
205.73,108.09,0.122
205.76,108.23,0.123
205.79,108.37,0.123
205.82,108.51,0.123
205.85,108.65,0.123
205.88,108.79,0.123
205.90,108.94,0.123
205.93,109.08,0.123
205.96,109.22,0.123
205.99,109.36,0.123
206.02,109.50,0.123
206.05,109.64,0.123
206.07,109.79,0.123
206.10,109.93,0.123
206.13,110.07,0.123
206.16,110.21,0.123
206.19,110.35,0.123
206.22,110.49,0.123
206.24,110.63,0.123
206.27,110.78,0.123
206.30,110.92,0.123
206.33,111.06,0.123
206.36,111.20,0.123
206.38,111.35,0.123
206.41,111.49,0.123
206.44,111.63,0.123
206.47,111.77,0.123
206.50,111.91,0.123
206.53,112.05,0.123
206.55,112.19,0.123
206.58,112.34,0.123
206.61,112.48,0.123
206.64,112.62,0.123
206.67,112.76,0.123
206.70,112.90,0.123
206.73,113.05,0.123
206.75,113.19,0.123
206.78,113.33,0.123
206.81,113.47,0.123
206.84,113.61,0.124
206.87,113.75,0.124
206.90,113.90,0.124
206.92,114.04,0.123
206.95,114.18,0.123
206.98,114.32,0.123
207.01,114.46,0.123
207.04,114.60,0.123
207.07,114.74,0.123
207.09,114.89,0.124
207.12,115.03,0.124
207.15,115.17,0.124
207.18,115.31,0.124
207.21,115.45,0.124
207.23,115.60,0.124
207.26,115.74,0.124
207.29,115.88,0.124
207.32,116.02,0.124
207.35,116.16,0.124
207.38,116.31,0.124
207.40,116.45,0.124
207.43,116.59,0.124
207.46,116.73,0.124
207.49,116.87,0.124
207.52,117.01,0.124
207.55,117.15,0.124
207.58,117.30,0.124
207.60,117.44,0.124
207.63,117.58,0.124
207.66,117.72,0.124
207.69,117.86,0.124
207.72,118.01,0.124
207.75,118.15,0.124
207.77,118.29,0.124
207.80,118.43,0.124
207.83,118.57,0.124
207.86,118.71,0.124
207.89,118.86,0.124
207.92,119.00,0.124
207.94,119.14,0.124
207.97,119.28,0.124
208.00,119.42,0.125
208.03,119.56,0.125
208.06,119.71,0.125
208.08,119.85,0.125
208.11,119.99,0.125
208.14,120.13,0.125
208.17,120.27,0.125
208.20,120.41,0.125
208.23,120.56,0.125
208.25,120.70,0.125
208.28,120.84,0.125
208.31,120.98,0.125
208.34,121.12,0.124
208.37,121.27,0.124
208.40,121.41,0.125
208.43,121.55,0.125
208.45,121.69,0.125
208.48,121.83,0.125
208.51,121.97,0.125
208.54,122.12,0.125
208.57,122.26,0.125
208.60,122.40,0.125
208.62,122.54,0.125
208.65,122.68,0.125
208.68,122.83,0.125
208.71,122.97,0.125
208.74,123.11,0.125
208.77,123.25,0.125
208.79,123.39,0.125
208.82,123.53,0.125
208.85,123.67,0.125
208.88,123.82,0.125
208.91,123.96,0.125
208.93,124.10,0.125
208.96,124.24,0.125
208.99,124.38,0.125
209.02,124.52,0.125
209.05,124.67,0.125
209.08,124.81,0.125
209.10,124.95,0.125
209.13,125.09,0.125
209.16,125.23,0.126
209.19,125.37,0.126
209.22,125.51,0.125
209.25,125.66,0.125
209.28,125.80,0.125
209.30,125.94,0.125
209.33,126.08,0.125
209.36,126.22,0.125
209.39,126.37,0.125
209.42,126.51,0.126
209.45,126.65,0.126
209.47,126.79,0.126
209.50,126.93,0.126
209.53,127.08,0.126
209.56,127.22,0.126
209.59,127.36,0.126
209.62,127.50,0.126
209.64,127.64,0.126
209.67,127.78,0.126
209.70,127.93,0.126
209.73,128.07,0.126
209.76,128.21,0.126
209.78,128.35,0.126
209.81,128.49,0.126
209.84,128.64,0.126
209.87,128.78,0.126
209.90,128.92,0.126
209.93,129.06,0.126
209.95,129.20,0.126
209.98,129.34,0.126
210.01,129.48,0.126
210.04,129.63,0.126
210.07,129.77,0.126
210.10,129.91,0.126
210.13,130.05,0.126
210.15,130.19,0.126
210.18,130.34,0.126
210.21,130.48,0.126
210.24,130.62,0.126
210.27,130.76,0.126
210.30,130.90,0.126
210.32,131.04,0.126
210.35,131.19,0.126
210.38,131.33,0.126
210.41,131.47,0.127
210.44,131.61,0.127
210.47,131.75,0.127
210.49,131.89,0.127
210.52,132.03,0.127
210.55,132.18,0.127
210.58,132.32,0.127
210.61,132.46,0.127
210.63,132.60,0.127
210.66,132.74,0.127
210.69,132.89,0.127
210.72,133.03,0.127
210.75,133.17,0.127
210.78,133.31,0.127
210.80,133.45,0.127
210.83,133.59,0.127
210.86,133.74,0.127
210.89,133.88,0.127
210.92,134.02,0.127
210.95,134.16,0.127
210.98,134.30,0.127
211.00,134.44,0.127
211.03,134.59,0.127
211.06,134.73,0.127
211.09,134.87,0.127
211.12,135.01,0.127
211.15,135.15,0.127
211.17,135.30,0.127
211.20,135.44,0.127
211.23,135.58,0.127
211.26,135.72,0.127
211.29,135.86,0.127
211.32,136.00,0.127
211.34,136.15,0.127
211.37,136.29,0.127
211.40,136.43,0.127
211.43,136.57,0.127
211.46,136.71,0.127
211.48,136.85,0.127
211.51,137.00,0.127
211.54,137.14,0.127
211.57,137.28,0.127
211.60,137.42,0.127
211.63,137.56,0.127
211.65,137.71,0.127
211.68,137.85,0.127
211.71,137.99,0.127
211.74,138.13,0.127
211.77,138.27,0.127
211.80,138.41,0.127
211.83,138.55,0.127
211.85,138.69,0.127
211.88,138.84,0.127
211.91,138.98,0.127
211.94,139.12,0.127
211.97,139.26,0.127
212.00,139.40,0.127
212.02,139.55,0.127
212.05,139.69,0.127
212.08,139.83,0.127
212.11,139.97,0.127
212.14,140.11,0.127
212.17,140.25,0.127
212.19,140.40,0.127
212.22,140.54,0.127
212.25,140.68,0.127
212.28,140.82,0.127
212.31,140.96,0.127
212.33,141.11,0.127
212.36,141.25,0.127
212.39,141.39,0.127
212.42,141.53,0.127
212.45,141.67,0.127
212.48,141.81,0.127
212.50,141.95,0.127
212.53,142.10,0.127
212.56,142.24,0.127
212.59,142.38,0.127
212.62,142.52,0.127
212.65,142.66,0.127
212.68,142.81,0.127
212.70,142.95,0.127
212.73,143.09,0.128
212.76,143.23,0.128
212.79,143.37,0.128
212.82,143.51,0.128
212.85,143.65,0.128
212.87,143.80,0.128
212.90,143.94,0.128
212.93,144.08,0.127
212.96,144.22,0.127
212.99,144.36,0.127
213.02,144.51,0.127
213.04,144.65,0.127
213.07,144.79,0.127
213.10,144.93,0.128
213.13,145.07,0.128
213.16,145.22,0.128
213.18,145.36,0.128
213.21,145.50,0.128
213.24,145.64,0.128
213.27,145.78,0.128
213.30,145.92,0.128
213.33,146.07,0.128
213.35,146.21,0.128
213.38,146.35,0.128
213.41,146.49,0.128
213.44,146.63,0.128
213.47,146.77,0.128
213.50,146.91,0.128
213.53,147.06,0.128
213.55,147.20,0.128
213.58,147.34,0.128
213.61,147.48,0.128
213.64,147.62,0.128
213.67,147.77,0.128
213.70,147.91,0.128
213.72,148.05,0.128
213.75,148.19,0.128
213.78,148.33,0.128
213.81,148.47,0.128
213.84,148.61,0.128
213.87,148.76,0.128
213.89,148.90,0.128
213.92,149.04,0.128
213.95,149.18,
213.98,149.32,
213.99,,