File: DSC/2025_02_13_Glucose_DSC.txt
Filename	2025_02_13_Glucose_DSC
Instrument name	DSC2A-00468 (192.168.1.100)
Operator	JLY
rundate	2/13/2025
Sample name	2025_02_13_Glucose_DSC
proceduresegments	Data Off ; Equilibrate 30.00 °C; Data On ; Ramp 5.00 °C/min to 200.00 °C
[File Parameters]
Run date	2/13/2025 4:47:51 PM
Trios version	5.1.1.46572
Original File Name
Current File Name	D:\DSC2500\CHM343\2025_02_13_Glucose_DSC.tri
[Procedure]
Procedure Name	Glucose Melting
Sample Name	2025_02_13_Glucose_DSC
Sample Mass	5.23 mg
Reference Sample Mass	0 mg
Pan Mass	54.05 mg
Pan Number	23
Reference Pan Mass	54 mg
Reference Pan Number	19
Pan Type	Tzero Aluminum Hermetic
Comments	Al Hermetic Sealed Pan, with ref Al pan
Project Name
Operator	JLY
Test	Custom
Unload Max Temperature	30
Unload Min Temperature	30
Load Max Temperature	30
Load Min Temperature	30
Stop on Gas Flow Error	Yes
[Signal List]
Signal #1	Time (min)
Signal #2	Temperature (°C)
Signal #3	Heat Flow (mW)
Signal #4	Delta T (µV)
Signal #5	Delta Tzero (µV)
Signal #6	Tzero Temperature (°C)
Signal #7	Cell Purge (mL/min)
Signal #8	Heater Temp (°C)
Signal #9	Power Delivered (W)
Signal #10	Reference Junction Temperature (°C)
Signal #11	Flange Temperature (°C)
Signal #12	Heat Flow Phase (rad)
Signal #13	Total Heat Capacity (J/°C)
Signal #14	Heat Capacity (J/°C)
[Configuration]
Company Name	ASU
Instrument Name	DSC2A-00468
Instrument Type	DSC2500
Serial Number	DSC2A-00468
IP	192.168.1.100
Location of Instrument	MRRC
DisplayType	Unknown
Sample Interval 	0.1 s/pt
Selected Heat Flow	T4P
Exotherm Direction	Down
Cell Serial	DRC2-00792
Lid Type	Standard
Cooler	RCS 90
Leave Cooler on at End of Sequence	On
Gas 2	Nitrogen
Gas Selected	Channel 1
Flow Rate	50 mL/min
Secondary Purge	On
Licensed Heat Flow	Heat Flow T4P
Modulation Licensed	Yes
[Versions]
Common IDD Version	1
Cortex Version	VER 2.10.2.31
Driver	5.0.0.6
GDM Version	1.0.3.3
TouchscreenVersion	1.0.0.16145
FEP Version	1.2.1.21
FEP Bootloader	2.0.0.5
AutoSampler Version	2.1.1.26
Auto Sampler Bootloader	2.0.0.5
FCM Version	1.1.0.3
FCM Bootloader	2.0.0.5
[Experiment Logs]
Experiment Log Entry # 1	Air Cool is off.
Experiment Log Entry # 3	Data On set to 0
Experiment Log Entry # 5	Equilibrate Segment 30 (C) Started
Experiment Log Entry # 7	Data On set to 1
Experiment Log Entry # 9	Ramp Segment 5 C/min to 200 Started
[Method Log]
Method Log Entry # 1	Data Off
Method Log Entry # 2	Equilibrate 30 °C
Method Log Entry # 3	Data On
Method Log Entry # 4	(Ramp 28941) Ramp 5 °C/minute to 200 °C
Cell Serial	DRC2-00792
[T1 Calibration]
Slope	-0.008529666
Offset	9.636258
Initial Temperature	98.23
GUID	f8bfdadc-4977-4fdf-ba6d-0ba9134940c3
[TZero Calibration]
Date Applied	11/29/2022 4:06:13 PM
Description	From -89.059 °C to 396.009 °C at 20.000°C/min
Gas Type	Nitrogen
Pan Type	None
Source Files 1	C:\Users\yargerlab\Desktop\DSC Data\General\TZero_calibration_11_29_22_2nd(2).tri
Source Files 2	C:\Users\yargerlab\Desktop\DSC Data\General\TZero_calibration_11_29_22_2nd(3).tri
Delta T Offset	13.05235
Delta T Slope	-0.007271007
Delta T0 Offset	-13.69128
Delta T0 Slope	0.06063341
[Temperature Calibration]
Date Applied	11/29/2022 7:12:28 PM
Description	From 106.590 °C to 186.590 °C at 10.000°C/min
Gas Type	Nitrogen
Pan Type	Tzero Aluminum Hermetic
Source Files 1	C:\Users\yargerlab\Desktop\DSC Data\General\Indium(6).tri
Measured 1	157.391
Known 1	156.598
[Cell Constant Calibration]
Date Applied	11/29/2022 7:12:29 PM
Description	From 106.590 °C to 186.590 °C at 10.000°C/min
Gas Type	Nitrogen
Pan Type	Tzero Aluminum Hermetic
Source Files 1	C:\Users\yargerlab\Desktop\DSC Data\General\Indium(6).tri
T4P KCell	1.006051
Onset Slope	63.26126 mW/°C
[Direct Cp Calibration]
Date Applied	11/30/2022 11:04:51 AM
Description	From -79.983 °C to 298.409 °C at 10.000°C/min
Gas Type	Nitrogen
Pan Type	Tzero Aluminum Hermetic
Source Files 1	C:\Users\yargerlab\Desktop\DSC Data\General\Sapphire_Heat_Capacity_11_30_22.tri
[Rev Cp Calibration]
Date Applied	11/30/2022 1:58:51 PM
Description	From -79.996 °C to 292.812 °C at 3.000°C/min
Gas Type	Nitrogen
Pan Type	Tzero Aluminum Hermetic
Source Files 1	C:\Users\yargerlab\Desktop\DSC Data\General\Sapphire_MDSC_Calibration_11_30_22.tri
[step]
Ramp 5.00 °C/min to 200.00 °C
Time	Temperature	Heat Flow (Normalized)
min	°C	W/g
0.00	29.93	-0.005
0.02	29.95	-0.004
0.05	29.97	-0.004
0.07	29.99	-0.002
0.09	30.04	0.009
0.12	30.09	0.025
0.14	30.17	0.040
0.16	30.25	0.054
0.19	30.35	0.066
0.21	30.45	0.076
0.23	30.55	0.083
0.26	30.66	0.087
0.28	30.77	0.094
0.30	30.88	0.097
0.33	30.99	0.099
0.35	31.11	0.102
0.37	31.22	0.104
0.40	31.34	0.105
0.42	31.45	0.106
0.44	31.57	0.107
0.47	31.69	0.107
0.49	31.81	0.108
0.51	31.92	0.108
0.54	32.04	0.109
0.56	32.16	0.109
0.58	32.27	0.109
0.61	32.39	0.109
0.63	32.51	0.110
0.65	32.63	0.110
0.68	32.74	0.110
0.70	32.86	0.110
0.72	32.98	0.110
0.75	33.10	0.110
0.77	33.21	0.111
0.79	33.33	0.111
0.82	33.45	0.111
0.84	33.56	0.111
0.86	33.68	0.111
0.89	33.80	0.111
0.91	33.91	0.111
0.93	34.03	0.111
0.96	34.15	0.111
0.98	34.26	0.111
1.00	34.38	0.111
1.03	34.50	0.111
1.05	34.61	0.111
1.07	34.73	0.111
1.10	34.85	0.111
1.12	34.96	0.111
1.14	35.08	0.111
1.17	35.20	0.111
1.19	35.31	0.111
1.21	35.43	0.111
1.24	35.55	0.111
1.26	35.66	0.111
1.28	35.78	0.111
1.31	35.90	0.111
1.33	36.01	0.111
1.35	36.13	0.111
1.38	36.25	0.111
1.40	36.36	0.111
1.42	36.48	0.111
1.45	36.60	0.111
1.47	36.71	0.111
1.49	36.83	0.111
1.52	36.95	0.111
1.54	37.07	0.111
1.56	37.18	0.111
1.59	37.30	0.111
1.61	37.41	0.111
1.63	37.53	0.111
1.66	37.65	0.111
1.68	37.77	0.111
1.70	37.88	0.111
1.73	38.00	0.111
1.75	38.11	0.111
1.77	38.23	0.111
1.80	38.35	0.111
1.82	38.46	0.111
1.84	38.58	0.111
1.87	38.70	0.111
1.89	38.81	0.111
1.91	38.93	0.111
1.94	39.05	0.111
1.96	39.16	0.111
1.98	39.28	0.111
2.01	39.40	0.111
2.03	39.51	0.111
2.05	39.63	0.111
2.08	39.75	0.111
2.10	39.86	0.111
2.12	39.98	0.111
2.15	40.10	0.111
2.17	40.21	0.111
2.19	40.33	0.111
2.22	40.45	0.111
2.24	40.57	0.111
2.26	40.68	0.111
2.29	40.80	0.111
2.31	40.91	0.111
2.33	41.03	0.111
2.36	41.15	0.111
2.38	41.27	0.111
2.40	41.38	0.111
2.43	41.50	0.111
2.45	41.62	0.111
2.47	41.73	0.111
2.50	41.85	0.111
2.52	41.97	0.111
2.54	42.08	0.111
2.57	42.20	0.111
2.59	42.32	0.111
2.61	42.43	0.111
2.64	42.55	0.111
2.66	42.66	0.111
2.68	42.78	0.111
2.71	42.90	0.111
2.73	43.02	0.112
2.75	43.13	0.112
2.78	43.25	0.112
2.80	43.37	0.112
2.82	43.48	0.112
2.85	43.60	0.112
2.87	43.72	0.112
2.89	43.83	0.112
2.92	43.95	0.112
2.94	44.07	0.112
2.96	44.18	0.112
2.99	44.30	0.112
3.01	44.42	0.112
3.03	44.53	0.112
3.06	44.65	0.112
3.08	44.77	0.112
3.10	44.88	0.112
3.13	45.00	0.112
3.15	45.12	0.112
3.17	45.23	0.112
3.20	45.35	0.112
3.22	45.47	0.112
3.24	45.58	0.112
3.27	45.70	0.112
3.29	45.82	0.112
3.31	45.93	0.112
3.34	46.05	0.112
3.36	46.17	0.112
3.38	46.28	0.112
3.41	46.40	0.112
3.43	46.52	0.112
3.45	46.63	0.112
3.48	46.75	0.112
3.50	46.87	0.113
3.52	46.98	0.113
3.55	47.10	0.113
3.57	47.22	0.113
3.59	47.33	0.113
3.62	47.45	0.113
3.64	47.57	0.113
3.66	47.69	0.113
3.69	47.80	0.113
3.71	47.92	0.113
3.73	48.03	0.113
3.76	48.15	0.113
3.78	48.27	0.113
3.80	48.39	0.113
3.83	48.50	0.113
3.85	48.62	0.113
3.87	48.74	0.113
3.90	48.85	0.113
3.92	48.97	0.113
3.94	49.08	0.113
3.97	49.20	0.113
3.99	49.32	0.113
4.01	49.44	0.113
4.04	49.55	0.113
4.06	49.67	0.113
4.08	49.79	0.113
4.11	49.90	0.113
4.13	50.02	0.113
4.15	50.14	0.113
4.18	50.25	0.113
4.20	50.37	0.113
4.22	50.49	0.114
4.25	50.60	0.114
4.27	50.72	0.114
4.29	50.84	0.114
4.32	50.95	0.114
4.34	51.07	0.114
4.36	51.19	0.114
4.39	51.30	0.114
4.41	51.42	0.114
4.43	51.54	0.114
4.46	51.65	0.114
4.48	51.77	0.114
4.50	51.89	0.114
4.53	52.00	0.114
4.55	52.12	0.114
4.57	52.24	0.114
4.60	52.36	0.114
4.62	52.47	0.114
4.64	52.59	0.114
4.67	52.71	0.114
4.69	52.82	0.114
4.71	52.94	0.114
4.74	53.06	0.114
4.76	53.17	0.114
4.78	53.29	0.114
4.81	53.40	0.114
4.83	53.52	0.114
4.85	53.64	0.114
4.88	53.76	0.115
4.90	53.87	0.115
4.92	53.99	0.115
4.95	54.10	0.115
4.97	54.22	0.115
4.99	54.34	0.115
5.02	54.46	0.115
5.04	54.57	0.115
5.06	54.69	0.115
5.09	54.81	0.115
5.11	54.92	0.115
5.13	55.04	0.115
5.16	55.16	0.115
5.18	55.27	0.115
5.20	55.39	0.115
5.23	55.51	0.115
5.25	55.62	0.115
5.27	55.74	0.115
5.30	55.86	0.115
5.32	55.97	0.115
5.34	56.09	0.115
5.37	56.21	0.115
5.39	56.32	0.115
5.41	56.44	0.115
5.44	56.56	0.116
5.46	56.67	0.116
5.48	56.79	0.116
5.51	56.91	0.116
5.53	57.02	0.116
5.55	57.14	0.116
5.58	57.26	0.116
5.60	57.37	0.116
5.62	57.49	0.116
5.65	57.61	0.116
5.67	57.72	0.116
5.69	57.84	0.116
5.72	57.96	0.116
5.74	58.08	0.116
5.76	58.19	0.116
5.79	58.31	0.116
5.81	58.43	0.116
5.83	58.54	0.116
5.86	58.66	0.116
5.88	58.77	0.116
5.90	58.89	0.116
5.93	59.01	0.116
5.95	59.12	0.116
5.97	59.24	0.116
6.00	59.36	0.116
6.02	59.47	0.116
6.04	59.59	0.116
6.07	59.71	0.117
6.09	59.83	0.117
6.11	59.94	0.117
6.14	60.06	0.117
6.16	60.18	0.117
6.18	60.29	0.117
6.21	60.41	0.117
6.23	60.53	0.117
6.25	60.64	0.117
6.28	60.76	0.117
6.30	60.88	0.117
6.32	60.99	0.117
6.35	61.11	0.117
6.37	61.23	0.117
6.39	61.34	0.117
6.42	61.46	0.117
6.44	61.58	0.117
6.46	61.69	0.117
6.49	61.81	0.117
6.51	61.93	0.117
6.53	62.04	0.117
6.56	62.16	0.117
6.58	62.28	0.117
6.60	62.39	0.117
6.63	62.51	0.118
6.65	62.63	0.118
6.67	62.74	0.118
6.70	62.86	0.118
6.72	62.98	0.118
6.74	63.09	0.118
6.77	63.21	0.118
6.79	63.33	0.118
6.81	63.44	0.118
6.84	63.56	0.118
6.86	63.68	0.118
6.88	63.79	0.118
6.91	63.91	0.118
6.93	64.03	0.118
6.95	64.14	0.118
6.98	64.26	0.118
7.00	64.38	0.118
7.02	64.49	0.118
7.05	64.61	0.118
7.07	64.73	0.118
7.09	64.84	0.119
7.12	64.96	0.119
7.14	65.08	0.119
7.16	65.19	0.119
7.19	65.31	0.119
7.21	65.43	0.119
7.23	65.54	0.119
7.26	65.66	0.119
7.28	65.78	0.119
7.30	65.90	0.119
7.33	66.01	0.119
7.35	66.13	0.119
7.37	66.24	0.119
7.40	66.36	0.119
7.42	66.48	0.119
7.44	66.60	0.119
7.47	66.71	0.119
7.49	66.83	0.119
7.51	66.95	0.119
7.54	67.06	0.119
7.56	67.18	0.119
7.58	67.30	0.119
7.61	67.41	0.119
7.63	67.53	0.120
7.65	67.65	0.120
7.68	67.76	0.120
7.70	67.88	0.120
7.72	68.00	0.120
7.75	68.11	0.120
7.77	68.23	0.120
7.79	68.35	0.120
7.82	68.46	0.120
7.84	68.58	0.120
7.86	68.70	0.120
7.89	68.81	0.120
7.91	68.93	0.120
7.93	69.05	0.120
7.96	69.16	0.120
7.98	69.28	0.120
8.00	69.40	0.120
8.03	69.51	0.120
8.05	69.63	0.120
8.07	69.75	0.120
8.10	69.86	0.120
8.12	69.98	0.120
8.14	70.10	0.120
8.17	70.21	0.121
8.19	70.33	0.121
8.21	70.45	0.121
8.24	70.57	0.121
8.26	70.68	0.121
8.28	70.80	0.121
8.31	70.92	0.121
8.33	71.03	0.121
8.35	71.15	0.121
8.38	71.27	0.121
8.40	71.38	0.121
8.42	71.50	0.121
8.45	71.62	0.121
8.47	71.73	0.121
8.49	71.85	0.121
8.52	71.97	0.121
8.54	72.08	0.121
8.56	72.20	0.121
8.59	72.32	0.121
8.61	72.43	0.122
8.63	72.55	0.122
8.66	72.67	0.122
8.68	72.78	0.122
8.70	72.90	0.122
8.73	73.02	0.122
8.75	73.13	0.122
8.77	73.25	0.122
8.80	73.36	0.122
8.82	73.48	0.122
8.84	73.60	0.122
8.87	73.72	0.122
8.89	73.83	0.122
8.91	73.95	0.122
8.94	74.07	0.122
8.96	74.18	0.122
8.98	74.30	0.122
9.01	74.42	0.122
9.03	74.53	0.123
9.05	74.65	0.123
9.08	74.77	0.123
9.10	74.88	0.123
9.12	75.00	0.123
9.15	75.12	0.123
9.17	75.23	0.123
9.19	75.35	0.123
9.22	75.47	0.123
9.24	75.58	0.123
9.26	75.70	0.123
9.29	75.82	0.123
9.31	75.93	0.123
9.33	76.05	0.123
9.36	76.17	0.123
9.38	76.28	0.123
9.40	76.40	0.123
9.43	76.52	0.123
9.45	76.63	0.123
9.47	76.75	0.123
9.50	76.87	0.124
9.52	76.98	0.124
9.54	77.10	0.124
9.57	77.22	0.124
9.59	77.33	0.124
9.61	77.45	0.124
9.64	77.57	0.124
9.66	77.68	0.124
9.68	77.80	0.124
9.71	77.92	0.124
9.73	78.03	0.124
9.75	78.15	0.124
9.78	78.27	0.124
9.80	78.38	0.124
9.82	78.50	0.124
9.85	78.62	0.124
9.87	78.73	0.124
9.89	78.85	0.124
9.92	78.97	0.124
9.94	79.08	0.124
9.96	79.20	0.124
9.99	79.32	0.124
10.01	79.43	0.124
10.03	79.55	0.124
10.06	79.67	0.124
10.08	79.78	0.124
10.10	79.90	0.124
10.13	80.02	0.124
10.15	80.13	0.124
10.17	80.25	0.124
10.20	80.37	0.124
10.22	80.48	0.124
10.24	80.60	0.125
10.27	80.72	0.125
10.29	80.83	0.125
10.31	80.95	0.125
10.34	81.07	0.125
10.36	81.19	0.125
10.38	81.30	0.125
10.41	81.42	0.125
10.43	81.54	0.125
10.45	81.65	0.125
10.48	81.77	0.125
10.50	81.89	0.125
10.52	82.00	0.125
10.55	82.12	0.125
10.57	82.24	0.125
10.59	82.35	0.125
10.62	82.47	0.125
10.64	82.59	0.125
10.66	82.70	0.125
10.69	82.82	0.125
10.71	82.94	0.125
10.73	83.05	0.125
10.76	83.17	0.125
10.78	83.29	0.125
10.80	83.40	0.125
10.83	83.52	0.125
10.85	83.64	0.125
10.87	83.75	0.125
10.90	83.87	0.125
10.92	83.99	0.125
10.94	84.10	0.125
10.97	84.22	0.125
10.99	84.34	0.125
11.01	84.45	0.125
11.04	84.57	0.125
11.06	84.69	0.126
11.08	84.80	0.126
11.11	84.92	0.126
11.13	85.04	0.126
11.15	85.15	0.126
11.18	85.27	0.126
11.20	85.39	0.126
11.22	85.50	0.126
11.25	85.62	0.126
11.27	85.74	0.126
11.29	85.85	0.126
11.32	85.97	0.126
11.34	86.09	0.126
11.36	86.20	0.126
11.39	86.32	0.126
11.41	86.44	0.126
11.43	86.55	0.126
11.46	86.67	0.126
11.48	86.79	0.126
11.50	86.91	0.126
11.53	87.02	0.126
11.55	87.14	0.127
11.57	87.26	0.127
11.60	87.37	0.127
11.62	87.49	0.127
11.64	87.61	0.127
11.67	87.72	0.127
11.69	87.84	0.127
11.71	87.95	0.127
11.74	88.07	0.127
11.76	88.19	0.127
11.78	88.31	0.127
11.81	88.42	0.127
11.83	88.54	0.127
11.85	88.66	0.127
11.88	88.77	0.127
11.90	88.89	0.127
11.92	89.01	0.127
11.95	89.12	0.127
11.97	89.24	0.127
11.99	89.36	0.127
12.02	89.47	0.127
12.04	89.59	0.127
12.06	89.71	0.128
12.09	89.82	0.128
12.11	89.94	0.128
12.13	90.06	0.128
12.16	90.17	0.128
12.18	90.29	0.128
12.20	90.41	0.128
12.23	90.52	0.128
12.25	90.64	0.128
12.27	90.76	0.128
12.30	90.87	0.128
12.32	90.99	0.128
12.34	91.11	0.128
12.37	91.22	0.128
12.39	91.34	0.128
12.41	91.46	0.128
12.44	91.57	0.128
12.46	91.69	0.128
12.48	91.81	0.129
12.51	91.92	0.129
12.53	92.04	0.129
12.55	92.16	0.129
12.58	92.27	0.129
12.60	92.39	0.129
12.62	92.51	0.129
12.65	92.62	0.129
12.67	92.74	0.129
12.69	92.86	0.129
12.72	92.97	0.129
12.74	93.09	0.129
12.76	93.21	0.129
12.79	93.32	0.129
12.81	93.44	0.129
12.83	93.56	0.129
12.86	93.67	0.129
12.88	93.79	0.130
12.90	93.91	0.130
12.93	94.02	0.130
12.95	94.14	0.130
12.97	94.26	0.130
13.00	94.37	0.130
13.02	94.49	0.130
13.04	94.61	0.130
13.07	94.72	0.130
13.09	94.84	0.130
13.11	94.96	0.130
13.14	95.07	0.130
13.16	95.19	0.130
13.18	95.31	0.130
13.21	95.42	0.130
13.23	95.54	0.130
13.25	95.66	0.130
13.28	95.77	0.130
13.30	95.89	0.130
13.32	96.01	0.130
13.35	96.13	0.131
13.37	96.24	0.131
13.39	96.36	0.131
13.42	96.48	0.131
13.44	96.59	0.131
13.46	96.71	0.131
13.49	96.83	0.131
13.51	96.94	0.131
13.53	97.06	0.131
13.56	97.18	0.131
13.58	97.29	0.131
13.60	97.41	0.131
13.63	97.53	0.131
13.65	97.64	0.131
13.67	97.76	0.131
13.70	97.88	0.131
13.72	97.99	0.131
13.74	98.11	0.131
13.77	98.23	0.131
13.79	98.34	0.132
13.81	98.46	0.132
13.84	98.58	0.132
13.86	98.69	0.132
13.88	98.81	0.132
13.91	98.93	0.132
13.93	99.04	0.132
13.95	99.16	0.132
13.98	99.28	0.132
14.00	99.39	0.132
14.02	99.51	0.132
14.05	99.63	0.132
14.07	99.74	0.132
14.09	99.86	0.132
14.12	99.98	0.132
14.14	100.09	0.132
14.16	100.21	0.132
14.19	100.33	0.132
14.21	100.44	0.132
14.23	100.56	0.132
14.26	100.68	0.133
14.28	100.79	0.133
14.30	100.91	0.133
14.33	101.03	0.133
14.35	101.14	0.133
14.37	101.26	0.133
14.40	101.38	0.133
14.42	101.49	0.133
14.44	101.61	0.133
14.47	101.73	0.133
14.49	101.84	0.133
14.51	101.96	0.133
14.54	102.08	0.133
14.56	102.19	0.133
14.58	102.31	0.133
14.61	102.43	0.133
14.63	102.54	0.133
14.65	102.66	0.134
14.68	102.78	0.134
14.70	102.89	0.134
14.72	103.01	0.134
14.75	103.13	0.134
14.77	103.24	0.134
14.79	103.36	0.134
14.82	103.48	0.134
14.84	103.59	0.134
14.86	103.71	0.134
14.89	103.83	0.134
14.91	103.94	0.134
14.93	104.06	0.134
14.96	104.18	0.134
14.98	104.29	0.134
15.00	104.41	0.134
15.03	104.53	0.134
15.05	104.64	0.134
15.07	104.76	0.134
15.10	104.88	0.135
15.12	104.99	0.135
15.14	105.11	0.135
15.17	105.23	0.135
15.19	105.34	0.135
15.21	105.46	0.135
15.24	105.58	0.135
15.26	105.70	0.135
15.28	105.81	0.135
15.31	105.93	0.135
15.33	106.05	0.135
15.35	106.16	0.135
15.38	106.28	0.135
15.40	106.39	0.135
15.42	106.51	0.135
15.45	106.63	0.135
15.47	106.75	0.135
15.49	106.86	0.135
15.52	106.98	0.135
15.54	107.09	0.135
15.56	107.21	0.135
15.59	107.33	0.135
15.61	107.44	0.136
15.63	107.56	0.136
15.66	107.68	0.136
15.68	107.79	0.136
15.70	107.91	0.136
15.73	108.03	0.136
15.75	108.15	0.136
15.77	108.26	0.136
15.80	108.38	0.136
15.82	108.50	0.136
15.84	108.61	0.136
15.87	108.73	0.136
15.89	108.85	0.136
15.91	108.96	0.136
15.94	109.08	0.136
15.96	109.20	0.136
15.98	109.31	0.137
16.01	109.43	0.137
16.03	109.55	0.137
16.05	109.66	0.137
16.08	109.78	0.137
16.10	109.90	0.137
16.12	110.01	0.137
16.15	110.13	0.137
16.17	110.25	0.137
16.19	110.36	0.137
16.22	110.48	0.137
16.24	110.60	0.137
16.26	110.71	0.137
16.29	110.83	0.137
16.31	110.95	0.137
16.33	111.06	0.137
16.36	111.18	0.137
16.38	111.30	0.137
16.40	111.41	0.137
16.43	111.53	0.138
16.45	111.65	0.138
16.47	111.76	0.138
16.50	111.88	0.138
16.52	112.00	0.138
16.54	112.11	0.138
16.57	112.23	0.138
16.59	112.35	0.138
16.61	112.46	0.138
16.64	112.58	0.138
16.66	112.70	0.138
16.68	112.81	0.138
16.71	112.93	0.138
16.73	113.05	0.138
16.75	113.16	0.138
16.78	113.28	0.138
16.80	113.40	0.138
16.82	113.51	0.138
16.85	113.63	0.138
16.87	113.75	0.138
16.89	113.86	0.139
16.92	113.98	0.139
16.94	114.10	0.139
16.96	114.21	0.139
16.99	114.33	0.139
17.01	114.45	0.139
17.03	114.56	0.139
17.06	114.68	0.139
17.08	114.80	0.139
17.10	114.92	0.139
17.13	115.03	0.139
17.15	115.15	0.139
17.17	115.27	0.139
17.20	115.38	0.139
17.22	115.50	0.139
17.24	115.61	0.139
17.27	115.73	0.139
17.29	115.85	0.139
17.31	115.96	0.139
17.34	116.08	0.139
17.36	116.20	0.140
17.38	116.32	0.140
17.41	116.43	0.140
17.43	116.55	0.140
17.45	116.67	0.140
17.48	116.78	0.140
17.50	116.90	0.140
17.52	117.02	0.140
17.55	117.13	0.140
17.57	117.25	0.140
17.59	117.37	0.140
17.62	117.48	0.140
17.64	117.60	0.140
17.66	117.72	0.140
17.69	117.83	0.140
17.71	117.95	0.140
17.73	118.07	0.140
17.76	118.18	0.140
17.78	118.30	0.141
17.80	118.41	0.141
17.83	118.53	0.141
17.85	118.65	0.141
17.87	118.77	0.141
17.90	118.88	0.141
17.92	119.00	0.141
17.94	119.12	0.141
17.97	119.23	0.141
17.99	119.35	0.141
18.01	119.47	0.141
18.04	119.58	0.141
18.06	119.70	0.141
18.08	119.82	0.141
18.11	119.93	0.141
18.13	120.05	0.141
18.15	120.17	0.141
18.18	120.28	0.141
18.20	120.40	0.142
18.22	120.52	0.142
18.25	120.63	0.142
18.27	120.75	0.142
18.29	120.87	0.142
18.32	120.98	0.142
18.34	121.10	0.142
18.36	121.22	0.142
18.39	121.33	0.142
18.41	121.45	0.142
18.43	121.57	0.142
18.46	121.68	0.142
18.48	121.80	0.142
18.50	121.92	0.142
18.53	122.03	0.142
18.55	122.15	0.142
18.57	122.27	0.142
18.60	122.38	0.143
18.62	122.50	0.143
18.64	122.62	0.143
18.67	122.73	0.143
18.69	122.85	0.143
18.71	122.97	0.143
18.74	123.08	0.143
18.76	123.20	0.143
18.78	123.32	0.143
18.81	123.43	0.143
18.83	123.55	0.143
18.85	123.67	0.143
18.88	123.78	0.143
18.90	123.90	0.143
18.92	124.02	0.143
18.95	124.13	0.143
18.97	124.25	0.143
18.99	124.37	0.143
19.02	124.48	0.144
19.04	124.60	0.144
19.06	124.72	0.144
19.09	124.83	0.144
19.11	124.95	0.144
19.13	125.07	0.144
19.16	125.18	0.144
19.18	125.30	0.144
19.20	125.42	0.144
19.23	125.53	0.144
19.25	125.65	0.144
19.27	125.77	0.144
19.30	125.88	0.144
19.32	126.00	0.144
19.34	126.12	0.144
19.37	126.23	0.144
19.39	126.35	0.145
19.41	126.47	0.145
19.44	126.58	0.145
19.46	126.70	0.145
19.48	126.82	0.145
19.51	126.93	0.145
19.53	127.05	0.145
19.55	127.17	0.145
19.58	127.28	0.145
19.60	127.40	0.145
19.62	127.52	0.145
19.65	127.64	0.146
19.67	127.75	0.146
19.69	127.87	0.146
19.72	127.98	0.146
19.74	128.10	0.146
19.76	128.22	0.146
19.79	128.33	0.146
19.81	128.45	0.146
19.83	128.57	0.146
19.86	128.68	0.146
19.88	128.80	0.146
19.90	128.92	0.146
19.93	129.03	0.146
19.95	129.15	0.146
19.97	129.27	0.147
20.00	129.38	0.147
20.02	129.50	0.147
20.04	129.62	0.147
20.07	129.74	0.147
20.09	129.85	0.147
20.11	129.97	0.147
20.14	130.08	0.147
20.16	130.20	0.147
20.18	130.32	0.147
20.21	130.43	0.147
20.23	130.55	0.148
20.25	130.67	0.148
20.28	130.78	0.148
20.30	130.90	0.148
20.32	131.02	0.148
20.35	131.13	0.148
20.37	131.25	0.148
20.39	131.37	0.148
20.42	131.48	0.148
20.44	131.60	0.149
20.46	131.72	0.149
20.49	131.84	0.149
20.51	131.95	0.149
20.53	132.07	0.149
20.56	132.19	0.149
20.58	132.30	0.149
20.60	132.42	0.149
20.63	132.53	0.149
20.65	132.65	0.149
20.67	132.77	0.150
20.70	132.88	0.150
20.72	133.00	0.150
20.74	133.12	0.150
20.77	133.23	0.150
20.79	133.35	0.150
20.81	133.47	0.150
20.84	133.58	0.151
20.86	133.70	0.151
20.88	133.82	0.151
20.91	133.94	0.151
20.93	134.05	0.151
20.95	134.17	0.151
20.98	134.29	0.152
21.00	134.40	0.152
21.02	134.52	0.152
21.05	134.63	0.152
21.07	134.75	0.152
21.09	134.87	0.152
21.12	134.98	0.152
21.14	135.10	0.153
21.16	135.22	0.153
21.19	135.33	0.153
21.21	135.45	0.153
21.23	135.57	0.153
21.26	135.69	0.154
21.28	135.80	0.154
21.30	135.92	0.154
21.33	136.03	0.154
21.35	136.15	0.154
21.37	136.27	0.154
21.40	136.38	0.155
21.42	136.50	0.155
21.44	136.62	0.155
21.47	136.73	0.155
21.49	136.85	0.156
21.51	136.97	0.156
21.54	137.08	0.156
21.56	137.20	0.156
21.58	137.32	0.157
21.61	137.43	0.157
21.63	137.55	0.157
21.65	137.67	0.157
21.68	137.78	0.158
21.70	137.90	0.158
21.72	138.02	0.158
21.75	138.13	0.159
21.77	138.25	0.159
21.79	138.37	0.159
21.82	138.48	0.159
21.84	138.60	0.160
21.86	138.72	0.160
21.89	138.83	0.160
21.91	138.95	0.161
21.93	139.07	0.161
21.96	139.18	0.161
21.98	139.30	0.162
22.00	139.41	0.162
22.03	139.53	0.163
22.05	139.65	0.163
22.07	139.76	0.163
22.10	139.88	0.164
22.12	140.00	0.164
22.14	140.11	0.165
22.17	140.23	0.165
22.19	140.35	0.166
22.21	140.46	0.166
22.24	140.58	0.167
22.26	140.70	0.168
22.28	140.81	0.168
22.31	140.93	0.169
22.33	141.05	0.169
22.35	141.16	0.170
22.38	141.28	0.170
22.40	141.40	0.171
22.42	141.51	0.172
22.45	141.63	0.172
22.47	141.74	0.173
22.49	141.86	0.174
22.52	141.98	0.175
22.54	142.10	0.176
22.56	142.21	0.177
22.59	142.33	0.177
22.61	142.44	0.178
22.63	142.56	0.179
22.66	142.68	0.180
22.68	142.79	0.182
22.70	142.91	0.183
22.73	143.03	0.184
22.75	143.14	0.185
22.77	143.26	0.187
22.80	143.37	0.188
22.82	143.49	0.189
22.84	143.61	0.191
22.87	143.72	0.192
22.89	143.84	0.194
22.91	143.96	0.195
22.94	144.07	0.197
22.96	144.19	0.198
22.98	144.31	0.200
23.01	144.42	0.202
23.03	144.54	0.203
23.05	144.65	0.205
23.08	144.77	0.207
23.10	144.89	0.210
23.12	145.00	0.212
23.15	145.12	0.214
23.17	145.23	0.217
23.19	145.35	0.219
23.22	145.47	0.221
23.24	145.58	0.224
23.26	145.70	0.226
23.29	145.81	0.229
23.31	145.93	0.231
23.33	146.05	0.234
23.36	146.16	0.238
23.38	146.28	0.240
23.40	146.39	0.244
23.43	146.51	0.246
23.45	146.63	0.250
23.47	146.74	0.253
23.50	146.86	0.257
23.52	146.97	0.259
23.54	147.09	0.263
23.57	147.20	0.267
23.59	147.32	0.271
23.61	147.43	0.274
23.64	147.55	0.279
23.66	147.66	0.283
23.68	147.78	0.287
23.71	147.90	0.292
23.73	148.01	0.297
23.75	148.13	0.302
23.78	148.24	0.307
23.80	148.36	0.311
23.82	148.47	0.317
23.85	148.59	0.322
23.87	148.70	0.327
23.89	148.82	0.333
23.92	148.93	0.339
23.94	149.05	0.344
23.96	149.16	0.351
23.99	149.28	0.358
24.01	149.39	0.365
24.03	149.51	0.371
24.06	149.62	0.378
24.08	149.73	0.385
24.10	149.85	0.394
24.13	149.96	0.401
24.15	150.08	0.409
24.17	150.19	0.418
24.20	150.31	0.428
24.22	150.42	0.437
24.24	150.54	0.446
24.27	150.65	0.455
24.29	150.76	0.467
24.31	150.88	0.475
24.34	150.99	0.485
24.36	151.10	0.497
24.38	151.22	0.508
24.41	151.33	0.521
24.43	151.44	0.533
24.45	151.56	0.543
24.48	151.67	0.558
24.50	151.78	0.572
24.52	151.90	0.586
24.55	152.01	0.600
24.57	152.12	0.613
24.59	152.23	0.631
24.62	152.34	0.646
24.64	152.46	0.664
24.66	152.57	0.680
24.69	152.68	0.697
24.71	152.79	0.716
24.73	152.90	0.734
24.76	153.01	0.754
24.78	153.12	0.775
24.80	153.23	0.795
24.83	153.34	0.817
24.85	153.45	0.839
24.87	153.56	0.862
24.90	153.67	0.886
24.92	153.78	0.911
24.94	153.89	0.937
24.97	154.00	0.964
24.99	154.11	0.990
25.01	154.22	1.020
25.04	154.33	1.049
25.06	154.44	1.078
25.08	154.54	1.109
25.11	154.65	1.140
25.13	154.76	1.173
25.15	154.86	1.211
25.18	154.97	1.248
25.20	155.07	1.288
25.22	155.18	1.328
25.25	155.28	1.372
25.27	155.38	1.420
25.29	155.49	1.474
25.32	155.59	1.533
25.34	155.69	1.598
25.36	155.79	1.668
25.39	155.88	1.745
25.41	155.98	1.832
25.43	156.07	1.924
25.46	156.16	2.016
25.48	156.25	2.119
25.50	156.33	2.214
25.53	156.42	2.290
25.55	156.51	2.353
25.57	156.61	2.414
25.60	156.70	2.480
25.62	156.80	2.536
25.64	156.90	2.593
25.67	157.00	2.652
25.69	157.09	2.713
25.71	157.19	2.775
25.74	157.29	2.834
25.76	157.39	2.888
25.78	157.49	2.938
25.81	157.59	2.982
25.83	157.69	3.011
25.85	157.79	3.028
25.88	157.91	3.013
25.90	158.02	2.950
25.92	158.15	2.853
25.95	158.29	2.718
25.97	158.44	2.551
25.99	158.60	2.357
26.02	158.77	2.143
26.04	158.94	1.911
26.06	159.12	1.676
26.09	159.31	1.446
26.11	159.49	1.237
26.13	159.68	1.055
26.16	159.85	0.904
26.18	160.02	0.778
26.20	160.18	0.668
26.23	160.34	0.583
26.25	160.49	0.511
26.27	160.63	0.453
26.30	160.77	0.405
26.32	160.91	0.367
26.34	161.04	0.336
26.37	161.17	0.313
26.39	161.30	0.296
26.41	161.42	0.284
26.44	161.54	0.274
26.46	161.67	0.267
26.48	161.79	0.262
26.51	161.90	0.258
26.53	162.02	0.254
26.55	162.14	0.253
26.58	162.26	0.251
26.60	162.38	0.250
26.62	162.50	0.249
26.65	162.61	0.249
26.67	162.73	0.248
26.69	162.85	0.248
26.72	162.96	0.248
26.74	163.08	0.247
26.76	163.20	0.247
26.79	163.31	0.247
26.81	163.43	0.247
26.83	163.55	0.247
26.86	163.66	0.247
26.88	163.78	0.247
26.90	163.90	0.247
26.93	164.01	0.246
26.95	164.13	0.246
26.97	164.25	0.246
27.00	164.36	0.246
27.02	164.48	0.247
27.04	164.60	0.247
27.07	164.71	0.247
27.09	164.83	0.247
27.11	164.95	0.247
27.14	165.06	0.247
27.16	165.18	0.247
27.18	165.30	0.247
27.21	165.41	0.247
27.23	165.53	0.248
27.25	165.65	0.248
27.28	165.76	0.248
27.30	165.88	0.248
27.32	166.00	0.248
27.35	166.11	0.248
27.37	166.23	0.249
27.39	166.35	0.249
27.42	166.46	0.249
27.44	166.58	0.249
27.46	166.70	0.249
27.49	166.81	0.250
27.51	166.93	0.250
27.53	167.05	0.250
27.56	167.16	0.250
27.58	167.28	0.251
27.60	167.40	0.251
27.63	167.51	0.251
27.65	167.63	0.252
27.67	167.75	0.252
27.70	167.86	0.252
27.72	167.98	0.252
27.74	168.10	0.253
27.77	168.21	0.253
27.79	168.33	0.253
27.81	168.44	0.253
27.84	168.56	0.254
27.86	168.68	0.254
27.88	168.79	0.254
27.91	168.91	0.255
27.93	169.03	0.255
27.95	169.14	0.255
27.98	169.26	0.255
28.00	169.38	0.256
28.02	169.49	0.256
28.05	169.61	0.256
28.07	169.73	0.257
28.09	169.84	0.257
28.12	169.96	0.257
28.14	170.08	0.258
28.16	170.19	0.258
28.19	170.31	0.258
28.21	170.43	0.259
28.23	170.55	0.259
28.26	170.66	0.259
28.28	170.78	0.260
28.30	170.89	0.260
28.33	171.01	0.260
28.35	171.13	0.261
28.37	171.24	0.261
28.40	171.36	0.261
28.42	171.48	0.262
28.44	171.59	0.262
28.47	171.71	0.262
28.49	171.83	0.263
28.51	171.94	0.263
28.54	172.06	0.263
28.56	172.18	0.264
28.58	172.29	0.264
28.61	172.41	0.264
28.63	172.53	0.265
28.65	172.64	0.265
28.68	172.76	0.265
28.70	172.88	0.266
28.72	172.99	0.266
28.75	173.11	0.267
28.77	173.23	0.267
28.79	173.34	0.267
28.82	173.46	0.267
28.84	173.57	0.268
28.86	173.69	0.268
28.89	173.81	0.269
28.91	173.92	0.269
28.93	174.04	0.269
28.96	174.16	0.270
28.98	174.27	0.270
29.00	174.39	0.271
29.03	174.51	0.271
29.05	174.62	0.272
29.07	174.74	0.272
29.10	174.86	0.272
29.12	174.98	0.273
29.14	175.09	0.273
29.17	175.21	0.273
29.19	175.32	0.274
29.21	175.44	0.274
29.24	175.56	0.274
29.26	175.67	0.275
29.28	175.79	0.275
29.31	175.91	0.276
29.33	176.02	0.276
29.35	176.14	0.277
29.38	176.26	0.277
29.40	176.37	0.277
29.42	176.49	0.278
29.45	176.61	0.278
29.47	176.72	0.278
29.49	176.84	0.279
29.52	176.96	0.279
29.54	177.07	0.280
29.56	177.19	0.280
29.59	177.31	0.281
29.61	177.42	0.281
29.63	177.54	0.282
29.66	177.66	0.282
29.68	177.77	0.283
29.70	177.89	0.283
29.73	178.01	0.284
29.75	178.12	0.284
29.77	178.24	0.284
29.80	178.36	0.285
29.82	178.47	0.285
29.84	178.59	0.286
29.87	178.71	0.286
29.89	178.82	0.286
29.91	178.94	0.287
29.94	179.05	0.287
29.96	179.17	0.287
29.98	179.29	0.288
30.01	179.40	0.288
30.03	179.52	0.289
30.05	179.64	0.289
30.08	179.75	0.290
30.10	179.87	0.290
30.12	179.99	0.291
30.15	180.10	0.291
30.17	180.22	0.291
30.19	180.34	0.292
30.22	180.45	0.292
30.24	180.57	0.293
30.26	180.69	0.293
30.29	180.80	0.294
30.31	180.92	0.294
30.33	181.04	0.295
30.36	181.15	0.295
30.38	181.27	0.295
30.40	181.38	0.296
30.43	181.50	0.296
30.45	181.62	0.297
30.47	181.73	0.297
30.50	181.85	0.298
30.52	181.97	0.298
30.54	182.08	0.299
30.57	182.20	0.299
30.59	182.32	0.300
30.61	182.43	0.301
30.64	182.55	0.301
30.66	182.67	0.302
30.68	182.78	0.302
30.71	182.90	0.303
30.73	183.02	0.303
30.75	183.13	0.303
30.78	183.25	0.304
30.80	183.37	0.304
30.82	183.48	0.305
30.85	183.60	0.305
30.87	183.72	0.305
30.89	183.83	0.306
30.92	183.95	0.306
30.94	184.06	0.306
30.96	184.18	0.307
30.99	184.30	0.307
31.01	184.42	0.308
31.03	184.53	0.308
31.06	184.65	0.309
31.08	184.77	0.309
31.10	184.88	0.310
31.13	185.00	0.310
31.15	185.12	0.310
31.17	185.23	0.311
31.20	185.35	0.311
31.22	185.47	0.312
31.24	185.58	0.312
31.27	185.70	0.312
31.29	185.82	0.313
31.31	185.93	0.313
31.34	186.05	0.313
31.36	186.16	0.314
31.38	186.28	0.314
31.41	186.40	0.314
31.43	186.51	0.315
31.45	186.63	0.315
31.48	186.75	0.316
31.50	186.86	0.316
31.52	186.98	0.317
31.55	187.10	0.317
31.57	187.21	0.317
31.59	187.33	0.318
31.62	187.44	0.318
31.64	187.56	0.318
31.66	187.68	0.319
31.69	187.80	0.319
31.71	187.91	0.320
31.73	188.03	0.320
31.76	188.15	0.321
31.78	188.26	0.321
31.80	188.38	0.322
31.83	188.50	0.322
31.85	188.61	0.322
31.87	188.73	0.323
31.90	188.85	0.323
31.92	188.96	0.324
31.94	189.08	0.324
31.97	189.20	0.324
31.99	189.31	0.325
32.01	189.43	0.325
32.04	189.54	0.326
32.06	189.66	0.326
32.08	189.78	0.326
32.11	189.89	0.327
32.13	190.01	0.328
32.15	190.13	0.328
32.18	190.24	0.328
32.20	190.36	0.329
32.22	190.48	0.329
32.25	190.59	0.330
32.27	190.71	0.330
32.29	190.82	0.331
32.32	190.94	0.331
32.34	191.06	0.332
32.36	191.18	0.332
32.39	191.29	0.333
32.41	191.41	0.333
32.43	191.52	0.334
32.46	191.64	0.334
32.48	191.76	0.334
32.50	191.87	0.335
32.53	191.99	0.335
32.55	192.11	0.336
32.57	192.23	0.337
32.60	192.34	0.337
32.62	192.46	0.337
32.64	192.58	0.338
32.67	192.69	0.338
32.69	192.81	0.339
32.71	192.92	0.339
32.74	193.04	0.340
32.76	193.16	0.340
32.78	193.27	0.341
32.81	193.39	0.341
32.83	193.51	0.342
32.85	193.62	0.343
32.88	193.74	0.344
32.90	193.86	0.345
32.92	193.97	0.345
32.95	194.09	0.347
32.97	194.21	0.347
32.99	194.32	0.348
33.02	194.44	0.349
33.04	194.56	0.349
33.06	194.67	0.350
33.09	194.79	0.351
33.11	194.90	0.352
33.13	195.02	0.354
33.16	195.14	0.355
33.18	195.25	0.357
33.20	195.37	0.359
33.23	195.49	0.362
33.25	195.60	0.366
33.27	195.72	0.372
33.30	195.83	0.398
33.32	195.94	0.461
33.34	196.05	0.464
33.37	196.16	0.462
33.39	196.28	0.458
33.41	196.39	0.456
33.44	196.51	0.453
33.46	196.63	0.451
33.48	196.74	0.450
33.51	196.86	0.448
33.53	196.98	0.446
33.55	197.10	0.444
33.58	197.21	0.443
33.60	197.33	0.442
33.62	197.45	0.441
33.65	197.56	0.440
33.67	197.68	0.439
33.69	197.80	0.439
33.72	197.91	0.438
33.74	198.03	0.437
33.76	198.15	0.437
33.79	198.27	0.436
33.81	198.38	0.436
33.83	198.50	0.435
33.86	198.62	0.435
33.88	198.73	0.434
33.90	198.85	0.434
33.93	198.97	0.434
33.95	199.08
33.97	199.20
33.99