File: DSC/2025_04_23_CBN_Theobromine_MC_n60C_150C_5Cmin_x3.csv
Filename,2025_04_23_CBN_Theobromine_MC_n60C_150C_5Cmin_x3
Instrument name,DSC2A-00468 (192.168.1.100)
Operator,Yarger
rundate,4/23/2025
Sample name,2025_04_23_CBN_Theobromine_MC_n60C_150C_5Cmin_x3
proceduresegments,Data Off ; Equilibrate -60.00 °C; Data On ; Ramp 5.00 °C/min to 150.00 °C; Data Off ; Isothermal 1.0 min; Data On ; Ramp 5.00 °C/min to -60.00 °C; Data Off ; Isothermal 1.0 min; Data On ; Ramp 5.00 °C/min to 150.00 °C; Data Off ; Isothermal 1.0 min; Data On ; Ramp 5.00 °C/min to -60.00 °C; Data Off ; Isothermal 1.0 min; Data On ; Ramp 5.00 °C/min to 150.00 °C
[File Parameters]
Run date,4/23/2025 11:13:05 PM
Trios version,5.1.1.46572
Original File Name,
Current File Name,D:\DSC2500\JYarger\2025_04_23_CBN_Theobromine_MC_n60C_150C_5Cmin_x3.tri
[Procedure]
Procedure Name,CBN_Theobromine_n60_150C_5Cmin_x3
Sample Name,2025_04_23_CBN_Theobromine_MC_n60C_150C_5Cmin_x3
Sample Mass,6.39 mg
Reference Sample Mass,0 mg
Pan Mass,52.89 mg
Pan Number,32
Reference Pan Mass,52.66 mg
Reference Pan Number,19
Pan Type,Tzero Aluminum Hermetic
Comments,Al Hermetic DSC Consumables sealed Pan/Lid.
Project Name,CA
Operator,Yarger
Test,Custom
Unload Max Temperature,30
Unload Min Temperature,30
Load Max Temperature,30
Load Min Temperature,30
Stop on Gas Flow Error,Yes
[Signal List]
Signal #1,Time (min)
Signal #2,Temperature (°C)
Signal #3,Heat Flow (mW)
Signal #4,Delta T (µV)
Signal #5,Delta Tzero (µV)
Signal #6,Tzero Temperature (°C)
Signal #7,Cell Purge (mL/min)
Signal #8,Heater Temp (°C)
Signal #9,Power Delivered (W)
Signal #10,Reference Junction Temperature (°C)
Signal #11,Flange Temperature (°C)
Signal #12,Heat Flow Phase (rad)
Signal #13,Total Heat Capacity (J/°C)
Signal #14,Heat Capacity (J/°C)
[Configuration]
Company Name,ASU
Instrument Name,DSC2A-00468
Instrument Type,DSC2500
Serial Number,DSC2A-00468
IP,192.168.1.100
Location of Instrument,MRRC
DisplayType,Unknown
Sample Interval ,0.1 s/pt
Selected Heat Flow,T4P
Exotherm Direction,Down
Cell Serial,DRC2-00792
Lid Type,Standard
Cooler,RCS 90
Leave Cooler on at End of Sequence,On
Gas 2,Nitrogen
Gas Selected,Channel 1
Flow Rate,50 mL/min
Secondary Purge,On
Licensed Heat Flow,Heat Flow T4P
Modulation Licensed,Yes
[Versions]
Common IDD Version,1
Cortex Version,VER 2.10.2.31
Driver,5.0.0.6
GDM Version,1.0.3.3
TouchscreenVersion,1.0.0.16145
FEP Version,1.2.1.21
FEP Bootloader,2.0.0.5
AutoSampler Version,2.1.1.26
Auto Sampler Bootloader,2.0.0.5
FCM Version,1.1.0.3
FCM Bootloader,2.0.0.5
[Experiment Logs]
Experiment Log Entry # 1,Air Cool is off.
Experiment Log Entry # 3,Data On set to 0
Experiment Log Entry # 5,Equilibrate Segment -60 (C) Started
Experiment Log Entry # 7,Data On set to 1
Experiment Log Entry # 9,Ramp Segment 5 C/min to 150 Started
Experiment Log Entry # 11,Data On set to 0
Experiment Log Entry # 13,Isothermal Segment 1 min started
Experiment Log Entry # 15,Data On set to 1
Experiment Log Entry # 17,Ramp Segment 5 C/min to -60 Started
Experiment Log Entry # 19,Data On set to 0
Experiment Log Entry # 21,Isothermal Segment 1 min started
Experiment Log Entry # 23,Data On set to 1
Experiment Log Entry # 25,Ramp Segment 5 C/min to 150 Started
Experiment Log Entry # 27,Data On set to 0
Experiment Log Entry # 29,Isothermal Segment 1 min started
Experiment Log Entry # 31,Data On set to 1
Experiment Log Entry # 33,Ramp Segment 5 C/min to -60 Started
Experiment Log Entry # 35,Auto sampler has detected that FEP has gone offline
Experiment Log Entry # 37,Data On set to 0
Experiment Log Entry # 39,Isothermal Segment 1 min started
Experiment Log Entry # 41,Data On set to 1
Experiment Log Entry # 43,Ramp Segment 5 C/min to 150 Started
[Method Log]
Method Log Entry # 1,Data Off
Method Log Entry # 2,Equilibrate -60 °C
Method Log Entry # 3,Data On
Method Log Entry # 4,(Ramp 126938) Ramp 5 °C/minute to 150 °C
Method Log Entry # 5,Data Off
Method Log Entry # 6,Isothermal 1 minutes
Method Log Entry # 7,Data On
Method Log Entry # 8,(Ramp 126942) Ramp 5 °C/minute to -60 °C
Method Log Entry # 9,Data Off
Method Log Entry # 10,Isothermal 1 minutes
Method Log Entry # 11,Data On
Method Log Entry # 12,(Ramp 126946) Ramp 5 °C/minute to 150 °C
Method Log Entry # 13,Data Off
Method Log Entry # 14,Isothermal 1 minutes
Method Log Entry # 15,Data On
Method Log Entry # 16,(Ramp 126950) Ramp 5 °C/minute to -60 °C
Method Log Entry # 17,Data Off
Method Log Entry # 18,Isothermal 1 minutes
Method Log Entry # 19,Data On
Method Log Entry # 20,(Ramp 126954) Ramp 5 °C/minute to 150 °C
Cell Serial,DRC2-00792
[T1 Calibration]
Slope,-0.008529666
Offset,9.636258
Initial Temperature,98.23
GUID,f8bfdadc-4977-4fdf-ba6d-0ba9134940c3
[TZero Calibration]
Date Applied,11/29/2022 4:06:13 PM
Description,From -89.059 °C to 396.009 °C at 20.000°C/min
Gas Type,Nitrogen
Pan Type,None
Source Files 1,C:\Users\yargerlab\Desktop\DSC Data\General\TZero_calibration_11_29_22_2nd(2).tri
Source Files 2,C:\Users\yargerlab\Desktop\DSC Data\General\TZero_calibration_11_29_22_2nd(3).tri
Delta T Offset,13.05235
Delta T Slope,-0.007271007
Delta T0 Offset,-13.69128
Delta T0 Slope,0.06063341
[Temperature Calibration]
Date Applied,11/29/2022 7:12:28 PM
Description,From 106.590 °C to 186.590 °C at 10.000°C/min
Gas Type,Nitrogen
Pan Type,Tzero Aluminum Hermetic
Source Files 1,C:\Users\yargerlab\Desktop\DSC Data\General\Indium(6).tri
Measured 1,157.391
Known 1,156.598
[Cell Constant Calibration]
Date Applied,11/29/2022 7:12:29 PM
Description,From 106.590 °C to 186.590 °C at 10.000°C/min
Gas Type,Nitrogen
Pan Type,Tzero Aluminum Hermetic
Source Files 1,C:\Users\yargerlab\Desktop\DSC Data\General\Indium(6).tri
T4P KCell,1.006051
Onset Slope,63.26126 mW/°C
[Direct Cp Calibration]
Date Applied,11/30/2022 11:04:51 AM
Description,From -79.983 °C to 298.409 °C at 10.000°C/min
Gas Type,Nitrogen
Pan Type,Tzero Aluminum Hermetic
Source Files 1,C:\Users\yargerlab\Desktop\DSC Data\General\Sapphire_Heat_Capacity_11_30_22.tri
[Rev Cp Calibration]
Date Applied,11/30/2022 1:58:51 PM
Description,From -79.996 °C to 292.812 °C at 3.000°C/min
Gas Type,Nitrogen
Pan Type,Tzero Aluminum Hermetic
Source Files 1,C:\Users\yargerlab\Desktop\DSC Data\General\Sapphire_MDSC_Calibration_11_30_22.tri
[step]
Ramp 5.00 °C/min to 150.00 °C
Time,Temperature,Heat Flow (Normalized)
min,°C,W/g
0.00,-59.67,-0.060
0.03,-59.69,-0.059
0.06,-59.70,-0.052
0.08,-59.67,-0.057
0.11,-59.62,-0.065
0.14,-59.54,-0.065
0.17,-59.45,-0.044
0.20,-59.35,-0.025
0.23,-59.24,-0.005
0.26,-59.12,0.011
0.28,-59.00,0.022
0.31,-58.88,0.031
0.34,-58.76,0.040
0.37,-58.63,0.046
0.40,-58.50,0.051
0.43,-58.37,0.055
0.45,-58.24,0.059
0.48,-58.10,0.061
0.51,-57.97,0.064
0.54,-57.83,0.065
0.57,-57.70,0.066
0.60,-57.56,0.067
0.62,-57.42,0.068
0.65,-57.28,0.069
0.68,-57.15,0.069
0.71,-57.01,0.070
0.74,-56.87,0.070
0.77,-56.73,0.071
0.79,-56.59,0.071
0.82,-56.45,0.071
0.85,-56.32,0.072
0.88,-56.18,0.072
0.91,-56.04,0.073
0.93,-55.90,0.073
0.96,-55.76,0.073
0.99,-55.62,0.074
1.02,-55.48,0.074
1.05,-55.34,0.074
1.08,-55.20,0.074
1.11,-55.06,0.074
1.13,-54.92,0.075
1.16,-54.78,0.075
1.19,-54.64,0.075
1.22,-54.50,0.075
1.25,-54.36,0.075
1.28,-54.22,0.075
1.30,-54.07,0.075
1.33,-53.93,0.075
1.36,-53.79,0.076
1.39,-53.65,0.076
1.42,-53.51,0.076
1.44,-53.37,0.076
1.47,-53.23,0.076
1.50,-53.09,0.076
1.53,-52.95,0.076
1.56,-52.80,0.076
1.59,-52.66,0.076
1.62,-52.52,0.076
1.64,-52.38,0.076
1.67,-52.24,0.076
1.70,-52.10,0.076
1.73,-51.96,0.076
1.76,-51.82,0.076
1.78,-51.68,0.076
1.81,-51.54,0.076
1.84,-51.39,0.076
1.87,-51.25,0.076
1.90,-51.11,0.076
1.93,-50.97,0.076
1.96,-50.83,0.076
1.98,-50.69,0.076
2.01,-50.55,0.076
2.04,-50.41,0.076
2.07,-50.26,0.076
2.10,-50.12,0.076
2.13,-49.98,0.076
2.15,-49.84,0.076
2.18,-49.70,0.076
2.21,-49.56,0.076
2.24,-49.42,0.076
2.27,-49.27,0.076
2.29,-49.13,0.076
2.32,-48.99,0.076
2.35,-48.85,0.076
2.38,-48.71,0.076
2.41,-48.56,0.076
2.44,-48.42,0.076
2.46,-48.28,0.076
2.49,-48.14,0.076
2.52,-48.00,0.076
2.55,-47.86,0.076
2.58,-47.72,0.076
2.61,-47.58,0.076
2.64,-47.43,0.076
2.66,-47.29,0.076
2.69,-47.15,0.076
2.72,-47.01,0.076
2.75,-46.87,0.076
2.78,-46.73,0.076
2.81,-46.58,0.076
2.83,-46.44,0.076
2.86,-46.30,0.076
2.89,-46.16,0.076
2.92,-46.02,0.076
2.95,-45.88,0.076
2.98,-45.74,0.076
3.00,-45.59,0.076
3.03,-45.45,0.076
3.06,-45.31,0.076
3.09,-45.17,0.076
3.12,-45.03,0.076
3.14,-44.89,0.076
3.17,-44.75,0.076
3.20,-44.60,0.076
3.23,-44.46,0.076
3.26,-44.32,0.076
3.29,-44.18,0.076
3.31,-44.04,0.076
3.34,-43.90,0.076
3.37,-43.75,0.076
3.40,-43.61,0.076
3.43,-43.47,0.076
3.46,-43.33,0.076
3.49,-43.19,0.076
3.51,-43.04,0.076
3.54,-42.90,0.076
3.57,-42.76,0.076
3.60,-42.62,0.076
3.63,-42.48,0.076
3.66,-42.34,0.076
3.68,-42.19,0.076
3.71,-42.05,0.076
3.74,-41.91,0.076
3.77,-41.77,0.076
3.80,-41.63,0.076
3.83,-41.49,0.076
3.85,-41.34,0.076
3.88,-41.20,0.076
3.91,-41.06,0.076
3.94,-40.92,0.076
3.97,-40.78,0.076
3.99,-40.63,0.076
4.02,-40.49,0.076
4.05,-40.35,0.076
4.08,-40.21,0.076
4.11,-40.07,0.076
4.14,-39.93,0.076
4.16,-39.78,0.076
4.19,-39.64,0.076
4.22,-39.50,0.076
4.25,-39.36,0.076
4.28,-39.22,0.076
4.31,-39.07,0.076
4.34,-38.93,0.076
4.36,-38.79,0.076
4.39,-38.65,0.076
4.42,-38.51,0.076
4.45,-38.37,0.076
4.48,-38.22,0.076
4.50,-38.08,0.076
4.53,-37.94,0.076
4.56,-37.80,0.076
4.59,-37.66,0.076
4.62,-37.51,0.076
4.65,-37.37,0.076
4.68,-37.23,0.076
4.70,-37.09,0.076
4.73,-36.95,0.076
4.76,-36.80,0.076
4.79,-36.66,0.076
4.82,-36.52,0.076
4.85,-36.38,0.076
4.87,-36.24,0.076
4.90,-36.10,0.076
4.93,-35.95,0.076
4.96,-35.81,0.076
4.99,-35.67,0.076
5.01,-35.53,0.076
5.04,-35.39,0.076
5.07,-35.25,0.076
5.10,-35.10,0.076
5.13,-34.96,0.076
5.16,-34.82,0.076
5.19,-34.68,0.076
5.21,-34.54,0.076
5.24,-34.39,0.076
5.27,-34.25,0.076
5.30,-34.11,0.076
5.33,-33.97,0.076
5.35,-33.83,0.076
5.38,-33.68,0.076
5.41,-33.54,0.076
5.44,-33.40,0.076
5.47,-33.26,0.076
5.50,-33.12,0.076
5.53,-32.97,0.076
5.55,-32.83,0.076
5.58,-32.69,0.076
5.61,-32.55,0.076
5.64,-32.41,0.076
5.67,-32.27,0.076
5.70,-32.13,0.076
5.72,-31.98,0.076
5.75,-31.84,0.076
5.78,-31.70,0.076
5.81,-31.56,0.076
5.84,-31.41,0.076
5.86,-31.27,0.076
5.89,-31.13,0.076
5.92,-30.99,0.076
5.95,-30.85,0.076
5.98,-30.71,0.076
6.01,-30.56,0.076
6.04,-30.42,0.076
6.06,-30.28,0.076
6.09,-30.14,0.076
6.12,-30.00,0.076
6.15,-29.85,0.076
6.18,-29.71,0.076
6.20,-29.57,0.076
6.23,-29.43,0.076
6.26,-29.29,0.076
6.29,-29.15,0.076
6.32,-29.00,0.076
6.35,-28.86,0.076
6.38,-28.72,0.076
6.40,-28.58,0.076
6.43,-28.44,0.076
6.46,-28.30,0.077
6.49,-28.15,0.077
6.52,-28.01,0.077
6.55,-27.87,0.077
6.57,-27.73,0.077
6.60,-27.59,0.077
6.63,-27.45,0.077
6.66,-27.30,0.077
6.69,-27.16,0.077
6.71,-27.02,0.077
6.74,-26.88,0.077
6.77,-26.74,0.077
6.80,-26.59,0.077
6.83,-26.45,0.077
6.86,-26.31,0.077
6.89,-26.17,0.077
6.91,-26.03,0.077
6.94,-25.89,0.077
6.97,-25.74,0.077
7.00,-25.60,0.077
7.03,-25.46,0.077
7.05,-25.32,0.077
7.08,-25.18,0.077
7.11,-25.03,0.077
7.14,-24.89,0.077
7.17,-24.75,0.077
7.20,-24.61,0.077
7.23,-24.47,0.077
7.25,-24.32,0.077
7.28,-24.18,0.077
7.31,-24.04,0.077
7.34,-23.90,0.077
7.37,-23.76,0.077
7.40,-23.62,0.077
7.42,-23.48,0.077
7.45,-23.33,0.077
7.48,-23.19,0.077
7.51,-23.05,0.077
7.54,-22.91,0.077
7.56,-22.77,0.077
7.59,-22.62,0.077
7.62,-22.48,0.077
7.65,-22.34,0.077
7.68,-22.20,0.077
7.71,-22.06,0.077
7.74,-21.91,0.077
7.76,-21.77,0.077
7.79,-21.63,0.077
7.82,-21.49,0.077
7.85,-21.35,0.077
7.88,-21.21,0.077
7.90,-21.07,0.077
7.93,-20.92,0.078
7.96,-20.78,0.078
7.99,-20.64,0.078
8.02,-20.50,0.078
8.05,-20.36,0.078
8.08,-20.22,0.078
8.10,-20.07,0.078
8.13,-19.93,0.078
8.16,-19.79,0.078
8.19,-19.65,0.078
8.22,-19.50,0.078
8.25,-19.36,0.078
8.27,-19.22,0.078
8.30,-19.08,0.078
8.33,-18.94,0.078
8.36,-18.80,0.078
8.39,-18.65,0.078
8.41,-18.51,0.078
8.44,-18.37,0.078
8.47,-18.23,0.078
8.50,-18.09,0.078
8.53,-17.95,0.078
8.56,-17.80,0.078
8.58,-17.66,0.078
8.61,-17.52,0.078
8.64,-17.38,0.078
8.67,-17.24,0.078
8.70,-17.10,0.078
8.73,-16.95,0.078
8.75,-16.81,0.078
8.78,-16.67,0.078
8.81,-16.53,0.078
8.84,-16.39,0.078
8.87,-16.24,0.078
8.90,-16.10,0.078
8.93,-15.96,0.078
8.95,-15.82,0.078
8.98,-15.68,0.078
9.01,-15.54,0.078
9.04,-15.40,0.078
9.07,-15.25,0.078
9.10,-15.11,0.078
9.12,-14.97,0.078
9.15,-14.83,0.078
9.18,-14.69,0.078
9.21,-14.54,0.078
9.24,-14.40,0.079
9.27,-14.26,0.079
9.29,-14.12,0.079
9.32,-13.98,0.079
9.35,-13.83,0.079
9.38,-13.69,0.079
9.41,-13.55,0.079
9.43,-13.41,0.079
9.46,-13.27,0.079
9.49,-13.12,0.079
9.52,-12.98,0.079
9.55,-12.84,0.079
9.58,-12.70,0.079
9.60,-12.56,0.079
9.63,-12.42,0.079
9.66,-12.28,0.079
9.69,-12.13,0.079
9.72,-11.99,0.079
9.75,-11.85,0.079
9.78,-11.71,0.079
9.80,-11.57,0.079
9.83,-11.43,0.079
9.86,-11.28,0.079
9.89,-11.14,0.079
9.92,-11.00,0.079
9.95,-10.86,0.079
9.97,-10.72,0.079
10.00,-10.57,0.079
10.03,-10.43,0.080
10.06,-10.29,0.080
10.09,-10.15,0.080
10.12,-10.01,0.080
10.14,-9.86,0.080
10.17,-9.72,0.080
10.20,-9.58,0.080
10.23,-9.44,0.080
10.26,-9.30,0.080
10.28,-9.16,0.080
10.31,-9.01,0.080
10.34,-8.87,0.080
10.37,-8.73,0.080
10.40,-8.59,0.080
10.43,-8.45,0.080
10.45,-8.31,0.080
10.48,-8.16,0.080
10.51,-8.02,0.080
10.54,-7.88,0.080
10.57,-7.74,0.080
10.60,-7.60,0.080
10.63,-7.45,0.080
10.65,-7.31,0.080
10.68,-7.17,0.080
10.71,-7.03,0.080
10.74,-6.89,0.080
10.77,-6.75,0.080
10.80,-6.60,0.080
10.82,-6.46,0.080
10.85,-6.32,0.080
10.88,-6.18,0.080
10.91,-6.04,0.080
10.94,-5.90,0.081
10.97,-5.75,0.081
10.99,-5.61,0.081
11.02,-5.47,0.081
11.05,-5.33,0.081
11.08,-5.19,0.081
11.11,-5.04,0.081
11.13,-4.90,0.081
11.16,-4.76,0.081
11.19,-4.62,0.081
11.22,-4.48,0.081
11.25,-4.34,0.081
11.28,-4.19,0.081
11.30,-4.05,0.081
11.33,-3.91,0.081
11.36,-3.77,0.081
11.39,-3.63,0.081
11.42,-3.48,0.081
11.45,-3.34,0.081
11.48,-3.20,0.081
11.50,-3.06,0.081
11.53,-2.92,0.081
11.56,-2.78,0.081
11.59,-2.64,0.081
11.62,-2.49,0.081
11.65,-2.35,0.081
11.67,-2.21,0.081
11.70,-2.07,0.082
11.73,-1.93,0.081
11.76,-1.79,0.082
11.79,-1.64,0.082
11.82,-1.50,0.082
11.84,-1.36,0.082
11.87,-1.22,0.082
11.90,-1.08,0.082
11.93,-0.93,0.082
11.96,-0.79,0.082
11.98,-0.65,0.082
12.01,-0.51,0.082
12.04,-0.37,0.082
12.07,-0.23,0.082
12.10,-0.08,0.082
12.13,0.06,0.082
12.15,0.20,0.082
12.18,0.34,0.082
12.21,0.48,0.082
12.24,0.63,0.082
12.27,0.77,0.082
12.30,0.91,0.082
12.33,1.05,0.082
12.35,1.19,0.082
12.38,1.33,0.082
12.41,1.48,0.082
12.44,1.62,0.082
12.47,1.76,0.083
12.50,1.90,0.083
12.52,2.04,0.083
12.55,2.18,0.083
12.58,2.33,0.083
12.61,2.47,0.083
12.64,2.61,0.083
12.67,2.75,0.083
12.69,2.89,0.083
12.72,3.04,0.083
12.75,3.18,0.083
12.78,3.32,0.083
12.81,3.46,0.083
12.83,3.60,0.083
12.86,3.74,0.083
12.89,3.89,0.083
12.92,4.03,0.083
12.95,4.17,0.083
12.98,4.31,0.083
13.00,4.45,0.083
13.03,4.60,0.083
13.06,4.74,0.083
13.09,4.88,0.083
13.12,5.02,0.083
13.15,5.16,0.083
13.18,5.30,0.084
13.20,5.44,0.084
13.23,5.59,0.084
13.26,5.73,0.084
13.29,5.87,0.084
13.32,6.01,0.084
13.35,6.15,0.084
13.37,6.30,0.084
13.40,6.44,0.084
13.43,6.58,0.084
13.46,6.72,0.084
13.49,6.86,0.084
13.52,7.00,0.084
13.54,7.15,0.084
13.57,7.29,0.084
13.60,7.43,0.084
13.63,7.57,0.084
13.66,7.71,0.084
13.68,7.86,0.084
13.71,8.00,0.084
13.74,8.14,0.085
13.77,8.28,0.085
13.80,8.42,0.085
13.83,8.56,0.085
13.85,8.71,0.085
13.88,8.85,0.085
13.91,8.99,0.085
13.94,9.13,0.085
13.97,9.27,0.085
14.00,9.42,0.085
14.03,9.56,0.085
14.05,9.70,0.085
14.08,9.84,0.085
14.11,9.98,0.085
14.14,10.12,0.085
14.17,10.27,0.085
14.20,10.41,0.085
14.22,10.55,0.085
14.25,10.69,0.085
14.28,10.83,0.085
14.31,10.97,0.085
14.34,11.12,0.085
14.37,11.26,0.085
14.39,11.40,0.086
14.42,11.54,0.086
14.45,11.68,0.086
14.48,11.82,0.086
14.51,11.97,0.086
14.53,12.11,0.086
14.56,12.25,0.086
14.59,12.39,0.086
14.62,12.53,0.086
14.65,12.68,0.086
14.68,12.82,0.086
14.70,12.96,0.086
14.73,13.10,0.086
14.76,13.24,0.086
14.79,13.38,0.086
14.82,13.53,0.086
14.85,13.67,0.086
14.88,13.81,0.086
14.90,13.95,0.086
14.93,14.09,0.086
14.96,14.24,0.086
14.99,14.38,0.086
15.02,14.52,0.086
15.05,14.66,0.087
15.07,14.80,0.087
15.10,14.94,0.087
15.13,15.09,0.087
15.16,15.23,0.087
15.19,15.37,0.087
15.22,15.51,0.087
15.24,15.65,0.087
15.27,15.80,0.087
15.30,15.94,0.087
15.33,16.08,0.087
15.36,16.22,0.087
15.38,16.36,0.087
15.41,16.50,0.087
15.44,16.64,0.087
15.47,16.79,0.087
15.50,16.93,0.087
15.53,17.07,0.087
15.55,17.21,0.087
15.58,17.35,0.088
15.61,17.50,0.088
15.64,17.64,0.088
15.67,17.78,0.088
15.70,17.92,0.088
15.73,18.06,0.088
15.75,18.20,0.088
15.78,18.35,0.088
15.81,18.49,0.088
15.84,18.63,0.088
15.87,18.77,0.088
15.90,18.91,0.088
15.92,19.05,0.088
15.95,19.20,0.088
15.98,19.34,0.088
16.01,19.48,0.088
16.04,19.62,0.088
16.07,19.76,0.088
16.09,19.90,0.088
16.12,20.05,0.088
16.15,20.19,0.088
16.18,20.33,0.088
16.21,20.47,0.088
16.23,20.61,0.088
16.26,20.76,0.088
16.29,20.90,0.088
16.32,21.04,0.089
16.35,21.18,0.089
16.38,21.32,0.089
16.40,21.46,0.089
16.43,21.61,0.089
16.46,21.75,0.089
16.49,21.89,0.089
16.52,22.03,0.089
16.55,22.17,0.089
16.58,22.31,0.089
16.60,22.46,0.089
16.63,22.60,0.089
16.66,22.74,0.089
16.69,22.88,0.089
16.72,23.02,0.090
16.75,23.16,0.090
16.77,23.31,0.090
16.80,23.45,0.090
16.83,23.59,0.090
16.86,23.73,0.090
16.89,23.87,0.090
16.92,24.01,0.090
16.94,24.16,0.090
16.97,24.30,0.090
17.00,24.44,0.090
17.03,24.58,0.090
17.06,24.72,0.090
17.08,24.87,0.090
17.11,25.01,0.090
17.14,25.15,0.090
17.17,25.29,0.090
17.20,25.43,0.090
17.23,25.57,0.090
17.26,25.72,0.090
17.28,25.86,0.091
17.31,26.00,0.091
17.34,26.14,0.091
17.37,26.28,0.091
17.40,26.42,0.091
17.43,26.57,0.091
17.45,26.71,0.091
17.48,26.85,0.091
17.51,26.99,0.091
17.54,27.13,0.091
17.57,27.28,0.091
17.59,27.42,0.091
17.62,27.56,0.091
17.65,27.70,0.091
17.68,27.84,0.091
17.71,27.99,0.091
17.74,28.13,0.091
17.77,28.27,0.091
17.79,28.41,0.092
17.82,28.55,0.092
17.85,28.69,0.092
17.88,28.84,0.092
17.91,28.98,0.092
17.93,29.12,0.092
17.96,29.26,0.092
17.99,29.40,0.092
18.02,29.54,0.092
18.05,29.69,0.092
18.08,29.83,0.092
18.11,29.97,0.092
18.13,30.11,0.092
18.16,30.25,0.092
18.19,30.39,0.092
18.22,30.54,0.092
18.25,30.68,0.092
18.28,30.82,0.092
18.30,30.96,0.093
18.33,31.10,0.093
18.36,31.25,0.093
18.39,31.39,0.093
18.42,31.53,0.093
18.44,31.67,0.093
18.47,31.81,0.093
18.50,31.95,0.093
18.53,32.10,0.093
18.56,32.24,0.093
18.59,32.38,0.093
18.62,32.52,0.093
18.64,32.66,0.093
18.67,32.80,0.093
18.70,32.95,0.093
18.73,33.09,0.093
18.76,33.23,0.093
18.78,33.37,0.093
18.81,33.51,0.093
18.84,33.66,0.093
18.87,33.80,0.094
18.90,33.94,0.094
18.93,34.08,0.094
18.96,34.22,0.094
18.98,34.36,0.094
19.01,34.50,0.094
19.04,34.65,0.094
19.07,34.79,0.094
19.10,34.93,0.094
19.13,35.07,0.094
19.15,35.22,0.094
19.18,35.36,0.094
19.21,35.50,0.094
19.24,35.64,0.094
19.27,35.78,0.094
19.29,35.92,0.094
19.32,36.07,0.094
19.35,36.21,0.094
19.38,36.35,0.094
19.41,36.49,0.095
19.44,36.63,0.095
19.47,36.77,0.095
19.49,36.91,0.095
19.52,37.06,0.095
19.55,37.20,0.095
19.58,37.34,0.095
19.61,37.48,0.095
19.63,37.62,0.095
19.66,37.77,0.095
19.69,37.91,0.095
19.72,38.05,0.095
19.75,38.19,0.095
19.78,38.33,0.095
19.81,38.47,0.095
19.83,38.62,0.095
19.86,38.76,0.095
19.89,38.90,0.095
19.92,39.04,0.095
19.95,39.18,0.095
19.98,39.33,0.095
20.00,39.47,0.096
20.03,39.61,0.096
20.06,39.75,0.096
20.09,39.89,0.096
20.12,40.03,0.096
20.14,40.18,0.096
20.17,40.32,0.096
20.20,40.46,0.096
20.23,40.60,0.096
20.26,40.74,0.096
20.29,40.88,0.096
20.32,41.03,0.096
20.34,41.17,0.096
20.37,41.31,0.096
20.40,41.45,0.096
20.43,41.59,0.096
20.46,41.73,0.096
20.48,41.88,0.096
20.51,42.02,0.096
20.54,42.16,0.096
20.57,42.30,0.097
20.60,42.44,0.097
20.63,42.59,0.097
20.66,42.73,0.097
20.68,42.87,0.097
20.71,43.01,0.097
20.74,43.15,0.097
20.77,43.29,0.097
20.80,43.44,0.097
20.83,43.58,0.097
20.85,43.72,0.097
20.88,43.86,0.097
20.91,44.00,0.097
20.94,44.14,0.097
20.97,44.29,0.097
20.99,44.43,0.097
21.02,44.57,0.098
21.05,44.71,0.098
21.08,44.85,0.098
21.11,44.99,0.098
21.14,45.13,0.098
21.17,45.28,0.098
21.19,45.42,0.098
21.22,45.56,0.098
21.25,45.70,0.098
21.28,45.84,0.098
21.31,45.99,0.098
21.33,46.13,0.098
21.36,46.27,0.098
21.39,46.41,0.098
21.42,46.55,0.098
21.45,46.69,0.099
21.48,46.84,0.099
21.51,46.98,0.099
21.53,47.12,0.099
21.56,47.26,0.099
21.59,47.40,0.099
21.62,47.54,0.099
21.65,47.69,0.099
21.68,47.83,0.099
21.70,47.97,0.099
21.73,48.11,0.099
21.76,48.26,0.099
21.79,48.40,0.100
21.82,48.54,0.099
21.84,48.68,0.099
21.87,48.82,0.100
21.90,48.96,0.100
21.93,49.11,0.100
21.96,49.25,0.100
21.99,49.39,0.100
22.02,49.53,0.100
22.04,49.67,0.100
22.07,49.82,0.100
22.10,49.96,0.100
22.13,50.10,0.100
22.16,50.24,0.100
22.18,50.38,0.100
22.21,50.52,0.100
22.24,50.67,0.100
22.27,50.81,0.100
22.30,50.95,0.100
22.33,51.09,0.100
22.36,51.23,0.100
22.38,51.37,0.100
22.41,51.51,0.101
22.44,51.66,0.101
22.47,51.80,0.101
22.50,51.94,0.101
22.53,52.08,0.101
22.55,52.22,0.101
22.58,52.36,0.101
22.61,52.51,0.101
22.64,52.65,0.101
22.67,52.79,0.101
22.69,52.93,0.101
22.72,53.07,0.102
22.75,53.22,0.102
22.78,53.36,0.102
22.81,53.50,0.102
22.84,53.64,0.102
22.87,53.78,0.102
22.89,53.93,0.102
22.92,54.07,0.102
22.95,54.21,0.102
22.98,54.35,0.102
23.01,54.49,0.102
23.03,54.63,0.103
23.06,54.77,0.103
23.09,54.92,0.103
23.12,55.06,0.103
23.15,55.20,0.103
23.18,55.34,0.103
23.21,55.48,0.103
23.23,55.62,0.103
23.26,55.77,0.103
23.29,55.91,0.103
23.32,56.05,0.103
23.35,56.19,0.103
23.38,56.33,0.103
23.40,56.48,0.104
23.43,56.62,0.104
23.46,56.76,0.104
23.49,56.90,0.104
23.52,57.04,0.104
23.54,57.18,0.104
23.57,57.33,0.104
23.60,57.47,0.104
23.63,57.61,0.104
23.66,57.75,0.104
23.69,57.89,0.104
23.72,58.03,0.104
23.74,58.18,0.104
23.77,58.32,0.105
23.80,58.46,0.105
23.83,58.60,0.105
23.86,58.74,0.105
23.88,58.88,0.105
23.91,59.03,0.105
23.94,59.17,0.105
23.97,59.31,0.105
24.00,59.45,0.105
24.03,59.59,0.105
24.06,59.73,0.106
24.08,59.88,0.106
24.11,60.02,0.106
24.14,60.16,0.106
24.17,60.30,0.106
24.20,60.44,0.106
24.23,60.58,0.106
24.25,60.73,0.106
24.28,60.87,0.106
24.31,61.01,0.106
24.34,61.15,0.106
24.37,61.29,0.107
24.39,61.44,0.107
24.42,61.58,0.107
24.45,61.72,0.107
24.48,61.86,0.107
24.51,62.00,0.107
24.54,62.14,0.107
24.57,62.28,0.107
24.59,62.43,0.107
24.62,62.57,0.108
24.65,62.71,0.108
24.68,62.85,0.108
24.71,62.99,0.108
24.73,63.14,0.108
24.76,63.28,0.108
24.79,63.42,0.108
24.82,63.56,0.108
24.85,63.70,0.109
24.88,63.84,0.109
24.91,63.99,0.109
24.93,64.13,0.109
24.96,64.27,0.109
24.99,64.41,0.109
25.02,64.55,0.110
25.05,64.69,0.110
25.08,64.84,0.110
25.10,64.98,0.110
25.13,65.12,0.110
25.16,65.26,0.111
25.19,65.40,0.111
25.22,65.54,0.111
25.24,65.69,0.111
25.27,65.83,0.112
25.30,65.97,0.112
25.33,66.11,0.112
25.36,66.25,0.112
25.39,66.39,0.112
25.42,66.54,0.113
25.44,66.68,0.113
25.47,66.82,0.113
25.50,66.96,0.114
25.53,67.10,0.114
25.56,67.24,0.114
25.58,67.39,0.115
25.61,67.53,0.115
25.64,67.67,0.116
25.67,67.81,0.116
25.70,67.95,0.117
25.73,68.09,0.117
25.76,68.23,0.118
25.78,68.38,0.118
25.81,68.52,0.119
25.84,68.66,0.120
25.87,68.80,0.120
25.90,68.94,0.121
25.93,69.08,0.122
25.95,69.22,0.123
25.98,69.36,0.124
26.01,69.50,0.126
26.04,69.65,0.127
26.07,69.79,0.129
26.09,69.93,0.131
26.12,70.07,0.132
26.15,70.21,0.134
26.18,70.35,0.136
26.21,70.49,0.139
26.24,70.63,0.142
26.27,70.77,0.145
26.29,70.91,0.148
26.32,71.06,0.152
26.35,71.20,0.156
26.38,71.34,0.159
26.41,71.48,0.164
26.43,71.62,0.168
26.46,71.76,0.174
26.49,71.90,0.180
26.52,72.04,0.185
26.55,72.18,0.192
26.58,72.31,0.200
26.61,72.45,0.207
26.63,72.59,0.216
26.66,72.73,0.225
26.69,72.87,0.235
26.72,73.01,0.247
26.75,73.14,0.260
26.78,73.28,0.274
26.80,73.42,0.289
26.83,73.55,0.305
26.86,73.69,0.324
26.89,73.82,0.342
26.92,73.95,0.364
26.94,74.09,0.387
26.97,74.22,0.411
27.00,74.35,0.436
27.03,74.48,0.465
27.06,74.61,0.494
27.09,74.74,0.526
27.12,74.87,0.560
27.14,75.00,0.596
27.17,75.12,0.634
27.20,75.25,0.670
27.23,75.37,0.710
27.26,75.50,0.749
27.28,75.62,0.793
27.31,75.75,0.835
27.34,75.87,0.878
27.37,76.00,0.916
27.40,76.12,0.949
27.43,76.25,0.989
27.46,76.37,1.041
27.48,76.49,1.086
27.51,76.61,1.145
27.54,76.74,1.139
27.57,76.88,1.101
27.60,77.03,1.040
27.63,77.19,0.969
27.65,77.35,0.886
27.68,77.52,0.819
27.71,77.69,0.770
27.74,77.86,0.726
27.77,78.02,0.689
27.79,78.18,0.651
27.82,78.34,0.617
27.85,78.50,0.582
27.88,78.66,0.538
27.91,78.82,0.485
27.94,78.98,0.427
27.97,79.14,0.370
27.99,79.31,0.316
28.02,79.47,0.274
28.05,79.63,0.239
28.08,79.79,0.212
28.11,79.95,0.192
28.13,80.10,0.176
28.16,80.25,0.164
28.19,80.40,0.156
28.22,80.55,0.149
28.25,80.69,0.144
28.28,80.84,0.140
28.31,80.98,0.137
28.33,81.12,0.136
28.36,81.27,0.134
28.39,81.41,0.132
28.42,81.55,0.131
28.45,81.70,0.131
28.48,81.84,0.130
28.50,81.98,0.130
28.53,82.12,0.129
28.56,82.26,0.129
28.59,82.41,0.129
28.62,82.55,0.128
28.64,82.69,0.128
28.67,82.83,0.128
28.70,82.97,0.128
28.73,83.11,0.127
28.76,83.26,0.127
28.79,83.40,0.127
28.82,83.54,0.127
28.84,83.68,0.126
28.87,83.82,0.126
28.90,83.97,0.126
28.93,84.11,0.126
28.96,84.25,0.126
28.98,84.39,0.126
29.01,84.53,0.126
29.04,84.67,0.126
29.07,84.82,0.126
29.10,84.96,0.126
29.13,85.10,0.126
29.16,85.24,0.126
29.18,85.38,0.126
29.21,85.52,0.126
29.24,85.67,0.126
29.27,85.81,0.126
29.30,85.95,0.126
29.33,86.09,0.126
29.35,86.23,0.126
29.38,86.38,0.126
29.41,86.52,0.126
29.44,86.66,0.126
29.47,86.80,0.126
29.49,86.94,0.126
29.52,87.08,0.126
29.55,87.23,0.126
29.58,87.37,0.126
29.61,87.51,0.126
29.64,87.65,0.126
29.67,87.79,0.126
29.69,87.93,0.126
29.72,88.08,0.126
29.75,88.22,0.126
29.78,88.36,0.126
29.81,88.50,0.126
29.83,88.64,0.126
29.86,88.78,0.126
29.89,88.93,0.126
29.92,89.07,0.126
29.95,89.21,0.126
29.98,89.35,0.126
30.01,89.49,0.126
30.03,89.63,0.126
30.06,89.78,0.126
30.09,89.92,0.126
30.12,90.06,0.126
30.15,90.20,0.126
30.18,90.34,0.126
30.20,90.49,0.126
30.23,90.63,0.126
30.26,90.77,0.126
30.29,90.91,0.127
30.32,91.05,0.127
30.34,91.19,0.127
30.37,91.34,0.127
30.40,91.48,0.127
30.43,91.62,0.127
30.46,91.76,0.127
30.49,91.90,0.127
30.52,92.04,0.127
30.54,92.19,0.127
30.57,92.33,0.127
30.60,92.47,0.127
30.63,92.61,0.127
30.66,92.75,0.127
30.68,92.89,0.127
30.71,93.04,0.127
30.74,93.18,0.127
30.77,93.32,0.127
30.80,93.46,0.127
30.83,93.60,0.127
30.86,93.75,0.127
30.88,93.89,0.127
30.91,94.03,0.127
30.94,94.17,0.127
30.97,94.31,0.127
31.00,94.45,0.127
31.03,94.60,0.127
31.05,94.74,0.127
31.08,94.88,0.127
31.11,95.02,0.127
31.14,95.16,0.127
31.17,95.30,0.127
31.19,95.45,0.127
31.22,95.59,0.127
31.25,95.73,0.127
31.28,95.87,0.127
31.31,96.01,0.127
31.34,96.15,0.128
31.37,96.30,0.128
31.39,96.44,0.128
31.42,96.58,0.128
31.45,96.72,0.128
31.48,96.86,0.128
31.51,97.01,0.128
31.53,97.15,0.128
31.56,97.29,0.128
31.59,97.43,0.128
31.62,97.57,0.128
31.65,97.71,0.128
31.68,97.85,0.128
31.71,98.00,0.128
31.73,98.14,0.128
31.76,98.28,0.128
31.79,98.42,0.128
31.82,98.56,0.128
31.85,98.71,0.128
31.88,98.85,0.128
31.90,98.99,0.128
31.93,99.13,0.128
31.96,99.27,0.128
31.99,99.41,0.128
32.02,99.56,0.128
32.04,99.70,0.128
32.07,99.84,0.128
32.10,99.98,0.128
32.13,100.12,0.128
32.16,100.26,0.128
32.19,100.41,0.128
32.22,100.55,0.128
32.24,100.69,0.128
32.27,100.83,0.129
32.30,100.97,0.129
32.33,101.12,0.129
32.36,101.26,0.129
32.38,101.40,0.129
32.41,101.54,0.129
32.44,101.68,0.129
32.47,101.82,0.129
32.50,101.97,0.129
32.53,102.11,0.129
32.56,102.25,0.129
32.58,102.39,0.129
32.61,102.53,0.129
32.64,102.67,0.129
32.67,102.82,0.129
32.70,102.96,0.129
32.73,103.10,0.129
32.75,103.24,0.129
32.78,103.38,0.129
32.81,103.52,0.129
32.84,103.67,0.129
32.87,103.81,0.129
32.89,103.95,0.129
32.92,104.09,0.129
32.95,104.23,0.129
32.98,104.37,0.129
33.01,104.52,0.129
33.04,104.66,0.129
33.07,104.80,0.129
33.09,104.94,0.129
33.12,105.08,0.129
33.15,105.22,0.129
33.18,105.37,0.129
33.21,105.51,0.129
33.23,105.65,0.129
33.26,105.79,0.129
33.29,105.93,0.129
33.32,106.08,0.129
33.35,106.22,0.129
33.38,106.36,0.129
33.41,106.50,0.129
33.43,106.64,0.129
33.46,106.79,0.129
33.49,106.93,0.129
33.52,107.07,0.130
33.55,107.21,0.130
33.58,107.35,0.130
33.60,107.49,0.130
33.63,107.63,0.130
33.66,107.78,0.130
33.69,107.92,0.130
33.72,108.06,0.130
33.74,108.20,0.130
33.77,108.34,0.130
33.80,108.48,0.130
33.83,108.63,0.130
33.86,108.77,0.130
33.89,108.91,0.130
33.92,109.05,0.130
33.94,109.19,0.130
33.97,109.34,0.130
34.00,109.48,0.130
34.03,109.62,0.130
34.06,109.76,0.130
34.08,109.90,0.130
34.11,110.04,0.130
34.14,110.19,0.130
34.17,110.33,0.130
34.20,110.47,0.130
34.23,110.61,0.130
34.26,110.75,0.130
34.28,110.89,0.130
34.31,111.04,0.130
34.34,111.18,0.130
34.37,111.32,0.130
34.40,111.46,0.130
34.43,111.60,0.130
34.45,111.74,0.130
34.48,111.88,0.130
34.51,112.03,0.131
34.54,112.17,0.131
34.57,112.31,0.131
34.59,112.45,0.131
34.62,112.59,0.131
34.65,112.74,0.131
34.68,112.88,0.131
34.71,113.02,0.131
34.74,113.16,0.131
34.76,113.30,0.131
34.79,113.44,0.131
34.82,113.59,0.131
34.85,113.73,0.131
34.88,113.87,0.131
34.91,114.01,0.131
34.94,114.15,0.131
34.96,114.30,0.131
34.99,114.44,0.131
35.02,114.58,0.131
35.05,114.72,0.131
35.08,114.86,0.131
35.11,115.00,0.131
35.13,115.15,0.131
35.16,115.29,0.131
35.19,115.43,0.131
35.22,115.57,0.131
35.25,115.71,0.131
35.28,115.85,0.131
35.30,116.00,0.131
35.33,116.14,0.131
35.36,116.28,0.131
35.39,116.42,0.131
35.42,116.56,0.131
35.44,116.70,0.132
35.47,116.85,0.132
35.50,116.99,0.132
35.53,117.13,0.131
35.56,117.27,0.132
35.59,117.41,0.131
35.61,117.55,0.131
35.64,117.70,0.132
35.67,117.84,0.132
35.70,117.98,0.132
35.73,118.12,0.132
35.76,118.26,0.132
35.79,118.41,0.132
35.81,118.55,0.132
35.84,118.69,0.132
35.87,118.83,0.132
35.90,118.97,0.132
35.93,119.11,0.132
35.96,119.26,0.132
35.98,119.40,0.132
36.01,119.54,0.132
36.04,119.68,0.132
36.07,119.82,0.132
36.10,119.96,0.132
36.13,120.11,0.132
36.15,120.25,0.132
36.18,120.39,0.132
36.21,120.53,0.132
36.24,120.67,0.132
36.27,120.82,0.132
36.29,120.96,0.132
36.32,121.10,0.132
36.35,121.24,0.132
36.38,121.38,0.132
36.41,121.53,0.132
36.44,121.67,0.132
36.46,121.81,0.132
36.49,121.95,0.132
36.52,122.09,0.132
36.55,122.23,0.132
36.58,122.37,0.132
36.61,122.51,0.132
36.64,122.66,0.132
36.66,122.80,0.132
36.69,122.94,0.132
36.72,123.08,0.132
36.75,123.22,0.132
36.78,123.36,0.132
36.81,123.51,0.132
36.83,123.65,0.132
36.86,123.79,0.132
36.89,123.93,0.132
36.92,124.07,0.132
36.95,124.21,0.132
36.98,124.36,0.132
37.00,124.50,0.132
37.03,124.64,0.132
37.06,124.78,0.132
37.09,124.92,0.132
37.12,125.07,0.132
37.14,125.21,0.132
37.17,125.35,0.132
37.20,125.49,0.132
37.23,125.63,0.132
37.26,125.78,0.132
37.29,125.92,0.132
37.31,126.06,0.132
37.34,126.20,0.132
37.37,126.34,0.132
37.40,126.48,0.132
37.43,126.63,0.132
37.46,126.77,0.132
37.49,126.91,0.132
37.51,127.05,0.132
37.54,127.19,0.132
37.57,127.33,0.132
37.60,127.48,0.132
37.63,127.62,0.132
37.66,127.76,0.132
37.68,127.90,0.132
37.71,128.04,0.132
37.74,128.18,0.132
37.77,128.33,0.132
37.80,128.47,0.132
37.83,128.61,0.132
37.85,128.75,0.132
37.88,128.89,0.132
37.91,129.04,0.132
37.94,129.18,0.133
37.97,129.32,0.133
37.99,129.46,0.133
38.02,129.60,0.133
38.05,129.74,0.133
38.08,129.89,0.133
38.11,130.03,0.133
38.14,130.17,0.133
38.16,130.31,0.133
38.19,130.45,0.133
38.22,130.59,0.133
38.25,130.73,0.133
38.28,130.88,0.133
38.31,131.02,0.133
38.34,131.16,0.133
38.36,131.31,0.133
38.39,131.45,0.133
38.42,131.59,0.133
38.45,131.74,0.133
38.48,131.88,0.133
38.51,132.02,0.133
38.53,132.16,0.133
38.56,132.30,0.133
38.59,132.44,0.133
38.62,132.58,0.133
38.65,132.73,0.133
38.68,132.87,0.133
38.70,133.01,0.133
38.73,133.15,0.133
38.76,133.29,0.133
38.79,133.43,0.132
38.82,133.57,0.132
38.84,133.72,0.132
38.87,133.86,0.132
38.90,134.00,0.132
38.93,134.14,0.132
38.96,134.28,0.132
38.99,134.42,0.132
39.01,134.56,0.132
39.04,134.70,0.132
39.07,134.85,0.132
39.10,134.99,0.132
39.13,135.13,0.132
39.16,135.27,0.132
39.19,135.41,0.132
39.21,135.55,0.132
39.24,135.69,0.132
39.27,135.84,0.132
39.30,135.98,0.132
39.33,136.12,0.132
39.36,136.26,0.132
39.38,136.40,0.132
39.41,136.54,0.132
39.44,136.69,0.132
39.47,136.83,0.132
39.50,136.97,0.132
39.53,137.11,0.133
39.55,137.25,0.133
39.58,137.40,0.133
39.61,137.54,0.133
39.64,137.68,0.133
39.67,137.82,0.133
39.69,137.96,0.133
39.72,138.10,0.133
39.75,138.25,0.133
39.78,138.39,0.133
39.81,138.53,0.133
39.84,138.67,0.133
39.86,138.81,0.133
39.89,138.95,0.133
39.92,139.10,0.133
39.95,139.24,0.133
39.98,139.38,0.133
40.01,139.52,0.133
40.04,139.66,0.133
40.06,139.80,0.133
40.09,139.95,0.133
40.12,140.09,0.133
40.15,140.23,0.133
40.18,140.37,0.133
40.21,140.51,0.133
40.23,140.65,0.133
40.26,140.80,0.133
40.29,140.94,0.133
40.32,141.08,0.133
40.35,141.22,0.133
40.38,141.36,0.133
40.40,141.51,0.133
40.43,141.65,0.133
40.46,141.79,0.133
40.49,141.93,0.133
40.52,142.07,0.133
40.54,142.21,0.133
40.57,142.36,0.133
40.60,142.50,0.133
40.63,142.64,0.133
40.66,142.78,0.133
40.69,142.92,0.133
40.71,143.06,0.133
40.74,143.21,0.133
40.77,143.35,0.133
40.80,143.49,0.133
40.83,143.63,0.133
40.86,143.77,0.133
40.89,143.91,0.133
40.91,144.06,0.133
40.94,144.20,0.133
40.97,144.34,0.133
41.00,144.48,0.133
41.03,144.62,0.133
41.06,144.77,0.133
41.08,144.91,0.133
41.11,145.05,0.133
41.14,145.19,0.133
41.17,145.33,0.133
41.20,145.47,0.134
41.23,145.62,0.134
41.25,145.76,0.134
41.28,145.90,0.134
41.31,146.04,0.134
41.34,146.18,0.133
41.37,146.32,0.133
41.39,146.47,0.133
41.42,146.61,0.133
41.45,146.75,0.133
41.48,146.89,0.133
41.51,147.03,0.133
41.54,147.17,0.133
41.56,147.31,0.133
41.59,147.46,0.133
41.62,147.60,0.133
41.65,147.74,0.133
41.68,147.88,0.133
41.71,148.02,0.133
41.74,148.17,0.133
41.76,148.31,0.133
41.79,148.45,0.133
41.82,148.59,0.133
41.85,148.73,0.133
41.88,148.88,0.133
41.91,149.02,0.134
41.93,149.16,
41.96,149.30,
41.99,,

[step]
Ramp 5.00 °C/min to -60.00 °C
Time,Temperature,Heat Flow (Normalized)
min,°C,W/g
42.99,150.12,-0.034
43.01,150.12,-0.034
43.04,150.11,-0.032
43.07,150.08,-0.020
43.10,150.04,-0.020
43.13,149.96,-0.048
43.16,149.87,-0.082
43.19,149.76,-0.113
43.21,149.65,-0.135
43.24,149.53,-0.152
43.27,149.40,-0.163
43.30,149.27,-0.171
43.33,149.14,-0.178
43.36,149.01,-0.184
43.38,148.87,-0.185
43.41,148.74,-0.189
43.44,148.60,-0.190
43.47,148.46,-0.191
43.50,148.32,-0.192
43.53,148.18,-0.194
43.55,148.05,-0.195
43.58,147.91,-0.195
43.61,147.77,-0.195
43.64,147.63,-0.196
43.67,147.49,-0.196
43.69,147.35,-0.196
43.72,147.21,-0.196
43.75,147.07,-0.197
43.78,146.93,-0.197
43.81,146.79,-0.197
43.84,146.65,-0.197
43.86,146.50,-0.198
43.89,146.36,-0.198
43.92,146.22,-0.198
43.95,146.08,-0.198
43.98,145.94,-0.198
44.01,145.80,-0.198
44.04,145.66,-0.198
44.06,145.52,-0.198
44.09,145.38,-0.198
44.12,145.24,-0.198
44.15,145.10,-0.199
44.18,144.96,-0.199
44.21,144.81,-0.199
44.23,144.67,-0.199
44.26,144.53,-0.199
44.29,144.39,-0.199
44.32,144.25,-0.199
44.35,144.11,-0.199
44.38,143.97,-0.199
44.40,143.83,-0.199
44.43,143.68,-0.199
44.46,143.54,-0.199
44.49,143.40,-0.198
44.52,143.26,-0.198
44.54,143.12,-0.198
44.57,142.98,-0.198
44.60,142.84,-0.198
44.63,142.69,-0.198
44.66,142.55,-0.198
44.69,142.41,-0.198
44.71,142.27,-0.198
44.74,142.13,-0.198
44.77,141.99,-0.198
44.80,141.84,-0.198
44.83,141.70,-0.198
44.86,141.56,-0.198
44.89,141.42,-0.198
44.91,141.28,-0.198
44.94,141.14,-0.198
44.97,140.99,-0.197
45.00,140.85,-0.197
45.03,140.71,-0.197
45.06,140.57,-0.197
45.08,140.43,-0.197
45.11,140.29,-0.197
45.14,140.15,-0.197
45.17,140.00,-0.197
45.20,139.86,-0.197
45.23,139.72,-0.197
45.25,139.58,-0.197
45.28,139.44,-0.196
45.31,139.30,-0.196
45.34,139.16,-0.196
45.37,139.01,-0.196
45.39,138.87,-0.196
45.42,138.73,-0.196
45.45,138.59,-0.196
45.48,138.45,-0.196
45.51,138.30,-0.196
45.54,138.16,-0.196
45.56,138.02,-0.196
45.59,137.88,-0.196
45.62,137.73,-0.196
45.65,137.59,-0.196
45.68,137.45,-0.196
45.71,137.31,-0.196
45.74,137.17,-0.195
45.76,137.03,-0.195
45.79,136.89,-0.195
45.82,136.74,-0.195
45.85,136.60,-0.195
45.88,136.46,-0.194
45.91,136.32,-0.194
45.93,136.18,-0.194
45.96,136.04,-0.194
45.99,135.90,-0.194
46.02,135.76,-0.194
46.05,135.61,-0.194
46.08,135.47,-0.194
46.10,135.33,-0.194
46.13,135.19,-0.194
46.16,135.05,-0.194
46.19,134.91,-0.193
46.22,134.77,-0.193
46.24,134.62,-0.193
46.27,134.48,-0.193
46.30,134.34,-0.193
46.33,134.20,-0.193
46.36,134.06,-0.193
46.39,133.92,-0.193
46.41,133.77,-0.193
46.44,133.63,-0.193
46.47,133.49,-0.193
46.50,133.35,-0.193
46.53,133.21,-0.193
46.56,133.07,-0.193
46.59,132.93,-0.192
46.61,132.79,-0.192
46.64,132.64,-0.192
46.67,132.50,-0.192
46.70,132.36,-0.192
46.73,132.22,-0.192
46.76,132.08,-0.192
46.78,131.94,-0.192
46.81,131.79,-0.192
46.84,131.65,-0.192
46.87,131.51,-0.192
46.90,131.37,-0.192
46.93,131.23,-0.192
46.95,131.09,-0.192
46.98,130.94,-0.192
47.01,130.80,-0.192
47.04,130.66,-0.192
47.07,130.52,-0.192
47.09,130.38,-0.192
47.12,130.24,-0.192
47.15,130.10,-0.191
47.18,129.95,-0.191
47.21,129.81,-0.191
47.24,129.67,-0.191
47.26,129.53,-0.191
47.29,129.39,-0.191
47.32,129.25,-0.190
47.35,129.11,-0.190
47.38,128.97,-0.190
47.41,128.82,-0.191
47.44,128.68,-0.191
47.46,128.54,-0.191
47.49,128.40,-0.191
47.52,128.26,-0.191
47.55,128.11,-0.191
47.58,127.97,-0.191
47.61,127.83,-0.191
47.63,127.69,-0.191
47.66,127.55,-0.191
47.69,127.41,-0.191
47.72,127.26,-0.191
47.75,127.12,-0.191
47.78,126.98,-0.191
47.80,126.84,-0.191
47.83,126.70,-0.191
47.86,126.56,-0.191
47.89,126.41,-0.191
47.92,126.27,-0.191
47.94,126.13,-0.191
47.97,125.99,-0.191
48.00,125.85,-0.191
48.03,125.71,-0.191
48.06,125.56,-0.190
48.09,125.42,-0.190
48.11,125.28,-0.190
48.14,125.14,-0.190
48.17,125.00,-0.190
48.20,124.86,-0.190
48.23,124.72,-0.190
48.26,124.57,-0.190
48.29,124.43,-0.190
48.31,124.29,-0.190
48.34,124.15,-0.190
48.37,124.01,-0.190
48.40,123.87,-0.190
48.43,123.72,-0.190
48.46,123.58,-0.190
48.48,123.44,-0.190
48.51,123.30,-0.190
48.54,123.16,-0.190
48.57,123.02,-0.190
48.60,122.87,-0.190
48.63,122.73,-0.190
48.65,122.59,-0.190
48.68,122.45,-0.190
48.71,122.31,-0.189
48.74,122.17,-0.189
48.77,122.03,-0.189
48.79,121.88,-0.189
48.82,121.74,-0.189
48.85,121.60,-0.189
48.88,121.46,-0.189
48.91,121.32,-0.189
48.94,121.17,-0.189
48.96,121.03,-0.189
48.99,120.89,-0.189
49.02,120.75,-0.189
49.05,120.61,-0.189
49.08,120.47,-0.189
49.11,120.32,-0.189
49.14,120.18,-0.189
49.16,120.04,-0.189
49.19,119.90,-0.189
49.22,119.76,-0.189
49.25,119.62,-0.189
49.28,119.48,-0.188
49.31,119.34,-0.188
49.33,119.19,-0.188
49.36,119.05,-0.188
49.39,118.91,-0.188
49.42,118.77,-0.188
49.45,118.63,-0.188
49.48,118.49,-0.188
49.50,118.34,-0.188
49.53,118.20,-0.188
49.56,118.06,-0.188
49.59,117.92,-0.188
49.62,117.78,-0.188
49.64,117.63,-0.188
49.67,117.49,-0.188
49.70,117.35,-0.188
49.73,117.21,-0.188
49.76,117.07,-0.188
49.79,116.93,-0.187
49.81,116.79,-0.188
49.84,116.64,-0.187
49.87,116.50,-0.187
49.90,116.36,-0.187
49.93,116.22,-0.187
49.96,116.08,-0.187
49.99,115.94,-0.187
50.01,115.79,-0.187
50.04,115.65,-0.187
50.07,115.51,-0.187
50.10,115.37,-0.187
50.13,115.23,-0.187
50.16,115.09,-0.187
50.18,114.94,-0.187
50.21,114.80,-0.187
50.24,114.66,-0.187
50.27,114.52,-0.187
50.30,114.38,-0.187
50.33,114.24,-0.187
50.35,114.10,-0.187
50.38,113.95,-0.187
50.41,113.81,-0.186
50.44,113.67,-0.186
50.47,113.53,-0.186
50.49,113.39,-0.186
50.52,113.25,-0.186
50.55,113.10,-0.186
50.58,112.96,-0.186
50.61,112.82,-0.186
50.64,112.68,-0.186
50.66,112.54,-0.186
50.69,112.40,-0.186
50.72,112.26,-0.186
50.75,112.11,-0.186
50.78,111.97,-0.186
50.81,111.83,-0.186
50.84,111.69,-0.186
50.86,111.55,-0.186
50.89,111.41,-0.186
50.92,111.26,-0.186
50.95,111.12,-0.186
50.98,110.98,-0.185
51.01,110.84,-0.185
51.03,110.70,-0.185
51.06,110.56,-0.186
51.09,110.41,-0.186
51.12,110.27,-0.185
51.15,110.13,-0.185
51.18,109.99,-0.185
51.20,109.85,-0.185
51.23,109.71,-0.185
51.26,109.56,-0.185
51.29,109.42,-0.185
51.32,109.28,-0.185
51.34,109.14,-0.185
51.37,109.00,-0.185
51.40,108.86,-0.185
51.43,108.72,-0.185
51.46,108.57,-0.185
51.49,108.43,-0.185
51.51,108.29,-0.185
51.54,108.15,-0.185
51.57,108.01,-0.185
51.60,107.87,-0.185
51.63,107.72,-0.185
51.66,107.58,-0.185
51.69,107.44,-0.185
51.71,107.30,-0.185
51.74,107.16,-0.185
51.77,107.01,-0.184
51.80,106.87,-0.185
51.83,106.73,-0.185
51.86,106.59,-0.185
51.88,106.45,-0.185
51.91,106.30,-0.184
51.94,106.16,-0.184
51.97,106.02,-0.184
52.00,105.88,-0.184
52.03,105.74,-0.184
52.05,105.60,-0.184
52.08,105.46,-0.184
52.11,105.32,-0.184
52.14,105.17,-0.184
52.17,105.03,-0.184
52.19,104.89,-0.183
52.22,104.75,-0.183
52.25,104.61,-0.183
52.28,104.47,-0.183
52.31,104.33,-0.183
52.34,104.18,-0.183
52.36,104.04,-0.183
52.39,103.90,-0.183
52.42,103.76,-0.183
52.45,103.62,-0.183
[...]
184.63,2.47,0.120
184.65,2.61,0.120
184.68,2.75,0.120
184.71,2.89,0.120
184.74,3.03,0.120
184.77,3.18,0.120
184.80,3.32,0.120
184.82,3.46,0.120
184.85,3.60,0.120
184.88,3.74,0.119
184.91,3.89,0.119
184.94,4.03,0.119
184.97,4.17,0.118
184.99,4.31,0.118
185.02,4.46,0.117
185.05,4.60,0.117
185.08,4.74,0.116
185.11,4.88,0.116
185.13,5.02,0.116
185.16,5.17,0.115
185.19,5.31,0.115
185.22,5.45,0.115
185.25,5.59,0.115
185.28,5.73,0.114
185.30,5.87,0.114
185.33,6.02,0.114
185.36,6.16,0.114
185.39,6.30,0.114
185.42,6.44,0.113
185.45,6.58,0.113
185.48,6.73,0.113
185.50,6.87,0.113
185.53,7.01,0.113
185.56,7.15,0.113
185.59,7.29,0.113
185.62,7.43,0.113
185.65,7.58,0.113
185.67,7.72,0.113
185.70,7.86,0.113
185.73,8.00,0.112
185.76,8.14,0.112
185.79,8.28,0.112
185.82,8.43,0.112
185.84,8.57,0.112
185.87,8.71,0.112
185.90,8.85,0.112
185.93,8.99,0.112
185.96,9.13,0.112
185.98,9.28,0.112
186.01,9.42,0.112
186.04,9.56,0.112
186.07,9.70,0.112
186.10,9.84,0.112
186.13,9.99,0.112
186.15,10.13,0.112
186.18,10.27,0.112
186.21,10.41,0.112
186.24,10.55,0.112
186.27,10.70,0.112
186.30,10.84,0.112
186.33,10.98,0.112
186.35,11.12,0.112
186.38,11.26,0.112
186.41,11.40,0.113
186.44,11.55,0.113
186.47,11.69,0.113
186.50,11.83,0.113
186.52,11.97,0.113
186.55,12.11,0.113
186.58,12.25,0.113
186.61,12.40,0.113
186.64,12.54,0.113
186.67,12.68,0.113
186.69,12.82,0.113
186.72,12.96,0.113
186.75,13.10,0.113
186.78,13.25,0.113
186.81,13.39,0.113
186.83,13.53,0.113
186.86,13.67,0.113
186.89,13.81,0.113
186.92,13.96,0.113
186.95,14.10,0.113
186.98,14.24,0.113
187.00,14.38,0.113
187.03,14.52,0.113
187.06,14.66,0.113
187.09,14.81,0.113
187.12,14.95,0.113
187.15,15.09,0.113
187.18,15.23,0.113
187.20,15.37,0.113
187.23,15.52,0.113
187.26,15.66,0.113
187.29,15.80,0.113
187.32,15.94,0.113
187.35,16.08,0.113
187.37,16.22,0.114
187.40,16.37,0.114
187.43,16.51,0.114
187.46,16.65,0.114
187.49,16.79,0.114
187.52,16.93,0.114
187.54,17.07,0.114
187.57,17.22,0.114
187.60,17.36,0.114
187.63,17.50,0.114
187.66,17.64,0.114
187.68,17.78,0.114
187.71,17.93,0.114
187.74,18.07,0.114
187.77,18.21,0.114
187.80,18.35,0.114
187.83,18.49,0.114
187.85,18.63,0.114
187.88,18.78,0.114
187.91,18.92,0.114
187.94,19.06,0.114
187.97,19.20,0.114
188.00,19.34,0.114
188.03,19.48,0.114
188.05,19.63,0.114
188.08,19.77,0.114
188.11,19.91,0.114
188.14,20.05,0.114
188.17,20.19,0.114
188.20,20.33,0.114
188.22,20.48,0.114
188.25,20.62,0.114
188.28,20.76,0.114
188.31,20.90,0.114
188.34,21.04,0.114
188.37,21.19,0.114
188.39,21.33,0.115
188.42,21.47,0.115
188.45,21.61,0.115
188.48,21.75,0.115
188.51,21.89,0.115
188.53,22.04,0.115
188.56,22.18,0.115
188.59,22.32,0.115
188.62,22.46,0.115
188.65,22.60,0.115
188.68,22.74,0.115
188.70,22.89,0.115
188.73,23.03,0.115
188.76,23.17,0.115
188.79,23.31,0.115
188.82,23.45,0.115
188.85,23.59,0.115
188.88,23.74,0.115
188.90,23.88,0.115
188.93,24.02,0.115
188.96,24.16,0.115
188.99,24.30,0.115
189.02,24.45,0.115
189.05,24.59,0.115
189.07,24.73,0.115
189.10,24.87,0.115
189.13,25.01,0.115
189.16,25.15,0.116
189.19,25.30,0.116
189.22,25.44,0.116
189.24,25.58,0.116
189.27,25.72,0.116
189.30,25.86,0.116
189.33,26.00,0.116
189.36,26.15,0.116
189.38,26.29,0.116
189.41,26.43,0.116
189.44,26.57,0.116
189.47,26.71,0.116
189.50,26.86,0.116
189.53,27.00,0.116
189.55,27.14,0.116
189.58,27.28,0.116
189.61,27.42,0.116
189.64,27.56,0.116
189.67,27.71,0.116
189.70,27.85,0.116
189.73,27.99,0.116
189.75,28.13,0.116
189.78,28.27,0.116
189.81,28.41,0.117
189.84,28.56,0.117
189.87,28.70,0.117
189.90,28.84,0.117
189.92,28.98,0.117
189.95,29.12,0.117
189.98,29.27,0.117
190.01,29.41,0.117
190.04,29.55,0.117
190.07,29.69,0.117
190.09,29.83,0.117
190.12,29.97,0.117
190.15,30.12,0.117
190.18,30.26,0.117
190.21,30.40,0.117
190.23,30.54,0.117
190.26,30.68,0.117
190.29,30.82,0.117
190.32,30.97,0.117
190.35,31.11,0.117
190.38,31.25,0.117
190.40,31.39,0.117
190.43,31.53,0.117
190.46,31.68,0.117
190.49,31.82,0.117
190.52,31.96,0.117
190.55,32.10,0.117
190.58,32.24,0.117
190.60,32.39,0.117
190.63,32.53,0.117
190.66,32.67,0.117
190.69,32.81,0.118
190.72,32.95,0.118
190.75,33.09,0.118
190.77,33.24,0.118
190.80,33.38,0.118
190.83,33.52,0.118
190.86,33.66,0.118
190.89,33.80,0.118
190.92,33.95,0.118
190.94,34.09,0.118
190.97,34.23,0.118
191.00,34.37,0.118
191.03,34.51,0.118
191.06,34.65,0.118
191.08,34.80,0.118
191.11,34.94,0.118
191.14,35.08,0.118
191.17,35.22,0.118
191.20,35.36,0.118
191.23,35.50,0.118
191.25,35.65,0.118
191.28,35.79,0.118
191.31,35.93,0.118
191.34,36.07,0.118
191.37,36.21,0.118
191.40,36.35,0.118
191.43,36.50,0.118
191.45,36.64,0.118
191.48,36.78,0.118
191.51,36.92,0.118
191.54,37.06,0.118
191.57,37.20,0.119
191.60,37.35,0.119
191.62,37.49,0.119
191.65,37.63,0.119
191.68,37.77,0.119
191.71,37.91,0.119
191.74,38.06,0.119
191.77,38.20,0.119
191.79,38.34,0.119
191.82,38.48,0.119
191.85,38.62,0.119
191.88,38.76,0.119
191.91,38.91,0.119
191.93,39.05,0.119
191.96,39.19,0.119
191.99,39.33,0.119
192.02,39.47,0.119
192.05,39.61,0.119
192.08,39.75,0.119
192.10,39.90,0.119
192.13,40.04,0.119
192.16,40.18,0.119
192.19,40.32,0.119
192.22,40.47,0.119
192.25,40.61,0.119
192.28,40.75,0.119
192.30,40.89,0.119
192.33,41.03,0.120
192.36,41.17,0.120
192.39,41.32,0.120
192.42,41.46,0.120
192.45,41.60,0.120
192.47,41.74,0.120
192.50,41.88,0.120
192.53,42.02,0.120
192.56,42.17,0.120
192.59,42.31,0.120
192.62,42.45,0.120
192.64,42.59,0.120
192.67,42.73,0.120
192.70,42.87,0.120
192.73,43.02,0.120
192.76,43.16,0.120
192.78,43.30,0.120
192.81,43.44,0.120
192.84,43.58,0.120
192.87,43.73,0.120
192.90,43.87,0.120
192.93,44.01,0.120
192.95,44.15,0.120
192.98,44.29,0.120
193.01,44.43,0.120
193.04,44.58,0.120
193.07,44.72,0.120
193.10,44.86,0.120
193.13,45.00,0.120
193.15,45.14,0.120
193.18,45.28,0.120
193.21,45.43,0.120
193.24,45.57,0.120
193.27,45.71,0.120
193.30,45.85,0.120
193.32,45.99,0.120
193.35,46.14,0.120
193.38,46.28,0.121
193.41,46.42,0.121
193.44,46.56,0.121
193.47,46.70,0.121
193.49,46.85,0.121
193.52,46.99,0.121
193.55,47.13,0.121
193.58,47.27,0.121
193.61,47.41,0.121
193.63,47.55,0.121
193.66,47.70,0.121
193.69,47.84,0.121
193.72,47.98,0.121
193.75,48.12,0.121
193.78,48.26,0.121
193.80,48.41,0.121
193.83,48.55,0.121
193.86,48.69,0.121
193.89,48.83,0.121
193.92,48.97,0.121
193.95,49.12,0.121
193.98,49.26,0.121
194.00,49.40,0.121
194.03,49.54,0.121
194.06,49.68,0.121
194.09,49.82,0.121
194.12,49.96,0.121
194.15,50.11,0.122
194.17,50.25,0.122
194.20,50.39,0.122
194.23,50.53,0.122
194.26,50.67,0.122
194.29,50.82,0.122
194.32,50.96,0.122
194.34,51.10,0.122
194.37,51.24,0.122
194.40,51.38,0.122
194.43,51.52,0.122
194.46,51.66,0.122
194.48,51.81,0.122
194.51,51.95,0.122
194.54,52.09,0.122
194.57,52.23,0.122
194.60,52.37,0.122
194.63,52.51,0.122
194.65,52.66,0.122
194.68,52.80,0.122
194.71,52.94,0.122
194.74,53.08,0.122
194.77,53.22,0.122
194.80,53.37,0.122
194.83,53.51,0.122
194.85,53.65,0.122
194.88,53.79,0.122
194.91,53.93,0.122
194.94,54.07,0.122
194.97,54.22,0.122
195.00,54.36,0.122
195.02,54.50,0.122
195.05,54.64,0.122
195.08,54.78,0.122
195.11,54.93,0.123
195.14,55.07,0.123
195.17,55.21,0.123
195.19,55.35,0.123
195.22,55.49,0.123
195.25,55.63,0.123
195.28,55.77,0.123
195.31,55.92,0.123
195.33,56.06,0.123
195.36,56.20,0.123
195.39,56.34,0.123
195.42,56.48,0.123
195.45,56.62,0.123
195.48,56.77,0.123
195.50,56.91,0.123
195.53,57.05,0.123
195.56,57.19,0.123
195.59,57.33,0.123
195.62,57.48,0.123
195.65,57.62,0.123
195.68,57.76,0.123
195.70,57.90,0.123
195.73,58.04,0.123
195.76,58.18,0.123
195.79,58.33,0.123
195.82,58.47,0.123
195.85,58.61,0.123
195.87,58.75,0.123
195.90,58.89,0.123
195.93,59.03,0.123
195.96,59.17,0.123
195.99,59.32,0.123
196.02,59.46,0.123
196.04,59.60,0.123
196.07,59.74,0.123
196.10,59.88,0.123
196.13,60.03,0.123
196.16,60.17,0.123
196.18,60.31,0.124
196.21,60.45,0.124
196.24,60.59,0.124
196.27,60.73,0.124
196.30,60.88,0.124
196.33,61.02,0.124
196.35,61.16,0.124
196.38,61.30,0.124
196.41,61.44,0.124
196.44,61.59,0.124
196.47,61.73,0.124
196.50,61.87,0.124
196.53,62.01,0.124
196.55,62.15,0.124
196.58,62.30,0.124
196.61,62.44,0.124
196.64,62.58,0.124
196.67,62.72,0.124
196.70,62.86,0.124
196.72,63.00,0.124
196.75,63.15,0.124
196.78,63.29,0.124
196.81,63.43,0.124
196.84,63.57,0.124
196.87,63.71,0.124
196.89,63.85,0.124
196.92,64.00,0.124
196.95,64.14,0.124
196.98,64.28,0.124
197.01,64.42,0.125
197.03,64.56,0.125
197.06,64.70,0.125
197.09,64.85,0.125
197.12,64.99,0.125
197.15,65.13,0.125
197.18,65.27,0.125
197.20,65.41,0.125
197.23,65.55,0.125
197.26,65.70,0.125
197.29,65.84,0.125
197.32,65.98,0.125
197.35,66.12,0.125
197.38,66.26,0.125
197.40,66.41,0.125
197.43,66.55,0.125
197.46,66.69,0.125
197.49,66.83,0.125
197.52,66.97,0.125
197.55,67.11,0.125
197.57,67.26,0.125
197.60,67.40,0.125
197.63,67.54,0.125
197.66,67.68,0.125
197.69,67.82,0.125
197.72,67.97,0.125
197.74,68.11,0.125
197.77,68.25,0.125
197.80,68.39,0.125
197.83,68.53,0.125
197.86,68.67,0.125
197.88,68.82,0.125
197.91,68.96,0.125
197.94,69.10,0.125
197.97,69.24,0.125
198.00,69.38,0.126
198.03,69.52,0.126
198.05,69.67,0.126
198.08,69.81,0.126
198.11,69.95,0.126
198.14,70.09,0.126
198.17,70.23,0.126
198.20,70.37,0.126
198.23,70.52,0.126
198.25,70.66,0.126
198.28,70.80,0.126
198.31,70.94,0.126
198.34,71.08,0.126
198.37,71.22,0.126
198.40,71.37,0.126
198.42,71.51,0.126
198.45,71.65,0.126
198.48,71.79,0.126
198.51,71.93,0.126
198.54,72.07,0.126
198.57,72.22,0.126
198.59,72.36,0.126
198.62,72.50,0.126
198.65,72.64,0.126
198.68,72.78,0.126
198.71,72.93,0.126
198.73,73.07,0.126
198.76,73.21,0.126
198.79,73.35,0.126
198.82,73.49,0.126
198.85,73.63,0.126
198.88,73.78,0.126
198.90,73.92,0.126
198.93,74.06,0.126
198.96,74.20,0.126
198.99,74.34,0.126
199.02,74.49,0.126
199.05,74.63,0.126
199.08,74.77,0.127
199.10,74.91,0.127
199.13,75.05,0.127
199.16,75.20,0.127
199.19,75.34,0.127
199.22,75.48,0.127
199.25,75.62,0.127
199.27,75.76,0.127
199.30,75.90,0.127
199.33,76.04,0.127
199.36,76.19,0.127
199.39,76.33,0.127
199.42,76.47,0.127
199.44,76.61,0.127
199.47,76.75,0.127
199.50,76.89,0.127
199.53,77.04,0.127
199.56,77.18,0.127
199.58,77.32,0.127
199.61,77.46,0.127
199.64,77.60,0.127
199.67,77.74,0.127
199.70,77.89,0.127
199.73,78.03,0.127
199.75,78.17,0.127
199.78,78.31,0.127
199.81,78.45,0.127
199.84,78.60,0.127
199.87,78.74,0.127
199.90,78.88,0.127
199.93,79.02,0.127
199.95,79.16,0.127
199.98,79.30,0.127
200.01,79.45,0.127
200.04,79.59,0.127
200.07,79.73,0.128
200.10,79.87,0.128
200.12,80.01,0.128
200.15,80.16,0.128
200.18,80.30,0.128
200.21,80.44,0.128
200.24,80.58,0.128
200.27,80.72,0.128
200.29,80.86,0.128
200.32,81.01,0.128
200.35,81.15,0.128
200.38,81.29,0.128
200.41,81.43,0.128
200.43,81.57,0.128
200.46,81.71,0.128
200.49,81.86,0.128
200.52,82.00,0.128
200.55,82.14,0.128
200.58,82.28,0.128
200.60,82.42,0.128
200.63,82.56,0.128
200.66,82.71,0.128
200.69,82.85,0.128
200.72,82.99,0.128
200.75,83.13,0.128
200.78,83.27,0.128
200.80,83.41,0.128
200.83,83.56,0.128
200.86,83.70,0.128
200.89,83.84,0.128
200.92,83.98,0.128
200.95,84.12,0.128
200.97,84.27,0.128
201.00,84.41,0.128
201.03,84.55,0.128
201.06,84.69,0.128
201.09,84.83,0.128
201.12,84.97,0.128
201.14,85.12,0.128
201.17,85.26,0.128
201.20,85.40,0.128
201.23,85.54,0.128
201.26,85.68,0.128
201.28,85.82,0.129
201.31,85.97,0.129
201.34,86.11,0.129
201.37,86.25,0.129
201.40,86.39,0.129
201.43,86.53,0.129
201.45,86.68,0.129
201.48,86.82,0.129
201.51,86.96,0.129
201.54,87.10,0.129
201.57,87.25,0.129
201.60,87.39,0.129
201.63,87.53,0.129
201.65,87.67,0.129
201.68,87.81,0.129
201.71,87.96,0.129
201.74,88.10,0.129
201.77,88.24,0.129
201.80,88.38,0.129
201.82,88.52,0.129
201.85,88.66,0.128
201.88,88.80,0.128
201.91,88.94,0.128
201.94,89.09,0.128
201.97,89.23,0.128
201.99,89.37,0.128
202.02,89.51,0.128
202.05,89.65,0.128
202.08,89.80,0.128
202.11,89.94,0.128
202.13,90.08,0.128
202.16,90.22,0.128
202.19,90.36,0.128
202.22,90.50,0.128
202.25,90.64,0.128
202.28,90.79,0.128
202.30,90.93,0.128
202.33,91.07,0.128
202.36,91.21,0.129
202.39,91.35,0.129
202.42,91.49,0.129
202.45,91.64,0.129
202.48,91.78,0.129
202.50,91.92,0.129
202.53,92.06,0.129
202.56,92.20,0.129
202.59,92.34,0.129
202.62,92.49,0.129
202.65,92.63,0.129
202.67,92.77,0.129
202.70,92.91,0.129
202.73,93.05,0.129
202.76,93.19,0.129
202.79,93.34,0.129
202.82,93.48,0.129
202.84,93.62,0.129
202.87,93.76,0.129
202.90,93.90,0.129
202.93,94.05,0.129
202.96,94.19,0.129
202.98,94.33,0.129
203.01,94.47,0.129
203.04,94.61,0.129
203.07,94.75,0.129
203.10,94.90,0.129
203.13,95.04,0.129
203.15,95.18,0.129
203.18,95.32,0.129
203.21,95.46,0.129
203.24,95.60,0.129
203.27,95.75,0.130
203.30,95.89,0.130
203.33,96.03,0.130
203.35,96.17,0.130
203.38,96.31,0.130
203.41,96.45,0.130
203.44,96.60,0.130
203.47,96.74,0.130
203.50,96.88,0.130
203.52,97.02,0.130
203.55,97.16,0.130
203.58,97.30,0.130
203.61,97.45,0.130
203.64,97.59,0.130
203.67,97.73,0.130
203.69,97.87,0.130
203.72,98.01,0.130
203.75,98.15,0.130
203.78,98.30,0.130
203.81,98.44,0.130
203.83,98.58,0.130
203.86,98.72,0.130
203.89,98.86,0.130
203.92,99.00,0.130
203.95,99.15,0.130
203.98,99.29,0.130
204.00,99.43,0.130
204.03,99.57,0.130
204.06,99.71,0.130
204.09,99.85,0.130
204.12,100.00,0.130
204.15,100.14,0.130
204.18,100.28,0.130
204.20,100.42,0.130
204.23,100.56,0.130
204.26,100.71,0.130
204.29,100.85,0.131
204.32,100.99,0.131
204.35,101.13,0.131
204.37,101.27,0.131
204.40,101.41,0.131
204.43,101.56,0.131
204.46,101.70,0.131
204.49,101.84,0.131
204.52,101.98,0.131
204.54,102.12,0.131
204.57,102.27,0.131
204.60,102.41,0.131
204.63,102.55,0.131
204.66,102.69,0.131
204.68,102.83,0.131
204.71,102.97,0.131
204.74,103.12,0.131
204.77,103.26,0.131
204.80,103.40,0.131
204.83,103.54,0.131
204.85,103.68,0.131
204.88,103.83,0.131
204.91,103.97,0.131
204.94,104.11,0.131
204.97,104.25,0.131
205.00,104.39,0.131
205.03,104.53,0.131
205.05,104.67,0.131
205.08,104.82,0.131
205.11,104.96,0.131
205.14,105.10,0.131
205.17,105.24,0.131
205.20,105.38,0.131
205.22,105.52,0.131
205.25,105.67,0.131
205.28,105.81,0.131
205.31,105.95,0.131
205.34,106.09,0.131
205.37,106.23,0.131
205.39,106.37,0.131
205.42,106.52,0.131
205.45,106.66,0.131
205.48,106.80,0.131
205.51,106.94,0.131
205.53,107.08,0.132
205.56,107.23,0.132
205.59,107.37,0.132
205.62,107.51,0.132
205.65,107.65,0.132
205.68,107.79,0.132
205.70,107.93,0.132
205.73,108.08,0.132
205.76,108.22,0.132
205.79,108.36,0.132
205.82,108.50,0.132
205.85,108.64,0.132
205.88,108.78,0.132
205.90,108.93,0.132
205.93,109.07,0.132
205.96,109.21,0.132
205.99,109.35,0.132
206.02,109.49,0.132
206.05,109.63,0.132
206.07,109.78,0.132
206.10,109.92,0.132
206.13,110.06,0.132
206.16,110.20,0.132
206.19,110.34,0.132
206.22,110.48,0.132
206.24,110.63,0.132
206.27,110.77,0.132
206.30,110.91,0.132
206.33,111.05,0.132
206.36,111.19,0.132
206.38,111.34,0.132
206.41,111.48,0.132
206.44,111.62,0.132
206.47,111.76,0.132
206.50,111.90,0.132
206.53,112.04,0.132
206.55,112.19,0.132
206.58,112.33,0.132
206.61,112.47,0.132
206.64,112.61,0.132
206.67,112.75,0.132
206.70,112.89,0.132
206.73,113.04,0.132
206.75,113.18,0.132
206.78,113.32,0.132
206.81,113.46,0.133
206.84,113.60,0.133
206.87,113.74,0.133
206.90,113.89,0.133
206.92,114.03,0.133
206.95,114.17,0.133
206.98,114.31,0.133
207.01,114.45,0.133
207.04,114.60,0.133
207.07,114.74,0.133
207.09,114.88,0.133
207.12,115.02,0.133
207.15,115.16,0.133
207.18,115.30,0.133
207.21,115.45,0.133
207.23,115.59,0.133
207.26,115.73,0.133
207.29,115.87,0.133
207.32,116.01,0.133
207.35,116.15,0.133
207.38,116.30,0.133
207.40,116.44,0.133
207.43,116.58,0.133
207.46,116.72,0.133
207.49,116.86,0.133
207.52,117.00,0.133
207.55,117.15,0.133
207.58,117.29,0.133
207.60,117.43,0.133
207.63,117.57,0.133
207.66,117.71,0.133
207.69,117.85,0.133
207.72,118.00,0.133
207.75,118.14,0.133
207.77,118.28,0.133
207.80,118.42,0.133
207.83,118.56,0.133
207.86,118.71,0.133
207.89,118.85,0.133
207.92,118.99,0.133
207.94,119.13,0.133
207.97,119.27,0.133
208.00,119.41,0.134
208.03,119.56,0.134
208.06,119.70,0.134
208.08,119.84,0.134
208.11,119.98,0.134
208.14,120.12,0.134
208.17,120.26,0.134
208.20,120.41,0.134
208.23,120.55,0.134
208.25,120.69,0.134
208.28,120.83,0.134
208.31,120.97,0.134
208.34,121.11,0.134
208.37,121.26,0.134
208.40,121.40,0.134
208.43,121.54,0.134
208.45,121.68,0.134
208.48,121.82,0.134
208.51,121.97,0.134
208.54,122.11,0.134
208.57,122.25,0.134
208.60,122.39,0.134
208.62,122.53,0.134
208.65,122.67,0.134
208.68,122.82,0.134
208.71,122.96,0.134
208.74,123.10,0.134
208.77,123.24,0.134
208.79,123.38,0.134
208.82,123.52,0.134
208.85,123.67,0.134
208.88,123.81,0.134
208.91,123.95,0.134
208.93,124.09,0.134
208.96,124.23,0.134
208.99,124.37,0.134
209.02,124.52,0.134
209.05,124.66,0.134
209.08,124.80,0.134
209.10,124.94,0.134
209.13,125.08,0.134
209.16,125.22,0.134
209.19,125.37,0.134
209.22,125.51,0.134
209.25,125.65,0.134
209.28,125.79,0.134
209.30,125.93,0.135
209.33,126.07,0.135
209.36,126.22,0.135
209.39,126.36,0.135
209.42,126.50,0.135
209.45,126.64,0.135
209.47,126.78,0.135
209.50,126.93,0.135
209.53,127.07,0.135
209.56,127.21,0.135
209.59,127.35,0.135
209.62,127.49,0.135
209.64,127.63,0.135
209.67,127.77,0.135
209.70,127.92,0.135
209.73,128.06,0.135
209.76,128.20,0.135
209.78,128.34,0.135
209.81,128.48,0.135
209.84,128.62,0.135
209.87,128.77,0.135
209.90,128.91,0.135
209.93,129.05,0.135
209.95,129.19,0.135
209.98,129.33,0.135
210.01,129.47,0.135
210.04,129.62,0.135
210.07,129.76,0.135
210.10,129.90,0.135
210.13,130.04,0.135
210.15,130.18,0.135
210.18,130.33,0.135
210.21,130.47,0.135
210.24,130.61,0.135
210.27,130.75,0.135
210.30,130.89,0.135
210.32,131.04,0.135
210.35,131.18,0.135
210.38,131.32,0.135
210.41,131.46,0.135
210.44,131.60,0.135
210.47,131.75,0.135
210.49,131.89,0.135
210.52,132.03,0.135
210.55,132.17,0.135
210.58,132.31,0.135
210.61,132.45,0.135
210.63,132.59,0.135
210.66,132.74,0.135
210.69,132.88,0.135
210.72,133.02,0.135
210.75,133.16,0.135
210.78,133.30,0.135
210.80,133.44,0.135
210.83,133.59,0.135
210.86,133.73,0.135
210.89,133.87,0.135
210.92,134.01,0.135
210.95,134.15,0.135
210.98,134.29,0.135
211.00,134.44,0.135
211.03,134.58,0.135
211.06,134.72,0.135
211.09,134.86,0.135
211.12,135.00,0.135
211.15,135.15,0.135
211.17,135.29,0.135
211.20,135.43,0.135
211.23,135.57,0.135
211.26,135.71,0.135
211.29,135.85,0.135
211.32,136.00,0.135
211.34,136.14,0.135
211.37,136.28,0.135
211.40,136.42,0.136
211.43,136.56,0.135
211.46,136.70,0.136
211.48,136.85,0.136
211.51,136.99,0.136
211.54,137.13,0.136
211.57,137.27,0.136
211.60,137.41,0.136
211.63,137.55,0.136
211.65,137.70,0.136
211.68,137.84,0.136
211.71,137.98,0.136
211.74,138.12,0.136
211.77,138.26,0.136
211.80,138.40,0.136
211.83,138.54,0.136
211.85,138.69,0.136
211.88,138.83,0.136
211.91,138.97,0.136
211.94,139.11,0.136
211.97,139.25,0.136
212.00,139.40,0.136
212.02,139.54,0.136
212.05,139.68,0.136
212.08,139.82,0.136
212.11,139.96,0.136
212.14,140.10,0.136
212.17,140.25,0.136
212.19,140.39,0.136
212.22,140.53,0.136
212.25,140.67,0.136
212.28,140.81,0.136
212.31,140.96,0.136
212.33,141.10,0.136
212.36,141.24,0.136
212.39,141.38,0.136
212.42,141.52,0.136
212.45,141.66,0.136
212.48,141.81,0.136
212.50,141.95,0.136
212.53,142.09,0.136
212.56,142.23,0.136
212.59,142.37,0.136
212.62,142.51,0.136
212.65,142.66,0.136
212.68,142.80,0.136
212.70,142.94,0.136
212.73,143.08,0.136
212.76,143.22,0.136
212.79,143.36,0.136
212.82,143.50,0.136
212.85,143.65,0.136
212.87,143.79,0.136
212.90,143.93,0.136
212.93,144.07,0.136
212.96,144.21,0.136
212.99,144.35,0.136
213.02,144.50,0.136
213.04,144.64,0.136
213.07,144.78,0.137
213.10,144.92,0.137
213.13,145.06,0.137
213.16,145.21,0.137
213.18,145.35,0.137
213.21,145.49,0.137
213.24,145.63,0.137
213.27,145.77,0.137
213.30,145.91,0.137
213.33,146.06,0.137
213.35,146.20,0.137
213.38,146.34,0.137
213.41,146.48,0.137
213.44,146.62,0.137
213.47,146.76,0.137
213.50,146.91,0.137
213.53,147.05,0.137
213.55,147.19,0.137
213.58,147.33,0.137
213.61,147.47,0.137
213.64,147.62,0.137
213.67,147.76,0.137
213.70,147.90,0.137
213.72,148.04,0.137
213.75,148.18,0.137
213.78,148.32,0.137
213.81,148.47,0.137
213.84,148.61,0.137
213.87,148.75,0.137
213.89,148.89,0.137
213.92,149.03,0.137
213.95,149.17,
213.98,149.32,
213.99,,