File: DSC/2025_06_01_THC_Sorbic_Acid_n60C_150C_5Cmin_x3.csv
Filename,2025_06_01_THC_Sorbic_Acid_n60C_150C_5Cmin_x3
Instrument name,DSC2A-00468 (192.168.1.100)
Operator,Yarger
rundate,6/1/2025
Sample name,2025_06_01_THC_Sorbic_Acid_n60C_150C_5Cmin_x3
proceduresegments,Data Off ; Equilibrate -60.00 °C; Data On ; Ramp 5.00 °C/min to 150.00 °C; Data Off ; Isothermal 1.0 min; Data On ; Ramp 5.00 °C/min to -60.00 °C; Data Off ; Isothermal 1.0 min; Data On ; Ramp 5.00 °C/min to 150.00 °C; Data Off ; Isothermal 1.0 min; Data On ; Ramp 5.00 °C/min to -60.00 °C; Data Off ; Isothermal 1.0 min; Data On ; Ramp 5.00 °C/min to 30.00 °C
[File Parameters]
Run date,6/1/2025 8:55:42 PM
Trios version,5.1.1.46572
Original File Name,
Current File Name,D:\DSC2500\JYarger\2025_06_01_THC_Sorbic_Acid_n60C_150C_5Cmin_x3.tri
[Procedure]
Procedure Name,THC_SA_n60C_150C_5Cmin_x3
Sample Name,2025_06_01_THC_Sorbic_Acid_n60C_150C_5Cmin_x3
Sample Mass,7.48 mg
Reference Sample Mass,0 mg
Pan Mass,56.49 mg
Pan Number,14
Reference Pan Mass,56.96 mg
Reference Pan Number,10
Pan Type,Tzero Aluminum Hermetic
Comments,Al Hermetic DSC Consumables sealed Pan/Lid. A2 Tray (Google Sheet: DSC_Samples_A2_Tray_May2025)
Project Name,CA
Operator,Yarger
Test,Custom
Unload Max Temperature,30
Unload Min Temperature,30
Load Max Temperature,30
Load Min Temperature,30
Stop on Gas Flow Error,Yes
[Signal List]
Signal #1,Time (min)
Signal #2,Temperature (°C)
Signal #3,Heat Flow (mW)
Signal #4,Delta T (µV)
Signal #5,Delta Tzero (µV)
Signal #6,Tzero Temperature (°C)
Signal #7,Cell Purge (mL/min)
Signal #8,Heater Temp (°C)
Signal #9,Power Delivered (W)
Signal #10,Reference Junction Temperature (°C)
Signal #11,Flange Temperature (°C)
Signal #12,Heat Flow Phase (rad)
Signal #13,Total Heat Capacity (J/°C)
Signal #14,Heat Capacity (J/°C)
[Configuration]
Company Name,ASU
Instrument Name,DSC2A-00468
Instrument Type,DSC2500
Serial Number,DSC2A-00468
IP,192.168.1.100
Location of Instrument,MRRC
DisplayType,Unknown
Sample Interval ,0.1 s/pt
Selected Heat Flow,T4P
Exotherm Direction,Down
Cell Serial,DRC2-00792
Lid Type,Standard
Cooler,RCS 90
Leave Cooler on at End of Sequence,On
Gas 2,Nitrogen
Gas Selected,Channel 1
Flow Rate,50 mL/min
Secondary Purge,On
Licensed Heat Flow,Heat Flow T4P
Modulation Licensed,Yes
[Versions]
Common IDD Version,1
Cortex Version,VER 2.10.2.31
Driver,5.0.0.6
GDM Version,1.0.3.3
TouchscreenVersion,1.0.0.16145
FEP Version,1.2.1.21
FEP Bootloader,2.0.0.5
AutoSampler Version,2.1.1.26
Auto Sampler Bootloader,2.0.0.5
FCM Version,1.1.0.3
FCM Bootloader,2.0.0.5
[Experiment Logs]
Experiment Log Entry # 1,Data On set to 0
Experiment Log Entry # 3,Equilibrate Segment -60 (C) Started
Experiment Log Entry # 5,Air Cool is off.
Experiment Log Entry # 7,Data On set to 1
Experiment Log Entry # 9,Ramp Segment 5 C/min to 150 Started
Experiment Log Entry # 11,Data On set to 0
Experiment Log Entry # 13,Isothermal Segment 1 min started
Experiment Log Entry # 15,Data On set to 1
Experiment Log Entry # 17,Ramp Segment 5 C/min to -60 Started
Experiment Log Entry # 19,Data On set to 0
Experiment Log Entry # 21,Isothermal Segment 1 min started
Experiment Log Entry # 23,Data On set to 1
Experiment Log Entry # 25,Ramp Segment 5 C/min to 150 Started
Experiment Log Entry # 27,Data On set to 0
Experiment Log Entry # 29,Isothermal Segment 1 min started
Experiment Log Entry # 31,Data On set to 1
Experiment Log Entry # 33,Ramp Segment 5 C/min to -60 Started
Experiment Log Entry # 35,Data On set to 0
Experiment Log Entry # 37,Isothermal Segment 1 min started
Experiment Log Entry # 39,Data On set to 1
Experiment Log Entry # 41,Ramp Segment 5 C/min to 30 Started
Experiment Log Entry # 43,Auto sampler has detected that GDM has gone offline
[Method Log]
Method Log Entry # 1,Data Off
Method Log Entry # 2,Equilibrate -60 °C
Method Log Entry # 3,Data On
Method Log Entry # 4,(Ramp 763934) Ramp 5 °C/minute to 150 °C
Method Log Entry # 5,Data Off
Method Log Entry # 6,Isothermal 1 minutes
Method Log Entry # 7,Data On
Method Log Entry # 8,(Ramp 763938) Ramp 5 °C/minute to -60 °C
Method Log Entry # 9,Data Off
Method Log Entry # 10,Isothermal 1 minutes
Method Log Entry # 11,Data On
Method Log Entry # 12,(Ramp 763942) Ramp 5 °C/minute to 150 °C
Method Log Entry # 13,Data Off
Method Log Entry # 14,Isothermal 1 minutes
Method Log Entry # 15,Data On
Method Log Entry # 16,(Ramp 763946) Ramp 5 °C/minute to -60 °C
Method Log Entry # 17,Data Off
Method Log Entry # 18,Isothermal 1 minutes
Method Log Entry # 19,Data On
Method Log Entry # 20,(Ramp 763950) Ramp 5 °C/minute to 30 °C
Cell Serial,DRC2-00792
[T1 Calibration]
Slope,-0.008529666
Offset,9.636258
Initial Temperature,98.23
GUID,f8bfdadc-4977-4fdf-ba6d-0ba9134940c3
[TZero Calibration]
Date Applied,11/29/2022 4:06:13 PM
Description,From -89.059 °C to 396.009 °C at 20.000°C/min
Gas Type,Nitrogen
Pan Type,None
Source Files 1,C:\Users\yargerlab\Desktop\DSC Data\General\TZero_calibration_11_29_22_2nd(2).tri
Source Files 2,C:\Users\yargerlab\Desktop\DSC Data\General\TZero_calibration_11_29_22_2nd(3).tri
Delta T Offset,13.05235
Delta T Slope,-0.007271007
Delta T0 Offset,-13.69128
Delta T0 Slope,0.06063341
[Temperature Calibration]
Date Applied,11/29/2022 7:12:28 PM
Description,From 106.590 °C to 186.590 °C at 10.000°C/min
Gas Type,Nitrogen
Pan Type,Tzero Aluminum Hermetic
Source Files 1,C:\Users\yargerlab\Desktop\DSC Data\General\Indium(6).tri
Measured 1,157.391
Known 1,156.598
[Cell Constant Calibration]
Date Applied,11/29/2022 7:12:29 PM
Description,From 106.590 °C to 186.590 °C at 10.000°C/min
Gas Type,Nitrogen
Pan Type,Tzero Aluminum Hermetic
Source Files 1,C:\Users\yargerlab\Desktop\DSC Data\General\Indium(6).tri
T4P KCell,1.006051
Onset Slope,63.26126 mW/°C
[Direct Cp Calibration]
Date Applied,11/30/2022 11:04:51 AM
Description,From -79.983 °C to 298.409 °C at 10.000°C/min
Gas Type,Nitrogen
Pan Type,Tzero Aluminum Hermetic
Source Files 1,C:\Users\yargerlab\Desktop\DSC Data\General\Sapphire_Heat_Capacity_11_30_22.tri
[Rev Cp Calibration]
Date Applied,11/30/2022 1:58:51 PM
Description,From -79.996 °C to 292.812 °C at 3.000°C/min
Gas Type,Nitrogen
Pan Type,Tzero Aluminum Hermetic
Source Files 1,C:\Users\yargerlab\Desktop\DSC Data\General\Sapphire_MDSC_Calibration_11_30_22.tri
[step]
Ramp 5.00 °C/min to 150.00 °C
Time,Temperature,Heat Flow (Normalized)
min,°C,W/g
0.00,-59.66,-0.064
0.03,-59.67,-0.063
0.06,-59.68,-0.054
0.08,-59.66,-0.049
0.11,-59.62,-0.043
0.14,-59.54,-0.030
0.17,-59.45,-0.013
0.20,-59.36,0.004
0.23,-59.25,0.019
0.26,-59.14,0.031
0.28,-59.02,0.040
0.31,-58.90,0.049
0.34,-58.78,0.056
0.37,-58.65,0.062
0.40,-58.52,0.066
0.43,-58.39,0.071
0.45,-58.26,0.075
0.48,-58.13,0.077
0.51,-58.00,0.079
0.54,-57.86,0.081
0.57,-57.73,0.083
0.60,-57.59,0.084
0.62,-57.45,0.085
0.65,-57.32,0.086
0.68,-57.18,0.086
0.71,-57.04,0.087
0.74,-56.90,0.087
0.77,-56.76,0.088
0.79,-56.62,0.088
0.82,-56.49,0.088
0.85,-56.35,0.089
0.88,-56.21,0.089
0.91,-56.07,0.089
0.93,-55.93,0.090
0.96,-55.79,0.090
0.99,-55.65,0.090
1.02,-55.51,0.091
1.05,-55.37,0.091
1.08,-55.23,0.091
1.11,-55.09,0.091
1.13,-54.95,0.092
1.16,-54.81,0.092
1.19,-54.67,0.092
1.22,-54.52,0.092
1.25,-54.38,0.092
1.28,-54.24,0.092
1.30,-54.10,0.092
1.33,-53.96,0.092
1.36,-53.82,0.093
1.39,-53.68,0.093
1.42,-53.54,0.093
1.44,-53.40,0.093
1.47,-53.26,0.093
1.50,-53.12,0.093
1.53,-52.97,0.093
1.56,-52.83,0.093
1.59,-52.69,0.093
1.62,-52.55,0.093
1.64,-52.41,0.093
1.67,-52.27,0.094
1.70,-52.13,0.094
1.73,-51.98,0.094
1.76,-51.84,0.094
1.78,-51.70,0.094
1.81,-51.56,0.094
1.84,-51.42,0.094
1.87,-51.28,0.094
1.90,-51.14,0.094
1.93,-51.00,0.094
1.96,-50.85,0.094
1.98,-50.71,0.094
2.01,-50.57,0.094
2.04,-50.43,0.094
2.07,-50.29,0.094
2.10,-50.15,0.094
2.13,-50.00,0.094
2.15,-49.86,0.094
2.18,-49.72,0.094
2.21,-49.58,0.094
2.24,-49.44,0.094
2.27,-49.30,0.094
2.29,-49.16,0.094
2.32,-49.01,0.094
2.35,-48.87,0.094
2.38,-48.73,0.094
2.41,-48.59,0.094
2.44,-48.45,0.094
2.46,-48.31,0.094
2.49,-48.17,0.094
2.52,-48.02,0.094
2.55,-47.88,0.094
2.58,-47.74,0.094
2.61,-47.60,0.094
2.64,-47.46,0.094
2.66,-47.32,0.094
2.69,-47.18,0.094
2.72,-47.03,0.094
2.75,-46.89,0.094
2.78,-46.75,0.094
2.81,-46.61,0.094
2.83,-46.47,0.094
2.86,-46.33,0.094
2.89,-46.18,0.094
2.92,-46.04,0.094
2.95,-45.90,0.094
2.98,-45.76,0.094
3.00,-45.62,0.094
3.03,-45.48,0.094
3.06,-45.34,0.094
3.09,-45.19,0.094
3.12,-45.05,0.094
3.14,-44.91,0.094
3.17,-44.77,0.094
3.20,-44.63,0.094
3.23,-44.48,0.094
3.26,-44.34,0.094
3.29,-44.20,0.095
3.31,-44.06,0.095
3.34,-43.92,0.095
3.37,-43.78,0.095
3.40,-43.63,0.095
3.43,-43.49,0.095
3.46,-43.35,0.095
3.49,-43.21,0.095
3.51,-43.07,0.095
3.54,-42.93,0.095
3.57,-42.79,0.095
3.60,-42.65,0.095
3.63,-42.50,0.095
3.66,-42.36,0.095
3.68,-42.22,0.095
3.71,-42.08,0.095
3.74,-41.94,0.095
3.77,-41.79,0.095
3.80,-41.65,0.095
3.83,-41.51,0.095
3.85,-41.37,0.095
3.88,-41.23,0.095
3.91,-41.09,0.095
3.94,-40.95,0.095
3.97,-40.80,0.095
3.99,-40.66,0.095
4.02,-40.52,0.095
4.05,-40.38,0.095
4.08,-40.24,0.095
4.11,-40.10,0.095
4.14,-39.95,0.095
4.16,-39.81,0.095
4.19,-39.67,0.095
4.22,-39.53,0.095
4.25,-39.39,0.095
4.28,-39.24,0.095
4.31,-39.10,0.095
4.34,-38.96,0.095
4.36,-38.82,0.095
4.39,-38.68,0.095
4.42,-38.54,0.096
4.45,-38.39,0.096
4.48,-38.25,0.096
4.50,-38.11,0.096
4.53,-37.97,0.096
4.56,-37.83,0.096
4.59,-37.68,0.096
4.62,-37.54,0.096
4.65,-37.40,0.096
4.68,-37.26,0.096
4.70,-37.12,0.096
4.73,-36.97,0.096
4.76,-36.83,0.096
4.79,-36.69,0.096
4.82,-36.55,0.096
4.85,-36.41,0.096
4.87,-36.27,0.096
4.90,-36.12,0.096
4.93,-35.98,0.096
4.96,-35.84,0.096
4.99,-35.70,0.096
5.01,-35.56,0.096
5.04,-35.41,0.096
5.07,-35.27,0.096
5.10,-35.13,0.097
5.13,-34.99,0.097
5.16,-34.85,0.097
5.19,-34.71,0.097
5.21,-34.56,0.097
5.24,-34.42,0.097
5.27,-34.28,0.097
5.30,-34.14,0.097
5.33,-34.00,0.097
5.35,-33.85,0.097
5.38,-33.71,0.097
5.41,-33.57,0.097
5.44,-33.43,0.097
5.47,-33.29,0.097
5.50,-33.15,0.097
5.53,-33.00,0.097
5.55,-32.86,0.097
5.58,-32.72,0.097
5.61,-32.58,0.097
5.64,-32.44,0.097
5.67,-32.30,0.097
5.70,-32.16,0.097
5.72,-32.01,0.097
5.75,-31.87,0.097
5.78,-31.73,0.098
5.81,-31.59,0.098
5.84,-31.44,0.098
5.86,-31.30,0.098
5.89,-31.16,0.098
5.92,-31.02,0.098
5.95,-30.88,0.098
5.98,-30.74,0.098
6.01,-30.59,0.098
6.04,-30.45,0.098
6.06,-30.31,0.099
6.09,-30.17,0.099
6.12,-30.02,0.099
6.15,-29.88,0.099
6.18,-29.74,0.099
6.20,-29.60,0.099
6.23,-29.46,0.099
6.26,-29.31,0.099
6.29,-29.17,0.099
6.32,-29.03,0.099
6.35,-28.89,0.100
6.38,-28.75,0.100
6.40,-28.61,0.100
6.43,-28.46,0.100
6.46,-28.32,0.100
6.49,-28.18,0.100
6.52,-28.04,0.100
6.55,-27.90,0.100
6.57,-27.75,0.100
6.60,-27.61,0.100
6.63,-27.47,0.100
6.66,-27.33,0.101
6.69,-27.19,0.101
6.71,-27.05,0.101
6.74,-26.91,0.101
6.77,-26.76,0.101
6.80,-26.62,0.101
6.83,-26.48,0.101
6.86,-26.34,0.102
6.89,-26.20,0.102
6.91,-26.06,0.102
6.94,-25.92,0.102
6.97,-25.77,0.102
7.00,-25.63,0.102
7.03,-25.49,0.103
7.05,-25.35,0.103
7.08,-25.21,0.103
7.11,-25.06,0.103
7.14,-24.92,0.103
7.17,-24.78,0.104
7.20,-24.64,0.104
7.23,-24.50,0.104
7.25,-24.36,0.104
7.28,-24.21,0.105
7.31,-24.07,0.105
7.34,-23.93,0.105
7.37,-23.79,0.105
7.40,-23.65,0.106
7.42,-23.51,0.106
7.45,-23.37,0.106
7.48,-23.22,0.106
7.51,-23.08,0.107
7.54,-22.94,0.107
7.56,-22.80,0.107
7.59,-22.66,0.108
7.62,-22.51,0.108
7.65,-22.37,0.108
7.68,-22.23,0.109
7.71,-22.09,0.109
7.74,-21.95,0.109
7.76,-21.81,0.109
7.79,-21.67,0.110
7.82,-21.52,0.110
7.85,-21.38,0.110
7.88,-21.24,0.111
7.90,-21.10,0.111
7.93,-20.96,0.111
7.96,-20.82,0.112
7.99,-20.68,0.112
8.02,-20.53,0.113
8.05,-20.39,0.113
8.08,-20.25,0.113
8.10,-20.11,0.114
8.13,-19.97,0.114
8.16,-19.83,0.114
8.19,-19.68,0.115
8.22,-19.54,0.115
8.25,-19.40,0.115
8.27,-19.26,0.115
8.30,-19.12,0.116
8.33,-18.98,0.116
8.36,-18.83,0.116
8.39,-18.69,0.117
8.41,-18.55,0.117
8.44,-18.41,0.117
8.47,-18.27,0.117
8.50,-18.13,0.118
8.53,-17.98,0.118
8.56,-17.84,0.118
8.58,-17.70,0.118
8.61,-17.56,0.119
8.64,-17.42,0.119
8.67,-17.28,0.119
8.70,-17.14,0.119
8.73,-16.99,0.119
8.75,-16.85,0.119
8.78,-16.71,0.119
8.81,-16.57,0.119
8.84,-16.43,0.120
8.87,-16.28,0.120
8.90,-16.14,0.120
8.93,-16.00,0.120
8.95,-15.86,0.120
8.98,-15.72,0.120
9.01,-15.57,0.120
9.04,-15.43,0.120
9.07,-15.29,0.120
9.10,-15.15,0.120
9.12,-15.01,0.120
9.15,-14.86,0.120
9.18,-14.72,0.120
9.21,-14.58,0.120
9.24,-14.44,0.120
9.27,-14.30,0.120
9.29,-14.16,0.120
9.32,-14.01,0.120
9.35,-13.87,0.120
9.38,-13.73,0.120
9.41,-13.59,0.120
9.43,-13.45,0.120
9.46,-13.30,0.120
9.49,-13.16,0.120
9.52,-13.02,0.120
9.55,-12.88,0.120
9.58,-12.74,0.120
9.60,-12.60,0.120
9.63,-12.45,0.120
9.66,-12.31,0.120
9.69,-12.17,0.120
9.72,-12.03,0.120
9.75,-11.89,0.120
9.78,-11.75,0.120
9.80,-11.60,0.120
9.83,-11.46,0.120
9.86,-11.32,0.120
9.89,-11.18,0.120
9.92,-11.04,0.120
9.95,-10.89,0.120
9.97,-10.75,0.120
10.00,-10.61,0.120
10.03,-10.47,0.120
10.06,-10.33,0.120
10.09,-10.18,0.120
10.12,-10.04,0.120
10.14,-9.90,0.120
10.17,-9.76,0.120
10.20,-9.62,0.120
10.23,-9.48,0.120
10.26,-9.33,0.120
10.28,-9.19,0.120
10.31,-9.05,0.120
10.34,-8.91,0.120
10.37,-8.77,0.120
10.40,-8.63,0.121
10.43,-8.48,0.121
10.45,-8.34,0.121
10.48,-8.20,0.121
10.51,-8.06,0.121
10.54,-7.91,0.121
10.57,-7.77,0.121
10.60,-7.63,0.121
10.63,-7.49,0.121
10.65,-7.35,0.121
10.68,-7.21,0.121
10.71,-7.07,0.121
10.74,-6.92,0.121
10.77,-6.78,0.121
10.80,-6.64,0.121
10.82,-6.50,0.121
10.85,-6.36,0.121
10.88,-6.21,0.121
10.91,-6.07,0.121
10.94,-5.93,0.121
10.97,-5.79,0.121
10.99,-5.65,0.121
11.02,-5.51,0.121
11.05,-5.36,0.121
11.08,-5.22,0.121
11.11,-5.08,0.121
11.13,-4.94,0.121
11.16,-4.80,0.121
11.19,-4.65,0.121
11.22,-4.51,0.121
11.25,-4.37,0.121
11.28,-4.23,0.121
11.30,-4.09,0.122
11.33,-3.95,0.122
11.36,-3.80,0.122
11.39,-3.66,0.122
11.42,-3.52,0.122
11.45,-3.38,0.122
11.48,-3.24,0.122
11.50,-3.10,0.122
11.53,-2.95,0.122
11.56,-2.81,0.122
11.59,-2.67,0.122
11.62,-2.53,0.122
11.65,-2.39,0.122
11.67,-2.24,0.122
11.70,-2.10,0.122
11.73,-1.96,0.122
11.76,-1.82,0.122
11.79,-1.68,0.122
11.82,-1.54,0.122
11.84,-1.39,0.122
11.87,-1.25,0.122
11.90,-1.11,0.122
11.93,-0.97,0.122
11.96,-0.83,0.122
11.98,-0.68,0.122
12.01,-0.54,0.122
12.04,-0.40,0.122
12.07,-0.26,0.122
12.10,-0.12,0.122
12.13,0.02,0.122
12.15,0.17,0.122
12.18,0.31,0.122
12.21,0.45,0.122
12.24,0.59,0.123
12.27,0.73,0.123
12.30,0.88,0.123
12.33,1.02,0.123
12.35,1.16,0.123
12.38,1.30,0.123
12.41,1.44,0.123
12.44,1.58,0.123
12.47,1.73,0.123
12.50,1.87,0.123
12.52,2.01,0.123
12.55,2.15,0.123
12.58,2.29,0.123
12.61,2.43,0.123
12.64,2.58,0.123
12.67,2.72,0.123
12.69,2.86,0.123
12.72,3.00,0.123
12.75,3.14,0.123
12.78,3.28,0.123
12.81,3.43,0.123
12.83,3.57,0.123
12.86,3.71,0.123
12.89,3.85,0.123
12.92,3.99,0.123
12.95,4.14,0.123
12.98,4.28,0.123
13.00,4.42,0.123
13.03,4.56,0.123
13.06,4.70,0.123
13.09,4.84,0.123
13.12,4.99,0.123
13.15,5.13,0.124
13.18,5.27,0.124
13.20,5.41,0.124
13.23,5.55,0.124
13.26,5.70,0.124
13.29,5.84,0.124
13.32,5.98,0.124
13.35,6.12,0.124
13.37,6.26,0.124
13.40,6.40,0.124
13.43,6.55,0.124
13.46,6.69,0.124
13.49,6.83,0.124
13.52,6.97,0.124
13.54,7.11,0.124
13.57,7.26,0.124
13.60,7.40,0.124
13.63,7.54,0.124
13.66,7.68,0.124
13.68,7.82,0.124
13.71,7.96,0.124
13.74,8.11,0.124
13.77,8.25,0.124
13.80,8.39,0.125
13.83,8.53,0.125
13.85,8.67,0.125
13.88,8.81,0.125
13.91,8.96,0.125
13.94,9.10,0.125
13.97,9.24,0.125
14.00,9.38,0.125
14.03,9.52,0.125
14.05,9.67,0.125
14.08,9.81,0.125
14.11,9.95,0.125
14.14,10.09,0.125
14.17,10.23,0.125
14.20,10.37,0.125
14.22,10.52,0.125
14.25,10.66,0.126
14.28,10.80,0.126
14.31,10.94,0.126
14.34,11.08,0.126
14.37,11.22,0.126
14.39,11.37,0.126
14.42,11.51,0.126
14.45,11.65,0.126
14.48,11.79,0.126
14.51,11.93,0.126
14.53,12.08,0.126
14.56,12.22,0.126
14.59,12.36,0.127
14.62,12.50,0.127
14.65,12.64,0.127
14.68,12.78,0.127
14.70,12.92,0.127
14.73,13.07,0.127
14.76,13.21,0.127
14.79,13.35,0.127
14.82,13.49,0.127
14.85,13.64,0.127
14.88,13.78,0.127
14.90,13.92,0.128
14.93,14.06,0.128
14.96,14.20,0.128
14.99,14.35,0.128
15.02,14.49,0.128
15.05,14.63,0.128
15.07,14.77,0.128
15.10,14.91,0.129
15.13,15.05,0.129
15.16,15.20,0.129
15.19,15.34,0.129
15.22,15.48,0.129
15.24,15.62,0.129
15.27,15.76,0.129
15.30,15.90,0.129
15.33,16.05,0.129
15.36,16.19,0.129
15.38,16.33,0.129
15.41,16.47,0.130
15.44,16.61,0.130
15.47,16.75,0.130
15.50,16.89,0.130
15.53,17.04,0.130
15.55,17.18,0.130
15.58,17.32,0.130
15.61,17.46,0.130
15.64,17.60,0.130
15.67,17.74,0.131
15.70,17.89,0.131
15.73,18.03,0.131
15.75,18.17,0.131
15.78,18.31,0.131
15.81,18.45,0.131
15.84,18.59,0.131
15.87,18.74,0.131
15.90,18.88,0.131
15.92,19.02,0.132
15.95,19.16,0.132
15.98,19.30,0.132
16.01,19.44,0.132
16.04,19.59,0.132
16.07,19.73,0.132
16.09,19.87,0.132
16.12,20.01,0.132
16.15,20.15,0.133
16.18,20.30,0.133
16.21,20.44,0.133
16.23,20.58,0.133
16.26,20.72,0.133
16.29,20.86,0.133
16.32,21.00,0.133
16.35,21.15,0.133
16.38,21.29,0.133
16.40,21.43,0.134
16.43,21.57,0.134
16.46,21.71,0.134
16.49,21.86,0.134
16.52,22.00,0.134
16.55,22.14,0.134
16.58,22.28,0.134
16.60,22.42,0.134
16.63,22.56,0.134
16.66,22.70,0.135
16.69,22.85,0.135
16.72,22.99,0.135
16.75,23.13,0.135
16.77,23.27,0.135
16.80,23.41,0.135
16.83,23.56,0.135
16.86,23.70,0.135
16.89,23.84,0.135
16.92,23.98,0.135
16.94,24.12,0.136
16.97,24.26,0.136
17.00,24.41,0.136
17.03,24.55,0.136
17.06,24.69,0.136
17.08,24.83,0.136
17.11,24.97,0.136
17.14,25.11,0.136
17.17,25.26,0.136
17.20,25.40,0.136
17.23,25.54,0.137
17.26,25.68,0.137
17.28,25.82,0.137
17.31,25.96,0.137
17.34,26.11,0.137
17.37,26.25,0.137
17.40,26.39,0.137
17.43,26.53,0.137
17.45,26.67,0.137
17.48,26.82,0.137
17.51,26.96,0.137
17.54,27.10,0.138
17.57,27.24,0.138
17.59,27.38,0.138
17.62,27.52,0.138
17.65,27.66,0.138
17.68,27.81,0.138
17.71,27.95,0.138
17.74,28.09,0.138
17.77,28.23,0.138
17.79,28.38,0.138
17.82,28.52,0.138
17.85,28.66,0.138
17.88,28.80,0.139
17.91,28.94,0.139
17.93,29.08,0.139
17.96,29.23,0.139
17.99,29.37,0.139
18.02,29.51,0.139
18.05,29.65,0.139
18.08,29.79,0.139
18.11,29.93,0.139
18.13,30.08,0.139
18.16,30.22,0.139
18.19,30.36,0.139
18.22,30.50,0.140
18.25,30.64,0.140
18.28,30.78,0.140
18.30,30.93,0.140
18.33,31.07,0.140
18.36,31.21,0.140
18.39,31.35,0.140
18.42,31.49,0.140
18.44,31.64,0.140
18.47,31.78,0.140
18.50,31.92,0.141
18.53,32.06,0.141
18.56,32.20,0.141
18.59,32.34,0.141
18.62,32.49,0.141
18.64,32.63,0.141
18.67,32.77,0.141
18.70,32.91,0.141
18.73,33.05,0.141
18.76,33.19,0.141
18.78,33.34,0.141
18.81,33.48,0.141
18.84,33.62,0.142
18.87,33.76,0.142
18.90,33.90,0.142
18.93,34.05,0.142
18.96,34.19,0.142
18.98,34.33,0.142
19.01,34.47,0.142
19.04,34.61,0.142
19.07,34.75,0.142
19.10,34.90,0.142
19.13,35.04,0.143
19.15,35.18,0.143
19.18,35.32,0.143
19.21,35.46,0.143
19.24,35.60,0.143
19.27,35.75,0.143
19.29,35.89,0.143
19.32,36.03,0.143
19.35,36.17,0.143
19.38,36.31,0.143
19.41,36.45,0.144
19.44,36.59,0.144
19.47,36.74,0.144
19.49,36.88,0.144
19.52,37.02,0.144
19.55,37.16,0.144
19.58,37.30,0.144
19.61,37.45,0.144
19.63,37.59,0.144
19.66,37.73,0.144
19.69,37.87,0.144
19.72,38.01,0.145
19.75,38.16,0.145
19.78,38.30,0.145
19.81,38.44,0.145
19.83,38.58,0.145
19.86,38.72,0.145
19.89,38.86,0.145
19.92,39.00,0.145
19.95,39.15,0.145
19.98,39.29,0.145
20.00,39.43,0.146
20.03,39.57,0.146
20.06,39.71,0.146
20.09,39.86,0.146
20.12,40.00,0.146
20.14,40.14,0.146
20.17,40.28,0.146
20.20,40.42,0.146
20.23,40.56,0.146
20.26,40.71,0.146
20.29,40.85,0.147
20.32,40.99,0.147
20.34,41.13,0.147
20.37,41.27,0.147
20.40,41.41,0.147
20.43,41.56,0.147
20.46,41.70,0.147
20.48,41.84,0.147
20.51,41.98,0.148
20.54,42.12,0.148
20.57,42.27,0.148
20.60,42.41,0.148
20.63,42.55,0.148
20.66,42.69,0.148
20.68,42.83,0.148
20.71,42.97,0.148
20.74,43.12,0.148
20.77,43.26,0.149
20.80,43.40,0.149
20.83,43.54,0.149
20.85,43.68,0.149
20.88,43.82,0.149
20.91,43.97,0.149
20.94,44.11,0.149
20.97,44.25,0.149
20.99,44.39,0.149
21.02,44.53,0.150
21.05,44.67,0.150
21.08,44.81,0.150
21.11,44.96,0.150
21.14,45.10,0.150
21.17,45.24,0.150
21.19,45.38,0.150
21.22,45.52,0.150
21.25,45.67,0.150
21.28,45.81,0.151
21.31,45.95,0.151
21.33,46.09,0.151
21.36,46.23,0.151
21.39,46.37,0.151
21.42,46.51,0.151
21.45,46.66,0.151
21.48,46.80,0.151
21.51,46.94,0.151
21.53,47.08,0.152
21.56,47.22,0.152
21.59,47.37,0.152
21.62,47.51,0.152
21.65,47.65,0.152
21.68,47.79,0.152
21.70,47.93,0.152
21.73,48.08,0.152
21.76,48.22,0.153
21.79,48.36,0.153
21.82,48.50,0.153
21.84,48.64,0.153
21.87,48.78,0.153
21.90,48.92,0.153
21.93,49.07,0.153
21.96,49.21,0.153
21.99,49.35,0.154
22.02,49.49,0.154
22.04,49.63,0.154
22.07,49.77,0.154
22.10,49.92,0.154
22.13,50.06,0.154
22.16,50.20,0.154
22.18,50.34,0.155
22.21,50.48,0.155
22.24,50.63,0.155
22.27,50.77,0.155
22.30,50.91,0.155
22.33,51.05,0.155
22.36,51.19,0.155
22.38,51.33,0.155
22.41,51.48,0.156
22.44,51.62,0.156
22.47,51.76,0.156
22.50,51.90,0.156
22.53,52.04,0.156
22.55,52.18,0.156
22.58,52.33,0.156
22.61,52.47,0.157
22.64,52.61,0.157
22.67,52.75,0.157
22.69,52.89,0.157
22.72,53.04,0.157
22.75,53.18,0.157
22.78,53.32,0.157
22.81,53.46,0.157
22.84,53.60,0.158
22.87,53.74,0.158
22.89,53.88,0.158
22.92,54.03,0.158
22.95,54.17,0.158
22.98,54.31,0.158
23.01,54.45,0.158
23.03,54.59,0.159
23.06,54.73,0.159
23.09,54.88,0.159
23.12,55.02,0.159
23.15,55.16,0.159
23.18,55.30,0.159
23.21,55.44,0.159
23.23,55.59,0.159
23.26,55.73,0.160
23.29,55.87,0.160
23.32,56.01,0.160
23.35,56.15,0.160
23.38,56.29,0.160
23.40,56.44,0.160
23.43,56.58,0.161
23.46,56.72,0.161
23.49,56.86,0.161
23.52,57.00,0.161
23.54,57.14,0.161
23.57,57.29,0.161
23.60,57.43,0.161
23.63,57.57,0.162
23.66,57.71,0.162
23.69,57.85,0.162
23.72,57.99,0.162
23.74,58.14,0.162
23.77,58.28,0.162
23.80,58.42,0.162
23.83,58.56,0.163
23.86,58.70,0.163
23.88,58.85,0.163
23.91,58.99,0.163
23.94,59.13,0.163
23.97,59.27,0.163
24.00,59.41,0.164
24.03,59.55,0.164
24.06,59.69,0.164
24.08,59.84,0.164
24.11,59.98,0.164
24.14,60.12,0.164
24.17,60.26,0.165
24.20,60.40,0.165
24.23,60.55,0.165
24.25,60.69,0.165
24.28,60.83,0.165
24.31,60.97,0.165
24.34,61.11,0.166
24.37,61.25,0.166
24.39,61.39,0.166
24.42,61.54,0.166
24.45,61.68,0.166
24.48,61.82,0.166
24.51,61.96,0.167
24.54,62.10,0.167
24.57,62.25,0.167
24.59,62.39,0.167
24.62,62.53,0.167
24.65,62.67,0.167
24.68,62.81,0.168
24.71,62.95,0.168
24.73,63.10,0.168
24.76,63.24,0.168
24.79,63.38,0.168
24.82,63.52,0.168
24.85,63.66,0.169
24.88,63.81,0.169
24.91,63.95,0.169
24.93,64.09,0.169
24.96,64.23,0.169
24.99,64.37,0.170
25.02,64.51,0.170
25.05,64.65,0.170
25.08,64.80,0.170
25.10,64.94,0.170
25.13,65.08,0.170
25.16,65.22,0.171
25.19,65.36,0.171
25.22,65.50,0.171
25.24,65.65,0.171
25.27,65.79,0.171
25.30,65.93,0.172
25.33,66.07,0.172
25.36,66.21,0.172
25.39,66.35,0.172
25.42,66.50,0.173
25.44,66.64,0.173
25.47,66.78,0.173
25.50,66.92,0.173
25.53,67.06,0.173
25.56,67.20,0.174
25.58,67.35,0.174
25.61,67.49,0.174
25.64,67.63,0.174
25.67,67.77,0.174
25.70,67.91,0.174
25.73,68.05,0.175
25.76,68.20,0.175
25.78,68.34,0.175
25.81,68.48,0.175
25.84,68.62,0.175
25.87,68.76,0.176
25.90,68.91,0.176
25.93,69.05,0.176
25.95,69.19,0.176
25.98,69.33,0.177
26.01,69.47,0.177
26.04,69.61,0.177
26.07,69.75,0.177
26.09,69.90,0.177
26.12,70.04,0.178
26.15,70.18,0.178
26.18,70.32,0.178
26.21,70.46,0.178
26.24,70.60,0.178
26.27,70.75,0.179
26.29,70.89,0.179
26.32,71.03,0.179
26.35,71.17,0.179
26.38,71.31,0.180
26.41,71.45,0.180
26.43,71.60,0.180
26.46,71.74,0.180
26.49,71.88,0.181
26.52,72.02,0.181
26.55,72.16,0.181
26.58,72.30,0.181
26.61,72.45,0.181
26.63,72.59,0.182
26.66,72.73,0.182
26.69,72.87,0.182
26.72,73.01,0.183
26.75,73.16,0.183
26.78,73.30,0.183
26.80,73.44,0.183
26.83,73.58,0.184
26.86,73.72,0.184
26.89,73.86,0.184
26.92,74.01,0.184
26.94,74.15,0.184
26.97,74.29,0.185
27.00,74.43,0.185
27.03,74.57,0.185
27.06,74.71,0.185
27.09,74.85,0.185
27.12,74.99,0.185
27.14,75.14,0.186
27.17,75.28,0.186
27.20,75.42,0.186
27.23,75.56,0.187
27.26,75.70,0.187
27.28,75.84,0.187
27.31,75.99,0.187
27.34,76.13,0.188
27.37,76.27,0.188
27.40,76.41,0.188
27.43,76.55,0.188
27.46,76.69,0.189
27.48,76.84,0.189
27.51,76.98,0.189
27.54,77.12,0.190
27.57,77.26,0.190
27.60,77.40,0.190
27.63,77.55,0.191
27.65,77.69,0.191
27.68,77.83,0.191
27.71,77.97,0.191
27.74,78.11,0.192
27.77,78.25,0.192
27.79,78.40,0.192
27.82,78.54,0.192
27.85,78.68,0.193
27.88,78.82,0.193
27.91,78.96,0.193
27.94,79.10,0.194
27.97,79.25,0.194
27.99,79.39,0.194
28.02,79.53,0.194
28.05,79.67,0.195
28.08,79.81,0.195
28.11,79.95,0.195
28.13,80.09,0.196
28.16,80.24,0.196
28.19,80.38,0.196
28.22,80.52,0.196
28.25,80.66,0.197
28.28,80.80,0.197
28.31,80.94,0.197
28.33,81.08,0.197
28.36,81.23,0.198
28.39,81.37,0.198
28.42,81.51,0.198
28.45,81.65,0.199
28.48,81.79,0.199
28.50,81.93,0.199
28.53,82.08,0.199
28.56,82.22,0.200
28.59,82.36,0.200
28.62,82.50,0.200
28.64,82.64,0.201
28.67,82.79,0.201
28.70,82.93,0.201
28.73,83.07,0.202
28.76,83.21,0.202
28.79,83.35,0.202
28.82,83.49,0.203
28.84,83.64,0.203
28.87,83.78,0.203
28.90,83.92,0.204
28.93,84.06,0.204
28.96,84.20,0.204
28.98,84.34,0.205
29.01,84.48,0.205
29.04,84.63,0.205
29.07,84.77,0.206
29.10,84.91,0.206
29.13,85.05,0.206
29.16,85.19,0.207
29.18,85.33,0.207
29.21,85.47,0.207
29.24,85.62,0.208
29.27,85.76,0.208
29.30,85.90,0.209
29.33,86.04,0.209
29.35,86.18,0.209
29.38,86.32,0.210
29.41,86.47,0.210
29.44,86.61,0.211
29.47,86.75,0.211
29.49,86.89,0.211
29.52,87.03,0.212
29.55,87.17,0.212
29.58,87.32,0.212
29.61,87.46,0.213
29.64,87.60,0.213
29.67,87.74,0.214
29.69,87.88,0.214
29.72,88.02,0.215
29.75,88.17,0.215
29.78,88.31,0.215
29.81,88.45,0.216
29.83,88.59,0.216
29.86,88.73,0.216
29.89,88.87,0.217
29.92,89.01,0.217
29.95,89.15,0.218
29.98,89.30,0.218
30.01,89.44,0.218
30.03,89.58,0.219
30.06,89.72,0.219
30.09,89.86,0.220
30.12,90.01,0.220
30.15,90.15,0.220
30.18,90.29,0.221
30.20,90.43,0.221
30.23,90.57,0.222
30.26,90.71,0.222
30.29,90.85,0.223
30.32,91.00,0.223
30.34,91.14,0.224
30.37,91.28,0.224
30.40,91.42,0.224
30.43,91.56,0.225
30.46,91.70,0.225
30.49,91.85,0.226
30.52,91.99,0.226
30.54,92.13,0.227
30.57,92.27,0.227
30.60,92.41,0.228
30.63,92.55,0.228
30.66,92.69,0.229
30.68,92.84,0.229
30.71,92.98,0.230
30.74,93.12,0.230
30.77,93.26,0.231
30.80,93.40,0.231
30.83,93.54,0.232
30.86,93.68,0.232
30.88,93.83,0.233
30.91,93.97,0.233
30.94,94.11,0.234
30.97,94.25,0.234
31.00,94.39,0.235
31.03,94.53,0.235
31.05,94.68,0.236
31.08,94.82,0.236
31.11,94.96,0.237
31.14,95.10,0.237
31.17,95.24,0.238
31.19,95.38,0.238
31.22,95.52,0.239
31.25,95.67,0.239
31.28,95.81,0.240
31.31,95.95,0.240
31.34,96.09,0.241
31.37,96.23,0.242
31.39,96.37,0.242
31.42,96.52,0.243
31.45,96.66,0.244
31.48,96.80,0.244
31.51,96.94,0.245
31.53,97.08,0.245
31.56,97.22,0.246
31.59,97.37,0.247
31.62,97.51,0.247
31.65,97.65,0.248
31.68,97.79,0.250
31.71,97.93,0.250
31.73,98.07,0.251
31.76,98.21,0.251
31.79,98.36,0.252
31.82,98.50,0.252
31.85,98.64,0.253
31.88,98.78,0.254
31.90,98.92,0.254
31.93,99.06,0.255
31.96,99.20,0.255
31.99,99.34,0.256
32.02,99.49,0.257
32.04,99.63,0.257
32.07,99.77,0.258
32.10,99.91,0.259
32.13,100.05,0.259
32.16,100.19,0.260
32.19,100.33,0.260
32.22,100.48,0.261
32.24,100.62,0.262
32.27,100.76,0.263
32.30,100.90,0.264
32.33,101.04,0.265
32.36,101.18,0.266
32.38,101.32,0.266
32.41,101.47,0.267
32.44,101.61,0.268
32.47,101.75,0.269
32.50,101.89,0.269
32.53,102.03,0.270
32.56,102.17,0.271
32.58,102.31,0.272
32.61,102.46,0.272
32.64,102.60,0.273
32.67,102.74,0.274
32.70,102.88,0.275
32.73,103.02,0.276
32.75,103.16,0.277
32.78,103.30,0.277
32.81,103.44,0.278
32.84,103.59,0.279
32.87,103.73,0.280
32.89,103.87,0.281
32.92,104.01,0.281
32.95,104.15,0.282
32.98,104.29,0.283
33.01,104.43,0.285
33.04,104.57,0.286
33.07,104.72,0.287
33.09,104.86,0.287
33.12,105.00,0.288
33.15,105.14,0.289
33.18,105.28,0.290
33.21,105.42,0.291
33.23,105.57,0.292
33.26,105.71,0.293
33.29,105.85,0.293
33.32,105.99,0.294
33.35,106.13,0.295
33.38,106.27,0.296
33.41,106.41,0.297
33.43,106.55,0.298
33.46,106.69,0.299
33.49,106.84,0.299
33.52,106.98,0.301
33.55,107.12,0.302
33.58,107.26,0.302
33.60,107.40,0.303
33.63,107.54,0.304
33.66,107.68,0.305
33.69,107.83,0.307
33.72,107.97,0.308
33.74,108.11,0.309
33.77,108.25,0.310
33.80,108.39,0.311
33.83,108.53,0.312
33.86,108.67,0.313
33.89,108.81,0.314
33.92,108.95,0.316
33.94,109.10,0.317
33.97,109.24,0.319
34.00,109.38,0.320
34.03,109.52,0.321
34.06,109.66,0.322
34.08,109.80,0.324
34.11,109.94,0.325
34.14,110.09,0.326
34.17,110.23,0.328
34.20,110.37,0.329
34.23,110.51,0.331
34.26,110.65,0.332
34.28,110.79,0.333
34.31,110.93,0.334
34.34,111.07,0.335
34.37,111.21,0.336
34.40,111.35,0.338
34.43,111.50,0.339
34.45,111.64,0.341
34.48,111.78,0.342
34.51,111.92,0.344
34.54,112.06,0.345
34.57,112.20,0.346
34.59,112.34,0.347
34.62,112.48,0.348
34.65,112.63,0.350
34.68,112.77,0.351
34.71,112.91,0.353
34.74,113.05,0.354
34.76,113.19,0.355
34.79,113.33,0.357
34.82,113.47,0.359
34.85,113.61,0.360
34.88,113.75,0.362
34.91,113.90,0.363
34.94,114.04,0.365
34.96,114.18,0.366
34.99,114.32,0.368
35.02,114.46,0.369
35.05,114.60,0.370
35.08,114.74,0.371
35.11,114.88,0.372
35.13,115.02,0.373
35.16,115.17,0.374
35.19,115.31,0.375
35.22,115.45,0.377
35.25,115.59,0.378
35.28,115.73,0.379
35.30,115.87,0.381
35.33,116.01,0.382
35.36,116.15,0.383
35.39,116.30,0.384
35.42,116.43,0.386
35.44,116.58,0.387
35.47,116.72,0.389
35.50,116.86,0.391
35.53,117.00,0.393
35.56,117.14,0.395
35.59,117.28,0.396
35.61,117.43,0.398
35.64,117.57,0.399
35.67,117.71,0.400
35.70,117.85,0.402
35.73,117.99,0.403
35.76,118.13,0.404
35.79,118.27,0.406
35.81,118.41,0.408
35.84,118.55,0.410
35.87,118.69,0.411
35.90,118.83,0.413
35.93,118.98,0.414
35.96,119.12,0.415
35.98,119.26,0.416
36.01,119.40,0.417
36.04,119.54,0.419
36.07,119.68,0.420
36.10,119.82,0.421
36.13,119.96,0.422
36.15,120.10,0.423
36.18,120.24,0.424
36.21,120.39,0.425
36.24,120.53,0.426
36.27,120.67,0.427
36.29,120.81,0.427
36.32,120.95,0.428
36.35,121.09,0.428
36.38,121.23,0.429
36.41,121.38,0.430
36.44,121.52,0.431
36.46,121.66,0.433
36.49,121.80,0.436
36.52,121.94,0.439
36.55,122.08,0.444
36.58,122.22,0.449
36.61,122.36,0.456
36.64,122.50,0.468
36.66,122.63,0.488
36.69,122.77,0.509
36.72,122.90,0.525
36.75,123.04,0.529
36.78,123.18,0.518
36.81,123.32,0.499
36.83,123.47,0.481
36.86,123.62,0.468
36.89,123.77,0.456
36.92,123.91,0.447
36.95,124.06,0.438
36.98,124.20,0.432
37.00,124.35,0.425
37.03,124.50,0.418
37.06,124.64,0.413
37.09,124.79,0.408
37.12,124.93,0.403
37.14,125.07,0.400
37.17,125.22,0.396
37.20,125.36,0.393
37.23,125.50,0.390
37.26,125.65,0.388
37.29,125.79,0.386
37.31,125.93,0.384
37.34,126.08,0.379
37.37,126.22,0.376
37.40,126.37,0.372
37.43,126.51,0.367
37.46,126.65,0.361
37.49,126.80,0.355
37.51,126.94,0.345
37.54,127.09,0.337
37.57,127.23,0.327
37.60,127.38,0.314
37.63,127.53,0.299
37.66,127.67,0.284
37.68,127.82,0.266
37.71,127.97,0.249
37.74,128.12,0.233
37.77,128.27,0.219
37.80,128.42,0.210
37.83,128.56,0.203
37.85,128.71,0.197
37.88,128.85,0.192
37.91,129.00,0.188
37.94,129.14,0.184
37.97,129.29,0.182
37.99,129.43,0.180
38.02,129.57,0.178
38.05,129.72,0.178
38.08,129.86,0.177
38.11,130.00,0.177
38.14,130.14,0.176
38.16,130.28,0.176
38.19,130.43,0.176
38.22,130.57,0.175
38.25,130.71,0.175
38.28,130.85,0.175
38.31,130.99,0.175
38.34,131.14,0.175
38.36,131.28,0.174
38.39,131.42,0.174
38.42,131.56,0.174
38.45,131.70,0.174
38.48,131.84,0.174
38.51,131.99,0.174
38.53,132.13,0.173
38.56,132.27,0.173
38.59,132.41,0.173
38.62,132.55,0.173
38.65,132.70,0.173
38.68,132.84,0.173
38.70,132.98,0.173
38.73,133.12,0.173
38.76,133.26,0.173
38.79,133.41,0.173
38.82,133.55,0.173
38.84,133.69,0.173
38.87,133.83,0.173
38.90,133.97,0.173
38.93,134.11,0.173
38.96,134.26,0.173
38.99,134.40,0.173
39.01,134.54,0.173
39.04,134.68,0.173
39.07,134.82,0.173
39.10,134.96,0.173
39.13,135.11,0.173
39.16,135.25,0.173
39.19,135.39,0.173
39.21,135.53,0.173
39.24,135.67,0.173
39.27,135.81,0.173
39.30,135.95,0.173
39.33,136.10,0.173
39.36,136.24,0.173
39.38,136.38,0.173
39.41,136.52,0.173
39.44,136.66,0.173
39.47,136.80,0.173
39.50,136.95,0.173
39.53,137.09,0.174
39.55,137.23,0.174
39.58,137.37,0.174
39.61,137.51,0.174
39.64,137.65,0.174
39.67,137.80,0.174
39.69,137.94,0.174
39.72,138.08,0.174
39.75,138.22,0.174
39.78,138.36,0.174
39.81,138.50,0.174
39.84,138.65,0.174
39.86,138.79,0.174
39.89,138.93,0.174
39.92,139.07,0.174
39.95,139.22,0.174
39.98,139.36,0.174
40.01,139.50,0.175
40.04,139.64,0.175
40.06,139.78,0.175
40.09,139.92,0.175
40.12,140.07,0.175
40.15,140.21,0.175
40.18,140.35,0.175
40.21,140.49,0.175
40.23,140.63,0.175
40.26,140.77,0.175
40.29,140.91,0.175
40.32,141.06,0.175
40.35,141.20,0.175
40.38,141.34,0.175
40.40,141.48,0.175
40.43,141.62,0.175
40.46,141.76,0.175
40.49,141.91,0.175
40.52,142.05,0.175
40.54,142.19,0.175
40.57,142.33,0.175
40.60,142.47,0.175
40.63,142.62,0.176
40.66,142.76,0.176
40.69,142.90,0.176
40.71,143.04,0.176
40.74,143.18,0.176
40.77,143.32,0.176
40.80,143.47,0.176
40.83,143.61,0.176
40.86,143.75,0.176
40.89,143.89,0.176
40.91,144.03,0.176
40.94,144.17,0.176
40.97,144.32,0.176
41.00,144.46,0.176
41.03,144.60,0.176
41.06,144.74,0.176
41.08,144.88,0.176
41.11,145.03,0.176
41.14,145.17,0.176
41.17,145.31,0.176
41.20,145.45,0.176
41.23,145.59,0.176
41.25,145.73,0.176
41.28,145.87,0.176
41.31,146.02,0.176
41.34,146.16,0.177
41.37,146.30,0.177
41.39,146.44,0.177
41.42,146.58,0.177
41.45,146.73,0.177
41.48,146.87,0.177
41.51,147.01,0.177
41.54,147.15,0.177
41.56,147.29,0.177
41.59,147.44,0.177
41.62,147.58,0.177
41.65,147.72,0.177
41.68,147.86,0.177
41.71,148.00,0.178
41.74,148.14,0.178
41.76,148.28,0.178
41.79,148.43,0.178
41.82,148.57,0.178
41.85,148.71,0.178
41.88,148.85,0.178
41.91,148.99,0.178
41.93,149.13,
41.96,149.28,
41.98,,

[step]
Ramp 5.00 °C/min to -60.00 °C
Time,Temperature,Heat Flow (Normalized)
min,°C,W/g
42.99,150.13,-0.037
43.01,150.13,-0.037
43.04,150.12,-0.037
43.07,150.09,-0.037
43.10,150.05,-0.055
43.13,149.98,-0.085
43.16,149.89,-0.119
43.18,149.79,-0.148
43.21,149.68,-0.170
43.24,149.56,-0.188
43.27,149.44,-0.201
43.30,149.31,-0.212
43.33,149.19,-0.219
43.35,149.05,-0.226
43.38,148.92,-0.229
43.41,148.79,-0.234
43.44,148.65,-0.236
43.47,148.51,-0.239
43.49,148.38,-0.240
43.52,148.24,-0.241
43.55,148.10,-0.242
43.58,147.96,-0.243
43.61,147.82,-0.244
43.64,147.68,-0.244
43.66,147.54,-0.245
43.69,147.40,-0.245
43.72,147.26,-0.245
43.75,147.12,-0.246
43.78,146.98,-0.246
43.81,146.84,-0.246
43.84,146.70,-0.246
43.86,146.56,-0.247
43.89,146.42,-0.247
43.92,146.28,-0.247
43.95,146.14,-0.247
43.98,146.00,-0.247
44.01,145.86,-0.247
44.03,145.72,-0.247
44.06,145.57,-0.247
44.09,145.43,-0.247
44.12,145.29,-0.247
44.15,145.15,-0.247
44.18,145.01,-0.247
44.20,144.87,-0.247
44.23,144.73,-0.247
44.26,144.59,-0.247
44.29,144.44,-0.247
44.32,144.30,-0.247
44.34,144.16,-0.247
44.37,144.02,-0.247
44.40,143.88,-0.247
44.43,143.74,-0.247
44.46,143.60,-0.247
44.49,143.46,-0.247
44.51,143.31,-0.247
44.54,143.17,-0.246
44.57,143.03,-0.246
44.60,142.89,-0.246
44.63,142.75,-0.246
44.66,142.61,-0.246
44.69,142.47,-0.246
44.71,142.32,-0.246
44.74,142.18,-0.246
44.77,142.04,-0.245
44.80,141.90,-0.245
44.83,141.76,-0.245
44.86,141.62,-0.245
44.88,141.47,-0.245
44.91,141.33,-0.245
44.94,141.19,-0.245
44.97,141.05,-0.245
45.00,140.91,-0.244
45.03,140.77,-0.244
45.05,140.63,-0.244
45.08,140.48,-0.244
45.11,140.34,-0.244
45.14,140.20,-0.244
45.17,140.06,-0.244
45.19,139.92,-0.244
45.22,139.78,-0.243
45.25,139.63,-0.243
45.28,139.49,-0.243
45.31,139.35,-0.243
45.34,139.21,-0.243
45.36,139.07,-0.243
45.39,138.93,-0.243
45.42,138.79,-0.243
45.45,138.64,-0.242
45.48,138.50,-0.243
45.51,138.35,-0.243
45.54,138.21,-0.243
45.56,138.07,-0.243
45.59,137.93,-0.242
45.62,137.79,-0.242
45.65,137.65,-0.242
45.68,137.51,-0.242
45.71,137.37,-0.241
45.73,137.22,-0.241
45.76,137.08,-0.241
45.79,136.94,-0.241
45.82,136.80,-0.241
45.85,136.66,-0.240
45.88,136.52,-0.240
45.90,136.38,-0.240
45.93,136.23,-0.240
45.96,136.09,-0.240
45.99,135.95,-0.240
46.02,135.81,-0.239
46.04,135.67,-0.239
46.07,135.53,-0.239
46.10,135.39,-0.239
46.13,135.24,-0.239
46.16,135.10,-0.239
46.19,134.96,-0.239
46.21,134.82,-0.239
46.24,134.68,-0.238
46.27,134.54,-0.238
46.30,134.40,-0.238
46.33,134.25,-0.238
46.36,134.11,-0.238
46.39,133.97,-0.238
46.41,133.83,-0.238
46.44,133.69,-0.238
46.47,133.55,-0.238
46.50,133.40,-0.238
46.53,133.26,-0.238
46.56,133.12,-0.238
46.58,132.98,-0.237
46.61,132.84,-0.237
46.64,132.70,-0.237
46.67,132.56,-0.237
46.70,132.42,-0.237
46.73,132.28,-0.237
46.75,132.13,-0.237
46.78,131.99,-0.237
46.81,131.85,-0.237
46.84,131.71,-0.237
46.87,131.57,-0.237
46.89,131.42,-0.237
46.92,131.28,-0.237
46.95,131.14,-0.237
46.98,131.00,-0.237
47.01,130.86,-0.237
47.04,130.72,-0.236
47.06,130.57,-0.236
47.09,130.43,-0.236
47.12,130.29,-0.236
47.15,130.15,-0.236
47.18,130.01,-0.236
47.21,129.87,-0.236
47.24,129.72,-0.236
47.26,129.58,-0.236
47.29,129.44,-0.236
47.32,129.30,-0.236
47.35,129.16,-0.236
47.38,129.01,-0.236
47.41,128.87,-0.236
47.43,128.73,-0.236
47.46,128.59,-0.236
47.49,128.45,-0.235
47.52,128.31,-0.235
47.55,128.17,-0.235
47.58,128.03,-0.235
47.60,127.88,-0.235
47.63,127.74,-0.235
47.66,127.60,-0.235
47.69,127.46,-0.235
47.72,127.32,-0.235
47.74,127.17,-0.235
47.77,127.03,-0.234
47.80,126.89,-0.234
47.83,126.75,-0.234
47.86,126.61,-0.234
47.89,126.46,-0.234
47.91,126.32,-0.234
47.94,126.18,-0.234
47.97,126.04,-0.234
48.00,125.90,-0.234
48.03,125.76,-0.234
48.06,125.62,-0.234
48.09,125.47,-0.233
48.11,125.33,-0.233
48.14,125.19,-0.233
48.17,125.05,-0.233
48.20,124.91,-0.233
48.23,124.77,-0.233
48.26,124.63,-0.233
48.28,124.48,-0.233
48.31,124.34,-0.233
48.34,124.20,-0.233
48.37,124.06,-0.233
48.40,123.92,-0.233
48.43,123.78,-0.232
48.45,123.63,-0.232
48.48,123.49,-0.232
48.51,123.35,-0.232
48.54,123.21,-0.232
48.57,123.07,-0.232
48.59,122.93,-0.232
48.62,122.79,-0.232
48.65,122.64,-0.232
48.68,122.50,-0.232
48.71,122.36,-0.232
48.74,122.22,-0.232
48.76,122.08,-0.232
48.79,121.93,-0.232
48.82,121.79,-0.232
48.85,121.65,-0.232
48.88,121.51,-0.232
48.91,121.37,-0.232
48.94,121.23,-0.231
48.96,121.09,-0.231
48.99,120.94,-0.231
49.02,120.80,-0.231
49.05,120.66,-0.231
49.08,120.52,-0.231
49.11,120.38,-0.231
49.13,120.24,-0.231
49.16,120.10,-0.231
49.19,119.95,-0.231
49.22,119.81,-0.231
49.25,119.67,-0.231
49.28,119.53,-0.230
49.30,119.39,-0.230
49.33,119.25,-0.230
49.36,119.10,-0.230
49.39,118.96,-0.230
49.42,118.82,-0.230
49.44,118.68,-0.230
49.47,118.54,-0.230
49.50,118.40,-0.230
49.53,118.26,-0.230
49.56,118.11,-0.230
49.59,117.97,-0.230
49.61,117.83,-0.230
49.64,117.69,-0.230
49.67,117.55,-0.230
49.70,117.40,-0.230
49.73,117.26,-0.230
49.76,117.12,-0.230
49.79,116.98,-0.230
49.81,116.84,-0.230
49.84,116.70,-0.230
49.87,116.55,-0.230
49.90,116.41,-0.230
49.93,116.27,-0.230
49.96,116.13,-0.230
49.98,115.99,-0.230
50.01,115.84,-0.230
50.04,115.70,-0.230
50.07,115.56,-0.229
50.10,115.42,-0.229
50.13,115.28,-0.229
50.15,115.14,-0.229
50.18,115.00,-0.229
50.21,114.85,-0.229
50.24,114.71,-0.229
50.27,114.57,-0.229
50.29,114.43,-0.229
50.32,114.29,-0.228
50.35,114.15,-0.228
50.38,114.01,-0.228
50.41,113.86,-0.228
50.44,113.72,-0.228
50.46,113.58,-0.228
50.49,113.44,-0.228
50.52,113.30,-0.228
50.55,113.16,-0.228
50.58,113.02,-0.228
50.61,112.87,-0.228
50.64,112.73,-0.228
50.66,112.59,-0.228
50.69,112.45,-0.228
50.72,112.31,-0.228
50.75,112.17,-0.228
50.78,112.02,-0.228
50.81,111.88,-0.228
50.83,111.74,-0.228
50.86,111.60,-0.228
50.89,111.46,-0.228
50.92,111.32,-0.227
50.95,111.17,-0.227
50.98,111.03,-0.227
51.00,110.89,-0.227
51.03,110.75,-0.227
51.06,110.61,-0.227
51.09,110.47,-0.227
51.12,110.32,-0.227
51.14,110.18,-0.227
51.17,110.04,-0.227
51.20,109.90,-0.227
51.23,109.76,-0.227
51.26,109.62,-0.227
51.29,109.48,-0.226
51.31,109.33,-0.226
51.34,109.19,-0.226
51.37,109.05,-0.226
51.40,108.91,-0.226
51.43,108.77,-0.226
51.46,108.63,-0.226
51.49,108.48,-0.226
51.51,108.34,-0.226
51.54,108.20,-0.226
51.57,108.06,-0.226
51.60,107.92,-0.226
51.63,107.78,-0.250
51.66,107.65,-0.371
51.68,107.54,-0.493
51.71,107.42,-0.462
51.74,107.29,-0.464
51.77,107.16,-0.456
51.80,107.03,-0.509
51.83,106.90,-0.536
51.85,106.79,-0.804
51.88,106.75,-1.422
51.91,106.72,-1.472
51.94,106.65,-1.379
51.97,106.54,-1.363
51.99,106.43,-1.316
52.02,106.29,-1.254
52.05,106.14,-1.172
52.08,105.98,-1.092
52.11,105.82,-1.031
52.14,105.65,-0.983
52.16,105.49,-0.946
52.19,105.33,-0.917
52.22,105.17,-0.889
52.25,105.01,-0.844
52.28,104.85,-0.804
52.31,104.69,-0.770
52.34,104.53,-0.742
52.36,104.37,-0.716
52.39,104.21,-0.694
52.42,104.06,-0.674
[...]
176.16,-39.91,0.097
176.17,-39.84,0.097
176.18,-39.77,0.097
176.20,-39.70,0.097
176.21,-39.64,0.097
176.23,-39.57,0.097
176.24,-39.51,0.097
176.25,-39.44,0.097
176.27,-39.37,0.097
176.28,-39.31,0.097
176.29,-39.24,0.098
176.30,-39.17,0.098
176.32,-39.11,0.098
176.33,-39.04,0.098
176.35,-38.97,0.098
176.36,-38.90,0.098
176.37,-38.84,0.098
176.38,-38.77,0.098
176.40,-38.71,0.098
176.41,-38.64,0.098
176.43,-38.57,0.098
176.44,-38.50,0.098
176.45,-38.44,0.098
176.47,-38.37,0.098
176.48,-38.30,0.098
176.49,-38.24,0.098
176.50,-38.17,0.098
176.52,-38.10,0.098
176.53,-38.04,0.098
176.55,-37.97,0.098
176.56,-37.91,0.098
176.57,-37.84,0.098
176.58,-37.77,0.098
176.60,-37.71,0.098
176.61,-37.64,0.098
176.63,-37.57,0.098
176.64,-37.51,0.099
176.65,-37.44,0.099
176.67,-37.37,0.099
176.68,-37.30,0.099
176.69,-37.24,0.099
176.70,-37.17,0.099
176.72,-37.10,0.099
176.73,-37.04,0.099
176.75,-36.97,0.099
176.76,-36.90,0.099
176.77,-36.84,0.099
176.78,-36.77,0.099
176.80,-36.70,0.099
176.81,-36.64,0.099
176.83,-36.57,0.099
176.84,-36.50,0.099
176.85,-36.44,0.099
176.87,-36.37,0.099
176.88,-36.30,0.099
176.89,-36.24,0.099
176.90,-36.17,0.099
176.92,-36.10,0.099
176.93,-36.04,0.099
176.95,-35.97,0.099
176.96,-35.90,0.100
176.97,-35.84,0.100
176.98,-35.77,0.100
177.00,-35.70,0.100
177.01,-35.63,0.100
177.03,-35.57,0.100
177.04,-35.50,0.100
177.05,-35.43,0.100
177.07,-35.37,0.100
177.08,-35.30,0.100
177.09,-35.23,0.100
177.10,-35.17,0.100
177.12,-35.10,0.100
177.13,-35.03,0.100
177.15,-34.97,0.100
177.16,-34.90,0.100
177.17,-34.83,0.100
177.18,-34.77,0.100
177.20,-34.70,0.101
177.21,-34.63,0.101
177.23,-34.57,0.101
177.24,-34.50,0.101
177.25,-34.43,0.101
177.27,-34.37,0.101
177.28,-34.30,0.101
177.29,-34.23,0.101
177.30,-34.17,0.101
177.32,-34.10,0.101
177.33,-34.03,0.101
177.35,-33.97,0.101
177.36,-33.90,0.101
177.37,-33.83,0.101
177.38,-33.77,0.101
177.40,-33.70,0.101
177.41,-33.63,0.102
177.43,-33.57,0.102
177.44,-33.50,0.102
177.45,-33.43,0.102
177.47,-33.37,0.102
177.48,-33.30,0.102
177.49,-33.23,0.102
177.50,-33.17,0.102
177.52,-33.10,0.102
177.53,-33.03,0.102
177.55,-32.97,0.102
177.56,-32.90,0.102
177.57,-32.83,0.102
177.58,-32.77,0.102
177.60,-32.70,0.103
177.61,-32.63,0.103
177.63,-32.57,0.103
177.64,-32.50,0.103
177.65,-32.43,0.103
177.67,-32.37,0.103
177.68,-32.30,0.103
177.69,-32.23,0.103
177.70,-32.17,0.103
177.72,-32.10,0.103
177.73,-32.03,0.103
177.75,-31.97,0.103
177.76,-31.90,0.104
177.77,-31.83,0.104
177.78,-31.77,0.104
177.80,-31.70,0.104
177.81,-31.63,0.104
177.83,-31.57,0.104
177.84,-31.50,0.104
177.85,-31.43,0.104
177.87,-31.37,0.104
177.88,-31.30,0.104
177.89,-31.23,0.104
177.90,-31.17,0.104
177.92,-31.10,0.105
177.93,-31.03,0.105
177.95,-30.97,0.105
177.96,-30.90,0.105
177.97,-30.83,0.105
177.98,-30.76,0.105
178.00,-30.70,0.105
178.01,-30.63,0.105
178.03,-30.57,0.105
178.04,-30.50,0.106
178.05,-30.43,0.106
178.07,-30.37,0.106
178.08,-30.30,0.106
178.09,-30.23,0.106
178.10,-30.16,0.106
178.12,-30.10,0.106
178.13,-30.03,0.106
178.15,-29.96,0.106
178.16,-29.90,0.106
178.17,-29.83,0.107
178.18,-29.76,0.107
178.20,-29.70,0.107
178.21,-29.63,0.107
178.23,-29.57,0.107
178.24,-29.50,0.107
178.25,-29.43,0.107
178.27,-29.37,0.107
178.28,-29.30,0.107
178.29,-29.23,0.108
178.30,-29.17,0.108
178.32,-29.10,0.108
178.33,-29.03,0.108
178.35,-28.97,0.108
178.36,-28.90,0.108
178.37,-28.83,0.108
178.38,-28.77,0.108
178.40,-28.70,0.109
178.41,-28.63,0.109
178.43,-28.56,0.109
178.44,-28.50,0.109
178.45,-28.43,0.109
178.47,-28.36,0.109
178.48,-28.30,0.109
178.49,-28.23,0.110
178.50,-28.16,0.110
178.52,-28.10,0.110
178.53,-28.03,0.110
178.55,-27.96,0.110
178.56,-27.90,0.110
178.57,-27.83,0.110
178.58,-27.76,0.110
178.60,-27.70,0.111
178.61,-27.63,0.111
178.63,-27.56,0.111
178.64,-27.50,0.111
178.65,-27.43,0.111
178.67,-27.36,0.111
178.68,-27.30,0.111
178.69,-27.23,0.112
178.70,-27.16,0.112
178.72,-27.10,0.112
178.73,-27.03,0.112
178.75,-26.97,0.112
178.76,-26.90,0.112
178.77,-26.83,0.112
178.78,-26.76,0.112
178.80,-26.70,0.113
178.81,-26.63,0.113
178.83,-26.57,0.113
178.84,-26.50,0.113
178.85,-26.43,0.113
178.87,-26.36,0.113
178.88,-26.30,0.113
178.89,-26.23,0.114
178.90,-26.17,0.114
178.92,-26.10,0.114
178.93,-26.03,0.114
178.95,-25.97,0.114
178.96,-25.90,0.114
178.97,-25.83,0.114
178.98,-25.77,0.115
179.00,-25.70,0.115
179.01,-25.63,0.115
179.03,-25.57,0.115
179.04,-25.50,0.115
179.05,-25.43,0.115
179.07,-25.36,0.115
179.08,-25.30,0.115
179.09,-25.23,0.116
179.10,-25.17,0.116
179.12,-25.10,0.116
179.13,-25.03,0.116
179.15,-24.97,0.116
179.16,-24.90,0.116
179.17,-24.83,0.116
179.18,-24.77,0.117
179.20,-24.70,0.117
179.21,-24.63,0.117
179.23,-24.56,0.117
179.24,-24.50,0.117
179.25,-24.43,0.117
179.27,-24.36,0.117
179.28,-24.30,0.117
179.29,-24.23,0.118
179.30,-24.17,0.118
179.32,-24.10,0.118
179.33,-24.03,0.118
179.35,-23.97,0.118
179.36,-23.90,0.118
179.37,-23.83,0.118
179.38,-23.77,0.118
179.40,-23.70,0.119
179.41,-23.63,0.119
179.43,-23.57,0.119
179.44,-23.50,0.119
179.45,-23.43,0.119
179.47,-23.36,0.119
179.48,-23.30,0.119
179.49,-23.23,0.119
179.50,-23.17,0.119
179.52,-23.10,0.120
179.53,-23.03,0.120
179.55,-22.97,0.120
179.56,-22.90,0.120
179.57,-22.83,0.120
179.58,-22.76,0.120
179.60,-22.70,0.120
179.61,-22.63,0.120
179.63,-22.56,0.120
179.64,-22.50,0.120
179.65,-22.43,0.120
179.67,-22.36,0.121
179.68,-22.30,0.121
179.69,-22.23,0.121
179.70,-22.17,0.121
179.72,-22.10,0.121
179.73,-22.03,0.121
179.75,-21.97,0.121
179.76,-21.90,0.121
179.77,-21.83,0.121
179.78,-21.76,0.121
179.80,-21.70,0.121
179.81,-21.63,0.121
179.83,-21.57,0.122
179.84,-21.50,0.122
179.85,-21.43,0.122
179.87,-21.36,0.122
179.88,-21.30,0.122
179.89,-21.23,0.122
179.90,-21.16,0.122
179.92,-21.10,0.122
179.93,-21.03,0.122
179.95,-20.96,0.122
179.96,-20.90,0.122
179.97,-20.83,0.122
179.98,-20.76,0.122
180.00,-20.70,0.122
180.01,-20.63,0.122
180.03,-20.56,0.122
180.04,-20.50,0.122
180.05,-20.43,0.122
180.07,-20.36,0.122
180.08,-20.30,0.122
180.09,-20.23,0.122
180.10,-20.16,0.123
180.12,-20.10,0.122
180.13,-20.03,0.123
180.15,-19.96,0.123
180.16,-19.90,0.123
180.17,-19.83,0.123
180.18,-19.76,0.123
180.20,-19.70,0.123
180.21,-19.63,0.123
180.23,-19.56,0.123
180.24,-19.50,0.123
180.25,-19.43,0.123
180.27,-19.36,0.123
180.28,-19.30,0.123
180.29,-19.23,0.123
180.30,-19.16,0.123
180.32,-19.10,0.123
180.33,-19.03,0.123
180.35,-18.96,0.123
180.36,-18.90,0.123
180.37,-18.83,0.123
180.38,-18.76,0.123
180.40,-18.70,0.123
180.41,-18.63,0.123
180.43,-18.56,0.123
180.44,-18.50,0.123
180.45,-18.43,0.123
180.47,-18.36,0.123
180.48,-18.30,0.123
180.49,-18.23,0.123
180.50,-18.16,0.123
180.52,-18.09,0.123
180.53,-18.03,0.123
180.55,-17.96,0.123
180.56,-17.89,0.123
180.57,-17.83,0.123
180.58,-17.76,0.123
180.60,-17.69,0.123
180.61,-17.63,0.123
180.63,-17.56,0.123
180.64,-17.49,0.123
180.65,-17.43,0.123
180.67,-17.36,0.123
180.68,-17.29,0.123
180.69,-17.23,0.123
180.70,-17.16,0.123
180.72,-17.09,0.123
180.73,-17.03,0.123
180.75,-16.96,0.123
180.76,-16.89,0.123
180.77,-16.83,0.123
180.78,-16.76,0.123
180.80,-16.69,0.123
180.81,-16.63,0.122
180.83,-16.56,0.122
180.84,-16.49,0.122
180.85,-16.43,0.122
180.87,-16.36,0.122
180.88,-16.29,0.122
180.89,-16.22,0.122
180.90,-16.16,0.122
180.92,-16.09,0.122
180.93,-16.03,0.122
180.95,-15.96,0.122
180.96,-15.89,0.122
180.97,-15.82,0.122
180.98,-15.76,0.122
181.00,-15.69,0.122
181.01,-15.63,0.122
181.03,-15.56,0.122
181.04,-15.49,0.122
181.05,-15.42,0.122
181.07,-15.36,0.122
181.08,-15.29,0.122
181.09,-15.22,0.122
181.10,-15.16,0.122
181.12,-15.09,0.122
181.13,-15.02,0.122
181.15,-14.96,0.122
181.16,-14.89,0.122
181.17,-14.82,0.122
181.18,-14.76,0.122
181.20,-14.69,0.122
181.21,-14.63,0.122
181.23,-14.56,0.122
181.24,-14.49,0.122
181.25,-14.42,0.122
181.27,-14.36,0.122
181.28,-14.29,0.122
181.29,-14.22,0.122
181.30,-14.16,0.122
181.32,-14.09,0.122
181.33,-14.02,0.122
181.35,-13.96,0.122
181.36,-13.89,0.122
181.37,-13.82,0.122
181.38,-13.76,0.122
181.40,-13.69,0.122
181.41,-13.62,0.122
181.43,-13.55,0.122
181.44,-13.49,0.122
181.45,-13.42,0.122
181.47,-13.36,0.122
181.48,-13.29,0.122
181.49,-13.22,0.122
181.50,-13.16,0.122
181.52,-13.09,0.122
181.53,-13.02,0.122
181.55,-12.96,0.122
181.56,-12.89,0.122
181.57,-12.82,0.122
181.58,-12.75,0.122
181.60,-12.69,0.122
181.61,-12.62,0.122
181.63,-12.55,0.122
181.64,-12.49,0.122
181.65,-12.42,0.122
181.67,-12.36,0.122
181.68,-12.29,0.122
181.69,-12.22,0.122
181.70,-12.15,0.122
181.72,-12.09,0.122
181.73,-12.02,0.122
181.75,-11.95,0.122
181.76,-11.89,0.122
181.77,-11.82,0.122
181.78,-11.75,0.122
181.80,-11.69,0.122
181.81,-11.62,0.122
181.83,-11.55,0.122
181.84,-11.49,0.122
181.85,-11.42,0.122
181.87,-11.35,0.122
181.88,-11.29,0.123
181.89,-11.22,0.123
181.90,-11.15,0.123
181.92,-11.09,0.123
181.93,-11.02,0.123
181.95,-10.95,0.123
181.96,-10.89,0.123
181.97,-10.82,0.123
181.98,-10.75,0.123
182.00,-10.69,0.123
182.01,-10.62,0.123
182.03,-10.55,0.123
182.04,-10.49,0.123
182.05,-10.42,0.123
182.07,-10.35,0.123
182.08,-10.29,0.123
182.09,-10.22,0.123
182.10,-10.15,0.123
182.12,-10.09,0.123
182.13,-10.02,0.123
182.15,-9.95,0.123
182.16,-9.89,0.123
182.17,-9.82,0.123
182.18,-9.75,0.123
182.20,-9.69,0.123
182.21,-9.62,0.123
182.23,-9.55,0.123
182.24,-9.49,0.123
182.25,-9.42,0.123
182.27,-9.35,0.123
182.28,-9.29,0.123
182.29,-9.22,0.123
182.30,-9.15,0.123
182.32,-9.09,0.123
182.33,-9.02,0.123
182.35,-8.95,0.123
182.36,-8.88,0.123
182.37,-8.82,0.123
182.38,-8.75,0.123
182.40,-8.68,0.123
182.41,-8.62,0.123
182.43,-8.55,0.123
182.44,-8.49,0.123
182.45,-8.42,0.123
182.47,-8.35,0.123
182.48,-8.28,0.123
182.49,-8.22,0.123
182.50,-8.15,0.123
182.52,-8.09,0.123
182.53,-8.02,0.123
182.55,-7.95,0.123
182.56,-7.89,0.123
182.57,-7.82,0.123
182.58,-7.75,0.123
182.60,-7.69,0.123
182.61,-7.62,0.123
182.63,-7.55,0.123
182.64,-7.48,0.123
182.65,-7.42,0.123
182.67,-7.35,0.123
182.68,-7.28,0.123
182.69,-7.22,0.123
182.70,-7.15,0.123
182.72,-7.08,0.123
182.73,-7.02,0.123
182.75,-6.95,0.123
182.76,-6.88,0.123
182.77,-6.82,0.123
182.78,-6.75,0.123
182.80,-6.68,0.124
182.81,-6.62,0.124
182.83,-6.55,0.124
182.84,-6.48,0.124
182.85,-6.42,0.124
182.87,-6.35,0.124
182.88,-6.28,0.124
182.89,-6.22,0.124
182.90,-6.15,0.124
182.92,-6.08,0.124
182.93,-6.02,0.124
182.95,-5.95,0.124
182.96,-5.88,0.124
182.97,-5.82,0.124
182.98,-5.75,0.124
183.00,-5.68,0.124
183.01,-5.62,0.124
183.03,-5.55,0.124
183.04,-5.48,0.124
183.05,-5.42,0.124
183.07,-5.35,0.124
183.08,-5.28,0.124
183.09,-5.22,0.124
183.10,-5.15,0.124
183.12,-5.08,0.124
183.13,-5.02,0.124
183.15,-4.95,0.124
183.16,-4.88,0.124
183.17,-4.81,0.124
183.18,-4.75,0.124
183.20,-4.68,0.124
183.21,-4.61,0.124
183.23,-4.55,0.124
183.24,-4.48,0.124
183.25,-4.42,0.124
183.27,-4.35,0.124
183.28,-4.28,0.124
183.29,-4.21,0.124
183.30,-4.15,0.124
183.32,-4.08,0.124
183.33,-4.01,0.124
183.35,-3.95,0.124
183.36,-3.88,0.124
183.37,-3.81,0.124
183.38,-3.75,0.124
183.40,-3.68,0.124
183.41,-3.61,0.124
183.43,-3.55,0.124
183.44,-3.48,0.124
183.45,-3.41,0.124
183.47,-3.35,0.124
183.48,-3.28,0.124
183.49,-3.21,0.124
183.50,-3.15,0.124
183.52,-3.08,0.124
183.53,-3.01,0.125
183.55,-2.95,0.125
183.56,-2.88,0.125
183.57,-2.81,0.125
183.58,-2.75,0.125
183.60,-2.68,0.125
183.61,-2.61,0.125
183.63,-2.55,0.125
183.64,-2.48,0.125
183.65,-2.41,0.125
183.67,-2.35,0.125
183.68,-2.28,0.125
183.69,-2.21,0.125
183.70,-2.15,0.125
183.72,-2.08,0.125
183.73,-2.01,0.125
183.75,-1.94,0.125
183.76,-1.88,0.125
183.77,-1.81,0.125
183.78,-1.75,0.125
183.80,-1.68,0.125
183.81,-1.61,0.125
183.83,-1.55,0.125
183.84,-1.48,0.125
183.85,-1.41,0.125
183.87,-1.35,0.125
183.88,-1.28,0.125
183.89,-1.21,0.125
183.90,-1.14,0.125
183.92,-1.08,0.125
183.93,-1.01,0.125
183.95,-0.94,0.125
183.96,-0.88,0.125
183.97,-0.81,0.125
183.98,-0.74,0.125
184.00,-0.68,0.125
184.01,-0.61,0.125
184.03,-0.54,0.125
184.04,-0.48,0.125
184.05,-0.41,0.125
184.07,-0.34,0.125
184.08,-0.28,0.125
184.09,-0.21,0.125
184.10,-0.14,0.125
184.12,-0.08,0.125
184.13,-0.01,0.125
184.15,0.06,0.125
184.16,0.12,0.125
184.17,0.19,0.125
184.18,0.26,0.125
184.20,0.32,0.125
184.21,0.39,0.125
184.23,0.46,0.125
184.24,0.52,0.125
184.25,0.59,0.125
184.27,0.66,0.125
184.28,0.72,0.125
184.29,0.79,0.125
184.30,0.86,0.125
184.32,0.92,0.125
184.33,0.99,0.125
184.35,1.06,0.125
184.36,1.12,0.125
184.37,1.19,0.125
184.38,1.26,0.125
184.40,1.32,0.125
184.41,1.39,0.125
184.43,1.46,0.126
184.44,1.52,0.125
184.45,1.59,0.126
184.47,1.66,0.126
184.48,1.72,0.126
184.49,1.79,0.126
184.50,1.86,0.126
184.52,1.92,0.126
184.53,1.99,0.126
184.55,2.06,0.126
184.56,2.12,0.126
184.57,2.19,0.126
184.58,2.26,0.126
184.60,2.32,0.126
184.61,2.39,0.126
184.63,2.46,0.126
184.64,2.53,0.126
184.65,2.59,0.126
184.67,2.66,0.126
184.68,2.73,0.126
184.69,2.79,0.126
184.70,2.86,0.126
184.72,2.92,0.126
184.73,2.99,0.126
184.75,3.06,0.126
184.76,3.13,0.126
184.77,3.19,0.126
184.78,3.26,0.126
184.80,3.33,0.126
184.81,3.39,0.126
184.83,3.46,0.126
184.84,3.53,0.126
184.85,3.59,0.126
184.87,3.66,0.126
184.88,3.73,0.126
184.89,3.79,0.126
184.90,3.86,0.126
184.92,3.93,0.126
184.93,3.99,0.126
184.95,4.06,0.126
184.96,4.13,0.126
184.97,4.19,0.126
184.98,4.26,0.126
185.00,4.33,0.126
185.01,4.39,0.126
185.03,4.46,0.126
185.04,4.53,0.126
185.05,4.59,0.126
185.07,4.66,0.126
185.08,4.73,0.126
185.09,4.79,0.126
185.10,4.86,0.126
185.12,4.93,0.126
185.13,4.99,0.126
185.15,5.06,0.126
185.16,5.13,0.126
185.17,5.19,0.126
185.18,5.26,0.126
185.20,5.33,0.126
185.21,5.39,0.126
185.23,5.46,0.126
185.24,5.53,0.126
185.25,5.59,0.126
185.27,5.66,0.126
185.28,5.73,0.126
185.29,5.79,0.126
185.30,5.86,0.126
185.32,5.93,0.126
185.33,6.00,0.126
185.35,6.06,0.126
185.36,6.13,0.126
185.37,6.19,0.126
185.38,6.26,0.126
185.40,6.33,0.127
185.41,6.39,0.126
185.43,6.46,0.127
185.44,6.53,0.127
185.45,6.59,0.127
185.47,6.66,0.127
185.48,6.73,0.127
185.49,6.80,0.127
185.50,6.86,0.127
185.52,6.93,0.127
185.53,7.00,0.127
185.55,7.06,0.127
185.56,7.13,0.127
185.57,7.20,0.127
185.58,7.26,0.127
185.60,7.33,0.127
185.61,7.40,0.127
185.63,7.46,0.127
185.64,7.53,0.127
185.65,7.60,0.127
185.67,7.66,0.127
185.68,7.73,0.127
185.69,7.80,0.127
185.70,7.86,0.127
185.72,7.93,0.127
185.73,8.00,0.127
185.75,8.06,0.127
185.76,8.13,0.127
185.77,8.20,0.127
185.78,8.26,0.127
185.80,8.33,0.127
185.81,8.40,0.127
185.83,8.46,0.127
185.84,8.53,0.127
185.85,8.60,0.127
185.87,8.66,0.127
185.88,8.73,0.127
185.89,8.80,0.127
185.90,8.86,0.127
185.92,8.93,0.127
185.93,9.00,0.127
185.95,9.06,0.127
185.96,9.13,0.127
185.97,9.20,0.127
185.98,9.26,0.127
186.00,9.33,0.127
186.01,9.40,0.127
186.03,9.47,0.127
186.04,9.53,0.127
186.05,9.60,0.127
186.07,9.66,0.127
186.08,9.73,0.127
186.09,9.80,0.127
186.10,9.86,0.127
186.12,9.93,0.127
186.13,10.00,0.127
186.15,10.06,0.127
186.16,10.13,0.127
186.17,10.20,0.127
186.18,10.27,0.127
186.20,10.33,0.127
186.21,10.40,0.127
186.23,10.47,0.127
186.24,10.53,0.127
186.25,10.60,0.127
186.27,10.67,0.127
186.28,10.73,0.127
186.29,10.80,0.127
186.30,10.87,0.127
186.32,10.93,0.127
186.33,11.00,0.127
186.35,11.07,0.127
186.36,11.13,0.127
186.37,11.20,0.127
186.38,11.27,0.127
186.40,11.33,0.127
186.41,11.40,0.127
186.43,11.47,0.127
186.44,11.53,0.127
186.45,11.60,0.127
186.47,11.67,0.127
186.48,11.73,0.127
186.49,11.80,0.127
186.50,11.87,0.127
186.52,11.93,0.127
186.53,12.00,0.127
186.55,12.07,0.127
186.56,12.13,0.128
186.57,12.20,0.128
186.58,12.27,0.128
186.60,12.33,0.128
186.61,12.40,0.128
186.63,12.47,0.128
186.64,12.53,0.128
186.65,12.60,0.128
186.67,12.67,0.128
186.68,12.73,0.128
186.69,12.80,0.128
186.70,12.87,0.128
186.72,12.93,0.128
186.73,13.00,0.128
186.75,13.07,0.128
186.76,13.13,0.128
186.77,13.20,0.128
186.78,13.27,0.128
186.80,13.34,0.128
186.81,13.40,0.128
186.83,13.47,0.128
186.84,13.53,0.128
186.85,13.60,0.128
186.87,13.67,0.128
186.88,13.73,0.128
186.89,13.80,0.128
186.90,13.87,0.128
186.92,13.93,0.128
186.93,14.00,0.128
186.95,14.07,0.128
186.96,14.13,0.128
186.97,14.20,0.128
186.98,14.27,0.128
187.00,14.34,0.128
187.01,14.40,0.128
187.03,14.47,0.128
187.04,14.53,0.128
187.05,14.60,0.128
187.07,14.67,0.128
187.08,14.73,0.128
187.09,14.80,0.128
187.10,14.87,0.128
187.12,14.94,0.128
187.13,15.00,0.128
187.15,15.07,0.128
187.16,15.14,0.128
187.17,15.20,0.128
187.18,15.27,0.128
187.20,15.34,0.128
187.21,15.40,0.128
187.23,15.47,0.128
187.24,15.54,0.128
187.25,15.60,0.128
187.27,15.67,0.128
187.28,15.74,0.128
187.29,15.80,0.128
187.30,15.87,0.128
187.32,15.94,0.128
187.33,16.00,0.128
187.35,16.07,0.128
187.36,16.14,0.128
187.37,16.20,0.128
187.38,16.27,0.128
187.40,16.34,0.128
187.41,16.41,0.128
187.43,16.47,0.128
187.44,16.54,0.128
187.45,16.61,0.128
187.47,16.67,0.128
187.48,16.74,0.128
187.49,16.80,0.128
187.50,16.87,0.128
187.52,16.94,0.128
187.53,17.01,0.128
187.55,17.07,0.128
187.56,17.14,0.128
187.57,17.21,0.128
187.58,17.27,0.128
187.60,17.34,0.128
187.61,17.41,0.128
187.63,17.47,0.128
187.64,17.54,0.129
187.65,17.61,0.129
187.67,17.67,0.129
187.68,17.74,0.129
187.69,17.81,0.129
187.70,17.87,0.129
187.72,17.94,0.129
187.73,18.01,0.129
187.75,18.07,0.129
187.76,18.14,0.129
187.77,18.21,0.129
187.78,18.28,0.129
187.80,18.34,0.129
187.81,18.41,0.129
187.83,18.47,0.129
187.84,18.54,0.129
187.85,18.61,0.129
187.87,18.67,0.129
187.88,18.74,0.129
187.89,18.81,0.129
187.90,18.87,0.129
187.92,18.94,0.129
187.93,19.01,0.129
187.95,19.07,0.129
187.96,19.14,0.129
187.97,19.21,0.129
187.98,19.27,0.129
188.00,19.34,0.129
188.01,19.41,0.129
188.03,19.47,0.129
188.04,19.54,0.129
188.05,19.61,0.129
188.07,19.67,0.129
188.08,19.74,0.129
188.09,19.81,0.129
188.10,19.87,0.129
188.12,19.94,0.129
188.13,20.01,0.129
188.15,20.07,0.129
188.16,20.14,0.129
188.17,20.21,0.129
188.18,20.27,0.129
188.20,20.34,0.129
188.21,20.41,0.129
188.23,20.47,0.129
188.24,20.54,0.129
188.25,20.61,0.129
188.27,20.67,0.129
188.28,20.74,0.129
188.29,20.81,0.129
188.30,20.87,0.129
188.32,20.94,0.129
188.33,21.01,0.129
188.35,21.07,0.129
188.36,21.14,0.129
188.37,21.21,0.129
188.38,21.27,0.129
188.40,21.34,0.129
188.41,21.41,0.129
188.43,21.47,0.129
188.44,21.54,0.129
188.45,21.61,0.129
188.47,21.67,0.129
188.48,21.74,0.130
188.49,21.81,0.130
188.50,21.87,0.130
188.52,21.94,0.130
188.53,22.01,0.130
188.55,22.08,0.130
188.56,22.14,0.130
188.57,22.21,0.130
188.58,22.27,0.130
188.60,22.34,0.130
188.61,22.41,0.130
188.63,22.48,0.130
188.64,22.54,0.130
188.65,22.61,0.130
188.67,22.68,0.130
188.68,22.74,0.130
188.69,22.81,0.130
188.70,22.88,0.130
188.72,22.94,0.130
188.73,23.01,0.130
188.75,23.08,0.130
188.76,23.14,0.130
188.77,23.21,0.130
188.78,23.28,0.130
188.80,23.34,0.130
188.81,23.41,0.130
188.83,23.48,0.130
188.84,23.54,0.130
188.85,23.61,0.130
188.87,23.67,0.130
188.88,23.74,0.130
188.89,23.81,0.130
188.90,23.88,0.130
188.92,23.94,0.130
188.93,24.01,0.130
188.95,24.08,0.130
188.96,24.14,0.130
188.97,24.21,0.131
188.98,24.28,0.131
189.00,24.34,0.131
189.01,24.41,0.131
189.03,24.48,0.131
189.04,24.54,0.131
189.05,24.61,0.131
189.07,24.68,0.131
189.08,24.74,0.131
189.09,24.81,0.131
189.10,24.88,0.131
189.12,24.94,0.131
189.13,25.01,0.131
189.15,25.08,0.131
189.16,25.14,0.131
189.17,25.21,0.131
189.18,25.28,0.131
189.20,25.34,0.131
189.21,25.41,0.131
189.23,25.48,0.131
189.24,25.54,0.131
189.25,25.61,0.131
189.27,25.68,0.131
189.28,25.74,0.131
189.29,25.81,0.131
189.30,25.88,0.131
189.32,25.94,0.131
189.33,26.01,0.132
189.35,26.08,0.132
189.36,26.14,0.132
189.37,26.21,0.132
189.38,26.28,0.132
189.40,26.34,0.132
189.41,26.41,0.132
189.43,26.48,0.132
189.44,26.54,0.132
189.45,26.61,0.132
189.47,26.68,0.132
189.48,26.74,0.132
189.49,26.81,0.132
189.50,26.88,0.132
189.52,26.94,0.132
189.53,27.01,0.132
189.55,27.08,0.132
189.56,27.14,0.132
189.57,27.21,0.132
189.58,27.28,0.132
189.60,27.34,0.132
189.61,27.41,0.132
189.63,27.48,0.132
189.64,27.54,0.132
189.65,27.61,0.132
189.67,27.68,0.132
189.68,27.74,0.132
189.69,27.81,0.132
189.70,27.88,0.133
189.72,27.94,0.133
189.73,28.01,0.133
189.75,28.08,0.133
189.76,28.14,0.133
189.77,28.21,0.133
189.78,28.28,0.133
189.80,28.34,0.133
189.81,28.41,0.133
189.83,28.48,0.133
189.84,28.54,0.133
189.85,28.61,0.133
189.87,28.68,0.133
189.88,28.74,0.133
189.89,28.81,0.133
189.90,28.88,0.133
189.92,28.94,0.133
189.93,29.01,
189.95,29.08,
189.96,29.15,
189.97,29.21,
189.98,,