File: DSC/2025_06_03_THC_Sorbic_Acid_n60C_150C_10Cmin_x3.csv
Filename,2025_06_03_THC_Sorbic_Acid_n60C_150C_10Cmin_x3
Instrument name,DSC2A-00468 (192.168.1.100)
Operator,Yarger
rundate,6/3/2025
Sample name,2025_06_03_THC_Sorbic_Acid_n60C_150C_10Cmin_x3
proceduresegments,Data Off ; Equilibrate -60.00 °C; Data On ; Ramp 10.00 °C/min to 150.00 °C; Data Off ; Isothermal 2.0 min; Data On ; Ramp 10.00 °C/min to -60.00 °C; Data Off ; Isothermal 2.0 min; Data On ; Ramp 10.00 °C/min to 150.00 °C; Data Off ; Isothermal 2.0 min; Data On ; Ramp 10.00 °C/min to -60.00 °C; Data Off ; Isothermal 2.0 min; Data On ; Ramp 10.00 °C/min to 30.00 °C
[File Parameters]
Run date,6/3/2025 3:50:48 PM
Trios version,5.1.1.46572
Original File Name,
Current File Name,D:\DSC2500\JYarger\2025_06_03_THC_Sorbic_Acid_n60C_150C_10Cmin_x3.tri
[Procedure]
Procedure Name,THC_SA_n60C_150C_10Cmin_x3
Sample Name,2025_06_03_THC_Sorbic_Acid_n60C_150C_10Cmin_x3
Sample Mass,6.1 mg
Reference Sample Mass,0 mg
Pan Mass,56.62 mg
Pan Number,15
Reference Pan Mass,56.96 mg
Reference Pan Number,10
Pan Type,Tzero Aluminum Hermetic
Comments,Al Hermetic DSC Consumables sealed Pan/Lid. A2 Tray (Google Sheet: DSC_Samples_A2_Tray_May2025)
Project Name,CA
Operator,Yarger
Test,Custom
Unload Max Temperature,30
Unload Min Temperature,30
Load Max Temperature,30
Load Min Temperature,30
Stop on Gas Flow Error,Yes
[Signal List]
Signal #1,Time (min)
Signal #2,Temperature (°C)
Signal #3,Heat Flow (mW)
Signal #4,Delta T (µV)
Signal #5,Delta Tzero (µV)
Signal #6,Tzero Temperature (°C)
Signal #7,Cell Purge (mL/min)
Signal #8,Heater Temp (°C)
Signal #9,Power Delivered (W)
Signal #10,Reference Junction Temperature (°C)
Signal #11,Flange Temperature (°C)
Signal #12,Heat Flow Phase (rad)
Signal #13,Total Heat Capacity (J/°C)
Signal #14,Heat Capacity (J/°C)
[Configuration]
Company Name,ASU
Instrument Name,DSC2A-00468
Instrument Type,DSC2500
Serial Number,DSC2A-00468
IP,192.168.1.100
Location of Instrument,MRRC
DisplayType,Unknown
Sample Interval ,0.1 s/pt
Selected Heat Flow,T4P
Exotherm Direction,Down
Cell Serial,DRC2-00792
Lid Type,Standard
Cooler,RCS 90
Leave Cooler on at End of Sequence,On
Gas 2,Nitrogen
Gas Selected,Channel 1
Flow Rate,50 mL/min
Secondary Purge,On
Licensed Heat Flow,Heat Flow T4P
Modulation Licensed,Yes
[Versions]
Common IDD Version,1
Cortex Version,VER 2.10.2.31
Driver,5.0.0.6
GDM Version,1.0.3.3
TouchscreenVersion,1.0.0.16145
FEP Version,1.2.1.21
FEP Bootloader,2.0.0.5
AutoSampler Version,2.1.1.26
Auto Sampler Bootloader,2.0.0.5
FCM Version,1.1.0.3
FCM Bootloader,2.0.0.5
[Experiment Logs]
Experiment Log Entry # 1,Data On set to 0
Experiment Log Entry # 3,Equilibrate Segment -60 (C) Started
Experiment Log Entry # 5,Air Cool is off.
Experiment Log Entry # 7,Data On set to 1
Experiment Log Entry # 9,Ramp Segment 10 C/min to 150 Started
Experiment Log Entry # 11,Data On set to 0
Experiment Log Entry # 13,Isothermal Segment 2 min started
Experiment Log Entry # 15,Data On set to 1
Experiment Log Entry # 17,Ramp Segment 10 C/min to -60 Started
Experiment Log Entry # 19,Data On set to 0
Experiment Log Entry # 21,Isothermal Segment 2 min started
Experiment Log Entry # 23,Data On set to 1
Experiment Log Entry # 25,Ramp Segment 10 C/min to 150 Started
Experiment Log Entry # 27,Data On set to 0
Experiment Log Entry # 29,Isothermal Segment 2 min started
Experiment Log Entry # 31,Data On set to 1
Experiment Log Entry # 33,Ramp Segment 10 C/min to -60 Started
Experiment Log Entry # 35,Data On set to 0
Experiment Log Entry # 37,Isothermal Segment 2 min started
Experiment Log Entry # 39,Data On set to 1
Experiment Log Entry # 41,Ramp Segment 10 C/min to 30 Started
[Method Log]
Method Log Entry # 1,Data Off
Method Log Entry # 2,Equilibrate -60 °C
Method Log Entry # 3,Data On
Method Log Entry # 4,(Ramp 896324) Ramp 10 °C/minute to 150 °C
Method Log Entry # 5,Data Off
Method Log Entry # 6,Isothermal 2 minutes
Method Log Entry # 7,Data On
Method Log Entry # 8,(Ramp 896328) Ramp 10 °C/minute to -60 °C
Method Log Entry # 9,Data Off
Method Log Entry # 10,Isothermal 2 minutes
Method Log Entry # 11,Data On
Method Log Entry # 12,(Ramp 896332) Ramp 10 °C/minute to 150 °C
Method Log Entry # 13,Data Off
Method Log Entry # 14,Isothermal 2 minutes
Method Log Entry # 15,Data On
Method Log Entry # 16,(Ramp 896336) Ramp 10 °C/minute to -60 °C
Method Log Entry # 17,Data Off
Method Log Entry # 18,Isothermal 2 minutes
Method Log Entry # 19,Data On
Method Log Entry # 20,(Ramp 896340) Ramp 10 °C/minute to 30 °C
Cell Serial,DRC2-00792
[T1 Calibration]
Slope,-0.008529666
Offset,9.636258
Initial Temperature,98.23
GUID,f8bfdadc-4977-4fdf-ba6d-0ba9134940c3
[TZero Calibration]
Date Applied,11/29/2022 4:06:13 PM
Description,From -89.059 °C to 396.009 °C at 20.000°C/min
Gas Type,Nitrogen
Pan Type,None
Source Files 1,C:\Users\yargerlab\Desktop\DSC Data\General\TZero_calibration_11_29_22_2nd(2).tri
Source Files 2,C:\Users\yargerlab\Desktop\DSC Data\General\TZero_calibration_11_29_22_2nd(3).tri
Delta T Offset,13.05235
Delta T Slope,-0.007271007
Delta T0 Offset,-13.69128
Delta T0 Slope,0.06063341
[Temperature Calibration]
Date Applied,11/29/2022 7:12:28 PM
Description,From 106.590 °C to 186.590 °C at 10.000°C/min
Gas Type,Nitrogen
Pan Type,Tzero Aluminum Hermetic
Source Files 1,C:\Users\yargerlab\Desktop\DSC Data\General\Indium(6).tri
Measured 1,157.391
Known 1,156.598
[Cell Constant Calibration]
Date Applied,11/29/2022 7:12:29 PM
Description,From 106.590 °C to 186.590 °C at 10.000°C/min
Gas Type,Nitrogen
Pan Type,Tzero Aluminum Hermetic
Source Files 1,C:\Users\yargerlab\Desktop\DSC Data\General\Indium(6).tri
T4P KCell,1.006051
Onset Slope,63.26126 mW/°C
[Direct Cp Calibration]
Date Applied,11/30/2022 11:04:51 AM
Description,From -79.983 °C to 298.409 °C at 10.000°C/min
Gas Type,Nitrogen
Pan Type,Tzero Aluminum Hermetic
Source Files 1,C:\Users\yargerlab\Desktop\DSC Data\General\Sapphire_Heat_Capacity_11_30_22.tri
[Rev Cp Calibration]
Date Applied,11/30/2022 1:58:51 PM
Description,From -79.996 °C to 292.812 °C at 3.000°C/min
Gas Type,Nitrogen
Pan Type,Tzero Aluminum Hermetic
Source Files 1,C:\Users\yargerlab\Desktop\DSC Data\General\Sapphire_MDSC_Calibration_11_30_22.tri
[step]
Ramp 10.00 °C/min to 150.00 °C
Time,Temperature,Heat Flow (Normalized)
min,°C,W/g
0.00,-59.67,-0.060
0.01,-59.68,-0.059
0.03,-59.69,-0.054
0.05,-59.69,-0.051
0.06,-59.68,-0.053
0.08,-59.67,-0.057
0.09,-59.64,-0.070
0.11,-59.59,-0.079
0.12,-59.53,-0.083
0.14,-59.46,-0.084
0.15,-59.38,-0.082
0.16,-59.29,-0.072
0.18,-59.19,-0.052
0.19,-59.09,-0.037
0.21,-58.98,-0.020
0.23,-58.86,-0.004
0.24,-58.74,0.013
0.26,-58.62,0.027
0.27,-58.50,0.040
0.29,-58.37,0.052
0.30,-58.24,0.063
0.31,-58.11,0.073
0.33,-57.98,0.082
0.35,-57.84,0.089
0.36,-57.71,0.095
0.38,-57.57,0.102
0.39,-57.44,0.107
0.40,-57.30,0.111
0.42,-57.16,0.115
0.44,-57.02,0.119
0.45,-56.88,0.122
0.46,-56.74,0.125
0.48,-56.59,0.127
0.50,-56.45,0.130
0.51,-56.31,0.132
0.53,-56.17,0.133
0.54,-56.02,0.136
0.55,-55.88,0.137
0.57,-55.73,0.138
0.58,-55.59,0.139
0.60,-55.44,0.141
0.62,-55.30,0.142
0.63,-55.15,0.142
0.65,-55.01,0.143
0.66,-54.86,0.144
0.68,-54.71,0.145
0.69,-54.57,0.145
0.70,-54.42,0.146
0.72,-54.27,0.146
0.73,-54.13,0.146
0.75,-53.98,0.147
0.77,-53.83,0.147
0.78,-53.69,0.148
0.80,-53.54,0.148
0.81,-53.39,0.148
0.83,-53.24,0.149
0.84,-53.10,0.149
0.85,-52.95,0.149
0.87,-52.80,0.149
0.88,-52.65,0.150
0.90,-52.50,0.150
0.92,-52.36,0.150
0.93,-52.21,0.151
0.95,-52.06,0.151
0.96,-51.91,0.151
0.98,-51.76,0.151
0.99,-51.61,0.152
1.00,-51.47,0.152
1.02,-51.32,0.152
1.03,-51.17,0.152
1.05,-51.02,0.153
1.07,-50.87,0.153
1.08,-50.72,0.153
1.09,-50.57,0.153
1.11,-50.42,0.153
1.13,-50.27,0.154
1.14,-50.13,0.154
1.16,-49.98,0.154
1.17,-49.83,0.154
1.18,-49.68,0.154
1.20,-49.53,0.155
1.22,-49.38,0.155
1.23,-49.23,0.155
1.24,-49.08,0.155
1.26,-48.93,0.155
1.28,-48.79,0.155
1.29,-48.64,0.156
1.31,-48.49,0.156
1.32,-48.34,0.156
1.33,-48.19,0.156
1.35,-48.04,0.156
1.37,-47.89,0.156
1.38,-47.74,0.156
1.39,-47.60,0.156
1.41,-47.44,0.156
1.43,-47.30,0.156
1.44,-47.15,0.157
1.46,-47.00,0.157
1.47,-46.85,0.157
1.48,-46.70,0.157
1.50,-46.55,0.157
1.52,-46.40,0.157
1.53,-46.25,0.157
1.54,-46.10,0.157
1.56,-45.95,0.157
1.58,-45.80,0.157
1.59,-45.65,0.158
1.61,-45.50,0.158
1.62,-45.35,0.158
1.63,-45.20,0.158
1.65,-45.05,0.158
1.67,-44.90,0.158
1.68,-44.75,0.158
1.69,-44.60,0.159
1.71,-44.45,0.159
1.73,-44.30,0.159
1.74,-44.15,0.159
1.76,-44.00,0.159
1.77,-43.85,0.159
1.78,-43.70,0.159
1.80,-43.55,0.159
1.82,-43.40,0.159
1.83,-43.25,0.160
1.84,-43.10,0.160
1.86,-42.94,0.160
1.88,-42.79,0.160
1.89,-42.65,0.160
1.91,-42.50,0.160
1.92,-42.34,0.160
1.93,-42.19,0.160
1.95,-42.04,0.160
1.97,-41.89,0.160
1.98,-41.74,0.160
1.99,-41.59,0.161
2.01,-41.45,0.161
2.03,-41.29,0.161
2.04,-41.14,0.161
2.06,-40.99,0.161
2.07,-40.84,0.161
2.08,-40.69,0.161
2.10,-40.54,0.161
2.12,-40.39,0.161
2.13,-40.24,0.161
2.14,-40.09,0.161
2.16,-39.94,0.161
2.18,-39.79,0.161
2.19,-39.64,0.161
2.21,-39.49,0.161
2.22,-39.34,0.162
2.24,-39.19,0.162
2.25,-39.04,0.162
2.26,-38.89,0.162
2.28,-38.74,0.162
2.29,-38.59,0.162
2.31,-38.44,0.162
2.33,-38.29,0.162
2.34,-38.14,0.162
2.36,-37.99,0.162
2.37,-37.84,0.162
2.39,-37.69,0.162
2.40,-37.54,0.162
2.41,-37.39,0.162
2.43,-37.24,0.162
2.44,-37.09,0.162
2.46,-36.94,0.162
2.48,-36.79,0.163
2.49,-36.64,0.163
2.51,-36.48,0.163
2.52,-36.33,0.163
2.54,-36.18,0.163
2.55,-36.03,0.163
2.56,-35.88,0.163
2.58,-35.73,0.163
2.59,-35.58,0.163
2.61,-35.43,0.163
2.63,-35.28,0.163
2.64,-35.13,0.163
2.66,-34.98,0.163
2.67,-34.83,0.164
2.69,-34.68,0.164
2.70,-34.53,0.164
2.71,-34.38,0.164
2.73,-34.23,0.164
2.74,-34.08,0.164
2.76,-33.93,0.164
2.78,-33.78,0.164
2.79,-33.63,0.164
2.81,-33.48,0.164
2.82,-33.33,0.164
2.84,-33.18,0.164
2.85,-33.03,0.164
2.86,-32.88,0.164
2.88,-32.73,0.164
2.89,-32.58,0.164
2.91,-32.43,0.164
2.93,-32.28,0.164
2.94,-32.13,0.165
2.96,-31.98,0.165
2.97,-31.83,0.165
2.99,-31.68,0.165
3.00,-31.53,0.165
3.01,-31.38,0.165
3.03,-31.23,0.165
3.04,-31.07,0.165
3.06,-30.93,0.165
3.08,-30.78,0.165
3.09,-30.63,0.165
3.11,-30.47,0.165
3.12,-30.32,0.166
3.14,-30.17,0.166
3.15,-30.02,0.166
3.16,-29.88,0.166
3.18,-29.72,0.166
3.19,-29.57,0.166
3.21,-29.42,0.166
3.23,-29.27,0.166
3.24,-29.12,0.166
3.26,-28.97,0.166
3.27,-28.82,0.166
3.29,-28.67,0.166
3.30,-28.52,0.166
3.31,-28.37,0.166
3.33,-28.22,0.166
3.34,-28.07,0.167
3.36,-27.92,0.167
3.38,-27.77,0.167
3.39,-27.62,0.167
3.41,-27.47,0.167
3.42,-27.32,0.167
3.44,-27.17,0.167
3.45,-27.02,0.167
3.46,-26.87,0.167
3.48,-26.72,0.167
3.49,-26.57,0.167
3.51,-26.42,0.168
3.53,-26.27,0.168
3.54,-26.12,0.168
3.56,-25.97,0.168
3.57,-25.82,0.168
3.59,-25.67,0.168
3.60,-25.52,0.168
3.61,-25.37,0.168
3.63,-25.22,0.168
3.64,-25.07,0.168
3.66,-24.92,0.169
3.68,-24.77,0.169
3.69,-24.62,0.169
3.71,-24.47,0.169
3.72,-24.32,0.169
3.74,-24.17,0.169
3.75,-24.02,0.169
3.76,-23.87,0.169
3.78,-23.72,0.170
3.79,-23.57,0.170
3.81,-23.42,0.170
3.83,-23.27,0.170
3.84,-23.12,0.170
3.86,-22.97,0.170
3.87,-22.82,0.170
3.89,-22.67,0.171
3.90,-22.52,0.171
3.91,-22.37,0.171
3.93,-22.22,0.171
3.94,-22.07,0.171
3.96,-21.92,0.171
3.98,-21.77,0.171
3.99,-21.62,0.172
4.01,-21.47,0.172
4.02,-21.32,0.172
4.04,-21.16,0.172
4.05,-21.01,0.172
4.06,-20.87,0.173
4.08,-20.72,0.173
4.09,-20.56,0.173
4.11,-20.42,0.173
4.13,-20.26,0.173
4.14,-20.11,0.173
4.16,-19.96,0.174
4.17,-19.81,0.174
4.19,-19.66,0.174
4.20,-19.51,0.174
4.21,-19.36,0.175
4.23,-19.22,0.175
4.24,-19.06,0.175
4.26,-18.92,0.175
4.28,-18.76,0.176
4.29,-18.61,0.176
4.30,-18.46,0.176
4.32,-18.31,0.176
4.34,-18.17,0.177
4.35,-18.01,0.177
4.36,-17.86,0.178
4.38,-17.71,0.178
4.40,-17.56,0.178
4.41,-17.41,0.179
4.43,-17.26,0.180
4.44,-17.11,0.180
4.45,-16.96,0.180
4.47,-16.81,0.181
4.49,-16.66,0.181
4.50,-16.52,0.181
4.51,-16.36,0.182
4.53,-16.21,0.182
4.55,-16.07,0.182
4.56,-15.91,0.183
4.58,-15.76,0.184
4.59,-15.61,0.185
4.60,-15.46,0.185
4.62,-15.31,0.186
4.64,-15.17,0.186
4.65,-15.02,0.187
4.66,-14.86,0.187
4.68,-14.71,0.188
4.70,-14.57,0.188
4.71,-14.42,0.189
4.73,-14.27,0.190
4.74,-14.12,0.190
4.75,-13.96,0.191
4.77,-13.82,0.192
4.79,-13.67,0.192
4.80,-13.52,0.193
4.81,-13.37,0.193
4.83,-13.22,0.195
4.85,-13.07,0.196
4.86,-12.92,0.198
4.88,-12.77,0.198
4.89,-12.62,0.199
4.90,-12.47,0.200
4.92,-12.32,0.201
4.94,-12.17,0.202
4.95,-12.02,0.202
4.96,-11.87,0.203
4.98,-11.72,0.204
5.00,-11.57,0.205
5.01,-11.42,0.206
5.03,-11.27,0.206
5.04,-11.12,0.207
5.05,-10.97,0.209
5.07,-10.82,0.210
5.09,-10.67,0.210
5.10,-10.52,0.210
5.11,-10.37,0.211
5.13,-10.22,0.212
5.15,-10.07,0.212
5.16,-9.92,0.214
5.18,-9.77,0.214
5.19,-9.62,0.214
5.20,-9.47,0.215
5.22,-9.32,0.216
5.24,-9.17,0.216
5.25,-9.02,0.217
5.26,-8.87,0.217
5.28,-8.72,0.217
5.30,-8.57,0.218
5.31,-8.42,0.218
5.33,-8.27,0.218
5.34,-8.12,0.219
5.35,-7.97,0.219
5.37,-7.82,0.220
5.39,-7.67,0.220
5.40,-7.52,0.220
5.41,-7.37,0.220
5.43,-7.22,0.221
5.45,-7.07,0.221
5.46,-6.92,0.221
5.48,-6.77,0.221
5.49,-6.62,0.222
5.50,-6.47,0.222
5.52,-6.32,0.222
5.54,-6.17,0.222
5.55,-6.02,0.222
5.56,-5.87,0.222
5.58,-5.72,0.222
5.60,-5.57,0.222
5.61,-5.42,0.222
5.63,-5.27,0.222
5.64,-5.12,0.222
5.65,-4.97,0.222
5.67,-4.82,0.222
5.69,-4.67,0.222
5.70,-4.52,0.222
5.71,-4.36,0.222
5.73,-4.22,0.222
5.75,-4.07,0.222
5.76,-3.91,0.222
5.78,-3.77,0.222
5.79,-3.61,0.222
5.80,-3.46,0.222
5.82,-3.31,0.222
5.84,-3.16,0.222
5.85,-3.01,0.222
5.86,-2.86,0.222
5.88,-2.71,0.222
5.90,-2.56,0.222
5.91,-2.41,0.222
5.93,-2.26,0.222
5.94,-2.11,0.222
5.95,-1.96,0.222
5.97,-1.81,0.222
5.99,-1.66,0.222
6.00,-1.51,0.222
6.01,-1.36,0.222
6.03,-1.21,0.222
6.05,-1.06,0.222
6.06,-0.91,0.222
6.08,-0.76,0.222
6.09,-0.61,0.222
6.10,-0.46,0.222
6.12,-0.31,0.222
6.14,-0.16,0.222
6.15,-0.01,0.222
6.16,0.14,0.222
6.18,0.29,0.222
6.20,0.44,0.222
6.21,0.59,0.222
6.23,0.74,0.222
6.24,0.89,0.222
6.25,1.04,0.222
6.27,1.19,0.222
6.29,1.34,0.222
6.30,1.49,0.223
6.31,1.65,0.223
6.33,1.80,0.223
6.35,1.95,0.223
6.36,2.10,0.223
6.38,2.25,0.223
6.39,2.40,0.223
6.40,2.55,0.223
6.42,2.70,0.223
6.44,2.85,0.223
6.45,3.00,0.223
6.46,3.15,0.223
6.48,3.30,0.223
6.50,3.45,0.223
6.51,3.60,0.223
6.53,3.75,0.223
6.54,3.90,0.224
6.55,4.05,0.224
6.57,4.20,0.224
6.59,4.35,0.224
6.60,4.50,0.224
6.61,4.65,0.224
6.63,4.80,0.224
6.65,4.95,0.224
6.66,5.10,0.224
6.68,5.25,0.224
6.69,5.40,0.224
6.70,5.55,0.224
6.72,5.70,0.224
6.74,5.85,0.224
6.75,6.00,0.224
6.76,6.15,0.225
6.78,6.30,0.225
6.80,6.45,0.225
6.81,6.60,0.225
6.83,6.75,0.225
6.84,6.90,0.225
6.85,7.05,0.225
6.87,7.20,0.225
6.89,7.35,0.225
6.90,7.50,0.225
6.91,7.65,0.225
6.93,7.81,0.225
6.95,7.95,0.226
6.96,8.11,0.226
6.98,8.25,0.226
6.99,8.40,0.226
7.00,8.56,0.226
7.02,8.71,0.226
7.04,8.86,0.226
7.05,9.01,0.226
7.06,9.16,0.226
7.08,9.31,0.226
7.10,9.46,0.226
7.11,9.61,0.226
7.13,9.76,0.226
7.14,9.91,0.227
7.15,10.06,0.227
7.17,10.21,0.227
7.19,10.36,0.227
7.20,10.51,0.227
7.21,10.66,0.227
7.23,10.81,0.227
7.25,10.96,0.227
7.26,11.11,0.227
7.28,11.26,0.227
7.29,11.41,0.227
7.30,11.56,0.228
7.32,11.71,0.228
7.34,11.86,0.228
7.35,12.01,0.228
7.36,12.16,0.228
7.38,12.31,0.228
7.40,12.46,0.228
7.41,12.61,0.228
7.43,12.76,0.228
7.44,12.91,0.228
7.45,13.06,0.229
7.47,13.21,0.229
7.49,13.36,0.229
7.50,13.51,0.229
7.51,13.66,0.229
7.53,13.81,0.229
7.55,13.96,0.229
7.56,14.11,0.229
7.58,14.26,0.229
7.59,14.41,0.229
7.60,14.56,0.229
7.62,14.71,0.230
7.64,14.86,0.230
7.65,15.01,0.230
7.66,15.16,0.230
7.68,15.31,0.230
7.70,15.46,0.230
7.71,15.61,0.230
7.73,15.76,0.230
7.74,15.92,0.230
7.75,16.06,0.231
7.77,16.21,0.231
7.79,16.37,0.231
7.80,16.51,0.231
7.81,16.67,0.231
7.83,16.82,0.231
7.85,16.97,0.231
7.86,17.12,0.231
7.88,17.27,0.231
7.89,17.42,0.231
7.90,17.57,0.232
7.92,17.72,0.232
7.94,17.87,0.232
7.95,18.02,0.232
7.96,18.17,0.232
7.98,18.32,0.232
8.00,18.47,0.232
8.01,18.62,0.232
8.03,18.77,0.232
8.04,18.92,0.233
8.05,19.07,0.233
8.07,19.22,0.233
8.09,19.37,0.233
8.10,19.52,0.233
8.11,19.67,0.233
8.13,19.82,0.233
8.15,19.97,0.234
8.16,20.12,0.234
8.18,20.27,0.234
8.19,20.42,0.234
8.20,20.57,0.234
8.22,20.72,0.234
8.24,20.87,0.234
8.25,21.02,0.235
8.26,21.17,0.235
8.28,21.32,0.235
8.30,21.47,0.235
8.31,21.62,0.235
8.33,21.77,0.236
8.34,21.92,0.236
8.35,22.07,0.236
8.37,22.22,0.236
8.39,22.37,0.236
8.40,22.52,0.237
8.41,22.67,0.237
8.43,22.82,0.237
8.45,22.97,0.237
8.46,23.12,0.237
8.48,23.27,0.238
8.49,23.42,0.238
8.50,23.57,0.238
8.52,23.72,0.238
8.53,23.87,0.238
8.55,24.02,0.239
8.57,24.17,0.239
8.58,24.32,0.239
8.60,24.47,0.239
8.61,24.62,0.240
8.63,24.77,0.240
8.64,24.92,0.240
8.65,25.07,0.240
8.67,25.22,0.241
8.68,25.37,0.241
8.70,25.52,0.241
8.72,25.67,0.241
8.73,25.82,0.242
8.75,25.97,0.242
8.76,26.12,0.242
8.78,26.27,0.242
8.79,26.42,0.243
8.80,26.57,0.243
8.82,26.72,0.243
8.83,26.87,0.244
8.85,27.02,0.244
8.87,27.17,0.244
8.88,27.32,0.245
8.90,27.47,0.245
8.91,27.62,0.245
8.93,27.77,0.245
8.94,27.92,0.246
8.95,28.07,0.246
8.97,28.22,0.246
8.98,28.37,0.247
9.00,28.52,0.247
9.02,28.67,0.247
9.03,28.82,0.248
9.05,28.97,0.248
9.06,29.12,0.248
9.08,29.27,0.248
9.09,29.42,0.249
9.10,29.57,0.249
9.12,29.72,0.249
9.13,29.87,0.250
9.15,30.02,0.251
9.17,30.17,0.251
9.18,30.32,0.251
9.20,30.47,0.251
9.21,30.62,0.252
9.23,30.77,0.252
9.24,30.92,0.252
9.25,31.07,0.252
9.27,31.22,0.253
9.28,31.37,0.253
9.30,31.52,0.253
9.32,31.67,0.254
9.33,31.82,0.254
9.35,31.97,0.254
9.36,32.12,0.255
9.38,32.27,0.255
9.39,32.42,0.255
9.40,32.57,0.255
9.42,32.72,0.256
9.43,32.87,0.256
9.45,33.02,0.256
9.47,33.17,0.256
9.48,33.32,0.257
9.50,33.47,0.257
9.51,33.62,0.257
9.53,33.77,0.258
9.54,33.92,0.258
9.55,34.07,0.258
9.57,34.22,0.258
9.58,34.37,0.259
9.60,34.52,0.259
9.62,34.68,0.259
9.63,34.82,0.259
9.65,34.97,0.260
9.66,35.12,0.260
9.68,35.27,0.260
9.69,35.42,0.260
9.70,35.57,0.260
9.72,35.73,0.261
9.73,35.88,0.261
9.75,36.03,0.261
9.77,36.17,0.261
9.78,36.33,0.262
9.80,36.48,0.262
9.81,36.63,0.262
9.83,36.78,0.262
9.84,36.93,0.263
9.85,37.08,0.263
9.87,37.23,0.263
9.88,37.38,0.263
9.90,37.53,0.263
9.92,37.68,0.264
9.93,37.83,0.264
9.95,37.98,0.264
9.96,38.13,0.264
9.98,38.28,0.264
9.99,38.43,0.265
10.00,38.58,0.265
10.02,38.73,0.265
10.03,38.88,0.265
10.05,39.03,0.266
10.07,39.18,0.266
10.08,39.33,0.266
10.10,39.48,0.266
10.11,39.63,0.266
10.13,39.78,0.266
10.14,39.93,0.267
10.15,40.08,0.267
10.17,40.23,0.267
10.18,40.38,0.267
10.20,40.53,0.267
10.22,40.68,0.268
10.23,40.83,0.268
10.25,40.98,0.268
10.26,41.13,0.268
10.28,41.28,0.269
10.29,41.43,0.269
10.30,41.58,0.269
10.32,41.73,0.269
10.33,41.88,0.270
10.35,42.03,0.270
10.37,42.18,0.270
10.38,42.33,0.270
10.40,42.48,0.270
10.41,42.63,0.271
10.43,42.78,0.271
10.44,42.93,0.271
10.45,43.08,0.271
10.47,43.23,0.271
10.48,43.38,0.272
10.50,43.53,0.272
10.52,43.68,0.272
10.53,43.83,0.272
10.55,43.98,0.273
10.56,44.13,0.273
10.58,44.28,0.273
10.59,44.43,0.273
10.60,44.58,0.273
10.62,44.73,0.274
10.63,44.88,0.274
10.65,45.03,0.274
10.67,45.18,0.274
10.68,45.33,0.275
10.70,45.48,0.275
10.71,45.63,0.275
10.73,45.78,0.275
10.74,45.93,0.276
10.75,46.08,0.276
10.77,46.23,0.276
10.78,46.38,0.276
10.80,46.53,0.276
10.82,46.68,0.277
10.83,46.83,0.277
10.85,46.99,0.277
10.86,47.14,0.277
10.88,47.28,0.278
10.89,47.44,0.278
10.90,47.59,0.278
10.92,47.74,0.279
10.93,47.89,0.279
10.95,48.03,0.279
10.97,48.18,0.279
10.98,48.33,0.280
11.00,48.49,0.280
11.01,48.64,0.280
11.03,48.79,0.280
11.04,48.94,0.281
11.05,49.09,0.281
11.07,49.24,0.281
11.08,49.39,0.281
11.10,49.54,0.282
11.12,49.69,0.282
11.13,49.84,0.282
11.15,49.99,0.282
11.16,50.14,0.283
11.18,50.29,0.283
11.19,50.44,0.283
11.20,50.59,0.283
11.22,50.74,0.284
11.23,50.89,0.284
11.25,51.04,0.284
11.27,51.19,0.284
11.28,51.34,0.285
11.30,51.49,0.285
11.31,51.64,0.285
11.33,51.79,0.286
11.34,51.94,0.286
11.35,52.09,0.286
11.37,52.24,0.286
11.38,52.39,0.287
11.40,52.54,0.287
11.42,52.69,0.287
11.43,52.84,0.288
11.45,52.99,0.288
11.46,53.14,0.288
11.48,53.29,0.288
11.49,53.44,0.289
11.50,53.59,0.289
11.52,53.74,0.290
11.53,53.89,0.290
11.55,54.04,0.290
11.57,54.19,0.290
11.58,54.34,0.291
11.60,54.49,0.291
11.61,54.64,0.291
11.63,54.79,0.292
11.64,54.94,0.292
11.65,55.09,0.292
11.67,55.24,0.292
11.68,55.39,0.293
11.70,55.54,0.293
11.72,55.69,0.293
11.73,55.84,0.293
11.75,55.99,0.294
11.76,56.14,0.294
11.78,56.29,0.294
11.79,56.44,0.295
11.80,56.59,0.295
11.82,56.74,0.295
11.83,56.89,0.296
11.85,57.04,0.296
11.87,57.19,0.297
11.88,57.34,0.297
11.90,57.49,0.297
11.91,57.64,0.298
11.93,57.79,0.298
11.94,57.94,0.298
11.95,58.09,0.299
11.97,58.24,0.299
11.98,58.39,0.299
12.00,58.54,0.300
12.02,58.69,0.300
12.03,58.84,0.300
12.05,58.99,0.300
12.06,59.14,0.301
12.08,59.29,0.301
12.09,59.44,0.301
12.10,59.59,0.302
12.12,59.74,0.302
12.13,59.89,0.302
12.15,60.04,0.303
12.17,60.19,0.303
12.18,60.34,0.304
12.20,60.49,0.305
12.21,60.64,0.305
12.23,60.79,0.306
12.24,60.94,0.306
12.25,61.09,0.306
12.27,61.24,0.307
12.28,61.39,0.307
12.30,61.54,0.307
12.32,61.69,0.307
12.33,61.84,0.308
12.35,61.99,0.308
12.36,62.15,0.308
12.38,62.29,0.308
12.39,62.45,0.309
12.40,62.60,0.310
12.42,62.74,0.310
12.43,62.89,0.311
12.45,63.04,0.311
12.47,63.19,0.311
12.48,63.34,0.312
12.50,63.49,0.312
12.51,63.64,0.312
12.53,63.79,0.312
12.54,63.94,0.313
12.55,64.09,0.313
12.57,64.24,0.314
12.58,64.39,0.314
12.60,64.54,0.314
12.62,64.69,0.315
12.63,64.84,0.315
12.65,64.99,0.315
12.66,65.14,0.316
12.68,65.29,0.316
12.69,65.44,0.317
12.70,65.59,0.317
12.72,65.74,0.317
12.73,65.89,0.318
12.75,66.04,0.318
12.77,66.19,0.319
12.78,66.34,0.319
12.80,66.49,0.320
12.81,66.64,0.320
12.83,66.79,0.321
12.84,66.94,0.321
12.85,67.09,0.322
12.87,67.24,0.322
12.88,67.39,0.322
12.90,67.54,0.323
12.92,67.69,0.323
12.93,67.84,0.324
12.95,67.99,0.325
12.96,68.14,0.325
12.98,68.29,0.325
12.99,68.44,0.326
13.00,68.59,0.326
13.02,68.74,0.327
13.03,68.89,0.327
13.05,69.04,0.328
13.07,69.19,0.328
13.08,69.34,0.329
13.10,69.49,0.330
13.11,69.64,0.330
13.13,69.79,0.331
13.14,69.94,0.331
13.15,70.09,0.332
13.17,70.24,0.332
13.18,70.39,0.333
13.20,70.54,0.333
13.22,70.69,0.333
13.23,70.84,0.334
13.25,70.99,0.335
13.26,71.14,0.335
13.28,71.29,0.336
13.29,71.44,0.336
13.30,71.59,0.337
13.32,71.74,0.338
13.33,71.89,0.338
13.35,72.04,0.339
13.37,72.19,0.339
13.38,72.34,0.340
13.40,72.49,0.341
13.41,72.64,0.342
13.43,72.79,0.343
13.44,72.94,0.344
13.45,73.09,0.346
13.47,73.24,0.347
13.48,73.39,0.348
13.50,73.54,0.349
13.52,73.69,0.351
13.53,73.84,0.353
13.55,73.99,0.355
13.56,74.14,0.361
13.58,74.29,0.377
13.59,74.44,0.392
13.60,74.58,0.393
13.62,74.73,0.404
13.63,74.88,0.413
13.65,75.03,0.433
13.67,75.17,0.459
13.68,75.31,0.478
13.70,75.46,0.459
13.71,75.61,0.413
13.73,75.76,0.404
13.74,75.92,0.400
13.75,76.07,0.399
13.77,76.22,0.396
13.78,76.37,0.395
13.80,76.52,0.394
13.82,76.67,0.393
13.83,76.83,0.393
13.85,76.98,0.392
13.86,77.13,0.391
13.88,77.28,0.391
13.89,77.43,0.391
13.90,77.58,0.391
13.92,77.73,0.391
13.93,77.88,0.391
13.95,78.03,0.391
13.97,78.18,0.391
13.98,78.33,0.391
14.00,78.48,0.391
14.01,78.63,0.391
14.03,78.78,0.391
14.04,78.93,0.391
14.05,79.08,0.391
14.07,79.23,0.391
14.08,79.38,0.391
14.10,79.53,0.391
14.12,79.68,0.392
14.13,79.83,0.392
14.15,79.98,0.392
14.16,80.13,0.392
14.18,80.28,0.393
14.19,80.43,0.393
14.20,80.58,0.394
14.22,80.73,0.395
14.23,80.88,0.395
14.25,81.03,0.396
14.27,81.18,0.397
14.28,81.33,0.397
14.30,81.48,0.398
14.31,81.63,0.399
14.33,81.78,0.399
14.34,81.93,0.400
14.35,82.08,0.401
14.37,82.23,0.401
14.38,82.38,0.401
14.40,82.53,0.402
14.42,82.68,0.403
14.43,82.83,0.403
14.45,82.98,0.404
14.46,83.13,0.406
14.48,83.28,0.407
14.49,83.43,0.407
14.50,83.58,0.408
14.52,83.73,0.409
14.53,83.88,0.409
14.55,84.03,0.410
14.57,84.18,0.411
14.58,84.33,0.412
14.60,84.48,0.413
14.61,84.63,0.413
14.63,84.78,0.415
14.64,84.93,0.415
14.65,85.08,0.416
14.67,85.23,0.417
14.68,85.38,0.418
14.70,85.53,0.419
14.72,85.68,0.419
14.73,85.83,0.420
14.75,85.98,0.422
14.76,86.13,0.423
14.78,86.28,0.423
14.79,86.43,0.424
14.80,86.58,0.425
14.82,86.73,0.426
14.83,86.88,0.427
14.85,87.03,0.428
14.87,87.18,0.428
14.88,87.33,0.429
14.90,87.48,0.431
14.91,87.63,0.432
14.93,87.78,0.432
14.94,87.93,0.433
14.95,88.08,0.435
14.97,88.22,0.435
14.98,88.38,0.436
15.00,88.52,0.437
15.02,88.67,0.438
15.03,88.83,0.440
15.05,88.98,0.441
15.06,89.13,0.442
15.08,89.28,0.443
15.09,89.43,0.445
15.10,89.58,0.447
15.12,89.73,0.449
15.13,89.88,0.449
15.15,90.03,0.451
15.17,90.18,0.452
15.18,90.33,0.453
15.20,90.48,0.454
15.21,90.63,0.455
15.23,90.78,0.455
15.24,90.93,0.456
15.25,91.08,0.457
15.27,91.23,0.457
15.28,91.38,0.458
15.30,91.53,0.459
15.32,91.68,0.460
15.33,91.83,0.461
15.35,91.97,0.462
15.36,92.13,0.464
15.38,92.27,0.464
15.39,92.42,0.466
15.40,92.57,0.466
15.42,92.72,0.468
15.43,92.87,0.469
15.45,93.02,0.470
15.47,93.17,0.471
15.48,93.32,0.473
15.50,93.47,0.474
15.51,93.62,0.475
15.53,93.77,0.477
15.54,93.92,0.478
15.55,94.07,0.480
15.57,94.22,0.481
15.58,94.37,0.483
15.60,94.52,0.486
15.62,94.67,0.486
15.63,94.82,0.488
15.65,94.97,0.488
15.66,95.12,0.490
15.68,95.27,0.491
15.69,95.41,0.493
15.70,95.56,0.495
15.72,95.71,0.496
15.73,95.86,0.497
15.75,96.01,0.498
15.77,96.16,0.500
15.78,96.31,0.502
15.80,96.46,0.504
15.81,96.61,0.506
15.83,96.76,0.507
15.84,96.91,0.508
15.85,97.06,0.509
15.87,97.21,0.511
15.88,97.36,0.513
15.90,97.51,0.515
15.92,97.66,0.516
15.93,97.81,0.519
15.95,97.96,0.521
15.96,98.11,0.524
15.98,98.26,0.526
15.99,98.41,0.527
16.00,98.56,0.529
16.02,98.70,0.529
16.03,98.85,0.531
16.05,99.00,0.532
16.07,99.15,0.532
16.08,99.30,0.534
16.10,99.45,0.535
16.11,99.60,0.537
16.13,99.75,0.539
16.14,99.90,0.541
16.15,100.05,0.542
16.17,100.20,0.545
16.18,100.35,0.546
16.20,100.50,0.547
16.22,100.65,0.550
16.23,100.80,0.552
16.25,100.95,0.554
16.26,101.10,0.556
16.28,101.25,0.557
16.29,101.40,0.560
16.30,101.54,0.561
16.32,101.70,0.564
16.33,101.84,0.566
16.35,101.99,0.568
16.37,102.14,0.570
16.38,102.29,0.572
16.40,102.44,0.573
16.41,102.59,0.577
16.43,102.74,0.578
16.44,102.89,0.580
16.45,103.04,0.583
16.47,103.19,0.585
16.48,103.34,0.587
16.50,103.49,0.590
16.52,103.64,0.590
16.53,103.79,0.593
16.55,103.94,0.595
16.56,104.09,0.597
16.58,104.23,0.599
16.59,104.38,0.601
16.60,104.53,0.602
16.62,104.68,0.604
16.63,104.83,0.606
16.65,104.98,0.608
16.67,105.13,0.610
16.68,105.28,0.612
16.70,105.43,0.614
16.71,105.58,0.616
16.73,105.73,0.618
16.74,105.88,0.620
16.75,106.03,0.622
16.77,106.18,0.624
16.78,106.33,0.627
16.80,106.48,0.629
16.82,106.63,0.631
16.83,106.77,0.635
16.85,106.92,0.636
16.86,107.07,0.638
16.88,107.22,0.640
16.89,107.37,0.642
16.90,107.52,0.645
16.92,107.67,0.648
16.93,107.82,0.649
16.95,107.97,0.655
16.97,108.12,0.658
16.98,108.27,0.662
17.00,108.42,0.666
17.01,108.57,0.669
17.03,108.72,0.673
17.04,108.86,0.678
17.05,109.01,0.679
17.07,109.16,0.680
17.08,109.31,0.681
17.10,109.46,0.682
17.12,109.61,0.682
17.13,109.76,0.682
17.14,109.91,0.683
17.16,110.06,0.684
17.18,110.21,0.685
17.19,110.36,0.685
17.21,110.51,0.687
17.22,110.66,0.689
17.23,110.80,0.690
17.25,110.96,0.692
17.27,111.10,0.694
17.28,111.25,0.696
17.29,111.40,0.697
17.31,111.55,0.699
17.33,111.70,0.700
17.34,111.85,0.701
17.36,112.00,0.703
17.37,112.15,0.704
17.38,112.30,0.705
17.40,112.45,0.706
17.42,112.60,0.708
17.43,112.75,0.709
17.44,112.90,0.710
17.46,113.05,0.710
17.48,113.20,0.712
17.49,113.35,0.712
17.51,113.50,0.712
17.52,113.65,0.712
17.53,113.80,0.712
17.55,113.95,0.713
17.57,114.10,0.713
17.58,114.25,0.713
17.59,114.40,0.713
17.61,114.55,0.713
17.63,114.70,0.713
17.64,114.85,0.713
17.66,115.00,0.713
17.67,115.15,0.714
17.68,115.30,0.714
17.70,115.45,0.714
17.72,115.60,0.714
17.73,115.75,0.714
17.74,115.90,0.714
17.76,116.05,0.713
17.78,116.20,0.713
17.79,116.35,0.713
17.81,116.50,0.713
17.82,116.65,0.713
17.83,116.80,0.713
17.85,116.95,0.712
17.87,117.10,0.712
17.88,117.26,0.712
17.89,117.41,0.712
17.91,117.56,0.711
17.93,117.71,0.711
17.94,117.86,0.710
17.96,118.01,0.710
17.97,118.16,0.708
17.98,118.31,0.708
18.00,118.46,0.706
18.02,118.61,0.705
18.03,118.76,0.703
18.04,118.91,0.701
18.06,119.06,0.699
18.08,119.21,0.693
18.09,119.37,0.691
18.11,119.52,0.687
18.12,119.67,0.686
18.13,119.82,0.682
18.15,119.97,0.679
18.17,120.12,0.675
18.18,120.27,0.672
18.19,120.42,0.667
18.21,120.58,0.663
18.23,120.73,0.657
18.24,120.88,0.652
18.26,121.03,0.646
18.27,121.18,0.642
18.28,121.33,0.635
18.30,121.49,0.631
18.32,121.64,0.623
18.33,121.79,0.617
18.34,121.94,0.611
18.36,122.10,0.603
18.38,122.25,0.598
18.39,122.40,0.590
18.41,122.55,0.583
18.42,122.71,0.576
18.43,122.86,0.568
18.45,123.01,0.561
18.47,123.16,0.555
18.48,123.32,0.547
18.49,123.47,0.541
18.51,123.62,0.536
18.53,123.78,0.528
18.54,123.93,0.524
18.56,124.08,0.517
18.57,124.23,0.512
18.58,124.39,0.506
18.60,124.54,0.500
18.62,124.69,0.494
18.63,124.84,0.488
18.64,125.00,0.483
18.66,125.15,0.478
18.68,125.30,0.473
18.69,125.45,0.469
18.71,125.60,0.465
18.72,125.76,0.459
18.73,125.91,0.455
18.75,126.06,0.447
18.77,126.21,0.443
18.78,126.36,0.435
18.79,126.52,0.431
18.81,126.67,0.426
18.83,126.82,0.421
18.84,126.97,0.418
18.86,127.13,0.412
18.87,127.28,0.408
18.88,127.43,0.403
18.90,127.58,0.398
18.92,127.73,0.394
18.93,127.88,0.389
18.94,128.04,0.384
18.96,128.19,0.380
18.98,128.34,0.376
18.99,128.49,0.373
19.01,128.64,0.369
19.02,128.80,0.366
19.03,128.95,0.360
19.05,129.10,0.357
19.07,129.25,0.354
19.08,129.40,0.350
19.09,129.55,0.350
19.11,129.70,0.348
19.13,129.85,0.346
19.14,130.01,0.346
19.16,130.16,0.345
19.17,130.31,0.345
19.18,130.46,0.345
19.20,130.61,0.344
19.22,130.76,0.344
19.23,130.91,0.344
19.24,131.06,0.343
19.26,131.21,0.343
19.28,131.36,0.343
19.29,131.51,0.343
19.31,131.66,0.342
19.32,131.81,0.342
19.33,131.96,0.342
19.35,132.11,0.342
19.37,132.26,0.342
19.38,132.41,0.342
19.39,132.57,0.341
19.41,132.71,0.341
19.43,132.87,0.341
19.44,133.02,0.341
19.46,133.17,0.341
19.47,133.32,0.341
19.48,133.47,0.341
19.50,133.62,0.341
19.52,133.77,0.341
19.53,133.92,0.341
19.54,134.07,0.340
19.56,134.22,0.340
19.58,134.37,0.340
19.59,134.52,0.340
19.61,134.67,0.340
19.62,134.82,0.340
19.63,134.97,0.340
19.65,135.12,0.340
19.67,135.27,0.340
19.68,135.42,0.340
19.69,135.57,0.340
19.71,135.72,0.340
19.73,135.87,0.340
19.74,136.02,0.340
19.76,136.17,0.340
19.77,136.32,0.340
19.78,136.47,0.340
19.80,136.62,0.340
19.82,136.77,0.340
19.83,136.92,0.340
19.84,137.07,0.340
19.86,137.22,0.340
19.88,137.37,0.340
19.89,137.52,0.340
19.91,137.67,0.340
19.92,137.82,0.341
19.93,137.97,0.341
19.95,138.12,0.341
19.97,138.27,0.341
19.98,138.42,0.341
19.99,138.57,0.341
20.01,138.72,0.341
20.03,138.87,0.341
20.04,139.02,0.341
20.06,139.17,0.341
20.07,139.32,0.341
20.08,139.47,0.341
20.10,139.62,0.341
20.12,139.77,0.341
20.13,139.92,0.341
20.14,140.07,0.341
20.16,140.22,0.341
20.18,140.37,0.341
20.19,140.52,0.342
20.21,140.67,0.342
20.22,140.82,0.342
20.23,140.97,0.342
20.25,141.12,0.342
20.27,141.27,0.342
20.28,141.42,0.342
20.29,141.57,0.342
20.31,141.72,0.342
20.33,141.87,0.342
20.34,142.02,0.342
20.36,142.18,0.342
20.37,142.32,0.342
20.38,142.47,0.343
20.40,142.62,0.343
20.42,142.77,0.343
20.43,142.93,0.343
20.44,143.08,0.343
20.46,143.23,0.343
20.48,143.37,0.343
20.49,143.53,0.343
20.51,143.67,0.343
20.52,143.82,0.343
20.53,143.97,0.344
20.55,144.12,0.344
20.57,144.28,0.344
20.58,144.43,0.344
20.59,144.58,0.344
20.61,144.72,0.344
20.63,144.88,0.344
20.64,145.03,0.344
20.66,145.18,0.344
20.67,145.33,0.344
20.68,145.48,0.344
20.70,145.63,0.345
20.72,145.78,0.345
20.73,145.93,0.345
20.74,146.08,0.345
20.76,146.23,0.345
20.78,146.38,0.345
20.79,146.53,0.345
20.81,146.68,0.345
20.82,146.83,0.345
20.83,146.98,0.345
20.85,147.13,0.345
20.87,147.28,0.345
20.88,147.43,0.345
20.89,147.58,0.346
20.91,147.73,0.346
20.93,147.88,0.346
20.94,148.03,
20.96,148.18,
20.97,148.33,
20.98,,
20.99,,

[step]
Ramp 10.00 °C/min to -60.00 °C
Time,Temperature,Heat Flow (Normalized)
min,°C,W/g
22.99,150.13,-0.055
23.01,150.12,-0.055
23.02,150.12,-0.055
23.04,150.12,-0.055
23.05,150.10,-0.055
23.07,150.08,-0.055
23.08,150.05,-0.064
23.10,150.00,-0.084
23.11,149.94,-0.110
23.13,149.86,-0.142
23.14,149.77,-0.176
23.16,149.67,-0.210
23.17,149.57,-0.244
23.19,149.46,-0.272
23.20,149.35,-0.297
23.22,149.23,-0.317
23.23,149.10,-0.336
23.25,148.98,-0.351
23.26,148.85,-0.364
23.28,148.71,-0.376
23.29,148.58,-0.386
23.31,148.44,-0.396
23.32,148.31,-0.402
23.34,148.17,-0.411
23.35,148.03,-0.416
23.37,147.89,-0.422
23.38,147.75,-0.425
23.40,147.60,-0.429
23.41,147.46,-0.434
23.43,147.31,-0.435
23.44,147.17,-0.438
23.46,147.02,-0.440
23.47,146.88,-0.442
23.49,146.73,-0.443
23.50,146.58,-0.444
23.52,146.44,-0.445
23.53,146.29,-0.446
23.55,146.15,-0.447
23.56,146.00,-0.447
23.58,145.85,-0.448
23.59,145.70,-0.448
23.61,145.56,-0.449
23.62,145.41,-0.449
23.64,145.26,-0.450
23.65,145.11,-0.450
23.67,144.96,-0.450
23.68,144.82,-0.450
23.70,144.67,-0.450
23.71,144.52,-0.450
23.73,144.37,-0.451
23.74,144.22,-0.451
23.76,144.07,-0.451
23.77,143.92,-0.451
23.79,143.77,-0.451
23.80,143.63,-0.451
23.82,143.48,-0.451
23.83,143.33,-0.451
23.85,143.18,-0.451
23.86,143.03,-0.451
23.88,142.88,-0.451
23.89,142.73,-0.451
23.91,142.58,-0.451
23.92,142.44,-0.451
23.94,142.29,-0.451
23.95,142.14,-0.451
23.97,141.99,-0.451
23.98,141.84,-0.451
24.00,141.69,-0.451
24.01,141.54,-0.451
24.03,141.39,-0.451
24.04,141.24,-0.451
24.06,141.09,-0.451
24.07,140.94,-0.451
24.09,140.79,-0.451
24.10,140.64,-0.451
24.12,140.49,-0.451
24.13,140.34,-0.451
24.15,140.20,-0.451
24.16,140.05,-0.451
24.18,139.90,-0.450
24.19,139.75,-0.450
24.21,139.60,-0.450
24.22,139.45,-0.450
24.24,139.30,-0.450
24.25,139.15,-0.450
24.27,139.00,-0.450
24.28,138.85,-0.449
24.30,138.70,-0.449
24.31,138.55,-0.449
24.33,138.40,-0.449
24.34,138.25,-0.449
24.36,138.10,-0.449
24.37,137.95,-0.449
24.39,137.80,-0.448
24.40,137.65,-0.448
24.42,137.50,-0.448
24.43,137.35,-0.448
24.45,137.20,-0.448
24.46,137.05,-0.448
24.48,136.90,-0.448
24.49,136.75,-0.448
24.51,136.60,-0.447
24.52,136.45,-0.447
24.54,136.30,-0.447
24.55,136.15,-0.447
24.57,136.00,-0.447
24.58,135.85,-0.446
24.60,135.70,-0.446
24.61,135.55,-0.446
24.63,135.40,-0.446
24.64,135.25,-0.445
24.66,135.10,-0.445
24.67,134.95,-0.445
24.69,134.80,-0.445
24.70,134.66,-0.445
24.72,134.50,-0.444
24.73,134.36,-0.444
24.75,134.21,-0.444
24.76,134.06,-0.444
24.78,133.91,-0.444
24.79,133.76,-0.443
24.81,133.61,-0.443
24.82,133.46,-0.443
24.84,133.31,-0.443
24.85,133.16,-0.442
24.87,133.01,-0.442
24.88,132.86,-0.442
24.90,132.71,-0.442
24.91,132.56,-0.442
24.93,132.41,-0.441
24.94,132.26,-0.441
24.96,132.11,-0.441
24.97,131.96,-0.441
24.99,131.81,-0.441
25.00,131.66,-0.441
25.02,131.51,-0.440
25.03,131.36,-0.440
25.05,131.21,-0.440
25.06,131.06,-0.440
25.08,130.91,-0.439
25.09,130.76,-0.439
25.11,130.61,-0.439
25.12,130.46,-0.439
25.14,130.31,-0.439
25.15,130.16,-0.438
25.17,130.01,-0.438
25.18,129.86,-0.438
25.20,129.71,-0.438
25.21,129.56,-0.438
25.23,129.41,-0.438
25.24,129.26,-0.437
25.26,129.11,-0.437
25.27,128.96,-0.437
25.29,128.81,-0.437
25.30,128.67,-0.437
25.32,128.52,-0.437
25.33,128.37,-0.436
25.35,128.22,-0.436
25.36,128.07,-0.436
25.38,127.92,-0.436
25.39,127.77,-0.436
25.41,127.62,-0.435
25.42,127.47,-0.435
25.44,127.32,-0.435
25.45,127.17,-0.435
25.47,127.02,-0.435
25.48,126.87,-0.435
25.50,126.72,-0.434
25.51,126.57,-0.434
25.53,126.42,-0.434
25.54,126.27,-0.434
25.56,126.12,-0.434
25.57,125.97,-0.434
25.59,125.82,-0.433
25.60,125.67,-0.433
25.62,125.52,-0.433
25.63,125.37,-0.433
25.65,125.22,-0.433
25.66,125.07,-0.432
25.68,124.92,-0.432
25.69,124.77,-0.432
25.71,124.62,-0.432
25.72,124.47,-0.432
25.74,124.32,-0.432
25.75,124.17,-0.431
25.77,124.02,-0.431
25.78,123.87,-0.431
25.80,123.72,-0.431
25.81,123.57,-0.431
25.83,123.42,-0.431
25.84,123.27,-0.431
25.86,123.12,-0.430
25.87,122.97,-0.430
25.89,122.82,-0.430
25.90,122.67,-0.430
25.92,122.52,-0.429
25.93,122.37,-0.429
25.95,122.22,-0.429
25.96,122.07,-0.429
25.98,121.92,-0.429
25.99,121.77,-0.429
26.01,121.62,-0.428
26.02,121.47,-0.428
26.04,121.32,-0.428
26.05,121.17,-0.428
26.07,121.02,-0.428
26.08,120.87,-0.428
26.10,120.72,-0.427
26.11,120.57,-0.427
26.13,120.42,-0.427
26.14,120.27,-0.427
26.16,120.12,-0.427
26.17,119.97,-0.427
26.19,119.82,-0.427
26.20,119.67,-0.426
26.22,119.52,-0.426
26.23,119.37,-0.426
26.25,119.22,-0.426
26.26,119.07,-0.426
26.28,118.92,-0.425
26.29,118.78,-0.425
26.31,118.62,-0.425
26.32,118.47,-0.425
26.34,118.33,-0.425
26.35,118.17,-0.425
26.37,118.02,-0.424
26.38,117.88,-0.424
26.40,117.73,-0.424
26.41,117.58,-0.424
26.43,117.43,-0.424
26.44,117.28,-0.424
26.46,117.13,-0.424
26.47,116.98,-0.423
26.49,116.83,-0.423
26.50,116.68,-0.423
26.52,116.53,-0.423
26.53,116.38,-0.423
26.55,116.23,-0.422
26.56,116.08,-0.422
26.58,115.93,-0.422
26.59,115.78,-0.422
26.61,115.63,-0.422
26.62,115.48,-0.422
26.64,115.33,-0.421
26.65,115.18,-0.421
26.67,115.03,-0.421
26.68,114.88,-0.421
26.70,114.73,-0.421
26.71,114.58,-0.421
26.73,114.43,-0.421
26.74,114.28,-0.420
26.76,114.13,-0.420
26.77,113.98,-0.420
26.79,113.83,-0.420
26.80,113.68,-0.420
26.82,113.53,-0.420
26.83,113.38,-0.420
26.85,113.23,-0.419
26.86,113.08,-0.419
26.88,112.93,-0.419
26.89,112.78,-0.419
26.91,112.63,-0.419
26.92,112.48,-0.419
26.94,112.33,-0.418
26.95,112.18,-0.418
26.97,112.03,-0.418
26.98,111.88,-0.418
27.00,111.73,-0.418
27.01,111.58,-0.418
27.03,111.43,-0.418
27.04,111.28,-0.417
27.06,111.13,-0.417
27.07,110.98,-0.417
27.09,110.83,-0.417
27.10,110.68,-0.418
27.12,110.53,-0.424
27.13,110.38,-0.433
27.15,110.24,-0.451
27.16,110.09,-0.465
27.18,109.94,-0.485
27.19,109.80,-0.493
27.21,109.65,-0.496
27.22,109.50,-0.499
27.24,109.36,-0.533
27.25,109.21,-0.547
27.27,109.07,-0.551
27.28,108.92,-0.566
27.30,108.78,-0.588
27.31,108.64,-0.607
27.33,108.49,-0.615
27.34,108.35,-0.643
27.36,108.20,-0.650
27.37,108.06,-0.668
27.39,107.92,-0.678
27.40,107.77,-0.714
27.42,107.64,-0.926
27.43,107.52,-1.186
27.45,107.41,-1.310
27.46,107.30,-1.270
27.48,107.17,-1.205
27.49,107.03,-1.142
27.51,106.89,-1.096
27.52,106.74,-1.061
27.54,106.59,-1.039
27.55,106.44,-1.019
27.57,106.28,-0.998
27.58,106.13,-0.982
27.60,105.98,-0.967
27.61,105.82,-0.950
27.63,105.67,-0.935
27.64,105.51,-0.924
27.66,105.36,-0.911
27.67,105.20,-0.897
27.69,105.05,-0.885
27.70,104.89,-0.874
27.72,104.74,-0.863
27.73,104.58,-0.853
27.75,104.43,-0.845
27.76,104.28,-0.837
27.78,104.12,-0.830
27.79,103.97,-0.822
27.81,103.81,-0.814
27.82,103.66,-0.808
27.84,103.51,-0.804
27.85,103.36,-0.797
27.87,103.20,-0.793
27.88,103.05,-0.788
27.90,102.90,-0.796
27.91,102.75,-0.872
27.93,102.61,-0.868
27.94,102.46,-0.885
27.96,102.32,-0.873
27.97,102.17,-0.860
27.99,102.02,-0.842
28.00,101.87,-0.832
28.02,101.71,-0.822
28.03,101.56,-0.814
28.05,101.41,-0.812
28.06,101.26,-0.818
28.08,101.11,-0.825
28.09,100.96,-0.827
28.11,100.81,-0.827
28.12,100.66,-0.824
28.14,100.51,-0.816
28.15,100.36,-0.811
28.17,100.21,-0.809
28.18,100.06,-0.808
28.20,99.91,-0.806
28.21,99.76,-0.806
28.23,99.60,-0.803
28.24,99.46,-0.802
28.26,99.30,-0.802
28.27,99.15,-0.822
28.29,99.01,-0.821
28.30,98.86,-0.819
28.32,98.71,-0.818
28.33,98.56,-0.817
28.35,98.41,-0.814
28.36,98.26,-0.814
28.38,98.11,-0.813
28.39,97.96,-0.805
28.41,97.81,-0.803
28.42,97.66,-0.800
28.44,97.51,-0.797
28.45,97.36,-0.793
28.47,97.20,-0.789
28.48,97.05,-0.784
28.50,96.90,-0.778
28.51,96.75,-0.773
28.53,96.60,-0.771
28.54,96.45,-0.768
28.56,96.30,-0.765
28.57,96.15,-0.761
28.59,96.00,-0.761
28.60,95.85,-0.764
28.62,95.70,-0.766
28.63,95.55,-0.781
28.65,95.40,-0.782
28.66,95.25,-0.781
28.68,95.10,-0.765
28.69,94.95,-0.751
28.71,94.79,-0.744
28.72,94.64,-0.737
28.74,94.49,-0.728
28.75,94.34,-0.723
28.77,94.19,-0.714
28.78,94.03,-0.709
28.80,93.88,-0.703
28.81,93.73,-0.696
28.83,93.58,-0.691
28.84,93.43,-0.687
28.86,93.27,-0.682
28.87,93.12,-0.676
28.89,92.97,-0.672
28.90,92.82,-0.668
28.92,92.67,-0.664
28.93,92.52,-0.659
28.95,92.36,-0.654
28.96,92.21,-0.651
28.98,92.06,-0.648
28.99,91.91,-0.647
29.01,91.76,-0.647
29.02,91.61,-0.647
29.04,91.45,-0.644
29.05,91.30,-0.640
29.07,91.15,-0.634
29.08,91.00,-0.629
29.10,90.85,-0.626
29.11,90.70,-0.622
29.13,90.55,-0.618
29.14,90.40,-0.616
29.16,90.25,-0.612
29.17,90.09,-0.610
29.19,89.94,-0.605
29.20,89.79,-0.603
29.22,89.64,-0.601
29.23,89.49,-0.597
29.25,89.34,-0.595
29.26,89.19,-0.592
29.28,89.04,-0.588
29.29,88.89,-0.586
29.31,88.74,-0.584
29.32,88.58,-0.581
29.34,88.43,-0.579
29.35,88.28,-0.579
29.37,88.13,-0.579
29.38,87.98,-0.580
29.40,87.83,-0.579
29.41,87.68,-0.578
29.43,87.53,-0.576
29.44,87.38,-0.576
29.46,87.23,-0.578
[...]
93.77,-43.97,0.174
93.78,-43.90,0.174
93.78,-43.83,0.174
93.79,-43.77,0.174
93.80,-43.70,0.174
93.80,-43.63,0.174
93.81,-43.57,0.174
93.81,-43.50,0.174
93.82,-43.43,0.174
93.83,-43.37,0.174
93.84,-43.30,0.174
93.84,-43.23,0.174
93.85,-43.17,0.174
93.85,-43.10,0.174
93.86,-43.03,0.174
93.87,-42.97,0.174
93.88,-42.90,0.175
93.88,-42.83,0.175
93.89,-42.77,0.175
93.90,-42.70,0.175
93.90,-42.63,0.175
93.91,-42.57,0.175
93.91,-42.50,0.175
93.92,-42.43,0.175
93.93,-42.37,0.175
93.94,-42.30,0.175
93.94,-42.23,0.175
93.95,-42.17,0.175
93.95,-42.10,0.175
93.96,-42.03,0.175
93.97,-41.97,0.175
93.98,-41.90,0.175
93.98,-41.83,0.175
93.99,-41.77,0.175
94.00,-41.70,0.175
94.00,-41.63,0.175
94.01,-41.57,0.175
94.01,-41.50,0.175
94.02,-41.43,0.175
94.03,-41.37,0.175
94.04,-41.30,0.176
94.04,-41.23,0.176
94.05,-41.17,0.176
94.05,-41.10,0.176
94.06,-41.03,0.176
94.07,-40.97,0.176
94.08,-40.90,0.176
94.08,-40.83,0.176
94.09,-40.77,0.176
94.10,-40.70,0.176
94.10,-40.63,0.176
94.11,-40.56,0.176
94.11,-40.50,0.176
94.12,-40.43,0.176
94.13,-40.37,0.176
94.14,-40.30,0.176
94.14,-40.23,0.176
94.15,-40.16,0.176
94.15,-40.10,0.176
94.16,-40.03,0.176
94.17,-39.97,0.176
94.18,-39.90,0.176
94.18,-39.83,0.176
94.19,-39.76,0.177
94.20,-39.70,0.177
94.20,-39.63,0.177
94.21,-39.56,0.177
94.21,-39.50,0.177
94.22,-39.43,0.177
94.23,-39.36,0.177
94.24,-39.30,0.177
94.24,-39.23,0.177
94.25,-39.16,0.177
94.25,-39.10,0.177
94.26,-39.03,0.177
94.27,-38.96,0.177
94.28,-38.90,0.177
94.28,-38.83,0.177
94.29,-38.76,0.177
94.30,-38.70,0.177
94.30,-38.63,0.177
94.31,-38.56,0.177
94.31,-38.50,0.177
94.32,-38.43,0.177
94.33,-38.36,0.177
94.34,-38.30,0.177
94.34,-38.23,0.177
94.35,-38.16,0.178
94.35,-38.10,0.178
94.36,-38.03,0.178
94.37,-37.96,0.178
94.38,-37.90,0.178
94.38,-37.83,0.178
94.39,-37.76,0.178
94.40,-37.70,0.178
94.40,-37.63,0.178
94.41,-37.56,0.178
94.41,-37.50,0.178
94.42,-37.43,0.178
94.43,-37.36,0.178
94.44,-37.29,0.178
94.44,-37.23,0.178
94.45,-37.16,0.178
94.45,-37.09,0.178
94.46,-37.03,0.178
94.47,-36.96,0.178
94.48,-36.89,0.178
94.48,-36.83,0.178
94.49,-36.76,0.178
94.50,-36.69,0.179
94.50,-36.63,0.179
94.51,-36.56,0.179
94.51,-36.49,0.179
94.52,-36.43,0.179
94.53,-36.36,0.179
94.54,-36.29,0.179
94.54,-36.23,0.179
94.55,-36.16,0.179
94.55,-36.09,0.179
94.56,-36.03,0.179
94.57,-35.96,0.179
94.58,-35.89,0.179
94.58,-35.83,0.179
94.59,-35.76,0.179
94.60,-35.69,0.179
94.60,-35.63,0.179
94.61,-35.56,0.179
94.61,-35.49,0.179
94.62,-35.43,0.179
94.63,-35.36,0.179
94.64,-35.29,0.179
94.64,-35.23,0.180
94.65,-35.16,0.180
94.65,-35.09,0.180
94.66,-35.03,0.180
94.67,-34.96,0.180
94.68,-34.89,0.180
94.68,-34.83,0.180
94.69,-34.76,0.180
94.70,-34.69,0.180
94.70,-34.62,0.180
94.71,-34.56,0.180
94.71,-34.49,0.180
94.72,-34.42,0.180
94.73,-34.36,0.180
94.74,-34.29,0.180
94.74,-34.22,0.180
94.75,-34.16,0.180
94.75,-34.09,0.180
94.76,-34.02,0.180
94.77,-33.96,0.180
94.78,-33.89,0.181
94.78,-33.82,0.181
94.79,-33.76,0.181
94.80,-33.69,0.181
94.80,-33.62,0.181
94.81,-33.56,0.181
94.81,-33.49,0.181
94.82,-33.42,0.181
94.83,-33.36,0.181
94.84,-33.29,0.181
94.84,-33.22,0.181
94.85,-33.16,0.181
94.85,-33.09,0.181
94.86,-33.02,0.181
94.87,-32.96,0.181
94.88,-32.89,0.181
94.88,-32.82,0.181
94.89,-32.75,0.181
94.90,-32.69,0.182
94.90,-32.62,0.182
94.91,-32.56,0.182
94.91,-32.49,0.182
94.92,-32.42,0.182
94.93,-32.35,0.182
94.94,-32.29,0.182
94.94,-32.22,0.182
94.95,-32.15,0.182
94.95,-32.09,0.182
94.96,-32.02,0.182
94.97,-31.95,0.182
94.98,-31.89,0.182
94.98,-31.82,0.182
94.99,-31.75,0.182
95.00,-31.69,0.182
95.00,-31.62,0.182
95.01,-31.55,0.183
95.01,-31.49,0.183
95.02,-31.42,0.183
95.03,-31.35,0.183
95.04,-31.29,0.183
95.04,-31.22,0.183
95.05,-31.15,0.183
95.05,-31.09,0.183
95.06,-31.02,0.183
95.07,-30.95,0.183
95.08,-30.89,0.183
95.08,-30.82,0.183
95.09,-30.75,0.183
95.10,-30.69,0.184
95.10,-30.62,0.184
95.11,-30.55,0.184
95.11,-30.49,0.184
95.12,-30.42,0.184
95.13,-30.35,0.184
95.14,-30.29,0.184
95.14,-30.22,0.184
95.15,-30.15,0.184
95.15,-30.09,0.184
95.16,-30.02,0.184
95.17,-29.95,0.184
95.18,-29.89,0.184
95.18,-29.82,0.184
95.19,-29.75,0.184
95.20,-29.69,0.185
95.20,-29.62,0.185
95.21,-29.55,0.185
95.21,-29.49,0.185
95.22,-29.42,0.185
95.23,-29.35,0.185
95.24,-29.28,0.185
95.24,-29.22,0.185
95.25,-29.15,0.185
95.25,-29.08,0.185
95.26,-29.02,0.185
95.27,-28.95,0.185
95.28,-28.88,0.186
95.28,-28.82,0.186
95.29,-28.75,0.186
95.30,-28.68,0.186
95.30,-28.62,0.186
95.31,-28.55,0.186
95.31,-28.48,0.186
95.32,-28.42,0.186
95.33,-28.35,0.186
95.34,-28.28,0.186
95.34,-28.22,0.187
95.35,-28.15,0.187
95.35,-28.08,0.187
95.36,-28.02,0.187
95.37,-27.95,0.187
95.38,-27.88,0.187
95.38,-27.82,0.187
95.39,-27.75,0.187
95.40,-27.68,0.187
95.40,-27.62,0.187
95.41,-27.55,0.188
95.41,-27.48,0.188
95.42,-27.42,0.188
95.43,-27.35,0.188
95.44,-27.28,0.188
95.44,-27.22,0.188
95.45,-27.15,0.188
95.45,-27.08,0.189
95.46,-27.02,0.189
95.47,-26.95,0.189
95.48,-26.88,0.189
95.48,-26.82,0.189
95.49,-26.75,0.189
95.50,-26.68,0.189
95.50,-26.62,0.190
95.51,-26.55,0.190
95.51,-26.48,0.190
95.52,-26.42,0.190
95.53,-26.35,0.190
95.54,-26.28,0.190
95.54,-26.22,0.191
95.55,-26.15,0.191
95.55,-26.08,0.191
95.56,-26.02,0.191
95.57,-25.95,0.191
95.58,-25.88,0.191
95.58,-25.82,0.191
95.59,-25.75,0.191
95.60,-25.68,0.192
95.60,-25.61,0.192
95.61,-25.55,0.192
95.61,-25.48,0.192
95.62,-25.41,0.192
95.63,-25.35,0.192
95.64,-25.28,0.192
95.64,-25.22,0.193
95.65,-25.15,0.193
95.65,-25.08,0.193
95.66,-25.02,0.193
95.67,-24.95,0.194
95.68,-24.88,0.194
95.68,-24.81,0.194
95.69,-24.75,0.194
95.70,-24.68,0.194
95.70,-24.62,0.194
95.71,-24.55,0.194
95.71,-24.48,0.195
95.72,-24.42,0.195
95.73,-24.35,0.195
95.74,-24.28,0.195
95.74,-24.22,0.195
95.75,-24.15,0.196
95.75,-24.08,0.196
95.76,-24.02,0.196
95.77,-23.95,0.196
95.78,-23.88,0.197
95.78,-23.82,0.197
95.79,-23.75,0.197
95.80,-23.68,0.197
95.80,-23.62,0.197
95.81,-23.55,0.197
95.81,-23.48,0.198
95.82,-23.41,0.198
95.83,-23.35,0.198
95.84,-23.28,0.198
95.84,-23.22,0.199
95.85,-23.15,0.199
95.85,-23.08,0.199
95.86,-23.02,0.199
95.87,-22.95,0.200
95.88,-22.88,0.200
95.88,-22.82,0.201
95.89,-22.75,0.201
95.90,-22.68,0.201
95.90,-22.62,0.201
95.91,-22.55,0.202
95.91,-22.48,0.203
95.92,-22.42,0.203
95.93,-22.35,0.203
95.94,-22.28,0.203
95.94,-22.22,0.203
95.95,-22.15,0.203
95.95,-22.08,0.204
95.96,-22.02,0.205
95.97,-21.95,0.205
95.98,-21.88,0.205
95.98,-21.82,0.205
95.99,-21.75,0.205
96.00,-21.68,0.206
96.00,-21.62,0.206
96.01,-21.55,0.206
96.01,-21.48,0.207
96.02,-21.42,0.207
96.03,-21.35,0.207
96.04,-21.28,0.207
96.04,-21.22,0.207
96.05,-21.15,0.208
96.05,-21.08,0.208
96.06,-21.02,0.208
96.07,-20.95,0.209
96.08,-20.88,0.209
96.08,-20.82,0.209
96.09,-20.75,0.209
96.10,-20.68,0.209
96.10,-20.62,0.210
96.11,-20.55,0.211
96.11,-20.48,0.211
96.12,-20.42,0.212
96.13,-20.35,0.212
96.14,-20.28,0.212
96.14,-20.22,0.212
96.15,-20.15,0.213
96.15,-20.08,0.213
96.16,-20.02,0.213
96.17,-19.95,0.213
96.18,-19.89,0.214
96.18,-19.82,0.214
96.19,-19.75,0.214
96.20,-19.69,0.215
96.20,-19.62,0.215
96.21,-19.55,0.215
96.21,-19.49,0.215
96.22,-19.42,0.216
96.23,-19.35,0.216
96.24,-19.29,0.216
96.24,-19.22,0.216
96.25,-19.15,0.217
96.25,-19.09,0.217
96.26,-19.02,0.217
96.27,-18.95,0.217
96.28,-18.89,0.218
96.28,-18.82,0.218
96.29,-18.75,0.218
96.30,-18.69,0.219
96.30,-18.62,0.219
96.31,-18.55,0.219
96.31,-18.49,0.219
96.32,-18.42,0.220
96.33,-18.35,0.220
96.34,-18.29,0.221
96.34,-18.22,0.221
96.35,-18.15,0.221
96.35,-18.09,0.221
96.36,-18.02,0.221
96.37,-17.95,0.222
96.38,-17.89,0.222
96.38,-17.82,0.222
96.39,-17.75,0.223
96.40,-17.69,0.223
96.40,-17.62,0.223
96.41,-17.55,0.223
96.41,-17.49,0.224
96.42,-17.42,0.224
96.43,-17.35,0.225
96.44,-17.29,0.225
96.44,-17.22,0.225
96.45,-17.15,0.225
96.45,-17.09,0.225
96.46,-17.02,0.226
96.47,-16.95,0.226
96.48,-16.89,0.226
96.48,-16.82,0.226
96.49,-16.75,0.227
96.50,-16.69,0.227
96.50,-16.62,0.227
96.51,-16.55,0.227
96.51,-16.49,0.227
96.52,-16.42,0.227
96.53,-16.35,0.228
96.54,-16.29,0.228
96.54,-16.22,0.228
96.55,-16.15,0.228
96.55,-16.09,0.229
96.56,-16.02,0.229
96.57,-15.95,0.229
96.58,-15.89,0.229
96.58,-15.82,0.229
96.59,-15.75,0.230
96.60,-15.69,0.230
96.60,-15.62,0.230
96.61,-15.55,0.230
96.61,-15.49,0.231
96.62,-15.42,0.231
96.63,-15.35,0.231
96.64,-15.29,0.231
96.64,-15.22,0.231
96.65,-15.15,0.231
96.65,-15.09,0.231
96.66,-15.02,0.232
96.67,-14.95,0.232
96.68,-14.89,0.232
96.68,-14.82,0.232
96.69,-14.75,0.232
96.70,-14.69,0.233
96.70,-14.62,0.233
96.71,-14.55,0.233
96.71,-14.49,0.233
96.72,-14.42,0.233
96.73,-14.35,0.233
96.74,-14.29,0.233
96.74,-14.22,0.234
96.75,-14.15,0.234
96.75,-14.09,0.234
96.76,-14.02,0.234
96.77,-13.95,0.234
96.78,-13.89,0.234
96.78,-13.82,0.234
96.79,-13.75,0.235
96.80,-13.69,0.235
96.80,-13.62,0.235
96.81,-13.55,0.235
96.81,-13.48,0.235
96.82,-13.42,0.235
96.83,-13.35,0.235
96.84,-13.29,0.235
96.84,-13.22,0.236
96.85,-13.15,0.236
96.85,-13.09,0.236
96.86,-13.02,0.236
96.87,-12.95,0.236
96.88,-12.88,0.236
96.88,-12.82,0.236
96.89,-12.75,0.236
96.90,-12.68,0.236
96.90,-12.62,0.236
96.91,-12.55,0.237
96.91,-12.48,0.237
96.92,-12.42,0.237
96.93,-12.35,0.237
96.94,-12.28,0.237
96.94,-12.22,0.237
96.95,-12.15,0.237
96.95,-12.08,0.237
96.96,-12.02,0.237
96.97,-11.95,0.237
96.98,-11.88,0.237
96.98,-11.82,0.237
96.99,-11.75,0.238
97.00,-11.68,0.238
97.00,-11.62,0.238
97.01,-11.55,0.238
97.01,-11.48,0.238
97.02,-11.42,0.238
97.03,-11.35,0.238
97.04,-11.28,0.238
97.04,-11.22,0.238
97.05,-11.15,0.238
97.05,-11.08,0.238
97.06,-11.02,0.238
97.07,-10.95,0.238
97.08,-10.88,0.238
97.08,-10.81,0.238
97.09,-10.75,0.238
97.10,-10.68,0.239
97.10,-10.62,0.239
97.11,-10.55,0.239
97.11,-10.48,0.239
97.12,-10.42,0.239
97.13,-10.35,0.239
97.14,-10.28,0.239
97.14,-10.21,0.239
97.15,-10.15,0.239
97.15,-10.08,0.239
97.16,-10.01,0.239
97.17,-9.95,0.239
97.18,-9.88,0.239
97.18,-9.82,0.239
97.19,-9.75,0.239
97.20,-9.68,0.239
97.20,-9.61,0.239
97.21,-9.55,0.239
97.21,-9.48,0.239
97.22,-9.41,0.239
97.23,-9.35,0.239
97.24,-9.28,0.239
97.24,-9.21,0.239
97.25,-9.15,0.239
97.25,-9.08,0.239
97.26,-9.01,0.239
97.27,-8.95,0.239
97.28,-8.88,0.239
97.28,-8.81,0.239
97.29,-8.75,0.239
97.30,-8.68,0.239
97.30,-8.61,0.239
97.31,-8.55,0.239
97.31,-8.48,0.239
97.32,-8.41,0.239
97.33,-8.35,0.239
97.34,-8.28,0.239
97.34,-8.21,0.239
97.35,-8.15,0.239
97.35,-8.08,0.239
97.36,-8.01,0.239
97.37,-7.95,0.239
97.38,-7.88,0.239
97.38,-7.81,0.239
97.39,-7.75,0.239
97.40,-7.68,0.239
97.40,-7.61,0.239
97.41,-7.54,0.239
97.41,-7.48,0.239
97.42,-7.41,0.239
97.43,-7.34,0.239
97.44,-7.28,0.239
97.44,-7.21,0.239
97.45,-7.14,0.239
97.45,-7.08,0.239
97.46,-7.01,0.239
97.47,-6.94,0.239
97.48,-6.88,0.239
97.48,-6.81,0.239
97.49,-6.74,0.239
97.50,-6.68,0.239
97.50,-6.61,0.240
97.51,-6.54,0.240
97.51,-6.48,0.240
97.52,-6.41,0.240
97.53,-6.34,0.240
97.54,-6.28,0.240
97.54,-6.21,0.240
97.55,-6.14,0.240
97.55,-6.07,0.240
97.56,-6.01,0.240
97.57,-5.94,0.240
97.58,-5.88,0.240
97.58,-5.81,0.240
97.59,-5.74,0.240
97.60,-5.68,0.240
97.60,-5.61,0.240
97.61,-5.54,0.240
97.61,-5.48,0.240
97.62,-5.41,0.240
97.63,-5.34,0.240
97.64,-5.27,0.240
97.64,-5.21,0.240
97.65,-5.14,0.240
97.65,-5.07,0.240
97.66,-5.01,0.240
97.67,-4.94,0.240
97.68,-4.87,0.240
97.68,-4.81,0.240
97.69,-4.74,0.240
97.70,-4.67,0.240
97.70,-4.61,0.240
97.71,-4.54,0.240
97.71,-4.47,0.240
97.72,-4.41,0.240
97.73,-4.34,0.240
97.74,-4.27,0.240
97.74,-4.21,0.240
97.75,-4.14,0.240
97.75,-4.07,0.240
97.76,-4.01,0.240
97.77,-3.94,0.240
97.78,-3.87,0.240
97.78,-3.80,0.240
97.79,-3.74,0.240
97.80,-3.67,0.240
97.80,-3.60,0.240
97.81,-3.54,0.240
97.81,-3.47,0.240
97.82,-3.41,0.240
97.83,-3.34,0.240
97.84,-3.27,0.240
97.84,-3.21,0.240
97.85,-3.14,0.240
97.85,-3.07,0.240
97.86,-3.01,0.240
97.87,-2.94,0.240
97.88,-2.87,0.240
97.88,-2.81,0.240
97.89,-2.74,0.240
97.90,-2.67,0.240
97.90,-2.61,0.240
97.91,-2.54,0.240
97.91,-2.47,0.240
97.92,-2.40,0.240
97.93,-2.34,0.240
97.94,-2.27,0.240
97.94,-2.20,0.240
97.95,-2.14,0.241
97.95,-2.07,0.241
97.96,-2.00,0.241
97.97,-1.94,0.241
97.98,-1.87,0.241
97.98,-1.80,0.241
97.99,-1.74,0.241
98.00,-1.67,0.241
98.00,-1.60,0.241
98.01,-1.54,0.241
98.01,-1.47,0.241
98.02,-1.40,0.241
98.03,-1.34,0.241
98.04,-1.27,0.241
98.04,-1.20,0.241
98.05,-1.14,0.241
98.05,-1.07,0.241
98.06,-1.00,0.241
98.07,-0.93,0.241
98.08,-0.87,0.241
98.08,-0.80,0.241
98.09,-0.73,0.241
98.10,-0.67,0.241
98.10,-0.60,0.241
98.11,-0.53,0.241
98.11,-0.47,0.241
98.12,-0.40,0.241
98.13,-0.33,0.241
98.14,-0.27,0.241
98.14,-0.20,0.241
98.15,-0.13,0.242
98.15,-0.06,0.242
98.16,0.00,0.242
98.17,0.07,0.242
98.18,0.13,0.242
98.18,0.20,0.242
98.19,0.27,0.242
98.20,0.34,0.242
98.20,0.40,0.242
98.21,0.47,0.242
98.21,0.54,0.242
98.22,0.60,0.242
98.23,0.67,0.242
98.24,0.74,0.242
98.24,0.80,0.242
98.25,0.87,0.242
98.25,0.94,0.242
98.26,1.00,0.242
98.27,1.07,0.242
98.28,1.14,0.242
98.28,1.20,0.242
98.29,1.27,0.242
98.30,1.34,0.242
98.30,1.40,0.242
98.31,1.47,0.242
98.31,1.54,0.242
98.32,1.61,0.242
98.33,1.67,0.243
98.34,1.74,0.243
98.34,1.81,0.243
98.35,1.87,0.243
98.35,1.94,0.243
98.36,2.00,0.243
98.37,2.07,0.243
98.38,2.14,0.243
98.38,2.21,0.243
98.39,2.27,0.243
98.40,2.34,0.243
98.40,2.41,0.243
98.41,2.47,0.243
98.41,2.54,0.243
98.42,2.61,0.243
98.43,2.67,0.243
98.44,2.74,0.243
98.44,2.81,0.243
98.45,2.87,0.243
98.45,2.94,0.243
98.46,3.01,0.243
98.47,3.07,0.243
98.48,3.14,0.243
98.48,3.21,0.243
98.49,3.27,0.243
98.50,3.34,0.243
98.50,3.41,0.243
98.51,3.47,0.243
98.51,3.54,0.243
98.52,3.61,0.244
98.53,3.67,0.244
98.54,3.74,0.244
98.54,3.81,0.244
98.55,3.87,0.244
98.55,3.94,0.244
98.56,4.01,0.244
98.57,4.07,0.244
98.58,4.14,0.244
98.58,4.21,0.244
98.59,4.28,0.244
98.60,4.34,0.244
98.60,4.41,0.244
98.61,4.47,0.244
98.61,4.54,0.244
98.62,4.61,0.244
98.63,4.67,0.244
98.64,4.74,0.244
98.64,4.81,0.244
98.65,4.88,0.244
98.65,4.94,0.244
98.66,5.01,0.244
98.67,5.07,0.244
98.68,5.14,0.244
98.68,5.21,0.244
98.69,5.27,0.244
98.70,5.34,0.244
98.70,5.41,0.244
98.71,5.47,0.244
98.71,5.54,0.244
98.72,5.61,0.244
98.73,5.67,0.244
98.74,5.74,0.245
98.74,5.81,0.245
98.75,5.88,0.245
98.75,5.94,0.245
98.76,6.01,0.245
98.77,6.07,0.245
98.78,6.14,0.245
98.78,6.21,0.245
98.79,6.28,0.245
98.80,6.34,0.245
98.80,6.41,0.245
98.81,6.48,0.245
98.81,6.54,0.245
98.82,6.61,0.245
98.83,6.68,0.245
98.84,6.74,0.245
98.84,6.81,0.245
98.85,6.88,0.245
98.85,6.94,0.245
98.86,7.01,0.245
98.87,7.08,0.245
98.88,7.14,0.245
98.88,7.21,0.245
98.89,7.28,0.245
98.90,7.34,0.246
98.90,7.41,0.246
98.91,7.48,0.246
98.91,7.54,0.246
98.92,7.61,0.246
98.93,7.68,0.246
98.94,7.74,0.246
98.94,7.81,0.246
98.95,7.88,0.246
98.95,7.94,0.246
98.96,8.01,0.246
98.97,8.08,0.246
98.98,8.15,0.246
98.98,8.21,0.246
98.99,8.28,0.246
99.00,8.35,0.246
99.00,8.41,0.246
99.01,8.48,0.246
99.01,8.55,0.246
99.02,8.61,0.246
99.03,8.68,0.246
99.04,8.75,0.246
99.04,8.81,0.246
99.05,8.88,0.246
99.05,8.95,0.246
99.06,9.01,0.246
99.07,9.08,0.246
99.08,9.15,0.247
99.08,9.21,0.247
99.09,9.28,0.247
99.10,9.35,0.247
99.10,9.41,0.247
99.11,9.48,0.247
99.11,9.55,0.247
99.12,9.61,0.247
99.13,9.68,0.247
99.14,9.75,0.247
99.14,9.81,0.247
99.15,9.88,0.247
99.15,9.95,0.247
99.16,10.01,0.247
99.17,10.08,0.247
99.18,10.15,0.247
99.18,10.22,0.247
99.19,10.28,0.247
99.20,10.35,0.247
99.20,10.41,0.247
99.21,10.48,0.247
99.21,10.55,0.247
99.22,10.62,0.247
99.23,10.68,0.247
99.24,10.75,0.247
99.24,10.81,0.247
99.25,10.88,0.247
99.25,10.95,0.247
99.26,11.02,0.247
99.27,11.08,0.247
99.28,11.15,0.247
99.28,11.22,0.247
99.29,11.28,0.247
99.30,11.35,0.247
99.30,11.42,0.247
99.31,11.48,0.247
99.31,11.55,0.247
99.32,11.62,0.248
99.33,11.68,0.248
99.34,11.75,0.248
99.34,11.82,0.248
99.35,11.88,0.248
99.35,11.95,0.248
99.36,12.02,0.248
99.37,12.08,0.248
99.38,12.15,0.248
99.38,12.22,0.248
99.39,12.29,0.248
99.40,12.35,0.248
99.40,12.42,0.248
99.41,12.49,0.248
99.41,12.55,0.248
99.42,12.62,0.248
99.43,12.69,0.248
99.44,12.75,0.248
99.44,12.82,0.248
99.45,12.89,0.248
99.45,12.95,0.248
99.46,13.02,0.248
99.47,13.09,0.248
99.48,13.15,0.248
99.48,13.22,0.248
99.49,13.29,0.248
99.50,13.35,0.248
99.50,13.42,0.248
99.51,13.49,0.248
99.51,13.55,0.248
99.52,13.62,0.248
99.53,13.69,0.248
99.54,13.75,0.248
99.54,13.82,0.248
99.55,13.89,0.248
99.55,13.95,0.248
99.56,14.02,0.248
99.57,14.09,0.248
99.58,14.15,0.248
99.58,14.22,0.248
99.59,14.29,0.248
99.60,14.36,0.248
99.60,14.42,0.248
99.61,14.49,0.248
99.61,14.55,0.248
99.62,14.62,0.248
99.63,14.69,0.248
99.64,14.75,0.248
99.64,14.82,0.248
99.65,14.89,0.248
99.65,14.96,0.248
99.66,15.02,0.248
99.67,15.09,0.248
99.68,15.15,0.248
99.68,15.22,0.248
99.69,15.29,0.248
99.70,15.36,0.248
99.70,15.42,0.248
99.71,15.49,0.248
99.71,15.56,0.248
99.72,15.62,0.248
99.73,15.69,0.248
99.74,15.76,0.248
99.74,15.82,0.248
99.75,15.89,0.248
99.75,15.96,0.248
99.76,16.02,0.248
99.77,16.09,0.248
99.78,16.16,0.248
99.78,16.22,0.248
99.79,16.29,0.248
99.80,16.36,0.248
99.80,16.42,0.248
99.81,16.49,0.248
99.81,16.56,0.248
99.82,16.62,0.248
99.83,16.69,0.248
99.84,16.76,0.248
99.84,16.82,0.248
99.85,16.89,0.248
99.85,16.96,0.248
99.86,17.03,0.248
99.87,17.09,0.248
99.88,17.16,0.248
99.88,17.22,0.248
99.89,17.29,0.248
99.90,17.36,0.248
99.90,17.43,0.248
99.91,17.49,0.248
99.91,17.56,0.248
99.92,17.63,0.248
99.93,17.69,0.248
99.94,17.76,0.248
99.94,17.83,0.248
99.95,17.89,0.248
99.95,17.96,0.248
99.96,18.03,0.248
99.97,18.09,0.248
99.98,18.16,0.248
99.98,18.23,0.248
99.99,18.29,0.248
100.00,18.36,0.248
100.00,18.43,0.248
100.01,18.49,0.248
100.01,18.56,0.248
100.02,18.63,0.248
100.03,18.69,0.248
100.04,18.76,0.248
100.04,18.83,0.248
100.05,18.89,0.248
100.05,18.96,0.248
100.06,19.03,0.248
100.07,19.09,0.248
100.08,19.16,0.248
100.08,19.23,0.248
100.09,19.29,0.248
100.10,19.36,0.248
100.10,19.43,0.248
100.11,19.49,0.248
100.11,19.56,0.248
100.12,19.63,0.248
100.13,19.69,0.248
100.14,19.76,0.247
100.14,19.83,0.247
100.15,19.90,0.247
100.15,19.96,0.247
100.16,20.03,0.247
100.17,20.10,0.247
100.18,20.16,0.247
100.18,20.23,0.247
100.19,20.30,0.247
100.20,20.36,0.247
100.20,20.43,0.247
100.21,20.50,0.247
100.21,20.56,0.247
100.22,20.63,0.247
100.23,20.70,0.247
100.24,20.76,0.247
100.24,20.83,0.247
100.25,20.90,0.247
100.25,20.96,0.247
100.26,21.03,0.247
100.27,21.10,0.247
100.28,21.16,0.247
100.28,21.23,0.247
100.29,21.30,0.247
100.30,21.37,0.247
100.30,21.43,0.247
100.31,21.50,0.247
100.31,21.56,0.247
100.32,21.63,0.247
100.33,21.70,0.247
100.34,21.77,0.247
100.34,21.83,0.247
100.35,21.90,0.247
100.35,21.97,0.247
100.36,22.03,0.247
100.37,22.10,0.247
100.38,22.17,0.247
100.38,22.23,0.247
100.39,22.30,0.247
100.40,22.37,0.247
100.40,22.43,0.247
100.41,22.50,0.247
100.41,22.57,0.247
100.42,22.63,0.246
100.43,22.70,0.246
100.44,22.77,0.246
100.44,22.83,0.246
100.45,22.90,0.246
100.45,22.97,0.246
100.46,23.03,0.246
100.47,23.10,0.246
100.48,23.17,0.246
100.48,23.23,0.246
100.49,23.30,0.246
100.50,23.37,0.246
100.50,23.43,0.246
100.51,23.50,0.246
100.51,23.57,0.246
100.52,23.63,0.246
100.53,23.70,0.246
100.54,23.77,0.246
100.54,23.83,0.246
100.55,23.90,0.246
100.55,23.97,0.246
100.56,24.04,0.246
100.57,24.10,0.246
100.58,24.17,0.246
100.58,24.23,0.246
100.59,24.30,0.246
100.60,24.37,0.246
100.60,24.43,0.246
100.61,24.50,0.246
100.61,24.57,0.246
100.62,24.64,0.245
100.63,24.70,0.245
100.64,24.77,0.245
100.64,24.83,0.245
100.65,24.90,0.245
100.65,24.97,0.245
100.66,25.03,0.245
100.67,25.10,0.245
100.68,25.17,0.245
100.68,25.24,0.245
100.69,25.30,0.245
100.70,25.37,0.245
100.70,25.44,0.245
100.71,25.50,0.245
100.71,25.57,0.245
100.72,25.64,0.245
100.73,25.70,0.245
100.74,25.77,0.245
100.74,25.84,0.245
100.75,25.90,0.245
100.75,25.97,0.245
100.76,26.04,0.245
100.77,26.10,0.245
100.78,26.17,0.245
100.78,26.24,0.245
100.79,26.30,0.245
100.80,26.37,0.245
100.80,26.44,0.245
100.81,26.50,0.245
100.81,26.57,0.245
100.82,26.64,0.245
100.83,26.71,0.245
100.84,26.77,0.245
100.84,26.84,0.245
100.85,26.90,0.245
100.85,26.97,0.245
100.86,27.04,0.245
100.87,27.11,0.245
100.88,27.17,0.245
100.88,27.24,0.245
100.89,27.31,0.245
100.90,27.37,0.245
100.90,27.44,0.245
100.91,27.51,0.245
100.91,27.57,0.245
100.92,27.64,0.245
100.93,27.71,0.245
100.94,27.77,0.245
100.94,27.84,
100.95,27.91,
100.95,27.97,
100.96,28.04,
100.97,28.11,
100.98,28.17,
100.98,28.24,
100.99,,
100.99,,