File: DSC/2025_02_13_Azulene_DSC.txt
Filename	2025_02_13_Azulene_DSC
Instrument name	DSC2A-00468 (192.168.1.100)
Operator	JLY
rundate	2/13/2025
Sample name	2025_02_13_Azulene_DSC
proceduresegments	Data Off ; Equilibrate 30.00 °C; Data On ; Ramp 5.00 °C/min to 120.00 °C
[File Parameters]
Run date	2/13/2025 7:55:09 PM
Trios version	5.1.1.46572
Original File Name
Current File Name	D:\DSC2500\CHM343\2025_02_13_Azulene_DSC.tri
[Procedure]
Procedure Name	Azulene Melting
Sample Name	2025_02_13_Azulene_DSC
Sample Mass	0.12 mg
Reference Sample Mass	0 mg
Pan Mass	53.61 mg
Pan Number	21
Reference Pan Mass	54 mg
Reference Pan Number	19
Pan Type	Tzero Aluminum Hermetic
Comments	Al Hermetic Sealed Pan, with ref Al pan
Project Name
Operator	JLY
Test	Custom
Unload Max Temperature	30
Unload Min Temperature	30
Load Max Temperature	30
Load Min Temperature	30
Stop on Gas Flow Error	Yes
[Signal List]
Signal #1	Time (min)
Signal #2	Temperature (°C)
Signal #3	Heat Flow (mW)
Signal #4	Delta T (µV)
Signal #5	Delta Tzero (µV)
Signal #6	Tzero Temperature (°C)
Signal #7	Cell Purge (mL/min)
Signal #8	Heater Temp (°C)
Signal #9	Power Delivered (W)
Signal #10	Reference Junction Temperature (°C)
Signal #11	Flange Temperature (°C)
Signal #12	Heat Flow Phase (rad)
Signal #13	Total Heat Capacity (J/°C)
Signal #14	Heat Capacity (J/°C)
[Configuration]
Company Name	ASU
Instrument Name	DSC2A-00468
Instrument Type	DSC2500
Serial Number	DSC2A-00468
IP	192.168.1.100
Location of Instrument	MRRC
DisplayType	Unknown
Sample Interval 	0.1 s/pt
Selected Heat Flow	T4P
Exotherm Direction	Down
Cell Serial	DRC2-00792
Lid Type	Standard
Cooler	RCS 90
Leave Cooler on at End of Sequence	On
Gas 2	Nitrogen
Gas Selected	Channel 1
Flow Rate	50 mL/min
Secondary Purge	On
Licensed Heat Flow	Heat Flow T4P
Modulation Licensed	Yes
[Versions]
Common IDD Version	1
Cortex Version	VER 2.10.2.31
Driver	5.0.0.6
GDM Version	1.0.3.3
TouchscreenVersion	1.0.0.16145
FEP Version	1.2.1.21
FEP Bootloader	2.0.0.5
AutoSampler Version	2.1.1.26
Auto Sampler Bootloader	2.0.0.5
FCM Version	1.1.0.3
FCM Bootloader	2.0.0.5
[Experiment Logs]
Experiment Log Entry # 1	Data On set to 0
Experiment Log Entry # 3	Air Cool is off.
Experiment Log Entry # 5	Equilibrate Segment 30 (C) Started
Experiment Log Entry # 7	Data On set to 1
Experiment Log Entry # 9	Ramp Segment 5 C/min to 120 Started
[Method Log]
Method Log Entry # 1	Data Off
Method Log Entry # 2	Equilibrate 30 °C
Method Log Entry # 3	Data On
Method Log Entry # 4	(Ramp 54038) Ramp 5 °C/minute to 120 °C
Cell Serial	DRC2-00792
[T1 Calibration]
Slope	-0.008529666
Offset	9.636258
Initial Temperature	98.23
GUID	f8bfdadc-4977-4fdf-ba6d-0ba9134940c3
[TZero Calibration]
Date Applied	11/29/2022 4:06:13 PM
Description	From -89.059 °C to 396.009 °C at 20.000°C/min
Gas Type	Nitrogen
Pan Type	None
Source Files 1	C:\Users\yargerlab\Desktop\DSC Data\General\TZero_calibration_11_29_22_2nd(2).tri
Source Files 2	C:\Users\yargerlab\Desktop\DSC Data\General\TZero_calibration_11_29_22_2nd(3).tri
Delta T Offset	13.05235
Delta T Slope	-0.007271007
Delta T0 Offset	-13.69128
Delta T0 Slope	0.06063341
[Temperature Calibration]
Date Applied	11/29/2022 7:12:28 PM
Description	From 106.590 °C to 186.590 °C at 10.000°C/min
Gas Type	Nitrogen
Pan Type	Tzero Aluminum Hermetic
Source Files 1	C:\Users\yargerlab\Desktop\DSC Data\General\Indium(6).tri
Measured 1	157.391
Known 1	156.598
[Cell Constant Calibration]
Date Applied	11/29/2022 7:12:29 PM
Description	From 106.590 °C to 186.590 °C at 10.000°C/min
Gas Type	Nitrogen
Pan Type	Tzero Aluminum Hermetic
Source Files 1	C:\Users\yargerlab\Desktop\DSC Data\General\Indium(6).tri
T4P KCell	1.006051
Onset Slope	63.26126 mW/°C
[Direct Cp Calibration]
Date Applied	11/30/2022 11:04:51 AM
Description	From -79.983 °C to 298.409 °C at 10.000°C/min
Gas Type	Nitrogen
Pan Type	Tzero Aluminum Hermetic
Source Files 1	C:\Users\yargerlab\Desktop\DSC Data\General\Sapphire_Heat_Capacity_11_30_22.tri
[Rev Cp Calibration]
Date Applied	11/30/2022 1:58:51 PM
Description	From -79.996 °C to 292.812 °C at 3.000°C/min
Gas Type	Nitrogen
Pan Type	Tzero Aluminum Hermetic
Source Files 1	C:\Users\yargerlab\Desktop\DSC Data\General\Sapphire_MDSC_Calibration_11_30_22.tri
[step]
Ramp 5.00 °C/min to 120.00 °C
Time	Temperature	Heat Flow (Normalized)
min	°C	W/g
0.00	30.07	-0.773
0.01	30.07	-0.773
0.03	30.07	-0.774
0.04	30.08	-0.775
0.05	30.08	-0.775
0.07	30.09	-0.768
0.08	30.10	-0.733
0.09	30.12	-0.598
0.11	30.14	-0.412
0.12	30.17	-0.175
0.13	30.20	-0.062
0.15	30.25	0.065
0.16	30.29	0.156
0.17	30.34	0.238
0.19	30.39	0.277
0.20	30.44	0.301
0.21	30.50	0.325
0.23	30.55	0.354
0.24	30.61	0.372
0.25	30.67	0.386
0.27	30.73	0.409
0.28	30.79	0.418
0.29	30.85	0.432
0.31	30.91	0.443
0.32	30.98	0.455
0.33	31.04	0.471
0.35	31.10	0.479
0.36	31.17	0.493
0.37	31.23	0.503
0.39	31.29	0.509
0.40	31.36	0.518
0.41	31.42	0.527
0.43	31.49	0.536
0.44	31.55	0.544
0.45	31.62	0.551
0.47	31.69	0.558
0.48	31.75	0.566
0.49	31.82	0.571
0.51	31.88	0.577
0.52	31.95	0.583
0.53	32.01	0.590
0.55	32.08	0.594
0.56	32.15	0.601
0.57	32.21	0.604
0.59	32.28	0.609
0.60	32.34	0.614
0.61	32.41	0.618
0.63	32.48	0.622
0.64	32.54	0.626
0.65	32.61	0.629
0.67	32.67	0.633
0.68	32.74	0.636
0.69	32.81	0.640
0.71	32.87	0.642
0.72	32.94	0.643
0.73	33.00	0.645
0.75	33.07	0.650
0.76	33.14	0.651
0.77	33.20	0.653
0.79	33.27	0.654
0.80	33.34	0.654
0.81	33.40	0.656
0.83	33.47	0.655
0.84	33.53	0.656
0.85	33.60	0.657
0.87	33.67	0.658
0.88	33.73	0.657
0.89	33.80	0.660
0.91	33.87	0.660
0.92	33.93	0.659
0.93	34.00	0.659
0.95	34.07	0.657
0.96	34.13	0.658
0.97	34.20	0.657
0.99	34.26	0.659
1.00	34.33	0.659
1.01	34.40	0.658
1.03	34.46	0.658
1.04	34.53	0.658
1.05	34.60	0.657
1.07	34.66	0.657
1.08	34.73	0.657
1.09	34.80	0.658
1.11	34.86	0.658
1.12	34.93	0.658
1.13	35.00	0.658
1.15	35.06	0.657
1.16	35.13	0.655
1.17	35.19	0.655
1.19	35.26	0.655
1.20	35.33	0.653
1.21	35.39	0.654
1.23	35.46	0.654
1.24	35.53	0.653
1.25	35.59	0.653
1.27	35.66	0.652
1.28	35.73	0.651
1.29	35.79	0.653
1.31	35.86	0.649
1.32	35.93	0.652
1.33	35.99	0.647
1.35	36.06	0.648
1.36	36.13	0.646
1.37	36.19	0.645
1.39	36.26	0.645
1.40	36.33	0.642
1.41	36.39	0.641
1.43	36.46	0.641
1.44	36.53	0.642
1.45	36.59	0.641
1.47	36.66	0.639
1.48	36.73	0.638
1.49	36.79	0.637
1.51	36.86	0.634
1.52	36.92	0.634
1.53	36.99	0.634
1.55	37.06	0.632
1.56	37.12	0.632
1.57	37.19	0.630
1.59	37.26	0.629
1.60	37.32	0.629
1.61	37.39	0.628
1.63	37.46	0.626
1.64	37.52	0.624
1.65	37.59	0.623
1.67	37.66	0.622
1.68	37.72	0.622
1.69	37.79	0.621
1.71	37.86	0.620
1.72	37.92	0.619
1.73	37.99	0.617
1.75	38.06	0.616
1.76	38.12	0.616
1.77	38.19	0.615
1.79	38.26	0.613
1.80	38.32	0.613
1.81	38.39	0.611
1.83	38.46	0.611
1.84	38.52	0.609
1.85	38.59	0.607
1.87	38.66	0.609
1.88	38.72	0.609
1.89	38.79	0.607
1.91	38.86	0.606
1.92	38.92	0.606
1.93	38.99	0.606
1.95	39.06	0.606
1.96	39.12	0.605
1.97	39.19	0.604
1.99	39.26	0.604
2.00	39.32	0.602
2.01	39.39	0.603
2.03	39.46	0.602
2.04	39.52	0.601
2.05	39.59	0.600
2.07	39.66	0.601
2.08	39.72	0.600
2.09	39.79	0.600
2.11	39.86	0.599
2.12	39.92	0.598
2.13	39.99	0.596
2.15	40.06	0.596
2.16	40.13	0.596
2.17	40.19	0.596
2.19	40.26	0.595
2.20	40.32	0.593
2.21	40.39	0.593
2.23	40.46	0.593
2.24	40.52	0.593
2.25	40.59	0.592
2.27	40.66	0.592
2.28	40.73	0.590
2.29	40.79	0.590
2.31	40.86	0.590
2.32	40.93	0.588
2.33	40.99	0.587
2.35	41.06	0.586
2.36	41.12	0.586
2.37	41.19	0.586
2.39	41.26	0.586
2.40	41.33	0.585
2.41	41.39	0.584
2.43	41.46	0.584
2.44	41.53	0.582
2.45	41.59	0.582
2.47	41.66	0.583
2.48	41.73	0.581
2.49	41.79	0.580
2.51	41.86	0.579
2.52	41.92	0.578
2.53	41.99	0.578
2.55	42.06	0.576
2.56	42.13	0.575
2.57	42.19	0.575
2.59	42.26	0.573
2.60	42.33	0.573
2.61	42.39	0.573
2.63	42.46	0.572
2.64	42.52	0.570
2.65	42.59	0.569
2.67	42.66	0.569
2.68	42.72	0.569
2.69	42.79	0.568
2.71	42.86	0.569
2.72	42.92	0.568
2.73	42.99	0.566
2.75	43.06	0.567
2.76	43.13	0.567
2.77	43.19	0.566
2.79	43.26	0.565
2.80	43.33	0.565
2.81	43.39	0.564
2.83	43.46	0.563
2.84	43.53	0.565
2.85	43.59	0.563
2.87	43.66	0.563
2.88	43.73	0.563
2.89	43.79	0.563
2.91	43.86	0.563
2.92	43.93	0.563
2.93	43.99	0.561
2.95	44.06	0.562
2.96	44.13	0.562
2.97	44.19	0.562
2.99	44.26	0.562
3.00	44.33	0.559
3.01	44.39	0.559
3.03	44.46	0.561
3.04	44.53	0.560
3.05	44.59	0.558
3.07	44.66	0.559
3.08	44.73	0.559
3.09	44.79	0.560
3.11	44.86	0.562
3.12	44.93	0.557
3.13	44.99	0.559
3.15	45.06	0.559
3.16	45.13	0.558
3.17	45.19	0.557
3.19	45.26	0.557
3.20	45.33	0.556
3.21	45.39	0.556
3.23	45.46	0.557
3.24	45.53	0.555
3.25	45.59	0.554
3.27	45.66	0.554
3.28	45.73	0.554
3.29	45.79	0.553
3.31	45.86	0.552
3.32	45.93	0.553
3.33	45.99	0.553
3.35	46.06	0.553
3.36	46.13	0.554
3.37	46.19	0.554
3.39	46.26	0.554
3.40	46.33	0.554
3.41	46.39	0.553
3.43	46.46	0.553
3.44	46.53	0.554
3.45	46.59	0.554
3.47	46.66	0.553
3.48	46.73	0.554
3.49	46.79	0.551
3.51	46.86	0.552
3.52	46.93	0.552
3.53	46.99	0.552
3.55	47.06	0.550
3.56	47.13	0.550
3.57	47.19	0.550
3.59	47.26	0.551
3.60	47.33	0.552
3.61	47.39	0.551
3.63	47.46	0.549
3.64	47.53	0.551
3.65	47.59	0.550
3.67	47.66	0.551
3.68	47.73	0.551
3.69	47.79	0.550
3.71	47.86	0.549
3.72	47.93	0.549
3.73	48.00	0.548
3.75	48.06	0.549
3.76	48.13	0.550
3.77	48.20	0.550
3.79	48.26	0.548
3.80	48.33	0.548
3.81	48.40	0.546
3.83	48.46	0.546
3.84	48.53	0.546
3.85	48.59	0.546
3.87	48.66	0.547
3.88	48.73	0.547
3.89	48.79	0.545
3.91	48.86	0.546
3.92	48.93	0.546
3.93	48.99	0.545
3.95	49.06	0.545
3.96	49.13	0.546
3.97	49.20	0.547
3.99	49.26	0.545
4.00	49.33	0.544
4.01	49.40	0.544
4.03	49.46	0.546
4.04	49.53	0.544
4.05	49.60	0.545
4.07	49.66	0.543
4.08	49.73	0.543
4.09	49.80	0.544
4.11	49.86	0.544
4.12	49.93	0.542
4.13	50.00	0.543
4.15	50.06	0.543
4.16	50.13	0.544
4.17	50.20	0.542
4.19	50.26	0.544
4.20	50.33	0.544
4.21	50.40	0.544
4.23	50.46	0.543
4.24	50.53	0.543
4.25	50.60	0.544
4.27	50.66	0.545
4.28	50.73	0.545
4.29	50.80	0.545
4.31	50.86	0.545
4.32	50.93	0.545
4.33	51.00	0.546
4.35	51.06	0.546
4.36	51.13	0.546
4.37	51.20	0.546
4.39	51.26	0.546
4.40	51.33	0.546
4.41	51.40	0.544
4.43	51.46	0.545
4.44	51.53	0.545
4.45	51.60	0.545
4.47	51.66	0.546
4.48	51.73	0.545
4.49	51.80	0.546
4.51	51.86	0.543
4.52	51.93	0.544
4.53	52.00	0.545
4.55	52.06	0.543
4.56	52.13	0.543
4.57	52.20	0.543
4.59	52.26	0.544
4.60	52.33	0.544
4.61	52.40	0.542
4.63	52.46	0.543
4.64	52.53	0.543
4.65	52.60	0.542
4.67	52.66	0.543
4.68	52.73	0.542
4.69	52.80	0.542
4.71	52.86	0.542
4.72	52.93	0.542
4.73	53.00	0.542
4.75	53.06	0.541
4.76	53.13	0.540
4.77	53.20	0.541
4.79	53.26	0.542
4.80	53.33	0.541
4.81	53.40	0.542
4.83	53.46	0.541
4.84	53.53	0.542
4.85	53.60	0.541
4.87	53.66	0.542
4.88	53.73	0.540
4.89	53.80	0.543
4.91	53.86	0.543
4.92	53.93	0.542
4.93	54.00	0.542
4.95	54.06	0.544
4.96	54.13	0.544
4.97	54.20	0.544
4.99	54.26	0.545
5.00	54.33	0.546
5.01	54.40	0.546
5.03	54.47	0.546
5.04	54.53	0.545
5.05	54.60	0.543
5.07	54.67	0.545
5.08	54.73	0.546
5.09	54.80	0.546
5.11	54.87	0.545
5.12	54.93	0.546
5.13	55.00	0.546
5.15	55.07	0.546
5.16	55.13	0.546
5.17	55.20	0.545
5.19	55.27	0.546
5.20	55.33	0.547
5.21	55.40	0.546
5.23	55.47	0.546
5.24	55.53	0.546
5.25	55.60	0.546
5.27	55.67	0.546
5.28	55.73	0.546
5.29	55.80	0.546
5.31	55.87	0.546
5.32	55.93	0.546
5.33	56.00	0.546
5.35	56.07	0.547
5.36	56.13	0.548
5.37	56.20	0.549
5.39	56.27	0.550
5.40	56.33	0.549
5.41	56.40	0.549
5.43	56.47	0.550
5.44	56.53	0.550
5.45	56.60	0.550
5.47	56.67	0.549
5.48	56.73	0.549
5.49	56.80	0.549
5.51	56.87	0.552
5.52	56.93	0.550
5.53	57.00	0.548
5.55	57.07	0.549
5.56	57.13	0.551
5.57	57.20	0.551
5.59	57.27	0.549
5.60	57.33	0.550
5.61	57.40	0.551
5.63	57.47	0.552
5.64	57.53	0.551
5.65	57.60	0.553
5.67	57.67	0.554
5.68	57.73	0.555
5.69	57.80	0.553
5.71	57.87	0.554
5.72	57.93	0.552
5.73	58.00	0.555
5.75	58.07	0.554
5.76	58.13	0.555
5.77	58.20	0.555
5.79	58.27	0.555
5.80	58.33	0.557
5.81	58.40	0.557
5.83	58.47	0.556
5.84	58.53	0.558
5.85	58.60	0.557
5.87	58.67	0.557
5.88	58.73	0.557
5.89	58.80	0.558
5.91	58.87	0.558
5.92	58.93	0.559
5.93	59.00	0.558
5.95	59.07	0.558
5.96	59.13	0.559
5.97	59.20	0.557
5.99	59.27	0.560
6.00	59.33	0.558
6.01	59.40	0.555
6.03	59.47	0.560
6.04	59.53	0.560
6.05	59.60	0.561
6.07	59.67	0.560
6.08	59.73	0.559
6.09	59.80	0.561
6.11	59.87	0.561
6.12	59.93	0.560
6.13	60.00	0.561
6.15	60.07	0.560
6.16	60.13	0.560
6.17	60.20	0.560
6.19	60.27	0.560
6.20	60.34	0.558
6.21	60.40	0.560
6.23	60.47	0.561
6.24	60.54	0.560
6.25	60.60	0.560
6.27	60.67	0.561
6.28	60.73	0.560
6.29	60.80	0.561
6.31	60.87	0.563
6.32	60.94	0.560
6.33	61.00	0.561
6.35	61.07	0.562
6.36	61.13	0.561
6.37	61.20	0.563
6.39	61.27	0.561
6.40	61.34	0.560
6.41	61.40	0.561
6.43	61.47	0.559
6.44	61.54	0.561
6.45	61.60	0.561
6.47	61.67	0.561
6.48	61.74	0.562
6.49	61.80	0.563
6.51	61.87	0.563
6.52	61.93	0.562
6.53	62.00	0.562
6.55	62.07	0.562
6.56	62.14	0.564
6.57	62.20	0.566
6.59	62.27	0.565
6.60	62.34	0.565
6.61	62.40	0.567
6.63	62.47	0.565
6.64	62.54	0.565
6.65	62.60	0.567
6.67	62.67	0.565
6.68	62.73	0.565
6.69	62.80	0.565
6.71	62.87	0.569
6.72	62.93	0.569
6.73	63.00	0.568
6.75	63.07	0.570
6.76	63.14	0.569
6.77	63.20	0.571
6.79	63.27	0.570
6.80	63.34	0.573
6.81	63.40	0.572
6.83	63.47	0.572
6.84	63.54	0.571
6.85	63.60	0.572
6.87	63.67	0.572
6.88	63.74	0.574
6.89	63.80	0.575
6.91	63.87	0.576
6.92	63.94	0.575
6.93	64.00	0.576
6.95	64.07	0.580
6.96	64.14	0.576
6.97	64.20	0.576
6.99	64.27	0.576
7.00	64.34	0.577
7.01	64.40	0.578
7.03	64.47	0.579
7.04	64.54	0.579
7.05	64.60	0.580
7.07	64.67	0.579
7.08	64.74	0.579
7.09	64.80	0.580
7.11	64.87	0.580
7.12	64.94	0.581
7.13	65.00	0.580
7.15	65.07	0.580
7.16	65.14	0.580
7.17	65.20	0.580
7.19	65.27	0.580
7.20	65.34	0.581
7.21	65.40	0.581
7.23	65.47	0.582
7.24	65.54	0.582
7.25	65.60	0.583
7.27	65.67	0.582
7.28	65.74	0.582
7.29	65.80	0.584
7.31	65.87	0.584
7.32	65.94	0.583
7.33	66.00	0.586
7.35	66.07	0.585
7.36	66.14	0.585
7.37	66.20	0.584
7.39	66.27	0.585
7.40	66.34	0.585
7.41	66.40	0.585
7.43	66.47	0.585
7.44	66.54	0.584
7.45	66.60	0.586
7.47	66.67	0.586
7.48	66.74	0.585
7.49	66.80	0.586
7.51	66.87	0.585
7.52	66.94	0.585
7.53	67.00	0.587
7.55	67.07	0.588
7.56	67.14	0.587
7.57	67.21	0.588
7.59	67.27	0.587
7.60	67.34	0.588
7.61	67.40	0.589
7.63	67.47	0.588
7.64	67.54	0.591
7.65	67.60	0.590
7.67	67.67	0.590
7.68	67.74	0.590
7.69	67.81	0.590
7.71	67.87	0.590
7.72	67.94	0.593
7.73	68.01	0.592
7.75	68.07	0.591
7.76	68.14	0.593
7.77	68.21	0.592
7.79	68.27	0.590
7.80	68.34	0.591
7.81	68.40	0.591
7.83	68.47	0.592
7.84	68.54	0.592
7.85	68.61	0.592
7.87	68.67	0.594
7.88	68.74	0.593
7.89	68.80	0.593
7.91	68.87	0.592
7.92	68.94	0.593
7.93	69.01	0.594
7.95	69.07	0.593
7.96	69.14	0.593
7.97	69.21	0.595
7.99	69.27	0.596
8.00	69.34	0.596
8.01	69.41	0.597
8.03	69.47	0.597
8.04	69.54	0.596
8.05	69.61	0.596
8.07	69.67	0.597
8.08	69.74	0.598
8.09	69.81	0.598
8.11	69.87	0.597
8.12	69.94	0.599
8.13	70.01	0.599
8.15	70.07	0.599
8.16	70.14	0.599
8.17	70.21	0.599
8.19	70.27	0.600
8.20	70.34	0.601
8.21	70.41	0.602
8.23	70.47	0.602
8.24	70.54	0.603
8.25	70.61	0.603
8.27	70.67	0.604
8.28	70.74	0.606
8.29	70.81	0.607
8.31	70.87	0.606
8.32	70.94	0.608
8.33	71.01	0.608
8.35	71.07	0.609
8.36	71.14	0.608
8.37	71.21	0.609
8.39	71.27	0.609
8.40	71.34	0.610
8.41	71.41	0.609
8.43	71.47	0.607
8.44	71.54	0.611
8.45	71.61	0.612
8.47	71.67	0.612
8.48	71.74	0.614
8.49	71.81	0.613
8.51	71.87	0.613
8.52	71.94	0.613
8.53	72.01	0.612
8.55	72.07	0.613
8.56	72.14	0.613
8.57	72.21	0.614
8.59	72.27	0.616
8.60	72.34	0.615
8.61	72.41	0.615
8.63	72.47	0.615
8.64	72.54	0.614
8.65	72.61	0.614
8.67	72.67	0.614
8.68	72.74	0.614
8.69	72.81	0.613
8.71	72.87	0.613
8.72	72.94	0.613
8.73	73.01	0.615
8.75	73.07	0.613
8.76	73.14	0.615
8.77	73.21	0.615
8.79	73.28	0.616
8.80	73.34	0.616
8.81	73.41	0.615
8.83	73.47	0.616
8.84	73.54	0.616
8.85	73.61	0.616
8.87	73.67	0.617
8.88	73.74	0.618
8.89	73.81	0.619
8.91	73.87	0.619
8.92	73.94	0.618
8.93	74.01	0.617
8.95	74.07	0.617
8.96	74.14	0.618
8.97	74.21	0.620
8.99	74.27	0.620
9.00	74.34	0.619
9.01	74.41	0.618
9.03	74.47	0.620
9.04	74.54	0.620
9.05	74.61	0.620
9.07	74.67	0.621
9.08	74.74	0.621
9.09	74.81	0.623
9.11	74.87	0.622
9.12	74.94	0.624
9.13	75.01	0.623
9.15	75.07	0.622
9.16	75.14	0.623
9.17	75.21	0.623
9.19	75.27	0.624
9.20	75.34	0.625
9.21	75.41	0.625
9.23	75.47	0.626
9.24	75.54	0.626
9.25	75.61	0.627
9.27	75.68	0.626
9.28	75.74	0.627
9.29	75.81	0.627
9.31	75.88	0.629
9.32	75.94	0.629
9.33	76.01	0.629
9.35	76.07	0.630
9.36	76.14	0.630
9.37	76.21	0.631
9.39	76.27	0.631
9.40	76.34	0.632
9.41	76.41	0.631
9.43	76.48	0.632
9.44	76.54	0.633
9.45	76.61	0.632
9.47	76.67	0.633
9.48	76.74	0.633
9.49	76.81	0.633
9.51	76.88	0.633
9.52	76.94	0.634
9.53	77.01	0.634
9.55	77.08	0.635
9.56	77.14	0.635
9.57	77.21	0.636
9.59	77.28	0.636
9.60	77.34	0.638
9.61	77.41	0.639
9.63	77.48	0.639
9.64	77.54	0.639
9.65	77.61	0.639
9.67	77.68	0.640
9.68	77.74	0.640
9.69	77.81	0.640
9.71	77.88	0.641
9.72	77.94	0.642
9.73	78.01	0.642
9.75	78.08	0.642
9.76	78.14	0.644
9.77	78.21	0.644
9.79	78.28	0.644
9.80	78.34	0.645
9.81	78.41	0.645
9.83	78.48	0.646
9.84	78.54	0.647
9.85	78.61	0.647
9.87	78.68	0.647
9.88	78.74	0.647
9.89	78.81	0.648
9.91	78.88	0.649
9.92	78.94	0.649
9.93	79.01	0.650
9.95	79.08	0.649
9.96	79.14	0.650
9.97	79.21	0.650
9.99	79.28	0.652
10.00	79.34	0.651
10.01	79.41	0.652
10.03	79.48	0.654
10.04	79.54	0.653
10.05	79.61	0.655
10.07	79.68	0.655
10.08	79.74	0.656
10.09	79.81	0.656
10.11	79.88	0.656
10.12	79.94	0.655
10.13	80.01	0.656
10.15	80.08	0.656
10.16	80.14	0.656
10.17	80.21	0.657
10.19	80.28	0.656
10.20	80.34	0.657
10.21	80.41	0.656
10.23	80.48	0.657
10.24	80.54	0.658
10.25	80.61	0.659
10.27	80.68	0.658
10.28	80.74	0.659
10.29	80.81	0.660
10.31	80.88	0.659
10.32	80.94	0.661
10.33	81.01	0.660
10.35	81.08	0.660
10.36	81.14	0.661
10.37	81.21	0.661
10.39	81.28	0.661
10.40	81.34	0.661
10.41	81.41	0.661
10.43	81.48	0.661
10.44	81.54	0.661
10.45	81.61	0.661
10.47	81.68	0.663
10.48	81.74	0.663
10.49	81.81	0.663
10.51	81.88	0.662
10.52	81.94	0.662
10.53	82.01	0.663
10.55	82.08	0.663
10.56	82.14	0.663
10.57	82.21	0.664
10.59	82.28	0.664
10.60	82.34	0.665
10.61	82.41	0.664
10.63	82.48	0.666
10.64	82.55	0.666
10.65	82.61	0.666
10.67	82.68	0.665
10.68	82.74	0.665
10.69	82.81	0.666
10.71	82.88	0.666
10.72	82.94	0.667
10.73	83.01	0.667
10.75	83.08	0.665
10.76	83.14	0.666
10.77	83.21	0.666
10.79	83.28	0.666
10.80	83.35	0.667
10.81	83.41	0.668
10.83	83.48	0.670
10.84	83.54	0.668
10.85	83.61	0.668
10.87	83.68	0.669
10.88	83.74	0.669
10.89	83.81	0.671
10.91	83.88	0.671
10.92	83.94	0.668
10.93	84.01	0.670
10.95	84.08	0.670
10.96	84.15	0.672
10.97	84.21	0.672
10.99	84.28	0.672
11.00	84.35	0.673
11.01	84.41	0.674
11.03	84.48	0.674
11.04	84.55	0.674
11.05	84.61	0.674
11.07	84.68	0.675
11.08	84.75	0.676
11.09	84.81	0.676
11.11	84.88	0.676
11.12	84.95	0.675
11.13	85.01	0.678
11.15	85.08	0.677
11.16	85.15	0.677
11.17	85.21	0.678
11.19	85.28	0.678
11.20	85.35	0.679
11.21	85.41	0.679
11.23	85.48	0.680
11.24	85.55	0.681
11.25	85.61	0.682
11.27	85.68	0.681
11.28	85.75	0.681
11.29	85.81	0.680
11.31	85.88	0.682
11.32	85.95	0.683
11.33	86.01	0.682
11.35	86.08	0.685
11.36	86.15	0.684
11.37	86.21	0.686
11.39	86.28	0.686
11.40	86.35	0.687
11.41	86.41	0.687
11.43	86.48	0.688
11.44	86.55	0.688
11.45	86.61	0.689
11.47	86.68	0.688
11.48	86.75	0.688
11.49	86.81	0.688
11.51	86.88	0.689
11.52	86.95	0.689
11.53	87.01	0.691
11.55	87.08	0.690
11.56	87.15	0.691
11.57	87.21	0.691
11.59	87.28	0.691
11.60	87.35	0.693
11.61	87.41	0.693
11.63	87.48	0.693
11.64	87.55	0.694
11.65	87.61	0.693
11.67	87.68	0.695
11.68	87.75	0.696
11.69	87.81	0.696
11.71	87.88	0.696
11.72	87.95	0.698
11.73	88.01	0.698
11.75	88.08	0.699
11.76	88.15	0.700
11.77	88.21	0.699
11.79	88.28	0.699
11.80	88.35	0.701
11.81	88.41	0.703
11.83	88.48	0.702
11.84	88.55	0.702
11.85	88.61	0.703
11.87	88.68	0.705
11.88	88.75	0.705
11.89	88.81	0.705
11.91	88.88	0.707
11.92	88.95	0.707
11.93	89.01	0.707
11.95	89.08	0.708
11.96	89.15	0.710
11.97	89.21	0.712
11.99	89.28	0.712
12.00	89.35	0.713
12.01	89.41	0.715
12.03	89.48	0.717
12.04	89.55	0.718
12.05	89.61	0.716
12.07	89.68	0.717
12.08	89.75	0.720
12.09	89.82	0.721
12.11	89.88	0.721
12.12	89.95	0.722
12.13	90.02	0.723
12.15	90.08	0.726
12.16	90.15	0.725
12.17	90.22	0.727
12.19	90.28	0.728
12.20	90.35	0.729
12.21	90.42	0.728
12.23	90.48	0.731
12.24	90.55	0.732
12.25	90.62	0.731
12.27	90.68	0.732
12.28	90.75	0.733
12.29	90.81	0.734
12.31	90.88	0.734
12.32	90.95	0.732
12.33	91.01	0.731
12.35	91.08	0.733
12.36	91.15	0.735
12.37	91.21	0.736
12.39	91.28	0.737
12.40	91.35	0.738
12.41	91.41	0.738
12.43	91.48	0.739
12.44	91.55	0.741
12.45	91.61	0.740
12.47	91.68	0.744
12.48	91.75	0.742
12.49	91.82	0.742
12.51	91.88	0.742
12.52	91.95	0.743
12.53	92.01	0.743
12.55	92.08	0.745
12.56	92.15	0.744
12.57	92.21	0.745
12.59	92.28	0.746
12.60	92.35	0.748
12.61	92.41	0.747
12.63	92.48	0.749
12.64	92.55	0.750
12.65	92.61	0.752
12.67	92.68	0.752
12.68	92.75	0.753
12.69	92.82	0.755
12.71	92.88	0.754
12.72	92.95	0.755
12.73	93.02	0.755
12.75	93.08	0.755
12.76	93.15	0.759
12.77	93.22	0.759
12.79	93.28	0.758
12.80	93.35	0.759
12.81	93.42	0.761
12.83	93.48	0.760
12.84	93.55	0.760
12.85	93.62	0.763
12.87	93.68	0.765
12.88	93.75	0.766
12.89	93.82	0.767
12.91	93.88	0.768
12.92	93.95	0.769
12.93	94.02	0.770
12.95	94.08	0.773
12.96	94.15	0.774
12.97	94.22	0.776
12.99	94.28	0.777
13.00	94.35	0.778
13.01	94.42	0.780
13.03	94.48	0.783
13.04	94.55	0.786
13.05	94.62	0.788
13.07	94.68	0.788
13.08	94.75	0.790
13.09	94.82	0.793
13.11	94.88	0.794
13.12	94.95	0.794
13.13	95.02	0.798
13.15	95.08	0.800
13.16	95.15	0.802
13.17	95.22	0.804
13.19	95.28	0.806
13.20	95.35	0.807
13.21	95.42	0.810
13.23	95.48	0.812
13.24	95.55	0.817
13.25	95.62	0.818
13.27	95.68	0.821
13.28	95.75	0.822
13.29	95.82	0.827
13.31	95.88	0.830
13.32	95.95	0.833
13.33	96.02	0.836
13.35	96.08	0.839
13.36	96.15	0.842
13.37	96.22	0.848
13.39	96.28	0.852
13.40	96.35	0.855
13.41	96.42	0.861
13.43	96.48	0.868
13.44	96.55	0.872
13.45	96.62	0.876
13.47	96.68	0.883
13.48	96.75	0.891
13.49	96.82	0.897
13.51	96.88	0.909
13.52	96.95	0.916
13.53	97.02	0.925
13.55	97.08	0.936
13.56	97.15	0.960
13.57	97.22	0.969
13.59	97.28	0.983
13.60	97.35	1.017
13.61	97.41	1.045
13.63	97.48	1.085
13.64	97.55	1.114
13.65	97.61	1.184
13.67	97.68	1.244
13.68	97.75	1.313
13.69	97.81	1.452
13.71	97.88	1.593
13.72	97.95	1.764
13.73	98.01	1.917
13.75	98.08	2.186
13.76	98.14	2.441
13.77	98.21	2.727
13.79	98.27	3.104
13.80	98.34	3.562
13.81	98.40	4.090
13.83	98.47	4.788
13.84	98.53	5.601
13.85	98.59	6.744
13.87	98.65	8.142
13.88	98.71	9.773
13.89	98.77	11.824
13.91	98.82	14.068
13.92	98.88	16.149
13.93	98.93	17.160
13.95	98.99	15.513
13.96	99.06	11.229
13.97	99.13	6.504
13.99	99.21	4.591
14.00	99.29	3.919
14.01	99.37	3.465
14.03	99.44	2.982
14.04	99.52	2.664
14.05	99.59	2.376
14.07	99.66	2.103
14.08	99.73	1.866
14.09	99.80	1.759
14.11	99.87	1.601
14.12	99.94	1.494
14.13	100.01	1.358
14.15	100.08	1.294
14.16	100.14	1.240
14.17	100.21	1.185
14.19	100.28	1.134
14.20	100.35	1.115
14.21	100.41	1.074
14.23	100.48	1.047
14.24	100.55	1.025
14.25	100.62	1.015
14.27	100.68	1.007
14.28	100.75	1.000
14.29	100.82	0.984
14.31	100.88	0.971
14.32	100.95	0.957
14.33	101.02	0.952
14.35	101.08	0.944
14.36	101.15	0.938
14.37	101.22	0.933
14.39	101.28	0.928
14.40	101.35	0.921
14.41	101.42	0.916
14.43	101.49	0.911
14.44	101.55	0.907
14.45	101.62	0.902
14.47	101.69	0.899
14.48	101.75	0.893
14.49	101.82	0.888
14.51	101.88	0.885
14.52	101.95	0.880
14.53	102.02	0.876
14.55	102.09	0.872
14.56	102.15	0.870
14.57	102.22	0.868
14.59	102.28	0.866
14.60	102.35	0.864
14.61	102.42	0.863
14.63	102.49	0.861
14.64	102.55	0.858
14.65	102.62	0.858
14.67	102.69	0.856
14.68	102.75	0.853
14.69	102.82	0.853
14.71	102.89	0.852
14.72	102.95	0.850
14.73	103.02	0.849
14.75	103.09	0.847
14.76	103.15	0.845
14.77	103.22	0.844
14.79	103.29	0.842
14.80	103.35	0.841
14.81	103.42	0.841
14.83	103.49	0.839
14.84	103.55	0.839
14.85	103.62	0.839
14.87	103.69	0.837
14.88	103.75	0.838
14.89	103.82	0.837
14.91	103.89	0.838
14.92	103.95	0.838
14.93	104.02	0.836
14.95	104.09	0.834
14.96	104.15	0.835
14.97	104.22	0.835
14.99	104.29	0.835
15.00	104.35	0.833
15.01	104.42	0.838
15.03	104.49	0.837
15.04	104.55	0.837
15.05	104.62	0.834
15.07	104.69	0.835
15.08	104.75	0.835
15.09	104.82	0.833
15.11	104.89	0.835
15.12	104.95	0.834
15.13	105.02	0.835
15.15	105.09	0.836
15.16	105.15	0.836
15.17	105.22	0.834
15.19	105.29	0.839
15.20	105.35	0.838
15.21	105.42	0.839
15.23	105.49	0.839
15.24	105.55	0.839
15.25	105.62	0.840
15.27	105.69	0.839
15.28	105.75	0.839
15.29	105.82	0.840
15.31	105.89	0.840
15.32	105.95	0.840
15.33	106.02	0.839
15.35	106.09	0.839
15.36	106.15	0.841
15.37	106.22	0.840
15.39	106.29	0.841
15.40	106.35	0.842
15.41	106.42	0.842
15.43	106.49	0.844
15.44	106.55	0.845
15.45	106.62	0.845
15.47	106.69	0.845
15.48	106.75	0.846
15.49	106.82	0.845
15.51	106.89	0.847
15.52	106.95	0.848
15.53	107.02	0.847
15.55	107.09	0.847
15.56	107.15	0.849
15.57	107.22	0.848
15.59	107.29	0.849
15.60	107.35	0.848
15.61	107.42	0.849
15.63	107.49	0.849
15.64	107.55	0.851
15.65	107.62	0.851
15.67	107.69	0.851
15.68	107.75	0.852
15.69	107.82	0.852
15.71	107.89	0.852
15.72	107.95	0.854
15.73	108.02	0.854
15.75	108.09	0.855
15.76	108.15	0.856
15.77	108.22	0.854
15.79	108.29	0.856
15.80	108.35	0.857
15.81	108.42	0.859
15.83	108.49	0.857
15.84	108.55	0.859
15.85	108.62	0.860
15.87	108.69	0.860
15.88	108.75	0.861
15.89	108.82	0.862
15.91	108.89	0.861
15.92	108.96	0.861
15.93	109.02	0.863
15.95	109.09	0.863
15.96	109.15	0.863
15.97	109.22	0.864
15.99	109.29	0.864
16.00	109.36	0.866
16.01	109.42	0.866
16.03	109.49	0.866
16.04	109.55	0.865
16.05	109.62	0.865
16.07	109.69	0.866
16.08	109.75	0.866
16.09	109.82	0.866
16.11	109.89	0.867
16.12	109.95	0.869
16.13	110.02	0.869
16.15	110.09	0.870
16.16	110.15	0.871
16.17	110.22	0.870
16.19	110.29	0.872
16.20	110.35	0.873
16.21	110.42	0.874
16.23	110.49	0.874
16.24	110.55	0.876
16.25	110.62	0.876
16.27	110.69	0.876
16.28	110.76	0.879
16.29	110.82	0.881
16.31	110.89	0.881
16.32	110.96	0.881
16.33	111.02	0.881
16.35	111.09	0.883
16.36	111.16	0.884
16.37	111.22	0.884
16.39	111.29	0.885
16.40	111.36	0.885
16.41	111.42	0.885
16.43	111.49	0.884
16.44	111.56	0.885
16.45	111.62	0.886
16.47	111.69	0.885
16.48	111.76	0.885
16.49	111.82	0.885
16.51	111.89	0.887
16.52	111.96	0.887
16.53	112.02	0.887
16.55	112.09	0.887
16.56	112.16	0.886
16.57	112.22	0.887
16.59	112.29	0.888
16.60	112.36	0.890
16.61	112.42	0.889
16.63	112.49	0.890
16.64	112.56	0.890
16.65	112.62	0.891
16.67	112.69	0.891
16.68	112.76	0.892
16.69	112.82	0.893
16.71	112.89	0.893
16.72	112.96	0.894
16.73	113.02	0.893
16.75	113.09	0.892
16.76	113.16	0.892
16.77	113.22	0.893
16.79	113.29	0.894
16.80	113.36	0.895
16.81	113.42	0.895
16.83	113.49	0.896
16.84	113.56	0.895
16.85	113.62	0.895
16.87	113.69	0.897
16.88	113.76	0.897
16.89	113.82	0.897
16.91	113.89	0.898
16.92	113.96	0.898
16.93	114.02	0.899
16.95	114.09	0.899
16.96	114.16	0.899
16.97	114.22	0.899
16.99	114.29	0.898
17.00	114.36	0.900
17.01	114.42	0.900
17.03	114.49	0.901
17.04	114.56	0.901
17.05	114.62	0.901
17.07	114.69	0.902
17.08	114.76	0.899
17.09	114.82	0.901
17.11	114.89	0.902
17.12	114.96	0.899
17.13	115.02	0.900
17.15	115.09	0.900
17.16	115.16	0.901
17.17	115.22	0.902
17.19	115.29	0.902
17.20	115.36	0.902
17.21	115.42	0.902
17.23	115.49	0.903
17.24	115.56	0.904
17.25	115.62	0.904
17.27	115.69	0.905
17.28	115.76	0.905
17.29	115.82	0.907
17.31	115.89	0.909
17.32	115.96	0.909
17.33	116.02	0.911
17.35	116.09	0.909
17.36	116.16	0.910
17.37	116.22	0.911
17.39	116.29	0.912
17.40	116.36	0.912
17.41	116.42	0.914
17.43	116.49	0.914
17.44	116.56	0.915
17.45	116.62	0.916
17.47	116.69	0.916
17.48	116.76	0.916
17.49	116.82	0.917
17.51	116.89	0.917
17.52	116.96	0.917
17.53	117.02	0.918
17.55	117.09	0.918
17.56	117.16	0.918
17.57	117.22	0.917
17.59	117.29	0.918
17.60	117.36	0.919
17.61	117.42	0.918
17.63	117.49	0.918
17.64	117.56	0.920
17.65	117.62	0.922
17.67	117.69	0.921
17.68	117.76	0.921
17.69	117.82	0.920
17.71	117.89	0.922
17.72	117.96	0.923
17.73	118.02	0.924
17.75	118.09	0.923
17.76	118.16	0.925
17.77	118.22	0.926
17.79	118.29	0.927
17.80	118.36	0.926
17.81	118.43	0.928
17.83	118.49	0.930
17.84	118.56	0.929
17.85	118.63	0.930
17.87	118.69	0.929
17.88	118.76	0.930
17.89	118.83	0.930
17.91	118.89	0.929
17.92	118.96	0.931
17.93	119.03	0.931
17.95	119.09
17.96	119.16
17.97	119.23
17.99	119.29
18.00
18.00