File: DSC/2025_07_01_Saccharin_n60_245_10C_min_x4.csv
Filename,2025_07_01_Saccharin_n60_245_10C_min_x4
Instrument name,DSC2A-00468 (192.168.1.100)
Operator,Gibbons
rundate,7/1/2025
Sample name,2025_07_01_Saccharin_n60_245_10C_min_x4
proceduresegments,Data Off ; Equilibrate -60.00 °C; Data On ; Ramp 10.00 °C/min to 245.00 °C; Data Off ; Isothermal 2.0 min; Data On ; Ramp 10.00 °C/min to -60.00 °C; Data Off ; Isothermal 2.0 min; Data On ; Ramp 10.00 °C/min to 245.00 °C; Data Off ; Isothermal 2.0 min; Data On ; Ramp 10.00 °C/min to -60.00 °C; Data Off ; Isothermal 2.0 min; Data On ; Ramp 10.00 °C/min to 245.00 °C; Data Off ; Isothermal 2.0 min; Data On ; Ramp 10.00 °C/min to -60.00 °C; Data Off ; Isothermal 2.0 min; Data On ; Ramp 10.00 °C/min to 30.00 °C
[File Parameters]
Run date,7/1/2025 6:22:39 PM
Trios version,5.1.1.46572
Original File Name,
Current File Name,D:\DSC2500\Gibbons\2025_07_01_Saccharin_n60_245_10C_min_x4.tri
[Procedure]
Procedure Name,Saccharin_n60_245_10C_min_x4
Sample Name,2025_07_01_Saccharin_n60_245_10C_min_x4
Sample Mass,5.88 mg
Reference Sample Mass,0 mg
Pan Mass,57.1 mg
Pan Number,11
Reference Pan Mass,57.15 mg
Reference Pan Number,28
Pan Type,Tzero Aluminum Hermetic
Comments,DSC Consumables Al Hermetically Sealed Pan. Y1 Tray (Google Sheet: DSC_Samples_Y1_Tray_June2025).
Project Name,Pharma - Cocrystals
Operator,Gibbons
Test,Custom
Unload Max Temperature,30
Unload Min Temperature,30
Load Max Temperature,30
Load Min Temperature,30
Stop on Gas Flow Error,Yes
[Signal List]
Signal #1,Time (min)
Signal #2,Temperature (°C)
Signal #3,Heat Flow (mW)
Signal #4,Delta T (µV)
Signal #5,Delta Tzero (µV)
Signal #6,Tzero Temperature (°C)
Signal #7,Cell Purge (mL/min)
Signal #8,Heater Temp (°C)
Signal #9,Power Delivered (W)
Signal #10,Reference Junction Temperature (°C)
Signal #11,Flange Temperature (°C)
Signal #12,Heat Flow Phase (rad)
Signal #13,Total Heat Capacity (J/°C)
Signal #14,Heat Capacity (J/°C)
[Configuration]
Company Name,ASU
Instrument Name,DSC2A-00468
Instrument Type,DSC2500
Serial Number,DSC2A-00468
IP,192.168.1.100
Location of Instrument,MRRC
DisplayType,Unknown
Sample Interval ,0.1 s/pt
Selected Heat Flow,T4P
Exotherm Direction,Down
Cell Serial,DRC2-00792
Lid Type,Standard
Cooler,RCS 90
Leave Cooler on at End of Sequence,On
Gas 2,Nitrogen
Gas Selected,Channel 1
Flow Rate,50 mL/min
Secondary Purge,On
Licensed Heat Flow,Heat Flow T4P
Modulation Licensed,Yes
[Versions]
Common IDD Version,1
Cortex Version,VER 2.10.2.31
Driver,5.0.0.6
GDM Version,1.0.3.3
TouchscreenVersion,1.0.0.16145
FEP Version,1.2.1.21
FEP Bootloader,2.0.0.5
AutoSampler Version,2.1.1.26
Auto Sampler Bootloader,2.0.0.5
FCM Version,1.1.0.3
FCM Bootloader,2.0.0.5
[Experiment Logs]
Experiment Log Entry # 1,Data On set to 0
Experiment Log Entry # 3,Equilibrate Segment -60 (C) Started
Experiment Log Entry # 5,Air Cool is off.
Experiment Log Entry # 7,Data On set to 1
Experiment Log Entry # 9,Ramp Segment 10 C/min to 245 Started
Experiment Log Entry # 11,Data On set to 0
Experiment Log Entry # 13,Isothermal Segment 2 min started
Experiment Log Entry # 15,Data On set to 1
Experiment Log Entry # 17,Ramp Segment 10 C/min to -60 Started
Experiment Log Entry # 19,Data On set to 0
Experiment Log Entry # 21,Isothermal Segment 2 min started
Experiment Log Entry # 23,Data On set to 1
Experiment Log Entry # 25,Ramp Segment 10 C/min to 245 Started
Experiment Log Entry # 27,Data On set to 0
Experiment Log Entry # 29,Isothermal Segment 2 min started
Experiment Log Entry # 31,Data On set to 1
Experiment Log Entry # 33,Ramp Segment 10 C/min to -60 Started
Experiment Log Entry # 35,Data On set to 0
Experiment Log Entry # 37,Isothermal Segment 2 min started
Experiment Log Entry # 39,Data On set to 1
Experiment Log Entry # 41,Ramp Segment 10 C/min to 245 Started
Experiment Log Entry # 43,Data On set to 0
Experiment Log Entry # 45,Isothermal Segment 2 min started
Experiment Log Entry # 47,Data On set to 1
Experiment Log Entry # 49,Ramp Segment 10 C/min to -60 Started
Experiment Log Entry # 51,Data On set to 0
Experiment Log Entry # 53,Isothermal Segment 2 min started
Experiment Log Entry # 55,Data On set to 1
Experiment Log Entry # 57,Ramp Segment 10 C/min to 30 Started
[Method Log]
Method Log Entry # 1,Data Off
Method Log Entry # 2,Equilibrate -60 °C
Method Log Entry # 3,Data On
Method Log Entry # 4,(Ramp 1001349) Ramp 10 °C/minute to 245 °C
Method Log Entry # 5,Data Off
Method Log Entry # 6,Isothermal 2 minutes
Method Log Entry # 7,Data On
Method Log Entry # 8,(Ramp 1001353) Ramp 10 °C/minute to -60 °C
Method Log Entry # 9,Data Off
Method Log Entry # 10,Isothermal 2 minutes
Method Log Entry # 11,Data On
Method Log Entry # 12,(Ramp 1001357) Ramp 10 °C/minute to 245 °C
Method Log Entry # 13,Data Off
Method Log Entry # 14,Isothermal 2 minutes
Method Log Entry # 15,Data On
Method Log Entry # 16,(Ramp 1001361) Ramp 10 °C/minute to -60 °C
Method Log Entry # 17,Data Off
Method Log Entry # 18,Isothermal 2 minutes
Method Log Entry # 19,Data On
Method Log Entry # 20,(Ramp 1001365) Ramp 10 °C/minute to 245 °C
Method Log Entry # 21,Data Off
Method Log Entry # 22,Isothermal 2 minutes
Method Log Entry # 23,Data On
Method Log Entry # 24,(Ramp 1001369) Ramp 10 °C/minute to -60 °C
Method Log Entry # 25,Data Off
Method Log Entry # 26,Isothermal 2 minutes
Method Log Entry # 27,Data On
Method Log Entry # 28,(Ramp 1001373) Ramp 10 °C/minute to 30 °C
Cell Serial,DRC2-00792
[T1 Calibration]
Slope,-0.008529666
Offset,9.636258
Initial Temperature,98.23
GUID,f8bfdadc-4977-4fdf-ba6d-0ba9134940c3
[TZero Calibration]
Date Applied,11/29/2022 4:06:13 PM
Description,From -89.059 °C to 396.009 °C at 20.000°C/min
Gas Type,Nitrogen
Pan Type,None
Source Files 1,C:\Users\yargerlab\Desktop\DSC Data\General\TZero_calibration_11_29_22_2nd(2).tri
Source Files 2,C:\Users\yargerlab\Desktop\DSC Data\General\TZero_calibration_11_29_22_2nd(3).tri
Delta T Offset,13.05235
Delta T Slope,-0.007271007
Delta T0 Offset,-13.69128
Delta T0 Slope,0.06063341
[Temperature Calibration]
Date Applied,11/29/2022 7:12:28 PM
Description,From 106.590 °C to 186.590 °C at 10.000°C/min
Gas Type,Nitrogen
Pan Type,Tzero Aluminum Hermetic
Source Files 1,C:\Users\yargerlab\Desktop\DSC Data\General\Indium(6).tri
Measured 1,157.391
Known 1,156.598
[Cell Constant Calibration]
Date Applied,11/29/2022 7:12:29 PM
Description,From 106.590 °C to 186.590 °C at 10.000°C/min
Gas Type,Nitrogen
Pan Type,Tzero Aluminum Hermetic
Source Files 1,C:\Users\yargerlab\Desktop\DSC Data\General\Indium(6).tri
T4P KCell,1.006051
Onset Slope,63.26126 mW/°C
[Direct Cp Calibration]
Date Applied,11/30/2022 11:04:51 AM
Description,From -79.983 °C to 298.409 °C at 10.000°C/min
Gas Type,Nitrogen
Pan Type,Tzero Aluminum Hermetic
Source Files 1,C:\Users\yargerlab\Desktop\DSC Data\General\Sapphire_Heat_Capacity_11_30_22.tri
[Rev Cp Calibration]
Date Applied,11/30/2022 1:58:51 PM
Description,From -79.996 °C to 292.812 °C at 3.000°C/min
Gas Type,Nitrogen
Pan Type,Tzero Aluminum Hermetic
Source Files 1,C:\Users\yargerlab\Desktop\DSC Data\General\Sapphire_MDSC_Calibration_11_30_22.tri
[step]
Ramp 10.00 °C/min to 245.00 °C
Time,Temperature,Heat Flow (Normalized)
min,°C,W/g
0.00,-59.71,-0.042
0.02,-59.72,-0.040
0.04,-59.72,-0.036
0.07,-59.71,-0.029
0.09,-59.68,-0.020
0.11,-59.63,-0.007
0.13,-59.54,0.008
0.15,-59.43,0.026
0.17,-59.30,0.045
0.19,-59.15,0.064
0.22,-58.99,0.080
0.24,-58.82,0.095
0.26,-58.64,0.106
0.28,-58.45,0.117
0.30,-58.26,0.125
0.33,-58.07,0.133
0.35,-57.87,0.137
0.37,-57.67,0.143
0.39,-57.47,0.146
0.41,-57.27,0.149
0.43,-57.06,0.151
0.45,-56.86,0.154
0.48,-56.65,0.155
0.50,-56.44,0.156
0.52,-56.24,0.157
0.54,-56.03,0.159
0.56,-55.82,0.160
0.58,-55.60,0.160
0.61,-55.39,0.161
0.63,-55.18,0.162
0.65,-54.97,0.162
0.67,-54.76,0.163
0.69,-54.55,0.163
0.72,-54.34,0.164
0.74,-54.12,0.164
0.76,-53.91,0.164
0.78,-53.69,0.165
0.80,-53.48,0.165
0.82,-53.27,0.165
0.85,-53.05,0.166
0.87,-52.84,0.166
0.89,-52.63,0.166
0.91,-52.41,0.166
0.93,-52.20,0.167
0.95,-51.98,0.167
0.98,-51.77,0.167
1.00,-51.55,0.167
1.02,-51.34,0.168
1.04,-51.12,0.168
1.06,-50.91,0.168
1.08,-50.69,0.168
1.11,-50.47,0.168
1.13,-50.26,0.169
1.15,-50.05,0.169
1.17,-49.83,0.169
1.19,-49.61,0.169
1.21,-49.40,0.169
1.23,-49.18,0.170
1.26,-48.97,0.170
1.28,-48.75,0.170
1.30,-48.53,0.170
1.32,-48.32,0.170
1.34,-48.10,0.170
1.37,-47.89,0.170
1.39,-47.67,0.170
1.41,-47.45,0.170
1.43,-47.24,0.171
1.45,-47.02,0.171
1.47,-46.80,0.171
1.49,-46.59,0.171
1.52,-46.37,0.171
1.54,-46.15,0.171
1.56,-45.94,0.171
1.58,-45.72,0.171
1.60,-45.51,0.171
1.63,-45.29,0.171
1.65,-45.07,0.171
1.67,-44.86,0.171
1.69,-44.64,0.172
1.71,-44.42,0.172
1.73,-44.21,0.172
1.76,-43.99,0.172
1.78,-43.77,0.172
1.80,-43.56,0.172
1.82,-43.34,0.172
1.84,-43.12,0.172
1.86,-42.91,0.172
1.88,-42.69,0.172
1.91,-42.47,0.172
1.93,-42.26,0.172
1.95,-42.04,0.172
1.97,-41.82,0.172
1.99,-41.61,0.172
2.02,-41.39,0.172
2.04,-41.17,0.172
2.06,-40.95,0.173
2.08,-40.74,0.173
2.10,-40.52,0.173
2.12,-40.30,0.173
2.14,-40.08,0.173
2.17,-39.87,0.173
2.19,-39.65,0.173
2.21,-39.44,0.173
2.23,-39.22,0.173
2.25,-39.00,0.173
2.28,-38.78,0.173
2.30,-38.57,0.173
2.32,-38.35,0.173
2.34,-38.13,0.173
2.36,-37.92,0.173
2.38,-37.70,0.173
2.41,-37.48,0.173
2.43,-37.26,0.173
2.45,-37.05,0.174
2.47,-36.83,0.174
2.49,-36.61,0.174
2.51,-36.40,0.174
2.54,-36.18,0.174
2.56,-35.96,0.174
2.58,-35.75,0.174
2.60,-35.53,0.174
2.62,-35.31,0.174
2.64,-35.09,0.174
2.66,-34.88,0.174
2.69,-34.66,0.174
2.71,-34.44,0.174
2.73,-34.23,0.174
2.75,-34.01,0.174
2.77,-33.79,0.174
2.79,-33.58,0.174
2.82,-33.36,0.174
2.84,-33.14,0.174
2.86,-32.92,0.174
2.88,-32.71,0.174
2.90,-32.49,0.174
2.93,-32.27,0.175
2.95,-32.06,0.175
2.97,-31.84,0.175
2.99,-31.62,0.175
3.01,-31.40,0.175
3.03,-31.19,0.175
3.06,-30.97,0.175
3.08,-30.75,0.175
3.10,-30.54,0.175
3.12,-30.32,0.175
3.14,-30.10,0.175
3.16,-29.89,0.175
3.19,-29.67,0.175
3.21,-29.45,0.175
3.23,-29.23,0.175
3.25,-29.02,0.175
3.27,-28.80,0.175
3.29,-28.58,0.175
3.31,-28.37,0.175
3.34,-28.15,0.176
3.36,-27.93,0.176
3.38,-27.72,0.176
3.40,-27.50,0.176
3.42,-27.28,0.176
3.44,-27.07,0.176
3.47,-26.85,0.176
3.49,-26.63,0.176
3.51,-26.41,0.176
3.53,-26.20,0.176
3.55,-25.98,0.176
3.58,-25.76,0.176
3.60,-25.55,0.176
3.62,-25.33,0.176
3.64,-25.11,0.177
3.66,-24.89,0.177
3.68,-24.68,0.177
3.71,-24.46,0.177
3.73,-24.24,0.177
3.75,-24.03,0.177
3.77,-23.81,0.177
3.79,-23.59,0.177
3.81,-23.37,0.177
3.84,-23.16,0.177
3.86,-22.94,0.177
3.88,-22.73,0.177
3.90,-22.51,0.177
3.92,-22.29,0.177
3.94,-22.08,0.177
3.96,-21.86,0.177
3.99,-21.64,0.178
4.01,-21.42,0.178
4.03,-21.21,0.178
4.05,-20.99,0.178
4.07,-20.77,0.178
4.09,-20.56,0.178
4.12,-20.34,0.178
4.14,-20.12,0.178
4.16,-19.91,0.178
4.18,-19.69,0.178
4.20,-19.47,0.178
4.23,-19.26,0.178
4.25,-19.04,0.178
4.27,-18.82,0.178
4.29,-18.60,0.179
4.31,-18.39,0.179
4.33,-18.17,0.179
4.35,-17.95,0.179
4.38,-17.74,0.179
4.40,-17.52,0.179
4.42,-17.30,0.179
4.44,-17.09,0.179
4.46,-16.87,0.179
4.49,-16.65,0.179
4.51,-16.43,0.179
4.53,-16.22,0.179
4.55,-16.00,0.179
4.57,-15.78,0.180
4.59,-15.57,0.180
4.61,-15.35,0.180
4.64,-15.13,0.180
4.66,-14.91,0.180
4.68,-14.70,0.180
4.70,-14.48,0.180
4.72,-14.26,0.180
4.75,-14.05,0.180
4.77,-13.83,0.180
4.79,-13.61,0.180
4.81,-13.40,0.180
4.83,-13.18,0.181
4.85,-12.96,0.181
4.88,-12.75,0.181
4.90,-12.53,0.181
4.92,-12.31,0.181
4.94,-12.10,0.181
4.96,-11.88,0.181
4.98,-11.66,0.181
5.00,-11.44,0.181
5.03,-11.23,0.181
5.05,-11.01,0.181
5.07,-10.79,0.181
5.09,-10.58,0.182
5.11,-10.36,0.182
5.14,-10.14,0.182
5.16,-9.93,0.182
5.18,-9.71,0.182
5.20,-9.49,0.182
5.22,-9.28,0.182
5.24,-9.06,0.182
5.26,-8.84,0.183
5.29,-8.63,0.183
5.31,-8.41,0.183
5.33,-8.19,0.183
5.35,-7.98,0.183
5.37,-7.76,0.183
5.40,-7.54,0.184
5.42,-7.33,0.184
5.44,-7.11,0.184
5.46,-6.89,0.185
5.48,-6.67,0.185
5.50,-6.46,0.185
5.53,-6.24,0.185
5.55,-6.02,0.186
5.57,-5.81,0.186
5.59,-5.59,0.186
5.61,-5.37,0.188
5.63,-5.16,0.188
5.65,-4.94,0.189
5.68,-4.72,0.190
5.70,-4.51,0.192
5.72,-4.29,0.194
5.74,-4.07,0.196
5.76,-3.86,0.201
5.79,-3.64,0.205
5.81,-3.43,0.210
5.83,-3.21,0.214
5.85,-2.99,0.219
5.87,-2.78,0.224
5.89,-2.57,0.226
5.91,-2.35,0.225
5.94,-2.13,0.212
5.96,-1.91,0.205
5.98,-1.69,0.202
6.00,-1.47,0.201
6.02,-1.26,0.199
6.05,-1.04,0.198
6.07,-0.82,0.198
6.09,-0.60,0.197
6.11,-0.38,0.196
6.13,-0.17,0.196
6.15,0.05,0.195
6.18,0.27,0.194
6.20,0.49,0.194
6.22,0.70,0.193
6.24,0.92,0.193
6.26,1.14,0.192
6.28,1.36,0.192
6.30,1.57,0.192
6.33,1.79,0.191
6.35,2.01,0.191
6.37,2.22,0.191
6.39,2.44,0.191
6.41,2.66,0.190
6.44,2.88,0.190
6.46,3.09,0.190
6.48,3.31,0.190
6.50,3.52,0.190
6.52,3.74,0.190
6.54,3.96,0.190
6.56,4.18,0.189
6.59,4.39,0.189
6.61,4.61,0.189
6.63,4.83,0.189
6.65,5.04,0.189
6.67,5.26,0.189
6.70,5.48,0.189
6.72,5.69,0.189
6.74,5.91,0.189
6.76,6.13,0.189
6.78,6.35,0.189
6.80,6.56,0.189
6.83,6.78,0.190
6.85,7.00,0.190
6.87,7.21,0.190
6.89,7.43,0.190
6.91,7.65,0.190
6.93,7.86,0.190
6.95,8.08,0.190
6.98,8.30,0.190
7.00,8.52,0.190
7.02,8.73,0.190
7.04,8.95,0.190
7.06,9.17,0.190
7.09,9.38,0.191
7.11,9.60,0.191
7.13,9.82,0.191
7.15,10.03,0.191
7.17,10.25,0.191
7.19,10.47,0.191
7.21,10.69,0.191
7.24,10.90,0.191
7.26,11.12,0.191
7.28,11.34,0.192
7.30,11.55,0.192
7.32,11.77,0.192
7.35,11.99,0.192
7.37,12.21,0.192
7.39,12.42,0.192
7.41,12.64,0.192
7.43,12.86,0.192
7.45,13.07,0.193
7.48,13.29,0.193
7.50,13.51,0.193
7.52,13.72,0.193
7.54,13.94,0.193
7.56,14.16,0.193
7.58,14.37,0.193
7.60,14.59,0.193
7.63,14.81,0.194
7.65,15.02,0.194
7.67,15.24,0.194
7.69,15.46,0.194
7.71,15.67,0.194
7.74,15.89,0.194
7.76,16.11,0.194
7.78,16.33,0.194
7.80,16.54,0.194
7.82,16.76,0.195
7.84,16.98,0.195
7.86,17.19,0.195
7.89,17.41,0.195
7.91,17.63,0.195
7.93,17.84,0.195
7.95,18.06,0.195
7.97,18.28,0.195
8.00,18.49,0.195
8.02,18.71,0.196
8.04,18.93,0.196
8.06,19.14,0.196
8.08,19.36,0.196
8.10,19.58,0.196
8.13,19.79,0.196
8.15,20.01,0.196
8.17,20.23,0.197
8.19,20.44,0.197
8.21,20.66,0.197
8.23,20.88,0.197
8.25,21.10,0.197
8.28,21.31,0.198
8.30,21.53,0.198
8.32,21.75,0.198
8.34,21.96,0.198
8.36,22.18,0.198
8.39,22.40,0.198
8.41,22.61,0.198
8.43,22.83,0.199
8.45,23.05,0.199
8.47,23.27,0.199
8.49,23.48,0.199
8.51,23.70,0.199
8.54,23.92,0.199
8.56,24.13,0.199
8.58,24.35,0.200
8.60,24.57,0.200
8.62,24.78,0.200
8.65,25.00,0.200
8.67,25.22,0.200
8.69,25.44,0.200
8.71,25.65,0.201
8.73,25.87,0.201
8.75,26.09,0.201
8.78,26.30,0.201
8.80,26.52,0.201
8.82,26.74,0.201
8.84,26.95,0.201
8.86,27.17,0.201
8.88,27.39,0.202
8.90,27.60,0.202
8.93,27.82,0.202
8.95,28.04,0.202
8.97,28.25,0.202
8.99,28.47,0.202
9.01,28.69,0.202
9.03,28.91,0.202
9.06,29.12,0.202
9.08,29.34,0.203
9.10,29.55,0.203
9.12,29.77,0.203
9.14,29.99,0.203
9.17,30.21,0.203
9.19,30.42,0.203
9.21,30.64,0.203
9.23,30.86,0.203
9.25,31.07,0.204
9.27,31.29,0.204
9.30,31.51,0.204
9.32,31.72,0.204
9.34,31.94,0.204
9.36,32.16,0.204
9.38,32.38,0.204
9.40,32.59,0.204
9.43,32.81,0.205
9.45,33.03,0.205
9.47,33.24,0.205
9.49,33.46,0.205
9.51,33.67,0.205
9.53,33.89,0.205
9.55,34.11,0.205
9.58,34.33,0.206
9.60,34.54,0.206
9.62,34.76,0.206
9.64,34.98,0.206
9.66,35.19,0.206
9.68,35.41,0.206
9.71,35.63,0.206
9.73,35.85,0.207
9.75,36.06,0.207
9.77,36.28,0.207
9.79,36.50,0.207
9.82,36.71,0.207
9.84,36.93,0.207
9.86,37.15,0.207
9.88,37.36,0.207
9.90,37.58,0.208
9.92,37.80,0.208
9.95,38.01,0.208
9.97,38.23,0.208
9.99,38.45,0.208
10.01,38.66,0.208
10.03,38.88,0.208
10.05,39.10,0.208
10.08,39.32,0.209
10.10,39.53,0.209
10.12,39.75,0.209
10.14,39.97,0.209
10.16,40.18,0.209
10.18,40.40,0.209
10.20,40.62,0.209
10.23,40.83,0.210
10.25,41.05,0.210
10.27,41.27,0.210
10.29,41.48,0.210
10.31,41.70,0.210
10.33,41.92,0.210
10.36,42.14,0.210
10.38,42.35,0.210
10.40,42.57,0.210
10.42,42.79,0.211
10.44,43.00,0.211
10.47,43.22,0.211
10.49,43.44,0.211
10.51,43.65,0.211
10.53,43.87,0.211
10.55,44.09,0.212
10.57,44.30,0.212
10.60,44.52,0.212
10.62,44.74,0.212
10.64,44.96,0.212
10.66,45.17,0.212
10.68,45.39,0.212
10.70,45.61,0.213
10.73,45.82,0.213
10.75,46.04,0.213
10.77,46.26,0.213
10.79,46.47,0.213
10.81,46.69,0.213
10.83,46.91,0.213
10.85,47.13,0.214
10.88,47.34,0.214
10.90,47.56,0.214
10.92,47.78,0.214
10.94,47.99,0.214
10.96,48.21,0.214
10.98,48.43,0.214
11.01,48.64,0.215
11.03,48.86,0.215
11.05,49.08,0.215
11.07,49.29,0.215
11.09,49.51,0.215
11.12,49.73,0.215
11.14,49.94,0.215
11.16,50.16,0.216
11.18,50.38,0.216
11.20,50.60,0.216
11.22,50.81,0.216
11.25,51.03,0.216
11.27,51.25,0.216
11.29,51.46,0.216
11.31,51.68,0.216
11.33,51.90,0.217
11.35,52.11,0.217
11.38,52.33,0.217
11.40,52.55,0.217
11.42,52.76,0.217
11.44,52.98,0.217
11.46,53.20,0.217
11.48,53.41,0.217
11.50,53.63,0.218
11.53,53.85,0.218
11.55,54.07,0.218
11.57,54.28,0.218
11.59,54.50,0.218
11.61,54.72,0.218
11.63,54.93,0.218
11.66,55.15,0.218
11.68,55.37,0.219
11.70,55.58,0.219
11.72,55.80,0.219
11.74,56.02,0.219
11.77,56.24,0.219
11.79,56.45,0.219
11.81,56.67,0.219
11.83,56.89,0.219
11.85,57.10,0.219
11.87,57.32,0.220
11.90,57.54,0.220
11.92,57.75,0.220
11.94,57.97,0.220
11.96,58.19,0.220
11.98,58.41,0.220
12.00,58.62,0.220
12.03,58.84,0.220
12.05,59.06,0.221
12.07,59.27,0.221
12.09,59.49,0.221
12.11,59.70,0.221
12.13,59.92,0.221
12.15,60.14,0.221
12.18,60.36,0.221
12.20,60.57,0.221
12.22,60.79,0.221
12.24,61.01,0.222
12.26,61.22,0.222
12.28,61.44,0.222
12.31,61.66,0.222
12.33,61.88,0.222
12.35,62.09,0.222
12.37,62.31,0.222
12.39,62.53,0.222
12.42,62.74,0.222
12.44,62.96,0.222
12.46,63.18,0.222
12.48,63.39,0.223
12.50,63.61,0.223
12.52,63.83,0.223
12.55,64.04,0.223
12.57,64.26,0.223
12.59,64.48,0.223
12.61,64.69,0.223
12.63,64.91,0.223
12.65,65.13,0.223
12.68,65.35,0.223
12.70,65.56,0.223
12.72,65.78,0.224
12.74,66.00,0.224
12.76,66.21,0.224
12.78,66.43,0.224
12.80,66.65,0.224
12.83,66.87,0.224
12.85,67.08,0.224
12.87,67.30,0.224
12.89,67.52,0.224
12.91,67.73,0.224
12.93,67.95,0.224
12.96,68.17,0.224
12.98,68.38,0.224
13.00,68.60,0.224
13.02,68.82,0.224
13.04,69.03,0.224
13.07,69.25,0.225
13.09,69.47,0.225
13.11,69.68,0.225
13.13,69.90,0.225
13.15,70.12,0.225
13.17,70.34,0.225
13.20,70.55,0.225
13.22,70.77,0.225
13.24,70.99,0.225
13.26,71.20,0.225
13.28,71.42,0.225
13.30,71.64,0.226
13.33,71.85,0.226
13.35,72.07,0.226
13.37,72.29,0.226
13.39,72.50,0.226
13.41,72.72,0.226
13.43,72.94,0.226
13.45,73.16,0.226
13.48,73.37,0.226
13.50,73.59,0.226
13.52,73.81,0.227
13.54,74.02,0.227
13.56,74.24,0.227
13.58,74.46,0.227
13.61,74.68,0.227
13.63,74.89,0.227
13.65,75.11,0.227
13.67,75.33,0.227
13.69,75.55,0.227
13.72,75.76,0.226
13.74,75.98,0.226
13.76,76.20,0.226
13.78,76.41,0.226
13.80,76.63,0.226
13.82,76.85,0.226
13.85,77.06,0.226
13.87,77.28,0.226
13.89,77.50,0.226
13.91,77.71,0.226
13.93,77.93,0.226
13.95,78.15,0.226
13.98,78.37,0.226
14.00,78.58,0.226
14.02,78.80,0.226
14.04,79.02,0.226
14.06,79.23,0.226
14.08,79.45,0.226
14.10,79.67,0.226
14.13,79.88,0.226
14.15,80.10,0.226
14.17,80.32,0.226
14.19,80.53,0.226
14.21,80.75,0.226
14.23,80.97,0.226
14.26,81.18,0.226
14.28,81.40,0.226
14.30,81.62,0.226
14.32,81.84,0.226
14.34,82.05,0.226
14.37,82.27,0.226
14.39,82.49,0.226
14.41,82.70,0.226
14.43,82.92,0.226
14.45,83.14,0.226
14.47,83.35,0.226
14.50,83.57,0.226
14.52,83.79,0.226
14.54,84.00,0.226
14.56,84.22,0.226
14.58,84.44,0.227
14.60,84.65,0.227
14.63,84.87,0.227
14.65,85.09,0.227
14.67,85.30,0.227
14.69,85.52,0.227
14.71,85.74,0.227
14.73,85.95,0.227
14.75,86.17,0.227
14.78,86.39,0.227
14.80,86.60,0.227
14.82,86.82,0.227
14.84,87.04,0.227
14.86,87.26,0.227
14.88,87.47,0.227
14.91,87.69,0.228
14.93,87.91,0.228
14.95,88.12,0.228
14.97,88.34,0.228
14.99,88.56,0.228
15.02,88.78,0.228
15.04,88.99,0.229
15.06,89.21,0.229
15.08,89.42,0.230
15.10,89.64,0.230
15.12,89.86,0.230
15.15,90.07,0.230
15.17,90.29,0.231
15.19,90.51,0.231
15.21,90.72,0.231
15.23,90.94,0.231
15.25,91.16,0.231
15.28,91.38,0.231
15.30,91.59,0.231
15.32,91.81,0.231
15.34,92.03,0.231
15.36,92.24,0.231
15.38,92.46,0.231
15.40,92.68,0.231
15.43,92.89,0.231
15.45,93.11,0.231
15.47,93.33,0.231
15.49,93.55,0.231
15.51,93.76,0.231
15.53,93.98,0.231
15.56,94.20,0.231
15.58,94.41,0.231
15.60,94.63,0.231
15.62,94.85,0.231
15.64,95.06,0.231
15.67,95.28,0.231
15.69,95.50,0.232
15.71,95.71,0.232
15.73,95.93,0.232
15.75,96.15,0.232
15.77,96.37,0.232
15.80,96.58,0.232
15.82,96.80,0.232
15.84,97.02,0.232
15.86,97.23,0.232
15.88,97.45,0.232
15.90,97.67,0.232
15.93,97.88,0.232
15.95,98.10,0.232
15.97,98.32,0.232
15.99,98.53,0.232
16.01,98.75,0.233
16.03,98.97,0.233
16.05,99.18,0.233
16.08,99.40,0.233
16.10,99.62,0.233
16.12,99.83,0.233
16.14,100.05,0.233
16.16,100.27,0.233
16.18,100.49,0.233
16.21,100.70,0.234
16.23,100.92,0.234
16.25,101.14,0.234
16.27,101.35,0.234
16.29,101.57,0.234
16.32,101.79,0.234
16.34,102.00,0.234
16.36,102.22,0.234
16.38,102.44,0.234
16.40,102.65,0.234
16.42,102.87,0.234
16.45,103.09,0.234
16.47,103.30,0.235
16.49,103.52,0.235
16.51,103.74,0.235
16.53,103.96,0.235
16.55,104.17,0.235
16.58,104.39,0.235
16.60,104.61,0.235
16.62,104.82,0.235
16.64,105.04,0.235
16.66,105.26,0.236
16.68,105.47,0.236
16.70,105.69,0.236
16.73,105.91,0.236
16.75,106.12,0.236
16.77,106.34,0.236
16.79,106.56,0.236
16.81,106.77,0.236
16.83,106.99,0.236
16.86,107.21,0.236
16.88,107.42,0.236
16.90,107.64,0.237
16.92,107.86,0.237
16.94,108.07,0.237
16.97,108.29,0.237
16.99,108.51,0.237
17.01,108.72,0.237
17.03,108.94,0.237
17.05,109.16,0.237
17.07,109.38,0.238
17.09,109.59,0.238
17.12,109.81,0.238
17.14,110.03,0.238
17.16,110.24,0.238
17.18,110.46,0.238
17.20,110.68,0.238
17.23,110.89,0.239
17.25,111.11,0.239
17.27,111.33,0.239
17.29,111.54,0.239
17.31,111.76,0.239
17.33,111.98,0.239
17.36,112.20,0.239
17.38,112.41,0.239
17.40,112.63,0.240
17.42,112.85,0.240
17.44,113.06,0.240
17.46,113.28,0.240
17.48,113.50,0.240
17.51,113.71,0.240
17.53,113.93,0.240
17.55,114.15,0.240
17.57,114.36,0.240
17.59,114.58,0.240
17.62,114.80,0.241
17.64,115.01,0.241
17.66,115.23,0.241
17.68,115.45,0.241
17.70,115.66,0.241
17.72,115.88,0.241
17.74,116.10,0.241
17.77,116.31,0.241
17.79,116.53,0.241
17.81,116.75,0.242
17.83,116.96,0.242
17.85,117.18,0.242
17.88,117.40,0.242
17.90,117.61,0.242
17.92,117.83,0.242
17.94,118.05,0.242
17.96,118.26,0.242
17.98,118.48,0.242
18.01,118.70,0.243
18.03,118.92,0.243
18.05,119.13,0.243
18.07,119.35,0.243
18.09,119.57,0.243
18.11,119.78,0.243
18.13,120.00,0.243
18.16,120.22,0.243
18.18,120.43,0.244
18.20,120.65,0.244
18.22,120.87,0.244
18.24,121.08,0.244
18.27,121.30,0.244
18.29,121.52,0.244
18.31,121.73,0.244
18.33,121.95,0.244
18.35,122.17,0.245
18.37,122.38,0.245
18.39,122.60,0.245
18.42,122.82,0.245
18.44,123.04,0.245
18.46,123.25,0.245
18.48,123.47,0.245
18.50,123.69,0.245
18.53,123.90,0.246
18.55,124.12,0.246
18.57,124.34,0.246
18.59,124.55,0.246
18.61,124.77,0.246
18.63,124.99,0.246
18.66,125.20,0.246
18.68,125.42,0.246
18.70,125.64,0.246
18.72,125.85,0.246
18.74,126.07,0.246
18.76,126.29,0.247
18.78,126.51,0.247
18.81,126.72,0.247
18.83,126.94,0.247
18.85,127.16,0.247
18.87,127.37,0.247
18.89,127.59,0.247
18.92,127.81,0.247
18.94,128.02,0.247
18.96,128.24,0.248
18.98,128.46,0.248
19.00,128.68,0.248
19.02,128.89,0.248
19.04,129.11,0.248
19.07,129.32,0.248
19.09,129.54,0.248
19.11,129.76,0.248
19.13,129.97,0.248
19.15,130.19,0.248
19.18,130.41,0.248
19.20,130.63,0.249
19.22,130.84,0.249
19.24,131.06,0.249
19.26,131.27,0.249
19.28,131.49,0.249
19.31,131.71,0.249
19.33,131.93,0.249
19.35,132.14,0.249
19.37,132.36,0.250
19.39,132.58,0.250
19.41,132.79,0.250
19.43,133.01,0.250
19.46,133.23,0.250
19.48,133.44,0.250
19.50,133.66,0.250
19.52,133.88,0.251
19.54,134.10,0.251
19.57,134.31,0.251
19.59,134.53,0.251
19.61,134.75,0.251
19.63,134.96,0.251
19.65,135.18,0.252
19.67,135.40,0.252
19.69,135.61,0.252
19.72,135.83,0.252
19.74,136.05,0.252
19.76,136.26,0.252
19.78,136.48,0.252
19.80,136.70,0.252
19.83,136.91,0.253
19.85,137.13,0.253
19.87,137.35,0.253
19.89,137.57,0.253
19.91,137.78,0.253
19.93,138.00,0.253
19.96,138.21,0.253
19.98,138.43,0.254
20.00,138.65,0.254
20.02,138.86,0.254
20.04,139.08,0.254
20.06,139.30,0.254
20.08,139.51,0.254
20.11,139.73,0.255
20.13,139.95,0.255
20.15,140.16,0.256
20.17,140.38,0.256
20.19,140.60,0.256
20.22,140.81,0.256
20.24,141.03,0.256
20.26,141.25,0.257
20.28,141.47,0.257
20.30,141.68,0.257
20.32,141.90,0.257
20.34,142.12,0.257
20.37,142.33,0.258
20.39,142.55,0.258
20.41,142.77,0.258
20.43,142.98,0.258
20.45,143.20,0.259
20.48,143.42,0.259
20.50,143.63,0.259
20.52,143.85,0.260
20.54,144.07,0.260
20.56,144.28,0.261
20.58,144.50,0.261
20.61,144.72,0.261
20.63,144.93,0.261
20.65,145.15,0.262
20.67,145.37,0.262
20.69,145.58,0.263
20.71,145.80,0.263
20.73,146.02,0.263
20.76,146.23,0.263
20.78,146.45,0.263
20.80,146.67,0.264
20.82,146.88,0.264
20.84,147.10,0.264
20.87,147.32,0.264
20.89,147.54,0.265
20.91,147.75,0.265
20.93,147.97,0.265
20.95,148.19,0.265
20.97,148.40,0.266
20.99,148.62,0.266
21.02,148.84,0.266
21.04,149.05,0.266
21.06,149.27,0.266
21.08,149.49,0.267
21.10,149.70,0.267
21.13,149.92,0.267
21.15,150.14,0.268
21.17,150.35,0.269
21.19,150.57,0.269
21.21,150.79,0.269
21.23,151.00,0.269
21.26,151.22,0.270
21.28,151.44,0.276
21.30,151.65,0.275
21.32,151.87,0.275
21.34,152.09,0.274
21.36,152.30,0.274
21.38,152.52,0.273
21.41,152.74,0.273
21.43,152.96,0.272
21.45,153.17,0.272
21.47,153.39,0.272
21.49,153.61,0.272
21.52,153.82,0.271
21.54,154.04,0.271
21.56,154.26,0.273
21.58,154.47,0.273
21.60,154.69,0.273
21.62,154.91,0.273
21.64,155.12,0.272
21.67,155.34,0.272
21.69,155.56,0.272
21.71,155.78,0.272
21.73,155.99,0.271
21.75,156.21,0.271
21.78,156.43,0.271
21.80,156.64,0.271
21.82,156.86,0.271
21.84,157.08,0.271
21.86,157.29,0.271
21.88,157.51,0.271
21.91,157.73,0.271
21.93,157.94,0.271
21.95,158.16,0.271
21.97,158.38,0.271
21.99,158.60,0.271
22.01,158.81,0.271
22.03,159.03,0.271
22.06,159.25,0.271
22.08,159.46,0.271
22.10,159.68,0.270
22.12,159.90,0.270
22.14,160.11,0.270
22.17,160.33,0.270
22.19,160.55,0.270
22.21,160.76,0.270
22.23,160.98,0.270
22.25,161.20,0.270
22.27,161.41,0.270
22.29,161.63,0.270
22.32,161.85,0.270
22.34,162.06,0.270
22.36,162.28,0.270
22.38,162.50,0.270
22.40,162.71,0.270
22.43,162.93,0.270
22.45,163.15,0.270
22.47,163.36,0.270
22.49,163.58,0.270
22.51,163.80,0.270
22.53,164.01,0.270
22.56,164.23,0.270
22.58,164.45,0.270
22.60,164.66,0.270
22.62,164.88,0.271
22.64,165.10,0.271
22.66,165.32,0.271
22.68,165.53,0.271
22.71,165.75,0.271
22.73,165.97,0.271
22.75,166.18,0.271
22.77,166.40,0.271
22.79,166.62,0.271
22.82,166.83,0.271
22.84,167.05,0.271
22.86,167.27,0.271
22.88,167.48,0.271
22.90,167.70,0.271
22.92,167.92,0.271
22.94,168.14,0.271
22.97,168.35,0.271
22.99,168.57,0.271
23.01,168.79,0.271
23.03,169.00,0.271
23.05,169.22,0.271
23.08,169.44,0.271
23.10,169.65,0.271
23.12,169.87,0.271
23.14,170.09,0.271
23.16,170.30,0.271
23.18,170.52,0.271
23.21,170.74,0.271
23.23,170.95,0.271
23.25,171.17,0.271
23.27,171.39,0.271
23.29,171.60,0.271
23.31,171.82,0.271
23.33,172.04,0.271
23.36,172.25,0.271
23.38,172.47,0.271
23.40,172.69,0.271
23.42,172.91,0.271
23.44,173.12,0.271
23.47,173.34,0.271
23.49,173.55,0.271
23.51,173.77,0.271
23.53,173.99,0.271
23.55,174.20,0.271
23.57,174.42,0.271
23.59,174.64,0.271
23.62,174.85,0.271
23.64,175.07,0.271
23.66,175.29,0.271
23.68,175.51,0.271
23.70,175.72,0.271
23.73,175.94,0.271
23.75,176.16,0.271
23.77,176.37,0.271
23.79,176.59,0.271
23.81,176.81,0.271
23.83,177.02,0.271
23.86,177.24,0.271
23.88,177.46,0.271
23.90,177.67,0.271
23.92,177.89,0.271
23.94,178.11,0.271
23.96,178.33,0.271
23.98,178.54,0.271
24.01,178.76,0.271
24.03,178.98,0.271
24.05,179.19,0.271
24.07,179.41,0.271
24.09,179.63,0.271
24.12,179.84,0.271
24.14,180.06,0.271
24.16,180.28,0.271
24.18,180.49,0.271
24.20,180.71,0.271
24.22,180.93,0.271
24.24,181.14,0.271
24.27,181.36,0.271
24.29,181.58,0.271
24.31,181.79,0.271
24.33,182.01,0.271
24.35,182.23,0.271
24.38,182.44,0.271
24.40,182.66,0.271
24.42,182.88,0.271
24.44,183.09,0.271
24.46,183.31,0.271
24.48,183.53,0.271
24.51,183.74,0.271
24.53,183.96,0.271
24.55,184.18,0.271
24.57,184.39,0.272
24.59,184.61,0.272
24.61,184.83,0.272
24.63,185.05,0.272
24.66,185.26,0.272
24.68,185.48,0.272
24.70,185.70,0.272
24.72,185.91,0.272
24.74,186.13,0.272
24.77,186.35,0.272
24.79,186.56,0.272
24.81,186.78,0.272
24.83,187.00,0.272
24.85,187.21,0.273
24.87,187.43,0.273
24.89,187.65,0.273
24.92,187.87,0.273
24.94,188.08,0.273
24.96,188.30,0.273
24.98,188.52,0.273
25.00,188.73,0.273
25.03,188.95,0.273
25.05,189.16,0.273
25.07,189.38,0.273
25.09,189.60,0.273
25.11,189.82,0.273
25.13,190.03,0.273
25.16,190.25,0.273
25.18,190.47,0.274
25.20,190.68,0.274
25.22,190.90,0.274
25.24,191.12,0.274
25.26,191.33,0.274
25.28,191.55,0.274
25.31,191.77,0.274
25.33,191.98,0.274
25.35,192.20,0.274
25.37,192.42,0.274
25.39,192.63,0.274
25.42,192.85,0.274
25.44,193.07,0.274
25.46,193.28,0.275
25.48,193.50,0.275
25.50,193.72,0.275
25.52,193.93,0.275
25.54,194.15,0.275
25.57,194.37,0.275
25.59,194.59,0.275
25.61,194.80,0.275
25.63,195.02,0.275
25.65,195.24,0.276
25.68,195.45,0.276
25.70,195.67,0.276
25.72,195.89,0.276
25.74,196.10,0.276
25.76,196.32,0.276
25.78,196.54,0.276
25.81,196.75,0.276
25.83,196.97,0.276
25.85,197.19,0.277
25.87,197.40,0.277
25.89,197.62,0.277
25.91,197.84,0.277
25.93,198.05,0.277
25.96,198.27,0.277
25.98,198.49,0.277
26.00,198.70,0.277
26.02,198.92,0.277
26.04,199.14,0.277
26.07,199.36,0.277
26.09,199.57,0.277
26.11,199.79,0.277
26.13,200.01,0.277
26.15,200.22,0.277
26.17,200.44,0.278
26.19,200.66,0.278
26.22,200.87,0.278
26.24,201.09,0.278
26.26,201.31,0.278
26.28,201.52,0.278
26.30,201.74,0.278
26.33,201.96,0.279
26.35,202.17,0.279
26.37,202.39,0.279
26.39,202.61,0.279
26.41,202.82,0.279
26.43,203.04,0.279
26.46,203.26,0.279
26.48,203.47,0.279
26.50,203.69,0.280
26.52,203.91,0.280
26.54,204.12,0.280
26.56,204.34,0.280
26.58,204.56,0.280
26.61,204.77,0.281
26.63,204.99,0.281
26.65,205.21,0.281
26.67,205.42,0.281
26.69,205.64,0.281
26.72,205.86,0.282
26.74,206.07,0.282
26.76,206.29,0.282
26.78,206.51,0.282
26.80,206.72,0.283
26.82,206.94,0.283
26.84,207.16,0.283
26.87,207.37,0.283
26.89,207.59,0.283
26.91,207.81,0.284
26.93,208.03,0.284
26.95,208.24,0.284
26.98,208.46,0.284
27.00,208.68,0.285
27.02,208.89,0.285
27.04,209.11,0.285
27.06,209.33,0.285
27.08,209.54,0.286
27.11,209.76,0.286
27.13,209.97,0.286
27.15,210.19,0.286
27.17,210.41,0.287
27.19,210.62,0.287
27.21,210.84,0.287
27.23,211.06,0.288
27.26,211.27,0.288
27.28,211.49,0.289
27.30,211.71,0.289
27.32,211.93,0.289
27.34,212.14,0.290
27.37,212.36,0.290
27.39,212.57,0.291
27.41,212.79,0.291
27.43,213.01,0.292
27.45,213.22,0.292
27.47,213.44,0.293
27.49,213.66,0.294
27.52,213.87,0.295
27.54,214.09,0.295
27.56,214.31,0.296
27.58,214.52,0.296
27.60,214.74,0.297
27.63,214.96,0.298
27.65,215.17,0.301
27.67,215.39,0.302
27.69,215.61,0.303
27.71,215.82,0.305
27.73,216.04,0.306
27.76,216.25,0.309
27.78,216.47,0.313
27.80,216.69,0.315
27.82,216.90,0.316
27.84,217.12,0.317
27.86,217.34,0.318
27.88,217.55,0.320
27.91,217.77,0.323
27.93,217.99,0.325
27.95,218.20,0.326
27.97,218.42,0.327
27.99,218.63,0.330
28.02,218.85,0.333
28.04,219.07,0.335
28.06,219.28,0.338
28.08,219.50,0.340
28.10,219.71,0.342
28.12,219.93,0.344
28.14,220.15,0.348
28.17,220.36,0.355
28.19,220.58,0.358
28.21,220.79,0.365
28.23,221.01,0.370
28.25,221.22,0.377
28.28,221.44,0.382
28.30,221.65,0.394
28.32,221.87,0.402
28.34,222.08,0.414
28.36,222.30,0.424
28.38,222.51,0.434
28.41,222.72,0.447
28.43,222.94,0.464
28.45,223.15,0.483
28.47,223.36,0.506
28.49,223.57,0.532
28.51,223.78,0.560
28.53,223.99,0.598
28.56,224.20,0.638
28.58,224.40,0.687
28.60,224.60,0.744
28.62,224.81,0.812
28.64,225.00,0.902
28.67,225.20,1.014
28.69,225.38,1.132
28.71,225.57,1.281
28.73,225.74,1.465
28.75,225.91,1.701
28.77,226.07,1.908
28.79,226.22,2.164
28.82,226.36,2.431
28.84,226.51,2.691
28.86,226.64,2.940
28.88,226.78,3.221
28.90,226.92,3.493
28.93,227.05,3.794
28.95,227.17,4.076
28.97,227.30,4.382
28.99,227.42,4.689
29.01,227.55,4.992
29.03,227.67,5.284
29.06,227.80,5.539
29.08,227.92,5.834
29.10,228.05,6.130
29.12,228.17,6.420
29.14,228.30,6.631
29.16,228.44,6.855
29.18,228.60,6.823
29.21,228.80,6.452
29.23,229.06,6.024
29.25,229.36,5.357
29.27,229.73,4.410
29.29,230.18,3.171
29.32,230.68,2.120
29.34,231.16,1.567
29.36,231.59,1.272
29.38,231.96,1.057
29.40,232.31,0.891
29.42,232.62,0.762
29.44,232.91,0.662
29.47,233.18,0.586
29.49,233.45,0.527
29.51,233.70,0.480
29.53,233.94,0.445
29.55,234.18,0.418
29.58,234.41,0.397
29.60,234.64,0.381
29.62,234.86,0.368
29.64,235.09,0.358
29.66,235.31,0.352
29.68,235.53,0.345
29.71,235.75,0.341
29.73,235.97,0.338
29.75,236.19,0.336
29.77,236.41,0.334
29.79,236.62,0.332
29.81,236.84,0.331
29.83,237.06,0.331
29.86,237.28,0.330
29.88,237.49,0.330
29.90,237.71,0.329
29.92,237.93,0.329
29.94,238.15,0.329
29.97,238.36,0.329
29.99,238.58,0.328
30.01,238.80,0.328
30.03,239.01,0.328
30.05,239.23,0.327
30.07,239.45,0.327
30.09,239.66,0.327
30.12,239.88,0.327
30.14,240.10,0.326
30.16,240.31,0.326
30.18,240.53,0.326
30.20,240.75,0.326
30.23,240.96,0.326
30.25,241.18,0.325
30.27,241.40,0.325
30.29,241.61,0.325
30.31,241.83,0.325
30.33,242.05,0.325
30.36,242.27,0.325
30.38,242.48,0.325
30.40,242.70,0.324
30.42,242.92,0.324
30.44,243.13,
30.46,243.35,
30.48,,
30.49,,

[step]
Ramp 10.00 °C/min to -60.00 °C
Time,Temperature,Heat Flow (Normalized)
min,°C,W/g
32.49,245.11,-0.054
32.52,245.11,-0.054
32.54,245.10,-0.054
32.56,245.08,-0.056
32.58,245.05,-0.076
32.60,244.98,-0.106
32.62,244.89,-0.148
32.64,244.77,-0.196
32.67,244.62,-0.244
32.69,244.46,-0.284
32.71,244.29,-0.318
32.73,244.10,-0.344
32.75,243.91,-0.364
32.78,243.71,-0.377
32.80,243.51,-0.387
32.82,243.31,-0.395
32.84,243.10,-0.402
32.86,242.89,-0.406
32.88,242.68,-0.410
32.91,242.47,-0.414
32.93,242.26,-0.415
32.95,242.05,-0.417
32.97,241.83,-0.418
32.99,241.62,-0.418
33.01,241.41,-0.419
33.03,241.19,-0.419
33.06,240.98,-0.420
33.08,240.77,-0.420
33.10,240.55,-0.420
33.12,240.34,-0.421
33.14,240.12,-0.421
33.17,239.91,-0.421
33.19,239.70,-0.421
33.21,239.48,-0.421
33.23,239.27,-0.421
33.25,239.05,-0.422
33.27,238.84,-0.422
33.29,238.62,-0.422
33.32,238.41,-0.422
33.34,238.19,-0.422
33.36,237.98,-0.422
33.38,237.76,-0.422
33.40,237.55,-0.422
33.43,237.33,-0.422
33.45,237.12,-0.422
33.47,236.90,-0.422
33.49,236.69,-0.422
33.51,236.47,-0.422
33.53,236.25,-0.422
33.56,236.04,-0.422
33.58,235.82,-0.422
33.60,235.61,-0.422
33.62,235.39,-0.422
33.64,235.18,-0.422
33.66,234.96,-0.422
33.68,234.74,-0.422
33.71,234.53,-0.422
33.73,234.31,-0.422
33.75,234.10,-0.422
33.77,233.88,-0.422
33.79,233.66,-0.421
33.82,233.45,-0.421
33.84,233.23,-0.421
33.86,233.02,-0.421
33.88,232.80,-0.421
33.90,232.59,-0.421
33.92,232.37,-0.421
33.94,232.15,-0.421
33.97,231.94,-0.420
33.99,231.72,-0.420
34.01,231.50,-0.420
34.03,231.29,-0.420
34.05,231.07,-0.420
34.08,230.85,-0.420
34.10,230.64,-0.419
34.12,230.42,-0.419
34.14,230.21,-0.419
34.16,229.99,-0.419
34.18,229.77,-0.419
34.21,229.56,-0.419
34.23,229.34,-0.418
34.25,229.12,-0.418
34.27,228.91,-0.418
34.29,228.69,-0.418
34.31,228.48,-0.418
34.34,228.26,-0.417
34.36,228.04,-0.417
34.38,227.83,-0.417
34.40,227.61,-0.417
34.42,227.40,-0.417
34.44,227.18,-0.416
34.46,226.96,-0.416
34.49,226.75,-0.416
34.51,226.53,-0.416
34.53,226.31,-0.416
34.55,226.10,-0.416
34.57,225.88,-0.415
34.59,225.67,-0.415
34.62,225.45,-0.415
34.64,225.23,-0.415
34.66,225.02,-0.414
34.68,224.80,-0.414
34.70,224.58,-0.414
34.73,224.37,-0.414
34.75,224.15,-0.414
34.77,223.93,-0.414
34.79,223.72,-0.414
34.81,223.50,-0.414
34.83,223.29,-0.413
34.86,223.07,-0.413
34.88,222.85,-0.413
34.90,222.64,-0.413
34.92,222.42,-0.413
34.94,222.20,-0.413
34.96,221.99,-0.413
34.99,221.77,-0.412
35.01,221.55,-0.412
35.03,221.34,-0.412
35.05,221.12,-0.412
35.07,220.90,-0.412
35.09,220.69,-0.412
35.11,220.47,-0.412
35.14,220.26,-0.411
35.16,220.04,-0.411
35.18,219.82,-0.411
35.20,219.61,-0.411
35.22,219.39,-0.411
35.24,219.18,-0.410
35.27,218.96,-0.410
35.29,218.74,-0.410
35.31,218.52,-0.410
35.33,218.31,-0.410
35.35,218.09,-0.410
35.38,217.87,-0.410
35.40,217.66,-0.410
35.42,217.44,-0.409
35.44,217.22,-0.409
35.46,217.01,-0.409
35.48,216.79,-0.409
35.51,216.58,-0.408
35.53,216.36,-0.408
35.55,216.14,-0.408
35.57,215.93,-0.408
35.59,215.71,-0.408
35.61,215.49,-0.408
35.64,215.28,-0.407
35.66,215.06,-0.407
35.68,214.85,-0.407
35.70,214.63,-0.407
35.72,214.41,-0.407
35.74,214.20,-0.407
35.76,213.98,-0.406
35.79,213.76,-0.406
35.81,213.55,-0.406
35.83,213.33,-0.406
35.85,213.11,-0.406
35.87,212.90,-0.406
35.89,212.68,-0.406
35.92,212.46,-0.406
35.94,212.25,-0.406
35.96,212.03,-0.406
35.98,211.81,-0.405
36.00,211.60,-0.405
36.03,211.38,-0.405
36.05,211.17,-0.405
36.07,210.95,-0.405
36.09,210.73,-0.405
36.11,210.52,-0.405
36.13,210.30,-0.404
36.16,210.08,-0.404
36.18,209.87,-0.404
36.20,209.65,-0.404
36.22,209.43,-0.404
36.24,209.22,-0.404
36.26,209.00,-0.404
36.29,208.79,-0.403
36.31,208.57,-0.403
36.33,208.35,-0.403
36.35,208.13,-0.403
36.37,207.92,-0.403
36.39,207.70,-0.403
36.41,207.49,-0.403
36.44,207.27,-0.403
36.46,207.05,-0.402
36.48,206.84,-0.402
36.50,206.62,-0.402
36.52,206.40,-0.402
36.54,206.19,-0.402
36.57,205.97,-0.402
36.59,205.76,-0.402
36.61,205.54,-0.402
36.63,205.32,-0.402
36.65,205.11,-0.402
36.68,204.89,-0.401
36.70,204.67,-0.401
36.72,204.46,-0.401
36.74,204.24,-0.401
36.76,204.02,-0.401
36.78,203.80,-0.401
36.81,203.59,-0.401
36.83,203.37,-0.401
36.85,203.16,-0.401
36.87,202.94,-0.400
36.89,202.72,-0.400
36.91,202.51,-0.400
36.94,202.29,-0.400
36.96,202.07,-0.400
36.98,201.86,-0.400
37.00,201.64,-0.400
37.02,201.43,-0.399
37.04,201.21,-0.399
37.06,200.99,-0.399
37.09,200.78,-0.399
37.11,200.56,-0.399
37.13,200.34,-0.399
37.15,200.13,-0.399
37.17,199.91,-0.399
37.19,199.69,-0.399
37.22,199.48,-0.399
37.24,199.26,-0.399
37.26,199.04,-0.398
37.28,198.83,-0.398
37.30,198.61,-0.398
37.33,198.39,-0.398
37.35,198.18,-0.398
37.37,197.96,-0.398
37.39,197.75,-0.398
37.41,197.53,-0.398
37.43,197.31,-0.398
37.46,197.10,-0.397
37.48,196.88,-0.397
37.50,196.66,-0.397
37.52,196.45,-0.397
37.54,196.23,-0.397
37.56,196.01,-0.397
37.59,195.80,-0.397
37.61,195.58,-0.397
37.63,195.36,-0.396
37.65,195.15,-0.396
37.67,194.93,-0.396
37.69,194.71,-0.396
37.71,194.50,-0.396
37.74,194.28,-0.396
37.76,194.07,-0.396
37.78,193.85,-0.396
37.80,193.63,-0.396
37.82,193.42,-0.396
37.84,193.20,-0.395
37.87,192.98,-0.395
37.89,192.77,-0.395
37.91,192.55,-0.395
37.93,192.34,-0.395
37.95,192.12,-0.395
37.98,191.90,-0.395
38.00,191.69,-0.395
38.02,191.47,-0.395
38.04,191.25,-0.395
38.06,191.04,-0.395
38.08,190.82,-0.395
38.11,190.60,-0.395
38.13,190.39,-0.394
38.15,190.17,-0.394
38.17,189.95,-0.394
38.19,189.74,-0.394
38.21,189.52,-0.394
38.24,189.31,-0.394
38.26,189.09,-0.394
38.28,188.87,-0.394
38.30,188.66,-0.394
38.32,188.44,-0.394
38.34,188.22,-0.393
38.36,188.01,-0.393
38.39,187.79,-0.393
38.41,187.57,-0.393
38.43,187.36,-0.393
38.45,187.14,-0.393
38.47,186.92,-0.393
38.49,186.71,-0.393
38.52,186.49,-0.393
38.54,186.27,-0.393
38.56,186.06,-0.393
38.58,185.84,-0.393
38.60,185.63,-0.393
38.63,185.41,-0.392
38.65,185.19,-0.392
38.67,184.97,-0.392
38.69,184.76,-0.392
38.71,184.54,-0.392
38.73,184.33,-0.392
38.76,184.11,-0.392
38.78,183.89,-0.392
38.80,183.68,-0.392
38.82,183.46,-0.392
38.84,183.24,-0.391
38.86,183.03,-0.391
38.89,182.81,-0.391
38.91,182.60,-0.391
38.93,182.38,-0.391
38.95,182.16,-0.391
38.97,181.95,-0.391
38.99,181.73,-0.391
39.01,181.51,-0.391
39.04,181.30,-0.391
39.06,181.08,-0.391
39.08,180.87,-0.390
39.10,180.65,-0.390
39.12,180.43,-0.390
39.14,180.22,-0.390
39.17,180.00,-0.390
39.19,179.78,-0.390
39.21,179.57,-0.390
39.23,179.35,-0.390
39.25,179.13,-0.390
39.28,178.92,-0.390
39.30,178.70,-0.390
39.32,178.48,-0.390
39.34,178.27,-0.390
39.36,178.05,-0.390
39.38,177.83,-0.390
39.41,177.62,-0.390
39.43,177.40,-0.390
39.45,177.18,-0.390
39.47,176.97,-0.390
39.49,176.75,-0.390
39.51,176.53,-0.389
39.54,176.32,-0.389
39.56,176.10,-0.389
39.58,175.88,-0.389
39.60,175.67,-0.389
39.62,175.45,-0.389
39.64,175.24,-0.389
39.66,175.02,-0.388
39.69,174.80,-0.388
39.71,174.59,-0.388
39.73,174.37,-0.388
39.75,174.15,-0.388
39.77,173.94,-0.388
39.79,173.72,-0.388
39.82,173.50,-0.388
39.84,173.29,-0.388
39.86,173.07,-0.388
39.88,172.85,-0.387
39.90,172.64,-0.387
39.93,172.42,-0.387
39.95,172.21,-0.387
39.97,171.99,-0.387
39.99,171.77,-0.387
40.01,171.56,-0.387
40.03,171.34,-0.387
40.06,171.12,-0.387
40.08,170.91,-0.387
40.10,170.69,-0.387
40.12,170.47,-0.387
[...]
198.65,-25.08,0.196,1.034
198.66,-25.01,0.196,1.034
198.67,-24.94,0.196,1.034
198.68,-24.87,0.196,1.035
198.68,-24.81,0.196,1.035
198.69,-24.74,0.196,1.035
198.70,-24.67,0.196,1.035
198.70,-24.61,0.196,1.036
198.71,-24.54,0.196,1.036
198.72,-24.48,0.196,1.036
198.72,-24.41,0.196,1.036
198.73,-24.34,0.196,1.036
198.73,-24.27,0.196,1.036
198.74,-24.21,0.196,1.036
198.75,-24.14,0.196,1.037
198.75,-24.07,0.196,1.036
198.76,-24.01,0.196,1.036
198.77,-23.94,0.196,1.037
198.78,-23.87,0.196,1.037
198.78,-23.81,0.196,1.037
198.79,-23.74,0.196,1.037
198.80,-23.67,0.196,1.038
198.80,-23.61,0.196,1.038
198.81,-23.54,0.196,1.037
198.82,-23.47,0.196,1.037
198.82,-23.41,0.196,1.037
198.83,-23.34,0.196,1.038
198.83,-23.27,0.196,1.038
198.84,-23.21,0.196,1.038
198.85,-23.14,0.196,1.038
198.85,-23.07,0.196,1.038
198.86,-23.01,0.196,1.039
198.87,-22.94,0.196,1.039
198.88,-22.87,0.196,1.039
198.88,-22.81,0.196,1.039
198.89,-22.74,0.196,1.040
198.90,-22.67,0.196,1.040
198.90,-22.60,0.196,1.040
198.91,-22.54,0.196,1.040
198.92,-22.47,0.196,1.041
198.92,-22.40,0.196,1.041
198.93,-22.34,0.196,1.041
198.93,-22.27,0.196,1.041
198.94,-22.20,0.196,1.041
198.95,-22.14,0.196,1.041
198.95,-22.07,0.196,1.041
198.96,-22.00,0.197,1.041
198.97,-21.94,0.197,1.042
198.98,-21.87,0.197,1.042
198.98,-21.80,0.197,1.042
198.99,-21.74,0.197,1.042
199.00,-21.67,0.197,1.042
199.00,-21.60,0.197,1.042
199.01,-21.54,0.197,1.043
199.02,-21.47,0.197,1.043
199.02,-21.40,0.197,1.043
199.03,-21.34,0.197,1.043
199.03,-21.27,0.197,1.043
199.04,-21.20,0.197,1.043
199.05,-21.14,0.197,1.044
199.05,-21.07,0.197,1.044
199.06,-21.00,0.197,1.044
199.07,-20.94,0.197,1.044
199.08,-20.87,0.197,1.045
199.08,-20.80,0.197,1.044
199.09,-20.74,0.197,1.044
199.10,-20.67,0.197,1.044
199.10,-20.60,0.197,1.044
199.11,-20.54,0.197,1.045
199.12,-20.47,0.197,1.045
199.12,-20.40,0.197,1.045
199.13,-20.34,0.197,1.045
199.13,-20.27,0.197,1.045
199.14,-20.20,0.197,1.045
199.15,-20.14,0.197,1.045
199.15,-20.07,0.197,1.045
199.16,-20.00,0.197,1.045
199.17,-19.94,0.197,1.046
199.18,-19.87,0.197,1.046
199.18,-19.80,0.197,1.046
199.19,-19.73,0.197,1.046
199.20,-19.67,0.197,1.046
199.20,-19.60,0.197,1.046
199.21,-19.53,0.197,1.047
199.22,-19.47,0.197,1.047
199.22,-19.40,0.197,1.047
199.23,-19.33,0.197,1.047
199.23,-19.27,0.197,1.047
199.24,-19.20,0.197,1.047
199.25,-19.13,0.197,1.047
199.25,-19.07,0.197,1.047
199.26,-19.00,0.197,1.047
199.27,-18.93,0.197,1.048
199.28,-18.87,0.198,1.048
199.28,-18.80,0.198,1.048
199.29,-18.73,0.198,1.048
199.30,-18.67,0.198,1.049
199.30,-18.60,0.198,1.049
199.31,-18.53,0.198,1.049
199.32,-18.47,0.198,1.049
199.32,-18.40,0.198,1.049
199.33,-18.33,0.198,1.049
199.33,-18.26,0.198,1.050
199.34,-18.20,0.198,1.050
199.35,-18.13,0.198,1.050
199.35,-18.07,0.198,1.050
199.36,-18.00,0.198,1.050
199.37,-17.93,0.198,1.050
199.38,-17.87,0.198,1.050
199.38,-17.80,0.198,1.051
199.39,-17.73,0.198,1.051
199.40,-17.67,0.198,1.051
199.40,-17.60,0.198,1.051
199.41,-17.53,0.198,1.051
199.42,-17.46,0.198,1.051
199.42,-17.40,0.198,1.052
199.43,-17.33,0.198,1.052
199.43,-17.26,0.198,1.052
199.44,-17.20,0.198,1.052
199.45,-17.13,0.198,1.052
199.45,-17.06,0.198,1.052
199.46,-17.00,0.198,1.052
199.47,-16.93,0.198,1.052
199.48,-16.86,0.198,1.053
199.48,-16.80,0.198,1.053
199.49,-16.73,0.198,1.053
199.50,-16.66,0.198,1.053
199.50,-16.60,0.198,1.053
199.51,-16.53,0.198,1.053
199.52,-16.46,0.198,1.054
199.52,-16.40,0.198,1.054
199.53,-16.33,0.198,1.054
199.53,-16.26,0.198,1.054
199.54,-16.19,0.198,1.054
199.55,-16.13,0.198,1.055
199.55,-16.06,0.198,1.054
199.56,-16.00,0.198,1.055
199.57,-15.93,0.198,1.055
199.58,-15.86,0.198,1.055
199.58,-15.80,0.198,1.055
199.59,-15.73,0.198,1.055
199.60,-15.66,0.198,1.055
199.60,-15.60,0.199,1.055
199.61,-15.53,0.199,1.056
199.62,-15.46,0.199,1.055
199.62,-15.39,0.199,1.055
199.63,-15.33,0.199,1.056
199.63,-15.26,0.199,1.056
199.64,-15.19,0.199,1.057
199.65,-15.13,0.199,1.057
199.65,-15.06,0.199,1.057
199.66,-14.99,0.199,1.057
199.67,-14.93,0.199,1.057
199.68,-14.86,0.199,1.057
199.68,-14.79,0.199,1.057
199.69,-14.73,0.199,1.058
199.70,-14.66,0.199,1.058
199.70,-14.59,0.199,1.058
199.71,-14.53,0.199,1.058
199.72,-14.46,0.199,1.059
199.72,-14.39,0.199,1.059
199.73,-14.33,0.199,1.059
199.73,-14.26,0.199,1.059
199.74,-14.19,0.199,1.058
199.75,-14.13,0.199,1.059
199.75,-14.06,0.199,1.059
199.76,-13.99,0.199,1.059
199.77,-13.93,0.199,1.059
199.78,-13.86,0.199,1.060
199.78,-13.79,0.199,1.060
199.79,-13.72,0.199,1.060
199.80,-13.66,0.199,1.060
199.80,-13.59,0.199,1.061
199.81,-13.53,0.199,1.061
199.82,-13.46,0.199,1.061
199.82,-13.39,0.199,1.061
199.83,-13.33,0.199,1.061
199.83,-13.26,0.199,1.061
199.84,-13.19,0.199,1.061
199.85,-13.12,0.199,1.062
199.85,-13.06,0.199,1.062
199.86,-12.99,0.199,1.061
199.87,-12.92,0.199,1.061
199.88,-12.86,0.200,1.062
199.88,-12.79,0.200,1.062
199.89,-12.72,0.200,1.063
199.90,-12.66,0.200,1.063
199.90,-12.59,0.200,1.063
199.91,-12.52,0.200,1.063
199.92,-12.46,0.200,1.063
199.92,-12.39,0.200,1.063
199.93,-12.32,0.200,1.063
199.93,-12.26,0.200,1.064
199.94,-12.19,0.200,1.064
199.95,-12.12,0.200,1.064
199.95,-12.06,0.200,1.065
199.96,-11.99,0.200,1.065
199.97,-11.92,0.200,1.065
199.98,-11.86,0.200,1.065
199.98,-11.79,0.200,1.065
199.99,-11.72,0.200,1.065
200.00,-11.66,0.200,1.065
200.00,-11.59,0.200,1.065
200.01,-11.52,0.200,1.065
200.02,-11.46,0.200,1.065
200.02,-11.39,0.200,1.066
200.03,-11.32,0.200,1.066
200.03,-11.26,0.200,1.066
200.04,-11.19,0.200,1.066
200.05,-11.12,0.200,1.066
200.05,-11.06,0.200,1.067
200.06,-10.99,0.200,1.067
200.07,-10.92,0.200,1.067
200.08,-10.86,0.200,1.067
200.08,-10.79,0.200,1.067
200.09,-10.72,0.200,1.067
200.10,-10.65,0.200,1.067
200.10,-10.59,0.200,1.067
200.11,-10.52,0.200,1.067
200.12,-10.46,0.200,1.067
200.12,-10.39,0.200,1.068
200.13,-10.32,0.200,1.068
200.13,-10.26,0.200,1.068
200.14,-10.19,0.200,1.068
200.15,-10.12,0.200,1.068
200.15,-10.06,0.200,1.068
200.16,-9.99,0.200,1.068
200.17,-9.92,0.200,1.068
200.18,-9.85,0.200,1.068
200.18,-9.79,0.200,1.068
200.19,-9.72,0.200,1.068
200.20,-9.65,0.200,1.068
200.20,-9.59,0.200,1.069
200.21,-9.52,0.200,1.069
200.22,-9.45,0.200,1.069
200.22,-9.39,0.200,1.069
200.23,-9.32,0.200,1.069
200.23,-9.25,0.200,1.069
200.24,-9.19,0.200,1.070
200.25,-9.12,0.200,1.069
200.25,-9.06,0.200,1.069
200.26,-8.99,0.200,1.069
200.27,-8.92,0.200,1.070
200.28,-8.85,0.201,1.070
200.28,-8.79,0.201,1.070
200.29,-8.72,0.201,1.070
200.30,-8.65,0.201,1.070
200.30,-8.59,0.201,1.070
200.31,-8.52,0.201,1.071
200.32,-8.45,0.201,1.071
200.32,-8.39,0.201,1.071
200.33,-8.32,0.201,1.071
200.33,-8.25,0.201,1.071
200.34,-8.19,0.201,1.071
200.35,-8.12,0.201,1.071
200.35,-8.05,0.201,1.071
200.36,-7.99,0.201,1.071
200.37,-7.92,0.201,1.072
200.38,-7.85,0.201,1.072
200.38,-7.79,0.201,1.072
200.39,-7.72,0.201,1.072
200.40,-7.65,0.201,1.071
200.40,-7.59,0.201,1.072
200.41,-7.52,0.201,1.072
200.42,-7.45,0.201,1.072
200.42,-7.39,0.201,1.072
200.43,-7.32,0.201,1.072
200.43,-7.25,0.201,1.072
200.44,-7.19,0.201,1.072
200.45,-7.12,0.201,1.073
200.45,-7.05,0.201,1.074
200.46,-6.98,0.201,1.073
200.47,-6.92,0.201,1.073
200.48,-6.85,0.201,1.074
200.48,-6.78,0.201,1.074
200.49,-6.72,0.201,1.074
200.50,-6.65,0.201,1.074
200.50,-6.58,0.201,1.074
200.51,-6.52,0.201,1.074
200.52,-6.45,0.201,1.074
200.52,-6.38,0.201,1.075
200.53,-6.32,0.201,1.075
200.53,-6.25,0.201,1.075
200.54,-6.18,0.201,1.075
200.55,-6.12,0.201,1.075
200.55,-6.05,0.201,1.076
200.56,-5.98,0.202,1.075
200.57,-5.92,0.202,1.075
200.58,-5.85,0.202,1.075
200.58,-5.78,0.202,1.076
200.59,-5.71,0.202,1.076
200.60,-5.65,0.202,1.076
200.60,-5.58,0.202,1.077
200.61,-5.51,0.202,1.077
200.62,-5.45,0.202,1.077
200.62,-5.38,0.202,1.077
200.63,-5.31,0.202,1.078
200.63,-5.25,0.202,1.078
200.64,-5.18,0.202,1.078
200.65,-5.11,0.202,1.078
200.65,-5.05,0.202,1.078
200.66,-4.98,0.202,1.078
200.67,-4.91,0.202,1.078
200.68,-4.85,0.202,1.079
200.68,-4.78,0.202,1.079
200.69,-4.71,0.202,1.079
200.70,-4.65,0.202,1.079
200.70,-4.58,0.202,1.079
200.71,-4.51,0.202,1.080
200.72,-4.45,0.202,1.080
200.72,-4.38,0.202,1.080
200.73,-4.31,0.202,1.080
200.73,-4.25,0.202,1.080
200.74,-4.18,0.202,1.080
200.75,-4.11,0.202,1.080
200.75,-4.05,0.202,1.081
200.76,-3.98,0.202,1.081
200.77,-3.91,0.202,1.081
200.78,-3.85,0.202,1.081
200.78,-3.78,0.202,1.081
200.79,-3.71,0.202,1.082
200.80,-3.65,0.202,1.082
200.80,-3.58,0.202,1.082
200.81,-3.51,0.203,1.083
200.82,-3.44,0.203,1.082
200.82,-3.38,0.203,1.082
200.83,-3.31,0.203,1.082
200.83,-3.24,0.203,1.083
200.84,-3.18,0.203,1.083
200.85,-3.11,0.203,1.083
200.85,-3.05,0.203,1.084
200.86,-2.98,0.203,1.083
200.87,-2.91,0.203,1.083
200.88,-2.84,0.203,1.084
200.88,-2.78,0.203,1.084
200.89,-2.71,0.203,1.084
200.90,-2.64,0.203,1.084
200.90,-2.58,0.203,1.084
200.91,-2.51,0.203,1.084
200.92,-2.44,0.203,1.084
200.92,-2.38,0.203,1.085
200.93,-2.31,0.203,1.085
200.93,-2.24,0.203,1.085
200.94,-2.17,0.203,1.085
200.95,-2.11,0.203,1.085
200.95,-2.04,0.203,1.085
200.96,-1.98,0.203,1.086
200.97,-1.91,0.203,1.086
200.98,-1.84,0.203,1.086
200.98,-1.78,0.203,1.086
200.99,-1.71,0.203,1.086
201.00,-1.64,0.203,1.086
201.00,-1.58,0.203,1.086
201.01,-1.51,0.203,1.086
201.02,-1.44,0.203,1.087
201.02,-1.37,0.203,1.087
201.03,-1.31,0.203,1.087
201.03,-1.24,0.203,1.087
201.04,-1.18,0.203,1.088
201.05,-1.11,0.203,1.088
201.05,-1.04,0.203,1.088
201.06,-0.97,0.203,1.088
201.07,-0.91,0.203,1.088
201.08,-0.84,0.203,1.088
201.08,-0.78,0.203,1.088
201.09,-0.71,0.203,1.088
201.10,-0.64,0.203,1.088
201.10,-0.57,0.203,1.088
201.11,-0.51,0.203,1.088
201.12,-0.44,0.204,1.089
201.12,-0.37,0.204,1.089
201.13,-0.31,0.204,1.089
201.13,-0.24,0.204,1.089
201.14,-0.17,0.204,1.089
201.15,-0.11,0.204,1.089
201.15,-0.04,0.204,1.089
201.16,0.03,0.204,1.090
201.17,0.09,0.204,1.090
201.18,0.16,0.204,1.090
201.18,0.23,0.204,1.090
201.19,0.29,0.204,1.090
201.20,0.36,0.204,1.091
201.20,0.43,0.204,1.091
201.21,0.49,0.204,1.091
201.22,0.56,0.204,1.091
201.22,0.63,0.204,1.092
201.23,0.69,0.204,1.092
201.23,0.76,0.204,1.092
201.24,0.83,0.204,1.092
201.25,0.90,0.204,1.092
201.25,0.96,0.204,1.092
201.26,1.03,0.204,1.092
201.27,1.09,0.204,1.092
201.28,1.16,0.204,1.093
201.28,1.23,0.204,1.093
201.29,1.29,0.204,1.093
201.30,1.36,0.204,1.093
201.30,1.43,0.204,1.093
201.31,1.49,0.204,1.094
201.32,1.56,0.204,1.094
201.32,1.63,0.204,1.094
201.33,1.69,0.204,1.094
201.33,1.76,0.204,1.094
201.34,1.83,0.205,1.094
201.35,1.89,0.205,1.094
201.35,1.96,0.205,1.094
201.36,2.03,0.205,1.094
201.37,2.10,0.205,1.094
201.38,2.16,0.205,1.094
201.38,2.23,0.205,1.094
201.39,2.30,0.205,1.094
201.40,2.36,0.205,1.095
201.40,2.43,0.205,1.095
201.41,2.50,0.205,1.096
201.42,2.56,0.205,1.096
201.42,2.63,0.205,1.096
201.43,2.70,0.205,1.096
201.43,2.76,0.205,1.096
201.44,2.83,0.205,1.096
201.45,2.90,0.205,1.097
201.45,2.96,0.205,1.097
201.46,3.03,0.205,1.097
201.47,3.10,0.205,1.097
201.48,3.16,0.205,1.097
201.48,3.23,0.205,1.097
201.49,3.30,0.205,1.098
201.50,3.36,0.205,1.099
201.50,3.43,0.205,1.098
201.51,3.50,0.205,1.098
201.52,3.56,0.205,1.099
201.52,3.63,0.205,1.099
201.53,3.70,0.205,1.099
201.53,3.76,0.205,1.099
201.54,3.83,0.205,1.099
201.55,3.90,0.205,1.099
201.55,3.96,0.205,1.099
201.56,4.03,0.205,1.100
201.57,4.10,0.205,1.100
201.58,4.16,0.205,1.100
201.58,4.23,0.205,1.099
201.59,4.30,0.205,1.100
201.60,4.36,0.205,1.100
201.60,4.43,0.205,1.100
201.61,4.50,0.205,1.099
201.62,4.56,0.205,1.100
201.62,4.63,0.206,1.100
201.63,4.70,0.206,1.100
201.63,4.76,0.206,1.099
201.64,4.83,0.206,1.100
201.65,4.90,0.206,1.100
201.65,4.96,0.206,1.100
201.66,5.03,0.206,1.100
201.67,5.10,0.206,1.100
201.68,5.16,0.206,1.100
201.68,5.23,0.206,1.100
201.69,5.30,0.206,1.100
201.70,5.36,0.206,1.101
201.70,5.43,0.206,1.101
201.71,5.50,0.206,1.101
201.72,5.56,0.206,1.101
201.72,5.63,0.206,1.101
201.73,5.70,0.206,1.101
201.73,5.77,0.206,1.101
201.74,5.83,0.206,1.101
201.75,5.90,0.206,1.102
201.75,5.97,0.206,1.102
201.76,6.03,0.206,1.102
201.77,6.10,0.206,1.102
201.78,6.17,0.206,1.102
201.78,6.23,0.206,1.103
201.79,6.30,0.206,1.103
201.80,6.37,0.206,1.103
201.80,6.43,0.206,1.103
201.81,6.50,0.206,1.104
201.82,6.57,0.206,1.104
201.82,6.63,0.207,1.104
201.83,6.70,0.207,1.104
201.83,6.77,0.207,1.105
201.84,6.83,0.207,1.105
201.85,6.90,0.207,1.105
201.85,6.97,0.207,1.105
201.86,7.03,0.207,1.105
201.87,7.10,0.207,1.105
201.88,7.17,0.207,1.105
201.88,7.24,0.207,1.105
201.89,7.30,0.207,1.106
201.90,7.37,0.207,1.106
201.90,7.44,0.207,1.106
201.91,7.50,0.207,1.107
201.92,7.57,0.207,1.107
201.92,7.64,0.207,1.107
201.93,7.70,0.207,1.107
201.93,7.77,0.207,1.107
201.94,7.84,0.207,1.107
201.95,7.90,0.207,1.108
201.95,7.97,0.207,1.109
201.96,8.04,0.207,1.109
201.97,8.10,0.207,1.108
201.98,8.17,0.207,1.109
201.98,8.24,0.207,1.109
201.99,8.30,0.207,1.109
202.00,8.37,0.207,1.110
202.00,8.44,0.207,1.110
202.01,8.50,0.207,1.110
202.02,8.57,0.207,1.110
202.02,8.64,0.207,1.110
202.03,8.70,0.207,1.110
202.03,8.77,0.207,1.111
202.04,8.84,0.207,1.111
202.05,8.90,0.207,1.111
202.05,8.97,0.208,1.111
202.06,9.04,0.208,1.111
202.07,9.10,0.208,1.111
202.08,9.17,0.208,1.111
202.08,9.24,0.208,1.111
202.09,9.30,0.208,1.112
202.10,9.37,0.208,1.112
202.10,9.44,0.208,1.112
202.11,9.50,0.208,1.112
202.12,9.57,0.208,1.112
202.12,9.64,0.208,1.112
202.13,9.70,0.208,1.112
202.13,9.77,0.208,1.112
202.14,9.84,0.208,1.112
202.15,9.90,0.208,1.112
202.15,9.97,0.208,1.112
202.16,10.04,0.208,1.112
202.17,10.10,0.208,1.113
202.18,10.17,0.208,1.113
202.18,10.24,0.208,1.113
202.19,10.30,0.208,1.113
202.20,10.37,0.208,1.112
202.20,10.44,0.208,1.112
202.21,10.50,0.208,1.113
202.22,10.57,0.208,1.113
202.22,10.64,0.208,1.113
202.23,10.70,0.208,1.113
202.23,10.77,0.208,1.113
202.24,10.84,0.208,1.113
202.25,10.90,0.208,1.113
202.25,10.97,0.208,1.113
202.26,11.04,0.208,1.114
202.27,11.10,0.208,1.114
202.28,11.17,0.208,1.114
202.28,11.24,0.208,1.114
202.29,11.30,0.208,1.114
202.30,11.37,0.208,1.114
202.30,11.44,0.208,1.114
202.31,11.50,0.208,1.114
202.32,11.57,0.208,1.115
202.32,11.64,0.208,1.114
202.33,11.70,0.208,1.114
202.33,11.77,0.209,1.114
202.34,11.84,0.209,1.115
202.35,11.90,0.209,1.115
202.35,11.97,0.209,1.116
202.36,12.04,0.209,1.116
202.37,12.10,0.209,1.115
202.38,12.17,0.209,1.116
202.38,12.24,0.209,1.116
202.39,12.30,0.209,1.116
202.40,12.37,0.209,1.117
202.40,12.44,0.209,1.117
202.41,12.50,0.209,1.117
202.42,12.57,0.209,1.117
202.42,12.64,0.209,1.116
202.43,12.71,0.209,1.116
202.43,12.77,0.209,1.117
202.44,12.84,0.209,1.117
202.45,12.90,0.209,1.118
202.45,12.97,0.209,1.118
202.46,13.04,0.209,1.118
202.47,13.11,0.209,1.118
202.48,13.17,0.209,1.119
202.48,13.24,0.209,1.118
202.49,13.31,0.209,1.118
202.50,13.37,0.209,1.118
202.50,13.44,0.209,1.119
202.51,13.51,0.209,1.119
202.52,13.57,0.209,1.118
202.52,13.64,0.209,1.118
202.53,13.71,0.209,1.119
202.53,13.78,0.210,1.120
202.54,13.84,0.210,1.120
202.55,13.91,0.210,1.120
202.55,13.97,0.210,1.120
202.56,14.04,0.210,1.120
202.57,14.11,0.210,1.120
202.58,14.17,0.210,1.121
202.58,14.24,0.210,1.121
202.59,14.31,0.210,1.121
202.60,14.38,0.210,1.121
202.60,14.44,0.210,1.121
202.61,14.51,0.210,1.121
202.62,14.58,0.210,1.121
202.62,14.64,0.210,1.122
202.63,14.71,0.210,1.122
202.63,14.78,0.210,1.123
202.64,14.84,0.210,1.122
202.65,14.91,0.210,1.123
202.65,14.98,0.210,1.123
202.66,15.04,0.210,1.123
202.67,15.11,0.210,1.122
202.68,15.18,0.210,1.123
202.68,15.24,0.210,1.123
202.69,15.31,0.210,1.124
202.70,15.38,0.210,1.124
202.70,15.44,0.210,1.124
202.71,15.51,0.210,1.123
202.72,15.58,0.210,1.124
202.72,15.64,0.211,1.125
202.73,15.71,0.211,1.125
202.73,15.78,0.211,1.124
202.74,15.84,0.211,1.125
202.75,15.91,0.211,1.125
202.75,15.98,0.211,1.125
202.76,16.05,0.211,1.125
202.77,16.11,0.211,1.125
202.78,16.18,0.211,1.126
202.78,16.25,0.211,1.126
202.79,16.31,0.211,1.126
202.80,16.38,0.211,1.126
202.80,16.45,0.211,1.127
202.81,16.51,0.211,1.127
202.82,16.58,0.211,1.127
202.82,16.65,0.211,1.127
202.83,16.71,0.211,1.128
202.83,16.78,0.211,1.128
202.84,16.85,0.211,1.128
202.85,16.91,0.211,1.128
202.85,16.98,0.211,1.128
202.86,17.05,0.211,1.129
202.87,17.11,0.211,1.130
202.88,17.18,0.211,1.129
202.88,17.25,0.211,1.129
202.89,17.31,0.211,1.130
202.90,17.38,0.211,1.130
202.90,17.45,0.211,1.130
202.91,17.51,0.211,1.130
202.92,17.58,0.212,1.130
202.92,17.65,0.212,1.130
202.93,17.72,0.212,1.131
202.93,17.78,0.212,1.131
202.94,17.85,0.212,1.131
202.95,17.92,0.212,1.131
202.95,17.98,0.212,1.132
202.96,18.05,0.212,1.132
202.97,18.11,0.212,1.132
202.98,18.18,0.212,1.132
202.98,18.25,0.212,1.132
202.99,18.31,0.212,1.133
203.00,18.38,0.212,1.132
203.00,18.45,0.212,1.132
203.01,18.52,0.212,1.133
203.02,18.58,0.212,1.133
203.02,18.65,0.212,1.133
203.03,18.72,0.212,1.133
203.03,18.78,0.212,1.133
203.04,18.85,0.212,1.133
203.05,18.92,0.212,1.134
203.05,18.98,0.212,1.134
203.06,19.05,0.212,1.134
203.07,19.12,0.212,1.134
203.08,19.18,0.212,1.134
203.08,19.25,0.212,1.134
203.09,19.32,0.212,1.134
203.10,19.38,0.212,1.135
203.10,19.45,0.212,1.135
203.11,19.52,0.212,1.135
203.12,19.58,0.212,1.136
203.12,19.65,0.212,1.136
203.13,19.72,0.213,1.136
203.13,19.78,0.213,1.136
203.14,19.85,0.213,1.136
203.15,19.92,0.213,1.137
203.15,19.98,0.213,1.137
203.16,20.05,0.213,1.137
203.17,20.12,0.213,1.137
203.18,20.19,0.213,1.137
203.18,20.25,0.213,1.137
203.19,20.32,0.213,1.137
203.20,20.38,0.213,1.138
203.20,20.45,0.213,1.139
203.21,20.52,0.213,1.139
203.22,20.59,0.213,1.139
203.22,20.65,0.213,1.139
203.23,20.72,0.213,1.139
203.23,20.78,0.213,1.140
203.24,20.85,0.213,1.140
203.25,20.92,0.213,1.140
203.25,20.98,0.213,1.140
203.26,21.05,0.213,1.140
203.27,21.12,0.213,1.140
203.28,21.19,0.213,1.141
203.28,21.25,0.213,1.141
203.29,21.32,0.213,1.141
203.30,21.38,0.214,1.141
203.30,21.45,0.214,1.141
203.31,21.52,0.214,1.142
203.32,21.59,0.214,1.142
203.32,21.65,0.214,1.141
203.33,21.72,0.214,1.141
203.33,21.79,0.214,1.142
203.34,21.85,0.214,1.142
203.35,21.92,0.214,1.143
203.35,21.99,0.214,1.143
203.36,22.05,0.214,1.143
203.37,22.12,0.214,1.143
203.38,22.19,0.214,1.144
203.38,22.25,0.214,1.144
203.39,22.32,0.214,1.144
203.40,22.39,0.214,1.144
203.40,22.45,0.214,1.144
203.41,22.52,0.214,1.145
203.42,22.59,0.214,1.145
203.42,22.65,0.214,1.146
203.43,22.72,0.214,1.146
203.43,22.79,0.214,1.146
203.44,22.85,0.215,1.146
203.45,22.92,0.215,1.147
203.45,22.99,0.215,1.147
203.46,23.05,0.215,1.147
203.47,23.12,0.215,1.147
203.48,23.19,0.215,1.147
203.48,23.26,0.215,1.147
203.49,23.32,0.215,1.147
203.50,23.39,0.215,1.148
203.50,23.46,0.215,1.149
203.51,23.52,0.215,1.149
203.52,23.59,0.215,1.149
203.52,23.66,0.215,1.149
203.53,23.72,0.215,1.150
203.53,23.79,0.215,1.150
203.54,23.86,0.215,1.150
203.55,23.92,0.215,1.150
203.55,23.99,0.215,1.150
203.56,24.06,0.215,1.150
203.57,24.12,0.215,1.151
203.58,24.19,0.215,1.151
203.58,24.26,0.215,1.151
203.59,24.32,0.215,1.151
203.60,24.39,0.215,1.152
203.60,24.46,0.215,1.152
203.61,24.52,0.215,1.152
203.62,24.59,0.215,1.152
203.62,24.66,0.215,1.152
203.63,24.72,0.215,1.152
203.63,24.79,0.216,1.152
203.64,24.86,0.216,1.151
203.65,24.92,0.216,1.152
203.65,24.99,0.216,1.152
203.66,25.06,0.216,1.152
203.67,25.12,0.216,1.152
203.68,25.19,0.216,1.153
203.68,25.26,0.216,1.153
203.69,25.32,0.216,1.154
203.70,25.39,0.216,1.153
203.70,25.46,0.216,1.153
203.71,25.52,0.216,1.154
203.72,25.59,0.216,1.154
203.72,25.66,0.216,1.154
203.73,25.73,0.216,1.154
203.73,25.79,0.216,1.154
203.74,25.86,0.216,1.154
203.75,25.92,0.216,1.154
203.75,25.99,0.216,1.155
203.76,26.06,0.216,1.155
203.77,26.12,0.216,1.155
203.78,26.19,0.216,1.156
203.78,26.26,0.216,1.156
203.79,26.32,0.216,1.155
203.80,26.39,0.216,1.155
203.80,26.46,0.216,1.155
203.81,26.53,0.216,1.157
203.82,26.59,0.216,1.157
203.82,26.66,0.217,1.157
203.83,26.73,0.217,1.157
203.83,26.79,0.217,1.158
203.84,26.86,0.217,1.158
203.85,26.93,0.217,1.158
203.85,26.99,0.217,1.158
203.86,27.06,0.217,1.159
203.87,27.13,0.217,1.159
203.88,27.19,0.217,1.159
203.88,27.26,0.217,
203.89,27.33,0.217,
203.90,27.39,0.217,
203.90,27.46,0.217,
203.91,27.53,0.217,
203.92,27.59,0.217,
203.92,27.66,0.217,
203.93,27.73,0.217,
203.93,27.79,0.217,
203.94,27.86,,
203.95,27.93,,
203.95,27.99,,
203.96,28.06,,
203.97,28.13,,
203.98,28.19,,
203.98,28.26,,
203.99,,,
203.99,,,