File: DSC/2025_06_03_Nifedipine_0C_190C_10Cmin_x3.csv
Filename,2025_06_03_Nifedipine_0C_190C_10Cmin_x3
Instrument name,DSC2A-00468 (192.168.1.100)
Operator,Yarger
rundate,6/3/2025
Sample name,2025_06_03_Nifedipine_0C_190C_10Cmin_x3
proceduresegments,Data Off ; Equilibrate 0.00 °C; Data On ; Ramp 10.00 °C/min to 190.00 °C; Data Off ; Isothermal 1.0 min; Data On ; Ramp 10.00 °C/min to 0.00 °C; Data Off ; Isothermal 1.0 min; Data On ; Ramp 10.00 °C/min to 190.00 °C; Data Off ; Isothermal 1.0 min; Data On ; Ramp 10.00 °C/min to 0.00 °C; Data Off ; Isothermal 1.0 min; Data On ; Ramp 10.00 °C/min to 30.00 °C
[File Parameters]
Run date,6/3/2025 7:54:19 AM
Trios version,5.1.1.46572
Original File Name,
Current File Name,D:\DSC2500\JYarger\2025_06_03_Nifedipine_0C_190C_10Cmin_x3.tri
[Procedure]
Procedure Name,NIF_0C_190C_10Cmin_x3
Sample Name,2025_06_03_Nifedipine_0C_190C_10Cmin_x3
Sample Mass,21.5 mg
Reference Sample Mass,0 mg
Pan Mass,56.74 mg
Pan Number,24
Reference Pan Mass,56.96 mg
Reference Pan Number,10
Pan Type,Tzero Aluminum Hermetic
Comments,Al Hermetic DSC Consumables sealed Pan/Lid. A2 Tray (Google Sheet: DSC_Samples_A2_Tray_May2025)
Project Name,CA
Operator,Yarger
Test,Custom
Unload Max Temperature,30
Unload Min Temperature,30
Load Max Temperature,30
Load Min Temperature,30
Stop on Gas Flow Error,Yes
[Signal List]
Signal #1,Time (min)
Signal #2,Temperature (°C)
Signal #3,Heat Flow (mW)
Signal #4,Delta T (µV)
Signal #5,Delta Tzero (µV)
Signal #6,Tzero Temperature (°C)
Signal #7,Cell Purge (mL/min)
Signal #8,Heater Temp (°C)
Signal #9,Power Delivered (W)
Signal #10,Reference Junction Temperature (°C)
Signal #11,Flange Temperature (°C)
Signal #12,Heat Flow Phase (rad)
Signal #13,Total Heat Capacity (J/°C)
Signal #14,Heat Capacity (J/°C)
[Configuration]
Company Name,ASU
Instrument Name,DSC2A-00468
Instrument Type,DSC2500
Serial Number,DSC2A-00468
IP,192.168.1.100
Location of Instrument,MRRC
DisplayType,Unknown
Sample Interval ,0.1 s/pt
Selected Heat Flow,T4P
Exotherm Direction,Down
Cell Serial,DRC2-00792
Lid Type,Standard
Cooler,RCS 90
Leave Cooler on at End of Sequence,On
Gas 2,Nitrogen
Gas Selected,Channel 1
Flow Rate,50 mL/min
Secondary Purge,On
Licensed Heat Flow,Heat Flow T4P
Modulation Licensed,Yes
[Versions]
Common IDD Version,1
Cortex Version,VER 2.10.2.31
Driver,5.0.0.6
GDM Version,1.0.3.3
TouchscreenVersion,1.0.0.16145
FEP Version,1.2.1.21
FEP Bootloader,2.0.0.5
AutoSampler Version,2.1.1.26
Auto Sampler Bootloader,2.0.0.5
FCM Version,1.1.0.3
FCM Bootloader,2.0.0.5
[Experiment Logs]
Experiment Log Entry # 1,Data On set to 0
Experiment Log Entry # 3,Equilibrate Segment 0 (C) Started
Experiment Log Entry # 5,Air Cool is off.
Experiment Log Entry # 7,Data On set to 1
Experiment Log Entry # 9,Ramp Segment 10 C/min to 190 Started
Experiment Log Entry # 11,Data On set to 0
Experiment Log Entry # 13,Isothermal Segment 1 min started
Experiment Log Entry # 15,Data On set to 1
Experiment Log Entry # 17,Ramp Segment 10 C/min to 0 Started
Experiment Log Entry # 19,Data On set to 0
Experiment Log Entry # 21,Isothermal Segment 1 min started
Experiment Log Entry # 23,Data On set to 1
Experiment Log Entry # 25,Ramp Segment 10 C/min to 190 Started
Experiment Log Entry # 27,Data On set to 0
Experiment Log Entry # 29,Isothermal Segment 1 min started
Experiment Log Entry # 31,Data On set to 1
Experiment Log Entry # 33,Ramp Segment 10 C/min to 0 Started
Experiment Log Entry # 35,Data On set to 0
Experiment Log Entry # 37,Isothermal Segment 1 min started
Experiment Log Entry # 39,Data On set to 1
Experiment Log Entry # 41,Ramp Segment 10 C/min to 30 Started
[Method Log]
Method Log Entry # 1,Data Off
Method Log Entry # 2,Equilibrate 0 °C
Method Log Entry # 3,Data On
Method Log Entry # 4,(Ramp 806775) Ramp 10 °C/minute to 190 °C
Method Log Entry # 5,Data Off
Method Log Entry # 6,Isothermal 1 minutes
Method Log Entry # 7,Data On
Method Log Entry # 8,(Ramp 806779) Ramp 10 °C/minute to 0 °C
Method Log Entry # 9,Data Off
Method Log Entry # 10,Isothermal 1 minutes
Method Log Entry # 11,Data On
Method Log Entry # 12,(Ramp 806783) Ramp 10 °C/minute to 190 °C
Method Log Entry # 13,Data Off
Method Log Entry # 14,Isothermal 1 minutes
Method Log Entry # 15,Data On
Method Log Entry # 16,(Ramp 806787) Ramp 10 °C/minute to 0 °C
Method Log Entry # 17,Data Off
Method Log Entry # 18,Isothermal 1 minutes
Method Log Entry # 19,Data On
Method Log Entry # 20,(Ramp 806791) Ramp 10 °C/minute to 30 °C
Cell Serial,DRC2-00792
[T1 Calibration]
Slope,-0.008529666
Offset,9.636258
Initial Temperature,98.23
GUID,f8bfdadc-4977-4fdf-ba6d-0ba9134940c3
[TZero Calibration]
Date Applied,11/29/2022 4:06:13 PM
Description,From -89.059 °C to 396.009 °C at 20.000°C/min
Gas Type,Nitrogen
Pan Type,None
Source Files 1,C:\Users\yargerlab\Desktop\DSC Data\General\TZero_calibration_11_29_22_2nd(2).tri
Source Files 2,C:\Users\yargerlab\Desktop\DSC Data\General\TZero_calibration_11_29_22_2nd(3).tri
Delta T Offset,13.05235
Delta T Slope,-0.007271007
Delta T0 Offset,-13.69128
Delta T0 Slope,0.06063341
[Temperature Calibration]
Date Applied,11/29/2022 7:12:28 PM
Description,From 106.590 °C to 186.590 °C at 10.000°C/min
Gas Type,Nitrogen
Pan Type,Tzero Aluminum Hermetic
Source Files 1,C:\Users\yargerlab\Desktop\DSC Data\General\Indium(6).tri
Measured 1,157.391
Known 1,156.598
[Cell Constant Calibration]
Date Applied,11/29/2022 7:12:29 PM
Description,From 106.590 °C to 186.590 °C at 10.000°C/min
Gas Type,Nitrogen
Pan Type,Tzero Aluminum Hermetic
Source Files 1,C:\Users\yargerlab\Desktop\DSC Data\General\Indium(6).tri
T4P KCell,1.006051
Onset Slope,63.26126 mW/°C
[Direct Cp Calibration]
Date Applied,11/30/2022 11:04:51 AM
Description,From -79.983 °C to 298.409 °C at 10.000°C/min
Gas Type,Nitrogen
Pan Type,Tzero Aluminum Hermetic
Source Files 1,C:\Users\yargerlab\Desktop\DSC Data\General\Sapphire_Heat_Capacity_11_30_22.tri
[Rev Cp Calibration]
Date Applied,11/30/2022 1:58:51 PM
Description,From -79.996 °C to 292.812 °C at 3.000°C/min
Gas Type,Nitrogen
Pan Type,Tzero Aluminum Hermetic
Source Files 1,C:\Users\yargerlab\Desktop\DSC Data\General\Sapphire_MDSC_Calibration_11_30_22.tri
[step]
Ramp 10.00 °C/min to 190.00 °C
Time,Temperature,Heat Flow (Normalized)
min,°C,W/g
0.00,0.18,-0.039
0.01,0.18,-0.039
0.03,0.17,-0.036
0.04,0.17,-0.033
0.05,0.17,-0.031
0.07,0.18,-0.029
0.08,0.19,-0.027
0.09,0.22,-0.025
0.11,0.25,-0.021
0.12,0.30,-0.016
0.13,0.36,-0.008
0.15,0.42,0.001
0.16,0.49,0.011
0.17,0.57,0.022
0.19,0.65,0.033
0.20,0.74,0.044
0.21,0.83,0.054
0.23,0.92,0.063
0.24,1.02,0.072
0.25,1.12,0.079
0.27,1.22,0.087
0.28,1.32,0.094
0.29,1.43,0.101
0.31,1.54,0.107
0.32,1.65,0.113
0.33,1.76,0.118
0.35,1.88,0.123
0.36,1.99,0.128
0.37,2.10,0.132
0.39,2.23,0.136
0.40,2.34,0.140
0.41,2.46,0.143
0.43,2.58,0.146
0.44,2.70,0.149
0.45,2.83,0.152
0.47,2.95,0.154
0.48,3.07,0.156
0.49,3.20,0.159
0.51,3.32,0.161
0.52,3.45,0.162
0.53,3.57,0.164
0.55,3.70,0.165
0.56,3.83,0.167
0.57,3.95,0.168
0.59,4.08,0.170
0.60,4.21,0.171
0.61,4.34,0.172
0.63,4.47,0.173
0.64,4.60,0.174
0.65,4.72,0.175
0.67,4.85,0.175
0.68,4.98,0.176
0.69,5.11,0.177
0.71,5.24,0.177
0.72,5.37,0.178
0.73,5.50,0.178
0.75,5.63,0.179
0.76,5.76,0.179
0.77,5.90,0.180
0.79,6.03,0.180
0.80,6.16,0.181
0.81,6.29,0.181
0.83,6.42,0.181
0.84,6.55,0.182
0.85,6.68,0.182
0.87,6.81,0.182
0.88,6.95,0.183
0.89,7.08,0.183
0.91,7.21,0.183
0.92,7.34,0.183
0.93,7.47,0.184
0.95,7.61,0.184
0.96,7.74,0.184
0.97,7.87,0.184
0.99,8.00,0.184
1.00,8.13,0.184
1.01,8.27,0.185
1.03,8.40,0.185
1.04,8.53,0.185
1.05,8.66,0.185
1.07,8.79,0.185
1.08,8.93,0.185
1.09,9.06,0.185
1.11,9.19,0.186
1.12,9.32,0.186
1.13,9.46,0.186
1.15,9.59,0.186
1.16,9.72,0.186
1.17,9.85,0.186
1.19,9.99,0.186
1.20,10.12,0.186
1.21,10.25,0.186
1.23,10.39,0.187
1.24,10.52,0.187
1.25,10.65,0.187
1.27,10.79,0.187
1.28,10.92,0.187
1.29,11.05,0.187
1.31,11.18,0.187
1.32,11.32,0.187
1.33,11.45,0.188
1.35,11.58,0.188
1.36,11.72,0.188
1.37,11.85,0.188
1.39,11.98,0.188
1.40,12.12,0.188
1.41,12.25,0.188
1.43,12.38,0.188
1.44,12.52,0.189
1.45,12.65,0.189
1.47,12.78,0.189
1.48,12.91,0.189
1.49,13.05,0.189
1.51,13.18,0.189
1.52,13.31,0.189
1.53,13.44,0.189
1.55,13.58,0.189
1.56,13.71,0.189
1.57,13.85,0.189
1.59,13.98,0.189
1.60,14.11,0.190
1.61,14.25,0.190
1.63,14.38,0.190
1.64,14.51,0.190
1.65,14.65,0.190
1.67,14.78,0.190
1.68,14.91,0.190
1.69,15.04,0.190
1.71,15.18,0.190
1.72,15.31,0.190
1.73,15.44,0.190
1.75,15.58,0.190
1.76,15.71,0.191
1.77,15.84,0.191
1.79,15.98,0.191
1.80,16.11,0.191
1.81,16.24,0.191
1.83,16.38,0.191
1.84,16.51,0.191
1.85,16.64,0.191
1.87,16.78,0.191
1.88,16.91,0.191
1.89,17.05,0.191
1.91,17.18,0.192
1.92,17.31,0.192
1.93,17.44,0.192
1.95,17.58,0.192
1.96,17.71,0.192
1.97,17.85,0.192
1.99,17.98,0.192
2.00,18.11,0.192
2.01,18.25,0.192
2.03,18.38,0.192
2.04,18.51,0.192
2.05,18.65,0.192
2.07,18.78,0.192
2.08,18.91,0.193
2.09,19.04,0.193
2.11,19.18,0.193
2.12,19.31,0.193
2.13,19.45,0.193
2.15,19.58,0.193
2.16,19.71,0.193
2.17,19.85,0.193
2.19,19.98,0.193
2.20,20.11,0.193
2.21,20.25,0.193
2.23,20.38,0.193
2.24,20.51,0.193
2.25,20.65,0.193
2.27,20.78,0.193
2.28,20.91,0.193
2.29,21.05,0.194
2.31,21.18,0.194
2.32,21.31,0.194
2.33,21.45,0.194
2.35,21.58,0.194
2.36,21.71,0.194
2.37,21.85,0.194
2.39,21.98,0.194
2.40,22.11,0.194
2.41,22.25,0.194
2.43,22.38,0.194
2.44,22.51,0.194
2.45,22.65,0.194
2.47,22.78,0.195
2.48,22.91,0.195
2.49,23.05,0.195
2.51,23.18,0.195
2.52,23.32,0.195
2.53,23.45,0.195
2.55,23.58,0.195
2.56,23.71,0.195
2.57,23.85,0.195
2.59,23.98,0.195
2.60,24.12,0.195
2.61,24.25,0.195
2.63,24.38,0.195
2.64,24.51,0.195
2.65,24.65,0.196
2.67,24.78,0.196
2.68,24.91,0.196
2.69,25.05,0.196
2.71,25.18,0.196
2.72,25.31,0.196
2.73,25.45,0.196
2.75,25.58,0.196
2.76,25.72,0.196
2.77,25.85,0.196
2.79,25.98,0.196
2.80,26.12,0.196
2.81,26.25,0.196
2.83,26.38,0.197
2.84,26.52,0.197
2.85,26.65,0.197
2.87,26.78,0.197
2.88,26.92,0.197
2.89,27.05,0.197
2.91,27.18,0.197
2.92,27.32,0.197
2.93,27.45,0.197
2.95,27.58,0.197
2.96,27.72,0.197
2.97,27.85,0.197
2.99,27.99,0.197
3.00,28.12,0.197
3.01,28.25,0.198
3.03,28.39,0.198
3.04,28.52,0.198
3.05,28.65,0.198
3.07,28.79,0.198
3.08,28.92,0.198
3.09,29.05,0.198
3.11,29.19,0.198
3.12,29.32,0.198
3.13,29.45,0.198
3.15,29.59,0.198
3.16,29.72,0.198
3.17,29.85,0.198
3.19,29.99,0.198
3.20,30.12,0.198
3.21,30.25,0.199
3.23,30.39,0.199
3.24,30.52,0.199
3.25,30.65,0.199
3.27,30.79,0.199
3.28,30.92,0.199
3.29,31.05,0.199
3.31,31.19,0.199
3.32,31.32,0.199
3.33,31.46,0.199
3.35,31.59,0.199
3.36,31.72,0.199
3.37,31.85,0.199
3.39,31.99,0.199
3.40,32.12,0.199
3.41,32.25,0.200
3.43,32.39,0.200
3.44,32.52,0.200
3.45,32.66,0.200
3.47,32.79,0.200
3.48,32.92,0.200
3.49,33.06,0.200
3.51,33.19,0.200
3.52,33.32,0.200
3.53,33.46,0.200
3.55,33.59,0.200
3.56,33.72,0.200
3.57,33.86,0.200
3.59,33.99,0.201
3.60,34.12,0.201
3.61,34.26,0.201
3.63,34.39,0.201
3.64,34.52,0.201
3.65,34.66,0.201
3.67,34.79,0.201
3.68,34.93,0.201
3.69,35.06,0.201
3.71,35.19,0.201
3.72,35.32,0.201
3.73,35.46,0.201
3.75,35.59,0.201
3.76,35.72,0.201
3.77,35.86,0.201
3.79,35.99,0.201
3.80,36.13,0.202
3.81,36.26,0.202
3.83,36.39,0.202
3.84,36.53,0.202
3.85,36.66,0.202
3.87,36.79,0.202
3.88,36.93,0.202
3.89,37.06,0.202
3.91,37.19,0.202
3.92,37.33,0.202
3.93,37.46,0.202
3.95,37.59,0.202
3.96,37.73,0.202
3.97,37.86,0.203
3.99,37.99,0.203
4.00,38.13,0.203
4.01,38.26,0.203
4.03,38.39,0.203
4.04,38.53,0.203
4.05,38.66,0.203
4.07,38.79,0.203
4.08,38.93,0.203
4.09,39.06,0.203
4.11,39.20,0.203
4.12,39.33,0.203
4.13,39.46,0.203
4.15,39.60,0.203
4.16,39.73,0.204
4.17,39.86,0.204
4.19,40.00,0.204
4.20,40.13,0.204
4.21,40.26,0.204
4.23,40.40,0.204
4.24,40.53,0.204
4.25,40.67,0.204
4.27,40.80,0.204
4.28,40.93,0.204
4.29,41.06,0.204
4.31,41.20,0.204
4.32,41.33,0.204
4.33,41.47,0.204
4.35,41.60,0.204
4.36,41.73,0.205
4.37,41.86,0.205
4.39,42.00,0.205
4.40,42.13,0.205
4.41,42.26,0.205
4.43,42.40,0.205
4.44,42.53,0.205
4.45,42.66,0.205
4.47,42.80,0.205
4.48,42.93,0.205
4.49,43.07,0.205
4.51,43.20,0.205
4.52,43.33,0.205
4.53,43.47,0.205
4.55,43.60,0.205
4.56,43.73,0.206
4.57,43.87,0.206
4.59,44.00,0.206
4.60,44.13,0.206
4.61,44.27,0.206
4.63,44.40,0.206
4.64,44.53,0.206
4.65,44.67,0.206
4.67,44.80,0.206
4.68,44.93,0.206
4.69,45.07,0.206
4.71,45.20,0.206
4.72,45.33,0.206
4.73,45.47,0.206
4.75,45.60,0.207
4.76,45.73,0.207
4.77,45.87,0.207
4.79,46.00,0.207
4.80,46.13,0.207
4.81,46.27,0.207
4.83,46.40,0.207
4.84,46.54,0.207
4.85,46.67,0.207
4.87,46.80,0.207
4.88,46.94,0.207
4.89,47.07,0.207
4.91,47.20,0.207
4.92,47.34,0.208
4.93,47.47,0.208
4.95,47.60,0.208
4.96,47.74,0.208
4.97,47.87,0.208
4.99,48.00,0.208
5.00,48.14,0.208
5.01,48.27,0.208
5.03,48.40,0.208
5.04,48.54,0.208
5.05,48.67,0.208
5.07,48.81,0.208
5.08,48.94,0.208
5.09,49.07,0.208
5.11,49.20,0.208
5.12,49.34,0.209
5.13,49.47,0.209
5.15,49.61,0.209
5.16,49.74,0.209
5.17,49.87,0.209
5.19,50.01,0.209
5.20,50.14,0.209
5.21,50.27,0.209
5.23,50.41,0.209
5.24,50.54,0.209
5.25,50.67,0.209
5.27,50.81,0.209
5.28,50.94,0.209
5.29,51.07,0.209
5.31,51.21,0.209
5.32,51.34,0.210
5.33,51.47,0.210
5.35,51.61,0.210
5.36,51.74,0.210
5.37,51.87,0.210
5.39,52.01,0.210
5.40,52.14,0.210
5.41,52.27,0.210
5.43,52.41,0.210
5.44,52.54,0.210
5.45,52.67,0.210
5.47,52.81,0.210
5.48,52.94,0.210
5.49,53.07,0.211
5.51,53.21,0.211
5.52,53.34,0.211
5.53,53.48,0.211
5.55,53.61,0.211
5.56,53.74,0.211
5.57,53.87,0.211
5.59,54.01,0.211
5.60,54.14,0.211
5.61,54.28,0.211
5.63,54.41,0.211
5.64,54.54,0.211
5.65,54.68,0.211
5.67,54.81,0.211
5.68,54.94,0.211
5.69,55.08,0.212
5.71,55.21,0.212
5.72,55.34,0.212
5.73,55.48,0.212
5.75,55.61,0.212
5.76,55.74,0.212
5.77,55.88,0.212
5.79,56.01,0.212
5.80,56.14,0.212
5.81,56.28,0.212
5.83,56.41,0.212
5.84,56.54,0.212
5.85,56.68,0.212
5.87,56.81,0.212
5.88,56.94,0.212
5.89,57.08,0.213
5.91,57.21,0.213
5.92,57.35,0.213
5.93,57.48,0.213
5.95,57.61,0.213
5.96,57.75,0.213
5.97,57.88,0.213
5.99,58.01,0.213
6.00,58.15,0.213
6.01,58.28,0.213
6.03,58.41,0.213
6.04,58.55,0.213
6.05,58.68,0.213
6.07,58.81,0.213
6.08,58.95,0.213
6.09,59.08,0.213
6.11,59.21,0.214
6.12,59.35,0.214
6.13,59.48,0.214
6.15,59.61,0.214
6.16,59.75,0.214
6.17,59.88,0.214
6.19,60.02,0.214
6.20,60.15,0.214
6.21,60.28,0.214
6.23,60.41,0.214
6.24,60.55,0.214
6.25,60.68,0.214
6.27,60.81,0.214
6.28,60.95,0.214
6.29,61.08,0.214
6.31,61.22,0.214
6.32,61.35,0.215
6.33,61.48,0.215
6.35,61.61,0.215
6.36,61.75,0.215
6.37,61.88,0.215
6.39,62.02,0.215
6.40,62.15,0.215
6.41,62.28,0.215
6.43,62.42,0.215
6.44,62.55,0.215
6.45,62.68,0.215
6.47,62.82,0.215
6.48,62.95,0.215
6.49,63.08,0.215
6.51,63.22,0.216
6.52,63.35,0.216
6.53,63.48,0.216
6.55,63.62,0.216
6.56,63.75,0.216
6.57,63.88,0.216
6.59,64.02,0.216
6.60,64.15,0.216
6.61,64.28,0.216
6.63,64.42,0.216
6.64,64.55,0.216
6.65,64.69,0.216
6.67,64.82,0.216
6.68,64.95,0.216
6.69,65.09,0.217
6.71,65.22,0.217
6.72,65.35,0.217
6.73,65.49,0.217
6.75,65.62,0.217
6.76,65.75,0.217
6.77,65.89,0.217
6.79,66.02,0.217
6.80,66.15,0.217
6.81,66.29,0.217
6.83,66.42,0.217
6.84,66.55,0.217
6.85,66.69,0.217
6.87,66.82,0.217
6.88,66.95,0.217
6.89,67.09,0.217
6.91,67.22,0.218
6.92,67.35,0.218
6.93,67.49,0.218
6.95,67.62,0.218
6.96,67.75,0.218
6.97,67.89,0.218
6.99,68.02,0.218
7.00,68.16,0.218
7.01,68.29,0.218
7.03,68.42,0.218
7.04,68.56,0.218
7.05,68.69,0.218
7.07,68.82,0.218
7.08,68.96,0.219
7.09,69.09,0.219
7.11,69.22,0.219
7.12,69.36,0.219
7.13,69.49,0.219
7.15,69.62,0.219
7.16,69.76,0.219
7.17,69.89,0.219
7.19,70.02,0.219
7.20,70.16,0.219
7.21,70.29,0.219
7.23,70.42,0.219
7.24,70.56,0.219
7.25,70.69,0.219
7.27,70.82,0.219
7.28,70.96,0.220
7.29,71.09,0.220
7.31,71.22,0.220
7.32,71.36,0.220
7.33,71.49,0.220
7.35,71.62,0.220
7.36,71.76,0.220
7.37,71.89,0.220
7.39,72.03,0.220
7.40,72.16,0.220
7.41,72.29,0.220
7.43,72.43,0.220
7.44,72.56,0.220
7.45,72.69,0.220
7.47,72.83,0.220
7.48,72.96,0.221
7.49,73.09,0.221
7.51,73.23,0.221
7.52,73.36,0.221
7.53,73.49,0.221
7.55,73.63,0.221
7.56,73.76,0.221
7.57,73.89,0.221
7.59,74.03,0.221
7.60,74.16,0.221
7.61,74.30,0.221
7.63,74.43,0.221
7.64,74.56,0.221
7.65,74.69,0.221
7.67,74.83,0.222
7.68,74.96,0.222
7.69,75.10,0.222
7.71,75.23,0.222
7.72,75.36,0.222
7.73,75.49,0.222
7.75,75.63,0.222
7.76,75.76,0.222
7.77,75.90,0.222
7.79,76.03,0.222
7.80,76.16,0.222
7.81,76.30,0.222
7.83,76.43,0.222
7.84,76.56,0.222
7.85,76.70,0.223
7.87,76.83,0.223
7.88,76.96,0.223
7.89,77.10,0.223
7.91,77.23,0.223
7.92,77.36,0.223
7.93,77.50,0.223
7.95,77.63,0.223
7.96,77.76,0.223
7.97,77.90,0.223
7.99,78.03,0.223
8.00,78.16,0.223
8.01,78.30,0.223
8.03,78.43,0.223
8.04,78.56,0.224
8.05,78.70,0.224
8.07,78.83,0.224
8.08,78.96,0.224
8.09,79.10,0.224
8.11,79.23,0.224
8.12,79.36,0.224
8.13,79.50,0.224
8.15,79.63,0.224
8.16,79.76,0.224
8.17,79.90,0.224
8.19,80.03,0.224
8.20,80.16,0.224
8.21,80.30,0.224
8.23,80.43,0.225
8.24,80.56,0.225
8.25,80.70,0.225
8.27,80.83,0.225
8.28,80.96,0.225
8.29,81.10,0.225
8.31,81.23,0.225
8.32,81.37,0.225
8.33,81.50,0.225
8.35,81.63,0.225
8.36,81.77,0.225
8.37,81.90,0.225
8.39,82.03,0.225
8.40,82.17,0.225
8.41,82.30,0.226
8.43,82.43,0.226
8.44,82.57,0.226
8.45,82.70,0.226
8.47,82.83,0.226
8.48,82.97,0.226
8.49,83.10,0.226
8.51,83.23,0.226
8.52,83.37,0.226
8.53,83.50,0.226
8.55,83.63,0.226
8.56,83.77,0.226
8.57,83.90,0.226
8.59,84.03,0.226
8.60,84.17,0.226
8.61,84.30,0.226
8.63,84.44,0.227
8.64,84.57,0.227
8.65,84.70,0.227
8.67,84.84,0.227
8.68,84.97,0.227
8.69,85.10,0.227
8.71,85.24,0.227
8.72,85.37,0.227
8.73,85.50,0.227
8.75,85.64,0.227
8.76,85.77,0.227
8.77,85.90,0.227
8.79,86.03,0.227
8.80,86.17,0.227
8.81,86.30,0.227
8.83,86.44,0.227
8.84,86.57,0.227
8.85,86.70,0.227
8.87,86.84,0.228
8.88,86.97,0.228
8.89,87.11,0.228
8.91,87.24,0.228
8.92,87.37,0.228
8.93,87.50,0.228
8.95,87.64,0.228
8.96,87.77,0.228
8.97,87.90,0.228
8.99,88.04,0.228
9.00,88.17,0.228
9.01,88.31,0.228
9.03,88.44,0.228
9.04,88.57,0.228
9.05,88.71,0.228
9.07,88.84,0.228
9.08,88.97,0.228
9.09,89.11,0.228
9.11,89.24,0.228
9.12,89.37,0.229
9.13,89.51,0.229
9.15,89.64,0.229
9.16,89.77,0.229
9.17,89.91,0.229
9.19,90.04,0.229
9.20,90.17,0.229
9.21,90.31,0.229
9.23,90.44,0.229
9.24,90.57,0.229
9.25,90.71,0.229
9.27,90.84,0.229
9.28,90.97,0.229
9.29,91.11,0.229
9.31,91.24,0.229
9.32,91.37,0.229
9.33,91.51,0.230
9.35,91.64,0.230
9.36,91.77,0.230
9.37,91.91,0.230
9.39,92.04,0.230
9.40,92.18,0.230
9.41,92.31,0.230
9.43,92.44,0.230
9.44,92.58,0.230
9.45,92.71,0.230
9.47,92.84,0.230
9.48,92.98,0.230
9.49,93.11,0.230
9.51,93.24,0.231
9.52,93.38,0.231
9.53,93.51,0.231
9.55,93.64,0.231
9.56,93.78,0.231
9.57,93.91,0.231
9.59,94.04,0.231
9.60,94.18,0.231
9.61,94.31,0.231
9.63,94.44,0.231
9.64,94.58,0.231
9.65,94.71,0.231
9.67,94.84,0.231
9.68,94.98,0.231
9.69,95.11,0.231
9.71,95.24,0.232
9.72,95.38,0.232
9.73,95.51,0.232
9.75,95.64,0.232
9.76,95.78,0.232
9.77,95.91,0.232
9.79,96.04,0.232
9.80,96.18,0.232
9.81,96.31,0.232
9.83,96.44,0.232
9.84,96.58,0.232
9.85,96.71,0.232
9.87,96.84,0.232
9.88,96.98,0.232
9.89,97.11,0.233
9.91,97.25,0.233
9.92,97.38,0.233
9.93,97.51,0.233
9.95,97.65,0.233
9.96,97.78,0.233
9.97,97.91,0.233
9.99,98.05,0.233
10.00,98.18,0.233
10.01,98.31,0.233
10.03,98.45,0.233
10.04,98.58,0.233
10.05,98.71,0.234
10.07,98.85,0.234
10.08,98.98,0.234
10.09,99.11,0.234
10.11,99.25,0.234
10.12,99.38,0.234
10.13,99.51,0.234
10.15,99.65,0.234
10.16,99.78,0.234
10.17,99.91,0.234
10.19,100.05,0.234
10.20,100.18,0.234
10.21,100.31,0.234
10.23,100.45,0.234
10.24,100.58,0.234
10.25,100.72,0.234
10.27,100.85,0.234
10.28,100.98,0.235
10.29,101.12,0.235
10.31,101.25,0.235
10.32,101.38,0.235
10.33,101.52,0.235
10.35,101.65,0.235
10.36,101.78,0.235
10.37,101.92,0.235
10.39,102.05,0.235
10.40,102.18,0.235
10.41,102.32,0.235
10.43,102.45,0.235
10.44,102.58,0.235
10.45,102.72,0.235
10.47,102.85,0.235
10.48,102.98,0.235
10.49,103.12,0.236
10.51,103.25,0.236
10.52,103.39,0.236
10.53,103.52,0.236
10.55,103.65,0.236
10.56,103.79,0.236
10.57,103.92,0.236
10.59,104.06,0.236
10.60,104.19,0.237
10.61,104.32,0.237
10.63,104.46,0.237
10.64,104.59,0.237
10.65,104.72,0.237
10.67,104.86,0.237
10.68,104.99,0.237
10.69,105.12,0.237
10.71,105.26,0.237
10.72,105.39,0.237
10.73,105.52,0.237
10.75,105.66,0.237
10.76,105.79,0.237
10.77,105.92,0.237
10.79,106.06,0.237
10.80,106.19,0.237
10.81,106.32,0.237
10.83,106.46,0.237
10.84,106.59,0.237
10.85,106.72,0.237
10.87,106.86,0.237
10.88,106.99,0.238
10.89,107.12,0.238
10.91,107.26,0.238
10.92,107.39,0.238
10.93,107.52,0.238
10.95,107.66,0.238
10.96,107.79,0.238
10.97,107.92,0.238
10.99,108.06,0.238
11.00,108.19,0.238
11.01,108.32,0.238
11.03,108.46,0.238
11.04,108.59,0.238
11.05,108.72,0.238
11.07,108.86,0.238
11.08,108.99,0.238
11.09,109.12,0.238
11.11,109.26,0.238
11.12,109.39,0.238
11.13,109.52,0.239
11.15,109.66,0.239
11.16,109.79,0.239
11.17,109.92,0.239
11.19,110.06,0.239
11.20,110.19,0.239
11.21,110.32,0.239
11.23,110.46,0.239
11.24,110.59,0.239
11.25,110.72,0.239
11.27,110.86,0.239
11.28,110.99,0.239
11.29,111.12,0.239
11.31,111.26,0.239
11.32,111.39,0.239
11.33,111.52,0.240
11.35,111.66,0.240
11.36,111.79,0.240
11.37,111.92,0.240
11.39,112.06,0.240
11.40,112.19,0.240
11.41,112.32,0.240
11.43,112.46,0.240
11.44,112.59,0.240
11.45,112.72,0.240
11.47,112.86,0.240
11.48,112.99,0.240
11.49,113.12,0.240
11.51,113.26,0.240
11.52,113.39,0.240
11.53,113.52,0.240
11.55,113.66,0.241
11.56,113.79,0.241
11.57,113.92,0.241
11.59,114.06,0.241
11.60,114.19,0.241
11.61,114.33,0.241
11.63,114.46,0.241
11.64,114.59,0.241
11.65,114.73,0.241
11.67,114.86,0.241
11.68,115.00,0.241
11.69,115.13,0.242
11.71,115.26,0.242
11.72,115.40,0.242
11.73,115.53,0.242
11.75,115.66,0.242
11.76,115.79,0.242
11.77,115.93,0.242
11.79,116.06,0.242
11.80,116.19,0.242
11.81,116.33,0.242
11.83,116.46,0.242
11.84,116.59,0.242
11.85,116.73,0.242
11.87,116.86,0.242
11.88,116.99,0.242
11.89,117.13,0.242
11.91,117.26,0.242
11.92,117.39,0.242
11.93,117.53,0.242
11.95,117.66,0.243
11.96,117.80,0.243
11.97,117.93,0.243
11.99,118.06,0.243
12.00,118.20,0.243
12.01,118.33,0.243
12.03,118.46,0.243
12.04,118.60,0.243
12.05,118.73,0.243
12.07,118.86,0.243
12.08,119.00,0.243
12.09,119.13,0.243
12.11,119.26,0.243
12.12,119.40,0.243
12.13,119.53,0.243
12.15,119.66,0.243
12.16,119.80,0.243
12.17,119.93,0.244
12.19,120.06,0.244
12.20,120.20,0.244
12.21,120.33,0.244
12.23,120.46,0.244
12.24,120.60,0.244
12.25,120.73,0.244
12.27,120.86,0.244
12.28,121.00,0.244
12.29,121.13,0.244
12.31,121.26,0.244
12.32,121.40,0.244
12.33,121.53,0.244
12.35,121.66,0.244
12.36,121.80,0.244
12.37,121.93,0.245
12.39,122.06,0.245
12.40,122.20,0.245
12.41,122.33,0.245
12.43,122.47,0.245
12.44,122.60,0.245
12.45,122.73,0.245
12.47,122.87,0.245
12.48,123.00,0.245
12.49,123.13,0.245
12.51,123.27,0.245
12.52,123.40,0.245
12.53,123.53,0.245
12.55,123.67,0.245
12.56,123.80,0.246
12.57,123.93,0.246
12.59,124.07,0.246
12.60,124.20,0.246
12.61,124.33,0.246
12.63,124.47,0.246
12.64,124.60,0.246
12.65,124.74,0.246
12.67,124.87,0.246
12.68,125.00,0.246
12.69,125.13,0.246
12.71,125.27,0.246
12.72,125.40,0.246
12.73,125.54,0.246
12.75,125.67,0.246
12.76,125.80,0.247
12.77,125.93,0.247
12.79,126.07,0.247
12.80,126.20,0.247
12.81,126.33,0.247
12.83,126.47,0.247
12.84,126.60,0.247
12.85,126.73,0.247
12.87,126.87,0.247
12.88,127.00,0.247
12.89,127.13,0.247
12.91,127.27,0.247
12.92,127.40,0.247
12.93,127.53,0.247
12.95,127.67,0.247
12.96,127.80,0.247
12.97,127.93,0.247
12.99,128.07,0.247
13.00,128.20,0.247
13.01,128.33,0.248
13.03,128.47,0.248
13.04,128.60,0.248
13.05,128.73,0.248
13.07,128.87,0.248
13.08,129.00,0.248
13.09,129.13,0.248
13.11,129.27,0.248
13.12,129.40,0.248
13.13,129.53,0.248
13.15,129.67,0.248
13.16,129.80,0.248
13.17,129.93,0.248
13.19,130.07,0.248
13.20,130.20,0.249
13.21,130.33,0.249
13.23,130.47,0.249
13.24,130.60,0.249
13.25,130.74,0.249
13.27,130.87,0.249
13.28,131.00,0.249
13.29,131.14,0.249
13.31,131.27,0.249
13.32,131.40,0.249
13.33,131.54,0.250
13.35,131.67,0.250
13.36,131.80,0.250
13.37,131.94,0.250
13.39,132.07,0.250
13.40,132.20,0.250
13.41,132.34,0.250
13.43,132.47,0.250
13.44,132.60,0.250
13.45,132.74,0.250
13.47,132.87,0.250
13.48,133.00,0.250
13.49,133.14,0.250
13.51,133.27,0.250
13.52,133.40,0.250
13.53,133.54,0.250
13.55,133.67,0.250
13.56,133.80,0.250
13.57,133.94,0.250
13.59,134.07,0.251
13.60,134.20,0.251
13.61,134.34,0.251
13.63,134.47,0.251
13.64,134.60,0.251
13.65,134.74,0.251
13.67,134.87,0.251
13.68,135.00,0.251
13.69,135.14,0.251
13.71,135.27,0.251
13.72,135.40,0.251
13.73,135.54,0.251
13.75,135.67,0.251
13.76,135.80,0.251
13.77,135.94,0.251
13.79,136.07,0.252
13.80,136.21,0.252
13.81,136.34,0.252
13.83,136.47,0.252
13.84,136.61,0.252
13.85,136.74,0.252
13.87,136.87,0.252
13.88,137.01,0.252
13.89,137.14,0.252
13.91,137.27,0.252
13.92,137.41,0.252
13.93,137.54,0.253
13.95,137.68,0.253
13.96,137.81,0.253
13.97,137.94,0.253
13.99,138.08,0.253
14.00,138.21,0.253
14.01,138.34,0.253
14.03,138.48,0.253
14.04,138.61,0.253
14.05,138.74,0.253
14.07,138.88,0.253
14.08,139.01,0.253
14.09,139.14,0.253
14.11,139.28,0.253
14.12,139.41,0.253
14.13,139.54,0.253
14.15,139.68,0.254
14.16,139.81,0.254
14.17,139.94,0.254
14.19,140.08,0.254
14.20,140.21,0.254
14.21,140.34,0.254
14.23,140.48,0.254
14.24,140.61,0.254
14.25,140.75,0.254
14.27,140.88,0.254
14.28,141.01,0.254
14.29,141.14,0.254
14.31,141.28,0.254
14.32,141.41,0.254
14.33,141.54,0.254
14.35,141.68,0.255
14.36,141.81,0.255
14.37,141.94,0.255
14.39,142.08,0.255
14.40,142.21,0.255
14.41,142.34,0.255
14.43,142.48,0.255
14.44,142.61,0.255
14.45,142.74,0.255
14.47,142.88,0.255
14.48,143.01,0.255
14.49,143.14,0.255
14.51,143.28,0.255
14.52,143.41,0.255
14.53,143.54,0.256
14.55,143.68,0.256
14.56,143.81,0.256
14.57,143.94,0.256
14.59,144.08,0.256
14.60,144.21,0.256
14.61,144.34,0.256
14.63,144.48,0.256
14.64,144.61,0.256
14.65,144.74,0.256
14.67,144.88,0.256
14.68,145.01,0.256
14.69,145.15,0.257
14.71,145.28,0.257
14.72,145.41,0.257
14.73,145.55,0.257
14.75,145.68,0.257
14.76,145.81,0.257
14.77,145.95,0.257
14.79,146.08,0.257
14.80,146.21,0.257
14.81,146.35,0.257
14.83,146.48,0.257
14.84,146.61,0.258
14.85,146.75,0.258
14.87,146.88,0.258
14.88,147.01,0.258
14.89,147.15,0.258
14.91,147.28,0.258
14.92,147.41,0.258
14.93,147.55,0.258
14.95,147.68,0.258
14.96,147.81,0.258
14.97,147.94,0.258
14.99,148.08,0.258
15.00,148.21,0.259
15.01,148.35,0.259
15.03,148.48,0.259
15.04,148.61,0.259
15.05,148.75,0.259
15.07,148.88,0.259
15.08,149.01,0.259
15.09,149.15,0.259
15.11,149.28,0.259
15.12,149.41,0.259
15.13,149.54,0.260
15.15,149.68,0.260
15.16,149.81,0.260
15.17,149.95,0.260
15.19,150.08,0.260
15.20,150.21,0.260
15.21,150.35,0.260
15.23,150.48,0.260
15.24,150.61,0.260
15.25,150.75,0.261
15.27,150.88,0.261
15.28,151.01,0.261
15.29,151.15,0.261
15.31,151.28,0.261
15.32,151.41,0.261
15.33,151.55,0.262
15.35,151.68,0.262
15.36,151.81,0.262
15.37,151.95,0.262
15.39,152.08,0.262
15.40,152.21,0.262
15.41,152.35,0.262
15.43,152.48,0.262
15.44,152.61,0.262
15.45,152.74,0.263
15.47,152.88,0.263
15.48,153.01,0.263
15.49,153.15,0.263
15.51,153.28,0.263
15.52,153.41,0.263
15.53,153.55,0.263
15.55,153.68,0.264
15.56,153.81,0.264
15.57,153.95,0.264
15.59,154.08,0.264
15.60,154.21,0.264
15.61,154.34,0.265
15.63,154.48,0.265
15.64,154.61,0.265
15.65,154.75,0.265
15.67,154.88,0.266
15.68,155.01,0.266
15.69,155.14,0.266
15.71,155.28,0.266
15.72,155.41,0.266
15.73,155.54,0.267
15.75,155.68,0.267
15.76,155.81,0.267
15.77,155.94,0.267
15.79,156.08,0.267
15.80,156.21,0.267
15.81,156.34,0.267
15.83,156.48,0.268
15.84,156.61,0.268
15.85,156.74,0.268
15.87,156.88,0.269
15.88,157.01,0.269
15.89,157.14,0.270
15.91,157.28,0.270
15.92,157.41,0.270
15.93,157.54,0.270
15.95,157.67,0.271
15.96,157.81,0.271
15.97,157.94,0.271
15.99,158.07,0.272
16.00,158.21,0.272
16.01,158.34,0.272
16.03,158.47,0.272
16.04,158.61,0.273
16.05,158.74,0.273
16.07,158.87,0.274
16.08,159.01,0.274
16.09,159.14,0.275
16.11,159.27,0.275
16.12,159.41,0.276
16.13,159.54,0.276
16.15,159.67,0.277
16.16,159.80,0.277
16.17,159.94,0.277
16.19,160.07,0.278
16.20,160.20,0.278
16.21,160.34,0.279
16.23,160.47,0.279
16.24,160.60,0.280
16.25,160.73,0.280
16.27,160.87,0.281
16.28,161.00,0.282
16.29,161.13,0.282
16.31,161.26,0.283
16.32,161.40,0.284
16.33,161.53,0.284
16.35,161.66,0.285
16.36,161.80,0.286
16.37,161.93,0.287
16.39,162.06,0.287
16.40,162.19,0.288
16.41,162.33,0.289
16.43,162.46,0.290
16.44,162.59,0.291
16.45,162.72,0.292
16.47,162.86,0.293
16.48,162.99,0.294
16.49,163.12,0.295
16.51,163.25,0.296
16.52,163.39,0.297
16.53,163.52,0.298
16.55,163.65,0.299
16.56,163.78,0.301
16.57,163.91,0.302
16.59,164.05,0.304
16.60,164.18,0.305
16.61,164.31,0.307
16.63,164.44,0.308
16.64,164.57,0.310
16.65,164.71,0.312
16.67,164.84,0.313
16.68,164.97,0.315
16.69,165.10,0.317
16.71,165.23,0.319
16.72,165.36,0.321
16.73,165.49,0.323
16.75,165.62,0.325
16.76,165.75,0.328
16.77,165.89,0.331
16.79,166.02,0.333
16.80,166.15,0.336
16.81,166.28,0.339
16.83,166.41,0.342
16.84,166.54,0.346
16.85,166.67,0.349
16.87,166.79,0.353
16.88,166.92,0.357
16.89,167.05,0.361
16.91,167.18,0.366
16.92,167.31,0.371
16.93,167.44,0.376
16.95,167.57,0.381
16.96,167.70,0.387
16.97,167.82,0.393
16.99,167.95,0.400
17.00,168.08,0.406
17.01,168.20,0.413
17.03,168.33,0.421
17.04,168.45,0.430
17.05,168.58,0.438
17.07,168.70,0.447
17.08,168.83,0.457
17.09,168.95,0.468
17.11,169.07,0.479
17.12,169.19,0.491
17.13,169.31,0.504
17.15,169.43,0.517
17.16,169.55,0.532
17.17,169.67,0.547
17.19,169.79,0.564
17.20,169.90,0.581
17.21,170.02,0.599
17.23,170.13,0.619
17.24,170.24,0.639
17.25,170.35,0.660
17.27,170.46,0.683
17.28,170.57,0.707
17.29,170.68,0.730
17.31,170.78,0.756
17.32,170.89,0.782
17.33,170.99,0.809
17.35,171.10,0.838
17.36,171.20,0.869
17.37,171.30,0.899
17.39,171.40,0.930
17.40,171.50,0.962
17.41,171.59,0.994
17.43,171.69,1.026
17.44,171.78,1.062
17.45,171.88,1.097
17.47,171.97,1.131
17.48,172.06,1.168
17.49,172.15,1.208
17.51,172.24,1.250
17.52,172.33,1.289
17.53,172.41,1.327
17.55,172.50,1.365
17.56,172.59,1.405
17.57,172.67,1.449
17.59,172.75,1.492
17.60,172.84,1.542
17.61,172.92,1.585
17.63,173.00,1.631
17.64,173.07,1.680
17.65,173.15,1.719
17.67,173.23,1.771
17.68,173.31,1.828
17.69,173.38,1.884
17.71,173.45,1.951
17.72,173.51,2.034
17.73,173.56,2.106
17.75,173.61,2.221
17.76,173.64,2.319
17.77,173.68,2.391
17.79,173.71,2.469
17.80,173.75,2.523
17.81,173.80,2.562
17.83,173.86,2.593
17.84,173.93,2.628
17.85,174.00,2.664
17.87,174.08,2.670
17.88,174.17,2.658
17.89,174.28,2.645
17.91,174.40,2.637
17.92,174.52,2.633
17.93,174.64,2.630
17.95,174.77,2.624
17.96,174.90,2.613
17.97,175.04,2.604
17.99,175.18,2.594
18.00,175.32,2.579
18.01,175.46,2.544
18.03,175.62,2.509
18.04,175.78,2.479
18.05,175.94,2.452
18.07,176.10,2.426
18.08,176.26,2.403
18.09,176.43,2.378
18.11,176.59,2.351
18.12,176.76,2.318
18.13,176.93,2.278
18.15,177.10,2.238
18.16,177.27,2.192
18.17,177.46,2.129
18.19,177.65,2.051
18.20,177.85,1.959
18.21,178.07,1.852
18.23,178.30,1.733
18.24,178.54,1.603
18.25,178.79,1.470
18.27,179.06,1.342
18.28,179.33,1.230
18.29,179.59,1.136
18.31,179.85,1.054
18.32,180.11,0.981
18.33,180.35,0.917
18.35,180.59,0.861
18.36,180.82,0.810
18.37,181.04,0.764
18.39,181.25,0.722
18.40,181.46,0.685
18.41,181.66,0.651
18.43,181.85,0.620
18.44,182.04,0.592
18.45,182.22,0.567
18.47,182.40,0.544
18.48,182.58,0.523
18.49,182.75,0.504
18.51,182.91,0.487
18.52,183.08,0.471
18.53,183.24,0.456
18.55,183.40,0.444
18.56,183.55,0.431
18.57,183.71,0.420
18.59,183.86,0.411
18.60,184.01,0.401
18.61,184.16,0.394
18.63,184.31,0.386
18.64,184.46,0.380
18.65,184.60,0.373
18.67,184.74,0.368
18.68,184.89,0.363
18.69,185.03,0.358
18.71,185.17,0.354
18.72,185.31,0.351
18.73,185.45,0.347
18.75,185.59,0.344
18.76,185.73,0.341
18.77,185.87,0.339
18.79,186.01,0.336
18.80,186.15,0.334
18.81,186.28,0.332
18.83,186.42,0.331
18.84,186.56,0.329
18.85,186.69,0.328
18.87,186.83,0.327
18.88,186.96,0.325
18.89,187.10,0.324
18.91,187.24,0.323
18.92,187.37,0.322
18.93,187.51,0.322
18.95,187.64,0.321
18.96,187.78,
18.97,187.91,
18.99,188.04,
19.00,,
19.01,,

[step]
Ramp 10.00 °C/min to 0.00 °C
Time,Temperature,Heat Flow (Normalized)
min,°C,W/g
20.01,190.10,-0.023
20.02,190.11,-0.023
20.03,190.10,-0.023
20.05,190.10,-0.023
20.06,190.09,-0.023
20.07,190.08,-0.024
20.09,190.06,-0.029
20.10,190.03,-0.035
20.11,189.99,-0.045
20.13,189.94,-0.058
20.14,189.88,-0.075
20.15,189.81,-0.094
20.17,189.73,-0.114
20.18,189.65,-0.134
20.19,189.57,-0.153
20.21,189.47,-0.172
20.22,189.38,-0.189
20.23,189.28,-0.204
20.25,189.18,-0.218
20.26,189.08,-0.231
20.27,188.98,-0.242
20.29,188.87,-0.253
20.30,188.76,-0.263
20.31,188.65,-0.271
20.33,188.53,-0.279
20.34,188.42,-0.286
20.35,188.30,-0.293
20.37,188.18,-0.299
20.38,188.07,-0.304
20.39,187.95,-0.309
20.41,187.82,-0.314
20.42,187.70,-0.318
20.43,187.58,-0.322
20.45,187.46,-0.325
20.46,187.33,-0.328
20.47,187.21,-0.331
20.49,187.08,-0.333
20.50,186.95,-0.336
20.51,186.83,-0.337
20.53,186.70,-0.340
20.54,186.57,-0.342
20.55,186.45,-0.343
20.57,186.32,-0.344
20.58,186.19,-0.346
20.59,186.06,-0.347
20.61,185.93,-0.348
20.62,185.80,-0.349
20.63,185.67,-0.350
20.65,185.54,-0.350
20.66,185.41,-0.351
20.67,185.28,-0.352
20.69,185.15,-0.352
20.70,185.02,-0.353
20.71,184.89,-0.353
20.73,184.76,-0.354
20.74,184.63,-0.354
20.75,184.50,-0.354
20.77,184.37,-0.355
20.78,184.23,-0.355
20.79,184.10,-0.355
20.81,183.97,-0.355
20.82,183.84,-0.355
20.83,183.71,-0.356
20.85,183.57,-0.356
20.86,183.44,-0.356
20.87,183.31,-0.356
20.89,183.18,-0.356
20.90,183.05,-0.357
20.91,182.91,-0.357
20.93,182.78,-0.357
20.94,182.65,-0.357
20.95,182.51,-0.357
20.97,182.38,-0.357
20.98,182.25,-0.357
20.99,182.12,-0.357
21.01,181.99,-0.357
21.02,181.85,-0.357
21.03,181.72,-0.357
21.05,181.59,-0.357
21.06,181.46,-0.357
21.07,181.32,-0.357
21.09,181.19,-0.357
21.10,181.06,-0.357
21.11,180.92,-0.357
21.13,180.79,-0.357
21.14,180.66,-0.357
21.15,180.53,-0.357
21.17,180.39,-0.357
21.18,180.26,-0.357
21.19,180.13,-0.357
21.21,179.99,-0.357
21.22,179.86,-0.356
21.23,179.73,-0.356
21.25,179.60,-0.356
21.26,179.46,-0.356
21.27,179.33,-0.356
21.29,179.20,-0.356
21.30,179.07,-0.356
21.31,178.93,-0.356
21.33,178.80,-0.356
21.34,178.67,-0.356
21.35,178.53,-0.356
21.37,178.40,-0.356
21.38,178.27,-0.355
21.39,178.14,-0.355
21.41,178.00,-0.355
21.42,177.87,-0.355
21.43,177.74,-0.355
21.45,177.60,-0.355
21.46,177.47,-0.355
21.47,177.34,-0.355
21.49,177.20,-0.355
21.50,177.07,-0.355
21.51,176.94,-0.355
21.53,176.81,-0.355
21.54,176.67,-0.354
21.55,176.54,-0.354
21.57,176.41,-0.354
21.58,176.27,-0.354
21.59,176.14,-0.354
21.61,176.01,-0.354
21.62,175.87,-0.354
21.63,175.74,-0.354
21.65,175.61,-0.354
21.66,175.47,-0.354
21.67,175.34,-0.353
21.69,175.21,-0.353
21.70,175.08,-0.353
21.71,174.94,-0.353
21.73,174.81,-0.353
21.74,174.68,-0.353
21.75,174.54,-0.353
21.77,174.41,-0.353
21.78,174.28,-0.352
21.79,174.15,-0.352
21.81,174.01,-0.352
21.82,173.88,-0.352
21.83,173.75,-0.352
21.85,173.61,-0.352
21.86,173.48,-0.352
21.87,173.35,-0.352
21.89,173.21,-0.352
21.90,173.08,-0.352
21.91,172.95,-0.352
21.93,172.81,-0.352
21.94,172.68,-0.351
21.95,172.55,-0.351
21.97,172.41,-0.351
21.98,172.28,-0.351
21.99,172.15,-0.351
22.01,172.01,-0.351
22.02,171.88,-0.351
22.03,171.75,-0.351
22.05,171.61,-0.351
22.06,171.48,-0.351
22.07,171.35,-0.350
22.09,171.21,-0.350
22.10,171.08,-0.350
22.11,170.95,-0.350
22.13,170.82,-0.350
22.14,170.68,-0.350
22.15,170.55,-0.350
22.17,170.42,-0.350
22.18,170.28,-0.350
22.19,170.15,-0.350
22.21,170.02,-0.349
22.22,169.88,-0.349
22.23,169.75,-0.349
22.25,169.62,-0.349
22.26,169.48,-0.349
22.27,169.35,-0.349
22.29,169.22,-0.349
22.30,169.08,-0.349
22.31,168.95,-0.349
22.33,168.82,-0.349
22.34,168.69,-0.349
22.35,168.55,-0.348
22.37,168.42,-0.348
22.38,168.29,-0.348
22.39,168.15,-0.348
22.41,168.02,-0.348
22.42,167.89,-0.348
22.43,167.75,-0.348
22.45,167.62,-0.348
22.46,167.49,-0.348
22.47,167.35,-0.348
22.49,167.22,-0.348
22.50,167.09,-0.348
22.51,166.95,-0.348
22.53,166.82,-0.347
22.54,166.69,-0.347
22.55,166.55,-0.347
22.57,166.42,-0.347
22.58,166.29,-0.347
22.59,166.16,-0.347
22.61,166.02,-0.347
22.62,165.89,-0.347
22.63,165.75,-0.347
22.65,165.62,-0.347
22.66,165.49,-0.347
22.67,165.35,-0.347
22.69,165.22,-0.347
22.70,165.09,-0.347
22.71,164.95,-0.347
22.73,164.82,-0.347
22.74,164.69,-0.346
22.75,164.55,-0.346
22.77,164.42,-0.346
22.78,164.29,-0.346
22.79,164.16,-0.346
22.81,164.02,-0.346
22.82,163.89,-0.346
22.83,163.76,-0.346
22.85,163.62,-0.346
22.86,163.49,-0.346
22.87,163.36,-0.346
22.89,163.22,-0.346
22.90,163.09,-0.345
22.91,162.96,-0.345
22.93,162.82,-0.345
22.94,162.69,-0.345
22.95,162.56,-0.345
22.97,162.43,-0.345
22.98,162.29,-0.345
22.99,162.16,-0.345
23.01,162.03,-0.345
23.02,161.89,-0.345
23.03,161.76,-0.345
23.05,161.63,-0.344
23.06,161.49,-0.344
23.07,161.36,-0.344
23.09,161.23,-0.344
23.10,161.09,-0.344
23.11,160.96,-0.344
23.13,160.83,-0.344
23.14,160.69,-0.344
23.15,160.56,-0.344
23.17,160.43,-0.344
23.18,160.29,-0.344
23.19,160.16,-0.344
23.21,160.03,-0.344
23.22,159.89,-0.344
23.23,159.76,-0.344
23.25,159.63,-0.344
23.26,159.49,-0.343
23.27,159.36,-0.343
23.29,159.23,-0.343
23.30,159.09,-0.343
23.31,158.96,-0.343
23.33,158.83,-0.343
23.34,158.70,-0.343
23.35,158.56,-0.343
23.37,158.43,-0.343
23.38,158.30,-0.343
23.39,158.16,-0.343
23.41,158.03,-0.343
23.42,157.90,-0.342
23.43,157.76,-0.342
23.45,157.63,-0.342
23.46,157.50,-0.342
23.47,157.36,-0.342
23.49,157.23,-0.342
23.50,157.10,-0.342
23.51,156.96,-0.342
23.53,156.83,-0.342
23.54,156.70,-0.342
23.55,156.56,-0.342
23.57,156.43,-0.342
23.58,156.30,-0.342
23.59,156.16,-0.342
23.61,156.03,-0.342
23.62,155.90,-0.342
23.63,155.77,-0.342
23.65,155.63,-0.341
23.66,155.50,-0.341
23.67,155.37,-0.341
23.69,155.23,-0.341
23.70,155.10,-0.341
23.71,154.97,-0.341
23.73,154.83,-0.341
23.74,154.70,-0.341
23.75,154.57,-0.341
23.77,154.43,-0.341
23.78,154.30,-0.341
23.79,154.17,-0.341
23.81,154.03,-0.341
23.82,153.90,-0.341
23.83,153.77,-0.341
23.85,153.63,-0.341
23.86,153.50,-0.340
23.87,153.37,-0.340
23.89,153.23,-0.340
23.90,153.10,-0.340
23.91,152.97,-0.340
23.93,152.83,-0.340
23.94,152.70,-0.340
23.95,152.57,-0.340
23.97,152.43,-0.340
23.98,152.30,-0.340
23.99,152.17,-0.340
24.01,152.04,-0.340
24.02,151.90,-0.340
24.03,151.77,-0.340
24.05,151.64,-0.340
24.06,151.50,-0.340
24.07,151.37,-0.340
24.09,151.24,-0.340
24.10,151.10,-0.340
24.11,150.97,-0.339
24.13,150.84,-0.339
24.14,150.70,-0.339
24.15,150.57,-0.339
24.17,150.44,-0.339
24.18,150.30,-0.339
24.19,150.17,-0.339
24.21,150.04,-0.339
24.22,149.90,-0.339
24.23,149.77,-0.339
24.25,149.64,-0.339
24.26,149.51,-0.339
24.27,149.37,-0.339
24.29,149.24,-0.339
24.30,149.11,-0.339
24.31,148.97,-0.339
24.33,148.84,-0.339
24.34,148.71,-0.339
24.35,148.57,-0.338
24.37,148.44,-0.338
24.38,148.31,-0.338
24.39,148.17,-0.338
24.41,148.04,-0.338
24.42,147.91,-0.338
24.43,147.77,-0.338
24.45,147.64,-0.338
24.46,147.51,-0.338
24.47,147.37,-0.338
24.49,147.24,-0.338
24.50,147.11,-0.338
24.51,146.97,-0.338
24.53,146.84,-0.338
24.54,146.71,-0.338
24.55,146.57,-0.338
24.57,146.44,-0.338
24.58,146.31,-0.338
24.59,146.18,-0.338
24.61,146.04,-0.338
24.62,145.91,-0.337
24.63,145.78,-0.337
24.65,145.64,-0.337
24.66,145.51,-0.337
24.67,145.38,-0.337
24.69,145.24,-0.337
24.70,145.11,-0.337
24.71,144.98,-0.337
24.73,144.84,-0.337
24.74,144.71,-0.337
24.75,144.58,-0.337
24.77,144.44,-0.337
24.78,144.31,-0.337
24.79,144.18,-0.337
24.81,144.04,-0.337
24.82,143.91,-0.337
24.83,143.78,-0.336
24.85,143.65,-0.336
24.86,143.51,-0.336
24.87,143.38,-0.336
24.89,143.25,-0.336
24.90,143.11,-0.336
24.91,142.98,-0.336
24.93,142.85,-0.336
24.94,142.71,-0.336
24.95,142.58,-0.336
24.97,142.45,-0.336
24.98,142.31,-0.336
24.99,142.18,-0.336
25.01,142.05,-0.336
25.02,141.92,-0.336
25.03,141.78,-0.335
25.05,141.65,-0.335
25.06,141.51,-0.335
25.07,141.38,-0.335
25.09,141.25,-0.335
25.10,141.12,-0.335
25.11,140.98,-0.335
25.13,140.85,-0.335
25.14,140.72,-0.335
25.15,140.58,-0.335
25.17,140.45,-0.335
25.18,140.32,-0.335
25.19,140.19,-0.335
25.21,140.05,-0.335
25.22,139.92,-0.335
25.23,139.79,-0.335
25.25,139.65,-0.335
25.26,139.52,-0.335
25.27,139.39,-0.335
25.29,139.25,-0.335
25.30,139.12,-0.335
25.31,138.99,-0.335
25.33,138.85,-0.334
25.34,138.72,-0.334
25.35,138.59,-0.334
25.37,138.45,-0.334
25.38,138.32,-0.334
25.39,138.19,-0.334
25.41,138.05,-0.334
25.42,137.92,-0.334
25.43,137.79,-0.334
25.45,137.65,-0.334
25.46,137.52,-0.334
25.47,137.39,-0.334
25.49,137.25,-0.334
25.50,137.12,-0.334
[...]
76.07,31.45,-0.241
76.09,31.32,-0.241
76.10,31.19,-0.241
76.11,31.05,-0.240
76.13,30.92,-0.240
76.14,30.79,-0.240
76.15,30.65,-0.239
76.17,30.52,-0.239
76.18,30.39,-0.239
76.19,30.25,-0.238
76.21,30.12,-0.238
76.22,29.99,-0.238
76.23,29.85,-0.237
76.25,29.72,-0.237
76.26,29.58,-0.237
76.27,29.45,-0.236
76.29,29.32,-0.236
76.30,29.18,-0.236
76.31,29.05,-0.236
76.33,28.92,-0.236
76.34,28.78,-0.235
76.35,28.65,-0.235
76.37,28.52,-0.235
76.38,28.38,-0.234
76.39,28.25,-0.234
76.41,28.12,-0.234
76.42,27.98,-0.234
76.43,27.85,-0.233
76.45,27.72,-0.233
76.46,27.58,-0.233
76.47,27.45,-0.232
76.49,27.32,-0.232
76.50,27.18,-0.232
76.51,27.05,-0.232
76.53,26.92,-0.232
76.54,26.78,-0.232
76.55,26.65,-0.231
76.57,26.52,-0.231
76.58,26.38,-0.231
76.59,26.25,-0.231
76.61,26.12,-0.235
76.62,25.98,-0.237
76.63,25.85,-0.235
76.65,25.72,-0.230
76.66,25.59,-0.236
76.67,25.45,-0.235
76.69,25.32,-0.234
76.70,25.19,-0.233
76.71,25.05,-0.231
76.73,24.92,-0.231
76.74,24.79,-0.231
76.75,24.65,-0.231
76.77,24.52,-0.230
76.78,24.39,-0.230
76.79,24.25,-0.230
76.81,24.12,-0.230
76.82,23.98,-0.224
76.83,23.85,-0.225
76.85,23.72,-0.226
76.86,23.58,-0.227
76.87,23.45,-0.227
76.89,23.32,-0.227
76.90,23.18,-0.227
76.91,23.05,-0.227
76.93,22.92,-0.227
76.94,22.78,-0.227
76.95,22.65,-0.227
76.97,22.52,-0.227
76.98,22.38,-0.227
76.99,22.25,-0.227
77.01,22.12,-0.226
77.02,21.98,-0.226
77.03,21.85,-0.226
77.05,21.71,-0.226
77.06,21.58,-0.226
77.07,21.45,-0.226
77.09,21.31,-0.226
77.10,21.18,-0.225
77.11,21.05,-0.225
77.13,20.91,-0.225
77.14,20.78,-0.225
77.15,20.65,-0.224
77.17,20.51,-0.224
77.18,20.38,-0.224
77.19,20.25,-0.224
77.21,20.11,-0.224
77.22,19.98,-0.224
77.23,19.85,-0.223
77.25,19.71,-0.223
77.26,19.58,-0.223
77.27,19.45,-0.223
77.29,19.31,-0.223
77.30,19.18,-0.223
77.31,19.05,-0.222
77.33,18.92,-0.222
77.34,18.78,-0.222
77.35,18.65,-0.222
77.37,18.52,-0.222
77.38,18.38,-0.221
77.39,18.25,-0.221
77.41,18.12,-0.221
77.42,17.98,-0.221
77.43,17.85,-0.221
77.45,17.72,-0.221
77.46,17.58,-0.221
77.47,17.45,-0.221
77.49,17.32,-0.221
77.50,17.18,-0.220
77.51,17.05,-0.220
77.53,16.92,-0.220
77.54,16.78,-0.220
77.55,16.65,-0.220
77.57,16.52,-0.219
77.58,16.39,-0.219
77.59,16.25,-0.219
77.61,16.12,-0.219
77.62,15.98,-0.219
77.63,15.85,-0.219
77.65,15.72,-0.219
77.66,15.58,-0.218
77.67,15.45,-0.218
77.69,15.32,-0.218
77.70,15.18,-0.218
77.71,15.05,-0.218
77.73,14.92,-0.218
77.74,14.79,-0.218
77.75,14.65,-0.218
77.77,14.52,-0.218
77.78,14.39,-0.218
77.79,14.25,-0.217
77.81,14.12,-0.217
77.82,13.99,-0.217
77.83,13.85,-0.217
77.85,13.72,-0.217
77.86,13.59,-0.217
77.87,13.45,-0.216
77.89,13.32,-0.216
77.90,13.19,-0.216
77.91,13.05,-0.216
77.93,12.92,-0.216
77.94,12.79,-0.216
77.95,12.65,-0.216
77.97,12.52,-0.216
77.98,12.39,-0.216
77.99,12.25,-0.216
78.01,12.12,-0.215
78.02,11.99,-0.215
78.03,11.86,-0.220
78.05,11.72,-0.219
78.06,11.59,-0.216
78.07,11.46,-0.215
78.09,11.32,-0.215
78.10,11.19,-0.214
78.11,11.06,-0.214
78.13,10.92,-0.214
78.14,10.79,-0.214
78.15,10.66,-0.213
78.17,10.52,-0.213
78.18,10.39,-0.213
78.19,10.26,-0.213
78.21,10.13,-0.213
78.22,9.99,-0.213
78.23,9.86,-0.213
78.25,9.72,-0.213
78.26,9.59,-0.213
78.27,9.46,-0.213
78.29,9.33,-0.213
78.30,9.19,-0.212
78.31,9.06,-0.212
78.33,8.93,-0.212
78.34,8.79,-0.212
78.35,8.66,-0.212
78.37,8.53,-0.212
78.38,8.39,-0.212
78.39,8.26,-0.212
78.41,8.13,-0.212
78.42,7.99,-0.212
78.43,7.86,-0.211
78.45,7.73,-0.211
78.46,7.59,-0.215
78.47,7.46,-0.214
78.49,7.33,-0.213
78.50,7.19,-0.212
78.51,7.06,-0.211
78.53,6.93,-0.211
78.54,6.80,-0.210
78.55,6.66,-0.210
78.57,6.53,-0.210
78.58,6.39,-0.210
78.59,6.26,-0.210
78.61,6.13,-0.210
78.62,5.99,-0.210
78.63,5.86,-0.210
78.65,5.73,-0.209
78.66,5.59,-0.209
78.67,5.46,-0.209
78.69,5.33,-0.209
78.70,5.19,-0.209
78.71,5.06,-0.209
78.73,4.93,-0.209
78.74,4.79,-0.209
78.75,4.66,-0.209
78.77,4.53,-0.208
78.78,4.39,-0.208
78.79,4.26,-0.208
78.81,4.13,-0.208
78.82,3.99,-0.208
78.83,3.86,-0.208
78.85,3.73,-0.208
78.86,3.59,-0.208
78.87,3.46,-0.208
78.89,3.33,-0.208
78.90,3.19,-0.207
78.91,3.06,-0.207
78.93,2.93,-0.207
78.94,2.79,-0.207
78.95,2.66,
78.97,2.53,
78.98,2.39,
78.99,2.26,
79.00,,

[step]
Ramp 10.00 °C/min to 30.00 °C
Time,Temperature,Heat Flow (Normalized)
min,°C,W/g
80.01,0.14,-0.008
80.01,0.14,-0.008
80.01,0.14,-0.008
80.02,0.14,-0.008
80.02,0.14,-0.008
80.02,0.14,-0.008
80.03,0.14,-0.008
80.03,0.14,-0.008
80.03,0.14,-0.008
80.04,0.14,-0.008
80.04,0.14,-0.008
80.04,0.14,-0.008
80.05,0.14,-0.008
80.05,0.14,-0.008
80.05,0.14,-0.008
80.06,0.15,-0.008
80.06,0.15,-0.008
80.06,0.15,-0.008
80.07,0.15,-0.008
80.07,0.16,-0.008
80.07,0.16,-0.008
80.08,0.16,-0.008
80.08,0.17,-0.007
80.08,0.17,-0.007
80.09,0.18,-0.007
80.09,0.19,-0.006
80.09,0.20,-0.005
80.10,0.20,-0.004
80.10,0.21,-0.003
80.10,0.22,-0.001
80.11,0.23,0.000
80.11,0.24,0.001
80.11,0.25,0.003
80.12,0.26,0.004
80.12,0.27,0.006
80.12,0.29,0.008
80.13,0.30,0.009
80.13,0.31,0.012
80.13,0.33,0.014
80.14,0.34,0.016
80.14,0.36,0.019
80.14,0.37,0.021
80.15,0.39,0.024
80.15,0.41,0.026
80.15,0.43,0.029
80.16,0.44,0.032
80.16,0.46,0.035
80.16,0.48,0.038
80.17,0.50,0.041
80.17,0.52,0.043
80.17,0.54,0.046
80.18,0.56,0.049
80.18,0.58,0.052
80.18,0.60,0.055
80.19,0.62,0.058
80.19,0.64,0.060
80.19,0.66,0.063
80.20,0.68,0.066
80.20,0.70,0.068
80.20,0.73,0.071
80.21,0.75,0.073
80.21,0.77,0.076
80.21,0.79,0.078
80.22,0.82,0.080
80.22,0.84,0.082
80.22,0.86,0.085
80.23,0.89,0.087
80.23,0.91,0.089
80.23,0.93,0.091
80.24,0.96,0.093
80.24,0.98,0.095
80.24,1.01,0.097
80.25,1.03,0.099
80.25,1.06,0.100
80.25,1.08,0.102
80.26,1.11,0.104
80.26,1.13,0.106
80.26,1.16,0.108
80.27,1.18,0.109
80.27,1.21,0.111
80.27,1.24,0.113
80.28,1.26,0.114
80.28,1.29,0.116
80.28,1.32,0.117
80.29,1.34,0.119
80.29,1.37,0.121
80.29,1.40,0.122
80.30,1.42,0.123
80.30,1.45,0.125
80.30,1.48,0.126
80.31,1.51,0.128
80.31,1.53,0.129
80.31,1.56,0.130
80.32,1.59,0.131
80.32,1.62,0.132
80.32,1.64,0.134
80.33,1.67,0.135
80.33,1.70,0.136
80.33,1.73,0.138
80.34,1.76,0.139
80.34,1.79,0.140
80.34,1.82,0.141
80.35,1.84,0.142
80.35,1.87,0.143
80.35,1.90,0.144
80.36,1.93,0.145
80.36,1.96,0.146
80.36,1.99,0.147
80.37,2.02,0.148
80.37,2.05,0.149
80.37,2.08,0.150
80.38,2.11,0.151
80.38,2.14,0.152
80.38,2.17,0.153
80.39,2.20,0.153
80.39,2.23,0.154
80.39,2.26,0.155
80.40,2.29,0.156
80.40,2.32,0.157
80.40,2.35,0.157
80.41,2.38,0.158
80.41,2.41,0.159
80.41,2.44,0.159
80.42,2.47,0.160
80.42,2.50,0.161
80.42,2.53,0.162
80.43,2.56,0.162
80.43,2.59,0.163
80.43,2.62,0.163
80.44,2.65,0.164
80.44,2.68,0.165
80.44,2.71,0.165
80.45,2.74,0.166
80.45,2.78,0.167
80.45,2.81,0.167
80.46,2.84,0.167
80.46,2.87,0.167
80.46,2.90,0.168
80.47,2.93,0.169
80.47,2.96,0.170
80.47,2.99,0.170
80.48,3.02,0.170
80.48,3.05,0.171
80.48,3.09,0.171
80.49,3.12,0.172
80.49,3.15,0.172
80.49,3.18,0.172
80.50,3.21,0.173
80.50,3.24,0.173
80.50,3.27,0.174
80.51,3.31,0.174
80.51,3.34,0.174
80.51,3.37,0.175
80.52,3.40,0.175
80.52,3.43,0.176
80.52,3.46,0.176
80.53,3.50,0.176
80.53,3.53,0.177
80.53,3.56,0.177
80.54,3.59,0.177
80.54,3.62,0.178
80.54,3.65,0.178
80.55,3.69,0.178
80.55,3.72,0.178
80.55,3.75,0.178
80.56,3.78,0.179
80.56,3.81,0.179
80.56,3.85,0.180
80.57,3.88,0.180
80.57,3.91,0.180
80.57,3.94,0.180
80.58,3.97,0.181
80.58,4.01,0.181
80.58,4.04,0.181
80.59,4.07,0.182
80.59,4.10,0.182
80.59,4.14,0.182
80.60,4.17,0.182
80.60,4.20,0.182
80.60,4.23,0.182
80.61,4.26,0.182
80.61,4.30,0.183
80.61,4.33,0.183
80.62,4.36,0.183
80.62,4.39,0.184
80.62,4.43,0.184
80.63,4.46,0.184
80.63,4.49,0.184
80.63,4.52,0.184
80.64,4.56,0.184
80.64,4.59,0.185
80.64,4.62,0.185
80.65,4.65,0.185
80.65,4.68,0.185
80.65,4.72,0.185
80.66,4.75,0.186
80.66,4.78,0.186
80.66,4.81,0.186
80.67,4.85,0.186
80.67,4.88,0.186
80.67,4.91,0.186
80.68,4.95,0.186
80.68,4.98,0.187
80.68,5.01,0.187
80.69,5.04,0.187
80.69,5.08,0.187
80.69,5.11,0.187
80.70,5.14,0.187
80.70,5.17,0.187
80.70,5.21,0.187
80.71,5.24,0.187
80.71,5.27,0.188
80.71,5.30,0.188
80.72,5.34,0.188
80.72,5.37,0.188
80.72,5.40,0.188
80.73,5.43,0.188
80.73,5.47,0.188
80.73,5.50,0.188
80.74,5.53,0.189
80.74,5.56,0.189
80.74,5.60,0.189
80.75,5.63,0.189
80.75,5.66,0.189
80.75,5.70,0.189
80.76,5.73,0.189
80.76,5.76,0.189
80.76,5.80,0.189
80.77,5.83,0.189
80.77,5.86,0.190
80.77,5.89,0.190
80.78,5.93,0.190
80.78,5.96,0.190
80.78,5.99,0.190
80.79,6.02,0.190
80.79,6.06,0.190
80.79,6.09,0.190
80.80,6.12,0.190
80.80,6.16,0.190
80.80,6.19,0.190
80.81,6.22,0.191
80.81,6.25,0.191
80.81,6.29,0.191
80.82,6.32,0.191
80.82,6.35,0.191
80.82,6.38,0.191
80.83,6.42,0.191
80.83,6.45,0.191
80.83,6.49,0.191
80.84,6.52,0.191
80.84,6.55,0.191
80.84,6.58,0.191
80.85,6.62,0.191
80.85,6.65,0.191
80.85,6.68,0.191
80.86,6.71,0.191
80.86,6.75,0.191
80.86,6.78,0.192
80.87,6.81,0.192
80.87,6.84,0.192
80.87,6.88,0.192
80.88,6.91,0.192
80.88,6.95,0.192
80.88,6.98,0.192
80.89,7.01,0.192
80.89,7.05,0.192
80.89,7.08,0.192
80.90,7.11,0.192
80.90,7.14,0.192
80.90,7.18,0.192
80.91,7.21,0.192
80.91,7.24,0.192
80.91,7.28,0.192
80.92,7.31,0.192
80.92,7.34,0.192
80.92,7.38,0.192
80.93,7.41,0.192
80.93,7.44,0.192
80.93,7.47,0.193
80.94,7.51,0.193
80.94,7.54,0.193
80.94,7.57,0.193
80.95,7.61,0.193
80.95,7.64,0.193
80.95,7.67,0.193
80.96,7.71,0.193
80.96,7.74,0.193
80.96,7.77,0.193
80.97,7.80,0.193
80.97,7.84,0.193
80.97,7.87,0.193
80.98,7.90,0.193
80.98,7.94,0.193
80.98,7.97,0.193
80.99,8.00,0.193
80.99,8.04,0.193
80.99,8.07,0.193
81.00,8.10,0.193
81.00,8.14,0.193
81.00,8.17,0.193
81.01,8.20,0.193
81.01,8.24,0.193
81.01,8.27,0.193
81.02,8.30,0.193
81.02,8.33,0.194
81.02,8.37,0.194
81.03,8.40,0.194
81.03,8.43,0.194
81.03,8.47,0.194
81.04,8.50,0.194
81.04,8.53,0.194
81.04,8.57,0.194
81.05,8.60,0.194
81.05,8.63,0.194
81.05,8.67,0.194
81.06,8.70,0.194
81.06,8.73,0.194
81.06,8.76,0.194
81.07,8.80,0.194
81.07,8.83,0.194
81.07,8.86,0.194
81.08,8.90,0.195
81.08,8.93,0.195
81.08,8.96,0.195
81.09,9.00,0.195
81.09,9.03,0.195
81.09,9.06,0.195
81.10,9.10,0.195
81.10,9.13,0.195
81.10,9.16,0.195
81.11,9.20,0.195
81.11,9.23,0.195
81.11,9.26,0.195
81.12,9.29,0.195
81.12,9.33,0.195
81.12,9.36,0.195
81.13,9.39,0.195
81.13,9.43,0.195
81.13,9.46,0.195
81.14,9.49,0.195
81.14,9.53,0.195
81.14,9.56,0.195
81.15,9.59,0.195
81.15,9.63,0.195
81.15,9.66,0.195
81.16,9.69,0.195
81.16,9.73,0.195
81.16,9.76,0.195
81.17,9.79,0.195
81.17,9.83,0.195
81.17,9.86,0.196
81.18,9.89,0.196
81.18,9.93,0.196
81.18,9.96,0.196
81.19,9.99,0.196
81.19,10.03,0.196
81.19,10.06,0.196
81.20,10.09,0.196
81.20,10.12,0.196
81.20,10.16,0.196
81.21,10.19,0.196
81.21,10.22,0.196
81.21,10.26,0.196
81.22,10.29,0.196
81.22,10.32,0.196
81.22,10.36,0.196
81.23,10.39,0.196
81.23,10.42,0.196
81.23,10.46,0.196
81.24,10.49,0.196
81.24,10.52,0.196
81.24,10.56,0.196
81.25,10.59,0.196
81.25,10.62,0.196
81.25,10.66,0.196
81.26,10.69,0.196
81.26,10.72,0.196
81.26,10.75,0.196
81.27,10.79,0.196
81.27,10.82,0.196
81.27,10.85,0.196
81.28,10.89,0.196
81.28,10.92,0.196
81.28,10.96,0.196
81.29,10.99,0.196
81.29,11.02,0.196
81.29,11.05,0.196
81.30,11.09,0.197
81.30,11.12,0.197
81.30,11.15,0.197
81.31,11.19,0.197
81.31,11.22,0.197
81.31,11.25,0.197
81.32,11.29,0.197
81.32,11.32,0.197
81.32,11.35,0.197
81.33,11.39,0.197
81.33,11.42,0.197
81.33,11.45,0.197
81.34,11.49,0.197
81.34,11.52,0.197
81.34,11.55,0.197
81.35,11.59,0.197
81.35,11.62,0.197
81.35,11.65,0.197
81.36,11.69,0.197
81.36,11.72,0.197
81.36,11.75,0.197
81.37,11.79,0.197
81.37,11.82,0.197
81.37,11.85,0.197
81.38,11.89,0.197
81.38,11.92,0.197
81.38,11.95,0.197
81.39,11.99,0.197
81.39,12.02,0.197
81.39,12.05,0.197
81.40,12.08,0.197
81.40,12.12,0.197
81.40,12.15,0.197
81.41,12.19,0.197
81.41,12.22,0.197
81.41,12.25,0.197
81.42,12.29,0.197
81.42,12.32,0.197
81.42,12.35,0.198
81.43,12.38,0.198
81.43,12.42,0.198
81.43,12.45,0.198
81.44,12.48,0.198
81.44,12.52,0.198
81.44,12.55,0.198
81.45,12.58,0.198
81.45,12.62,0.198
81.45,12.65,0.198
81.46,12.68,0.198
81.46,12.72,0.198
81.46,12.75,0.198
81.47,12.78,0.198
81.47,12.82,0.198
81.47,12.85,0.198
81.48,12.88,0.198
81.48,12.92,0.198
81.48,12.95,0.198
81.49,12.98,0.198
81.49,13.02,0.198
81.49,13.05,0.198
81.50,13.08,0.198
81.50,13.12,0.198
81.50,13.15,0.198
81.51,13.18,0.198
81.51,13.22,0.198
81.51,13.25,0.198
81.52,13.28,0.198
81.52,13.32,0.198
81.52,13.35,0.198
81.53,13.38,0.198
81.53,13.42,0.198
81.53,13.45,0.198
81.54,13.48,0.198
81.54,13.52,0.198
81.54,13.55,0.198
81.55,13.58,0.198
81.55,13.62,0.198
81.55,13.65,0.199
81.56,13.68,0.199
81.56,13.72,0.199
81.56,13.75,0.199
81.57,13.78,0.199
81.57,13.82,0.199
81.57,13.85,0.199
81.58,13.88,0.199
81.58,13.92,0.199
81.58,13.95,0.199
81.59,13.98,0.199
81.59,14.02,0.199
81.59,14.05,0.199
81.60,14.08,0.199
81.60,14.12,0.199
81.60,14.15,0.199
81.61,14.18,0.199
81.61,14.22,0.199
81.61,14.25,0.199
81.62,14.28,0.199
81.62,14.32,0.199
81.62,14.35,0.199
81.63,14.38,0.199
81.63,14.42,0.199
81.63,14.45,0.199
81.64,14.48,0.199
81.64,14.52,0.199
81.64,14.55,0.199
81.65,14.58,0.199
81.65,14.62,0.199
81.65,14.65,0.199
81.66,14.68,0.199
81.66,14.72,0.199
81.66,14.75,0.199
81.67,14.78,0.199
81.67,14.82,0.199
81.67,14.85,0.199
81.68,14.88,0.199
81.68,14.92,0.199
81.68,14.95,0.199
81.69,14.98,0.199
81.69,15.02,0.199
81.69,15.05,0.199
81.70,15.08,0.199
81.70,15.12,0.199
81.70,15.15,0.199
81.71,15.18,0.200
81.71,15.22,0.200
81.71,15.25,0.200
81.72,15.28,0.200
81.72,15.32,0.200
81.72,15.35,0.200
81.73,15.38,0.200
81.73,15.42,0.200
81.73,15.45,0.200
81.74,15.48,0.200
81.74,15.52,0.200
81.74,15.55,0.200
81.75,15.58,0.200
81.75,15.62,0.200
81.75,15.65,0.200
81.76,15.68,0.200
81.76,15.72,0.200
81.76,15.75,0.200
81.77,15.78,0.200
81.77,15.82,0.200
81.77,15.85,0.200
81.78,15.88,0.200
81.78,15.92,0.200
81.78,15.95,0.200
81.79,15.98,0.200
81.79,16.02,0.200
81.79,16.05,0.200
81.80,16.08,0.200
81.80,16.12,0.200
81.80,16.15,0.200
81.81,16.18,0.200
81.81,16.22,0.200
81.81,16.25,0.200
81.82,16.28,0.200
81.82,16.32,0.200
81.82,16.35,0.200
81.83,16.38,0.200
81.83,16.41,0.200
81.83,16.45,0.200
81.84,16.48,0.200
81.84,16.52,0.200
81.84,16.55,0.200
81.85,16.58,0.200
81.85,16.62,0.200
81.85,16.65,0.200
81.86,16.68,0.200
81.86,16.71,0.200
81.86,16.75,0.200
81.87,16.78,0.200
81.87,16.82,0.200
81.87,16.85,0.201
81.88,16.88,0.201
81.88,16.92,0.201
81.88,16.95,0.201
81.89,16.98,0.201
81.89,17.02,0.201
81.89,17.05,0.201
81.90,17.08,0.201
81.90,17.12,0.201
81.90,17.15,0.201
81.91,17.18,0.201
81.91,17.22,0.201
81.91,17.25,0.201
81.92,17.28,0.201
81.92,17.32,0.201
81.92,17.35,0.201
81.93,17.38,0.201
81.93,17.42,0.201
81.93,17.45,0.201
81.94,17.48,0.201
81.94,17.52,0.201
81.94,17.55,0.201
81.95,17.58,0.201
81.95,17.62,0.201
81.95,17.65,0.201
81.96,17.68,0.201
81.96,17.72,0.201
81.96,17.75,0.201
81.97,17.78,0.201
81.97,17.82,0.201
81.97,17.85,0.201
81.98,17.88,0.201
81.98,17.92,0.201
81.98,17.95,0.201
81.99,17.98,0.202
81.99,18.02,0.202
81.99,18.05,0.202
82.00,18.08,0.202
82.00,18.12,0.202
82.00,18.15,0.202
82.01,18.18,0.202
82.01,18.22,0.202
82.01,18.25,0.202
82.02,18.28,0.202
82.02,18.32,0.202
82.02,18.35,0.202
82.03,18.38,0.202
82.03,18.42,0.202
82.03,18.45,0.202
82.04,18.48,0.202
82.04,18.52,0.202
82.04,18.55,0.202
82.05,18.58,0.202
82.05,18.62,0.202
82.05,18.65,0.202
82.06,18.68,0.202
82.06,18.72,0.202
82.06,18.75,0.202
82.07,18.78,0.202
82.07,18.82,0.202
82.07,18.85,0.202
82.08,18.88,0.202
82.08,18.92,0.202
82.08,18.95,0.202
82.09,18.98,0.202
82.09,19.02,0.202
82.09,19.05,0.202
82.10,19.08,0.202
82.10,19.12,0.202
82.10,19.15,0.202
82.11,19.18,0.202
82.11,19.22,0.202
82.11,19.25,0.202
82.12,19.28,0.202
82.12,19.32,0.202
82.12,19.35,0.202
82.13,19.38,0.202
82.13,19.42,0.202
82.13,19.45,0.202
82.14,19.48,0.202
82.14,19.52,0.202
82.14,19.55,0.202
82.15,19.58,0.202
82.15,19.62,0.202
82.15,19.65,0.202
82.16,19.68,0.202
82.16,19.72,0.203
82.16,19.75,0.203
82.17,19.78,0.203
82.17,19.82,0.203
82.17,19.85,0.203
82.18,19.88,0.203
82.18,19.92,0.203
82.18,19.95,0.203
82.19,19.98,0.203
82.19,20.02,0.203
82.19,20.05,0.203
82.20,20.08,0.203
82.20,20.12,0.203
82.20,20.15,0.203
82.21,20.18,0.203
82.21,20.22,0.203
82.21,20.25,0.203
82.22,20.28,0.203
82.22,20.32,0.203
82.22,20.35,0.203
82.23,20.38,0.203
82.23,20.42,0.203
82.23,20.45,0.203
82.24,20.48,0.203
82.24,20.51,0.203
82.24,20.55,0.203
82.25,20.58,0.203
82.25,20.62,0.203
82.25,20.65,0.203
82.26,20.68,0.203
82.26,20.72,0.203
82.26,20.75,0.203
82.27,20.78,0.203
82.27,20.82,0.203
82.27,20.85,0.203
82.28,20.88,0.203
82.28,20.92,0.203
82.28,20.95,0.203
82.29,20.98,0.203
82.29,21.02,0.203
82.29,21.05,0.203
82.30,21.08,0.204
82.30,21.12,0.204
82.30,21.15,0.204
82.31,21.18,0.204
82.31,21.22,0.204
82.31,21.25,0.204
82.32,21.28,0.204
82.32,21.32,0.204
82.32,21.35,0.204
82.33,21.38,0.204
82.33,21.42,0.204
82.33,21.45,0.204
82.34,21.48,0.204
82.34,21.52,0.204
82.34,21.55,0.204
82.35,21.58,0.204
82.35,21.62,0.204
82.35,21.65,0.204
82.36,21.68,0.204
82.36,21.72,0.204
82.36,21.75,0.204
82.37,21.78,0.204
82.37,21.82,0.204
82.37,21.85,0.204
82.38,21.88,0.204
82.38,21.92,0.204
82.38,21.95,0.204
82.39,21.98,0.204
82.39,22.02,0.204
82.39,22.05,0.204
82.40,22.08,0.204
82.40,22.12,0.204
82.40,22.15,0.204
82.41,22.18,0.204
82.41,22.22,0.204
82.41,22.25,0.204
82.42,22.28,0.204
82.42,22.32,0.204
82.42,22.35,0.204
82.43,22.38,0.204
82.43,22.42,0.204
82.43,22.45,0.204
82.44,22.48,0.204
82.44,22.52,0.204
82.44,22.55,0.204
82.45,22.58,0.204
82.45,22.62,0.205
82.45,22.65,0.205
82.46,22.68,0.205
82.46,22.72,0.205
82.46,22.75,0.205
82.47,22.78,0.205
82.47,22.82,0.205
82.47,22.85,0.205
82.48,22.88,0.205
82.48,22.92,0.205
82.48,22.95,0.205
82.49,22.98,0.205
82.49,23.02,0.205
82.49,23.05,0.205
82.50,23.08,0.205
82.50,23.12,0.205
82.50,23.15,0.205
82.51,23.18,0.205
82.51,23.22,0.205
82.51,23.25,0.205
82.52,23.28,0.205
82.52,23.32,0.205
82.52,23.35,0.205
82.53,23.38,0.205
82.53,23.42,0.205
82.53,23.45,0.205
82.54,23.48,0.205
82.54,23.52,0.205
82.54,23.55,0.205
82.55,23.58,0.205
82.55,23.62,0.205
82.55,23.65,0.205
82.56,23.68,0.205
82.56,23.72,0.205
82.56,23.75,0.205
82.57,23.78,0.205
82.57,23.82,0.205
82.57,23.85,0.205
82.58,23.88,0.205
82.58,23.92,0.205
82.58,23.95,0.205
82.59,23.98,0.205
82.59,24.02,0.205
82.59,24.05,0.205
82.60,24.09,0.205
82.60,24.12,0.206
82.60,24.15,0.206
82.61,24.18,0.206
82.61,24.22,0.206
82.61,24.25,0.206
82.62,24.29,0.206
82.62,24.32,0.206
82.62,24.35,0.206
82.63,24.38,0.206
82.63,24.42,0.206
82.63,24.45,0.206
82.64,24.48,0.206
82.64,24.52,0.206
82.64,24.55,0.206
82.65,24.58,0.206
82.65,24.62,0.206
82.65,24.65,0.206
82.66,24.68,0.206
82.66,24.72,0.206
82.66,24.75,0.206
82.67,24.78,0.206
82.67,24.82,0.206
82.67,24.85,0.206
82.68,24.88,0.206
82.68,24.92,0.206
82.68,24.95,0.206
82.69,24.98,0.206
82.69,25.02,0.206
82.69,25.05,0.206
82.70,25.08,0.206
82.70,25.12,0.206
82.70,25.15,0.206
82.71,25.18,0.206
82.71,25.22,0.206
82.71,25.25,0.206
82.72,25.28,0.206
82.72,25.32,0.206
82.72,25.35,0.206
82.73,25.38,0.206
82.73,25.42,0.206
82.73,25.45,0.206
82.74,25.48,0.206
82.74,25.52,0.206
82.74,25.55,0.207
82.75,25.58,0.207
82.75,25.62,0.207
82.75,25.65,0.207
82.76,25.68,0.207
82.76,25.72,0.207
82.76,25.75,0.207
82.77,25.78,0.207
82.77,25.82,0.207
82.77,25.85,0.207
82.78,25.89,0.207
82.78,25.92,0.207
82.78,25.95,0.207
82.79,25.98,0.207
82.79,26.02,0.207
82.79,26.05,0.207
82.80,26.08,0.207
82.80,26.12,0.207
82.80,26.15,0.207
82.81,26.18,0.207
82.81,26.22,0.207
82.81,26.25,0.207
82.82,26.29,0.207
82.82,26.32,0.207
82.82,26.35,0.207
82.83,26.38,0.207
82.83,26.42,0.207
82.83,26.45,0.207
82.84,26.49,0.207
82.84,26.52,0.207
82.84,26.55,0.207
82.85,26.58,0.207
82.85,26.62,0.208
82.85,26.65,0.208
82.86,26.68,0.208
82.86,26.72,0.208
82.86,26.75,0.208
82.87,26.79,0.208
82.87,26.82,0.208
82.87,26.85,0.208
82.88,26.89,0.208
82.88,26.92,0.208
82.88,26.95,0.208
82.89,26.99,0.208
82.89,27.02,0.208
82.89,27.05,0.208
82.90,27.09,0.208
82.90,27.12,0.208
82.90,27.15,0.208
82.91,27.18,0.208
82.91,27.22,0.208
82.91,27.25,0.208
82.92,27.29,0.208
82.92,27.32,0.208
82.92,27.35,0.208
82.93,27.39,0.208
82.93,27.42,0.208
82.93,27.45,0.208
82.94,27.49,0.208
82.94,27.52,0.208
82.94,27.55,0.208
82.95,27.59,0.208
82.95,27.62,
82.95,27.65,
82.96,27.69,
82.96,27.72,
82.96,27.75,
82.97,27.79,
82.97,27.82,
82.97,27.85,
82.98,27.88,
82.98,27.92,
82.98,27.95,
82.99,27.99,
82.99,28.02,
82.99,28.05,
83.00,28.08,
83.00,,
83.00,,
83.00,,