File: DSC/2025_02_13_Water_DSC.txt
Filename	2025_02_13_Water_DSC
Instrument name	DSC2A-00468 (192.168.1.100)
Operator	JLY
rundate	2/13/2025
Sample name	2025_02_13_Water_DSC
proceduresegments	Data Off ; Equilibrate -30.00 °C; Data On ; Ramp 5.00 °C/min to 30.00 °C
[File Parameters]
Run date	2/13/2025 5:50:24 PM
Trios version	5.1.1.46572
Original File Name
Current File Name	D:\DSC2500\CHM343\2025_02_13_Water_DSC.tri
[Procedure]
Procedure Name	Ice Melting
Sample Name	2025_02_13_Water_DSC
Sample Mass	3.47 mg
Reference Sample Mass	0 mg
Pan Mass	54.2 mg
Pan Number	26
Reference Pan Mass	54 mg
Reference Pan Number	19
Pan Type	Tzero Aluminum Hermetic
Comments	Al Hermetic Sealed Pan, with ref Al pan
Project Name
Operator	JLY
Test	Custom
Unload Max Temperature	30
Unload Min Temperature	30
Load Max Temperature	30
Load Min Temperature	30
Stop on Gas Flow Error	Yes
[Signal List]
Signal #1	Time (min)
Signal #2	Temperature (°C)
Signal #3	Heat Flow (mW)
Signal #4	Delta T (µV)
Signal #5	Delta Tzero (µV)
Signal #6	Tzero Temperature (°C)
Signal #7	Cell Purge (mL/min)
Signal #8	Heater Temp (°C)
Signal #9	Power Delivered (W)
Signal #10	Reference Junction Temperature (°C)
Signal #11	Flange Temperature (°C)
Signal #12	Heat Flow Phase (rad)
Signal #13	Total Heat Capacity (J/°C)
Signal #14	Heat Capacity (J/°C)
[Configuration]
Company Name	ASU
Instrument Name	DSC2A-00468
Instrument Type	DSC2500
Serial Number	DSC2A-00468
IP	192.168.1.100
Location of Instrument	MRRC
DisplayType	Unknown
Sample Interval 	0.1 s/pt
Selected Heat Flow	T4P
Exotherm Direction	Down
Cell Serial	DRC2-00792
Lid Type	Standard
Cooler	RCS 90
Leave Cooler on at End of Sequence	On
Gas 2	Nitrogen
Gas Selected	Channel 1
Flow Rate	50 mL/min
Secondary Purge	On
Licensed Heat Flow	Heat Flow T4P
Modulation Licensed	Yes
[Versions]
Common IDD Version	1
Cortex Version	VER 2.10.2.31
Driver	5.0.0.6
GDM Version	1.0.3.3
TouchscreenVersion	1.0.0.16145
FEP Version	1.2.1.21
FEP Bootloader	2.0.0.5
AutoSampler Version	2.1.1.26
Auto Sampler Bootloader	2.0.0.5
FCM Version	1.1.0.3
FCM Bootloader	2.0.0.5
[Experiment Logs]
Experiment Log Entry # 1	Data On set to 0
Experiment Log Entry # 3	Equilibrate Segment -30 (C) Started
Experiment Log Entry # 5	Data On set to 1
Experiment Log Entry # 7	Ramp Segment 5 C/min to 30 Started
[Method Log]
Method Log Entry # 1	Data Off
Method Log Entry # 2	Equilibrate -30 °C
Method Log Entry # 3	Data On
Method Log Entry # 4	(Ramp 37599) Ramp 5 °C/minute to 30 °C
Cell Serial	DRC2-00792
[T1 Calibration]
Slope	-0.008529666
Offset	9.636258
Initial Temperature	98.23
GUID	f8bfdadc-4977-4fdf-ba6d-0ba9134940c3
[TZero Calibration]
Date Applied	11/29/2022 4:06:13 PM
Description	From -89.059 °C to 396.009 °C at 20.000°C/min
Gas Type	Nitrogen
Pan Type	None
Source Files 1	C:\Users\yargerlab\Desktop\DSC Data\General\TZero_calibration_11_29_22_2nd(2).tri
Source Files 2	C:\Users\yargerlab\Desktop\DSC Data\General\TZero_calibration_11_29_22_2nd(3).tri
Delta T Offset	13.05235
Delta T Slope	-0.007271007
Delta T0 Offset	-13.69128
Delta T0 Slope	0.06063341
[Temperature Calibration]
Date Applied	11/29/2022 7:12:28 PM
Description	From 106.590 °C to 186.590 °C at 10.000°C/min
Gas Type	Nitrogen
Pan Type	Tzero Aluminum Hermetic
Source Files 1	C:\Users\yargerlab\Desktop\DSC Data\General\Indium(6).tri
Measured 1	157.391
Known 1	156.598
[Cell Constant Calibration]
Date Applied	11/29/2022 7:12:29 PM
Description	From 106.590 °C to 186.590 °C at 10.000°C/min
Gas Type	Nitrogen
Pan Type	Tzero Aluminum Hermetic
Source Files 1	C:\Users\yargerlab\Desktop\DSC Data\General\Indium(6).tri
T4P KCell	1.006051
Onset Slope	63.26126 mW/°C
[Direct Cp Calibration]
Date Applied	11/30/2022 11:04:51 AM
Description	From -79.983 °C to 298.409 °C at 10.000°C/min
Gas Type	Nitrogen
Pan Type	Tzero Aluminum Hermetic
Source Files 1	C:\Users\yargerlab\Desktop\DSC Data\General\Sapphire_Heat_Capacity_11_30_22.tri
[Rev Cp Calibration]
Date Applied	11/30/2022 1:58:51 PM
Description	From -79.996 °C to 292.812 °C at 3.000°C/min
Gas Type	Nitrogen
Pan Type	Tzero Aluminum Hermetic
Source Files 1	C:\Users\yargerlab\Desktop\DSC Data\General\Sapphire_MDSC_Calibration_11_30_22.tri
[step]
Ramp 5.00 °C/min to 30.00 °C
Time	Temperature	Heat Flow (Normalized)
min	°C	W/g
0.00	-29.54	-0.869
0.01	-29.55	-0.924
0.02	-29.56	-0.892
0.03	-29.58	-0.841
0.03	-29.59	-0.789
0.04	-29.60	-0.749
0.05	-29.61	-0.715
0.06	-29.62	-0.681
0.07	-29.63	-0.648
0.08	-29.63	-0.624
0.08	-29.63	-0.607
0.09	-29.63	-0.595
0.10	-29.63	-0.573
0.11	-29.62	-0.550
0.12	-29.62	-0.534
0.13	-29.61	-0.523
0.13	-29.60	-0.511
0.14	-29.58	-0.499
0.15	-29.57	-0.491
0.16	-29.55	-0.476
0.17	-29.53	-0.467
0.18	-29.50	-0.453
0.18	-29.48	-0.427
0.19	-29.46	-0.413
0.20	-29.43	-0.406
0.21	-29.41	-0.380
0.22	-29.38	-0.366
0.23	-29.35	-0.347
0.23	-29.32	-0.315
0.24	-29.29	-0.291
0.25	-29.26	-0.271
0.26	-29.23	-0.257
0.27	-29.20	-0.237
0.28	-29.17	-0.215
0.28	-29.14	-0.199
0.29	-29.11	-0.183
0.30	-29.08	-0.176
0.31	-29.04	-0.171
0.32	-29.01	-0.156
0.33	-28.98	-0.143
0.33	-28.94	-0.130
0.34	-28.91	-0.118
0.35	-28.87	-0.107
0.36	-28.84	-0.095
0.37	-28.80	-0.085
0.38	-28.77	-0.076
0.38	-28.73	-0.071
0.39	-28.70	-0.063
0.40	-28.66	-0.052
0.41	-28.62	-0.045
0.42	-28.59	-0.041
0.43	-28.55	-0.035
0.43	-28.51	-0.028
0.44	-28.48	-0.025
0.45	-28.44	-0.018
0.46	-28.40	-0.015
0.47	-28.36	-0.012
0.48	-28.32	-0.007
0.48	-28.29	-0.003
0.49	-28.25	0.002
0.50	-28.21	0.007
0.51	-28.17	0.012
0.52	-28.13	0.014
0.53	-28.09	0.016
0.53	-28.05	0.021
0.54	-28.01	0.024
0.55	-27.97	0.028
0.56	-27.94	0.031
0.57	-27.90	0.033
0.58	-27.86	0.036
0.58	-27.82	0.038
0.59	-27.78	0.039
0.60	-27.74	0.042
0.61	-27.70	0.044
0.62	-27.66	0.044
0.63	-27.62	0.042
0.63	-27.58	0.041
0.64	-27.54	0.042
0.65	-27.50	0.042
0.66	-27.46	0.043
0.67	-27.42	0.047
0.68	-27.38	0.048
0.68	-27.34	0.050
0.69	-27.30	0.052
0.70	-27.26	0.054
0.71	-27.22	0.056
0.72	-27.18	0.058
0.73	-27.14	0.061
0.73	-27.10	0.062
0.74	-27.05	0.063
0.75	-27.01	0.064
0.76	-26.97	0.064
0.77	-26.93	0.065
0.78	-26.89	0.066
0.78	-26.85	0.067
0.79	-26.81	0.067
0.80	-26.77	0.067
0.81	-26.73	0.067
0.82	-26.69	0.068
0.83	-26.65	0.070
0.83	-26.61	0.070
0.84	-26.57	0.070
0.85	-26.53	0.071
0.86	-26.49	0.071
0.87	-26.45	0.072
0.88	-26.41	0.072
0.88	-26.36	0.072
0.89	-26.32	0.072
0.90	-26.28	0.073
0.91	-26.24	0.073
0.92	-26.20	0.073
0.93	-26.16	0.074
0.93	-26.12	0.075
0.94	-26.08	0.076
0.95	-26.04	0.076
0.96	-26.00	0.077
0.97	-25.96	0.078
0.98	-25.91	0.079
0.98	-25.87	0.079
0.99	-25.83	0.080
1.00	-25.79	0.080
1.01	-25.75	0.080
1.02	-25.71	0.081
1.03	-25.67	0.081
1.03	-25.63	0.081
1.04	-25.59	0.082
1.05	-25.54	0.082
1.06	-25.50	0.082
1.07	-25.46	0.082
1.08	-25.42	0.083
1.08	-25.38	0.083
1.09	-25.34	0.083
1.10	-25.30	0.084
1.11	-25.26	0.084
1.12	-25.22	0.084
1.13	-25.17	0.084
1.13	-25.13	0.085
1.14	-25.09	0.085
1.15	-25.05	0.085
1.16	-25.01	0.086
1.17	-24.97	0.086
1.18	-24.93	0.086
1.18	-24.89	0.086
1.19	-24.84	0.087
1.20	-24.80	0.087
1.21	-24.76	0.087
1.22	-24.72	0.087
1.23	-24.68	0.088
1.23	-24.64	0.088
1.24	-24.60	0.088
1.25	-24.55	0.088
1.26	-24.51	0.089
1.27	-24.47	0.089
1.28	-24.43	0.089
1.28	-24.39	0.089
1.29	-24.35	0.089
1.30	-24.31	0.090
1.31	-24.27	0.090
1.32	-24.22	0.090
1.33	-24.18	0.090
1.33	-24.14	0.090
1.34	-24.10	0.091
1.35	-24.06	0.091
1.36	-24.02	0.091
1.37	-23.97	0.091
1.38	-23.93	0.091
1.38	-23.89	0.092
1.39	-23.85	0.092
1.40	-23.81	0.092
1.41	-23.77	0.092
1.42	-23.72	0.093
1.43	-23.68	0.093
1.43	-23.64	0.093
1.44	-23.60	0.093
1.45	-23.56	0.093
1.46	-23.52	0.094
1.47	-23.48	0.094
1.48	-23.43	0.094
1.48	-23.39	0.094
1.49	-23.35	0.094
1.50	-23.31	0.095
1.51	-23.27	0.095
1.52	-23.23	0.095
1.53	-23.19	0.095
1.53	-23.14	0.095
1.54	-23.10	0.095
1.55	-23.06	0.096
1.56	-23.02	0.096
1.57	-22.98	0.096
1.58	-22.94	0.096
1.58	-22.89	0.096
1.59	-22.85	0.096
1.60	-22.81	0.096
1.61	-22.77	0.097
1.62	-22.73	0.097
1.63	-22.69	0.097
1.63	-22.65	0.097
1.64	-22.61	0.097
1.65	-22.56	0.097
1.66	-22.52	0.097
1.67	-22.48	0.097
1.68	-22.44	0.098
1.68	-22.40	0.098
1.69	-22.36	0.098
1.70	-22.31	0.098
1.71	-22.27	0.098
1.72	-22.23	0.098
1.73	-22.19	0.098
1.73	-22.15	0.098
1.74	-22.11	0.098
1.75	-22.06	0.099
1.76	-22.02	0.099
1.77	-21.98	0.099
1.78	-21.94	0.099
1.78	-21.90	0.099
1.79	-21.86	0.099
1.80	-21.81	0.099
1.81	-21.77	0.099
1.82	-21.73	0.099
1.83	-21.69	0.100
1.83	-21.65	0.100
1.84	-21.61	0.100
1.85	-21.56	0.100
1.86	-21.52	0.100
1.87	-21.48	0.100
1.88	-21.44	0.100
1.88	-21.40	0.100
1.89	-21.36	0.100
1.90	-21.31	0.100
1.91	-21.27	0.100
1.92	-21.23	0.100
1.93	-21.19	0.101
1.93	-21.15	0.101
1.94	-21.10	0.101
1.95	-21.06	0.101
1.96	-21.02	0.101
1.97	-20.98	0.101
1.98	-20.94	0.101
1.98	-20.90	0.101
1.99	-20.86	0.101
2.00	-20.82	0.101
2.01	-20.77	0.101
2.02	-20.73	0.102
2.03	-20.69	0.102
2.03	-20.65	0.102
2.04	-20.61	0.102
2.05	-20.57	0.102
2.06	-20.52	0.102
2.07	-20.48	0.102
2.08	-20.44	0.102
2.08	-20.40	0.102
2.09	-20.36	0.102
2.10	-20.31	0.102
2.11	-20.27	0.102
2.12	-20.23	0.102
2.13	-20.19	0.102
2.13	-20.15	0.102
2.14	-20.11	0.103
2.15	-20.06	0.103
2.16	-20.02	0.103
2.17	-19.98	0.103
2.18	-19.94	0.103
2.18	-19.90	0.103
2.19	-19.86	0.103
2.20	-19.81	0.103
2.21	-19.77	0.103
2.22	-19.73	0.103
2.23	-19.69	0.103
2.23	-19.65	0.103
2.24	-19.61	0.103
2.25	-19.57	0.103
2.26	-19.52	0.103
2.27	-19.48	0.103
2.28	-19.44	0.103
2.28	-19.40	0.103
2.29	-19.36	0.104
2.30	-19.31	0.104
2.31	-19.27	0.104
2.32	-19.23	0.104
2.33	-19.19	0.104
2.33	-19.15	0.104
2.34	-19.11	0.104
2.35	-19.06	0.103
2.36	-19.02	0.103
2.37	-18.98	0.104
2.38	-18.94	0.104
2.38	-18.90	0.104
2.39	-18.86	0.104
2.40	-18.82	0.104
2.41	-18.77	0.104
2.42	-18.73	0.104
2.43	-18.69	0.104
2.43	-18.65	0.104
2.44	-18.61	0.104
2.45	-18.56	0.104
2.46	-18.52	0.104
2.47	-18.48	0.104
2.48	-18.44	0.104
2.48	-18.40	0.104
2.49	-18.36	0.104
2.50	-18.32	0.104
2.51	-18.27	0.104
2.52	-18.23	0.104
2.53	-18.19	0.104
2.53	-18.15	0.104
2.54	-18.11	0.104
2.55	-18.07	0.104
2.56	-18.02	0.104
2.57	-17.98	0.104
2.58	-17.94	0.104
2.58	-17.90	0.104
2.59	-17.86	0.104
2.60	-17.82	0.105
2.61	-17.77	0.105
2.62	-17.73	0.105
2.63	-17.69	0.105
2.63	-17.65	0.105
2.64	-17.61	0.105
2.65	-17.56	0.105
2.66	-17.52	0.105
2.67	-17.48	0.105
2.68	-17.44	0.105
2.68	-17.40	0.105
2.69	-17.36	0.105
2.70	-17.31	0.105
2.71	-17.27	0.105
2.72	-17.23	0.105
2.73	-17.19	0.105
2.73	-17.15	0.105
2.74	-17.11	0.105
2.75	-17.06	0.105
2.76	-17.02	0.105
2.77	-16.98	0.105
2.78	-16.94	0.105
2.78	-16.90	0.105
2.79	-16.86	0.105
2.80	-16.81	0.105
2.81	-16.77	0.105
2.82	-16.73	0.105
2.83	-16.69	0.105
2.83	-16.65	0.105
2.84	-16.61	0.105
2.85	-16.57	0.106
2.86	-16.52	0.106
2.87	-16.48	0.106
2.88	-16.44	0.106
2.88	-16.40	0.106
2.89	-16.36	0.106
2.90	-16.31	0.106
2.91	-16.27	0.106
2.92	-16.23	0.106
2.93	-16.19	0.106
2.93	-16.15	0.106
2.94	-16.11	0.106
2.95	-16.07	0.106
2.96	-16.02	0.106
2.97	-15.98	0.106
2.98	-15.94	0.106
2.98	-15.90	0.106
2.99	-15.86	0.106
3.00	-15.81	0.106
3.01	-15.77	0.106
3.02	-15.73	0.106
3.03	-15.69	0.106
3.03	-15.65	0.106
3.04	-15.61	0.106
3.05	-15.57	0.106
3.06	-15.52	0.106
3.07	-15.48	0.106
3.08	-15.44	0.106
3.08	-15.40	0.106
3.09	-15.36	0.106
3.10	-15.31	0.106
3.11	-15.27	0.106
3.12	-15.23	0.106
3.13	-15.19	0.106
3.13	-15.15	0.106
3.14	-15.11	0.106
3.15	-15.06	0.106
3.16	-15.02	0.106
3.17	-14.98	0.106
3.18	-14.94	0.106
3.18	-14.90	0.106
3.19	-14.86	0.106
3.20	-14.81	0.106
3.21	-14.77	0.106
3.22	-14.73	0.106
3.23	-14.69	0.106
3.23	-14.65	0.106
3.24	-14.61	0.106
3.25	-14.56	0.106
3.26	-14.52	0.106
3.27	-14.48	0.106
3.28	-14.44	0.106
3.28	-14.40	0.106
3.29	-14.35	0.106
3.30	-14.31	0.106
3.31	-14.27	0.106
3.32	-14.23	0.106
3.33	-14.19	0.106
3.33	-14.15	0.106
3.34	-14.11	0.106
3.35	-14.06	0.106
3.36	-14.02	0.106
3.37	-13.98	0.106
3.38	-13.94	0.106
3.38	-13.90	0.106
3.39	-13.85	0.106
3.40	-13.81	0.106
3.41	-13.77	0.106
3.42	-13.73	0.106
3.43	-13.69	0.106
3.43	-13.65	0.106
3.44	-13.60	0.106
3.45	-13.56	0.106
3.46	-13.52	0.106
3.47	-13.48	0.107
3.48	-13.44	0.107
3.48	-13.40	0.107
3.49	-13.35	0.107
3.50	-13.31	0.107
3.51	-13.27	0.107
3.52	-13.23	0.107
3.53	-13.19	0.107
3.53	-13.15	0.107
3.54	-13.10	0.107
3.55	-13.06	0.107
3.56	-13.02	0.107
3.57	-12.98	0.107
3.58	-12.94	0.107
3.58	-12.90	0.107
3.59	-12.85	0.107
3.60	-12.81	0.107
3.61	-12.77	0.107
3.62	-12.73	0.107
3.63	-12.69	0.107
3.63	-12.65	0.107
3.64	-12.60	0.107
3.65	-12.56	0.107
3.66	-12.52	0.107
3.67	-12.48	0.107
3.68	-12.44	0.107
3.68	-12.40	0.107
3.69	-12.35	0.107
3.70	-12.31	0.107
3.71	-12.27	0.107
3.72	-12.23	0.107
3.73	-12.19	0.107
3.73	-12.15	0.107
3.74	-12.11	0.108
3.75	-12.06	0.108
3.76	-12.02	0.108
3.77	-11.98	0.108
3.78	-11.94	0.108
3.78	-11.90	0.108
3.79	-11.85	0.108
3.80	-11.81	0.108
3.81	-11.77	0.108
3.82	-11.73	0.108
3.83	-11.69	0.108
3.83	-11.65	0.108
3.84	-11.60	0.108
3.85	-11.56	0.108
3.86	-11.52	0.108
3.87	-11.48	0.108
3.88	-11.44	0.108
3.88	-11.40	0.108
3.89	-11.35	0.108
3.90	-11.31	0.108
3.91	-11.27	0.108
3.92	-11.23	0.108
3.93	-11.19	0.108
3.93	-11.15	0.108
3.94	-11.10	0.108
3.95	-11.06	0.108
3.96	-11.02	0.108
3.97	-10.98	0.108
3.98	-10.94	0.108
3.98	-10.89	0.108
3.99	-10.85	0.108
4.00	-10.81	0.108
4.01	-10.77	0.108
4.02	-10.73	0.108
4.03	-10.69	0.108
4.03	-10.64	0.108
4.04	-10.60	0.108
4.05	-10.56	0.108
4.06	-10.52	0.108
4.07	-10.48	0.108
4.08	-10.44	0.108
4.08	-10.39	0.109
4.09	-10.35	0.109
4.10	-10.31	0.109
4.11	-10.27	0.109
4.12	-10.23	0.109
4.13	-10.19	0.109
4.13	-10.14	0.109
4.14	-10.10	0.109
4.15	-10.06	0.109
4.16	-10.02	0.109
4.17	-9.98	0.109
4.18	-9.94	0.109
4.18	-9.89	0.109
4.19	-9.85	0.109
4.20	-9.81	0.109
4.21	-9.77	0.109
4.22	-9.73	0.109
4.23	-9.68	0.109
4.23	-9.64	0.109
4.24	-9.60	0.109
4.25	-9.56	0.109
4.26	-9.52	0.109
4.27	-9.48	0.109
4.28	-9.44	0.109
4.28	-9.39	0.109
4.29	-9.35	0.109
4.30	-9.31	0.109
4.31	-9.27	0.109
4.32	-9.23	0.109
4.33	-9.18	0.109
4.33	-9.14	0.109
4.34	-9.10	0.110
4.35	-9.06	0.110
4.36	-9.02	0.110
4.37	-8.98	0.110
4.38	-8.93	0.110
4.38	-8.89	0.110
4.39	-8.85	0.110
4.40	-8.81	0.110
4.41	-8.77	0.110
4.42	-8.73	0.110
4.43	-8.69	0.110
4.43	-8.64	0.110
4.44	-8.60	0.110
4.45	-8.56	0.110
4.46	-8.52	0.110
4.47	-8.48	0.110
4.48	-8.44	0.110
4.48	-8.39	0.110
4.49	-8.35	0.110
4.50	-8.31	0.110
4.51	-8.27	0.110
4.52	-8.23	0.110
4.53	-8.19	0.110
4.53	-8.15	0.110
4.54	-8.10	0.110
4.55	-8.06	0.110
4.56	-8.02	0.110
4.57	-7.98	0.110
4.58	-7.94	0.110
4.58	-7.89	0.110
4.59	-7.85	0.110
4.60	-7.81	0.110
4.61	-7.77	0.110
4.62	-7.73	0.110
4.63	-7.68	0.110
4.63	-7.64	0.111
4.64	-7.60	0.111
4.65	-7.56	0.111
4.66	-7.52	0.111
4.67	-7.48	0.111
4.68	-7.44	0.111
4.68	-7.39	0.111
4.69	-7.35	0.111
4.70	-7.31	0.111
4.71	-7.27	0.111
4.72	-7.23	0.111
4.73	-7.18	0.111
4.73	-7.14	0.111
4.74	-7.10	0.111
4.75	-7.06	0.111
4.76	-7.02	0.111
4.77	-6.98	0.111
4.78	-6.93	0.111
4.78	-6.89	0.111
4.79	-6.85	0.111
4.80	-6.81	0.111
4.81	-6.77	0.111
4.82	-6.73	0.111
4.83	-6.68	0.111
4.83	-6.64	0.111
4.84	-6.60	0.112
4.85	-6.56	0.112
4.86	-6.52	0.112
4.87	-6.48	0.112
4.88	-6.43	0.112
4.88	-6.39	0.112
4.89	-6.35	0.112
4.90	-6.31	0.112
4.91	-6.27	0.112
4.92	-6.23	0.112
4.93	-6.19	0.112
4.93	-6.14	0.112
4.94	-6.10	0.112
4.95	-6.06	0.112
4.96	-6.02	0.112
4.97	-5.98	0.112
4.98	-5.93	0.112
4.98	-5.89	0.112
4.99	-5.85	0.112
5.00	-5.81	0.112
5.01	-5.77	0.112
5.02	-5.73	0.112
5.03	-5.69	0.112
5.03	-5.64	0.112
5.04	-5.60	0.113
5.05	-5.56	0.113
5.06	-5.52	0.113
5.07	-5.48	0.113
5.08	-5.43	0.113
5.08	-5.39	0.113
5.09	-5.35	0.113
5.10	-5.31	0.113
5.11	-5.27	0.113
5.12	-5.23	0.113
5.13	-5.18	0.113
5.13	-5.14	0.113
5.14	-5.10	0.113
5.15	-5.06	0.113
5.16	-5.02	0.113
5.17	-4.98	0.113
5.18	-4.93	0.113
5.18	-4.89	0.114
5.19	-4.85	0.114
5.20	-4.81	0.114
5.21	-4.77	0.114
5.22	-4.73	0.114
5.23	-4.69	0.114
5.23	-4.64	0.114
5.24	-4.60	0.114
5.25	-4.56	0.114
5.26	-4.52	0.114
5.27	-4.48	0.114
5.28	-4.43	0.114
5.28	-4.39	0.114
5.29	-4.35	0.114
5.30	-4.31	0.114
5.31	-4.27	0.114
5.32	-4.23	0.115
5.33	-4.18	0.115
5.33	-4.14	0.115
5.34	-4.10	0.115
5.35	-4.06	0.115
5.36	-4.02	0.115
5.37	-3.98	0.115
5.38	-3.93	0.115
5.38	-3.89	0.116
5.39	-3.85	0.116
5.40	-3.81	0.116
5.41	-3.77	0.116
5.42	-3.73	0.116
5.43	-3.68	0.116
5.43	-3.64	0.117
5.44	-3.60	0.117
5.45	-3.56	0.117
5.46	-3.52	0.117
5.47	-3.48	0.117
5.48	-3.43	0.117
5.48	-3.39	0.117
5.49	-3.35	0.118
5.50	-3.31	0.118
5.51	-3.27	0.118
5.52	-3.23	0.118
5.53	-3.18	0.118
5.53	-3.14	0.119
5.54	-3.10	0.119
5.55	-3.06	0.119
5.56	-3.02	0.119
5.57	-2.98	0.120
5.58	-2.94	0.120
5.58	-2.89	0.120
5.59	-2.85	0.121
5.60	-2.81	0.121
5.61	-2.77	0.122
5.62	-2.73	0.122
5.63	-2.69	0.123
5.63	-2.64	0.124
5.64	-2.60	0.124
5.65	-2.56	0.125
5.66	-2.52	0.127
5.67	-2.48	0.129
5.68	-2.44	0.132
5.68	-2.40	0.133
5.69	-2.36	0.134
5.70	-2.31	0.136
5.71	-2.27	0.138
5.72	-2.23	0.143
5.73	-2.19	0.148
5.73	-2.15	0.152
5.74	-2.11	0.157
5.75	-2.07	0.163
5.76	-2.03	0.169
5.77	-1.98	0.177
5.78	-1.94	0.185
5.78	-1.90	0.195
5.79	-1.86	0.203
5.80	-1.82	0.218
5.81	-1.78	0.234
5.82	-1.74	0.254
5.83	-1.71	0.277
5.83	-1.67	0.304
5.84	-1.63	0.340
5.85	-1.59	0.382
5.86	-1.56	0.434
5.87	-1.52	0.493
5.88	-1.49	0.558
5.88	-1.46	0.633
5.89	-1.43	0.715
5.90	-1.41	0.802
5.91	-1.38	0.890
5.92	-1.35	0.984
5.93	-1.33	1.075
5.93	-1.31	1.168
5.94	-1.28	1.260
5.95	-1.27	1.351
5.96	-1.24	1.444
5.97	-1.22	1.531
5.98	-1.20	1.622
5.98	-1.19	1.712
5.99	-1.17	1.799
6.00	-1.15	1.887
6.01	-1.13	1.977
6.02	-1.11	2.068
6.03	-1.09	2.152
6.03	-1.07	2.228
6.04	-1.06	2.328
6.05	-1.04	2.424
6.06	-1.02	2.496
6.07	-1.00	2.583
6.08	-0.98	2.674
6.08	-0.96	2.760
6.09	-0.95	2.844
6.10	-0.93	2.934
6.11	-0.91	3.017
6.12	-0.89	3.103
6.13	-0.87	3.188
6.13	-0.86	3.272
6.14	-0.84	3.355
6.15	-0.82	3.437
6.16	-0.80	3.523
6.17	-0.78	3.608
6.18	-0.76	3.693
6.18	-0.75	3.778
6.19	-0.73	3.860
6.20	-0.71	3.945
6.21	-0.69	4.027
6.22	-0.67	4.109
6.23	-0.65	4.190
6.23	-0.64	4.272
6.24	-0.62	4.354
6.25	-0.60	4.430
6.26	-0.58	4.510
6.27	-0.56	4.591
6.28	-0.54	4.674
6.28	-0.52	4.753
6.29	-0.50	4.831
6.30	-0.48	4.908
6.31	-0.46	4.985
6.32	-0.44	5.064
6.33	-0.42	5.140
6.33	-0.40	5.216
6.34	-0.38	5.285
6.35	-0.36	5.353
6.36	-0.34	5.424
6.37	-0.32	5.497
6.38	-0.30	5.574
6.38	-0.28	5.651
6.39	-0.26	5.712
6.40	-0.23	5.765
6.41	-0.21	5.817
6.42	-0.19	5.868
6.43	-0.16	5.912
6.43	-0.14	5.956
6.44	-0.11	6.031
6.45	-0.09	6.104
6.46	-0.06	6.133
6.47	-0.04	6.139
6.48	-0.01	6.123
6.48	0.03	6.091
6.49	0.06	6.059
6.50	0.10	6.035
6.51	0.14	6.028
6.52	0.18	6.034
6.53	0.21	6.043
6.53	0.25	6.076
6.54	0.29	6.103
6.55	0.33	6.071
6.56	0.37	5.988
6.57	0.41	5.850
6.58	0.47	5.684
6.58	0.52	5.505
6.59	0.59	5.333
6.60	0.65	5.196
6.61	0.72	5.048
6.62	0.79	4.834
6.63	0.86	4.541
6.63	0.95	4.201
6.64	1.04	3.849
6.65	1.14	3.557
6.66	1.24	3.347
6.67	1.33	3.171
6.68	1.43	2.994
6.68	1.52	2.790
6.69	1.62	2.558
6.70	1.72	2.335
6.71	1.82	2.163
6.72	1.91	2.023
6.73	2.00	1.903
6.73	2.09	1.794
6.74	2.18	1.694
6.75	2.26	1.605
6.76	2.34	1.520
6.77	2.42	1.440
6.78	2.50	1.366
6.78	2.57	1.298
6.79	2.65	1.232
6.80	2.72	1.178
6.81	2.79	1.109
6.82	2.86	1.057
6.83	2.92	1.020
6.83	2.98	0.962
6.84	3.05	0.914
6.85	3.11	0.876
6.86	3.17	0.836
6.87	3.23	0.798
6.88	3.29	0.763
6.88	3.35	0.730
6.89	3.40	0.699
6.90	3.46	0.670
6.91	3.51	0.643
6.92	3.57	0.619
6.93	3.62	0.594
6.93	3.67	0.570
6.94	3.72	0.550
6.95	3.77	0.531
6.96	3.82	0.512
6.97	3.87	0.492
6.98	3.92	0.478
6.98	3.97	0.462
6.99	4.02	0.446
7.00	4.07	0.432
7.01	4.12	0.421
7.02	4.16	0.408
7.03	4.21	0.395
7.03	4.26	0.385
7.04	4.30	0.375
7.05	4.35	0.367
7.06	4.40	0.357
7.07	4.44	0.347
7.08	4.49	0.342
7.08	4.53	0.335
7.09	4.58	0.328
7.10	4.62	0.322
7.11	4.67	0.316
7.12	4.71	0.309
7.13	4.76	0.304
7.13	4.80	0.301
7.14	4.84	0.295
7.15	4.89	0.290
7.16	4.93	0.288
7.17	4.97	0.282
7.18	5.02	0.277
7.18	5.06	0.277
7.19	5.10	0.272
7.20	5.15	0.268
7.21	5.19	0.266
7.22	5.23	0.264
7.23	5.28	0.263
7.23	5.32	0.258
7.24	5.36	0.256
7.25	5.40	0.255
7.26	5.45	0.252
7.27	5.49	0.252
7.28	5.53	0.251
7.28	5.57	0.249
7.29	5.62	0.248
7.30	5.66	0.246
7.31	5.70	0.245
7.32	5.74	0.244
7.33	5.79	0.243
7.33	5.83	0.243
7.34	5.87	0.242
7.35	5.91	0.242
7.36	5.96	0.241
7.37	6.00	0.240
7.38	6.04	0.239
7.38	6.08	0.239
7.39	6.12	0.238
7.40	6.16	0.237
7.41	6.21	0.237
7.42	6.25	0.237
7.43	6.29	0.236
7.43	6.33	0.236
7.44	6.37	0.235
7.45	6.42	0.235
7.46	6.46	0.234
7.47	6.50	0.234
7.48	6.54	0.234
7.48	6.58	0.233
7.49	6.63	0.233
7.50	6.67	0.232
7.51	6.71	0.232
7.52	6.75	0.232
7.53	6.79	0.232
7.53	6.84	0.231
7.54	6.88	0.231
7.55	6.92	0.231
7.56	6.96	0.231
7.57	7.00	0.230
7.58	7.04	0.230
7.58	7.09	0.230
7.59	7.13	0.230
7.60	7.17	0.230
7.61	7.21	0.230
7.62	7.25	0.229
7.63	7.30	0.229
7.63	7.34	0.229
7.64	7.38	0.229
7.65	7.42	0.229
7.66	7.46	0.228
7.67	7.50	0.228
7.68	7.55	0.228
7.68	7.59	0.228
7.69	7.63	0.228
7.70	7.67	0.227
7.71	7.71	0.227
7.72	7.75	0.227
7.73	7.80	0.227
7.73	7.84	0.227
7.74	7.88	0.227
7.75	7.92	0.227
7.76	7.96	0.226
7.77	8.00	0.226
7.78	8.05	0.226
7.78	8.09	0.226
7.79	8.13	0.226
7.80	8.17	0.226
7.81	8.21	0.226
7.82	8.25	0.226
7.83	8.30	0.226
7.83	8.34	0.225
7.84	8.38	0.225
7.85	8.42	0.225
7.86	8.46	0.225
7.87	8.50	0.225
7.88	8.55	0.225
7.88	8.59	0.225
7.89	8.63	0.225
7.90	8.67	0.225
7.91	8.71	0.224
7.92	8.75	0.224
7.93	8.80	0.224
7.93	8.84	0.224
7.94	8.88	0.224
7.95	8.92	0.224
7.96	8.96	0.224
7.97	9.01	0.224
7.98	9.05	0.224
7.98	9.09	0.224
7.99	9.13	0.224
8.00	9.17	0.224
8.01	9.21	0.224
8.02	9.25	0.224
8.03	9.30	0.224
8.03	9.34	0.224
8.04	9.38	0.224
8.05	9.42	0.224
8.06	9.46	0.223
8.07	9.51	0.223
8.08	9.55	0.223
8.08	9.59	0.223
8.09	9.63	0.224
8.10	9.67	0.223
8.11	9.71	0.223
8.12	9.76	0.223
8.13	9.80	0.223
8.13	9.84	0.223
8.14	9.88	0.223
8.15	9.92	0.223
8.16	9.97	0.223
8.17	10.01	0.223
8.18	10.05	0.223
8.18	10.09	0.223
8.19	10.13	0.223
8.20	10.17	0.223
8.21	10.22	0.223
8.22	10.26	0.223
8.23	10.30	0.223
8.23	10.34	0.223
8.24	10.38	0.223
8.25	10.42	0.223
8.26	10.46	0.223
8.27	10.51	0.223
8.28	10.55	0.223
8.28	10.59	0.223
8.29	10.63	0.223
8.30	10.67	0.223
8.31	10.71	0.223
8.32	10.76	0.223
8.33	10.80	0.223
8.33	10.84	0.223
8.34	10.88	0.223
8.35	10.92	0.223
8.36	10.97	0.223
8.37	11.01	0.223
8.38	11.05	0.223
8.38	11.09	0.223
8.39	11.13	0.223
8.40	11.17	0.223
8.41	11.22	0.223
8.42	11.26	0.223
8.43	11.30	0.223
8.43	11.34	0.223
8.44	11.38	0.223
8.45	11.42	0.223
8.46	11.47	0.223
8.47	11.51	0.223
8.48	11.55	0.223
8.48	11.59	0.223
8.49	11.63	0.223
8.50	11.67	0.223
8.51	11.72	0.223
8.52	11.76	0.223
8.53	11.80	0.223
8.53	11.84	0.223
8.54	11.88	0.223
8.55	11.92	0.223
8.56	11.97	0.223
8.57	12.01	0.223
8.58	12.05	0.223
8.58	12.09	0.223
8.59	12.13	0.223
8.60	12.17	0.223
8.61	12.22	0.223
8.62	12.26	0.223
8.63	12.30	0.223
8.63	12.34	0.223
8.64	12.38	0.223
8.65	12.42	0.223
8.66	12.47	0.223
8.67	12.51	0.223
8.68	12.55	0.223
8.68	12.59	0.223
8.69	12.63	0.223
8.70	12.67	0.223
8.71	12.72	0.223
8.72	12.76	0.224
8.73	12.80	0.224
8.73	12.84	0.224
8.74	12.88	0.224
8.75	12.92	0.224
8.76	12.97	0.224
8.77	13.01	0.224
8.78	13.05	0.224
8.78	13.09	0.224
8.79	13.13	0.224
8.80	13.17	0.224
8.81	13.22	0.224
8.82	13.26	0.224
8.83	13.30	0.224
8.83	13.34	0.224
8.84	13.38	0.224
8.85	13.42	0.224
8.86	13.47	0.224
8.87	13.51	0.224
8.88	13.55	0.224
8.88	13.59	0.224
8.89	13.63	0.224
8.90	13.67	0.224
8.91	13.72	0.224
8.92	13.76	0.223
8.93	13.80	0.223
8.93	13.84	0.223
8.94	13.88	0.223
8.95	13.93	0.223
8.96	13.97	0.223
8.97	14.01	0.223
8.98	14.05	0.223
8.98	14.09	0.223
8.99	14.13	0.224
9.00	14.18	0.224
9.01	14.22	0.224
9.02	14.26	0.224
9.03	14.30	0.224
9.03	14.34	0.224
9.04	14.39	0.224
9.05	14.43	0.224
9.06	14.47	0.224
9.07	14.51	0.224
9.08	14.55	0.224
9.08	14.59	0.224
9.09	14.64	0.224
9.10	14.68	0.224
9.11	14.72	0.224
9.12	14.76	0.224
9.13	14.80	0.224
9.13	14.84	0.224
9.14	14.88	0.224
9.15	14.93	0.224
9.16	14.97	0.224
9.17	15.01	0.224
9.18	15.05	0.224
9.18	15.09	0.224
9.19	15.14	0.224
9.20	15.18	0.224
9.21	15.22	0.224
9.22	15.26	0.224
9.23	15.30	0.224
9.23	15.34	0.224
9.24	15.38	0.224
9.25	15.43	0.224
9.26	15.47	0.224
9.27	15.51	0.225
9.28	15.55	0.224
9.28	15.59	0.224
9.29	15.63	0.225
9.30	15.68	0.225
9.31	15.72	0.225
9.32	15.76	0.225
9.33	15.80	0.225
9.33	15.84	0.225
9.34	15.89	0.225
9.35	15.93	0.225
9.36	15.97	0.225
9.37	16.01	0.225
9.38	16.05	0.225
9.38	16.09	0.225
9.39	16.14	0.225
9.40	16.18	0.225
9.41	16.22	0.225
9.42	16.26	0.225
9.43	16.30	0.225
9.43	16.34	0.225
9.44	16.39	0.225
9.45	16.43	0.225
9.46	16.47	0.225
9.47	16.51	0.225
9.48	16.55	0.225
9.48	16.59	0.225
9.49	16.64	0.225
9.50	16.68	0.225
9.51	16.72	0.225
9.52	16.76	0.225
9.53	16.80	0.225
9.53	16.84	0.225
9.54	16.89	0.225
9.55	16.93	0.225
9.56	16.97	0.225
9.57	17.01	0.225
9.58	17.05	0.225
9.58	17.09	0.225
9.59	17.14	0.225
9.60	17.18	0.225
9.61	17.22	0.225
9.62	17.26	0.225
9.63	17.30	0.225
9.63	17.34	0.225
9.64	17.39	0.225
9.65	17.43	0.225
9.66	17.47	0.225
9.67	17.51	0.225
9.68	17.55	0.225
9.68	17.59	0.225
9.69	17.64	0.225
9.70	17.68	0.225
9.71	17.72	0.225
9.72	17.76	0.225
9.73	17.80	0.225
9.73	17.85	0.225
9.74	17.89	0.225
9.75	17.93	0.225
9.76	17.97	0.225
9.77	18.01	0.225
9.78	18.05	0.225
9.78	18.09	0.225
9.79	18.14	0.225
9.80	18.18	0.225
9.81	18.22	0.225
9.82	18.26	0.226
9.83	18.30	0.226
9.83	18.34	0.226
9.84	18.39	0.226
9.85	18.43	0.226
9.86	18.47	0.226
9.87	18.51	0.226
9.88	18.55	0.226
9.88	18.59	0.226
9.89	18.64	0.226
9.90	18.68	0.226
9.91	18.72	0.226
9.92	18.76	0.226
9.93	18.80	0.226
9.93	18.84	0.226
9.94	18.89	0.226
9.95	18.93	0.226
9.96	18.97	0.226
9.97	19.01	0.226
9.98	19.05	0.226
9.98	19.10	0.226
9.99	19.14	0.226
10.00	19.18	0.226
10.01	19.22	0.226
10.02	19.26	0.226
10.03	19.30	0.226
10.03	19.35	0.226
10.04	19.39	0.226
10.05	19.43	0.226
10.06	19.47	0.226
10.07	19.51	0.226
10.08	19.55	0.226
10.08	19.60	0.226
10.09	19.64	0.226
10.10	19.68	0.226
10.11	19.72	0.226
10.12	19.76	0.226
10.13	19.80	0.226
10.13	19.85	0.226
10.14	19.89	0.226
10.15	19.93	0.226
10.16	19.97	0.226
10.17	20.01	0.226
10.18	20.05	0.226
10.18	20.10	0.226
10.19	20.14	0.226
10.20	20.18	0.226
10.21	20.22	0.226
10.22	20.26	0.226
10.23	20.31	0.226
10.23	20.34	0.226
10.24	20.39	0.226
10.25	20.43	0.226
10.26	20.47	0.226
10.27	20.51	0.227
10.28	20.55	0.227
10.28	20.60	0.227
10.29	20.64	0.227
10.30	20.68	0.227
10.31	20.72	0.227
10.32	20.76	0.227
10.33	20.80	0.226
10.33	20.85	0.227
10.34	20.89	0.227
10.35	20.93	0.227
10.36	20.97	0.226
10.37	21.01	0.226
10.38	21.06	0.226
10.38	21.10	0.226
10.39	21.14	0.226
10.40	21.18	0.226
10.41	21.22	0.227
10.42	21.26	0.227
10.43	21.31	0.227
10.43	21.35	0.227
10.44	21.39	0.227
10.45	21.43	0.227
10.46	21.47	0.227
10.47	21.51	0.227
10.48	21.56	0.227
10.48	21.60	0.227
10.49	21.64	0.227
10.50	21.68	0.227
10.51	21.72	0.227
10.52	21.76	0.227
10.53	21.81	0.227
10.53	21.85	0.227
10.54	21.89	0.227
10.55	21.93	0.227
10.56	21.97	0.227
10.57	22.01	0.227
10.58	22.06	0.227
10.58	22.10	0.227
10.59	22.14	0.227
10.60	22.18	0.227
10.61	22.22	0.227
10.62	22.26	0.227
10.63	22.31	0.227
10.63	22.35	0.227
10.64	22.39	0.227
10.65	22.43	0.227
10.66	22.47	0.227
10.67	22.51	0.227
10.68	22.56	0.227
10.68	22.60	0.227
10.69	22.64	0.227
10.70	22.68	0.227
10.71	22.72	0.227
10.72	22.76	0.227
10.73	22.81	0.227
10.73	22.85	0.227
10.74	22.89	0.227
10.75	22.93	0.227
10.76	22.97	0.227
10.77	23.01	0.227
10.78	23.06	0.227
10.78	23.10	0.227
10.79	23.14	0.227
10.80	23.18	0.227
10.81	23.22	0.227
10.82	23.27	0.227
10.83	23.31	0.227
10.83	23.35	0.227
10.84	23.39	0.227
10.85	23.43	0.227
10.86	23.47	0.227
10.87	23.52	0.227
10.88	23.56	0.228
10.88	23.60	0.228
10.89	23.64	0.228
10.90	23.68	0.228
10.91	23.72	0.228
10.92	23.76	0.228
10.93	23.81	0.228
10.93	23.85	0.228
10.94	23.89	0.228
10.95	23.93	0.228
10.96	23.97	0.228
10.97	24.02	0.228
10.98	24.06	0.228
10.98	24.10	0.228
10.99	24.14	0.228
11.00	24.18	0.228
11.01	24.22	0.228
11.02	24.27	0.228
11.03	24.31	0.228
11.03	24.35	0.228
11.04	24.39	0.228
11.05	24.43	0.228
11.06	24.47	0.228
11.07	24.52	0.228
11.08	24.56	0.228
11.08	24.60	0.228
11.09	24.64	0.228
11.10	24.68	0.228
11.11	24.72	0.228
11.12	24.77	0.228
11.13	24.81	0.228
11.13	24.85	0.228
11.14	24.89	0.228
11.15	24.93	0.228
11.16	24.97	0.228
11.17	25.02	0.228
11.18	25.06	0.228
11.18	25.10	0.228
11.19	25.14	0.228
11.20	25.18	0.228
11.21	25.22	0.228
11.22	25.27	0.229
11.23	25.31	0.229
11.23	25.35	0.229
11.24	25.39	0.229
11.25	25.43	0.229
11.26	25.47	0.229
11.27	25.52	0.229
11.28	25.56	0.229
11.28	25.60	0.229
11.29	25.64	0.229
11.30	25.68	0.229
11.31	25.72	0.229
11.32	25.77	0.229
11.33	25.81	0.229
11.33	25.85	0.229
11.34	25.89	0.229
11.35	25.93	0.229
11.36	25.97	0.229
11.37	26.02	0.229
11.38	26.06	0.229
11.38	26.10	0.229
11.39	26.14	0.229
11.40	26.18	0.229
11.41	26.22	0.229
11.42	26.27	0.229
11.43	26.31	0.229
11.43	26.35	0.229
11.44	26.39	0.229
11.45	26.43	0.229
11.46	26.47	0.229
11.47	26.52	0.229
11.48	26.56	0.229
11.48	26.60	0.229
11.49	26.64	0.229
11.50	26.68	0.229
11.51	26.72	0.229
11.52	26.77	0.229
11.53	26.81	0.229
11.53	26.85	0.229
11.54	26.89	0.229
11.55	26.93	0.229
11.56	26.98	0.229
11.57	27.02	0.229
11.58	27.06	0.229
11.58	27.10	0.229
11.59	27.14	0.229
11.60	27.18	0.229
11.61	27.23	0.229
11.62	27.27	0.229
11.63	27.31	0.229
11.63	27.35	0.229
11.64	27.39	0.229
11.65	27.44	0.229
11.66	27.48	0.230
11.67	27.52	0.230
11.68	27.56	0.230
11.68	27.60	0.230
11.69	27.64	0.230
11.70	27.69	0.230
11.71	27.73	0.230
11.72	27.77	0.230
11.73	27.81	0.230
11.73	27.85	0.230
11.74	27.89	0.230
11.75	27.94	0.230
11.76	27.98	0.230
11.77	28.02	0.230
11.78	28.06	0.230
11.78	28.10	0.230
11.79	28.14	0.230
11.80	28.19	0.230
11.81	28.23	0.231
11.82	28.27	0.231
11.83	28.31	0.231
11.83	28.35	0.231
11.84	28.39	0.231
11.85	28.44	0.231
11.86	28.48	0.231
11.87	28.52	0.231
11.88	28.56	0.231
11.88	28.60	0.231
11.89	28.64	0.231
11.90	28.69	0.231
11.91	28.73	0.231
11.92	28.77	0.231
11.93	28.81	0.231
11.93	28.85	0.231
11.94	28.89	0.231
11.95	28.94
11.96	28.98
11.97	29.02
11.98	29.06
11.98	29.10
11.99	29.14
12.00