File: DSC/2025_06_30_Ibuprofen_n60C_100C_10Cmin_x4.csv
Filename,2025_06_30_Ibuprofen_n60C_100C_10Cmin_x4
Instrument name,DSC2A-00468 (192.168.1.100)
Operator,Gibbons
rundate,6/30/2025
Sample name,2025_06_30_Ibuprofen_n60C_100C_10Cmin_x4
proceduresegments,Data Off ; Equilibrate -60.00 °C; Data On ; Ramp 10.00 °C/min to 100.00 °C; Data Off ; Isothermal 2.0 min; Data On ; Ramp 10.00 °C/min to -60.00 °C; Data Off ; Isothermal 2.0 min; Data On ; Ramp 10.00 °C/min to 100.00 °C; Data Off ; Isothermal 2.0 min; Data On ; Ramp 10.00 °C/min to -60.00 °C; Data Off ; Isothermal 2.0 min; Data On ; Ramp 10.00 °C/min to 100.00 °C; Data Off ; Isothermal 2.0 min; Data On ; Ramp 10.00 °C/min to -60.00 °C; Data Off ; Isothermal 2.0 min; Data On ; Ramp 10.00 °C/min to 30.00 °C
[File Parameters]
Run date,6/30/2025 6:13:34 PM
Trios version,5.1.1.46572
Original File Name,
Current File Name,D:\DSC2500\Gibbons\2025_06_30_Ibuprofen_n60C_100C_10Cmin_x4.tri
[Procedure]
Procedure Name,Ibuprofen_n60C_100C_10Cmin_x4
Sample Name,2025_06_30_Ibuprofen_n60C_100C_10Cmin_x4
Sample Mass,8.16 mg
Reference Sample Mass,0 mg
Pan Mass,56.6 mg
Pan Number,5
Reference Pan Mass,56.76 mg
Reference Pan Number,10
Pan Type,Tzero Aluminum Hermetic
Comments,Al Hermetic DSC Consumables sealed Pan/Lid. Y1 Tray (Google Sheet: DSC_Samples_Y1_Tray_June2025). Run after an empty DSC run to confirm no water was absorbed overnight.
Project Name,Pharma - Cocrystals
Operator,Gibbons
Test,Custom
Unload Max Temperature,30
Unload Min Temperature,30
Load Max Temperature,30
Load Min Temperature,30
Stop on Gas Flow Error,Yes
[Signal List]
Signal #1,Time (min)
Signal #2,Temperature (°C)
Signal #3,Heat Flow (mW)
Signal #4,Delta T (µV)
Signal #5,Delta Tzero (µV)
Signal #6,Tzero Temperature (°C)
Signal #7,Cell Purge (mL/min)
Signal #8,Heater Temp (°C)
Signal #9,Power Delivered (W)
Signal #10,Reference Junction Temperature (°C)
Signal #11,Flange Temperature (°C)
Signal #12,Heat Flow Phase (rad)
Signal #13,Total Heat Capacity (J/°C)
Signal #14,Heat Capacity (J/°C)
[Configuration]
Company Name,ASU
Instrument Name,DSC2A-00468
Instrument Type,DSC2500
Serial Number,DSC2A-00468
IP,192.168.1.100
Location of Instrument,MRRC
DisplayType,Unknown
Sample Interval ,0.1 s/pt
Selected Heat Flow,T4P
Exotherm Direction,Down
Cell Serial,DRC2-00792
Lid Type,Standard
Cooler,RCS 90
Leave Cooler on at End of Sequence,On
Gas 2,Nitrogen
Gas Selected,Channel 1
Flow Rate,50 mL/min
Secondary Purge,On
Licensed Heat Flow,Heat Flow T4P
Modulation Licensed,Yes
[Versions]
Common IDD Version,1
Cortex Version,VER 2.10.2.31
Driver,5.0.0.6
GDM Version,1.0.3.3
TouchscreenVersion,1.0.0.16145
FEP Version,1.2.1.21
FEP Bootloader,2.0.0.5
AutoSampler Version,2.1.1.26
Auto Sampler Bootloader,2.0.0.5
FCM Version,1.1.0.3
FCM Bootloader,2.0.0.5
[Experiment Logs]
Experiment Log Entry # 1,Data On set to 0
Experiment Log Entry # 3,Air Cool is off.
Experiment Log Entry # 4,Equilibrate Segment -60 (C) Started
Experiment Log Entry # 7,Data On set to 1
Experiment Log Entry # 9,Ramp Segment 10 C/min to 100 Started
Experiment Log Entry # 11,Data On set to 0
Experiment Log Entry # 13,Isothermal Segment 2 min started
Experiment Log Entry # 15,Data On set to 1
Experiment Log Entry # 17,Ramp Segment 10 C/min to -60 Started
Experiment Log Entry # 19,Data On set to 0
Experiment Log Entry # 21,Isothermal Segment 2 min started
Experiment Log Entry # 23,Data On set to 1
Experiment Log Entry # 25,Ramp Segment 10 C/min to 100 Started
Experiment Log Entry # 27,Data On set to 0
Experiment Log Entry # 29,Isothermal Segment 2 min started
Experiment Log Entry # 31,Data On set to 1
Experiment Log Entry # 33,Ramp Segment 10 C/min to -60 Started
Experiment Log Entry # 35,Data On set to 0
Experiment Log Entry # 37,Isothermal Segment 2 min started
Experiment Log Entry # 39,Data On set to 1
Experiment Log Entry # 41,Ramp Segment 10 C/min to 100 Started
Experiment Log Entry # 43,Data On set to 0
Experiment Log Entry # 45,Isothermal Segment 2 min started
Experiment Log Entry # 47,Data On set to 1
Experiment Log Entry # 49,Ramp Segment 10 C/min to -60 Started
Experiment Log Entry # 51,Data On set to 0
Experiment Log Entry # 53,Isothermal Segment 2 min started
Experiment Log Entry # 55,Data On set to 1
Experiment Log Entry # 57,Ramp Segment 10 C/min to 30 Started
[Method Log]
Method Log Entry # 1,Data Off
Method Log Entry # 2,Equilibrate -60 °C
Method Log Entry # 3,Data On
Method Log Entry # 4,(Ramp 874736) Ramp 10 °C/minute to 100 °C
Method Log Entry # 5,Data Off
Method Log Entry # 6,Isothermal 2 minutes
Method Log Entry # 7,Data On
Method Log Entry # 8,(Ramp 874740) Ramp 10 °C/minute to -60 °C
Method Log Entry # 9,Data Off
Method Log Entry # 10,Isothermal 2 minutes
Method Log Entry # 11,Data On
Method Log Entry # 12,(Ramp 874744) Ramp 10 °C/minute to 100 °C
Method Log Entry # 13,Data Off
Method Log Entry # 14,Isothermal 2 minutes
Method Log Entry # 15,Data On
Method Log Entry # 16,(Ramp 874748) Ramp 10 °C/minute to -60 °C
Method Log Entry # 17,Data Off
Method Log Entry # 18,Isothermal 2 minutes
Method Log Entry # 19,Data On
Method Log Entry # 20,(Ramp 874752) Ramp 10 °C/minute to 100 °C
Method Log Entry # 21,Data Off
Method Log Entry # 22,Isothermal 2 minutes
Method Log Entry # 23,Data On
Method Log Entry # 24,(Ramp 874756) Ramp 10 °C/minute to -60 °C
Method Log Entry # 25,Data Off
Method Log Entry # 26,Isothermal 2 minutes
Method Log Entry # 27,Data On
Method Log Entry # 28,(Ramp 874760) Ramp 10 °C/minute to 30 °C
Cell Serial,DRC2-00792
[T1 Calibration]
Slope,-0.008529666
Offset,9.636258
Initial Temperature,98.23
GUID,f8bfdadc-4977-4fdf-ba6d-0ba9134940c3
[TZero Calibration]
Date Applied,11/29/2022 4:06:13 PM
Description,From -89.059 °C to 396.009 °C at 20.000°C/min
Gas Type,Nitrogen
Pan Type,None
Source Files 1,C:\Users\yargerlab\Desktop\DSC Data\General\TZero_calibration_11_29_22_2nd(2).tri
Source Files 2,C:\Users\yargerlab\Desktop\DSC Data\General\TZero_calibration_11_29_22_2nd(3).tri
Delta T Offset,13.05235
Delta T Slope,-0.007271007
Delta T0 Offset,-13.69128
Delta T0 Slope,0.06063341
[Temperature Calibration]
Date Applied,11/29/2022 7:12:28 PM
Description,From 106.590 °C to 186.590 °C at 10.000°C/min
Gas Type,Nitrogen
Pan Type,Tzero Aluminum Hermetic
Source Files 1,C:\Users\yargerlab\Desktop\DSC Data\General\Indium(6).tri
Measured 1,157.391
Known 1,156.598
[Cell Constant Calibration]
Date Applied,11/29/2022 7:12:29 PM
Description,From 106.590 °C to 186.590 °C at 10.000°C/min
Gas Type,Nitrogen
Pan Type,Tzero Aluminum Hermetic
Source Files 1,C:\Users\yargerlab\Desktop\DSC Data\General\Indium(6).tri
T4P KCell,1.006051
Onset Slope,63.26126 mW/°C
[Direct Cp Calibration]
Date Applied,11/30/2022 11:04:51 AM
Description,From -79.983 °C to 298.409 °C at 10.000°C/min
Gas Type,Nitrogen
Pan Type,Tzero Aluminum Hermetic
Source Files 1,C:\Users\yargerlab\Desktop\DSC Data\General\Sapphire_Heat_Capacity_11_30_22.tri
[Rev Cp Calibration]
Date Applied,11/30/2022 1:58:51 PM
Description,From -79.996 °C to 292.812 °C at 3.000°C/min
Gas Type,Nitrogen
Pan Type,Tzero Aluminum Hermetic
Source Files 1,C:\Users\yargerlab\Desktop\DSC Data\General\Sapphire_MDSC_Calibration_11_30_22.tri
[step]
Ramp 10.00 °C/min to 100.00 °C
Time,Temperature,Heat Flow (Normalized)
min,°C,W/g
0.00,-59.69,-0.040
0.01,-59.70,-0.040
0.02,-59.70,-0.037
0.03,-59.71,-0.034
0.05,-59.71,-0.031
0.06,-59.71,-0.027
0.07,-59.70,-0.022
0.08,-59.68,-0.018
0.09,-59.66,-0.012
0.11,-59.62,-0.005
0.12,-59.58,0.003
0.13,-59.54,0.012
0.14,-59.48,0.021
0.15,-59.42,0.031
0.16,-59.35,0.042
0.18,-59.28,0.053
0.19,-59.20,0.063
0.20,-59.12,0.073
0.21,-59.03,0.082
0.22,-58.95,0.092
0.23,-58.86,0.101
0.24,-58.76,0.108
0.26,-58.67,0.116
0.27,-58.57,0.123
0.28,-58.47,0.129
0.29,-58.38,0.134
0.30,-58.27,0.139
0.31,-58.17,0.145
0.33,-58.07,0.149
0.34,-57.96,0.151
0.35,-57.86,0.157
0.36,-57.76,0.159
0.37,-57.65,0.162
0.39,-57.54,0.164
0.40,-57.43,0.166
0.41,-57.33,0.169
0.42,-57.22,0.172
0.43,-57.11,0.173
0.44,-57.00,0.174
0.45,-56.89,0.176
0.47,-56.78,0.178
0.48,-56.67,0.179
0.49,-56.56,0.181
0.50,-56.45,0.181
0.51,-56.34,0.182
0.53,-56.22,0.183
0.54,-56.11,0.184
0.55,-56.00,0.185
0.56,-55.89,0.186
0.57,-55.77,0.186
0.58,-55.66,0.186
0.60,-55.55,0.187
0.61,-55.43,0.188
0.62,-55.32,0.188
0.63,-55.21,0.189
0.64,-55.09,0.189
0.65,-54.98,0.189
0.67,-54.87,0.190
0.68,-54.75,0.190
0.69,-54.64,0.190
0.70,-54.52,0.190
0.71,-54.41,0.191
0.72,-54.29,0.191
0.73,-54.18,0.191
0.75,-54.07,0.191
0.76,-53.95,0.192
0.77,-53.84,0.192
0.78,-53.72,0.192
0.79,-53.61,0.192
0.80,-53.49,0.192
0.82,-53.38,0.192
0.83,-53.26,0.193
0.84,-53.15,0.193
0.85,-53.03,0.193
0.86,-52.92,0.193
0.88,-52.80,0.193
0.89,-52.69,0.194
0.90,-52.57,0.194
0.91,-52.46,0.194
0.92,-52.34,0.194
0.93,-52.23,0.194
0.95,-52.11,0.194
0.96,-51.99,0.194
0.97,-51.88,0.194
0.98,-51.76,0.195
0.99,-51.65,0.195
1.00,-51.53,0.195
1.02,-51.42,0.195
1.03,-51.30,0.195
1.04,-51.19,0.195
1.05,-51.07,0.195
1.06,-50.95,0.195
1.07,-50.84,0.196
1.08,-50.72,0.196
1.10,-50.60,0.196
1.11,-50.49,0.196
1.12,-50.37,0.196
1.13,-50.26,0.196
1.14,-50.14,0.196
1.16,-50.03,0.196
1.17,-49.91,0.196
1.18,-49.79,0.196
1.19,-49.68,0.197
1.20,-49.56,0.197
1.21,-49.45,0.197
1.23,-49.33,0.197
1.24,-49.21,0.197
1.25,-49.10,0.197
1.26,-48.98,0.197
1.27,-48.86,0.197
1.28,-48.75,0.197
1.29,-48.63,0.197
1.31,-48.52,0.198
1.32,-48.40,0.198
1.33,-48.28,0.198
1.34,-48.17,0.198
1.35,-48.05,0.198
1.37,-47.93,0.198
1.38,-47.82,0.198
1.39,-47.70,0.198
1.40,-47.58,0.198
1.41,-47.47,0.198
1.42,-47.35,0.198
1.43,-47.23,0.198
1.45,-47.12,0.199
1.46,-47.00,0.199
1.47,-46.89,0.199
1.48,-46.77,0.199
1.49,-46.65,0.199
1.51,-46.54,0.199
1.52,-46.42,0.199
1.53,-46.30,0.199
1.54,-46.19,0.199
1.55,-46.07,0.199
1.56,-45.95,0.199
1.58,-45.84,0.199
1.59,-45.72,0.199
1.60,-45.60,0.199
1.61,-45.49,0.200
1.62,-45.37,0.200
1.63,-45.25,0.200
1.64,-45.14,0.200
1.66,-45.02,0.200
1.67,-44.90,0.200
1.68,-44.79,0.200
1.69,-44.67,0.200
1.70,-44.55,0.200
1.72,-44.44,0.200
1.73,-44.32,0.200
1.74,-44.20,0.200
1.75,-44.09,0.200
1.76,-43.97,0.201
1.77,-43.85,0.201
1.78,-43.74,0.201
1.80,-43.62,0.201
1.81,-43.50,0.201
1.82,-43.39,0.201
1.83,-43.27,0.201
1.84,-43.15,0.201
1.86,-43.04,0.201
1.87,-42.92,0.201
1.88,-42.80,0.201
1.89,-42.69,0.201
1.90,-42.57,0.201
1.91,-42.45,0.201
1.93,-42.34,0.202
1.94,-42.22,0.202
1.95,-42.10,0.202
1.96,-41.99,0.202
1.97,-41.87,0.202
1.98,-41.75,0.202
1.99,-41.64,0.202
2.01,-41.52,0.202
2.02,-41.40,0.202
2.03,-41.29,0.202
2.04,-41.17,0.202
2.05,-41.05,0.202
2.07,-40.94,0.202
2.08,-40.82,0.202
2.09,-40.70,0.202
2.10,-40.59,0.202
2.11,-40.47,0.202
2.12,-40.35,0.203
2.14,-40.24,0.203
2.15,-40.12,0.203
2.16,-40.00,0.203
2.17,-39.89,0.203
2.18,-39.77,0.203
2.19,-39.65,0.203
2.21,-39.54,0.203
2.22,-39.42,0.203
2.23,-39.30,0.203
2.24,-39.18,0.203
2.25,-39.07,0.203
2.26,-38.95,0.203
2.28,-38.83,0.203
2.29,-38.72,0.203
2.30,-38.60,0.203
2.31,-38.48,0.204
2.32,-38.37,0.204
2.33,-38.25,0.204
2.34,-38.13,0.204
2.36,-38.02,0.204
2.37,-37.90,0.204
2.38,-37.78,0.204
2.39,-37.67,0.204
2.40,-37.55,0.204
2.41,-37.43,0.204
2.43,-37.32,0.204
2.44,-37.20,0.204
2.45,-37.08,0.204
2.46,-36.96,0.204
2.47,-36.85,0.204
2.49,-36.73,0.204
2.50,-36.61,0.204
2.51,-36.50,0.205
2.52,-36.38,0.205
2.53,-36.27,0.205
2.54,-36.15,0.205
2.56,-36.03,0.205
2.57,-35.91,0.205
2.58,-35.80,0.205
2.59,-35.68,0.205
2.60,-35.56,0.205
2.61,-35.45,0.205
2.63,-35.33,0.205
2.64,-35.21,0.205
2.65,-35.10,0.205
2.66,-34.98,0.205
2.67,-34.86,0.205
2.68,-34.74,0.205
2.69,-34.63,0.205
2.71,-34.51,0.206
2.72,-34.39,0.206
2.73,-34.28,0.206
2.74,-34.16,0.206
2.75,-34.05,0.206
2.76,-33.93,0.206
2.78,-33.81,0.206
2.79,-33.69,0.206
2.80,-33.58,0.206
2.81,-33.46,0.206
2.82,-33.34,0.206
2.84,-33.23,0.206
2.85,-33.11,0.206
2.86,-32.99,0.207
2.87,-32.88,0.207
2.88,-32.76,0.207
2.89,-32.64,0.207
2.91,-32.53,0.207
2.92,-32.41,0.207
2.93,-32.29,0.207
2.94,-32.17,0.207
2.95,-32.06,0.207
2.96,-31.94,0.207
2.98,-31.83,0.207
2.99,-31.71,0.207
3.00,-31.59,0.207
3.01,-31.47,0.207
3.02,-31.36,0.207
3.03,-31.24,0.208
3.04,-31.12,0.208
3.06,-31.01,0.208
3.07,-30.89,0.208
3.08,-30.77,0.208
3.09,-30.66,0.208
3.10,-30.54,0.208
3.11,-30.42,0.208
3.13,-30.31,0.208
3.14,-30.19,0.208
3.15,-30.07,0.208
3.16,-29.96,0.208
3.17,-29.84,0.208
3.19,-29.72,0.208
3.20,-29.61,0.208
3.21,-29.49,0.208
3.22,-29.37,0.208
3.23,-29.25,0.209
3.24,-29.14,0.209
3.26,-29.02,0.209
3.27,-28.90,0.209
3.28,-28.79,0.209
3.29,-28.67,0.209
3.30,-28.55,0.209
3.31,-28.44,0.209
3.33,-28.32,0.209
3.34,-28.20,0.209
3.35,-28.09,0.209
3.36,-27.97,0.209
3.37,-27.85,0.209
3.38,-27.74,0.209
3.39,-27.62,0.209
3.41,-27.50,0.209
3.42,-27.39,0.210
3.43,-27.27,0.210
3.44,-27.15,0.210
3.45,-27.03,0.210
3.46,-26.92,0.210
3.48,-26.80,0.210
3.49,-26.68,0.210
3.50,-26.57,0.210
3.51,-26.45,0.210
3.52,-26.33,0.210
3.54,-26.22,0.210
3.55,-26.10,0.210
3.56,-25.98,0.210
3.57,-25.87,0.210
3.58,-25.75,0.211
3.59,-25.63,0.211
3.61,-25.52,0.211
3.62,-25.40,0.211
3.63,-25.28,0.211
3.64,-25.17,0.211
3.65,-25.05,0.211
3.66,-24.93,0.211
3.68,-24.81,0.211
3.69,-24.70,0.211
3.70,-24.58,0.211
3.71,-24.47,0.211
3.72,-24.35,0.211
3.73,-24.23,0.211
3.74,-24.11,0.211
3.76,-24.00,0.212
3.77,-23.88,0.212
3.78,-23.76,0.212
3.79,-23.65,0.212
3.80,-23.53,0.212
3.81,-23.41,0.212
3.83,-23.30,0.212
3.84,-23.18,0.212
3.85,-23.06,0.212
3.86,-22.95,0.212
3.87,-22.83,0.212
3.89,-22.71,0.212
3.90,-22.60,0.212
3.91,-22.48,0.213
3.92,-22.36,0.213
3.93,-22.25,0.213
3.94,-22.13,0.213
3.96,-22.01,0.213
3.97,-21.90,0.213
3.98,-21.78,0.213
3.99,-21.66,0.213
4.00,-21.54,0.213
4.01,-21.43,0.213
4.03,-21.31,0.213
4.04,-21.19,0.213
4.05,-21.08,0.213
4.06,-20.96,0.214
4.07,-20.84,0.214
4.08,-20.73,0.214
4.09,-20.61,0.214
4.11,-20.49,0.214
4.12,-20.38,0.214
4.13,-20.26,0.214
4.14,-20.14,0.214
4.15,-20.03,0.214
4.16,-19.91,0.214
4.18,-19.79,0.214
4.19,-19.68,0.214
4.20,-19.56,0.214
4.21,-19.44,0.214
4.22,-19.32,0.214
4.24,-19.21,0.214
4.25,-19.09,0.215
4.26,-18.97,0.215
4.27,-18.86,0.215
4.28,-18.74,0.215
4.29,-18.62,0.215
4.30,-18.51,0.215
4.32,-18.39,0.215
4.33,-18.27,0.215
4.34,-18.16,0.215
4.35,-18.04,0.215
4.36,-17.92,0.215
4.38,-17.81,0.215
4.39,-17.69,0.215
4.40,-17.57,0.215
4.41,-17.46,0.215
4.42,-17.34,0.216
4.43,-17.22,0.216
4.45,-17.11,0.216
4.46,-16.99,0.216
4.47,-16.87,0.216
4.48,-16.76,0.216
4.49,-16.64,0.216
4.50,-16.52,0.216
4.51,-16.41,0.216
4.53,-16.29,0.216
4.54,-16.17,0.216
4.55,-16.05,0.216
4.56,-15.94,0.216
4.57,-15.82,0.216
4.59,-15.70,0.216
4.60,-15.59,0.217
4.61,-15.47,0.217
4.62,-15.35,0.217
4.63,-15.24,0.217
4.64,-15.12,0.217
4.65,-15.00,0.217
4.67,-14.89,0.217
4.68,-14.77,0.217
4.69,-14.65,0.217
4.70,-14.54,0.217
4.71,-14.42,0.217
4.73,-14.30,0.217
4.74,-14.19,0.217
4.75,-14.07,0.217
4.76,-13.95,0.218
4.77,-13.84,0.218
4.78,-13.72,0.218
4.80,-13.60,0.218
4.81,-13.48,0.218
4.82,-13.37,0.218
4.83,-13.25,0.218
4.84,-13.13,0.218
4.85,-13.02,0.218
4.86,-12.90,0.218
4.88,-12.78,0.218
4.89,-12.67,0.218
4.90,-12.55,0.219
4.91,-12.43,0.219
4.92,-12.32,0.219
4.94,-12.20,0.219
4.95,-12.08,0.219
4.96,-11.97,0.219
4.97,-11.85,0.219
4.98,-11.73,0.219
4.99,-11.61,0.219
5.00,-11.50,0.219
5.02,-11.38,0.219
5.03,-11.27,0.219
5.04,-11.15,0.219
5.05,-11.03,0.219
5.06,-10.91,0.220
5.08,-10.80,0.220
5.09,-10.68,0.220
5.10,-10.56,0.220
5.11,-10.45,0.220
5.12,-10.33,0.220
5.13,-10.21,0.220
5.15,-10.10,0.220
5.16,-9.98,0.220
5.17,-9.86,0.220
5.18,-9.75,0.220
5.19,-9.63,0.220
5.20,-9.51,0.220
5.21,-9.40,0.221
5.23,-9.28,0.221
5.24,-9.16,0.221
5.25,-9.05,0.221
5.26,-8.93,0.221
5.27,-8.81,0.221
5.29,-8.70,0.221
5.30,-8.58,0.221
5.31,-8.46,0.221
5.32,-8.35,0.221
5.33,-8.23,0.221
5.34,-8.11,0.221
5.35,-8.00,0.222
5.37,-7.88,0.222
5.38,-7.76,0.222
5.39,-7.65,0.222
5.40,-7.53,0.222
5.41,-7.41,0.222
5.43,-7.29,0.222
5.44,-7.18,0.222
5.45,-7.06,0.222
5.46,-6.94,0.222
5.47,-6.83,0.222
5.48,-6.71,0.222
5.50,-6.59,0.222
5.51,-6.48,0.223
5.52,-6.36,0.223
5.53,-6.24,0.223
5.54,-6.13,0.223
5.55,-6.01,0.223
5.56,-5.89,0.223
5.58,-5.78,0.223
5.59,-5.66,0.223
5.60,-5.54,0.223
5.61,-5.43,0.223
5.62,-5.31,0.223
5.64,-5.19,0.223
5.65,-5.08,0.223
5.66,-4.96,0.224
5.67,-4.84,0.224
5.68,-4.73,0.224
5.69,-4.61,0.224
5.70,-4.49,0.224
5.72,-4.38,0.224
5.73,-4.26,0.224
5.74,-4.14,0.224
5.75,-4.03,0.224
5.76,-3.91,0.224
5.78,-3.79,0.225
5.79,-3.67,0.225
5.80,-3.56,0.225
5.81,-3.44,0.225
5.82,-3.32,0.225
5.83,-3.21,0.225
5.85,-3.09,0.225
5.86,-2.97,0.225
5.87,-2.86,0.225
5.88,-2.74,0.225
5.89,-2.62,0.225
5.90,-2.51,0.226
5.91,-2.39,0.226
5.93,-2.27,0.226
5.94,-2.15,0.226
5.95,-2.04,0.226
5.96,-1.92,0.226
5.97,-1.80,0.226
5.99,-1.69,0.226
6.00,-1.57,0.226
6.01,-1.45,0.226
6.02,-1.34,0.227
6.03,-1.22,0.227
6.04,-1.10,0.227
6.05,-0.99,0.227
6.07,-0.87,0.227
6.08,-0.75,0.227
6.09,-0.64,0.227
6.10,-0.52,0.227
6.11,-0.40,0.227
6.13,-0.29,0.227
6.14,-0.17,0.227
6.15,-0.05,0.228
6.16,0.07,0.228
6.17,0.18,0.228
6.18,0.30,0.228
6.20,0.41,0.228
6.21,0.53,0.228
6.22,0.65,0.228
6.23,0.76,0.228
6.24,0.88,0.228
6.25,1.00,0.228
6.26,1.12,0.228
6.28,1.23,0.228
6.29,1.35,0.229
6.30,1.47,0.229
6.31,1.58,0.229
6.32,1.70,0.229
6.34,1.82,0.229
6.35,1.93,0.229
6.36,2.05,0.229
6.37,2.17,0.229
6.38,2.28,0.229
6.39,2.40,0.229
6.40,2.52,0.229
6.42,2.63,0.230
6.43,2.75,0.230
6.44,2.87,0.230
6.45,2.98,0.230
6.46,3.10,0.230
6.48,3.22,0.230
6.49,3.34,0.230
6.50,3.45,0.230
6.51,3.57,0.230
6.52,3.69,0.230
6.53,3.80,0.230
6.55,3.92,0.230
6.56,4.04,0.231
6.57,4.15,0.231
6.58,4.27,0.231
6.59,4.39,0.231
6.60,4.50,0.231
6.61,4.62,0.231
6.63,4.74,0.231
6.64,4.85,0.231
6.65,4.97,0.231
6.66,5.09,0.231
6.67,5.20,0.231
6.69,5.32,0.232
6.70,5.44,0.232
6.71,5.55,0.232
6.72,5.67,0.232
6.73,5.79,0.232
6.74,5.90,0.232
6.75,6.02,0.232
6.77,6.14,0.232
6.78,6.26,0.232
6.79,6.37,0.232
6.80,6.49,0.233
6.81,6.61,0.233
6.83,6.72,0.233
6.84,6.84,0.233
6.85,6.96,0.233
6.86,7.07,0.233
6.87,7.19,0.233
6.88,7.31,0.233
6.90,7.42,0.233
6.91,7.54,0.233
6.92,7.66,0.234
6.93,7.77,0.234
6.94,7.89,0.234
6.95,8.01,0.234
6.96,8.12,0.234
6.98,8.24,0.234
6.99,8.36,0.234
7.00,8.47,0.234
7.01,8.59,0.234
7.02,8.71,0.234
7.04,8.82,0.234
7.05,8.94,0.235
7.06,9.06,0.235
7.07,9.18,0.235
7.08,9.29,0.235
7.09,9.41,0.235
7.10,9.53,0.235
7.12,9.64,0.235
7.13,9.76,0.235
7.14,9.88,0.235
7.15,9.99,0.235
7.16,10.11,0.236
7.18,10.22,0.236
7.19,10.34,0.236
7.20,10.46,0.236
7.21,10.58,0.236
7.22,10.69,0.236
7.23,10.81,0.236
7.25,10.92,0.237
7.26,11.04,0.237
7.27,11.16,0.237
7.28,11.28,0.237
7.29,11.39,0.237
7.30,11.51,0.237
7.31,11.63,0.237
7.33,11.74,0.237
7.34,11.86,0.237
7.35,11.98,0.237
7.36,12.09,0.237
7.37,12.21,0.238
7.39,12.33,0.238
7.40,12.44,0.238
7.41,12.56,0.238
7.42,12.68,0.238
7.43,12.80,0.238
7.44,12.91,0.238
7.45,13.03,0.238
7.47,13.15,0.239
7.48,13.26,0.239
7.49,13.38,0.239
7.50,13.49,0.239
7.51,13.61,0.239
7.53,13.73,0.239
7.54,13.85,0.239
7.55,13.96,0.239
7.56,14.08,0.239
7.57,14.20,0.239
7.58,14.31,0.239
7.60,14.43,0.240
7.61,14.55,0.240
7.62,14.66,0.240
7.63,14.78,0.240
7.64,14.90,0.240
7.65,15.01,0.240
7.66,15.13,0.240
7.68,15.25,0.240
7.69,15.37,0.240
7.70,15.48,0.241
7.71,15.60,0.241
7.72,15.71,0.241
7.74,15.83,0.241
7.75,15.95,0.241
7.76,16.06,0.241
7.77,16.18,0.241
7.78,16.30,0.241
7.79,16.42,0.241
7.80,16.53,0.241
7.82,16.65,0.242
7.83,16.77,0.242
7.84,16.88,0.242
7.85,17.00,0.242
7.86,17.12,0.242
7.88,17.23,0.242
7.89,17.35,0.242
7.90,17.47,0.242
7.91,17.58,0.242
7.92,17.70,0.242
7.93,17.82,0.243
7.95,17.93,0.243
7.96,18.05,0.243
7.97,18.17,0.243
7.98,18.28,0.243
7.99,18.40,0.243
8.00,18.52,0.243
8.01,18.63,0.243
8.03,18.75,0.244
8.04,18.87,0.244
8.05,18.98,0.244
8.06,19.10,0.244
8.07,19.22,0.244
8.09,19.33,0.244
8.10,19.45,0.244
8.11,19.57,0.244
8.12,19.69,0.244
8.13,19.80,0.244
8.14,19.92,0.244
8.15,20.04,0.245
8.17,20.15,0.245
8.18,20.27,0.245
8.19,20.39,0.245
8.20,20.50,0.245
8.21,20.62,0.245
8.23,20.74,0.245
8.24,20.85,0.245
8.25,20.97,0.245
8.26,21.09,0.246
8.27,21.20,0.246
8.28,21.32,0.246
8.30,21.44,0.246
8.31,21.55,0.246
8.32,21.67,0.246
8.33,21.79,0.246
8.34,21.90,0.246
8.35,22.02,0.246
8.36,22.14,0.246
8.38,22.25,0.247
8.39,22.37,0.247
8.40,22.49,0.247
8.41,22.60,0.247
8.42,22.72,0.247
8.44,22.84,0.247
8.45,22.96,0.247
8.46,23.07,0.247
8.47,23.19,0.247
8.48,23.31,0.247
8.49,23.42,0.248
8.50,23.54,0.248
8.52,23.66,0.248
8.53,23.77,0.248
8.54,23.89,0.248
8.55,24.01,0.248
8.56,24.12,0.248
8.58,24.24,0.248
8.59,24.36,0.248
8.60,24.47,0.248
8.61,24.59,0.249
8.62,24.71,0.249
8.63,24.82,0.249
8.65,24.94,0.249
8.66,25.06,0.249
8.67,25.17,0.249
8.68,25.29,0.249
8.69,25.41,0.249
8.70,25.52,0.249
8.72,25.64,0.249
8.73,25.76,0.250
8.74,25.87,0.250
8.75,25.99,0.250
8.76,26.11,0.250
8.77,26.22,0.250
8.78,26.34,0.250
8.80,26.46,0.250
8.81,26.57,0.250
8.82,26.69,0.250
8.83,26.81,0.251
8.84,26.92,0.251
8.85,27.04,0.251
8.87,27.16,0.251
8.88,27.27,0.251
8.89,27.39,0.251
8.90,27.51,0.251
8.91,27.63,0.251
8.93,27.74,0.251
8.94,27.86,0.252
8.95,27.98,0.252
8.96,28.09,0.252
8.97,28.21,0.252
8.98,28.33,0.252
9.00,28.44,0.252
9.01,28.56,0.252
9.02,28.68,0.252
9.03,28.79,0.252
9.04,28.91,0.252
9.05,29.03,0.253
9.07,29.14,0.253
9.08,29.26,0.253
9.09,29.38,0.253
9.10,29.49,0.253
9.11,29.61,0.253
9.12,29.73,0.253
9.13,29.84,0.253
9.15,29.96,0.253
9.16,30.08,0.254
9.17,30.19,0.254
9.18,30.31,0.254
9.19,30.43,0.254
9.20,30.55,0.254
9.22,30.66,0.254
9.23,30.78,0.254
9.24,30.89,0.254
9.25,31.01,0.254
9.26,31.13,0.255
9.28,31.25,0.255
9.29,31.36,0.255
9.30,31.48,0.255
9.31,31.60,0.255
9.32,31.71,0.255
9.33,31.83,0.255
9.35,31.95,0.255
9.36,32.06,0.255
9.37,32.18,0.255
9.38,32.30,0.256
9.39,32.41,0.256
9.40,32.53,0.256
9.42,32.65,0.256
9.43,32.76,0.256
9.44,32.88,0.256
9.45,33.00,0.256
9.46,33.11,0.256
9.47,33.23,0.256
9.48,33.35,0.257
9.50,33.46,0.257
9.51,33.58,0.257
9.52,33.70,0.257
9.53,33.81,0.257
9.54,33.93,0.257
9.55,34.05,0.257
9.57,34.16,0.257
9.58,34.28,0.257
9.59,34.40,0.258
9.60,34.51,0.258
9.61,34.63,0.258
9.63,34.75,0.258
9.64,34.87,0.258
9.65,34.98,0.258
9.66,35.10,0.258
9.67,35.22,0.258
9.68,35.33,0.258
9.70,35.45,0.259
9.71,35.57,0.259
9.72,35.68,0.259
9.73,35.80,0.259
9.74,35.92,0.259
9.75,36.03,0.259
9.77,36.15,0.259
9.78,36.27,0.259
9.79,36.38,0.259
9.80,36.50,0.260
9.81,36.62,0.260
9.82,36.73,0.260
9.83,36.85,0.260
9.85,36.97,0.260
9.86,37.09,0.260
9.87,37.20,0.260
9.88,37.32,0.260
9.89,37.43,0.260
9.90,37.55,0.260
9.92,37.67,0.261
9.93,37.79,0.261
9.94,37.90,0.261
9.95,38.02,0.261
9.96,38.14,0.261
9.98,38.25,0.261
9.99,38.37,0.261
10.00,38.49,0.261
10.01,38.60,0.261
10.02,38.72,0.262
10.03,38.84,0.262
10.05,38.95,0.262
10.06,39.07,0.262
10.07,39.19,0.262
10.08,39.30,0.262
10.09,39.42,0.262
10.10,39.54,0.262
10.12,39.66,0.262
10.13,39.77,0.263
10.14,39.89,0.263
10.15,40.00,0.263
10.16,40.12,0.263
10.17,40.24,0.263
10.18,40.35,0.263
10.20,40.47,0.263
10.21,40.59,0.263
10.22,40.70,0.264
10.23,40.82,0.264
10.24,40.94,0.264
10.25,41.06,0.264
10.27,41.17,0.264
10.28,41.29,0.264
10.29,41.41,0.264
10.30,41.52,0.264
10.31,41.64,0.264
10.33,41.76,0.265
10.34,41.87,0.265
10.35,41.99,0.265
10.36,42.11,0.265
10.37,42.22,0.265
10.38,42.34,0.265
10.40,42.46,0.265
10.41,42.58,0.265
10.42,42.69,0.266
10.43,42.81,0.266
10.44,42.93,0.266
10.45,43.04,0.266
10.47,43.16,0.266
10.48,43.27,0.266
10.49,43.39,0.266
10.50,43.51,0.266
10.51,43.63,0.266
10.52,43.74,0.266
10.53,43.86,0.267
10.55,43.98,0.267
10.56,44.09,0.267
10.57,44.21,0.267
10.58,44.32,0.267
10.59,44.44,0.267
10.60,44.56,0.267
10.62,44.67,0.267
10.63,44.79,0.267
10.64,44.91,0.268
10.65,45.03,0.268
10.66,45.14,0.268
10.68,45.26,0.268
10.69,45.38,0.268
10.70,45.49,0.268
10.71,45.61,0.268
10.72,45.73,0.268
10.73,45.84,0.268
10.75,45.96,0.269
10.76,46.08,0.269
10.77,46.19,0.269
10.78,46.31,0.269
10.79,46.43,0.269
10.80,46.54,0.269
10.82,46.66,0.269
10.83,46.78,0.269
10.84,46.89,0.270
10.85,47.01,0.270
10.86,47.13,0.270
10.87,47.25,0.270
10.88,47.36,0.270
10.90,47.48,0.270
10.91,47.59,0.270
10.92,47.71,0.270
10.93,47.83,0.270
10.94,47.95,0.271
10.95,48.06,0.271
10.97,48.18,0.271
10.98,48.29,0.271
10.99,48.41,0.271
11.00,48.53,0.271
11.01,48.65,0.271
11.03,48.76,0.271
11.04,48.88,0.272
11.05,49.00,0.272
11.06,49.11,0.272
11.07,49.23,0.272
11.08,49.35,0.272
11.10,49.46,0.272
11.11,49.58,0.272
11.12,49.70,0.273
11.13,49.81,0.273
11.14,49.93,0.273
11.15,50.05,0.273
11.17,50.16,0.273
11.18,50.28,0.273
11.19,50.40,0.273
11.20,50.52,0.273
11.21,50.63,0.273
11.22,50.75,0.273
11.23,50.87,0.274
11.25,50.98,0.274
11.26,51.10,0.274
11.27,51.22,0.274
11.28,51.33,0.274
11.29,51.45,0.274
11.30,51.57,0.274
11.32,51.68,0.274
11.33,51.80,0.274
11.34,51.92,0.275
11.35,52.03,0.275
11.36,52.15,0.275
11.38,52.27,0.275
11.39,52.38,0.275
11.40,52.50,0.275
11.41,52.62,0.275
11.42,52.73,0.275
11.43,52.85,0.275
11.45,52.97,0.276
11.46,53.08,0.276
11.47,53.20,0.276
11.48,53.32,0.276
11.49,53.43,0.276
11.50,53.55,0.276
11.52,53.67,0.276
11.53,53.78,0.276
11.54,53.90,0.276
11.55,54.02,0.277
11.56,54.13,0.277
11.57,54.25,0.277
11.58,54.37,0.277
11.60,54.48,0.277
11.61,54.60,0.277
11.62,54.72,0.277
11.63,54.84,0.277
11.64,54.95,0.277
11.65,55.07,0.278
11.67,55.19,0.278
11.68,55.30,0.278
11.69,55.42,0.278
11.70,55.54,0.278
11.71,55.65,0.278
11.73,55.77,0.278
11.74,55.89,0.278
11.75,56.00,0.279
11.76,56.12,0.279
11.77,56.24,0.279
11.78,56.35,0.279
11.80,56.47,0.279
11.81,56.59,0.279
11.82,56.70,0.279
11.83,56.82,0.279
11.84,56.94,0.279
11.85,57.05,0.280
11.87,57.17,0.280
11.88,57.29,0.280
11.89,57.40,0.280
11.90,57.52,0.280
11.91,57.64,0.280
11.92,57.75,0.280
11.93,57.87,0.280
11.95,57.99,0.280
11.96,58.11,0.281
11.97,58.22,0.281
11.98,58.34,0.281
11.99,58.46,0.281
12.00,58.57,0.281
12.02,58.69,0.281
12.03,58.81,0.281
12.04,58.92,0.281
12.05,59.04,0.282
12.06,59.16,0.282
12.08,59.27,0.282
12.09,59.39,0.282
12.10,59.50,0.282
12.11,59.62,0.282
12.12,59.74,0.282
12.13,59.86,0.282
12.15,59.97,0.282
12.16,60.09,0.283
12.17,60.21,0.283
12.18,60.32,0.283
12.19,60.44,0.283
12.20,60.56,0.283
12.22,60.67,0.283
12.23,60.79,0.283
12.24,60.91,0.283
12.25,61.02,0.284
12.26,61.14,0.284
12.27,61.26,0.284
12.28,61.38,0.284
12.30,61.49,0.284
12.31,61.61,0.284
12.32,61.72,0.284
12.33,61.84,0.284
12.34,61.96,0.284
12.35,62.07,0.285
12.37,62.19,0.285
12.38,62.31,0.285
12.39,62.42,0.285
12.40,62.54,0.285
12.41,62.66,0.285
12.43,62.77,0.285
12.44,62.89,0.285
12.45,63.01,0.286
12.46,63.13,0.286
12.47,63.24,0.286
12.48,63.36,0.286
12.50,63.48,0.286
12.51,63.59,0.286
12.52,63.71,0.286
12.53,63.82,0.287
12.54,63.94,0.287
12.55,64.06,0.287
12.57,64.18,0.287
12.58,64.29,0.287
12.59,64.41,0.287
12.60,64.53,0.287
12.61,64.64,0.288
12.62,64.76,0.288
12.63,64.88,0.288
12.65,64.99,0.288
12.66,65.11,0.288
12.67,65.23,0.288
12.68,65.34,0.288
12.69,65.46,0.288
12.70,65.58,0.289
12.72,65.69,0.289
12.73,65.81,0.289
12.74,65.93,0.289
12.75,66.04,0.289
12.76,66.16,0.289
12.78,66.28,0.289
12.79,66.39,0.289
12.80,66.51,0.290
12.81,66.63,0.290
12.82,66.74,0.290
12.83,66.86,0.290
12.85,66.98,0.290
12.86,67.10,0.290
12.87,67.21,0.290
12.88,67.33,0.291
12.89,67.45,0.291
12.90,67.56,0.291
12.92,67.68,0.291
12.93,67.80,0.291
12.94,67.91,0.291
12.95,68.03,0.292
12.96,68.15,0.292
12.97,68.26,0.292
12.98,68.38,0.292
13.00,68.50,0.292
13.01,68.61,0.292
13.02,68.73,0.292
13.03,68.85,0.293
13.04,68.96,0.293
13.05,69.08,0.293
13.07,69.20,0.293
13.08,69.31,0.293
13.09,69.43,0.293
13.10,69.55,0.294
13.11,69.66,0.294
13.13,69.78,0.294
13.14,69.90,0.294
13.15,70.01,0.294
13.16,70.13,0.295
13.17,70.25,0.295
13.18,70.36,0.295
13.20,70.48,0.295
13.21,70.60,0.296
13.22,70.71,0.296
13.23,70.83,0.296
13.24,70.95,0.297
13.25,71.06,0.297
13.27,71.18,0.298
13.28,71.30,0.298
13.29,71.41,0.298
13.30,71.53,0.299
13.31,71.65,0.299
13.32,71.76,0.300
13.33,71.88,0.301
13.35,72.00,0.302
13.36,72.11,0.303
13.37,72.23,0.304
13.38,72.35,0.306
13.39,72.46,0.308
13.40,72.58,0.310
13.42,72.69,0.313
13.43,72.81,0.316
13.44,72.93,0.320
13.45,73.04,0.324
13.46,73.16,0.330
13.48,73.27,0.336
13.49,73.38,0.345
13.50,73.50,0.358
13.51,73.61,0.376
13.52,73.72,0.401
13.53,73.83,0.439
13.55,73.94,0.491
13.56,74.04,0.562
13.57,74.13,0.650
13.58,74.22,0.753
13.59,74.30,0.863
13.60,74.38,0.978
13.62,74.45,1.095
13.63,74.52,1.218
13.64,74.59,1.339
13.65,74.65,1.467
13.66,74.71,1.592
13.67,74.76,1.718
13.68,74.82,1.843
13.70,74.87,1.968
13.71,74.92,2.094
13.72,74.98,2.219
13.73,75.03,2.344
13.74,75.08,2.475
13.75,75.13,2.618
13.77,75.17,2.758
13.78,75.21,2.900
13.79,75.26,3.043
13.80,75.30,3.196
13.81,75.34,3.356
13.83,75.38,3.509
13.84,75.41,3.641
13.85,75.45,3.769
13.86,75.49,3.900
13.87,75.54,4.053
13.88,75.57,4.215
13.90,75.61,4.355
13.91,75.65,4.468
13.92,75.69,4.556
13.93,75.74,4.629
13.94,75.80,4.656
13.95,75.87,4.652
13.97,75.95,4.665
13.98,76.03,4.711
13.99,76.11,4.792
14.00,76.19,4.836
14.01,76.28,4.836
14.02,76.37,4.818
14.03,76.47,4.787
14.05,76.58,4.755
14.06,76.69,4.715
14.07,76.81,4.643
14.08,76.94,4.523
14.09,77.09,4.333
14.10,77.25,4.097
14.12,77.43,3.856
14.13,77.62,3.630
14.14,77.82,3.421
14.15,78.03,3.219
14.16,78.24,3.007
14.18,78.46,2.778
14.19,78.68,2.539
14.20,78.90,2.298
14.21,79.13,2.068
14.22,79.37,1.855
14.23,79.60,1.663
14.25,79.82,1.492
14.26,80.05,1.347
14.27,80.26,1.227
14.28,80.47,1.131
14.29,80.67,1.048
14.30,80.86,0.976
14.32,81.05,0.912
14.33,81.23,0.856
14.34,81.40,0.806
14.35,81.57,0.759
14.36,81.73,0.719
14.37,81.89,0.682
14.38,82.04,0.650
14.40,82.19,0.618
14.41,82.34,0.595
14.42,82.48,0.567
14.43,82.62,0.544
14.44,82.76,0.530
14.45,82.89,0.509
14.47,83.03,0.491
14.48,83.16,0.479
14.49,83.29,0.465
14.50,83.42,0.453
14.51,83.55,0.444
14.53,83.68,0.434
14.54,83.80,0.426
14.55,83.93,0.418
14.56,84.05,0.412
14.57,84.18,0.405
14.58,84.30,0.400
14.60,84.42,0.395
14.61,84.54,0.390
14.62,84.66,0.387
14.63,84.79,0.383
14.64,84.91,0.380
14.65,85.03,0.376
14.67,85.15,0.374
14.68,85.27,0.371
14.69,85.39,0.369
14.70,85.50,0.367
14.71,85.62,0.366
14.72,85.74,0.365
14.73,85.86,0.363
14.75,85.98,0.362
14.76,86.10,0.361
14.77,86.22,0.360
14.78,86.33,0.359
14.79,86.45,0.358
14.80,86.57,0.358
14.82,86.69,0.356
14.83,86.80,0.351
14.84,86.92,0.351
14.85,87.04,0.351
14.86,87.16,0.352
14.88,87.27,0.352
14.89,87.39,0.352
14.90,87.51,0.352
14.91,87.62,0.352
14.92,87.74,0.352
14.93,87.86,0.352
14.95,87.98,0.352
14.96,88.09,0.352
14.97,88.21,0.352
14.98,88.33,0.352
14.99,88.44,0.352
15.00,88.56,0.352
15.02,88.68,0.352
15.03,88.79,0.352
15.04,88.91,0.352
15.05,89.03,0.352
15.06,89.14,0.352
15.07,89.26,0.352
15.08,89.38,0.352
15.10,89.49,0.352
15.11,89.61,0.352
15.12,89.73,0.352
15.13,89.84,0.352
15.14,89.96,0.352
15.15,90.08,0.352
15.17,90.19,0.352
15.18,90.31,0.352
15.19,90.43,0.352
15.20,90.54,0.352
15.21,90.66,0.352
15.23,90.78,0.352
15.24,90.89,0.352
15.25,91.01,0.352
15.26,91.13,0.352
15.27,91.25,0.353
15.28,91.36,0.353
15.30,91.48,0.353
15.31,91.60,0.353
15.32,91.71,0.353
15.33,91.83,0.353
15.34,91.94,0.353
15.35,92.06,0.353
15.37,92.18,0.353
15.38,92.29,0.353
15.39,92.41,0.353
15.40,92.53,0.353
15.41,92.64,0.353
15.42,92.76,0.353
15.43,92.88,0.353
15.45,92.99,0.353
15.46,93.11,0.354
15.47,93.23,0.354
15.48,93.35,0.354
15.49,93.46,0.354
15.50,93.58,0.354
15.52,93.70,0.354
15.53,93.81,0.354
15.54,93.93,0.354
15.55,94.05,0.354
15.56,94.16,0.354
15.58,94.28,0.354
15.59,94.40,0.354
15.60,94.51,0.355
15.61,94.63,0.355
15.62,94.75,0.355
15.63,94.86,0.355
15.65,94.98,0.355
15.66,95.10,0.355
15.67,95.21,0.355
15.68,95.33,0.355
15.69,95.45,0.355
15.70,95.56,0.355
15.72,95.68,0.356
15.73,95.80,0.356
15.74,95.91,0.356
15.75,96.03,0.356
15.76,96.15,0.356
15.77,96.26,0.356
15.78,96.38,0.356
15.80,96.50,0.356
15.81,96.61,0.356
15.82,96.73,0.356
15.83,96.85,0.357
15.84,96.96,0.357
15.85,97.08,0.357
15.87,97.20,0.357
15.88,97.32,0.357
15.89,97.43,0.357
15.90,97.55,0.357
15.91,97.67,0.357
15.93,97.78,0.357
15.94,97.90,
15.95,98.02,
15.96,98.13,
15.97,98.25,
15.98,98.37,
15.99,,

[step]
Ramp 10.00 °C/min to -60.00 °C
Time,Temperature,Heat Flow (Normalized)
min,°C,W/g
17.99,100.12,-0.027
18.01,100.12,-0.027
18.02,100.12,-0.027
18.03,100.12,-0.027
18.04,100.11,-0.027
18.05,100.10,-0.030
18.06,100.09,-0.039
18.08,100.06,-0.049
18.09,100.03,-0.063
18.10,99.99,-0.080
18.11,99.94,-0.100
18.12,99.89,-0.121
18.13,99.82,-0.146
18.14,99.75,-0.167
18.16,99.68,-0.189
18.17,99.60,-0.210
18.18,99.52,-0.229
18.19,99.44,-0.245
18.20,99.35,-0.260
18.22,99.26,-0.274
18.23,99.17,-0.286
18.24,99.07,-0.296
18.25,98.97,-0.307
18.26,98.88,-0.317
18.27,98.78,-0.324
18.28,98.68,-0.334
18.30,98.57,-0.340
18.31,98.47,-0.347
18.32,98.37,-0.353
18.33,98.26,-0.358
18.34,98.15,-0.364
18.36,98.04,-0.368
18.37,97.93,-0.371
18.38,97.83,-0.375
18.39,97.72,-0.379
18.40,97.61,-0.381
18.41,97.50,-0.384
18.43,97.39,-0.386
18.44,97.27,-0.388
18.45,97.16,-0.390
18.46,97.05,-0.392
18.47,96.94,-0.394
18.48,96.82,-0.394
18.49,96.71,-0.396
18.51,96.60,-0.398
18.52,96.49,-0.399
18.53,96.37,-0.399
18.54,96.26,-0.400
18.55,96.14,-0.400
18.57,96.03,-0.401
18.58,95.92,-0.401
18.59,95.80,-0.402
18.60,95.69,-0.403
18.61,95.57,-0.403
18.62,95.46,-0.403
18.63,95.34,-0.403
18.65,95.23,-0.403
18.66,95.11,-0.403
18.67,95.00,-0.404
18.68,94.88,-0.404
18.69,94.77,-0.404
18.71,94.65,-0.404
18.72,94.54,-0.404
18.73,94.42,-0.404
18.74,94.31,-0.405
18.75,94.19,-0.405
18.76,94.07,-0.405
18.78,93.96,-0.405
18.79,93.84,-0.405
18.80,93.73,-0.405
18.81,93.61,-0.405
18.82,93.49,-0.405
18.83,93.38,-0.406
18.84,93.26,-0.406
18.86,93.15,-0.406
18.87,93.03,-0.406
18.88,92.92,-0.406
18.89,92.80,-0.406
18.90,92.68,-0.406
18.92,92.57,-0.406
18.93,92.45,-0.406
18.94,92.34,-0.406
18.95,92.22,-0.406
18.96,92.11,-0.406
18.97,91.99,-0.406
18.98,91.87,-0.406
19.00,91.76,-0.406
19.01,91.64,-0.406
19.02,91.52,-0.406
19.03,91.41,-0.406
19.04,91.29,-0.406
19.06,91.17,-0.406
19.07,91.06,-0.406
19.08,90.94,-0.406
19.09,90.83,-0.406
19.10,90.71,-0.406
19.11,90.59,-0.406
19.13,90.48,-0.406
19.14,90.36,-0.406
19.15,90.25,-0.406
19.16,90.13,-0.406
19.17,90.01,-0.406
19.18,89.90,-0.406
19.19,89.78,-0.406
19.21,89.66,-0.406
19.22,89.55,-0.406
19.23,89.43,-0.406
19.24,89.31,-0.406
19.25,89.20,-0.406
19.27,89.08,-0.406
19.28,88.97,-0.406
19.29,88.85,-0.406
19.30,88.73,-0.405
19.31,88.62,-0.405
19.32,88.50,-0.405
19.33,88.38,-0.405
19.35,88.27,-0.405
19.36,88.15,-0.405
19.37,88.04,-0.405
19.38,87.92,-0.405
19.39,87.80,-0.405
19.41,87.69,-0.404
19.42,87.57,-0.404
19.43,87.45,-0.404
19.44,87.34,-0.404
19.45,87.22,-0.404
19.46,87.10,-0.404
19.48,86.99,-0.404
19.49,86.87,-0.404
19.50,86.75,-0.404
19.51,86.64,-0.404
19.52,86.52,-0.404
19.53,86.40,-0.404
19.54,86.29,-0.403
19.56,86.17,-0.403
19.57,86.06,-0.403
19.58,85.94,-0.403
19.59,85.82,-0.403
19.60,85.71,-0.403
19.62,85.59,-0.403
19.63,85.47,-0.403
19.64,85.36,-0.403
19.65,85.24,-0.402
19.66,85.12,-0.402
19.67,85.01,-0.402
19.68,84.89,-0.402
19.70,84.78,-0.402
19.71,84.66,-0.402
19.72,84.54,-0.402
19.73,84.43,-0.402
19.74,84.31,-0.401
19.76,84.19,-0.401
19.77,84.08,-0.401
19.78,83.96,-0.401
19.79,83.84,-0.401
19.80,83.73,-0.401
19.81,83.61,-0.401
19.83,83.49,-0.401
19.84,83.38,-0.401
19.85,83.26,-0.401
19.86,83.14,-0.401
19.87,83.03,-0.400
19.88,82.91,-0.400
19.89,82.79,-0.400
19.91,82.68,-0.400
19.92,82.56,-0.400
19.93,82.45,-0.400
19.94,82.33,-0.400
19.95,82.21,-0.400
19.97,82.10,-0.400
19.98,81.98,-0.400
19.99,81.86,-0.400
20.00,81.75,-0.400
20.01,81.63,-0.399
20.02,81.51,-0.399
20.03,81.40,-0.399
20.05,81.28,-0.399
20.06,81.16,-0.399
20.07,81.05,-0.399
20.08,80.93,-0.399
20.09,80.81,-0.399
20.11,80.70,-0.399
20.12,80.58,-0.399
20.13,80.46,-0.399
20.14,80.35,-0.399
20.15,80.23,-0.398
20.16,80.11,-0.398
20.18,80.00,-0.398
20.19,79.88,-0.398
20.20,79.76,-0.398
20.21,79.65,-0.398
20.22,79.53,-0.398
20.23,79.41,-0.398
20.24,79.30,-0.398
20.26,79.18,-0.397
20.27,79.07,-0.397
20.28,78.95,-0.397
20.29,78.83,-0.397
20.30,78.72,-0.397
20.32,78.60,-0.397
20.33,78.48,-0.397
20.34,78.37,-0.397
20.35,78.25,-0.397
20.36,78.13,-0.396
20.37,78.02,-0.396
20.38,77.90,-0.396
20.40,77.78,-0.396
20.41,77.67,-0.396
20.42,77.55,-0.396
20.43,77.43,-0.396
20.44,77.32,-0.396
20.46,77.20,-0.396
20.47,77.08,-0.395
20.48,76.97,-0.395
20.49,76.85,-0.395
20.50,76.73,-0.395
20.51,76.62,-0.395
20.53,76.50,-0.395
20.54,76.38,-0.395
20.55,76.27,-0.395
20.56,76.15,-0.394
20.57,76.04,-0.394
20.58,75.92,-0.394
20.59,75.80,-0.394
20.61,75.69,-0.394
20.62,75.57,-0.394
20.63,75.45,-0.394
20.64,75.34,-0.394
20.65,75.22,-0.393
20.67,75.10,-0.393
20.68,74.99,-0.393
20.69,74.87,-0.393
20.70,74.75,-0.393
20.71,74.64,-0.393
20.72,74.52,-0.393
20.73,74.40,-0.393
20.75,74.29,-0.392
20.76,74.17,-0.392
20.77,74.06,-0.392
20.78,73.94,-0.392
20.79,73.82,-0.392
20.81,73.71,-0.392
20.82,73.59,-0.392
20.83,73.47,-0.392
20.84,73.35,-0.391
20.85,73.24,-0.391
20.86,73.12,-0.391
20.88,73.01,-0.391
20.89,72.89,-0.391
20.90,72.77,-0.391
20.91,72.66,-0.391
20.92,72.54,-0.391
20.93,72.42,-0.391
20.94,72.31,-0.390
20.96,72.19,-0.390
20.97,72.07,-0.390
20.98,71.96,-0.390
20.99,71.84,-0.390
21.00,71.72,-0.390
21.02,71.61,-0.390
21.03,71.49,-0.390
21.04,71.37,-0.389
21.05,71.26,-0.389
21.06,71.14,-0.389
21.07,71.02,-0.389
21.08,70.91,-0.389
21.10,70.79,-0.389
21.11,70.67,-0.389
21.12,70.56,-0.389
21.13,70.44,-0.389
21.14,70.32,-0.388
21.16,70.21,-0.388
21.17,70.09,-0.388
21.18,69.97,-0.388
21.19,69.86,-0.388
21.20,69.74,-0.388
21.21,69.62,-0.388
21.23,69.51,-0.387
21.24,69.39,-0.387
21.25,69.27,-0.387
21.26,69.16,-0.387
21.27,69.04,-0.387
21.28,68.93,-0.387
21.29,68.81,-0.387
21.31,68.69,-0.387
21.32,68.58,-0.387
21.33,68.46,-0.386
21.34,68.34,-0.386
21.35,68.23,-0.386
21.37,68.11,-0.386
21.38,67.99,-0.386
21.39,67.88,-0.386
21.40,67.76,-0.386
21.41,67.64,-0.386
21.42,67.53,-0.385
21.43,67.41,-0.385
21.45,67.29,-0.385
21.46,67.18,-0.385
21.47,67.06,-0.385
21.48,66.94,-0.385
21.49,66.83,-0.385
21.51,66.71,-0.385
21.52,66.59,-0.385
21.53,66.48,-0.384
21.54,66.36,-0.384
21.55,66.24,-0.384
21.56,66.13,-0.384
21.58,66.01,-0.384
21.59,65.89,-0.384
21.60,65.78,-0.384
21.61,65.66,-0.384
21.62,65.54,-0.384
21.63,65.43,-0.383
21.64,65.31,-0.383
21.66,65.19,-0.383
21.67,65.08,-0.383
21.68,64.96,-0.383
21.69,64.84,-0.383
21.70,64.73,-0.383
21.72,64.61,-0.383
21.73,64.49,-0.383
21.74,64.38,-0.383
21.75,64.26,-0.382
21.76,64.14,-0.382
21.77,64.03,-0.382
21.78,63.91,-0.382
21.80,63.79,-0.382
21.81,63.68,-0.382
21.82,63.56,-0.382
21.83,63.44,-0.382
21.84,63.33,-0.381
21.86,63.21,-0.381
21.87,63.10,-0.381
21.88,62.98,-0.381
21.89,62.86,-0.381
21.90,62.75,-0.381
21.91,62.63,-0.381
21.93,62.51,-0.380
21.94,62.40,-0.380
21.95,62.28,-0.380
21.96,62.16,-0.380
21.97,62.05,-0.380
21.98,61.93,-0.380
21.99,61.81,-0.380
22.01,61.70,-0.380
22.02,61.58,-0.380
22.03,61.47,-0.380
22.04,61.35,-0.379
22.05,61.23,-0.379
22.07,61.11,-0.379
22.08,61.00,-0.379
22.09,60.88,-0.379
22.10,60.77,-0.379
22.11,60.65,-0.379
22.12,60.53,-0.379
22.13,60.42,-0.378
22.15,60.30,-0.378
22.16,60.18,-0.378
22.17,60.07,-0.378
22.18,59.95,-0.378
22.19,59.83,-0.378
22.21,59.72,-0.378
22.22,59.60,-0.378
22.23,59.48,-0.378
22.24,59.37,-0.378
22.25,59.25,-0.377
22.26,59.13,-0.377
22.28,59.02,-0.377
22.29,58.90,-0.377
22.30,58.78,-0.377
22.31,58.67,-0.377
22.32,58.55,-0.377
22.33,58.43,-0.376
22.34,58.32,-0.376
22.36,58.20,-0.376
22.37,58.08,-0.376
22.38,57.97,-0.376
22.39,57.85,-0.376
22.40,57.73,-0.376
22.42,57.62,-0.376
22.43,57.50,-0.376
22.44,57.39,-0.376
22.45,57.27,-0.375
22.46,57.15,-0.375
22.47,57.04,-0.375
22.48,56.92,-0.375
22.50,56.80,-0.375
22.51,56.69,-0.375
22.52,56.57,-0.375
22.53,56.45,-0.374
22.54,56.34,-0.374
22.56,56.22,-0.374
22.57,56.10,-0.374
22.58,55.99,-0.374
22.59,55.87,-0.374
22.60,55.75,-0.374
22.61,55.64,-0.374
22.63,55.52,-0.373
22.64,55.40,-0.373
22.65,55.29,-0.373
22.66,55.17,-0.373
22.67,55.06,-0.373
22.68,54.94,-0.373
22.69,54.82,-0.373
22.71,54.70,-0.373
22.72,54.59,-0.373
22.73,54.47,-0.373
22.74,54.36,-0.372
22.75,54.24,-0.372
22.77,54.12,-0.372
22.78,54.00,-0.372
22.79,53.89,-0.372
22.80,53.77,-0.372
22.81,53.66,-0.372
22.82,53.54,-0.372
22.83,53.42,-0.371
22.85,53.31,-0.371
22.86,53.19,-0.371
22.87,53.07,-0.371
22.88,52.96,-0.371
22.89,52.84,-0.371
22.91,52.72,-0.371
22.92,52.61,-0.371
22.93,52.49,-0.371
22.94,52.37,-0.370
22.95,52.26,-0.370
22.96,52.14,-0.370
22.98,52.02,-0.370
22.99,51.91,-0.370
23.00,51.79,-0.370
23.01,51.67,-0.370
23.02,51.56,-0.370
23.03,51.44,-0.370
23.04,51.32,-0.370
23.06,51.21,-0.369
23.07,51.09,-0.369
23.08,50.98,-0.369
23.09,50.86,-0.369
23.10,50.74,-0.369
23.12,50.62,-0.369
23.13,50.51,-0.369
23.14,50.39,-0.369
23.15,50.28,-0.369
23.16,50.16,-0.369
23.17,50.04,-0.368
23.18,49.93,-0.368
23.20,49.81,-0.368
23.21,49.69,-0.368
23.22,49.58,-0.368
23.23,49.46,-0.368
[...]
110.08,-40.94,0.287
110.09,-40.87,0.287
110.09,-40.80,0.287
110.10,-40.74,0.286
110.11,-40.67,0.286
110.11,-40.60,0.285
110.12,-40.53,0.285
110.13,-40.47,0.284
110.13,-40.40,0.284
110.14,-40.33,0.284
110.15,-40.27,0.283
110.15,-40.20,0.283
110.16,-40.13,0.283
110.17,-40.06,0.282
110.17,-40.00,0.282
110.18,-39.93,0.282
110.19,-39.86,0.282
110.19,-39.80,0.282
110.20,-39.73,0.282
110.21,-39.66,0.281
110.21,-39.59,0.281
110.22,-39.53,0.281
110.23,-39.46,0.281
110.23,-39.39,0.281
110.24,-39.33,0.281
110.25,-39.26,0.280
110.25,-39.19,0.280
110.26,-39.13,0.280
110.27,-39.06,0.280
110.27,-38.99,0.280
110.28,-38.93,0.280
110.29,-38.86,0.280
110.29,-38.79,0.280
110.30,-38.72,0.280
110.31,-38.66,0.280
110.31,-38.59,0.279
110.32,-38.52,0.279
110.33,-38.46,0.279
110.33,-38.39,0.279
110.34,-38.32,0.279
110.35,-38.26,0.279
110.35,-38.19,0.279
110.36,-38.12,0.279
110.37,-38.05,0.279
110.37,-37.99,0.279
110.38,-37.92,0.279
110.39,-37.86,0.278
110.39,-37.79,0.278
110.40,-37.72,0.278
110.41,-37.65,0.278
110.41,-37.59,0.278
110.42,-37.52,0.278
110.43,-37.45,0.278
110.43,-37.39,0.278
110.44,-37.32,0.278
110.45,-37.25,0.278
110.45,-37.19,0.278
110.46,-37.12,0.278
110.47,-37.05,0.278
110.47,-36.99,0.278
110.48,-36.92,0.278
110.49,-36.85,0.278
110.49,-36.79,0.278
110.50,-36.72,0.277
110.51,-36.65,0.277
110.51,-36.58,0.277
110.52,-36.52,0.277
110.53,-36.45,0.277
110.53,-36.38,0.277
110.54,-36.32,0.277
110.55,-36.25,0.277
110.55,-36.18,0.277
110.56,-36.12,0.277
110.57,-36.05,0.277
110.57,-35.98,0.277
110.58,-35.92,0.277
110.59,-35.85,0.277
110.59,-35.78,0.277
110.60,-35.72,0.277
110.61,-35.65,0.277
110.61,-35.58,0.277
110.62,-35.52,0.277
110.63,-35.45,0.277
110.63,-35.38,0.277
110.64,-35.32,0.277
110.65,-35.25,0.277
110.65,-35.18,0.276
110.66,-35.12,0.277
110.67,-35.05,0.277
110.67,-34.98,0.276
110.68,-34.91,0.276
110.69,-34.85,0.276
110.69,-34.78,0.276
110.70,-34.71,0.276
110.71,-34.65,0.276
110.71,-34.58,0.276
110.72,-34.51,0.276
110.73,-34.45,0.276
110.73,-34.38,0.276
110.74,-34.31,0.276
110.75,-34.25,0.276
110.75,-34.18,0.276
110.76,-34.11,0.276
110.77,-34.05,0.276
110.77,-33.98,0.276
110.78,-33.91,0.276
110.79,-33.85,0.276
110.79,-33.78,0.276
110.80,-33.71,0.276
110.81,-33.64,0.276
110.81,-33.58,0.276
110.82,-33.51,0.276
110.83,-33.45,0.276
110.83,-33.38,0.276
110.84,-33.31,0.276
110.85,-33.25,0.276
110.85,-33.18,0.276
110.86,-33.11,0.276
110.87,-33.04,0.276
110.87,-32.98,0.276
110.88,-32.91,0.276
110.89,-32.84,0.276
110.89,-32.78,0.276
110.90,-32.71,0.276
110.91,-32.64,0.276
110.91,-32.58,0.276
110.92,-32.51,0.276
110.93,-32.44,0.276
110.93,-32.37,0.276
110.94,-32.31,0.276
110.95,-32.24,0.276
110.95,-32.18,0.276
110.96,-32.11,0.276
110.97,-32.04,0.276
110.97,-31.98,0.276
110.98,-31.91,0.276
110.99,-31.84,0.276
110.99,-31.77,0.276
111.00,-31.71,0.276
111.01,-31.64,0.276
111.01,-31.58,0.276
111.02,-31.51,0.276
111.03,-31.44,0.276
111.03,-31.37,0.276
111.04,-31.31,0.276
111.05,-31.24,0.276
111.05,-31.17,0.276
111.06,-31.11,0.276
111.07,-31.04,0.276
111.07,-30.97,0.276
111.08,-30.91,0.276
111.09,-30.84,0.276
111.09,-30.77,0.276
111.10,-30.71,0.276
111.11,-30.64,0.276
111.11,-30.57,0.276
111.12,-30.51,0.276
111.13,-30.44,0.276
111.13,-30.37,0.276
111.14,-30.31,0.276
111.15,-30.24,0.276
111.15,-30.17,0.276
111.16,-30.11,0.276
111.17,-30.04,0.276
111.17,-29.97,0.276
111.18,-29.91,0.276
111.19,-29.84,0.276
111.19,-29.77,0.277
111.20,-29.71,0.277
111.21,-29.64,0.277
111.21,-29.57,0.277
111.22,-29.51,0.277
111.23,-29.44,0.277
111.23,-29.37,0.277
111.24,-29.31,0.277
111.25,-29.24,0.277
111.25,-29.17,0.277
111.26,-29.10,0.277
111.27,-29.04,0.277
111.27,-28.97,0.277
111.28,-28.91,0.277
111.29,-28.84,0.277
111.29,-28.77,0.277
111.30,-28.70,0.277
111.31,-28.64,0.277
111.31,-28.57,0.277
111.32,-28.50,0.277
111.33,-28.44,0.277
111.33,-28.37,0.277
111.34,-28.30,0.277
111.35,-28.24,0.277
111.35,-28.17,0.277
111.36,-28.10,0.277
111.37,-28.04,0.277
111.37,-27.97,0.277
111.38,-27.90,0.277
111.39,-27.84,0.277
111.39,-27.77,0.277
111.40,-27.70,0.277
111.41,-27.64,0.277
111.41,-27.57,0.277
111.42,-27.50,0.277
111.43,-27.43,0.277
111.43,-27.37,0.277
111.44,-27.30,0.277
111.45,-27.24,0.277
111.45,-27.17,0.277
111.46,-27.10,0.277
111.47,-27.04,0.277
111.47,-26.97,0.277
111.48,-26.90,0.277
111.49,-26.83,0.277
111.49,-26.77,0.277
111.50,-26.70,0.277
111.51,-26.63,0.277
111.51,-26.57,0.277
111.52,-26.50,0.278
111.53,-26.43,0.278
111.53,-26.37,0.278
111.54,-26.30,0.278
111.55,-26.23,0.278
111.55,-26.17,0.278
111.56,-26.10,0.278
111.57,-26.03,0.278
111.57,-25.97,0.278
111.58,-25.90,0.278
111.59,-25.83,0.278
111.59,-25.77,0.278
111.60,-25.70,0.278
111.61,-25.63,0.278
111.61,-25.57,0.278
111.62,-25.50,0.278
111.63,-25.43,0.278
111.63,-25.36,0.278
111.64,-25.30,0.278
111.65,-25.23,0.278
111.65,-25.16,0.278
111.66,-25.10,0.278
111.67,-25.03,0.278
111.67,-24.96,0.278
111.68,-24.90,0.278
111.69,-24.83,0.278
111.69,-24.76,0.278
111.70,-24.70,0.278
111.71,-24.63,0.278
111.71,-24.56,0.278
111.72,-24.50,0.278
111.73,-24.43,0.278
111.73,-24.36,0.278
111.74,-24.30,0.278
111.75,-24.23,0.278
111.75,-24.16,0.278
111.76,-24.09,0.278
111.77,-24.03,0.278
111.77,-23.96,0.278
111.78,-23.90,0.278
111.79,-23.83,0.278
111.79,-23.76,0.278
111.80,-23.69,0.278
111.81,-23.63,0.278
111.81,-23.56,0.278
111.82,-23.50,0.278
111.83,-23.43,0.279
111.83,-23.36,0.279
111.84,-23.29,0.279
111.85,-23.23,0.279
111.85,-23.16,0.279
111.86,-23.09,0.279
111.87,-23.03,0.279
111.87,-22.96,0.279
111.88,-22.89,0.279
111.89,-22.83,0.279
111.89,-22.76,0.279
111.90,-22.69,0.279
111.91,-22.63,0.279
111.91,-22.56,0.279
111.92,-22.49,0.279
111.93,-22.43,0.279
111.93,-22.36,0.279
111.94,-22.29,0.279
111.95,-22.23,0.279
111.95,-22.16,0.279
111.96,-22.09,0.279
111.97,-22.03,0.279
111.97,-21.96,0.279
111.98,-21.89,0.279
111.99,-21.83,0.279
111.99,-21.76,0.279
112.00,-21.69,0.279
112.01,-21.63,0.279
112.01,-21.56,0.279
112.02,-21.49,0.279
112.03,-21.42,0.279
112.03,-21.36,0.279
112.04,-21.29,0.279
112.05,-21.23,0.279
112.05,-21.16,0.279
112.06,-21.09,0.279
112.07,-21.03,0.279
112.07,-20.96,0.279
112.08,-20.89,0.279
112.09,-20.82,0.279
112.09,-20.76,0.279
112.10,-20.69,0.279
112.11,-20.63,0.279
112.11,-20.56,0.279
112.12,-20.49,0.279
112.13,-20.42,0.280
112.13,-20.36,0.280
112.14,-20.29,0.280
112.15,-20.23,0.280
112.15,-20.16,0.280
112.16,-20.09,0.280
112.17,-20.02,0.280
112.17,-19.96,0.280
112.18,-19.89,0.280
112.19,-19.82,0.280
112.19,-19.76,0.280
112.20,-19.69,0.280
112.21,-19.62,0.280
112.21,-19.56,0.280
112.22,-19.49,0.280
112.23,-19.42,0.280
112.23,-19.36,0.280
112.24,-19.29,0.280
112.25,-19.22,0.280
112.25,-19.16,0.280
112.26,-19.09,0.280
112.27,-19.02,0.280
112.27,-18.96,0.280
112.28,-18.89,0.280
112.29,-18.82,0.280
112.29,-18.76,0.280
112.30,-18.69,0.280
112.31,-18.62,0.280
112.31,-18.56,0.280
112.32,-18.49,0.280
112.33,-18.42,0.280
112.33,-18.36,0.280
112.34,-18.29,0.280
112.35,-18.22,0.280
112.35,-18.16,0.280
112.36,-18.09,0.280
112.37,-18.02,0.280
112.37,-17.96,0.280
112.38,-17.89,0.280
112.39,-17.82,0.280
112.39,-17.76,0.280
112.40,-17.69,0.280
112.41,-17.62,0.280
112.41,-17.55,0.280
112.42,-17.49,0.280
112.43,-17.42,0.281
112.43,-17.35,0.281
112.44,-17.29,0.281
112.45,-17.22,0.281
112.45,-17.15,0.281
112.46,-17.09,0.281
112.47,-17.02,0.281
112.47,-16.95,0.281
112.48,-16.89,0.281
112.49,-16.82,0.281
112.49,-16.75,0.281
112.50,-16.69,0.281
112.51,-16.62,0.281
112.51,-16.55,0.281
112.52,-16.49,0.281
112.53,-16.42,0.281
112.53,-16.35,0.281
112.54,-16.29,0.281
112.55,-16.22,0.281
112.55,-16.15,0.281
112.56,-16.09,0.281
112.57,-16.02,0.281
112.57,-15.95,0.281
112.58,-15.89,0.281
112.59,-15.82,0.281
112.59,-15.75,0.281
112.60,-15.69,0.281
112.61,-15.62,0.281
112.61,-15.55,0.281
112.62,-15.49,0.281
112.63,-15.42,0.281
112.63,-15.35,0.281
112.64,-15.29,0.281
112.65,-15.22,0.281
112.65,-15.15,0.281
112.66,-15.09,0.281
112.67,-15.02,0.281
112.67,-14.95,0.281
112.68,-14.89,0.281
112.69,-14.82,0.281
112.69,-14.75,0.281
112.70,-14.69,0.281
112.71,-14.62,0.282
112.71,-14.55,0.282
112.72,-14.48,0.282
112.73,-14.42,0.282
112.73,-14.35,0.282
112.74,-14.28,0.282
112.75,-14.22,0.282
112.75,-14.15,0.282
112.76,-14.08,0.282
112.77,-14.02,0.282
112.77,-13.95,0.282
112.78,-13.88,0.282
112.79,-13.82,0.282
112.79,-13.75,0.282
112.80,-13.68,0.282
112.81,-13.62,0.282
112.81,-13.55,0.282
112.82,-13.48,0.282
112.83,-13.42,0.282
112.83,-13.35,0.282
112.84,-13.28,0.282
112.85,-13.22,0.282
112.85,-13.15,0.282
112.86,-13.08,0.282
112.87,-13.02,0.282
112.87,-12.95,0.282
112.88,-12.88,0.282
112.89,-12.81,0.282
112.89,-12.75,0.282
112.90,-12.68,0.282
112.91,-12.61,0.282
112.91,-12.54,0.282
112.92,-12.48,0.283
112.93,-12.41,0.283
112.93,-12.35,0.283
112.94,-12.28,0.283
112.95,-12.21,0.283
112.95,-12.15,0.283
112.96,-12.08,0.283
112.97,-12.01,0.283
112.97,-11.95,0.283
112.98,-11.88,0.283
112.99,-11.81,0.283
112.99,-11.75,0.283
113.00,-11.68,0.283
113.01,-11.61,0.283
113.01,-11.55,0.283
113.02,-11.48,0.283
113.03,-11.41,0.283
113.03,-11.35,0.283
113.04,-11.28,0.283
113.05,-11.21,0.283
113.05,-11.15,0.283
113.06,-11.08,0.283
113.07,-11.01,0.283
113.07,-10.94,0.283
113.08,-10.88,0.283
113.09,-10.81,0.283
113.09,-10.74,0.283
113.10,-10.68,0.283
113.11,-10.61,0.283
113.11,-10.54,0.283
113.12,-10.48,0.283
113.13,-10.41,0.283
113.13,-10.34,0.283
113.14,-10.28,0.283
113.15,-10.21,0.283
113.15,-10.14,0.283
113.16,-10.08,0.283
113.17,-10.01,0.283
113.17,-9.94,0.284
113.18,-9.88,0.284
113.19,-9.81,0.284
113.19,-9.74,0.284
113.20,-9.68,0.284
113.21,-9.61,0.284
113.21,-9.54,0.284
113.22,-9.47,0.284
113.23,-9.41,0.284
113.23,-9.34,0.284
113.24,-9.27,0.284
113.25,-9.21,0.284
113.25,-9.14,0.284
113.26,-9.07,0.284
113.27,-9.01,0.284
113.27,-8.94,0.284
113.28,-8.87,0.284
113.29,-8.81,0.284
113.29,-8.74,0.284
113.30,-8.67,0.284
113.31,-8.61,0.284
113.31,-8.54,0.284
113.32,-8.47,0.284
113.33,-8.41,0.284
113.33,-8.34,0.284
113.34,-8.27,0.284
113.35,-8.21,0.284
113.35,-8.14,0.284
113.36,-8.07,0.284
113.37,-8.01,0.284
113.37,-7.94,0.284
113.38,-7.87,0.284
113.39,-7.81,0.285
113.39,-7.74,0.285
113.40,-7.67,0.285
113.41,-7.61,0.285
113.41,-7.54,0.285
113.42,-7.47,0.285
113.43,-7.41,0.285
113.43,-7.34,0.285
113.44,-7.27,0.285
113.45,-7.21,0.285
113.45,-7.14,0.285
113.46,-7.07,0.285
113.47,-7.01,0.285
113.47,-6.94,0.285
113.48,-6.87,0.285
113.49,-6.80,0.285
113.49,-6.74,0.285
113.50,-6.67,0.285
113.51,-6.60,0.285
113.51,-6.54,0.285
113.52,-6.47,0.285
113.53,-6.40,0.285
113.53,-6.34,0.285
113.54,-6.27,0.285
113.55,-6.20,0.285
113.55,-6.14,0.285
113.56,-6.07,0.285
113.57,-6.00,0.285
113.57,-5.94,0.285
113.58,-5.87,0.285
113.59,-5.80,0.285
113.59,-5.74,0.285
113.60,-5.67,0.285
113.61,-5.60,0.285
113.61,-5.54,0.285
113.62,-5.47,0.285
113.63,-5.40,0.285
113.63,-5.34,0.285
113.64,-5.27,0.286
113.65,-5.20,0.286
113.65,-5.14,0.286
113.66,-5.07,0.286
113.67,-5.00,0.286
113.67,-4.94,0.286
113.68,-4.87,0.286
113.69,-4.80,0.286
113.69,-4.74,0.286
113.70,-4.67,0.286
113.71,-4.60,0.286
113.71,-4.53,0.286
113.72,-4.47,0.286
113.73,-4.40,0.286
113.73,-4.34,0.286
113.74,-4.27,0.286
113.75,-4.20,0.286
113.75,-4.13,0.286
113.76,-4.07,0.286
113.77,-4.00,0.286
113.77,-3.93,0.286
113.78,-3.87,0.286
113.79,-3.80,0.286
113.79,-3.74,0.286
113.80,-3.67,0.286
113.81,-3.60,0.286
113.81,-3.53,0.286
113.82,-3.47,0.286
113.83,-3.40,0.286
113.83,-3.33,0.286
113.84,-3.27,0.287
113.85,-3.20,0.287
113.85,-3.13,0.287
113.86,-3.07,0.287
113.87,-3.00,0.287
113.87,-2.93,0.287
113.88,-2.87,0.287
113.89,-2.80,0.287
113.89,-2.73,0.287
113.90,-2.67,0.287
113.91,-2.60,0.287
113.91,-2.53,0.287
113.92,-2.47,0.287
113.93,-2.40,0.287
113.93,-2.33,0.287
113.94,-2.27,0.287
113.95,-2.20,0.287
113.95,-2.13,0.287
113.96,-2.06,0.287
113.97,-2.00,0.287
113.97,-1.93,0.287
113.98,-1.86,0.287
113.99,-1.80,0.287
113.99,-1.73,0.287
114.00,-1.66,0.287
114.01,-1.60,0.287
114.01,-1.53,0.287
114.02,-1.46,0.287
114.03,-1.40,0.287
114.03,-1.33,0.287
114.04,-1.26,0.288
114.05,-1.20,0.288
114.05,-1.13,0.288
114.06,-1.06,0.288
114.07,-1.00,0.288
114.07,-0.93,0.288
114.08,-0.86,0.288
114.09,-0.79,0.288
114.09,-0.73,0.288
114.10,-0.66,0.288
114.11,-0.60,0.288
114.11,-0.53,0.288
114.12,-0.46,0.288
114.13,-0.40,0.288
114.13,-0.33,0.288
114.14,-0.26,0.288
114.15,-0.20,0.288
114.15,-0.13,0.288
114.16,-0.06,0.288
114.17,0.00,0.288
114.17,0.07,0.288
114.18,0.14,0.288
114.19,0.21,0.288
114.19,0.27,0.288
114.20,0.34,0.288
114.21,0.40,0.288
114.21,0.47,0.288
114.22,0.54,0.288
114.23,0.61,0.288
114.23,0.67,0.289
114.24,0.74,0.289
114.25,0.81,0.289
114.25,0.87,0.289
114.26,0.94,0.289
114.27,1.01,0.289
114.27,1.07,0.289
114.28,1.14,0.289
114.29,1.21,0.289
114.29,1.27,0.289
114.30,1.34,0.289
114.31,1.41,0.289
114.31,1.47,0.289
114.32,1.54,0.289
114.33,1.61,0.289
114.33,1.67,0.289
114.34,1.74,0.289
114.35,1.81,0.289
114.35,1.87,0.289
114.36,1.94,0.289
114.37,2.01,0.289
114.37,2.07,0.289
114.38,2.14,0.289
114.39,2.21,0.289
114.39,2.27,0.289
114.40,2.34,0.289
114.41,2.41,0.289
114.41,2.48,0.290
114.42,2.54,0.290
114.43,2.61,0.290
114.43,2.67,0.290
114.44,2.74,0.290
114.45,2.81,0.290
114.45,2.88,0.290
114.46,2.94,0.290
114.47,3.01,0.290
114.47,3.08,0.290
114.48,3.14,0.290
114.49,3.21,0.290
114.49,3.28,0.290
114.50,3.34,0.290
114.51,3.41,0.290
114.51,3.48,0.290
114.52,3.54,0.290
114.53,3.61,0.290
114.53,3.68,0.290
114.54,3.74,0.290
114.55,3.81,0.290
114.55,3.88,0.290
114.56,3.94,0.290
114.57,4.01,0.290
114.57,4.08,0.290
114.58,4.14,0.290
114.59,4.21,0.290
114.59,4.28,0.291
114.60,4.34,0.291
114.61,4.41,0.291
114.61,4.48,0.291
114.62,4.54,0.291
114.63,4.61,0.291
114.63,4.68,0.291
114.64,4.75,0.291
114.65,4.81,0.291
114.65,4.88,0.291
114.66,4.94,0.291
114.67,5.01,0.291
114.67,5.08,0.291
114.68,5.15,0.291
114.69,5.21,0.291
114.69,5.28,0.291
114.70,5.35,0.291
114.71,5.41,0.291
114.71,5.48,0.291
114.72,5.55,0.291
114.73,5.61,0.291
114.73,5.68,0.291
114.74,5.75,0.291
114.75,5.81,0.291
114.75,5.88,0.291
114.76,5.95,0.291
114.77,6.01,0.291
114.77,6.08,0.291
114.78,6.15,0.292
114.79,6.21,0.292
114.79,6.28,0.292
114.80,6.35,0.292
114.81,6.41,0.292
114.81,6.48,0.292
114.82,6.55,0.292
114.83,6.61,0.292
114.83,6.68,0.292
114.84,6.75,0.292
114.85,6.81,0.292
114.85,6.88,0.292
114.86,6.95,0.292
114.87,7.02,0.292
114.87,7.08,0.292
114.88,7.15,0.292
114.89,7.22,0.292
114.89,7.28,0.292
114.90,7.35,0.292
114.91,7.42,0.292
114.91,7.48,0.292
114.92,7.55,0.292
114.93,7.62,0.292
114.93,7.68,0.292
114.94,7.75,0.292
114.95,7.82,0.292
114.95,7.88,0.293
114.96,7.95,0.293
114.97,8.02,0.293
114.97,8.08,0.293
114.98,8.15,0.293
114.99,8.22,0.293
114.99,8.28,0.293
115.00,8.35,0.293
115.01,8.42,0.293
115.01,8.48,0.293
115.02,8.55,0.293
115.03,8.62,0.293
115.03,8.68,0.293
115.04,8.75,0.293
115.05,8.82,0.293
115.05,8.88,0.293
115.06,8.95,0.293
115.07,9.02,0.293
115.07,9.08,0.293
115.08,9.15,0.293
115.09,9.22,0.293
115.09,9.28,0.293
115.10,9.35,0.293
115.11,9.42,0.293
115.11,9.48,0.293
115.12,9.55,0.293
115.13,9.62,0.293
115.13,9.69,0.294
115.14,9.75,0.294
115.15,9.82,0.294
115.15,9.89,0.294
115.16,9.95,0.294
115.17,10.02,0.294
115.17,10.09,0.294
115.18,10.15,0.294
115.19,10.22,0.294
115.19,10.29,0.294
115.20,10.35,0.294
115.21,10.42,0.294
115.21,10.49,0.294
115.22,10.55,0.294
115.23,10.62,0.294
115.23,10.69,0.294
115.24,10.75,0.294
115.25,10.82,0.294
115.25,10.89,0.294
115.26,10.96,0.294
115.27,11.02,0.294
115.27,11.09,0.294
115.28,11.15,0.295
115.29,11.22,0.295
115.29,11.29,0.295
115.30,11.35,0.295
115.31,11.42,0.295
115.31,11.49,0.295
115.32,11.55,0.295
115.33,11.62,0.295
115.33,11.69,0.295
115.34,11.75,0.295
115.35,11.82,0.295
115.35,11.89,0.295
115.36,11.96,0.295
115.37,12.02,0.295
115.37,12.09,0.295
115.38,12.16,0.295
115.39,12.22,0.295
115.39,12.29,0.295
115.40,12.36,0.295
115.41,12.42,0.295
115.41,12.49,0.295
115.42,12.56,0.295
115.43,12.62,0.295
115.43,12.69,0.295
115.44,12.75,0.295
115.45,12.82,0.295
115.45,12.89,0.296
115.46,12.96,0.296
115.47,13.02,0.296
115.47,13.09,0.296
115.48,13.16,0.296
115.49,13.22,0.296
115.49,13.29,0.296
115.50,13.35,0.296
115.51,13.42,0.296
115.51,13.49,0.296
115.52,13.56,0.296
115.53,13.62,0.296
115.53,13.69,0.296
115.54,13.76,0.296
115.55,13.82,0.296
115.55,13.89,0.296
115.56,13.96,0.296
115.57,14.02,0.296
115.57,14.09,0.296
115.58,14.16,0.296
115.59,14.22,0.296
115.59,14.29,0.296
115.60,14.36,0.296
115.61,14.42,0.297
115.61,14.49,0.297
115.62,14.56,0.297
115.63,14.62,0.297
115.63,14.69,0.297
115.64,14.76,0.297
115.65,14.82,0.297
115.65,14.89,0.297
115.66,14.96,0.297
115.67,15.03,0.297
115.67,15.09,0.297
115.68,15.16,0.297
115.69,15.22,0.297
115.69,15.29,0.297
115.70,15.36,0.297
115.71,15.42,0.297
115.71,15.49,0.297
115.72,15.56,0.297
115.73,15.63,0.297
115.73,15.69,0.297
115.74,15.76,0.298
115.75,15.83,0.298
115.75,15.89,0.298
115.76,15.96,0.298
115.77,16.03,0.298
115.77,16.09,0.298
115.78,16.16,0.298
115.79,16.23,0.298
115.79,16.29,0.298
115.80,16.36,0.298
115.81,16.43,0.298
115.81,16.49,0.298
115.82,16.56,0.298
115.83,16.63,0.298
115.83,16.69,0.298
115.84,16.76,0.298
115.85,16.83,0.299
115.85,16.89,0.299
115.86,16.96,0.299
115.87,17.03,0.299
115.87,17.09,0.299
115.88,17.16,0.299
115.89,17.23,0.299
115.89,17.29,0.299
115.90,17.36,0.299
115.91,17.43,0.299
115.91,17.50,0.299
115.92,17.56,0.299
115.93,17.63,0.299
115.93,17.69,0.299
115.94,17.76,0.299
115.95,17.83,0.299
115.95,17.90,0.299
115.96,17.96,0.299
115.97,18.03,0.299
115.97,18.10,0.299
115.98,18.16,0.299
115.99,18.23,0.299
115.99,18.30,0.299
116.00,18.36,0.300
116.01,18.43,0.300
116.01,18.50,0.300
116.02,18.56,0.300
116.03,18.63,0.300
116.03,18.70,0.300
116.04,18.76,0.300
116.05,18.83,0.300
116.05,18.90,0.300
116.06,18.96,0.300
116.07,19.03,0.300
116.07,19.10,0.300
116.08,19.16,0.300
116.09,19.23,0.300
116.09,19.30,0.300
116.10,19.36,0.300
116.11,19.43,0.300
116.11,19.50,0.300
116.12,19.57,0.300
116.13,19.63,0.300
116.13,19.70,0.300
116.14,19.76,0.301
116.15,19.83,0.301
116.15,19.90,0.301
116.16,19.96,0.301
116.17,20.03,0.301
116.17,20.10,0.301
116.18,20.17,0.301
116.19,20.23,0.301
116.19,20.30,0.301
116.20,20.37,0.301
116.21,20.43,0.301
116.21,20.50,0.301
116.22,20.57,0.301
116.23,20.63,0.301
116.23,20.70,0.301
116.24,20.77,0.301
116.25,20.83,0.301
116.25,20.90,0.301
116.26,20.97,0.301
116.27,21.03,0.301
116.27,21.10,0.301
116.28,21.17,0.301
116.29,21.23,0.301
116.29,21.30,0.301
116.30,21.37,0.302
116.31,21.43,0.302
116.31,21.50,0.302
116.32,21.57,0.302
116.33,21.63,0.302
116.33,21.70,0.302
116.34,21.77,0.302
116.35,21.83,0.302
116.35,21.90,0.302
116.36,21.97,0.302
116.37,22.03,0.302
116.37,22.10,0.302
116.38,22.17,0.302
116.39,22.23,0.302
116.39,22.30,0.302
116.40,22.37,0.302
116.41,22.43,0.302
116.41,22.50,0.302
116.42,22.57,0.302
116.43,22.63,0.302
116.43,22.70,0.302
116.44,22.77,0.302
116.45,22.83,0.303
116.45,22.90,0.303
116.46,22.97,0.303
116.47,23.04,0.303
116.47,23.10,0.303
116.48,23.17,0.303
116.49,23.24,0.303
116.49,23.30,0.303
116.50,23.37,0.303
116.51,23.44,0.303
116.51,23.50,0.303
116.52,23.57,0.303
116.53,23.64,0.303
116.53,23.70,0.303
116.54,23.77,0.303
116.55,23.83,0.303
116.55,23.90,0.303
116.56,23.97,0.303
116.57,24.04,0.303
116.57,24.10,0.303
116.58,24.17,0.303
116.59,24.24,0.303
116.59,24.30,0.303
116.60,24.37,0.304
116.61,24.44,0.304
116.61,24.50,0.304
116.62,24.57,0.304
116.63,24.63,0.304
116.63,24.70,0.304
116.64,24.77,0.304
116.65,24.84,0.304
116.65,24.90,0.304
116.66,24.97,0.304
116.67,25.04,0.304
116.67,25.10,0.304
116.68,25.17,0.304
116.69,25.24,0.304
116.69,25.30,0.304
116.70,25.37,0.304
116.71,25.44,0.304
116.71,25.50,0.304
116.72,25.57,0.304
116.73,25.64,0.304
116.73,25.70,0.304
116.74,25.77,0.305
116.75,25.84,0.305
116.75,25.90,0.305
116.76,25.97,0.305
116.77,26.04,0.305
116.77,26.10,0.305
116.78,26.17,0.305
116.79,26.24,0.305
116.79,26.30,0.305
116.80,26.37,0.305
116.81,26.44,0.305
116.81,26.50,0.305
116.82,26.57,0.305
116.83,26.64,0.305
116.83,26.70,0.305
116.84,26.77,0.305
116.85,26.84,0.305
116.85,26.90,0.305
116.86,26.97,0.305
116.87,27.04,0.305
116.87,27.10,0.306
116.88,27.17,0.306
116.89,27.24,0.306
116.89,27.30,0.306
116.90,27.37,0.306
116.91,27.44,0.306
116.91,27.50,0.306
116.92,27.57,0.306
116.93,27.64,0.306
116.93,27.71,0.306
116.94,27.77,
116.95,27.84,
116.95,27.91,
116.96,27.97,
116.97,28.04,
116.97,28.11,
116.98,28.17,
116.99,,
116.99,,