File: DSC/2025_06_14_THC_PyroGA_MC_n60C_200C_10Cmin_x3.csv
Filename,2025_06_14_THC_PyroGA_MC_n60C_200C_10Cmin_x3
Instrument name,DSC2A-00468 (192.168.1.100)
Operator,Yarger
rundate,6/14/2025
Sample name,2025_06_14_THC_PyroGA_MC_n60C_200C_10Cmin_x3
proceduresegments,Data Off ; Equilibrate -60.00 °C; Data On ; Ramp 10.00 °C/min to 200.00 °C; Data Off ; Isothermal 2.0 min; Data On ; Ramp 10.00 °C/min to -60.00 °C; Data Off ; Isothermal 2.0 min; Data On ; Ramp 10.00 °C/min to 200.00 °C; Data Off ; Isothermal 2.0 min; Data On ; Ramp 10.00 °C/min to -60.00 °C; Data Off ; Isothermal 2.0 min; Data On ; Ramp 10.00 °C/min to 30.00 °C
[File Parameters]
Run date,6/14/2025 6:45:18 PM
Trios version,5.1.1.46572
Original File Name,
Current File Name,D:\DSC2500\JYarger\2025_06_14_THC_PyroGA_MC_n60C_200C_10Cmin_x3.tri
[Procedure]
Procedure Name,THC_PGA_n60C_200C_10Cmin_x3
Sample Name,2025_06_14_THC_PyroGA_MC_n60C_200C_10Cmin_x3
Sample Mass,5.99 mg
Reference Sample Mass,0 mg
Pan Mass,57.14 mg
Pan Number,34
Reference Pan Mass,57.05 mg
Reference Pan Number,28
Pan Type,Tzero Aluminum Hermetic
Comments,Al Hermetic DSC Consumables sealed Pan/Lid. A2 Tray (Google Sheet: DSC_Samples_A2_Tray_May2025)
Project Name,CA
Operator,Yarger
Test,Custom
Unload Max Temperature,30
Unload Min Temperature,30
Load Max Temperature,30
Load Min Temperature,30
Stop on Gas Flow Error,Yes
[Signal List]
Signal #1,Time (min)
Signal #2,Temperature (°C)
Signal #3,Heat Flow (mW)
Signal #4,Delta T (µV)
Signal #5,Delta Tzero (µV)
Signal #6,Tzero Temperature (°C)
Signal #7,Cell Purge (mL/min)
Signal #8,Heater Temp (°C)
Signal #9,Power Delivered (W)
Signal #10,Reference Junction Temperature (°C)
Signal #11,Flange Temperature (°C)
Signal #12,Heat Flow Phase (rad)
Signal #13,Total Heat Capacity (J/°C)
Signal #14,Heat Capacity (J/°C)
[Configuration]
Company Name,ASU
Instrument Name,DSC2A-00468
Instrument Type,DSC2500
Serial Number,DSC2A-00468
IP,192.168.1.100
Location of Instrument,MRRC
DisplayType,Unknown
Sample Interval ,0.1 s/pt
Selected Heat Flow,T4P
Exotherm Direction,Down
Cell Serial,DRC2-00792
Lid Type,Standard
Cooler,RCS 90
Leave Cooler on at End of Sequence,On
Gas 2,Nitrogen
Gas Selected,Channel 1
Flow Rate,50 mL/min
Secondary Purge,On
Licensed Heat Flow,Heat Flow T4P
Modulation Licensed,Yes
[Versions]
Common IDD Version,1
Cortex Version,VER 2.10.2.31
Driver,5.0.0.6
GDM Version,1.0.3.3
TouchscreenVersion,1.0.0.16145
FEP Version,1.2.1.21
FEP Bootloader,2.0.0.5
AutoSampler Version,2.1.1.26
Auto Sampler Bootloader,2.0.0.5
FCM Version,1.1.0.3
FCM Bootloader,2.0.0.5
[Experiment Logs]
Experiment Log Entry # 1,Data On set to 0
Experiment Log Entry # 3,Equilibrate Segment -60 (C) Started
Experiment Log Entry # 5,Air Cool is off.
Experiment Log Entry # 7,Data On set to 1
Experiment Log Entry # 9,Ramp Segment 10 C/min to 200 Started
Experiment Log Entry # 11,Data On set to 0
Experiment Log Entry # 13,Isothermal Segment 2 min started
Experiment Log Entry # 15,Data On set to 1
Experiment Log Entry # 17,Ramp Segment 10 C/min to -60 Started
Experiment Log Entry # 19,Data On set to 0
Experiment Log Entry # 21,Isothermal Segment 2 min started
Experiment Log Entry # 23,Data On set to 1
Experiment Log Entry # 25,Ramp Segment 10 C/min to 200 Started
Experiment Log Entry # 27,Data On set to 0
Experiment Log Entry # 29,Isothermal Segment 2 min started
Experiment Log Entry # 31,Data On set to 1
Experiment Log Entry # 33,Ramp Segment 10 C/min to -60 Started
Experiment Log Entry # 35,Data On set to 0
Experiment Log Entry # 37,Isothermal Segment 2 min started
Experiment Log Entry # 39,Data On set to 1
Experiment Log Entry # 41,Ramp Segment 10 C/min to 30 Started
[Method Log]
Method Log Entry # 1,Data Off
Method Log Entry # 2,Equilibrate -60 °C
Method Log Entry # 3,Data On
Method Log Entry # 4,(Ramp 164729) Ramp 10 °C/minute to 200 °C
Method Log Entry # 5,Data Off
Method Log Entry # 6,Isothermal 2 minutes
Method Log Entry # 7,Data On
Method Log Entry # 8,(Ramp 164733) Ramp 10 °C/minute to -60 °C
Method Log Entry # 9,Data Off
Method Log Entry # 10,Isothermal 2 minutes
Method Log Entry # 11,Data On
Method Log Entry # 12,(Ramp 164737) Ramp 10 °C/minute to 200 °C
Method Log Entry # 13,Data Off
Method Log Entry # 14,Isothermal 2 minutes
Method Log Entry # 15,Data On
Method Log Entry # 16,(Ramp 164741) Ramp 10 °C/minute to -60 °C
Method Log Entry # 17,Data Off
Method Log Entry # 18,Isothermal 2 minutes
Method Log Entry # 19,Data On
Method Log Entry # 20,(Ramp 164745) Ramp 10 °C/minute to 30 °C
Cell Serial,DRC2-00792
[T1 Calibration]
Slope,-0.008529666
Offset,9.636258
Initial Temperature,98.23
GUID,f8bfdadc-4977-4fdf-ba6d-0ba9134940c3
[TZero Calibration]
Date Applied,11/29/2022 4:06:13 PM
Description,From -89.059 °C to 396.009 °C at 20.000°C/min
Gas Type,Nitrogen
Pan Type,None
Source Files 1,C:\Users\yargerlab\Desktop\DSC Data\General\TZero_calibration_11_29_22_2nd(2).tri
Source Files 2,C:\Users\yargerlab\Desktop\DSC Data\General\TZero_calibration_11_29_22_2nd(3).tri
Delta T Offset,13.05235
Delta T Slope,-0.007271007
Delta T0 Offset,-13.69128
Delta T0 Slope,0.06063341
[Temperature Calibration]
Date Applied,11/29/2022 7:12:28 PM
Description,From 106.590 °C to 186.590 °C at 10.000°C/min
Gas Type,Nitrogen
Pan Type,Tzero Aluminum Hermetic
Source Files 1,C:\Users\yargerlab\Desktop\DSC Data\General\Indium(6).tri
Measured 1,157.391
Known 1,156.598
[Cell Constant Calibration]
Date Applied,11/29/2022 7:12:29 PM
Description,From 106.590 °C to 186.590 °C at 10.000°C/min
Gas Type,Nitrogen
Pan Type,Tzero Aluminum Hermetic
Source Files 1,C:\Users\yargerlab\Desktop\DSC Data\General\Indium(6).tri
T4P KCell,1.006051
Onset Slope,63.26126 mW/°C
[Direct Cp Calibration]
Date Applied,11/30/2022 11:04:51 AM
Description,From -79.983 °C to 298.409 °C at 10.000°C/min
Gas Type,Nitrogen
Pan Type,Tzero Aluminum Hermetic
Source Files 1,C:\Users\yargerlab\Desktop\DSC Data\General\Sapphire_Heat_Capacity_11_30_22.tri
[Rev Cp Calibration]
Date Applied,11/30/2022 1:58:51 PM
Description,From -79.996 °C to 292.812 °C at 3.000°C/min
Gas Type,Nitrogen
Pan Type,Tzero Aluminum Hermetic
Source Files 1,C:\Users\yargerlab\Desktop\DSC Data\General\Sapphire_MDSC_Calibration_11_30_22.tri
[step]
Ramp 10.00 °C/min to 200.00 °C
Time,Temperature,Heat Flow (Normalized)
min,°C,W/g
0.00,-59.67,-0.064
0.02,-59.69,-0.062
0.04,-59.69,-0.056
0.05,-59.69,-0.055
0.07,-59.67,-0.058
0.09,-59.63,-0.072
0.11,-59.56,-0.083
0.13,-59.48,-0.088
0.15,-59.38,-0.088
0.16,-59.27,-0.084
0.18,-59.15,-0.063
0.20,-59.02,-0.045
0.22,-58.88,-0.026
0.24,-58.73,-0.007
0.26,-58.58,0.011
0.28,-58.43,0.028
0.29,-58.28,0.042
0.31,-58.12,0.054
0.33,-57.96,0.068
0.35,-57.80,0.076
0.37,-57.63,0.086
0.39,-57.47,0.095
0.40,-57.30,0.102
0.42,-57.13,0.108
0.44,-56.96,0.113
0.46,-56.79,0.117
0.48,-56.61,0.123
0.50,-56.44,0.125
0.51,-56.27,0.128
0.53,-56.09,0.131
0.55,-55.92,0.134
0.57,-55.74,0.137
0.59,-55.57,0.138
0.60,-55.39,0.140
0.62,-55.21,0.142
0.64,-55.03,0.143
0.66,-54.86,0.144
0.68,-54.68,0.146
0.70,-54.50,0.147
0.72,-54.32,0.148
0.73,-54.14,0.148
0.75,-53.96,0.149
0.77,-53.78,0.150
0.79,-53.60,0.151
0.81,-53.42,0.152
0.83,-53.24,0.153
0.84,-53.06,0.153
0.86,-52.88,0.154
0.88,-52.70,0.154
0.90,-52.52,0.155
0.92,-52.34,0.155
0.93,-52.16,0.156
0.95,-51.98,0.156
0.97,-51.80,0.156
0.99,-51.62,0.157
1.01,-51.43,0.157
1.03,-51.25,0.157
1.05,-51.07,0.157
1.06,-50.89,0.158
1.08,-50.71,0.158
1.10,-50.53,0.159
1.12,-50.34,0.159
1.14,-50.16,0.159
1.16,-49.98,0.159
1.17,-49.80,0.160
1.19,-49.61,0.160
1.21,-49.43,0.160
1.23,-49.25,0.161
1.25,-49.07,0.161
1.27,-48.88,0.161
1.28,-48.70,0.161
1.30,-48.52,0.162
1.32,-48.34,0.162
1.34,-48.15,0.162
1.36,-47.97,0.162
1.38,-47.79,0.163
1.39,-47.61,0.163
1.41,-47.42,0.163
1.43,-47.24,0.163
1.45,-47.06,0.164
1.47,-46.87,0.164
1.48,-46.69,0.164
1.50,-46.51,0.164
1.52,-46.33,0.164
1.54,-46.14,0.165
1.56,-45.96,0.165
1.58,-45.78,0.165
1.59,-45.59,0.166
1.61,-45.41,0.166
1.63,-45.23,0.166
1.65,-45.05,0.166
1.67,-44.86,0.166
1.69,-44.68,0.166
1.71,-44.49,0.167
1.72,-44.31,0.167
1.74,-44.13,0.167
1.76,-43.95,0.167
1.78,-43.76,0.167
1.80,-43.58,0.168
1.82,-43.39,0.168
1.83,-43.21,0.168
1.85,-43.03,0.168
1.87,-42.84,0.168
1.89,-42.66,0.169
1.91,-42.48,0.169
1.93,-42.30,0.169
1.94,-42.11,0.169
1.96,-41.93,0.169
1.98,-41.75,0.169
2.00,-41.56,0.169
2.02,-41.38,0.170
2.03,-41.20,0.170
2.05,-41.01,0.170
2.07,-40.83,0.170
2.09,-40.65,0.170
2.11,-40.46,0.170
2.13,-40.28,0.171
2.14,-40.10,0.171
2.16,-39.91,0.171
2.18,-39.73,0.171
2.20,-39.54,0.171
2.22,-39.36,0.171
2.24,-39.18,0.172
2.26,-38.99,0.172
2.27,-38.81,0.172
2.29,-38.63,0.172
2.31,-38.44,0.172
2.33,-38.26,0.172
2.35,-38.08,0.173
2.36,-37.89,0.173
2.38,-37.71,0.173
2.40,-37.53,0.173
2.42,-37.34,0.173
2.44,-37.16,0.173
2.46,-36.98,0.174
2.48,-36.79,0.174
2.49,-36.61,0.174
2.51,-36.42,0.174
2.53,-36.24,0.174
2.55,-36.06,0.174
2.57,-35.87,0.174
2.59,-35.69,0.175
2.60,-35.51,0.175
2.62,-35.32,0.175
2.64,-35.14,0.175
2.66,-34.96,0.175
2.68,-34.77,0.175
2.69,-34.59,0.176
2.71,-34.40,0.176
2.73,-34.22,0.176
2.75,-34.04,0.176
2.77,-33.86,0.176
2.79,-33.67,0.177
2.81,-33.49,0.177
2.82,-33.30,0.177
2.84,-33.12,0.177
2.86,-32.94,0.177
2.88,-32.75,0.177
2.90,-32.57,0.178
2.91,-32.39,0.178
2.93,-32.20,0.178
2.95,-32.02,0.178
2.97,-31.84,0.178
2.99,-31.65,0.178
3.01,-31.47,0.179
3.03,-31.29,0.179
3.04,-31.10,0.179
3.06,-30.92,0.179
3.08,-30.74,0.179
3.10,-30.55,0.180
3.12,-30.37,0.180
3.14,-30.18,0.180
3.15,-30.00,0.180
3.17,-29.82,0.181
3.19,-29.63,0.181
3.21,-29.45,0.181
3.23,-29.27,0.181
3.24,-29.08,0.181
3.26,-28.90,0.182
3.28,-28.72,0.182
3.30,-28.53,0.182
3.32,-28.35,0.182
3.34,-28.16,0.182
3.36,-27.98,0.183
3.37,-27.80,0.183
3.39,-27.61,0.183
3.41,-27.43,0.183
3.43,-27.25,0.183
3.45,-27.07,0.184
3.46,-26.88,0.184
3.48,-26.70,0.184
3.50,-26.51,0.184
3.52,-26.33,0.184
3.54,-26.15,0.185
3.56,-25.97,0.185
3.58,-25.78,0.185
3.59,-25.60,0.185
3.61,-25.41,0.186
3.63,-25.23,0.186
3.65,-25.05,0.186
3.67,-24.86,0.186
3.69,-24.68,0.187
3.70,-24.50,0.187
3.72,-24.31,0.187
3.74,-24.13,0.188
3.76,-23.94,0.188
3.78,-23.76,0.188
3.79,-23.58,0.189
3.81,-23.40,0.189
3.83,-23.21,0.190
3.85,-23.03,0.190
3.87,-22.84,0.190
3.89,-22.66,0.191
3.91,-22.48,0.191
3.92,-22.29,0.192
3.94,-22.11,0.192
3.96,-21.93,0.193
3.98,-21.74,0.193
4.00,-21.56,0.193
4.01,-21.38,0.194
4.03,-21.20,0.194
4.05,-21.01,0.195
4.07,-20.83,0.195
4.09,-20.65,0.196
4.11,-20.46,0.196
4.13,-20.28,0.197
4.14,-20.09,0.197
4.16,-19.91,0.198
4.18,-19.73,0.200
4.20,-19.54,0.201
4.22,-19.36,0.202
4.24,-19.18,0.202
4.25,-19.00,0.203
4.27,-18.81,0.204
4.29,-18.63,0.206
4.31,-18.45,0.206
4.33,-18.26,0.207
4.35,-18.08,0.208
4.36,-17.90,0.209
4.38,-17.71,0.210
4.40,-17.53,0.210
4.42,-17.35,0.211
4.44,-17.16,0.212
4.45,-16.98,0.213
4.47,-16.80,0.214
4.49,-16.61,0.215
4.51,-16.43,0.216
4.53,-16.25,0.217
4.55,-16.06,0.218
4.56,-15.88,0.220
4.58,-15.70,0.220
4.60,-15.52,0.223
4.62,-15.33,0.224
4.64,-15.15,0.225
4.66,-14.97,0.226
4.68,-14.78,0.227
4.69,-14.60,0.229
4.71,-14.42,0.229
4.73,-14.23,0.230
4.75,-14.05,0.231
4.77,-13.87,0.233
4.79,-13.68,0.234
4.80,-13.50,0.235
4.82,-13.32,0.237
4.84,-13.14,0.237
4.86,-12.95,0.239
4.88,-12.77,0.240
4.90,-12.59,0.240
4.91,-12.40,0.241
4.93,-12.22,0.242
4.95,-12.04,0.243
4.97,-11.85,0.243
4.99,-11.67,0.245
5.00,-11.49,0.245
5.02,-11.30,0.246
5.04,-11.12,0.246
5.06,-10.94,0.247
5.08,-10.75,0.247
5.10,-10.57,0.248
5.11,-10.39,0.248
5.13,-10.20,0.249
5.15,-10.02,0.249
5.17,-9.84,0.249
5.19,-9.65,0.250
5.21,-9.47,0.250
5.23,-9.29,0.250
5.24,-9.10,0.251
5.26,-8.92,0.251
5.28,-8.74,0.251
5.30,-8.55,0.251
5.32,-8.37,0.252
5.34,-8.19,0.252
5.35,-8.00,0.252
5.37,-7.82,0.252
5.39,-7.64,0.252
5.41,-7.45,0.252
5.43,-7.27,0.252
5.45,-7.08,0.252
5.46,-6.90,0.252
5.48,-6.72,0.252
5.50,-6.53,0.252
5.52,-6.35,0.252
5.54,-6.16,0.252
5.55,-5.98,0.252
5.57,-5.80,0.252
5.59,-5.61,0.252
5.61,-5.43,0.252
5.63,-5.25,0.252
5.65,-5.06,0.252
5.66,-4.88,0.252
5.68,-4.70,0.252
5.70,-4.51,0.252
5.72,-4.33,0.252
5.74,-4.15,0.252
5.76,-3.96,0.252
5.78,-3.78,0.252
5.79,-3.60,0.252
5.81,-3.41,0.252
5.83,-3.23,0.252
5.85,-3.04,0.252
5.87,-2.86,0.252
5.89,-2.68,0.252
5.90,-2.49,0.252
5.92,-2.31,0.252
5.94,-2.12,0.252
5.96,-1.94,0.252
5.98,-1.76,0.252
6.00,-1.57,0.252
6.01,-1.39,0.252
6.03,-1.21,0.252
6.05,-1.02,0.252
6.07,-0.84,0.252
6.09,-0.66,0.253
6.10,-0.47,0.253
6.12,-0.29,0.253
6.14,-0.11,0.253
6.16,0.08,0.253
6.18,0.26,0.253
6.20,0.45,0.253
6.21,0.63,0.253
6.23,0.81,0.253
6.25,1.00,0.253
6.27,1.18,0.253
6.29,1.36,0.253
6.31,1.55,0.253
6.33,1.73,0.253
6.34,1.91,0.254
6.36,2.10,0.254
6.38,2.28,0.254
6.40,2.46,0.254
6.42,2.65,0.254
6.44,2.83,0.254
6.45,3.02,0.254
6.47,3.20,0.254
6.49,3.38,0.254
6.51,3.57,0.254
6.53,3.75,0.254
6.55,3.93,0.255
6.56,4.12,0.255
6.58,4.30,0.255
6.60,4.48,0.255
6.62,4.67,0.255
6.64,4.85,0.255
6.65,5.03,0.255
6.67,5.22,0.255
6.69,5.40,0.255
6.71,5.59,0.256
6.73,5.77,0.256
6.75,5.95,0.256
6.76,6.14,0.256
6.78,6.32,0.256
6.80,6.50,0.256
6.82,6.69,0.256
6.84,6.87,0.257
6.86,7.05,0.257
6.88,7.24,0.257
6.89,7.42,0.257
6.91,7.60,0.257
6.93,7.79,0.257
6.95,7.97,0.257
6.97,8.15,0.257
6.99,8.34,0.257
7.00,8.52,0.258
7.02,8.71,0.258
7.04,8.89,0.258
7.06,9.07,0.258
7.08,9.26,0.258
7.10,9.44,0.258
7.11,9.62,0.258
7.13,9.81,0.258
7.15,9.99,0.259
7.17,10.17,0.259
7.19,10.36,0.259
7.20,10.54,0.259
7.22,10.73,0.259
7.24,10.91,0.259
7.26,11.09,0.259
7.28,11.28,0.260
7.30,11.46,0.260
7.31,11.64,0.260
7.33,11.83,0.260
7.35,12.01,0.260
7.37,12.19,0.260
7.39,12.38,0.260
7.41,12.56,0.260
7.43,12.74,0.261
7.44,12.93,0.261
7.46,13.11,0.261
7.48,13.29,0.261
7.50,13.48,0.261
7.52,13.66,0.261
7.54,13.84,0.261
7.55,14.03,0.262
7.57,14.21,0.262
7.59,14.40,0.262
7.61,14.58,0.262
7.63,14.76,0.262
7.65,14.95,0.262
7.66,15.13,0.262
7.68,15.31,0.262
7.70,15.50,0.263
7.72,15.68,0.263
7.74,15.86,0.263
7.75,16.05,0.263
7.77,16.23,0.263
7.79,16.41,0.263
7.81,16.60,0.263
7.83,16.78,0.263
7.85,16.96,0.264
7.86,17.15,0.264
7.88,17.33,0.264
7.90,17.51,0.264
7.92,17.70,0.264
7.94,17.88,0.264
7.96,18.07,0.264
7.98,18.25,0.264
7.99,18.43,0.265
8.01,18.62,0.265
8.03,18.80,0.265
8.05,18.99,0.265
8.07,19.17,0.265
8.09,19.35,0.265
8.10,19.53,0.265
8.12,19.72,0.265
8.14,19.90,0.266
8.16,20.09,0.266
8.18,20.27,0.266
8.20,20.45,0.266
8.21,20.64,0.266
8.23,20.82,0.266
8.25,21.00,0.266
8.27,21.19,0.267
8.29,21.37,0.267
8.30,21.55,0.267
8.32,21.74,0.267
8.34,21.92,0.267
8.36,22.10,0.267
8.38,22.29,0.267
8.40,22.47,0.268
8.41,22.66,0.268
8.43,22.84,0.268
8.45,23.02,0.268
8.47,23.21,0.268
8.49,23.39,0.268
8.51,23.57,0.269
8.53,23.76,0.269
8.54,23.94,0.269
8.56,24.12,0.269
8.58,24.31,0.269
8.60,24.49,0.269
8.62,24.67,0.269
8.63,24.86,0.270
8.65,25.04,0.270
8.67,25.22,0.270
8.69,25.41,0.270
8.71,25.59,0.270
8.73,25.77,0.270
8.75,25.96,0.270
8.76,26.14,0.270
8.78,26.32,0.271
8.80,26.51,0.271
8.82,26.69,0.271
8.84,26.88,0.271
8.85,27.06,0.271
8.87,27.24,0.271
8.89,27.43,0.271
8.91,27.61,0.272
8.93,27.79,0.272
8.95,27.98,0.272
8.97,28.16,0.272
8.98,28.34,0.272
9.00,28.53,0.272
9.02,28.71,0.273
9.04,28.89,0.273
9.06,29.08,0.273
9.08,29.26,0.273
9.09,29.45,0.273
9.11,29.63,0.273
9.13,29.81,0.273
9.15,29.99,0.274
9.17,30.18,0.274
9.18,30.36,0.274
9.20,30.55,0.274
9.22,30.73,0.274
9.24,30.91,0.274
9.26,31.10,0.274
9.28,31.28,0.274
9.30,31.46,0.275
9.31,31.65,0.275
9.33,31.83,0.275
9.35,32.01,0.275
9.37,32.20,0.275
9.39,32.38,0.275
9.40,32.57,0.276
9.42,32.75,0.276
9.44,32.93,0.276
9.46,33.12,0.276
9.48,33.30,0.276
9.50,33.48,0.276
9.52,33.67,0.276
9.53,33.85,0.277
9.55,34.03,0.277
9.57,34.22,0.277
9.59,34.40,0.277
9.61,34.58,0.277
9.63,34.77,0.277
9.64,34.95,0.277
9.66,35.14,0.278
9.68,35.32,0.278
9.70,35.50,0.278
9.72,35.69,0.278
9.73,35.87,0.278
9.75,36.05,0.278
9.77,36.24,0.278
9.79,36.42,0.278
9.81,36.60,0.279
9.83,36.79,0.279
9.85,36.97,0.279
9.86,37.16,0.279
9.88,37.34,0.279
9.90,37.52,0.279
9.92,37.70,0.279
9.94,37.89,0.280
9.95,38.07,0.280
9.97,38.26,0.280
9.99,38.44,0.280
10.01,38.62,0.280
10.03,38.81,0.280
10.05,38.99,0.280
10.07,39.17,0.281
10.08,39.36,0.281
10.10,39.54,0.281
10.12,39.72,0.281
10.14,39.91,0.281
10.16,40.09,0.281
10.18,40.27,0.281
10.19,40.46,0.281
10.21,40.64,0.281
10.23,40.82,0.282
10.25,41.01,0.282
10.27,41.19,0.282
10.28,41.37,0.282
10.30,41.56,0.282
10.32,41.74,0.282
10.34,41.93,0.282
10.36,42.11,0.282
10.38,42.29,0.283
10.40,42.47,0.283
10.41,42.66,0.283
10.43,42.84,0.283
10.45,43.03,0.283
10.47,43.21,0.283
10.49,43.39,0.283
10.50,43.58,0.284
10.52,43.76,0.284
10.54,43.94,0.284
10.56,44.13,0.284
10.58,44.31,0.284
10.60,44.49,0.284
10.62,44.68,0.285
10.63,44.86,0.285
10.65,45.04,0.285
10.67,45.23,0.285
10.69,45.41,0.285
10.71,45.59,0.285
10.73,45.78,0.286
10.74,45.96,0.286
10.76,46.14,0.286
10.78,46.33,0.286
10.80,46.51,0.286
10.82,46.69,0.286
10.83,46.88,0.287
10.85,47.06,0.287
10.87,47.25,0.287
10.89,47.43,0.287
10.91,47.61,0.287
10.93,47.80,0.288
10.95,47.98,0.288
10.96,48.16,0.288
10.98,48.35,0.288
11.00,48.53,0.288
11.02,48.71,0.288
11.04,48.90,0.288
11.05,49.08,0.289
11.07,49.26,0.289
11.09,49.45,0.289
11.11,49.63,0.289
11.13,49.81,0.289
11.15,50.00,0.289
11.17,50.18,0.290
11.18,50.37,0.290
11.20,50.55,0.290
11.22,50.73,0.290
11.24,50.92,0.290
11.26,51.10,0.291
11.28,51.28,0.291
11.29,51.47,0.291
11.31,51.65,0.291
11.33,51.83,0.291
11.35,52.02,0.291
11.37,52.20,0.292
11.38,52.39,0.292
11.40,52.57,0.292
11.42,52.75,0.292
11.44,52.94,0.292
11.46,53.12,0.292
11.48,53.30,0.292
11.50,53.49,0.293
11.51,53.67,0.293
11.53,53.85,0.293
11.55,54.04,0.293
11.57,54.22,0.293
11.59,54.40,0.293
11.60,54.59,0.294
11.62,54.77,0.294
11.64,54.95,0.294
11.66,55.14,0.294
11.68,55.32,0.294
11.70,55.50,0.294
11.72,55.69,0.294
11.73,55.87,0.295
11.75,56.06,0.295
11.77,56.24,0.295
11.79,56.42,0.295
11.81,56.61,0.295
11.83,56.79,0.295
11.84,56.97,0.295
11.86,57.16,0.296
11.88,57.34,0.296
11.90,57.52,0.296
11.92,57.71,0.296
11.93,57.89,0.296
11.95,58.07,0.296
11.97,58.26,0.297
11.99,58.44,0.297
12.01,58.63,0.297
12.03,58.81,0.297
12.05,58.99,0.297
12.06,59.18,0.297
12.08,59.36,0.297
12.10,59.54,0.298
12.12,59.73,0.298
12.14,59.91,0.298
12.15,60.09,0.299
12.17,60.28,0.299
12.19,60.46,0.301
12.21,60.64,0.302
12.23,60.83,0.306
12.25,61.01,0.313
12.27,61.19,0.319
12.28,61.37,0.326
12.30,61.56,0.329
12.32,61.74,0.330
12.34,61.92,0.330
12.36,62.10,0.330
12.38,62.29,0.330
12.39,62.47,0.330
12.41,62.65,0.329
12.43,62.84,0.329
12.45,63.02,0.327
12.47,63.20,0.325
12.48,63.39,0.324
12.50,63.57,0.322
12.52,63.76,0.319
12.54,63.94,0.318
12.56,64.13,0.316
12.58,64.31,0.315
12.60,64.49,0.313
12.61,64.68,0.312
12.63,64.86,0.312
12.65,65.05,0.310
12.67,65.23,0.309
12.69,65.41,0.309
12.70,65.60,0.308
12.72,65.78,0.308
12.74,65.96,0.307
12.76,66.15,0.307
12.78,66.33,0.306
12.80,66.52,0.306
12.82,66.70,0.306
12.83,66.88,0.306
12.85,67.07,0.305
12.87,67.25,0.305
12.89,67.44,0.305
12.91,67.62,0.305
12.93,67.80,0.304
12.94,67.99,0.304
12.96,68.17,0.304
12.98,68.35,0.304
13.00,68.54,0.304
13.02,68.72,0.304
13.03,68.90,0.304
13.05,69.09,0.303
13.07,69.27,0.303
13.09,69.46,0.303
13.11,69.64,0.303
13.13,69.82,0.303
13.15,70.01,0.303
13.16,70.19,0.303
13.18,70.37,0.303
13.20,70.56,0.303
13.22,70.74,0.303
13.24,70.92,0.303
13.25,71.11,0.303
13.27,71.29,0.303
13.29,71.47,0.303
13.31,71.66,0.303
13.33,71.84,0.303
13.35,72.03,0.303
13.37,72.21,0.303
13.38,72.39,0.303
13.40,72.58,0.303
13.42,72.76,0.303
13.44,72.94,0.303
13.46,73.13,0.303
13.48,73.31,0.303
13.49,73.49,0.303
13.51,73.68,0.303
13.53,73.86,0.303
13.55,74.04,0.304
13.57,74.23,0.304
13.58,74.41,0.304
13.60,74.60,0.304
13.62,74.78,0.304
13.64,74.96,0.304
13.66,75.15,0.304
13.68,75.33,0.304
13.70,75.51,0.304
13.71,75.70,0.304
13.73,75.88,0.304
13.75,76.07,0.304
13.77,76.25,0.304
13.79,76.43,0.305
13.80,76.62,0.305
13.82,76.80,0.305
13.84,76.98,0.305
13.86,77.17,0.305
13.88,77.35,0.305
13.90,77.54,0.305
13.92,77.72,0.305
13.93,77.90,0.305
13.95,78.09,0.305
13.97,78.27,0.305
13.99,78.45,0.306
14.01,78.64,0.306
14.03,78.82,0.306
14.04,79.00,0.306
14.06,79.19,0.306
14.08,79.37,0.306
14.10,79.55,0.306
14.12,79.74,0.306
14.13,79.92,0.306
14.15,80.10,0.306
14.17,80.29,0.306
14.19,80.47,0.306
14.21,80.65,0.306
14.23,80.84,0.306
14.25,81.02,0.306
14.26,81.20,0.307
14.28,81.39,0.307
14.30,81.57,0.307
14.32,81.75,0.307
14.34,81.94,0.307
14.35,82.12,0.307
14.37,82.31,0.307
14.39,82.49,0.307
14.41,82.67,0.307
14.43,82.86,0.307
14.45,83.04,0.307
14.47,83.22,0.307
14.48,83.41,0.307
14.50,83.59,0.307
14.52,83.77,0.307
14.54,83.96,0.307
14.56,84.14,0.307
14.58,84.32,0.307
14.59,84.51,0.307
14.61,84.69,0.307
14.63,84.87,0.307
14.65,85.06,0.307
14.67,85.24,0.307
14.68,85.42,0.307
14.70,85.61,0.307
14.72,85.79,0.308
14.74,85.97,0.308
14.76,86.16,0.308
14.78,86.34,0.308
14.80,86.52,0.308
14.81,86.71,0.308
14.83,86.89,0.308
14.85,87.07,0.308
14.87,87.26,0.308
14.89,87.44,0.308
14.90,87.63,0.308
14.92,87.81,0.308
14.94,87.99,0.308
14.96,88.18,0.308
14.98,88.36,0.308
15.00,88.54,0.308
15.02,88.73,0.309
15.03,88.91,0.309
15.05,89.09,0.309
15.07,89.28,0.309
15.09,89.46,0.309
15.11,89.64,0.309
15.13,89.83,0.309
15.14,90.01,0.309
15.16,90.19,0.309
15.18,90.38,0.309
15.20,90.56,0.309
15.22,90.74,0.309
15.23,90.93,0.310
15.25,91.11,0.310
15.27,91.30,0.310
15.29,91.48,0.310
15.31,91.66,0.310
15.33,91.85,0.310
15.35,92.03,0.310
15.36,92.21,0.310
15.38,92.40,0.310
15.40,92.58,0.311
15.42,92.76,0.311
15.44,92.95,0.311
15.45,93.13,0.311
15.47,93.31,0.311
15.49,93.50,0.311
15.51,93.68,0.311
15.53,93.86,0.311
15.55,94.05,0.311
15.57,94.23,0.312
15.58,94.41,0.312
15.60,94.60,0.312
15.62,94.78,0.312
15.64,94.96,0.312
15.66,95.15,0.312
15.68,95.33,0.312
15.69,95.52,0.312
15.71,95.70,0.312
15.73,95.88,0.312
15.75,96.07,0.312
15.77,96.25,0.312
15.78,96.43,0.312
15.80,96.62,0.313
15.82,96.80,0.313
15.84,96.98,0.313
15.86,97.17,0.313
15.88,97.35,0.313
15.90,97.53,0.313
15.91,97.72,0.313
15.93,97.90,0.313
15.95,98.08,0.313
15.97,98.27,0.313
15.99,98.45,0.314
16.00,98.63,0.314
16.02,98.82,0.314
16.04,99.00,0.314
16.06,99.19,0.314
16.08,99.37,0.314
16.10,99.55,0.314
16.12,99.74,0.314
16.13,99.92,0.314
16.15,100.10,0.314
16.17,100.29,0.314
16.19,100.47,0.314
16.21,100.65,0.315
16.23,100.84,0.315
16.24,101.02,0.315
16.26,101.21,0.315
16.28,101.39,0.315
16.30,101.57,0.315
16.32,101.76,0.315
16.33,101.94,0.315
16.35,102.12,0.315
16.37,102.31,0.315
16.39,102.49,0.315
16.41,102.67,0.316
16.43,102.86,0.316
16.45,103.04,0.316
16.46,103.22,0.316
16.48,103.41,0.316
16.50,103.59,0.316
16.52,103.78,0.316
16.54,103.96,0.316
16.55,104.14,0.316
16.57,104.33,0.316
16.59,104.51,0.316
16.61,104.69,0.316
16.63,104.87,0.316
16.65,105.06,0.317
16.67,105.24,0.317
16.68,105.43,0.317
16.70,105.61,0.317
16.72,105.79,0.317
16.74,105.98,0.317
16.76,106.16,0.317
16.78,106.34,0.317
16.79,106.53,0.317
16.81,106.71,0.317
16.83,106.89,0.317
16.85,107.08,0.317
16.87,107.26,0.317
16.88,107.44,0.318
16.90,107.63,0.318
16.92,107.81,0.318
16.94,108.00,0.318
16.96,108.18,0.318
16.98,108.36,0.318
17.00,108.55,0.318
17.01,108.73,0.318
17.03,108.91,0.318
17.05,109.10,0.318
17.07,109.28,0.318
17.09,109.46,0.319
17.11,109.65,0.319
17.12,109.83,0.319
17.14,110.01,0.319
17.16,110.20,0.319
17.18,110.38,0.319
17.20,110.56,0.319
17.22,110.75,0.319
17.23,110.93,0.319
17.25,111.11,0.319
17.27,111.30,0.319
17.29,111.48,0.319
17.31,111.66,0.319
17.33,111.85,0.319
17.34,112.03,0.320
17.36,112.22,0.320
17.38,112.40,0.320
17.40,112.58,0.320
17.42,112.77,0.320
17.43,112.95,0.320
17.45,113.13,0.320
17.47,113.32,0.320
17.49,113.50,0.320
17.51,113.68,0.320
17.53,113.87,0.320
17.54,114.05,0.320
17.56,114.24,0.320
17.58,114.42,0.320
17.60,114.60,0.320
17.62,114.79,0.321
17.64,114.97,0.321
17.66,115.15,0.321
17.67,115.34,0.321
17.69,115.52,0.321
17.71,115.70,0.321
17.73,115.89,0.321
17.75,116.07,0.321
17.77,116.25,0.321
17.78,116.44,0.321
17.80,116.62,0.321
17.82,116.80,0.322
17.84,116.99,0.322
17.86,117.17,0.322
17.88,117.36,0.322
17.89,117.54,0.322
17.91,117.72,0.322
17.93,117.91,0.322
17.95,118.09,0.322
17.97,118.27,0.322
17.98,118.46,0.322
18.00,118.64,0.322
18.02,118.82,0.322
18.04,119.01,0.322
18.06,119.19,0.323
18.08,119.37,0.323
18.09,119.56,0.323
18.11,119.74,0.323
18.13,119.93,0.323
18.15,120.11,0.323
18.17,120.29,0.323
18.19,120.47,0.323
18.21,120.66,0.323
18.22,120.84,0.323
18.24,121.02,0.323
18.26,121.21,0.323
18.28,121.39,0.323
18.30,121.58,0.323
18.32,121.76,0.323
18.33,121.94,0.323
18.35,122.13,0.324
18.37,122.31,0.324
18.39,122.49,0.324
18.41,122.68,0.324
18.43,122.86,0.324
18.44,123.04,0.324
18.46,123.23,0.324
18.48,123.41,0.324
18.50,123.59,0.324
18.52,123.78,0.324
18.53,123.96,0.324
18.55,124.14,0.324
18.57,124.33,0.324
18.59,124.51,0.325
18.61,124.69,0.325
18.63,124.88,0.325
18.64,125.06,0.325
18.66,125.24,0.325
18.68,125.43,0.325
18.70,125.61,0.325
18.72,125.79,0.325
18.74,125.98,0.325
18.76,126.16,0.325
18.77,126.34,0.325
18.79,126.53,0.325
18.81,126.71,0.325
18.83,126.89,0.326
18.85,127.08,0.326
18.87,127.26,0.326
18.88,127.45,0.326
18.90,127.63,0.326
18.92,127.81,0.326
18.94,128.00,0.326
18.96,128.18,0.326
18.98,128.36,0.326
18.99,128.55,0.326
19.01,128.73,0.327
19.03,128.91,0.327
19.05,129.10,0.327
19.07,129.28,0.327
19.08,129.47,0.327
19.10,129.65,0.327
19.12,129.83,0.327
19.14,130.02,0.327
19.16,130.20,0.327
19.18,130.38,0.328
19.19,130.57,0.328
19.21,130.75,0.328
19.23,130.93,0.328
19.25,131.12,0.328
19.27,131.30,0.328
19.29,131.48,0.328
19.31,131.67,0.328
19.32,131.85,0.329
19.34,132.04,0.329
19.36,132.22,0.329
19.38,132.40,0.329
19.40,132.59,0.329
19.42,132.77,0.329
19.43,132.96,0.329
19.45,133.14,0.330
19.47,133.33,0.330
19.49,133.51,0.330
19.51,133.70,0.331
19.53,133.88,0.331
19.54,134.06,0.331
19.56,134.24,0.331
19.58,134.43,0.331
19.60,134.61,0.331
19.62,134.80,0.331
19.63,134.98,0.331
19.65,135.16,0.331
19.67,135.34,0.331
19.69,135.53,0.331
19.71,135.71,0.332
19.73,135.89,0.332
19.74,136.08,0.332
19.76,136.26,0.332
19.78,136.44,0.332
19.80,136.63,0.332
19.82,136.81,0.332
19.84,136.99,0.332
19.86,137.17,0.332
19.87,137.36,0.332
19.89,137.54,0.332
19.91,137.72,0.332
19.93,137.91,0.332
19.95,138.09,0.333
19.97,138.27,0.333
19.98,138.46,0.333
20.00,138.64,0.333
20.02,138.82,0.333
20.04,139.01,0.334
20.06,139.19,0.334
20.08,139.37,0.334
20.09,139.56,0.334
20.11,139.74,0.334
20.13,139.92,0.335
20.15,140.11,0.335
20.17,140.29,0.335
20.18,140.47,0.336
20.20,140.66,0.336
20.22,140.84,0.336
20.24,141.02,0.337
20.26,141.21,0.337
20.28,141.39,0.337
20.29,141.57,0.337
20.31,141.76,0.338
20.33,141.94,0.338
20.35,142.12,0.338
20.37,142.31,0.338
20.39,142.49,0.339
20.41,142.67,0.339
20.42,142.86,0.339
20.44,143.04,0.339
20.46,143.22,0.340
20.48,143.41,0.340
20.50,143.59,0.340
20.52,143.77,0.341
20.53,143.96,0.341
20.55,144.14,0.341
20.57,144.32,0.341
20.59,144.51,0.342
20.61,144.69,0.342
20.63,144.87,0.342
20.64,145.06,0.342
20.66,145.24,0.343
20.68,145.42,0.343
20.70,145.61,0.344
20.72,145.79,0.344
20.73,145.97,0.344
20.75,146.16,0.345
20.77,146.34,0.345
20.79,146.52,0.345
20.81,146.71,0.346
20.83,146.89,0.347
20.84,147.07,0.347
20.86,147.26,0.348
20.88,147.44,0.349
20.90,147.62,0.349
20.92,147.81,0.350
20.94,147.99,0.351
20.96,148.17,0.352
20.97,148.36,0.352
20.99,148.54,0.353
21.01,148.72,0.354
21.03,148.91,0.356
21.05,149.09,0.356
21.07,149.27,0.358
21.08,149.45,0.360
21.10,149.64,0.361
21.12,149.82,0.364
21.14,150.00,0.365
21.16,150.19,0.368
21.18,150.37,0.371
21.19,150.55,0.374
21.21,150.73,0.376
21.23,150.92,0.379
21.25,151.10,0.383
21.27,151.28,0.386
21.28,151.47,0.389
21.30,151.65,0.393
21.32,151.83,0.397
21.34,152.01,0.402
21.36,152.19,0.407
21.38,152.38,0.414
21.39,152.56,0.418
21.41,152.74,0.424
21.43,152.92,0.431
21.45,153.10,0.439
21.47,153.28,0.447
21.49,153.46,0.458
21.51,153.64,0.467
21.52,153.82,0.478
21.54,154.00,0.490
21.56,154.18,0.503
21.58,154.37,0.517
21.60,154.54,0.532
21.62,154.72,0.547
21.63,154.90,0.564
21.65,155.08,0.582
21.67,155.26,0.598
21.69,155.43,0.615
21.71,155.61,0.631
21.73,155.79,0.644
21.74,155.97,0.656
21.76,156.15,0.668
21.78,156.33,0.679
21.80,156.51,0.687
21.82,156.68,0.695
21.83,156.87,0.699
21.85,157.05,0.705
21.87,157.23,0.709
21.89,157.41,0.715
21.91,157.59,0.721
21.93,157.77,0.731
21.94,157.95,0.739
21.96,158.13,0.750
21.98,158.31,0.760
22.00,158.49,0.773
22.02,158.67,0.782
22.04,158.85,0.782
22.06,159.04,0.778
22.07,159.22,0.765
22.09,159.41,0.738
22.11,159.60,0.693
22.13,159.79,0.631
22.15,159.99,0.560
22.17,160.19,0.499
22.18,160.39,0.463
22.20,160.59,0.441
22.22,160.78,0.421
22.24,160.98,0.406
22.26,161.17,0.392
22.28,161.36,0.380
22.29,161.55,0.371
22.31,161.73,0.363
22.33,161.92,0.356
22.35,162.11,0.349
22.37,162.29,0.346
22.38,162.48,0.342
22.40,162.67,0.338
22.42,162.85,0.336
22.44,163.04,0.334
22.46,163.22,0.332
22.48,163.41,0.331
22.49,163.59,0.329
22.51,163.78,0.328
22.53,163.96,0.327
22.55,164.15,0.327
22.57,164.33,0.326
22.59,164.51,0.326
22.61,164.70,0.326
22.62,164.88,0.325
22.64,165.07,0.325
22.66,165.25,0.325
22.68,165.43,0.325
22.70,165.62,0.324
22.72,165.80,0.324
22.73,165.98,0.324
22.75,166.17,0.323
22.77,166.35,0.323
22.79,166.53,0.323
22.81,166.72,0.323
22.83,166.90,0.323
22.84,167.08,0.322
22.86,167.27,0.322
22.88,167.45,0.322
22.90,167.64,0.322
22.92,167.82,0.322
22.93,168.00,0.322
22.95,168.19,0.322
22.97,168.37,0.321
22.99,168.55,0.321
23.01,168.74,0.321
23.03,168.92,0.321
23.04,169.10,0.321
23.06,169.29,0.321
23.08,169.47,0.321
23.10,169.65,0.321
23.12,169.84,0.321
23.14,170.02,0.321
23.16,170.20,0.321
23.17,170.39,0.321
23.19,170.57,0.321
23.21,170.75,0.321
23.23,170.94,0.321
23.25,171.12,0.321
23.27,171.30,0.321
23.28,171.49,0.321
23.30,171.67,0.321
23.32,171.86,0.321
23.34,172.04,0.321
23.36,172.22,0.321
23.38,172.41,0.321
23.39,172.59,0.321
23.41,172.77,0.321
23.43,172.96,0.321
23.45,173.14,0.321
23.47,173.32,0.321
23.48,173.51,0.321
23.50,173.69,0.321
23.52,173.87,0.321
23.54,174.06,0.321
23.56,174.24,0.321
23.58,174.42,0.321
23.59,174.61,0.321
23.61,174.79,0.321
23.63,174.97,0.321
23.65,175.16,0.322
23.67,175.34,0.322
23.69,175.52,0.322
23.71,175.71,0.322
23.72,175.89,0.322
23.74,176.07,0.322
23.76,176.26,0.322
23.78,176.44,0.322
23.80,176.62,0.322
23.82,176.81,0.322
23.83,176.99,0.322
23.85,177.17,0.322
23.87,177.36,0.322
23.89,177.54,0.323
23.91,177.73,0.323
23.93,177.91,0.323
23.94,178.09,0.323
23.96,178.28,0.323
23.98,178.46,0.323
24.00,178.64,0.323
24.02,178.83,0.324
24.03,179.01,0.324
24.05,179.19,0.324
24.07,179.38,0.324
24.09,179.56,0.324
24.11,179.74,0.324
24.13,179.93,0.324
24.14,180.11,0.324
24.16,180.29,0.324
24.18,180.48,0.325
24.20,180.66,0.325
24.22,180.84,0.325
24.24,181.03,0.325
24.26,181.21,0.325
24.27,181.39,0.325
24.29,181.58,0.326
24.31,181.76,0.326
24.33,181.94,0.326
24.35,182.13,0.326
24.37,182.31,0.326
24.38,182.50,0.326
24.40,182.68,0.326
24.42,182.86,0.327
24.44,183.05,0.327
24.46,183.23,0.327
24.48,183.41,0.327
24.49,183.60,0.327
24.51,183.78,0.328
24.53,183.96,0.328
24.55,184.15,0.328
24.57,184.33,0.328
24.58,184.51,0.328
24.60,184.70,0.328
24.62,184.88,0.329
24.64,185.06,0.329
24.66,185.24,0.329
24.68,185.43,0.329
24.69,185.61,0.329
24.71,185.80,0.329
24.73,185.98,0.330
24.75,186.16,0.330
24.77,186.35,0.330
24.79,186.53,0.330
24.81,186.71,0.330
24.82,186.90,0.331
24.84,187.08,0.331
24.86,187.26,0.331
24.88,187.45,0.331
24.90,187.63,0.332
24.92,187.81,0.332
24.93,188.00,0.332
24.95,188.18,0.332
24.97,188.36,0.332
24.99,188.55,0.333
25.01,188.73,0.333
25.03,188.91,0.333
25.04,189.10,0.333
25.06,189.28,0.333
25.08,189.46,0.334
25.10,189.65,0.334
25.12,189.83,0.334
25.13,190.01,0.334
25.15,190.20,0.334
25.17,190.38,0.335
25.19,190.56,0.335
25.21,190.75,0.335
25.23,190.93,0.335
25.24,191.11,0.336
25.26,191.30,0.336
25.28,191.48,0.336
25.30,191.66,0.336
25.32,191.85,0.336
25.34,192.03,0.337
25.36,192.21,0.337
25.37,192.40,0.337
25.39,192.58,0.337
25.41,192.77,0.338
25.43,192.95,0.338
25.45,193.13,0.338
25.47,193.32,0.338
25.48,193.50,0.338
25.50,193.68,0.339
25.52,193.87,0.339
25.54,194.05,0.339
25.56,194.23,0.339
25.58,194.42,0.340
25.59,194.60,0.340
25.61,194.78,0.340
25.63,194.97,0.340
25.65,195.15,0.340
25.67,195.33,0.341
25.68,195.52,0.341
25.70,195.70,0.341
25.72,195.88,0.341
25.74,196.06,0.341
25.76,196.25,0.341
25.78,196.43,0.342
25.79,196.62,0.342
25.81,196.80,0.342
25.83,196.98,0.342
25.85,197.17,0.342
25.87,197.35,0.342
25.89,197.53,0.343
25.91,197.72,0.343
25.92,197.90,0.343
25.94,198.08,
25.96,198.27,
25.98,198.45,
25.99,,

[step]
Ramp 10.00 °C/min to -60.00 °C
Time,Temperature,Heat Flow (Normalized)
min,°C,W/g
27.99,200.11,-0.050
28.01,200.11,-0.050
28.03,200.11,-0.050
28.05,200.10,-0.049
28.07,200.07,-0.036
28.08,200.02,-0.028
28.10,199.96,-0.028
28.12,199.87,-0.042
28.14,199.76,-0.076
28.16,199.64,-0.114
28.18,199.51,-0.156
28.19,199.37,-0.197
28.21,199.22,-0.235
28.23,199.07,-0.265
28.25,198.91,-0.293
28.27,198.76,-0.313
28.29,198.59,-0.333
28.31,198.43,-0.349
28.32,198.26,-0.362
28.34,198.09,-0.375
28.36,197.92,-0.384
28.38,197.75,-0.395
28.40,197.57,-0.402
28.42,197.40,-0.408
28.43,197.22,-0.413
28.45,197.04,-0.418
28.47,196.87,-0.422
28.49,196.69,-0.424
28.51,196.51,-0.428
28.53,196.33,-0.430
28.54,196.15,-0.432
28.56,195.97,-0.434
28.58,195.79,-0.436
28.60,195.61,-0.436
28.62,195.43,-0.438
28.63,195.25,-0.438
28.65,195.07,-0.439
28.67,194.89,-0.440
28.69,194.71,-0.441
28.71,194.53,-0.441
28.73,194.35,-0.441
28.74,194.16,-0.442
28.76,193.98,-0.442
28.78,193.80,-0.442
28.80,193.62,-0.442
28.82,193.44,-0.443
28.84,193.26,-0.443
28.86,193.07,-0.443
28.87,192.89,-0.443
28.89,192.71,-0.443
28.91,192.53,-0.444
28.93,192.35,-0.444
28.95,192.16,-0.444
28.97,191.98,-0.444
28.98,191.80,-0.444
29.00,191.62,-0.444
29.02,191.44,-0.445
29.04,191.25,-0.445
29.06,191.07,-0.445
29.08,190.89,-0.445
29.09,190.71,-0.445
29.11,190.52,-0.445
29.13,190.34,-0.445
29.15,190.16,-0.445
29.17,189.98,-0.445
29.18,189.79,-0.445
29.20,189.61,-0.445
29.22,189.43,-0.445
29.24,189.25,-0.445
29.26,189.06,-0.445
29.28,188.88,-0.445
29.29,188.70,-0.445
29.31,188.52,-0.445
29.33,188.33,-0.445
29.35,188.15,-0.445
29.37,187.97,-0.445
29.39,187.79,-0.445
29.41,187.60,-0.445
29.42,187.42,-0.445
29.44,187.24,-0.445
29.46,187.05,-0.445
29.48,186.87,-0.445
29.50,186.69,-0.444
29.52,186.50,-0.444
29.53,186.32,-0.444
29.55,186.14,-0.444
29.57,185.95,-0.444
29.59,185.77,-0.444
29.61,185.59,-0.444
29.63,185.40,-0.444
29.64,185.22,-0.444
29.66,185.04,-0.444
29.68,184.86,-0.444
29.70,184.67,-0.444
29.72,184.49,-0.443
29.73,184.31,-0.443
29.75,184.12,-0.443
29.77,183.94,-0.443
29.79,183.76,-0.443
29.81,183.58,-0.442
29.83,183.39,-0.442
29.84,183.21,-0.442
29.86,183.03,-0.442
29.88,182.84,-0.442
29.90,182.66,-0.442
29.92,182.48,-0.441
29.94,182.29,-0.441
29.96,182.11,-0.441
29.97,181.93,-0.441
29.99,181.74,-0.441
30.01,181.56,-0.441
30.03,181.38,-0.441
30.05,181.20,-0.441
30.07,181.01,-0.441
30.08,180.83,-0.440
30.10,180.65,-0.440
30.12,180.46,-0.440
30.14,180.28,-0.440
30.16,180.10,-0.440
30.18,179.91,-0.440
30.19,179.73,-0.439
30.21,179.55,-0.439
30.23,179.37,-0.439
30.25,179.18,-0.439
30.27,179.00,-0.439
30.28,178.82,-0.439
30.30,178.63,-0.438
30.32,178.45,-0.438
30.34,178.27,-0.438
30.36,178.08,-0.438
30.38,177.90,-0.438
30.39,177.72,-0.438
30.41,177.53,-0.438
30.43,177.35,-0.438
30.45,177.17,-0.437
30.47,176.98,-0.437
30.49,176.80,-0.437
30.51,176.62,-0.437
30.52,176.44,-0.437
30.54,176.25,-0.437
30.56,176.07,-0.437
30.58,175.89,-0.436
30.60,175.70,-0.436
30.62,175.52,-0.436
30.63,175.34,-0.436
30.65,175.15,-0.436
30.67,174.97,-0.436
30.69,174.79,-0.436
30.71,174.61,-0.436
30.73,174.42,-0.435
30.74,174.24,-0.435
30.76,174.06,-0.435
30.78,173.87,-0.435
30.80,173.69,-0.435
30.82,173.51,-0.435
30.83,173.32,-0.435
30.85,173.14,-0.435
30.87,172.96,-0.435
30.89,172.77,-0.434
30.91,172.59,-0.434
30.93,172.41,-0.434
30.94,172.22,-0.434
30.96,172.04,-0.434
30.98,171.86,-0.434
31.00,171.68,-0.433
31.02,171.49,-0.433
31.04,171.31,-0.433
31.06,171.13,-0.433
31.07,170.94,-0.433
31.09,170.76,-0.433
31.11,170.58,-0.433
31.13,170.39,-0.432
31.15,170.21,-0.432
31.17,170.03,-0.432
31.18,169.84,-0.432
31.20,169.66,-0.432
31.22,169.48,-0.432
31.24,169.29,-0.432
31.26,169.11,-0.432
31.28,168.93,-0.432
31.29,168.74,-0.432
31.31,168.56,-0.431
31.33,168.38,-0.431
31.35,168.19,-0.431
31.37,168.01,-0.431
31.38,167.83,-0.431
31.40,167.65,-0.431
31.42,167.46,-0.431
31.44,167.28,-0.430
31.46,167.10,-0.430
31.48,166.91,-0.430
31.49,166.73,-0.430
31.51,166.55,-0.430
31.53,166.36,-0.430
31.55,166.18,-0.430
31.57,166.00,-0.430
31.59,165.82,-0.430
31.61,165.63,-0.429
31.62,165.45,-0.429
31.64,165.27,-0.429
31.66,165.08,-0.429
31.68,164.90,-0.429
31.70,164.72,-0.429
31.72,164.53,-0.429
31.73,164.35,-0.428
31.75,164.17,-0.428
31.77,163.99,-0.428
31.79,163.80,-0.428
31.81,163.62,-0.428
31.83,163.43,-0.428
31.84,163.25,-0.428
31.86,163.07,-0.428
31.88,162.88,-0.428
31.90,162.70,-0.428
31.92,162.52,-0.428
31.93,162.33,-0.428
31.95,162.15,-0.427
31.97,161.97,-0.427
31.99,161.78,-0.427
32.01,161.60,-0.427
32.03,161.42,-0.427
32.04,161.24,-0.427
32.06,161.05,-0.427
32.08,160.87,-0.427
32.10,160.69,-0.427
32.12,160.50,-0.426
32.14,160.32,-0.426
32.16,160.14,-0.426
32.17,159.95,-0.426
32.19,159.77,-0.426
32.21,159.59,-0.426
32.23,159.40,-0.426
32.25,159.22,-0.425
32.27,159.04,-0.425
32.28,158.85,-0.425
32.30,158.67,-0.425
32.32,158.49,-0.425
32.34,158.30,-0.425
32.36,158.12,-0.425
32.38,157.94,-0.425
32.39,157.76,-0.425
32.41,157.57,-0.424
32.43,157.39,-0.424
32.45,157.21,-0.424
32.47,157.02,-0.424
32.48,156.84,-0.424
32.50,156.66,-0.424
32.52,156.48,-0.424
32.54,156.29,-0.424
32.56,156.11,-0.423
32.58,155.92,-0.423
32.59,155.74,-0.423
32.61,155.56,-0.423
32.63,155.38,-0.423
32.65,155.19,-0.423
32.67,155.01,-0.423
32.69,154.83,-0.423
32.71,154.64,-0.423
32.72,154.46,-0.423
32.74,154.28,-0.423
32.76,154.09,-0.422
32.78,153.91,-0.422
32.80,153.73,-0.422
32.82,153.54,-0.422
32.83,153.36,-0.422
32.85,153.18,-0.422
32.87,153.00,-0.422
32.89,152.81,-0.422
32.91,152.63,-0.422
32.93,152.45,-0.422
32.94,152.26,-0.422
32.96,152.08,-0.422
32.98,151.90,-0.421
33.00,151.71,-0.421
33.02,151.53,-0.421
33.03,151.35,-0.421
33.05,151.16,-0.421
33.07,150.98,-0.421
33.09,150.80,-0.421
33.11,150.61,-0.421
33.13,150.43,-0.421
33.14,150.25,-0.421
33.16,150.06,-0.421
33.18,149.88,-0.420
33.20,149.70,-0.420
33.22,149.52,-0.420
33.24,149.33,-0.420
33.26,149.15,-0.420
33.27,148.97,-0.420
33.29,148.78,-0.420
33.31,148.60,-0.420
33.33,148.42,-0.420
33.35,148.23,-0.419
33.37,148.05,-0.419
33.38,147.87,-0.419
33.40,147.68,-0.419
33.42,147.50,-0.419
33.44,147.32,-0.419
33.46,147.13,-0.419
33.48,146.95,-0.419
33.49,146.77,-0.419
33.51,146.58,-0.419
33.53,146.40,-0.418
33.55,146.22,-0.418
33.57,146.03,-0.418
33.58,145.85,-0.418
33.60,145.67,-0.418
33.62,145.49,-0.418
33.64,145.30,-0.418
33.66,145.12,-0.418
33.68,144.94,-0.417
33.69,144.75,-0.417
33.71,144.57,-0.417
33.73,144.39,-0.417
33.75,144.20,-0.417
33.77,144.02,-0.417
33.79,143.84,-0.417
33.81,143.65,-0.417
33.82,143.47,-0.417
33.84,143.29,-0.417
33.86,143.11,-0.417
33.88,142.92,-0.416
33.90,142.74,-0.416
33.92,142.55,-0.416
33.93,142.37,-0.416
33.95,142.19,-0.416
33.97,142.01,-0.416
33.99,141.82,-0.416
34.01,141.64,-0.416
34.03,141.46,-0.416
34.04,141.27,-0.415
34.06,141.09,-0.415
34.08,140.91,-0.415
34.10,140.72,-0.415
34.12,140.54,-0.415
34.14,140.36,-0.415
34.15,140.17,-0.415
34.17,139.99,-0.415
34.19,139.81,-0.415
34.21,139.63,-0.415
34.23,139.44,-0.415
34.24,139.26,-0.414
34.26,139.07,-0.414
34.28,138.89,-0.414
34.30,138.71,-0.414
34.32,138.53,-0.414
34.34,138.34,-0.414
34.36,138.16,-0.414
34.37,137.98,-0.414
34.39,137.79,-0.414
34.41,137.61,-0.413
34.43,137.43,-0.413
34.45,137.25,-0.413
34.46,137.06,-0.413
34.48,136.88,-0.413
34.50,136.70,-0.413
34.52,136.51,-0.412
34.54,136.33,-0.412
34.56,136.14,-0.412
34.58,135.96,-0.412
34.59,135.78,-0.412
34.61,135.59,-0.412
34.63,135.41,-0.412
34.65,135.23,-0.412
34.67,135.04,-0.412
34.69,134.86,-0.412
34.70,134.68,-0.412
34.72,134.50,-0.412
34.74,134.31,-0.411
34.76,134.13,-0.411
34.78,133.95,-0.411
34.79,133.76,-0.411
34.81,133.58,-0.411
34.83,133.40,-0.411
34.85,133.21,-0.411
34.87,133.03,-0.411
34.89,132.85,-0.411
34.91,132.67,-0.411
34.92,132.48,-0.411
34.94,132.30,-0.411
34.96,132.12,-0.410
34.98,131.93,-0.410
35.00,131.75,-0.410
35.01,131.57,-0.410
35.03,131.38,-0.410
35.05,131.20,-0.410
35.07,131.02,-0.410
35.09,130.83,-0.410
35.11,130.65,-0.409
35.13,130.47,-0.409
35.14,130.28,-0.409
35.16,130.10,-0.409
35.18,129.92,-0.409
35.20,129.74,-0.409
35.22,129.55,-0.409
35.24,129.37,-0.409
35.25,129.19,-0.409
[...]
114.08,-40.82,0.156
114.09,-40.76,0.156
114.10,-40.69,0.157
114.10,-40.62,0.157
114.11,-40.56,0.157
114.11,-40.49,0.157
114.12,-40.42,0.157
114.13,-40.36,0.157
114.14,-40.29,0.157
114.14,-40.22,0.157
114.15,-40.16,0.157
114.15,-40.09,0.157
114.16,-40.02,0.157
114.17,-39.96,0.157
114.18,-39.89,0.157
114.18,-39.82,0.157
114.19,-39.76,0.158
114.20,-39.69,0.158
114.20,-39.62,0.158
114.21,-39.56,0.158
114.21,-39.49,0.158
114.22,-39.42,0.158
114.23,-39.36,0.158
114.24,-39.29,0.158
114.24,-39.22,0.158
114.25,-39.15,0.158
114.25,-39.09,0.158
114.26,-39.02,0.158
114.27,-38.95,0.159
114.28,-38.89,0.159
114.28,-38.82,0.159
114.29,-38.75,0.159
114.30,-38.69,0.159
114.30,-38.62,0.159
114.31,-38.55,0.159
114.31,-38.49,0.159
114.32,-38.42,0.159
114.33,-38.35,0.159
114.34,-38.29,0.159
114.34,-38.22,0.159
114.35,-38.15,0.159
114.35,-38.09,0.160
114.36,-38.02,0.160
114.37,-37.95,0.160
114.38,-37.89,0.160
114.38,-37.82,0.160
114.39,-37.75,0.160
114.40,-37.69,0.160
114.40,-37.62,0.160
114.41,-37.55,0.160
114.41,-37.48,0.160
114.42,-37.42,0.160
114.43,-37.35,0.160
114.44,-37.28,0.161
114.44,-37.22,0.161
114.45,-37.15,0.161
114.45,-37.08,0.161
114.46,-37.02,0.161
114.47,-36.95,0.161
114.48,-36.88,0.161
114.48,-36.82,0.161
114.49,-36.75,0.161
114.50,-36.68,0.161
114.50,-36.62,0.161
114.51,-36.55,0.161
114.51,-36.48,0.161
114.52,-36.42,0.161
114.53,-36.35,0.162
114.54,-36.28,0.162
114.54,-36.22,0.162
114.55,-36.15,0.162
114.55,-36.08,0.162
114.56,-36.02,0.162
114.57,-35.95,0.162
114.58,-35.88,0.162
114.58,-35.82,0.162
114.59,-35.75,0.162
114.60,-35.68,0.162
114.60,-35.61,0.162
114.61,-35.55,0.162
114.61,-35.48,0.163
114.62,-35.41,0.163
114.63,-35.35,0.163
114.64,-35.28,0.163
114.64,-35.21,0.163
114.65,-35.15,0.163
114.65,-35.08,0.163
114.66,-35.02,0.163
114.67,-34.95,0.163
114.68,-34.88,0.163
114.68,-34.81,0.163
114.69,-34.75,0.163
114.70,-34.68,0.163
114.70,-34.61,0.164
114.71,-34.55,0.164
114.71,-34.48,0.164
114.72,-34.41,0.164
114.73,-34.35,0.164
114.74,-34.28,0.164
114.74,-34.21,0.164
114.75,-34.15,0.164
114.75,-34.08,0.164
114.76,-34.01,0.164
114.77,-33.95,0.164
114.78,-33.88,0.164
114.78,-33.81,0.164
114.79,-33.75,0.165
114.80,-33.68,0.165
114.80,-33.61,0.165
114.81,-33.55,0.165
114.81,-33.48,0.165
114.82,-33.41,0.165
114.83,-33.35,0.165
114.84,-33.28,0.165
114.84,-33.21,0.165
114.85,-33.15,0.165
114.85,-33.08,0.165
114.86,-33.01,0.165
114.87,-32.95,0.165
114.88,-32.88,0.165
114.88,-32.81,0.166
114.89,-32.75,0.166
114.90,-32.68,0.166
114.90,-32.61,0.166
114.91,-32.54,0.166
114.91,-32.48,0.166
114.92,-32.41,0.166
114.93,-32.35,0.166
114.94,-32.28,0.166
114.94,-32.21,0.166
114.95,-32.15,0.166
114.95,-32.08,0.166
114.96,-32.01,0.166
114.97,-31.94,0.167
114.98,-31.88,0.167
114.98,-31.81,0.167
114.99,-31.75,0.167
115.00,-31.68,0.167
115.00,-31.61,0.167
115.01,-31.54,0.167
115.01,-31.48,0.167
115.02,-31.41,0.167
115.03,-31.35,0.167
115.04,-31.28,0.167
115.04,-31.21,0.167
115.05,-31.14,0.167
115.05,-31.07,0.167
115.06,-31.01,0.167
115.07,-30.94,0.167
115.08,-30.87,0.168
115.08,-30.81,0.168
115.09,-30.74,0.168
115.10,-30.67,0.168
115.10,-30.60,0.168
115.11,-30.54,0.168
115.11,-30.47,0.168
115.12,-30.40,0.168
115.13,-30.34,0.168
115.14,-30.27,0.168
115.14,-30.20,0.169
115.15,-30.14,0.169
115.15,-30.07,0.169
115.16,-30.00,0.169
115.17,-29.94,0.169
115.18,-29.87,0.170
115.18,-29.80,0.170
115.19,-29.74,0.170
115.20,-29.67,0.170
115.20,-29.60,0.170
115.21,-29.54,0.170
115.21,-29.47,0.170
115.22,-29.40,0.170
115.23,-29.34,0.170
115.24,-29.27,0.170
115.24,-29.20,0.171
115.25,-29.13,0.171
115.25,-29.07,0.171
115.26,-29.00,0.171
115.27,-28.93,0.171
115.28,-28.87,0.171
115.28,-28.80,0.171
115.29,-28.73,0.171
115.30,-28.67,0.171
115.30,-28.60,0.172
115.31,-28.53,0.172
115.31,-28.47,0.172
115.32,-28.40,0.172
115.33,-28.34,0.172
115.34,-28.27,0.172
115.34,-28.20,0.172
115.35,-28.13,0.172
115.35,-28.07,0.172
115.36,-28.00,0.172
115.37,-27.94,0.172
115.38,-27.87,0.173
115.38,-27.80,0.173
115.39,-27.74,0.173
115.40,-27.67,0.173
115.40,-27.60,0.173
115.41,-27.54,0.173
115.41,-27.47,0.173
115.42,-27.40,0.173
115.43,-27.34,0.173
115.44,-27.27,0.173
115.44,-27.20,0.173
115.45,-27.14,0.173
115.45,-27.07,0.174
115.46,-27.00,0.174
115.47,-26.94,0.174
115.48,-26.87,0.174
115.48,-26.80,0.174
115.49,-26.74,0.174
115.50,-26.67,0.174
115.50,-26.60,0.174
115.51,-26.54,0.174
115.51,-26.47,0.174
115.52,-26.40,0.175
115.53,-26.34,0.175
115.54,-26.27,0.175
115.54,-26.20,0.175
115.55,-26.14,0.175
115.55,-26.07,0.175
115.56,-26.00,0.175
115.57,-25.94,0.175
115.58,-25.87,0.175
115.58,-25.80,0.175
115.59,-25.74,0.176
115.60,-25.67,0.176
115.60,-25.60,0.176
115.61,-25.54,0.176
115.61,-25.47,0.176
115.62,-25.40,0.176
115.63,-25.34,0.176
115.64,-25.27,0.176
115.64,-25.20,0.176
115.65,-25.14,0.177
115.65,-25.07,0.177
115.66,-25.00,0.177
115.67,-24.94,0.177
115.68,-24.87,0.177
115.68,-24.80,0.177
115.69,-24.74,0.177
115.70,-24.67,0.178
115.70,-24.60,0.178
115.71,-24.54,0.178
115.71,-24.47,0.178
115.72,-24.40,0.178
115.73,-24.34,0.178
115.74,-24.27,0.178
115.74,-24.20,0.179
115.75,-24.14,0.179
115.75,-24.07,0.179
115.76,-24.00,0.179
115.77,-23.94,0.179
115.78,-23.87,0.180
115.78,-23.80,0.180
115.79,-23.74,0.180
115.80,-23.67,0.180
115.80,-23.60,0.180
115.81,-23.54,0.180
115.81,-23.47,0.180
115.82,-23.40,0.180
115.83,-23.34,0.180
115.84,-23.27,0.181
115.84,-23.20,0.181
115.85,-23.14,0.181
115.85,-23.07,0.181
115.86,-23.00,0.181
115.87,-22.94,0.181
115.88,-22.87,0.182
115.88,-22.80,0.182
115.89,-22.74,0.182
115.90,-22.67,0.182
115.90,-22.60,0.182
115.91,-22.54,0.182
115.91,-22.47,0.183
115.92,-22.40,0.183
115.93,-22.34,0.183
115.94,-22.27,0.183
115.94,-22.20,0.184
115.95,-22.14,0.184
115.95,-22.07,0.184
115.96,-22.00,0.184
115.97,-21.94,0.184
115.98,-21.87,0.184
115.98,-21.80,0.185
115.99,-21.74,0.185
116.00,-21.67,0.185
116.00,-21.60,0.185
116.01,-21.54,0.185
116.01,-21.47,0.185
116.02,-21.40,0.186
116.03,-21.34,0.186
116.04,-21.27,0.186
116.04,-21.20,0.186
116.05,-21.14,0.186
116.05,-21.07,0.187
116.06,-21.00,0.187
116.07,-20.94,0.187
116.08,-20.87,0.187
116.08,-20.80,0.187
116.09,-20.74,0.188
116.10,-20.67,0.188
116.10,-20.60,0.188
116.11,-20.54,0.188
116.11,-20.47,0.188
116.12,-20.40,0.188
116.13,-20.34,0.189
116.14,-20.27,0.189
116.14,-20.20,0.189
116.15,-20.14,0.189
116.15,-20.07,0.189
116.16,-20.01,0.189
116.17,-19.94,0.190
116.18,-19.87,0.190
116.18,-19.80,0.190
116.19,-19.74,0.190
116.20,-19.67,0.191
116.20,-19.61,0.191
116.21,-19.54,0.191
116.21,-19.47,0.191
116.22,-19.40,0.191
116.23,-19.34,0.192
116.24,-19.27,0.192
116.24,-19.20,0.192
116.25,-19.14,0.193
116.25,-19.07,0.193
116.26,-19.01,0.193
116.27,-18.94,0.194
116.28,-18.87,0.194
116.28,-18.80,0.194
116.29,-18.74,0.194
116.30,-18.67,0.195
116.30,-18.60,0.195
116.31,-18.54,0.195
116.31,-18.47,0.196
116.32,-18.40,0.197
116.33,-18.34,0.197
116.34,-18.27,0.197
116.34,-18.20,0.197
116.35,-18.14,0.198
116.35,-18.07,0.198
116.36,-18.00,0.198
116.37,-17.94,0.198
116.38,-17.87,0.198
116.38,-17.80,0.199
116.39,-17.74,0.199
116.40,-17.67,0.200
116.40,-17.61,0.200
116.41,-17.54,0.200
116.41,-17.47,0.201
116.42,-17.40,0.201
116.43,-17.34,0.201
116.44,-17.27,0.202
116.44,-17.21,0.202
116.45,-17.14,0.202
116.45,-17.07,0.202
116.46,-17.00,0.203
116.47,-16.94,0.203
116.48,-16.87,0.204
116.48,-16.81,0.204
116.49,-16.74,0.204
116.50,-16.67,0.205
116.50,-16.60,0.205
116.51,-16.54,0.205
116.51,-16.47,0.206
116.52,-16.41,0.206
116.53,-16.34,0.206
116.54,-16.27,0.207
116.54,-16.21,0.207
116.55,-16.14,0.208
116.55,-16.07,0.208
116.56,-16.01,0.208
116.57,-15.94,0.209
116.58,-15.87,0.209
116.58,-15.81,0.210
116.59,-15.74,0.210
116.60,-15.67,0.210
116.60,-15.61,0.211
116.61,-15.54,0.211
116.61,-15.47,0.212
116.62,-15.41,0.212
116.63,-15.34,0.212
116.64,-15.27,0.213
116.64,-15.21,0.213
116.65,-15.14,0.214
116.65,-15.07,0.214
116.66,-15.01,0.214
116.67,-14.94,0.214
116.68,-14.87,0.215
116.68,-14.81,0.215
116.69,-14.74,0.216
116.70,-14.68,0.216
116.70,-14.61,0.216
116.71,-14.54,0.217
116.71,-14.47,0.217
116.72,-14.41,0.217
116.73,-14.34,0.218
116.74,-14.27,0.219
116.74,-14.21,0.219
116.75,-14.14,0.219
116.75,-14.08,0.220
116.76,-14.01,0.220
116.77,-13.94,0.221
116.78,-13.88,0.221
116.78,-13.81,0.222
116.79,-13.74,0.222
116.80,-13.68,0.223
116.80,-13.61,0.223
116.81,-13.54,0.223
116.81,-13.48,0.223
116.82,-13.41,0.223
116.83,-13.34,0.224
116.84,-13.28,0.225
116.84,-13.21,0.226
116.85,-13.14,0.226
116.85,-13.08,0.226
116.86,-13.01,0.227
116.87,-12.94,0.227
116.88,-12.88,0.227
116.88,-12.81,0.228
116.89,-12.74,0.229
116.90,-12.68,0.229
116.90,-12.61,0.229
116.91,-12.54,0.229
116.91,-12.48,0.230
116.92,-12.41,0.231
116.93,-12.34,0.231
116.94,-12.28,0.231
116.94,-12.21,0.232
116.95,-12.14,0.232
116.95,-12.08,0.232
116.96,-12.01,0.232
116.97,-11.95,0.233
116.98,-11.88,0.233
116.98,-11.81,0.233
116.99,-11.75,0.234
117.00,-11.68,0.234
117.00,-11.61,0.235
117.01,-11.55,0.235
117.01,-11.48,0.235
117.02,-11.41,0.235
117.03,-11.35,0.236
117.04,-11.28,0.236
117.04,-11.21,0.236
117.05,-11.15,0.237
117.05,-11.08,0.237
117.06,-11.01,0.237
117.07,-10.95,0.237
117.08,-10.88,0.238
117.08,-10.81,0.238
117.09,-10.75,0.239
117.10,-10.68,0.239
117.10,-10.61,0.239
117.11,-10.55,0.240
117.11,-10.48,0.240
117.12,-10.41,0.241
117.13,-10.35,0.241
117.14,-10.28,0.241
117.14,-10.21,0.241
117.15,-10.15,0.242
117.15,-10.08,0.242
117.16,-10.01,0.243
117.17,-9.95,0.243
117.18,-9.88,0.243
117.18,-9.81,0.243
117.19,-9.75,0.244
117.20,-9.68,0.244
117.20,-9.61,0.245
117.21,-9.55,0.245
117.21,-9.48,0.245
117.22,-9.41,0.245
117.23,-9.35,0.245
117.24,-9.28,0.246
117.24,-9.22,0.246
117.25,-9.15,0.246
117.25,-9.08,0.246
117.26,-9.02,0.246
117.27,-8.95,0.246
117.28,-8.88,0.247
117.28,-8.81,0.247
117.29,-8.75,0.247
117.30,-8.68,0.248
117.30,-8.62,0.248
117.31,-8.55,0.248
117.31,-8.48,0.248
117.32,-8.42,0.248
117.33,-8.35,0.248
117.34,-8.28,0.248
117.34,-8.22,0.248
117.35,-8.15,0.249
117.35,-8.08,0.249
117.36,-8.02,0.249
117.37,-7.95,0.249
117.38,-7.88,0.249
117.38,-7.82,0.249
117.39,-7.75,0.249
117.40,-7.68,0.250
117.40,-7.62,0.250
117.41,-7.55,0.250
117.41,-7.48,0.250
117.42,-7.42,0.250
117.43,-7.35,0.250
117.44,-7.28,0.250
117.44,-7.22,0.251
117.45,-7.15,0.251
117.45,-7.08,0.251
117.46,-7.02,0.251
117.47,-6.95,0.251
117.48,-6.88,0.251
117.48,-6.82,0.251
117.49,-6.75,0.251
117.50,-6.68,0.252
117.50,-6.62,0.252
117.51,-6.55,0.252
117.51,-6.48,0.252
117.52,-6.42,0.252
117.53,-6.35,0.252
117.54,-6.28,0.252
117.54,-6.22,0.252
117.55,-6.15,0.252
117.55,-6.08,0.253
117.56,-6.02,0.253
117.57,-5.95,0.253
117.58,-5.88,0.253
117.58,-5.81,0.253
117.59,-5.75,0.253
117.60,-5.68,0.253
117.60,-5.61,0.253
117.61,-5.55,0.253
117.61,-5.48,0.253
117.62,-5.41,0.253
117.63,-5.35,0.253
117.64,-5.28,0.253
117.64,-5.21,0.253
117.65,-5.15,0.254
117.65,-5.08,0.254
117.66,-5.01,0.254
117.67,-4.95,0.254
117.68,-4.88,0.254
117.68,-4.81,0.254
117.69,-4.75,0.254
117.70,-4.68,0.254
117.70,-4.61,0.254
117.71,-4.55,0.254
117.71,-4.48,0.254
117.72,-4.41,0.254
117.73,-4.35,0.254
117.74,-4.28,0.254
117.74,-4.21,0.254
117.75,-4.15,0.254
117.75,-4.08,0.254
117.76,-4.01,0.254
117.77,-3.94,0.254
117.78,-3.88,0.255
117.78,-3.81,0.255
117.79,-3.75,0.255
117.80,-3.68,0.255
117.80,-3.61,0.255
117.81,-3.54,0.255
117.81,-3.48,0.255
117.82,-3.41,0.255
117.83,-3.34,0.255
117.84,-3.28,0.255
117.84,-3.21,0.255
117.85,-3.14,0.255
117.85,-3.08,0.255
117.86,-3.01,0.255
117.87,-2.94,0.255
117.88,-2.88,0.255
117.88,-2.81,0.255
117.89,-2.74,0.255
117.90,-2.68,0.255
117.90,-2.61,0.256
117.91,-2.54,0.256
117.91,-2.48,0.256
117.92,-2.41,0.256
117.93,-2.34,0.256
117.94,-2.28,0.256
117.94,-2.21,0.256
117.95,-2.14,0.256
117.95,-2.07,0.256
117.96,-2.01,0.256
117.97,-1.94,0.256
117.98,-1.87,0.257
117.98,-1.81,0.257
117.99,-1.74,0.257
118.00,-1.67,0.257
118.00,-1.61,0.257
118.01,-1.54,0.257
118.01,-1.47,0.257
118.02,-1.41,0.257
118.03,-1.34,0.258
118.04,-1.27,0.258
118.04,-1.21,0.258
118.05,-1.14,0.258
118.05,-1.07,0.258
118.06,-1.01,0.258
118.07,-0.94,0.258
118.08,-0.88,0.258
118.08,-0.81,0.258
118.09,-0.74,0.258
118.10,-0.68,0.259
118.10,-0.61,0.259
118.11,-0.54,0.259
118.11,-0.48,0.259
118.12,-0.41,0.260
118.13,-0.35,0.260
118.14,-0.28,0.260
118.14,-0.21,0.260
118.15,-0.15,0.260
118.15,-0.08,0.260
118.16,-0.01,0.260
118.17,0.05,0.261
118.18,0.12,0.261
118.18,0.19,0.261
118.19,0.25,0.260
118.20,0.32,0.260
118.20,0.38,0.261
118.21,0.45,0.261
118.21,0.52,0.260
118.22,0.59,0.261
118.23,0.65,0.261
118.24,0.72,0.261
118.24,0.79,0.261
118.25,0.85,0.261
118.25,0.92,0.261
118.26,0.99,0.261
118.27,1.05,0.261
118.28,1.12,0.261
118.28,1.19,0.261
118.29,1.25,0.261
118.30,1.32,0.261
118.30,1.39,0.261
118.31,1.45,0.261
118.31,1.52,0.261
118.32,1.59,0.261
118.33,1.65,0.261
118.34,1.72,0.261
118.34,1.79,0.261
118.35,1.85,0.261
118.35,1.92,0.261
118.36,1.99,0.262
118.37,2.05,0.262
118.38,2.12,0.262
118.38,2.19,0.262
118.39,2.25,0.262
118.40,2.32,0.262
118.40,2.39,0.262
118.41,2.46,0.262
118.41,2.52,0.262
118.42,2.59,0.262
118.43,2.66,0.262
118.44,2.72,0.262
118.44,2.79,0.262
118.45,2.86,0.262
118.45,2.92,0.262
118.46,2.99,0.262
118.47,3.06,0.262
118.48,3.13,0.262
118.48,3.19,0.262
118.49,3.26,0.262
118.50,3.33,0.262
118.50,3.39,0.262
118.51,3.46,0.262
118.51,3.53,0.262
118.52,3.59,0.262
118.53,3.66,0.262
118.54,3.73,0.262
118.54,3.79,0.262
118.55,3.86,0.262
118.55,3.93,0.263
118.56,3.99,0.263
118.57,4.06,0.263
118.58,4.13,0.263
118.58,4.19,0.263
118.59,4.26,0.263
118.60,4.33,0.263
118.60,4.40,0.263
118.61,4.46,0.263
118.61,4.53,0.263
118.62,4.60,0.263
118.63,4.66,0.263
118.64,4.73,0.263
118.64,4.80,0.262
118.65,4.86,0.262
118.65,4.93,0.262
118.66,5.00,0.262
118.67,5.07,0.262
118.68,5.13,0.262
118.68,5.20,0.262
118.69,5.27,0.262
118.70,5.33,0.262
118.70,5.40,0.262
118.71,5.47,0.262
118.71,5.54,0.263
118.72,5.60,0.263
118.73,5.67,0.263
118.74,5.74,0.263
118.74,5.80,0.263
118.75,5.87,0.263
118.75,5.94,0.263
118.76,6.01,0.263
118.77,6.07,0.263
118.78,6.14,0.263
118.78,6.21,0.264
118.79,6.27,0.264
118.80,6.34,0.264
118.80,6.41,0.264
118.81,6.47,0.264
118.81,6.54,0.264
118.82,6.61,0.264
118.83,6.67,0.264
118.84,6.74,0.264
118.84,6.81,0.264
118.85,6.87,0.264
118.85,6.94,0.264
118.86,7.01,0.264
118.87,7.07,0.264
118.88,7.14,0.264
118.88,7.21,0.264
118.89,7.28,0.264
118.90,7.34,0.264
118.90,7.41,0.264
118.91,7.47,0.264
118.91,7.54,0.264
118.92,7.61,0.264
118.93,7.68,0.264
118.94,7.74,0.264
118.94,7.81,0.264
118.95,7.88,0.264
118.95,7.94,0.264
118.96,8.01,0.264
118.97,8.08,0.264
118.98,8.14,0.264
118.98,8.21,0.264
118.99,8.28,0.264
119.00,8.34,0.264
119.00,8.41,0.264
119.01,8.48,0.264
119.01,8.54,0.264
119.02,8.61,0.264
119.03,8.68,0.264
119.04,8.74,0.264
119.04,8.81,0.264
119.05,8.88,0.264
119.05,8.94,0.264
119.06,9.01,0.264
119.07,9.08,0.264
119.08,9.14,0.264
119.08,9.21,0.264
119.09,9.28,0.264
119.10,9.34,0.264
119.10,9.41,0.264
119.11,9.48,0.264
119.11,9.54,0.264
119.12,9.61,0.264
119.13,9.68,0.264
119.14,9.74,0.264
119.14,9.81,0.264
119.15,9.88,0.264
119.15,9.94,0.265
119.16,10.01,0.265
119.17,10.08,0.265
119.18,10.14,0.265
119.18,10.21,0.265
119.19,10.28,0.265
119.20,10.34,0.265
119.20,10.41,0.265
119.21,10.48,0.265
119.21,10.54,0.265
119.22,10.61,0.265
119.23,10.68,0.265
119.24,10.74,0.265
119.24,10.81,0.265
119.25,10.88,0.265
119.25,10.94,0.265
119.26,11.01,0.265
119.27,11.08,0.265
119.28,11.14,0.265
119.28,11.21,0.265
119.29,11.28,0.265
119.30,11.34,0.265
119.30,11.41,0.265
119.31,11.48,0.265
119.31,11.54,0.265
119.32,11.61,0.265
119.33,11.68,0.265
119.34,11.74,0.265
119.34,11.81,0.265
119.35,11.88,0.265
119.35,11.94,0.265
119.36,12.01,0.265
119.37,12.08,0.265
119.38,12.14,0.265
119.38,12.21,0.265
119.39,12.28,0.265
119.40,12.35,0.265
119.40,12.41,0.265
119.41,12.48,0.266
119.41,12.55,0.266
119.42,12.61,0.266
119.43,12.68,0.266
119.44,12.75,0.266
119.44,12.81,0.266
119.45,12.88,0.266
119.45,12.94,0.266
119.46,13.01,0.266
119.47,13.08,0.266
119.48,13.15,0.266
119.48,13.21,0.266
119.49,13.28,0.266
119.50,13.35,0.266
119.50,13.41,0.266
119.51,13.48,0.266
119.51,13.55,0.266
119.52,13.61,0.266
119.53,13.68,0.266
119.54,13.75,0.266
119.54,13.81,0.266
119.55,13.88,0.266
119.55,13.95,0.266
119.56,14.01,0.266
119.57,14.08,0.266
119.58,14.15,0.267
119.58,14.21,0.267
119.59,14.28,0.267
119.60,14.35,0.267
119.60,14.41,0.267
119.61,14.48,0.267
119.61,14.55,0.267
119.62,14.61,0.267
119.63,14.68,0.267
119.64,14.75,0.267
119.64,14.82,0.267
119.65,14.88,0.267
119.65,14.95,0.267
119.66,15.01,0.267
119.67,15.08,0.267
119.68,15.15,0.267
119.68,15.21,0.267
119.69,15.28,0.267
119.70,15.35,0.267
119.70,15.41,0.267
119.71,15.48,0.267
119.71,15.55,0.267
119.72,15.62,0.267
119.73,15.68,0.267
119.74,15.75,0.267
119.74,15.82,0.268
119.75,15.88,0.268
119.75,15.95,0.268
119.76,16.02,0.268
119.77,16.08,0.268
119.78,16.15,0.268
119.78,16.22,0.268
119.79,16.28,0.268
119.80,16.35,0.268
119.80,16.42,0.268
119.81,16.48,0.268
119.81,16.55,0.268
119.82,16.61,0.268
119.83,16.68,0.268
119.84,16.75,0.268
119.84,16.82,0.268
119.85,16.88,0.268
119.85,16.95,0.268
119.86,17.02,0.268
119.87,17.08,0.268
119.88,17.15,0.268
119.88,17.22,0.268
119.89,17.28,0.268
119.90,17.35,0.268
119.90,17.42,0.269
119.91,17.48,0.269
119.91,17.55,0.269
119.92,17.62,0.269
119.93,17.68,0.269
119.94,17.75,0.269
119.94,17.82,0.269
119.95,17.88,0.269
119.95,17.95,0.269
119.96,18.02,0.269
119.97,18.08,0.269
119.98,18.15,0.269
119.98,18.22,0.269
119.99,18.28,0.269
120.00,18.35,0.269
120.00,18.42,0.269
120.01,18.48,0.269
120.01,18.55,0.269
120.02,18.62,0.269
120.03,18.68,0.269
120.04,18.75,0.269
120.04,18.82,0.269
120.05,18.88,0.270
120.05,18.95,0.270
120.06,19.02,0.270
120.07,19.09,0.270
120.08,19.15,0.270
120.08,19.22,0.270
120.09,19.28,0.270
120.10,19.35,0.270
120.10,19.42,0.270
120.11,19.48,0.270
120.11,19.55,0.270
120.12,19.62,0.270
120.13,19.68,0.270
120.14,19.75,0.270
120.14,19.82,0.270
120.15,19.88,0.270
120.15,19.95,0.270
120.16,20.02,0.270
120.17,20.09,0.270
120.18,20.15,0.270
120.18,20.22,0.270
120.19,20.29,0.270
120.20,20.35,0.270
120.20,20.42,0.271
120.21,20.49,0.271
120.21,20.55,0.271
120.22,20.62,0.271
120.23,20.69,0.271
120.24,20.75,0.271
120.24,20.82,0.271
120.25,20.89,0.271
120.25,20.95,0.271
120.26,21.02,0.271
120.27,21.09,0.271
120.28,21.15,0.271
120.28,21.22,0.271
120.29,21.29,0.271
120.30,21.35,0.271
120.30,21.42,0.271
120.31,21.49,0.271
120.31,21.55,0.271
120.32,21.62,0.271
120.33,21.69,0.271
120.34,21.75,0.271
120.34,21.82,0.271
120.35,21.89,0.271
120.35,21.95,0.271
120.36,22.02,0.272
120.37,22.09,0.272
120.38,22.15,0.272
120.38,22.22,0.272
120.39,22.29,0.272
120.40,22.35,0.272
120.40,22.42,0.272
120.41,22.49,0.272
120.41,22.56,0.272
120.42,22.62,0.272
120.43,22.69,0.272
120.44,22.76,0.272
120.44,22.82,0.272
120.45,22.89,0.272
120.45,22.96,0.272
120.46,23.02,0.272
120.47,23.09,0.272
120.48,23.16,0.273
120.48,23.22,0.273
120.49,23.29,0.273
120.50,23.36,0.273
120.50,23.42,0.273
120.51,23.49,0.273
120.51,23.56,0.273
120.52,23.62,0.273
120.53,23.69,0.273
120.54,23.76,0.273
120.54,23.82,0.273
120.55,23.89,0.273
120.55,23.96,0.273
120.56,24.02,0.273
120.57,24.09,0.273
120.58,24.16,0.273
120.58,24.22,0.273
120.59,24.29,0.273
120.60,24.36,0.273
120.60,24.42,0.274
120.61,24.49,0.274
120.61,24.56,0.274
120.62,24.63,0.274
120.63,24.69,0.274
120.64,24.76,0.274
120.64,24.82,0.274
120.65,24.89,0.274
120.65,24.96,0.274
120.66,25.02,0.274
120.67,25.09,0.274
120.68,25.16,0.274
120.68,25.23,0.274
120.69,25.29,0.274
120.70,25.36,0.274
120.70,25.43,0.274
120.71,25.49,0.274
120.71,25.56,0.274
120.72,25.63,0.274
120.73,25.69,0.274
120.74,25.76,0.274
120.74,25.83,0.275
120.75,25.89,0.275
120.75,25.96,0.275
120.76,26.03,0.275
120.77,26.09,0.275
120.78,26.16,0.275
120.78,26.23,0.275
120.79,26.29,0.275
120.80,26.36,0.275
120.80,26.43,0.275
120.81,26.49,0.275
120.81,26.56,0.275
120.82,26.63,0.275
120.83,26.69,0.275
120.84,26.76,0.275
120.84,26.83,0.275
120.85,26.89,0.275
120.85,26.96,0.275
120.86,27.03,0.275
120.87,27.09,0.275
120.88,27.16,0.275
120.88,27.23,0.275
120.89,27.29,0.275
120.90,27.36,0.275
120.90,27.43,0.276
120.91,27.49,0.276
120.91,27.56,0.276
120.92,27.63,0.276
120.93,27.70,0.276
120.94,27.76,0.276
120.94,27.83,
120.95,27.89,
120.95,27.96,
120.96,28.03,
120.97,28.09,
120.98,28.16,
120.98,28.23,
120.99,,
120.99,,