File: DSC/2025_05_21_THC_Pro_Sonic_n60C_150C_5Cmin_x3.csv
Filename,2025_05_21_THC_Pro_Sonic_n60C_150C_5Cmin_x3
Instrument name,DSC2A-00468 (192.168.1.100)
Operator,Yarger
rundate,5/21/2025
Sample name,2025_05_21_THC_Pro_Sonic_n60C_150C_5Cmin_x3
proceduresegments,Data Off ; Equilibrate -60.00 °C; Data On ; Ramp 5.00 °C/min to 150.00 °C; Data Off ; Isothermal 1.0 min; Data On ; Ramp 5.00 °C/min to -60.00 °C; Data Off ; Isothermal 1.0 min; Data On ; Ramp 5.00 °C/min to 150.00 °C; Data Off ; Isothermal 1.0 min; Data On ; Ramp 5.00 °C/min to -60.00 °C; Data Off ; Isothermal 1.0 min; Data On ; Ramp 5.00 °C/min to 30.00 °C
[File Parameters]
Run date,5/21/2025 2:40:28 PM
Trios version,5.1.1.46572
Original File Name,
Current File Name,D:\DSC2500\JYarger\2025_05_21_THC_Pro_Sonic_n60C_150C_5Cmin_x3.tri
[Procedure]
Procedure Name,THC_Pro_n60C_150C_5Cmin_x3
Sample Name,2025_05_21_THC_Pro_Sonic_n60C_150C_5Cmin_x3
Sample Mass,3.6 mg
Reference Sample Mass,0 mg
Pan Mass,57.11 mg
Pan Number,52
Reference Pan Mass,57.13 mg
Reference Pan Number,37
Pan Type,Tzero Aluminum Hermetic
Comments,Al Hermetic DSC Consumables sealed Pan/Lid. Y2 Tray (Google Sheet: DSC_Samples_Vext_Y2_Tray_May2025)
Project Name,CA
Operator,Yarger
Test,Custom
Unload Max Temperature,30
Unload Min Temperature,30
Load Max Temperature,30
Load Min Temperature,30
Stop on Gas Flow Error,Yes
[Signal List]
Signal #1,Time (min)
Signal #2,Temperature (°C)
Signal #3,Heat Flow (mW)
Signal #4,Delta T (µV)
Signal #5,Delta Tzero (µV)
Signal #6,Tzero Temperature (°C)
Signal #7,Cell Purge (mL/min)
Signal #8,Heater Temp (°C)
Signal #9,Power Delivered (W)
Signal #10,Reference Junction Temperature (°C)
Signal #11,Flange Temperature (°C)
Signal #12,Heat Flow Phase (rad)
Signal #13,Total Heat Capacity (J/°C)
Signal #14,Heat Capacity (J/°C)
[Configuration]
Company Name,ASU
Instrument Name,DSC2A-00468
Instrument Type,DSC2500
Serial Number,DSC2A-00468
IP,192.168.1.100
Location of Instrument,MRRC
DisplayType,Unknown
Sample Interval ,0.1 s/pt
Selected Heat Flow,T4P
Exotherm Direction,Down
Cell Serial,DRC2-00792
Lid Type,Standard
Cooler,RCS 90
Leave Cooler on at End of Sequence,On
Gas 2,Nitrogen
Gas Selected,Channel 1
Flow Rate,50 mL/min
Secondary Purge,On
Licensed Heat Flow,Heat Flow T4P
Modulation Licensed,Yes
[Versions]
Common IDD Version,1
Cortex Version,VER 2.10.2.31
Driver,5.0.0.6
GDM Version,1.0.3.3
TouchscreenVersion,1.0.0.16145
FEP Version,1.2.1.21
FEP Bootloader,2.0.0.5
AutoSampler Version,2.1.1.26
Auto Sampler Bootloader,2.0.0.5
FCM Version,1.1.0.3
FCM Bootloader,2.0.0.5
[Experiment Logs]
Experiment Log Entry # 1,Data On set to 0
Experiment Log Entry # 3,Equilibrate Segment -60 (C) Started
Experiment Log Entry # 5,Air Cool is off.
Experiment Log Entry # 7,Data On set to 1
Experiment Log Entry # 9,Ramp Segment 5 C/min to 150 Started
Experiment Log Entry # 11,Data On set to 0
Experiment Log Entry # 13,Isothermal Segment 1 min started
Experiment Log Entry # 15,Data On set to 1
Experiment Log Entry # 17,Ramp Segment 5 C/min to -60 Started
Experiment Log Entry # 19,Data On set to 0
Experiment Log Entry # 21,Isothermal Segment 1 min started
Experiment Log Entry # 23,Data On set to 1
Experiment Log Entry # 25,Ramp Segment 5 C/min to 150 Started
Experiment Log Entry # 27,Data On set to 0
Experiment Log Entry # 29,Isothermal Segment 1 min started
Experiment Log Entry # 31,Data On set to 1
Experiment Log Entry # 33,Ramp Segment 5 C/min to -60 Started
Experiment Log Entry # 35,FEP has detected that FCM has gone offline
Experiment Log Entry # 37,Data On set to 0
Experiment Log Entry # 39,Isothermal Segment 1 min started
Experiment Log Entry # 41,Data On set to 1
Experiment Log Entry # 43,Ramp Segment 5 C/min to 30 Started
[Method Log]
Method Log Entry # 1,Data Off
Method Log Entry # 2,Equilibrate -60 °C
Method Log Entry # 3,Data On
Method Log Entry # 4,(Ramp 300356) Ramp 5 °C/minute to 150 °C
Method Log Entry # 5,Data Off
Method Log Entry # 6,Isothermal 1 minutes
Method Log Entry # 7,Data On
Method Log Entry # 8,(Ramp 300360) Ramp 5 °C/minute to -60 °C
Method Log Entry # 9,Data Off
Method Log Entry # 10,Isothermal 1 minutes
Method Log Entry # 11,Data On
Method Log Entry # 12,(Ramp 300364) Ramp 5 °C/minute to 150 °C
Method Log Entry # 13,Data Off
Method Log Entry # 14,Isothermal 1 minutes
Method Log Entry # 15,Data On
Method Log Entry # 16,(Ramp 300368) Ramp 5 °C/minute to -60 °C
Method Log Entry # 17,Data Off
Method Log Entry # 18,Isothermal 1 minutes
Method Log Entry # 19,Data On
Method Log Entry # 20,(Ramp 300372) Ramp 5 °C/minute to 30 °C
Cell Serial,DRC2-00792
[T1 Calibration]
Slope,-0.008529666
Offset,9.636258
Initial Temperature,98.23
GUID,f8bfdadc-4977-4fdf-ba6d-0ba9134940c3
[TZero Calibration]
Date Applied,11/29/2022 4:06:13 PM
Description,From -89.059 °C to 396.009 °C at 20.000°C/min
Gas Type,Nitrogen
Pan Type,None
Source Files 1,C:\Users\yargerlab\Desktop\DSC Data\General\TZero_calibration_11_29_22_2nd(2).tri
Source Files 2,C:\Users\yargerlab\Desktop\DSC Data\General\TZero_calibration_11_29_22_2nd(3).tri
Delta T Offset,13.05235
Delta T Slope,-0.007271007
Delta T0 Offset,-13.69128
Delta T0 Slope,0.06063341
[Temperature Calibration]
Date Applied,11/29/2022 7:12:28 PM
Description,From 106.590 °C to 186.590 °C at 10.000°C/min
Gas Type,Nitrogen
Pan Type,Tzero Aluminum Hermetic
Source Files 1,C:\Users\yargerlab\Desktop\DSC Data\General\Indium(6).tri
Measured 1,157.391
Known 1,156.598
[Cell Constant Calibration]
Date Applied,11/29/2022 7:12:29 PM
Description,From 106.590 °C to 186.590 °C at 10.000°C/min
Gas Type,Nitrogen
Pan Type,Tzero Aluminum Hermetic
Source Files 1,C:\Users\yargerlab\Desktop\DSC Data\General\Indium(6).tri
T4P KCell,1.006051
Onset Slope,63.26126 mW/°C
[Direct Cp Calibration]
Date Applied,11/30/2022 11:04:51 AM
Description,From -79.983 °C to 298.409 °C at 10.000°C/min
Gas Type,Nitrogen
Pan Type,Tzero Aluminum Hermetic
Source Files 1,C:\Users\yargerlab\Desktop\DSC Data\General\Sapphire_Heat_Capacity_11_30_22.tri
[Rev Cp Calibration]
Date Applied,11/30/2022 1:58:51 PM
Description,From -79.996 °C to 292.812 °C at 3.000°C/min
Gas Type,Nitrogen
Pan Type,Tzero Aluminum Hermetic
Source Files 1,C:\Users\yargerlab\Desktop\DSC Data\General\Sapphire_MDSC_Calibration_11_30_22.tri
[step]
Ramp 5.00 °C/min to 150.00 °C
Time,Temperature,Heat Flow (Normalized)
min,°C,W/g
0.00,-59.69,-0.050
0.03,-59.71,-0.049
0.06,-59.71,-0.037
0.08,-59.69,-0.007
0.11,-59.64,0.022
0.14,-59.57,0.049
0.17,-59.48,0.068
0.20,-59.38,0.080
0.23,-59.27,0.088
0.26,-59.15,0.095
0.28,-59.03,0.100
0.31,-58.91,0.105
0.34,-58.79,0.109
0.37,-58.66,0.112
0.40,-58.53,0.114
0.43,-58.40,0.115
0.45,-58.26,0.116
0.48,-58.13,0.117
0.51,-57.99,0.118
0.54,-57.86,0.119
0.57,-57.72,0.120
0.60,-57.58,0.121
0.62,-57.45,0.121
0.65,-57.31,0.122
0.68,-57.17,0.123
0.71,-57.03,0.123
0.74,-56.89,0.123
0.77,-56.76,0.124
0.79,-56.62,0.124
0.82,-56.48,0.125
0.85,-56.34,0.125
0.88,-56.20,0.125
0.91,-56.06,0.126
0.93,-55.92,0.126
0.96,-55.78,0.126
0.99,-55.64,0.126
1.02,-55.50,0.126
1.05,-55.36,0.126
1.08,-55.22,0.127
1.11,-55.08,0.127
1.13,-54.94,0.127
1.16,-54.80,0.127
1.19,-54.66,0.127
1.22,-54.52,0.127
1.25,-54.38,0.127
1.28,-54.23,0.127
1.30,-54.09,0.127
1.33,-53.95,0.127
1.36,-53.81,0.127
1.39,-53.67,0.127
1.42,-53.53,0.127
1.44,-53.39,0.127
1.47,-53.25,0.127
1.50,-53.11,0.127
1.53,-52.96,0.127
1.56,-52.82,0.127
1.59,-52.68,0.127
1.62,-52.54,0.126
1.64,-52.40,0.126
1.67,-52.26,0.126
1.70,-52.12,0.126
1.73,-51.98,0.126
1.76,-51.83,0.126
1.78,-51.69,0.126
1.81,-51.55,0.126
1.84,-51.41,0.126
1.87,-51.27,0.126
1.90,-51.13,0.126
1.93,-50.99,0.126
1.96,-50.85,0.126
1.98,-50.70,0.126
2.01,-50.56,0.126
2.04,-50.42,0.126
2.07,-50.28,0.126
2.10,-50.14,0.126
2.13,-50.00,0.126
2.15,-49.86,0.126
2.18,-49.72,0.126
2.21,-49.57,0.126
2.24,-49.43,0.126
2.27,-49.29,0.125
2.29,-49.15,0.125
2.32,-49.01,0.125
2.35,-48.86,0.125
2.38,-48.72,0.125
2.41,-48.58,0.125
2.44,-48.44,0.125
2.46,-48.30,0.125
2.49,-48.16,0.125
2.52,-48.02,0.125
2.55,-47.88,0.125
2.58,-47.73,0.125
2.61,-47.59,0.125
2.64,-47.45,0.125
2.66,-47.31,0.125
2.69,-47.17,0.125
2.72,-47.03,0.125
2.75,-46.89,0.125
2.78,-46.74,0.125
2.81,-46.60,0.125
2.83,-46.46,0.125
2.86,-46.32,0.125
2.89,-46.18,0.125
2.92,-46.04,0.125
2.95,-45.89,0.125
2.98,-45.75,0.125
3.00,-45.61,0.125
3.03,-45.47,0.125
3.06,-45.33,0.125
3.09,-45.19,0.125
3.12,-45.04,0.125
3.14,-44.90,0.125
3.17,-44.76,0.125
3.20,-44.62,0.125
3.23,-44.48,0.124
3.26,-44.33,0.124
3.29,-44.19,0.125
3.31,-44.05,0.124
3.34,-43.91,0.125
3.37,-43.77,0.125
3.40,-43.63,0.125
3.43,-43.49,0.125
3.46,-43.34,0.125
3.49,-43.20,0.125
3.51,-43.06,0.125
3.54,-42.92,0.125
3.57,-42.78,0.125
3.60,-42.64,0.125
3.63,-42.49,0.125
3.66,-42.35,0.125
3.68,-42.21,0.125
3.71,-42.07,0.125
3.74,-41.93,0.125
3.77,-41.78,0.125
3.80,-41.64,0.125
3.83,-41.50,0.125
3.85,-41.36,0.125
3.88,-41.22,0.125
3.91,-41.07,0.125
3.94,-40.93,0.125
3.97,-40.79,0.125
3.99,-40.65,0.125
4.02,-40.51,0.125
4.05,-40.37,0.125
4.08,-40.22,0.125
4.11,-40.08,0.125
4.14,-39.94,0.124
4.16,-39.80,0.125
4.19,-39.66,0.125
4.22,-39.52,0.125
4.25,-39.37,0.125
4.28,-39.23,0.125
4.31,-39.09,0.125
4.34,-38.95,0.125
4.36,-38.81,0.125
4.39,-38.66,0.125
4.42,-38.52,0.124
4.45,-38.38,0.125
4.48,-38.24,0.125
4.50,-38.10,0.125
4.53,-37.95,0.125
4.56,-37.81,0.125
4.59,-37.67,0.125
4.62,-37.53,0.125
4.65,-37.39,0.125
4.68,-37.25,0.125
4.70,-37.10,0.125
4.73,-36.96,0.125
4.76,-36.82,0.125
4.79,-36.68,0.125
4.82,-36.54,0.125
4.85,-36.39,0.125
4.87,-36.25,0.125
4.90,-36.11,0.125
4.93,-35.97,0.125
4.96,-35.83,0.125
4.99,-35.69,0.125
5.01,-35.54,0.125
5.04,-35.40,0.125
5.07,-35.26,0.125
5.10,-35.12,0.125
5.13,-34.98,0.125
5.16,-34.83,0.125
5.19,-34.69,0.125
5.21,-34.55,0.125
5.24,-34.41,0.125
5.27,-34.27,0.125
5.30,-34.12,0.125
5.33,-33.98,0.125
5.35,-33.84,0.125
5.38,-33.70,0.125
5.41,-33.56,0.125
5.44,-33.42,0.125
5.47,-33.27,0.125
5.50,-33.13,0.125
5.53,-32.99,0.125
5.55,-32.85,0.125
5.58,-32.71,0.125
5.61,-32.57,0.125
5.64,-32.42,0.125
5.67,-32.28,0.125
5.70,-32.14,0.125
5.72,-32.00,0.125
5.75,-31.86,0.125
5.78,-31.71,0.125
5.81,-31.57,0.125
5.84,-31.43,0.125
5.86,-31.29,0.125
5.89,-31.15,0.125
5.92,-31.00,0.125
5.95,-30.86,0.125
5.98,-30.72,0.125
6.01,-30.58,0.125
6.04,-30.44,0.125
6.06,-30.29,0.125
6.09,-30.15,0.125
6.12,-30.01,0.125
6.15,-29.87,0.125
6.18,-29.73,0.125
6.20,-29.59,0.125
6.23,-29.44,0.125
6.26,-29.30,0.125
6.29,-29.16,0.125
6.32,-29.02,0.125
6.35,-28.88,0.125
6.38,-28.74,0.125
6.40,-28.60,0.125
6.43,-28.46,0.125
6.46,-28.31,0.126
6.49,-28.17,0.126
6.52,-28.02,0.126
6.55,-27.88,0.126
6.57,-27.74,0.126
6.60,-27.60,0.126
6.63,-27.46,0.126
6.66,-27.32,0.126
6.69,-27.17,0.126
6.71,-27.03,0.126
6.74,-26.89,0.126
6.77,-26.75,0.126
6.80,-26.61,0.126
6.83,-26.46,0.126
6.86,-26.32,0.126
6.89,-26.18,0.126
6.91,-26.04,0.126
6.94,-25.90,0.126
6.97,-25.76,0.126
7.00,-25.61,0.126
7.03,-25.47,0.126
7.05,-25.33,0.126
7.08,-25.19,0.126
7.11,-25.05,0.126
7.14,-24.90,0.126
7.17,-24.76,0.126
7.20,-24.62,0.126
7.23,-24.48,0.126
7.25,-24.34,0.126
7.28,-24.20,0.126
7.31,-24.06,0.126
7.34,-23.92,0.126
7.37,-23.78,0.126
7.40,-23.63,0.126
7.42,-23.49,0.126
7.45,-23.35,0.126
7.48,-23.21,0.126
7.51,-23.06,0.126
7.54,-22.92,0.126
7.56,-22.78,0.126
7.59,-22.64,0.126
7.62,-22.50,0.126
7.65,-22.36,0.126
7.68,-22.21,0.126
7.71,-22.07,0.126
7.74,-21.93,0.127
7.76,-21.79,0.127
7.79,-21.64,0.127
7.82,-21.50,0.127
7.85,-21.36,0.127
7.88,-21.22,0.127
7.90,-21.08,0.127
7.93,-20.94,0.127
7.96,-20.79,0.127
7.99,-20.65,0.127
8.02,-20.51,0.127
8.05,-20.37,0.127
8.08,-20.23,0.127
8.10,-20.08,0.127
8.13,-19.94,0.127
8.16,-19.80,0.127
8.19,-19.66,0.127
8.22,-19.52,0.127
8.25,-19.38,0.127
8.27,-19.23,0.127
8.30,-19.09,0.127
8.33,-18.95,0.127
8.36,-18.81,0.127
8.39,-18.67,0.127
8.41,-18.52,0.127
8.44,-18.38,0.127
8.47,-18.24,0.127
8.50,-18.10,0.127
8.53,-17.96,0.127
8.56,-17.81,0.127
8.58,-17.67,0.127
8.61,-17.53,0.127
8.64,-17.39,0.127
8.67,-17.25,0.127
8.70,-17.11,0.127
8.73,-16.96,0.127
8.75,-16.82,0.127
8.78,-16.68,0.127
8.81,-16.54,0.127
8.84,-16.40,0.127
8.87,-16.26,0.127
8.90,-16.11,0.127
8.93,-15.97,0.127
8.95,-15.83,0.128
8.98,-15.69,0.128
9.01,-15.55,0.128
9.04,-15.41,0.127
9.07,-15.26,0.127
9.10,-15.12,0.128
9.12,-14.98,0.127
9.15,-14.84,0.127
9.18,-14.70,0.128
9.21,-14.55,0.128
9.24,-14.41,0.128
9.27,-14.27,0.128
9.29,-14.13,0.128
9.32,-13.99,0.128
9.35,-13.85,0.128
9.38,-13.70,0.128
9.41,-13.56,0.128
9.43,-13.42,0.128
9.46,-13.28,0.128
9.49,-13.13,0.128
9.52,-12.99,0.128
9.55,-12.85,0.129
9.58,-12.70,0.129
9.60,-12.56,0.128
9.63,-12.42,0.128
9.66,-12.28,0.128
9.69,-12.14,0.128
9.72,-12.00,0.128
9.75,-11.85,0.128
9.78,-11.71,0.128
9.80,-11.57,0.128
9.83,-11.43,0.128
9.86,-11.29,0.128
9.89,-11.15,0.128
9.92,-11.01,0.128
9.95,-10.86,0.128
9.97,-10.72,0.128
10.00,-10.58,0.128
10.03,-10.44,0.128
10.06,-10.30,0.128
10.09,-10.16,0.128
10.12,-10.02,0.128
10.14,-9.87,0.128
10.17,-9.73,0.128
10.20,-9.59,0.128
10.23,-9.45,0.128
10.26,-9.31,0.128
10.28,-9.16,0.128
10.31,-9.02,0.128
10.34,-8.88,0.128
10.37,-8.74,0.129
10.40,-8.60,0.129
10.43,-8.46,0.129
10.45,-8.31,0.129
10.48,-8.17,0.129
10.51,-8.03,0.129
10.54,-7.89,0.129
10.57,-7.75,0.129
10.60,-7.61,0.129
10.63,-7.46,0.129
10.65,-7.32,0.129
10.68,-7.18,0.129
10.71,-7.04,0.129
10.74,-6.90,0.129
10.77,-6.76,0.129
10.80,-6.61,0.129
10.82,-6.47,0.129
10.85,-6.33,0.129
10.88,-6.19,0.129
10.91,-6.05,0.129
10.94,-5.91,0.129
10.97,-5.76,0.129
10.99,-5.62,0.129
11.02,-5.48,0.129
11.05,-5.34,0.129
11.08,-5.20,0.129
11.11,-5.06,0.129
11.13,-4.91,0.129
11.16,-4.77,0.130
11.19,-4.63,0.130
11.22,-4.49,0.130
11.25,-4.35,0.130
11.28,-4.20,0.130
11.30,-4.06,0.130
11.33,-3.92,0.130
11.36,-3.78,0.130
11.39,-3.64,0.130
11.42,-3.49,0.130
11.45,-3.35,0.130
11.48,-3.21,0.130
11.50,-3.07,0.130
11.53,-2.93,0.130
11.56,-2.79,0.130
11.59,-2.64,0.130
11.62,-2.50,0.130
11.65,-2.36,0.130
11.67,-2.22,0.130
11.70,-2.08,0.130
11.73,-1.94,0.130
11.76,-1.79,0.130
11.79,-1.65,0.130
11.82,-1.51,0.131
11.84,-1.37,0.130
11.87,-1.23,0.131
11.90,-1.08,0.130
11.93,-0.94,0.131
11.96,-0.80,0.131
11.98,-0.66,0.131
12.01,-0.52,0.131
12.04,-0.37,0.131
12.07,-0.23,0.131
12.10,-0.09,0.131
12.13,0.05,0.131
12.15,0.19,0.131
12.18,0.33,0.131
12.21,0.47,0.131
12.24,0.62,0.131
12.27,0.76,0.131
12.30,0.90,0.131
12.33,1.04,0.132
12.35,1.18,0.132
12.38,1.32,0.132
12.41,1.47,0.132
12.44,1.61,0.132
12.47,1.75,0.132
12.50,1.89,0.132
12.52,2.03,0.132
12.55,2.18,0.132
12.58,2.32,0.132
12.61,2.46,0.132
12.64,2.60,0.132
12.67,2.74,0.133
12.69,2.89,0.133
12.72,3.03,0.133
12.75,3.17,0.133
12.78,3.31,0.133
12.81,3.45,0.133
12.83,3.60,0.133
12.86,3.74,0.133
12.89,3.88,0.133
12.92,4.02,0.133
12.95,4.16,0.133
12.98,4.30,0.133
13.00,4.44,0.133
13.03,4.59,0.133
13.06,4.73,0.133
13.09,4.87,0.133
13.12,5.01,0.134
13.15,5.15,0.134
13.18,5.30,0.134
13.20,5.44,0.134
13.23,5.58,0.134
13.26,5.72,0.134
13.29,5.86,0.134
13.32,6.00,0.134
13.35,6.15,0.134
13.37,6.29,0.134
13.40,6.43,0.134
13.43,6.57,0.135
13.46,6.71,0.135
13.49,6.85,0.135
13.52,7.00,0.135
13.54,7.14,0.135
13.57,7.28,0.135
13.60,7.42,0.135
13.63,7.56,0.135
13.66,7.70,0.135
13.68,7.85,0.135
13.71,7.99,0.135
13.74,8.13,0.136
13.77,8.27,0.136
13.80,8.41,0.136
13.83,8.56,0.136
13.85,8.70,0.136
13.88,8.84,0.136
13.91,8.98,0.136
13.94,9.12,0.136
13.97,9.27,0.136
14.00,9.41,0.136
14.03,9.55,0.136
14.05,9.69,0.136
14.08,9.83,0.136
14.11,9.97,0.136
14.14,10.12,0.136
14.17,10.26,0.137
14.20,10.40,0.137
14.22,10.54,0.137
14.25,10.68,0.137
14.28,10.82,0.137
14.31,10.97,0.137
14.34,11.11,0.137
14.37,11.25,0.137
14.39,11.39,0.137
14.42,11.53,0.137
14.45,11.68,0.137
14.48,11.82,0.137
14.51,11.96,0.138
14.53,12.10,0.138
14.56,12.24,0.138
14.59,12.38,0.138
14.62,12.53,0.138
14.65,12.67,0.138
14.68,12.81,0.138
14.70,12.95,0.138
14.73,13.09,0.138
14.76,13.24,0.138
14.79,13.38,0.138
14.82,13.52,0.138
14.85,13.66,0.138
14.88,13.80,0.138
14.90,13.94,0.138
14.93,14.09,0.138
14.96,14.23,0.138
14.99,14.37,0.138
15.02,14.51,0.138
15.05,14.65,0.138
15.07,14.79,0.138
15.10,14.94,0.138
15.13,15.08,0.139
15.16,15.22,0.139
15.19,15.36,0.139
15.22,15.50,0.139
15.24,15.64,0.139
15.27,15.79,0.139
15.30,15.93,0.139
15.33,16.07,0.139
15.36,16.21,0.139
15.38,16.35,0.139
15.41,16.49,0.139
15.44,16.64,0.139
15.47,16.78,0.139
15.50,16.92,0.139
15.53,17.06,0.139
15.55,17.20,0.139
15.58,17.35,0.140
15.61,17.49,0.140
15.64,17.63,0.140
15.67,17.77,0.140
15.70,17.91,0.140
15.73,18.05,0.140
15.75,18.20,0.140
15.78,18.34,0.140
15.81,18.48,0.140
15.84,18.62,0.140
15.87,18.76,0.140
15.90,18.91,0.140
15.92,19.05,0.140
15.95,19.19,0.140
15.98,19.33,0.140
16.01,19.47,0.140
16.04,19.61,0.140
16.07,19.76,0.141
16.09,19.90,0.141
16.12,20.04,0.141
16.15,20.18,0.141
16.18,20.32,0.141
16.21,20.46,0.141
16.23,20.61,0.141
16.26,20.75,0.141
16.29,20.89,0.141
16.32,21.03,0.141
16.35,21.17,0.141
16.38,21.31,0.141
16.40,21.46,0.141
16.43,21.60,0.141
16.46,21.74,0.141
16.49,21.88,0.141
16.52,22.02,0.141
16.55,22.16,0.141
16.58,22.31,0.141
16.60,22.45,0.141
16.63,22.59,0.142
16.66,22.73,0.142
16.69,22.87,0.142
16.72,23.02,0.142
16.75,23.16,0.142
16.77,23.30,0.142
16.80,23.44,0.142
16.83,23.58,0.142
16.86,23.72,0.142
16.89,23.87,0.142
16.92,24.01,0.142
16.94,24.15,0.142
16.97,24.29,0.142
17.00,24.43,0.142
17.03,24.58,0.143
17.06,24.72,0.143
17.08,24.86,0.143
17.11,25.00,0.143
17.14,25.14,0.143
17.17,25.28,0.143
17.20,25.43,0.143
17.23,25.57,0.143
17.26,25.71,0.143
17.28,25.85,0.143
17.31,25.99,0.143
17.34,26.13,0.143
17.37,26.28,0.143
17.40,26.42,0.143
17.43,26.56,0.143
17.45,26.70,0.144
17.48,26.84,0.144
17.51,26.99,0.144
17.54,27.13,0.144
17.57,27.27,0.144
17.59,27.41,0.144
17.62,27.55,0.144
17.65,27.69,0.144
17.68,27.84,0.144
17.71,27.98,0.144
17.74,28.12,0.144
17.77,28.26,0.144
17.79,28.40,0.144
17.82,28.54,0.144
17.85,28.69,0.144
17.88,28.83,0.145
17.91,28.97,0.145
17.93,29.11,0.145
17.96,29.25,0.145
17.99,29.40,0.145
18.02,29.54,0.145
18.05,29.68,0.145
18.08,29.82,0.145
18.11,29.96,0.145
18.13,30.11,0.145
18.16,30.25,0.145
18.19,30.39,0.145
18.22,30.53,0.145
18.25,30.67,0.145
18.28,30.81,0.145
18.30,30.96,0.145
18.33,31.10,0.145
18.36,31.24,0.145
18.39,31.38,0.145
18.42,31.52,0.145
18.44,31.67,0.145
18.47,31.81,0.146
18.50,31.95,0.146
18.53,32.09,0.146
18.56,32.23,0.146
18.59,32.37,0.146
18.62,32.51,0.146
18.64,32.66,0.146
18.67,32.80,0.146
18.70,32.94,0.146
18.73,33.08,0.146
18.76,33.22,0.146
18.78,33.37,0.146
18.81,33.51,0.146
18.84,33.65,0.146
18.87,33.79,0.146
18.90,33.93,0.146
18.93,34.07,0.146
18.96,34.22,0.147
18.98,34.36,0.147
19.01,34.50,0.147
19.04,34.64,0.147
19.07,34.78,0.147
19.10,34.92,0.147
19.13,35.07,0.147
19.15,35.21,0.147
19.18,35.35,0.147
19.21,35.49,0.147
19.24,35.63,0.147
19.27,35.78,0.147
19.29,35.92,0.147
19.32,36.06,0.147
19.35,36.20,0.147
19.38,36.34,0.147
19.41,36.48,0.147
19.44,36.63,0.148
19.47,36.77,0.148
19.49,36.91,0.148
19.52,37.05,0.148
19.55,37.19,0.148
19.58,37.34,0.148
19.61,37.48,0.148
19.63,37.62,0.148
19.66,37.76,0.148
19.69,37.90,0.148
19.72,38.04,0.148
19.75,38.18,0.148
19.78,38.33,0.148
19.81,38.47,0.148
19.83,38.61,0.148
19.86,38.75,0.149
19.89,38.89,0.149
19.92,39.04,0.149
19.95,39.18,0.149
19.98,39.32,0.149
20.00,39.46,0.149
20.03,39.60,0.149
20.06,39.74,0.149
20.09,39.89,0.149
20.12,40.03,0.149
20.14,40.17,0.149
20.17,40.31,0.149
20.20,40.45,0.149
20.23,40.59,0.149
20.26,40.74,0.149
20.29,40.88,0.149
20.32,41.02,0.149
20.34,41.16,0.150
20.37,41.30,0.150
20.40,41.45,0.150
20.43,41.59,0.150
20.46,41.73,0.150
20.48,41.87,0.150
20.51,42.01,0.150
20.54,42.16,0.150
20.57,42.30,0.150
20.60,42.44,0.150
20.63,42.58,0.150
20.66,42.72,0.150
20.68,42.86,0.150
20.71,43.01,0.150
20.74,43.15,0.150
20.77,43.29,0.150
20.80,43.43,0.151
20.83,43.57,0.151
20.85,43.72,0.151
20.88,43.86,0.151
20.91,44.00,0.151
20.94,44.14,0.151
20.97,44.28,0.151
20.99,44.42,0.151
21.02,44.57,0.151
21.05,44.71,0.151
21.08,44.85,0.151
21.11,44.99,0.151
21.14,45.13,0.151
21.17,45.28,0.151
21.19,45.42,0.151
21.22,45.56,0.151
21.25,45.70,0.151
21.28,45.84,0.151
21.31,45.98,0.151
21.33,46.13,0.152
21.36,46.27,0.152
21.39,46.41,0.152
21.42,46.55,0.152
21.45,46.69,0.152
21.48,46.83,0.152
21.51,46.97,0.152
21.53,47.12,0.152
21.56,47.26,0.152
21.59,47.40,0.152
21.62,47.54,0.152
21.65,47.68,0.152
21.68,47.83,0.152
21.70,47.97,0.152
21.73,48.11,0.152
21.76,48.25,0.152
21.79,48.39,0.152
21.82,48.53,0.152
21.84,48.67,0.153
21.87,48.82,0.153
21.90,48.96,0.153
21.93,49.10,0.153
21.96,49.24,0.153
21.99,49.38,0.153
22.02,49.53,0.153
22.04,49.67,0.153
22.07,49.81,0.153
22.10,49.95,0.153
22.13,50.09,0.153
22.16,50.23,0.153
22.18,50.38,0.153
22.21,50.52,0.153
22.24,50.66,0.153
22.27,50.80,0.154
22.30,50.94,0.154
22.33,51.08,0.154
22.36,51.23,0.154
22.38,51.37,0.154
22.41,51.51,0.154
22.44,51.65,0.154
22.47,51.79,0.154
22.50,51.94,0.154
22.53,52.08,0.154
22.55,52.22,0.154
22.58,52.36,0.154
22.61,52.50,0.154
22.64,52.64,0.154
22.67,52.79,0.154
22.69,52.93,0.154
22.72,53.07,0.155
22.75,53.21,0.155
22.78,53.35,0.155
22.81,53.49,0.155
22.84,53.64,0.155
22.87,53.78,0.155
22.89,53.92,0.155
22.92,54.06,0.155
22.95,54.20,0.155
22.98,54.35,0.155
23.01,54.49,0.155
23.03,54.63,0.155
23.06,54.77,0.155
23.09,54.91,0.155
23.12,55.05,0.155
23.15,55.20,0.155
23.18,55.34,0.155
23.21,55.48,0.155
23.23,55.62,0.156
23.26,55.76,0.156
23.29,55.90,0.156
23.32,56.05,0.156
23.35,56.19,0.156
23.38,56.33,0.156
23.40,56.47,0.156
23.43,56.61,0.156
23.46,56.76,0.156
23.49,56.90,0.156
23.52,57.04,0.156
23.54,57.18,0.156
23.57,57.32,0.156
23.60,57.47,0.156
23.63,57.61,0.156
23.66,57.75,0.156
23.69,57.89,0.156
23.72,58.03,0.156
23.74,58.17,0.156
23.77,58.31,0.156
23.80,58.46,0.156
23.83,58.60,0.157
23.86,58.74,0.157
23.88,58.88,0.157
23.91,59.02,0.157
23.94,59.16,0.157
23.97,59.31,0.157
24.00,59.45,0.157
24.03,59.59,0.157
24.06,59.73,0.157
24.08,59.87,0.157
24.11,60.01,0.157
24.14,60.16,0.157
24.17,60.30,0.157
24.20,60.44,0.157
24.23,60.58,0.157
24.25,60.73,0.157
24.28,60.87,0.157
24.31,61.01,0.157
24.34,61.15,0.157
24.37,61.29,0.157
24.39,61.43,0.157
24.42,61.57,0.158
24.45,61.72,0.158
24.48,61.86,0.158
24.51,62.00,0.158
24.54,62.14,0.158
24.57,62.28,0.158
24.59,62.42,0.158
24.62,62.57,0.158
24.65,62.71,0.158
24.68,62.85,0.158
24.71,62.99,0.158
24.73,63.13,0.158
24.76,63.28,0.158
24.79,63.42,0.158
24.82,63.56,0.158
24.85,63.70,0.158
24.88,63.84,0.158
24.91,63.99,0.158
24.93,64.13,0.158
24.96,64.27,0.158
24.99,64.41,0.158
25.02,64.55,0.158
25.05,64.69,0.158
25.08,64.83,0.158
25.10,64.98,0.158
25.13,65.12,0.159
25.16,65.26,0.159
25.19,65.40,0.159
25.22,65.54,0.159
25.24,65.68,0.159
25.27,65.83,0.159
25.30,65.97,0.159
25.33,66.11,0.159
25.36,66.25,0.159
25.39,66.39,0.159
25.42,66.53,0.159
25.44,66.68,0.159
25.47,66.82,0.159
25.50,66.96,0.159
25.53,67.10,0.159
25.56,67.25,0.159
25.58,67.39,0.159
25.61,67.53,0.159
25.64,67.67,0.160
25.67,67.81,0.160
25.70,67.95,0.159
25.73,68.10,0.160
25.76,68.24,0.160
25.78,68.38,0.160
25.81,68.52,0.160
25.84,68.66,0.160
25.87,68.80,0.160
25.90,68.95,0.160
25.93,69.09,0.160
25.95,69.23,0.160
25.98,69.37,0.160
26.01,69.51,0.160
26.04,69.65,0.160
26.07,69.80,0.160
26.09,69.94,0.160
26.12,70.08,0.160
26.15,70.22,0.160
26.18,70.36,0.160
26.21,70.51,0.160
26.24,70.65,0.160
26.27,70.79,0.160
26.29,70.93,0.161
26.32,71.07,0.161
26.35,71.21,0.161
26.38,71.36,0.161
26.41,71.50,0.161
26.43,71.64,0.161
26.46,71.78,0.161
26.49,71.92,0.161
26.52,72.06,0.161
26.55,72.21,0.161
26.58,72.35,0.161
26.61,72.49,0.161
26.63,72.63,0.161
26.66,72.77,0.161
26.69,72.91,0.161
26.72,73.06,0.161
26.75,73.20,0.162
26.78,73.34,0.162
26.80,73.48,0.162
26.83,73.62,0.162
26.86,73.77,0.162
26.89,73.91,0.162
26.92,74.05,0.162
26.94,74.19,0.162
26.97,74.33,0.162
27.00,74.47,0.163
27.03,74.62,0.163
27.06,74.76,0.163
27.09,74.90,0.163
27.12,75.04,0.163
27.14,75.18,0.163
27.17,75.32,0.163
27.20,75.47,0.163
27.23,75.61,0.163
27.26,75.75,0.163
27.28,75.89,0.163
27.31,76.03,0.164
27.34,76.17,0.164
27.37,76.32,0.164
27.40,76.46,0.164
27.43,76.60,0.164
27.46,76.74,0.164
27.48,76.88,0.164
27.51,77.02,0.164
27.54,77.17,0.164
27.57,77.31,0.164
27.60,77.45,0.165
27.63,77.59,0.165
27.65,77.73,0.165
27.68,77.88,0.165
27.71,78.02,0.165
27.74,78.16,0.165
27.77,78.30,0.165
27.79,78.44,0.165
27.82,78.59,0.166
27.85,78.73,0.166
27.88,78.87,0.166
27.91,79.01,0.166
27.94,79.15,0.166
27.97,79.29,0.166
27.99,79.44,0.166
28.02,79.58,0.166
28.05,79.72,0.167
28.08,79.86,0.167
28.11,80.00,0.167
28.13,80.14,0.167
28.16,80.28,0.167
28.19,80.43,0.167
28.22,80.57,0.168
28.25,80.71,0.168
28.28,80.85,0.168
28.31,80.99,0.168
28.33,81.14,0.168
28.36,81.28,0.168
28.39,81.42,0.168
28.42,81.56,0.168
28.45,81.70,0.168
28.48,81.84,0.169
28.50,81.99,0.169
28.53,82.13,0.169
28.56,82.27,0.169
28.59,82.41,0.169
28.62,82.55,0.169
28.64,82.69,0.169
28.67,82.84,0.169
28.70,82.98,0.169
28.73,83.12,0.169
28.76,83.26,0.169
28.79,83.40,0.169
28.82,83.54,0.170
28.84,83.69,0.170
28.87,83.83,0.170
28.90,83.97,0.170
28.93,84.11,0.170
28.96,84.25,0.170
28.98,84.39,0.170
29.01,84.54,0.170
29.04,84.68,0.170
29.07,84.82,0.171
29.10,84.96,0.171
29.13,85.10,0.171
29.16,85.25,0.171
29.18,85.39,0.171
29.21,85.53,0.171
29.24,85.67,0.171
29.27,85.81,0.172
29.30,85.96,0.172
29.33,86.10,0.172
29.35,86.24,0.172
29.38,86.38,0.172
29.41,86.52,0.172
29.44,86.66,0.172
29.47,86.80,0.173
29.49,86.95,0.173
29.52,87.09,0.173
29.55,87.23,0.173
29.58,87.37,0.173
29.61,87.51,0.173
29.64,87.65,0.173
29.67,87.80,0.173
29.69,87.94,0.174
29.72,88.08,0.174
29.75,88.22,0.174
29.78,88.36,0.174
29.81,88.51,0.174
29.83,88.65,0.174
29.86,88.79,0.175
29.89,88.93,0.175
29.92,89.07,0.175
29.95,89.21,0.175
29.98,89.35,0.175
30.01,89.50,0.176
30.03,89.64,0.176
30.06,89.78,0.176
30.09,89.92,0.176
30.12,90.06,0.176
30.15,90.21,0.177
30.18,90.35,0.177
30.20,90.49,0.177
30.23,90.63,0.177
30.26,90.77,0.177
30.29,90.91,0.178
30.32,91.06,0.178
30.34,91.20,0.178
30.37,91.34,0.178
30.40,91.48,0.178
30.43,91.62,0.179
30.46,91.77,0.179
30.49,91.91,0.179
30.52,92.05,0.179
30.54,92.19,0.180
30.57,92.33,0.180
30.60,92.47,0.180
30.63,92.61,0.180
30.66,92.76,0.180
30.68,92.90,0.181
30.71,93.04,0.181
30.74,93.18,0.181
30.77,93.32,0.181
30.80,93.46,0.182
30.83,93.61,0.182
30.86,93.75,0.182
30.88,93.89,0.183
30.91,94.03,0.183
30.94,94.17,0.183
30.97,94.31,0.183
31.00,94.46,0.184
31.03,94.60,0.184
31.05,94.74,0.184
31.08,94.88,0.184
31.11,95.02,0.185
31.14,95.16,0.185
31.17,95.31,0.185
31.19,95.45,0.185
31.22,95.59,0.186
31.25,95.73,0.186
31.28,95.87,0.186
31.31,96.01,0.187
31.34,96.15,0.187
31.37,96.30,0.187
31.39,96.44,0.188
31.42,96.58,0.188
31.45,96.72,0.188
31.48,96.86,0.189
31.51,97.01,0.189
31.53,97.15,0.189
31.56,97.29,0.190
31.59,97.43,0.190
31.62,97.57,0.190
31.65,97.71,0.191
31.68,97.86,0.191
31.71,98.00,0.191
31.73,98.14,0.191
31.76,98.28,0.192
31.79,98.42,0.192
31.82,98.56,0.193
31.85,98.70,0.193
31.88,98.85,0.193
31.90,98.99,0.194
31.93,99.13,0.194
31.96,99.27,0.195
31.99,99.41,0.195
32.02,99.56,0.195
32.04,99.70,0.196
32.07,99.84,0.196
32.10,99.98,0.197
32.13,100.12,0.197
32.16,100.26,0.197
32.19,100.41,0.198
32.22,100.55,0.198
32.24,100.69,0.199
32.27,100.83,0.199
32.30,100.97,0.199
32.33,101.11,0.200
32.36,101.26,0.200
32.38,101.40,0.201
32.41,101.54,0.201
32.44,101.68,0.202
32.47,101.82,0.202
32.50,101.96,0.203
32.53,102.11,0.203
32.56,102.25,0.204
32.58,102.39,0.204
32.61,102.53,0.205
32.64,102.67,0.205
32.67,102.81,0.206
32.70,102.96,0.207
32.73,103.10,0.207
32.75,103.24,0.208
32.78,103.38,0.208
32.81,103.52,0.209
32.84,103.66,0.209
32.87,103.80,0.210
32.89,103.95,0.211
32.92,104.09,0.211
32.95,104.23,0.212
32.98,104.37,0.212
33.01,104.51,0.213
33.04,104.65,0.214
33.07,104.80,0.214
33.09,104.94,0.215
33.12,105.08,0.215
33.15,105.22,0.216
33.18,105.36,0.217
33.21,105.50,0.218
33.23,105.64,0.218
33.26,105.79,0.219
33.29,105.93,0.220
33.32,106.07,0.220
33.35,106.21,0.221
33.38,106.35,0.222
33.41,106.49,0.223
33.43,106.64,0.223
33.46,106.78,0.224
33.49,106.92,0.225
33.52,107.06,0.226
33.55,107.20,0.227
33.58,107.34,0.228
33.60,107.48,0.228
33.63,107.63,0.229
33.66,107.77,0.230
33.69,107.91,0.231
33.72,108.05,0.232
33.74,108.19,0.233
33.77,108.33,0.234
33.80,108.48,0.235
33.83,108.62,0.236
33.86,108.76,0.237
33.89,108.90,0.238
33.92,109.04,0.240
33.94,109.18,0.245
33.97,109.32,0.246
34.00,109.46,0.248
34.03,109.61,0.249
34.06,109.75,0.250
34.08,109.89,0.251
34.11,110.03,0.252
34.14,110.17,0.253
34.17,110.31,0.254
34.20,110.45,0.255
34.23,110.60,0.256
34.26,110.74,0.257
34.28,110.88,0.258
34.31,111.02,0.260
34.34,111.16,0.261
34.37,111.30,0.262
34.40,111.45,0.264
34.43,111.59,0.265
34.45,111.73,0.267
34.48,111.87,0.268
34.51,112.01,0.269
34.54,112.15,0.271
34.57,112.29,0.273
34.59,112.43,0.275
34.62,112.58,0.276
34.65,112.72,0.279
34.68,112.86,0.282
34.71,113.00,0.283
34.74,113.14,0.286
34.76,113.28,0.288
34.79,113.42,0.291
34.82,113.56,0.293
34.85,113.71,0.295
34.88,113.85,0.298
34.91,113.99,0.302
34.94,114.13,0.304
34.96,114.27,0.309
34.99,114.41,0.312
35.02,114.55,0.314
35.05,114.69,0.317
35.08,114.83,0.320
35.11,114.98,0.324
35.13,115.12,0.327
35.16,115.26,0.329
35.19,115.40,0.333
35.22,115.54,0.336
35.25,115.68,0.339
35.28,115.82,0.342
35.30,115.96,0.345
35.33,116.10,0.348
35.36,116.24,0.351
35.39,116.39,0.355
35.42,116.53,0.359
35.44,116.67,0.363
35.47,116.81,0.366
35.50,116.95,0.369
35.53,117.09,0.373
35.56,117.23,0.376
35.59,117.37,0.379
35.61,117.51,0.381
35.64,117.65,0.383
35.67,117.80,0.390
35.70,117.94,0.393
35.73,118.08,0.394
35.76,118.22,0.395
35.79,118.36,0.396
35.81,118.50,0.396
35.84,118.64,0.397
35.87,118.78,0.398
35.90,118.93,0.399
35.93,119.07,0.400
35.96,119.21,0.400
35.98,119.35,0.401
36.01,119.49,0.401
36.04,119.64,0.401
36.07,119.78,0.400
36.10,119.92,0.396
36.13,120.06,0.391
36.15,120.21,0.383
36.18,120.35,0.373
36.21,120.49,0.364
36.24,120.64,0.353
36.27,120.78,0.338
36.29,120.92,0.326
36.32,121.07,0.311
36.35,121.21,0.294
36.38,121.36,0.277
36.41,121.51,0.262
36.44,121.65,0.245
36.46,121.80,0.230
36.49,121.94,0.217
36.52,122.09,0.206
36.55,122.23,0.196
36.58,122.37,0.190
36.61,122.52,0.186
36.64,122.66,0.182
36.66,122.80,0.179
36.69,122.95,0.177
36.72,123.09,0.176
36.75,123.23,0.174
36.78,123.37,0.173
36.81,123.52,0.173
36.83,123.66,0.172
36.86,123.80,0.171
36.89,123.94,0.171
36.92,124.08,0.170
36.95,124.22,0.170
36.98,124.37,0.169
37.00,124.51,0.169
37.03,124.65,0.168
37.06,124.79,0.168
37.09,124.93,0.167
37.12,125.07,0.167
37.14,125.22,0.167
37.17,125.36,0.166
37.20,125.50,0.166
37.23,125.64,0.166
37.26,125.79,0.166
37.29,125.93,0.166
37.31,126.07,0.165
37.34,126.21,0.165
37.37,126.35,0.165
37.40,126.49,0.165
37.43,126.63,0.165
37.46,126.78,0.165
37.49,126.92,0.165
37.51,127.06,0.165
37.54,127.20,0.165
37.57,127.34,0.165
37.60,127.49,0.165
37.63,127.63,0.165
37.66,127.77,0.164
37.68,127.91,0.164
37.71,128.05,0.164
37.74,128.20,0.164
37.77,128.34,0.164
37.80,128.48,0.164
37.83,128.62,0.164
37.85,128.76,0.164
37.88,128.90,0.164
37.91,129.05,0.164
37.94,129.19,0.164
37.97,129.33,0.164
37.99,129.47,0.164
38.02,129.61,0.164
38.05,129.75,0.164
38.08,129.89,0.164
38.11,130.04,0.164
38.14,130.18,0.164
38.16,130.32,0.164
38.19,130.46,0.164
38.22,130.60,0.164
38.25,130.75,0.164
38.28,130.89,0.164
38.31,131.03,0.164
38.34,131.17,0.164
38.36,131.31,0.164
38.39,131.45,0.164
38.42,131.60,0.164
38.45,131.74,0.164
38.48,131.88,0.164
38.51,132.02,0.163
38.53,132.16,0.163
38.56,132.30,0.163
38.59,132.45,0.163
38.62,132.59,0.163
38.65,132.73,0.163
38.68,132.87,0.163
38.70,133.01,0.163
38.73,133.16,0.163
38.76,133.30,0.163
38.79,133.44,0.162
38.82,133.58,0.162
38.84,133.72,0.162
38.87,133.86,0.162
38.90,134.01,0.162
38.93,134.15,0.162
38.96,134.29,0.162
38.99,134.43,0.162
39.01,134.57,0.162
39.04,134.71,0.162
39.07,134.86,0.161
39.10,135.00,0.161
39.13,135.14,0.161
39.16,135.28,0.161
39.19,135.42,0.161
39.21,135.56,0.161
39.24,135.71,0.161
39.27,135.85,0.161
39.30,135.99,0.161
39.33,136.13,0.161
39.36,136.27,0.160
39.38,136.41,0.160
39.41,136.56,0.160
39.44,136.70,0.160
39.47,136.84,0.160
39.50,136.98,0.160
39.53,137.12,0.160
39.55,137.27,0.160
39.58,137.41,0.160
39.61,137.55,0.160
39.64,137.69,0.160
39.67,137.83,0.160
39.69,137.97,0.159
39.72,138.12,0.159
39.75,138.26,0.159
39.78,138.40,0.159
39.81,138.54,0.159
39.84,138.68,0.159
39.86,138.83,0.159
39.89,138.97,0.159
39.92,139.11,0.158
39.95,139.25,0.158
39.98,139.39,0.158
40.01,139.53,0.158
40.04,139.68,0.158
40.06,139.82,0.158
40.09,139.96,0.158
40.12,140.10,0.158
40.15,140.24,0.158
40.18,140.38,0.158
40.21,140.52,0.158
40.23,140.67,0.158
40.26,140.81,0.157
40.29,140.95,0.157
40.32,141.09,0.157
40.35,141.23,0.157
40.38,141.38,0.157
40.40,141.52,0.157
40.43,141.66,0.157
40.46,141.80,0.157
40.49,141.94,0.157
40.52,142.09,0.157
40.54,142.23,0.157
40.57,142.37,0.157
40.60,142.51,0.156
40.63,142.65,0.156
40.66,142.79,0.156
40.69,142.93,0.156
40.71,143.08,0.156
40.74,143.22,0.156
40.77,143.36,0.156
40.80,143.50,0.156
40.83,143.64,0.156
40.86,143.79,0.156
40.89,143.93,0.156
40.91,144.07,0.156
40.94,144.21,0.156
40.97,144.35,0.156
41.00,144.49,0.156
41.03,144.64,0.156
41.06,144.78,0.156
41.08,144.92,0.156
41.11,145.06,0.156
41.14,145.20,0.155
41.17,145.34,0.155
41.20,145.49,0.155
41.23,145.63,0.155
41.25,145.77,0.155
41.28,145.91,0.155
41.31,146.05,0.155
41.34,146.19,0.155
41.37,146.34,0.155
41.39,146.48,0.155
41.42,146.62,0.155
41.45,146.76,0.155
41.48,146.90,0.155
41.51,147.05,0.155
41.54,147.19,0.155
41.56,147.33,0.155
41.59,147.47,0.155
41.62,147.61,0.155
41.65,147.75,0.155
41.68,147.90,0.155
41.71,148.04,0.155
41.74,148.18,0.155
41.76,148.32,0.155
41.79,148.46,0.155
41.82,148.60,0.155
41.85,148.75,0.155
41.88,148.89,0.155
41.91,149.03,0.155
41.93,149.17,
41.96,149.31,
41.99,,

[step]
Ramp 5.00 °C/min to -60.00 °C
Time,Temperature,Heat Flow (Normalized)
min,°C,W/g
42.99,150.12,-0.092
43.01,150.12,-0.092
43.04,150.12,-0.094
43.07,150.09,-0.128
43.10,150.04,-0.168
43.13,149.97,-0.209
43.16,149.88,-0.241
43.19,149.77,-0.266
43.21,149.65,-0.282
43.24,149.53,-0.294
43.27,149.41,-0.304
43.30,149.28,-0.310
43.33,149.15,-0.315
43.36,149.02,-0.319
43.38,148.88,-0.322
43.41,148.74,-0.323
43.44,148.61,-0.325
43.47,148.47,-0.327
43.50,148.33,-0.327
43.53,148.19,-0.328
43.55,148.05,-0.328
43.58,147.91,-0.329
43.61,147.78,-0.329
43.64,147.64,-0.330
43.67,147.50,-0.330
43.69,147.36,-0.330
43.72,147.22,-0.331
43.75,147.07,-0.331
43.78,146.93,-0.331
43.81,146.79,-0.331
43.84,146.65,-0.331
43.86,146.51,-0.331
43.89,146.37,-0.331
43.92,146.23,-0.331
43.95,146.09,-0.331
43.98,145.95,-0.331
44.01,145.81,-0.331
44.04,145.67,-0.331
44.06,145.53,-0.330
44.09,145.39,-0.330
44.12,145.25,-0.330
44.15,145.10,-0.330
44.18,144.96,-0.330
44.21,144.82,-0.330
44.23,144.68,-0.329
44.26,144.54,-0.329
44.29,144.40,-0.329
44.32,144.26,-0.329
44.35,144.11,-0.329
44.38,143.97,-0.328
44.40,143.83,-0.328
44.43,143.69,-0.328
44.46,143.55,-0.328
44.49,143.40,-0.328
44.52,143.26,-0.327
44.54,143.12,-0.327
44.57,142.98,-0.327
44.60,142.84,-0.326
44.63,142.70,-0.326
44.66,142.56,-0.325
44.69,142.42,-0.325
44.71,142.27,-0.324
44.74,142.13,-0.324
44.77,141.99,-0.324
44.80,141.85,-0.323
44.83,141.71,-0.323
44.86,141.57,-0.323
44.89,141.42,-0.322
44.91,141.28,-0.322
44.94,141.14,-0.322
44.97,141.00,-0.321
45.00,140.86,-0.321
45.03,140.72,-0.321
45.06,140.58,-0.321
45.08,140.43,-0.320
45.11,140.29,-0.320
45.14,140.15,-0.320
45.17,140.01,-0.319
45.20,139.87,-0.319
45.23,139.73,-0.319
45.25,139.58,-0.319
45.28,139.44,-0.318
45.31,139.30,-0.318
45.34,139.16,-0.317
45.37,139.02,-0.317
45.39,138.88,-0.317
45.42,138.73,-0.317
45.45,138.59,-0.316
45.48,138.45,-0.316
45.51,138.31,-0.316
45.54,138.17,-0.316
45.56,138.03,-0.315
45.59,137.89,-0.315
45.62,137.74,-0.315
45.65,137.60,-0.314
45.68,137.46,-0.314
45.71,137.32,-0.314
45.74,137.18,-0.314
45.76,137.04,-0.313
45.79,136.89,-0.313
45.82,136.75,-0.313
45.85,136.61,-0.313
45.88,136.47,-0.313
45.91,136.33,-0.312
45.93,136.19,-0.312
45.96,136.04,-0.311
45.99,135.90,-0.311
46.02,135.76,-0.311
46.05,135.62,-0.311
46.08,135.48,-0.310
46.10,135.34,-0.310
46.13,135.19,-0.310
46.16,135.05,-0.310
46.19,134.91,-0.310
46.22,134.77,-0.309
46.24,134.63,-0.309
46.27,134.49,-0.309
46.30,134.34,-0.309
46.33,134.20,-0.309
46.36,134.06,-0.308
46.39,133.92,-0.308
46.41,133.78,-0.308
46.44,133.64,-0.308
46.47,133.49,-0.307
46.50,133.35,-0.307
46.53,133.21,-0.307
46.56,133.07,-0.306
46.59,132.93,-0.306
46.61,132.79,-0.306
46.64,132.65,-0.306
46.67,132.50,-0.306
46.70,132.36,-0.306
46.73,132.22,-0.306
46.76,132.08,-0.305
46.78,131.94,-0.305
46.81,131.80,-0.305
46.84,131.65,-0.305
46.87,131.51,-0.304
46.90,131.37,-0.304
46.93,131.23,-0.304
46.95,131.09,-0.304
46.98,130.95,-0.304
47.01,130.80,-0.303
47.04,130.66,-0.303
47.07,130.52,-0.303
47.09,130.38,-0.303
47.12,130.24,-0.303
47.15,130.10,-0.303
47.18,129.95,-0.302
47.21,129.81,-0.302
47.24,129.67,-0.302
47.26,129.53,-0.302
47.29,129.39,-0.302
47.32,129.25,-0.302
47.35,129.11,-0.301
47.38,128.96,-0.301
47.41,128.82,-0.301
47.44,128.68,-0.301
47.46,128.54,-0.301
47.49,128.40,-0.301
47.52,128.25,-0.301
47.55,128.11,-0.300
47.58,127.97,-0.300
47.61,127.83,-0.300
47.63,127.69,-0.300
47.66,127.55,-0.300
47.69,127.41,-0.299
47.72,127.26,-0.299
47.75,127.12,-0.299
47.78,126.98,-0.299
47.80,126.84,-0.299
47.83,126.70,-0.299
47.86,126.56,-0.299
47.89,126.42,-0.299
47.92,126.27,-0.299
47.94,126.13,-0.299
47.97,125.99,-0.298
48.00,125.85,-0.298
48.03,125.71,-0.298
48.06,125.57,-0.298
48.09,125.42,-0.298
48.11,125.28,-0.298
48.14,125.14,-0.298
48.17,125.00,-0.297
48.20,124.86,-0.297
48.23,124.71,-0.297
48.26,124.57,-0.297
48.29,124.43,-0.297
48.31,124.29,-0.297
48.34,124.15,-0.297
48.37,124.01,-0.296
48.40,123.87,-0.296
48.43,123.72,-0.296
48.46,123.58,-0.296
48.48,123.44,-0.296
48.51,123.30,-0.296
48.54,123.16,-0.295
48.57,123.02,-0.296
48.60,122.87,-0.295
48.63,122.73,-0.295
48.65,122.59,-0.295
48.68,122.45,-0.295
48.71,122.31,-0.295
48.74,122.17,-0.295
48.77,122.03,-0.295
48.79,121.88,-0.295
48.82,121.74,-0.294
48.85,121.60,-0.294
48.88,121.46,-0.294
48.91,121.32,-0.294
48.94,121.18,-0.294
48.96,121.03,-0.294
48.99,120.89,-0.294
49.02,120.75,-0.294
49.05,120.61,-0.293
49.08,120.47,-0.293
49.11,120.33,-0.293
49.14,120.19,-0.293
49.16,120.04,-0.293
49.19,119.90,-0.293
49.22,119.76,-0.293
49.25,119.62,-0.293
49.28,119.48,-0.293
49.31,119.33,-0.293
49.33,119.19,-0.292
49.36,119.05,-0.292
49.39,118.91,-0.292
49.42,118.77,-0.292
49.45,118.63,-0.292
49.48,118.49,-0.292
49.50,118.34,-0.292
49.53,118.20,-0.292
49.56,118.06,-0.291
49.59,117.92,-0.292
49.62,117.78,-0.291
49.64,117.63,-0.291
49.67,117.49,-0.291
49.70,117.35,-0.291
49.73,117.21,-0.291
49.76,117.07,-0.291
49.79,116.93,-0.291
49.81,116.79,-0.291
49.84,116.64,-0.291
49.87,116.50,-0.290
49.90,116.36,-0.290
49.93,116.22,-0.290
49.96,116.08,-0.290
49.99,115.94,-0.290
50.01,115.79,-0.290
50.04,115.65,-0.290
50.07,115.51,-0.290
50.10,115.37,-0.290
50.13,115.23,-0.289
50.16,115.09,-0.289
50.18,114.94,-0.289
50.21,114.80,-0.289
50.24,114.66,-0.289
50.27,114.52,-0.289
50.30,114.38,-0.289
50.33,114.24,-0.289
50.35,114.10,-0.289
50.38,113.95,-0.289
50.41,113.81,-0.289
50.44,113.67,-0.289
50.47,113.53,-0.288
50.49,113.39,-0.288
50.52,113.25,-0.288
50.55,113.11,-0.288
50.58,112.96,-0.288
50.61,112.82,-0.288
50.64,112.68,-0.288
50.66,112.54,-0.288
50.69,112.40,-0.288
50.72,112.26,-0.288
50.75,112.11,-0.288
50.78,111.97,-0.287
50.81,111.83,-0.288
50.84,111.69,-0.287
50.86,111.55,-0.287
50.89,111.41,-0.287
50.92,111.26,-0.287
50.95,111.12,-0.287
50.98,110.98,-0.287
51.01,110.84,-0.287
51.03,110.70,-0.287
51.06,110.56,-0.287
51.09,110.41,-0.287
51.12,110.27,-0.287
51.15,110.13,-0.287
51.18,109.99,-0.286
51.20,109.85,-0.286
51.23,109.71,-0.286
51.26,109.56,-0.286
51.29,109.42,-0.286
51.32,109.28,-0.286
51.34,109.14,-0.286
51.37,109.00,-0.286
51.40,108.86,-0.286
51.43,108.71,-0.286
51.46,108.57,-0.286
51.49,108.43,-0.286
51.51,108.29,-0.285
51.54,108.15,-0.285
51.57,108.01,-0.285
51.60,107.87,-0.285
51.63,107.72,-0.285
51.66,107.58,-0.285
51.69,107.44,-0.285
51.71,107.30,-0.285
51.74,107.16,-0.285
51.77,107.02,-0.285
51.80,106.87,-0.285
51.83,106.73,-0.284
51.86,106.59,-0.284
51.88,106.45,-0.284
51.91,106.31,-0.284
51.94,106.17,-0.284
51.97,106.03,-0.284
52.00,105.88,-0.284
52.03,105.74,-0.284
52.05,105.60,-0.284
52.08,105.46,-0.284
52.11,105.32,-0.284
52.14,105.18,-0.284
52.17,105.03,-0.284
52.19,104.89,-0.284
52.22,104.75,-0.284
52.25,104.61,-0.283
52.28,104.47,-0.283
52.31,104.33,-0.283
52.34,104.19,-0.283
52.36,104.04,-0.283
52.39,103.90,-0.283
52.42,103.76,-0.283
[...]
176.16,-39.88,0.127
176.18,-39.82,0.127
176.19,-39.75,0.127
176.20,-39.68,0.127
176.22,-39.62,0.127
176.23,-39.55,0.127
176.24,-39.48,0.127
176.25,-39.42,0.127
176.27,-39.35,0.127
176.28,-39.28,0.127
176.30,-39.22,0.127
176.31,-39.15,0.127
176.32,-39.08,0.127
176.33,-39.02,0.127
176.35,-38.95,0.127
176.36,-38.88,0.127
176.38,-38.82,0.127
176.39,-38.75,0.127
176.40,-38.68,0.127
176.42,-38.62,0.127
176.43,-38.55,0.127
176.44,-38.48,0.127
176.45,-38.42,0.127
176.47,-38.35,0.127
176.48,-38.28,0.127
176.50,-38.22,0.127
176.51,-38.15,0.127
176.52,-38.08,0.127
176.53,-38.02,0.127
176.55,-37.95,0.127
176.56,-37.88,0.127
176.58,-37.81,0.128
176.59,-37.75,0.128
176.60,-37.68,0.128
176.62,-37.61,0.128
176.63,-37.55,0.128
176.64,-37.48,0.128
176.65,-37.42,0.128
176.67,-37.35,0.128
176.68,-37.28,0.128
176.70,-37.21,0.128
176.71,-37.15,0.128
176.72,-37.08,0.128
176.73,-37.01,0.128
176.75,-36.95,0.128
176.76,-36.88,0.128
176.78,-36.81,0.128
176.79,-36.75,0.128
176.80,-36.68,0.128
176.82,-36.61,0.128
176.83,-36.55,0.128
176.84,-36.48,0.128
176.85,-36.41,0.128
176.87,-36.35,0.128
176.88,-36.28,0.128
176.90,-36.21,0.128
176.91,-36.15,0.128
176.92,-36.08,0.128
176.93,-36.01,0.128
176.95,-35.95,0.128
176.96,-35.88,0.128
176.98,-35.81,0.128
176.99,-35.75,0.128
177.00,-35.68,0.128
177.02,-35.61,0.128
177.03,-35.55,0.128
177.04,-35.48,0.128
177.05,-35.41,0.128
177.07,-35.34,0.128
177.08,-35.28,0.128
177.10,-35.21,0.129
177.11,-35.15,0.129
177.12,-35.08,0.129
177.13,-35.01,0.129
177.15,-34.95,0.129
177.16,-34.88,0.129
177.18,-34.81,0.129
177.19,-34.74,0.129
177.20,-34.68,0.129
177.22,-34.61,0.129
177.23,-34.54,0.129
177.24,-34.48,0.129
177.25,-34.41,0.129
177.27,-34.34,0.129
177.28,-34.28,0.129
177.30,-34.21,0.129
177.31,-34.14,0.129
177.32,-34.08,0.129
177.33,-34.01,0.129
177.35,-33.94,0.129
177.36,-33.88,0.129
177.38,-33.81,0.129
177.39,-33.74,0.129
177.40,-33.68,0.129
177.42,-33.61,0.129
177.43,-33.54,0.129
177.44,-33.48,0.129
177.45,-33.41,0.129
177.47,-33.34,0.129
177.48,-33.28,0.129
177.50,-33.21,0.129
177.51,-33.14,0.129
177.52,-33.08,0.129
177.53,-33.01,0.129
177.55,-32.94,0.129
177.56,-32.88,0.129
177.58,-32.81,0.129
177.59,-32.74,0.129
177.60,-32.68,0.129
177.62,-32.61,0.129
177.63,-32.54,0.129
177.64,-32.47,0.129
177.65,-32.41,0.129
177.67,-32.34,0.129
177.68,-32.28,0.129
177.70,-32.21,0.130
177.71,-32.14,0.130
177.72,-32.08,0.130
177.73,-32.01,0.130
177.75,-31.94,0.130
177.76,-31.87,0.130
177.78,-31.81,0.130
177.79,-31.74,0.130
177.80,-31.67,0.130
177.82,-31.61,0.130
177.83,-31.54,0.130
177.84,-31.48,0.130
177.85,-31.41,0.130
177.87,-31.34,0.130
177.88,-31.27,0.130
177.90,-31.21,0.130
177.91,-31.14,0.130
177.92,-31.07,0.130
177.93,-31.01,0.130
177.95,-30.94,0.130
177.96,-30.87,0.130
177.98,-30.81,0.130
177.99,-30.74,0.130
178.00,-30.67,0.130
178.02,-30.61,0.130
178.03,-30.54,0.130
178.04,-30.47,0.130
178.05,-30.41,0.130
178.07,-30.34,0.130
178.08,-30.27,0.130
178.10,-30.21,0.130
178.11,-30.14,0.130
178.12,-30.07,0.130
178.13,-30.01,0.130
178.15,-29.94,0.130
178.16,-29.87,0.130
178.18,-29.81,0.130
178.19,-29.74,0.130
178.20,-29.67,0.130
178.22,-29.61,0.130
178.23,-29.54,0.130
178.24,-29.47,0.130
178.25,-29.41,0.130
178.27,-29.34,0.130
178.28,-29.27,0.130
178.30,-29.21,0.130
178.31,-29.14,0.130
178.32,-29.07,0.130
178.33,-29.01,0.130
178.35,-28.94,0.130
178.36,-28.87,0.130
178.38,-28.81,0.130
178.39,-28.74,0.131
178.40,-28.67,0.131
178.42,-28.61,0.131
178.43,-28.54,0.131
178.44,-28.47,0.131
178.45,-28.41,0.131
178.47,-28.34,0.131
178.48,-28.27,0.131
178.50,-28.20,0.131
178.51,-28.14,0.131
178.52,-28.07,0.131
178.53,-28.01,0.131
178.55,-27.94,0.131
178.56,-27.87,0.131
178.58,-27.80,0.131
178.59,-27.74,0.131
178.60,-27.67,0.131
178.62,-27.60,0.131
178.63,-27.54,0.131
178.64,-27.47,0.131
178.65,-27.40,0.131
178.67,-27.34,0.131
178.68,-27.27,0.131
178.70,-27.20,0.131
178.71,-27.14,0.131
178.72,-27.07,0.131
178.73,-27.00,0.131
178.75,-26.94,0.131
178.76,-26.87,0.131
178.78,-26.80,0.131
178.79,-26.74,0.131
178.80,-26.67,0.131
178.82,-26.60,0.131
178.83,-26.54,0.132
178.84,-26.47,0.132
178.85,-26.40,0.132
178.87,-26.34,0.132
178.88,-26.27,0.132
178.90,-26.20,0.132
178.91,-26.14,0.132
178.92,-26.07,0.132
178.93,-26.00,0.132
178.95,-25.94,0.132
178.96,-25.87,0.132
178.98,-25.80,0.132
178.99,-25.74,0.132
179.00,-25.67,0.132
179.02,-25.60,0.132
179.03,-25.54,0.132
179.04,-25.47,0.132
179.05,-25.40,0.132
179.07,-25.33,0.132
179.08,-25.27,0.132
179.10,-25.20,0.132
179.11,-25.14,0.132
179.12,-25.07,0.132
179.13,-25.00,0.132
179.15,-24.94,0.132
179.16,-24.87,0.132
179.18,-24.80,0.132
179.19,-24.73,0.132
179.20,-24.67,0.132
179.22,-24.60,0.132
179.23,-24.53,0.132
179.24,-24.47,0.132
179.25,-24.40,0.132
179.27,-24.34,0.132
179.28,-24.27,0.132
179.30,-24.20,0.132
179.31,-24.13,0.133
179.32,-24.07,0.133
179.33,-24.00,0.133
179.35,-23.93,0.133
179.36,-23.87,0.133
179.38,-23.80,0.133
179.39,-23.73,0.133
179.40,-23.67,0.133
179.42,-23.60,0.133
179.43,-23.53,0.133
179.44,-23.47,0.133
179.45,-23.40,0.133
179.47,-23.33,0.133
179.48,-23.27,0.133
179.50,-23.20,0.133
179.51,-23.13,0.133
179.52,-23.07,0.133
179.53,-23.00,0.133
179.55,-22.93,0.133
179.56,-22.87,0.133
179.58,-22.80,0.133
179.59,-22.73,0.133
179.60,-22.67,0.133
179.62,-22.60,0.133
179.63,-22.53,0.133
179.64,-22.47,0.133
179.65,-22.40,0.133
179.67,-22.33,0.133
179.68,-22.27,0.133
179.70,-22.20,0.134
179.71,-22.13,0.134
179.72,-22.07,0.134
179.73,-22.00,0.134
179.75,-21.93,0.134
179.76,-21.87,0.134
179.78,-21.80,0.134
179.79,-21.73,0.134
179.80,-21.67,0.134
179.82,-21.60,0.134
179.83,-21.53,0.134
179.84,-21.47,0.134
179.85,-21.40,0.134
179.87,-21.33,0.134
179.88,-21.27,0.134
179.90,-21.20,0.134
179.91,-21.13,0.134
179.92,-21.07,0.134
179.93,-21.00,0.134
179.95,-20.93,0.134
179.96,-20.87,0.134
179.98,-20.80,0.134
179.99,-20.73,0.134
180.00,-20.66,0.134
180.02,-20.60,0.135
180.03,-20.53,0.135
180.04,-20.47,0.135
180.05,-20.40,0.135
180.07,-20.33,0.135
180.08,-20.26,0.135
180.10,-20.20,0.135
180.11,-20.13,0.135
180.12,-20.06,0.135
180.13,-20.00,0.135
180.15,-19.93,0.135
180.16,-19.86,0.135
180.18,-19.80,0.135
180.19,-19.73,0.135
180.20,-19.66,0.135
180.22,-19.60,0.135
180.23,-19.53,0.135
180.24,-19.46,0.135
180.25,-19.40,0.135
180.27,-19.33,0.136
180.28,-19.26,0.136
180.30,-19.19,0.136
180.31,-19.13,0.136
180.32,-19.06,0.136
180.33,-18.99,0.136
180.35,-18.92,0.136
180.36,-18.86,0.136
180.38,-18.79,0.136
180.39,-18.73,0.136
180.40,-18.66,0.136
180.42,-18.59,0.136
180.43,-18.52,0.136
180.44,-18.46,0.136
180.45,-18.39,0.136
180.47,-18.32,0.136
180.48,-18.26,0.136
180.50,-18.19,0.136
180.51,-18.12,0.136
180.52,-18.06,0.136
180.53,-17.99,0.136
180.55,-17.93,0.136
180.56,-17.86,0.136
180.58,-17.79,0.136
180.59,-17.73,0.137
180.60,-17.66,0.137
180.62,-17.59,0.137
180.63,-17.53,0.137
180.64,-17.46,0.137
180.65,-17.39,0.137
180.67,-17.33,0.137
180.68,-17.26,0.137
180.70,-17.19,0.137
180.71,-17.13,0.137
180.72,-17.06,0.137
180.73,-16.99,0.137
180.75,-16.93,0.137
180.76,-16.86,0.137
180.78,-16.79,0.137
180.79,-16.73,0.138
180.80,-16.66,0.138
180.82,-16.59,0.138
180.83,-16.53,0.138
180.84,-16.46,0.138
180.85,-16.39,0.138
180.87,-16.33,0.138
180.88,-16.26,0.138
180.90,-16.19,0.138
180.91,-16.13,0.138
180.92,-16.06,0.138
180.93,-15.99,0.138
180.95,-15.93,0.138
180.96,-15.86,0.138
180.98,-15.79,0.138
180.99,-15.73,0.138
181.00,-15.66,0.139
181.02,-15.59,0.139
181.03,-15.53,0.139
181.04,-15.46,0.139
181.05,-15.39,0.139
181.07,-15.33,0.139
181.08,-15.26,0.139
181.10,-15.19,0.139
181.11,-15.13,0.139
181.12,-15.06,0.139
181.13,-14.99,0.139
181.15,-14.93,0.139
181.16,-14.86,0.140
181.18,-14.79,0.140
181.19,-14.73,0.140
181.20,-14.66,0.140
181.22,-14.59,0.140
181.23,-14.53,0.140
181.24,-14.46,0.140
181.25,-14.39,0.140
181.27,-14.33,0.140
181.28,-14.26,0.140
181.30,-14.19,0.140
181.31,-14.13,0.141
181.32,-14.06,0.141
181.33,-13.99,0.141
181.35,-13.93,0.141
181.36,-13.86,0.141
181.38,-13.79,0.141
181.39,-13.73,0.141
181.40,-13.66,0.141
181.42,-13.59,0.141
181.43,-13.52,0.141
181.44,-13.46,0.141
181.45,-13.39,0.141
181.47,-13.32,0.141
181.48,-13.26,0.142
181.50,-13.19,0.142
181.51,-13.12,0.142
181.52,-13.06,0.142
181.53,-12.99,0.142
181.55,-12.92,0.142
181.56,-12.86,0.142
181.58,-12.79,0.142
181.59,-12.73,0.142
181.60,-12.66,0.142
181.62,-12.59,0.142
181.63,-12.53,0.142
181.64,-12.46,0.143
181.65,-12.39,0.143
181.67,-12.33,0.143
181.68,-12.26,0.143
181.70,-12.19,0.143
181.71,-12.13,0.143
181.72,-12.06,0.143
181.73,-11.99,0.143
181.75,-11.93,0.143
181.76,-11.86,0.143
181.78,-11.79,0.143
181.79,-11.73,0.144
181.80,-11.66,0.144
181.82,-11.59,0.144
181.83,-11.53,0.144
181.84,-11.46,0.144
181.85,-11.39,0.144
181.87,-11.32,0.144
181.88,-11.26,0.144
181.90,-11.19,0.145
181.91,-11.12,0.145
181.92,-11.06,0.145
181.93,-10.99,0.145
181.95,-10.93,0.145
181.96,-10.86,0.145
181.98,-10.79,0.145
181.99,-10.73,0.145
182.00,-10.66,0.145
182.02,-10.59,0.145
182.03,-10.53,0.146
182.04,-10.46,0.146
182.05,-10.39,0.146
182.07,-10.33,0.146
182.08,-10.26,0.146
182.10,-10.19,0.146
182.11,-10.13,0.146
182.12,-10.06,0.146
182.13,-9.99,0.146
182.15,-9.92,0.147
182.16,-9.86,0.147
182.18,-9.79,0.147
182.19,-9.72,0.147
182.20,-9.66,0.147
182.22,-9.59,0.147
182.23,-9.52,0.147
182.24,-9.46,0.147
182.25,-9.39,0.148
182.27,-9.32,0.148
182.28,-9.26,0.148
182.30,-9.19,0.148
182.31,-9.12,0.148
182.32,-9.06,0.148
182.33,-8.99,0.148
182.35,-8.93,0.148
182.36,-8.86,0.148
182.38,-8.79,0.148
182.39,-8.72,0.149
182.40,-8.66,0.149
182.42,-8.59,0.149
182.43,-8.52,0.149
182.44,-8.46,0.149
182.45,-8.39,0.149
182.47,-8.32,0.149
182.48,-8.26,0.149
182.50,-8.19,0.150
182.51,-8.12,0.150
182.52,-8.06,0.150
182.53,-7.99,0.150
182.55,-7.92,0.150
182.56,-7.86,0.150
182.58,-7.79,0.150
182.59,-7.72,0.150
182.60,-7.66,0.151
182.62,-7.59,0.151
182.63,-7.52,0.151
182.64,-7.46,0.151
182.65,-7.39,0.151
182.67,-7.32,0.151
182.68,-7.26,0.151
182.70,-7.19,0.151
182.71,-7.12,0.151
182.72,-7.06,0.152
182.73,-6.99,0.152
182.75,-6.92,0.152
182.76,-6.86,0.152
182.78,-6.79,0.152
182.79,-6.72,0.152
182.80,-6.66,0.152
182.82,-6.59,0.152
182.83,-6.52,0.152
182.84,-6.46,0.153
182.85,-6.39,0.153
182.87,-6.32,0.153
182.88,-6.26,0.153
182.90,-6.19,0.153
182.91,-6.12,0.153
182.92,-6.06,0.153
182.93,-5.99,0.153
182.95,-5.92,0.153
182.96,-5.86,0.154
182.98,-5.79,0.154
182.99,-5.72,0.154
183.00,-5.66,0.154
183.02,-5.59,0.154
183.03,-5.52,0.154
183.04,-5.46,0.154
183.05,-5.39,0.154
183.07,-5.32,0.154
183.08,-5.26,0.155
183.10,-5.19,0.155
183.11,-5.12,0.155
183.12,-5.06,0.155
183.13,-4.99,0.155
183.15,-4.92,0.155
183.16,-4.86,0.155
183.18,-4.79,0.155
183.19,-4.72,0.155
183.20,-4.66,0.155
183.22,-4.59,0.155
183.23,-4.52,0.155
183.24,-4.46,0.155
183.25,-4.39,0.156
183.27,-4.32,0.156
183.28,-4.26,0.156
183.30,-4.19,0.156
183.31,-4.12,0.156
183.32,-4.06,0.156
183.33,-3.99,0.156
183.35,-3.92,0.156
183.36,-3.86,0.156
183.38,-3.79,0.156
183.39,-3.72,0.157
183.40,-3.66,0.157
183.42,-3.59,0.157
183.43,-3.52,0.157
183.44,-3.46,0.157
183.45,-3.39,0.157
183.47,-3.32,0.157
183.48,-3.25,0.157
183.50,-3.19,0.157
183.51,-3.12,0.158
183.52,-3.05,0.158
183.53,-2.99,0.158
183.55,-2.92,0.158
183.56,-2.86,0.158
183.58,-2.79,0.158
183.59,-2.72,0.158
183.60,-2.65,0.158
183.62,-2.59,0.158
183.63,-2.52,0.158
183.64,-2.46,0.158
183.65,-2.39,0.158
183.67,-2.32,0.158
183.68,-2.25,0.158
183.70,-2.19,0.158
183.71,-2.12,0.158
183.72,-2.05,0.158
183.73,-1.99,0.159
183.75,-1.92,0.159
183.76,-1.85,0.159
183.78,-1.79,0.159
183.79,-1.72,0.159
183.80,-1.65,0.159
183.82,-1.59,0.159
183.83,-1.52,0.159
183.84,-1.45,0.159
183.85,-1.39,0.159
183.87,-1.32,0.159
183.88,-1.25,0.159
183.90,-1.19,0.159
183.91,-1.12,0.159
183.92,-1.05,0.159
183.93,-0.99,0.159
183.95,-0.92,0.159
183.96,-0.85,0.159
183.98,-0.79,0.160
183.99,-0.72,0.160
184.00,-0.65,0.160
184.02,-0.59,0.160
184.03,-0.52,0.160
184.04,-0.45,0.160
184.05,-0.39,0.160
184.07,-0.32,0.160
184.08,-0.25,0.160
184.10,-0.19,0.160
184.11,-0.12,0.160
184.12,-0.05,0.160
184.13,0.01,0.160
184.15,0.08,0.160
184.16,0.15,0.160
184.18,0.21,0.160
184.19,0.28,0.160
184.20,0.35,0.160
184.22,0.41,0.160
184.23,0.48,0.160
184.24,0.55,0.160
184.25,0.61,0.160
184.27,0.68,0.160
184.28,0.75,0.160
184.30,0.82,0.160
184.31,0.88,0.160
184.32,0.95,0.160
184.33,1.01,0.160
184.35,1.08,0.160
184.36,1.15,0.160
184.38,1.22,0.160
184.39,1.28,0.160
184.40,1.35,0.160
184.42,1.42,0.160
184.43,1.48,0.160
184.44,1.55,0.160
184.45,1.62,0.160
184.47,1.68,0.160
184.48,1.75,0.161
184.50,1.82,0.161
184.51,1.88,0.161
184.52,1.95,0.161
184.53,2.02,0.161
184.55,2.08,0.161
184.56,2.15,0.161
184.58,2.22,0.161
184.59,2.28,0.161
184.60,2.35,0.161
184.62,2.42,0.161
184.63,2.48,0.161
184.64,2.55,0.161
184.65,2.62,0.161
184.67,2.68,0.161
184.68,2.75,0.161
184.70,2.82,0.161
184.71,2.88,0.161
184.72,2.95,0.161
184.73,3.02,0.161
184.75,3.08,0.161
184.76,3.15,0.161
184.78,3.22,0.161
184.79,3.28,0.161
184.80,3.35,0.161
184.82,3.42,0.161
184.83,3.48,0.161
184.84,3.55,0.161
184.85,3.62,0.161
184.87,3.68,0.161
184.88,3.75,0.161
184.90,3.82,0.161
184.91,3.88,0.161
184.92,3.95,0.161
184.93,4.02,0.161
184.95,4.09,0.161
184.96,4.15,0.161
184.98,4.22,0.161
184.99,4.28,0.161
185.00,4.35,0.161
185.02,4.42,0.161
185.03,4.48,0.161
185.04,4.55,0.161
185.05,4.62,0.161
185.07,4.68,0.161
185.08,4.75,0.161
185.10,4.82,0.161
185.11,4.88,0.161
185.12,4.95,0.161
185.13,5.02,0.161
185.15,5.08,0.161
185.16,5.15,0.161
185.18,5.22,0.161
185.19,5.28,0.161
185.20,5.35,0.161
185.22,5.42,0.161
185.23,5.48,0.161
185.24,5.55,0.161
185.25,5.62,0.161
185.27,5.69,0.161
185.28,5.75,0.161
185.30,5.82,0.161
185.31,5.89,0.161
185.32,5.95,0.162
185.33,6.02,0.162
185.35,6.09,0.162
185.36,6.15,0.162
185.38,6.22,0.162
185.39,6.29,0.162
185.40,6.35,0.162
185.42,6.42,0.162
185.43,6.49,0.162
185.44,6.55,0.162
185.45,6.62,0.162
185.47,6.69,0.162
185.48,6.75,0.162
185.50,6.82,0.162
185.51,6.89,0.162
185.52,6.96,0.162
185.53,7.02,0.162
185.55,7.09,0.162
185.56,7.15,0.162
185.58,7.22,0.162
185.59,7.29,0.162
185.60,7.36,0.162
185.62,7.42,0.162
185.63,7.49,0.162
185.64,7.55,0.162
185.65,7.62,0.162
185.67,7.69,0.162
185.68,7.75,0.162
185.70,7.82,0.162
185.71,7.89,0.162
185.72,7.95,0.162
185.73,8.02,0.162
185.75,8.09,0.162
185.76,8.16,0.162
185.78,8.22,0.162
185.79,8.29,0.162
185.80,8.35,0.162
185.82,8.42,0.162
185.83,8.49,0.162
185.84,8.55,0.162
185.85,8.62,0.162
185.87,8.69,0.162
185.88,8.76,0.162
185.90,8.82,0.163
185.91,8.89,0.163
185.92,8.95,0.163
185.93,9.02,0.163
185.95,9.09,0.163
185.96,9.16,0.163
185.98,9.22,0.163
185.99,9.29,0.163
186.00,9.36,0.163
186.02,9.42,0.163
186.03,9.49,0.163
186.04,9.56,0.163
186.05,9.62,0.163
186.07,9.69,0.163
186.08,9.76,0.163
186.10,9.82,0.163
186.11,9.89,0.163
186.12,9.96,0.163
186.13,10.02,0.163
186.15,10.09,0.163
186.16,10.16,0.163
186.18,10.22,0.163
186.19,10.29,0.163
186.20,10.36,0.163
186.22,10.42,0.163
186.23,10.49,0.163
186.24,10.56,0.163
186.25,10.62,0.163
186.27,10.69,0.163
186.28,10.76,0.163
186.30,10.82,0.163
186.31,10.89,0.163
186.32,10.96,0.163
186.33,11.02,0.163
186.35,11.09,0.163
186.36,11.16,0.163
186.38,11.22,0.163
186.39,11.29,0.163
186.40,11.36,0.163
186.42,11.42,0.163
186.43,11.49,0.163
186.44,11.56,0.163
186.45,11.62,0.164
186.47,11.69,0.163
186.48,11.76,0.164
186.50,11.82,0.164
186.51,11.89,0.164
186.52,11.96,0.164
186.53,12.02,0.164
186.55,12.09,0.164
186.56,12.16,0.164
186.58,12.22,0.164
186.59,12.29,0.164
186.60,12.36,0.164
186.62,12.42,0.164
186.63,12.49,0.164
186.64,12.56,0.164
186.65,12.62,0.164
186.67,12.69,0.164
186.68,12.76,0.164
186.70,12.82,0.164
186.71,12.89,0.164
186.72,12.96,0.164
186.73,13.02,0.164
186.75,13.09,0.164
186.76,13.16,0.164
186.78,13.22,0.164
186.79,13.29,0.164
186.80,13.36,0.164
186.82,13.43,0.164
186.83,13.49,0.164
186.84,13.56,0.164
186.85,13.62,0.164
186.87,13.69,0.164
186.88,13.76,0.164
186.90,13.83,0.164
186.91,13.89,0.164
186.92,13.96,0.164
186.93,14.03,0.164
186.95,14.09,0.164
186.96,14.16,0.164
186.98,14.23,0.164
186.99,14.29,0.164
187.00,14.36,0.164
187.02,14.43,0.164
187.03,14.49,0.164
187.04,14.56,0.164
187.05,14.63,0.164
187.07,14.69,0.164
187.08,14.76,0.164
187.10,14.83,0.164
187.11,14.89,0.164
187.12,14.96,0.164
187.13,15.03,0.164
187.15,15.09,0.164
187.16,15.16,0.164
187.18,15.23,0.164
187.19,15.29,0.164
187.20,15.36,0.164
187.22,15.43,0.164
187.23,15.49,0.164
187.24,15.56,0.164
187.25,15.63,0.164
187.27,15.69,0.164
187.28,15.76,0.164
187.30,15.83,0.164
187.31,15.89,0.164
187.32,15.96,0.164
187.33,16.03,0.165
187.35,16.09,0.165
187.36,16.16,0.165
187.38,16.23,0.165
187.39,16.29,0.165
187.40,16.36,0.165
187.42,16.43,0.165
187.43,16.49,0.165
187.44,16.56,0.165
187.45,16.63,0.165
187.47,16.70,0.165
187.48,16.76,0.165
187.50,16.83,0.165
187.51,16.90,0.165
187.52,16.96,0.165
187.53,17.03,0.165
187.55,17.09,0.165
187.56,17.16,0.165
187.58,17.23,0.165
187.59,17.29,0.165
187.60,17.36,0.165
187.62,17.43,0.165
187.63,17.50,0.165
187.64,17.56,0.165
187.65,17.63,0.165
187.67,17.69,0.165
187.68,17.76,0.165
187.70,17.83,0.165
187.71,17.90,0.165
187.72,17.96,0.165
187.73,18.03,0.165
187.75,18.10,0.165
187.76,18.16,0.165
187.78,18.23,0.166
187.79,18.30,0.165
187.80,18.36,0.166
187.82,18.43,0.166
187.83,18.50,0.166
187.84,18.56,0.166
187.85,18.63,0.166
187.87,18.70,0.166
187.88,18.76,0.166
187.90,18.83,0.166
187.91,18.90,0.166
187.92,18.96,0.166
187.93,19.03,0.166
187.95,19.10,0.166
187.96,19.16,0.166
187.98,19.23,0.166
187.99,19.30,0.166
188.00,19.36,0.166
188.02,19.43,0.166
188.03,19.50,0.166
188.04,19.56,0.166
188.05,19.63,0.166
188.07,19.70,0.166
188.08,19.76,0.166
188.10,19.83,0.166
188.11,19.90,0.166
188.12,19.96,0.166
188.13,20.03,0.166
188.15,20.10,0.166
188.16,20.16,0.166
188.18,20.23,0.166
188.19,20.30,0.166
188.20,20.36,0.166
188.22,20.43,0.166
188.23,20.50,0.166
188.24,20.56,0.166
188.25,20.63,0.166
188.27,20.70,0.166
188.28,20.76,0.166
188.30,20.83,0.166
188.31,20.90,0.167
188.32,20.96,0.167
188.33,21.03,0.167
188.35,21.10,0.167
188.36,21.16,0.167
188.38,21.23,0.167
188.39,21.30,0.167
188.40,21.37,0.167
188.42,21.43,0.167
188.43,21.50,0.167
188.44,21.57,0.167
188.45,21.63,0.167
188.47,21.70,0.167
188.48,21.77,0.167
188.50,21.83,0.167
188.51,21.90,0.167
188.52,21.97,0.167
188.53,22.03,0.167
188.55,22.10,0.167
188.56,22.17,0.167
188.58,22.23,0.167
188.59,22.30,0.167
188.60,22.36,0.167
188.62,22.43,0.167
188.63,22.50,0.167
188.64,22.57,0.167
188.65,22.63,0.167
188.67,22.70,0.167
188.68,22.76,0.167
188.70,22.83,0.167
188.71,22.90,0.167
188.72,22.96,0.167
188.73,23.03,0.167
188.75,23.10,0.167
188.76,23.17,0.167
188.78,23.23,0.167
188.79,23.30,0.167
188.80,23.37,0.167
188.82,23.43,0.168
188.83,23.50,0.167
188.84,23.57,0.168
188.85,23.63,0.168
188.87,23.70,0.168
188.88,23.77,0.168
188.90,23.83,0.168
188.91,23.90,0.168
188.92,23.97,0.168
188.93,24.03,0.168
188.95,24.10,0.168
188.96,24.17,0.168
188.98,24.23,0.168
188.99,24.30,0.168
189.00,24.37,0.168
189.02,24.43,0.168
189.03,24.50,0.168
189.04,24.57,0.168
189.05,24.63,0.168
189.07,24.70,0.168
189.08,24.77,0.168
189.10,24.83,0.168
189.11,24.90,0.168
189.12,24.97,0.168
189.13,25.04,0.168
189.15,25.10,0.168
189.16,25.17,0.168
189.18,25.23,0.168
189.19,25.30,0.168
189.20,25.37,0.168
189.22,25.43,0.168
189.23,25.50,0.168
189.24,25.57,0.168
189.25,25.63,0.168
189.27,25.70,0.168
189.28,25.77,0.168
189.30,25.83,0.168
189.31,25.90,0.168
189.32,25.97,0.168
189.33,26.04,0.168
189.35,26.10,0.168
189.36,26.17,0.169
189.38,26.24,0.169
189.39,26.30,0.169
189.40,26.37,0.169
189.42,26.43,0.169
189.43,26.50,0.169
189.44,26.57,0.169
189.45,26.63,0.169
189.47,26.70,0.169
189.48,26.77,0.169
189.50,26.83,0.169
189.51,26.90,0.169
189.52,26.97,0.169
189.53,27.04,0.169
189.55,27.10,0.169
189.56,27.17,0.169
189.58,27.23,0.169
189.59,27.30,0.169
189.60,27.37,0.169
189.62,27.43,0.169
189.63,27.50,0.169
189.64,27.57,0.169
189.65,27.64,0.169
189.67,27.70,0.169
189.68,27.77,0.170
189.70,27.84,0.169
189.71,27.90,0.169
189.72,27.97,0.170
189.73,28.04,0.170
189.75,28.10,0.170
189.76,28.17,0.170
189.78,28.24,0.170
189.79,28.30,0.170
189.80,28.37,0.170
189.82,28.44,0.170
189.83,28.50,0.170
189.84,28.57,0.170
189.85,28.64,0.170
189.87,28.70,0.170
189.88,28.77,0.170
189.90,28.84,0.170
189.91,28.90,0.170
189.92,28.97,0.170
189.93,29.04,
189.95,29.10,
189.96,29.17,
189.98,29.24,
189.99,,