File: DSC/2025_05_29_Nifedipine_0C_190C_10Cmin_x3.csv
Filename,2025_05_29_Nifedipine_0C_190C_10Cmin_x3
Instrument name,DSC2A-00468 (192.168.1.100)
Operator,Yarger
rundate,5/29/2025
Sample name,2025_05_29_Nifedipine_0C_190C_10Cmin_x3
proceduresegments,Data Off ; Equilibrate 0.00 °C; Data On ; Ramp 10.00 °C/min to 190.00 °C; Data Off ; Isothermal 1.0 min; Data On ; Ramp 10.00 °C/min to 0.00 °C; Data Off ; Isothermal 1.0 min; Data On ; Ramp 10.00 °C/min to 190.00 °C; Data Off ; Isothermal 1.0 min; Data On ; Ramp 10.00 °C/min to 0.00 °C; Data Off ; Isothermal 1.0 min; Data On ; Ramp 10.00 °C/min to 30.00 °C
[File Parameters]
Run date,5/29/2025 5:30:52 PM
Trios version,5.1.1.46572
Original File Name,
Current File Name,D:\DSC2500\JYarger\2025_05_29_Nifedipine_0C_190C_10Cmin_x3.tri
[Procedure]
Procedure Name,Nidedipine_0C_190C_10Cmin_x3
Sample Name,2025_05_29_Nifedipine_0C_190C_10Cmin_x3
Sample Mass,9.98 mg
Reference Sample Mass,0 mg
Pan Mass,56.36 mg
Pan Number,6
Reference Pan Mass,55.79 mg
Reference Pan Number,1
Pan Type,Tzero Aluminum Hermetic
Comments,Al Hermetic DSC Consumables sealed Pan/Lid. A2 Tray (Google Sheet: DSC_Samples_A2_Tray_May2025)
Project Name,CA
Operator,Yarger
Test,Custom
Unload Max Temperature,30
Unload Min Temperature,30
Load Max Temperature,30
Load Min Temperature,30
Stop on Gas Flow Error,Yes
[Signal List]
Signal #1,Time (min)
Signal #2,Temperature (°C)
Signal #3,Heat Flow (mW)
Signal #4,Delta T (µV)
Signal #5,Delta Tzero (µV)
Signal #6,Tzero Temperature (°C)
Signal #7,Cell Purge (mL/min)
Signal #8,Heater Temp (°C)
Signal #9,Power Delivered (W)
Signal #10,Reference Junction Temperature (°C)
Signal #11,Flange Temperature (°C)
Signal #12,Heat Flow Phase (rad)
Signal #13,Total Heat Capacity (J/°C)
Signal #14,Heat Capacity (J/°C)
[Configuration]
Company Name,ASU
Instrument Name,DSC2A-00468
Instrument Type,DSC2500
Serial Number,DSC2A-00468
IP,192.168.1.100
Location of Instrument,MRRC
DisplayType,Unknown
Sample Interval ,0.1 s/pt
Selected Heat Flow,T4P
Exotherm Direction,Down
Cell Serial,DRC2-00792
Lid Type,Standard
Cooler,RCS 90
Leave Cooler on at End of Sequence,On
Gas 2,Nitrogen
Gas Selected,Channel 1
Flow Rate,50 mL/min
Secondary Purge,On
Licensed Heat Flow,Heat Flow T4P
Modulation Licensed,Yes
[Versions]
Common IDD Version,1
Cortex Version,VER 2.10.2.31
Driver,5.0.0.6
GDM Version,1.0.3.3
TouchscreenVersion,1.0.0.16145
FEP Version,1.2.1.21
FEP Bootloader,2.0.0.5
AutoSampler Version,2.1.1.26
Auto Sampler Bootloader,2.0.0.5
FCM Version,1.1.0.3
FCM Bootloader,2.0.0.5
[Experiment Logs]
Experiment Log Entry # 2,Air Cool is off.
Experiment Log Entry # 4,Data On set to 0
Experiment Log Entry # 6,Equilibrate Segment 0 (C) Started
Experiment Log Entry # 8,Data On set to 1
Experiment Log Entry # 10,Ramp Segment 10 C/min to 190 Started
Experiment Log Entry # 12,Data On set to 0
Experiment Log Entry # 14,Isothermal Segment 1 min started
Experiment Log Entry # 16,Data On set to 1
Experiment Log Entry # 18,Ramp Segment 10 C/min to 0 Started
Experiment Log Entry # 20,Data On set to 0
Experiment Log Entry # 22,Isothermal Segment 1 min started
Experiment Log Entry # 24,Data On set to 1
Experiment Log Entry # 26,Ramp Segment 10 C/min to 190 Started
Experiment Log Entry # 28,Data On set to 0
Experiment Log Entry # 30,Isothermal Segment 1 min started
Experiment Log Entry # 32,Data On set to 1
Experiment Log Entry # 34,Ramp Segment 10 C/min to 0 Started
Experiment Log Entry # 36,Data On set to 0
Experiment Log Entry # 38,Isothermal Segment 1 min started
Experiment Log Entry # 40,Data On set to 1
Experiment Log Entry # 42,Ramp Segment 10 C/min to 30 Started
[Method Log]
Method Log Entry # 1,Data Off
Method Log Entry # 2,Equilibrate 0 °C
Method Log Entry # 3,Data On
Method Log Entry # 4,(Ramp 446336) Ramp 10 °C/minute to 190 °C
Method Log Entry # 5,Data Off
Method Log Entry # 6,Isothermal 1 minutes
Method Log Entry # 7,Data On
Method Log Entry # 8,(Ramp 446340) Ramp 10 °C/minute to 0 °C
Method Log Entry # 9,Data Off
Method Log Entry # 10,Isothermal 1 minutes
Method Log Entry # 11,Data On
Method Log Entry # 12,(Ramp 446344) Ramp 10 °C/minute to 190 °C
Method Log Entry # 13,Data Off
Method Log Entry # 14,Isothermal 1 minutes
Method Log Entry # 15,Data On
Method Log Entry # 16,(Ramp 446348) Ramp 10 °C/minute to 0 °C
Method Log Entry # 17,Data Off
Method Log Entry # 18,Isothermal 1 minutes
Method Log Entry # 19,Data On
Method Log Entry # 20,(Ramp 446352) Ramp 10 °C/minute to 30 °C
Cell Serial,DRC2-00792
[T1 Calibration]
Slope,-0.008529666
Offset,9.636258
Initial Temperature,98.23
GUID,f8bfdadc-4977-4fdf-ba6d-0ba9134940c3
[TZero Calibration]
Date Applied,11/29/2022 4:06:13 PM
Description,From -89.059 °C to 396.009 °C at 20.000°C/min
Gas Type,Nitrogen
Pan Type,None
Source Files 1,C:\Users\yargerlab\Desktop\DSC Data\General\TZero_calibration_11_29_22_2nd(2).tri
Source Files 2,C:\Users\yargerlab\Desktop\DSC Data\General\TZero_calibration_11_29_22_2nd(3).tri
Delta T Offset,13.05235
Delta T Slope,-0.007271007
Delta T0 Offset,-13.69128
Delta T0 Slope,0.06063341
[Temperature Calibration]
Date Applied,11/29/2022 7:12:28 PM
Description,From 106.590 °C to 186.590 °C at 10.000°C/min
Gas Type,Nitrogen
Pan Type,Tzero Aluminum Hermetic
Source Files 1,C:\Users\yargerlab\Desktop\DSC Data\General\Indium(6).tri
Measured 1,157.391
Known 1,156.598
[Cell Constant Calibration]
Date Applied,11/29/2022 7:12:29 PM
Description,From 106.590 °C to 186.590 °C at 10.000°C/min
Gas Type,Nitrogen
Pan Type,Tzero Aluminum Hermetic
Source Files 1,C:\Users\yargerlab\Desktop\DSC Data\General\Indium(6).tri
T4P KCell,1.006051
Onset Slope,63.26126 mW/°C
[Direct Cp Calibration]
Date Applied,11/30/2022 11:04:51 AM
Description,From -79.983 °C to 298.409 °C at 10.000°C/min
Gas Type,Nitrogen
Pan Type,Tzero Aluminum Hermetic
Source Files 1,C:\Users\yargerlab\Desktop\DSC Data\General\Sapphire_Heat_Capacity_11_30_22.tri
[Rev Cp Calibration]
Date Applied,11/30/2022 1:58:51 PM
Description,From -79.996 °C to 292.812 °C at 3.000°C/min
Gas Type,Nitrogen
Pan Type,Tzero Aluminum Hermetic
Source Files 1,C:\Users\yargerlab\Desktop\DSC Data\General\Sapphire_MDSC_Calibration_11_30_22.tri
[step]
Ramp 10.00 °C/min to 190.00 °C
Time,Temperature,Heat Flow (Normalized)
min,°C,W/g
0.00,0.14,-0.039
0.01,0.14,-0.039
0.03,0.14,-0.036
0.04,0.14,-0.033
0.05,0.14,-0.030
0.07,0.15,-0.027
0.08,0.17,-0.023
0.09,0.20,-0.019
0.11,0.23,-0.012
0.12,0.28,-0.004
0.13,0.34,0.006
0.15,0.41,0.017
0.16,0.49,0.030
0.17,0.57,0.043
0.19,0.66,0.056
0.20,0.75,0.068
0.21,0.85,0.079
0.23,0.95,0.090
0.24,1.05,0.099
0.25,1.15,0.108
0.27,1.26,0.116
0.28,1.37,0.125
0.29,1.48,0.130
0.31,1.60,0.137
0.32,1.71,0.143
0.33,1.83,0.148
0.35,1.95,0.154
0.36,2.07,0.158
0.37,2.19,0.163
0.39,2.31,0.166
0.40,2.43,0.170
0.41,2.56,0.173
0.43,2.68,0.175
0.44,2.81,0.178
0.45,2.93,0.180
0.47,3.06,0.183
0.48,3.19,0.185
0.49,3.31,0.186
0.51,3.44,0.187
0.52,3.57,0.189
0.53,3.69,0.191
0.55,3.83,0.192
0.56,3.95,0.192
0.57,4.08,0.194
0.59,4.21,0.195
0.60,4.34,0.196
0.61,4.47,0.196
0.63,4.60,0.197
0.64,4.73,0.198
0.65,4.86,0.198
0.67,4.99,0.199
0.68,5.12,0.200
0.69,5.25,0.200
0.71,5.39,0.200
0.72,5.52,0.201
0.73,5.65,0.201
0.75,5.78,0.201
0.76,5.91,0.202
0.77,6.04,0.202
0.79,6.17,0.202
0.80,6.30,0.202
0.81,6.44,0.202
0.83,6.57,0.203
0.84,6.70,0.203
0.85,6.83,0.203
0.87,6.96,0.203
0.88,7.09,0.203
0.89,7.23,0.203
0.91,7.36,0.204
0.92,7.49,0.204
0.93,7.62,0.204
0.95,7.76,0.204
0.96,7.89,0.204
0.97,8.02,0.204
0.99,8.15,0.205
1.00,8.29,0.205
1.01,8.42,0.205
1.03,8.55,0.205
1.04,8.68,0.205
1.05,8.82,0.205
1.07,8.95,0.206
1.08,9.08,0.206
1.09,9.21,0.206
1.11,9.35,0.206
1.12,9.48,0.206
1.13,9.61,0.206
1.15,9.74,0.207
1.16,9.88,0.207
1.17,10.01,0.207
1.19,10.14,0.207
1.20,10.28,0.207
1.21,10.41,0.207
1.23,10.54,0.207
1.24,10.67,0.207
1.25,10.81,0.208
1.27,10.94,0.208
1.28,11.07,0.208
1.29,11.21,0.208
1.31,11.34,0.208
1.32,11.47,0.208
1.33,11.61,0.208
1.35,11.74,0.208
1.36,11.87,0.208
1.37,12.00,0.209
1.39,12.14,0.209
1.40,12.27,0.209
1.41,12.40,0.209
1.43,12.54,0.209
1.44,12.67,0.209
1.45,12.80,0.209
1.47,12.93,0.209
1.48,13.07,0.209
1.49,13.20,0.209
1.51,13.34,0.209
1.52,13.47,0.210
1.53,13.60,0.210
1.55,13.74,0.210
1.56,13.87,0.210
1.57,14.00,0.210
1.59,14.14,0.210
1.60,14.27,0.210
1.61,14.40,0.210
1.63,14.54,0.210
1.64,14.67,0.210
1.65,14.80,0.211
1.67,14.93,0.211
1.68,15.07,0.211
1.69,15.20,0.211
1.71,15.33,0.211
1.72,15.47,0.211
1.73,15.60,0.211
1.75,15.74,0.211
1.76,15.87,0.211
1.77,16.00,0.211
1.79,16.13,0.211
1.80,16.27,0.211
1.81,16.40,0.211
1.83,16.53,0.211
1.84,16.67,0.212
1.85,16.80,0.212
1.87,16.93,0.212
1.88,17.07,0.212
1.89,17.20,0.212
1.91,17.33,0.212
1.92,17.47,0.212
1.93,17.60,0.212
1.95,17.74,0.212
1.96,17.87,0.212
1.97,18.00,0.212
1.99,18.14,0.212
2.00,18.27,0.212
2.01,18.40,0.213
2.03,18.53,0.213
2.04,18.67,0.213
2.05,18.80,0.213
2.07,18.94,0.213
2.08,19.07,0.213
2.09,19.20,0.213
2.11,19.34,0.213
2.12,19.47,0.213
2.13,19.60,0.213
2.15,19.74,0.213
2.16,19.87,0.213
2.17,20.00,0.213
2.19,20.14,0.214
2.20,20.27,0.214
2.21,20.40,0.214
2.23,20.54,0.214
2.24,20.67,0.214
2.25,20.80,0.214
2.27,20.94,0.214
2.28,21.07,0.214
2.29,21.20,0.214
2.31,21.34,0.214
2.32,21.47,0.214
2.33,21.60,0.214
2.35,21.74,0.214
2.36,21.87,0.214
2.37,22.01,0.214
2.39,22.14,0.215
2.40,22.27,0.215
2.41,22.40,0.215
2.43,22.54,0.215
2.44,22.67,0.215
2.45,22.80,0.215
2.47,22.94,0.215
2.48,23.07,0.215
2.49,23.21,0.215
2.51,23.34,0.215
2.52,23.47,0.215
2.53,23.61,0.215
2.55,23.74,0.215
2.56,23.87,0.215
2.57,24.01,0.216
2.59,24.14,0.216
2.60,24.27,0.216
2.61,24.41,0.216
2.63,24.54,0.216
2.64,24.67,0.216
2.65,24.81,0.216
2.67,24.94,0.216
2.68,25.07,0.216
2.69,25.21,0.216
2.71,25.34,0.216
2.72,25.47,0.216
2.73,25.61,0.216
2.75,25.74,0.217
2.76,25.87,0.217
2.77,26.01,0.217
2.79,26.14,0.217
2.80,26.28,0.217
2.81,26.41,0.217
2.83,26.54,0.217
2.84,26.68,0.217
2.85,26.81,0.217
2.87,26.94,0.217
2.88,27.08,0.217
2.89,27.21,0.217
2.91,27.34,0.217
2.92,27.48,0.218
2.93,27.61,0.218
2.95,27.74,0.218
2.96,27.88,0.218
2.97,28.01,0.218
2.99,28.14,0.218
3.00,28.28,0.218
3.01,28.41,0.218
3.03,28.54,0.218
3.04,28.68,0.218
3.05,28.81,0.218
3.07,28.94,0.218
3.08,29.08,0.218
3.09,29.21,0.218
3.11,29.34,0.218
3.12,29.48,0.218
3.13,29.61,0.218
3.15,29.74,0.219
3.16,29.88,0.219
3.17,30.01,0.219
3.19,30.15,0.219
3.20,30.28,0.219
3.21,30.41,0.219
3.23,30.55,0.219
3.24,30.68,0.219
3.25,30.81,0.219
3.27,30.95,0.219
3.28,31.08,0.219
3.29,31.21,0.219
3.31,31.35,0.219
3.32,31.48,0.219
3.33,31.61,0.219
3.35,31.75,0.219
3.36,31.88,0.220
3.37,32.01,0.220
3.39,32.15,0.220
3.40,32.28,0.220
3.41,32.41,0.220
3.43,32.55,0.220
3.44,32.68,0.220
3.45,32.81,0.220
3.47,32.95,0.220
3.48,33.08,0.220
3.49,33.22,0.220
3.51,33.35,0.220
3.52,33.48,0.220
3.53,33.61,0.220
3.55,33.75,0.220
3.56,33.88,0.221
3.57,34.02,0.221
3.59,34.15,0.221
3.60,34.28,0.221
3.61,34.42,0.221
3.63,34.55,0.221
3.64,34.68,0.221
3.65,34.82,0.221
3.67,34.95,0.221
3.68,35.08,0.221
3.69,35.22,0.221
3.71,35.35,0.221
3.72,35.49,0.221
3.73,35.62,0.221
3.75,35.75,0.221
3.76,35.88,0.221
3.77,36.02,0.222
3.79,36.15,0.222
3.80,36.29,0.222
3.81,36.42,0.222
3.83,36.55,0.222
3.84,36.69,0.222
3.85,36.82,0.222
3.87,36.95,0.222
3.88,37.09,0.222
3.89,37.22,0.222
3.91,37.35,0.222
3.92,37.49,0.222
3.93,37.62,0.222
3.95,37.75,0.222
3.96,37.89,0.222
3.97,38.02,0.222
3.99,38.15,0.223
4.00,38.29,0.223
4.01,38.42,0.223
4.03,38.55,0.223
4.04,38.69,0.223
4.05,38.82,0.223
4.07,38.95,0.223
4.08,39.09,0.223
4.09,39.22,0.223
4.11,39.35,0.223
4.12,39.49,0.223
4.13,39.62,0.223
4.15,39.76,0.223
4.16,39.89,0.223
4.17,40.02,0.223
4.19,40.16,0.224
4.20,40.29,0.224
4.21,40.42,0.224
4.23,40.56,0.224
4.24,40.69,0.224
4.25,40.82,0.224
4.27,40.96,0.224
4.28,41.09,0.224
4.29,41.22,0.224
4.31,41.36,0.224
4.32,41.49,0.224
4.33,41.62,0.224
4.35,41.76,0.224
4.36,41.89,0.224
4.37,42.02,0.224
4.39,42.16,0.224
4.40,42.29,0.225
4.41,42.43,0.225
4.43,42.56,0.225
4.44,42.69,0.225
4.45,42.83,0.225
4.47,42.96,0.225
4.48,43.09,0.225
4.49,43.23,0.225
4.51,43.36,0.225
4.52,43.49,0.225
4.53,43.63,0.225
4.55,43.76,0.225
4.56,43.89,0.225
4.57,44.03,0.226
4.59,44.16,0.226
4.60,44.29,0.226
4.61,44.43,0.226
4.63,44.56,0.226
4.64,44.69,0.226
4.65,44.83,0.226
4.67,44.96,0.226
4.68,45.09,0.226
4.69,45.23,0.226
4.71,45.36,0.226
4.72,45.49,0.226
4.73,45.63,0.226
4.75,45.76,0.226
4.76,45.89,0.226
4.77,46.03,0.226
4.79,46.16,0.227
4.80,46.29,0.227
4.81,46.43,0.227
4.83,46.56,0.227
4.84,46.70,0.227
4.85,46.83,0.227
4.87,46.96,0.227
4.88,47.10,0.227
4.89,47.23,0.227
4.91,47.36,0.227
4.92,47.50,0.227
4.93,47.63,0.227
4.95,47.76,0.227
4.96,47.90,0.228
4.97,48.03,0.228
4.99,48.16,0.228
5.00,48.30,0.228
5.01,48.43,0.228
5.03,48.56,0.228
5.04,48.70,0.228
5.05,48.83,0.228
5.07,48.96,0.228
5.08,49.10,0.228
5.09,49.23,0.228
5.11,49.37,0.228
5.12,49.50,0.228
5.13,49.63,0.228
5.15,49.77,0.228
5.16,49.90,0.229
5.17,50.03,0.229
5.19,50.17,0.229
5.20,50.30,0.229
5.21,50.43,0.229
5.23,50.57,0.229
5.24,50.70,0.229
5.25,50.83,0.229
5.27,50.97,0.229
5.28,51.10,0.229
5.29,51.23,0.229
5.31,51.37,0.229
5.32,51.50,0.229
5.33,51.63,0.229
5.35,51.77,0.230
5.36,51.90,0.230
5.37,52.03,0.230
5.39,52.17,0.230
5.40,52.30,0.230
5.41,52.44,0.230
5.43,52.57,0.230
5.44,52.70,0.230
5.45,52.84,0.230
5.47,52.97,0.230
5.48,53.10,0.230
5.49,53.24,0.230
5.51,53.37,0.230
5.52,53.50,0.230
5.53,53.64,0.230
5.55,53.77,0.231
5.56,53.90,0.231
5.57,54.04,0.231
5.59,54.17,0.231
5.60,54.30,0.231
5.61,54.44,0.231
5.63,54.57,0.231
5.64,54.70,0.231
5.65,54.84,0.231
5.67,54.97,0.231
5.68,55.11,0.231
5.69,55.24,0.231
5.71,55.37,0.231
5.72,55.51,0.232
5.73,55.64,0.232
5.75,55.77,0.232
5.76,55.91,0.232
5.77,56.04,0.232
5.79,56.17,0.232
5.80,56.31,0.232
5.81,56.44,0.232
5.83,56.57,0.232
5.84,56.71,0.232
5.85,56.84,0.232
5.87,56.97,0.232
5.88,57.11,0.232
5.89,57.24,0.232
5.91,57.37,0.233
5.92,57.51,0.233
5.93,57.64,0.233
5.95,57.78,0.233
5.96,57.91,0.233
5.97,58.04,0.233
5.99,58.18,0.233
6.00,58.31,0.233
6.01,58.44,0.233
6.03,58.58,0.233
6.04,58.71,0.233
6.05,58.84,0.233
6.07,58.97,0.233
6.08,59.11,0.233
6.09,59.24,0.233
6.11,59.38,0.233
6.12,59.51,0.233
6.13,59.64,0.233
6.15,59.78,0.233
6.16,59.91,0.234
6.17,60.04,0.234
6.19,60.18,0.234
6.20,60.31,0.234
6.21,60.44,0.234
6.23,60.58,0.234
6.24,60.71,0.234
6.25,60.84,0.234
6.27,60.98,0.234
6.28,61.11,0.234
6.29,61.24,0.234
6.31,61.38,0.234
6.32,61.51,0.234
6.33,61.64,0.234
6.35,61.78,0.234
6.36,61.91,0.235
6.37,62.04,0.235
6.39,62.18,0.235
6.40,62.31,0.235
6.41,62.44,0.235
6.43,62.58,0.235
6.44,62.71,0.235
6.45,62.85,0.235
6.47,62.98,0.235
6.48,63.11,0.235
6.49,63.25,0.235
6.51,63.38,0.235
6.52,63.51,0.235
6.53,63.65,0.235
6.55,63.78,0.236
6.56,63.91,0.236
6.57,64.05,0.236
6.59,64.18,0.236
6.60,64.31,0.236
6.61,64.45,0.236
6.63,64.58,0.236
6.64,64.71,0.236
6.65,64.85,0.236
6.67,64.98,0.236
6.68,65.11,0.236
6.69,65.25,0.236
6.71,65.38,0.236
6.72,65.51,0.236
6.73,65.65,0.236
6.75,65.78,0.237
6.76,65.91,0.237
6.77,66.05,0.237
6.79,66.18,0.237
6.80,66.32,0.237
6.81,66.45,0.237
6.83,66.58,0.237
6.84,66.72,0.237
6.85,66.85,0.237
6.87,66.98,0.237
6.88,67.12,0.237
6.89,67.25,0.237
6.91,67.38,0.237
6.92,67.52,0.237
6.93,67.65,0.237
6.95,67.78,0.238
6.96,67.92,0.238
6.97,68.05,0.238
6.99,68.18,0.238
7.00,68.32,0.238
7.01,68.45,0.238
7.03,68.58,0.238
7.04,68.72,0.238
7.05,68.85,0.238
7.07,68.98,0.238
7.08,69.12,0.238
7.09,69.25,0.238
7.11,69.38,0.238
7.12,69.52,0.238
7.13,69.65,0.239
7.15,69.78,0.239
7.16,69.92,0.239
7.17,70.05,0.239
7.19,70.19,0.239
7.20,70.32,0.239
7.21,70.45,0.239
7.23,70.59,0.239
7.24,70.72,0.239
7.25,70.85,0.239
7.27,70.99,0.239
7.28,71.12,0.239
7.29,71.25,0.239
7.31,71.39,0.239
7.32,71.52,0.240
7.33,71.65,0.240
7.35,71.79,0.240
7.36,71.92,0.240
7.37,72.05,0.240
7.39,72.19,0.240
7.40,72.32,0.240
7.41,72.45,0.240
7.43,72.59,0.240
7.44,72.72,0.240
7.45,72.85,0.240
7.47,72.99,0.240
7.48,73.12,0.240
7.49,73.25,0.240
7.51,73.39,0.241
7.52,73.52,0.241
7.53,73.66,0.241
7.55,73.79,0.241
7.56,73.92,0.241
7.57,74.06,0.241
7.59,74.19,0.241
7.60,74.32,0.241
7.61,74.46,0.241
7.63,74.59,0.241
7.64,74.72,0.241
7.65,74.86,0.241
7.67,74.99,0.241
7.68,75.12,0.241
7.69,75.26,0.242
7.71,75.39,0.242
7.72,75.52,0.242
7.73,75.66,0.242
7.75,75.79,0.242
7.76,75.92,0.242
7.77,76.06,0.242
7.79,76.19,0.242
7.80,76.32,0.242
7.81,76.46,0.242
7.83,76.59,0.242
7.84,76.72,0.242
7.85,76.86,0.242
7.87,76.99,0.242
7.88,77.12,0.243
7.89,77.26,0.243
7.91,77.39,0.243
7.92,77.53,0.243
7.93,77.66,0.243
7.95,77.79,0.243
7.96,77.93,0.243
7.97,78.06,0.243
7.99,78.19,0.243
8.00,78.33,0.243
8.01,78.46,0.243
8.03,78.59,0.243
8.04,78.73,0.243
8.05,78.86,0.243
8.07,78.99,0.244
8.08,79.13,0.244
8.09,79.26,0.244
8.11,79.39,0.244
8.12,79.53,0.244
8.13,79.66,0.244
8.15,79.79,0.244
8.16,79.93,0.244
8.17,80.06,0.244
8.19,80.20,0.244
8.20,80.33,0.244
8.21,80.46,0.244
8.23,80.60,0.245
8.24,80.73,0.245
8.25,80.86,0.245
8.27,81.00,0.245
8.28,81.13,0.245
8.29,81.26,0.245
8.31,81.40,0.245
8.32,81.53,0.245
8.33,81.66,0.245
8.35,81.80,0.245
8.36,81.93,0.245
8.37,82.06,0.245
8.39,82.20,0.245
8.40,82.33,0.245
8.41,82.46,0.245
8.43,82.60,0.245
8.44,82.73,0.245
8.45,82.86,0.245
8.47,83.00,0.245
8.48,83.13,0.246
8.49,83.26,0.246
8.51,83.40,0.246
8.52,83.53,0.246
8.53,83.66,0.246
8.55,83.80,0.246
8.56,83.93,0.246
8.57,84.06,0.246
8.59,84.20,0.246
8.60,84.33,0.246
8.61,84.47,0.246
8.63,84.60,0.246
8.64,84.73,0.246
8.65,84.87,0.246
8.67,85.00,0.246
8.68,85.13,0.246
8.69,85.27,0.246
8.71,85.40,0.246
8.72,85.53,0.246
8.73,85.67,0.246
8.75,85.80,0.246
8.76,85.93,0.246
8.77,86.07,0.247
8.79,86.20,0.247
8.80,86.33,0.247
8.81,86.47,0.247
8.83,86.60,0.247
8.84,86.73,0.247
8.85,86.87,0.247
8.87,87.00,0.247
8.88,87.13,0.247
8.89,87.27,0.247
8.91,87.40,0.247
8.92,87.54,0.247
8.93,87.67,0.247
8.95,87.80,0.247
8.96,87.93,0.247
8.97,88.07,0.247
8.99,88.20,0.247
9.00,88.33,0.247
9.01,88.47,0.248
9.03,88.60,0.248
9.04,88.73,0.248
9.05,88.87,0.248
9.07,89.00,0.248
9.08,89.14,0.248
9.09,89.27,0.248
9.11,89.40,0.248
9.12,89.54,0.248
9.13,89.67,0.248
9.15,89.80,0.248
9.16,89.94,0.248
9.17,90.07,0.248
9.19,90.20,0.248
9.20,90.34,0.249
9.21,90.47,0.249
9.23,90.60,0.249
9.24,90.74,0.249
9.25,90.87,0.249
9.27,91.00,0.249
9.28,91.14,0.249
9.29,91.27,0.249
9.31,91.41,0.249
9.32,91.54,0.249
9.33,91.67,0.249
9.35,91.81,0.249
9.36,91.94,0.250
9.37,92.07,0.250
9.39,92.21,0.250
9.40,92.34,0.250
9.41,92.47,0.250
9.43,92.61,0.250
9.44,92.74,0.250
9.45,92.87,0.250
9.47,93.01,0.250
9.48,93.14,0.250
9.49,93.27,0.250
9.51,93.41,0.250
9.52,93.54,0.250
9.53,93.67,0.251
9.55,93.81,0.251
9.56,93.94,0.251
9.57,94.08,0.251
9.59,94.21,0.251
9.60,94.34,0.251
9.61,94.47,0.251
9.63,94.61,0.251
9.64,94.74,0.251
9.65,94.88,0.251
9.67,95.01,0.251
9.68,95.14,0.251
9.69,95.27,0.251
9.71,95.41,0.251
9.72,95.54,0.251
9.73,95.68,0.252
9.75,95.81,0.252
9.76,95.94,0.252
9.77,96.08,0.252
9.79,96.21,0.252
9.80,96.34,0.252
9.81,96.48,0.252
9.83,96.61,0.252
9.84,96.74,0.252
9.85,96.88,0.252
9.87,97.01,0.252
9.88,97.14,0.252
9.89,97.28,0.252
9.91,97.41,0.252
9.92,97.54,0.253
9.93,97.68,0.253
9.95,97.81,0.253
9.96,97.94,0.253
9.97,98.08,0.253
9.99,98.21,0.253
10.00,98.34,0.253
10.01,98.48,0.253
10.03,98.61,0.253
10.04,98.75,0.253
10.05,98.88,0.253
10.07,99.01,0.253
10.08,99.15,0.253
10.09,99.28,0.253
10.11,99.41,0.253
10.12,99.55,0.254
10.13,99.68,0.254
10.15,99.81,0.254
10.16,99.95,0.254
10.17,100.08,0.254
10.19,100.21,0.254
10.20,100.35,0.254
10.21,100.48,0.254
10.23,100.61,0.254
10.24,100.75,0.254
10.25,100.88,0.254
10.27,101.01,0.254
10.28,101.15,0.254
10.29,101.28,0.255
10.31,101.42,0.255
10.32,101.55,0.255
10.33,101.68,0.255
10.35,101.81,0.255
10.36,101.95,0.255
10.37,102.08,0.255
10.39,102.22,0.255
10.40,102.35,0.255
10.41,102.48,0.255
10.43,102.61,0.255
10.44,102.75,0.255
10.45,102.88,0.255
10.47,103.02,0.255
10.48,103.15,0.255
10.49,103.28,0.256
10.51,103.42,0.256
10.52,103.55,0.256
10.53,103.68,0.256
10.55,103.82,0.256
10.56,103.95,0.256
10.57,104.08,0.256
10.59,104.22,0.256
10.60,104.35,0.256
10.61,104.48,0.256
10.63,104.62,0.256
10.64,104.75,0.256
10.65,104.88,0.256
10.67,105.02,0.256
10.68,105.15,0.256
10.69,105.28,0.257
10.71,105.42,0.257
10.72,105.55,0.257
10.73,105.68,0.257
10.75,105.82,0.257
10.76,105.95,0.257
10.77,106.08,0.257
10.79,106.22,0.257
10.80,106.35,0.257
10.81,106.48,0.257
10.83,106.62,0.257
10.84,106.75,0.257
10.85,106.88,0.257
10.87,107.02,0.257
10.88,107.15,0.257
10.89,107.28,0.258
10.91,107.42,0.258
10.92,107.55,0.258
10.93,107.68,0.258
10.95,107.82,0.258
10.96,107.95,0.258
10.97,108.09,0.258
10.99,108.22,0.258
11.00,108.35,0.258
11.01,108.49,0.258
11.03,108.62,0.258
11.04,108.75,0.258
11.05,108.89,0.258
11.07,109.02,0.258
11.08,109.15,0.259
11.09,109.29,0.259
11.11,109.42,0.259
11.12,109.55,0.259
11.13,109.69,0.259
11.15,109.82,0.259
11.16,109.95,0.259
11.17,110.09,0.259
11.19,110.22,0.259
11.20,110.35,0.259
11.21,110.49,0.259
11.23,110.62,0.259
11.24,110.75,0.259
11.25,110.89,0.259
11.27,111.02,0.260
11.28,111.15,0.260
11.29,111.29,0.260
11.31,111.42,0.260
11.32,111.56,0.260
11.33,111.69,0.260
11.35,111.82,0.260
11.36,111.96,0.260
11.37,112.09,0.260
11.39,112.22,0.260
11.40,112.36,0.260
11.41,112.49,0.260
11.43,112.62,0.260
11.44,112.76,0.260
11.45,112.89,0.261
11.47,113.02,0.261
11.48,113.16,0.261
11.49,113.29,0.261
11.51,113.42,0.261
11.52,113.56,0.261
11.53,113.69,0.261
11.55,113.82,0.261
11.56,113.96,0.261
11.57,114.09,0.261
11.59,114.23,0.261
11.60,114.36,0.261
11.61,114.49,0.261
11.63,114.63,0.261
11.64,114.76,0.261
11.65,114.89,0.262
11.67,115.03,0.262
11.68,115.16,0.262
11.69,115.29,0.262
11.71,115.43,0.262
11.72,115.56,0.262
11.73,115.69,0.262
11.75,115.83,0.262
11.76,115.96,0.262
11.77,116.09,0.262
11.79,116.23,0.262
11.80,116.36,0.262
11.81,116.49,0.262
11.83,116.63,0.262
11.84,116.76,0.262
11.85,116.89,0.262
11.87,117.03,0.263
11.88,117.16,0.263
11.89,117.29,0.263
11.91,117.43,0.263
11.92,117.56,0.263
11.93,117.69,0.263
11.95,117.83,0.263
11.96,117.96,0.263
11.97,118.09,0.263
11.99,118.23,0.263
12.00,118.36,0.263
12.01,118.49,0.263
12.03,118.63,0.263
12.04,118.76,0.263
12.05,118.89,0.263
12.07,119.03,0.263
12.08,119.16,0.263
12.09,119.30,0.264
12.11,119.43,0.264
12.12,119.56,0.264
12.13,119.70,0.264
12.15,119.83,0.264
12.16,119.96,0.264
12.17,120.10,0.264
12.19,120.23,0.264
12.20,120.36,0.264
12.21,120.50,0.264
12.23,120.63,0.264
12.24,120.76,0.264
12.25,120.90,0.264
12.27,121.03,0.264
12.28,121.16,0.265
12.29,121.30,0.265
12.31,121.43,0.265
12.32,121.56,0.265
12.33,121.70,0.265
12.35,121.83,0.265
12.36,121.96,0.265
12.37,122.10,0.265
12.39,122.23,0.265
12.40,122.36,0.265
12.41,122.50,0.265
12.43,122.63,0.265
12.44,122.77,0.265
12.45,122.90,0.265
12.47,123.03,0.265
12.48,123.17,0.266
12.49,123.30,0.266
12.51,123.43,0.266
12.52,123.57,0.266
12.53,123.70,0.266
12.55,123.83,0.266
12.56,123.97,0.266
12.57,124.10,0.266
12.59,124.23,0.266
12.60,124.37,0.266
12.61,124.50,0.266
12.63,124.63,0.266
12.64,124.77,0.266
12.65,124.90,0.266
12.67,125.03,0.266
12.68,125.17,0.267
12.69,125.30,0.267
12.71,125.44,0.267
12.72,125.57,0.267
12.73,125.70,0.267
12.75,125.83,0.267
12.76,125.97,0.267
12.77,126.10,0.267
12.79,126.23,0.267
12.80,126.37,0.267
12.81,126.50,0.267
12.83,126.63,0.267
12.84,126.77,0.267
12.85,126.90,0.267
12.87,127.03,0.267
12.88,127.17,0.268
12.89,127.30,0.268
12.91,127.44,0.268
12.92,127.57,0.268
12.93,127.70,0.268
12.95,127.83,0.268
12.96,127.97,0.268
12.97,128.10,0.268
12.99,128.23,0.268
13.00,128.37,0.268
13.01,128.50,0.268
13.03,128.63,0.268
13.04,128.77,0.268
13.05,128.90,0.268
13.07,129.04,0.268
13.08,129.17,0.269
13.09,129.30,0.269
13.11,129.43,0.269
13.12,129.57,0.269
13.13,129.70,0.269
13.15,129.84,0.269
13.16,129.97,0.269
13.17,130.10,0.269
13.19,130.24,0.269
13.20,130.37,0.269
13.21,130.50,0.269
13.23,130.64,0.269
13.24,130.77,0.269
13.25,130.90,0.270
13.27,131.04,0.270
13.28,131.17,0.270
13.29,131.30,0.270
13.31,131.44,0.270
13.32,131.57,0.270
13.33,131.70,0.270
13.35,131.84,0.270
13.36,131.97,0.270
13.37,132.11,0.270
13.39,132.24,0.270
13.40,132.37,0.270
13.41,132.50,0.270
13.43,132.64,0.271
13.44,132.77,0.271
13.45,132.91,0.271
13.47,133.04,0.271
13.48,133.17,0.271
13.49,133.31,0.271
13.51,133.44,0.271
13.52,133.57,0.271
13.53,133.71,0.271
13.55,133.84,0.271
13.56,133.97,0.271
13.57,134.11,0.271
13.59,134.24,0.271
13.60,134.37,0.271
13.61,134.51,0.272
13.63,134.64,0.272
13.64,134.77,0.272
13.65,134.91,0.272
13.67,135.04,0.272
13.68,135.17,0.272
13.69,135.31,0.272
13.71,135.44,0.272
13.72,135.58,0.272
13.73,135.71,0.272
13.75,135.84,0.272
13.76,135.97,0.272
13.77,136.11,0.272
13.79,136.24,0.272
13.80,136.38,0.273
13.81,136.51,0.273
13.83,136.64,0.273
13.84,136.78,0.273
13.85,136.91,0.273
13.87,137.04,0.273
13.88,137.18,0.273
13.89,137.31,0.273
13.91,137.44,0.273
13.92,137.58,0.273
13.93,137.71,0.273
13.95,137.85,0.274
13.96,137.98,0.274
13.97,138.12,0.274
13.99,138.25,0.274
14.00,138.38,0.274
14.01,138.52,0.274
14.03,138.65,0.274
14.04,138.78,0.274
14.05,138.92,0.274
14.07,139.05,0.274
14.08,139.18,0.274
14.09,139.32,0.275
14.11,139.45,0.275
14.12,139.58,0.275
14.13,139.71,0.275
14.15,139.85,0.275
14.16,139.98,0.275
14.17,140.11,0.275
14.19,140.25,0.275
14.20,140.38,0.275
14.21,140.51,0.275
14.23,140.65,0.275
14.24,140.78,0.275
14.25,140.91,0.275
14.27,141.05,0.275
14.28,141.18,0.275
14.29,141.31,0.275
14.31,141.45,0.275
14.32,141.58,0.275
14.33,141.71,0.275
14.35,141.85,0.275
14.36,141.98,0.275
14.37,142.11,0.275
14.39,142.25,0.275
14.40,142.38,0.275
14.41,142.51,0.275
14.43,142.65,0.276
14.44,142.78,0.276
14.45,142.91,0.276
14.47,143.05,0.276
14.48,143.18,0.276
14.49,143.31,0.276
14.51,143.45,0.276
14.52,143.58,0.276
14.53,143.71,0.276
14.55,143.85,0.276
14.56,143.98,0.276
14.57,144.11,0.276
14.59,144.25,0.276
14.60,144.38,0.276
14.61,144.51,0.277
14.63,144.65,0.277
14.64,144.78,0.277
14.65,144.91,0.277
14.67,145.05,0.277
14.68,145.18,0.277
14.69,145.31,0.277
14.71,145.45,0.277
14.72,145.58,0.277
14.73,145.71,0.277
14.75,145.85,0.277
14.76,145.98,0.277
14.77,146.11,0.277
14.79,146.25,0.278
14.80,146.38,0.278
14.81,146.51,0.278
14.83,146.65,0.278
14.84,146.78,0.278
14.85,146.91,0.278
14.87,147.05,0.278
14.88,147.18,0.278
14.89,147.31,0.278
14.91,147.45,0.278
14.92,147.58,0.278
14.93,147.71,0.279
14.95,147.85,0.279
14.96,147.98,0.279
14.97,148.11,0.279
14.99,148.25,0.279
15.00,148.38,0.279
15.01,148.51,0.279
15.03,148.65,0.279
15.04,148.78,0.279
15.05,148.91,0.279
15.07,149.05,0.279
15.08,149.18,0.280
15.09,149.32,0.280
15.11,149.45,0.280
15.12,149.58,0.280
15.13,149.72,0.280
15.15,149.85,0.280
15.16,149.98,0.280
15.17,150.12,0.280
15.19,150.25,0.280
15.20,150.38,0.280
15.21,150.52,0.280
15.23,150.65,0.281
15.24,150.78,0.281
15.25,150.91,0.281
15.27,151.05,0.281
15.28,151.18,0.281
15.29,151.31,0.281
15.31,151.45,0.281
15.32,151.58,0.281
15.33,151.72,0.281
15.35,151.85,0.281
15.36,151.98,0.281
15.37,152.12,0.281
15.39,152.25,0.281
15.40,152.38,0.281
15.41,152.52,0.281
15.43,152.65,0.282
15.44,152.78,0.282
15.45,152.92,0.282
15.47,153.05,0.282
15.48,153.18,0.282
15.49,153.32,0.282
15.51,153.45,0.282
15.52,153.58,0.282
15.53,153.72,0.282
15.55,153.85,0.282
15.56,153.98,0.282
15.57,154.12,0.282
15.59,154.25,0.283
15.60,154.38,0.283
15.61,154.52,0.283
15.63,154.65,0.283
15.64,154.78,0.283
15.65,154.92,0.283
15.67,155.05,0.283
15.68,155.19,0.283
15.69,155.32,0.283
15.71,155.45,0.283
15.72,155.58,0.284
15.73,155.72,0.284
15.75,155.85,0.284
15.76,155.99,0.284
15.77,156.12,0.284
15.79,156.25,0.284
15.80,156.38,0.284
15.81,156.52,0.284
15.83,156.65,0.284
15.84,156.79,0.285
15.85,156.92,0.285
15.87,157.05,0.285
15.88,157.19,0.285
15.89,157.32,0.285
15.91,157.45,0.285
15.92,157.59,0.285
15.93,157.72,0.285
15.95,157.85,0.286
15.96,157.99,0.286
15.97,158.12,0.286
15.99,158.25,0.286
16.00,158.39,0.286
16.01,158.52,0.286
16.03,158.65,0.286
16.04,158.79,0.286
16.05,158.92,0.287
16.07,159.05,0.287
16.08,159.19,0.287
16.09,159.32,0.287
16.11,159.45,0.287
16.12,159.59,0.288
16.13,159.72,0.288
16.15,159.85,0.288
16.16,159.99,0.288
16.17,160.12,0.288
16.19,160.25,0.288
16.20,160.39,0.289
16.21,160.52,0.289
16.23,160.65,0.289
16.24,160.79,0.289
16.25,160.92,0.290
16.27,161.05,0.290
16.28,161.19,0.290
16.29,161.32,0.290
16.31,161.45,0.291
16.32,161.59,0.291
16.33,161.72,0.291
16.35,161.85,0.291
16.36,161.98,0.291
16.37,162.12,0.292
16.39,162.25,0.292
16.40,162.38,0.293
16.41,162.52,0.293
16.43,162.65,0.294
16.44,162.78,0.294
16.45,162.92,0.295
16.47,163.05,0.295
16.48,163.18,0.295
16.49,163.32,0.296
16.51,163.45,0.297
16.52,163.58,0.297
16.53,163.72,0.298
16.55,163.85,0.298
16.56,163.98,0.299
16.57,164.12,0.299
16.59,164.25,0.300
16.60,164.38,0.301
16.61,164.52,0.301
16.63,164.65,0.302
16.64,164.78,0.302
16.65,164.91,0.303
16.67,165.05,0.305
16.68,165.18,0.306
16.69,165.31,0.307
16.71,165.45,0.308
16.72,165.58,0.309
16.73,165.71,0.311
16.75,165.84,0.312
16.76,165.98,0.313
16.77,166.11,0.314
16.79,166.24,0.315
16.80,166.38,0.317
16.81,166.51,0.318
16.83,166.64,0.320
16.84,166.77,0.322
16.85,166.91,0.323
16.87,167.04,0.325
16.88,167.17,0.327
16.89,167.30,0.329
16.91,167.44,0.333
16.92,167.57,0.335
16.93,167.70,0.337
16.95,167.83,0.341
16.96,167.97,0.343
16.97,168.10,0.346
16.99,168.23,0.349
17.00,168.36,0.354
17.01,168.49,0.357
17.03,168.63,0.361
17.04,168.76,0.366
17.05,168.89,0.371
17.07,169.02,0.377
17.08,169.15,0.383
17.09,169.28,0.389
17.11,169.41,0.397
17.12,169.54,0.404
17.13,169.67,0.413
17.15,169.80,0.423
17.16,169.93,0.434
17.17,170.05,0.445
17.19,170.18,0.459
17.20,170.31,0.473
17.21,170.44,0.490
17.23,170.56,0.508
17.24,170.69,0.529
17.25,170.81,0.552
17.27,170.94,0.578
17.28,171.06,0.610
17.29,171.18,0.641
17.31,171.30,0.674
17.32,171.41,0.714
17.33,171.53,0.762
17.35,171.64,0.806
17.36,171.75,0.858
17.37,171.86,0.923
17.39,171.96,0.988
17.40,172.07,1.052
17.41,172.17,1.123
17.43,172.27,1.202
17.44,172.36,1.285
17.45,172.45,1.376
17.47,172.54,1.476
17.48,172.63,1.584
17.49,172.71,1.691
17.51,172.79,1.803
17.52,172.87,1.914
17.53,172.94,2.031
17.55,173.01,2.151
17.56,173.08,2.260
17.57,173.15,2.378
17.59,173.22,2.487
17.60,173.29,2.600
17.61,173.36,2.721
17.63,173.43,2.869
17.64,173.49,2.995
17.65,173.55,3.118
17.67,173.61,3.254
17.68,173.67,3.368
17.69,173.74,3.510
17.71,173.79,3.656
17.72,173.85,3.848
17.73,173.89,4.019
17.75,173.94,4.151
17.76,173.99,4.198
17.77,174.07,4.206
17.79,174.15,4.216
17.80,174.25,4.213
17.81,174.35,4.220
17.83,174.46,4.212
17.84,174.59,4.148
17.85,174.72,4.064
17.87,174.87,3.966
17.88,175.03,3.811
17.89,175.21,3.628
17.91,175.40,3.432
17.92,175.61,3.243
17.93,175.82,3.058
17.95,176.04,2.866
17.96,176.27,2.633
17.97,176.51,2.362
17.99,176.76,2.075
18.00,177.03,1.806
18.01,177.29,1.570
18.03,177.56,1.371
18.04,177.82,1.221
18.05,178.06,1.104
18.07,178.29,1.010
18.08,178.52,0.927
18.09,178.73,0.857
18.11,178.93,0.795
18.12,179.13,0.741
18.13,179.31,0.692
18.15,179.49,0.650
18.16,179.67,0.612
18.17,179.84,0.579
18.19,180.00,0.550
18.20,180.17,0.524
18.21,180.32,0.503
18.23,180.48,0.479
18.24,180.63,0.465
18.25,180.78,0.449
18.27,180.93,0.434
18.28,181.08,0.422
18.29,181.23,0.411
18.31,181.37,0.403
18.32,181.51,0.395
18.33,181.65,0.386
18.35,181.79,0.380
18.36,181.93,0.375
18.37,182.07,0.369
18.39,182.21,0.365
18.40,182.35,0.361
18.41,182.48,0.358
18.43,182.62,0.355
18.44,182.76,0.352
18.45,182.89,0.350
18.47,183.03,0.348
18.48,183.16,0.346
18.49,183.30,0.345
18.51,183.44,0.343
18.52,183.57,0.343
18.53,183.70,0.341
18.55,183.84,0.340
18.56,183.97,0.339
18.57,184.11,0.339
18.59,184.24,0.338
18.60,184.37,0.337
18.61,184.51,0.337
18.63,184.64,0.337
18.64,184.78,0.336
18.65,184.91,0.336
18.67,185.04,0.336
18.68,185.18,0.336
18.69,185.31,0.336
18.71,185.45,0.335
18.72,185.58,0.335
18.73,185.71,0.335
18.75,185.85,0.335
18.76,185.98,0.335
18.77,186.11,0.335
18.79,186.25,0.335
18.80,186.38,0.335
18.81,186.52,0.335
18.83,186.65,0.334
18.84,186.78,0.334
18.85,186.92,0.334
18.87,187.05,0.334
18.88,187.18,0.334
18.89,187.32,0.334
18.91,187.45,0.334
18.92,187.58,0.334
18.93,187.72,0.334
18.95,187.85,0.334
18.96,187.98,
18.97,188.12,
18.99,188.25,
19.00,,
19.01,,

[step]
Ramp 10.00 °C/min to 0.00 °C
Time,Temperature,Heat Flow (Normalized)
min,°C,W/g
20.01,190.09,-0.031
20.02,190.09,-0.031
20.03,190.09,-0.031
20.05,190.09,-0.031
20.06,190.08,-0.031
20.07,190.07,-0.034
20.09,190.04,-0.042
20.10,190.01,-0.053
20.11,189.96,-0.067
20.13,189.91,-0.087
20.14,189.84,-0.109
20.15,189.77,-0.135
20.17,189.69,-0.159
20.18,189.60,-0.184
20.19,189.50,-0.207
20.21,189.41,-0.228
20.22,189.30,-0.248
20.23,189.20,-0.265
20.25,189.09,-0.278
20.26,188.98,-0.292
20.27,188.86,-0.302
20.29,188.75,-0.313
20.30,188.63,-0.322
20.31,188.51,-0.330
20.33,188.39,-0.337
20.34,188.27,-0.343
20.35,188.15,-0.348
20.37,188.02,-0.354
20.38,187.90,-0.358
20.39,187.77,-0.362
20.41,187.65,-0.365
20.42,187.52,-0.368
20.43,187.40,-0.371
20.45,187.27,-0.373
20.46,187.14,-0.375
20.47,187.01,-0.377
20.49,186.88,-0.379
20.50,186.75,-0.380
20.51,186.62,-0.382
20.53,186.49,-0.383
20.54,186.36,-0.384
20.55,186.23,-0.385
20.57,186.10,-0.385
20.58,185.97,-0.386
20.59,185.84,-0.386
20.61,185.71,-0.387
20.62,185.58,-0.387
20.63,185.45,-0.387
20.65,185.32,-0.388
20.66,185.18,-0.388
20.67,185.05,-0.388
20.69,184.92,-0.389
20.70,184.79,-0.389
20.71,184.66,-0.389
20.73,184.53,-0.389
20.74,184.39,-0.389
20.75,184.26,-0.389
20.77,184.13,-0.389
20.78,184.00,-0.389
20.79,183.87,-0.389
20.81,183.73,-0.389
20.82,183.60,-0.389
20.83,183.47,-0.389
20.85,183.34,-0.390
20.86,183.20,-0.390
20.87,183.07,-0.390
20.89,182.94,-0.390
20.90,182.81,-0.390
20.91,182.68,-0.390
20.93,182.54,-0.390
20.94,182.41,-0.390
20.95,182.28,-0.390
20.97,182.15,-0.390
20.98,182.01,-0.390
20.99,181.88,-0.390
21.01,181.75,-0.390
21.02,181.62,-0.390
21.03,181.48,-0.390
21.05,181.35,-0.390
21.06,181.22,-0.390
21.07,181.09,-0.390
21.09,180.95,-0.390
21.10,180.82,-0.390
21.11,180.69,-0.390
21.13,180.55,-0.390
21.14,180.42,-0.390
21.15,180.29,-0.390
21.17,180.16,-0.389
21.18,180.02,-0.389
21.19,179.89,-0.389
21.21,179.76,-0.389
21.22,179.63,-0.389
21.23,179.49,-0.389
21.25,179.36,-0.389
21.26,179.23,-0.389
21.27,179.09,-0.389
21.29,178.96,-0.389
21.30,178.83,-0.389
21.31,178.70,-0.389
21.33,178.56,-0.389
21.34,178.43,-0.389
21.35,178.30,-0.389
21.37,178.16,-0.389
21.38,178.03,-0.389
21.39,177.90,-0.388
21.41,177.76,-0.388
21.42,177.63,-0.388
21.43,177.50,-0.388
21.45,177.36,-0.388
21.46,177.23,-0.388
21.47,177.10,-0.388
21.49,176.96,-0.388
21.50,176.83,-0.388
21.51,176.70,-0.388
21.53,176.56,-0.388
21.54,176.43,-0.387
21.55,176.30,-0.387
21.57,176.17,-0.387
21.58,176.03,-0.387
21.59,175.90,-0.387
21.61,175.77,-0.387
21.62,175.63,-0.387
21.63,175.50,-0.386
21.65,175.37,-0.386
21.66,175.24,-0.386
21.67,175.10,-0.386
21.69,174.97,-0.386
21.70,174.84,-0.386
21.71,174.70,-0.386
21.73,174.57,-0.386
21.74,174.44,-0.385
21.75,174.30,-0.385
21.77,174.17,-0.385
21.78,174.04,-0.385
21.79,173.90,-0.385
21.81,173.77,-0.385
21.82,173.64,-0.385
21.83,173.51,-0.385
21.85,173.37,-0.385
21.86,173.24,-0.384
21.87,173.11,-0.384
21.89,172.97,-0.384
21.90,172.84,-0.384
21.91,172.71,-0.384
21.93,172.57,-0.384
21.94,172.44,-0.384
21.95,172.31,-0.384
21.97,172.17,-0.383
21.98,172.04,-0.383
21.99,171.91,-0.383
22.01,171.77,-0.383
22.02,171.64,-0.383
22.03,171.51,-0.383
22.05,171.38,-0.383
22.06,171.24,-0.383
22.07,171.11,-0.382
22.09,170.98,-0.382
22.10,170.84,-0.382
22.11,170.71,-0.382
22.13,170.58,-0.382
22.14,170.44,-0.382
22.15,170.31,-0.382
22.17,170.18,-0.382
22.18,170.04,-0.382
22.19,169.91,-0.381
22.21,169.78,-0.381
22.22,169.64,-0.381
22.23,169.51,-0.381
22.25,169.38,-0.381
22.26,169.25,-0.381
22.27,169.11,-0.381
22.29,168.98,-0.381
22.30,168.85,-0.381
22.31,168.71,-0.381
22.33,168.58,-0.381
22.34,168.45,-0.380
22.35,168.31,-0.380
22.37,168.18,-0.380
22.38,168.05,-0.380
22.39,167.91,-0.380
22.41,167.78,-0.380
22.42,167.65,-0.380
22.43,167.51,-0.380
22.45,167.38,-0.380
22.46,167.25,-0.379
22.47,167.12,-0.379
22.49,166.98,-0.379
22.50,166.85,-0.379
22.51,166.71,-0.379
22.53,166.58,-0.379
22.54,166.45,-0.379
22.55,166.32,-0.379
22.57,166.18,-0.379
22.58,166.05,-0.379
22.59,165.92,-0.379
22.61,165.78,-0.379
22.62,165.65,-0.378
22.63,165.52,-0.378
22.65,165.38,-0.378
22.66,165.25,-0.378
22.67,165.12,-0.378
22.69,164.99,-0.378
22.70,164.85,-0.378
22.71,164.72,-0.378
22.73,164.58,-0.378
22.74,164.45,-0.378
22.75,164.32,-0.378
22.77,164.19,-0.378
22.78,164.05,-0.377
22.79,163.92,-0.377
22.81,163.79,-0.377
22.82,163.65,-0.377
22.83,163.52,-0.377
22.85,163.39,-0.377
22.86,163.25,-0.377
22.87,163.12,-0.377
22.89,162.99,-0.377
22.90,162.85,-0.377
22.91,162.72,-0.377
22.93,162.59,-0.377
22.94,162.45,-0.377
22.95,162.32,-0.376
22.97,162.19,-0.376
22.98,162.06,-0.376
22.99,161.92,-0.376
23.01,161.79,-0.376
23.02,161.65,-0.376
23.03,161.52,-0.376
23.05,161.39,-0.376
23.06,161.26,-0.376
23.07,161.12,-0.376
23.09,160.99,-0.375
23.10,160.86,-0.375
23.11,160.72,-0.375
23.13,160.59,-0.375
23.14,160.46,-0.375
23.15,160.32,-0.375
23.17,160.19,-0.375
23.18,160.06,-0.375
23.19,159.92,-0.375
23.21,159.79,-0.375
23.22,159.66,-0.375
23.23,159.52,-0.375
23.25,159.39,-0.375
23.26,159.26,-0.375
23.27,159.12,-0.375
23.29,158.99,-0.375
23.30,158.86,-0.374
23.31,158.72,-0.374
23.33,158.59,-0.374
23.34,158.46,-0.374
23.35,158.33,-0.374
23.37,158.19,-0.374
23.38,158.06,-0.374
23.39,157.93,-0.374
23.41,157.79,-0.374
23.42,157.66,-0.374
23.43,157.53,-0.374
23.45,157.39,-0.374
23.46,157.26,-0.373
23.47,157.13,-0.373
23.49,156.99,-0.373
23.50,156.86,-0.373
23.51,156.73,-0.373
23.53,156.59,-0.373
23.54,156.46,-0.373
23.55,156.33,-0.373
23.57,156.19,-0.373
23.58,156.06,-0.373
23.59,155.93,-0.373
23.61,155.79,-0.373
23.62,155.66,-0.373
23.63,155.53,-0.373
23.65,155.40,-0.373
23.66,155.26,-0.372
23.67,155.13,-0.372
23.69,155.00,-0.372
23.70,154.86,-0.372
23.71,154.73,-0.372
23.73,154.60,-0.372
23.74,154.46,-0.372
23.75,154.33,-0.372
23.77,154.20,-0.372
23.78,154.06,-0.372
23.79,153.93,-0.372
23.81,153.80,-0.372
23.82,153.67,-0.372
23.83,153.53,-0.372
23.85,153.40,-0.372
23.86,153.27,-0.372
23.87,153.13,-0.371
23.89,153.00,-0.371
23.90,152.87,-0.371
23.91,152.73,-0.371
23.93,152.60,-0.371
23.94,152.47,-0.371
23.95,152.33,-0.371
23.97,152.20,-0.371
23.98,152.07,-0.371
23.99,151.93,-0.371
24.01,151.80,-0.371
24.02,151.67,-0.371
24.03,151.53,-0.371
24.05,151.40,-0.371
24.06,151.27,-0.371
24.07,151.13,-0.371
24.09,151.00,-0.371
24.10,150.87,-0.370
24.11,150.74,-0.370
24.13,150.60,-0.370
24.14,150.47,-0.370
24.15,150.34,-0.370
24.17,150.20,-0.370
24.18,150.07,-0.370
24.19,149.94,-0.370
24.21,149.80,-0.370
24.22,149.67,-0.370
24.23,149.54,-0.370
24.25,149.40,-0.370
24.26,149.27,-0.370
24.27,149.14,-0.370
24.29,149.00,-0.370
24.30,148.87,-0.370
24.31,148.74,-0.370
24.33,148.60,-0.369
24.34,148.47,-0.369
24.35,148.34,-0.369
24.37,148.20,-0.369
24.38,148.07,-0.369
24.39,147.94,-0.369
24.41,147.81,-0.369
24.42,147.67,-0.369
24.43,147.54,-0.369
24.45,147.40,-0.369
24.46,147.27,-0.369
24.47,147.14,-0.369
24.49,147.00,-0.369
24.50,146.87,-0.369
24.51,146.74,-0.369
24.53,146.61,-0.369
24.54,146.47,-0.368
24.55,146.34,-0.368
24.57,146.21,-0.368
24.58,146.07,-0.368
24.59,145.94,-0.368
24.61,145.81,-0.368
24.62,145.67,-0.368
24.63,145.54,-0.368
24.65,145.41,-0.368
24.66,145.27,-0.368
24.67,145.14,-0.368
24.69,145.01,-0.368
24.70,144.88,-0.368
24.71,144.74,-0.368
24.73,144.61,-0.368
24.74,144.47,-0.368
24.75,144.34,-0.368
24.77,144.21,-0.367
24.78,144.07,-0.367
24.79,143.94,-0.367
24.81,143.81,-0.367
24.82,143.68,-0.367
24.83,143.54,-0.367
24.85,143.41,-0.367
24.86,143.28,-0.367
24.87,143.14,-0.367
24.89,143.01,-0.367
24.90,142.88,-0.367
24.91,142.74,-0.367
24.93,142.61,-0.367
24.94,142.48,-0.367
24.95,142.34,-0.367
24.97,142.21,-0.367
24.98,142.08,-0.367
24.99,141.94,-0.367
25.01,141.81,-0.367
25.02,141.68,-0.366
25.03,141.55,-0.366
25.05,141.41,-0.366
25.06,141.28,-0.366
25.07,141.14,-0.366
25.09,141.01,-0.366
25.10,140.88,-0.366
25.11,140.75,-0.366
25.13,140.61,-0.366
25.14,140.48,-0.366
25.15,140.35,-0.366
25.17,140.21,-0.366
25.18,140.08,-0.366
25.19,139.95,-0.366
25.21,139.81,-0.366
25.22,139.68,-0.366
25.23,139.55,-0.366
25.25,139.41,-0.366
25.26,139.28,-0.365
25.27,139.15,-0.365
25.29,139.01,-0.365
25.30,138.88,-0.365
25.31,138.75,-0.365
25.33,138.62,-0.365
25.34,138.48,-0.365
25.35,138.35,-0.365
25.37,138.22,-0.365
25.38,138.08,-0.365
25.39,137.95,-0.365
25.41,137.82,-0.365
25.42,137.68,-0.365
25.43,137.55,-0.365
25.45,137.42,-0.365
25.46,137.28,-0.364
25.47,137.15,-0.364
25.49,137.02,-0.364
[...]
76.07,31.25,-0.275
76.09,31.12,-0.274
76.10,30.98,-0.274
76.11,30.85,-0.274
76.13,30.72,-0.273
76.14,30.58,-0.273
76.15,30.45,-0.273
76.17,30.32,-0.272
76.18,30.18,-0.272
76.19,30.05,-0.271
76.21,29.92,-0.271
76.22,29.78,-0.271
76.23,29.65,-0.270
76.25,29.52,-0.270
76.26,29.38,-0.270
76.27,29.25,-0.269
76.29,29.12,-0.269
76.30,28.98,-0.269
76.31,28.85,-0.269
76.33,28.72,-0.268
76.34,28.58,-0.268
76.35,28.45,-0.268
76.37,28.32,-0.268
76.38,28.18,-0.267
76.39,28.05,-0.267
76.41,27.92,-0.266
76.42,27.78,-0.266
76.43,27.65,-0.266
76.45,27.52,-0.266
76.46,27.38,-0.266
76.47,27.25,-0.265
76.49,27.12,-0.265
76.50,26.98,-0.265
76.51,26.85,-0.265
76.53,26.72,-0.265
76.54,26.58,-0.264
76.55,26.45,-0.264
76.57,26.32,-0.264
76.58,26.18,-0.264
76.59,26.05,-0.264
76.61,25.92,-0.263
76.62,25.78,-0.263
76.63,25.65,-0.263
76.65,25.52,-0.263
76.66,25.38,-0.263
76.67,25.25,-0.262
76.69,25.12,-0.262
76.70,24.98,-0.262
76.71,24.85,-0.262
76.73,24.72,-0.261
76.74,24.58,-0.261
76.75,24.45,-0.261
76.77,24.32,-0.260
76.78,24.18,-0.260
76.79,24.05,-0.260
76.81,23.92,-0.260
76.82,23.78,-0.260
76.83,23.65,-0.259
76.85,23.52,-0.259
76.86,23.38,-0.259
76.87,23.25,-0.259
76.89,23.12,-0.258
76.90,22.99,-0.258
76.91,22.85,-0.258
76.93,22.72,-0.258
76.94,22.59,-0.257
76.95,22.45,-0.257
76.97,22.32,-0.257
76.98,22.19,-0.257
76.99,22.05,-0.257
77.01,21.92,-0.257
77.02,21.79,-0.256
77.03,21.65,-0.256
77.05,21.52,-0.256
77.06,21.39,-0.256
77.07,21.25,-0.256
77.09,21.12,-0.256
77.10,20.99,-0.256
77.11,20.85,-0.255
77.13,20.72,-0.255
77.14,20.59,-0.255
77.15,20.45,-0.255
77.17,20.32,-0.255
77.18,20.19,-0.255
77.19,20.05,-0.255
77.21,19.92,-0.254
77.22,19.79,-0.254
77.23,19.65,-0.254
77.25,19.52,-0.254
77.26,19.39,-0.254
77.27,19.26,-0.254
77.29,19.12,-0.253
77.30,18.99,-0.239
77.31,18.84,-0.171
77.33,18.71,-0.247
77.34,18.58,-0.247
77.35,18.45,-0.246
77.37,18.31,-0.247
77.38,18.18,-0.246
77.39,18.05,-0.246
77.41,17.92,-0.246
77.42,17.79,-0.246
77.43,17.65,-0.246
77.45,17.52,-0.246
77.46,17.39,-0.246
77.47,17.25,-0.246
77.49,17.12,-0.246
77.50,16.99,-0.246
77.51,16.85,-0.246
77.53,16.72,-0.246
77.54,16.59,-0.246
77.55,16.46,-0.246
77.57,16.32,-0.246
77.58,16.19,-0.246
77.59,16.06,-0.246
77.61,15.92,-0.246
77.62,15.79,-0.246
77.63,15.66,-0.246
77.65,15.52,-0.246
77.66,15.39,-0.246
77.67,15.26,-0.246
77.69,15.13,-0.246
77.70,14.99,-0.246
77.71,14.86,-0.246
77.73,14.73,-0.245
77.74,14.59,-0.245
77.75,14.46,-0.245
77.77,14.33,-0.245
77.78,14.19,-0.245
77.79,14.06,-0.245
77.81,13.93,-0.245
77.82,13.79,-0.245
77.83,13.66,-0.245
77.85,13.53,-0.245
77.86,13.39,-0.244
77.87,13.26,-0.244
77.89,13.13,-0.244
77.90,13.00,-0.244
77.91,12.86,-0.244
77.93,12.73,-0.244
77.94,12.60,-0.244
77.95,12.46,-0.244
77.97,12.33,-0.244
77.98,12.20,-0.244
77.99,12.07,-0.244
78.01,11.93,-0.243
78.02,11.80,-0.243
78.03,11.66,-0.243
78.05,11.53,-0.243
78.06,11.40,-0.243
78.07,11.26,-0.243
78.09,11.13,-0.243
78.10,11.00,-0.243
78.11,10.87,-0.243
78.13,10.73,-0.242
78.14,10.60,-0.242
78.15,10.47,-0.242
78.17,10.33,-0.242
78.18,10.20,-0.242
78.19,10.07,-0.242
78.21,9.93,-0.242
78.22,9.80,-0.242
78.23,9.67,-0.242
78.25,9.53,-0.242
78.26,9.40,-0.242
78.27,9.27,-0.241
78.29,9.13,-0.241
78.30,9.00,-0.242
78.31,8.87,-0.242
78.33,8.73,-0.242
78.34,8.60,-0.241
78.35,8.47,-0.241
78.37,8.33,-0.241
78.38,8.20,-0.241
78.39,8.07,-0.241
78.41,7.93,-0.241
78.42,7.80,-0.241
78.43,7.67,-0.241
78.45,7.53,-0.240
78.46,7.40,-0.240
78.47,7.27,-0.240
78.49,7.14,-0.240
78.50,7.00,-0.240
78.51,6.87,-0.240
78.53,6.73,-0.240
78.54,6.60,-0.240
78.55,6.47,-0.240
78.57,6.33,-0.239
78.58,6.20,-0.239
78.59,6.07,-0.239
78.61,5.93,-0.239
78.62,5.80,-0.239
78.63,5.67,-0.239
78.65,5.53,-0.239
78.66,5.40,-0.239
78.67,5.27,-0.239
78.69,5.13,-0.238
78.70,5.00,-0.238
78.71,4.87,-0.238
78.73,4.73,-0.238
78.74,4.60,-0.238
78.75,4.47,-0.238
78.77,4.33,-0.238
78.78,4.20,-0.238
78.79,4.07,-0.238
78.81,3.93,-0.238
78.82,3.80,-0.238
78.83,3.66,-0.238
78.85,3.53,-0.238
78.86,3.40,-0.237
78.87,3.26,-0.237
78.89,3.13,-0.237
78.90,3.00,-0.237
78.91,2.87,-0.237
78.93,2.73,-0.237
78.94,2.60,-0.237
78.95,2.46,
78.97,2.33,
78.98,2.20,
78.99,2.06,
79.00,,

[step]
Ramp 10.00 °C/min to 30.00 °C
Time,Temperature,Heat Flow (Normalized)
min,°C,W/g
80.01,0.13,-0.013
80.01,0.13,-0.013
80.01,0.13,-0.013
80.02,0.13,-0.013
80.02,0.13,-0.013
80.02,0.13,-0.013
80.03,0.13,-0.013
80.03,0.13,-0.013
80.03,0.13,-0.013
80.04,0.13,-0.013
80.04,0.14,-0.013
80.04,0.14,-0.013
80.05,0.14,-0.013
80.05,0.14,-0.013
80.05,0.14,-0.013
80.06,0.14,-0.012
80.06,0.14,-0.012
80.06,0.15,-0.012
80.07,0.15,-0.012
80.07,0.16,-0.011
80.07,0.16,-0.011
80.08,0.16,-0.010
80.08,0.17,-0.009
80.08,0.17,-0.008
80.09,0.18,-0.006
80.09,0.19,-0.004
80.09,0.20,-0.002
80.10,0.20,0.000
80.10,0.21,0.002
80.10,0.22,0.004
80.11,0.23,0.006
80.11,0.25,0.008
80.11,0.26,0.010
80.12,0.27,0.013
80.12,0.28,0.015
80.12,0.30,0.018
80.13,0.31,0.021
80.13,0.33,0.024
80.13,0.34,0.027
80.14,0.36,0.030
80.14,0.37,0.033
80.14,0.39,0.036
80.15,0.41,0.039
80.15,0.43,0.043
80.15,0.45,0.047
80.16,0.47,0.050
80.16,0.49,0.053
80.16,0.51,0.056
80.17,0.53,0.060
80.17,0.55,0.063
80.17,0.57,0.066
80.18,0.59,0.069
80.18,0.61,0.072
80.18,0.63,0.076
80.19,0.66,0.078
80.19,0.68,0.081
80.19,0.70,0.085
80.20,0.73,0.088
80.20,0.75,0.091
80.20,0.77,0.093
80.21,0.80,0.096
80.21,0.82,0.098
80.21,0.84,0.100
80.22,0.87,0.103
80.22,0.89,0.106
80.22,0.92,0.109
80.23,0.94,0.111
80.23,0.97,0.113
80.23,0.99,0.115
80.24,1.02,0.117
80.24,1.05,0.119
80.24,1.07,0.121
80.25,1.10,0.124
80.25,1.12,0.125
80.25,1.15,0.127
80.26,1.18,0.129
80.26,1.21,0.131
80.26,1.23,0.133
80.27,1.26,0.135
80.27,1.29,0.136
80.27,1.31,0.138
80.28,1.34,0.140
80.28,1.37,0.142
80.28,1.40,0.143
80.29,1.43,0.145
80.29,1.45,0.146
80.29,1.48,0.148
80.30,1.51,0.149
80.30,1.54,0.151
80.30,1.57,0.152
80.31,1.60,0.154
80.31,1.63,0.155
80.31,1.66,0.156
80.32,1.69,0.158
80.32,1.71,0.159
80.32,1.74,0.160
80.33,1.77,0.162
80.33,1.80,0.163
80.33,1.83,0.164
80.34,1.86,0.165
80.34,1.89,0.166
80.34,1.92,0.167
80.35,1.95,0.168
80.35,1.98,0.169
80.35,2.01,0.170
80.36,2.04,0.171
80.36,2.07,0.173
80.36,2.10,0.174
80.37,2.13,0.175
80.37,2.16,0.175
80.37,2.19,0.176
80.38,2.22,0.177
80.38,2.25,0.177
80.38,2.28,0.178
80.39,2.32,0.178
80.39,2.35,0.179
80.39,2.38,0.180
80.40,2.41,0.181
80.40,2.44,0.182
80.40,2.47,0.183
80.41,2.50,0.184
80.41,2.53,0.184
80.41,2.56,0.184
80.42,2.60,0.185
80.42,2.63,0.186
80.42,2.66,0.187
80.43,2.69,0.187
80.43,2.72,0.188
80.43,2.75,0.188
80.44,2.78,0.189
80.44,2.81,0.190
80.44,2.85,0.190
80.45,2.88,0.190
80.45,2.91,0.190
80.45,2.94,0.190
80.46,2.97,0.191
80.46,3.00,0.192
80.46,3.04,0.192
80.47,3.07,0.193
80.47,3.10,0.193
80.47,3.13,0.194
80.48,3.16,0.195
80.48,3.19,0.195
80.48,3.23,0.195
80.49,3.26,0.195
80.49,3.29,0.195
80.49,3.32,0.196
80.50,3.35,0.197
80.50,3.39,0.197
80.50,3.42,0.197
80.51,3.45,0.197
80.51,3.48,0.198
80.51,3.51,0.198
80.52,3.55,0.198
80.52,3.58,0.198
80.52,3.61,0.199
80.53,3.64,0.199
80.53,3.68,0.199
80.53,3.71,0.200
80.54,3.74,0.200
80.54,3.77,0.200
80.54,3.80,0.201
80.55,3.84,0.201
80.55,3.87,0.201
80.55,3.90,0.201
80.56,3.93,0.202
80.56,3.97,0.202
80.56,4.00,0.202
80.57,4.03,0.202
80.57,4.06,0.202
80.57,4.10,0.202
80.58,4.13,0.202
80.58,4.16,0.203
80.58,4.19,0.203
80.59,4.23,0.203
80.59,4.26,0.203
80.59,4.29,0.203
80.60,4.32,0.204
80.60,4.36,0.204
80.60,4.39,0.204
80.61,4.42,0.204
80.61,4.45,0.205
80.61,4.49,0.205
80.62,4.52,0.205
80.62,4.55,0.205
80.62,4.58,0.205
80.63,4.61,0.205
80.63,4.65,0.205
80.63,4.68,0.205
80.64,4.71,0.205
80.64,4.75,0.206
80.64,4.78,0.206
80.65,4.81,0.206
80.65,4.84,0.206
80.65,4.88,0.206
80.66,4.91,0.206
80.66,4.94,0.206
80.66,4.97,0.206
80.67,5.01,0.206
80.67,5.04,0.206
80.67,5.07,0.207
80.68,5.11,0.207
80.68,5.14,0.207
80.68,5.17,0.207
80.69,5.20,0.207
80.69,5.24,0.207
80.69,5.27,0.208
80.70,5.30,0.208
80.70,5.34,0.208
80.70,5.37,0.208
80.71,5.40,0.208
80.71,5.44,0.208
80.71,5.47,0.208
80.72,5.50,0.208
80.72,5.53,0.208
80.72,5.56,0.208
80.73,5.60,0.208
80.73,5.63,0.208
80.73,5.66,0.208
80.74,5.70,0.208
80.74,5.73,0.208
80.74,5.76,0.208
80.75,5.80,0.209
80.75,5.83,0.209
80.75,5.86,0.209
80.76,5.89,0.209
80.76,5.93,0.209
80.76,5.96,0.209
80.77,5.99,0.209
80.77,6.03,0.209
80.77,6.06,0.209
80.78,6.09,0.209
80.78,6.13,0.209
80.78,6.16,0.209
80.79,6.19,0.209
80.79,6.22,0.209
80.79,6.26,0.209
80.80,6.29,0.209
80.80,6.32,0.209
80.80,6.36,0.209
80.81,6.39,0.209
80.81,6.42,0.209
80.81,6.45,0.209
80.82,6.49,0.209
80.82,6.52,0.210
80.82,6.55,0.210
80.83,6.59,0.210
80.83,6.62,0.210
80.83,6.65,0.210
80.84,6.68,0.210
80.84,6.72,0.210
80.84,6.75,0.210
80.85,6.78,0.210
80.85,6.82,0.210
80.85,6.85,0.210
80.86,6.88,0.210
80.86,6.92,0.210
80.86,6.95,0.210
80.87,6.98,0.210
80.87,7.01,0.210
80.87,7.05,0.210
80.88,7.08,0.211
80.88,7.11,0.211
80.88,7.15,0.211
80.89,7.18,0.211
80.89,7.21,0.211
80.89,7.25,0.211
80.90,7.28,0.211
80.90,7.31,0.211
80.90,7.35,0.211
80.91,7.38,0.211
80.91,7.41,0.211
80.91,7.45,0.211
80.92,7.48,0.211
80.92,7.51,0.211
80.92,7.54,0.211
80.93,7.58,0.211
80.93,7.61,0.211
80.93,7.64,0.211
80.94,7.68,0.211
80.94,7.71,0.211
80.94,7.74,0.211
80.95,7.78,0.211
80.95,7.81,0.211
80.95,7.84,0.211
80.96,7.87,0.211
80.96,7.91,0.212
80.96,7.94,0.212
80.97,7.97,0.212
80.97,8.01,0.212
80.97,8.04,0.212
80.98,8.07,0.212
80.98,8.11,0.212
80.98,8.14,0.212
80.99,8.17,0.212
80.99,8.21,0.212
80.99,8.24,0.212
81.00,8.27,0.212
81.00,8.31,0.212
81.00,8.34,0.212
81.01,8.37,0.212
81.01,8.40,0.212
81.01,8.44,0.212
81.02,8.47,0.212
81.02,8.50,0.212
81.02,8.54,0.212
81.03,8.57,0.212
81.03,8.60,0.212
81.03,8.64,0.212
81.04,8.67,0.212
81.04,8.70,0.212
81.04,8.74,0.212
81.05,8.77,0.213
81.05,8.80,0.213
81.05,8.83,0.213
81.06,8.87,0.213
81.06,8.90,0.213
81.06,8.93,0.213
81.07,8.97,0.213
81.07,9.00,0.213
81.07,9.03,0.213
81.08,9.07,0.213
81.08,9.10,0.213
81.08,9.13,0.213
81.09,9.17,0.213
81.09,9.20,0.213
81.09,9.23,0.213
81.10,9.27,0.213
81.10,9.30,0.213
81.10,9.33,0.213
81.11,9.37,0.213
81.11,9.40,0.213
81.11,9.43,0.213
81.12,9.47,0.213
81.12,9.50,0.213
81.12,9.53,0.213
81.13,9.57,0.213
81.13,9.60,0.213
81.13,9.63,0.213
81.14,9.66,0.213
81.14,9.70,0.213
81.14,9.73,0.214
81.15,9.77,0.214
81.15,9.80,0.214
81.15,9.83,0.214
81.16,9.86,0.214
81.16,9.90,0.214
81.16,9.93,0.214
81.17,9.96,0.214
81.17,10.00,0.214
81.17,10.03,0.214
81.18,10.06,0.214
81.18,10.10,0.214
81.18,10.13,0.214
81.19,10.16,0.214
81.19,10.20,0.214
81.19,10.23,0.214
81.20,10.26,0.214
81.20,10.30,0.214
81.20,10.33,0.214
81.21,10.36,0.214
81.21,10.40,0.214
81.21,10.43,0.214
81.22,10.46,0.214
81.22,10.49,0.214
81.22,10.53,0.214
81.23,10.56,0.214
81.23,10.60,0.214
81.23,10.63,0.214
81.24,10.66,0.214
81.24,10.69,0.214
81.24,10.73,0.214
81.25,10.76,0.214
81.25,10.79,0.215
81.25,10.83,0.215
81.26,10.86,0.215
81.26,10.89,0.215
81.26,10.93,0.215
81.27,10.96,0.215
81.27,10.99,0.215
81.27,11.03,0.215
81.28,11.06,0.215
81.28,11.09,0.215
81.28,11.13,0.215
81.29,11.16,0.215
81.29,11.19,0.215
81.29,11.23,0.215
81.30,11.26,0.215
81.30,11.29,0.215
81.30,11.33,0.215
81.31,11.36,0.215
81.31,11.39,0.215
81.31,11.43,0.215
81.32,11.46,0.215
81.32,11.49,0.215
81.32,11.53,0.215
81.33,11.56,0.215
81.33,11.59,0.215
81.33,11.63,0.215
81.34,11.66,0.215
81.34,11.69,0.215
81.34,11.73,0.215
81.35,11.76,0.215
81.35,11.79,0.215
81.35,11.83,0.215
81.36,11.86,0.215
81.36,11.89,0.215
81.36,11.93,0.215
81.37,11.96,0.215
81.37,11.99,0.216
81.37,12.03,0.216
81.38,12.06,0.216
81.38,12.09,0.216
81.38,12.13,0.216
81.39,12.16,0.216
81.39,12.19,0.216
81.39,12.23,0.216
81.40,12.26,0.216
81.40,12.29,0.216
81.40,12.33,0.216
81.41,12.36,0.216
81.41,12.39,0.216
81.41,12.43,0.216
81.42,12.46,0.216
81.42,12.49,0.216
81.42,12.53,0.216
81.43,12.56,0.216
81.43,12.59,0.216
81.43,12.63,0.216
81.44,12.66,0.216
81.44,12.69,0.216
81.44,12.72,0.216
81.45,12.76,0.216
81.45,12.79,0.216
81.45,12.82,0.216
81.46,12.86,0.216
81.46,12.89,0.216
81.46,12.93,0.216
81.47,12.96,0.216
81.47,12.99,0.216
81.47,13.03,0.216
81.48,13.06,0.216
81.48,13.09,0.216
81.48,13.12,0.216
81.49,13.16,0.216
81.49,13.19,0.216
81.49,13.22,0.217
81.50,13.26,0.217
81.50,13.29,0.217
81.50,13.33,0.217
81.51,13.36,0.217
81.51,13.39,0.217
81.51,13.43,0.217
81.52,13.46,0.217
81.52,13.49,0.217
81.52,13.52,0.217
81.53,13.56,0.217
81.53,13.59,0.217
81.53,13.63,0.217
81.54,13.66,0.217
81.54,13.69,0.217
81.54,13.73,0.217
81.55,13.76,0.217
81.55,13.79,0.217
81.55,13.83,0.217
81.56,13.86,0.217
81.56,13.89,0.217
81.56,13.92,0.217
81.57,13.96,0.217
81.57,13.99,0.217
81.57,14.02,0.217
81.58,14.06,0.217
81.58,14.09,0.217
81.58,14.13,0.217
81.59,14.16,0.217
81.59,14.19,0.217
81.59,14.22,0.217
81.60,14.26,0.217
81.60,14.29,0.217
81.60,14.32,0.217
81.61,14.36,0.217
81.61,14.39,0.217
81.61,14.42,0.217
81.62,14.46,0.217
81.62,14.49,0.217
81.62,14.52,0.217
81.63,14.56,0.217
81.63,14.59,0.217
81.63,14.62,0.217
81.64,14.66,0.217
81.64,14.69,0.217
81.64,14.72,0.217
81.65,14.76,0.217
81.65,14.79,0.218
81.65,14.82,0.218
81.66,14.86,0.218
81.66,14.89,0.218
81.66,14.92,0.218
81.67,14.96,0.218
81.67,14.99,0.218
81.67,15.02,0.218
81.68,15.06,0.218
81.68,15.09,0.218
81.68,15.12,0.218
81.69,15.16,0.218
81.69,15.19,0.218
81.69,15.22,0.218
81.70,15.26,0.218
81.70,15.29,0.218
81.70,15.32,0.218
81.71,15.36,0.218
81.71,15.39,0.218
81.71,15.42,0.218
81.72,15.46,0.218
81.72,15.49,0.218
81.72,15.52,0.218
81.73,15.56,0.218
81.73,15.59,0.218
81.73,15.62,0.218
81.74,15.66,0.218
81.74,15.69,0.218
81.74,15.72,0.218
81.75,15.76,0.218
81.75,15.79,0.218
81.75,15.82,0.218
81.76,15.86,0.218
81.76,15.89,0.218
81.76,15.92,0.218
81.77,15.96,0.218
81.77,15.99,0.218
81.77,16.02,0.218
81.78,16.06,0.218
81.78,16.09,0.218
81.78,16.12,0.218
81.79,16.16,0.218
81.79,16.19,0.218
81.79,16.22,0.218
81.80,16.26,0.218
81.80,16.29,0.218
81.80,16.32,0.218
81.81,16.36,0.218
81.81,16.39,0.219
81.81,16.42,0.219
81.82,16.46,0.219
81.82,16.49,0.219
81.82,16.52,0.219
81.83,16.56,0.219
81.83,16.59,0.219
81.83,16.62,0.219
81.84,16.66,0.219
81.84,16.69,0.219
81.84,16.72,0.219
81.85,16.76,0.219
81.85,16.79,0.219
81.85,16.82,0.219
81.86,16.86,0.219
81.86,16.89,0.219
81.86,16.92,0.219
81.87,16.96,0.219
81.87,16.99,0.219
81.87,17.02,0.219
81.88,17.06,0.219
81.88,17.09,0.219
81.88,17.12,0.219
81.89,17.16,0.219
81.89,17.19,0.219
81.89,17.22,0.219
81.90,17.26,0.219
81.90,17.29,0.219
81.90,17.32,0.219
81.91,17.36,0.219
81.91,17.39,0.219
81.91,17.42,0.219
81.92,17.46,0.219
81.92,17.49,0.219
81.92,17.52,0.219
81.93,17.56,0.219
81.93,17.59,0.219
81.93,17.62,0.219
81.94,17.66,0.219
81.94,17.69,0.219
81.94,17.72,0.219
81.95,17.76,0.219
81.95,17.79,0.219
81.95,17.82,0.219
81.96,17.86,0.219
81.96,17.89,0.219
81.96,17.92,0.219
81.97,17.96,0.219
81.97,17.99,0.219
81.97,18.02,0.219
81.98,18.06,0.219
81.98,18.09,0.220
81.98,18.12,0.220
81.99,18.16,0.220
81.99,18.19,0.220
81.99,18.22,0.220
82.00,18.26,0.220
82.00,18.29,0.220
82.00,18.32,0.220
82.01,18.36,0.220
82.01,18.39,0.220
82.01,18.42,0.220
82.02,18.46,0.220
82.02,18.49,0.220
82.02,18.52,0.220
82.03,18.56,0.220
82.03,18.59,0.220
82.03,18.62,0.220
82.04,18.66,0.220
82.04,18.69,0.220
82.04,18.72,0.220
82.05,18.76,0.220
82.05,18.79,0.220
82.05,18.82,0.220
82.06,18.86,0.220
82.06,18.89,0.220
82.06,18.92,0.220
82.07,18.96,0.220
82.07,18.99,0.220
82.07,19.02,0.220
82.08,19.06,0.220
82.08,19.09,0.220
82.08,19.12,0.220
82.09,19.16,0.220
82.09,19.19,0.220
82.09,19.22,0.220
82.10,19.26,0.220
82.10,19.29,0.220
82.10,19.32,0.220
82.11,19.36,0.220
82.11,19.39,0.220
82.11,19.42,0.220
82.12,19.46,0.220
82.12,19.49,0.220
82.12,19.52,0.220
82.13,19.56,0.220
82.13,19.59,0.220
82.13,19.62,0.220
82.14,19.66,0.221
82.14,19.69,0.221
82.14,19.72,0.221
82.15,19.76,0.221
82.15,19.79,0.221
82.15,19.82,0.221
82.16,19.86,0.221
82.16,19.89,0.221
82.16,19.92,0.221
82.17,19.96,0.221
82.17,19.99,0.221
82.17,20.02,0.221
82.18,20.06,0.221
82.18,20.09,0.221
82.18,20.12,0.221
82.19,20.16,0.221
82.19,20.19,0.221
82.19,20.22,0.221
82.20,20.26,0.221
82.20,20.29,0.221
82.20,20.33,0.221
82.21,20.36,0.221
82.21,20.39,0.221
82.21,20.42,0.221
82.22,20.46,0.221
82.22,20.49,0.221
82.22,20.53,0.221
82.23,20.56,0.221
82.23,20.59,0.221
82.23,20.62,0.221
82.24,20.66,0.221
82.24,20.69,0.221
82.24,20.72,0.221
82.25,20.76,0.221
82.25,20.79,0.221
82.25,20.83,0.221
82.26,20.86,0.221
82.26,20.89,0.221
82.26,20.92,0.221
82.27,20.96,0.221
82.27,20.99,0.221
82.27,21.02,0.221
82.28,21.06,0.221
82.28,21.09,0.221
82.28,21.12,0.222
82.29,21.16,0.222
82.29,21.19,0.222
82.29,21.22,0.222
82.30,21.26,0.222
82.30,21.29,0.222
82.30,21.33,0.222
82.31,21.36,0.222
82.31,21.39,0.222
82.31,21.42,0.222
82.32,21.46,0.222
82.32,21.49,0.222
82.32,21.52,0.222
82.33,21.56,0.222
82.33,21.59,0.222
82.33,21.62,0.222
82.34,21.66,0.222
82.34,21.69,0.222
82.34,21.73,0.222
82.35,21.76,0.222
82.35,21.79,0.222
82.35,21.82,0.222
82.36,21.86,0.222
82.36,21.89,0.222
82.36,21.93,0.222
82.37,21.96,0.222
82.37,21.99,0.222
82.37,22.03,0.222
82.38,22.06,0.222
82.38,22.09,0.222
82.38,22.13,0.222
82.39,22.16,0.222
82.39,22.19,0.222
82.39,22.23,0.222
82.40,22.26,0.222
82.40,22.29,0.222
82.40,22.33,0.222
82.41,22.36,0.222
82.41,22.39,0.222
82.41,22.43,0.222
82.42,22.46,0.222
82.42,22.49,0.222
82.42,22.53,0.222
82.43,22.56,0.222
82.43,22.59,0.222
82.43,22.63,0.223
82.44,22.66,0.223
82.44,22.69,0.223
82.44,22.73,0.223
82.45,22.76,0.223
82.45,22.79,0.223
82.45,22.83,0.223
82.46,22.86,0.223
82.46,22.89,0.223
82.46,22.93,0.223
82.47,22.96,0.223
82.47,22.99,0.223
82.47,23.03,0.223
82.48,23.06,0.223
82.48,23.09,0.223
82.48,23.13,0.223
82.49,23.16,0.223
82.49,23.19,0.223
82.49,23.23,0.223
82.50,23.26,0.223
82.50,23.29,0.223
82.50,23.33,0.223
82.51,23.36,0.223
82.51,23.39,0.223
82.51,23.43,0.223
82.52,23.46,0.223
82.52,23.49,0.223
82.52,23.53,0.223
82.53,23.56,0.223
82.53,23.59,0.223
82.53,23.63,0.223
82.54,23.66,0.223
82.54,23.69,0.223
82.54,23.73,0.223
82.55,23.76,0.223
82.55,23.79,0.223
82.55,23.83,0.223
82.56,23.86,0.223
82.56,23.89,0.223
82.56,23.93,0.223
82.57,23.96,0.223
82.57,23.99,0.223
82.57,24.03,0.224
82.58,24.06,0.224
82.58,24.09,0.224
82.58,24.13,0.224
82.59,24.16,0.224
82.59,24.19,0.224
82.59,24.23,0.224
82.60,24.26,0.224
82.60,24.29,0.224
82.60,24.33,0.224
82.61,24.36,0.224
82.61,24.39,0.224
82.61,24.43,0.224
82.62,24.46,0.224
82.62,24.49,0.224
82.62,24.53,0.224
82.63,24.56,0.224
82.63,24.59,0.224
82.63,24.63,0.224
82.64,24.66,0.224
82.64,24.69,0.224
82.64,24.73,0.224
82.65,24.76,0.224
82.65,24.79,0.224
82.65,24.83,0.224
82.66,24.86,0.224
82.66,24.89,0.224
82.66,24.93,0.224
82.67,24.96,0.224
82.67,24.99,0.224
82.67,25.03,0.224
82.68,25.06,0.224
82.68,25.09,0.224
82.68,25.13,0.224
82.69,25.16,0.224
82.69,25.19,0.224
82.69,25.23,0.224
82.70,25.26,0.224
82.70,25.30,0.224
82.70,25.33,0.224
82.71,25.36,0.224
82.71,25.39,0.224
82.71,25.43,0.225
82.72,25.46,0.225
82.72,25.50,0.225
82.72,25.53,0.225
82.73,25.56,0.225
82.73,25.60,0.225
82.73,25.63,0.225
82.74,25.66,0.225
82.74,25.69,0.225
82.74,25.73,0.225
82.75,25.76,0.225
82.75,25.80,0.225
82.75,25.83,0.225
82.76,25.86,0.225
82.76,25.89,0.225
82.76,25.93,0.225
82.77,25.96,0.225
82.77,26.00,0.225
82.77,26.03,0.225
82.78,26.06,0.225
82.78,26.09,0.225
82.78,26.13,0.225
82.79,26.16,0.225
82.79,26.20,0.225
82.79,26.23,0.225
82.80,26.26,0.225
82.80,26.29,0.225
82.80,26.33,0.225
82.81,26.36,0.225
82.81,26.39,0.225
82.81,26.43,0.225
82.82,26.46,0.225
82.82,26.50,0.225
82.82,26.53,0.225
82.83,26.56,0.225
82.83,26.59,0.225
82.83,26.63,0.225
82.84,26.66,0.225
82.84,26.70,0.225
82.84,26.73,0.225
82.85,26.76,0.225
82.85,26.80,0.226
82.85,26.83,0.226
82.86,26.86,0.226
82.86,26.90,0.226
82.86,26.93,0.226
82.87,26.96,0.226
82.87,27.00,0.226
82.87,27.03,0.226
82.88,27.06,0.226
82.88,27.10,0.226
82.88,27.13,0.226
82.89,27.16,0.226
82.89,27.20,0.226
82.89,27.23,0.226
82.90,27.26,0.226
82.90,27.30,0.226
82.90,27.33,0.226
82.91,27.36,0.226
82.91,27.40,0.226
82.91,27.43,0.226
82.92,27.46,0.226
82.92,27.50,0.226
82.92,27.53,0.226
82.93,27.56,0.226
82.93,27.60,0.226
82.93,27.63,0.226
82.94,27.66,0.226
82.94,27.70,0.226
82.94,27.73,0.226
82.95,27.76,0.226
82.95,27.80,
82.95,27.83,
82.96,27.86,
82.96,27.90,
82.96,27.93,
82.97,27.96,
82.97,28.00,
82.97,28.03,
82.98,28.06,
82.98,28.10,
82.98,28.13,
82.99,28.16,
82.99,28.20,
82.99,28.23,
83.00,28.26,
83.00,,
83.00,,
83.01,,