File: DSC/2025_06_01_Nifedipine_0C_190C_10Cmin_x3.csv
Filename,2025_06_01_Nifedipine_0C_190C_10Cmin_x3
Instrument name,DSC2A-00468 (192.168.1.100)
Operator,Yarger
rundate,6/1/2025
Sample name,2025_06_01_Nifedipine_0C_190C_10Cmin_x3
proceduresegments,Data Off ; Equilibrate 0.00 °C; Data On ; Ramp 10.00 °C/min to 190.00 °C; Data Off ; Isothermal 1.0 min; Data On ; Ramp 10.00 °C/min to 0.00 °C; Data Off ; Isothermal 1.0 min; Data On ; Ramp 10.00 °C/min to 190.00 °C; Data Off ; Isothermal 1.0 min; Data On ; Ramp 10.00 °C/min to 0.00 °C; Data Off ; Isothermal 1.0 min; Data On ; Ramp 10.00 °C/min to 30.00 °C
[File Parameters]
Run date,6/1/2025 6:12:37 PM
Trios version,5.1.1.46572
Original File Name,
Current File Name,D:\DSC2500\JYarger\2025_06_01_Nifedipine_0C_190C_10Cmin_x3.tri
[Procedure]
Procedure Name,NIF_0C_190C_10Cmin_x3
Sample Name,2025_06_01_Nifedipine_0C_190C_10Cmin_x3
Sample Mass,9.98 mg
Reference Sample Mass,0 mg
Pan Mass,56.36 mg
Pan Number,6
Reference Pan Mass,55.79 mg
Reference Pan Number,1
Pan Type,Tzero Aluminum Hermetic
Comments,Al Hermetic DSC Consumables sealed Pan/Lid. A2 Tray (Google Sheet: DSC_Samples_A2_Tray_May2025)
Project Name,CA
Operator,Yarger
Test,Custom
Unload Max Temperature,30
Unload Min Temperature,30
Load Max Temperature,30
Load Min Temperature,30
Stop on Gas Flow Error,Yes
[Signal List]
Signal #1,Time (min)
Signal #2,Temperature (°C)
Signal #3,Heat Flow (mW)
Signal #4,Delta T (µV)
Signal #5,Delta Tzero (µV)
Signal #6,Tzero Temperature (°C)
Signal #7,Cell Purge (mL/min)
Signal #8,Heater Temp (°C)
Signal #9,Power Delivered (W)
Signal #10,Reference Junction Temperature (°C)
Signal #11,Flange Temperature (°C)
Signal #12,Heat Flow Phase (rad)
Signal #13,Total Heat Capacity (J/°C)
Signal #14,Heat Capacity (J/°C)
[Configuration]
Company Name,ASU
Instrument Name,DSC2A-00468
Instrument Type,DSC2500
Serial Number,DSC2A-00468
IP,192.168.1.100
Location of Instrument,MRRC
DisplayType,Unknown
Sample Interval ,0.1 s/pt
Selected Heat Flow,T4P
Exotherm Direction,Down
Cell Serial,DRC2-00792
Lid Type,Standard
Cooler,RCS 90
Leave Cooler on at End of Sequence,On
Gas 2,Nitrogen
Gas Selected,Channel 1
Flow Rate,50 mL/min
Secondary Purge,On
Licensed Heat Flow,Heat Flow T4P
Modulation Licensed,Yes
[Versions]
Common IDD Version,1
Cortex Version,VER 2.10.2.31
Driver,5.0.0.6
GDM Version,1.0.3.3
TouchscreenVersion,1.0.0.16145
FEP Version,1.2.1.21
FEP Bootloader,2.0.0.5
AutoSampler Version,2.1.1.26
Auto Sampler Bootloader,2.0.0.5
FCM Version,1.1.0.3
FCM Bootloader,2.0.0.5
[Experiment Logs]
Experiment Log Entry # 1,Data On set to 0
Experiment Log Entry # 3,Equilibrate Segment 0 (C) Started
Experiment Log Entry # 5,Air Cool is off.
Experiment Log Entry # 7,Data On set to 1
Experiment Log Entry # 9,Ramp Segment 10 C/min to 190 Started
Experiment Log Entry # 11,Data On set to 0
Experiment Log Entry # 13,Isothermal Segment 1 min started
Experiment Log Entry # 15,Data On set to 1
Experiment Log Entry # 17,Ramp Segment 10 C/min to 0 Started
Experiment Log Entry # 19,Data On set to 0
Experiment Log Entry # 21,Isothermal Segment 1 min started
Experiment Log Entry # 23,Data On set to 1
Experiment Log Entry # 25,Ramp Segment 10 C/min to 190 Started
Experiment Log Entry # 27,Data On set to 0
Experiment Log Entry # 29,Isothermal Segment 1 min started
Experiment Log Entry # 31,Data On set to 1
Experiment Log Entry # 33,Ramp Segment 10 C/min to 0 Started
Experiment Log Entry # 35,Data On set to 0
Experiment Log Entry # 37,Isothermal Segment 1 min started
Experiment Log Entry # 39,Data On set to 1
Experiment Log Entry # 41,Ramp Segment 10 C/min to 30 Started
[Method Log]
Method Log Entry # 1,Data Off
Method Log Entry # 2,Equilibrate 0 °C
Method Log Entry # 3,Data On
Method Log Entry # 4,(Ramp 728352) Ramp 10 °C/minute to 190 °C
Method Log Entry # 5,Data Off
Method Log Entry # 6,Isothermal 1 minutes
Method Log Entry # 7,Data On
Method Log Entry # 8,(Ramp 728356) Ramp 10 °C/minute to 0 °C
Method Log Entry # 9,Data Off
Method Log Entry # 10,Isothermal 1 minutes
Method Log Entry # 11,Data On
Method Log Entry # 12,(Ramp 728360) Ramp 10 °C/minute to 190 °C
Method Log Entry # 13,Data Off
Method Log Entry # 14,Isothermal 1 minutes
Method Log Entry # 15,Data On
Method Log Entry # 16,(Ramp 728364) Ramp 10 °C/minute to 0 °C
Method Log Entry # 17,Data Off
Method Log Entry # 18,Isothermal 1 minutes
Method Log Entry # 19,Data On
Method Log Entry # 20,(Ramp 728368) Ramp 10 °C/minute to 30 °C
Cell Serial,DRC2-00792
[T1 Calibration]
Slope,-0.008529666
Offset,9.636258
Initial Temperature,98.23
GUID,f8bfdadc-4977-4fdf-ba6d-0ba9134940c3
[TZero Calibration]
Date Applied,11/29/2022 4:06:13 PM
Description,From -89.059 °C to 396.009 °C at 20.000°C/min
Gas Type,Nitrogen
Pan Type,None
Source Files 1,C:\Users\yargerlab\Desktop\DSC Data\General\TZero_calibration_11_29_22_2nd(2).tri
Source Files 2,C:\Users\yargerlab\Desktop\DSC Data\General\TZero_calibration_11_29_22_2nd(3).tri
Delta T Offset,13.05235
Delta T Slope,-0.007271007
Delta T0 Offset,-13.69128
Delta T0 Slope,0.06063341
[Temperature Calibration]
Date Applied,11/29/2022 7:12:28 PM
Description,From 106.590 °C to 186.590 °C at 10.000°C/min
Gas Type,Nitrogen
Pan Type,Tzero Aluminum Hermetic
Source Files 1,C:\Users\yargerlab\Desktop\DSC Data\General\Indium(6).tri
Measured 1,157.391
Known 1,156.598
[Cell Constant Calibration]
Date Applied,11/29/2022 7:12:29 PM
Description,From 106.590 °C to 186.590 °C at 10.000°C/min
Gas Type,Nitrogen
Pan Type,Tzero Aluminum Hermetic
Source Files 1,C:\Users\yargerlab\Desktop\DSC Data\General\Indium(6).tri
T4P KCell,1.006051
Onset Slope,63.26126 mW/°C
[Direct Cp Calibration]
Date Applied,11/30/2022 11:04:51 AM
Description,From -79.983 °C to 298.409 °C at 10.000°C/min
Gas Type,Nitrogen
Pan Type,Tzero Aluminum Hermetic
Source Files 1,C:\Users\yargerlab\Desktop\DSC Data\General\Sapphire_Heat_Capacity_11_30_22.tri
[Rev Cp Calibration]
Date Applied,11/30/2022 1:58:51 PM
Description,From -79.996 °C to 292.812 °C at 3.000°C/min
Gas Type,Nitrogen
Pan Type,Tzero Aluminum Hermetic
Source Files 1,C:\Users\yargerlab\Desktop\DSC Data\General\Sapphire_MDSC_Calibration_11_30_22.tri
[step]
Ramp 10.00 °C/min to 190.00 °C
Time,Temperature,Heat Flow (Normalized)
min,°C,W/g
0.00,0.15,-0.040
0.01,0.14,-0.040
0.03,0.14,-0.037
0.04,0.14,-0.034
0.05,0.14,-0.031
0.07,0.15,-0.030
0.08,0.17,-0.030
0.09,0.19,-0.029
0.11,0.23,-0.027
0.12,0.28,-0.020
0.13,0.34,-0.011
0.15,0.41,0.001
0.16,0.48,0.016
0.17,0.57,0.031
0.19,0.65,0.045
0.20,0.75,0.059
0.21,0.84,0.071
0.23,0.94,0.082
0.24,1.04,0.092
0.25,1.15,0.101
0.27,1.25,0.110
0.28,1.36,0.117
0.29,1.48,0.124
0.31,1.59,0.131
0.32,1.71,0.137
0.33,1.82,0.143
0.35,1.94,0.147
0.36,2.06,0.152
0.37,2.18,0.156
0.39,2.31,0.160
0.40,2.43,0.163
0.41,2.55,0.167
0.43,2.68,0.169
0.44,2.80,0.172
0.45,2.93,0.174
0.47,3.05,0.176
0.48,3.18,0.178
0.49,3.31,0.180
0.51,3.44,0.180
0.52,3.56,0.184
0.53,3.69,0.184
0.55,3.82,0.185
0.56,3.95,0.186
0.57,4.08,0.187
0.59,4.21,0.188
0.60,4.34,0.189
0.61,4.47,0.190
0.63,4.60,0.190
0.64,4.73,0.191
0.65,4.86,0.192
0.67,4.99,0.192
0.68,5.12,0.192
0.69,5.25,0.193
0.71,5.38,0.194
0.72,5.51,0.194
0.73,5.65,0.194
0.75,5.78,0.195
0.76,5.91,0.195
0.77,6.04,0.195
0.79,6.17,0.195
0.80,6.30,0.196
0.81,6.44,0.196
0.83,6.57,0.196
0.84,6.70,0.196
0.85,6.83,0.196
0.87,6.96,0.196
0.88,7.10,0.197
0.89,7.23,0.197
0.91,7.36,0.197
0.92,7.49,0.197
0.93,7.62,0.197
0.95,7.75,0.197
0.96,7.89,0.198
0.97,8.02,0.198
0.99,8.15,0.198
1.00,8.29,0.198
1.01,8.42,0.198
1.03,8.55,0.198
1.04,8.68,0.199
1.05,8.81,0.199
1.07,8.95,0.199
1.08,9.08,0.199
1.09,9.21,0.199
1.11,9.35,0.200
1.12,9.48,0.200
1.13,9.61,0.200
1.15,9.74,0.200
1.16,9.88,0.200
1.17,10.01,0.200
1.19,10.14,0.200
1.20,10.27,0.201
1.21,10.41,0.201
1.23,10.54,0.201
1.24,10.67,0.201
1.25,10.81,0.201
1.27,10.94,0.201
1.28,11.07,0.201
1.29,11.21,0.201
1.31,11.34,0.201
1.32,11.47,0.202
1.33,11.60,0.202
1.35,11.74,0.202
1.36,11.87,0.202
1.37,12.00,0.202
1.39,12.14,0.202
1.40,12.27,0.202
1.41,12.40,0.202
1.43,12.54,0.202
1.44,12.67,0.203
1.45,12.80,0.203
1.47,12.93,0.203
1.48,13.07,0.203
1.49,13.20,0.203
1.51,13.34,0.203
1.52,13.47,0.203
1.53,13.60,0.203
1.55,13.73,0.203
1.56,13.87,0.203
1.57,14.00,0.203
1.59,14.13,0.203
1.60,14.27,0.204
1.61,14.40,0.204
1.63,14.53,0.204
1.64,14.67,0.204
1.65,14.80,0.204
1.67,14.93,0.204
1.68,15.07,0.204
1.69,15.20,0.204
1.71,15.33,0.204
1.72,15.47,0.204
1.73,15.60,0.204
1.75,15.73,0.204
1.76,15.87,0.205
1.77,16.00,0.205
1.79,16.13,0.205
1.80,16.27,0.205
1.81,16.40,0.205
1.83,16.53,0.205
1.84,16.67,0.205
1.85,16.80,0.205
1.87,16.93,0.205
1.88,17.07,0.205
1.89,17.20,0.205
1.91,17.33,0.206
1.92,17.47,0.206
1.93,17.60,0.206
1.95,17.73,0.206
1.96,17.87,0.206
1.97,18.00,0.206
1.99,18.13,0.206
2.00,18.27,0.206
2.01,18.40,0.206
2.03,18.53,0.206
2.04,18.67,0.206
2.05,18.80,0.206
2.07,18.93,0.206
2.08,19.07,0.207
2.09,19.20,0.207
2.11,19.33,0.207
2.12,19.47,0.207
2.13,19.60,0.207
2.15,19.73,0.207
2.16,19.87,0.207
2.17,20.00,0.207
2.19,20.13,0.207
2.20,20.27,0.207
2.21,20.40,0.207
2.23,20.53,0.208
2.24,20.67,0.208
2.25,20.80,0.208
2.27,20.94,0.208
2.28,21.07,0.208
2.29,21.20,0.208
2.31,21.34,0.208
2.32,21.47,0.208
2.33,21.60,0.208
2.35,21.74,0.208
2.36,21.87,0.208
2.37,22.00,0.208
2.39,22.14,0.209
2.40,22.27,0.209
2.41,22.40,0.209
2.43,22.54,0.209
2.44,22.67,0.209
2.45,22.80,0.209
2.47,22.94,0.209
2.48,23.07,0.209
2.49,23.20,0.209
2.51,23.34,0.209
2.52,23.47,0.209
2.53,23.60,0.209
2.55,23.74,0.210
2.56,23.87,0.210
2.57,24.00,0.210
2.59,24.14,0.210
2.60,24.27,0.210
2.61,24.40,0.210
2.63,24.54,0.210
2.64,24.67,0.210
2.65,24.80,0.210
2.67,24.94,0.210
2.68,25.07,0.210
2.69,25.21,0.210
2.71,25.34,0.210
2.72,25.47,0.211
2.73,25.61,0.211
2.75,25.74,0.211
2.76,25.87,0.211
2.77,26.01,0.211
2.79,26.14,0.211
2.80,26.27,0.211
2.81,26.41,0.211
2.83,26.54,0.211
2.84,26.67,0.211
2.85,26.81,0.211
2.87,26.94,0.211
2.88,27.07,0.211
2.89,27.21,0.212
2.91,27.34,0.212
2.92,27.47,0.212
2.93,27.61,0.212
2.95,27.74,0.212
2.96,27.87,0.212
2.97,28.01,0.212
2.99,28.14,0.212
3.00,28.27,0.212
3.01,28.41,0.212
3.03,28.54,0.212
3.04,28.68,0.212
3.05,28.81,0.212
3.07,28.94,0.213
3.08,29.08,0.213
3.09,29.21,0.213
3.11,29.34,0.213
3.12,29.48,0.213
3.13,29.61,0.213
3.15,29.74,0.213
3.16,29.88,0.213
3.17,30.01,0.213
3.19,30.14,0.213
3.20,30.28,0.213
3.21,30.41,0.213
3.23,30.54,0.214
3.24,30.68,0.214
3.25,30.81,0.214
3.27,30.94,0.214
3.28,31.08,0.214
3.29,31.21,0.214
3.31,31.34,0.214
3.32,31.48,0.214
3.33,31.61,0.214
3.35,31.74,0.214
3.36,31.88,0.214
3.37,32.01,0.215
3.39,32.14,0.215
3.40,32.28,0.215
3.41,32.41,0.215
3.43,32.54,0.215
3.44,32.68,0.215
3.45,32.81,0.215
3.47,32.95,0.215
3.48,33.08,0.215
3.49,33.21,0.215
3.51,33.35,0.215
3.52,33.48,0.216
3.53,33.61,0.216
3.55,33.74,0.216
3.56,33.88,0.216
3.57,34.01,0.216
3.59,34.15,0.216
3.60,34.28,0.216
3.61,34.41,0.216
3.63,34.55,0.216
3.64,34.68,0.216
3.65,34.81,0.217
3.67,34.95,0.217
3.68,35.08,0.217
3.69,35.21,0.217
3.71,35.35,0.217
3.72,35.48,0.217
3.73,35.61,0.217
3.75,35.75,0.217
3.76,35.88,0.217
3.77,36.01,0.217
3.79,36.15,0.218
3.80,36.28,0.218
3.81,36.41,0.218
3.83,36.55,0.218
3.84,36.68,0.218
3.85,36.82,0.218
3.87,36.95,0.218
3.88,37.08,0.218
3.89,37.22,0.218
3.91,37.35,0.219
3.92,37.48,0.219
3.93,37.62,0.219
3.95,37.75,0.219
3.96,37.88,0.219
3.97,38.02,0.219
3.99,38.15,0.219
4.00,38.28,0.220
4.01,38.42,0.220
4.03,38.55,0.220
4.04,38.68,0.220
4.05,38.82,0.220
4.07,38.95,0.220
4.08,39.08,0.220
4.09,39.22,0.221
4.11,39.35,0.221
4.12,39.48,0.221
4.13,39.62,0.221
4.15,39.75,0.221
4.16,39.88,0.221
4.17,40.02,0.222
4.19,40.15,0.222
4.20,40.28,0.222
4.21,40.42,0.223
4.23,40.55,0.223
4.24,40.68,0.223
4.25,40.82,0.224
4.27,40.95,0.224
4.28,41.08,0.224
4.29,41.22,0.224
4.31,41.35,0.225
4.32,41.48,0.225
4.33,41.62,0.225
4.35,41.75,0.226
4.36,41.88,0.226
4.37,42.02,0.227
4.39,42.15,0.227
4.40,42.28,0.228
4.41,42.42,0.228
4.43,42.55,0.229
4.44,42.68,0.230
4.45,42.82,0.231
4.47,42.95,0.232
4.48,43.08,0.232
4.49,43.21,0.234
4.51,43.35,0.235
4.52,43.48,0.236
4.53,43.61,0.237
4.55,43.75,0.238
4.56,43.88,0.239
4.57,44.01,0.241
4.59,44.15,0.242
4.60,44.28,0.244
4.61,44.41,0.245
4.63,44.54,0.247
4.64,44.68,0.249
4.65,44.81,0.250
4.67,44.94,0.253
4.68,45.07,0.256
4.69,45.20,0.258
4.71,45.34,0.261
4.72,45.47,0.263
4.73,45.60,0.267
4.75,45.73,0.271
4.76,45.86,0.274
4.77,45.99,0.279
4.79,46.13,0.284
4.80,46.26,0.289
4.81,46.39,0.294
4.83,46.52,0.301
4.84,46.65,0.308
4.85,46.78,0.315
4.87,46.91,0.323
4.88,47.04,0.333
4.89,47.17,0.343
4.91,47.29,0.354
4.92,47.42,0.366
4.93,47.55,0.379
4.95,47.67,0.395
4.96,47.80,0.411
4.97,47.92,0.429
4.99,48.04,0.449
5.00,48.17,0.470
5.01,48.29,0.491
5.03,48.41,0.515
5.04,48.53,0.538
5.05,48.65,0.562
5.07,48.77,0.583
5.08,48.89,0.603
5.09,49.01,0.618
5.11,49.13,0.627
5.12,49.25,0.628
5.13,49.38,0.625
5.15,49.51,0.613
5.16,49.64,0.596
5.17,49.77,0.573
5.19,49.91,0.545
5.20,50.05,0.516
5.21,50.20,0.486
5.23,50.34,0.456
5.24,50.49,0.430
5.25,50.64,0.408
5.27,50.79,0.391
5.28,50.93,0.376
5.29,51.08,0.365
5.31,51.22,0.357
5.32,51.37,0.347
5.33,51.51,0.341
5.35,51.65,0.335
5.36,51.79,0.330
5.37,51.93,0.325
5.39,52.07,0.320
5.40,52.21,0.317
5.41,52.35,0.314
5.43,52.49,0.310
5.44,52.62,0.308
5.45,52.76,0.305
5.47,52.90,0.304
5.48,53.03,0.302
5.49,53.17,0.300
5.51,53.31,0.299
5.52,53.44,0.297
5.53,53.58,0.296
5.55,53.71,0.296
5.56,53.85,0.295
5.57,53.98,0.294
5.59,54.12,0.293
5.60,54.25,0.292
5.61,54.39,0.292
5.63,54.52,0.291
5.64,54.65,0.291
5.65,54.79,0.291
5.67,54.92,0.290
5.68,55.06,0.290
5.69,55.19,0.290
5.71,55.32,0.290
5.72,55.46,0.289
5.73,55.59,0.289
5.75,55.73,0.289
5.76,55.86,0.289
5.77,55.99,0.289
5.79,56.13,0.289
5.80,56.26,0.288
5.81,56.39,0.288
5.83,56.53,0.288
5.84,56.66,0.288
5.85,56.79,0.288
5.87,56.93,0.288
5.88,57.06,0.288
5.89,57.20,0.288
5.91,57.33,0.288
5.92,57.46,0.288
5.93,57.60,0.288
5.95,57.73,0.287
5.96,57.86,0.287
5.97,58.00,0.287
5.99,58.13,0.287
6.00,58.26,0.287
6.01,58.40,0.287
6.03,58.53,0.287
6.04,58.66,0.287
6.05,58.80,0.287
6.07,58.93,0.287
6.08,59.06,0.287
6.09,59.20,0.287
6.11,59.33,0.287
6.12,59.46,0.287
6.13,59.60,0.287
6.15,59.73,0.287
6.16,59.87,0.287
6.17,60.00,0.287
6.19,60.13,0.287
6.20,60.27,0.287
6.21,60.40,0.287
6.23,60.53,0.287
6.24,60.67,0.287
6.25,60.80,0.287
6.27,60.93,0.287
6.28,61.07,0.287
6.29,61.20,0.287
6.31,61.33,0.287
6.32,61.47,0.287
6.33,61.60,0.287
6.35,61.74,0.287
6.36,61.87,0.287
6.37,62.00,0.287
6.39,62.14,0.287
6.40,62.27,0.287
6.41,62.40,0.287
6.43,62.54,0.287
6.44,62.67,0.287
6.45,62.80,0.287
6.47,62.94,0.287
6.48,63.07,0.287
6.49,63.20,0.287
6.51,63.34,0.287
6.52,63.47,0.287
6.53,63.60,0.287
6.55,63.74,0.287
6.56,63.87,0.287
6.57,64.01,0.287
6.59,64.14,0.287
6.60,64.27,0.287
6.61,64.41,0.287
6.63,64.54,0.287
6.64,64.67,0.287
6.65,64.81,0.287
6.67,64.94,0.287
6.68,65.07,0.287
6.69,65.21,0.287
6.71,65.34,0.287
6.72,65.47,0.287
6.73,65.61,0.287
6.75,65.74,0.287
6.76,65.87,0.287
6.77,66.01,0.287
6.79,66.14,0.287
6.80,66.27,0.287
6.81,66.41,0.287
6.83,66.54,0.287
6.84,66.68,0.287
6.85,66.81,0.287
6.87,66.94,0.287
6.88,67.07,0.287
6.89,67.21,0.287
6.91,67.34,0.287
6.92,67.48,0.287
6.93,67.61,0.287
6.95,67.74,0.287
6.96,67.88,0.287
6.97,68.01,0.288
6.99,68.14,0.288
7.00,68.28,0.288
7.01,68.41,0.288
7.03,68.54,0.287
7.04,68.68,0.288
7.05,68.81,0.288
7.07,68.95,0.288
7.08,69.08,0.288
7.09,69.21,0.287
7.11,69.35,0.287
7.12,69.48,0.287
7.13,69.61,0.288
7.15,69.75,0.288
7.16,69.88,0.288
7.17,70.01,0.288
7.19,70.15,0.287
7.20,70.28,0.288
7.21,70.41,0.287
7.23,70.55,0.287
7.24,70.68,0.287
7.25,70.81,0.287
7.27,70.95,0.287
7.28,71.08,0.287
7.29,71.22,0.287
7.31,71.35,0.287
7.32,71.48,0.287
7.33,71.62,0.287
7.35,71.75,0.287
7.36,71.88,0.287
7.37,72.02,0.287
7.39,72.15,0.287
7.40,72.28,0.287
7.41,72.42,0.287
7.43,72.55,0.287
7.44,72.68,0.287
7.45,72.82,0.287
7.47,72.95,0.287
7.48,73.09,0.287
7.49,73.22,0.287
7.51,73.35,0.287
7.52,73.49,0.287
7.53,73.62,0.286
7.55,73.75,0.286
7.56,73.89,0.286
7.57,74.02,0.286
7.59,74.15,0.286
7.60,74.29,0.286
7.61,74.42,0.286
7.63,74.55,0.286
7.64,74.69,0.285
7.65,74.82,0.285
7.67,74.96,0.285
7.68,75.09,0.285
7.69,75.22,0.285
7.71,75.36,0.285
7.72,75.49,0.284
7.73,75.62,0.284
7.75,75.76,0.284
7.76,75.89,0.284
7.77,76.03,0.283
7.79,76.16,0.283
7.80,76.29,0.283
7.81,76.43,0.282
7.83,76.56,0.282
7.84,76.69,0.281
7.85,76.83,0.281
7.87,76.96,0.281
7.88,77.10,0.281
7.89,77.23,0.280
7.91,77.36,0.280
7.92,77.50,0.280
7.93,77.63,0.279
7.95,77.76,0.279
7.96,77.90,0.279
7.97,78.03,0.278
7.99,78.16,0.278
8.00,78.30,0.278
8.01,78.43,0.277
8.03,78.57,0.277
8.04,78.70,0.276
8.05,78.84,0.276
8.07,78.97,0.275
8.08,79.10,0.275
8.09,79.24,0.274
8.11,79.37,0.274
8.12,79.50,0.273
8.13,79.64,0.273
8.15,79.77,0.273
8.16,79.91,0.272
8.17,80.04,0.271
8.19,80.17,0.271
8.20,80.31,0.271
8.21,80.44,0.270
8.23,80.57,0.270
8.24,80.71,0.269
8.25,80.84,0.269
8.27,80.98,0.269
8.28,81.11,0.268
8.29,81.24,0.268
8.31,81.38,0.267
8.32,81.51,0.267
8.33,81.64,0.266
8.35,81.78,0.265
8.36,81.91,0.265
8.37,82.04,0.264
8.39,82.18,0.264
8.40,82.31,0.263
8.41,82.45,0.262
8.43,82.58,0.262
8.44,82.71,0.261
8.45,82.85,0.260
8.47,82.98,0.260
8.48,83.12,0.259
8.49,83.25,0.259
8.51,83.39,0.258
8.52,83.52,0.257
8.53,83.65,0.257
8.55,83.79,0.256
8.56,83.92,0.255
8.57,84.05,0.254
8.59,84.19,0.253
8.60,84.32,0.252
8.61,84.46,0.251
8.63,84.59,0.250
8.64,84.72,0.250
8.65,84.86,0.248
8.67,84.99,0.247
8.68,85.13,0.246
8.69,85.26,0.244
8.71,85.39,0.243
8.72,85.53,0.242
8.73,85.66,0.241
8.75,85.80,0.240
8.76,85.93,0.237
8.77,86.07,0.237
8.79,86.20,0.236
8.80,86.33,0.234
8.81,86.47,0.232
8.83,86.60,0.230
8.84,86.74,0.229
8.85,86.87,0.227
8.87,87.01,0.225
8.88,87.14,0.223
8.89,87.28,0.221
8.91,87.41,0.219
8.92,87.55,0.217
8.93,87.68,0.214
8.95,87.81,0.213
8.96,87.95,0.210
8.97,88.08,0.208
8.99,88.22,0.204
9.00,88.35,0.203
9.01,88.49,0.200
9.03,88.62,0.197
9.04,88.76,0.194
9.05,88.89,0.192
9.07,89.03,0.189
9.08,89.17,0.185
9.09,89.30,0.182
9.11,89.44,0.179
9.12,89.57,0.175
9.13,89.71,0.173
9.15,89.84,0.168
9.16,89.98,0.165
9.17,90.11,0.161
9.19,90.25,0.157
9.20,90.39,0.153
9.21,90.52,0.149
9.23,90.66,0.145
9.24,90.79,0.140
9.25,90.93,0.135
9.27,91.07,0.131
9.28,91.20,0.126
9.29,91.34,0.121
9.31,91.48,0.116
9.32,91.61,0.111
9.33,91.75,0.105
9.35,91.89,0.100
9.36,92.02,0.095
9.37,92.16,0.088
9.39,92.30,0.083
9.40,92.43,0.076
9.41,92.57,0.069
9.43,92.71,0.063
9.44,92.85,0.055
9.45,92.98,0.048
9.47,93.12,0.041
9.48,93.26,0.033
9.49,93.40,0.026
9.51,93.54,0.017
9.52,93.67,0.009
9.53,93.81,0.001
9.55,93.95,-0.009
9.56,94.09,-0.019
9.57,94.23,-0.028
9.59,94.37,-0.038
9.60,94.51,-0.049
9.61,94.65,-0.061
9.63,94.79,-0.071
9.64,94.93,-0.084
9.65,95.07,-0.096
9.67,95.21,-0.108
9.68,95.35,-0.122
9.69,95.49,-0.136
9.71,95.63,-0.149
9.72,95.77,-0.164
9.73,95.92,-0.178
9.75,96.06,-0.194
9.76,96.20,-0.209
9.77,96.35,-0.226
9.79,96.49,-0.243
9.80,96.63,-0.260
9.81,96.78,-0.279
9.83,96.92,-0.297
9.84,97.06,-0.315
9.85,97.21,-0.334
9.87,97.35,-0.352
9.88,97.50,-0.373
9.89,97.64,-0.392
9.91,97.79,-0.412
9.92,97.94,-0.431
9.93,98.08,-0.451
9.95,98.23,-0.471
9.96,98.37,-0.492
9.97,98.52,-0.512
9.99,98.67,-0.533
10.00,98.81,-0.556
10.01,98.96,-0.578
10.03,99.11,-0.601
10.04,99.25,-0.622
10.05,99.40,-0.645
10.07,99.55,-0.666
10.08,99.70,-0.687
10.09,99.84,-0.704
10.11,99.99,-0.722
10.12,100.14,-0.738
10.13,100.28,-0.756
10.15,100.43,-0.770
10.16,100.57,-0.783
10.17,100.72,-0.794
10.19,100.86,-0.799
10.20,101.00,-0.805
10.21,101.14,-0.810
10.23,101.28,-0.814
10.24,101.42,-0.814
10.25,101.55,-0.815
10.27,101.69,-0.811
10.28,101.82,-0.808
10.29,101.96,-0.810
10.31,102.09,-0.810
10.32,102.23,-0.811
10.33,102.36,-0.807
10.35,102.50,-0.797
10.36,102.63,-0.779
10.37,102.75,-0.757
10.39,102.88,-0.731
10.40,103.00,-0.699
10.41,103.13,-0.663
10.43,103.24,-0.626
10.44,103.36,-0.587
10.45,103.47,-0.545
10.47,103.59,-0.502
10.48,103.70,-0.457
10.49,103.81,-0.409
10.51,103.91,-0.361
10.52,104.02,-0.315
10.53,104.13,-0.274
10.55,104.23,-0.235
10.56,104.34,-0.202
10.57,104.45,-0.171
10.59,104.56,-0.143
10.60,104.67,-0.117
10.61,104.79,-0.092
10.63,104.90,-0.066
10.64,105.01,-0.041
10.65,105.13,-0.021
10.67,105.25,-0.004
10.68,105.36,0.011
10.69,105.48,0.025
10.71,105.60,0.038
10.72,105.72,0.050
10.73,105.85,0.059
10.75,105.97,0.068
10.76,106.10,0.074
10.77,106.22,0.082
10.79,106.35,0.086
10.80,106.48,0.091
10.81,106.60,0.093
10.83,106.73,0.096
10.84,106.86,0.099
10.85,106.99,0.100
10.87,107.12,0.101
10.88,107.25,0.101
10.89,107.39,0.101
10.91,107.52,0.102
10.92,107.65,0.102
10.93,107.78,0.101
10.95,107.92,0.101
10.96,108.05,0.100
10.97,108.18,0.100
10.99,108.32,0.099
11.00,108.45,0.098
11.01,108.58,0.098
11.03,108.72,0.097
11.04,108.85,0.096
11.05,108.99,0.095
11.07,109.12,0.094
11.08,109.25,0.092
11.09,109.39,0.091
11.11,109.52,0.090
11.12,109.66,0.089
11.13,109.79,0.087
11.15,109.92,0.087
11.16,110.06,0.085
11.17,110.19,0.084
11.19,110.33,0.084
11.20,110.46,0.083
11.21,110.59,0.082
11.23,110.73,0.082
11.24,110.86,0.081
11.25,111.00,0.080
11.27,111.13,0.080
11.28,111.26,0.080
11.29,111.40,0.079
11.31,111.53,0.079
11.32,111.66,0.079
11.33,111.80,0.079
11.35,111.93,0.079
11.36,112.07,0.078
11.37,112.20,0.078
11.39,112.33,0.078
11.40,112.47,0.078
11.41,112.60,0.078
11.43,112.73,0.078
11.44,112.87,0.078
11.45,113.00,0.078
11.47,113.13,0.078
11.48,113.27,0.078
11.49,113.40,0.079
11.51,113.53,0.079
11.52,113.67,0.079
11.53,113.80,0.080
11.55,113.93,0.081
11.56,114.07,0.082
11.57,114.20,0.083
11.59,114.33,0.083
11.60,114.46,0.085
11.61,114.60,0.086
11.63,114.73,0.088
11.64,114.86,0.089
11.65,115.00,0.090
11.67,115.13,0.091
11.68,115.26,0.092
11.69,115.40,0.093
11.71,115.53,0.095
11.72,115.66,0.096
11.73,115.79,0.097
11.75,115.93,0.098
11.76,116.06,0.100
11.77,116.19,0.102
11.79,116.32,0.103
11.80,116.46,0.104
11.81,116.59,0.105
11.83,116.72,0.107
11.84,116.85,0.108
11.85,116.99,0.110
11.87,117.12,0.111
11.88,117.25,0.112
11.89,117.38,0.114
11.91,117.52,0.115
11.92,117.65,0.116
11.93,117.78,0.117
11.95,117.92,0.119
11.96,118.05,0.121
11.97,118.18,0.121
11.99,118.31,0.123
12.00,118.44,0.124
12.01,118.58,0.125
12.03,118.71,0.127
12.04,118.84,0.128
12.05,118.98,0.129
12.07,119.11,0.130
12.08,119.24,0.132
12.09,119.37,0.133
12.11,119.51,0.134
12.12,119.64,0.135
12.13,119.77,0.136
12.15,119.90,0.138
12.16,120.04,0.139
12.17,120.17,0.140
12.19,120.30,0.142
12.20,120.43,0.143
12.21,120.57,0.144
12.23,120.70,0.146
12.24,120.83,0.147
12.25,120.97,0.148
12.27,121.10,0.149
12.28,121.23,0.151
12.29,121.37,0.151
12.31,121.50,0.153
12.32,121.63,0.154
12.33,121.76,0.155
12.35,121.89,0.156
12.36,122.03,0.158
12.37,122.16,0.159
12.39,122.29,0.160
12.40,122.43,0.161
12.41,122.56,0.162
12.43,122.69,0.163
12.44,122.82,0.164
12.45,122.96,0.166
12.47,123.09,0.166
12.48,123.22,0.168
12.49,123.35,0.169
12.51,123.49,0.170
12.52,123.62,0.172
12.53,123.75,0.174
12.55,123.89,0.174
12.56,124.02,0.175
12.57,124.15,0.177
12.59,124.28,0.178
12.60,124.42,0.179
12.61,124.55,0.180
12.63,124.68,0.181
12.64,124.81,0.183
12.65,124.95,0.183
12.67,125.08,0.184
12.68,125.21,0.186
12.69,125.35,0.187
12.71,125.48,0.188
12.72,125.61,0.189
12.73,125.74,0.190
12.75,125.88,0.192
12.76,126.01,0.193
12.77,126.14,0.193
12.79,126.27,0.194
12.80,126.41,0.196
12.81,126.54,0.196
12.83,126.67,0.197
12.84,126.81,0.198
12.85,126.94,0.199
12.87,127.07,0.200
12.88,127.20,0.201
12.89,127.34,0.202
12.91,127.47,0.203
12.92,127.60,0.204
12.93,127.73,0.205
12.95,127.87,0.205
12.96,128.00,0.206
12.97,128.13,0.208
12.99,128.27,0.209
13.00,128.40,0.210
13.01,128.53,0.211
13.03,128.67,0.213
13.04,128.80,0.213
13.05,128.93,0.214
13.07,129.07,0.215
13.08,129.20,0.215
13.09,129.33,0.216
13.11,129.47,0.216
13.12,129.60,0.217
13.13,129.73,0.218
13.15,129.86,0.219
13.16,130.00,0.220
13.17,130.13,0.220
13.19,130.26,0.221
13.20,130.39,0.221
13.21,130.53,0.222
13.23,130.66,0.222
13.24,130.79,0.223
13.25,130.92,0.223
13.27,131.06,0.224
13.28,131.19,0.225
13.29,131.32,0.226
13.31,131.46,0.227
13.32,131.59,0.227
13.33,131.72,0.228
13.35,131.85,0.229
13.36,131.99,0.230
13.37,132.12,0.231
13.39,132.25,0.232
13.40,132.39,0.232
13.41,132.52,0.233
13.43,132.65,0.234
13.44,132.79,0.234
13.45,132.92,0.235
13.47,133.05,0.236
13.48,133.19,0.236
13.49,133.32,0.237
13.51,133.45,0.238
13.52,133.59,0.239
13.53,133.72,0.240
13.55,133.85,0.240
13.56,133.99,0.241
13.57,134.12,0.241
13.59,134.25,0.242
13.60,134.39,0.242
13.61,134.52,0.243
13.63,134.65,0.243
13.64,134.79,0.244
13.65,134.92,0.245
13.67,135.05,0.246
13.68,135.18,0.247
13.69,135.32,0.247
13.71,135.45,0.247
13.72,135.58,0.248
13.73,135.71,0.248
13.75,135.85,0.248
13.76,135.98,0.249
13.77,136.11,0.250
13.79,136.25,0.250
13.80,136.38,0.250
13.81,136.51,0.251
13.83,136.65,0.252
13.84,136.78,0.252
13.85,136.91,0.253
13.87,137.04,0.254
13.88,137.18,0.254
13.89,137.31,0.255
13.91,137.44,0.255
13.92,137.58,0.256
13.93,137.71,0.256
13.95,137.84,0.257
13.96,137.98,0.258
13.97,138.11,0.259
13.99,138.24,0.259
14.00,138.38,0.260
14.01,138.51,0.260
14.03,138.64,0.260
14.04,138.78,0.261
14.05,138.91,0.261
14.07,139.04,0.261
14.08,139.17,0.262
14.09,139.31,0.262
14.11,139.44,0.262
14.12,139.57,0.263
14.13,139.71,0.264
14.15,139.84,0.264
14.16,139.97,0.265
14.17,140.11,0.265
14.19,140.24,0.266
14.20,140.37,0.266
14.21,140.51,0.266
14.23,140.64,0.267
14.24,140.77,0.268
14.25,140.91,0.268
14.27,141.04,0.268
14.28,141.17,0.269
14.29,141.31,0.269
14.31,141.44,0.269
14.32,141.57,0.270
14.33,141.71,0.270
14.35,141.84,0.270
14.36,141.97,0.271
14.37,142.10,0.271
14.39,142.24,0.271
14.40,142.37,0.272
14.41,142.51,0.272
14.43,142.64,0.273
14.44,142.77,0.273
14.45,142.91,0.273
14.47,143.04,0.274
14.48,143.17,0.274
14.49,143.30,0.275
14.51,143.44,0.275
14.52,143.57,0.276
14.53,143.70,0.276
14.55,143.84,0.276
14.56,143.97,0.277
14.57,144.10,0.277
14.59,144.24,0.277
14.60,144.37,0.277
14.61,144.50,0.277
14.63,144.64,0.278
14.64,144.77,0.278
14.65,144.90,0.278
14.67,145.04,0.279
14.68,145.17,0.279
14.69,145.30,0.280
14.71,145.44,0.281
14.72,145.57,0.281
14.73,145.70,0.281
14.75,145.84,0.281
14.76,145.97,0.282
14.77,146.10,0.282
14.79,146.24,0.282
14.80,146.37,0.283
14.81,146.50,0.283
14.83,146.64,0.283
14.84,146.77,0.284
14.85,146.90,0.284
14.87,147.04,0.285
14.88,147.17,0.285
14.89,147.30,0.286
14.91,147.43,0.287
14.92,147.57,0.287
14.93,147.70,0.288
14.95,147.83,0.288
14.96,147.97,0.289
14.97,148.10,0.289
14.99,148.23,0.289
15.00,148.37,0.290
15.01,148.50,0.290
15.03,148.63,0.291
15.04,148.77,0.291
15.05,148.90,0.291
15.07,149.03,0.292
15.08,149.17,0.292
15.09,149.30,0.293
15.11,149.43,0.293
15.12,149.56,0.294
15.13,149.70,0.294
15.15,149.83,0.295
15.16,149.96,0.296
15.17,150.10,0.297
15.19,150.23,0.297
15.20,150.36,0.298
15.21,150.50,0.299
15.23,150.63,0.300
15.24,150.76,0.301
15.25,150.90,0.301
15.27,151.03,0.303
15.28,151.16,0.303
15.29,151.30,0.305
15.31,151.43,0.305
15.32,151.56,0.306
15.33,151.70,0.306
15.35,151.83,0.307
15.36,151.96,0.307
15.37,152.09,0.307
15.39,152.23,0.308
15.40,152.36,0.309
15.41,152.49,0.309
15.43,152.63,0.310
15.44,152.76,0.311
15.45,152.89,0.311
15.47,153.02,0.312
15.48,153.16,0.313
15.49,153.29,0.314
15.51,153.42,0.315
15.52,153.56,0.316
15.53,153.69,0.317
15.55,153.82,0.319
15.56,153.96,0.320
15.57,154.09,0.321
15.59,154.22,0.322
15.60,154.35,0.323
15.61,154.49,0.324
15.63,154.62,0.325
15.64,154.75,0.326
15.65,154.89,0.326
15.67,155.02,0.328
15.68,155.15,0.329
15.69,155.28,0.330
15.71,155.42,0.332
15.72,155.55,0.333
15.73,155.68,0.334
15.75,155.82,0.335
15.76,155.95,0.337
15.77,156.08,0.338
15.79,156.21,0.339
15.80,156.35,0.340
15.81,156.48,0.342
15.83,156.61,0.343
15.84,156.75,0.346
15.85,156.88,0.347
15.87,157.01,0.349
15.88,157.14,0.350
15.89,157.27,0.352
15.91,157.41,0.353
15.92,157.54,0.355
15.93,157.67,0.356
15.95,157.81,0.359
15.96,157.94,0.361
15.97,158.07,0.362
15.99,158.20,0.364
16.00,158.34,0.366
16.01,158.47,0.369
16.03,158.60,0.371
16.04,158.73,0.372
16.05,158.86,0.375
16.07,159.00,0.378
16.08,159.13,0.379
16.09,159.26,0.382
16.11,159.39,0.385
16.12,159.53,0.387
16.13,159.66,0.390
16.15,159.79,0.393
16.16,159.92,0.396
16.17,160.05,0.399
16.19,160.19,0.401
16.20,160.32,0.405
16.21,160.45,0.408
16.23,160.58,0.411
16.24,160.71,0.416
16.25,160.85,0.418
16.27,160.98,0.422
16.28,161.11,0.426
16.29,161.24,0.430
16.31,161.37,0.432
16.32,161.50,0.437
16.33,161.64,0.440
16.35,161.77,0.444
16.36,161.90,0.449
16.37,162.03,0.453
16.39,162.16,0.457
16.40,162.29,0.463
16.41,162.42,0.467
16.43,162.55,0.472
16.44,162.68,0.478
16.45,162.81,0.483
16.47,162.94,0.490
16.48,163.07,0.496
16.49,163.20,0.502
16.51,163.33,0.508
16.52,163.46,0.515
16.53,163.59,0.521
16.55,163.72,0.528
16.56,163.85,0.536
16.57,163.98,0.543
16.59,164.11,0.551
16.60,164.24,0.560
16.61,164.37,0.568
16.63,164.50,0.576
16.64,164.63,0.586
16.65,164.75,0.595
16.67,164.88,0.605
16.68,165.01,0.615
16.69,165.14,0.626
16.71,165.27,0.636
16.72,165.39,0.649
16.73,165.52,0.663
16.75,165.65,0.675
16.76,165.78,0.688
16.77,165.90,0.701
16.79,166.03,0.715
16.80,166.15,0.728
16.81,166.28,0.743
16.83,166.41,0.759
16.84,166.53,0.777
16.85,166.66,0.793
16.87,166.78,0.812
16.88,166.90,0.828
16.89,167.03,0.848
16.91,167.15,0.867
16.92,167.27,0.888
16.93,167.39,0.910
16.95,167.52,0.933
16.96,167.64,0.956
16.97,167.76,0.980
16.99,167.88,1.006
17.00,168.00,1.032
17.01,168.12,1.059
17.03,168.24,1.088
17.04,168.36,1.117
17.05,168.48,1.148
17.07,168.59,1.179
17.08,168.71,1.212
17.09,168.82,1.245
17.11,168.94,1.282
17.12,169.05,1.318
17.13,169.17,1.355
17.15,169.28,1.394
17.16,169.40,1.434
17.17,169.51,1.476
17.19,169.62,1.521
17.20,169.73,1.567
17.21,169.84,1.613
17.23,169.95,1.661
17.24,170.05,1.711
17.25,170.16,1.763
17.27,170.27,1.816
17.28,170.37,1.870
17.29,170.48,1.925
17.31,170.58,1.981
17.32,170.68,2.038
17.33,170.78,2.095
17.35,170.89,2.152
17.36,170.99,2.208
17.37,171.09,2.266
17.39,171.19,2.324
17.40,171.29,2.380
17.41,171.39,2.436
17.43,171.49,2.490
17.44,171.59,2.541
17.45,171.70,2.587
17.47,171.80,2.628
17.48,171.91,2.667
17.49,172.01,2.700
17.51,172.12,2.726
17.52,172.24,2.746
17.53,172.35,2.757
17.55,172.47,2.760
17.56,172.59,2.751
17.57,172.72,2.731
17.59,172.85,2.698
17.60,172.99,2.656
17.61,173.13,2.605
17.63,173.28,2.542
17.64,173.44,2.467
17.65,173.59,2.380
17.67,173.76,2.275
17.68,173.94,2.147
17.69,174.12,1.989
17.71,174.32,1.794
17.72,174.53,1.578
17.73,174.75,1.368
17.75,174.98,1.185
17.76,175.21,1.042
17.77,175.43,0.937
17.79,175.64,0.856
17.80,175.84,0.789
17.81,176.04,0.732
17.83,176.23,0.682
17.84,176.41,0.640
17.85,176.59,0.602
17.87,176.76,0.568
17.88,176.93,0.538
17.89,177.09,0.513
17.91,177.25,0.489
17.92,177.41,0.466
17.93,177.56,0.454
17.95,177.71,0.435
17.96,177.86,0.421
17.97,178.01,0.409
17.99,178.15,0.399
18.00,178.30,0.389
18.01,178.44,0.381
18.03,178.58,0.373
18.04,178.72,0.367
18.05,178.86,0.360
18.07,179.00,0.356
18.08,179.14,0.352
18.09,179.28,0.347
18.11,179.42,0.344
18.12,179.55,0.340
18.13,179.69,0.338
18.15,179.83,0.336
18.16,179.96,0.334
18.17,180.10,0.331
18.19,180.23,0.330
18.20,180.37,0.329
18.21,180.50,0.327
18.23,180.64,0.326
18.24,180.77,0.325
18.25,180.91,0.325
18.27,181.04,0.324
18.28,181.17,0.323
18.29,181.31,0.323
18.31,181.44,0.323
18.32,181.58,0.322
18.33,181.71,0.322
18.35,181.84,0.321
18.36,181.98,0.321
18.37,182.11,0.321
18.39,182.24,0.320
18.40,182.38,0.320
18.41,182.51,0.320
18.43,182.65,0.320
18.44,182.78,0.319
18.45,182.91,0.319
18.47,183.05,0.319
18.48,183.18,0.319
18.49,183.32,0.319
18.51,183.45,0.319
18.52,183.58,0.319
18.53,183.72,0.319
18.55,183.85,0.319
18.56,183.98,0.319
18.57,184.12,0.318
18.59,184.25,0.318
18.60,184.38,0.318
18.61,184.52,0.318
18.63,184.65,0.318
18.64,184.78,0.318
18.65,184.92,0.318
18.67,185.05,0.318
18.68,185.18,0.318
18.69,185.32,0.317
18.71,185.45,0.317
18.72,185.59,0.317
18.73,185.72,0.317
18.75,185.85,0.317
18.76,185.99,0.317
18.77,186.12,0.317
18.79,186.25,0.317
18.80,186.39,0.317
18.81,186.52,0.317
18.83,186.65,0.316
18.84,186.79,0.316
18.85,186.92,0.316
18.87,187.05,0.316
18.88,187.19,0.316
18.89,187.32,0.316
18.91,187.45,0.316
18.92,187.59,0.315
18.93,187.72,0.315
18.95,187.86,0.315
18.96,187.99,
18.97,188.12,
18.99,188.26,
19.00,,
19.01,,

[step]
Ramp 10.00 °C/min to 0.00 °C
Time,Temperature,Heat Flow (Normalized)
min,°C,W/g
20.01,190.09,-0.032
20.02,190.09,-0.032
20.03,190.09,-0.032
20.05,190.09,-0.032
20.06,190.08,-0.032
20.07,190.07,-0.031
20.09,190.04,-0.030
20.10,190.01,-0.030
20.11,189.97,-0.042
20.13,189.91,-0.057
20.14,189.84,-0.077
20.15,189.77,-0.101
20.17,189.69,-0.127
20.18,189.60,-0.155
20.19,189.51,-0.180
20.21,189.41,-0.202
20.22,189.30,-0.223
20.23,189.20,-0.239
20.25,189.09,-0.256
20.26,188.98,-0.270
20.27,188.87,-0.282
20.29,188.75,-0.292
20.30,188.63,-0.302
20.31,188.52,-0.309
20.33,188.40,-0.317
20.34,188.27,-0.324
20.35,188.15,-0.328
20.37,188.03,-0.334
20.38,187.90,-0.338
20.39,187.78,-0.343
20.41,187.65,-0.346
20.42,187.52,-0.350
20.43,187.40,-0.351
20.45,187.27,-0.354
20.46,187.14,-0.357
20.47,187.01,-0.359
20.49,186.88,-0.361
20.50,186.75,-0.362
20.51,186.62,-0.362
20.53,186.50,-0.364
20.54,186.37,-0.365
20.55,186.24,-0.366
20.57,186.10,-0.367
20.58,185.98,-0.368
20.59,185.84,-0.367
20.61,185.71,-0.368
20.62,185.58,-0.368
20.63,185.45,-0.369
20.65,185.32,-0.369
20.66,185.19,-0.369
20.67,185.06,-0.370
20.69,184.92,-0.370
20.70,184.79,-0.370
20.71,184.66,-0.370
20.73,184.53,-0.371
20.74,184.40,-0.371
20.75,184.27,-0.371
20.77,184.13,-0.371
20.78,184.00,-0.371
20.79,183.87,-0.371
20.81,183.74,-0.371
20.82,183.60,-0.371
20.83,183.47,-0.371
20.85,183.34,-0.371
20.86,183.21,-0.371
20.87,183.08,-0.372
20.89,182.94,-0.372
20.90,182.81,-0.372
20.91,182.68,-0.372
20.93,182.55,-0.372
20.94,182.41,-0.372
20.95,182.28,-0.372
20.97,182.15,-0.372
20.98,182.02,-0.372
20.99,181.88,-0.372
21.01,181.75,-0.372
21.02,181.62,-0.372
21.03,181.49,-0.372
21.05,181.35,-0.372
21.06,181.22,-0.372
21.07,181.09,-0.372
21.09,180.96,-0.372
21.10,180.82,-0.372
21.11,180.69,-0.372
21.13,180.56,-0.371
21.14,180.42,-0.371
21.15,180.29,-0.371
21.17,180.16,-0.371
21.18,180.03,-0.371
21.19,179.89,-0.371
21.21,179.76,-0.371
21.22,179.63,-0.371
21.23,179.50,-0.371
21.25,179.36,-0.371
21.26,179.23,-0.371
21.27,179.10,-0.371
21.29,178.97,-0.371
21.30,178.83,-0.371
21.31,178.70,-0.370
21.33,178.57,-0.370
21.34,178.44,-0.370
21.35,178.30,-0.370
21.37,178.17,-0.370
21.38,178.04,-0.370
21.39,177.90,-0.370
21.41,177.77,-0.370
21.42,177.64,-0.370
21.43,177.50,-0.370
21.45,177.37,-0.370
21.46,177.24,-0.370
21.47,177.11,-0.370
21.49,176.97,-0.370
21.50,176.84,-0.370
21.51,176.71,-0.369
21.53,176.57,-0.369
21.54,176.44,-0.369
21.55,176.31,-0.369
21.57,176.17,-0.369
21.58,176.04,-0.369
21.59,175.91,-0.369
21.61,175.77,-0.369
21.62,175.64,-0.369
21.63,175.51,-0.369
21.65,175.37,-0.369
21.66,175.24,-0.368
21.67,175.11,-0.368
21.69,174.98,-0.368
21.70,174.84,-0.368
21.71,174.71,-0.368
21.73,174.58,-0.368
21.74,174.44,-0.368
21.75,174.31,-0.368
21.77,174.18,-0.368
21.78,174.05,-0.367
21.79,173.91,-0.367
21.81,173.78,-0.367
21.82,173.65,-0.367
21.83,173.51,-0.367
21.85,173.38,-0.367
21.86,173.25,-0.367
21.87,173.11,-0.367
21.89,172.98,-0.367
21.90,172.85,-0.367
21.91,172.71,-0.366
21.93,172.58,-0.366
21.94,172.45,-0.366
21.95,172.31,-0.366
21.97,172.18,-0.366
21.98,172.05,-0.366
21.99,171.91,-0.366
22.01,171.78,-0.366
22.02,171.65,-0.366
22.03,171.51,-0.366
22.05,171.38,-0.366
22.06,171.25,-0.365
22.07,171.11,-0.365
22.09,170.98,-0.365
22.10,170.85,-0.365
22.11,170.72,-0.365
22.13,170.58,-0.365
22.14,170.45,-0.365
22.15,170.31,-0.365
22.17,170.18,-0.365
22.18,170.05,-0.365
22.19,169.91,-0.365
22.21,169.78,-0.365
22.22,169.65,-0.365
22.23,169.52,-0.364
22.25,169.38,-0.364
22.26,169.25,-0.364
22.27,169.12,-0.364
22.29,168.98,-0.364
22.30,168.85,-0.364
22.31,168.72,-0.364
22.33,168.58,-0.364
22.34,168.45,-0.363
22.35,168.32,-0.363
22.37,168.18,-0.363
22.38,168.05,-0.363
22.39,167.92,-0.363
22.41,167.79,-0.363
22.42,167.65,-0.363
22.43,167.52,-0.363
22.45,167.39,-0.363
22.46,167.25,-0.363
22.47,167.12,-0.362
22.49,166.99,-0.362
22.50,166.86,-0.362
22.51,166.72,-0.362
22.53,166.59,-0.362
22.54,166.46,-0.362
22.55,166.32,-0.362
22.57,166.19,-0.362
22.58,166.06,-0.362
22.59,165.92,-0.362
22.61,165.79,-0.362
22.62,165.66,-0.361
22.63,165.52,-0.361
22.65,165.39,-0.361
22.66,165.26,-0.361
22.67,165.12,-0.361
22.69,164.99,-0.361
22.70,164.86,-0.361
22.71,164.72,-0.361
22.73,164.59,-0.361
22.74,164.46,-0.361
22.75,164.32,-0.361
22.77,164.19,-0.361
22.78,164.06,-0.361
22.79,163.92,-0.361
22.81,163.79,-0.361
22.82,163.66,-0.361
22.83,163.52,-0.360
22.85,163.39,-0.360
22.86,163.26,-0.360
22.87,163.12,-0.360
22.89,162.99,-0.360
22.90,162.86,-0.360
22.91,162.73,-0.360
22.93,162.59,-0.360
22.94,162.46,-0.360
22.95,162.33,-0.360
22.97,162.19,-0.360
22.98,162.06,-0.360
22.99,161.93,-0.360
23.01,161.79,-0.360
23.02,161.66,-0.359
23.03,161.53,-0.359
23.05,161.39,-0.359
23.06,161.26,-0.359
23.07,161.13,-0.359
23.09,160.99,-0.359
23.10,160.86,-0.359
23.11,160.73,-0.359
23.13,160.60,-0.359
23.14,160.46,-0.359
23.15,160.33,-0.359
23.17,160.20,-0.359
23.18,160.06,-0.358
23.19,159.93,-0.358
23.21,159.80,-0.358
23.22,159.66,-0.358
23.23,159.53,-0.358
23.25,159.40,-0.358
23.26,159.26,-0.358
23.27,159.13,-0.358
23.29,159.00,-0.358
23.30,158.86,-0.358
23.31,158.73,-0.358
23.33,158.60,-0.358
23.34,158.47,-0.358
23.35,158.33,-0.357
23.37,158.20,-0.357
23.38,158.07,-0.357
23.39,157.93,-0.357
23.41,157.80,-0.357
23.42,157.66,-0.357
23.43,157.53,-0.357
23.45,157.40,-0.357
23.46,157.26,-0.357
23.47,157.13,-0.357
23.49,157.00,-0.357
23.50,156.87,-0.357
23.51,156.73,-0.357
23.53,156.60,-0.357
23.54,156.47,-0.357
23.55,156.33,-0.357
23.57,156.20,-0.357
23.58,156.07,-0.357
23.59,155.93,-0.357
23.61,155.80,-0.357
23.62,155.67,-0.356
23.63,155.53,-0.356
23.65,155.40,-0.356
23.66,155.27,-0.356
23.67,155.13,-0.356
23.69,155.00,-0.356
23.70,154.87,-0.356
23.71,154.73,-0.356
23.73,154.60,-0.356
23.74,154.47,-0.356
23.75,154.33,-0.356
23.77,154.20,-0.356
23.78,154.07,-0.356
23.79,153.94,-0.356
23.81,153.80,-0.356
23.82,153.67,-0.356
23.83,153.53,-0.355
23.85,153.40,-0.355
23.86,153.27,-0.355
23.87,153.14,-0.355
23.89,153.00,-0.355
23.90,152.87,-0.355
23.91,152.73,-0.355
23.93,152.60,-0.355
23.94,152.47,-0.355
23.95,152.33,-0.355
23.97,152.20,-0.355
23.98,152.07,-0.355
23.99,151.94,-0.355
24.01,151.80,-0.355
24.02,151.67,-0.355
24.03,151.54,-0.355
24.05,151.40,-0.355
24.06,151.27,-0.355
24.07,151.14,-0.354
24.09,151.00,-0.354
24.10,150.87,-0.354
24.11,150.74,-0.354
24.13,150.61,-0.354
24.14,150.47,-0.354
24.15,150.34,-0.354
24.17,150.21,-0.354
24.18,150.07,-0.354
24.19,149.94,-0.354
24.21,149.81,-0.354
24.22,149.67,-0.354
24.23,149.54,-0.354
24.25,149.41,-0.354
24.26,149.27,-0.354
24.27,149.14,-0.354
24.29,149.01,-0.353
24.30,148.87,-0.353
24.31,148.74,-0.353
24.33,148.61,-0.353
24.34,148.47,-0.353
24.35,148.34,-0.353
24.37,148.21,-0.353
24.38,148.08,-0.353
24.39,147.94,-0.353
24.41,147.81,-0.353
24.42,147.68,-0.353
24.43,147.54,-0.353
24.45,147.41,-0.353
24.46,147.28,-0.353
24.47,147.14,-0.353
24.49,147.01,-0.353
24.50,146.88,-0.353
24.51,146.74,-0.353
24.53,146.61,-0.353
24.54,146.48,-0.352
24.55,146.34,-0.352
24.57,146.21,-0.352
24.58,146.08,-0.352
24.59,145.94,-0.352
24.61,145.81,-0.352
24.62,145.68,-0.352
24.63,145.54,-0.352
24.65,145.41,-0.352
24.66,145.28,-0.352
24.67,145.14,-0.352
24.69,145.01,-0.352
24.70,144.88,-0.352
24.71,144.74,-0.352
24.73,144.61,-0.352
24.74,144.48,-0.352
24.75,144.34,-0.352
24.77,144.21,-0.352
24.78,144.08,-0.352
24.79,143.95,-0.352
24.81,143.81,-0.351
24.82,143.68,-0.351
24.83,143.55,-0.351
24.85,143.41,-0.351
24.86,143.28,-0.351
24.87,143.15,-0.351
24.89,143.01,-0.351
24.90,142.88,-0.351
24.91,142.75,-0.351
24.93,142.62,-0.351
24.94,142.48,-0.351
24.95,142.35,-0.351
24.97,142.21,-0.351
24.98,142.08,-0.350
24.99,141.95,-0.350
25.01,141.81,-0.350
25.02,141.68,-0.350
25.03,141.55,-0.350
25.05,141.42,-0.350
25.06,141.28,-0.350
25.07,141.15,-0.350
25.09,141.02,-0.350
25.10,140.88,-0.350
25.11,140.75,-0.350
25.13,140.62,-0.350
25.14,140.48,-0.350
25.15,140.35,-0.350
25.17,140.22,-0.350
25.18,140.08,-0.350
25.19,139.95,-0.350
25.21,139.82,-0.350
25.22,139.69,-0.349
25.23,139.55,-0.349
25.25,139.42,-0.349
25.26,139.29,-0.349
25.27,139.15,-0.349
25.29,139.02,-0.349
25.30,138.89,-0.349
25.31,138.75,-0.349
25.33,138.62,-0.349
25.34,138.49,-0.349
25.35,138.35,-0.349
25.37,138.22,-0.349
25.38,138.09,-0.349
25.39,137.95,-0.349
25.41,137.82,-0.349
25.42,137.69,-0.349
25.43,137.55,-0.349
[...]
76.07,31.25,-0.258
76.09,31.12,-0.257
76.10,30.98,-0.257
76.11,30.85,-0.256
76.13,30.72,-0.256
76.14,30.58,-0.255
76.15,30.45,-0.255
76.17,30.32,-0.255
76.18,30.19,-0.254
76.19,30.05,-0.254
76.21,29.92,-0.253
76.22,29.78,-0.253
76.23,29.65,-0.253
76.25,29.52,-0.252
76.26,29.38,-0.252
76.27,29.25,-0.252
76.29,29.12,-0.252
76.30,28.98,-0.251
76.31,28.85,-0.251
76.33,28.72,-0.251
76.34,28.58,-0.251
76.35,28.45,-0.250
76.37,28.32,-0.250
76.38,28.18,-0.249
76.39,28.05,-0.249
76.41,27.92,-0.249
76.42,27.78,-0.248
76.43,27.65,-0.248
76.45,27.52,-0.248
76.46,27.38,-0.248
76.47,27.25,-0.247
76.49,27.12,-0.247
76.50,26.98,-0.246
76.51,26.85,-0.246
76.53,26.72,-0.246
76.54,26.58,-0.245
76.55,26.45,-0.245
76.57,26.32,-0.245
76.58,26.18,-0.245
76.59,26.05,-0.245
76.61,25.92,-0.244
76.62,25.79,-0.244
76.63,25.65,-0.244
76.65,25.52,-0.243
76.66,25.38,-0.243
76.67,25.25,-0.243
76.69,25.12,-0.242
76.70,24.98,-0.242
76.71,24.85,-0.242
76.73,24.72,-0.242
76.74,24.58,-0.242
76.75,24.45,-0.241
76.77,24.32,-0.241
76.78,24.18,-0.241
76.79,24.05,-0.240
76.81,23.92,-0.240
76.82,23.78,-0.240
76.83,23.65,-0.240
76.85,23.52,-0.240
76.86,23.38,-0.239
76.87,23.25,-0.239
76.89,23.12,-0.239
76.90,22.98,-0.239
76.91,22.85,-0.239
76.93,22.72,-0.239
76.94,22.58,-0.238
76.95,22.45,-0.237
76.97,22.32,-0.237
76.98,22.18,-0.237
76.99,22.05,-0.237
77.01,21.92,-0.236
77.02,21.79,-0.236
77.03,21.65,-0.236
77.05,21.52,-0.236
77.06,21.39,-0.236
77.07,21.25,-0.236
77.09,21.12,-0.236
77.10,20.98,-0.235
77.11,20.85,-0.235
77.13,20.72,-0.235
77.14,20.59,-0.235
77.15,20.45,-0.235
77.17,20.32,-0.235
77.18,20.19,-0.235
77.19,20.05,-0.234
77.21,19.92,-0.234
77.22,19.79,-0.234
77.23,19.65,-0.234
77.25,19.52,-0.234
77.26,19.39,-0.233
77.27,19.25,-0.233
77.29,19.12,-0.233
77.30,18.99,-0.233
77.31,18.85,-0.233
77.33,18.72,-0.233
77.34,18.59,-0.233
77.35,18.45,-0.232
77.37,18.32,-0.232
77.38,18.19,-0.232
77.39,18.05,-0.232
77.41,17.92,-0.232
77.42,17.79,-0.232
77.43,17.65,-0.232
77.45,17.52,-0.231
77.46,17.39,-0.231
77.47,17.26,-0.231
77.49,17.12,-0.231
77.50,16.99,-0.231
77.51,16.86,-0.230
77.53,16.72,-0.230
77.54,16.59,-0.230
77.55,16.46,-0.230
77.57,16.32,-0.230
77.58,16.19,-0.230
77.59,16.06,-0.244
77.61,15.93,-0.246
77.62,15.79,-0.240
77.63,15.66,-0.235
77.65,15.53,-0.230
77.66,15.39,-0.230
77.67,15.26,-0.229
77.69,15.13,-0.229
77.70,14.99,-0.229
77.71,14.86,-0.229
77.73,14.73,-0.228
77.74,14.59,-0.228
77.75,14.46,-0.228
77.77,14.33,-0.228
77.78,14.19,-0.228
77.79,14.06,-0.228
77.81,13.93,-0.228
77.82,13.79,-0.227
77.83,13.66,-0.227
77.85,13.53,-0.227
77.86,13.39,-0.227
77.87,13.26,-0.227
77.89,13.13,-0.227
77.90,13.00,-0.227
77.91,12.86,-0.227
77.93,12.73,-0.226
77.94,12.60,-0.226
77.95,12.46,-0.226
77.97,12.33,-0.226
77.98,12.20,-0.226
77.99,12.06,-0.226
78.01,11.93,-0.226
78.02,11.80,-0.226
78.03,11.66,-0.226
78.05,11.53,-0.225
78.06,11.40,-0.225
78.07,11.27,-0.225
78.09,11.13,-0.225
78.10,11.00,-0.225
78.11,10.87,-0.225
78.13,10.73,-0.225
78.14,10.60,-0.225
78.15,10.47,-0.224
78.17,10.33,-0.224
78.18,10.20,-0.224
78.19,10.07,-0.224
78.21,9.93,-0.224
78.22,9.80,-0.225
78.23,9.67,-0.225
78.25,9.54,-0.225
78.26,9.40,-0.225
78.27,9.27,-0.224
78.29,9.14,-0.224
78.30,9.00,-0.224
78.31,8.87,-0.224
78.33,8.74,-0.224
78.34,8.60,-0.223
78.35,8.47,-0.223
78.37,8.34,-0.223
78.38,8.20,-0.223
78.39,8.07,-0.223
78.41,7.94,-0.223
78.42,7.80,-0.223
78.43,7.67,-0.222
78.45,7.54,-0.222
78.46,7.41,-0.222
78.47,7.27,-0.222
78.49,7.14,-0.222
78.50,7.00,-0.222
78.51,6.87,-0.222
78.53,6.74,-0.222
78.54,6.60,-0.222
78.55,6.47,-0.221
78.57,6.34,-0.221
78.58,6.21,-0.221
78.59,6.07,-0.221
78.61,5.94,-0.221
78.62,5.81,-0.221
78.63,5.67,-0.221
78.65,5.54,-0.221
78.66,5.41,-0.221
78.67,5.27,-0.220
78.69,5.14,-0.220
78.70,5.00,-0.220
78.71,4.87,-0.220
78.73,4.74,-0.220
78.74,4.61,-0.220
78.75,4.47,-0.220
78.77,4.34,-0.220
78.78,4.20,-0.220
78.79,4.07,-0.219
78.81,3.94,-0.219
78.82,3.80,-0.219
78.83,3.67,-0.219
78.85,3.54,-0.219
78.86,3.40,-0.219
78.87,3.27,-0.219
78.89,3.14,-0.219
78.90,3.00,-0.219
78.91,2.87,-0.219
78.93,2.74,-0.219
78.94,2.60,-0.219
78.95,2.47,
78.97,2.34,
78.98,2.20,
78.99,2.07,
79.00,,

[step]
Ramp 10.00 °C/min to 30.00 °C
Time,Temperature,Heat Flow (Normalized)
min,°C,W/g
80.01,0.13,-0.013
80.01,0.13,-0.013
80.01,0.13,-0.013
80.02,0.13,-0.013
80.02,0.13,-0.013
80.02,0.13,-0.013
80.03,0.13,-0.013
80.03,0.13,-0.013
80.03,0.14,-0.013
80.04,0.14,-0.013
80.04,0.14,-0.013
80.04,0.14,-0.013
80.05,0.14,-0.013
80.05,0.14,-0.013
80.05,0.14,-0.013
80.06,0.14,-0.012
80.06,0.15,-0.012
80.06,0.15,-0.012
80.07,0.15,-0.012
80.07,0.16,-0.013
80.07,0.16,-0.013
80.08,0.17,-0.013
80.08,0.17,-0.014
80.08,0.18,-0.015
80.09,0.18,-0.015
80.09,0.19,-0.016
80.09,0.20,-0.017
80.10,0.21,-0.018
80.10,0.22,-0.018
80.10,0.23,-0.018
80.11,0.24,-0.019
80.11,0.25,-0.019
80.11,0.26,-0.019
80.12,0.27,-0.018
80.12,0.29,-0.018
80.12,0.30,-0.018
80.13,0.32,-0.018
80.13,0.33,-0.016
80.13,0.35,-0.012
80.14,0.36,-0.009
80.14,0.38,-0.006
80.14,0.40,-0.003
80.15,0.42,0.000
80.15,0.43,0.003
80.15,0.45,0.006
80.16,0.47,0.010
80.16,0.49,0.013
80.16,0.51,0.017
80.17,0.53,0.020
80.17,0.55,0.024
80.17,0.57,0.028
80.18,0.60,0.031
80.18,0.62,0.035
80.18,0.64,0.039
80.19,0.66,0.042
80.19,0.68,0.046
80.19,0.71,0.049
80.20,0.73,0.053
80.20,0.75,0.056
80.20,0.78,0.059
80.21,0.80,0.062
80.21,0.83,0.065
80.21,0.85,0.069
80.22,0.87,0.072
80.22,0.90,0.074
80.22,0.93,0.077
80.23,0.95,0.080
80.23,0.97,0.083
80.23,1.00,0.085
80.24,1.03,0.088
80.24,1.05,0.090
80.24,1.08,0.092
80.25,1.11,0.094
80.25,1.13,0.097
80.25,1.16,0.099
80.26,1.19,0.101
80.26,1.21,0.103
80.26,1.24,0.105
80.27,1.27,0.107
80.27,1.29,0.109
80.27,1.32,0.111
80.28,1.35,0.113
80.28,1.38,0.115
80.28,1.41,0.117
80.29,1.43,0.118
80.29,1.46,0.120
80.29,1.49,0.121
80.30,1.52,0.123
80.30,1.54,0.125
80.30,1.57,0.127
80.31,1.60,0.128
80.31,1.63,0.130
80.31,1.66,0.131
80.32,1.69,0.133
80.32,1.72,0.134
80.32,1.75,0.136
80.33,1.78,0.137
80.33,1.81,0.138
80.33,1.84,0.140
80.34,1.87,0.141
80.34,1.90,0.142
80.34,1.93,0.144
80.35,1.96,0.145
80.35,1.99,0.146
80.35,2.02,0.147
80.36,2.05,0.148
80.36,2.08,0.149
80.36,2.11,0.150
80.37,2.14,0.151
80.37,2.17,0.153
80.37,2.20,0.154
80.38,2.23,0.155
80.38,2.26,0.156
80.38,2.29,0.156
80.39,2.32,0.158
80.39,2.35,0.158
80.39,2.38,0.159
80.40,2.42,0.161
80.40,2.45,0.161
80.40,2.48,0.162
80.41,2.51,0.163
80.41,2.54,0.163
80.41,2.57,0.163
80.42,2.60,0.164
80.42,2.63,0.165
80.42,2.67,0.166
80.43,2.70,0.167
80.43,2.73,0.168
80.43,2.76,0.169
80.44,2.79,0.169
80.44,2.82,0.169
80.44,2.85,0.169
80.45,2.89,0.170
80.45,2.92,0.170
80.45,2.95,0.171
80.46,2.98,0.172
80.46,3.01,0.173
80.46,3.04,0.173
80.47,3.08,0.174
80.47,3.11,0.174
80.47,3.14,0.174
80.48,3.17,0.174
80.48,3.20,0.174
80.48,3.23,0.175
80.49,3.27,0.176
80.49,3.30,0.176
80.49,3.33,0.177
80.50,3.36,0.178
80.50,3.39,0.178
80.50,3.43,0.178
80.51,3.46,0.179
80.51,3.49,0.179
80.51,3.52,0.179
80.52,3.55,0.180
80.52,3.59,0.180
80.52,3.62,0.180
80.53,3.65,0.180
80.53,3.68,0.181
80.53,3.71,0.181
80.54,3.75,0.181
80.54,3.78,0.182
80.54,3.81,0.182
80.55,3.84,0.182
80.55,3.88,0.183
80.55,3.91,0.183
80.56,3.94,0.183
80.56,3.97,0.183
80.56,4.01,0.184
80.57,4.04,0.184
80.57,4.07,0.184
80.57,4.10,0.184
80.58,4.14,0.184
80.58,4.17,0.184
80.58,4.20,0.184
80.59,4.23,0.185
80.59,4.26,0.185
80.59,4.30,0.185
80.60,4.33,0.185
80.60,4.36,0.185
80.60,4.39,0.186
80.61,4.43,0.186
80.61,4.46,0.186
80.61,4.49,0.186
80.62,4.53,0.186
80.62,4.56,0.186
80.62,4.59,0.187
80.63,4.62,0.187
80.63,4.66,0.187
80.63,4.69,0.187
80.64,4.72,0.187
80.64,4.75,0.187
80.64,4.79,0.187
80.65,4.82,0.188
80.65,4.85,0.188
80.65,4.88,0.188
80.66,4.92,0.188
80.66,4.95,0.188
80.66,4.98,0.188
80.67,5.02,0.188
80.67,5.05,0.189
80.67,5.08,0.189
80.68,5.11,0.189
80.68,5.15,0.189
80.68,5.18,0.189
80.69,5.21,0.189
80.69,5.24,0.189
80.69,5.28,0.189
80.70,5.31,0.189
80.70,5.34,0.189
80.70,5.38,0.190
80.71,5.41,0.190
80.71,5.44,0.190
80.71,5.47,0.190
80.72,5.51,0.190
80.72,5.54,0.190
80.72,5.57,0.190
80.73,5.61,0.190
80.73,5.64,0.190
80.73,5.67,0.191
80.74,5.70,0.191
80.74,5.74,0.191
80.74,5.77,0.191
80.75,5.80,0.191
80.75,5.84,0.191
80.75,5.87,0.191
80.76,5.90,0.191
80.76,5.93,0.191
80.76,5.97,0.191
80.77,6.00,0.191
80.77,6.03,0.191
80.77,6.07,0.191
80.78,6.10,0.191
80.78,6.13,0.191
80.78,6.16,0.191
80.79,6.20,0.191
80.79,6.23,0.191
80.79,6.26,0.191
80.80,6.30,0.192
80.80,6.33,0.192
80.80,6.36,0.192
80.81,6.40,0.192
80.81,6.43,0.192
80.81,6.46,0.192
80.82,6.50,0.192
80.82,6.53,0.192
80.82,6.56,0.192
80.83,6.59,0.192
80.83,6.63,0.192
80.83,6.66,0.192
80.84,6.69,0.192
80.84,6.73,0.192
80.84,6.76,0.192
80.85,6.79,0.192
80.85,6.82,0.192
80.85,6.86,0.192
80.86,6.89,0.192
80.86,6.92,0.192
80.86,6.96,0.193
80.87,6.99,0.193
80.87,7.02,0.193
80.87,7.06,0.193
80.88,7.09,0.193
80.88,7.12,0.193
80.88,7.16,0.193
80.89,7.19,0.193
80.89,7.22,0.193
80.89,7.25,0.193
80.90,7.29,0.193
80.90,7.32,0.193
80.90,7.35,0.193
80.91,7.39,0.193
80.91,7.42,0.193
80.91,7.45,0.193
80.92,7.49,0.193
80.92,7.52,0.193
80.92,7.55,0.193
80.93,7.58,0.193
80.93,7.62,0.194
80.93,7.65,0.194
80.94,7.69,0.194
80.94,7.72,0.194
80.94,7.75,0.194
80.95,7.78,0.194
80.95,7.82,0.194
80.95,7.85,0.194
80.96,7.88,0.194
80.96,7.92,0.194
80.96,7.95,0.194
80.97,7.98,0.194
80.97,8.01,0.194
80.97,8.05,0.194
80.98,8.08,0.194
80.98,8.11,0.194
80.98,8.15,0.194
80.99,8.18,0.194
80.99,8.21,0.194
80.99,8.25,0.194
81.00,8.28,0.194
81.00,8.31,0.194
81.00,8.35,0.194
81.01,8.38,0.194
81.01,8.41,0.194
81.01,8.45,0.194
81.02,8.48,0.194
81.02,8.51,0.195
81.02,8.54,0.195
81.03,8.58,0.195
81.03,8.61,0.195
81.03,8.64,0.195
81.04,8.68,0.195
81.04,8.71,0.195
81.04,8.74,0.195
81.05,8.78,0.195
81.05,8.81,0.195
81.05,8.84,0.195
81.06,8.88,0.195
81.06,8.91,0.195
81.06,8.94,0.195
81.07,8.98,0.195
81.07,9.01,0.195
81.07,9.04,0.195
81.08,9.07,0.195
81.08,9.11,0.195
81.08,9.14,0.195
81.09,9.17,0.195
81.09,9.21,0.195
81.09,9.24,0.195
81.10,9.27,0.195
81.10,9.31,0.195
81.10,9.34,0.195
81.11,9.37,0.195
81.11,9.41,0.196
81.11,9.44,0.196
81.12,9.47,0.196
81.12,9.51,0.196
81.12,9.54,0.196
81.13,9.57,0.196
81.13,9.61,0.196
81.13,9.64,0.196
81.14,9.67,0.196
81.14,9.71,0.196
81.14,9.74,0.196
81.15,9.77,0.196
81.15,9.81,0.196
81.15,9.84,0.196
81.16,9.87,0.196
81.16,9.91,0.196
81.16,9.94,0.196
81.17,9.97,0.196
81.17,10.00,0.196
81.17,10.04,0.196
81.18,10.07,0.196
81.18,10.11,0.196
81.18,10.14,0.196
81.19,10.17,0.196
81.19,10.20,0.196
81.19,10.24,0.196
81.20,10.27,0.196
81.20,10.30,0.196
81.20,10.34,0.196
81.21,10.37,0.197
81.21,10.40,0.197
81.21,10.44,0.197
81.22,10.47,0.197
81.22,10.50,0.197
81.22,10.54,0.197
81.23,10.57,0.197
81.23,10.60,0.197
81.23,10.64,0.197
81.24,10.67,0.197
81.24,10.70,0.197
81.24,10.74,0.197
81.25,10.77,0.197
81.25,10.80,0.197
81.25,10.84,0.197
81.26,10.87,0.197
81.26,10.90,0.197
81.26,10.94,0.197
81.27,10.97,0.197
81.27,11.00,0.197
81.27,11.04,0.197
81.28,11.07,0.197
81.28,11.10,0.197
81.28,11.14,0.197
81.29,11.17,0.197
81.29,11.20,0.197
81.29,11.23,0.197
81.30,11.27,0.197
81.30,11.30,0.198
81.30,11.33,0.198
81.31,11.37,0.198
81.31,11.40,0.198
81.31,11.44,0.198
81.32,11.47,0.198
81.32,11.50,0.198
81.32,11.53,0.198
81.33,11.57,0.198
81.33,11.60,0.198
81.33,11.64,0.198
81.34,11.67,0.198
81.34,11.70,0.198
81.34,11.74,0.198
81.35,11.77,0.198
81.35,11.80,0.198
81.35,11.83,0.198
81.36,11.87,0.198
81.36,11.90,0.198
81.36,11.93,0.198
81.37,11.97,0.198
81.37,12.00,0.198
81.37,12.03,0.198
81.38,12.07,0.198
81.38,12.10,0.198
81.38,12.13,0.198
81.39,12.17,0.198
81.39,12.20,0.198
81.39,12.23,0.198
81.40,12.27,0.198
81.40,12.30,0.198
81.40,12.33,0.198
81.41,12.37,0.198
81.41,12.40,0.198
81.41,12.43,0.199
81.42,12.47,0.199
81.42,12.50,0.199
81.42,12.53,0.199
81.43,12.57,0.199
81.43,12.60,0.199
81.43,12.63,0.199
81.44,12.67,0.199
81.44,12.70,0.199
81.44,12.73,0.199
81.45,12.77,0.199
81.45,12.80,0.199
81.45,12.83,0.199
81.46,12.87,0.199
81.46,12.90,0.199
81.46,12.93,0.199
81.47,12.97,0.199
81.47,13.00,0.199
81.47,13.03,0.199
81.48,13.07,0.199
81.48,13.10,0.199
81.48,13.13,0.199
81.49,13.17,0.199
81.49,13.20,0.199
81.49,13.23,0.199
81.50,13.27,0.199
81.50,13.30,0.199
81.50,13.33,0.199
81.51,13.36,0.199
81.51,13.40,0.199
81.51,13.43,0.199
81.52,13.47,0.199
81.52,13.50,0.199
81.52,13.53,0.199
81.53,13.57,0.199
81.53,13.60,0.199
81.53,13.63,0.199
81.54,13.67,0.199
81.54,13.70,0.199
81.54,13.73,0.199
81.55,13.76,0.199
81.55,13.80,0.199
81.55,13.83,0.199
81.56,13.86,0.200
81.56,13.90,0.200
81.56,13.93,0.200
81.57,13.97,0.200
81.57,14.00,0.200
81.57,14.03,0.200
81.58,14.07,0.200
81.58,14.10,0.200
81.58,14.13,0.200
81.59,14.17,0.200
81.59,14.20,0.200
81.59,14.23,0.200
81.60,14.27,0.200
81.60,14.30,0.200
81.60,14.33,0.200
81.61,14.37,0.200
81.61,14.40,0.200
81.61,14.43,0.200
81.62,14.47,0.200
81.62,14.50,0.200
81.62,14.53,0.200
81.63,14.56,0.200
81.63,14.60,0.200
81.63,14.63,0.200
81.64,14.66,0.200
81.64,14.70,0.200
81.64,14.73,0.200
81.65,14.77,0.200
81.65,14.80,0.200
81.65,14.83,0.200
81.66,14.86,0.200
81.66,14.90,0.200
81.66,14.93,0.200
81.67,14.96,0.200
81.67,15.00,0.200
81.67,15.03,0.200
81.68,15.06,0.200
81.68,15.10,0.200
81.68,15.13,0.200
81.69,15.17,0.200
81.69,15.20,0.200
81.69,15.23,0.200
81.70,15.26,0.200
81.70,15.30,0.201
81.70,15.33,0.201
81.71,15.36,0.201
81.71,15.40,0.201
81.71,15.43,0.201
81.72,15.46,0.201
81.72,15.50,0.201
81.72,15.53,0.201
81.73,15.57,0.201
81.73,15.60,0.201
81.73,15.63,0.201
81.74,15.66,0.201
81.74,15.70,0.201
81.74,15.73,0.201
81.75,15.76,0.201
81.75,15.80,0.201
81.75,15.83,0.201
81.76,15.86,0.201
81.76,15.90,0.201
81.76,15.93,0.201
81.77,15.97,0.201
81.77,16.00,0.201
81.77,16.03,0.201
81.78,16.06,0.201
81.78,16.10,0.201
81.78,16.13,0.201
81.79,16.16,0.201
81.79,16.20,0.201
81.79,16.23,0.201
81.80,16.27,0.201
81.80,16.30,0.201
81.80,16.33,0.201
81.81,16.36,0.201
81.81,16.40,0.201
81.81,16.43,0.201
81.82,16.46,0.201
81.82,16.50,0.201
81.82,16.53,0.201
81.83,16.56,0.201
81.83,16.60,0.201
81.83,16.63,0.201
81.84,16.66,0.201
81.84,16.70,0.201
81.84,16.73,0.201
81.85,16.76,0.202
81.85,16.80,0.202
81.85,16.83,0.202
81.86,16.86,0.202
81.86,16.90,0.202
81.86,16.93,0.202
81.87,16.96,0.202
81.87,17.00,0.202
81.87,17.03,0.202
81.88,17.06,0.202
81.88,17.10,0.202
81.88,17.13,0.202
81.89,17.16,0.202
81.89,17.20,0.202
81.89,17.23,0.202
81.90,17.26,0.202
81.90,17.30,0.202
81.90,17.33,0.202
81.91,17.36,0.202
81.91,17.40,0.202
81.91,17.43,0.202
81.92,17.46,0.202
81.92,17.50,0.202
81.92,17.53,0.202
81.93,17.56,0.202
81.93,17.60,0.202
81.93,17.63,0.202
81.94,17.66,0.202
81.94,17.70,0.202
81.94,17.73,0.202
81.95,17.76,0.202
81.95,17.80,0.202
81.95,17.83,0.202
81.96,17.86,0.202
81.96,17.90,0.202
81.96,17.93,0.202
81.97,17.96,0.202
81.97,18.00,0.202
81.97,18.03,0.202
81.98,18.06,0.202
81.98,18.10,0.202
81.98,18.13,0.202
81.99,18.16,0.202
81.99,18.20,0.202
81.99,18.23,0.202
82.00,18.27,0.202
82.00,18.30,0.203
82.00,18.33,0.203
82.01,18.36,0.203
82.01,18.40,0.203
82.01,18.43,0.203
82.02,18.46,0.203
82.02,18.50,0.203
82.02,18.53,0.203
82.03,18.56,0.203
82.03,18.60,0.203
82.03,18.63,0.203
82.04,18.66,0.203
82.04,18.70,0.203
82.04,18.73,0.203
82.05,18.76,0.203
82.05,18.80,0.203
82.05,18.83,0.203
82.06,18.86,0.203
82.06,18.90,0.203
82.06,18.93,0.203
82.07,18.97,0.203
82.07,19.00,0.203
82.07,19.03,0.203
82.08,19.07,0.203
82.08,19.10,0.203
82.08,19.13,0.203
82.09,19.16,0.203
82.09,19.20,0.203
82.09,19.23,0.203
82.10,19.26,0.203
82.10,19.30,0.203
82.10,19.33,0.203
82.11,19.36,0.203
82.11,19.40,0.203
82.11,19.43,0.203
82.12,19.47,0.203
82.12,19.50,0.203
82.12,19.53,0.203
82.13,19.57,0.203
82.13,19.60,0.203
82.13,19.63,0.203
82.14,19.66,0.203
82.14,19.70,0.203
82.14,19.73,0.203
82.15,19.77,0.204
82.15,19.80,0.204
82.15,19.83,0.204
82.16,19.87,0.204
82.16,19.90,0.204
82.16,19.93,0.204
82.17,19.96,0.204
82.17,20.00,0.204
82.17,20.03,0.204
82.18,20.07,0.204
82.18,20.10,0.204
82.18,20.13,0.204
82.19,20.16,0.204
82.19,20.20,0.204
82.19,20.23,0.204
82.20,20.26,0.204
82.20,20.30,0.204
82.20,20.33,0.204
82.21,20.37,0.204
82.21,20.40,0.204
82.21,20.43,0.204
82.22,20.47,0.204
82.22,20.50,0.204
82.22,20.53,0.204
82.23,20.57,0.204
82.23,20.60,0.204
82.23,20.63,0.204
82.24,20.67,0.204
82.24,20.70,0.204
82.24,20.73,0.204
82.25,20.77,0.204
82.25,20.80,0.204
82.25,20.83,0.204
82.26,20.87,0.204
82.26,20.90,0.204
82.26,20.93,0.204
82.27,20.97,0.204
82.27,21.00,0.204
82.27,21.03,0.204
82.28,21.07,0.205
82.28,21.10,0.205
82.28,21.13,0.205
82.29,21.17,0.205
82.29,21.20,0.205
82.29,21.23,0.205
82.30,21.26,0.205
82.30,21.30,0.205
82.30,21.33,0.205
82.31,21.37,0.205
82.31,21.40,0.205
82.31,21.43,0.205
82.32,21.47,0.205
82.32,21.50,0.205
82.32,21.53,0.205
82.33,21.57,0.205
82.33,21.60,0.205
82.33,21.63,0.205
82.34,21.67,0.205
82.34,21.70,0.205
82.34,21.73,0.205
82.35,21.77,0.205
82.35,21.80,0.205
82.35,21.83,0.205
82.36,21.87,0.205
82.36,21.90,0.205
82.36,21.93,0.205
82.37,21.97,0.205
82.37,22.00,0.205
82.37,22.03,0.205
82.38,22.07,0.205
82.38,22.10,0.205
82.38,22.13,0.205
82.39,22.17,0.205
82.39,22.20,0.205
82.39,22.23,0.205
82.40,22.27,0.205
82.40,22.30,0.205
82.40,22.33,0.205
82.41,22.37,0.205
82.41,22.40,0.205
82.41,22.43,0.205
82.42,22.47,0.205
82.42,22.50,0.206
82.42,22.53,0.206
82.43,22.57,0.206
82.43,22.60,0.206
82.43,22.63,0.206
82.44,22.67,0.206
82.44,22.70,0.206
82.44,22.73,0.206
82.45,22.77,0.206
82.45,22.80,0.206
82.45,22.83,0.206
82.46,22.87,0.206
82.46,22.90,0.206
82.46,22.93,0.206
82.47,22.97,0.206
82.47,23.00,0.206
82.47,23.03,0.206
82.48,23.07,0.206
82.48,23.10,0.206
82.48,23.13,0.206
82.49,23.17,0.206
82.49,23.20,0.206
82.49,23.23,0.206
82.50,23.27,0.206
82.50,23.30,0.206
82.50,23.33,0.206
82.51,23.37,0.206
82.51,23.40,0.206
82.51,23.43,0.206
82.52,23.47,0.206
82.52,23.50,0.206
82.52,23.54,0.206
82.53,23.57,0.206
82.53,23.60,0.206
82.53,23.64,0.206
82.54,23.67,0.206
82.54,23.70,0.206
82.54,23.73,0.206
82.55,23.77,0.206
82.55,23.80,0.206
82.55,23.83,0.206
82.56,23.87,0.206
82.56,23.90,0.206
82.56,23.94,0.206
82.57,23.97,0.206
82.57,24.00,0.206
82.57,24.03,0.206
82.58,24.07,0.207
82.58,24.10,0.207
82.58,24.13,0.207
82.59,24.17,0.207
82.59,24.20,0.207
82.59,24.24,0.207
82.60,24.27,0.207
82.60,24.30,0.207
82.60,24.34,0.207
82.61,24.37,0.207
82.61,24.40,0.207
82.61,24.44,0.207
82.62,24.47,0.207
82.62,24.50,0.207
82.62,24.53,0.207
82.63,24.57,0.207
82.63,24.60,0.207
82.63,24.64,0.207
82.64,24.67,0.207
82.64,24.70,0.207
82.64,24.73,0.207
82.65,24.77,0.207
82.65,24.80,0.207
82.65,24.83,0.207
82.66,24.87,0.207
82.66,24.90,0.207
82.66,24.93,0.207
82.67,24.97,0.207
82.67,25.00,0.207
82.67,25.04,0.207
82.68,25.07,0.207
82.68,25.10,0.207
82.68,25.14,0.207
82.69,25.17,0.207
82.69,25.20,0.207
82.69,25.24,0.207
82.70,25.27,0.207
82.70,25.30,0.207
82.70,25.34,0.207
82.71,25.37,0.207
82.71,25.40,0.208
82.71,25.44,0.208
82.72,25.47,0.208
82.72,25.50,0.208
82.72,25.54,0.208
82.73,25.57,0.208
82.73,25.60,0.208
82.73,25.64,0.208
82.74,25.67,0.208
82.74,25.70,0.208
82.74,25.74,0.208
82.75,25.77,0.208
82.75,25.80,0.208
82.75,25.84,0.208
82.76,25.87,0.208
82.76,25.90,0.208
82.76,25.94,0.208
82.77,25.97,0.208
82.77,26.00,0.208
82.77,26.04,0.208
82.78,26.07,0.208
82.78,26.10,0.208
82.78,26.14,0.208
82.79,26.17,0.208
82.79,26.20,0.208
82.79,26.24,0.208
82.80,26.27,0.208
82.80,26.30,0.208
82.80,26.34,0.208
82.81,26.37,0.208
82.81,26.40,0.208
82.81,26.44,0.208
82.82,26.47,0.208
82.82,26.50,0.208
82.82,26.54,0.208
82.83,26.57,0.208
82.83,26.60,0.208
82.83,26.64,0.208
82.84,26.67,0.209
82.84,26.70,0.209
82.84,26.74,0.209
82.85,26.77,0.209
82.85,26.80,0.209
82.85,26.84,0.209
82.86,26.87,0.209
82.86,26.90,0.209
82.86,26.94,0.209
82.87,26.97,0.209
82.87,27.00,0.209
82.87,27.04,0.209
82.88,27.07,0.209
82.88,27.10,0.209
82.88,27.14,0.209
82.89,27.17,0.209
82.89,27.20,0.209
82.89,27.24,0.209
82.90,27.27,0.209
82.90,27.30,0.209
82.90,27.34,0.209
82.91,27.37,0.209
82.91,27.40,0.209
82.91,27.44,0.209
82.92,27.47,0.209
82.92,27.50,0.209
82.92,27.54,0.209
82.93,27.57,0.209
82.93,27.60,0.209
82.93,27.64,0.209
82.94,27.67,0.209
82.94,27.70,0.209
82.94,27.74,0.209
82.95,27.77,0.209
82.95,27.80,
82.95,27.84,
82.96,27.87,
82.96,27.90,
82.96,27.94,
82.97,27.97,
82.97,28.00,
82.97,28.04,
82.98,28.07,
82.98,28.10,
82.98,28.14,
82.99,28.17,
82.99,28.20,
82.99,28.24,
83.00,28.27,
83.00,,
83.00,,
83.00,,