File: DSC/2025_02_13_Naphthalene_DSC.txt
Filename	2025_02_13_Naphthalene_DSC
Instrument name	DSC2A-00468 (192.168.1.100)
Operator	JLY
rundate	2/13/2025
Sample name	2025_02_13_Naphthalene_DSC
proceduresegments	Data Off ; Equilibrate 30.00 °C; Data On ; Ramp 5.00 °C/min to 100.00 °C
[File Parameters]
Run date	2/13/2025 8:17:52 PM
Trios version	5.1.1.46572
Original File Name
Current File Name	D:\DSC2500\CHM343\2025_02_13_Naphthalene_DSC.tri
[Procedure]
Procedure Name	Naphthalene Melting
Sample Name	2025_02_13_Naphthalene_DSC
Sample Mass	3.65 mg
Reference Sample Mass	0 mg
Pan Mass	54.57 mg
Pan Number	22
Reference Pan Mass	54 mg
Reference Pan Number	19
Pan Type	Tzero Aluminum Hermetic
Comments	Al Hermetic Sealed Pan, with ref Al pan
Project Name
Operator	JLY
Test	Custom
Unload Max Temperature	30
Unload Min Temperature	30
Load Max Temperature	30
Load Min Temperature	30
Stop on Gas Flow Error	Yes
[Signal List]
Signal #1	Time (min)
Signal #2	Temperature (°C)
Signal #3	Heat Flow (mW)
Signal #4	Delta T (µV)
Signal #5	Delta Tzero (µV)
Signal #6	Tzero Temperature (°C)
Signal #7	Cell Purge (mL/min)
Signal #8	Heater Temp (°C)
Signal #9	Power Delivered (W)
Signal #10	Reference Junction Temperature (°C)
Signal #11	Flange Temperature (°C)
Signal #12	Heat Flow Phase (rad)
Signal #13	Total Heat Capacity (J/°C)
Signal #14	Heat Capacity (J/°C)
[Configuration]
Company Name	ASU
Instrument Name	DSC2A-00468
Instrument Type	DSC2500
Serial Number	DSC2A-00468
IP	192.168.1.100
Location of Instrument	MRRC
DisplayType	Unknown
Sample Interval 	0.1 s/pt
Selected Heat Flow	T4P
Exotherm Direction	Down
Cell Serial	DRC2-00792
Lid Type	Standard
Cooler	RCS 90
Leave Cooler on at End of Sequence	On
Gas 2	Nitrogen
Gas Selected	Channel 1
Flow Rate	50 mL/min
Secondary Purge	On
Licensed Heat Flow	Heat Flow T4P
Modulation Licensed	Yes
[Versions]
Common IDD Version	1
Cortex Version	VER 2.10.2.31
Driver	5.0.0.6
GDM Version	1.0.3.3
TouchscreenVersion	1.0.0.16145
FEP Version	1.2.1.21
FEP Bootloader	2.0.0.5
AutoSampler Version	2.1.1.26
Auto Sampler Bootloader	2.0.0.5
FCM Version	1.1.0.3
FCM Bootloader	2.0.0.5
[Experiment Logs]
Experiment Log Entry # 1	Data On set to 0
Experiment Log Entry # 3	Equilibrate Segment 30 (C) Started
Experiment Log Entry # 5	Air Cool is off.
Experiment Log Entry # 7	Data On set to 1
Experiment Log Entry # 9	Ramp Segment 5 C/min to 100 Started
[Method Log]
Method Log Entry # 1	Data Off
Method Log Entry # 2	Equilibrate 30 °C
Method Log Entry # 3	Data On
Method Log Entry # 4	(Ramp 57183) Ramp 5 °C/minute to 100 °C
Cell Serial	DRC2-00792
[T1 Calibration]
Slope	-0.008529666
Offset	9.636258
Initial Temperature	98.23
GUID	f8bfdadc-4977-4fdf-ba6d-0ba9134940c3
[TZero Calibration]
Date Applied	11/29/2022 4:06:13 PM
Description	From -89.059 °C to 396.009 °C at 20.000°C/min
Gas Type	Nitrogen
Pan Type	None
Source Files 1	C:\Users\yargerlab\Desktop\DSC Data\General\TZero_calibration_11_29_22_2nd(2).tri
Source Files 2	C:\Users\yargerlab\Desktop\DSC Data\General\TZero_calibration_11_29_22_2nd(3).tri
Delta T Offset	13.05235
Delta T Slope	-0.007271007
Delta T0 Offset	-13.69128
Delta T0 Slope	0.06063341
[Temperature Calibration]
Date Applied	11/29/2022 7:12:28 PM
Description	From 106.590 °C to 186.590 °C at 10.000°C/min
Gas Type	Nitrogen
Pan Type	Tzero Aluminum Hermetic
Source Files 1	C:\Users\yargerlab\Desktop\DSC Data\General\Indium(6).tri
Measured 1	157.391
Known 1	156.598
[Cell Constant Calibration]
Date Applied	11/29/2022 7:12:29 PM
Description	From 106.590 °C to 186.590 °C at 10.000°C/min
Gas Type	Nitrogen
Pan Type	Tzero Aluminum Hermetic
Source Files 1	C:\Users\yargerlab\Desktop\DSC Data\General\Indium(6).tri
T4P KCell	1.006051
Onset Slope	63.26126 mW/°C
[Direct Cp Calibration]
Date Applied	11/30/2022 11:04:51 AM
Description	From -79.983 °C to 298.409 °C at 10.000°C/min
Gas Type	Nitrogen
Pan Type	Tzero Aluminum Hermetic
Source Files 1	C:\Users\yargerlab\Desktop\DSC Data\General\Sapphire_Heat_Capacity_11_30_22.tri
[Rev Cp Calibration]
Date Applied	11/30/2022 1:58:51 PM
Description	From -79.996 °C to 292.812 °C at 3.000°C/min
Gas Type	Nitrogen
Pan Type	Tzero Aluminum Hermetic
Source Files 1	C:\Users\yargerlab\Desktop\DSC Data\General\Sapphire_MDSC_Calibration_11_30_22.tri
[step]
Ramp 5.00 °C/min to 100.00 °C
Time	Temperature	Heat Flow (Normalized)
min	°C	W/g
0.00	30.06	-0.038
0.01	30.06	-0.038
0.02	30.07	-0.037
0.03	30.07	-0.037
0.04	30.07	-0.036
0.05	30.07	-0.035
0.06	30.08	-0.033
0.07	30.08	-0.031
0.08	30.09	-0.029
0.09	30.10	-0.025
0.10	30.12	-0.020
0.11	30.14	-0.014
0.12	30.16	-0.006
0.13	30.19	0.002
0.14	30.22	0.008
0.15	30.24	0.018
0.16	30.28	0.025
0.17	30.31	0.032
0.18	30.35	0.039
0.19	30.39	0.045
0.20	30.43	0.050
0.21	30.47	0.055
0.22	30.51	0.058
0.23	30.55	0.063
0.24	30.59	0.066
0.25	30.63	0.070
0.26	30.68	0.073
0.27	30.72	0.076
0.28	30.77	0.078
0.29	30.81	0.081
0.30	30.86	0.082
0.31	30.90	0.085
0.32	30.95	0.087
0.33	31.00	0.089
0.34	31.04	0.090
0.35	31.09	0.091
0.36	31.14	0.093
0.37	31.19	0.094
0.38	31.23	0.095
0.39	31.28	0.096
0.40	31.33	0.097
0.41	31.38	0.098
0.42	31.43	0.099
0.43	31.48	0.099
0.44	31.53	0.099
0.45	31.57	0.100
0.46	31.62	0.101
0.47	31.67	0.101
0.48	31.72	0.101
0.49	31.77	0.101
0.50	31.82	0.102
0.51	31.87	0.102
0.52	31.92	0.102
0.53	31.97	0.103
0.54	32.02	0.103
0.55	32.07	0.103
0.56	32.11	0.103
0.57	32.17	0.103
0.58	32.21	0.104
0.59	32.26	0.104
0.60	32.31	0.104
0.61	32.36	0.104
0.62	32.41	0.104
0.63	32.46	0.105
0.64	32.51	0.105
0.65	32.56	0.105
0.66	32.61	0.105
0.67	32.66	0.105
0.68	32.71	0.106
0.69	32.76	0.106
0.70	32.81	0.106
0.71	32.86	0.106
0.72	32.91	0.106
0.73	32.96	0.106
0.74	33.01	0.106
0.75	33.06	0.107
0.76	33.11	0.107
0.77	33.16	0.107
0.78	33.21	0.107
0.79	33.25	0.107
0.80	33.31	0.107
0.81	33.35	0.107
0.82	33.41	0.108
0.83	33.45	0.108
0.84	33.50	0.108
0.85	33.55	0.108
0.86	33.60	0.108
0.87	33.65	0.108
0.88	33.70	0.108
0.89	33.75	0.108
0.90	33.80	0.108
0.91	33.85	0.108
0.92	33.90	0.108
0.93	33.95	0.108
0.94	34.00	0.109
0.95	34.05	0.109
0.96	34.10	0.109
0.97	34.15	0.109
0.98	34.20	0.109
0.99	34.25	0.109
1.00	34.30	0.109
1.01	34.35	0.109
1.02	34.40	0.109
1.03	34.45	0.109
1.04	34.50	0.109
1.05	34.55	0.109
1.06	34.60	0.109
1.07	34.65	0.109
1.08	34.70	0.109
1.09	34.75	0.109
1.10	34.80	0.109
1.11	34.85	0.109
1.12	34.90	0.109
1.13	34.95	0.109
1.14	35.00	0.110
1.15	35.05	0.110
1.16	35.10	0.110
1.17	35.15	0.110
1.18	35.20	0.110
1.19	35.25	0.110
1.20	35.30	0.110
1.21	35.35	0.110
1.22	35.40	0.110
1.23	35.45	0.110
1.24	35.50	0.110
1.25	35.55	0.110
1.26	35.60	0.110
1.27	35.65	0.110
1.28	35.70	0.110
1.29	35.75	0.110
1.30	35.80	0.110
1.31	35.85	0.110
1.32	35.90	0.110
1.33	35.95	0.110
1.34	36.00	0.110
1.35	36.05	0.110
1.36	36.10	0.110
1.37	36.15	0.110
1.38	36.20	0.110
1.39	36.25	0.110
1.40	36.30	0.110
1.41	36.35	0.110
1.42	36.40	0.110
1.43	36.45	0.110
1.44	36.50	0.110
1.45	36.55	0.110
1.46	36.59	0.110
1.47	36.65	0.110
1.48	36.70	0.110
1.49	36.74	0.110
1.50	36.80	0.110
1.51	36.85	0.110
1.52	36.89	0.110
1.53	36.94	0.110
1.54	36.99	0.110
1.55	37.04	0.110
1.56	37.09	0.110
1.57	37.14	0.110
1.58	37.19	0.110
1.59	37.25	0.110
1.60	37.29	0.110
1.61	37.34	0.110
1.62	37.39	0.110
1.63	37.44	0.110
1.64	37.49	0.110
1.65	37.54	0.110
1.66	37.59	0.110
1.67	37.64	0.110
1.68	37.69	0.110
1.69	37.74	0.110
1.70	37.79	0.110
1.71	37.84	0.110
1.72	37.89	0.110
1.73	37.94	0.110
1.74	37.99	0.110
1.75	38.04	0.110
1.76	38.09	0.110
1.77	38.14	0.110
1.78	38.19	0.110
1.79	38.24	0.110
1.80	38.29	0.110
1.81	38.34	0.110
1.82	38.39	0.110
1.83	38.44	0.110
1.84	38.49	0.110
1.85	38.54	0.110
1.86	38.59	0.110
1.87	38.64	0.110
1.88	38.69	0.110
1.89	38.74	0.110
1.90	38.79	0.110
1.91	38.84	0.110
1.92	38.89	0.110
1.93	38.94	0.110
1.94	38.99	0.110
1.95	39.04	0.110
1.96	39.09	0.110
1.97	39.14	0.110
1.98	39.19	0.110
1.99	39.24	0.110
2.00	39.29	0.110
2.01	39.34	0.110
2.02	39.39	0.110
2.03	39.44	0.110
2.04	39.49	0.110
2.05	39.54	0.110
2.06	39.59	0.110
2.07	39.64	0.110
2.08	39.69	0.110
2.09	39.74	0.110
2.10	39.79	0.110
2.11	39.84	0.110
2.12	39.89	0.110
2.13	39.95	0.110
2.14	39.99	0.110
2.15	40.04	0.110
2.16	40.09	0.110
2.17	40.14	0.110
2.18	40.20	0.110
2.19	40.25	0.110
2.20	40.29	0.110
2.21	40.34	0.110
2.22	40.39	0.110
2.23	40.44	0.110
2.24	40.49	0.110
2.25	40.54	0.110
2.26	40.59	0.110
2.27	40.65	0.111
2.28	40.69	0.111
2.29	40.75	0.111
2.30	40.79	0.111
2.31	40.85	0.111
2.32	40.90	0.111
2.33	40.94	0.111
2.34	40.99	0.111
2.35	41.04	0.111
2.36	41.10	0.111
2.37	41.15	0.111
2.38	41.20	0.111
2.39	41.24	0.111
2.40	41.30	0.111
2.41	41.34	0.111
2.42	41.40	0.111
2.43	41.45	0.111
2.44	41.49	0.111
2.45	41.54	0.111
2.46	41.59	0.111
2.47	41.65	0.111
2.48	41.70	0.111
2.49	41.75	0.111
2.50	41.79	0.111
2.51	41.85	0.111
2.52	41.90	0.111
2.53	41.94	0.111
2.54	42.00	0.111
2.55	42.05	0.111
2.56	42.10	0.111
2.57	42.15	0.111
2.58	42.20	0.111
2.59	42.25	0.111
2.60	42.30	0.111
2.61	42.35	0.111
2.62	42.40	0.111
2.63	42.45	0.111
2.64	42.50	0.111
2.65	42.55	0.111
2.66	42.59	0.111
2.67	42.65	0.111
2.68	42.70	0.111
2.69	42.75	0.111
2.70	42.80	0.111
2.71	42.85	0.111
2.72	42.90	0.111
2.73	42.95	0.111
2.74	43.00	0.111
2.75	43.05	0.111
2.76	43.10	0.111
2.77	43.15	0.111
2.78	43.20	0.111
2.79	43.25	0.111
2.80	43.30	0.111
2.81	43.35	0.111
2.82	43.40	0.111
2.83	43.45	0.111
2.84	43.50	0.111
2.85	43.55	0.111
2.86	43.60	0.111
2.87	43.65	0.111
2.88	43.70	0.111
2.89	43.75	0.111
2.90	43.80	0.111
2.91	43.85	0.111
2.92	43.90	0.111
2.93	43.95	0.111
2.94	44.00	0.111
2.95	44.05	0.111
2.96	44.10	0.111
2.97	44.15	0.111
2.98	44.20	0.111
2.99	44.25	0.111
3.00	44.30	0.111
3.01	44.35	0.111
3.02	44.40	0.111
3.03	44.45	0.111
3.04	44.50	0.111
3.05	44.55	0.111
3.06	44.60	0.111
3.07	44.65	0.111
3.08	44.70	0.111
3.09	44.75	0.111
3.10	44.80	0.111
3.11	44.85	0.111
3.12	44.90	0.111
3.13	44.95	0.111
3.14	45.00	0.111
3.15	45.05	0.111
3.16	45.10	0.111
3.17	45.15	0.111
3.18	45.20	0.111
3.19	45.25	0.111
3.20	45.30	0.111
3.21	45.35	0.111
3.22	45.40	0.111
3.23	45.45	0.111
3.24	45.50	0.111
3.25	45.55	0.111
3.26	45.60	0.112
3.27	45.65	0.111
3.28	45.70	0.112
3.29	45.75	0.112
3.30	45.80	0.112
3.31	45.85	0.112
3.32	45.90	0.112
3.33	45.95	0.112
3.34	46.00	0.112
3.35	46.05	0.112
3.36	46.10	0.112
3.37	46.15	0.112
3.38	46.20	0.112
3.39	46.25	0.112
3.40	46.30	0.112
3.41	46.35	0.112
3.42	46.40	0.112
3.43	46.45	0.112
3.44	46.50	0.112
3.45	46.55	0.112
3.46	46.60	0.112
3.47	46.65	0.112
3.48	46.70	0.112
3.49	46.75	0.112
3.50	46.80	0.112
3.51	46.85	0.112
3.52	46.90	0.112
3.53	46.95	0.112
3.54	47.00	0.112
3.55	47.05	0.112
3.56	47.10	0.112
3.57	47.15	0.112
3.58	47.20	0.112
3.59	47.25	0.112
3.60	47.30	0.112
3.61	47.35	0.112
3.62	47.40	0.112
3.63	47.45	0.112
3.64	47.50	0.112
3.65	47.55	0.112
3.66	47.60	0.112
3.67	47.65	0.112
3.68	47.70	0.112
3.69	47.75	0.112
3.70	47.80	0.112
3.71	47.85	0.112
3.72	47.90	0.112
3.73	47.95	0.112
3.74	48.00	0.112
3.75	48.05	0.112
3.76	48.10	0.112
3.77	48.15	0.112
3.78	48.20	0.112
3.79	48.25	0.112
3.80	48.30	0.112
3.81	48.35	0.112
3.82	48.40	0.112
3.83	48.45	0.112
3.84	48.50	0.112
3.85	48.55	0.112
3.86	48.60	0.112
3.87	48.65	0.112
3.88	48.70	0.112
3.89	48.75	0.112
3.90	48.80	0.112
3.91	48.85	0.112
3.92	48.90	0.112
3.93	48.95	0.112
3.94	49.00	0.113
3.95	49.05	0.113
3.96	49.10	0.113
3.97	49.15	0.113
3.98	49.20	0.113
3.99	49.25	0.113
4.00	49.30	0.113
4.01	49.35	0.113
4.02	49.40	0.113
4.03	49.45	0.113
4.04	49.50	0.113
4.05	49.55	0.113
4.06	49.60	0.113
4.07	49.65	0.113
4.08	49.70	0.113
4.09	49.75	0.113
4.10	49.80	0.113
4.11	49.85	0.113
4.12	49.90	0.113
4.13	49.95	0.113
4.14	50.00	0.113
4.15	50.05	0.113
4.16	50.10	0.113
4.17	50.15	0.113
4.18	50.20	0.113
4.19	50.25	0.113
4.20	50.30	0.113
4.21	50.35	0.113
4.22	50.40	0.113
4.23	50.45	0.113
4.24	50.50	0.113
4.25	50.55	0.113
4.26	50.60	0.113
4.27	50.65	0.113
4.28	50.70	0.113
4.29	50.75	0.113
4.30	50.80	0.113
4.31	50.85	0.113
4.32	50.90	0.113
4.33	50.95	0.113
4.34	51.00	0.113
4.35	51.05	0.113
4.36	51.10	0.113
4.37	51.15	0.113
4.38	51.20	0.113
4.39	51.25	0.113
4.40	51.30	0.113
4.41	51.35	0.113
4.42	51.40	0.113
4.43	51.45	0.113
4.44	51.50	0.113
4.45	51.55	0.113
4.46	51.60	0.113
4.47	51.65	0.113
4.48	51.70	0.113
4.49	51.75	0.114
4.50	51.80	0.114
4.51	51.85	0.114
4.52	51.90	0.114
4.53	51.95	0.114
4.54	52.00	0.114
4.55	52.05	0.114
4.56	52.10	0.114
4.57	52.15	0.114
4.58	52.20	0.114
4.59	52.25	0.114
4.60	52.30	0.114
4.61	52.35	0.114
4.62	52.40	0.114
4.63	52.45	0.114
4.64	52.50	0.114
4.65	52.55	0.114
4.66	52.60	0.114
4.67	52.65	0.114
4.68	52.70	0.114
4.69	52.75	0.114
4.70	52.80	0.114
4.71	52.85	0.114
4.72	52.90	0.114
4.73	52.95	0.114
4.74	53.00	0.114
4.75	53.05	0.114
4.76	53.10	0.114
4.77	53.15	0.114
4.78	53.20	0.114
4.79	53.25	0.114
4.80	53.30	0.114
4.81	53.35	0.114
4.82	53.40	0.114
4.83	53.45	0.114
4.84	53.50	0.114
4.85	53.55	0.114
4.86	53.60	0.114
4.87	53.65	0.114
4.88	53.70	0.114
4.89	53.75	0.114
4.90	53.80	0.114
4.91	53.85	0.114
4.92	53.90	0.114
4.93	53.95	0.114
4.94	54.00	0.114
4.95	54.05	0.114
4.96	54.10	0.114
4.97	54.15	0.114
4.98	54.20	0.114
4.99	54.25	0.114
5.00	54.30	0.114
5.01	54.35	0.115
5.02	54.40	0.115
5.03	54.45	0.115
5.04	54.50	0.115
5.05	54.55	0.115
5.06	54.60	0.115
5.07	54.65	0.115
5.08	54.70	0.115
5.09	54.75	0.115
5.10	54.80	0.115
5.11	54.85	0.115
5.12	54.90	0.115
5.13	54.95	0.115
5.14	55.00	0.115
5.15	55.05	0.115
5.16	55.10	0.115
5.17	55.15	0.115
5.18	55.20	0.115
5.19	55.25	0.115
5.20	55.30	0.115
5.21	55.35	0.115
5.22	55.40	0.115
5.23	55.45	0.115
5.24	55.50	0.115
5.25	55.55	0.115
5.26	55.60	0.115
5.27	55.65	0.115
5.28	55.70	0.115
5.29	55.75	0.115
5.30	55.80	0.115
5.31	55.85	0.115
5.32	55.90	0.115
5.33	55.95	0.115
5.34	56.00	0.115
5.35	56.05	0.115
5.36	56.10	0.115
5.37	56.15	0.115
5.38	56.20	0.115
5.39	56.25	0.115
5.40	56.30	0.115
5.41	56.35	0.115
5.42	56.40	0.116
5.43	56.45	0.116
5.44	56.50	0.116
5.45	56.55	0.116
5.46	56.60	0.116
5.47	56.65	0.116
5.48	56.70	0.116
5.49	56.75	0.116
5.50	56.80	0.116
5.51	56.85	0.116
5.52	56.90	0.116
5.53	56.95	0.116
5.54	57.00	0.116
5.55	57.05	0.116
5.56	57.10	0.116
5.57	57.15	0.116
5.58	57.20	0.116
5.59	57.25	0.116
5.60	57.30	0.116
5.61	57.35	0.116
5.62	57.40	0.116
5.63	57.45	0.116
5.64	57.50	0.116
5.65	57.55	0.116
5.66	57.60	0.116
5.67	57.65	0.116
5.68	57.70	0.116
5.69	57.75	0.116
5.70	57.80	0.116
5.71	57.85	0.116
5.72	57.90	0.116
5.73	57.95	0.116
5.74	58.00	0.116
5.75	58.05	0.116
5.76	58.10	0.116
5.77	58.15	0.116
5.78	58.20	0.116
5.79	58.25	0.116
5.80	58.30	0.116
5.81	58.35	0.116
5.82	58.40	0.116
5.83	58.45	0.116
5.84	58.50	0.116
5.85	58.55	0.117
5.86	58.60	0.117
5.87	58.65	0.117
5.88	58.70	0.117
5.89	58.75	0.117
5.90	58.80	0.117
5.91	58.85	0.117
5.92	58.90	0.117
5.93	58.95	0.117
5.94	59.00	0.117
5.95	59.05	0.117
5.96	59.10	0.117
5.97	59.15	0.117
5.98	59.20	0.117
5.99	59.25	0.117
6.00	59.30	0.117
6.01	59.35	0.117
6.02	59.40	0.117
6.03	59.45	0.117
6.04	59.50	0.117
6.05	59.55	0.117
6.06	59.60	0.117
6.07	59.65	0.117
6.08	59.70	0.117
6.09	59.75	0.117
6.10	59.80	0.117
6.11	59.85	0.117
6.12	59.90	0.117
6.13	59.95	0.117
6.14	60.00	0.117
6.15	60.05	0.117
6.16	60.10	0.117
6.17	60.15	0.117
6.18	60.20	0.117
6.19	60.25	0.117
6.20	60.30	0.117
6.21	60.35	0.117
6.22	60.40	0.117
6.23	60.45	0.117
6.24	60.50	0.117
6.25	60.55	0.118
6.26	60.60	0.118
6.27	60.65	0.118
6.28	60.70	0.118
6.29	60.75	0.118
6.30	60.80	0.118
6.31	60.85	0.118
6.32	60.90	0.118
6.33	60.95	0.118
6.34	61.00	0.118
6.35	61.05	0.118
6.36	61.10	0.118
6.37	61.15	0.118
6.38	61.20	0.118
6.39	61.25	0.118
6.40	61.30	0.118
6.41	61.35	0.118
6.42	61.40	0.118
6.43	61.45	0.118
6.44	61.51	0.118
6.45	61.55	0.118
6.46	61.60	0.118
6.47	61.65	0.118
6.48	61.71	0.118
6.49	61.75	0.118
6.50	61.80	0.118
6.51	61.85	0.118
6.52	61.90	0.118
6.53	61.95	0.118
6.54	62.00	0.118
6.55	62.05	0.118
6.56	62.10	0.118
6.57	62.15	0.118
6.58	62.20	0.118
6.59	62.25	0.119
6.60	62.31	0.119
6.61	62.35	0.119
6.62	62.40	0.119
6.63	62.46	0.119
6.64	62.50	0.119
6.65	62.55	0.119
6.66	62.61	0.119
6.67	62.66	0.119
6.68	62.71	0.119
6.69	62.76	0.119
6.70	62.80	0.119
6.71	62.85	0.119
6.72	62.91	0.119
6.73	62.95	0.119
6.74	63.01	0.119
6.75	63.05	0.119
6.76	63.10	0.119
6.77	63.16	0.119
6.78	63.20	0.119
6.79	63.26	0.119
6.80	63.31	0.119
6.81	63.35	0.119
6.82	63.41	0.119
6.83	63.45	0.119
6.84	63.50	0.119
6.85	63.56	0.119
6.86	63.61	0.119
6.87	63.65	0.120
6.88	63.70	0.120
6.89	63.75	0.120
6.90	63.80	0.120
6.91	63.85	0.120
6.92	63.90	0.120
6.93	63.95	0.120
6.94	64.01	0.120
6.95	64.06	0.120
6.96	64.10	0.120
6.97	64.15	0.120
6.98	64.20	0.120
6.99	64.25	0.120
7.00	64.30	0.120
7.01	64.36	0.120
7.02	64.40	0.120
7.03	64.45	0.120
7.04	64.51	0.120
7.05	64.56	0.120
7.06	64.60	0.120
7.07	64.66	0.120
7.08	64.71	0.120
7.09	64.75	0.120
7.10	64.81	0.120
7.11	64.86	0.120
7.12	64.91	0.120
7.13	64.96	0.120
7.14	65.00	0.120
7.15	65.05	0.120
7.16	65.10	0.121
7.17	65.16	0.121
7.18	65.21	0.121
7.19	65.26	0.121
7.20	65.31	0.121
7.21	65.36	0.121
7.22	65.40	0.121
7.23	65.46	0.121
7.24	65.51	0.121
7.25	65.56	0.121
7.26	65.60	0.121
7.27	65.65	0.121
7.28	65.71	0.121
7.29	65.75	0.121
7.30	65.81	0.121
7.31	65.86	0.121
7.32	65.91	0.121
7.33	65.96	0.121
7.34	66.01	0.121
7.35	66.06	0.121
7.36	66.11	0.121
7.37	66.16	0.121
7.38	66.20	0.121
7.39	66.26	0.121
7.40	66.31	0.121
7.41	66.36	0.121
7.42	66.41	0.121
7.43	66.46	0.121
7.44	66.51	0.121
7.45	66.56	0.121
7.46	66.61	0.121
7.47	66.66	0.121
7.48	66.71	0.121
7.49	66.76	0.121
7.50	66.81	0.122
7.51	66.86	0.122
7.52	66.91	0.122
7.53	66.96	0.122
7.54	67.01	0.122
7.55	67.06	0.122
7.56	67.11	0.122
7.57	67.16	0.122
7.58	67.21	0.122
7.59	67.26	0.122
7.60	67.31	0.122
7.61	67.36	0.122
7.62	67.41	0.122
7.63	67.46	0.122
7.64	67.51	0.122
7.65	67.56	0.122
7.66	67.61	0.122
7.67	67.66	0.122
7.68	67.71	0.122
7.69	67.76	0.122
7.70	67.81	0.122
7.71	67.86	0.122
7.72	67.91	0.122
7.73	67.96	0.122
7.74	68.01	0.122
7.75	68.06	0.122
7.76	68.11	0.122
7.77	68.16	0.122
7.78	68.21	0.122
7.79	68.26	0.123
7.80	68.31	0.123
7.81	68.36	0.123
7.82	68.41	0.123
7.83	68.46	0.123
7.84	68.51	0.123
7.85	68.56	0.123
7.86	68.61	0.123
7.87	68.66	0.123
7.88	68.71	0.123
7.89	68.76	0.123
7.90	68.81	0.123
7.91	68.86	0.123
7.92	68.91	0.123
7.93	68.96	0.123
7.94	69.01	0.123
7.95	69.06	0.123
7.96	69.11	0.123
7.97	69.16	0.123
7.98	69.21	0.123
7.99	69.26	0.123
8.00	69.31	0.123
8.01	69.36	0.123
8.02	69.41	0.123
8.03	69.46	0.123
8.04	69.51	0.123
8.05	69.56	0.123
8.06	69.61	0.123
8.07	69.66	0.124
8.08	69.71	0.124
8.09	69.76	0.124
8.10	69.81	0.124
8.11	69.86	0.124
8.12	69.91	0.124
8.13	69.96	0.124
8.14	70.01	0.124
8.15	70.06	0.124
8.16	70.11	0.124
8.17	70.16	0.124
8.18	70.21	0.124
8.19	70.26	0.124
8.20	70.31	0.124
8.21	70.36	0.124
8.22	70.41	0.124
8.23	70.46	0.124
8.24	70.51	0.124
8.25	70.56	0.124
8.26	70.61	0.124
8.27	70.66	0.124
8.28	70.71	0.124
8.29	70.76	0.124
8.30	70.81	0.124
8.31	70.86	0.124
8.32	70.91	0.124
8.33	70.96	0.124
8.34	71.01	0.124
8.35	71.06	0.125
8.36	71.11	0.125
8.37	71.16	0.125
8.38	71.21	0.125
8.39	71.26	0.125
8.40	71.31	0.125
8.41	71.36	0.125
8.42	71.41	0.125
8.43	71.46	0.125
8.44	71.51	0.125
8.45	71.56	0.125
8.46	71.61	0.125
8.47	71.66	0.125
8.48	71.71	0.125
8.49	71.76	0.125
8.50	71.81	0.125
8.51	71.86	0.125
8.52	71.91	0.125
8.53	71.96	0.125
8.54	72.01	0.125
8.55	72.06	0.125
8.56	72.11	0.125
8.57	72.16	0.125
8.58	72.21	0.125
8.59	72.26	0.126
8.60	72.31	0.126
8.61	72.36	0.126
8.62	72.41	0.126
8.63	72.46	0.126
8.64	72.51	0.126
8.65	72.56	0.126
8.66	72.61	0.126
8.67	72.66	0.126
8.68	72.71	0.126
8.69	72.76	0.126
8.70	72.81	0.126
8.71	72.86	0.126
8.72	72.91	0.126
8.73	72.96	0.126
8.74	73.01	0.126
8.75	73.06	0.126
8.76	73.11	0.126
8.77	73.16	0.126
8.78	73.21	0.127
8.79	73.26	0.127
8.80	73.31	0.127
8.81	73.36	0.127
8.82	73.41	0.127
8.83	73.46	0.127
8.84	73.51	0.127
8.85	73.56	0.127
8.86	73.61	0.127
8.87	73.66	0.127
8.88	73.71	0.127
8.89	73.76	0.127
8.90	73.81	0.127
8.91	73.86	0.127
8.92	73.91	0.127
8.93	73.96	0.127
8.94	74.01	0.127
8.95	74.06	0.127
8.96	74.11	0.127
8.97	74.16	0.127
8.98	74.21	0.128
8.99	74.26	0.128
9.00	74.31	0.128
9.01	74.36	0.128
9.02	74.41	0.128
9.03	74.46	0.128
9.04	74.51	0.128
9.05	74.56	0.128
9.06	74.61	0.128
9.07	74.66	0.128
9.08	74.71	0.128
9.09	74.76	0.128
9.10	74.81	0.128
9.11	74.86	0.128
9.12	74.91	0.128
9.13	74.96	0.128
9.14	75.01	0.129
9.15	75.06	0.129
9.16	75.11	0.129
9.17	75.16	0.129
9.18	75.21	0.129
9.19	75.26	0.129
9.20	75.31	0.129
9.21	75.36	0.129
9.22	75.41	0.129
9.23	75.46	0.129
9.24	75.51	0.129
9.25	75.56	0.129
9.26	75.61	0.129
9.27	75.66	0.129
9.28	75.71	0.129
9.29	75.76	0.129
9.30	75.81	0.130
9.31	75.86	0.130
9.32	75.91	0.130
9.33	75.96	0.130
9.34	76.01	0.130
9.35	76.06	0.130
9.36	76.11	0.130
9.37	76.16	0.130
9.38	76.21	0.130
9.39	76.26	0.130
9.40	76.31	0.130
9.41	76.36	0.131
9.42	76.41	0.131
9.43	76.46	0.131
9.44	76.51	0.131
9.45	76.56	0.131
9.46	76.61	0.131
9.47	76.66	0.132
9.48	76.71	0.132
9.49	76.76	0.132
9.50	76.81	0.132
9.51	76.86	0.132
9.52	76.91	0.133
9.53	76.96	0.133
9.54	77.01	0.135
9.55	77.06	0.136
9.56	77.11	0.138
9.57	77.16	0.143
9.58	77.21	0.148
9.59	77.26	0.154
9.60	77.31	0.162
9.61	77.36	0.170
9.62	77.40	0.182
9.63	77.45	0.191
9.64	77.50	0.202
9.65	77.55	0.214
9.66	77.60	0.231
9.67	77.64	0.249
9.68	77.69	0.269
9.69	77.74	0.298
9.70	77.78	0.330
9.71	77.83	0.369
9.72	77.87	0.415
9.73	77.91	0.470
9.74	77.96	0.535
9.75	78.00	0.610
9.76	78.03	0.695
9.77	78.07	0.790
9.78	78.10	0.893
9.79	78.13	1.002
9.80	78.16	1.113
9.81	78.19	1.230
9.82	78.22	1.344
9.83	78.25	1.460
9.84	78.27	1.574
9.85	78.30	1.687
9.86	78.32	1.795
9.87	78.35	1.904
9.88	78.37	2.004
9.89	78.39	2.091
9.90	78.42	2.190
9.91	78.45	2.260
9.92	78.47	2.323
9.93	78.50	2.386
9.94	78.53	2.435
9.95	78.57	2.483
9.96	78.60	2.534
9.97	78.63	2.583
9.98	78.67	2.638
9.99	78.70	2.696
10.00	78.74	2.758
10.01	78.77	2.831
10.02	78.81	2.900
10.03	78.84	2.972
10.04	78.87	3.044
10.05	78.90	3.120
10.06	78.94	3.200
10.07	78.97	3.279
10.08	79.00	3.362
10.09	79.03	3.446
10.10	79.06	3.531
10.11	79.09	3.618
10.12	79.13	3.703
10.13	79.16	3.783
10.14	79.19	3.860
10.15	79.22	3.928
10.16	79.25	3.991
10.17	79.28	4.046
10.18	79.31	4.099
10.19	79.35	4.151
10.20	79.38	4.201
10.21	79.42	4.243
10.22	79.45	4.279
10.23	79.49	4.314
10.24	79.53	4.341
10.25	79.57	4.375
10.26	79.61	4.419
10.27	79.65	4.455
10.28	79.69	4.499
10.29	79.72	4.543
10.30	79.76	4.600
10.31	79.80	4.674
10.32	79.84	4.737
10.33	79.88	4.831
10.34	79.91	4.990
10.35	79.93	5.166
10.36	79.96	5.176
10.37	80.00	5.162
10.38	80.03	5.247
10.39	80.07	5.225
10.40	80.11	5.028
10.41	80.17	4.809
10.42	80.24	4.453
10.43	80.32	3.924
10.44	80.43	3.352
10.45	80.55	2.800
10.46	80.68	2.306
10.47	80.82	1.891
10.48	80.95	1.582
10.49	81.08	1.382
10.50	81.20	1.238
10.51	81.32	1.119
10.52	81.42	1.015
10.53	81.53	0.924
10.54	81.62	0.841
10.55	81.71	0.765
10.56	81.80	0.705
10.57	81.88	0.641
10.58	81.96	0.589
10.59	82.04	0.540
10.60	82.11	0.500
10.61	82.18	0.462
10.62	82.25	0.427
10.63	82.32	0.396
10.64	82.39	0.371
10.65	82.45	0.344
10.66	82.51	0.323
10.67	82.57	0.303
10.68	82.63	0.285
10.69	82.69	0.270
10.70	82.75	0.255
10.71	82.80	0.243
10.72	82.86	0.232
10.73	82.91	0.222
10.74	82.97	0.214
10.75	83.02	0.205
10.76	83.08	0.199
10.77	83.13	0.191
10.78	83.19	0.185
10.79	83.24	0.179
10.80	83.29	0.178
10.81	83.34	0.172
10.82	83.40	0.170
10.83	83.45	0.165
10.84	83.50	0.163
10.85	83.55	0.161
10.86	83.60	0.158
10.87	83.65	0.157
10.88	83.70	0.153
10.89	83.75	0.153
10.90	83.81	0.152
10.91	83.86	0.151
10.92	83.91	0.150
10.93	83.96	0.149
10.94	84.01	0.148
10.95	84.06	0.148
10.96	84.11	0.147
10.97	84.16	0.147
10.98	84.21	0.146
10.99	84.26	0.146
11.00	84.31	0.145
11.01	84.36	0.145
11.02	84.41	0.144
11.03	84.46	0.144
11.04	84.51	0.144
11.05	84.56	0.144
11.06	84.61	0.143
11.07	84.66	0.143
11.08	84.71	0.143
11.09	84.76	0.143
11.10	84.81	0.142
11.11	84.86	0.142
11.12	84.91	0.142
11.13	84.96	0.142
11.14	85.01	0.142
11.15	85.06	0.142
11.16	85.11	0.141
11.17	85.16	0.141
11.18	85.21	0.141
11.19	85.26	0.141
11.20	85.31	0.141
11.21	85.36	0.141
11.22	85.41	0.141
11.23	85.46	0.141
11.24	85.51	0.140
11.25	85.56	0.140
11.26	85.61	0.140
11.27	85.66	0.140
11.28	85.71	0.140
11.29	85.76	0.140
11.30	85.81	0.140
11.31	85.86	0.140
11.32	85.91	0.140
11.33	85.96	0.140
11.34	86.01	0.140
11.35	86.06	0.140
11.36	86.11	0.140
11.37	86.16	0.140
11.38	86.21	0.139
11.39	86.26	0.139
11.40	86.31	0.139
11.41	86.36	0.139
11.42	86.41	0.139
11.43	86.46	0.139
11.44	86.51	0.139
11.45	86.56	0.139
11.46	86.61	0.139
11.47	86.66	0.139
11.48	86.71	0.139
11.49	86.76	0.139
11.50	86.81	0.139
11.51	86.86	0.139
11.52	86.91	0.139
11.53	86.96	0.139
11.54	87.01	0.139
11.55	87.06	0.139
11.56	87.11	0.139
11.57	87.16	0.139
11.58	87.21	0.139
11.59	87.26	0.139
11.60	87.31	0.139
11.61	87.36	0.139
11.62	87.41	0.139
11.63	87.46	0.139
11.64	87.51	0.139
11.65	87.56	0.139
11.66	87.61	0.139
11.67	87.66	0.139
11.68	87.71	0.139
11.69	87.76	0.139
11.70	87.81	0.139
11.71	87.86	0.139
11.72	87.91	0.139
11.73	87.96	0.139
11.74	88.01	0.139
11.75	88.06	0.139
11.76	88.11	0.139
11.77	88.16	0.139
11.78	88.21	0.139
11.79	88.26	0.139
11.80	88.31	0.139
11.81	88.36	0.139
11.82	88.41	0.139
11.83	88.46	0.139
11.84	88.51	0.139
11.85	88.56	0.139
11.86	88.61	0.139
11.87	88.67	0.139
11.88	88.71	0.139
11.89	88.76	0.139
11.90	88.81	0.139
11.91	88.86	0.139
11.92	88.91	0.139
11.93	88.96	0.139
11.94	89.01	0.139
11.95	89.06	0.139
11.96	89.11	0.139
11.97	89.16	0.139
11.98	89.21	0.139
11.99	89.26	0.139
12.00	89.31	0.139
12.01	89.36	0.139
12.02	89.41	0.139
12.03	89.46	0.139
12.04	89.51	0.139
12.05	89.56	0.139
12.06	89.61	0.139
12.07	89.66	0.139
12.08	89.71	0.139
12.09	89.76	0.139
12.10	89.81	0.139
12.11	89.86	0.139
12.12	89.92	0.139
12.13	89.97	0.139
12.14	90.01	0.139
12.15	90.06	0.139
12.16	90.12	0.139
12.17	90.16	0.140
12.18	90.21	0.139
12.19	90.26	0.140
12.20	90.32	0.140
12.21	90.36	0.140
12.22	90.41	0.140
12.23	90.46	0.140
12.24	90.51	0.140
12.25	90.56	0.140
12.26	90.62	0.140
12.27	90.66	0.140
12.28	90.71	0.140
12.29	90.76	0.140
12.30	90.82	0.140
12.31	90.86	0.140
12.32	90.92	0.140
12.33	90.97	0.140
12.34	91.02	0.140
12.35	91.06	0.140
12.36	91.11	0.140
12.37	91.17	0.140
12.38	91.22	0.140
12.39	91.27	0.140
12.40	91.31	0.140
12.41	91.37	0.140
12.42	91.42	0.140
12.43	91.47	0.140
12.44	91.52	0.140
12.45	91.57	0.140
12.46	91.61	0.140
12.47	91.67	0.140
12.48	91.72	0.140
12.49	91.77	0.140
12.50	91.81	0.140
12.51	91.86	0.140
12.52	91.91	0.140
12.53	91.97	0.140
12.54	92.02	0.140
12.55	92.07	0.140
12.56	92.12	0.140
12.57	92.16	0.140
12.58	92.22	0.140
12.59	92.26	0.140
12.60	92.31	0.140
12.61	92.37	0.140
12.62	92.42	0.140
12.63	92.47	0.140
12.64	92.51	0.140
12.65	92.57	0.140
12.66	92.61	0.141
12.67	92.66	0.141
12.68	92.72	0.141
12.69	92.76	0.141
12.70	92.82	0.141
12.71	92.87	0.141
12.72	92.91	0.141
12.73	92.97	0.141
12.74	93.02	0.141
12.75	93.07	0.141
12.76	93.11	0.141
12.77	93.17	0.141
12.78	93.21	0.141
12.79	93.27	0.141
12.80	93.31	0.141
12.81	93.37	0.141
12.82	93.42	0.141
12.83	93.47	0.141
12.84	93.52	0.141
12.85	93.57	0.141
12.86	93.62	0.141
12.87	93.67	0.141
12.88	93.72	0.141
12.89	93.77	0.141
12.90	93.82	0.141
12.91	93.87	0.141
12.92	93.92	0.141
12.93	93.97	0.141
12.94	94.02	0.141
12.95	94.07	0.141
12.96	94.12	0.141
12.97	94.17	0.141
12.98	94.22	0.141
12.99	94.27	0.141
13.00	94.32	0.141
13.01	94.37	0.141
13.02	94.42	0.141
13.03	94.47	0.141
13.04	94.52	0.141
13.05	94.57	0.141
13.06	94.62	0.141
13.07	94.67	0.141
13.08	94.72	0.142
13.09	94.77	0.142
13.10	94.82	0.142
13.11	94.87	0.142
13.12	94.92	0.142
13.13	94.97	0.142
13.14	95.02	0.142
13.15	95.07	0.142
13.16	95.12	0.142
13.17	95.17	0.142
13.18	95.22	0.142
13.19	95.27	0.142
13.20	95.32	0.142
13.21	95.37	0.142
13.22	95.42	0.142
13.23	95.47	0.142
13.24	95.52	0.142
13.25	95.57	0.142
13.26	95.62	0.142
13.27	95.67	0.142
13.28	95.72	0.142
13.29	95.77	0.142
13.30	95.82	0.142
13.31	95.87	0.142
13.32	95.92	0.142
13.33	95.97	0.142
13.34	96.02	0.142
13.35	96.07	0.142
13.36	96.12	0.142
13.37	96.17	0.142
13.38	96.22	0.142
13.39	96.27	0.142
13.40	96.32	0.142
13.41	96.37	0.142
13.42	96.42	0.142
13.43	96.47	0.142
13.44	96.52	0.142
13.45	96.57	0.142
13.46	96.62	0.143
13.47	96.67	0.143
13.48	96.72	0.143
13.49	96.77	0.143
13.50	96.82	0.143
13.51	96.87	0.143
13.52	96.92	0.143
13.53	96.97	0.143
13.54	97.02	0.143
13.55	97.07	0.143
13.56	97.12	0.143
13.57	97.17	0.143
13.58	97.22	0.143
13.59	97.27	0.143
13.60	97.32	0.143
13.61	97.37	0.143
13.62	97.42	0.143
13.63	97.47	0.143
13.64	97.52	0.143
13.65	97.57	0.143
13.66	97.62	0.143
13.67	97.67	0.143
13.68	97.72	0.143
13.69	97.77	0.143
13.70	97.82	0.143
13.71	97.87	0.143
13.72	97.92	0.143
13.73	97.97	0.143
13.74	98.02	0.143
13.75	98.07	0.143
13.76	98.12	0.143
13.77	98.17	0.143
13.78	98.22	0.143
13.79	98.27	0.143
13.80	98.32	0.143
13.81	98.37	0.143
13.82	98.42	0.143
13.83	98.47	0.143
13.84	98.52	0.143
13.85	98.57	0.143
13.86	98.62	0.143
13.87	98.67	0.143
13.88	98.72	0.143
13.89	98.77	0.143
13.90	98.82	0.144
13.91	98.87	0.144
13.92	98.92	0.144
13.93	98.97	0.144
13.94	99.02	0.144
13.95	99.07
13.96	99.12
13.97	99.17
13.98	99.22
13.99	99.27
14.00
14.00