File: DSC/2025_04_20_CBG_n60C_100C_10Cmin_x3.csv
Filename,2025_04_20_CBG_n60C_100C_10Cmin_x3
Instrument name,DSC2A-00468 (192.168.1.100)
Operator,Yarger
rundate,4/20/2025
Sample name,2025_04_20_CBG_n60C_100C_10Cmin_x3
proceduresegments,Data Off ; Equilibrate -60.00 °C; Data On ; Ramp 10.00 °C/min to 100.00 °C; Data Off ; Isothermal 1.0 min; Data On ; Ramp 10.00 °C/min to -60.00 °C; Data Off ; Isothermal 1.0 min; Data On ; Ramp 10.00 °C/min to 100.00 °C; Data Off ; Isothermal 1.0 min; Data On ; Ramp 10.00 °C/min to -60.00 °C; Data Off ; Isothermal 1.0 min; Data On ; Ramp 10.00 °C/min to 100.00 °C
[File Parameters]
Run date,4/20/2025 10:44:44 PM
Trios version,5.1.1.46572
Original File Name,
Current File Name,D:\DSC2500\JYarger\2025_04_20_CBG_n60C_100C_10Cmin_x3.tri
[Procedure]
Procedure Name,CBG_n60_100C_10Cmin_x3
Sample Name,2025_04_20_CBG_n60C_100C_10Cmin_x3
Sample Mass,0.38 mg
Reference Sample Mass,0 mg
Pan Mass,25.95 mg
Pan Number,29
Reference Pan Mass,25.8 mg
Reference Pan Number,28
Pan Type,Tzero Aluminum
Comments,"Al Pan/Lid, Not sealed."
Project Name,CA
Operator,Yarger
Test,Custom
Unload Max Temperature,30
Unload Min Temperature,30
Load Max Temperature,30
Load Min Temperature,30
Stop on Gas Flow Error,Yes
[Signal List]
Signal #1,Time (min)
Signal #2,Temperature (°C)
Signal #3,Heat Flow (mW)
Signal #4,Delta T (µV)
Signal #5,Delta Tzero (µV)
Signal #6,Tzero Temperature (°C)
Signal #7,Cell Purge (mL/min)
Signal #8,Heater Temp (°C)
Signal #9,Power Delivered (W)
Signal #10,Reference Junction Temperature (°C)
Signal #11,Flange Temperature (°C)
Signal #12,Heat Flow Phase (rad)
Signal #13,Total Heat Capacity (J/°C)
Signal #14,Heat Capacity (J/°C)
[Configuration]
Company Name,ASU
Instrument Name,DSC2A-00468
Instrument Type,DSC2500
Serial Number,DSC2A-00468
IP,192.168.1.100
Location of Instrument,MRRC
DisplayType,Unknown
Sample Interval ,0.1 s/pt
Selected Heat Flow,T4P
Exotherm Direction,Down
Cell Serial,DRC2-00792
Lid Type,Standard
Cooler,RCS 90
Leave Cooler on at End of Sequence,On
Gas 2,Nitrogen
Gas Selected,Channel 1
Flow Rate,50 mL/min
Secondary Purge,On
Licensed Heat Flow,Heat Flow T4P
Modulation Licensed,Yes
[Versions]
Common IDD Version,1
Cortex Version,VER 2.10.2.31
Driver,5.0.0.6
GDM Version,1.0.3.3
TouchscreenVersion,1.0.0.16145
FEP Version,1.2.1.21
FEP Bootloader,2.0.0.5
AutoSampler Version,2.1.1.26
Auto Sampler Bootloader,2.0.0.5
FCM Version,1.1.0.3
FCM Bootloader,2.0.0.5
[Experiment Logs]
Experiment Log Entry # 1,Data On set to 0
Experiment Log Entry # 3,Equilibrate Segment -60 (C) Started
Experiment Log Entry # 5,Air Cool is off.
Experiment Log Entry # 7,Data On set to 1
Experiment Log Entry # 9,Ramp Segment 10 C/min to 100 Started
Experiment Log Entry # 11,Data On set to 0
Experiment Log Entry # 13,Isothermal Segment 1 min started
Experiment Log Entry # 15,Data On set to 1
Experiment Log Entry # 17,Ramp Segment 10 C/min to -60 Started
Experiment Log Entry # 19,Data On set to 0
Experiment Log Entry # 21,Isothermal Segment 1 min started
Experiment Log Entry # 23,Data On set to 1
Experiment Log Entry # 25,Ramp Segment 10 C/min to 100 Started
Experiment Log Entry # 27,Data On set to 0
Experiment Log Entry # 29,Isothermal Segment 1 min started
Experiment Log Entry # 31,Data On set to 1
Experiment Log Entry # 33,Ramp Segment 10 C/min to -60 Started
Experiment Log Entry # 35,Data On set to 0
Experiment Log Entry # 37,Isothermal Segment 1 min started
Experiment Log Entry # 39,Data On set to 1
Experiment Log Entry # 41,Ramp Segment 10 C/min to 100 Started
[Method Log]
Method Log Entry # 1,Data Off
Method Log Entry # 2,Equilibrate -60 °C
Method Log Entry # 3,Data On
Method Log Entry # 4,(Ramp 644553) Ramp 10 °C/minute to 100 °C
Method Log Entry # 5,Data Off
Method Log Entry # 6,Isothermal 1 minutes
Method Log Entry # 7,Data On
Method Log Entry # 8,(Ramp 644557) Ramp 10 °C/minute to -60 °C
Method Log Entry # 9,Data Off
Method Log Entry # 10,Isothermal 1 minutes
Method Log Entry # 11,Data On
Method Log Entry # 12,(Ramp 644561) Ramp 10 °C/minute to 100 °C
Method Log Entry # 13,Data Off
Method Log Entry # 14,Isothermal 1 minutes
Method Log Entry # 15,Data On
Method Log Entry # 16,(Ramp 644565) Ramp 10 °C/minute to -60 °C
Method Log Entry # 17,Data Off
Method Log Entry # 18,Isothermal 1 minutes
Method Log Entry # 19,Data On
Method Log Entry # 20,(Ramp 644569) Ramp 10 °C/minute to 100 °C
Cell Serial,DRC2-00792
[T1 Calibration]
Slope,-0.008529666
Offset,9.636258
Initial Temperature,98.23
GUID,f8bfdadc-4977-4fdf-ba6d-0ba9134940c3
[TZero Calibration]
Date Applied,11/29/2022 4:06:13 PM
Description,From -89.059 °C to 396.009 °C at 20.000°C/min
Gas Type,Nitrogen
Pan Type,None
Source Files 1,C:\Users\yargerlab\Desktop\DSC Data\General\TZero_calibration_11_29_22_2nd(2).tri
Source Files 2,C:\Users\yargerlab\Desktop\DSC Data\General\TZero_calibration_11_29_22_2nd(3).tri
Delta T Offset,13.05235
Delta T Slope,-0.007271007
Delta T0 Offset,-13.69128
Delta T0 Slope,0.06063341
[Temperature Calibration]
Date Applied,11/29/2022 7:12:28 PM
Description,From 106.590 °C to 186.590 °C at 10.000°C/min
Gas Type,Nitrogen
Pan Type,Tzero Aluminum Hermetic
Source Files 1,C:\Users\yargerlab\Desktop\DSC Data\General\Indium(6).tri
Measured 1,157.391
Known 1,156.598
[Cell Constant Calibration]
Date Applied,11/29/2022 7:12:29 PM
Description,From 106.590 °C to 186.590 °C at 10.000°C/min
Gas Type,Nitrogen
Pan Type,Tzero Aluminum Hermetic
Source Files 1,C:\Users\yargerlab\Desktop\DSC Data\General\Indium(6).tri
T4P KCell,1.006051
Onset Slope,63.26126 mW/°C
[Direct Cp Calibration]
Date Applied,11/30/2022 11:04:51 AM
Description,From -79.983 °C to 298.409 °C at 10.000°C/min
Gas Type,Nitrogen
Pan Type,Tzero Aluminum Hermetic
Source Files 1,C:\Users\yargerlab\Desktop\DSC Data\General\Sapphire_Heat_Capacity_11_30_22.tri
[Rev Cp Calibration]
Date Applied,11/30/2022 1:58:51 PM
Description,From -79.996 °C to 292.812 °C at 3.000°C/min
Gas Type,Nitrogen
Pan Type,Tzero Aluminum Hermetic
Source Files 1,C:\Users\yargerlab\Desktop\DSC Data\General\Sapphire_MDSC_Calibration_11_30_22.tri
[step]
Ramp 10.00 °C/min to 100.00 °C
Time,Temperature,Heat Flow (Normalized)
min,°C,W/g
0.00,-59.81,-0.316
0.01,-59.81,-0.313
0.02,-59.81,-0.309
0.03,-59.81,-0.303
0.05,-59.81,-0.294
0.06,-59.80,-0.281
0.07,-59.78,-0.270
0.08,-59.75,-0.253
0.09,-59.71,-0.234
0.11,-59.65,-0.214
0.12,-59.59,-0.178
0.13,-59.52,-0.134
0.14,-59.44,-0.093
0.15,-59.35,-0.029
0.16,-59.26,0.010
0.18,-59.16,0.049
0.19,-59.06,0.084
0.20,-58.95,0.112
0.21,-58.84,0.152
0.22,-58.73,0.168
0.23,-58.62,0.197
0.24,-58.51,0.214
0.26,-58.39,0.226
0.27,-58.28,0.233
0.28,-58.17,0.243
0.29,-58.06,0.253
0.30,-57.94,0.258
0.31,-57.83,0.263
0.33,-57.71,0.267
0.34,-57.60,0.269
0.35,-57.49,0.272
0.36,-57.37,0.277
0.37,-57.26,0.279
0.39,-57.14,0.281
0.40,-57.03,0.284
0.41,-56.92,0.287
0.42,-56.80,0.288
0.43,-56.69,0.291
0.44,-56.58,0.292
0.45,-56.46,0.295
0.47,-56.35,0.297
0.48,-56.23,0.299
0.49,-56.12,0.301
0.50,-56.00,0.303
0.51,-55.89,0.305
0.53,-55.77,0.307
0.54,-55.66,0.309
0.55,-55.54,0.311
0.56,-55.43,0.312
0.57,-55.31,0.314
0.58,-55.20,0.316
0.60,-55.09,0.318
0.61,-54.97,0.319
0.62,-54.86,0.321
0.63,-54.74,0.323
0.64,-54.63,0.324
0.65,-54.51,0.326
0.67,-54.40,0.328
0.68,-54.28,0.329
0.69,-54.16,0.331
0.70,-54.05,0.332
0.71,-53.94,0.333
0.72,-53.82,0.335
0.73,-53.70,0.336
0.75,-53.59,0.337
0.76,-53.47,0.338
0.77,-53.36,0.340
0.78,-53.24,0.341
0.79,-53.13,0.341
0.80,-53.01,0.342
0.82,-52.90,0.344
0.83,-52.78,0.344
0.84,-52.67,0.345
0.85,-52.55,0.346
0.86,-52.44,0.347
0.88,-52.32,0.348
0.89,-52.20,0.348
0.90,-52.09,0.349
0.91,-51.97,0.350
0.92,-51.86,0.350
0.93,-51.74,0.351
0.95,-51.63,0.351
0.96,-51.51,0.352
0.97,-51.39,0.353
0.98,-51.28,0.353
0.99,-51.16,0.353
1.00,-51.05,0.354
1.02,-50.93,0.354
1.03,-50.81,0.355
1.04,-50.70,0.355
1.05,-50.58,0.355
1.06,-50.46,0.356
1.07,-50.35,0.356
1.08,-50.23,0.356
1.10,-50.12,0.356
1.11,-50.00,0.357
1.12,-49.89,0.357
1.13,-49.77,0.358
1.14,-49.65,0.358
1.16,-49.54,0.358
1.17,-49.42,0.358
1.18,-49.30,0.359
1.19,-49.19,0.359
1.20,-49.07,0.358
1.21,-48.95,0.358
1.23,-48.84,0.359
1.24,-48.72,0.359
1.25,-48.61,0.359
1.26,-48.49,0.359
1.27,-48.37,0.359
1.28,-48.26,0.359
1.29,-48.14,0.359
1.31,-48.03,0.360
1.32,-47.91,0.359
1.33,-47.79,0.359
1.34,-47.68,0.359
1.35,-47.56,0.359
1.37,-47.44,0.359
1.38,-47.33,0.360
1.39,-47.21,0.359
1.40,-47.09,0.359
1.41,-46.98,0.359
1.42,-46.86,0.358
1.43,-46.74,0.359
1.45,-46.63,0.358
1.46,-46.51,0.359
1.47,-46.39,0.359
1.48,-46.28,0.358
1.49,-46.16,0.358
1.51,-46.04,0.358
1.52,-45.93,0.358
1.53,-45.81,0.358
1.54,-45.70,0.357
1.55,-45.58,0.357
1.56,-45.46,0.357
1.58,-45.35,0.357
1.59,-45.23,0.356
1.60,-45.11,0.357
1.61,-45.00,0.357
1.62,-44.88,0.356
1.63,-44.76,0.356
1.64,-44.65,0.356
1.66,-44.53,0.356
1.67,-44.41,0.355
1.68,-44.30,0.355
1.69,-44.18,0.354
1.70,-44.06,0.354
1.72,-43.94,0.354
1.73,-43.83,0.354
1.74,-43.71,0.354
1.75,-43.60,0.353
1.76,-43.48,0.353
1.77,-43.36,0.353
1.78,-43.25,0.352
1.80,-43.13,0.352
1.81,-43.01,0.352
1.82,-42.90,0.351
1.83,-42.78,0.351
1.84,-42.66,0.350
1.86,-42.55,0.350
1.87,-42.43,0.350
1.88,-42.31,0.350
1.89,-42.20,0.349
1.90,-42.08,0.349
1.91,-41.96,0.348
1.93,-41.85,0.348
1.94,-41.73,0.348
1.95,-41.61,0.347
1.96,-41.49,0.347
1.97,-41.38,0.347
1.98,-41.26,0.346
1.99,-41.15,0.345
2.01,-41.03,0.344
2.02,-40.91,0.344
2.03,-40.79,0.343
2.04,-40.68,0.343
2.05,-40.56,0.342
2.07,-40.44,0.341
2.08,-40.33,0.341
2.09,-40.21,0.340
2.10,-40.09,0.340
2.11,-39.98,0.339
2.12,-39.86,0.338
2.14,-39.74,0.338
2.15,-39.63,0.337
2.16,-39.51,0.336
2.17,-39.39,0.336
2.18,-39.28,0.335
2.19,-39.16,0.335
2.21,-39.04,0.334
2.22,-38.93,0.334
2.23,-38.81,0.333
2.24,-38.69,0.332
2.25,-38.58,0.332
2.26,-38.46,0.332
2.28,-38.34,0.331
2.29,-38.23,0.331
2.30,-38.11,0.330
2.31,-37.99,0.329
2.32,-37.88,0.328
2.33,-37.76,0.327
2.34,-37.64,0.327
2.36,-37.53,0.326
2.37,-37.41,0.326
2.38,-37.29,0.325
2.39,-37.17,0.325
2.40,-37.06,0.324
2.41,-36.94,0.324
2.43,-36.82,0.324
2.44,-36.71,0.323
2.45,-36.59,0.323
2.46,-36.47,0.322
2.47,-36.36,0.321
2.49,-36.24,0.321
2.50,-36.12,0.320
2.51,-36.01,0.319
2.52,-35.89,0.318
2.53,-35.77,0.317
2.54,-35.66,0.317
2.56,-35.54,0.316
2.57,-35.42,0.315
2.58,-35.31,0.314
2.59,-35.19,0.313
2.60,-35.07,0.313
2.61,-34.96,0.311
2.63,-34.84,0.311
2.64,-34.72,0.311
2.65,-34.60,0.310
2.66,-34.49,0.309
2.67,-34.37,0.308
2.68,-34.25,0.308
2.69,-34.14,0.307
2.71,-34.02,0.306
2.72,-33.90,0.306
2.73,-33.79,0.305
2.74,-33.67,0.304
2.75,-33.55,0.304
2.76,-33.44,0.303
2.78,-33.32,0.302
2.79,-33.20,0.302
2.80,-33.09,0.302
2.81,-32.97,0.301
2.82,-32.85,0.301
2.84,-32.74,0.299
2.85,-32.62,0.299
2.86,-32.50,0.298
2.87,-32.38,0.298
2.88,-32.27,0.297
2.89,-32.15,0.297
2.91,-32.04,0.296
2.92,-31.92,0.295
2.93,-31.80,0.295
2.94,-31.68,0.294
2.95,-31.57,0.293
2.96,-31.45,0.293
2.98,-31.33,0.292
2.99,-31.22,0.292
3.00,-31.10,0.291
3.01,-30.98,0.291
3.02,-30.87,0.290
3.03,-30.75,0.289
3.04,-30.63,0.288
3.06,-30.52,0.288
3.07,-30.40,0.288
3.08,-30.28,0.287
3.09,-30.16,0.287
3.10,-30.05,0.286
3.11,-29.93,0.285
3.13,-29.81,0.285
3.14,-29.70,0.284
3.15,-29.58,0.283
3.16,-29.46,0.283
3.17,-29.35,0.281
3.19,-29.23,0.281
3.20,-29.11,0.281
3.21,-29.00,0.280
3.22,-28.88,0.280
3.23,-28.76,0.280
3.24,-28.65,0.279
3.26,-28.53,0.279
3.27,-28.41,0.278
3.28,-28.30,0.277
3.29,-28.18,0.277
3.30,-28.06,0.276
3.31,-27.95,0.276
3.33,-27.83,0.276
3.34,-27.71,0.275
3.35,-27.60,0.275
3.36,-27.48,0.274
3.37,-27.36,0.274
3.38,-27.25,0.273
3.39,-27.13,0.273
3.41,-27.01,0.272
3.42,-26.89,0.272
3.43,-26.78,0.272
3.44,-26.66,0.271
3.45,-26.54,0.270
3.46,-26.43,0.270
3.48,-26.31,0.269
3.49,-26.19,0.269
3.50,-26.08,0.269
3.51,-25.96,0.268
3.52,-25.84,0.268
3.54,-25.73,0.267
3.55,-25.61,0.267
3.56,-25.49,0.267
3.57,-25.38,0.266
3.58,-25.26,0.266
3.59,-25.14,0.265
3.61,-25.02,0.265
3.62,-24.91,0.264
3.63,-24.79,0.264
3.64,-24.67,0.264
3.65,-24.56,0.263
3.66,-24.44,0.262
3.68,-24.32,0.262
3.69,-24.21,0.261
3.70,-24.09,0.261
3.71,-23.97,0.261
3.72,-23.86,0.260
3.73,-23.74,0.260
3.74,-23.62,0.259
3.76,-23.51,0.260
3.77,-23.39,0.259
3.78,-23.27,0.259
3.79,-23.16,0.258
3.80,-23.04,0.257
3.81,-22.92,0.257
3.83,-22.81,0.257
3.84,-22.69,0.256
3.85,-22.57,0.256
3.86,-22.46,0.255
3.87,-22.34,0.254
3.89,-22.22,0.254
3.90,-22.10,0.253
3.91,-21.99,0.252
3.92,-21.87,0.252
3.93,-21.76,0.251
3.94,-21.64,0.251
3.96,-21.52,0.250
3.97,-21.40,0.250
3.98,-21.29,0.250
3.99,-21.17,0.249
4.00,-21.05,0.248
4.01,-20.94,0.248
4.03,-20.82,0.248
4.04,-20.70,0.247
4.05,-20.59,0.247
4.06,-20.47,0.246
4.07,-20.35,0.245
4.08,-20.24,0.245
4.09,-20.12,0.245
4.11,-20.00,0.244
4.12,-19.89,0.244
4.13,-19.77,0.244
4.14,-19.65,0.243
4.15,-19.54,0.243
4.16,-19.42,0.242
4.18,-19.30,0.242
4.19,-19.18,0.242
4.20,-19.07,0.241
4.21,-18.95,0.241
4.22,-18.83,0.240
4.24,-18.72,0.240
4.25,-18.60,0.240
4.26,-18.48,0.239
4.27,-18.37,0.239
4.28,-18.25,0.239
4.29,-18.13,0.238
4.30,-18.02,0.238
4.32,-17.90,0.237
4.33,-17.78,0.237
4.34,-17.67,0.236
4.35,-17.55,0.236
4.36,-17.43,0.236
4.38,-17.32,0.235
4.39,-17.20,0.234
4.40,-17.08,0.234
4.41,-16.97,0.234
4.42,-16.85,0.234
4.43,-16.73,0.233
4.45,-16.61,0.233
4.46,-16.50,0.232
4.47,-16.38,0.232
4.48,-16.26,0.231
4.49,-16.15,0.231
4.50,-16.03,0.231
4.51,-15.91,0.230
4.53,-15.80,0.230
4.54,-15.68,0.230
4.55,-15.56,0.229
4.56,-15.45,0.228
4.57,-15.33,0.228
4.59,-15.21,0.228
4.60,-15.10,0.228
4.61,-14.98,0.227
4.62,-14.86,0.227
4.63,-14.75,0.227
4.64,-14.63,0.226
4.65,-14.51,0.226
4.67,-14.40,0.226
4.68,-14.28,0.225
4.69,-14.16,0.225
4.70,-14.05,0.225
4.71,-13.93,0.224
4.73,-13.81,0.224
4.74,-13.70,0.224
4.75,-13.58,0.224
4.76,-13.46,0.223
4.77,-13.35,0.223
4.78,-13.23,0.222
4.80,-13.11,0.222
4.81,-12.99,0.222
4.82,-12.88,0.221
4.83,-12.76,0.221
4.84,-12.64,0.221
4.85,-12.53,0.220
4.86,-12.41,0.220
4.88,-12.29,0.220
4.89,-12.18,0.219
4.90,-12.06,0.219
4.91,-11.94,0.219
4.92,-11.83,0.218
4.94,-11.71,0.218
4.95,-11.59,0.218
4.96,-11.48,0.217
4.97,-11.36,0.217
4.98,-11.24,0.216
4.99,-11.13,0.216
5.00,-11.01,0.216
5.02,-10.89,0.216
5.03,-10.78,0.215
5.04,-10.66,0.215
5.05,-10.54,0.215
5.06,-10.43,0.214
5.08,-10.31,0.214
5.09,-10.19,0.214
5.10,-10.07,0.213
5.11,-9.96,0.213
5.12,-9.84,0.213
5.13,-9.72,0.212
5.15,-9.61,0.212
5.16,-9.49,0.211
5.17,-9.37,0.212
5.18,-9.26,0.211
5.19,-9.14,0.210
5.20,-9.02,0.210
5.21,-8.91,0.210
5.23,-8.79,0.210
5.24,-8.67,0.209
5.25,-8.56,0.209
5.26,-8.44,0.209
5.27,-8.32,0.209
5.29,-8.21,0.209
5.30,-8.09,0.208
5.31,-7.97,0.208
5.32,-7.86,0.208
5.33,-7.74,0.207
5.34,-7.62,0.207
5.35,-7.51,0.206
5.37,-7.39,0.206
5.38,-7.27,0.206
5.39,-7.16,0.206
5.40,-7.04,0.205
5.41,-6.92,0.205
5.43,-6.80,0.205
5.44,-6.69,0.204
5.45,-6.57,0.204
5.46,-6.45,0.204
5.47,-6.34,0.203
5.48,-6.22,0.203
5.50,-6.10,0.203
5.51,-5.99,0.203
5.52,-5.87,0.202
5.53,-5.75,0.202
5.54,-5.64,0.202
5.55,-5.52,0.201
5.56,-5.40,0.201
5.58,-5.29,0.201
5.59,-5.17,0.201
5.60,-5.05,0.200
5.61,-4.94,0.200
5.62,-4.82,0.200
5.64,-4.70,0.200
5.65,-4.59,0.200
5.66,-4.47,0.199
5.67,-4.35,0.198
5.68,-4.24,0.199
5.69,-4.12,0.198
5.70,-4.00,0.197
5.72,-3.89,0.197
5.73,-3.77,0.197
5.74,-3.65,0.197
5.75,-3.53,0.196
5.76,-3.42,0.196
5.78,-3.30,0.196
5.79,-3.18,0.195
5.80,-3.07,0.195
5.81,-2.95,0.194
5.82,-2.83,0.195
5.83,-2.72,0.194
5.85,-2.60,0.193
5.86,-2.48,0.193
5.87,-2.36,0.193
5.88,-2.25,0.193
5.89,-2.13,0.192
5.90,-2.01,0.192
5.91,-1.90,0.192
5.93,-1.78,0.192
5.94,-1.66,0.191
5.95,-1.55,0.191
5.96,-1.43,0.190
5.97,-1.31,0.190
5.99,-1.20,0.190
6.00,-1.08,0.189
6.01,-0.96,0.189
6.02,-0.85,0.189
6.03,-0.73,0.188
6.04,-0.61,0.188
6.05,-0.50,0.188
6.07,-0.38,0.188
6.08,-0.26,0.187
6.09,-0.15,0.187
6.10,-0.03,0.187
6.11,0.09,0.187
6.13,0.20,0.186
6.14,0.32,0.186
6.15,0.44,0.186
6.16,0.55,0.186
6.17,0.67,0.186
6.18,0.79,0.186
6.20,0.90,0.185
6.21,1.02,0.184
6.22,1.14,0.184
6.23,1.26,0.184
6.24,1.37,0.184
6.25,1.49,0.183
6.26,1.61,0.183
6.28,1.72,0.183
6.29,1.84,0.183
6.30,1.96,0.183
6.31,2.07,0.183
6.32,2.19,0.183
6.34,2.31,0.183
6.35,2.42,0.182
6.36,2.54,0.182
6.37,2.66,0.182
6.38,2.77,0.181
6.39,2.89,0.181
6.40,3.01,0.182
6.42,3.12,0.181
6.43,3.24,0.182
6.44,3.36,0.181
6.45,3.47,0.181
6.46,3.59,0.181
6.48,3.71,0.180
6.49,3.82,0.180
6.50,3.94,0.180
6.51,4.06,0.180
6.52,4.17,0.180
6.53,4.29,0.180
6.55,4.41,0.180
6.56,4.53,0.180
6.57,4.64,0.180
6.58,4.76,0.179
6.59,4.88,0.179
6.60,4.99,0.179
6.61,5.11,0.179
6.63,5.23,0.179
6.64,5.34,0.179
6.65,5.46,0.179
6.66,5.58,0.178
6.67,5.69,0.178
6.69,5.81,0.178
6.70,5.93,0.178
6.71,6.04,0.178
6.72,6.16,0.178
6.73,6.28,0.178
6.74,6.39,0.178
6.75,6.51,0.177
6.77,6.63,0.177
6.78,6.74,0.177
6.79,6.86,0.177
6.80,6.98,0.176
6.81,7.09,0.176
6.83,7.21,0.176
6.84,7.33,0.176
6.85,7.45,0.175
6.86,7.56,0.175
6.87,7.68,0.175
6.88,7.80,0.174
6.90,7.91,0.174
6.91,8.03,0.175
6.92,8.15,0.174
6.93,8.26,0.174
6.94,8.38,0.173
6.95,8.50,0.173
6.96,8.61,0.173
6.98,8.73,0.172
6.99,8.85,0.172
7.00,8.96,0.172
7.01,9.08,0.171
7.02,9.20,0.171
7.04,9.32,0.171
7.05,9.43,0.171
7.06,9.55,0.170
7.07,9.66,0.170
7.08,9.78,0.170
7.09,9.90,0.170
7.10,10.02,0.170
7.12,10.13,0.169
7.13,10.25,0.169
7.14,10.37,0.169
7.15,10.48,0.169
7.16,10.60,0.168
7.18,10.72,0.168
7.19,10.83,0.168
7.20,10.95,0.168
7.21,11.07,0.167
7.22,11.18,0.167
7.23,11.30,0.167
7.25,11.42,0.167
7.26,11.53,0.167
7.27,11.65,0.166
7.28,11.77,0.166
7.29,11.88,0.166
7.30,12.00,0.166
7.31,12.12,0.165
7.33,12.23,0.165
7.34,12.35,0.165
7.35,12.47,0.164
7.36,12.58,0.164
7.37,12.70,0.164
7.39,12.82,0.164
7.40,12.94,0.164
7.41,13.05,0.164
7.42,13.17,0.163
7.43,13.28,0.163
7.44,13.40,0.163
7.45,13.52,0.163
7.47,13.63,0.163
7.48,13.75,0.162
7.49,13.87,0.162
7.50,13.99,0.162
7.51,14.10,0.162
7.53,14.22,0.162
7.54,14.34,0.162
7.55,14.45,0.162
7.56,14.57,0.162
7.57,14.69,0.162
7.58,14.80,0.161
7.60,14.92,0.161
7.61,15.04,0.161
7.62,15.15,0.161
7.63,15.27,0.161
7.64,15.39,0.161
7.65,15.50,0.161
7.66,15.62,0.161
7.68,15.74,0.161
7.69,15.85,0.161
7.70,15.97,0.161
7.71,16.09,0.161
7.72,16.20,0.161
7.74,16.32,0.160
7.75,16.44,0.160
7.76,16.55,0.160
7.77,16.67,0.160
7.78,16.79,0.160
7.79,16.90,0.160
7.80,17.02,0.160
7.82,17.14,0.160
7.83,17.26,0.159
7.84,17.37,0.159
7.85,17.49,0.159
7.86,17.61,0.158
7.88,17.72,0.158
7.89,17.84,0.158
7.90,17.96,0.158
7.91,18.07,0.158
7.92,18.19,0.158
7.93,18.31,0.157
7.95,18.42,0.158
7.96,18.54,0.157
7.97,18.66,0.157
7.98,18.77,0.156
7.99,18.89,0.156
8.00,19.01,0.156
8.01,19.12,0.156
8.03,19.24,0.156
8.04,19.36,0.156
8.05,19.47,0.155
8.06,19.59,0.155
8.07,19.71,0.155
8.09,19.82,0.155
8.10,19.94,0.155
8.11,20.06,0.155
8.12,20.17,0.154
8.13,20.29,0.154
8.14,20.41,0.154
8.15,20.52,0.154
8.17,20.64,0.154
8.18,20.76,0.154
8.19,20.87,0.154
8.20,20.99,0.154
8.21,21.11,0.154
8.23,21.23,0.154
8.24,21.34,0.155
8.25,21.46,0.154
8.26,21.58,0.155
8.27,21.69,0.155
8.28,21.81,0.155
8.30,21.92,0.155
8.31,22.04,0.155
8.32,22.16,0.155
8.33,22.28,0.155
8.34,22.39,0.155
8.35,22.51,0.155
8.36,22.63,0.156
8.38,22.74,0.156
8.39,22.86,0.156
8.40,22.98,0.156
8.41,23.09,0.156
8.42,23.21,0.157
8.44,23.33,0.156
8.45,23.45,0.157
8.46,23.56,0.157
8.47,23.68,0.157
8.48,23.80,0.157
8.49,23.91,0.157
8.50,24.03,0.157
8.52,24.15,0.157
8.53,24.26,0.157
8.54,24.38,0.157
8.55,24.50,0.157
8.56,24.61,0.157
8.58,24.73,0.157
8.59,24.85,0.157
8.60,24.96,0.157
8.61,25.08,0.158
8.62,25.20,0.157
8.63,25.31,0.157
8.65,25.43,0.157
8.66,25.55,0.158
8.67,25.66,0.158
8.68,25.78,0.157
8.69,25.90,0.157
8.70,26.01,0.157
8.72,26.13,0.157
8.73,26.25,0.158
8.74,26.37,0.158
8.75,26.48,0.157
8.76,26.60,0.158
8.77,26.72,0.157
8.78,26.83,0.157
8.80,26.95,0.157
8.81,27.07,0.157
8.82,27.18,0.157
8.83,27.30,0.157
8.84,27.42,0.157
8.85,27.53,0.157
8.87,27.65,0.157
8.88,27.77,0.157
8.89,27.88,0.157
8.90,28.00,0.157
8.91,28.11,0.158
8.93,28.23,0.157
8.94,28.35,0.158
8.95,28.47,0.157
8.96,28.58,0.157
8.97,28.70,0.157
8.98,28.82,0.157
9.00,28.93,0.157
9.01,29.05,0.157
9.02,29.17,0.157
9.03,29.28,0.158
9.04,29.40,0.158
9.05,29.52,0.158
9.07,29.64,0.158
9.08,29.75,0.158
9.09,29.87,0.159
9.10,29.98,0.158
9.11,30.10,0.159
9.12,30.22,0.159
9.13,30.33,0.159
9.15,30.45,0.159
9.16,30.57,0.159
9.17,30.68,0.160
9.18,30.80,0.160
9.19,30.92,0.160
9.20,31.03,0.160
9.22,31.15,0.160
9.23,31.27,0.161
9.24,31.38,0.161
9.25,31.50,0.161
9.26,31.62,0.162
9.28,31.73,0.162
9.29,31.85,0.162
9.30,31.97,0.162
9.31,32.09,0.162
9.32,32.20,0.163
9.33,32.32,0.163
9.35,32.44,0.164
9.36,32.55,0.164
9.37,32.67,0.164
9.38,32.79,0.165
9.39,32.90,0.165
9.40,33.02,0.165
9.42,33.13,0.166
9.43,33.25,0.166
9.44,33.37,0.167
9.45,33.49,0.167
9.46,33.60,0.167
9.47,33.72,0.167
9.48,33.84,0.168
9.50,33.95,0.168
9.51,34.07,0.168
9.52,34.19,0.168
9.53,34.30,0.169
9.54,34.42,0.169
9.55,34.54,0.170
9.57,34.65,0.170
9.58,34.77,0.170
9.59,34.89,0.171
9.60,35.01,0.171
9.61,35.12,0.171
9.63,35.24,0.171
9.64,35.36,0.171
9.65,35.47,0.172
9.66,35.59,0.172
9.67,35.71,0.172
9.68,35.82,0.173
9.70,35.94,0.174
9.71,36.06,0.174
9.72,36.17,0.173
9.73,36.29,0.172
9.74,36.41,0.172
9.75,36.52,0.171
9.77,36.64,0.171
9.78,36.76,0.171
9.79,36.87,0.170
9.80,36.99,0.169
9.81,37.11,0.175
9.82,37.22,0.377
9.83,37.34,0.395
9.85,37.45,0.365
9.86,37.57,0.359
9.87,37.69,0.330
9.88,37.81,0.309
9.89,37.92,0.302
9.90,38.04,0.293
9.92,38.16,0.289
9.93,38.27,0.285
9.94,38.39,0.281
9.95,38.51,0.277
9.96,38.63,0.273
9.98,38.74,0.270
9.99,38.86,0.267
10.00,38.98,0.264
10.01,39.09,0.261
10.02,39.21,0.258
10.03,39.32,0.256
10.05,39.44,0.254
10.06,39.56,0.252
10.07,39.67,0.250
10.08,39.79,0.249
10.09,39.91,0.248
10.10,40.02,0.246
10.12,40.14,0.245
10.13,40.26,0.244
10.14,40.38,0.243
10.15,40.49,0.242
10.16,40.61,0.242
10.17,40.73,0.241
10.18,40.84,0.241
10.20,40.96,0.240
10.21,41.07,0.241
10.22,41.19,0.241
10.23,41.31,0.240
10.24,41.43,0.240
10.25,41.54,0.240
10.27,41.66,0.241
10.28,41.78,0.242
10.29,41.89,0.242
10.30,42.01,0.243
10.31,42.13,0.244
10.33,42.24,0.245
10.34,42.36,0.245
10.35,42.48,0.247
10.36,42.59,0.248
10.37,42.71,0.249
10.38,42.83,0.251
10.40,42.94,0.252
10.41,43.06,0.253
10.42,43.18,0.254
10.43,43.29,0.257
10.44,43.41,0.259
10.45,43.53,0.261
10.47,43.64,0.263
10.48,43.76,0.265
10.49,43.88,0.267
10.50,43.99,0.270
10.51,44.11,0.273
10.52,44.23,0.275
10.53,44.34,0.279
10.55,44.46,0.282
10.56,44.58,0.286
10.57,44.69,0.289
10.58,44.81,0.292
10.59,44.93,0.296
10.60,45.04,0.300
10.62,45.16,0.304
10.63,45.28,0.308
10.64,45.39,0.312
10.65,45.51,0.320
10.66,45.63,0.330
10.68,45.74,0.337
10.69,45.86,0.348
10.70,45.98,0.355
10.71,46.09,0.365
10.72,46.21,0.384
10.73,46.33,0.395
10.75,46.44,0.409
10.76,46.56,0.437
10.77,46.67,0.464
10.78,46.79,0.478
10.79,46.91,0.503
10.80,47.02,0.535
10.82,47.14,0.565
10.83,47.26,0.593
10.84,47.37,0.626
10.85,47.49,0.660
10.86,47.60,0.695
10.87,47.72,0.734
10.88,47.84,0.785
10.90,47.95,0.828
10.91,48.07,0.884
10.92,48.18,0.934
10.93,48.30,0.994
10.94,48.42,1.051
10.95,48.53,1.127
10.97,48.65,1.208
10.98,48.76,1.277
10.99,48.88,1.374
11.00,48.99,1.475
11.01,49.11,1.578
11.03,49.22,1.702
11.04,49.33,1.824
11.05,49.45,1.945
11.06,49.56,2.090
11.07,49.68,2.227
11.08,49.79,2.383
11.10,49.90,2.515
11.11,50.02,2.650
11.12,50.13,2.747
11.13,50.24,2.826
11.14,50.36,2.832
11.15,50.47,2.809
11.17,50.59,2.739
11.18,50.71,2.701
11.19,50.82,2.678
11.20,50.94,2.695
11.21,51.06,3.003
11.22,51.17,3.344
11.23,51.28,3.781
11.25,51.39,4.309
11.26,51.50,4.878
11.27,51.60,5.472
11.28,51.71,6.069
11.29,51.81,6.605
11.30,51.92,7.029
11.32,52.02,7.307
11.33,52.13,7.363
11.34,52.24,7.077
11.35,52.36,6.378
11.36,52.48,5.264
11.38,52.61,3.962
11.39,52.75,2.784
11.40,52.88,1.998
11.41,53.02,1.538
11.42,53.15,1.258
11.43,53.28,1.049
11.45,53.41,0.890
11.46,53.54,0.765
11.47,53.66,0.672
11.48,53.78,0.590
11.49,53.90,0.538
11.50,54.02,0.477
11.52,54.14,0.423
11.53,54.26,0.395
11.54,54.38,0.372
11.55,54.50,0.346
11.56,54.62,0.318
11.57,54.74,0.307
11.58,54.85,0.298
11.60,54.97,0.291
11.61,55.09,0.283
11.62,55.21,0.273
11.63,55.32,0.271
11.64,55.44,0.267
11.65,55.56,0.265
11.67,55.67,0.262
11.68,55.79,0.258
11.69,55.91,0.254
11.70,56.02,0.252
11.71,56.14,0.250
11.73,56.26,0.249
11.74,56.38,0.248
11.75,56.49,0.247
11.76,56.61,0.246
11.77,56.72,0.245
11.78,56.84,0.245
11.80,56.96,0.244
11.81,57.07,0.243
11.82,57.19,0.242
11.83,57.31,0.242
11.84,57.42,0.241
11.85,57.54,0.240
11.87,57.66,0.240
11.88,57.77,0.239
11.89,57.89,0.238
11.90,58.01,0.238
11.91,58.13,0.237
11.92,58.24,0.237
11.93,58.36,0.237
11.95,58.48,0.237
11.96,58.59,0.236
11.97,58.71,0.236
11.98,58.83,0.235
11.99,58.94,0.235
12.00,59.06,0.235
12.02,59.18,0.235
12.03,59.29,0.234
12.04,59.41,0.234
12.05,59.53,0.234
12.06,59.64,0.234
12.08,59.76,0.233
12.09,59.88,0.233
12.10,59.99,0.233
12.11,60.11,0.233
12.12,60.23,0.233
12.13,60.34,0.233
12.15,60.46,0.233
12.16,60.58,0.233
12.17,60.69,0.233
12.18,60.81,0.232
12.19,60.93,0.233
12.20,61.05,0.232
12.22,61.16,0.232
12.23,61.28,0.232
12.24,61.40,0.233
12.25,61.51,0.232
12.26,61.63,0.232
12.27,61.75,0.232
12.28,61.86,0.232
12.30,61.98,0.232
12.31,62.10,0.232
12.32,62.21,0.231
12.33,62.33,0.231
12.34,62.45,0.231
12.35,62.56,0.231
12.37,62.68,0.231
12.38,62.80,0.231
12.39,62.91,0.231
12.40,63.03,0.231
12.41,63.15,0.231
12.43,63.26,0.231
12.44,63.38,0.231
12.45,63.50,0.232
12.46,63.61,0.232
12.47,63.73,0.232
12.48,63.85,0.231
12.50,63.96,0.231
12.51,64.08,0.231
12.52,64.20,0.231
12.53,64.32,0.231
12.54,64.43,0.231
12.55,64.55,0.231
12.57,64.66,0.231
12.58,64.78,0.231
12.59,64.90,0.231
12.60,65.01,0.231
12.61,65.13,0.231
12.62,65.25,0.231
12.63,65.37,0.231
12.65,65.48,0.230
12.66,65.60,0.231
12.67,65.72,0.231
12.68,65.83,0.231
12.69,65.95,0.231
12.70,66.07,0.230
12.72,66.18,0.231
12.73,66.30,0.231
12.74,66.41,0.231
12.75,66.53,0.231
12.76,66.65,0.231
12.78,66.76,0.231
12.79,66.88,0.231
12.80,67.00,0.231
12.81,67.12,0.231
12.82,67.23,0.231
12.83,67.35,0.231
12.85,67.47,0.231
12.86,67.58,0.231
12.87,67.70,0.230
12.88,67.82,0.230
12.89,67.93,0.230
12.90,68.05,0.230
12.92,68.17,0.230
12.93,68.28,0.230
12.94,68.40,0.230
12.95,68.52,0.230
12.96,68.63,0.230
12.97,68.75,0.230
12.98,68.87,0.230
13.00,68.98,0.230
13.01,69.10,0.230
13.02,69.22,0.230
13.03,69.34,0.230
13.04,69.45,0.230
13.05,69.57,0.230
13.07,69.69,0.230
13.08,69.80,0.230
13.09,69.92,0.230
13.10,70.04,0.230
13.11,70.15,0.230
13.13,70.27,0.230
13.14,70.39,0.230
13.15,70.50,0.230
13.16,70.62,0.231
13.17,70.74,0.231
13.18,70.85,0.231
13.20,70.97,0.231
13.21,71.09,0.231
13.22,71.20,0.231
13.23,71.32,0.231
13.24,71.44,0.231
13.25,71.55,0.231
13.27,71.67,0.230
13.28,71.79,0.230
13.29,71.90,0.230
13.30,72.02,0.230
13.31,72.14,0.230
13.32,72.25,0.230
13.33,72.37,0.230
13.35,72.49,0.230
13.36,72.60,0.230
13.37,72.72,0.230
13.38,72.84,0.230
13.39,72.95,0.231
13.40,73.07,0.230
13.42,73.19,0.231
13.43,73.31,0.230
13.44,73.42,0.231
13.45,73.54,0.230
13.46,73.66,0.230
13.48,73.77,0.231
13.49,73.89,0.231
13.50,74.01,0.231
13.51,74.12,0.231
13.52,74.24,0.231
13.53,74.36,0.231
13.55,74.47,0.231
13.56,74.59,0.231
13.57,74.71,0.232
13.58,74.82,0.232
13.59,74.94,0.232
13.60,75.06,0.232
13.62,75.17,0.232
13.63,75.29,0.232
13.64,75.41,0.233
13.65,75.52,0.233
13.66,75.64,0.233
13.67,75.76,0.233
13.68,75.87,0.233
13.70,75.99,0.233
13.71,76.11,0.233
13.72,76.23,0.234
13.73,76.34,0.234
13.74,76.46,0.234
13.75,76.57,0.233
13.77,76.69,0.233
13.78,76.81,0.233
13.79,76.92,0.233
13.80,77.04,0.233
13.81,77.16,0.233
13.83,77.27,0.233
13.84,77.39,0.233
13.85,77.51,0.233
13.86,77.63,0.233
13.87,77.74,0.233
13.88,77.86,0.233
13.90,77.98,0.235
13.91,78.09,0.238
13.92,78.21,0.238
13.93,78.33,0.238
13.94,78.44,0.239
13.95,78.56,0.239
13.97,78.68,0.239
13.98,78.79,0.239
13.99,78.91,0.239
14.00,79.03,0.238
14.01,79.14,0.238
14.02,79.26,0.238
14.03,79.38,0.238
14.05,79.50,0.238
14.06,79.61,0.238
14.07,79.73,0.238
14.08,79.84,0.238
14.09,79.96,0.238
14.10,80.08,0.238
14.12,80.20,0.237
14.13,80.31,0.237
14.14,80.43,0.237
14.15,80.55,0.237
14.16,80.66,0.236
14.18,80.78,0.236
14.19,80.90,0.236
14.20,81.01,0.236
14.21,81.13,0.236
14.22,81.25,0.236
14.23,81.36,0.235
14.25,81.48,0.235
14.26,81.60,0.235
14.27,81.71,0.235
14.28,81.83,0.235
14.29,81.95,0.235
14.30,82.06,0.235
14.32,82.18,0.235
14.33,82.29,0.235
14.34,82.41,0.235
14.35,82.53,0.235
14.36,82.64,0.235
14.37,82.76,0.235
14.38,82.88,0.235
14.40,83.00,0.235
14.41,83.11,0.234
14.42,83.23,0.234
14.43,83.35,0.234
14.44,83.46,0.234
14.45,83.58,0.234
14.47,83.70,0.233
14.48,83.81,0.234
14.49,83.93,0.234
14.50,84.05,0.233
14.51,84.16,0.233
14.53,84.28,0.233
14.54,84.40,0.233
14.55,84.51,0.233
14.56,84.63,0.233
14.57,84.75,0.232
14.58,84.86,0.232
14.60,84.98,0.232
14.61,85.10,0.233
14.62,85.22,0.233
14.63,85.33,0.233
14.64,85.45,0.233
14.65,85.57,0.233
14.67,85.68,0.233
14.68,85.80,0.233
14.69,85.92,0.233
14.70,86.03,0.233
14.71,86.15,0.233
14.72,86.27,0.233
14.73,86.38,0.232
14.75,86.50,0.232
14.76,86.62,0.233
14.77,86.73,0.233
14.78,86.85,0.233
14.79,86.97,0.233
14.80,87.08,0.232
14.82,87.20,0.232
14.83,87.32,0.232
14.84,87.43,0.233
14.85,87.55,0.233
14.86,87.67,0.233
14.88,87.78,0.233
14.89,87.90,0.233
14.90,88.02,0.233
14.91,88.14,0.234
14.92,88.25,0.234
14.93,88.37,0.234
14.95,88.49,0.234
14.96,88.60,0.234
14.97,88.72,0.234
14.98,88.84,0.234
14.99,88.95,0.234
15.00,89.07,0.234
15.02,89.19,0.234
15.03,89.30,0.235
15.04,89.42,0.235
15.05,89.54,0.235
15.06,89.65,0.236
15.07,89.77,0.236
15.08,89.89,0.236
15.10,90.01,0.235
15.11,90.12,0.235
15.12,90.24,0.235
15.13,90.36,0.235
15.14,90.47,0.235
15.15,90.59,0.236
15.17,90.71,0.236
15.18,90.82,0.236
15.19,90.94,0.236
15.20,91.06,0.235
15.21,91.17,0.235
15.23,91.29,0.235
15.24,91.41,0.234
15.25,91.52,0.234
15.26,91.64,0.234
15.27,91.76,0.234
15.28,91.87,0.233
15.30,91.99,0.233
15.31,92.11,0.232
15.32,92.22,0.232
15.33,92.34,0.232
15.34,92.46,0.232
15.35,92.57,0.231
15.37,92.69,0.231
15.38,92.81,0.231
15.39,92.92,0.231
15.40,93.04,0.230
15.41,93.16,0.229
15.42,93.27,0.229
15.43,93.39,0.229
15.45,93.51,0.229
15.46,93.62,0.229
15.47,93.74,0.229
15.48,93.86,0.228
15.49,93.97,0.228
15.50,94.09,0.228
15.52,94.21,0.228
15.53,94.32,0.228
15.54,94.44,0.228
15.55,94.56,0.227
15.56,94.68,0.227
15.58,94.79,0.228
15.59,94.91,0.228
15.60,95.03,0.228
15.61,95.14,0.228
15.62,95.26,0.228
15.63,95.38,0.228
15.65,95.49,0.228
15.66,95.61,0.228
15.67,95.73,0.228
15.68,95.84,0.228
15.69,95.96,0.228
15.70,96.07,0.228
15.72,96.19,0.228
15.73,96.31,0.228
15.74,96.43,0.228
15.75,96.54,0.228
15.76,96.66,0.228
15.77,96.78,0.228
15.78,96.89,0.228
15.80,97.01,0.228
15.81,97.13,0.229
15.82,97.24,0.229
15.83,97.36,0.229
15.84,97.48,0.229
15.85,97.59,0.230
15.87,97.71,0.230
15.88,97.83,0.230
15.89,97.95,0.230
15.90,98.06,0.230
15.91,98.18,0.230
15.93,98.30,0.230
15.94,98.41,
15.95,98.53,
15.96,98.64,
15.97,98.76,
15.98,98.88,
15.99,,

[step]
Ramp 10.00 °C/min to -60.00 °C
Time,Temperature,Heat Flow (Normalized)
min,°C,W/g
16.99,100.12,-0.406
17.00,100.12,-0.407
17.02,100.12,-0.408
17.03,100.12,-0.409
17.04,100.11,-0.411
17.05,100.10,-0.412
17.06,100.07,-0.413
17.08,100.04,-0.414
17.09,99.99,-0.414
17.10,99.93,-0.416
17.11,99.85,-0.427
17.12,99.77,-0.476
17.13,99.68,-0.556
17.14,99.58,-0.641
17.16,99.48,-0.716
17.17,99.38,-0.758
17.18,99.27,-0.803
17.19,99.16,-0.838
17.20,99.06,-0.875
17.22,98.95,-0.883
17.23,98.84,-0.892
17.24,98.73,-0.913
17.25,98.62,-0.920
17.26,98.50,-0.930
17.27,98.39,-0.932
17.28,98.27,-0.937
17.30,98.16,-0.940
17.31,98.05,-0.946
17.32,97.93,-0.949
17.33,97.82,-0.952
17.34,97.70,-0.954
17.36,97.59,-0.959
17.37,97.47,-0.962
17.38,97.36,-0.964
17.39,97.24,-0.965
17.40,97.13,-0.968
17.41,97.01,-0.970
17.43,96.90,-0.972
17.44,96.78,-0.974
17.45,96.67,-0.977
17.46,96.55,-0.979
17.47,96.44,-0.981
17.48,96.32,-0.983
17.49,96.21,-0.985
17.51,96.09,-0.986
17.52,95.97,-0.988
17.53,95.86,-0.990
17.54,95.74,-0.992
17.55,95.63,-0.994
17.57,95.51,-0.995
17.58,95.40,-0.997
17.59,95.28,-0.999
17.60,95.16,-1.000
17.61,95.05,-1.002
17.62,94.93,-1.003
17.63,94.82,-1.005
17.65,94.70,-1.005
17.66,94.59,-1.007
17.67,94.47,-1.008
17.68,94.35,-1.009
17.69,94.24,-1.011
17.71,94.12,-1.011
17.72,94.01,-1.012
17.73,93.89,-1.013
17.74,93.78,-1.014
17.75,93.66,-1.015
17.76,93.54,-1.015
17.78,93.43,-1.017
17.79,93.31,-1.017
17.80,93.19,-1.018
17.81,93.08,-1.019
17.82,92.96,-1.020
17.83,92.85,-1.020
17.84,92.73,-1.021
17.86,92.61,-1.021
17.87,92.50,-1.021
17.88,92.38,-1.022
17.89,92.27,-1.022
17.90,92.15,-1.022
17.92,92.03,-1.023
17.93,91.92,-1.023
17.94,91.80,-1.023
17.95,91.68,-1.023
17.96,91.57,-1.023
17.97,91.45,-1.024
17.98,91.34,-1.024
18.00,91.22,-1.024
18.01,91.10,-1.024
18.02,90.99,-1.024
18.03,90.87,-1.023
18.04,90.75,-1.023
18.06,90.64,-1.023
18.07,90.52,-1.023
18.08,90.41,-1.023
18.09,90.29,-1.023
18.10,90.17,-1.023
18.11,90.06,-1.023
18.13,89.94,-1.023
18.14,89.82,-1.022
18.15,89.71,-1.022
18.16,89.59,-1.021
18.17,89.47,-1.021
18.18,89.36,-1.021
18.19,89.24,-1.020
18.21,89.13,-1.019
18.22,89.01,-1.020
18.23,88.89,-1.019
18.24,88.78,-1.018
18.25,88.66,-1.018
18.27,88.54,-1.018
18.28,88.43,-1.017
18.29,88.31,-1.017
18.30,88.19,-1.016
18.31,88.08,-1.016
18.32,87.96,-1.016
18.33,87.84,-1.016
18.35,87.73,-1.015
18.36,87.61,-1.014
18.37,87.50,-1.014
18.38,87.38,-1.014
18.39,87.26,-1.013
18.41,87.14,-1.012
18.42,87.03,-1.012
18.43,86.91,-1.012
18.44,86.80,-1.011
18.45,86.68,-1.011
18.46,86.56,-1.010
18.48,86.45,-1.009
18.49,86.33,-1.009
18.50,86.21,-1.009
18.51,86.10,-1.008
18.52,85.98,-1.007
18.53,85.86,-1.006
18.54,85.75,-1.006
18.56,85.63,-1.006
18.57,85.51,-1.005
18.58,85.40,-1.005
18.59,85.28,-1.004
18.60,85.16,-1.004
18.62,85.05,-1.003
18.63,84.93,-1.003
18.64,84.81,-1.002
18.65,84.70,-1.002
18.66,84.58,-1.002
18.67,84.46,-1.001
18.68,84.35,-1.000
18.70,84.23,-1.000
18.71,84.11,-1.000
18.72,84.00,-1.000
18.73,83.88,-0.999
18.74,83.76,-0.999
18.76,83.65,-0.998
18.77,83.53,-0.998
18.78,83.42,-0.998
18.79,83.30,-0.998
18.80,83.18,-0.997
18.81,83.07,-0.997
18.83,82.95,-0.997
18.84,82.83,-0.996
18.85,82.72,-0.996
18.86,82.60,-0.995
18.87,82.48,-0.995
18.88,82.37,-0.995
18.89,82.25,-0.995
18.91,82.13,-0.994
18.92,82.02,-0.994
18.93,81.90,-0.994
18.94,81.78,-0.993
18.95,81.67,-0.993
18.97,81.55,-0.993
18.98,81.43,-0.993
18.99,81.32,-0.993
19.00,81.20,-0.992
19.01,81.08,-0.992
19.02,80.97,-0.992
19.03,80.85,-0.992
19.05,80.73,-0.992
19.06,80.62,-0.991
19.07,80.50,-0.991
19.08,80.38,-0.991
19.09,80.27,-0.991
19.11,80.15,-0.991
19.12,80.03,-0.991
19.13,79.92,-0.990
19.14,79.80,-0.990
19.15,79.68,-0.990
19.16,79.57,-0.990
19.18,79.45,-0.990
19.19,79.33,-0.989
19.20,79.22,-0.989
19.21,79.10,-0.989
19.22,78.99,-0.988
19.23,78.87,-0.988
19.24,78.75,-0.988
19.26,78.63,-0.987
19.27,78.52,-0.987
19.28,78.40,-0.986
19.29,78.29,-0.986
19.30,78.17,-0.986
19.32,78.05,-0.986
19.33,77.93,-0.986
19.34,77.82,-0.985
19.35,77.70,-0.985
19.36,77.59,-0.985
19.37,77.47,-0.984
19.38,77.35,-0.984
19.40,77.24,-0.984
19.41,77.12,-0.984
19.42,77.00,-0.983
19.43,76.89,-0.982
19.44,76.77,-0.982
19.46,76.65,-0.982
19.47,76.54,-0.982
19.48,76.42,-0.981
19.49,76.30,-0.981
19.50,76.19,-0.981
19.51,76.07,-0.981
19.53,75.95,-0.980
19.54,75.84,-0.979
19.55,75.72,-0.979
19.56,75.60,-0.979
19.57,75.49,-0.979
19.58,75.37,-0.979
19.59,75.25,-0.978
19.61,75.14,-0.978
19.62,75.02,-0.978
19.63,74.90,-0.977
19.64,74.79,-0.977
19.65,74.67,-0.977
19.67,74.55,-0.977
19.68,74.44,-0.977
19.69,74.32,-0.976
19.70,74.20,-0.976
19.71,74.09,-0.976
19.72,73.97,-0.975
19.73,73.85,-0.975
19.75,73.74,-0.975
19.76,73.62,-0.974
19.77,73.50,-0.974
19.78,73.39,-0.974
19.79,73.27,-0.974
19.81,73.15,-0.973
19.82,73.04,-0.973
19.83,72.92,-0.972
19.84,72.80,-0.973
19.85,72.69,-0.972
19.86,72.57,-0.972
19.88,72.45,-0.972
19.89,72.34,-0.971
19.90,72.22,-0.970
19.91,72.10,-0.970
19.92,71.99,-0.970
19.93,71.87,-0.969
19.94,71.75,-0.969
19.96,71.64,-0.968
19.97,71.52,-0.968
19.98,71.40,-0.968
19.99,71.29,-0.968
20.00,71.17,-0.967
20.02,71.05,-0.967
20.03,70.94,-0.967
20.04,70.82,-0.966
20.05,70.70,-0.967
20.06,70.59,-0.965
20.07,70.47,-0.965
20.08,70.35,-0.965
20.10,70.24,-0.965
20.11,70.12,-0.964
20.12,70.00,-0.965
20.13,69.89,-0.964
20.14,69.77,-0.963
20.16,69.65,-0.963
20.17,69.54,-0.963
20.18,69.42,-0.962
20.19,69.31,-0.962
20.20,69.19,-0.963
20.21,69.07,-0.962
20.23,68.96,-0.962
20.24,68.84,-0.962
20.25,68.72,-0.961
20.26,68.61,-0.961
20.27,68.49,-0.961
20.28,68.37,-0.961
20.29,68.26,-0.961
20.31,68.14,-0.961
20.32,68.02,-0.961
20.33,67.91,-0.960
20.34,67.79,-0.960
20.35,67.67,-0.960
20.37,67.56,-0.959
20.38,67.44,-0.959
20.39,67.32,-0.959
20.40,67.21,-0.959
20.41,67.09,-0.959
20.42,66.97,-0.958
20.43,66.86,-0.958
20.45,66.74,-0.958
20.46,66.62,-0.958
20.47,66.51,-0.958
20.48,66.39,-0.958
20.49,66.27,-0.957
20.51,66.16,-0.957
20.52,66.04,-0.957
20.53,65.92,-0.957
20.54,65.81,-0.956
20.55,65.69,-0.956
20.56,65.57,-0.956
20.58,65.46,-0.956
20.59,65.34,-0.955
20.60,65.22,-0.955
20.61,65.11,-0.955
20.62,64.99,-0.954
20.63,64.87,-0.954
20.64,64.76,-0.954
20.66,64.64,-0.953
20.67,64.52,-0.953
20.68,64.41,-0.952
20.69,64.29,-0.952
20.70,64.17,-0.952
20.72,64.06,-0.952
20.73,63.94,-0.951
20.74,63.82,-0.951
20.75,63.71,-0.950
20.76,63.59,-0.951
20.77,63.47,-0.951
20.78,63.36,-0.950
20.80,63.24,-0.950
20.81,63.12,-0.950
20.82,63.01,-0.950
20.83,62.89,-0.949
20.84,62.77,-0.949
20.86,62.66,-0.949
20.87,62.54,-0.948
20.88,62.42,-0.948
20.89,62.31,-0.948
20.90,62.19,-0.948
20.91,62.07,-0.948
20.93,61.96,-0.947
20.94,61.84,-0.947
20.95,61.72,-0.947
20.96,61.61,-0.947
20.97,61.49,-0.947
20.98,61.37,-0.946
20.99,61.26,-0.946
21.01,61.14,-0.946
21.02,61.02,-0.945
21.03,60.91,-0.945
21.04,60.79,-0.944
21.05,60.67,-0.944
21.07,60.56,-0.944
21.08,60.44,-0.943
21.09,60.32,-0.943
21.10,60.21,-0.943
21.11,60.09,-0.942
21.12,59.97,-0.942
21.13,59.86,-0.942
21.15,59.74,-0.941
21.16,59.63,-0.942
21.17,59.51,-0.942
21.18,59.39,-0.941
21.19,59.28,-0.941
21.21,59.16,-0.941
21.22,59.04,-0.941
21.23,58.93,-0.941
21.24,58.81,-0.941
21.25,58.69,-0.940
21.26,58.58,-0.940
21.28,58.46,-0.940
21.29,58.34,-0.940
21.30,58.23,-0.940
21.31,58.11,-0.939
21.32,57.99,-0.940
21.33,57.88,-0.939
21.34,57.76,-0.939
21.36,57.64,-0.939
21.37,57.53,-0.939
21.38,57.41,-0.939
21.39,57.29,-0.939
21.40,57.18,-0.939
21.42,57.06,-0.938
21.43,56.94,-0.938
21.44,56.83,-0.938
21.45,56.71,-0.937
21.46,56.59,-0.937
21.47,56.48,-0.938
21.48,56.36,-0.937
21.50,56.24,-0.937
21.51,56.12,-0.937
21.52,56.01,-0.937
21.53,55.89,-0.936
21.54,55.78,-0.936
21.56,55.66,-0.936
21.57,55.54,-0.936
21.58,55.43,-0.936
21.59,55.31,-0.936
21.60,55.19,-0.936
21.61,55.08,-0.935
21.63,54.96,-0.935
21.64,54.84,-0.935
21.65,54.73,-0.934
21.66,54.61,-0.934
21.67,54.49,-0.934
21.68,54.38,-0.934
21.69,54.26,-0.934
21.71,54.14,-0.933
21.72,54.03,-0.933
21.73,53.91,-0.933
21.74,53.79,-0.933
21.75,53.68,-0.932
21.77,53.56,-0.932
21.78,53.44,-0.932
21.79,53.33,-0.932
21.80,53.21,-0.932
21.81,53.09,-0.932
21.82,52.98,-0.932
21.83,52.86,-0.932
21.85,52.74,-0.932
21.86,52.63,-0.932
21.87,52.51,-0.931
21.88,52.39,-0.931
21.89,52.28,-0.931
21.91,52.16,-0.931
21.92,52.04,-0.931
21.93,51.93,-0.930
21.94,51.81,-0.931
21.95,51.69,-0.930
21.96,51.58,-0.930
21.98,51.46,-0.930
21.99,51.34,-0.930
22.00,51.23,-0.929
22.01,51.11,-0.929
22.02,50.99,-0.929
22.03,50.88,-0.929
22.04,50.76,-0.929
22.06,50.64,-0.929
22.07,50.53,-0.928
22.08,50.41,-0.929
22.09,50.29,-0.928
22.10,50.18,-0.928
22.12,50.06,-0.928
22.13,49.94,-0.928
22.14,49.83,-0.928
22.15,49.71,-0.928
22.16,49.59,-0.927
22.17,49.48,-0.927
22.18,49.36,-0.927
22.20,49.25,-0.927
22.21,49.13,-0.927
22.22,49.01,-0.927
22.23,48.90,-0.926
22.24,48.78,-0.927
22.26,48.66,-0.926
22.27,48.55,-0.926
22.28,48.43,-0.926
22.29,48.31,-0.926
22.30,48.19,-0.926
22.31,48.08,-0.925
22.33,47.96,-0.925
22.34,47.85,-0.925
22.35,47.73,-0.925
22.36,47.61,-0.925
22.37,47.50,-0.925
22.38,47.38,-0.925
22.39,47.26,-0.925
22.41,47.15,-0.925
22.42,47.03,-0.924
22.43,46.91,-0.924
22.44,46.80,-0.924
22.45,46.68,-0.923
22.47,46.56,-0.923
22.48,46.45,-0.923
22.49,46.33,-0.922
22.50,46.21,-0.922
22.51,46.10,-0.922
22.52,45.98,-0.922
22.53,45.86,-0.922
22.55,45.75,-0.921
22.56,45.63,-0.921
22.57,45.51,-0.921
22.58,45.40,-0.921
22.59,45.28,-0.921
22.61,45.16,-0.921
22.62,45.05,-0.921
22.63,44.93,-0.920
22.64,44.81,-0.920
22.65,44.69,-0.920
22.66,44.58,-0.920
22.68,44.46,-0.920
22.69,44.35,-0.919
22.70,44.23,-0.919
22.71,44.11,-0.919
22.72,44.00,-0.918
22.73,43.88,-0.918
22.74,43.76,-0.918
22.76,43.65,-0.918
22.77,43.53,-0.917
22.78,43.41,-0.917
22.79,43.30,-0.917
22.80,43.18,-0.917
22.82,43.06,-0.917
22.83,42.95,-0.917
22.84,42.83,-0.917
22.85,42.71,-0.917
22.86,42.60,-0.917
22.87,42.48,-0.917
22.88,42.36,-0.917
22.90,42.25,-0.917
[...]
71.11,-30.06,0.348
71.12,-29.94,0.348
71.13,-29.82,0.347
71.14,-29.70,0.346
71.15,-29.59,0.346
71.17,-29.47,0.345
71.18,-29.36,0.345
71.19,-29.24,0.345
71.20,-29.12,0.344
71.21,-29.00,0.343
71.23,-28.89,0.343
71.24,-28.77,0.343
71.25,-28.65,0.342
71.26,-28.54,0.341
71.27,-28.42,0.341
71.28,-28.30,0.340
71.30,-28.19,0.340
71.31,-28.07,0.339
71.32,-27.95,0.339
71.33,-27.84,0.338
71.34,-27.72,0.337
71.35,-27.60,0.337
71.36,-27.49,0.337
71.38,-27.37,0.337
71.39,-27.25,0.336
71.40,-27.13,0.336
71.41,-27.02,0.335
71.42,-26.90,0.335
71.44,-26.79,0.335
71.45,-26.67,0.335
71.46,-26.55,0.334
71.47,-26.43,0.334
71.48,-26.32,0.333
71.49,-26.20,0.333
71.50,-26.08,0.332
71.52,-25.97,0.332
71.53,-25.85,0.332
71.54,-25.73,0.331
71.55,-25.62,0.331
71.56,-25.50,0.331
71.58,-25.38,0.330
71.59,-25.26,0.329
71.60,-25.15,0.328
71.61,-25.03,0.328
71.62,-24.92,0.328
71.63,-24.80,0.327
71.65,-24.68,0.327
71.66,-24.57,0.326
71.67,-24.45,0.326
71.68,-24.33,0.325
71.69,-24.22,0.325
71.70,-24.10,0.324
71.71,-23.98,0.324
71.73,-23.86,0.323
71.74,-23.75,0.323
71.75,-23.63,0.322
71.76,-23.51,0.322
71.77,-23.40,0.322
71.79,-23.28,0.321
71.80,-23.16,0.321
71.81,-23.05,0.321
71.82,-22.93,0.320
71.83,-22.81,0.319
71.84,-22.70,0.319
71.85,-22.58,0.319
71.87,-22.46,0.318
71.88,-22.35,0.317
71.89,-22.23,0.317
71.90,-22.11,0.316
71.91,-22.00,0.316
71.93,-21.88,0.315
71.94,-21.76,0.314
71.95,-21.65,0.314
71.96,-21.53,0.313
71.97,-21.41,0.313
71.98,-21.30,0.312
72.00,-21.18,0.312
72.01,-21.06,0.311
72.02,-20.95,0.311
72.03,-20.83,0.310
72.04,-20.71,0.310
72.05,-20.59,0.309
72.06,-20.48,0.309
72.08,-20.36,0.308
72.09,-20.24,0.308
72.10,-20.13,0.307
72.11,-20.01,0.307
72.12,-19.89,0.306
72.14,-19.78,0.305
72.15,-19.66,0.305
72.16,-19.54,0.304
72.17,-19.43,0.303
72.18,-19.31,0.303
72.19,-19.19,0.302
72.20,-19.08,0.301
72.22,-18.96,0.301
72.23,-18.84,0.300
72.24,-18.73,0.300
72.25,-18.61,0.299
72.26,-18.49,0.298
72.28,-18.37,0.298
72.29,-18.26,0.297
72.30,-18.14,0.296
72.31,-18.02,0.296
72.32,-17.91,0.295
72.33,-17.79,0.294
72.35,-17.67,0.293
72.36,-17.56,0.293
72.37,-17.44,0.292
72.38,-17.32,0.291
72.39,-17.21,0.291
72.40,-17.09,0.289
72.41,-16.97,0.289
72.43,-16.86,0.288
72.44,-16.74,0.287
72.45,-16.62,0.286
72.46,-16.50,0.286
72.47,-16.39,0.285
72.49,-16.27,0.284
72.50,-16.15,0.283
72.51,-16.04,0.282
72.52,-15.92,0.281
72.53,-15.80,0.280
72.54,-15.69,0.279
72.55,-15.57,0.278
72.57,-15.45,0.277
72.58,-15.34,0.276
72.59,-15.22,0.275
72.60,-15.10,0.274
72.61,-14.99,0.273
72.63,-14.87,0.272
72.64,-14.75,0.271
72.65,-14.64,0.271
72.66,-14.52,0.269
72.67,-14.40,0.268
72.68,-14.28,0.267
72.70,-14.17,0.266
72.71,-14.05,0.265
72.72,-13.93,0.264
72.73,-13.82,0.262
72.74,-13.70,0.261
72.75,-13.58,0.259
72.76,-13.47,0.258
72.78,-13.35,0.257
72.79,-13.23,0.255
72.80,-13.12,0.253
72.81,-13.00,0.252
72.82,-12.88,0.251
72.84,-12.77,0.249
72.85,-12.65,0.248
72.86,-12.53,0.246
72.87,-12.42,0.244
72.88,-12.30,0.243
72.89,-12.18,0.241
72.90,-12.07,0.239
72.92,-11.95,0.237
72.93,-11.83,0.235
72.94,-11.72,0.233
72.95,-11.60,0.231
72.96,-11.48,0.228
72.98,-11.36,0.226
72.99,-11.25,0.224
73.00,-11.13,0.222
73.01,-11.02,0.220
73.02,-10.90,0.217
73.03,-10.78,0.215
73.05,-10.66,0.212
73.06,-10.55,0.209
73.07,-10.43,0.206
73.08,-10.31,0.203
73.09,-10.20,0.200
73.10,-10.08,0.197
73.11,-9.96,0.194
73.13,-9.85,0.189
73.14,-9.73,0.186
73.15,-9.61,0.182
73.16,-9.49,0.179
73.17,-9.38,0.175
73.19,-9.26,0.170
73.20,-9.14,0.166
73.21,-9.03,0.162
73.22,-8.91,0.158
73.23,-8.79,0.154
73.24,-8.68,0.149
73.25,-8.56,0.144
73.27,-8.44,0.140
73.28,-8.33,0.134
73.29,-8.21,0.128
73.30,-8.09,0.124
73.31,-7.97,0.109
73.33,-7.86,0.105
73.34,-7.74,0.101
73.35,-7.62,0.096
73.36,-7.51,0.091
73.37,-7.39,0.083
73.38,-7.27,0.078
73.40,-7.16,0.073
73.41,-7.04,0.068
73.42,-6.92,0.061
73.43,-6.80,0.057
73.44,-6.69,0.051
73.45,-6.57,0.046
73.46,-6.45,0.041
73.48,-6.34,0.037
73.49,-6.22,0.026
73.50,-6.10,0.022
73.51,-5.99,0.017
73.52,-5.87,0.013
73.54,-5.75,0.008
73.55,-5.63,0.004
73.56,-5.52,-0.001
73.57,-5.40,-0.004
73.58,-5.28,-0.009
73.59,-5.17,-0.013
73.60,-5.05,-0.016
73.62,-4.93,-0.020
73.63,-4.82,-0.023
73.64,-4.70,-0.027
73.65,-4.58,-0.030
73.66,-4.47,-0.033
73.68,-4.35,-0.036
73.69,-4.23,-0.038
73.70,-4.12,-0.040
73.71,-4.00,-0.042
73.72,-3.88,-0.044
73.73,-3.76,-0.045
73.75,-3.65,-0.047
73.76,-3.53,-0.048
73.77,-3.42,-0.048
73.78,-3.30,-0.048
73.79,-3.18,-0.049
73.80,-3.07,-0.049
73.81,-2.95,-0.049
73.83,-2.83,-0.049
73.84,-2.72,-0.048
73.85,-2.60,-0.048
73.86,-2.48,-0.047
73.87,-2.36,-0.046
73.89,-2.25,-0.044
73.90,-2.13,-0.043
73.91,-2.01,-0.041
73.92,-1.90,-0.039
73.93,-1.78,-0.035
73.94,-1.67,-0.033
73.95,-1.55,-0.031
73.97,-1.43,-0.029
73.98,-1.31,-0.027
73.99,-1.20,-0.024
74.00,-1.08,-0.021
74.01,-0.96,-0.018
74.03,-0.85,-0.015
74.04,-0.73,-0.012
74.05,-0.62,-0.010
74.06,-0.50,-0.006
74.07,-0.38,-0.002
74.08,-0.26,0.001
74.10,-0.15,0.004
74.11,-0.03,0.007
74.12,0.08,0.010
74.13,0.20,0.015
74.14,0.32,0.018
74.15,0.44,0.022
74.16,0.55,0.025
74.18,0.67,0.028
74.19,0.78,0.031
74.20,0.90,0.035
74.21,1.02,0.038
74.22,1.14,0.041
74.24,1.25,0.045
74.25,1.37,0.048
74.26,1.49,0.051
74.27,1.60,0.053
74.28,1.72,0.057
74.29,1.84,0.060
74.30,1.95,0.063
74.32,2.07,0.066
74.33,2.19,0.068
74.34,2.30,0.071
74.35,2.42,0.074
74.36,2.54,0.076
74.38,2.65,0.079
74.39,2.77,0.081
74.40,2.89,0.083
74.41,3.00,0.085
74.42,3.12,0.088
74.43,3.24,0.090
74.45,3.35,0.092
74.46,3.47,0.094
74.47,3.59,0.096
74.48,3.70,0.098
74.49,3.82,0.100
74.50,3.94,0.102
74.51,4.05,0.103
74.53,4.17,0.105
74.54,4.29,0.107
74.55,4.40,0.108
74.56,4.52,0.111
74.57,4.64,0.112
74.59,4.75,0.114
74.60,4.87,0.115
74.61,4.99,0.116
74.62,5.10,0.118
74.63,5.22,0.119
74.64,5.34,0.120
74.65,5.46,0.121
74.67,5.57,0.122
74.68,5.69,0.124
74.69,5.81,0.125
74.70,5.92,0.126
74.71,6.04,0.127
74.73,6.16,0.128
74.74,6.27,0.129
74.75,6.39,0.130
74.76,6.51,0.131
74.77,6.62,0.132
74.78,6.74,0.133
74.80,6.86,0.134
74.81,6.97,0.135
74.82,7.09,0.136
74.83,7.21,0.136
74.84,7.32,0.137
74.85,7.44,0.138
74.86,7.56,0.139
74.88,7.67,0.139
74.89,7.79,0.141
74.90,7.91,0.141
74.91,8.02,0.142
74.92,8.14,0.143
74.94,8.26,0.143
74.95,8.38,0.144
74.96,8.49,0.145
74.97,8.61,0.145
74.98,8.72,0.146
74.99,8.84,0.147
75.00,8.96,0.147
75.02,9.08,0.148
75.03,9.19,0.148
75.04,9.31,0.149
75.05,9.43,0.150
75.06,9.54,0.150
75.08,9.66,0.151
75.09,9.78,0.152
75.10,9.89,0.152
75.11,10.01,0.153
75.12,10.13,0.154
75.13,10.24,0.154
75.15,10.36,0.155
75.16,10.48,0.155
75.17,10.59,0.156
75.18,10.71,0.156
75.19,10.83,0.157
75.20,10.94,0.157
75.21,11.06,0.157
75.23,11.18,0.158
75.24,11.29,0.159
75.25,11.41,0.160
75.26,11.53,0.160
75.27,11.64,0.160
75.29,11.76,0.160
75.30,11.88,0.161
75.31,12.00,0.161
75.32,12.11,0.162
75.33,12.23,0.163
75.34,12.34,0.163
75.35,12.46,0.164
75.37,12.58,0.164
75.38,12.70,0.165
75.39,12.81,0.165
75.40,12.93,0.166
75.41,13.05,0.166
75.43,13.16,0.167
75.44,13.28,0.167
75.45,13.40,0.167
75.46,13.51,0.168
75.47,13.63,0.168
75.48,13.75,0.169
75.50,13.86,0.169
75.51,13.98,0.170
75.52,14.10,0.170
75.53,14.21,0.171
75.54,14.33,0.172
75.55,14.45,0.172
75.56,14.56,0.172
75.58,14.68,0.173
75.59,14.80,0.173
75.60,14.92,0.173
75.61,15.03,0.174
75.62,15.15,0.174
75.64,15.26,0.175
75.65,15.38,0.175
75.66,15.50,0.176
75.67,15.62,0.177
75.68,15.73,0.177
75.69,15.85,0.177
75.70,15.97,0.178
75.72,16.08,0.178
75.73,16.20,0.179
75.74,16.32,0.179
75.75,16.43,0.179
75.76,16.55,0.179
75.78,16.67,0.180
75.79,16.78,0.180
75.80,16.90,0.181
75.81,17.02,0.181
75.82,17.13,0.182
75.83,17.25,0.182
75.85,17.37,0.182
75.86,17.48,0.183
75.87,17.60,0.184
75.88,17.72,0.184
75.89,17.83,0.185
75.90,17.95,0.185
75.91,18.07,0.186
75.93,18.18,0.186
75.94,18.30,0.188
75.95,18.42,0.188
75.96,18.53,0.189
75.97,18.65,0.189
75.99,18.77,0.190
76.00,18.88,0.191
76.01,19.00,0.192
76.02,19.12,0.192
76.03,19.23,0.192
76.04,19.35,0.193
76.05,19.47,0.194
76.07,19.59,0.195
76.08,19.70,0.195
76.09,19.82,0.196
76.10,19.93,0.198
76.11,20.05,0.198
76.13,20.17,0.199
76.14,20.29,0.200
76.15,20.40,0.201
76.16,20.52,0.202
76.17,20.64,0.203
76.18,20.75,0.204
76.20,20.87,0.204
76.21,20.99,0.206
76.22,21.10,0.207
76.23,21.22,0.208
76.24,21.34,0.209
76.25,21.45,0.211
76.26,21.57,0.211
76.28,21.69,0.213
76.29,21.80,0.215
76.30,21.92,0.216
76.31,22.03,0.218
76.32,22.15,0.220
76.34,22.27,0.223
76.35,22.39,0.228
76.36,22.50,0.232
76.37,22.62,0.235
76.38,22.73,0.238
76.39,22.85,0.244
76.40,22.97,0.246
76.42,23.09,0.249
76.43,23.20,0.252
76.44,23.32,0.255
76.45,23.44,0.258
76.46,23.55,0.261
76.48,23.67,0.263
76.49,23.79,0.266
76.50,23.90,0.268
76.51,24.02,0.271
76.52,24.13,0.274
76.53,24.25,0.277
76.55,24.37,0.279
76.56,24.49,0.282
76.57,24.60,0.285
76.58,24.72,0.288
76.59,24.84,0.291
76.60,24.95,0.294
76.61,25.07,0.297
76.63,25.19,0.301
76.64,25.30,0.304
76.65,25.42,0.310
76.66,25.54,0.313
76.67,25.65,0.321
76.69,25.77,0.325
76.70,25.88,0.330
76.71,26.00,0.343
76.72,26.12,0.347
76.73,26.23,0.364
76.74,26.35,0.372
76.75,26.47,0.380
76.77,26.59,0.393
76.78,26.70,0.400
76.79,26.82,0.407
76.80,26.93,0.434
76.81,27.05,0.445
76.83,27.17,0.460
76.84,27.28,0.477
76.85,27.40,0.500
76.86,27.52,0.530
76.87,27.63,0.547
76.88,27.75,0.567
76.90,27.87,0.594
76.91,27.98,0.617
76.92,28.10,0.654
76.93,28.21,0.678
76.94,28.33,0.718
76.95,28.45,0.748
76.96,28.56,0.784
76.98,28.68,0.825
76.99,28.80,0.848
77.00,28.91,0.892
77.01,29.03,0.931
77.02,29.14,0.962
77.04,29.26,1.010
77.05,29.37,1.044
77.06,29.49,1.086
77.07,29.60,1.135
77.08,29.72,1.177
77.09,29.84,1.223
77.10,29.95,1.266
77.12,30.07,1.303
77.13,30.18,1.339
77.14,30.30,1.392
77.15,30.42,1.412
77.16,30.53,1.441
77.18,30.65,1.463
77.19,30.76,1.488
77.20,30.88,1.496
77.21,31.00,1.505
77.22,31.11,1.511
77.23,31.23,1.513
77.25,31.34,1.512
77.26,31.46,1.511
77.27,31.58,1.508
77.28,31.70,1.504
77.29,31.81,1.494
77.30,31.93,1.477
77.31,32.05,1.458
77.33,32.16,1.429
77.34,32.28,1.404
77.35,32.40,1.378
77.36,32.52,1.355
77.37,32.63,1.319
77.39,32.75,1.301
77.40,32.87,1.281
77.41,32.98,1.270
77.42,33.10,1.262
77.43,33.22,1.255
77.44,33.34,1.244
77.45,33.45,1.240
77.47,33.57,1.237
77.48,33.69,1.234
77.49,33.80,1.232
77.50,33.92,1.230
77.51,34.04,1.228
77.53,34.15,1.227
77.54,34.27,1.226
77.55,34.39,1.225
77.56,34.51,1.223
77.57,34.62,1.222
77.58,34.74,1.221
77.60,34.86,1.219
77.61,34.97,1.217
77.62,35.09,1.211
77.63,35.21,1.204
77.64,35.32,1.183
77.65,35.44,1.153
77.66,35.56,1.116
77.68,35.68,1.081
77.69,35.79,1.035
77.70,35.91,0.975
77.71,36.03,0.923
77.72,36.15,0.884
77.74,36.26,0.839
77.75,36.38,0.795
77.76,36.50,0.750
77.77,36.62,0.712
77.78,36.74,0.682
77.79,36.85,0.649
77.80,36.97,0.622
77.82,37.09,0.595
77.83,37.21,0.569
77.84,37.32,0.545
77.85,37.44,0.523
77.86,37.56,0.508
77.88,37.68,0.488
77.89,37.79,0.475
77.90,37.91,0.455
77.91,38.03,0.444
77.92,38.15,0.433
77.93,38.26,0.428
77.95,38.38,0.418
77.96,38.50,0.404
77.97,38.61,0.391
77.98,38.73,0.377
77.99,38.85,0.364
78.00,38.97,0.339
78.01,39.08,0.322
78.03,39.20,0.305
78.04,39.32,0.286
78.05,39.44,0.271
78.06,39.55,0.257
78.07,39.67,0.234
78.09,39.79,0.218
78.10,39.90,0.198
78.11,40.02,0.180
78.12,40.14,0.165
78.13,40.26,0.154
78.14,40.37,0.137
78.15,40.49,0.125
78.17,40.61,0.115
78.18,40.72,0.106
78.19,40.84,0.097
78.20,40.96,0.093
78.21,41.08,0.088
78.23,41.19,0.084
78.24,41.31,0.080
78.25,41.43,0.077
78.26,41.54,0.075
78.27,41.66,0.073
78.28,41.78,0.070
78.30,41.89,0.068
78.31,42.01,0.066
78.32,42.13,0.065
78.33,42.24,0.063
78.34,42.36,0.062
78.35,42.48,0.061
78.36,42.59,0.061
78.38,42.71,0.061
78.39,42.83,0.061
78.40,42.94,0.062
78.41,43.06,0.063
78.42,43.18,0.065
78.44,43.29,0.066
78.45,43.41,0.068
78.46,43.53,0.072
78.47,43.64,0.074
78.48,43.76,0.076
78.49,43.88,0.080
78.50,43.99,0.083
78.52,44.11,0.086
78.53,44.23,0.090
78.54,44.34,0.095
78.55,44.46,0.099
78.56,44.58,0.103
78.58,44.69,0.106
78.59,44.81,0.111
78.60,44.93,0.117
78.61,45.04,0.121
78.62,45.16,0.124
78.63,45.27,0.128
78.65,45.39,0.134
78.66,45.51,0.137
78.67,45.63,0.141
78.68,45.74,0.145
78.69,45.86,0.149
78.70,45.98,0.152
78.71,46.09,0.156
78.73,46.21,0.160
78.74,46.33,0.163
78.75,46.44,0.168
78.76,46.56,0.171
78.77,46.68,0.174
78.79,46.79,0.179
78.80,46.91,0.182
78.81,47.03,0.185
78.82,47.14,0.188
78.83,47.26,0.192
78.84,47.38,0.195
78.85,47.49,0.199
78.87,47.61,0.202
78.88,47.73,0.205
78.89,47.84,0.209
78.90,47.96,0.213
78.91,48.08,0.217
78.93,48.19,0.221
78.94,48.31,0.228
78.95,48.43,0.233
78.96,48.54,0.246
78.97,48.66,0.260
78.98,48.78,0.279
79.00,48.89,0.303
79.01,49.01,0.338
79.02,49.12,0.386
79.03,49.24,0.457
79.04,49.36,0.518
79.05,49.47,0.592
79.06,49.59,0.685
79.08,49.70,0.777
79.09,49.82,0.847
79.10,49.93,0.907
79.11,50.05,0.960
79.12,50.17,0.986
79.14,50.28,0.984
79.15,50.40,0.977
79.16,50.51,0.948
79.17,50.63,0.851
79.18,50.75,0.691
79.19,50.87,0.589
79.20,50.98,0.516
79.22,51.10,0.456
79.23,51.22,0.401
79.24,51.34,0.357
79.25,51.46,0.336
79.26,51.58,0.306
79.28,51.69,0.296
79.29,51.81,0.295
79.30,51.93,0.291
79.31,52.04,0.286
79.32,52.16,0.278
79.33,52.28,0.273
79.35,52.40,0.271
79.36,52.51,0.269
79.37,52.63,0.266
79.38,52.75,0.264
79.39,52.87,0.263
79.40,52.98,0.262
79.41,53.10,0.261
79.43,53.21,0.260
79.44,53.33,0.259
79.45,53.45,0.258
79.46,53.57,0.257
79.47,53.68,0.256
79.49,53.80,0.254
79.50,53.92,0.253
79.51,54.03,0.253
79.52,54.15,0.252
79.53,54.27,0.251
79.54,54.38,0.250
79.55,54.50,0.249
79.57,54.62,0.249
79.58,54.73,0.248
79.59,54.85,0.247
79.60,54.97,0.246
79.61,55.08,0.245
79.63,55.20,0.245
79.64,55.32,0.244
79.65,55.43,0.244
79.66,55.55,0.243
79.67,55.67,0.243
79.68,55.78,0.242
79.70,55.90,0.242
79.71,56.02,0.241
79.72,56.13,0.241
79.73,56.25,0.241
79.74,56.37,0.240
79.75,56.49,0.240
79.76,56.60,0.239
79.78,56.72,0.239
79.79,56.84,0.239
79.80,56.95,0.238
79.81,57.07,0.238
79.82,57.18,0.238
79.84,57.30,0.238
79.85,57.42,0.238
79.86,57.54,0.237
79.87,57.65,0.237
79.88,57.77,0.236
79.89,57.89,0.236
79.90,58.00,0.236
79.92,58.12,0.236
79.93,58.24,0.236
79.94,58.35,0.235
79.95,58.47,0.235
79.96,58.59,0.235
79.98,58.70,0.234
79.99,58.82,0.234
80.00,58.94,0.234
80.01,59.05,0.234
80.02,59.17,0.234
80.03,59.29,0.234
80.05,59.41,0.234
80.06,59.52,0.234
80.07,59.64,0.234
80.08,59.76,0.233
80.09,59.87,0.233
80.10,59.99,0.233
80.11,60.11,0.233
80.13,60.22,0.233
80.14,60.34,0.233
80.15,60.46,0.233
80.16,60.57,0.233
80.17,60.69,0.233
80.19,60.81,0.233
80.20,60.93,0.233
80.21,61.04,0.232
80.22,61.16,0.232
80.23,61.27,0.232
80.24,61.39,0.232
80.25,61.51,0.232
80.27,61.63,0.232
80.28,61.74,0.232
80.29,61.86,0.232
80.30,61.98,0.232
80.31,62.09,0.231
80.33,62.21,0.231
80.34,62.32,0.231
80.35,62.44,0.231
80.36,62.56,0.231
80.37,62.68,0.231
80.38,62.79,0.232
80.40,62.91,0.232
80.41,63.03,0.232
80.42,63.14,0.232
80.43,63.26,0.232
80.44,63.37,0.232
80.45,63.49,0.232
80.46,63.61,0.231
80.48,63.73,0.232
80.49,63.84,0.232
80.50,63.96,0.232
80.51,64.08,0.232
80.52,64.19,0.232
80.54,64.31,0.232
80.55,64.43,0.232
80.56,64.54,0.231
80.57,64.66,0.231
80.58,64.78,0.231
80.59,64.89,0.231
80.60,65.01,0.231
80.62,65.13,0.231
80.63,65.24,0.231
80.64,65.36,0.231
80.65,65.48,0.231
80.66,65.59,0.231
80.68,65.71,0.231
80.69,65.83,0.231
80.70,65.95,0.231
80.71,66.06,0.231
80.72,66.18,0.231
80.73,66.29,0.231
80.75,66.41,0.231
80.76,66.53,0.231
80.77,66.64,0.231
80.78,66.76,0.231
80.79,66.88,0.231
80.80,66.99,0.231
80.81,67.11,0.231
80.83,67.23,0.231
80.84,67.34,0.230
80.85,67.46,0.231
80.86,67.58,0.231
80.87,67.69,0.230
80.89,67.81,0.230
80.90,67.93,0.230
80.91,68.04,0.230
80.92,68.16,0.230
80.93,68.28,0.230
80.94,68.40,0.230
80.95,68.51,0.230
80.97,68.63,0.230
80.98,68.74,0.230
80.99,68.86,0.230
81.00,68.98,0.229
81.01,69.10,0.230
81.03,69.21,0.229
81.04,69.33,0.229
81.05,69.45,0.230
81.06,69.56,0.229
81.07,69.68,0.230
81.08,69.80,0.230
81.10,69.91,0.231
81.11,70.03,0.230
81.12,70.15,0.230
81.13,70.26,0.230
81.14,70.38,0.231
81.15,70.50,0.231
81.16,70.61,0.231
81.18,70.73,0.231
81.19,70.85,0.230
81.20,70.96,0.230
81.21,71.08,0.231
81.22,71.20,0.231
81.24,71.31,0.231
81.25,71.43,0.230
81.26,71.55,0.231
81.27,71.67,0.231
81.28,71.78,0.231
81.29,71.90,0.231
81.30,72.01,0.231
81.32,72.13,0.230
81.33,72.25,0.230
81.34,72.37,0.230
81.35,72.48,0.230
81.36,72.60,0.230
81.38,72.72,0.230
81.39,72.83,0.231
81.40,72.95,0.231
81.41,73.07,0.231
81.42,73.18,0.231
81.43,73.30,0.231
81.45,73.42,0.231
81.46,73.53,0.231
81.47,73.65,0.231
81.48,73.77,0.231
81.49,73.88,0.231
81.50,74.00,0.231
81.51,74.12,0.231
81.53,74.23,0.231
81.54,74.35,0.231
81.55,74.47,0.231
81.56,74.58,0.232
81.57,74.70,0.231
81.59,74.82,0.232
81.60,74.93,0.232
81.61,75.05,0.232
81.62,75.17,0.231
81.63,75.28,0.231
81.64,75.40,0.231
81.65,75.52,0.231
81.67,75.63,0.232
81.68,75.75,0.231
81.69,75.87,0.231
81.70,75.99,0.232
81.71,76.10,0.232
81.73,76.22,0.232
81.74,76.34,0.232
81.75,76.45,0.232
81.76,76.57,0.232
81.77,76.68,0.232
81.78,76.80,0.232
81.80,76.92,0.232
81.81,77.04,0.233
81.82,77.15,0.233
81.83,77.27,0.232
81.84,77.39,0.232
81.85,77.50,0.232
81.86,77.62,0.232
81.88,77.74,0.232
81.89,77.85,0.232
81.90,77.97,0.232
81.91,78.09,0.232
81.92,78.20,0.232
81.94,78.32,0.232
81.95,78.44,0.232
81.96,78.55,0.232
81.97,78.67,0.232
81.98,78.79,0.232
81.99,78.90,0.232
82.00,79.02,0.232
82.02,79.14,0.232
82.03,79.25,0.232
82.04,79.37,0.232
82.05,79.49,0.232
82.06,79.60,0.232
82.08,79.72,0.232
82.09,79.84,0.232
82.10,79.95,0.232
82.11,80.07,0.232
82.12,80.19,0.232
82.13,80.31,0.232
82.15,80.42,0.232
82.16,80.54,0.232
82.17,80.66,0.232
82.18,80.77,0.232
82.19,80.89,0.232
82.20,81.01,0.232
82.21,81.12,0.232
82.23,81.24,0.232
82.24,81.36,0.232
82.25,81.47,0.232
82.26,81.59,0.232
82.27,81.71,0.232
82.29,81.82,0.232
82.30,81.94,0.232
82.31,82.06,0.232
82.32,82.17,0.232
82.33,82.29,0.232
82.34,82.41,0.232
82.35,82.52,0.232
82.37,82.64,0.232
82.38,82.76,0.232
82.39,82.87,0.232
82.40,82.99,0.232
82.41,83.11,0.232
82.43,83.22,0.232
82.44,83.34,0.232
82.45,83.46,0.232
82.46,83.58,0.232
82.47,83.69,0.232
82.48,83.81,0.231
82.50,83.92,0.231
82.51,84.04,0.231
82.52,84.16,0.231
82.53,84.27,0.231
82.54,84.39,0.231
82.55,84.51,0.231
82.56,84.62,0.231
82.58,84.74,0.231
82.59,84.86,0.231
82.60,84.98,0.231
82.61,85.09,0.231
82.62,85.21,0.231
82.64,85.33,0.231
82.65,85.45,0.231
82.66,85.56,0.231
82.67,85.68,0.231
82.68,85.80,0.231
82.69,85.91,0.231
82.70,86.03,0.230
82.72,86.15,0.230
82.73,86.26,0.230
82.74,86.38,0.230
82.75,86.50,0.229
82.76,86.62,0.229
82.78,86.73,0.229
82.79,86.85,0.228
82.80,86.97,0.228
82.81,87.08,0.228
82.82,87.20,0.227
82.83,87.32,0.227
82.85,87.43,0.226
82.86,87.55,0.226
82.87,87.67,0.226
82.88,87.78,0.225
82.89,87.90,0.225
82.90,88.02,0.225
82.91,88.13,0.224
82.93,88.25,0.224
82.94,88.37,0.224
82.95,88.48,0.223
82.96,88.60,0.223
82.97,88.71,0.222
82.99,88.83,0.222
83.00,88.95,0.222
83.01,89.07,0.222
83.02,89.18,0.221
83.03,89.30,0.221
83.04,89.42,0.221
83.05,89.53,0.220
83.07,89.65,0.220
83.08,89.77,0.220
83.09,89.88,0.220
83.10,90.00,0.220
83.11,90.12,0.220
83.13,90.23,0.220
83.14,90.35,0.219
83.15,90.46,0.220
83.16,90.58,0.220
83.17,90.70,0.219
83.18,90.81,0.220
83.20,90.93,0.220
83.21,91.05,0.220
83.22,91.16,0.220
83.23,91.28,0.220
83.24,91.40,0.220
83.25,91.52,0.220
83.26,91.63,0.220
83.28,91.75,0.220
83.29,91.87,0.220
83.30,91.98,0.220
83.31,92.10,0.221
83.32,92.22,0.221
83.34,92.33,0.221
83.35,92.45,0.221
83.36,92.57,0.221
83.37,92.68,0.221
83.38,92.80,0.221
83.39,92.92,0.221
83.40,93.03,0.221
83.42,93.15,0.221
83.43,93.27,0.221
83.44,93.38,0.221
83.45,93.50,0.221
83.46,93.62,0.222
83.48,93.73,0.222
83.49,93.85,0.222
83.50,93.97,0.222
83.51,94.08,0.222
83.52,94.20,0.221
83.53,94.32,0.222
83.55,94.43,0.222
83.56,94.55,0.222
83.57,94.67,0.222
83.58,94.78,0.222
83.59,94.90,0.222
83.60,95.02,0.222
83.61,95.13,0.222
83.63,95.25,0.222
83.64,95.37,0.222
83.65,95.48,0.222
83.66,95.60,0.222
83.67,95.72,0.222
83.69,95.83,0.222
83.70,95.95,0.222
83.71,96.07,0.221
83.72,96.18,0.221
83.73,96.30,0.222
83.74,96.42,0.222
83.75,96.53,0.222
83.77,96.65,0.222
83.78,96.77,0.222
83.79,96.89,0.222
83.80,97.00,0.222
83.81,97.12,0.221
83.83,97.24,0.221
83.84,97.35,0.221
83.85,97.47,0.221
83.86,97.59,0.221
83.87,97.70,0.222
83.88,97.82,0.222
83.90,97.94,0.222
83.91,98.05,0.222
83.92,98.17,0.222
83.93,98.29,0.222
83.94,98.40,
83.95,98.52,
83.96,98.64,
83.98,98.75,
83.99,,
83.99,,