File: DSC/2025_02_10_Azulene_DSC.txt
Filename	2025_02_10_Azulene_DSC
Instrument name	DSC2A-00468 (192.168.1.100)
Operator	JLY
rundate	2/10/2025
Sample name	2025_02_10_Azulene_DSC
proceduresegments	Data Off ; Equilibrate 30.00 °C; Data On ; Ramp 5.00 °C/min to 120.00 °C
[File Parameters]
Run date	2/10/2025 4:47:45 PM
Trios version	5.1.1.46572
Original File Name
Current File Name	D:\DSC2500\CHM343\2025_02_10_Azulene_DSC.tri
[Procedure]
Procedure Name	Azulene Melting
Sample Name	2025_02_10_Azulene_DSC
Sample Mass	0.12 mg
Reference Sample Mass	0 mg
Pan Mass	53.61 mg
Pan Number	21
Reference Pan Mass	54 mg
Reference Pan Number	19
Pan Type	Tzero Aluminum Hermetic
Comments	Al Hermetic Sealed Pan, with ref Al pan
Project Name
Operator	JLY
Test	Custom
Unload Max Temperature	30
Unload Min Temperature	30
Load Max Temperature	30
Load Min Temperature	30
Stop on Gas Flow Error	Yes
[Signal List]
Signal #1	Time (min)
Signal #2	Temperature (°C)
Signal #3	Heat Flow (mW)
Signal #4	Delta T (µV)
Signal #5	Delta Tzero (µV)
Signal #6	Tzero Temperature (°C)
Signal #7	Cell Purge (mL/min)
Signal #8	Heater Temp (°C)
Signal #9	Power Delivered (W)
Signal #10	Reference Junction Temperature (°C)
Signal #11	Flange Temperature (°C)
Signal #12	Heat Flow Phase (rad)
Signal #13	Total Heat Capacity (J/°C)
Signal #14	Heat Capacity (J/°C)
[Configuration]
Company Name	ASU
Instrument Name	DSC2A-00468
Instrument Type	DSC2500
Serial Number	DSC2A-00468
IP	192.168.1.100
Location of Instrument	MRRC
DisplayType	Unknown
Sample Interval 	0.1 s/pt
Selected Heat Flow	T4P
Exotherm Direction	Down
Cell Serial	DRC2-00792
Lid Type	Standard
Cooler	RCS 90
Leave Cooler on at End of Sequence	On
Gas 2	Nitrogen
Gas Selected	Channel 1
Flow Rate	50 mL/min
Secondary Purge	On
Licensed Heat Flow	Heat Flow T4P
Modulation Licensed	Yes
[Versions]
Common IDD Version	1
Cortex Version	VER 2.10.2.31
Driver	5.0.0.6
GDM Version	1.0.3.3
TouchscreenVersion	1.0.0.16145
FEP Version	1.2.1.21
FEP Bootloader	2.0.0.5
AutoSampler Version	2.1.1.26
Auto Sampler Bootloader	2.0.0.5
FCM Version	1.1.0.3
FCM Bootloader	2.0.0.5
[Experiment Logs]
Experiment Log Entry # 1	Data On set to 0
Experiment Log Entry # 3	Equilibrate Segment 30 (C) Started
Experiment Log Entry # 5	Data On set to 1
Experiment Log Entry # 7	Ramp Segment 5 C/min to 120 Started
[Method Log]
Method Log Entry # 1	Data Off
Method Log Entry # 2	Equilibrate 30 °C
Method Log Entry # 3	Data On
Method Log Entry # 4	(Ramp 11897) Ramp 5 °C/minute to 120 °C
Cell Serial	DRC2-00792
[T1 Calibration]
Slope	-0.008529666
Offset	9.636258
Initial Temperature	98.23
GUID	f8bfdadc-4977-4fdf-ba6d-0ba9134940c3
[TZero Calibration]
Date Applied	11/29/2022 4:06:13 PM
Description	From -89.059 °C to 396.009 °C at 20.000°C/min
Gas Type	Nitrogen
Pan Type	None
Source Files 1	C:\Users\yargerlab\Desktop\DSC Data\General\TZero_calibration_11_29_22_2nd(2).tri
Source Files 2	C:\Users\yargerlab\Desktop\DSC Data\General\TZero_calibration_11_29_22_2nd(3).tri
Delta T Offset	13.05235
Delta T Slope	-0.007271007
Delta T0 Offset	-13.69128
Delta T0 Slope	0.06063341
[Temperature Calibration]
Date Applied	11/29/2022 7:12:28 PM
Description	From 106.590 °C to 186.590 °C at 10.000°C/min
Gas Type	Nitrogen
Pan Type	Tzero Aluminum Hermetic
Source Files 1	C:\Users\yargerlab\Desktop\DSC Data\General\Indium(6).tri
Measured 1	157.391
Known 1	156.598
[Cell Constant Calibration]
Date Applied	11/29/2022 7:12:29 PM
Description	From 106.590 °C to 186.590 °C at 10.000°C/min
Gas Type	Nitrogen
Pan Type	Tzero Aluminum Hermetic
Source Files 1	C:\Users\yargerlab\Desktop\DSC Data\General\Indium(6).tri
T4P KCell	1.006051
Onset Slope	63.26126 mW/°C
[Direct Cp Calibration]
Date Applied	11/30/2022 11:04:51 AM
Description	From -79.983 °C to 298.409 °C at 10.000°C/min
Gas Type	Nitrogen
Pan Type	Tzero Aluminum Hermetic
Source Files 1	C:\Users\yargerlab\Desktop\DSC Data\General\Sapphire_Heat_Capacity_11_30_22.tri
[Rev Cp Calibration]
Date Applied	11/30/2022 1:58:51 PM
Description	From -79.996 °C to 292.812 °C at 3.000°C/min
Gas Type	Nitrogen
Pan Type	Tzero Aluminum Hermetic
Source Files 1	C:\Users\yargerlab\Desktop\DSC Data\General\Sapphire_MDSC_Calibration_11_30_22.tri
[step]
Ramp 5.00 °C/min to 120.00 °C
Time	Temperature	Heat Flow (Normalized)
min	°C	W/g
0.00	30.07	-0.884
0.01	30.07	-0.883
0.03	30.07	-0.881
0.04	30.07	-0.878
0.05	30.08	-0.875
0.07	30.09	-0.867
0.08	30.10	-0.851
0.09	30.12	-0.805
0.11	30.14	-0.679
0.12	30.17	-0.559
0.13	30.21	-0.375
0.15	30.25	-0.226
0.16	30.29	-0.122
0.17	30.34	-0.010
0.19	30.39	0.080
0.20	30.44	0.138
0.21	30.50	0.228
0.23	30.56	0.259
0.24	30.61	0.295
0.25	30.67	0.339
0.27	30.73	0.357
0.28	30.79	0.378
0.29	30.85	0.410
0.31	30.92	0.432
0.32	30.98	0.446
0.33	31.04	0.456
0.35	31.10	0.473
0.36	31.17	0.485
0.37	31.23	0.497
0.39	31.30	0.508
0.40	31.36	0.520
0.41	31.43	0.532
0.43	31.49	0.541
0.44	31.56	0.550
0.45	31.62	0.560
0.47	31.69	0.569
0.48	31.76	0.577
0.49	31.82	0.586
0.51	31.89	0.596
0.52	31.95	0.605
0.53	32.02	0.612
0.55	32.08	0.618
0.56	32.15	0.624
0.57	32.21	0.631
0.59	32.28	0.636
0.60	32.35	0.643
0.61	32.41	0.648
0.63	32.48	0.654
0.64	32.54	0.659
0.65	32.61	0.664
0.67	32.68	0.669
0.68	32.74	0.673
0.69	32.81	0.676
0.71	32.88	0.678
0.72	32.94	0.682
0.73	33.01	0.686
0.75	33.07	0.688
0.76	33.14	0.690
0.77	33.21	0.694
0.79	33.27	0.695
0.80	33.34	0.697
0.81	33.41	0.698
0.83	33.47	0.700
0.84	33.54	0.704
0.85	33.61	0.703
0.87	33.67	0.705
0.88	33.74	0.707
0.89	33.80	0.710
0.91	33.87	0.710
0.92	33.94	0.710
0.93	34.00	0.710
0.95	34.07	0.710
0.96	34.14	0.711
0.97	34.20	0.713
0.99	34.27	0.713
1.00	34.34	0.714
1.01	34.40	0.714
1.03	34.47	0.714
1.04	34.53	0.715
1.05	34.60	0.715
1.07	34.67	0.713
1.08	34.73	0.711
1.09	34.80	0.713
1.11	34.87	0.712
1.12	34.93	0.713
1.13	35.00	0.712
1.15	35.07	0.711
1.16	35.13	0.711
1.17	35.20	0.710
1.19	35.27	0.709
1.20	35.33	0.708
1.21	35.40	0.706
1.23	35.47	0.707
1.24	35.53	0.705
1.25	35.60	0.704
1.27	35.66	0.703
1.28	35.73	0.702
1.29	35.80	0.697
1.31	35.86	0.700
1.32	35.93	0.699
1.33	36.00	0.697
1.35	36.06	0.696
1.36	36.13	0.696
1.37	36.20	0.693
1.39	36.26	0.692
1.40	36.33	0.690
1.41	36.40	0.689
1.43	36.46	0.690
1.44	36.53	0.689
1.45	36.60	0.687
1.47	36.66	0.687
1.48	36.73	0.686
1.49	36.80	0.685
1.51	36.86	0.684
1.52	36.93	0.682
1.53	37.00	0.680
1.55	37.06	0.679
1.56	37.13	0.677
1.57	37.20	0.676
1.59	37.26	0.675
1.60	37.33	0.675
1.61	37.40	0.675
1.63	37.46	0.674
1.64	37.53	0.673
1.65	37.60	0.671
1.67	37.66	0.671
1.68	37.73	0.668
1.69	37.80	0.667
1.71	37.86	0.666
1.72	37.93	0.664
1.73	38.00	0.662
1.75	38.06	0.662
1.76	38.13	0.660
1.77	38.20	0.658
1.79	38.26	0.658
1.80	38.33	0.659
1.81	38.40	0.659
1.83	38.46	0.658
1.84	38.53	0.656
1.85	38.60	0.657
1.87	38.66	0.655
1.88	38.73	0.655
1.89	38.80	0.654
1.91	38.86	0.653
1.92	38.93	0.652
1.93	39.00	0.649
1.95	39.06	0.649
1.96	39.13	0.648
1.97	39.20	0.646
1.99	39.26	0.647
2.00	39.33	0.645
2.01	39.40	0.644
2.03	39.46	0.643
2.04	39.53	0.642
2.05	39.60	0.642
2.07	39.66	0.642
2.08	39.73	0.639
2.09	39.80	0.638
2.11	39.86	0.638
2.12	39.93	0.638
2.13	40.00	0.635
2.15	40.06	0.635
2.16	40.13	0.633
2.17	40.20	0.633
2.19	40.26	0.631
2.20	40.33	0.633
2.21	40.40	0.632
2.23	40.46	0.630
2.24	40.53	0.630
2.25	40.60	0.629
2.27	40.66	0.628
2.28	40.73	0.626
2.29	40.80	0.627
2.31	40.86	0.627
2.32	40.93	0.626
2.33	41.00	0.625
2.35	41.06	0.625
2.36	41.13	0.623
2.37	41.20	0.622
2.39	41.26	0.621
2.40	41.33	0.621
2.41	41.40	0.620
2.43	41.46	0.618
2.44	41.53	0.619
2.45	41.60	0.617
2.47	41.67	0.616
2.48	41.73	0.616
2.49	41.80	0.614
2.51	41.86	0.614
2.52	41.93	0.615
2.53	42.00	0.613
2.55	42.06	0.613
2.56	42.13	0.612
2.57	42.20	0.611
2.59	42.26	0.612
2.60	42.33	0.610
2.61	42.40	0.610
2.63	42.46	0.610
2.64	42.53	0.609
2.65	42.60	0.608
2.67	42.66	0.607
2.68	42.73	0.606
2.69	42.80	0.606
2.71	42.87	0.605
2.72	42.93	0.604
2.73	43.00	0.603
2.75	43.07	0.603
2.76	43.13	0.603
2.77	43.20	0.603
2.79	43.26	0.601
2.80	43.33	0.603
2.81	43.40	0.601
2.83	43.46	0.603
2.84	43.53	0.601
2.85	43.60	0.600
2.87	43.66	0.599
2.88	43.73	0.599
2.89	43.80	0.599
2.91	43.86	0.599
2.92	43.93	0.599
2.93	44.00	0.597
2.95	44.06	0.597
2.96	44.13	0.596
2.97	44.20	0.598
2.99	44.27	0.595
3.00	44.33	0.595
3.01	44.40	0.593
3.03	44.46	0.594
3.04	44.53	0.596
3.05	44.60	0.594
3.07	44.67	0.593
3.08	44.73	0.593
3.09	44.80	0.592
3.11	44.87	0.591
3.12	44.93	0.590
3.13	45.00	0.590
3.15	45.07	0.590
3.16	45.13	0.590
3.17	45.20	0.590
3.19	45.27	0.590
3.20	45.33	0.588
3.21	45.40	0.588
3.23	45.47	0.587
3.24	45.53	0.587
3.25	45.60	0.587
3.27	45.66	0.586
3.28	45.73	0.586
3.29	45.80	0.585
3.31	45.87	0.585
3.32	45.93	0.584
3.33	46.00	0.585
3.35	46.07	0.583
3.36	46.13	0.583
3.37	46.20	0.582
3.39	46.27	0.581
3.40	46.33	0.581
3.41	46.40	0.580
3.43	46.47	0.579
3.44	46.53	0.579
3.45	46.60	0.579
3.47	46.67	0.577
3.48	46.73	0.577
3.49	46.80	0.577
3.51	46.87	0.577
3.52	46.93	0.577
3.53	47.00	0.578
3.55	47.07	0.576
3.56	47.13	0.574
3.57	47.20	0.576
3.59	47.27	0.577
3.60	47.33	0.575
3.61	47.40	0.576
3.63	47.47	0.575
3.64	47.53	0.575
3.65	47.60	0.576
3.67	47.67	0.576
3.68	47.73	0.574
3.69	47.80	0.576
3.71	47.87	0.577
3.72	47.93	0.574
3.73	48.00	0.574
3.75	48.07	0.575
3.76	48.14	0.576
3.77	48.20	0.574
3.79	48.27	0.572
3.80	48.33	0.574
3.81	48.40	0.575
3.83	48.47	0.574
3.84	48.53	0.575
3.85	48.60	0.575
3.87	48.67	0.574
3.88	48.73	0.572
3.89	48.80	0.573
3.91	48.87	0.575
3.92	48.93	0.575
3.93	49.00	0.573
3.95	49.07	0.573
3.96	49.13	0.574
3.97	49.20	0.574
3.99	49.27	0.574
4.00	49.33	0.574
4.01	49.40	0.573
4.03	49.47	0.573
4.04	49.54	0.573
4.05	49.60	0.572
4.07	49.67	0.572
4.08	49.74	0.571
4.09	49.80	0.572
4.11	49.87	0.570
4.12	49.94	0.570
4.13	50.00	0.571
4.15	50.07	0.571
4.16	50.13	0.571
4.17	50.20	0.572
4.19	50.27	0.571
4.20	50.34	0.571
4.21	50.40	0.570
4.23	50.47	0.570
4.24	50.53	0.569
4.25	50.60	0.570
4.27	50.67	0.570
4.28	50.74	0.570
4.29	50.80	0.570
4.31	50.87	0.571
4.32	50.94	0.568
4.33	51.00	0.569
4.35	51.07	0.566
4.36	51.14	0.567
4.37	51.20	0.568
4.39	51.27	0.568
4.40	51.34	0.567
4.41	51.40	0.567
4.43	51.47	0.568
4.44	51.54	0.567
4.45	51.60	0.567
4.47	51.67	0.567
4.48	51.74	0.566
4.49	51.80	0.567
4.51	51.87	0.564
4.52	51.94	0.567
4.53	52.00	0.563
4.55	52.07	0.563
4.56	52.14	0.563
4.57	52.20	0.564
4.59	52.27	0.563
4.60	52.34	0.563
4.61	52.40	0.562
4.63	52.47	0.561
4.64	52.54	0.563
4.65	52.60	0.562
4.67	52.67	0.563
4.68	52.74	0.561
4.69	52.80	0.563
4.71	52.87	0.561
4.72	52.94	0.561
4.73	53.00	0.561
4.75	53.07	0.560
4.76	53.14	0.560
4.77	53.20	0.560
4.79	53.27	0.561
4.80	53.34	0.561
4.81	53.40	0.561
4.83	53.47	0.560
4.84	53.54	0.559
4.85	53.60	0.558
4.87	53.67	0.559
4.88	53.74	0.559
4.89	53.80	0.560
4.91	53.87	0.561
4.92	53.94	0.561
4.93	54.00	0.561
4.95	54.07	0.558
4.96	54.14	0.562
4.97	54.20	0.560
4.99	54.27	0.558
5.00	54.34	0.558
5.01	54.40	0.559
5.03	54.47	0.559
5.04	54.54	0.559
5.05	54.60	0.559
5.07	54.67	0.557
5.08	54.74	0.558
5.09	54.80	0.559
5.11	54.87	0.560
5.12	54.94	0.559
5.13	55.00	0.559
5.15	55.07	0.558
5.16	55.14	0.558
5.17	55.20	0.559
5.19	55.27	0.558
5.20	55.34	0.558
5.21	55.40	0.558
5.23	55.47	0.559
5.24	55.54	0.557
5.25	55.60	0.559
5.27	55.67	0.559
5.28	55.74	0.560
5.29	55.80	0.560
5.31	55.87	0.559
5.32	55.94	0.558
5.33	56.00	0.560
5.35	56.07	0.560
5.36	56.14	0.559
5.37	56.21	0.559
5.39	56.27	0.558
5.40	56.34	0.559
5.41	56.40	0.559
5.43	56.47	0.560
5.44	56.54	0.560
5.45	56.61	0.559
5.47	56.67	0.560
5.48	56.74	0.561
5.49	56.81	0.562
5.51	56.87	0.561
5.52	56.94	0.561
5.53	57.01	0.560
5.55	57.07	0.560
5.56	57.14	0.562
5.57	57.20	0.560
5.59	57.27	0.561
5.60	57.34	0.560
5.61	57.41	0.561
5.63	57.47	0.561
5.64	57.54	0.562
5.65	57.61	0.561
5.67	57.67	0.562
5.68	57.74	0.562
5.69	57.81	0.563
5.71	57.87	0.562
5.72	57.94	0.564
5.73	58.01	0.565
5.75	58.07	0.565
5.76	58.14	0.564
5.77	58.21	0.565
5.79	58.27	0.565
5.80	58.34	0.565
5.81	58.41	0.566
5.83	58.47	0.565
5.84	58.54	0.565
5.85	58.61	0.566
5.87	58.67	0.566
5.88	58.74	0.567
5.89	58.81	0.567
5.91	58.87	0.567
5.92	58.94	0.566
5.93	59.01	0.565
5.95	59.07	0.566
5.96	59.14	0.565
5.97	59.21	0.565
5.99	59.27	0.565
6.00	59.34	0.567
6.01	59.41	0.566
6.03	59.47	0.565
6.04	59.54	0.565
6.05	59.61	0.565
6.07	59.67	0.566
6.08	59.74	0.564
6.09	59.81	0.566
6.11	59.87	0.565
6.12	59.94	0.565
6.13	60.01	0.564
6.15	60.07	0.565
6.16	60.14	0.566
6.17	60.21	0.566
6.19	60.27	0.565
6.20	60.34	0.566
6.21	60.41	0.566
6.23	60.47	0.566
6.24	60.54	0.567
6.25	60.61	0.568
6.27	60.67	0.568
6.28	60.74	0.568
6.29	60.81	0.567
6.31	60.87	0.567
6.32	60.94	0.567
6.33	61.01	0.566
6.35	61.07	0.567
6.36	61.14	0.567
6.37	61.21	0.567
6.39	61.27	0.568
6.40	61.34	0.570
6.41	61.41	0.570
6.43	61.47	0.569
6.44	61.54	0.570
6.45	61.61	0.570
6.47	61.67	0.571
6.48	61.74	0.572
6.49	61.81	0.573
6.51	61.87	0.574
6.52	61.94	0.573
6.53	62.01	0.572
6.55	62.07	0.573
6.56	62.14	0.573
6.57	62.21	0.575
6.59	62.28	0.575
6.60	62.34	0.574
6.61	62.41	0.573
6.63	62.48	0.575
6.64	62.54	0.574
6.65	62.61	0.574
6.67	62.68	0.575
6.68	62.74	0.573
6.69	62.81	0.574
6.71	62.87	0.573
6.72	62.94	0.573
6.73	63.01	0.573
6.75	63.08	0.574
6.76	63.14	0.574
6.77	63.21	0.573
6.79	63.27	0.575
6.80	63.34	0.576
6.81	63.41	0.575
6.83	63.48	0.577
6.84	63.54	0.576
6.85	63.61	0.577
6.87	63.68	0.578
6.88	63.74	0.578
6.89	63.81	0.578
6.91	63.88	0.578
6.92	63.94	0.578
6.93	64.01	0.577
6.95	64.07	0.577
6.96	64.14	0.578
6.97	64.21	0.578
6.99	64.28	0.578
7.00	64.34	0.578
7.01	64.41	0.577
7.03	64.48	0.577
7.04	64.54	0.577
7.05	64.61	0.576
7.07	64.68	0.577
7.08	64.74	0.576
7.09	64.81	0.577
7.11	64.88	0.576
7.12	64.94	0.577
7.13	65.01	0.578
7.15	65.08	0.577
7.16	65.14	0.578
7.17	65.21	0.579
7.19	65.28	0.578
7.20	65.34	0.578
7.21	65.41	0.578
7.23	65.48	0.578
7.24	65.54	0.577
7.25	65.61	0.576
7.27	65.68	0.578
7.28	65.74	0.579
7.29	65.81	0.580
7.31	65.88	0.579
7.32	65.94	0.580
7.33	66.01	0.579
7.35	66.08	0.580
7.36	66.14	0.580
7.37	66.21	0.581
7.39	66.28	0.580
7.40	66.34	0.582
7.41	66.41	0.582
7.43	66.48	0.582
7.44	66.54	0.581
7.45	66.61	0.581
7.47	66.68	0.584
7.48	66.74	0.584
7.49	66.81	0.583
7.51	66.88	0.582
7.52	66.94	0.582
7.53	67.01	0.583
7.55	67.08	0.584
7.56	67.14	0.584
7.57	67.21	0.584
7.59	67.28	0.585
7.60	67.34	0.586
7.61	67.41	0.585
7.63	67.48	0.586
7.64	67.54	0.587
7.65	67.61	0.589
7.67	67.68	0.588
7.68	67.74	0.588
7.69	67.81	0.588
7.71	67.88	0.586
7.72	67.94	0.588
7.73	68.01	0.589
7.75	68.08	0.589
7.76	68.14	0.588
7.77	68.21	0.589
7.79	68.28	0.589
7.80	68.35	0.590
7.81	68.41	0.589
7.83	68.48	0.590
7.84	68.54	0.591
7.85	68.61	0.591
7.87	68.68	0.590
7.88	68.75	0.592
7.89	68.81	0.591
7.91	68.88	0.591
7.92	68.94	0.593
7.93	69.01	0.592
7.95	69.08	0.593
7.96	69.15	0.592
7.97	69.21	0.593
7.99	69.28	0.593
8.00	69.35	0.593
8.01	69.41	0.591
8.03	69.48	0.592
8.04	69.54	0.591
8.05	69.61	0.593
8.07	69.68	0.592
8.08	69.75	0.593
8.09	69.81	0.594
8.11	69.88	0.595
8.12	69.94	0.595
8.13	70.01	0.594
8.15	70.08	0.594
8.16	70.15	0.593
8.17	70.21	0.593
8.19	70.28	0.595
8.20	70.35	0.595
8.21	70.41	0.594
8.23	70.48	0.594
8.24	70.55	0.593
8.25	70.61	0.594
8.27	70.68	0.594
8.28	70.75	0.594
8.29	70.81	0.595
8.31	70.88	0.596
8.32	70.95	0.594
8.33	71.01	0.595
8.35	71.08	0.596
8.36	71.15	0.595
8.37	71.21	0.595
8.39	71.28	0.597
8.40	71.35	0.597
8.41	71.41	0.598
8.43	71.48	0.597
8.44	71.55	0.597
8.45	71.61	0.598
8.47	71.68	0.598
8.48	71.75	0.598
8.49	71.81	0.599
8.51	71.88	0.599
8.52	71.95	0.601
8.53	72.01	0.599
8.55	72.08	0.598
8.56	72.15	0.598
8.57	72.21	0.599
8.59	72.28	0.599
8.60	72.35	0.598
8.61	72.41	0.599
8.63	72.48	0.599
8.64	72.55	0.600
8.65	72.61	0.601
8.67	72.68	0.601
8.68	72.75	0.600
8.69	72.81	0.601
8.71	72.88	0.600
8.72	72.95	0.600
8.73	73.01	0.600
8.75	73.08	0.601
8.76	73.15	0.599
8.77	73.21	0.600
8.79	73.28	0.601
8.80	73.35	0.601
8.81	73.41	0.601
8.83	73.48	0.601
8.84	73.55	0.601
8.85	73.61	0.600
8.87	73.68	0.601
8.88	73.75	0.601
8.89	73.81	0.602
8.91	73.88	0.603
8.92	73.95	0.605
8.93	74.01	0.602
8.95	74.08	0.604
8.96	74.15	0.605
8.97	74.21	0.606
8.99	74.28	0.605
9.00	74.35	0.607
9.01	74.42	0.608
9.03	74.48	0.608
9.04	74.55	0.607
9.05	74.61	0.606
9.07	74.68	0.605
9.08	74.75	0.608
9.09	74.81	0.609
9.11	74.88	0.609
9.12	74.95	0.608
9.13	75.01	0.610
9.15	75.08	0.609
9.16	75.15	0.610
9.17	75.21	0.610
9.19	75.28	0.610
9.20	75.35	0.610
9.21	75.41	0.611
9.23	75.48	0.611
9.24	75.55	0.612
9.25	75.61	0.612
9.27	75.68	0.612
9.28	75.75	0.612
9.29	75.81	0.612
9.31	75.88	0.613
9.32	75.95	0.613
9.33	76.01	0.611
9.35	76.08	0.612
9.36	76.15	0.614
9.37	76.21	0.613
9.39	76.28	0.613
9.40	76.35	0.615
9.41	76.42	0.614
9.43	76.48	0.615
9.44	76.55	0.614
9.45	76.62	0.615
9.47	76.68	0.616
9.48	76.75	0.617
9.49	76.82	0.617
9.51	76.88	0.617
9.52	76.95	0.616
9.53	77.02	0.618
9.55	77.08	0.616
9.56	77.15	0.616
9.57	77.22	0.617
9.59	77.28	0.617
9.60	77.35	0.617
9.61	77.42	0.618
9.63	77.48	0.618
9.64	77.55	0.617
9.65	77.61	0.617
9.67	77.68	0.617
9.68	77.75	0.619
9.69	77.81	0.618
9.71	77.88	0.619
9.72	77.95	0.618
9.73	78.01	0.619
9.75	78.08	0.620
9.76	78.15	0.620
9.77	78.22	0.621
9.79	78.28	0.621
9.80	78.35	0.620
9.81	78.42	0.620
9.83	78.48	0.620
9.84	78.55	0.621
9.85	78.62	0.622
9.87	78.68	0.621
9.88	78.75	0.623
9.89	78.82	0.623
9.91	78.88	0.624
9.92	78.95	0.624
9.93	79.02	0.626
9.95	79.08	0.626
9.96	79.15	0.628
9.97	79.22	0.628
9.99	79.28	0.627
10.00	79.35	0.628
10.01	79.42	0.629
10.03	79.48	0.630
10.04	79.55	0.629
10.05	79.62	0.630
10.07	79.68	0.630
10.08	79.75	0.630
10.09	79.82	0.629
10.11	79.88	0.630
10.12	79.95	0.629
10.13	80.02	0.630
10.15	80.08	0.630
10.16	80.15	0.630
10.17	80.22	0.629
10.19	80.28	0.630
10.20	80.35	0.631
10.21	80.42	0.630
10.23	80.48	0.630
10.24	80.55	0.629
10.25	80.62	0.631
10.27	80.68	0.630
10.28	80.75	0.630
10.29	80.82	0.631
10.31	80.88	0.630
10.32	80.95	0.630
10.33	81.02	0.630
10.35	81.08	0.629
10.36	81.15	0.629
10.37	81.22	0.629
10.39	81.28	0.629
10.40	81.35	0.628
10.41	81.42	0.629
10.43	81.48	0.628
10.44	81.55	0.629
10.45	81.62	0.630
10.47	81.68	0.632
10.48	81.75	0.633
10.49	81.82	0.632
10.51	81.88	0.632
10.52	81.95	0.631
10.53	82.02	0.633
10.55	82.08	0.634
10.56	82.15	0.633
10.57	82.22	0.634
10.59	82.28	0.633
10.60	82.35	0.634
10.61	82.42	0.635
10.63	82.48	0.632
10.64	82.55	0.634
10.65	82.62	0.633
10.67	82.68	0.633
10.68	82.75	0.632
10.69	82.82	0.632
10.71	82.88	0.633
10.72	82.95	0.632
10.73	83.02	0.631
10.75	83.08	0.631
10.76	83.15	0.631
10.77	83.22	0.632
10.79	83.28	0.632
10.80	83.35	0.632
10.81	83.42	0.630
10.83	83.49	0.631
10.84	83.55	0.631
10.85	83.62	0.631
10.87	83.68	0.631
10.88	83.75	0.630
10.89	83.82	0.630
10.91	83.88	0.629
10.92	83.95	0.631
10.93	84.02	0.631
10.95	84.08	0.632
10.96	84.15	0.632
10.97	84.22	0.633
10.99	84.29	0.634
11.00	84.35	0.634
11.01	84.42	0.633
11.03	84.49	0.635
11.04	84.55	0.635
11.05	84.62	0.635
11.07	84.69	0.636
11.08	84.75	0.635
11.09	84.82	0.637
11.11	84.89	0.637
11.12	84.95	0.638
11.13	85.02	0.637
11.15	85.09	0.637
11.16	85.15	0.637
11.17	85.22	0.638
11.19	85.29	0.640
11.20	85.35	0.639
11.21	85.42	0.638
11.23	85.49	0.639
11.24	85.55	0.639
11.25	85.62	0.639
11.27	85.69	0.639
11.28	85.75	0.639
11.29	85.82	0.639
11.31	85.89	0.640
11.32	85.95	0.642
11.33	86.02	0.643
11.35	86.09	0.643
11.36	86.15	0.643
11.37	86.22	0.643
11.39	86.29	0.643
11.40	86.35	0.644
11.41	86.42	0.644
11.43	86.49	0.646
11.44	86.55	0.645
11.45	86.62	0.646
11.47	86.69	0.646
11.48	86.75	0.645
11.49	86.82	0.645
11.51	86.89	0.646
11.52	86.95	0.646
11.53	87.02	0.647
11.55	87.09	0.646
11.56	87.15	0.647
11.57	87.22	0.646
11.59	87.29	0.648
11.60	87.35	0.649
11.61	87.42	0.651
11.63	87.49	0.651
11.64	87.55	0.651
11.65	87.62	0.650
11.67	87.69	0.650
11.68	87.75	0.651
11.69	87.82	0.651
11.71	87.89	0.651
11.72	87.95	0.651
11.73	88.02	0.652
11.75	88.09	0.653
11.76	88.15	0.652
11.77	88.22	0.654
11.79	88.29	0.655
11.80	88.35	0.656
11.81	88.42	0.656
11.83	88.49	0.655
11.84	88.55	0.657
11.85	88.62	0.656
11.87	88.69	0.655
11.88	88.75	0.657
11.89	88.82	0.658
11.91	88.89	0.659
11.92	88.95	0.657
11.93	89.02	0.658
11.95	89.09	0.660
11.96	89.15	0.659
11.97	89.22	0.661
11.99	89.29	0.662
12.00	89.35	0.662
12.01	89.42	0.662
12.03	89.49	0.663
12.04	89.55	0.664
12.05	89.62	0.665
12.07	89.69	0.665
12.08	89.75	0.666
12.09	89.82	0.666
12.11	89.89	0.667
12.12	89.95	0.666
12.13	90.02	0.668
12.15	90.09	0.668
12.16	90.15	0.669
12.17	90.22	0.670
12.19	90.29	0.671
12.20	90.36	0.671
12.21	90.42	0.670
12.23	90.49	0.672
12.24	90.56	0.672
12.25	90.62	0.673
12.27	90.69	0.674
12.28	90.75	0.673
12.29	90.82	0.674
12.31	90.89	0.675
12.32	90.96	0.676
12.33	91.02	0.677
12.35	91.09	0.678
12.36	91.16	0.680
12.37	91.22	0.680
12.39	91.29	0.680
12.40	91.35	0.680
12.41	91.42	0.682
12.43	91.49	0.681
12.44	91.56	0.682
12.45	91.62	0.681
12.47	91.69	0.683
12.48	91.76	0.684
12.49	91.82	0.684
12.51	91.89	0.685
12.52	91.96	0.685
12.53	92.02	0.686
12.55	92.09	0.686
12.56	92.15	0.687
12.57	92.22	0.688
12.59	92.29	0.690
12.60	92.36	0.690
12.61	92.42	0.690
12.63	92.49	0.692
12.64	92.56	0.693
12.65	92.62	0.693
12.67	92.69	0.694
12.68	92.76	0.695
12.69	92.82	0.697
12.71	92.89	0.699
12.72	92.96	0.699
12.73	93.02	0.702
12.75	93.09	0.703
12.76	93.16	0.703
12.77	93.22	0.703
12.79	93.29	0.705
12.80	93.36	0.705
12.81	93.42	0.707
12.83	93.49	0.708
12.84	93.56	0.709
12.85	93.62	0.709
12.87	93.69	0.710
12.88	93.76	0.710
12.89	93.82	0.712
12.91	93.89	0.714
12.92	93.95	0.715
12.93	94.02	0.716
12.95	94.09	0.716
12.96	94.16	0.717
12.97	94.22	0.718
12.99	94.29	0.720
13.00	94.36	0.720
13.01	94.42	0.722
13.03	94.49	0.723
13.04	94.56	0.724
13.05	94.62	0.725
13.07	94.69	0.727
13.08	94.76	0.730
13.09	94.82	0.732
13.11	94.89	0.732
13.12	94.96	0.734
13.13	95.02	0.737
13.15	95.09	0.738
13.16	95.16	0.742
13.17	95.22	0.742
13.19	95.29	0.744
13.20	95.36	0.747
13.21	95.42	0.748
13.23	95.49	0.750
13.24	95.56	0.752
13.25	95.62	0.754
13.27	95.69	0.756
13.28	95.76	0.760
13.29	95.82	0.763
13.31	95.89	0.766
13.32	95.96	0.770
13.33	96.02	0.773
13.35	96.09	0.775
13.36	96.16	0.779
13.37	96.22	0.782
13.39	96.29	0.787
13.40	96.36	0.792
13.41	96.42	0.795
13.43	96.49	0.802
13.44	96.56	0.805
13.45	96.62	0.810
13.47	96.69	0.819
13.48	96.76	0.824
13.49	96.82	0.831
13.51	96.89	0.837
13.52	96.96	0.844
13.53	97.02	0.852
13.55	97.09	0.860
13.56	97.15	0.875
13.57	97.22	0.893
13.59	97.29	0.903
13.60	97.36	0.923
13.61	97.42	0.941
13.63	97.49	0.980
13.64	97.55	0.999
13.65	97.62	1.064
13.67	97.69	1.146
13.68	97.75	1.201
13.69	97.82	1.299
13.71	97.89	1.432
13.72	97.95	1.636
13.73	98.02	1.730
13.75	98.08	2.068
13.76	98.15	2.221
13.77	98.21	2.570
13.79	98.28	2.893
13.80	98.34	3.304
13.81	98.41	3.830
13.83	98.47	4.430
13.84	98.54	5.228
13.85	98.60	6.301
13.87	98.66	7.508
13.88	98.72	9.125
13.89	98.78	11.019
13.91	98.83	13.157
13.92	98.89	15.283
13.93	98.94	16.563
13.95	99.00	15.739
13.96	99.06	12.323
13.97	99.14	7.829
13.99	99.22	5.003
14.00	99.29	4.158
14.01	99.37	3.557
14.03	99.45	3.135
14.04	99.52	2.754
14.05	99.59	2.461
14.07	99.66	2.172
14.08	99.73	1.952
14.09	99.80	1.744
14.11	99.88	1.645
14.12	99.94	1.453
14.13	100.01	1.393
14.15	100.08	1.253
14.16	100.15	1.215
14.17	100.22	1.125
14.19	100.28	1.111
14.20	100.35	1.048
14.21	100.42	1.025
14.23	100.49	1.006
14.24	100.56	0.967
14.25	100.62	0.960
14.27	100.69	0.934
14.28	100.76	0.923
14.29	100.82	0.916
14.31	100.89	0.910
14.32	100.96	0.902
14.33	101.02	0.891
14.35	101.09	0.884
14.36	101.16	0.878
14.37	101.22	0.872
14.39	101.29	0.864
14.40	101.36	0.858
14.41	101.43	0.853
14.43	101.49	0.847
14.44	101.56	0.840
14.45	101.63	0.834
14.47	101.69	0.828
14.48	101.76	0.825
14.49	101.83	0.818
14.51	101.89	0.812
14.52	101.96	0.809
14.53	102.03	0.807
14.55	102.09	0.801
14.56	102.16	0.798
14.57	102.23	0.793
14.59	102.29	0.791
14.60	102.36	0.788
14.61	102.43	0.785
14.63	102.49	0.782
14.64	102.56	0.778
14.65	102.63	0.775
14.67	102.69	0.772
14.68	102.76	0.771
14.69	102.83	0.769
14.71	102.89	0.767
14.72	102.96	0.766
14.73	103.03	0.762
14.75	103.09	0.762
14.76	103.16	0.760
14.77	103.23	0.757
14.79	103.29	0.758
14.80	103.36	0.757
14.81	103.43	0.755
14.83	103.49	0.754
14.84	103.56	0.753
14.85	103.63	0.754
14.87	103.69	0.754
14.88	103.76	0.751
14.89	103.83	0.750
14.91	103.89	0.750
14.92	103.96	0.749
14.93	104.03	0.749
14.95	104.09	0.750
14.96	104.16	0.748
14.97	104.23	0.748
14.99	104.29	0.748
15.00	104.36	0.746
15.01	104.43	0.747
15.03	104.49	0.746
15.04	104.56	0.745
15.05	104.63	0.747
15.07	104.69	0.747
15.08	104.76	0.746
15.09	104.83	0.748
15.11	104.89	0.747
15.12	104.96	0.747
15.13	105.03	0.748
15.15	105.09	0.747
15.16	105.16	0.748
15.17	105.23	0.748
15.19	105.29	0.748
15.20	105.36	0.748
15.21	105.43	0.749
15.23	105.49	0.750
15.24	105.56	0.751
15.25	105.63	0.749
15.27	105.69	0.750
15.28	105.76	0.749
15.29	105.83	0.749
15.31	105.89	0.750
15.32	105.96	0.751
15.33	106.03	0.751
15.35	106.10	0.751
15.36	106.16	0.752
15.37	106.23	0.750
15.39	106.29	0.752
15.40	106.36	0.752
15.41	106.43	0.751
15.43	106.50	0.752
15.44	106.56	0.753
15.45	106.63	0.753
15.47	106.69	0.753
15.48	106.76	0.753
15.49	106.83	0.754
15.51	106.90	0.755
15.52	106.96	0.754
15.53	107.03	0.756
15.55	107.09	0.755
15.56	107.16	0.756
15.57	107.23	0.757
15.59	107.29	0.757
15.60	107.36	0.757
15.61	107.43	0.757
15.63	107.49	0.756
15.64	107.56	0.757
15.65	107.63	0.757
15.67	107.69	0.758
15.68	107.76	0.759
15.69	107.83	0.759
15.71	107.89	0.760
15.72	107.96	0.762
15.73	108.03	0.762
15.75	108.09	0.760
15.76	108.16	0.762
15.77	108.23	0.762
15.79	108.29	0.761
15.80	108.36	0.762
15.81	108.43	0.762
15.83	108.50	0.761
15.84	108.56	0.762
15.85	108.63	0.761
15.87	108.69	0.762
15.88	108.76	0.764
15.89	108.83	0.760
15.91	108.90	0.763
15.92	108.96	0.762
15.93	109.03	0.762
15.95	109.09	0.763
15.96	109.16	0.765
15.97	109.23	0.765
15.99	109.30	0.767
16.00	109.36	0.768
16.01	109.43	0.768
16.03	109.50	0.767
16.04	109.56	0.769
16.05	109.63	0.768
16.07	109.70	0.769
16.08	109.76	0.769
16.09	109.83	0.769
16.11	109.90	0.769
16.12	109.96	0.771
16.13	110.03	0.769
16.15	110.10	0.771
16.16	110.16	0.771
16.17	110.23	0.771
16.19	110.30	0.772
16.20	110.36	0.772
16.21	110.43	0.772
16.23	110.50	0.772
16.24	110.56	0.772
16.25	110.63	0.775
16.27	110.70	0.774
16.28	110.76	0.772
16.29	110.83	0.771
16.31	110.90	0.770
16.32	110.96	0.773
16.33	111.03	0.774
16.35	111.10	0.774
16.36	111.16	0.773
16.37	111.23	0.773
16.39	111.30	0.774
16.40	111.36	0.775
16.41	111.43	0.776
16.43	111.50	0.776
16.44	111.56	0.777
16.45	111.63	0.777
16.47	111.70	0.778
16.48	111.76	0.777
16.49	111.83	0.778
16.51	111.90	0.777
16.52	111.97	0.776
16.53	112.03	0.777
16.55	112.10	0.779
16.56	112.16	0.778
16.57	112.23	0.778
16.59	112.30	0.778
16.60	112.36	0.778
16.61	112.43	0.779
16.63	112.50	0.778
16.64	112.56	0.778
16.65	112.63	0.779
16.67	112.70	0.780
16.68	112.76	0.781
16.69	112.83	0.780
16.71	112.90	0.780
16.72	112.96	0.779
16.73	113.03	0.780
16.75	113.10	0.779
16.76	113.16	0.780
16.77	113.23	0.780
16.79	113.30	0.782
16.80	113.36	0.783
16.81	113.43	0.782
16.83	113.50	0.784
16.84	113.56	0.783
16.85	113.63	0.784
16.87	113.70	0.786
16.88	113.76	0.786
16.89	113.83	0.786
16.91	113.90	0.788
16.92	113.96	0.788
16.93	114.03	0.789
16.95	114.10	0.786
16.96	114.16	0.790
16.97	114.23	0.790
16.99	114.30	0.789
17.00	114.37	0.790
17.01	114.43	0.790
17.03	114.50	0.791
17.04	114.57	0.791
17.05	114.63	0.792
17.07	114.70	0.792
17.08	114.76	0.793
17.09	114.83	0.793
17.11	114.90	0.793
17.12	114.97	0.794
17.13	115.03	0.795
17.15	115.10	0.796
17.16	115.16	0.796
17.17	115.23	0.797
17.19	115.30	0.797
17.20	115.37	0.799
17.21	115.43	0.799
17.23	115.50	0.800
17.24	115.57	0.800
17.25	115.63	0.800
17.27	115.70	0.801
17.28	115.77	0.800
17.29	115.83	0.802
17.31	115.90	0.801
17.32	115.97	0.802
17.33	116.03	0.802
17.35	116.10	0.802
17.36	116.17	0.802
17.37	116.23	0.805
17.39	116.30	0.805
17.40	116.37	0.803
17.41	116.43	0.803
17.43	116.50	0.803
17.44	116.57	0.804
17.45	116.63	0.805
17.47	116.70	0.804
17.48	116.76	0.804
17.49	116.83	0.804
17.51	116.90	0.804
17.52	116.97	0.804
17.53	117.03	0.804
17.55	117.10	0.804
17.56	117.16	0.803
17.57	117.23	0.804
17.59	117.30	0.804
17.60	117.37	0.803
17.61	117.43	0.805
17.63	117.50	0.805
17.64	117.57	0.804
17.65	117.63	0.806
17.67	117.70	0.806
17.68	117.77	0.805
17.69	117.83	0.805
17.71	117.90	0.806
17.72	117.96	0.805
17.73	118.03	0.806
17.75	118.10	0.808
17.76	118.17	0.808
17.77	118.23	0.808
17.79	118.30	0.808
17.80	118.37	0.809
17.81	118.43	0.809
17.83	118.50	0.810
17.84	118.57	0.811
17.85	118.63	0.812
17.87	118.70	0.812
17.88	118.77	0.813
17.89	118.83	0.812
17.91	118.90	0.813
17.92	118.96	0.814
17.93	119.03	0.815
17.95	119.10
17.96	119.17
17.97	119.23
17.99	119.30
18.00
18.00