File: DSC/2025_04_21_CBG_Pro_MC_n60C_150C_5Cmin_x3.csv
Filename,2025_04_21_CBG_Pro_MC_n60C_150C_5Cmin_x3
Instrument name,DSC2A-00468 (192.168.1.100)
Operator,Yarger
rundate,4/21/2025
Sample name,2025_04_21_CBG_Pro_MC_n60C_150C_5Cmin_x3
proceduresegments,Data Off ; Equilibrate -60.00 °C; Data On ; Ramp 5.00 °C/min to 150.00 °C; Data Off ; Isothermal 1.0 min; Data On ; Ramp 10.00 °C/min to -60.00 °C; Data Off ; Isothermal 1.0 min; Data On ; Ramp 5.00 °C/min to 150.00 °C; Data Off ; Isothermal 1.0 min; Data On ; Ramp 10.00 °C/min to -60.00 °C; Data Off ; Isothermal 1.0 min; Data On ; Ramp 5.00 °C/min to 150.00 °C
[File Parameters]
Run date,4/21/2025 1:44:53 PM
Trios version,5.1.1.46572
Original File Name,
Current File Name,D:\DSC2500\JYarger\2025_04_21_CBG_Pro_MC_n60C_150C_5Cmin_x3.tri
[Procedure]
Procedure Name,CBG_Pro_n60_150C_5Cmin_x3
Sample Name,2025_04_21_CBG_Pro_MC_n60C_150C_5Cmin_x3
Sample Mass,4.85 mg
Reference Sample Mass,0 mg
Pan Mass,53.28 mg
Pan Number,16
Reference Pan Mass,52.66 mg
Reference Pan Number,19
Pan Type,Tzero Aluminum Hermetic
Comments,Al Hermetic DSC Consumables sealed Pan/Lid.
Project Name,CA
Operator,Yarger
Test,Custom
Unload Max Temperature,30
Unload Min Temperature,30
Load Max Temperature,30
Load Min Temperature,30
Stop on Gas Flow Error,Yes
[Signal List]
Signal #1,Time (min)
Signal #2,Temperature (°C)
Signal #3,Heat Flow (mW)
Signal #4,Delta T (µV)
Signal #5,Delta Tzero (µV)
Signal #6,Tzero Temperature (°C)
Signal #7,Cell Purge (mL/min)
Signal #8,Heater Temp (°C)
Signal #9,Power Delivered (W)
Signal #10,Reference Junction Temperature (°C)
Signal #11,Flange Temperature (°C)
Signal #12,Heat Flow Phase (rad)
Signal #13,Total Heat Capacity (J/°C)
Signal #14,Heat Capacity (J/°C)
[Configuration]
Company Name,ASU
Instrument Name,DSC2A-00468
Instrument Type,DSC2500
Serial Number,DSC2A-00468
IP,192.168.1.100
Location of Instrument,MRRC
DisplayType,Unknown
Sample Interval ,0.1 s/pt
Selected Heat Flow,T4P
Exotherm Direction,Down
Cell Serial,DRC2-00792
Lid Type,Standard
Cooler,RCS 90
Leave Cooler on at End of Sequence,On
Gas 2,Nitrogen
Gas Selected,Channel 1
Flow Rate,50 mL/min
Secondary Purge,On
Licensed Heat Flow,Heat Flow T4P
Modulation Licensed,Yes
[Versions]
Common IDD Version,1
Cortex Version,VER 2.10.2.31
Driver,5.0.0.6
GDM Version,1.0.3.3
TouchscreenVersion,1.0.0.16145
FEP Version,1.2.1.21
FEP Bootloader,2.0.0.5
AutoSampler Version,2.1.1.26
Auto Sampler Bootloader,2.0.0.5
FCM Version,1.1.0.3
FCM Bootloader,2.0.0.5
[Experiment Logs]
Experiment Log Entry # 1,Data On set to 0
Experiment Log Entry # 3,Equilibrate Segment -60 (C) Started
Experiment Log Entry # 5,Air Cool is off.
Experiment Log Entry # 7,Data On set to 1
Experiment Log Entry # 9,Ramp Segment 5 C/min to 150 Started
Experiment Log Entry # 11,Data On set to 0
Experiment Log Entry # 13,Isothermal Segment 1 min started
Experiment Log Entry # 15,Data On set to 1
Experiment Log Entry # 17,Ramp Segment 10 C/min to -60 Started
Experiment Log Entry # 19,Data On set to 0
Experiment Log Entry # 21,Isothermal Segment 1 min started
Experiment Log Entry # 23,Data On set to 1
Experiment Log Entry # 25,Ramp Segment 5 C/min to 150 Started
Experiment Log Entry # 27,Data On set to 0
Experiment Log Entry # 29,Isothermal Segment 1 min started
Experiment Log Entry # 31,Data On set to 1
Experiment Log Entry # 33,Ramp Segment 10 C/min to -60 Started
Experiment Log Entry # 35,Data On set to 0
Experiment Log Entry # 37,Isothermal Segment 1 min started
Experiment Log Entry # 39,Data On set to 1
Experiment Log Entry # 41,Ramp Segment 5 C/min to 150 Started
[Method Log]
Method Log Entry # 1,Data Off
Method Log Entry # 2,Equilibrate -60 °C
Method Log Entry # 3,Data On
Method Log Entry # 4,(Ramp 737989) Ramp 5 °C/minute to 150 °C
Method Log Entry # 5,Data Off
Method Log Entry # 6,Isothermal 1 minutes
Method Log Entry # 7,Data On
Method Log Entry # 8,(Ramp 737993) Ramp 10 °C/minute to -60 °C
Method Log Entry # 9,Data Off
Method Log Entry # 10,Isothermal 1 minutes
Method Log Entry # 11,Data On
Method Log Entry # 12,(Ramp 737997) Ramp 5 °C/minute to 150 °C
Method Log Entry # 13,Data Off
Method Log Entry # 14,Isothermal 1 minutes
Method Log Entry # 15,Data On
Method Log Entry # 16,(Ramp 738001) Ramp 10 °C/minute to -60 °C
Method Log Entry # 17,Data Off
Method Log Entry # 18,Isothermal 1 minutes
Method Log Entry # 19,Data On
Method Log Entry # 20,(Ramp 738005) Ramp 5 °C/minute to 150 °C
Cell Serial,DRC2-00792
[T1 Calibration]
Slope,-0.008529666
Offset,9.636258
Initial Temperature,98.23
GUID,f8bfdadc-4977-4fdf-ba6d-0ba9134940c3
[TZero Calibration]
Date Applied,11/29/2022 4:06:13 PM
Description,From -89.059 °C to 396.009 °C at 20.000°C/min
Gas Type,Nitrogen
Pan Type,None
Source Files 1,C:\Users\yargerlab\Desktop\DSC Data\General\TZero_calibration_11_29_22_2nd(2).tri
Source Files 2,C:\Users\yargerlab\Desktop\DSC Data\General\TZero_calibration_11_29_22_2nd(3).tri
Delta T Offset,13.05235
Delta T Slope,-0.007271007
Delta T0 Offset,-13.69128
Delta T0 Slope,0.06063341
[Temperature Calibration]
Date Applied,11/29/2022 7:12:28 PM
Description,From 106.590 °C to 186.590 °C at 10.000°C/min
Gas Type,Nitrogen
Pan Type,Tzero Aluminum Hermetic
Source Files 1,C:\Users\yargerlab\Desktop\DSC Data\General\Indium(6).tri
Measured 1,157.391
Known 1,156.598
[Cell Constant Calibration]
Date Applied,11/29/2022 7:12:29 PM
Description,From 106.590 °C to 186.590 °C at 10.000°C/min
Gas Type,Nitrogen
Pan Type,Tzero Aluminum Hermetic
Source Files 1,C:\Users\yargerlab\Desktop\DSC Data\General\Indium(6).tri
T4P KCell,1.006051
Onset Slope,63.26126 mW/°C
[Direct Cp Calibration]
Date Applied,11/30/2022 11:04:51 AM
Description,From -79.983 °C to 298.409 °C at 10.000°C/min
Gas Type,Nitrogen
Pan Type,Tzero Aluminum Hermetic
Source Files 1,C:\Users\yargerlab\Desktop\DSC Data\General\Sapphire_Heat_Capacity_11_30_22.tri
[Rev Cp Calibration]
Date Applied,11/30/2022 1:58:51 PM
Description,From -79.996 °C to 292.812 °C at 3.000°C/min
Gas Type,Nitrogen
Pan Type,Tzero Aluminum Hermetic
Source Files 1,C:\Users\yargerlab\Desktop\DSC Data\General\Sapphire_MDSC_Calibration_11_30_22.tri
[step]
Ramp 5.00 °C/min to 150.00 °C
Time,Temperature,Heat Flow (Normalized)
min,°C,W/g
0.00,-59.67,-0.078
0.03,-59.69,-0.076
0.06,-59.70,-0.067
0.08,-59.67,-0.066
0.11,-59.62,-0.066
0.14,-59.55,-0.057
0.17,-59.46,-0.036
0.20,-59.35,-0.013
0.23,-59.24,0.007
0.26,-59.12,0.022
0.28,-59.00,0.035
0.31,-58.88,0.047
0.34,-58.76,0.056
0.37,-58.63,0.065
0.40,-58.50,0.069
0.43,-58.37,0.074
0.45,-58.23,0.079
0.48,-58.10,0.082
0.51,-57.97,0.084
0.54,-57.83,0.086
0.57,-57.70,0.088
0.60,-57.56,0.089
0.62,-57.42,0.090
0.65,-57.28,0.090
0.68,-57.15,0.091
0.71,-57.01,0.092
0.74,-56.87,0.092
0.77,-56.73,0.093
0.79,-56.60,0.094
0.82,-56.46,0.094
0.85,-56.32,0.095
0.88,-56.18,0.095
0.91,-56.04,0.096
0.93,-55.90,0.096
0.96,-55.76,0.097
0.99,-55.62,0.097
1.02,-55.48,0.098
1.05,-55.34,0.098
1.08,-55.20,0.098
1.11,-55.06,0.099
1.13,-54.92,0.099
1.16,-54.78,0.099
1.19,-54.64,0.099
1.22,-54.50,0.100
1.25,-54.36,0.100
1.28,-54.22,0.100
1.30,-54.08,0.100
1.33,-53.94,0.100
1.36,-53.79,0.100
1.39,-53.65,0.100
1.42,-53.51,0.101
1.44,-53.37,0.101
1.47,-53.23,0.101
1.50,-53.09,0.101
1.53,-52.95,0.101
1.56,-52.81,0.101
1.59,-52.67,0.101
1.62,-52.53,0.101
1.64,-52.38,0.101
1.67,-52.24,0.101
1.70,-52.10,0.101
1.73,-51.96,0.101
1.76,-51.82,0.102
1.78,-51.68,0.102
1.81,-51.54,0.102
1.84,-51.39,0.102
1.87,-51.25,0.102
1.90,-51.11,0.102
1.93,-50.97,0.102
1.96,-50.83,0.102
1.98,-50.69,0.102
2.01,-50.55,0.102
2.04,-50.41,0.102
2.07,-50.26,0.102
2.10,-50.12,0.102
2.13,-49.98,0.102
2.15,-49.84,0.102
2.18,-49.70,0.102
2.21,-49.56,0.102
2.24,-49.41,0.102
2.27,-49.27,0.102
2.29,-49.13,0.102
2.32,-48.99,0.102
2.35,-48.85,0.102
2.38,-48.71,0.102
2.41,-48.57,0.102
2.44,-48.42,0.102
2.46,-48.28,0.102
2.49,-48.14,0.102
2.52,-48.00,0.102
2.55,-47.86,0.102
2.58,-47.72,0.102
2.61,-47.58,0.102
2.64,-47.44,0.102
2.66,-47.29,0.102
2.69,-47.15,0.102
2.72,-47.01,0.102
2.75,-46.87,0.102
2.78,-46.73,0.102
2.81,-46.59,0.102
2.83,-46.44,0.102
2.86,-46.30,0.102
2.89,-46.16,0.102
2.92,-46.02,0.102
2.95,-45.88,0.102
2.98,-45.74,0.102
3.00,-45.60,0.102
3.03,-45.45,0.102
3.06,-45.31,0.102
3.09,-45.17,0.102
3.12,-45.03,0.102
3.14,-44.89,0.102
3.17,-44.75,0.102
3.20,-44.60,0.102
3.23,-44.46,0.102
3.26,-44.32,0.102
3.29,-44.18,0.102
3.31,-44.04,0.102
3.34,-43.90,0.102
3.37,-43.75,0.102
3.40,-43.61,0.102
3.43,-43.47,0.102
3.46,-43.33,0.102
3.49,-43.19,0.102
3.51,-43.04,0.102
3.54,-42.90,0.102
3.57,-42.76,0.102
3.60,-42.62,0.102
3.63,-42.48,0.102
3.66,-42.34,0.102
3.68,-42.20,0.102
3.71,-42.05,0.102
3.74,-41.91,0.102
3.77,-41.77,0.102
3.80,-41.63,0.102
3.83,-41.49,0.102
3.85,-41.34,0.102
3.88,-41.20,0.102
3.91,-41.06,0.102
3.94,-40.92,0.102
3.97,-40.78,0.102
3.99,-40.63,0.102
4.02,-40.49,0.102
4.05,-40.35,0.102
4.08,-40.21,0.102
4.11,-40.07,0.102
4.14,-39.93,0.102
4.16,-39.78,0.102
4.19,-39.64,0.103
4.22,-39.50,0.103
4.25,-39.36,0.103
4.28,-39.22,0.103
4.31,-39.07,0.103
4.34,-38.93,0.103
4.36,-38.79,0.103
4.39,-38.65,0.103
4.42,-38.51,0.103
4.45,-38.37,0.103
4.48,-38.22,0.103
4.50,-38.08,0.103
4.53,-37.94,0.103
4.56,-37.80,0.103
4.59,-37.66,0.103
4.62,-37.51,0.103
4.65,-37.37,0.103
4.68,-37.23,0.103
4.70,-37.09,0.103
4.73,-36.95,0.103
4.76,-36.80,0.103
4.79,-36.66,0.103
4.82,-36.52,0.103
4.85,-36.38,0.103
4.87,-36.24,0.103
4.90,-36.09,0.103
4.93,-35.95,0.103
4.96,-35.81,0.103
4.99,-35.67,0.103
5.01,-35.53,0.103
5.04,-35.39,0.103
5.07,-35.25,0.103
5.10,-35.10,0.103
5.13,-34.96,0.103
5.16,-34.82,0.103
5.19,-34.68,0.103
5.21,-34.54,0.103
5.24,-34.39,0.103
5.27,-34.25,0.103
5.30,-34.11,0.103
5.33,-33.97,0.103
5.35,-33.83,0.104
5.38,-33.68,0.104
5.41,-33.54,0.104
5.44,-33.40,0.104
5.47,-33.26,0.104
5.50,-33.12,0.104
5.53,-32.98,0.104
5.55,-32.84,0.104
5.58,-32.69,0.104
5.61,-32.55,0.104
5.64,-32.41,0.104
5.67,-32.27,0.104
5.70,-32.13,0.104
5.72,-31.98,0.104
5.75,-31.84,0.104
5.78,-31.70,0.104
5.81,-31.56,0.104
5.84,-31.42,0.104
5.86,-31.27,0.104
5.89,-31.13,0.104
5.92,-30.99,0.104
5.95,-30.85,0.104
5.98,-30.71,0.104
6.01,-30.57,0.104
6.04,-30.42,0.104
6.06,-30.28,0.104
6.09,-30.14,0.104
6.12,-30.00,0.104
6.15,-29.86,0.104
6.18,-29.71,0.104
6.20,-29.57,0.105
6.23,-29.43,0.105
6.26,-29.29,0.105
6.29,-29.15,0.105
6.32,-29.01,0.105
6.35,-28.86,0.105
6.38,-28.72,0.105
6.40,-28.58,0.105
6.43,-28.44,0.105
6.46,-28.30,0.105
6.49,-28.16,0.105
6.52,-28.01,0.105
6.55,-27.87,0.105
6.57,-27.73,0.105
6.60,-27.59,0.105
6.63,-27.45,0.105
6.66,-27.30,0.105
6.69,-27.16,0.105
6.71,-27.02,0.105
6.74,-26.88,0.105
6.77,-26.74,0.105
6.80,-26.60,0.105
6.83,-26.45,0.105
6.86,-26.31,0.105
6.89,-26.17,0.106
6.91,-26.03,0.106
6.94,-25.89,0.106
6.97,-25.74,0.106
7.00,-25.60,0.106
7.03,-25.46,0.106
7.05,-25.32,0.106
7.08,-25.18,0.106
7.11,-25.04,0.106
7.14,-24.89,0.106
7.17,-24.75,0.106
7.20,-24.61,0.106
7.23,-24.47,0.106
7.25,-24.33,0.106
7.28,-24.18,0.106
7.31,-24.04,0.106
7.34,-23.90,0.106
7.37,-23.76,0.106
7.40,-23.62,0.106
7.42,-23.48,0.106
7.45,-23.33,0.107
7.48,-23.19,0.107
7.51,-23.05,0.107
7.54,-22.91,0.107
7.56,-22.77,0.107
7.59,-22.63,0.107
7.62,-22.48,0.107
7.65,-22.34,0.107
7.68,-22.20,0.107
7.71,-22.06,0.107
7.74,-21.92,0.107
7.76,-21.77,0.107
7.79,-21.63,0.107
7.82,-21.49,0.107
7.85,-21.35,0.107
7.88,-21.21,0.107
7.90,-21.07,0.107
7.93,-20.92,0.107
7.96,-20.78,0.107
7.99,-20.64,0.107
8.02,-20.50,0.107
8.05,-20.36,0.107
8.08,-20.22,0.107
8.10,-20.08,0.107
8.13,-19.93,0.108
8.16,-19.79,0.108
8.19,-19.65,0.108
8.22,-19.51,0.108
8.25,-19.37,0.108
8.27,-19.22,0.108
8.30,-19.08,0.108
8.33,-18.94,0.108
8.36,-18.80,0.108
8.39,-18.66,0.108
8.41,-18.51,0.108
8.44,-18.37,0.108
8.47,-18.23,0.108
8.50,-18.09,0.108
8.53,-17.95,0.108
8.56,-17.81,0.108
8.58,-17.66,0.108
8.61,-17.52,0.108
8.64,-17.38,0.108
8.67,-17.24,0.108
8.70,-17.10,0.108
8.73,-16.96,0.108
8.75,-16.81,0.108
8.78,-16.67,0.109
8.81,-16.53,0.109
8.84,-16.39,0.109
8.87,-16.25,0.109
8.90,-16.10,0.109
8.93,-15.96,0.109
8.95,-15.82,0.109
8.98,-15.68,0.109
9.01,-15.54,0.109
9.04,-15.40,0.109
9.07,-15.25,0.109
9.10,-15.11,0.109
9.12,-14.97,0.109
9.15,-14.83,0.109
9.18,-14.69,0.109
9.21,-14.54,0.109
9.24,-14.40,0.109
9.27,-14.26,0.109
9.29,-14.12,0.109
9.32,-13.98,0.109
9.35,-13.84,0.109
9.38,-13.69,0.110
9.41,-13.55,0.110
9.43,-13.41,0.110
9.46,-13.27,0.110
9.49,-13.13,0.110
9.52,-12.99,0.110
9.55,-12.85,0.110
9.58,-12.70,0.110
9.60,-12.56,0.110
9.63,-12.42,0.110
9.66,-12.28,0.110
9.69,-12.14,0.110
9.72,-11.99,0.110
9.75,-11.85,0.110
9.78,-11.71,0.110
9.80,-11.57,0.110
9.83,-11.43,0.110
9.86,-11.28,0.110
9.89,-11.14,0.110
9.92,-11.00,0.110
9.95,-10.86,0.110
9.97,-10.72,0.111
10.00,-10.57,0.111
10.03,-10.43,0.111
10.06,-10.29,0.111
10.09,-10.15,0.111
10.12,-10.01,0.111
10.14,-9.86,0.111
10.17,-9.72,0.111
10.20,-9.58,0.111
10.23,-9.44,0.111
10.26,-9.30,0.111
10.28,-9.16,0.111
10.31,-9.02,0.111
10.34,-8.87,0.111
10.37,-8.73,0.111
10.40,-8.59,0.111
10.43,-8.45,0.111
10.45,-8.31,0.111
10.48,-8.16,0.111
10.51,-8.02,0.112
10.54,-7.88,0.112
10.57,-7.74,0.112
10.60,-7.60,0.112
10.63,-7.46,0.112
10.65,-7.32,0.112
10.68,-7.17,0.112
10.71,-7.03,0.112
10.74,-6.89,0.112
10.77,-6.75,0.112
10.80,-6.60,0.112
10.82,-6.46,0.112
10.85,-6.32,0.112
10.88,-6.18,0.112
10.91,-6.04,0.112
10.94,-5.90,0.112
10.97,-5.75,0.112
10.99,-5.61,0.112
11.02,-5.47,0.112
11.05,-5.33,0.112
11.08,-5.19,0.112
11.11,-5.05,0.112
11.13,-4.90,0.112
11.16,-4.76,0.113
11.19,-4.62,0.113
11.22,-4.48,0.113
11.25,-4.34,0.113
11.28,-4.20,0.113
11.30,-4.05,0.113
11.33,-3.91,0.113
11.36,-3.77,0.113
11.39,-3.63,0.113
11.42,-3.48,0.113
11.45,-3.34,0.113
11.48,-3.20,0.113
11.50,-3.06,0.113
11.53,-2.92,0.113
11.56,-2.78,0.113
11.59,-2.64,0.113
11.62,-2.49,0.113
11.65,-2.35,0.113
11.67,-2.21,0.114
11.70,-2.07,0.114
11.73,-1.93,0.114
11.76,-1.78,0.114
11.79,-1.64,0.114
11.82,-1.50,0.114
11.84,-1.36,0.114
11.87,-1.22,0.114
11.90,-1.08,0.114
11.93,-0.93,0.114
11.96,-0.79,0.114
11.98,-0.65,0.114
12.01,-0.51,0.114
12.04,-0.37,0.114
12.07,-0.22,0.114
12.10,-0.08,0.115
12.13,0.06,0.115
12.15,0.20,0.115
12.18,0.34,0.115
12.21,0.48,0.115
12.24,0.63,0.115
12.27,0.77,0.115
12.30,0.91,0.115
12.33,1.05,0.115
12.35,1.19,0.115
12.38,1.33,0.115
12.41,1.48,0.115
12.44,1.62,0.115
12.47,1.76,0.115
12.50,1.90,0.115
12.52,2.04,0.115
12.55,2.19,0.115
12.58,2.33,0.116
12.61,2.47,0.116
12.64,2.61,0.116
12.67,2.75,0.116
12.69,2.89,0.116
12.72,3.04,0.116
12.75,3.18,0.116
12.78,3.32,0.116
12.81,3.46,0.116
12.83,3.60,0.116
12.86,3.74,0.116
12.89,3.89,0.116
12.92,4.03,0.116
12.95,4.17,0.116
12.98,4.31,0.116
13.00,4.45,0.116
13.03,4.60,0.116
13.06,4.74,0.116
13.09,4.88,0.116
13.12,5.02,0.117
13.15,5.16,0.117
13.18,5.30,0.117
13.20,5.45,0.117
13.23,5.59,0.117
13.26,5.73,0.117
13.29,5.87,0.117
13.32,6.01,0.117
13.35,6.15,0.117
13.37,6.30,0.117
13.40,6.44,0.117
13.43,6.58,0.117
13.46,6.72,0.117
13.49,6.86,0.117
13.52,7.00,0.117
13.54,7.15,0.118
13.57,7.29,0.118
13.60,7.43,0.118
13.63,7.57,0.118
13.66,7.71,0.118
13.68,7.86,0.118
13.71,8.00,0.118
13.74,8.14,0.118
13.77,8.28,0.118
13.80,8.42,0.118
13.83,8.56,0.118
13.85,8.71,0.118
13.88,8.85,0.118
13.91,8.99,0.118
13.94,9.13,0.118
13.97,9.27,0.118
14.00,9.41,0.118
14.03,9.56,0.118
14.05,9.70,0.118
14.08,9.84,0.118
14.11,9.98,0.119
14.14,10.12,0.119
14.17,10.26,0.119
14.20,10.41,0.119
14.22,10.55,0.119
14.25,10.69,0.119
14.28,10.83,0.119
14.31,10.97,0.119
14.34,11.12,0.119
14.37,11.26,0.119
14.39,11.40,0.119
14.42,11.54,0.119
14.45,11.68,0.119
14.48,11.82,0.119
14.51,11.97,0.120
14.53,12.11,0.120
14.56,12.25,0.120
14.59,12.39,0.120
14.62,12.53,0.120
14.65,12.67,0.120
14.68,12.82,0.120
14.70,12.96,0.120
14.73,13.10,0.120
14.76,13.24,0.120
14.79,13.38,0.120
14.82,13.53,0.120
14.85,13.67,0.120
14.88,13.81,0.120
14.90,13.95,0.120
14.93,14.09,0.121
14.96,14.23,0.121
14.99,14.38,0.121
15.02,14.52,0.121
15.05,14.66,0.121
15.07,14.80,0.121
15.10,14.94,0.121
15.13,15.08,0.121
15.16,15.23,0.121
15.19,15.37,0.121
15.22,15.51,0.121
15.24,15.65,0.121
15.27,15.79,0.121
15.30,15.93,0.121
15.33,16.08,0.121
15.36,16.22,0.122
15.38,16.36,0.122
15.41,16.50,0.122
15.44,16.64,0.122
15.47,16.78,0.122
15.50,16.93,0.122
15.53,17.07,0.122
15.55,17.21,0.122
15.58,17.35,0.122
15.61,17.49,0.122
15.64,17.64,0.122
15.67,17.78,0.122
15.70,17.92,0.122
15.73,18.06,0.123
15.75,18.20,0.123
15.78,18.35,0.123
15.81,18.49,0.123
15.84,18.63,0.123
15.87,18.77,0.123
15.90,18.91,0.123
15.92,19.05,0.123
15.95,19.20,0.123
15.98,19.34,0.123
16.01,19.48,0.123
16.04,19.62,0.123
16.07,19.76,0.123
16.09,19.90,0.124
16.12,20.05,0.124
16.15,20.19,0.124
16.18,20.33,0.124
16.21,20.47,0.124
16.23,20.61,0.124
16.26,20.75,0.124
16.29,20.90,0.124
16.32,21.04,0.124
16.35,21.18,0.124
16.38,21.32,0.124
16.40,21.46,0.124
16.43,21.60,0.124
16.46,21.74,0.124
16.49,21.89,0.124
16.52,22.03,0.124
16.55,22.17,0.124
16.58,22.31,0.125
16.60,22.45,0.125
16.63,22.60,0.125
16.66,22.74,0.125
16.69,22.88,0.125
16.72,23.02,0.125
16.75,23.16,0.125
16.77,23.31,0.125
16.80,23.45,0.125
16.83,23.59,0.125
16.86,23.73,0.126
16.89,23.87,0.126
16.92,24.01,0.126
16.94,24.16,0.126
16.97,24.30,0.126
17.00,24.44,0.126
17.03,24.58,0.126
17.06,24.72,0.126
17.08,24.86,0.126
17.11,25.01,0.126
17.14,25.15,0.126
17.17,25.29,0.126
17.20,25.43,0.127
17.23,25.57,0.127
17.26,25.72,0.127
17.28,25.86,0.127
17.31,26.00,0.127
17.34,26.14,0.127
17.37,26.28,0.127
17.40,26.42,0.127
17.43,26.57,0.127
17.45,26.71,0.127
17.48,26.85,0.127
17.51,26.99,0.127
17.54,27.13,0.128
17.57,27.28,0.128
17.59,27.42,0.128
17.62,27.56,0.128
17.65,27.70,0.128
17.68,27.84,0.128
17.71,27.98,0.128
17.74,28.13,0.128
17.77,28.27,0.128
17.79,28.41,0.128
17.82,28.55,0.128
17.85,28.69,0.128
17.88,28.83,0.128
17.91,28.98,0.128
17.93,29.12,0.129
17.96,29.26,0.129
17.99,29.40,0.129
18.02,29.54,0.129
18.05,29.68,0.129
18.08,29.83,0.129
18.11,29.97,0.129
18.13,30.11,0.129
18.16,30.25,0.129
18.19,30.39,0.129
18.22,30.53,0.129
18.25,30.68,0.129
18.28,30.82,0.129
18.30,30.96,0.130
18.33,31.10,0.130
18.36,31.24,0.130
18.39,31.39,0.130
18.42,31.53,0.130
18.44,31.67,0.130
18.47,31.81,0.130
18.50,31.95,0.130
18.53,32.09,0.131
18.56,32.24,0.131
18.59,32.38,0.131
18.62,32.52,0.131
18.64,32.66,0.131
18.67,32.80,0.131
18.70,32.94,0.131
18.73,33.09,0.131
18.76,33.23,0.131
18.78,33.37,0.131
18.81,33.51,0.132
18.84,33.65,0.132
18.87,33.80,0.132
18.90,33.94,0.132
18.93,34.08,0.132
18.96,34.22,0.132
18.98,34.36,0.132
19.01,34.50,0.132
19.04,34.65,0.132
19.07,34.79,0.133
19.10,34.93,0.133
19.13,35.07,0.133
19.15,35.21,0.133
19.18,35.35,0.133
19.21,35.49,0.133
19.24,35.64,0.133
19.27,35.78,0.133
19.29,35.92,0.133
19.32,36.06,0.134
19.35,36.20,0.134
19.38,36.35,0.134
19.41,36.49,0.134
19.44,36.63,0.134
19.47,36.77,0.134
19.49,36.91,0.134
19.52,37.05,0.135
19.55,37.20,0.135
19.58,37.34,0.135
19.61,37.48,0.135
19.63,37.62,0.135
19.66,37.76,0.135
19.69,37.90,0.135
19.72,38.05,0.136
19.75,38.19,0.136
19.78,38.33,0.136
19.81,38.47,0.136
19.83,38.61,0.136
19.86,38.75,0.136
19.89,38.90,0.137
19.92,39.04,0.137
19.95,39.18,0.137
19.98,39.32,0.137
20.00,39.46,0.137
20.03,39.61,0.137
20.06,39.75,0.138
20.09,39.89,0.138
20.12,40.03,0.138
20.14,40.17,0.138
20.17,40.31,0.138
20.20,40.46,0.138
20.23,40.60,0.139
20.26,40.74,0.139
20.29,40.88,0.139
20.32,41.02,0.139
20.34,41.16,0.139
20.37,41.31,0.140
20.40,41.45,0.140
20.43,41.59,0.140
20.46,41.73,0.141
20.48,41.87,0.141
20.51,42.01,0.141
20.54,42.16,0.141
20.57,42.30,0.142
20.60,42.44,0.142
20.63,42.58,0.142
20.66,42.72,0.143
20.68,42.86,0.143
20.71,43.01,0.143
20.74,43.15,0.144
20.77,43.29,0.144
20.80,43.43,0.144
20.83,43.57,0.145
20.85,43.71,0.145
20.88,43.85,0.146
20.91,44.00,0.146
20.94,44.14,0.146
20.97,44.28,0.147
20.99,44.42,0.147
21.02,44.56,0.148
21.05,44.71,0.149
21.08,44.85,0.149
21.11,44.99,0.150
21.14,45.13,0.151
21.17,45.27,0.151
21.19,45.41,0.152
21.22,45.55,0.153
21.25,45.70,0.153
21.28,45.84,0.154
21.31,45.98,0.155
21.33,46.12,0.156
21.36,46.26,0.156
21.39,46.40,0.158
21.42,46.54,0.159
21.45,46.69,0.160
21.48,46.83,0.161
21.51,46.97,0.163
21.53,47.11,0.165
21.56,47.25,0.166
21.59,47.39,0.169
21.62,47.53,0.171
21.65,47.67,0.174
21.68,47.82,0.177
21.70,47.96,0.181
21.73,48.10,0.185
21.76,48.24,0.188
21.79,48.38,0.192
21.82,48.52,0.197
21.84,48.66,0.202
21.87,48.80,0.207
21.90,48.94,0.212
21.93,49.08,0.219
21.96,49.22,0.226
21.99,49.36,0.233
22.02,49.50,0.241
22.04,49.64,0.249
22.07,49.78,0.258
22.10,49.92,0.270
22.13,50.05,0.281
22.16,50.19,0.295
22.18,50.33,0.309
22.21,50.47,0.327
22.24,50.60,0.345
22.27,50.74,0.365
22.30,50.87,0.389
22.33,51.01,0.416
22.36,51.14,0.446
22.38,51.27,0.482
22.41,51.40,0.522
22.44,51.53,0.570
22.47,51.66,0.619
22.50,51.79,0.666
22.53,51.91,0.705
22.55,52.04,0.743
22.58,52.17,0.784
22.61,52.29,0.833
22.64,52.42,0.874
22.67,52.55,0.917
22.69,52.68,0.962
22.72,52.80,1.017
22.75,52.93,1.072
22.78,53.04,1.145
22.81,53.17,1.142
22.84,53.30,1.248
22.87,53.42,1.242
22.89,53.56,1.165
22.92,53.72,1.096
22.95,53.88,1.010
22.98,54.04,0.947
23.01,54.20,0.930
23.03,54.35,0.934
23.06,54.49,0.948
23.09,54.63,0.973
23.12,54.77,1.012
23.15,54.90,1.081
23.18,55.03,1.151
23.21,55.14,1.268
23.23,55.26,1.348
23.26,55.37,1.469
23.29,55.48,1.517
23.32,55.60,1.541
23.35,55.73,1.565
23.38,55.85,1.627
23.40,55.98,1.601
23.43,56.13,1.539
23.46,56.28,1.451
23.49,56.45,1.336
23.52,56.62,1.202
23.54,56.80,1.060
23.57,56.98,0.929
23.60,57.17,0.785
23.63,57.36,0.640
23.66,57.55,0.510
23.69,57.73,0.419
23.72,57.91,0.355
23.74,58.08,0.308
23.77,58.24,0.276
23.80,58.40,0.249
23.83,58.55,0.229
23.86,58.70,0.216
23.88,58.85,0.204
23.91,59.00,0.197
23.94,59.14,0.189
23.97,59.29,0.185
24.00,59.43,0.182
24.03,59.58,0.180
24.06,59.72,0.178
24.08,59.86,0.176
24.11,60.01,0.176
24.14,60.15,0.175
24.17,60.29,0.174
24.20,60.43,0.174
24.23,60.58,0.173
24.25,60.72,0.173
24.28,60.86,0.173
24.31,61.00,0.172
24.34,61.14,0.172
24.37,61.28,0.171
24.39,61.43,0.171
24.42,61.57,0.171
24.45,61.71,0.171
24.48,61.85,0.170
24.51,61.99,0.170
24.54,62.14,0.170
24.57,62.28,0.170
24.59,62.42,0.170
24.62,62.56,0.170
24.65,62.70,0.170
24.68,62.84,0.169
24.71,62.99,0.169
24.73,63.13,0.169
24.76,63.27,0.169
24.79,63.41,0.169
24.82,63.55,0.169
24.85,63.69,0.169
24.88,63.84,0.169
24.91,63.98,0.169
24.93,64.12,0.169
24.96,64.26,0.169
24.99,64.40,0.169
25.02,64.54,0.169
25.05,64.69,0.169
25.08,64.83,0.169
25.10,64.97,0.169
25.13,65.11,0.169
25.16,65.26,0.169
25.19,65.40,0.169
25.22,65.54,0.169
25.24,65.68,0.169
25.27,65.82,0.169
25.30,65.96,0.169
25.33,66.11,0.170
25.36,66.25,0.170
25.39,66.39,0.170
25.42,66.53,0.170
25.44,66.67,0.170
25.47,66.81,0.170
25.50,66.95,0.170
25.53,67.10,0.170
25.56,67.24,0.170
25.58,67.38,0.170
25.61,67.52,0.170
25.64,67.66,0.170
25.67,67.81,0.170
25.70,67.95,0.170
25.73,68.09,0.170
25.76,68.23,0.170
25.78,68.37,0.170
25.81,68.51,0.170
25.84,68.66,0.170
25.87,68.80,0.170
25.90,68.94,0.170
25.93,69.08,0.170
25.95,69.22,0.170
25.98,69.36,0.170
26.01,69.51,0.170
26.04,69.65,0.170
26.07,69.79,0.170
26.09,69.93,0.170
26.12,70.07,0.170
26.15,70.22,0.170
26.18,70.36,0.170
26.21,70.50,0.170
26.24,70.64,0.170
26.27,70.78,0.170
26.29,70.92,0.170
26.32,71.07,0.170
26.35,71.21,0.170
26.38,71.35,0.170
26.41,71.49,0.170
26.43,71.63,0.170
26.46,71.78,0.170
26.49,71.92,0.171
26.52,72.06,0.170
26.55,72.20,0.171
26.58,72.34,0.171
26.61,72.48,0.171
26.63,72.63,0.171
26.66,72.77,0.171
26.69,72.91,0.171
26.72,73.05,0.171
26.75,73.19,0.171
26.78,73.33,0.171
26.80,73.48,0.171
26.83,73.62,0.171
26.86,73.76,0.171
26.89,73.90,0.171
26.92,74.04,0.171
26.94,74.18,0.171
26.97,74.33,0.171
27.00,74.47,0.171
27.03,74.61,0.171
27.06,74.75,0.171
27.09,74.89,0.171
27.12,75.03,0.171
27.14,75.18,0.171
27.17,75.32,0.171
27.20,75.46,0.171
27.23,75.60,0.171
27.26,75.74,0.171
27.28,75.89,0.171
27.31,76.03,0.171
27.34,76.17,0.171
27.37,76.31,0.171
27.40,76.45,0.171
27.43,76.59,0.171
27.46,76.74,0.171
27.48,76.88,0.171
27.51,77.02,0.171
27.54,77.16,0.171
27.57,77.30,0.171
27.60,77.45,0.171
27.63,77.59,0.171
27.65,77.73,0.171
27.68,77.87,0.171
27.71,78.01,0.171
27.74,78.15,0.171
27.77,78.29,0.171
27.79,78.44,0.171
27.82,78.58,0.170
27.85,78.72,0.170
27.88,78.86,0.170
27.91,79.00,0.170
27.94,79.15,0.170
27.97,79.29,0.170
27.99,79.43,0.170
28.02,79.57,0.170
28.05,79.71,0.170
28.08,79.86,0.170
28.11,80.00,0.170
28.13,80.14,0.170
28.16,80.28,0.170
28.19,80.42,0.170
28.22,80.56,0.170
28.25,80.71,0.170
28.28,80.85,0.170
28.31,80.99,0.170
28.33,81.13,0.170
28.36,81.27,0.170
28.39,81.41,0.170
28.42,81.56,0.170
28.45,81.70,0.169
28.48,81.84,0.169
28.50,81.98,0.169
28.53,82.12,0.169
28.56,82.27,0.169
28.59,82.41,0.169
28.62,82.55,0.169
28.64,82.69,0.169
28.67,82.83,0.169
28.70,82.97,0.169
28.73,83.11,0.169
28.76,83.26,0.169
28.79,83.40,0.169
28.82,83.54,0.168
28.84,83.68,0.168
28.87,83.82,0.168
28.90,83.97,0.168
28.93,84.11,0.168
28.96,84.25,0.168
28.98,84.39,0.168
29.01,84.53,0.168
29.04,84.67,0.167
29.07,84.82,0.167
29.10,84.96,0.167
29.13,85.10,0.167
29.16,85.24,0.167
29.18,85.39,0.167
29.21,85.53,0.167
29.24,85.67,0.167
29.27,85.81,0.166
29.30,85.95,0.166
29.33,86.09,0.166
29.35,86.23,0.166
29.38,86.38,0.166
29.41,86.52,0.166
29.44,86.66,0.166
29.47,86.80,0.165
29.49,86.94,0.165
29.52,87.08,0.165
29.55,87.23,0.165
29.58,87.37,0.165
29.61,87.51,0.165
29.64,87.65,0.165
29.67,87.79,0.164
29.69,87.94,0.164
29.72,88.08,0.164
29.75,88.22,0.164
29.78,88.36,0.164
29.81,88.50,0.164
29.83,88.65,0.163
29.86,88.79,0.163
29.89,88.93,0.163
29.92,89.07,0.163
29.95,89.21,0.163
29.98,89.35,0.163
30.01,89.50,0.162
30.03,89.64,0.162
30.06,89.78,0.162
30.09,89.92,0.162
30.12,90.06,0.161
30.15,90.21,0.161
30.18,90.35,0.161
30.20,90.49,0.161
30.23,90.63,0.161
30.26,90.77,0.160
30.29,90.92,0.160
30.32,91.06,0.160
30.34,91.20,0.160
30.37,91.34,0.159
30.40,91.48,0.159
30.43,91.62,0.159
30.46,91.77,0.159
30.49,91.91,0.158
30.52,92.05,0.158
30.54,92.19,0.158
30.57,92.33,0.158
30.60,92.47,0.157
30.63,92.62,0.157
30.66,92.76,0.157
30.68,92.90,0.156
30.71,93.04,0.156
30.74,93.18,0.156
30.77,93.33,0.155
30.80,93.47,0.155
30.83,93.61,0.155
30.86,93.75,0.155
30.88,93.89,0.154
30.91,94.04,0.154
30.94,94.18,0.154
30.97,94.32,0.153
31.00,94.46,0.153
31.03,94.60,0.152
31.05,94.75,0.152
31.08,94.89,0.152
31.11,95.03,0.151
31.14,95.17,0.151
31.17,95.31,0.151
31.19,95.45,0.150
31.22,95.60,0.150
31.25,95.74,0.149
31.28,95.88,0.149
31.31,96.02,0.149
31.34,96.16,0.148
31.37,96.31,0.148
31.39,96.45,0.147
31.42,96.59,0.147
31.45,96.73,0.147
31.48,96.87,0.146
31.51,97.01,0.146
31.53,97.16,0.145
31.56,97.30,0.145
31.59,97.44,0.145
31.62,97.58,0.144
31.65,97.72,0.144
31.68,97.87,0.143
31.71,98.01,0.143
31.73,98.15,0.143
31.76,98.29,0.142
31.79,98.43,0.142
31.82,98.58,0.141
31.85,98.72,0.141
31.88,98.86,0.141
31.90,99.00,0.140
31.93,99.14,0.140
31.96,99.28,0.139
31.99,99.43,0.139
32.02,99.57,0.139
32.04,99.71,0.138
32.07,99.85,0.138
32.10,99.99,0.137
32.13,100.14,0.137
32.16,100.28,0.137
32.19,100.42,0.136
32.22,100.56,0.136
32.24,100.70,0.135
32.27,100.84,0.135
32.30,100.99,0.135
32.33,101.13,0.134
32.36,101.27,0.134
32.38,101.41,0.134
32.41,101.55,0.133
32.44,101.70,0.133
32.47,101.84,0.132
32.50,101.98,0.132
32.53,102.12,0.132
32.56,102.26,0.131
32.58,102.40,0.131
32.61,102.55,0.131
32.64,102.69,0.131
32.67,102.83,0.130
32.70,102.97,0.130
32.73,103.11,0.130
32.75,103.26,0.130
32.78,103.40,0.129
32.81,103.54,0.129
32.84,103.68,0.129
32.87,103.82,0.129
32.89,103.96,0.129
32.92,104.11,0.128
32.95,104.25,0.128
32.98,104.39,0.128
33.01,104.53,0.128
33.04,104.67,0.128
33.07,104.81,0.128
33.09,104.96,0.128
33.12,105.10,0.128
33.15,105.24,0.128
33.18,105.38,0.128
33.21,105.53,0.128
33.23,105.67,0.128
33.26,105.81,0.128
33.29,105.95,0.128
33.32,106.10,0.128
33.35,106.24,0.128
33.38,106.38,0.128
33.41,106.52,0.128
33.43,106.66,0.128
33.46,106.80,0.128
33.49,106.94,0.128
33.52,107.09,0.128
33.55,107.23,0.128
33.58,107.37,0.128
33.60,107.51,0.128
33.63,107.65,0.128
33.66,107.79,0.128
33.69,107.93,0.128
33.72,108.08,0.128
33.74,108.22,0.128
33.77,108.36,0.129
33.80,108.50,0.129
33.83,108.64,0.129
33.86,108.78,0.129
33.89,108.93,0.129
33.92,109.07,0.130
33.94,109.21,0.130
33.97,109.35,0.130
34.00,109.49,0.130
34.03,109.63,0.131
34.06,109.78,0.131
34.08,109.92,0.131
34.11,110.06,0.132
34.14,110.20,0.132
34.17,110.34,0.132
34.20,110.48,0.133
34.23,110.62,0.133
34.26,110.77,0.134
34.28,110.91,0.134
34.31,111.05,0.134
34.34,111.19,0.135
34.37,111.33,0.135
34.40,111.47,0.136
34.43,111.61,0.136
34.45,111.76,0.137
34.48,111.90,0.137
34.51,112.04,0.137
34.54,112.18,0.138
34.57,112.32,0.138
34.59,112.47,0.139
34.62,112.61,0.139
34.65,112.75,0.140
34.68,112.89,0.140
34.71,113.03,0.141
34.74,113.17,0.141
34.76,113.31,0.142
34.79,113.46,0.142
34.82,113.60,0.143
34.85,113.74,0.143
34.88,113.88,0.144
34.91,114.02,0.144
34.94,114.16,0.145
34.96,114.30,0.145
34.99,114.45,0.146
35.02,114.59,0.146
35.05,114.73,0.147
35.08,114.87,0.147
35.11,115.01,0.148
35.13,115.15,0.148
35.16,115.30,0.149
35.19,115.44,0.149
35.22,115.58,0.150
35.25,115.72,0.150
35.28,115.86,0.151
35.30,116.00,0.151
35.33,116.14,0.152
35.36,116.29,0.152
35.39,116.43,0.153
35.42,116.57,0.153
35.44,116.71,0.154
35.47,116.85,0.154
35.50,116.99,0.155
35.53,117.14,0.156
35.56,117.28,0.156
35.59,117.42,0.157
35.61,117.56,0.157
35.64,117.70,0.158
35.67,117.84,0.158
35.70,117.99,0.159
35.73,118.13,0.159
35.76,118.27,0.160
35.79,118.41,0.161
35.81,118.55,0.161
35.84,118.69,0.162
35.87,118.83,0.162
35.90,118.98,0.163
35.93,119.12,0.163
35.96,119.26,0.164
35.98,119.40,0.164
36.01,119.54,0.165
36.04,119.68,0.165
36.07,119.83,0.166
36.10,119.97,0.166
36.13,120.11,0.167
36.15,120.25,0.167
36.18,120.39,0.168
36.21,120.53,0.168
36.24,120.67,0.169
36.27,120.82,0.170
36.29,120.96,0.170
36.32,121.10,0.171
36.35,121.24,0.171
36.38,121.38,0.172
36.41,121.52,0.172
36.44,121.67,0.173
36.46,121.81,0.173
36.49,121.95,0.174
36.52,122.09,0.174
36.55,122.23,0.174
36.58,122.37,0.175
36.61,122.52,0.175
36.64,122.66,0.176
36.66,122.80,0.176
36.69,122.94,0.177
36.72,123.08,0.177
36.75,123.22,0.178
36.78,123.36,0.178
36.81,123.51,0.178
36.83,123.65,0.179
36.86,123.79,0.179
36.89,123.93,0.180
36.92,124.07,0.180
36.95,124.21,0.180
36.98,124.36,0.181
37.00,124.50,0.181
37.03,124.64,0.182
37.06,124.78,0.182
37.09,124.92,0.183
37.12,125.06,0.183
37.14,125.20,0.183
37.17,125.35,0.184
37.20,125.49,0.186
37.23,125.63,0.186
37.26,125.77,0.186
37.29,125.91,0.187
37.31,126.05,0.187
37.34,126.20,0.188
37.37,126.34,0.188
37.40,126.48,0.189
37.43,126.62,0.189
37.46,126.76,0.189
37.49,126.91,0.190
37.51,127.05,0.190
37.54,127.19,0.190
37.57,127.33,0.190
37.60,127.47,0.191
37.63,127.61,0.191
37.66,127.76,0.191
37.68,127.90,0.191
37.71,128.04,0.192
37.74,128.18,0.192
37.77,128.32,0.192
37.80,128.46,0.192
37.83,128.60,0.192
37.85,128.75,0.192
37.88,128.89,0.193
37.91,129.03,0.193
37.94,129.17,0.193
37.97,129.31,0.193
37.99,129.45,0.193
38.02,129.60,0.193
38.05,129.74,0.193
38.08,129.88,0.193
38.11,130.02,0.194
38.14,130.16,0.194
38.16,130.31,0.194
38.19,130.45,0.194
38.22,130.59,0.194
38.25,130.73,0.194
38.28,130.87,0.194
38.31,131.01,0.194
38.34,131.16,0.194
38.36,131.30,0.195
38.39,131.44,0.195
38.42,131.58,0.195
38.45,131.72,0.195
38.48,131.86,0.195
38.51,132.01,0.195
38.53,132.15,0.195
38.56,132.29,0.195
38.59,132.43,0.195
38.62,132.57,0.195
38.65,132.71,0.195
38.68,132.86,0.195
38.70,133.00,0.196
38.73,133.14,0.196
38.76,133.28,0.196
38.79,133.42,0.196
38.82,133.56,0.196
38.84,133.71,0.196
38.87,133.85,0.196
38.90,133.99,0.196
38.93,134.13,0.196
38.96,134.27,0.196
38.99,134.41,0.196
39.01,134.56,0.196
39.04,134.70,0.196
39.07,134.84,0.196
39.10,134.98,0.196
39.13,135.12,0.196
39.16,135.26,0.197
39.19,135.41,0.197
39.21,135.55,0.197
39.24,135.69,0.197
39.27,135.83,0.197
39.30,135.97,0.197
39.33,136.11,0.197
39.36,136.26,0.197
39.38,136.40,0.197
39.41,136.54,0.197
39.44,136.68,0.198
39.47,136.82,0.198
39.50,136.96,0.198
39.53,137.11,0.198
39.55,137.25,0.198
39.58,137.39,0.198
39.61,137.53,0.198
39.64,137.67,0.199
39.67,137.82,0.199
39.69,137.96,0.199
39.72,138.10,0.199
39.75,138.24,0.199
39.78,138.38,0.199
39.81,138.53,0.199
39.84,138.67,0.199
39.86,138.81,0.199
39.89,138.95,0.199
39.92,139.09,0.199
39.95,139.23,0.199
39.98,139.37,0.199
40.01,139.51,0.199
40.04,139.66,0.199
40.06,139.80,0.199
40.09,139.94,0.200
40.12,140.08,0.200
40.15,140.22,0.200
40.18,140.37,0.200
40.21,140.51,0.200
40.23,140.65,0.200
40.26,140.79,0.200
40.29,140.93,0.200
40.32,141.07,0.200
40.35,141.22,0.200
40.38,141.36,0.200
40.40,141.50,0.200
40.43,141.64,0.200
40.46,141.78,0.200
40.49,141.93,0.201
40.52,142.07,0.201
40.54,142.21,0.201
40.57,142.35,0.201
40.60,142.49,0.201
40.63,142.63,0.201
40.66,142.77,0.201
40.69,142.91,0.201
40.71,143.06,0.201
40.74,143.20,0.201
40.77,143.34,0.201
40.80,143.48,0.201
40.83,143.62,0.201
40.86,143.77,0.201
40.89,143.91,0.201
40.91,144.05,0.201
40.94,144.19,0.201
40.97,144.33,0.202
41.00,144.47,0.202
41.03,144.62,0.202
41.06,144.76,0.202
41.08,144.90,0.202
41.11,145.04,0.202
41.14,145.18,0.202
41.17,145.32,0.202
41.20,145.47,0.202
41.23,145.61,0.202
41.25,145.75,0.202
41.28,145.89,0.202
41.31,146.03,0.202
41.34,146.17,0.203
41.37,146.32,0.203
41.39,146.46,0.203
41.42,146.60,0.203
41.45,146.74,0.203
41.48,146.88,0.203
41.51,147.02,0.203
41.54,147.17,0.203
41.56,147.31,0.203
41.59,147.45,0.203
41.62,147.59,0.203
41.65,147.73,0.204
41.68,147.87,0.204
41.71,148.02,0.204
41.74,148.16,0.204
41.76,148.30,0.204
41.79,148.44,0.204
41.82,148.58,0.204
41.85,148.73,0.204
41.88,148.87,0.205
41.91,149.01,0.205
41.93,149.15,
41.96,149.29,
41.99,,

[step]
Ramp 10.00 °C/min to -60.00 °C
Time,Temperature,Heat Flow (Normalized)
min,°C,W/g
42.99,150.12,-0.047
43.00,150.12,-0.047
43.02,150.11,-0.047
43.03,150.11,-0.047
43.05,150.10,-0.047
43.06,150.07,-0.045
43.08,150.04,-0.045
43.09,149.99,-0.057
43.11,149.92,-0.088
43.12,149.84,-0.126
43.14,149.75,-0.169
43.15,149.65,-0.215
43.17,149.55,-0.258
43.18,149.43,-0.295
43.20,149.32,-0.328
43.21,149.19,-0.358
43.23,149.07,-0.381
43.24,148.94,-0.402
43.26,148.81,-0.420
43.27,148.68,-0.433
43.29,148.54,-0.449
43.30,148.40,-0.461
43.32,148.26,-0.469
43.33,148.13,-0.478
43.35,147.98,-0.486
43.36,147.84,-0.493
43.38,147.70,-0.497
43.39,147.56,-0.504
43.41,147.41,-0.506
43.42,147.27,-0.510
43.44,147.12,-0.513
43.45,146.98,-0.515
43.47,146.83,-0.518
43.48,146.69,-0.518
43.50,146.54,-0.520
43.51,146.39,-0.521
43.53,146.25,-0.521
43.54,146.10,-0.523
43.56,145.95,-0.524
43.57,145.80,-0.524
43.59,145.66,-0.524
43.60,145.51,-0.525
43.62,145.36,-0.525
43.63,145.21,-0.525
43.65,145.06,-0.525
43.66,144.91,-0.525
43.68,144.77,-0.526
43.69,144.62,-0.526
43.71,144.47,-0.526
43.72,144.32,-0.526
43.74,144.17,-0.526
43.75,144.02,-0.526
43.77,143.87,-0.526
43.78,143.72,-0.526
43.80,143.58,-0.526
43.81,143.43,-0.526
43.83,143.28,-0.526
43.84,143.13,-0.525
43.86,142.98,-0.525
43.87,142.83,-0.525
43.89,142.68,-0.525
43.90,142.53,-0.525
43.92,142.38,-0.524
43.93,142.24,-0.524
43.95,142.09,-0.524
43.96,141.94,-0.524
43.98,141.79,-0.523
43.99,141.64,-0.523
44.01,141.49,-0.523
44.02,141.34,-0.523
44.04,141.19,-0.522
44.05,141.04,-0.522
44.07,140.89,-0.522
44.08,140.74,-0.521
44.10,140.60,-0.521
44.11,140.44,-0.521
44.13,140.30,-0.520
44.14,140.15,-0.520
44.16,140.00,-0.520
44.17,139.85,-0.519
44.19,139.70,-0.519
44.20,139.55,-0.518
44.22,139.40,-0.518
44.23,139.25,-0.518
44.25,139.10,-0.517
44.26,138.95,-0.517
44.28,138.80,-0.517
44.29,138.65,-0.516
44.31,138.50,-0.516
44.32,138.35,-0.515
44.34,138.20,-0.515
44.35,138.05,-0.515
44.37,137.90,-0.514
44.38,137.75,-0.514
44.40,137.60,-0.513
44.41,137.46,-0.513
44.43,137.30,-0.513
44.44,137.15,-0.512
44.46,137.01,-0.512
44.47,136.86,-0.511
44.49,136.71,-0.511
44.50,136.56,-0.510
44.52,136.41,-0.510
44.53,136.26,-0.510
44.55,136.11,-0.509
44.56,135.96,-0.509
44.58,135.81,-0.509
44.59,135.66,-0.508
44.61,135.51,-0.508
44.62,135.36,-0.507
44.64,135.21,-0.507
44.65,135.06,-0.507
44.67,134.91,-0.506
44.68,134.76,-0.506
44.70,134.61,-0.505
44.71,134.46,-0.505
44.73,134.31,-0.504
44.74,134.16,-0.504
44.76,134.01,-0.504
44.77,133.86,-0.503
44.79,133.71,-0.503
44.80,133.56,-0.503
44.82,133.41,-0.502
44.83,133.26,-0.502
44.85,133.11,-0.501
44.86,132.96,-0.501
44.88,132.81,-0.501
44.89,132.66,-0.500
44.91,132.51,-0.500
44.92,132.36,-0.500
44.94,132.21,-0.499
44.95,132.06,-0.499
44.97,131.91,-0.498
44.98,131.76,-0.498
45.00,131.61,-0.498
45.01,131.46,-0.497
45.03,131.31,-0.497
45.04,131.16,-0.497
45.06,131.01,-0.497
45.07,130.86,-0.496
45.09,130.71,-0.496
45.10,130.56,-0.495
45.12,130.41,-0.495
45.13,130.26,-0.495
45.15,130.11,-0.495
45.16,129.97,-0.494
45.18,129.81,-0.494
45.19,129.66,-0.493
45.21,129.51,-0.493
45.22,129.36,-0.493
45.24,129.22,-0.493
45.25,129.07,-0.492
45.27,128.91,-0.492
45.28,128.77,-0.492
45.30,128.62,-0.491
45.31,128.47,-0.491
45.33,128.32,-0.491
45.34,128.17,-0.490
45.36,128.02,-0.490
45.37,127.87,-0.490
45.39,127.72,-0.490
45.40,127.57,-0.489
45.42,127.42,-0.489
45.43,127.27,-0.489
45.45,127.12,-0.488
45.46,126.97,-0.488
45.48,126.82,-0.487
45.49,126.67,-0.487
45.51,126.52,-0.487
45.52,126.37,-0.487
45.54,126.22,-0.486
45.55,126.07,-0.486
45.57,125.92,-0.486
45.58,125.77,-0.485
45.60,125.62,-0.485
45.61,125.47,-0.485
45.63,125.32,-0.485
45.64,125.17,-0.484
45.66,125.02,-0.484
45.67,124.87,-0.484
45.69,124.72,-0.483
45.70,124.57,-0.483
45.72,124.42,-0.483
45.73,124.27,-0.483
45.75,124.12,-0.482
45.76,123.97,-0.482
45.78,123.82,-0.482
45.79,123.67,-0.482
45.81,123.52,-0.481
45.82,123.37,-0.481
45.84,123.22,-0.480
45.85,123.07,-0.480
45.87,122.92,-0.480
45.88,122.77,-0.480
45.90,122.62,-0.480
45.91,122.47,-0.479
45.93,122.32,-0.479
45.94,122.17,-0.479
45.96,122.02,-0.478
45.97,121.87,-0.478
45.99,121.72,-0.478
46.00,121.57,-0.478
46.02,121.42,-0.478
46.03,121.27,-0.477
46.05,121.12,-0.477
46.06,120.97,-0.477
46.08,120.82,-0.477
46.09,120.67,-0.476
46.11,120.52,-0.476
46.12,120.37,-0.476
46.14,120.22,-0.475
46.15,120.07,-0.475
46.17,119.92,-0.475
46.18,119.77,-0.475
46.20,119.62,-0.475
46.21,119.47,-0.474
46.23,119.32,-0.474
46.24,119.17,-0.474
46.26,119.02,-0.474
46.27,118.87,-0.473
46.29,118.72,-0.473
46.30,118.57,-0.473
46.32,118.42,-0.473
46.33,118.27,-0.473
46.35,118.12,-0.472
46.36,117.97,-0.472
46.38,117.82,-0.472
46.39,117.67,-0.472
46.41,117.52,-0.471
46.42,117.37,-0.471
46.44,117.22,-0.471
46.45,117.07,-0.470
46.47,116.92,-0.470
46.48,116.77,-0.470
46.50,116.62,-0.470
46.51,116.48,-0.470
46.53,116.33,-0.470
46.54,116.18,-0.469
46.56,116.03,-0.469
46.57,115.88,-0.469
46.59,115.73,-0.469
46.60,115.58,-0.469
46.62,115.43,-0.468
46.63,115.28,-0.468
46.65,115.13,-0.468
46.66,114.98,-0.468
46.68,114.83,-0.468
46.69,114.68,-0.467
46.71,114.53,-0.467
46.72,114.38,-0.467
46.74,114.23,-0.467
46.75,114.08,-0.467
46.77,113.93,-0.467
46.78,113.78,-0.466
46.80,113.63,-0.466
46.81,113.48,-0.466
46.83,113.33,-0.466
46.84,113.18,-0.466
46.86,113.03,-0.466
46.87,112.88,-0.465
46.89,112.73,-0.465
46.90,112.58,-0.465
46.92,112.43,-0.465
46.93,112.28,-0.464
46.95,112.13,-0.464
46.96,111.98,-0.464
46.98,111.83,-0.464
46.99,111.68,-0.464
47.01,111.53,-0.464
47.02,111.38,-0.463
47.04,111.23,-0.463
47.05,111.08,-0.463
47.07,110.93,-0.463
47.08,110.78,-0.463
47.10,110.63,-0.463
47.11,110.48,-0.462
47.13,110.33,-0.462
47.14,110.18,-0.462
47.16,110.03,-0.462
47.17,109.88,-0.462
47.19,109.73,-0.462
47.20,109.58,-0.461
47.22,109.43,-0.461
47.23,109.28,-0.461
47.25,109.13,-0.461
47.26,108.98,-0.461
47.28,108.83,-0.460
47.29,108.68,-0.460
47.31,108.53,-0.460
47.32,108.38,-0.460
47.34,108.23,-0.460
47.35,108.08,-0.460
47.37,107.93,-0.460
47.38,107.78,-0.459
47.40,107.63,-0.459
47.41,107.48,-0.459
47.43,107.33,-0.459
47.44,107.18,-0.459
47.46,107.03,-0.459
47.47,106.88,-0.459
47.49,106.73,-0.458
47.50,106.58,-0.458
47.52,106.43,-0.458
47.53,106.28,-0.458
47.55,106.13,-0.458
47.56,105.98,-0.458
47.58,105.84,-0.458
47.59,105.69,-0.457
47.61,105.54,-0.457
47.62,105.39,-0.457
47.64,105.24,-0.457
47.65,105.09,-0.457
47.67,104.94,-0.456
47.68,104.79,-0.456
47.70,104.64,-0.456
47.71,104.49,-0.456
47.73,104.34,-0.456
47.74,104.19,-0.456
47.76,104.04,-0.456
47.77,103.89,-0.455
47.79,103.74,-0.455
47.80,103.59,-0.455
47.82,103.44,-0.455
47.83,103.29,-0.455
47.85,103.14,-0.455
47.86,102.99,-0.455
47.88,102.84,-0.455
47.89,102.69,-0.454
47.91,102.54,-0.454
47.92,102.39,-0.454
47.94,102.24,-0.454
47.95,102.09,-0.454
47.97,101.94,-0.454
47.98,101.79,-0.454
48.00,101.64,-0.453
48.01,101.49,-0.453
48.03,101.34,-0.453
48.04,101.19,-0.453
48.06,101.04,-0.453
48.07,100.89,-0.453
[...]
142.65,2.63,0.129
142.68,2.78,0.129
142.71,2.92,0.129
142.74,3.06,0.129
142.77,3.20,0.129
142.79,3.34,0.129
142.82,3.48,0.130
142.85,3.63,0.130
142.88,3.77,0.130
142.91,3.91,0.130
142.93,4.05,0.130
142.96,4.19,0.130
142.99,4.33,0.130
143.02,4.47,0.131
143.05,4.62,0.131
143.08,4.76,0.131
143.10,4.90,0.131
143.13,5.04,0.131
143.16,5.18,0.131
143.19,5.32,0.131
143.22,5.47,0.132
143.25,5.61,0.132
143.28,5.75,0.132
143.30,5.89,0.132
143.33,6.03,0.133
143.36,6.17,0.133
143.39,6.31,0.133
143.42,6.46,0.133
143.45,6.60,0.133
143.47,6.74,0.133
143.50,6.88,0.134
143.53,7.02,0.134
143.56,7.17,0.134
143.59,7.31,0.134
143.62,7.45,0.135
143.64,7.59,0.135
143.67,7.73,0.135
143.70,7.88,0.135
143.73,8.02,0.135
143.76,8.16,0.136
143.78,8.30,0.136
143.81,8.44,0.136
143.84,8.58,0.136
143.87,8.72,0.136
143.90,8.86,0.137
143.93,9.01,0.137
143.95,9.15,0.137
143.98,9.29,0.137
144.01,9.43,0.138
144.04,9.57,0.138
144.07,9.71,0.138
144.10,9.86,0.138
144.13,10.00,0.139
144.15,10.14,0.139
144.18,10.28,0.139
144.21,10.42,0.140
144.24,10.57,0.140
144.27,10.71,0.140
144.30,10.85,0.141
144.32,10.99,0.141
144.35,11.13,0.141
144.38,11.27,0.142
144.41,11.42,0.142
144.44,11.56,0.142
144.47,11.70,0.143
144.49,11.84,0.143
144.52,11.98,0.143
144.55,12.12,0.144
144.58,12.27,0.144
144.61,12.41,0.144
144.63,12.55,0.145
144.66,12.69,0.145
144.69,12.83,0.145
144.72,12.98,0.146
144.75,13.12,0.146
144.78,13.26,0.146
144.80,13.40,0.147
144.83,13.54,0.147
144.86,13.68,0.148
144.89,13.83,0.148
144.92,13.97,0.148
144.95,14.11,0.149
144.98,14.25,0.149
145.00,14.39,0.149
145.03,14.53,0.150
145.06,14.68,0.150
145.09,14.82,0.151
145.12,14.96,0.151
145.15,15.10,0.152
145.17,15.24,0.152
145.20,15.38,0.153
145.23,15.53,0.153
145.26,15.67,0.154
145.29,15.81,0.154
145.32,15.95,0.155
145.34,16.09,0.155
145.37,16.23,0.156
145.40,16.38,0.156
145.43,16.52,0.156
145.46,16.66,0.157
145.48,16.80,0.158
145.51,16.94,0.158
145.54,17.08,0.159
145.57,17.22,0.159
145.60,17.37,0.160
145.63,17.51,0.160
145.65,17.65,0.161
145.68,17.79,0.162
145.71,17.93,0.162
145.74,18.07,0.163
145.77,18.22,0.163
145.80,18.36,0.164
145.83,18.50,0.165
145.85,18.64,0.166
145.88,18.78,0.166
145.91,18.92,0.167
145.94,19.06,0.168
145.97,19.21,0.169
146.00,19.35,0.169
146.02,19.49,0.170
146.05,19.63,0.171
146.08,19.77,0.172
146.11,19.91,0.173
146.14,20.06,0.174
146.17,20.20,0.174
146.19,20.34,0.175
146.22,20.48,0.176
146.25,20.62,0.177
146.28,20.77,0.178
146.31,20.91,0.180
146.33,21.05,0.183
146.36,21.19,0.184
146.39,21.33,0.185
146.42,21.47,0.186
146.45,21.62,0.186
146.48,21.76,0.187
146.50,21.90,0.188
146.53,22.04,0.190
146.56,22.18,0.191
146.59,22.32,0.192
146.62,22.46,0.194
146.65,22.60,0.195
146.68,22.74,0.197
146.70,22.89,0.199
146.73,23.03,0.200
146.76,23.17,0.203
146.79,23.31,0.205
146.82,23.45,0.207
146.85,23.59,0.209
146.87,23.73,0.212
146.90,23.87,0.215
146.93,24.01,0.217
146.96,24.15,0.220
146.99,24.29,0.222
147.02,24.43,0.225
147.04,24.57,0.228
147.07,24.71,0.231
147.10,24.86,0.234
147.13,25.00,0.237
147.16,25.14,0.239
147.18,25.28,0.243
147.21,25.42,0.246
147.24,25.56,0.251
147.27,25.70,0.254
147.30,25.84,0.258
147.33,25.98,0.262
147.35,26.12,0.264
147.38,26.26,0.268
147.41,26.40,0.273
147.44,26.54,0.276
147.47,26.68,0.280
147.50,26.82,0.283
147.53,26.96,0.288
147.55,27.10,0.293
147.58,27.24,0.297
147.61,27.38,0.302
147.64,27.53,0.305
147.67,27.67,0.312
147.70,27.81,0.316
147.72,27.94,0.321
147.75,28.09,0.326
147.78,28.23,0.331
147.81,28.37,0.337
147.84,28.51,0.341
147.87,28.65,0.347
147.89,28.78,0.352
147.92,28.92,0.358
147.95,29.07,0.363
147.98,29.20,0.368
148.01,29.35,0.374
148.03,29.49,0.378
148.06,29.63,0.382
148.09,29.77,0.386
148.12,29.91,0.390
148.15,30.05,0.392
148.18,30.19,0.394
148.20,30.33,0.395
148.23,30.47,0.396
148.26,30.61,0.396
148.29,30.75,0.395
148.32,30.90,0.389
148.35,31.04,0.378
148.38,31.18,0.366
148.40,31.33,0.350
148.43,31.47,0.331
148.46,31.62,0.309
148.49,31.77,0.286
148.52,31.92,0.257
148.55,32.07,0.224
148.57,32.23,0.190
148.60,32.38,0.151
148.63,32.53,0.109
148.66,32.69,0.066
148.69,32.84,0.022
148.72,33.00,-0.018
148.74,33.16,-0.054
148.77,33.31,-0.081
148.80,33.46,-0.100
148.83,33.61,-0.113
148.86,33.76,-0.118
148.88,33.91,-0.120
148.91,34.05,-0.120
148.94,34.20,-0.118
148.97,34.34,-0.114
149.00,34.48,-0.107
149.03,34.62,-0.098
149.05,34.76,-0.089
149.08,34.90,-0.079
149.11,35.03,-0.070
149.14,35.17,-0.062
149.17,35.31,-0.054
149.20,35.45,-0.046
149.23,35.59,-0.037
149.25,35.73,-0.028
149.28,35.87,-0.020
149.31,36.01,-0.013
149.34,36.14,-0.005
149.37,36.28,0.002
149.40,36.42,0.011
149.42,36.56,0.018
149.45,36.70,0.024
149.48,36.84,0.031
149.51,36.98,0.038
149.54,37.12,0.045
149.57,37.26,0.050
149.59,37.40,0.058
149.62,37.54,0.063
149.65,37.68,0.069
149.68,37.82,0.075
149.71,37.96,0.080
149.73,38.10,0.087
149.76,38.24,0.091
149.79,38.38,0.098
149.82,38.52,0.102
149.85,38.65,0.107
149.88,38.79,0.113
149.90,38.93,0.118
149.93,39.07,0.124
149.96,39.21,0.128
149.99,39.35,0.133
150.02,39.49,0.138
150.05,39.63,0.143
150.08,39.77,0.147
150.10,39.91,0.152
150.13,40.05,0.157
150.16,40.20,0.162
150.19,40.33,0.166
150.22,40.48,0.171
150.25,40.62,0.176
150.27,40.76,0.180
150.30,40.90,0.184
150.33,41.04,0.189
150.36,41.18,0.194
150.39,41.32,0.198
150.42,41.46,0.203
150.44,41.60,0.208
150.47,41.74,0.213
150.50,41.88,0.218
150.53,42.02,0.222
150.56,42.16,0.228
150.58,42.30,0.235
150.61,42.44,0.239
150.64,42.58,0.244
150.67,42.72,0.249
150.70,42.86,0.255
150.73,43.00,0.262
150.75,43.14,0.268
150.78,43.28,0.274
150.81,43.42,0.283
150.84,43.55,0.288
150.87,43.69,0.294
150.90,43.83,0.303
150.93,43.97,0.311
150.95,44.11,0.318
150.98,44.25,0.328
151.01,44.39,0.338
151.04,44.53,0.346
151.07,44.67,0.357
151.10,44.80,0.367
151.12,44.94,0.378
151.15,45.08,0.391
151.18,45.22,0.403
151.21,45.36,0.414
151.24,45.49,0.428
151.27,45.63,0.443
151.29,45.77,0.458
151.32,45.91,0.473
151.35,46.04,0.488
151.38,46.18,0.505
151.41,46.32,0.522
151.43,46.45,0.539
151.46,46.59,0.558
151.49,46.72,0.577
151.52,46.86,0.596
151.55,46.99,0.616
151.58,47.13,0.633
151.60,47.26,0.652
151.63,47.40,0.668
151.66,47.54,0.682
151.69,47.67,0.691
151.72,47.81,0.693
151.75,47.95,0.689
151.78,48.09,0.670
151.80,48.24,0.644
151.83,48.39,0.608
151.86,48.54,0.562
151.89,48.69,0.508
151.92,48.85,0.445
151.95,49.02,0.380
151.97,49.18,0.319
152.00,49.34,0.276
152.03,49.50,0.246
152.06,49.65,0.226
152.09,49.80,0.211
152.12,49.95,0.201
152.14,50.10,0.194
152.17,50.24,0.187
152.20,50.39,0.182
152.23,50.53,0.180
152.26,50.68,0.177
152.28,50.82,0.176
152.31,50.96,0.175
152.34,51.11,0.174
152.37,51.25,0.173
152.40,51.39,0.172
152.43,51.53,0.172
152.45,51.67,0.171
152.48,51.81,0.171
152.51,51.96,0.171
152.54,52.10,0.170
152.57,52.24,0.170
152.60,52.38,0.170
152.63,52.52,0.170
152.65,52.67,0.169
152.68,52.81,0.169
152.71,52.95,0.169
152.74,53.09,0.169
152.77,53.23,0.169
152.80,53.37,0.169
152.82,53.52,0.169
152.85,53.66,0.169
152.88,53.80,0.169
152.91,53.94,0.169
152.94,54.08,0.168
152.97,54.23,0.168
152.99,54.37,0.168
153.02,54.51,0.168
153.05,54.65,0.168
153.08,54.79,0.168
153.11,54.94,0.168
153.13,55.08,0.168
153.16,55.22,0.169
153.19,55.36,0.169
153.22,55.50,0.169
153.25,55.64,0.169
153.28,55.79,0.169
153.30,55.93,0.169
153.33,56.07,0.169
153.36,56.21,0.169
153.39,56.35,0.169
153.42,56.49,0.169
153.45,56.63,0.169
153.48,56.78,0.169
153.50,56.92,0.169
153.53,57.06,0.169
153.56,57.20,0.169
153.59,57.34,0.169
153.62,57.49,0.169
153.65,57.63,0.169
153.67,57.77,0.169
153.70,57.91,0.169
153.73,58.05,0.170
153.76,58.20,0.170
153.79,58.34,0.170
153.82,58.48,0.170
153.84,58.62,0.170
153.87,58.76,0.170
153.90,58.90,0.170
153.93,59.05,0.170
153.96,59.19,0.170
153.98,59.33,0.170
154.01,59.47,0.170
154.04,59.61,0.170
154.07,59.75,0.170
154.10,59.90,0.170
154.13,60.04,0.170
154.15,60.18,0.170
154.18,60.32,0.170
154.21,60.46,0.170
154.24,60.60,0.170
154.27,60.75,0.170
154.30,60.89,0.170
154.33,61.03,0.171
154.35,61.17,0.171
154.38,61.31,0.171
154.41,61.46,0.171
154.44,61.60,0.171
154.47,61.74,0.171
154.50,61.88,0.171
154.52,62.02,0.171
154.55,62.16,0.171
154.58,62.31,0.171
154.61,62.45,0.171
154.64,62.59,0.171
154.67,62.73,0.171
154.69,62.87,0.171
154.72,63.01,0.171
154.75,63.16,0.171
154.78,63.30,0.171
154.81,63.44,0.171
154.83,63.58,0.171
154.86,63.72,0.171
154.89,63.86,0.171
154.92,64.01,0.172
154.95,64.15,0.172
154.98,64.29,0.172
155.00,64.43,0.172
155.03,64.57,0.172
155.06,64.72,0.172
155.09,64.86,0.172
155.12,65.00,0.172
155.15,65.14,0.172
155.18,65.28,0.172
155.20,65.43,0.172
155.23,65.57,0.172
155.26,65.71,0.172
155.29,65.85,0.172
155.32,65.99,0.172
155.35,66.13,0.172
155.37,66.28,0.173
155.40,66.42,0.173
155.43,66.56,0.173
155.46,66.70,0.173
155.49,66.84,0.173
155.52,66.98,0.173
155.54,67.12,0.173
155.57,67.27,0.173
155.60,67.41,0.173
155.63,67.55,0.173
155.66,67.69,0.173
155.68,67.83,0.173
155.71,67.98,0.173
155.74,68.12,0.173
155.77,68.26,0.173
155.80,68.40,0.173
155.83,68.54,0.173
155.85,68.68,0.173
155.88,68.83,0.174
155.91,68.97,0.174
155.94,69.11,0.174
155.97,69.25,0.174
156.00,69.39,0.174
156.03,69.53,0.174
156.05,69.68,0.174
156.08,69.82,0.174
156.11,69.96,0.174
156.14,70.10,0.174
156.17,70.24,0.174
156.20,70.38,0.174
156.22,70.53,0.174
156.25,70.67,0.174
156.28,70.81,0.174
156.31,70.95,0.174
156.34,71.09,0.175
156.37,71.24,0.175
156.39,71.38,0.175
156.42,71.52,0.175
156.45,71.66,0.175
156.48,71.80,0.175
156.51,71.94,0.175
156.53,72.09,0.175
156.56,72.23,0.175
156.59,72.37,0.175
156.62,72.51,0.175
156.65,72.65,0.175
156.68,72.79,0.175
156.70,72.94,0.175
156.73,73.08,0.175
156.76,73.22,0.175
156.79,73.36,0.175
156.82,73.50,0.175
156.85,73.64,0.176
156.88,73.79,0.176
156.90,73.93,0.176
156.93,74.07,0.176
156.96,74.21,0.176
156.99,74.35,0.176
157.02,74.49,0.176
157.05,74.64,0.176
157.07,74.78,0.176
157.10,74.92,0.176
157.13,75.06,0.176
157.16,75.20,0.176
157.19,75.35,0.176
157.22,75.49,0.176
157.24,75.63,0.177
157.27,75.77,0.177
157.30,75.91,0.177
157.33,76.05,0.177
157.36,76.20,0.177
157.38,76.34,0.177
157.41,76.48,0.177
157.44,76.62,0.177
157.47,76.76,0.177
157.50,76.90,0.177
157.53,77.05,0.177
157.55,77.19,0.177
157.58,77.33,0.177
157.61,77.47,0.177
157.64,77.61,0.177
157.67,77.76,0.177
157.70,77.90,0.177
157.73,78.04,0.178
157.75,78.18,0.178
157.78,78.32,0.178
157.81,78.46,0.178
157.84,78.61,0.178
157.87,78.75,0.178
157.90,78.89,0.178
157.92,79.03,0.178
157.95,79.17,0.178
157.98,79.31,0.178
158.01,79.46,0.178
158.04,79.60,0.178
158.07,79.74,0.178
158.09,79.88,0.179
158.12,80.02,0.179
158.15,80.16,0.179
158.18,80.31,0.179
158.21,80.45,0.179
158.23,80.59,0.179
158.26,80.73,0.179
158.29,80.87,0.179
158.32,81.01,0.179
158.35,81.16,0.179
158.38,81.30,0.179
158.40,81.44,0.179
158.43,81.58,0.179
158.46,81.72,0.179
158.49,81.86,0.179
158.52,82.01,0.179
158.55,82.15,0.179
158.58,82.29,0.179
158.60,82.43,0.180
158.63,82.57,0.180
158.66,82.71,0.180
158.69,82.86,0.180
158.72,83.00,0.180
158.75,83.14,0.180
158.77,83.28,0.180
158.80,83.42,0.180
158.83,83.57,0.180
158.86,83.71,0.180
158.89,83.85,0.180
158.92,83.99,0.180
158.94,84.13,0.180
158.97,84.27,0.180
159.00,84.41,0.180
159.03,84.56,0.180
159.06,84.70,0.180
159.08,84.84,0.180
159.11,84.98,0.180
159.14,85.12,0.181
159.17,85.27,0.181
159.20,85.41,0.181
159.23,85.55,0.181
159.25,85.69,0.181
159.28,85.83,0.181
159.31,85.98,0.181
159.34,86.12,0.181
159.37,86.26,0.181
159.40,86.40,0.181
159.43,86.54,0.181
159.45,86.68,0.181
159.48,86.83,0.181
159.51,86.97,0.181
159.54,87.11,0.181
159.57,87.25,0.181
159.60,87.39,0.181
159.62,87.53,0.181
159.65,87.68,0.182
159.68,87.82,0.182
159.71,87.96,0.182
159.74,88.10,0.182
159.77,88.24,0.182
159.79,88.38,0.182
159.82,88.53,0.182
159.85,88.67,0.182
159.88,88.81,0.182
159.91,88.95,0.182
159.93,89.09,0.182
159.96,89.24,0.182
159.99,89.38,0.182
160.02,89.52,0.182
160.05,89.66,0.182
160.08,89.80,0.182
160.10,89.94,0.182
160.13,90.08,0.182
160.16,90.23,0.183
160.19,90.37,0.183
160.22,90.51,0.183
160.25,90.65,0.183
160.28,90.79,0.183
160.30,90.94,0.183
160.33,91.08,0.183
160.36,91.22,0.183
160.39,91.36,0.183
160.42,91.50,0.183
160.45,91.64,0.183
160.47,91.79,0.183
160.50,91.93,0.184
160.53,92.07,0.184
160.56,92.21,0.184
160.59,92.35,0.184
160.62,92.49,0.184
160.64,92.64,0.184
160.67,92.78,0.184
160.70,92.92,0.184
160.73,93.06,0.184
160.76,93.20,0.184
160.78,93.34,0.184
160.81,93.49,0.184
160.84,93.63,0.184
160.87,93.77,0.184
160.90,93.91,0.184
160.93,94.05,0.185
160.95,94.19,0.185
160.98,94.34,0.185
161.01,94.48,0.185
161.04,94.62,0.185
161.07,94.76,0.185
161.10,94.90,0.185
161.13,95.05,0.185
161.15,95.19,0.185
161.18,95.33,0.185
161.21,95.47,0.185
161.24,95.61,0.185
161.27,95.75,0.185
161.30,95.90,0.186
161.32,96.04,0.186
161.35,96.18,0.186
161.38,96.32,0.186
161.41,96.46,0.186
161.44,96.60,0.186
161.47,96.75,0.186
161.49,96.89,0.186
161.52,97.03,0.186
161.55,97.17,0.186
161.58,97.31,0.186
161.61,97.45,0.186
161.63,97.60,0.186
161.66,97.74,0.186
161.69,97.88,0.186
161.72,98.02,0.186
161.75,98.16,0.186
161.78,98.30,0.186
161.80,98.45,0.187
161.83,98.59,0.187
161.86,98.73,0.187
161.89,98.87,0.187
161.92,99.01,0.187
161.95,99.15,0.187
161.98,99.30,0.187
162.00,99.44,0.187
162.03,99.58,0.187
162.06,99.72,0.187
162.09,99.86,0.187
162.12,100.00,0.187
162.15,100.15,0.187
162.17,100.29,0.187
162.20,100.43,0.187
162.23,100.57,0.188
162.26,100.71,0.188
162.29,100.86,0.188
162.32,101.00,0.188
162.34,101.14,0.188
162.37,101.28,0.188
162.40,101.42,0.188
162.43,101.56,0.188
162.46,101.71,0.188
162.48,101.85,0.188
162.51,101.99,0.188
162.54,102.13,0.188
162.57,102.27,0.188
162.60,102.41,0.188
162.63,102.56,0.188
162.65,102.70,0.189
162.68,102.84,0.189
162.71,102.98,0.189
162.74,103.12,0.189
162.77,103.27,0.189
162.80,103.41,0.189
162.83,103.55,0.189
162.85,103.69,0.189
162.88,103.83,0.189
162.91,103.97,0.189
162.94,104.11,0.189
162.97,104.26,0.189
163.00,104.40,0.189
163.02,104.54,0.189
163.05,104.68,0.189
163.08,104.82,0.189
163.11,104.97,0.189
163.14,105.11,0.189
163.17,105.25,0.189
163.19,105.39,0.189
163.22,105.53,0.189
163.25,105.67,0.189
163.28,105.82,0.189
163.31,105.96,0.190
163.33,106.10,0.190
163.36,106.24,0.190
163.39,106.38,0.190
163.42,106.53,0.190
163.45,106.67,0.190
163.48,106.81,0.190
163.50,106.95,0.190
163.53,107.09,0.190
163.56,107.23,0.190
163.59,107.37,0.190
163.62,107.52,0.190
163.65,107.66,0.190
163.68,107.80,0.190
163.70,107.94,0.190
163.73,108.08,0.190
163.76,108.23,0.190
163.79,108.37,0.190
163.82,108.51,0.191
163.85,108.65,0.191
163.87,108.79,0.191
163.90,108.93,0.191
163.93,109.07,0.191
163.96,109.22,0.191
163.99,109.36,0.191
164.02,109.50,0.191
164.04,109.64,0.191
164.07,109.79,0.191
164.10,109.93,0.191
164.13,110.07,0.191
164.16,110.21,0.192
164.18,110.36,0.192
164.21,110.50,0.192
164.24,110.64,0.192
164.27,110.78,0.192
164.30,110.92,0.192
164.33,111.06,0.192
164.35,111.20,0.192
164.38,111.34,0.191
164.41,111.49,0.191
164.44,111.63,0.191
164.47,111.77,0.191
164.50,111.91,0.191
164.53,112.05,0.191
164.55,112.20,0.192
164.58,112.34,0.191
164.61,112.48,0.192
164.64,112.62,0.192
164.67,112.76,0.192
164.70,112.90,0.192
164.72,113.04,0.192
164.75,113.19,0.192
164.78,113.33,0.192
164.81,113.47,0.192
164.84,113.61,0.192
164.87,113.75,0.192
164.89,113.89,0.192
164.92,114.04,0.192
164.95,114.18,0.192
164.98,114.32,0.192
165.01,114.46,0.192
165.03,114.60,0.192
165.06,114.74,0.192
165.09,114.89,0.192
165.12,115.03,0.192
165.15,115.17,0.192
165.18,115.31,0.192
165.20,115.45,0.192
165.23,115.59,0.193
165.26,115.73,0.193
165.29,115.88,0.193
165.32,116.02,0.193
165.35,116.16,0.193
165.38,116.30,0.193
165.40,116.45,0.193
165.43,116.59,0.193
165.46,116.73,0.193
165.49,116.87,0.193
165.52,117.01,0.193
165.55,117.15,0.193
165.57,117.29,0.193
165.60,117.44,0.193
165.63,117.58,0.193
165.66,117.72,0.194
165.69,117.86,0.194
165.72,118.00,0.194
165.74,118.15,0.194
165.77,118.29,0.194
165.80,118.43,0.194
165.83,118.57,0.194
165.86,118.71,0.194
165.88,118.85,0.194
165.91,119.00,0.194
165.94,119.14,0.194
165.97,119.28,0.194
166.00,119.42,0.194
166.03,119.56,0.194
166.05,119.70,0.194
166.08,119.85,0.194
166.11,119.99,0.195
166.14,120.13,0.195
166.17,120.27,0.195
166.20,120.41,0.195
166.23,120.55,0.195
166.25,120.70,0.195
166.28,120.84,0.195
166.31,120.98,0.195
166.34,121.12,0.195
166.37,121.26,0.195
166.40,121.40,0.195
166.42,121.55,0.195
166.45,121.69,0.195
166.48,121.83,0.195
166.51,121.97,0.195
166.54,122.11,0.195
166.57,122.25,0.195
166.59,122.40,0.196
166.62,122.54,0.196
166.65,122.68,0.196
166.68,122.82,0.196
166.71,122.96,0.196
166.73,123.10,0.196
166.76,123.25,0.196
166.79,123.39,0.196
166.82,123.53,0.196
166.85,123.67,0.196
166.88,123.81,0.196
166.90,123.96,0.196
166.93,124.10,0.196
166.96,124.24,0.197
166.99,124.38,0.197
167.02,124.52,0.197
167.05,124.66,0.197
167.08,124.81,0.197
167.10,124.95,0.197
167.13,125.09,0.197
167.16,125.23,0.197
167.19,125.37,0.197
167.22,125.51,0.197
167.25,125.66,0.197
167.27,125.80,0.198
167.30,125.94,0.198
167.33,126.08,0.198
167.36,126.22,0.198
167.39,126.36,0.198
167.42,126.51,0.198
167.44,126.65,0.198
167.47,126.79,0.198
167.50,126.93,0.198
167.53,127.07,0.198
167.56,127.21,0.198
167.58,127.36,0.198
167.61,127.50,0.198
167.64,127.64,0.199
167.67,127.78,0.199
167.70,127.92,0.199
167.73,128.06,0.199
167.75,128.21,0.199
167.78,128.35,0.199
167.81,128.49,0.199
167.84,128.63,0.199
167.87,128.77,0.199
167.90,128.91,0.199
167.93,129.06,0.199
167.95,129.20,0.199
167.98,129.34,0.200
168.01,129.48,0.200
168.04,129.62,0.200
168.07,129.76,0.200
168.10,129.91,0.200
168.12,130.05,0.200
168.15,130.19,0.200
168.18,130.33,0.200
168.21,130.47,0.200
168.24,130.61,0.200
168.27,130.76,0.200
168.29,130.90,0.201
168.32,131.04,0.201
168.35,131.18,0.201
168.38,131.32,0.201
168.41,131.46,0.201
168.43,131.61,0.201
168.46,131.75,0.201
168.49,131.89,0.201
168.52,132.03,0.201
168.55,132.17,0.202
168.58,132.31,0.202
168.60,132.46,0.202
168.63,132.60,0.202
168.66,132.74,0.202
168.69,132.88,0.202
168.72,133.02,0.202
168.75,133.17,0.202
168.78,133.31,0.202
168.80,133.45,0.203
168.83,133.59,0.203
168.86,133.73,0.203
168.89,133.87,0.203
168.92,134.02,0.203
168.95,134.16,0.203
168.97,134.30,0.203
169.00,134.44,0.203
169.03,134.58,0.203
169.06,134.72,0.204
169.09,134.87,0.204
169.12,135.01,0.204
169.14,135.15,0.204
169.17,135.29,0.204
169.20,135.43,0.204
169.23,135.57,0.204
169.26,135.71,0.205
169.28,135.86,0.205
169.31,136.00,0.205
169.34,136.14,0.205
169.37,136.28,0.205
169.40,136.42,0.205
169.43,136.57,0.205
169.45,136.71,0.205
169.48,136.85,0.206
169.51,136.99,0.206
169.54,137.13,0.206
169.57,137.27,0.206
169.60,137.42,0.206
169.63,137.56,0.206
169.65,137.70,0.207
169.68,137.84,0.207
169.71,137.98,0.207
169.74,138.12,0.207
169.77,138.26,0.207
169.80,138.41,0.207
169.82,138.55,0.207
169.85,138.69,0.208
169.88,138.83,0.208
169.91,138.97,0.208
169.94,139.11,0.208
169.97,139.26,0.208
169.99,139.40,0.208
170.02,139.54,0.209
170.05,139.68,0.209
170.08,139.82,0.209
170.11,139.97,0.209
170.13,140.11,0.209
170.16,140.25,0.210
170.19,140.39,0.210
170.22,140.53,0.210
170.25,140.67,0.210
170.28,140.82,0.210
170.30,140.96,0.210
170.33,141.10,0.211
170.36,141.24,0.211
170.39,141.38,0.211
170.42,141.52,0.211
170.45,141.67,0.211
170.48,141.81,0.212
170.50,141.95,0.212
170.53,142.09,0.212
170.56,142.23,0.212
170.59,142.37,0.212
170.62,142.51,0.212
170.65,142.66,0.213
170.67,142.80,0.213
170.70,142.94,0.213
170.73,143.08,0.213
170.76,143.22,0.214
170.79,143.37,0.214
170.82,143.51,0.214
170.84,143.65,0.215
170.87,143.79,0.215
170.90,143.93,0.215
170.93,144.08,0.215
170.96,144.21,0.215
170.98,144.36,0.216
171.01,144.50,0.216
171.04,144.64,0.216
171.07,144.78,0.216
171.10,144.92,0.216
171.13,145.07,0.217
171.15,145.21,0.217
171.18,145.35,0.217
171.21,145.49,0.218
171.24,145.63,0.218
171.27,145.77,0.218
171.30,145.92,0.218
171.33,146.06,0.219
171.35,146.20,0.219
171.38,146.34,0.219
171.41,146.48,0.219
171.44,146.62,0.220
171.47,146.76,0.220
171.50,146.91,0.220
171.52,147.05,0.220
171.55,147.19,0.221
171.58,147.33,0.221
171.61,147.47,0.221
171.64,147.61,0.222
171.67,147.75,0.222
171.69,147.90,0.222
171.72,148.04,0.223
171.75,148.18,0.223
171.78,148.32,0.224
171.81,148.46,0.224
171.83,148.61,0.224
171.86,148.75,0.225
171.89,148.89,0.225
171.92,149.03,0.226
171.95,149.17,
171.98,,
171.98,,