File: DSC/2025_04_21_CBD_Carnitine_ACN_MC_n60C_150C_5Cmin_x3.csv
Filename,2025_04_21_CBD_Carnitine_ACN_MC_n60C_150C_5Cmin_x3
Instrument name,DSC2A-00468 (192.168.1.100)
Operator,Yarger
rundate,4/22/2025
Sample name,2025_04_21_CBD_Carnitine_ACN_MC_n60C_150C_5Cmin_x3
proceduresegments,Data Off ; Equilibrate -60.00 °C; Data On ; Ramp 5.00 °C/min to 150.00 °C; Data Off ; Isothermal 1.0 min; Data On ; Ramp 10.00 °C/min to -60.00 °C; Data Off ; Isothermal 1.0 min; Data On ; Ramp 5.00 °C/min to 150.00 °C; Data Off ; Isothermal 1.0 min; Data On ; Ramp 10.00 °C/min to -60.00 °C; Data Off ; Isothermal 1.0 min; Data On ; Ramp 5.00 °C/min to 150.00 °C
[File Parameters]
Run date,4/22/2025 7:53:54 AM
Trios version,5.1.1.46572
Original File Name,
Current File Name,D:\DSC2500\JYarger\2025_04_21_CBD_Carnitine_ACN_MC_n60C_150C_5Cmin_x3.tri
[Procedure]
Procedure Name,CBD_Canitine_n60_150C_5Cmin_x3
Sample Name,2025_04_21_CBD_Carnitine_ACN_MC_n60C_150C_5Cmin_x3
Sample Mass,5.12 mg
Reference Sample Mass,0 mg
Pan Mass,52.51 mg
Pan Number,20
Reference Pan Mass,52.66 mg
Reference Pan Number,19
Pan Type,Tzero Aluminum Hermetic
Comments,Al Hermetic DSC Consumables sealed Pan/Lid.
Project Name,CA
Operator,Yarger
Test,Custom
Unload Max Temperature,30
Unload Min Temperature,30
Load Max Temperature,30
Load Min Temperature,30
Stop on Gas Flow Error,Yes
[Signal List]
Signal #1,Time (min)
Signal #2,Temperature (°C)
Signal #3,Heat Flow (mW)
Signal #4,Delta T (µV)
Signal #5,Delta Tzero (µV)
Signal #6,Tzero Temperature (°C)
Signal #7,Cell Purge (mL/min)
Signal #8,Heater Temp (°C)
Signal #9,Power Delivered (W)
Signal #10,Reference Junction Temperature (°C)
Signal #11,Flange Temperature (°C)
Signal #12,Heat Flow Phase (rad)
Signal #13,Total Heat Capacity (J/°C)
Signal #14,Heat Capacity (J/°C)
[Configuration]
Company Name,ASU
Instrument Name,DSC2A-00468
Instrument Type,DSC2500
Serial Number,DSC2A-00468
IP,192.168.1.100
Location of Instrument,MRRC
DisplayType,Unknown
Sample Interval ,0.1 s/pt
Selected Heat Flow,T4P
Exotherm Direction,Down
Cell Serial,DRC2-00792
Lid Type,Standard
Cooler,RCS 90
Leave Cooler on at End of Sequence,On
Gas 2,Nitrogen
Gas Selected,Channel 1
Flow Rate,50 mL/min
Secondary Purge,On
Licensed Heat Flow,Heat Flow T4P
Modulation Licensed,Yes
[Versions]
Common IDD Version,1
Cortex Version,VER 2.10.2.31
Driver,5.0.0.6
GDM Version,1.0.3.3
TouchscreenVersion,1.0.0.16145
FEP Version,1.2.1.21
FEP Bootloader,2.0.0.5
AutoSampler Version,2.1.1.26
Auto Sampler Bootloader,2.0.0.5
FCM Version,1.1.0.3
FCM Bootloader,2.0.0.5
[Experiment Logs]
Experiment Log Entry # 1,Air Cool is off.
Experiment Log Entry # 3,Data On set to 0
Experiment Log Entry # 5,Equilibrate Segment -60 (C) Started
Experiment Log Entry # 7,Data On set to 1
Experiment Log Entry # 9,Ramp Segment 5 C/min to 150 Started
Experiment Log Entry # 11,Data On set to 0
Experiment Log Entry # 13,Isothermal Segment 1 min started
Experiment Log Entry # 15,Data On set to 1
Experiment Log Entry # 17,Ramp Segment 10 C/min to -60 Started
Experiment Log Entry # 19,Data On set to 0
Experiment Log Entry # 21,Isothermal Segment 1 min started
Experiment Log Entry # 23,Data On set to 1
Experiment Log Entry # 25,Ramp Segment 5 C/min to 150 Started
Experiment Log Entry # 27,Auto sampler has detected that GDM has gone offline
Experiment Log Entry # 29,Data On set to 0
Experiment Log Entry # 31,Isothermal Segment 1 min started
Experiment Log Entry # 33,Data On set to 1
Experiment Log Entry # 35,Ramp Segment 10 C/min to -60 Started
Experiment Log Entry # 37,Data On set to 0
Experiment Log Entry # 39,Isothermal Segment 1 min started
Experiment Log Entry # 41,Data On set to 1
Experiment Log Entry # 43,Ramp Segment 5 C/min to 150 Started
[Method Log]
Method Log Entry # 1,Data Off
Method Log Entry # 2,Equilibrate -60 °C
Method Log Entry # 3,Data On
Method Log Entry # 4,(Ramp 971447) Ramp 5 °C/minute to 150 °C
Method Log Entry # 5,Data Off
Method Log Entry # 6,Isothermal 1 minutes
Method Log Entry # 7,Data On
Method Log Entry # 8,(Ramp 971451) Ramp 10 °C/minute to -60 °C
Method Log Entry # 9,Data Off
Method Log Entry # 10,Isothermal 1 minutes
Method Log Entry # 11,Data On
Method Log Entry # 12,(Ramp 971455) Ramp 5 °C/minute to 150 °C
Method Log Entry # 13,Data Off
Method Log Entry # 14,Isothermal 1 minutes
Method Log Entry # 15,Data On
Method Log Entry # 16,(Ramp 971459) Ramp 10 °C/minute to -60 °C
Method Log Entry # 17,Data Off
Method Log Entry # 18,Isothermal 1 minutes
Method Log Entry # 19,Data On
Method Log Entry # 20,(Ramp 971463) Ramp 5 °C/minute to 150 °C
Cell Serial,DRC2-00792
[T1 Calibration]
Slope,-0.008529666
Offset,9.636258
Initial Temperature,98.23
GUID,f8bfdadc-4977-4fdf-ba6d-0ba9134940c3
[TZero Calibration]
Date Applied,11/29/2022 4:06:13 PM
Description,From -89.059 °C to 396.009 °C at 20.000°C/min
Gas Type,Nitrogen
Pan Type,None
Source Files 1,C:\Users\yargerlab\Desktop\DSC Data\General\TZero_calibration_11_29_22_2nd(2).tri
Source Files 2,C:\Users\yargerlab\Desktop\DSC Data\General\TZero_calibration_11_29_22_2nd(3).tri
Delta T Offset,13.05235
Delta T Slope,-0.007271007
Delta T0 Offset,-13.69128
Delta T0 Slope,0.06063341
[Temperature Calibration]
Date Applied,11/29/2022 7:12:28 PM
Description,From 106.590 °C to 186.590 °C at 10.000°C/min
Gas Type,Nitrogen
Pan Type,Tzero Aluminum Hermetic
Source Files 1,C:\Users\yargerlab\Desktop\DSC Data\General\Indium(6).tri
Measured 1,157.391
Known 1,156.598
[Cell Constant Calibration]
Date Applied,11/29/2022 7:12:29 PM
Description,From 106.590 °C to 186.590 °C at 10.000°C/min
Gas Type,Nitrogen
Pan Type,Tzero Aluminum Hermetic
Source Files 1,C:\Users\yargerlab\Desktop\DSC Data\General\Indium(6).tri
T4P KCell,1.006051
Onset Slope,63.26126 mW/°C
[Direct Cp Calibration]
Date Applied,11/30/2022 11:04:51 AM
Description,From -79.983 °C to 298.409 °C at 10.000°C/min
Gas Type,Nitrogen
Pan Type,Tzero Aluminum Hermetic
Source Files 1,C:\Users\yargerlab\Desktop\DSC Data\General\Sapphire_Heat_Capacity_11_30_22.tri
[Rev Cp Calibration]
Date Applied,11/30/2022 1:58:51 PM
Description,From -79.996 °C to 292.812 °C at 3.000°C/min
Gas Type,Nitrogen
Pan Type,Tzero Aluminum Hermetic
Source Files 1,C:\Users\yargerlab\Desktop\DSC Data\General\Sapphire_MDSC_Calibration_11_30_22.tri
[step]
Ramp 5.00 °C/min to 150.00 °C
Time,Temperature,Heat Flow (Normalized)
min,°C,W/g
0.00,-59.68,-0.067
0.03,-59.69,-0.066
0.06,-59.70,-0.057
0.08,-59.68,-0.055
0.11,-59.63,-0.053
0.14,-59.55,-0.040
0.17,-59.46,-0.020
0.20,-59.36,0.000
0.23,-59.25,0.019
0.26,-59.13,0.033
0.28,-59.01,0.043
0.31,-58.88,0.052
0.34,-58.76,0.060
0.37,-58.63,0.065
0.40,-58.50,0.070
0.43,-58.36,0.074
0.45,-58.23,0.078
0.48,-58.10,0.079
0.51,-57.96,0.081
0.54,-57.83,0.082
0.57,-57.69,0.084
0.60,-57.55,0.085
0.62,-57.41,0.085
0.65,-57.28,0.086
0.68,-57.14,0.087
0.71,-57.00,0.087
0.74,-56.86,0.088
0.77,-56.72,0.088
0.79,-56.59,0.089
0.82,-56.45,0.089
0.85,-56.31,0.089
0.88,-56.17,0.090
0.91,-56.03,0.090
0.93,-55.89,0.091
0.96,-55.75,0.091
0.99,-55.61,0.091
1.02,-55.47,0.091
1.05,-55.33,0.092
1.08,-55.19,0.092
1.11,-55.05,0.092
1.13,-54.91,0.092
1.16,-54.77,0.092
1.19,-54.63,0.092
1.22,-54.49,0.093
1.25,-54.35,0.093
1.28,-54.21,0.093
1.30,-54.07,0.093
1.33,-53.92,0.093
1.36,-53.79,0.093
1.39,-53.64,0.093
1.42,-53.50,0.093
1.44,-53.36,0.093
1.47,-53.22,0.093
1.50,-53.08,0.093
1.53,-52.94,0.093
1.56,-52.80,0.094
1.59,-52.66,0.094
1.62,-52.51,0.094
1.64,-52.37,0.094
1.67,-52.23,0.094
1.70,-52.09,0.094
1.73,-51.95,0.094
1.76,-51.81,0.094
1.78,-51.67,0.094
1.81,-51.52,0.094
1.84,-51.38,0.094
1.87,-51.24,0.094
1.90,-51.10,0.094
1.93,-50.96,0.094
1.96,-50.82,0.094
1.98,-50.68,0.094
2.01,-50.54,0.094
2.04,-50.39,0.094
2.07,-50.25,0.094
2.10,-50.11,0.094
2.13,-49.97,0.094
2.15,-49.83,0.094
2.18,-49.69,0.094
2.21,-49.55,0.094
2.24,-49.40,0.094
2.27,-49.26,0.094
2.29,-49.12,0.094
2.32,-48.98,0.094
2.35,-48.84,0.094
2.38,-48.70,0.094
2.41,-48.56,0.094
2.44,-48.41,0.094
2.46,-48.27,0.094
2.49,-48.13,0.094
2.52,-47.99,0.094
2.55,-47.85,0.094
2.58,-47.71,0.094
2.61,-47.57,0.094
2.64,-47.42,0.094
2.66,-47.28,0.094
2.69,-47.14,0.094
2.72,-47.00,0.094
2.75,-46.86,0.094
2.78,-46.72,0.094
2.81,-46.57,0.094
2.83,-46.43,0.094
2.86,-46.29,0.094
2.89,-46.15,0.094
2.92,-46.01,0.094
2.95,-45.87,0.094
2.98,-45.73,0.094
3.00,-45.58,0.094
3.03,-45.44,0.094
3.06,-45.30,0.094
3.09,-45.16,0.094
3.12,-45.02,0.094
3.14,-44.88,0.094
3.17,-44.73,0.094
3.20,-44.59,0.094
3.23,-44.45,0.094
3.26,-44.31,0.094
3.29,-44.17,0.094
3.31,-44.03,0.094
3.34,-43.89,0.094
3.37,-43.74,0.094
3.40,-43.60,0.094
3.43,-43.46,0.094
3.46,-43.32,0.094
3.49,-43.18,0.094
3.51,-43.03,0.094
3.54,-42.89,0.094
3.57,-42.75,0.094
3.60,-42.61,0.094
3.63,-42.47,0.094
3.66,-42.33,0.094
3.68,-42.18,0.094
3.71,-42.04,0.094
3.74,-41.90,0.094
3.77,-41.76,0.094
3.80,-41.62,0.094
3.83,-41.48,0.094
3.85,-41.33,0.094
3.88,-41.19,0.094
3.91,-41.05,0.094
3.94,-40.91,0.094
3.97,-40.77,0.094
3.99,-40.62,0.094
4.02,-40.48,0.094
4.05,-40.34,0.094
4.08,-40.20,0.094
4.11,-40.06,0.094
4.14,-39.91,0.094
4.16,-39.77,0.094
4.19,-39.63,0.094
4.22,-39.49,0.094
4.25,-39.35,0.094
4.28,-39.21,0.094
4.31,-39.06,0.094
4.34,-38.92,0.094
4.36,-38.78,0.094
4.39,-38.64,0.094
4.42,-38.50,0.094
4.45,-38.36,0.094
4.48,-38.21,0.094
4.50,-38.07,0.094
4.53,-37.93,0.094
4.56,-37.79,0.094
4.59,-37.65,0.094
4.62,-37.50,0.094
4.65,-37.36,0.094
4.68,-37.22,0.094
4.70,-37.08,0.094
4.73,-36.94,0.094
4.76,-36.79,0.094
4.79,-36.65,0.094
4.82,-36.51,0.094
4.85,-36.37,0.094
4.87,-36.23,0.094
4.90,-36.09,0.094
4.93,-35.95,0.094
4.96,-35.80,0.094
4.99,-35.66,0.094
5.01,-35.52,0.094
5.04,-35.38,0.094
5.07,-35.24,0.094
5.10,-35.09,0.094
5.13,-34.95,0.094
5.16,-34.81,0.094
5.19,-34.67,0.094
5.21,-34.53,0.094
5.24,-34.38,0.094
5.27,-34.24,0.094
5.30,-34.10,0.094
5.33,-33.96,0.094
5.35,-33.82,0.094
5.38,-33.67,0.094
5.41,-33.53,0.094
5.44,-33.39,0.094
5.47,-33.25,0.094
5.50,-33.11,0.094
5.53,-32.96,0.095
5.55,-32.83,0.094
5.58,-32.68,0.095
5.61,-32.54,0.095
5.64,-32.40,0.095
5.67,-32.26,0.095
5.70,-32.11,0.095
5.72,-31.97,0.095
5.75,-31.83,0.095
5.78,-31.69,0.095
5.81,-31.55,0.095
5.84,-31.40,0.095
5.86,-31.26,0.095
5.89,-31.12,0.095
5.92,-30.98,0.095
5.95,-30.84,0.095
5.98,-30.70,0.095
6.01,-30.55,0.095
6.04,-30.41,0.095
6.06,-30.27,0.095
6.09,-30.13,0.095
6.12,-29.99,0.095
6.15,-29.85,0.095
6.18,-29.70,0.095
6.20,-29.56,0.095
6.23,-29.42,0.095
6.26,-29.28,0.095
6.29,-29.14,0.095
6.32,-29.00,0.095
6.35,-28.85,0.095
6.38,-28.71,0.095
6.40,-28.57,0.095
6.43,-28.43,0.095
6.46,-28.29,0.095
6.49,-28.15,0.095
6.52,-28.00,0.095
6.55,-27.86,0.095
6.57,-27.72,0.095
6.60,-27.58,0.095
6.63,-27.44,0.095
6.66,-27.29,0.095
6.69,-27.15,0.095
6.71,-27.01,0.095
6.74,-26.87,0.095
6.77,-26.73,0.095
6.80,-26.58,0.095
6.83,-26.44,0.095
6.86,-26.30,0.095
6.89,-26.16,0.095
6.91,-26.02,0.096
6.94,-25.88,0.095
6.97,-25.73,0.096
7.00,-25.59,0.096
7.03,-25.45,0.096
7.05,-25.31,0.096
7.08,-25.17,0.096
7.11,-25.03,0.096
7.14,-24.88,0.096
7.17,-24.74,0.096
7.20,-24.60,0.096
7.23,-24.46,0.096
7.25,-24.32,0.096
7.28,-24.17,0.096
7.31,-24.03,0.096
7.34,-23.89,0.096
7.37,-23.75,0.096
7.40,-23.61,0.096
7.42,-23.47,0.096
7.45,-23.32,0.096
7.48,-23.18,0.096
7.51,-23.04,0.096
7.54,-22.90,0.096
7.56,-22.76,0.096
7.59,-22.62,0.096
7.62,-22.47,0.096
7.65,-22.33,0.096
7.68,-22.19,0.096
7.71,-22.05,0.096
7.74,-21.91,0.096
7.76,-21.76,0.096
7.79,-21.62,0.096
7.82,-21.48,0.096
7.85,-21.34,0.096
7.88,-21.20,0.096
7.90,-21.05,0.097
7.93,-20.91,0.097
7.96,-20.77,0.097
7.99,-20.63,0.097
8.02,-20.49,0.097
8.05,-20.35,0.097
8.08,-20.20,0.097
8.10,-20.06,0.097
8.13,-19.92,0.097
8.16,-19.78,0.097
8.19,-19.64,0.097
8.22,-19.50,0.097
8.25,-19.35,0.097
8.27,-19.21,0.097
8.30,-19.07,0.097
8.33,-18.93,0.097
8.36,-18.79,0.097
8.39,-18.64,0.097
8.41,-18.50,0.097
8.44,-18.36,0.097
8.47,-18.22,0.097
8.50,-18.08,0.097
8.53,-17.94,0.097
8.56,-17.79,0.097
8.58,-17.65,0.097
8.61,-17.51,0.097
8.64,-17.37,0.097
8.67,-17.23,0.097
8.70,-17.08,0.097
8.73,-16.94,0.097
8.75,-16.80,0.097
8.78,-16.66,0.097
8.81,-16.52,0.097
8.84,-16.38,0.097
8.87,-16.24,0.097
8.90,-16.09,0.098
8.93,-15.95,0.098
8.95,-15.81,0.098
8.98,-15.67,0.098
9.01,-15.53,0.098
9.04,-15.38,0.098
9.07,-15.24,0.098
9.10,-15.10,0.098
9.12,-14.96,0.098
9.15,-14.82,0.098
9.18,-14.67,0.098
9.21,-14.53,0.098
9.24,-14.39,0.098
9.27,-14.25,0.098
9.29,-14.11,0.098
9.32,-13.97,0.098
9.35,-13.82,0.098
9.38,-13.68,0.098
9.41,-13.54,0.098
9.43,-13.40,0.098
9.46,-13.26,0.098
9.49,-13.11,0.098
9.52,-12.97,0.098
9.55,-12.83,0.098
9.58,-12.69,0.098
9.60,-12.55,0.098
9.63,-12.41,0.098
9.66,-12.26,0.098
9.69,-12.12,0.098
9.72,-11.98,0.098
9.75,-11.84,0.099
9.78,-11.70,0.099
9.80,-11.56,0.099
9.83,-11.41,0.099
9.86,-11.27,0.099
9.89,-11.13,0.099
9.92,-10.99,0.099
9.95,-10.85,0.099
9.97,-10.71,0.099
10.00,-10.56,0.099
10.03,-10.42,0.099
10.06,-10.28,0.099
10.09,-10.14,0.099
10.12,-10.00,0.099
10.14,-9.85,0.099
10.17,-9.71,0.099
10.20,-9.57,0.099
10.23,-9.43,0.099
10.26,-9.29,0.099
10.28,-9.15,0.099
10.31,-9.00,0.099
10.34,-8.86,0.099
10.37,-8.72,0.099
10.40,-8.58,0.099
10.43,-8.44,0.099
10.45,-8.29,0.099
10.48,-8.15,0.099
10.51,-8.01,0.099
10.54,-7.87,0.099
10.57,-7.73,0.099
10.60,-7.59,0.099
10.63,-7.44,0.100
10.65,-7.30,0.100
10.68,-7.16,0.100
10.71,-7.02,0.100
10.74,-6.88,0.100
10.77,-6.74,0.100
10.80,-6.59,0.100
10.82,-6.45,0.100
10.85,-6.31,0.100
10.88,-6.17,0.100
10.91,-6.03,0.100
10.94,-5.88,0.100
10.97,-5.74,0.100
10.99,-5.60,0.100
11.02,-5.46,0.100
11.05,-5.32,0.100
11.08,-5.18,0.100
11.11,-5.04,0.100
11.13,-4.89,0.100
11.16,-4.75,0.100
11.19,-4.61,0.100
11.22,-4.47,0.100
11.25,-4.33,0.100
11.28,-4.18,0.100
11.30,-4.04,0.100
11.33,-3.90,0.100
11.36,-3.76,0.100
11.39,-3.62,0.100
11.42,-3.48,0.100
11.45,-3.33,0.101
11.48,-3.19,0.101
11.50,-3.05,0.101
11.53,-2.91,0.101
11.56,-2.77,0.101
11.59,-2.62,0.101
11.62,-2.48,0.101
11.65,-2.34,0.101
11.67,-2.20,0.101
11.70,-2.06,0.101
11.73,-1.92,0.101
11.76,-1.77,0.101
11.79,-1.63,0.101
11.82,-1.49,0.101
11.84,-1.35,0.101
11.87,-1.21,0.101
11.90,-1.07,0.101
11.93,-0.92,0.101
11.96,-0.78,0.101
11.98,-0.64,0.101
12.01,-0.50,0.101
12.04,-0.36,0.101
12.07,-0.21,0.101
12.10,-0.07,0.101
12.13,0.07,0.101
12.15,0.21,0.101
12.18,0.35,0.102
12.21,0.49,0.102
12.24,0.64,0.102
12.27,0.78,0.102
12.30,0.92,0.102
12.33,1.06,0.102
12.35,1.20,0.102
12.38,1.34,0.102
12.41,1.49,0.102
12.44,1.63,0.102
12.47,1.77,0.102
12.50,1.91,0.102
12.52,2.05,0.102
12.55,2.20,0.102
12.58,2.34,0.102
12.61,2.48,0.102
12.64,2.62,0.102
12.67,2.76,0.102
12.69,2.90,0.102
12.72,3.05,0.102
12.75,3.19,0.102
12.78,3.33,0.102
12.81,3.47,0.103
12.83,3.61,0.103
12.86,3.76,0.103
12.89,3.90,0.103
12.92,4.04,0.103
12.95,4.18,0.103
12.98,4.32,0.103
13.00,4.47,0.103
13.03,4.61,0.103
13.06,4.75,0.103
13.09,4.89,0.103
13.12,5.03,0.103
13.15,5.17,0.103
13.18,5.32,0.103
13.20,5.46,0.103
13.23,5.60,0.103
13.26,5.74,0.103
13.29,5.88,0.103
13.32,6.02,0.103
13.35,6.16,0.103
13.37,6.31,0.103
13.40,6.45,0.104
13.43,6.59,0.104
13.46,6.73,0.104
13.49,6.87,0.104
13.52,7.02,0.104
13.54,7.16,0.104
13.57,7.30,0.104
13.60,7.44,0.104
13.63,7.58,0.104
13.66,7.72,0.104
13.68,7.87,0.104
13.71,8.01,0.104
13.74,8.15,0.104
13.77,8.29,0.104
13.80,8.44,0.104
13.83,8.58,0.104
13.85,8.72,0.104
13.88,8.86,0.104
13.91,9.00,0.104
13.94,9.14,0.105
13.97,9.29,0.105
14.00,9.43,0.105
14.03,9.57,0.105
14.05,9.71,0.105
14.08,9.85,0.105
14.11,9.99,0.105
14.14,10.13,0.105
14.17,10.28,0.105
14.20,10.42,0.105
14.22,10.56,0.105
14.25,10.70,0.105
14.28,10.84,0.105
14.31,10.99,0.105
14.34,11.13,0.105
14.37,11.27,0.105
14.39,11.41,0.105
14.42,11.55,0.106
14.45,11.69,0.106
14.48,11.84,0.106
14.51,11.98,0.106
14.53,12.12,0.106
14.56,12.26,0.106
14.59,12.40,0.106
14.62,12.54,0.106
14.65,12.69,0.106
14.68,12.83,0.106
14.70,12.97,0.106
14.73,13.11,0.107
14.76,13.25,0.107
14.79,13.40,0.107
14.82,13.54,0.107
14.85,13.68,0.107
14.88,13.82,0.107
14.90,13.96,0.107
14.93,14.11,0.107
14.96,14.25,0.107
14.99,14.39,0.107
15.02,14.53,0.107
15.05,14.67,0.107
15.07,14.81,0.107
15.10,14.96,0.108
15.13,15.10,0.108
15.16,15.24,0.108
15.19,15.38,0.108
15.22,15.52,0.108
15.24,15.66,0.108
15.27,15.80,0.108
15.30,15.95,0.108
15.33,16.09,0.108
15.36,16.23,0.108
15.38,16.37,0.108
15.41,16.51,0.108
15.44,16.66,0.109
15.47,16.80,0.109
15.50,16.94,0.109
15.53,17.08,0.109
15.55,17.22,0.109
15.58,17.36,0.109
15.61,17.51,0.109
15.64,17.65,0.109
15.67,17.79,0.110
15.70,17.93,0.110
15.73,18.07,0.110
15.75,18.21,0.110
15.78,18.36,0.110
15.81,18.50,0.110
15.84,18.64,0.111
15.87,18.78,0.111
15.90,18.92,0.111
15.92,19.06,0.111
15.95,19.21,0.111
15.98,19.35,0.111
16.01,19.49,0.111
16.04,19.63,0.112
16.07,19.77,0.112
16.09,19.91,0.112
16.12,20.06,0.112
16.15,20.20,0.112
16.18,20.34,0.112
16.21,20.48,0.113
16.23,20.62,0.113
16.26,20.77,0.113
16.29,20.91,0.113
16.32,21.05,0.113
16.35,21.19,0.113
16.38,21.33,0.114
16.40,21.47,0.114
16.43,21.61,0.114
16.46,21.76,0.114
16.49,21.90,0.114
16.52,22.04,0.114
16.55,22.18,0.114
16.58,22.32,0.115
16.60,22.47,0.115
16.63,22.61,0.115
16.66,22.75,0.115
16.69,22.89,0.115
16.72,23.03,0.115
16.75,23.17,0.116
16.77,23.32,0.116
16.80,23.46,0.116
16.83,23.60,0.116
16.86,23.74,0.116
16.89,23.88,0.116
16.92,24.02,0.116
16.94,24.17,0.117
16.97,24.31,0.117
17.00,24.45,0.117
17.03,24.59,0.117
17.06,24.73,0.117
17.08,24.88,0.117
17.11,25.02,0.117
17.14,25.16,0.117
17.17,25.30,0.117
17.20,25.44,0.118
17.23,25.58,0.118
17.26,25.73,0.118
17.28,25.87,0.118
17.31,26.01,0.118
17.34,26.15,0.118
17.37,26.29,0.118
17.40,26.44,0.118
17.43,26.58,0.118
17.45,26.72,0.119
17.48,26.86,0.119
17.51,27.00,0.119
17.54,27.14,0.119
17.57,27.28,0.119
17.59,27.43,0.119
17.62,27.57,0.119
17.65,27.71,0.119
17.68,27.85,0.119
17.71,27.99,0.119
17.74,28.14,0.119
17.77,28.28,0.119
17.79,28.42,0.119
17.82,28.56,0.119
17.85,28.70,0.120
17.88,28.84,0.120
17.91,28.99,0.120
17.93,29.13,0.120
17.96,29.27,0.120
17.99,29.41,0.120
18.02,29.55,0.120
18.05,29.69,0.120
18.08,29.84,0.120
18.11,29.98,0.120
18.13,30.12,0.120
18.16,30.26,0.121
18.19,30.40,0.121
18.22,30.54,0.121
18.25,30.68,0.121
18.28,30.83,0.121
18.30,30.97,0.121
18.33,31.11,0.121
18.36,31.25,0.121
18.39,31.39,0.121
18.42,31.54,0.121
18.44,31.68,0.122
18.47,31.82,0.122
18.50,31.96,0.122
18.53,32.11,0.122
18.56,32.25,0.122
18.59,32.39,0.122
18.62,32.53,0.123
18.64,32.67,0.123
18.67,32.81,0.123
18.70,32.95,0.123
18.73,33.09,0.123
18.76,33.24,0.124
18.78,33.38,0.124
18.81,33.52,0.124
18.84,33.66,0.124
18.87,33.80,0.125
18.90,33.95,0.125
18.93,34.09,0.125
18.96,34.23,0.125
18.98,34.37,0.126
19.01,34.51,0.126
19.04,34.65,0.126
19.07,34.79,0.127
19.10,34.94,0.127
19.13,35.08,0.127
19.15,35.22,0.127
19.18,35.36,0.128
19.21,35.50,0.128
19.24,35.65,0.129
19.27,35.79,0.129
19.29,35.93,0.129
19.32,36.07,0.130
19.35,36.21,0.130
19.38,36.35,0.130
19.41,36.49,0.131
19.44,36.64,0.131
19.47,36.78,0.132
19.49,36.92,0.132
19.52,37.06,0.133
19.55,37.20,0.133
19.58,37.34,0.133
19.61,37.48,0.134
19.63,37.63,0.134
19.66,37.77,0.135
19.69,37.91,0.135
19.72,38.05,0.136
19.75,38.19,0.136
19.78,38.34,0.137
19.81,38.48,0.137
19.83,38.62,0.138
19.86,38.76,0.138
19.89,38.90,0.139
19.92,39.04,0.139
19.95,39.19,0.140
19.98,39.33,0.140
20.00,39.47,0.141
20.03,39.61,0.141
20.06,39.75,0.142
20.09,39.89,0.142
20.12,40.03,0.142
20.14,40.18,0.143
20.17,40.32,0.143
20.20,40.46,0.144
20.23,40.60,0.144
20.26,40.74,0.145
20.29,40.88,0.145
20.32,41.03,0.146
20.34,41.17,0.147
20.37,41.31,0.147
20.40,41.45,0.148
20.43,41.59,0.149
20.46,41.73,0.149
20.48,41.87,0.150
20.51,42.02,0.150
20.54,42.16,0.151
20.57,42.30,0.151
20.60,42.44,0.152
20.63,42.58,0.153
20.66,42.72,0.153
20.68,42.86,0.154
20.71,43.01,0.155
20.74,43.15,0.155
20.77,43.29,0.156
20.80,43.43,0.157
20.83,43.57,0.157
20.85,43.71,0.158
20.88,43.86,0.159
20.91,44.00,0.159
20.94,44.14,0.160
20.97,44.28,0.161
20.99,44.42,0.162
21.02,44.56,0.163
21.05,44.70,0.164
21.08,44.84,0.164
21.11,44.99,0.165
21.14,45.13,0.166
21.17,45.27,0.167
21.19,45.41,0.169
21.22,45.55,0.170
21.25,45.69,0.172
21.28,45.84,0.173
21.31,45.98,0.174
21.33,46.12,0.175
21.36,46.26,0.176
21.39,46.40,0.177
21.42,46.54,0.178
21.45,46.68,0.179
21.48,46.83,0.181
21.51,46.97,0.182
21.53,47.11,0.184
21.56,47.25,0.185
21.59,47.39,0.186
21.62,47.53,0.188
21.65,47.67,0.189
21.68,47.81,0.191
21.70,47.96,0.193
21.73,48.10,0.194
21.76,48.24,0.196
21.79,48.38,0.198
21.82,48.52,0.199
21.84,48.66,0.201
21.87,48.80,0.204
21.90,48.94,0.206
21.93,49.08,0.207
21.96,49.23,0.210
21.99,49.37,0.212
22.02,49.51,0.214
22.04,49.65,0.215
22.07,49.79,0.217
22.10,49.93,0.219
22.13,50.07,0.221
22.16,50.21,0.223
22.18,50.35,0.226
22.21,50.49,0.228
22.24,50.63,0.230
22.27,50.78,0.232
22.30,50.92,0.234
22.33,51.06,0.236
22.36,51.20,0.238
22.38,51.34,0.241
22.41,51.48,0.243
22.44,51.62,0.245
22.47,51.76,0.247
22.50,51.90,0.249
22.53,52.05,0.252
22.55,52.19,0.255
22.58,52.33,0.257
22.61,52.47,0.260
22.64,52.61,0.262
22.67,52.75,0.264
22.69,52.89,0.267
22.72,53.03,0.269
22.75,53.17,0.272
22.78,53.31,0.275
22.81,53.46,0.277
22.84,53.59,0.280
22.87,53.74,0.281
22.89,53.88,0.284
22.92,54.02,0.286
22.95,54.16,0.288
22.98,54.30,0.289
23.01,54.44,0.291
23.03,54.58,0.293
23.06,54.72,0.295
23.09,54.86,0.297
23.12,55.01,0.299
23.15,55.15,0.302
23.18,55.29,0.303
23.21,55.43,0.305
23.23,55.57,0.307
23.26,55.71,0.309
23.29,55.85,0.311
23.32,55.99,0.313
23.35,56.13,0.316
23.38,56.27,0.318
23.40,56.42,0.321
23.43,56.56,0.325
23.46,56.70,0.330
23.49,56.84,0.334
23.52,56.98,0.336
23.54,57.12,0.340
23.57,57.26,0.344
23.60,57.40,0.349
23.63,57.54,0.355
23.66,57.68,0.362
23.69,57.82,0.370
23.72,57.96,0.375
23.74,58.10,0.378
23.77,58.24,0.378
23.80,58.38,0.378
23.83,58.52,0.377
23.86,58.67,0.377
23.88,58.81,0.375
23.91,58.95,0.373
23.94,59.09,0.369
23.97,59.24,0.366
24.00,59.38,0.361
24.03,59.52,0.359
24.06,59.66,0.355
24.08,59.81,0.351
24.11,59.95,0.348
24.14,60.09,0.345
24.17,60.24,0.340
24.20,60.38,0.336
24.23,60.52,0.331
24.25,60.67,0.328
24.28,60.81,0.322
24.31,60.95,0.318
24.34,61.10,0.314
24.37,61.24,0.309
24.39,61.38,0.305
24.42,61.53,0.302
24.45,61.67,0.299
24.48,61.81,0.297
24.51,61.96,0.295
24.54,62.10,0.295
24.57,62.24,0.294
24.59,62.38,0.294
24.62,62.52,0.294
24.65,62.66,0.294
24.68,62.81,0.294
24.71,62.95,0.294
24.73,63.09,0.294
24.76,63.23,0.294
24.79,63.37,0.293
24.82,63.52,0.293
24.85,63.66,0.292
24.88,63.80,0.291
24.91,63.94,0.290
24.93,64.09,0.287
24.96,64.23,0.282
24.99,64.37,0.275
25.02,64.52,0.268
25.05,64.66,0.259
25.08,64.80,0.250
25.10,64.95,0.238
25.13,65.09,0.229
25.16,65.24,0.219
25.19,65.38,0.209
25.22,65.53,0.201
25.24,65.67,0.192
25.27,65.82,0.186
25.30,65.96,0.180
25.33,66.11,0.176
25.36,66.25,0.172
25.39,66.39,0.169
25.42,66.54,0.168
25.44,66.68,0.165
25.47,66.82,0.164
25.50,66.96,0.163
25.53,67.11,0.163
25.56,67.25,0.162
25.58,67.39,0.162
25.61,67.53,0.161
25.64,67.67,0.161
25.67,67.82,0.161
25.70,67.96,0.160
25.73,68.10,0.160
25.76,68.24,0.160
25.78,68.39,0.159
25.81,68.53,0.159
25.84,68.67,0.159
25.87,68.81,0.159
25.90,68.95,0.159
25.93,69.09,0.158
25.95,69.24,0.158
25.98,69.38,0.158
26.01,69.52,0.158
26.04,69.66,0.158
26.07,69.80,0.158
26.09,69.94,0.158
26.12,70.09,0.158
26.15,70.23,0.158
26.18,70.37,0.158
26.21,70.51,0.158
26.24,70.65,0.158
26.27,70.79,0.158
26.29,70.94,0.158
26.32,71.08,0.158
26.35,71.22,0.158
26.38,71.36,0.158
26.41,71.50,0.158
26.43,71.64,0.158
26.46,71.79,0.158
26.49,71.93,0.158
26.52,72.07,0.158
26.55,72.21,0.158
26.58,72.35,0.158
26.61,72.49,0.158
26.63,72.64,0.158
26.66,72.78,0.158
26.69,72.92,0.158
26.72,73.06,0.158
26.75,73.20,0.159
26.78,73.34,0.159
26.80,73.49,0.159
26.83,73.63,0.159
26.86,73.77,0.159
26.89,73.91,0.159
26.92,74.05,0.159
26.94,74.19,0.159
26.97,74.34,0.159
27.00,74.48,0.159
27.03,74.62,0.159
27.06,74.76,0.159
27.09,74.90,0.159
27.12,75.04,0.159
27.14,75.19,0.159
27.17,75.33,0.159
27.20,75.47,0.159
27.23,75.61,0.159
27.26,75.75,0.159
27.28,75.89,0.159
27.31,76.04,0.159
27.34,76.18,0.159
27.37,76.32,0.160
27.40,76.46,0.160
27.43,76.60,0.160
27.46,76.75,0.160
27.48,76.89,0.160
27.51,77.03,0.160
27.54,77.17,0.160
27.57,77.31,0.160
27.60,77.45,0.160
27.63,77.59,0.160
27.65,77.74,0.160
27.68,77.88,0.160
27.71,78.02,0.160
27.74,78.16,0.160
27.77,78.31,0.160
27.79,78.45,0.160
27.82,78.59,0.160
27.85,78.73,0.160
27.88,78.87,0.160
27.91,79.01,0.160
27.94,79.16,0.160
27.97,79.30,0.160
27.99,79.44,0.160
28.02,79.58,0.160
28.05,79.72,0.161
28.08,79.86,0.161
28.11,80.01,0.161
28.13,80.15,0.161
28.16,80.29,0.161
28.19,80.43,0.161
28.22,80.57,0.161
28.25,80.71,0.161
28.28,80.86,0.161
28.31,81.00,0.161
28.33,81.14,0.161
28.36,81.28,0.161
28.39,81.42,0.161
28.42,81.57,0.161
28.45,81.71,0.161
28.48,81.85,0.161
28.50,81.99,0.161
28.53,82.13,0.161
28.56,82.27,0.161
28.59,82.42,0.161
28.62,82.56,0.161
28.64,82.70,0.161
28.67,82.84,0.161
28.70,82.98,0.161
28.73,83.12,0.161
28.76,83.27,0.161
28.79,83.41,0.161
28.82,83.55,0.161
28.84,83.69,0.161
28.87,83.83,0.161
28.90,83.97,0.161
28.93,84.12,0.161
28.96,84.26,0.161
28.98,84.40,0.161
29.01,84.54,0.161
29.04,84.68,0.161
29.07,84.82,0.161
29.10,84.97,0.161
29.13,85.11,0.161
29.16,85.25,0.161
29.18,85.39,0.161
29.21,85.53,0.161
29.24,85.68,0.161
29.27,85.82,0.162
29.30,85.96,0.161
29.33,86.10,0.162
29.35,86.24,0.162
29.38,86.38,0.162
29.41,86.52,0.162
29.44,86.67,0.162
29.47,86.81,0.162
29.49,86.95,0.162
29.52,87.09,0.162
29.55,87.23,0.162
29.58,87.38,0.162
29.61,87.52,0.162
29.64,87.66,0.162
29.67,87.80,0.162
29.69,87.94,0.162
29.72,88.09,0.162
29.75,88.23,0.162
29.78,88.37,0.162
29.81,88.51,0.162
29.83,88.65,0.162
29.86,88.79,0.162
29.89,88.93,0.162
29.92,89.08,0.162
29.95,89.22,0.162
29.98,89.36,0.162
30.01,89.50,0.162
30.03,89.64,0.162
30.06,89.79,0.162
30.09,89.93,0.162
30.12,90.07,0.162
30.15,90.21,0.162
30.18,90.35,0.162
30.20,90.50,0.162
30.23,90.64,0.162
30.26,90.78,0.162
30.29,90.92,0.163
30.32,91.06,0.163
30.34,91.20,0.163
30.37,91.35,0.163
30.40,91.49,0.163
30.43,91.63,0.163
30.46,91.77,0.163
30.49,91.91,0.163
30.52,92.05,0.163
30.54,92.20,0.163
30.57,92.34,0.163
30.60,92.48,0.163
30.63,92.62,0.163
30.66,92.76,0.163
30.68,92.90,0.163
30.71,93.05,0.163
30.74,93.19,0.163
30.77,93.33,0.163
30.80,93.47,0.163
30.83,93.61,0.163
30.86,93.75,0.163
30.88,93.90,0.163
30.91,94.04,0.163
30.94,94.18,0.163
30.97,94.32,0.163
31.00,94.46,0.163
31.03,94.60,0.163
31.05,94.75,0.163
31.08,94.89,0.163
31.11,95.03,0.163
31.14,95.17,0.163
31.17,95.31,0.163
31.19,95.46,0.163
31.22,95.60,0.163
31.25,95.74,0.163
31.28,95.88,0.163
31.31,96.02,0.163
31.34,96.16,0.163
31.37,96.30,0.163
31.39,96.45,0.163
31.42,96.59,0.163
31.45,96.73,0.163
31.48,96.87,0.163
31.51,97.02,0.163
31.53,97.16,0.163
31.56,97.30,0.163
31.59,97.44,0.163
31.62,97.58,0.163
31.65,97.72,0.163
31.68,97.87,0.163
31.71,98.01,0.163
31.73,98.15,0.163
31.76,98.29,0.163
31.79,98.43,0.163
31.82,98.57,0.163
31.85,98.72,0.163
31.88,98.86,0.163
31.90,99.00,0.163
31.93,99.14,0.163
31.96,99.28,0.163
31.99,99.42,0.163
32.02,99.57,0.163
32.04,99.71,0.163
32.07,99.85,0.163
32.10,99.99,0.163
32.13,100.13,0.163
32.16,100.27,0.163
32.19,100.42,0.162
32.22,100.56,0.163
32.24,100.70,0.162
32.27,100.84,0.162
32.30,100.98,0.162
32.33,101.12,0.162
32.36,101.27,0.162
32.38,101.41,0.162
32.41,101.55,0.162
32.44,101.69,0.162
32.47,101.84,0.162
32.50,101.98,0.162
32.53,102.12,0.162
32.56,102.26,0.162
32.58,102.40,0.162
32.61,102.54,0.162
32.64,102.69,0.162
32.67,102.83,0.162
32.70,102.97,0.162
32.73,103.11,0.162
32.75,103.25,0.162
32.78,103.39,0.162
32.81,103.54,0.162
32.84,103.68,0.162
32.87,103.82,0.162
32.89,103.96,0.162
32.92,104.10,0.162
32.95,104.24,0.162
32.98,104.39,0.162
33.01,104.53,0.162
33.04,104.67,0.162
33.07,104.81,0.161
33.09,104.95,0.161
33.12,105.10,0.161
33.15,105.24,0.161
33.18,105.38,0.161
33.21,105.52,0.161
33.23,105.66,0.161
33.26,105.80,0.161
33.29,105.94,0.161
33.32,106.09,0.161
33.35,106.23,0.161
33.38,106.37,0.161
33.41,106.51,0.161
33.43,106.65,0.161
33.46,106.80,0.161
33.49,106.94,0.161
33.52,107.08,0.161
33.55,107.22,0.161
33.58,107.36,0.161
33.60,107.50,0.161
33.63,107.64,0.161
33.66,107.79,0.161
33.69,107.93,0.161
33.72,108.07,0.161
33.74,108.21,0.161
33.77,108.35,0.161
33.80,108.50,0.161
33.83,108.64,0.161
33.86,108.78,0.161
33.89,108.92,0.161
33.92,109.06,0.161
33.94,109.21,0.161
33.97,109.35,0.161
34.00,109.49,0.161
34.03,109.63,0.161
34.06,109.77,0.161
34.08,109.91,0.161
34.11,110.05,0.161
34.14,110.20,0.161
34.17,110.34,0.160
34.20,110.48,0.160
34.23,110.62,0.160
34.26,110.76,0.160
34.28,110.91,0.160
34.31,111.05,0.160
34.34,111.19,0.160
34.37,111.33,0.160
34.40,111.47,0.160
34.43,111.61,0.160
34.45,111.76,0.160
34.48,111.90,0.160
34.51,112.04,0.160
34.54,112.18,0.160
34.57,112.32,0.160
34.59,112.46,0.160
34.62,112.61,0.160
34.65,112.75,0.160
34.68,112.89,0.160
34.71,113.03,0.160
34.74,113.17,0.159
34.76,113.31,0.159
34.79,113.46,0.159
34.82,113.60,0.159
34.85,113.74,0.159
34.88,113.88,0.159
34.91,114.02,0.159
34.94,114.17,0.159
34.96,114.31,0.159
34.99,114.45,0.159
35.02,114.59,0.159
35.05,114.73,0.159
35.08,114.87,0.159
35.11,115.02,0.159
35.13,115.16,0.159
35.16,115.30,0.159
35.19,115.44,0.159
35.22,115.58,0.159
35.25,115.73,0.159
35.28,115.87,0.159
35.30,116.01,0.159
35.33,116.15,0.159
35.36,116.29,0.159
35.39,116.43,0.159
35.42,116.58,0.159
35.44,116.72,0.159
35.47,116.86,0.159
35.50,117.00,0.159
35.53,117.14,0.159
35.56,117.28,0.159
35.59,117.43,0.159
35.61,117.57,0.159
35.64,117.71,0.159
35.67,117.85,0.159
35.70,117.99,0.159
35.73,118.14,0.159
35.76,118.28,0.159
35.79,118.42,0.159
35.81,118.56,0.160
35.84,118.70,0.160
35.87,118.84,0.160
35.90,118.99,0.160
35.93,119.13,0.160
35.96,119.27,0.160
35.98,119.41,0.160
36.01,119.55,0.160
36.04,119.69,0.160
36.07,119.83,0.160
36.10,119.98,0.160
36.13,120.12,0.160
36.15,120.26,0.160
36.18,120.40,0.160
36.21,120.54,0.160
36.24,120.69,0.160
36.27,120.83,0.160
36.29,120.97,0.160
36.32,121.11,0.160
36.35,121.25,0.160
36.38,121.40,0.160
36.41,121.54,0.160
36.44,121.68,0.160
36.46,121.82,0.160
36.49,121.96,0.161
36.52,122.10,0.161
36.55,122.24,0.161
36.58,122.39,0.161
36.61,122.53,0.161
36.64,122.67,0.161
36.66,122.81,0.161
36.69,122.95,0.161
36.72,123.09,0.161
36.75,123.24,0.161
36.78,123.38,0.162
36.81,123.52,0.162
36.83,123.66,0.162
36.86,123.80,0.162
36.89,123.94,0.162
36.92,124.09,0.162
36.95,124.23,0.162
36.98,124.37,0.162
37.00,124.51,0.162
37.03,124.65,0.163
37.06,124.79,0.163
37.09,124.94,0.163
37.12,125.08,0.163
37.14,125.22,0.163
37.17,125.36,0.163
37.20,125.50,0.164
37.23,125.65,0.164
37.26,125.79,0.164
37.29,125.93,0.164
37.31,126.07,0.164
37.34,126.21,0.164
37.37,126.35,0.164
37.40,126.49,0.164
37.43,126.64,0.165
37.46,126.78,0.165
37.49,126.92,0.165
37.51,127.06,0.165
37.54,127.20,0.165
37.57,127.35,0.166
37.60,127.49,0.166
37.63,127.63,0.166
37.66,127.77,0.166
37.68,127.91,0.166
37.71,128.05,0.166
37.74,128.20,0.166
37.77,128.34,0.166
37.80,128.48,0.167
37.83,128.62,0.167
37.85,128.76,0.167
37.88,128.90,0.167
37.91,129.04,0.168
37.94,129.19,0.168
37.97,129.33,0.168
37.99,129.47,0.168
38.02,129.61,0.168
38.05,129.75,0.169
38.08,129.90,0.169
38.11,130.04,0.169
38.14,130.18,0.169
38.16,130.32,0.169
38.19,130.46,0.170
38.22,130.60,0.170
38.25,130.75,0.170
38.28,130.89,0.170
38.31,131.03,0.171
38.34,131.17,0.171
38.36,131.31,0.171
38.39,131.45,0.171
38.42,131.60,0.171
38.45,131.74,0.172
38.48,131.88,0.172
38.51,132.02,0.172
38.53,132.16,0.172
38.56,132.30,0.173
38.59,132.44,0.173
38.62,132.59,0.173
38.65,132.73,0.173
38.68,132.87,0.174
38.70,133.01,0.174
38.73,133.15,0.174
38.76,133.29,0.174
38.79,133.44,0.175
38.82,133.58,0.175
38.84,133.72,0.175
38.87,133.86,0.175
38.90,134.00,0.176
38.93,134.14,0.176
38.96,134.28,0.176
38.99,134.43,0.176
39.01,134.57,0.177
39.04,134.71,0.177
39.07,134.85,0.177
39.10,134.99,0.178
39.13,135.13,0.178
39.16,135.28,0.178
39.19,135.42,0.179
39.21,135.56,0.179
39.24,135.70,0.179
39.27,135.84,0.179
39.30,135.98,0.180
39.33,136.13,0.180
39.36,136.27,0.180
39.38,136.41,0.180
39.41,136.55,0.181
39.44,136.69,0.181
39.47,136.83,0.182
39.50,136.98,0.182
39.53,137.12,0.182
39.55,137.26,0.183
39.58,137.40,0.183
39.61,137.54,0.183
39.64,137.68,0.184
39.67,137.83,0.184
39.69,137.97,0.184
39.72,138.11,0.185
39.75,138.25,0.185
39.78,138.39,0.186
39.81,138.54,0.186
39.84,138.68,0.186
39.86,138.82,0.187
39.89,138.96,0.187
39.92,139.10,0.188
39.95,139.24,0.188
39.98,139.38,0.188
40.01,139.52,0.189
40.04,139.67,0.189
40.06,139.81,0.190
40.09,139.95,0.190
40.12,140.09,0.191
40.15,140.23,0.191
40.18,140.37,0.192
40.21,140.52,0.192
40.23,140.66,0.193
40.26,140.80,0.193
40.29,140.94,0.194
40.32,141.08,0.194
40.35,141.22,0.195
40.38,141.36,0.195
40.40,141.51,0.196
40.43,141.65,0.196
40.46,141.79,0.197
40.49,141.93,0.197
40.52,142.07,0.198
40.54,142.21,0.198
40.57,142.35,0.199
40.60,142.50,0.200
40.63,142.64,0.200
40.66,142.78,0.201
40.69,142.92,0.202
40.71,143.06,0.202
40.74,143.20,0.203
40.77,143.35,0.204
40.80,143.49,0.204
40.83,143.63,0.205
40.86,143.77,0.206
40.89,143.91,0.206
40.91,144.05,0.207
40.94,144.20,0.208
40.97,144.34,0.209
41.00,144.48,0.209
41.03,144.62,0.210
41.06,144.76,0.211
41.08,144.90,0.212
41.11,145.04,0.212
41.14,145.19,0.213
41.17,145.33,0.214
41.20,145.47,0.215
41.23,145.61,0.216
41.25,145.75,0.217
41.28,145.89,0.218
41.31,146.03,0.219
41.34,146.17,0.220
41.37,146.32,0.221
41.39,146.46,0.221
41.42,146.60,0.223
41.45,146.74,0.224
41.48,146.88,0.225
41.51,147.02,0.226
41.54,147.17,0.227
41.56,147.31,0.228
41.59,147.45,0.229
41.62,147.59,0.230
41.65,147.73,0.232
41.68,147.87,0.233
41.71,148.01,0.235
41.74,148.15,0.236
41.76,148.30,0.237
41.79,148.44,0.238
41.82,148.58,0.240
41.85,148.72,0.240
41.88,148.86,0.241
41.91,149.00,0.243
41.93,149.14,
41.96,149.28,
41.99,,

[step]
Ramp 10.00 °C/min to -60.00 °C
Time,Temperature,Heat Flow (Normalized)
min,°C,W/g
42.99,150.09,0.039
43.00,150.09,0.039
43.02,150.09,0.039
43.03,150.09,0.039
43.05,150.07,0.039
43.06,150.05,0.039
43.08,150.02,0.036
43.09,149.97,0.010
43.11,149.90,-0.022
43.12,149.82,-0.062
43.14,149.73,-0.106
43.15,149.63,-0.149
43.17,149.53,-0.189
43.18,149.41,-0.222
43.20,149.30,-0.252
43.21,149.17,-0.276
43.23,149.05,-0.298
43.24,148.92,-0.315
43.26,148.79,-0.331
43.27,148.66,-0.344
43.29,148.52,-0.357
43.30,148.38,-0.366
43.32,148.24,-0.378
43.33,148.10,-0.385
43.35,147.96,-0.393
43.36,147.82,-0.398
43.38,147.68,-0.406
43.39,147.53,-0.409
43.41,147.39,-0.414
43.42,147.24,-0.418
43.44,147.10,-0.421
43.45,146.95,-0.424
43.47,146.81,-0.427
43.48,146.66,-0.429
43.50,146.52,-0.432
43.51,146.37,-0.434
43.53,146.22,-0.436
43.54,146.08,-0.437
43.56,145.93,-0.440
43.57,145.78,-0.442
43.59,145.63,-0.442
43.60,145.49,-0.444
43.62,145.34,-0.445
43.63,145.19,-0.446
43.65,145.04,-0.449
43.66,144.89,-0.449
43.68,144.75,-0.450
43.69,144.60,-0.451
43.71,144.45,-0.451
43.72,144.30,-0.453
43.74,144.15,-0.454
43.75,144.01,-0.454
43.77,143.86,-0.455
43.78,143.71,-0.455
43.80,143.56,-0.456
43.81,143.41,-0.456
43.83,143.26,-0.458
43.84,143.12,-0.458
43.86,142.97,-0.459
43.87,142.82,-0.460
43.89,142.67,-0.460
43.90,142.52,-0.461
43.92,142.37,-0.462
43.93,142.22,-0.463
43.95,142.07,-0.463
43.96,141.93,-0.464
43.98,141.78,-0.465
43.99,141.63,-0.465
44.01,141.48,-0.466
44.02,141.33,-0.467
44.04,141.18,-0.467
44.05,141.03,-0.468
44.07,140.88,-0.468
44.08,140.73,-0.469
44.10,140.59,-0.469
44.11,140.43,-0.470
44.13,140.29,-0.470
44.14,140.14,-0.470
44.16,139.99,-0.471
44.17,139.84,-0.471
44.19,139.69,-0.472
44.20,139.54,-0.472
44.22,139.39,-0.472
44.23,139.24,-0.473
44.25,139.09,-0.473
44.26,138.94,-0.474
44.28,138.79,-0.474
44.29,138.64,-0.474
44.31,138.49,-0.475
44.32,138.34,-0.475
44.34,138.19,-0.475
44.35,138.04,-0.476
44.37,137.89,-0.476
44.38,137.75,-0.477
44.40,137.60,-0.477
44.41,137.45,-0.477
44.43,137.30,-0.477
44.44,137.15,-0.478
44.46,137.00,-0.478
44.47,136.85,-0.478
44.49,136.70,-0.479
44.50,136.55,-0.479
44.52,136.40,-0.479
44.53,136.25,-0.480
44.55,136.10,-0.480
44.56,135.95,-0.480
44.58,135.80,-0.480
44.59,135.65,-0.481
44.61,135.50,-0.481
44.62,135.35,-0.481
44.64,135.20,-0.482
44.65,135.05,-0.482
44.67,134.90,-0.482
44.68,134.75,-0.482
44.70,134.61,-0.482
44.71,134.46,-0.483
44.73,134.31,-0.483
44.74,134.16,-0.483
44.76,134.01,-0.483
44.77,133.86,-0.484
44.79,133.71,-0.484
44.80,133.56,-0.484
44.82,133.41,-0.484
44.83,133.26,-0.485
44.85,133.11,-0.485
44.86,132.96,-0.485
44.88,132.81,-0.485
44.89,132.66,-0.485
44.91,132.51,-0.485
44.92,132.36,-0.486
44.94,132.21,-0.486
44.95,132.06,-0.486
44.97,131.91,-0.486
44.98,131.76,-0.486
45.00,131.61,-0.486
45.01,131.46,-0.486
45.03,131.31,-0.486
45.04,131.16,-0.487
45.06,131.01,-0.487
45.07,130.86,-0.487
45.09,130.71,-0.487
45.10,130.56,-0.487
45.12,130.41,-0.487
45.13,130.26,-0.487
45.15,130.11,-0.487
45.16,129.96,-0.488
45.18,129.81,-0.488
45.19,129.67,-0.488
45.21,129.52,-0.488
45.22,129.37,-0.488
45.24,129.21,-0.488
45.25,129.06,-0.488
45.27,128.92,-0.488
45.28,128.77,-0.488
45.30,128.62,-0.488
45.31,128.47,-0.488
45.33,128.32,-0.488
45.34,128.17,-0.488
45.36,128.02,-0.488
45.37,127.87,-0.488
45.39,127.72,-0.488
45.40,127.57,-0.488
45.42,127.42,-0.488
45.43,127.27,-0.488
45.45,127.12,-0.489
45.46,126.97,-0.489
45.48,126.82,-0.489
45.49,126.67,-0.489
45.51,126.52,-0.489
45.52,126.37,-0.489
45.54,126.22,-0.489
45.55,126.07,-0.489
45.57,125.92,-0.489
45.58,125.77,-0.489
45.60,125.62,-0.489
45.61,125.47,-0.488
45.63,125.32,-0.489
45.64,125.17,-0.488
45.66,125.02,-0.488
45.67,124.87,-0.488
45.69,124.72,-0.488
45.70,124.57,-0.488
45.72,124.42,-0.488
45.73,124.27,-0.488
45.75,124.12,-0.488
45.76,123.97,-0.488
45.78,123.82,-0.488
45.79,123.67,-0.488
45.81,123.52,-0.488
45.82,123.37,-0.488
45.84,123.22,-0.488
45.85,123.07,-0.488
45.87,122.92,-0.488
45.88,122.77,-0.488
45.90,122.62,-0.488
45.91,122.47,-0.488
45.93,122.32,-0.488
45.94,122.17,-0.488
45.96,122.02,-0.487
45.97,121.87,-0.487
45.99,121.72,-0.487
46.00,121.57,-0.487
46.02,121.43,-0.487
46.03,121.27,-0.487
46.05,121.13,-0.487
46.06,120.97,-0.487
46.08,120.83,-0.487
46.09,120.68,-0.487
46.11,120.53,-0.487
46.12,120.38,-0.486
46.14,120.23,-0.486
46.15,120.08,-0.486
46.17,119.93,-0.486
46.18,119.78,-0.486
46.20,119.63,-0.486
46.21,119.48,-0.486
46.23,119.33,-0.486
46.24,119.18,-0.486
46.26,119.03,-0.486
46.27,118.88,-0.486
46.29,118.73,-0.486
46.30,118.58,-0.486
46.32,118.43,-0.485
46.33,118.28,-0.485
46.35,118.13,-0.485
46.36,117.98,-0.485
46.38,117.83,-0.485
46.39,117.68,-0.485
46.41,117.53,-0.485
46.42,117.38,-0.485
46.44,117.23,-0.485
46.45,117.08,-0.485
46.47,116.93,-0.485
46.48,116.78,-0.484
46.50,116.63,-0.484
46.51,116.48,-0.484
46.53,116.33,-0.484
46.54,116.18,-0.484
46.56,116.03,-0.484
46.57,115.88,-0.484
46.59,115.73,-0.484
46.60,115.58,-0.483
46.62,115.43,-0.483
46.63,115.28,-0.483
46.65,115.13,-0.483
46.66,114.98,-0.483
46.68,114.83,-0.483
46.69,114.68,-0.483
46.71,114.53,-0.483
46.72,114.38,-0.483
46.74,114.23,-0.483
46.75,114.08,-0.482
46.77,113.93,-0.482
46.78,113.78,-0.482
46.80,113.63,-0.482
46.81,113.48,-0.482
46.83,113.33,-0.482
46.84,113.18,-0.482
46.86,113.03,-0.482
46.87,112.88,-0.481
46.89,112.73,-0.481
46.90,112.58,-0.481
46.92,112.43,-0.481
46.93,112.28,-0.481
46.95,112.14,-0.481
46.96,111.98,-0.481
46.98,111.84,-0.481
46.99,111.68,-0.481
47.01,111.53,-0.480
47.02,111.38,-0.480
47.04,111.23,-0.480
47.05,111.09,-0.480
47.07,110.93,-0.480
47.08,110.79,-0.480
47.10,110.64,-0.480
47.11,110.48,-0.480
47.13,110.34,-0.480
47.14,110.18,-0.479
47.16,110.04,-0.479
47.17,109.89,-0.479
47.19,109.74,-0.479
47.20,109.59,-0.479
47.22,109.44,-0.479
47.23,109.29,-0.479
47.25,109.14,-0.478
47.26,108.99,-0.478
47.28,108.84,-0.478
47.29,108.69,-0.478
47.31,108.54,-0.478
47.32,108.39,-0.478
47.34,108.24,-0.478
47.35,108.09,-0.478
47.37,107.94,-0.478
47.38,107.79,-0.477
47.40,107.64,-0.477
47.41,107.49,-0.477
47.43,107.34,-0.477
47.44,107.19,-0.477
47.46,107.04,-0.477
47.47,106.89,-0.477
47.49,106.74,-0.477
47.50,106.59,-0.476
47.52,106.44,-0.476
47.53,106.29,-0.476
47.55,106.14,-0.476
47.56,105.99,-0.476
47.58,105.84,-0.476
47.59,105.69,-0.475
47.61,105.54,-0.475
47.62,105.39,-0.475
47.64,105.24,-0.475
47.65,105.09,-0.475
47.67,104.94,-0.475
47.68,104.79,-0.474
47.70,104.64,-0.474
47.71,104.49,-0.474
47.73,104.34,-0.474
47.74,104.19,-0.474
47.76,104.04,-0.474
47.77,103.89,-0.474
47.79,103.74,-0.474
47.80,103.59,-0.473
47.82,103.44,-0.473
47.83,103.29,-0.473
47.85,103.14,-0.473
47.86,102.99,-0.473
47.88,102.84,-0.473
47.89,102.69,-0.473
47.91,102.54,-0.472
47.92,102.39,-0.472
47.94,102.24,-0.472
47.95,102.09,-0.472
47.97,101.94,-0.472
47.98,101.79,-0.472
48.00,101.64,-0.471
[...]
142.62,2.49,0.143
142.65,2.63,0.144
142.68,2.77,0.144
142.71,2.91,0.145
142.74,3.05,0.145
142.77,3.19,0.146
142.79,3.34,0.146
142.82,3.48,0.146
142.85,3.62,0.147
142.88,3.76,0.147
142.91,3.90,0.148
142.93,4.04,0.148
142.96,4.19,0.148
142.99,4.33,0.149
143.02,4.47,0.149
143.05,4.61,0.150
143.08,4.75,0.150
143.10,4.89,0.150
143.13,5.04,0.151
143.16,5.18,0.151
143.19,5.32,0.151
143.22,5.46,0.152
143.25,5.60,0.152
143.28,5.74,0.152
143.30,5.89,0.153
143.33,6.03,0.153
143.36,6.17,0.153
143.39,6.31,0.154
143.42,6.45,0.154
143.45,6.59,0.154
143.47,6.73,0.155
143.50,6.88,0.155
143.53,7.02,0.155
143.56,7.16,0.155
143.59,7.30,0.156
143.62,7.44,0.156
143.64,7.59,0.156
143.67,7.73,0.156
143.70,7.87,0.157
143.73,8.01,0.157
143.76,8.15,0.157
143.78,8.29,0.158
143.81,8.44,0.158
143.84,8.58,0.158
143.87,8.72,0.158
143.90,8.86,0.158
143.93,9.00,0.158
143.95,9.14,0.159
143.98,9.29,0.159
144.01,9.43,0.159
144.04,9.57,0.159
144.07,9.71,0.159
144.10,9.85,0.159
144.13,10.00,0.159
144.15,10.14,0.160
144.18,10.28,0.160
144.21,10.42,0.160
144.24,10.56,0.160
144.27,10.70,0.160
144.30,10.85,0.160
144.32,10.99,0.160
144.35,11.13,0.160
144.38,11.27,0.160
144.41,11.41,0.160
144.44,11.56,0.160
144.47,11.70,0.160
144.49,11.84,0.160
144.52,11.98,0.160
144.55,12.12,0.160
144.58,12.27,0.160
144.61,12.40,0.160
144.63,12.55,0.160
144.66,12.69,0.160
144.69,12.83,0.160
144.72,12.97,0.160
144.75,13.11,0.160
144.78,13.26,0.160
144.80,13.40,0.160
144.83,13.54,0.160
144.86,13.68,0.160
144.89,13.82,0.160
144.92,13.96,0.160
144.95,14.11,0.160
144.98,14.25,0.160
145.00,14.39,0.160
145.03,14.53,0.160
145.06,14.67,0.160
145.09,14.81,0.160
145.12,14.96,0.160
145.15,15.10,0.160
145.17,15.24,0.160
145.20,15.38,0.160
145.23,15.52,0.160
145.26,15.67,0.160
145.29,15.81,0.160
145.32,15.95,0.160
145.34,16.09,0.160
145.37,16.23,0.160
145.40,16.38,0.160
145.43,16.52,0.160
145.46,16.66,0.160
145.48,16.80,0.160
145.51,16.94,0.160
145.54,17.08,0.160
145.57,17.23,0.160
145.60,17.37,0.160
145.63,17.51,0.160
145.65,17.65,0.160
145.68,17.79,0.160
145.71,17.94,0.160
145.74,18.08,0.160
145.77,18.22,0.160
145.80,18.36,0.160
145.83,18.50,0.160
145.85,18.64,0.160
145.88,18.79,0.160
145.91,18.93,0.160
145.94,19.07,0.161
145.97,19.21,0.161
146.00,19.35,0.161
146.02,19.49,0.161
146.05,19.64,0.161
146.08,19.78,0.161
146.11,19.92,0.161
146.14,20.06,0.161
146.17,20.20,0.161
146.19,20.34,0.161
146.22,20.49,0.161
146.25,20.63,0.161
146.28,20.77,0.161
146.31,20.91,0.161
146.33,21.05,0.161
146.36,21.19,0.161
146.39,21.34,0.161
146.42,21.48,0.161
146.45,21.62,0.161
146.48,21.76,0.161
146.50,21.90,0.161
146.53,22.05,0.162
146.56,22.19,0.162
146.59,22.33,0.162
146.62,22.47,0.162
146.65,22.61,0.162
146.68,22.75,0.162
146.70,22.90,0.162
146.73,23.04,0.162
146.76,23.18,0.162
146.79,23.32,0.162
146.82,23.46,0.162
146.85,23.61,0.162
146.87,23.75,0.162
146.90,23.89,0.162
146.93,24.03,0.162
146.96,24.17,0.162
146.99,24.31,0.162
147.02,24.45,0.163
147.04,24.60,0.163
147.07,24.74,0.163
147.10,24.88,0.163
147.13,25.02,0.163
147.16,25.16,0.163
147.18,25.31,0.163
147.21,25.45,0.163
147.24,25.59,0.163
147.27,25.73,0.163
147.30,25.87,0.163
147.33,26.02,0.163
147.35,26.16,0.163
147.38,26.30,0.163
147.41,26.44,0.163
147.44,26.58,0.163
147.47,26.73,0.163
147.50,26.87,0.163
147.53,27.01,0.163
147.55,27.15,0.163
147.58,27.29,0.163
147.61,27.43,0.163
147.64,27.57,0.163
147.67,27.72,0.163
147.70,27.86,0.163
147.72,28.00,0.164
147.75,28.14,0.164
147.78,28.28,0.164
147.81,28.43,0.164
147.84,28.57,0.164
147.87,28.71,0.164
147.89,28.85,0.164
147.92,28.99,0.164
147.95,29.14,0.164
147.98,29.28,0.164
148.01,29.42,0.164
148.03,29.56,0.164
148.06,29.70,0.164
148.09,29.84,0.164
148.12,29.99,0.164
148.15,30.13,0.164
148.18,30.27,0.164
148.20,30.41,0.164
148.23,30.55,0.164
148.26,30.69,0.164
148.29,30.84,0.164
148.32,30.98,0.165
148.35,31.12,0.165
148.38,31.26,0.165
148.40,31.40,0.165
148.43,31.55,0.165
148.46,31.69,0.165
148.49,31.83,0.165
148.52,31.97,0.165
148.55,32.11,0.165
148.57,32.25,0.165
148.60,32.40,0.165
148.63,32.54,0.165
148.66,32.68,0.165
148.69,32.82,0.165
148.72,32.96,0.165
148.74,33.10,0.165
148.77,33.25,0.165
148.80,33.39,0.165
148.83,33.53,0.165
148.86,33.67,0.166
148.88,33.81,0.166
148.91,33.95,0.166
148.94,34.10,0.166
148.97,34.24,0.166
149.00,34.38,0.166
149.03,34.52,0.166
149.05,34.66,0.166
149.08,34.81,0.166
149.11,34.95,0.166
149.14,35.09,0.166
149.17,35.23,0.166
149.20,35.37,0.166
149.23,35.51,0.166
149.25,35.65,0.166
149.28,35.80,0.166
149.31,35.94,0.166
149.34,36.08,0.166
149.37,36.22,0.166
149.40,36.36,0.166
149.42,36.51,0.167
149.45,36.65,0.167
149.48,36.79,0.167
149.51,36.93,0.167
149.54,37.07,0.167
149.57,37.22,0.167
149.59,37.36,0.167
149.62,37.50,0.167
149.65,37.64,0.167
149.68,37.78,0.167
149.71,37.92,0.167
149.73,38.07,0.167
149.76,38.21,0.167
149.79,38.35,0.167
149.82,38.49,0.167
149.85,38.63,0.167
149.88,38.77,0.167
149.90,38.92,0.167
149.93,39.06,0.167
149.96,39.20,0.167
149.99,39.34,0.167
150.02,39.48,0.167
150.05,39.62,0.167
150.08,39.77,0.168
150.10,39.91,0.168
150.13,40.05,0.168
150.16,40.19,0.168
150.19,40.33,0.168
150.22,40.48,0.168
150.25,40.62,0.168
150.27,40.76,0.168
150.30,40.90,0.168
150.33,41.04,0.168
150.36,41.18,0.168
150.39,41.33,0.168
150.42,41.47,0.168
150.44,41.61,0.168
150.47,41.75,0.168
150.50,41.89,0.168
150.53,42.03,0.168
150.56,42.18,0.168
150.58,42.32,0.168
150.61,42.46,0.168
150.64,42.60,0.169
150.67,42.74,0.169
150.70,42.89,0.169
150.73,43.03,0.169
150.75,43.17,0.169
150.78,43.31,0.169
150.81,43.45,0.169
150.84,43.60,0.169
150.87,43.74,0.169
150.90,43.88,0.169
150.93,44.02,0.169
150.95,44.16,0.169
150.98,44.31,0.169
151.01,44.45,0.169
151.04,44.59,0.169
151.07,44.73,0.169
151.10,44.87,0.170
151.12,45.01,0.170
151.15,45.16,0.170
151.18,45.30,0.170
151.21,45.44,0.170
151.24,45.58,0.170
151.27,45.72,0.170
151.29,45.86,0.170
151.32,46.01,0.170
151.35,46.15,0.170
151.38,46.29,0.170
151.41,46.43,0.170
151.43,46.57,0.170
151.46,46.71,0.170
151.49,46.85,0.170
151.52,47.00,0.170
151.55,47.14,0.170
151.58,47.28,0.170
151.60,47.42,0.170
151.63,47.56,0.170
151.66,47.71,0.170
151.69,47.85,0.170
151.72,47.99,0.170
151.75,48.13,0.170
151.78,48.27,0.170
151.80,48.41,0.170
151.83,48.56,0.170
151.86,48.70,0.170
151.89,48.84,0.170
151.92,48.98,0.170
151.95,49.12,0.170
151.97,49.26,0.171
152.00,49.41,0.171
152.03,49.55,0.171
152.06,49.69,0.171
152.09,49.83,0.171
152.12,49.97,0.171
152.14,50.11,0.171
152.17,50.26,0.171
152.20,50.40,0.171
152.23,50.54,0.171
152.26,50.68,0.171
152.28,50.82,0.171
152.31,50.97,0.171
152.34,51.11,0.171
152.37,51.25,0.171
152.40,51.39,0.171
152.43,51.53,0.172
152.45,51.67,0.172
152.48,51.82,0.172
152.51,51.96,0.172
152.54,52.10,0.172
152.57,52.24,0.172
152.60,52.38,0.172
152.63,52.52,0.172
152.65,52.67,0.172
152.68,52.81,0.172
152.71,52.95,0.172
152.74,53.09,0.172
152.77,53.23,0.172
152.80,53.38,0.172
152.82,53.52,0.172
152.85,53.66,0.172
152.88,53.80,0.172
152.91,53.94,0.172
152.94,54.08,0.173
152.97,54.23,0.173
152.99,54.37,0.173
153.02,54.51,0.173
153.05,54.65,0.173
153.08,54.79,0.173
153.11,54.93,0.173
153.13,55.08,0.173
153.16,55.22,0.173
153.19,55.36,0.173
153.22,55.50,0.173
153.25,55.64,0.173
153.28,55.78,0.173
153.30,55.93,0.173
153.33,56.07,0.173
153.36,56.21,0.173
153.39,56.35,0.173
153.42,56.49,0.173
153.45,56.64,0.174
153.48,56.78,0.174
153.50,56.92,0.174
153.53,57.06,0.174
153.56,57.20,0.174
153.59,57.34,0.174
153.62,57.49,0.174
153.65,57.63,0.174
153.67,57.77,0.174
153.70,57.91,0.174
153.73,58.05,0.174
153.76,58.19,0.174
153.79,58.34,0.174
153.82,58.48,0.174
153.84,58.62,0.174
153.87,58.76,0.174
153.90,58.90,0.175
153.93,59.05,0.175
153.96,59.19,0.175
153.98,59.33,0.175
154.01,59.47,0.175
154.04,59.61,0.175
154.07,59.75,0.175
154.10,59.90,0.175
154.13,60.04,0.175
154.15,60.18,0.175
154.18,60.32,0.175
154.21,60.46,0.175
154.24,60.60,0.175
154.27,60.75,0.175
154.30,60.89,0.175
154.33,61.03,0.175
154.35,61.17,0.176
154.38,61.31,0.176
154.41,61.45,0.176
154.44,61.60,0.176
154.47,61.74,0.176
154.50,61.88,0.176
154.52,62.02,0.176
154.55,62.16,0.176
154.58,62.30,0.176
154.61,62.45,0.176
154.64,62.59,0.176
154.67,62.73,0.176
154.69,62.87,0.176
154.72,63.01,0.176
154.75,63.16,0.176
154.78,63.30,0.176
154.81,63.44,0.176
154.83,63.58,0.176
154.86,63.72,0.177
154.89,63.86,0.177
154.92,64.01,0.177
154.95,64.15,0.177
154.98,64.29,0.177
155.00,64.43,0.177
155.03,64.57,0.177
155.06,64.72,0.177
155.09,64.86,0.177
155.12,65.00,0.177
155.15,65.14,0.177
155.18,65.28,0.177
155.20,65.42,0.177
155.23,65.57,0.177
155.26,65.71,0.177
155.29,65.85,0.177
155.32,65.99,0.177
155.35,66.13,0.178
155.37,66.28,0.178
155.40,66.42,0.178
155.43,66.56,0.178
155.46,66.70,0.178
155.49,66.84,0.178
155.52,66.98,0.178
155.54,67.13,0.178
155.57,67.27,0.178
155.60,67.41,0.178
155.63,67.55,0.178
155.66,67.69,0.178
155.68,67.83,0.178
155.71,67.98,0.178
155.74,68.12,0.178
155.77,68.26,0.178
155.80,68.40,0.178
155.83,68.54,0.179
155.85,68.69,0.179
155.88,68.83,0.179
155.91,68.97,0.179
155.94,69.11,0.179
155.97,69.25,0.179
156.00,69.39,0.179
156.03,69.54,0.179
156.05,69.68,0.179
156.08,69.82,0.179
156.11,69.96,0.179
156.14,70.10,0.179
156.17,70.24,0.179
156.20,70.39,0.179
156.22,70.53,0.179
156.25,70.67,0.180
156.28,70.81,0.180
156.31,70.95,0.180
156.34,71.09,0.180
156.37,71.24,0.180
156.39,71.38,0.180
156.42,71.52,0.180
156.45,71.66,0.180
156.48,71.80,0.180
156.51,71.94,0.180
156.53,72.09,0.180
156.56,72.23,0.180
156.59,72.37,0.180
156.62,72.51,0.180
156.65,72.65,0.180
156.68,72.79,0.180
156.70,72.94,0.180
156.73,73.08,0.180
156.76,73.22,0.181
156.79,73.36,0.181
156.82,73.50,0.181
156.85,73.65,0.181
156.88,73.79,0.181
156.90,73.93,0.181
156.93,74.07,0.181
156.96,74.21,0.181
156.99,74.36,0.181
157.02,74.50,0.181
157.05,74.64,0.181
157.07,74.78,0.181
157.10,74.92,0.181
157.13,75.06,0.181
157.16,75.20,0.181
157.19,75.35,0.181
157.22,75.49,0.181
157.24,75.63,0.181
157.27,75.77,0.182
157.30,75.91,0.182
157.33,76.05,0.182
157.36,76.20,0.182
157.38,76.34,0.182
157.41,76.48,0.182
157.44,76.62,0.182
157.47,76.76,0.182
157.50,76.90,0.182
157.53,77.05,0.182
157.55,77.19,0.182
157.58,77.33,0.182
157.61,77.47,0.182
157.64,77.61,0.182
157.67,77.75,0.183
157.70,77.90,0.183
157.73,78.04,0.183
157.75,78.18,0.183
157.78,78.32,0.183
157.81,78.46,0.183
157.84,78.60,0.183
157.87,78.74,0.183
157.90,78.89,0.183
157.92,79.03,0.183
157.95,79.17,0.183
157.98,79.31,0.183
158.01,79.45,0.183
158.04,79.60,0.184
158.07,79.74,0.184
158.09,79.88,0.184
158.12,80.02,0.184
158.15,80.16,0.184
158.18,80.31,0.184
158.21,80.45,0.184
158.23,80.59,0.184
158.26,80.73,0.184
158.29,80.87,0.184
158.32,81.01,0.184
158.35,81.16,0.184
158.38,81.30,0.184
158.40,81.44,0.184
158.43,81.58,0.184
158.46,81.72,0.184
158.49,81.86,0.184
158.52,82.01,0.184
158.55,82.15,0.184
158.58,82.29,0.184
158.60,82.43,0.184
158.63,82.57,0.185
158.66,82.72,0.184
158.69,82.86,0.185
158.72,83.00,0.185
158.75,83.14,0.185
158.77,83.28,0.185
158.80,83.42,0.185
158.83,83.57,0.185
158.86,83.71,0.185
158.89,83.85,0.185
158.92,83.99,0.185
158.94,84.13,0.185
158.97,84.28,0.185
159.00,84.42,0.185
159.03,84.56,0.185
159.06,84.70,0.185
159.08,84.84,0.185
159.11,84.98,0.185
159.14,85.12,0.185
159.17,85.27,0.185
159.20,85.41,0.185
159.23,85.55,0.185
159.25,85.69,0.185
159.28,85.83,0.185
159.31,85.97,0.186
159.34,86.12,0.186
159.37,86.26,0.186
159.40,86.40,0.186
159.43,86.54,0.186
159.45,86.68,0.186
159.48,86.82,0.186
159.51,86.97,0.186
159.54,87.11,0.186
159.57,87.25,0.186
159.60,87.39,0.186
159.62,87.53,0.186
159.65,87.68,0.186
159.68,87.82,0.186
159.71,87.96,0.187
159.74,88.10,0.187
159.77,88.24,0.187
159.79,88.38,0.187
159.82,88.53,0.187
159.85,88.67,0.187
159.88,88.81,0.187
159.91,88.95,0.187
159.93,89.09,0.187
159.96,89.23,0.187
159.99,89.38,0.187
160.02,89.52,0.187
160.05,89.66,0.187
160.08,89.80,0.188
160.10,89.94,0.188
160.13,90.09,0.188
160.16,90.23,0.188
160.19,90.37,0.188
160.22,90.51,0.188
160.25,90.65,0.188
160.28,90.79,0.188
160.30,90.93,0.188
160.33,91.08,0.188
160.36,91.22,0.188
160.39,91.36,0.188
160.42,91.50,0.188
160.45,91.64,0.188
160.47,91.79,0.188
160.50,91.93,0.189
160.53,92.07,0.189
160.56,92.21,0.189
160.59,92.35,0.189
160.62,92.49,0.189
160.64,92.64,0.189
160.67,92.78,0.189
160.70,92.92,0.189
160.73,93.06,0.189
160.76,93.20,0.189
160.78,93.35,0.190
160.81,93.49,0.190
160.84,93.63,0.190
160.87,93.77,0.190
160.90,93.91,0.190
160.93,94.05,0.190
160.95,94.19,0.190
160.98,94.34,0.190
161.01,94.48,0.190
161.04,94.62,0.190
161.07,94.76,0.190
161.10,94.90,0.190
161.13,95.05,0.190
161.15,95.19,0.191
161.18,95.33,0.191
161.21,95.47,0.191
161.24,95.61,0.191
161.27,95.76,0.191
161.30,95.90,0.191
161.32,96.04,0.191
161.35,96.18,0.191
161.38,96.32,0.191
161.41,96.46,0.191
161.44,96.61,0.191
161.47,96.75,0.191
161.49,96.89,0.191
161.52,97.03,0.191
161.55,97.17,0.191
161.58,97.31,0.191
161.61,97.45,0.191
161.63,97.60,0.191
161.66,97.74,0.191
161.69,97.88,0.192
161.72,98.02,0.192
161.75,98.16,0.192
161.78,98.31,0.192
161.80,98.45,0.192
161.83,98.59,0.192
161.86,98.73,0.192
161.89,98.87,0.192
161.92,99.01,0.192
161.95,99.16,0.192
161.98,99.30,0.192
162.00,99.44,0.192
162.03,99.58,0.192
162.06,99.72,0.192
162.09,99.86,0.192
162.12,100.01,0.193
162.15,100.15,0.193
162.17,100.29,0.193
162.20,100.43,0.193
162.23,100.57,0.193
162.26,100.71,0.193
162.29,100.86,0.193
162.32,101.00,0.193
162.34,101.14,0.193
162.37,101.28,0.193
162.40,101.42,0.193
162.43,101.57,0.193
162.46,101.71,0.194
162.48,101.85,0.194
162.51,101.99,0.194
162.54,102.13,0.194
162.57,102.27,0.194
162.60,102.41,0.194
162.63,102.56,0.194
162.65,102.70,0.194
162.68,102.84,0.194
162.71,102.98,0.194
162.74,103.12,0.194
162.77,103.26,0.194
162.80,103.41,0.194
162.83,103.55,0.194
162.85,103.69,0.195
162.88,103.83,0.195
162.91,103.97,0.195
162.94,104.11,0.195
162.97,104.26,0.195
163.00,104.40,0.195
163.02,104.54,0.195
163.05,104.68,0.195
163.08,104.82,0.195
163.11,104.96,0.195
163.14,105.11,0.195
163.17,105.25,0.195
163.19,105.39,0.196
163.22,105.53,0.196
163.25,105.68,0.196
163.28,105.82,0.196
163.31,105.96,0.196
163.33,106.10,0.196
163.36,106.24,0.196
163.39,106.38,0.196
163.42,106.53,0.196
163.45,106.67,0.196
163.48,106.81,0.196
163.50,106.95,0.196
163.53,107.09,0.196
163.56,107.23,0.197
163.59,107.38,0.197
163.62,107.52,0.197
163.65,107.66,0.197
163.68,107.80,0.197
163.70,107.94,0.197
163.73,108.08,0.197
163.76,108.23,0.197
163.79,108.37,0.197
163.82,108.51,0.197
163.85,108.65,0.197
163.87,108.79,0.197
163.90,108.93,0.197
163.93,109.07,0.197
163.96,109.22,0.197
163.99,109.36,0.197
164.02,109.50,0.197
164.04,109.64,0.197
164.07,109.78,0.198
164.10,109.93,0.198
164.13,110.07,0.198
164.16,110.21,0.198
164.18,110.35,0.198
164.21,110.49,0.198
164.24,110.64,0.198
164.27,110.78,0.198
164.30,110.92,0.198
164.33,111.06,0.198
164.35,111.20,0.198
164.38,111.34,0.198
164.41,111.48,0.198
164.44,111.63,0.199
164.47,111.77,0.199
164.50,111.91,0.199
164.53,112.05,0.199
164.55,112.19,0.199
164.58,112.33,0.199
164.61,112.48,0.199
164.64,112.62,0.199
164.67,112.76,0.199
164.70,112.90,0.199
164.72,113.04,0.199
164.75,113.19,0.199
164.78,113.33,0.199
164.81,113.47,0.199
164.84,113.61,0.199
164.87,113.75,0.199
164.89,113.89,0.200
164.92,114.04,0.200
164.95,114.18,0.200
164.98,114.32,0.200
165.01,114.46,0.200
165.03,114.60,0.200
165.06,114.74,0.200
165.09,114.89,0.200
165.12,115.03,0.200
165.15,115.17,0.200
165.18,115.31,0.200
165.20,115.45,0.200
165.23,115.59,0.200
165.26,115.74,0.200
165.29,115.88,0.200
165.32,116.02,0.201
165.35,116.16,0.201
165.38,116.30,0.201
165.40,116.44,0.201
165.43,116.59,0.201
165.46,116.73,0.201
165.49,116.87,0.201
165.52,117.01,0.201
165.55,117.15,0.201
165.57,117.30,0.201
165.60,117.44,0.201
165.63,117.58,0.201
165.66,117.72,0.202
165.69,117.86,0.202
165.72,118.00,0.202
165.74,118.14,0.202
165.77,118.29,0.202
165.80,118.43,0.202
165.83,118.57,0.202
165.86,118.71,0.202
165.88,118.85,0.202
165.91,119.00,0.202
165.94,119.14,0.202
165.97,119.28,0.202
166.00,119.42,0.202
166.03,119.56,0.202
166.05,119.70,0.202
166.08,119.85,0.203
166.11,119.99,0.203
166.14,120.13,0.203
166.17,120.27,0.203
166.20,120.41,0.203
166.23,120.56,0.203
166.25,120.70,0.203
166.28,120.84,0.203
166.31,120.98,0.203
166.34,121.12,0.203
166.37,121.26,0.203
166.40,121.41,0.204
166.42,121.55,0.204
166.45,121.69,0.204
166.48,121.83,0.204
166.51,121.97,0.204
166.54,122.11,0.204
166.57,122.25,0.204
166.59,122.40,0.204
166.62,122.54,0.204
166.65,122.68,0.204
166.68,122.82,0.205
166.71,122.96,0.205
166.73,123.11,0.205
166.76,123.25,0.205
166.79,123.39,0.205
166.82,123.53,0.205
166.85,123.67,0.205
166.88,123.81,0.205
166.90,123.95,0.205
166.93,124.10,0.205
166.96,124.24,0.205
166.99,124.38,0.205
167.02,124.52,0.206
167.05,124.66,0.206
167.08,124.81,0.206
167.10,124.95,0.206
167.13,125.09,0.206
167.16,125.23,0.206
167.19,125.37,0.206
167.22,125.51,0.206
167.25,125.66,0.206
167.27,125.80,0.206
167.30,125.94,0.206
167.33,126.08,0.206
167.36,126.22,0.207
167.39,126.37,0.207
167.42,126.51,0.207
167.44,126.65,0.207
167.47,126.79,0.207
167.50,126.93,0.207
167.53,127.07,0.208
167.56,127.22,0.208
167.58,127.36,0.208
167.61,127.50,0.208
167.64,127.64,0.209
167.67,127.78,0.209
167.70,127.92,0.209
167.73,128.07,0.209
167.75,128.21,0.209
167.78,128.35,0.209
167.81,128.49,0.209
167.84,128.63,0.209
167.87,128.77,0.209
167.90,128.91,0.209
167.93,129.06,0.209
167.95,129.20,0.209
167.98,129.34,0.209
168.01,129.48,0.209
168.04,129.62,0.209
168.07,129.77,0.209
168.10,129.91,0.210
168.12,130.05,0.210
168.15,130.19,0.210
168.18,130.33,0.210
168.21,130.47,0.210
168.24,130.61,0.210
168.27,130.76,0.210
168.29,130.90,0.210
168.32,131.04,0.210
168.35,131.18,0.210
168.38,131.32,0.211
168.41,131.47,0.211
168.43,131.61,0.211
168.46,131.75,0.211
168.49,131.89,0.211
168.52,132.03,0.211
168.55,132.17,0.211
168.58,132.32,0.211
168.60,132.46,0.212
168.63,132.60,0.212
168.66,132.74,0.212
168.69,132.88,0.212
168.72,133.02,0.212
168.75,133.16,0.212
168.78,133.31,0.212
168.80,133.45,0.212
168.83,133.59,0.213
168.86,133.73,0.213
168.89,133.87,0.213
168.92,134.01,0.213
168.95,134.16,0.214
168.97,134.30,0.214
169.00,134.44,0.214
169.03,134.58,0.214
169.06,134.72,0.215
169.09,134.86,0.215
169.12,135.01,0.215
169.14,135.15,0.215
169.17,135.29,0.216
169.20,135.43,0.216
169.23,135.57,0.216
169.26,135.72,0.216
169.28,135.86,0.216
169.31,136.00,0.216
169.34,136.14,0.216
169.37,136.28,0.217
169.40,136.42,0.217
169.43,136.57,0.217
169.45,136.71,0.217
169.48,136.85,0.217
169.51,136.99,0.218
169.54,137.13,0.218
169.57,137.27,0.218
169.60,137.42,0.218
169.63,137.56,0.219
169.65,137.70,0.219
169.68,137.84,0.219
169.71,137.98,0.219
169.74,138.12,0.219
169.77,138.26,0.220
169.80,138.41,0.220
169.82,138.55,0.220
169.85,138.69,0.220
169.88,138.83,0.220
169.91,138.97,0.221
169.94,139.11,0.221
169.97,139.25,0.221
169.99,139.40,0.221
170.02,139.54,0.221
170.05,139.68,0.221
170.08,139.82,0.222
170.11,139.96,0.222
170.13,140.11,0.222
170.16,140.25,0.222
170.19,140.39,0.222
170.22,140.53,0.223
170.25,140.67,0.223
170.28,140.81,0.223
170.30,140.95,0.223
170.33,141.10,0.224
170.36,141.24,0.224
170.39,141.38,0.224
170.42,141.52,0.225
170.45,141.66,0.225
170.48,141.81,0.225
170.50,141.95,0.225
170.53,142.09,0.226
170.56,142.23,0.226
170.59,142.37,0.226
170.62,142.51,0.227
170.65,142.65,0.227
170.67,142.80,0.227
170.70,142.94,0.228
170.73,143.08,0.228
170.76,143.22,0.229
170.79,143.36,0.229
170.82,143.51,0.229
170.84,143.65,0.230
170.87,143.79,0.230
170.90,143.93,0.231
170.93,144.07,0.231
170.96,144.21,0.231
170.98,144.35,0.232
171.01,144.50,0.232
171.04,144.64,0.232
171.07,144.78,0.232
171.10,144.92,0.233
171.13,145.06,0.233
171.15,145.20,0.233
171.18,145.35,0.234
171.21,145.49,0.234
171.24,145.63,0.235
171.27,145.77,0.235
171.30,145.91,0.235
171.33,146.05,0.236
171.35,146.20,0.236
171.38,146.34,0.237
171.41,146.48,0.237
171.44,146.62,0.237
171.47,146.76,0.238
171.50,146.90,0.239
171.52,147.05,0.239
171.55,147.19,0.239
171.58,147.33,0.240
171.61,147.47,0.240
171.64,147.61,0.241
171.67,147.75,0.241
171.69,147.89,0.242
171.72,148.04,0.242
171.75,148.18,0.243
171.78,148.32,0.243
171.81,148.46,0.244
171.83,148.60,0.244
171.86,148.74,0.245
171.89,148.88,0.245
171.92,149.03,0.246
171.95,149.17,
171.98,,
171.98,,