File: DSC/2025_07_16_Indium_30_190_10Cmin_x4.csv
Filename,2025_07_16_Indium_30_190_10Cmin_x4
Instrument name,DSC2A-00468 (192.168.1.100)
Operator,Gibbons
rundate,7/16/2025
Sample name,2025_07_16_Indium_30_190_10Cmin_x4
proceduresegments,Data Off ; Equilibrate 30.00 °C; Data On ; Ramp 10.00 °C/min to 190.00 °C; Data Off ; Isothermal 2.0 min; Data On ; Ramp 10.00 °C/min to 30.00 °C; Data Off ; Isothermal 2.0 min; Data On ; Ramp 10.00 °C/min to 190.00 °C; Data Off ; Isothermal 2.0 min; Data On ; Ramp 10.00 °C/min to 30.00 °C; Data Off ; Isothermal 2.0 min; Data On ; Ramp 10.00 °C/min to 190.00 °C; Data Off ; Isothermal 2.0 min; Data On ; Ramp 10.00 °C/min to 30.00 °C; Data Off
[File Parameters]
Run date,7/16/2025 12:15:26 PM
Trios version,5.1.1.46572
Original File Name,
Current File Name,D:\DSC2500\Gibbons\2025_07_16_Indium_30_190_10Cmin_x4.tri
[Procedure]
Procedure Name,Indium_30_190_10Cmin_x4
Sample Name,2025_07_16_Indium_30_190_10Cmin_x4
Sample Mass,4.07 mg
Reference Sample Mass,0 mg
Pan Mass,56.5 mg
Pan Number,2
Reference Pan Mass,56.6 mg
Reference Pan Number,1
Pan Type,Tzero Aluminum Hermetic
Comments,DSC Consumables Al Hermetically Sealed Pan. Y1 Tray (Google Sheet: DSC_Samples_Y1_Tray_June2025).
Project Name,Pharmaceuticals - Cannabinoids
Operator,Gibbons
Test,Custom
Unload Max Temperature,30
Unload Min Temperature,30
Load Max Temperature,30
Load Min Temperature,30
Stop on Gas Flow Error,Yes
[Signal List]
Signal #1,Time (min)
Signal #2,Temperature (°C)
Signal #3,Heat Flow (mW)
Signal #4,Delta T (µV)
Signal #5,Delta Tzero (µV)
Signal #6,Tzero Temperature (°C)
Signal #7,Cell Purge (mL/min)
Signal #8,Heater Temp (°C)
Signal #9,Power Delivered (W)
Signal #10,Reference Junction Temperature (°C)
Signal #11,Flange Temperature (°C)
Signal #12,Heat Flow Phase (rad)
Signal #13,Total Heat Capacity (J/°C)
Signal #14,Heat Capacity (J/°C)
[Configuration]
Company Name,ASU
Instrument Name,DSC2A-00468
Instrument Type,DSC2500
Serial Number,DSC2A-00468
IP,192.168.1.100
Location of Instrument,MRRC
DisplayType,Unknown
Sample Interval ,0.1 s/pt
Selected Heat Flow,T4P
Exotherm Direction,Down
Cell Serial,DRC2-00792
Lid Type,Standard
Cooler,RCS 90
Leave Cooler on at End of Sequence,On
Gas 2,Nitrogen
Gas Selected,Channel 1
Flow Rate,50 mL/min
Secondary Purge,On
Licensed Heat Flow,Heat Flow T4P
Modulation Licensed,Yes
[Versions]
Common IDD Version,1
Cortex Version,VER 2.10.2.31
Driver,5.0.0.6
GDM Version,1.0.3.3
TouchscreenVersion,1.0.0.16145
FEP Version,1.2.1.21
FEP Bootloader,2.0.0.5
AutoSampler Version,2.1.1.26
Auto Sampler Bootloader,2.0.0.5
FCM Version,1.1.0.3
FCM Bootloader,2.0.0.5
[Experiment Logs]
Experiment Log Entry # 1,Data On set to 0
Experiment Log Entry # 3,Equilibrate Segment 30 (C) Started
Experiment Log Entry # 5,Air Cool is off.
Experiment Log Entry # 7,Data On set to 1
Experiment Log Entry # 9,Ramp Segment 10 C/min to 190 Started
Experiment Log Entry # 11,Data On set to 0
Experiment Log Entry # 13,Isothermal Segment 2 min started
Experiment Log Entry # 15,Data On set to 1
Experiment Log Entry # 17,Ramp Segment 10 C/min to 30 Started
Experiment Log Entry # 19,Data On set to 0
Experiment Log Entry # 21,Isothermal Segment 2 min started
Experiment Log Entry # 23,Data On set to 1
Experiment Log Entry # 25,Ramp Segment 10 C/min to 190 Started
Experiment Log Entry # 27,Data On set to 0
Experiment Log Entry # 29,Isothermal Segment 2 min started
Experiment Log Entry # 31,Data On set to 1
Experiment Log Entry # 33,Ramp Segment 10 C/min to 30 Started
Experiment Log Entry # 35,Data On set to 0
Experiment Log Entry # 37,Isothermal Segment 2 min started
Experiment Log Entry # 39,Data On set to 1
Experiment Log Entry # 41,Ramp Segment 10 C/min to 190 Started
Experiment Log Entry # 43,Data On set to 0
Experiment Log Entry # 45,Isothermal Segment 2 min started
Experiment Log Entry # 47,Data On set to 1
Experiment Log Entry # 49,Ramp Segment 10 C/min to 30 Started
Experiment Log Entry # 51,Data On set to 0
[Method Log]
Method Log Entry # 1,Data Off
Method Log Entry # 2,Equilibrate 30 °C
Method Log Entry # 3,Data On
Method Log Entry # 4,(Ramp 1775) Ramp 10 °C/minute to 190 °C
Method Log Entry # 5,Data Off
Method Log Entry # 6,Isothermal 2 minutes
Method Log Entry # 7,Data On
Method Log Entry # 8,(Ramp 1779) Ramp 10 °C/minute to 30 °C
Method Log Entry # 9,Data Off
Method Log Entry # 10,Isothermal 2 minutes
Method Log Entry # 11,Data On
Method Log Entry # 12,(Ramp 1783) Ramp 10 °C/minute to 190 °C
Method Log Entry # 13,Data Off
Method Log Entry # 14,Isothermal 2 minutes
Method Log Entry # 15,Data On
Method Log Entry # 16,(Ramp 1787) Ramp 10 °C/minute to 30 °C
Method Log Entry # 17,Data Off
Method Log Entry # 18,Isothermal 2 minutes
Method Log Entry # 19,Data On
Method Log Entry # 20,(Ramp 1791) Ramp 10 °C/minute to 190 °C
Method Log Entry # 21,Data Off
Method Log Entry # 22,Isothermal 2 minutes
Method Log Entry # 23,Data On
Method Log Entry # 24,(Ramp 1795) Ramp 10 °C/minute to 30 °C
Method Log Entry # 25,Data Off
Cell Serial,DRC2-00792
[T1 Calibration]
Slope,-0.008529666
Offset,9.636258
Initial Temperature,98.23
GUID,f8bfdadc-4977-4fdf-ba6d-0ba9134940c3
[TZero Calibration]
Date Applied,11/29/2022 4:06:13 PM
Description,From -89.059 °C to 396.009 °C at 20.000°C/min
Gas Type,Nitrogen
Pan Type,None
Source Files 1,C:\Users\yargerlab\Desktop\DSC Data\General\TZero_calibration_11_29_22_2nd(2).tri
Source Files 2,C:\Users\yargerlab\Desktop\DSC Data\General\TZero_calibration_11_29_22_2nd(3).tri
Delta T Offset,13.05235
Delta T Slope,-0.007271007
Delta T0 Offset,-13.69128
Delta T0 Slope,0.06063341
[Temperature Calibration]
Date Applied,11/29/2022 7:12:28 PM
Description,From 106.590 °C to 186.590 °C at 10.000°C/min
Gas Type,Nitrogen
Pan Type,Tzero Aluminum Hermetic
Source Files 1,C:\Users\yargerlab\Desktop\DSC Data\General\Indium(6).tri
Measured 1,157.391
Known 1,156.598
[Cell Constant Calibration]
Date Applied,11/29/2022 7:12:29 PM
Description,From 106.590 °C to 186.590 °C at 10.000°C/min
Gas Type,Nitrogen
Pan Type,Tzero Aluminum Hermetic
Source Files 1,C:\Users\yargerlab\Desktop\DSC Data\General\Indium(6).tri
T4P KCell,1.006051
Onset Slope,63.26126 mW/°C
[Direct Cp Calibration]
Date Applied,11/30/2022 11:04:51 AM
Description,From -79.983 °C to 298.409 °C at 10.000°C/min
Gas Type,Nitrogen
Pan Type,Tzero Aluminum Hermetic
Source Files 1,C:\Users\yargerlab\Desktop\DSC Data\General\Sapphire_Heat_Capacity_11_30_22.tri
[Rev Cp Calibration]
Date Applied,11/30/2022 1:58:51 PM
Description,From -79.996 °C to 292.812 °C at 3.000°C/min
Gas Type,Nitrogen
Pan Type,Tzero Aluminum Hermetic
Source Files 1,C:\Users\yargerlab\Desktop\DSC Data\General\Sapphire_MDSC_Calibration_11_30_22.tri
[step]
Ramp 10.00 °C/min to 190.00 °C
Time,Temperature,Heat Flow (Normalized)
min,°C,W/g
0.00,30.00,0.019
0.01,30.00,0.018
0.02,30.01,0.018
0.03,30.01,0.018
0.05,30.02,0.017
0.06,30.03,0.017
0.07,30.05,0.017
0.08,30.07,0.019
0.09,30.10,0.023
0.11,30.14,0.029
0.12,30.19,0.034
0.13,30.25,0.038
0.14,30.32,0.044
0.15,30.39,0.046
0.16,30.47,0.051
0.18,30.55,0.054
0.19,30.64,0.057
0.20,30.73,0.061
0.21,30.82,0.063
0.22,30.92,0.065
0.23,31.01,0.066
0.24,31.11,0.069
0.26,31.21,0.071
0.27,31.32,0.071
0.28,31.42,0.072
0.29,31.53,0.073
0.30,31.63,0.074
0.31,31.74,0.075
0.33,31.85,0.075
0.34,31.96,0.075
0.35,32.07,0.076
0.36,32.18,0.076
0.37,32.29,0.076
0.39,32.40,0.077
0.40,32.51,0.077
0.41,32.62,0.077
0.42,32.74,0.077
0.43,32.85,0.078
0.44,32.96,0.078
0.45,33.08,0.078
0.47,33.19,0.078
0.48,33.30,0.079
0.49,33.42,0.079
0.50,33.53,0.079
0.51,33.65,0.079
0.53,33.76,0.079
0.54,33.87,0.079
0.55,33.99,0.080
0.56,34.10,0.080
0.57,34.22,0.080
0.58,34.33,0.080
0.60,34.45,0.080
0.61,34.56,0.080
0.62,34.68,0.080
0.63,34.79,0.080
0.64,34.91,0.080
0.65,35.02,0.081
0.67,35.14,0.081
0.68,35.25,0.081
0.69,35.37,0.081
0.70,35.49,0.081
0.71,35.60,0.081
0.72,35.72,0.081
0.73,35.83,0.081
0.75,35.95,0.081
0.76,36.06,0.081
0.77,36.18,0.081
0.78,36.30,0.081
0.79,36.41,0.081
0.80,36.53,0.081
0.82,36.65,0.081
0.83,36.76,0.081
0.84,36.88,0.081
0.85,36.99,0.081
0.86,37.11,0.081
0.88,37.23,0.081
0.89,37.34,0.081
0.90,37.46,0.081
0.91,37.57,0.081
0.92,37.69,0.081
0.93,37.81,0.081
0.95,37.92,0.081
0.96,38.04,0.080
0.97,38.16,0.080
0.98,38.27,0.080
0.99,38.39,0.080
1.00,38.50,0.080
1.02,38.62,0.080
1.03,38.74,0.080
1.04,38.85,0.080
1.05,38.97,0.080
1.06,39.09,0.080
1.07,39.20,0.080
1.08,39.32,0.080
1.10,39.44,0.080
1.11,39.55,0.080
1.12,39.67,0.080
1.13,39.79,0.079
1.14,39.90,0.079
1.16,40.02,0.079
1.17,40.14,0.079
1.18,40.25,0.079
1.19,40.37,0.079
1.20,40.49,0.079
1.21,40.60,0.079
1.23,40.72,0.079
1.24,40.84,0.079
1.25,40.96,0.079
1.26,41.07,0.078
1.27,41.19,0.078
1.28,41.31,0.078
1.29,41.42,0.078
1.31,41.54,0.078
1.32,41.66,0.078
1.33,41.77,0.078
1.34,41.89,0.078
1.35,42.01,0.078
1.37,42.12,0.078
1.38,42.24,0.078
1.39,42.36,0.078
1.40,42.47,0.077
1.41,42.59,0.077
1.42,42.71,0.077
1.43,42.83,0.077
1.45,42.94,0.077
1.46,43.06,0.077
1.47,43.18,0.077
1.48,43.29,0.077
1.49,43.41,0.077
1.51,43.53,0.077
1.52,43.64,0.077
1.53,43.76,0.077
1.54,43.88,0.076
1.55,43.99,0.076
1.56,44.11,0.076
1.58,44.23,0.076
1.59,44.34,0.076
1.60,44.46,0.076
1.61,44.58,0.076
1.62,44.70,0.076
1.63,44.81,0.076
1.64,44.93,0.076
1.66,45.05,0.076
1.67,45.16,0.076
1.68,45.28,0.076
1.69,45.40,0.075
1.70,45.51,0.075
1.72,45.63,0.075
1.73,45.75,0.075
1.74,45.86,0.075
1.75,45.98,0.075
1.76,46.10,0.075
1.77,46.21,0.075
1.78,46.33,0.075
1.80,46.45,0.075
1.81,46.57,0.075
1.82,46.68,0.074
1.83,46.80,0.074
1.84,46.92,0.074
1.86,47.03,0.074
1.87,47.15,0.074
1.88,47.27,0.074
1.89,47.38,0.074
1.90,47.50,0.074
1.91,47.62,0.074
1.93,47.73,0.074
1.94,47.85,0.074
1.95,47.97,0.074
1.96,48.08,0.074
1.97,48.20,0.073
1.98,48.32,0.073
1.99,48.44,0.073
2.01,48.55,0.073
2.02,48.67,0.073
2.03,48.79,0.073
2.04,48.90,0.073
2.05,49.02,0.073
2.07,49.13,0.073
2.08,49.25,0.073
2.09,49.37,0.073
2.10,49.49,0.073
2.11,49.60,0.073
2.12,49.72,0.073
2.14,49.84,0.073
2.15,49.95,0.072
2.16,50.07,0.072
2.17,50.19,0.072
2.18,50.30,0.072
2.19,50.42,0.072
2.21,50.54,0.072
2.22,50.65,0.072
2.23,50.77,0.072
2.24,50.89,0.072
2.25,51.00,0.072
2.26,51.12,0.072
2.28,51.24,0.072
2.29,51.35,0.072
2.30,51.47,0.072
2.31,51.59,0.072
2.32,51.71,0.072
2.33,51.82,0.072
2.34,51.94,0.071
2.36,52.06,0.071
2.37,52.17,0.071
2.38,52.29,0.071
2.39,52.41,0.071
2.40,52.52,0.071
2.41,52.64,0.071
2.43,52.76,0.071
2.44,52.87,0.071
2.45,52.99,0.071
2.46,53.11,0.071
2.47,53.22,0.071
2.49,53.34,0.071
2.50,53.46,0.071
2.51,53.57,0.071
2.52,53.69,0.071
2.53,53.81,0.071
2.54,53.92,0.071
2.56,54.04,0.070
2.57,54.16,0.070
2.58,54.27,0.070
2.59,54.39,0.070
2.60,54.51,0.070
2.61,54.63,0.070
2.63,54.74,0.070
2.64,54.86,0.070
2.65,54.98,0.070
2.66,55.09,0.070
2.67,55.21,0.070
2.68,55.33,0.070
2.69,55.44,0.070
2.71,55.56,0.070
2.72,55.68,0.070
2.73,55.79,0.070
2.74,55.91,0.069
2.75,56.03,0.069
2.76,56.14,0.069
2.78,56.26,0.069
2.79,56.38,0.069
2.80,56.49,0.069
2.81,56.61,0.069
2.82,56.73,0.069
2.84,56.84,0.069
2.85,56.96,0.069
2.86,57.08,0.069
2.87,57.19,0.069
2.88,57.31,0.069
2.89,57.43,0.069
2.91,57.54,0.069
2.92,57.66,0.069
2.93,57.78,0.069
2.94,57.90,0.069
2.95,58.01,0.068
2.96,58.13,0.068
2.98,58.25,0.068
2.99,58.36,0.068
3.00,58.48,0.068
3.01,58.60,0.068
3.02,58.71,0.068
3.03,58.83,0.068
3.04,58.95,0.068
3.06,59.06,0.068
3.07,59.18,0.068
3.08,59.30,0.068
3.09,59.41,0.068
3.10,59.53,0.068
3.11,59.65,0.068
3.13,59.76,0.068
3.14,59.88,0.068
3.15,60.00,0.068
3.16,60.11,0.068
3.17,60.23,0.068
3.19,60.35,0.068
3.20,60.47,0.068
3.21,60.58,0.068
3.22,60.70,0.068
3.23,60.82,0.068
3.24,60.93,0.068
3.26,61.05,0.068
3.27,61.17,0.068
3.28,61.28,0.067
3.29,61.40,0.067
3.30,61.52,0.067
3.31,61.63,0.067
3.33,61.75,0.067
3.34,61.87,0.067
3.35,61.98,0.067
3.36,62.10,0.067
3.37,62.22,0.067
3.38,62.33,0.067
3.39,62.45,0.067
3.41,62.57,0.067
3.42,62.69,0.067
3.43,62.80,0.067
3.44,62.92,0.067
3.45,63.04,0.067
3.46,63.15,0.067
3.48,63.27,0.067
3.49,63.39,0.067
3.50,63.50,0.067
3.51,63.62,0.067
3.52,63.74,0.067
3.54,63.85,0.067
3.55,63.97,0.067
3.56,64.09,0.067
3.57,64.20,0.067
3.58,64.32,0.066
3.59,64.44,0.066
3.61,64.55,0.066
3.62,64.67,0.066
3.63,64.79,0.066
3.64,64.90,0.066
3.65,65.02,0.066
3.66,65.14,0.066
3.68,65.26,0.066
3.69,65.37,0.066
3.70,65.49,0.066
3.71,65.61,0.066
3.72,65.72,0.066
3.73,65.84,0.066
3.74,65.96,0.066
3.76,66.07,0.066
3.77,66.19,0.066
3.78,66.31,0.066
3.79,66.42,0.066
3.80,66.54,0.066
3.81,66.66,0.066
3.83,66.78,0.066
3.84,66.89,0.066
3.85,67.01,0.066
3.86,67.13,0.066
3.87,67.24,0.066
3.89,67.36,0.066
3.90,67.48,0.066
3.91,67.59,0.066
3.92,67.71,0.065
3.93,67.83,0.065
3.94,67.94,0.065
3.96,68.06,0.065
3.97,68.18,0.065
3.98,68.29,0.065
3.99,68.41,0.065
4.00,68.53,0.065
4.01,68.64,0.065
4.03,68.76,0.065
4.04,68.88,0.065
4.05,68.99,0.065
4.06,69.11,0.065
4.07,69.23,0.065
4.08,69.34,0.065
4.09,69.46,0.065
4.11,69.58,0.065
4.12,69.70,0.065
4.13,69.81,0.065
4.14,69.93,0.065
4.15,70.05,0.065
4.16,70.16,0.065
4.18,70.28,0.065
4.19,70.40,0.065
4.20,70.51,0.065
4.21,70.63,0.064
4.22,70.75,0.064
4.24,70.86,0.064
4.25,70.98,0.064
4.26,71.10,0.064
4.27,71.21,0.064
4.28,71.33,0.064
4.29,71.45,0.064
4.30,71.56,0.064
4.32,71.68,0.064
4.33,71.80,0.064
4.34,71.91,0.064
4.35,72.03,0.064
4.36,72.15,0.064
4.38,72.26,0.064
4.39,72.38,0.064
4.40,72.50,0.064
4.41,72.62,0.064
4.42,72.73,0.064
4.43,72.85,0.064
4.45,72.97,0.064
4.46,73.08,0.064
4.47,73.20,0.064
4.48,73.32,0.064
4.49,73.43,0.064
4.50,73.55,0.064
4.51,73.67,0.064
4.53,73.78,0.064
4.54,73.90,0.064
4.55,74.02,0.064
4.56,74.13,0.064
4.57,74.25,0.064
4.59,74.37,0.064
4.60,74.48,0.063
4.61,74.60,0.063
4.62,74.72,0.063
4.63,74.83,0.063
4.64,74.95,0.063
4.65,75.07,0.063
4.67,75.18,0.063
4.68,75.30,0.063
4.69,75.42,0.063
4.70,75.53,0.063
4.71,75.65,0.063
4.73,75.77,0.063
4.74,75.88,0.063
4.75,76.00,0.063
4.76,76.12,0.063
4.77,76.23,0.063
4.78,76.35,0.063
4.80,76.47,0.063
4.81,76.58,0.063
4.82,76.70,0.063
4.83,76.82,0.063
4.84,76.94,0.063
4.85,77.05,0.063
4.86,77.17,0.063
4.88,77.29,0.063
4.89,77.40,0.063
4.90,77.52,0.063
4.91,77.64,0.063
4.92,77.75,0.063
4.94,77.87,0.063
4.95,77.99,0.063
4.96,78.10,0.063
4.97,78.22,0.063
4.98,78.34,0.063
4.99,78.45,0.063
5.00,78.57,0.063
5.02,78.69,0.063
5.03,78.80,0.063
5.04,78.92,0.063
5.05,79.04,0.063
5.06,79.16,0.063
5.08,79.27,0.063
5.09,79.39,0.063
5.10,79.51,0.063
5.11,79.62,0.063
5.12,79.74,0.063
5.13,79.86,0.063
5.15,79.97,0.063
5.16,80.09,0.063
5.17,80.21,0.063
5.18,80.32,0.063
5.19,80.44,0.063
5.20,80.56,0.063
5.21,80.67,0.063
5.23,80.79,0.062
5.24,80.91,0.062
5.25,81.02,0.062
5.26,81.14,0.062
5.27,81.26,0.062
5.29,81.37,0.062
5.30,81.49,0.062
5.31,81.61,0.062
5.32,81.72,0.062
5.33,81.84,0.062
5.34,81.96,0.062
5.35,82.08,0.062
5.37,82.19,0.062
5.38,82.31,0.062
5.39,82.43,0.062
5.40,82.54,0.062
5.41,82.66,0.062
5.43,82.78,0.062
5.44,82.89,0.062
5.45,83.01,0.062
5.46,83.13,0.062
5.47,83.24,0.062
5.48,83.36,0.062
5.50,83.48,0.062
5.51,83.59,0.062
5.52,83.71,0.062
5.53,83.83,0.061
5.54,83.94,0.061
5.55,84.06,0.061
5.56,84.18,0.061
5.58,84.29,0.061
5.59,84.41,0.061
5.60,84.53,0.061
5.61,84.64,0.061
5.62,84.76,0.061
5.64,84.88,0.061
5.65,84.99,0.061
5.66,85.11,0.061
5.67,85.23,0.061
5.68,85.34,0.061
5.69,85.46,0.061
5.70,85.58,0.061
5.72,85.70,0.061
5.73,85.81,0.061
5.74,85.93,0.061
5.75,86.05,0.061
5.76,86.16,0.061
5.78,86.28,0.061
5.79,86.40,0.061
5.80,86.51,0.061
5.81,86.63,0.061
5.82,86.75,0.061
5.83,86.86,0.061
5.85,86.98,0.061
5.86,87.10,0.060
5.87,87.21,0.060
5.88,87.33,0.060
5.89,87.45,0.060
5.90,87.56,0.060
5.91,87.68,0.060
5.93,87.80,0.060
5.94,87.91,0.060
5.95,88.03,0.060
5.96,88.15,0.060
5.97,88.26,0.060
5.99,88.38,0.060
6.00,88.50,0.060
6.01,88.62,0.060
6.02,88.73,0.060
6.03,88.85,0.060
6.04,88.97,0.060
6.05,89.08,0.060
6.07,89.20,0.060
6.08,89.32,0.060
6.09,89.43,0.060
6.10,89.55,0.060
6.11,89.67,0.060
6.13,89.78,0.060
6.14,89.90,0.060
6.15,90.02,0.060
6.16,90.13,0.060
6.17,90.25,0.060
6.18,90.37,0.060
6.20,90.48,0.060
6.21,90.60,0.060
6.22,90.72,0.060
6.23,90.83,0.060
6.24,90.95,0.060
6.25,91.07,0.060
6.26,91.19,0.060
6.28,91.30,0.060
6.29,91.42,0.060
6.30,91.54,0.060
6.31,91.65,0.060
6.32,91.77,0.060
6.34,91.89,0.060
6.35,92.01,0.060
6.36,92.12,0.060
6.37,92.24,0.060
6.38,92.35,0.060
6.39,92.47,0.060
6.40,92.59,0.060
6.42,92.70,0.060
6.43,92.82,0.060
6.44,92.94,0.060
6.45,93.05,0.060
6.46,93.17,0.060
6.48,93.29,0.060
6.49,93.41,0.060
6.50,93.52,0.060
6.51,93.64,0.060
6.52,93.75,0.060
6.53,93.87,0.060
6.55,93.99,0.060
6.56,94.11,0.060
6.57,94.22,0.060
6.58,94.34,0.060
6.59,94.46,0.060
6.60,94.57,0.060
6.61,94.69,0.060
6.63,94.81,0.060
6.64,94.92,0.060
6.65,95.04,0.060
6.66,95.16,0.060
6.67,95.27,0.060
6.69,95.39,0.060
6.70,95.51,0.060
6.71,95.62,0.060
6.72,95.74,0.060
6.73,95.86,0.060
6.74,95.97,0.060
6.75,96.09,0.060
6.77,96.21,0.060
6.78,96.32,0.060
6.79,96.44,0.060
6.80,96.56,0.060
6.81,96.67,0.060
6.83,96.79,0.060
6.84,96.91,0.060
6.85,97.02,0.060
6.86,97.14,0.060
6.87,97.26,0.060
6.88,97.37,0.060
6.90,97.49,0.060
6.91,97.61,0.060
6.92,97.72,0.060
6.93,97.84,0.060
6.94,97.96,0.060
6.95,98.08,0.060
6.96,98.19,0.060
6.98,98.31,0.060
6.99,98.42,0.060
7.00,98.54,0.060
7.01,98.66,0.060
7.02,98.77,0.060
7.04,98.89,0.060
7.05,99.01,0.060
7.06,99.13,0.060
7.07,99.24,0.060
7.08,99.36,0.060
7.09,99.48,0.060
7.10,99.59,0.060
7.12,99.71,0.060
7.13,99.83,0.060
7.14,99.94,0.060
7.15,100.06,0.060
7.16,100.18,0.060
7.18,100.29,0.060
7.19,100.41,0.060
7.20,100.53,0.060
7.21,100.64,0.060
7.22,100.76,0.060
7.23,100.88,0.060
7.25,100.99,0.060
7.26,101.11,0.060
7.27,101.23,0.060
7.28,101.34,0.060
7.29,101.46,0.060
7.30,101.58,0.060
7.31,101.69,0.060
7.33,101.81,0.060
7.34,101.93,0.060
7.35,102.04,0.060
7.36,102.16,0.060
7.37,102.28,0.060
7.39,102.39,0.060
7.40,102.51,0.060
7.41,102.63,0.060
7.42,102.74,0.060
7.43,102.86,0.060
7.44,102.98,0.060
7.45,103.09,0.060
7.47,103.21,0.060
7.48,103.33,0.060
7.49,103.44,0.060
7.50,103.56,0.060
7.51,103.68,0.060
7.53,103.80,0.060
7.54,103.91,0.060
7.55,104.03,0.060
7.56,104.14,0.060
7.57,104.26,0.060
7.58,104.38,0.060
7.60,104.50,0.060
7.61,104.61,0.060
7.62,104.73,0.060
7.63,104.85,0.060
7.64,104.96,0.060
7.65,105.08,0.060
7.66,105.20,0.060
7.68,105.31,0.060
7.69,105.43,0.060
7.70,105.55,0.060
7.71,105.66,0.060
7.72,105.78,0.060
7.74,105.90,0.060
7.75,106.01,0.060
7.76,106.13,0.060
7.77,106.25,0.060
7.78,106.36,0.060
7.79,106.48,0.060
7.80,106.60,0.060
7.82,106.72,0.060
7.83,106.83,0.060
7.84,106.95,0.060
7.85,107.07,0.060
7.86,107.18,0.060
7.88,107.30,0.060
7.89,107.41,0.060
7.90,107.53,0.060
7.91,107.65,0.060
7.92,107.77,0.060
7.93,107.88,0.060
7.95,108.00,0.060
7.96,108.12,0.060
7.97,108.23,0.060
7.98,108.35,0.060
7.99,108.47,0.060
8.00,108.58,0.060
8.01,108.70,0.060
8.03,108.82,0.060
8.04,108.93,0.060
8.05,109.05,0.060
8.06,109.17,0.060
8.07,109.28,0.060
8.09,109.40,0.060
8.10,109.52,0.060
8.11,109.63,0.060
8.12,109.75,0.060
8.13,109.87,0.060
8.14,109.98,0.060
8.15,110.10,0.060
8.17,110.22,0.060
8.18,110.34,0.060
8.19,110.45,0.060
8.20,110.57,0.060
8.21,110.68,0.060
8.23,110.80,0.060
8.24,110.92,0.060
8.25,111.03,0.060
8.26,111.15,0.060
8.27,111.27,0.060
8.28,111.39,0.060
8.30,111.50,0.060
8.31,111.62,0.060
8.32,111.74,0.060
8.33,111.85,0.060
8.34,111.97,0.060
8.35,112.09,0.060
8.36,112.20,0.060
8.38,112.32,0.060
8.39,112.44,0.060
8.40,112.55,0.060
8.41,112.67,0.060
8.42,112.79,0.060
8.44,112.90,0.060
8.45,113.02,0.060
8.46,113.14,0.060
8.47,113.25,0.060
8.48,113.37,0.060
8.49,113.49,0.060
8.50,113.60,0.060
8.52,113.72,0.060
8.53,113.84,0.060
8.54,113.95,0.060
8.55,114.07,0.060
8.56,114.19,0.060
8.58,114.30,0.060
8.59,114.42,0.060
8.60,114.54,0.060
8.61,114.66,0.060
8.62,114.77,0.060
8.63,114.89,0.060
8.65,115.00,0.060
8.66,115.12,0.060
8.67,115.24,0.060
8.68,115.36,0.060
8.69,115.47,0.060
8.70,115.59,0.060
8.72,115.71,0.060
8.73,115.82,0.060
8.74,115.94,0.060
8.75,116.05,0.060
8.76,116.17,0.060
8.77,116.29,0.060
8.78,116.41,0.060
8.80,116.52,0.060
8.81,116.64,0.060
8.82,116.76,0.060
8.83,116.87,0.060
8.84,116.99,0.060
8.85,117.11,0.060
8.87,117.22,0.060
8.88,117.34,0.060
8.89,117.46,0.060
8.90,117.57,0.060
8.91,117.69,0.060
8.93,117.81,0.060
8.94,117.93,0.060
8.95,118.04,0.060
8.96,118.16,0.060
8.97,118.28,0.060
8.98,118.39,0.060
9.00,118.51,0.060
9.01,118.63,0.060
9.02,118.74,0.060
9.03,118.86,0.060
9.04,118.98,0.060
9.05,119.09,0.060
9.07,119.21,0.060
9.08,119.33,0.060
9.09,119.44,0.060
9.10,119.56,0.060
9.11,119.68,0.060
9.12,119.79,0.060
9.13,119.91,0.060
9.15,120.03,0.060
9.16,120.14,0.060
9.17,120.26,0.060
9.18,120.38,0.060
9.19,120.49,0.060
9.20,120.61,0.060
9.22,120.73,0.060
9.23,120.84,0.060
9.24,120.96,0.060
9.25,121.08,0.060
9.26,121.19,0.060
9.28,121.31,0.060
9.29,121.43,0.060
9.30,121.54,0.060
9.31,121.66,0.060
9.32,121.78,0.060
9.33,121.89,0.060
9.35,122.01,0.060
9.36,122.13,0.060
9.37,122.24,0.060
9.38,122.36,0.060
9.39,122.48,0.060
9.40,122.59,0.060
9.42,122.71,0.060
9.43,122.83,0.060
9.44,122.94,0.060
9.45,123.06,0.060
9.46,123.18,0.060
9.47,123.29,0.060
9.48,123.41,0.060
9.50,123.53,0.060
9.51,123.64,0.060
9.52,123.76,0.060
9.53,123.88,0.060
9.54,124.00,0.060
9.55,124.11,0.060
9.57,124.23,0.060
9.58,124.35,0.060
9.59,124.46,0.060
9.60,124.58,0.060
9.61,124.70,0.060
9.63,124.81,0.060
9.64,124.93,0.060
9.65,125.05,0.060
9.66,125.16,0.060
9.67,125.28,0.060
9.68,125.40,0.059
9.70,125.51,0.060
9.71,125.63,0.059
9.72,125.75,0.060
9.73,125.86,0.060
9.74,125.98,0.060
9.75,126.10,0.060
9.77,126.21,0.060
9.78,126.33,0.060
9.79,126.45,0.060
9.80,126.56,0.060
9.81,126.68,0.060
9.82,126.80,0.060
9.83,126.91,0.059
9.85,127.03,0.060
9.86,127.15,0.059
9.87,127.26,0.059
9.88,127.38,0.059
9.89,127.50,0.059
9.90,127.61,0.059
9.92,127.73,0.059
9.93,127.85,0.059
9.94,127.96,0.059
9.95,128.08,0.059
9.96,128.20,0.059
9.98,128.31,0.059
9.99,128.43,0.059
10.00,128.55,0.059
10.01,128.67,0.059
10.02,128.78,0.059
10.03,128.90,0.059
10.05,129.02,0.059
10.06,129.13,0.059
10.07,129.25,0.059
10.08,129.37,0.059
10.09,129.48,0.059
10.10,129.60,0.059
10.12,129.72,0.059
10.13,129.83,0.059
10.14,129.95,0.059
10.15,130.07,0.059
10.16,130.18,0.059
10.17,130.30,0.059
10.18,130.42,0.059
10.20,130.53,0.059
10.21,130.65,0.059
10.22,130.77,0.059
10.23,130.88,0.059
10.24,131.00,0.059
10.25,131.12,0.059
10.27,131.23,0.059
10.28,131.35,0.059
10.29,131.47,0.059
10.30,131.58,0.059
10.31,131.70,0.059
10.33,131.82,0.059
10.34,131.93,0.059
10.35,132.05,0.059
10.36,132.17,0.059
10.37,132.29,0.059
10.38,132.40,0.059
10.40,132.52,0.059
10.41,132.64,0.059
10.42,132.75,0.059
10.43,132.87,0.059
10.44,132.99,0.059
10.45,133.10,0.059
10.47,133.22,0.059
10.48,133.34,0.059
10.49,133.45,0.059
10.50,133.57,0.059
10.51,133.69,0.059
10.52,133.80,0.059
10.53,133.92,0.059
10.55,134.04,0.059
10.56,134.15,0.059
10.57,134.27,0.059
10.58,134.39,0.059
10.59,134.50,0.059
10.60,134.62,0.059
10.62,134.74,0.059
10.63,134.85,0.059
10.64,134.97,0.059
10.65,135.09,0.059
10.66,135.20,0.059
10.68,135.32,0.059
10.69,135.44,0.059
10.70,135.55,0.059
10.71,135.67,0.059
10.72,135.79,0.059
10.73,135.91,0.059
10.75,136.02,0.059
10.76,136.14,0.059
10.77,136.26,0.059
10.78,136.37,0.059
10.79,136.49,0.059
10.80,136.61,0.059
10.82,136.72,0.059
10.83,136.84,0.059
10.84,136.96,0.059
10.85,137.07,0.059
10.86,137.19,0.059
10.87,137.31,0.059
10.88,137.42,0.059
10.90,137.54,0.059
10.91,137.66,0.059
10.92,137.77,0.059
10.93,137.89,0.059
10.94,138.01,0.059
10.95,138.12,0.059
10.97,138.24,0.059
10.98,138.36,0.059
10.99,138.48,0.059
11.00,138.59,0.059
11.01,138.71,0.059
11.03,138.82,0.059
11.04,138.94,0.059
11.05,139.06,0.059
11.06,139.18,0.059
11.07,139.29,0.059
11.08,139.41,0.059
11.10,139.52,0.059
11.11,139.64,0.059
11.12,139.76,0.059
11.13,139.88,0.059
11.14,139.99,0.059
11.15,140.11,0.059
11.17,140.23,0.059
11.18,140.34,0.059
11.19,140.46,0.059
11.20,140.58,0.059
11.21,140.69,0.059
11.22,140.81,0.059
11.23,140.93,0.059
11.25,141.04,0.059
11.26,141.16,0.059
11.27,141.28,0.059
11.28,141.39,0.059
11.29,141.51,0.059
11.30,141.63,0.059
11.32,141.74,0.059
11.33,141.86,0.059
11.34,141.98,0.059
11.35,142.09,0.059
11.36,142.21,0.059
11.38,142.33,0.059
11.39,142.44,0.059
11.40,142.56,0.059
11.41,142.68,0.059
11.42,142.80,0.059
11.43,142.91,0.059
11.45,143.03,0.059
11.46,143.14,0.059
11.47,143.26,0.059
11.48,143.38,0.059
11.49,143.50,0.059
11.50,143.61,0.059
11.52,143.73,0.059
11.53,143.85,0.059
11.54,143.96,0.059
11.55,144.08,0.059
11.56,144.20,0.059
11.57,144.31,0.059
11.58,144.43,0.059
11.60,144.55,0.059
11.61,144.67,0.059
11.62,144.78,0.059
11.63,144.90,0.059
11.64,145.02,0.059
11.65,145.13,0.059
11.67,145.25,0.059
11.68,145.37,0.059
11.69,145.48,0.059
11.70,145.60,0.059
11.71,145.72,0.059
11.73,145.83,0.059
11.74,145.95,0.059
11.75,146.07,0.059
11.76,146.18,0.059
11.77,146.30,0.059
11.78,146.42,0.059
11.80,146.53,0.059
11.81,146.65,0.059
11.82,146.77,0.059
11.83,146.88,0.059
11.84,147.00,0.059
11.85,147.12,0.059
11.87,147.23,0.059
11.88,147.35,0.058
11.89,147.47,0.059
11.90,147.58,0.059
11.91,147.70,0.058
11.92,147.82,0.059
11.93,147.93,0.059
11.95,148.05,0.058
11.96,148.17,0.058
11.97,148.28,0.058
11.98,148.40,0.058
11.99,148.52,0.058
12.00,148.63,0.058
12.02,148.75,0.058
12.03,148.87,0.058
12.04,148.99,0.058
12.05,149.10,0.058
12.06,149.22,0.058
12.08,149.34,0.058
12.09,149.45,0.058
12.10,149.57,0.058
12.11,149.69,0.058
12.12,149.80,0.058
12.13,149.92,0.058
12.15,150.04,0.058
12.16,150.15,0.058
12.17,150.27,0.058
12.18,150.39,0.058
12.19,150.50,0.058
12.20,150.62,0.058
12.22,150.74,0.058
12.23,150.85,0.058
12.24,150.97,0.058
12.25,151.09,0.058
12.26,151.21,0.058
12.27,151.32,0.058
12.28,151.44,0.058
12.30,151.55,0.058
12.31,151.67,0.058
12.32,151.79,0.058
12.33,151.90,0.058
12.34,152.02,0.058
12.35,152.14,0.058
12.37,152.25,0.058
12.38,152.37,0.058
12.39,152.49,0.058
12.40,152.60,0.058
12.41,152.72,0.058
12.43,152.84,0.058
12.44,152.96,0.058
12.45,153.07,0.058
12.46,153.19,0.058
12.47,153.31,0.058
12.48,153.42,0.058
12.50,153.54,0.058
12.51,153.66,0.058
12.52,153.77,0.058
12.53,153.89,0.058
12.54,154.01,0.058
12.55,154.12,0.058
12.57,154.24,0.058
12.58,154.36,0.058
12.59,154.47,0.058
12.60,154.59,0.058
12.61,154.71,0.058
12.62,154.82,0.058
12.63,154.94,0.058
12.65,155.06,0.058
12.66,155.17,0.058
12.67,155.29,0.058
12.68,155.41,0.058
12.69,155.52,0.058
12.70,155.64,0.058
12.72,155.76,0.058
12.73,155.87,0.058
12.74,155.99,0.058
12.75,156.11,0.059
12.76,156.22,0.059
12.78,156.34,0.059
12.79,156.46,0.059
12.80,156.57,0.061
12.81,156.69,0.089
12.82,156.80,0.199
12.83,156.91,0.438
12.85,157.00,0.721
12.86,157.08,1.016
12.87,157.16,1.301
12.88,157.23,1.565
12.89,157.29,1.809
12.90,157.36,2.050
12.92,157.42,2.307
12.93,157.49,2.594
12.94,157.54,2.918
12.95,157.60,3.203
12.96,157.65,3.562
12.97,157.70,3.793
12.98,157.76,3.614
13.00,157.87,2.708
13.01,158.02,1.734
13.02,158.22,0.956
13.03,158.42,0.776
13.04,158.60,0.664
13.05,158.78,0.576
13.07,158.94,0.507
13.08,159.11,0.440
13.09,159.26,0.390
13.10,159.41,0.343
13.11,159.55,0.305
13.13,159.69,0.270
13.14,159.83,0.242
13.15,159.97,0.215
13.16,160.10,0.194
13.17,160.23,0.174
13.18,160.36,0.160
13.20,160.48,0.143
13.21,160.61,0.133
13.22,160.73,0.122
13.23,160.85,0.114
13.24,160.97,0.104
13.25,161.10,0.098
13.27,161.22,0.093
13.28,161.34,0.089
13.29,161.46,0.083
13.30,161.58,0.081
13.31,161.69,0.077
13.32,161.81,0.073
13.33,161.93,0.073
13.35,162.05,0.069
13.36,162.17,0.068
13.37,162.29,0.067
13.38,162.40,0.066
13.39,162.52,0.065
13.40,162.64,0.064
13.42,162.76,0.064
13.43,162.88,0.063
13.44,162.99,0.062
13.45,163.11,0.062
13.46,163.23,0.062
13.48,163.34,0.062
13.49,163.46,0.061
13.50,163.58,0.061
13.51,163.70,0.061
13.52,163.81,0.060
13.53,163.93,0.060
13.55,164.05,0.060
13.56,164.16,0.060
13.57,164.28,0.060
13.58,164.40,0.059
13.59,164.51,0.059
13.60,164.63,0.059
13.62,164.75,0.059
13.63,164.86,0.059
13.64,164.98,0.059
13.65,165.09,0.059
13.66,165.21,0.059
13.67,165.33,0.058
13.68,165.44,0.058
13.70,165.56,0.058
13.71,165.68,0.058
13.72,165.79,0.058
13.73,165.91,0.058
13.74,166.03,0.058
13.75,166.14,0.058
13.77,166.26,0.058
13.78,166.38,0.058
13.79,166.49,0.058
13.80,166.61,0.058
13.81,166.73,0.057
13.83,166.85,0.057
13.84,166.96,0.057
13.85,167.08,0.057
13.86,167.20,0.057
13.87,167.31,0.057
13.88,167.43,0.057
13.90,167.55,0.057
13.91,167.66,0.057
13.92,167.78,0.057
13.93,167.90,0.057
13.94,168.01,0.057
13.95,168.13,0.057
13.97,168.25,0.057
13.98,168.36,0.057
13.99,168.48,0.056
14.00,168.60,0.056
14.01,168.72,0.056
14.02,168.83,0.056
14.03,168.95,0.056
14.05,169.07,0.056
14.06,169.18,0.056
14.07,169.30,0.056
14.08,169.42,0.056
14.09,169.53,0.056
14.10,169.65,0.056
14.12,169.77,0.056
14.13,169.88,0.056
14.14,170.00,0.056
14.15,170.12,0.056
14.16,170.23,0.056
14.18,170.35,0.056
14.19,170.47,0.056
14.20,170.58,0.056
14.21,170.70,0.056
14.22,170.82,0.056
14.23,170.93,0.056
14.25,171.05,0.056
14.26,171.17,0.056
14.27,171.28,0.056
14.28,171.40,0.056
14.29,171.52,0.056
14.30,171.63,0.056
14.32,171.75,0.056
14.33,171.87,0.056
14.34,171.98,0.056
14.35,172.10,0.056
14.36,172.22,0.056
14.37,172.34,0.056
14.38,172.45,0.056
14.40,172.57,0.056
14.41,172.68,0.056
14.42,172.80,0.056
14.43,172.92,0.056
14.44,173.04,0.056
14.45,173.15,0.056
14.47,173.27,0.056
14.48,173.38,0.056
14.49,173.50,0.056
14.50,173.62,0.056
14.51,173.73,0.056
14.53,173.85,0.056
14.54,173.97,0.056
14.55,174.09,0.056
14.56,174.20,0.056
14.57,174.32,0.056
14.58,174.44,0.056
14.60,174.55,0.056
14.61,174.67,0.056
14.62,174.79,0.056
14.63,174.90,0.056
14.64,175.02,0.056
14.65,175.14,0.056
14.67,175.25,0.056
14.68,175.37,0.056
14.69,175.49,0.056
14.70,175.60,0.056
14.71,175.72,0.056
14.72,175.84,0.056
14.73,175.95,0.056
14.75,176.07,0.056
14.76,176.19,0.056
14.77,176.30,0.056
14.78,176.42,0.055
14.79,176.54,0.055
14.80,176.66,0.055
14.82,176.77,0.055
14.83,176.89,0.055
14.84,177.01,0.055
14.85,177.12,0.055
14.86,177.24,0.055
14.88,177.36,0.055
14.89,177.47,0.055
14.90,177.59,0.055
14.91,177.71,0.055
14.92,177.82,0.055
14.93,177.94,0.055
14.95,178.06,0.055
14.96,178.17,0.055
14.97,178.29,0.055
14.98,178.41,0.055
14.99,178.52,0.055
15.00,178.64,0.055
15.02,178.76,0.055
15.03,178.87,0.055
15.04,178.99,0.055
15.05,179.11,0.055
15.06,179.22,0.055
15.07,179.34,0.055
15.08,179.46,0.055
15.10,179.57,0.055
15.11,179.69,0.055
15.12,179.81,0.055
15.13,179.92,0.055
15.14,180.04,0.055
15.15,180.16,0.055
15.17,180.27,0.055
15.18,180.39,0.055
15.19,180.51,0.055
15.20,180.62,0.055
15.21,180.74,0.055
15.23,180.86,0.055
15.24,180.97,0.055
15.25,181.09,0.055
15.26,181.21,0.055
15.27,181.33,0.055
15.28,181.44,0.055
15.30,181.56,0.055
15.31,181.68,0.055
15.32,181.79,0.055
15.33,181.91,0.055
15.34,182.02,0.055
15.35,182.14,0.055
15.37,182.26,0.055
15.38,182.38,0.055
15.39,182.49,0.055
15.40,182.61,0.055
15.41,182.73,0.055
15.42,182.84,0.055
15.43,182.96,0.055
15.45,183.08,0.055
15.46,183.19,0.055
15.47,183.31,0.055
15.48,183.43,0.055
15.49,183.54,0.055
15.50,183.66,0.055
15.52,183.78,0.055
15.53,183.89,0.055
15.54,184.01,0.055
15.55,184.13,0.055
15.56,184.24,0.055
15.58,184.36,0.055
15.59,184.48,0.055
15.60,184.59,0.055
15.61,184.71,0.055
15.62,184.83,0.055
15.63,184.94,0.055
15.65,185.06,0.055
15.66,185.18,0.055
15.67,185.29,0.054
15.68,185.41,0.054
15.69,185.53,0.054
15.70,185.64,0.054
15.72,185.76,0.054
15.73,185.88,0.054
15.74,185.99,0.054
15.75,186.11,0.054
15.76,186.23,0.054
15.77,186.34,0.054
15.78,186.46,0.054
15.80,186.58,0.054
15.81,186.69,0.054
15.82,186.81,0.054
15.83,186.93,0.054
15.84,187.04,0.054
15.85,187.16,0.054
15.87,187.28,0.054
15.88,187.39,0.054
15.89,187.51,0.054
15.90,187.63,0.054
15.91,187.74,0.054
15.93,187.86,0.054
15.94,187.98,0.054
15.95,188.09,
15.96,188.21,
15.97,188.33,
15.98,188.44,
16.00,,
16.00,,

[step]
Ramp 10.00 °C/min to 30.00 °C
Time,Temperature,Heat Flow (Normalized)
min,°C,W/g
18.00,190.11,-0.053
18.02,190.11,-0.053
18.03,190.11,-0.053
18.04,190.10,-0.053
18.05,190.10,-0.053
18.06,190.09,-0.055
18.07,190.08,-0.059
18.08,190.06,-0.068
18.10,190.03,-0.077
18.11,189.99,-0.085
18.12,189.94,-0.092
18.13,189.88,-0.101
18.14,189.81,-0.108
18.16,189.74,-0.115
18.17,189.66,-0.120
18.18,189.57,-0.126
18.19,189.48,-0.130
18.20,189.39,-0.134
18.21,189.29,-0.137
18.23,189.19,-0.140
18.24,189.09,-0.143
18.25,188.99,-0.144
18.26,188.88,-0.146
18.27,188.77,-0.147
18.28,188.67,-0.148
18.29,188.56,-0.149
18.31,188.45,-0.150
18.32,188.34,-0.151
18.33,188.23,-0.152
18.34,188.12,-0.152
18.35,188.00,-0.152
18.37,187.89,-0.153
18.38,187.78,-0.153
18.39,187.66,-0.153
18.40,187.55,-0.153
18.41,187.44,-0.153
18.42,187.32,-0.154
18.43,187.21,-0.154
18.45,187.10,-0.154
18.46,186.98,-0.154
18.47,186.87,-0.154
18.48,186.75,-0.155
18.49,186.64,-0.155
18.51,186.52,-0.155
18.52,186.41,-0.155
18.53,186.29,-0.155
18.54,186.18,-0.155
18.55,186.06,-0.155
18.56,185.95,-0.156
18.58,185.83,-0.156
18.59,185.72,-0.156
18.60,185.60,-0.156
18.61,185.49,-0.156
18.62,185.37,-0.156
18.63,185.26,-0.156
18.64,185.14,-0.156
18.66,185.03,-0.156
18.67,184.91,-0.156
18.68,184.80,-0.156
18.69,184.68,-0.156
18.70,184.56,-0.157
18.72,184.45,-0.157
18.73,184.33,-0.157
18.74,184.22,-0.157
18.75,184.10,-0.157
18.76,183.99,-0.157
18.77,183.87,-0.157
18.78,183.75,-0.157
18.80,183.64,-0.157
18.81,183.52,-0.157
18.82,183.41,-0.157
18.83,183.29,-0.157
18.84,183.17,-0.157
18.86,183.06,-0.157
18.87,182.94,-0.157
18.88,182.82,-0.157
18.89,182.71,-0.157
18.90,182.59,-0.157
18.91,182.48,-0.157
18.93,182.36,-0.156
18.94,182.24,-0.156
18.95,182.13,-0.156
18.96,182.01,-0.156
18.97,181.90,-0.156
18.98,181.78,-0.156
18.99,181.66,-0.156
19.01,181.55,-0.156
19.02,181.43,-0.156
19.03,181.31,-0.156
19.04,181.20,-0.156
19.05,181.08,-0.156
19.07,180.97,-0.156
19.08,180.85,-0.156
19.09,180.73,-0.156
19.10,180.62,-0.156
19.11,180.50,-0.156
19.12,180.38,-0.156
19.13,180.27,-0.156
19.15,180.15,-0.156
19.16,180.03,-0.155
19.17,179.92,-0.155
19.18,179.80,-0.155
19.19,179.69,-0.155
19.21,179.57,-0.155
19.22,179.45,-0.155
19.23,179.34,-0.155
19.24,179.22,-0.155
19.25,179.11,-0.155
19.26,178.99,-0.155
19.28,178.87,-0.155
19.29,178.76,-0.155
19.30,178.64,-0.155
19.31,178.52,-0.154
19.32,178.41,-0.154
19.33,178.29,-0.154
19.34,178.18,-0.154
19.36,178.06,-0.154
19.37,177.94,-0.154
19.38,177.83,-0.154
19.39,177.71,-0.154
19.40,177.59,-0.154
19.42,177.48,-0.154
19.43,177.36,-0.154
19.44,177.25,-0.154
19.45,177.13,-0.154
19.46,177.01,-0.153
19.47,176.90,-0.153
19.48,176.78,-0.153
19.50,176.66,-0.153
19.51,176.55,-0.153
19.52,176.43,-0.153
19.53,176.31,-0.153
19.54,176.20,-0.153
19.56,176.08,-0.153
19.57,175.96,-0.153
19.58,175.85,-0.153
19.59,175.73,-0.153
19.60,175.62,-0.152
19.61,175.50,-0.152
19.63,175.38,-0.152
19.64,175.27,-0.152
19.65,175.15,-0.152
19.66,175.03,-0.152
19.67,174.92,-0.152
19.68,174.80,-0.152
19.69,174.68,-0.152
19.71,174.57,-0.152
19.72,174.45,-0.152
19.73,174.34,-0.152
19.74,174.22,-0.151
19.75,174.10,-0.151
19.77,173.99,-0.151
19.78,173.87,-0.151
19.79,173.75,-0.151
19.80,173.64,-0.151
19.81,173.52,-0.151
19.82,173.40,-0.151
19.83,173.29,-0.151
19.85,173.17,-0.151
19.86,173.05,-0.151
19.87,172.94,-0.151
19.88,172.82,-0.151
19.89,172.70,-0.151
19.91,172.59,-0.150
19.92,172.47,-0.150
19.93,172.35,-0.150
19.94,172.24,-0.150
19.95,172.12,-0.150
19.96,172.00,-0.150
19.98,171.89,-0.150
19.99,171.77,-0.150
20.00,171.65,-0.150
20.01,171.54,-0.150
20.02,171.42,-0.150
20.03,171.31,-0.150
20.04,171.19,-0.150
20.06,171.07,-0.150
20.07,170.95,-0.150
20.08,170.84,-0.150
20.09,170.72,-0.150
20.10,170.61,-0.150
20.12,170.49,-0.149
20.13,170.37,-0.149
20.14,170.26,-0.149
20.15,170.14,-0.149
20.16,170.02,-0.149
20.17,169.91,-0.149
20.18,169.79,-0.149
20.20,169.67,-0.149
20.21,169.56,-0.149
20.22,169.44,-0.149
20.23,169.33,-0.149
20.24,169.21,-0.149
20.26,169.09,-0.149
20.27,168.97,-0.149
20.28,168.86,-0.149
20.29,168.74,-0.149
20.30,168.63,-0.149
20.31,168.51,-0.149
20.33,168.39,-0.149
20.34,168.28,-0.148
20.35,168.16,-0.148
20.36,168.04,-0.148
20.37,167.93,-0.148
20.38,167.81,-0.148
20.39,167.69,-0.148
20.41,167.58,-0.148
20.42,167.46,-0.148
20.43,167.34,-0.148
20.44,167.23,-0.148
20.45,167.11,-0.148
20.47,166.99,-0.148
20.48,166.88,-0.148
20.49,166.76,-0.148
20.50,166.64,-0.148
20.51,166.53,-0.148
20.52,166.41,-0.148
20.53,166.29,-0.147
20.55,166.18,-0.147
20.56,166.06,-0.147
20.57,165.94,-0.147
20.58,165.83,-0.147
20.59,165.71,-0.147
20.61,165.59,-0.147
20.62,165.48,-0.147
20.63,165.36,-0.147
20.64,165.24,-0.147
20.65,165.13,-0.147
20.66,165.01,-0.147
20.68,164.90,-0.147
20.69,164.78,-0.147
20.70,164.66,-0.147
20.71,164.55,-0.147
20.72,164.43,-0.147
20.73,164.31,-0.146
20.74,164.20,-0.146
20.76,164.08,-0.146
20.77,163.97,-0.146
20.78,163.85,-0.146
20.79,163.73,-0.146
20.80,163.62,-0.146
20.82,163.50,-0.146
20.83,163.38,-0.146
20.84,163.27,-0.146
20.85,163.15,-0.146
20.86,163.03,-0.146
20.87,162.91,-0.146
20.88,162.80,-0.146
20.90,162.68,-0.146
20.91,162.56,-0.146
20.92,162.45,-0.146
20.93,162.33,-0.146
20.94,162.21,-0.145
20.96,162.10,-0.146
20.97,161.98,-0.145
20.98,161.87,-0.145
20.99,161.75,-0.145
21.00,161.63,-0.145
21.01,161.52,-0.145
21.03,161.40,-0.145
21.04,161.28,-0.145
21.05,161.17,-0.145
21.06,161.05,-0.145
21.07,160.93,-0.145
21.08,160.82,-0.145
21.09,160.70,-0.145
21.11,160.58,-0.145
21.12,160.47,-0.145
21.13,160.35,-0.144
21.14,160.23,-0.144
21.15,160.12,-0.144
21.17,160.00,-0.144
21.18,159.88,-0.144
21.19,159.77,-0.144
21.20,159.65,-0.144
21.21,159.53,-0.144
21.22,159.42,-0.144
21.23,159.30,-0.144
21.25,159.18,-0.144
21.26,159.07,-0.144
21.27,158.95,-0.144
21.28,158.83,-0.144
21.29,158.72,-0.144
21.31,158.60,-0.144
21.32,158.48,-0.144
21.33,158.37,-0.144
21.34,158.25,-0.144
21.35,158.14,-0.144
21.36,158.02,-0.144
21.38,157.90,-0.144
21.39,157.79,-0.144
21.40,157.67,-0.144
21.41,157.55,-0.144
21.42,157.44,-0.143
21.43,157.32,-0.143
21.44,157.20,-0.143
21.46,157.09,-0.143
21.47,156.97,-0.143
21.48,156.85,-0.143
21.49,156.74,-0.143
21.50,156.62,-0.143
21.52,156.50,-0.143
21.53,156.39,-0.143
21.54,156.27,-0.143
21.55,156.15,-0.143
21.56,156.04,-0.143
21.57,155.92,-0.143
21.58,155.80,-0.143
21.60,155.69,-0.143
21.61,155.57,-0.143
21.62,155.45,-0.143
21.63,155.34,-0.143
21.64,155.22,-0.143
21.66,155.10,-0.143
21.67,154.99,-0.143
21.68,154.87,-0.142
21.69,154.76,-0.656
21.70,154.78,-7.056
21.71,155.09,-11.221
21.73,155.30,-9.554
21.74,155.34,-6.030
21.75,155.16,-1.969
21.76,154.91,-0.957
21.77,154.68,-0.744
21.78,154.46,-0.641
21.79,154.26,-0.563
21.81,154.07,-0.505
21.82,153.88,-0.456
21.83,153.71,-0.410
21.84,153.55,-0.372
21.85,153.39,-0.342
21.87,153.23,-0.314
21.88,153.09,-0.291
21.89,152.94,-0.271
21.90,152.80,-0.251
21.91,152.67,-0.238
21.92,152.53,-0.223
21.93,152.40,-0.211
21.95,152.27,-0.203
21.96,152.14,-0.194
21.97,152.02,-0.186
21.98,151.89,-0.179
21.99,151.77,-0.174
22.01,151.65,-0.173
22.02,151.52,-0.164
22.03,151.40,-0.163
22.04,151.28,-0.160
22.05,151.16,-0.158
22.06,151.04,-0.155
22.08,150.92,-0.154
22.09,150.81,-0.153
22.10,150.69,-0.151
22.11,150.57,-0.150
22.12,150.45,-0.147
22.13,150.33,-0.147
22.14,150.22,-0.147
22.16,150.10,-0.147
22.17,149.98,-0.146
22.18,149.86,-0.146
22.19,149.75,-0.145
22.20,149.63,-0.145
22.22,149.51,-0.144
22.23,149.39,-0.144
22.24,149.28,-0.144
22.25,149.16,-0.144
22.26,149.05,-0.144
22.27,148.93,-0.143
22.28,148.81,-0.143
22.30,148.69,-0.142
22.31,148.58,-0.142
22.32,148.46,-0.142
22.33,148.34,-0.142
22.34,148.23,-0.142
22.36,148.11,-0.142
22.37,147.99,-0.142
22.38,147.88,-0.142
22.39,147.76,-0.141
22.40,147.64,-0.141
22.41,147.53,-0.141
22.43,147.41,-0.141
22.44,147.29,-0.141
22.45,147.18,-0.141
22.46,147.06,-0.141
22.47,146.94,-0.141
22.48,146.83,-0.141
22.49,146.71,-0.141
22.51,146.59,-0.140
22.52,146.48,-0.140
22.53,146.36,-0.140
22.54,146.25,-0.140
22.55,146.13,-0.140
22.57,146.01,-0.140
22.58,145.90,-0.140
22.59,145.78,-0.140
22.60,145.66,-0.140
22.61,145.55,-0.140
22.62,145.43,-0.139
22.63,145.31,-0.139
22.65,145.20,-0.139
22.66,145.08,-0.139
22.67,144.96,-0.139
22.68,144.85,-0.139
22.69,144.73,-0.139
22.71,144.62,-0.139
22.72,144.50,-0.139
22.73,144.38,-0.139
22.74,144.26,-0.139
22.75,144.15,-0.139
22.76,144.03,-0.139
22.78,143.92,-0.139
22.79,143.80,-0.139
22.80,143.68,-0.139
22.81,143.57,-0.138
22.82,143.45,-0.138
22.83,143.33,-0.138
22.84,143.22,-0.138
22.86,143.10,-0.138
22.87,142.98,-0.138
22.88,142.87,-0.138
22.89,142.75,-0.138
22.90,142.63,-0.138
22.92,142.52,-0.138
22.93,142.40,-0.138
22.94,142.28,-0.138
22.95,142.17,-0.138
22.96,142.05,-0.138
22.97,141.93,-0.138
22.98,141.82,-0.138
23.00,141.70,-0.138
23.01,141.58,-0.138
23.02,141.47,-0.138
[...]
94.30,148.70,-0.143
94.31,148.58,-0.142
94.32,148.47,-0.142
94.33,148.35,-0.142
94.35,148.23,-0.142
94.36,148.12,-0.142
94.37,148.00,-0.142
94.38,147.88,-0.142
94.39,147.77,-0.141
94.40,147.65,-0.141
94.41,147.53,-0.141
94.43,147.42,-0.141
94.44,147.30,-0.141
94.45,147.18,-0.141
94.46,147.07,-0.141
94.47,146.95,-0.141
94.49,146.83,-0.140
94.50,146.72,-0.140
94.51,146.60,-0.140
94.52,146.48,-0.140
94.53,146.37,-0.140
94.54,146.25,-0.140
94.55,146.13,-0.140
94.57,146.02,-0.140
94.58,145.90,-0.140
94.59,145.78,-0.140
94.60,145.67,-0.139
94.61,145.55,-0.139
94.63,145.44,-0.139
94.64,145.32,-0.139
94.65,145.20,-0.139
94.66,145.09,-0.139
94.67,144.97,-0.139
94.68,144.85,-0.139
94.70,144.74,-0.139
94.71,144.62,-0.139
94.72,144.50,-0.139
94.73,144.39,-0.139
94.74,144.27,-0.139
94.75,144.15,-0.138
94.76,144.04,-0.138
94.78,143.92,-0.138
94.79,143.80,-0.138
94.80,143.69,-0.138
94.81,143.57,-0.138
94.82,143.45,-0.138
94.84,143.34,-0.138
94.85,143.22,-0.138
94.86,143.10,-0.138
94.87,142.99,-0.138
94.88,142.87,-0.138
94.89,142.76,-0.138
94.90,142.64,-0.138
94.92,142.52,-0.138
94.93,142.41,-0.138
94.94,142.29,-0.137
94.95,142.17,-0.137
94.96,142.06,-0.137
94.98,141.94,-0.137
94.99,141.82,-0.137
95.00,141.71,-0.137
95.01,141.59,-0.137
95.02,141.47,-0.137
95.03,141.36,-0.137
95.05,141.24,-0.137
95.06,141.12,-0.137
95.07,141.01,-0.137
95.08,140.89,-0.137
95.09,140.77,-0.137
95.10,140.66,-0.137
95.11,140.54,-0.137
95.13,140.42,-0.137
95.14,140.31,-0.137
95.15,140.19,-0.137
95.16,140.07,-0.137
95.17,139.96,-0.137
95.19,139.84,-0.137
95.20,139.72,-0.137
95.21,139.61,-0.137
95.22,139.49,-0.137
95.23,139.37,-0.136
95.24,139.26,-0.136
95.25,139.14,-0.136
95.27,139.02,-0.136
95.28,138.91,-0.136
95.29,138.79,-0.136
95.30,138.67,-0.136
95.31,138.56,-0.136
95.33,138.44,-0.136
95.34,138.32,-0.136
95.35,138.21,-0.136
95.36,138.09,-0.136
95.37,137.98,-0.136
95.38,137.86,-0.136
95.40,137.74,-0.136
95.41,137.63,-0.136
95.42,137.51,-0.136
95.43,137.39,-0.135
95.44,137.28,-0.135
95.45,137.16,-0.135
95.46,137.04,-0.135
95.48,136.93,-0.135
95.49,136.81,-0.135
95.50,136.69,-0.135
95.51,136.58,-0.135
95.52,136.46,-0.135
95.54,136.34,-0.135
95.55,136.23,-0.135
95.56,136.11,-0.135
95.57,135.99,-0.135
95.58,135.88,-0.135
95.59,135.76,-0.135
95.60,135.64,-0.135
95.62,135.53,-0.135
95.63,135.41,-0.135
95.64,135.30,-0.135
95.65,135.18,-0.135
95.66,135.06,-0.134
95.68,134.95,-0.134
95.69,134.83,-0.134
95.70,134.71,-0.134
95.71,134.60,-0.134
95.72,134.48,-0.134
95.73,134.36,-0.134
95.75,134.25,-0.134
95.76,134.13,-0.134
95.77,134.01,-0.134
95.78,133.90,-0.134
95.79,133.78,-0.134
95.80,133.66,-0.134
95.81,133.55,-0.134
95.83,133.43,-0.134
95.84,133.31,-0.134
95.85,133.20,-0.134
95.86,133.08,-0.134
95.87,132.96,-0.134
95.89,132.85,-0.134
95.90,132.73,-0.134
95.91,132.62,-0.134
95.92,132.50,-0.134
95.93,132.38,-0.134
95.94,132.26,-0.134
95.95,132.15,-0.134
95.97,132.03,-0.134
95.98,131.92,-0.134
95.99,131.80,-0.133
96.00,131.68,-0.133
96.01,131.57,-0.133
96.03,131.45,-0.133
96.04,131.33,-0.133
96.05,131.22,-0.133
96.06,131.10,-0.133
96.07,130.98,-0.133
96.08,130.87,-0.133
96.10,130.75,-0.133
96.11,130.63,-0.133
96.12,130.52,-0.133
96.13,130.40,-0.133
96.14,130.28,-0.133
96.15,130.17,-0.133
96.16,130.05,-0.133
96.18,129.93,-0.133
96.19,129.82,-0.133
96.20,129.70,-0.133
96.21,129.58,-0.133
96.22,129.47,-0.133
96.24,129.35,-0.132
96.25,129.24,-0.132
96.26,129.12,-0.132
96.27,129.00,-0.132
96.28,128.89,-0.132
96.29,128.77,-0.132
96.30,128.65,-0.132
96.32,128.54,-0.132
96.33,128.42,-0.132
96.34,128.30,-0.132
96.35,128.19,-0.132
96.36,128.07,-0.132
96.38,127.95,-0.132
96.39,127.84,-0.132
96.40,127.72,-0.132
96.41,127.60,-0.132
96.42,127.49,-0.132
96.43,127.37,-0.132
96.45,127.25,-0.132
96.46,127.14,-0.132
96.47,127.02,-0.132
96.48,126.90,-0.132
96.49,126.79,-0.132
96.50,126.67,-0.132
96.51,126.55,-0.132
96.53,126.44,-0.132
96.54,126.32,-0.132
96.55,126.20,-0.132
96.56,126.09,-0.132
96.57,125.97,-0.132
96.59,125.85,-0.132
96.60,125.74,-0.132
96.61,125.62,-0.132
96.62,125.50,-0.131
96.63,125.39,-0.131
96.64,125.27,-0.131
96.65,125.15,-0.131
96.67,125.04,-0.131
96.68,124.92,-0.131
96.69,124.80,-0.131
96.70,124.69,-0.131
96.71,124.57,-0.131
96.73,124.46,-0.131
96.74,124.34,-0.131
96.75,124.22,-0.131
96.76,124.11,-0.131
96.77,123.99,-0.131
96.78,123.87,-0.131
96.80,123.76,-0.131
96.81,123.64,-0.131
96.82,123.52,-0.131
96.83,123.41,-0.131
96.84,123.29,-0.131
96.85,123.17,-0.131
96.86,123.06,-0.131
96.88,122.94,-0.131
96.89,122.82,-0.131
96.90,122.71,-0.131
96.91,122.59,-0.131
96.92,122.47,-0.130
96.94,122.36,-0.130
96.95,122.24,-0.130
96.96,122.12,-0.130
96.97,122.01,-0.130
96.98,121.89,-0.130
96.99,121.77,-0.130
97.00,121.66,-0.130
97.02,121.54,-0.130
97.03,121.42,-0.130
97.04,121.31,-0.130
97.05,121.19,-0.130
97.06,121.07,-0.130
97.08,120.96,-0.130
97.09,120.84,-0.130
97.10,120.73,-0.130
97.11,120.61,-0.130
97.12,120.49,-0.130
97.13,120.38,-0.130
97.15,120.26,-0.130
97.16,120.14,-0.130
97.17,120.03,-0.130
97.18,119.91,-0.130
97.19,119.79,-0.130
97.20,119.68,-0.130
97.21,119.56,-0.130
97.23,119.44,-0.130
97.24,119.33,-0.130
97.25,119.21,-0.130
97.26,119.09,-0.130
97.27,118.98,-0.130
97.29,118.86,-0.129
97.30,118.74,-0.129
97.31,118.63,-0.129
97.32,118.51,-0.129
97.33,118.40,-0.129
97.34,118.28,-0.129
97.35,118.16,-0.129
97.37,118.05,-0.129
97.38,117.93,-0.129
97.39,117.81,-0.129
97.40,117.70,-0.129
97.41,117.58,-0.129
97.43,117.46,-0.132
97.44,117.35,-0.135
97.45,117.23,-0.135
97.46,117.12,-0.134
97.47,117.00,-0.134
97.48,116.88,-0.134
97.50,116.76,-0.134
97.51,116.65,-0.134
97.52,116.53,-0.133
97.53,116.41,-0.133
97.54,116.30,-0.133
97.55,116.18,-0.132
97.56,116.06,-0.132
97.58,115.95,-0.132
97.59,115.83,-0.132
97.60,115.71,-0.132
97.61,115.60,-0.131
97.62,115.48,-0.131
97.64,115.36,-0.131
97.65,115.25,-0.131
97.66,115.13,-0.131
97.67,115.01,-0.131
97.68,114.90,-0.130
97.69,114.78,-0.130
97.70,114.66,-0.130
97.72,114.55,-0.130
97.73,114.43,-0.130
97.74,114.31,-0.130
97.75,114.20,-0.130
97.76,114.08,-0.130
97.78,113.96,-0.130
97.79,113.85,-0.130
97.80,113.73,-0.130
97.81,113.61,-0.129
97.82,113.50,-0.129
97.83,113.38,-0.129
97.85,113.26,-0.129
97.86,113.15,-0.129
97.87,113.03,-0.129
97.88,112.92,-0.129
97.89,112.80,-0.129
97.90,112.68,-0.129
97.91,112.57,-0.129
97.93,112.45,-0.128
97.94,112.33,-0.128
97.95,112.22,-0.128
97.96,112.10,-0.128
97.97,111.98,-0.128
97.99,111.87,-0.128
98.00,111.75,-0.128
98.01,111.63,-0.128
98.02,111.52,-0.128
98.03,111.40,-0.128
98.04,111.28,-0.128
98.05,111.17,-0.128
98.07,111.05,-0.128
98.08,110.94,-0.128
98.09,110.82,-0.128
98.10,110.70,-0.128
98.11,110.59,-0.128
98.13,110.47,-0.128
98.14,110.35,-0.128
98.15,110.24,-0.128
98.16,110.12,-0.128
98.17,110.00,-0.128
98.18,109.89,-0.128
98.20,109.77,-0.128
98.21,109.65,-0.128
98.22,109.54,-0.128
98.23,109.42,-0.128
98.24,109.30,-0.128
98.25,109.19,-0.128
98.26,109.07,-0.128
98.28,108.95,-0.128
98.29,108.84,-0.128
98.30,108.72,-0.128
98.31,108.60,-0.128
98.32,108.49,-0.128
98.34,108.37,-0.128
98.35,108.25,-0.127
98.36,108.14,-0.127
98.37,108.02,-0.127
98.38,107.90,-0.127
98.39,107.79,-0.127
98.40,107.67,-0.127
98.42,107.55,-0.127
98.43,107.44,-0.127
98.44,107.32,-0.127
98.45,107.20,-0.127
98.46,107.09,-0.127
98.48,106.97,-0.127
98.49,106.85,-0.127
98.50,106.74,-0.127
98.51,106.62,-0.127
98.52,106.50,-0.127
98.53,106.39,-0.127
98.55,106.27,-0.127
98.56,106.15,-0.127
98.57,106.04,-0.127
98.58,105.92,-0.127
98.59,105.80,-0.127
98.60,105.69,-0.127
98.61,105.57,-0.127
98.63,105.45,-0.126
98.64,105.34,-0.126
98.65,105.22,-0.126
98.66,105.11,-0.126
98.67,104.99,-0.126
98.69,104.87,-0.126
98.70,104.75,-0.126
98.71,104.64,-0.126
98.72,104.52,-0.126
98.73,104.40,-0.126
98.74,104.29,-0.126
98.75,104.17,-0.126
98.77,104.05,-0.126
98.78,103.94,-0.126
98.79,103.82,-0.126
98.80,103.70,-0.126
98.81,103.59,-0.126
98.83,103.47,-0.126
98.84,103.35,-0.126
98.85,103.24,-0.126
98.86,103.12,-0.126
98.87,103.00,-0.126
98.88,102.89,-0.126
98.90,102.77,-0.126
98.91,102.65,-0.125
98.92,102.54,-0.125
98.93,102.42,-0.125
98.94,102.30,-0.125
98.95,102.19,-0.125
98.96,102.07,-0.125
98.98,101.96,-0.125
98.99,101.84,-0.125
99.00,101.72,-0.125
99.01,101.61,-0.125
99.02,101.49,-0.125
99.04,101.37,-0.125
99.05,101.26,-0.125
99.06,101.14,-0.125
99.07,101.02,-0.125
99.08,100.91,-0.125
99.09,100.79,-0.125
99.10,100.68,-0.125
99.12,100.56,-0.125
99.13,100.44,-0.124
99.14,100.33,-0.124
99.15,100.21,-0.124
99.16,100.09,-0.124
99.18,99.98,-0.124
99.19,99.86,-0.124
99.20,99.74,-0.124
99.21,99.63,-0.124
99.22,99.51,-0.124
99.23,99.39,-0.124
99.25,99.28,-0.124
99.26,99.16,-0.124
99.27,99.04,-0.124
99.28,98.93,-0.124
99.29,98.81,-0.124
99.30,98.70,-0.124
99.31,98.58,-0.124
99.33,98.46,-0.124
99.34,98.35,-0.124
99.35,98.23,-0.124
99.36,98.11,-0.124
99.37,98.00,-0.124
99.39,97.88,-0.124
99.40,97.76,-0.124
99.41,97.65,-0.124
99.42,97.53,-0.123
99.43,97.41,-0.124
99.44,97.30,-0.123
99.45,97.18,-0.123
99.47,97.06,-0.123
99.48,96.95,-0.123
99.49,96.83,-0.123
99.50,96.72,-0.123
99.51,96.60,-0.123
99.53,96.48,-0.123
99.54,96.36,-0.123
99.55,96.25,-0.123
99.56,96.13,-0.123
99.57,96.01,-0.123
99.58,95.90,-0.123
99.60,95.78,-0.123
99.61,95.66,-0.123
99.62,95.55,-0.123
99.63,95.43,-0.123
99.64,95.31,-0.123
99.65,95.20,-0.123
99.66,95.08,-0.123
99.68,94.96,-0.123
99.69,94.85,-0.123
99.70,94.73,-0.123
99.71,94.62,-0.123
99.72,94.50,-0.123
99.74,94.38,-0.123
99.75,94.27,-0.123
99.76,94.15,-0.122
99.77,94.03,-0.123
99.78,93.92,-0.123
99.79,93.80,-0.122
99.80,93.68,-0.122
99.82,93.57,-0.122
99.83,93.45,-0.122
99.84,93.33,-0.122
99.85,93.22,-0.122
99.86,93.10,-0.122
99.88,92.98,-0.122
99.89,92.87,-0.122
99.90,92.75,-0.122
99.91,92.63,-0.122
99.92,92.52,-0.122
99.93,92.40,-0.122
99.95,92.29,-0.122
99.96,92.17,-0.122
99.97,92.05,-0.122
99.98,91.93,-0.122
99.99,91.82,-0.122
100.00,91.70,-0.122
100.01,91.58,-0.122
100.03,91.47,-0.121
100.04,91.35,-0.122
100.05,91.23,-0.121
100.06,91.12,-0.121
100.07,91.00,-0.121
100.09,90.89,-0.121
100.10,90.77,-0.121
100.11,90.65,-0.121
100.12,90.54,-0.121
100.13,90.42,-0.121
100.14,90.30,-0.121
100.15,90.19,-0.121
100.17,90.07,-0.121
100.18,89.95,-0.121
100.19,89.84,-0.121
100.20,89.72,-0.121
100.21,89.60,-0.121
100.23,89.49,-0.121
100.24,89.37,-0.121
100.25,89.25,-0.121
100.26,89.14,-0.120
100.27,89.02,-0.120
100.28,88.90,-0.120
100.30,88.79,-0.120
100.31,88.67,-0.120
100.32,88.55,-0.120
100.33,88.44,-0.120
100.34,88.32,-0.120
100.35,88.21,-0.120
100.36,88.09,-0.120
100.38,87.97,-0.120
100.39,87.86,-0.120
100.40,87.74,-0.120
100.41,87.62,-0.120
100.42,87.51,-0.120
100.44,87.39,-0.120
100.45,87.27,-0.120
100.46,87.16,-0.120
100.47,87.04,-0.120
100.48,86.92,-0.120
100.49,86.81,-0.120
100.50,86.69,-0.120
100.52,86.57,-0.119
100.53,86.46,-0.119
100.54,86.34,-0.119
100.55,86.22,-0.119
100.56,86.11,-0.119
100.58,85.99,-0.119
100.59,85.87,-0.119
100.60,85.76,-0.119
100.61,85.64,-0.119
100.62,85.52,-0.119
100.63,85.41,-0.119
100.65,85.29,-0.119
100.66,85.18,-0.119
100.67,85.06,-0.119
100.68,84.94,-0.119
100.69,84.82,-0.119
100.70,84.71,-0.119
100.71,84.59,-0.119
100.73,84.48,-0.119
100.74,84.36,-0.119
100.75,84.24,-0.119
100.76,84.13,-0.119
100.77,84.01,-0.119
100.79,83.89,-0.119
100.80,83.78,-0.119
100.81,83.66,-0.119
100.82,83.54,-0.119
100.83,83.43,-0.119
100.84,83.31,-0.119
100.85,83.20,-0.119
100.87,83.08,-0.119
100.88,82.96,-0.119
100.89,82.85,-0.119
100.90,82.73,-0.119
100.91,82.61,-0.119
100.93,82.50,-0.119
100.94,82.38,-0.119
100.95,82.26,-0.119
100.96,82.15,-0.119
100.97,82.03,-0.119
100.98,81.91,-0.119
101.00,81.80,-0.119
101.01,81.68,-0.119
101.02,81.56,-0.119
101.03,81.45,-0.119
101.04,81.33,-0.119
101.05,81.21,-0.119
101.06,81.10,-0.119
101.08,80.98,-0.119
101.09,80.86,-0.119
101.10,80.75,-0.119
101.11,80.63,-0.119
101.12,80.51,-0.119
101.14,80.40,-0.119
101.15,80.28,-0.119
101.16,80.16,-0.119
101.17,80.05,-0.119
101.18,79.93,-0.119
101.19,79.81,-0.119
101.20,79.70,-0.119
101.22,79.58,-0.119
101.23,79.46,-0.119
101.24,79.35,-0.119
101.25,79.23,-0.119
101.26,79.11,-0.119
101.28,79.00,-0.119
101.29,78.88,-0.119
101.30,78.76,-0.119
101.31,78.65,-0.119
101.32,78.53,-0.119
101.33,78.42,-0.119
101.35,78.30,-0.119
101.36,78.18,-0.119
101.37,78.07,-0.119
101.38,77.95,-0.119
101.39,77.83,-0.119
101.40,77.71,-0.119
101.41,77.60,-0.119
101.43,77.48,-0.119
101.44,77.37,-0.119
101.45,77.25,-0.119
101.46,77.13,-0.118
101.47,77.01,-0.118
101.49,76.90,-0.118
101.50,76.78,-0.118
101.51,76.67,-0.118
101.52,76.55,-0.118
101.53,76.43,-0.118
101.54,76.32,-0.118
101.55,76.20,-0.118
101.57,76.09,-0.118
101.58,75.97,-0.118
101.59,75.85,-0.118
101.60,75.74,-0.118
101.61,75.62,-0.118
101.63,75.50,-0.118
101.64,75.39,-0.118
101.65,75.27,-0.118
101.66,75.15,-0.118
101.67,75.04,-0.118
101.68,74.92,-0.118
101.70,74.80,-0.118
101.71,74.69,-0.118
101.72,74.57,-0.118
101.73,74.45,-0.118
101.74,74.34,-0.118
101.75,74.22,-0.118
101.76,74.10,-0.118
101.78,73.99,-0.118
101.79,73.87,-0.118
101.80,73.75,-0.118
101.81,73.64,-0.118
101.82,73.52,-0.118
101.84,73.40,-0.118
101.85,73.29,-0.118
101.86,73.17,-0.118
101.87,73.05,-0.117
101.88,72.94,-0.118
101.89,72.82,-0.117
101.90,72.70,-0.117
101.92,72.59,-0.117
101.93,72.47,-0.117
101.94,72.35,-0.117
101.95,72.24,-0.117
101.96,72.12,-0.117
101.98,72.00,-0.117
101.99,71.89,-0.117
102.00,71.77,-0.117
102.01,71.65,-0.117
102.02,71.54,-0.117
102.03,71.42,-0.117
102.05,71.30,-0.117
102.06,71.19,-0.117
102.07,71.07,-0.117
102.08,70.95,-0.117
102.09,70.84,-0.117
102.10,70.72,-0.117
102.11,70.60,-0.117
102.13,70.49,-0.117
102.14,70.37,-0.117
102.15,70.25,-0.117
102.16,70.14,-0.117
102.17,70.02,-0.117
102.19,69.90,-0.117
102.20,69.79,-0.117
102.21,69.67,-0.117
102.22,69.56,-0.117
102.23,69.44,-0.117
102.24,69.32,-0.117
102.25,69.21,-0.117
102.27,69.09,-0.117
102.28,68.97,-0.117
102.29,68.86,-0.116
102.30,68.74,-0.116
102.31,68.62,-0.116
102.33,68.51,-0.116
102.34,68.39,-0.116
102.35,68.27,-0.116
102.36,68.16,-0.116
102.37,68.04,-0.116
102.38,67.92,-0.116
102.40,67.81,-0.116
102.41,67.69,-0.116
102.42,67.58,-0.116
102.43,67.46,-0.116
102.44,67.34,-0.116
102.45,67.23,-0.116
102.46,67.11,-0.116
102.48,66.99,-0.116
102.49,66.88,-0.116
102.50,66.76,-0.116
102.51,66.64,-0.116
102.52,66.53,-0.116
102.54,66.41,-0.116
102.55,66.29,-0.116
102.56,66.18,-0.116
102.57,66.06,-0.116
102.58,65.94,-0.116
102.59,65.83,-0.116
102.60,65.71,-0.116
102.62,65.59,-0.116
102.63,65.48,-0.116
102.64,65.36,-0.116
102.65,65.24,-0.116
102.66,65.13,-0.115
102.68,65.01,-0.115
102.69,64.89,-0.115
102.70,64.78,-0.115
102.71,64.66,-0.115
102.72,64.55,-0.115
102.73,64.43,-0.115
102.75,64.31,-0.115
102.76,64.20,-0.115
102.77,64.08,-0.115
102.78,63.96,-0.115
102.79,63.85,-0.115
102.80,63.73,-0.115
102.81,63.61,-0.115
102.83,63.50,-0.115
102.84,63.38,-0.115
102.85,63.26,-0.115
102.86,63.15,-0.115
102.87,63.03,-0.115
102.89,62.91,-0.115
102.90,62.80,-0.115
102.91,62.68,-0.115
102.92,62.56,-0.115
102.93,62.45,-0.115
102.94,62.33,-0.115
102.95,62.21,-0.115
102.97,62.10,-0.115
102.98,61.98,-0.115
102.99,61.86,-0.115
103.00,61.75,-0.115
103.01,61.63,-0.114
103.03,61.51,-0.114
103.04,61.40,-0.114
103.05,61.28,-0.114
103.06,61.16,-0.114
103.07,61.05,-0.114
103.08,60.93,-0.114
103.10,60.81,-0.114
103.11,60.70,-0.114
103.12,60.58,-0.114
103.13,60.46,-0.114
103.14,60.35,-0.114
103.15,60.23,-0.114
103.16,60.11,-0.114
103.18,60.00,-0.114
103.19,59.88,-0.114
103.20,59.77,-0.114
103.21,59.65,-0.114
103.22,59.53,-0.114
103.24,59.42,-0.114
103.25,59.30,-0.114
103.26,59.18,-0.114
103.27,59.06,-0.114
103.28,58.95,-0.114
103.29,58.83,-0.114
103.30,58.72,-0.114
103.32,58.60,-0.114
103.33,58.48,-0.113
103.34,58.37,-0.113
103.35,58.25,-0.113
103.36,58.13,-0.113
103.38,58.02,-0.113
103.39,57.90,-0.113
103.40,57.79,-0.113
103.41,57.67,-0.113
103.42,57.55,-0.113
103.43,57.43,-0.113
103.45,57.32,-0.113
103.46,57.20,-0.113
103.47,57.08,-0.113
103.48,56.97,-0.113
103.49,56.85,-0.113
103.50,56.73,-0.113
103.51,56.62,-0.113
103.53,56.50,-0.113
103.54,56.39,-0.113
103.55,56.27,-0.113
103.56,56.15,-0.113
103.57,56.04,-0.113
103.59,55.92,-0.113
103.60,55.80,-0.113
103.61,55.69,-0.113
103.62,55.57,-0.113
103.63,55.45,-0.113
103.64,55.34,-0.113
103.65,55.22,-0.113
103.67,55.11,-0.113
103.68,54.99,-0.113
103.69,54.87,-0.113
103.70,54.76,-0.113
103.71,54.64,-0.113
103.73,54.52,-0.113
103.74,54.41,-0.113
103.75,54.29,-0.113
103.76,54.17,-0.113
103.77,54.06,-0.113
103.78,53.94,-0.113
103.80,53.82,-0.113
103.81,53.71,-0.113
103.82,53.59,-0.112
103.83,53.47,-0.112
103.84,53.36,-0.112
103.85,53.24,-0.112
103.86,53.12,-0.112
103.88,53.01,-0.112
103.89,52.89,-0.112
103.90,52.77,-0.112
103.91,52.66,-0.112
103.92,52.54,-0.112
103.94,52.42,-0.112
103.95,52.31,-0.112
103.96,52.19,-0.112
103.97,52.07,-0.112
103.98,51.96,-0.112
103.99,51.84,-0.112
104.00,51.72,-0.112
104.02,51.61,-0.112
104.03,51.49,-0.112
104.04,51.37,-0.112
104.05,51.26,-0.112
104.06,51.14,-0.112
104.08,51.03,-0.112
104.09,50.91,-0.112
104.10,50.79,-0.112
104.11,50.67,-0.112
104.12,50.56,-0.112
104.13,50.44,-0.112
104.15,50.32,-0.111
104.16,50.21,-0.111
104.17,50.09,-0.111
104.18,49.98,-0.111
104.19,49.86,-0.111
104.20,49.74,-0.111
104.21,49.63,-0.111
104.23,49.51,-0.111
104.24,49.39,-0.111
104.25,49.28,-0.111
104.26,49.16,-0.111
104.27,49.04,-0.111
104.29,48.93,-0.111
104.30,48.81,-0.111
104.31,48.69,-0.111
104.32,48.58,-0.111
104.33,48.46,-0.111
104.34,48.34,-0.111
104.35,48.23,-0.111
104.37,48.11,-0.111
104.38,47.99,-0.111
104.39,47.88,-0.111
104.40,47.76,-0.111
104.41,47.64,-0.111
104.43,47.53,-0.111
104.44,47.41,-0.111
104.45,47.29,-0.111
104.46,47.18,-0.111
104.47,47.06,-0.111
104.48,46.94,-0.111
104.50,46.83,-0.111
104.51,46.71,-0.110
104.52,46.59,-0.110
104.53,46.48,-0.110
104.54,46.36,-0.110
104.55,46.24,-0.110
104.56,46.13,-0.110
104.58,46.01,-0.110
104.59,45.90,-0.110
104.60,45.78,-0.110
104.61,45.66,-0.110
104.62,45.55,-0.110
104.64,45.43,-0.110
104.65,45.31,-0.110
104.66,45.20,-0.110
104.67,45.08,-0.110
104.68,44.96,-0.110
104.69,44.85,-0.110
104.70,44.73,-0.110
104.72,44.61,-0.110
104.73,44.50,-0.110
104.74,44.38,-0.110
104.75,44.26,-0.110
104.76,44.15,-0.110
104.78,44.03,-0.110
104.79,43.91,-0.110
104.80,43.80,-0.110
104.81,43.68,-0.110
104.82,43.56,-0.110
104.83,43.45,-0.110
104.85,43.33,-0.110
104.86,43.22,-0.110
104.87,43.10,-0.109
104.88,42.98,-0.109
104.89,42.87,-0.109
104.90,42.75,-0.109
104.91,42.63,-0.109
104.93,42.52,-0.109
104.94,42.40,-0.109
104.95,42.28,-0.109
104.96,42.17,-0.109
104.97,42.05,-0.109
104.99,41.93,-0.109
105.00,41.82,-0.109
105.01,41.70,-0.109
105.02,41.58,-0.109
105.03,41.47,-0.109
105.04,41.35,-0.109
105.05,41.23,-0.109
105.07,41.12,-0.109
105.08,41.00,-0.109
105.09,40.88,-0.109
105.10,40.77,-0.109
105.11,40.65,-0.109
105.13,40.53,-0.109
105.14,40.42,-0.109
105.15,40.30,-0.109
105.16,40.19,-0.109
105.17,40.07,-0.109
105.18,39.95,-0.108
105.20,39.83,-0.108
105.21,39.72,-0.108
105.22,39.60,-0.108
105.23,39.49,-0.108
105.24,39.37,-0.108
105.25,39.25,-0.108
105.26,39.14,-0.108
105.28,39.02,-0.108
105.29,38.90,-0.108
105.30,38.79,-0.108
105.31,38.67,-0.108
105.32,38.55,-0.108
105.34,38.44,-0.108
105.35,38.32,-0.108
105.36,38.20,-0.108
105.37,38.09,-0.108
105.38,37.97,-0.108
105.39,37.85,-0.108
105.40,37.74,-0.108
105.42,37.62,-0.108
105.43,37.50,-0.108
105.44,37.39,-0.108
105.45,37.27,-0.108
105.46,37.16,-0.108
105.48,37.04,-0.108
105.49,36.92,-0.108
105.50,36.81,-0.108
105.51,36.69,-0.108
105.52,36.57,-0.108
105.53,36.46,-0.108
105.55,36.34,-0.108
105.56,36.22,-0.107
105.57,36.10,-0.107
105.58,35.99,-0.107
105.59,35.87,-0.107
105.60,35.76,-0.107
105.61,35.64,-0.107
105.63,35.52,-0.107
105.64,35.41,-0.107
105.65,35.29,-0.107
105.66,35.17,-0.107
105.67,35.06,-0.107
105.69,34.94,-0.107
105.70,34.82,-0.107
105.71,34.71,-0.107
105.72,34.59,-0.107
105.73,34.48,-0.107
105.74,34.36,-0.107
105.75,34.24,-0.107
105.77,34.13,-0.107
105.78,34.01,-0.107
105.79,33.89,-0.107
105.80,33.78,-0.107
105.81,33.66,-0.107
105.83,33.54,-0.107
105.84,33.43,-0.107
105.85,33.31,-0.107
105.86,33.19,-0.107
105.87,33.08,-0.107
105.88,32.96,-0.107
105.90,32.84,-0.107
105.91,32.73,-0.107
105.92,32.61,-0.107
105.93,32.49,-0.107
105.94,32.38,-0.107
105.95,32.26,
105.96,32.14,
105.98,32.03,
105.99,31.91,
106.00,,
106.00,,