File: DSC/2025_06_14_CBN_PyroGA_MC_n60C_200C_10Cmin_x3.csv
Filename,2025_06_14_CBN_PyroGA_MC_n60C_200C_10Cmin_x3
Instrument name,DSC2A-00468 (192.168.1.100)
Operator,Yarger
rundate,6/14/2025
Sample name,2025_06_14_CBN_PyroGA_MC_n60C_200C_10Cmin_x3
proceduresegments,Data Off ; Equilibrate -60.00 °C; Data On ; Ramp 10.00 °C/min to 200.00 °C; Data Off ; Isothermal 2.0 min; Data On ; Ramp 10.00 °C/min to -60.00 °C; Data Off ; Isothermal 2.0 min; Data On ; Ramp 10.00 °C/min to 200.00 °C; Data Off ; Isothermal 2.0 min; Data On ; Ramp 10.00 °C/min to -60.00 °C; Data Off ; Isothermal 2.0 min; Data On ; Ramp 10.00 °C/min to 30.00 °C
[File Parameters]
Run date,6/14/2025 4:37:51 PM
Trios version,5.1.1.46572
Original File Name,
Current File Name,D:\DSC2500\JYarger\2025_06_14_CBN_PyroGA_MC_n60C_200C_10Cmin_x3.tri
[Procedure]
Procedure Name,CBN_PGA_n60C_200C_10Cmin_x3
Sample Name,2025_06_14_CBN_PyroGA_MC_n60C_200C_10Cmin_x3
Sample Mass,4.55 mg
Reference Sample Mass,0 mg
Pan Mass,56.81 mg
Pan Number,29
Reference Pan Mass,57.05 mg
Reference Pan Number,28
Pan Type,Tzero Aluminum Hermetic
Comments,Al Hermetic DSC Consumables sealed Pan/Lid. A2 Tray (Google Sheet: DSC_Samples_A2_Tray_May2025)
Project Name,CA
Operator,Yarger
Test,Custom
Unload Max Temperature,30
Unload Min Temperature,30
Load Max Temperature,30
Load Min Temperature,30
Stop on Gas Flow Error,Yes
[Signal List]
Signal #1,Time (min)
Signal #2,Temperature (°C)
Signal #3,Heat Flow (mW)
Signal #4,Delta T (µV)
Signal #5,Delta Tzero (µV)
Signal #6,Tzero Temperature (°C)
Signal #7,Cell Purge (mL/min)
Signal #8,Heater Temp (°C)
Signal #9,Power Delivered (W)
Signal #10,Reference Junction Temperature (°C)
Signal #11,Flange Temperature (°C)
Signal #12,Heat Flow Phase (rad)
Signal #13,Total Heat Capacity (J/°C)
Signal #14,Heat Capacity (J/°C)
[Configuration]
Company Name,ASU
Instrument Name,DSC2A-00468
Instrument Type,DSC2500
Serial Number,DSC2A-00468
IP,192.168.1.100
Location of Instrument,MRRC
DisplayType,Unknown
Sample Interval ,0.1 s/pt
Selected Heat Flow,T4P
Exotherm Direction,Down
Cell Serial,DRC2-00792
Lid Type,Standard
Cooler,RCS 90
Leave Cooler on at End of Sequence,On
Gas 2,Nitrogen
Gas Selected,Channel 1
Flow Rate,50 mL/min
Secondary Purge,On
Licensed Heat Flow,Heat Flow T4P
Modulation Licensed,Yes
[Versions]
Common IDD Version,1
Cortex Version,VER 2.10.2.31
Driver,5.0.0.6
GDM Version,1.0.3.3
TouchscreenVersion,1.0.0.16145
FEP Version,1.2.1.21
FEP Bootloader,2.0.0.5
AutoSampler Version,2.1.1.26
Auto Sampler Bootloader,2.0.0.5
FCM Version,1.1.0.3
FCM Bootloader,2.0.0.5
[Experiment Logs]
Experiment Log Entry # 1,Air Cool is off.
Experiment Log Entry # 3,Data On set to 0
Experiment Log Entry # 5,Equilibrate Segment -60 (C) Started
Experiment Log Entry # 7,Data On set to 1
Experiment Log Entry # 9,Ramp Segment 10 C/min to 200 Started
Experiment Log Entry # 11,Data On set to 0
Experiment Log Entry # 13,Isothermal Segment 2 min started
Experiment Log Entry # 15,Data On set to 1
Experiment Log Entry # 17,Ramp Segment 10 C/min to -60 Started
Experiment Log Entry # 19,Data On set to 0
Experiment Log Entry # 21,Isothermal Segment 2 min started
Experiment Log Entry # 23,Data On set to 1
Experiment Log Entry # 25,Ramp Segment 10 C/min to 200 Started
Experiment Log Entry # 27,Data On set to 0
Experiment Log Entry # 29,Isothermal Segment 2 min started
Experiment Log Entry # 31,Data On set to 1
Experiment Log Entry # 33,Ramp Segment 10 C/min to -60 Started
Experiment Log Entry # 35,Data On set to 0
Experiment Log Entry # 37,Isothermal Segment 2 min started
Experiment Log Entry # 39,Data On set to 1
Experiment Log Entry # 41,Ramp Segment 10 C/min to 30 Started
[Method Log]
Method Log Entry # 1,Data Off
Method Log Entry # 2,Equilibrate -60 °C
Method Log Entry # 3,Data On
Method Log Entry # 4,(Ramp 136400) Ramp 10 °C/minute to 200 °C
Method Log Entry # 5,Data Off
Method Log Entry # 6,Isothermal 2 minutes
Method Log Entry # 7,Data On
Method Log Entry # 8,(Ramp 136404) Ramp 10 °C/minute to -60 °C
Method Log Entry # 9,Data Off
Method Log Entry # 10,Isothermal 2 minutes
Method Log Entry # 11,Data On
Method Log Entry # 12,(Ramp 136408) Ramp 10 °C/minute to 200 °C
Method Log Entry # 13,Data Off
Method Log Entry # 14,Isothermal 2 minutes
Method Log Entry # 15,Data On
Method Log Entry # 16,(Ramp 136412) Ramp 10 °C/minute to -60 °C
Method Log Entry # 17,Data Off
Method Log Entry # 18,Isothermal 2 minutes
Method Log Entry # 19,Data On
Method Log Entry # 20,(Ramp 136416) Ramp 10 °C/minute to 30 °C
Cell Serial,DRC2-00792
[T1 Calibration]
Slope,-0.008529666
Offset,9.636258
Initial Temperature,98.23
GUID,f8bfdadc-4977-4fdf-ba6d-0ba9134940c3
[TZero Calibration]
Date Applied,11/29/2022 4:06:13 PM
Description,From -89.059 °C to 396.009 °C at 20.000°C/min
Gas Type,Nitrogen
Pan Type,None
Source Files 1,C:\Users\yargerlab\Desktop\DSC Data\General\TZero_calibration_11_29_22_2nd(2).tri
Source Files 2,C:\Users\yargerlab\Desktop\DSC Data\General\TZero_calibration_11_29_22_2nd(3).tri
Delta T Offset,13.05235
Delta T Slope,-0.007271007
Delta T0 Offset,-13.69128
Delta T0 Slope,0.06063341
[Temperature Calibration]
Date Applied,11/29/2022 7:12:28 PM
Description,From 106.590 °C to 186.590 °C at 10.000°C/min
Gas Type,Nitrogen
Pan Type,Tzero Aluminum Hermetic
Source Files 1,C:\Users\yargerlab\Desktop\DSC Data\General\Indium(6).tri
Measured 1,157.391
Known 1,156.598
[Cell Constant Calibration]
Date Applied,11/29/2022 7:12:29 PM
Description,From 106.590 °C to 186.590 °C at 10.000°C/min
Gas Type,Nitrogen
Pan Type,Tzero Aluminum Hermetic
Source Files 1,C:\Users\yargerlab\Desktop\DSC Data\General\Indium(6).tri
T4P KCell,1.006051
Onset Slope,63.26126 mW/°C
[Direct Cp Calibration]
Date Applied,11/30/2022 11:04:51 AM
Description,From -79.983 °C to 298.409 °C at 10.000°C/min
Gas Type,Nitrogen
Pan Type,Tzero Aluminum Hermetic
Source Files 1,C:\Users\yargerlab\Desktop\DSC Data\General\Sapphire_Heat_Capacity_11_30_22.tri
[Rev Cp Calibration]
Date Applied,11/30/2022 1:58:51 PM
Description,From -79.996 °C to 292.812 °C at 3.000°C/min
Gas Type,Nitrogen
Pan Type,Tzero Aluminum Hermetic
Source Files 1,C:\Users\yargerlab\Desktop\DSC Data\General\Sapphire_MDSC_Calibration_11_30_22.tri
[step]
Ramp 10.00 °C/min to 200.00 °C
Time,Temperature,Heat Flow (Normalized)
min,°C,W/g
0.00,-59.68,-0.068
0.02,-59.69,-0.067
0.04,-59.70,-0.061
0.05,-59.70,-0.054
0.07,-59.68,-0.047
0.09,-59.65,-0.037
0.11,-59.59,-0.026
0.13,-59.51,-0.011
0.15,-59.42,0.006
0.16,-59.31,0.024
0.18,-59.19,0.045
0.20,-59.06,0.064
0.22,-58.92,0.081
0.24,-58.78,0.099
0.26,-58.63,0.114
0.28,-58.47,0.128
0.29,-58.31,0.140
0.31,-58.15,0.149
0.33,-57.99,0.160
0.35,-57.82,0.167
0.37,-57.66,0.174
0.39,-57.49,0.178
0.40,-57.32,0.186
0.42,-57.15,0.189
0.44,-56.98,0.193
0.46,-56.80,0.196
0.48,-56.63,0.199
0.50,-56.45,0.202
0.51,-56.28,0.203
0.53,-56.10,0.205
0.55,-55.93,0.208
0.57,-55.75,0.209
0.59,-55.57,0.210
0.60,-55.40,0.211
0.62,-55.22,0.213
0.64,-55.04,0.214
0.66,-54.86,0.214
0.68,-54.68,0.216
0.70,-54.50,0.216
0.72,-54.32,0.217
0.73,-54.15,0.217
0.75,-53.97,0.218
0.77,-53.78,0.218
0.79,-53.60,0.219
0.81,-53.42,0.219
0.83,-53.24,0.219
0.84,-53.06,0.220
0.86,-52.88,0.220
0.88,-52.70,0.221
0.90,-52.52,0.221
0.92,-52.34,0.222
0.93,-52.16,0.222
0.95,-51.97,0.222
0.97,-51.79,0.223
0.99,-51.61,0.223
1.01,-51.43,0.223
1.03,-51.25,0.224
1.05,-51.07,0.224
1.06,-50.89,0.225
1.08,-50.71,0.225
1.10,-50.52,0.225
1.12,-50.34,0.226
1.14,-50.16,0.226
1.16,-49.98,0.226
1.17,-49.80,0.226
1.19,-49.61,0.227
1.21,-49.43,0.227
1.23,-49.25,0.227
1.25,-49.07,0.227
1.27,-48.88,0.228
1.28,-48.70,0.228
1.30,-48.52,0.228
1.32,-48.34,0.228
1.34,-48.15,0.229
1.36,-47.97,0.229
1.38,-47.79,0.229
1.39,-47.61,0.229
1.41,-47.42,0.229
1.43,-47.24,0.230
1.45,-47.05,0.230
1.47,-46.87,0.230
1.48,-46.69,0.230
1.50,-46.50,0.230
1.52,-46.32,0.231
1.54,-46.14,0.231
1.56,-45.96,0.231
1.58,-45.77,0.231
1.59,-45.59,0.231
1.61,-45.41,0.231
1.63,-45.23,0.232
1.65,-45.05,0.232
1.67,-44.86,0.232
1.69,-44.68,0.232
1.71,-44.50,0.232
1.72,-44.31,0.232
1.74,-44.13,0.232
1.76,-43.95,0.232
1.78,-43.76,0.232
1.80,-43.58,0.233
1.82,-43.40,0.233
1.83,-43.21,0.233
1.85,-43.03,0.233
1.87,-42.85,0.233
1.89,-42.66,0.233
1.91,-42.48,0.233
1.93,-42.29,0.234
1.94,-42.11,0.234
1.96,-41.93,0.234
1.98,-41.74,0.234
2.00,-41.56,0.234
2.02,-41.38,0.234
2.03,-41.19,0.234
2.05,-41.01,0.235
2.07,-40.83,0.235
2.09,-40.64,0.235
2.11,-40.46,0.235
2.13,-40.27,0.235
2.14,-40.09,0.235
2.16,-39.91,0.235
2.18,-39.72,0.235
2.20,-39.54,0.235
2.22,-39.36,0.236
2.24,-39.17,0.236
2.26,-38.99,0.236
2.27,-38.80,0.236
2.29,-38.62,0.236
2.31,-38.44,0.236
2.33,-38.25,0.236
2.35,-38.07,0.236
2.36,-37.89,0.236
2.38,-37.70,0.236
2.40,-37.52,0.237
2.42,-37.34,0.237
2.44,-37.15,0.237
2.46,-36.97,0.237
2.48,-36.78,0.237
2.49,-36.60,0.237
2.51,-36.42,0.237
2.53,-36.23,0.237
2.55,-36.05,0.237
2.57,-35.87,0.237
2.59,-35.68,0.237
2.60,-35.50,0.237
2.62,-35.32,0.237
2.64,-35.13,0.238
2.66,-34.95,0.238
2.68,-34.76,0.238
2.69,-34.58,0.238
2.71,-34.40,0.238
2.73,-34.21,0.238
2.75,-34.03,0.238
2.77,-33.85,0.238
2.79,-33.66,0.238
2.81,-33.48,0.239
2.82,-33.30,0.239
2.84,-33.11,0.239
2.86,-32.93,0.239
2.88,-32.75,0.239
2.90,-32.56,0.239
2.91,-32.38,0.239
2.93,-32.19,0.239
2.95,-32.01,0.239
2.97,-31.83,0.239
2.99,-31.64,0.240
3.01,-31.46,0.240
3.03,-31.28,0.240
3.04,-31.09,0.240
3.06,-30.91,0.240
3.08,-30.73,0.240
3.10,-30.54,0.240
3.12,-30.36,0.240
3.14,-30.17,0.240
3.15,-29.99,0.240
3.17,-29.81,0.241
3.19,-29.62,0.241
3.21,-29.44,0.241
3.23,-29.25,0.241
3.24,-29.07,0.241
3.26,-28.88,0.241
3.28,-28.70,0.242
3.30,-28.52,0.242
3.32,-28.33,0.242
3.34,-28.15,0.242
3.36,-27.97,0.242
3.37,-27.78,0.242
3.39,-27.60,0.242
3.41,-27.42,0.242
3.43,-27.23,0.242
3.45,-27.05,0.242
3.46,-26.87,0.242
3.48,-26.68,0.242
3.50,-26.50,0.243
3.52,-26.32,0.243
3.54,-26.13,0.243
3.56,-25.95,0.243
3.58,-25.76,0.243
3.59,-25.58,0.243
3.61,-25.40,0.243
3.63,-25.21,0.243
3.65,-25.03,0.243
3.67,-24.85,0.243
3.69,-24.67,0.244
3.70,-24.48,0.244
3.72,-24.30,0.244
3.74,-24.12,0.244
3.76,-23.93,0.244
3.78,-23.75,0.244
3.79,-23.56,0.244
3.81,-23.38,0.244
3.83,-23.20,0.244
3.85,-23.01,0.244
3.87,-22.83,0.244
3.89,-22.65,0.245
3.91,-22.47,0.245
3.92,-22.28,0.245
3.94,-22.10,0.245
3.96,-21.91,0.245
3.98,-21.73,0.245
4.00,-21.55,0.245
4.01,-21.36,0.245
4.03,-21.18,0.245
4.05,-20.99,0.246
4.07,-20.81,0.246
4.09,-20.63,0.246
4.11,-20.44,0.246
4.13,-20.26,0.246
4.14,-20.08,0.246
4.16,-19.89,0.246
4.18,-19.71,0.247
4.20,-19.53,0.247
4.22,-19.34,0.247
4.24,-19.16,0.247
4.25,-18.98,0.247
4.27,-18.79,0.247
4.29,-18.61,0.247
4.31,-18.42,0.247
4.33,-18.24,0.248
4.35,-18.06,0.248
4.36,-17.87,0.248
4.38,-17.69,0.248
4.40,-17.51,0.248
4.42,-17.32,0.248
4.44,-17.14,0.248
4.45,-16.96,0.248
4.47,-16.77,0.248
4.49,-16.59,0.249
4.51,-16.41,0.249
4.53,-16.22,0.249
4.55,-16.04,0.249
4.56,-15.86,0.249
4.58,-15.67,0.249
4.60,-15.49,0.249
4.62,-15.31,0.250
4.64,-15.12,0.250
4.66,-14.94,0.250
4.68,-14.76,0.250
4.69,-14.57,0.250
4.71,-14.39,0.250
4.73,-14.21,0.250
4.75,-14.02,0.251
4.77,-13.84,0.251
4.79,-13.65,0.251
4.80,-13.47,0.251
4.82,-13.29,0.251
4.84,-13.10,0.251
4.86,-12.92,0.251
4.88,-12.74,0.252
4.90,-12.55,0.252
4.91,-12.37,0.252
4.93,-12.19,0.252
4.95,-12.00,0.252
4.97,-11.82,0.252
4.99,-11.64,0.252
5.00,-11.45,0.253
5.02,-11.27,0.253
5.04,-11.08,0.253
5.06,-10.90,0.253
5.08,-10.72,0.253
5.10,-10.53,0.253
5.11,-10.35,0.253
5.13,-10.17,0.254
5.15,-9.98,0.254
5.17,-9.80,0.254
5.19,-9.62,0.254
5.21,-9.43,0.254
5.23,-9.25,0.254
5.24,-9.07,0.254
5.26,-8.88,0.255
5.28,-8.70,0.255
5.30,-8.51,0.255
5.32,-8.33,0.255
5.34,-8.15,0.255
5.35,-7.96,0.255
5.37,-7.78,0.255
5.39,-7.59,0.255
5.41,-7.41,0.256
5.43,-7.23,0.256
5.45,-7.04,0.256
5.46,-6.86,0.256
5.48,-6.68,0.256
5.50,-6.49,0.256
5.52,-6.31,0.256
5.54,-6.13,0.257
5.55,-5.94,0.257
5.57,-5.76,0.257
5.59,-5.58,0.257
5.61,-5.39,0.257
5.63,-5.21,0.257
5.65,-5.03,0.257
5.66,-4.84,0.258
5.68,-4.66,0.258
5.70,-4.48,0.258
5.72,-4.29,0.258
5.74,-4.11,0.258
5.76,-3.93,0.258
5.78,-3.74,0.259
5.79,-3.56,0.259
5.81,-3.38,0.259
5.83,-3.19,0.259
5.85,-3.01,0.259
5.87,-2.82,0.259
5.89,-2.64,0.260
5.90,-2.46,0.260
5.92,-2.27,0.260
5.94,-2.09,0.260
5.96,-1.91,0.260
5.98,-1.72,0.260
6.00,-1.54,0.261
6.01,-1.36,0.261
6.03,-1.17,0.261
6.05,-0.99,0.261
6.07,-0.80,0.261
6.09,-0.62,0.261
6.10,-0.44,0.261
6.12,-0.25,0.262
6.14,-0.07,0.262
6.16,0.11,0.262
6.18,0.30,0.262
6.20,0.48,0.262
6.21,0.66,0.262
6.23,0.85,0.262
6.25,1.03,0.263
6.27,1.21,0.263
6.29,1.40,0.263
6.31,1.58,0.263
6.33,1.76,0.263
6.34,1.95,0.263
6.36,2.13,0.264
6.38,2.32,0.264
6.40,2.50,0.264
6.42,2.68,0.264
6.44,2.87,0.264
6.45,3.05,0.264
6.47,3.23,0.265
6.49,3.42,0.265
6.51,3.60,0.265
6.53,3.78,0.265
6.55,3.97,0.265
6.56,4.15,0.266
6.58,4.34,0.266
6.60,4.52,0.266
6.62,4.70,0.266
6.64,4.89,0.266
6.65,5.07,0.266
6.67,5.25,0.266
6.69,5.44,0.267
6.71,5.62,0.267
6.73,5.80,0.267
6.75,5.99,0.267
6.76,6.17,0.267
6.78,6.35,0.268
6.80,6.54,0.268
6.82,6.72,0.268
6.84,6.90,0.268
6.86,7.09,0.268
6.88,7.27,0.268
6.89,7.46,0.269
6.91,7.64,0.269
6.93,7.82,0.269
6.95,8.01,0.269
6.97,8.19,0.269
6.99,8.37,0.269
7.00,8.56,0.270
7.02,8.74,0.270
7.04,8.92,0.270
7.06,9.11,0.270
7.08,9.29,0.270
7.10,9.47,0.270
7.11,9.66,0.271
7.13,9.84,0.271
7.15,10.03,0.271
7.17,10.21,0.271
7.19,10.39,0.271
7.20,10.58,0.272
7.22,10.76,0.272
7.24,10.94,0.272
7.26,11.13,0.272
7.28,11.31,0.272
7.30,11.49,0.272
7.31,11.68,0.273
7.33,11.86,0.273
7.35,12.04,0.273
7.37,12.23,0.273
7.39,12.41,0.273
7.41,12.59,0.274
7.43,12.78,0.274
7.44,12.96,0.274
7.46,13.15,0.274
7.48,13.33,0.274
7.50,13.51,0.274
7.52,13.70,0.275
7.54,13.88,0.275
7.55,14.06,0.275
7.57,14.25,0.275
7.59,14.43,0.275
7.61,14.61,0.276
7.63,14.80,0.276
7.65,14.98,0.276
7.66,15.16,0.276
7.68,15.35,0.276
7.70,15.53,0.277
7.72,15.71,0.277
7.74,15.90,0.277
7.75,16.08,0.277
7.77,16.27,0.277
7.79,16.45,0.278
7.81,16.63,0.278
7.83,16.82,0.278
7.85,17.00,0.278
7.86,17.18,0.278
7.88,17.37,0.279
7.90,17.55,0.279
7.92,17.73,0.279
7.94,17.92,0.279
7.96,18.10,0.279
7.98,18.28,0.279
7.99,18.47,0.280
8.01,18.65,0.280
8.03,18.84,0.280
8.05,19.02,0.280
8.07,19.20,0.280
8.09,19.39,0.280
8.10,19.57,0.281
8.12,19.75,0.281
8.14,19.94,0.281
8.16,20.12,0.281
8.18,20.30,0.281
8.20,20.49,0.282
8.21,20.67,0.282
8.23,20.85,0.282
8.25,21.04,0.282
8.27,21.22,0.282
8.29,21.40,0.282
8.30,21.59,0.283
8.32,21.77,0.283
8.34,21.95,0.283
8.36,22.14,0.283
8.38,22.32,0.283
8.40,22.51,0.284
8.41,22.69,0.284
8.43,22.87,0.284
8.45,23.06,0.284
8.47,23.24,0.284
8.49,23.42,0.285
8.51,23.61,0.285
8.53,23.79,0.285
8.54,23.97,0.285
8.56,24.16,0.285
8.58,24.34,0.285
8.60,24.52,0.286
8.62,24.71,0.286
8.63,24.89,0.286
8.65,25.07,0.286
8.67,25.26,0.286
8.69,25.44,0.287
8.71,25.62,0.287
8.73,25.81,0.287
8.75,25.99,0.287
8.76,26.17,0.287
8.78,26.36,0.287
8.80,26.54,0.288
8.82,26.72,0.288
8.84,26.91,0.288
8.85,27.09,0.288
8.87,27.28,0.288
8.89,27.46,0.289
8.91,27.64,0.289
8.93,27.83,0.289
8.95,28.01,0.289
8.97,28.19,0.289
8.98,28.38,0.290
9.00,28.56,0.290
9.02,28.74,0.290
9.04,28.93,0.290
9.06,29.11,0.290
9.08,29.30,0.291
9.09,29.48,0.291
9.11,29.66,0.291
9.13,29.85,0.291
9.15,30.03,0.291
9.17,30.21,0.292
9.18,30.40,0.292
9.20,30.58,0.292
9.22,30.76,0.292
9.24,30.95,0.292
9.26,31.13,0.293
9.28,31.32,0.293
9.30,31.50,0.293
9.31,31.68,0.293
9.33,31.87,0.293
9.35,32.05,0.293
9.37,32.23,0.294
9.39,32.42,0.294
9.40,32.60,0.294
9.42,32.78,0.294
9.44,32.97,0.294
9.46,33.15,0.294
9.48,33.33,0.295
9.50,33.52,0.295
9.52,33.70,0.295
9.53,33.88,0.295
9.55,34.07,0.295
9.57,34.25,0.296
9.59,34.44,0.296
9.61,34.62,0.296
9.63,34.80,0.296
9.64,34.98,0.296
9.66,35.17,0.296
9.68,35.35,0.297
9.70,35.54,0.297
9.72,35.72,0.297
9.73,35.90,0.297
9.75,36.09,0.297
9.77,36.27,0.297
9.79,36.45,0.298
9.81,36.64,0.298
9.83,36.82,0.298
9.85,37.00,0.298
9.86,37.19,0.298
9.88,37.37,0.298
9.90,37.55,0.299
9.92,37.74,0.299
9.94,37.92,0.299
9.95,38.11,0.299
9.97,38.29,0.299
9.99,38.47,0.300
10.01,38.66,0.300
10.03,38.84,0.300
10.05,39.02,0.300
10.07,39.21,0.301
10.08,39.39,0.301
10.10,39.57,0.301
10.12,39.76,0.301
10.14,39.94,0.301
10.16,40.12,0.301
10.18,40.31,0.302
10.19,40.49,0.302
10.21,40.67,0.302
10.23,40.86,0.302
10.25,41.04,0.302
10.27,41.22,0.302
10.28,41.41,0.303
10.30,41.59,0.303
10.32,41.77,0.303
10.34,41.96,0.303
10.36,42.14,0.303
10.38,42.33,0.303
10.40,42.51,0.304
10.41,42.69,0.304
10.43,42.88,0.304
10.45,43.06,0.304
10.47,43.24,0.304
10.49,43.43,0.305
10.50,43.61,0.305
10.52,43.79,0.305
10.54,43.98,0.305
10.56,44.16,0.306
10.58,44.35,0.306
10.60,44.53,0.306
10.62,44.71,0.306
10.63,44.89,0.306
10.65,45.08,0.306
10.67,45.26,0.306
10.69,45.45,0.307
10.71,45.63,0.307
10.73,45.81,0.307
10.74,46.00,0.307
10.76,46.18,0.307
10.78,46.36,0.307
10.80,46.54,0.308
10.82,46.73,0.308
10.83,46.91,0.308
10.85,47.10,0.308
10.87,47.28,0.308
10.89,47.46,0.308
10.91,47.65,0.309
10.93,47.83,0.309
10.95,48.01,0.309
10.96,48.20,0.309
10.98,48.38,0.309
11.00,48.56,0.310
11.02,48.75,0.310
11.04,48.93,0.310
11.05,49.11,0.310
11.07,49.30,0.310
11.09,49.48,0.311
11.11,49.67,0.311
11.13,49.85,0.311
11.15,50.03,0.311
11.17,50.21,0.311
11.18,50.40,0.312
11.20,50.58,0.312
11.22,50.77,0.312
11.24,50.95,0.312
11.26,51.13,0.312
11.28,51.32,0.312
11.29,51.50,0.313
11.31,51.69,0.313
11.33,51.87,0.313
11.35,52.05,0.313
11.37,52.24,0.314
11.38,52.42,0.314
11.40,52.60,0.314
11.42,52.79,0.314
11.44,52.97,0.314
11.46,53.15,0.314
11.48,53.34,0.315
11.50,53.52,0.315
11.51,53.70,0.315
11.53,53.89,0.315
11.55,54.07,0.315
11.57,54.25,0.316
11.59,54.44,0.316
11.60,54.62,0.316
11.62,54.80,0.316
11.64,54.99,0.316
11.66,55.17,0.317
11.68,55.36,0.317
11.70,55.54,0.317
11.72,55.72,0.317
11.73,55.90,0.317
11.75,56.09,0.318
11.77,56.27,0.318
11.79,56.46,0.318
11.81,56.64,0.318
11.83,56.82,0.318
11.84,57.01,0.319
11.86,57.19,0.319
11.88,57.37,0.319
11.90,57.56,0.319
11.92,57.74,0.319
11.93,57.92,0.320
11.95,58.11,0.320
11.97,58.29,0.320
11.99,58.48,0.320
12.01,58.66,0.321
12.03,58.84,0.321
12.05,59.03,0.321
12.06,59.21,0.321
12.08,59.39,0.321
12.10,59.58,0.322
12.12,59.76,0.322
12.14,59.94,0.322
12.15,60.13,0.322
12.17,60.31,0.323
12.19,60.49,0.323
12.21,60.68,0.323
12.23,60.86,0.323
12.25,61.04,0.324
12.27,61.23,0.324
12.28,61.41,0.324
12.30,61.60,0.325
12.32,61.78,0.325
12.34,61.96,0.326
12.36,62.15,0.326
12.38,62.33,0.328
12.39,62.51,0.332
12.41,62.69,0.336
12.43,62.87,0.343
12.45,63.06,0.351
12.47,63.24,0.356
12.48,63.42,0.364
12.50,63.60,0.371
12.52,63.79,0.377
12.54,63.97,0.383
12.56,64.15,0.390
12.58,64.33,0.397
12.60,64.51,0.405
12.61,64.69,0.405
12.63,64.88,0.405
12.65,65.06,0.405
12.67,65.24,0.404
12.69,65.43,0.403
12.70,65.61,0.397
12.72,65.80,0.389
12.74,65.98,0.382
12.76,66.16,0.376
12.78,66.35,0.370
12.80,66.54,0.365
12.82,66.72,0.360
12.83,66.91,0.358
12.85,67.09,0.357
12.87,67.27,0.356
12.89,67.46,0.355
12.91,67.64,0.354
12.93,67.83,0.353
12.94,68.01,0.353
12.96,68.19,0.353
12.98,68.38,0.353
13.00,68.56,0.353
13.02,68.75,0.354
13.03,68.93,0.355
13.05,69.11,0.355
13.07,69.30,0.357
13.09,69.48,0.360
13.11,69.66,0.363
13.13,69.84,0.368
13.15,70.03,0.373
13.16,70.21,0.379
13.18,70.39,0.385
13.20,70.57,0.391
13.22,70.76,0.400
13.24,70.94,0.407
13.25,71.12,0.418
13.27,71.30,0.429
13.29,71.48,0.444
13.31,71.66,0.457
13.33,71.84,0.476
13.35,72.02,0.497
13.37,72.20,0.522
13.38,72.38,0.547
13.40,72.55,0.583
13.42,72.73,0.619
13.44,72.90,0.665
13.46,73.07,0.712
13.48,73.24,0.772
13.49,73.41,0.833
13.51,73.58,0.905
13.53,73.75,0.984
13.55,73.91,1.071
13.57,74.07,1.164
13.58,74.23,1.266
13.60,74.39,1.368
13.62,74.54,1.468
13.64,74.70,1.562
13.66,74.85,1.674
13.68,75.00,1.775
13.70,75.16,1.878
13.71,75.31,1.995
13.73,75.46,2.108
13.75,75.61,2.180
13.77,75.77,2.282
13.79,75.92,2.360
13.80,76.08,2.396
13.82,76.24,2.412
13.84,76.41,2.438
13.86,76.58,2.492
13.88,76.75,2.443
13.90,76.93,2.352
13.92,77.12,2.231
13.93,77.33,2.074
13.95,77.54,1.882
13.97,77.76,1.660
13.99,77.99,1.430
14.01,78.23,1.219
14.03,78.47,1.043
14.04,78.70,0.905
14.06,78.94,0.811
14.08,79.16,0.721
14.10,79.38,0.662
14.12,79.59,0.617
14.13,79.80,0.577
14.15,80.01,0.543
14.17,80.21,0.518
14.19,80.41,0.496
14.21,80.61,0.476
14.23,80.80,0.460
14.25,80.99,0.446
14.26,81.18,0.435
14.28,81.37,0.425
14.30,81.56,0.419
14.32,81.75,0.411
14.34,81.94,0.407
14.35,82.12,0.402
14.37,82.31,0.399
14.39,82.49,0.396
14.41,82.68,0.393
14.43,82.86,0.392
14.45,83.05,0.390
14.47,83.23,0.388
14.48,83.42,0.387
14.50,83.60,0.386
14.52,83.79,0.386
14.54,83.97,0.385
14.56,84.16,0.385
14.58,84.34,0.384
14.59,84.52,0.384
14.61,84.71,0.384
14.63,84.89,0.383
14.65,85.07,0.383
14.67,85.26,0.383
14.68,85.44,0.383
14.70,85.63,0.382
14.72,85.81,0.382
14.74,85.99,0.382
14.76,86.18,0.382
14.78,86.36,0.381
14.80,86.54,0.381
14.81,86.73,0.381
14.83,86.91,0.381
14.85,87.10,0.381
14.87,87.28,0.381
14.89,87.46,0.381
14.90,87.65,0.381
14.92,87.83,0.381
14.94,88.01,0.381
14.96,88.20,0.381
14.98,88.38,0.380
15.00,88.56,0.380
15.02,88.75,0.380
15.03,88.93,0.380
15.05,89.12,0.380
15.07,89.30,0.380
15.09,89.48,0.381
15.11,89.66,0.381
15.13,89.85,0.381
15.14,90.03,0.381
15.16,90.22,0.381
15.18,90.40,0.381
15.20,90.58,0.381
15.22,90.77,0.381
15.23,90.95,0.381
15.25,91.13,0.381
15.27,91.32,0.381
15.29,91.50,0.382
15.31,91.68,0.382
15.33,91.87,0.382
15.35,92.05,0.382
15.36,92.23,0.382
15.38,92.42,0.382
15.40,92.60,0.382
15.42,92.78,0.382
15.44,92.97,0.382
15.45,93.15,0.383
15.47,93.33,0.383
15.49,93.52,0.383
15.51,93.70,0.383
15.53,93.88,0.383
15.55,94.07,0.383
15.57,94.25,0.383
15.58,94.43,0.384
15.60,94.62,0.384
15.62,94.80,0.384
15.64,94.99,0.384
15.66,95.17,0.384
15.68,95.35,0.384
15.69,95.54,0.384
15.71,95.72,0.384
15.73,95.90,0.385
15.75,96.09,0.385
15.77,96.27,0.385
15.78,96.45,0.385
15.80,96.64,0.385
15.82,96.82,0.385
15.84,97.00,0.385
15.86,97.19,0.386
15.88,97.37,0.386
15.90,97.55,0.386
15.91,97.74,0.386
15.93,97.92,0.386
15.95,98.10,0.386
15.97,98.29,0.386
15.99,98.47,0.387
16.00,98.65,0.387
16.02,98.84,0.387
16.04,99.02,0.387
16.06,99.21,0.387
16.08,99.39,0.387
16.10,99.57,0.387
16.12,99.75,0.387
16.13,99.94,0.388
16.15,100.12,0.388
16.17,100.30,0.388
16.19,100.49,0.388
16.21,100.67,0.388
16.23,100.86,0.388
16.24,101.04,0.389
16.26,101.22,0.389
16.28,101.41,0.389
16.30,101.59,0.389
16.32,101.77,0.389
16.33,101.96,0.389
16.35,102.14,0.390
16.37,102.32,0.390
16.39,102.51,0.390
16.41,102.69,0.390
16.43,102.87,0.390
16.45,103.06,0.390
16.46,103.24,0.390
16.48,103.42,0.391
16.50,103.61,0.391
16.52,103.79,0.391
16.54,103.97,0.391
16.55,104.16,0.391
16.57,104.34,0.391
16.59,104.53,0.391
16.61,104.71,0.392
16.63,104.89,0.392
16.65,105.08,0.392
16.67,105.26,0.392
16.68,105.44,0.392
16.70,105.63,0.392
16.72,105.81,0.392
16.74,105.99,0.393
16.76,106.18,0.393
16.78,106.36,0.393
16.79,106.54,0.393
16.81,106.73,0.393
16.83,106.91,0.393
16.85,107.09,0.393
16.87,107.28,0.393
16.88,107.46,0.393
16.90,107.65,0.394
16.92,107.83,0.394
16.94,108.01,0.394
16.96,108.20,0.394
16.98,108.38,0.394
17.00,108.56,0.394
17.01,108.75,0.394
17.03,108.93,0.395
17.05,109.11,0.395
17.07,109.30,0.395
17.09,109.48,0.395
17.11,109.66,0.395
17.12,109.85,0.395
17.14,110.03,0.395
17.16,110.22,0.395
17.18,110.40,0.396
17.20,110.58,0.396
17.22,110.77,0.396
17.23,110.95,0.396
17.25,111.13,0.396
17.27,111.32,0.396
17.29,111.50,0.396
17.31,111.68,0.396
17.33,111.87,0.397
17.34,112.05,0.397
17.36,112.24,0.397
17.38,112.42,0.397
17.40,112.61,0.398
17.42,112.79,0.398
17.43,112.98,0.398
17.45,113.16,0.398
17.47,113.35,0.398
17.49,113.53,0.399
17.51,113.71,0.399
17.53,113.90,0.399
17.54,114.08,0.399
17.56,114.26,0.399
17.58,114.45,0.399
17.60,114.63,0.399
17.62,114.81,0.399
17.64,114.99,0.399
17.66,115.18,0.399
17.67,115.36,0.399
17.69,115.54,0.399
17.71,115.73,0.399
17.73,115.91,0.399
17.75,116.09,0.399
17.77,116.28,0.399
17.78,116.46,0.399
17.80,116.64,0.399
17.82,116.83,0.399
17.84,117.01,0.399
17.86,117.19,0.399
17.88,117.37,0.399
17.89,117.56,0.399
17.91,117.74,0.399
17.93,117.93,0.399
17.95,118.11,0.400
17.97,118.29,0.400
17.98,118.48,0.400
18.00,118.66,0.400
18.02,118.84,0.400
18.04,119.03,0.400
18.06,119.21,0.400
18.08,119.39,0.401
18.09,119.58,0.401
18.11,119.76,0.401
18.13,119.94,0.401
18.15,120.13,0.401
18.17,120.31,0.401
18.19,120.49,0.401
18.21,120.68,0.402
18.22,120.86,0.402
18.24,121.04,0.402
18.26,121.22,0.402
18.28,121.41,0.402
18.30,121.59,0.402
18.32,121.77,0.402
18.33,121.96,0.403
18.35,122.14,0.403
18.37,122.32,0.403
18.39,122.51,0.403
18.41,122.69,0.404
18.43,122.88,0.404
18.44,123.06,0.404
18.46,123.24,0.404
18.48,123.43,0.405
18.50,123.61,0.405
18.52,123.79,0.405
18.53,123.98,0.405
18.55,124.16,0.405
18.57,124.34,0.406
18.59,124.53,0.406
18.61,124.71,0.406
18.63,124.89,0.407
18.64,125.07,0.407
18.66,125.26,0.407
18.68,125.44,0.408
18.70,125.63,0.408
18.72,125.81,0.408
18.74,125.99,0.409
18.76,126.18,0.409
18.77,126.36,0.409
18.79,126.54,0.410
18.81,126.73,0.410
18.83,126.91,0.411
18.85,127.09,0.411
18.87,127.28,0.411
18.88,127.46,0.412
18.90,127.64,0.412
18.92,127.83,0.413
18.94,128.01,0.413
18.96,128.20,0.413
18.98,128.38,0.414
18.99,128.56,0.414
19.01,128.75,0.414
19.03,128.93,0.415
19.05,129.11,0.415
19.07,129.30,0.415
19.08,129.48,0.415
19.10,129.66,0.416
19.12,129.85,0.416
19.14,130.03,0.417
19.16,130.21,0.417
19.18,130.40,0.417
19.19,130.58,0.418
19.21,130.76,0.418
19.23,130.95,0.418
19.25,131.13,0.419
19.27,131.31,0.419
19.29,131.50,0.419
19.31,131.68,0.420
19.32,131.86,0.420
19.34,132.05,0.421
19.36,132.23,0.421
19.38,132.41,0.421
19.40,132.60,0.422
19.42,132.78,0.422
19.43,132.97,0.423
19.45,133.15,0.423
19.47,133.33,0.423
19.49,133.52,0.424
19.51,133.70,0.424
19.53,133.88,0.424
19.54,134.07,0.425
19.56,134.25,0.425
19.58,134.43,0.426
19.60,134.62,0.426
19.62,134.80,0.426
19.63,134.98,0.427
19.65,135.17,0.427
19.67,135.35,0.427
19.69,135.53,0.428
19.71,135.72,0.428
19.73,135.90,0.429
19.74,136.08,0.429
19.76,136.27,0.429
19.78,136.45,0.430
19.80,136.63,0.430
19.82,136.82,0.431
19.84,137.00,0.431
19.86,137.18,0.432
19.87,137.36,0.432
19.89,137.55,0.433
19.91,137.73,0.433
19.93,137.91,0.434
19.95,138.10,0.434
19.97,138.28,0.435
19.98,138.46,0.435
20.00,138.65,0.435
20.02,138.83,0.436
20.04,139.01,0.437
20.06,139.20,0.437
20.08,139.38,0.438
20.09,139.56,0.439
20.11,139.75,0.440
20.13,139.93,0.440
20.15,140.11,0.441
20.17,140.30,0.441
20.18,140.48,0.442
20.20,140.66,0.443
20.22,140.85,0.443
20.24,141.03,0.444
20.26,141.21,0.445
20.28,141.40,0.446
20.29,141.58,0.447
20.31,141.76,0.447
20.33,141.95,0.448
20.35,142.13,0.449
20.37,142.31,0.450
20.39,142.50,0.451
20.41,142.68,0.452
20.42,142.86,0.453
20.44,143.05,0.454
20.46,143.23,0.455
20.48,143.41,0.456
20.50,143.60,0.457
20.52,143.78,0.458
20.53,143.96,0.459
20.55,144.15,0.461
20.57,144.33,0.462
20.59,144.51,0.463
20.61,144.70,0.466
20.63,144.88,0.467
20.64,145.06,0.468
20.66,145.25,0.469
20.68,145.43,0.470
20.70,145.61,0.471
20.72,145.80,0.473
20.73,145.98,0.474
20.75,146.16,0.475
20.77,146.35,0.478
20.79,146.53,0.479
20.81,146.71,0.481
20.83,146.90,0.482
20.84,147.08,0.484
20.86,147.26,0.485
20.88,147.45,0.487
20.90,147.63,0.489
20.92,147.81,0.490
20.94,148.00,0.492
20.96,148.18,0.493
20.97,148.36,0.495
20.99,148.54,0.497
21.01,148.73,0.499
21.03,148.91,0.501
21.05,149.09,0.503
21.07,149.28,0.504
21.08,149.46,0.507
21.10,149.64,0.510
21.12,149.82,0.512
21.14,150.01,0.514
21.16,150.19,0.517
21.18,150.37,0.520
21.19,150.55,0.523
21.21,150.74,0.526
21.23,150.92,0.529
21.25,151.10,0.532
21.27,151.28,0.536
21.28,151.47,0.540
21.30,151.65,0.543
21.32,151.83,0.546
21.34,152.01,0.551
21.36,152.20,0.555
21.38,152.38,0.559
21.39,152.56,0.564
21.41,152.74,0.569
21.43,152.93,0.575
21.45,153.11,0.580
21.47,153.29,0.586
21.49,153.47,0.593
21.51,153.66,0.598
21.52,153.84,0.606
21.54,154.02,0.611
21.56,154.20,0.622
21.58,154.38,0.630
21.60,154.56,0.639
21.62,154.74,0.646
21.63,154.93,0.657
21.65,155.11,0.668
21.67,155.29,0.680
21.69,155.47,0.692
21.71,155.65,0.704
21.73,155.83,0.719
21.74,156.01,0.736
21.76,156.19,0.753
21.78,156.37,0.773
21.80,156.55,0.797
21.82,156.73,0.823
21.83,156.90,0.856
21.85,157.08,0.898
21.87,157.25,0.948
21.89,157.43,1.011
21.91,157.60,1.088
21.93,157.76,1.178
21.94,157.93,1.279
21.96,158.09,1.385
21.98,158.25,1.489
22.00,158.41,1.579
22.02,158.57,1.662
22.04,158.73,1.699
22.06,158.90,1.714
22.07,159.07,1.693
22.09,159.25,1.641
22.11,159.43,1.572
22.13,159.62,1.480
22.15,159.82,1.380
22.17,160.02,1.274
22.18,160.23,1.170
22.20,160.43,1.080
22.22,160.64,0.978
22.24,160.85,0.886
22.26,161.06,0.810
22.28,161.26,0.740
22.29,161.47,0.686
22.31,161.67,0.642
22.33,161.87,0.606
22.35,162.06,0.572
22.37,162.26,0.543
22.38,162.45,0.526
22.40,162.64,0.509
22.42,162.84,0.498
22.44,163.02,0.490
22.46,163.21,0.481
22.48,163.40,0.474
22.49,163.59,0.470
22.51,163.77,0.466
22.53,163.96,0.463
22.55,164.14,0.460
22.57,164.33,0.457
22.59,164.51,0.456
22.61,164.70,0.455
22.62,164.88,0.453
22.64,165.07,0.453
22.66,165.25,0.452
22.68,165.44,0.451
22.70,165.62,0.451
22.72,165.80,0.451
22.73,165.99,0.450
22.75,166.17,0.450
22.77,166.35,0.450
22.79,166.54,0.450
22.81,166.72,0.450
22.83,166.91,0.449
22.84,167.09,0.449
22.86,167.27,0.449
22.88,167.45,0.449
22.90,167.64,0.449
22.92,167.82,0.449
22.93,168.01,0.449
22.95,168.19,0.449
22.97,168.37,0.449
22.99,168.56,0.449
23.01,168.74,0.449
23.03,168.92,0.449
23.04,169.11,0.449
23.06,169.29,0.449
23.08,169.47,0.449
23.10,169.66,0.449
23.12,169.84,0.449
23.14,170.02,0.449
23.16,170.21,0.449
23.17,170.39,0.449
23.19,170.57,0.449
23.21,170.76,0.449
23.23,170.94,0.449
23.25,171.12,0.449
23.27,171.31,0.449
23.28,171.49,0.449
23.30,171.67,0.449
23.32,171.86,0.449
23.34,172.04,0.450
23.36,172.22,0.450
23.38,172.41,0.450
23.39,172.59,0.450
23.41,172.77,0.450
23.43,172.96,0.450
23.45,173.14,0.450
23.47,173.33,0.450
23.48,173.51,0.450
23.50,173.69,0.450
23.52,173.88,0.451
23.54,174.06,0.451
23.56,174.24,0.451
23.58,174.43,0.451
23.59,174.61,0.451
23.61,174.79,0.451
23.63,174.98,0.451
23.65,175.16,0.451
23.67,175.34,0.451
23.69,175.53,0.451
23.71,175.71,0.452
23.72,175.90,0.452
23.74,176.08,0.452
23.76,176.26,0.452
23.78,176.45,0.452
23.80,176.63,0.452
23.82,176.81,0.452
23.83,177.00,0.452
23.85,177.18,0.452
23.87,177.36,0.452
23.89,177.55,0.452
23.91,177.73,0.453
23.93,177.91,0.453
23.94,178.10,0.453
23.96,178.28,0.453
23.98,178.46,0.453
24.00,178.65,0.453
24.02,178.83,0.453
24.03,179.01,0.453
24.05,179.20,0.453
24.07,179.38,0.453
24.09,179.56,0.453
24.11,179.75,0.453
24.13,179.93,0.453
24.14,180.11,0.453
24.16,180.30,0.453
24.18,180.48,0.453
24.20,180.66,0.454
24.22,180.85,0.454
24.24,181.03,0.454
24.26,181.22,0.454
24.27,181.40,0.454
24.29,181.58,0.454
24.31,181.76,0.454
24.33,181.95,0.454
24.35,182.13,0.454
24.37,182.32,0.454
24.38,182.50,0.454
24.40,182.68,0.454
24.42,182.87,0.454
24.44,183.05,0.455
24.46,183.23,0.455
24.48,183.42,0.455
24.49,183.60,0.455
24.51,183.78,0.455
24.53,183.97,0.455
24.55,184.15,0.455
24.57,184.33,0.455
24.58,184.52,0.455
24.60,184.70,0.455
24.62,184.88,0.455
24.64,185.07,0.455
24.66,185.25,0.455
24.68,185.43,0.455
24.69,185.62,0.455
24.71,185.80,0.455
24.73,185.98,0.455
24.75,186.17,0.455
24.77,186.35,0.455
24.79,186.54,0.455
24.81,186.72,0.455
24.82,186.90,0.455
24.84,187.09,0.455
24.86,187.27,0.455
24.88,187.45,0.455
24.90,187.64,0.456
24.92,187.82,0.456
24.93,188.00,0.456
24.95,188.19,0.456
24.97,188.37,0.456
24.99,188.55,0.456
25.01,188.74,0.456
25.03,188.92,0.456
25.04,189.10,0.456
25.06,189.29,0.456
25.08,189.47,0.456
25.10,189.66,0.456
25.12,189.84,0.456
25.13,190.02,0.456
25.15,190.20,0.456
25.17,190.39,0.456
25.19,190.57,0.456
25.21,190.75,0.456
25.23,190.94,0.456
25.24,191.12,0.456
25.26,191.30,0.456
25.28,191.49,0.456
25.30,191.67,0.456
25.32,191.85,0.456
25.34,192.04,0.456
25.36,192.22,0.456
25.37,192.41,0.456
25.39,192.59,0.456
25.41,192.77,0.456
25.43,192.96,0.456
25.45,193.14,0.456
25.47,193.32,0.456
25.48,193.51,0.456
25.50,193.69,0.456
25.52,193.88,0.457
25.54,194.06,0.456
25.56,194.24,0.456
25.58,194.42,0.456
25.59,194.61,0.456
25.61,194.79,0.457
25.63,194.98,0.457
25.65,195.16,0.457
25.67,195.34,0.457
25.68,195.52,0.457
25.70,195.71,0.457
25.72,195.89,0.457
25.74,196.08,0.457
25.76,196.26,0.457
25.78,196.44,0.457
25.79,196.62,0.457
25.81,196.81,0.457
25.83,196.99,0.457
25.85,197.18,0.457
25.87,197.36,0.457
25.89,197.54,0.457
25.91,197.73,0.457
25.92,197.91,0.457
25.94,198.09,
25.96,198.28,
25.98,198.46,
25.99,,

[step]
Ramp 10.00 °C/min to -60.00 °C
Time,Temperature,Heat Flow (Normalized)
min,°C,W/g
27.99,200.11,-0.053
28.01,200.11,-0.053
28.03,200.11,-0.053
28.05,200.10,-0.054
28.07,200.08,-0.070
28.08,200.03,-0.099
28.10,199.97,-0.136
28.12,199.89,-0.184
28.14,199.79,-0.234
28.16,199.67,-0.285
28.18,199.54,-0.331
28.19,199.40,-0.371
28.21,199.25,-0.402
28.23,199.10,-0.428
28.25,198.94,-0.451
28.27,198.78,-0.467
28.29,198.61,-0.482
28.31,198.44,-0.494
28.32,198.27,-0.504
28.34,198.10,-0.512
28.36,197.93,-0.519
28.38,197.75,-0.525
28.40,197.58,-0.533
28.42,197.40,-0.534
28.43,197.22,-0.537
28.45,197.04,-0.540
28.47,196.86,-0.545
28.49,196.69,-0.545
28.51,196.51,-0.547
28.53,196.33,-0.548
28.54,196.15,-0.550
28.56,195.97,-0.550
28.58,195.79,-0.551
28.60,195.61,-0.551
28.62,195.42,-0.552
28.63,195.24,-0.552
28.65,195.06,-0.552
28.67,194.88,-0.553
28.69,194.70,-0.553
28.71,194.52,-0.553
28.73,194.34,-0.554
28.74,194.16,-0.554
28.76,193.97,-0.554
28.78,193.79,-0.555
28.80,193.61,-0.555
28.82,193.43,-0.555
28.84,193.25,-0.555
28.86,193.06,-0.555
28.87,192.88,-0.556
28.89,192.70,-0.556
28.91,192.52,-0.556
28.93,192.34,-0.556
28.95,192.15,-0.556
28.97,191.97,-0.556
28.98,191.79,-0.557
29.00,191.61,-0.557
29.02,191.43,-0.557
29.04,191.24,-0.557
29.06,191.06,-0.557
29.08,190.88,-0.557
29.09,190.69,-0.557
29.11,190.51,-0.557
29.13,190.33,-0.557
29.15,190.15,-0.557
29.17,189.96,-0.557
29.18,189.78,-0.557
29.20,189.60,-0.557
29.22,189.42,-0.557
29.24,189.23,-0.557
29.26,189.05,-0.557
29.28,188.87,-0.557
29.29,188.69,-0.557
29.31,188.50,-0.557
29.33,188.32,-0.556
29.35,188.14,-0.556
29.37,187.95,-0.556
29.39,187.77,-0.556
29.41,187.59,-0.556
29.42,187.40,-0.556
29.44,187.22,-0.556
29.46,187.04,-0.556
29.48,186.86,-0.556
29.50,186.67,-0.555
29.52,186.49,-0.555
29.53,186.31,-0.555
29.55,186.12,-0.555
29.57,185.94,-0.555
29.59,185.76,-0.555
29.61,185.58,-0.555
29.63,185.39,-0.554
29.64,185.21,-0.554
29.66,185.03,-0.554
29.68,184.84,-0.554
29.70,184.66,-0.554
29.72,184.48,-0.554
29.73,184.30,-0.554
29.75,184.11,-0.554
29.77,183.93,-0.553
29.79,183.75,-0.553
29.81,183.56,-0.553
29.83,183.38,-0.553
29.84,183.20,-0.553
29.86,183.02,-0.553
29.88,182.83,-0.552
29.90,182.65,-0.552
29.92,182.47,-0.552
29.94,182.28,-0.552
29.96,182.10,-0.552
29.97,181.91,-0.552
29.99,181.73,-0.551
30.01,181.55,-0.551
30.03,181.37,-0.551
30.05,181.19,-0.551
30.07,181.00,-0.551
30.08,180.82,-0.550
30.10,180.63,-0.550
30.12,180.45,-0.550
30.14,180.27,-0.550
30.16,180.09,-0.550
30.18,179.90,-0.550
30.19,179.72,-0.550
30.21,179.54,-0.550
30.23,179.35,-0.549
30.25,179.17,-0.549
30.27,178.99,-0.549
30.28,178.80,-0.549
30.30,178.62,-0.549
30.32,178.44,-0.549
30.34,178.25,-0.549
30.36,178.07,-0.548
30.38,177.89,-0.548
30.39,177.70,-0.548
30.41,177.52,-0.548
30.43,177.34,-0.548
30.45,177.16,-0.548
30.47,176.97,-0.548
30.49,176.79,-0.547
30.51,176.60,-0.547
30.52,176.42,-0.547
30.54,176.24,-0.547
30.56,176.06,-0.547
30.58,175.87,-0.547
30.60,175.69,-0.546
30.62,175.51,-0.546
30.63,175.32,-0.546
30.65,175.14,-0.546
30.67,174.96,-0.546
30.69,174.77,-0.546
30.71,174.59,-0.545
30.73,174.41,-0.545
30.74,174.22,-0.545
30.76,174.04,-0.545
30.78,173.86,-0.545
30.80,173.68,-0.545
30.82,173.49,-0.545
30.83,173.31,-0.545
30.85,173.12,-0.545
30.87,172.94,-0.544
30.89,172.76,-0.544
30.91,172.57,-0.544
30.93,172.39,-0.544
30.94,172.21,-0.544
30.96,172.03,-0.544
30.98,171.84,-0.543
31.00,171.66,-0.543
31.02,171.48,-0.543
31.04,171.29,-0.543
31.06,171.11,-0.543
31.07,170.93,-0.542
31.09,170.74,-0.542
31.11,170.56,-0.542
31.13,170.38,-0.542
31.15,170.20,-0.542
31.17,170.01,-0.542
31.18,169.83,-0.541
31.20,169.65,-0.541
31.22,169.46,-0.541
31.24,169.28,-0.541
31.26,169.10,-0.541
31.28,168.91,-0.541
31.29,168.73,-0.541
31.31,168.55,-0.540
31.33,168.37,-0.540
31.35,168.18,-0.540
31.37,168.00,-0.540
31.38,167.82,-0.540
31.40,167.63,-0.540
31.42,167.45,-0.540
31.44,167.27,-0.540
31.46,167.08,-0.540
31.48,166.90,-0.540
31.49,166.72,-0.539
31.51,166.53,-0.539
31.53,166.35,-0.539
31.55,166.17,-0.539
31.57,165.98,-0.539
31.59,165.80,-0.539
31.61,165.62,-0.539
31.62,165.44,-0.539
31.64,165.25,-0.539
31.66,165.07,-0.539
31.68,164.89,-0.539
31.70,164.70,-0.539
31.72,164.52,-0.538
31.73,164.34,-0.538
31.75,164.15,-0.538
31.77,163.97,-0.538
31.79,163.79,-0.538
31.81,163.60,-0.538
31.83,163.42,-0.538
31.84,163.24,-0.538
31.86,163.05,-0.538
31.88,162.87,-0.537
31.90,162.69,-0.537
31.92,162.50,-0.537
31.93,162.32,-0.537
31.95,162.14,-0.537
31.97,161.95,-0.537
31.99,161.77,-0.536
32.01,161.59,-0.536
32.03,161.41,-0.536
32.04,161.22,-0.536
32.06,161.04,-0.536
32.08,160.86,-0.536
32.10,160.67,-0.536
32.12,160.49,-0.535
32.14,160.31,-0.535
32.16,160.12,-0.535
32.17,159.94,-0.535
32.19,159.76,-0.535
32.21,159.57,-0.535
32.23,159.39,-0.535
32.25,159.21,-0.535
32.27,159.02,-0.534
32.28,158.84,-0.534
32.30,158.66,-0.534
32.32,158.47,-0.534
32.34,158.29,-0.534
32.36,158.11,-0.534
32.38,157.92,-0.534
32.39,157.74,-0.533
32.41,157.56,-0.533
32.43,157.38,-0.533
32.45,157.19,-0.533
32.47,157.01,-0.533
32.48,156.83,-0.533
32.50,156.64,-0.533
32.52,156.46,-0.533
32.54,156.28,-0.533
32.56,156.09,-0.533
32.58,155.91,-0.532
32.59,155.73,-0.532
32.61,155.55,-0.532
32.63,155.36,-0.532
32.65,155.18,-0.532
32.67,155.00,-0.532
32.69,154.81,-0.532
32.71,154.63,-0.532
32.72,154.45,-0.532
32.74,154.26,-0.532
32.76,154.08,-0.532
32.78,153.90,-0.532
32.80,153.71,-0.531
32.82,153.53,-0.531
32.83,153.35,-0.531
32.85,153.16,-0.531
32.87,152.98,-0.531
32.89,152.80,-0.531
32.91,152.61,-0.531
32.93,152.43,-0.531
32.94,152.25,-0.531
32.96,152.07,-0.531
32.98,151.88,-0.531
33.00,151.70,-0.530
33.02,151.52,-0.530
33.03,151.33,-0.530
33.05,151.15,-0.530
33.07,150.97,-0.530
33.09,150.78,-0.530
33.11,150.60,-0.530
33.13,150.42,-0.530
33.14,150.23,-0.530
33.16,150.05,-0.530
33.18,149.87,-0.529
33.20,149.69,-0.529
33.22,149.50,-0.529
33.24,149.32,-0.529
33.26,149.13,-0.529
33.27,148.95,-0.529
33.29,148.77,-0.529
33.31,148.59,-0.529
33.33,148.40,-0.528
33.35,148.22,-0.528
33.37,148.04,-0.528
33.38,147.85,-0.528
33.40,147.67,-0.528
33.42,147.49,-0.528
33.44,147.30,-0.528
33.46,147.12,-0.528
33.48,146.94,-0.528
33.49,146.75,-0.527
33.51,146.57,-0.527
33.53,146.39,-0.527
33.55,146.20,-0.527
33.57,146.02,-0.527
33.58,145.84,-0.527
33.60,145.66,-0.527
33.62,145.47,-0.527
33.64,145.29,-0.527
33.66,145.11,-0.527
33.68,144.92,-0.526
33.69,144.74,-0.526
33.71,144.56,-0.526
33.73,144.37,-0.526
33.75,144.19,-0.526
33.77,144.01,-0.526
33.79,143.82,-0.526
33.81,143.64,-0.526
33.82,143.46,-0.526
33.84,143.27,-0.526
33.86,143.09,-0.525
33.88,142.91,-0.525
33.90,142.72,-0.525
33.92,142.54,-0.525
33.93,142.36,-0.525
33.95,142.18,-0.525
33.97,141.99,-0.525
33.99,141.81,-0.525
34.01,141.63,-0.525
34.03,141.44,-0.524
34.04,141.26,-0.524
34.06,141.08,-0.524
34.08,140.89,-0.524
34.10,140.71,-0.524
34.12,140.53,-0.524
34.14,140.34,-0.524
34.15,140.16,-0.524
34.17,139.98,-0.524
34.19,139.79,-0.524
34.21,139.61,-0.523
34.23,139.43,-0.523
34.24,139.24,-0.523
34.26,139.06,-0.523
34.28,138.88,-0.523
34.30,138.69,-0.523
34.32,138.51,-0.523
34.34,138.33,-0.523
34.36,138.14,-0.523
34.37,137.96,-0.522
34.39,137.78,-0.522
34.41,137.59,-0.522
34.43,137.41,-0.522
34.45,137.23,-0.522
34.46,137.05,-0.522
34.48,136.86,-0.521
34.50,136.68,-0.521
34.52,136.50,-0.521
34.54,136.32,-0.521
34.56,136.13,-0.521
34.58,135.95,-0.521
34.59,135.76,-0.521
34.61,135.58,-0.521
34.63,135.40,-0.520
34.65,135.22,-0.520
34.67,135.03,-0.520
34.69,134.85,-0.520
34.70,134.67,-0.520
34.72,134.48,-0.520
34.74,134.30,-0.520
34.76,134.12,-0.520
34.78,133.93,-0.520
34.79,133.75,-0.520
34.81,133.57,-0.520
34.83,133.39,-0.520
34.85,133.20,-0.519
34.87,133.02,-0.519
34.89,132.83,-0.519
34.91,132.65,-0.519
34.92,132.47,-0.519
34.94,132.29,-0.519
34.96,132.10,-0.519
34.98,131.92,-0.519
35.00,131.74,-0.519
35.01,131.55,-0.519
35.03,131.37,-0.519
35.05,131.19,-0.518
35.07,131.00,-0.518
35.09,130.82,-0.518
35.11,130.64,-0.518
35.13,130.45,-0.518
35.14,130.27,-0.518
35.16,130.09,-0.518
35.18,129.91,-0.518
35.20,129.72,-0.518
35.22,129.54,-0.517
35.24,129.36,-0.517
35.25,129.17,-0.517
35.27,128.99,-0.517
[...]
114.08,-40.89,0.238
114.08,-40.83,0.238
114.09,-40.76,0.238
114.10,-40.70,0.238
114.10,-40.63,0.238
114.11,-40.56,0.238
114.12,-40.50,0.238
114.12,-40.43,0.238
114.13,-40.36,0.238
114.14,-40.30,0.238
114.14,-40.23,0.238
114.15,-40.16,0.238
114.16,-40.09,0.238
114.16,-40.03,0.238
114.17,-39.96,0.238
114.18,-39.89,0.238
114.18,-39.83,0.238
114.19,-39.76,0.238
114.20,-39.69,0.238
114.20,-39.63,0.238
114.21,-39.56,0.238
114.22,-39.49,0.239
114.22,-39.43,0.239
114.23,-39.36,0.239
114.24,-39.29,0.239
114.24,-39.23,0.239
114.25,-39.16,0.239
114.26,-39.09,0.239
114.26,-39.03,0.239
114.27,-38.96,0.239
114.28,-38.89,0.239
114.28,-38.83,0.239
114.29,-38.76,0.239
114.30,-38.69,0.239
114.30,-38.63,0.239
114.31,-38.56,0.239
114.32,-38.49,0.239
114.32,-38.43,0.239
114.33,-38.36,0.239
114.34,-38.29,0.239
114.34,-38.23,0.239
114.35,-38.16,0.239
114.36,-38.09,0.239
114.36,-38.03,0.239
114.37,-37.96,0.239
114.38,-37.89,0.239
114.38,-37.83,0.239
114.39,-37.76,0.239
114.40,-37.69,0.240
114.40,-37.63,0.240
114.41,-37.56,0.240
114.42,-37.49,0.240
114.42,-37.43,0.240
114.43,-37.36,0.240
114.44,-37.29,0.240
114.44,-37.23,0.240
114.45,-37.16,0.240
114.46,-37.09,0.240
114.46,-37.02,0.240
114.47,-36.96,0.240
114.48,-36.89,0.240
114.48,-36.82,0.240
114.49,-36.76,0.240
114.50,-36.69,0.240
114.50,-36.62,0.240
114.51,-36.56,0.240
114.52,-36.49,0.240
114.52,-36.42,0.240
114.53,-36.36,0.240
114.54,-36.29,0.240
114.54,-36.22,0.240
114.55,-36.16,0.240
114.56,-36.09,0.241
114.56,-36.02,0.241
114.57,-35.96,0.241
114.58,-35.89,0.241
114.58,-35.82,0.241
114.59,-35.76,0.241
114.60,-35.69,0.241
114.60,-35.62,0.241
114.61,-35.56,0.241
114.62,-35.49,0.241
114.62,-35.42,0.241
114.63,-35.36,0.241
114.64,-35.29,0.241
114.64,-35.22,0.241
114.65,-35.15,0.241
114.66,-35.09,0.241
114.66,-35.02,0.241
114.67,-34.96,0.241
114.68,-34.89,0.241
114.68,-34.82,0.241
114.69,-34.76,0.241
114.70,-34.69,0.241
114.70,-34.62,0.241
114.71,-34.55,0.241
114.72,-34.49,0.242
114.72,-34.42,0.242
114.73,-34.35,0.242
114.74,-34.29,0.242
114.74,-34.22,0.242
114.75,-34.15,0.242
114.76,-34.09,0.242
114.76,-34.02,0.242
114.77,-33.95,0.242
114.78,-33.89,0.242
114.78,-33.82,0.242
114.79,-33.75,0.242
114.80,-33.69,0.242
114.80,-33.62,0.242
114.81,-33.55,0.242
114.82,-33.49,0.242
114.82,-33.42,0.242
114.83,-33.35,0.242
114.84,-33.29,0.242
114.84,-33.22,0.242
114.85,-33.15,0.242
114.86,-33.09,0.242
114.86,-33.02,0.242
114.87,-32.95,0.242
114.88,-32.89,0.242
114.88,-32.82,0.242
114.89,-32.75,0.243
114.90,-32.69,0.243
114.90,-32.62,0.243
114.91,-32.55,0.243
114.92,-32.49,0.243
114.92,-32.42,0.243
114.93,-32.35,0.243
114.94,-32.28,0.243
114.94,-32.22,0.243
114.95,-32.15,0.243
114.96,-32.08,0.243
114.96,-32.02,0.243
114.97,-31.95,0.243
114.98,-31.88,0.243
114.98,-31.82,0.243
114.99,-31.75,0.243
115.00,-31.68,0.243
115.00,-31.62,0.243
115.01,-31.55,0.243
115.02,-31.48,0.243
115.02,-31.42,0.243
115.03,-31.35,0.243
115.04,-31.28,0.243
115.04,-31.22,0.243
115.05,-31.15,0.243
115.06,-31.08,0.244
115.06,-31.02,0.244
115.07,-30.95,0.244
115.08,-30.88,0.244
115.08,-30.82,0.244
115.09,-30.75,0.244
115.10,-30.68,0.244
115.10,-30.62,0.244
115.11,-30.55,0.244
115.12,-30.48,0.244
115.12,-30.42,0.244
115.13,-30.35,0.244
115.14,-30.28,0.244
115.14,-30.22,0.244
115.15,-30.15,0.244
115.16,-30.08,0.244
115.16,-30.02,0.244
115.17,-29.95,0.244
115.18,-29.88,0.244
115.18,-29.82,0.244
115.19,-29.75,0.244
115.20,-29.68,0.244
115.20,-29.62,0.244
115.21,-29.55,0.244
115.22,-29.48,0.244
115.22,-29.42,0.245
115.23,-29.35,0.245
115.24,-29.28,0.245
115.24,-29.21,0.245
115.25,-29.15,0.245
115.26,-29.08,0.245
115.26,-29.01,0.245
115.27,-28.95,0.245
115.28,-28.88,0.245
115.28,-28.81,0.245
115.29,-28.75,0.245
115.30,-28.68,0.245
115.30,-28.61,0.245
115.31,-28.55,0.245
115.32,-28.48,0.245
115.32,-28.41,0.245
115.33,-28.35,0.245
115.34,-28.28,0.245
115.34,-28.21,0.245
115.35,-28.15,0.245
115.36,-28.08,0.245
115.36,-28.01,0.245
115.37,-27.95,0.245
115.38,-27.88,0.245
115.38,-27.81,0.245
115.39,-27.75,0.245
115.40,-27.68,0.245
115.40,-27.61,0.245
115.41,-27.55,0.246
115.42,-27.48,0.246
115.42,-27.41,0.246
115.43,-27.34,0.246
115.44,-27.28,0.246
115.44,-27.21,0.246
115.45,-27.14,0.246
115.46,-27.08,0.246
115.46,-27.01,0.246
115.47,-26.94,0.246
115.48,-26.88,0.246
115.48,-26.81,0.246
115.49,-26.75,0.246
115.50,-26.68,0.246
115.50,-26.61,0.246
115.51,-26.54,0.246
115.52,-26.48,0.246
115.52,-26.41,0.246
115.53,-26.34,0.246
115.54,-26.28,0.246
115.54,-26.21,0.246
115.55,-26.14,0.246
115.56,-26.08,0.247
115.56,-26.01,0.247
115.57,-25.94,0.247
115.58,-25.88,0.247
115.58,-25.81,0.247
115.59,-25.74,0.247
115.60,-25.67,0.247
115.60,-25.61,0.247
115.61,-25.54,0.247
115.62,-25.47,0.247
115.62,-25.41,0.247
115.63,-25.34,0.247
115.64,-25.27,0.247
115.64,-25.21,0.247
115.65,-25.14,0.247
115.66,-25.07,0.247
115.66,-25.01,0.247
115.67,-24.94,0.247
115.68,-24.87,0.247
115.68,-24.81,0.247
115.69,-24.74,0.247
115.70,-24.67,0.247
115.70,-24.61,0.247
115.71,-24.54,0.247
115.72,-24.47,0.248
115.72,-24.41,0.248
115.73,-24.34,0.248
115.74,-24.27,0.248
115.74,-24.21,0.248
115.75,-24.14,0.248
115.76,-24.07,0.248
115.76,-24.01,0.248
115.77,-23.94,0.248
115.78,-23.87,0.248
115.78,-23.81,0.248
115.79,-23.74,0.248
115.80,-23.67,0.248
115.80,-23.60,0.248
115.81,-23.54,0.248
115.82,-23.47,0.248
115.82,-23.40,0.248
115.83,-23.34,0.248
115.84,-23.27,0.248
115.84,-23.20,0.248
115.85,-23.14,0.248
115.86,-23.07,0.248
115.86,-23.00,0.248
115.87,-22.94,0.248
115.88,-22.87,0.248
115.88,-22.80,0.249
115.89,-22.74,0.249
115.90,-22.67,0.249
115.90,-22.60,0.249
115.91,-22.54,0.249
115.92,-22.47,0.249
115.92,-22.40,0.249
115.93,-22.34,0.249
115.94,-22.27,0.249
115.94,-22.20,0.249
115.95,-22.14,0.249
115.96,-22.07,0.249
115.96,-22.00,0.249
115.97,-21.94,0.249
115.98,-21.87,0.249
115.98,-21.80,0.249
115.99,-21.74,0.249
116.00,-21.67,0.249
116.00,-21.60,0.249
116.01,-21.53,0.249
116.02,-21.47,0.249
116.02,-21.40,0.249
116.03,-21.34,0.250
116.04,-21.27,0.250
116.04,-21.20,0.250
116.05,-21.13,0.250
116.06,-21.07,0.250
116.06,-21.00,0.250
116.07,-20.93,0.250
116.08,-20.87,0.250
116.08,-20.80,0.250
116.09,-20.73,0.250
116.10,-20.67,0.250
116.10,-20.60,0.250
116.11,-20.53,0.250
116.12,-20.47,0.250
116.12,-20.40,0.250
116.13,-20.33,0.250
116.14,-20.27,0.250
116.14,-20.20,0.250
116.15,-20.13,0.250
116.16,-20.07,0.250
116.16,-20.00,0.250
116.17,-19.93,0.250
116.18,-19.87,0.250
116.18,-19.80,0.251
116.19,-19.73,0.251
116.20,-19.67,0.251
116.20,-19.60,0.251
116.21,-19.53,0.251
116.22,-19.47,0.251
116.22,-19.40,0.251
116.23,-19.33,0.251
116.24,-19.27,0.251
116.24,-19.20,0.251
116.25,-19.13,0.251
116.26,-19.07,0.251
116.26,-19.00,0.251
116.27,-18.93,0.251
116.28,-18.87,0.251
116.28,-18.80,0.251
116.29,-18.73,0.251
116.30,-18.67,0.251
116.30,-18.60,0.251
116.31,-18.53,0.251
116.32,-18.47,0.251
116.32,-18.40,0.251
116.33,-18.33,0.251
116.34,-18.27,0.251
116.34,-18.20,0.251
116.35,-18.13,0.252
116.36,-18.06,0.252
116.36,-18.00,0.252
116.37,-17.93,0.252
116.38,-17.86,0.252
116.38,-17.80,0.252
116.39,-17.73,0.252
116.40,-17.67,0.252
116.40,-17.60,0.252
116.41,-17.53,0.252
116.42,-17.47,0.252
116.42,-17.40,0.252
116.43,-17.33,0.252
116.44,-17.26,0.252
116.44,-17.20,0.252
116.45,-17.13,0.252
116.46,-17.06,0.252
116.46,-17.00,0.252
116.47,-16.93,0.252
116.48,-16.86,0.252
116.48,-16.80,0.252
116.49,-16.73,0.252
116.50,-16.66,0.253
116.50,-16.60,0.253
116.51,-16.53,0.253
116.52,-16.46,0.253
116.52,-16.40,0.253
116.53,-16.33,0.253
116.54,-16.26,0.253
116.54,-16.20,0.253
116.55,-16.13,0.253
116.56,-16.06,0.253
116.56,-16.00,0.253
116.57,-15.93,0.253
116.58,-15.86,0.253
116.58,-15.79,0.253
116.59,-15.73,0.253
116.60,-15.66,0.253
116.60,-15.60,0.253
116.61,-15.53,0.253
116.62,-15.46,0.253
116.62,-15.40,0.253
116.63,-15.33,0.253
116.64,-15.26,0.254
116.64,-15.19,0.254
116.65,-15.13,0.254
116.66,-15.06,0.254
116.66,-14.99,0.254
116.67,-14.93,0.254
116.68,-14.86,0.254
116.68,-14.79,0.254
116.69,-14.73,0.254
116.70,-14.66,0.254
116.70,-14.59,0.254
116.71,-14.53,0.254
116.72,-14.46,0.254
116.72,-14.39,0.254
116.73,-14.33,0.254
116.74,-14.26,0.254
116.74,-14.19,0.254
116.75,-14.13,0.254
116.76,-14.06,0.254
116.76,-13.99,0.254
116.77,-13.93,0.255
116.78,-13.86,0.255
116.78,-13.79,0.255
116.79,-13.73,0.255
116.80,-13.66,0.255
116.80,-13.59,0.255
116.81,-13.52,0.255
116.82,-13.46,0.255
116.82,-13.39,0.255
116.83,-13.33,0.255
116.84,-13.26,0.255
116.84,-13.19,0.255
116.85,-13.13,0.255
116.86,-13.06,0.255
116.86,-12.99,0.255
116.87,-12.92,0.255
116.88,-12.86,0.255
116.88,-12.79,0.255
116.89,-12.72,0.255
116.90,-12.66,0.255
116.90,-12.59,0.255
116.91,-12.52,0.256
116.92,-12.46,0.256
116.92,-12.39,0.256
116.93,-12.32,0.256
116.94,-12.26,0.256
116.94,-12.19,0.256
116.95,-12.12,0.256
116.96,-12.06,0.256
116.96,-11.99,0.256
116.97,-11.92,0.256
116.98,-11.86,0.256
116.98,-11.79,0.256
116.99,-11.72,0.256
117.00,-11.66,0.256
117.00,-11.59,0.256
117.01,-11.52,0.256
117.02,-11.46,0.256
117.02,-11.39,0.256
117.03,-11.32,0.256
117.04,-11.26,0.256
117.04,-11.19,0.256
117.05,-11.12,0.257
117.06,-11.06,0.257
117.06,-10.99,0.257
117.07,-10.92,0.257
117.08,-10.86,0.257
117.08,-10.79,0.257
117.09,-10.72,0.257
117.10,-10.66,0.257
117.10,-10.59,0.257
117.11,-10.52,0.257
117.12,-10.46,0.257
117.12,-10.39,0.257
117.13,-10.32,0.257
117.14,-10.26,0.257
117.14,-10.19,0.257
117.15,-10.12,0.257
117.16,-10.06,0.257
117.16,-9.99,0.258
117.17,-9.92,0.258
117.18,-9.86,0.258
117.18,-9.79,0.258
117.19,-9.72,0.258
117.20,-9.66,0.258
117.20,-9.59,0.258
117.21,-9.52,0.258
117.22,-9.46,0.258
117.22,-9.39,0.258
117.23,-9.32,0.258
117.24,-9.25,0.258
117.24,-9.19,0.258
117.25,-9.12,0.258
117.26,-9.05,0.258
117.26,-8.99,0.258
117.27,-8.92,0.258
117.28,-8.85,0.258
117.28,-8.79,0.259
117.29,-8.72,0.259
117.30,-8.65,0.259
117.30,-8.59,0.259
117.31,-8.52,0.259
117.32,-8.45,0.259
117.32,-8.39,0.259
117.33,-8.32,0.259
117.34,-8.25,0.259
117.34,-8.19,0.259
117.35,-8.12,0.259
117.36,-8.05,0.259
117.36,-7.99,0.259
117.37,-7.92,0.259
117.38,-7.85,0.259
117.38,-7.79,0.259
117.39,-7.72,0.260
117.40,-7.65,0.260
117.40,-7.59,0.260
117.41,-7.52,0.260
117.42,-7.45,0.260
117.42,-7.39,0.260
117.43,-7.32,0.260
117.44,-7.25,0.260
117.44,-7.19,0.260
117.45,-7.12,0.260
117.46,-7.05,0.260
117.46,-6.99,0.260
117.47,-6.92,0.261
117.48,-6.85,0.261
117.48,-6.79,0.261
117.49,-6.72,0.261
117.50,-6.65,0.261
117.50,-6.59,0.261
117.51,-6.52,0.261
117.52,-6.45,0.261
117.52,-6.39,0.261
117.53,-6.32,0.261
117.54,-6.25,0.261
117.54,-6.19,0.261
117.55,-6.12,0.262
117.56,-6.05,0.262
117.56,-5.99,0.262
117.57,-5.92,0.262
117.58,-5.85,0.262
117.58,-5.79,0.262
117.59,-5.72,0.262
117.60,-5.65,0.262
117.60,-5.58,0.262
117.61,-5.52,0.262
117.62,-5.45,0.262
117.62,-5.38,0.263
117.63,-5.32,0.263
117.64,-5.25,0.263
117.64,-5.18,0.263
117.65,-5.12,0.263
117.66,-5.05,0.263
117.66,-4.99,0.263
117.67,-4.92,0.263
117.68,-4.85,0.263
117.68,-4.78,0.264
117.69,-4.72,0.264
117.70,-4.65,0.264
117.70,-4.58,0.264
117.71,-4.52,0.264
117.72,-4.45,0.264
117.72,-4.38,0.264
117.73,-4.32,0.264
117.74,-4.25,0.264
117.74,-4.18,0.264
117.75,-4.12,0.265
117.76,-4.05,0.265
117.76,-3.98,0.265
117.77,-3.92,0.265
117.78,-3.85,0.265
117.78,-3.78,0.265
117.79,-3.72,0.265
117.80,-3.65,0.265
117.80,-3.58,0.265
117.81,-3.52,0.265
117.82,-3.45,0.266
117.82,-3.38,0.266
117.83,-3.32,0.266
117.84,-3.25,0.266
117.84,-3.18,0.266
117.85,-3.11,0.266
117.86,-3.05,0.266
117.86,-2.98,0.266
117.87,-2.91,0.266
117.88,-2.85,0.267
117.88,-2.78,0.267
117.89,-2.71,0.267
117.90,-2.65,0.267
117.90,-2.58,0.267
117.91,-2.51,0.267
117.92,-2.45,0.267
117.92,-2.38,0.267
117.93,-2.31,0.268
117.94,-2.25,0.268
117.94,-2.18,0.268
117.95,-2.11,0.268
117.96,-2.05,0.268
117.96,-1.98,0.268
117.97,-1.91,0.268
117.98,-1.85,0.268
117.98,-1.78,0.269
117.99,-1.71,0.269
118.00,-1.65,0.269
118.00,-1.58,0.269
118.01,-1.51,0.269
118.02,-1.45,0.269
118.02,-1.38,0.269
118.03,-1.31,0.270
118.04,-1.25,0.270
118.04,-1.18,0.270
118.05,-1.11,0.270
118.06,-1.05,0.271
118.06,-0.98,0.271
118.07,-0.91,0.271
118.08,-0.85,0.271
118.08,-0.78,0.271
118.09,-0.71,0.271
118.10,-0.65,0.272
118.10,-0.58,0.272
118.11,-0.51,0.272
118.12,-0.45,0.272
118.12,-0.38,0.272
118.13,-0.31,0.272
118.14,-0.25,0.273
118.14,-0.18,0.273
118.15,-0.11,0.273
118.16,-0.05,0.273
118.16,0.02,0.273
118.17,0.09,0.273
118.18,0.15,0.274
118.18,0.22,0.274
118.19,0.29,0.275
118.20,0.35,0.275
118.20,0.42,0.275
118.21,0.49,0.275
118.22,0.55,0.276
118.22,0.62,0.276
118.23,0.69,0.276
118.24,0.75,0.276
118.24,0.82,0.276
118.25,0.89,0.277
118.26,0.95,0.277
118.26,1.02,0.278
118.27,1.09,0.278
118.28,1.15,0.278
118.28,1.22,0.278
118.29,1.29,0.278
118.30,1.35,0.279
118.30,1.42,0.280
118.31,1.49,0.280
118.32,1.55,0.280
118.32,1.62,0.281
118.33,1.69,0.282
118.34,1.75,0.282
118.34,1.82,0.282
118.35,1.89,0.283
118.36,1.95,0.283
118.36,2.02,0.283
118.37,2.09,0.283
118.38,2.15,0.284
118.38,2.22,0.284
118.39,2.29,0.284
118.40,2.35,0.285
118.40,2.42,0.285
118.41,2.49,0.285
118.42,2.55,0.286
118.42,2.62,0.286
118.43,2.69,0.286
118.44,2.75,0.288
118.44,2.82,0.288
118.45,2.89,0.288
118.46,2.95,0.289
118.46,3.02,0.289
118.47,3.08,0.289
118.48,3.15,0.290
118.48,3.22,0.290
118.49,3.29,0.291
118.50,3.35,0.291
118.50,3.42,0.293
118.51,3.49,0.293
118.52,3.55,0.294
118.52,3.62,0.294
118.53,3.69,0.294
118.54,3.75,0.295
118.54,3.82,0.296
118.55,3.89,0.297
118.56,3.95,0.297
118.56,4.02,0.298
118.57,4.09,0.298
118.58,4.15,0.299
118.58,4.22,0.299
118.59,4.28,0.301
118.60,4.35,0.301
118.60,4.42,0.302
118.61,4.49,0.302
118.62,4.55,0.303
118.62,4.62,0.303
118.63,4.68,0.304
118.64,4.75,0.304
118.64,4.82,0.306
118.65,4.88,0.307
118.66,4.95,0.307
118.66,5.02,0.308
118.67,5.08,0.308
118.68,5.15,0.309
118.68,5.22,0.310
118.69,5.28,0.311
118.70,5.35,0.312
118.70,5.42,0.313
118.71,5.48,0.313
118.72,5.55,0.314
118.72,5.62,0.315
118.73,5.68,0.316
118.74,5.75,0.317
118.74,5.82,0.317
118.75,5.88,0.318
118.76,5.95,0.318
118.76,6.02,0.320
118.77,6.08,0.321
118.78,6.15,0.321
118.78,6.22,0.322
118.79,6.28,0.323
118.80,6.35,0.324
118.80,6.41,0.325
118.81,6.48,0.326
118.82,6.55,0.326
118.82,6.61,0.327
118.83,6.68,0.328
118.84,6.75,0.329
118.84,6.81,0.331
118.85,6.88,0.332
118.86,6.95,0.332
118.86,7.01,0.333
118.87,7.08,0.334
118.88,7.15,0.335
118.88,7.21,0.336
118.89,7.28,0.336
118.90,7.34,0.337
118.90,7.41,0.338
118.91,7.48,0.340
118.92,7.54,0.341
118.92,7.61,0.342
118.93,7.68,0.343
118.94,7.74,0.343
118.94,7.81,0.345
118.95,7.88,0.346
118.96,7.94,0.347
118.96,8.01,0.348
118.97,8.08,0.349
118.98,8.14,0.350
118.98,8.21,0.351
118.99,8.27,0.351
119.00,8.34,0.353
119.00,8.41,0.354
119.01,8.47,0.354
119.02,8.54,0.355
119.02,8.61,0.356
119.03,8.67,0.357
119.04,8.74,0.359
119.04,8.81,0.360
119.05,8.87,0.361
119.06,8.94,0.361
119.06,9.01,0.362
119.07,9.07,0.363
119.08,9.14,0.364
119.08,9.20,0.365
119.09,9.27,0.366
119.10,9.34,0.367
119.10,9.40,0.367
119.11,9.47,0.368
119.12,9.54,0.369
119.12,9.60,0.370
119.13,9.67,0.371
119.14,9.74,0.371
119.14,9.80,0.372
119.15,9.87,0.373
119.16,9.94,0.373
119.16,10.00,0.374
119.17,10.07,0.375
119.18,10.14,0.375
119.18,10.20,0.376
119.19,10.27,0.376
119.20,10.34,0.377
119.20,10.40,0.378
119.21,10.47,0.378
119.22,10.53,0.378
119.22,10.60,0.379
119.23,10.67,0.379
119.24,10.73,0.379
119.24,10.80,0.380
119.25,10.87,0.380
119.26,10.93,0.381
119.26,11.00,0.381
119.27,11.07,0.381
119.28,11.13,0.381
119.28,11.20,0.382
119.29,11.27,0.382
119.30,11.33,0.382
119.30,11.40,0.382
119.31,11.47,0.382
119.32,11.53,0.382
119.32,11.60,0.382
119.33,11.67,0.382
119.34,11.74,0.382
119.34,11.80,0.382
119.35,11.87,0.382
119.36,11.93,0.383
119.36,12.00,0.383
119.37,12.07,0.383
119.38,12.13,0.383
119.38,12.20,0.383
119.39,12.27,0.383
119.40,12.34,0.383
119.40,12.40,0.383
119.41,12.47,0.383
119.42,12.54,0.383
119.42,12.60,0.383
119.43,12.67,0.383
119.44,12.74,0.382
119.44,12.80,0.382
119.45,12.87,0.382
119.46,12.94,0.382
119.46,13.00,0.382
119.47,13.07,0.382
119.48,13.14,0.382
119.48,13.20,0.382
119.49,13.27,0.381
119.50,13.34,0.381
119.50,13.40,0.381
119.51,13.47,0.381
119.52,13.54,0.381
119.52,13.61,0.380
119.53,13.67,0.380
119.54,13.74,0.380
119.54,13.81,0.380
119.55,13.87,0.379
119.56,13.94,0.379
119.56,14.01,0.379
119.57,14.07,0.379
119.58,14.14,0.379
119.58,14.21,0.378
119.59,14.27,0.378
119.60,14.34,0.378
119.60,14.41,0.378
119.61,14.47,0.377
119.62,14.54,0.377
119.62,14.61,0.377
119.63,14.68,0.377
119.64,14.74,0.377
119.64,14.81,0.376
119.65,14.87,0.376
119.66,14.94,0.376
119.66,15.01,0.376
119.67,15.08,0.375
119.68,15.14,0.375
119.68,15.21,0.375
119.69,15.28,0.375
119.70,15.34,0.375
119.70,15.41,0.375
119.71,15.48,0.374
119.72,15.54,0.374
119.72,15.61,0.374
119.73,15.68,0.374
119.74,15.74,0.374
119.74,15.81,0.374
119.75,15.88,0.374
119.76,15.94,0.373
119.76,16.01,0.373
119.77,16.08,0.373
119.78,16.15,0.373
119.78,16.21,0.373
119.79,16.28,0.373
119.80,16.35,0.373
119.80,16.41,0.372
119.81,16.48,0.372
119.82,16.55,0.372
119.82,16.61,0.372
119.83,16.68,0.372
119.84,16.75,0.372
119.84,16.81,0.372
119.85,16.88,0.371
119.86,16.95,0.371
119.86,17.01,0.371
119.87,17.08,0.371
119.88,17.15,0.371
119.88,17.21,0.371
119.89,17.28,0.371
119.90,17.35,0.371
119.90,17.41,0.371
119.91,17.48,0.371
119.92,17.55,0.370
119.92,17.62,0.370
119.93,17.68,0.370
119.94,17.75,0.370
119.94,17.81,0.370
119.95,17.88,0.370
119.96,17.95,0.370
119.96,18.02,0.370
119.97,18.08,0.370
119.98,18.15,0.370
119.98,18.22,0.370
119.99,18.28,0.370
120.00,18.35,0.370
120.00,18.42,0.369
120.01,18.48,0.369
120.02,18.55,0.369
120.02,18.62,0.369
120.03,18.68,0.369
120.04,18.75,0.369
120.04,18.82,0.369
120.05,18.88,0.369
120.06,18.95,0.369
120.06,19.02,0.369
120.07,19.08,0.369
120.08,19.15,0.369
120.08,19.22,0.369
120.09,19.28,0.369
120.10,19.35,0.369
120.10,19.42,0.369
120.11,19.48,0.369
120.12,19.55,0.369
120.12,19.62,0.369
120.13,19.68,0.369
120.14,19.75,0.369
120.14,19.82,0.369
120.15,19.88,0.369
120.16,19.95,0.369
120.16,20.02,0.369
120.17,20.09,0.369
120.18,20.15,0.369
120.18,20.22,0.368
120.19,20.29,0.368
120.20,20.35,0.368
120.20,20.42,0.368
120.21,20.49,0.368
120.22,20.55,0.368
120.22,20.62,0.368
120.23,20.69,0.368
120.24,20.75,0.368
120.24,20.82,0.368
120.25,20.89,0.368
120.26,20.95,0.368
120.26,21.02,0.368
120.27,21.09,0.368
120.28,21.15,0.368
120.28,21.22,0.368
120.29,21.29,0.368
120.30,21.35,0.368
120.30,21.42,0.368
120.31,21.49,0.368
120.32,21.55,0.368
120.32,21.62,0.368
120.33,21.69,0.368
120.34,21.75,0.369
120.34,21.82,0.369
120.35,21.89,0.369
120.36,21.95,0.369
120.36,22.02,0.369
120.37,22.09,0.369
120.38,22.15,0.369
120.38,22.22,0.369
120.39,22.29,0.369
120.40,22.35,0.369
120.40,22.42,0.369
120.41,22.49,0.369
120.42,22.55,0.369
120.42,22.62,0.369
120.43,22.69,0.369
120.44,22.75,0.369
120.44,22.82,0.369
120.45,22.89,0.369
120.46,22.95,0.369
120.46,23.02,0.369
120.47,23.09,0.369
120.48,23.15,0.369
120.48,23.22,0.369
120.49,23.29,0.369
120.50,23.35,0.369
120.50,23.42,0.369
120.51,23.49,0.369
120.52,23.55,0.369
120.52,23.62,0.370
120.53,23.69,0.370
120.54,23.76,0.370
120.54,23.82,0.370
120.55,23.89,0.370
120.56,23.95,0.370
120.56,24.02,0.370
120.57,24.09,0.370
120.58,24.16,0.370
120.58,24.22,0.370
120.59,24.29,0.370
120.60,24.36,0.370
120.60,24.42,0.370
120.61,24.49,0.370
120.62,24.56,0.370
120.62,24.62,0.370
120.63,24.69,0.370
120.64,24.76,0.370
120.64,24.82,0.370
120.65,24.89,0.370
120.66,24.95,0.370
120.66,25.02,0.370
120.67,25.09,0.370
120.68,25.16,0.370
120.68,25.22,0.370
120.69,25.29,0.371
120.70,25.36,0.371
120.70,25.42,0.371
120.71,25.49,0.371
120.72,25.56,0.371
120.72,25.62,0.371
120.73,25.69,0.371
120.74,25.76,0.371
120.74,25.82,0.371
120.75,25.89,0.371
120.76,25.96,0.371
120.76,26.02,0.371
120.77,26.09,0.371
120.78,26.16,0.371
120.78,26.22,0.371
120.79,26.29,0.371
120.80,26.36,0.371
120.80,26.42,0.371
120.81,26.49,0.371
120.82,26.56,0.371
120.82,26.62,0.371
120.83,26.69,0.371
120.84,26.76,0.372
120.84,26.82,0.372
120.85,26.89,0.372
120.86,26.96,0.372
120.86,27.02,0.372
120.87,27.09,0.372
120.88,27.16,0.372
120.88,27.22,0.372
120.89,27.29,0.372
120.90,27.36,0.372
120.90,27.43,0.372
120.91,27.49,0.372
120.92,27.56,0.372
120.92,27.62,0.372
120.93,27.69,0.372
120.94,27.76,0.372
120.94,27.82,
120.95,27.89,
120.96,27.96,
120.96,28.02,
120.97,28.09,
120.98,28.16,
120.98,28.22,
120.99,,
121.00,,