File: DSC/2025_02_13_CBD_Rerun_2023_DSC3.txt
Filename	2025_02_13_CBD_Rerun_2023_DSC3
Instrument name	DSC2A-00468 (192.168.1.100)
Operator	JLY
rundate	2/14/2025
Sample name	2025_02_13_CBD_Rerun_2023_DSC3
proceduresegments	Data Off ; Equilibrate -40.00 °C; Data On ; Ramp 5.00 °C/min to 100.00 °C; Data Off ; Isothermal 1.0 min; Data On ; Ramp 5.00 °C/min to -40.00 °C; Data Off ; Isothermal 1.0 min; Data On ; Ramp 5.00 °C/min to 100.00 °C; Data Off ; Isothermal 1.0 min; Data On ; Ramp 5.00 °C/min to -40.00 °C; Data Off ; Isothermal 1.0 min; Data On ; Ramp 5.00 °C/min to 100.00 °C
[File Parameters]
Run date	2/14/2025 8:02:41 AM
Trios version	5.1.1.46572
Original File Name
Current File Name	D:\DSC2500\CHM343\2025_02_13_CBD_Rerun_2023_DSC3.tri
[Procedure]
Procedure Name	CBD Re-Test
Sample Name	2025_02_13_CBD_Rerun_2023_DSC3
Sample Mass	5.7 mg
Reference Sample Mass	0 mg
Pan Mass	53.62 mg
Pan Number	3
Reference Pan Mass	54 mg
Reference Pan Number	19
Pan Type	Tzero Aluminum Hermetic
Comments	Al Hermetic Sealed Pan, with ref Al pan.  7/11/23 SBK CBD Sample.  Sitting in DSC Tray.
Project Name
Operator	JLY
Test	Custom
Unload Max Temperature	30
Unload Min Temperature	30
Load Max Temperature	30
Load Min Temperature	30
Stop on Gas Flow Error	Yes
[Signal List]
Signal #1	Time (min)
Signal #2	Temperature (°C)
Signal #3	Heat Flow (mW)
Signal #4	Delta T (µV)
Signal #5	Delta Tzero (µV)
Signal #6	Tzero Temperature (°C)
Signal #7	Cell Purge (mL/min)
Signal #8	Heater Temp (°C)
Signal #9	Power Delivered (W)
Signal #10	Reference Junction Temperature (°C)
Signal #11	Flange Temperature (°C)
Signal #12	Heat Flow Phase (rad)
Signal #13	Total Heat Capacity (J/°C)
Signal #14	Heat Capacity (J/°C)
[Configuration]
Company Name	ASU
Instrument Name	DSC2A-00468
Instrument Type	DSC2500
Serial Number	DSC2A-00468
IP	192.168.1.100
Location of Instrument	MRRC
DisplayType	Unknown
Sample Interval 	0.1 s/pt
Selected Heat Flow	T4P
Exotherm Direction	Down
Cell Serial	DRC2-00792
Lid Type	Standard
Cooler	RCS 90
Leave Cooler on at End of Sequence	On
Gas 2	Nitrogen
Gas Selected	Channel 1
Flow Rate	50 mL/min
Secondary Purge	On
Licensed Heat Flow	Heat Flow T4P
Modulation Licensed	Yes
[Versions]
Common IDD Version	1
Cortex Version	VER 2.10.2.31
Driver	5.0.0.6
GDM Version	1.0.3.3
TouchscreenVersion	1.0.0.16145
FEP Version	1.2.1.21
FEP Bootloader	2.0.0.5
AutoSampler Version	2.1.1.26
Auto Sampler Bootloader	2.0.0.5
FCM Version	1.1.0.3
FCM Bootloader	2.0.0.5
[Experiment Logs]
Experiment Log Entry # 2	Data On set to 0
Experiment Log Entry # 4	Equilibrate Segment -40 (C) Started
Experiment Log Entry # 6	Air Cool is off.
Experiment Log Entry # 8	Data On set to 1
Experiment Log Entry # 10	Ramp Segment 5 C/min to 100 Started
Experiment Log Entry # 12	Data On set to 0
Experiment Log Entry # 14	Isothermal Segment 1 min started
Experiment Log Entry # 16	Data On set to 1
Experiment Log Entry # 18	Ramp Segment 5 C/min to -40 Started
Experiment Log Entry # 20	Data On set to 0
Experiment Log Entry # 22	Isothermal Segment 1 min started
Experiment Log Entry # 24	Data On set to 1
Experiment Log Entry # 26	Ramp Segment 5 C/min to 100 Started
Experiment Log Entry # 28	Data On set to 0
Experiment Log Entry # 30	Isothermal Segment 1 min started
Experiment Log Entry # 32	Data On set to 1
Experiment Log Entry # 34	Ramp Segment 5 C/min to -40 Started
Experiment Log Entry # 36	Data On set to 0
Experiment Log Entry # 38	Isothermal Segment 1 min started
Experiment Log Entry # 40	Data On set to 1
Experiment Log Entry # 42	Ramp Segment 5 C/min to 100 Started
[Method Log]
Method Log Entry # 1	Data Off
Method Log Entry # 2	Equilibrate -40 °C
Method Log Entry # 3	Data On
Method Log Entry # 4	(Ramp 203397) Ramp 5 °C/minute to 100 °C
Method Log Entry # 5	Data Off
Method Log Entry # 6	Isothermal 1 minutes
Method Log Entry # 7	Data On
Method Log Entry # 8	(Ramp 203401) Ramp 5 °C/minute to -40 °C
Method Log Entry # 9	Data Off
Method Log Entry # 10	Isothermal 1 minutes
Method Log Entry # 11	Data On
Method Log Entry # 12	(Ramp 203405) Ramp 5 °C/minute to 100 °C
Method Log Entry # 13	Data Off
Method Log Entry # 14	Isothermal 1 minutes
Method Log Entry # 15	Data On
Method Log Entry # 16	(Ramp 203409) Ramp 5 °C/minute to -40 °C
Method Log Entry # 17	Data Off
Method Log Entry # 18	Isothermal 1 minutes
Method Log Entry # 19	Data On
Method Log Entry # 20	(Ramp 203413) Ramp 5 °C/minute to 100 °C
Cell Serial	DRC2-00792
[T1 Calibration]
Slope	-0.008529666
Offset	9.636258
Initial Temperature	98.23
GUID	f8bfdadc-4977-4fdf-ba6d-0ba9134940c3
[TZero Calibration]
Date Applied	11/29/2022 4:06:13 PM
Description	From -89.059 °C to 396.009 °C at 20.000°C/min
Gas Type	Nitrogen
Pan Type	None
Source Files 1	C:\Users\yargerlab\Desktop\DSC Data\General\TZero_calibration_11_29_22_2nd(2).tri
Source Files 2	C:\Users\yargerlab\Desktop\DSC Data\General\TZero_calibration_11_29_22_2nd(3).tri
Delta T Offset	13.05235
Delta T Slope	-0.007271007
Delta T0 Offset	-13.69128
Delta T0 Slope	0.06063341
[Temperature Calibration]
Date Applied	11/29/2022 7:12:28 PM
Description	From 106.590 °C to 186.590 °C at 10.000°C/min
Gas Type	Nitrogen
Pan Type	Tzero Aluminum Hermetic
Source Files 1	C:\Users\yargerlab\Desktop\DSC Data\General\Indium(6).tri
Measured 1	157.391
Known 1	156.598
[Cell Constant Calibration]
Date Applied	11/29/2022 7:12:29 PM
Description	From 106.590 °C to 186.590 °C at 10.000°C/min
Gas Type	Nitrogen
Pan Type	Tzero Aluminum Hermetic
Source Files 1	C:\Users\yargerlab\Desktop\DSC Data\General\Indium(6).tri
T4P KCell	1.006051
Onset Slope	63.26126 mW/°C
[Direct Cp Calibration]
Date Applied	11/30/2022 11:04:51 AM
Description	From -79.983 °C to 298.409 °C at 10.000°C/min
Gas Type	Nitrogen
Pan Type	Tzero Aluminum Hermetic
Source Files 1	C:\Users\yargerlab\Desktop\DSC Data\General\Sapphire_Heat_Capacity_11_30_22.tri
[Rev Cp Calibration]
Date Applied	11/30/2022 1:58:51 PM
Description	From -79.996 °C to 292.812 °C at 3.000°C/min
Gas Type	Nitrogen
Pan Type	Tzero Aluminum Hermetic
Source Files 1	C:\Users\yargerlab\Desktop\DSC Data\General\Sapphire_MDSC_Calibration_11_30_22.tri
[step]
Ramp 5.00 °C/min to 100.00 °C
Time	Temperature	Heat Flow (Normalized)
min	°C	W/g
0.00	-39.72	-0.052
0.02	-39.73	-0.054
0.04	-39.74	-0.047
0.06	-39.74	-0.042
0.08	-39.74	-0.039
0.10	-39.72	-0.038
0.12	-39.70	-0.038
0.14	-39.66	-0.037
0.16	-39.61	-0.032
0.18	-39.55	-0.022
0.20	-39.48	-0.012
0.22	-39.41	0.000
0.24	-39.34	0.011
0.26	-39.26	0.019
0.28	-39.17	0.028
0.30	-39.09	0.035
0.32	-39.00	0.042
0.34	-38.91	0.047
0.36	-38.82	0.050
0.38	-38.73	0.055
0.40	-38.64	0.056
0.42	-38.55	0.060
0.44	-38.46	0.062
0.46	-38.36	0.063
0.48	-38.27	0.065
0.50	-38.17	0.066
0.52	-38.08	0.067
0.54	-37.98	0.068
0.56	-37.89	0.068
0.58	-37.79	0.069
0.60	-37.70	0.069
0.62	-37.60	0.069
0.64	-37.50	0.070
0.66	-37.40	0.070
0.68	-37.31	0.071
0.70	-37.21	0.071
0.72	-37.11	0.071
0.74	-37.01	0.072
0.76	-36.92	0.072
0.78	-36.82	0.072
0.80	-36.72	0.073
0.82	-36.62	0.073
0.84	-36.52	0.073
0.86	-36.43	0.073
0.88	-36.33	0.073
0.90	-36.23	0.074
0.92	-36.13	0.074
0.94	-36.03	0.074
0.96	-35.93	0.074
0.98	-35.84	0.074
1.00	-35.74	0.074
1.02	-35.64	0.075
1.04	-35.54	0.075
1.06	-35.44	0.075
1.08	-35.34	0.075
1.10	-35.24	0.075
1.12	-35.14	0.075
1.14	-35.04	0.075
1.16	-34.94	0.075
1.18	-34.85	0.075
1.20	-34.75	0.075
1.22	-34.65	0.075
1.24	-34.55	0.075
1.26	-34.45	0.076
1.28	-34.35	0.076
1.30	-34.25	0.076
1.32	-34.15	0.076
1.34	-34.05	0.076
1.36	-33.95	0.076
1.38	-33.85	0.076
1.40	-33.75	0.076
1.42	-33.65	0.076
1.44	-33.55	0.076
1.46	-33.46	0.076
1.48	-33.35	0.076
1.50	-33.26	0.076
1.52	-33.15	0.076
1.54	-33.06	0.076
1.56	-32.96	0.076
1.58	-32.86	0.076
1.60	-32.76	0.076
1.62	-32.66	0.076
1.64	-32.56	0.076
1.66	-32.46	0.076
1.68	-32.36	0.076
1.70	-32.26	0.076
1.72	-32.16	0.076
1.74	-32.06	0.076
1.76	-31.96	0.076
1.78	-31.86	0.076
1.80	-31.76	0.076
1.82	-31.66	0.076
1.84	-31.56	0.076
1.86	-31.46	0.076
1.88	-31.36	0.076
1.90	-31.26	0.076
1.92	-31.16	0.076
1.94	-31.06	0.076
1.96	-30.96	0.076
1.98	-30.86	0.076
2.00	-30.76	0.076
2.02	-30.66	0.076
2.04	-30.56	0.076
2.06	-30.46	0.076
2.08	-30.36	0.076
2.10	-30.26	0.076
2.12	-30.16	0.076
2.14	-30.06	0.076
2.16	-29.96	0.076
2.18	-29.86	0.076
2.20	-29.76	0.076
2.22	-29.66	0.076
2.24	-29.56	0.076
2.26	-29.46	0.076
2.28	-29.36	0.076
2.30	-29.26	0.076
2.32	-29.16	0.076
2.34	-29.06	0.076
2.36	-28.96	0.076
2.38	-28.86	0.076
2.40	-28.76	0.076
2.42	-28.66	0.076
2.44	-28.56	0.076
2.46	-28.46	0.076
2.48	-28.36	0.076
2.50	-28.26	0.076
2.52	-28.16	0.077
2.54	-28.06	0.077
2.56	-27.96	0.077
2.58	-27.86	0.077
2.60	-27.76	0.077
2.62	-27.66	0.077
2.64	-27.56	0.077
2.66	-27.46	0.077
2.68	-27.36	0.077
2.70	-27.26	0.077
2.72	-27.16	0.077
2.74	-27.06	0.077
2.76	-26.96	0.077
2.78	-26.86	0.077
2.80	-26.76	0.077
2.82	-26.66	0.077
2.84	-26.56	0.077
2.86	-26.46	0.077
2.88	-26.36	0.077
2.90	-26.26	0.077
2.92	-26.16	0.077
2.94	-26.06	0.077
2.96	-25.96	0.077
2.98	-25.86	0.077
3.00	-25.76	0.077
3.02	-25.66	0.077
3.04	-25.56	0.077
3.06	-25.46	0.077
3.08	-25.36	0.078
3.10	-25.26	0.078
3.12	-25.16	0.078
3.14	-25.06	0.078
3.16	-24.96	0.078
3.18	-24.86	0.078
3.20	-24.76	0.078
3.22	-24.66	0.078
3.24	-24.56	0.078
3.26	-24.46	0.078
3.28	-24.36	0.078
3.30	-24.26	0.078
3.32	-24.16	0.078
3.34	-24.06	0.078
3.36	-23.95	0.078
3.38	-23.86	0.078
3.40	-23.76	0.079
3.42	-23.66	0.079
3.44	-23.55	0.079
3.46	-23.46	0.079
3.48	-23.35	0.079
3.50	-23.25	0.079
3.52	-23.16	0.079
3.54	-23.06	0.079
3.56	-22.96	0.079
3.58	-22.86	0.079
3.60	-22.76	0.079
3.62	-22.66	0.079
3.64	-22.56	0.080
3.66	-22.46	0.080
3.68	-22.36	0.080
3.70	-22.26	0.080
3.72	-22.16	0.080
3.74	-22.06	0.080
3.76	-21.96	0.080
3.78	-21.86	0.080
3.80	-21.76	0.080
3.82	-21.66	0.080
3.84	-21.56	0.080
3.86	-21.46	0.081
3.88	-21.35	0.081
3.90	-21.26	0.081
3.92	-21.16	0.081
3.94	-21.05	0.081
3.96	-20.95	0.081
3.98	-20.85	0.082
4.00	-20.75	0.082
4.02	-20.65	0.082
4.04	-20.56	0.082
4.06	-20.45	0.082
4.08	-20.36	0.082
4.10	-20.26	0.083
4.12	-20.16	0.083
4.14	-20.06	0.083
4.16	-19.96	0.083
4.18	-19.85	0.083
4.20	-19.76	0.083
4.22	-19.66	0.084
4.24	-19.55	0.084
4.26	-19.46	0.084
4.28	-19.36	0.084
4.30	-19.26	0.084
4.32	-19.16	0.085
4.34	-19.06	0.085
4.36	-18.96	0.085
4.38	-18.86	0.085
4.40	-18.76	0.086
4.42	-18.66	0.086
4.44	-18.56	0.086
4.46	-18.46	0.086
4.48	-18.36	0.087
4.50	-18.26	0.087
4.52	-18.16	0.087
4.54	-18.06	0.087
4.56	-17.96	0.088
4.58	-17.86	0.088
4.60	-17.76	0.088
4.62	-17.66	0.089
4.64	-17.56	0.089
4.66	-17.46	0.089
4.68	-17.36	0.090
4.70	-17.26	0.090
4.72	-17.16	0.090
4.74	-17.06	0.091
4.76	-16.96	0.092
4.78	-16.86	0.092
4.80	-16.76	0.092
4.82	-16.66	0.093
4.84	-16.56	0.093
4.86	-16.46	0.094
4.88	-16.36	0.094
4.90	-16.26	0.095
4.92	-16.16	0.095
4.94	-16.06	0.096
4.96	-15.96	0.096
4.98	-15.86	0.097
5.00	-15.76	0.097
5.02	-15.66	0.098
5.04	-15.56	0.099
5.06	-15.46	0.099
5.08	-15.36	0.100
5.10	-15.26	0.100
5.12	-15.16	0.101
5.14	-15.06	0.102
5.16	-14.96	0.103
5.18	-14.86	0.104
5.20	-14.76	0.105
5.22	-14.66	0.106
5.24	-14.56	0.106
5.26	-14.46	0.107
5.28	-14.36	0.108
5.30	-14.26	0.108
5.32	-14.16	0.109
5.34	-14.06	0.110
5.36	-13.96	0.111
5.38	-13.86	0.112
5.40	-13.77	0.112
5.42	-13.66	0.113
5.44	-13.56	0.114
5.46	-13.47	0.115
5.48	-13.37	0.115
5.50	-13.27	0.116
5.52	-13.17	0.116
5.54	-13.07	0.117
5.56	-12.97	0.117
5.58	-12.87	0.118
5.60	-12.77	0.118
5.62	-12.67	0.118
5.64	-12.57	0.119
5.66	-12.47	0.119
5.68	-12.37	0.119
5.70	-12.27	0.120
5.72	-12.17	0.120
5.74	-12.07	0.120
5.76	-11.97	0.120
5.78	-11.87	0.120
5.80	-11.77	0.121
5.82	-11.67	0.121
5.84	-11.57	0.121
5.86	-11.47	0.121
5.88	-11.37	0.121
5.90	-11.27	0.121
5.92	-11.17	0.121
5.94	-11.07	0.120
5.96	-10.97	0.120
5.98	-10.86	0.120
6.00	-10.76	0.120
6.02	-10.66	0.120
6.04	-10.56	0.120
6.06	-10.46	0.119
6.08	-10.36	0.119
6.10	-10.26	0.119
6.12	-10.16	0.119
6.14	-10.06	0.118
6.16	-9.96	0.118
6.18	-9.86	0.118
6.20	-9.76	0.118
6.22	-9.66	0.118
6.24	-9.56	0.117
6.26	-9.46	0.117
6.28	-9.36	0.117
6.30	-9.26	0.117
6.32	-9.16	0.117
6.34	-9.06	0.117
6.36	-8.96	0.116
6.38	-8.86	0.116
6.40	-8.76	0.116
6.42	-8.66	0.116
6.44	-8.56	0.116
6.46	-8.46	0.116
6.48	-8.36	0.116
6.50	-8.26	0.116
6.52	-8.16	0.116
6.54	-8.06	0.115
6.56	-7.96	0.115
6.58	-7.86	0.115
6.60	-7.76	0.115
6.62	-7.66	0.115
6.64	-7.56	0.115
6.66	-7.46	0.115
6.68	-7.36	0.115
6.70	-7.26	0.115
6.72	-7.16	0.115
6.74	-7.06	0.115
6.76	-6.96	0.115
6.78	-6.86	0.115
6.80	-6.76	0.115
6.82	-6.66	0.115
6.84	-6.56	0.114
6.86	-6.46	0.114
6.88	-6.36	0.114
6.90	-6.26	0.114
6.92	-6.16	0.114
6.94	-6.06	0.114
6.96	-5.96	0.114
6.98	-5.86	0.114
7.00	-5.76	0.114
7.02	-5.66	0.114
7.04	-5.56	0.114
7.06	-5.46	0.114
7.08	-5.36	0.114
7.10	-5.26	0.114
7.12	-5.16	0.114
7.14	-5.06	0.114
7.16	-4.96	0.114
7.18	-4.86	0.114
7.20	-4.76	0.114
7.22	-4.66	0.114
7.24	-4.56	0.114
7.26	-4.46	0.114
7.28	-4.36	0.114
7.30	-4.26	0.114
7.32	-4.16	0.114
7.34	-4.06	0.114
7.36	-3.96	0.114
7.38	-3.86	0.114
7.40	-3.76	0.114
7.42	-3.66	0.114
7.44	-3.56	0.114
7.46	-3.46	0.114
7.48	-3.36	0.114
7.50	-3.26	0.114
7.52	-3.16	0.114
7.54	-3.06	0.114
7.56	-2.96	0.114
7.58	-2.86	0.114
7.60	-2.75	0.114
7.62	-2.65	0.114
7.64	-2.56	0.114
7.66	-2.46	0.114
7.68	-2.35	0.114
7.70	-2.26	0.114
7.72	-2.15	0.114
7.74	-2.05	0.114
7.76	-1.96	0.114
7.78	-1.86	0.114
7.80	-1.76	0.114
7.82	-1.65	0.114
7.84	-1.55	0.114
7.86	-1.45	0.114
7.88	-1.35	0.114
7.90	-1.26	0.114
7.92	-1.15	0.114
7.94	-1.05	0.114
7.96	-0.95	0.114
7.98	-0.85	0.114
8.00	-0.75	0.114
8.02	-0.65	0.114
8.04	-0.55	0.114
8.06	-0.45	0.115
8.08	-0.35	0.115
8.10	-0.25	0.115
8.12	-0.15	0.115
8.14	-0.05	0.115
8.16	0.05	0.115
8.18	0.15	0.115
8.20	0.25	0.115
8.22	0.35	0.115
8.24	0.45	0.115
8.26	0.55	0.115
8.28	0.65	0.115
8.30	0.75	0.115
8.32	0.85	0.115
8.34	0.95	0.115
8.36	1.05	0.115
8.38	1.15	0.115
8.40	1.25	0.115
8.42	1.35	0.115
8.44	1.45	0.115
8.46	1.55	0.115
8.48	1.65	0.115
8.50	1.75	0.115
8.52	1.85	0.115
8.54	1.95	0.115
8.56	2.05	0.115
8.58	2.15	0.115
8.60	2.25	0.115
8.62	2.35	0.115
8.64	2.45	0.115
8.66	2.55	0.115
8.68	2.65	0.115
8.70	2.75	0.115
8.72	2.85	0.115
8.74	2.95	0.115
8.76	3.05	0.115
8.78	3.15	0.115
8.80	3.25	0.115
8.82	3.35	0.115
8.84	3.45	0.115
8.86	3.55	0.115
8.88	3.65	0.115
8.90	3.75	0.115
8.92	3.85	0.115
8.94	3.95	0.115
8.96	4.05	0.115
8.98	4.15	0.115
9.00	4.25	0.115
9.02	4.35	0.115
9.04	4.45	0.115
9.06	4.55	0.115
9.08	4.65	0.115
9.10	4.75	0.115
9.12	4.85	0.115
9.14	4.95	0.115
9.16	5.05	0.115
9.18	5.15	0.115
9.20	5.25	0.115
9.22	5.35	0.115
9.24	5.45	0.115
9.26	5.55	0.115
9.28	5.65	0.115
9.30	5.75	0.115
9.32	5.85	0.115
9.34	5.95	0.115
9.36	6.05	0.116
9.38	6.15	0.116
9.40	6.25	0.116
9.42	6.35	0.116
9.44	6.45	0.116
9.46	6.55	0.116
9.48	6.65	0.116
9.50	6.75	0.116
9.52	6.85	0.116
9.54	6.95	0.116
9.56	7.05	0.116
9.58	7.15	0.116
9.60	7.25	0.116
9.62	7.35	0.116
9.64	7.45	0.116
9.66	7.55	0.116
9.68	7.65	0.116
9.70	7.75	0.116
9.72	7.85	0.116
9.74	7.95	0.116
9.76	8.05	0.116
9.78	8.15	0.116
9.80	8.25	0.116
9.82	8.35	0.116
9.84	8.45	0.116
9.86	8.55	0.116
9.88	8.65	0.116
9.90	8.75	0.116
9.92	8.85	0.116
9.94	8.96	0.116
9.96	9.05	0.116
9.98	9.15	0.116
10.00	9.25	0.116
10.02	9.35	0.116
10.04	9.45	0.116
10.06	9.56	0.116
10.08	9.65	0.116
10.10	9.76	0.116
10.12	9.86	0.116
10.14	9.95	0.116
10.16	10.05	0.116
10.18	10.16	0.116
10.20	10.26	0.116
10.22	10.35	0.116
10.24	10.46	0.116
10.26	10.56	0.116
10.28	10.66	0.116
10.30	10.75	0.116
10.32	10.85	0.116
10.34	10.96	0.116
10.36	11.05	0.116
10.38	11.16	0.116
10.40	11.25	0.116
10.42	11.36	0.116
10.44	11.46	0.116
10.46	11.56	0.117
10.48	11.66	0.116
10.50	11.76	0.117
10.52	11.86	0.117
10.54	11.96	0.117
10.56	12.06	0.117
10.58	12.16	0.117
10.60	12.26	0.117
10.62	12.36	0.117
10.64	12.46	0.117
10.66	12.56	0.117
10.68	12.66	0.117
10.70	12.76	0.117
10.72	12.86	0.117
10.74	12.96	0.117
10.76	13.06	0.117
10.78	13.16	0.117
10.80	13.26	0.117
10.82	13.36	0.117
10.84	13.46	0.117
10.86	13.56	0.117
10.88	13.66	0.117
10.90	13.76	0.117
10.92	13.86	0.117
10.94	13.96	0.117
10.96	14.06	0.117
10.98	14.16	0.117
11.00	14.26	0.117
11.02	14.36	0.117
11.04	14.46	0.117
11.06	14.56	0.117
11.08	14.66	0.117
11.10	14.76	0.117
11.12	14.86	0.117
11.14	14.96	0.117
11.16	15.06	0.117
11.18	15.16	0.117
11.20	15.26	0.117
11.22	15.36	0.117
11.24	15.46	0.117
11.26	15.56	0.117
11.28	15.66	0.117
11.30	15.76	0.117
11.32	15.86	0.117
11.34	15.96	0.118
11.36	16.06	0.118
11.38	16.16	0.118
11.40	16.26	0.118
11.42	16.36	0.118
11.44	16.46	0.118
11.46	16.56	0.118
11.48	16.66	0.118
11.50	16.76	0.118
11.52	16.86	0.118
11.54	16.96	0.118
11.56	17.06	0.118
11.58	17.16	0.118
11.60	17.26	0.118
11.62	17.36	0.118
11.64	17.46	0.118
11.66	17.56	0.118
11.68	17.66	0.118
11.70	17.76	0.118
11.72	17.86	0.118
11.74	17.96	0.118
11.76	18.06	0.118
11.78	18.16	0.118
11.80	18.26	0.118
11.82	18.36	0.118
11.84	18.46	0.118
11.86	18.56	0.118
11.88	18.66	0.118
11.90	18.76	0.118
11.92	18.86	0.118
11.94	18.96	0.118
11.96	19.06	0.118
11.98	19.16	0.118
12.00	19.26	0.118
12.02	19.36	0.118
12.04	19.46	0.118
12.06	19.56	0.118
12.08	19.66	0.118
12.10	19.76	0.118
12.12	19.86	0.118
12.14	19.96	0.118
12.16	20.06	0.118
12.18	20.16	0.118
12.20	20.26	0.118
12.22	20.36	0.118
12.24	20.46	0.118
12.26	20.56	0.118
12.28	20.66	0.118
12.30	20.76	0.118
12.32	20.86	0.118
12.34	20.96	0.118
12.36	21.06	0.118
12.38	21.16	0.118
12.40	21.26	0.118
12.42	21.36	0.119
12.44	21.46	0.119
12.46	21.56	0.119
12.48	21.66	0.119
12.50	21.76	0.119
12.52	21.86	0.119
12.54	21.96	0.119
12.56	22.06	0.119
12.58	22.16	0.119
12.60	22.26	0.119
12.62	22.36	0.119
12.64	22.46	0.119
12.66	22.56	0.119
12.68	22.66	0.119
12.70	22.76	0.119
12.72	22.86	0.119
12.74	22.96	0.119
12.76	23.06	0.119
12.78	23.16	0.119
12.80	23.26	0.119
12.82	23.36	0.119
12.84	23.46	0.119
12.86	23.56	0.119
12.88	23.66	0.119
12.90	23.76	0.119
12.92	23.86	0.119
12.94	23.96	0.119
12.96	24.06	0.119
12.98	24.16	0.119
13.00	24.26	0.119
13.02	24.36	0.119
13.04	24.46	0.119
13.06	24.56	0.119
13.08	24.66	0.119
13.10	24.76	0.119
13.12	24.87	0.119
13.14	24.96	0.119
13.16	25.07	0.119
13.18	25.16	0.119
13.20	25.26	0.119
13.22	25.36	0.119
13.24	25.46	0.119
13.26	25.56	0.119
13.28	25.67	0.119
13.30	25.77	0.120
13.32	25.87	0.120
13.34	25.97	0.120
13.36	26.07	0.120
13.38	26.17	0.120
13.40	26.26	0.120
13.42	26.36	0.120
13.44	26.47	0.120
13.46	26.57	0.120
13.48	26.67	0.120
13.50	26.77	0.120
13.52	26.87	0.120
13.54	26.97	0.120
13.56	27.07	0.120
13.58	27.17	0.120
13.60	27.27	0.120
13.62	27.37	0.120
13.64	27.47	0.120
13.66	27.57	0.120
13.68	27.67	0.120
13.70	27.77	0.120
13.72	27.87	0.120
13.74	27.97	0.120
13.76	28.07	0.120
13.78	28.17	0.120
13.80	28.27	0.120
13.82	28.37	0.120
13.84	28.47	0.120
13.86	28.57	0.120
13.88	28.67	0.121
13.90	28.77	0.121
13.92	28.87	0.121
13.94	28.97	0.121
13.96	29.07	0.121
13.98	29.17	0.121
14.00	29.27	0.121
14.02	29.37	0.121
14.04	29.47	0.121
14.06	29.57	0.121
14.08	29.67	0.121
14.10	29.77	0.121
14.12	29.87	0.121
14.14	29.97	0.121
14.16	30.07	0.121
14.18	30.17	0.121
14.20	30.27	0.121
14.22	30.37	0.121
14.24	30.47	0.121
14.26	30.57	0.121
14.28	30.67	0.121
14.30	30.77	0.121
14.32	30.87	0.121
14.34	30.97	0.122
14.36	31.07	0.122
14.38	31.17	0.122
14.40	31.27	0.122
14.42	31.37	0.122
14.44	31.47	0.122
14.46	31.57	0.122
14.48	31.67	0.122
14.50	31.77	0.122
14.52	31.87	0.122
14.54	31.97	0.122
14.56	32.07	0.122
14.58	32.17	0.122
14.60	32.27	0.122
14.62	32.37	0.122
14.64	32.47	0.122
14.66	32.57	0.122
14.68	32.67	0.122
14.70	32.77	0.122
14.72	32.87	0.122
14.74	32.97	0.122
14.76	33.07	0.122
14.78	33.17	0.122
14.80	33.27	0.122
14.82	33.37	0.122
14.84	33.47	0.122
14.86	33.57	0.122
14.88	33.67	0.122
14.90	33.77	0.122
14.92	33.87	0.122
14.94	33.97	0.122
14.96	34.07	0.122
14.98	34.17	0.122
15.00	34.27	0.122
15.02	34.37	0.122
15.04	34.47	0.122
15.06	34.57	0.122
15.08	34.67	0.122
15.10	34.77	0.123
15.12	34.87	0.123
15.14	34.97	0.123
15.16	35.07	0.123
15.18	35.17	0.123
15.20	35.27	0.123
15.22	35.37	0.123
15.24	35.47	0.123
15.26	35.57	0.123
15.28	35.67	0.123
15.30	35.77	0.123
15.32	35.87	0.123
15.34	35.97	0.123
15.36	36.07	0.123
15.38	36.17	0.123
15.40	36.27	0.123
15.42	36.37	0.123
15.44	36.47	0.123
15.46	36.57	0.123
15.48	36.67	0.123
15.50	36.77	0.123
15.52	36.87	0.123
15.54	36.97	0.123
15.56	37.07	0.123
15.58	37.17	0.123
15.60	37.27	0.123
15.62	37.37	0.123
15.64	37.47	0.123
15.66	37.57	0.123
15.68	37.67	0.123
15.70	37.77	0.123
15.72	37.87	0.123
15.74	37.97	0.123
15.76	38.07	0.123
15.78	38.17	0.123
15.80	38.27	0.123
15.82	38.37	0.123
15.84	38.47	0.123
15.86	38.57	0.123
15.88	38.67	0.123
15.90	38.77	0.123
15.92	38.87	0.123
15.94	38.97	0.124
15.96	39.07	0.124
15.98	39.17	0.124
16.00	39.27	0.124
16.02	39.37	0.124
16.04	39.47	0.124
16.06	39.57	0.124
16.08	39.67	0.124
16.10	39.77	0.124
16.12	39.87	0.124
16.14	39.97	0.124
16.16	40.07	0.124
16.18	40.17	0.124
16.20	40.28	0.124
16.22	40.38	0.124
16.24	40.47	0.124
16.26	40.57	0.124
16.28	40.68	0.124
16.30	40.77	0.124
16.32	40.87	0.124
16.34	40.97	0.124
16.36	41.07	0.124
16.38	41.17	0.124
16.40	41.27	0.124
16.42	41.37	0.124
16.44	41.48	0.124
16.46	41.58	0.124
16.48	41.68	0.124
16.50	41.77	0.124
16.52	41.88	0.124
16.54	41.98	0.124
16.56	42.08	0.124
16.58	42.18	0.124
16.60	42.28	0.124
16.62	42.38	0.125
16.64	42.48	0.125
16.66	42.58	0.125
16.68	42.68	0.125
16.70	42.78	0.125
16.72	42.88	0.125
16.74	42.98	0.125
16.76	43.08	0.125
16.78	43.18	0.125
16.80	43.28	0.125
16.82	43.38	0.125
16.84	43.48	0.125
16.86	43.58	0.125
16.88	43.68	0.125
16.90	43.78	0.125
16.92	43.88	0.125
16.94	43.98	0.125
16.96	44.08	0.125
16.98	44.18	0.125
17.00	44.28	0.125
17.02	44.38	0.125
17.04	44.48	0.125
17.06	44.58	0.125
17.08	44.68	0.125
17.10	44.78	0.125
17.12	44.88	0.125
17.14	44.98	0.125
17.16	45.08	0.125
17.18	45.18	0.125
17.20	45.28	0.125
17.22	45.38	0.125
17.24	45.48	0.125
17.26	45.58	0.125
17.28	45.68	0.125
17.30	45.78	0.125
17.32	45.88	0.125
17.34	45.98	0.125
17.36	46.08	0.125
17.38	46.18	0.125
17.40	46.28	0.125
17.42	46.38	0.126
17.44	46.48	0.125
17.46	46.58	0.126
17.48	46.68	0.126
17.50	46.78	0.126
17.52	46.88	0.126
17.54	46.98	0.126
17.56	47.08	0.126
17.58	47.18	0.126
17.60	47.28	0.126
17.62	47.38	0.126
17.64	47.48	0.126
17.66	47.58	0.126
17.68	47.68	0.126
17.70	47.78	0.126
17.72	47.88	0.126
17.74	47.98	0.126
17.76	48.08	0.126
17.78	48.18	0.126
17.80	48.28	0.126
17.82	48.38	0.126
17.84	48.48	0.126
17.86	48.58	0.126
17.88	48.68	0.126
17.90	48.78	0.126
17.92	48.88	0.126
17.94	48.98	0.126
17.96	49.08	0.126
17.98	49.18	0.126
18.00	49.28	0.126
18.02	49.38	0.126
18.04	49.48	0.126
18.06	49.58	0.126
18.08	49.68	0.126
18.10	49.78	0.126
18.12	49.88	0.126
18.14	49.98	0.126
18.16	50.08	0.126
18.18	50.18	0.126
18.20	50.28	0.126
18.22	50.38	0.126
18.24	50.48	0.126
18.26	50.58	0.126
18.28	50.68	0.126
18.30	50.78	0.126
18.32	50.88	0.126
18.34	50.98	0.127
18.36	51.08	0.127
18.38	51.18	0.127
18.40	51.28	0.127
18.42	51.38	0.127
18.44	51.48	0.127
18.46	51.58	0.127
18.48	51.68	0.127
18.50	51.78	0.127
18.52	51.88	0.127
18.54	51.98	0.127
18.56	52.08	0.127
18.58	52.18	0.127
18.60	52.28	0.127
18.62	52.38	0.127
18.64	52.48	0.127
18.66	52.58	0.127
18.68	52.68	0.127
18.70	52.78	0.127
18.72	52.88	0.127
18.74	52.98	0.127
18.76	53.08	0.127
18.78	53.18	0.127
18.80	53.28	0.127
18.82	53.38	0.127
18.84	53.48	0.127
18.86	53.58	0.127
18.88	53.68	0.127
18.90	53.78	0.127
18.92	53.88	0.127
18.94	53.98	0.127
18.96	54.08	0.127
18.98	54.18	0.127
19.00	54.28	0.127
19.02	54.38	0.127
19.04	54.49	0.127
19.06	54.59	0.127
19.08	54.68	0.128
19.10	54.78	0.128
19.12	54.88	0.128
19.14	54.98	0.128
19.16	55.08	0.128
19.18	55.18	0.128
19.20	55.28	0.128
19.22	55.38	0.128
19.24	55.48	0.128
19.26	55.58	0.128
19.28	55.69	0.128
19.30	55.78	0.128
19.32	55.89	0.128
19.34	55.98	0.128
19.36	56.08	0.128
19.38	56.19	0.128
19.40	56.28	0.128
19.42	56.38	0.128
19.44	56.48	0.128
19.46	56.58	0.128
19.48	56.69	0.128
19.50	56.78	0.128
19.52	56.88	0.128
19.54	56.98	0.128
19.56	57.08	0.128
19.58	57.18	0.128
19.60	57.28	0.128
19.62	57.39	0.128
19.64	57.49	0.128
19.66	57.59	0.128
19.68	57.69	0.128
19.70	57.79	0.128
19.72	57.89	0.128
19.74	57.99	0.128
19.76	58.09	0.128
19.78	58.19	0.128
19.80	58.29	0.128
19.82	58.39	0.128
19.84	58.49	0.128
19.86	58.59	0.128
19.88	58.69	0.128
19.90	58.79	0.128
19.92	58.89	0.128
19.94	58.99	0.128
19.96	59.09	0.128
19.98	59.19	0.129
20.00	59.29	0.129
20.02	59.39	0.129
20.04	59.49	0.129
20.06	59.59	0.129
20.08	59.69	0.129
20.10	59.79	0.129
20.12	59.89	0.129
20.14	59.99	0.129
20.16	60.09	0.129
20.18	60.19	0.129
20.20	60.29	0.129
20.22	60.39	0.129
20.24	60.49	0.129
20.26	60.59	0.129
20.28	60.69	0.129
20.30	60.79	0.129
20.32	60.89	0.129
20.34	60.99	0.129
20.36	61.09	0.129
20.38	61.19	0.129
20.40	61.29	0.129
20.42	61.39	0.129
20.44	61.49	0.129
20.46	61.59	0.129
20.48	61.69	0.129
20.50	61.79	0.129
20.52	61.89	0.129
20.54	61.99	0.129
20.56	62.09	0.129
20.58	62.19	0.129
20.60	62.29	0.129
20.62	62.39	0.129
20.64	62.49	0.129
20.66	62.59	0.129
20.68	62.69	0.129
20.70	62.79	0.129
20.72	62.89	0.129
20.74	62.99	0.129
20.76	63.09	0.129
20.78	63.19	0.130
20.80	63.29	0.130
20.82	63.39	0.130
20.84	63.49	0.130
20.86	63.59	0.130
20.88	63.69	0.130
20.90	63.79	0.130
20.92	63.89	0.130
20.94	63.99	0.130
20.96	64.09	0.130
20.98	64.19	0.130
21.00	64.29	0.130
21.02	64.39	0.130
21.04	64.49	0.130
21.06	64.59	0.130
21.08	64.69	0.130
21.10	64.79	0.130
21.12	64.89	0.130
21.14	64.99	0.130
21.16	65.09	0.130
21.18	65.19	0.130
21.20	65.29	0.130
21.22	65.39	0.130
21.24	65.49	0.130
21.26	65.59	0.130
21.28	65.69	0.130
21.30	65.79	0.130
21.32	65.89	0.130
21.34	65.99	0.130
21.36	66.09	0.130
21.38	66.19	0.130
21.40	66.29	0.130
21.42	66.39	0.130
21.44	66.49	0.130
21.46	66.59	0.130
21.48	66.69	0.130
21.50	66.79	0.130
21.52	66.89	0.130
21.54	66.99	0.130
21.56	67.09	0.130
21.58	67.19	0.130
21.60	67.29	0.130
21.62	67.39	0.130
21.64	67.49	0.130
21.66	67.59	0.130
21.68	67.69	0.130
21.70	67.79	0.130
21.72	67.89	0.131
21.74	67.99	0.131
21.76	68.09	0.131
21.78	68.19	0.131
21.80	68.29	0.131
21.82	68.39	0.131
21.84	68.49	0.131
21.86	68.59	0.131
21.88	68.69	0.131
21.90	68.79	0.131
21.92	68.89	0.131
21.94	68.99	0.131
21.96	69.09	0.131
21.98	69.19	0.131
22.00	69.29	0.131
22.02	69.39	0.131
22.04	69.49	0.131
22.06	69.59	0.131
22.08	69.69	0.131
22.10	69.79	0.131
22.12	69.89	0.131
22.14	69.99	0.131
22.16	70.09	0.131
22.18	70.19	0.131
22.20	70.29	0.131
22.22	70.39	0.131
22.24	70.49	0.131
22.26	70.59	0.131
22.28	70.69	0.131
22.30	70.79	0.131
22.32	70.89	0.131
22.34	70.99	0.131
22.36	71.09	0.131
22.38	71.19	0.131
22.40	71.29	0.131
22.42	71.39	0.131
22.44	71.49	0.131
22.46	71.60	0.131
22.48	71.70	0.131
22.50	71.79	0.131
22.52	71.89	0.131
22.54	71.99	0.131
22.56	72.10	0.131
22.58	72.19	0.131
22.60	72.29	0.131
22.62	72.39	0.131
22.64	72.49	0.131
22.66	72.59	0.131
22.68	72.70	0.131
22.70	72.79	0.131
22.72	72.89	0.132
22.74	73.00	0.132
22.76	73.10	0.132
22.78	73.19	0.132
22.80	73.29	0.132
22.82	73.39	0.132
22.84	73.49	0.132
22.86	73.60	0.132
22.88	73.70	0.132
22.90	73.80	0.132
22.92	73.90	0.132
22.94	74.00	0.132
22.96	74.10	0.132
22.98	74.20	0.132
23.00	74.30	0.132
23.02	74.40	0.132
23.04	74.50	0.132
23.06	74.59	0.132
23.08	74.70	0.132
23.10	74.80	0.132
23.12	74.90	0.132
23.14	75.00	0.132
23.16	75.10	0.132
23.18	75.20	0.132
23.20	75.30	0.132
23.22	75.40	0.132
23.24	75.50	0.132
23.26	75.60	0.132
23.28	75.70	0.132
23.30	75.80	0.132
23.32	75.89	0.132
23.34	76.00	0.132
23.36	76.10	0.132
23.38	76.20	0.132
23.40	76.30	0.132
23.42	76.40	0.132
23.44	76.50	0.132
23.46	76.60	0.132
23.48	76.70	0.132
23.50	76.80	0.133
23.52	76.90	0.132
23.54	77.00	0.133
23.56	77.10	0.133
23.58	77.20	0.133
23.60	77.30	0.133
23.62	77.40	0.133
23.64	77.50	0.133
23.66	77.60	0.133
23.68	77.70	0.133
23.70	77.80	0.133
23.72	77.90	0.133
23.74	78.00	0.133
23.76	78.10	0.133
23.78	78.20	0.133
23.80	78.30	0.133
23.82	78.40	0.133
23.84	78.50	0.133
23.86	78.60	0.133
23.88	78.70	0.133
23.90	78.80	0.133
23.92	78.90	0.133
23.94	79.00	0.133
23.96	79.10	0.133
23.98	79.20	0.133
24.00	79.30	0.133
24.02	79.40	0.133
24.04	79.50	0.133
24.06	79.60	0.133
24.08	79.70	0.133
24.10	79.80	0.133
24.12	79.90	0.133
24.14	80.00	0.133
24.16	80.10	0.133
24.18	80.20	0.133
24.20	80.30	0.133
24.22	80.40	0.133
24.24	80.50	0.133
24.26	80.60	0.133
24.28	80.70	0.133
24.30	80.80	0.133
24.32	80.90	0.133
24.34	81.00	0.133
24.36	81.10	0.133
24.38	81.20	0.133
24.40	81.30	0.133
24.42	81.40	0.133
24.44	81.50	0.134
24.46	81.60	0.134
24.48	81.70	0.134
24.50	81.80	0.134
24.52	81.90	0.134
24.54	82.00	0.134
24.56	82.10	0.134
24.58	82.20	0.134
24.60	82.30	0.134
24.62	82.40	0.134
24.64	82.50	0.134
24.66	82.60	0.134
24.68	82.70	0.134
24.70	82.80	0.134
24.72	82.90	0.134
24.74	83.00	0.134
24.76	83.10	0.134
24.78	83.20	0.134
24.80	83.30	0.134
24.82	83.40	0.134
24.84	83.50	0.134
24.86	83.60	0.134
24.88	83.70	0.134
24.90	83.80	0.134
24.92	83.90	0.134
24.94	84.00	0.134
24.96	84.10	0.134
24.98	84.20	0.134
25.00	84.30	0.134
25.02	84.40	0.134
25.04	84.50	0.134
25.06	84.60	0.134
25.08	84.70	0.134
25.10	84.80	0.134
25.12	84.90	0.134
25.14	85.00	0.134
25.16	85.10	0.134
25.18	85.20	0.134
25.20	85.30	0.134
25.22	85.40	0.134
25.24	85.50	0.134
25.26	85.60	0.134
25.28	85.70	0.134
25.30	85.80	0.134
25.32	85.90	0.134
25.34	86.00	0.134
25.36	86.10	0.134
25.38	86.20	0.134
25.40	86.30	0.134
25.42	86.40	0.134
25.44	86.50	0.134
25.46	86.60	0.134
25.48	86.70	0.134
25.50	86.80	0.134
25.52	86.90	0.135
25.54	87.00	0.135
25.56	87.10	0.135
25.58	87.20	0.135
25.60	87.30	0.135
25.62	87.40	0.135
25.64	87.50	0.135
25.66	87.60	0.135
25.68	87.70	0.135
25.70	87.80	0.135
25.72	87.90	0.135
25.74	88.00	0.135
25.76	88.10	0.135
25.78	88.20	0.135
25.80	88.30	0.135
25.82	88.40	0.135
25.84	88.50	0.135
25.86	88.60	0.135
25.88	88.70	0.135
25.90	88.80	0.135
25.92	88.90	0.135
25.94	89.00	0.135
25.96	89.10	0.135
25.98	89.20	0.135
26.00	89.30	0.135
26.02	89.40	0.135
26.04	89.50	0.135
26.06	89.60	0.135
26.08	89.70	0.135
26.10	89.80	0.135
26.12	89.90	0.135
26.14	90.00	0.135
26.16	90.10	0.135
26.18	90.20	0.135
26.20	90.30	0.135
26.22	90.40	0.135
26.24	90.50	0.135
26.26	90.60	0.135
26.28	90.70	0.135
26.30	90.80	0.135
26.32	90.90	0.135
26.34	91.00	0.135
26.36	91.10	0.135
26.38	91.20	0.135
26.40	91.30	0.136
26.42	91.40	0.136
26.44	91.50	0.136
26.46	91.60	0.136
26.48	91.70	0.136
26.50	91.80	0.136
26.52	91.90	0.136
26.54	92.00	0.136
26.56	92.10	0.136
26.58	92.20	0.136
26.60	92.31	0.136
26.62	92.40	0.136
26.64	92.50	0.136
26.66	92.60	0.136
26.68	92.70	0.136
26.70	92.80	0.136
26.72	92.90	0.136
26.74	93.00	0.136
26.76	93.10	0.136
26.78	93.20	0.136
26.80	93.30	0.136
26.82	93.41	0.136
26.84	93.50	0.136
26.86	93.60	0.136
26.88	93.70	0.136
26.90	93.81	0.136
26.92	93.91	0.136
26.94	94.01	0.136
26.96	94.10	0.136
26.98	94.21	0.136
27.00	94.30	0.136
27.02	94.40	0.136
27.04	94.50	0.136
27.06	94.60	0.136
27.08	94.70	0.136
27.10	94.80	0.136
27.12	94.90	0.136
27.14	95.00	0.136
27.16	95.10	0.136
27.18	95.20	0.136
27.20	95.30	0.136
27.22	95.40	0.136
27.24	95.50	0.136
27.26	95.60	0.137
27.28	95.71	0.136
27.30	95.80	0.137
27.32	95.90	0.137
27.34	96.01	0.137
27.36	96.10	0.137
27.38	96.21	0.137
27.40	96.31	0.137
27.42	96.41	0.137
27.44	96.51	0.137
27.46	96.60	0.137
27.48	96.71	0.137
27.50	96.81	0.137
27.52	96.91	0.137
27.54	97.00	0.137
27.56	97.10	0.137
27.58	97.20	0.137
27.60	97.30	0.137
27.62	97.41	0.137
27.64	97.50	0.137
27.66	97.61	0.137
27.68	97.71	0.137
27.70	97.81	0.137
27.72	97.91	0.137
27.74	98.01	0.137
27.76	98.11	0.137
27.78	98.21	0.137
27.80	98.31	0.137
27.82	98.41	0.137
27.84	98.51	0.137
27.86	98.61	0.137
27.88	98.71	0.137
27.90	98.81	0.137
27.92	98.91	0.137
27.94	99.01
27.96	99.11
27.98	99.21
27.99

[step]
Ramp 5.00 °C/min to -40.00 °C
Time	Temperature	Heat Flow (Normalized)
min	°C	W/g
28.99	100.11	-0.032
29.01	100.11	-0.033
29.03	100.10	-0.033
29.05	100.10	-0.033
29.07	100.08	-0.033
29.09	100.05	-0.034
29.11	100.00	-0.053
29.13	99.94	-0.074
29.15	99.88	-0.097
29.17	99.81	-0.117
29.19	99.73	-0.133
29.21	99.66	-0.146
29.23	99.57	-0.156
29.25	99.49	-0.165
29.27	99.40	-0.172
29.29	99.31	-0.178
29.31	99.22	-0.182
29.33	99.13	-0.186
29.35	99.04	-0.190
29.37	98.94	-0.192
29.39	98.85	-0.195
29.41	98.75	-0.197
29.43	98.66	-0.198
29.45	98.56	-0.199
29.47	98.46	-0.201
29.49	98.36	-0.201
29.51	98.27	-0.202
29.53	98.17	-0.202
29.55	98.07	-0.203
29.57	97.97	-0.203
29.59	97.87	-0.203
29.61	97.78	-0.204
29.63	97.68	-0.204
29.65	97.58	-0.204
29.67	97.48	-0.204
29.69	97.38	-0.205
29.71	97.28	-0.205
29.73	97.18	-0.205
29.75	97.09	-0.205
29.77	96.99	-0.205
29.79	96.89	-0.206
29.81	96.79	-0.206
29.83	96.69	-0.206
29.85	96.59	-0.206
29.87	96.49	-0.206
29.89	96.39	-0.206
29.91	96.29	-0.206
29.93	96.19	-0.207
29.95	96.09	-0.207
29.97	95.99	-0.207
29.99	95.89	-0.207
30.01	95.80	-0.207
30.03	95.70	-0.207
30.05	95.60	-0.207
30.07	95.50	-0.207
30.09	95.40	-0.207
30.11	95.30	-0.207
30.13	95.20	-0.207
30.15	95.10	-0.207
30.17	95.00	-0.207
30.19	94.90	-0.207
30.21	94.80	-0.207
30.23	94.70	-0.207
30.25	94.60	-0.207
30.27	94.50	-0.207
30.29	94.40	-0.207
30.31	94.30	-0.207
30.33	94.20	-0.207
30.35	94.10	-0.207
30.37	94.00	-0.207
30.39	93.90	-0.207
30.41	93.80	-0.207
30.43	93.70	-0.207
30.45	93.60	-0.207
30.47	93.50	-0.207
30.49	93.40	-0.207
30.51	93.30	-0.207
30.53	93.20	-0.207
30.55	93.10	-0.207
30.57	93.00	-0.207
30.59	92.90	-0.207
30.61	92.80	-0.207
30.63	92.70	-0.207
30.65	92.60	-0.207
30.67	92.50	-0.207
30.69	92.40	-0.207
30.71	92.31	-0.207
30.73	92.20	-0.207
30.75	92.10	-0.206
30.77	92.00	-0.206
30.79	91.91	-0.206
30.81	91.80	-0.206
30.83	91.70	-0.206
30.85	91.61	-0.206
30.87	91.51	-0.206
30.89	91.41	-0.206
30.91	91.31	-0.206
30.93	91.21	-0.206
30.95	91.11	-0.206
30.97	91.01	-0.206
30.99	90.91	-0.206
31.01	90.81	-0.206
31.03	90.71	-0.206
31.05	90.61	-0.206
31.07	90.51	-0.206
31.09	90.41	-0.205
31.11	90.31	-0.205
31.13	90.21	-0.205
31.15	90.11	-0.205
31.17	90.01	-0.205
31.19	89.91	-0.205
31.21	89.81	-0.205
31.23	89.71	-0.205
31.25	89.61	-0.205
31.27	89.51	-0.205
31.29	89.41	-0.205
31.31	89.31	-0.205
31.33	89.21	-0.205
31.35	89.11	-0.205
31.37	89.01	-0.205
31.39	88.91	-0.204
31.41	88.81	-0.204
31.43	88.71	-0.204
31.45	88.61	-0.204
31.47	88.51	-0.204
31.49	88.41	-0.204
31.51	88.31	-0.204
31.53	88.21	-0.204
31.55	88.11	-0.204
31.57	88.01	-0.204
31.59	87.91	-0.204
31.61	87.81	-0.204
31.63	87.71	-0.204
31.65	87.61	-0.204
31.67	87.51	-0.204
31.69	87.41	-0.203
31.71	87.31	-0.203
31.73	87.21	-0.203
31.75	87.11	-0.203
31.77	87.01	-0.203
31.79	86.91	-0.203
31.81	86.81	-0.203
31.83	86.71	-0.203
31.85	86.61	-0.203
31.87	86.51	-0.203
31.89	86.41	-0.203
31.91	86.31	-0.203
31.93	86.21	-0.203
31.95	86.11	-0.203
31.97	86.01	-0.203
31.99	85.91	-0.203
32.01	85.81	-0.202
32.03	85.71	-0.202
32.05	85.61	-0.202
32.07	85.51	-0.202
32.09	85.41	-0.202
32.11	85.31	-0.202
32.13	85.21	-0.202
32.15	85.11	-0.202
32.17	85.01	-0.202
32.19	84.91	-0.202
32.21	84.81	-0.202
32.23	84.71	-0.202
32.25	84.61	-0.202
32.27	84.51	-0.202
32.29	84.41	-0.202
32.31	84.31	-0.202
32.33	84.21	-0.202
32.35	84.11	-0.202
32.37	84.01	-0.202
32.39	83.91	-0.202
32.41	83.81	-0.201
32.43	83.71	-0.201
32.45	83.61	-0.201
32.47	83.51	-0.201
32.49	83.41	-0.201
32.51	83.31	-0.201
32.53	83.21	-0.201
32.55	83.11	-0.201
32.57	83.01	-0.201
32.59	82.91	-0.201
32.61	82.81	-0.201
32.63	82.71	-0.201
32.65	82.61	-0.201
32.67	82.51	-0.201
32.69	82.41	-0.201
32.71	82.31	-0.201
32.73	82.21	-0.201
32.75	82.11	-0.201
32.77	82.01	-0.201
32.79	81.91	-0.201
32.81	81.81	-0.201
32.83	81.71	-0.201
32.85	81.61	-0.201
32.87	81.51	-0.201
32.89	81.41	-0.201
32.91	81.31	-0.201
32.93	81.21	-0.201
32.95	81.11	-0.201
32.97	81.01	-0.200
32.99	80.91	-0.201
33.01	80.81	-0.200
33.03	80.71	-0.200
33.05	80.61	-0.200
33.07	80.51	-0.200
33.09	80.41	-0.200
33.11	80.31	-0.200
33.13	80.21	-0.200
33.15	80.11	-0.200
33.17	80.01	-0.200
33.19	79.91	-0.200
33.21	79.81	-0.200
33.23	79.71	-0.200
33.25	79.61	-0.200
33.27	79.51	-0.200
33.29	79.41	-0.200
33.31	79.31	-0.200
33.33	79.21	-0.200
33.35	79.11	-0.200
33.37	79.01	-0.200
33.39	78.91	-0.200
33.41	78.81	-0.200
33.43	78.71	-0.200
33.45	78.61	-0.199
33.47	78.51	-0.199
33.49	78.41	-0.199
33.51	78.31	-0.199
33.53	78.21	-0.199
33.55	78.11	-0.199
33.57	78.01	-0.199
33.59	77.91	-0.199
33.61	77.82	-0.199
33.63	77.72	-0.199
33.65	77.61	-0.199
33.67	77.51	-0.199
33.69	77.41	-0.199
33.71	77.32	-0.199
33.73	77.21	-0.199
33.75	77.11	-0.199
33.77	77.01	-0.199
33.79	76.91	-0.199
33.81	76.81	-0.199
33.83	76.71	-0.199
33.85	76.61	-0.199
33.87	76.51	-0.199
33.89	76.41	-0.199
33.91	76.31	-0.198
33.93	76.21	-0.198
33.95	76.11	-0.198
33.97	76.02	-0.198
33.99	75.91	-0.198
34.01	75.81	-0.198
34.03	75.72	-0.198
34.05	75.62	-0.198
34.07	75.52	-0.198
34.09	75.41	-0.198
34.11	75.31	-0.198
34.13	75.21	-0.198
34.15	75.12	-0.198
34.17	75.02	-0.198
34.19	74.92	-0.198
34.21	74.82	-0.198
34.23	74.72	-0.198
34.25	74.61	-0.198
34.27	74.52	-0.197
34.29	74.42	-0.197
34.31	74.32	-0.197
34.33	74.22	-0.197
34.35	74.12	-0.197
34.37	74.02	-0.197
34.39	73.92	-0.197
34.41	73.82	-0.197
34.43	73.72	-0.197
34.45	73.62	-0.197
34.47	73.52	-0.197
34.49	73.42	-0.197
34.51	73.32	-0.197
34.53	73.22	-0.197
34.55	73.12	-0.197
34.57	73.02	-0.197
34.59	72.92	-0.197
34.61	72.82	-0.197
34.63	72.72	-0.197
34.65	72.62	-0.197
34.67	72.52	-0.197
34.69	72.42	-0.197
34.71	72.32	-0.197
34.73	72.22	-0.197
34.75	72.12	-0.197
34.77	72.02	-0.196
34.79	71.92	-0.196
34.81	71.82	-0.196
34.83	71.72	-0.196
34.85	71.62	-0.196
34.87	71.52	-0.196
34.89	71.42	-0.196
34.91	71.32	-0.196
34.93	71.22	-0.196
34.95	71.12	-0.196
34.97	71.02	-0.196
34.99	70.92	-0.196
35.01	70.82	-0.196
35.03	70.72	-0.196
35.05	70.62	-0.196
35.07	70.52	-0.196
35.09	70.42	-0.196
35.11	70.32	-0.195
35.13	70.22	-0.196
35.15	70.12	-0.195
35.17	70.02	-0.195
35.19	69.92	-0.195
35.21	69.82	-0.195
35.23	69.72	-0.195
35.25	69.62	-0.195
35.27	69.52	-0.195
35.29	69.42	-0.195
35.31	69.32	-0.195
35.33	69.22	-0.195
35.35	69.12	-0.195
35.37	69.02	-0.195
35.39	68.92	-0.195
35.41	68.82	-0.195
35.43	68.72	-0.195
35.45	68.62	-0.195
35.47	68.52	-0.195
35.49	68.42	-0.195
35.51	68.32	-0.195
35.53	68.22	-0.194
35.55	68.12	-0.194
35.57	68.02	-0.194
35.59	67.92	-0.194
35.61	67.82	-0.194
35.63	67.72	-0.194
35.65	67.62	-0.194
35.67	67.52	-0.194
35.69	67.42	-0.194
35.71	67.32	-0.194
35.73	67.22	-0.194
35.75	67.12	-0.194
35.77	67.02	-0.194
35.79	66.92	-0.194
35.81	66.82	-0.194
35.83	66.72	-0.194
35.85	66.62	-0.193
35.87	66.52	-0.194
35.89	66.42	-0.193
35.91	66.32	-0.193
35.93	66.22	-0.193
35.95	66.12	-0.193
35.97	66.02	-0.193
35.99	65.92	-0.193
36.01	65.82	-0.193
36.03	65.72	-0.193
36.05	65.62	-0.193
36.07	65.52	-0.193
36.09	65.42	-0.193
36.11	65.32	-0.193
36.13	65.22	-0.193
36.15	65.12	-0.193
36.17	65.02	-0.193
36.19	64.92	-0.193
36.21	64.82	-0.193
36.23	64.72	-0.193
36.25	64.62	-0.192
36.27	64.52	-0.192
36.29	64.42	-0.192
36.31	64.32	-0.192
36.33	64.22	-0.192
36.35	64.12	-0.192
36.37	64.02	-0.192
36.39	63.92	-0.192
36.41	63.82	-0.192
36.43	63.72	-0.192
36.45	63.62	-0.192
36.47	63.52	-0.192
36.49	63.42	-0.192
36.51	63.32	-0.192
36.53	63.22	-0.192
36.55	63.12	-0.192
36.57	63.02	-0.192
36.59	62.92	-0.192
36.61	62.82	-0.192
36.63	62.72	-0.192
36.65	62.62	-0.191
36.67	62.52	-0.191
36.69	62.42	-0.191
36.71	62.32	-0.191
36.73	62.22	-0.191
36.75	62.12	-0.191
36.77	62.02	-0.191
36.79	61.92	-0.191
36.81	61.82	-0.191
36.83	61.72	-0.191
36.85	61.62	-0.191
36.87	61.52	-0.191
36.89	61.42	-0.191
36.91	61.32	-0.191
36.93	61.22	-0.191
36.95	61.12	-0.191
36.97	61.02	-0.191
36.99	60.92	-0.191
37.01	60.82	-0.191
37.03	60.72	-0.191
37.05	60.62	-0.191
37.07	60.52	-0.191
37.09	60.42	-0.190
37.11	60.32	-0.190
37.13	60.22	-0.190
37.15	60.12	-0.190
37.17	60.02	-0.190
37.19	59.92	-0.190
37.21	59.82	-0.190
37.23	59.72	-0.190
37.25	59.62	-0.190
37.27	59.52	-0.190
37.29	59.42	-0.190
37.31	59.32	-0.190
37.33	59.22	-0.190
37.35	59.12	-0.190
37.37	59.02	-0.190
37.39	58.92	-0.189
37.41	58.82	-0.189
37.43	58.72	-0.189
37.45	58.62	-0.189
37.47	58.52	-0.189
37.49	58.42	-0.189
37.51	58.32	-0.189
37.53	58.22	-0.189
37.55	58.12	-0.189
37.57	58.02	-0.189
37.59	57.92	-0.189
37.61	57.82	-0.189
37.63	57.72	-0.189
37.65	57.62	-0.189
37.67	57.52	-0.189
37.69	57.42	-0.189
37.71	57.32	-0.189
37.73	57.22	-0.189
37.75	57.12	-0.189
37.77	57.02	-0.189
37.79	56.92	-0.189
37.81	56.82	-0.189
37.83	56.72	-0.189
37.85	56.62	-0.188
37.87	56.52	-0.188
37.89	56.42	-0.188
37.91	56.33	-0.188
37.93	56.22	-0.188
37.95	56.12	-0.188
37.97	56.03	-0.188
37.99	55.92	-0.188
38.01	55.82	-0.188
38.03	55.72	-0.188
38.05	55.62	-0.188
38.07	55.52	-0.188
38.09	55.42	-0.188
38.11	55.33	-0.188
38.13	55.22	-0.188
38.15	55.13	-0.188
38.17	55.02	-0.188
38.19	54.93	-0.188
38.21	54.82	-0.188
38.23	54.73	-0.188
38.25	54.62	-0.188
38.27	54.52	-0.188
38.29	54.43	-0.188
38.31	54.32	-0.187
38.33	54.22	-0.187
[...]
122.83	-6.63	0.115
122.85	-6.53	0.115
122.87	-6.43	0.115
122.89	-6.33	0.115
122.91	-6.23	0.115
122.93	-6.13	0.115
122.95	-6.03	0.115
122.97	-5.93	0.115
122.99	-5.83	0.115
123.01	-5.73	0.115
123.03	-5.63	0.115
123.05	-5.53	0.115
123.07	-5.43	0.115
123.09	-5.33	0.115
123.11	-5.23	0.115
123.13	-5.13	0.115
123.15	-5.03	0.115
123.17	-4.93	0.115
123.19	-4.83	0.115
123.21	-4.73	0.115
123.23	-4.63	0.115
123.25	-4.53	0.115
123.27	-4.43	0.115
123.29	-4.33	0.115
123.31	-4.23	0.115
123.33	-4.13	0.115
123.35	-4.03	0.115
123.37	-3.93	0.115
123.39	-3.83	0.115
123.41	-3.73	0.115
123.43	-3.63	0.115
123.45	-3.53	0.115
123.47	-3.43	0.115
123.49	-3.33	0.115
123.51	-3.23	0.115
123.53	-3.13	0.115
123.55	-3.03	0.115
123.57	-2.93	0.115
123.59	-2.83	0.115
123.61	-2.73	0.115
123.63	-2.63	0.115
123.65	-2.53	0.115
123.67	-2.43	0.115
123.69	-2.33	0.115
123.71	-2.23	0.115
123.73	-2.13	0.115
123.75	-2.03	0.115
123.77	-1.93	0.115
123.79	-1.83	0.115
123.81	-1.73	0.115
123.83	-1.63	0.115
123.85	-1.53	0.115
123.87	-1.43	0.115
123.89	-1.33	0.115
123.91	-1.23	0.115
123.93	-1.13	0.115
123.95	-1.03	0.115
123.97	-0.93	0.115
123.99	-0.83	0.115
124.01	-0.73	0.115
124.03	-0.63	0.115
124.05	-0.53	0.115
124.07	-0.43	0.115
124.09	-0.33	0.115
124.11	-0.23	0.115
124.13	-0.13	0.115
124.15	-0.03	0.115
124.17	0.07	0.115
124.19	0.17	0.115
124.21	0.27	0.115
124.23	0.37	0.115
124.25	0.47	0.115
124.27	0.57	0.115
124.29	0.67	0.115
124.31	0.77	0.115
124.33	0.87	0.115
124.35	0.97	0.115
124.37	1.07	0.115
124.39	1.17	0.115
124.41	1.27	0.115
124.43	1.37	0.115
124.45	1.47	0.115
124.47	1.57	0.115
124.49	1.67	0.115
124.51	1.77	0.115
124.53	1.87	0.115
124.55	1.97	0.115
124.57	2.07	0.115
124.59	2.17	0.116
124.61	2.27	0.115
124.63	2.38	0.115
124.65	2.47	0.115
124.67	2.57	0.116
124.69	2.67	0.116
124.71	2.77	0.116
124.73	2.88	0.115
124.75	2.97	0.116
124.77	3.08	0.116
124.79	3.18	0.116
124.81	3.28	0.116
124.83	3.38	0.116
124.85	3.48	0.116
124.87	3.58	0.116
124.89	3.68	0.116
124.91	3.78	0.116
124.93	3.88	0.116
124.95	3.98	0.116
124.97	4.08	0.116
124.99	4.18	0.116
125.01	4.28	0.116
125.03	4.38	0.116
125.05	4.48	0.116
125.07	4.58	0.116
125.09	4.68	0.116
125.11	4.78	0.116
125.13	4.88	0.116
125.15	4.98	0.116
125.17	5.08	0.116
125.19	5.18	0.116
125.21	5.28	0.116
125.23	5.38	0.116
125.25	5.48	0.116
125.27	5.58	0.116
125.29	5.68	0.116
125.31	5.78	0.116
125.33	5.88	0.116
125.35	5.98	0.116
125.37	6.08	0.116
125.39	6.18	0.116
125.41	6.28	0.116
125.43	6.38	0.116
125.45	6.48	0.116
125.47	6.58	0.116
125.49	6.68	0.116
125.51	6.78	0.116
125.53	6.88	0.116
125.55	6.98	0.116
125.57	7.08	0.116
125.59	7.18	0.116
125.61	7.28	0.116
125.63	7.38	0.116
125.65	7.48	0.116
125.67	7.58	0.116
125.69	7.68	0.116
125.71	7.78	0.116
125.73	7.88	0.116
125.75	7.98	0.116
125.77	8.08	0.116
125.79	8.18	0.116
125.81	8.28	0.116
125.83	8.38	0.116
125.85	8.48	0.117
125.87	8.58	0.117
125.89	8.68	0.117
125.91	8.78	0.117
125.93	8.88	0.117
125.95	8.98	0.117
125.97	9.08	0.117
125.99	9.18	0.117
126.01	9.28	0.117
126.03	9.38	0.117
126.05	9.48	0.117
126.07	9.58	0.117
126.09	9.68	0.117
126.11	9.78	0.117
126.13	9.88	0.117
126.15	9.98	0.117
126.17	10.08	0.117
126.19	10.18	0.117
126.21	10.28	0.117
126.23	10.38	0.117
126.25	10.48	0.117
126.27	10.58	0.117
126.29	10.68	0.117
126.31	10.78	0.117
126.33	10.88	0.117
126.35	10.98	0.117
126.37	11.08	0.117
126.39	11.18	0.117
126.41	11.28	0.117
126.43	11.38	0.117
126.45	11.48	0.117
126.47	11.58	0.117
126.49	11.68	0.117
126.51	11.78	0.117
126.53	11.88	0.117
126.55	11.98	0.117
126.57	12.08	0.117
126.59	12.18	0.117
126.61	12.28	0.117
126.63	12.38	0.117
126.65	12.48	0.117
126.67	12.58	0.117
126.69	12.68	0.117
126.71	12.78	0.117
126.73	12.88	0.117
126.75	12.98	0.117
126.77	13.08	0.117
126.79	13.18	0.117
126.81	13.28	0.117
126.83	13.38	0.117
126.85	13.48	0.117
126.87	13.58	0.118
126.89	13.68	0.118
126.91	13.78	0.117
126.93	13.88	0.118
126.95	13.98	0.118
126.97	14.08	0.118
126.99	14.18	0.118
127.01	14.28	0.118
127.03	14.38	0.118
127.05	14.48	0.118
127.07	14.58	0.118
127.09	14.68	0.118
127.11	14.78	0.118
127.13	14.88	0.118
127.15	14.98	0.118
127.17	15.08	0.118
127.19	15.18	0.118
127.21	15.28	0.118
127.23	15.38	0.118
127.25	15.48	0.118
127.27	15.58	0.118
127.29	15.68	0.118
127.31	15.78	0.118
127.33	15.88	0.118
127.35	15.98	0.118
127.37	16.09	0.118
127.39	16.18	0.118
127.41	16.28	0.118
127.43	16.38	0.118
127.45	16.49	0.118
127.47	16.58	0.118
127.49	16.68	0.118
127.51	16.79	0.118
127.53	16.88	0.118
127.55	16.99	0.118
127.57	17.08	0.118
127.59	17.18	0.118
127.61	17.28	0.118
127.63	17.38	0.118
127.65	17.49	0.118
127.67	17.59	0.118
127.69	17.69	0.118
127.71	17.79	0.118
127.73	17.89	0.118
127.75	17.99	0.118
127.77	18.09	0.118
127.79	18.19	0.118
127.81	18.29	0.118
127.83	18.39	0.118
127.85	18.49	0.118
127.87	18.59	0.118
127.89	18.69	0.119
127.91	18.79	0.119
127.93	18.89	0.119
127.95	18.99	0.119
127.97	19.09	0.119
127.99	19.19	0.119
128.01	19.29	0.119
128.03	19.39	0.119
128.05	19.49	0.119
128.07	19.59	0.119
128.09	19.69	0.119
128.11	19.79	0.119
128.13	19.89	0.119
128.15	19.99	0.119
128.17	20.09	0.119
128.19	20.19	0.119
128.21	20.29	0.119
128.23	20.39	0.119
128.25	20.49	0.119
128.27	20.59	0.119
128.29	20.69	0.119
128.31	20.79	0.119
128.33	20.89	0.119
128.35	20.99	0.119
128.37	21.09	0.119
128.39	21.19	0.119
128.41	21.29	0.119
128.43	21.39	0.119
128.45	21.49	0.119
128.47	21.59	0.119
128.49	21.69	0.119
128.51	21.79	0.119
128.53	21.89	0.119
128.55	21.99	0.119
128.57	22.09	0.119
128.59	22.19	0.119
128.61	22.29	0.119
128.63	22.39	0.119
128.65	22.49	0.119
128.67	22.59	0.119
128.69	22.69	0.119
128.71	22.79	0.119
128.73	22.89	0.120
128.75	22.99	0.119
128.77	23.09	0.120
128.79	23.19	0.120
128.81	23.29	0.120
128.83	23.39	0.120
128.85	23.49	0.120
128.87	23.59	0.120
128.89	23.69	0.120
128.91	23.79	0.120
128.93	23.89	0.120
128.95	23.99	0.120
128.97	24.09	0.120
128.99	24.19	0.120
129.01	24.29	0.120
129.03	24.39	0.120
129.05	24.49	0.120
129.07	24.59	0.120
129.09	24.69	0.120
129.11	24.79	0.120
129.13	24.89	0.120
129.15	24.99	0.120
129.17	25.09	0.120
129.19	25.19	0.120
129.21	25.29	0.120
129.23	25.39	0.120
129.25	25.49	0.120
129.27	25.59	0.120
129.29	25.69	0.120
129.31	25.79	0.120
129.33	25.89	0.120
129.35	25.99	0.120
129.37	26.09	0.120
129.39	26.19	0.120
129.41	26.29	0.120
129.43	26.39	0.120
129.45	26.49	0.120
129.47	26.59	0.120
129.49	26.69	0.120
129.51	26.79	0.120
129.53	26.89	0.120
129.55	26.99	0.120
129.57	27.09	0.120
129.59	27.19	0.120
129.61	27.29	0.120
129.63	27.39	0.121
129.65	27.49	0.121
129.67	27.59	0.121
129.69	27.69	0.121
129.71	27.79	0.121
129.73	27.89	0.121
129.75	27.99	0.121
129.77	28.09	0.121
129.79	28.19	0.121
129.81	28.29	0.121
129.83	28.39	0.121
129.85	28.49	0.121
129.87	28.59	0.121
129.89	28.69	0.121
129.91	28.79	0.121
129.93	28.89	0.121
129.95	28.99	0.121
129.97	29.09	0.121
129.99	29.19	0.121
130.01	29.29	0.121
130.03	29.39	0.121
130.05	29.49	0.121
130.07	29.59	0.121
130.09	29.69	0.121
130.11	29.79	0.121
130.13	29.89	0.121
130.15	30.00	0.121
130.17	30.09	0.121
130.19	30.19	0.121
130.21	30.29	0.121
130.23	30.40	0.122
130.25	30.50	0.122
130.27	30.60	0.122
130.29	30.69	0.122
130.31	30.80	0.122
130.33	30.90	0.122
130.35	31.00	0.122
130.37	31.09	0.122
130.39	31.20	0.122
130.41	31.30	0.122
130.43	31.39	0.122
130.45	31.49	0.122
130.47	31.60	0.122
130.49	31.70	0.122
130.51	31.80	0.122
130.53	31.90	0.122
130.55	32.00	0.122
130.57	32.10	0.122
130.59	32.20	0.122
130.61	32.30	0.122
130.63	32.40	0.122
130.65	32.50	0.122
130.67	32.60	0.122
130.69	32.70	0.122
130.71	32.80	0.122
130.73	32.90	0.122
130.75	33.00	0.122
130.77	33.10	0.122
130.79	33.19	0.122
130.81	33.30	0.122
130.83	33.40	0.122
130.85	33.50	0.122
130.87	33.60	0.123
130.89	33.70	0.123
130.91	33.80	0.123
130.93	33.90	0.123
130.95	34.00	0.123
130.97	34.10	0.123
130.99	34.20	0.123
131.01	34.30	0.123
131.03	34.40	0.123
131.05	34.50	0.123
131.07	34.60	0.123
131.09	34.70	0.123
131.11	34.80	0.123
131.13	34.90	0.123
131.15	35.00	0.123
131.17	35.10	0.123
131.19	35.20	0.123
131.21	35.30	0.123
131.23	35.40	0.123
131.25	35.50	0.123
131.27	35.60	0.123
131.29	35.70	0.123
131.31	35.80	0.123
131.33	35.90	0.123
131.35	36.00	0.123
131.37	36.10	0.123
131.39	36.20	0.123
131.41	36.30	0.123
131.43	36.40	0.123
131.45	36.50	0.123
131.47	36.60	0.123
131.49	36.70	0.123
131.51	36.80	0.123
131.53	36.90	0.123
131.55	37.00	0.123
131.57	37.10	0.124
131.59	37.20	0.124
131.61	37.30	0.124
131.63	37.40	0.124
131.65	37.50	0.124
131.67	37.60	0.124
131.69	37.70	0.124
131.71	37.80	0.124
131.73	37.90	0.124
131.75	38.00	0.124
131.77	38.10	0.124
131.79	38.20	0.124
131.81	38.30	0.124
131.83	38.40	0.124
131.85	38.50	0.124
131.87	38.60	0.124
131.89	38.70	0.124
131.91	38.80	0.124
131.93	38.90	0.124
131.95	39.00	0.124
131.97	39.10	0.124
131.99	39.20	0.124
132.01	39.30	0.124
132.03	39.40	0.124
132.05	39.50	0.124
132.07	39.60	0.124
132.09	39.70	0.124
132.11	39.80	0.124
132.13	39.90	0.124
132.15	40.00	0.124
132.17	40.10	0.124
132.19	40.20	0.124
132.21	40.30	0.124
132.23	40.40	0.124
132.25	40.50	0.124
132.27	40.60	0.124
132.29	40.70	0.124
132.31	40.80	0.124
132.33	40.90	0.124
132.35	41.00	0.124
132.37	41.10	0.124
132.39	41.20	0.124
132.41	41.30	0.124
132.43	41.40	0.125
132.45	41.50	0.125
132.47	41.60	0.125
132.49	41.70	0.125
132.51	41.80	0.125
132.53	41.90	0.125
132.55	42.00	0.125
132.57	42.10	0.125
132.59	42.20	0.125
132.61	42.30	0.125
132.63	42.40	0.125
132.65	42.50	0.125
132.67	42.60	0.125
132.69	42.70	0.125
132.71	42.80	0.125
132.73	42.90	0.125
132.75	43.00	0.125
132.77	43.10	0.125
132.79	43.20	0.125
132.81	43.30	0.125
132.83	43.40	0.125
132.85	43.50	0.125
132.87	43.60	0.125
132.89	43.70	0.125
132.91	43.80	0.125
132.93	43.90	0.125
132.95	44.00	0.125
132.97	44.10	0.125
132.99	44.20	0.125
133.01	44.30	0.125
133.03	44.40	0.125
133.05	44.50	0.125
133.07	44.60	0.125
133.09	44.70	0.125
133.11	44.80	0.125
133.13	44.90	0.125
133.15	45.00	0.125
133.17	45.10	0.126
133.19	45.20	0.126
133.21	45.30	0.126
133.23	45.40	0.126
133.25	45.50	0.126
133.27	45.60	0.126
133.29	45.71	0.126
133.31	45.80	0.126
133.33	45.91	0.126
133.35	46.00	0.126
133.37	46.11	0.126
133.39	46.20	0.126
133.41	46.30	0.126
133.43	46.41	0.126
133.45	46.51	0.126
133.47	46.61	0.126
133.49	46.71	0.126
133.51	46.80	0.126
133.53	46.91	0.126
133.55	47.00	0.126
133.57	47.11	0.126
133.59	47.21	0.126
133.61	47.31	0.126
133.63	47.41	0.126
133.65	47.51	0.126
133.67	47.61	0.126
133.69	47.71	0.126
133.71	47.81	0.126
133.73	47.91	0.126
133.75	48.01	0.126
133.77	48.11	0.126
133.79	48.21	0.126
133.81	48.31	0.126
133.83	48.41	0.126
133.85	48.51	0.126
133.87	48.61	0.126
133.89	48.71	0.126
133.91	48.81	0.126
133.93	48.91	0.126
133.95	49.01	0.126
133.97	49.11	0.126
133.99	49.21	0.126
134.01	49.31	0.126
134.03	49.41	0.126
134.05	49.51	0.127
134.07	49.61	0.127
134.09	49.71	0.127
134.11	49.81	0.127
134.13	49.91	0.127
134.15	50.01	0.127
134.17	50.11	0.127
134.19	50.21	0.127
134.21	50.31	0.127
134.23	50.41	0.127
134.25	50.51	0.127
134.27	50.61	0.127
134.29	50.71	0.127
134.31	50.81	0.127
134.33	50.91	0.127
134.35	51.01	0.127
134.37	51.11	0.127
134.39	51.21	0.127
134.41	51.31	0.127
134.43	51.41	0.127
134.45	51.51	0.127
134.47	51.61	0.127
134.49	51.71	0.127
134.51	51.81	0.127
134.53	51.91	0.127
134.55	52.01	0.127
134.57	52.11	0.127
134.59	52.21	0.127
134.61	52.31	0.127
134.63	52.41	0.127
134.65	52.51	0.127
134.67	52.61	0.127
134.69	52.71	0.127
134.71	52.81	0.127
134.73	52.91	0.127
134.75	53.01	0.127
134.77	53.11	0.127
134.79	53.21	0.127
134.81	53.31	0.127
134.83	53.41	0.127
134.85	53.51	0.127
134.87	53.61	0.127
134.89	53.71	0.127
134.91	53.81	0.128
134.93	53.91	0.128
134.95	54.01	0.128
134.97	54.11	0.128
134.99	54.21	0.128
135.01	54.31	0.128
135.03	54.41	0.128
135.05	54.51	0.128
135.07	54.61	0.128
135.09	54.71	0.128
135.11	54.81	0.128
135.13	54.91	0.128
135.15	55.01	0.128
135.17	55.11	0.128
135.19	55.21	0.128
135.21	55.31	0.128
135.23	55.41	0.128
135.25	55.51	0.128
135.27	55.61	0.128
135.29	55.71	0.128
135.31	55.81	0.128
135.33	55.91	0.128
135.35	56.01	0.128
135.37	56.11	0.128
135.39	56.21	0.128
135.41	56.31	0.128
135.43	56.41	0.128
135.45	56.51	0.128
135.47	56.61	0.128
135.49	56.71	0.128
135.51	56.81	0.128
135.53	56.91	0.128
135.55	57.01	0.128
135.57	57.11	0.128
135.59	57.21	0.128
135.61	57.31	0.129
135.63	57.41	0.129
135.65	57.51	0.129
135.67	57.61	0.129
135.69	57.71	0.129
135.71	57.81	0.129
135.73	57.91	0.129
135.75	58.01	0.129
135.77	58.11	0.129
135.79	58.21	0.129
135.81	58.31	0.129
135.83	58.41	0.129
135.85	58.51	0.129
135.87	58.61	0.129
135.89	58.71	0.129
135.91	58.81	0.129
135.93	58.91	0.129
135.95	59.01	0.129
135.97	59.11	0.129
135.99	59.21	0.129
136.01	59.31	0.129
136.03	59.41	0.129
136.05	59.51	0.129
136.07	59.61	0.129
136.09	59.71	0.129
136.11	59.81	0.129
136.13	59.91	0.129
136.15	60.01	0.129
136.17	60.11	0.129
136.19	60.21	0.129
136.21	60.31	0.129
136.23	60.41	0.129
136.25	60.51	0.129
136.27	60.61	0.129
136.29	60.71	0.129
136.31	60.81	0.129
136.33	60.91	0.129
136.35	61.01	0.129
136.37	61.11	0.129
136.39	61.21	0.129
136.41	61.31	0.129
136.43	61.41	0.129
136.45	61.51	0.129
136.47	61.61	0.129
136.49	61.72	0.129
136.51	61.82	0.130
136.53	61.92	0.130
136.55	62.02	0.130
136.57	62.12	0.130
136.59	62.22	0.130
136.61	62.32	0.130
136.63	62.42	0.130
136.65	62.52	0.130
136.67	62.62	0.130
136.69	62.72	0.130
136.71	62.82	0.130
136.73	62.92	0.130
136.75	63.02	0.130
136.77	63.12	0.130
136.79	63.22	0.130
136.81	63.31	0.130
136.83	63.42	0.130
136.85	63.52	0.130
136.87	63.62	0.130
136.89	63.72	0.130
136.91	63.82	0.130
136.93	63.92	0.130
136.95	64.02	0.130
136.97	64.12	0.130
136.99	64.21	0.130
137.01	64.32	0.130
137.03	64.42	0.130
137.05	64.52	0.130
137.07	64.62	0.130
137.09	64.72	0.130
137.11	64.82	0.130
137.13	64.92	0.130
137.15	65.02	0.130
137.17	65.12	0.130
137.19	65.22	0.130
137.21	65.32	0.130
137.23	65.42	0.130
137.25	65.52	0.130
137.27	65.62	0.130
137.29	65.72	0.130
137.31	65.82	0.130
137.33	65.92	0.130
137.35	66.02	0.130
137.37	66.12	0.131
137.39	66.22	0.130
137.41	66.32	0.131
137.43	66.42	0.131
137.45	66.52	0.131
137.47	66.62	0.131
137.49	66.72	0.131
137.51	66.82	0.131
137.53	66.92	0.131
137.55	67.02	0.131
137.57	67.12	0.131
137.59	67.22	0.131
137.61	67.32	0.131
137.63	67.42	0.131
137.65	67.52	0.131
137.67	67.62	0.131
137.69	67.72	0.131
137.71	67.82	0.131
137.73	67.92	0.131
137.75	68.02	0.131
137.77	68.12	0.131
137.79	68.22	0.131
137.81	68.32	0.131
137.83	68.42	0.131
137.85	68.52	0.131
137.87	68.62	0.131
137.89	68.72	0.131
137.91	68.82	0.131
137.93	68.92	0.131
137.95	69.02	0.131
137.97	69.12	0.131
137.99	69.22	0.131
138.01	69.32	0.131
138.03	69.42	0.131
138.05	69.52	0.131
138.07	69.62	0.131
138.09	69.72	0.131
138.11	69.82	0.131
138.13	69.92	0.131
138.15	70.02	0.131
138.17	70.12	0.131
138.19	70.22	0.131
138.21	70.32	0.131
138.23	70.42	0.131
138.25	70.52	0.131
138.27	70.62	0.131
138.29	70.72	0.131
138.31	70.82	0.132
138.33	70.92	0.132
138.35	71.02	0.132
138.37	71.12	0.132
138.39	71.22	0.132
138.41	71.32	0.132
138.43	71.42	0.132
138.45	71.52	0.132
138.47	71.62	0.132
138.49	71.72	0.132
138.51	71.82	0.132
138.53	71.92	0.132
138.55	72.02	0.132
138.57	72.12	0.132
138.59	72.22	0.132
138.61	72.32	0.132
138.63	72.42	0.132
138.65	72.52	0.132
138.67	72.62	0.132
138.69	72.72	0.132
138.71	72.82	0.132
138.73	72.92	0.132
138.75	73.02	0.132
138.77	73.12	0.132
138.79	73.22	0.132
138.81	73.32	0.132
138.83	73.42	0.132
138.85	73.52	0.132
138.87	73.62	0.132
138.89	73.72	0.132
138.91	73.82	0.132
138.93	73.92	0.132
138.95	74.02	0.132
138.97	74.12	0.132
138.99	74.22	0.132
139.01	74.32	0.132
139.03	74.42	0.132
139.05	74.52	0.132
139.07	74.62	0.132
139.09	74.72	0.132
139.11	74.82	0.132
139.13	74.92	0.132
139.15	75.02	0.132
139.17	75.12	0.132
139.19	75.22	0.132
139.21	75.32	0.132
139.23	75.42	0.132
139.25	75.52	0.133
139.27	75.62	0.133
139.29	75.72	0.133
139.31	75.82	0.133
139.33	75.92	0.133
139.35	76.02	0.133
139.37	76.12	0.133
139.39	76.22	0.133
139.41	76.32	0.133
139.43	76.42	0.133
139.45	76.52	0.133
139.47	76.62	0.133
139.49	76.72	0.133
139.51	76.82	0.133
139.53	76.92	0.133
139.55	77.02	0.133
139.57	77.12	0.133
139.59	77.22	0.133
139.61	77.32	0.133
139.63	77.42	0.133
139.65	77.52	0.133
139.67	77.62	0.133
139.69	77.72	0.133
139.71	77.82	0.133
139.73	77.92	0.133
139.75	78.02	0.133
139.77	78.12	0.133
139.79	78.22	0.133
139.81	78.32	0.133
139.83	78.42	0.133
139.85	78.52	0.133
139.87	78.62	0.133
139.89	78.73	0.133
139.91	78.83	0.133
139.93	78.93	0.133
139.95	79.02	0.133
139.97	79.12	0.133
139.99	79.22	0.133
140.01	79.33	0.133
140.03	79.42	0.133
140.05	79.52	0.133
140.07	79.62	0.133
140.09	79.72	0.134
140.11	79.82	0.134
140.13	79.92	0.134
140.15	80.02	0.134
140.17	80.12	0.134
140.19	80.22	0.134
140.21	80.32	0.134
140.23	80.42	0.134
140.25	80.53	0.134
140.27	80.63	0.134
140.29	80.73	0.134
140.31	80.82	0.134
140.33	80.93	0.134
140.35	81.03	0.134
140.37	81.13	0.134
140.39	81.23	0.134
140.41	81.33	0.134
140.43	81.42	0.134
140.45	81.52	0.134
140.47	81.62	0.134
140.49	81.73	0.134
140.51	81.82	0.134
140.53	81.93	0.134
140.55	82.03	0.134
140.57	82.13	0.134
140.59	82.22	0.134
140.61	82.33	0.134
140.63	82.42	0.134
140.65	82.53	0.134
140.67	82.63	0.134
140.69	82.73	0.134
140.71	82.82	0.134
140.73	82.93	0.134
140.75	83.03	0.134
140.77	83.13	0.134
140.79	83.23	0.134
140.81	83.33	0.134
140.83	83.43	0.134
140.85	83.53	0.134
140.87	83.63	0.134
140.89	83.73	0.134
140.91	83.83	0.134
140.93	83.93	0.134
140.95	84.03	0.134
140.97	84.13	0.134
140.99	84.23	0.134
141.01	84.33	0.134
141.03	84.43	0.134
141.05	84.53	0.134
141.07	84.63	0.134
141.09	84.73	0.134
141.11	84.83	0.134
141.13	84.93	0.134
141.15	85.03	0.134
141.17	85.13	0.134
141.19	85.23	0.134
141.21	85.33	0.134
141.23	85.43	0.134
141.25	85.53	0.134
141.27	85.63	0.134
141.29	85.73	0.134
141.31	85.83	0.134
141.33	85.93	0.134
141.35	86.03	0.134
141.37	86.13	0.134
141.39	86.23	0.134
141.41	86.33	0.134
141.43	86.43	0.134
141.45	86.53	0.134
141.47	86.63	0.135
141.49	86.73	0.134
141.51	86.83	0.135
141.53	86.93	0.135
141.55	87.03	0.135
141.57	87.13	0.135
141.59	87.23	0.135
141.61	87.33	0.135
141.63	87.43	0.135
141.65	87.53	0.135
141.67	87.63	0.135
141.69	87.73	0.135
141.71	87.83	0.135
141.73	87.93	0.135
141.75	88.03	0.135
141.77	88.13	0.135
141.79	88.23	0.135
141.81	88.33	0.135
141.83	88.43	0.135
141.85	88.53	0.135
141.87	88.63	0.135
141.89	88.73	0.135
141.91	88.83	0.135
141.93	88.93	0.135
141.95	89.03	0.135
141.97	89.13	0.135
141.99	89.23	0.135
142.01	89.33	0.135
142.03	89.43	0.135
142.05	89.53	0.135
142.07	89.63	0.135
142.09	89.73	0.135
142.11	89.83	0.135
142.13	89.93	0.135
142.15	90.03	0.135
142.17	90.13	0.135
142.19	90.23	0.135
142.21	90.33	0.135
142.23	90.43	0.135
142.25	90.53	0.135
142.27	90.63	0.135
142.29	90.73	0.135
142.31	90.83	0.135
142.33	90.93	0.135
142.35	91.03	0.135
142.37	91.13	0.135
142.39	91.23	0.135
142.41	91.33	0.135
142.43	91.43	0.135
142.45	91.53	0.135
142.47	91.63	0.135
142.49	91.73	0.135
142.51	91.83	0.136
142.53	91.93	0.136
142.55	92.03	0.136
142.57	92.13	0.136
142.59	92.23	0.136
142.61	92.33	0.136
142.63	92.43	0.136
142.65	92.53	0.136
142.67	92.63	0.136
142.69	92.73	0.136
142.71	92.83	0.136
142.73	92.93	0.136
142.75	93.03	0.136
142.77	93.13	0.136
142.79	93.23	0.136
142.81	93.33	0.136
142.83	93.43	0.136
142.85	93.53	0.136
142.87	93.63	0.136
142.89	93.73	0.136
142.91	93.83	0.136
142.93	93.93	0.136
142.95	94.03	0.136
142.97	94.13	0.136
142.99	94.23	0.136
143.01	94.33	0.136
143.03	94.43	0.136
143.05	94.53	0.136
143.07	94.63	0.136
143.09	94.73	0.136
143.11	94.83	0.136
143.13	94.93	0.136
143.15	95.03	0.136
143.17	95.13	0.136
143.19	95.23	0.136
143.21	95.33	0.136
143.23	95.43	0.136
143.25	95.53	0.136
143.27	95.63	0.136
143.29	95.73	0.136
143.31	95.83	0.136
143.33	95.93	0.137
143.35	96.03	0.137
143.37	96.13	0.137
143.39	96.23	0.137
143.41	96.33	0.137
143.43	96.43	0.137
143.45	96.53	0.137
143.47	96.63	0.137
143.49	96.73	0.137
143.51	96.83	0.137
143.53	96.93	0.137
143.55	97.03	0.137
143.57	97.13	0.137
143.59	97.23	0.137
143.61	97.33	0.137
143.63	97.43	0.137
143.65	97.53	0.137
143.67	97.63	0.137
143.69	97.73	0.137
143.71	97.83	0.137
143.73	97.93	0.137
143.75	98.03	0.137
143.77	98.13	0.137
143.79	98.23	0.137
143.81	98.33	0.137
143.83	98.43	0.137
143.85	98.53	0.137
143.87	98.63	0.137
143.89	98.73	0.137
143.91	98.83	0.137
143.93	98.93	0.137
143.95	99.03
143.97	99.13
143.99