File: DSC/2025_06_06_Felodipine2_0C_165C_10Cmin_x3.csv
Filename,2025_06_06_Felodipine2_0C_165C_10Cmin_x3
Instrument name,DSC2A-00468 (192.168.1.100)
Operator,Yarger
rundate,6/6/2025
Sample name,2025_06_06_Felodipine2_0C_165C_10Cmin_x3
proceduresegments,Data Off ; Equilibrate 0.00 °C; Data On ; Ramp 10.00 °C/min to 165.00 °C; Data Off ; Isothermal 2.0 min; Data On ; Ramp 10.00 °C/min to 0.00 °C; Data Off ; Isothermal 2.0 min; Data On ; Ramp 10.00 °C/min to 165.00 °C; Data Off ; Isothermal 2.0 min; Data On ; Ramp 10.00 °C/min to 0.00 °C; Data Off ; Isothermal 2.0 min; Data On ; Ramp 10.00 °C/min to 30.00 °C
[File Parameters]
Run date,6/6/2025 11:19:34 AM
Trios version,5.1.1.46572
Original File Name,
Current File Name,D:\DSC2500\JYarger\2025_06_06_Felodipine2_0C_165C_10Cmin_x3.tri
[Procedure]
Procedure Name,Fel_0C_165C_10Cmin_x3
Sample Name,2025_06_06_Felodipine2_0C_165C_10Cmin_x3
Sample Mass,9.63 mg
Reference Sample Mass,0 mg
Pan Mass,55.93 mg
Pan Number,27
Reference Pan Mass,55.79 mg
Reference Pan Number,1
Pan Type,Tzero Aluminum Hermetic
Comments,Al Hermetic DSC Consumables sealed Pan/Lid. A2 Tray (Google Sheet: DSC_Samples_A2_Tray_May2025)
Project Name,CA
Operator,Yarger
Test,Custom
Unload Max Temperature,30
Unload Min Temperature,30
Load Max Temperature,30
Load Min Temperature,30
Stop on Gas Flow Error,Yes
[Signal List]
Signal #1,Time (min)
Signal #2,Temperature (°C)
Signal #3,Heat Flow (mW)
Signal #4,Delta T (µV)
Signal #5,Delta Tzero (µV)
Signal #6,Tzero Temperature (°C)
Signal #7,Cell Purge (mL/min)
Signal #8,Heater Temp (°C)
Signal #9,Power Delivered (W)
Signal #10,Reference Junction Temperature (°C)
Signal #11,Flange Temperature (°C)
Signal #12,Heat Flow Phase (rad)
Signal #13,Total Heat Capacity (J/°C)
Signal #14,Heat Capacity (J/°C)
[Configuration]
Company Name,ASU
Instrument Name,DSC2A-00468
Instrument Type,DSC2500
Serial Number,DSC2A-00468
IP,192.168.1.100
Location of Instrument,MRRC
DisplayType,Unknown
Sample Interval ,0.1 s/pt
Selected Heat Flow,T4P
Exotherm Direction,Down
Cell Serial,DRC2-00792
Lid Type,Standard
Cooler,RCS 90
Leave Cooler on at End of Sequence,On
Gas 2,Nitrogen
Gas Selected,Channel 1
Flow Rate,50 mL/min
Secondary Purge,On
Licensed Heat Flow,Heat Flow T4P
Modulation Licensed,Yes
[Versions]
Common IDD Version,1
Cortex Version,VER 2.10.2.31
Driver,5.0.0.6
GDM Version,1.0.3.3
TouchscreenVersion,1.0.0.16145
FEP Version,1.2.1.21
FEP Bootloader,2.0.0.5
AutoSampler Version,2.1.1.26
Auto Sampler Bootloader,2.0.0.5
FCM Version,1.1.0.3
FCM Bootloader,2.0.0.5
[Experiment Logs]
Experiment Log Entry # 1,Lid Close
Experiment Log Entry # 3,Data On set to 0
Experiment Log Entry # 5,Equilibrate Segment 0 (C) Started
Experiment Log Entry # 7,Air Cool is off.
Experiment Log Entry # 9,Data On set to 1
Experiment Log Entry # 11,Ramp Segment 10 C/min to 165 Started
Experiment Log Entry # 13,Data On set to 0
Experiment Log Entry # 15,Isothermal Segment 2 min started
Experiment Log Entry # 17,Data On set to 1
Experiment Log Entry # 19,Ramp Segment 10 C/min to 0 Started
Experiment Log Entry # 21,Data On set to 0
Experiment Log Entry # 23,Isothermal Segment 2 min started
Experiment Log Entry # 25,Data On set to 1
Experiment Log Entry # 27,Ramp Segment 10 C/min to 165 Started
Experiment Log Entry # 29,Data On set to 0
Experiment Log Entry # 31,Isothermal Segment 2 min started
Experiment Log Entry # 33,Data On set to 1
Experiment Log Entry # 35,Ramp Segment 10 C/min to 0 Started
Experiment Log Entry # 37,Data On set to 0
Experiment Log Entry # 39,Isothermal Segment 2 min started
Experiment Log Entry # 41,Data On set to 1
Experiment Log Entry # 43,Ramp Segment 10 C/min to 30 Started
[Method Log]
Method Log Entry # 1,Data Off
Method Log Entry # 2,Equilibrate 0 °C
Method Log Entry # 3,Data On
Method Log Entry # 4,(Ramp 813) Ramp 10 °C/minute to 165 °C
Method Log Entry # 5,Data Off
Method Log Entry # 6,Isothermal 2 minutes
Method Log Entry # 7,Data On
Method Log Entry # 8,(Ramp 817) Ramp 10 °C/minute to 0 °C
Method Log Entry # 9,Data Off
Method Log Entry # 10,Isothermal 2 minutes
Method Log Entry # 11,Data On
Method Log Entry # 12,(Ramp 821) Ramp 10 °C/minute to 165 °C
Method Log Entry # 13,Data Off
Method Log Entry # 14,Isothermal 2 minutes
Method Log Entry # 15,Data On
Method Log Entry # 16,(Ramp 825) Ramp 10 °C/minute to 0 °C
Method Log Entry # 17,Data Off
Method Log Entry # 18,Isothermal 2 minutes
Method Log Entry # 19,Data On
Method Log Entry # 20,(Ramp 829) Ramp 10 °C/minute to 30 °C
Cell Serial,DRC2-00792
[T1 Calibration]
Slope,-0.008529666
Offset,9.636258
Initial Temperature,98.23
GUID,f8bfdadc-4977-4fdf-ba6d-0ba9134940c3
[TZero Calibration]
Date Applied,11/29/2022 4:06:13 PM
Description,From -89.059 °C to 396.009 °C at 20.000°C/min
Gas Type,Nitrogen
Pan Type,None
Source Files 1,C:\Users\yargerlab\Desktop\DSC Data\General\TZero_calibration_11_29_22_2nd(2).tri
Source Files 2,C:\Users\yargerlab\Desktop\DSC Data\General\TZero_calibration_11_29_22_2nd(3).tri
Delta T Offset,13.05235
Delta T Slope,-0.007271007
Delta T0 Offset,-13.69128
Delta T0 Slope,0.06063341
[Temperature Calibration]
Date Applied,11/29/2022 7:12:28 PM
Description,From 106.590 °C to 186.590 °C at 10.000°C/min
Gas Type,Nitrogen
Pan Type,Tzero Aluminum Hermetic
Source Files 1,C:\Users\yargerlab\Desktop\DSC Data\General\Indium(6).tri
Measured 1,157.391
Known 1,156.598
[Cell Constant Calibration]
Date Applied,11/29/2022 7:12:29 PM
Description,From 106.590 °C to 186.590 °C at 10.000°C/min
Gas Type,Nitrogen
Pan Type,Tzero Aluminum Hermetic
Source Files 1,C:\Users\yargerlab\Desktop\DSC Data\General\Indium(6).tri
T4P KCell,1.006051
Onset Slope,63.26126 mW/°C
[Direct Cp Calibration]
Date Applied,11/30/2022 11:04:51 AM
Description,From -79.983 °C to 298.409 °C at 10.000°C/min
Gas Type,Nitrogen
Pan Type,Tzero Aluminum Hermetic
Source Files 1,C:\Users\yargerlab\Desktop\DSC Data\General\Sapphire_Heat_Capacity_11_30_22.tri
[Rev Cp Calibration]
Date Applied,11/30/2022 1:58:51 PM
Description,From -79.996 °C to 292.812 °C at 3.000°C/min
Gas Type,Nitrogen
Pan Type,Tzero Aluminum Hermetic
Source Files 1,C:\Users\yargerlab\Desktop\DSC Data\General\Sapphire_MDSC_Calibration_11_30_22.tri
[step]
Ramp 10.00 °C/min to 165.00 °C
Time,Temperature,Heat Flow (Normalized)
min,°C,W/g
0.00,0.14,-0.042
0.01,0.14,-0.042
0.02,0.14,-0.039
0.03,0.13,-0.037
0.05,0.14,-0.035
0.06,0.14,-0.033
0.07,0.15,-0.032
0.08,0.17,-0.032
0.09,0.20,-0.032
0.11,0.23,-0.033
0.12,0.27,-0.032
0.13,0.33,-0.029
0.14,0.38,-0.021
0.15,0.45,-0.013
0.16,0.52,-0.003
0.18,0.60,0.007
0.19,0.68,0.018
0.20,0.76,0.029
0.21,0.84,0.039
0.22,0.93,0.049
0.23,1.02,0.057
0.24,1.11,0.066
0.26,1.20,0.073
0.27,1.30,0.080
0.28,1.39,0.086
0.29,1.49,0.092
0.30,1.59,0.098
0.31,1.69,0.103
0.33,1.80,0.108
0.34,1.90,0.113
0.35,2.00,0.117
0.36,2.11,0.121
0.37,2.22,0.125
0.39,2.32,0.128
0.40,2.43,0.132
0.41,2.54,0.135
0.42,2.65,0.137
0.43,2.76,0.140
0.44,2.87,0.142
0.45,2.98,0.143
0.47,3.09,0.146
0.48,3.20,0.147
0.49,3.31,0.149
0.50,3.42,0.150
0.51,3.53,0.152
0.53,3.65,0.154
0.54,3.76,0.154
0.55,3.87,0.155
0.56,3.98,0.156
0.57,4.10,0.157
0.58,4.21,0.158
0.60,4.32,0.158
0.61,4.44,0.159
0.62,4.55,0.160
0.63,4.67,0.161
0.64,4.78,0.161
0.65,4.89,0.162
0.67,5.01,0.162
0.68,5.12,0.163
0.69,5.24,0.163
0.70,5.35,0.163
0.71,5.47,0.164
0.72,5.58,0.164
0.73,5.70,0.164
0.75,5.81,0.164
0.76,5.93,0.165
0.77,6.04,0.165
0.78,6.16,0.165
0.79,6.27,0.165
0.80,6.39,0.166
0.82,6.50,0.166
0.83,6.62,0.166
0.84,6.73,0.166
0.85,6.85,0.167
0.86,6.96,0.167
0.88,7.08,0.167
0.89,7.19,0.167
0.90,7.31,0.167
0.91,7.43,0.167
0.92,7.54,0.167
0.93,7.66,0.168
0.95,7.77,0.168
0.96,7.89,0.168
0.97,8.01,0.168
0.98,8.12,0.168
0.99,8.24,0.168
1.00,8.35,0.168
1.02,8.47,0.169
1.03,8.58,0.169
1.04,8.70,0.169
1.05,8.82,0.169
1.06,8.93,0.169
1.07,9.05,0.169
1.08,9.16,0.169
1.10,9.28,0.169
1.11,9.40,0.170
1.12,9.51,0.170
1.13,9.63,0.170
1.14,9.75,0.170
1.16,9.86,0.170
1.17,9.98,0.170
1.18,10.09,0.170
1.19,10.21,0.170
1.20,10.33,0.170
1.21,10.44,0.171
1.23,10.56,0.171
1.24,10.68,0.171
1.25,10.79,0.171
1.26,10.91,0.171
1.27,11.02,0.171
1.28,11.14,0.171
1.29,11.26,0.171
1.31,11.37,0.171
1.32,11.49,0.172
1.33,11.61,0.172
1.34,11.72,0.172
1.35,11.84,0.172
1.37,11.96,0.172
1.38,12.07,0.172
1.39,12.19,0.172
1.40,12.30,0.172
1.41,12.42,0.172
1.42,12.54,0.172
1.43,12.65,0.173
1.45,12.77,0.173
1.46,12.89,0.173
1.47,13.00,0.173
1.48,13.12,0.173
1.49,13.24,0.173
1.51,13.35,0.173
1.52,13.47,0.173
1.53,13.59,0.173
1.54,13.70,0.173
1.55,13.82,0.173
1.56,13.94,0.173
1.58,14.05,0.173
1.59,14.17,0.174
1.60,14.29,0.174
1.61,14.40,0.174
1.62,14.52,0.174
1.63,14.64,0.174
1.64,14.75,0.174
1.66,14.87,0.174
1.67,14.99,0.174
1.68,15.10,0.174
1.69,15.22,0.174
1.70,15.34,0.174
1.72,15.45,0.174
1.73,15.57,0.174
1.74,15.69,0.174
1.75,15.80,0.174
1.76,15.92,0.175
1.77,16.04,0.175
1.78,16.15,0.175
1.80,16.27,0.175
1.81,16.39,0.175
1.82,16.50,0.175
1.83,16.62,0.175
1.84,16.74,0.175
1.86,16.85,0.175
1.87,16.97,0.175
1.88,17.09,0.175
1.89,17.20,0.175
1.90,17.32,0.175
1.91,17.44,0.175
1.93,17.55,0.175
1.94,17.67,0.176
1.95,17.79,0.176
1.96,17.91,0.176
1.97,18.02,0.176
1.98,18.14,0.176
1.99,18.25,0.176
2.01,18.37,0.176
2.02,18.49,0.176
2.03,18.60,0.176
2.04,18.72,0.176
2.05,18.84,0.176
2.07,18.95,0.176
2.08,19.07,0.176
2.09,19.19,0.176
2.10,19.31,0.176
2.11,19.42,0.176
2.12,19.54,0.177
2.14,19.66,0.177
2.15,19.77,0.177
2.16,19.89,0.177
2.17,20.00,0.177
2.18,20.12,0.177
2.19,20.24,0.177
2.21,20.35,0.177
2.22,20.47,0.177
2.23,20.59,0.177
2.24,20.71,0.177
2.25,20.82,0.177
2.26,20.94,0.177
2.28,21.06,0.177
2.29,21.17,0.177
2.30,21.29,0.177
2.31,21.41,0.177
2.32,21.52,0.178
2.33,21.64,0.178
2.34,21.76,0.178
2.36,21.87,0.178
2.37,21.99,0.178
2.38,22.11,0.178
2.39,22.22,0.178
2.40,22.34,0.178
2.41,22.46,0.178
2.43,22.57,0.178
2.44,22.69,0.178
2.45,22.81,0.178
2.46,22.92,0.178
2.47,23.04,0.178
2.49,23.16,0.178
2.50,23.27,0.178
2.51,23.39,0.178
2.52,23.51,0.179
2.53,23.62,0.179
2.54,23.74,0.179
2.56,23.86,0.179
2.57,23.98,0.179
2.58,24.09,0.179
2.59,24.21,0.179
2.60,24.33,0.179
2.61,24.44,0.179
2.63,24.56,0.179
2.64,24.67,0.179
2.65,24.79,0.179
2.66,24.91,0.179
2.67,25.03,0.179
2.68,25.14,0.179
2.69,25.26,0.179
2.71,25.38,0.180
2.72,25.49,0.180
2.73,25.61,0.180
2.74,25.73,0.180
2.75,25.84,0.180
2.76,25.96,0.180
2.78,26.08,0.180
2.79,26.19,0.180
2.80,26.31,0.180
2.81,26.43,0.180
2.82,26.54,0.180
2.84,26.66,0.180
2.85,26.78,0.180
2.86,26.89,0.180
2.87,27.01,0.180
2.88,27.13,0.180
2.89,27.25,0.180
2.91,27.36,0.181
2.92,27.48,0.181
2.93,27.59,0.181
2.94,27.71,0.181
2.95,27.83,0.181
2.96,27.94,0.181
2.98,28.06,0.181
2.99,28.18,0.181
3.00,28.30,0.181
3.01,28.41,0.181
3.02,28.53,0.181
3.03,28.65,0.181
3.04,28.76,0.181
3.06,28.88,0.181
3.07,29.00,0.181
3.08,29.11,0.181
3.09,29.23,0.181
3.10,29.35,0.181
3.11,29.46,0.181
3.13,29.58,0.182
3.14,29.70,0.182
3.15,29.81,0.182
3.16,29.93,0.182
3.17,30.05,0.182
3.19,30.16,0.182
3.20,30.28,0.182
3.21,30.40,0.182
3.22,30.51,0.182
3.23,30.63,0.182
3.24,30.75,0.182
3.26,30.87,0.182
3.27,30.98,0.182
3.28,31.10,0.182
3.29,31.22,0.182
3.30,31.33,0.182
3.31,31.45,0.182
3.33,31.57,0.183
3.34,31.68,0.183
3.35,31.80,0.183
3.36,31.92,0.183
3.37,32.03,0.183
3.38,32.15,0.183
3.39,32.27,0.183
3.41,32.38,0.183
3.42,32.50,0.183
3.43,32.62,0.183
3.44,32.73,0.183
3.45,32.85,0.183
3.46,32.97,0.183
3.48,33.08,0.183
3.49,33.20,0.183
3.50,33.32,0.183
3.51,33.43,0.183
3.52,33.55,0.183
3.54,33.67,0.183
3.55,33.78,0.184
3.56,33.90,0.184
3.57,34.02,0.184
3.58,34.14,0.184
3.59,34.25,0.184
3.61,34.37,0.184
3.62,34.49,0.184
3.63,34.60,0.184
3.64,34.72,0.184
3.65,34.84,0.184
3.66,34.95,0.184
3.68,35.07,0.184
3.69,35.19,0.184
3.70,35.30,0.184
3.71,35.42,0.184
3.72,35.54,0.184
3.73,35.65,0.184
3.74,35.77,0.184
3.76,35.89,0.185
3.77,36.00,0.185
3.78,36.12,0.185
3.79,36.24,0.185
3.80,36.35,0.185
3.81,36.47,0.185
3.83,36.59,0.185
3.84,36.71,0.185
3.85,36.82,0.185
3.86,36.94,0.185
3.87,37.05,0.185
3.89,37.17,0.185
3.90,37.29,0.185
3.91,37.40,0.185
3.92,37.52,0.185
3.93,37.64,0.185
3.94,37.76,0.186
3.96,37.87,0.186
3.97,37.99,0.186
3.98,38.11,0.186
3.99,38.22,0.186
4.00,38.34,0.186
4.01,38.46,0.186
4.03,38.58,0.186
4.04,38.69,0.186
4.05,38.81,0.186
4.06,38.92,0.186
4.07,39.04,0.186
4.08,39.16,0.186
4.09,39.27,0.186
4.11,39.39,0.186
4.12,39.51,0.186
4.13,39.62,0.186
4.14,39.74,0.186
4.15,39.86,0.187
4.16,39.97,0.187
4.18,40.09,0.187
4.19,40.21,0.187
4.20,40.33,0.187
4.21,40.44,0.187
4.22,40.56,0.187
4.24,40.68,0.187
4.25,40.79,0.187
4.26,40.91,0.187
4.27,41.03,0.187
4.28,41.14,0.187
4.29,41.26,0.187
4.30,41.38,0.187
4.32,41.49,0.187
4.33,41.61,0.187
4.34,41.73,0.187
4.35,41.84,0.188
4.36,41.96,0.188
4.38,42.08,0.188
4.39,42.20,0.188
4.40,42.31,0.188
4.41,42.43,0.188
4.42,42.54,0.188
4.43,42.66,0.188
4.45,42.78,0.188
4.46,42.90,0.188
4.47,43.01,0.188
4.48,43.13,0.188
4.49,43.24,0.188
4.50,43.36,0.188
4.51,43.48,0.188
4.53,43.60,0.188
4.54,43.71,0.188
4.55,43.83,0.188
4.56,43.95,0.188
4.57,44.06,0.189
4.59,44.18,0.189
4.60,44.30,0.189
4.61,44.41,0.189
4.62,44.53,0.189
4.63,44.65,0.189
4.64,44.76,0.189
4.65,44.88,0.189
4.67,45.00,0.189
4.68,45.11,0.189
4.69,45.23,0.189
4.70,45.35,0.189
4.71,45.46,0.189
4.73,45.58,0.189
4.74,45.70,0.189
4.75,45.81,0.190
4.76,45.93,0.190
4.77,46.05,0.190
4.78,46.16,0.190
4.80,46.28,0.190
4.81,46.40,0.190
4.82,46.51,0.190
4.83,46.63,0.190
4.84,46.75,0.190
4.85,46.86,0.190
4.86,46.98,0.190
4.88,47.10,0.190
4.89,47.22,0.190
4.90,47.33,0.190
4.91,47.45,0.190
4.92,47.57,0.191
4.94,47.68,0.191
4.95,47.80,0.191
4.96,47.92,0.191
4.97,48.03,0.191
4.98,48.15,0.191
4.99,48.27,0.191
5.00,48.38,0.191
5.02,48.50,0.191
5.03,48.62,0.191
5.04,48.73,0.191
5.05,48.85,0.191
5.06,48.97,0.191
5.08,49.08,0.191
5.09,49.20,0.191
5.10,49.32,0.191
5.11,49.43,0.191
5.12,49.55,0.192
5.13,49.67,0.192
5.15,49.78,0.192
5.16,49.90,0.192
5.17,50.02,0.192
5.18,50.13,0.192
5.19,50.25,0.192
5.20,50.37,0.192
5.21,50.49,0.192
5.23,50.60,0.192
5.24,50.72,0.192
5.25,50.84,0.192
5.26,50.95,0.192
5.27,51.07,0.192
5.29,51.19,0.192
5.30,51.30,0.192
5.31,51.42,0.192
5.32,51.54,0.192
5.33,51.65,0.193
5.34,51.77,0.193
5.35,51.89,0.193
5.37,52.00,0.193
5.38,52.12,0.193
5.39,52.24,0.193
5.40,52.35,0.193
5.41,52.47,0.193
5.43,52.59,0.193
5.44,52.70,0.193
5.45,52.82,0.193
5.46,52.94,0.193
5.47,53.06,0.193
5.48,53.17,0.193
5.50,53.29,0.193
5.51,53.41,0.193
5.52,53.52,0.193
5.53,53.64,0.194
5.54,53.75,0.194
5.55,53.87,0.194
5.56,53.99,0.194
5.58,54.11,0.194
5.59,54.22,0.194
5.60,54.34,0.194
5.61,54.46,0.194
5.62,54.57,0.194
5.64,54.69,0.194
5.65,54.81,0.194
5.66,54.92,0.194
5.67,55.04,0.194
5.68,55.16,0.194
5.69,55.27,0.194
5.70,55.39,0.194
5.72,55.51,0.194
5.73,55.63,0.194
5.74,55.74,0.195
5.75,55.86,0.195
5.76,55.97,0.195
5.78,56.09,0.195
5.79,56.21,0.195
5.80,56.32,0.195
5.81,56.44,0.195
5.82,56.56,0.195
5.83,56.68,0.195
5.85,56.79,0.195
5.86,56.91,0.195
5.87,57.03,0.195
5.88,57.14,0.195
5.89,57.26,0.195
5.90,57.38,0.195
5.91,57.49,0.195
5.93,57.61,0.195
5.94,57.73,0.196
5.95,57.84,0.196
5.96,57.96,0.196
5.97,58.08,0.196
5.99,58.19,0.196
6.00,58.31,0.196
6.01,58.43,0.196
6.02,58.54,0.196
6.03,58.66,0.196
6.04,58.78,0.196
6.05,58.89,0.196
6.07,59.01,0.196
6.08,59.13,0.196
6.09,59.24,0.196
6.10,59.36,0.196
6.11,59.48,0.196
6.13,59.59,0.196
6.14,59.71,0.196
6.15,59.83,0.197
6.16,59.95,0.197
6.17,60.06,0.197
6.18,60.18,0.197
6.20,60.29,0.197
6.21,60.41,0.197
6.22,60.53,0.197
6.23,60.65,0.197
6.24,60.76,0.197
6.25,60.88,0.197
6.26,61.00,0.197
6.28,61.11,0.197
6.29,61.23,0.197
6.30,61.35,0.197
6.31,61.46,0.197
6.32,61.58,0.197
6.34,61.70,0.197
6.35,61.81,0.198
6.36,61.93,0.198
6.37,62.05,0.198
6.38,62.16,0.198
6.39,62.28,0.198
6.40,62.40,0.198
6.42,62.51,0.198
6.43,62.63,0.198
6.44,62.75,0.198
6.45,62.86,0.198
6.46,62.98,0.198
6.48,63.10,0.198
6.49,63.22,0.198
6.50,63.33,0.198
6.51,63.45,0.198
6.52,63.57,0.198
6.53,63.68,0.198
6.55,63.80,0.199
6.56,63.92,0.199
6.57,64.03,0.199
6.58,64.15,0.199
6.59,64.27,0.199
6.60,64.38,0.199
6.61,64.50,0.199
6.63,64.62,0.199
6.64,64.73,0.199
6.65,64.85,0.199
6.66,64.97,0.199
6.67,65.08,0.199
6.69,65.20,0.199
6.70,65.32,0.199
6.71,65.43,0.199
6.72,65.55,0.199
6.73,65.67,0.199
6.74,65.79,0.199
6.75,65.90,0.200
6.77,66.02,0.200
6.78,66.14,0.200
6.79,66.25,0.200
6.80,66.37,0.200
6.81,66.49,0.200
6.83,66.60,0.200
6.84,66.72,0.200
6.85,66.84,0.200
6.86,66.95,0.200
6.87,67.07,0.200
6.88,67.19,0.200
6.90,67.30,0.200
6.91,67.42,0.200
6.92,67.54,0.200
6.93,67.65,0.200
6.94,67.77,0.200
6.95,67.89,0.200
6.96,68.00,0.200
6.98,68.12,0.201
6.99,68.24,0.201
7.00,68.35,0.201
7.01,68.47,0.201
7.02,68.59,0.201
7.04,68.71,0.201
7.05,68.82,0.201
7.06,68.94,0.201
7.07,69.05,0.201
7.08,69.17,0.201
7.09,69.29,0.201
7.10,69.40,0.201
7.12,69.52,0.201
7.13,69.64,0.201
7.14,69.76,0.201
7.15,69.87,0.201
7.16,69.99,0.201
7.18,70.11,0.201
7.19,70.22,0.202
7.20,70.34,0.202
7.21,70.46,0.202
7.22,70.57,0.202
7.23,70.69,0.202
7.25,70.81,0.202
7.26,70.92,0.202
7.27,71.04,0.202
7.28,71.16,0.202
7.29,71.27,0.202
7.30,71.39,0.202
7.31,71.51,0.202
7.33,71.62,0.202
7.34,71.74,0.202
7.35,71.86,0.202
7.36,71.97,0.202
7.37,72.09,0.203
7.39,72.21,0.203
7.40,72.32,0.203
7.41,72.44,0.203
7.42,72.56,0.203
7.43,72.67,0.203
7.44,72.79,0.203
7.45,72.91,0.203
7.47,73.02,0.203
7.48,73.14,0.203
7.49,73.26,0.203
7.50,73.37,0.203
7.51,73.49,0.203
7.53,73.61,0.203
7.54,73.73,0.203
7.55,73.84,0.203
7.56,73.96,0.203
7.57,74.08,0.204
7.58,74.19,0.204
7.60,74.31,0.204
7.61,74.43,0.204
7.62,74.54,0.204
7.63,74.66,0.204
7.64,74.78,0.204
7.65,74.89,0.204
7.66,75.01,0.204
7.68,75.13,0.204
7.69,75.24,0.204
7.70,75.36,0.204
7.71,75.48,0.204
7.72,75.59,0.204
7.74,75.71,0.204
7.75,75.83,0.204
7.76,75.95,0.205
7.77,76.06,0.205
7.78,76.18,0.205
7.79,76.29,0.205
7.80,76.41,0.205
7.82,76.53,0.205
7.83,76.65,0.205
7.84,76.76,0.205
7.85,76.88,0.205
7.86,77.00,0.205
7.88,77.11,0.205
7.89,77.23,0.205
7.90,77.35,0.205
7.91,77.46,0.205
7.92,77.58,0.205
7.93,77.70,0.205
7.95,77.81,0.205
7.96,77.93,0.206
7.97,78.05,0.206
7.98,78.16,0.206
7.99,78.28,0.206
8.00,78.40,0.206
8.01,78.51,0.206
8.03,78.63,0.206
8.04,78.75,0.206
8.05,78.86,0.206
8.06,78.98,0.206
8.07,79.10,0.206
8.09,79.21,0.206
8.10,79.33,0.206
8.11,79.45,0.206
8.12,79.57,0.206
8.13,79.68,0.206
8.14,79.80,0.206
8.15,79.92,0.206
8.17,80.03,0.206
8.18,80.15,0.207
8.19,80.27,0.207
8.20,80.38,0.207
8.21,80.50,0.207
8.23,80.62,0.207
8.24,80.73,0.207
8.25,80.85,0.207
8.26,80.97,0.207
8.27,81.08,0.207
8.28,81.20,0.207
8.30,81.32,0.207
8.31,81.43,0.207
8.32,81.55,0.207
8.33,81.67,0.207
8.34,81.78,0.207
8.35,81.90,0.207
8.36,82.02,0.208
8.38,82.13,0.208
8.39,82.25,0.208
8.40,82.37,0.208
8.41,82.48,0.208
8.42,82.60,0.208
8.44,82.72,0.208
8.45,82.83,0.208
8.46,82.95,0.208
8.47,83.07,0.208
8.48,83.18,0.208
8.49,83.30,0.208
8.50,83.42,0.208
8.52,83.54,0.208
8.53,83.65,0.208
8.54,83.77,0.208
8.55,83.88,0.208
8.56,84.00,0.208
8.58,84.12,0.208
8.59,84.24,0.208
8.60,84.35,0.208
8.61,84.47,0.208
8.62,84.59,0.209
8.63,84.70,0.209
8.65,84.82,0.209
8.66,84.94,0.209
8.67,85.05,0.209
8.68,85.17,0.209
8.69,85.29,0.209
8.70,85.40,0.209
8.72,85.52,0.209
8.73,85.64,0.209
8.74,85.75,0.209
8.75,85.87,0.209
8.76,85.99,0.209
8.77,86.10,0.209
8.78,86.22,0.209
8.80,86.34,0.209
8.81,86.45,0.209
8.82,86.57,0.209
8.83,86.69,0.209
8.84,86.80,0.209
8.85,86.92,0.209
8.87,87.04,0.209
8.88,87.16,0.210
8.89,87.27,0.210
8.90,87.39,0.210
8.91,87.51,0.210
8.93,87.62,0.210
8.94,87.74,0.210
8.95,87.86,0.210
8.96,87.97,0.210
8.97,88.09,0.210
8.98,88.21,0.210
9.00,88.32,0.210
9.01,88.44,0.210
9.02,88.56,0.210
9.03,88.67,0.210
9.04,88.79,0.210
9.05,88.91,0.210
9.07,89.02,0.210
9.08,89.14,0.210
9.09,89.26,0.211
9.10,89.37,0.211
9.11,89.49,0.211
9.12,89.61,0.211
9.13,89.72,0.211
9.15,89.84,0.211
9.16,89.96,0.211
9.17,90.07,0.211
9.18,90.19,0.211
9.19,90.31,0.211
9.20,90.42,0.211
9.22,90.54,0.211
9.23,90.66,0.211
9.24,90.77,0.211
9.25,90.89,0.211
9.26,91.01,0.211
9.28,91.12,0.211
9.29,91.24,0.212
9.30,91.36,0.212
9.31,91.48,0.212
9.32,91.59,0.212
9.33,91.71,0.212
9.35,91.83,0.212
9.36,91.94,0.212
9.37,92.06,0.212
9.38,92.18,0.212
9.39,92.29,0.212
9.40,92.41,0.212
9.42,92.53,0.212
9.43,92.64,0.212
9.44,92.76,0.212
9.45,92.88,0.212
9.46,92.99,0.213
9.47,93.11,0.213
9.48,93.23,0.213
9.50,93.34,0.213
9.51,93.46,0.213
9.52,93.58,0.213
9.53,93.69,0.213
9.54,93.81,0.213
9.55,93.93,0.213
9.57,94.04,0.213
9.58,94.16,0.213
9.59,94.28,0.213
9.60,94.39,0.213
9.61,94.51,0.213
9.63,94.63,0.213
9.64,94.74,0.213
9.65,94.86,0.214
9.66,94.98,0.214
9.67,95.10,0.214
9.68,95.21,0.214
9.70,95.33,0.214
9.71,95.45,0.214
9.72,95.56,0.214
9.73,95.68,0.214
9.74,95.80,0.214
9.75,95.91,0.214
9.77,96.03,0.214
9.78,96.15,0.214
9.79,96.26,0.214
9.80,96.38,0.214
9.81,96.50,0.214
9.82,96.61,0.214
9.83,96.73,0.214
9.85,96.85,0.215
9.86,96.96,0.215
9.87,97.08,0.215
9.88,97.20,0.215
9.89,97.31,0.215
9.90,97.43,0.215
9.92,97.55,0.215
9.93,97.66,0.215
9.94,97.78,0.215
9.95,97.90,0.215
9.96,98.01,0.215
9.98,98.13,0.215
9.99,98.25,0.215
10.00,98.36,0.215
10.01,98.48,0.215
10.02,98.60,0.215
10.03,98.72,0.215
10.05,98.83,0.216
10.06,98.95,0.216
10.07,99.07,0.216
10.08,99.18,0.216
10.09,99.30,0.216
10.10,99.42,0.216
10.12,99.53,0.216
10.13,99.65,0.216
10.14,99.77,0.216
10.15,99.88,0.216
10.16,100.00,0.216
10.17,100.12,0.216
10.18,100.23,0.216
10.20,100.35,0.216
10.21,100.47,0.216
10.22,100.58,0.216
10.23,100.70,0.217
10.24,100.82,0.217
10.25,100.93,0.217
10.27,101.05,0.217
10.28,101.17,0.217
10.29,101.28,0.217
10.30,101.40,0.217
10.31,101.52,0.217
10.33,101.63,0.217
10.34,101.75,0.217
10.35,101.87,0.217
10.36,101.98,0.217
10.37,102.10,0.217
10.38,102.22,0.217
10.40,102.34,0.217
10.41,102.45,0.217
10.42,102.57,0.217
10.43,102.68,0.218
10.44,102.80,0.218
10.45,102.92,0.218
10.47,103.04,0.218
10.48,103.15,0.218
10.49,103.27,0.218
10.50,103.39,0.218
10.51,103.50,0.218
10.52,103.62,0.218
10.53,103.74,0.218
10.55,103.85,0.218
10.56,103.97,0.218
10.57,104.09,0.218
10.58,104.20,0.218
10.59,104.32,0.218
10.60,104.44,0.218
10.62,104.55,0.218
10.63,104.67,0.218
10.64,104.79,0.218
10.65,104.90,0.219
10.66,105.02,0.219
10.68,105.14,0.219
10.69,105.25,0.219
10.70,105.37,0.219
10.71,105.49,0.219
10.72,105.61,0.219
10.73,105.72,0.219
10.75,105.84,0.219
10.76,105.95,0.219
10.77,106.07,0.219
10.78,106.19,0.219
10.79,106.31,0.219
10.80,106.42,0.219
10.82,106.54,0.219
10.83,106.66,0.219
10.84,106.77,0.219
10.85,106.89,0.219
10.86,107.00,0.220
10.87,107.12,0.220
10.88,107.24,0.220
10.90,107.36,0.220
10.91,107.47,0.220
10.92,107.59,0.220
10.93,107.71,0.220
10.94,107.82,0.220
10.95,107.94,0.220
10.97,108.06,0.220
10.98,108.17,0.220
10.99,108.29,0.220
11.00,108.41,0.220
11.01,108.52,0.220
11.03,108.64,0.220
11.04,108.76,0.220
11.05,108.87,0.220
11.06,108.99,0.220
11.07,109.11,0.221
11.08,109.22,0.221
11.10,109.34,0.221
11.11,109.46,0.221
11.12,109.57,0.221
11.13,109.69,0.221
11.14,109.81,0.221
11.15,109.93,0.221
11.17,110.04,0.221
11.18,110.16,0.221
11.19,110.27,0.221
11.20,110.39,0.221
11.21,110.51,0.221
11.22,110.62,0.221
11.23,110.74,0.221
11.25,110.86,0.221
11.26,110.98,0.221
11.27,111.09,0.221
11.28,111.21,0.222
11.29,111.33,0.222
11.30,111.44,0.222
11.32,111.56,0.222
11.33,111.68,0.222
11.34,111.79,0.222
11.35,111.91,0.222
11.36,112.03,0.222
11.38,112.14,0.222
11.39,112.26,0.222
11.40,112.38,0.222
11.41,112.49,0.222
11.42,112.61,0.222
11.43,112.73,0.222
11.45,112.84,0.222
11.46,112.96,0.222
11.47,113.08,0.222
11.48,113.19,0.222
11.49,113.31,0.222
11.50,113.43,0.223
11.52,113.54,0.223
11.53,113.66,0.223
11.54,113.78,0.223
11.55,113.89,0.223
11.56,114.01,0.223
11.57,114.13,0.223
11.58,114.25,0.223
11.60,114.36,0.223
11.61,114.48,0.223
11.62,114.59,0.223
11.63,114.71,0.223
11.64,114.83,0.223
11.65,114.95,0.223
11.67,115.06,0.223
11.68,115.18,0.223
11.69,115.29,0.223
11.70,115.41,0.223
11.71,115.53,0.223
11.73,115.65,0.224
11.74,115.76,0.224
11.75,115.88,0.224
11.76,116.00,0.224
11.77,116.11,0.224
11.78,116.23,0.224
11.80,116.35,0.224
11.81,116.46,0.224
11.82,116.58,0.224
11.83,116.70,0.224
11.84,116.81,0.224
11.85,116.93,0.224
11.87,117.05,0.224
11.88,117.16,0.224
11.89,117.28,0.224
11.90,117.40,0.224
11.91,117.51,0.224
11.92,117.63,0.224
11.93,117.75,0.225
11.95,117.87,0.225
11.96,117.98,0.225
11.97,118.10,0.225
11.98,118.21,0.225
11.99,118.33,0.225
12.00,118.45,0.225
12.02,118.57,0.225
12.03,118.68,0.225
12.04,118.80,0.225
12.05,118.92,0.225
12.06,119.03,0.225
12.08,119.15,0.225
12.09,119.26,0.225
12.10,119.38,0.225
12.11,119.50,0.225
12.12,119.61,0.225
12.13,119.73,0.225
12.15,119.85,0.226
12.16,119.96,0.226
12.17,120.08,0.226
12.18,120.20,0.226
12.19,120.32,0.226
12.20,120.43,0.226
12.22,120.55,0.226
12.23,120.67,0.226
12.24,120.78,0.226
12.25,120.90,0.226
12.26,121.02,0.226
12.27,121.13,0.226
12.28,121.25,0.226
12.30,121.37,0.226
12.31,121.48,0.226
12.32,121.60,0.226
12.33,121.72,0.227
12.34,121.83,0.227
12.35,121.95,0.227
12.37,122.07,0.227
12.38,122.18,0.227
12.39,122.30,0.227
12.40,122.42,0.227
12.41,122.54,0.227
12.43,122.65,0.227
12.44,122.77,0.227
12.45,122.89,0.227
12.46,123.01,0.227
12.47,123.12,0.227
12.48,123.24,0.227
12.50,123.36,0.228
12.51,123.47,0.228
12.52,123.59,0.228
12.53,123.71,0.228
12.54,123.83,0.228
12.55,123.94,0.228
12.57,124.06,0.228
12.58,124.18,0.228
12.59,124.29,0.228
12.60,124.41,0.228
12.61,124.52,0.228
12.62,124.64,0.228
12.63,124.76,0.228
12.65,124.87,0.228
12.66,124.99,0.228
12.67,125.11,0.228
12.68,125.22,0.228
12.69,125.34,0.228
12.70,125.46,0.228
12.72,125.57,0.229
12.73,125.69,0.229
12.74,125.81,0.229
12.75,125.92,0.229
12.76,126.04,0.229
12.78,126.16,0.229
12.79,126.27,0.229
12.80,126.39,0.229
12.81,126.51,0.229
12.82,126.62,0.229
12.83,126.74,0.229
12.85,126.86,0.229
12.86,126.98,0.229
12.87,127.09,0.229
12.88,127.21,0.229
12.89,127.33,0.229
12.90,127.44,0.229
12.92,127.56,0.229
12.93,127.68,0.229
12.94,127.79,0.229
12.95,127.91,0.229
12.96,128.02,0.229
12.97,128.14,0.229
12.98,128.26,0.229
13.00,128.37,0.229
13.01,128.49,0.229
13.02,128.61,0.229
13.03,128.73,0.229
13.04,128.84,0.229
13.05,128.96,0.230
13.07,129.08,0.230
13.08,129.19,0.230
13.09,129.31,0.230
13.10,129.43,0.230
13.11,129.54,0.230
13.13,129.66,0.230
13.14,129.77,0.230
13.15,129.89,0.230
13.16,130.01,0.230
13.17,130.13,0.230
13.18,130.24,0.230
13.20,130.36,0.230
13.21,130.48,0.230
13.22,130.59,0.230
13.23,130.71,0.230
13.24,130.83,0.230
13.25,130.94,0.231
13.27,131.06,0.231
13.28,131.17,0.231
13.29,131.29,0.231
13.30,131.41,0.231
13.31,131.52,0.231
13.32,131.64,0.231
13.33,131.76,0.231
13.35,131.88,0.231
13.36,131.99,0.231
13.37,132.11,0.231
13.38,132.23,0.231
13.39,132.34,0.232
13.40,132.46,0.232
13.42,132.58,0.232
13.43,132.69,0.232
13.44,132.81,0.232
13.45,132.93,0.232
13.46,133.04,0.232
13.48,133.16,0.232
13.49,133.28,0.233
13.50,133.39,0.233
13.51,133.51,0.233
13.52,133.63,0.233
13.53,133.74,0.233
13.55,133.86,0.233
13.56,133.98,0.233
13.57,134.09,0.233
13.58,134.21,0.233
13.59,134.33,0.233
13.60,134.44,0.234
13.62,134.56,0.234
13.63,134.68,0.234
13.64,134.79,0.234
13.65,134.91,0.234
13.66,135.03,0.234
13.67,135.14,0.235
13.68,135.26,0.235
13.70,135.38,0.235
13.71,135.49,0.235
13.72,135.61,0.236
13.73,135.73,0.236
13.74,135.84,0.236
13.75,135.96,0.237
13.77,136.08,0.237
13.78,136.19,0.237
13.79,136.31,0.238
13.80,136.43,0.238
13.81,136.54,0.238
13.83,136.66,0.239
13.84,136.77,0.240
13.85,136.89,0.241
13.86,137.01,0.241
13.87,137.13,0.242
13.88,137.24,0.242
13.90,137.36,0.243
13.91,137.47,0.244
13.92,137.59,0.245
13.93,137.71,0.246
13.94,137.82,0.247
13.95,137.94,0.249
13.97,138.05,0.250
13.98,138.17,0.252
13.99,138.29,0.254
14.00,138.40,0.256
14.01,138.52,0.257
14.02,138.63,0.260
14.03,138.75,0.262
14.05,138.87,0.264
14.06,138.98,0.267
14.07,139.10,0.270
14.08,139.21,0.272
14.09,139.33,0.277
14.10,139.44,0.280
14.12,139.56,0.285
14.13,139.67,0.288
14.14,139.79,0.295
14.15,139.90,0.299
14.16,140.02,0.307
14.18,140.13,0.313
14.19,140.24,0.321
14.20,140.36,0.330
14.21,140.47,0.340
14.22,140.58,0.351
14.23,140.69,0.364
14.25,140.80,0.379
14.26,140.92,0.394
14.27,141.02,0.412
14.28,141.13,0.432
14.29,141.24,0.454
14.30,141.35,0.478
14.32,141.46,0.504
14.33,141.56,0.533
14.34,141.66,0.564
14.35,141.77,0.598
14.36,141.87,0.634
14.37,141.97,0.675
14.38,142.07,0.717
14.40,142.16,0.759
14.41,142.26,0.809
14.42,142.35,0.859
14.43,142.45,0.906
14.44,142.54,0.957
14.45,142.63,1.006
14.47,142.72,1.055
14.48,142.81,1.103
14.49,142.90,1.150
14.50,142.99,1.196
14.51,143.08,1.243
14.53,143.17,1.292
14.54,143.26,1.344
14.55,143.34,1.399
14.56,143.43,1.460
14.57,143.52,1.524
14.58,143.60,1.591
14.60,143.68,1.661
14.61,143.77,1.731
14.62,143.85,1.798
14.63,143.93,1.860
14.64,144.01,1.917
14.65,144.09,1.971
14.67,144.17,2.026
14.68,144.25,2.077
14.69,144.34,2.122
14.70,144.42,2.158
14.71,144.51,2.179
14.72,144.61,2.191
14.73,144.70,2.200
14.75,144.80,2.207
14.76,144.91,2.219
14.77,145.01,2.239
14.78,145.11,2.270
14.79,145.21,2.321
14.80,145.31,2.393
14.82,145.40,2.462
14.83,145.49,2.530
14.84,145.58,2.593
14.85,145.66,2.642
14.86,145.75,2.680
14.88,145.84,2.706
14.89,145.93,2.719
14.90,146.03,2.722
14.91,146.13,2.720
14.92,146.24,2.709
14.93,146.35,2.691
14.95,146.46,2.662
14.96,146.58,2.617
14.97,146.71,2.553
14.98,146.84,2.472
14.99,146.98,2.373
15.00,147.13,2.264
15.02,147.28,2.145
15.03,147.44,2.023
15.04,147.61,1.897
15.05,147.78,1.770
15.06,147.96,1.645
15.07,148.14,1.520
15.08,148.32,1.400
15.10,148.50,1.284
15.11,148.68,1.176
15.12,148.86,1.071
15.13,149.04,0.975
15.14,149.22,0.887
15.15,149.39,0.812
15.17,149.57,0.746
15.18,149.73,0.692
15.19,149.89,0.646
15.20,150.05,0.608
15.21,150.21,0.574
15.23,150.36,0.544
15.24,150.50,0.517
15.25,150.65,0.494
15.26,150.79,0.469
15.27,150.93,0.455
15.28,151.06,0.438
15.30,151.20,0.420
15.31,151.33,0.408
15.32,151.46,0.396
15.33,151.59,0.385
15.34,151.72,0.375
15.35,151.84,0.366
15.37,151.97,0.359
15.38,152.09,0.351
15.39,152.22,0.346
15.40,152.34,0.340
15.41,152.46,0.335
15.42,152.58,0.331
15.43,152.71,0.326
15.45,152.83,0.324
15.46,152.95,0.320
15.47,153.07,0.317
15.48,153.19,0.314
15.49,153.31,0.312
15.50,153.42,0.310
15.52,153.54,0.308
15.53,153.66,0.306
15.54,153.78,0.305
15.55,153.90,0.304
15.56,154.02,0.303
15.58,154.13,0.302
15.59,154.25,0.301
15.60,154.37,0.300
15.61,154.49,0.299
15.62,154.60,0.298
15.63,154.72,0.298
15.65,154.84,0.298
15.66,154.96,0.297
15.67,155.08,0.297
15.68,155.19,0.297
15.69,155.31,0.297
15.70,155.43,0.296
15.72,155.54,0.296
15.73,155.66,0.296
15.74,155.78,0.296
15.75,155.89,0.296
15.76,156.01,0.296
15.77,156.13,0.295
15.78,156.25,0.295
15.80,156.36,0.295
15.81,156.48,0.295
15.82,156.60,0.295
15.83,156.71,0.295
15.84,156.83,0.295
15.85,156.95,0.295
15.87,157.06,0.295
15.88,157.18,0.295
15.89,157.30,0.295
15.90,157.41,0.295
15.91,157.53,0.294
15.93,157.65,0.294
15.94,157.76,0.294
15.95,157.88,0.294
15.96,158.00,0.294
15.97,158.11,0.294
15.98,158.23,0.294
16.00,158.35,0.294
16.01,158.46,0.294
16.02,158.58,0.294
16.03,158.70,0.294
16.04,158.81,0.294
16.05,158.93,0.294
16.07,159.05,0.294
16.08,159.17,0.294
16.09,159.28,0.294
16.10,159.40,0.294
16.11,159.52,0.294
16.12,159.63,0.294
16.13,159.75,0.294
16.15,159.87,0.293
16.16,159.98,0.293
16.17,160.10,0.293
16.18,160.22,0.293
16.19,160.33,0.293
16.20,160.45,0.293
16.22,160.56,0.293
16.23,160.68,0.293
16.24,160.80,0.293
16.25,160.91,0.293
16.26,161.03,0.293
16.28,161.15,0.293
16.29,161.27,0.293
16.30,161.38,0.293
16.31,161.50,0.293
16.32,161.62,0.293
16.33,161.73,0.293
16.35,161.85,0.293
16.36,161.97,0.293
16.37,162.08,0.293
16.38,162.20,0.293
16.39,162.32,0.293
16.40,162.43,0.293
16.42,162.55,0.293
16.43,162.67,0.293
16.44,162.78,0.293
16.45,162.90,
16.46,163.02,
16.47,163.13,
16.48,163.25,
16.50,163.37,
16.50,,

[step]
Ramp 10.00 °C/min to 0.00 °C
Time,Temperature,Heat Flow (Normalized)
min,°C,W/g
18.51,165.11,-0.020
18.52,165.11,-0.020
18.53,165.11,-0.020
18.54,165.11,-0.020
18.55,165.10,-0.020
18.57,165.09,-0.020
18.58,165.08,-0.020
18.59,165.06,-0.020
18.60,165.02,-0.023
18.61,164.98,-0.034
18.62,164.94,-0.045
18.63,164.88,-0.061
18.65,164.82,-0.079
18.66,164.75,-0.098
18.67,164.67,-0.119
18.68,164.59,-0.140
18.69,164.51,-0.157
18.71,164.42,-0.175
18.72,164.33,-0.190
18.73,164.24,-0.205
18.74,164.15,-0.217
18.75,164.05,-0.228
18.76,163.95,-0.238
18.78,163.85,-0.246
18.79,163.75,-0.255
18.80,163.65,-0.261
18.81,163.54,-0.268
18.82,163.44,-0.274
18.83,163.33,-0.280
18.84,163.23,-0.286
18.86,163.12,-0.290
18.87,163.01,-0.294
18.88,162.90,-0.297
18.89,162.79,-0.300
18.90,162.68,-0.303
18.92,162.57,-0.307
18.93,162.45,-0.308
18.94,162.34,-0.311
18.95,162.23,-0.312
18.96,162.12,-0.314
18.97,162.00,-0.315
18.98,161.89,-0.316
19.00,161.78,-0.318
19.01,161.67,-0.318
19.02,161.55,-0.319
19.03,161.44,-0.320
19.04,161.32,-0.321
19.06,161.21,-0.322
19.07,161.10,-0.323
19.08,160.98,-0.323
19.09,160.87,-0.323
19.10,160.75,-0.324
19.11,160.64,-0.324
19.13,160.52,-0.324
19.14,160.41,-0.325
19.15,160.29,-0.325
19.16,160.18,-0.326
19.17,160.06,-0.326
19.18,159.95,-0.326
19.19,159.83,-0.326
19.21,159.72,-0.326
19.22,159.60,-0.327
19.23,159.49,-0.327
19.24,159.37,-0.327
19.25,159.26,-0.327
19.27,159.14,-0.327
19.28,159.03,-0.327
19.29,158.91,-0.328
19.30,158.79,-0.328
19.31,158.68,-0.328
19.32,158.56,-0.328
19.33,158.45,-0.328
19.35,158.33,-0.328
19.36,158.22,-0.328
19.37,158.10,-0.328
19.38,157.98,-0.328
19.39,157.87,-0.329
19.41,157.75,-0.329
19.42,157.64,-0.329
19.43,157.52,-0.329
19.44,157.40,-0.329
19.45,157.29,-0.329
19.46,157.17,-0.329
19.48,157.06,-0.329
19.49,156.94,-0.329
19.50,156.83,-0.329
19.51,156.71,-0.329
19.52,156.59,-0.329
19.53,156.48,-0.329
19.54,156.36,-0.329
19.56,156.25,-0.329
19.57,156.13,-0.329
19.58,156.01,-0.329
19.59,155.90,-0.329
19.60,155.78,-0.330
19.62,155.66,-0.330
19.63,155.55,-0.330
19.64,155.43,-0.330
19.65,155.32,-0.330
19.66,155.20,-0.330
19.67,155.08,-0.330
19.68,154.97,-0.330
19.70,154.85,-0.330
19.71,154.74,-0.330
19.72,154.62,-0.330
19.73,154.50,-0.330
19.74,154.39,-0.330
19.76,154.27,-0.330
19.77,154.15,-0.330
19.78,154.04,-0.330
19.79,153.92,-0.330
19.80,153.80,-0.330
19.81,153.69,-0.330
19.83,153.57,-0.330
19.84,153.46,-0.330
19.85,153.34,-0.330
19.86,153.22,-0.330
19.87,153.11,-0.330
19.88,152.99,-0.330
19.89,152.88,-0.330
19.91,152.76,-0.330
19.92,152.64,-0.330
19.93,152.53,-0.330
19.94,152.41,-0.330
19.95,152.29,-0.330
19.97,152.18,-0.330
19.98,152.06,-0.330
19.99,151.94,-0.330
20.00,151.83,-0.330
20.01,151.71,-0.330
20.02,151.59,-0.330
20.03,151.48,-0.330
20.05,151.36,-0.330
20.06,151.24,-0.330
20.07,151.13,-0.330
20.08,151.01,-0.330
20.09,150.90,-0.329
20.11,150.78,-0.329
20.12,150.66,-0.329
20.13,150.55,-0.329
20.14,150.43,-0.329
20.15,150.31,-0.329
20.16,150.20,-0.329
20.18,150.08,-0.329
20.19,149.96,-0.329
20.20,149.85,-0.329
20.21,149.73,-0.329
20.22,149.62,-0.329
20.23,149.50,-0.329
20.24,149.38,-0.329
20.26,149.27,-0.329
20.27,149.15,-0.329
20.28,149.03,-0.329
20.29,148.92,-0.329
20.30,148.80,-0.329
20.32,148.68,-0.329
20.33,148.57,-0.329
20.34,148.45,-0.329
20.35,148.33,-0.329
20.36,148.22,-0.329
20.37,148.10,-0.329
20.38,147.98,-0.329
20.40,147.87,-0.328
20.41,147.75,-0.328
20.42,147.63,-0.328
20.43,147.52,-0.328
20.44,147.40,-0.328
20.46,147.29,-0.328
20.47,147.17,-0.328
20.48,147.05,-0.328
20.49,146.94,-0.328
20.50,146.82,-0.328
20.51,146.70,-0.328
20.53,146.59,-0.328
20.54,146.47,-0.328
20.55,146.35,-0.328
20.56,146.24,-0.328
20.57,146.12,-0.328
20.58,146.00,-0.328
20.59,145.89,-0.328
20.61,145.77,-0.328
20.62,145.65,-0.328
20.63,145.54,-0.328
20.64,145.42,-0.327
20.65,145.30,-0.327
20.67,145.19,-0.327
20.68,145.07,-0.327
20.69,144.96,-0.327
20.70,144.84,-0.327
20.71,144.72,-0.327
20.72,144.61,-0.327
20.73,144.49,-0.327
20.75,144.37,-0.327
20.76,144.26,-0.327
20.77,144.14,-0.327
20.78,144.02,-0.327
20.79,143.91,-0.327
20.81,143.79,-0.327
20.82,143.68,-0.327
20.83,143.56,-0.327
20.84,143.44,-0.327
20.85,143.33,-0.327
20.86,143.21,-0.326
20.88,143.09,-0.326
20.89,142.98,-0.326
20.90,142.86,-0.326
20.91,142.74,-0.326
20.92,142.63,-0.325
20.93,142.51,-0.325
20.94,142.40,-0.325
20.96,142.28,-0.325
20.97,142.16,-0.325
20.98,142.04,-0.325
20.99,141.93,-0.325
21.00,141.81,-0.326
21.02,141.69,-0.326
21.03,141.58,-0.326
21.04,141.46,-0.326
21.05,141.34,-0.326
21.06,141.23,-0.326
21.07,141.11,-0.326
21.08,140.99,-0.326
21.10,140.88,-0.326
21.11,140.76,-0.326
21.12,140.64,-0.325
21.13,140.53,-0.325
21.14,140.41,-0.325
21.16,140.29,-0.325
21.17,140.18,-0.325
21.18,140.06,-0.325
21.19,139.95,-0.325
21.20,139.83,-0.325
21.21,139.71,-0.325
21.23,139.60,-0.325
21.24,139.48,-0.325
21.25,139.36,-0.325
21.26,139.25,-0.325
21.27,139.13,-0.325
21.28,139.01,-0.325
21.29,138.90,-0.325
21.31,138.78,-0.325
21.32,138.66,-0.325
21.33,138.55,-0.325
21.34,138.43,-0.325
21.35,138.31,-0.324
21.37,138.20,-0.324
21.38,138.08,-0.324
21.39,137.96,-0.324
21.40,137.85,-0.324
21.41,137.73,-0.324
21.42,137.61,-0.324
21.43,137.50,-0.324
21.45,137.38,-0.324
21.46,137.26,-0.324
21.47,137.15,-0.324
21.48,137.03,-0.324
21.49,136.91,-0.324
21.51,136.80,-0.324
21.52,136.68,-0.324
21.53,136.57,-0.324
21.54,136.45,-0.324
21.55,136.33,-0.323
21.56,136.22,-0.323
21.58,136.10,-0.323
21.59,135.98,-0.323
21.60,135.87,-0.323
21.61,135.75,-0.323
21.62,135.63,-0.323
21.63,135.52,-0.323
21.64,135.40,-0.323
21.66,135.28,-0.323
21.67,135.17,-0.323
21.68,135.05,-0.323
21.69,134.93,-0.323
21.70,134.82,-0.323
21.72,134.70,-0.323
21.73,134.59,-0.323
21.74,134.47,-0.323
21.75,134.35,-0.323
21.76,134.24,-0.323
21.77,134.12,-0.323
21.78,134.00,-0.322
21.80,133.89,-0.322
21.81,133.77,-0.322
21.82,133.65,-0.322
21.83,133.54,-0.322
21.84,133.42,-0.322
21.86,133.30,-0.322
21.87,133.19,-0.322
21.88,133.07,-0.322
21.89,132.95,-0.322
21.90,132.84,-0.322
21.91,132.72,-0.322
21.93,132.60,-0.322
21.94,132.49,-0.322
21.95,132.37,-0.322
21.96,132.25,-0.322
21.97,132.14,-0.322
21.98,132.02,-0.322
21.99,131.90,-0.322
22.01,131.79,-0.322
22.02,131.67,-0.321
22.03,131.56,-0.321
22.04,131.44,-0.321
22.05,131.32,-0.321
22.07,131.21,-0.321
22.08,131.09,-0.321
22.09,130.97,-0.321
22.10,130.86,-0.321
22.11,130.74,-0.321
22.12,130.62,-0.321
22.13,130.51,-0.321
22.15,130.39,-0.321
22.16,130.27,-0.321
22.17,130.16,-0.321
22.18,130.04,-0.321
22.19,129.92,-0.321
22.21,129.81,-0.321
22.22,129.69,-0.321
22.23,129.57,-0.321
22.24,129.46,-0.321
22.25,129.34,-0.320
22.26,129.23,-0.320
22.28,129.11,-0.320
22.29,128.99,-0.320
22.30,128.88,-0.320
22.31,128.76,-0.320
22.32,128.64,-0.320
22.33,128.53,-0.320
22.34,128.41,-0.320
22.36,128.29,-0.320
22.37,128.18,-0.320
22.38,128.06,-0.320
22.39,127.94,-0.320
22.40,127.83,-0.320
22.42,127.71,-0.320
22.43,127.59,-0.320
22.44,127.48,-0.320
22.45,127.36,-0.320
22.46,127.24,-0.320
22.47,127.13,-0.320
22.48,127.01,-0.320
22.50,126.89,-0.320
22.51,126.78,-0.320
22.52,126.66,-0.320
22.53,126.54,-0.320
22.54,126.43,-0.320
22.56,126.31,-0.320
22.57,126.19,-0.319
22.58,126.08,-0.319
22.59,125.96,-0.319
22.60,125.84,-0.319
22.61,125.73,-0.319
22.63,125.61,-0.319
22.64,125.49,-0.319
22.65,125.38,-0.319
22.66,125.26,-0.319
22.67,125.14,-0.319
22.68,125.03,-0.319
22.69,124.91,-0.319
22.71,124.79,-0.319
22.72,124.68,-0.319
22.73,124.56,-0.319
22.74,124.44,-0.319
22.75,124.33,-0.319
22.77,124.21,-0.319
22.78,124.09,-0.319
22.79,123.98,-0.319
22.80,123.86,-0.319
22.81,123.74,-0.319
22.82,123.63,-0.319
22.83,123.51,-0.318
22.85,123.39,-0.318
22.86,123.28,-0.318
22.87,123.16,-0.318
22.88,123.04,-0.318
22.89,122.93,-0.318
22.91,122.81,-0.318
22.92,122.69,-0.318
22.93,122.58,-0.318
22.94,122.46,-0.318
22.95,122.35,-0.318
22.96,122.23,-0.318
22.98,122.11,-0.318
22.99,122.00,-0.318
23.00,121.88,-0.318
23.01,121.76,-0.318
23.02,121.65,-0.318
23.03,121.53,-0.318
23.04,121.41,-0.318
23.06,121.30,-0.317
23.07,121.18,-0.317
23.08,121.06,-0.317
23.09,120.95,-0.317
23.10,120.83,-0.317
23.12,120.71,-0.317
23.13,120.60,-0.317
23.14,120.48,-0.317
23.15,120.36,-0.317
23.16,120.25,-0.317
23.17,120.13,-0.317
23.18,120.02,-0.317
23.20,119.90,-0.317
23.21,119.78,-0.317
23.22,119.67,-0.317
23.23,119.55,-0.317
23.24,119.43,-0.317
23.26,119.32,-0.317
23.27,119.20,-0.316
23.28,119.08,-0.316
23.29,118.97,-0.316
23.30,118.85,-0.316
23.31,118.73,-0.316
23.33,118.62,-0.316
23.34,118.50,-0.316
23.35,118.38,-0.316
23.36,118.27,-0.316
23.37,118.15,-0.316
23.38,118.04,-0.316
23.39,117.92,-0.316
23.41,117.80,-0.316
23.42,117.69,-0.316
23.43,117.57,-0.316
23.44,117.45,-0.316
23.45,117.34,-0.316
23.47,117.22,-0.316
23.48,117.10,-0.316
23.49,116.99,-0.315
23.50,116.87,-0.315
23.51,116.75,-0.315
23.52,116.64,-0.315
23.53,116.52,-0.315
23.55,116.40,-0.315
[...]
69.45,27.45,-0.212
69.46,27.34,-0.212
69.47,27.22,-0.212
69.49,27.10,-0.211
69.50,26.99,-0.211
69.51,26.87,-0.211
69.52,26.75,-0.211
69.53,26.64,-0.211
69.54,26.52,-0.210
69.55,26.40,-0.210
69.57,26.29,-0.210
69.58,26.17,-0.210
69.59,26.05,-0.210
69.60,25.94,-0.210
69.61,25.82,-0.209
69.63,25.70,-0.209
69.64,25.59,-0.209
69.65,25.47,-0.209
69.66,25.35,-0.209
69.67,25.24,-0.208
69.68,25.12,-0.208
69.70,25.01,-0.208
69.71,24.89,-0.207
69.72,24.77,-0.207
69.73,24.66,-0.207
69.74,24.54,-0.207
69.75,24.42,-0.207
69.76,24.31,-0.206
69.78,24.19,-0.206
69.79,24.07,-0.206
69.80,23.96,-0.206
69.81,23.84,-0.206
69.82,23.72,-0.205
69.84,23.61,-0.205
69.85,23.49,-0.205
69.86,23.37,-0.205
69.87,23.26,-0.205
69.88,23.14,-0.205
69.89,23.03,-0.204
69.90,22.91,-0.204
69.92,22.79,-0.204
69.93,22.67,-0.204
69.94,22.56,-0.203
69.95,22.44,-0.203
69.96,22.32,-0.203
69.98,22.21,-0.203
69.99,22.09,-0.203
70.00,21.97,-0.203
70.01,21.86,-0.202
70.02,21.74,-0.202
70.03,21.62,-0.202
70.05,21.51,-0.202
70.06,21.39,-0.202
70.07,21.27,-0.201
70.08,21.16,-0.201
70.09,21.04,-0.201
70.10,20.92,-0.201
70.11,20.81,-0.201
70.13,20.69,-0.201
70.14,20.57,-0.200
70.15,20.46,-0.200
70.16,20.34,-0.200
70.17,20.22,-0.200
70.19,20.11,-0.200
70.20,19.99,-0.199
70.21,19.87,-0.199
70.22,19.76,-0.199
70.23,19.64,-0.199
70.24,19.52,-0.199
70.25,19.41,-0.199
70.27,19.29,-0.199
70.28,19.18,-0.198
70.29,19.06,-0.198
70.30,18.94,-0.198
70.31,18.83,-0.198
70.33,18.71,-0.198
70.34,18.59,-0.197
70.35,18.47,-0.197
70.36,18.36,-0.197
70.37,18.24,-0.197
70.38,18.13,-0.197
70.40,18.01,-0.197
70.41,17.89,-0.197
70.42,17.77,-0.196
70.43,17.66,-0.196
70.44,17.54,-0.196
70.45,17.43,-0.196
70.46,17.31,-0.196
70.48,17.19,-0.196
70.49,17.08,-0.195
70.50,16.96,-0.195
70.51,16.84,-0.195
70.52,16.73,-0.195
70.54,16.61,-0.195
70.55,16.49,-0.195
70.56,16.38,-0.195
70.57,16.26,-0.194
70.58,16.14,-0.194
70.59,16.03,-0.194
70.60,15.91,-0.194
70.62,15.79,-0.194
70.63,15.68,-0.193
70.64,15.56,-0.193
70.65,15.44,-0.193
70.66,15.33,-0.193
70.68,15.21,-0.193
70.69,15.09,-0.193
70.70,14.98,-0.193
70.71,14.86,-0.192
70.72,14.75,-0.192
70.73,14.63,-0.192
70.75,14.51,-0.192
70.76,14.40,-0.192
70.77,14.28,-0.192
70.78,14.16,-0.192
70.79,14.05,-0.191
70.80,13.93,-0.191
70.81,13.81,-0.191
70.83,13.70,-0.191
70.84,13.58,-0.191
70.85,13.46,-0.191
70.86,13.35,-0.191
70.87,13.23,-0.190
70.89,13.11,-0.190
70.90,13.00,-0.190
70.91,12.88,-0.190
70.92,12.76,-0.190
70.93,12.65,-0.190
70.94,12.53,-0.190
70.95,12.41,-0.190
70.97,12.30,-0.189
70.98,12.18,-0.189
70.99,12.06,-0.189
71.00,11.95,-0.189
71.01,11.83,-0.189
71.03,11.72,-0.188
71.04,11.60,-0.188
71.05,11.48,-0.188
71.06,11.37,-0.188
71.07,11.25,-0.188
71.08,11.13,-0.187
71.10,11.02,-0.187
71.11,10.90,-0.187
71.12,10.78,-0.187
71.13,10.67,-0.187
71.14,10.55,-0.187
71.15,10.44,-0.187
71.16,10.32,-0.187
71.18,10.20,-0.186
71.19,10.09,-0.186
71.20,9.97,-0.186
71.21,9.85,-0.186
71.22,9.74,-0.186
71.24,9.62,-0.186
71.25,9.51,-0.186
71.26,9.39,-0.186
71.27,9.27,-0.185
71.28,9.15,-0.185
71.29,9.04,-0.185
71.30,8.92,-0.185
71.32,8.80,-0.185
71.33,8.69,-0.184
71.34,8.57,-0.184
71.35,8.46,-0.184
71.36,8.34,-0.184
71.38,8.22,-0.184
71.39,8.11,-0.184
71.40,7.99,-0.184
71.41,7.87,-0.184
71.42,7.76,-0.184
71.43,7.64,-0.183
71.45,7.52,-0.183
71.46,7.41,-0.183
71.47,7.29,-0.183
71.48,7.17,-0.183
71.49,7.06,-0.183
71.50,6.94,-0.182
71.51,6.82,-0.182
71.53,6.71,-0.182
71.54,6.59,-0.182
71.55,6.47,-0.182
71.56,6.36,-0.182
71.57,6.24,-0.182
71.59,6.12,-0.182
71.60,6.01,-0.182
71.61,5.89,-0.182
71.62,5.78,-0.181
71.63,5.66,-0.181
71.64,5.54,-0.181
71.65,5.43,-0.181
71.67,5.31,-0.181
71.68,5.19,-0.181
71.69,5.08,-0.181
71.70,4.96,-0.180
71.71,4.84,-0.180
71.73,4.72,-0.180
71.74,4.61,-0.180
71.75,4.49,-0.180
71.76,4.37,-0.180
71.77,4.26,-0.180
71.78,4.14,-0.180
71.80,4.02,-0.179
71.81,3.91,-0.179
71.82,3.79,-0.179
71.83,3.67,-0.179
71.84,3.56,-0.179
71.85,3.44,-0.179
71.86,3.32,-0.179
71.88,3.21,-0.179
71.89,3.09,-0.179
71.90,2.97,-0.178
71.91,2.86,-0.178
71.92,2.74,-0.178
71.94,2.62,-0.178
71.95,2.51,-0.178
71.96,2.39,
71.97,2.27,
71.98,2.16,
71.99,2.04,
72.00,,
72.01,,

[step]
Ramp 10.00 °C/min to 30.00 °C
Time,Temperature,Heat Flow (Normalized)
min,°C,W/g
74.01,0.11,-0.010
74.01,0.11,-0.010
74.01,0.11,-0.010
74.02,0.11,-0.010
74.02,0.11,-0.010
74.03,0.11,-0.010
74.03,0.11,-0.010
74.03,0.11,-0.010
74.04,0.11,-0.010
74.04,0.11,-0.010
74.04,0.11,-0.010
74.05,0.11,-0.010
74.05,0.12,-0.010
74.05,0.12,-0.010
74.05,0.12,-0.010
74.06,0.12,-0.010
74.06,0.12,-0.010
74.06,0.13,-0.010
74.07,0.13,-0.010
74.07,0.13,-0.010
74.08,0.14,-0.011
74.08,0.14,-0.011
74.08,0.15,-0.011
74.09,0.16,-0.012
74.09,0.16,-0.013
74.09,0.17,-0.014
74.10,0.18,-0.015
74.10,0.19,-0.016
74.10,0.20,-0.017
74.10,0.21,-0.017
74.11,0.22,-0.018
74.11,0.23,-0.018
74.11,0.24,-0.018
74.12,0.26,-0.018
74.12,0.27,-0.018
74.13,0.28,-0.018
74.13,0.30,-0.018
74.13,0.32,-0.018
74.14,0.33,-0.017
74.14,0.35,-0.016
74.14,0.37,-0.014
74.15,0.38,-0.010
74.15,0.40,-0.006
74.15,0.42,-0.004
74.15,0.44,-0.001
74.16,0.46,0.002
74.16,0.48,0.004
74.16,0.50,0.007
74.17,0.53,0.010
74.17,0.55,0.013
74.18,0.57,0.016
74.18,0.59,0.019
74.18,0.61,0.022
74.19,0.64,0.026
74.19,0.66,0.029
74.19,0.68,0.032
74.20,0.71,0.035
74.20,0.73,0.037
74.20,0.75,0.040
74.20,0.78,0.042
74.21,0.80,0.045
74.21,0.83,0.048
74.21,0.85,0.050
74.22,0.88,0.053
74.22,0.90,0.056
74.23,0.93,0.058
74.23,0.95,0.060
74.23,0.98,0.062
74.24,1.01,0.065
74.24,1.03,0.067
74.24,1.06,0.069
74.25,1.09,0.071
74.25,1.11,0.073
74.25,1.14,0.075
74.25,1.17,0.076
74.26,1.19,0.078
74.26,1.22,0.080
74.26,1.25,0.081
74.27,1.27,0.083
74.27,1.30,0.085
74.28,1.33,0.086
74.28,1.36,0.087
74.28,1.39,0.089
74.29,1.42,0.091
74.29,1.44,0.093
74.29,1.47,0.094
74.30,1.50,0.095
74.30,1.53,0.096
74.30,1.56,0.098
74.30,1.59,0.099
74.31,1.62,0.100
74.31,1.65,0.102
74.31,1.68,0.103
74.32,1.70,0.105
74.32,1.73,0.106
74.33,1.77,0.107
74.33,1.79,0.108
74.33,1.82,0.109
74.34,1.85,0.110
74.34,1.88,0.111
74.34,1.91,0.113
74.35,1.94,0.114
74.35,1.97,0.115
74.35,2.00,0.116
74.35,2.03,0.117
74.36,2.07,0.118
74.36,2.10,0.119
74.36,2.13,0.119
74.37,2.16,0.120
74.37,2.19,0.121
74.38,2.22,0.122
74.38,2.25,0.123
74.38,2.28,0.124
74.39,2.31,0.125
74.39,2.34,0.125
74.39,2.37,0.126
74.40,2.40,0.127
74.40,2.43,0.127
74.40,2.46,0.129
74.40,2.49,0.129
74.41,2.53,0.130
74.41,2.56,0.130
74.41,2.59,0.130
74.42,2.62,0.131
74.42,2.65,0.131
74.43,2.68,0.132
74.43,2.72,0.133
74.43,2.75,0.134
74.44,2.78,0.134
74.44,2.81,0.135
74.44,2.84,0.135
74.45,2.87,0.135
74.45,2.91,0.136
74.45,2.94,0.136
74.45,2.97,0.137
74.46,3.00,0.137
74.46,3.03,0.137
74.46,3.06,0.138
74.47,3.10,0.138
74.47,3.13,0.139
74.48,3.16,0.139
74.48,3.19,0.140
74.48,3.22,0.140
74.49,3.26,0.141
74.49,3.29,0.141
74.49,3.32,0.141
74.50,3.35,0.142
74.50,3.38,0.142
74.50,3.42,0.142
74.50,3.45,0.143
74.51,3.48,0.143
74.51,3.51,0.143
74.51,3.54,0.144
74.52,3.58,0.144
74.52,3.61,0.144
74.53,3.64,0.144
74.53,3.67,0.145
74.53,3.71,0.145
74.54,3.74,0.146
74.54,3.77,0.146
74.54,3.80,0.146
74.55,3.84,0.146
74.55,3.87,0.146
74.55,3.90,0.146
74.55,3.93,0.147
74.56,3.96,0.147
74.56,4.00,0.147
74.56,4.03,0.147
74.57,4.06,0.147
74.57,4.09,0.147
74.58,4.13,0.148
74.58,4.16,0.148
74.58,4.19,0.148
74.59,4.23,0.148
74.59,4.26,0.148
74.59,4.29,0.148
74.60,4.32,0.149
74.60,4.36,0.149
74.60,4.39,0.149
74.60,4.42,0.149
74.61,4.45,0.150
74.61,4.49,0.150
74.61,4.52,0.150
74.62,4.55,0.150
74.62,4.58,0.150
74.63,4.62,0.150
74.63,4.65,0.150
74.63,4.68,0.150
74.64,4.71,0.150
74.64,4.75,0.151
74.64,4.78,0.151
74.65,4.81,0.151
74.65,4.85,0.151
74.65,4.88,0.151
74.65,4.91,0.151
74.66,4.94,0.151
74.66,4.98,0.151
74.66,5.01,0.151
74.67,5.04,0.152
74.67,5.07,0.152
74.68,5.11,0.152
74.68,5.14,0.152
74.68,5.17,0.152
74.69,5.21,0.152
74.69,5.24,0.152
74.69,5.27,0.152
74.70,5.30,0.152
74.70,5.34,0.152
74.70,5.37,0.152
74.70,5.40,0.153
74.71,5.44,0.153
74.71,5.47,0.153
74.71,5.50,0.153
74.72,5.53,0.153
74.72,5.57,0.153
74.73,5.60,0.153
74.73,5.63,0.153
74.73,5.67,0.153
74.74,5.70,0.153
74.74,5.73,0.153
74.74,5.76,0.154
74.75,5.80,0.154
74.75,5.83,0.154
74.75,5.86,0.154
74.75,5.90,0.154
74.76,5.93,0.154
74.76,5.96,0.154
74.76,5.99,0.154
74.77,6.03,0.154
74.77,6.06,0.154
74.78,6.09,0.154
74.78,6.13,0.154
74.78,6.16,0.154
74.79,6.19,0.154
74.79,6.23,0.154
74.79,6.26,0.154
74.80,6.29,0.154
74.80,6.32,0.154
74.80,6.36,0.154
74.80,6.39,0.155
74.81,6.42,0.155
74.81,6.46,0.155
74.81,6.49,0.155
74.82,6.52,0.155
74.82,6.56,0.155
74.83,6.59,0.155
74.83,6.62,0.155
74.83,6.65,0.155
74.84,6.69,0.155
74.84,6.72,0.155
74.84,6.75,0.155
74.85,6.79,0.155
74.85,6.82,0.155
74.85,6.85,0.155
74.85,6.89,0.155
74.86,6.92,0.155
74.86,6.95,0.155
74.86,6.99,0.155
74.87,7.02,0.155
74.87,7.05,0.155
74.88,7.08,0.155
74.88,7.12,0.155
74.88,7.15,0.155
74.89,7.18,0.156
74.89,7.22,0.156
74.89,7.25,0.156
74.90,7.28,0.156
74.90,7.32,0.156
74.90,7.35,0.156
74.90,7.38,0.156
74.91,7.42,0.156
74.91,7.45,0.156
74.91,7.48,0.156
74.92,7.52,0.156
74.92,7.55,0.156
74.93,7.58,0.156
74.93,7.61,0.156
74.93,7.65,0.156
74.94,7.68,0.156
74.94,7.71,0.156
74.94,7.75,0.156
74.95,7.78,0.156
74.95,7.81,0.157
74.95,7.85,0.157
74.95,7.88,0.157
74.96,7.91,0.157
74.96,7.95,0.157
74.96,7.98,0.157
74.97,8.01,0.157
74.97,8.04,0.157
74.98,8.08,0.157
74.98,8.11,0.157
74.98,8.14,0.157
74.99,8.18,0.157
74.99,8.21,0.157
74.99,8.24,0.157
75.00,8.28,0.157
75.00,8.31,0.157
75.00,8.34,0.157
75.00,8.37,0.157
75.01,8.41,0.157
75.01,8.44,0.158
75.01,8.48,0.158
75.02,8.51,0.158
75.02,8.54,0.158
75.03,8.57,0.158
75.03,8.61,0.158
75.03,8.64,0.158
75.04,8.67,0.158
75.04,8.71,0.158
75.04,8.74,0.158
75.05,8.77,0.158
75.05,8.81,0.158
75.05,8.84,0.158
75.05,8.87,0.158
75.06,8.91,0.158
75.06,8.94,0.158
75.06,8.97,0.158
75.07,9.01,0.158
75.07,9.04,0.158
75.08,9.07,0.158
75.08,9.11,0.158
75.08,9.14,0.158
75.09,9.17,0.158
75.09,9.20,0.158
75.09,9.24,0.158
75.10,9.27,0.158
75.10,9.31,0.158
75.10,9.34,0.159
75.10,9.37,0.159
75.11,9.41,0.159
75.11,9.44,0.159
75.11,9.47,0.159
75.12,9.50,0.159
75.12,9.54,0.159
75.13,9.57,0.159
75.13,9.60,0.159
75.13,9.64,0.159
75.14,9.67,0.159
75.14,9.70,0.159
75.14,9.74,0.159
75.15,9.77,0.159
75.15,9.80,0.159
75.15,9.84,0.159
75.15,9.87,0.159
75.16,9.90,0.159
75.16,9.94,0.159
75.16,9.97,0.159
75.17,10.00,0.159
75.17,10.04,0.159
75.18,10.07,0.159
75.18,10.10,0.159
75.18,10.14,0.159
75.19,10.17,0.159
75.19,10.20,0.159
75.19,10.23,0.160
75.20,10.27,0.160
75.20,10.30,0.160
75.20,10.33,0.160
75.20,10.37,0.160
75.21,10.40,0.160
75.21,10.43,0.160
75.21,10.47,0.160
75.22,10.50,0.160
75.22,10.53,0.160
75.23,10.57,0.160
75.23,10.60,0.160
75.23,10.63,0.160
75.24,10.67,0.160
75.24,10.70,0.160
75.24,10.73,0.160
75.25,10.77,0.160
75.25,10.80,0.160
75.25,10.83,0.160
75.25,10.87,0.160
75.26,10.90,0.160
75.26,10.93,0.160
75.26,10.96,0.160
75.27,11.00,0.160
75.27,11.03,0.160
75.28,11.06,0.160
75.28,11.10,0.160
75.28,11.13,0.160
75.29,11.17,0.160
75.29,11.20,0.160
75.29,11.23,0.160
75.30,11.26,0.160
75.30,11.30,0.161
75.30,11.33,0.161
75.30,11.36,0.161
75.31,11.40,0.161
75.31,11.43,0.161
75.31,11.46,0.161
75.32,11.50,0.161
75.32,11.53,0.161
75.33,11.56,0.161
75.33,11.60,0.161
75.33,11.63,0.161
75.34,11.66,0.161
75.34,11.70,0.161
75.34,11.73,0.161
75.35,11.76,0.161
75.35,11.80,0.161
75.35,11.83,0.161
75.35,11.86,0.161
75.36,11.90,0.161
75.36,11.93,0.161
75.36,11.96,0.161
75.37,12.00,0.161
75.37,12.03,0.161
75.38,12.06,0.161
75.38,12.10,0.161
75.38,12.13,0.161
75.39,12.16,0.161
75.39,12.20,0.161
75.39,12.23,0.161
75.40,12.26,0.161
75.40,12.30,0.161
75.40,12.33,0.162
75.40,12.36,0.162
75.41,12.40,0.162
75.41,12.43,0.162
75.41,12.46,0.162
75.42,12.49,0.162
75.42,12.53,0.162
75.43,12.56,0.162
75.43,12.59,0.162
75.43,12.63,0.162
75.44,12.66,0.162
75.44,12.70,0.162
75.44,12.73,0.162
75.45,12.76,0.162
75.45,12.79,0.162
75.45,12.83,0.162
75.45,12.86,0.162
75.46,12.90,0.162
75.46,12.93,0.162
75.46,12.96,0.162
75.47,13.00,0.162
75.47,13.03,0.162
75.48,13.06,0.162
75.48,13.10,0.162
75.48,13.13,0.162
75.49,13.16,0.162
75.49,13.20,0.162
75.49,13.23,0.162
75.50,13.26,0.162
75.50,13.30,0.162
75.50,13.33,0.162
75.50,13.36,0.162
75.51,13.40,0.163
75.51,13.43,0.163
75.51,13.46,0.163
75.52,13.49,0.163
75.52,13.53,0.163
75.53,13.56,0.163
75.53,13.60,0.163
75.53,13.63,0.163
75.54,13.66,0.163
75.54,13.69,0.163
75.54,13.73,0.163
75.55,13.76,0.163
75.55,13.79,0.163
75.55,13.83,0.163
75.55,13.86,0.163
75.56,13.89,0.163
75.56,13.93,0.163
75.56,13.96,0.163
75.57,13.99,0.163
75.57,14.03,0.163
75.58,14.06,0.163
75.58,14.09,0.163
75.58,14.13,0.163
75.59,14.16,0.163
75.59,14.19,0.163
75.59,14.23,0.163
75.60,14.26,0.163
75.60,14.29,0.163
75.60,14.33,0.163
75.60,14.36,0.163
75.61,14.39,0.163
75.61,14.43,0.164
75.61,14.46,0.164
75.62,14.49,0.164
75.62,14.53,0.164
75.63,14.56,0.164
75.63,14.60,0.164
75.63,14.63,0.164
75.64,14.66,0.164
75.64,14.69,0.164
75.64,14.73,0.164
75.65,14.76,0.164
75.65,14.79,0.164
75.65,14.83,0.164
75.65,14.86,0.164
75.66,14.89,0.164
75.66,14.93,0.164
75.66,14.96,0.164
75.67,15.00,0.164
75.67,15.03,0.164
75.68,15.06,0.164
75.68,15.10,0.164
75.68,15.13,0.164
75.69,15.16,0.164
75.69,15.19,0.164
75.69,15.23,0.164
75.70,15.26,0.164
75.70,15.30,0.164
75.70,15.33,0.164
75.70,15.36,0.164
75.71,15.39,0.164
75.71,15.43,0.164
75.71,15.46,0.164
75.72,15.50,0.164
75.72,15.53,0.164
75.73,15.56,0.164
75.73,15.60,0.165
75.73,15.63,0.165
75.74,15.66,0.165
75.74,15.70,0.165
75.74,15.73,0.165
75.75,15.76,0.165
75.75,15.80,0.165
75.75,15.83,0.165
75.75,15.86,0.165
75.76,15.90,0.165
75.76,15.93,0.165
75.76,15.96,0.165
75.77,16.00,0.165
75.77,16.03,0.165
75.78,16.06,0.165
75.78,16.10,0.165
75.78,16.13,0.165
75.79,16.16,0.165
75.79,16.20,0.165
75.79,16.23,0.165
75.80,16.26,0.165
75.80,16.30,0.165
75.80,16.33,0.165
75.80,16.36,0.165
75.81,16.40,0.165
75.81,16.43,0.165
75.81,16.46,0.165
75.82,16.50,0.165
75.82,16.53,0.165
75.83,16.56,0.165
75.83,16.60,0.165
75.83,16.63,0.165
75.84,16.66,0.166
75.84,16.70,0.166
75.84,16.73,0.166
75.85,16.76,0.166
75.85,16.80,0.166
75.85,16.83,0.166
75.85,16.86,0.166
75.86,16.90,0.166
75.86,16.93,0.166
75.86,16.96,0.166
75.87,17.00,0.166
75.87,17.03,0.166
75.88,17.06,0.166
75.88,17.10,0.166
75.88,17.13,0.166
75.89,17.16,0.166
75.89,17.20,0.166
75.89,17.23,0.166
75.90,17.26,0.166
75.90,17.30,0.166
75.90,17.33,0.166
75.90,17.36,0.166
75.91,17.40,0.166
75.91,17.43,0.166
75.91,17.46,0.166
75.92,17.50,0.166
75.92,17.53,0.166
75.93,17.56,0.166
75.93,17.60,0.166
75.93,17.63,0.166
75.94,17.66,0.166
75.94,17.70,0.166
75.94,17.73,0.166
75.95,17.76,0.166
75.95,17.80,0.166
75.95,17.83,0.166
75.95,17.86,0.166
75.96,17.90,0.167
75.96,17.93,0.167
75.96,17.96,0.167
75.97,18.00,0.167
75.97,18.03,0.167
75.98,18.06,0.167
75.98,18.10,0.167
75.98,18.13,0.167
75.99,18.16,0.167
75.99,18.20,0.167
75.99,18.23,0.167
76.00,18.26,0.167
76.00,18.30,0.167
76.00,18.33,0.167
76.00,18.36,0.167
76.01,18.40,0.167
76.01,18.43,0.167
76.01,18.46,0.167
76.02,18.50,0.167
76.02,18.53,0.167
76.03,18.56,0.167
76.03,18.60,0.167
76.03,18.63,0.167
76.04,18.66,0.167
76.04,18.70,0.167
76.04,18.73,0.167
76.05,18.76,0.167
76.05,18.80,0.167
76.05,18.83,0.167
76.05,18.86,0.167
76.06,18.90,0.167
76.06,18.93,0.167
76.06,18.96,0.167
76.07,19.00,0.167
76.07,19.03,0.167
76.08,19.06,0.168
76.08,19.10,0.168
76.08,19.13,0.168
76.09,19.16,0.168
76.09,19.20,0.168
76.09,19.23,0.168
76.10,19.26,0.168
76.10,19.30,0.168
76.10,19.33,0.168
76.10,19.36,0.168
76.11,19.40,0.168
76.11,19.43,0.168
76.11,19.46,0.168
76.12,19.50,0.168
76.12,19.53,0.168
76.13,19.56,0.168
76.13,19.60,0.168
76.13,19.63,0.168
76.14,19.66,0.168
76.14,19.70,0.168
76.14,19.73,0.168
76.15,19.76,0.168
76.15,19.80,0.168
76.15,19.83,0.168
76.15,19.86,0.168
76.16,19.90,0.168
76.16,19.93,0.168
76.16,19.96,0.168
76.17,20.00,0.168
76.17,20.03,0.168
76.18,20.06,0.168
76.18,20.10,0.168
76.18,20.13,0.168
76.19,20.16,0.168
76.19,20.20,0.168
76.19,20.23,0.168
76.20,20.26,0.168
76.20,20.30,0.169
76.20,20.33,0.169
76.20,20.36,0.169
76.21,20.40,0.169
76.21,20.43,0.169
76.21,20.46,0.169
76.22,20.50,0.169
76.22,20.53,0.169
76.23,20.56,0.169
76.23,20.60,0.169
76.23,20.63,0.169
76.24,20.66,0.169
76.24,20.70,0.169
76.24,20.73,0.169
76.25,20.76,0.169
76.25,20.80,0.169
76.25,20.83,0.169
76.25,20.86,0.169
76.26,20.90,0.169
76.26,20.93,0.169
76.26,20.96,0.169
76.27,21.00,0.169
76.27,21.03,0.169
76.28,21.06,0.169
76.28,21.10,0.169
76.28,21.13,0.169
76.29,21.16,0.169
76.29,21.20,0.169
76.29,21.23,0.169
76.30,21.26,0.169
76.30,21.30,0.169
76.30,21.33,0.169
76.30,21.36,0.169
76.31,21.40,0.169
76.31,21.43,0.169
76.31,21.46,0.169
76.32,21.50,0.169
76.32,21.53,0.170
76.33,21.56,0.170
76.33,21.60,0.170
76.33,21.63,0.170
76.34,21.66,0.170
76.34,21.70,0.170
76.34,21.73,0.170
76.35,21.76,0.170
76.35,21.80,0.170
76.35,21.83,0.170
76.35,21.86,0.170
76.36,21.90,0.170
76.36,21.93,0.170
76.36,21.96,0.170
76.37,22.00,0.170
76.37,22.03,0.170
76.38,22.06,0.170
76.38,22.10,0.170
76.38,22.13,0.170
76.39,22.16,0.170
76.39,22.20,0.170
76.39,22.23,0.170
76.40,22.26,0.170
76.40,22.30,0.170
76.40,22.33,0.170
76.40,22.36,0.170
76.41,22.40,0.170
76.41,22.43,0.170
76.41,22.46,0.170
76.42,22.50,0.170
76.42,22.53,0.170
76.43,22.56,0.170
76.43,22.60,0.170
76.43,22.63,0.171
76.44,22.66,0.171
76.44,22.70,0.171
76.44,22.73,0.171
76.45,22.76,0.171
76.45,22.80,0.171
76.45,22.83,0.171
76.45,22.86,0.171
76.46,22.90,0.171
76.46,22.93,0.171
76.46,22.96,0.171
76.47,23.00,0.171
76.47,23.03,0.171
76.48,23.07,0.171
76.48,23.10,0.171
76.48,23.13,0.171
76.49,23.16,0.171
76.49,23.20,0.171
76.49,23.23,0.171
76.50,23.26,0.171
76.50,23.30,0.171
76.50,23.33,0.171
76.50,23.36,0.171
76.51,23.40,0.171
76.51,23.43,0.171
76.51,23.46,0.171
76.52,23.50,0.171
76.52,23.53,0.171
76.53,23.56,0.171
76.53,23.60,0.171
76.53,23.63,0.171
76.54,23.66,0.172
76.54,23.70,0.172
76.54,23.73,0.172
76.55,23.76,0.172
76.55,23.80,0.172
76.55,23.83,0.172
76.55,23.86,0.172
76.56,23.90,0.172
76.56,23.93,0.172
76.56,23.96,0.172
76.57,24.00,0.172
76.57,24.03,0.172
76.58,24.06,0.172
76.58,24.10,0.172
76.58,24.13,0.172
76.59,24.16,0.172
76.59,24.20,0.172
76.59,24.23,0.172
76.60,24.26,0.172
76.60,24.30,0.172
76.60,24.33,0.172
76.60,24.36,0.172
76.61,24.40,0.172
76.61,24.43,0.172
76.61,24.46,0.172
76.62,24.50,0.172
76.62,24.53,0.172
76.63,24.56,0.172
76.63,24.60,0.172
76.63,24.63,0.172
76.64,24.67,0.172
76.64,24.70,0.172
76.64,24.73,0.172
76.65,24.76,0.172
76.65,24.80,0.173
76.65,24.83,0.173
76.65,24.86,0.173
76.66,24.90,0.173
76.66,24.93,0.173
76.66,24.96,0.173
76.67,25.00,0.173
76.67,25.03,0.173
76.68,25.06,0.173
76.68,25.10,0.173
76.68,25.13,0.173
76.69,25.16,0.173
76.69,25.20,0.173
76.69,25.23,0.173
76.70,25.26,0.173
76.70,25.30,0.173
76.70,25.33,0.173
76.70,25.36,0.173
76.71,25.40,0.173
76.71,25.43,0.173
76.71,25.46,0.173
76.72,25.50,0.173
76.72,25.53,0.173
76.73,25.56,0.173
76.73,25.60,0.173
76.73,25.63,0.173
76.74,25.66,0.173
76.74,25.70,0.173
76.74,25.73,0.173
76.75,25.76,0.173
76.75,25.80,0.173
76.75,25.83,0.173
76.75,25.86,0.173
76.76,25.90,0.173
76.76,25.93,0.173
76.76,25.96,0.173
76.77,26.00,0.173
76.77,26.03,0.174
76.78,26.06,0.174
76.78,26.10,0.174
76.78,26.13,0.174
76.79,26.16,0.174
76.79,26.20,0.174
76.79,26.23,0.174
76.80,26.26,0.174
76.80,26.30,0.174
76.80,26.33,0.174
76.80,26.36,0.174
76.81,26.40,0.174
76.81,26.43,0.174
76.81,26.46,0.174
76.82,26.50,0.174
76.82,26.53,0.174
76.83,26.56,0.174
76.83,26.60,0.174
76.83,26.63,0.174
76.84,26.66,0.174
76.84,26.70,0.174
76.84,26.73,0.174
76.85,26.76,0.174
76.85,26.80,0.174
76.85,26.83,0.174
76.85,26.86,0.174
76.86,26.90,0.174
76.86,26.93,0.174
76.86,26.96,0.174
76.87,27.00,0.174
76.87,27.03,0.174
76.88,27.06,0.174
76.88,27.10,0.174
76.88,27.13,0.174
76.89,27.16,0.174
76.89,27.20,0.175
76.89,27.23,0.175
76.90,27.26,0.175
76.90,27.30,0.175
76.90,27.33,0.175
76.90,27.36,0.175
76.91,27.40,0.175
76.91,27.43,0.175
76.91,27.47,0.175
76.92,27.50,0.175
76.92,27.53,0.175
76.93,27.57,0.175
76.93,27.60,0.175
76.93,27.63,0.175
76.94,27.66,0.175
76.94,27.70,0.175
76.94,27.73,0.175
76.95,27.77,0.175
76.95,27.80,0.175
76.95,27.83,
76.95,27.87,
76.96,27.90,
76.96,27.93,
76.96,27.97,
76.97,28.00,
76.97,28.03,
76.98,28.06,
76.98,28.10,
76.98,28.13,
76.99,28.17,
76.99,28.20,
76.99,28.23,
77.00,28.27,
77.00,28.30,
77.00,,
77.00,,
77.01,,