File: DSC/2025_04_22_CBG_n60C_80C_2Cmin_x3.csv
Filename,2025_04_22_CBG_n60C_80C_2Cmin_x3
Instrument name,DSC2A-00468 (192.168.1.100)
Operator,Yarger
rundate,4/22/2025
Sample name,2025_04_22_CBG_n60C_80C_2Cmin_x3
proceduresegments,Data Off ; Equilibrate -60.00 °C; Data On ; Ramp 2.00 °C/min to 80.00 °C; Data Off ; Isothermal 1.0 min; Data On ; Ramp 20.00 °C/min to -60.00 °C; Data Off ; Isothermal 2.0 min; Data On ; Ramp 2.00 °C/min to 80.00 °C; Data Off ; Isothermal 1.0 min; Data On ; Ramp 20.00 °C/min to -60.00 °C; Data Off ; Isothermal 2.0 min; Data On ; Ramp 2.00 °C/min to 80.00 °C
[File Parameters]
Run date,4/22/2025 1:56:50 PM
Trios version,5.1.1.46572
Original File Name,
Current File Name,D:\DSC2500\JYarger\2025_04_22_CBG_n60C_80C_2Cmin_x3.tri
[Procedure]
Procedure Name,CBG_n60_80C_2Cmin_x3
Sample Name,2025_04_22_CBG_n60C_80C_2Cmin_x3
Sample Mass,3.5 mg
Reference Sample Mass,0 mg
Pan Mass,52.8 mg
Pan Number,15
Reference Pan Mass,52.66 mg
Reference Pan Number,19
Pan Type,Tzero Aluminum Hermetic
Comments,Al Hermetic DSC Consumables sealed Pan/Lid.
Project Name,CA
Operator,Yarger
Test,Custom
Unload Max Temperature,30
Unload Min Temperature,30
Load Max Temperature,30
Load Min Temperature,30
Stop on Gas Flow Error,Yes
[Signal List]
Signal #1,Time (min)
Signal #2,Temperature (°C)
Signal #3,Heat Flow (mW)
Signal #4,Delta T (µV)
Signal #5,Delta Tzero (µV)
Signal #6,Tzero Temperature (°C)
Signal #7,Cell Purge (mL/min)
Signal #8,Heater Temp (°C)
Signal #9,Power Delivered (W)
Signal #10,Reference Junction Temperature (°C)
Signal #11,Flange Temperature (°C)
Signal #12,Heat Flow Phase (rad)
Signal #13,Total Heat Capacity (J/°C)
Signal #14,Heat Capacity (J/°C)
[Configuration]
Company Name,ASU
Instrument Name,DSC2A-00468
Instrument Type,DSC2500
Serial Number,DSC2A-00468
IP,192.168.1.100
Location of Instrument,MRRC
DisplayType,Unknown
Sample Interval ,0.1 s/pt
Selected Heat Flow,T4P
Exotherm Direction,Down
Cell Serial,DRC2-00792
Lid Type,Standard
Cooler,RCS 90
Leave Cooler on at End of Sequence,On
Gas 2,Nitrogen
Gas Selected,Channel 1
Flow Rate,50 mL/min
Secondary Purge,On
Licensed Heat Flow,Heat Flow T4P
Modulation Licensed,Yes
[Versions]
Common IDD Version,1
Cortex Version,VER 2.10.2.31
Driver,5.0.0.6
GDM Version,1.0.3.3
TouchscreenVersion,1.0.0.16145
FEP Version,1.2.1.21
FEP Bootloader,2.0.0.5
AutoSampler Version,2.1.1.26
Auto Sampler Bootloader,2.0.0.5
FCM Version,1.1.0.3
FCM Bootloader,2.0.0.5
[Experiment Logs]
Experiment Log Entry # 1,Air Cool is off.
Experiment Log Entry # 3,Data On set to 0
Experiment Log Entry # 5,Equilibrate Segment -60 (C) Started
Experiment Log Entry # 7,Data On set to 1
Experiment Log Entry # 9,Ramp Segment 2 C/min to 80 Started
Experiment Log Entry # 11,Data On set to 0
Experiment Log Entry # 13,Isothermal Segment 1 min started
Experiment Log Entry # 15,Data On set to 1
Experiment Log Entry # 17,Ramp Segment 20 C/min to -60 Started
Experiment Log Entry # 19,Data On set to 0
Experiment Log Entry # 21,Isothermal Segment 2 min started
Experiment Log Entry # 23,Data On set to 1
Experiment Log Entry # 25,Ramp Segment 2 C/min to 80 Started
Experiment Log Entry # 27,Data On set to 0
Experiment Log Entry # 29,Isothermal Segment 1 min started
Experiment Log Entry # 31,Data On set to 1
Experiment Log Entry # 33,Ramp Segment 20 C/min to -60 Started
Experiment Log Entry # 35,Data On set to 0
Experiment Log Entry # 37,Isothermal Segment 2 min started
Experiment Log Entry # 39,Data On set to 1
Experiment Log Entry # 41,Ramp Segment 2 C/min to 80 Started
[Method Log]
Method Log Entry # 1,Data Off
Method Log Entry # 2,Equilibrate -60 °C
Method Log Entry # 3,Data On
Method Log Entry # 4,(Ramp 1049125) Ramp 2 °C/minute to 80 °C
Method Log Entry # 5,Data Off
Method Log Entry # 6,Isothermal 1 minutes
Method Log Entry # 7,Data On
Method Log Entry # 8,(Ramp 1049129) Ramp 20 °C/minute to -60 °C
Method Log Entry # 9,Data Off
Method Log Entry # 10,Isothermal 2 minutes
Method Log Entry # 11,Data On
Method Log Entry # 12,(Ramp 1049133) Ramp 2 °C/minute to 80 °C
Method Log Entry # 13,Data Off
Method Log Entry # 14,Isothermal 1 minutes
Method Log Entry # 15,Data On
Method Log Entry # 16,(Ramp 1049137) Ramp 20 °C/minute to -60 °C
Method Log Entry # 17,Data Off
Method Log Entry # 18,Isothermal 2 minutes
Method Log Entry # 19,Data On
Method Log Entry # 20,(Ramp 1049141) Ramp 2 °C/minute to 80 °C
Cell Serial,DRC2-00792
[T1 Calibration]
Slope,-0.008529666
Offset,9.636258
Initial Temperature,98.23
GUID,f8bfdadc-4977-4fdf-ba6d-0ba9134940c3
[TZero Calibration]
Date Applied,11/29/2022 4:06:13 PM
Description,From -89.059 °C to 396.009 °C at 20.000°C/min
Gas Type,Nitrogen
Pan Type,None
Source Files 1,C:\Users\yargerlab\Desktop\DSC Data\General\TZero_calibration_11_29_22_2nd(2).tri
Source Files 2,C:\Users\yargerlab\Desktop\DSC Data\General\TZero_calibration_11_29_22_2nd(3).tri
Delta T Offset,13.05235
Delta T Slope,-0.007271007
Delta T0 Offset,-13.69128
Delta T0 Slope,0.06063341
[Temperature Calibration]
Date Applied,11/29/2022 7:12:28 PM
Description,From 106.590 °C to 186.590 °C at 10.000°C/min
Gas Type,Nitrogen
Pan Type,Tzero Aluminum Hermetic
Source Files 1,C:\Users\yargerlab\Desktop\DSC Data\General\Indium(6).tri
Measured 1,157.391
Known 1,156.598
[Cell Constant Calibration]
Date Applied,11/29/2022 7:12:29 PM
Description,From 106.590 °C to 186.590 °C at 10.000°C/min
Gas Type,Nitrogen
Pan Type,Tzero Aluminum Hermetic
Source Files 1,C:\Users\yargerlab\Desktop\DSC Data\General\Indium(6).tri
T4P KCell,1.006051
Onset Slope,63.26126 mW/°C
[Direct Cp Calibration]
Date Applied,11/30/2022 11:04:51 AM
Description,From -79.983 °C to 298.409 °C at 10.000°C/min
Gas Type,Nitrogen
Pan Type,Tzero Aluminum Hermetic
Source Files 1,C:\Users\yargerlab\Desktop\DSC Data\General\Sapphire_Heat_Capacity_11_30_22.tri
[Rev Cp Calibration]
Date Applied,11/30/2022 1:58:51 PM
Description,From -79.996 °C to 292.812 °C at 3.000°C/min
Gas Type,Nitrogen
Pan Type,Tzero Aluminum Hermetic
Source Files 1,C:\Users\yargerlab\Desktop\DSC Data\General\Sapphire_MDSC_Calibration_11_30_22.tri
[step]
Ramp 2.00 °C/min to 80.00 °C
Time,Temperature,Heat Flow (Normalized)
min,°C,W/g
0.00,-59.67,-0.108
0.05,-59.70,-0.093
0.09,-59.68,-0.099
0.14,-59.62,-0.122
0.19,-59.56,-0.083
0.23,-59.50,-0.058
0.28,-59.42,-0.041
0.33,-59.34,-0.025
0.37,-59.26,-0.014
0.42,-59.18,-0.007
0.47,-59.09,-0.003
0.51,-59.00,0.001
0.56,-58.92,0.003
0.61,-58.83,0.005
0.65,-58.74,0.006
0.70,-58.65,0.008
0.75,-58.56,0.009
0.79,-58.47,0.010
0.84,-58.38,0.011
0.89,-58.29,0.012
0.93,-58.20,0.013
0.98,-58.10,0.013
1.03,-58.01,0.014
1.07,-57.92,0.014
1.12,-57.83,0.015
1.17,-57.74,0.015
1.21,-57.65,0.015
1.26,-57.55,0.015
1.31,-57.46,0.016
1.35,-57.37,0.016
1.40,-57.27,0.016
1.45,-57.18,0.016
1.49,-57.09,0.016
1.54,-57.00,0.016
1.59,-56.90,0.016
1.63,-56.81,0.016
1.68,-56.72,0.016
1.73,-56.62,0.016
1.77,-56.53,0.016
1.82,-56.44,0.016
1.87,-56.34,0.015
1.91,-56.25,0.015
1.96,-56.16,0.015
2.01,-56.07,0.015
2.05,-55.97,0.015
2.10,-55.88,0.015
2.15,-55.79,0.015
2.19,-55.69,0.015
2.24,-55.60,0.015
2.29,-55.51,0.014
2.33,-55.41,0.014
2.38,-55.32,0.014
2.43,-55.23,0.014
2.47,-55.13,0.014
2.52,-55.04,0.014
2.57,-54.95,0.014
2.61,-54.86,0.014
2.66,-54.76,0.014
2.71,-54.67,0.013
2.75,-54.57,0.013
2.80,-54.48,0.013
2.85,-54.39,0.013
2.89,-54.29,0.013
2.94,-54.20,0.013
2.99,-54.11,0.013
3.03,-54.01,0.013
3.08,-53.92,0.013
3.13,-53.83,0.013
3.17,-53.73,0.012
3.22,-53.64,0.012
3.27,-53.55,0.012
3.31,-53.46,0.012
3.36,-53.36,0.012
3.41,-53.27,0.012
3.45,-53.17,0.012
3.50,-53.08,0.012
3.55,-52.99,0.012
3.59,-52.89,0.012
3.64,-52.80,0.012
3.69,-52.71,0.011
3.73,-52.61,0.011
3.78,-52.52,0.011
3.83,-52.43,0.011
3.87,-52.33,0.011
3.92,-52.24,0.011
3.97,-52.15,0.011
4.01,-52.05,0.011
4.06,-51.96,0.011
4.11,-51.87,0.011
4.15,-51.77,0.011
4.20,-51.68,0.011
4.25,-51.59,0.011
4.29,-51.49,0.011
4.34,-51.40,0.011
4.39,-51.31,0.011
4.43,-51.22,0.011
4.48,-51.12,0.011
4.53,-51.03,0.011
4.57,-50.93,0.011
4.62,-50.84,0.011
4.67,-50.75,0.011
4.71,-50.65,0.011
4.76,-50.56,0.011
4.81,-50.47,0.010
4.85,-50.37,0.010
4.90,-50.28,0.010
4.95,-50.19,0.010
4.99,-50.09,0.010
5.04,-50.00,0.010
5.09,-49.91,0.010
5.13,-49.81,0.010
5.18,-49.72,0.010
5.23,-49.63,0.010
5.27,-49.53,0.010
5.32,-49.44,0.010
5.37,-49.35,0.010
5.41,-49.25,0.010
5.46,-49.16,0.010
5.51,-49.07,0.010
5.55,-48.98,0.010
5.60,-48.88,0.010
5.65,-48.79,0.010
5.69,-48.69,0.009
5.74,-48.60,0.009
5.79,-48.51,0.009
5.83,-48.41,0.009
5.88,-48.32,0.009
5.93,-48.23,0.009
5.97,-48.14,0.009
6.02,-48.04,0.009
6.07,-47.95,0.009
6.11,-47.85,0.009
6.16,-47.76,0.009
6.21,-47.67,0.009
6.25,-47.58,0.009
6.30,-47.48,0.009
6.35,-47.39,0.009
6.39,-47.29,0.009
6.44,-47.20,0.009
6.49,-47.11,0.009
6.53,-47.01,0.009
6.58,-46.92,0.009
6.63,-46.83,0.009
6.67,-46.73,0.009
6.72,-46.64,0.009
6.77,-46.55,0.009
6.81,-46.45,0.009
6.86,-46.36,0.009
6.91,-46.27,0.009
6.95,-46.17,0.009
7.00,-46.08,0.009
7.05,-45.99,0.009
7.09,-45.89,0.009
7.14,-45.80,0.009
7.19,-45.71,0.009
7.23,-45.61,0.009
7.28,-45.52,0.009
7.33,-45.43,0.008
7.37,-45.33,0.008
7.42,-45.24,0.008
7.47,-45.15,0.008
7.51,-45.06,0.008
7.56,-44.96,0.008
7.61,-44.87,0.008
7.65,-44.77,0.008
7.70,-44.68,0.008
7.75,-44.59,0.008
7.79,-44.49,0.008
7.84,-44.40,0.008
7.89,-44.31,0.008
7.93,-44.21,0.008
7.98,-44.12,0.008
8.03,-44.03,0.008
8.07,-43.93,0.008
8.12,-43.84,0.008
8.17,-43.75,0.008
8.21,-43.66,0.008
8.26,-43.56,0.008
8.31,-43.47,0.008
8.35,-43.37,0.008
8.40,-43.28,0.008
8.45,-43.19,0.008
8.49,-43.09,0.008
8.54,-43.00,0.008
8.59,-42.91,0.008
8.63,-42.81,0.008
8.68,-42.72,0.008
8.73,-42.63,0.008
8.77,-42.53,0.007
8.82,-42.44,0.008
8.87,-42.35,0.008
8.91,-42.25,0.008
8.96,-42.16,0.008
9.01,-42.07,0.007
9.05,-41.97,0.007
9.10,-41.88,0.007
9.15,-41.79,0.007
9.19,-41.69,0.007
9.24,-41.60,0.007
9.29,-41.51,0.007
9.33,-41.41,0.007
9.38,-41.32,0.007
9.43,-41.23,0.007
9.47,-41.13,0.007
9.52,-41.04,0.007
9.57,-40.95,0.007
9.61,-40.85,0.007
9.66,-40.76,0.007
9.71,-40.67,0.007
9.75,-40.57,0.007
9.80,-40.48,0.007
9.85,-40.39,0.007
9.89,-40.29,0.007
9.94,-40.20,0.007
9.99,-40.11,0.007
10.03,-40.01,0.007
10.08,-39.92,0.007
10.13,-39.83,0.007
10.17,-39.74,0.007
10.22,-39.64,0.007
10.27,-39.55,0.007
10.31,-39.46,0.007
10.36,-39.36,0.007
10.41,-39.27,0.007
10.45,-39.18,0.007
10.50,-39.08,0.007
10.55,-38.99,0.007
10.59,-38.90,0.007
10.64,-38.80,0.007
10.69,-38.71,0.007
10.73,-38.62,0.006
10.78,-38.52,0.007
10.83,-38.43,0.006
10.87,-38.33,0.006
10.92,-38.24,0.006
10.97,-38.15,0.006
11.01,-38.05,0.006
11.06,-37.96,0.006
11.11,-37.87,0.006
11.15,-37.78,0.006
11.20,-37.68,0.006
11.25,-37.59,0.006
11.29,-37.49,0.006
11.34,-37.40,0.006
11.39,-37.31,0.006
11.43,-37.22,0.006
11.48,-37.12,0.006
11.53,-37.03,0.006
11.57,-36.94,0.006
11.62,-36.84,0.006
11.67,-36.75,0.006
11.71,-36.66,0.006
11.76,-36.56,0.006
11.81,-36.47,0.006
11.85,-36.37,0.006
11.90,-36.28,0.006
11.95,-36.19,0.006
11.99,-36.10,0.006
12.04,-36.00,0.006
12.09,-35.91,0.006
12.13,-35.82,0.006
12.18,-35.72,0.006
12.23,-35.63,0.006
12.27,-35.53,0.005
12.32,-35.44,0.005
12.37,-35.35,0.005
12.41,-35.25,0.005
12.46,-35.16,0.006
12.51,-35.07,0.006
12.55,-34.98,0.006
12.60,-34.88,0.006
12.65,-34.79,0.006
12.69,-34.69,0.006
12.74,-34.60,0.006
12.79,-34.51,0.006
12.83,-34.42,0.006
12.88,-34.32,0.006
12.93,-34.23,0.006
12.97,-34.14,0.006
13.02,-34.04,0.005
13.07,-33.95,0.005
13.11,-33.85,0.005
13.16,-33.76,0.005
13.21,-33.67,0.005
13.25,-33.58,0.005
13.30,-33.48,0.005
13.35,-33.39,0.005
13.39,-33.29,0.005
13.44,-33.20,0.005
13.49,-33.11,0.005
13.53,-33.02,0.005
13.58,-32.92,0.005
13.63,-32.83,0.005
13.67,-32.73,0.005
13.72,-32.64,0.005
13.77,-32.55,0.005
13.81,-32.45,0.005
13.86,-32.36,0.005
13.91,-32.27,0.005
13.95,-32.17,0.005
14.00,-32.08,0.005
14.05,-31.99,0.005
14.09,-31.89,0.005
14.14,-31.80,0.005
14.19,-31.71,0.005
14.23,-31.61,0.005
14.28,-31.52,0.005
14.33,-31.43,0.005
14.37,-31.33,0.005
14.42,-31.24,0.005
14.47,-31.15,0.005
14.51,-31.05,0.005
14.56,-30.96,0.005
14.61,-30.87,0.005
14.65,-30.77,0.005
14.70,-30.68,0.005
14.75,-30.59,0.005
14.79,-30.49,0.005
14.84,-30.40,0.005
14.89,-30.31,0.005
14.93,-30.21,0.005
14.98,-30.12,0.005
15.03,-30.02,0.005
15.07,-29.93,0.005
15.12,-29.84,0.005
15.17,-29.75,0.004
15.21,-29.65,0.004
15.26,-29.56,0.004
15.31,-29.46,0.004
15.35,-29.37,0.004
15.40,-29.28,0.004
15.45,-29.18,0.004
15.49,-29.09,0.004
15.54,-29.00,0.004
15.59,-28.90,0.004
15.63,-28.81,0.004
15.68,-28.72,0.004
15.73,-28.63,0.004
15.77,-28.53,0.004
15.82,-28.44,0.004
15.87,-28.34,0.004
15.91,-28.25,0.004
15.96,-28.16,0.004
16.01,-28.06,0.004
16.05,-27.97,0.004
16.10,-27.88,0.004
16.15,-27.78,0.004
16.19,-27.69,0.004
16.24,-27.60,0.004
16.29,-27.50,0.004
16.33,-27.41,0.004
16.38,-27.32,0.004
16.43,-27.22,0.004
16.47,-27.13,0.004
16.52,-27.04,0.004
16.57,-26.94,0.004
16.61,-26.85,0.004
16.66,-26.76,0.004
16.71,-26.66,0.004
16.75,-26.57,0.004
16.80,-26.48,0.004
16.85,-26.38,0.004
16.89,-26.29,0.004
16.94,-26.20,0.004
16.99,-26.10,0.004
17.03,-26.01,0.004
17.08,-25.92,0.004
17.13,-25.82,0.004
17.17,-25.73,0.004
17.22,-25.64,0.004
17.27,-25.54,0.004
17.31,-25.45,0.004
17.36,-25.36,0.004
17.41,-25.26,0.003
17.45,-25.17,0.003
17.50,-25.08,0.003
17.55,-24.98,0.003
17.59,-24.89,0.003
17.64,-24.80,0.003
17.69,-24.70,0.003
17.73,-24.61,0.003
17.78,-24.52,0.003
17.83,-24.42,0.003
17.87,-24.33,0.003
17.92,-24.23,0.003
17.97,-24.14,0.003
18.01,-24.05,0.003
18.06,-23.95,0.003
18.11,-23.86,0.003
18.15,-23.77,0.003
18.20,-23.67,0.003
18.25,-23.58,0.003
18.29,-23.49,0.003
18.34,-23.39,0.003
18.39,-23.30,0.003
18.43,-23.21,0.003
18.48,-23.11,0.003
18.53,-23.02,0.003
18.57,-22.93,0.003
18.62,-22.83,0.003
18.67,-22.74,0.003
18.71,-22.65,0.003
18.76,-22.55,0.003
18.81,-22.46,0.003
18.85,-22.37,0.003
18.90,-22.27,0.003
18.95,-22.18,0.003
18.99,-22.09,0.003
19.04,-21.99,0.003
19.09,-21.90,0.003
19.13,-21.81,0.003
19.18,-21.71,0.003
19.23,-21.62,0.003
19.27,-21.53,0.003
19.32,-21.43,0.003
19.37,-21.34,0.003
19.41,-21.25,0.003
19.46,-21.15,0.003
19.51,-21.06,0.003
19.55,-20.97,0.003
19.60,-20.87,0.003
19.65,-20.78,0.003
19.69,-20.69,0.003
19.74,-20.59,0.003
19.79,-20.50,0.003
19.83,-20.41,0.003
19.88,-20.31,0.003
19.93,-20.22,0.003
19.97,-20.13,0.003
20.02,-20.03,0.003
20.07,-19.94,0.003
20.11,-19.85,0.003
20.16,-19.75,0.003
20.21,-19.66,0.003
20.25,-19.57,0.003
20.30,-19.47,0.002
20.35,-19.38,0.002
20.39,-19.29,0.002
20.44,-19.19,0.002
20.49,-19.10,0.002
20.53,-19.01,0.002
20.58,-18.91,0.002
20.63,-18.82,0.002
20.67,-18.72,0.002
20.72,-18.63,0.002
20.77,-18.54,0.002
20.81,-18.45,0.002
20.86,-18.35,0.002
20.91,-18.26,0.002
20.95,-18.17,0.002
21.00,-18.07,0.002
21.05,-17.98,0.002
21.09,-17.88,0.002
21.14,-17.79,0.002
21.19,-17.70,0.002
21.23,-17.61,0.002
21.28,-17.51,0.002
21.33,-17.42,0.002
21.37,-17.32,0.002
21.42,-17.23,0.002
21.47,-17.14,0.002
21.51,-17.04,0.002
21.56,-16.95,0.002
21.61,-16.86,0.002
21.65,-16.76,0.002
21.70,-16.67,0.002
21.75,-16.58,0.002
21.79,-16.48,0.002
21.84,-16.39,0.002
21.89,-16.30,0.002
21.93,-16.20,0.002
21.98,-16.11,0.002
22.03,-16.02,0.002
22.07,-15.92,0.002
22.12,-15.83,0.002
22.17,-15.74,0.002
22.21,-15.64,0.002
22.26,-15.55,0.002
22.31,-15.46,0.002
22.35,-15.36,0.002
22.40,-15.27,0.002
22.45,-15.18,0.002
22.49,-15.08,0.002
22.54,-14.99,0.002
22.59,-14.90,0.002
22.63,-14.80,0.002
22.68,-14.71,0.002
22.73,-14.62,0.002
22.77,-14.52,0.001
22.82,-14.43,0.001
22.87,-14.34,0.001
22.91,-14.24,0.001
22.96,-14.15,0.001
23.01,-14.06,0.001
23.05,-13.96,0.001
23.10,-13.87,0.001
23.15,-13.78,0.001
23.19,-13.68,0.001
23.24,-13.59,0.001
23.29,-13.50,0.001
23.33,-13.40,0.001
23.38,-13.31,0.001
23.43,-13.22,0.001
23.47,-13.12,0.001
23.52,-13.03,0.001
23.57,-12.93,0.001
23.61,-12.84,0.001
23.66,-12.75,0.001
23.71,-12.66,0.001
23.75,-12.56,0.001
23.80,-12.47,0.001
23.85,-12.38,0.001
23.89,-12.28,0.001
23.94,-12.19,0.001
23.99,-12.10,0.001
24.03,-12.00,0.001
24.08,-11.91,0.001
24.13,-11.81,0.001
24.17,-11.72,0.001
24.22,-11.63,0.001
24.27,-11.54,0.001
24.31,-11.44,0.001
24.36,-11.35,0.001
24.41,-11.26,0.001
24.45,-11.16,0.001
24.50,-11.07,0.001
24.55,-10.97,0.001
24.59,-10.88,0.001
24.64,-10.79,0.001
24.69,-10.70,0.001
24.73,-10.60,0.001
24.78,-10.51,0.001
24.83,-10.42,0.001
24.87,-10.32,0.001
24.92,-10.23,0.001
24.97,-10.13,0.001
25.01,-10.04,0.001
25.06,-9.95,0.001
25.11,-9.85,0.001
25.15,-9.76,0.001
25.20,-9.67,0.001
25.25,-9.57,0.001
25.29,-9.48,0.001
25.34,-9.39,0.001
25.39,-9.29,0.001
25.43,-9.20,0.001
25.48,-9.11,0.001
25.53,-9.01,0.001
25.57,-8.92,0.001
25.62,-8.83,0.001
25.67,-8.73,0.001
25.71,-8.64,0.001
25.76,-8.55,0.001
25.81,-8.45,0.001
25.85,-8.36,0.001
25.90,-8.27,0.001
25.95,-8.17,0.001
25.99,-8.08,0.001
26.04,-7.99,0.001
26.09,-7.89,0.001
26.13,-7.80,0.001
26.18,-7.71,0.001
26.23,-7.61,0.001
26.27,-7.52,0.001
26.32,-7.43,0.001
26.37,-7.33,0.001
26.41,-7.24,0.001
26.46,-7.15,0.001
26.51,-7.05,0.000
26.55,-6.96,0.000
26.60,-6.87,0.000
26.65,-6.77,0.000
26.69,-6.68,0.000
26.74,-6.58,0.000
26.79,-6.49,0.000
26.83,-6.40,0.000
26.88,-6.31,0.000
26.93,-6.21,0.000
26.97,-6.12,0.000
27.02,-6.03,0.000
27.07,-5.93,0.000
27.11,-5.84,0.000
27.16,-5.75,0.000
27.21,-5.65,0.000
27.25,-5.56,0.000
27.30,-5.46,0.000
27.35,-5.37,0.000
27.39,-5.28,0.000
27.44,-5.19,0.000
27.49,-5.09,0.000
27.53,-5.00,0.000
27.58,-4.91,0.000
27.63,-4.81,0.000
27.67,-4.72,0.000
27.72,-4.62,0.000
27.77,-4.53,0.000
27.81,-4.44,0.000
27.86,-4.34,0.000
27.91,-4.25,0.000
27.95,-4.16,0.000
28.00,-4.06,0.000
28.05,-3.97,0.000
28.09,-3.88,0.000
28.14,-3.78,0.000
28.19,-3.69,0.000
28.23,-3.60,0.000
28.28,-3.50,0.000
28.33,-3.41,0.000
28.37,-3.32,0.000
28.42,-3.22,0.000
28.47,-3.13,0.000
28.51,-3.04,0.000
28.56,-2.94,0.000
28.61,-2.85,0.000
28.65,-2.76,0.000
28.70,-2.66,0.000
28.75,-2.57,0.000
28.79,-2.48,0.000
28.84,-2.38,0.000
28.89,-2.29,0.000
28.93,-2.20,0.000
28.98,-2.10,0.000
29.03,-2.01,0.000
29.07,-1.92,0.000
29.12,-1.82,0.000
29.17,-1.73,0.000
29.21,-1.64,0.000
29.26,-1.54,0.000
29.31,-1.45,0.000
29.35,-1.36,0.000
29.40,-1.26,0.000
29.45,-1.17,0.000
29.49,-1.08,0.000
29.54,-0.98,0.000
29.59,-0.89,0.000
29.63,-0.80,0.000
29.68,-0.70,0.000
29.73,-0.61,0.000
29.77,-0.52,0.000
29.82,-0.42,0.000
29.87,-0.33,0.000
29.91,-0.24,0.000
29.96,-0.14,0.000
30.01,-0.05,0.000
30.05,0.04,0.000
30.10,0.14,0.000
30.15,0.23,0.000
30.19,0.32,0.000
30.24,0.42,-0.001
30.29,0.51,0.000
30.33,0.60,0.000
30.38,0.70,-0.001
30.43,0.79,-0.001
30.47,0.88,-0.001
30.52,0.98,-0.001
30.57,1.07,-0.001
30.61,1.17,0.000
30.66,1.26,-0.001
30.71,1.35,-0.001
30.75,1.45,-0.001
30.80,1.54,-0.001
30.85,1.63,-0.001
30.89,1.73,-0.001
30.94,1.82,-0.001
30.99,1.91,-0.001
31.03,2.01,-0.001
31.08,2.10,-0.001
31.13,2.19,-0.001
31.17,2.29,-0.001
31.22,2.38,-0.001
31.27,2.47,-0.001
31.31,2.57,-0.001
31.36,2.66,-0.001
31.41,2.75,-0.001
31.45,2.85,-0.001
31.50,2.94,-0.001
31.55,3.03,-0.001
31.59,3.13,-0.001
31.64,3.22,-0.001
31.69,3.31,-0.001
31.73,3.41,-0.001
31.78,3.50,-0.001
31.83,3.59,-0.001
31.87,3.69,-0.001
31.92,3.78,-0.001
31.97,3.87,-0.001
32.01,3.97,-0.001
32.06,4.06,-0.001
32.11,4.15,-0.001
32.15,4.25,-0.001
32.20,4.34,-0.001
32.25,4.43,-0.001
32.29,4.53,-0.001
32.34,4.62,-0.001
32.39,4.71,-0.001
32.43,4.81,-0.001
32.48,4.90,-0.001
32.53,4.99,-0.001
32.57,5.09,-0.001
32.62,5.18,-0.001
32.67,5.27,-0.001
32.71,5.37,-0.001
32.76,5.46,-0.001
32.81,5.55,-0.001
32.85,5.65,-0.001
32.90,5.74,-0.001
32.95,5.83,-0.001
32.99,5.93,-0.001
33.04,6.02,-0.001
33.09,6.11,-0.001
33.13,6.21,-0.001
33.18,6.30,-0.001
33.23,6.39,-0.001
33.27,6.49,-0.001
33.32,6.58,-0.001
33.37,6.68,-0.001
33.41,6.77,-0.001
33.46,6.86,-0.001
33.51,6.96,-0.001
33.55,7.05,-0.001
33.60,7.14,-0.001
33.65,7.23,-0.001
33.69,7.33,-0.001
33.74,7.42,-0.001
33.79,7.52,-0.001
33.83,7.61,-0.001
33.88,7.70,-0.002
33.93,7.80,-0.002
33.97,7.89,-0.001
34.02,7.98,-0.001
34.07,8.08,-0.002
34.11,8.17,-0.002
34.16,8.26,-0.002
34.21,8.36,-0.001
34.25,8.45,-0.002
34.30,8.54,-0.002
34.35,8.63,-0.002
34.39,8.73,-0.001
34.44,8.82,-0.002
34.49,8.92,-0.002
34.53,9.01,-0.002
34.58,9.10,-0.002
34.63,9.20,-0.002
34.67,9.29,-0.002
34.72,9.38,-0.001
34.77,9.48,-0.001
34.81,9.57,-0.001
34.86,9.66,-0.001
34.91,9.76,-0.001
34.95,9.85,-0.001
35.00,9.94,-0.001
35.05,10.04,-0.001
35.09,10.13,-0.001
35.14,10.22,-0.001
35.19,10.32,-0.001
35.23,10.41,-0.001
35.28,10.50,-0.001
35.33,10.60,-0.002
35.37,10.69,-0.001
35.42,10.78,-0.001
35.47,10.88,-0.001
35.51,10.97,-0.001
35.56,11.06,-0.002
35.61,11.16,-0.001
35.65,11.25,-0.002
35.70,11.34,-0.002
35.75,11.44,-0.002
35.79,11.53,-0.001
35.84,11.62,-0.001
35.89,11.72,-0.002
35.93,11.81,-0.002
35.98,11.90,-0.002
36.03,12.00,-0.002
36.07,12.09,-0.002
36.12,12.18,-0.002
36.17,12.28,-0.002
36.21,12.37,-0.002
36.26,12.46,-0.002
36.31,12.56,-0.002
36.35,12.65,-0.002
36.40,12.74,-0.002
36.45,12.84,-0.002
36.49,12.93,-0.002
36.54,13.02,-0.002
36.59,13.12,-0.002
36.63,13.21,-0.002
36.68,13.31,-0.002
36.73,13.40,-0.002
36.77,13.49,-0.002
36.82,13.58,-0.002
36.87,13.68,-0.002
36.91,13.77,-0.002
36.96,13.87,-0.002
37.01,13.96,-0.002
37.05,14.05,-0.002
37.10,14.15,-0.002
37.15,14.24,-0.002
37.19,14.33,-0.002
37.24,14.43,-0.002
37.29,14.52,-0.002
37.33,14.61,-0.002
37.38,14.71,-0.002
37.43,14.80,-0.002
37.47,14.89,-0.002
37.52,14.99,-0.002
37.57,15.08,-0.002
37.61,15.17,-0.002
37.66,15.27,-0.002
37.71,15.36,-0.002
37.75,15.45,-0.002
37.80,15.55,-0.002
37.85,15.64,-0.002
37.89,15.73,-0.002
37.94,15.83,-0.002
37.99,15.92,-0.002
38.03,16.01,-0.002
38.08,16.11,-0.002
38.13,16.20,-0.002
38.17,16.29,-0.002
38.22,16.39,-0.002
38.27,16.48,-0.002
38.31,16.57,-0.002
38.36,16.67,-0.002
38.41,16.76,-0.002
38.45,16.85,-0.002
38.50,16.95,-0.002
38.55,17.04,-0.002
38.59,17.13,-0.002
38.64,17.23,-0.002
38.69,17.32,-0.002
38.73,17.41,-0.002
38.78,17.51,-0.002
38.83,17.60,-0.002
38.87,17.69,-0.002
38.92,17.79,-0.002
38.97,17.88,-0.002
39.01,17.97,-0.002
39.06,18.07,-0.002
39.11,18.16,-0.002
39.15,18.25,-0.002
39.20,18.35,-0.002
39.25,18.44,-0.002
39.29,18.53,-0.002
39.34,18.63,-0.002
39.39,18.72,-0.002
39.43,18.81,-0.002
39.48,18.91,-0.002
39.53,19.00,-0.002
39.57,19.09,-0.002
39.62,19.19,-0.002
39.67,19.28,-0.002
39.71,19.37,-0.002
39.76,19.47,-0.002
39.81,19.56,-0.002
39.85,19.65,-0.002
39.90,19.75,-0.002
39.95,19.84,-0.002
39.99,19.93,-0.002
40.04,20.03,-0.002
40.09,20.12,-0.002
40.13,20.21,-0.002
40.18,20.31,-0.002
40.23,20.40,-0.002
40.27,20.49,-0.002
40.32,20.59,-0.002
40.37,20.68,-0.002
40.41,20.78,-0.002
40.46,20.87,-0.002
40.51,20.96,-0.002
40.55,21.06,-0.002
40.60,21.15,-0.002
40.65,21.24,-0.002
40.69,21.33,-0.002
40.74,21.43,-0.002
40.79,21.52,-0.002
40.83,21.61,-0.002
40.88,21.71,-0.002
40.93,21.80,-0.002
40.97,21.89,-0.002
41.02,21.99,-0.002
41.07,22.08,-0.002
41.11,22.17,-0.002
41.16,22.27,-0.002
41.21,22.36,-0.002
41.25,22.46,-0.002
41.30,22.55,-0.002
41.35,22.64,-0.002
41.39,22.74,-0.002
41.44,22.83,-0.002
41.49,22.92,-0.002
41.53,23.02,-0.002
41.58,23.11,-0.002
41.63,23.20,-0.002
41.67,23.30,-0.002
41.72,23.39,-0.002
41.77,23.48,-0.002
41.81,23.58,-0.002
41.86,23.67,-0.002
41.91,23.76,-0.002
41.95,23.86,-0.002
42.00,23.95,-0.002
42.05,24.04,-0.002
42.09,24.14,-0.002
42.14,24.23,-0.002
42.19,24.32,-0.002
42.23,24.42,-0.002
42.28,24.51,-0.002
42.33,24.60,-0.002
42.37,24.70,-0.002
42.42,24.79,-0.002
42.47,24.88,-0.002
42.51,24.98,-0.002
42.56,25.07,-0.002
42.61,25.16,-0.002
42.65,25.26,-0.002
42.70,25.35,-0.002
42.75,25.44,-0.002
42.79,25.54,-0.002
42.84,25.63,-0.002
42.89,25.72,-0.002
42.93,25.82,-0.002
42.98,25.91,-0.002
43.03,26.00,-0.002
43.07,26.10,-0.002
43.12,26.19,-0.002
43.17,26.28,-0.002
43.21,26.38,-0.002
43.26,26.47,-0.002
43.31,26.56,-0.002
43.35,26.66,-0.002
43.40,26.75,-0.002
43.45,26.84,-0.002
43.49,26.94,-0.002
43.54,27.03,-0.002
43.59,27.12,-0.002
43.63,27.22,-0.002
43.68,27.31,-0.002
43.73,27.40,-0.002
43.77,27.50,-0.002
43.82,27.59,-0.002
43.87,27.68,-0.002
43.91,27.78,-0.002
43.96,27.87,-0.002
44.01,27.96,-0.002
44.05,28.06,-0.002
44.10,28.15,-0.002
44.15,28.25,-0.002
44.19,28.34,-0.002
44.24,28.43,-0.002
44.29,28.52,-0.002
44.33,28.62,-0.002
44.38,28.71,-0.002
44.43,28.80,-0.001
44.47,28.90,-0.002
44.52,28.99,-0.002
44.57,29.09,-0.002
44.61,29.18,-0.002
44.66,29.27,-0.002
44.71,29.36,-0.002
44.75,29.46,-0.001
44.80,29.55,-0.001
44.85,29.65,-0.001
44.89,29.74,-0.002
44.94,29.83,-0.002
44.99,29.93,-0.002
45.03,30.02,-0.002
45.08,30.11,-0.002
45.13,30.20,-0.002
45.17,30.30,-0.001
45.22,30.39,-0.001
45.27,30.48,-0.001
45.31,30.58,-0.001
45.36,30.67,-0.001
45.41,30.77,-0.001
45.45,30.86,-0.001
45.50,30.95,-0.001
45.55,31.05,-0.001
45.59,31.14,-0.001
45.64,31.23,-0.001
45.69,31.33,-0.001
45.73,31.42,-0.001
45.78,31.51,-0.001
45.83,31.61,-0.001
45.87,31.70,-0.001
45.92,31.79,-0.001
45.97,31.89,-0.001
46.01,31.98,-0.001
46.06,32.07,-0.001
46.11,32.17,-0.001
46.15,32.26,-0.001
46.20,32.35,-0.001
46.25,32.44,-0.001
46.29,32.54,-0.001
46.34,32.63,-0.001
46.39,32.72,-0.001
46.43,32.82,-0.001
46.48,32.91,-0.001
46.53,33.01,-0.001
46.57,33.10,-0.001
46.62,33.19,-0.001
46.67,33.29,-0.001
46.71,33.38,-0.001
46.76,33.47,0.000
46.81,33.57,0.000
46.85,33.66,0.000
46.90,33.75,0.000
46.95,33.85,0.000
46.99,33.94,0.000
47.04,34.03,-0.001
47.09,34.13,-0.001
47.13,34.22,-0.001
47.18,34.31,-0.001
47.23,34.41,-0.001
47.27,34.50,-0.001
47.32,34.59,-0.001
47.37,34.69,-0.001
47.41,34.78,-0.001
47.46,34.87,-0.001
47.51,34.97,-0.001
47.55,35.06,0.000
47.60,35.15,0.000
47.65,35.25,0.000
47.69,35.34,0.000
47.74,35.43,0.000
47.79,35.53,0.000
47.83,35.62,0.000
47.88,35.71,0.000
47.93,35.81,0.000
47.97,35.90,0.000
48.02,35.99,0.000
48.07,36.09,0.000
48.11,36.18,0.000
48.16,36.27,0.000
48.21,36.37,0.000
48.25,36.46,0.000
48.30,36.55,0.000
48.35,36.65,0.000
48.39,36.74,0.000
48.44,36.83,0.000
48.49,36.93,0.000
48.53,37.02,0.000
48.58,37.11,0.000
48.63,37.21,0.000
48.67,37.30,0.000
48.72,37.40,0.000
48.77,37.49,0.000
48.81,37.58,0.000
48.86,37.67,0.000
48.91,37.77,0.000
48.95,37.86,0.000
49.00,37.95,0.000
49.05,38.05,0.000
49.09,38.14,0.000
49.14,38.24,0.000
49.19,38.33,0.000
49.23,38.42,0.000
49.28,38.51,0.000
49.33,38.61,0.000
49.37,38.70,0.000
49.42,38.79,0.000
49.47,38.89,0.000
49.51,38.98,0.001
49.56,39.07,0.001
49.61,39.17,0.001
49.65,39.26,0.001
49.70,39.35,0.001
49.75,39.45,0.001
49.79,39.54,0.001
49.84,39.63,0.001
49.89,39.73,0.001
49.93,39.82,0.001
49.98,39.91,0.001
50.03,40.01,0.001
50.07,40.10,0.001
50.12,40.19,0.001
50.17,40.29,0.001
50.21,40.38,0.001
50.26,40.48,0.002
50.31,40.57,0.002
50.35,40.66,0.002
50.40,40.75,0.002
50.45,40.85,0.002
50.49,40.94,0.002
50.54,41.04,0.002
50.59,41.13,0.002
50.63,41.22,0.002
50.68,41.32,0.002
50.73,41.41,0.002
50.77,41.50,0.002
50.82,41.59,0.002
50.87,41.69,0.003
50.91,41.78,0.003
50.96,41.88,0.003
51.01,41.97,0.003
51.05,42.06,0.003
51.10,42.16,0.003
51.15,42.25,0.003
51.19,42.34,0.003
51.24,42.43,0.003
51.29,42.53,0.003
51.33,42.62,0.004
51.38,42.71,0.004
51.43,42.81,0.004
51.47,42.90,0.004
51.52,42.99,0.004
51.57,43.09,0.004
51.61,43.18,0.004
51.66,43.27,0.004
51.71,43.37,0.005
51.75,43.46,0.005
51.80,43.55,0.005
51.85,43.65,0.005
51.89,43.74,0.005
51.94,43.84,0.005
51.99,43.93,0.006
52.03,44.02,0.006
52.08,44.12,0.006
52.13,44.21,0.006
52.17,44.30,0.006
52.22,44.40,0.006
52.27,44.49,0.007
52.31,44.58,0.007
52.36,44.67,0.007
52.41,44.77,0.007
52.45,44.86,0.008
52.50,44.95,0.008
52.55,45.05,0.008
52.59,45.14,0.008
52.64,45.23,0.009
52.69,45.33,0.009
52.73,45.42,0.009
52.78,45.51,0.009
52.83,45.61,0.010
52.87,45.70,0.010
52.92,45.79,0.011
52.97,45.89,0.011
53.01,45.98,0.011
53.06,46.07,0.012
53.11,46.17,0.012
53.15,46.26,0.013
53.20,46.35,0.013
53.25,46.45,0.014
53.29,46.54,0.014
53.34,46.63,0.015
53.39,46.73,0.015
53.43,46.82,0.015
53.48,46.91,0.016
53.53,47.01,0.017
53.57,47.10,0.018
53.62,47.19,0.019
53.67,47.29,0.019
53.71,47.38,0.020
53.76,47.47,0.021
53.81,47.56,0.022
53.85,47.66,0.023
53.90,47.75,0.024
53.95,47.84,0.025
53.99,47.94,0.026
54.04,48.03,0.027
54.09,48.12,0.028
54.13,48.21,0.030
54.18,48.31,0.031
54.23,48.40,0.032
54.27,48.49,0.034
54.32,48.59,0.035
54.37,48.68,0.037
54.41,48.77,0.039
54.46,48.86,0.042
54.51,48.96,0.044
54.55,49.05,0.046
54.60,49.14,0.049
54.65,49.24,0.053
54.69,49.33,0.057
54.74,49.42,0.062
54.79,49.51,0.066
54.83,49.61,0.072
54.88,49.70,0.077
54.93,49.79,0.082
54.97,49.88,0.090
55.02,49.97,0.097
55.07,50.07,0.105
55.11,50.16,0.114
55.16,50.25,0.122
55.21,50.34,0.134
55.25,50.43,0.143
55.30,50.52,0.155
55.35,50.61,0.168
55.39,50.70,0.181
55.44,50.79,0.196
55.49,50.88,0.213
55.53,50.97,0.230
55.58,51.06,0.250
55.63,51.15,0.272
55.67,51.23,0.296
55.72,51.32,0.320
55.77,51.41,0.349
55.81,51.50,0.380
55.86,51.58,0.418
55.91,51.66,0.456
55.95,51.75,0.503
56.00,51.83,0.560
56.05,51.91,0.628
56.09,51.98,0.705
56.14,52.05,0.796
56.19,52.12,0.908
56.23,52.19,0.988
56.28,52.26,1.100
56.33,52.33,1.163
56.37,52.41,1.220
56.42,52.48,1.342
56.47,52.53,1.604
56.51,52.57,1.793
56.56,52.62,1.909
56.61,52.68,2.079
56.65,52.74,2.133
56.70,52.83,2.106
56.75,52.90,2.300
56.79,52.97,2.317
56.84,53.09,2.019
56.89,53.28,1.537
56.93,53.49,0.983
56.98,53.70,0.633
57.03,53.86,0.423
57.07,54.01,0.285
57.12,54.13,0.191
57.17,54.25,0.131
57.21,54.36,0.090
57.26,54.46,0.063
57.31,54.56,0.046
57.35,54.66,0.035
57.40,54.75,0.030
57.45,54.85,0.024
57.49,54.94,0.022
57.54,55.04,0.020
57.59,55.13,0.019
57.63,55.22,0.018
57.68,55.32,0.017
57.73,55.41,0.016
57.77,55.50,0.015
57.82,55.60,0.014
57.87,55.69,0.014
57.91,55.78,0.013
57.96,55.88,0.013
58.01,55.97,0.012
58.05,56.07,0.012
58.10,56.16,0.012
58.15,56.25,0.011
58.19,56.34,0.011
58.24,56.44,0.011
58.29,56.53,0.011
58.33,56.62,0.011
58.38,56.72,0.011
58.43,56.81,0.011
58.47,56.91,0.011
58.52,57.00,0.011
58.57,57.09,0.011
58.61,57.18,0.011
58.66,57.28,0.011
58.71,57.37,0.011
58.75,57.46,0.010
58.80,57.56,0.011
58.85,57.65,0.011
58.89,57.75,0.011
58.94,57.84,0.010
58.99,57.93,0.010
59.03,58.03,0.010
59.08,58.12,0.010
59.13,58.21,0.010
59.17,58.31,0.010
59.22,58.40,0.010
59.27,58.49,0.010
59.31,58.58,0.010
59.36,58.68,0.010
59.41,58.77,0.010
59.45,58.86,0.010
59.50,58.96,0.010
59.55,59.05,0.010
59.59,59.14,0.010
59.64,59.24,0.010
59.69,59.33,0.010
59.73,59.43,0.010
59.78,59.52,0.010
59.83,59.61,0.010
59.87,59.71,0.010
59.92,59.80,0.010
59.97,59.89,0.010
60.01,59.98,0.010
60.06,60.08,0.010
60.11,60.17,0.010
60.15,60.27,0.010
60.20,60.36,0.010
60.25,60.45,0.010
60.29,60.55,0.010
60.34,60.64,0.010
60.39,60.73,0.010
60.43,60.83,0.010
60.48,60.92,0.010
60.53,61.01,0.010
60.57,61.11,0.010
60.62,61.20,0.010
60.67,61.29,0.010
60.71,61.39,0.010
60.76,61.48,0.010
60.81,61.57,0.010
60.85,61.67,0.010
60.90,61.76,0.010
60.95,61.85,0.010
60.99,61.95,0.010
61.04,62.04,0.010
61.09,62.13,0.010
61.13,62.23,0.010
61.18,62.32,0.010
61.23,62.41,0.010
61.27,62.51,0.010
61.32,62.60,0.010
61.37,62.69,0.010
61.41,62.79,0.010
61.46,62.88,0.010
61.51,62.97,0.010
61.55,63.07,0.010
61.60,63.16,0.010
61.65,63.25,0.010
61.69,63.35,0.010
61.74,63.44,0.010
61.79,63.53,0.010
61.83,63.63,0.010
61.88,63.72,0.010
61.93,63.81,0.010
61.97,63.91,0.010
62.02,64.00,0.010
62.07,64.09,0.010
62.11,64.19,0.010
62.16,64.28,0.010
62.21,64.37,0.010
62.25,64.47,0.010
62.30,64.56,0.010
62.35,64.65,0.010
62.39,64.75,0.010
62.44,64.84,0.010
62.49,64.93,0.010
62.53,65.03,0.010
62.58,65.12,0.010
62.63,65.21,0.010
62.67,65.31,0.010
62.72,65.40,0.010
62.77,65.49,0.010
62.81,65.59,0.010
62.86,65.68,0.010
62.91,65.78,0.010
62.95,65.87,0.010
63.00,65.96,0.010
63.05,66.05,0.010
63.09,66.15,0.010
63.14,66.24,0.010
63.19,66.33,0.010
63.23,66.43,0.010
63.28,66.52,0.010
63.33,66.61,0.010
63.37,66.71,0.010
63.42,66.80,0.010
63.47,66.89,0.010
63.51,66.99,0.010
63.56,67.08,0.010
63.61,67.17,0.010
63.65,67.27,0.010
63.70,67.36,0.010
63.75,67.45,0.010
63.79,67.55,0.010
63.84,67.64,0.010
63.89,67.73,0.010
63.93,67.83,0.010
63.98,67.92,0.010
64.03,68.02,0.010
64.07,68.11,0.010
64.12,68.20,0.010
64.17,68.30,0.010
64.21,68.39,0.010
64.26,68.48,0.010
64.31,68.58,0.010
64.35,68.67,0.010
64.40,68.76,0.010
64.45,68.86,0.010
64.49,68.95,0.010
64.54,69.04,0.010
64.59,69.14,0.010
64.63,69.23,0.010
64.68,69.32,0.010
64.73,69.42,0.010
64.77,69.51,0.010
64.82,69.60,0.010
64.87,69.70,0.010
64.91,69.79,0.010
64.96,69.88,0.010
65.01,69.98,0.010
65.05,70.07,0.010
65.10,70.16,0.010
65.15,70.26,0.010
65.19,70.35,0.010
65.24,70.44,0.010
65.29,70.54,0.010
65.33,70.63,0.010
65.38,70.72,0.010
65.43,70.82,0.010
65.47,70.91,0.010
65.52,71.00,0.010
65.57,71.10,0.010
65.61,71.19,0.010
65.66,71.28,0.010
65.71,71.38,0.010
65.75,71.47,0.010
65.80,71.56,0.010
65.85,71.66,0.010
65.89,71.75,0.010
65.94,71.84,0.010
65.99,71.94,0.010
66.03,72.03,0.010
66.08,72.12,0.010
66.13,72.22,0.010
66.17,72.31,0.010
66.22,72.40,0.010
66.27,72.50,0.010
66.31,72.59,0.010
66.36,72.68,0.010
66.41,72.78,0.010
66.45,72.87,0.010
66.50,72.96,0.010
66.55,73.06,0.010
66.59,73.15,0.010
66.64,73.24,0.010
66.69,73.34,0.010
66.73,73.43,0.010
66.78,73.52,0.010
66.83,73.62,0.010
66.87,73.71,0.010
66.92,73.80,0.010
66.97,73.90,0.010
67.01,73.99,0.010
67.06,74.08,0.010
67.11,74.18,0.010
67.15,74.27,0.010
67.20,74.36,0.010
67.25,74.46,0.010
67.29,74.55,0.010
67.34,74.64,0.010
67.39,74.74,0.010
67.43,74.83,0.010
67.48,74.92,0.010
67.53,75.02,0.010
67.57,75.11,0.010
67.62,75.20,0.010
67.67,75.30,0.010
67.71,75.39,0.010
67.76,75.48,0.010
67.81,75.58,0.010
67.85,75.67,0.010
67.90,75.76,0.010
67.95,75.86,0.010
67.99,75.95,0.010
68.04,76.04,0.010
68.09,76.14,0.010
68.13,76.23,0.010
68.18,76.32,0.010
68.23,76.42,0.010
68.27,76.51,0.010
68.32,76.60,0.010
68.37,76.70,0.010
68.41,76.79,0.010
68.46,76.88,0.010
68.51,76.98,0.010
68.55,77.07,0.010
68.60,77.16,0.010
68.65,77.26,0.009
68.69,77.35,0.009
68.74,77.44,0.010
68.79,77.54,0.010
68.83,77.63,0.010
68.88,77.72,0.009
68.93,77.82,0.010
68.97,77.91,0.010
69.02,78.00,0.009
69.07,78.10,0.009
69.11,78.19,0.010
69.16,78.28,0.010
69.21,78.38,0.010
69.25,78.47,0.010
69.30,78.57,0.010
69.35,78.66,0.010
69.39,78.75,0.010
69.44,78.84,0.010
69.49,78.94,0.010
69.53,79.03,0.010
69.58,79.12,0.009
69.63,79.22,0.009
69.67,79.31,0.009
69.72,79.40,0.009
69.77,79.50,0.009
69.81,79.59,0.009
69.86,79.68,0.010
69.91,79.78,
69.95,79.87,
69.96,,

[step]
Ramp 20.00 °C/min to -60.00 °C
Time,Temperature,Heat Flow (Normalized)
min,°C,W/g
70.96,80.12,-0.047
70.97,80.12,-0.047
70.97,80.12,-0.047
70.98,80.12,-0.047
70.98,80.12,-0.047
70.99,80.12,-0.047
70.99,80.12,-0.047
71.00,80.11,-0.047
71.00,80.11,-0.040
71.01,80.10,-0.019
71.01,80.10,0.000
71.02,80.09,0.025
71.02,80.07,0.053
71.03,80.06,0.085
71.03,80.04,0.120
71.04,80.02,0.157
71.04,79.99,0.194
71.05,79.97,0.231
71.05,79.93,0.267
71.06,79.90,0.302
71.06,79.86,0.332
71.07,79.82,0.359
71.07,79.78,0.382
71.08,79.73,0.402
71.08,79.68,0.417
71.09,79.63,0.427
71.09,79.57,0.433
71.10,79.51,0.433
71.10,79.45,0.429
71.11,79.39,0.421
71.11,79.32,0.408
71.12,79.25,0.394
71.12,79.18,0.376
71.13,79.11,0.354
71.13,79.04,0.328
71.14,78.97,0.299
71.14,78.89,0.271
71.15,78.81,0.241
71.15,78.74,0.210
71.16,78.66,0.181
71.16,78.58,0.149
71.17,78.50,0.117
71.17,78.42,0.083
71.18,78.33,0.050
71.18,78.25,0.021
71.19,78.17,-0.009
71.19,78.08,-0.037
71.20,78.00,-0.062
71.20,77.91,-0.087
71.21,77.83,-0.113
71.21,77.74,-0.137
71.22,77.65,-0.157
71.22,77.57,-0.178
71.23,77.48,-0.197
71.23,77.39,-0.217
71.24,77.30,-0.234
71.24,77.21,-0.250
71.25,77.12,-0.263
71.25,77.04,-0.277
71.26,76.95,-0.292
71.26,76.86,-0.306
71.27,76.77,-0.317
71.27,76.68,-0.327
71.28,76.58,-0.336
71.28,76.49,-0.347
71.29,76.40,-0.358
71.29,76.31,-0.368
71.30,76.22,-0.377
71.30,76.13,-0.385
71.31,76.03,-0.391
71.31,75.94,-0.399
71.32,75.85,-0.408
71.32,75.75,-0.415
71.33,75.66,-0.422
71.33,75.57,-0.429
71.34,75.47,-0.436
71.34,75.38,-0.441
71.35,75.28,-0.447
71.35,75.19,-0.453
71.36,75.09,-0.460
71.36,75.00,-0.464
71.37,74.91,-0.469
71.37,74.81,-0.475
71.38,74.71,-0.478
71.38,74.62,-0.484
71.39,74.52,-0.488
71.39,74.43,-0.493
71.40,74.33,-0.497
71.40,74.24,-0.499
71.41,74.14,-0.503
71.41,74.04,-0.508
71.42,73.95,-0.511
71.42,73.85,-0.513
71.43,73.76,-0.517
71.43,73.66,-0.522
71.44,73.56,-0.524
71.44,73.47,-0.526
71.45,73.37,-0.527
71.45,73.27,-0.531
71.46,73.18,-0.534
71.46,73.08,-0.537
71.47,72.98,-0.538
71.47,72.88,-0.540
71.48,72.79,-0.542
71.48,72.69,-0.544
71.49,72.59,-0.546
71.49,72.50,-0.547
71.50,72.40,-0.549
71.50,72.30,-0.551
71.51,72.20,-0.553
71.51,72.11,-0.554
71.52,72.01,-0.555
71.52,71.91,-0.557
71.53,71.81,-0.559
71.53,71.72,-0.560
71.54,71.62,-0.560
71.54,71.52,-0.560
71.55,71.42,-0.561
71.55,71.32,-0.562
71.56,71.23,-0.563
71.56,71.13,-0.564
71.57,71.03,-0.565
71.57,70.93,-0.567
71.58,70.84,-0.569
71.58,70.74,-0.569
71.59,70.64,-0.570
71.59,70.54,-0.571
71.60,70.44,-0.573
71.60,70.34,-0.573
71.61,70.25,-0.574
71.61,70.15,-0.574
71.62,70.05,-0.575
71.62,69.95,-0.575
71.63,69.85,-0.575
71.63,69.75,-0.576
71.64,69.66,-0.576
71.64,69.56,-0.577
71.65,69.46,-0.578
71.65,69.36,-0.578
71.66,69.26,-0.578
71.66,69.16,-0.579
71.67,69.07,-0.579
71.67,68.97,-0.580
71.68,68.87,-0.580
71.68,68.77,-0.581
71.69,68.67,-0.581
71.69,68.57,-0.581
71.70,68.47,-0.581
71.70,68.37,-0.582
71.71,68.28,-0.582
71.71,68.18,-0.582
71.72,68.08,-0.582
71.72,67.98,-0.583
71.73,67.88,-0.583
71.73,67.78,-0.583
71.74,67.69,-0.583
71.74,67.59,-0.583
71.75,67.49,-0.584
71.75,67.39,-0.584
71.76,67.29,-0.584
71.76,67.19,-0.584
71.77,67.09,-0.584
71.77,66.99,-0.585
71.78,66.89,-0.585
71.78,66.79,-0.585
71.79,66.70,-0.585
71.79,66.60,-0.585
71.80,66.50,-0.585
71.80,66.40,-0.585
71.81,66.30,-0.585
71.81,66.20,-0.586
71.82,66.10,-0.586
71.82,66.00,-0.586
71.83,65.90,-0.586
71.83,65.81,-0.586
71.84,65.71,-0.586
71.84,65.61,-0.586
71.85,65.51,-0.586
71.85,65.41,-0.587
71.86,65.31,-0.587
71.86,65.21,-0.587
71.87,65.11,-0.587
71.87,65.01,-0.587
71.88,64.91,-0.587
71.88,64.82,-0.587
71.89,64.72,-0.588
71.89,64.62,-0.588
71.90,64.52,-0.588
71.90,64.42,-0.588
71.91,64.32,-0.588
71.91,64.22,-0.588
71.92,64.12,-0.588
71.92,64.02,-0.588
71.93,63.92,-0.588
71.93,63.82,-0.588
71.94,63.72,-0.589
71.94,63.63,-0.589
71.95,63.53,-0.589
71.95,63.43,-0.589
71.96,63.33,-0.589
71.96,63.23,-0.589
71.97,63.13,-0.589
71.97,63.03,-0.589
71.98,62.93,-0.589
71.98,62.83,-0.589
71.99,62.73,-0.589
71.99,62.63,-0.589
72.00,62.53,-0.589
72.00,62.44,-0.589
72.01,62.34,-0.590
72.01,62.24,-0.590
72.02,62.14,-0.590
72.02,62.04,-0.590
72.03,61.94,-0.590
72.03,61.84,-0.590
72.04,61.74,-0.590
72.04,61.64,-0.590
72.05,61.54,-0.590
72.05,61.44,-0.590
72.06,61.34,-0.590
72.06,61.24,-0.590
72.07,61.14,-0.590
72.07,61.05,-0.590
72.08,60.95,-0.590
72.08,60.85,-0.590
72.09,60.75,-0.590
72.09,60.65,-0.590
72.10,60.55,-0.590
72.10,60.45,-0.590
72.11,60.35,-0.590
72.11,60.25,-0.590
72.12,60.15,-0.590
72.12,60.05,-0.590
72.13,59.95,-0.590
72.13,59.85,-0.590
72.14,59.75,-0.590
72.14,59.65,-0.590
72.15,59.55,-0.590
72.15,59.46,-0.590
72.16,59.36,-0.590
72.16,59.26,-0.590
72.17,59.16,-0.591
72.17,59.06,-0.590
72.18,58.96,-0.590
72.18,58.86,-0.590
72.19,58.76,-0.591
72.19,58.66,-0.591
72.20,58.56,-0.590
72.20,58.46,-0.590
72.21,58.36,-0.590
72.21,58.26,-0.590
72.22,58.16,-0.590
72.22,58.06,-0.590
72.23,57.96,-0.590
72.23,57.86,-0.590
72.24,57.76,-0.590
72.24,57.67,-0.590
72.25,57.57,-0.590
72.25,57.46,-0.590
72.26,57.37,-0.590
72.26,57.27,-0.590
72.27,57.17,-0.590
72.27,57.07,-0.590
72.28,56.97,-0.590
72.28,56.87,-0.590
72.29,56.77,-0.590
72.29,56.67,-0.590
72.30,56.57,-0.590
72.30,56.47,-0.590
72.31,56.37,-0.590
72.31,56.27,-0.590
72.32,56.17,-0.590
72.32,56.07,-0.590
72.33,55.97,-0.590
72.33,55.87,-0.590
72.34,55.77,-0.589
72.34,55.67,-0.589
72.35,55.58,-0.589
72.35,55.48,-0.589
72.36,55.38,-0.589
72.36,55.28,-0.589
72.37,55.18,-0.589
72.37,55.08,-0.589
72.38,54.98,-0.589
72.38,54.88,-0.589
72.39,54.78,-0.589
72.39,54.68,-0.589
72.40,54.58,-0.589
72.40,54.48,-0.589
72.41,54.38,-0.589
72.41,54.28,-0.589
72.42,54.18,-0.588
72.42,54.08,-0.588
72.43,53.98,-0.588
72.43,53.88,-0.588
72.44,53.78,-0.588
72.44,53.69,-0.588
72.45,53.58,-0.588
72.45,53.49,-0.588
72.46,53.39,-0.588
72.46,53.29,-0.588
72.47,53.19,-0.588
72.47,53.09,-0.588
72.48,52.99,-0.587
72.48,52.89,-0.587
72.49,52.79,-0.587
72.49,52.69,-0.587
72.50,52.59,-0.587
72.50,52.49,-0.587
72.51,52.39,-0.587
72.51,52.29,-0.587
72.52,52.19,-0.586
72.52,52.09,-0.586
72.53,51.99,-0.586
72.53,51.89,-0.586
72.54,51.79,-0.586
72.54,51.69,-0.586
72.55,51.59,-0.586
72.55,51.49,-0.586
72.56,51.40,-0.586
72.56,51.30,-0.586
72.57,51.20,-0.586
72.57,51.10,-0.586
72.58,51.00,-0.585
72.58,50.90,-0.585
72.59,50.80,-0.585
72.59,50.70,-0.585
72.60,50.60,-0.585
72.60,50.50,-0.585
72.61,50.40,-0.585
[...]
179.90,-20.45,-0.007
179.95,-20.36,-0.006
179.99,-20.26,-0.005
180.04,-20.16,-0.004
180.09,-20.07,-0.003
180.14,-19.97,-0.003
180.19,-19.88,-0.002
180.23,-19.78,-0.002
180.28,-19.68,-0.002
180.33,-19.58,-0.001
180.38,-19.49,-0.001
180.43,-19.39,-0.001
180.48,-19.30,0.000
180.53,-19.20,0.000
180.57,-19.10,0.000
180.62,-19.01,0.000
180.67,-18.91,0.000
180.72,-18.81,0.001
180.77,-18.71,0.001
180.82,-18.62,0.001
180.86,-18.52,0.001
180.91,-18.42,0.001
180.96,-18.33,0.001
181.01,-18.23,0.001
181.06,-18.14,0.001
181.10,-18.04,0.001
181.15,-17.94,0.001
181.20,-17.85,0.001
181.25,-17.75,0.001
181.30,-17.65,0.001
181.35,-17.55,0.001
181.40,-17.46,0.001
181.44,-17.36,0.002
181.49,-17.26,0.002
181.54,-17.17,0.002
181.59,-17.07,0.002
181.64,-16.97,0.002
181.68,-16.88,0.002
181.73,-16.78,0.002
181.78,-16.68,0.002
181.83,-16.59,0.002
181.88,-16.49,0.002
181.93,-16.39,0.002
181.98,-16.30,0.002
182.02,-16.20,0.002
182.07,-16.10,0.002
182.12,-16.01,0.002
182.17,-15.91,0.002
182.22,-15.81,0.002
182.27,-15.72,0.002
182.31,-15.62,0.002
182.36,-15.52,0.002
182.41,-15.43,0.002
182.46,-15.33,0.002
182.51,-15.23,0.002
182.55,-15.14,0.002
182.60,-15.04,0.002
182.65,-14.94,0.002
182.70,-14.85,0.002
182.75,-14.75,0.002
182.80,-14.65,0.002
182.85,-14.56,0.002
182.89,-14.46,0.002
182.94,-14.36,0.002
182.99,-14.27,0.002
183.04,-14.17,0.002
183.09,-14.07,0.002
183.13,-13.98,0.002
183.18,-13.88,0.002
183.23,-13.78,0.002
183.28,-13.69,0.002
183.33,-13.59,0.002
183.38,-13.49,0.002
183.43,-13.40,0.002
183.47,-13.30,0.002
183.52,-13.20,0.002
183.57,-13.11,0.002
183.62,-13.01,0.002
183.67,-12.91,0.002
183.72,-12.82,0.002
183.76,-12.72,0.002
183.81,-12.62,0.002
183.86,-12.53,0.002
183.91,-12.43,0.002
183.96,-12.33,0.002
184.00,-12.24,0.002
184.05,-12.14,0.002
184.10,-12.04,0.002
184.15,-11.95,0.002
184.20,-11.85,0.002
184.25,-11.75,0.002
184.30,-11.66,0.002
184.34,-11.56,0.002
184.39,-11.46,0.002
184.44,-11.37,0.002
184.49,-11.27,0.002
184.54,-11.17,0.002
184.58,-11.07,0.002
184.63,-10.98,0.002
184.68,-10.88,0.002
184.73,-10.79,0.002
184.78,-10.69,0.002
184.83,-10.59,0.002
184.88,-10.50,0.002
184.92,-10.40,0.002
184.97,-10.30,0.002
185.02,-10.20,0.002
185.07,-10.11,0.002
185.12,-10.01,0.002
185.17,-9.91,0.002
185.21,-9.82,0.002
185.26,-9.72,0.002
185.31,-9.62,0.002
185.36,-9.53,0.002
185.41,-9.43,0.002
185.45,-9.33,0.002
185.50,-9.24,0.002
185.55,-9.14,0.002
185.60,-9.04,0.002
185.65,-8.95,0.002
185.70,-8.85,0.001
185.75,-8.75,0.001
185.79,-8.66,0.002
185.84,-8.56,0.002
185.89,-8.46,0.001
185.94,-8.37,0.002
185.99,-8.27,0.002
186.03,-8.17,0.002
186.08,-8.08,0.001
186.13,-7.98,0.001
186.18,-7.88,0.001
186.23,-7.79,0.001
186.28,-7.69,0.001
186.33,-7.59,0.001
186.37,-7.50,0.001
186.42,-7.40,0.001
186.47,-7.30,0.001
186.52,-7.21,0.001
186.57,-7.11,0.001
186.62,-7.01,0.001
186.66,-6.92,0.001
186.71,-6.82,0.001
186.76,-6.72,0.001
186.81,-6.63,0.001
186.86,-6.53,0.001
186.90,-6.43,0.001
186.95,-6.34,0.001
187.00,-6.24,0.001
187.05,-6.14,0.001
187.10,-6.05,0.001
187.15,-5.95,0.001
187.20,-5.85,0.001
187.24,-5.76,0.001
187.29,-5.66,0.001
187.34,-5.56,0.001
187.39,-5.46,0.001
187.44,-5.37,0.001
187.48,-5.27,0.001
187.53,-5.18,0.001
187.58,-5.08,0.001
187.63,-4.98,0.001
187.68,-4.89,0.001
187.73,-4.79,0.001
187.78,-4.69,0.001
187.82,-4.59,0.001
187.87,-4.50,0.001
187.92,-4.40,0.001
187.97,-4.30,0.001
188.02,-4.21,0.001
188.07,-4.11,0.001
188.11,-4.02,0.001
188.16,-3.92,0.001
188.21,-3.82,0.001
188.26,-3.73,0.001
188.31,-3.63,0.001
188.35,-3.53,0.001
188.40,-3.43,0.001
188.45,-3.34,0.001
188.50,-3.24,0.001
188.55,-3.14,0.001
188.60,-3.05,0.001
188.65,-2.95,0.001
188.69,-2.85,0.001
188.74,-2.76,0.001
188.79,-2.66,0.001
188.84,-2.56,0.001
188.89,-2.47,0.001
188.93,-2.37,0.001
188.98,-2.27,0.001
189.03,-2.18,0.001
189.08,-2.08,0.001
189.13,-1.98,0.001
189.18,-1.89,0.001
189.23,-1.79,0.001
189.27,-1.69,0.001
189.32,-1.60,0.001
189.37,-1.50,0.001
189.42,-1.40,0.001
189.47,-1.31,0.001
189.52,-1.21,0.001
189.56,-1.11,0.001
189.61,-1.01,0.001
189.66,-0.92,0.001
189.71,-0.82,0.001
189.76,-0.73,0.001
189.80,-0.63,0.001
189.85,-0.53,0.001
189.90,-0.44,0.001
189.95,-0.34,0.001
190.00,-0.24,0.001
190.05,-0.14,0.001
190.10,-0.05,0.001
190.14,0.05,0.001
190.19,0.15,0.001
190.24,0.24,0.001
190.29,0.34,0.001
190.34,0.44,0.001
190.38,0.53,0.001
190.43,0.63,0.001
190.48,0.72,0.001
190.53,0.82,0.001
190.58,0.92,0.001
190.63,1.01,0.001
190.68,1.11,0.001
190.72,1.21,0.001
190.77,1.31,0.001
190.82,1.40,0.001
190.87,1.50,0.001
190.92,1.60,0.001
190.97,1.69,0.001
191.01,1.79,0.001
191.06,1.89,0.001
191.11,1.98,0.001
191.16,2.08,0.001
191.21,2.18,0.001
191.25,2.27,0.001
191.30,2.37,0.001
191.35,2.46,0.001
191.40,2.56,0.001
191.45,2.66,0.001
191.50,2.76,0.001
191.55,2.85,0.001
191.59,2.95,0.001
191.64,3.05,0.001
191.69,3.14,0.001
191.74,3.24,0.001
191.79,3.34,0.001
191.83,3.43,0.001
191.88,3.53,0.001
191.93,3.63,0.001
191.98,3.72,0.001
192.03,3.82,0.000
192.08,3.92,0.000
192.13,4.01,0.000
192.17,4.11,0.000
192.22,4.21,0.000
192.27,4.30,0.000
192.32,4.40,0.000
192.37,4.50,0.000
192.42,4.59,0.000
192.46,4.69,0.000
192.51,4.79,0.000
192.56,4.88,0.000
192.61,4.98,0.000
192.66,5.08,0.000
192.70,5.17,0.000
192.75,5.27,0.000
192.80,5.37,0.000
192.85,5.46,0.000
192.90,5.56,0.000
192.95,5.66,0.000
193.00,5.75,0.000
193.04,5.85,0.000
193.09,5.95,0.000
193.14,6.04,0.000
193.19,6.14,0.000
193.24,6.24,0.000
193.28,6.33,0.000
193.33,6.43,0.000
193.38,6.53,0.000
193.43,6.62,0.000
193.48,6.72,0.000
193.53,6.82,0.000
193.58,6.91,0.000
193.62,7.01,0.000
193.67,7.11,0.000
193.72,7.20,0.000
193.77,7.30,0.000
193.82,7.40,0.000
193.87,7.50,0.000
193.91,7.59,0.000
193.96,7.69,0.000
194.01,7.78,0.000
194.06,7.88,0.000
194.11,7.98,0.000
194.15,8.07,0.000
194.20,8.17,0.000
194.25,8.27,0.000
194.30,8.37,0.000
194.35,8.46,0.000
194.40,8.56,0.000
194.45,8.66,0.000
194.49,8.75,0.000
194.54,8.85,0.000
194.59,8.95,0.000
194.64,9.04,0.000
194.69,9.14,0.000
194.73,9.24,0.000
194.78,9.33,0.000
194.83,9.43,0.000
194.88,9.53,0.000
194.93,9.62,0.000
194.98,9.72,0.000
195.03,9.82,0.000
195.07,9.91,0.000
195.12,10.01,0.000
195.17,10.10,0.000
195.22,10.20,0.000
195.27,10.30,0.000
195.32,10.40,0.000
195.36,10.49,0.000
195.41,10.59,0.000
195.46,10.69,0.000
195.51,10.79,0.000
195.56,10.88,0.000
195.60,10.98,0.000
195.65,11.07,0.000
195.70,11.17,0.000
195.75,11.27,0.000
195.80,11.36,0.000
195.85,11.46,0.000
195.90,11.56,0.000
195.94,11.65,0.000
195.99,11.75,0.000
196.04,11.85,0.000
196.09,11.95,0.000
196.14,12.04,0.000
196.18,12.14,0.000
196.23,12.23,0.000
196.28,12.33,0.000
196.33,12.43,0.000
196.38,12.52,0.000
196.43,12.62,0.000
196.48,12.72,-0.001
196.52,12.81,-0.001
196.57,12.91,-0.001
196.62,13.01,-0.001
196.67,13.11,-0.001
196.72,13.20,-0.001
196.77,13.30,-0.001
196.81,13.40,-0.001
196.86,13.49,-0.001
196.91,13.59,-0.001
196.96,13.69,-0.001
197.01,13.78,-0.001
197.05,13.88,-0.001
197.10,13.97,-0.001
197.15,14.07,-0.001
197.20,14.17,-0.001
197.25,14.27,-0.001
197.30,14.36,-0.001
197.35,14.46,-0.002
197.39,14.56,-0.002
197.44,14.65,-0.002
197.49,14.75,-0.002
197.54,14.85,-0.002
197.59,14.94,-0.002
197.63,15.04,-0.002
197.68,15.14,-0.002
197.73,15.23,-0.003
197.78,15.33,-0.003
197.83,15.43,-0.003
197.88,15.52,-0.003
197.93,15.62,-0.003
197.97,15.72,-0.003
198.02,15.81,-0.004
198.07,15.91,-0.004
198.12,16.01,-0.004
198.17,16.10,-0.004
198.22,16.20,-0.005
198.26,16.30,-0.005
198.31,16.39,-0.005
198.36,16.49,-0.005
198.41,16.59,-0.006
198.46,16.68,-0.006
198.50,16.78,-0.006
198.55,16.88,-0.007
198.60,16.97,-0.007
198.65,17.07,-0.008
198.70,17.17,-0.008
198.75,17.27,-0.009
198.80,17.36,-0.009
198.84,17.46,-0.010
198.89,17.56,-0.011
198.94,17.65,-0.011
198.99,17.75,-0.012
199.04,17.85,-0.013
199.08,17.94,-0.014
199.13,18.04,-0.015
199.18,18.14,-0.015
199.23,18.24,-0.017
199.28,18.33,-0.018
199.33,18.43,-0.019
199.38,18.53,-0.020
199.42,18.62,-0.022
199.47,18.72,-0.023
199.52,18.82,-0.024
199.57,18.91,-0.026
199.62,19.01,-0.027
199.67,19.11,-0.029
199.71,19.20,-0.030
199.76,19.30,-0.032
199.81,19.40,-0.033
199.86,19.50,-0.034
199.91,19.59,-0.036
199.95,19.69,-0.037
200.00,19.79,-0.038
200.05,19.89,-0.039
200.10,19.98,-0.040
200.15,20.08,-0.040
200.20,20.18,-0.041
200.25,20.27,-0.041
200.29,20.37,-0.041
200.34,20.46,-0.041
200.39,20.56,-0.040
200.44,20.66,-0.039
200.49,20.75,-0.038
200.53,20.85,-0.037
200.58,20.95,-0.036
200.63,21.04,-0.035
200.68,21.14,-0.033
200.73,21.23,-0.031
200.78,21.33,-0.030
200.83,21.43,-0.028
200.87,21.52,-0.026
200.92,21.62,-0.024
200.97,21.71,-0.022
201.02,21.81,-0.021
201.07,21.91,-0.020
201.12,22.00,-0.018
201.16,22.10,-0.016
201.21,22.20,-0.015
201.26,22.29,-0.014
201.31,22.39,-0.013
201.36,22.49,-0.011
201.40,22.58,-0.010
201.45,22.68,-0.009
201.50,22.78,-0.008
201.55,22.87,-0.007
201.60,22.97,-0.006
201.65,23.07,-0.006
201.70,23.16,-0.005
201.74,23.26,-0.004
201.79,23.36,-0.004
201.84,23.45,-0.003
201.89,23.55,-0.003
201.94,23.65,-0.002
201.98,23.74,-0.002
202.03,23.84,-0.001
202.08,23.94,-0.001
202.13,24.03,-0.001
202.18,24.13,-0.001
202.23,24.23,0.000
202.28,24.32,0.000
202.32,24.42,0.000
202.37,24.52,0.001
202.42,24.61,0.001
202.47,24.71,0.001
202.52,24.81,0.001
202.57,24.90,0.002
202.61,25.00,0.002
202.66,25.10,0.002
202.71,25.19,0.002
202.76,25.29,0.002
202.81,25.39,0.002
202.85,25.48,0.002
202.90,25.58,0.003
202.95,25.68,0.003
203.00,25.77,0.003
203.05,25.87,0.003
203.10,25.97,0.003
203.15,26.06,0.003
203.19,26.16,0.003
203.24,26.25,0.003
203.29,26.35,0.003
203.34,26.45,0.003
203.39,26.55,0.003
203.43,26.64,0.003
203.48,26.74,0.002
203.53,26.84,0.002
203.58,26.93,0.002
203.63,27.03,0.001
203.68,27.13,0.000
203.73,27.22,-0.001
203.77,27.32,-0.002
203.82,27.42,-0.004
203.87,27.52,-0.006
203.92,27.62,-0.008
203.97,27.71,-0.012
204.02,27.81,-0.019
204.06,27.91,-0.024
204.11,28.01,-0.033
204.16,28.11,-0.041
204.21,28.20,-0.051
204.26,28.30,-0.062
204.30,28.40,-0.073
204.35,28.50,-0.083
204.40,28.60,-0.093
204.45,28.70,-0.104
204.50,28.80,-0.113
204.55,28.90,-0.123
204.60,29.00,-0.132
204.64,29.10,-0.140
204.69,29.20,-0.146
204.74,29.29,-0.151
204.79,29.39,-0.152
204.84,29.49,-0.154
204.88,29.59,-0.155
204.93,29.68,-0.156
204.98,29.78,-0.155
205.03,29.87,-0.154
205.08,29.97,-0.152
205.13,30.06,-0.149
205.18,30.16,-0.144
205.22,30.26,-0.139
205.27,30.35,-0.134
205.32,30.45,-0.130
205.37,30.54,-0.127
205.42,30.64,-0.123
205.47,30.73,-0.120
205.51,30.83,-0.116
205.56,30.93,-0.113
205.61,31.02,-0.110
205.66,31.12,-0.108
205.71,31.21,-0.105
205.75,31.31,-0.103
205.80,31.41,-0.100
205.85,31.50,-0.098
205.90,31.60,-0.095
205.95,31.69,-0.093
206.00,31.79,-0.091
206.05,31.89,-0.089
206.09,31.98,-0.086
206.14,32.08,-0.084
206.19,32.17,-0.082
206.24,32.27,-0.080
206.29,32.37,-0.078
206.33,32.46,-0.076
206.38,32.56,-0.074
206.43,32.66,-0.072
206.48,32.75,-0.070
206.53,32.85,-0.068
206.58,32.94,-0.067
206.63,33.04,-0.065
206.67,33.14,-0.064
206.72,33.23,-0.063
206.77,33.33,-0.061
206.82,33.43,-0.060
206.87,33.52,-0.059
206.92,33.62,-0.058
206.96,33.72,-0.056
207.01,33.81,-0.055
207.06,33.91,-0.054
207.11,34.01,-0.053
207.16,34.10,-0.052
207.20,34.20,-0.051
207.25,34.30,-0.050
207.30,34.39,-0.049
207.35,34.49,-0.048
207.40,34.58,-0.047
207.45,34.68,-0.046
207.50,34.78,-0.045
207.54,34.87,-0.044
207.59,34.97,-0.043
207.64,35.07,-0.042
207.69,35.16,-0.040
207.74,35.26,-0.039
207.78,35.36,-0.037
207.83,35.45,-0.036
207.88,35.55,-0.035
207.93,35.64,-0.033
207.98,35.74,-0.031
208.03,35.84,-0.030
208.08,35.93,-0.028
208.12,36.03,-0.026
208.17,36.13,-0.025
208.22,36.22,-0.023
208.27,36.32,-0.022
208.32,36.41,-0.020
208.37,36.51,-0.019
208.41,36.61,-0.017
208.46,36.70,-0.016
208.51,36.80,-0.015
208.56,36.90,-0.014
208.61,36.99,-0.013
208.65,37.09,-0.013
208.70,37.19,-0.012
208.75,37.28,-0.012
208.80,37.38,-0.011
208.85,37.48,-0.011
208.90,37.57,-0.010
208.95,37.67,-0.010
208.99,37.77,-0.010
209.04,37.86,-0.009
209.09,37.96,-0.009
209.14,38.06,-0.009
209.19,38.15,-0.008
209.23,38.25,-0.008
209.28,38.35,-0.008
209.33,38.44,-0.008
209.38,38.54,-0.007
209.43,38.64,-0.007
209.48,38.73,-0.007
209.53,38.83,-0.007
209.57,38.93,-0.007
209.62,39.02,-0.006
209.67,39.12,-0.006
209.72,39.22,-0.006
209.77,39.31,-0.006
209.82,39.41,-0.006
209.86,39.51,-0.005
209.91,39.60,-0.005
209.96,39.70,-0.005
210.01,39.80,-0.005
210.06,39.89,-0.005
210.10,39.99,-0.005
210.15,40.09,-0.004
210.20,40.18,-0.004
210.25,40.28,-0.004
210.30,40.37,-0.004
210.35,40.47,-0.004
210.40,40.57,-0.003
210.44,40.67,-0.003
210.49,40.76,-0.003
210.54,40.86,-0.003
210.59,40.96,-0.003
210.64,41.05,-0.003
210.68,41.15,-0.002
210.73,41.25,-0.002
210.78,41.34,-0.002
210.83,41.44,-0.002
210.88,41.54,-0.002
210.93,41.63,-0.001
210.98,41.73,-0.001
211.02,41.83,-0.001
211.07,41.92,-0.001
211.12,42.02,-0.001
211.17,42.11,0.000
211.22,42.21,0.000
211.27,42.31,0.000
211.31,42.41,0.001
211.36,42.50,0.001
211.41,42.60,0.001
211.46,42.69,0.002
211.51,42.79,0.002
211.55,42.89,0.002
211.60,42.99,0.002
211.65,43.08,0.002
211.70,43.18,0.003
211.75,43.28,0.003
211.80,43.37,0.004
211.85,43.47,0.004
211.89,43.57,0.005
211.94,43.66,0.005
211.99,43.76,0.005
212.04,43.85,0.006
212.09,43.95,0.006
212.13,44.05,0.006
212.18,44.14,0.007
212.23,44.24,0.007
212.28,44.34,0.008
212.33,44.43,0.008
212.38,44.53,0.009
212.43,44.63,0.009
212.47,44.72,0.010
212.52,44.82,0.011
212.57,44.92,0.011
212.62,45.01,0.012
212.67,45.11,0.013
212.72,45.21,0.014
212.76,45.30,0.014
212.81,45.40,0.015
212.86,45.50,0.016
212.91,45.59,0.017
212.96,45.69,0.018
213.00,45.78,0.019
213.05,45.88,0.020
213.10,45.98,0.021
213.15,46.07,0.022
213.20,46.17,0.024
213.25,46.26,0.025
213.30,46.36,0.027
213.34,46.46,0.028
213.39,46.55,0.030
213.44,46.65,0.031
213.49,46.75,0.033
213.54,46.84,0.036
213.58,46.94,0.038
213.63,47.04,0.041
213.68,47.13,0.043
213.73,47.23,0.046
213.78,47.32,0.049
213.83,47.42,0.053
213.88,47.51,0.057
213.92,47.61,0.063
213.97,47.71,0.069
214.02,47.80,0.074
214.07,47.90,0.081
214.12,47.99,0.087
214.17,48.09,0.096
214.21,48.18,0.105
214.26,48.28,0.115
214.31,48.37,0.124
214.36,48.46,0.133
214.41,48.56,0.144
214.45,48.65,0.158
214.50,48.75,0.172
214.55,48.84,0.186
214.60,48.93,0.202
214.65,49.02,0.219
214.70,49.11,0.240
214.75,49.21,0.262
214.79,49.30,0.285
214.84,49.39,0.309
214.89,49.48,0.336
214.94,49.57,0.367
214.99,49.66,0.399
215.03,49.75,0.434
215.08,49.83,0.474
215.13,49.92,0.516
215.18,50.01,0.561
215.23,50.09,0.610
215.28,50.18,0.664
215.33,50.26,0.720
215.37,50.34,0.781
215.42,50.42,0.844
215.47,50.50,0.912
215.52,50.58,0.983
215.57,50.66,1.058
215.62,50.74,1.131
215.66,50.82,1.206
215.71,50.90,1.278
215.76,50.98,1.334
215.81,51.06,1.370
215.86,51.15,1.372
215.90,51.25,1.341
215.95,51.36,1.247
216.00,51.49,1.103
216.05,51.61,0.986
216.10,51.73,0.950
216.15,51.83,0.968
216.20,51.92,1.021
216.24,52.01,1.078
216.29,52.09,1.116
216.34,52.18,1.101
216.39,52.30,0.945
216.44,52.45,0.640
216.48,52.62,0.396
216.53,52.76,0.261
216.58,52.89,0.175
216.63,53.00,0.119
216.68,53.11,0.082
216.73,53.22,0.057
216.78,53.32,0.043
216.82,53.42,0.034
216.87,53.52,0.028
216.92,53.62,0.025
216.97,53.71,0.023
217.02,53.81,0.021
217.07,53.91,0.020
217.11,54.01,0.019
217.16,54.10,0.017
217.21,54.20,0.017
217.26,54.30,0.016
217.31,54.40,0.015
217.35,54.49,0.015
217.40,54.59,0.015
217.45,54.69,0.014
217.50,54.78,0.014
217.55,54.88,0.014
217.60,54.97,0.013
217.65,55.07,0.013
217.69,55.17,0.013
217.74,55.27,0.013
217.79,55.36,0.012
217.84,55.46,0.012
217.89,55.56,0.012
217.93,55.65,0.012
217.98,55.75,0.012
218.03,55.85,0.012
218.08,55.94,0.012
218.13,56.04,0.012
218.18,56.14,0.012
218.23,56.23,0.012
218.27,56.33,0.012
218.32,56.43,0.012
218.37,56.52,0.012
218.42,56.62,0.012
218.47,56.72,0.012
218.52,56.81,0.012
218.56,56.91,0.012
218.61,57.01,0.012
218.66,57.10,0.012
218.71,57.20,0.012
218.76,57.30,0.012
218.80,57.39,0.012
218.85,57.49,0.012
218.90,57.59,0.012
218.95,57.68,0.012
219.00,57.78,0.012
219.05,57.87,0.012
219.10,57.97,0.012
219.14,58.07,0.012
219.19,58.16,0.012
219.24,58.26,0.012
219.29,58.36,0.012
219.34,58.45,0.012
219.38,58.55,0.012
219.43,58.65,0.012
219.48,58.74,0.012
219.53,58.84,0.012
219.58,58.94,0.012
219.63,59.03,0.012
219.68,59.13,0.012
219.72,59.23,0.012
219.77,59.33,0.012
219.82,59.42,0.012
219.87,59.52,0.012
219.92,59.62,0.012
219.97,59.71,0.012
220.01,59.81,0.012
220.06,59.91,0.012
220.11,60.00,0.012
220.16,60.10,0.012
220.21,60.19,0.012
220.25,60.29,0.012
220.30,60.39,0.012
220.35,60.49,0.012
220.40,60.58,0.012
220.45,60.68,0.012
220.50,60.78,0.012
220.55,60.87,0.012
220.59,60.97,0.012
220.64,61.07,0.012
220.69,61.16,0.012
220.74,61.26,0.012
220.79,61.36,0.012
220.83,61.45,0.012
220.88,61.55,0.012
220.93,61.65,0.012
220.98,61.74,0.012
221.03,61.84,0.012
221.08,61.94,0.012
221.13,62.03,0.012
221.17,62.13,0.012
221.22,62.23,0.012
221.27,62.32,0.012
221.32,62.42,0.012
221.37,62.52,0.012
221.42,62.61,0.012
221.46,62.71,0.012
221.51,62.81,0.012
221.56,62.90,0.012
221.61,63.00,0.012
221.66,63.10,0.012
221.70,63.19,0.012
221.75,63.29,0.012
221.80,63.39,0.012
221.85,63.48,0.012
221.90,63.58,0.012
221.95,63.68,0.012
222.00,63.77,0.012
222.04,63.87,0.012
222.09,63.97,0.012
222.14,64.06,0.012
222.19,64.16,0.012
222.24,64.26,0.012
222.28,64.35,0.012
222.33,64.45,0.012
222.38,64.55,0.012
222.43,64.64,0.012
222.48,64.74,0.012
222.53,64.84,0.012
222.58,64.93,0.012
222.62,65.03,0.012
222.67,65.13,0.012
222.72,65.22,0.012
222.77,65.32,0.012
222.82,65.42,0.012
222.87,65.51,0.012
222.91,65.61,0.012
222.96,65.71,0.012
223.01,65.80,0.012
223.06,65.90,0.012
223.11,66.00,0.012
223.15,66.09,0.012
223.20,66.19,0.012
223.25,66.29,0.012
223.30,66.38,0.012
223.35,66.48,0.012
223.40,66.58,0.012
223.45,66.67,0.012
223.49,66.77,0.012
223.54,66.87,0.012
223.59,66.96,0.012
223.64,67.06,0.012
223.69,67.16,0.012
223.73,67.25,0.012
223.78,67.35,0.012
223.83,67.45,0.012
223.88,67.54,0.012
223.93,67.64,0.012
223.98,67.74,0.012
224.03,67.83,0.012
224.07,67.93,0.012
224.12,68.03,0.012
224.17,68.13,0.012
224.22,68.22,0.012
224.27,68.32,0.012
224.32,68.42,0.012
224.36,68.51,0.012
224.41,68.61,0.012
224.46,68.70,0.012
224.51,68.80,0.012
224.56,68.90,0.012
224.60,69.00,0.012
224.65,69.09,0.011
224.70,69.19,0.011
224.75,69.29,0.011
224.80,69.38,0.012
224.85,69.48,0.012
224.90,69.58,0.012
224.94,69.67,0.012
224.99,69.77,0.012
225.04,69.87,0.012
225.09,69.96,0.012
225.14,70.06,0.012
225.18,70.16,0.012
225.23,70.25,0.012
225.28,70.35,0.012
225.33,70.44,0.012
225.38,70.54,0.012
225.43,70.64,0.012
225.48,70.73,0.011
225.52,70.83,0.011
225.57,70.93,0.011
225.62,71.02,0.011
225.67,71.12,0.011
225.72,71.22,0.011
225.77,71.32,0.011
225.81,71.41,0.011
225.86,71.51,0.011
225.91,71.60,0.011
225.96,71.70,0.011
226.01,71.80,0.011
226.05,71.89,0.011
226.10,71.99,0.011
226.15,72.09,0.011
226.20,72.19,0.011
226.25,72.28,0.011
226.30,72.38,0.012
226.35,72.48,0.012
226.39,72.57,0.012
226.44,72.67,0.011
226.49,72.77,0.011
226.54,72.86,0.011
226.59,72.96,0.011
226.63,73.06,0.011
226.68,73.15,0.011
226.73,73.25,0.012
226.78,73.35,0.012
226.83,73.44,0.011
226.88,73.54,0.011
226.93,73.64,0.011
226.97,73.73,0.012
227.02,73.83,0.011
227.07,73.93,0.011
227.12,74.02,0.011
227.17,74.12,0.011
227.22,74.21,0.011
227.26,74.31,0.011
227.31,74.41,0.011
227.36,74.51,0.011
227.41,74.60,0.011
227.46,74.70,0.011
227.50,74.80,0.011
227.55,74.89,0.011
227.60,74.99,0.011
227.65,75.09,0.011
227.70,75.18,0.011
227.75,75.28,0.011
227.80,75.38,0.012
227.84,75.47,0.011
227.89,75.57,0.011
227.94,75.67,0.011
227.99,75.76,0.011
228.04,75.86,0.011
228.08,75.96,0.011
228.13,76.05,0.011
228.18,76.15,0.011
228.23,76.25,0.011
228.28,76.34,0.011
228.33,76.44,0.011
228.38,76.54,0.011
228.42,76.63,0.011
228.47,76.73,0.011
228.52,76.82,0.011
228.57,76.92,0.011
228.62,77.02,0.011
228.67,77.12,0.011
228.71,77.21,0.011
228.76,77.31,0.011
228.81,77.41,0.011
228.86,77.50,0.011
228.91,77.60,0.011
228.95,77.70,0.011
229.00,77.79,0.011
229.05,77.89,0.011
229.10,77.99,0.011
229.15,78.08,0.011
229.20,78.18,0.011
229.25,78.28,0.011
229.29,78.37,0.011
229.34,78.47,0.012
229.39,78.57,0.011
229.44,78.66,0.011
229.49,78.76,0.011
229.53,78.86,0.011
229.58,78.95,0.011
229.63,79.05,0.011
229.68,79.15,0.011
229.73,79.24,0.011
229.78,79.34,0.011
229.83,79.44,0.011
229.87,79.53,0.011
229.92,79.63,0.011
229.97,79.73,
230.00,,