File: DSC/2025_04_25_CBN_Caffeine_MC_n60C_250C_5Cmin_x3.csv
Filename,2025_04_25_CBN_Caffeine_MC_n60C_250C_5Cmin_x3
Instrument name,DSC2A-00468 (192.168.1.100)
Operator,Yarger
rundate,4/26/2025
Sample name,2025_04_25_CBN_Caffeine_MC_n60C_250C_5Cmin_x3
proceduresegments,Data Off ; Equilibrate -60.00 °C; Data On ; Ramp 5.00 °C/min to 250.00 °C; Data Off ; Isothermal 0.1 min; Data On ; Ramp 5.00 °C/min to -60.00 °C; Data Off ; Isothermal 1.0 min; Data On ; Ramp 5.00 °C/min to 250.00 °C; Data Off ; Isothermal 0.1 min; Data On ; Ramp 5.00 °C/min to -60.00 °C; Data Off ; Isothermal 1.0 min; Data On ; Ramp 5.00 °C/min to 250.00 °C
[File Parameters]
Run date,4/26/2025 6:10:18 AM
Trios version,5.1.1.46572
Original File Name,
Current File Name,D:\DSC2500\JYarger\2025_04_25_CBN_Caffeine_MC_n60C_250C_5Cmin_x3.tri
[Procedure]
Procedure Name,CBN_Caff_250_5
Sample Name,2025_04_25_CBN_Caffeine_MC_n60C_250C_5Cmin_x3
Sample Mass,5.42 mg
Reference Sample Mass,0 mg
Pan Mass,53.43 mg
Pan Number,50
Reference Pan Mass,52.66 mg
Reference Pan Number,19
Pan Type,Tzero Aluminum Hermetic
Comments,Al Hermetic DSC Consumables sealed Pan/Lid.
Project Name,CA
Operator,Yarger
Test,Custom
Unload Max Temperature,30
Unload Min Temperature,30
Load Max Temperature,30
Load Min Temperature,30
Stop on Gas Flow Error,Yes
[Signal List]
Signal #1,Time (min)
Signal #2,Temperature (°C)
Signal #3,Heat Flow (mW)
Signal #4,Delta T (µV)
Signal #5,Delta Tzero (µV)
Signal #6,Tzero Temperature (°C)
Signal #7,Cell Purge (mL/min)
Signal #8,Heater Temp (°C)
Signal #9,Power Delivered (W)
Signal #10,Reference Junction Temperature (°C)
Signal #11,Flange Temperature (°C)
Signal #12,Heat Flow Phase (rad)
Signal #13,Total Heat Capacity (J/°C)
Signal #14,Heat Capacity (J/°C)
[Configuration]
Company Name,ASU
Instrument Name,DSC2A-00468
Instrument Type,DSC2500
Serial Number,DSC2A-00468
IP,192.168.1.100
Location of Instrument,MRRC
DisplayType,Unknown
Sample Interval ,0.1 s/pt
Selected Heat Flow,T4P
Exotherm Direction,Down
Cell Serial,DRC2-00792
Lid Type,Standard
Cooler,RCS 90
Leave Cooler on at End of Sequence,On
Gas 2,Nitrogen
Gas Selected,Channel 1
Flow Rate,50 mL/min
Secondary Purge,On
Licensed Heat Flow,Heat Flow T4P
Modulation Licensed,Yes
[Versions]
Common IDD Version,1
Cortex Version,VER 2.10.2.31
Driver,5.0.0.6
GDM Version,1.0.3.3
TouchscreenVersion,1.0.0.16145
FEP Version,1.2.1.21
FEP Bootloader,2.0.0.5
AutoSampler Version,2.1.1.26
Auto Sampler Bootloader,2.0.0.5
FCM Version,1.1.0.3
FCM Bootloader,2.0.0.5
[Experiment Logs]
Experiment Log Entry # 1,Data On set to 0
Experiment Log Entry # 3,Equilibrate Segment -60 (C) Started
Experiment Log Entry # 5,Air Cool is off.
Experiment Log Entry # 7,Data On set to 1
Experiment Log Entry # 9,Ramp Segment 5 C/min to 250 Started
Experiment Log Entry # 11,Data On set to 0
Experiment Log Entry # 13,Isothermal Segment 0.1 min started
Experiment Log Entry # 15,Data On set to 1
Experiment Log Entry # 17,Ramp Segment 5 C/min to -60 Started
Experiment Log Entry # 19,Data On set to 0
Experiment Log Entry # 21,Isothermal Segment 1 min started
Experiment Log Entry # 23,Data On set to 1
Experiment Log Entry # 25,Ramp Segment 5 C/min to 250 Started
Experiment Log Entry # 27,Data On set to 0
Experiment Log Entry # 29,Isothermal Segment 0.1 min started
Experiment Log Entry # 31,Data On set to 1
Experiment Log Entry # 33,Ramp Segment 5 C/min to -60 Started
Experiment Log Entry # 35,Data On set to 0
Experiment Log Entry # 37,Isothermal Segment 1 min started
Experiment Log Entry # 39,Data On set to 1
Experiment Log Entry # 41,Ramp Segment 5 C/min to 250 Started
[Method Log]
Method Log Entry # 1,Data Off
Method Log Entry # 2,Equilibrate -60 °C
Method Log Entry # 3,Data On
Method Log Entry # 4,(Ramp 564556) Ramp 5 °C/minute to 250 °C
Method Log Entry # 5,Data Off
Method Log Entry # 6,Isothermal 0.1 minutes
Method Log Entry # 7,Data On
Method Log Entry # 8,(Ramp 564560) Ramp 5 °C/minute to -60 °C
Method Log Entry # 9,Data Off
Method Log Entry # 10,Isothermal 1 minutes
Method Log Entry # 11,Data On
Method Log Entry # 12,(Ramp 564564) Ramp 5 °C/minute to 250 °C
Method Log Entry # 13,Data Off
Method Log Entry # 14,Isothermal 0.1 minutes
Method Log Entry # 15,Data On
Method Log Entry # 16,(Ramp 564568) Ramp 5 °C/minute to -60 °C
Method Log Entry # 17,Data Off
Method Log Entry # 18,Isothermal 1 minutes
Method Log Entry # 19,Data On
Method Log Entry # 20,(Ramp 564572) Ramp 5 °C/minute to 250 °C
Cell Serial,DRC2-00792
[T1 Calibration]
Slope,-0.008529666
Offset,9.636258
Initial Temperature,98.23
GUID,f8bfdadc-4977-4fdf-ba6d-0ba9134940c3
[TZero Calibration]
Date Applied,11/29/2022 4:06:13 PM
Description,From -89.059 °C to 396.009 °C at 20.000°C/min
Gas Type,Nitrogen
Pan Type,None
Source Files 1,C:\Users\yargerlab\Desktop\DSC Data\General\TZero_calibration_11_29_22_2nd(2).tri
Source Files 2,C:\Users\yargerlab\Desktop\DSC Data\General\TZero_calibration_11_29_22_2nd(3).tri
Delta T Offset,13.05235
Delta T Slope,-0.007271007
Delta T0 Offset,-13.69128
Delta T0 Slope,0.06063341
[Temperature Calibration]
Date Applied,11/29/2022 7:12:28 PM
Description,From 106.590 °C to 186.590 °C at 10.000°C/min
Gas Type,Nitrogen
Pan Type,Tzero Aluminum Hermetic
Source Files 1,C:\Users\yargerlab\Desktop\DSC Data\General\Indium(6).tri
Measured 1,157.391
Known 1,156.598
[Cell Constant Calibration]
Date Applied,11/29/2022 7:12:29 PM
Description,From 106.590 °C to 186.590 °C at 10.000°C/min
Gas Type,Nitrogen
Pan Type,Tzero Aluminum Hermetic
Source Files 1,C:\Users\yargerlab\Desktop\DSC Data\General\Indium(6).tri
T4P KCell,1.006051
Onset Slope,63.26126 mW/°C
[Direct Cp Calibration]
Date Applied,11/30/2022 11:04:51 AM
Description,From -79.983 °C to 298.409 °C at 10.000°C/min
Gas Type,Nitrogen
Pan Type,Tzero Aluminum Hermetic
Source Files 1,C:\Users\yargerlab\Desktop\DSC Data\General\Sapphire_Heat_Capacity_11_30_22.tri
[Rev Cp Calibration]
Date Applied,11/30/2022 1:58:51 PM
Description,From -79.996 °C to 292.812 °C at 3.000°C/min
Gas Type,Nitrogen
Pan Type,Tzero Aluminum Hermetic
Source Files 1,C:\Users\yargerlab\Desktop\DSC Data\General\Sapphire_MDSC_Calibration_11_30_22.tri
[step]
Ramp 5.00 °C/min to 250.00 °C
Time,Temperature,Heat Flow (Normalized)
min,°C,W/g
0.00,-59.68,-0.058
0.04,-59.70,-0.051
0.08,-59.69,-0.049
0.13,-59.60,-0.048
0.17,-59.48,-0.023
0.21,-59.32,0.004
0.25,-59.15,0.025
0.29,-58.98,0.040
0.33,-58.79,0.052
0.38,-58.60,0.060
0.42,-58.41,0.065
0.46,-58.21,0.070
0.50,-58.01,0.073
0.54,-57.81,0.075
0.58,-57.62,0.077
0.63,-57.41,0.078
0.67,-57.21,0.079
0.71,-57.01,0.079
0.75,-56.80,0.080
0.79,-56.60,0.081
0.83,-56.39,0.081
0.88,-56.19,0.082
0.92,-55.98,0.082
0.96,-55.78,0.083
1.00,-55.57,0.083
1.04,-55.37,0.083
1.08,-55.16,0.084
1.13,-54.95,0.084
1.17,-54.75,0.084
1.21,-54.54,0.084
1.25,-54.33,0.084
1.29,-54.13,0.084
1.33,-53.92,0.085
1.38,-53.71,0.085
1.42,-53.50,0.085
1.46,-53.30,0.085
1.50,-53.09,0.085
1.54,-52.88,0.085
1.58,-52.68,0.085
1.63,-52.47,0.085
1.67,-52.26,0.085
1.71,-52.05,0.085
1.75,-51.84,0.085
1.79,-51.64,0.085
1.83,-51.43,0.085
1.88,-51.22,0.085
1.92,-51.01,0.085
1.96,-50.80,0.085
2.00,-50.60,0.085
2.04,-50.39,0.085
2.08,-50.18,0.085
2.13,-49.97,0.085
2.17,-49.76,0.085
2.21,-49.55,0.085
2.25,-49.35,0.085
2.29,-49.14,0.085
2.33,-48.93,0.085
2.38,-48.72,0.085
2.42,-48.52,0.085
2.46,-48.31,0.085
2.50,-48.10,0.084
2.54,-47.89,0.084
2.58,-47.69,0.084
2.63,-47.48,0.084
2.67,-47.27,0.084
2.71,-47.06,0.084
2.75,-46.85,0.084
2.79,-46.65,0.084
2.83,-46.44,0.084
2.88,-46.23,0.084
2.92,-46.02,0.084
2.96,-45.81,0.084
3.00,-45.60,0.084
3.04,-45.40,0.084
3.08,-45.19,0.084
3.13,-44.98,0.084
3.17,-44.77,0.084
3.21,-44.56,0.084
3.25,-44.35,0.084
3.29,-44.15,0.084
3.33,-43.94,0.084
3.38,-43.73,0.084
3.42,-43.52,0.084
3.46,-43.31,0.084
3.50,-43.11,0.084
3.54,-42.90,0.084
3.58,-42.69,0.084
3.63,-42.48,0.084
3.67,-42.27,0.084
3.71,-42.06,0.084
3.75,-41.85,0.084
3.79,-41.65,0.084
3.83,-41.44,0.084
3.88,-41.23,0.084
3.92,-41.02,0.084
3.96,-40.81,0.084
4.00,-40.61,0.084
4.04,-40.40,0.084
4.08,-40.19,0.084
4.13,-39.98,0.084
4.17,-39.77,0.084
4.21,-39.56,0.084
4.25,-39.35,0.084
4.29,-39.14,0.084
4.33,-38.94,0.084
4.38,-38.73,0.085
4.42,-38.52,0.085
4.46,-38.31,0.085
4.50,-38.10,0.085
4.54,-37.89,0.085
4.58,-37.68,0.085
4.63,-37.47,0.085
4.67,-37.27,0.085
4.71,-37.06,0.085
4.75,-36.85,0.085
4.79,-36.64,0.085
4.83,-36.43,0.085
4.88,-36.22,0.085
4.92,-36.02,0.085
4.96,-35.81,0.085
5.00,-35.60,0.085
5.04,-35.39,0.085
5.08,-35.18,0.085
5.13,-34.97,0.085
5.17,-34.76,0.085
5.21,-34.55,0.085
5.25,-34.35,0.085
5.29,-34.14,0.085
5.33,-33.93,0.085
5.38,-33.72,0.085
5.42,-33.51,0.085
5.46,-33.30,0.085
5.50,-33.09,0.085
5.54,-32.89,0.085
5.58,-32.68,0.085
5.63,-32.47,0.085
5.67,-32.26,0.085
5.71,-32.05,0.085
5.75,-31.84,0.085
5.79,-31.63,0.085
5.83,-31.42,0.085
5.88,-31.22,0.085
5.92,-31.01,0.085
5.96,-30.80,0.085
6.00,-30.59,0.085
6.04,-30.38,0.085
6.08,-30.18,0.085
6.13,-29.97,0.085
6.17,-29.76,0.085
6.21,-29.55,0.085
6.25,-29.34,0.085
6.29,-29.13,0.085
6.33,-28.92,0.085
6.38,-28.72,0.085
6.42,-28.51,0.086
6.46,-28.30,0.086
6.50,-28.09,0.086
6.54,-27.88,0.086
6.58,-27.67,0.086
6.63,-27.46,0.086
6.67,-27.26,0.086
6.71,-27.05,0.086
6.75,-26.84,0.086
6.79,-26.63,0.086
6.83,-26.42,0.086
6.88,-26.21,0.086
6.92,-26.01,0.086
6.96,-25.80,0.086
7.00,-25.59,0.086
7.04,-25.38,0.086
7.08,-25.17,0.086
7.13,-24.96,0.086
7.17,-24.75,0.086
7.21,-24.55,0.086
7.25,-24.34,0.086
7.29,-24.13,0.086
7.33,-23.92,0.086
7.38,-23.71,0.086
7.42,-23.50,0.086
7.46,-23.29,0.086
7.50,-23.09,0.086
7.54,-22.88,0.087
7.58,-22.67,0.087
7.63,-22.46,0.087
7.67,-22.25,0.087
7.71,-22.04,0.087
7.75,-21.83,0.087
7.79,-21.63,0.087
7.83,-21.42,0.087
7.88,-21.21,0.087
7.92,-21.00,0.087
7.96,-20.79,0.087
8.00,-20.58,0.087
8.04,-20.37,0.087
8.08,-20.17,0.087
8.13,-19.96,0.087
8.17,-19.75,0.087
8.21,-19.54,0.087
8.25,-19.33,0.087
8.29,-19.13,0.087
8.33,-18.91,0.087
8.38,-18.71,0.087
8.42,-18.50,0.087
8.46,-18.29,0.087
8.50,-18.08,0.087
8.54,-17.87,0.087
8.58,-17.66,0.087
8.63,-17.46,0.087
8.67,-17.25,0.088
8.71,-17.04,0.088
8.75,-16.83,0.088
8.79,-16.62,0.088
8.83,-16.41,0.088
8.88,-16.21,0.088
8.92,-16.00,0.088
8.96,-15.79,0.088
9.00,-15.58,0.088
9.04,-15.37,0.088
9.08,-15.17,0.088
9.13,-14.96,0.088
9.17,-14.75,0.088
9.21,-14.54,0.088
9.25,-14.33,0.088
9.29,-14.12,0.088
9.33,-13.91,0.088
9.38,-13.70,0.088
9.42,-13.50,0.088
9.46,-13.29,0.088
9.50,-13.08,0.088
9.54,-12.87,0.088
9.58,-12.66,0.088
9.63,-12.45,0.088
9.67,-12.24,0.089
9.71,-12.04,0.089
9.75,-11.83,0.089
9.79,-11.62,0.089
9.83,-11.41,0.089
9.88,-11.20,0.089
9.92,-10.99,0.089
9.96,-10.78,0.089
10.00,-10.58,0.089
10.04,-10.37,0.089
10.08,-10.16,0.089
10.13,-9.95,0.089
10.17,-9.74,0.089
10.21,-9.53,0.089
10.25,-9.33,0.089
10.29,-9.12,0.089
10.33,-8.91,0.089
10.38,-8.70,0.089
10.42,-8.49,0.090
10.46,-8.28,0.090
10.50,-8.08,0.090
10.54,-7.87,0.090
10.58,-7.66,0.090
10.63,-7.45,0.090
10.67,-7.24,0.090
10.71,-7.03,0.090
10.75,-6.82,0.090
10.79,-6.62,0.090
10.83,-6.41,0.090
10.88,-6.20,0.090
10.92,-5.99,0.090
10.96,-5.78,0.090
11.00,-5.57,0.090
11.04,-5.36,0.090
11.08,-5.16,0.090
11.13,-4.95,0.090
11.17,-4.74,0.091
11.21,-4.53,0.091
11.25,-4.32,0.091
11.29,-4.12,0.091
11.33,-3.90,0.091
11.38,-3.70,0.091
11.42,-3.49,0.091
11.46,-3.28,0.091
11.50,-3.07,0.091
11.54,-2.86,0.091
11.58,-2.66,0.091
11.63,-2.45,0.091
11.67,-2.24,0.091
11.71,-2.03,0.091
11.75,-1.82,0.091
11.79,-1.61,0.091
11.83,-1.40,0.091
11.88,-1.19,0.091
11.92,-0.99,0.091
11.96,-0.78,0.092
12.00,-0.57,0.092
12.04,-0.36,0.092
12.08,-0.15,0.092
12.13,0.06,0.092
12.17,0.26,0.092
12.21,0.47,0.092
12.25,0.68,0.092
12.29,0.89,0.092
12.33,1.10,0.092
12.38,1.31,0.092
12.42,1.51,0.092
12.46,1.72,0.092
12.50,1.93,0.092
12.54,2.14,0.092
12.58,2.35,0.092
12.63,2.56,0.092
12.67,2.77,0.092
12.71,2.98,0.092
12.75,3.18,0.092
12.79,3.39,0.093
12.83,3.60,0.093
12.88,3.81,0.093
12.92,4.02,0.093
12.96,4.23,0.093
13.00,4.43,0.093
13.04,4.64,0.093
13.08,4.85,0.093
13.13,5.06,0.093
13.17,5.27,0.093
13.21,5.48,0.093
13.25,5.68,0.093
13.29,5.89,0.093
13.33,6.10,0.093
13.38,6.31,0.093
13.42,6.52,0.093
13.46,6.73,0.093
13.50,6.94,0.094
13.54,7.14,0.094
13.58,7.35,0.094
13.63,7.56,0.094
13.67,7.77,0.094
13.71,7.98,0.094
13.75,8.19,0.094
13.79,8.39,0.094
13.83,8.60,0.094
13.88,8.81,0.094
13.92,9.02,0.094
13.96,9.23,0.094
14.00,9.44,0.094
14.04,9.65,0.094
14.08,9.85,0.094
14.13,10.06,0.095
14.17,10.27,0.095
14.21,10.48,0.095
14.25,10.69,0.095
14.29,10.90,0.095
14.33,11.11,0.095
14.38,11.31,0.095
14.42,11.52,0.095
14.46,11.73,0.095
14.50,11.94,0.095
14.54,12.15,0.095
14.58,12.36,0.095
14.63,12.56,0.095
14.67,12.77,0.095
14.71,12.98,0.096
14.75,13.19,0.096
14.79,13.40,0.096
14.83,13.61,0.096
14.88,13.82,0.096
14.92,14.02,0.096
14.96,14.23,0.096
15.00,14.44,0.096
15.04,14.65,0.096
15.08,14.86,0.096
15.13,15.07,0.096
15.17,15.28,0.096
15.21,15.48,0.096
15.25,15.69,0.096
15.29,15.90,0.096
15.33,16.11,0.096
15.38,16.32,0.096
15.42,16.53,0.097
15.46,16.73,0.097
15.50,16.94,0.097
15.54,17.15,0.097
15.58,17.36,0.097
15.63,17.57,0.097
15.67,17.78,0.097
15.71,17.98,0.097
15.75,18.19,0.097
15.79,18.40,0.097
15.83,18.61,0.097
15.88,18.82,0.097
15.92,19.03,0.097
15.96,19.23,0.098
16.00,19.44,0.098
16.04,19.65,0.098
16.08,19.86,0.098
16.13,20.07,0.098
16.17,20.28,0.098
16.21,20.49,0.098
16.25,20.69,0.098
16.29,20.90,0.098
16.33,21.11,0.098
16.38,21.32,0.098
16.42,21.53,0.098
16.46,21.74,0.098
16.50,21.95,0.098
16.54,22.15,0.098
16.58,22.36,0.098
16.63,22.57,0.098
16.67,22.78,0.098
16.71,22.99,0.099
16.75,23.20,0.099
16.79,23.40,0.099
16.83,23.61,0.099
16.88,23.82,0.099
16.92,24.03,0.099
16.96,24.24,0.099
17.00,24.45,0.099
17.04,24.65,0.099
17.08,24.86,0.099
17.13,25.07,0.099
17.17,25.28,0.100
17.21,25.49,0.100
17.25,25.70,0.100
17.29,25.91,0.100
17.33,26.12,0.100
17.38,26.32,0.100
17.42,26.53,0.100
17.46,26.74,0.100
17.50,26.95,0.100
17.54,27.16,0.100
17.58,27.37,0.101
17.63,27.57,0.101
17.67,27.78,0.101
17.71,27.99,0.101
17.75,28.20,0.101
17.79,28.41,0.101
17.83,28.61,0.101
17.88,28.82,0.101
17.92,29.03,0.101
17.96,29.24,0.101
18.00,29.45,0.101
18.04,29.66,0.102
18.08,29.87,0.102
18.13,30.07,0.102
18.17,30.29,0.102
18.21,30.49,0.102
18.25,30.70,0.102
18.29,30.91,0.102
18.33,31.12,0.102
18.38,31.33,0.102
18.42,31.53,0.102
18.46,31.74,0.103
18.50,31.95,0.103
18.54,32.16,0.103
18.58,32.37,0.103
18.63,32.58,0.103
18.67,32.78,0.103
18.71,32.99,0.103
18.75,33.20,0.104
18.79,33.41,0.104
18.83,33.62,0.104
18.88,33.83,0.104
18.92,34.04,0.104
18.96,34.25,0.104
19.00,34.45,0.104
19.04,34.66,0.104
19.08,34.87,0.104
19.13,35.08,0.105
19.17,35.29,0.105
19.21,35.50,0.105
19.25,35.70,0.105
19.29,35.91,0.105
19.33,36.12,0.105
19.38,36.33,0.105
19.42,36.54,0.105
19.46,36.75,0.105
19.50,36.95,0.105
19.54,37.16,0.106
19.58,37.37,0.106
19.63,37.58,0.106
19.67,37.79,0.106
19.71,38.00,0.106
19.75,38.20,0.106
19.79,38.41,0.106
19.83,38.62,0.106
19.88,38.83,0.107
19.92,39.04,0.107
19.96,39.25,0.107
20.00,39.46,0.107
20.04,39.66,0.107
20.08,39.87,0.107
20.13,40.08,0.108
20.17,40.29,0.108
20.21,40.50,0.108
20.25,40.71,0.108
20.29,40.92,0.108
20.33,41.12,0.108
20.38,41.33,0.109
20.42,41.54,0.109
20.46,41.75,0.109
20.50,41.96,0.109
20.54,42.16,0.109
20.58,42.37,0.110
20.63,42.58,0.110
20.67,42.79,0.110
20.71,43.00,0.110
20.75,43.21,0.111
20.79,43.41,0.111
20.83,43.62,0.111
20.88,43.83,0.112
20.92,44.04,0.112
20.96,44.25,0.112
21.00,44.46,0.113
21.04,44.66,0.113
21.08,44.87,0.114
21.13,45.08,0.114
21.17,45.29,0.115
21.21,45.50,0.115
21.25,45.71,0.116
21.29,45.91,0.116
21.33,46.12,0.117
21.38,46.33,0.118
21.42,46.54,0.118
21.46,46.75,0.119
21.50,46.95,0.120
21.54,47.16,0.121
21.58,47.37,0.121
21.63,47.58,0.122
21.67,47.79,0.123
21.71,48.00,0.124
21.75,48.20,0.125
21.79,48.41,0.125
21.83,48.62,0.126
21.88,48.83,0.127
21.92,49.04,0.128
21.96,49.24,0.130
22.00,49.45,0.131
22.04,49.66,0.132
22.08,49.87,0.133
22.13,50.08,0.134
22.17,50.28,0.136
22.21,50.49,0.138
22.25,50.70,0.140
22.29,50.91,0.142
22.33,51.11,0.143
22.38,51.32,0.146
22.42,51.53,0.148
22.46,51.74,0.150
22.50,51.95,0.152
22.54,52.15,0.155
22.58,52.36,0.158
22.63,52.57,0.160
22.67,52.78,0.163
22.71,52.98,0.167
22.75,53.19,0.170
22.79,53.40,0.173
22.83,53.60,0.178
22.88,53.81,0.181
22.92,54.02,0.185
22.96,54.23,0.189
23.00,54.43,0.192
23.04,54.64,0.196
23.08,54.85,0.201
23.13,55.05,0.206
23.17,55.26,0.210
23.21,55.47,0.215
23.25,55.67,0.219
23.29,55.88,0.225
23.33,56.09,0.230
23.38,56.30,0.235
23.42,56.50,0.239
23.46,56.71,0.246
23.50,56.92,0.250
23.54,57.12,0.255
23.58,57.33,0.261
23.63,57.53,0.266
23.67,57.74,0.272
23.71,57.95,0.277
23.75,58.15,0.283
23.79,58.36,0.289
23.83,58.57,0.294
23.88,58.77,0.299
23.92,58.98,0.304
23.96,59.19,0.310
24.00,59.39,0.315
24.04,59.60,0.321
24.08,59.80,0.325
24.13,60.01,0.329
24.17,60.22,0.335
24.21,60.43,0.338
24.25,60.63,0.343
24.29,60.84,0.347
24.33,61.05,0.350
24.38,61.25,0.355
24.42,61.46,0.358
24.46,61.67,0.360
24.50,61.88,0.361
24.54,62.08,0.362
24.58,62.29,0.364
24.63,62.50,0.366
24.67,62.71,0.367
24.71,62.92,0.368
24.75,63.12,0.370
24.79,63.33,0.372
24.83,63.54,0.372
24.88,63.75,0.374
24.92,63.95,0.388
24.96,64.16,0.398
25.00,64.37,0.393
25.04,64.58,0.382
25.08,64.79,0.372
25.13,65.00,0.364
25.17,65.21,0.360
25.21,65.42,0.357
25.25,65.63,0.354
25.29,65.84,0.349
25.33,66.05,0.345
25.38,66.26,0.341
25.42,66.47,0.336
25.46,66.68,0.331
25.50,66.89,0.326
25.54,67.10,0.321
25.58,67.31,0.316
25.63,67.52,0.310
25.67,67.73,0.305
25.71,67.94,0.300
25.75,68.16,0.295
25.79,68.37,0.289
25.83,68.58,0.284
25.88,68.79,0.279
25.92,69.00,0.275
25.96,69.21,0.270
26.00,69.42,0.266
26.04,69.63,0.261
26.08,69.84,0.257
26.13,70.05,0.252
26.17,70.26,0.248
26.21,70.47,0.245
26.25,70.68,0.241
26.29,70.89,0.238
26.33,71.10,0.235
26.38,71.31,0.232
26.42,71.52,0.228
26.46,71.73,0.226
26.50,71.94,0.224
26.54,72.15,0.221
26.58,72.36,0.218
26.63,72.56,0.217
26.67,72.77,0.214
26.71,72.98,0.213
26.75,73.19,0.211
26.79,73.40,0.210
26.83,73.61,0.208
26.88,73.82,0.207
26.92,74.03,0.206
26.96,74.24,0.204
27.00,74.45,0.203
27.04,74.66,0.202
27.08,74.87,0.200
27.13,75.07,0.199
27.17,75.28,0.197
27.21,75.49,0.195
27.25,75.70,0.193
27.29,75.91,0.190
27.33,76.12,0.186
27.38,76.33,0.182
27.42,76.54,0.179
27.46,76.75,0.176
27.50,76.96,0.173
27.54,77.17,0.171
27.58,77.38,0.169
27.63,77.59,0.168
27.67,77.80,0.167
27.71,78.00,0.166
27.75,78.21,0.165
27.79,78.42,0.163
27.83,78.63,0.162
27.88,78.84,0.161
27.92,79.05,0.161
27.96,79.26,0.160
28.00,79.46,0.159
28.04,79.67,0.159
28.08,79.88,0.159
28.13,80.09,0.159
28.17,80.30,0.158
28.21,80.51,0.158
28.25,80.71,0.158
28.29,80.92,0.158
28.33,81.13,0.158
28.38,81.34,0.158
28.42,81.55,0.158
28.46,81.76,0.158
28.50,81.97,0.158
28.54,82.17,0.158
28.58,82.38,0.158
28.63,82.59,0.158
28.67,82.80,0.158
28.71,83.01,0.158
28.75,83.22,0.158
28.79,83.43,0.158
28.83,83.63,0.158
28.88,83.84,0.158
28.92,84.05,0.158
28.96,84.26,0.158
29.00,84.47,0.158
29.04,84.67,0.158
29.08,84.88,0.158
29.13,85.09,0.158
29.17,85.30,0.158
29.21,85.51,0.158
29.25,85.72,0.158
29.29,85.93,0.158
29.33,86.13,0.158
29.38,86.34,0.158
29.42,86.55,0.158
29.46,86.76,0.158
29.50,86.97,0.158
29.54,87.18,0.158
29.58,87.38,0.158
29.63,87.59,0.158
29.67,87.80,0.158
29.71,88.01,0.158
29.75,88.22,0.159
29.79,88.43,0.159
29.83,88.63,0.159
29.88,88.84,0.159
29.92,89.05,0.159
29.96,89.26,0.159
30.00,89.47,0.159
30.04,89.68,0.159
30.08,89.89,0.159
30.13,90.10,0.159
30.17,90.30,0.159
30.21,90.51,0.159
30.25,90.72,0.159
30.29,90.93,0.159
30.33,91.14,0.159
30.38,91.35,0.160
30.42,91.55,0.160
30.46,91.76,0.160
30.50,91.97,0.160
30.54,92.18,0.160
30.58,92.39,0.160
30.63,92.59,0.160
30.67,92.80,0.160
30.71,93.01,0.160
30.75,93.22,0.160
30.79,93.43,0.160
30.83,93.64,0.161
30.88,93.85,0.161
30.92,94.05,0.161
30.96,94.26,0.161
31.00,94.47,0.161
31.04,94.68,0.161
31.08,94.89,0.161
31.13,95.10,0.161
31.17,95.31,0.161
31.21,95.51,0.161
31.25,95.72,0.161
31.29,95.93,0.162
31.33,96.14,0.162
31.38,96.35,0.162
31.42,96.55,0.162
31.46,96.76,0.162
31.50,96.97,0.162
31.54,97.18,0.162
31.58,97.39,0.162
31.63,97.60,0.162
31.67,97.81,0.162
31.71,98.01,0.162
31.75,98.22,0.162
31.79,98.43,0.163
31.83,98.64,0.163
31.88,98.85,0.163
31.92,99.06,0.163
31.96,99.26,0.163
32.00,99.47,0.163
32.04,99.68,0.163
32.08,99.89,0.163
32.13,100.10,0.163
32.17,100.31,0.163
32.21,100.52,0.164
32.25,100.72,0.164
32.29,100.93,0.164
32.33,101.14,0.164
32.38,101.35,0.164
32.42,101.56,0.164
32.46,101.77,0.164
32.50,101.98,0.164
32.54,102.18,0.165
32.58,102.39,0.165
32.63,102.60,0.165
32.67,102.81,0.165
32.71,103.02,0.165
32.75,103.22,0.165
32.79,103.43,0.165
32.83,103.64,0.165
32.88,103.85,0.165
32.92,104.06,0.166
32.96,104.27,0.166
33.00,104.48,0.166
33.04,104.68,0.166
33.08,104.89,0.166
33.13,105.10,0.166
33.17,105.31,0.166
33.21,105.52,0.166
33.25,105.73,0.167
33.29,105.93,0.167
33.33,106.14,0.167
33.38,106.35,0.167
33.42,106.56,0.167
33.46,106.77,0.167
33.50,106.98,0.167
33.54,107.18,0.167
33.58,107.39,0.168
33.63,107.60,0.168
33.67,107.81,0.168
33.71,108.02,0.168
33.75,108.23,0.168
33.79,108.43,0.168
33.83,108.64,0.168
33.88,108.85,0.168
33.92,109.06,0.169
33.96,109.27,0.169
34.00,109.48,0.169
34.04,109.69,0.169
34.08,109.89,0.169
34.13,110.10,0.169
34.17,110.31,0.169
34.21,110.52,0.169
34.25,110.73,0.170
34.29,110.94,0.170
34.33,111.14,0.170
34.38,111.35,0.170
34.42,111.56,0.170
34.46,111.77,0.170
34.50,111.98,0.170
34.54,112.19,0.171
34.58,112.39,0.171
34.63,112.60,0.171
34.67,112.81,0.171
34.71,113.02,0.171
34.75,113.23,0.171
34.79,113.44,0.171
34.83,113.65,0.171
34.88,113.85,0.172
34.92,114.06,0.172
34.96,114.27,0.172
35.00,114.48,0.172
35.04,114.69,0.172
35.08,114.89,0.172
35.13,115.10,0.172
35.17,115.31,0.172
35.21,115.52,0.172
35.25,115.73,0.172
35.29,115.94,0.173
35.33,116.14,0.173
35.38,116.35,0.173
35.42,116.56,0.173
35.46,116.77,0.173
35.50,116.98,0.173
35.54,117.19,0.173
35.58,117.40,0.174
35.63,117.61,0.174
35.67,117.81,0.174
35.71,118.02,0.174
35.75,118.23,0.174
35.79,118.44,0.174
35.83,118.65,0.174
35.88,118.85,0.174
35.92,119.06,0.174
35.96,119.27,0.174
36.00,119.48,0.175
36.04,119.69,0.175
36.08,119.90,0.175
36.13,120.11,0.175
36.17,120.31,0.175
36.21,120.52,0.175
36.25,120.73,0.175
36.29,120.94,0.176
36.33,121.15,0.176
36.38,121.35,0.176
36.42,121.56,0.176
36.46,121.77,0.176
36.50,121.98,0.176
36.54,122.19,0.176
36.58,122.40,0.176
36.63,122.61,0.177
36.67,122.81,0.177
36.71,123.02,0.177
36.75,123.23,0.177
36.79,123.44,0.177
36.83,123.65,0.177
36.88,123.86,0.177
36.92,124.06,0.178
36.96,124.27,0.178
37.00,124.48,0.178
37.04,124.69,0.178
37.08,124.90,0.178
37.13,125.11,0.178
37.17,125.32,0.178
37.21,125.52,0.179
37.25,125.73,0.179
37.29,125.94,0.179
37.33,126.15,0.179
37.38,126.35,0.179
37.42,126.57,0.179
37.46,126.77,0.179
37.50,126.98,0.179
37.54,127.19,0.180
37.58,127.40,0.180
37.63,127.61,0.180
37.67,127.81,0.180
37.71,128.02,0.180
37.75,128.23,0.180
37.79,128.44,0.180
37.83,128.65,0.180
37.88,128.86,0.181
37.92,129.06,0.181
37.96,129.27,0.181
38.00,129.48,0.181
38.04,129.69,0.181
38.08,129.90,0.181
38.13,130.11,0.181
38.17,130.32,0.182
38.21,130.52,0.182
38.25,130.73,0.182
38.29,130.94,0.182
38.33,131.15,0.182
38.38,131.36,0.182
38.42,131.57,0.183
38.46,131.77,0.183
38.50,131.98,0.183
38.54,132.19,0.183
38.58,132.40,0.183
38.63,132.61,0.183
38.67,132.81,0.183
38.71,133.02,0.183
38.75,133.23,0.184
38.79,133.44,0.184
38.83,133.65,0.184
38.88,133.86,0.184
38.92,134.07,0.185
38.96,134.28,0.185
39.00,134.49,0.185
39.04,134.69,0.185
39.08,134.90,0.185
39.13,135.11,0.186
39.17,135.32,0.186
39.21,135.53,0.186
39.25,135.73,0.186
39.29,135.94,0.186
39.33,136.15,0.186
39.38,136.36,0.186
39.42,136.57,0.187
39.46,136.77,0.187
39.50,136.98,0.187
39.54,137.19,0.187
39.58,137.40,0.187
39.63,137.61,0.188
39.67,137.82,0.188
39.71,138.03,0.188
39.75,138.23,0.188
39.79,138.44,0.189
39.83,138.65,0.189
39.88,138.86,0.189
39.92,139.07,0.189
39.96,139.27,0.189
40.00,139.48,0.190
40.04,139.69,0.190
40.08,139.90,0.190
40.13,140.11,0.190
40.17,140.32,0.191
40.21,140.52,0.191
40.25,140.73,0.191
40.29,140.94,0.192
40.33,141.15,0.192
40.38,141.36,0.193
40.42,141.56,0.193
40.46,141.77,0.193
40.50,141.98,0.194
40.54,142.19,0.194
40.58,142.40,0.195
40.63,142.61,0.195
40.67,142.82,0.196
40.71,143.02,0.197
40.75,143.23,0.198
40.79,143.44,0.198
40.83,143.65,0.199
40.88,143.85,0.200
40.92,144.06,0.201
40.96,144.27,0.202
41.00,144.48,0.202
41.04,144.69,0.203
41.08,144.90,0.204
41.13,145.10,0.205
41.17,145.31,0.206
41.21,145.52,0.206
41.25,145.73,0.207
41.29,145.94,0.207
41.33,146.14,0.208
41.38,146.35,0.208
41.42,146.56,0.208
41.46,146.77,0.208
41.50,146.98,0.209
41.54,147.19,0.209
41.58,147.40,0.209
41.63,147.61,0.209
41.67,147.81,0.209
41.71,148.02,0.209
41.75,148.23,0.209
41.79,148.44,0.208
41.83,148.65,0.208
41.88,148.86,0.208
41.92,149.06,0.208
41.96,149.27,0.207
42.00,149.48,0.207
42.04,149.69,0.207
42.08,149.90,0.207
42.13,150.11,0.207
42.17,150.32,0.207
42.21,150.52,0.207
42.25,150.73,0.206
42.29,150.94,0.206
42.33,151.15,0.206
42.38,151.36,0.206
42.42,151.57,0.206
42.46,151.78,0.206
42.50,151.98,0.205
42.54,152.19,0.205
42.58,152.40,0.205
42.63,152.61,0.205
42.67,152.82,0.205
42.71,153.03,0.205
42.75,153.23,0.205
42.79,153.44,0.205
42.83,153.65,0.204
42.88,153.86,0.204
42.92,154.07,0.204
42.96,154.27,0.204
43.00,154.48,0.204
43.04,154.69,0.203
43.08,154.90,0.203
43.13,155.11,0.203
43.17,155.32,0.203
43.21,155.53,0.203
43.25,155.73,0.203
43.29,155.94,0.203
43.33,156.15,0.202
43.38,156.36,0.202
43.42,156.57,0.202
43.46,156.78,0.202
43.50,156.99,0.202
43.54,157.19,0.202
43.58,157.40,0.202
43.63,157.61,0.202
43.67,157.82,0.202
43.71,158.03,0.201
43.75,158.24,0.201
43.79,158.44,0.201
43.83,158.65,0.201
43.88,158.86,0.201
43.92,159.07,0.201
43.96,159.28,0.201
44.00,159.49,0.201
44.04,159.70,0.201
44.08,159.90,0.200
44.13,160.11,0.200
44.17,160.32,0.200
44.21,160.53,0.200
44.25,160.74,0.200
44.29,160.95,0.200
44.33,161.15,0.200
44.38,161.36,0.200
44.42,161.57,0.200
44.46,161.78,0.199
44.50,161.99,0.199
44.54,162.20,0.199
44.58,162.41,0.199
44.63,162.61,0.199
44.67,162.82,0.199
44.71,163.03,0.199
44.75,163.24,0.199
44.79,163.45,0.199
44.83,163.65,0.199
44.88,163.86,0.199
44.92,164.07,0.199
44.96,164.28,0.199
45.00,164.49,0.199
45.04,164.70,0.199
45.08,164.91,0.199
45.13,165.12,0.199
45.17,165.32,0.199
45.21,165.53,0.199
45.25,165.74,0.199
45.29,165.95,0.199
45.33,166.16,0.199
45.38,166.36,0.199
45.42,166.57,0.199
45.46,166.78,0.199
45.50,166.99,0.199
45.54,167.20,0.199
45.58,167.41,0.199
45.63,167.62,0.199
45.67,167.82,0.199
45.71,168.03,0.199
45.75,168.24,0.199
45.79,168.45,0.199
45.83,168.66,0.200
45.88,168.86,0.200
45.92,169.07,0.199
45.96,169.28,0.200
46.00,169.49,0.200
46.04,169.70,0.200
46.08,169.91,0.200
46.13,170.12,0.200
46.17,170.32,0.200
46.21,170.53,0.200
46.25,170.74,0.200
46.29,170.95,0.200
46.33,171.16,0.200
46.38,171.37,0.200
46.42,171.58,0.200
46.46,171.78,0.199
46.50,171.99,0.199
46.54,172.20,0.199
46.58,172.41,0.199
46.63,172.62,0.199
46.67,172.82,0.199
46.71,173.03,0.199
46.75,173.24,0.199
46.79,173.45,0.198
46.83,173.66,0.198
46.88,173.87,0.198
46.92,174.08,0.198
46.96,174.28,0.198
47.00,174.49,0.198
47.04,174.70,0.198
47.08,174.91,0.197
47.13,175.12,0.197
47.17,175.33,0.197
47.21,175.53,0.197
47.25,175.74,0.197
47.29,175.95,0.197
47.33,176.16,0.196
47.38,176.37,0.196
47.42,176.58,0.196
47.46,176.78,0.196
47.50,176.99,0.196
47.54,177.20,0.196
47.58,177.41,0.196
47.63,177.62,0.195
47.67,177.83,0.195
47.71,178.04,0.195
47.75,178.24,0.195
47.79,178.45,0.194
47.83,178.66,0.194
47.88,178.87,0.194
47.92,179.08,0.194
47.96,179.29,0.193
48.00,179.50,0.193
48.04,179.70,0.193
48.08,179.91,0.193
48.13,180.12,0.192
48.17,180.33,0.192
48.21,180.54,0.192
48.25,180.74,0.191
48.29,180.95,0.191
48.33,181.16,0.190
48.38,181.37,0.190
48.42,181.58,0.190
48.46,181.79,0.189
48.50,182.00,0.189
48.54,182.21,0.188
48.58,182.41,0.188
48.63,182.62,0.188
48.67,182.83,0.187
48.71,183.04,0.187
48.75,183.25,0.187
48.79,183.45,0.186
48.83,183.66,0.186
48.88,183.87,0.186
48.92,184.08,0.185
48.96,184.29,0.185
49.00,184.50,0.185
49.04,184.71,0.184
49.08,184.92,0.184
49.13,185.12,0.184
49.17,185.33,0.183
49.21,185.54,0.183
49.25,185.75,0.183
49.29,185.96,0.182
49.33,186.17,0.182
49.38,186.38,0.181
49.42,186.59,0.181
49.46,186.79,0.181
49.50,187.00,0.180
49.54,187.21,0.180
49.58,187.42,0.180
49.63,187.63,0.179
49.67,187.84,0.179
49.71,188.04,0.179
49.75,188.25,0.179
49.79,188.46,0.179
49.83,188.67,0.178
49.88,188.88,0.178
49.92,189.08,0.178
49.96,189.29,0.178
50.00,189.50,0.177
50.04,189.71,0.177
50.08,189.92,0.177
50.13,190.13,0.177
50.17,190.33,0.177
50.21,190.54,0.177
50.25,190.75,0.177
50.29,190.96,0.176
50.33,191.17,0.176
50.38,191.38,0.176
50.42,191.59,0.176
50.46,191.80,0.176
50.50,192.00,0.176
50.54,192.21,0.176
50.58,192.42,0.176
50.63,192.63,0.176
50.67,192.84,0.176
50.71,193.04,0.175
50.75,193.25,0.175
50.79,193.46,0.175
50.83,193.67,0.175
50.88,193.88,0.175
50.92,194.09,0.175
50.96,194.29,0.174
51.00,194.50,0.174
51.04,194.71,0.174
51.08,194.92,0.174
51.13,195.13,0.174
51.17,195.34,0.174
51.21,195.54,0.174
51.25,195.75,0.174
51.29,195.96,0.174
51.33,196.17,0.174
51.38,196.38,0.174
51.42,196.59,0.174
51.46,196.80,0.174
51.50,197.00,0.177
51.54,197.21,0.177
51.58,197.42,0.176
51.63,197.63,0.176
51.67,197.84,0.176
51.71,198.05,0.175
51.75,198.25,0.175
51.79,198.46,0.175
51.83,198.67,0.175
51.88,198.88,0.175
51.92,199.09,0.174
51.96,199.30,0.174
52.00,199.50,0.174
52.04,199.71,0.174
52.08,199.92,0.174
52.13,200.13,0.174
52.17,200.34,0.174
52.21,200.54,0.174
52.25,200.75,0.173
52.29,200.96,0.173
52.33,201.17,0.173
52.38,201.38,0.173
52.42,201.59,0.173
52.46,201.80,0.173
52.50,202.01,0.173
52.54,202.21,0.173
52.58,202.42,0.173
52.63,202.63,0.173
52.67,202.84,0.173
52.71,203.05,0.173
52.75,203.26,0.173
52.79,203.47,0.173
52.83,203.67,0.173
52.88,203.88,0.173
52.92,204.09,0.173
52.96,204.30,0.173
53.00,204.51,0.173
53.04,204.71,0.173
53.08,204.92,0.173
53.13,205.13,0.173
53.17,205.34,0.173
53.21,205.55,0.173
53.25,205.76,0.173
53.29,205.96,0.172
53.33,206.17,0.172
53.38,206.38,0.172
53.42,206.59,0.172
53.46,206.80,0.172
53.50,207.01,0.172
53.54,207.22,0.172
53.58,207.42,0.172
53.63,207.63,0.172
53.67,207.84,0.171
53.71,208.05,0.171
53.75,208.26,0.171
53.79,208.46,0.171
53.83,208.67,0.171
53.88,208.88,0.171
53.92,209.09,0.171
53.96,209.30,0.171
54.00,209.51,0.171
54.04,209.71,0.171
54.08,209.92,0.171
54.13,210.13,0.170
54.17,210.34,0.170
54.21,210.55,0.170
54.25,210.76,0.170
54.29,210.96,0.170
54.33,211.17,0.170
54.38,211.38,0.170
54.42,211.59,0.170
54.46,211.80,0.170
54.50,212.01,0.170
54.54,212.22,0.170
54.58,212.42,0.170
54.63,212.63,0.170
54.67,212.84,0.170
54.71,213.05,0.170
54.75,213.26,0.170
54.79,213.47,0.170
54.83,213.67,0.170
54.88,213.88,0.170
54.92,214.09,0.170
54.96,214.30,0.170
55.00,214.51,0.169
55.04,214.72,0.169
55.08,214.92,0.169
55.13,215.13,0.169
55.17,215.34,0.170
55.21,215.55,0.170
55.25,215.76,0.170
55.29,215.96,0.169
55.33,216.17,0.169
55.38,216.38,0.169
55.42,216.59,0.169
55.46,216.80,0.169
55.50,217.01,0.169
55.54,217.22,0.169
55.58,217.42,0.169
55.63,217.63,0.169
55.67,217.84,0.169
55.71,218.05,0.169
55.75,218.26,0.169
55.79,218.47,0.169
55.83,218.67,0.169
55.88,218.88,0.169
55.92,219.09,0.169
55.96,219.30,0.169
56.00,219.51,0.169
56.04,219.72,0.169
56.08,219.92,0.169
56.13,220.13,0.169
56.17,220.34,0.169
56.21,220.55,0.169
56.25,220.76,0.169
56.29,220.97,0.169
56.33,221.18,0.169
56.38,221.38,0.169
56.42,221.59,0.169
56.46,221.80,0.169
56.50,222.01,0.169
56.54,222.22,0.168
56.58,222.42,0.168
56.63,222.63,0.168
56.67,222.84,0.168
56.71,223.05,0.168
56.75,223.26,0.168
56.79,223.47,0.168
56.83,223.68,0.168
56.88,223.88,0.168
56.92,224.09,0.168
56.96,224.30,0.168
57.00,224.51,0.168
57.04,224.72,0.168
57.08,224.92,0.168
57.13,225.13,0.168
57.17,225.34,0.168
57.21,225.55,0.168
57.25,225.76,0.168
57.29,225.97,0.168
57.33,226.18,0.168
57.38,226.38,0.168
57.42,226.59,0.168
57.46,226.80,0.168
57.50,227.01,0.167
57.54,227.22,0.167
57.58,227.43,0.167
57.63,227.63,0.167
57.67,227.84,0.167
57.71,228.05,0.167
57.75,228.26,0.167
57.79,228.47,0.167
57.83,228.68,0.167
57.88,228.88,0.167
57.92,229.09,0.167
57.96,229.30,0.167
58.00,229.51,0.167
58.04,229.72,0.167
58.08,229.92,0.167
58.13,230.13,0.167
58.17,230.34,0.167
58.21,230.55,0.167
58.25,230.76,0.167
58.29,230.97,0.167
58.33,231.18,0.167
58.38,231.38,0.167
58.42,231.59,0.167
58.46,231.80,0.167
58.50,232.01,0.167
58.54,232.22,0.167
58.58,232.43,0.167
58.63,232.63,0.167
58.67,232.84,0.167
58.71,233.05,0.167
58.75,233.26,0.167
58.79,233.47,0.167
58.83,233.67,0.167
58.88,233.88,0.167
58.92,234.09,0.167
58.96,234.30,0.167
59.00,234.51,0.167
59.04,234.72,0.167
59.08,234.93,0.167
59.13,235.13,0.167
59.17,235.34,0.167
59.21,235.55,0.167
59.25,235.76,0.168
59.29,235.97,0.168
59.33,236.18,0.168
59.38,236.38,0.168
59.42,236.59,0.168
59.46,236.80,0.168
59.50,237.01,0.168
59.54,237.22,0.168
59.58,237.42,0.168
59.63,237.63,0.168
59.67,237.84,0.168
59.71,238.05,0.168
59.75,238.26,0.168
59.79,238.46,0.168
59.83,238.67,0.168
59.88,238.88,0.168
59.92,239.09,0.169
59.96,239.30,0.169
60.00,239.51,0.169
60.04,239.72,0.169
60.08,239.93,0.169
60.13,240.13,0.169
60.17,240.34,0.170
60.21,240.55,0.170
60.25,240.76,0.170
60.29,240.97,0.170
60.33,241.17,0.170
60.38,241.38,0.170
60.42,241.59,0.170
60.46,241.80,0.170
60.50,242.01,0.171
60.54,242.22,0.171
60.58,242.42,0.171
60.63,242.63,0.171
60.67,242.84,0.171
60.71,243.05,0.171
60.75,243.26,0.171
60.79,243.47,0.172
60.83,243.67,0.172
60.88,243.88,0.172
60.92,244.09,0.172
60.96,244.30,0.172
61.00,244.51,0.172
61.04,244.71,0.173
61.08,244.92,0.173
61.13,245.13,0.173
61.17,245.34,0.173
61.21,245.55,0.174
61.25,245.76,0.174
61.29,245.96,0.174
61.33,246.17,0.175
61.38,246.38,0.175
61.42,246.59,0.175
61.46,246.80,0.176
61.50,247.00,0.176
61.54,247.21,0.176
61.58,247.42,0.176
61.63,247.63,0.177
61.67,247.84,0.177
61.71,248.05,0.177
61.75,248.26,0.178
61.79,248.46,0.178
61.83,248.67,0.178
61.88,248.88,0.179
61.92,249.09,0.179
61.96,249.30,
61.99,,

[step]
Ramp 5.00 °C/min to -60.00 °C
Time,Temperature,Heat Flow (Normalized)
min,°C,W/g
62.09,249.88,0.171
62.13,250.00,0.137
62.17,250.06,0.087
62.21,250.05,0.021
62.25,249.97,-0.063
62.29,249.84,-0.137
62.34,249.68,-0.182
62.38,249.49,-0.210
62.42,249.30,-0.222
62.46,249.11,-0.231
62.50,248.91,-0.235
62.54,248.71,-0.237
62.59,248.50,-0.239
62.63,248.30,-0.241
62.67,248.10,-0.241
62.71,247.89,-0.242
62.75,247.69,-0.242
62.79,247.48,-0.242
62.84,247.27,-0.243
62.88,247.07,-0.243
62.92,246.86,-0.243
62.96,246.66,-0.243
63.00,246.45,-0.243
63.04,246.24,-0.243
63.09,246.04,-0.243
63.13,245.83,-0.243
63.17,245.62,-0.242
63.21,245.42,-0.242
63.25,245.21,-0.242
63.29,245.00,-0.242
63.34,244.79,-0.242
63.38,244.58,-0.242
63.42,244.38,-0.242
63.46,244.17,-0.241
63.50,243.96,-0.241
63.54,243.75,-0.241
63.59,243.55,-0.240
63.63,243.34,-0.240
63.67,243.13,-0.240
63.71,242.92,-0.239
63.75,242.72,-0.239
63.79,242.51,-0.239
63.84,242.30,-0.239
63.88,242.09,-0.239
63.92,241.88,-0.238
63.96,241.68,-0.238
64.00,241.47,-0.237
64.04,241.26,-0.237
64.09,241.05,-0.237
64.13,240.85,-0.237
64.17,240.64,-0.237
64.21,240.43,-0.237
64.25,240.22,-0.236
64.29,240.01,-0.236
64.34,239.81,-0.236
64.38,239.60,-0.236
64.42,239.39,-0.236
64.46,239.18,-0.236
64.50,238.97,-0.235
64.54,238.76,-0.235
64.59,238.56,-0.235
64.63,238.35,-0.235
64.67,238.14,-0.235
64.71,237.93,-0.235
64.75,237.72,-0.235
64.79,237.52,-0.235
64.84,237.31,-0.235
64.88,237.10,-0.234
64.92,236.89,-0.234
64.96,236.68,-0.234
65.00,236.48,-0.234
65.04,236.27,-0.234
65.09,236.06,-0.234
65.13,235.85,-0.234
65.17,235.64,-0.234
65.21,235.44,-0.234
65.25,235.23,-0.234
65.29,235.02,-0.234
65.34,234.81,-0.234
65.38,234.60,-0.234
65.42,234.39,-0.233
65.46,234.19,-0.233
65.50,233.98,-0.233
65.54,233.77,-0.233
65.59,233.56,-0.233
65.63,233.35,-0.233
65.67,233.15,-0.233
65.71,232.94,-0.233
65.75,232.73,-0.233
65.79,232.52,-0.233
65.84,232.31,-0.233
65.88,232.11,-0.233
65.92,231.90,-0.233
65.96,231.69,-0.233
66.00,231.48,-0.233
66.04,231.27,-0.233
66.09,231.06,-0.233
66.13,230.86,-0.233
66.17,230.65,-0.232
66.21,230.44,-0.233
66.25,230.23,-0.233
66.29,230.02,-0.233
66.34,229.81,-0.233
66.38,229.61,-0.233
66.42,229.40,-0.232
66.46,229.19,-0.232
66.50,228.98,-0.232
66.54,228.77,-0.232
66.59,228.57,-0.232
66.63,228.36,-0.232
66.67,228.15,-0.232
66.71,227.94,-0.232
66.75,227.74,-0.232
66.79,227.53,-0.232
66.84,227.32,-0.232
66.88,227.11,-0.232
66.92,226.90,-0.232
66.96,226.69,-0.232
67.00,226.48,-0.232
67.04,226.28,-0.232
67.09,226.07,-0.232
67.13,225.86,-0.232
67.17,225.65,-0.232
67.21,225.44,-0.232
67.25,225.24,-0.232
67.29,225.03,-0.232
67.34,224.82,-0.231
67.38,224.61,-0.231
67.42,224.41,-0.231
67.46,224.20,-0.231
67.50,223.99,-0.231
67.54,223.78,-0.231
67.59,223.57,-0.231
67.63,223.36,-0.231
67.67,223.16,-0.231
67.71,222.95,-0.231
67.75,222.74,-0.231
67.79,222.53,-0.231
67.84,222.32,-0.231
67.88,222.11,-0.231
67.92,221.91,-0.231
67.96,221.70,-0.231
68.00,221.49,-0.231
68.04,221.28,-0.231
68.09,221.07,-0.231
68.13,220.87,-0.231
68.17,220.66,-0.231
68.21,220.45,-0.231
68.25,220.24,-0.231
68.30,220.03,-0.231
68.34,219.82,-0.231
68.38,219.62,-0.231
68.42,219.41,-0.231
68.46,219.20,-0.231
68.50,218.99,-0.231
68.55,218.78,-0.231
68.59,218.58,-0.230
68.63,218.37,-0.231
68.67,218.16,-0.231
68.71,217.95,-0.231
68.75,217.74,-0.231
68.80,217.53,-0.231
68.84,217.33,-0.231
68.88,217.12,-0.231
68.92,216.91,-0.230
68.96,216.70,-0.230
69.00,216.49,-0.230
69.05,216.29,-0.230
69.09,216.08,-0.230
69.13,215.87,-0.230
69.17,215.66,-0.230
69.21,215.45,-0.230
69.25,215.25,-0.230
69.30,215.04,-0.230
69.34,214.83,-0.230
69.38,214.62,-0.230
69.42,214.41,-0.230
69.46,214.20,-0.230
69.50,214.00,-0.230
69.55,213.79,-0.230
69.59,213.58,-0.230
69.63,213.37,-0.230
69.67,213.16,-0.230
69.71,212.96,-0.230
69.75,212.75,-0.230
69.80,212.54,-0.230
69.84,212.33,-0.230
69.88,212.12,-0.230
69.92,211.91,-0.230
69.96,211.71,-0.230
70.00,211.50,-0.230
70.05,211.29,-0.230
70.09,211.08,-0.230
70.13,210.87,-0.229
70.17,210.67,-0.229
70.21,210.46,-0.229
70.25,210.25,-0.229
70.30,210.04,-0.229
70.34,209.83,-0.229
70.38,209.62,-0.229
70.42,209.42,-0.229
70.46,209.21,-0.229
70.50,209.00,-0.229
70.55,208.79,-0.229
70.59,208.58,-0.229
70.63,208.37,-0.229
70.67,208.17,-0.229
70.71,207.96,-0.229
70.75,207.75,-0.229
70.80,207.54,-0.229
70.84,207.33,-0.229
70.88,207.13,-0.229
70.92,206.92,-0.229
70.96,206.71,-0.229
71.00,206.50,-0.229
71.05,206.29,-0.229
71.09,206.09,-0.229
71.13,205.88,-0.229
71.17,205.67,-0.229
71.21,205.46,-0.229
71.25,205.25,-0.229
71.30,205.04,-0.229
71.34,204.84,-0.229
71.38,204.63,-0.229
71.42,204.42,-0.229
71.46,204.21,-0.229
71.50,204.01,-0.229
71.55,203.80,-0.228
71.59,203.59,-0.229
71.63,203.38,-0.229
71.67,203.17,-0.229
71.71,202.96,-0.229
71.75,202.75,-0.229
71.80,202.55,-0.229
71.84,202.34,-0.228
71.88,202.13,-0.228
71.92,201.92,-0.228
71.96,201.71,-0.228
72.00,201.51,-0.228
72.05,201.30,-0.228
72.09,201.09,-0.228
72.13,200.88,-0.228
72.17,200.67,-0.228
72.21,200.47,-0.228
72.25,200.26,-0.229
72.30,200.05,-0.229
72.34,199.84,-0.228
72.38,199.63,-0.228
72.42,199.43,-0.228
72.46,199.22,-0.228
72.50,199.01,-0.228
72.55,198.80,-0.228
72.59,198.59,-0.228
72.63,198.38,-0.228
72.67,198.18,-0.228
72.71,197.97,-0.228
72.75,197.76,-0.228
72.80,197.55,-0.228
72.84,197.34,-0.228
72.88,197.13,-0.228
72.92,196.93,-0.228
72.96,196.72,-0.228
73.00,196.51,-0.228
73.05,196.30,-0.228
73.09,196.09,-0.228
73.13,195.89,-0.228
73.17,195.68,-0.228
73.21,195.47,-0.228
73.25,195.26,-0.228
73.30,195.05,-0.228
73.34,194.85,-0.228
73.38,194.64,-0.228
73.42,194.43,-0.228
73.46,194.22,-0.228
73.50,194.01,-0.228
73.55,193.80,-0.228
73.59,193.60,-0.228
73.63,193.39,-0.228
73.67,193.18,-0.228
73.71,192.97,-0.227
73.75,192.76,-0.227
73.80,192.56,-0.227
73.84,192.35,-0.227
73.88,192.14,-0.227
73.92,191.93,-0.228
73.96,191.72,-0.228
74.00,191.51,-0.228
74.05,191.31,-0.227
74.09,191.10,-0.227
74.13,190.89,-0.227
74.17,190.68,-0.227
74.21,190.47,-0.227
74.25,190.27,-0.227
74.30,190.06,-0.227
74.34,189.85,-0.227
74.38,189.64,-0.227
74.42,189.43,-0.227
74.46,189.22,-0.227
74.50,189.02,-0.227
74.55,188.81,-0.227
74.59,188.60,-0.227
74.63,188.39,-0.227
74.67,188.18,-0.227
74.71,187.97,-0.227
74.75,187.77,-0.227
74.80,187.56,-0.227
74.84,187.35,-0.227
74.88,187.14,-0.227
74.92,186.93,-0.227
74.96,186.73,-0.227
75.00,186.52,-0.227
75.05,186.31,-0.227
75.09,186.10,-0.227
75.13,185.89,-0.227
75.17,185.69,-0.227
[...]
269.97,38.07,0.142
270.02,38.28,0.142
270.06,38.49,0.142
270.10,38.70,0.142
270.14,38.91,0.142
270.18,39.12,0.142
270.22,39.32,0.142
270.27,39.53,0.142
270.31,39.74,0.142
270.35,39.95,0.142
270.39,40.16,0.142
270.43,40.37,0.142
270.47,40.58,0.142
270.52,40.78,0.142
270.56,40.99,0.142
270.60,41.20,0.142
270.64,41.41,0.142
270.68,41.62,0.143
270.72,41.83,0.143
270.77,42.03,0.143
270.81,42.24,0.143
270.85,42.45,0.143
270.89,42.66,0.143
270.93,42.87,0.143
270.97,43.08,0.143
271.02,43.28,0.143
271.06,43.49,0.143
271.10,43.70,0.143
271.14,43.91,0.143
271.18,44.12,0.143
271.22,44.33,0.143
271.27,44.54,0.143
271.31,44.74,0.143
271.35,44.95,0.143
271.39,45.16,0.143
271.43,45.37,0.143
271.47,45.58,0.144
271.52,45.79,0.144
271.56,46.00,0.144
271.60,46.20,0.144
271.64,46.41,0.144
271.68,46.62,0.144
271.72,46.83,0.144
271.77,47.04,0.144
271.81,47.25,0.144
271.85,47.45,0.144
271.89,47.66,0.144
271.93,47.87,0.144
271.97,48.08,0.144
272.02,48.29,0.145
272.06,48.50,0.145
272.10,48.71,0.145
272.14,48.91,0.145
272.18,49.12,0.145
272.22,49.33,0.145
272.27,49.54,0.145
272.31,49.75,0.145
272.35,49.96,0.145
272.39,50.17,0.145
272.43,50.37,0.145
272.47,50.58,0.145
272.52,50.79,0.145
272.56,51.00,0.145
272.60,51.21,0.145
272.64,51.42,0.145
272.68,51.63,0.145
272.72,51.83,0.145
272.77,52.04,0.145
272.81,52.25,0.145
272.85,52.46,0.145
272.89,52.67,0.145
272.93,52.88,0.146
272.97,53.08,0.146
273.02,53.29,0.146
273.06,53.50,0.146
273.10,53.71,0.146
273.14,53.92,0.146
273.18,54.13,0.146
273.22,54.34,0.146
273.27,54.54,0.146
273.31,54.75,0.146
273.35,54.96,0.146
273.39,55.17,0.146
273.43,55.38,0.146
273.47,55.59,0.146
273.52,55.79,0.146
273.56,56.00,0.146
273.60,56.21,0.147
273.64,56.42,0.147
273.68,56.63,0.147
273.72,56.84,0.147
273.77,57.05,0.147
273.81,57.25,0.147
273.85,57.46,0.147
273.89,57.67,0.147
273.93,57.88,0.147
273.97,58.09,0.147
274.02,58.29,0.147
274.06,58.50,0.147
274.10,58.71,0.147
274.14,58.92,0.147
274.18,59.13,0.147
274.22,59.34,0.147
274.27,59.55,0.147
274.31,59.76,0.147
274.35,59.96,0.147
274.39,60.17,0.147
274.43,60.38,0.147
274.47,60.59,0.147
274.52,60.80,0.147
274.56,61.01,0.147
274.60,61.21,0.147
274.64,61.42,0.147
274.68,61.63,0.147
274.72,61.84,0.147
274.77,62.05,0.147
274.81,62.26,0.147
274.85,62.46,0.147
274.89,62.67,0.148
274.93,62.88,0.148
274.97,63.09,0.148
275.02,63.30,0.148
275.06,63.51,0.148
275.10,63.71,0.147
275.14,63.92,0.148
275.18,64.13,0.148
275.22,64.34,0.148
275.27,64.55,0.148
275.31,64.76,0.148
275.35,64.97,0.148
275.39,65.17,0.148
275.43,65.38,0.148
275.47,65.59,0.148
275.52,65.80,0.148
275.56,66.01,0.148
275.60,66.22,0.148
275.64,66.43,0.148
275.68,66.63,0.148
275.72,66.84,0.148
275.77,67.05,0.148
275.81,67.26,0.148
275.85,67.47,0.148
275.89,67.68,0.148
275.93,67.89,0.148
275.97,68.09,0.148
276.02,68.30,0.148
276.06,68.51,0.148
276.10,68.72,0.148
276.14,68.93,0.148
276.18,69.14,0.148
276.22,69.34,0.148
276.27,69.55,0.148
276.31,69.76,0.148
276.35,69.97,0.148
276.39,70.18,0.148
276.43,70.39,0.148
276.47,70.59,0.148
276.52,70.80,0.148
276.56,71.01,0.148
276.60,71.22,0.148
276.64,71.43,0.148
276.68,71.64,0.148
276.72,71.85,0.148
276.77,72.05,0.148
276.81,72.26,0.148
276.85,72.47,0.148
276.89,72.68,0.148
276.93,72.89,0.148
276.97,73.10,0.149
277.02,73.31,0.149
277.06,73.51,0.149
277.10,73.72,0.149
277.14,73.93,0.149
277.18,74.14,0.149
277.22,74.35,0.149
277.27,74.56,0.149
277.31,74.76,0.149
277.35,74.97,0.149
277.39,75.18,0.149
277.43,75.39,0.150
277.47,75.60,0.150
277.52,75.81,0.150
277.56,76.02,0.150
277.60,76.22,0.150
277.64,76.43,0.150
277.68,76.64,0.150
277.72,76.85,0.150
277.77,77.06,0.150
277.81,77.27,0.151
277.85,77.47,0.151
277.89,77.68,0.151
277.93,77.89,0.151
277.97,78.10,0.151
278.02,78.31,0.151
278.06,78.52,0.151
278.10,78.72,0.152
278.14,78.93,0.152
278.18,79.14,0.152
278.22,79.35,0.152
278.27,79.56,0.152
278.31,79.77,0.152
278.35,79.97,0.152
278.39,80.18,0.153
278.43,80.39,0.153
278.47,80.60,0.153
278.52,80.81,0.153
278.56,81.02,0.153
278.60,81.23,0.153
278.64,81.43,0.154
278.68,81.64,0.154
278.72,81.85,0.154
278.77,82.06,0.154
278.81,82.27,0.154
278.85,82.47,0.154
278.89,82.68,0.154
278.93,82.89,0.155
278.97,83.10,0.155
279.02,83.31,0.155
279.06,83.52,0.155
279.10,83.73,0.155
279.14,83.93,0.155
279.18,84.14,0.156
279.22,84.35,0.156
279.27,84.56,0.156
279.31,84.77,0.156
279.35,84.98,0.156
279.39,85.18,0.156
279.43,85.39,0.156
279.47,85.60,0.157
279.52,85.81,0.157
279.56,86.02,0.157
279.60,86.23,0.157
279.64,86.43,0.157
279.68,86.64,0.157
279.72,86.85,0.157
279.77,87.06,0.158
279.81,87.27,0.158
279.85,87.48,0.158
279.89,87.69,0.158
279.93,87.89,0.158
279.97,88.10,0.158
280.02,88.31,0.158
280.06,88.52,0.159
280.10,88.73,0.159
280.14,88.94,0.159
280.18,89.14,0.159
280.22,89.35,0.159
280.27,89.56,0.159
280.31,89.77,0.159
280.35,89.98,0.160
280.39,90.19,0.160
280.43,90.40,0.160
280.47,90.60,0.160
280.52,90.81,0.160
280.56,91.02,0.160
280.60,91.23,0.160
280.64,91.44,0.160
280.68,91.64,0.161
280.72,91.85,0.161
280.77,92.06,0.161
280.81,92.27,0.161
280.85,92.48,0.161
280.89,92.69,0.161
280.93,92.89,0.161
280.97,93.10,0.161
281.02,93.31,0.162
281.06,93.52,0.162
281.10,93.73,0.162
281.14,93.94,0.162
281.18,94.15,0.162
281.22,94.35,0.162
281.27,94.56,0.162
281.31,94.77,0.162
281.35,94.98,0.162
281.39,95.19,0.163
281.43,95.40,0.163
281.47,95.61,0.163
281.52,95.81,0.163
281.56,96.02,0.163
281.60,96.23,0.163
281.64,96.44,0.163
281.68,96.65,0.163
281.72,96.86,0.163
281.77,97.06,0.163
281.81,97.27,0.164
281.85,97.48,0.164
281.89,97.69,0.164
281.93,97.90,0.164
281.97,98.11,0.164
282.02,98.32,0.164
282.06,98.52,0.164
282.10,98.73,0.164
282.14,98.94,0.164
282.18,99.15,0.165
282.22,99.36,0.165
282.27,99.57,0.165
282.31,99.78,0.165
282.35,99.98,0.165
282.39,100.19,0.165
282.43,100.40,0.165
282.47,100.61,0.165
282.52,100.82,0.165
282.56,101.02,0.165
282.60,101.23,0.165
282.64,101.44,0.166
282.68,101.65,0.166
282.72,101.86,0.166
282.77,102.07,0.166
282.81,102.27,0.166
282.85,102.48,0.166
282.89,102.69,0.166
282.93,102.90,0.166
282.97,103.11,0.166
283.02,103.32,0.166
283.06,103.52,0.166
283.10,103.73,0.167
283.14,103.94,0.167
283.18,104.15,0.167
283.22,104.36,0.167
283.27,104.57,0.167
283.31,104.78,0.167
283.35,104.98,0.167
283.39,105.19,0.167
283.43,105.40,0.167
283.47,105.61,0.167
283.52,105.82,0.167
283.56,106.03,0.167
283.60,106.23,0.168
283.64,106.44,0.168
283.68,106.65,0.168
283.72,106.86,0.168
283.77,107.07,0.168
283.81,107.28,0.168
283.85,107.49,0.168
283.89,107.69,0.168
283.93,107.90,0.168
283.97,108.11,0.168
284.02,108.32,0.168
284.06,108.53,0.168
284.10,108.73,0.168
284.14,108.94,0.169
284.18,109.15,0.169
284.22,109.36,0.169
284.27,109.57,0.169
284.31,109.78,0.169
284.35,109.99,0.169
284.39,110.19,0.169
284.43,110.40,0.169
284.47,110.61,0.169
284.52,110.82,0.169
284.56,111.03,0.170
284.60,111.24,0.170
284.64,111.44,0.170
284.68,111.65,0.170
284.72,111.86,0.170
284.77,112.07,0.170
284.81,112.28,0.170
284.85,112.49,0.170
284.89,112.69,0.170
284.93,112.90,0.170
284.97,113.11,0.170
285.02,113.32,0.171
285.06,113.53,0.171
285.10,113.74,0.171
285.14,113.95,0.171
285.18,114.16,0.171
285.22,114.36,0.171
285.27,114.57,0.171
285.31,114.78,0.171
285.35,114.99,0.171
285.39,115.20,0.171
285.43,115.40,0.172
285.47,115.61,0.172
285.52,115.82,0.172
285.56,116.03,0.172
285.60,116.24,0.172
285.64,116.45,0.172
285.68,116.66,0.172
285.72,116.86,0.172
285.77,117.07,0.173
285.81,117.28,0.173
285.85,117.49,0.173
285.89,117.70,0.173
285.93,117.91,0.173
285.97,118.11,0.173
286.02,118.32,0.173
286.06,118.53,0.173
286.10,118.74,0.174
286.14,118.95,0.174
286.18,119.16,0.174
286.22,119.36,0.174
286.27,119.57,0.174
286.31,119.78,0.174
286.35,119.99,0.174
286.39,120.20,0.174
286.43,120.41,0.174
286.47,120.61,0.174
286.52,120.82,0.175
286.56,121.03,0.175
286.60,121.24,0.175
286.64,121.45,0.175
286.68,121.66,0.175
286.72,121.86,0.175
286.77,122.07,0.175
286.81,122.28,0.175
286.85,122.49,0.175
286.89,122.70,0.176
286.93,122.91,0.176
286.97,123.11,0.176
287.02,123.32,0.176
287.06,123.53,0.176
287.10,123.74,0.176
287.14,123.95,0.176
287.18,124.16,0.177
287.22,124.37,0.177
287.27,124.57,0.177
287.31,124.78,0.177
287.35,124.99,0.177
287.39,125.20,0.177
287.43,125.41,0.177
287.47,125.61,0.177
287.52,125.82,0.177
287.56,126.03,0.178
287.60,126.24,0.178
287.64,126.45,0.178
287.68,126.66,0.178
287.72,126.87,0.178
287.77,127.08,0.179
287.81,127.28,0.179
287.85,127.49,0.179
287.89,127.70,0.179
287.93,127.91,0.179
287.97,128.12,0.179
288.02,128.32,0.179
288.06,128.53,0.179
288.10,128.74,0.179
288.14,128.95,0.179
288.18,129.16,0.179
288.22,129.37,0.180
288.27,129.57,0.180
288.31,129.78,0.180
288.35,129.99,0.180
288.39,130.20,0.180
288.43,130.41,0.180
288.47,130.62,0.181
288.52,130.83,0.181
288.56,131.03,0.181
288.60,131.24,0.181
288.64,131.45,0.181
288.68,131.66,0.181
288.72,131.87,0.181
288.77,132.07,0.181
288.81,132.28,0.182
288.85,132.49,0.182
288.89,132.70,0.182
288.93,132.91,0.182
288.97,133.12,0.182
289.02,133.32,0.182
289.06,133.54,0.183
289.10,133.74,0.183
289.14,133.95,0.183
289.18,134.16,0.183
289.22,134.37,0.183
289.27,134.58,0.183
289.31,134.78,0.183
289.35,134.99,0.184
289.39,135.20,0.184
289.43,135.41,0.184
289.47,135.62,0.184
289.52,135.83,0.184
289.56,136.03,0.184
289.60,136.24,0.184
289.64,136.45,0.185
289.68,136.66,0.185
289.72,136.87,0.185
289.77,137.08,0.185
289.81,137.28,0.185
289.85,137.49,0.185
289.89,137.70,0.186
289.93,137.91,0.186
289.97,138.12,0.186
290.02,138.33,0.186
290.06,138.53,0.186
290.10,138.74,0.186
290.14,138.95,0.187
290.18,139.16,0.187
290.22,139.37,0.187
290.27,139.58,0.187
290.31,139.78,0.187
290.35,139.99,0.187
290.39,140.20,0.187
290.43,140.41,0.188
290.47,140.62,0.188
290.52,140.83,0.188
290.56,141.03,0.188
290.60,141.24,0.188
290.64,141.45,0.188
290.68,141.66,0.188
290.72,141.87,0.189
290.77,142.08,0.189
290.81,142.28,0.189
290.85,142.49,0.189
290.89,142.70,0.189
290.93,142.91,0.190
290.97,143.12,0.190
291.02,143.33,0.190
291.06,143.54,0.190
291.10,143.74,0.190
291.14,143.95,0.190
291.18,144.16,0.191
291.22,144.37,0.191
291.27,144.58,0.191
291.31,144.79,0.191
291.35,144.99,0.192
291.39,145.20,0.192
291.43,145.41,0.192
291.47,145.62,0.192
291.52,145.83,0.192
291.56,146.03,0.192
291.60,146.24,0.193
291.64,146.45,0.193
291.68,146.66,0.193
291.72,146.87,0.193
291.77,147.08,0.193
291.81,147.28,0.193
291.85,147.49,0.194
291.89,147.70,0.194
291.93,147.91,0.194
291.97,148.12,0.194
292.02,148.33,0.194
292.06,148.54,0.195
292.10,148.74,0.195
292.14,148.95,0.195
292.18,149.16,0.195
292.22,149.37,0.195
292.27,149.58,0.195
292.31,149.79,0.196
292.35,149.99,0.196
292.39,150.20,0.196
292.43,150.41,0.196
292.47,150.62,0.196
292.52,150.83,0.196
292.56,151.03,0.197
292.60,151.24,0.197
292.64,151.45,0.197
292.68,151.66,0.198
292.72,151.87,0.198
292.77,152.08,0.198
292.81,152.29,0.198
292.85,152.49,0.198
292.89,152.70,0.198
292.93,152.91,0.199
292.97,153.12,0.199
293.02,153.33,0.199
293.06,153.54,0.199
293.10,153.74,0.199
293.14,153.95,0.200
293.18,154.16,0.200
293.22,154.37,0.200
293.27,154.58,0.200
293.31,154.78,0.200
293.35,154.99,0.201
293.39,155.20,0.201
293.43,155.41,0.201
293.47,155.62,0.201
293.52,155.83,0.201
293.56,156.03,0.201
293.60,156.24,0.202
293.64,156.45,0.202
293.68,156.66,0.202
293.72,156.87,0.202
293.77,157.08,0.202
293.81,157.29,0.203
293.85,157.49,0.203
293.89,157.70,0.203
293.93,157.91,0.203
293.97,158.12,0.203
294.02,158.33,0.203
294.06,158.54,0.204
294.10,158.74,0.204
294.14,158.95,0.204
294.18,159.16,0.204
294.22,159.37,0.204
294.27,159.58,0.205
294.31,159.78,0.205
294.35,159.99,0.205
294.39,160.20,0.205
294.43,160.41,0.205
294.47,160.62,0.206
294.52,160.83,0.206
294.56,161.04,0.206
294.60,161.24,0.206
294.64,161.45,0.207
294.68,161.66,0.207
294.72,161.87,0.207
294.77,162.08,0.207
294.81,162.28,0.207
294.85,162.49,0.207
294.89,162.70,0.207
294.93,162.91,0.208
294.97,163.12,0.208
295.02,163.33,0.208
295.06,163.53,0.208
295.10,163.74,0.209
295.14,163.95,0.209
295.18,164.16,0.209
295.22,164.37,0.209
295.27,164.58,0.210
295.31,164.79,0.210
295.35,164.99,0.210
295.39,165.20,0.210
295.43,165.41,0.210
295.47,165.62,0.210
295.52,165.83,0.211
295.56,166.04,0.211
295.60,166.24,0.211
295.64,166.45,0.211
295.68,166.66,0.211
295.72,166.87,0.211
295.77,167.08,0.211
295.81,167.29,0.211
295.85,167.49,0.211
295.89,167.70,0.211
295.93,167.91,0.211
295.97,168.12,0.211
296.02,168.33,0.211
296.06,168.54,0.211
296.10,168.74,0.211
296.14,168.95,0.211
296.18,169.16,0.211
296.22,169.37,0.212
296.27,169.58,0.212
296.31,169.79,0.212
296.35,170.00,0.212
296.39,170.20,0.212
296.43,170.41,0.212
296.47,170.62,0.211
296.52,170.83,0.211
296.56,171.04,0.211
296.60,171.25,0.211
296.64,171.46,0.211
296.68,171.66,0.210
296.72,171.87,0.210
296.77,172.08,0.210
296.81,172.29,0.210
296.85,172.50,0.209
296.89,172.70,0.209
296.93,172.91,0.209
296.97,173.12,0.208
297.02,173.33,0.208
297.06,173.54,0.208
297.10,173.75,0.207
297.14,173.96,0.207
297.18,174.16,0.207
297.22,174.37,0.207
297.27,174.58,0.207
297.31,174.79,0.206
297.35,175.00,0.206
297.39,175.21,0.206
297.43,175.42,0.205
297.47,175.62,0.205
297.52,175.83,0.205
297.56,176.04,0.204
297.60,176.25,0.204
297.64,176.46,0.203
297.68,176.67,0.203
297.72,176.88,0.202
297.77,177.08,0.202
297.81,177.29,0.202
297.85,177.50,0.201
297.89,177.71,0.201
297.93,177.92,0.200
297.97,178.13,0.200
298.02,178.34,0.199
298.06,178.54,0.199
298.10,178.75,0.198
298.14,178.96,0.198
298.18,179.17,0.197
298.22,179.38,0.197
298.27,179.59,0.197
298.31,179.79,0.196
298.35,180.00,0.196
298.39,180.21,0.195
298.43,180.42,0.195
298.47,180.63,0.194
298.52,180.84,0.194
298.56,181.05,0.193
298.60,181.25,0.193
298.64,181.46,0.192
298.68,181.67,0.192
298.72,181.88,0.191
298.77,182.09,0.191
298.81,182.30,0.191
298.85,182.51,0.190
298.89,182.71,0.189
298.93,182.92,0.189
298.97,183.13,0.188
299.02,183.34,0.188
299.06,183.55,0.187
299.10,183.76,0.187
299.14,183.96,0.187
299.18,184.17,0.186
299.22,184.38,0.186
299.27,184.59,0.186
299.31,184.80,0.186
299.35,185.01,0.185
299.39,185.21,0.185
299.43,185.42,0.185
299.47,185.63,0.185
299.52,185.84,0.185
299.56,186.05,0.184
299.60,186.26,0.184
299.64,186.47,0.184
299.68,186.67,0.184
299.72,186.88,0.184
299.77,187.09,0.184
299.81,187.30,0.184
299.85,187.51,0.184
299.89,187.72,0.184
299.93,187.92,0.184
299.97,188.13,0.184
300.02,188.34,0.184
300.06,188.55,0.184
300.10,188.76,0.184
300.14,188.97,0.184
300.18,189.17,0.184
300.22,189.38,0.184
300.27,189.59,0.184
300.31,189.80,0.184
300.35,190.01,0.184
300.39,190.22,0.184
300.43,190.42,0.185
300.47,190.63,0.185
300.52,190.84,0.185
300.56,191.05,0.185
300.60,191.26,0.185
300.64,191.47,0.185
300.68,191.68,0.185
300.72,191.89,0.185
300.77,192.09,0.185
300.81,192.30,0.185
300.85,192.51,0.185
300.89,192.72,0.185
300.93,192.93,0.185
300.97,193.14,0.185
301.02,193.34,0.185
301.06,193.55,0.185
301.10,193.76,0.185
301.14,193.97,0.185
301.18,194.18,0.185
301.22,194.38,0.185
301.27,194.59,0.185
301.31,194.80,0.185
301.35,195.01,0.185
301.39,195.22,0.185
301.43,195.43,0.186
301.47,195.63,0.186
301.52,195.84,0.186
301.56,196.05,0.186
301.60,196.26,0.186
301.64,196.47,0.186
301.68,196.68,0.186
301.72,196.88,0.186
301.77,197.09,0.186
301.81,197.30,0.186
301.85,197.51,0.186
301.89,197.72,0.186
301.93,197.93,0.186
301.97,198.13,0.186
302.02,198.34,0.187
302.06,198.55,0.187
302.10,198.76,0.187
302.14,198.97,0.187
302.18,199.18,0.187
302.22,199.38,0.187
302.27,199.59,0.187
302.31,199.80,0.187
302.35,200.01,0.187
302.39,200.22,0.187
302.43,200.43,0.187
302.47,200.63,0.187
302.52,200.84,0.187
302.56,201.05,0.187
302.60,201.26,0.187
302.64,201.47,0.187
302.68,201.68,0.187
302.72,201.88,0.187
302.77,202.09,0.187
302.81,202.30,0.187
302.85,202.51,0.187
302.89,202.72,0.187
302.93,202.93,0.187
302.97,203.14,0.187
303.02,203.34,0.187
303.06,203.55,0.187
303.10,203.76,0.187
303.14,203.97,0.187
303.18,204.18,0.187
303.22,204.39,0.187
303.27,204.59,0.188
303.31,204.80,0.188
303.35,205.01,0.188
303.39,205.22,0.188
303.43,205.42,0.188
303.47,205.63,0.188
303.52,205.84,0.188
303.56,206.05,0.188
303.60,206.26,0.188
303.64,206.47,0.188
303.68,206.68,0.188
303.72,206.89,0.188
303.77,207.09,0.188
303.81,207.30,0.188
303.85,207.51,0.188
303.89,207.72,0.188
303.93,207.93,0.188
303.97,208.14,0.188
304.02,208.34,0.188
304.06,208.55,0.188
304.10,208.76,0.188
304.14,208.97,0.189
304.18,209.18,0.189
304.22,209.39,0.189
304.27,209.59,0.189
304.31,209.80,0.189
304.35,210.01,0.189
304.39,210.22,0.189
304.43,210.43,0.189
304.47,210.63,0.189
304.52,210.84,0.189
304.56,211.05,0.189
304.60,211.26,0.189
304.64,211.47,0.189
304.68,211.68,0.189
304.72,211.88,0.190
304.77,212.09,0.190
304.81,212.30,0.190
304.85,212.51,0.190
304.89,212.72,0.190
304.93,212.93,0.190
304.97,213.14,0.190
305.02,213.34,0.190
305.06,213.55,0.190
305.10,213.76,0.190
305.14,213.97,0.190
305.18,214.18,0.190
305.22,214.39,0.190
305.27,214.59,0.190
305.31,214.80,0.190
305.35,215.01,0.190
305.39,215.22,0.190
305.43,215.43,0.190
305.47,215.63,0.190
305.52,215.84,0.190
305.56,216.05,0.190
305.60,216.26,0.190
305.64,216.47,0.190
305.68,216.68,0.191
305.72,216.89,0.191
305.77,217.09,0.191
305.81,217.30,0.191
305.85,217.51,0.191
305.89,217.72,0.191
305.93,217.93,0.191
305.97,218.14,0.191
306.02,218.34,0.191
306.06,218.55,0.191
306.10,218.76,0.191
306.14,218.97,0.191
306.18,219.18,0.191
306.22,219.38,0.191
306.27,219.59,0.191
306.31,219.80,0.191
306.35,220.01,0.191
306.39,220.22,0.191
306.43,220.43,0.191
306.47,220.64,0.191
306.52,220.84,0.191
306.56,221.05,0.192
306.60,221.26,0.192
306.64,221.47,0.192
306.68,221.68,0.192
306.72,221.89,0.192
306.77,222.09,0.192
306.81,222.30,0.192
306.85,222.51,0.192
306.89,222.72,0.192
306.93,222.93,0.192
306.97,223.13,0.192
307.02,223.34,0.192
307.06,223.55,0.192
307.10,223.76,0.192
307.14,223.97,0.192
307.18,224.18,0.192
307.22,224.38,0.192
307.27,224.59,0.192
307.31,224.80,0.192
307.35,225.01,0.192
307.39,225.22,0.193
307.43,225.43,0.193
307.47,225.64,0.193
307.52,225.84,0.193
307.56,226.05,0.193
307.60,226.26,0.193
307.64,226.47,0.193
307.68,226.68,0.193
307.72,226.89,0.193
307.77,227.09,0.193
307.81,227.30,0.193
307.85,227.51,0.193
307.89,227.72,0.193
307.93,227.93,0.193
307.97,228.14,0.193
308.02,228.34,0.193
308.06,228.55,0.193
308.10,228.76,0.193
308.14,228.97,0.193
308.18,229.18,0.193
308.22,229.38,0.193
308.27,229.59,0.193
308.31,229.80,0.193
308.35,230.01,0.193
308.39,230.22,0.193
308.43,230.43,0.194
308.47,230.64,0.194
308.52,230.84,0.194
308.56,231.05,0.194
308.60,231.26,0.194
308.64,231.47,0.194
308.68,231.68,0.194
308.72,231.89,0.194
308.77,232.09,0.194
308.81,232.30,0.194
308.85,232.51,0.194
308.89,232.72,0.194
308.93,232.93,0.194
308.97,233.14,0.194
309.02,233.34,0.194
309.06,233.55,0.194
309.10,233.76,0.194
309.14,233.97,0.194
309.18,234.18,0.194
309.22,234.39,0.194
309.27,234.59,0.194
309.31,234.80,0.194
309.35,235.01,0.194
309.39,235.22,0.194
309.43,235.43,0.195
309.47,235.63,0.195
309.52,235.84,0.195
309.56,236.05,0.195
309.60,236.26,0.195
309.64,236.47,0.195
309.68,236.68,0.195
309.72,236.89,0.195
309.77,237.09,0.195
309.81,237.30,0.195
309.85,237.51,0.195
309.89,237.72,0.195
309.93,237.92,0.195
309.97,238.13,0.195
310.02,238.34,0.195
310.06,238.55,0.196
310.10,238.76,0.196
310.14,238.97,0.196
310.18,239.18,0.196
310.22,239.39,0.196
310.27,239.60,0.196
310.31,239.80,0.196
310.35,240.01,0.196
310.39,240.22,0.196
310.43,240.43,0.196
310.47,240.63,0.196
310.52,240.84,0.196
310.56,241.05,0.196
310.60,241.26,0.196
310.64,241.47,0.196
310.68,241.68,0.196
310.72,241.88,0.196
310.77,242.09,0.196
310.81,242.30,0.196
310.85,242.51,0.197
310.89,242.72,0.197
310.93,242.93,0.197
310.97,243.13,0.197
311.02,243.34,0.197
311.06,243.55,0.197
311.10,243.76,0.197
311.14,243.97,0.197
311.18,244.18,0.197
311.22,244.38,0.197
311.27,244.59,0.197
311.31,244.80,0.197
311.35,245.01,0.197
311.39,245.22,0.197
311.43,245.42,0.197
311.47,245.63,0.197
311.52,245.84,0.198
311.56,246.05,0.198
311.60,246.26,0.198
311.64,246.47,0.198
311.68,246.68,0.198
311.72,246.88,0.198
311.77,247.09,0.198
311.81,247.30,0.198
311.85,247.51,0.198
311.89,247.72,0.198
311.93,247.93,0.198
311.97,248.13,0.199
312.02,248.34,0.199
312.06,248.55,0.199
312.10,248.76,0.199
312.14,248.97,0.199
312.18,249.17,
312.22,,