File: DSC/2025_04_21_CBN_Creatinine_MC_n60C_150C_5Cmin_x3.csv
Filename,2025_04_21_CBN_Creatinine_MC_n60C_150C_5Cmin_x3
Instrument name,DSC2A-00468 (192.168.1.100)
Operator,Yarger
rundate,4/21/2025
Sample name,2025_04_21_CBN_Creatinine_MC_n60C_150C_5Cmin_x3
proceduresegments,Data Off ; Equilibrate -60.00 °C; Data On ; Ramp 5.00 °C/min to 150.00 °C; Data Off ; Isothermal 1.0 min; Data On ; Ramp 10.00 °C/min to -60.00 °C; Data Off ; Isothermal 1.0 min; Data On ; Ramp 5.00 °C/min to 150.00 °C; Data Off ; Isothermal 1.0 min; Data On ; Ramp 10.00 °C/min to -60.00 °C; Data Off ; Isothermal 1.0 min; Data On ; Ramp 5.00 °C/min to 150.00 °C
[File Parameters]
Run date,4/21/2025 7:47:55 PM
Trios version,5.1.1.46572
Original File Name,
Current File Name,D:\DSC2500\JYarger\2025_04_21_CBN_Creatinine_MC_n60C_150C_5Cmin_x3.tri
[Procedure]
Procedure Name,CBN_Creatinine_n60_150C_5Cmin_x3
Sample Name,2025_04_21_CBN_Creatinine_MC_n60C_150C_5Cmin_x3
Sample Mass,5.18 mg
Reference Sample Mass,0 mg
Pan Mass,52.34 mg
Pan Number,10
Reference Pan Mass,52.66 mg
Reference Pan Number,19
Pan Type,Tzero Aluminum Hermetic
Comments,Al Hermetic DSC Consumables sealed Pan/Lid.
Project Name,CA
Operator,Yarger
Test,Custom
Unload Max Temperature,30
Unload Min Temperature,30
Load Max Temperature,30
Load Min Temperature,30
Stop on Gas Flow Error,Yes
[Signal List]
Signal #1,Time (min)
Signal #2,Temperature (°C)
Signal #3,Heat Flow (mW)
Signal #4,Delta T (µV)
Signal #5,Delta Tzero (µV)
Signal #6,Tzero Temperature (°C)
Signal #7,Cell Purge (mL/min)
Signal #8,Heater Temp (°C)
Signal #9,Power Delivered (W)
Signal #10,Reference Junction Temperature (°C)
Signal #11,Flange Temperature (°C)
Signal #12,Heat Flow Phase (rad)
Signal #13,Total Heat Capacity (J/°C)
Signal #14,Heat Capacity (J/°C)
[Configuration]
Company Name,ASU
Instrument Name,DSC2A-00468
Instrument Type,DSC2500
Serial Number,DSC2A-00468
IP,192.168.1.100
Location of Instrument,MRRC
DisplayType,Unknown
Sample Interval ,0.1 s/pt
Selected Heat Flow,T4P
Exotherm Direction,Down
Cell Serial,DRC2-00792
Lid Type,Standard
Cooler,RCS 90
Leave Cooler on at End of Sequence,On
Gas 2,Nitrogen
Gas Selected,Channel 1
Flow Rate,50 mL/min
Secondary Purge,On
Licensed Heat Flow,Heat Flow T4P
Modulation Licensed,Yes
[Versions]
Common IDD Version,1
Cortex Version,VER 2.10.2.31
Driver,5.0.0.6
GDM Version,1.0.3.3
TouchscreenVersion,1.0.0.16145
FEP Version,1.2.1.21
FEP Bootloader,2.0.0.5
AutoSampler Version,2.1.1.26
Auto Sampler Bootloader,2.0.0.5
FCM Version,1.1.0.3
FCM Bootloader,2.0.0.5
[Experiment Logs]
Experiment Log Entry # 1,Air Cool is off.
Experiment Log Entry # 3,Data On set to 0
Experiment Log Entry # 5,Equilibrate Segment -60 (C) Started
Experiment Log Entry # 7,Data On set to 1
Experiment Log Entry # 9,Ramp Segment 5 C/min to 150 Started
Experiment Log Entry # 11,Data On set to 0
Experiment Log Entry # 13,Isothermal Segment 1 min started
Experiment Log Entry # 15,Data On set to 1
Experiment Log Entry # 17,Ramp Segment 10 C/min to -60 Started
Experiment Log Entry # 19,Data On set to 0
Experiment Log Entry # 21,Isothermal Segment 1 min started
Experiment Log Entry # 23,Data On set to 1
Experiment Log Entry # 25,Ramp Segment 5 C/min to 150 Started
Experiment Log Entry # 27,Data On set to 0
Experiment Log Entry # 29,Isothermal Segment 1 min started
Experiment Log Entry # 31,Data On set to 1
Experiment Log Entry # 33,Ramp Segment 10 C/min to -60 Started
Experiment Log Entry # 35,Data On set to 0
Experiment Log Entry # 37,Isothermal Segment 1 min started
Experiment Log Entry # 39,Data On set to 1
Experiment Log Entry # 41,Ramp Segment 5 C/min to 150 Started
[Method Log]
Method Log Entry # 1,Data Off
Method Log Entry # 2,Equilibrate -60 °C
Method Log Entry # 3,Data On
Method Log Entry # 4,(Ramp 815667) Ramp 5 °C/minute to 150 °C
Method Log Entry # 5,Data Off
Method Log Entry # 6,Isothermal 1 minutes
Method Log Entry # 7,Data On
Method Log Entry # 8,(Ramp 815671) Ramp 10 °C/minute to -60 °C
Method Log Entry # 9,Data Off
Method Log Entry # 10,Isothermal 1 minutes
Method Log Entry # 11,Data On
Method Log Entry # 12,(Ramp 815675) Ramp 5 °C/minute to 150 °C
Method Log Entry # 13,Data Off
Method Log Entry # 14,Isothermal 1 minutes
Method Log Entry # 15,Data On
Method Log Entry # 16,(Ramp 815679) Ramp 10 °C/minute to -60 °C
Method Log Entry # 17,Data Off
Method Log Entry # 18,Isothermal 1 minutes
Method Log Entry # 19,Data On
Method Log Entry # 20,(Ramp 815683) Ramp 5 °C/minute to 150 °C
Cell Serial,DRC2-00792
[T1 Calibration]
Slope,-0.008529666
Offset,9.636258
Initial Temperature,98.23
GUID,f8bfdadc-4977-4fdf-ba6d-0ba9134940c3
[TZero Calibration]
Date Applied,11/29/2022 4:06:13 PM
Description,From -89.059 °C to 396.009 °C at 20.000°C/min
Gas Type,Nitrogen
Pan Type,None
Source Files 1,C:\Users\yargerlab\Desktop\DSC Data\General\TZero_calibration_11_29_22_2nd(2).tri
Source Files 2,C:\Users\yargerlab\Desktop\DSC Data\General\TZero_calibration_11_29_22_2nd(3).tri
Delta T Offset,13.05235
Delta T Slope,-0.007271007
Delta T0 Offset,-13.69128
Delta T0 Slope,0.06063341
[Temperature Calibration]
Date Applied,11/29/2022 7:12:28 PM
Description,From 106.590 °C to 186.590 °C at 10.000°C/min
Gas Type,Nitrogen
Pan Type,Tzero Aluminum Hermetic
Source Files 1,C:\Users\yargerlab\Desktop\DSC Data\General\Indium(6).tri
Measured 1,157.391
Known 1,156.598
[Cell Constant Calibration]
Date Applied,11/29/2022 7:12:29 PM
Description,From 106.590 °C to 186.590 °C at 10.000°C/min
Gas Type,Nitrogen
Pan Type,Tzero Aluminum Hermetic
Source Files 1,C:\Users\yargerlab\Desktop\DSC Data\General\Indium(6).tri
T4P KCell,1.006051
Onset Slope,63.26126 mW/°C
[Direct Cp Calibration]
Date Applied,11/30/2022 11:04:51 AM
Description,From -79.983 °C to 298.409 °C at 10.000°C/min
Gas Type,Nitrogen
Pan Type,Tzero Aluminum Hermetic
Source Files 1,C:\Users\yargerlab\Desktop\DSC Data\General\Sapphire_Heat_Capacity_11_30_22.tri
[Rev Cp Calibration]
Date Applied,11/30/2022 1:58:51 PM
Description,From -79.996 °C to 292.812 °C at 3.000°C/min
Gas Type,Nitrogen
Pan Type,Tzero Aluminum Hermetic
Source Files 1,C:\Users\yargerlab\Desktop\DSC Data\General\Sapphire_MDSC_Calibration_11_30_22.tri
[step]
Ramp 5.00 °C/min to 150.00 °C
Time,Temperature,Heat Flow (Normalized)
min,°C,W/g
0.00,-59.68,-0.069
0.03,-59.69,-0.068
0.06,-59.70,-0.058
0.08,-59.68,-0.053
0.11,-59.63,-0.044
0.14,-59.56,-0.027
0.17,-59.47,-0.008
0.20,-59.36,0.010
0.23,-59.25,0.026
0.26,-59.13,0.039
0.28,-59.01,0.050
0.31,-58.89,0.058
0.34,-58.76,0.064
0.37,-58.63,0.069
0.40,-58.50,0.072
0.43,-58.37,0.076
0.45,-58.23,0.079
0.48,-58.10,0.080
0.51,-57.96,0.082
0.54,-57.83,0.084
0.57,-57.69,0.085
0.60,-57.55,0.085
0.62,-57.42,0.086
0.65,-57.28,0.086
0.68,-57.14,0.087
0.71,-57.00,0.088
0.74,-56.86,0.088
0.77,-56.73,0.089
0.79,-56.59,0.089
0.82,-56.45,0.090
0.85,-56.31,0.090
0.88,-56.17,0.091
0.91,-56.03,0.091
0.93,-55.89,0.092
0.96,-55.75,0.092
0.99,-55.61,0.092
1.02,-55.47,0.093
1.05,-55.33,0.093
1.08,-55.19,0.093
1.11,-55.05,0.093
1.13,-54.91,0.094
1.16,-54.77,0.094
1.19,-54.63,0.094
1.22,-54.49,0.094
1.25,-54.35,0.095
1.28,-54.21,0.095
1.30,-54.07,0.095
1.33,-53.93,0.095
1.36,-53.79,0.095
1.39,-53.64,0.095
1.42,-53.50,0.095
1.44,-53.36,0.095
1.47,-53.22,0.095
1.50,-53.08,0.096
1.53,-52.94,0.096
1.56,-52.80,0.096
1.59,-52.66,0.096
1.62,-52.52,0.096
1.64,-52.38,0.096
1.67,-52.24,0.096
1.70,-52.09,0.096
1.73,-51.95,0.096
1.76,-51.81,0.096
1.78,-51.67,0.096
1.81,-51.53,0.096
1.84,-51.39,0.096
1.87,-51.24,0.096
1.90,-51.10,0.096
1.93,-50.96,0.096
1.96,-50.82,0.096
1.98,-50.68,0.096
2.01,-50.54,0.096
2.04,-50.40,0.096
2.07,-50.26,0.096
2.10,-50.11,0.097
2.13,-49.97,0.097
2.15,-49.83,0.097
2.18,-49.69,0.097
2.21,-49.55,0.097
2.24,-49.41,0.097
2.27,-49.27,0.097
2.29,-49.12,0.097
2.32,-48.98,0.097
2.35,-48.84,0.097
2.38,-48.70,0.097
2.41,-48.56,0.097
2.44,-48.42,0.097
2.46,-48.27,0.097
2.49,-48.13,0.097
2.52,-47.99,0.097
2.55,-47.85,0.097
2.58,-47.71,0.097
2.61,-47.57,0.097
2.64,-47.43,0.097
2.66,-47.29,0.097
2.69,-47.14,0.097
2.72,-47.00,0.097
2.75,-46.86,0.097
2.78,-46.72,0.097
2.81,-46.58,0.097
2.83,-46.44,0.097
2.86,-46.30,0.097
2.89,-46.15,0.097
2.92,-46.01,0.097
2.95,-45.87,0.097
2.98,-45.73,0.097
3.00,-45.59,0.097
3.03,-45.45,0.097
3.06,-45.30,0.097
3.09,-45.16,0.097
3.12,-45.02,0.097
3.14,-44.88,0.097
3.17,-44.74,0.097
3.20,-44.60,0.097
3.23,-44.45,0.097
3.26,-44.31,0.097
3.29,-44.17,0.097
3.31,-44.03,0.097
3.34,-43.89,0.097
3.37,-43.75,0.097
3.40,-43.60,0.097
3.43,-43.46,0.097
3.46,-43.32,0.097
3.49,-43.18,0.097
3.51,-43.04,0.097
3.54,-42.90,0.097
3.57,-42.75,0.097
3.60,-42.61,0.097
3.63,-42.47,0.097
3.66,-42.33,0.097
3.68,-42.19,0.097
3.71,-42.04,0.097
3.74,-41.90,0.097
3.77,-41.76,0.097
3.80,-41.62,0.097
3.83,-41.48,0.097
3.85,-41.34,0.097
3.88,-41.20,0.097
3.91,-41.05,0.097
3.94,-40.91,0.097
3.97,-40.77,0.097
3.99,-40.63,0.097
4.02,-40.49,0.097
4.05,-40.34,0.097
4.08,-40.20,0.098
4.11,-40.06,0.098
4.14,-39.92,0.098
4.16,-39.78,0.098
4.19,-39.64,0.098
4.22,-39.49,0.098
4.25,-39.35,0.098
4.28,-39.21,0.098
4.31,-39.07,0.098
4.34,-38.92,0.098
4.36,-38.78,0.098
4.39,-38.64,0.098
4.42,-38.50,0.098
4.45,-38.36,0.098
4.48,-38.22,0.098
4.50,-38.07,0.098
4.53,-37.93,0.098
4.56,-37.79,0.098
4.59,-37.65,0.098
4.62,-37.51,0.098
4.65,-37.36,0.098
4.68,-37.22,0.098
4.70,-37.08,0.098
4.73,-36.94,0.098
4.76,-36.80,0.098
4.79,-36.66,0.098
4.82,-36.52,0.098
4.85,-36.38,0.098
4.87,-36.23,0.098
4.90,-36.09,0.098
4.93,-35.95,0.098
4.96,-35.81,0.098
4.99,-35.67,0.098
5.01,-35.53,0.098
5.04,-35.38,0.098
5.07,-35.24,0.098
5.10,-35.10,0.098
5.13,-34.96,0.098
5.16,-34.82,0.098
5.19,-34.68,0.099
5.21,-34.53,0.099
5.24,-34.39,0.099
5.27,-34.25,0.099
5.30,-34.11,0.099
5.33,-33.96,0.099
5.35,-33.82,0.099
5.38,-33.68,0.099
5.41,-33.54,0.099
5.44,-33.40,0.099
5.47,-33.25,0.099
5.50,-33.11,0.099
5.53,-32.97,0.099
5.55,-32.83,0.099
5.58,-32.68,0.100
5.61,-32.54,0.100
5.64,-32.40,0.100
5.67,-32.26,0.100
5.70,-32.12,0.100
5.72,-31.98,0.100
5.75,-31.83,0.100
5.78,-31.69,0.100
5.81,-31.55,0.101
5.84,-31.41,0.101
5.86,-31.27,0.101
5.89,-31.13,0.101
5.92,-30.98,0.101
5.95,-30.84,0.101
5.98,-30.70,0.101
6.01,-30.56,0.101
6.04,-30.42,0.101
6.06,-30.27,0.101
6.09,-30.13,0.101
6.12,-29.99,0.101
6.15,-29.85,0.101
6.18,-29.71,0.100
6.20,-29.56,0.100
6.23,-29.42,0.100
6.26,-29.28,0.100
6.29,-29.14,0.100
6.32,-29.00,0.100
6.35,-28.86,0.100
6.38,-28.71,0.100
6.40,-28.57,0.100
6.43,-28.43,0.100
6.46,-28.29,0.100
6.49,-28.15,0.100
6.52,-28.01,0.100
6.55,-27.86,0.100
6.57,-27.72,0.100
6.60,-27.58,0.100
6.63,-27.44,0.100
6.66,-27.30,0.100
6.69,-27.16,0.100
6.71,-27.01,0.100
6.74,-26.87,0.101
6.77,-26.73,0.101
6.80,-26.59,0.101
6.83,-26.45,0.101
6.86,-26.30,0.101
6.89,-26.16,0.101
6.91,-26.02,0.101
6.94,-25.88,0.101
6.97,-25.74,0.101
7.00,-25.60,0.101
7.03,-25.45,0.101
7.05,-25.31,0.101
7.08,-25.17,0.101
7.11,-25.03,0.101
7.14,-24.89,0.101
7.17,-24.74,0.101
7.20,-24.60,0.101
7.23,-24.46,0.101
7.25,-24.32,0.101
7.28,-24.18,0.101
7.31,-24.04,0.101
7.34,-23.89,0.101
7.37,-23.75,0.101
7.40,-23.61,0.101
7.42,-23.47,0.101
7.45,-23.33,0.101
7.48,-23.18,0.101
7.51,-23.04,0.102
7.54,-22.90,0.102
7.56,-22.76,0.102
7.59,-22.62,0.102
7.62,-22.48,0.102
7.65,-22.33,0.102
7.68,-22.19,0.102
7.71,-22.05,0.102
7.74,-21.91,0.102
7.76,-21.77,0.102
7.79,-21.63,0.102
7.82,-21.48,0.102
7.85,-21.34,0.102
7.88,-21.20,0.102
7.90,-21.06,0.102
7.93,-20.92,0.102
7.96,-20.77,0.102
7.99,-20.63,0.102
8.02,-20.49,0.102
8.05,-20.35,0.102
8.08,-20.21,0.102
8.10,-20.07,0.102
8.13,-19.92,0.102
8.16,-19.78,0.103
8.19,-19.64,0.103
8.22,-19.50,0.103
8.25,-19.36,0.103
8.27,-19.22,0.103
8.30,-19.07,0.103
8.33,-18.93,0.103
8.36,-18.79,0.103
8.39,-18.65,0.103
8.41,-18.51,0.103
8.44,-18.36,0.103
8.47,-18.22,0.103
8.50,-18.08,0.103
8.53,-17.94,0.103
8.56,-17.80,0.103
8.58,-17.66,0.103
8.61,-17.51,0.103
8.64,-17.37,0.103
8.67,-17.23,0.103
8.70,-17.09,0.103
8.73,-16.95,0.103
8.75,-16.80,0.104
8.78,-16.66,0.104
8.81,-16.52,0.104
8.84,-16.38,0.104
8.87,-16.24,0.104
8.90,-16.10,0.104
8.93,-15.95,0.104
8.95,-15.81,0.104
8.98,-15.67,0.104
9.01,-15.53,0.104
9.04,-15.39,0.104
9.07,-15.24,0.104
9.10,-15.10,0.104
9.12,-14.96,0.104
9.15,-14.82,0.104
9.18,-14.67,0.104
9.21,-14.53,0.105
9.24,-14.39,0.105
9.27,-14.25,0.105
9.29,-14.11,0.105
9.32,-13.97,0.105
9.35,-13.82,0.105
9.38,-13.68,0.105
9.41,-13.54,0.105
9.43,-13.40,0.105
9.46,-13.26,0.105
9.49,-13.12,0.105
9.52,-12.97,0.105
9.55,-12.83,0.105
9.58,-12.69,0.105
9.60,-12.55,0.105
9.63,-12.41,0.105
9.66,-12.27,0.105
9.69,-12.12,0.105
9.72,-11.98,0.105
9.75,-11.84,0.105
9.78,-11.70,0.105
9.80,-11.56,0.105
9.83,-11.42,0.105
9.86,-11.28,0.105
9.89,-11.14,0.105
9.92,-10.99,0.105
9.95,-10.85,0.105
9.97,-10.71,0.105
10.00,-10.57,0.105
10.03,-10.43,0.105
10.06,-10.28,0.106
10.09,-10.14,0.106
10.12,-10.00,0.106
10.14,-9.86,0.106
10.17,-9.72,0.106
10.20,-9.58,0.106
10.23,-9.43,0.106
10.26,-9.29,0.106
10.28,-9.15,0.106
10.31,-9.01,0.106
10.34,-8.87,0.106
10.37,-8.72,0.106
10.40,-8.58,0.106
10.43,-8.44,0.106
10.45,-8.30,0.107
10.48,-8.16,0.107
10.51,-8.02,0.107
10.54,-7.87,0.107
10.57,-7.73,0.107
10.60,-7.59,0.107
10.63,-7.45,0.107
10.65,-7.31,0.107
10.68,-7.16,0.107
10.71,-7.02,0.107
10.74,-6.88,0.107
10.77,-6.74,0.107
10.80,-6.60,0.107
10.82,-6.46,0.107
10.85,-6.32,0.107
10.88,-6.17,0.107
10.91,-6.03,0.107
10.94,-5.89,0.107
10.97,-5.75,0.108
10.99,-5.61,0.108
11.02,-5.46,0.108
11.05,-5.32,0.108
11.08,-5.18,0.108
11.11,-5.04,0.108
11.13,-4.90,0.108
11.16,-4.75,0.108
11.19,-4.61,0.108
11.22,-4.47,0.108
11.25,-4.33,0.108
11.28,-4.19,0.108
11.30,-4.05,0.108
11.33,-3.90,0.108
11.36,-3.76,0.108
11.39,-3.62,0.108
11.42,-3.48,0.108
11.45,-3.34,0.108
11.48,-3.19,0.108
11.50,-3.05,0.109
11.53,-2.91,0.109
11.56,-2.77,0.109
11.59,-2.63,0.109
11.62,-2.49,0.109
11.65,-2.34,0.109
11.67,-2.20,0.109
11.70,-2.06,0.109
11.73,-1.92,0.109
11.76,-1.78,0.109
11.79,-1.63,0.109
11.82,-1.49,0.109
11.84,-1.35,0.109
11.87,-1.21,0.109
11.90,-1.07,0.109
11.93,-0.93,0.109
11.96,-0.78,0.109
11.98,-0.64,0.109
12.01,-0.50,0.109
12.04,-0.36,0.109
12.07,-0.22,0.110
12.10,-0.08,0.110
12.13,0.07,0.110
12.15,0.21,0.110
12.18,0.35,0.110
12.21,0.49,0.110
12.24,0.63,0.110
12.27,0.77,0.110
12.30,0.92,0.110
12.33,1.06,0.110
12.35,1.20,0.110
12.38,1.34,0.110
12.41,1.48,0.110
12.44,1.63,0.110
12.47,1.77,0.110
12.50,1.91,0.110
12.52,2.05,0.110
12.55,2.19,0.111
12.58,2.33,0.111
12.61,2.48,0.111
12.64,2.62,0.111
12.67,2.76,0.111
12.69,2.90,0.111
12.72,3.04,0.111
12.75,3.18,0.111
12.78,3.33,0.111
12.81,3.47,0.111
12.83,3.61,0.111
12.86,3.75,0.111
12.89,3.89,0.111
12.92,4.03,0.111
12.95,4.18,0.111
12.98,4.32,0.111
13.00,4.46,0.111
13.03,4.60,0.111
13.06,4.74,0.111
13.09,4.89,0.111
13.12,5.03,0.112
13.15,5.17,0.112
13.18,5.31,0.112
13.20,5.45,0.112
13.23,5.59,0.112
13.26,5.73,0.112
13.29,5.88,0.112
13.32,6.02,0.112
13.35,6.16,0.112
13.37,6.30,0.112
13.40,6.44,0.112
13.43,6.58,0.112
13.46,6.73,0.112
13.49,6.87,0.113
13.52,7.01,0.113
13.54,7.15,0.113
13.57,7.30,0.113
13.60,7.44,0.113
13.63,7.58,0.113
13.66,7.72,0.113
13.68,7.86,0.113
13.71,8.00,0.113
13.74,8.15,0.113
13.77,8.29,0.113
13.80,8.43,0.113
13.83,8.57,0.113
13.85,8.71,0.113
13.88,8.85,0.113
13.91,9.00,0.113
13.94,9.14,0.114
13.97,9.28,0.114
14.00,9.42,0.114
14.03,9.56,0.114
14.05,9.71,0.114
14.08,9.85,0.114
14.11,9.99,0.114
14.14,10.13,0.114
14.17,10.27,0.114
14.20,10.41,0.114
14.22,10.56,0.114
14.25,10.70,0.114
14.28,10.84,0.114
14.31,10.98,0.114
14.34,11.12,0.115
14.37,11.26,0.115
14.39,11.41,0.115
14.42,11.55,0.115
14.45,11.69,0.115
14.48,11.83,0.115
14.51,11.97,0.115
14.53,12.11,0.115
14.56,12.26,0.115
14.59,12.40,0.115
14.62,12.54,0.115
14.65,12.68,0.115
14.68,12.82,0.115
14.70,12.97,0.115
14.73,13.11,0.115
14.76,13.25,0.115
14.79,13.39,0.116
14.82,13.53,0.116
14.85,13.67,0.116
14.88,13.82,0.116
14.90,13.96,0.116
14.93,14.10,0.116
14.96,14.24,0.116
14.99,14.38,0.116
15.02,14.52,0.116
15.05,14.67,0.116
15.07,14.81,0.116
15.10,14.95,0.116
15.13,15.09,0.116
15.16,15.23,0.116
15.19,15.38,0.116
15.22,15.52,0.116
15.24,15.66,0.116
15.27,15.80,0.116
15.30,15.94,0.116
15.33,16.08,0.116
15.36,16.23,0.117
15.38,16.37,0.117
15.41,16.51,0.117
15.44,16.65,0.117
15.47,16.79,0.117
15.50,16.94,0.117
15.53,17.07,0.117
15.55,17.22,0.117
15.58,17.36,0.117
15.61,17.50,0.118
15.64,17.64,0.118
15.67,17.78,0.118
15.70,17.93,0.118
15.73,18.07,0.118
15.75,18.21,0.118
15.78,18.35,0.118
15.81,18.49,0.118
15.84,18.64,0.118
15.87,18.78,0.118
15.90,18.92,0.118
15.92,19.06,0.118
15.95,19.20,0.118
15.98,19.34,0.118
16.01,19.48,0.118
16.04,19.63,0.118
16.07,19.77,0.118
16.09,19.91,0.119
16.12,20.05,0.119
16.15,20.19,0.119
16.18,20.34,0.119
16.21,20.48,0.119
16.23,20.62,0.119
16.26,20.76,0.119
16.29,20.90,0.119
16.32,21.04,0.119
16.35,21.19,0.119
16.38,21.33,0.119
16.40,21.47,0.119
16.43,21.61,0.119
16.46,21.75,0.120
16.49,21.89,0.120
16.52,22.04,0.120
16.55,22.18,0.120
16.58,22.32,0.120
16.60,22.46,0.120
16.63,22.60,0.120
16.66,22.75,0.120
16.69,22.89,0.120
16.72,23.03,0.120
16.75,23.17,0.120
16.77,23.31,0.120
16.80,23.45,0.120
16.83,23.60,0.120
16.86,23.74,0.121
16.89,23.88,0.121
16.92,24.02,0.121
16.94,24.16,0.121
16.97,24.30,0.121
17.00,24.45,0.121
17.03,24.59,0.121
17.06,24.73,0.121
17.08,24.87,0.121
17.11,25.01,0.121
17.14,25.15,0.121
17.17,25.30,0.122
17.20,25.44,0.122
17.23,25.58,0.122
17.26,25.72,0.122
17.28,25.86,0.122
17.31,26.00,0.122
17.34,26.15,0.122
17.37,26.29,0.122
17.40,26.43,0.122
17.43,26.57,0.122
17.45,26.71,0.122
17.48,26.86,0.123
17.51,27.00,0.123
17.54,27.14,0.123
17.57,27.28,0.123
17.59,27.42,0.123
17.62,27.57,0.123
17.65,27.71,0.123
17.68,27.85,0.123
17.71,27.99,0.123
17.74,28.13,0.123
17.77,28.27,0.123
17.79,28.42,0.123
17.82,28.56,0.123
17.85,28.70,0.123
17.88,28.84,0.124
17.91,28.98,0.124
17.93,29.12,0.124
17.96,29.27,0.124
17.99,29.41,0.124
18.02,29.55,0.124
18.05,29.69,0.124
18.08,29.83,0.124
18.11,29.97,0.124
18.13,30.12,0.124
18.16,30.26,0.124
18.19,30.40,0.124
18.22,30.54,0.124
18.25,30.68,0.124
18.28,30.82,0.125
18.30,30.97,0.125
18.33,31.11,0.125
18.36,31.25,0.125
18.39,31.39,0.125
18.42,31.53,0.125
18.44,31.68,0.125
18.47,31.82,0.125
18.50,31.96,0.125
18.53,32.10,0.125
18.56,32.24,0.125
18.59,32.39,0.125
18.62,32.53,0.125
18.64,32.67,0.125
18.67,32.81,0.126
18.70,32.95,0.126
18.73,33.09,0.126
18.76,33.23,0.126
18.78,33.38,0.126
18.81,33.52,0.126
18.84,33.66,0.126
18.87,33.80,0.126
18.90,33.94,0.126
18.93,34.09,0.126
18.96,34.23,0.126
18.98,34.37,0.126
19.01,34.51,0.126
19.04,34.65,0.126
19.07,34.80,0.127
19.10,34.94,0.127
19.13,35.08,0.127
19.15,35.22,0.127
19.18,35.36,0.127
19.21,35.50,0.127
19.24,35.65,0.127
19.27,35.79,0.127
19.29,35.93,0.127
19.32,36.07,0.127
19.35,36.21,0.127
19.38,36.35,0.127
19.41,36.50,0.127
19.44,36.64,0.127
19.47,36.78,0.127
19.49,36.92,0.127
19.52,37.06,0.128
19.55,37.20,0.128
19.58,37.35,0.128
19.61,37.49,0.128
19.63,37.63,0.128
19.66,37.77,0.128
19.69,37.91,0.128
19.72,38.05,0.128
19.75,38.20,0.128
19.78,38.34,0.128
19.81,38.48,0.128
19.83,38.62,0.128
19.86,38.76,0.128
19.89,38.91,0.128
19.92,39.05,0.129
19.95,39.19,0.129
19.98,39.33,0.129
20.00,39.47,0.129
20.03,39.61,0.129
20.06,39.76,0.129
20.09,39.90,0.129
20.12,40.04,0.129
20.14,40.18,0.129
20.17,40.32,0.129
20.20,40.46,0.129
20.23,40.61,0.129
20.26,40.75,0.130
20.29,40.89,0.130
20.32,41.03,0.130
20.34,41.17,0.130
20.37,41.31,0.130
20.40,41.46,0.130
20.43,41.60,0.130
20.46,41.74,0.130
20.48,41.88,0.130
20.51,42.02,0.130
20.54,42.16,0.130
20.57,42.31,0.130
20.60,42.45,0.130
20.63,42.59,0.131
20.66,42.73,0.131
20.68,42.87,0.131
20.71,43.01,0.131
20.74,43.16,0.131
20.77,43.30,0.131
20.80,43.44,0.131
20.83,43.58,0.131
20.85,43.72,0.131
20.88,43.87,0.131
20.91,44.01,0.132
20.94,44.15,0.132
20.97,44.29,0.132
20.99,44.43,0.132
21.02,44.57,0.132
21.05,44.72,0.132
21.08,44.86,0.132
21.11,45.00,0.132
21.14,45.14,0.132
21.17,45.28,0.132
21.19,45.42,0.132
21.22,45.57,0.132
21.25,45.71,0.132
21.28,45.85,0.133
21.31,45.99,0.133
21.33,46.13,0.133
21.36,46.27,0.133
21.39,46.42,0.133
21.42,46.56,0.133
21.45,46.70,0.133
21.48,46.84,0.133
21.51,46.98,0.133
21.53,47.13,0.133
21.56,47.27,0.133
21.59,47.41,0.133
21.62,47.55,0.133
21.65,47.69,0.134
21.68,47.83,0.134
21.70,47.98,0.134
21.73,48.12,0.134
21.76,48.26,0.134
21.79,48.40,0.134
21.82,48.54,0.134
21.84,48.68,0.134
21.87,48.83,0.134
21.90,48.97,0.134
21.93,49.11,0.134
21.96,49.25,0.134
21.99,49.39,0.134
22.02,49.53,0.134
22.04,49.68,0.135
22.07,49.82,0.135
22.10,49.96,0.135
22.13,50.10,0.135
22.16,50.24,0.135
22.18,50.39,0.135
22.21,50.53,0.135
22.24,50.67,0.135
22.27,50.81,0.135
22.30,50.95,0.135
22.33,51.10,0.135
22.36,51.24,0.135
22.38,51.38,0.136
22.41,51.52,0.136
22.44,51.66,0.136
22.47,51.80,0.136
22.50,51.94,0.136
22.53,52.09,0.136
22.55,52.23,0.136
22.58,52.37,0.136
22.61,52.51,0.136
22.64,52.65,0.136
22.67,52.79,0.136
22.69,52.94,0.136
22.72,53.08,0.136
22.75,53.22,0.136
22.78,53.36,0.137
22.81,53.50,0.137
22.84,53.65,0.137
22.87,53.79,0.137
22.89,53.93,0.137
22.92,54.07,0.137
22.95,54.21,0.137
22.98,54.35,0.137
23.01,54.50,0.137
23.03,54.64,0.137
23.06,54.78,0.137
23.09,54.92,0.137
23.12,55.06,0.137
23.15,55.20,0.138
23.18,55.35,0.138
23.21,55.49,0.138
23.23,55.63,0.138
23.26,55.77,0.138
23.29,55.91,0.138
23.32,56.06,0.138
23.35,56.20,0.138
23.38,56.34,0.138
23.40,56.48,0.138
23.43,56.62,0.138
23.46,56.76,0.138
23.49,56.91,0.139
23.52,57.05,0.139
23.54,57.19,0.139
23.57,57.33,0.139
23.60,57.47,0.139
23.63,57.61,0.139
23.66,57.75,0.139
23.69,57.90,0.139
23.72,58.04,0.139
23.74,58.18,0.139
23.77,58.32,0.139
23.80,58.47,0.139
23.83,58.61,0.140
23.86,58.75,0.140
23.88,58.89,0.140
23.91,59.03,0.140
23.94,59.17,0.140
23.97,59.32,0.140
24.00,59.46,0.140
24.03,59.60,0.140
24.06,59.74,0.141
24.08,59.88,0.141
24.11,60.02,0.141
24.14,60.16,0.141
24.17,60.31,0.141
24.20,60.45,0.141
24.23,60.59,0.141
24.25,60.73,0.141
24.28,60.87,0.142
24.31,61.02,0.142
24.34,61.16,0.142
24.37,61.30,0.142
24.39,61.44,0.142
24.42,61.58,0.142
24.45,61.72,0.143
24.48,61.87,0.143
24.51,62.01,0.143
24.54,62.15,0.143
24.57,62.29,0.143
24.59,62.43,0.143
24.62,62.57,0.144
24.65,62.72,0.144
24.68,62.86,0.144
24.71,63.00,0.144
24.73,63.14,0.144
24.76,63.28,0.145
24.79,63.43,0.145
24.82,63.57,0.145
24.85,63.71,0.145
24.88,63.85,0.145
24.91,63.99,0.146
24.93,64.13,0.146
24.96,64.27,0.146
24.99,64.42,0.146
25.02,64.56,0.147
25.05,64.70,0.147
25.08,64.84,0.147
25.10,64.98,0.147
25.13,65.12,0.148
25.16,65.27,0.148
25.19,65.41,0.148
25.22,65.55,0.149
25.24,65.69,0.149
25.27,65.83,0.150
25.30,65.97,0.150
25.33,66.12,0.150
25.36,66.26,0.151
25.39,66.40,0.151
25.42,66.54,0.152
25.44,66.68,0.152
25.47,66.82,0.153
25.50,66.97,0.153
25.53,67.11,0.154
25.56,67.25,0.154
25.58,67.39,0.155
25.61,67.53,0.155
25.64,67.67,0.156
25.67,67.81,0.157
25.70,67.96,0.158
25.73,68.10,0.158
25.76,68.24,0.160
25.78,68.38,0.161
25.81,68.52,0.162
25.84,68.66,0.164
25.87,68.80,0.165
25.90,68.95,0.166
25.93,69.09,0.167
25.95,69.23,0.169
25.98,69.37,0.171
26.01,69.51,0.173
26.04,69.65,0.175
26.07,69.79,0.178
26.09,69.93,0.181
26.12,70.07,0.184
26.15,70.21,0.188
26.18,70.35,0.190
26.21,70.50,0.195
26.24,70.64,0.199
26.27,70.78,0.203
26.29,70.92,0.208
26.32,71.06,0.212
26.35,71.20,0.218
26.38,71.34,0.224
26.41,71.48,0.230
26.43,71.62,0.237
26.46,71.76,0.245
26.49,71.90,0.252
26.52,72.04,0.260
26.55,72.17,0.269
26.58,72.31,0.280
26.61,72.45,0.290
26.63,72.59,0.301
26.66,72.73,0.313
26.69,72.86,0.328
26.72,73.00,0.344
26.75,73.14,0.358
26.78,73.27,0.374
26.80,73.41,0.392
26.83,73.55,0.411
26.86,73.68,0.433
26.89,73.82,0.455
26.92,73.95,0.479
26.94,74.08,0.507
26.97,74.22,0.539
27.00,74.35,0.571
27.03,74.48,0.610
27.06,74.61,0.654
27.09,74.73,0.700
27.12,74.86,0.753
27.14,74.98,0.812
27.17,75.11,0.878
27.20,75.23,0.960
27.23,75.34,1.055
27.26,75.45,1.156
27.28,75.55,1.431
27.31,75.63,1.549
27.34,75.73,1.603
27.37,75.84,1.640
27.40,75.96,1.685
27.43,76.08,1.708
27.46,76.21,1.697
27.48,76.36,1.643
27.51,76.51,1.547
27.54,76.68,1.411
27.57,76.86,1.252
27.60,77.05,1.077
27.63,77.24,0.897
27.65,77.44,0.748
27.68,77.64,0.623
27.71,77.82,0.513
27.74,78.01,0.429
27.77,78.18,0.357
27.79,78.35,0.304
27.82,78.52,0.266
27.85,78.68,0.238
27.88,78.83,0.218
27.91,78.98,0.202
27.94,79.13,0.191
27.97,79.28,0.184
27.99,79.43,0.178
28.02,79.57,0.176
28.05,79.71,0.172
28.08,79.86,0.170
28.11,80.00,0.169
28.13,80.14,0.168
28.16,80.29,0.168
28.19,80.43,0.167
28.22,80.57,0.167
28.25,80.71,0.166
28.28,80.85,0.166
28.31,80.99,0.166
28.33,81.14,0.166
28.36,81.28,0.165
28.39,81.42,0.165
28.42,81.56,0.165
28.45,81.70,0.165
28.48,81.85,0.164
28.50,81.99,0.164
28.53,82.13,0.164
28.56,82.27,0.164
28.59,82.41,0.164
28.62,82.55,0.164
28.64,82.70,0.164
28.67,82.84,0.164
28.70,82.98,0.164
28.73,83.12,0.164
28.76,83.26,0.164
28.79,83.40,0.164
28.82,83.55,0.164
28.84,83.69,0.164
28.87,83.83,0.164
28.90,83.97,0.164
28.93,84.11,0.164
28.96,84.26,0.164
28.98,84.40,0.164
29.01,84.54,0.164
29.04,84.68,0.164
29.07,84.82,0.164
29.10,84.96,0.164
29.13,85.11,0.164
29.16,85.25,0.165
29.18,85.39,0.165
29.21,85.53,0.165
29.24,85.67,0.165
29.27,85.81,0.165
29.30,85.96,0.165
29.33,86.10,0.165
29.35,86.24,0.165
29.38,86.38,0.165
29.41,86.52,0.165
29.44,86.66,0.165
29.47,86.81,0.165
29.49,86.95,0.165
29.52,87.09,0.165
29.55,87.23,0.165
29.58,87.37,0.166
29.61,87.52,0.166
29.64,87.66,0.166
29.67,87.80,0.166
29.69,87.94,0.166
29.72,88.08,0.166
29.75,88.22,0.166
29.78,88.37,0.166
29.81,88.51,0.166
29.83,88.65,0.166
29.86,88.79,0.166
29.89,88.93,0.167
29.92,89.08,0.167
29.95,89.22,0.167
29.98,89.36,0.167
30.01,89.50,0.167
30.03,89.64,0.167
30.06,89.78,0.167
30.09,89.92,0.167
30.12,90.07,0.167
30.15,90.21,0.167
30.18,90.35,0.167
30.20,90.49,0.167
30.23,90.63,0.167
30.26,90.78,0.167
30.29,90.92,0.167
30.32,91.06,0.168
30.34,91.20,0.168
30.37,91.34,0.168
30.40,91.48,0.168
30.43,91.62,0.168
30.46,91.77,0.168
30.49,91.91,0.168
30.52,92.05,0.168
30.54,92.19,0.168
30.57,92.33,0.168
30.60,92.47,0.168
30.63,92.62,0.168
30.66,92.76,0.168
30.68,92.90,0.168
30.71,93.04,0.169
30.74,93.18,0.169
30.77,93.32,0.169
30.80,93.47,0.169
30.83,93.61,0.169
30.86,93.75,0.169
30.88,93.89,0.169
30.91,94.03,0.169
30.94,94.18,0.169
30.97,94.32,0.169
31.00,94.46,0.169
31.03,94.60,0.169
31.05,94.74,0.169
31.08,94.89,0.169
31.11,95.03,0.170
31.14,95.17,0.170
31.17,95.31,0.170
31.19,95.45,0.170
31.22,95.59,0.170
31.25,95.73,0.170
31.28,95.88,0.170
31.31,96.02,0.170
31.34,96.16,0.170
31.37,96.30,0.170
31.39,96.44,0.170
31.42,96.59,0.170
31.45,96.73,0.170
31.48,96.87,0.170
31.51,97.01,0.170
31.53,97.15,0.170
31.56,97.29,0.171
31.59,97.44,0.171
31.62,97.58,0.171
31.65,97.72,0.171
31.68,97.86,0.171
31.71,98.00,0.171
31.73,98.14,0.171
31.76,98.29,0.171
31.79,98.43,0.171
31.82,98.57,0.171
31.85,98.71,0.171
31.88,98.85,0.171
31.90,98.99,0.171
31.93,99.14,0.171
31.96,99.28,0.171
31.99,99.42,0.171
32.02,99.56,0.171
32.04,99.70,0.172
32.07,99.84,0.172
32.10,99.99,0.172
32.13,100.13,0.172
32.16,100.27,0.172
32.19,100.41,0.172
32.22,100.55,0.172
32.24,100.70,0.172
32.27,100.84,0.172
32.30,100.98,0.172
32.33,101.12,0.172
32.36,101.26,0.172
32.38,101.40,0.172
32.41,101.55,0.172
32.44,101.69,0.172
32.47,101.83,0.172
32.50,101.97,0.172
32.53,102.11,0.172
32.56,102.25,0.172
32.58,102.40,0.172
32.61,102.54,0.173
32.64,102.68,0.173
32.67,102.82,0.173
32.70,102.96,0.173
32.73,103.10,0.173
32.75,103.24,0.173
32.78,103.39,0.173
32.81,103.53,0.173
32.84,103.67,0.173
32.87,103.81,0.173
32.89,103.95,0.173
32.92,104.10,0.173
32.95,104.24,0.173
32.98,104.38,0.173
33.01,104.52,0.173
33.04,104.66,0.173
33.07,104.80,0.173
33.09,104.95,0.173
33.12,105.09,0.173
33.15,105.23,0.173
33.18,105.37,0.173
33.21,105.51,0.173
33.23,105.66,0.173
33.26,105.80,0.173
33.29,105.94,0.173
33.32,106.08,0.173
33.35,106.22,0.173
33.38,106.36,0.173
33.41,106.51,0.173
33.43,106.65,0.174
33.46,106.79,0.174
33.49,106.93,0.174
33.52,107.07,0.174
33.55,107.21,0.174
33.58,107.35,0.174
33.60,107.50,0.174
33.63,107.64,0.174
33.66,107.78,0.174
33.69,107.92,0.174
33.72,108.06,0.174
33.74,108.21,0.174
33.77,108.35,0.174
33.80,108.49,0.174
33.83,108.63,0.174
33.86,108.78,0.174
33.89,108.92,0.174
33.92,109.06,0.174
33.94,109.20,0.175
33.97,109.35,0.175
34.00,109.49,0.175
34.03,109.63,0.175
34.06,109.77,0.175
34.08,109.91,0.174
34.11,110.05,0.174
34.14,110.20,0.174
34.17,110.34,0.174
34.20,110.48,0.174
34.23,110.62,0.174
34.26,110.76,0.174
34.28,110.90,0.174
34.31,111.04,0.174
34.34,111.19,0.174
34.37,111.33,0.174
34.40,111.47,0.174
34.43,111.61,0.174
34.45,111.75,0.174
34.48,111.89,0.174
34.51,112.03,0.174
34.54,112.18,0.174
34.57,112.32,0.174
34.59,112.46,0.174
34.62,112.60,0.174
34.65,112.74,0.174
34.68,112.88,0.174
34.71,113.03,0.174
34.74,113.17,0.174
34.76,113.31,0.174
34.79,113.45,0.174
34.82,113.59,0.174
34.85,113.73,0.174
34.88,113.88,0.174
34.91,114.02,0.174
34.94,114.16,0.174
34.96,114.30,0.174
34.99,114.44,0.174
35.02,114.59,0.174
35.05,114.73,0.174
35.08,114.87,0.174
35.11,115.01,0.174
35.13,115.15,0.174
35.16,115.29,0.174
35.19,115.43,0.174
35.22,115.58,0.174
35.25,115.72,0.174
35.28,115.86,0.174
35.30,116.00,0.174
35.33,116.14,0.174
35.36,116.29,0.174
35.39,116.43,0.174
35.42,116.57,0.174
35.44,116.71,0.174
35.47,116.85,0.174
35.50,116.99,0.174
35.53,117.14,0.174
35.56,117.28,0.174
35.59,117.42,0.174
35.61,117.56,0.174
35.64,117.70,0.174
35.67,117.84,0.174
35.70,117.99,0.174
35.73,118.13,0.174
35.76,118.27,0.174
35.79,118.41,0.174
35.81,118.55,0.174
35.84,118.70,0.174
35.87,118.84,0.174
35.90,118.98,0.174
35.93,119.12,0.174
35.96,119.26,0.174
35.98,119.40,0.174
36.01,119.54,0.174
36.04,119.69,0.174
36.07,119.83,0.174
36.10,119.97,0.174
36.13,120.11,0.174
36.15,120.25,0.174
36.18,120.39,0.174
36.21,120.54,0.174
36.24,120.68,0.174
36.27,120.82,0.174
36.29,120.96,0.174
36.32,121.10,0.174
36.35,121.25,0.174
36.38,121.39,0.174
36.41,121.53,0.174
36.44,121.67,0.174
36.46,121.81,0.174
36.49,121.95,0.174
36.52,122.10,0.174
36.55,122.24,0.174
36.58,122.38,0.174
36.61,122.52,0.174
36.64,122.66,0.174
36.66,122.81,0.174
36.69,122.95,0.174
36.72,123.09,0.174
36.75,123.23,0.174
36.78,123.37,0.174
36.81,123.51,0.174
36.83,123.65,0.174
36.86,123.80,0.174
36.89,123.94,0.174
36.92,124.08,0.174
36.95,124.22,0.174
36.98,124.36,0.174
37.00,124.51,0.174
37.03,124.65,0.174
37.06,124.79,0.174
37.09,124.93,0.174
37.12,125.07,0.174
37.14,125.21,0.174
37.17,125.36,0.174
37.20,125.50,0.174
37.23,125.64,0.174
37.26,125.78,0.174
37.29,125.92,0.174
37.31,126.06,0.174
37.34,126.21,0.174
37.37,126.35,0.174
37.40,126.49,0.174
37.43,126.63,0.174
37.46,126.77,0.174
37.49,126.92,0.174
37.51,127.06,0.174
37.54,127.20,0.174
37.57,127.34,0.175
37.60,127.48,0.175
37.63,127.62,0.175
37.66,127.77,0.174
37.68,127.91,0.174
37.71,128.05,0.174
37.74,128.19,0.174
37.77,128.33,0.174
37.80,128.47,0.174
37.83,128.62,0.174
37.85,128.76,0.174
37.88,128.90,0.174
37.91,129.04,0.174
37.94,129.18,0.174
37.97,129.32,0.174
37.99,129.47,0.174
38.02,129.61,0.174
38.05,129.75,0.174
38.08,129.89,0.174
38.11,130.03,0.174
38.14,130.17,0.174
38.16,130.32,0.174
38.19,130.46,0.174
38.22,130.60,0.174
38.25,130.74,0.174
38.28,130.88,0.174
38.31,131.03,0.174
38.34,131.17,0.174
38.36,131.31,0.174
38.39,131.45,0.174
38.42,131.59,0.175
38.45,131.73,0.174
38.48,131.88,0.174
38.51,132.02,0.174
38.53,132.16,0.174
38.56,132.30,0.174
38.59,132.44,0.174
38.62,132.58,0.174
38.65,132.72,0.174
38.68,132.87,0.174
38.70,133.01,0.174
38.73,133.15,0.174
38.76,133.29,0.174
38.79,133.43,0.174
38.82,133.58,0.174
38.84,133.72,0.174
38.87,133.86,0.174
38.90,134.00,0.174
38.93,134.14,0.174
38.96,134.28,0.174
38.99,134.42,0.174
39.01,134.57,0.174
39.04,134.71,0.174
39.07,134.85,0.174
39.10,134.99,0.174
39.13,135.13,0.174
39.16,135.28,0.174
39.19,135.42,0.174
39.21,135.56,0.174
39.24,135.70,0.174
39.27,135.84,0.174
39.30,135.98,0.174
39.33,136.13,0.174
39.36,136.27,0.174
39.38,136.41,0.174
39.41,136.55,0.174
39.44,136.69,0.174
39.47,136.83,0.174
39.50,136.98,0.174
39.53,137.12,0.174
39.55,137.26,0.174
39.58,137.40,0.174
39.61,137.54,0.174
39.64,137.68,0.174
39.67,137.83,0.174
39.69,137.97,0.174
39.72,138.11,0.175
39.75,138.25,0.175
39.78,138.39,0.175
39.81,138.54,0.175
39.84,138.68,0.175
39.86,138.82,0.175
39.89,138.96,0.175
39.92,139.10,0.175
39.95,139.24,0.175
39.98,139.38,0.175
40.01,139.53,0.175
40.04,139.67,0.175
40.06,139.81,0.175
40.09,139.95,0.175
40.12,140.09,0.175
40.15,140.24,0.175
40.18,140.38,0.175
40.21,140.52,0.175
40.23,140.66,0.175
40.26,140.80,0.175
40.29,140.94,0.175
40.32,141.09,0.175
40.35,141.23,0.175
40.38,141.37,0.175
40.40,141.51,0.175
40.43,141.65,0.175
40.46,141.79,0.175
40.49,141.94,0.175
40.52,142.08,0.175
40.54,142.22,0.175
40.57,142.36,0.175
40.60,142.50,0.175
40.63,142.65,0.175
40.66,142.79,0.175
40.69,142.93,0.175
40.71,143.07,0.175
40.74,143.21,0.175
40.77,143.35,0.176
40.80,143.50,0.176
40.83,143.64,0.176
40.86,143.78,0.176
40.89,143.92,0.176
40.91,144.06,0.176
40.94,144.20,0.176
40.97,144.35,0.176
41.00,144.49,0.176
41.03,144.63,0.176
41.06,144.77,0.176
41.08,144.91,0.176
41.11,145.06,0.176
41.14,145.20,0.176
41.17,145.34,0.176
41.20,145.48,0.176
41.23,145.62,0.176
41.25,145.76,0.176
41.28,145.90,0.176
41.31,146.05,0.176
41.34,146.19,0.176
41.37,146.33,0.176
41.39,146.47,0.176
41.42,146.61,0.177
41.45,146.75,0.177
41.48,146.90,0.177
41.51,147.04,0.177
41.54,147.18,0.177
41.56,147.32,0.177
41.59,147.46,0.177
41.62,147.60,0.177
41.65,147.75,0.177
41.68,147.89,0.177
41.71,148.03,0.177
41.74,148.17,0.177
41.76,148.31,0.177
41.79,148.46,0.177
41.82,148.60,0.177
41.85,148.74,0.177
41.88,148.88,0.177
41.91,149.02,0.177
41.93,149.16,
41.96,149.30,
41.99,,

[step]
Ramp 10.00 °C/min to -60.00 °C
Time,Temperature,Heat Flow (Normalized)
min,°C,W/g
42.99,150.12,-0.034
43.00,150.12,-0.034
43.02,150.11,-0.034
43.03,150.11,-0.034
43.05,150.09,-0.034
43.06,150.07,-0.038
43.08,150.04,-0.057
43.09,149.99,-0.082
43.11,149.93,-0.115
43.12,149.85,-0.153
43.14,149.76,-0.192
43.15,149.66,-0.232
43.17,149.55,-0.265
43.18,149.44,-0.293
43.20,149.32,-0.317
43.21,149.20,-0.337
43.23,149.07,-0.352
43.24,148.94,-0.366
43.26,148.81,-0.378
43.27,148.67,-0.390
43.29,148.54,-0.398
43.30,148.40,-0.405
43.32,148.26,-0.412
43.33,148.12,-0.418
43.35,147.97,-0.423
43.36,147.83,-0.426
43.38,147.69,-0.431
43.39,147.54,-0.433
43.41,147.40,-0.436
43.42,147.25,-0.439
43.44,147.11,-0.442
43.45,146.96,-0.442
43.47,146.81,-0.443
43.48,146.67,-0.444
43.50,146.52,-0.445
43.51,146.37,-0.446
43.53,146.23,-0.447
43.54,146.08,-0.448
43.56,145.93,-0.448
43.57,145.79,-0.449
43.59,145.64,-0.450
43.60,145.49,-0.450
43.62,145.34,-0.450
43.63,145.19,-0.451
43.65,145.05,-0.451
43.66,144.90,-0.451
43.68,144.75,-0.452
43.69,144.60,-0.452
43.71,144.45,-0.452
43.72,144.30,-0.452
43.74,144.16,-0.453
43.75,144.01,-0.453
43.77,143.86,-0.453
43.78,143.71,-0.453
43.80,143.56,-0.453
43.81,143.41,-0.454
43.83,143.26,-0.454
43.84,143.11,-0.454
43.86,142.97,-0.454
43.87,142.82,-0.454
43.89,142.67,-0.454
43.90,142.52,-0.455
43.92,142.37,-0.455
43.93,142.22,-0.455
43.95,142.07,-0.455
43.96,141.92,-0.455
43.98,141.77,-0.455
43.99,141.63,-0.455
44.01,141.48,-0.455
44.02,141.33,-0.455
44.04,141.18,-0.456
44.05,141.03,-0.456
44.07,140.88,-0.456
44.08,140.73,-0.456
44.10,140.58,-0.456
44.11,140.43,-0.456
44.13,140.28,-0.456
44.14,140.13,-0.456
44.16,139.98,-0.456
44.17,139.83,-0.456
44.19,139.68,-0.456
44.20,139.53,-0.456
44.22,139.38,-0.456
44.23,139.23,-0.456
44.25,139.08,-0.456
44.26,138.94,-0.456
44.28,138.79,-0.456
44.29,138.64,-0.456
44.31,138.49,-0.456
44.32,138.34,-0.456
44.34,138.19,-0.456
44.35,138.04,-0.456
44.37,137.89,-0.456
44.38,137.74,-0.456
44.40,137.59,-0.456
44.41,137.44,-0.455
44.43,137.29,-0.455
44.44,137.14,-0.455
44.46,136.99,-0.455
44.47,136.84,-0.455
44.49,136.69,-0.455
44.50,136.54,-0.455
44.52,136.39,-0.455
44.53,136.24,-0.455
44.55,136.09,-0.455
44.56,135.94,-0.455
44.58,135.79,-0.455
44.59,135.64,-0.455
44.61,135.49,-0.454
44.62,135.34,-0.454
44.64,135.19,-0.454
44.65,135.04,-0.454
44.67,134.89,-0.454
44.68,134.74,-0.454
44.70,134.59,-0.454
44.71,134.44,-0.454
44.73,134.29,-0.453
44.74,134.15,-0.453
44.76,133.99,-0.453
44.77,133.85,-0.453
44.79,133.69,-0.453
44.80,133.55,-0.453
44.82,133.40,-0.453
44.83,133.24,-0.453
44.85,133.10,-0.453
44.86,132.95,-0.453
44.88,132.80,-0.452
44.89,132.65,-0.452
44.91,132.50,-0.452
44.92,132.35,-0.452
44.94,132.20,-0.452
44.95,132.05,-0.452
44.97,131.90,-0.452
44.98,131.75,-0.452
45.00,131.60,-0.451
45.01,131.45,-0.451
45.03,131.30,-0.451
45.04,131.15,-0.451
45.06,131.00,-0.451
45.07,130.85,-0.451
45.09,130.70,-0.451
45.10,130.55,-0.451
45.12,130.40,-0.451
45.13,130.25,-0.450
45.15,130.10,-0.450
45.16,129.95,-0.450
45.18,129.80,-0.450
45.19,129.65,-0.450
45.21,129.50,-0.450
45.22,129.35,-0.450
45.24,129.20,-0.450
45.25,129.05,-0.450
45.27,128.90,-0.450
45.28,128.75,-0.450
45.30,128.60,-0.449
45.31,128.45,-0.449
45.33,128.30,-0.449
45.34,128.16,-0.449
45.36,128.00,-0.449
45.37,127.86,-0.449
45.39,127.70,-0.449
45.40,127.55,-0.449
45.42,127.41,-0.449
45.43,127.26,-0.449
45.45,127.11,-0.449
45.46,126.96,-0.448
45.48,126.80,-0.448
45.49,126.66,-0.448
45.51,126.51,-0.448
45.52,126.36,-0.448
45.54,126.21,-0.448
45.55,126.06,-0.448
45.57,125.91,-0.448
45.58,125.76,-0.448
45.60,125.61,-0.448
45.61,125.46,-0.447
45.63,125.31,-0.447
45.64,125.16,-0.447
45.66,125.01,-0.447
45.67,124.86,-0.447
45.69,124.71,-0.447
45.70,124.56,-0.447
45.72,124.41,-0.447
45.73,124.26,-0.447
45.75,124.11,-0.447
45.76,123.96,-0.446
45.78,123.81,-0.446
45.79,123.66,-0.446
45.81,123.51,-0.446
45.82,123.36,-0.446
45.84,123.21,-0.446
45.85,123.06,-0.446
45.87,122.91,-0.446
45.88,122.76,-0.446
45.90,122.61,-0.446
45.91,122.46,-0.445
45.93,122.31,-0.445
45.94,122.16,-0.445
45.96,122.01,-0.445
45.97,121.86,-0.445
45.99,121.71,-0.445
46.00,121.56,-0.445
46.02,121.41,-0.445
46.03,121.26,-0.445
46.05,121.11,-0.445
46.06,120.96,-0.445
46.08,120.81,-0.445
46.09,120.66,-0.444
46.11,120.51,-0.444
46.12,120.36,-0.444
46.14,120.21,-0.444
46.15,120.07,-0.444
46.17,119.91,-0.444
46.18,119.76,-0.444
46.20,119.61,-0.444
46.21,119.46,-0.444
46.23,119.32,-0.444
46.24,119.16,-0.444
46.26,119.01,-0.443
46.27,118.86,-0.443
46.29,118.72,-0.443
46.30,118.56,-0.443
46.32,118.42,-0.443
46.33,118.27,-0.443
46.35,118.11,-0.443
46.36,117.97,-0.443
46.38,117.81,-0.443
46.39,117.67,-0.443
46.41,117.52,-0.443
46.42,117.37,-0.442
46.44,117.22,-0.442
46.45,117.07,-0.442
46.47,116.92,-0.442
46.48,116.77,-0.442
46.50,116.62,-0.442
46.51,116.47,-0.442
46.53,116.32,-0.442
46.54,116.17,-0.442
46.56,116.02,-0.442
46.57,115.87,-0.442
46.59,115.72,-0.441
46.60,115.57,-0.441
46.62,115.42,-0.441
46.63,115.27,-0.441
46.65,115.12,-0.441
46.66,114.97,-0.441
46.68,114.82,-0.441
46.69,114.67,-0.441
46.71,114.52,-0.441
46.72,114.37,-0.441
46.74,114.22,-0.440
46.75,114.07,-0.440
46.77,113.92,-0.440
46.78,113.77,-0.440
46.80,113.62,-0.440
46.81,113.47,-0.440
46.83,113.32,-0.440
46.84,113.17,-0.440
46.86,113.02,-0.440
46.87,112.87,-0.440
46.89,112.72,-0.439
46.90,112.57,-0.439
46.92,112.42,-0.439
46.93,112.27,-0.439
46.95,112.12,-0.439
46.96,111.97,-0.439
46.98,111.82,-0.439
46.99,111.67,-0.439
47.01,111.52,-0.439
47.02,111.37,-0.439
47.04,111.22,-0.439
47.05,111.07,-0.439
47.07,110.92,-0.438
47.08,110.77,-0.438
47.10,110.62,-0.438
47.11,110.47,-0.438
47.13,110.32,-0.438
47.14,110.17,-0.438
47.16,110.02,-0.438
47.17,109.87,-0.438
47.19,109.72,-0.438
47.20,109.57,-0.438
47.22,109.42,-0.438
47.23,109.27,-0.438
47.25,109.12,-0.438
47.26,108.98,-0.437
47.28,108.83,-0.437
47.29,108.68,-0.437
47.31,108.53,-0.437
47.32,108.38,-0.437
47.34,108.23,-0.437
47.35,108.08,-0.437
47.37,107.93,-0.437
47.38,107.78,-0.437
47.40,107.63,-0.437
47.41,107.48,-0.437
47.43,107.33,-0.436
47.44,107.18,-0.436
47.46,107.03,-0.436
47.47,106.88,-0.436
47.49,106.73,-0.436
47.50,106.58,-0.436
47.52,106.43,-0.436
47.53,106.28,-0.436
47.55,106.13,-0.436
47.56,105.98,-0.436
47.58,105.83,-0.436
47.59,105.68,-0.436
47.61,105.53,-0.435
47.62,105.38,-0.435
47.64,105.23,-0.435
47.65,105.08,-0.435
47.67,104.93,-0.435
47.68,104.78,-0.435
47.70,104.63,-0.435
47.71,104.48,-0.435
47.73,104.33,-0.435
47.74,104.18,-0.435
47.76,104.03,-0.435
47.77,103.88,-0.435
47.79,103.73,-0.435
47.80,103.58,-0.434
47.82,103.43,-0.434
47.83,103.28,-0.434
47.85,103.13,-0.434
47.86,102.98,-0.434
47.88,102.83,-0.434
47.89,102.68,-0.434
47.91,102.53,-0.434
47.92,102.38,-0.434
47.94,102.23,-0.434
47.95,102.08,-0.434
47.97,101.93,-0.434
47.98,101.78,-0.433
48.00,101.63,-0.433
48.01,101.48,-0.433
48.03,101.33,-0.433
48.04,101.18,-0.433
48.06,101.03,-0.433
[...]
142.62,2.48,0.138
142.65,2.63,0.139
142.68,2.77,0.139
142.71,2.91,0.140
142.74,3.05,0.141
142.77,3.19,0.142
142.79,3.34,0.142
142.82,3.48,0.143
142.85,3.62,0.143
142.88,3.76,0.144
142.91,3.90,0.144
142.93,4.04,0.144
142.96,4.18,0.145
142.99,4.33,0.145
143.02,4.47,0.145
143.05,4.61,0.145
143.08,4.75,0.145
143.10,4.90,0.145
143.13,5.04,0.145
143.16,5.18,0.145
143.19,5.32,0.145
143.22,5.46,0.145
143.25,5.60,0.145
143.28,5.75,0.144
143.30,5.89,0.144
143.33,6.03,0.144
143.36,6.17,0.144
143.39,6.31,0.144
143.42,6.45,0.143
143.45,6.60,0.143
143.47,6.74,0.143
143.50,6.88,0.143
143.53,7.02,0.142
143.56,7.16,0.142
143.59,7.31,0.142
143.62,7.45,0.142
143.64,7.59,0.142
143.67,7.73,0.142
143.70,7.87,0.142
143.73,8.01,0.141
143.76,8.16,0.141
143.78,8.30,0.141
143.81,8.44,0.141
143.84,8.58,0.141
143.87,8.72,0.141
143.90,8.87,0.141
143.93,9.01,0.141
143.95,9.15,0.141
143.98,9.29,0.141
144.01,9.44,0.141
144.04,9.58,0.141
144.07,9.72,0.141
144.10,9.86,0.141
144.13,10.00,0.141
144.15,10.14,0.141
144.18,10.28,0.141
144.21,10.43,0.141
144.24,10.57,0.141
144.27,10.71,0.141
144.30,10.85,0.141
144.32,10.99,0.141
144.35,11.14,0.141
144.38,11.28,0.141
144.41,11.42,0.141
144.44,11.56,0.141
144.47,11.70,0.141
144.49,11.84,0.141
144.52,11.98,0.141
144.55,12.12,0.141
144.58,12.27,0.141
144.61,12.41,0.141
144.63,12.55,0.141
144.66,12.69,0.141
144.69,12.84,0.141
144.72,12.98,0.142
144.75,13.12,0.141
144.78,13.26,0.142
144.80,13.40,0.142
144.83,13.55,0.142
144.86,13.69,0.142
144.89,13.83,0.142
144.92,13.97,0.142
144.95,14.11,0.142
144.98,14.25,0.142
145.00,14.40,0.142
145.03,14.54,0.142
145.06,14.68,0.142
145.09,14.82,0.142
145.12,14.96,0.142
145.15,15.10,0.142
145.17,15.25,0.142
145.20,15.39,0.142
145.23,15.53,0.142
145.26,15.67,0.142
145.29,15.81,0.142
145.32,15.95,0.142
145.34,16.10,0.142
145.37,16.24,0.142
145.40,16.38,0.142
145.43,16.52,0.142
145.46,16.66,0.142
145.48,16.81,0.143
145.51,16.95,0.143
145.54,17.09,0.143
145.57,17.23,0.143
145.60,17.37,0.143
145.63,17.51,0.143
145.65,17.66,0.143
145.68,17.80,0.143
145.71,17.94,0.143
145.74,18.08,0.143
145.77,18.22,0.143
145.80,18.37,0.143
145.83,18.51,0.143
145.85,18.65,0.143
145.88,18.79,0.143
145.91,18.93,0.144
145.94,19.07,0.144
145.97,19.21,0.144
146.00,19.36,0.144
146.02,19.50,0.144
146.05,19.64,0.144
146.08,19.78,0.144
146.11,19.92,0.144
146.14,20.07,0.144
146.17,20.21,0.144
146.19,20.35,0.144
146.22,20.49,0.144
146.25,20.63,0.144
146.28,20.77,0.144
146.31,20.92,0.144
146.33,21.06,0.144
146.36,21.20,0.144
146.39,21.34,0.145
146.42,21.48,0.145
146.45,21.63,0.145
146.48,21.77,0.145
146.50,21.91,0.145
146.53,22.05,0.145
146.56,22.19,0.145
146.59,22.34,0.145
146.62,22.48,0.145
146.65,22.62,0.145
146.68,22.76,0.145
146.70,22.90,0.145
146.73,23.04,0.145
146.76,23.19,0.145
146.79,23.33,0.145
146.82,23.47,0.146
146.85,23.61,0.146
146.87,23.75,0.146
146.90,23.89,0.146
146.93,24.04,0.146
146.96,24.18,0.146
146.99,24.32,0.146
147.02,24.46,0.146
147.04,24.60,0.146
147.07,24.74,0.146
147.10,24.89,0.146
147.13,25.03,0.146
147.16,25.17,0.146
147.18,25.31,0.146
147.21,25.45,0.146
147.24,25.59,0.146
147.27,25.74,0.146
147.30,25.88,0.146
147.33,26.02,0.146
147.35,26.16,0.146
147.38,26.30,0.147
147.41,26.44,0.147
147.44,26.59,0.147
147.47,26.73,0.147
147.50,26.87,0.147
147.53,27.01,0.147
147.55,27.15,0.147
147.58,27.30,0.147
147.61,27.44,0.147
147.64,27.58,0.147
147.67,27.72,0.147
147.70,27.86,0.147
147.72,28.00,0.147
147.75,28.15,0.147
147.78,28.29,0.147
147.81,28.43,0.147
147.84,28.57,0.147
147.87,28.71,0.147
147.89,28.85,0.148
147.92,29.00,0.148
147.95,29.14,0.148
147.98,29.28,0.148
148.01,29.42,0.148
148.03,29.56,0.148
148.06,29.71,0.148
148.09,29.85,0.148
148.12,29.99,0.148
148.15,30.13,0.148
148.18,30.27,0.148
148.20,30.41,0.148
148.23,30.56,0.148
148.26,30.70,0.148
148.29,30.84,0.148
148.32,30.98,0.148
148.35,31.12,0.148
148.38,31.26,0.149
148.40,31.40,0.149
148.43,31.55,0.149
148.46,31.69,0.149
148.49,31.83,0.149
148.52,31.97,0.149
148.55,32.12,0.149
148.57,32.26,0.149
148.60,32.40,0.149
148.63,32.54,0.149
148.66,32.68,0.149
148.69,32.82,0.149
148.72,32.97,0.149
148.74,33.11,0.149
148.77,33.25,0.149
148.80,33.39,0.149
148.83,33.53,0.149
148.86,33.68,0.149
148.88,33.82,0.149
148.91,33.96,0.149
148.94,34.10,0.149
148.97,34.24,0.149
149.00,34.38,0.150
149.03,34.53,0.150
149.05,34.67,0.150
149.08,34.81,0.150
149.11,34.95,0.150
149.14,35.09,0.150
149.17,35.24,0.150
149.20,35.38,0.150
149.23,35.52,0.150
149.25,35.66,0.150
149.28,35.80,0.150
149.31,35.94,0.150
149.34,36.09,0.150
149.37,36.23,0.150
149.40,36.37,0.150
149.42,36.51,0.150
149.45,36.65,0.150
149.48,36.79,0.151
149.51,36.94,0.151
149.54,37.08,0.151
149.57,37.22,0.151
149.59,37.36,0.151
149.62,37.50,0.151
149.65,37.64,0.151
149.68,37.79,0.151
149.71,37.93,0.151
149.73,38.07,0.151
149.76,38.21,0.151
149.79,38.35,0.151
149.82,38.50,0.151
149.85,38.64,0.151
149.88,38.78,0.151
149.90,38.92,0.151
149.93,39.06,0.151
149.96,39.20,0.151
149.99,39.35,0.151
150.02,39.49,0.152
150.05,39.63,0.152
150.08,39.77,0.152
150.10,39.91,0.152
150.13,40.05,0.152
150.16,40.20,0.152
150.19,40.34,0.152
150.22,40.48,0.152
150.25,40.62,0.152
150.27,40.76,0.152
150.30,40.90,0.152
150.33,41.05,0.152
150.36,41.19,0.152
150.39,41.33,0.152
150.42,41.47,0.152
150.44,41.61,0.152
150.47,41.75,0.152
150.50,41.90,0.152
150.53,42.04,0.153
150.56,42.18,0.153
150.58,42.32,0.153
150.61,42.46,0.153
150.64,42.61,0.153
150.67,42.75,0.153
150.70,42.89,0.153
150.73,43.03,0.153
150.75,43.17,0.153
150.78,43.31,0.153
150.81,43.46,0.153
150.84,43.60,0.153
150.87,43.74,0.153
150.90,43.88,0.153
150.93,44.02,0.153
150.95,44.17,0.153
150.98,44.31,0.153
151.01,44.45,0.153
151.04,44.59,0.154
151.07,44.73,0.154
151.10,44.87,0.153
151.12,45.01,0.154
151.15,45.16,0.154
151.18,45.30,0.154
151.21,45.44,0.154
151.24,45.58,0.154
151.27,45.72,0.154
151.29,45.87,0.154
151.32,46.01,0.154
151.35,46.15,0.154
151.38,46.29,0.154
151.41,46.43,0.154
151.43,46.58,0.154
151.46,46.72,0.154
151.49,46.86,0.154
151.52,47.00,0.154
151.55,47.14,0.155
151.58,47.28,0.154
151.60,47.43,0.155
151.63,47.57,0.155
151.66,47.71,0.155
151.69,47.85,0.155
151.72,47.99,0.155
151.75,48.13,0.155
151.78,48.28,0.155
151.80,48.42,0.155
151.83,48.56,0.155
151.86,48.70,0.155
151.89,48.84,0.155
151.92,48.98,0.155
151.95,49.13,0.155
151.97,49.27,0.155
152.00,49.41,0.155
152.03,49.55,0.155
152.06,49.69,0.155
152.09,49.84,0.155
152.12,49.98,0.156
152.14,50.12,0.156
152.17,50.26,0.156
152.20,50.40,0.156
152.23,50.54,0.156
152.26,50.68,0.156
152.28,50.83,0.156
152.31,50.97,0.156
152.34,51.11,0.156
152.37,51.25,0.156
152.40,51.40,0.156
152.43,51.54,0.156
152.45,51.68,0.156
152.48,51.82,0.156
152.51,51.96,0.156
152.54,52.10,0.156
152.57,52.24,0.156
152.60,52.39,0.156
152.63,52.53,0.156
152.65,52.67,0.157
152.68,52.81,0.157
152.71,52.95,0.157
152.74,53.10,0.157
152.77,53.24,0.157
152.80,53.38,0.157
152.82,53.52,0.157
152.85,53.66,0.157
152.88,53.80,0.157
152.91,53.95,0.157
152.94,54.09,0.157
152.97,54.23,0.157
152.99,54.37,0.157
153.02,54.51,0.157
153.05,54.65,0.157
153.08,54.80,0.157
153.11,54.94,0.157
153.13,55.08,0.157
153.16,55.22,0.157
153.19,55.36,0.157
153.22,55.51,0.158
153.25,55.65,0.158
153.28,55.79,0.158
153.30,55.93,0.158
153.33,56.07,0.158
153.36,56.21,0.158
153.39,56.36,0.158
153.42,56.50,0.158
153.45,56.64,0.158
153.48,56.78,0.158
153.50,56.92,0.158
153.53,57.06,0.158
153.56,57.21,0.158
153.59,57.35,0.158
153.62,57.49,0.158
153.65,57.63,0.158
153.67,57.77,0.158
153.70,57.91,0.158
153.73,58.06,0.158
153.76,58.20,0.159
153.79,58.34,0.159
153.82,58.48,0.159
153.84,58.62,0.159
153.87,58.77,0.159
153.90,58.91,0.159
153.93,59.05,0.159
153.96,59.19,0.159
153.98,59.33,0.159
154.01,59.47,0.159
154.04,59.61,0.159
154.07,59.76,0.159
154.10,59.90,0.159
154.13,60.04,0.159
154.15,60.18,0.159
154.18,60.32,0.159
154.21,60.47,0.159
154.24,60.61,0.159
154.27,60.75,0.159
154.30,60.89,0.159
154.33,61.03,0.159
154.35,61.17,0.159
154.38,61.32,0.159
154.41,61.46,0.159
154.44,61.60,0.160
154.47,61.74,0.160
154.50,61.88,0.160
154.52,62.02,0.160
154.55,62.17,0.160
154.58,62.31,0.160
154.61,62.45,0.160
154.64,62.59,0.160
154.67,62.74,0.160
154.69,62.88,0.160
154.72,63.02,0.160
154.75,63.16,0.160
154.78,63.30,0.160
154.81,63.44,0.160
154.83,63.58,0.160
154.86,63.73,0.160
154.89,63.87,0.160
154.92,64.01,0.160
154.95,64.15,0.160
154.98,64.29,0.161
155.00,64.43,0.161
155.03,64.58,0.161
155.06,64.72,0.161
155.09,64.86,0.161
155.12,65.00,0.161
155.15,65.14,0.161
155.18,65.28,0.161
155.20,65.43,0.161
155.23,65.57,0.161
155.26,65.71,0.161
155.29,65.85,0.161
155.32,65.99,0.161
155.35,66.14,0.161
155.37,66.28,0.161
155.40,66.42,0.161
155.43,66.56,0.161
155.46,66.70,0.161
155.49,66.84,0.161
155.52,66.99,0.162
155.54,67.13,0.162
155.57,67.27,0.162
155.60,67.41,0.162
155.63,67.55,0.162
155.66,67.70,0.162
155.68,67.84,0.162
155.71,67.98,0.162
155.74,68.12,0.162
155.77,68.26,0.162
155.80,68.40,0.162
155.83,68.55,0.162
155.85,68.69,0.162
155.88,68.83,0.162
155.91,68.97,0.162
155.94,69.11,0.162
155.97,69.25,0.162
156.00,69.40,0.162
156.03,69.54,0.162
156.05,69.68,0.162
156.08,69.82,0.162
156.11,69.96,0.163
156.14,70.10,0.163
156.17,70.25,0.163
156.20,70.39,0.163
156.22,70.53,0.163
156.25,70.67,0.163
156.28,70.81,0.163
156.31,70.95,0.163
156.34,71.10,0.163
156.37,71.24,0.163
156.39,71.38,0.163
156.42,71.52,0.163
156.45,71.67,0.163
156.48,71.81,0.163
156.51,71.95,0.163
156.53,72.09,0.163
156.56,72.23,0.163
156.59,72.37,0.164
156.62,72.51,0.164
156.65,72.66,0.164
156.68,72.80,0.164
156.70,72.94,0.164
156.73,73.08,0.164
156.76,73.22,0.164
156.79,73.37,0.164
156.82,73.51,0.164
156.85,73.65,0.164
156.88,73.79,0.164
156.90,73.93,0.164
156.93,74.07,0.164
156.96,74.22,0.164
156.99,74.36,0.164
157.02,74.50,0.165
157.05,74.64,0.165
157.07,74.78,0.165
157.10,74.92,0.165
157.13,75.06,0.165
157.16,75.21,0.165
157.19,75.35,0.165
157.22,75.49,0.165
157.24,75.63,0.165
157.27,75.77,0.165
157.30,75.92,0.165
157.33,76.06,0.165
157.36,76.20,0.165
157.38,76.34,0.165
157.41,76.48,0.165
157.44,76.62,0.165
157.47,76.77,0.166
157.50,76.91,0.166
157.53,77.05,0.166
157.55,77.19,0.166
157.58,77.33,0.166
157.61,77.47,0.166
157.64,77.62,0.166
157.67,77.76,0.166
157.70,77.90,0.166
157.73,78.04,0.166
157.75,78.18,0.166
157.78,78.32,0.166
157.81,78.47,0.166
157.84,78.61,0.166
157.87,78.75,0.166
157.90,78.89,0.166
157.92,79.03,0.166
157.95,79.17,0.166
157.98,79.32,0.166
158.01,79.46,0.167
158.04,79.60,0.167
158.07,79.74,0.167
158.09,79.88,0.167
158.12,80.03,0.167
158.15,80.17,0.167
158.18,80.31,0.167
158.21,80.45,0.167
158.23,80.59,0.167
158.26,80.73,0.167
158.29,80.88,0.167
158.32,81.02,0.167
158.35,81.16,0.167
158.38,81.30,0.167
158.40,81.44,0.167
158.43,81.58,0.167
158.46,81.73,0.167
158.49,81.87,0.168
158.52,82.01,0.168
158.55,82.15,0.168
158.58,82.29,0.168
158.60,82.43,0.168
158.63,82.58,0.168
158.66,82.72,0.168
158.69,82.86,0.168
158.72,83.00,0.168
158.75,83.14,0.168
158.77,83.29,0.168
158.80,83.43,0.168
158.83,83.57,0.168
158.86,83.71,0.168
158.89,83.85,0.168
158.92,83.99,0.168
158.94,84.14,0.168
158.97,84.28,0.168
159.00,84.42,0.168
159.03,84.56,0.168
159.06,84.70,0.168
159.08,84.85,0.168
159.11,84.99,0.169
159.14,85.13,0.169
159.17,85.27,0.169
159.20,85.41,0.169
159.23,85.56,0.169
159.25,85.70,0.169
159.28,85.84,0.169
159.31,85.98,0.169
159.34,86.13,0.169
159.37,86.27,0.169
159.40,86.41,0.169
159.43,86.55,0.169
159.45,86.69,0.169
159.48,86.83,0.169
159.51,86.97,0.169
159.54,87.12,0.169
159.57,87.26,0.169
159.60,87.40,0.169
159.62,87.54,0.169
159.65,87.68,0.169
159.68,87.82,0.169
159.71,87.96,0.169
159.74,88.11,0.169
159.77,88.25,0.169
159.79,88.39,0.169
159.82,88.53,0.169
159.85,88.67,0.169
159.88,88.81,0.169
159.91,88.95,0.169
159.93,89.10,0.169
159.96,89.24,0.169
159.99,89.38,0.169
160.02,89.52,0.169
160.05,89.67,0.169
160.08,89.81,0.169
160.10,89.95,0.169
160.13,90.09,0.169
160.16,90.23,0.169
160.19,90.37,0.169
160.22,90.52,0.169
160.25,90.66,0.170
160.28,90.80,0.170
160.30,90.94,0.170
160.33,91.08,0.170
160.36,91.22,0.170
160.39,91.37,0.170
160.42,91.51,0.170
160.45,91.65,0.170
160.47,91.79,0.170
160.50,91.93,0.170
160.53,92.07,0.170
160.56,92.22,0.170
160.59,92.36,0.170
160.62,92.50,0.170
160.64,92.64,0.170
160.67,92.78,0.170
160.70,92.92,0.171
160.73,93.07,0.171
160.76,93.21,0.171
160.78,93.35,0.171
160.81,93.49,0.171
160.84,93.63,0.171
160.87,93.77,0.171
160.90,93.92,0.171
160.93,94.06,0.171
160.95,94.20,0.171
160.98,94.34,0.171
161.01,94.48,0.171
161.04,94.63,0.171
161.07,94.76,0.171
161.10,94.91,0.171
161.13,95.05,0.172
161.15,95.19,0.172
161.18,95.33,0.172
161.21,95.47,0.172
161.24,95.62,0.172
161.27,95.76,0.172
161.30,95.90,0.172
161.32,96.04,0.172
161.35,96.18,0.172
161.38,96.32,0.172
161.41,96.47,0.172
161.44,96.61,0.172
161.47,96.75,0.172
161.49,96.89,0.172
161.52,97.03,0.172
161.55,97.18,0.172
161.58,97.32,0.172
161.61,97.46,0.172
161.63,97.60,0.173
161.66,97.74,0.173
161.69,97.88,0.173
161.72,98.03,0.173
161.75,98.17,0.173
161.78,98.31,0.173
161.80,98.45,0.173
161.83,98.59,0.173
161.86,98.73,0.173
161.89,98.88,0.173
161.92,99.02,0.173
161.95,99.16,0.173
161.98,99.30,0.173
162.00,99.44,0.173
162.03,99.58,0.173
162.06,99.73,0.173
162.09,99.87,0.173
162.12,100.01,0.173
162.15,100.15,0.173
162.17,100.29,0.174
162.20,100.43,0.174
162.23,100.58,0.174
162.26,100.72,0.174
162.29,100.86,0.174
162.32,101.00,0.174
162.34,101.14,0.174
162.37,101.29,0.174
162.40,101.43,0.174
162.43,101.57,0.174
162.46,101.71,0.174
162.48,101.85,0.174
162.51,101.99,0.174
162.54,102.14,0.174
162.57,102.28,0.175
162.60,102.42,0.175
162.63,102.56,0.175
162.65,102.70,0.175
162.68,102.84,0.175
162.71,102.99,0.175
162.74,103.13,0.175
162.77,103.27,0.175
162.80,103.41,0.175
162.83,103.55,0.175
162.85,103.69,0.175
162.88,103.84,0.175
162.91,103.98,0.175
162.94,104.12,0.175
162.97,104.26,0.175
163.00,104.40,0.175
163.02,104.55,0.175
163.05,104.69,0.175
163.08,104.83,0.175
163.11,104.97,0.175
163.14,105.11,0.175
163.17,105.25,0.175
163.19,105.39,0.175
163.22,105.54,0.176
163.25,105.68,0.176
163.28,105.82,0.176
163.31,105.96,0.176
163.33,106.10,0.176
163.36,106.25,0.176
163.39,106.39,0.176
163.42,106.53,0.176
163.45,106.67,0.176
163.48,106.81,0.176
163.50,106.95,0.176
163.53,107.09,0.176
163.56,107.24,0.176
163.59,107.38,0.176
163.62,107.52,0.176
163.65,107.66,0.176
163.68,107.80,0.176
163.70,107.94,0.176
163.73,108.09,0.176
163.76,108.23,0.177
163.79,108.37,0.177
163.82,108.51,0.177
163.85,108.65,0.177
163.87,108.80,0.177
163.90,108.94,0.177
163.93,109.08,0.177
163.96,109.22,0.177
163.99,109.36,0.177
164.02,109.51,0.177
164.04,109.65,0.177
164.07,109.79,0.177
164.10,109.93,0.177
164.13,110.07,0.177
164.16,110.21,0.177
164.18,110.36,0.177
164.21,110.50,0.177
164.24,110.64,0.177
164.27,110.78,0.178
164.30,110.92,0.178
164.33,111.06,0.178
164.35,111.20,0.178
164.38,111.35,0.178
164.41,111.49,0.178
164.44,111.63,0.178
164.47,111.77,0.178
164.50,111.91,0.178
164.53,112.06,0.178
164.55,112.20,0.178
164.58,112.34,0.178
164.61,112.48,0.178
164.64,112.62,0.178
164.67,112.77,0.178
164.70,112.91,0.178
164.72,113.05,0.178
164.75,113.19,0.179
164.78,113.33,0.179
164.81,113.47,0.179
164.84,113.62,0.179
164.87,113.76,0.179
164.89,113.90,0.179
164.92,114.04,0.179
164.95,114.18,0.179
164.98,114.32,0.179
165.01,114.47,0.179
165.03,114.61,0.179
165.06,114.75,0.179
165.09,114.89,0.179
165.12,115.03,0.179
165.15,115.17,0.179
165.18,115.31,0.179
165.20,115.46,0.179
165.23,115.60,0.179
165.26,115.74,0.179
165.29,115.88,0.179
165.32,116.02,0.180
165.35,116.17,0.180
165.38,116.31,0.180
165.40,116.45,0.180
165.43,116.59,0.180
165.46,116.73,0.180
165.49,116.87,0.180
165.52,117.02,0.180
165.55,117.16,0.180
165.57,117.30,0.180
165.60,117.44,0.180
165.63,117.58,0.180
165.66,117.72,0.180
165.69,117.87,0.180
165.72,118.01,0.180
165.74,118.15,0.180
165.77,118.29,0.180
165.80,118.43,0.180
165.83,118.57,0.180
165.86,118.72,0.180
165.88,118.86,0.180
165.91,119.00,0.180
165.94,119.14,0.181
165.97,119.28,0.181
166.00,119.43,0.181
166.03,119.57,0.181
166.05,119.71,0.181
166.08,119.85,0.181
166.11,119.99,0.181
166.14,120.13,0.181
166.17,120.27,0.181
166.20,120.42,0.181
166.23,120.56,0.181
166.25,120.70,0.181
166.28,120.84,0.181
166.31,120.98,0.181
166.34,121.13,0.181
166.37,121.27,0.181
166.40,121.41,0.181
166.42,121.55,0.181
166.45,121.69,0.181
166.48,121.83,0.181
166.51,121.98,0.182
166.54,122.12,0.182
166.57,122.26,0.182
166.59,122.40,0.182
166.62,122.54,0.182
166.65,122.68,0.182
166.68,122.83,0.182
166.71,122.97,0.182
166.73,123.11,0.182
166.76,123.25,0.182
166.79,123.39,0.182
166.82,123.54,0.182
166.85,123.68,0.182
166.88,123.82,0.182
166.90,123.96,0.182
166.93,124.10,0.182
166.96,124.24,0.182
166.99,124.38,0.182
167.02,124.53,0.182
167.05,124.67,0.182
167.08,124.81,0.182
167.10,124.95,0.182
167.13,125.09,0.182
167.16,125.23,0.182
167.19,125.38,0.182
167.22,125.52,0.183
167.25,125.66,0.183
167.27,125.80,0.183
167.30,125.94,0.183
167.33,126.08,0.183
167.36,126.23,0.183
167.39,126.37,0.183
167.42,126.51,0.183
167.44,126.65,0.183
167.47,126.79,0.183
167.50,126.93,0.183
167.53,127.08,0.183
167.56,127.22,0.183
167.58,127.36,0.183
167.61,127.50,0.183
167.64,127.64,0.183
167.67,127.79,0.183
167.70,127.93,0.183
167.73,128.07,0.183
167.75,128.21,0.183
167.78,128.35,0.183
167.81,128.49,0.183
167.84,128.64,0.183
167.87,128.78,0.183
167.90,128.92,0.183
167.93,129.06,0.183
167.95,129.20,0.184
167.98,129.34,0.184
168.01,129.49,0.184
168.04,129.63,0.184
168.07,129.77,0.184
168.10,129.91,0.184
168.12,130.05,0.184
168.15,130.19,0.184
168.18,130.34,0.184
168.21,130.48,0.184
168.24,130.62,0.184
168.27,130.76,0.184
168.29,130.90,0.184
168.32,131.04,0.184
168.35,131.19,0.184
168.38,131.33,0.184
168.41,131.47,0.184
168.43,131.61,0.184
168.46,131.75,0.184
168.49,131.90,0.184
168.52,132.04,0.184
168.55,132.18,0.184
168.58,132.32,0.184
168.60,132.46,0.184
168.63,132.60,0.184
168.66,132.75,0.184
168.69,132.89,0.185
168.72,133.03,0.185
168.75,133.17,0.185
168.78,133.31,0.185
168.80,133.45,0.185
168.83,133.60,0.185
168.86,133.74,0.185
168.89,133.88,0.185
168.92,134.02,0.185
168.95,134.16,0.185
168.97,134.30,0.185
169.00,134.45,0.185
169.03,134.59,0.185
169.06,134.73,0.185
169.09,134.87,0.185
169.12,135.01,0.185
169.14,135.15,0.185
169.17,135.30,0.185
169.20,135.44,0.185
169.23,135.58,0.185
169.26,135.72,0.185
169.28,135.86,0.185
169.31,136.00,0.185
169.34,136.15,0.185
169.37,136.29,0.185
169.40,136.43,0.185
169.43,136.57,0.185
169.45,136.71,0.185
169.48,136.86,0.185
169.51,137.00,0.185
169.54,137.14,0.185
169.57,137.28,0.185
169.60,137.42,0.185
169.63,137.57,0.186
169.65,137.71,0.186
169.68,137.85,0.186
169.71,137.99,0.186
169.74,138.13,0.186
169.77,138.27,0.186
169.80,138.41,0.186
169.82,138.55,0.186
169.85,138.70,0.186
169.88,138.84,0.186
169.91,138.98,0.186
169.94,139.12,0.186
169.97,139.26,0.186
169.99,139.41,0.186
170.02,139.55,0.186
170.05,139.69,0.186
170.08,139.83,0.186
170.11,139.97,0.186
170.13,140.11,0.186
170.16,140.26,0.186
170.19,140.40,0.186
170.22,140.54,0.186
170.25,140.68,0.187
170.28,140.82,0.187
170.30,140.97,0.186
170.33,141.11,0.187
170.36,141.25,0.187
170.39,141.39,0.187
170.42,141.53,0.187
170.45,141.67,0.187
170.48,141.81,0.187
170.50,141.96,0.187
170.53,142.10,0.187
170.56,142.24,0.187
170.59,142.38,0.187
170.62,142.52,0.187
170.65,142.66,0.187
170.67,142.81,0.187
170.70,142.95,0.187
170.73,143.09,0.187
170.76,143.23,0.187
170.79,143.37,0.187
170.82,143.52,0.187
170.84,143.66,0.187
170.87,143.80,0.187
170.90,143.94,0.187
170.93,144.08,0.187
170.96,144.23,0.187
170.98,144.37,0.187
171.01,144.51,0.187
171.04,144.65,0.187
171.07,144.79,0.187
171.10,144.93,0.187
171.13,145.07,0.187
171.15,145.22,0.187
171.18,145.36,0.187
171.21,145.50,0.188
171.24,145.64,0.188
171.27,145.78,0.188
171.30,145.92,0.188
171.33,146.07,0.188
171.35,146.21,0.188
171.38,146.35,0.188
171.41,146.49,0.188
171.44,146.63,0.188
171.47,146.77,0.188
171.50,146.92,0.188
171.52,147.06,0.188
171.55,147.20,0.188
171.58,147.34,0.188
171.61,147.48,0.188
171.64,147.62,0.188
171.67,147.77,0.188
171.69,147.91,0.188
171.72,148.05,0.188
171.75,148.19,0.188
171.78,148.33,0.188
171.81,148.48,0.188
171.83,148.62,0.188
171.86,148.76,0.189
171.89,148.90,0.189
171.92,149.04,0.189
171.95,149.18,
171.98,,
171.98,,