File: DSC/2025_04_18_THCa_Pro_n60C_170C_5Cmin_x3.csv
Filename,2025_04_18_THCa_Pro_n60C_170C_5Cmin_x3
Instrument name,DSC2A-00468 (192.168.1.100)
Operator,Yarger
rundate,4/18/2025
Sample name,2025_04_18_THCa_Pro_n60C_170C_5Cmin_x3
proceduresegments,Data Off ; Equilibrate -60.00 °C; Data On ; Ramp 5.00 °C/min to 170.00 °C; Data Off ; Isothermal 0.1 min; Data On ; Ramp 10.00 °C/min to -60.00 °C; Data Off ; Isothermal 1.0 min; Data On ; Ramp 5.00 °C/min to 170.00 °C; Data Off ; Isothermal 0.1 min; Data On ; Ramp 10.00 °C/min to -60.00 °C; Data Off ; Isothermal 1.0 min; Data On ; Ramp 5.00 °C/min to 30.00 °C
[File Parameters]
Run date,4/18/2025 6:42:42 PM
Trios version,5.1.1.46572
Original File Name,D:\DSC2500\JYarger\2025_04_18_THCa_Pro_n60C_170C_5Cmin_x3.tri
Current File Name,Y:\Files\Data\DSC\DSC2500\JYarger\2025_04_18_THCa_Pro_n60C_170C_5Cmin_x3.tri
[Procedure]
Procedure Name,THCa_Pro_n60_170C_5Cmin_x3
Sample Name,2025_04_18_THCa_Pro_n60C_170C_5Cmin_x3
Sample Mass,8.14 mg
Reference Sample Mass,0 mg
Pan Mass,54.39 mg
Pan Number,51
Reference Pan Mass,53.66 mg
Reference Pan Number,46
Pan Type,Tzero Aluminum Hermetic
Comments,Hermetic Sealed Al DSC Consumables Pan/Lids.
Project Name,CA
Operator,Yarger
Test,Custom
Unload Max Temperature,30
Unload Min Temperature,30
Load Max Temperature,30
Load Min Temperature,30
Stop on Gas Flow Error,Yes
[Signal List]
Signal #1,Time (min)
Signal #2,Temperature (°C)
Signal #3,Heat Flow (mW)
Signal #4,Delta T (µV)
Signal #5,Delta Tzero (µV)
Signal #6,Tzero Temperature (°C)
Signal #7,Cell Purge (mL/min)
Signal #8,Heater Temp (°C)
Signal #9,Power Delivered (W)
Signal #10,Reference Junction Temperature (°C)
Signal #11,Flange Temperature (°C)
Signal #12,Heat Flow Phase (rad)
Signal #13,Total Heat Capacity (J/°C)
Signal #14,Heat Capacity (J/°C)
[Configuration]
Company Name,ASU
Instrument Name,DSC2A-00468
Instrument Type,DSC2500
Serial Number,DSC2A-00468
IP,192.168.1.100
Location of Instrument,MRRC
DisplayType,Unknown
Sample Interval ,0.1 s/pt
Selected Heat Flow,T4P
Exotherm Direction,Down
Cell Serial,DRC2-00792
Lid Type,Standard
Cooler,RCS 90
Leave Cooler on at End of Sequence,On
Gas 2,Nitrogen
Gas Selected,Channel 1
Flow Rate,50 mL/min
Secondary Purge,On
Licensed Heat Flow,Heat Flow T4P
Modulation Licensed,Yes
[Versions]
Common IDD Version,1
Cortex Version,VER 2.10.2.31
Driver,5.0.0.6
GDM Version,1.0.3.3
TouchscreenVersion,1.0.0.16145
FEP Version,1.2.1.21
FEP Bootloader,2.0.0.5
AutoSampler Version,2.1.1.26
Auto Sampler Bootloader,2.0.0.5
FCM Version,1.1.0.3
FCM Bootloader,2.0.0.5
[Experiment Logs]
Experiment Log Entry # 1,Data On set to 0
Experiment Log Entry # 3,Equilibrate Segment -60 (C) Started
Experiment Log Entry # 5,Air Cool is off.
Experiment Log Entry # 7,Data On set to 1
Experiment Log Entry # 9,Ramp Segment 5 C/min to 170 Started
Experiment Log Entry # 11,Data On set to 0
Experiment Log Entry # 13,Isothermal Segment 0.1 min started
Experiment Log Entry # 15,Data On set to 1
Experiment Log Entry # 17,Ramp Segment 10 C/min to -60 Started
Experiment Log Entry # 19,Data On set to 0
Experiment Log Entry # 21,Isothermal Segment 1 min started
Experiment Log Entry # 23,Data On set to 1
Experiment Log Entry # 25,Ramp Segment 5 C/min to 170 Started
Experiment Log Entry # 27,Data On set to 0
Experiment Log Entry # 29,Isothermal Segment 0.1 min started
Experiment Log Entry # 31,Data On set to 1
Experiment Log Entry # 33,Ramp Segment 10 C/min to -60 Started
Experiment Log Entry # 35,Data On set to 0
Experiment Log Entry # 37,Isothermal Segment 1 min started
Experiment Log Entry # 39,Data On set to 1
Experiment Log Entry # 41,Ramp Segment 5 C/min to 30 Started
[Method Log]
Method Log Entry # 1,Data Off
Method Log Entry # 2,Equilibrate -60 °C
Method Log Entry # 3,Data On
Method Log Entry # 4,(Ramp 67112) Ramp 5 °C/minute to 170 °C
Method Log Entry # 5,Data Off
Method Log Entry # 6,Isothermal 0.1 minutes
Method Log Entry # 7,Data On
Method Log Entry # 8,(Ramp 67116) Ramp 10 °C/minute to -60 °C
Method Log Entry # 9,Data Off
Method Log Entry # 10,Isothermal 1 minutes
Method Log Entry # 11,Data On
Method Log Entry # 12,(Ramp 67120) Ramp 5 °C/minute to 170 °C
Method Log Entry # 13,Data Off
Method Log Entry # 14,Isothermal 0.1 minutes
Method Log Entry # 15,Data On
Method Log Entry # 16,(Ramp 67124) Ramp 10 °C/minute to -60 °C
Method Log Entry # 17,Data Off
Method Log Entry # 18,Isothermal 1 minutes
Method Log Entry # 19,Data On
Method Log Entry # 20,(Ramp 67128) Ramp 5 °C/minute to 30 °C
Cell Serial,DRC2-00792
[T1 Calibration]
Slope,-0.008529666
Offset,9.636258
Initial Temperature,98.23
GUID,f8bfdadc-4977-4fdf-ba6d-0ba9134940c3
[TZero Calibration]
Date Applied,11/29/2022 4:06:13 PM
Description,From -89.059 °C to 396.009 °C at 20.000°C/min
Gas Type,Nitrogen
Pan Type,None
Source Files 1,C:\Users\yargerlab\Desktop\DSC Data\General\TZero_calibration_11_29_22_2nd(2).tri
Source Files 2,C:\Users\yargerlab\Desktop\DSC Data\General\TZero_calibration_11_29_22_2nd(3).tri
Delta T Offset,13.05235
Delta T Slope,-0.007271007
Delta T0 Offset,-13.69128
Delta T0 Slope,0.06063341
[Temperature Calibration]
Date Applied,11/29/2022 7:12:28 PM
Description,From 106.590 °C to 186.590 °C at 10.000°C/min
Gas Type,Nitrogen
Pan Type,Tzero Aluminum Hermetic
Source Files 1,C:\Users\yargerlab\Desktop\DSC Data\General\Indium(6).tri
Measured 1,157.391
Known 1,156.598
[Cell Constant Calibration]
Date Applied,11/29/2022 7:12:29 PM
Description,From 106.590 °C to 186.590 °C at 10.000°C/min
Gas Type,Nitrogen
Pan Type,Tzero Aluminum Hermetic
Source Files 1,C:\Users\yargerlab\Desktop\DSC Data\General\Indium(6).tri
T4P KCell,1.006051
Onset Slope,63.26126 mW/°C
[Direct Cp Calibration]
Date Applied,11/30/2022 11:04:51 AM
Description,From -79.983 °C to 298.409 °C at 10.000°C/min
Gas Type,Nitrogen
Pan Type,Tzero Aluminum Hermetic
Source Files 1,C:\Users\yargerlab\Desktop\DSC Data\General\Sapphire_Heat_Capacity_11_30_22.tri
[Rev Cp Calibration]
Date Applied,11/30/2022 1:58:51 PM
Description,From -79.996 °C to 292.812 °C at 3.000°C/min
Gas Type,Nitrogen
Pan Type,Tzero Aluminum Hermetic
Source Files 1,C:\Users\yargerlab\Desktop\DSC Data\General\Sapphire_MDSC_Calibration_11_30_22.tri
[step]
Ramp 5.00 °C/min to 170.00 °C
Time,Temperature,Heat Flow (Normalized)
min,°C,W/g
0.00,-59.65,-0.052
0.03,-59.67,-0.050
0.06,-59.67,-0.042
0.09,-59.64,-0.038
0.13,-59.58,-0.032
0.16,-59.49,-0.020
0.19,-59.38,-0.005
0.22,-59.26,0.009
0.25,-59.13,0.023
0.29,-59.00,0.033
0.32,-58.86,0.042
0.35,-58.73,0.049
0.38,-58.58,0.055
0.41,-58.44,0.060
0.44,-58.29,0.064
0.48,-58.15,0.067
0.51,-58.00,0.070
0.54,-57.85,0.071
0.57,-57.70,0.073
0.60,-57.54,0.074
0.63,-57.39,0.075
0.67,-57.24,0.076
0.70,-57.08,0.076
0.73,-56.93,0.077
0.76,-56.78,0.077
0.79,-56.62,0.078
0.82,-56.47,0.078
0.85,-56.31,0.078
0.89,-56.16,0.079
0.92,-56.00,0.079
0.95,-55.84,0.079
0.98,-55.69,0.080
1.01,-55.53,0.080
1.05,-55.38,0.080
1.08,-55.22,0.080
1.11,-55.06,0.080
1.14,-54.91,0.081
1.17,-54.75,0.081
1.20,-54.59,0.081
1.23,-54.44,0.081
1.27,-54.28,0.081
1.30,-54.12,0.081
1.33,-53.96,0.081
1.36,-53.81,0.081
1.39,-53.65,0.081
1.43,-53.49,0.081
1.46,-53.34,0.081
1.49,-53.18,0.081
1.52,-53.02,0.081
1.55,-52.86,0.082
1.58,-52.70,0.082
1.62,-52.55,0.082
1.65,-52.39,0.082
1.68,-52.23,0.082
1.71,-52.07,0.082
1.74,-51.91,0.082
1.77,-51.76,0.082
1.81,-51.60,0.082
1.84,-51.44,0.082
1.87,-51.28,0.082
1.90,-51.12,0.082
1.93,-50.97,0.082
1.96,-50.81,0.082
1.99,-50.65,0.082
2.03,-50.49,0.082
2.06,-50.33,0.082
2.09,-50.18,0.082
2.12,-50.02,0.082
2.15,-49.86,0.082
2.19,-49.70,0.082
2.22,-49.54,0.082
2.25,-49.39,0.082
2.28,-49.23,0.082
2.31,-49.07,0.082
2.34,-48.91,0.082
2.38,-48.75,0.082
2.41,-48.60,0.082
2.44,-48.44,0.082
2.47,-48.28,0.082
2.50,-48.12,0.082
2.53,-47.96,0.082
2.56,-47.81,0.082
2.60,-47.65,0.081
2.63,-47.49,0.082
2.66,-47.33,0.081
2.69,-47.17,0.081
2.72,-47.02,0.081
2.76,-46.86,0.081
2.79,-46.70,0.081
2.82,-46.54,0.081
2.85,-46.38,0.081
2.88,-46.23,0.081
2.91,-46.07,0.081
2.94,-45.91,0.081
2.98,-45.75,0.081
3.01,-45.59,0.082
3.04,-45.43,0.082
3.07,-45.28,0.082
3.10,-45.12,0.082
3.14,-44.96,0.082
3.17,-44.80,0.082
3.20,-44.64,0.082
3.23,-44.48,0.082
3.26,-44.33,0.082
3.29,-44.17,0.082
3.33,-44.01,0.082
3.36,-43.85,0.082
3.39,-43.69,0.082
3.42,-43.53,0.082
3.45,-43.38,0.082
3.48,-43.22,0.082
3.51,-43.06,0.082
3.55,-42.90,0.082
3.58,-42.75,0.082
3.61,-42.59,0.082
3.64,-42.43,0.081
3.67,-42.27,0.081
3.71,-42.11,0.081
3.74,-41.95,0.082
3.77,-41.80,0.082
3.80,-41.64,0.082
3.83,-41.48,0.082
3.86,-41.32,0.082
3.89,-41.16,0.082
3.93,-41.00,0.082
3.96,-40.84,0.082
3.99,-40.68,0.082
4.02,-40.53,0.082
4.05,-40.37,0.082
4.09,-40.21,0.082
4.12,-40.05,0.082
4.15,-39.89,0.082
4.18,-39.73,0.082
4.21,-39.57,0.082
4.24,-39.42,0.082
4.28,-39.25,0.082
4.31,-39.10,0.082
4.34,-38.94,0.082
4.37,-38.78,0.082
4.40,-38.62,0.082
4.43,-38.46,0.082
4.46,-38.30,0.082
4.50,-38.14,0.082
4.53,-37.99,0.082
4.56,-37.83,0.082
4.59,-37.67,0.082
4.62,-37.51,0.082
4.65,-37.35,0.082
4.69,-37.19,0.082
4.72,-37.03,0.082
4.75,-36.88,0.082
4.78,-36.72,0.082
4.81,-36.56,0.082
4.85,-36.40,0.082
4.88,-36.24,0.082
4.91,-36.08,0.082
4.94,-35.93,0.082
4.97,-35.77,0.082
5.00,-35.61,0.082
5.04,-35.45,0.082
5.07,-35.29,0.082
5.10,-35.13,0.082
5.13,-34.97,0.082
5.16,-34.82,0.082
5.19,-34.66,0.082
5.23,-34.50,0.083
5.26,-34.34,0.083
5.29,-34.18,0.083
5.32,-34.02,0.083
5.35,-33.87,0.083
5.38,-33.71,0.083
5.41,-33.55,0.083
5.45,-33.39,0.083
5.48,-33.23,0.083
5.51,-33.07,0.083
5.54,-32.91,0.083
5.57,-32.76,0.083
5.60,-32.60,0.083
5.64,-32.44,0.083
5.67,-32.28,0.083
5.70,-32.12,0.083
5.73,-31.96,0.083
5.76,-31.80,0.083
5.80,-31.64,0.083
5.83,-31.49,0.083
5.86,-31.33,0.083
5.89,-31.17,0.083
5.92,-31.01,0.083
5.95,-30.85,0.083
5.99,-30.69,0.083
6.02,-30.54,0.083
6.05,-30.38,0.083
6.08,-30.22,0.083
6.11,-30.06,0.083
6.14,-29.90,0.083
6.18,-29.74,0.083
6.21,-29.59,0.083
6.24,-29.43,0.083
6.27,-29.27,0.083
6.30,-29.11,0.083
6.33,-28.95,0.083
6.36,-28.79,0.083
6.40,-28.63,0.083
6.43,-28.47,0.084
6.46,-28.32,0.084
6.49,-28.16,0.084
6.52,-28.00,0.084
6.55,-27.84,0.084
6.59,-27.68,0.084
6.62,-27.52,0.084
6.65,-27.37,0.084
6.68,-27.21,0.084
6.71,-27.05,0.084
6.75,-26.89,0.084
6.78,-26.73,0.084
6.81,-26.57,0.084
6.84,-26.42,0.084
6.87,-26.26,0.084
6.90,-26.10,0.084
6.94,-25.94,0.084
6.97,-25.78,0.084
7.00,-25.62,0.084
7.03,-25.47,0.084
7.06,-25.31,0.084
7.09,-25.15,0.084
7.13,-24.99,0.084
7.16,-24.83,0.084
7.19,-24.67,0.084
7.22,-24.51,0.084
7.25,-24.35,0.084
7.28,-24.20,0.084
7.31,-24.04,0.084
7.35,-23.88,0.084
7.38,-23.72,0.084
7.41,-23.56,0.084
7.44,-23.40,0.084
7.47,-23.25,0.084
7.50,-23.09,0.085
7.54,-22.93,0.085
7.57,-22.77,0.085
7.60,-22.61,0.085
7.63,-22.45,0.085
7.66,-22.30,0.085
7.70,-22.14,0.085
7.73,-21.98,0.085
7.76,-21.82,0.085
7.79,-21.66,0.085
7.82,-21.50,0.085
7.85,-21.34,0.085
7.89,-21.19,0.085
7.92,-21.03,0.085
7.95,-20.87,0.085
7.98,-20.71,0.085
8.01,-20.55,0.085
8.04,-20.39,0.085
8.08,-20.24,0.085
8.11,-20.08,0.085
8.14,-19.92,0.085
8.17,-19.76,0.085
8.20,-19.60,0.085
8.23,-19.44,0.085
8.26,-19.28,0.085
8.30,-19.13,0.085
8.33,-18.97,0.085
8.36,-18.81,0.085
8.39,-18.65,0.085
8.42,-18.49,0.085
8.45,-18.33,0.085
8.49,-18.17,0.085
8.52,-18.02,0.085
8.55,-17.86,0.085
8.58,-17.70,0.086
8.61,-17.54,0.086
8.65,-17.38,0.086
8.68,-17.22,0.086
8.71,-17.06,0.086
8.74,-16.90,0.086
8.77,-16.75,0.086
8.80,-16.59,0.086
8.83,-16.43,0.086
8.87,-16.27,0.086
8.90,-16.11,0.086
8.93,-15.95,0.086
8.96,-15.79,0.086
8.99,-15.64,0.086
9.03,-15.48,0.086
9.06,-15.32,0.086
9.09,-15.16,0.086
9.12,-15.00,0.086
9.15,-14.84,0.086
9.18,-14.68,0.086
9.22,-14.53,0.086
9.25,-14.37,0.086
9.28,-14.21,0.086
9.31,-14.05,0.086
9.34,-13.89,0.086
9.37,-13.74,0.086
9.40,-13.58,0.086
9.44,-13.42,0.086
9.47,-13.26,0.086
9.50,-13.10,0.086
9.53,-12.95,0.086
9.56,-12.79,0.086
9.60,-12.63,0.086
9.63,-12.47,0.086
9.66,-12.31,0.086
9.69,-12.16,0.086
9.72,-12.00,0.086
9.75,-11.84,0.086
9.78,-11.68,0.086
9.82,-11.52,0.086
9.85,-11.37,0.086
9.88,-11.21,0.087
9.91,-11.05,0.087
9.94,-10.89,0.087
9.98,-10.73,0.087
10.01,-10.57,0.087
10.04,-10.41,0.087
10.07,-10.25,0.087
10.10,-10.10,0.087
10.13,-9.94,0.087
10.17,-9.78,0.087
10.20,-9.62,0.087
10.23,-9.46,0.087
10.26,-9.30,0.087
10.29,-9.14,0.087
10.32,-8.99,0.087
10.35,-8.83,0.087
10.39,-8.67,0.087
10.42,-8.51,0.087
10.45,-8.35,0.087
10.48,-8.19,0.087
10.51,-8.03,0.087
10.55,-7.87,0.088
10.58,-7.71,0.088
10.61,-7.56,0.088
10.64,-7.39,0.088
10.67,-7.24,0.088
10.70,-7.08,0.088
10.73,-6.92,0.088
10.77,-6.76,0.088
10.80,-6.60,0.088
10.83,-6.45,0.088
10.86,-6.29,0.088
10.89,-6.13,0.088
10.93,-5.97,0.088
10.96,-5.81,0.088
10.99,-5.66,0.088
11.02,-5.50,0.088
11.05,-5.34,0.088
11.08,-5.18,0.088
11.12,-5.02,0.088
11.15,-4.86,0.088
11.18,-4.71,0.088
11.21,-4.55,0.088
11.24,-4.39,0.088
11.27,-4.23,0.088
11.30,-4.07,0.089
11.34,-3.91,0.089
11.37,-3.76,0.089
11.40,-3.60,0.089
11.43,-3.44,0.089
11.46,-3.28,0.089
11.50,-3.12,0.089
11.53,-2.96,0.089
11.56,-2.80,0.089
11.59,-2.65,0.089
11.62,-2.49,0.089
11.65,-2.33,0.089
11.68,-2.17,0.089
11.72,-2.01,0.089
11.75,-1.86,0.089
11.78,-1.70,0.089
11.81,-1.54,0.089
11.84,-1.38,0.089
11.88,-1.22,0.089
11.91,-1.06,0.089
11.94,-0.90,0.089
11.97,-0.74,0.089
12.00,-0.59,0.089
12.03,-0.43,0.089
12.07,-0.27,0.089
12.10,-0.11,0.089
12.13,0.05,0.089
12.16,0.21,0.089
12.19,0.36,0.090
12.22,0.52,0.090
12.25,0.68,0.090
12.29,0.84,0.090
12.32,1.00,0.090
12.35,1.16,0.090
12.38,1.32,0.090
12.41,1.47,0.090
12.45,1.63,0.090
12.48,1.79,0.090
12.51,1.95,0.090
12.54,2.11,0.090
12.57,2.26,0.090
12.60,2.42,0.090
12.63,2.58,0.090
12.67,2.74,0.090
12.70,2.90,0.090
12.73,3.06,0.090
12.76,3.22,0.090
12.79,3.37,0.090
12.83,3.53,0.090
12.86,3.69,0.090
12.89,3.85,0.091
12.92,4.01,0.091
12.95,4.17,0.091
12.98,4.33,0.091
13.02,4.48,0.091
13.05,4.64,0.091
13.08,4.80,0.091
13.11,4.96,0.091
13.14,5.12,0.091
13.17,5.28,0.091
13.20,5.43,0.091
13.24,5.59,0.091
13.27,5.75,0.091
13.30,5.91,0.091
13.33,6.07,0.091
13.36,6.23,0.091
13.40,6.38,0.091
13.43,6.54,0.091
13.46,6.70,0.091
13.49,6.86,0.091
13.52,7.02,0.092
13.55,7.18,0.092
13.58,7.34,0.092
13.62,7.49,0.092
13.65,7.65,0.092
13.68,7.81,0.092
13.71,7.97,0.092
13.74,8.13,0.092
13.78,8.29,0.092
13.81,8.44,0.092
13.84,8.60,0.092
13.87,8.76,0.092
13.90,8.92,0.092
13.93,9.08,0.092
13.97,9.24,0.092
14.00,9.40,0.092
14.03,9.55,0.092
14.06,9.71,0.092
14.09,9.87,0.092
14.12,10.03,0.092
14.15,10.19,0.092
14.19,10.35,0.092
14.22,10.51,0.093
14.25,10.66,0.093
14.28,10.82,0.093
14.31,10.98,0.093
14.35,11.14,0.093
14.38,11.30,0.093
14.41,11.46,0.093
14.44,11.61,0.093
14.47,11.77,0.093
14.50,11.93,0.093
14.53,12.09,0.093
14.57,12.25,0.093
14.60,12.41,0.093
14.63,12.56,0.093
14.66,12.72,0.093
14.69,12.88,0.093
14.73,13.04,0.093
14.76,13.20,0.093
14.79,13.36,0.093
14.82,13.52,0.093
14.85,13.67,0.093
14.88,13.83,0.093
14.92,13.99,0.094
14.95,14.15,0.094
14.98,14.31,0.094
15.01,14.47,0.094
15.04,14.62,0.094
15.07,14.78,0.094
15.10,14.94,0.094
15.14,15.10,0.094
15.17,15.26,0.094
15.20,15.42,0.094
15.23,15.57,0.094
15.26,15.73,0.094
15.30,15.89,0.094
15.33,16.05,0.094
15.36,16.21,0.094
15.39,16.37,0.094
15.42,16.52,0.094
15.45,16.68,0.094
15.48,16.84,0.094
15.52,17.00,0.094
15.55,17.16,0.094
15.58,17.32,0.095
15.61,17.48,0.095
15.64,17.63,0.095
15.68,17.79,0.095
15.71,17.95,0.095
15.74,18.11,0.095
15.77,18.27,0.095
15.80,18.43,0.095
15.83,18.58,0.095
15.87,18.74,0.095
15.90,18.90,0.095
15.93,19.06,0.095
15.96,19.22,0.095
15.99,19.38,0.095
16.02,19.53,0.095
16.05,19.69,0.095
16.09,19.85,0.095
16.12,20.01,0.095
16.15,20.17,0.096
16.18,20.33,0.096
16.21,20.49,0.096
16.25,20.64,0.096
16.28,20.80,0.096
16.31,20.96,0.096
16.34,21.12,0.096
16.37,21.28,0.096
16.40,21.44,0.096
16.43,21.59,0.096
16.47,21.75,0.096
16.50,21.91,0.096
16.53,22.07,0.096
16.56,22.23,0.096
16.59,22.39,0.096
16.63,22.54,0.096
16.66,22.70,0.096
16.69,22.86,0.096
16.72,23.02,0.096
16.75,23.18,0.097
16.78,23.34,0.097
16.82,23.49,0.097
16.85,23.65,0.097
16.88,23.81,0.097
16.91,23.97,0.097
16.94,24.13,0.097
16.97,24.29,0.097
17.00,24.45,0.097
17.04,24.60,0.097
17.07,24.76,0.097
17.10,24.92,0.097
17.13,25.08,0.097
17.16,25.24,0.097
17.19,25.40,0.097
17.23,25.56,0.097
17.26,25.71,0.097
17.29,25.87,0.097
17.32,26.03,0.097
17.35,26.19,0.097
17.38,26.35,0.097
17.42,26.51,0.097
17.45,26.66,0.098
17.48,26.82,0.098
17.51,26.98,0.098
17.54,27.14,0.098
17.58,27.30,0.098
17.61,27.46,0.098
17.64,27.62,0.098
17.67,27.77,0.098
17.70,27.93,0.098
17.73,28.09,0.098
17.77,28.25,0.098
17.80,28.41,0.098
17.83,28.57,0.098
17.86,28.72,0.098
17.89,28.88,0.098
17.92,29.04,0.098
17.96,29.20,0.098
17.99,29.36,0.098
18.02,29.52,0.098
18.05,29.67,0.099
18.08,29.83,0.099
18.11,29.99,0.099
18.14,30.15,0.099
18.18,30.31,0.099
18.21,30.47,0.099
18.24,30.63,0.099
18.27,30.78,0.099
18.30,30.94,0.099
18.33,31.10,0.099
18.37,31.26,0.099
18.40,31.42,0.099
18.43,31.58,0.099
18.46,31.73,0.099
18.49,31.89,0.099
18.53,32.05,0.099
18.56,32.21,0.099
18.59,32.37,0.099
18.62,32.53,0.099
18.65,32.68,0.099
18.68,32.84,0.100
18.72,33.00,0.100
18.75,33.16,0.100
18.78,33.32,0.100
18.81,33.48,0.100
18.84,33.64,0.100
18.87,33.79,0.100
18.91,33.95,0.100
18.94,34.11,0.100
18.97,34.27,0.100
19.00,34.43,0.100
19.03,34.59,0.100
19.06,34.74,0.100
19.09,34.90,0.100
19.13,35.06,0.100
19.16,35.22,0.100
19.19,35.38,0.100
19.22,35.54,0.100
19.25,35.70,0.100
19.28,35.85,0.100
19.32,36.01,0.101
19.35,36.17,0.101
19.38,36.33,0.101
19.41,36.49,0.101
19.44,36.65,0.101
19.48,36.80,0.101
19.51,36.96,0.101
19.54,37.12,0.101
19.57,37.28,0.101
19.60,37.44,0.101
19.63,37.60,0.101
19.67,37.76,0.101
19.70,37.91,0.101
19.73,38.07,0.101
19.76,38.23,0.101
19.79,38.39,0.101
19.82,38.55,0.101
19.86,38.71,0.101
19.89,38.86,0.101
19.92,39.02,0.101
19.95,39.18,0.101
19.98,39.34,0.102
20.01,39.50,0.102
20.04,39.66,0.102
20.08,39.82,0.102
20.11,39.97,0.102
20.14,40.13,0.102
20.17,40.29,0.102
20.20,40.45,0.102
20.23,40.61,0.102
20.27,40.77,0.102
20.30,40.92,0.102
20.33,41.08,0.102
20.36,41.24,0.102
20.39,41.40,0.102
20.43,41.56,0.102
20.46,41.72,0.102
20.49,41.87,0.102
20.52,42.03,0.102
20.55,42.19,0.102
20.58,42.35,0.102
20.62,42.51,0.102
20.65,42.67,0.102
20.68,42.83,0.103
20.71,42.98,0.103
20.74,43.14,0.103
20.77,43.30,0.103
20.81,43.46,0.103
20.84,43.62,0.103
20.87,43.78,0.103
20.90,43.94,0.103
20.93,44.09,0.103
20.96,44.25,0.103
20.99,44.41,0.103
21.03,44.57,0.103
21.06,44.73,0.103
21.09,44.89,0.103
21.12,45.04,0.103
21.15,45.20,0.103
21.18,45.36,0.103
21.22,45.52,0.104
21.25,45.68,0.104
21.28,45.84,0.104
21.31,45.99,0.104
21.34,46.15,0.104
21.38,46.31,0.104
21.41,46.47,0.104
21.44,46.63,0.104
21.47,46.79,0.104
21.50,46.94,0.104
21.53,47.10,0.104
21.57,47.26,0.104
21.60,47.42,0.104
21.63,47.58,0.104
21.66,47.74,0.104
21.69,47.90,0.104
21.72,48.05,0.104
21.76,48.21,0.104
21.79,48.37,0.104
21.82,48.53,0.104
21.85,48.69,0.105
21.88,48.84,0.105
21.91,49.00,0.105
21.94,49.16,0.105
21.98,49.32,0.105
22.01,49.48,0.105
22.04,49.63,0.105
22.07,49.79,0.105
22.10,49.95,0.105
22.13,50.11,0.105
22.17,50.27,0.105
22.20,50.43,0.105
22.23,50.59,0.105
22.26,50.74,0.105
22.29,50.90,0.105
22.33,51.06,0.105
22.36,51.22,0.105
22.39,51.38,0.105
22.42,51.54,0.106
22.45,51.69,0.106
22.48,51.85,0.106
22.52,52.01,0.106
22.55,52.17,0.106
22.58,52.33,0.106
22.61,52.49,0.106
22.64,52.65,0.106
22.67,52.80,0.106
22.71,52.96,0.106
22.74,53.12,0.106
22.77,53.28,0.106
22.80,53.44,0.106
22.83,53.60,0.106
22.86,53.76,0.106
22.89,53.91,0.106
22.93,54.07,0.106
22.96,54.23,0.107
22.99,54.39,0.107
23.02,54.55,0.107
23.05,54.71,0.107
23.08,54.86,0.107
23.12,55.02,0.107
23.15,55.18,0.107
23.18,55.34,0.107
23.21,55.50,0.107
23.24,55.66,0.107
23.28,55.81,0.107
23.31,55.97,0.107
23.34,56.13,0.107
23.37,56.29,0.107
23.40,56.45,0.107
23.43,56.61,0.107
23.47,56.76,0.107
23.50,56.92,0.107
23.53,57.08,0.107
23.56,57.24,0.108
23.59,57.40,0.108
23.62,57.56,0.108
23.66,57.72,0.108
23.69,57.87,0.108
23.72,58.03,0.108
23.75,58.19,0.108
23.78,58.35,0.108
23.81,58.51,0.108
23.84,58.67,0.108
23.88,58.82,0.108
23.91,58.98,0.108
23.94,59.14,0.108
23.97,59.30,0.108
24.00,59.46,0.108
24.03,59.62,0.108
24.07,59.77,0.109
24.10,59.93,0.109
24.13,60.09,0.109
24.16,60.25,0.109
24.19,60.41,0.109
24.23,60.57,0.109
24.26,60.73,0.109
24.29,60.88,0.109
24.32,61.04,0.109
24.35,61.20,0.109
24.38,61.36,0.109
24.42,61.52,0.109
24.45,61.68,0.109
24.48,61.83,0.109
24.51,61.99,0.109
24.54,62.15,0.109
24.57,62.31,0.110
24.61,62.47,0.110
24.64,62.63,0.110
24.67,62.78,0.110
24.70,62.94,0.110
24.73,63.10,0.110
24.76,63.26,0.110
24.79,63.42,0.110
24.83,63.57,0.110
24.86,63.73,0.110
24.89,63.89,0.110
24.92,64.05,0.110
24.95,64.21,0.110
24.98,64.37,0.110
25.02,64.53,0.110
25.05,64.68,0.110
25.08,64.84,0.110
25.11,65.00,0.110
25.14,65.16,0.110
25.18,65.32,0.110
25.21,65.48,0.111
25.24,65.63,0.111
25.27,65.79,0.111
25.30,65.95,0.111
25.33,66.11,0.111
25.37,66.27,0.111
25.40,66.43,0.111
25.43,66.58,0.111
25.46,66.74,0.111
25.49,66.90,0.111
25.52,67.06,0.111
25.56,67.22,0.111
25.59,67.38,0.111
25.62,67.54,0.111
25.65,67.69,0.111
25.68,67.85,0.111
25.71,68.01,0.111
25.74,68.17,0.111
25.78,68.33,0.111
25.81,68.49,0.111
25.84,68.65,0.112
25.87,68.80,0.112
25.90,68.96,0.112
25.93,69.12,0.112
25.97,69.28,0.112
26.00,69.44,0.112
26.03,69.60,0.112
26.06,69.75,0.112
26.09,69.91,0.112
26.13,70.07,0.112
26.16,70.23,0.112
26.19,70.39,0.112
26.22,70.55,0.112
26.25,70.70,0.112
26.28,70.86,0.112
26.32,71.02,0.112
26.35,71.18,0.112
26.38,71.34,0.112
26.41,71.50,0.112
26.44,71.66,0.112
26.47,71.81,0.113
26.51,71.97,0.113
26.54,72.13,0.113
26.57,72.29,0.113
26.60,72.45,0.113
26.63,72.61,0.113
26.66,72.77,0.113
26.69,72.92,0.113
26.73,73.08,0.113
26.76,73.24,0.113
26.79,73.40,0.113
26.82,73.56,0.113
26.85,73.71,0.113
26.88,73.87,0.113
26.92,74.03,0.113
26.95,74.19,0.113
26.98,74.35,0.113
27.01,74.51,0.113
27.04,74.67,0.113
27.08,74.82,0.113
27.11,74.98,0.113
27.14,75.14,0.114
27.17,75.30,0.114
27.20,75.46,0.114
27.23,75.62,0.114
27.27,75.77,0.114
27.30,75.93,0.114
27.33,76.09,0.114
27.36,76.25,0.114
27.39,76.41,0.114
27.42,76.56,0.114
27.46,76.72,0.114
27.49,76.88,0.114
27.52,77.04,0.114
27.55,77.20,0.114
27.58,77.36,0.114
27.61,77.52,0.114
27.64,77.67,0.114
27.68,77.83,0.114
27.71,77.99,0.114
27.74,78.15,0.114
27.77,78.31,0.115
27.80,78.47,0.115
27.83,78.62,0.115
27.87,78.78,0.115
27.90,78.94,0.115
27.93,79.10,0.115
27.96,79.26,0.115
27.99,79.42,0.115
28.03,79.58,0.115
28.06,79.73,0.115
28.09,79.89,0.115
28.12,80.05,0.115
28.15,80.21,0.115
28.18,80.37,0.115
28.22,80.53,0.115
28.25,80.68,0.115
28.28,80.84,0.115
28.31,81.00,0.115
28.34,81.16,0.115
28.37,81.32,0.115
28.41,81.48,0.115
28.44,81.63,0.115
28.47,81.79,0.115
28.50,81.95,0.115
28.53,82.11,0.116
28.56,82.27,0.116
28.59,82.43,0.116
28.63,82.58,0.116
28.66,82.74,0.116
28.69,82.90,0.116
28.72,83.06,0.116
28.75,83.22,0.116
28.78,83.38,0.116
28.82,83.54,0.116
28.85,83.69,0.116
28.88,83.85,0.116
28.91,84.01,0.116
28.94,84.17,0.116
28.98,84.33,0.116
29.01,84.49,0.116
29.04,84.64,0.116
29.07,84.80,0.116
29.10,84.96,0.116
29.13,85.12,0.116
29.17,85.28,0.116
29.20,85.44,0.116
29.23,85.59,0.116
29.26,85.75,0.116
29.29,85.91,0.116
29.32,86.07,0.116
29.36,86.23,0.116
29.39,86.39,0.116
29.42,86.55,0.117
29.45,86.70,0.117
29.48,86.86,0.117
29.51,87.02,0.117
29.54,87.18,0.117
29.58,87.34,0.117
29.61,87.50,0.117
29.64,87.65,0.117
29.67,87.81,0.117
29.70,87.97,0.117
29.73,88.13,0.117
29.77,88.29,0.117
29.80,88.45,0.117
29.83,88.60,0.117
29.86,88.76,0.117
29.89,88.92,0.117
29.93,89.08,0.117
29.96,89.24,0.117
29.99,89.40,0.117
30.02,89.56,0.117
30.05,89.71,0.117
30.08,89.87,0.117
30.12,90.03,0.117
30.15,90.19,0.117
30.18,90.35,0.118
30.21,90.51,0.118
30.24,90.66,0.118
30.27,90.82,0.118
30.31,90.98,0.118
30.34,91.14,0.118
30.37,91.30,0.118
30.40,91.45,0.118
30.43,91.61,0.118
30.46,91.77,0.118
30.49,91.93,0.118
30.53,92.09,0.118
30.56,92.25,0.118
30.59,92.41,0.118
30.62,92.56,0.118
30.65,92.72,0.118
30.68,92.88,0.118
30.72,93.04,0.118
30.75,93.20,0.118
30.78,93.36,0.118
30.81,93.51,0.118
30.84,93.67,0.119
30.88,93.83,0.119
30.91,93.99,0.119
30.94,94.15,0.119
30.97,94.31,0.119
31.00,94.47,0.119
31.03,94.62,0.119
31.07,94.78,0.119
31.10,94.94,0.119
31.13,95.10,0.119
31.16,95.26,0.119
31.19,95.42,0.119
31.22,95.57,0.119
31.26,95.73,0.119
31.29,95.89,0.119
31.32,96.05,0.119
31.35,96.21,0.119
31.38,96.37,0.119
31.41,96.53,0.120
31.44,96.68,0.120
31.48,96.84,0.120
31.51,97.00,0.120
31.54,97.16,0.120
31.57,97.32,0.120
31.60,97.47,0.120
31.63,97.63,0.120
31.67,97.79,0.120
31.70,97.95,0.120
31.73,98.11,0.120
31.76,98.27,0.120
31.79,98.43,0.120
31.83,98.58,0.120
31.86,98.74,0.120
31.89,98.90,0.120
31.92,99.06,0.120
31.95,99.22,0.120
31.98,99.38,0.120
32.02,99.53,0.120
32.05,99.69,0.120
32.08,99.85,0.120
32.11,100.01,0.121
32.14,100.17,0.121
32.17,100.33,0.121
32.21,100.48,0.121
32.24,100.64,0.121
32.27,100.80,0.121
32.30,100.96,0.121
32.33,101.12,0.121
32.36,101.28,0.121
32.39,101.44,0.121
32.43,101.59,0.121
32.46,101.75,0.121
32.49,101.91,0.121
32.52,102.07,0.121
32.55,102.23,0.121
32.58,102.39,0.121
32.62,102.54,0.121
32.65,102.70,0.121
32.68,102.86,0.121
32.71,103.02,0.121
32.74,103.18,0.121
32.78,103.34,0.121
32.81,103.49,0.122
32.84,103.65,0.122
32.87,103.81,0.122
32.90,103.97,0.122
32.93,104.13,0.122
32.97,104.28,0.122
33.00,104.44,0.122
33.03,104.60,0.122
33.06,104.76,0.122
33.09,104.92,0.122
33.12,105.08,0.122
33.16,105.23,0.122
33.19,105.39,0.122
33.22,105.55,0.122
33.25,105.71,0.122
33.28,105.87,0.122
33.31,106.03,0.122
33.34,106.19,0.122
33.38,106.34,0.122
33.41,106.50,0.122
33.44,106.66,0.123
33.47,106.82,0.123
33.50,106.98,0.123
33.53,107.14,0.123
33.57,107.29,0.123
33.60,107.45,0.123
33.63,107.61,0.123
33.66,107.77,0.123
33.69,107.93,0.123
33.73,108.09,0.123
33.76,108.25,0.123
33.79,108.40,0.123
33.82,108.56,0.123
33.85,108.72,0.123
33.88,108.88,0.123
33.92,109.04,0.123
33.95,109.20,0.123
33.98,109.35,0.123
34.01,109.51,0.123
34.04,109.67,0.123
34.07,109.83,0.124
34.11,109.99,0.124
34.14,110.15,0.124
34.17,110.30,0.124
34.20,110.46,0.124
34.23,110.62,0.124
34.26,110.78,0.124
34.29,110.94,0.124
34.33,111.10,0.124
34.36,111.26,0.124
34.39,111.41,0.124
34.42,111.57,0.124
34.45,111.73,0.124
34.49,111.89,0.124
34.52,112.05,0.124
34.55,112.20,0.124
34.58,112.36,0.124
34.61,112.52,0.124
34.64,112.68,0.124
34.68,112.84,0.124
34.71,113.00,0.125
34.74,113.15,0.125
34.77,113.31,0.125
34.80,113.47,0.125
34.83,113.63,0.125
34.86,113.79,0.125
34.90,113.95,0.125
34.93,114.10,0.125
34.96,114.26,0.125
34.99,114.42,0.125
35.02,114.58,0.125
35.06,114.74,0.125
35.09,114.90,0.125
35.12,115.06,0.125
35.15,115.21,0.125
35.18,115.37,0.126
35.21,115.53,0.126
35.24,115.69,0.126
35.28,115.85,0.126
35.31,116.01,0.126
35.34,116.16,0.126
35.37,116.32,0.126
35.40,116.48,0.126
35.44,116.64,0.126
35.47,116.80,0.126
35.50,116.96,0.126
35.53,117.11,0.126
35.56,117.27,0.126
35.59,117.43,0.127
35.63,117.59,0.127
35.66,117.75,0.127
35.69,117.91,0.127
35.72,118.07,0.127
35.75,118.22,0.127
35.78,118.38,0.127
35.81,118.54,0.127
35.85,118.70,0.127
35.88,118.86,0.127
35.91,119.02,0.128
35.94,119.17,0.128
35.97,119.33,0.128
36.01,119.49,0.128
36.04,119.65,0.128
36.07,119.81,0.128
36.10,119.96,0.128
36.13,120.12,0.128
36.16,120.28,0.129
36.19,120.44,0.129
36.23,120.60,0.129
36.26,120.76,0.129
36.29,120.92,0.129
36.32,121.07,0.130
36.35,121.23,0.130
36.39,121.39,0.130
36.42,121.55,0.130
36.45,121.71,0.131
36.48,121.86,0.131
36.51,122.02,0.131
36.54,122.18,0.131
36.58,122.34,0.132
36.61,122.50,0.132
36.64,122.65,0.132
36.67,122.81,0.132
36.70,122.97,0.133
36.73,123.13,0.133
36.76,123.29,0.133
36.80,123.45,0.134
36.83,123.60,0.134
36.86,123.76,0.134
36.89,123.92,0.135
36.92,124.08,0.135
36.96,124.24,0.136
36.99,124.40,0.136
37.02,124.55,0.137
37.05,124.71,0.137
37.08,124.87,0.138
37.11,125.03,0.138
37.14,125.19,0.139
37.18,125.34,0.139
37.21,125.50,0.140
37.24,125.66,0.141
37.27,125.82,0.141
37.30,125.97,0.142
37.34,126.13,0.143
37.37,126.29,0.144
37.40,126.45,0.145
37.43,126.61,0.146
37.46,126.76,0.147
37.49,126.92,0.148
37.53,127.08,0.149
37.56,127.24,0.151
37.59,127.40,0.152
37.62,127.55,0.153
37.65,127.71,0.154
37.68,127.87,0.156
37.71,128.03,0.157
37.75,128.19,0.159
37.78,128.34,0.160
37.81,128.50,0.162
37.84,128.66,0.164
37.87,128.82,0.165
37.91,128.97,0.167
37.94,129.13,0.169
37.97,129.29,0.171
38.00,129.45,0.173
38.03,129.60,0.175
38.06,129.76,0.177
38.09,129.92,0.180
38.13,130.08,0.181
38.16,130.23,0.184
38.19,130.39,0.187
38.22,130.55,0.189
38.25,130.71,0.191
38.29,130.86,0.194
38.32,131.02,0.197
38.35,131.18,0.201
38.38,131.33,0.204
38.41,131.49,0.206
38.44,131.65,0.210
38.48,131.80,0.214
38.51,131.96,0.218
38.54,132.12,0.223
38.57,132.27,0.228
38.60,132.43,0.232
38.63,132.59,0.237
38.66,132.74,0.243
38.70,132.90,0.249
38.73,133.05,0.256
38.76,133.21,0.263
38.79,133.36,0.270
38.82,133.52,0.279
38.86,133.67,0.286
38.89,133.83,0.296
38.92,133.98,0.305
38.95,134.14,0.314
38.98,134.29,0.325
39.01,134.44,0.336
39.04,134.59,0.348
39.08,134.75,0.360
39.11,134.90,0.372
39.14,135.05,0.384
39.17,135.20,0.397
39.20,135.36,0.409
39.24,135.51,0.424
39.27,135.66,0.440
39.30,135.81,0.454
39.33,135.96,0.473
39.36,136.11,0.486
39.39,136.26,0.501
39.43,136.41,0.518
39.46,136.56,0.535
39.49,136.71,0.563
39.52,136.86,0.599
39.55,137.00,0.637
39.58,137.14,0.664
39.61,137.29,0.689
39.65,137.43,0.713
39.68,137.58,0.734
39.71,137.72,0.745
39.74,137.88,0.750
39.77,138.03,0.743
39.81,138.19,0.749
39.84,138.34,0.768
39.87,138.49,0.781
39.90,138.65,0.776
39.93,138.81,0.778
39.96,138.97,0.761
39.99,139.13,0.756
40.03,139.29,0.748
40.06,139.45,0.756
40.09,139.61,0.750
40.12,139.77,0.776
40.15,139.91,0.857
40.19,140.04,0.904
40.22,140.19,0.908
40.25,140.33,0.935
40.28,140.48,0.929
40.31,140.63,0.962
40.34,140.78,0.990
40.38,140.93,0.968
40.41,141.09,0.930
40.44,141.26,0.911
40.47,141.42,0.924
40.50,141.58,0.947
40.53,141.73,0.949
40.56,141.89,0.917
40.60,142.06,0.894
40.63,142.23,0.851
40.66,142.40,0.841
40.69,142.57,0.821
40.72,142.74,0.774
40.76,142.92,0.729
40.79,143.10,0.695
40.82,143.28,0.656
40.85,143.45,0.651
40.88,143.62,0.578
40.91,143.81,0.517
40.94,143.99,0.466
40.98,144.18,0.422
41.01,144.36,0.381
41.04,144.53,0.346
41.07,144.71,0.315
41.10,144.89,0.289
41.14,145.06,0.266
41.17,145.23,0.245
41.20,145.40,0.226
41.23,145.57,0.210
41.26,145.73,0.195
41.29,145.90,0.182
41.33,146.07,0.171
41.36,146.23,0.161
41.39,146.39,0.153
41.42,146.56,0.144
41.45,146.72,0.138
41.48,146.88,0.134
41.51,147.04,0.128
41.55,147.20,0.124
41.58,147.36,0.121
41.61,147.52,0.117
41.64,147.69,0.114
41.67,147.85,0.112
41.71,148.01,0.110
41.74,148.16,0.108
41.77,148.33,0.107
41.80,148.48,0.107
41.83,148.64,0.106
41.86,148.80,0.105
41.89,148.96,0.104
41.93,149.12,0.104
41.96,149.28,0.103
41.99,149.44,0.103
42.02,149.60,0.102
42.05,149.75,0.102
42.09,149.91,0.101
42.12,150.07,0.100
42.15,150.23,0.100
42.18,150.39,0.099
42.21,150.55,0.099
42.24,150.71,0.099
42.28,150.86,0.098
42.31,151.02,0.098
42.34,151.18,0.098
42.37,151.34,0.097
42.40,151.50,0.097
42.43,151.66,0.097
42.46,151.82,0.096
42.50,151.97,0.096
42.53,152.13,0.096
42.56,152.29,0.096
42.59,152.45,0.096
42.62,152.61,0.097
42.66,152.76,0.103
42.69,152.92,0.110
42.72,153.08,0.118
42.75,153.23,0.124
42.78,153.39,0.129
42.81,153.54,0.132
42.84,153.70,0.137
42.88,153.85,0.141
42.91,154.01,0.144
42.94,154.17,0.146
42.97,154.32,0.148
43.00,154.48,0.149
43.04,154.64,0.150
43.07,154.80,0.151
43.10,154.95,0.152
43.13,155.11,0.152
43.16,155.27,0.152
43.19,155.43,0.153
43.23,155.59,0.153
43.26,155.74,0.153
43.29,155.90,0.153
43.32,156.06,0.153
43.35,156.22,0.153
43.38,156.38,0.153
43.41,156.54,0.153
43.45,156.70,0.153
43.48,156.86,0.152
43.51,157.01,0.152
43.54,157.17,0.151
43.57,157.33,0.151
43.61,157.49,0.150
43.64,157.65,0.149
43.67,157.81,0.149
43.70,157.97,0.148
43.73,158.12,0.147
43.76,158.29,0.146
43.79,158.44,0.146
43.83,158.60,0.145
43.86,158.76,0.144
43.89,158.92,0.144
43.92,159.08,0.143
43.95,159.24,0.142
43.99,159.39,0.141
44.02,159.55,0.140
44.05,159.71,0.139
44.08,159.87,0.139
44.11,160.03,0.138
44.14,160.19,0.137
44.18,160.35,0.137
44.21,160.51,0.136
44.24,160.67,0.136
44.27,160.82,0.135
44.30,160.98,0.135
44.33,161.14,0.134
44.36,161.30,0.134
44.40,161.46,0.133
44.43,161.62,0.133
44.46,161.78,0.132
44.49,161.93,0.131
44.52,162.09,0.131
44.56,162.25,0.130
44.59,162.41,0.130
44.62,162.57,0.129
44.65,162.73,0.129
44.68,162.89,0.128
44.71,163.04,0.128
44.74,163.20,0.128
44.78,163.36,0.127
44.81,163.52,0.127
44.84,163.68,0.127
44.87,163.84,0.126
44.90,163.99,0.126
44.94,164.15,0.126
44.97,164.31,0.125
45.00,164.47,0.125
45.03,164.63,0.125
45.06,164.79,0.125
45.09,164.95,0.125
45.13,165.10,0.124
45.16,165.26,0.124
45.19,165.42,0.124
45.22,165.58,0.124
45.25,165.74,0.124
45.28,165.90,0.124
45.31,166.05,0.124
45.35,166.21,0.124
45.38,166.37,0.124
45.41,166.53,0.124
45.44,166.69,0.123
45.47,166.85,0.123
45.51,167.01,0.123
45.54,167.16,0.124
45.57,167.32,0.124
45.60,167.48,0.124
45.63,167.64,0.124
45.66,167.80,0.124
45.69,167.96,0.124
45.73,168.11,0.124
45.76,168.27,0.125
45.79,168.43,0.125
45.82,168.59,0.125
45.85,168.74,0.125
45.89,168.90,0.126
45.92,169.06,0.126
45.95,169.22,
45.98,,
45.98,,

[step]
Ramp 10.00 °C/min to -60.00 °C
Time,Temperature,Heat Flow (Normalized)
min,°C,W/g
46.09,169.83,0.181
46.10,169.87,0.193
46.12,169.91,0.209
46.14,169.93,0.221
46.15,169.94,0.238
46.17,169.92,0.270
46.19,169.89,0.312
46.20,169.83,0.352
46.22,169.75,0.378
46.24,169.65,0.381
46.25,169.54,0.364
46.27,169.43,0.328
46.29,169.31,0.287
46.30,169.18,0.243
46.32,169.05,0.201
46.34,168.93,0.164
46.35,168.79,0.130
46.37,168.66,0.100
46.39,168.52,0.072
46.40,168.38,0.046
46.42,168.23,0.023
46.44,168.09,0.001
46.45,167.94,-0.018
46.47,167.79,-0.036
46.49,167.64,-0.052
46.50,167.49,-0.067
46.52,167.34,-0.081
46.54,167.18,-0.093
46.55,167.03,-0.103
46.57,166.87,-0.114
46.59,166.72,-0.123
46.60,166.56,-0.131
46.62,166.40,-0.138
46.64,166.24,-0.146
46.65,166.08,-0.152
46.67,165.92,-0.157
46.69,165.76,-0.162
46.70,165.60,-0.167
46.72,165.44,-0.171
46.74,165.28,-0.174
46.75,165.12,-0.178
46.77,164.96,-0.182
46.79,164.79,-0.185
46.80,164.63,-0.188
46.82,164.47,-0.191
46.84,164.31,-0.192
46.85,164.14,-0.194
46.87,163.98,-0.196
46.89,163.82,-0.197
46.90,163.65,-0.200
46.92,163.49,-0.201
46.94,163.32,-0.202
46.95,163.16,-0.203
46.97,163.00,-0.205
46.99,162.83,-0.206
47.00,162.67,-0.207
47.02,162.50,-0.208
47.04,162.34,-0.208
47.05,162.17,-0.208
47.07,162.01,-0.209
47.09,161.84,-0.210
47.10,161.68,-0.210
47.12,161.51,-0.210
47.14,161.35,-0.211
47.15,161.18,-0.212
47.17,161.02,-0.213
47.19,160.85,-0.213
47.20,160.69,-0.214
47.22,160.52,-0.214
47.24,160.35,-0.214
47.25,160.19,-0.215
47.27,160.02,-0.215
47.29,159.86,-0.215
47.30,159.69,-0.215
47.32,159.53,-0.215
47.34,159.36,-0.216
47.35,159.20,-0.216
47.37,159.03,-0.216
47.39,158.86,-0.216
47.40,158.70,-0.217
47.42,158.53,-0.217
47.44,158.37,-0.217
47.45,158.20,-0.217
47.47,158.03,-0.218
47.49,157.87,-0.218
47.50,157.70,-0.218
47.52,157.54,-0.218
47.54,157.37,-0.218
47.55,157.20,-0.219
47.57,157.04,-0.219
47.59,156.87,-0.219
47.60,156.71,-0.219
47.62,156.54,-0.219
47.64,156.37,-0.220
47.65,156.21,-0.220
47.67,156.04,-0.220
47.69,155.88,-0.220
47.70,155.71,-0.220
47.72,155.54,-0.220
47.74,155.38,-0.220
47.75,155.21,-0.220
47.77,155.04,-0.220
47.79,154.88,-0.220
47.80,154.71,-0.221
47.82,154.54,-0.221
47.84,154.38,-0.221
47.85,154.21,-0.221
47.87,154.05,-0.221
47.89,153.88,-0.221
47.90,153.71,-0.221
47.92,153.55,-0.222
47.94,153.38,-0.222
47.95,153.21,-0.222
47.97,153.05,-0.222
47.99,152.88,-0.222
48.00,152.72,-0.222
48.02,152.55,-0.222
48.04,152.38,-0.222
48.05,152.22,-0.222
48.07,152.05,-0.222
48.09,151.88,-0.222
48.10,151.72,-0.222
48.12,151.55,-0.222
48.14,151.38,-0.222
48.15,151.22,-0.222
48.17,151.05,-0.222
48.19,150.89,-0.222
48.20,150.72,-0.222
48.22,150.55,-0.222
48.24,150.39,-0.222
48.25,150.22,-0.222
48.27,150.05,-0.222
48.29,149.89,-0.222
48.30,149.72,-0.222
48.32,149.55,-0.222
48.34,149.39,-0.222
48.35,149.22,-0.222
48.37,149.06,-0.222
48.39,148.89,-0.222
48.40,148.72,-0.222
48.42,148.56,-0.222
48.44,148.39,-0.222
48.45,148.22,-0.222
48.47,148.06,-0.222
48.49,147.89,-0.222
48.50,147.72,-0.222
48.52,147.56,-0.222
48.54,147.39,-0.222
48.55,147.22,-0.222
48.57,147.06,-0.222
48.59,146.89,-0.222
48.60,146.72,-0.222
48.62,146.56,-0.222
48.64,146.39,-0.222
48.65,146.23,-0.222
48.67,146.06,-0.222
48.69,145.89,-0.222
48.70,145.72,-0.222
48.72,145.56,-0.222
48.74,145.39,-0.222
48.75,145.23,-0.222
48.77,145.06,-0.222
48.79,144.89,-0.222
48.80,144.73,-0.222
48.82,144.56,-0.222
48.84,144.39,-0.222
48.85,144.23,-0.222
48.87,144.06,-0.222
48.89,143.89,-0.222
48.90,143.73,-0.222
48.92,143.56,-0.222
48.94,143.39,-0.222
48.95,143.23,-0.222
48.97,143.06,-0.222
48.99,142.90,-0.222
49.00,142.73,-0.222
49.02,142.56,-0.222
49.04,142.40,-0.222
49.05,142.23,-0.222
49.07,142.06,-0.222
49.09,141.90,-0.222
49.10,141.73,-0.222
49.12,141.56,-0.222
49.14,141.40,-0.222
49.15,141.23,-0.222
49.17,141.07,-0.222
49.19,140.90,-0.221
49.20,140.73,-0.221
49.22,140.57,-0.221
49.24,140.40,-0.221
49.25,140.23,-0.221
49.27,140.07,-0.221
49.29,139.90,-0.221
49.30,139.73,-0.221
49.32,139.57,-0.221
49.34,139.40,-0.221
49.35,139.23,-0.221
49.37,139.07,-0.221
49.39,138.90,-0.221
49.40,138.74,-0.221
49.42,138.57,-0.221
49.44,138.40,-0.221
49.45,138.24,-0.221
49.47,138.07,-0.221
49.49,137.90,-0.221
49.50,137.74,-0.221
49.52,137.57,-0.221
49.54,137.40,-0.221
49.55,137.24,-0.221
49.57,137.07,-0.221
49.59,136.91,-0.221
49.60,136.74,-0.221
49.62,136.57,-0.221
49.64,136.40,-0.221
49.65,136.24,-0.221
49.67,136.07,-0.221
49.69,135.91,-0.221
49.70,135.74,-0.221
49.72,135.57,-0.221
49.74,135.41,-0.221
49.75,135.24,-0.221
49.77,135.07,-0.221
49.79,134.91,-0.221
49.80,134.74,-0.221
49.82,134.57,-0.221
49.84,134.41,-0.221
49.85,134.24,-0.221
49.87,134.08,-0.220
49.89,133.91,-0.220
49.90,133.74,-0.220
49.92,133.58,-0.220
49.94,133.41,-0.220
49.95,133.24,-0.220
49.97,133.08,-0.220
49.99,132.91,-0.220
50.00,132.74,-0.220
50.02,132.58,-0.220
50.04,132.41,-0.220
50.05,132.25,-0.220
50.07,132.08,-0.220
50.09,131.91,-0.220
50.10,131.75,-0.220
50.12,131.58,-0.220
50.14,131.41,-0.220
50.15,131.24,-0.220
50.17,131.08,-0.220
50.19,130.91,-0.220
50.20,130.75,-0.220
50.22,130.58,-0.220
50.24,130.41,-0.220
50.25,130.25,-0.220
50.27,130.08,-0.220
50.29,129.91,-0.220
50.30,129.75,-0.219
50.32,129.58,-0.219
50.34,129.41,-0.219
50.35,129.25,-0.219
50.37,129.08,-0.219
50.39,128.91,-0.219
50.40,128.75,-0.219
50.42,128.58,-0.219
50.44,128.42,-0.219
50.45,128.25,-0.219
50.47,128.08,-0.219
50.49,127.92,-0.219
50.50,127.75,-0.219
50.52,127.58,-0.219
50.54,127.42,-0.219
50.55,127.25,-0.219
50.57,127.08,-0.219
50.59,126.92,-0.219
50.60,126.75,-0.219
50.62,126.58,-0.219
50.64,126.42,-0.219
50.65,126.25,-0.219
50.67,126.09,-0.219
50.69,125.92,-0.219
50.70,125.75,-0.219
50.72,125.59,-0.219
50.74,125.42,-0.218
50.75,125.25,-0.218
50.77,125.09,-0.218
50.79,124.92,-0.218
50.80,124.75,-0.218
50.82,124.59,-0.219
50.84,124.42,-0.218
50.85,124.25,-0.218
50.87,124.09,-0.218
50.89,123.92,-0.218
50.90,123.75,-0.218
50.92,123.59,-0.218
50.94,123.42,-0.218
50.95,123.25,-0.218
50.97,123.09,-0.218
50.99,122.92,-0.218
51.00,122.75,-0.218
51.02,122.59,-0.218
51.04,122.42,-0.218
51.05,122.26,-0.218
51.07,122.09,-0.218
51.09,121.92,-0.218
51.10,121.76,-0.218
51.12,121.59,-0.218
51.14,121.42,-0.218
51.15,121.26,-0.218
51.17,121.09,-0.218
51.19,120.92,-0.218
51.20,120.76,-0.218
51.22,120.59,-0.218
51.24,120.42,-0.218
51.25,120.26,-0.217
51.27,120.09,-0.217
51.29,119.93,-0.217
51.30,119.76,-0.217
51.32,119.59,-0.217
51.34,119.42,-0.217
51.35,119.26,-0.217
51.37,119.09,-0.217
51.39,118.93,-0.217
51.40,118.76,-0.217
51.42,118.59,-0.217
51.44,118.43,-0.217
51.45,118.26,-0.217
51.47,118.10,-0.217
51.49,117.93,-0.217
51.50,117.76,-0.217
51.52,117.60,-0.217
51.54,117.43,-0.217
51.55,117.26,-0.217
51.57,117.10,-0.217
51.59,116.93,-0.217
51.60,116.76,-0.217
51.62,116.60,-0.217
51.64,116.43,-0.217
51.65,116.26,-0.217
51.67,116.10,-0.217
51.69,115.93,-0.217
51.70,115.76,-0.217
51.72,115.60,-0.217
51.74,115.43,-0.217
51.75,115.26,-0.217
51.77,115.10,-0.216
51.79,114.93,-0.216
51.80,114.77,-0.216
51.82,114.60,-0.216
51.84,114.43,-0.216
51.85,114.26,-0.216
51.87,114.10,-0.216
51.89,113.93,-0.216
51.90,113.77,-0.216
51.92,113.60,-0.216
51.94,113.43,-0.216
51.95,113.27,-0.216
51.97,113.10,-0.216
51.99,112.93,-0.216
52.00,112.77,-0.216
52.02,112.60,-0.216
52.04,112.43,-0.216
52.05,112.27,-0.216
52.07,112.10,-0.215
[...]
144.38,-39.83,0.014
144.39,-39.76,0.014
144.40,-39.69,0.014
144.42,-39.63,0.014
144.43,-39.56,0.014
144.44,-39.49,0.014
144.46,-39.43,0.014
144.47,-39.36,0.014
144.48,-39.29,0.014
144.50,-39.23,0.014
144.51,-39.16,0.014
144.52,-39.09,0.014
144.54,-39.03,0.014
144.55,-38.96,0.015
144.56,-38.89,0.015
144.58,-38.83,0.015
144.59,-38.76,0.015
144.60,-38.69,0.015
144.62,-38.63,0.015
144.63,-38.56,0.015
144.64,-38.49,0.015
144.66,-38.43,0.015
144.67,-38.36,0.015
144.68,-38.29,0.015
144.70,-38.23,0.015
144.71,-38.16,0.015
144.72,-38.09,0.015
144.74,-38.03,0.015
144.75,-37.96,0.015
144.76,-37.89,0.015
144.78,-37.82,0.015
144.79,-37.76,0.015
144.80,-37.69,0.015
144.82,-37.63,0.015
144.83,-37.56,0.015
144.84,-37.49,0.015
144.86,-37.43,0.015
144.87,-37.36,0.015
144.88,-37.29,0.015
144.90,-37.22,0.015
144.91,-37.16,0.015
144.92,-37.09,0.015
144.94,-37.02,0.015
144.95,-36.96,0.015
144.96,-36.89,0.015
144.98,-36.82,0.015
144.99,-36.76,0.015
145.00,-36.69,0.015
145.02,-36.62,0.015
145.03,-36.55,0.015
145.04,-36.49,0.015
145.06,-36.42,0.015
145.07,-36.36,0.015
145.08,-36.29,0.015
145.10,-36.22,0.015
145.11,-36.16,0.015
145.12,-36.09,0.015
145.14,-36.02,0.015
145.15,-35.96,0.015
145.16,-35.89,0.015
145.18,-35.82,0.015
145.19,-35.76,0.015
145.20,-35.69,0.015
145.22,-35.62,0.015
145.23,-35.56,0.015
145.24,-35.49,0.015
145.26,-35.42,0.015
145.27,-35.36,0.015
145.28,-35.29,0.015
145.30,-35.22,0.016
145.31,-35.16,0.015
145.32,-35.09,0.015
145.34,-35.02,0.016
145.35,-34.96,0.016
145.36,-34.89,0.016
145.38,-34.82,0.016
145.39,-34.76,0.016
145.40,-34.69,0.016
145.42,-34.62,0.016
145.43,-34.56,0.016
145.44,-34.49,0.016
145.46,-34.42,0.016
145.47,-34.36,0.016
145.48,-34.29,0.016
145.50,-34.22,0.016
145.51,-34.16,0.016
145.52,-34.09,0.016
145.54,-34.02,0.016
145.55,-33.96,0.016
145.56,-33.89,0.016
145.58,-33.82,0.016
145.59,-33.76,0.016
145.60,-33.69,0.016
145.62,-33.62,0.016
145.63,-33.56,0.016
145.64,-33.49,0.016
145.66,-33.42,0.016
145.67,-33.36,0.016
145.68,-33.29,0.016
145.70,-33.22,0.016
145.71,-33.15,0.016
145.72,-33.09,0.016
145.74,-33.02,0.016
145.75,-32.96,0.016
145.76,-32.89,0.016
145.78,-32.82,0.016
145.79,-32.75,0.016
145.80,-32.69,0.016
145.82,-32.62,0.016
145.83,-32.55,0.016
145.84,-32.49,0.016
145.86,-32.42,0.016
145.87,-32.35,0.016
145.88,-32.29,0.016
145.90,-32.22,0.016
145.91,-32.15,0.016
145.92,-32.09,0.016
145.94,-32.02,0.016
145.95,-31.95,0.016
145.96,-31.89,0.016
145.98,-31.82,0.016
145.99,-31.75,0.016
146.00,-31.69,0.016
146.02,-31.62,0.016
146.03,-31.55,0.016
146.04,-31.49,0.016
146.06,-31.42,0.016
146.07,-31.35,0.016
146.08,-31.29,0.016
146.10,-31.22,0.016
146.11,-31.15,0.016
146.12,-31.09,0.016
146.14,-31.02,0.016
146.15,-30.95,0.016
146.16,-30.89,0.016
146.18,-30.82,0.016
146.19,-30.75,0.016
146.20,-30.69,0.016
146.22,-30.62,0.016
146.23,-30.55,0.017
146.24,-30.49,0.017
146.26,-30.42,0.017
146.27,-30.35,0.017
146.28,-30.29,0.017
146.30,-30.22,0.017
146.31,-30.15,0.017
146.32,-30.09,0.017
146.34,-30.02,0.017
146.35,-29.95,0.017
146.36,-29.89,0.017
146.38,-29.82,0.017
146.39,-29.75,0.017
146.40,-29.69,0.017
146.42,-29.62,0.017
146.43,-29.55,0.017
146.44,-29.49,0.017
146.46,-29.42,0.017
146.47,-29.35,0.017
146.48,-29.29,0.017
146.50,-29.22,0.017
146.51,-29.15,0.017
146.52,-29.09,0.017
146.54,-29.02,0.017
146.55,-28.95,0.017
146.56,-28.89,0.017
146.58,-28.82,0.017
146.59,-28.75,0.017
146.60,-28.69,0.017
146.62,-28.62,0.017
146.63,-28.55,0.017
146.64,-28.49,0.017
146.66,-28.42,0.017
146.67,-28.35,0.017
146.68,-28.29,0.017
146.70,-28.22,0.017
146.71,-28.15,0.017
146.72,-28.08,0.017
146.74,-28.02,0.017
146.75,-27.95,0.017
146.76,-27.88,0.017
146.78,-27.82,0.017
146.79,-27.75,0.017
146.80,-27.68,0.017
146.82,-27.62,0.017
146.83,-27.55,0.017
146.84,-27.48,0.017
146.86,-27.42,0.017
146.87,-27.35,0.017
146.88,-27.28,0.017
146.90,-27.22,0.017
146.91,-27.15,0.017
146.92,-27.08,0.017
146.94,-27.02,0.017
146.95,-26.95,0.017
146.96,-26.88,0.017
146.98,-26.82,0.017
146.99,-26.75,0.017
147.00,-26.68,0.017
147.02,-26.62,0.017
147.03,-26.55,0.017
147.04,-26.48,0.017
147.06,-26.42,0.017
147.07,-26.35,0.017
147.08,-26.28,0.018
147.10,-26.22,0.018
147.11,-26.15,0.018
147.12,-26.08,0.018
147.14,-26.02,0.018
147.15,-25.95,0.018
147.16,-25.88,0.018
147.18,-25.81,0.018
147.19,-25.75,0.018
147.20,-25.68,0.018
147.22,-25.61,0.018
147.23,-25.55,0.018
147.24,-25.48,0.018
147.26,-25.42,0.018
147.27,-25.35,0.018
147.28,-25.28,0.018
147.30,-25.21,0.018
147.31,-25.15,0.018
147.32,-25.08,0.018
147.34,-25.02,0.018
147.35,-24.95,0.018
147.36,-24.88,0.018
147.38,-24.81,0.018
147.39,-24.75,0.018
147.40,-24.68,0.018
147.42,-24.61,0.018
147.43,-24.55,0.018
147.44,-24.48,0.018
147.46,-24.41,0.018
147.47,-24.35,0.018
147.48,-24.28,0.018
147.50,-24.21,0.018
147.51,-24.15,0.018
147.52,-24.08,0.018
147.54,-24.01,0.018
147.55,-23.95,0.018
147.56,-23.88,0.018
147.58,-23.82,0.018
147.59,-23.75,0.018
147.60,-23.68,0.018
147.62,-23.61,0.018
147.63,-23.55,0.018
147.64,-23.48,0.018
147.66,-23.41,0.018
147.67,-23.35,0.018
147.68,-23.28,0.018
147.70,-23.21,0.018
147.71,-23.15,0.018
147.72,-23.08,0.018
147.74,-23.01,0.018
147.75,-22.95,0.018
147.76,-22.88,0.018
147.78,-22.81,0.018
147.79,-22.75,0.018
147.80,-22.68,0.018
147.82,-22.61,0.018
147.83,-22.55,0.018
147.84,-22.48,0.018
147.86,-22.41,0.018
147.87,-22.35,0.018
147.88,-22.28,0.018
147.90,-22.21,0.018
147.91,-22.15,0.018
147.92,-22.08,0.018
147.94,-22.01,0.018
147.95,-21.95,0.018
147.96,-21.88,0.018
147.98,-21.81,0.018
147.99,-21.74,0.018
148.00,-21.68,0.019
148.02,-21.61,0.019
148.03,-21.55,0.019
148.04,-21.48,0.019
148.06,-21.41,0.019
148.07,-21.35,0.019
148.08,-21.28,0.019
148.10,-21.21,0.019
148.11,-21.14,0.019
148.12,-21.08,0.019
148.14,-21.01,0.019
148.15,-20.94,0.019
148.16,-20.88,0.019
148.18,-20.81,0.019
148.19,-20.75,0.019
148.20,-20.68,0.019
148.22,-20.61,0.019
148.23,-20.54,0.019
148.24,-20.48,0.019
148.26,-20.41,0.019
148.27,-20.34,0.019
148.28,-20.28,0.019
148.30,-20.21,0.019
148.31,-20.14,0.019
148.32,-20.08,0.019
148.34,-20.01,0.019
148.35,-19.94,0.019
148.36,-19.88,0.019
148.38,-19.81,0.019
148.39,-19.74,0.019
148.40,-19.68,0.019
148.42,-19.61,0.019
148.43,-19.55,0.019
148.44,-19.48,0.019
148.46,-19.41,0.019
148.47,-19.34,0.019
148.48,-19.28,0.019
148.50,-19.21,0.019
148.51,-19.14,0.019
148.52,-19.08,0.019
148.54,-19.01,0.019
148.55,-18.94,0.019
148.56,-18.88,0.019
148.58,-18.81,0.019
148.59,-18.74,0.019
148.60,-18.68,0.019
148.62,-18.61,0.019
148.63,-18.54,0.019
148.64,-18.48,0.019
148.66,-18.41,0.019
148.67,-18.34,0.019
148.68,-18.28,0.019
148.70,-18.21,0.019
148.71,-18.14,0.019
148.72,-18.08,0.019
148.74,-18.01,0.020
148.75,-17.94,0.020
148.76,-17.88,0.020
148.78,-17.81,0.020
148.79,-17.74,0.020
148.80,-17.68,0.020
148.82,-17.61,0.020
148.83,-17.54,0.020
148.84,-17.48,0.020
148.86,-17.41,0.020
148.87,-17.34,0.020
148.88,-17.28,0.020
148.90,-17.21,0.020
148.91,-17.14,0.020
148.92,-17.08,0.020
148.94,-17.01,0.020
148.95,-16.94,0.020
148.96,-16.88,0.020
148.98,-16.81,0.020
148.99,-16.74,0.020
149.00,-16.68,0.020
149.02,-16.61,0.020
149.03,-16.54,0.020
149.04,-16.48,0.020
149.06,-16.41,0.020
149.07,-16.34,0.020
149.08,-16.28,0.020
149.10,-16.21,0.020
149.11,-16.14,0.020
149.12,-16.08,0.020
149.14,-16.01,0.020
149.15,-15.94,0.020
149.16,-15.88,0.020
149.18,-15.81,0.020
149.19,-15.74,0.020
149.20,-15.67,0.020
149.22,-15.61,0.020
149.23,-15.54,0.020
149.24,-15.47,0.020
149.26,-15.41,0.020
149.27,-15.34,0.020
149.28,-15.27,0.020
149.30,-15.21,0.020
149.31,-15.14,0.020
149.32,-15.07,0.020
149.34,-15.01,0.020
149.35,-14.94,0.020
149.36,-14.87,0.020
149.38,-14.81,0.020
149.39,-14.74,0.020
149.40,-14.68,0.021
149.42,-14.61,0.021
149.43,-14.54,0.021
149.44,-14.48,0.021
149.46,-14.41,0.021
149.47,-14.34,0.021
149.48,-14.28,0.021
149.50,-14.21,0.021
149.51,-14.14,0.021
149.52,-14.08,0.021
149.54,-14.01,0.021
149.55,-13.94,0.021
149.56,-13.88,0.021
149.58,-13.81,0.021
149.59,-13.74,0.021
149.60,-13.67,0.021
149.62,-13.61,0.021
149.63,-13.54,0.021
149.64,-13.47,0.021
149.66,-13.41,0.021
149.67,-13.34,0.021
149.68,-13.28,0.021
149.70,-13.21,0.021
149.71,-13.14,0.021
149.72,-13.07,0.021
149.74,-13.01,0.021
149.75,-12.94,0.021
149.76,-12.87,0.021
149.78,-12.81,0.021
149.79,-12.74,0.021
149.80,-12.67,0.021
149.82,-12.61,0.021
149.83,-12.54,0.021
149.84,-12.47,0.021
149.86,-12.41,0.021
149.87,-12.34,0.021
149.88,-12.27,0.021
149.90,-12.21,0.021
149.91,-12.14,0.021
149.92,-12.07,0.021
149.94,-12.01,0.021
149.95,-11.94,0.021
149.96,-11.87,0.021
149.98,-11.81,0.021
149.99,-11.74,0.021
150.00,-11.67,0.021
150.02,-11.61,0.021
150.03,-11.54,0.021
150.04,-11.47,0.021
150.06,-11.41,0.021
150.07,-11.34,0.021
150.08,-11.27,0.021
150.10,-11.21,0.021
150.11,-11.14,0.021
150.12,-11.07,0.021
150.14,-11.01,0.021
150.15,-10.94,0.021
150.16,-10.87,0.021
150.18,-10.81,0.021
150.19,-10.74,0.021
150.20,-10.67,0.021
150.22,-10.61,0.022
150.23,-10.54,0.022
150.24,-10.47,0.022
150.26,-10.41,0.022
150.27,-10.34,0.022
150.28,-10.27,0.022
150.30,-10.21,0.022
150.31,-10.14,0.022
150.32,-10.07,0.022
150.34,-10.01,0.022
150.35,-9.94,0.022
150.36,-9.87,0.022
150.38,-9.80,0.022
150.39,-9.74,0.022
150.40,-9.67,0.022
150.42,-9.60,0.022
150.43,-9.54,0.022
150.44,-9.47,0.022
150.46,-9.41,0.022
150.47,-9.34,0.022
150.48,-9.27,0.022
150.50,-9.20,0.022
150.51,-9.14,0.022
150.52,-9.07,0.022
150.54,-9.00,0.022
150.55,-8.94,0.022
150.56,-8.87,0.022
150.58,-8.80,0.022
150.59,-8.74,0.022
150.60,-8.67,0.022
150.62,-8.60,0.022
150.63,-8.54,0.022
150.64,-8.47,0.022
150.66,-8.41,0.022
150.67,-8.34,0.022
150.68,-8.27,0.022
150.70,-8.21,0.022
150.71,-8.14,0.022
150.72,-8.07,0.022
150.74,-8.00,0.022
150.75,-7.94,0.022
150.76,-7.87,0.022
150.78,-7.81,0.022
150.79,-7.74,0.022
150.80,-7.67,0.022
150.82,-7.60,0.022
150.83,-7.54,0.022
150.84,-7.47,0.022
150.86,-7.40,0.022
150.87,-7.34,0.022
150.88,-7.27,0.023
150.90,-7.20,0.023
150.91,-7.14,0.023
150.92,-7.07,0.023
150.94,-7.00,0.023
150.95,-6.94,0.023
150.96,-6.87,0.023
150.98,-6.80,0.023
150.99,-6.74,0.023
151.00,-6.67,0.023
151.02,-6.60,0.023
151.03,-6.54,0.023
151.04,-6.47,0.023
151.06,-6.40,0.023
151.07,-6.34,0.023
151.08,-6.27,0.023
151.10,-6.20,0.023
151.11,-6.14,0.023
151.12,-6.07,0.023
151.14,-6.00,0.023
151.15,-5.94,0.023
151.16,-5.87,0.023
151.18,-5.80,0.023
151.19,-5.74,0.023
151.20,-5.67,0.023
151.22,-5.60,0.023
151.23,-5.54,0.023
151.24,-5.47,0.023
151.26,-5.40,0.023
151.27,-5.34,0.023
151.28,-5.27,0.023
151.30,-5.20,0.023
151.31,-5.14,0.023
151.32,-5.07,0.023
151.34,-5.00,0.023
151.35,-4.94,0.023
151.36,-4.87,0.024
151.38,-4.80,0.024
151.39,-4.74,0.024
151.40,-4.67,0.024
151.42,-4.60,0.024
151.43,-4.53,0.024
151.44,-4.47,0.024
151.46,-4.40,0.024
151.47,-4.34,0.024
151.48,-4.27,0.024
151.50,-4.20,0.024
151.51,-4.14,0.024
151.52,-4.07,0.024
151.54,-4.00,0.024
151.55,-3.94,0.024
151.56,-3.87,0.024
151.58,-3.80,0.024
151.59,-3.73,0.024
151.60,-3.67,0.024
151.62,-3.60,0.024
151.63,-3.53,0.024
151.64,-3.47,0.024
151.66,-3.40,0.024
151.67,-3.33,0.024
151.68,-3.27,0.024
151.70,-3.20,0.024
151.71,-3.13,0.024
151.72,-3.07,0.024
151.74,-3.00,0.024
151.75,-2.93,0.024
151.76,-2.87,0.024
151.78,-2.80,0.024
151.79,-2.73,0.024
151.80,-2.67,0.024
151.82,-2.60,0.024
151.83,-2.53,0.024
151.84,-2.47,0.024
151.86,-2.40,0.024
151.87,-2.33,0.024
151.88,-2.27,0.024
151.90,-2.20,0.024
151.91,-2.13,0.024
151.92,-2.07,0.024
151.94,-2.00,0.024
151.95,-1.93,0.024
151.96,-1.87,0.024
151.98,-1.80,0.024
151.99,-1.73,0.024
152.00,-1.66,0.024
152.02,-1.60,0.025
152.03,-1.53,0.025
152.04,-1.47,0.025
152.06,-1.40,0.025
152.07,-1.33,0.025
152.08,-1.27,0.025
152.10,-1.20,0.025
152.11,-1.14,0.025
152.12,-1.07,0.025
152.14,-1.00,0.025
152.15,-0.93,0.025
152.16,-0.87,0.025
152.18,-0.80,0.025
152.19,-0.73,0.025
152.20,-0.67,0.025
152.22,-0.60,0.025
152.23,-0.53,0.025
152.24,-0.47,0.025
152.26,-0.40,0.025
152.27,-0.33,0.025
152.28,-0.27,0.025
152.30,-0.20,0.025
152.31,-0.13,0.025
152.32,-0.07,0.025
152.34,0.00,0.025
152.35,0.07,0.025
152.36,0.13,0.025
152.38,0.20,0.025
152.39,0.27,0.025
152.40,0.33,0.025
152.42,0.40,0.025
152.43,0.47,0.025
152.44,0.53,0.025
152.46,0.60,0.025
152.47,0.67,0.025
152.48,0.73,0.025
152.50,0.80,0.025
152.51,0.87,0.025
152.52,0.94,0.025
152.54,1.00,0.025
152.55,1.07,0.025
152.56,1.13,0.025
152.58,1.20,0.025
152.59,1.27,0.025
152.60,1.33,0.025
152.62,1.40,0.026
152.63,1.47,0.026
152.64,1.53,0.026
152.66,1.60,0.026
152.67,1.67,0.026
152.68,1.73,0.026
152.70,1.80,0.026
152.71,1.87,0.026
152.72,1.93,0.026
152.74,2.00,0.026
152.75,2.07,0.026
152.76,2.13,0.026
152.78,2.20,0.026
152.79,2.27,0.026
152.80,2.33,0.026
152.82,2.40,0.026
152.83,2.47,0.026
152.84,2.54,0.026
152.86,2.60,0.026
152.87,2.67,0.026
152.88,2.73,0.026
152.90,2.80,0.026
152.91,2.87,0.026
152.92,2.93,0.026
152.94,3.00,0.026
152.95,3.07,0.026
152.96,3.13,0.026
152.98,3.20,0.026
152.99,3.27,0.027
153.00,3.34,0.027
153.02,3.40,0.027
153.03,3.47,0.027
153.04,3.54,0.027
153.06,3.60,0.027
153.07,3.67,0.027
153.08,3.74,0.027
153.10,3.80,0.027
153.11,3.87,0.027
153.12,3.94,0.027
153.14,4.00,0.027
153.15,4.07,0.027
153.16,4.13,0.027
153.18,4.20,0.027
153.19,4.27,0.027
153.20,4.34,0.027
153.22,4.40,0.027
153.23,4.47,0.027
153.24,4.53,0.027
153.26,4.60,0.027
153.27,4.67,0.027
153.28,4.74,0.027
153.30,4.80,0.027
153.31,4.87,0.027
153.32,4.94,0.027
153.34,5.00,0.027
153.35,5.07,0.027
153.36,5.14,0.027
153.38,5.20,0.027
153.39,5.27,0.027
153.40,5.34,0.027
153.42,5.40,0.027
153.43,5.47,0.027
153.44,5.54,0.027
153.46,5.60,0.027
153.47,5.67,0.027
153.48,5.74,0.027
153.50,5.80,0.027
153.51,5.87,0.028
153.52,5.94,0.028
153.54,6.00,0.028
153.55,6.07,0.028
153.56,6.14,0.028
153.58,6.20,0.028
153.59,6.27,0.028
153.60,6.34,0.028
153.62,6.40,0.028
153.63,6.47,0.028
153.64,6.54,0.028
153.66,6.60,0.028
153.67,6.67,0.028
153.68,6.74,0.028
153.70,6.80,0.028
153.71,6.87,0.028
153.72,6.94,0.029
153.74,7.00,0.029
153.75,7.07,0.029
153.76,7.14,0.029
153.78,7.20,0.029
153.79,7.27,0.029
153.80,7.34,0.029
153.82,7.41,0.029
153.83,7.47,0.029
153.84,7.54,0.029
153.86,7.60,0.029
153.87,7.67,0.029
153.88,7.74,0.029
153.90,7.80,0.029
153.91,7.87,0.029
153.92,7.94,0.029
153.94,8.00,0.029
153.95,8.07,0.029
153.96,8.14,0.029
153.98,8.20,0.029
153.99,8.27,0.029
154.00,8.34,0.029
154.02,8.40,0.029
154.03,8.47,0.029
154.04,8.54,0.029
154.06,8.60,0.029
154.07,8.67,0.029
154.08,8.74,0.029
154.10,8.80,0.030
154.11,8.87,0.030
154.12,8.94,0.030
154.14,9.00,0.030
154.15,9.07,0.030
154.16,9.14,0.030
154.18,9.20,0.030
154.19,9.27,0.030
154.20,9.34,0.030
154.22,9.41,0.030
154.23,9.47,0.031
154.24,9.54,0.031
154.26,9.60,0.031
154.27,9.67,0.031
154.28,9.74,0.031
154.30,9.80,0.031
154.31,9.87,0.031
154.32,9.94,0.031
154.34,10.01,0.031
154.35,10.07,0.031
154.36,10.14,0.031
154.38,10.21,0.031
154.39,10.27,0.031
154.40,10.34,0.031
154.42,10.41,0.032
154.43,10.47,0.032
154.44,10.54,0.032
154.46,10.61,0.032
154.47,10.67,0.032
154.48,10.74,0.032
154.50,10.80,0.032
154.51,10.87,0.032
154.52,10.94,0.032
154.54,11.01,0.032
154.55,11.07,0.032
154.56,11.14,0.032
154.58,11.21,0.032
154.59,11.27,0.033
154.60,11.34,0.033
154.62,11.41,0.033
154.63,11.47,0.033
154.64,11.54,0.033
154.66,11.61,0.033
154.67,11.67,0.033
154.68,11.74,0.033
154.70,11.81,0.033
154.71,11.87,0.033
154.72,11.94,0.034
154.74,12.00,0.034
154.75,12.07,0.034
154.76,12.14,0.034
154.78,12.20,0.034
154.79,12.27,0.034
154.80,12.34,0.034
154.82,12.40,0.035
154.83,12.47,0.035
154.84,12.54,0.035
154.86,12.60,0.035
154.87,12.67,0.035
154.88,12.74,0.035
154.90,12.80,0.035
154.91,12.87,0.035
154.92,12.94,0.035
154.94,13.00,0.035
154.95,13.07,0.036
154.96,13.14,0.036
154.98,13.20,0.036
154.99,13.27,0.036
155.00,13.34,0.036
155.02,13.40,0.036
155.03,13.47,0.036
155.04,13.54,0.036
155.06,13.60,0.037
155.07,13.67,0.037
155.08,13.74,0.037
155.10,13.80,0.037
155.11,13.87,0.037
155.12,13.94,0.037
155.14,14.00,0.038
155.15,14.07,0.038
155.16,14.14,0.038
155.18,14.20,0.038
155.19,14.27,0.038
155.20,14.34,0.038
155.22,14.40,0.039
155.23,14.47,0.039
155.24,14.53,0.039
155.26,14.60,0.039
155.27,14.67,0.039
155.28,14.74,0.039
155.30,14.80,0.040
155.31,14.87,0.040
155.32,14.94,0.040
155.34,15.00,0.040
155.35,15.07,0.040
155.36,15.14,0.041
155.38,15.20,0.041
155.39,15.27,0.041
155.40,15.33,0.041
155.42,15.40,0.041
155.43,15.47,0.041
155.44,15.53,0.042
155.46,15.60,0.042
155.47,15.67,0.042
155.48,15.73,0.042
155.50,15.80,0.042
155.51,15.87,0.043
155.52,15.93,0.043
155.54,16.00,0.043
155.55,16.07,0.043
155.56,16.13,0.043
155.58,16.20,0.044
155.59,16.27,0.044
155.60,16.33,0.044
155.62,16.40,0.044
155.63,16.47,0.044
155.64,16.53,0.045
155.66,16.60,0.045
155.67,16.66,0.045
155.68,16.73,0.046
155.70,16.80,0.046
155.71,16.86,0.046
155.72,16.93,0.046
155.74,17.00,0.046
155.75,17.07,0.047
155.76,17.13,0.047
155.78,17.20,0.047
155.79,17.27,0.047
155.80,17.33,0.048
155.82,17.40,0.048
155.83,17.47,0.048
155.84,17.53,0.048
155.86,17.60,0.048
155.87,17.66,0.049
155.88,17.73,0.049
155.90,17.80,0.049
155.91,17.86,0.049
155.92,17.93,0.049
155.94,18.00,0.050
155.95,18.06,0.050
155.96,18.13,0.050
155.98,18.20,0.050
155.99,18.26,0.050
156.00,18.33,0.050
156.02,18.40,0.051
156.03,18.46,0.051
156.04,18.53,0.051
156.06,18.60,0.051
156.07,18.66,0.051
156.08,18.73,0.051
156.10,18.80,0.052
156.11,18.86,0.052
156.12,18.93,0.052
156.14,19.00,0.052
156.15,19.06,0.052
156.16,19.13,0.052
156.18,19.20,0.052
156.19,19.26,0.052
156.20,19.33,0.052
156.22,19.40,0.053
156.23,19.46,0.053
156.24,19.53,0.053
156.26,19.60,0.053
156.27,19.66,0.053
156.28,19.73,0.053
156.30,19.80,0.053
156.31,19.86,0.053
156.32,19.93,0.053
156.34,20.00,0.053
156.35,20.06,0.053
156.36,20.13,0.054
156.38,20.20,0.054
156.39,20.26,0.054
156.40,20.33,0.054
156.42,20.40,0.054
156.43,20.47,0.054
156.44,20.53,0.054
156.46,20.60,0.054
156.47,20.66,0.054
156.48,20.73,0.054
156.50,20.80,0.054
156.51,20.86,0.054
156.52,20.93,0.054
156.54,21.00,0.054
156.55,21.06,0.054
156.56,21.13,0.054
156.58,21.20,0.054
156.59,21.26,0.054
156.60,21.33,0.054
156.62,21.40,0.054
156.63,21.46,0.054
156.64,21.53,0.054
156.66,21.60,0.054
156.67,21.67,0.054
156.68,21.73,0.054
156.70,21.80,0.054
156.71,21.87,0.054
156.72,21.93,0.054
156.74,22.00,0.054
156.75,22.07,0.054
156.76,22.13,0.054
156.78,22.20,0.054
156.79,22.27,0.054
156.80,22.33,0.054
156.82,22.40,0.054
156.83,22.47,0.054
156.84,22.53,0.054
156.86,22.60,0.054
156.87,22.67,0.054
156.88,22.73,0.054
156.90,22.80,0.054
156.91,22.87,0.054
156.92,22.93,0.054
156.94,23.00,0.054
156.95,23.07,0.054
156.96,23.13,0.054
156.98,23.20,0.054
156.99,23.27,0.054
157.00,23.33,0.054
157.02,23.40,0.054
157.03,23.47,0.054
157.04,23.53,0.054
157.06,23.60,0.054
157.07,23.67,0.054
157.08,23.73,0.054
157.10,23.80,0.054
157.11,23.87,0.055
157.12,23.93,0.055
157.14,24.00,0.055
157.15,24.07,0.055
157.16,24.13,0.054
157.18,24.20,0.054
157.19,24.27,0.054
157.20,24.34,0.054
157.22,24.40,0.054
157.23,24.47,0.054
157.24,24.53,0.054
157.26,24.60,0.054
157.27,24.67,0.054
157.28,24.73,0.055
157.30,24.80,0.055
157.31,24.87,0.055
157.32,24.94,0.055
157.34,25.00,0.055
157.35,25.07,0.055
157.36,25.13,0.055
157.38,25.20,0.055
157.39,25.27,0.055
157.40,25.33,0.055
157.42,25.40,0.055
157.43,25.47,0.055
157.44,25.54,0.055
157.46,25.60,0.055
157.47,25.67,0.055
157.48,25.74,0.055
157.50,25.80,0.055
157.51,25.87,0.055
157.52,25.94,0.055
157.54,26.00,0.055
157.55,26.07,0.055
157.56,26.14,0.055
157.58,26.20,0.055
157.59,26.27,0.055
157.60,26.34,0.055
157.62,26.40,0.055
157.63,26.47,0.055
157.64,26.54,0.055
157.66,26.60,0.055
157.67,26.67,0.055
157.68,26.74,0.055
157.70,26.80,0.055
157.71,26.87,0.055
157.72,26.94,0.055
157.74,27.00,0.055
157.75,27.07,0.055
157.76,27.14,0.055
157.78,27.20,0.055
157.79,27.27,0.055
157.80,27.34,0.055
157.82,27.40,0.055
157.83,27.47,0.055
157.84,27.54,0.055
157.86,27.60,0.056
157.87,27.67,0.056
157.88,27.74,0.056
157.90,27.80,0.056
157.91,27.87,0.056
157.92,27.94,0.056
157.94,28.00,0.056
157.95,28.07,0.056
157.96,28.14,0.056
157.98,28.20,0.056
157.99,28.27,0.056
158.00,28.34,0.056
158.02,28.40,0.056
158.03,28.47,0.056
158.04,28.54,0.056
158.06,28.60,0.056
158.07,28.67,0.056
158.08,28.74,0.056
158.10,28.80,0.056
158.11,28.87,0.056
158.12,28.94,0.056
158.14,29.00,0.056
158.15,29.07,
158.16,29.14,
158.18,29.20,
158.19,29.27,
158.20,,