File: DSC/2025_06_16_Adamantane_n90C_30C_10Cmin_5Cmin_2Cmin.csv
Filename,2025_06_16_Adamantane_n90C_30C_10Cmin_5Cmin_2Cmin
Instrument name,DSC2A-00468 (192.168.1.100)
Operator,Gibbons
rundate,6/16/2025
Sample name,2025_06_16_Adamantane_n90C_30C_10Cmin_5Cmin_2Cmin
proceduresegments,Data Off ; Equilibrate 30.00 °C; Data On ; Ramp 10.00 °C/min to -90.00 °C; Data Off ; Isothermal 2.0 min; Data On ; Ramp 10.00 °C/min to 30.00 °C; Data Off ; Isothermal 2.0 min; Data On ; Ramp 5.00 °C/min to -90.00 °C; Data Off ; Isothermal 2.0 min; Data On ; Ramp 5.00 °C/min to 30.00 °C; Data Off ; Isothermal 2.0 min; Data On ; Ramp 2.00 °C/min to -90.00 °C; Data Off ; Isothermal 2.0 min; Data On ; Ramp 2.00 °C/min to 30.00 °C
[File Parameters]
Run date,6/16/2025 8:59:31 PM
Trios version,5.1.1.46572
Original File Name,
Current File Name,D:\DSC2500\Gibbons\2025_06_16_Adamantane_n90C_30C_10Cmin_5Cmin_2Cmin.tri
[Procedure]
Procedure Name,TPP_n90C_30C_10Cmin_5Cmin_2Cmin
Sample Name,2025_06_16_Adamantane_n90C_30C_10Cmin_5Cmin_2Cmin
Sample Mass,2.08 mg
Reference Sample Mass,0 mg
Pan Mass,56.67 mg
Pan Number,46
Reference Pan Mass,56.96 mg
Reference Pan Number,10
Pan Type,Tzero Aluminum Hermetic
Comments,Al Hermetic DSC Consumables sealed Pan/Lid. A2 Tray (Google Sheet: DSC_Samples_A2_Tray_May2025)
Project Name,CA
Operator,Gibbons
Test,Custom
Unload Max Temperature,30
Unload Min Temperature,30
Load Max Temperature,30
Load Min Temperature,30
Stop on Gas Flow Error,Yes
[Signal List]
Signal #1,Time (min)
Signal #2,Temperature (°C)
Signal #3,Heat Flow (mW)
Signal #4,Delta T (µV)
Signal #5,Delta Tzero (µV)
Signal #6,Tzero Temperature (°C)
Signal #7,Cell Purge (mL/min)
Signal #8,Heater Temp (°C)
Signal #9,Power Delivered (W)
Signal #10,Reference Junction Temperature (°C)
Signal #11,Flange Temperature (°C)
Signal #12,Heat Flow Phase (rad)
Signal #13,Total Heat Capacity (J/°C)
Signal #14,Heat Capacity (J/°C)
[Configuration]
Company Name,ASU
Instrument Name,DSC2A-00468
Instrument Type,DSC2500
Serial Number,DSC2A-00468
IP,192.168.1.100
Location of Instrument,MRRC
DisplayType,Unknown
Sample Interval ,0.1 s/pt
Selected Heat Flow,T4P
Exotherm Direction,Down
Cell Serial,DRC2-00792
Lid Type,Standard
Cooler,RCS 90
Leave Cooler on at End of Sequence,On
Gas 2,Nitrogen
Gas Selected,Channel 1
Flow Rate,50 mL/min
Secondary Purge,On
Licensed Heat Flow,Heat Flow T4P
Modulation Licensed,Yes
[Versions]
Common IDD Version,1
Cortex Version,VER 2.10.2.31
Driver,5.0.0.6
GDM Version,1.0.3.3
TouchscreenVersion,1.0.0.16145
FEP Version,1.2.1.21
FEP Bootloader,2.0.0.5
AutoSampler Version,2.1.1.26
Auto Sampler Bootloader,2.0.0.5
FCM Version,1.1.0.3
FCM Bootloader,2.0.0.5
[Experiment Logs]
Experiment Log Entry # 1,Data On set to 0
Experiment Log Entry # 3,Equilibrate Segment 30 (C) Started
Experiment Log Entry # 5,Data On set to 1
Experiment Log Entry # 7,Ramp Segment 10 C/min to -90 Started
Experiment Log Entry # 9,Data On set to 0
Experiment Log Entry # 11,Isothermal Segment 2 min started
Experiment Log Entry # 13,Data On set to 1
Experiment Log Entry # 15,Ramp Segment 10 C/min to 30 Started
Experiment Log Entry # 17,Data On set to 0
Experiment Log Entry # 19,Isothermal Segment 2 min started
Experiment Log Entry # 21,Data On set to 1
Experiment Log Entry # 23,Ramp Segment 5 C/min to -90 Started
Experiment Log Entry # 25,Data On set to 0
Experiment Log Entry # 27,Isothermal Segment 2 min started
Experiment Log Entry # 29,Data On set to 1
Experiment Log Entry # 31,Ramp Segment 5 C/min to 30 Started
Experiment Log Entry # 33,Data On set to 0
Experiment Log Entry # 35,Isothermal Segment 2 min started
Experiment Log Entry # 37,Data On set to 1
Experiment Log Entry # 39,Ramp Segment 2 C/min to -90 Started
Experiment Log Entry # 41,Data On set to 0
Experiment Log Entry # 43,Isothermal Segment 2 min started
Experiment Log Entry # 45,Data On set to 1
Experiment Log Entry # 47,Ramp Segment 2 C/min to 30 Started
[Method Log]
Method Log Entry # 1,Data Off
Method Log Entry # 2,Equilibrate 30 °C
Method Log Entry # 3,Data On
Method Log Entry # 4,(Ramp 450381) Ramp 10 °C/minute to -90 °C
Method Log Entry # 5,Data Off
Method Log Entry # 6,Isothermal 2 minutes
Method Log Entry # 7,Data On
Method Log Entry # 8,(Ramp 450385) Ramp 10 °C/minute to 30 °C
Method Log Entry # 9,Data Off
Method Log Entry # 10,Isothermal 2 minutes
Method Log Entry # 11,Data On
Method Log Entry # 12,(Ramp 450389) Ramp 5 °C/minute to -90 °C
Method Log Entry # 13,Data Off
Method Log Entry # 14,Isothermal 2 minutes
Method Log Entry # 15,Data On
Method Log Entry # 16,(Ramp 450393) Ramp 5 °C/minute to 30 °C
Method Log Entry # 17,Data Off
Method Log Entry # 18,Isothermal 2 minutes
Method Log Entry # 19,Data On
Method Log Entry # 20,(Ramp 450397) Ramp 2 °C/minute to -90 °C
Method Log Entry # 21,Data Off
Method Log Entry # 22,Isothermal 2 minutes
Method Log Entry # 23,Data On
Method Log Entry # 24,(Ramp 450401) Ramp 2 °C/minute to 30 °C
Cell Serial,DRC2-00792
[T1 Calibration]
Slope,-0.008529666
Offset,9.636258
Initial Temperature,98.23
GUID,f8bfdadc-4977-4fdf-ba6d-0ba9134940c3
[TZero Calibration]
Date Applied,11/29/2022 4:06:13 PM
Description,From -89.059 °C to 396.009 °C at 20.000°C/min
Gas Type,Nitrogen
Pan Type,None
Source Files 1,C:\Users\yargerlab\Desktop\DSC Data\General\TZero_calibration_11_29_22_2nd(2).tri
Source Files 2,C:\Users\yargerlab\Desktop\DSC Data\General\TZero_calibration_11_29_22_2nd(3).tri
Delta T Offset,13.05235
Delta T Slope,-0.007271007
Delta T0 Offset,-13.69128
Delta T0 Slope,0.06063341
[Temperature Calibration]
Date Applied,11/29/2022 7:12:28 PM
Description,From 106.590 °C to 186.590 °C at 10.000°C/min
Gas Type,Nitrogen
Pan Type,Tzero Aluminum Hermetic
Source Files 1,C:\Users\yargerlab\Desktop\DSC Data\General\Indium(6).tri
Measured 1,157.391
Known 1,156.598
[Cell Constant Calibration]
Date Applied,11/29/2022 7:12:29 PM
Description,From 106.590 °C to 186.590 °C at 10.000°C/min
Gas Type,Nitrogen
Pan Type,Tzero Aluminum Hermetic
Source Files 1,C:\Users\yargerlab\Desktop\DSC Data\General\Indium(6).tri
T4P KCell,1.006051
Onset Slope,63.26126 mW/°C
[Direct Cp Calibration]
Date Applied,11/30/2022 11:04:51 AM
Description,From -79.983 °C to 298.409 °C at 10.000°C/min
Gas Type,Nitrogen
Pan Type,Tzero Aluminum Hermetic
Source Files 1,C:\Users\yargerlab\Desktop\DSC Data\General\Sapphire_Heat_Capacity_11_30_22.tri
[Rev Cp Calibration]
Date Applied,11/30/2022 1:58:51 PM
Description,From -79.996 °C to 292.812 °C at 3.000°C/min
Gas Type,Nitrogen
Pan Type,Tzero Aluminum Hermetic
Source Files 1,C:\Users\yargerlab\Desktop\DSC Data\General\Sapphire_MDSC_Calibration_11_30_22.tri
[step]
Ramp 10.00 °C/min to -90.00 °C
Time,Temperature,Heat Flow (Normalized)
min,°C,W/g
0.00,29.86,0.053
0.01,29.87,0.050
0.02,29.88,0.048
0.03,29.89,0.045
0.03,29.89,0.042
0.04,29.90,0.039
0.05,29.90,0.037
0.06,29.90,0.037
0.07,29.90,0.038
0.08,29.89,0.046
0.08,29.88,0.072
0.09,29.86,0.096
0.10,29.84,0.117
0.11,29.82,0.131
0.12,29.79,0.145
0.13,29.76,0.154
0.13,29.72,0.161
0.14,29.68,0.162
0.15,29.63,0.159
0.16,29.59,0.152
0.17,29.53,0.148
0.18,29.48,0.139
0.18,29.43,0.118
0.19,29.37,0.093
0.20,29.31,0.070
0.21,29.25,0.048
0.22,29.18,0.031
0.23,29.12,0.017
0.23,29.06,-0.005
0.24,28.99,-0.022
0.25,28.92,-0.036
0.26,28.86,-0.053
0.27,28.79,-0.065
0.28,28.72,-0.077
0.28,28.65,-0.089
0.29,28.58,-0.100
0.30,28.51,-0.105
0.31,28.43,-0.117
0.32,28.36,-0.128
0.33,28.29,-0.132
0.33,28.22,-0.138
0.34,28.14,-0.145
0.35,28.07,-0.152
0.36,27.99,-0.161
0.37,27.92,-0.162
0.38,27.84,-0.166
0.38,27.77,-0.177
0.39,27.69,-0.179
0.40,27.61,-0.182
0.41,27.54,-0.188
0.42,27.46,-0.191
0.43,27.38,-0.193
0.43,27.31,-0.194
0.44,27.23,-0.199
0.45,27.15,-0.204
0.46,27.07,-0.206
0.47,26.99,-0.207
0.48,26.91,-0.210
0.48,26.84,-0.212
0.49,26.76,-0.212
0.50,26.68,-0.215
0.51,26.60,-0.216
0.52,26.52,-0.217
0.53,26.44,-0.219
0.53,26.36,-0.221
0.54,26.28,-0.222
0.55,26.20,-0.222
0.56,26.12,-0.224
0.57,26.04,-0.226
0.58,25.96,-0.226
0.58,25.88,-0.227
0.59,25.80,-0.227
0.60,25.72,-0.228
0.61,25.64,-0.229
0.62,25.56,-0.229
0.63,25.48,-0.230
0.63,25.40,-0.230
0.64,25.32,-0.232
0.65,25.24,-0.232
0.66,25.16,-0.233
0.67,25.08,-0.234
0.68,24.99,-0.234
0.68,24.91,-0.235
0.69,24.83,-0.235
0.70,24.75,-0.236
0.71,24.67,-0.236
0.72,24.59,-0.237
0.73,24.51,-0.237
0.73,24.43,-0.238
0.74,24.34,-0.238
0.75,24.26,-0.238
0.76,24.18,-0.239
0.77,24.10,-0.239
0.78,24.02,-0.240
0.78,23.94,-0.240
0.79,23.86,-0.241
0.80,23.77,-0.241
0.81,23.69,-0.241
0.82,23.61,-0.242
0.83,23.53,-0.242
0.83,23.45,-0.242
0.84,23.36,-0.243
0.85,23.28,-0.243
0.86,23.20,-0.243
0.87,23.12,-0.243
0.88,23.04,-0.244
0.88,22.96,-0.244
0.89,22.87,-0.244
0.90,22.79,-0.245
0.91,22.71,-0.245
0.92,22.63,-0.245
0.93,22.54,-0.245
0.93,22.46,-0.245
0.94,22.38,-0.246
0.95,22.30,-0.246
0.96,22.21,-0.246
0.97,22.13,-0.246
0.98,22.05,-0.247
0.98,21.97,-0.247
0.99,21.89,-0.247
1.00,21.80,-0.247
1.01,21.72,-0.247
1.02,21.64,-0.247
1.03,21.56,-0.248
1.03,21.47,-0.248
1.04,21.39,-0.248
1.05,21.31,-0.248
1.06,21.23,-0.248
1.07,21.14,-0.249
1.08,21.06,-0.249
1.08,20.98,-0.249
1.09,20.89,-0.249
1.10,20.81,-0.249
1.11,20.73,-0.249
1.12,20.65,-0.250
1.13,20.56,-0.250
1.13,20.48,-0.250
1.14,20.40,-0.250
1.15,20.31,-0.250
1.16,20.23,-0.250
1.17,20.15,-0.250
1.18,20.07,-0.250
1.18,19.98,-0.250
1.19,19.90,-0.250
1.20,19.82,-0.250
1.21,19.74,-0.251
1.22,19.65,-0.251
1.23,19.57,-0.251
1.23,19.49,-0.251
1.24,19.40,-0.251
1.25,19.32,-0.251
1.26,19.24,-0.251
1.27,19.16,-0.250
1.28,19.07,-0.251
1.28,18.99,-0.250
1.29,18.91,-0.250
1.30,18.82,-0.250
1.31,18.74,-0.250
1.32,18.66,-0.250
1.33,18.57,-0.250
1.33,18.49,-0.250
1.34,18.41,-0.250
1.35,18.32,-0.250
1.36,18.24,-0.250
1.37,18.16,-0.250
1.38,18.07,-0.250
1.38,17.99,-0.250
1.39,17.91,-0.250
1.40,17.82,-0.250
1.41,17.74,-0.250
1.42,17.66,-0.250
1.43,17.57,-0.250
1.43,17.49,-0.250
1.44,17.41,-0.250
1.45,17.32,-0.250
1.46,17.24,-0.250
1.47,17.16,-0.250
1.48,17.08,-0.251
1.48,16.99,-0.251
1.49,16.91,-0.251
1.50,16.83,-0.251
1.51,16.74,-0.251
1.52,16.66,-0.251
1.53,16.58,-0.251
1.53,16.49,-0.251
1.54,16.41,-0.251
1.55,16.33,-0.251
1.56,16.24,-0.251
1.57,16.16,-0.251
1.58,16.08,-0.250
1.58,16.00,-0.250
1.59,15.91,-0.250
1.60,15.83,-0.250
1.61,15.75,-0.250
1.62,15.66,-0.250
1.63,15.58,-0.250
1.63,15.50,-0.249
1.64,15.42,-0.249
1.65,15.33,-0.249
1.66,15.25,-0.249
1.67,15.17,-0.249
1.68,15.08,-0.249
1.68,15.00,-0.249
1.69,14.92,-0.249
1.70,14.83,-0.249
1.71,14.75,-0.248
1.72,14.67,-0.248
1.73,14.58,-0.248
1.73,14.50,-0.248
1.74,14.42,-0.248
1.75,14.33,-0.248
1.76,14.25,-0.248
1.77,14.17,-0.248
1.78,14.09,-0.248
1.78,14.00,-0.248
1.79,13.92,-0.247
1.80,13.84,-0.247
1.81,13.75,-0.247
1.82,13.67,-0.247
1.83,13.59,-0.247
1.83,13.50,-0.247
1.84,13.42,-0.247
1.85,13.34,-0.247
1.86,13.25,-0.246
1.87,13.17,-0.246
1.88,13.09,-0.246
1.88,13.00,-0.246
1.89,12.92,-0.246
1.90,12.84,-0.246
1.91,12.76,-0.246
1.92,12.67,-0.246
1.93,12.59,-0.246
1.93,12.51,-0.246
1.94,12.42,-0.245
1.95,12.34,-0.244
1.96,12.26,-0.244
1.97,12.17,-0.244
1.98,12.09,-0.244
1.98,12.01,-0.244
1.99,11.92,-0.244
2.00,11.84,-0.244
2.01,11.76,-0.244
2.02,11.67,-0.243
2.03,11.59,-0.243
2.03,11.51,-0.243
2.04,11.42,-0.243
2.05,11.34,-0.243
2.06,11.26,-0.243
2.07,11.17,-0.243
2.08,11.09,-0.243
2.08,11.01,-0.243
2.09,10.93,-0.243
2.10,10.84,-0.243
2.11,10.76,-0.243
2.12,10.68,-0.242
2.13,10.59,-0.242
2.13,10.51,-0.242
2.14,10.43,-0.242
2.15,10.34,-0.241
2.16,10.26,-0.241
2.17,10.18,-0.241
2.18,10.09,-0.241
2.18,10.01,-0.241
2.19,9.93,-0.241
2.20,9.84,-0.241
2.21,9.76,-0.241
2.22,9.68,-0.241
2.23,9.59,-0.241
2.23,9.51,-0.241
2.24,9.43,-0.240
2.25,9.35,-0.240
2.26,9.26,-0.240
2.27,9.18,-0.240
2.28,9.10,-0.240
2.28,9.01,-0.240
2.29,8.93,-0.240
2.30,8.85,-0.239
2.31,8.76,-0.239
2.32,8.68,-0.239
2.33,8.60,-0.239
2.33,8.51,-0.239
2.34,8.43,-0.239
2.35,8.35,-0.239
2.36,8.26,-0.239
2.37,8.18,-0.239
2.38,8.10,-0.238
2.38,8.02,-0.238
2.39,7.93,-0.238
2.40,7.85,-0.238
2.41,7.77,-0.238
2.42,7.68,-0.238
2.43,7.60,-0.238
2.43,7.52,-0.237
2.44,7.43,-0.237
2.45,7.35,-0.237
2.46,7.27,-0.237
2.47,7.18,-0.237
2.48,7.10,-0.237
2.48,7.02,-0.237
2.49,6.94,-0.236
2.50,6.85,-0.236
2.51,6.77,-0.236
2.52,6.69,-0.236
2.53,6.60,-0.236
2.53,6.52,-0.236
2.54,6.44,-0.236
2.55,6.35,-0.236
2.56,6.27,-0.235
2.57,6.19,-0.235
2.58,6.10,-0.235
2.58,6.02,-0.235
2.59,5.94,-0.235
2.60,5.85,-0.235
2.61,5.77,-0.235
2.62,5.69,-0.234
2.63,5.61,-0.234
2.63,5.52,-0.234
2.64,5.44,-0.234
2.65,5.36,-0.234
2.66,5.27,-0.234
2.67,5.19,-0.234
2.68,5.11,-0.233
2.68,5.02,-0.233
2.69,4.94,-0.233
2.70,4.86,-0.233
2.71,4.77,-0.233
2.72,4.69,-0.233
2.73,4.61,-0.233
2.73,4.52,-0.232
2.74,4.44,-0.232
2.75,4.36,-0.232
2.76,4.27,-0.232
2.77,4.19,-0.232
2.78,4.11,-0.232
2.78,4.02,-0.232
2.79,3.94,-0.231
2.80,3.86,-0.231
2.81,3.78,-0.231
2.82,3.69,-0.231
2.83,3.61,-0.231
2.83,3.53,-0.230
2.84,3.44,-0.230
2.85,3.36,-0.230
2.86,3.27,-0.230
2.87,3.19,-0.230
2.88,3.11,-0.230
2.88,3.03,-0.230
2.89,2.94,-0.230
2.90,2.86,-0.229
2.91,2.78,-0.229
2.92,2.69,-0.229
2.93,2.61,-0.229
2.93,2.53,-0.229
2.94,2.44,-0.229
2.95,2.36,-0.229
2.96,2.28,-0.229
2.97,2.19,-0.228
2.98,2.11,-0.228
2.98,2.03,-0.228
2.99,1.94,-0.228
3.00,1.86,-0.228
3.01,1.78,-0.228
3.02,1.69,-0.228
3.03,1.61,-0.228
3.03,1.53,-0.227
3.04,1.44,-0.227
3.05,1.36,-0.227
3.06,1.28,-0.227
3.07,1.19,-0.227
3.08,1.11,-0.227
3.08,1.03,-0.227
3.09,0.94,-0.226
3.10,0.86,-0.226
3.11,0.78,-0.226
3.12,0.69,-0.226
3.13,0.61,-0.226
3.13,0.53,-0.225
3.14,0.44,-0.225
3.15,0.36,-0.225
3.16,0.28,-0.225
3.17,0.19,-0.225
3.18,0.11,-0.225
3.18,0.02,-0.225
3.19,-0.06,-0.225
3.20,-0.14,-0.225
3.21,-0.23,-0.224
3.22,-0.31,-0.224
3.23,-0.39,-0.224
3.23,-0.48,-0.224
3.24,-0.56,-0.224
3.25,-0.64,-0.224
3.26,-0.72,-0.224
3.27,-0.81,-0.223
3.28,-0.89,-0.223
3.28,-0.98,-0.223
3.29,-1.06,-0.223
3.30,-1.14,-0.223
3.31,-1.23,-0.223
3.32,-1.31,-0.223
3.33,-1.39,-0.222
3.33,-1.48,-0.222
3.34,-1.56,-0.222
3.35,-1.64,-0.222
3.36,-1.72,-0.222
3.37,-1.81,-0.222
3.38,-1.89,-0.221
3.38,-1.98,-0.221
3.39,-2.06,-0.221
3.40,-2.14,-0.221
3.41,-2.23,-0.221
3.42,-2.31,-0.221
3.43,-2.39,-0.221
3.43,-2.48,-0.221
3.44,-2.56,-0.220
3.45,-2.64,-0.220
3.46,-2.73,-0.220
3.47,-2.81,-0.220
3.48,-2.89,-0.220
3.48,-2.98,-0.220
3.49,-3.06,-0.220
3.50,-3.14,-0.219
3.51,-3.23,-0.219
3.52,-3.31,-0.219
3.53,-3.39,-0.219
3.53,-3.48,-0.219
3.54,-3.56,-0.219
3.55,-3.64,-0.219
3.56,-3.73,-0.219
3.57,-3.81,-0.218
3.58,-3.89,-0.218
3.58,-3.98,-0.218
3.59,-4.06,-0.218
3.60,-4.15,-0.218
3.61,-4.23,-0.218
3.62,-4.31,-0.217
3.63,-4.40,-0.217
3.63,-4.48,-0.217
3.64,-4.56,-0.217
3.65,-4.65,-0.217
3.66,-4.73,-0.217
3.67,-4.81,-0.217
3.68,-4.90,-0.217
3.68,-4.98,-0.216
3.69,-5.06,-0.216
3.70,-5.15,-0.216
3.71,-5.23,-0.216
3.72,-5.31,-0.216
3.73,-5.40,-0.216
3.73,-5.48,-0.216
3.74,-5.56,-0.216
3.75,-5.65,-0.216
3.76,-5.73,-0.215
3.77,-5.81,-0.216
3.78,-5.90,-0.215
3.78,-5.98,-0.215
3.79,-6.06,-0.215
3.80,-6.15,-0.215
3.81,-6.23,-0.215
3.82,-6.31,-0.215
3.83,-6.40,-0.214
3.83,-6.48,-0.214
3.84,-6.56,-0.214
3.85,-6.65,-0.214
3.86,-6.73,-0.214
3.87,-6.81,-0.214
3.88,-6.90,-0.214
3.88,-6.98,-0.214
3.89,-7.06,-0.214
3.90,-7.15,-0.213
3.91,-7.23,-0.213
3.92,-7.31,-0.213
3.93,-7.40,-0.213
3.93,-7.48,-0.213
3.94,-7.56,-0.213
3.95,-7.65,-0.213
3.96,-7.73,-0.212
3.97,-7.81,-0.212
3.98,-7.90,-0.212
3.98,-7.98,-0.212
3.99,-8.06,-0.212
4.00,-8.15,-0.212
4.01,-8.23,-0.211
4.02,-8.32,-0.211
4.03,-8.40,-0.211
4.03,-8.48,-0.211
4.04,-8.56,-0.211
4.05,-8.65,-0.210
4.06,-8.73,-0.210
4.07,-8.82,-0.210
4.08,-8.90,-0.210
4.08,-8.98,-0.210
4.09,-9.07,-0.210
4.10,-9.15,-0.210
4.11,-9.23,-0.210
4.12,-9.32,-0.210
4.13,-9.40,-0.210
4.13,-9.48,-0.209
4.14,-9.57,-0.209
4.15,-9.65,-0.209
4.16,-9.73,-0.209
4.17,-9.82,-0.209
4.18,-9.90,-0.209
4.18,-9.98,-0.209
4.19,-10.07,-0.209
4.20,-10.15,-0.208
4.21,-10.23,-0.208
4.22,-10.32,-0.208
4.23,-10.40,-0.208
4.23,-10.48,-0.208
4.24,-10.57,-0.208
4.25,-10.65,-0.208
4.26,-10.74,-0.208
4.27,-10.82,-0.207
4.28,-10.90,-0.207
4.28,-10.98,-0.207
4.29,-11.07,-0.207
4.30,-11.15,-0.207
4.31,-11.23,-0.207
4.32,-11.32,-0.207
4.33,-11.40,-0.207
4.33,-11.48,-0.207
4.34,-11.57,-0.206
4.35,-11.65,-0.206
4.36,-11.73,-0.206
4.37,-11.82,-0.206
4.38,-11.90,-0.205
4.38,-11.98,-0.205
4.39,-12.07,-0.205
4.40,-12.15,-0.205
4.41,-12.23,-0.205
4.42,-12.32,-0.205
4.43,-12.40,-0.205
4.43,-12.48,-0.204
4.44,-12.57,-0.204
4.45,-12.65,-0.204
4.46,-12.74,-0.204
4.47,-12.82,-0.204
4.48,-12.90,-0.204
4.48,-12.99,-0.204
4.49,-13.07,-0.204
4.50,-13.15,-0.204
4.51,-13.24,-0.203
4.52,-13.32,-0.203
4.53,-13.40,-0.203
4.53,-13.49,-0.203
4.54,-13.57,-0.203
4.55,-13.65,-0.203
4.56,-13.74,-0.203
4.57,-13.82,-0.203
4.58,-13.90,-0.203
4.58,-13.99,-0.203
4.59,-14.07,-0.203
4.60,-14.15,-0.202
4.61,-14.24,-0.202
4.62,-14.32,-0.202
4.63,-14.40,-0.202
4.63,-14.49,-0.202
4.64,-14.57,-0.202
4.65,-14.65,-0.202
4.66,-14.74,-0.202
4.67,-14.82,-0.201
4.68,-14.90,-0.201
4.68,-14.99,-0.201
4.69,-15.07,-0.201
4.70,-15.15,-0.201
4.71,-15.24,-0.201
4.72,-15.32,-0.201
4.73,-15.40,-0.200
4.73,-15.49,-0.200
4.74,-15.57,-0.200
4.75,-15.65,-0.200
4.76,-15.74,-0.200
4.77,-15.82,-0.200
4.78,-15.90,-0.200
4.78,-15.99,-0.200
4.79,-16.07,-0.200
4.80,-16.15,-0.199
4.81,-16.24,-0.199
4.82,-16.32,-0.199
4.83,-16.40,-0.199
4.83,-16.49,-0.199
4.84,-16.57,-0.199
4.85,-16.65,-0.199
4.86,-16.74,-0.199
4.87,-16.82,-0.199
4.88,-16.90,-0.198
4.88,-16.99,-0.198
4.89,-17.07,-0.198
4.90,-17.15,-0.198
4.91,-17.24,-0.198
4.92,-17.32,-0.198
4.93,-17.40,-0.198
4.93,-17.49,-0.197
4.94,-17.57,-0.197
4.95,-17.65,-0.197
4.96,-17.74,-0.197
4.97,-17.82,-0.197
4.98,-17.90,-0.197
4.98,-17.99,-0.197
4.99,-18.07,-0.196
5.00,-18.15,-0.196
5.01,-18.24,-0.196
5.02,-18.32,-0.196
5.03,-18.40,-0.196
5.03,-18.49,-0.196
5.04,-18.57,-0.196
5.05,-18.65,-0.196
5.06,-18.74,-0.196
5.07,-18.82,-0.195
5.08,-18.91,-0.195
5.08,-18.99,-0.195
5.09,-19.07,-0.195
5.10,-19.15,-0.194
5.11,-19.24,-0.194
5.12,-19.32,-0.194
5.13,-19.40,-0.194
5.13,-19.49,-0.194
5.14,-19.57,-0.194
5.15,-19.65,-0.194
5.16,-19.74,-0.194
5.17,-19.82,-0.194
5.18,-19.90,-0.193
5.18,-19.99,-0.193
5.19,-20.07,-0.193
5.20,-20.15,-0.193
5.21,-20.24,-0.193
5.22,-20.32,-0.193
5.23,-20.40,-0.193
5.23,-20.49,-0.192
5.24,-20.57,-0.192
5.25,-20.66,-0.192
5.26,-20.74,-0.192
5.27,-20.82,-0.192
5.28,-20.90,-0.192
5.28,-20.99,-0.192
5.29,-21.07,-0.191
5.30,-21.15,-0.191
5.31,-21.24,-0.191
5.32,-21.32,-0.191
5.33,-21.41,-0.191
5.33,-21.49,-0.191
5.34,-21.57,-0.191
5.35,-21.66,-0.191
5.36,-21.74,-0.190
5.37,-21.82,-0.190
5.38,-21.91,-0.190
5.38,-21.99,-0.190
5.39,-22.07,-0.190
5.40,-22.16,-0.190
5.41,-22.24,-0.190
5.42,-22.32,-0.190
5.43,-22.40,-0.190
5.43,-22.49,-0.190
5.44,-22.57,-0.189
5.45,-22.66,-0.189
5.46,-22.74,-0.189
5.47,-22.82,-0.189
5.48,-22.90,-0.189
5.48,-22.99,-0.189
5.49,-23.07,-0.188
5.50,-23.16,-0.188
5.51,-23.24,-0.188
5.52,-23.32,-0.188
5.53,-23.41,-0.188
5.53,-23.49,-0.188
5.54,-23.57,-0.188
5.55,-23.66,-0.188
5.56,-23.74,-0.188
5.57,-23.82,-0.188
5.58,-23.91,-0.187
5.58,-23.99,-0.187
5.59,-24.07,-0.187
5.60,-24.16,-0.187
5.61,-24.24,-0.187
5.62,-24.32,-0.187
5.63,-24.41,-0.187
5.63,-24.49,-0.187
5.64,-24.57,-0.186
5.65,-24.66,-0.186
5.66,-24.74,-0.186
5.67,-24.82,-0.186
5.68,-24.91,-0.186
5.68,-24.99,-0.186
5.69,-25.07,-0.186
5.70,-25.15,-0.186
5.71,-25.24,-0.185
5.72,-25.32,-0.185
5.73,-25.41,-0.185
5.73,-25.49,-0.185
5.74,-25.57,-0.185
5.75,-25.66,-0.185
5.76,-25.74,-0.185
5.77,-25.82,-0.185
5.78,-25.91,-0.184
5.78,-25.99,-0.184
5.79,-26.07,-0.184
5.80,-26.16,-0.184
5.81,-26.24,-0.184
5.82,-26.32,-0.184
5.83,-26.40,-0.184
5.83,-26.49,-0.183
5.84,-26.57,-0.183
5.85,-26.66,-0.183
5.86,-26.74,-0.183
5.87,-26.82,-0.183
5.88,-26.91,-0.183
5.88,-26.99,-0.183
5.89,-27.07,-0.183
5.90,-27.16,-0.183
5.91,-27.24,-0.182
5.92,-27.32,-0.182
5.93,-27.41,-0.182
5.93,-27.49,-0.182
5.94,-27.57,-0.182
5.95,-27.66,-0.181
5.96,-27.74,-0.182
5.97,-27.82,-0.181
5.98,-27.91,-0.181
5.98,-27.99,-0.181
5.99,-28.07,-0.181
6.00,-28.16,-0.181
6.01,-28.24,-0.181
6.02,-28.32,-0.181
6.03,-28.41,-0.181
6.03,-28.49,-0.180
6.04,-28.57,-0.180
6.05,-28.66,-0.180
6.06,-28.74,-0.180
6.07,-28.82,-0.180
6.08,-28.90,-0.180
6.08,-28.99,-0.180
6.09,-29.07,-0.180
6.10,-29.16,-0.179
6.11,-29.24,-0.179
6.12,-29.32,-0.179
6.13,-29.40,-0.179
6.13,-29.49,-0.179
6.14,-29.57,-0.179
6.15,-29.65,-0.178
6.16,-29.74,-0.178
6.17,-29.82,-0.178
6.18,-29.90,-0.178
6.18,-29.99,-0.178
6.19,-30.07,-0.178
6.20,-30.15,-0.177
6.21,-30.24,-0.177
6.22,-30.32,-0.177
6.23,-30.41,-0.177
6.23,-30.49,-0.177
6.24,-30.57,-0.177
6.25,-30.66,-0.177
6.26,-30.74,-0.177
6.27,-30.82,-0.177
6.28,-30.90,-0.177
6.28,-30.99,-0.176
6.29,-31.07,-0.176
6.30,-31.16,-0.176
6.31,-31.24,-0.176
6.32,-31.32,-0.176
6.33,-31.40,-0.176
6.33,-31.49,-0.176
6.34,-31.57,-0.175
6.35,-31.65,-0.175
6.36,-31.74,-0.175
6.37,-31.82,-0.175
6.38,-31.90,-0.175
6.38,-31.99,-0.175
6.39,-32.07,-0.175
6.40,-32.15,-0.175
6.41,-32.24,-0.175
6.42,-32.32,-0.174
6.43,-32.41,-0.174
6.43,-32.49,-0.174
6.44,-32.57,-0.174
6.45,-32.66,-0.174
6.46,-32.74,-0.174
6.47,-32.82,-0.174
6.48,-32.90,-0.174
6.48,-32.99,-0.173
6.49,-33.07,-0.173
6.50,-33.15,-0.173
6.51,-33.24,-0.173
6.52,-33.32,-0.173
6.53,-33.40,-0.173
6.53,-33.49,-0.173
6.54,-33.57,-0.173
6.55,-33.66,-0.172
6.56,-33.74,-0.172
6.57,-33.82,-0.172
6.58,-33.91,-0.172
6.58,-33.99,-0.172
6.59,-34.07,-0.172
6.60,-34.15,-0.172
6.61,-34.24,-0.172
6.62,-34.32,-0.172
6.63,-34.41,-0.171
6.63,-34.49,-0.171
6.64,-34.57,-0.171
6.65,-34.65,-0.171
6.66,-34.74,-0.171
6.67,-34.82,-0.171
6.68,-34.91,-0.171
6.68,-34.99,-0.171
6.69,-35.07,-0.170
6.70,-35.15,-0.170
6.71,-35.24,-0.170
6.72,-35.32,-0.170
6.73,-35.41,-0.169
6.73,-35.49,-0.169
6.74,-35.57,-0.169
6.75,-35.66,-0.169
6.76,-35.74,-0.169
6.77,-35.82,-0.169
6.78,-35.91,-0.169
6.78,-35.99,-0.169
6.79,-36.07,-0.169
6.80,-36.15,-0.169
6.81,-36.24,-0.169
6.82,-36.32,-0.168
6.83,-36.40,-0.168
6.83,-36.49,-0.168
6.84,-36.57,-0.168
6.85,-36.65,-0.168
6.86,-36.74,-0.168
6.87,-36.82,-0.168
6.88,-36.90,-0.167
6.88,-36.99,-0.167
6.89,-37.07,-0.167
6.90,-37.16,-0.167
6.91,-37.24,-0.167
6.92,-37.32,-0.167
6.93,-37.40,-0.167
6.93,-37.49,-0.167
6.94,-37.57,-0.167
6.95,-37.65,-0.167
6.96,-37.74,-0.166
6.97,-37.82,-0.166
6.98,-37.90,-0.166
6.98,-37.99,-0.166
6.99,-38.07,-0.166
7.00,-38.15,-0.166
7.01,-38.24,-0.166
7.02,-38.32,-0.165
7.03,-38.40,-0.165
7.03,-38.49,-0.165
7.04,-38.57,-0.165
7.05,-38.65,-0.165
7.06,-38.74,-0.165
7.07,-38.82,-0.165
7.08,-38.91,-0.165
7.08,-38.99,-0.164
7.09,-39.07,-0.164
7.10,-39.15,-0.164
7.11,-39.24,-0.164
7.12,-39.32,-0.164
7.13,-39.40,-0.164
7.13,-39.49,-0.164
7.14,-39.57,-0.164
7.15,-39.65,-0.164
7.16,-39.74,-0.164
7.17,-39.82,-0.164
7.18,-39.90,-0.164
7.18,-39.98,-0.164
7.19,-40.07,-0.164
7.20,-40.15,-0.164
7.21,-40.24,-0.164
7.22,-40.32,-0.164
7.23,-40.40,-0.163
7.23,-40.49,-0.163
7.24,-40.57,-0.163
7.25,-40.65,-0.163
7.26,-40.74,-0.164
7.27,-40.82,-0.163
7.28,-40.90,-0.163
7.28,-40.99,-0.163
7.29,-41.07,-0.163
7.30,-41.15,-0.163
7.31,-41.24,-0.163
7.32,-41.32,-0.163
7.33,-41.40,-0.162
7.33,-41.49,-0.163
7.34,-41.57,-0.162
7.35,-41.65,-0.162
7.36,-41.74,-0.162
7.37,-41.82,-0.162
7.38,-41.90,-0.162
7.38,-41.99,-0.162
7.39,-42.07,-0.162
7.40,-42.15,-0.161
7.41,-42.24,-0.161
7.42,-42.32,-0.161
7.43,-42.40,-0.161
7.43,-42.49,-0.161
7.44,-42.57,-0.161
7.45,-42.65,-0.161
7.46,-42.73,-0.160
7.47,-42.82,-0.160
7.48,-42.90,-0.160
7.48,-42.99,-0.160
7.49,-43.07,-0.160
7.50,-43.15,-0.159
7.51,-43.24,-0.159
7.52,-43.32,-0.159
7.53,-43.40,-0.159
7.53,-43.48,-0.159
7.54,-43.57,-0.159
7.55,-43.65,-0.159
7.56,-43.74,-0.158
7.57,-43.82,-0.158
7.58,-43.90,-0.158
7.58,-43.99,-0.158
7.59,-44.07,-0.158
7.60,-44.15,-0.158
7.61,-44.24,-0.158
7.62,-44.32,-0.157
7.63,-44.40,-0.157
7.63,-44.49,-0.157
7.64,-44.57,-0.157
7.65,-44.65,-0.157
7.66,-44.74,-0.157
7.67,-44.82,-0.156
7.68,-44.90,-0.156
7.68,-44.99,-0.156
7.69,-45.07,-0.155
7.70,-45.15,-0.155
7.71,-45.24,-0.155
7.72,-45.32,-0.155
7.73,-45.40,-0.155
7.73,-45.49,-0.155
7.74,-45.57,-0.155
7.75,-45.65,-0.155
7.76,-45.73,-0.155
7.77,-45.82,-0.154
7.78,-45.90,-0.154
7.78,-45.98,-0.154
7.79,-46.07,-0.154
7.80,-46.15,-0.154
7.81,-46.23,-0.154
7.82,-46.32,-0.154
7.83,-46.40,-0.153
7.83,-46.49,-0.153
7.84,-46.57,-0.153
7.85,-46.65,-0.153
7.86,-46.74,-0.153
7.87,-46.82,-0.153
7.88,-46.90,-0.153
7.88,-46.98,-0.153
7.89,-47.07,-0.152
7.90,-47.15,-0.152
7.91,-47.23,-0.152
7.92,-47.32,-0.152
7.93,-47.40,-0.152
7.93,-47.48,-0.152
7.94,-47.57,-0.152
7.95,-47.65,-0.152
7.96,-47.74,-0.151
7.97,-47.82,-0.151
7.98,-47.90,-0.151
7.98,-47.99,-0.151
7.99,-48.07,-0.151
8.00,-48.15,-0.151
8.01,-48.24,-0.150
8.02,-48.32,-0.150
8.03,-48.40,-0.150
8.03,-48.49,-0.150
8.04,-48.57,-0.150
8.05,-48.65,-0.150
8.06,-48.74,-0.150
8.07,-48.82,-0.150
8.08,-48.90,-0.149
8.08,-48.99,-0.149
8.09,-49.07,-0.149
8.10,-49.15,-0.149
8.11,-49.23,-0.149
8.12,-49.32,-0.149
8.13,-49.40,-0.149
8.13,-49.48,-0.148
8.14,-49.57,-0.148
8.15,-49.65,-0.148
8.16,-49.73,-0.148
8.17,-49.82,-0.148
8.18,-49.90,-0.148
8.18,-49.98,-0.148
8.19,-50.07,-0.147
8.20,-50.15,-0.147
8.21,-50.23,-0.147
8.22,-50.32,-0.147
8.23,-50.40,-0.147
8.23,-50.49,-0.147
8.24,-50.57,-0.147
8.25,-50.65,-0.147
8.26,-50.73,-0.145
8.27,-50.82,-0.145
8.28,-50.90,-0.145
8.28,-50.98,-0.145
8.29,-51.07,-0.145
8.30,-51.15,-0.145
8.31,-51.23,-0.145
8.32,-51.32,-0.145
8.33,-51.40,-0.144
8.33,-51.48,-0.144
8.34,-51.57,-0.144
8.35,-51.65,-0.144
8.36,-51.73,-0.144
8.37,-51.82,-0.144
8.38,-51.90,-0.144
8.38,-51.98,-0.144
8.39,-52.07,-0.144
8.40,-52.15,-0.143
8.41,-52.23,-0.143
8.42,-52.32,-0.143
8.43,-52.40,-0.143
8.43,-52.48,-0.143
8.44,-52.57,-0.143
8.45,-52.65,-0.143
8.46,-52.73,-0.142
8.47,-52.82,-0.142
8.48,-52.90,-0.142
8.48,-52.98,-0.141
8.49,-53.07,-0.141
8.50,-53.15,-0.141
8.51,-53.23,-0.141
8.52,-53.32,-0.141
8.53,-53.40,-0.140
8.53,-53.48,-0.140
8.54,-53.57,-0.140
8.55,-53.65,-0.140
8.56,-53.73,-0.140
8.57,-53.82,-0.139
8.58,-53.90,-0.139
8.58,-53.98,-0.139
8.59,-54.07,-0.139
8.60,-54.15,-0.139
8.61,-54.23,-0.139
8.62,-54.32,-0.139
8.63,-54.40,-0.138
8.63,-54.48,-0.138
8.64,-54.57,-0.138
8.65,-54.65,-0.138
8.66,-54.73,-0.138
8.67,-54.82,-0.138
8.68,-54.90,-0.138
8.68,-54.98,-0.138
8.69,-55.07,-0.137
8.70,-55.15,-0.137
8.71,-55.23,-0.137
8.72,-55.32,-0.137
8.73,-55.40,-0.137
8.73,-55.48,-0.137
8.74,-55.57,-0.137
8.75,-55.65,-0.136
8.76,-55.73,-0.136
8.77,-55.81,-0.136
8.78,-55.90,-0.136
8.78,-55.98,-0.136
8.79,-56.07,-0.136
8.80,-56.15,-0.136
8.81,-56.23,-0.136
8.82,-56.32,-0.135
8.83,-56.40,-0.135
8.83,-56.48,-0.135
8.84,-56.56,-0.135
8.85,-56.65,-0.135
8.86,-56.73,-0.135
8.87,-56.81,-0.134
8.88,-56.90,-0.134
8.88,-56.98,-0.134
8.89,-57.06,-0.134
8.90,-57.15,-0.134
8.91,-57.23,-0.134
8.92,-57.31,-0.134
8.93,-57.40,-0.133
8.93,-57.48,-0.132
8.94,-57.56,-0.132
8.95,-57.65,-0.132
8.96,-57.73,-0.132
8.97,-57.81,-0.132
8.98,-57.90,-0.131
8.98,-57.98,-0.131
8.99,-58.06,-0.131
9.00,-58.15,-0.131
9.01,-58.23,-0.131
9.02,-58.31,-0.131
9.03,-58.40,-0.131
9.03,-58.48,-0.131
9.04,-58.56,-0.130
9.05,-58.65,-0.130
9.06,-58.73,-0.130
9.07,-58.81,-0.130
9.08,-58.89,-0.129
9.08,-58.98,-0.129
9.09,-59.06,-0.129
9.10,-59.15,-0.129
9.11,-59.23,-0.129
9.12,-59.31,-0.129
9.13,-59.40,-0.129
9.13,-59.48,-0.128
9.14,-59.56,-0.128
9.15,-59.65,-0.128
9.16,-59.73,-0.128
9.17,-59.81,-0.127
9.18,-59.89,-0.127
9.18,-59.98,-0.127
9.19,-60.06,-0.127
9.20,-60.14,-0.127
9.21,-60.23,-0.127
9.22,-60.31,-0.127
9.23,-60.39,-0.127
9.23,-60.48,-0.127
9.24,-60.56,-0.127
9.25,-60.65,-0.126
9.26,-60.73,-0.126
9.27,-60.81,-0.126
9.28,-60.89,-0.126
9.28,-60.98,-0.125
9.29,-61.06,-0.125
9.30,-61.14,-0.125
9.31,-61.23,-0.125
9.32,-61.31,-0.125
9.33,-61.39,-0.125
9.33,-61.48,-0.124
9.34,-61.56,-0.124
9.35,-61.64,-0.124
9.36,-61.73,-0.124
9.37,-61.81,-0.124
9.38,-61.89,-0.124
9.38,-61.98,-0.124
9.39,-62.06,-0.124
9.40,-62.14,-0.123
9.41,-62.23,-0.123
9.42,-62.31,-0.123
9.43,-62.39,-0.123
9.43,-62.48,-0.123
9.44,-62.56,-0.123
9.45,-62.64,-0.122
9.46,-62.72,-0.122
9.47,-62.81,-0.122
9.48,-62.89,-0.122
9.48,-62.97,-0.122
9.49,-63.06,-0.122
9.50,-63.14,-0.121
9.51,-63.22,-0.121
9.52,-63.31,-0.121
9.53,-63.39,-0.121
9.53,-63.47,-0.121
9.54,-63.56,-0.121
9.55,-63.64,-0.120
9.56,-63.72,-0.120
9.57,-63.80,-0.120
9.58,-63.89,-0.120
9.58,-63.97,-0.120
9.59,-64.06,-0.119
9.60,-64.14,-0.119
9.61,-64.22,-0.119
9.62,-64.30,-0.119
9.63,-64.39,-0.119
9.63,-64.47,-0.119
9.64,-64.55,-0.119
9.65,-64.64,-0.118
9.66,-64.72,-0.118
9.67,-64.80,-0.118
9.68,-64.88,-0.118
9.68,-64.97,-0.118
9.69,-65.05,-0.118
9.70,-65.13,-0.118
9.71,-65.22,-0.118
9.72,-65.30,-0.118
9.73,-65.38,-0.117
9.73,-65.46,-0.117
9.74,-65.55,-0.117
9.75,-65.63,-0.117
9.76,-65.71,-0.117
9.77,-65.80,-0.116
9.78,-65.88,-0.116
9.78,-65.96,-0.117
9.79,-66.04,-0.116
9.80,-66.13,-0.116
9.81,-66.21,-0.116
9.82,-66.29,-0.116
9.83,-66.37,-0.116
9.83,-66.45,-0.116
9.84,-66.54,-0.116
9.85,-66.62,-0.116
9.86,-66.70,-0.116
9.87,-66.78,-0.115
9.88,-66.86,-0.115
9.88,-66.95,-0.116
9.89,-67.03,-0.115
9.90,-67.11,-0.115
9.91,-67.19,-0.115
9.92,-67.27,-0.115
9.93,-67.35,-0.115
9.93,-67.43,-0.115
9.94,-67.51,-0.115
9.95,-67.59,-0.115
9.96,-67.67,-0.115
9.97,-67.75,-0.116
9.98,-67.83,-0.116
9.98,-67.91,-0.115
9.99,-67.99,-0.118
10.00,-68.07,-0.144
10.01,-68.15,-0.216
10.02,-68.22,-0.286
10.03,-68.30,-0.389
10.03,-68.37,-0.505
10.04,-68.44,-0.630
10.05,-68.51,-0.751
10.06,-68.58,-0.870
10.07,-68.64,-0.978
10.08,-68.71,-1.073
10.08,-68.77,-1.148
10.09,-68.84,-1.215
10.10,-68.90,-1.260
10.11,-68.97,-1.291
10.12,-69.03,-1.321
10.13,-69.10,-1.335
10.13,-69.16,-1.338
10.14,-69.23,-1.331
10.15,-69.30,-1.329
10.16,-69.37,-1.314
10.17,-69.44,-1.306
10.18,-69.51,-1.299
10.18,-69.58,-1.289
10.19,-69.65,-1.286
10.20,-69.73,-1.274
10.21,-69.80,-1.263
10.22,-69.87,-1.244
10.23,-69.95,-1.226
10.23,-70.02,-1.207
10.24,-70.10,-1.177
10.25,-70.17,-1.149
10.26,-70.24,-1.111
10.27,-70.32,-1.076
10.28,-70.40,-1.026
10.28,-70.47,-0.977
10.29,-70.55,-0.923
10.30,-70.62,-0.863
10.31,-70.70,-0.814
10.32,-70.78,-0.761
10.33,-70.86,-0.708
10.33,-70.94,-0.656
10.34,-71.02,-0.602
10.35,-71.10,-0.547
10.36,-71.18,-0.500
10.37,-71.26,-0.464
10.38,-71.34,-0.427
10.38,-71.42,-0.392
10.39,-71.49,-0.370
10.40,-71.57,-0.346
10.41,-71.65,-0.327
10.42,-71.73,-0.310
10.43,-71.80,-0.296
10.43,-71.88,-0.281
10.44,-71.95,-0.263
10.45,-72.03,-0.260
10.46,-72.10,-0.248
10.47,-72.17,-0.236
10.48,-72.25,-0.230
10.48,-72.32,-0.219
10.49,-72.39,-0.212
10.50,-72.47,-0.202
10.51,-72.54,-0.200
10.52,-72.61,-0.190
10.53,-72.68,-0.187
10.53,-72.75,-0.186
10.54,-72.82,-0.176
10.55,-72.89,-0.172
10.56,-72.96,-0.169
10.57,-73.03,-0.165
10.58,-73.10,-0.157
10.58,-73.17,-0.151
10.59,-73.24,-0.151
10.60,-73.30,-0.147
10.61,-73.37,-0.146
10.62,-73.44,-0.144
10.63,-73.51,-0.143
10.63,-73.57,-0.139
10.64,-73.64,-0.135
10.65,-73.71,-0.132
10.66,-73.77,-0.131
10.67,-73.84,-0.129
10.68,-73.91,-0.128
10.68,-73.97,-0.126
10.69,-74.04,-0.125
10.70,-74.10,-0.124
10.71,-74.17,-0.122
10.72,-74.23,-0.121
10.73,-74.30,-0.119
10.73,-74.36,-0.119
10.74,-74.43,-0.118
10.75,-74.49,-0.117
10.76,-74.55,-0.116
10.77,-74.62,-0.114
10.78,-74.68,-0.113
10.78,-74.75,-0.112
10.79,-74.81,-0.111
10.80,-74.87,-0.111
10.81,-74.93,-0.111
10.82,-75.00,-0.109
10.83,-75.06,-0.108
10.83,-75.12,-0.108
10.84,-75.18,-0.108
10.85,-75.25,-0.107
10.86,-75.31,-0.107
10.87,-75.37,-0.106
10.88,-75.43,-0.106
10.88,-75.49,-0.105
10.89,-75.55,-0.104
10.90,-75.61,-0.104
10.91,-75.68,-0.104
10.92,-75.74,-0.103
10.93,-75.80,-0.102
10.93,-75.86,-0.102
10.94,-75.92,-0.101
10.95,-75.98,-0.101
10.96,-76.04,-0.101
10.97,-76.10,-0.100
10.98,-76.16,-0.100
10.98,-76.21,-0.100
10.99,-76.28,-0.099
11.00,-76.34,-0.099
11.01,-76.39,-0.098
11.02,-76.45,-0.097
11.03,-76.51,-0.097
11.03,-76.57,-0.097
11.04,-76.63,-0.097
11.05,-76.69,-0.096
11.06,-76.74,-0.095
11.07,-76.80,-0.095
11.08,-76.86,-0.095
11.08,-76.92,-0.094
11.09,-76.97,-0.094
11.10,-77.03,-0.093
11.11,-77.09,-0.093
11.12,-77.15,-0.093
11.13,-77.20,-0.092
11.13,-77.26,-0.092
11.14,-77.32,-0.092
11.15,-77.37,-0.091
11.16,-77.43,-0.091
11.17,-77.48,-0.091
11.18,-77.54,-0.090
11.18,-77.60,-0.090
11.19,-77.65,-0.090
11.20,-77.71,-0.090
11.21,-77.76,-0.089
11.22,-77.82,-0.089
11.23,-77.87,-0.088
11.23,-77.93,-0.088
11.24,-77.98,-0.088
11.25,-78.04,-0.087
11.26,-78.09,-0.087
11.27,-78.15,-0.087
11.28,-78.20,-0.086
11.28,-78.25,-0.086
11.29,-78.31,-0.086
11.30,-78.36,-0.086
11.31,-78.41,-0.085
11.32,-78.47,-0.085
11.33,-78.52,-0.085
11.33,-78.58,-0.085
11.34,-78.63,-0.084
11.35,-78.68,-0.084
11.36,-78.73,-0.084
11.37,-78.79,-0.084
11.38,-78.84,-0.083
11.38,-78.89,-0.083
11.39,-78.94,-0.083
11.40,-79.00,-0.082
11.41,-79.05,-0.082
11.42,-79.10,-0.082
11.43,-79.15,-0.082
11.43,-79.20,-0.081
11.44,-79.25,-0.081
11.45,-79.31,-0.081
11.46,-79.36,-0.081
11.47,-79.41,-0.080
11.48,-79.46,-0.080
11.48,-79.51,-0.080
11.49,-79.56,-0.080
11.50,-79.61,-0.080
11.51,-79.66,-0.079
11.52,-79.71,-0.079
11.53,-79.76,-0.079
11.53,-79.81,-0.078
11.54,-79.86,-0.078
11.55,-79.91,-0.078
11.56,-79.96,-0.078
11.57,-80.01,-0.078
11.58,-80.06,-0.077
11.58,-80.11,-0.077
11.59,-80.16,-0.077
11.60,-80.20,-0.076
11.61,-80.25,-0.076
11.62,-80.30,-0.076
11.63,-80.35,-0.076
11.63,-80.40,-0.075
11.64,-80.45,-0.075
11.65,-80.49,-0.075
11.66,-80.54,-0.075
11.67,-80.59,-0.075
11.68,-80.64,-0.074
11.68,-80.68,-0.074
11.69,-80.73,-0.074
11.70,-80.78,-0.074
11.71,-80.83,-0.073
11.72,-80.87,-0.073
11.73,-80.92,-0.073
11.73,-80.97,-0.073
11.74,-81.01,-0.073
11.75,-81.06,-0.072
11.76,-81.11,-0.072
11.77,-81.15,-0.072
11.78,-81.20,-0.072
11.78,-81.25,-0.072
11.79,-81.29,-0.071
11.80,-81.34,-0.071
11.81,-81.38,-0.071
11.82,-81.43,-0.071
11.83,-81.47,-0.071
11.83,-81.52,-0.070
11.84,-81.56,-0.070
11.85,-81.61,-0.070
11.86,-81.66,-0.070
11.87,-81.70,-0.069
11.88,-81.74,-0.069
11.88,-81.79,-0.069
11.89,-81.83,-0.069
11.90,-81.88,-0.069
11.91,-81.92,-0.068
11.92,-81.97,-0.068
11.93,-82.01,-0.068
11.93,-82.05,-0.068
11.94,-82.10,-0.068
11.95,-82.14,
11.96,-82.19,
11.97,-82.23,
11.98,-82.27,
11.98,-82.32,
11.99,-82.36,
12.00,,
12.00,,

[step]
Ramp 10.00 °C/min to 30.00 °C
Time,Temperature,Heat Flow (Normalized)
min,°C,W/g
14.00,-90.03,-0.036
14.01,-90.05,-0.036
14.02,-90.07,-0.036
14.03,-90.09,-0.035
14.04,-90.12,-0.035
14.05,-90.14,-0.035
14.05,-90.16,-0.035
14.06,-90.18,-0.035
14.07,-90.20,-0.035
14.08,-90.23,-0.035
14.09,-90.24,-0.035
14.10,-90.26,-0.035
14.10,-90.28,-0.035
14.11,-90.29,-0.035
14.12,-90.30,-0.044
14.13,-90.30,-0.073
14.14,-90.30,-0.107
14.15,-90.29,-0.136
14.15,-90.28,-0.172
14.16,-90.26,-0.202
14.17,-90.23,-0.231
14.18,-90.20,-0.258
14.19,-90.17,-0.272
14.20,-90.13,-0.283
14.20,-90.08,-0.286
14.21,-90.04,-0.283
14.22,-89.98,-0.274
14.23,-89.93,-0.259
14.24,-89.88,-0.245
14.25,-89.82,-0.223
14.25,-89.76,-0.198
14.26,-89.71,-0.180
14.27,-89.65,-0.163
14.28,-89.58,-0.148
14.29,-89.52,-0.134
14.30,-89.46,-0.124
14.30,-89.39,-0.115
14.31,-89.33,-0.102
14.32,-89.26,-0.098
14.33,-89.19,-0.089
14.34,-89.12,-0.077
14.35,-89.05,-0.069
14.35,-88.98,-0.058
14.36,-88.91,-0.052
14.37,-88.84,-0.042
14.38,-88.77,-0.032
14.39,-88.69,-0.024
14.40,-88.62,-0.017
14.40,-88.55,-0.008
14.41,-88.47,-0.007
14.42,-88.39,-0.001
14.43,-88.32,0.011
14.44,-88.24,0.016
14.45,-88.17,0.020
14.45,-88.09,0.020
14.46,-88.01,0.024
14.47,-87.94,0.028
14.48,-87.86,0.032
14.49,-87.78,0.035
14.50,-87.70,0.038
14.50,-87.62,0.043
14.51,-87.54,0.045
14.52,-87.46,0.049
14.53,-87.39,0.053
14.54,-87.31,0.054
14.55,-87.23,0.054
14.55,-87.15,0.056
14.56,-87.07,0.059
14.57,-86.99,0.061
14.58,-86.91,0.062
14.59,-86.83,0.062
14.60,-86.75,0.067
14.60,-86.67,0.069
14.61,-86.59,0.069
14.62,-86.51,0.070
14.63,-86.43,0.071
14.64,-86.34,0.071
14.65,-86.26,0.072
14.65,-86.18,0.072
14.66,-86.10,0.073
14.67,-86.02,0.074
14.68,-85.94,0.075
14.69,-85.86,0.075
14.70,-85.78,0.075
14.70,-85.70,0.076
14.71,-85.61,0.076
14.72,-85.53,0.076
14.73,-85.45,0.077
14.74,-85.37,0.078
14.75,-85.29,0.079
14.75,-85.21,0.079
14.76,-85.13,0.080
14.77,-85.04,0.081
14.78,-84.96,0.081
14.79,-84.88,0.081
14.80,-84.80,0.082
14.80,-84.72,0.082
14.81,-84.64,0.082
14.82,-84.55,0.082
14.83,-84.47,0.083
14.84,-84.39,0.083
14.85,-84.30,0.083
14.85,-84.22,0.083
14.86,-84.14,0.084
14.87,-84.06,0.085
14.88,-83.98,0.085
14.89,-83.90,0.085
14.90,-83.81,0.086
14.90,-83.73,0.086
14.91,-83.65,0.086
14.92,-83.57,0.087
14.93,-83.48,0.087
14.94,-83.40,0.087
14.95,-83.32,0.087
14.95,-83.24,0.088
14.96,-83.16,0.089
14.97,-83.07,0.089
14.98,-82.99,0.089
14.99,-82.91,0.089
15.00,-82.83,0.089
15.00,-82.74,0.090
15.01,-82.66,0.090
15.02,-82.58,0.090
15.03,-82.50,0.090
15.04,-82.41,0.090
15.05,-82.33,0.091
15.05,-82.25,0.091
15.06,-82.17,0.091
15.07,-82.08,0.091
15.08,-82.00,0.091
15.09,-81.92,0.091
15.10,-81.84,0.091
15.10,-81.75,0.092
15.11,-81.67,0.092
15.12,-81.59,0.092
15.13,-81.50,0.092
15.14,-81.42,0.092
15.15,-81.34,0.092
15.15,-81.26,0.092
15.16,-81.17,0.093
15.17,-81.09,0.093
15.18,-81.01,0.093
15.19,-80.92,0.093
15.20,-80.84,0.093
15.20,-80.76,0.094
15.21,-80.68,0.094
15.22,-80.59,0.094
15.23,-80.51,0.094
15.24,-80.43,0.094
15.25,-80.34,0.094
15.25,-80.26,0.094
15.26,-80.18,0.094
15.27,-80.09,0.094
15.28,-80.01,0.094
15.29,-79.93,0.094
15.30,-79.85,0.094
15.30,-79.76,0.094
15.31,-79.68,0.094
15.32,-79.60,0.094
15.33,-79.52,0.095
15.34,-79.43,0.095
15.35,-79.35,0.095
15.35,-79.27,0.095
15.36,-79.18,0.095
15.37,-79.10,0.095
15.38,-79.02,0.095
15.39,-78.93,0.095
15.40,-78.85,0.095
15.40,-78.77,0.095
15.41,-78.68,0.095
15.42,-78.60,0.095
15.43,-78.52,0.095
15.44,-78.44,0.095
15.45,-78.35,0.095
15.45,-78.27,0.095
15.46,-78.18,0.095
15.47,-78.10,0.095
15.48,-78.02,0.095
15.49,-77.94,0.095
15.50,-77.85,0.095
15.50,-77.77,0.095
15.51,-77.69,0.095
15.52,-77.60,0.095
15.53,-77.52,0.095
15.54,-77.44,0.095
15.55,-77.35,0.095
15.55,-77.27,0.095
15.56,-77.19,0.095
15.57,-77.10,0.095
15.58,-77.02,0.095
15.59,-76.94,0.095
15.60,-76.86,0.095
15.60,-76.77,0.095
15.61,-76.69,0.095
15.62,-76.61,0.095
15.63,-76.52,0.095
15.64,-76.44,0.095
15.65,-76.36,0.095
15.65,-76.27,0.095
15.66,-76.19,0.095
15.67,-76.11,0.095
15.68,-76.02,0.095
15.69,-75.94,0.095
15.70,-75.86,0.095
15.70,-75.77,0.095
15.71,-75.69,0.095
15.72,-75.61,0.095
15.73,-75.52,0.095
15.74,-75.44,0.095
15.75,-75.36,0.095
15.75,-75.27,0.095
15.76,-75.19,0.095
15.77,-75.11,0.095
15.78,-75.02,0.096
15.79,-74.94,0.095
15.80,-74.86,0.095
15.80,-74.77,0.095
15.81,-74.69,0.096
15.82,-74.61,0.096
15.83,-74.52,0.096
15.84,-74.44,0.096
15.85,-74.36,0.096
15.85,-74.28,0.096
15.86,-74.19,0.096
15.87,-74.11,0.096
15.88,-74.03,0.096
15.89,-73.94,0.096
15.90,-73.86,0.096
15.90,-73.77,0.096
15.91,-73.69,0.096
15.92,-73.61,0.096
15.93,-73.52,0.096
15.94,-73.44,0.096
15.95,-73.36,0.096
15.95,-73.28,0.097
15.96,-73.19,0.097
15.97,-73.11,0.097
15.98,-73.02,0.097
15.99,-72.94,0.097
16.00,-72.86,0.097
16.00,-72.78,0.097
16.01,-72.69,0.097
16.02,-72.61,0.097
16.03,-72.53,0.097
16.04,-72.44,0.098
16.05,-72.36,0.098
16.05,-72.28,0.098
16.06,-72.19,0.098
16.07,-72.11,0.098
16.08,-72.03,0.098
16.09,-71.94,0.099
16.10,-71.86,0.099
16.10,-71.78,0.099
16.11,-71.69,0.099
16.12,-71.61,0.099
16.13,-71.53,0.099
16.14,-71.44,0.099
16.15,-71.36,0.099
16.15,-71.28,0.099
16.16,-71.20,0.099
16.17,-71.11,0.099
16.18,-71.03,0.100
16.19,-70.94,0.100
16.20,-70.86,0.100
16.20,-70.78,0.100
16.21,-70.69,0.100
16.22,-70.61,0.101
16.23,-70.53,0.101
16.24,-70.44,0.101
16.25,-70.36,0.101
16.25,-70.28,0.101
16.26,-70.19,0.101
16.27,-70.11,0.102
16.28,-70.03,0.102
16.29,-69.94,0.102
16.30,-69.86,0.102
16.30,-69.78,0.103
16.31,-69.70,0.103
16.32,-69.61,0.103
16.33,-69.53,0.103
16.34,-69.44,0.104
16.35,-69.36,0.106
16.35,-69.28,0.106
16.36,-69.20,0.106
16.37,-69.11,0.106
16.38,-69.03,0.107
16.39,-68.95,0.107
16.40,-68.86,0.108
16.40,-68.78,0.108
16.41,-68.70,0.108
16.42,-68.61,0.109
16.43,-68.53,0.110
16.44,-68.45,0.111
16.45,-68.36,0.112
16.45,-68.28,0.112
16.46,-68.20,0.113
16.47,-68.11,0.114
16.48,-68.03,0.115
16.49,-67.95,0.117
16.50,-67.86,0.120
16.50,-67.78,0.122
16.51,-67.70,0.122
16.52,-67.61,0.127
16.53,-67.53,0.134
16.54,-67.45,0.137
16.55,-67.37,0.143
16.55,-67.28,0.150
16.56,-67.20,0.158
16.57,-67.12,0.164
16.58,-67.04,0.175
16.59,-66.95,0.180
16.60,-66.87,0.202
16.60,-66.79,0.214
16.61,-66.71,0.233
16.62,-66.63,0.253
16.63,-66.55,0.282
16.64,-66.47,0.324
16.65,-66.38,0.370
16.65,-66.30,0.433
16.66,-66.23,0.509
16.67,-66.15,0.592
16.68,-66.08,0.674
16.69,-66.00,0.760
16.70,-65.93,0.837
16.70,-65.85,0.903
16.71,-65.78,0.965
16.72,-65.71,1.028
16.73,-65.63,1.078
16.74,-65.56,1.119
16.75,-65.49,1.156
16.75,-65.41,1.186
16.76,-65.34,1.215
[...]
162.81,-48.71,-0.004
162.85,-48.63,-0.004
162.89,-48.55,-0.004
162.93,-48.47,-0.004
162.97,-48.39,-0.004
163.01,-48.31,-0.004
163.05,-48.23,-0.004
163.09,-48.15,-0.004
163.13,-48.07,-0.004
163.17,-47.99,-0.004
163.21,-47.91,-0.004
163.25,-47.83,-0.004
163.29,-47.75,-0.004
163.33,-47.67,-0.004
163.37,-47.59,-0.004
163.41,-47.51,-0.004
163.45,-47.43,-0.004
163.49,-47.35,-0.004
163.53,-47.27,-0.004
163.57,-47.19,-0.004
163.61,-47.11,-0.004
163.65,-47.03,-0.005
163.69,-46.95,-0.004
163.73,-46.87,-0.004
163.77,-46.79,-0.005
163.81,-46.71,-0.005
163.85,-46.63,-0.005
163.89,-46.55,-0.005
163.93,-46.47,-0.005
163.97,-46.39,-0.005
164.01,-46.31,-0.005
164.05,-46.23,-0.005
164.09,-46.15,-0.005
164.13,-46.07,-0.005
164.17,-45.99,-0.005
164.21,-45.91,-0.005
164.25,-45.83,-0.005
164.29,-45.75,-0.005
164.33,-45.67,-0.005
164.37,-45.59,-0.005
164.41,-45.51,-0.005
164.45,-45.43,-0.005
164.49,-45.35,-0.005
164.53,-45.27,-0.005
164.57,-45.19,-0.005
164.61,-45.11,-0.005
164.65,-45.03,-0.005
164.69,-44.95,-0.005
164.73,-44.87,-0.005
164.77,-44.79,-0.005
164.81,-44.71,-0.005
164.85,-44.63,-0.005
164.89,-44.55,-0.005
164.93,-44.47,-0.005
164.97,-44.39,-0.005
165.01,-44.31,-0.005
165.05,-44.23,-0.006
165.09,-44.15,-0.006
165.13,-44.07,-0.006
165.17,-43.99,-0.006
165.21,-43.91,-0.006
165.25,-43.83,-0.006
165.29,-43.75,-0.006
165.33,-43.67,-0.006
165.37,-43.59,-0.006
165.41,-43.51,-0.006
165.45,-43.43,-0.006
165.49,-43.35,-0.006
165.53,-43.27,-0.006
165.57,-43.19,-0.006
165.61,-43.11,-0.006
165.65,-43.03,-0.006
165.69,-42.95,-0.006
165.73,-42.87,-0.006
165.77,-42.79,-0.006
165.81,-42.71,-0.006
165.85,-42.63,-0.006
165.89,-42.55,-0.006
165.93,-42.47,-0.006
165.97,-42.39,-0.006
166.01,-42.31,-0.006
166.05,-42.23,-0.006
166.09,-42.15,-0.006
166.13,-42.07,-0.006
166.17,-41.99,-0.006
166.21,-41.91,-0.006
166.25,-41.83,-0.007
166.29,-41.75,-0.007
166.33,-41.67,-0.007
166.37,-41.59,-0.007
166.41,-41.51,-0.007
166.45,-41.43,-0.007
166.49,-41.35,-0.007
166.53,-41.27,-0.007
166.57,-41.19,-0.007
166.61,-41.11,-0.007
166.65,-41.03,-0.007
166.69,-40.95,-0.007
166.73,-40.87,-0.007
166.77,-40.79,-0.007
166.81,-40.71,-0.007
166.85,-40.63,-0.007
166.89,-40.55,-0.007
166.93,-40.47,-0.007
166.97,-40.39,-0.007
167.01,-40.31,-0.007
167.05,-40.23,-0.007
167.09,-40.15,-0.007
167.13,-40.07,-0.007
167.17,-39.99,-0.007
167.21,-39.91,-0.007
167.25,-39.83,-0.007
167.29,-39.75,-0.008
167.33,-39.67,-0.008
167.37,-39.59,-0.007
167.41,-39.51,-0.008
167.45,-39.43,-0.007
167.49,-39.35,-0.008
167.53,-39.27,-0.008
167.57,-39.19,-0.008
167.61,-39.11,-0.008
167.65,-39.03,-0.008
167.69,-38.95,-0.008
167.73,-38.87,-0.008
167.77,-38.79,-0.008
167.81,-38.71,-0.008
167.85,-38.63,-0.008
167.89,-38.55,-0.008
167.93,-38.47,-0.008
167.97,-38.39,-0.008
168.01,-38.31,-0.008
168.05,-38.23,-0.008
168.09,-38.15,-0.008
168.13,-38.07,-0.008
168.17,-37.99,-0.008
168.21,-37.91,-0.008
168.25,-37.83,-0.008
168.29,-37.75,-0.008
168.33,-37.67,-0.008
168.37,-37.59,-0.008
168.41,-37.51,-0.008
168.45,-37.43,-0.009
168.49,-37.35,-0.009
168.53,-37.27,-0.009
168.57,-37.19,-0.009
168.61,-37.11,-0.009
168.65,-37.03,-0.009
168.69,-36.95,-0.009
168.73,-36.87,-0.009
168.77,-36.79,-0.009
168.81,-36.71,-0.009
168.85,-36.63,-0.009
168.89,-36.55,-0.009
168.93,-36.47,-0.009
168.97,-36.39,-0.009
169.01,-36.31,-0.009
169.05,-36.23,-0.009
169.09,-36.15,-0.009
169.13,-36.07,-0.009
169.17,-35.99,-0.009
169.21,-35.91,-0.010
169.25,-35.83,-0.010
169.29,-35.75,-0.010
169.33,-35.67,-0.010
169.37,-35.59,-0.010
169.41,-35.51,-0.010
169.45,-35.43,-0.010
169.49,-35.35,-0.010
169.53,-35.27,-0.010
169.57,-35.19,-0.010
169.61,-35.11,-0.010
169.65,-35.03,-0.010
169.69,-34.95,-0.010
169.73,-34.87,-0.010
169.77,-34.79,-0.010
169.81,-34.71,-0.010
169.85,-34.63,-0.010
169.89,-34.55,-0.010
169.93,-34.47,-0.010
169.97,-34.39,-0.010
170.01,-34.31,-0.010
170.05,-34.23,-0.010
170.09,-34.15,-0.010
170.13,-34.07,-0.010
170.17,-33.99,-0.010
170.21,-33.91,-0.010
170.25,-33.83,-0.010
170.29,-33.75,-0.010
170.33,-33.67,-0.010
170.37,-33.59,-0.010
170.41,-33.51,-0.010
170.45,-33.43,-0.010
170.49,-33.35,-0.010
170.53,-33.27,-0.010
170.57,-33.19,-0.010
170.61,-33.11,-0.010
170.65,-33.03,-0.011
170.69,-32.95,-0.011
170.73,-32.87,-0.010
170.77,-32.79,-0.011
170.81,-32.71,-0.011
170.85,-32.63,-0.011
170.89,-32.55,-0.011
170.93,-32.47,-0.011
170.97,-32.39,-0.011
171.01,-32.31,-0.011
171.05,-32.23,-0.011
171.09,-32.15,-0.011
171.13,-32.07,-0.011
171.17,-31.99,-0.011
171.21,-31.91,-0.011
171.25,-31.83,-0.011
171.29,-31.75,-0.011
171.33,-31.67,-0.011
171.37,-31.59,-0.011
171.41,-31.51,-0.011
171.45,-31.43,-0.011
171.49,-31.35,-0.011
171.53,-31.27,-0.011
171.57,-31.19,-0.011
171.61,-31.11,-0.011
171.65,-31.03,-0.011
171.69,-30.95,-0.011
171.73,-30.87,-0.011
171.77,-30.79,-0.011
171.81,-30.71,-0.011
171.85,-30.63,-0.011
171.89,-30.55,-0.011
171.93,-30.47,-0.011
171.97,-30.39,-0.011
172.01,-30.31,-0.011
172.05,-30.23,-0.011
172.09,-30.15,-0.012
172.13,-30.07,-0.012
172.17,-29.99,-0.012
172.21,-29.91,-0.012
172.25,-29.83,-0.012
172.29,-29.75,-0.012
172.33,-29.67,-0.012
172.37,-29.59,-0.012
172.41,-29.51,-0.012
172.45,-29.43,-0.012
172.49,-29.35,-0.012
172.53,-29.27,-0.012
172.57,-29.19,-0.012
172.61,-29.10,-0.012
172.65,-29.03,-0.012
172.69,-28.95,-0.012
172.73,-28.87,-0.012
172.77,-28.78,-0.012
172.81,-28.70,-0.012
172.85,-28.62,-0.012
172.89,-28.54,-0.012
172.93,-28.46,-0.012
172.97,-28.38,-0.012
173.01,-28.30,-0.012
173.05,-28.22,-0.012
173.09,-28.14,-0.012
173.13,-28.06,-0.012
173.17,-27.98,-0.012
173.21,-27.90,-0.012
173.25,-27.82,-0.012
173.29,-27.74,-0.013
173.33,-27.66,-0.013
173.37,-27.58,-0.013
173.41,-27.50,-0.013
173.45,-27.42,-0.013
173.49,-27.34,-0.013
173.53,-27.26,-0.013
173.57,-27.18,-0.013
173.61,-27.10,-0.013
173.65,-27.02,-0.013
173.69,-26.94,-0.013
173.73,-26.86,-0.013
173.77,-26.78,-0.013
173.81,-26.70,-0.013
173.85,-26.62,-0.013
173.89,-26.54,-0.013
173.93,-26.46,-0.013
173.97,-26.38,-0.013
174.01,-26.30,-0.013
174.05,-26.22,-0.013
174.09,-26.14,-0.013
174.13,-26.06,-0.013
174.17,-25.98,-0.014
174.21,-25.90,-0.014
174.25,-25.82,-0.014
174.29,-25.74,-0.014
174.33,-25.66,-0.014
174.37,-25.58,-0.014
174.41,-25.50,-0.014
174.45,-25.42,-0.014
174.49,-25.34,-0.014
174.53,-25.26,-0.014
174.57,-25.18,-0.014
174.61,-25.10,-0.014
174.65,-25.02,-0.014
174.69,-24.94,-0.014
174.73,-24.86,-0.014
174.77,-24.78,-0.014
174.81,-24.70,-0.014
174.85,-24.62,-0.014
174.89,-24.54,-0.014
174.93,-24.46,-0.014
174.97,-24.38,-0.014
175.01,-24.30,-0.014
175.05,-24.22,-0.014
175.09,-24.14,-0.014
175.13,-24.06,-0.014
175.17,-23.98,-0.014
175.21,-23.90,-0.014
175.25,-23.82,-0.014
175.29,-23.74,-0.014
175.33,-23.66,-0.014
175.37,-23.58,-0.014
175.41,-23.50,-0.014
175.45,-23.42,-0.014
175.49,-23.34,-0.014
175.53,-23.26,-0.014
175.57,-23.18,-0.014
175.61,-23.10,-0.014
175.65,-23.02,-0.014
175.69,-22.94,-0.015
175.73,-22.86,-0.015
175.77,-22.78,-0.015
175.81,-22.70,-0.015
175.85,-22.62,-0.015
175.89,-22.54,-0.015
175.93,-22.46,-0.015
175.97,-22.38,-0.015
176.01,-22.30,-0.015
176.05,-22.22,-0.015
176.09,-22.14,-0.015
176.13,-22.06,-0.015
176.17,-21.98,-0.015
176.21,-21.90,-0.015
176.25,-21.82,-0.015
176.29,-21.74,-0.015
176.33,-21.66,-0.015
176.37,-21.58,-0.015
176.41,-21.50,-0.015
176.45,-21.42,-0.015
176.49,-21.34,-0.015
176.53,-21.26,-0.015
176.57,-21.18,-0.015
176.61,-21.10,-0.015
176.65,-21.02,-0.015
176.69,-20.94,-0.015
176.73,-20.86,-0.015
176.77,-20.78,-0.015
176.81,-20.70,-0.015
176.85,-20.62,-0.015
176.89,-20.54,-0.016
176.93,-20.46,-0.016
176.97,-20.38,-0.016
177.01,-20.30,-0.016
177.05,-20.22,-0.016
177.09,-20.14,-0.016
177.13,-20.06,-0.016
177.17,-19.98,-0.016
177.21,-19.90,-0.016
177.25,-19.82,-0.016
177.29,-19.74,-0.016
177.33,-19.66,-0.016
177.37,-19.58,-0.016
177.41,-19.50,-0.016
177.45,-19.42,-0.016
177.49,-19.34,-0.016
177.53,-19.26,-0.016
177.57,-19.18,-0.016
177.61,-19.10,-0.016
177.65,-19.02,-0.016
177.69,-18.94,-0.016
177.73,-18.86,-0.016
177.77,-18.78,-0.016
177.81,-18.70,-0.016
177.85,-18.62,-0.016
177.89,-18.54,-0.016
177.93,-18.46,-0.016
177.97,-18.38,-0.016
178.01,-18.30,-0.016
178.05,-18.22,-0.016
178.09,-18.14,-0.016
178.13,-18.06,-0.016
178.17,-17.98,-0.017
178.21,-17.90,-0.017
178.25,-17.82,-0.017
178.29,-17.74,-0.017
178.33,-17.66,-0.017
178.37,-17.58,-0.017
178.41,-17.50,-0.017
178.45,-17.42,-0.017
178.49,-17.34,-0.017
178.53,-17.26,-0.017
178.57,-17.18,-0.017
178.61,-17.10,-0.017
178.65,-17.02,-0.017
178.69,-16.94,-0.017
178.73,-16.86,-0.017
178.77,-16.78,-0.017
178.81,-16.70,-0.017
178.85,-16.62,-0.017
178.89,-16.54,-0.017
178.93,-16.46,-0.017
178.97,-16.38,-0.017
179.01,-16.30,-0.017
179.05,-16.22,-0.017
179.09,-16.14,-0.017
179.13,-16.06,-0.017
179.17,-15.98,-0.017
179.21,-15.90,-0.017
179.25,-15.82,-0.017
179.29,-15.74,-0.018
179.33,-15.65,-0.017
179.37,-15.58,-0.017
179.41,-15.50,-0.017
179.45,-15.42,-0.017
179.49,-15.34,-0.017
179.53,-15.26,-0.017
179.57,-15.18,-0.017
179.61,-15.10,-0.017
179.65,-15.02,-0.017
179.69,-14.94,-0.017
179.73,-14.86,-0.017
179.77,-14.77,-0.017
179.81,-14.69,-0.017
179.85,-14.61,-0.017
179.89,-14.54,-0.017
179.93,-14.46,-0.017
179.97,-14.38,-0.017
180.01,-14.29,-0.017
180.05,-14.21,-0.017
180.09,-14.13,-0.018
180.13,-14.05,-0.018
180.17,-13.98,-0.018
180.21,-13.89,-0.018
180.25,-13.81,-0.018
180.29,-13.73,-0.018
180.33,-13.65,-0.018
180.37,-13.57,-0.018
180.41,-13.49,-0.018
180.45,-13.41,-0.018
180.49,-13.33,-0.018
180.53,-13.25,-0.018
180.57,-13.17,-0.018
180.61,-13.09,-0.018
180.65,-13.01,-0.018
180.69,-12.93,-0.018
180.73,-12.85,-0.018
180.77,-12.77,-0.018
180.81,-12.69,-0.018
180.85,-12.62,-0.018
180.89,-12.53,-0.018
180.93,-12.45,-0.018
180.97,-12.37,-0.018
181.01,-12.29,-0.018
181.05,-12.21,-0.018
181.09,-12.13,-0.018
181.13,-12.05,-0.018
181.17,-11.97,-0.018
181.21,-11.89,-0.018
181.25,-11.81,-0.018
181.29,-11.73,-0.018
181.33,-11.65,-0.018
181.37,-11.57,-0.018
181.41,-11.49,-0.018
181.45,-11.41,-0.018
181.49,-11.33,-0.018
181.53,-11.25,-0.018
181.57,-11.17,-0.018
181.61,-11.09,-0.018
181.65,-11.01,-0.018
181.69,-10.93,-0.018
181.73,-10.85,-0.018
181.77,-10.77,-0.018
181.81,-10.69,-0.018
181.85,-10.61,-0.019
181.89,-10.53,-0.019
181.93,-10.45,-0.019
181.97,-10.37,-0.019
182.01,-10.29,-0.019
182.05,-10.21,-0.019
182.09,-10.13,-0.019
182.13,-10.05,-0.019
182.17,-9.97,-0.019
182.21,-9.89,-0.019
182.25,-9.81,-0.019
182.29,-9.73,-0.019
182.33,-9.65,-0.019
182.37,-9.57,-0.019
182.41,-9.49,-0.019
182.45,-9.41,-0.019
182.49,-9.33,-0.019
182.53,-9.25,-0.019
182.57,-9.17,-0.019
182.61,-9.09,-0.019
182.65,-9.01,-0.020
182.69,-8.93,-0.019
182.73,-8.85,-0.019
182.77,-8.77,-0.019
182.81,-8.69,-0.019
182.85,-8.61,-0.020
182.89,-8.53,-0.019
182.93,-8.45,-0.019
182.97,-8.37,-0.019
183.01,-8.29,-0.019
183.05,-8.21,-0.019
183.09,-8.13,-0.019
183.13,-8.05,-0.019
183.17,-7.97,-0.020
183.21,-7.89,-0.020
183.25,-7.81,-0.020
183.29,-7.73,-0.020
183.33,-7.65,-0.020
183.37,-7.57,-0.020
183.41,-7.49,-0.020
183.45,-7.41,-0.020
183.49,-7.33,-0.020
183.53,-7.25,-0.020
183.57,-7.17,-0.020
183.61,-7.09,-0.020
183.65,-7.01,-0.020
183.69,-6.93,-0.020
183.73,-6.85,-0.020
183.77,-6.77,-0.020
183.81,-6.69,-0.020
183.85,-6.61,-0.020
183.89,-6.53,-0.020
183.93,-6.45,-0.020
183.97,-6.37,-0.020
184.01,-6.29,-0.020
184.05,-6.21,-0.021
184.09,-6.13,-0.021
184.13,-6.05,-0.020
184.17,-5.97,-0.021
184.21,-5.89,-0.021
184.25,-5.81,-0.021
184.29,-5.72,-0.021
184.33,-5.65,-0.020
184.37,-5.57,-0.020
184.41,-5.49,-0.020
184.45,-5.41,-0.020
184.49,-5.33,-0.020
184.53,-5.25,-0.020
184.57,-5.17,-0.020
184.61,-5.09,-0.021
184.65,-5.01,-0.021
184.69,-4.93,-0.021
184.73,-4.85,-0.021
184.77,-4.77,-0.021
184.81,-4.69,-0.021
184.85,-4.61,-0.021
184.89,-4.53,-0.021
184.93,-4.45,-0.021
184.97,-4.37,-0.021
185.01,-4.29,-0.021
185.05,-4.21,-0.021
185.09,-4.13,-0.021
185.13,-4.05,-0.021
185.17,-3.97,-0.021
185.21,-3.89,-0.021
185.25,-3.81,-0.021
185.29,-3.73,-0.021
185.33,-3.65,-0.021
185.37,-3.57,-0.021
185.41,-3.49,-0.021
185.45,-3.41,-0.021
185.49,-3.33,-0.021
185.53,-3.25,-0.021
185.57,-3.17,-0.021
185.61,-3.09,-0.021
185.65,-3.01,-0.022
185.69,-2.93,-0.022
185.73,-2.85,-0.022
185.77,-2.77,-0.022
185.81,-2.69,-0.022
185.85,-2.61,-0.022
185.89,-2.53,-0.022
185.93,-2.45,-0.022
185.97,-2.37,-0.022
186.01,-2.29,-0.021
186.05,-2.21,-0.021
186.09,-2.13,-0.021
186.13,-2.05,-0.021
186.17,-1.97,-0.021
186.21,-1.89,-0.021
186.25,-1.81,-0.021
186.29,-1.73,-0.021
186.33,-1.65,-0.020
186.37,-1.57,-0.020
186.41,-1.49,-0.020
186.45,-1.41,-0.020
186.49,-1.33,-0.020
186.53,-1.25,-0.020
186.57,-1.17,-0.020
186.61,-1.09,-0.020
186.65,-1.01,-0.021
186.69,-0.93,-0.021
186.73,-0.85,-0.021
186.77,-0.77,-0.021
186.81,-0.69,-0.021
186.85,-0.61,-0.021
186.89,-0.53,-0.021
186.93,-0.45,-0.022
186.97,-0.37,-0.022
187.01,-0.29,-0.022
187.05,-0.21,-0.022
187.09,-0.13,-0.022
187.13,-0.05,-0.022
187.17,0.03,-0.022
187.21,0.11,-0.022
187.25,0.19,-0.022
187.29,0.27,-0.022
187.33,0.35,-0.022
187.37,0.43,-0.022
187.41,0.51,-0.022
187.45,0.59,-0.022
187.49,0.67,-0.022
187.53,0.75,-0.022
187.57,0.83,-0.022
187.61,0.92,-0.022
187.65,0.99,-0.022
187.69,1.07,-0.022
187.73,1.15,-0.022
187.77,1.23,-0.022
187.81,1.31,-0.022
187.85,1.39,-0.022
187.89,1.48,-0.022
187.93,1.55,-0.022
187.97,1.63,-0.022
188.01,1.71,-0.022
188.05,1.79,-0.022
188.09,1.88,-0.022
188.13,1.95,-0.022
188.17,2.03,-0.023
188.21,2.12,-0.023
188.25,2.19,-0.023
188.29,2.27,-0.023
188.33,2.35,-0.023
188.37,2.43,-0.023
188.41,2.52,-0.023
188.45,2.60,-0.023
188.49,2.67,-0.023
188.53,2.76,-0.023
188.57,2.84,-0.023
188.61,2.91,-0.023
188.65,2.99,-0.023
188.69,3.08,-0.023
188.73,3.16,-0.023
188.77,3.23,-0.023
188.81,3.32,-0.023
188.85,3.40,-0.023
188.89,3.48,-0.023
188.93,3.56,-0.023
188.97,3.64,-0.023
189.01,3.72,-0.023
189.05,3.80,-0.023
189.09,3.88,-0.023
189.13,3.96,-0.023
189.17,4.03,-0.023
189.21,4.12,-0.023
189.25,4.20,-0.023
189.29,4.28,-0.023
189.33,4.36,-0.023
189.37,4.43,-0.024
189.41,4.52,-0.024
189.45,4.60,-0.024
189.49,4.68,-0.024
189.53,4.76,-0.024
189.57,4.84,-0.024
189.61,4.92,-0.024
189.65,5.00,-0.024
189.69,5.08,-0.024
189.73,5.16,-0.024
189.77,5.24,-0.024
189.81,5.32,-0.024
189.85,5.40,-0.024
189.89,5.48,-0.024
189.93,5.56,-0.024
189.97,5.64,-0.024
190.01,5.72,-0.024
190.05,5.80,-0.024
190.09,5.88,-0.024
190.13,5.96,-0.024
190.17,6.04,-0.024
190.21,6.12,-0.024
190.25,6.20,-0.024
190.29,6.28,-0.024
190.33,6.36,-0.024
190.37,6.44,-0.024
190.41,6.52,-0.024
190.45,6.60,-0.024
190.49,6.68,-0.024
190.53,6.76,-0.024
190.57,6.84,-0.024
190.61,6.92,-0.024
190.65,7.00,-0.024
190.69,7.08,-0.024
190.73,7.16,-0.024
190.77,7.24,-0.024
190.81,7.32,-0.024
190.85,7.40,-0.024
190.89,7.48,-0.024
190.93,7.56,-0.024
190.97,7.64,-0.024
191.01,7.72,-0.025
191.05,7.80,-0.024
191.09,7.88,-0.024
191.13,7.96,-0.024
191.17,8.04,-0.024
191.21,8.12,-0.024
191.25,8.20,-0.024
191.29,8.28,-0.024
191.33,8.36,-0.025
191.37,8.44,-0.025
191.41,8.52,-0.025
191.45,8.60,-0.025
191.49,8.68,-0.024
191.53,8.76,-0.024
191.57,8.84,-0.025
191.61,8.92,-0.025
191.65,9.00,-0.025
191.69,9.08,-0.025
191.73,9.16,-0.025
191.77,9.24,-0.025
191.81,9.32,-0.025
191.85,9.40,-0.025
191.89,9.48,-0.025
191.93,9.56,-0.025
191.97,9.64,-0.025
192.01,9.72,-0.025
192.05,9.80,-0.025
192.09,9.88,-0.025
192.13,9.96,-0.025
192.17,10.04,-0.025
192.21,10.12,-0.025
192.25,10.20,-0.025
192.29,10.28,-0.025
192.33,10.36,-0.025
192.37,10.44,-0.025
192.41,10.52,-0.025
192.45,10.60,-0.025
192.49,10.68,-0.025
192.53,10.76,-0.025
192.57,10.84,-0.025
192.61,10.92,-0.025
192.65,11.00,-0.025
192.69,11.08,-0.025
192.73,11.16,-0.025
192.77,11.24,-0.025
192.81,11.32,-0.025
192.85,11.40,-0.025
192.89,11.48,-0.025
192.93,11.56,-0.025
192.97,11.64,-0.025
193.01,11.72,-0.025
193.05,11.80,-0.025
193.09,11.88,-0.025
193.13,11.96,-0.025
193.17,12.04,-0.025
193.21,12.12,-0.026
193.25,12.20,-0.025
193.29,12.28,-0.025
193.33,12.36,-0.025
193.37,12.44,-0.026
193.41,12.52,-0.026
193.45,12.60,-0.025
193.49,12.68,-0.025
193.53,12.76,-0.025
193.57,12.84,-0.025
193.61,12.92,-0.025
193.65,13.00,-0.025
193.69,13.08,-0.025
193.73,13.16,-0.025
193.77,13.24,-0.025
193.81,13.32,-0.025
193.85,13.40,-0.025
193.89,13.48,-0.025
193.93,13.56,-0.025
193.97,13.64,-0.025
194.01,13.72,-0.025
194.05,13.80,-0.026
194.09,13.88,-0.026
194.13,13.96,-0.026
194.17,14.04,-0.026
194.21,14.12,-0.026
194.25,14.20,-0.026
194.29,14.28,-0.026
194.33,14.36,-0.026
194.37,14.44,-0.026
194.41,14.52,-0.026
194.45,14.60,-0.026
194.49,14.68,-0.026
194.53,14.76,-0.026
194.57,14.84,-0.026
194.61,14.92,-0.026
194.65,15.00,-0.026
194.69,15.08,-0.026
194.73,15.16,-0.026
194.77,15.24,-0.026
194.81,15.32,-0.026
194.85,15.40,-0.026
194.89,15.48,-0.026
194.93,15.56,-0.026
194.97,15.64,-0.026
195.01,15.72,-0.026
195.05,15.80,-0.026
195.09,15.88,-0.026
195.13,15.96,-0.026
195.17,16.04,-0.026
195.21,16.12,-0.026
195.25,16.20,-0.026
195.29,16.28,-0.027
195.33,16.36,-0.026
195.37,16.44,-0.026
195.41,16.52,-0.027
195.45,16.60,-0.027
195.49,16.68,-0.026
195.53,16.76,-0.026
195.57,16.84,-0.026
195.61,16.92,-0.027
195.65,17.00,-0.027
195.69,17.08,-0.027
195.73,17.16,-0.027
195.77,17.24,-0.027
195.81,17.32,-0.027
195.85,17.40,-0.027
195.89,17.48,-0.027
195.93,17.56,-0.027
195.97,17.64,-0.027
196.01,17.72,-0.027
196.05,17.80,-0.027
196.09,17.88,-0.027
196.13,17.96,-0.027
196.17,18.04,-0.027
196.21,18.12,-0.027
196.25,18.20,-0.027
196.29,18.28,-0.027
196.33,18.36,-0.027
196.37,18.44,-0.027
196.41,18.52,-0.027
196.45,18.60,-0.027
196.49,18.68,-0.027
196.53,18.76,-0.027
196.57,18.84,-0.027
196.61,18.92,-0.027
196.65,19.00,-0.027
196.69,19.08,-0.027
196.73,19.16,-0.027
196.77,19.24,-0.027
196.81,19.32,-0.027
196.85,19.40,-0.027
196.89,19.48,-0.027
196.93,19.56,-0.027
196.97,19.65,-0.027
197.01,19.73,-0.027
197.05,19.81,-0.027
197.09,19.88,-0.027
197.13,19.96,-0.027
197.17,20.04,-0.027
197.21,20.13,-0.027
197.25,20.21,-0.027
197.29,20.29,-0.027
197.33,20.36,-0.027
197.37,20.44,-0.027
197.41,20.52,-0.027
197.45,20.60,-0.027
197.49,20.68,-0.027
197.53,20.76,-0.027
197.57,20.84,-0.027
197.61,20.92,-0.027
197.65,21.00,-0.027
197.69,21.08,-0.027
197.73,21.16,-0.027
197.77,21.24,-0.027
197.81,21.32,-0.027
197.85,21.40,-0.027
197.89,21.48,-0.027
197.93,21.56,-0.027
197.97,21.64,-0.027
198.01,21.72,-0.027
198.05,21.80,-0.027
198.09,21.88,-0.028
198.13,21.96,-0.028
198.17,22.05,-0.028
198.21,22.12,-0.027
198.25,22.20,-0.028
198.29,22.28,-0.028
198.33,22.36,-0.028
198.37,22.45,-0.028
198.41,22.53,-0.028
198.45,22.60,-0.028
198.49,22.68,-0.028
198.53,22.76,-0.028
198.57,22.84,-0.028
198.61,22.93,-0.028
198.65,23.01,-0.028
198.69,23.09,-0.028
198.73,23.17,-0.028
198.77,23.25,-0.028
198.81,23.33,-0.028
198.85,23.41,-0.028
198.89,23.48,-0.028
198.93,23.57,-0.028
198.97,23.65,-0.028
199.01,23.73,-0.028
199.05,23.81,-0.028
199.09,23.89,-0.028
199.13,23.97,-0.028
199.17,24.05,-0.028
199.21,24.13,-0.028
199.25,24.21,-0.028
199.29,24.29,-0.028
199.33,24.37,-0.028
199.37,24.45,-0.028
199.41,24.53,-0.028
199.45,24.61,-0.028
199.49,24.69,-0.028
199.53,24.77,-0.028
199.57,24.85,-0.028
199.61,24.93,-0.028
199.65,25.01,-0.028
199.69,25.09,-0.028
199.73,25.17,-0.028
199.77,25.25,-0.029
199.81,25.33,-0.028
199.85,25.41,-0.028
199.89,25.49,-0.028
199.93,25.57,-0.028
199.97,25.65,-0.028
200.01,25.73,-0.028
200.05,25.81,-0.028
200.09,25.89,-0.028
200.13,25.97,-0.028
200.17,26.05,-0.028
200.21,26.13,-0.028
200.25,26.21,-0.028
200.29,26.29,-0.028
200.33,26.37,-0.028
200.37,26.45,-0.028
200.41,26.53,-0.028
200.45,26.61,-0.028
200.49,26.69,-0.028
200.53,26.77,-0.029
200.57,26.85,-0.028
200.61,26.93,-0.028
200.65,27.01,-0.029
200.69,27.09,-0.029
200.73,27.17,-0.029
200.77,27.25,-0.029
200.81,27.33,-0.029
200.85,27.41,-0.028
200.89,27.49,-0.029
200.93,27.57,-0.029
200.97,27.65,-0.029
201.01,27.73,-0.029
201.05,27.81,-0.029
201.09,27.89,-0.029
201.13,27.97,-0.029
201.17,28.05,-0.029
201.21,28.13,-0.029
201.25,28.21,-0.029
201.29,28.29,-0.029
201.33,28.37,-0.029
201.37,28.45,-0.029
201.41,28.53,-0.029
201.45,28.61,-0.029
201.49,28.69,-0.029
201.53,28.77,-0.029
201.57,28.85,-0.029
201.61,28.93,-0.029
201.65,29.01,-0.029
201.69,29.09,-0.029
201.73,29.17,-0.029
201.77,29.25,-0.029
201.81,29.33,-0.029
201.85,29.41,-0.029
201.89,29.49,-0.029
201.93,29.57,-0.029
201.97,29.65,-0.029
202.01,29.73,
202.05,,