File: DSC/2025_06_19_Indium_Wire_0_175C_10Cmin_x3.csv
Filename,2025_06_19_Indium_Wire_0_175C_10Cmin_x3
Instrument name,DSC2A-00468 (192.168.1.100)
Operator,Gibbons
rundate,6/19/2025
Sample name,2025_06_19_Indium_Wire_0_175C_10Cmin_x3
proceduresegments,Data Off ; Equilibrate 30.00 °C; Data On ; Ramp 10.00 °C/min to 200.00 °C; Data Off ; Isothermal 1.0 min; Data On ; Ramp 10.00 °C/min to 30.00 °C; Data Off ; Isothermal 1.0 min; Data On ; Ramp 10.00 °C/min to 200.00 °C; Data Off ; Isothermal 1.0 min; Data On ; Ramp 10.00 °C/min to 30.00 °C; Data Off ; Isothermal 1.0 min; Data On ; Ramp 10.00 °C/min to 200.00 °C; Data Off ; Isothermal 1.0 min; Data On ; Ramp 10.00 °C/min to 30.00 °C
[File Parameters]
Run date,6/19/2025 4:19:08 PM
Trios version,5.1.1.46572
Original File Name,
Current File Name,D:\DSC2500\Gibbons\2025_06_19_Indium_Wire_0_175C_10Cmin_x3.tri
[Procedure]
Procedure Name,Indium_30_200C_10Cmin_3x
Sample Name,2025_06_19_Indium_Wire_0_175C_10Cmin_x3
Sample Mass,10.76 mg
Reference Sample Mass,0 mg
Pan Mass,55.75 mg
Pan Number,51
Reference Pan Mass,55.79 mg
Reference Pan Number,1
Pan Type,Tzero Aluminum Hermetic
Comments,Al Hermetic DSC Consumables sealed Pan/Lid. A2 Tray (Google Sheet: DSC_Samples_A2_Tray_May2025)
Project Name,CA
Operator,Gibbons
Test,Custom
Unload Max Temperature,30
Unload Min Temperature,30
Load Max Temperature,30
Load Min Temperature,30
Stop on Gas Flow Error,Yes
[Signal List]
Signal #1,Time (min)
Signal #2,Temperature (°C)
Signal #3,Heat Flow (mW)
Signal #4,Delta T (µV)
Signal #5,Delta Tzero (µV)
Signal #6,Tzero Temperature (°C)
Signal #7,Cell Purge (mL/min)
Signal #8,Heater Temp (°C)
Signal #9,Power Delivered (W)
Signal #10,Reference Junction Temperature (°C)
Signal #11,Flange Temperature (°C)
Signal #12,Heat Flow Phase (rad)
Signal #13,Total Heat Capacity (J/°C)
Signal #14,Heat Capacity (J/°C)
[Configuration]
Company Name,ASU
Instrument Name,DSC2A-00468
Instrument Type,DSC2500
Serial Number,DSC2A-00468
IP,192.168.1.100
Location of Instrument,MRRC
DisplayType,Unknown
Sample Interval ,0.1 s/pt
Selected Heat Flow,T4P
Exotherm Direction,Down
Cell Serial,DRC2-00792
Lid Type,Standard
Cooler,RCS 90
Leave Cooler on at End of Sequence,On
Gas 2,Nitrogen
Gas Selected,Channel 1
Flow Rate,50 mL/min
Secondary Purge,On
Licensed Heat Flow,Heat Flow T4P
Modulation Licensed,Yes
[Versions]
Common IDD Version,1
Cortex Version,VER 2.10.2.31
Driver,5.0.0.6
GDM Version,1.0.3.3
TouchscreenVersion,1.0.0.16145
FEP Version,1.2.1.21
FEP Bootloader,2.0.0.5
AutoSampler Version,2.1.1.26
Auto Sampler Bootloader,2.0.0.5
FCM Version,1.1.0.3
FCM Bootloader,2.0.0.5
[Experiment Logs]
Experiment Log Entry # 1,Air Cool is off.
Experiment Log Entry # 3,Data On set to 0
Experiment Log Entry # 5,Equilibrate Segment 30 (C) Started
Experiment Log Entry # 7,Data On set to 1
Experiment Log Entry # 9,Ramp Segment 10 C/min to 200 Started
Experiment Log Entry # 11,Data On set to 0
Experiment Log Entry # 13,Isothermal Segment 1 min started
Experiment Log Entry # 15,Data On set to 1
Experiment Log Entry # 17,Ramp Segment 10 C/min to 30 Started
Experiment Log Entry # 19,Data On set to 0
Experiment Log Entry # 21,Isothermal Segment 1 min started
Experiment Log Entry # 23,Data On set to 1
Experiment Log Entry # 25,Ramp Segment 10 C/min to 200 Started
Experiment Log Entry # 27,Data On set to 0
Experiment Log Entry # 29,Isothermal Segment 1 min started
Experiment Log Entry # 31,Data On set to 1
Experiment Log Entry # 33,Ramp Segment 10 C/min to 30 Started
Experiment Log Entry # 35,Data On set to 0
Experiment Log Entry # 37,Isothermal Segment 1 min started
Experiment Log Entry # 39,Data On set to 1
Experiment Log Entry # 41,Ramp Segment 10 C/min to 200 Started
Experiment Log Entry # 43,Data On set to 0
Experiment Log Entry # 45,Isothermal Segment 1 min started
Experiment Log Entry # 47,Data On set to 1
Experiment Log Entry # 49,Ramp Segment 10 C/min to 30 Started
[Method Log]
Method Log Entry # 1,Data Off
Method Log Entry # 2,Equilibrate 30 °C
Method Log Entry # 3,Data On
Method Log Entry # 4,(Ramp 622059) Ramp 10 °C/minute to 200 °C
Method Log Entry # 5,Data Off
Method Log Entry # 6,Isothermal 1 minutes
Method Log Entry # 7,Data On
Method Log Entry # 8,(Ramp 622063) Ramp 10 °C/minute to 30 °C
Method Log Entry # 9,Data Off
Method Log Entry # 10,Isothermal 1 minutes
Method Log Entry # 11,Data On
Method Log Entry # 12,(Ramp 622067) Ramp 10 °C/minute to 200 °C
Method Log Entry # 13,Data Off
Method Log Entry # 14,Isothermal 1 minutes
Method Log Entry # 15,Data On
Method Log Entry # 16,(Ramp 622071) Ramp 10 °C/minute to 30 °C
Method Log Entry # 17,Data Off
Method Log Entry # 18,Isothermal 1 minutes
Method Log Entry # 19,Data On
Method Log Entry # 20,(Ramp 622075) Ramp 10 °C/minute to 200 °C
Method Log Entry # 21,Data Off
Method Log Entry # 22,Isothermal 1 minutes
Method Log Entry # 23,Data On
Method Log Entry # 24,(Ramp 622079) Ramp 10 °C/minute to 30 °C
Cell Serial,DRC2-00792
[T1 Calibration]
Slope,-0.008529666
Offset,9.636258
Initial Temperature,98.23
GUID,f8bfdadc-4977-4fdf-ba6d-0ba9134940c3
[TZero Calibration]
Date Applied,11/29/2022 4:06:13 PM
Description,From -89.059 °C to 396.009 °C at 20.000°C/min
Gas Type,Nitrogen
Pan Type,None
Source Files 1,C:\Users\yargerlab\Desktop\DSC Data\General\TZero_calibration_11_29_22_2nd(2).tri
Source Files 2,C:\Users\yargerlab\Desktop\DSC Data\General\TZero_calibration_11_29_22_2nd(3).tri
Delta T Offset,13.05235
Delta T Slope,-0.007271007
Delta T0 Offset,-13.69128
Delta T0 Slope,0.06063341
[Temperature Calibration]
Date Applied,11/29/2022 7:12:28 PM
Description,From 106.590 °C to 186.590 °C at 10.000°C/min
Gas Type,Nitrogen
Pan Type,Tzero Aluminum Hermetic
Source Files 1,C:\Users\yargerlab\Desktop\DSC Data\General\Indium(6).tri
Measured 1,157.391
Known 1,156.598
[Cell Constant Calibration]
Date Applied,11/29/2022 7:12:29 PM
Description,From 106.590 °C to 186.590 °C at 10.000°C/min
Gas Type,Nitrogen
Pan Type,Tzero Aluminum Hermetic
Source Files 1,C:\Users\yargerlab\Desktop\DSC Data\General\Indium(6).tri
T4P KCell,1.006051
Onset Slope,63.26126 mW/°C
[Direct Cp Calibration]
Date Applied,11/30/2022 11:04:51 AM
Description,From -79.983 °C to 298.409 °C at 10.000°C/min
Gas Type,Nitrogen
Pan Type,Tzero Aluminum Hermetic
Source Files 1,C:\Users\yargerlab\Desktop\DSC Data\General\Sapphire_Heat_Capacity_11_30_22.tri
[Rev Cp Calibration]
Date Applied,11/30/2022 1:58:51 PM
Description,From -79.996 °C to 292.812 °C at 3.000°C/min
Gas Type,Nitrogen
Pan Type,Tzero Aluminum Hermetic
Source Files 1,C:\Users\yargerlab\Desktop\DSC Data\General\Sapphire_MDSC_Calibration_11_30_22.tri
[step]
Ramp 10.00 °C/min to 200.00 °C
Time,Temperature,Heat Flow (Normalized)
min,°C,W/g
0.00,29.96,0.007
0.01,29.96,0.005
0.02,29.97,0.004
0.03,29.98,0.002
0.05,30.00,-0.006
0.06,30.02,-0.019
0.07,30.05,-0.039
0.08,30.08,-0.062
0.09,30.13,-0.086
0.11,30.19,-0.108
0.12,30.26,-0.126
0.13,30.33,-0.137
0.14,30.41,-0.141
0.15,30.50,-0.141
0.16,30.59,-0.135
0.18,30.68,-0.127
0.19,30.77,-0.119
0.20,30.87,-0.111
0.21,30.96,-0.103
0.22,31.06,-0.097
0.23,31.16,-0.091
0.24,31.26,-0.087
0.26,31.37,-0.083
0.27,31.47,-0.080
0.28,31.58,-0.076
0.29,31.68,-0.073
0.30,31.79,-0.070
0.31,31.90,-0.067
0.33,32.01,-0.064
0.34,32.12,-0.062
0.35,32.23,-0.058
0.36,32.34,-0.057
0.37,32.45,-0.055
0.39,32.57,-0.053
0.40,32.68,-0.051
0.41,32.79,-0.050
0.42,32.91,-0.049
0.43,33.02,-0.048
0.44,33.14,-0.047
0.45,33.25,-0.045
0.47,33.36,-0.044
0.48,33.48,-0.044
0.49,33.59,-0.043
0.50,33.71,-0.041
0.51,33.82,-0.041
0.53,33.94,-0.041
0.54,34.05,-0.040
0.55,34.17,-0.040
0.56,34.28,-0.040
0.57,34.40,-0.039
0.58,34.52,-0.039
0.60,34.63,-0.039
0.61,34.75,-0.039
0.62,34.86,-0.038
0.63,34.98,-0.038
0.64,35.09,-0.038
0.65,35.21,-0.038
0.67,35.33,-0.038
0.68,35.44,-0.038
0.69,35.56,-0.038
0.70,35.67,-0.038
0.71,35.79,-0.038
0.72,35.91,-0.037
0.73,36.02,-0.037
0.75,36.14,-0.037
0.76,36.26,-0.037
0.77,36.37,-0.037
0.78,36.49,-0.037
0.79,36.60,-0.037
0.80,36.72,-0.037
0.82,36.84,-0.037
0.83,36.95,-0.037
0.84,37.07,-0.037
0.85,37.19,-0.037
0.86,37.30,-0.037
0.88,37.42,-0.037
0.89,37.54,-0.036
0.90,37.65,-0.036
0.91,37.77,-0.036
0.92,37.89,-0.036
0.93,38.00,-0.036
0.95,38.12,-0.036
0.96,38.23,-0.036
0.97,38.35,-0.036
0.98,38.47,-0.036
0.99,38.58,-0.036
1.00,38.70,-0.036
1.02,38.81,-0.036
1.03,38.93,-0.036
1.04,39.05,-0.036
1.05,39.16,-0.036
1.06,39.28,-0.036
1.07,39.40,-0.036
1.08,39.51,-0.036
1.10,39.63,-0.036
1.11,39.75,-0.036
1.12,39.86,-0.036
1.13,39.98,-0.036
1.14,40.10,-0.036
1.16,40.21,-0.036
1.17,40.33,-0.036
1.18,40.45,-0.036
1.19,40.56,-0.036
1.20,40.68,-0.036
1.21,40.80,-0.036
1.23,40.91,-0.036
1.24,41.03,-0.036
1.25,41.15,-0.036
1.26,41.26,-0.036
1.27,41.38,-0.036
1.28,41.50,-0.036
1.29,41.61,-0.036
1.31,41.73,-0.036
1.32,41.84,-0.036
1.33,41.96,-0.036
1.34,42.08,-0.036
1.35,42.20,-0.036
1.37,42.31,-0.036
1.38,42.43,-0.036
1.39,42.55,-0.036
1.40,42.66,-0.036
1.41,42.78,-0.036
1.42,42.90,-0.036
1.43,43.01,-0.036
1.45,43.13,-0.036
1.46,43.25,-0.036
1.47,43.36,-0.036
1.48,43.48,-0.036
1.49,43.60,-0.036
1.51,43.71,-0.036
1.52,43.83,-0.036
1.53,43.95,-0.036
1.54,44.06,-0.036
1.55,44.18,-0.036
1.56,44.29,-0.036
1.58,44.41,-0.036
1.59,44.53,-0.036
1.60,44.65,-0.036
1.61,44.76,-0.036
1.62,44.88,-0.036
1.63,44.99,-0.036
1.64,45.11,-0.036
1.66,45.23,-0.036
1.67,45.34,-0.036
1.68,45.46,-0.036
1.69,45.58,-0.037
1.70,45.70,-0.037
1.72,45.81,-0.037
1.73,45.93,-0.037
1.74,46.05,-0.037
1.75,46.16,-0.037
1.76,46.28,-0.037
1.77,46.40,-0.037
1.78,46.51,-0.037
1.80,46.63,-0.037
1.81,46.75,-0.037
1.82,46.86,-0.037
1.83,46.98,-0.037
1.84,47.10,-0.037
1.86,47.21,-0.037
1.87,47.33,-0.037
1.88,47.45,-0.037
1.89,47.56,-0.037
1.90,47.68,-0.037
1.91,47.80,-0.037
1.93,47.91,-0.037
1.94,48.03,-0.037
1.95,48.15,-0.037
1.96,48.26,-0.037
1.97,48.38,-0.037
1.98,48.50,-0.037
1.99,48.61,-0.037
2.01,48.73,-0.037
2.02,48.85,-0.037
2.03,48.96,-0.037
2.04,49.08,-0.037
2.05,49.20,-0.037
2.07,49.31,-0.037
2.08,49.43,-0.037
2.09,49.55,-0.037
2.10,49.66,-0.037
2.11,49.78,-0.037
2.12,49.90,-0.037
2.14,50.01,-0.037
2.15,50.13,-0.037
2.16,50.25,-0.037
2.17,50.37,-0.037
2.18,50.48,-0.037
2.19,50.60,-0.037
2.21,50.72,-0.037
2.22,50.83,-0.037
2.23,50.95,-0.037
2.24,51.07,-0.037
2.25,51.18,-0.037
2.26,51.30,-0.037
2.28,51.42,-0.037
2.29,51.53,-0.037
2.30,51.65,-0.037
2.31,51.77,-0.037
2.32,51.88,-0.037
2.33,52.00,-0.037
2.34,52.12,-0.037
2.36,52.23,-0.037
2.37,52.35,-0.037
2.38,52.47,-0.037
2.39,52.58,-0.037
2.40,52.70,-0.037
2.41,52.82,-0.037
2.43,52.93,-0.037
2.44,53.05,-0.037
2.45,53.17,-0.037
2.46,53.29,-0.037
2.47,53.40,-0.037
2.49,53.52,-0.037
2.50,53.64,-0.037
2.51,53.75,-0.038
2.52,53.87,-0.038
2.53,53.99,-0.037
2.54,54.10,-0.037
2.56,54.22,-0.038
2.57,54.33,-0.037
2.58,54.45,-0.037
2.59,54.57,-0.037
2.60,54.69,-0.038
2.61,54.80,-0.038
2.63,54.92,-0.038
2.64,55.04,-0.038
2.65,55.15,-0.038
2.66,55.27,-0.038
2.67,55.39,-0.038
2.68,55.50,-0.038
2.69,55.62,-0.038
2.71,55.74,-0.038
2.72,55.85,-0.038
2.73,55.97,-0.038
2.74,56.09,-0.038
2.75,56.20,-0.038
2.76,56.32,-0.038
2.78,56.44,-0.038
2.79,56.56,-0.038
2.80,56.67,-0.038
2.81,56.79,-0.038
2.82,56.90,-0.038
2.84,57.02,-0.038
2.85,57.14,-0.038
2.86,57.25,-0.038
2.87,57.37,-0.038
2.88,57.49,-0.038
2.89,57.61,-0.038
2.91,57.72,-0.038
2.92,57.84,-0.038
2.93,57.96,-0.038
2.94,58.07,-0.038
2.95,58.19,-0.038
2.96,58.31,-0.038
2.98,58.42,-0.038
2.99,58.54,-0.038
3.00,58.66,-0.038
3.01,58.77,-0.038
3.02,58.89,-0.038
3.03,59.01,-0.038
3.04,59.12,-0.038
3.06,59.24,-0.038
3.07,59.36,-0.038
3.08,59.47,-0.038
3.09,59.59,-0.038
3.10,59.71,-0.038
3.11,59.83,-0.038
3.13,59.94,-0.038
3.14,60.06,-0.038
3.15,60.17,-0.038
3.16,60.29,-0.038
3.17,60.41,-0.038
3.19,60.52,-0.038
3.20,60.64,-0.038
3.21,60.76,-0.038
3.22,60.88,-0.038
3.23,60.99,-0.038
3.24,61.11,-0.038
3.26,61.23,-0.038
3.27,61.34,-0.038
3.28,61.46,-0.038
3.29,61.58,-0.038
3.30,61.69,-0.038
3.31,61.81,-0.038
3.33,61.93,-0.038
3.34,62.04,-0.038
3.35,62.16,-0.038
3.36,62.28,-0.038
3.37,62.39,-0.038
3.38,62.51,-0.038
3.39,62.63,-0.038
3.41,62.74,-0.038
3.42,62.86,-0.038
3.43,62.98,-0.038
3.44,63.09,-0.038
3.45,63.21,-0.038
3.46,63.33,-0.038
3.48,63.44,-0.038
3.49,63.56,-0.038
3.50,63.68,-0.038
3.51,63.80,-0.038
3.52,63.91,-0.038
3.54,64.03,-0.038
3.55,64.15,-0.038
3.56,64.26,-0.039
3.57,64.38,-0.039
3.58,64.50,-0.039
3.59,64.61,-0.039
3.61,64.73,-0.039
3.62,64.85,-0.039
3.63,64.96,-0.039
3.64,65.08,-0.039
3.65,65.20,-0.039
3.66,65.31,-0.039
3.68,65.43,-0.039
3.69,65.55,-0.039
3.70,65.66,-0.039
3.71,65.78,-0.039
3.72,65.90,-0.039
3.73,66.01,-0.039
3.74,66.13,-0.039
3.76,66.25,-0.039
3.77,66.36,-0.039
3.78,66.48,-0.039
3.79,66.60,-0.039
3.80,66.72,-0.039
3.81,66.83,-0.039
3.83,66.95,-0.039
3.84,67.07,-0.039
3.85,67.18,-0.039
3.86,67.30,-0.039
3.87,67.42,-0.039
3.89,67.53,-0.039
3.90,67.65,-0.039
3.91,67.77,-0.039
3.92,67.88,-0.039
3.93,68.00,-0.039
3.94,68.12,-0.039
3.96,68.23,-0.039
3.97,68.35,-0.039
3.98,68.47,-0.039
3.99,68.58,-0.039
4.00,68.70,-0.039
4.01,68.82,-0.039
4.03,68.93,-0.039
4.04,69.05,-0.039
4.05,69.17,-0.039
4.06,69.29,-0.039
4.07,69.40,-0.039
4.08,69.52,-0.039
4.09,69.64,-0.039
4.11,69.75,-0.039
4.12,69.87,-0.039
4.13,69.98,-0.039
4.14,70.10,-0.039
4.15,70.22,-0.039
4.16,70.34,-0.039
4.18,70.45,-0.039
4.19,70.57,-0.039
4.20,70.69,-0.039
4.21,70.80,-0.039
4.22,70.92,-0.039
4.24,71.04,-0.039
4.25,71.15,-0.039
4.26,71.27,-0.039
4.27,71.39,-0.039
4.28,71.50,-0.039
4.29,71.62,-0.039
4.30,71.74,-0.039
4.32,71.86,-0.039
4.33,71.97,-0.039
4.34,72.09,-0.039
4.35,72.20,-0.039
4.36,72.32,-0.039
4.38,72.44,-0.039
4.39,72.55,-0.039
4.40,72.67,-0.039
4.41,72.79,-0.039
4.42,72.90,-0.039
4.43,73.02,-0.039
4.45,73.14,-0.039
4.46,73.26,-0.039
4.47,73.37,-0.039
4.48,73.49,-0.039
4.49,73.61,-0.039
4.50,73.72,-0.039
4.51,73.84,-0.039
4.53,73.96,-0.039
4.54,74.07,-0.039
4.55,74.19,-0.039
4.56,74.31,-0.039
4.57,74.42,-0.039
4.59,74.54,-0.039
4.60,74.66,-0.039
4.61,74.77,-0.039
4.62,74.89,-0.039
4.63,75.01,-0.039
4.64,75.12,-0.039
4.65,75.24,-0.039
4.67,75.36,-0.039
4.68,75.47,-0.039
4.69,75.59,-0.039
4.70,75.71,-0.039
4.71,75.83,-0.039
4.73,75.94,-0.039
4.74,76.06,-0.039
4.75,76.18,-0.039
4.76,76.29,-0.039
4.77,76.41,-0.039
4.78,76.53,-0.039
4.80,76.64,-0.039
4.81,76.76,-0.039
4.82,76.88,-0.039
4.83,76.99,-0.039
4.84,77.11,-0.039
4.85,77.23,-0.039
4.86,77.34,-0.039
4.88,77.46,-0.039
4.89,77.58,-0.039
4.90,77.69,-0.039
4.91,77.81,-0.039
4.92,77.93,-0.039
4.94,78.04,-0.039
4.95,78.16,-0.039
4.96,78.28,-0.039
4.97,78.39,-0.039
4.98,78.51,-0.039
4.99,78.63,-0.039
5.00,78.74,-0.039
5.02,78.86,-0.039
5.03,78.98,-0.039
5.04,79.09,-0.039
5.05,79.21,-0.039
5.06,79.33,-0.039
5.08,79.44,-0.039
5.09,79.56,-0.039
5.10,79.68,-0.039
5.11,79.79,-0.039
5.12,79.91,-0.039
5.13,80.03,-0.039
5.15,80.15,-0.039
5.16,80.26,-0.039
5.17,80.38,-0.039
5.18,80.50,-0.039
5.19,80.61,-0.039
5.20,80.73,-0.039
5.21,80.85,-0.039
5.23,80.96,-0.039
5.24,81.08,-0.039
5.25,81.20,-0.039
5.26,81.31,-0.039
5.27,81.43,-0.039
5.29,81.55,-0.039
5.30,81.66,-0.039
5.31,81.78,-0.039
5.32,81.90,-0.040
5.33,82.01,-0.040
5.34,82.13,-0.040
5.35,82.25,-0.040
5.37,82.36,-0.040
5.38,82.48,-0.040
5.39,82.60,-0.040
5.40,82.71,-0.040
5.41,82.83,-0.040
5.43,82.95,-0.040
5.44,83.07,-0.040
5.45,83.18,-0.040
5.46,83.30,-0.040
5.47,83.42,-0.040
5.48,83.53,-0.040
5.50,83.65,-0.040
5.51,83.77,-0.040
5.52,83.88,-0.040
5.53,84.00,-0.040
5.54,84.12,-0.040
5.55,84.23,-0.040
5.56,84.35,-0.040
5.58,84.47,-0.040
5.59,84.58,-0.040
5.60,84.70,-0.040
5.61,84.82,-0.040
5.62,84.93,-0.040
5.64,85.05,-0.040
5.65,85.17,-0.040
5.66,85.28,-0.040
5.67,85.40,-0.040
5.68,85.52,-0.040
5.69,85.63,-0.040
5.70,85.75,-0.040
5.72,85.87,-0.040
5.73,85.98,-0.040
5.74,86.10,-0.040
5.75,86.22,-0.040
5.76,86.33,-0.040
5.78,86.45,-0.040
5.79,86.57,-0.040
5.80,86.69,-0.040
5.81,86.80,-0.040
5.82,86.92,-0.040
5.83,87.04,-0.040
5.85,87.15,-0.040
5.86,87.27,-0.040
5.87,87.39,-0.040
5.88,87.50,-0.040
5.89,87.62,-0.040
5.90,87.74,-0.040
5.91,87.85,-0.040
5.93,87.97,-0.040
5.94,88.09,-0.040
5.95,88.20,-0.040
5.96,88.32,-0.040
5.97,88.44,-0.040
5.99,88.55,-0.040
6.00,88.67,-0.040
6.01,88.79,-0.040
6.02,88.90,-0.040
6.03,89.02,-0.040
6.04,89.14,-0.040
6.05,89.25,-0.040
6.07,89.37,-0.040
6.08,89.49,-0.040
6.09,89.61,-0.040
6.10,89.72,-0.040
6.11,89.84,-0.040
6.13,89.95,-0.040
6.14,90.07,-0.040
6.15,90.19,-0.040
6.16,90.30,-0.040
6.17,90.42,-0.040
6.18,90.54,-0.040
6.20,90.65,-0.040
6.21,90.77,-0.040
6.22,90.89,-0.040
6.23,91.01,-0.040
6.24,91.12,-0.040
6.25,91.24,-0.040
6.26,91.36,-0.040
6.28,91.47,-0.040
6.29,91.59,-0.040
6.30,91.71,-0.040
6.31,91.82,-0.040
6.32,91.94,-0.040
6.34,92.06,-0.040
6.35,92.17,-0.040
6.36,92.29,-0.040
6.37,92.41,-0.040
6.38,92.52,-0.040
6.39,92.64,-0.040
6.40,92.76,-0.040
6.42,92.87,-0.040
6.43,92.99,-0.040
6.44,93.11,-0.040
6.45,93.22,-0.040
6.46,93.34,-0.040
6.48,93.46,-0.040
6.49,93.58,-0.040
6.50,93.69,-0.040
6.51,93.81,-0.040
6.52,93.93,-0.040
6.53,94.04,-0.040
6.55,94.16,-0.040
6.56,94.28,-0.040
6.57,94.39,-0.040
6.58,94.51,-0.040
6.59,94.63,-0.040
6.60,94.74,-0.040
6.61,94.86,-0.040
6.63,94.98,-0.040
6.64,95.09,-0.040
6.65,95.21,-0.040
6.66,95.33,-0.040
6.67,95.44,-0.040
6.69,95.56,-0.040
6.70,95.68,-0.040
6.71,95.79,-0.040
6.72,95.91,-0.040
6.73,96.03,-0.040
6.74,96.14,-0.040
6.75,96.26,-0.040
6.77,96.38,-0.040
6.78,96.50,-0.040
6.79,96.61,-0.040
6.80,96.73,-0.040
6.81,96.84,-0.040
6.83,96.96,-0.040
6.84,97.08,-0.040
6.85,97.20,-0.040
6.86,97.31,-0.040
6.87,97.43,-0.040
6.88,97.55,-0.040
6.90,97.66,-0.040
6.91,97.78,-0.040
6.92,97.89,-0.040
6.93,98.01,-0.040
6.94,98.13,-0.040
6.95,98.25,-0.040
6.96,98.36,-0.040
6.98,98.48,-0.040
6.99,98.60,-0.040
7.00,98.71,-0.040
7.01,98.83,-0.040
7.02,98.95,-0.040
7.04,99.06,-0.040
7.05,99.18,-0.040
7.06,99.30,-0.040
7.07,99.42,-0.040
7.08,99.53,-0.040
7.09,99.65,-0.040
7.10,99.77,-0.040
7.12,99.88,-0.040
7.13,100.00,-0.040
7.14,100.12,-0.040
7.15,100.23,-0.040
7.16,100.35,-0.039
7.18,100.46,-0.039
7.19,100.58,-0.038
7.20,100.70,-0.039
7.21,100.81,-0.039
7.22,100.93,-0.039
7.23,101.05,-0.039
7.25,101.16,-0.039
7.26,101.28,-0.039
7.27,101.40,-0.039
7.28,101.52,-0.039
7.29,101.63,-0.039
7.30,101.75,-0.039
7.31,101.87,-0.039
7.33,101.98,-0.039
7.34,102.10,-0.039
7.35,102.22,-0.039
7.36,102.33,-0.039
7.37,102.45,-0.039
7.39,102.57,-0.039
7.40,102.68,-0.039
7.41,102.80,-0.039
7.42,102.92,-0.039
7.43,103.03,-0.039
7.44,103.15,-0.039
7.45,103.27,-0.039
7.47,103.39,-0.039
7.48,103.50,-0.039
7.49,103.62,-0.039
7.50,103.74,-0.039
7.51,103.85,-0.039
7.53,103.97,-0.039
7.54,104.09,-0.039
7.55,104.20,-0.039
7.56,104.32,-0.039
7.57,104.44,-0.039
7.58,104.55,-0.039
7.60,104.67,-0.039
7.61,104.79,-0.039
7.62,104.90,-0.039
7.63,105.02,-0.039
7.64,105.14,-0.039
7.65,105.25,-0.039
7.66,105.37,-0.039
7.68,105.49,-0.039
7.69,105.60,-0.039
7.70,105.72,-0.039
7.71,105.84,-0.039
7.72,105.95,-0.039
7.74,106.07,-0.039
7.75,106.19,-0.039
7.76,106.30,-0.039
7.77,106.42,-0.039
7.78,106.54,-0.039
7.79,106.65,-0.039
7.80,106.77,-0.039
7.82,106.89,-0.039
7.83,107.00,-0.039
7.84,107.12,-0.039
7.85,107.24,-0.039
7.86,107.36,-0.039
7.88,107.47,-0.039
7.89,107.59,-0.039
7.90,107.71,-0.039
7.91,107.82,-0.039
7.92,107.94,-0.039
7.93,108.06,-0.039
7.95,108.17,-0.039
7.96,108.29,-0.039
7.97,108.41,-0.039
7.98,108.52,-0.039
7.99,108.64,-0.039
8.00,108.76,-0.039
8.01,108.87,-0.039
8.03,108.99,-0.039
8.04,109.11,-0.039
8.05,109.22,-0.039
8.06,109.34,-0.039
8.07,109.46,-0.039
8.09,109.57,-0.039
8.10,109.69,-0.039
8.11,109.81,-0.039
8.12,109.92,-0.039
8.13,110.04,-0.039
8.14,110.16,-0.039
8.15,110.27,-0.039
8.17,110.39,-0.039
8.18,110.51,-0.039
8.19,110.62,-0.039
8.20,110.74,-0.039
8.21,110.86,-0.039
8.23,110.97,-0.039
8.24,111.09,-0.039
8.25,111.21,-0.039
8.26,111.32,-0.039
8.27,111.44,-0.039
8.28,111.56,-0.039
8.30,111.67,-0.039
8.31,111.79,-0.039
8.32,111.91,-0.039
8.33,112.03,-0.039
8.34,112.14,-0.039
8.35,112.26,-0.040
8.36,112.38,-0.040
8.38,112.49,-0.040
8.39,112.61,-0.040
8.40,112.72,-0.040
8.41,112.84,-0.040
8.42,112.96,-0.040
8.44,113.08,-0.040
8.45,113.19,-0.040
8.46,113.31,-0.040
8.47,113.43,-0.040
8.48,113.54,-0.040
8.49,113.66,-0.040
8.50,113.78,-0.040
8.52,113.89,-0.040
8.53,114.01,-0.040
8.54,114.13,-0.040
8.55,114.24,-0.040
8.56,114.36,-0.040
8.58,114.48,-0.040
8.59,114.59,-0.040
8.60,114.71,-0.040
8.61,114.83,-0.040
8.62,114.94,-0.040
8.63,115.06,-0.040
8.65,115.18,-0.040
8.66,115.29,-0.040
8.67,115.41,-0.040
8.68,115.53,-0.040
8.69,115.65,-0.040
8.70,115.76,-0.040
8.72,115.88,-0.040
8.73,116.00,-0.040
8.74,116.11,-0.040
8.75,116.23,-0.040
8.76,116.35,-0.040
8.77,116.46,-0.040
8.78,116.58,-0.040
8.80,116.70,-0.040
8.81,116.81,-0.040
8.82,116.93,-0.040
8.83,117.05,-0.040
8.84,117.16,-0.040
8.85,117.28,-0.040
8.87,117.40,-0.040
8.88,117.51,-0.040
8.89,117.63,-0.040
8.90,117.75,-0.040
8.91,117.86,-0.040
8.93,117.98,-0.040
8.94,118.10,-0.040
8.95,118.21,-0.040
8.96,118.33,-0.040
8.97,118.45,-0.040
8.98,118.56,-0.040
9.00,118.68,-0.040
9.01,118.80,-0.040
9.02,118.91,-0.040
9.03,119.03,-0.040
9.04,119.15,-0.040
9.05,119.26,-0.040
9.07,119.38,-0.040
9.08,119.50,-0.040
9.09,119.61,-0.040
9.10,119.73,-0.040
9.11,119.85,-0.040
9.12,119.96,-0.040
9.13,120.08,-0.040
9.15,120.20,-0.040
9.16,120.31,-0.040
9.17,120.43,-0.040
9.18,120.55,-0.040
9.19,120.66,-0.040
9.20,120.78,-0.040
9.22,120.90,-0.040
9.23,121.01,-0.040
9.24,121.13,-0.040
9.25,121.25,-0.040
9.26,121.37,-0.040
9.28,121.48,-0.040
9.29,121.60,-0.040
9.30,121.72,-0.040
9.31,121.83,-0.040
9.32,121.95,-0.040
9.33,122.07,-0.040
9.35,122.18,-0.040
9.36,122.30,-0.040
9.37,122.42,-0.040
9.38,122.53,-0.040
9.39,122.65,-0.040
9.40,122.77,-0.040
9.42,122.88,-0.040
9.43,123.00,-0.040
9.44,123.12,-0.040
9.45,123.23,-0.040
9.46,123.35,-0.040
9.47,123.47,-0.040
9.48,123.58,-0.040
9.50,123.70,-0.040
9.51,123.82,-0.040
9.52,123.93,-0.040
9.53,124.05,-0.040
9.54,124.17,-0.040
9.55,124.28,-0.040
9.57,124.40,-0.040
9.58,124.52,-0.040
9.59,124.63,-0.040
9.60,124.75,-0.040
9.61,124.87,-0.040
9.63,124.98,-0.040
9.64,125.10,-0.040
9.65,125.22,-0.040
9.66,125.33,-0.040
9.67,125.45,-0.040
9.68,125.57,-0.040
9.70,125.69,-0.040
9.71,125.80,-0.040
9.72,125.92,-0.040
9.73,126.03,-0.040
9.74,126.15,-0.040
9.75,126.27,-0.040
9.77,126.39,-0.040
9.78,126.50,-0.040
9.79,126.62,-0.040
9.80,126.74,-0.040
9.81,126.85,-0.040
9.82,126.97,-0.040
9.83,127.09,-0.040
9.85,127.20,-0.040
9.86,127.32,-0.040
9.87,127.44,-0.040
9.88,127.55,-0.040
9.89,127.67,-0.040
9.90,127.79,-0.040
9.92,127.90,-0.040
9.93,128.02,-0.040
9.94,128.14,-0.040
9.95,128.25,-0.040
9.96,128.37,-0.040
9.98,128.49,-0.040
9.99,128.60,-0.040
10.00,128.72,-0.040
10.01,128.84,-0.040
10.02,128.95,-0.040
10.03,129.07,-0.040
10.05,129.19,-0.040
10.06,129.31,-0.040
10.07,129.42,-0.040
10.08,129.54,-0.040
10.09,129.66,-0.040
10.10,129.77,-0.041
10.12,129.89,-0.041
10.13,130.01,-0.041
10.14,130.12,-0.041
10.15,130.24,-0.041
10.16,130.36,-0.041
10.17,130.47,-0.041
10.18,130.59,-0.041
10.20,130.71,-0.041
10.21,130.82,-0.041
10.22,130.94,-0.041
10.23,131.06,-0.041
10.24,131.17,-0.041
10.25,131.29,-0.041
10.27,131.41,-0.041
10.28,131.52,-0.041
10.29,131.64,-0.041
10.30,131.76,-0.041
10.31,131.87,-0.041
10.33,131.99,-0.041
10.34,132.11,-0.041
10.35,132.22,-0.041
10.36,132.34,-0.041
10.37,132.46,-0.041
10.38,132.57,-0.041
10.40,132.69,-0.041
10.41,132.81,-0.041
10.42,132.92,-0.041
10.43,133.04,-0.041
10.44,133.16,-0.041
10.45,133.27,-0.041
10.47,133.39,-0.041
10.48,133.51,-0.041
10.49,133.62,-0.041
10.50,133.74,-0.041
10.51,133.86,-0.041
10.52,133.97,-0.040
10.53,134.09,-0.040
10.55,134.21,-0.040
10.56,134.33,-0.040
10.57,134.44,-0.040
10.58,134.56,-0.040
10.59,134.68,-0.041
10.60,134.79,-0.040
10.62,134.91,-0.039
10.63,135.03,-0.039
10.64,135.14,-0.039
10.65,135.26,-0.039
10.66,135.38,-0.039
10.68,135.49,-0.039
10.69,135.61,-0.039
10.70,135.72,-0.039
10.71,135.84,-0.039
10.72,135.96,-0.040
10.73,136.08,-0.040
10.75,136.19,-0.040
10.76,136.31,-0.040
10.77,136.43,-0.040
10.78,136.54,-0.040
10.79,136.66,-0.040
10.80,136.78,-0.040
10.82,136.89,-0.040
10.83,137.01,-0.040
10.84,137.13,-0.040
10.85,137.24,-0.040
10.86,137.36,-0.040
10.87,137.48,-0.040
10.88,137.60,-0.040
10.90,137.71,-0.040
10.91,137.83,-0.040
10.92,137.94,-0.040
10.93,138.06,-0.040
10.94,138.18,-0.040
10.95,138.30,-0.040
10.97,138.41,-0.040
10.98,138.53,-0.040
10.99,138.64,-0.040
11.00,138.76,-0.040
11.01,138.88,-0.040
11.03,138.99,-0.040
11.04,139.11,-0.040
11.05,139.23,-0.040
11.06,139.35,-0.040
11.07,139.46,-0.040
11.08,139.58,-0.040
11.10,139.69,-0.040
11.11,139.81,-0.040
11.12,139.93,-0.040
11.13,140.05,-0.040
11.14,140.16,-0.040
11.15,140.28,-0.040
11.17,140.40,-0.040
11.18,140.51,-0.040
11.19,140.63,-0.040
11.20,140.75,-0.040
11.21,140.86,-0.040
11.22,140.98,-0.040
11.23,141.10,-0.040
11.25,141.21,-0.040
11.26,141.33,-0.040
11.27,141.45,-0.040
11.28,141.56,-0.040
11.29,141.68,-0.040
11.30,141.80,-0.040
11.32,141.91,-0.040
11.33,142.03,-0.040
11.34,142.15,-0.040
11.35,142.26,-0.040
11.36,142.38,-0.040
11.38,142.50,-0.040
11.39,142.62,-0.040
11.40,142.73,-0.040
11.41,142.85,-0.040
11.42,142.96,-0.040
11.43,143.08,-0.040
11.45,143.20,-0.040
11.46,143.31,-0.040
11.47,143.43,-0.040
11.48,143.55,-0.040
11.49,143.67,-0.040
11.50,143.78,-0.040
11.52,143.90,-0.040
11.53,144.01,-0.040
11.54,144.13,-0.040
11.55,144.25,-0.040
11.56,144.37,-0.040
11.57,144.48,-0.040
11.58,144.60,-0.040
11.60,144.72,-0.040
11.61,144.83,-0.040
11.62,144.95,-0.040
11.63,145.07,-0.040
11.64,145.18,-0.040
11.65,145.30,-0.040
11.67,145.42,-0.040
11.68,145.53,-0.040
11.69,145.65,-0.040
11.70,145.77,-0.040
11.71,145.88,-0.040
11.73,146.00,-0.040
11.74,146.12,-0.040
11.75,146.23,-0.040
11.76,146.35,-0.040
11.77,146.47,-0.040
11.78,146.58,-0.040
11.80,146.70,-0.039
11.81,146.82,-0.039
11.82,146.93,-0.039
11.83,147.05,-0.039
11.84,147.17,-0.039
11.85,147.28,-0.039
11.87,147.40,-0.039
11.88,147.52,-0.039
11.89,147.64,-0.039
11.90,147.75,-0.040
11.91,147.87,-0.040
11.92,147.99,-0.040
11.93,148.10,-0.040
11.95,148.22,-0.040
11.96,148.34,-0.040
11.97,148.45,-0.040
11.98,148.57,-0.040
11.99,148.69,-0.040
12.00,148.80,-0.040
12.02,148.92,-0.040
12.03,149.04,-0.040
12.04,149.16,-0.040
12.05,149.27,-0.040
12.06,149.39,-0.040
12.08,149.50,-0.040
12.09,149.62,-0.040
12.10,149.74,-0.040
12.11,149.86,-0.040
12.12,149.97,-0.040
12.13,150.09,-0.040
12.15,150.21,-0.040
12.16,150.32,-0.040
12.17,150.44,-0.040
12.18,150.56,-0.040
12.19,150.67,-0.040
12.20,150.79,-0.040
12.22,150.91,-0.040
12.23,151.02,-0.040
12.24,151.14,-0.040
12.25,151.26,-0.040
12.26,151.37,-0.040
12.27,151.49,-0.040
12.28,151.60,-0.040
12.30,151.72,-0.040
12.31,151.84,-0.040
12.32,151.96,-0.040
12.33,152.07,-0.040
12.34,152.19,-0.040
12.35,152.31,-0.040
12.37,152.42,-0.040
12.38,152.54,-0.040
12.39,152.66,-0.040
12.40,152.77,-0.040
12.41,152.89,-0.040
12.43,153.01,-0.040
12.44,153.12,-0.040
12.45,153.24,-0.040
12.46,153.36,-0.040
12.47,153.47,-0.040
12.48,153.59,-0.040
12.50,153.71,-0.040
12.51,153.82,-0.040
12.52,153.94,-0.040
12.53,154.06,-0.040
12.54,154.17,-0.040
12.55,154.29,-0.040
12.57,154.41,-0.040
12.58,154.52,-0.040
12.59,154.64,-0.040
12.60,154.76,-0.040
12.61,154.87,-0.040
12.62,154.99,-0.040
12.63,155.11,-0.040
12.65,155.22,-0.040
12.66,155.34,-0.040
12.67,155.46,-0.038
12.68,155.57,-0.038
12.69,155.69,-0.038
12.70,155.81,-0.038
12.72,155.92,-0.038
12.73,156.04,-0.038
12.74,156.16,-0.038
12.75,156.27,-0.038
12.76,156.39,-0.038
12.78,156.50,-0.038
12.79,156.62,-0.038
12.80,156.74,-0.038
12.81,156.85,-0.037
12.82,156.97,-0.035
12.83,157.09,-0.016
12.85,157.20,0.064
12.86,157.29,0.206
12.87,157.37,0.323
12.88,157.45,0.416
12.89,157.52,0.502
12.90,157.59,0.587
12.92,157.66,0.666
12.93,157.73,0.738
12.94,157.80,0.816
12.95,157.87,0.883
12.96,157.94,0.943
12.97,158.01,1.000
12.98,158.08,1.064
13.00,158.16,1.130
13.01,158.23,1.197
13.02,158.30,1.269
13.03,158.38,1.345
13.04,158.45,1.418
13.05,158.52,1.485
13.07,158.59,1.553
13.08,158.66,1.621
13.09,158.74,1.677
13.10,158.81,1.718
13.11,158.90,1.735
13.13,158.98,1.713
13.14,159.08,1.688
13.15,159.19,1.588
13.16,159.33,1.251
13.17,159.53,0.811
13.18,159.75,0.598
13.20,159.96,0.486
13.21,160.16,0.411
13.22,160.36,0.354
13.23,160.55,0.305
13.24,160.72,0.264
13.25,160.89,0.227
13.27,161.06,0.197
13.28,161.22,0.168
13.29,161.37,0.143
13.30,161.52,0.121
13.31,161.67,0.102
13.32,161.81,0.085
13.33,161.95,0.071
13.35,162.08,0.057
13.36,162.22,0.046
13.37,162.35,0.035
13.38,162.48,0.027
13.39,162.61,0.019
13.40,162.73,0.011
13.42,162.86,0.005
13.43,162.98,0.000
13.44,163.11,-0.004
13.45,163.23,-0.009
13.46,163.35,-0.013
13.48,163.48,-0.016
13.49,163.60,-0.019
13.50,163.72,-0.022
13.51,163.84,-0.023
13.52,163.96,-0.025
13.53,164.08,-0.027
13.55,164.20,-0.029
13.56,164.31,-0.029
13.57,164.43,-0.031
13.58,164.55,-0.032
13.59,164.67,-0.033
13.60,164.79,-0.034
13.62,164.90,-0.035
13.63,165.02,-0.035
13.64,165.14,-0.036
13.65,165.26,-0.037
13.66,165.37,-0.037
13.67,165.49,-0.037
13.68,165.61,-0.037
13.70,165.73,-0.037
13.71,165.84,-0.038
13.72,165.96,-0.038
13.73,166.08,-0.038
13.74,166.19,-0.038
13.75,166.31,-0.038
13.77,166.43,-0.038
13.78,166.55,-0.038
13.79,166.66,-0.039
13.80,166.78,-0.039
13.81,166.90,-0.039
13.83,167.01,-0.039
13.84,167.13,-0.039
13.85,167.24,-0.039
13.86,167.36,-0.039
13.87,167.48,-0.039
13.88,167.60,-0.039
13.90,167.71,-0.039
13.91,167.83,-0.039
13.92,167.95,-0.039
13.93,168.06,-0.039
13.94,168.18,-0.040
13.95,168.30,-0.040
13.97,168.41,-0.040
13.98,168.53,-0.040
13.99,168.65,-0.040
14.00,168.76,-0.040
14.01,168.88,-0.040
14.02,169.00,-0.040
14.03,169.12,-0.040
14.05,169.23,-0.040
14.06,169.35,-0.040
14.07,169.47,-0.040
14.08,169.58,-0.040
14.09,169.70,-0.040
14.10,169.82,-0.040
14.12,169.93,-0.040
14.13,170.05,-0.040
14.14,170.17,-0.040
14.15,170.28,-0.040
14.16,170.40,-0.040
14.18,170.52,-0.041
14.19,170.63,-0.041
14.20,170.75,-0.041
14.21,170.87,-0.041
14.22,170.98,-0.041
14.23,171.10,-0.041
14.25,171.22,-0.041
14.26,171.33,-0.041
14.27,171.45,-0.041
14.28,171.57,-0.041
14.29,171.68,-0.041
14.30,171.80,-0.041
14.32,171.92,-0.041
14.33,172.04,-0.041
14.34,172.15,-0.041
14.35,172.27,-0.041
14.36,172.39,-0.041
14.37,172.50,-0.041
14.38,172.62,-0.041
14.40,172.73,-0.041
14.41,172.85,-0.041
14.42,172.97,-0.041
14.43,173.08,-0.041
14.44,173.20,-0.041
14.45,173.32,-0.041
14.47,173.43,-0.041
14.48,173.55,-0.041
14.49,173.67,-0.041
14.50,173.78,-0.041
14.51,173.90,-0.041
14.53,174.02,-0.041
14.54,174.13,-0.041
14.55,174.25,-0.041
14.56,174.37,-0.041
14.57,174.48,-0.041
14.58,174.60,-0.042
14.60,174.72,-0.042
14.61,174.84,-0.042
14.62,174.95,-0.042
14.63,175.07,-0.042
14.64,175.19,-0.043
14.65,175.31,-0.043
14.67,175.42,-0.044
14.68,175.54,-0.044
14.69,175.66,-0.044
14.70,175.78,-0.044
14.71,175.90,-0.043
14.72,176.02,-0.043
14.73,176.13,-0.043
14.75,176.25,-0.042
14.76,176.37,-0.042
14.77,176.48,-0.042
14.78,176.60,-0.042
14.79,176.72,-0.042
14.80,176.84,-0.042
14.82,176.95,-0.042
14.83,177.07,-0.042
14.84,177.19,-0.042
14.85,177.30,-0.042
14.86,177.42,-0.042
14.88,177.54,-0.042
14.89,177.65,-0.042
14.90,177.77,-0.042
14.91,177.88,-0.042
14.92,178.00,-0.042
14.93,178.12,-0.042
14.95,178.23,-0.042
14.96,178.35,-0.042
14.97,178.47,-0.042
14.98,178.58,-0.042
14.99,178.70,-0.042
15.00,178.82,-0.042
15.02,178.93,-0.042
15.03,179.05,-0.042
15.04,179.16,-0.042
15.05,179.28,-0.042
15.06,179.40,-0.042
15.07,179.51,-0.043
15.08,179.63,-0.043
15.10,179.75,-0.043
15.11,179.86,-0.043
15.12,179.98,-0.043
15.13,180.10,-0.043
15.14,180.21,-0.043
15.15,180.33,-0.043
15.17,180.45,-0.043
15.18,180.56,-0.043
15.19,180.68,-0.043
15.20,180.80,-0.043
15.21,180.91,-0.043
15.23,181.03,-0.043
15.24,181.14,-0.043
15.25,181.26,-0.043
15.26,181.38,-0.043
15.27,181.49,-0.043
15.28,181.61,-0.043
15.30,181.73,-0.043
15.31,181.84,-0.043
15.32,181.96,-0.043
15.33,182.08,-0.043
15.34,182.19,-0.043
15.35,182.31,-0.043
15.37,182.43,-0.043
15.38,182.54,-0.044
15.39,182.66,-0.044
15.40,182.78,-0.044
15.41,182.89,-0.044
15.42,183.01,-0.044
15.43,183.13,-0.044
15.45,183.24,-0.044
15.46,183.36,-0.044
15.47,183.48,-0.044
15.48,183.59,-0.044
15.49,183.71,-0.044
15.50,183.83,-0.044
15.52,183.94,-0.044
15.53,184.06,-0.044
15.54,184.18,-0.044
15.55,184.29,-0.044
15.56,184.41,-0.044
15.58,184.53,-0.044
15.59,184.64,-0.044
15.60,184.76,-0.044
15.61,184.88,-0.044
15.62,184.99,-0.044
15.63,185.11,-0.044
15.65,185.23,-0.044
15.66,185.34,-0.044
15.67,185.46,-0.044
15.68,185.58,-0.044
15.69,185.69,-0.044
15.70,185.81,-0.044
15.72,185.93,-0.044
15.73,186.04,-0.044
15.74,186.16,-0.044
15.75,186.28,-0.044
15.76,186.39,-0.044
15.77,186.51,-0.044
15.78,186.63,-0.044
15.80,186.74,-0.044
15.81,186.86,-0.044
15.82,186.98,-0.044
15.83,187.09,-0.044
15.84,187.21,-0.044
15.85,187.33,-0.044
15.87,187.44,-0.044
15.88,187.56,-0.044
15.89,187.68,-0.044
15.90,187.79,-0.044
15.91,187.91,-0.044
15.93,188.03,-0.044
15.94,188.14,-0.044
15.95,188.26,-0.044
15.96,188.38,-0.044
15.97,188.49,-0.044
15.98,188.61,-0.044
16.00,188.73,-0.044
16.01,188.84,-0.044
16.02,188.96,-0.044
16.03,189.08,-0.044
16.04,189.19,-0.044
16.05,189.31,-0.044
16.07,189.43,-0.045
16.08,189.54,-0.045
16.09,189.66,-0.045
16.10,189.78,-0.045
16.11,189.89,-0.045
16.12,190.01,-0.045
16.13,190.13,-0.045
16.15,190.24,-0.045
16.16,190.36,-0.045
16.17,190.48,-0.045
16.18,190.59,-0.045
16.19,190.71,-0.045
16.20,190.83,-0.045
16.22,190.94,-0.045
16.23,191.06,-0.045
16.24,191.18,-0.045
16.25,191.30,-0.045
16.26,191.41,-0.045
16.28,191.53,-0.045
16.29,191.65,-0.045
16.30,191.76,-0.045
16.31,191.88,-0.045
16.32,192.00,-0.045
16.33,192.11,-0.045
16.35,192.23,-0.045
16.36,192.35,-0.045
16.37,192.46,-0.045
16.38,192.58,-0.045
16.39,192.70,-0.045
16.40,192.81,-0.045
16.42,192.93,-0.045
16.43,193.05,-0.045
16.44,193.16,-0.045
16.45,193.28,-0.045
16.46,193.40,-0.045
16.47,193.51,-0.045
16.48,193.63,-0.045
16.50,193.75,-0.045
16.51,193.86,-0.045
16.52,193.98,-0.045
16.53,194.10,-0.045
16.54,194.21,-0.045
16.55,194.33,-0.046
16.57,194.45,-0.046
16.58,194.57,-0.046
16.59,194.68,-0.046
16.60,194.80,-0.046
16.61,194.91,-0.046
16.63,195.03,-0.046
16.64,195.15,-0.046
16.65,195.26,-0.046
16.66,195.38,-0.046
16.67,195.50,-0.046
16.68,195.61,-0.046
16.70,195.73,-0.046
16.71,195.85,-0.046
16.72,195.96,-0.046
16.73,196.08,-0.046
16.74,196.20,-0.046
16.75,196.32,-0.046
16.77,196.43,-0.046
16.78,196.55,-0.046
16.79,196.67,-0.046
16.80,196.78,-0.046
16.81,196.90,-0.046
16.82,197.02,-0.046
16.83,197.13,-0.046
16.85,197.25,-0.046
16.86,197.37,-0.046
16.87,197.48,-0.046
16.88,197.60,-0.046
16.89,197.72,-0.046
16.90,197.83,-0.046
16.92,197.95,-0.046
16.93,198.07,-0.046
16.94,198.18,
16.95,198.30,
16.96,198.42,
16.98,198.53,
16.99,198.65,
17.00,,

[step]
Ramp 10.00 °C/min to 30.00 °C
Time,Temperature,Heat Flow (Normalized)
min,°C,W/g
18.00,200.11,-0.040
18.01,200.11,-0.040
18.02,200.11,-0.040
18.03,200.11,-0.040
18.04,200.10,-0.036
18.06,200.09,-0.025
18.07,200.07,-0.011
18.08,200.05,0.005
18.09,200.01,0.022
18.10,199.97,0.037
18.12,199.91,0.050
18.13,199.85,0.058
18.14,199.78,0.061
18.15,199.70,0.060
18.16,199.62,0.056
18.17,199.53,0.050
18.18,199.44,0.042
18.20,199.35,0.034
18.21,199.25,0.026
18.22,199.15,0.019
18.23,199.05,0.012
18.24,198.95,0.006
18.26,198.84,0.002
18.27,198.74,-0.003
18.28,198.63,-0.006
18.29,198.52,-0.009
18.30,198.42,-0.013
18.31,198.31,-0.014
18.33,198.20,-0.016
18.34,198.09,-0.018
18.35,197.97,-0.018
18.36,197.86,-0.020
18.37,197.75,-0.022
18.38,197.64,-0.022
18.39,197.53,-0.023
18.41,197.41,-0.024
18.42,197.30,-0.025
18.43,197.19,-0.026
18.44,197.07,-0.026
18.45,196.96,-0.027
18.47,196.84,-0.027
18.48,196.73,-0.028
18.49,196.62,-0.028
18.50,196.50,-0.028
18.51,196.39,-0.029
18.52,196.27,-0.029
18.53,196.16,-0.029
18.55,196.04,-0.029
18.56,195.93,-0.029
18.57,195.82,-0.029
18.58,195.70,-0.029
18.59,195.59,-0.029
18.61,195.47,-0.030
18.62,195.35,-0.030
18.63,195.24,-0.030
18.64,195.13,-0.030
18.65,195.01,-0.030
18.66,194.89,-0.030
18.68,194.78,-0.030
18.69,194.66,-0.030
18.70,194.55,-0.030
18.71,194.43,-0.030
18.72,194.32,-0.030
18.73,194.20,-0.030
18.74,194.08,-0.030
18.76,193.97,-0.030
18.77,193.85,-0.030
18.78,193.74,-0.030
18.79,193.62,-0.030
18.80,193.51,-0.030
18.82,193.39,-0.030
18.83,193.28,-0.030
18.84,193.16,-0.030
18.85,193.04,-0.030
18.86,192.93,-0.030
18.87,192.81,-0.030
18.88,192.70,-0.030
18.90,192.58,-0.030
18.91,192.46,-0.030
18.92,192.35,-0.030
18.93,192.23,-0.030
18.94,192.12,-0.030
18.96,192.00,-0.030
18.97,191.88,-0.030
18.98,191.77,-0.030
18.99,191.65,-0.030
19.00,191.54,-0.030
19.01,191.42,-0.030
19.03,191.30,-0.030
19.04,191.19,-0.030
19.05,191.07,-0.030
19.06,190.96,-0.030
19.07,190.84,-0.030
19.08,190.72,-0.030
19.09,190.61,-0.030
19.11,190.49,-0.030
19.12,190.37,-0.030
19.13,190.26,-0.030
19.14,190.14,-0.030
19.15,190.03,-0.030
19.17,189.91,-0.030
19.18,189.79,-0.030
19.19,189.68,-0.030
19.20,189.56,-0.030
19.21,189.45,-0.030
19.22,189.33,-0.030
19.23,189.21,-0.030
19.25,189.10,-0.030
19.26,188.98,-0.030
19.27,188.86,-0.030
19.28,188.75,-0.030
19.29,188.63,-0.030
19.31,188.52,-0.030
19.32,188.40,-0.030
19.33,188.28,-0.030
19.34,188.17,-0.030
19.35,188.05,-0.029
19.36,187.94,-0.029
19.38,187.82,-0.029
19.39,187.70,-0.029
19.40,187.59,-0.029
19.41,187.47,-0.029
19.42,187.35,-0.029
19.43,187.24,-0.029
19.44,187.12,-0.029
19.46,187.00,-0.029
19.47,186.89,-0.029
19.48,186.77,-0.029
19.49,186.65,-0.029
19.50,186.54,-0.029
19.52,186.42,-0.029
19.53,186.30,-0.029
19.54,186.19,-0.029
19.55,186.07,-0.029
19.56,185.96,-0.029
19.57,185.84,-0.029
19.58,185.72,-0.029
19.60,185.61,-0.029
19.61,185.49,-0.029
19.62,185.37,-0.029
19.63,185.25,-0.029
19.64,185.14,-0.029
19.66,185.02,-0.028
19.67,184.91,-0.028
19.68,184.79,-0.028
19.69,184.67,-0.028
19.70,184.56,-0.028
19.71,184.44,-0.028
19.73,184.32,-0.028
19.74,184.21,-0.028
19.75,184.09,-0.028
19.76,183.97,-0.028
19.77,183.86,-0.028
19.78,183.74,-0.028
19.79,183.63,-0.028
19.81,183.51,-0.028
19.82,183.39,-0.028
19.83,183.28,-0.028
19.84,183.16,-0.028
19.85,183.04,-0.028
19.87,182.93,-0.028
19.88,182.81,-0.028
19.89,182.69,-0.028
19.90,182.58,-0.028
19.91,182.46,-0.028
19.92,182.34,-0.028
19.93,182.23,-0.028
19.95,182.11,-0.027
19.96,181.99,-0.027
19.97,181.88,-0.027
19.98,181.76,-0.027
19.99,181.65,-0.027
20.01,181.53,-0.027
20.02,181.41,-0.027
20.03,181.30,-0.027
20.04,181.18,-0.027
20.05,181.06,-0.027
20.06,180.95,-0.027
20.08,180.83,-0.027
20.09,180.71,-0.027
20.10,180.60,-0.027
20.11,180.48,-0.027
20.12,180.36,-0.027
20.13,180.25,-0.027
20.14,180.13,-0.027
20.16,180.01,-0.027
20.17,179.90,-0.027
20.18,179.78,-0.027
20.19,179.66,-0.027
20.20,179.55,-0.027
20.22,179.43,-0.027
20.23,179.31,-0.027
20.24,179.20,-0.027
20.25,179.08,-0.027
20.26,178.97,-0.027
20.27,178.85,-0.026
20.28,178.73,-0.026
20.30,178.62,-0.026
20.31,178.50,-0.026
20.32,178.38,-0.026
20.33,178.27,-0.026
20.34,178.15,-0.026
20.36,178.03,-0.026
20.37,177.92,-0.026
20.38,177.80,-0.026
20.39,177.68,-0.026
20.40,177.57,-0.026
20.41,177.45,-0.026
20.43,177.33,-0.026
20.44,177.22,-0.026
20.45,177.10,-0.026
20.46,176.98,-0.026
20.47,176.87,-0.026
20.48,176.75,-0.026
20.49,176.63,-0.026
20.51,176.52,-0.026
20.52,176.40,-0.026
20.53,176.29,-0.026
20.54,176.17,-0.026
20.55,176.05,-0.026
20.57,175.94,-0.026
20.58,175.82,-0.025
20.59,175.70,-0.025
20.60,175.59,-0.025
20.61,175.47,-0.025
20.62,175.35,-0.025
20.63,175.24,-0.025
20.65,175.12,-0.025
20.66,175.00,-0.025
20.67,174.89,-0.025
20.68,174.77,-0.025
20.69,174.65,-0.025
20.71,174.54,-0.025
20.72,174.42,-0.025
20.73,174.30,-0.025
20.74,174.19,-0.025
20.75,174.07,-0.025
20.76,173.95,-0.025
20.78,173.84,-0.025
20.79,173.72,-0.025
20.80,173.60,-0.025
20.81,173.49,-0.025
20.82,173.37,-0.025
20.83,173.26,-0.025
20.84,173.14,-0.025
20.86,173.02,-0.025
20.87,172.91,-0.025
20.88,172.79,-0.025
20.89,172.67,-0.025
20.90,172.56,-0.025
20.92,172.44,-0.025
20.93,172.32,-0.025
20.94,172.21,-0.025
20.95,172.09,-0.025
20.96,171.97,-0.025
20.97,171.86,-0.025
20.98,171.74,-0.025
21.00,171.62,-0.024
21.01,171.51,-0.024
21.02,171.39,-0.024
21.03,171.27,-0.024
21.04,171.16,-0.024
21.06,171.04,-0.024
21.07,170.93,-0.024
21.08,170.81,-0.024
21.09,170.69,-0.024
21.10,170.57,-0.024
21.11,170.46,-0.024
21.13,170.34,-0.024
21.14,170.22,-0.024
21.15,170.11,-0.024
21.16,169.99,-0.024
21.17,169.87,-0.024
21.18,169.76,-0.024
21.19,169.64,-0.024
21.21,169.52,-0.024
21.22,169.41,-0.024
21.23,169.29,-0.024
21.24,169.17,-0.024
21.25,169.06,-0.024
21.27,168.94,-0.024
21.28,168.82,-0.024
21.29,168.71,-0.024
21.30,168.59,-0.024
21.31,168.48,-0.024
[...]
95.30,148.67,-0.028
95.31,148.56,-0.027
95.32,148.44,-0.027
95.33,148.32,-0.026
95.34,148.20,-0.026
95.35,148.08,-0.025
95.36,147.97,-0.025
95.38,147.85,-0.025
95.39,147.73,-0.024
95.40,147.61,-0.024
95.41,147.50,-0.024
95.42,147.38,-0.023
95.44,147.26,-0.023
95.45,147.15,-0.022
95.46,147.03,-0.022
95.47,146.91,-0.022
95.48,146.80,-0.022
95.49,146.68,-0.022
95.50,146.56,-0.022
95.52,146.44,-0.022
95.53,146.33,-0.022
95.54,146.21,-0.022
95.55,146.10,-0.021
95.56,145.98,-0.021
95.58,145.86,-0.021
95.59,145.75,-0.021
95.60,145.63,-0.021
95.61,145.51,-0.021
95.62,145.40,-0.021
95.63,145.28,-0.021
95.65,145.16,-0.021
95.66,145.04,-0.021
95.67,144.93,-0.021
95.68,144.81,-0.020
95.69,144.70,-0.020
95.70,144.58,-0.020
95.71,144.46,-0.020
95.73,144.34,-0.020
95.74,144.23,-0.020
95.75,144.11,-0.020
95.76,144.00,-0.020
95.77,143.88,-0.020
95.79,143.76,-0.020
95.80,143.65,-0.020
95.81,143.53,-0.020
95.82,143.41,-0.020
95.83,143.30,-0.020
95.84,143.18,-0.020
95.85,143.06,-0.020
95.87,142.95,-0.020
95.88,142.83,-0.020
95.89,142.71,-0.020
95.90,142.60,-0.020
95.91,142.48,-0.020
95.93,142.36,-0.020
95.94,142.25,-0.020
95.95,142.13,-0.020
95.96,142.01,-0.019
95.97,141.90,-0.019
95.98,141.78,-0.019
96.00,141.66,-0.019
96.01,141.55,-0.019
96.02,141.43,-0.019
96.03,141.31,-0.019
96.04,141.20,-0.019
96.05,141.08,-0.019
96.06,140.96,-0.019
96.08,140.85,-0.019
96.09,140.73,-0.019
96.10,140.61,-0.019
96.11,140.50,-0.019
96.12,140.38,-0.019
96.14,140.26,-0.019
96.15,140.15,-0.019
96.16,140.03,-0.019
96.17,139.91,-0.019
96.18,139.80,-0.019
96.19,139.68,-0.019
96.20,139.56,-0.019
96.22,139.45,-0.019
96.23,139.33,-0.019
96.24,139.21,-0.019
96.25,139.10,-0.019
96.26,138.98,-0.019
96.28,138.86,-0.019
96.29,138.75,-0.019
96.30,138.63,-0.019
96.31,138.52,-0.019
96.32,138.40,-0.019
96.33,138.28,-0.019
96.35,138.17,-0.019
96.36,138.05,-0.019
96.37,137.93,-0.019
96.38,137.82,-0.019
96.39,137.70,-0.019
96.40,137.58,-0.019
96.41,137.47,-0.018
96.43,137.35,-0.018
96.44,137.23,-0.018
96.45,137.12,-0.018
96.46,137.00,-0.018
96.47,136.88,-0.018
96.49,136.77,-0.018
96.50,136.65,-0.018
96.51,136.54,-0.018
96.52,136.42,-0.018
96.53,136.30,-0.018
96.54,136.19,-0.018
96.55,136.07,-0.018
96.57,135.95,-0.018
96.58,135.84,-0.018
96.59,135.72,-0.018
96.60,135.60,-0.018
96.61,135.49,-0.018
96.63,135.37,-0.018
96.64,135.25,-0.018
96.65,135.14,-0.018
96.66,135.02,-0.018
96.67,134.90,-0.018
96.68,134.79,-0.018
96.70,134.67,-0.018
96.71,134.55,-0.018
96.72,134.44,-0.018
96.73,134.32,-0.018
96.74,134.20,-0.018
96.75,134.09,-0.018
96.76,133.97,-0.018
96.78,133.85,-0.018
96.79,133.74,-0.018
96.80,133.62,-0.018
96.81,133.50,-0.018
96.82,133.39,-0.018
96.84,133.27,-0.017
96.85,133.15,-0.017
96.86,133.04,-0.017
96.87,132.92,-0.017
96.88,132.80,-0.017
96.89,132.69,-0.017
96.90,132.57,-0.017
96.92,132.45,-0.017
96.93,132.34,-0.017
96.94,132.22,-0.017
96.95,132.11,-0.017
96.96,131.99,-0.017
96.98,131.87,-0.017
96.99,131.76,-0.017
97.00,131.64,-0.017
97.01,131.52,-0.017
97.02,131.41,-0.017
97.03,131.29,-0.017
97.05,131.17,-0.017
97.06,131.06,-0.017
97.07,130.94,-0.017
97.08,130.82,-0.017
97.09,130.71,-0.017
97.10,130.59,-0.017
97.11,130.47,-0.017
97.13,130.36,-0.017
97.14,130.24,-0.017
97.15,130.12,-0.017
97.16,130.01,-0.017
97.17,129.89,-0.017
97.19,129.77,-0.017
97.20,129.66,-0.017
97.21,129.54,-0.017
97.22,129.42,-0.017
97.23,129.31,-0.017
97.24,129.19,-0.017
97.25,129.07,-0.017
97.27,128.96,-0.017
97.28,128.84,-0.017
97.29,128.73,-0.017
97.30,128.61,-0.017
97.31,128.49,-0.017
97.33,128.38,-0.017
97.34,128.26,-0.017
97.35,128.14,-0.017
97.36,128.03,-0.017
97.37,127.91,-0.017
97.38,127.79,-0.017
97.40,127.68,-0.017
97.41,127.56,-0.017
97.42,127.44,-0.017
97.43,127.33,-0.017
97.44,127.21,-0.017
97.45,127.10,-0.016
97.46,126.98,-0.016
97.48,126.86,-0.016
97.49,126.75,-0.016
97.50,126.63,-0.016
97.51,126.51,-0.016
97.52,126.40,-0.016
97.54,126.28,-0.016
97.55,126.16,-0.016
97.56,126.05,-0.016
97.57,125.93,-0.016
97.58,125.81,-0.016
97.59,125.70,-0.016
97.60,125.58,-0.016
97.62,125.46,-0.016
97.63,125.35,-0.016
97.64,125.23,-0.016
97.65,125.11,-0.016
97.66,125.00,-0.016
97.68,124.88,-0.016
97.69,124.76,-0.016
97.70,124.65,-0.016
97.71,124.53,-0.016
97.72,124.41,-0.016
97.73,124.30,-0.016
97.75,124.18,-0.016
97.76,124.06,-0.016
97.77,123.95,-0.016
97.78,123.83,-0.016
97.79,123.71,-0.016
97.80,123.60,-0.016
97.81,123.48,-0.016
97.83,123.37,-0.016
97.84,123.25,-0.016
97.85,123.13,-0.016
97.86,123.01,-0.016
97.87,122.90,-0.016
97.89,122.78,-0.016
97.90,122.67,-0.015
97.91,122.55,-0.015
97.92,122.43,-0.015
97.93,122.31,-0.015
97.94,122.20,-0.015
97.95,122.08,-0.015
97.97,121.96,-0.015
97.98,121.85,-0.015
97.99,121.73,-0.015
98.00,121.61,-0.015
98.01,121.50,-0.015
98.03,121.38,-0.015
98.04,121.26,-0.015
98.05,121.15,-0.015
98.06,121.03,-0.015
98.07,120.91,-0.015
98.08,120.80,-0.015
98.10,120.68,-0.015
98.11,120.57,-0.015
98.12,120.45,-0.015
98.13,120.33,-0.015
98.14,120.22,-0.015
98.15,120.10,-0.015
98.16,119.98,-0.015
98.18,119.86,-0.015
98.19,119.75,-0.015
98.20,119.63,-0.015
98.21,119.52,-0.015
98.22,119.40,-0.015
98.24,119.28,-0.015
98.25,119.17,-0.015
98.26,119.05,-0.015
98.27,118.93,-0.015
98.28,118.82,-0.015
98.29,118.70,-0.015
98.30,118.59,-0.015
98.32,118.47,-0.015
98.33,118.35,-0.015
98.34,118.23,-0.015
98.35,118.12,-0.015
98.36,118.00,-0.015
98.38,117.88,-0.015
98.39,117.77,-0.015
98.40,117.65,-0.015
98.41,117.54,-0.015
98.42,117.42,-0.015
98.43,117.30,-0.015
98.45,117.19,-0.015
98.46,117.07,-0.015
98.47,116.95,-0.015
98.48,116.84,-0.015
98.49,116.72,-0.015
98.50,116.61,-0.015
98.51,116.49,-0.015
98.53,116.37,-0.014
98.54,116.26,-0.014
98.55,116.14,-0.014
98.56,116.02,-0.014
98.57,115.91,-0.014
98.59,115.79,-0.014
98.60,115.67,-0.014
98.61,115.56,-0.014
98.62,115.44,-0.014
98.63,115.32,-0.014
98.64,115.21,-0.014
98.65,115.09,-0.014
98.67,114.97,-0.014
98.68,114.86,-0.014
98.69,114.74,-0.014
98.70,114.62,-0.014
98.71,114.51,-0.014
98.73,114.39,-0.014
98.74,114.27,-0.014
98.75,114.15,-0.014
98.76,114.04,-0.014
98.77,113.92,-0.014
98.78,113.81,-0.014
98.80,113.69,-0.014
98.81,113.57,-0.014
98.82,113.46,-0.014
98.83,113.34,-0.014
98.84,113.22,-0.014
98.85,113.11,-0.014
98.86,112.99,-0.014
98.88,112.87,-0.014
98.89,112.76,-0.014
98.90,112.64,-0.014
98.91,112.52,-0.014
98.92,112.41,-0.014
98.94,112.29,-0.014
98.95,112.18,-0.014
98.96,112.06,-0.014
98.97,111.94,-0.014
98.98,111.83,-0.014
98.99,111.71,-0.013
99.00,111.59,-0.013
99.02,111.48,-0.013
99.03,111.36,-0.013
99.04,111.24,-0.013
99.05,111.13,-0.013
99.06,111.01,-0.013
99.08,110.89,-0.013
99.09,110.78,-0.013
99.10,110.66,-0.013
99.11,110.54,-0.013
99.12,110.43,-0.013
99.13,110.31,-0.013
99.15,110.19,-0.013
99.16,110.08,-0.013
99.17,109.96,-0.013
99.18,109.84,-0.013
99.19,109.73,-0.013
99.20,109.61,-0.013
99.21,109.49,-0.013
99.23,109.38,-0.013
99.24,109.26,-0.013
99.25,109.14,-0.013
99.26,109.03,-0.013
99.27,108.91,-0.013
99.29,108.79,-0.013
99.30,108.68,-0.013
99.31,108.56,-0.013
99.32,108.44,-0.013
99.33,108.33,-0.013
99.34,108.21,-0.013
99.35,108.10,-0.013
99.37,107.98,-0.013
99.38,107.86,-0.013
99.39,107.75,-0.013
99.40,107.63,-0.013
99.41,107.51,-0.013
99.43,107.40,-0.013
99.44,107.28,-0.013
99.45,107.16,-0.013
99.46,107.05,-0.013
99.47,106.93,-0.013
99.48,106.81,-0.013
99.50,106.70,-0.013
99.51,106.58,-0.013
99.52,106.46,-0.013
99.53,106.35,-0.013
99.54,106.23,-0.013
99.55,106.12,-0.013
99.56,106.00,-0.013
99.58,105.88,-0.013
99.59,105.77,-0.013
99.60,105.65,-0.012
99.61,105.53,-0.012
99.62,105.42,-0.012
99.64,105.30,-0.012
99.65,105.18,-0.012
99.66,105.07,-0.012
99.67,104.95,-0.012
99.68,104.83,-0.012
99.69,104.71,-0.012
99.70,104.60,-0.012
99.72,104.48,-0.012
99.73,104.36,-0.012
99.74,104.25,-0.012
99.75,104.13,-0.012
99.76,104.01,-0.012
99.78,103.90,-0.012
99.79,103.78,-0.012
99.80,103.66,-0.012
99.81,103.55,-0.012
99.82,103.43,-0.012
99.83,103.31,-0.012
99.85,103.20,-0.012
99.86,103.08,-0.012
99.87,102.97,-0.012
99.88,102.85,-0.012
99.89,102.73,-0.012
99.90,102.62,-0.012
99.91,102.50,-0.012
99.93,102.38,-0.012
99.94,102.27,-0.012
99.95,102.15,-0.012
99.96,102.03,-0.012
99.97,101.91,-0.012
99.99,101.80,-0.012
100.00,101.68,-0.012
100.01,101.57,-0.012
100.02,101.45,-0.012
100.03,101.33,-0.012
100.04,101.22,-0.012
100.05,101.10,-0.012
100.07,100.98,-0.012
100.08,100.87,-0.011
100.09,100.75,-0.011
100.10,100.63,-0.011
100.11,100.52,-0.011
100.13,100.40,-0.011
100.14,100.28,-0.011
100.15,100.17,-0.011
100.16,100.05,-0.011
100.17,99.93,-0.011
100.18,99.82,-0.011
100.20,99.70,-0.011
100.21,99.58,-0.011
100.22,99.47,-0.011
100.23,99.35,-0.011
100.24,99.23,-0.011
100.25,99.12,-0.011
100.26,99.00,-0.011
100.28,98.88,-0.011
100.29,98.77,-0.011
100.30,98.65,-0.011
100.31,98.53,-0.011
100.32,98.42,-0.011
100.34,98.30,-0.011
100.35,98.19,-0.011
100.36,98.07,-0.011
100.37,97.95,-0.011
100.38,97.84,-0.011
100.39,97.72,-0.011
100.40,97.60,-0.011
100.42,97.49,-0.011
100.43,97.37,-0.011
100.44,97.25,-0.011
100.45,97.14,-0.011
100.46,97.02,-0.011
100.48,96.90,-0.011
100.49,96.79,-0.011
100.50,96.67,-0.011
100.51,96.56,-0.011
100.52,96.44,-0.011
100.53,96.32,-0.011
100.55,96.21,-0.010
100.56,96.09,-0.010
100.57,95.97,-0.010
100.58,95.86,-0.010
100.59,95.74,-0.010
100.60,95.62,-0.010
100.61,95.51,-0.010
100.63,95.39,-0.010
100.64,95.27,-0.010
100.65,95.16,-0.010
100.66,95.04,-0.010
100.67,94.92,-0.010
100.69,94.81,-0.010
100.70,94.69,-0.010
100.71,94.57,-0.010
100.72,94.46,-0.010
100.73,94.34,-0.010
100.74,94.23,-0.010
100.75,94.11,-0.010
100.77,93.99,-0.010
100.78,93.88,-0.010
100.79,93.76,-0.010
100.80,93.64,-0.010
100.81,93.53,-0.010
100.83,93.41,-0.010
100.84,93.29,-0.010
100.85,93.18,-0.010
100.86,93.06,-0.010
100.87,92.94,-0.010
100.88,92.83,-0.010
100.90,92.71,-0.010
100.91,92.59,-0.010
100.92,92.48,-0.010
100.93,92.36,-0.010
100.94,92.24,-0.010
100.95,92.13,-0.010
100.96,92.01,-0.010
100.98,91.89,-0.010
100.99,91.78,-0.010
101.00,91.66,-0.010
101.01,91.55,-0.009
101.02,91.43,-0.009
101.04,91.31,-0.009
101.05,91.19,-0.009
101.06,91.08,-0.009
101.07,90.96,-0.009
101.08,90.85,-0.009
101.09,90.73,-0.009
101.10,90.61,-0.009
101.12,90.50,-0.009
101.13,90.38,-0.009
101.14,90.26,-0.009
101.15,90.15,-0.009
101.16,90.03,-0.009
101.18,89.91,-0.009
101.19,89.80,-0.009
101.20,89.68,-0.009
101.21,89.56,-0.009
101.22,89.45,-0.009
101.23,89.33,-0.009
101.25,89.21,-0.009
101.26,89.10,-0.009
101.27,88.98,-0.009
101.28,88.86,-0.009
101.29,88.75,-0.009
101.30,88.63,-0.009
101.31,88.51,-0.009
101.33,88.40,-0.009
101.34,88.28,-0.009
101.35,88.16,-0.009
101.36,88.05,-0.009
101.37,87.93,-0.009
101.39,87.81,-0.009
101.40,87.70,-0.009
101.41,87.58,-0.008
101.42,87.46,-0.008
101.43,87.35,-0.008
101.44,87.23,-0.008
101.45,87.11,-0.008
101.47,87.00,-0.008
101.48,86.88,-0.008
101.49,86.77,-0.008
101.50,86.65,-0.008
101.51,86.53,-0.008
101.53,86.42,-0.008
101.54,86.30,-0.008
101.55,86.18,-0.008
101.56,86.07,-0.008
101.57,85.95,-0.008
101.58,85.83,-0.008
101.60,85.72,-0.008
101.61,85.60,-0.008
101.62,85.48,-0.008
101.63,85.37,-0.008
101.64,85.25,-0.008
101.65,85.13,-0.008
101.66,85.02,-0.008
101.68,84.90,-0.008
101.69,84.78,-0.008
101.70,84.67,-0.008
101.71,84.55,-0.008
101.72,84.43,-0.008
101.74,84.32,-0.008
101.75,84.20,-0.008
101.76,84.08,-0.008
101.77,83.97,-0.008
101.78,83.85,-0.008
101.79,83.74,-0.008
101.80,83.62,-0.008
101.82,83.50,-0.008
101.83,83.39,-0.008
101.84,83.27,-0.008
101.85,83.15,-0.008
101.86,83.04,-0.008
101.88,82.92,-0.008
101.89,82.80,-0.008
101.90,82.69,-0.008
101.91,82.57,-0.008
101.92,82.45,-0.008
101.93,82.33,-0.008
101.95,82.22,-0.008
101.96,82.10,-0.008
101.97,81.99,-0.008
101.98,81.87,-0.008
101.99,81.75,-0.008
102.00,81.64,-0.008
102.01,81.52,-0.008
102.03,81.40,-0.008
102.04,81.29,-0.008
102.05,81.17,-0.007
102.06,81.05,-0.007
102.07,80.94,-0.007
102.09,80.82,-0.007
102.10,80.70,-0.007
102.11,80.59,-0.007
102.12,80.47,-0.007
102.13,80.35,-0.007
102.14,80.24,-0.007
102.15,80.12,-0.007
102.17,80.00,-0.007
102.18,79.89,-0.007
102.19,79.77,-0.007
102.20,79.66,-0.007
102.21,79.54,-0.007
102.23,79.42,-0.007
102.24,79.31,-0.007
102.25,79.19,-0.007
102.26,79.07,-0.007
102.27,78.96,-0.007
102.28,78.84,-0.007
102.30,78.72,-0.007
102.31,78.61,-0.007
102.32,78.49,-0.007
102.33,78.37,-0.007
102.34,78.26,-0.007
102.35,78.14,-0.007
102.36,78.02,-0.007
102.38,77.91,-0.007
102.39,77.79,-0.007
102.40,77.67,-0.007
102.41,77.56,-0.007
102.42,77.44,-0.007
102.44,77.32,-0.007
102.45,77.21,-0.007
102.46,77.09,-0.007
102.47,76.97,-0.007
102.48,76.86,-0.007
102.49,76.74,-0.007
102.50,76.62,-0.007
102.52,76.51,-0.007
102.53,76.39,-0.007
102.54,76.27,-0.007
102.55,76.16,-0.007
102.56,76.04,-0.007
102.58,75.92,-0.007
102.59,75.81,-0.007
102.60,75.69,-0.007
102.61,75.57,-0.007
102.62,75.46,-0.007
102.63,75.34,-0.007
102.65,75.22,-0.007
102.66,75.11,-0.007
102.67,74.99,-0.007
102.68,74.88,-0.007
102.69,74.76,-0.007
102.70,74.64,-0.007
102.71,74.52,-0.007
102.73,74.41,-0.007
102.74,74.29,-0.007
102.75,74.18,-0.007
102.76,74.06,-0.006
102.77,73.94,-0.006
102.79,73.83,-0.006
102.80,73.71,-0.006
102.81,73.59,-0.006
102.82,73.48,-0.006
102.83,73.36,-0.006
102.84,73.24,-0.006
102.85,73.12,-0.006
102.87,73.01,-0.006
102.88,72.89,-0.006
102.89,72.78,-0.006
102.90,72.66,-0.006
102.91,72.54,-0.006
102.93,72.42,-0.006
102.94,72.31,-0.006
102.95,72.19,-0.006
102.96,72.07,-0.006
102.97,71.96,-0.006
102.98,71.84,-0.006
103.00,71.73,-0.006
103.01,71.61,-0.006
103.02,71.49,-0.006
103.03,71.38,-0.006
103.04,71.26,-0.006
103.05,71.14,-0.006
103.06,71.03,-0.006
103.08,70.91,-0.006
103.09,70.79,-0.006
103.10,70.68,-0.006
103.11,70.56,-0.006
103.12,70.44,-0.006
103.14,70.33,-0.006
103.15,70.21,-0.006
103.16,70.09,-0.006
103.17,69.98,-0.006
103.18,69.86,-0.006
103.19,69.74,-0.006
103.20,69.63,-0.006
103.22,69.51,-0.006
103.23,69.39,-0.006
103.24,69.28,-0.006
103.25,69.16,-0.006
103.26,69.04,-0.006
103.28,68.93,-0.006
103.29,68.81,-0.006
103.30,68.70,-0.005
103.31,68.58,-0.005
103.32,68.46,-0.005
103.33,68.34,-0.005
103.35,68.23,-0.005
103.36,68.11,-0.005
103.37,67.99,-0.005
103.38,67.88,-0.005
103.39,67.76,-0.005
103.40,67.64,-0.005
103.41,67.53,-0.005
103.43,67.41,-0.005
103.44,67.30,-0.005
103.45,67.18,-0.005
103.46,67.06,-0.005
103.47,66.95,-0.005
103.49,66.83,-0.005
103.50,66.71,-0.005
103.51,66.60,-0.005
103.52,66.48,-0.005
103.53,66.36,-0.005
103.54,66.25,-0.005
103.55,66.13,-0.005
103.57,66.01,-0.005
103.58,65.90,-0.005
103.59,65.78,-0.005
103.60,65.67,-0.005
103.61,65.55,-0.005
103.63,65.43,-0.005
103.64,65.31,-0.005
103.65,65.20,-0.005
103.66,65.08,-0.005
103.67,64.96,-0.005
103.68,64.85,-0.005
103.70,64.73,-0.005
103.71,64.62,-0.005
103.72,64.50,-0.005
103.73,64.38,-0.005
103.74,64.27,-0.005
103.75,64.15,-0.005
103.76,64.03,-0.004
103.78,63.92,-0.004
103.79,63.80,-0.004
103.80,63.68,-0.004
103.81,63.57,-0.004
103.82,63.45,-0.004
103.84,63.33,-0.004
103.85,63.22,-0.004
103.86,63.10,-0.004
103.87,62.98,-0.004
103.88,62.87,-0.004
103.89,62.75,-0.004
103.90,62.64,-0.004
103.92,62.52,-0.004
103.93,62.40,-0.004
103.94,62.29,-0.004
103.95,62.17,-0.004
103.96,62.05,-0.004
103.98,61.94,-0.004
103.99,61.82,-0.004
104.00,61.70,-0.004
104.01,61.59,-0.004
104.02,61.47,-0.004
104.03,61.36,-0.004
104.05,61.24,-0.004
104.06,61.12,-0.004
104.07,61.01,-0.004
104.08,60.89,-0.004
104.09,60.77,-0.004
104.10,60.65,-0.004
104.11,60.54,-0.004
104.13,60.42,-0.004
104.14,60.30,-0.004
104.15,60.19,-0.004
104.16,60.07,-0.004
104.17,59.96,-0.004
104.19,59.84,-0.004
104.20,59.72,-0.004
104.21,59.61,-0.004
104.22,59.49,-0.004
104.23,59.37,-0.004
104.24,59.26,-0.004
104.25,59.14,-0.004
104.27,59.02,-0.004
104.28,58.91,-0.004
104.29,58.79,-0.004
104.30,58.67,-0.004
104.31,58.56,-0.004
104.33,58.44,-0.004
104.34,58.32,-0.004
104.35,58.21,-0.003
104.36,58.09,-0.003
104.37,57.97,-0.003
104.38,57.86,-0.003
104.40,57.74,-0.003
104.41,57.63,-0.003
104.42,57.51,-0.003
104.43,57.39,-0.003
104.44,57.28,-0.003
104.45,57.16,-0.003
104.46,57.04,-0.003
104.48,56.93,-0.003
104.49,56.81,-0.003
104.50,56.69,-0.003
104.51,56.58,-0.003
104.52,56.46,-0.003
104.54,56.34,-0.003
104.55,56.23,-0.003
104.56,56.11,-0.003
104.57,56.00,-0.003
104.58,55.88,-0.003
104.59,55.76,-0.003
104.60,55.65,-0.003
104.62,55.53,-0.003
104.63,55.41,-0.003
104.64,55.30,-0.003
104.65,55.18,-0.003
104.66,55.06,-0.003
104.68,54.95,-0.003
104.69,54.83,-0.003
104.70,54.71,-0.003
104.71,54.60,-0.003
104.72,54.48,-0.003
104.73,54.36,-0.003
104.75,54.25,-0.003
104.76,54.13,-0.003
104.77,54.02,-0.003
104.78,53.90,-0.003
104.79,53.78,-0.003
104.80,53.67,-0.003
104.81,53.55,-0.003
104.83,53.43,-0.003
104.84,53.32,-0.003
104.85,53.20,-0.003
104.86,53.08,-0.002
104.87,52.97,-0.002
104.89,52.85,-0.002
104.90,52.73,-0.002
104.91,52.62,-0.002
104.92,52.50,-0.002
104.93,52.38,-0.002
104.94,52.27,-0.002
104.95,52.15,-0.002
104.97,52.03,-0.002
104.98,51.92,-0.002
104.99,51.80,-0.002
105.00,51.68,-0.002
105.01,51.57,-0.002
105.03,51.45,-0.002
105.04,51.33,-0.002
105.05,51.22,-0.002
105.06,51.10,-0.002
105.07,50.98,-0.002
105.08,50.87,-0.002
105.10,50.75,-0.002
105.11,50.63,-0.002
105.12,50.52,-0.002
105.13,50.40,-0.002
105.14,50.28,-0.002
105.15,50.17,-0.002
105.16,50.05,-0.002
105.18,49.93,-0.002
105.19,49.82,-0.002
105.20,49.70,-0.002
105.21,49.58,-0.002
105.22,49.47,-0.002
105.24,49.35,-0.002
105.25,49.23,-0.002
105.26,49.12,-0.002
105.27,49.00,-0.002
105.28,48.88,-0.002
105.29,48.77,-0.002
105.30,48.65,-0.002
105.32,48.54,-0.002
105.33,48.42,-0.002
105.34,48.30,-0.002
105.35,48.19,-0.002
105.36,48.07,-0.002
105.38,47.95,-0.002
105.39,47.84,-0.002
105.40,47.72,-0.002
105.41,47.60,-0.002
105.42,47.49,-0.002
105.43,47.37,-0.002
105.45,47.25,-0.002
105.46,47.14,-0.002
105.47,47.02,-0.002
105.48,46.90,-0.001
105.49,46.79,-0.001
105.50,46.67,-0.001
105.51,46.56,-0.001
105.53,46.44,-0.001
105.54,46.32,-0.001
105.55,46.21,-0.001
105.56,46.09,-0.001
105.57,45.97,-0.001
105.59,45.86,-0.001
105.60,45.74,-0.001
105.61,45.62,-0.001
105.62,45.51,-0.001
105.63,45.39,-0.001
105.64,45.27,-0.001
105.65,45.16,-0.001
105.67,45.04,-0.001
105.68,44.92,-0.001
105.69,44.80,-0.001
105.70,44.69,-0.001
105.71,44.57,-0.001
105.73,44.45,-0.001
105.74,44.34,-0.001
105.75,44.22,-0.001
105.76,44.10,-0.001
105.77,43.99,-0.001
105.78,43.87,-0.001
105.80,43.75,-0.001
105.81,43.64,-0.001
105.82,43.52,-0.001
105.83,43.41,-0.001
105.84,43.29,-0.001
105.85,43.17,-0.001
105.86,43.06,-0.001
105.88,42.94,-0.001
105.89,42.82,-0.001
105.90,42.70,-0.001
105.91,42.59,-0.001
105.92,42.47,-0.001
105.94,42.36,-0.001
105.95,42.24,-0.001
105.96,42.12,-0.001
105.97,42.01,-0.001
105.98,41.89,-0.001
105.99,41.77,-0.001
106.00,41.66,-0.001
106.02,41.54,-0.001
106.03,41.42,-0.001
106.04,41.31,-0.001
106.05,41.19,-0.001
106.06,41.07,-0.001
106.08,40.96,-0.001
106.09,40.84,0.000
106.10,40.72,0.000
106.11,40.61,0.000
106.12,40.49,0.000
106.13,40.37,0.000
106.15,40.26,0.000
106.16,40.14,0.000
106.17,40.02,0.000
106.18,39.91,0.000
106.19,39.79,0.000
106.20,39.67,0.000
106.21,39.56,0.000
106.23,39.44,0.000
106.24,39.32,0.000
106.25,39.21,0.000
106.26,39.09,0.000
106.27,38.98,0.000
106.29,38.86,0.000
106.30,38.74,0.000
106.31,38.63,0.000
106.32,38.51,0.000
106.33,38.39,0.000
106.34,38.28,0.000
106.35,38.16,0.000
106.37,38.04,0.000
106.38,37.93,0.000
106.39,37.81,0.000
106.40,37.69,0.000
106.41,37.58,0.000
106.43,37.46,0.000
106.44,37.34,0.000
106.45,37.23,0.000
106.46,37.11,0.000
106.47,37.00,0.000
106.48,36.88,0.000
106.50,36.76,0.000
106.51,36.65,0.000
106.52,36.53,0.000
106.53,36.41,0.000
106.54,36.29,0.000
106.55,36.18,0.000
106.56,36.06,0.000
106.58,35.95,0.000
106.59,35.83,0.000
106.60,35.71,0.000
106.61,35.60,0.000
106.62,35.48,0.000
106.64,35.36,0.000
106.65,35.25,0.000
106.66,35.13,0.000
106.67,35.02,0.000
106.68,34.90,0.000
106.69,34.78,0.000
106.70,34.67,0.000
106.72,34.55,0.000
106.73,34.43,0.000
106.74,34.32,0.000
106.75,34.20,0.000
106.76,34.08,0.000
106.78,33.97,0.000
106.79,33.85,0.001
106.80,33.73,0.000
106.81,33.62,0.001
106.82,33.50,0.001
106.83,33.38,0.001
106.85,33.27,0.001
106.86,33.15,0.001
106.87,33.03,0.001
106.88,32.92,0.001
106.89,32.80,0.001
106.90,32.68,0.001
106.91,32.57,0.001
106.93,32.45,0.001
106.94,32.33,0.001
106.95,32.22,
106.96,32.10,
106.97,31.99,
106.99,31.87,
107.00,,