File: DSC/2025_02_10_Naphthalene_DSC.txt
Filename	2025_02_10_Naphthalene_DSC
Instrument name	DSC2A-00468 (192.168.1.100)
Operator	JLY
rundate	2/10/2025
Sample name	2025_02_10_Naphthalene_DSC
proceduresegments	Data Off ; Equilibrate 30.00 °C; Data On ; Ramp 5.00 °C/min to 100.00 °C
[File Parameters]
Run date	2/10/2025 5:10:30 PM
Trios version	5.1.1.46572
Original File Name
Current File Name	D:\DSC2500\CHM343\2025_02_10_Naphthalene_DSC.tri
[Procedure]
Procedure Name	Naphthalene Melting
Sample Name	2025_02_10_Naphthalene_DSC
Sample Mass	3.65 mg
Reference Sample Mass	0 mg
Pan Mass	54.57 mg
Pan Number	22
Reference Pan Mass	54 mg
Reference Pan Number	19
Pan Type	Tzero Aluminum Hermetic
Comments	Al Hermetic Sealed Pan, with ref Al pan
Project Name
Operator	JLY
Test	Custom
Unload Max Temperature	30
Unload Min Temperature	30
Load Max Temperature	30
Load Min Temperature	30
Stop on Gas Flow Error	Yes
[Signal List]
Signal #1	Time (min)
Signal #2	Temperature (°C)
Signal #3	Heat Flow (mW)
Signal #4	Delta T (µV)
Signal #5	Delta Tzero (µV)
Signal #6	Tzero Temperature (°C)
Signal #7	Cell Purge (mL/min)
Signal #8	Heater Temp (°C)
Signal #9	Power Delivered (W)
Signal #10	Reference Junction Temperature (°C)
Signal #11	Flange Temperature (°C)
Signal #12	Heat Flow Phase (rad)
Signal #13	Total Heat Capacity (J/°C)
Signal #14	Heat Capacity (J/°C)
[Configuration]
Company Name	ASU
Instrument Name	DSC2A-00468
Instrument Type	DSC2500
Serial Number	DSC2A-00468
IP	192.168.1.100
Location of Instrument	MRRC
DisplayType	Unknown
Sample Interval 	0.1 s/pt
Selected Heat Flow	T4P
Exotherm Direction	Down
Cell Serial	DRC2-00792
Lid Type	Standard
Cooler	RCS 90
Leave Cooler on at End of Sequence	On
Gas 2	Nitrogen
Gas Selected	Channel 1
Flow Rate	50 mL/min
Secondary Purge	On
Licensed Heat Flow	Heat Flow T4P
Modulation Licensed	Yes
[Versions]
Common IDD Version	1
Cortex Version	VER 2.10.2.31
Driver	5.0.0.6
GDM Version	1.0.3.3
TouchscreenVersion	1.0.0.16145
FEP Version	1.2.1.21
FEP Bootloader	2.0.0.5
AutoSampler Version	2.1.1.26
Auto Sampler Bootloader	2.0.0.5
FCM Version	1.1.0.3
FCM Bootloader	2.0.0.5
[Experiment Logs]
Experiment Log Entry # 1	Air Cool is off.
Experiment Log Entry # 3	Data On set to 0
Experiment Log Entry # 5	Equilibrate Segment 30 (C) Started
Experiment Log Entry # 7	Data On set to 1
Experiment Log Entry # 9	Ramp Segment 5 C/min to 100 Started
[Method Log]
Method Log Entry # 1	Data Off
Method Log Entry # 2	Equilibrate 30 °C
Method Log Entry # 3	Data On
Method Log Entry # 4	(Ramp 15042) Ramp 5 °C/minute to 100 °C
Cell Serial	DRC2-00792
[T1 Calibration]
Slope	-0.008529666
Offset	9.636258
Initial Temperature	98.23
GUID	f8bfdadc-4977-4fdf-ba6d-0ba9134940c3
[TZero Calibration]
Date Applied	11/29/2022 4:06:13 PM
Description	From -89.059 °C to 396.009 °C at 20.000°C/min
Gas Type	Nitrogen
Pan Type	None
Source Files 1	C:\Users\yargerlab\Desktop\DSC Data\General\TZero_calibration_11_29_22_2nd(2).tri
Source Files 2	C:\Users\yargerlab\Desktop\DSC Data\General\TZero_calibration_11_29_22_2nd(3).tri
Delta T Offset	13.05235
Delta T Slope	-0.007271007
Delta T0 Offset	-13.69128
Delta T0 Slope	0.06063341
[Temperature Calibration]
Date Applied	11/29/2022 7:12:28 PM
Description	From 106.590 °C to 186.590 °C at 10.000°C/min
Gas Type	Nitrogen
Pan Type	Tzero Aluminum Hermetic
Source Files 1	C:\Users\yargerlab\Desktop\DSC Data\General\Indium(6).tri
Measured 1	157.391
Known 1	156.598
[Cell Constant Calibration]
Date Applied	11/29/2022 7:12:29 PM
Description	From 106.590 °C to 186.590 °C at 10.000°C/min
Gas Type	Nitrogen
Pan Type	Tzero Aluminum Hermetic
Source Files 1	C:\Users\yargerlab\Desktop\DSC Data\General\Indium(6).tri
T4P KCell	1.006051
Onset Slope	63.26126 mW/°C
[Direct Cp Calibration]
Date Applied	11/30/2022 11:04:51 AM
Description	From -79.983 °C to 298.409 °C at 10.000°C/min
Gas Type	Nitrogen
Pan Type	Tzero Aluminum Hermetic
Source Files 1	C:\Users\yargerlab\Desktop\DSC Data\General\Sapphire_Heat_Capacity_11_30_22.tri
[Rev Cp Calibration]
Date Applied	11/30/2022 1:58:51 PM
Description	From -79.996 °C to 292.812 °C at 3.000°C/min
Gas Type	Nitrogen
Pan Type	Tzero Aluminum Hermetic
Source Files 1	C:\Users\yargerlab\Desktop\DSC Data\General\Sapphire_MDSC_Calibration_11_30_22.tri
[step]
Ramp 5.00 °C/min to 100.00 °C
Time	Temperature	Heat Flow (Normalized)
min	°C	W/g
0.00	30.05	-0.038
0.01	30.05	-0.037
0.02	30.06	-0.036
0.03	30.06	-0.035
0.04	30.06	-0.035
0.05	30.06	-0.033
0.06	30.07	-0.030
0.07	30.08	-0.025
0.08	30.08	-0.016
0.09	30.10	-0.007
0.10	30.11	0.000
0.11	30.13	0.010
0.12	30.15	0.017
0.13	30.18	0.025
0.14	30.21	0.034
0.15	30.24	0.040
0.16	30.27	0.046
0.17	30.31	0.051
0.18	30.35	0.056
0.19	30.38	0.062
0.20	30.42	0.067
0.21	30.46	0.071
0.22	30.51	0.074
0.23	30.55	0.077
0.24	30.59	0.082
0.25	30.63	0.086
0.26	30.68	0.088
0.27	30.72	0.090
0.28	30.77	0.094
0.29	30.81	0.096
0.30	30.86	0.097
0.31	30.90	0.100
0.32	30.95	0.102
0.33	31.00	0.103
0.34	31.04	0.104
0.35	31.09	0.105
0.36	31.14	0.106
0.37	31.19	0.107
0.38	31.24	0.108
0.39	31.29	0.108
0.40	31.33	0.109
0.41	31.38	0.110
0.42	31.43	0.111
0.43	31.48	0.112
0.44	31.53	0.112
0.45	31.58	0.113
0.46	31.63	0.113
0.47	31.68	0.114
0.48	31.72	0.114
0.49	31.77	0.114
0.50	31.82	0.115
0.51	31.87	0.115
0.52	31.92	0.115
0.53	31.97	0.115
0.54	32.02	0.115
0.55	32.07	0.115
0.56	32.12	0.116
0.57	32.17	0.116
0.58	32.22	0.116
0.59	32.27	0.116
0.60	32.32	0.116
0.61	32.37	0.116
0.62	32.42	0.117
0.63	32.47	0.117
0.64	32.52	0.117
0.65	32.56	0.117
0.66	32.61	0.117
0.67	32.66	0.118
0.68	32.71	0.118
0.69	32.76	0.118
0.70	32.81	0.118
0.71	32.86	0.118
0.72	32.91	0.118
0.73	32.96	0.118
0.74	33.01	0.118
0.75	33.06	0.119
0.76	33.11	0.119
0.77	33.16	0.119
0.78	33.21	0.119
0.79	33.26	0.119
0.80	33.31	0.119
0.81	33.36	0.119
0.82	33.41	0.119
0.83	33.46	0.119
0.84	33.51	0.119
0.85	33.56	0.119
0.86	33.61	0.119
0.87	33.66	0.120
0.88	33.71	0.120
0.89	33.76	0.120
0.90	33.81	0.120
0.91	33.86	0.120
0.92	33.91	0.120
0.93	33.96	0.120
0.94	34.01	0.120
0.95	34.06	0.120
0.96	34.11	0.120
0.97	34.16	0.120
0.98	34.21	0.120
0.99	34.26	0.120
1.00	34.31	0.120
1.01	34.35	0.120
1.02	34.41	0.120
1.03	34.46	0.120
1.04	34.51	0.120
1.05	34.56	0.120
1.06	34.60	0.120
1.07	34.65	0.120
1.08	34.70	0.120
1.09	34.75	0.120
1.10	34.80	0.120
1.11	34.85	0.120
1.12	34.90	0.120
1.13	34.95	0.120
1.14	35.00	0.120
1.15	35.05	0.120
1.16	35.10	0.120
1.17	35.15	0.121
1.18	35.20	0.121
1.19	35.25	0.121
1.20	35.30	0.121
1.21	35.35	0.121
1.22	35.40	0.121
1.23	35.45	0.121
1.24	35.50	0.121
1.25	35.55	0.121
1.26	35.60	0.121
1.27	35.65	0.121
1.28	35.70	0.121
1.29	35.75	0.121
1.30	35.80	0.121
1.31	35.85	0.121
1.32	35.90	0.121
1.33	35.95	0.121
1.34	36.00	0.121
1.35	36.05	0.121
1.36	36.10	0.121
1.37	36.15	0.121
1.38	36.20	0.121
1.39	36.25	0.121
1.40	36.30	0.121
1.41	36.35	0.121
1.42	36.40	0.121
1.43	36.45	0.121
1.44	36.50	0.121
1.45	36.55	0.121
1.46	36.60	0.121
1.47	36.65	0.121
1.48	36.70	0.121
1.49	36.75	0.121
1.50	36.80	0.121
1.51	36.85	0.121
1.52	36.90	0.121
1.53	36.95	0.121
1.54	37.00	0.121
1.55	37.05	0.121
1.56	37.10	0.121
1.57	37.15	0.121
1.58	37.20	0.121
1.59	37.25	0.121
1.60	37.30	0.121
1.61	37.35	0.121
1.62	37.40	0.121
1.63	37.45	0.121
1.64	37.50	0.121
1.65	37.55	0.121
1.66	37.60	0.121
1.67	37.65	0.121
1.68	37.70	0.121
1.69	37.75	0.121
1.70	37.80	0.121
1.71	37.85	0.121
1.72	37.90	0.121
1.73	37.95	0.121
1.74	38.00	0.121
1.75	38.05	0.121
1.76	38.10	0.121
1.77	38.15	0.121
1.78	38.20	0.121
1.79	38.25	0.121
1.80	38.30	0.121
1.81	38.35	0.121
1.82	38.40	0.121
1.83	38.45	0.121
1.84	38.50	0.121
1.85	38.55	0.121
1.86	38.60	0.120
1.87	38.65	0.121
1.88	38.70	0.121
1.89	38.75	0.121
1.90	38.80	0.121
1.91	38.85	0.121
1.92	38.90	0.120
1.93	38.95	0.121
1.94	39.00	0.121
1.95	39.05	0.121
1.96	39.10	0.121
1.97	39.15	0.121
1.98	39.20	0.121
1.99	39.25	0.121
2.00	39.30	0.120
2.01	39.35	0.121
2.02	39.40	0.121
2.03	39.45	0.121
2.04	39.50	0.121
2.05	39.55	0.121
2.06	39.60	0.121
2.07	39.65	0.121
2.08	39.70	0.121
2.09	39.75	0.121
2.10	39.80	0.121
2.11	39.85	0.121
2.12	39.90	0.121
2.13	39.95	0.121
2.14	40.00	0.121
2.15	40.05	0.121
2.16	40.10	0.121
2.17	40.15	0.121
2.18	40.20	0.121
2.19	40.25	0.121
2.20	40.30	0.121
2.21	40.35	0.121
2.22	40.40	0.121
2.23	40.45	0.121
2.24	40.50	0.121
2.25	40.55	0.121
2.26	40.60	0.121
2.27	40.65	0.121
2.28	40.70	0.121
2.29	40.75	0.121
2.30	40.80	0.121
2.31	40.85	0.121
2.32	40.90	0.121
2.33	40.95	0.121
2.34	41.00	0.121
2.35	41.05	0.121
2.36	41.10	0.121
2.37	41.15	0.121
2.38	41.20	0.121
2.39	41.25	0.121
2.40	41.30	0.121
2.41	41.35	0.121
2.42	41.40	0.121
2.43	41.45	0.121
2.44	41.50	0.121
2.45	41.55	0.121
2.46	41.60	0.121
2.47	41.65	0.121
2.48	41.70	0.121
2.49	41.75	0.121
2.50	41.80	0.121
2.51	41.85	0.121
2.52	41.90	0.121
2.53	41.95	0.121
2.54	42.00	0.121
2.55	42.05	0.121
2.56	42.10	0.121
2.57	42.15	0.121
2.58	42.20	0.121
2.59	42.25	0.121
2.60	42.30	0.121
2.61	42.35	0.121
2.62	42.40	0.121
2.63	42.45	0.121
2.64	42.50	0.121
2.65	42.55	0.121
2.66	42.60	0.121
2.67	42.65	0.121
2.68	42.70	0.121
2.69	42.75	0.121
2.70	42.80	0.121
2.71	42.85	0.121
2.72	42.90	0.121
2.73	42.95	0.121
2.74	43.00	0.121
2.75	43.05	0.121
2.76	43.10	0.121
2.77	43.15	0.121
2.78	43.20	0.121
2.79	43.25	0.121
2.80	43.30	0.121
2.81	43.35	0.121
2.82	43.40	0.121
2.83	43.45	0.121
2.84	43.50	0.121
2.85	43.55	0.121
2.86	43.60	0.121
2.87	43.65	0.121
2.88	43.70	0.121
2.89	43.75	0.121
2.90	43.80	0.121
2.91	43.85	0.121
2.92	43.90	0.121
2.93	43.95	0.121
2.94	44.00	0.121
2.95	44.05	0.121
2.96	44.10	0.121
2.97	44.15	0.121
2.98	44.20	0.121
2.99	44.25	0.121
3.00	44.30	0.121
3.01	44.35	0.121
3.02	44.40	0.121
3.03	44.45	0.121
3.04	44.50	0.121
3.05	44.55	0.121
3.06	44.60	0.121
3.07	44.65	0.121
3.08	44.70	0.121
3.09	44.75	0.121
3.10	44.80	0.121
3.11	44.85	0.121
3.12	44.90	0.121
3.13	44.95	0.121
3.14	45.00	0.121
3.15	45.05	0.121
3.16	45.10	0.121
3.17	45.15	0.121
3.18	45.20	0.121
3.19	45.25	0.121
3.20	45.30	0.121
3.21	45.35	0.122
3.22	45.40	0.122
3.23	45.45	0.122
3.24	45.50	0.121
3.25	45.55	0.122
3.26	45.60	0.122
3.27	45.65	0.122
3.28	45.70	0.122
3.29	45.75	0.122
3.30	45.80	0.122
3.31	45.85	0.122
3.32	45.90	0.122
3.33	45.95	0.122
3.34	46.00	0.122
3.35	46.05	0.122
3.36	46.10	0.122
3.37	46.15	0.122
3.38	46.20	0.122
3.39	46.25	0.122
3.40	46.30	0.122
3.41	46.35	0.122
3.42	46.40	0.122
3.43	46.45	0.122
3.44	46.50	0.122
3.45	46.55	0.122
3.46	46.60	0.122
3.47	46.65	0.122
3.48	46.70	0.122
3.49	46.75	0.122
3.50	46.80	0.122
3.51	46.85	0.122
3.52	46.90	0.122
3.53	46.95	0.122
3.54	47.00	0.122
3.55	47.05	0.122
3.56	47.10	0.122
3.57	47.15	0.122
3.58	47.20	0.122
3.59	47.25	0.122
3.60	47.30	0.122
3.61	47.35	0.122
3.62	47.40	0.122
3.63	47.45	0.122
3.64	47.50	0.122
3.65	47.55	0.122
3.66	47.60	0.122
3.67	47.65	0.122
3.68	47.70	0.122
3.69	47.76	0.122
3.70	47.80	0.122
3.71	47.86	0.122
3.72	47.90	0.122
3.73	47.96	0.122
3.74	48.01	0.122
3.75	48.06	0.122
3.76	48.11	0.122
3.77	48.16	0.122
3.78	48.20	0.122
3.79	48.25	0.122
3.80	48.30	0.123
3.81	48.35	0.123
3.82	48.40	0.123
3.83	48.45	0.123
3.84	48.51	0.123
3.85	48.55	0.123
3.86	48.60	0.123
3.87	48.65	0.123
3.88	48.70	0.123
3.89	48.75	0.123
3.90	48.80	0.123
3.91	48.85	0.123
3.92	48.90	0.123
3.93	48.95	0.123
3.94	49.00	0.123
3.95	49.05	0.123
3.96	49.10	0.123
3.97	49.16	0.123
3.98	49.21	0.123
3.99	49.26	0.123
4.00	49.31	0.123
4.01	49.36	0.123
4.02	49.41	0.123
4.03	49.45	0.123
4.04	49.51	0.123
4.05	49.55	0.123
4.06	49.60	0.123
4.07	49.65	0.123
4.08	49.70	0.123
4.09	49.75	0.123
4.10	49.80	0.123
4.11	49.86	0.123
4.12	49.91	0.123
4.13	49.95	0.123
4.14	50.00	0.123
4.15	50.05	0.123
4.16	50.11	0.123
4.17	50.16	0.123
4.18	50.21	0.123
4.19	50.26	0.123
4.20	50.31	0.123
4.21	50.36	0.123
4.22	50.41	0.123
4.23	50.46	0.123
4.24	50.50	0.123
4.25	50.56	0.123
4.26	50.61	0.123
4.27	50.66	0.123
4.28	50.71	0.123
4.29	50.76	0.123
4.30	50.81	0.123
4.31	50.86	0.123
4.32	50.91	0.123
4.33	50.96	0.123
4.34	51.01	0.124
4.35	51.06	0.124
4.36	51.11	0.124
4.37	51.16	0.124
4.38	51.21	0.124
4.39	51.26	0.124
4.40	51.31	0.124
4.41	51.36	0.124
4.42	51.41	0.124
4.43	51.46	0.124
4.44	51.51	0.124
4.45	51.56	0.124
4.46	51.61	0.124
4.47	51.66	0.124
4.48	51.71	0.124
4.49	51.76	0.124
4.50	51.81	0.124
4.51	51.86	0.124
4.52	51.91	0.124
4.53	51.96	0.124
4.54	52.01	0.124
4.55	52.06	0.124
4.56	52.11	0.124
4.57	52.16	0.124
4.58	52.21	0.124
4.59	52.26	0.124
4.60	52.31	0.124
4.61	52.36	0.124
4.62	52.41	0.124
4.63	52.46	0.124
4.64	52.51	0.124
4.65	52.56	0.124
4.66	52.61	0.124
4.67	52.66	0.124
4.68	52.71	0.124
4.69	52.76	0.124
4.70	52.81	0.124
4.71	52.86	0.124
4.72	52.91	0.124
4.73	52.96	0.124
4.74	53.01	0.124
4.75	53.06	0.124
4.76	53.11	0.124
4.77	53.16	0.124
4.78	53.21	0.124
4.79	53.26	0.124
4.80	53.31	0.124
4.81	53.36	0.124
4.82	53.41	0.125
4.83	53.46	0.125
4.84	53.51	0.124
4.85	53.56	0.125
4.86	53.61	0.125
4.87	53.66	0.125
4.88	53.71	0.125
4.89	53.76	0.125
4.90	53.81	0.125
4.91	53.86	0.125
4.92	53.91	0.125
4.93	53.96	0.125
4.94	54.01	0.125
4.95	54.06	0.125
4.96	54.11	0.125
4.97	54.16	0.125
4.98	54.21	0.125
4.99	54.26	0.125
5.00	54.31	0.125
5.01	54.36	0.125
5.02	54.41	0.125
5.03	54.46	0.125
5.04	54.51	0.125
5.05	54.56	0.125
5.06	54.61	0.125
5.07	54.66	0.125
5.08	54.71	0.125
5.09	54.76	0.125
5.10	54.81	0.125
5.11	54.86	0.125
5.12	54.91	0.125
5.13	54.96	0.125
5.14	55.01	0.125
5.15	55.06	0.125
5.16	55.11	0.125
5.17	55.16	0.125
5.18	55.21	0.125
5.19	55.26	0.125
5.20	55.31	0.125
5.21	55.36	0.125
5.22	55.41	0.125
5.23	55.46	0.125
5.24	55.51	0.125
5.25	55.56	0.125
5.26	55.61	0.125
5.27	55.66	0.125
5.28	55.71	0.125
5.29	55.76	0.126
5.30	55.81	0.125
5.31	55.86	0.126
5.32	55.91	0.126
5.33	55.96	0.126
5.34	56.01	0.126
5.35	56.06	0.126
5.36	56.11	0.126
5.37	56.16	0.126
5.38	56.21	0.126
5.39	56.26	0.126
5.40	56.31	0.126
5.41	56.36	0.126
5.42	56.41	0.126
5.43	56.46	0.126
5.44	56.51	0.126
5.45	56.56	0.126
5.46	56.61	0.126
5.47	56.66	0.126
5.48	56.71	0.126
5.49	56.76	0.126
5.50	56.81	0.126
5.51	56.86	0.126
5.52	56.91	0.126
5.53	56.96	0.126
5.54	57.01	0.126
5.55	57.06	0.126
5.56	57.11	0.126
5.57	57.16	0.126
5.58	57.21	0.126
5.59	57.26	0.126
5.60	57.31	0.126
5.61	57.36	0.126
5.62	57.41	0.126
5.63	57.46	0.126
5.64	57.51	0.126
5.65	57.56	0.126
5.66	57.61	0.126
5.67	57.66	0.126
5.68	57.71	0.126
5.69	57.76	0.127
5.70	57.81	0.127
5.71	57.86	0.127
5.72	57.91	0.127
5.73	57.96	0.127
5.74	58.01	0.127
5.75	58.06	0.127
5.76	58.11	0.127
5.77	58.16	0.127
5.78	58.21	0.127
5.79	58.26	0.127
5.80	58.31	0.127
5.81	58.36	0.127
5.82	58.41	0.127
5.83	58.46	0.127
5.84	58.51	0.127
5.85	58.56	0.127
5.86	58.61	0.127
5.87	58.66	0.127
5.88	58.71	0.127
5.89	58.76	0.127
5.90	58.81	0.127
5.91	58.86	0.127
5.92	58.91	0.127
5.93	58.96	0.127
5.94	59.01	0.127
5.95	59.06	0.127
5.96	59.11	0.127
5.97	59.16	0.127
5.98	59.21	0.127
5.99	59.26	0.127
6.00	59.31	0.127
6.01	59.36	0.127
6.02	59.41	0.127
6.03	59.46	0.127
6.04	59.51	0.128
6.05	59.56	0.128
6.06	59.61	0.128
6.07	59.66	0.128
6.08	59.71	0.128
6.09	59.76	0.128
6.10	59.81	0.128
6.11	59.86	0.128
6.12	59.91	0.128
6.13	59.96	0.128
6.14	60.01	0.128
6.15	60.06	0.128
6.16	60.11	0.128
6.17	60.16	0.128
6.18	60.21	0.128
6.19	60.26	0.128
6.20	60.31	0.128
6.21	60.36	0.128
6.22	60.41	0.128
6.23	60.46	0.128
6.24	60.51	0.128
6.25	60.56	0.128
6.26	60.61	0.128
6.27	60.66	0.128
6.28	60.71	0.128
6.29	60.76	0.128
6.30	60.81	0.128
6.31	60.86	0.128
6.32	60.91	0.128
6.33	60.96	0.128
6.34	61.01	0.128
6.35	61.06	0.128
6.36	61.11	0.128
6.37	61.16	0.128
6.38	61.21	0.129
6.39	61.26	0.129
6.40	61.31	0.129
6.41	61.36	0.129
6.42	61.41	0.129
6.43	61.46	0.129
6.44	61.51	0.129
6.45	61.56	0.129
6.46	61.61	0.129
6.47	61.66	0.129
6.48	61.71	0.129
6.49	61.76	0.129
6.50	61.81	0.129
6.51	61.86	0.129
6.52	61.91	0.129
6.53	61.96	0.129
6.54	62.01	0.129
6.55	62.06	0.129
6.56	62.11	0.129
6.57	62.16	0.129
6.58	62.21	0.129
6.59	62.26	0.129
6.60	62.31	0.129
6.61	62.36	0.129
6.62	62.41	0.129
6.63	62.46	0.129
6.64	62.51	0.129
6.65	62.56	0.129
6.66	62.61	0.129
6.67	62.66	0.129
6.68	62.71	0.129
6.69	62.76	0.129
6.70	62.81	0.129
6.71	62.86	0.129
6.72	62.91	0.129
6.73	62.96	0.129
6.74	63.01	0.129
6.75	63.06	0.129
6.76	63.11	0.129
6.77	63.16	0.130
6.78	63.21	0.130
6.79	63.26	0.130
6.80	63.31	0.130
6.81	63.36	0.130
6.82	63.41	0.130
6.83	63.46	0.130
6.84	63.51	0.130
6.85	63.56	0.130
6.86	63.61	0.130
6.87	63.66	0.130
6.88	63.71	0.130
6.89	63.76	0.130
6.90	63.81	0.130
6.91	63.86	0.130
6.92	63.91	0.130
6.93	63.96	0.130
6.94	64.01	0.130
6.95	64.06	0.130
6.96	64.11	0.130
6.97	64.16	0.130
6.98	64.21	0.130
6.99	64.26	0.130
7.00	64.31	0.130
7.01	64.36	0.130
7.02	64.41	0.130
7.03	64.46	0.130
7.04	64.51	0.130
7.05	64.56	0.130
7.06	64.61	0.130
7.07	64.66	0.131
7.08	64.71	0.131
7.09	64.76	0.131
7.10	64.81	0.131
7.11	64.86	0.131
7.12	64.91	0.131
7.13	64.96	0.131
7.14	65.01	0.131
7.15	65.06	0.131
7.16	65.11	0.131
7.17	65.16	0.131
7.18	65.21	0.131
7.19	65.26	0.131
7.20	65.31	0.131
7.21	65.36	0.131
7.22	65.41	0.131
7.23	65.46	0.131
7.24	65.51	0.131
7.25	65.56	0.131
7.26	65.61	0.131
7.27	65.66	0.131
7.28	65.71	0.131
7.29	65.76	0.131
7.30	65.81	0.131
7.31	65.86	0.131
7.32	65.91	0.131
7.33	65.96	0.131
7.34	66.01	0.131
7.35	66.06	0.131
7.36	66.11	0.131
7.37	66.16	0.131
7.38	66.21	0.131
7.39	66.26	0.131
7.40	66.31	0.131
7.41	66.36	0.131
7.42	66.41	0.131
7.43	66.46	0.131
7.44	66.51	0.132
7.45	66.56	0.132
7.46	66.61	0.132
7.47	66.66	0.132
7.48	66.71	0.132
7.49	66.76	0.132
7.50	66.81	0.132
7.51	66.86	0.132
7.52	66.91	0.132
7.53	66.96	0.132
7.54	67.01	0.132
7.55	67.06	0.132
7.56	67.11	0.132
7.57	67.16	0.132
7.58	67.21	0.132
7.59	67.26	0.132
7.60	67.31	0.132
7.61	67.36	0.132
7.62	67.41	0.132
7.63	67.46	0.132
7.64	67.51	0.132
7.65	67.56	0.132
7.66	67.61	0.132
7.67	67.66	0.132
7.68	67.71	0.132
7.69	67.76	0.132
7.70	67.81	0.132
7.71	67.86	0.132
7.72	67.91	0.132
7.73	67.96	0.132
7.74	68.01	0.132
7.75	68.06	0.133
7.76	68.11	0.133
7.77	68.16	0.133
7.78	68.21	0.133
7.79	68.26	0.133
7.80	68.31	0.133
7.81	68.36	0.133
7.82	68.41	0.133
7.83	68.46	0.133
7.84	68.51	0.133
7.85	68.56	0.133
7.86	68.61	0.133
7.87	68.66	0.133
7.88	68.71	0.133
7.89	68.76	0.133
7.90	68.81	0.133
7.91	68.86	0.133
7.92	68.91	0.133
7.93	68.96	0.133
7.94	69.01	0.133
7.95	69.07	0.133
7.96	69.11	0.133
7.97	69.16	0.133
7.98	69.21	0.133
7.99	69.26	0.133
8.00	69.31	0.133
8.01	69.36	0.133
8.02	69.41	0.133
8.03	69.47	0.133
8.04	69.51	0.133
8.05	69.56	0.133
8.06	69.61	0.134
8.07	69.66	0.134
8.08	69.71	0.134
8.09	69.77	0.134
8.10	69.81	0.134
8.11	69.86	0.134
8.12	69.91	0.134
8.13	69.96	0.134
8.14	70.01	0.134
8.15	70.06	0.134
8.16	70.11	0.134
8.17	70.16	0.134
8.18	70.22	0.134
8.19	70.26	0.134
8.20	70.31	0.134
8.21	70.36	0.134
8.22	70.41	0.134
8.23	70.47	0.134
8.24	70.51	0.134
8.25	70.56	0.134
8.26	70.61	0.134
8.27	70.66	0.134
8.28	70.71	0.134
8.29	70.76	0.134
8.30	70.81	0.134
8.31	70.86	0.134
8.32	70.91	0.134
8.33	70.96	0.134
8.34	71.01	0.134
8.35	71.07	0.134
8.36	71.12	0.135
8.37	71.16	0.135
8.38	71.21	0.135
8.39	71.26	0.135
8.40	71.31	0.135
8.41	71.37	0.135
8.42	71.41	0.135
8.43	71.47	0.135
8.44	71.52	0.135
8.45	71.57	0.135
8.46	71.62	0.135
8.47	71.67	0.135
8.48	71.72	0.135
8.49	71.76	0.135
8.50	71.82	0.135
8.51	71.86	0.135
8.52	71.91	0.135
8.53	71.97	0.135
8.54	72.01	0.135
8.55	72.07	0.135
8.56	72.12	0.135
8.57	72.17	0.135
8.58	72.22	0.135
8.59	72.27	0.135
8.60	72.32	0.135
8.61	72.37	0.135
8.62	72.42	0.135
8.63	72.47	0.136
8.64	72.51	0.136
8.65	72.57	0.135
8.66	72.62	0.136
8.67	72.67	0.136
8.68	72.72	0.136
8.69	72.77	0.136
8.70	72.82	0.136
8.71	72.87	0.136
8.72	72.92	0.136
8.73	72.97	0.136
8.74	73.02	0.136
8.75	73.07	0.136
8.76	73.12	0.136
8.77	73.17	0.136
8.78	73.22	0.136
8.79	73.27	0.136
8.80	73.32	0.136
8.81	73.37	0.136
8.82	73.42	0.136
8.83	73.47	0.136
8.84	73.52	0.136
8.85	73.57	0.136
8.86	73.62	0.136
8.87	73.67	0.136
8.88	73.72	0.136
8.89	73.77	0.137
8.90	73.82	0.137
8.91	73.87	0.137
8.92	73.92	0.137
8.93	73.96	0.137
8.94	74.02	0.137
8.95	74.07	0.137
8.96	74.11	0.137
8.97	74.17	0.137
8.98	74.22	0.137
8.99	74.27	0.137
9.00	74.32	0.137
9.01	74.37	0.137
9.02	74.42	0.137
9.03	74.47	0.137
9.04	74.52	0.137
9.05	74.57	0.137
9.06	74.62	0.137
9.07	74.67	0.137
9.08	74.72	0.137
9.09	74.77	0.137
9.10	74.82	0.137
9.11	74.87	0.137
9.12	74.92	0.137
9.13	74.97	0.138
9.14	75.02	0.138
9.15	75.07	0.138
9.16	75.12	0.138
9.17	75.17	0.138
9.18	75.22	0.138
9.19	75.27	0.138
9.20	75.32	0.138
9.21	75.37	0.138
9.22	75.42	0.138
9.23	75.47	0.138
9.24	75.52	0.138
9.25	75.57	0.138
9.26	75.62	0.138
9.27	75.67	0.138
9.28	75.72	0.138
9.29	75.77	0.138
9.30	75.82	0.138
9.31	75.87	0.138
9.32	75.92	0.139
9.33	75.97	0.139
9.34	76.02	0.139
9.35	76.07	0.139
9.36	76.12	0.139
9.37	76.17	0.139
9.38	76.22	0.139
9.39	76.27	0.139
9.40	76.32	0.139
9.41	76.37	0.139
9.42	76.42	0.139
9.43	76.47	0.139
9.44	76.52	0.139
9.45	76.57	0.139
9.46	76.62	0.139
9.47	76.67	0.139
9.48	76.72	0.139
9.49	76.77	0.140
9.50	76.82	0.140
9.51	76.87	0.140
9.52	76.92	0.140
9.53	76.97	0.140
9.54	77.02	0.140
9.55	77.07	0.140
9.56	77.12	0.140
9.57	77.17	0.140
9.58	77.22	0.141
9.59	77.27	0.141
9.60	77.32	0.141
9.61	77.37	0.141
9.62	77.42	0.142
9.63	77.47	0.142
9.64	77.51	0.143
9.65	77.57	0.145
9.66	77.61	0.147
9.67	77.66	0.153
9.68	77.71	0.157
9.69	77.76	0.163
9.70	77.81	0.169
9.71	77.86	0.177
9.72	77.91	0.184
9.73	77.96	0.192
9.74	78.01	0.199
9.75	78.06	0.209
9.76	78.11	0.221
9.77	78.15	0.231
9.78	78.20	0.246
9.79	78.25	0.258
9.80	78.30	0.274
9.81	78.34	0.288
9.82	78.39	0.307
9.83	78.44	0.324
9.84	78.49	0.344
9.85	78.53	0.365
9.86	78.58	0.386
9.87	78.62	0.410
9.88	78.67	0.435
9.89	78.71	0.460
9.90	78.76	0.489
9.91	78.80	0.517
9.92	78.85	0.549
9.93	78.89	0.590
9.94	78.93	0.632
9.95	78.97	0.682
9.96	79.01	0.732
9.97	79.06	0.785
9.98	79.10	0.845
9.99	79.13	0.909
10.00	79.17	0.976
10.01	79.21	1.053
10.02	79.24	1.135
10.03	79.28	1.224
10.04	79.31	1.311
10.05	79.34	1.393
10.06	79.38	1.483
10.07	79.41	1.608
10.08	79.43	1.759
10.09	79.46	1.922
10.10	79.48	2.120
10.11	79.50	2.255
10.12	79.51	2.446
10.13	79.53	2.611
10.14	79.54	2.783
10.15	79.55	2.983
10.16	79.56	3.205
10.17	79.57	3.424
10.18	79.57	3.683
10.19	79.57	3.831
10.20	79.58	3.922
10.21	79.59	4.040
10.22	79.60	4.268
10.23	79.60	4.586
10.24	79.60	4.885
10.25	79.60	4.995
10.26	79.61	5.110
10.27	79.61	5.181
10.28	79.63	5.231
10.29	79.65	5.260
10.30	79.66	5.538
10.31	79.68	5.758
10.32	79.68	5.916
10.33	79.70	5.862
10.34	79.73	5.757
10.35	79.76	5.911
10.36	79.78	6.282
10.37	79.79	6.360
10.38	79.81	6.258
10.39	79.85	6.052
10.40	79.90	6.022
10.41	79.94	6.083
10.42	79.99	5.765
10.43	80.06	5.570
10.44	80.13	5.554
10.45	80.19	5.406
10.46	80.26	5.148
10.47	80.35	4.915
10.48	80.43	4.743
10.49	80.52	4.429
10.50	80.62	4.016
10.51	80.72	3.804
10.52	80.82	3.700
10.53	80.92	3.491
10.54	81.01	3.260
10.55	81.11	3.037
10.56	81.22	2.805
10.57	81.32	2.508
10.58	81.43	2.099
10.59	81.55	1.728
10.60	81.67	1.462
10.61	81.79	1.228
10.62	81.90	1.071
10.63	82.01	0.962
10.64	82.11	0.877
10.65	82.20	0.790
10.66	82.29	0.728
10.67	82.38	0.661
10.68	82.46	0.605
10.69	82.54	0.556
10.70	82.61	0.512
10.71	82.68	0.474
10.72	82.75	0.436
10.73	82.82	0.406
10.74	82.89	0.376
10.75	82.95	0.353
10.76	83.02	0.330
10.77	83.08	0.310
10.78	83.14	0.293
10.79	83.20	0.277
10.80	83.25	0.263
10.81	83.31	0.250
10.82	83.37	0.240
10.83	83.42	0.228
10.84	83.48	0.219
10.85	83.53	0.211
10.86	83.59	0.204
10.87	83.64	0.199
10.88	83.69	0.192
10.89	83.75	0.187
10.90	83.80	0.183
10.91	83.85	0.180
10.92	83.90	0.177
10.93	83.95	0.173
10.94	84.01	0.170
10.95	84.06	0.168
10.96	84.11	0.167
10.97	84.16	0.165
10.98	84.21	0.163
10.99	84.26	0.162
11.00	84.31	0.160
11.01	84.36	0.159
11.02	84.41	0.158
11.03	84.47	0.157
11.04	84.52	0.157
11.05	84.57	0.156
11.06	84.62	0.156
11.07	84.67	0.156
11.08	84.72	0.155
11.09	84.77	0.154
11.10	84.82	0.154
11.11	84.87	0.154
11.12	84.92	0.153
11.13	84.97	0.153
11.14	85.02	0.153
11.15	85.07	0.153
11.16	85.12	0.152
11.17	85.17	0.152
11.18	85.22	0.152
11.19	85.27	0.152
11.20	85.32	0.152
11.21	85.37	0.152
11.22	85.42	0.151
11.23	85.47	0.151
11.24	85.52	0.151
11.25	85.57	0.151
11.26	85.62	0.151
11.27	85.67	0.151
11.28	85.72	0.150
11.29	85.77	0.150
11.30	85.82	0.150
11.31	85.87	0.150
11.32	85.92	0.150
11.33	85.97	0.150
11.34	86.02	0.150
11.35	86.07	0.150
11.36	86.12	0.150
11.37	86.17	0.150
11.38	86.22	0.149
11.39	86.27	0.149
11.40	86.32	0.149
11.41	86.37	0.149
11.42	86.42	0.149
11.43	86.47	0.149
11.44	86.52	0.149
11.45	86.57	0.149
11.46	86.62	0.149
11.47	86.67	0.149
11.48	86.72	0.149
11.49	86.77	0.149
11.50	86.82	0.149
11.51	86.87	0.149
11.52	86.92	0.149
11.53	86.97	0.148
11.54	87.02	0.148
11.55	87.07	0.148
11.56	87.12	0.148
11.57	87.17	0.148
11.58	87.22	0.148
11.59	87.27	0.148
11.60	87.32	0.148
11.61	87.37	0.148
11.62	87.42	0.148
11.63	87.47	0.148
11.64	87.52	0.148
11.65	87.57	0.148
11.66	87.62	0.148
11.67	87.67	0.148
11.68	87.72	0.148
11.69	87.77	0.148
11.70	87.82	0.148
11.71	87.87	0.148
11.72	87.92	0.148
11.73	87.97	0.148
11.74	88.02	0.148
11.75	88.07	0.148
11.76	88.12	0.148
11.77	88.17	0.148
11.78	88.22	0.148
11.79	88.27	0.148
11.80	88.32	0.148
11.81	88.37	0.148
11.82	88.42	0.148
11.83	88.47	0.148
11.84	88.52	0.148
11.85	88.57	0.148
11.86	88.62	0.148
11.87	88.67	0.148
11.88	88.72	0.148
11.89	88.77	0.148
11.90	88.82	0.148
11.91	88.87	0.148
11.92	88.92	0.148
11.93	88.97	0.148
11.94	89.02	0.148
11.95	89.07	0.148
11.96	89.12	0.148
11.97	89.17	0.148
11.98	89.22	0.148
11.99	89.27	0.148
12.00	89.32	0.149
12.01	89.37	0.149
12.02	89.42	0.149
12.03	89.47	0.149
12.04	89.52	0.149
12.05	89.57	0.149
12.06	89.62	0.149
12.07	89.67	0.149
12.08	89.72	0.149
12.09	89.77	0.149
12.10	89.82	0.149
12.11	89.87	0.149
12.12	89.92	0.149
12.13	89.97	0.149
12.14	90.02	0.149
12.15	90.07	0.149
12.16	90.12	0.149
12.17	90.17	0.149
12.18	90.22	0.149
12.19	90.27	0.149
12.20	90.32	0.149
12.21	90.37	0.149
12.22	90.42	0.149
12.23	90.47	0.149
12.24	90.52	0.149
12.25	90.57	0.149
12.26	90.62	0.149
12.27	90.67	0.149
12.28	90.72	0.149
12.29	90.77	0.149
12.30	90.82	0.149
12.31	90.87	0.149
12.32	90.92	0.149
12.33	90.97	0.149
12.34	91.02	0.149
12.35	91.07	0.149
12.36	91.12	0.149
12.37	91.17	0.149
12.38	91.22	0.149
12.39	91.27	0.149
12.40	91.32	0.149
12.41	91.37	0.149
12.42	91.42	0.149
12.43	91.47	0.149
12.44	91.52	0.149
12.45	91.57	0.149
12.46	91.62	0.149
12.47	91.67	0.149
12.48	91.72	0.149
12.49	91.77	0.149
12.50	91.82	0.149
12.51	91.87	0.149
12.52	91.92	0.149
12.53	91.97	0.149
12.54	92.02	0.149
12.55	92.07	0.149
12.56	92.12	0.149
12.57	92.17	0.149
12.58	92.22	0.149
12.59	92.27	0.150
12.60	92.32	0.150
12.61	92.37	0.150
12.62	92.42	0.150
12.63	92.47	0.150
12.64	92.52	0.150
12.65	92.57	0.150
12.66	92.62	0.150
12.67	92.67	0.150
12.68	92.72	0.150
12.69	92.77	0.150
12.70	92.82	0.150
12.71	92.87	0.150
12.72	92.92	0.150
12.73	92.97	0.150
12.74	93.02	0.150
12.75	93.07	0.150
12.76	93.12	0.150
12.77	93.17	0.150
12.78	93.22	0.150
12.79	93.27	0.150
12.80	93.32	0.150
12.81	93.37	0.150
12.82	93.42	0.150
12.83	93.47	0.150
12.84	93.52	0.150
12.85	93.57	0.150
12.86	93.62	0.150
12.87	93.67	0.150
12.88	93.72	0.150
12.89	93.77	0.150
12.90	93.82	0.150
12.91	93.87	0.150
12.92	93.92	0.150
12.93	93.97	0.150
12.94	94.02	0.150
12.95	94.07	0.150
12.96	94.12	0.150
12.97	94.17	0.150
12.98	94.22	0.151
12.99	94.27	0.151
13.00	94.32	0.151
13.01	94.37	0.151
13.02	94.42	0.151
13.03	94.47	0.151
13.04	94.52	0.151
13.05	94.57	0.151
13.06	94.62	0.151
13.07	94.67	0.151
13.08	94.72	0.151
13.09	94.77	0.151
13.10	94.82	0.151
13.11	94.87	0.151
13.12	94.92	0.151
13.13	94.97	0.151
13.14	95.02	0.151
13.15	95.07	0.151
13.16	95.12	0.151
13.17	95.17	0.151
13.18	95.22	0.151
13.19	95.27	0.151
13.20	95.32	0.151
13.21	95.37	0.151
13.22	95.42	0.151
13.23	95.47	0.151
13.24	95.52	0.151
13.25	95.57	0.151
13.26	95.62	0.151
13.27	95.67	0.151
13.28	95.72	0.151
13.29	95.77	0.151
13.30	95.82	0.151
13.31	95.87	0.151
13.32	95.92	0.151
13.33	95.97	0.151
13.34	96.02	0.151
13.35	96.07	0.151
13.36	96.12	0.151
13.37	96.17	0.151
13.38	96.22	0.151
13.39	96.27	0.151
13.40	96.32	0.152
13.41	96.37	0.152
13.42	96.43	0.152
13.43	96.48	0.152
13.44	96.52	0.152
13.45	96.58	0.152
13.46	96.63	0.152
13.47	96.68	0.152
13.48	96.73	0.152
13.49	96.78	0.152
13.50	96.82	0.152
13.51	96.88	0.152
13.52	96.93	0.152
13.53	96.98	0.152
13.54	97.03	0.152
13.55	97.08	0.152
13.56	97.13	0.152
13.57	97.18	0.152
13.58	97.22	0.152
13.59	97.28	0.152
13.60	97.33	0.152
13.61	97.38	0.152
13.62	97.42	0.152
13.63	97.48	0.152
13.64	97.52	0.152
13.65	97.57	0.152
13.66	97.63	0.152
13.67	97.68	0.152
13.68	97.73	0.152
13.69	97.77	0.152
13.70	97.83	0.152
13.71	97.87	0.152
13.72	97.92	0.152
13.73	97.98	0.152
13.74	98.02	0.152
13.75	98.07	0.152
13.76	98.12	0.152
13.77	98.17	0.152
13.78	98.23	0.152
13.79	98.28	0.152
13.80	98.32	0.152
13.81	98.37	0.152
13.82	98.42	0.152
13.83	98.48	0.152
13.84	98.52	0.152
13.85	98.58	0.152
13.86	98.63	0.152
13.87	98.68	0.152
13.88	98.73	0.152
13.89	98.78	0.152
13.90	98.83	0.153
13.91	98.88	0.153
13.92	98.93	0.153
13.93	98.98	0.153
13.94	99.03	0.153
13.95	99.08
13.96	99.13
13.97	99.18
13.98	99.23
13.99	99.27
14.00
14.00