File: DSC/2025_02_13_CBD_Rerun_2023_Melted_12_DSC.txt
Filename	2025_02_13_CBD_Rerun_2023_Melted_12_DSC
Instrument name	DSC2A-00468 (192.168.1.100)
Operator	JLY
rundate	2/14/2025
Sample name	2025_02_13_CBD_Rerun_2023_Melted_12_DSC
proceduresegments	Data Off ; Equilibrate -40.00 °C; Data On ; Ramp 5.00 °C/min to 100.00 °C; Data Off ; Isothermal 1.0 min; Data On ; Ramp 5.00 °C/min to -40.00 °C; Data Off ; Isothermal 1.0 min; Data On ; Ramp 5.00 °C/min to 100.00 °C; Data Off ; Isothermal 1.0 min; Data On ; Ramp 5.00 °C/min to -40.00 °C; Data Off ; Isothermal 1.0 min; Data On ; Ramp 5.00 °C/min to 100.00 °C
[File Parameters]
Run date	2/14/2025 2:59:47 AM
Trios version	5.1.1.46572
Original File Name
Current File Name	D:\DSC2500\CHM343\2025_02_13_CBD_Rerun_2023_Melted_12_DSC.tri
[Procedure]
Procedure Name	CBD Test
Sample Name	2025_02_13_CBD_Rerun_2023_Melted_12_DSC
Sample Mass	7.52 mg
Reference Sample Mass	0 mg
Pan Mass	53.84 mg
Pan Number	12
Reference Pan Mass	54 mg
Reference Pan Number	19
Pan Type	Tzero Aluminum Hermetic
Comments	Al Hermetic Sealed Pan, with ref Al pan.  8/7/23 SBK CBD Sample.  Sitting in DSC Tray and test if its recrystallized after 6+ months.
Project Name
Operator	JLY
Test	Custom
Unload Max Temperature	30
Unload Min Temperature	30
Load Max Temperature	30
Load Min Temperature	30
Stop on Gas Flow Error	Yes
[Signal List]
Signal #1	Time (min)
Signal #2	Temperature (°C)
Signal #3	Heat Flow (mW)
Signal #4	Delta T (µV)
Signal #5	Delta Tzero (µV)
Signal #6	Tzero Temperature (°C)
Signal #7	Cell Purge (mL/min)
Signal #8	Heater Temp (°C)
Signal #9	Power Delivered (W)
Signal #10	Reference Junction Temperature (°C)
Signal #11	Flange Temperature (°C)
Signal #12	Heat Flow Phase (rad)
Signal #13	Total Heat Capacity (J/°C)
Signal #14	Heat Capacity (J/°C)
[Configuration]
Company Name	ASU
Instrument Name	DSC2A-00468
Instrument Type	DSC2500
Serial Number	DSC2A-00468
IP	192.168.1.100
Location of Instrument	MRRC
DisplayType	Unknown
Sample Interval 	0.1 s/pt
Selected Heat Flow	T4P
Exotherm Direction	Down
Cell Serial	DRC2-00792
Lid Type	Standard
Cooler	RCS 90
Leave Cooler on at End of Sequence	On
Gas 2	Nitrogen
Gas Selected	Channel 1
Flow Rate	50 mL/min
Secondary Purge	On
Licensed Heat Flow	Heat Flow T4P
Modulation Licensed	Yes
[Versions]
Common IDD Version	1
Cortex Version	VER 2.10.2.31
Driver	5.0.0.6
GDM Version	1.0.3.3
TouchscreenVersion	1.0.0.16145
FEP Version	1.2.1.21
FEP Bootloader	2.0.0.5
AutoSampler Version	2.1.1.26
Auto Sampler Bootloader	2.0.0.5
FCM Version	1.1.0.3
FCM Bootloader	2.0.0.5
[Experiment Logs]
Experiment Log Entry # 1	Data On set to 0
Experiment Log Entry # 3	Equilibrate Segment -40 (C) Started
Experiment Log Entry # 5	Air Cool is off.
Experiment Log Entry # 7	Data On set to 1
Experiment Log Entry # 9	Ramp Segment 5 C/min to 100 Started
Experiment Log Entry # 11	Data On set to 0
Experiment Log Entry # 13	Isothermal Segment 1 min started
Experiment Log Entry # 15	Data On set to 1
Experiment Log Entry # 17	Ramp Segment 5 C/min to -40 Started
Experiment Log Entry # 19	Data On set to 0
Experiment Log Entry # 21	Isothermal Segment 1 min started
Experiment Log Entry # 23	Data On set to 1
Experiment Log Entry # 25	Ramp Segment 5 C/min to 100 Started
Experiment Log Entry # 27	Data On set to 0
Experiment Log Entry # 29	Isothermal Segment 1 min started
Experiment Log Entry # 31	Data On set to 1
Experiment Log Entry # 33	Ramp Segment 5 C/min to -40 Started
Experiment Log Entry # 35	Data On set to 0
Experiment Log Entry # 37	Isothermal Segment 1 min started
Experiment Log Entry # 39	Data On set to 1
Experiment Log Entry # 41	Ramp Segment 5 C/min to 100 Started
[Method Log]
Method Log Entry # 1	Data Off
Method Log Entry # 2	Equilibrate -40 °C
Method Log Entry # 3	Data On
Method Log Entry # 4	(Ramp 138467) Ramp 5 °C/minute to 100 °C
Method Log Entry # 5	Data Off
Method Log Entry # 6	Isothermal 1 minutes
Method Log Entry # 7	Data On
Method Log Entry # 8	(Ramp 138471) Ramp 5 °C/minute to -40 °C
Method Log Entry # 9	Data Off
Method Log Entry # 10	Isothermal 1 minutes
Method Log Entry # 11	Data On
Method Log Entry # 12	(Ramp 138475) Ramp 5 °C/minute to 100 °C
Method Log Entry # 13	Data Off
Method Log Entry # 14	Isothermal 1 minutes
Method Log Entry # 15	Data On
Method Log Entry # 16	(Ramp 138479) Ramp 5 °C/minute to -40 °C
Method Log Entry # 17	Data Off
Method Log Entry # 18	Isothermal 1 minutes
Method Log Entry # 19	Data On
Method Log Entry # 20	(Ramp 138483) Ramp 5 °C/minute to 100 °C
Cell Serial	DRC2-00792
[T1 Calibration]
Slope	-0.008529666
Offset	9.636258
Initial Temperature	98.23
GUID	f8bfdadc-4977-4fdf-ba6d-0ba9134940c3
[TZero Calibration]
Date Applied	11/29/2022 4:06:13 PM
Description	From -89.059 °C to 396.009 °C at 20.000°C/min
Gas Type	Nitrogen
Pan Type	None
Source Files 1	C:\Users\yargerlab\Desktop\DSC Data\General\TZero_calibration_11_29_22_2nd(2).tri
Source Files 2	C:\Users\yargerlab\Desktop\DSC Data\General\TZero_calibration_11_29_22_2nd(3).tri
Delta T Offset	13.05235
Delta T Slope	-0.007271007
Delta T0 Offset	-13.69128
Delta T0 Slope	0.06063341
[Temperature Calibration]
Date Applied	11/29/2022 7:12:28 PM
Description	From 106.590 °C to 186.590 °C at 10.000°C/min
Gas Type	Nitrogen
Pan Type	Tzero Aluminum Hermetic
Source Files 1	C:\Users\yargerlab\Desktop\DSC Data\General\Indium(6).tri
Measured 1	157.391
Known 1	156.598
[Cell Constant Calibration]
Date Applied	11/29/2022 7:12:29 PM
Description	From 106.590 °C to 186.590 °C at 10.000°C/min
Gas Type	Nitrogen
Pan Type	Tzero Aluminum Hermetic
Source Files 1	C:\Users\yargerlab\Desktop\DSC Data\General\Indium(6).tri
T4P KCell	1.006051
Onset Slope	63.26126 mW/°C
[Direct Cp Calibration]
Date Applied	11/30/2022 11:04:51 AM
Description	From -79.983 °C to 298.409 °C at 10.000°C/min
Gas Type	Nitrogen
Pan Type	Tzero Aluminum Hermetic
Source Files 1	C:\Users\yargerlab\Desktop\DSC Data\General\Sapphire_Heat_Capacity_11_30_22.tri
[Rev Cp Calibration]
Date Applied	11/30/2022 1:58:51 PM
Description	From -79.996 °C to 292.812 °C at 3.000°C/min
Gas Type	Nitrogen
Pan Type	Tzero Aluminum Hermetic
Source Files 1	C:\Users\yargerlab\Desktop\DSC Data\General\Sapphire_MDSC_Calibration_11_30_22.tri
[step]
Ramp 5.00 °C/min to 100.00 °C
Time	Temperature	Heat Flow (Normalized)
min	°C	W/g
0.00	-39.69	-0.075
0.02	-39.71	-0.075
0.04	-39.72	-0.066
0.06	-39.72	-0.061
0.08	-39.72	-0.062
0.10	-39.70	-0.067
0.12	-39.66	-0.081
0.14	-39.62	-0.091
0.16	-39.57	-0.097
0.18	-39.50	-0.097
0.20	-39.44	-0.095
0.22	-39.36	-0.087
0.24	-39.29	-0.074
0.26	-39.21	-0.062
0.28	-39.12	-0.052
0.30	-39.04	-0.041
0.32	-38.96	-0.032
0.34	-38.87	-0.025
0.36	-38.78	-0.017
0.38	-38.70	-0.011
0.40	-38.61	-0.006
0.42	-38.52	-0.001
0.44	-38.43	0.003
0.46	-38.33	0.007
0.48	-38.24	0.010
0.50	-38.15	0.013
0.52	-38.06	0.016
0.54	-37.96	0.017
0.56	-37.87	0.019
0.58	-37.77	0.020
0.60	-37.68	0.022
0.62	-37.58	0.023
0.64	-37.48	0.024
0.66	-37.39	0.025
0.68	-37.29	0.026
0.70	-37.19	0.026
0.72	-37.10	0.027
0.74	-37.00	0.027
0.76	-36.90	0.028
0.78	-36.80	0.028
0.80	-36.71	0.029
0.82	-36.61	0.029
0.84	-36.51	0.029
0.86	-36.41	0.029
0.88	-36.32	0.030
0.90	-36.22	0.030
0.92	-36.12	0.030
0.94	-36.02	0.030
0.96	-35.92	0.031
0.98	-35.82	0.031
1.00	-35.73	0.031
1.02	-35.63	0.031
1.04	-35.53	0.032
1.06	-35.43	0.032
1.08	-35.33	0.032
1.10	-35.23	0.032
1.12	-35.13	0.032
1.14	-35.03	0.032
1.16	-34.94	0.033
1.18	-34.84	0.033
1.20	-34.74	0.033
1.22	-34.64	0.033
1.24	-34.54	0.033
1.26	-34.44	0.033
1.28	-34.34	0.033
1.30	-34.24	0.034
1.32	-34.14	0.034
1.34	-34.04	0.034
1.36	-33.94	0.034
1.38	-33.84	0.034
1.40	-33.74	0.034
1.42	-33.64	0.034
1.44	-33.54	0.034
1.46	-33.44	0.034
1.48	-33.35	0.034
1.50	-33.25	0.034
1.52	-33.15	0.034
1.54	-33.05	0.034
1.56	-32.95	0.034
1.58	-32.85	0.034
1.60	-32.75	0.034
1.62	-32.65	0.034
1.64	-32.55	0.034
1.66	-32.45	0.034
1.68	-32.35	0.034
1.70	-32.25	0.034
1.72	-32.15	0.034
1.74	-32.05	0.034
1.76	-31.95	0.034
1.78	-31.85	0.034
1.80	-31.75	0.034
1.82	-31.65	0.034
1.84	-31.55	0.034
1.86	-31.45	0.035
1.88	-31.35	0.034
1.90	-31.25	0.034
1.92	-31.15	0.034
1.94	-31.05	0.034
1.96	-30.95	0.035
1.98	-30.85	0.035
2.00	-30.75	0.035
2.02	-30.65	0.034
2.04	-30.55	0.034
2.06	-30.45	0.035
2.08	-30.35	0.035
2.10	-30.25	0.035
2.12	-30.15	0.035
2.14	-30.05	0.035
2.16	-29.95	0.035
2.18	-29.85	0.034
2.20	-29.75	0.034
2.22	-29.65	0.034
2.24	-29.55	0.034
2.26	-29.45	0.034
2.28	-29.35	0.034
2.30	-29.25	0.034
2.32	-29.15	0.034
2.34	-29.05	0.034
2.36	-28.95	0.034
2.38	-28.85	0.034
2.40	-28.75	0.034
2.42	-28.65	0.034
2.44	-28.55	0.034
2.46	-28.45	0.034
2.48	-28.35	0.034
2.50	-28.25	0.034
2.52	-28.15	0.034
2.54	-28.05	0.034
2.56	-27.95	0.034
2.58	-27.85	0.034
2.60	-27.75	0.034
2.62	-27.65	0.034
2.64	-27.55	0.034
2.66	-27.45	0.034
2.68	-27.35	0.034
2.70	-27.25	0.034
2.72	-27.15	0.034
2.74	-27.05	0.034
2.76	-26.95	0.034
2.78	-26.85	0.034
2.80	-26.75	0.034
2.82	-26.65	0.034
2.84	-26.55	0.034
2.86	-26.45	0.034
2.88	-26.35	0.034
2.90	-26.25	0.034
2.92	-26.15	0.035
2.94	-26.05	0.035
2.96	-25.95	0.035
2.98	-25.85	0.035
3.00	-25.75	0.035
3.02	-25.65	0.035
3.04	-25.55	0.035
3.06	-25.45	0.035
3.08	-25.35	0.035
3.10	-25.25	0.035
3.12	-25.14	0.035
3.14	-25.05	0.035
3.16	-24.95	0.035
3.18	-24.85	0.035
3.20	-24.75	0.035
3.22	-24.65	0.035
3.24	-24.55	0.035
3.26	-24.45	0.035
3.28	-24.35	0.035
3.30	-24.25	0.035
3.32	-24.15	0.035
3.34	-24.05	0.035
3.36	-23.95	0.035
3.38	-23.85	0.035
3.40	-23.74	0.035
3.42	-23.64	0.035
3.44	-23.55	0.035
3.46	-23.45	0.035
3.48	-23.35	0.035
3.50	-23.25	0.035
3.52	-23.14	0.035
3.54	-23.05	0.035
3.56	-22.95	0.036
3.58	-22.84	0.036
3.60	-22.75	0.036
3.62	-22.65	0.036
3.64	-22.54	0.036
3.66	-22.44	0.036
3.68	-22.34	0.036
3.70	-22.24	0.036
3.72	-22.15	0.036
3.74	-22.05	0.036
3.76	-21.94	0.036
3.78	-21.85	0.036
3.80	-21.75	0.036
3.82	-21.64	0.036
3.84	-21.54	0.036
3.86	-21.44	0.036
3.88	-21.34	0.037
3.90	-21.24	0.037
3.92	-21.14	0.037
3.94	-21.04	0.037
3.96	-20.94	0.037
3.98	-20.85	0.037
4.00	-20.75	0.037
4.02	-20.64	0.037
4.04	-20.55	0.038
4.06	-20.44	0.038
4.08	-20.34	0.038
4.10	-20.25	0.038
4.12	-20.15	0.038
4.14	-20.05	0.038
4.16	-19.95	0.038
4.18	-19.84	0.038
4.20	-19.74	0.038
4.22	-19.64	0.039
4.24	-19.54	0.039
4.26	-19.44	0.039
4.28	-19.34	0.039
4.30	-19.24	0.039
4.32	-19.14	0.039
4.34	-19.04	0.040
4.36	-18.94	0.040
4.38	-18.84	0.040
4.40	-18.75	0.040
4.42	-18.65	0.040
4.44	-18.54	0.040
4.46	-18.45	0.041
4.48	-18.35	0.041
4.50	-18.25	0.041
4.52	-18.15	0.041
4.54	-18.04	0.042
4.56	-17.95	0.042
4.58	-17.85	0.042
4.60	-17.75	0.043
4.62	-17.65	0.043
4.64	-17.55	0.043
4.66	-17.44	0.043
4.68	-17.35	0.044
4.70	-17.25	0.044
4.72	-17.15	0.044
4.74	-17.05	0.045
4.76	-16.95	0.045
4.78	-16.85	0.045
4.80	-16.75	0.045
4.82	-16.65	0.046
4.84	-16.55	0.047
4.86	-16.45	0.047
4.88	-16.35	0.047
4.90	-16.25	0.048
4.92	-16.15	0.048
4.94	-16.05	0.048
4.96	-15.95	0.049
4.98	-15.85	0.050
5.00	-15.75	0.050
5.02	-15.65	0.051
5.04	-15.55	0.051
5.06	-15.45	0.052
5.08	-15.35	0.052
5.10	-15.25	0.053
5.12	-15.15	0.054
5.14	-15.05	0.054
5.16	-14.95	0.055
5.18	-14.85	0.055
5.20	-14.75	0.056
5.22	-14.65	0.057
5.24	-14.55	0.058
5.26	-14.45	0.059
5.28	-14.35	0.060
5.30	-14.25	0.061
5.32	-14.15	0.062
5.34	-14.05	0.062
5.36	-13.95	0.063
5.38	-13.86	0.063
5.40	-13.76	0.064
5.42	-13.66	0.064
5.44	-13.56	0.065
5.46	-13.46	0.066
5.48	-13.36	0.066
5.50	-13.26	0.067
5.52	-13.16	0.068
5.54	-13.06	0.068
5.56	-12.96	0.068
5.58	-12.86	0.069
5.60	-12.76	0.069
5.62	-12.66	0.069
5.64	-12.56	0.070
5.66	-12.46	0.070
5.68	-12.36	0.070
5.70	-12.26	0.071
5.72	-12.16	0.071
5.74	-12.06	0.071
5.76	-11.96	0.072
5.78	-11.86	0.072
5.80	-11.76	0.072
5.82	-11.66	0.072
5.84	-11.56	0.072
5.86	-11.46	0.072
5.88	-11.36	0.072
5.90	-11.26	0.072
5.92	-11.16	0.072
5.94	-11.06	0.072
5.96	-10.96	0.072
5.98	-10.86	0.072
6.00	-10.76	0.072
6.02	-10.66	0.072
6.04	-10.56	0.072
6.06	-10.46	0.071
6.08	-10.36	0.071
6.10	-10.26	0.071
6.12	-10.16	0.071
6.14	-10.06	0.070
6.16	-9.96	0.070
6.18	-9.86	0.070
6.20	-9.75	0.070
6.22	-9.65	0.070
6.24	-9.55	0.069
6.26	-9.45	0.069
6.28	-9.35	0.069
6.30	-9.25	0.069
6.32	-9.15	0.069
6.34	-9.05	0.069
6.36	-8.95	0.068
6.38	-8.85	0.068
6.40	-8.75	0.068
6.42	-8.65	0.068
6.44	-8.55	0.068
6.46	-8.45	0.068
6.48	-8.35	0.068
6.50	-8.25	0.068
6.52	-8.15	0.067
6.54	-8.05	0.067
6.56	-7.95	0.067
6.58	-7.85	0.067
6.60	-7.75	0.067
6.62	-7.65	0.067
6.64	-7.55	0.067
6.66	-7.45	0.067
6.68	-7.35	0.067
6.70	-7.25	0.067
6.72	-7.15	0.067
6.74	-7.05	0.066
6.76	-6.95	0.066
6.78	-6.85	0.066
6.80	-6.75	0.066
6.82	-6.65	0.066
6.84	-6.55	0.066
6.86	-6.45	0.066
6.88	-6.35	0.066
6.90	-6.25	0.066
6.92	-6.15	0.066
6.94	-6.05	0.066
6.96	-5.95	0.066
6.98	-5.85	0.066
7.00	-5.75	0.066
7.02	-5.65	0.066
7.04	-5.55	0.066
7.06	-5.45	0.066
7.08	-5.35	0.066
7.10	-5.25	0.066
7.12	-5.15	0.066
7.14	-5.05	0.066
7.16	-4.95	0.066
7.18	-4.85	0.066
7.20	-4.75	0.066
7.22	-4.65	0.066
7.24	-4.55	0.066
7.26	-4.45	0.066
7.28	-4.35	0.066
7.30	-4.25	0.066
7.32	-4.15	0.066
7.34	-4.05	0.066
7.36	-3.95	0.066
7.38	-3.85	0.065
7.40	-3.75	0.066
7.42	-3.65	0.065
7.44	-3.55	0.065
7.46	-3.45	0.065
7.48	-3.35	0.065
7.50	-3.25	0.065
7.52	-3.15	0.065
7.54	-3.05	0.065
7.56	-2.95	0.065
7.58	-2.85	0.065
7.60	-2.75	0.066
7.62	-2.65	0.066
7.64	-2.55	0.066
7.66	-2.45	0.066
7.68	-2.35	0.065
7.70	-2.25	0.065
7.72	-2.15	0.065
7.74	-2.05	0.065
7.76	-1.95	0.065
7.78	-1.85	0.065
7.80	-1.75	0.065
7.82	-1.65	0.065
7.84	-1.55	0.065
7.86	-1.45	0.065
7.88	-1.35	0.065
7.90	-1.25	0.065
7.92	-1.15	0.065
7.94	-1.05	0.065
7.96	-0.95	0.065
7.98	-0.85	0.065
8.00	-0.75	0.065
8.02	-0.65	0.065
8.04	-0.55	0.065
8.06	-0.45	0.065
8.08	-0.35	0.065
8.10	-0.25	0.065
8.12	-0.15	0.065
8.14	-0.05	0.065
8.16	0.05	0.065
8.18	0.15	0.065
8.20	0.25	0.065
8.22	0.35	0.065
8.24	0.45	0.065
8.26	0.55	0.065
8.28	0.65	0.065
8.30	0.76	0.065
8.32	0.86	0.065
8.34	0.95	0.065
8.36	1.05	0.065
8.38	1.15	0.065
8.40	1.25	0.065
8.42	1.36	0.065
8.44	1.45	0.065
8.46	1.56	0.065
8.48	1.66	0.065
8.50	1.76	0.065
8.52	1.86	0.065
8.54	1.96	0.065
8.56	2.06	0.065
8.58	2.16	0.065
8.60	2.26	0.065
8.62	2.36	0.065
8.64	2.46	0.065
8.66	2.56	0.065
8.68	2.66	0.065
8.70	2.76	0.065
8.72	2.86	0.065
8.74	2.96	0.065
8.76	3.06	0.065
8.78	3.16	0.065
8.80	3.26	0.065
8.82	3.36	0.065
8.84	3.46	0.065
8.86	3.56	0.065
8.88	3.66	0.065
8.90	3.76	0.065
8.92	3.86	0.065
8.94	3.96	0.065
8.96	4.06	0.065
8.98	4.16	0.065
9.00	4.26	0.065
9.02	4.36	0.065
9.04	4.46	0.065
9.06	4.56	0.065
9.08	4.66	0.065
9.10	4.76	0.065
9.12	4.86	0.065
9.14	4.96	0.065
9.16	5.06	0.065
9.18	5.16	0.065
9.20	5.26	0.065
9.22	5.36	0.065
9.24	5.46	0.065
9.26	5.56	0.065
9.28	5.66	0.065
9.30	5.76	0.065
9.32	5.86	0.065
9.34	5.96	0.065
9.36	6.06	0.065
9.38	6.16	0.065
9.40	6.26	0.065
9.42	6.36	0.065
9.44	6.46	0.065
9.46	6.56	0.065
9.48	6.66	0.065
9.50	6.76	0.065
9.52	6.86	0.065
9.54	6.96	0.065
9.56	7.06	0.065
9.58	7.16	0.065
9.60	7.26	0.065
9.62	7.36	0.065
9.64	7.46	0.065
9.66	7.56	0.065
9.68	7.66	0.065
9.70	7.76	0.065
9.72	7.86	0.065
9.74	7.96	0.065
9.76	8.06	0.065
9.78	8.16	0.065
9.80	8.26	0.065
9.82	8.36	0.065
9.84	8.46	0.065
9.86	8.56	0.065
9.88	8.66	0.065
9.90	8.76	0.065
9.92	8.86	0.065
9.94	8.96	0.065
9.96	9.06	0.065
9.98	9.16	0.065
10.00	9.26	0.065
10.02	9.36	0.065
10.04	9.46	0.065
10.06	9.56	0.065
10.08	9.66	0.065
10.10	9.76	0.065
10.12	9.86	0.065
10.14	9.96	0.066
10.16	10.06	0.065
10.18	10.16	0.066
10.20	10.26	0.065
10.22	10.36	0.065
10.24	10.46	0.065
10.26	10.56	0.065
10.28	10.66	0.065
10.30	10.76	0.065
10.32	10.86	0.065
10.34	10.96	0.066
10.36	11.06	0.066
10.38	11.16	0.066
10.40	11.26	0.066
10.42	11.36	0.066
10.44	11.47	0.066
10.46	11.57	0.066
10.48	11.67	0.066
10.50	11.77	0.066
10.52	11.86	0.066
10.54	11.96	0.066
10.56	12.06	0.066
10.58	12.16	0.066
10.60	12.26	0.066
10.62	12.36	0.066
10.64	12.47	0.066
10.66	12.57	0.066
10.68	12.66	0.066
10.70	12.77	0.066
10.72	12.87	0.066
10.74	12.97	0.066
10.76	13.06	0.066
10.78	13.16	0.066
10.80	13.27	0.066
10.82	13.37	0.066
10.84	13.46	0.066
10.86	13.56	0.066
10.88	13.66	0.066
10.90	13.77	0.066
10.92	13.87	0.066
10.94	13.97	0.066
10.96	14.07	0.066
10.98	14.17	0.066
11.00	14.27	0.066
11.02	14.37	0.066
11.04	14.47	0.066
11.06	14.57	0.066
11.08	14.67	0.066
11.10	14.77	0.066
11.12	14.87	0.066
11.14	14.97	0.066
11.16	15.07	0.066
11.18	15.17	0.066
11.20	15.27	0.066
11.22	15.37	0.066
11.24	15.47	0.066
11.26	15.57	0.066
11.28	15.67	0.066
11.30	15.77	0.066
11.32	15.87	0.066
11.34	15.97	0.066
11.36	16.07	0.066
11.38	16.17	0.066
11.40	16.27	0.066
11.42	16.37	0.066
11.44	16.47	0.066
11.46	16.57	0.066
11.48	16.67	0.066
11.50	16.77	0.066
11.52	16.87	0.066
11.54	16.97	0.066
11.56	17.07	0.066
11.58	17.17	0.066
11.60	17.27	0.066
11.62	17.37	0.066
11.64	17.47	0.066
11.66	17.57	0.066
11.68	17.67	0.066
11.70	17.77	0.066
11.72	17.87	0.066
11.74	17.97	0.066
11.76	18.07	0.066
11.78	18.17	0.066
11.80	18.27	0.066
11.82	18.37	0.066
11.84	18.47	0.066
11.86	18.57	0.066
11.88	18.67	0.066
11.90	18.77	0.066
11.92	18.87	0.066
11.94	18.97	0.066
11.96	19.07	0.066
11.98	19.17	0.066
12.00	19.27	0.066
12.02	19.37	0.066
12.04	19.47	0.066
12.06	19.57	0.066
12.08	19.67	0.066
12.10	19.77	0.066
12.12	19.87	0.066
12.14	19.97	0.066
12.16	20.07	0.066
12.18	20.17	0.066
12.20	20.27	0.066
12.22	20.37	0.066
12.24	20.47	0.066
12.26	20.57	0.066
12.28	20.67	0.066
12.30	20.77	0.066
12.32	20.87	0.066
12.34	20.97	0.066
12.36	21.07	0.066
12.38	21.17	0.066
12.40	21.27	0.066
12.42	21.37	0.066
12.44	21.47	0.066
12.46	21.57	0.066
12.48	21.67	0.066
12.50	21.77	0.066
12.52	21.87	0.066
12.54	21.97	0.066
12.56	22.07	0.066
12.58	22.17	0.066
12.60	22.27	0.066
12.62	22.37	0.066
12.64	22.47	0.066
12.66	22.57	0.066
12.68	22.67	0.066
12.70	22.77	0.066
12.72	22.87	0.066
12.74	22.97	0.066
12.76	23.07	0.066
12.78	23.17	0.066
12.80	23.27	0.066
12.82	23.37	0.066
12.84	23.47	0.066
12.86	23.57	0.066
12.88	23.67	0.066
12.90	23.77	0.066
12.92	23.87	0.066
12.94	23.97	0.066
12.96	24.07	0.066
12.98	24.17	0.066
13.00	24.27	0.066
13.02	24.37	0.066
13.04	24.47	0.066
13.06	24.57	0.066
13.08	24.67	0.066
13.10	24.77	0.067
13.12	24.87	0.067
13.14	24.97	0.067
13.16	25.07	0.067
13.18	25.17	0.067
13.20	25.27	0.067
13.22	25.37	0.067
13.24	25.47	0.067
13.26	25.57	0.067
13.28	25.67	0.067
13.30	25.77	0.067
13.32	25.87	0.067
13.34	25.97	0.067
13.36	26.07	0.067
13.38	26.17	0.067
13.40	26.27	0.067
13.42	26.37	0.067
13.44	26.47	0.067
13.46	26.57	0.067
13.48	26.67	0.067
13.50	26.77	0.067
13.52	26.87	0.067
13.54	26.97	0.067
13.56	27.07	0.067
13.58	27.17	0.067
13.60	27.27	0.067
13.62	27.37	0.067
13.64	27.48	0.067
13.66	27.58	0.067
13.68	27.67	0.067
13.70	27.77	0.067
13.72	27.87	0.067
13.74	27.97	0.067
13.76	28.07	0.067
13.78	28.18	0.067
13.80	28.27	0.067
13.82	28.37	0.067
13.84	28.48	0.067
13.86	28.58	0.067
13.88	28.68	0.067
13.90	28.78	0.067
13.92	28.88	0.067
13.94	28.97	0.067
13.96	29.07	0.067
13.98	29.18	0.067
14.00	29.28	0.067
14.02	29.38	0.067
14.04	29.48	0.067
14.06	29.58	0.067
14.08	29.68	0.067
14.10	29.78	0.067
14.12	29.88	0.067
14.14	29.98	0.067
14.16	30.08	0.067
14.18	30.18	0.067
14.20	30.28	0.067
14.22	30.38	0.067
14.24	30.48	0.067
14.26	30.58	0.067
14.28	30.68	0.068
14.30	30.78	0.068
14.32	30.88	0.068
14.34	30.98	0.068
14.36	31.08	0.068
14.38	31.18	0.068
14.40	31.28	0.068
14.42	31.38	0.068
14.44	31.48	0.068
14.46	31.58	0.068
14.48	31.68	0.068
14.50	31.78	0.068
14.52	31.88	0.068
14.54	31.98	0.068
14.56	32.08	0.068
14.58	32.18	0.068
14.60	32.28	0.068
14.62	32.38	0.068
14.64	32.48	0.068
14.66	32.58	0.068
14.68	32.68	0.068
14.70	32.78	0.068
14.72	32.88	0.068
14.74	32.98	0.068
14.76	33.08	0.068
14.78	33.18	0.068
14.80	33.28	0.068
14.82	33.38	0.068
14.84	33.48	0.068
14.86	33.58	0.068
14.88	33.68	0.068
14.90	33.78	0.068
14.92	33.88	0.068
14.94	33.98	0.068
14.96	34.08	0.068
14.98	34.18	0.068
15.00	34.28	0.068
15.02	34.38	0.068
15.04	34.48	0.068
15.06	34.58	0.068
15.08	34.68	0.068
15.10	34.78	0.068
15.12	34.88	0.068
15.14	34.98	0.068
15.16	35.08	0.068
15.18	35.18	0.068
15.20	35.28	0.068
15.22	35.38	0.068
15.24	35.48	0.068
15.26	35.58	0.068
15.28	35.68	0.068
15.30	35.78	0.068
15.32	35.88	0.068
15.34	35.98	0.068
15.36	36.08	0.068
15.38	36.18	0.068
15.40	36.28	0.068
15.42	36.38	0.068
15.44	36.48	0.068
15.46	36.58	0.068
15.48	36.68	0.068
15.50	36.78	0.068
15.52	36.88	0.068
15.54	36.98	0.068
15.56	37.08	0.068
15.58	37.18	0.068
15.60	37.28	0.068
15.62	37.38	0.068
15.64	37.48	0.068
15.66	37.58	0.068
15.68	37.68	0.068
15.70	37.78	0.068
15.72	37.88	0.068
15.74	37.98	0.068
15.76	38.08	0.068
15.78	38.18	0.068
15.80	38.28	0.068
15.82	38.38	0.068
15.84	38.48	0.068
15.86	38.58	0.068
15.88	38.68	0.068
15.90	38.78	0.068
15.92	38.88	0.068
15.94	38.98	0.068
15.96	39.08	0.068
15.98	39.18	0.068
16.00	39.28	0.068
16.02	39.38	0.068
16.04	39.48	0.068
16.06	39.58	0.068
16.08	39.68	0.068
16.10	39.78	0.068
16.12	39.88	0.068
16.14	39.98	0.068
16.16	40.08	0.069
16.18	40.18	0.069
16.20	40.28	0.069
16.22	40.38	0.069
16.24	40.48	0.069
16.26	40.58	0.069
16.28	40.68	0.069
16.30	40.78	0.069
16.32	40.88	0.069
16.34	40.98	0.069
16.36	41.08	0.069
16.38	41.18	0.069
16.40	41.28	0.069
16.42	41.38	0.069
16.44	41.48	0.069
16.46	41.58	0.069
16.48	41.68	0.069
16.50	41.79	0.069
16.52	41.88	0.069
16.54	41.98	0.069
16.56	42.08	0.069
16.58	42.19	0.069
16.60	42.28	0.069
16.62	42.38	0.069
16.64	42.48	0.069
16.66	42.58	0.069
16.68	42.68	0.069
16.70	42.78	0.069
16.72	42.88	0.069
16.74	42.98	0.069
16.76	43.08	0.069
16.78	43.18	0.069
16.80	43.28	0.069
16.82	43.38	0.069
16.84	43.48	0.069
16.86	43.58	0.069
16.88	43.68	0.069
16.90	43.78	0.069
16.92	43.89	0.069
16.94	43.98	0.069
16.96	44.09	0.069
16.98	44.18	0.069
17.00	44.29	0.069
17.02	44.38	0.069
17.04	44.49	0.069
17.06	44.59	0.069
17.08	44.69	0.069
17.10	44.78	0.069
17.12	44.89	0.069
17.14	44.99	0.069
17.16	45.09	0.069
17.18	45.19	0.069
17.20	45.28	0.069
17.22	45.39	0.069
17.24	45.49	0.069
17.26	45.59	0.069
17.28	45.69	0.069
17.30	45.79	0.069
17.32	45.89	0.069
17.34	45.99	0.069
17.36	46.09	0.069
17.38	46.19	0.069
17.40	46.29	0.069
17.42	46.39	0.069
17.44	46.49	0.069
17.46	46.59	0.069
17.48	46.69	0.069
17.50	46.79	0.069
17.52	46.89	0.069
17.54	46.99	0.069
17.56	47.09	0.069
17.58	47.19	0.069
17.60	47.29	0.069
17.62	47.39	0.069
17.64	47.49	0.069
17.66	47.59	0.069
17.68	47.69	0.070
17.70	47.79	0.070
17.72	47.89	0.070
17.74	47.99	0.070
17.76	48.09	0.070
17.78	48.19	0.070
17.80	48.29	0.070
17.82	48.39	0.070
17.84	48.49	0.070
17.86	48.59	0.070
17.88	48.69	0.070
17.90	48.79	0.070
17.92	48.89	0.070
17.94	48.99	0.070
17.96	49.09	0.070
17.98	49.19	0.070
18.00	49.29	0.070
18.02	49.39	0.070
18.04	49.49	0.070
18.06	49.59	0.070
18.08	49.69	0.070
18.10	49.79	0.070
18.12	49.89	0.070
18.14	49.99	0.070
18.16	50.09	0.070
18.18	50.19	0.070
18.20	50.29	0.070
18.22	50.39	0.070
18.24	50.49	0.070
18.26	50.59	0.070
18.28	50.69	0.070
18.30	50.79	0.070
18.32	50.89	0.070
18.34	50.99	0.070
18.36	51.09	0.070
18.38	51.19	0.070
18.40	51.29	0.070
18.42	51.39	0.070
18.44	51.49	0.070
18.46	51.59	0.070
18.48	51.69	0.070
18.50	51.79	0.070
18.52	51.89	0.070
18.54	51.99	0.070
18.56	52.09	0.070
18.58	52.19	0.070
18.60	52.29	0.070
18.62	52.39	0.070
18.64	52.49	0.070
18.66	52.59	0.070
18.68	52.69	0.070
18.70	52.79	0.070
18.72	52.89	0.070
18.74	52.99	0.070
18.76	53.09	0.070
18.78	53.19	0.070
18.80	53.29	0.070
18.82	53.39	0.070
18.84	53.49	0.070
18.86	53.59	0.070
18.88	53.69	0.070
18.90	53.79	0.070
18.92	53.89	0.070
18.94	53.99	0.070
18.96	54.09	0.070
18.98	54.19	0.070
19.00	54.29	0.070
19.02	54.39	0.070
19.04	54.49	0.070
19.06	54.59	0.070
19.08	54.69	0.070
19.10	54.79	0.070
19.12	54.89	0.070
19.14	54.99	0.070
19.16	55.09	0.070
19.18	55.19	0.070
19.20	55.29	0.070
19.22	55.39	0.070
19.24	55.49	0.070
19.26	55.59	0.070
19.28	55.69	0.070
19.30	55.79	0.070
19.32	55.89	0.070
19.34	55.99	0.070
19.36	56.09	0.070
19.38	56.19	0.070
19.40	56.29	0.070
19.42	56.39	0.070
19.44	56.49	0.070
19.46	56.59	0.070
19.48	56.69	0.070
19.50	56.79	0.071
19.52	56.90	0.071
19.54	56.99	0.071
19.56	57.09	0.071
19.58	57.19	0.071
19.60	57.29	0.071
19.62	57.39	0.070
19.64	57.49	0.071
19.66	57.59	0.071
19.68	57.69	0.071
19.70	57.79	0.071
19.72	57.89	0.071
19.74	57.99	0.071
19.76	58.09	0.071
19.78	58.19	0.071
19.80	58.29	0.071
19.82	58.40	0.071
19.84	58.50	0.071
19.86	58.59	0.071
19.88	58.69	0.071
19.90	58.80	0.071
19.92	58.89	0.071
19.94	58.99	0.071
19.96	59.10	0.071
19.98	59.20	0.071
20.00	59.30	0.071
20.02	59.40	0.071
20.04	59.50	0.071
20.06	59.60	0.071
20.08	59.70	0.071
20.10	59.79	0.071
20.12	59.89	0.071
20.14	60.00	0.071
20.16	60.10	0.071
20.18	60.20	0.071
20.20	60.30	0.071
20.22	60.40	0.071
20.24	60.50	0.071
20.26	60.60	0.071
20.28	60.70	0.071
20.30	60.80	0.071
20.32	60.90	0.071
20.34	61.00	0.071
20.36	61.09	0.071
20.38	61.20	0.071
20.40	61.30	0.071
20.42	61.40	0.071
20.44	61.50	0.071
20.46	61.60	0.071
20.48	61.70	0.071
20.50	61.80	0.071
20.52	61.90	0.071
20.54	62.00	0.071
20.56	62.10	0.071
20.58	62.20	0.071
20.60	62.30	0.071
20.62	62.40	0.071
20.64	62.50	0.071
20.66	62.60	0.071
20.68	62.70	0.071
20.70	62.80	0.071
20.72	62.90	0.071
20.74	63.00	0.071
20.76	63.10	0.071
20.78	63.20	0.071
20.80	63.30	0.071
20.82	63.40	0.071
20.84	63.50	0.071
20.86	63.60	0.071
20.88	63.70	0.071
20.90	63.80	0.071
20.92	63.90	0.071
20.94	64.00	0.071
20.96	64.10	0.071
20.98	64.20	0.071
21.00	64.30	0.071
21.02	64.40	0.071
21.04	64.50	0.071
21.06	64.60	0.071
21.08	64.70	0.071
21.10	64.80	0.071
21.12	64.90	0.071
21.14	65.00	0.071
21.16	65.10	0.071
21.18	65.20	0.071
21.20	65.30	0.071
21.22	65.40	0.071
21.24	65.50	0.071
21.26	65.60	0.071
21.28	65.70	0.071
21.30	65.80	0.071
21.32	65.90	0.071
21.34	66.00	0.071
21.36	66.10	0.071
21.38	66.20	0.071
21.40	66.30	0.071
21.42	66.40	0.071
21.44	66.50	0.071
21.46	66.60	0.071
21.48	66.70	0.072
21.50	66.80	0.072
21.52	66.90	0.072
21.54	67.00	0.072
21.56	67.10	0.072
21.58	67.20	0.072
21.60	67.30	0.072
21.62	67.40	0.072
21.64	67.50	0.072
21.66	67.60	0.072
21.68	67.70	0.072
21.70	67.80	0.072
21.72	67.90	0.072
21.74	68.00	0.072
21.76	68.10	0.072
21.78	68.20	0.072
21.80	68.30	0.072
21.82	68.40	0.072
21.84	68.50	0.071
21.86	68.60	0.072
21.88	68.70	0.072
21.90	68.80	0.072
21.92	68.90	0.072
21.94	69.00	0.072
21.96	69.10	0.072
21.98	69.20	0.072
22.00	69.30	0.072
22.02	69.40	0.072
22.04	69.50	0.072
22.06	69.60	0.072
22.08	69.70	0.072
22.10	69.80	0.072
22.12	69.90	0.072
22.14	70.00	0.072
22.16	70.10	0.072
22.18	70.20	0.072
22.20	70.30	0.072
22.22	70.40	0.072
22.24	70.50	0.072
22.26	70.60	0.072
22.28	70.70	0.072
22.30	70.80	0.072
22.32	70.90	0.072
22.34	71.00	0.072
22.36	71.10	0.072
22.38	71.20	0.072
22.40	71.30	0.072
22.42	71.40	0.072
22.44	71.50	0.072
22.46	71.60	0.072
22.48	71.70	0.072
22.50	71.80	0.072
22.52	71.90	0.072
22.54	72.00	0.072
22.56	72.10	0.072
22.58	72.20	0.072
22.60	72.30	0.072
22.62	72.40	0.072
22.64	72.50	0.072
22.66	72.60	0.072
22.68	72.70	0.072
22.70	72.80	0.072
22.72	72.90	0.072
22.74	73.00	0.072
22.76	73.10	0.072
22.78	73.20	0.072
22.80	73.30	0.072
22.82	73.40	0.072
22.84	73.50	0.072
22.86	73.60	0.072
22.88	73.70	0.072
22.90	73.80	0.072
22.92	73.90	0.072
22.94	74.00	0.072
22.96	74.10	0.072
22.98	74.20	0.072
23.00	74.30	0.072
23.02	74.41	0.072
23.04	74.50	0.072
23.06	74.60	0.072
23.08	74.70	0.072
23.10	74.80	0.072
23.12	74.90	0.072
23.14	75.00	0.072
23.16	75.10	0.072
23.18	75.20	0.072
23.20	75.30	0.072
23.22	75.41	0.072
23.24	75.51	0.072
23.26	75.60	0.072
23.28	75.71	0.072
23.30	75.81	0.073
23.32	75.91	0.073
23.34	76.01	0.073
23.36	76.10	0.073
23.38	76.21	0.073
23.40	76.30	0.073
23.42	76.40	0.073
23.44	76.51	0.073
23.46	76.60	0.073
23.48	76.71	0.073
23.50	76.81	0.073
23.52	76.90	0.073
23.54	77.01	0.073
23.56	77.11	0.073
23.58	77.20	0.073
23.60	77.31	0.073
23.62	77.41	0.073
23.64	77.51	0.073
23.66	77.61	0.073
23.68	77.71	0.073
23.70	77.81	0.073
23.72	77.91	0.073
23.74	78.01	0.073
23.76	78.11	0.073
23.78	78.21	0.073
23.80	78.31	0.073
23.82	78.41	0.073
23.84	78.51	0.073
23.86	78.61	0.073
23.88	78.71	0.073
23.90	78.81	0.073
23.92	78.91	0.073
23.94	79.01	0.073
23.96	79.11	0.073
23.98	79.21	0.073
24.00	79.31	0.073
24.02	79.41	0.073
24.04	79.51	0.073
24.06	79.61	0.073
24.08	79.71	0.073
24.10	79.81	0.073
24.12	79.91	0.073
24.14	80.01	0.073
24.16	80.11	0.073
24.18	80.21	0.073
24.20	80.31	0.073
24.22	80.41	0.073
24.24	80.51	0.073
24.26	80.61	0.073
24.28	80.71	0.073
24.30	80.81	0.073
24.32	80.91	0.073
24.34	81.01	0.073
24.36	81.11	0.073
24.38	81.21	0.073
24.40	81.31	0.073
24.42	81.41	0.073
24.44	81.51	0.073
24.46	81.61	0.073
24.48	81.71	0.073
24.50	81.81	0.073
24.52	81.91	0.073
24.54	82.01	0.073
24.56	82.11	0.073
24.58	82.21	0.073
24.60	82.31	0.073
24.62	82.41	0.073
24.64	82.51	0.073
24.66	82.61	0.073
24.68	82.71	0.073
24.70	82.81	0.073
24.72	82.91	0.073
24.74	83.01	0.073
24.76	83.11	0.073
24.78	83.21	0.073
24.80	83.31	0.073
24.82	83.41	0.073
24.84	83.51	0.073
24.86	83.61	0.073
24.88	83.71	0.073
24.90	83.81	0.073
24.92	83.91	0.073
24.94	84.01	0.073
24.96	84.11	0.073
24.98	84.21	0.073
25.00	84.31	0.073
25.02	84.41	0.073
25.04	84.51	0.073
25.06	84.61	0.073
25.08	84.71	0.073
25.10	84.81	0.073
25.12	84.91	0.073
25.14	85.01	0.073
25.16	85.11	0.073
25.18	85.21	0.073
25.20	85.31	0.073
25.22	85.41	0.073
25.24	85.51	0.073
25.26	85.61	0.073
25.28	85.71	0.073
25.30	85.81	0.073
25.32	85.91	0.073
25.34	86.01	0.073
25.36	86.11	0.073
25.38	86.21	0.073
25.40	86.31	0.073
25.42	86.41	0.073
25.44	86.51	0.073
25.46	86.61	0.074
25.48	86.71	0.074
25.50	86.81	0.074
25.52	86.91	0.074
25.54	87.01	0.074
25.56	87.11	0.074
25.58	87.21	0.073
25.60	87.31	0.074
25.62	87.41	0.074
25.64	87.51	0.074
25.66	87.61	0.074
25.68	87.71	0.074
25.70	87.81	0.074
25.72	87.91	0.074
25.74	88.01	0.074
25.76	88.11	0.074
25.78	88.21	0.074
25.80	88.31	0.074
25.82	88.41	0.074
25.84	88.51	0.074
25.86	88.61	0.074
25.88	88.71	0.074
25.90	88.81	0.074
25.92	88.91	0.074
25.94	89.01	0.074
25.96	89.11	0.074
25.98	89.21	0.074
26.00	89.31	0.074
26.02	89.41	0.074
26.04	89.51	0.074
26.06	89.61	0.074
26.08	89.71	0.074
26.10	89.81	0.074
26.12	89.91	0.074
26.14	90.01	0.074
26.16	90.11	0.074
26.18	90.21	0.074
26.20	90.31	0.074
26.22	90.41	0.074
26.24	90.51	0.074
26.26	90.61	0.074
26.28	90.71	0.074
26.30	90.81	0.074
26.32	90.91	0.074
26.34	91.01	0.074
26.36	91.11	0.074
26.38	91.21	0.074
26.40	91.31	0.074
26.42	91.41	0.074
26.44	91.51	0.074
26.46	91.61	0.074
26.48	91.71	0.074
26.50	91.81	0.074
26.52	91.91	0.074
26.54	92.01	0.074
26.56	92.11	0.074
26.58	92.21	0.074
26.60	92.31	0.074
26.62	92.41	0.074
26.64	92.51	0.074
26.66	92.61	0.074
26.68	92.71	0.074
26.70	92.81	0.074
26.72	92.91	0.074
26.74	93.01	0.074
26.76	93.11	0.074
26.78	93.21	0.074
26.80	93.31	0.074
26.82	93.41	0.074
26.84	93.51	0.074
26.86	93.61	0.074
26.88	93.71	0.074
26.90	93.81	0.074
26.92	93.91	0.074
26.94	94.01	0.074
26.96	94.11	0.074
26.98	94.21	0.074
27.00	94.31	0.074
27.02	94.41	0.074
27.04	94.51	0.074
27.06	94.61	0.074
27.08	94.71	0.074
27.10	94.81	0.074
27.12	94.91	0.074
27.14	95.01	0.074
27.16	95.11	0.074
27.18	95.21	0.074
27.20	95.31	0.074
27.22	95.41	0.074
27.24	95.51	0.074
27.26	95.61	0.074
27.28	95.71	0.074
27.30	95.81	0.074
27.32	95.91	0.074
27.34	96.01	0.074
27.36	96.11	0.074
27.38	96.21	0.074
27.40	96.31	0.074
27.42	96.41	0.074
27.44	96.52	0.074
27.46	96.62	0.074
27.48	96.71	0.075
27.50	96.82	0.075
27.52	96.91	0.075
27.54	97.02	0.075
27.56	97.12	0.075
27.58	97.21	0.075
27.60	97.32	0.075
27.62	97.41	0.075
27.64	97.52	0.075
27.66	97.62	0.075
27.68	97.72	0.075
27.70	97.81	0.075
27.72	97.91	0.075
27.74	98.02	0.075
27.76	98.11	0.075
27.78	98.22	0.075
27.80	98.32	0.075
27.82	98.42	0.075
27.84	98.52	0.075
27.86	98.62	0.075
27.88	98.72	0.075
27.90	98.82	0.075
27.92	98.92	0.075
27.94	99.02
27.96	99.12
27.98	99.22
27.99

[step]
Ramp 5.00 °C/min to -40.00 °C
Time	Temperature	Heat Flow (Normalized)
min	°C	W/g
28.99	100.11	-0.030
29.01	100.11	-0.030
29.03	100.11	-0.030
29.05	100.10	-0.018
29.07	100.07	0.005
29.09	100.03	0.026
29.11	99.98	0.035
29.13	99.92	0.029
29.15	99.85	0.011
29.17	99.78	-0.011
29.19	99.70	-0.031
29.21	99.62	-0.045
29.23	99.54	-0.059
29.25	99.46	-0.070
29.27	99.37	-0.078
29.29	99.29	-0.087
29.31	99.20	-0.095
29.33	99.11	-0.102
29.35	99.01	-0.107
29.37	98.92	-0.112
29.39	98.83	-0.115
29.41	98.73	-0.119
29.43	98.64	-0.122
29.45	98.54	-0.124
29.47	98.45	-0.126
29.49	98.35	-0.128
29.51	98.26	-0.129
29.53	98.16	-0.131
29.55	98.06	-0.131
29.57	97.96	-0.133
29.59	97.87	-0.134
29.61	97.77	-0.135
29.63	97.67	-0.135
29.65	97.57	-0.135
29.67	97.47	-0.136
29.69	97.38	-0.136
29.71	97.28	-0.137
29.73	97.18	-0.137
29.75	97.08	-0.138
29.77	96.98	-0.138
29.79	96.88	-0.138
29.81	96.78	-0.138
29.83	96.68	-0.138
29.85	96.58	-0.139
29.87	96.48	-0.139
29.89	96.39	-0.139
29.91	96.29	-0.139
29.93	96.19	-0.139
29.95	96.09	-0.140
29.97	95.99	-0.140
29.99	95.89	-0.140
30.01	95.79	-0.140
30.03	95.69	-0.140
30.05	95.59	-0.140
30.07	95.49	-0.140
30.09	95.39	-0.140
30.11	95.29	-0.140
30.13	95.19	-0.140
30.15	95.09	-0.140
30.17	94.99	-0.140
30.19	94.89	-0.141
30.21	94.79	-0.141
30.23	94.69	-0.141
30.25	94.59	-0.141
30.27	94.49	-0.141
30.29	94.39	-0.141
30.31	94.29	-0.141
30.33	94.20	-0.140
30.35	94.09	-0.140
30.37	93.99	-0.140
30.39	93.90	-0.140
30.41	93.80	-0.140
30.43	93.70	-0.140
30.45	93.60	-0.140
30.47	93.49	-0.140
30.49	93.40	-0.140
30.51	93.30	-0.140
30.53	93.20	-0.140
30.55	93.10	-0.140
30.57	93.00	-0.140
30.59	92.90	-0.140
30.61	92.80	-0.140
30.63	92.70	-0.140
30.65	92.60	-0.140
30.67	92.50	-0.140
30.69	92.40	-0.140
30.71	92.30	-0.140
30.73	92.20	-0.140
30.75	92.10	-0.140
30.77	92.00	-0.140
30.79	91.90	-0.140
30.81	91.80	-0.140
30.83	91.70	-0.140
30.85	91.60	-0.140
30.87	91.50	-0.139
30.89	91.40	-0.139
30.91	91.30	-0.139
30.93	91.20	-0.139
30.95	91.10	-0.139
30.97	91.00	-0.139
30.99	90.90	-0.139
31.01	90.80	-0.139
31.03	90.70	-0.139
31.05	90.60	-0.139
31.07	90.50	-0.139
31.09	90.40	-0.139
31.11	90.30	-0.139
31.13	90.20	-0.139
31.15	90.10	-0.139
31.17	90.00	-0.138
31.19	89.90	-0.139
31.21	89.80	-0.138
31.23	89.70	-0.138
31.25	89.60	-0.138
31.27	89.50	-0.138
31.29	89.40	-0.138
31.31	89.30	-0.138
31.33	89.20	-0.138
31.35	89.10	-0.138
31.37	89.00	-0.138
31.39	88.90	-0.138
31.41	88.80	-0.138
31.43	88.70	-0.138
31.45	88.60	-0.138
31.47	88.50	-0.138
31.49	88.40	-0.138
31.51	88.30	-0.138
31.53	88.20	-0.137
31.55	88.10	-0.137
31.57	88.00	-0.137
31.59	87.90	-0.137
31.61	87.80	-0.137
31.63	87.70	-0.137
31.65	87.60	-0.137
31.67	87.50	-0.137
31.69	87.40	-0.137
31.71	87.30	-0.137
31.73	87.20	-0.137
31.75	87.10	-0.137
31.77	87.00	-0.137
31.79	86.90	-0.137
31.81	86.80	-0.137
31.83	86.70	-0.137
31.85	86.60	-0.137
31.87	86.50	-0.136
31.89	86.40	-0.136
31.91	86.30	-0.136
31.93	86.20	-0.136
31.95	86.10	-0.136
31.97	86.00	-0.136
31.99	85.90	-0.136
32.01	85.80	-0.136
32.03	85.70	-0.136
32.05	85.60	-0.136
32.07	85.50	-0.136
32.09	85.40	-0.136
32.11	85.30	-0.136
32.13	85.20	-0.136
32.15	85.10	-0.136
32.17	85.00	-0.136
32.19	84.90	-0.136
32.21	84.80	-0.136
32.23	84.70	-0.135
32.25	84.60	-0.135
32.27	84.50	-0.135
32.29	84.40	-0.135
32.31	84.30	-0.135
32.33	84.20	-0.135
32.35	84.10	-0.135
32.37	84.00	-0.135
32.39	83.90	-0.135
32.41	83.80	-0.135
32.43	83.70	-0.135
32.45	83.60	-0.135
32.47	83.50	-0.135
32.49	83.40	-0.135
32.51	83.30	-0.135
32.53	83.20	-0.135
32.55	83.10	-0.134
32.57	83.00	-0.134
32.59	82.90	-0.135
32.61	82.80	-0.135
32.63	82.70	-0.135
32.65	82.61	-0.134
32.67	82.50	-0.134
32.69	82.40	-0.133
32.71	82.30	-0.133
32.73	82.20	-0.134
32.75	82.10	-0.134
32.77	82.00	-0.134
32.79	81.90	-0.134
32.81	81.80	-0.134
32.83	81.71	-0.134
32.85	81.60	-0.133
32.87	81.50	-0.133
32.89	81.40	-0.133
32.91	81.30	-0.133
32.93	81.20	-0.133
32.95	81.10	-0.133
32.97	81.00	-0.133
32.99	80.90	-0.133
33.01	80.80	-0.133
33.03	80.71	-0.133
33.05	80.60	-0.133
33.07	80.50	-0.133
33.09	80.40	-0.133
33.11	80.30	-0.133
33.13	80.20	-0.133
33.15	80.11	-0.133
33.17	80.00	-0.133
33.19	79.90	-0.133
33.21	79.81	-0.133
33.23	79.71	-0.133
33.25	79.61	-0.133
33.27	79.51	-0.133
33.29	79.41	-0.133
33.31	79.31	-0.133
33.33	79.21	-0.133
33.35	79.11	-0.133
33.37	79.01	-0.133
33.39	78.91	-0.133
33.41	78.81	-0.133
33.43	78.71	-0.133
33.45	78.61	-0.133
33.47	78.51	-0.133
33.49	78.41	-0.133
33.51	78.31	-0.133
33.53	78.21	-0.133
33.55	78.11	-0.132
33.57	78.01	-0.132
33.59	77.91	-0.132
33.61	77.81	-0.132
33.63	77.71	-0.132
33.65	77.61	-0.132
33.67	77.51	-0.132
33.69	77.40	-0.132
33.71	77.30	-0.132
33.73	77.20	-0.132
33.75	77.11	-0.132
33.77	77.01	-0.132
33.79	76.91	-0.132
33.81	76.81	-0.132
33.83	76.71	-0.132
33.85	76.61	-0.132
33.87	76.51	-0.131
33.89	76.41	-0.131
33.91	76.31	-0.132
33.93	76.21	-0.131
33.95	76.11	-0.131
33.97	76.01	-0.131
33.99	75.91	-0.131
34.01	75.81	-0.131
34.03	75.71	-0.131
34.05	75.61	-0.131
34.07	75.51	-0.131
34.09	75.41	-0.131
34.11	75.31	-0.131
34.13	75.21	-0.131
34.15	75.11	-0.131
34.17	75.01	-0.131
34.19	74.91	-0.131
34.21	74.81	-0.130
34.23	74.71	-0.131
34.25	74.61	-0.131
34.27	74.51	-0.130
34.29	74.41	-0.130
34.31	74.31	-0.130
34.33	74.21	-0.131
34.35	74.11	-0.131
34.37	74.01	-0.130
34.39	73.91	-0.130
34.41	73.81	-0.130
34.43	73.71	-0.130
34.45	73.61	-0.130
34.47	73.51	-0.130
34.49	73.41	-0.130
34.51	73.31	-0.130
34.53	73.21	-0.130
34.55	73.11	-0.130
34.57	73.01	-0.130
34.59	72.91	-0.130
34.61	72.81	-0.130
34.63	72.71	-0.130
34.65	72.61	-0.129
34.67	72.51	-0.129
34.69	72.41	-0.129
34.71	72.31	-0.129
34.73	72.21	-0.129
34.75	72.11	-0.129
34.77	72.01	-0.129
34.79	71.91	-0.129
34.81	71.81	-0.129
34.83	71.71	-0.129
34.85	71.61	-0.129
34.87	71.51	-0.129
34.89	71.41	-0.129
34.91	71.31	-0.129
34.93	71.21	-0.129
34.95	71.11	-0.129
34.97	71.01	-0.129
34.99	70.91	-0.129
35.01	70.81	-0.129
35.03	70.71	-0.129
35.05	70.61	-0.129
35.07	70.51	-0.128
35.09	70.41	-0.128
35.11	70.31	-0.128
35.13	70.21	-0.128
35.15	70.11	-0.128
35.17	70.01	-0.128
35.19	69.91	-0.128
35.21	69.81	-0.128
35.23	69.71	-0.128
35.25	69.61	-0.128
35.27	69.51	-0.128
35.29	69.41	-0.128
35.31	69.31	-0.128
35.33	69.21	-0.128
35.35	69.11	-0.128
35.37	69.01	-0.128
35.39	68.91	-0.128
35.41	68.81	-0.128
35.43	68.71	-0.128
35.45	68.61	-0.128
35.47	68.51	-0.128
35.49	68.41	-0.127
35.51	68.31	-0.127
35.53	68.21	-0.127
35.55	68.11	-0.127
35.57	68.01	-0.127
35.59	67.91	-0.127
35.61	67.81	-0.127
35.63	67.71	-0.127
35.65	67.61	-0.127
35.67	67.51	-0.127
35.69	67.41	-0.127
35.71	67.31	-0.127
35.73	67.21	-0.127
35.75	67.11	-0.127
35.77	67.01	-0.127
35.79	66.91	-0.126
35.81	66.81	-0.126
35.83	66.71	-0.126
35.85	66.61	-0.126
35.87	66.51	-0.126
35.89	66.41	-0.126
35.91	66.31	-0.126
35.93	66.21	-0.126
35.95	66.11	-0.126
35.97	66.01	-0.126
35.99	65.91	-0.126
36.01	65.81	-0.126
36.03	65.71	-0.126
36.05	65.61	-0.126
36.07	65.51	-0.126
36.09	65.41	-0.125
36.11	65.31	-0.126
36.13	65.21	-0.126
36.15	65.11	-0.126
36.17	65.01	-0.125
36.19	64.91	-0.125
36.21	64.81	-0.125
36.23	64.71	-0.125
36.25	64.61	-0.125
36.27	64.51	-0.125
36.29	64.41	-0.125
36.31	64.31	-0.125
36.33	64.21	-0.125
36.35	64.11	-0.125
36.37	64.01	-0.125
36.39	63.91	-0.125
36.41	63.81	-0.125
36.43	63.71	-0.125
36.45	63.61	-0.125
36.47	63.51	-0.125
36.49	63.41	-0.125
36.51	63.31	-0.125
36.53	63.21	-0.125
36.55	63.11	-0.125
36.57	63.01	-0.125
36.59	62.91	-0.125
36.61	62.81	-0.125
36.63	62.71	-0.125
36.65	62.61	-0.125
36.67	62.51	-0.125
36.69	62.41	-0.124
36.71	62.31	-0.124
36.73	62.21	-0.124
36.75	62.11	-0.124
36.77	62.01	-0.124
36.79	61.91	-0.124
36.81	61.81	-0.124
36.83	61.71	-0.124
36.85	61.61	-0.124
36.87	61.51	-0.124
36.89	61.41	-0.124
36.91	61.31	-0.124
36.93	61.21	-0.124
36.95	61.11	-0.124
36.97	61.01	-0.124
36.99	60.91	-0.124
37.01	60.81	-0.124
37.03	60.71	-0.124
37.05	60.61	-0.123
37.07	60.51	-0.123
37.09	60.41	-0.123
37.11	60.31	-0.123
37.13	60.21	-0.123
37.15	60.11	-0.123
37.17	60.01	-0.123
37.19	59.91	-0.123
37.21	59.81	-0.123
37.23	59.71	-0.123
37.25	59.61	-0.123
37.27	59.51	-0.123
37.29	59.41	-0.123
37.31	59.31	-0.123
37.33	59.21	-0.123
37.35	59.11	-0.123
37.37	59.01	-0.122
37.39	58.91	-0.122
37.41	58.81	-0.122
37.43	58.71	-0.122
37.45	58.61	-0.122
37.47	58.51	-0.122
37.49	58.41	-0.122
37.51	58.31	-0.122
37.53	58.21	-0.122
37.55	58.11	-0.122
37.57	58.01	-0.122
37.59	57.91	-0.122
37.61	57.81	-0.122
37.63	57.71	-0.122
37.65	57.61	-0.122
37.67	57.51	-0.122
37.69	57.41	-0.122
37.71	57.31	-0.122
37.73	57.21	-0.122
37.75	57.11	-0.122
37.77	57.01	-0.122
37.79	56.91	-0.121
37.81	56.81	-0.121
37.83	56.72	-0.121
37.85	56.61	-0.121
37.87	56.52	-0.121
37.89	56.41	-0.121
37.91	56.31	-0.121
37.93	56.21	-0.121
37.95	56.11	-0.121
37.97	56.01	-0.121
37.99	55.91	-0.121
38.01	55.81	-0.121
38.03	55.71	-0.121
38.05	55.62	-0.121
38.07	55.51	-0.121
38.09	55.41	-0.121
38.11	55.31	-0.121
38.13	55.21	-0.121
38.15	55.12	-0.121
38.17	55.02	-0.121
38.19	54.92	-0.121
38.21	54.82	-0.120
38.23	54.72	-0.120
[...]
122.83	-6.62	0.072
122.85	-6.53	0.072
122.87	-6.43	0.072
122.89	-6.33	0.072
122.91	-6.23	0.072
122.93	-6.13	0.072
122.95	-6.02	0.072
122.97	-5.93	0.072
122.99	-5.82	0.072
123.01	-5.73	0.072
123.03	-5.63	0.072
123.05	-5.52	0.072
123.07	-5.42	0.072
123.09	-5.32	0.072
123.11	-5.22	0.072
123.13	-5.12	0.072
123.15	-5.02	0.072
123.17	-4.92	0.072
123.19	-4.82	0.072
123.21	-4.72	0.072
123.23	-4.62	0.072
123.25	-4.52	0.072
123.27	-4.42	0.072
123.29	-4.32	0.072
123.31	-4.22	0.072
123.33	-4.12	0.072
123.35	-4.02	0.072
123.37	-3.92	0.072
123.39	-3.82	0.072
123.41	-3.72	0.072
123.43	-3.62	0.072
123.45	-3.52	0.072
123.47	-3.42	0.072
123.49	-3.32	0.072
123.51	-3.22	0.072
123.53	-3.12	0.072
123.55	-3.02	0.072
123.57	-2.92	0.072
123.59	-2.82	0.072
123.61	-2.72	0.072
123.63	-2.62	0.072
123.65	-2.52	0.072
123.67	-2.42	0.072
123.69	-2.32	0.072
123.71	-2.22	0.072
123.73	-2.12	0.072
123.75	-2.02	0.072
123.77	-1.92	0.072
123.79	-1.82	0.072
123.81	-1.72	0.072
123.83	-1.62	0.072
123.85	-1.52	0.072
123.87	-1.42	0.072
123.89	-1.32	0.072
123.91	-1.22	0.072
123.93	-1.12	0.072
123.95	-1.02	0.072
123.97	-0.92	0.072
123.99	-0.82	0.072
124.01	-0.72	0.072
124.03	-0.62	0.072
124.05	-0.52	0.072
124.07	-0.42	0.072
124.09	-0.32	0.072
124.11	-0.22	0.072
124.13	-0.12	0.072
124.15	-0.02	0.072
124.17	0.08	0.072
124.19	0.18	0.072
124.21	0.28	0.072
124.23	0.38	0.072
124.25	0.48	0.072
124.27	0.58	0.072
124.29	0.68	0.072
124.31	0.78	0.072
124.33	0.88	0.072
124.35	0.98	0.072
124.37	1.08	0.072
124.39	1.18	0.072
124.41	1.28	0.072
124.43	1.38	0.072
124.45	1.48	0.072
124.47	1.58	0.072
124.49	1.68	0.072
124.51	1.78	0.072
124.53	1.88	0.072
124.55	1.98	0.072
124.57	2.08	0.072
124.59	2.18	0.072
124.61	2.28	0.072
124.63	2.38	0.072
124.65	2.48	0.072
124.67	2.58	0.072
124.69	2.68	0.072
124.71	2.78	0.072
124.73	2.88	0.072
124.75	2.98	0.072
124.77	3.08	0.072
124.79	3.18	0.072
124.81	3.28	0.072
124.83	3.38	0.072
124.85	3.48	0.072
124.87	3.58	0.072
124.89	3.68	0.072
124.91	3.78	0.072
124.93	3.88	0.072
124.95	3.98	0.072
124.97	4.08	0.072
124.99	4.18	0.072
125.01	4.28	0.072
125.03	4.38	0.072
125.05	4.48	0.072
125.07	4.58	0.072
125.09	4.68	0.072
125.11	4.78	0.072
125.13	4.88	0.072
125.15	4.98	0.072
125.17	5.08	0.072
125.19	5.18	0.072
125.21	5.28	0.072
125.23	5.38	0.072
125.25	5.48	0.072
125.27	5.58	0.072
125.29	5.68	0.072
125.31	5.78	0.072
125.33	5.88	0.072
125.35	5.99	0.072
125.37	6.08	0.072
125.39	6.18	0.072
125.41	6.28	0.072
125.43	6.38	0.072
125.45	6.48	0.072
125.47	6.59	0.072
125.49	6.68	0.072
125.51	6.79	0.072
125.53	6.88	0.072
125.55	6.99	0.072
125.57	7.08	0.072
125.59	7.19	0.072
125.61	7.28	0.072
125.63	7.38	0.072
125.65	7.48	0.072
125.67	7.58	0.072
125.69	7.69	0.072
125.71	7.79	0.072
125.73	7.89	0.072
125.75	7.99	0.072
125.77	8.09	0.072
125.79	8.19	0.072
125.81	8.29	0.072
125.83	8.38	0.072
125.85	8.49	0.072
125.87	8.58	0.072
125.89	8.68	0.072
125.91	8.79	0.072
125.93	8.89	0.072
125.95	8.99	0.072
125.97	9.09	0.072
125.99	9.18	0.072
126.01	9.29	0.072
126.03	9.39	0.072
126.05	9.49	0.072
126.07	9.59	0.072
126.09	9.69	0.072
126.11	9.79	0.072
126.13	9.89	0.072
126.15	9.99	0.072
126.17	10.09	0.072
126.19	10.19	0.072
126.21	10.29	0.072
126.23	10.39	0.072
126.25	10.49	0.072
126.27	10.59	0.072
126.29	10.69	0.072
126.31	10.79	0.072
126.33	10.89	0.072
126.35	10.99	0.072
126.37	11.09	0.072
126.39	11.19	0.072
126.41	11.29	0.072
126.43	11.39	0.072
126.45	11.49	0.072
126.47	11.59	0.072
126.49	11.69	0.072
126.51	11.79	0.072
126.53	11.89	0.072
126.55	11.99	0.072
126.57	12.09	0.072
126.59	12.19	0.072
126.61	12.29	0.072
126.63	12.39	0.072
126.65	12.49	0.072
126.67	12.59	0.072
126.69	12.69	0.072
126.71	12.79	0.072
126.73	12.89	0.072
126.75	12.99	0.072
126.77	13.09	0.072
126.79	13.19	0.072
126.81	13.29	0.072
126.83	13.39	0.072
126.85	13.49	0.072
126.87	13.59	0.073
126.89	13.69	0.073
126.91	13.79	0.073
126.93	13.89	0.073
126.95	13.99	0.073
126.97	14.09	0.073
126.99	14.19	0.073
127.01	14.29	0.073
127.03	14.39	0.073
127.05	14.49	0.073
127.07	14.59	0.073
127.09	14.69	0.073
127.11	14.79	0.073
127.13	14.89	0.073
127.15	14.99	0.073
127.17	15.09	0.073
127.19	15.19	0.073
127.21	15.29	0.073
127.23	15.39	0.073
127.25	15.49	0.073
127.27	15.59	0.073
127.29	15.69	0.073
127.31	15.79	0.073
127.33	15.89	0.073
127.35	15.99	0.073
127.37	16.09	0.073
127.39	16.19	0.073
127.41	16.29	0.073
127.43	16.39	0.073
127.45	16.49	0.073
127.47	16.59	0.073
127.49	16.69	0.073
127.51	16.79	0.073
127.53	16.89	0.073
127.55	16.99	0.073
127.57	17.09	0.073
127.59	17.19	0.073
127.61	17.29	0.073
127.63	17.39	0.073
127.65	17.49	0.073
127.67	17.59	0.073
127.69	17.69	0.073
127.71	17.79	0.073
127.73	17.89	0.073
127.75	17.99	0.073
127.77	18.09	0.073
127.79	18.19	0.073
127.81	18.29	0.073
127.83	18.39	0.073
127.85	18.49	0.073
127.87	18.59	0.073
127.89	18.69	0.073
127.91	18.79	0.073
127.93	18.89	0.073
127.95	18.99	0.073
127.97	19.09	0.073
127.99	19.19	0.073
128.01	19.29	0.073
128.03	19.39	0.073
128.05	19.49	0.073
128.07	19.59	0.073
128.09	19.69	0.073
128.11	19.79	0.073
128.13	19.89	0.073
128.15	19.99	0.073
128.17	20.10	0.073
128.19	20.20	0.073
128.21	20.30	0.073
128.23	20.39	0.073
128.25	20.50	0.073
128.27	20.60	0.073
128.29	20.70	0.073
128.31	20.80	0.073
128.33	20.89	0.073
128.35	21.00	0.073
128.37	21.09	0.073
128.39	21.20	0.073
128.41	21.30	0.073
128.43	21.40	0.073
128.45	21.50	0.073
128.47	21.60	0.073
128.49	21.70	0.073
128.51	21.80	0.073
128.53	21.89	0.073
128.55	22.00	0.073
128.57	22.10	0.073
128.59	22.20	0.073
128.61	22.30	0.073
128.63	22.40	0.073
128.65	22.50	0.073
128.67	22.60	0.073
128.69	22.70	0.073
128.71	22.80	0.073
128.73	22.90	0.073
128.75	23.00	0.073
128.77	23.10	0.073
128.79	23.20	0.073
128.81	23.30	0.073
128.83	23.40	0.073
128.85	23.50	0.073
128.87	23.60	0.073
128.89	23.70	0.073
128.91	23.80	0.073
128.93	23.90	0.073
128.95	24.00	0.073
128.97	24.10	0.074
128.99	24.20	0.073
129.01	24.30	0.073
129.03	24.40	0.073
129.05	24.50	0.073
129.07	24.60	0.073
129.09	24.70	0.073
129.11	24.80	0.073
129.13	24.90	0.073
129.15	25.00	0.074
129.17	25.10	0.074
129.19	25.20	0.074
129.21	25.30	0.074
129.23	25.40	0.074
129.25	25.50	0.074
129.27	25.60	0.074
129.29	25.70	0.074
129.31	25.80	0.074
129.33	25.90	0.074
129.35	26.00	0.074
129.37	26.10	0.074
129.39	26.20	0.074
129.41	26.30	0.074
129.43	26.40	0.074
129.45	26.50	0.074
129.47	26.60	0.074
129.49	26.70	0.074
129.51	26.80	0.074
129.53	26.90	0.074
129.55	27.00	0.074
129.57	27.10	0.074
129.59	27.20	0.074
129.61	27.30	0.074
129.63	27.40	0.074
129.65	27.50	0.074
129.67	27.60	0.074
129.69	27.70	0.074
129.71	27.80	0.074
129.73	27.90	0.074
129.75	28.00	0.074
129.77	28.10	0.074
129.79	28.20	0.074
129.81	28.30	0.074
129.83	28.40	0.074
129.85	28.50	0.074
129.87	28.60	0.074
129.89	28.70	0.074
129.91	28.80	0.074
129.93	28.90	0.074
129.95	29.00	0.074
129.97	29.10	0.074
129.99	29.20	0.074
130.01	29.30	0.074
130.03	29.40	0.074
130.05	29.50	0.074
130.07	29.60	0.074
130.09	29.70	0.074
130.11	29.80	0.074
130.13	29.90	0.074
130.15	30.00	0.074
130.17	30.10	0.074
130.19	30.20	0.074
130.21	30.30	0.074
130.23	30.40	0.074
130.25	30.50	0.074
130.27	30.60	0.074
130.29	30.70	0.074
130.31	30.80	0.074
130.33	30.90	0.074
130.35	31.00	0.074
130.37	31.10	0.075
130.39	31.20	0.075
130.41	31.30	0.075
130.43	31.40	0.075
130.45	31.50	0.075
130.47	31.60	0.075
130.49	31.70	0.075
130.51	31.80	0.075
130.53	31.90	0.075
130.55	32.00	0.075
130.57	32.10	0.075
130.59	32.20	0.075
130.61	32.30	0.075
130.63	32.40	0.075
130.65	32.50	0.075
130.67	32.60	0.075
130.69	32.70	0.075
130.71	32.80	0.075
130.73	32.90	0.075
130.75	33.00	0.075
130.77	33.10	0.075
130.79	33.20	0.075
130.81	33.30	0.075
130.83	33.40	0.075
130.85	33.50	0.075
130.87	33.60	0.075
130.89	33.70	0.075
130.91	33.80	0.075
130.93	33.90	0.075
130.95	34.01	0.075
130.97	34.10	0.075
130.99	34.20	0.075
131.01	34.30	0.075
131.03	34.41	0.075
131.05	34.50	0.075
131.07	34.61	0.075
131.09	34.71	0.075
131.11	34.80	0.075
131.13	34.91	0.075
131.15	35.01	0.075
131.17	35.11	0.075
131.19	35.21	0.075
131.21	35.31	0.075
131.23	35.41	0.075
131.25	35.51	0.075
131.27	35.61	0.075
131.29	35.71	0.075
131.31	35.81	0.075
131.33	35.91	0.075
131.35	36.01	0.075
131.37	36.11	0.075
131.39	36.21	0.075
131.41	36.31	0.075
131.43	36.41	0.075
131.45	36.51	0.075
131.47	36.61	0.075
131.49	36.71	0.075
131.51	36.81	0.075
131.53	36.91	0.075
131.55	37.01	0.075
131.57	37.11	0.075
131.59	37.21	0.075
131.61	37.31	0.075
131.63	37.41	0.075
131.65	37.51	0.075
131.67	37.61	0.075
131.69	37.71	0.075
131.71	37.81	0.075
131.73	37.91	0.075
131.75	38.01	0.075
131.77	38.11	0.075
131.79	38.21	0.075
131.81	38.31	0.075
131.83	38.41	0.075
131.85	38.51	0.076
131.87	38.61	0.076
131.89	38.71	0.076
131.91	38.81	0.076
131.93	38.91	0.075
131.95	39.01	0.075
131.97	39.11	0.075
131.99	39.21	0.076
132.01	39.31	0.076
132.03	39.41	0.075
132.05	39.51	0.075
132.07	39.61	0.075
132.09	39.71	0.075
132.11	39.81	0.075
132.13	39.91	0.076
132.15	40.01	0.075
132.17	40.11	0.076
132.19	40.21	0.076
132.21	40.31	0.076
132.23	40.41	0.076
132.25	40.51	0.076
132.27	40.61	0.076
132.29	40.71	0.076
132.31	40.81	0.076
132.33	40.91	0.076
132.35	41.01	0.076
132.37	41.11	0.076
132.39	41.21	0.076
132.41	41.31	0.076
132.43	41.41	0.076
132.45	41.51	0.076
132.47	41.61	0.076
132.49	41.71	0.076
132.51	41.81	0.076
132.53	41.91	0.076
132.55	42.01	0.076
132.57	42.11	0.076
132.59	42.21	0.076
132.61	42.31	0.076
132.63	42.41	0.076
132.65	42.51	0.076
132.67	42.61	0.076
132.69	42.71	0.076
132.71	42.81	0.076
132.73	42.91	0.076
132.75	43.01	0.076
132.77	43.11	0.076
132.79	43.21	0.076
132.81	43.31	0.076
132.83	43.41	0.076
132.85	43.51	0.076
132.87	43.61	0.076
132.89	43.71	0.076
132.91	43.81	0.076
132.93	43.91	0.076
132.95	44.01	0.076
132.97	44.11	0.076
132.99	44.21	0.076
133.01	44.31	0.076
133.03	44.41	0.076
133.05	44.51	0.076
133.07	44.61	0.076
133.09	44.71	0.076
133.11	44.81	0.076
133.13	44.91	0.076
133.15	45.01	0.076
133.17	45.11	0.076
133.19	45.21	0.076
133.21	45.31	0.076
133.23	45.41	0.076
133.25	45.51	0.076
133.27	45.61	0.076
133.29	45.71	0.076
133.31	45.81	0.076
133.33	45.91	0.076
133.35	46.01	0.076
133.37	46.11	0.076
133.39	46.21	0.076
133.41	46.31	0.076
133.43	46.41	0.076
133.45	46.51	0.076
133.47	46.61	0.076
133.49	46.71	0.076
133.51	46.81	0.076
133.53	46.91	0.076
133.55	47.01	0.076
133.57	47.11	0.076
133.59	47.21	0.076
133.61	47.31	0.076
133.63	47.41	0.076
133.65	47.51	0.076
133.67	47.61	0.076
133.69	47.71	0.076
133.71	47.81	0.076
133.73	47.91	0.076
133.75	48.01	0.076
133.77	48.11	0.076
133.79	48.21	0.076
133.81	48.31	0.076
133.83	48.41	0.077
133.85	48.52	0.077
133.87	48.61	0.077
133.89	48.71	0.077
133.91	48.81	0.077
133.93	48.91	0.077
133.95	49.01	0.077
133.97	49.11	0.077
133.99	49.21	0.077
134.01	49.31	0.077
134.03	49.41	0.077
134.05	49.51	0.077
134.07	49.61	0.077
134.09	49.71	0.077
134.11	49.81	0.077
134.13	49.91	0.077
134.15	50.01	0.077
134.17	50.12	0.077
134.19	50.21	0.077
134.21	50.31	0.077
134.23	50.41	0.077
134.25	50.52	0.077
134.27	50.62	0.077
134.29	50.72	0.077
134.31	50.82	0.077
134.33	50.92	0.077
134.35	51.02	0.077
134.37	51.12	0.077
134.39	51.22	0.077
134.41	51.32	0.077
134.43	51.42	0.077
134.45	51.52	0.077
134.47	51.62	0.077
134.49	51.72	0.077
134.51	51.82	0.077
134.53	51.92	0.077
134.55	52.02	0.077
134.57	52.12	0.077
134.59	52.22	0.077
134.61	52.32	0.077
134.63	52.42	0.077
134.65	52.52	0.077
134.67	52.62	0.077
134.69	52.72	0.077
134.71	52.82	0.077
134.73	52.92	0.077
134.75	53.02	0.077
134.77	53.12	0.077
134.79	53.22	0.077
134.81	53.32	0.077
134.83	53.42	0.077
134.85	53.52	0.077
134.87	53.62	0.077
134.89	53.72	0.077
134.91	53.82	0.077
134.93	53.92	0.077
134.95	54.02	0.077
134.97	54.12	0.077
134.99	54.22	0.077
135.01	54.32	0.077
135.03	54.42	0.077
135.05	54.52	0.077
135.07	54.62	0.077
135.09	54.72	0.077
135.11	54.82	0.077
135.13	54.92	0.077
135.15	55.02	0.077
135.17	55.12	0.077
135.19	55.22	0.077
135.21	55.32	0.077
135.23	55.42	0.077
135.25	55.52	0.077
135.27	55.62	0.077
135.29	55.72	0.077
135.31	55.82	0.077
135.33	55.92	0.077
135.35	56.02	0.077
135.37	56.12	0.077
135.39	56.22	0.077
135.41	56.32	0.077
135.43	56.42	0.077
135.45	56.52	0.077
135.47	56.62	0.077
135.49	56.72	0.077
135.51	56.82	0.077
135.53	56.92	0.078
135.55	57.02	0.078
135.57	57.12	0.078
135.59	57.22	0.078
135.61	57.32	0.078
135.63	57.42	0.078
135.65	57.52	0.078
135.67	57.62	0.078
135.69	57.72	0.078
135.71	57.82	0.078
135.73	57.92	0.078
135.75	58.02	0.078
135.77	58.12	0.078
135.79	58.22	0.078
135.81	58.32	0.078
135.83	58.42	0.078
135.85	58.52	0.078
135.87	58.62	0.078
135.89	58.72	0.078
135.91	58.82	0.078
135.93	58.92	0.078
135.95	59.02	0.078
135.97	59.12	0.078
135.99	59.22	0.078
136.01	59.32	0.078
136.03	59.42	0.078
136.05	59.52	0.078
136.07	59.62	0.078
136.09	59.72	0.078
136.11	59.82	0.078
136.13	59.92	0.078
136.15	60.02	0.078
136.17	60.12	0.078
136.19	60.22	0.078
136.21	60.32	0.078
136.23	60.42	0.078
136.25	60.52	0.078
136.27	60.62	0.078
136.29	60.72	0.078
136.31	60.82	0.078
136.33	60.92	0.078
136.35	61.02	0.078
136.37	61.12	0.078
136.39	61.22	0.078
136.41	61.32	0.078
136.43	61.42	0.078
136.45	61.52	0.078
136.47	61.62	0.078
136.49	61.72	0.078
136.51	61.82	0.078
136.53	61.92	0.078
136.55	62.02	0.078
136.57	62.12	0.078
136.59	62.22	0.078
136.61	62.32	0.078
136.63	62.42	0.078
136.65	62.52	0.078
136.67	62.62	0.078
136.69	62.72	0.078
136.71	62.82	0.078
136.73	62.92	0.078
136.75	63.02	0.078
136.77	63.12	0.078
136.79	63.22	0.078
136.81	63.32	0.078
136.83	63.42	0.078
136.85	63.52	0.078
136.87	63.62	0.078
136.89	63.73	0.078
136.91	63.82	0.078
136.93	63.92	0.078
136.95	64.02	0.078
136.97	64.12	0.078
136.99	64.23	0.078
137.01	64.33	0.078
137.03	64.43	0.078
137.05	64.52	0.078
137.07	64.62	0.078
137.09	64.72	0.078
137.11	64.82	0.078
137.13	64.92	0.078
137.15	65.02	0.078
137.17	65.13	0.078
137.19	65.23	0.078
137.21	65.32	0.078
137.23	65.42	0.078
137.25	65.53	0.078
137.27	65.63	0.078
137.29	65.73	0.078
137.31	65.83	0.078
137.33	65.93	0.078
137.35	66.03	0.078
137.37	66.13	0.078
137.39	66.23	0.078
137.41	66.33	0.078
137.43	66.43	0.078
137.45	66.53	0.078
137.47	66.63	0.078
137.49	66.73	0.078
137.51	66.83	0.078
137.53	66.93	0.078
137.55	67.03	0.078
137.57	67.13	0.078
137.59	67.23	0.078
137.61	67.33	0.079
137.63	67.43	0.078
137.65	67.53	0.079
137.67	67.63	0.079
137.69	67.73	0.079
137.71	67.83	0.079
137.73	67.93	0.079
137.75	68.03	0.079
137.77	68.13	0.079
137.79	68.23	0.079
137.81	68.33	0.079
137.83	68.43	0.079
137.85	68.53	0.079
137.87	68.63	0.079
137.89	68.73	0.079
137.91	68.83	0.079
137.93	68.93	0.079
137.95	69.03	0.079
137.97	69.13	0.079
137.99	69.23	0.079
138.01	69.33	0.079
138.03	69.43	0.079
138.05	69.53	0.079
138.07	69.63	0.079
138.09	69.73	0.079
138.11	69.83	0.079
138.13	69.93	0.079
138.15	70.03	0.079
138.17	70.13	0.079
138.19	70.23	0.079
138.21	70.33	0.079
138.23	70.43	0.079
138.25	70.53	0.079
138.27	70.63	0.079
138.29	70.73	0.079
138.31	70.83	0.079
138.33	70.93	0.079
138.35	71.03	0.079
138.37	71.13	0.079
138.39	71.23	0.079
138.41	71.33	0.079
138.43	71.43	0.079
138.45	71.53	0.079
138.47	71.63	0.079
138.49	71.73	0.079
138.51	71.83	0.079
138.53	71.93	0.079
138.55	72.03	0.079
138.57	72.13	0.079
138.59	72.23	0.079
138.61	72.33	0.079
138.63	72.43	0.079
138.65	72.53	0.079
138.67	72.63	0.079
138.69	72.73	0.079
138.71	72.83	0.079
138.73	72.93	0.079
138.75	73.03	0.079
138.77	73.13	0.079
138.79	73.23	0.079
138.81	73.33	0.079
138.83	73.43	0.079
138.85	73.53	0.079
138.87	73.63	0.079
138.89	73.73	0.079
138.91	73.83	0.079
138.93	73.93	0.079
138.95	74.03	0.079
138.97	74.13	0.079
138.99	74.23	0.079
139.01	74.33	0.079
139.03	74.43	0.079
139.05	74.53	0.079
139.07	74.63	0.079
139.09	74.73	0.079
139.11	74.83	0.079
139.13	74.93	0.079
139.15	75.03	0.079
139.17	75.13	0.079
139.19	75.23	0.079
139.21	75.33	0.079
139.23	75.43	0.079
139.25	75.53	0.079
139.27	75.63	0.079
139.29	75.73	0.079
139.31	75.83	0.079
139.33	75.93	0.079
139.35	76.03	0.079
139.37	76.13	0.079
139.39	76.23	0.079
139.41	76.33	0.079
139.43	76.43	0.079
139.45	76.53	0.079
139.47	76.63	0.079
139.49	76.73	0.079
139.51	76.83	0.079
139.53	76.93	0.079
139.55	77.03	0.079
139.57	77.13	0.079
139.59	77.23	0.079
139.61	77.33	0.079
139.63	77.43	0.079
139.65	77.53	0.079
139.67	77.63	0.079
139.69	77.73	0.079
139.71	77.83	0.079
139.73	77.93	0.079
139.75	78.03	0.079
139.77	78.13	0.079
139.79	78.23	0.079
139.81	78.33	0.080
139.83	78.43	0.080
139.85	78.53	0.080
139.87	78.63	0.080
139.89	78.73	0.080
139.91	78.83	0.080
139.93	78.93	0.080
139.95	79.03	0.080
139.97	79.13	0.080
139.99	79.23	0.080
140.01	79.33	0.080
140.03	79.43	0.080
140.05	79.53	0.080
140.07	79.63	0.080
140.09	79.73	0.080
140.11	79.83	0.080
140.13	79.93	0.080
140.15	80.03	0.080
140.17	80.13	0.080
140.19	80.23	0.080
140.21	80.33	0.080
140.23	80.43	0.080
140.25	80.53	0.080
140.27	80.63	0.080
140.29	80.73	0.080
140.31	80.83	0.080
140.33	80.93	0.080
140.35	81.03	0.080
140.37	81.13	0.080
140.39	81.23	0.080
140.41	81.33	0.080
140.43	81.43	0.080
140.45	81.53	0.080
140.47	81.63	0.080
140.49	81.73	0.080
140.51	81.83	0.080
140.53	81.93	0.080
140.55	82.03	0.080
140.57	82.13	0.080
140.59	82.23	0.080
140.61	82.33	0.080
140.63	82.43	0.080
140.65	82.53	0.080
140.67	82.63	0.080
140.69	82.73	0.080
140.71	82.83	0.080
140.73	82.93	0.080
140.75	83.03	0.080
140.77	83.14	0.080
140.79	83.24	0.080
140.81	83.33	0.080
140.83	83.44	0.080
140.85	83.53	0.080
140.87	83.63	0.080
140.89	83.74	0.080
140.91	83.83	0.080
140.93	83.94	0.080
140.95	84.03	0.080
140.97	84.14	0.080
140.99	84.24	0.080
141.01	84.33	0.080
141.03	84.44	0.080
141.05	84.54	0.080
141.07	84.64	0.080
141.09	84.74	0.080
141.11	84.84	0.080
141.13	84.93	0.080
141.15	85.04	0.080
141.17	85.13	0.080
141.19	85.23	0.080
141.21	85.34	0.080
141.23	85.44	0.080
141.25	85.53	0.080
141.27	85.63	0.080
141.29	85.73	0.080
141.31	85.84	0.080
141.33	85.94	0.080
141.35	86.04	0.080
141.37	86.14	0.080
141.39	86.24	0.080
141.41	86.34	0.080
141.43	86.44	0.080
141.45	86.54	0.080
141.47	86.64	0.080
141.49	86.74	0.080
141.51	86.84	0.080
141.53	86.94	0.080
141.55	87.04	0.080
141.57	87.14	0.080
141.59	87.24	0.080
141.61	87.34	0.080
141.63	87.44	0.080
141.65	87.54	0.080
141.67	87.64	0.080
141.69	87.74	0.080
141.71	87.84	0.080
141.73	87.94	0.080
141.75	88.04	0.080
141.77	88.14	0.080
141.79	88.24	0.080
141.81	88.34	0.080
141.83	88.44	0.080
141.85	88.54	0.080
141.87	88.64	0.080
141.89	88.74	0.080
141.91	88.84	0.080
141.93	88.94	0.080
141.95	89.04	0.080
141.97	89.14	0.080
141.99	89.24	0.080
142.01	89.34	0.080
142.03	89.44	0.080
142.05	89.54	0.080
142.07	89.64	0.080
142.09	89.74	0.080
142.11	89.84	0.080
142.13	89.94	0.080
142.15	90.04	0.080
142.17	90.14	0.080
142.19	90.24	0.080
142.21	90.34	0.080
142.23	90.44	0.080
142.25	90.54	0.080
142.27	90.64	0.080
142.29	90.74	0.080
142.31	90.84	0.080
142.33	90.94	0.080
142.35	91.04	0.080
142.37	91.14	0.080
142.39	91.24	0.080
142.41	91.34	0.080
142.43	91.44	0.080
142.45	91.54	0.080
142.47	91.64	0.080
142.49	91.74	0.080
142.51	91.84	0.080
142.53	91.94	0.080
142.55	92.04	0.080
142.57	92.14	0.080
142.59	92.24	0.080
142.61	92.34	0.080
142.63	92.44	0.080
142.65	92.54	0.080
142.67	92.64	0.080
142.69	92.74	0.080
142.71	92.84	0.080
142.73	92.94	0.080
142.75	93.04	0.080
142.77	93.14	0.080
142.79	93.24	0.080
142.81	93.34	0.080
142.83	93.44	0.080
142.85	93.54	0.080
142.87	93.64	0.080
142.89	93.74	0.080
142.91	93.84	0.080
142.93	93.94	0.080
142.95	94.04	0.080
142.97	94.14	0.080
142.99	94.24	0.080
143.01	94.34	0.080
143.03	94.44	0.080
143.05	94.54	0.080
143.07	94.64	0.080
143.09	94.74	0.080
143.11	94.84	0.080
143.13	94.94	0.080
143.15	95.04	0.080
143.17	95.14	0.080
143.19	95.24	0.080
143.21	95.34	0.080
143.23	95.44	0.080
143.25	95.54	0.080
143.27	95.64	0.080
143.29	95.74	0.080
143.31	95.84	0.080
143.33	95.94	0.080
143.35	96.04	0.080
143.37	96.14	0.080
143.39	96.24	0.080
143.41	96.34	0.080
143.43	96.44	0.080
143.45	96.54	0.080
143.47	96.64	0.080
143.49	96.74	0.080
143.51	96.84	0.080
143.53	96.94	0.080
143.55	97.04	0.080
143.57	97.14	0.080
143.59	97.24	0.080
143.61	97.34	0.080
143.63	97.44	0.080
143.65	97.54	0.080
143.67	97.64	0.081
143.69	97.74	0.081
143.71	97.84	0.081
143.73	97.94	0.081
143.75	98.04	0.081
143.77	98.14	0.081
143.79	98.24	0.081
143.81	98.34	0.081
143.83	98.44	0.081
143.85	98.54	0.081
143.87	98.64	0.081
143.89	98.74	0.081
143.91	98.84	0.081
143.93	98.94	0.081
143.95	99.04
143.97	99.14
143.99