File: DSC/2025_05_29_Nifedipine_0C_190C_20Cmin_5Cmin_x3.csv
Filename,2025_05_29_Nifedipine_0C_190C_20Cmin_5Cmin_x3
Instrument name,DSC2A-00468 (192.168.1.100)
Operator,Yarger
rundate,5/29/2025
Sample name,2025_05_29_Nifedipine_0C_190C_20Cmin_5Cmin_x3
proceduresegments,Data Off ; Equilibrate 0.00 °C; Data On ; Ramp 5.00 °C/min to 190.00 °C; Data Off ; Isothermal 1.0 min; Data On ; Ramp 20.00 °C/min to 0.00 °C; Data Off ; Isothermal 2.0 min; Data On ; Ramp 5.00 °C/min to 190.00 °C; Data Off ; Isothermal 1.0 min; Data On ; Ramp 20.00 °C/min to 0.00 °C; Data Off ; Isothermal 2.0 min; Data On ; Ramp 5.00 °C/min to 30.00 °C
[File Parameters]
Run date,5/29/2025 7:00:02 PM
Trios version,5.1.1.46572
Original File Name,
Current File Name,D:\DSC2500\JYarger\2025_05_29_Nifedipine_0C_190C_20Cmin_5Cmin_x3.tri
[Procedure]
Procedure Name,Nidedipine_0C_190C_5Cmin_20Cmin_x3
Sample Name,2025_05_29_Nifedipine_0C_190C_20Cmin_5Cmin_x3
Sample Mass,20.35 mg
Reference Sample Mass,0 mg
Pan Mass,55.89 mg
Pan Number,5
Reference Pan Mass,55.79 mg
Reference Pan Number,1
Pan Type,Tzero Aluminum Hermetic
Comments,Al Hermetic DSC Consumables sealed Pan/Lid. A2 Tray (Google Sheet: DSC_Samples_A2_Tray_May2025)
Project Name,CA
Operator,Yarger
Test,Custom
Unload Max Temperature,30
Unload Min Temperature,30
Load Max Temperature,30
Load Min Temperature,30
Stop on Gas Flow Error,Yes
[Signal List]
Signal #1,Time (min)
Signal #2,Temperature (°C)
Signal #3,Heat Flow (mW)
Signal #4,Delta T (µV)
Signal #5,Delta Tzero (µV)
Signal #6,Tzero Temperature (°C)
Signal #7,Cell Purge (mL/min)
Signal #8,Heater Temp (°C)
Signal #9,Power Delivered (W)
Signal #10,Reference Junction Temperature (°C)
Signal #11,Flange Temperature (°C)
Signal #12,Heat Flow Phase (rad)
Signal #13,Total Heat Capacity (J/°C)
Signal #14,Heat Capacity (J/°C)
[Configuration]
Company Name,ASU
Instrument Name,DSC2A-00468
Instrument Type,DSC2500
Serial Number,DSC2A-00468
IP,192.168.1.100
Location of Instrument,MRRC
DisplayType,Unknown
Sample Interval ,0.1 s/pt
Selected Heat Flow,T4P
Exotherm Direction,Down
Cell Serial,DRC2-00792
Lid Type,Standard
Cooler,RCS 90
Leave Cooler on at End of Sequence,On
Gas 2,Nitrogen
Gas Selected,Channel 1
Flow Rate,50 mL/min
Secondary Purge,On
Licensed Heat Flow,Heat Flow T4P
Modulation Licensed,Yes
[Versions]
Common IDD Version,1
Cortex Version,VER 2.10.2.31
Driver,5.0.0.6
GDM Version,1.0.3.3
TouchscreenVersion,1.0.0.16145
FEP Version,1.2.1.21
FEP Bootloader,2.0.0.5
AutoSampler Version,2.1.1.26
Auto Sampler Bootloader,2.0.0.5
FCM Version,1.1.0.3
FCM Bootloader,2.0.0.5
[Experiment Logs]
Experiment Log Entry # 1,Data On set to 0
Experiment Log Entry # 3,Equilibrate Segment 0 (C) Started
Experiment Log Entry # 5,Air Cool is off.
Experiment Log Entry # 7,Data On set to 1
Experiment Log Entry # 9,Ramp Segment 5 C/min to 190 Started
Experiment Log Entry # 11,Data On set to 0
Experiment Log Entry # 13,Isothermal Segment 1 min started
Experiment Log Entry # 15,Data On set to 1
Experiment Log Entry # 17,Ramp Segment 20 C/min to 0 Started
Experiment Log Entry # 19,Data On set to 0
Experiment Log Entry # 21,Isothermal Segment 2 min started
Experiment Log Entry # 23,Data On set to 1
Experiment Log Entry # 25,Ramp Segment 5 C/min to 190 Started
Experiment Log Entry # 27,Data On set to 0
Experiment Log Entry # 29,Isothermal Segment 1 min started
Experiment Log Entry # 31,Data On set to 1
Experiment Log Entry # 33,Ramp Segment 20 C/min to 0 Started
Experiment Log Entry # 35,Data On set to 0
Experiment Log Entry # 37,Isothermal Segment 2 min started
Experiment Log Entry # 39,Data On set to 1
Experiment Log Entry # 41,Ramp Segment 5 C/min to 30 Started
[Method Log]
Method Log Entry # 1,Data Off
Method Log Entry # 2,Equilibrate 0 °C
Method Log Entry # 3,Data On
Method Log Entry # 4,(Ramp 465325) Ramp 5 °C/minute to 190 °C
Method Log Entry # 5,Data Off
Method Log Entry # 6,Isothermal 1 minutes
Method Log Entry # 7,Data On
Method Log Entry # 8,(Ramp 465329) Ramp 20 °C/minute to 0 °C
Method Log Entry # 9,Data Off
Method Log Entry # 10,Isothermal 2 minutes
Method Log Entry # 11,Data On
Method Log Entry # 12,(Ramp 465333) Ramp 5 °C/minute to 190 °C
Method Log Entry # 13,Data Off
Method Log Entry # 14,Isothermal 1 minutes
Method Log Entry # 15,Data On
Method Log Entry # 16,(Ramp 465337) Ramp 20 °C/minute to 0 °C
Method Log Entry # 17,Data Off
Method Log Entry # 18,Isothermal 2 minutes
Method Log Entry # 19,Data On
Method Log Entry # 20,(Ramp 465341) Ramp 5 °C/minute to 30 °C
Cell Serial,DRC2-00792
[T1 Calibration]
Slope,-0.008529666
Offset,9.636258
Initial Temperature,98.23
GUID,f8bfdadc-4977-4fdf-ba6d-0ba9134940c3
[TZero Calibration]
Date Applied,11/29/2022 4:06:13 PM
Description,From -89.059 °C to 396.009 °C at 20.000°C/min
Gas Type,Nitrogen
Pan Type,None
Source Files 1,C:\Users\yargerlab\Desktop\DSC Data\General\TZero_calibration_11_29_22_2nd(2).tri
Source Files 2,C:\Users\yargerlab\Desktop\DSC Data\General\TZero_calibration_11_29_22_2nd(3).tri
Delta T Offset,13.05235
Delta T Slope,-0.007271007
Delta T0 Offset,-13.69128
Delta T0 Slope,0.06063341
[Temperature Calibration]
Date Applied,11/29/2022 7:12:28 PM
Description,From 106.590 °C to 186.590 °C at 10.000°C/min
Gas Type,Nitrogen
Pan Type,Tzero Aluminum Hermetic
Source Files 1,C:\Users\yargerlab\Desktop\DSC Data\General\Indium(6).tri
Measured 1,157.391
Known 1,156.598
[Cell Constant Calibration]
Date Applied,11/29/2022 7:12:29 PM
Description,From 106.590 °C to 186.590 °C at 10.000°C/min
Gas Type,Nitrogen
Pan Type,Tzero Aluminum Hermetic
Source Files 1,C:\Users\yargerlab\Desktop\DSC Data\General\Indium(6).tri
T4P KCell,1.006051
Onset Slope,63.26126 mW/°C
[Direct Cp Calibration]
Date Applied,11/30/2022 11:04:51 AM
Description,From -79.983 °C to 298.409 °C at 10.000°C/min
Gas Type,Nitrogen
Pan Type,Tzero Aluminum Hermetic
Source Files 1,C:\Users\yargerlab\Desktop\DSC Data\General\Sapphire_Heat_Capacity_11_30_22.tri
[Rev Cp Calibration]
Date Applied,11/30/2022 1:58:51 PM
Description,From -79.996 °C to 292.812 °C at 3.000°C/min
Gas Type,Nitrogen
Pan Type,Tzero Aluminum Hermetic
Source Files 1,C:\Users\yargerlab\Desktop\DSC Data\General\Sapphire_MDSC_Calibration_11_30_22.tri
[step]
Ramp 5.00 °C/min to 190.00 °C
Time,Temperature,Heat Flow (Normalized)
min,°C,W/g
0.00,0.18,-0.041
0.03,0.17,-0.039
0.05,0.16,-0.034
0.08,0.16,-0.029
0.11,0.18,-0.025
0.13,0.23,-0.018
0.16,0.29,-0.009
0.19,0.37,0.003
0.21,0.45,0.014
0.24,0.54,0.025
0.27,0.64,0.034
0.29,0.74,0.042
0.32,0.85,0.049
0.35,0.96,0.055
0.37,1.07,0.060
0.40,1.19,0.065
0.43,1.31,0.068
0.45,1.43,0.072
0.48,1.55,0.075
0.51,1.68,0.077
0.53,1.80,0.079
0.56,1.93,0.081
0.59,2.05,0.082
0.61,2.18,0.084
0.64,2.31,0.085
0.67,2.44,0.086
0.69,2.57,0.086
0.72,2.70,0.087
0.75,2.82,0.088
0.77,2.96,0.088
0.80,3.09,0.088
0.83,3.22,0.089
0.85,3.35,0.089
0.88,3.48,0.089
0.91,3.61,0.089
0.93,3.74,0.090
0.96,3.87,0.090
0.99,4.01,0.090
1.01,4.14,0.090
1.04,4.27,0.090
1.07,4.40,0.091
1.09,4.53,0.091
1.12,4.67,0.091
1.15,4.80,0.091
1.17,4.93,0.091
1.20,5.07,0.091
1.23,5.20,0.091
1.25,5.33,0.092
1.28,5.46,0.092
1.31,5.60,0.092
1.33,5.73,0.092
1.36,5.86,0.092
1.39,5.99,0.092
1.41,6.13,0.092
1.44,6.26,0.092
1.47,6.39,0.092
1.49,6.53,0.093
1.52,6.66,0.093
1.55,6.79,0.093
1.57,6.93,0.093
1.60,7.06,0.093
1.63,7.19,0.093
1.65,7.33,0.093
1.68,7.46,0.093
1.71,7.59,0.093
1.73,7.73,0.093
1.76,7.86,0.093
1.79,7.99,0.093
1.81,8.13,0.093
1.84,8.26,0.093
1.87,8.39,0.093
1.89,8.52,0.093
1.92,8.66,0.093
1.95,8.79,0.093
1.97,8.93,0.093
2.00,9.06,0.094
2.03,9.19,0.094
2.05,9.32,0.094
2.08,9.46,0.094
2.11,9.59,0.094
2.13,9.72,0.094
2.16,9.86,0.094
2.19,9.99,0.094
2.21,10.13,0.094
2.24,10.26,0.094
2.27,10.39,0.094
2.29,10.52,0.094
2.32,10.66,0.094
2.35,10.79,0.094
2.37,10.92,0.094
2.40,11.06,0.094
2.43,11.19,0.094
2.45,11.33,0.094
2.48,11.46,0.094
2.51,11.59,0.094
2.53,11.73,0.094
2.56,11.86,0.094
2.59,11.99,0.094
2.61,12.12,0.094
2.64,12.26,0.094
2.67,12.39,0.094
2.69,12.53,0.094
2.72,12.66,0.094
2.75,12.79,0.094
2.77,12.93,0.094
2.80,13.06,0.095
2.83,13.19,0.095
2.85,13.33,0.095
2.88,13.46,0.095
2.91,13.59,0.095
2.93,13.72,0.095
2.96,13.86,0.095
2.99,13.99,0.095
3.01,14.13,0.095
3.04,14.26,0.095
3.07,14.39,0.095
3.09,14.53,0.095
3.12,14.66,0.095
3.15,14.79,0.095
3.17,14.93,0.095
3.20,15.06,0.095
3.23,15.19,0.095
3.25,15.33,0.095
3.28,15.46,0.095
3.31,15.59,0.095
3.33,15.73,0.095
3.36,15.86,0.095
3.39,15.99,0.095
3.41,16.13,0.095
3.44,16.26,0.095
3.47,16.40,0.095
3.49,16.53,0.095
3.52,16.66,0.095
3.55,16.80,0.095
3.57,16.93,0.095
3.60,17.06,0.095
3.63,17.19,0.095
3.65,17.33,0.096
3.68,17.46,0.096
3.71,17.60,0.096
3.73,17.73,0.096
3.76,17.86,0.096
3.79,18.00,0.096
3.81,18.13,0.096
3.84,18.26,0.096
3.87,18.40,0.096
3.89,18.53,0.096
3.92,18.66,0.096
3.95,18.80,0.096
3.97,18.93,0.096
4.00,19.06,0.096
4.03,19.20,0.096
4.05,19.33,0.096
4.08,19.46,0.096
4.11,19.60,0.096
4.13,19.73,0.096
4.16,19.86,0.096
4.19,20.00,0.096
4.21,20.13,0.096
4.24,20.26,0.096
4.27,20.40,0.096
4.29,20.53,0.096
4.32,20.66,0.096
4.35,20.80,0.096
4.37,20.93,0.096
4.40,21.06,0.096
4.43,21.20,0.096
4.45,21.33,0.096
4.48,21.46,0.096
4.51,21.60,0.096
4.53,21.73,0.097
4.56,21.86,0.097
4.59,22.00,0.097
4.61,22.13,0.097
4.64,22.26,0.097
4.67,22.40,0.097
4.69,22.53,0.097
4.72,22.66,0.097
4.75,22.80,0.097
4.77,22.93,0.097
4.80,23.06,0.097
4.83,23.20,0.097
4.85,23.33,0.097
4.88,23.46,0.097
4.91,23.60,0.097
4.93,23.73,0.097
4.96,23.86,0.097
4.99,24.00,0.097
5.01,24.13,0.097
5.04,24.27,0.097
5.07,24.40,0.097
5.09,24.53,0.097
5.12,24.66,0.097
5.15,24.80,0.097
5.17,24.93,0.097
5.20,25.06,0.097
5.23,25.20,0.097
5.25,25.33,0.097
5.28,25.47,0.097
5.31,25.60,0.097
5.33,25.73,0.097
5.36,25.86,0.097
5.39,26.00,0.098
5.41,26.13,0.098
5.44,26.26,0.098
5.47,26.40,0.098
5.49,26.53,0.098
5.52,26.67,0.098
5.55,26.80,0.098
5.57,26.93,0.098
5.60,27.07,0.098
5.63,27.20,0.098
5.65,27.34,0.098
5.68,27.47,0.098
5.71,27.60,0.098
5.73,27.74,0.098
5.76,27.87,0.098
5.79,28.00,0.098
5.81,28.13,0.098
5.84,28.27,0.098
5.87,28.40,0.098
5.89,28.53,0.098
5.92,28.67,0.098
5.95,28.80,0.098
5.97,28.93,0.098
6.00,29.07,0.098
6.03,29.20,0.098
6.05,29.33,0.098
6.08,29.47,0.099
6.11,29.60,0.099
6.13,29.74,0.099
6.16,29.87,0.099
6.19,30.00,0.099
6.21,30.14,0.099
6.24,30.27,0.099
6.27,30.40,0.099
6.29,30.54,0.099
6.32,30.67,0.099
6.35,30.80,0.099
6.37,30.94,0.099
6.40,31.07,0.099
6.43,31.20,0.099
6.45,31.34,0.099
6.48,31.47,0.099
6.51,31.60,0.099
6.53,31.74,0.099
6.56,31.87,0.099
6.59,32.00,0.099
6.61,32.14,0.099
6.64,32.27,0.099
6.67,32.40,0.099
6.69,32.54,0.099
6.72,32.67,0.099
6.75,32.80,0.099
6.77,32.94,0.099
6.80,33.07,0.099
6.83,33.20,0.099
6.85,33.34,0.099
6.88,33.47,0.099
6.91,33.60,0.099
6.93,33.74,0.099
6.96,33.87,0.100
6.99,34.00,0.100
7.01,34.14,0.100
7.04,34.27,0.100
7.07,34.40,0.100
7.09,34.54,0.100
7.12,34.67,0.100
7.15,34.80,0.100
7.17,34.94,0.100
7.20,35.07,0.100
7.23,35.21,0.100
7.25,35.34,0.100
7.28,35.47,0.100
7.31,35.61,0.100
7.33,35.74,0.100
7.36,35.87,0.100
7.39,36.00,0.100
7.41,36.14,0.100
7.44,36.27,0.100
7.47,36.40,0.100
7.49,36.54,0.100
7.52,36.67,0.100
7.55,36.81,0.100
7.57,36.94,0.100
7.60,37.07,0.100
7.63,37.21,0.100
7.65,37.34,0.100
7.68,37.47,0.101
7.71,37.61,0.101
7.73,37.74,0.101
7.76,37.87,0.101
7.79,38.01,0.101
7.81,38.14,0.101
7.84,38.27,0.101
7.87,38.41,0.101
7.89,38.54,0.101
7.92,38.67,0.101
7.95,38.81,0.101
7.97,38.94,0.101
8.00,39.07,0.101
8.03,39.21,0.101
8.05,39.34,0.101
8.08,39.48,0.101
8.11,39.61,0.101
8.13,39.74,0.101
8.16,39.87,0.101
8.19,40.01,0.101
8.21,40.14,0.101
8.24,40.28,0.101
8.27,40.41,0.101
8.29,40.54,0.101
8.32,40.68,0.101
8.35,40.81,0.101
8.37,40.94,0.101
8.40,41.08,0.101
8.43,41.21,0.101
8.45,41.34,0.101
8.48,41.48,0.101
8.51,41.61,0.101
8.53,41.74,0.101
8.56,41.87,0.101
8.59,42.01,0.102
8.61,42.14,0.102
8.64,42.28,0.102
8.67,42.41,0.102
8.69,42.54,0.102
8.72,42.68,0.102
8.75,42.81,0.102
8.77,42.94,0.102
8.80,43.08,0.102
8.83,43.21,0.102
8.85,43.34,0.102
8.88,43.48,0.102
8.91,43.61,0.102
8.93,43.74,0.102
8.96,43.88,0.102
8.99,44.01,0.102
9.01,44.14,0.102
9.04,44.28,0.102
9.07,44.41,0.102
9.09,44.54,0.102
9.12,44.68,0.102
9.15,44.81,0.102
9.17,44.94,0.102
9.20,45.08,0.102
9.23,45.21,0.102
9.25,45.34,0.102
9.28,45.48,0.102
9.31,45.61,0.102
9.33,45.74,0.102
9.36,45.88,0.102
9.39,46.01,0.103
9.41,46.14,0.103
9.44,46.28,0.103
9.47,46.41,0.103
9.49,46.54,0.103
9.52,46.68,0.103
9.55,46.81,0.103
9.57,46.95,0.103
9.60,47.08,0.103
9.63,47.21,0.103
9.65,47.34,0.103
9.68,47.48,0.103
9.71,47.61,0.103
9.73,47.75,0.103
9.76,47.88,0.103
9.79,48.01,0.103
9.81,48.14,0.103
9.84,48.28,0.103
9.87,48.41,0.103
9.89,48.55,0.103
9.92,48.68,0.103
9.95,48.81,0.103
9.97,48.95,0.103
10.00,49.08,0.103
10.03,49.21,0.103
10.05,49.35,0.103
10.08,49.48,0.103
10.11,49.61,0.103
10.13,49.75,0.103
10.16,49.88,0.103
10.19,50.01,0.104
10.21,50.15,0.104
10.24,50.28,0.104
10.27,50.41,0.104
10.29,50.55,0.104
10.32,50.68,0.104
10.35,50.81,0.104
10.37,50.95,0.104
10.40,51.08,0.104
10.43,51.21,0.104
10.45,51.35,0.104
10.48,51.48,0.104
10.51,51.61,0.104
10.53,51.75,0.104
10.56,51.88,0.104
10.59,52.01,0.104
10.61,52.15,0.104
10.64,52.28,0.104
10.67,52.42,0.104
10.69,52.55,0.104
10.72,52.68,0.104
10.75,52.82,0.104
10.77,52.95,0.104
10.80,53.08,0.104
10.83,53.22,0.104
10.85,53.35,0.104
10.88,53.48,0.104
10.91,53.62,0.104
10.93,53.75,0.104
10.96,53.88,0.104
10.99,54.02,0.105
11.01,54.15,0.105
11.04,54.28,0.105
11.07,54.42,0.105
11.09,54.55,0.105
11.12,54.68,0.105
11.15,54.82,0.105
11.17,54.95,0.105
11.20,55.08,0.105
11.23,55.22,0.105
11.25,55.35,0.105
11.28,55.48,0.105
11.31,55.62,0.105
11.33,55.75,0.105
11.36,55.88,0.105
11.39,56.02,0.105
11.41,56.15,0.105
11.44,56.28,0.105
11.47,56.42,0.105
11.49,56.55,0.105
11.52,56.68,0.105
11.55,56.82,0.105
11.57,56.95,0.105
11.60,57.08,0.105
11.63,57.22,0.105
11.65,57.35,0.105
11.68,57.48,0.105
11.71,57.62,0.105
11.73,57.75,0.105
11.76,57.89,0.105
11.79,58.02,0.105
11.81,58.15,0.105
11.84,58.28,0.106
11.87,58.42,0.106
11.89,58.55,0.106
11.92,58.69,0.106
11.95,58.82,0.106
11.97,58.95,0.106
12.00,59.08,0.106
12.03,59.22,0.106
12.05,59.35,0.106
12.08,59.48,0.106
12.11,59.62,0.106
12.13,59.75,0.106
12.16,59.88,0.106
12.19,60.02,0.106
12.21,60.15,0.106
12.24,60.29,0.106
12.27,60.42,0.106
12.29,60.55,0.106
12.32,60.69,0.106
12.35,60.82,0.106
12.37,60.95,0.106
12.40,61.09,0.106
12.43,61.22,0.106
12.45,61.35,0.106
12.48,61.49,0.106
12.51,61.62,0.106
12.53,61.75,0.106
12.56,61.89,0.106
12.59,62.02,0.106
12.61,62.15,0.106
12.64,62.29,0.106
12.67,62.42,0.106
12.69,62.55,0.106
12.72,62.69,0.106
12.75,62.82,0.106
12.77,62.95,0.107
12.80,63.09,0.107
12.83,63.22,0.107
12.85,63.35,0.107
12.88,63.49,0.107
12.91,63.62,0.107
12.93,63.75,0.107
12.96,63.89,0.107
12.99,64.02,0.107
13.01,64.15,0.107
13.04,64.29,0.107
13.07,64.42,0.107
13.09,64.55,0.107
13.12,64.69,0.107
13.15,64.82,0.107
13.17,64.96,0.107
13.20,65.09,0.107
13.23,65.22,0.107
13.25,65.36,0.107
13.28,65.49,0.107
13.31,65.62,0.107
13.33,65.75,0.107
13.36,65.89,0.107
13.39,66.02,0.107
13.41,66.16,0.107
13.44,66.29,0.107
13.47,66.42,0.107
13.49,66.55,0.107
13.52,66.69,0.107
13.55,66.82,0.107
13.57,66.96,0.107
13.60,67.09,0.107
13.63,67.22,0.108
13.65,67.36,0.108
13.68,67.49,0.108
13.71,67.62,0.108
13.73,67.75,0.108
13.76,67.89,0.108
13.79,68.02,0.108
13.81,68.16,0.108
13.84,68.29,0.108
13.87,68.42,0.108
13.89,68.56,0.108
13.92,68.69,0.108
13.95,68.82,0.108
13.97,68.96,0.108
14.00,69.09,0.108
14.03,69.22,0.108
14.05,69.36,0.108
14.08,69.49,0.108
14.11,69.62,0.108
14.13,69.76,0.108
14.16,69.89,0.108
14.19,70.02,0.108
14.21,70.16,0.108
14.24,70.29,0.108
14.27,70.42,0.108
14.29,70.56,0.108
14.32,70.69,0.108
14.35,70.82,0.108
14.37,70.96,0.108
14.40,71.09,0.108
14.43,71.22,0.108
14.45,71.36,0.109
14.48,71.49,0.109
14.51,71.62,0.109
14.53,71.76,0.109
14.56,71.89,0.109
14.59,72.02,0.109
14.61,72.16,0.109
14.64,72.29,0.109
14.67,72.42,0.109
14.69,72.56,0.109
14.72,72.69,0.109
14.75,72.82,0.109
14.77,72.96,0.109
14.80,73.09,0.109
14.83,73.23,0.109
14.85,73.36,0.109
14.88,73.49,0.109
14.91,73.63,0.109
14.93,73.76,0.109
14.96,73.89,0.109
14.99,74.03,0.109
15.01,74.16,0.109
15.04,74.29,0.109
15.07,74.43,0.109
15.09,74.56,0.109
15.12,74.69,0.109
15.15,74.83,0.109
15.17,74.96,0.109
15.20,75.09,0.109
15.23,75.23,0.109
15.25,75.36,0.109
15.28,75.49,0.110
15.31,75.63,0.110
15.33,75.76,0.110
15.36,75.89,0.110
15.39,76.03,0.110
15.41,76.16,0.110
15.44,76.29,0.110
15.47,76.43,0.110
15.49,76.56,0.110
15.52,76.69,0.110
15.55,76.83,0.110
15.57,76.96,0.110
15.60,77.09,0.110
15.63,77.23,0.110
15.65,77.36,0.110
15.68,77.49,0.110
15.71,77.63,0.110
15.73,77.76,0.110
15.76,77.89,0.110
15.79,78.03,0.110
15.81,78.16,0.110
15.84,78.29,0.110
15.87,78.43,0.110
15.89,78.56,0.110
15.92,78.69,0.110
15.95,78.83,0.110
15.97,78.96,0.110
16.00,79.09,0.110
16.03,79.23,0.110
16.05,79.36,0.110
16.08,79.50,0.110
16.11,79.63,0.111
16.13,79.76,0.111
16.16,79.90,0.111
16.19,80.03,0.111
16.21,80.16,0.111
16.24,80.30,0.111
16.27,80.43,0.111
16.29,80.56,0.111
16.32,80.70,0.111
16.35,80.83,0.111
16.37,80.96,0.111
16.40,81.09,0.111
16.43,81.23,0.111
16.45,81.36,0.111
16.48,81.50,0.111
16.51,81.63,0.111
16.53,81.76,0.111
16.56,81.89,0.111
16.59,82.03,0.111
16.61,82.16,0.111
16.64,82.30,0.111
16.67,82.43,0.111
16.69,82.56,0.111
16.72,82.70,0.111
16.75,82.83,0.111
16.77,82.96,0.111
16.80,83.10,0.111
16.83,83.23,0.111
16.85,83.36,0.111
16.88,83.50,0.111
16.91,83.63,0.111
16.93,83.76,0.111
16.96,83.90,0.111
16.99,84.03,0.112
17.01,84.16,0.112
17.04,84.30,0.112
17.07,84.43,0.112
17.09,84.56,0.112
17.12,84.70,0.112
17.15,84.83,0.112
17.17,84.97,0.112
17.20,85.10,0.112
17.23,85.23,0.112
17.25,85.37,0.112
17.28,85.50,0.112
17.31,85.63,0.112
17.33,85.77,0.112
17.36,85.90,0.112
17.39,86.03,0.112
17.41,86.17,0.112
17.44,86.30,0.112
17.47,86.43,0.112
17.49,86.57,0.112
17.52,86.70,0.112
17.55,86.83,0.112
17.57,86.97,0.112
17.60,87.10,0.112
17.63,87.23,0.112
17.65,87.37,0.112
17.68,87.50,0.112
17.71,87.63,0.112
17.73,87.77,0.112
17.76,87.90,0.112
17.79,88.03,0.112
17.81,88.17,0.112
17.84,88.30,0.112
17.87,88.43,0.112
17.89,88.57,0.112
17.92,88.70,0.112
17.95,88.83,0.112
17.97,88.97,0.112
18.00,89.10,0.112
18.03,89.23,0.112
18.05,89.37,0.113
18.08,89.50,0.113
18.11,89.63,0.113
18.13,89.77,0.113
18.16,89.90,0.113
18.19,90.03,0.113
18.21,90.17,0.113
18.24,90.30,0.113
18.27,90.43,0.113
18.29,90.57,0.113
18.32,90.70,0.113
18.35,90.83,0.113
18.37,90.97,0.113
18.40,91.10,0.113
18.43,91.23,0.113
18.45,91.37,0.113
18.48,91.50,0.113
18.51,91.63,0.113
18.53,91.77,0.113
18.56,91.90,0.113
18.59,92.04,0.113
18.61,92.17,0.113
18.64,92.30,0.113
18.67,92.43,0.113
18.69,92.57,0.113
18.72,92.70,0.113
18.75,92.83,0.113
18.77,92.97,0.113
18.80,93.10,0.113
18.83,93.23,0.114
18.85,93.37,0.114
18.88,93.50,0.114
18.91,93.64,0.114
18.93,93.77,0.114
18.96,93.90,0.114
18.99,94.03,0.114
19.01,94.17,0.114
19.04,94.30,0.114
19.07,94.44,0.114
19.09,94.57,0.114
19.12,94.70,0.114
19.15,94.83,0.114
19.17,94.97,0.114
19.20,95.10,0.114
19.23,95.24,0.114
19.25,95.37,0.114
19.28,95.50,0.114
19.31,95.64,0.114
19.33,95.77,0.114
19.36,95.90,0.114
19.39,96.03,0.114
19.41,96.17,0.114
19.44,96.30,0.114
19.47,96.44,0.114
19.49,96.57,0.114
19.52,96.70,0.114
19.55,96.84,0.114
19.57,96.97,0.114
19.60,97.10,0.114
19.63,97.24,0.114
19.65,97.37,0.114
19.68,97.50,0.115
19.71,97.64,0.115
19.73,97.77,0.115
19.76,97.90,0.115
19.79,98.04,0.115
19.81,98.17,0.115
19.84,98.30,0.115
19.87,98.44,0.115
19.89,98.57,0.115
19.92,98.70,0.115
19.95,98.84,0.115
19.97,98.97,0.115
20.00,99.10,0.115
20.03,99.24,0.115
20.05,99.37,0.115
20.08,99.50,0.115
20.11,99.64,0.115
20.13,99.77,0.115
20.16,99.90,0.115
20.19,100.04,0.115
20.21,100.17,0.115
20.24,100.30,0.115
20.27,100.44,0.115
20.29,100.57,0.115
20.32,100.70,0.115
20.35,100.84,0.115
20.37,100.97,0.115
20.40,101.10,0.115
20.43,101.24,0.115
20.45,101.37,0.115
20.48,101.50,0.115
20.51,101.64,0.115
20.53,101.77,0.115
20.56,101.90,0.116
20.59,102.04,0.116
20.61,102.17,0.116
20.64,102.30,0.116
20.67,102.44,0.116
20.69,102.57,0.116
20.72,102.70,0.116
20.75,102.84,0.116
20.77,102.97,0.116
20.80,103.11,0.116
20.83,103.24,0.116
20.85,103.37,0.116
20.88,103.51,0.116
20.91,103.64,0.116
20.93,103.77,0.116
20.96,103.91,0.116
20.99,104.04,0.116
21.01,104.17,0.116
21.04,104.31,0.116
21.07,104.44,0.116
21.09,104.57,0.116
21.12,104.71,0.116
21.15,104.84,0.116
21.17,104.97,0.116
21.20,105.11,0.116
21.23,105.24,0.116
21.25,105.37,0.116
21.28,105.51,0.116
21.31,105.64,0.116
21.33,105.77,0.116
21.36,105.91,0.116
21.39,106.04,0.116
21.41,106.17,0.117
21.44,106.31,0.117
21.47,106.44,0.117
21.49,106.57,0.117
21.52,106.71,0.117
21.55,106.84,0.117
21.57,106.97,0.117
21.60,107.11,0.117
21.63,107.24,0.117
21.65,107.37,0.117
21.68,107.51,0.117
21.71,107.64,0.117
21.73,107.77,0.117
21.76,107.91,0.117
21.79,108.04,0.117
21.81,108.17,0.117
21.84,108.31,0.117
21.87,108.44,0.117
21.89,108.57,0.117
21.92,108.71,0.117
21.95,108.84,0.117
21.97,108.97,0.117
22.00,109.11,0.117
22.03,109.24,0.117
22.05,109.37,0.117
22.08,109.51,0.117
22.11,109.64,0.117
22.13,109.77,0.117
22.16,109.91,0.117
22.19,110.04,0.117
22.21,110.17,0.117
22.24,110.31,0.117
22.27,110.44,0.118
22.29,110.58,0.118
22.32,110.71,0.118
22.35,110.84,0.118
22.37,110.97,0.118
22.40,111.11,0.118
22.43,111.24,0.118
22.45,111.37,0.118
22.48,111.51,0.118
22.51,111.64,0.118
22.53,111.77,0.118
22.56,111.91,0.118
22.59,112.04,0.118
22.61,112.17,0.118
22.64,112.31,0.118
22.67,112.44,0.118
22.69,112.58,0.118
22.72,112.71,0.118
22.75,112.84,0.118
22.77,112.98,0.118
22.80,113.11,0.118
22.83,113.24,0.118
22.85,113.38,0.118
22.88,113.51,0.118
22.91,113.64,0.118
22.93,113.78,0.118
22.96,113.91,0.118
22.99,114.04,0.118
23.01,114.18,0.118
23.04,114.31,0.118
23.07,114.44,0.118
23.09,114.57,0.118
23.12,114.71,0.118
23.15,114.84,0.118
23.17,114.97,0.119
23.20,115.11,0.119
23.23,115.24,0.119
23.25,115.38,0.119
23.28,115.51,0.119
23.31,115.64,0.119
23.33,115.78,0.119
23.36,115.91,0.119
23.39,116.04,0.119
23.41,116.18,0.119
23.44,116.31,0.119
23.47,116.44,0.119
23.49,116.58,0.119
23.52,116.71,0.119
23.55,116.84,0.119
23.57,116.98,0.119
23.60,117.11,0.119
23.63,117.24,0.119
23.65,117.38,0.119
23.68,117.51,0.119
23.71,117.64,0.119
23.73,117.78,0.119
23.76,117.91,0.119
23.79,118.04,0.119
23.81,118.18,0.119
23.84,118.31,0.119
23.87,118.44,0.119
23.89,118.58,0.119
23.92,118.71,0.119
23.95,118.84,0.119
23.97,118.98,0.119
24.00,119.11,0.119
24.03,119.24,0.119
24.05,119.38,0.119
24.08,119.51,0.119
24.11,119.64,0.119
24.13,119.78,0.120
24.16,119.91,0.120
24.19,120.04,0.120
24.21,120.18,0.120
24.24,120.31,0.120
24.27,120.45,0.120
24.29,120.58,0.120
24.32,120.71,0.120
24.35,120.85,0.120
24.37,120.98,0.120
24.40,121.11,0.120
24.43,121.25,0.120
24.45,121.38,0.120
24.48,121.51,0.120
24.51,121.65,0.120
24.53,121.78,0.120
24.56,121.91,0.120
24.59,122.04,0.120
24.61,122.18,0.120
24.64,122.31,0.120
24.67,122.44,0.120
24.69,122.58,0.120
24.72,122.71,0.120
24.75,122.85,0.120
24.77,122.98,0.120
24.80,123.11,0.120
24.83,123.25,0.120
24.85,123.38,0.120
24.88,123.51,0.120
24.91,123.65,0.120
24.93,123.78,0.120
24.96,123.91,0.120
24.99,124.05,0.120
25.01,124.18,0.120
25.04,124.31,0.120
25.07,124.45,0.120
25.09,124.58,0.121
25.12,124.71,0.121
25.15,124.85,0.121
25.17,124.98,0.121
25.20,125.11,0.121
25.23,125.25,0.121
25.25,125.38,0.121
25.28,125.51,0.121
25.31,125.65,0.121
25.33,125.78,0.121
25.36,125.91,0.121
25.39,126.05,0.121
25.41,126.18,0.121
25.44,126.31,0.121
25.47,126.45,0.121
25.49,126.58,0.121
25.52,126.71,0.121
25.55,126.85,0.121
25.57,126.98,0.121
25.60,127.11,0.121
25.63,127.25,0.121
25.65,127.38,0.121
25.68,127.51,0.121
25.71,127.64,0.121
25.73,127.78,0.121
25.76,127.91,0.121
25.79,128.05,0.121
25.81,128.18,0.121
25.84,128.31,0.121
25.87,128.45,0.121
25.89,128.58,0.121
25.92,128.71,0.121
25.95,128.85,0.121
25.97,128.98,0.122
26.00,129.11,0.122
26.03,129.25,0.122
26.05,129.38,0.122
26.08,129.51,0.122
26.11,129.65,0.122
26.13,129.78,0.122
26.16,129.91,0.122
26.19,130.05,0.122
26.21,130.18,0.122
26.24,130.31,0.122
26.27,130.45,0.122
26.29,130.58,0.122
26.32,130.71,0.122
26.35,130.85,0.122
26.37,130.98,0.122
26.40,131.11,0.122
26.43,131.25,0.122
26.45,131.38,0.122
26.48,131.52,0.122
26.51,131.65,0.122
26.53,131.78,0.122
26.56,131.91,0.122
26.59,132.05,0.122
26.61,132.18,0.122
26.64,132.31,0.122
26.67,132.45,0.122
26.69,132.58,0.122
26.72,132.71,0.122
26.75,132.85,0.122
26.77,132.98,0.122
26.80,133.11,0.122
26.83,133.25,0.122
26.85,133.38,0.122
26.88,133.51,0.122
26.91,133.65,0.122
26.93,133.78,0.122
26.96,133.92,0.123
26.99,134.05,0.123
27.01,134.18,0.123
27.04,134.31,0.123
27.07,134.45,0.123
27.09,134.58,0.123
27.12,134.72,0.123
27.15,134.85,0.123
27.17,134.98,0.123
27.20,135.12,0.123
27.23,135.25,0.123
27.25,135.38,0.123
27.28,135.51,0.123
27.31,135.65,0.123
27.33,135.78,0.123
27.36,135.91,0.123
27.39,136.05,0.123
27.41,136.18,0.123
27.44,136.32,0.123
27.47,136.45,0.123
27.49,136.58,0.123
27.52,136.72,0.123
27.55,136.85,0.123
27.57,136.98,0.123
27.60,137.12,0.123
27.63,137.25,0.123
27.65,137.38,0.123
27.68,137.52,0.123
27.71,137.65,0.123
27.73,137.78,0.123
27.76,137.92,0.123
27.79,138.05,0.123
27.81,138.18,0.124
27.84,138.31,0.124
27.87,138.45,0.124
27.89,138.58,0.124
27.92,138.72,0.124
27.95,138.85,0.124
27.97,138.98,0.124
28.00,139.12,0.124
28.03,139.25,0.124
28.05,139.38,0.124
28.08,139.52,0.124
28.11,139.65,0.124
28.13,139.78,0.124
28.16,139.92,0.124
28.19,140.05,0.124
28.21,140.18,0.124
28.24,140.32,0.124
28.27,140.45,0.124
28.29,140.58,0.124
28.32,140.72,0.124
28.35,140.85,0.124
28.37,140.98,0.124
28.40,141.12,0.124
28.43,141.25,0.124
28.45,141.38,0.124
28.48,141.52,0.124
28.51,141.65,0.124
28.53,141.78,0.124
28.56,141.92,0.124
28.59,142.05,0.124
28.61,142.18,0.124
28.64,142.32,0.125
28.67,142.45,0.125
28.69,142.58,0.125
28.72,142.72,0.125
28.75,142.85,0.125
28.77,142.98,0.125
28.80,143.12,0.125
28.83,143.25,0.125
28.85,143.38,0.125
28.88,143.52,0.125
28.91,143.65,0.125
28.93,143.78,0.125
28.96,143.92,0.125
28.99,144.05,0.125
29.01,144.18,0.125
29.04,144.32,0.125
29.07,144.45,0.125
29.09,144.58,0.125
29.12,144.72,0.125
29.15,144.85,0.125
29.17,144.98,0.125
29.20,145.12,0.125
29.23,145.25,0.125
29.25,145.38,0.125
29.28,145.52,0.125
29.31,145.65,0.125
29.33,145.78,0.125
29.36,145.92,0.125
29.39,146.05,0.125
29.41,146.18,0.125
29.44,146.32,0.126
29.47,146.45,0.126
29.49,146.58,0.126
29.52,146.72,0.126
29.55,146.85,0.126
29.57,146.98,0.126
29.60,147.12,0.126
29.63,147.25,0.126
29.65,147.38,0.126
29.68,147.52,0.126
29.71,147.65,0.126
29.73,147.78,0.126
29.76,147.92,0.126
29.79,148.05,0.126
29.81,148.18,0.126
29.84,148.32,0.126
29.87,148.45,0.126
29.89,148.58,0.126
29.92,148.72,0.126
29.95,148.85,0.126
29.97,148.98,0.126
30.00,149.12,0.126
30.03,149.25,0.126
30.05,149.38,0.127
30.08,149.52,0.127
30.11,149.65,0.127
30.13,149.78,0.127
30.16,149.92,0.127
30.19,150.05,0.127
30.21,150.18,0.127
30.24,150.32,0.127
30.27,150.45,0.127
30.29,150.58,0.127
30.32,150.72,0.127
30.35,150.85,0.127
30.37,150.98,0.127
30.40,151.12,0.127
30.43,151.25,0.127
30.45,151.39,0.127
30.48,151.52,0.127
30.51,151.65,0.127
30.53,151.79,0.127
30.56,151.92,0.128
30.59,152.05,0.128
30.61,152.19,0.128
30.64,152.32,0.128
30.67,152.45,0.128
30.69,152.58,0.128
30.72,152.72,0.128
30.75,152.85,0.128
30.77,152.98,0.128
30.80,153.12,0.128
30.83,153.25,0.128
30.85,153.38,0.128
30.88,153.52,0.128
30.91,153.65,0.128
30.93,153.78,0.128
30.96,153.92,0.128
30.99,154.05,0.128
31.01,154.18,0.129
31.04,154.32,0.129
31.07,154.45,0.129
31.09,154.58,0.129
31.12,154.72,0.129
31.15,154.85,0.129
31.17,154.98,0.129
31.20,155.12,0.129
31.23,155.25,0.129
31.25,155.38,0.129
31.28,155.52,0.129
31.31,155.65,0.129
31.33,155.78,0.130
31.36,155.92,0.130
31.39,156.05,0.130
31.41,156.18,0.130
31.44,156.32,0.130
31.47,156.45,0.130
31.49,156.58,0.130
31.52,156.72,0.130
31.55,156.85,0.130
31.57,156.98,0.130
31.60,157.11,0.130
31.63,157.25,0.130
31.65,157.38,0.130
31.68,157.51,0.131
31.71,157.65,0.131
31.73,157.78,0.131
31.76,157.91,0.131
31.79,158.05,0.131
31.81,158.18,0.131
31.84,158.32,0.131
31.87,158.45,0.131
31.89,158.58,0.132
31.92,158.71,0.132
31.95,158.85,0.132
31.97,158.98,0.132
32.00,159.11,0.132
32.03,159.25,0.132
32.05,159.38,0.132
32.08,159.51,0.133
32.11,159.65,0.133
32.13,159.78,0.133
32.16,159.91,0.133
32.19,160.05,0.133
32.21,160.18,0.133
32.24,160.31,0.133
32.27,160.45,0.134
32.29,160.58,0.134
32.32,160.71,0.134
32.35,160.85,0.134
32.37,160.98,0.134
32.40,161.11,0.135
32.43,161.25,0.135
32.45,161.38,0.135
32.48,161.51,0.135
32.51,161.64,0.135
32.53,161.78,0.136
32.56,161.91,0.136
32.59,162.04,0.136
32.61,162.18,0.136
32.64,162.31,0.137
32.67,162.44,0.137
32.69,162.57,0.138
32.72,162.71,0.138
32.75,162.84,0.139
32.77,162.97,0.139
32.80,163.11,0.140
32.83,163.24,0.140
32.85,163.37,0.141
32.88,163.51,0.141
32.91,163.64,0.142
32.93,163.77,0.142
32.96,163.90,0.143
32.99,164.04,0.143
33.01,164.17,0.144
33.04,164.30,0.144
33.07,164.43,0.145
33.09,164.57,0.146
33.12,164.70,0.147
33.15,164.83,0.147
33.17,164.97,0.148
33.20,165.10,0.149
33.23,165.23,0.150
33.25,165.36,0.151
33.28,165.50,0.152
33.31,165.63,0.154
33.33,165.76,0.155
33.36,165.89,0.156
33.39,166.02,0.157
33.41,166.16,0.159
33.44,166.29,0.160
33.47,166.42,0.162
33.49,166.55,0.164
33.52,166.68,0.165
33.55,166.81,0.167
33.57,166.94,0.169
33.60,167.08,0.171
33.63,167.21,0.173
33.65,167.34,0.176
33.68,167.47,0.178
33.71,167.60,0.181
33.73,167.73,0.184
33.76,167.86,0.187
33.79,167.99,0.190
33.81,168.12,0.194
33.84,168.25,0.198
33.87,168.38,0.201
33.89,168.51,0.206
33.92,168.64,0.211
33.95,168.76,0.217
33.97,168.89,0.222
34.00,169.02,0.228
34.03,169.14,0.235
34.05,169.27,0.242
34.08,169.39,0.250
34.11,169.52,0.258
34.13,169.64,0.268
34.16,169.76,0.277
34.19,169.89,0.288
34.21,170.01,0.299
34.24,170.13,0.312
34.27,170.24,0.327
34.29,170.36,0.342
34.32,170.48,0.357
34.35,170.59,0.374
34.37,170.71,0.392
34.40,170.82,0.412
34.43,170.93,0.434
34.45,171.04,0.457
34.48,171.15,0.480
34.51,171.26,0.505
34.53,171.36,0.531
34.56,171.46,0.558
34.59,171.57,0.587
34.61,171.66,0.619
34.64,171.76,0.650
34.67,171.86,0.683
34.69,171.96,0.717
34.72,172.05,0.754
34.75,172.14,0.793
34.77,172.23,0.832
34.80,172.32,0.869
34.83,172.41,0.908
34.85,172.49,0.947
34.88,172.58,0.986
34.91,172.67,1.028
34.93,172.75,1.067
34.96,172.84,1.114
34.99,172.92,1.156
35.01,173.00,1.205
35.04,173.08,1.245
35.07,173.16,1.296
35.09,173.23,1.369
35.12,173.29,1.457
35.15,173.33,1.551
35.17,173.37,1.630
35.20,173.42,1.694
35.23,173.46,1.766
35.25,173.51,1.820
35.28,173.58,1.852
35.31,173.66,1.889
35.33,173.74,1.937
35.36,173.83,1.949
35.39,173.94,1.946
35.41,174.06,1.936
35.44,174.19,1.927
35.47,174.33,1.916
35.49,174.47,1.902
35.52,174.62,1.884
35.55,174.77,1.857
35.57,174.94,1.819
35.60,175.11,1.781
35.63,175.28,1.732
35.65,175.47,1.674
35.68,175.67,1.601
35.71,175.88,1.503
35.73,176.12,1.367
35.76,176.40,1.190
35.79,176.72,0.991
35.81,177.05,0.818
35.84,177.37,0.694
35.87,177.66,0.596
35.89,177.93,0.518
35.92,178.17,0.454
35.95,178.40,0.401
35.97,178.61,0.357
36.00,178.80,0.320
36.03,178.99,0.290
36.05,179.17,0.266
36.08,179.34,0.245
36.11,179.50,0.228
36.13,179.66,0.214
36.16,179.81,0.203
36.19,179.96,0.194
36.21,180.11,0.186
36.24,180.25,0.179
36.27,180.40,0.173
36.29,180.54,0.169
36.32,180.68,0.165
36.35,180.81,0.162
36.37,180.95,0.160
36.40,181.09,0.158
36.43,181.22,0.156
36.45,181.36,0.155
36.48,181.49,0.154
36.51,181.63,0.153
36.53,181.76,0.152
36.56,181.90,0.151
36.59,182.03,0.151
36.61,182.17,0.151
36.64,182.30,0.150
36.67,182.44,0.150
36.69,182.57,0.150
36.72,182.70,0.150
36.75,182.84,0.150
36.77,182.97,0.150
36.80,183.10,0.150
36.83,183.24,0.150
36.85,183.37,0.150
36.88,183.50,0.149
36.91,183.64,0.149
36.93,183.77,0.149
36.96,183.90,0.149
36.99,184.04,0.149
37.01,184.17,0.149
37.04,184.30,0.149
37.07,184.44,0.149
37.09,184.57,0.149
37.12,184.71,0.148
37.15,184.84,0.148
37.17,184.97,0.148
37.20,185.11,0.148
37.23,185.24,0.148
37.25,185.37,0.148
37.28,185.51,0.148
37.31,185.64,0.148
37.33,185.77,0.148
37.36,185.91,0.148
37.39,186.04,0.148
37.41,186.17,0.148
37.44,186.31,0.148
37.47,186.44,0.148
37.49,186.57,0.148
37.52,186.71,0.147
37.55,186.84,0.147
37.57,186.98,0.147
37.60,187.11,0.147
37.63,187.24,0.147
37.65,187.38,0.147
37.68,187.51,0.147
37.71,187.64,0.147
37.73,187.78,0.147
37.76,187.91,0.147
37.79,188.04,0.146
37.81,188.18,0.146
37.84,188.31,0.146
37.87,188.44,0.146
37.89,188.58,0.146
37.92,188.71,0.146
37.95,188.84,0.146
37.97,188.98,
38.00,189.11,
38.01,,

[step]
Ramp 20.00 °C/min to 0.00 °C
Time,Temperature,Heat Flow (Normalized)
min,°C,W/g
39.01,190.11,-0.024
39.02,190.11,-0.024
39.03,190.11,-0.024
39.03,190.11,-0.024
39.04,190.11,-0.024
39.04,190.11,-0.024
39.05,190.10,-0.024
39.06,190.10,-0.025
39.06,190.09,-0.025
39.07,190.07,-0.025
39.08,190.06,-0.025
39.09,190.03,-0.026
39.09,190.01,-0.031
39.10,189.97,-0.035
39.11,189.94,-0.041
39.11,189.89,-0.049
39.12,189.85,-0.058
39.13,189.79,-0.071
39.13,189.73,-0.084
39.14,189.67,-0.101
39.14,189.61,-0.118
39.15,189.54,-0.137
39.16,189.46,-0.156
39.16,189.39,-0.176
39.17,189.31,-0.196
39.18,189.22,-0.216
39.19,189.14,-0.236
39.19,189.05,-0.256
39.20,188.97,-0.275
39.21,188.88,-0.293
39.21,188.78,-0.310
39.22,188.69,-0.327
39.23,188.59,-0.343
39.23,188.50,-0.358
39.24,188.40,-0.373
39.24,188.30,-0.387
39.25,188.20,-0.400
39.26,188.09,-0.413
39.26,187.99,-0.426
39.27,187.88,-0.437
39.28,187.78,-0.449
39.29,187.67,-0.460
39.29,187.56,-0.470
39.30,187.45,-0.481
39.31,187.34,-0.490
39.31,187.23,-0.499
39.32,187.12,-0.508
39.33,187.00,-0.517
39.33,186.89,-0.525
39.34,186.77,-0.532
39.34,186.66,-0.540
39.35,186.54,-0.546
39.36,186.43,-0.553
39.36,186.31,-0.560
39.37,186.19,-0.566
39.38,186.07,-0.572
39.39,185.95,-0.577
39.39,185.83,-0.582
39.40,185.71,-0.588
39.41,185.59,-0.592
39.41,185.47,-0.597
39.42,185.35,-0.601
39.43,185.22,-0.606
39.43,185.10,-0.610
39.44,184.98,-0.613
39.44,184.85,-0.617
39.45,184.73,-0.621
39.46,184.60,-0.624
39.46,184.48,-0.627
39.47,184.35,-0.630
39.48,184.23,-0.633
39.49,184.10,-0.636
39.49,183.98,-0.638
39.50,183.85,-0.640
39.51,183.73,-0.643
39.51,183.60,-0.645
39.52,183.47,-0.648
39.53,183.35,-0.650
39.53,183.22,-0.652
39.54,183.09,-0.654
39.54,182.96,-0.655
39.55,182.84,-0.657
39.56,182.71,-0.659
39.56,182.58,-0.661
39.57,182.45,-0.662
39.58,182.32,-0.663
39.59,182.19,-0.664
39.59,182.06,-0.666
39.60,181.93,-0.667
39.61,181.81,-0.668
39.61,181.68,-0.669
39.62,181.55,-0.670
39.63,181.42,-0.671
39.63,181.29,-0.672
39.64,181.16,-0.673
39.64,181.03,-0.674
39.65,180.90,-0.675
39.66,180.77,-0.675
39.66,180.64,-0.676
39.67,180.51,-0.677
39.68,180.38,-0.677
39.69,180.25,-0.678
39.69,180.12,-0.679
39.70,179.99,-0.679
39.71,179.86,-0.680
39.71,179.72,-0.680
39.72,179.59,-0.680
39.73,179.46,-0.681
39.73,179.33,-0.682
39.74,179.20,-0.682
39.74,179.07,-0.682
39.75,178.94,-0.683
39.76,178.81,-0.683
39.76,178.68,-0.683
39.77,178.55,-0.684
39.78,178.41,-0.684
39.79,178.28,-0.684
39.79,178.15,-0.684
39.80,178.02,-0.684
39.81,177.89,-0.685
39.81,177.76,-0.685
39.82,177.63,-0.685
39.83,177.49,-0.685
39.83,177.36,-0.685
39.84,177.23,-0.686
39.84,177.10,-0.686
39.85,176.97,-0.686
39.86,176.83,-0.686
39.86,176.70,-0.686
39.87,176.57,-0.686
39.88,176.44,-0.686
39.89,176.31,-0.687
39.89,176.18,-0.687
39.90,176.04,-0.687
39.91,175.91,-0.687
39.91,175.78,-0.687
39.92,175.65,-0.687
39.93,175.51,-0.687
39.93,175.38,-0.687
39.94,175.25,-0.687
39.94,175.12,-0.687
39.95,174.99,-0.687
39.96,174.85,-0.687
39.96,174.72,-0.687
39.97,174.59,-0.687
39.98,174.46,-0.687
39.99,174.33,-0.687
39.99,174.19,-0.687
40.00,174.06,-0.687
40.01,173.93,-0.687
40.01,173.80,-0.687
40.02,173.66,-0.687
40.03,173.53,-0.687
40.03,173.40,-0.687
40.04,173.27,-0.687
40.04,173.13,-0.687
40.05,173.00,-0.687
40.06,172.87,-0.687
40.06,172.74,-0.687
40.07,172.60,-0.687
40.08,172.47,-0.687
40.09,172.34,-0.687
40.09,172.21,-0.687
40.10,172.07,-0.687
40.11,171.94,-0.687
40.11,171.81,-0.687
40.12,171.68,-0.687
40.13,171.54,-0.687
40.13,171.41,-0.687
40.14,171.28,-0.687
40.14,171.15,-0.687
40.15,171.01,-0.687
40.16,170.88,-0.687
40.16,170.75,-0.687
40.17,170.62,-0.687
40.18,170.48,-0.687
40.19,170.35,-0.687
40.19,170.22,-0.687
40.20,170.09,-0.687
40.21,169.95,-0.687
40.21,169.82,-0.687
40.22,169.69,-0.687
40.23,169.56,-0.687
40.23,169.42,-0.687
40.24,169.29,-0.687
40.24,169.16,-0.687
40.25,169.03,-0.687
40.26,168.89,-0.686
40.26,168.76,-0.686
40.27,168.63,-0.686
40.28,168.49,-0.686
40.29,168.36,-0.686
40.29,168.23,-0.686
40.30,168.09,-0.686
40.31,167.96,-0.686
40.31,167.83,-0.686
40.32,167.70,-0.686
40.33,167.56,-0.686
40.33,167.43,-0.686
40.34,167.30,-0.686
40.34,167.17,-0.686
40.35,167.03,-0.686
40.36,166.90,-0.686
40.36,166.77,-0.686
40.37,166.64,-0.685
40.38,166.50,-0.685
40.39,166.37,-0.685
40.39,166.24,-0.685
40.40,166.10,-0.685
40.41,165.97,-0.685
40.41,165.84,-0.685
40.42,165.71,-0.684
40.43,165.57,-0.684
40.43,165.44,-0.684
40.44,165.31,-0.684
40.44,165.18,-0.684
40.45,165.04,-0.684
40.46,164.91,-0.684
40.46,164.78,-0.684
40.47,164.64,-0.684
40.48,164.51,-0.684
40.49,164.38,-0.684
40.49,164.25,-0.684
40.50,164.11,-0.684
40.51,163.98,-0.684
40.51,163.85,-0.684
40.52,163.71,-0.684
40.53,163.58,-0.684
40.53,163.45,-0.683
40.54,163.31,-0.683
40.54,163.18,-0.683
40.55,163.05,-0.683
40.56,162.91,-0.683
40.56,162.78,-0.683
40.57,162.65,-0.683
40.58,162.52,-0.683
40.59,162.38,-0.682
40.59,162.25,-0.682
40.60,162.12,-0.682
40.61,161.99,-0.682
40.61,161.85,-0.682
40.62,161.72,-0.682
40.63,161.59,-0.682
40.63,161.45,-0.682
40.64,161.32,-0.682
40.64,161.19,-0.682
40.65,161.05,-0.682
40.66,160.92,-0.681
40.66,160.79,-0.681
40.67,160.66,-0.681
40.68,160.52,-0.681
40.69,160.39,-0.681
40.69,160.26,-0.681
40.70,160.12,-0.681
40.71,159.99,-0.681
40.71,159.86,-0.681
40.72,159.73,-0.680
40.73,159.59,-0.680
40.73,159.46,-0.680
40.74,159.33,-0.680
40.74,159.19,-0.680
40.75,159.06,-0.680
40.76,158.93,-0.680
40.76,158.80,-0.680
40.77,158.66,-0.680
40.78,158.53,-0.680
40.79,158.40,-0.680
40.79,158.26,-0.680
40.80,158.13,-0.679
40.81,158.00,-0.679
40.81,157.86,-0.679
40.82,157.73,-0.679
40.83,157.60,-0.679
40.83,157.47,-0.679
40.84,157.33,-0.679
40.84,157.20,-0.679
40.85,157.07,-0.679
40.86,156.93,-0.678
40.86,156.80,-0.678
40.87,156.67,-0.678
40.88,156.53,-0.678
40.89,156.40,-0.678
40.89,156.27,-0.678
40.90,156.14,-0.678
40.91,156.00,-0.678
40.91,155.87,-0.678
40.92,155.74,-0.678
40.93,155.60,-0.678
40.93,155.47,-0.678
40.94,155.34,-0.678
40.94,155.21,-0.678
40.95,155.07,-0.677
40.96,154.94,-0.677
40.96,154.81,-0.677
40.97,154.67,-0.677
40.98,154.54,-0.677
40.99,154.41,-0.677
40.99,154.28,-0.676
41.00,154.14,-0.676
41.01,154.01,-0.676
41.01,153.88,-0.676
41.02,153.74,-0.676
41.03,153.61,-0.676
41.03,153.48,-0.676
41.04,153.34,-0.676
41.04,153.21,-0.676
41.05,153.08,-0.676
41.06,152.95,-0.675
41.06,152.81,-0.675
41.07,152.68,-0.675
41.08,152.55,-0.675
41.09,152.41,-0.675
41.09,152.28,-0.675
41.10,152.15,-0.675
41.11,152.01,-0.675
41.11,151.88,-0.675
41.12,151.75,-0.675
41.13,151.62,-0.675
41.13,151.48,-0.675
41.14,151.35,-0.674
41.14,151.22,-0.674
41.15,151.08,-0.674
41.16,150.95,-0.674
41.16,150.82,-0.674
41.17,150.68,-0.674
41.18,150.55,-0.674
41.19,150.42,-0.674
41.19,150.28,-0.674
41.20,150.15,-0.674
41.21,150.02,-0.673
41.21,149.89,-0.673
41.22,149.75,-0.673
41.23,149.62,-0.673
41.23,149.49,-0.673
41.24,149.35,-0.673
41.24,149.22,-0.673
41.25,149.09,-0.673
41.26,148.95,-0.673
41.26,148.82,-0.673
41.27,148.69,-0.673
41.28,148.56,-0.672
41.29,148.42,-0.672
41.29,148.29,-0.672
41.30,148.16,-0.672
41.31,148.02,-0.672
41.31,147.89,-0.672
41.32,147.76,-0.672
41.33,147.62,-0.672
41.33,147.49,-0.671
41.34,147.36,-0.671
41.34,147.23,-0.671
41.35,147.09,-0.671
41.36,146.96,-0.671
41.36,146.83,-0.671
41.37,146.69,-0.671
41.38,146.56,-0.671
41.39,146.43,-0.671
41.39,146.29,-0.671
41.40,146.16,-0.671
41.41,146.03,-0.670
41.41,145.90,-0.670
41.42,145.76,-0.670
41.43,145.63,-0.670
41.43,145.50,-0.670
41.44,145.36,-0.670
41.44,145.23,-0.670
41.45,145.10,-0.670
41.46,144.97,-0.670
41.46,144.83,-0.670
41.47,144.70,-0.670
41.48,144.57,-0.669
41.49,144.43,-0.669
41.49,144.30,-0.669
41.50,144.17,-0.669
41.51,144.03,-0.669
41.51,143.90,-0.669
41.52,143.77,-0.669
41.53,143.63,-0.669
41.53,143.50,-0.669
41.54,143.37,-0.668
41.54,143.24,-0.668
41.55,143.10,-0.668
41.56,142.97,-0.668
41.56,142.84,-0.668
41.57,142.70,-0.668
41.58,142.57,-0.668
41.59,142.44,-0.668
41.59,142.31,-0.668
41.60,142.17,-0.668
41.61,142.04,-0.668
41.61,141.91,-0.667
41.62,141.77,-0.667
[...]
101.66,2.41,0.091
101.66,2.43,0.091
101.67,2.46,0.091
101.67,2.48,0.091
101.68,2.50,0.091
101.68,2.53,0.092
101.69,2.55,0.092
101.69,2.58,0.092
101.70,2.60,0.092
101.70,2.63,0.092
101.71,2.65,0.092
101.71,2.67,0.092
101.72,2.70,0.092
101.72,2.72,0.092
101.73,2.75,0.092
101.73,2.77,0.092
101.74,2.80,0.092
101.74,2.82,0.092
101.75,2.85,0.093
101.75,2.87,0.093
101.76,2.90,0.093
101.76,2.92,0.093
101.77,2.94,0.093
101.77,2.97,0.093
101.78,2.99,0.093
101.78,3.02,0.093
101.79,3.04,0.093
101.79,3.07,0.093
101.80,3.09,0.093
101.80,3.12,0.093
101.81,3.14,0.093
101.81,3.17,0.093
101.82,3.19,0.093
101.82,3.22,0.093
101.83,3.24,0.093
101.83,3.26,0.093
101.84,3.29,0.093
101.84,3.31,0.093
101.85,3.34,0.093
101.85,3.36,0.093
101.86,3.39,0.093
101.86,3.41,0.093
101.87,3.44,0.094
101.87,3.46,0.094
101.88,3.49,0.094
101.88,3.51,0.094
101.89,3.54,0.094
101.89,3.56,0.094
101.90,3.59,0.094
101.90,3.61,0.094
101.91,3.64,0.094
101.91,3.66,0.094
101.92,3.69,0.094
101.92,3.71,0.094
101.93,3.73,0.094
101.93,3.76,0.094
101.94,3.78,0.094
101.94,3.81,0.094
101.95,3.83,0.094
101.95,3.86,0.094
101.96,3.88,0.094
101.96,3.91,0.094
101.97,3.93,0.094
101.97,3.96,0.094
101.98,3.98,0.094
101.98,4.01,0.094
101.99,4.03,0.094
101.99,4.06,0.094
102.00,4.08,0.094
102.00,4.11,0.094
102.01,4.13,0.094
102.01,4.16,0.094
102.02,4.18,0.094
102.02,4.20,0.095
102.03,4.23,0.095
102.03,4.25,0.095
102.04,4.28,0.095
102.04,4.30,0.095
102.05,4.33,0.095
102.05,4.35,0.095
102.06,4.38,0.095
102.06,4.40,0.095
102.07,4.43,0.095
102.07,4.45,0.095
102.08,4.48,0.095
102.08,4.50,0.095
102.09,4.53,0.095
102.09,4.55,0.095
102.10,4.58,0.095
102.10,4.60,0.095
102.11,4.63,0.095
102.11,4.65,0.095
102.12,4.68,0.095
102.12,4.70,0.095
102.13,4.73,0.095
102.13,4.75,0.095
102.14,4.78,0.095
102.14,4.80,0.095
102.15,4.83,0.095
102.15,4.85,0.095
102.16,4.88,0.095
102.16,4.90,0.095
102.17,4.93,0.095
102.17,4.95,0.095
102.18,4.98,0.095
102.18,5.00,0.095
102.19,5.02,0.095
102.19,5.05,0.095
102.20,5.08,0.095
102.20,5.10,0.095
102.21,5.12,0.095
102.21,5.15,0.095
102.22,5.17,0.095
102.22,5.20,0.095
102.23,5.22,0.095
102.23,5.25,0.095
102.24,5.27,0.096
102.24,5.30,0.096
102.25,5.32,0.096
102.25,5.35,0.096
102.26,5.37,0.096
102.26,5.40,0.096
102.27,5.42,0.096
102.27,5.45,0.096
102.28,5.47,0.096
102.28,5.50,0.096
102.29,5.52,0.096
102.29,5.55,0.096
102.30,5.57,0.096
102.30,5.60,0.096
102.31,5.62,0.096
102.31,5.65,0.096
102.32,5.67,0.096
102.32,5.70,0.096
102.33,5.72,0.096
102.33,5.75,0.096
102.34,5.77,0.096
102.34,5.80,0.096
102.35,5.82,0.096
102.35,5.85,0.096
102.36,5.87,0.096
102.36,5.90,0.096
102.37,5.92,0.096
102.37,5.95,0.096
102.38,5.97,0.096
102.38,6.00,0.096
102.39,6.02,0.096
102.39,6.05,0.096
102.40,6.07,0.096
102.40,6.10,0.096
102.41,6.12,0.096
102.41,6.15,0.096
102.42,6.17,0.096
102.42,6.20,0.096
102.43,6.22,0.096
102.43,6.25,0.096
102.44,6.27,0.096
102.44,6.30,0.096
102.45,6.32,0.096
102.45,6.35,0.096
102.46,6.37,0.096
102.46,6.40,0.096
102.47,6.42,0.096
102.47,6.45,0.096
102.48,6.47,0.096
102.48,6.50,0.096
102.49,6.52,0.096
102.49,6.55,0.096
102.50,6.57,0.096
102.50,6.59,0.096
102.51,6.62,0.096
102.51,6.64,0.096
102.52,6.67,0.096
102.52,6.70,0.096
102.53,6.72,0.096
102.53,6.74,0.096
102.54,6.77,0.096
102.54,6.80,0.096
102.55,6.82,0.096
102.55,6.84,0.096
102.56,6.87,0.096
102.56,6.89,0.096
102.57,6.92,0.097
102.57,6.95,0.097
102.58,6.97,0.097
102.58,7.00,0.097
102.59,7.02,0.097
102.59,7.04,0.097
102.60,7.07,0.097
102.60,7.10,0.097
102.61,7.12,0.097
102.61,7.14,0.097
102.62,7.17,0.097
102.62,7.19,0.097
102.63,7.22,0.097
102.63,7.24,0.097
102.64,7.27,0.097
102.64,7.29,0.097
102.65,7.32,0.097
102.65,7.34,0.097
102.66,7.37,0.097
102.66,7.39,0.097
102.67,7.42,0.097
102.67,7.44,0.097
102.68,7.47,0.097
102.68,7.49,0.097
102.69,7.52,0.097
102.69,7.54,0.097
102.70,7.57,0.097
102.70,7.60,0.097
102.71,7.62,0.097
102.71,7.64,0.097
102.72,7.67,0.097
102.72,7.69,0.097
102.73,7.72,0.097
102.73,7.74,0.097
102.74,7.77,0.097
102.74,7.79,0.097
102.75,7.82,0.097
102.75,7.84,0.097
102.76,7.87,0.097
102.76,7.89,0.097
102.77,7.92,0.097
102.77,7.94,0.097
102.78,7.97,0.097
102.78,7.99,0.097
102.79,8.02,0.097
102.79,8.04,0.097
102.80,8.07,0.097
102.80,8.09,0.097
102.81,8.12,0.097
102.81,8.15,0.097
102.82,8.17,0.097
102.82,8.19,0.097
102.83,8.22,0.097
102.83,8.24,0.097
102.84,8.27,0.097
102.84,8.29,0.097
102.85,8.32,0.097
102.85,8.34,0.097
102.86,8.37,0.097
102.86,8.39,0.097
102.87,8.42,0.097
102.87,8.44,0.097
102.88,8.47,0.097
102.88,8.49,0.097
102.89,8.52,0.097
102.89,8.54,0.097
102.90,8.57,0.097
102.90,8.59,0.097
102.91,8.62,0.097
102.91,8.64,0.097
102.92,8.67,0.097
102.92,8.69,0.097
102.93,8.72,0.097
102.93,8.74,0.097
102.94,8.77,0.097
102.94,8.79,0.097
102.95,8.82,0.097
102.95,8.84,0.097
102.96,8.87,0.097
102.96,8.89,0.097
102.97,8.92,0.097
102.97,8.94,0.097
102.98,8.97,0.097
102.98,8.99,0.097
102.99,9.02,0.097
102.99,9.04,0.097
103.00,9.07,0.097
103.00,9.09,0.097
103.01,9.12,0.097
103.01,9.14,0.097
103.02,9.17,0.097
103.02,9.19,0.097
103.03,9.22,0.097
103.03,9.24,0.097
103.04,9.27,0.097
103.04,9.29,0.097
103.05,9.32,0.097
103.05,9.34,0.097
103.06,9.37,0.097
103.06,9.39,0.097
103.07,9.42,0.097
103.07,9.44,0.097
103.08,9.47,0.097
103.08,9.49,0.097
103.09,9.52,0.097
103.09,9.54,0.097
103.10,9.57,0.097
103.10,9.59,0.097
103.11,9.62,0.097
103.11,9.64,0.097
103.12,9.67,0.097
103.12,9.69,0.097
103.13,9.72,0.097
103.13,9.74,0.097
103.14,9.77,0.097
103.14,9.79,0.097
103.15,9.82,0.097
103.15,9.84,0.097
103.16,9.87,0.097
103.16,9.89,0.097
103.17,9.92,0.097
103.17,9.94,0.097
103.18,9.97,0.097
103.18,9.99,0.097
103.19,10.02,0.097
103.19,10.04,0.098
103.20,10.07,0.098
103.20,10.09,0.098
103.21,10.12,0.098
103.21,10.14,0.098
103.22,10.17,0.098
103.22,10.19,0.098
103.23,10.22,0.098
103.23,10.24,0.098
103.24,10.27,0.098
103.24,10.29,0.098
103.25,10.32,0.098
103.25,10.34,0.098
103.26,10.37,0.098
103.26,10.39,0.098
103.27,10.42,0.098
103.27,10.44,0.098
103.28,10.47,0.098
103.28,10.49,0.098
103.29,10.52,0.098
103.29,10.54,0.098
103.30,10.57,0.098
103.30,10.59,0.098
103.31,10.62,0.098
103.31,10.64,0.098
103.32,10.67,0.098
103.32,10.69,0.098
103.33,10.72,0.098
103.33,10.74,0.098
103.34,10.77,0.098
103.34,10.79,0.098
103.35,10.82,0.098
103.35,10.84,0.098
103.36,10.87,0.098
103.36,10.89,0.098
103.37,10.92,0.098
103.37,10.94,0.098
103.38,10.97,0.098
103.38,10.99,0.098
103.39,11.02,0.098
103.39,11.04,0.098
103.40,11.07,0.098
103.40,11.09,0.098
103.41,11.12,0.098
103.41,11.15,0.098
103.42,11.17,0.098
103.42,11.19,0.098
103.43,11.22,0.098
103.43,11.24,0.098
103.44,11.27,0.098
103.44,11.30,0.098
103.45,11.32,0.098
103.45,11.34,0.098
103.46,11.37,0.098
103.46,11.39,0.098
103.47,11.42,0.098
103.47,11.44,0.098
103.48,11.47,0.098
103.48,11.49,0.098
103.49,11.52,0.098
103.49,11.54,0.098
103.50,11.57,0.098
103.50,11.59,0.098
103.51,11.62,0.098
103.51,11.64,0.098
103.52,11.67,0.098
103.52,11.69,0.098
103.53,11.72,0.098
103.53,11.74,0.098
103.54,11.77,0.098
103.54,11.79,0.098
103.55,11.82,0.098
103.55,11.84,0.098
103.56,11.87,0.098
103.56,11.89,0.098
103.57,11.92,0.098
103.57,11.94,0.098
103.58,11.97,0.098
103.58,11.99,0.098
103.59,12.02,0.098
103.59,12.04,0.098
103.60,12.07,0.098
103.60,12.09,0.098
103.61,12.12,0.098
103.61,12.14,0.098
103.62,12.17,0.098
103.62,12.19,0.098
103.63,12.22,0.098
103.63,12.24,0.098
103.64,12.27,0.098
103.64,12.29,0.098
103.65,12.32,0.098
103.65,12.34,0.098
103.66,12.37,0.098
103.66,12.39,0.098
103.67,12.42,0.098
103.67,12.44,0.098
103.68,12.47,0.098
103.68,12.49,0.098
103.69,12.52,0.098
103.69,12.54,0.098
103.70,12.57,0.098
103.70,12.59,0.098
103.71,12.62,0.098
103.71,12.64,0.098
103.72,12.67,0.098
103.72,12.69,0.098
103.73,12.72,0.098
103.73,12.74,0.098
103.74,12.77,0.098
103.74,12.79,0.098
103.75,12.82,0.098
103.75,12.84,0.098
103.76,12.87,0.098
103.76,12.89,0.098
103.77,12.92,0.098
103.77,12.94,0.098
103.78,12.97,0.098
103.78,12.99,0.098
103.79,13.02,0.098
103.79,13.04,0.098
103.80,13.07,0.098
103.80,13.09,0.098
103.81,13.12,0.098
103.81,13.14,0.098
103.82,13.17,0.098
103.82,13.19,0.098
103.83,13.22,0.098
103.83,13.24,0.098
103.84,13.27,0.098
103.84,13.29,0.098
103.85,13.32,0.098
103.85,13.34,0.098
103.86,13.37,0.098
103.86,13.39,0.098
103.87,13.42,0.098
103.87,13.44,0.098
103.88,13.47,0.098
103.88,13.49,0.098
103.89,13.52,0.098
103.89,13.54,0.098
103.90,13.57,0.098
103.90,13.59,0.098
103.91,13.62,0.098
103.91,13.64,0.098
103.92,13.67,0.098
103.92,13.69,0.098
103.93,13.72,0.098
103.93,13.74,0.098
103.94,13.77,0.098
103.94,13.80,0.098
103.95,13.82,0.098
103.95,13.84,0.098
103.96,13.87,0.098
103.96,13.90,0.098
103.97,13.92,0.098
103.97,13.95,0.098
103.98,13.97,0.098
103.98,13.99,0.099
103.99,14.02,0.099
103.99,14.04,0.099
104.00,14.07,0.099
104.00,14.09,0.099
104.01,14.12,0.099
104.01,14.15,0.099
104.02,14.17,0.099
104.02,14.20,0.099
104.03,14.22,0.099
104.03,14.24,0.099
104.04,14.27,0.099
104.04,14.29,0.099
104.05,14.32,0.099
104.05,14.35,0.099
104.06,14.37,0.099
104.06,14.40,0.099
104.07,14.42,0.099
104.07,14.45,0.099
104.08,14.47,0.099
104.08,14.50,0.099
104.09,14.52,0.099
104.09,14.55,0.099
104.10,14.57,0.099
104.10,14.59,0.099
104.11,14.62,0.099
104.11,14.65,0.099
104.12,14.67,0.099
104.12,14.70,0.099
104.13,14.72,0.099
104.13,14.74,0.099
104.14,14.77,0.099
104.14,14.80,0.099
104.15,14.82,0.099
104.15,14.85,0.099
104.16,14.87,0.099
104.16,14.89,0.099
104.17,14.92,0.099
104.17,14.95,0.099
104.18,14.97,0.099
104.18,15.00,0.099
104.19,15.02,0.099
104.19,15.04,0.099
104.20,15.07,0.099
104.20,15.10,0.099
104.21,15.12,0.099
104.21,15.15,0.099
104.22,15.17,0.099
104.22,15.20,0.099
104.23,15.22,0.099
104.23,15.24,0.099
104.24,15.27,0.099
104.24,15.29,0.099
104.25,15.32,0.099
104.25,15.34,0.099
104.26,15.37,0.099
104.26,15.40,0.099
104.27,15.42,0.099
104.27,15.45,0.099
104.28,15.47,0.099
104.28,15.50,0.099
104.29,15.52,0.099
104.29,15.55,0.099
104.30,15.57,0.099
104.30,15.60,0.099
104.31,15.62,0.099
104.31,15.65,0.099
104.32,15.67,0.099
104.32,15.70,0.099
104.33,15.72,0.099
104.33,15.75,0.099
104.34,15.77,0.099
104.34,15.80,0.099
104.35,15.82,0.099
104.35,15.85,0.099
104.36,15.87,0.099
104.36,15.90,0.099
104.37,15.92,0.099
104.37,15.95,0.099
104.38,15.97,0.099
104.38,16.00,0.099
104.39,16.02,0.099
104.39,16.05,0.099
104.40,16.07,0.099
104.40,16.10,0.099
104.41,16.12,0.099
104.41,16.15,0.099
104.42,16.17,0.099
104.42,16.20,0.099
104.43,16.22,0.099
104.43,16.25,0.099
104.44,16.27,0.099
104.44,16.30,0.099
104.45,16.32,0.099
104.45,16.35,0.099
104.46,16.37,0.099
104.46,16.40,0.099
104.47,16.42,0.099
104.47,16.45,0.099
104.48,16.47,0.099
104.48,16.50,0.099
104.49,16.52,0.099
104.49,16.55,0.099
104.50,16.57,0.099
104.50,16.59,0.099
104.51,16.62,0.099
104.51,16.65,0.099
104.52,16.67,0.099
104.52,16.70,0.099
104.53,16.72,0.099
104.53,16.75,0.099
104.54,16.77,0.099
104.54,16.79,0.099
104.55,16.82,0.099
104.55,16.85,0.099
104.56,16.87,0.099
104.56,16.90,0.099
104.57,16.92,0.099
104.57,16.95,0.099
104.58,16.97,0.099
104.58,17.00,0.099
104.59,17.02,0.099
104.59,17.05,0.099
104.60,17.07,0.099
104.60,17.10,0.099
104.61,17.12,0.099
104.61,17.15,0.099
104.62,17.17,0.099
104.62,17.20,0.099
104.63,17.22,0.099
104.63,17.25,0.099
104.64,17.27,0.099
104.64,17.30,0.099
104.65,17.32,0.099
104.65,17.35,0.099
104.66,17.37,0.099
104.66,17.39,0.099
104.67,17.42,0.099
104.67,17.45,0.099
104.68,17.47,0.099
104.68,17.50,0.099
104.69,17.52,0.099
104.69,17.55,0.099
104.70,17.57,0.099
104.70,17.60,0.099
104.71,17.62,0.099
104.71,17.64,0.099
104.72,17.67,0.099
104.72,17.70,0.099
104.73,17.72,0.099
104.73,17.75,0.099
104.74,17.77,0.099
104.74,17.80,0.099
104.75,17.82,0.099
104.75,17.85,0.099
104.76,17.87,0.099
104.76,17.90,0.099
104.77,17.92,0.099
104.77,17.94,0.099
104.78,17.97,0.099
104.78,18.00,0.099
104.79,18.02,0.099
104.79,18.05,0.099
104.80,18.07,0.099
104.80,18.10,0.099
104.81,18.12,0.099
104.81,18.15,0.099
104.82,18.17,0.099
104.82,18.20,0.099
104.83,18.22,0.099
104.83,18.25,0.099
104.84,18.27,0.099
104.84,18.30,0.099
104.85,18.32,0.099
104.85,18.35,0.099
104.86,18.37,0.099
104.86,18.40,0.099
104.87,18.42,0.099
104.87,18.45,0.100
104.88,18.47,0.100
104.88,18.50,0.100
104.89,18.52,0.100
104.89,18.55,0.100
104.90,18.57,0.100
104.90,18.60,0.100
104.91,18.62,0.100
104.91,18.65,0.100
104.92,18.67,0.100
104.92,18.70,0.100
104.93,18.72,0.100
104.93,18.75,0.100
104.94,18.77,0.100
104.94,18.80,0.100
104.95,18.82,0.100
104.95,18.85,0.100
104.96,18.87,0.100
104.96,18.90,0.100
104.97,18.92,0.100
104.97,18.95,0.100
104.98,18.97,0.100
104.98,19.00,0.100
104.99,19.02,0.100
104.99,19.05,0.100
105.00,19.07,0.100
105.00,19.10,0.100
105.01,19.12,0.100
105.01,19.15,0.100
105.02,19.17,0.100
105.02,19.20,0.100
105.03,19.22,0.100
105.03,19.25,0.100
105.04,19.27,0.100
105.04,19.30,0.100
105.05,19.32,0.100
105.05,19.35,0.100
105.06,19.37,0.100
105.06,19.40,0.100
105.07,19.42,0.100
105.07,19.45,0.100
105.08,19.47,0.100
105.08,19.50,0.100
105.09,19.52,0.100
105.09,19.55,0.100
105.10,19.57,0.100
105.10,19.60,0.100
105.11,19.62,0.100
105.11,19.65,0.100
105.12,19.67,0.100
105.12,19.70,0.100
105.13,19.72,0.100
105.13,19.75,0.100
105.14,19.77,0.100
105.14,19.80,0.100
105.15,19.82,0.100
105.15,19.85,0.100
105.16,19.87,0.100
105.16,19.90,0.100
105.17,19.92,0.100
105.17,19.95,0.100
105.18,19.97,0.100
105.18,20.00,0.100
105.19,20.02,0.100
105.19,20.05,0.100
105.20,20.07,0.100
105.20,20.10,0.100
105.21,20.12,0.100
105.21,20.15,0.100
105.22,20.17,0.100
105.22,20.20,0.100
105.23,20.22,0.100
105.23,20.25,0.100
105.24,20.27,0.100
105.24,20.30,0.100
105.25,20.32,0.100
105.25,20.35,0.100
105.26,20.37,0.100
105.26,20.40,0.100
105.27,20.42,0.100
105.27,20.45,0.100
105.28,20.47,0.100
105.28,20.50,0.100
105.29,20.52,0.100
105.29,20.55,0.100
105.30,20.57,0.100
105.30,20.60,0.100
105.31,20.62,0.100
105.31,20.65,0.100
105.32,20.67,0.100
105.32,20.70,0.100
105.33,20.72,0.100
105.33,20.75,0.100
105.34,20.77,0.100
105.34,20.80,0.100
105.35,20.82,0.100
105.35,20.85,0.100
105.36,20.87,0.100
105.36,20.90,0.100
105.37,20.92,0.100
105.37,20.95,0.100
105.38,20.97,0.100
105.38,21.00,0.100
105.39,21.02,0.100
105.39,21.05,0.100
105.40,21.07,0.100
105.40,21.10,0.100
105.41,21.12,0.100
105.41,21.15,0.100
105.42,21.17,0.100
105.42,21.20,0.100
105.43,21.22,0.100
105.43,21.25,0.100
105.44,21.27,0.100
105.44,21.30,0.100
105.45,21.32,0.100
105.45,21.35,0.100
105.46,21.37,0.100
105.46,21.40,0.100
105.47,21.42,0.100
105.47,21.45,0.100
105.48,21.47,0.100
105.48,21.50,0.100
105.49,21.52,0.100
105.49,21.55,0.100
105.50,21.57,0.100
105.50,21.60,0.100
105.51,21.62,0.100
105.51,21.65,0.100
105.52,21.67,0.100
105.52,21.70,0.100
105.53,21.72,0.100
105.53,21.75,0.100
105.54,21.77,0.100
105.54,21.80,0.100
105.55,21.82,0.100
105.55,21.85,0.100
105.56,21.87,0.100
105.56,21.90,0.100
105.57,21.92,0.100
105.57,21.95,0.100
105.58,21.97,0.100
105.58,22.00,0.100
105.59,22.02,0.100
105.59,22.05,0.100
105.60,22.07,0.100
105.60,22.10,0.101
105.61,22.12,0.101
105.61,22.15,0.101
105.62,22.17,0.101
105.62,22.20,0.101
105.63,22.22,0.101
105.63,22.25,0.101
105.64,22.27,0.101
105.64,22.30,0.101
105.65,22.32,0.101
105.65,22.35,0.101
105.66,22.37,0.101
105.66,22.40,0.101
105.67,22.42,0.101
105.67,22.45,0.101
105.68,22.47,0.101
105.68,22.50,0.101
105.69,22.52,0.101
105.69,22.55,0.101
105.70,22.57,0.101
105.70,22.60,0.101
105.71,22.62,0.101
105.71,22.65,0.101
105.72,22.67,0.101
105.72,22.70,0.101
105.73,22.72,0.101
105.73,22.75,0.101
105.74,22.77,0.101
105.74,22.80,0.101
105.75,22.82,0.101
105.75,22.85,0.101
105.76,22.87,0.101
105.76,22.90,0.101
105.77,22.92,0.101
105.77,22.95,0.101
105.78,22.98,0.101
105.78,23.00,0.101
105.79,23.02,0.101
105.79,23.05,0.101
105.80,23.07,0.101
105.80,23.10,0.101
105.81,23.12,0.101
105.81,23.15,0.101
105.82,23.17,0.101
105.82,23.20,0.101
105.83,23.22,0.101
105.83,23.25,0.101
105.84,23.27,0.101
105.84,23.30,0.101
105.85,23.32,0.101
105.85,23.35,0.101
105.86,23.37,0.101
105.86,23.40,0.101
105.87,23.42,0.101
105.87,23.45,0.101
105.88,23.47,0.101
105.88,23.50,0.101
105.89,23.52,0.101
105.89,23.55,0.101
105.90,23.57,0.101
105.90,23.60,0.101
105.91,23.62,0.101
105.91,23.65,0.101
105.92,23.67,0.101
105.92,23.70,0.101
105.93,23.72,0.101
105.93,23.75,0.101
105.94,23.78,0.101
105.94,23.80,0.101
105.95,23.82,0.101
105.95,23.85,0.101
105.96,23.87,0.101
105.96,23.90,0.101
105.97,23.92,0.101
105.97,23.95,0.101
105.98,23.97,0.101
105.98,24.00,0.101
105.99,24.02,0.101
105.99,24.05,0.101
106.00,24.07,0.101
106.00,24.10,0.101
106.01,24.12,0.101
106.01,24.15,0.101
106.02,24.18,0.101
106.02,24.20,0.101
106.03,24.22,0.101
106.03,24.25,0.101
106.04,24.27,0.101
106.04,24.30,0.101
106.05,24.32,0.101
106.05,24.35,0.101
106.06,24.37,0.101
106.06,24.40,0.101
106.07,24.42,0.101
106.07,24.45,0.101
106.08,24.47,0.101
106.08,24.50,0.101
106.09,24.52,0.101
106.09,24.55,0.101
106.10,24.57,0.101
106.10,24.60,0.101
106.11,24.62,0.101
106.11,24.65,0.101
106.12,24.67,0.101
106.12,24.70,0.101
106.13,24.72,0.101
106.13,24.75,0.101
106.14,24.78,0.101
106.14,24.80,0.101
106.15,24.82,0.101
106.15,24.85,0.101
106.16,24.87,0.101
106.16,24.90,0.101
106.17,24.92,0.101
106.17,24.95,0.101
106.18,24.97,0.101
106.18,25.00,0.101
106.19,25.02,0.101
106.19,25.05,0.101
106.20,25.07,0.101
106.20,25.10,0.101
106.21,25.12,0.101
106.21,25.15,0.101
106.22,25.17,0.101
106.22,25.20,0.101
106.23,25.22,0.101
106.23,25.25,0.101
106.24,25.27,0.101
106.24,25.30,0.101
106.25,25.33,0.101
106.25,25.35,0.101
106.26,25.38,0.101
106.26,25.40,0.101
106.27,25.42,0.101
106.27,25.45,0.101
106.28,25.47,0.101
106.28,25.50,0.102
106.29,25.52,0.102
106.29,25.55,0.102
106.30,25.57,0.102
106.30,25.60,0.102
106.31,25.63,0.102
106.31,25.65,0.102
106.32,25.67,0.102
106.32,25.70,0.102
106.33,25.72,0.102
106.33,25.75,0.102
106.34,25.78,0.102
106.34,25.80,0.102
106.35,25.82,0.102
106.35,25.85,0.102
106.36,25.87,0.102
106.36,25.90,0.102
106.37,25.92,0.102
106.37,25.95,0.102
106.38,25.97,0.102
106.38,26.00,0.102
106.39,26.02,0.102
106.39,26.05,0.102
106.40,26.08,0.102
106.40,26.10,0.102
106.41,26.12,0.102
106.41,26.15,0.102
106.42,26.17,0.102
106.42,26.20,0.102
106.43,26.22,0.102
106.43,26.25,0.102
106.44,26.27,0.102
106.44,26.30,0.102
106.45,26.33,0.102
106.45,26.35,0.102
106.46,26.38,0.102
106.46,26.40,0.102
106.47,26.43,0.102
106.47,26.45,0.102
106.48,26.48,0.102
106.48,26.50,0.102
106.49,26.53,0.102
106.49,26.55,0.102
106.50,26.58,0.102
106.50,26.60,0.102
106.51,26.63,0.102
106.51,26.65,0.102
106.52,26.67,0.102
106.52,26.70,0.102
106.53,26.72,0.102
106.53,26.75,0.102
106.54,26.78,0.102
106.54,26.80,0.102
106.55,26.83,0.102
106.55,26.85,0.102
106.56,26.87,0.102
106.56,26.90,0.102
106.57,26.93,0.102
106.57,26.95,0.102
106.58,26.97,0.102
106.58,27.00,0.102
106.59,27.02,0.102
106.59,27.05,0.102
106.60,27.07,0.102
106.60,27.10,0.102
106.61,27.13,0.102
106.61,27.15,0.102
106.62,27.17,0.102
106.62,27.20,0.102
106.63,27.23,0.102
106.63,27.25,0.102
106.64,27.28,0.102
106.64,27.30,0.102
106.65,27.33,0.102
106.65,27.35,0.102
106.66,27.37,0.102
106.66,27.40,0.102
106.67,27.43,0.102
106.67,27.45,0.102
106.68,27.48,0.102
106.68,27.50,0.102
106.69,27.53,0.102
106.69,27.55,0.102
106.70,27.58,0.102
106.70,27.60,0.102
106.71,27.63,0.102
106.71,27.65,0.102
106.72,27.68,0.102
106.72,27.70,0.102
106.73,27.73,0.102
106.73,27.75,0.102
106.74,27.77,0.102
106.74,27.80,0.102
106.75,27.83,0.102
106.75,27.85,0.102
106.76,27.88,0.102
106.76,27.90,0.102
106.77,27.93,0.102
106.77,27.95,0.102
106.78,27.98,0.102
106.78,28.00,0.102
106.79,28.03,0.102
106.79,28.05,0.102
106.80,28.07,0.102
106.80,28.10,0.102
106.81,28.13,0.102
106.81,28.15,0.102
106.82,28.18,0.102
106.82,28.20,0.102
106.83,28.23,0.102
106.83,28.25,0.103
106.84,28.28,0.103
106.84,28.30,0.103
106.85,28.33,0.103
106.85,28.35,0.103
106.86,28.38,0.103
106.86,28.40,0.103
106.87,28.43,0.103
106.87,28.45,0.103
106.88,28.47,0.103
106.88,28.50,0.103
106.89,28.53,0.103
106.89,28.55,0.103
106.90,28.57,0.103
106.90,28.60,0.103
106.91,28.62,0.103
106.91,28.65,0.103
106.92,28.67,0.103
106.92,28.70,0.103
106.93,28.72,0.103
106.93,28.75,0.103
106.94,28.77,0.103
106.94,28.80,0.103
106.95,28.83,0.103
106.95,28.85,0.103
106.96,28.88,
106.96,28.90,
106.97,28.92,
106.97,28.95,
106.98,28.98,
106.98,29.00,
106.99,29.03,
106.99,29.05,
107.00,29.08,
107.00,29.10,
107.01,,
107.01,,