File: DSC/2025_07_01_L_PGA_n60_200_10C_min_x4.csv
Filename,2025_07_01_L_PGA_n60_200_10C_min_x4
Instrument name,DSC2A-00468 (192.168.1.100)
Operator,Gibbons
rundate,7/1/2025
Sample name,2025_07_01_L_PGA_n60_200_10C_min_x4
proceduresegments,Data Off ; Equilibrate -60.00 °C; Data On ; Ramp 10.00 °C/min to 200.00 °C; Data Off ; Isothermal 2.0 min; Data On ; Ramp 10.00 °C/min to -60.00 °C; Data Off ; Isothermal 2.0 min; Data On ; Ramp 10.00 °C/min to 200.00 °C; Data Off ; Isothermal 2.0 min; Data On ; Ramp 10.00 °C/min to -60.00 °C; Data Off ; Isothermal 2.0 min; Data On ; Ramp 10.00 °C/min to 200.00 °C; Data Off ; Isothermal 2.0 min; Data On ; Ramp 10.00 °C/min to -60.00 °C; Data Off ; Isothermal 2.0 min; Data On ; Ramp 10.00 °C/min to 30.00 °C
[File Parameters]
Run date,7/1/2025 9:54:14 PM
Trios version,5.1.1.46572
Original File Name,
Current File Name,D:\DSC2500\Gibbons\2025_07_01_L_PGA_n60_200_10C_min_x4.tri
[Procedure]
Procedure Name,L_PGA_n60_200_10C_min_x4
Sample Name,2025_07_01_L_PGA_n60_200_10C_min_x4
Sample Mass,6.35 mg
Reference Sample Mass,0 mg
Pan Mass,57.31 mg
Pan Number,14
Reference Pan Mass,57.15 mg
Reference Pan Number,28
Pan Type,Tzero Aluminum Hermetic
Comments,DSC Consumables Al Hermetically Sealed Pan. Y1 Tray (Google Sheet: DSC_Samples_Y1_Tray_June2025).
Project Name,Pharma - Cocrystals
Operator,Gibbons
Test,Custom
Unload Max Temperature,30
Unload Min Temperature,30
Load Max Temperature,30
Load Min Temperature,30
Stop on Gas Flow Error,Yes
[Signal List]
Signal #1,Time (min)
Signal #2,Temperature (°C)
Signal #3,Heat Flow (mW)
Signal #4,Delta T (µV)
Signal #5,Delta Tzero (µV)
Signal #6,Tzero Temperature (°C)
Signal #7,Cell Purge (mL/min)
Signal #8,Heater Temp (°C)
Signal #9,Power Delivered (W)
Signal #10,Reference Junction Temperature (°C)
Signal #11,Flange Temperature (°C)
Signal #12,Heat Flow Phase (rad)
Signal #13,Total Heat Capacity (J/°C)
Signal #14,Heat Capacity (J/°C)
[Configuration]
Company Name,ASU
Instrument Name,DSC2A-00468
Instrument Type,DSC2500
Serial Number,DSC2A-00468
IP,192.168.1.100
Location of Instrument,MRRC
DisplayType,Unknown
Sample Interval ,0.1 s/pt
Selected Heat Flow,T4P
Exotherm Direction,Down
Cell Serial,DRC2-00792
Lid Type,Standard
Cooler,RCS 90
Leave Cooler on at End of Sequence,On
Gas 2,Nitrogen
Gas Selected,Channel 1
Flow Rate,50 mL/min
Secondary Purge,On
Licensed Heat Flow,Heat Flow T4P
Modulation Licensed,Yes
[Versions]
Common IDD Version,1
Cortex Version,VER 2.10.2.31
Driver,5.0.0.6
GDM Version,1.0.3.3
TouchscreenVersion,1.0.0.16145
FEP Version,1.2.1.21
FEP Bootloader,2.0.0.5
AutoSampler Version,2.1.1.26
Auto Sampler Bootloader,2.0.0.5
FCM Version,1.1.0.3
FCM Bootloader,2.0.0.5
[Experiment Logs]
Experiment Log Entry # 1,Air Cool is off.
Experiment Log Entry # 3,Lid Close
Experiment Log Entry # 5,Data On set to 0
Experiment Log Entry # 7,Equilibrate Segment -60 (C) Started
Experiment Log Entry # 9,Data On set to 1
Experiment Log Entry # 11,Ramp Segment 10 C/min to 200 Started
Experiment Log Entry # 13,Data On set to 0
Experiment Log Entry # 15,Isothermal Segment 2 min started
Experiment Log Entry # 17,Data On set to 1
Experiment Log Entry # 19,Ramp Segment 10 C/min to -60 Started
Experiment Log Entry # 21,Data On set to 0
Experiment Log Entry # 23,Isothermal Segment 2 min started
Experiment Log Entry # 25,Data On set to 1
Experiment Log Entry # 27,Ramp Segment 10 C/min to 200 Started
Experiment Log Entry # 29,Data On set to 0
Experiment Log Entry # 31,Isothermal Segment 2 min started
Experiment Log Entry # 33,Data On set to 1
Experiment Log Entry # 35,Ramp Segment 10 C/min to -60 Started
Experiment Log Entry # 37,Data On set to 0
Experiment Log Entry # 39,Isothermal Segment 2 min started
Experiment Log Entry # 41,Data On set to 1
Experiment Log Entry # 43,Ramp Segment 10 C/min to 200 Started
Experiment Log Entry # 45,Data On set to 0
Experiment Log Entry # 47,Isothermal Segment 2 min started
Experiment Log Entry # 49,Data On set to 1
Experiment Log Entry # 51,Ramp Segment 10 C/min to -60 Started
Experiment Log Entry # 53,Data On set to 0
Experiment Log Entry # 55,Isothermal Segment 2 min started
Experiment Log Entry # 57,Data On set to 1
Experiment Log Entry # 59,Ramp Segment 10 C/min to 30 Started
[Method Log]
Method Log Entry # 1,Data Off
Method Log Entry # 2,Equilibrate -60 °C
Method Log Entry # 3,Data On
Method Log Entry # 4,(Ramp 1054744) Ramp 10 °C/minute to 200 °C
Method Log Entry # 5,Data Off
Method Log Entry # 6,Isothermal 2 minutes
Method Log Entry # 7,Data On
Method Log Entry # 8,(Ramp 1054748) Ramp 10 °C/minute to -60 °C
Method Log Entry # 9,Data Off
Method Log Entry # 10,Isothermal 2 minutes
Method Log Entry # 11,Data On
Method Log Entry # 12,(Ramp 1054752) Ramp 10 °C/minute to 200 °C
Method Log Entry # 13,Data Off
Method Log Entry # 14,Isothermal 2 minutes
Method Log Entry # 15,Data On
Method Log Entry # 16,(Ramp 1054756) Ramp 10 °C/minute to -60 °C
Method Log Entry # 17,Data Off
Method Log Entry # 18,Isothermal 2 minutes
Method Log Entry # 19,Data On
Method Log Entry # 20,(Ramp 1054760) Ramp 10 °C/minute to 200 °C
Method Log Entry # 21,Data Off
Method Log Entry # 22,Isothermal 2 minutes
Method Log Entry # 23,Data On
Method Log Entry # 24,(Ramp 1054764) Ramp 10 °C/minute to -60 °C
Method Log Entry # 25,Data Off
Method Log Entry # 26,Isothermal 2 minutes
Method Log Entry # 27,Data On
Method Log Entry # 28,(Ramp 1054768) Ramp 10 °C/minute to 30 °C
Cell Serial,DRC2-00792
[T1 Calibration]
Slope,-0.008529666
Offset,9.636258
Initial Temperature,98.23
GUID,f8bfdadc-4977-4fdf-ba6d-0ba9134940c3
[TZero Calibration]
Date Applied,11/29/2022 4:06:13 PM
Description,From -89.059 °C to 396.009 °C at 20.000°C/min
Gas Type,Nitrogen
Pan Type,None
Source Files 1,C:\Users\yargerlab\Desktop\DSC Data\General\TZero_calibration_11_29_22_2nd(2).tri
Source Files 2,C:\Users\yargerlab\Desktop\DSC Data\General\TZero_calibration_11_29_22_2nd(3).tri
Delta T Offset,13.05235
Delta T Slope,-0.007271007
Delta T0 Offset,-13.69128
Delta T0 Slope,0.06063341
[Temperature Calibration]
Date Applied,11/29/2022 7:12:28 PM
Description,From 106.590 °C to 186.590 °C at 10.000°C/min
Gas Type,Nitrogen
Pan Type,Tzero Aluminum Hermetic
Source Files 1,C:\Users\yargerlab\Desktop\DSC Data\General\Indium(6).tri
Measured 1,157.391
Known 1,156.598
[Cell Constant Calibration]
Date Applied,11/29/2022 7:12:29 PM
Description,From 106.590 °C to 186.590 °C at 10.000°C/min
Gas Type,Nitrogen
Pan Type,Tzero Aluminum Hermetic
Source Files 1,C:\Users\yargerlab\Desktop\DSC Data\General\Indium(6).tri
T4P KCell,1.006051
Onset Slope,63.26126 mW/°C
[Direct Cp Calibration]
Date Applied,11/30/2022 11:04:51 AM
Description,From -79.983 °C to 298.409 °C at 10.000°C/min
Gas Type,Nitrogen
Pan Type,Tzero Aluminum Hermetic
Source Files 1,C:\Users\yargerlab\Desktop\DSC Data\General\Sapphire_Heat_Capacity_11_30_22.tri
[Rev Cp Calibration]
Date Applied,11/30/2022 1:58:51 PM
Description,From -79.996 °C to 292.812 °C at 3.000°C/min
Gas Type,Nitrogen
Pan Type,Tzero Aluminum Hermetic
Source Files 1,C:\Users\yargerlab\Desktop\DSC Data\General\Sapphire_MDSC_Calibration_11_30_22.tri
[step]
Ramp 10.00 °C/min to 200.00 °C
Time,Temperature,Heat Flow (Normalized)
min,°C,W/g
0.00,-59.71,-0.045
0.02,-59.72,-0.043
0.04,-59.73,-0.039
0.05,-59.72,-0.037
0.07,-59.71,-0.035
0.09,-59.68,-0.034
0.11,-59.62,-0.030
0.13,-59.55,-0.019
0.15,-59.46,-0.005
0.16,-59.35,0.012
0.18,-59.23,0.030
0.20,-59.11,0.048
0.22,-58.97,0.065
0.24,-58.82,0.080
0.26,-58.67,0.094
0.28,-58.52,0.105
0.29,-58.36,0.116
0.31,-58.20,0.124
0.33,-58.03,0.131
0.35,-57.87,0.137
0.37,-57.70,0.143
0.39,-57.53,0.147
0.40,-57.36,0.150
0.42,-57.19,0.153
0.44,-57.02,0.158
0.46,-56.84,0.159
0.48,-56.67,0.161
0.50,-56.49,0.163
0.51,-56.32,0.164
0.53,-56.14,0.165
0.55,-55.96,0.167
0.57,-55.79,0.168
0.59,-55.61,0.168
0.60,-55.43,0.169
0.62,-55.25,0.170
0.64,-55.07,0.170
0.66,-54.89,0.171
0.68,-54.71,0.172
0.70,-54.53,0.172
0.72,-54.35,0.173
0.73,-54.17,0.173
0.75,-53.99,0.173
0.77,-53.81,0.173
0.79,-53.63,0.174
0.81,-53.45,0.174
0.83,-53.27,0.174
0.84,-53.09,0.175
0.86,-52.91,0.175
0.88,-52.73,0.175
0.90,-52.55,0.175
0.92,-52.36,0.176
0.93,-52.18,0.176
0.95,-52.00,0.176
0.97,-51.82,0.176
0.99,-51.64,0.176
1.01,-51.45,0.177
1.03,-51.27,0.177
1.05,-51.09,0.177
1.06,-50.91,0.177
1.08,-50.73,0.177
1.10,-50.54,0.178
1.12,-50.36,0.178
1.14,-50.18,0.178
1.16,-50.00,0.178
1.17,-49.81,0.178
1.19,-49.63,0.178
1.21,-49.45,0.179
1.23,-49.27,0.179
1.25,-49.08,0.179
1.27,-48.90,0.179
1.28,-48.72,0.179
1.30,-48.53,0.179
1.32,-48.35,0.179
1.34,-48.17,0.180
1.36,-47.99,0.180
1.38,-47.80,0.180
1.39,-47.62,0.180
1.41,-47.44,0.180
1.43,-47.25,0.180
1.45,-47.07,0.180
1.47,-46.89,0.180
1.48,-46.70,0.180
1.50,-46.52,0.180
1.52,-46.34,0.181
1.54,-46.15,0.181
1.56,-45.97,0.181
1.58,-45.79,0.181
1.59,-45.61,0.181
1.61,-45.42,0.181
1.63,-45.24,0.181
1.65,-45.06,0.181
1.67,-44.87,0.181
1.69,-44.69,0.181
1.71,-44.51,0.181
1.72,-44.32,0.182
1.74,-44.14,0.182
1.76,-43.96,0.182
1.78,-43.77,0.182
1.80,-43.59,0.182
1.82,-43.41,0.182
1.83,-43.22,0.182
1.85,-43.04,0.182
1.87,-42.86,0.182
1.89,-42.67,0.182
1.91,-42.49,0.182
1.93,-42.31,0.182
1.94,-42.12,0.182
1.96,-41.94,0.182
1.98,-41.76,0.182
2.00,-41.57,0.183
2.02,-41.39,0.183
2.03,-41.21,0.183
2.05,-41.02,0.183
2.07,-40.84,0.183
2.09,-40.66,0.183
2.11,-40.47,0.183
2.13,-40.29,0.183
2.14,-40.10,0.183
2.16,-39.92,0.183
2.18,-39.74,0.183
2.20,-39.56,0.183
2.22,-39.37,0.183
2.24,-39.19,0.183
2.26,-39.00,0.184
2.27,-38.82,0.184
2.29,-38.64,0.184
2.31,-38.45,0.184
2.33,-38.27,0.184
2.35,-38.08,0.184
2.36,-37.90,0.184
2.38,-37.72,0.184
2.40,-37.53,0.184
2.42,-37.35,0.184
2.44,-37.17,0.184
2.46,-36.98,0.184
2.48,-36.80,0.184
2.49,-36.61,0.184
2.51,-36.43,0.184
2.53,-36.25,0.184
2.55,-36.06,0.185
2.57,-35.88,0.185
2.59,-35.70,0.185
2.60,-35.51,0.185
2.62,-35.33,0.185
2.64,-35.15,0.185
2.66,-34.96,0.185
2.68,-34.78,0.185
2.69,-34.60,0.185
2.71,-34.41,0.185
2.73,-34.23,0.185
2.75,-34.04,0.185
2.77,-33.86,0.185
2.79,-33.68,0.185
2.81,-33.49,0.185
2.82,-33.31,0.185
2.84,-33.13,0.185
2.86,-32.94,0.185
2.88,-32.76,0.186
2.90,-32.58,0.186
2.91,-32.39,0.186
2.93,-32.21,0.186
2.95,-32.03,0.186
2.97,-31.84,0.186
2.99,-31.66,0.186
3.01,-31.48,0.186
3.03,-31.29,0.186
3.04,-31.11,0.186
3.06,-30.92,0.186
3.08,-30.74,0.186
3.10,-30.56,0.186
3.12,-30.37,0.186
3.14,-30.19,0.186
3.15,-30.01,0.186
3.17,-29.82,0.186
3.19,-29.64,0.186
3.21,-29.45,0.187
3.23,-29.27,0.187
3.24,-29.09,0.187
3.26,-28.90,0.187
3.28,-28.72,0.187
3.30,-28.54,0.187
3.32,-28.35,0.187
3.34,-28.17,0.187
3.36,-27.98,0.187
3.37,-27.80,0.187
3.39,-27.62,0.187
3.41,-27.43,0.187
3.43,-27.25,0.188
3.45,-27.07,0.188
3.46,-26.88,0.188
3.48,-26.70,0.188
3.50,-26.52,0.188
3.52,-26.33,0.188
3.54,-26.15,0.188
3.56,-25.97,0.188
3.58,-25.78,0.188
3.59,-25.60,0.188
3.61,-25.41,0.188
3.63,-25.23,0.188
3.65,-25.05,0.188
3.67,-24.86,0.189
3.69,-24.68,0.189
3.70,-24.49,0.189
3.72,-24.31,0.189
3.74,-24.13,0.189
3.76,-23.95,0.189
3.78,-23.76,0.189
3.79,-23.58,0.189
3.81,-23.39,0.189
3.83,-23.21,0.189
3.85,-23.03,0.189
3.87,-22.84,0.189
3.89,-22.66,0.189
3.91,-22.48,0.189
3.92,-22.29,0.189
3.94,-22.11,0.190
3.96,-21.93,0.190
3.98,-21.74,0.190
4.00,-21.56,0.190
4.01,-21.37,0.190
4.03,-21.19,0.190
4.05,-21.01,0.190
4.07,-20.82,0.190
4.09,-20.64,0.190
4.11,-20.46,0.190
4.13,-20.27,0.190
4.14,-20.09,0.190
4.16,-19.91,0.190
4.18,-19.72,0.190
4.20,-19.54,0.190
4.22,-19.36,0.191
4.24,-19.17,0.191
4.25,-18.99,0.191
4.27,-18.81,0.191
4.29,-18.62,0.191
4.31,-18.44,0.191
4.33,-18.26,0.191
4.35,-18.07,0.191
4.36,-17.89,0.191
4.38,-17.71,0.191
4.40,-17.52,0.191
4.42,-17.34,0.191
4.44,-17.16,0.191
4.45,-16.97,0.191
4.47,-16.79,0.192
4.49,-16.60,0.192
4.51,-16.42,0.192
4.53,-16.24,0.192
4.55,-16.05,0.192
4.56,-15.87,0.192
4.58,-15.69,0.192
4.60,-15.50,0.192
4.62,-15.32,0.192
4.64,-15.14,0.192
4.66,-14.95,0.192
4.68,-14.77,0.192
4.69,-14.58,0.193
4.71,-14.40,0.193
4.73,-14.22,0.193
4.75,-14.03,0.193
4.77,-13.85,0.193
4.79,-13.67,0.193
4.80,-13.48,0.193
4.82,-13.30,0.193
4.84,-13.11,0.193
4.86,-12.93,0.193
4.88,-12.75,0.193
4.90,-12.56,0.193
4.91,-12.38,0.194
4.93,-12.19,0.194
4.95,-12.01,0.194
4.97,-11.83,0.194
4.99,-11.64,0.194
5.00,-11.46,0.194
5.02,-11.28,0.194
5.04,-11.10,0.194
5.06,-10.91,0.194
5.08,-10.73,0.194
5.10,-10.55,0.194
5.11,-10.36,0.194
5.13,-10.18,0.194
5.15,-10.00,0.195
5.17,-9.81,0.195
5.19,-9.63,0.195
5.21,-9.45,0.195
5.23,-9.26,0.195
5.24,-9.08,0.195
5.26,-8.90,0.195
5.28,-8.71,0.195
5.30,-8.53,0.195
5.32,-8.34,0.195
5.34,-8.16,0.195
5.35,-7.98,0.195
5.37,-7.79,0.195
5.39,-7.61,0.196
5.41,-7.43,0.196
5.43,-7.24,0.196
5.45,-7.06,0.196
5.46,-6.87,0.196
5.48,-6.69,0.196
5.50,-6.51,0.196
5.52,-6.32,0.196
5.54,-6.14,0.196
5.55,-5.96,0.196
5.57,-5.77,0.196
5.59,-5.59,0.196
5.61,-5.41,0.196
5.63,-5.22,0.197
5.65,-5.04,0.197
5.66,-4.86,0.197
5.68,-4.67,0.197
5.70,-4.49,0.197
5.72,-4.30,0.197
5.74,-4.12,0.197
5.76,-3.94,0.197
5.78,-3.75,0.197
5.79,-3.57,0.197
5.81,-3.39,0.198
5.83,-3.20,0.198
5.85,-3.02,0.198
5.87,-2.83,0.198
5.89,-2.65,0.198
5.90,-2.47,0.198
5.92,-2.28,0.198
5.94,-2.10,0.198
5.96,-1.92,0.199
5.98,-1.73,0.199
6.00,-1.55,0.199
6.01,-1.37,0.199
6.03,-1.18,0.199
6.05,-1.00,0.199
6.07,-0.82,0.199
6.09,-0.63,0.199
6.10,-0.45,0.199
6.12,-0.27,0.199
6.14,-0.08,0.199
6.16,0.10,0.200
6.18,0.28,0.200
6.20,0.47,0.200
6.21,0.65,0.200
6.23,0.84,0.200
6.25,1.02,0.200
6.27,1.20,0.200
6.29,1.39,0.201
6.31,1.57,0.201
6.33,1.75,0.201
6.34,1.94,0.201
6.36,2.12,0.201
6.38,2.30,0.201
6.40,2.49,0.201
6.42,2.67,0.201
6.44,2.86,0.201
6.45,3.04,0.201
6.47,3.22,0.201
6.49,3.41,0.201
6.51,3.59,0.202
6.53,3.78,0.202
6.55,3.96,0.202
6.56,4.14,0.202
6.58,4.33,0.202
6.60,4.51,0.202
6.62,4.69,0.202
6.64,4.88,0.202
6.65,5.06,0.203
6.67,5.24,0.203
6.69,5.43,0.203
6.71,5.61,0.203
6.73,5.79,0.203
6.75,5.98,0.203
6.76,6.16,0.203
6.78,6.34,0.203
6.80,6.53,0.203
6.82,6.71,0.203
6.84,6.89,0.204
6.86,7.08,0.204
6.88,7.26,0.204
6.89,7.45,0.204
6.91,7.63,0.204
6.93,7.81,0.204
6.95,7.99,0.204
6.97,8.18,0.204
6.99,8.36,0.204
7.00,8.55,0.204
7.02,8.73,0.205
7.04,8.91,0.205
7.06,9.10,0.205
7.08,9.28,0.205
7.10,9.47,0.205
7.11,9.65,0.205
7.13,9.83,0.205
7.15,10.02,0.205
7.17,10.20,0.206
7.19,10.38,0.206
7.20,10.57,0.206
7.22,10.75,0.206
7.24,10.93,0.206
7.26,11.12,0.206
7.28,11.30,0.206
7.30,11.48,0.206
7.31,11.67,0.206
7.33,11.85,0.207
7.35,12.04,0.207
7.37,12.22,0.207
7.39,12.40,0.207
7.41,12.59,0.207
7.43,12.77,0.207
7.44,12.95,0.207
7.46,13.14,0.207
7.48,13.32,0.207
7.50,13.50,0.208
7.52,13.69,0.208
7.54,13.87,0.208
7.55,14.05,0.208
7.57,14.24,0.208
7.59,14.42,0.208
7.61,14.61,0.208
7.63,14.79,0.208
7.65,14.97,0.208
7.66,15.15,0.208
7.68,15.34,0.209
7.70,15.52,0.209
7.72,15.71,0.209
7.74,15.89,0.209
7.75,16.07,0.209
7.77,16.26,0.209
7.79,16.44,0.209
7.81,16.62,0.209
7.83,16.81,0.210
7.85,16.99,0.210
7.86,17.17,0.210
7.88,17.36,0.210
7.90,17.54,0.210
7.92,17.72,0.210
7.94,17.91,0.210
7.96,18.09,0.210
7.98,18.27,0.211
7.99,18.46,0.211
8.01,18.64,0.211
8.03,18.82,0.211
8.05,19.01,0.211
8.07,19.19,0.211
8.09,19.38,0.211
8.10,19.56,0.212
8.12,19.74,0.212
8.14,19.93,0.212
8.16,20.11,0.212
8.18,20.29,0.212
8.20,20.48,0.212
8.21,20.66,0.212
8.23,20.84,0.213
8.25,21.03,0.213
8.27,21.21,0.213
8.29,21.39,0.213
8.30,21.58,0.213
8.32,21.76,0.213
8.34,21.94,0.213
8.36,22.13,0.213
8.38,22.31,0.214
8.40,22.49,0.214
8.41,22.68,0.214
8.43,22.86,0.214
8.45,23.05,0.214
8.47,23.23,0.214
8.49,23.41,0.214
8.51,23.60,0.214
8.53,23.78,0.215
8.54,23.96,0.215
8.56,24.15,0.215
8.58,24.33,0.215
8.60,24.51,0.215
8.62,24.70,0.215
8.63,24.88,0.215
8.65,25.06,0.216
8.67,25.25,0.216
8.69,25.43,0.216
8.71,25.61,0.216
8.73,25.80,0.216
8.75,25.98,0.216
8.76,26.17,0.216
8.78,26.35,0.216
8.80,26.53,0.217
8.82,26.72,0.217
8.84,26.90,0.217
8.85,27.08,0.217
8.87,27.27,0.217
8.89,27.45,0.217
8.91,27.63,0.217
8.93,27.82,0.218
8.95,28.00,0.218
8.97,28.18,0.218
8.98,28.37,0.218
9.00,28.55,0.218
9.02,28.73,0.218
9.04,28.92,0.219
9.06,29.10,0.219
9.08,29.28,0.219
9.09,29.47,0.219
9.11,29.65,0.219
9.13,29.83,0.219
9.15,30.02,0.219
9.17,30.20,0.220
9.18,30.39,0.220
9.20,30.57,0.220
9.22,30.75,0.220
9.24,30.94,0.220
9.26,31.12,0.220
9.28,31.30,0.220
9.30,31.49,0.221
9.31,31.67,0.221
9.33,31.85,0.221
9.35,32.04,0.221
9.37,32.22,0.221
9.39,32.41,0.221
9.40,32.59,0.221
9.42,32.77,0.222
9.44,32.95,0.222
9.46,33.14,0.222
9.48,33.32,0.222
9.50,33.51,0.222
9.52,33.69,0.222
9.53,33.87,0.222
9.55,34.05,0.223
9.57,34.24,0.223
9.59,34.42,0.223
9.61,34.61,0.223
9.63,34.79,0.223
9.64,34.97,0.223
9.66,35.16,0.223
9.68,35.34,0.224
9.70,35.52,0.224
9.72,35.71,0.224
9.73,35.89,0.224
9.75,36.08,0.224
9.77,36.26,0.224
9.79,36.44,0.224
9.81,36.63,0.224
9.83,36.81,0.224
9.85,36.99,0.225
9.86,37.18,0.225
9.88,37.36,0.225
9.90,37.54,0.225
9.92,37.73,0.225
9.94,37.91,0.225
9.95,38.09,0.226
9.97,38.28,0.226
9.99,38.46,0.226
10.01,38.65,0.226
10.03,38.83,0.226
10.05,39.01,0.226
10.07,39.20,0.226
10.08,39.38,0.226
10.10,39.56,0.227
10.12,39.75,0.227
10.14,39.93,0.227
10.16,40.11,0.227
10.18,40.30,0.227
10.19,40.48,0.227
10.21,40.66,0.227
10.23,40.85,0.227
10.25,41.03,0.227
10.27,41.21,0.228
10.28,41.40,0.228
10.30,41.58,0.228
10.32,41.76,0.228
10.34,41.95,0.228
10.36,42.13,0.228
10.38,42.32,0.228
10.40,42.50,0.229
10.41,42.68,0.229
10.43,42.87,0.229
10.45,43.05,0.229
10.47,43.23,0.229
10.49,43.42,0.229
10.50,43.60,0.229
10.52,43.79,0.230
10.54,43.97,0.230
10.56,44.15,0.230
10.58,44.34,0.230
10.60,44.52,0.230
10.62,44.70,0.230
10.63,44.89,0.231
10.65,45.07,0.231
10.67,45.25,0.231
10.69,45.44,0.231
10.71,45.62,0.231
10.73,45.80,0.231
10.74,45.99,0.231
10.76,46.17,0.231
10.78,46.35,0.232
10.80,46.54,0.232
10.82,46.72,0.232
10.83,46.91,0.232
10.85,47.09,0.232
10.87,47.27,0.232
10.89,47.46,0.232
10.91,47.64,0.233
10.93,47.82,0.233
10.95,48.01,0.233
10.96,48.19,0.233
10.98,48.37,0.233
11.00,48.56,0.233
11.02,48.74,0.233
11.04,48.92,0.234
11.05,49.11,0.234
11.07,49.29,0.234
11.09,49.47,0.234
11.11,49.66,0.234
11.13,49.84,0.234
11.15,50.03,0.235
11.17,50.21,0.235
11.18,50.39,0.235
11.20,50.58,0.235
11.22,50.76,0.235
11.24,50.94,0.235
11.26,51.13,0.235
11.28,51.31,0.236
11.29,51.49,0.236
11.31,51.68,0.236
11.33,51.86,0.236
11.35,52.04,0.236
11.37,52.23,0.236
11.38,52.41,0.236
11.40,52.59,0.237
11.42,52.78,0.237
11.44,52.96,0.237
11.46,53.14,0.237
11.48,53.33,0.237
11.50,53.51,0.237
11.51,53.69,0.238
11.53,53.88,0.238
11.55,54.06,0.238
11.57,54.24,0.238
11.59,54.43,0.238
11.60,54.61,0.238
11.62,54.80,0.238
11.64,54.98,0.239
11.66,55.16,0.239
11.68,55.35,0.239
11.70,55.53,0.239
11.72,55.71,0.239
11.73,55.90,0.239
11.75,56.08,0.240
11.77,56.26,0.240
11.79,56.45,0.240
11.81,56.63,0.240
11.83,56.81,0.240
11.84,57.00,0.240
11.86,57.18,0.241
11.88,57.36,0.241
11.90,57.55,0.241
11.92,57.73,0.241
11.93,57.92,0.241
11.95,58.10,0.242
11.97,58.28,0.242
11.99,58.47,0.242
12.01,58.65,0.242
12.03,58.83,0.242
12.05,59.02,0.242
12.06,59.20,0.243
12.08,59.38,0.243
12.10,59.57,0.243
12.12,59.75,0.243
12.14,59.93,0.243
12.15,60.12,0.244
12.17,60.30,0.244
12.19,60.48,0.244
12.21,60.67,0.244
12.23,60.85,0.244
12.25,61.03,0.245
12.27,61.22,0.245
12.28,61.40,0.245
12.30,61.59,0.245
12.32,61.77,0.245
12.34,61.95,0.246
12.36,62.14,0.246
12.38,62.32,0.246
12.39,62.50,0.246
12.41,62.69,0.247
12.43,62.87,0.247
12.45,63.05,0.247
12.47,63.23,0.248
12.48,63.42,0.248
12.50,63.60,0.253
12.52,63.78,0.263
12.54,63.97,0.266
12.56,64.15,0.269
12.58,64.33,0.308
12.60,64.51,0.350
12.61,64.68,0.338
12.63,64.86,0.377
12.65,65.03,0.458
12.67,65.19,0.516
12.69,65.36,0.570
12.70,65.52,0.600
12.72,65.69,0.608
12.74,65.87,0.562
12.76,66.05,0.520
12.78,66.23,0.548
12.80,66.42,0.482
12.82,66.61,0.427
12.83,66.81,0.378
12.85,67.01,0.346
12.87,67.20,0.322
12.89,67.40,0.308
12.91,67.59,0.294
12.93,67.79,0.286
12.94,67.98,0.279
12.96,68.17,0.273
12.98,68.35,0.266
13.00,68.54,0.262
13.02,68.73,0.259
13.03,68.92,0.256
13.05,69.10,0.253
13.07,69.29,0.251
13.09,69.47,0.250
13.11,69.66,0.248
13.13,69.84,0.248
13.15,70.03,0.247
13.16,70.21,0.247
13.18,70.40,0.245
13.20,70.58,0.245
13.22,70.77,0.245
13.24,70.95,0.244
13.25,71.14,0.244
13.27,71.32,0.244
13.29,71.50,0.244
13.31,71.69,0.244
13.33,71.87,0.244
13.35,72.05,0.243
13.37,72.24,0.243
13.38,72.42,0.243
13.40,72.60,0.243
13.42,72.79,0.243
13.44,72.97,0.243
13.46,73.15,0.243
13.48,73.34,0.243
13.49,73.52,0.243
13.51,73.71,0.242
13.53,73.89,0.242
13.55,74.07,0.242
13.57,74.25,0.242
13.58,74.44,0.242
13.60,74.62,0.242
13.62,74.81,0.242
13.64,74.99,0.242
13.66,75.17,0.242
13.68,75.36,0.243
13.70,75.54,0.243
13.71,75.73,0.243
13.73,75.91,0.243
13.75,76.09,0.243
13.77,76.28,0.243
13.79,76.46,0.243
13.80,76.64,0.243
13.82,76.83,0.243
13.84,77.01,0.243
13.86,77.19,0.243
13.88,77.37,0.243
13.90,77.56,0.243
13.92,77.74,0.243
13.93,77.92,0.243
13.95,78.11,0.243
13.97,78.29,0.244
13.99,78.48,0.244
14.01,78.66,0.244
14.03,78.84,0.244
14.04,79.03,0.244
14.06,79.21,0.244
14.08,79.39,0.244
14.10,79.58,0.244
14.12,79.76,0.244
14.13,79.94,0.245
14.15,80.13,0.245
14.17,80.31,0.245
14.19,80.49,0.245
14.21,80.68,0.245
14.23,80.86,0.245
14.25,81.04,0.245
14.26,81.23,0.245
14.28,81.41,0.245
14.30,81.59,0.245
14.32,81.78,0.245
14.34,81.96,0.246
14.35,82.14,0.246
14.37,82.33,0.246
14.39,82.51,0.246
14.41,82.70,0.246
14.43,82.88,0.246
14.45,83.06,0.246
14.47,83.25,0.246
14.48,83.43,0.246
14.50,83.61,0.246
14.52,83.80,0.246
14.54,83.98,0.247
14.56,84.16,0.247
14.58,84.35,0.247
14.59,84.53,0.247
14.61,84.72,0.247
14.63,84.90,0.247
14.65,85.08,0.247
14.67,85.27,0.247
14.68,85.45,0.247
14.70,85.63,0.247
14.72,85.82,0.247
14.74,86.00,0.248
14.76,86.18,0.248
14.78,86.37,0.248
14.80,86.55,0.248
14.81,86.73,0.248
14.83,86.92,0.248
14.85,87.10,0.248
14.87,87.28,0.248
14.89,87.47,0.248
14.90,87.65,0.249
14.92,87.83,0.249
14.94,88.02,0.249
14.96,88.20,0.249
14.98,88.38,0.249
15.00,88.57,0.249
15.02,88.75,0.249
15.03,88.93,0.249
15.05,89.12,0.249
15.07,89.30,0.249
15.09,89.49,0.250
15.11,89.67,0.250
15.13,89.85,0.250
15.14,90.04,0.250
15.16,90.22,0.250
15.18,90.40,0.250
15.20,90.59,0.251
15.22,90.77,0.251
15.23,90.95,0.251
15.25,91.14,0.251
15.27,91.32,0.251
15.29,91.50,0.251
15.31,91.69,0.251
15.33,91.87,0.251
15.35,92.05,0.252
15.36,92.24,0.252
15.38,92.42,0.252
15.40,92.60,0.252
15.42,92.79,0.252
15.44,92.97,0.252
15.45,93.15,0.252
15.47,93.34,0.253
15.49,93.52,0.253
15.51,93.71,0.253
15.53,93.89,0.253
15.55,94.07,0.253
15.57,94.26,0.253
15.58,94.44,0.253
15.60,94.62,0.253
15.62,94.81,0.254
15.64,94.99,0.254
15.66,95.17,0.254
15.68,95.36,0.254
15.69,95.54,0.254
15.71,95.72,0.254
15.73,95.91,0.254
15.75,96.09,0.254
15.77,96.27,0.255
15.78,96.46,0.255
15.80,96.64,0.255
15.82,96.82,0.255
15.84,97.01,0.255
15.86,97.19,0.255
15.88,97.37,0.255
15.90,97.56,0.256
15.91,97.74,0.256
15.93,97.93,0.256
15.95,98.11,0.256
15.97,98.29,0.256
15.99,98.48,0.256
16.00,98.66,0.256
16.02,98.84,0.256
16.04,99.03,0.257
16.06,99.21,0.257
16.08,99.39,0.257
16.10,99.58,0.257
16.12,99.76,0.257
16.13,99.94,0.257
16.15,100.13,0.257
16.17,100.31,0.258
16.19,100.50,0.258
16.21,100.68,0.258
16.23,100.86,0.258
16.24,101.04,0.258
16.26,101.23,0.258
16.28,101.41,0.258
16.30,101.60,0.258
16.32,101.78,0.259
16.33,101.96,0.259
16.35,102.15,0.259
16.37,102.33,0.259
16.39,102.51,0.259
16.41,102.70,0.259
16.43,102.88,0.260
16.45,103.06,0.260
16.46,103.25,0.260
16.48,103.43,0.260
16.50,103.61,0.260
16.52,103.80,0.260
16.54,103.98,0.260
16.55,104.16,0.261
16.57,104.35,0.261
16.59,104.53,0.261
16.61,104.71,0.261
16.63,104.90,0.261
16.65,105.08,0.261
16.67,105.27,0.261
16.68,105.45,0.261
16.70,105.63,0.262
16.72,105.82,0.262
16.74,106.00,0.262
16.76,106.18,0.262
16.78,106.37,0.262
16.79,106.55,0.262
16.81,106.73,0.262
16.83,106.92,0.263
16.85,107.10,0.263
16.87,107.28,0.263
16.88,107.47,0.263
16.90,107.65,0.263
16.92,107.83,0.263
16.94,108.02,0.264
16.96,108.20,0.264
16.98,108.38,0.264
17.00,108.57,0.264
17.01,108.75,0.264
17.03,108.93,0.264
17.05,109.12,0.264
17.07,109.30,0.265
17.09,109.49,0.265
17.11,109.67,0.265
17.12,109.85,0.265
17.14,110.04,0.265
17.16,110.22,0.266
17.18,110.40,0.266
17.20,110.59,0.266
17.22,110.77,0.266
17.23,110.95,0.266
17.25,111.14,0.266
17.27,111.32,0.267
17.29,111.50,0.267
17.31,111.69,0.267
17.33,111.87,0.267
17.34,112.06,0.267
17.36,112.24,0.268
17.38,112.43,0.268
17.40,112.61,0.268
17.42,112.80,0.268
17.43,112.98,0.268
17.45,113.16,0.269
17.47,113.35,0.269
17.49,113.53,0.269
17.51,113.71,0.269
17.53,113.90,0.269
17.54,114.08,0.269
17.56,114.26,0.269
17.58,114.45,0.269
17.60,114.63,0.269
17.62,114.81,0.269
17.64,114.99,0.269
17.66,115.18,0.269
17.67,115.36,0.270
17.69,115.55,0.270
17.71,115.73,0.270
17.73,115.91,0.270
17.75,116.09,0.270
17.77,116.28,0.270
17.78,116.46,0.270
17.80,116.65,0.270
17.82,116.83,0.270
17.84,117.01,0.270
17.86,117.19,0.270
17.88,117.38,0.270
17.89,117.56,0.271
17.91,117.75,0.271
17.93,117.93,0.271
17.95,118.11,0.271
17.97,118.29,0.271
17.98,118.48,0.271
18.00,118.66,0.271
18.02,118.84,0.271
18.04,119.03,0.271
18.06,119.21,0.271
18.08,119.39,0.272
18.09,119.58,0.272
18.11,119.76,0.272
18.13,119.95,0.272
18.15,120.13,0.272
18.17,120.31,0.272
18.19,120.49,0.272
18.21,120.68,0.273
18.22,120.86,0.273
18.24,121.04,0.273
18.26,121.23,0.273
18.28,121.41,0.273
18.30,121.59,0.273
18.32,121.78,0.273
18.33,121.96,0.274
18.35,122.15,0.274
18.37,122.33,0.274
18.39,122.51,0.274
18.41,122.70,0.274
18.43,122.88,0.274
18.44,123.06,0.275
18.46,123.25,0.275
18.48,123.43,0.275
18.50,123.61,0.275
18.52,123.80,0.275
18.53,123.98,0.276
18.55,124.16,0.276
18.57,124.35,0.276
18.59,124.53,0.276
18.61,124.71,0.276
18.63,124.90,0.276
18.64,125.08,0.277
18.66,125.26,0.277
18.68,125.45,0.277
18.70,125.63,0.277
18.72,125.81,0.277
18.74,126.00,0.277
18.76,126.18,0.278
18.77,126.36,0.278
18.79,126.55,0.278
18.81,126.73,0.278
18.83,126.91,0.278
18.85,127.10,0.279
18.87,127.28,0.279
18.88,127.47,0.279
18.90,127.65,0.279
18.92,127.83,0.279
18.94,128.02,0.280
18.96,128.20,0.280
18.98,128.38,0.280
18.99,128.57,0.280
19.01,128.75,0.280
19.03,128.93,0.280
19.05,129.12,0.281
19.07,129.30,0.281
19.08,129.48,0.281
19.10,129.67,0.281
19.12,129.85,0.281
19.14,130.03,0.282
19.16,130.22,0.282
19.18,130.40,0.282
19.19,130.58,0.282
19.21,130.77,0.283
19.23,130.95,0.283
19.25,131.13,0.283
19.27,131.32,0.283
19.29,131.50,0.283
19.31,131.69,0.283
19.32,131.87,0.284
19.34,132.05,0.284
19.36,132.23,0.284
19.38,132.42,0.284
19.40,132.60,0.285
19.42,132.79,0.285
19.43,132.97,0.285
19.45,133.15,0.285
19.47,133.34,0.286
19.49,133.52,0.286
19.51,133.70,0.286
19.53,133.89,0.286
19.54,134.07,0.286
19.56,134.25,0.287
19.58,134.44,0.287
19.60,134.62,0.287
19.62,134.80,0.287
19.63,134.99,0.288
19.65,135.17,0.288
19.67,135.35,0.288
19.69,135.54,0.288
19.71,135.72,0.289
19.73,135.90,0.289
19.74,136.08,0.289
19.76,136.27,0.289
19.78,136.45,0.290
19.80,136.63,0.290
19.82,136.82,0.290
19.84,137.00,0.291
19.86,137.19,0.291
19.87,137.37,0.291
19.89,137.55,0.291
19.91,137.74,0.292
19.93,137.92,0.292
19.95,138.10,0.292
19.97,138.29,0.293
19.98,138.47,0.293
20.00,138.65,0.294
20.02,138.84,0.294
20.04,139.02,0.294
20.06,139.20,0.295
20.08,139.39,0.295
20.09,139.57,0.295
20.11,139.75,0.296
20.13,139.94,0.296
20.15,140.12,0.297
20.17,140.30,0.297
20.18,140.49,0.297
20.20,140.67,0.298
20.22,140.85,0.299
20.24,141.04,0.299
20.26,141.22,0.300
20.28,141.40,0.300
20.29,141.59,0.301
20.31,141.77,0.301
20.33,141.95,0.301
20.35,142.14,0.302
20.37,142.32,0.302
20.39,142.50,0.303
20.41,142.69,0.303
20.42,142.87,0.304
20.44,143.05,0.304
20.46,143.24,0.305
20.48,143.42,0.306
20.50,143.60,0.306
20.52,143.79,0.307
20.53,143.97,0.307
20.55,144.15,0.308
20.57,144.34,0.310
20.59,144.52,0.310
20.61,144.70,0.311
20.63,144.88,0.311
20.64,145.07,0.311
20.66,145.25,0.313
20.68,145.44,0.314
20.70,145.62,0.315
20.72,145.80,0.316
20.73,145.99,0.317
20.75,146.17,0.317
20.77,146.35,0.319
20.79,146.53,0.319
20.81,146.72,0.320
20.83,146.90,0.321
20.84,147.09,0.322
20.86,147.27,0.323
20.88,147.45,0.324
20.90,147.64,0.325
20.92,147.82,0.325
20.94,148.00,0.326
20.96,148.18,0.327
20.97,148.37,0.328
20.99,148.55,0.329
21.01,148.73,0.330
21.03,148.91,0.330
21.05,149.10,0.332
21.07,149.28,0.333
21.08,149.47,0.334
21.10,149.65,0.336
21.12,149.83,0.337
21.14,150.02,0.338
21.16,150.20,0.340
21.18,150.38,0.341
21.19,150.56,0.343
21.21,150.75,0.344
21.23,150.93,0.346
21.25,151.11,0.349
21.27,151.30,0.350
21.28,151.48,0.353
21.30,151.66,0.355
21.32,151.84,0.357
21.34,152.03,0.359
21.36,152.21,0.360
21.38,152.39,0.362
21.39,152.58,0.365
21.41,152.76,0.367
21.43,152.94,0.370
21.45,153.12,0.373
21.47,153.30,0.376
21.49,153.49,0.379
21.51,153.67,0.382
21.52,153.85,0.387
21.54,154.04,0.391
21.56,154.22,0.394
21.58,154.40,0.399
21.60,154.58,0.404
21.62,154.76,0.408
21.63,154.95,0.414
21.65,155.13,0.420
21.67,155.31,0.427
21.69,155.49,0.434
21.71,155.67,0.441
21.73,155.85,0.448
21.74,156.03,0.457
21.76,156.21,0.465
21.78,156.40,0.475
21.80,156.58,0.485
21.82,156.76,0.498
21.83,156.94,0.511
21.85,157.11,0.524
21.87,157.29,0.540
21.89,157.47,0.556
21.91,157.65,0.574
21.93,157.83,0.595
21.94,158.00,0.618
21.96,158.18,0.642
21.98,158.36,0.668
22.00,158.53,0.697
22.02,158.70,0.731
22.04,158.87,0.767
22.06,159.05,0.806
22.07,159.22,0.854
22.09,159.38,0.909
22.11,159.55,0.957
22.13,159.72,1.022
22.15,159.88,1.089
22.17,160.04,1.175
22.18,160.20,1.272
22.20,160.35,1.378
22.22,160.50,1.490
22.24,160.65,1.623
22.26,160.79,1.768
22.28,160.93,1.914
22.29,161.06,2.072
22.31,161.19,2.266
22.33,161.31,2.465
22.35,161.43,2.677
22.37,161.54,2.903
22.38,161.65,3.140
22.40,161.75,3.417
22.42,161.84,3.694
22.44,161.93,3.968
22.46,162.02,4.262
22.48,162.10,4.522
22.49,162.18,4.828
22.51,162.26,5.138
22.53,162.33,5.491
22.55,162.40,5.841
22.57,162.47,6.112
22.59,162.55,6.235
22.61,162.65,6.271
22.62,162.78,6.189
22.64,162.96,5.773
22.66,163.20,5.250
22.68,163.48,4.815
22.70,163.78,4.321
22.72,164.10,3.773
22.73,164.45,3.161
22.75,164.82,2.586
22.77,165.19,2.105
22.79,165.55,1.694
22.81,165.90,1.385
22.83,166.23,1.196
22.84,166.53,1.049
22.86,166.81,0.932
22.88,167.07,0.834
22.90,167.32,0.752
22.92,167.55,0.688
22.93,167.78,0.633
22.95,168.00,0.585
22.97,168.22,0.549
22.99,168.42,0.519
23.01,168.63,0.492
23.03,168.83,0.472
23.04,169.02,0.455
23.06,169.22,0.441
23.08,169.41,0.430
23.10,169.60,0.420
23.12,169.79,0.413
23.14,169.98,0.406
23.16,170.17,0.402
23.17,170.36,0.397
23.19,170.54,0.394
23.21,170.73,0.392
23.23,170.91,0.390
23.25,171.10,0.388
23.27,171.28,0.387
23.28,171.47,0.386
23.30,171.65,0.384
23.32,171.84,0.384
23.34,172.02,0.383
23.36,172.20,0.383
23.38,172.39,0.382
23.39,172.57,0.382
23.41,172.75,0.382
23.43,172.94,0.382
23.45,173.12,0.382
23.47,173.30,0.381
23.48,173.49,0.381
23.50,173.67,0.381
23.52,173.85,0.381
23.54,174.04,0.381
23.56,174.22,0.381
23.58,174.41,0.381
23.59,174.59,0.381
23.61,174.77,0.381
23.63,174.95,0.381
23.65,175.14,0.381
23.67,175.32,0.381
23.69,175.51,0.381
23.71,175.69,0.381
23.72,175.87,0.381
23.74,176.06,0.381
23.76,176.24,0.381
23.78,176.42,0.381
23.80,176.61,0.381
23.82,176.79,0.381
23.83,176.97,0.381
23.85,177.16,0.381
23.87,177.34,0.381
23.89,177.52,0.381
23.91,177.71,0.381
23.93,177.89,0.382
23.94,178.07,0.382
23.96,178.26,0.382
23.98,178.44,0.382
24.00,178.63,0.382
24.02,178.81,0.382
24.03,178.99,0.382
24.05,179.18,0.382
24.07,179.36,0.382
24.09,179.54,0.382
24.11,179.73,0.382
24.13,179.91,0.382
24.14,180.09,0.382
24.16,180.27,0.383
24.18,180.46,0.383
24.20,180.64,0.383
24.22,180.82,0.383
24.24,181.01,0.383
24.26,181.19,0.383
24.27,181.38,0.383
24.29,181.56,0.383
24.31,181.74,0.383
24.33,181.93,0.383
24.35,182.11,0.384
24.37,182.29,0.384
24.38,182.48,0.384
24.40,182.66,0.384
24.42,182.85,0.384
24.44,183.03,0.384
24.46,183.21,0.384
24.48,183.39,0.384
24.49,183.58,0.384
24.51,183.76,0.385
24.53,183.94,0.385
24.55,184.13,0.385
24.57,184.31,0.385
24.58,184.49,0.385
24.60,184.68,0.385
24.62,184.86,0.385
24.64,185.04,0.385
24.66,185.23,0.385
24.68,185.41,0.385
24.69,185.59,0.385
24.71,185.78,0.386
24.73,185.96,0.386
24.75,186.15,0.386
24.77,186.33,0.386
24.79,186.51,0.386
24.81,186.69,0.386
24.82,186.88,0.386
24.84,187.06,0.386
24.86,187.25,0.386
24.88,187.43,0.386
24.90,187.61,0.386
24.92,187.80,0.387
24.93,187.98,0.387
24.95,188.16,0.387
24.97,188.35,0.387
24.99,188.53,0.387
25.01,188.71,0.387
25.03,188.90,0.387
25.04,189.08,0.387
25.06,189.26,0.387
25.08,189.45,0.387
25.10,189.63,0.387
25.12,189.81,0.387
25.13,190.00,0.388
25.15,190.18,0.388
25.17,190.37,0.388
25.19,190.55,0.388
25.21,190.73,0.388
25.23,190.91,0.388
25.24,191.10,0.388
25.26,191.28,0.388
25.28,191.47,0.388
25.30,191.65,0.388
25.32,191.83,0.388
25.34,192.02,0.389
25.36,192.20,0.389
25.37,192.38,0.389
25.39,192.57,0.389
25.41,192.75,0.389
25.43,192.93,0.389
25.45,193.12,0.389
25.47,193.30,0.389
25.48,193.48,0.389
25.50,193.67,0.389
25.52,193.85,0.389
25.54,194.03,0.389
25.56,194.22,0.389
25.58,194.40,0.389
25.59,194.58,0.389
25.61,194.77,0.389
25.63,194.95,0.389
25.65,195.13,0.390
25.67,195.32,0.390
25.68,195.50,0.390
25.70,195.69,0.390
25.72,195.87,0.390
25.74,196.05,0.390
25.76,196.24,0.390
25.78,196.42,0.390
25.79,196.60,0.390
25.81,196.79,0.390
25.83,196.97,0.390
25.85,197.15,0.391
25.87,197.34,0.391
25.89,197.52,0.391
25.91,197.70,0.391
25.92,197.89,0.391
25.94,198.07,
25.96,198.26,
25.98,198.44,
25.99,,

[step]
Ramp 10.00 °C/min to -60.00 °C
Time,Temperature,Heat Flow (Normalized)
min,°C,W/g
27.99,200.12,-0.043
28.01,200.12,-0.043
28.03,200.12,-0.043
28.05,200.11,-0.043
28.07,200.09,-0.045
28.08,200.05,-0.065
28.10,199.99,-0.093
28.12,199.92,-0.131
28.14,199.82,-0.177
28.16,199.71,-0.224
28.18,199.58,-0.265
28.19,199.44,-0.303
28.21,199.30,-0.334
28.23,199.14,-0.360
28.25,198.99,-0.379
28.27,198.83,-0.394
28.29,198.66,-0.408
28.31,198.49,-0.420
28.32,198.32,-0.429
28.34,198.15,-0.436
28.36,197.98,-0.443
28.38,197.80,-0.448
28.40,197.63,-0.452
28.42,197.45,-0.455
28.43,197.27,-0.458
28.45,197.09,-0.461
28.47,196.91,-0.463
28.49,196.74,-0.464
28.51,196.56,-0.465
28.53,196.38,-0.466
28.54,196.19,-0.467
28.56,196.02,-0.468
28.58,195.84,-0.469
28.60,195.65,-0.469
28.62,195.47,-0.469
28.63,195.29,-0.470
28.65,195.11,-0.470
28.67,194.93,-0.471
28.69,194.75,-0.471
28.71,194.57,-0.471
28.73,194.38,-0.472
28.74,194.20,-0.472
28.76,194.02,-0.472
28.78,193.84,-0.472
28.80,193.66,-0.472
28.82,193.47,-0.473
28.84,193.29,-0.473
28.86,193.11,-0.473
28.87,192.93,-0.473
28.89,192.75,-0.473
28.91,192.56,-0.473
28.93,192.38,-0.473
28.95,192.20,-0.474
28.97,192.02,-0.474
28.98,191.84,-0.474
29.00,191.65,-0.474
29.02,191.47,-0.474
29.04,191.29,-0.474
29.06,191.11,-0.474
29.08,190.92,-0.474
29.09,190.74,-0.474
29.11,190.56,-0.474
29.13,190.38,-0.474
29.15,190.19,-0.474
29.17,190.01,-0.474
29.18,189.83,-0.474
29.20,189.65,-0.474
29.22,189.46,-0.474
29.24,189.28,-0.474
29.26,189.10,-0.474
29.28,188.92,-0.474
29.29,188.73,-0.474
29.31,188.55,-0.474
29.33,188.37,-0.474
29.35,188.18,-0.474
29.37,188.00,-0.474
29.39,187.82,-0.474
29.41,187.64,-0.474
29.42,187.45,-0.474
29.44,187.27,-0.474
29.46,187.09,-0.474
29.48,186.90,-0.474
29.50,186.72,-0.474
29.52,186.54,-0.474
29.53,186.36,-0.474
29.55,186.17,-0.474
29.57,185.99,-0.473
29.59,185.81,-0.473
29.61,185.63,-0.473
29.63,185.44,-0.473
29.64,185.26,-0.473
29.66,185.08,-0.473
29.68,184.89,-0.473
29.70,184.71,-0.473
29.72,184.53,-0.473
29.73,184.34,-0.473
29.75,184.16,-0.473
29.77,183.98,-0.473
29.79,183.79,-0.472
29.81,183.61,-0.472
29.83,183.43,-0.472
29.84,183.24,-0.472
29.86,183.06,-0.472
29.88,182.88,-0.472
29.90,182.70,-0.472
29.92,182.51,-0.472
29.94,182.33,-0.471
29.96,182.15,-0.471
29.97,181.96,-0.471
29.99,181.78,-0.471
30.01,181.60,-0.471
30.03,181.41,-0.471
30.05,181.23,-0.471
30.07,181.05,-0.471
30.08,180.86,-0.470
30.10,180.68,-0.470
30.12,180.50,-0.470
30.14,180.31,-0.470
30.16,180.13,-0.470
30.18,179.95,-0.470
30.19,179.77,-0.470
30.21,179.58,-0.469
30.23,179.40,-0.469
30.25,179.22,-0.469
30.27,179.03,-0.469
30.28,178.85,-0.469
30.30,178.67,-0.469
30.32,178.48,-0.469
30.34,178.30,-0.468
30.36,178.12,-0.468
30.38,177.93,-0.468
30.39,177.75,-0.468
30.41,177.57,-0.468
30.43,177.38,-0.468
30.45,177.20,-0.468
30.47,177.02,-0.468
30.49,176.84,-0.468
30.51,176.65,-0.467
30.52,176.47,-0.467
30.54,176.29,-0.467
30.56,176.10,-0.467
30.58,175.92,-0.467
30.60,175.74,-0.466
30.62,175.56,-0.466
30.63,175.37,-0.466
30.65,175.19,-0.466
30.67,175.01,-0.466
30.69,174.82,-0.466
30.71,174.64,-0.466
30.73,174.46,-0.466
30.74,174.27,-0.465
30.76,174.09,-0.465
30.78,173.91,-0.465
30.80,173.72,-0.465
30.82,173.54,-0.465
30.83,173.36,-0.465
30.85,173.17,-0.465
30.87,172.99,-0.465
30.89,172.81,-0.464
30.91,172.62,-0.464
30.93,172.44,-0.464
30.94,172.26,-0.464
30.96,172.07,-0.464
30.98,171.89,-0.464
31.00,171.71,-0.464
31.02,171.52,-0.463
31.04,171.34,-0.463
31.06,171.16,-0.463
31.07,170.97,-0.463
31.09,170.79,-0.463
31.11,170.61,-0.463
31.13,170.42,-0.463
31.15,170.24,-0.462
31.17,170.06,-0.462
31.18,169.87,-0.462
31.20,169.69,-0.462
31.22,169.51,-0.462
31.24,169.33,-0.462
31.26,169.14,-0.462
31.28,168.96,-0.461
31.29,168.78,-0.461
31.31,168.59,-0.461
31.33,168.41,-0.461
31.35,168.23,-0.461
31.37,168.04,-0.461
31.38,167.86,-0.461
31.40,167.68,-0.460
31.42,167.49,-0.460
31.44,167.31,-0.460
31.46,167.13,-0.460
31.48,166.95,-0.460
31.49,166.76,-0.460
31.51,166.58,-0.459
31.53,166.40,-0.459
31.55,166.21,-0.459
31.57,166.03,-0.459
31.59,165.85,-0.459
31.61,165.66,-0.459
31.62,165.48,-0.459
31.64,165.30,-0.459
31.66,165.11,-0.458
31.68,164.93,-0.458
31.70,164.75,-0.458
31.72,164.56,-0.458
31.73,164.38,-0.458
31.75,164.20,-0.458
31.77,164.02,-0.457
31.79,163.83,-0.457
31.81,163.65,-0.457
31.83,163.47,-0.457
31.84,163.28,-0.457
31.86,163.10,-0.457
31.88,162.92,-0.457
31.90,162.73,-0.457
31.92,162.55,-0.456
31.93,162.37,-0.456
31.95,162.18,-0.456
31.97,162.00,-0.456
31.99,161.82,-0.456
32.01,161.63,-0.456
32.03,161.45,-0.456
32.04,161.27,-0.455
32.06,161.08,-0.455
32.08,160.90,-0.455
32.10,160.72,-0.455
32.12,160.53,-0.455
32.14,160.35,-0.455
32.16,160.17,-0.455
32.17,159.98,-0.455
32.19,159.80,-0.455
32.21,159.62,-0.454
32.23,159.43,-0.454
32.25,159.25,-0.454
32.27,159.07,-0.454
32.28,158.89,-0.454
32.30,158.70,-0.453
32.32,158.52,-0.454
32.34,158.34,-0.454
32.36,158.15,-0.454
32.38,157.97,-0.454
32.39,157.79,-0.454
32.41,157.60,-0.454
32.43,157.42,-0.453
32.45,157.24,-0.453
32.47,157.05,-0.453
32.48,156.87,-0.453
32.50,156.69,-0.453
32.52,156.50,-0.453
32.54,156.32,-0.453
32.56,156.14,-0.452
32.58,155.96,-0.452
32.59,155.77,-0.452
32.61,155.59,-0.452
32.63,155.41,-0.452
32.65,155.22,-0.451
32.67,155.04,-0.451
32.69,154.86,-0.451
32.71,154.67,-0.451
32.72,154.49,-0.451
32.74,154.31,-0.451
32.76,154.12,-0.451
32.78,153.94,-0.450
32.80,153.76,-0.450
32.82,153.57,-0.450
32.83,153.39,-0.450
32.85,153.21,-0.450
32.87,153.02,-0.450
32.89,152.84,-0.450
32.91,152.66,-0.450
32.93,152.48,-0.450
32.94,152.29,-0.449
32.96,152.11,-0.449
32.98,151.93,-0.449
33.00,151.74,-0.449
33.02,151.56,-0.449
33.03,151.38,-0.449
33.05,151.19,-0.449
33.07,151.01,-0.448
33.09,150.83,-0.448
33.11,150.64,-0.448
33.13,150.46,-0.448
33.14,150.28,-0.448
33.16,150.09,-0.448
33.18,149.91,-0.448
33.20,149.73,-0.448
33.22,149.54,-0.447
33.24,149.36,-0.447
33.26,149.18,-0.447
33.27,148.99,-0.447
33.29,148.81,-0.447
33.31,148.63,-0.447
33.33,148.45,-0.447
33.35,148.26,-0.446
33.37,148.08,-0.446
33.38,147.90,-0.446
33.40,147.71,-0.446
33.42,147.53,-0.446
33.44,147.35,-0.446
33.46,147.16,-0.446
33.48,146.98,-0.446
33.49,146.80,-0.446
33.51,146.61,-0.446
33.53,146.43,-0.445
33.55,146.25,-0.445
33.57,146.06,-0.445
33.58,145.88,-0.445
33.60,145.70,-0.445
33.62,145.51,-0.445
33.64,145.33,-0.445
33.66,145.15,-0.445
33.68,144.96,-0.445
33.69,144.78,-0.445
33.71,144.60,-0.445
33.73,144.41,-0.444
33.75,144.23,-0.444
33.77,144.05,-0.444
33.79,143.86,-0.444
33.81,143.68,-0.444
33.82,143.50,-0.444
33.84,143.32,-0.443
33.86,143.13,-0.443
33.88,142.95,-0.443
33.90,142.77,-0.443
33.92,142.58,-0.443
33.93,142.40,-0.443
33.95,142.22,-0.443
33.97,142.03,-0.442
33.99,141.85,-0.442
34.01,141.67,-0.442
34.03,141.48,-0.442
34.04,141.30,-0.442
34.06,141.12,-0.442
34.08,140.93,-0.442
34.10,140.75,-0.442
34.12,140.57,-0.442
34.14,140.38,-0.442
34.15,140.20,-0.442
34.17,140.02,-0.442
34.19,139.83,-0.441
34.21,139.65,-0.441
34.23,139.47,-0.441
34.24,139.28,-0.441
34.26,139.10,-0.441
34.28,138.92,-0.441
34.30,138.74,-0.440
34.32,138.55,-0.440
34.34,138.37,-0.440
34.36,138.19,-0.440
34.37,138.00,-0.440
34.39,137.82,-0.440
34.41,137.64,-0.440
[...]
170.07,-40.89,0.152
170.08,-40.82,0.152
170.09,-40.75,0.152
170.09,-40.69,0.152
170.10,-40.62,0.152
170.11,-40.55,0.152
170.11,-40.49,0.152
170.12,-40.42,0.152
170.13,-40.35,0.152
170.13,-40.29,0.152
170.14,-40.22,0.152
170.15,-40.15,0.152
170.15,-40.09,0.152
170.16,-40.02,0.152
170.17,-39.95,0.152
170.17,-39.88,0.152
170.18,-39.82,0.152
170.19,-39.75,0.152
170.19,-39.68,0.152
170.20,-39.62,0.152
170.21,-39.55,0.152
170.21,-39.49,0.152
170.22,-39.42,0.152
170.23,-39.35,0.153
170.23,-39.28,0.153
170.24,-39.22,0.153
170.25,-39.15,0.153
170.25,-39.08,0.153
170.26,-39.02,0.153
170.27,-38.95,0.153
170.27,-38.88,0.153
170.28,-38.82,0.153
170.29,-38.75,0.153
170.29,-38.68,0.153
170.30,-38.62,0.153
170.31,-38.55,0.153
170.31,-38.48,0.153
170.32,-38.42,0.153
170.33,-38.35,0.153
170.33,-38.28,0.153
170.34,-38.22,0.153
170.35,-38.15,0.153
170.35,-38.08,0.153
170.36,-38.02,0.153
170.37,-37.95,0.153
170.37,-37.88,0.153
170.38,-37.82,0.153
170.39,-37.75,0.153
170.39,-37.68,0.153
170.40,-37.62,0.153
170.41,-37.55,0.154
170.41,-37.48,0.154
170.42,-37.41,0.153
170.43,-37.35,0.154
170.43,-37.28,0.154
170.44,-37.22,0.154
170.45,-37.15,0.154
170.45,-37.08,0.154
170.46,-37.01,0.154
170.47,-36.95,0.154
170.47,-36.88,0.154
170.48,-36.82,0.154
170.49,-36.75,0.154
170.49,-36.68,0.154
170.50,-36.61,0.154
170.51,-36.55,0.154
170.51,-36.48,0.154
170.52,-36.41,0.154
170.53,-36.35,0.154
170.53,-36.28,0.154
170.54,-36.21,0.154
170.55,-36.15,0.154
170.55,-36.08,0.154
170.56,-36.02,0.154
170.57,-35.95,0.154
170.57,-35.88,0.154
170.58,-35.81,0.154
170.59,-35.75,0.154
170.59,-35.68,0.154
170.60,-35.61,0.155
170.61,-35.55,0.155
170.61,-35.48,0.155
170.62,-35.41,0.155
170.63,-35.35,0.155
170.63,-35.28,0.155
170.64,-35.21,0.155
170.65,-35.15,0.155
170.65,-35.08,0.155
170.66,-35.01,0.155
170.67,-34.95,0.155
170.67,-34.88,0.155
170.68,-34.81,0.155
170.69,-34.75,0.155
170.69,-34.68,0.155
170.70,-34.61,0.155
170.71,-34.55,0.155
170.71,-34.48,0.155
170.72,-34.41,0.155
170.73,-34.35,0.155
170.73,-34.28,0.155
170.74,-34.21,0.155
170.75,-34.15,0.155
170.75,-34.08,0.155
170.76,-34.01,0.155
170.77,-33.95,0.155
170.77,-33.88,0.155
170.78,-33.81,0.155
170.79,-33.75,0.155
170.79,-33.68,0.155
170.80,-33.61,0.156
170.81,-33.54,0.156
170.81,-33.48,0.156
170.82,-33.41,0.156
170.83,-33.35,0.156
170.83,-33.28,0.156
170.84,-33.21,0.156
170.85,-33.14,0.156
170.85,-33.08,0.156
170.86,-33.01,0.156
170.87,-32.94,0.156
170.87,-32.88,0.156
170.88,-32.81,0.156
170.89,-32.74,0.156
170.89,-32.68,0.156
170.90,-32.61,0.156
170.91,-32.54,0.156
170.91,-32.47,0.156
170.92,-32.41,0.156
170.93,-32.34,0.156
170.93,-32.28,0.156
170.94,-32.21,0.156
170.95,-32.14,0.156
170.95,-32.08,0.156
170.96,-32.01,0.157
170.97,-31.94,0.157
170.97,-31.87,0.157
170.98,-31.81,0.157
170.99,-31.74,0.157
170.99,-31.68,0.157
171.00,-31.61,0.157
171.01,-31.54,0.157
171.01,-31.47,0.157
171.02,-31.41,0.157
171.03,-31.34,0.157
171.03,-31.28,0.157
171.04,-31.21,0.157
171.05,-31.14,0.157
171.05,-31.07,0.157
171.06,-31.01,0.157
171.07,-30.94,0.157
171.07,-30.88,0.157
171.08,-30.81,0.157
171.09,-30.74,0.157
171.09,-30.67,0.157
171.10,-30.61,0.157
171.11,-30.54,0.157
171.11,-30.47,0.157
171.12,-30.41,0.157
171.13,-30.34,0.157
171.13,-30.27,0.157
171.14,-30.21,0.158
171.15,-30.14,0.158
171.15,-30.07,0.158
171.16,-30.01,0.158
171.17,-29.94,0.158
171.17,-29.87,0.158
171.18,-29.81,0.158
171.19,-29.74,0.158
171.19,-29.67,0.158
171.20,-29.61,0.158
171.21,-29.54,0.158
171.21,-29.47,0.158
171.22,-29.41,0.158
171.23,-29.34,0.158
171.23,-29.27,0.158
171.24,-29.20,0.158
171.25,-29.14,0.158
171.25,-29.07,0.158
171.26,-29.01,0.158
171.27,-28.94,0.158
171.27,-28.87,0.158
171.28,-28.80,0.158
171.29,-28.74,0.158
171.29,-28.67,0.159
171.30,-28.60,0.159
171.31,-28.54,0.159
171.31,-28.47,0.159
171.32,-28.40,0.159
171.33,-28.34,0.159
171.33,-28.27,0.159
171.34,-28.20,0.159
171.35,-28.14,0.159
171.35,-28.07,0.159
171.36,-28.00,0.159
171.37,-27.94,0.159
171.37,-27.87,0.159
171.38,-27.80,0.159
171.39,-27.74,0.159
171.39,-27.67,0.159
171.40,-27.60,0.159
171.41,-27.54,0.159
171.41,-27.47,0.159
171.42,-27.40,0.159
171.43,-27.33,0.159
171.43,-27.27,0.159
171.44,-27.20,0.159
171.45,-27.14,0.159
171.45,-27.07,0.159
171.46,-27.00,0.160
171.47,-26.93,0.160
171.47,-26.87,0.160
171.48,-26.80,0.160
171.49,-26.74,0.160
171.49,-26.67,0.160
171.50,-26.60,0.160
171.51,-26.54,0.160
171.51,-26.47,0.160
171.52,-26.40,0.160
171.53,-26.33,0.160
171.53,-26.27,0.160
171.54,-26.20,0.160
171.55,-26.14,0.160
171.55,-26.07,0.160
171.56,-26.00,0.160
171.57,-25.93,0.160
171.57,-25.87,0.160
171.58,-25.80,0.160
171.59,-25.73,0.160
171.59,-25.67,0.160
171.60,-25.60,0.160
171.61,-25.53,0.160
171.61,-25.47,0.160
171.62,-25.40,0.160
171.63,-25.33,0.161
171.63,-25.27,0.161
171.64,-25.20,0.161
171.65,-25.13,0.161
171.65,-25.07,0.161
171.66,-25.00,0.161
171.67,-24.93,0.161
171.67,-24.86,0.161
171.68,-24.80,0.161
171.69,-24.73,0.161
171.69,-24.66,0.161
171.70,-24.60,0.161
171.71,-24.53,0.161
171.71,-24.46,0.161
171.72,-24.40,0.161
171.73,-24.33,0.161
171.73,-24.26,0.161
171.74,-24.20,0.161
171.75,-24.13,0.161
171.75,-24.06,0.161
171.76,-24.00,0.161
171.77,-23.93,0.161
171.77,-23.86,0.162
171.78,-23.80,0.162
171.79,-23.73,0.162
171.79,-23.66,0.162
171.80,-23.60,0.162
171.81,-23.53,0.162
171.81,-23.46,0.162
171.82,-23.40,0.162
171.83,-23.33,0.162
171.83,-23.26,0.162
171.84,-23.20,0.162
171.85,-23.13,0.162
171.85,-23.06,0.162
171.86,-23.00,0.162
171.87,-22.93,0.162
171.87,-22.86,0.162
171.88,-22.80,0.162
171.89,-22.73,0.162
171.89,-22.66,0.162
171.90,-22.60,0.162
171.91,-22.53,0.163
171.91,-22.46,0.163
171.92,-22.40,0.163
171.93,-22.33,0.163
171.93,-22.26,0.163
171.94,-22.20,0.163
171.95,-22.13,0.163
171.95,-22.06,0.163
171.96,-22.00,0.163
171.97,-21.93,0.163
171.97,-21.86,0.163
171.98,-21.79,0.163
171.99,-21.73,0.163
171.99,-21.66,0.163
172.00,-21.59,0.163
172.01,-21.53,0.163
172.01,-21.46,0.163
172.02,-21.40,0.163
172.03,-21.33,0.163
172.03,-21.26,0.163
172.04,-21.19,0.163
172.05,-21.13,0.164
172.05,-21.06,0.164
172.06,-20.99,0.164
172.07,-20.93,0.164
172.07,-20.86,0.164
172.08,-20.79,0.164
172.09,-20.73,0.164
172.09,-20.66,0.164
172.10,-20.59,0.164
172.11,-20.53,0.164
172.11,-20.46,0.164
172.12,-20.39,0.164
172.13,-20.33,0.164
172.13,-20.26,0.164
172.14,-20.19,0.164
172.15,-20.13,0.164
172.15,-20.06,0.164
172.16,-19.99,0.164
172.17,-19.93,0.164
172.17,-19.86,0.164
172.18,-19.79,0.164
172.19,-19.72,0.164
172.19,-19.66,0.164
172.20,-19.59,0.165
172.21,-19.53,0.165
172.21,-19.46,0.165
172.22,-19.39,0.165
172.23,-19.33,0.165
172.23,-19.26,0.165
172.24,-19.19,0.165
172.25,-19.13,0.165
172.25,-19.06,0.165
172.26,-18.99,0.165
172.27,-18.93,0.165
172.27,-18.86,0.165
172.28,-18.79,0.165
172.29,-18.72,0.165
172.29,-18.66,0.165
172.30,-18.59,0.165
172.31,-18.53,0.165
172.31,-18.46,0.165
172.32,-18.39,0.165
172.33,-18.32,0.165
172.33,-18.26,0.165
172.34,-18.19,0.165
172.35,-18.12,0.165
172.35,-18.06,0.166
172.36,-17.99,0.166
172.37,-17.92,0.166
172.37,-17.86,0.166
172.38,-17.79,0.166
172.39,-17.72,0.166
172.39,-17.66,0.166
172.40,-17.59,0.166
172.41,-17.52,0.166
172.41,-17.46,0.166
172.42,-17.39,0.166
172.43,-17.32,0.166
172.43,-17.26,0.166
172.44,-17.19,0.166
172.45,-17.12,0.166
172.45,-17.06,0.166
172.46,-16.99,0.166
172.47,-16.92,0.166
172.47,-16.86,0.166
172.48,-16.79,0.167
172.49,-16.72,0.167
172.49,-16.66,0.167
172.50,-16.59,0.167
172.51,-16.52,0.167
172.51,-16.46,0.167
172.52,-16.39,0.167
172.53,-16.32,0.167
172.53,-16.25,0.167
172.54,-16.19,0.167
172.55,-16.12,0.167
172.55,-16.06,0.167
172.56,-15.99,0.167
172.57,-15.92,0.167
172.57,-15.85,0.167
172.58,-15.79,0.167
172.59,-15.72,0.167
172.59,-15.66,0.167
172.60,-15.59,0.167
172.61,-15.52,0.167
172.61,-15.45,0.167
172.62,-15.39,0.167
172.63,-15.32,0.167
172.63,-15.26,0.168
172.64,-15.19,0.168
172.65,-15.12,0.168
172.65,-15.06,0.168
172.66,-14.99,0.168
172.67,-14.92,0.168
172.67,-14.86,0.168
172.68,-14.79,0.168
172.69,-14.72,0.168
172.69,-14.65,0.168
172.70,-14.59,0.168
172.71,-14.52,0.168
172.71,-14.45,0.168
172.72,-14.39,0.168
172.73,-14.32,0.168
172.73,-14.25,0.168
172.74,-14.19,0.168
172.75,-14.12,0.168
172.75,-14.05,0.168
172.76,-13.99,0.169
172.77,-13.92,0.169
172.77,-13.85,0.169
172.78,-13.79,0.169
172.79,-13.72,0.169
172.79,-13.65,0.169
172.80,-13.59,0.169
172.81,-13.52,0.169
172.81,-13.45,0.169
172.82,-13.39,0.169
172.83,-13.32,0.169
172.83,-13.25,0.169
172.84,-13.19,0.169
172.85,-13.12,0.169
172.85,-13.05,0.169
172.86,-12.99,0.169
172.87,-12.92,0.169
172.87,-12.85,0.169
172.88,-12.79,0.169
172.89,-12.72,0.169
172.89,-12.65,0.169
172.90,-12.59,0.169
172.91,-12.52,0.170
172.91,-12.45,0.170
172.92,-12.38,0.170
172.93,-12.32,0.170
172.93,-12.25,0.170
172.94,-12.19,0.170
172.95,-12.12,0.170
172.95,-12.05,0.170
172.96,-11.99,0.170
172.97,-11.92,0.170
172.97,-11.85,0.170
172.98,-11.78,0.170
172.99,-11.72,0.170
172.99,-11.65,0.170
173.00,-11.59,0.170
173.01,-11.52,0.170
173.01,-11.45,0.170
173.02,-11.38,0.170
173.03,-11.32,0.171
173.03,-11.25,0.171
173.04,-11.18,0.171
173.05,-11.12,0.171
173.05,-11.05,0.171
173.06,-10.98,0.171
173.07,-10.92,0.171
173.07,-10.85,0.171
173.08,-10.78,0.171
173.09,-10.72,0.171
173.09,-10.65,0.171
173.10,-10.58,0.171
173.11,-10.52,0.171
173.11,-10.45,0.171
173.12,-10.38,0.171
173.13,-10.32,0.171
173.13,-10.25,0.171
173.14,-10.18,0.171
173.15,-10.12,0.172
173.15,-10.05,0.172
173.16,-9.98,0.172
173.17,-9.92,0.172
173.17,-9.85,0.172
173.18,-9.78,0.172
173.19,-9.72,0.172
173.19,-9.65,0.172
173.20,-9.58,0.172
173.21,-9.52,0.172
173.21,-9.45,0.172
173.22,-9.38,0.172
173.23,-9.32,0.172
173.23,-9.25,0.172
173.24,-9.18,0.172
173.25,-9.11,0.172
173.25,-9.05,0.172
173.26,-8.98,0.173
173.27,-8.92,0.173
173.27,-8.85,0.173
173.28,-8.78,0.173
173.29,-8.72,0.173
173.29,-8.65,0.173
173.30,-8.58,0.173
173.31,-8.51,0.173
173.31,-8.45,0.173
173.32,-8.38,0.173
173.33,-8.31,0.173
173.33,-8.25,0.173
173.34,-8.18,0.173
173.35,-8.11,0.173
173.35,-8.05,0.173
173.36,-7.98,0.173
173.37,-7.91,0.173
173.37,-7.85,0.173
173.38,-7.78,0.174
173.39,-7.71,0.174
173.39,-7.65,0.174
173.40,-7.58,0.174
173.41,-7.52,0.174
173.41,-7.45,0.174
173.42,-7.38,0.174
173.43,-7.31,0.174
173.43,-7.25,0.174
173.44,-7.18,0.174
173.45,-7.11,0.174
173.45,-7.05,0.174
173.46,-6.98,0.174
173.47,-6.91,0.174
173.47,-6.85,0.174
173.48,-6.78,0.174
173.49,-6.71,0.174
173.49,-6.65,0.174
173.50,-6.58,0.175
173.51,-6.51,0.175
173.51,-6.45,0.175
173.52,-6.38,0.175
173.53,-6.31,0.175
173.53,-6.25,0.175
173.54,-6.18,0.175
173.55,-6.11,0.175
173.55,-6.05,0.175
173.56,-5.98,0.175
173.57,-5.91,0.175
173.57,-5.85,0.175
173.58,-5.78,0.175
173.59,-5.71,0.175
173.59,-5.65,0.175
173.60,-5.58,0.175
173.61,-5.51,0.176
173.61,-5.45,0.176
173.62,-5.38,0.176
173.63,-5.31,0.176
173.63,-5.25,0.176
173.64,-5.18,0.176
173.65,-5.11,0.176
173.65,-5.05,0.176
173.66,-4.98,0.176
173.67,-4.91,0.176
173.67,-4.85,0.176
173.68,-4.78,0.176
173.69,-4.71,0.176
173.69,-4.65,0.177
173.70,-4.58,0.177
173.71,-4.51,0.177
173.71,-4.45,0.177
173.72,-4.38,0.177
173.73,-4.31,0.177
173.73,-4.24,0.177
173.74,-4.18,0.177
173.75,-4.11,0.177
173.75,-4.04,0.177
173.76,-3.98,0.177
173.77,-3.91,0.178
173.77,-3.84,0.178
173.78,-3.78,0.178
173.79,-3.71,0.178
173.79,-3.64,0.178
173.80,-3.58,0.178
173.81,-3.51,0.178
173.81,-3.44,0.178
173.82,-3.38,0.179
173.83,-3.31,0.179
173.83,-3.24,0.179
173.84,-3.18,0.179
173.85,-3.11,0.179
173.85,-3.04,0.179
173.86,-2.98,0.179
173.87,-2.91,0.179
173.87,-2.84,0.180
173.88,-2.78,0.180
173.89,-2.71,0.180
173.89,-2.64,0.180
173.90,-2.58,0.180
173.91,-2.51,0.180
173.91,-2.44,0.180
173.92,-2.38,0.180
173.93,-2.31,0.180
173.93,-2.24,0.181
173.94,-2.18,0.181
173.95,-2.11,0.181
173.95,-2.04,0.181
173.96,-1.98,0.181
173.97,-1.91,0.181
173.97,-1.84,0.181
173.98,-1.77,0.181
173.99,-1.71,0.181
173.99,-1.64,0.182
174.00,-1.58,0.182
174.01,-1.51,0.182
174.01,-1.44,0.182
174.02,-1.38,0.182
174.03,-1.31,0.182
174.03,-1.24,0.182
174.04,-1.18,0.182
174.05,-1.11,0.183
174.05,-1.04,0.183
174.06,-0.98,0.183
174.07,-0.91,0.183
174.07,-0.84,0.183
174.08,-0.78,0.183
174.09,-0.71,0.184
174.09,-0.64,0.184
174.10,-0.58,0.184
174.11,-0.51,0.184
174.11,-0.44,0.184
174.12,-0.38,0.184
174.13,-0.31,0.184
174.13,-0.24,0.185
174.14,-0.18,0.185
174.15,-0.11,0.185
174.15,-0.04,0.185
174.16,0.02,0.186
174.17,0.09,0.186
174.17,0.16,0.186
174.18,0.22,0.186
174.19,0.29,0.186
174.19,0.36,0.186
174.20,0.43,0.187
174.21,0.49,0.187
174.21,0.56,0.187
174.22,0.62,0.187
174.23,0.69,0.188
174.23,0.76,0.188
174.24,0.82,0.188
174.25,0.89,0.188
174.25,0.96,0.188
174.26,1.02,0.189
174.27,1.09,0.189
174.27,1.16,0.189
174.28,1.23,0.189
174.29,1.29,0.189
174.29,1.36,0.190
174.30,1.43,0.190
174.31,1.49,0.190
174.31,1.56,0.191
174.32,1.63,0.191
174.33,1.69,0.192
174.33,1.76,0.192
174.34,1.82,0.192
174.35,1.89,0.192
174.35,1.96,0.193
174.36,2.02,0.193
174.37,2.09,0.193
174.37,2.16,0.194
174.38,2.22,0.194
174.39,2.29,0.195
174.39,2.36,0.195
174.40,2.42,0.195
174.41,2.49,0.195
174.41,2.56,0.196
174.42,2.62,0.196
174.43,2.69,0.197
174.43,2.76,0.198
174.44,2.82,0.198
174.45,2.89,0.198
174.45,2.96,0.199
174.46,3.02,0.199
174.47,3.09,0.200
174.47,3.16,0.200
174.48,3.22,0.200
174.49,3.29,0.201
174.49,3.36,0.202
174.50,3.42,0.204
174.51,3.49,0.204
174.51,3.55,0.204
174.52,3.62,0.205
174.53,3.69,0.206
174.53,3.75,0.206
174.54,3.82,0.207
174.55,3.89,0.207
174.55,3.95,0.208
174.56,4.02,0.209
174.57,4.09,0.210
174.57,4.15,0.211
174.58,4.22,0.211
174.59,4.29,0.212
174.59,4.35,0.213
174.60,4.42,0.214
174.61,4.49,0.214
174.61,4.55,0.215
174.62,4.62,0.216
174.63,4.68,0.216
174.63,4.75,0.217
174.64,4.82,0.219
174.65,4.88,0.219
174.65,4.95,0.220
174.66,5.02,0.221
174.67,5.08,0.222
174.67,5.15,0.223
174.68,5.22,0.223
174.69,5.28,0.225
174.69,5.35,0.225
174.70,5.42,0.226
174.71,5.48,0.227
174.71,5.55,0.229
174.72,5.62,0.230
174.73,5.68,0.231
174.73,5.75,0.232
174.74,5.81,0.234
174.75,5.88,0.235
174.75,5.95,0.236
174.76,6.01,0.236
174.77,6.08,0.237
174.77,6.15,0.239
174.78,6.21,0.241
174.79,6.28,0.242
174.79,6.34,0.243
174.80,6.41,0.245
174.81,6.48,0.246
174.81,6.54,0.247
174.82,6.61,0.248
174.83,6.67,0.250
174.83,6.74,0.251
174.84,6.81,0.253
174.85,6.87,0.255
174.85,6.94,0.255
174.86,7.01,0.257
174.87,7.07,0.259
174.87,7.14,0.260
174.88,7.20,0.263
174.89,7.27,0.265
174.89,7.34,0.265
174.90,7.40,0.266
174.91,7.47,0.268
174.91,7.53,0.270
174.92,7.60,0.272
174.93,7.67,0.273
174.93,7.73,0.275
174.94,7.80,0.277
174.95,7.86,0.278
174.95,7.93,0.281
174.96,8.00,0.282
174.97,8.06,0.283
174.97,8.13,0.286
174.98,8.19,0.288
174.99,8.26,0.288
174.99,8.33,0.290
175.00,8.39,0.293
175.01,8.46,0.295
175.01,8.52,0.297
175.02,8.59,0.298
175.03,8.66,0.300
175.03,8.72,0.301
175.04,8.79,0.304
175.05,8.85,0.306
175.05,8.92,0.306
175.06,8.98,0.307
175.07,9.05,0.310
175.07,9.12,0.311
175.08,9.18,0.313
175.09,9.25,0.315
175.09,9.31,0.315
175.10,9.38,0.316
175.11,9.45,0.319
175.11,9.51,0.319
175.12,9.58,0.321
175.13,9.65,0.322
175.13,9.71,0.323
175.14,9.78,0.324
175.15,9.84,0.326
175.15,9.91,0.327
175.16,9.98,0.327
175.17,10.04,0.328
175.17,10.11,0.329
175.18,10.17,0.329
175.19,10.24,0.330
175.19,10.31,0.330
175.20,10.37,0.330
175.21,10.44,0.331
175.21,10.50,0.331
175.22,10.57,0.331
175.23,10.64,0.331
175.23,10.71,0.331
175.24,10.77,0.331
175.25,10.84,0.331
175.25,10.90,0.331
175.26,10.97,0.331
175.27,11.04,0.331
175.27,11.10,0.331
175.28,11.17,0.331
175.29,11.24,0.331
175.29,11.30,0.331
175.30,11.37,0.331
175.31,11.44,0.330
175.31,11.51,0.330
175.32,11.57,0.328
175.33,11.64,0.328
175.33,11.71,0.327
175.34,11.77,0.326
175.35,11.84,0.324
175.35,11.91,0.322
175.36,11.97,0.322
175.37,12.04,0.321
175.37,12.11,0.321
175.38,12.17,0.320
175.39,12.24,0.318
175.39,12.31,0.317
175.40,12.38,0.317
175.41,12.44,0.316
175.41,12.51,0.315
175.42,12.58,0.315
175.43,12.65,0.313
175.43,12.71,0.312
175.44,12.78,0.311
175.45,12.85,0.311
175.45,12.91,0.310
175.46,12.98,0.309
175.47,13.05,0.309
175.47,13.12,0.308
175.48,13.18,0.308
175.49,13.25,0.308
175.49,13.32,0.307
175.50,13.38,0.306
175.51,13.45,0.305
175.51,13.52,0.305
175.52,13.59,0.305
175.53,13.65,0.305
175.53,13.72,0.304
175.54,13.79,0.304
175.55,13.85,0.304
175.55,13.92,0.303
175.56,13.99,0.302
175.57,14.05,0.302
175.57,14.12,0.302
175.58,14.19,0.302
175.59,14.26,0.302
175.59,14.32,0.302
175.60,14.39,0.302
175.61,14.46,0.301
175.61,14.52,0.301
175.62,14.59,0.301
175.63,14.66,0.301
175.63,14.72,0.301
175.64,14.79,0.301
175.65,14.86,0.301
175.65,14.92,0.300
175.66,14.99,0.300
175.67,15.06,0.300
175.67,15.13,0.300
175.68,15.19,0.300
175.69,15.26,0.300
175.69,15.33,0.300
175.70,15.39,0.300
175.71,15.46,0.299
175.71,15.53,0.299
175.72,15.59,0.299
175.73,15.66,0.299
175.73,15.73,0.299
175.74,15.79,0.299
175.75,15.86,0.299
175.75,15.93,0.299
175.76,15.99,0.299
175.77,16.06,0.299
175.77,16.13,0.298
175.78,16.20,0.298
175.79,16.26,0.298
175.79,16.33,0.298
175.80,16.40,0.298
175.81,16.46,0.298
175.81,16.53,0.298
175.82,16.60,0.298
175.83,16.66,0.298
175.83,16.73,0.298
175.84,16.80,0.298
175.85,16.86,0.297
175.85,16.93,0.297
175.86,17.00,0.297
175.87,17.06,0.297
175.87,17.13,0.297
175.88,17.20,0.297
175.89,17.26,0.297
175.89,17.33,0.297
175.90,17.40,0.297
175.91,17.46,0.297
175.91,17.53,0.297
175.92,17.60,0.297
175.93,17.66,0.297
175.93,17.73,0.297
175.94,17.80,0.297
175.95,17.86,0.296
175.95,17.93,0.296
175.96,18.00,0.296
175.97,18.06,0.296
175.97,18.13,0.296
175.98,18.20,0.296
175.99,18.26,0.296
175.99,18.33,0.296
176.00,18.40,0.296
176.01,18.47,0.296
176.01,18.53,0.296
176.02,18.60,0.296
176.03,18.67,0.296
176.03,18.73,0.296
176.04,18.80,0.296
176.05,18.87,0.296
176.05,18.93,0.296
176.06,19.00,0.296
176.07,19.07,0.296
176.07,19.13,0.296
176.08,19.20,0.296
176.09,19.27,0.296
176.09,19.33,0.296
176.10,19.40,0.296
176.11,19.47,0.296
176.11,19.53,0.296
176.12,19.60,0.296
176.13,19.67,0.296
176.13,19.73,0.296
176.14,19.80,0.296
176.15,19.87,0.296
176.15,19.93,0.296
176.16,20.00,0.296
176.17,20.07,0.296
176.17,20.14,0.296
176.18,20.20,0.296
176.19,20.27,0.296
176.19,20.34,0.296
176.20,20.40,0.296
176.21,20.47,0.296
176.21,20.54,0.296
176.22,20.60,0.296
176.23,20.67,0.296
176.23,20.74,0.296
176.24,20.80,0.296
176.25,20.87,0.296
176.25,20.94,0.296
176.26,21.00,0.296
176.27,21.07,0.296
176.27,21.14,0.296
176.28,21.21,0.296
176.29,21.27,0.296
176.29,21.34,0.296
176.30,21.41,0.296
176.31,21.47,0.296
176.31,21.54,0.296
176.32,21.61,0.296
176.33,21.67,0.296
176.33,21.74,0.296
176.34,21.81,0.296
176.35,21.88,0.296
176.35,21.94,0.296
176.36,22.01,0.296
176.37,22.08,0.296
176.37,22.14,0.296
176.38,22.21,0.296
176.39,22.27,0.296
176.39,22.34,0.296
176.40,22.41,0.296
176.41,22.48,0.296
176.41,22.54,0.296
176.42,22.61,0.296
176.43,22.68,0.296
176.43,22.74,0.296
176.44,22.81,0.296
176.45,22.88,0.296
176.45,22.94,0.296
176.46,23.01,0.296
176.47,23.08,0.296
176.47,23.14,0.296
176.48,23.21,0.296
176.49,23.28,0.296
176.49,23.34,0.296
176.50,23.41,0.296
176.51,23.48,0.296
176.51,23.54,0.296
176.52,23.61,0.296
176.53,23.68,0.296
176.53,23.74,0.296
176.54,23.81,0.296
176.55,23.88,0.296
176.55,23.95,0.296
176.56,24.01,0.296
176.57,24.08,0.296
176.57,24.14,0.296
176.58,24.21,0.296
176.59,24.28,0.296
176.59,24.34,0.296
176.60,24.41,0.296
176.61,24.48,0.296
176.61,24.54,0.296
176.62,24.61,0.296
176.63,24.68,0.296
176.63,24.74,0.296
176.64,24.81,0.296
176.65,24.88,0.296
176.65,24.95,0.296
176.66,25.01,0.296
176.67,25.08,0.297
176.67,25.15,0.296
176.68,25.21,0.296
176.69,25.28,0.297
176.69,25.34,0.297
176.70,25.41,0.297
176.71,25.48,0.297
176.71,25.54,0.297
176.72,25.61,0.297
176.73,25.68,0.297
176.73,25.75,0.297
176.74,25.81,0.297
176.75,25.88,0.297
176.75,25.95,0.297
176.76,26.01,0.297
176.77,26.08,0.297
176.77,26.15,0.297
176.78,26.21,0.297
176.79,26.28,0.297
176.79,26.35,0.297
176.80,26.41,0.297
176.81,26.48,0.297
176.81,26.55,0.297
176.82,26.61,0.297
176.83,26.68,0.297
176.83,26.75,0.297
176.84,26.81,0.297
176.85,26.88,0.297
176.85,26.95,0.297
176.86,27.01,0.297
176.87,27.08,0.297
176.87,27.15,0.297
176.88,27.21,0.297
176.89,27.28,0.297
176.89,27.35,0.297
176.90,27.41,0.297
176.91,27.48,0.297
176.91,27.55,0.297
176.92,27.61,0.297
176.93,27.68,0.297
176.93,27.75,0.297
176.94,27.81,
176.95,27.88,
176.95,27.95,
176.96,28.01,
176.97,28.08,
176.97,28.15,
176.98,28.21,
176.99,,
176.99,,