File: DSC/2025_04_21_Creatinine_n60C_150C_5Cmin_x3.csv
Filename,2025_04_21_Creatinine_n60C_150C_5Cmin_x3
Instrument name,DSC2A-00468 (192.168.1.100)
Operator,Yarger
rundate,4/21/2025
Sample name,2025_04_21_Creatinine_n60C_150C_5Cmin_x3
proceduresegments,Data Off ; Equilibrate -60.00 °C; Data On ; Ramp 5.00 °C/min to 150.00 °C; Data Off ; Isothermal 1.0 min; Data On ; Ramp 10.00 °C/min to -60.00 °C; Data Off ; Isothermal 1.0 min; Data On ; Ramp 5.00 °C/min to 150.00 °C; Data Off ; Isothermal 1.0 min; Data On ; Ramp 10.00 °C/min to -60.00 °C; Data Off ; Isothermal 1.0 min; Data On ; Ramp 5.00 °C/min to 150.00 °C
[File Parameters]
Run date,4/21/2025 4:46:23 PM
Trios version,5.1.1.46572
Original File Name,
Current File Name,D:\DSC2500\JYarger\2025_04_21_Creatinine_n60C_150C_5Cmin_x3.tri
[Procedure]
Procedure Name,Creatinine_n60_150C_5Cmin_x3
Sample Name,2025_04_21_Creatinine_n60C_150C_5Cmin_x3
Sample Mass,3.9 mg
Reference Sample Mass,0 mg
Pan Mass,52.86 mg
Pan Number,26
Reference Pan Mass,52.66 mg
Reference Pan Number,19
Pan Type,Tzero Aluminum Hermetic
Comments,Al Hermetic DSC Consumables sealed Pan/Lid.
Project Name,CA
Operator,Yarger
Test,Custom
Unload Max Temperature,30
Unload Min Temperature,30
Load Max Temperature,30
Load Min Temperature,30
Stop on Gas Flow Error,Yes
[Signal List]
Signal #1,Time (min)
Signal #2,Temperature (°C)
Signal #3,Heat Flow (mW)
Signal #4,Delta T (µV)
Signal #5,Delta Tzero (µV)
Signal #6,Tzero Temperature (°C)
Signal #7,Cell Purge (mL/min)
Signal #8,Heater Temp (°C)
Signal #9,Power Delivered (W)
Signal #10,Reference Junction Temperature (°C)
Signal #11,Flange Temperature (°C)
Signal #12,Heat Flow Phase (rad)
Signal #13,Total Heat Capacity (J/°C)
Signal #14,Heat Capacity (J/°C)
[Configuration]
Company Name,ASU
Instrument Name,DSC2A-00468
Instrument Type,DSC2500
Serial Number,DSC2A-00468
IP,192.168.1.100
Location of Instrument,MRRC
DisplayType,Unknown
Sample Interval ,0.1 s/pt
Selected Heat Flow,T4P
Exotherm Direction,Down
Cell Serial,DRC2-00792
Lid Type,Standard
Cooler,RCS 90
Leave Cooler on at End of Sequence,On
Gas 2,Nitrogen
Gas Selected,Channel 1
Flow Rate,50 mL/min
Secondary Purge,On
Licensed Heat Flow,Heat Flow T4P
Modulation Licensed,Yes
[Versions]
Common IDD Version,1
Cortex Version,VER 2.10.2.31
Driver,5.0.0.6
GDM Version,1.0.3.3
TouchscreenVersion,1.0.0.16145
FEP Version,1.2.1.21
FEP Bootloader,2.0.0.5
AutoSampler Version,2.1.1.26
Auto Sampler Bootloader,2.0.0.5
FCM Version,1.1.0.3
FCM Bootloader,2.0.0.5
[Experiment Logs]
Experiment Log Entry # 1,Data On set to 0
Experiment Log Entry # 3,Equilibrate Segment -60 (C) Started
Experiment Log Entry # 5,Air Cool is off.
Experiment Log Entry # 7,Data On set to 1
Experiment Log Entry # 9,Ramp Segment 5 C/min to 150 Started
Experiment Log Entry # 11,Data On set to 0
Experiment Log Entry # 13,Isothermal Segment 1 min started
Experiment Log Entry # 15,Data On set to 1
Experiment Log Entry # 17,Ramp Segment 10 C/min to -60 Started
Experiment Log Entry # 19,Data On set to 0
Experiment Log Entry # 21,Isothermal Segment 1 min started
Experiment Log Entry # 23,Data On set to 1
Experiment Log Entry # 25,Ramp Segment 5 C/min to 150 Started
Experiment Log Entry # 27,Data On set to 0
Experiment Log Entry # 29,Isothermal Segment 1 min started
Experiment Log Entry # 31,Data On set to 1
Experiment Log Entry # 33,Ramp Segment 10 C/min to -60 Started
Experiment Log Entry # 35,Data On set to 0
Experiment Log Entry # 37,Isothermal Segment 1 min started
Experiment Log Entry # 39,Data On set to 1
Experiment Log Entry # 41,Ramp Segment 5 C/min to 150 Started
[Method Log]
Method Log Entry # 1,Data Off
Method Log Entry # 2,Equilibrate -60 °C
Method Log Entry # 3,Data On
Method Log Entry # 4,(Ramp 776722) Ramp 5 °C/minute to 150 °C
Method Log Entry # 5,Data Off
Method Log Entry # 6,Isothermal 1 minutes
Method Log Entry # 7,Data On
Method Log Entry # 8,(Ramp 776726) Ramp 10 °C/minute to -60 °C
Method Log Entry # 9,Data Off
Method Log Entry # 10,Isothermal 1 minutes
Method Log Entry # 11,Data On
Method Log Entry # 12,(Ramp 776730) Ramp 5 °C/minute to 150 °C
Method Log Entry # 13,Data Off
Method Log Entry # 14,Isothermal 1 minutes
Method Log Entry # 15,Data On
Method Log Entry # 16,(Ramp 776734) Ramp 10 °C/minute to -60 °C
Method Log Entry # 17,Data Off
Method Log Entry # 18,Isothermal 1 minutes
Method Log Entry # 19,Data On
Method Log Entry # 20,(Ramp 776738) Ramp 5 °C/minute to 150 °C
Cell Serial,DRC2-00792
[T1 Calibration]
Slope,-0.008529666
Offset,9.636258
Initial Temperature,98.23
GUID,f8bfdadc-4977-4fdf-ba6d-0ba9134940c3
[TZero Calibration]
Date Applied,11/29/2022 4:06:13 PM
Description,From -89.059 °C to 396.009 °C at 20.000°C/min
Gas Type,Nitrogen
Pan Type,None
Source Files 1,C:\Users\yargerlab\Desktop\DSC Data\General\TZero_calibration_11_29_22_2nd(2).tri
Source Files 2,C:\Users\yargerlab\Desktop\DSC Data\General\TZero_calibration_11_29_22_2nd(3).tri
Delta T Offset,13.05235
Delta T Slope,-0.007271007
Delta T0 Offset,-13.69128
Delta T0 Slope,0.06063341
[Temperature Calibration]
Date Applied,11/29/2022 7:12:28 PM
Description,From 106.590 °C to 186.590 °C at 10.000°C/min
Gas Type,Nitrogen
Pan Type,Tzero Aluminum Hermetic
Source Files 1,C:\Users\yargerlab\Desktop\DSC Data\General\Indium(6).tri
Measured 1,157.391
Known 1,156.598
[Cell Constant Calibration]
Date Applied,11/29/2022 7:12:29 PM
Description,From 106.590 °C to 186.590 °C at 10.000°C/min
Gas Type,Nitrogen
Pan Type,Tzero Aluminum Hermetic
Source Files 1,C:\Users\yargerlab\Desktop\DSC Data\General\Indium(6).tri
T4P KCell,1.006051
Onset Slope,63.26126 mW/°C
[Direct Cp Calibration]
Date Applied,11/30/2022 11:04:51 AM
Description,From -79.983 °C to 298.409 °C at 10.000°C/min
Gas Type,Nitrogen
Pan Type,Tzero Aluminum Hermetic
Source Files 1,C:\Users\yargerlab\Desktop\DSC Data\General\Sapphire_Heat_Capacity_11_30_22.tri
[Rev Cp Calibration]
Date Applied,11/30/2022 1:58:51 PM
Description,From -79.996 °C to 292.812 °C at 3.000°C/min
Gas Type,Nitrogen
Pan Type,Tzero Aluminum Hermetic
Source Files 1,C:\Users\yargerlab\Desktop\DSC Data\General\Sapphire_MDSC_Calibration_11_30_22.tri
[step]
Ramp 5.00 °C/min to 150.00 °C
Time,Temperature,Heat Flow (Normalized)
min,°C,W/g
0.00,-59.69,-0.055
0.03,-59.71,-0.054
0.06,-59.71,-0.045
0.08,-59.69,-0.029
0.11,-59.64,-0.010
0.14,-59.58,0.013
0.17,-59.48,0.034
0.20,-59.38,0.051
0.23,-59.26,0.066
0.26,-59.15,0.075
0.28,-59.02,0.084
0.31,-58.90,0.088
0.34,-58.77,0.092
0.37,-58.64,0.095
0.40,-58.50,0.098
0.43,-58.37,0.099
0.45,-58.24,0.101
0.48,-58.10,0.102
0.51,-57.97,0.102
0.54,-57.83,0.103
0.57,-57.69,0.104
0.60,-57.55,0.105
0.62,-57.42,0.106
0.65,-57.28,0.106
0.68,-57.14,0.107
0.71,-57.00,0.107
0.74,-56.86,0.107
0.77,-56.73,0.108
0.79,-56.59,0.108
0.82,-56.45,0.109
0.85,-56.31,0.109
0.88,-56.17,0.109
0.91,-56.03,0.109
0.93,-55.89,0.110
0.96,-55.75,0.110
0.99,-55.61,0.110
1.02,-55.47,0.110
1.05,-55.33,0.110
1.08,-55.19,0.110
1.11,-55.05,0.110
1.13,-54.91,0.110
1.16,-54.77,0.111
1.19,-54.63,0.111
1.22,-54.49,0.111
1.25,-54.35,0.111
1.28,-54.20,0.111
1.30,-54.06,0.111
1.33,-53.92,0.111
1.36,-53.78,0.111
1.39,-53.64,0.111
1.42,-53.50,0.111
1.44,-53.36,0.111
1.47,-53.22,0.111
1.50,-53.08,0.111
1.53,-52.94,0.111
1.56,-52.80,0.111
1.59,-52.66,0.111
1.62,-52.52,0.111
1.64,-52.37,0.111
1.67,-52.23,0.111
1.70,-52.09,0.111
1.73,-51.95,0.111
1.76,-51.81,0.111
1.78,-51.67,0.111
1.81,-51.53,0.111
1.84,-51.39,0.111
1.87,-51.24,0.111
1.90,-51.10,0.111
1.93,-50.96,0.111
1.96,-50.82,0.111
1.98,-50.68,0.111
2.01,-50.54,0.111
2.04,-50.39,0.110
2.07,-50.25,0.110
2.10,-50.11,0.110
2.13,-49.97,0.110
2.15,-49.83,0.110
2.18,-49.69,0.110
2.21,-49.55,0.110
2.24,-49.40,0.110
2.27,-49.26,0.110
2.29,-49.12,0.110
2.32,-48.98,0.110
2.35,-48.84,0.110
2.38,-48.70,0.110
2.41,-48.56,0.110
2.44,-48.41,0.110
2.46,-48.27,0.110
2.49,-48.13,0.110
2.52,-47.99,0.110
2.55,-47.85,0.110
2.58,-47.71,0.110
2.61,-47.57,0.109
2.64,-47.43,0.109
2.66,-47.28,0.109
2.69,-47.14,0.109
2.72,-47.00,0.109
2.75,-46.86,0.109
2.78,-46.72,0.109
2.81,-46.58,0.109
2.83,-46.43,0.109
2.86,-46.29,0.109
2.89,-46.15,0.109
2.92,-46.01,0.109
2.95,-45.87,0.109
2.98,-45.73,0.109
3.00,-45.59,0.109
3.03,-45.44,0.109
3.06,-45.30,0.109
3.09,-45.16,0.109
3.12,-45.02,0.109
3.14,-44.88,0.109
3.17,-44.73,0.109
3.20,-44.59,0.109
3.23,-44.45,0.109
3.26,-44.31,0.109
3.29,-44.17,0.109
3.31,-44.03,0.109
3.34,-43.88,0.109
3.37,-43.74,0.109
3.40,-43.60,0.109
3.43,-43.46,0.109
3.46,-43.32,0.109
3.49,-43.18,0.109
3.51,-43.03,0.109
3.54,-42.89,0.109
3.57,-42.75,0.109
3.60,-42.61,0.109
3.63,-42.47,0.109
3.66,-42.33,0.109
3.68,-42.18,0.109
3.71,-42.04,0.109
3.74,-41.90,0.109
3.77,-41.76,0.109
3.80,-41.62,0.109
3.83,-41.48,0.109
3.85,-41.33,0.109
3.88,-41.19,0.109
3.91,-41.05,0.109
3.94,-40.91,0.109
3.97,-40.77,0.109
3.99,-40.62,0.109
4.02,-40.48,0.109
4.05,-40.34,0.109
4.08,-40.20,0.109
4.11,-40.06,0.109
4.14,-39.92,0.109
4.16,-39.77,0.109
4.19,-39.63,0.109
4.22,-39.49,0.109
4.25,-39.35,0.109
4.28,-39.21,0.109
4.31,-39.06,0.109
4.34,-38.92,0.109
4.36,-38.78,0.109
4.39,-38.64,0.109
4.42,-38.50,0.109
4.45,-38.35,0.109
4.48,-38.21,0.109
4.50,-38.07,0.109
4.53,-37.93,0.109
4.56,-37.79,0.109
4.59,-37.65,0.109
4.62,-37.50,0.109
4.65,-37.36,0.109
4.68,-37.22,0.109
4.70,-37.08,0.109
4.73,-36.94,0.109
4.76,-36.79,0.109
4.79,-36.65,0.109
4.82,-36.51,0.109
4.85,-36.37,0.109
4.87,-36.23,0.109
4.90,-36.09,0.109
4.93,-35.94,0.109
4.96,-35.80,0.109
4.99,-35.66,0.109
5.01,-35.52,0.109
5.04,-35.38,0.109
5.07,-35.24,0.109
5.10,-35.09,0.109
5.13,-34.95,0.109
5.16,-34.81,0.109
5.19,-34.67,0.109
5.21,-34.52,0.109
5.24,-34.38,0.109
5.27,-34.24,0.109
5.30,-34.10,0.109
5.33,-33.96,0.109
5.35,-33.82,0.109
5.38,-33.67,0.109
5.41,-33.53,0.109
5.44,-33.39,0.109
5.47,-33.25,0.109
5.50,-33.11,0.109
5.53,-32.96,0.109
5.55,-32.82,0.109
5.58,-32.68,0.110
5.61,-32.54,0.110
5.64,-32.40,0.110
5.67,-32.26,0.110
5.70,-32.11,0.112
5.72,-31.97,0.116
5.75,-31.83,0.118
5.78,-31.69,0.117
5.81,-31.55,0.116
5.84,-31.41,0.115
5.86,-31.26,0.114
5.89,-31.12,0.114
5.92,-30.98,0.113
5.95,-30.84,0.113
5.98,-30.70,0.112
6.01,-30.56,0.112
6.04,-30.41,0.111
6.06,-30.27,0.111
6.09,-30.13,0.111
6.12,-29.99,0.111
6.15,-29.85,0.110
6.18,-29.70,0.110
6.20,-29.56,0.110
6.23,-29.42,0.110
6.26,-29.28,0.110
6.29,-29.14,0.110
6.32,-28.99,0.109
6.35,-28.85,0.109
6.38,-28.71,0.109
6.40,-28.57,0.109
6.43,-28.43,0.109
6.46,-28.29,0.109
6.49,-28.14,0.109
6.52,-28.00,0.109
6.55,-27.86,0.109
6.57,-27.72,0.109
6.60,-27.58,0.109
6.63,-27.44,0.109
6.66,-27.29,0.109
6.69,-27.15,0.109
6.71,-27.01,0.109
6.74,-26.87,0.109
6.77,-26.73,0.109
6.80,-26.58,0.109
6.83,-26.44,0.109
6.86,-26.30,0.109
6.89,-26.16,0.109
6.91,-26.02,0.109
6.94,-25.88,0.109
6.97,-25.74,0.109
7.00,-25.59,0.109
7.03,-25.45,0.109
7.05,-25.31,0.108
7.08,-25.17,0.109
7.11,-25.03,0.108
7.14,-24.89,0.108
7.17,-24.74,0.108
7.20,-24.60,0.109
7.23,-24.46,0.109
7.25,-24.32,0.109
7.28,-24.17,0.109
7.31,-24.03,0.109
7.34,-23.89,0.109
7.37,-23.75,0.109
7.40,-23.61,0.109
7.42,-23.46,0.109
7.45,-23.32,0.109
7.48,-23.18,0.109
7.51,-23.04,0.109
7.54,-22.90,0.109
7.56,-22.76,0.109
7.59,-22.61,0.109
7.62,-22.47,0.109
7.65,-22.33,0.109
7.68,-22.19,0.109
7.71,-22.05,0.109
7.74,-21.90,0.109
7.76,-21.76,0.109
7.79,-21.62,0.109
7.82,-21.48,0.109
7.85,-21.34,0.109
7.88,-21.20,0.109
7.90,-21.05,0.109
7.93,-20.91,0.109
7.96,-20.77,0.109
7.99,-20.63,0.109
8.02,-20.49,0.109
8.05,-20.35,0.109
8.08,-20.20,0.109
8.10,-20.06,0.109
8.13,-19.92,0.109
8.16,-19.78,0.109
8.19,-19.64,0.109
8.22,-19.49,0.109
8.25,-19.35,0.109
8.27,-19.21,0.109
8.30,-19.07,0.109
8.33,-18.93,0.109
8.36,-18.79,0.109
8.39,-18.64,0.109
8.41,-18.50,0.109
8.44,-18.36,0.109
8.47,-18.22,0.109
8.50,-18.08,0.109
8.53,-17.94,0.109
8.56,-17.79,0.109
8.58,-17.65,0.109
8.61,-17.51,0.109
8.64,-17.37,0.109
8.67,-17.23,0.109
8.70,-17.09,0.109
8.73,-16.94,0.109
8.75,-16.80,0.109
8.78,-16.66,0.109
8.81,-16.52,0.109
8.84,-16.38,0.109
8.87,-16.23,0.109
8.90,-16.09,0.109
8.93,-15.95,0.109
8.95,-15.81,0.109
8.98,-15.67,0.109
9.01,-15.52,0.109
9.04,-15.38,0.109
9.07,-15.24,0.110
9.10,-15.10,0.110
9.12,-14.96,0.110
9.15,-14.81,0.110
9.18,-14.67,0.110
9.21,-14.53,0.110
9.24,-14.39,0.110
9.27,-14.25,0.110
9.29,-14.11,0.110
9.32,-13.97,0.110
9.35,-13.82,0.110
9.38,-13.68,0.110
9.41,-13.54,0.110
9.43,-13.40,0.110
9.46,-13.26,0.110
9.49,-13.11,0.110
9.52,-12.97,0.110
9.55,-12.83,0.110
9.58,-12.69,0.110
9.60,-12.55,0.110
9.63,-12.40,0.110
9.66,-12.26,0.110
9.69,-12.12,0.110
9.72,-11.98,0.110
9.75,-11.84,0.110
9.78,-11.70,0.110
9.80,-11.56,0.110
9.83,-11.41,0.110
9.86,-11.27,0.110
9.89,-11.13,0.110
9.92,-10.99,0.110
9.95,-10.84,0.110
9.97,-10.70,0.110
10.00,-10.56,0.110
10.03,-10.42,0.110
10.06,-10.28,0.110
10.09,-10.14,0.110
10.12,-10.00,0.110
10.14,-9.85,0.110
10.17,-9.71,0.110
10.20,-9.57,0.110
10.23,-9.43,0.110
10.26,-9.29,0.110
10.28,-9.14,0.110
10.31,-9.00,0.110
10.34,-8.86,0.110
10.37,-8.72,0.110
10.40,-8.58,0.110
10.43,-8.44,0.110
10.45,-8.29,0.110
10.48,-8.15,0.110
10.51,-8.01,0.110
10.54,-7.87,0.110
10.57,-7.73,0.110
10.60,-7.59,0.110
10.63,-7.44,0.111
10.65,-7.30,0.111
10.68,-7.16,0.111
10.71,-7.02,0.111
10.74,-6.88,0.111
10.77,-6.73,0.111
10.80,-6.59,0.111
10.82,-6.45,0.111
10.85,-6.31,0.111
10.88,-6.17,0.111
10.91,-6.02,0.111
10.94,-5.88,0.111
10.97,-5.74,0.111
10.99,-5.60,0.111
11.02,-5.46,0.111
11.05,-5.32,0.111
11.08,-5.18,0.111
11.11,-5.03,0.111
11.13,-4.89,0.111
11.16,-4.75,0.111
11.19,-4.61,0.111
11.22,-4.47,0.111
11.25,-4.33,0.111
11.28,-4.18,0.111
11.30,-4.04,0.111
11.33,-3.90,0.111
11.36,-3.76,0.111
11.39,-3.62,0.111
11.42,-3.47,0.111
11.45,-3.33,0.111
11.48,-3.19,0.111
11.50,-3.05,0.111
11.53,-2.91,0.111
11.56,-2.77,0.111
11.59,-2.62,0.111
11.62,-2.48,0.111
11.65,-2.34,0.112
11.67,-2.20,0.112
11.70,-2.06,0.112
11.73,-1.91,0.112
11.76,-1.77,0.112
11.79,-1.63,0.112
11.82,-1.49,0.112
11.84,-1.35,0.112
11.87,-1.21,0.112
11.90,-1.06,0.112
11.93,-0.92,0.112
11.96,-0.78,0.112
11.98,-0.64,0.112
12.01,-0.50,0.112
12.04,-0.35,0.112
12.07,-0.21,0.112
12.10,-0.07,0.112
12.13,0.07,0.112
12.15,0.21,0.112
12.18,0.35,0.112
12.21,0.50,0.112
12.24,0.64,0.112
12.27,0.78,0.112
12.30,0.92,0.112
12.33,1.06,0.112
12.35,1.21,0.112
12.38,1.35,0.112
12.41,1.49,0.112
12.44,1.63,0.112
12.47,1.77,0.112
12.50,1.91,0.112
12.52,2.06,0.112
12.55,2.20,0.112
12.58,2.34,0.112
12.61,2.48,0.112
12.64,2.62,0.112
12.67,2.77,0.112
12.69,2.91,0.112
12.72,3.05,0.112
12.75,3.19,0.112
12.78,3.33,0.112
12.81,3.47,0.112
12.83,3.62,0.112
12.86,3.76,0.112
12.89,3.90,0.113
12.92,4.04,0.113
12.95,4.18,0.113
12.98,4.32,0.113
13.00,4.47,0.113
13.03,4.61,0.113
13.06,4.75,0.113
13.09,4.89,0.113
13.12,5.03,0.113
13.15,5.18,0.113
13.18,5.32,0.113
13.20,5.46,0.113
13.23,5.60,0.113
13.26,5.74,0.113
13.29,5.88,0.113
13.32,6.03,0.113
13.35,6.17,0.113
13.37,6.31,0.113
13.40,6.45,0.113
13.43,6.59,0.113
13.46,6.73,0.113
13.49,6.88,0.113
13.52,7.02,0.113
13.54,7.16,0.113
13.57,7.30,0.113
13.60,7.44,0.113
13.63,7.58,0.113
13.66,7.73,0.113
13.68,7.87,0.113
13.71,8.01,0.113
13.74,8.15,0.113
13.77,8.29,0.114
13.80,8.44,0.114
13.83,8.58,0.114
13.85,8.72,0.114
13.88,8.86,0.114
13.91,9.00,0.114
13.94,9.14,0.114
13.97,9.29,0.114
14.00,9.43,0.114
14.03,9.57,0.114
14.05,9.71,0.114
14.08,9.85,0.114
14.11,9.99,0.114
14.14,10.14,0.114
14.17,10.28,0.114
14.20,10.42,0.114
14.22,10.56,0.114
14.25,10.70,0.114
14.28,10.85,0.114
14.31,10.99,0.114
14.34,11.13,0.114
14.37,11.27,0.114
14.39,11.41,0.114
14.42,11.56,0.114
14.45,11.70,0.114
14.48,11.84,0.114
14.51,11.98,0.114
14.53,12.12,0.115
14.56,12.26,0.115
14.59,12.41,0.115
14.62,12.55,0.115
14.65,12.69,0.115
14.68,12.83,0.115
14.70,12.97,0.115
14.73,13.12,0.115
14.76,13.26,0.115
14.79,13.40,0.115
14.82,13.54,0.115
14.85,13.68,0.115
14.88,13.82,0.115
14.90,13.96,0.115
14.93,14.11,0.115
14.96,14.25,0.115
14.99,14.39,0.115
15.02,14.53,0.114
15.05,14.67,0.114
15.07,14.81,0.115
15.10,14.96,0.115
15.13,15.10,0.115
15.16,15.24,0.115
15.19,15.38,0.115
15.22,15.52,0.115
15.24,15.67,0.115
15.27,15.81,0.115
15.30,15.95,0.115
15.33,16.09,0.115
15.36,16.23,0.115
15.38,16.37,0.115
15.41,16.52,0.115
15.44,16.66,0.115
15.47,16.80,0.115
15.50,16.94,0.115
15.53,17.08,0.115
15.55,17.23,0.115
15.58,17.37,0.115
15.61,17.51,0.116
15.64,17.65,0.116
15.67,17.79,0.116
15.70,17.93,0.116
15.73,18.08,0.116
15.75,18.22,0.116
15.78,18.36,0.116
15.81,18.50,0.116
15.84,18.64,0.116
15.87,18.79,0.116
15.90,18.93,0.116
15.92,19.07,0.116
15.95,19.21,0.116
15.98,19.35,0.116
16.01,19.49,0.116
16.04,19.63,0.116
16.07,19.78,0.116
16.09,19.92,0.116
16.12,20.06,0.116
16.15,20.20,0.116
16.18,20.34,0.116
16.21,20.48,0.116
16.23,20.63,0.116
16.26,20.77,0.117
16.29,20.91,0.117
16.32,21.05,0.117
16.35,21.19,0.117
16.38,21.34,0.117
16.40,21.48,0.117
16.43,21.62,0.117
16.46,21.76,0.117
16.49,21.90,0.117
16.52,22.05,0.117
16.55,22.19,0.117
16.58,22.33,0.117
16.60,22.47,0.117
16.63,22.61,0.117
16.66,22.75,0.117
16.69,22.90,0.117
16.72,23.04,0.117
16.75,23.18,0.117
16.77,23.32,0.117
16.80,23.46,0.117
16.83,23.61,0.117
16.86,23.75,0.117
16.89,23.89,0.117
16.92,24.03,0.117
16.94,24.17,0.117
16.97,24.31,0.117
17.00,24.46,0.118
17.03,24.60,0.118
17.06,24.74,0.118
17.08,24.88,0.118
17.11,25.02,0.118
17.14,25.16,0.118
17.17,25.31,0.118
17.20,25.45,0.118
17.23,25.59,0.118
17.26,25.73,0.118
17.28,25.87,0.118
17.31,26.01,0.118
17.34,26.16,0.118
17.37,26.30,0.118
17.40,26.44,0.118
17.43,26.58,0.118
17.45,26.72,0.118
17.48,26.86,0.118
17.51,27.01,0.118
17.54,27.15,0.118
17.57,27.29,0.118
17.59,27.43,0.118
17.62,27.57,0.119
17.65,27.72,0.119
17.68,27.86,0.119
17.71,28.00,0.119
17.74,28.14,0.119
17.77,28.28,0.119
17.79,28.42,0.119
17.82,28.57,0.119
17.85,28.71,0.119
17.88,28.85,0.119
17.91,28.99,0.119
17.93,29.13,0.119
17.96,29.27,0.119
17.99,29.42,0.119
18.02,29.56,0.119
18.05,29.70,0.119
18.08,29.84,0.119
18.11,29.99,0.119
18.13,30.13,0.119
18.16,30.27,0.119
18.19,30.41,0.120
18.22,30.55,0.120
18.25,30.69,0.120
18.28,30.84,0.120
18.30,30.98,0.120
18.33,31.12,0.120
18.36,31.26,0.120
18.39,31.40,0.120
18.42,31.54,0.120
18.44,31.69,0.120
18.47,31.83,0.120
18.50,31.97,0.120
18.53,32.11,0.120
18.56,32.25,0.120
18.59,32.39,0.120
18.62,32.54,0.120
18.64,32.68,0.120
18.67,32.82,0.120
18.70,32.96,0.120
18.73,33.10,0.120
18.76,33.24,0.120
18.78,33.39,0.120
18.81,33.53,0.120
18.84,33.67,0.120
18.87,33.81,0.120
18.90,33.95,0.120
18.93,34.09,0.120
18.96,34.24,0.120
18.98,34.38,0.121
19.01,34.52,0.121
19.04,34.66,0.121
19.07,34.80,0.121
19.10,34.94,0.121
19.13,35.09,0.121
19.15,35.23,0.121
19.18,35.37,0.121
19.21,35.51,0.121
19.24,35.65,0.121
19.27,35.80,0.121
19.29,35.94,0.121
19.32,36.08,0.121
19.35,36.22,0.121
19.38,36.36,0.121
19.41,36.50,0.121
19.44,36.65,0.121
19.47,36.79,0.121
19.49,36.93,0.121
19.52,37.07,0.121
19.55,37.21,0.121
19.58,37.36,0.121
19.61,37.50,0.121
19.63,37.64,0.121
19.66,37.78,0.121
19.69,37.92,0.121
19.72,38.06,0.121
19.75,38.21,0.121
19.78,38.35,0.121
19.81,38.49,0.121
19.83,38.63,0.121
19.86,38.77,0.122
19.89,38.92,0.122
19.92,39.06,0.122
19.95,39.20,0.122
19.98,39.34,0.122
20.00,39.48,0.122
20.03,39.62,0.122
20.06,39.76,0.122
20.09,39.91,0.122
20.12,40.05,0.122
20.14,40.19,0.122
20.17,40.33,0.122
20.20,40.47,0.122
20.23,40.62,0.122
20.26,40.76,0.122
20.29,40.90,0.122
20.32,41.04,0.122
20.34,41.18,0.122
20.37,41.33,0.122
20.40,41.47,0.122
20.43,41.61,0.122
20.46,41.75,0.122
20.48,41.89,0.122
20.51,42.03,0.123
20.54,42.17,0.123
20.57,42.32,0.123
20.60,42.46,0.123
20.63,42.60,0.123
20.66,42.74,0.123
20.68,42.88,0.123
20.71,43.02,0.123
20.74,43.17,0.123
20.77,43.31,0.123
20.80,43.45,0.123
20.83,43.59,0.123
20.85,43.73,0.123
20.88,43.88,0.123
20.91,44.02,0.123
20.94,44.16,0.123
20.97,44.30,0.123
20.99,44.44,0.123
21.02,44.58,0.123
21.05,44.73,0.124
21.08,44.87,0.124
21.11,45.01,0.124
21.14,45.15,0.124
21.17,45.29,0.124
21.19,45.44,0.124
21.22,45.58,0.124
21.25,45.72,0.124
21.28,45.86,0.124
21.31,46.00,0.124
21.33,46.14,0.124
21.36,46.28,0.124
21.39,46.43,0.124
21.42,46.57,0.124
21.45,46.71,0.124
21.48,46.85,0.124
21.51,46.99,0.124
21.53,47.13,0.124
21.56,47.28,0.124
21.59,47.42,0.124
21.62,47.56,0.124
21.65,47.70,0.124
21.68,47.84,0.124
21.70,47.99,0.125
21.73,48.13,0.125
21.76,48.27,0.125
21.79,48.41,0.125
21.82,48.55,0.125
21.84,48.69,0.125
21.87,48.84,0.125
21.90,48.98,0.125
21.93,49.12,0.125
21.96,49.26,0.125
21.99,49.40,0.125
22.02,49.54,0.125
22.04,49.69,0.125
22.07,49.83,0.125
22.10,49.97,0.125
22.13,50.11,0.125
22.16,50.25,0.125
22.18,50.40,0.125
22.21,50.54,0.125
22.24,50.68,0.125
22.27,50.82,0.125
22.30,50.96,0.125
22.33,51.11,0.125
22.36,51.25,0.126
22.38,51.39,0.126
22.41,51.53,0.126
22.44,51.67,0.126
22.47,51.81,0.126
22.50,51.96,0.126
22.53,52.10,0.126
22.55,52.24,0.126
22.58,52.38,0.126
22.61,52.52,0.126
22.64,52.66,0.126
22.67,52.81,0.126
22.69,52.95,0.126
22.72,53.09,0.126
22.75,53.23,0.126
22.78,53.37,0.126
22.81,53.51,0.126
22.84,53.66,0.127
22.87,53.80,0.127
22.89,53.94,0.127
22.92,54.08,0.127
22.95,54.22,0.127
22.98,54.37,0.127
23.01,54.51,0.127
23.03,54.65,0.127
23.06,54.79,0.127
23.09,54.93,0.127
23.12,55.07,0.127
23.15,55.22,0.127
23.18,55.36,0.127
23.21,55.50,0.127
23.23,55.64,0.127
23.26,55.78,0.127
23.29,55.92,0.128
23.32,56.07,0.128
23.35,56.21,0.128
23.38,56.35,0.128
23.40,56.49,0.128
23.43,56.63,0.128
23.46,56.78,0.128
23.49,56.92,0.128
23.52,57.06,0.128
23.54,57.20,0.128
23.57,57.34,0.128
23.60,57.48,0.128
23.63,57.62,0.128
23.66,57.77,0.128
23.69,57.91,0.128
23.72,58.05,0.128
23.74,58.19,0.128
23.77,58.33,0.128
23.80,58.48,0.128
23.83,58.62,0.128
23.86,58.76,0.128
23.88,58.90,0.128
23.91,59.04,0.129
23.94,59.19,0.129
23.97,59.33,0.129
24.00,59.47,0.129
24.03,59.61,0.129
24.06,59.75,0.129
24.08,59.89,0.129
24.11,60.04,0.129
24.14,60.18,0.129
24.17,60.32,0.129
24.20,60.46,0.129
24.23,60.60,0.129
24.25,60.74,0.129
24.28,60.89,0.129
24.31,61.03,0.129
24.34,61.17,0.129
24.37,61.31,0.129
24.39,61.45,0.129
24.42,61.60,0.129
24.45,61.74,0.129
24.48,61.88,0.129
24.51,62.02,0.129
24.54,62.16,0.129
24.57,62.30,0.129
24.59,62.45,0.129
24.62,62.59,0.129
24.65,62.73,0.129
24.68,62.87,0.129
24.71,63.01,0.129
24.73,63.16,0.129
24.76,63.30,0.130
24.79,63.44,0.129
24.82,63.58,0.130
24.85,63.72,0.130
24.88,63.86,0.130
24.91,64.00,0.130
24.93,64.15,0.130
24.96,64.29,0.130
24.99,64.43,0.130
25.02,64.57,0.130
25.05,64.71,0.130
25.08,64.85,0.130
25.10,64.99,0.130
25.13,65.14,0.130
25.16,65.28,0.130
25.19,65.42,0.130
25.22,65.56,0.130
25.24,65.71,0.130
25.27,65.85,0.130
25.30,65.99,0.130
25.33,66.13,0.131
25.36,66.27,0.131
25.39,66.42,0.131
25.42,66.56,0.131
25.44,66.70,0.131
25.47,66.84,0.131
25.50,66.98,0.131
25.53,67.12,0.131
25.56,67.26,0.131
25.58,67.41,0.131
25.61,67.55,0.131
25.64,67.69,0.131
25.67,67.83,0.131
25.70,67.97,0.131
25.73,68.11,0.131
25.76,68.26,0.131
25.78,68.40,0.131
25.81,68.54,0.131
25.84,68.68,0.131
25.87,68.82,0.131
25.90,68.97,0.131
25.93,69.11,0.131
25.95,69.25,0.131
25.98,69.39,0.131
26.01,69.53,0.131
26.04,69.67,0.132
26.07,69.82,0.132
26.09,69.96,0.132
26.12,70.10,0.132
26.15,70.24,0.132
26.18,70.38,0.132
26.21,70.52,0.132
26.24,70.67,0.132
26.27,70.81,0.132
26.29,70.95,0.132
26.32,71.09,0.132
26.35,71.23,0.132
26.38,71.37,0.132
26.41,71.52,0.132
26.43,71.66,0.132
26.46,71.80,0.132
26.49,71.94,0.132
26.52,72.08,0.132
26.55,72.22,0.132
26.58,72.37,0.132
26.61,72.51,0.132
26.63,72.65,0.133
26.66,72.79,0.133
26.69,72.93,0.133
26.72,73.07,0.133
26.75,73.22,0.133
26.78,73.36,0.133
26.80,73.50,0.133
26.83,73.64,0.133
26.86,73.78,0.133
26.89,73.93,0.133
26.92,74.07,0.133
26.94,74.21,0.133
26.97,74.35,0.133
27.00,74.49,0.133
27.03,74.63,0.133
27.06,74.77,0.133
27.09,74.92,0.133
27.12,75.06,0.133
27.14,75.20,0.133
27.17,75.34,0.134
27.20,75.48,0.134
27.23,75.63,0.134
27.26,75.77,0.134
27.28,75.91,0.134
27.31,76.05,0.134
27.34,76.19,0.134
27.37,76.34,0.134
27.40,76.48,0.134
27.43,76.62,0.134
27.46,76.76,0.134
27.48,76.90,0.134
27.51,77.04,0.134
27.54,77.19,0.134
27.57,77.33,0.134
27.60,77.47,0.134
27.63,77.61,0.134
27.65,77.75,0.134
27.68,77.89,0.135
27.71,78.04,0.135
27.74,78.18,0.135
27.77,78.32,0.135
27.79,78.46,0.135
27.82,78.60,0.135
27.85,78.74,0.135
27.88,78.89,0.135
27.91,79.03,0.135
27.94,79.17,0.135
27.97,79.31,0.135
27.99,79.45,0.135
28.02,79.60,0.135
28.05,79.74,0.135
28.08,79.88,0.135
28.11,80.02,0.135
28.13,80.16,0.135
28.16,80.30,0.135
28.19,80.45,0.136
28.22,80.59,0.136
28.25,80.73,0.136
28.28,80.87,0.136
28.31,81.01,0.136
28.33,81.15,0.136
28.36,81.30,0.136
28.39,81.44,0.136
28.42,81.58,0.136
28.45,81.72,0.136
28.48,81.86,0.136
28.50,82.00,0.136
28.53,82.15,0.136
28.56,82.29,0.136
28.59,82.43,0.136
28.62,82.57,0.136
28.64,82.71,0.136
28.67,82.85,0.136
28.70,83.00,0.136
28.73,83.14,0.136
28.76,83.28,0.136
28.79,83.42,0.136
28.82,83.56,0.136
28.84,83.71,0.136
28.87,83.85,0.136
28.90,83.99,0.136
28.93,84.13,0.136
28.96,84.27,0.136
28.98,84.42,0.136
29.01,84.56,0.136
29.04,84.70,0.136
29.07,84.84,0.136
29.10,84.98,0.136
29.13,85.12,0.136
29.16,85.26,0.136
29.18,85.41,0.137
29.21,85.55,0.137
29.24,85.69,0.137
29.27,85.83,0.137
29.30,85.97,0.137
29.33,86.11,0.137
29.35,86.26,0.137
29.38,86.40,0.137
29.41,86.54,0.137
29.44,86.68,0.137
29.47,86.82,0.137
29.49,86.96,0.137
29.52,87.11,0.137
29.55,87.25,0.137
29.58,87.39,0.137
29.61,87.53,0.137
29.64,87.67,0.137
29.67,87.81,0.137
29.69,87.96,0.137
29.72,88.10,0.137
29.75,88.24,0.137
29.78,88.38,0.137
29.81,88.52,0.137
29.83,88.67,0.137
29.86,88.81,0.138
29.89,88.95,0.138
29.92,89.09,0.138
29.95,89.23,0.138
29.98,89.38,0.138
30.01,89.52,0.138
30.03,89.66,0.138
30.06,89.80,0.138
30.09,89.94,0.138
30.12,90.08,0.138
30.15,90.22,0.138
30.18,90.37,0.138
30.20,90.51,0.138
30.23,90.65,0.138
30.26,90.79,0.138
30.29,90.93,0.138
30.32,91.08,0.138
30.34,91.22,0.139
30.37,91.36,0.139
30.40,91.50,0.139
30.43,91.64,0.139
30.46,91.78,0.139
30.49,91.93,0.139
30.52,92.07,0.139
30.54,92.21,0.139
30.57,92.35,0.139
30.60,92.49,0.139
30.63,92.63,0.139
30.66,92.78,0.139
30.68,92.92,0.139
30.71,93.06,0.139
30.74,93.20,0.139
30.77,93.34,0.139
30.80,93.48,0.139
30.83,93.63,0.139
30.86,93.77,0.139
30.88,93.91,0.139
30.91,94.05,0.139
30.94,94.19,0.139
30.97,94.34,0.140
31.00,94.48,0.140
31.03,94.62,0.140
31.05,94.76,0.140
31.08,94.90,0.140
31.11,95.05,0.140
31.14,95.19,0.140
31.17,95.33,0.140
31.19,95.47,0.140
31.22,95.61,0.140
31.25,95.75,0.140
31.28,95.89,0.140
31.31,96.04,0.140
31.34,96.18,0.140
31.37,96.32,0.140
31.39,96.46,0.140
31.42,96.60,0.140
31.45,96.74,0.140
31.48,96.89,0.141
31.51,97.03,0.141
31.53,97.17,0.141
31.56,97.31,0.141
31.59,97.45,0.141
31.62,97.60,0.141
31.65,97.74,0.141
31.68,97.88,0.141
31.71,98.02,0.141
31.73,98.16,0.141
31.76,98.30,0.141
31.79,98.44,0.141
31.82,98.59,0.141
31.85,98.73,0.141
31.88,98.87,0.141
31.90,99.01,0.141
31.93,99.15,0.141
31.96,99.30,0.141
31.99,99.44,0.141
32.02,99.58,0.141
32.04,99.72,0.141
32.07,99.86,0.141
32.10,100.00,0.141
32.13,100.15,0.141
32.16,100.29,0.141
32.19,100.43,0.142
32.22,100.57,0.142
32.24,100.71,0.142
32.27,100.86,0.142
32.30,101.00,0.142
32.33,101.14,0.142
32.36,101.28,0.142
32.38,101.42,0.142
32.41,101.56,0.142
32.44,101.70,0.142
32.47,101.85,0.142
32.50,101.99,0.142
32.53,102.13,0.142
32.56,102.27,0.142
32.58,102.41,0.142
32.61,102.55,0.142
32.64,102.70,0.142
32.67,102.84,0.142
32.70,102.98,0.142
32.73,103.12,0.142
32.75,103.26,0.142
32.78,103.40,0.142
32.81,103.55,0.142
32.84,103.69,0.142
32.87,103.83,0.142
32.89,103.97,0.143
32.92,104.11,0.142
32.95,104.26,0.143
32.98,104.40,0.143
33.01,104.54,0.143
33.04,104.68,0.143
33.07,104.82,0.143
33.09,104.96,0.143
33.12,105.11,0.143
33.15,105.25,0.143
33.18,105.39,0.143
33.21,105.53,0.143
33.23,105.67,0.143
33.26,105.82,0.143
33.29,105.96,0.143
33.32,106.10,0.143
33.35,106.24,0.143
33.38,106.38,0.143
33.41,106.52,0.143
33.43,106.67,0.143
33.46,106.81,0.143
33.49,106.95,0.143
33.52,107.09,0.143
33.55,107.23,0.143
33.58,107.37,0.144
33.60,107.51,0.144
33.63,107.66,0.144
33.66,107.80,0.144
33.69,107.94,0.144
33.72,108.08,0.144
33.74,108.22,0.144
33.77,108.37,0.144
33.80,108.51,0.144
33.83,108.65,0.144
33.86,108.79,0.144
33.89,108.93,0.144
33.92,109.07,0.144
33.94,109.22,0.144
33.97,109.36,0.144
34.00,109.50,0.144
34.03,109.64,0.144
34.06,109.78,0.144
34.08,109.92,0.144
34.11,110.07,0.144
34.14,110.21,0.144
34.17,110.35,0.144
34.20,110.49,0.144
34.23,110.63,0.144
34.26,110.77,0.144
34.28,110.92,0.144
34.31,111.06,0.144
34.34,111.20,0.145
34.37,111.34,0.145
34.40,111.48,0.145
34.43,111.62,0.145
34.45,111.77,0.145
34.48,111.91,0.145
34.51,112.05,0.145
34.54,112.19,0.145
34.57,112.33,0.145
34.59,112.47,0.145
34.62,112.62,0.145
34.65,112.76,0.145
34.68,112.90,0.145
34.71,113.04,0.145
34.74,113.18,0.145
34.76,113.33,0.145
34.79,113.47,0.145
34.82,113.61,0.146
34.85,113.75,0.146
34.88,113.89,0.146
34.91,114.04,0.146
34.94,114.17,0.146
34.96,114.32,0.146
34.99,114.46,0.146
35.02,114.60,0.146
35.05,114.74,0.146
35.08,114.88,0.146
35.11,115.03,0.146
35.13,115.17,0.146
35.16,115.31,0.146
35.19,115.45,0.146
35.22,115.59,0.146
35.25,115.74,0.146
35.28,115.88,0.146
35.30,116.02,0.147
35.33,116.16,0.147
35.36,116.30,0.147
35.39,116.44,0.147
35.42,116.59,0.147
35.44,116.73,0.147
35.47,116.87,0.147
35.50,117.01,0.147
35.53,117.15,0.147
35.56,117.29,0.147
35.59,117.44,0.147
35.61,117.58,0.147
35.64,117.72,0.147
35.67,117.86,0.147
35.70,118.00,0.147
35.73,118.14,0.147
35.76,118.28,0.147
35.79,118.43,0.147
35.81,118.57,0.147
35.84,118.71,0.147
35.87,118.85,0.147
35.90,118.99,0.147
35.93,119.14,0.147
35.96,119.28,0.147
35.98,119.42,0.148
36.01,119.56,0.148
36.04,119.70,0.148
36.07,119.84,0.148
36.10,119.99,0.148
36.13,120.13,0.148
36.15,120.27,0.148
36.18,120.41,0.148
36.21,120.55,0.148
36.24,120.70,0.148
36.27,120.84,0.148
36.29,120.98,0.148
36.32,121.12,0.148
36.35,121.26,0.148
36.38,121.40,0.148
36.41,121.54,0.148
36.44,121.69,0.148
36.46,121.83,0.148
36.49,121.97,0.148
36.52,122.11,0.148
36.55,122.25,0.148
36.58,122.39,0.149
36.61,122.54,0.149
36.64,122.68,0.149
36.66,122.82,0.149
36.69,122.96,0.149
36.72,123.10,0.149
36.75,123.25,0.149
36.78,123.39,0.149
36.81,123.53,0.149
36.83,123.67,0.149
36.86,123.81,0.149
36.89,123.96,0.149
36.92,124.10,0.149
36.95,124.24,0.149
36.98,124.38,0.149
37.00,124.52,0.150
37.03,124.66,0.150
37.06,124.81,0.150
37.09,124.95,0.150
37.12,125.09,0.150
37.14,125.23,0.150
37.17,125.37,0.150
37.20,125.51,0.150
37.23,125.66,0.150
37.26,125.80,0.150
37.29,125.94,0.150
37.31,126.08,0.150
37.34,126.22,0.150
37.37,126.37,0.150
37.40,126.51,0.150
37.43,126.65,0.150
37.46,126.79,0.150
37.49,126.93,0.150
37.51,127.07,0.150
37.54,127.21,0.151
37.57,127.35,0.151
37.60,127.50,0.151
37.63,127.64,0.151
37.66,127.78,0.151
37.68,127.92,0.151
37.71,128.06,0.151
37.74,128.20,0.151
37.77,128.35,0.151
37.80,128.49,0.151
37.83,128.63,0.151
37.85,128.77,0.151
37.88,128.91,0.151
37.91,129.05,0.151
37.94,129.20,0.151
37.97,129.34,0.151
37.99,129.48,0.151
38.02,129.62,0.152
38.05,129.76,0.152
38.08,129.91,0.152
38.11,130.05,0.152
38.14,130.19,0.152
38.16,130.33,0.152
38.19,130.47,0.152
38.22,130.62,0.152
38.25,130.76,0.152
38.28,130.90,0.152
38.31,131.04,0.152
38.34,131.18,0.152
38.36,131.32,0.152
38.39,131.47,0.152
38.42,131.61,0.152
38.45,131.75,0.152
38.48,131.89,0.152
38.51,132.03,0.152
38.53,132.17,0.152
38.56,132.31,0.153
38.59,132.46,0.153
38.62,132.60,0.153
38.65,132.74,0.153
38.68,132.88,0.153
38.70,133.02,0.153
38.73,133.16,0.153
38.76,133.31,0.153
38.79,133.45,0.153
38.82,133.59,0.153
38.84,133.73,0.153
38.87,133.88,0.153
38.90,134.02,0.153
38.93,134.16,0.153
38.96,134.30,0.154
38.99,134.44,0.154
39.01,134.58,0.154
39.04,134.72,0.154
39.07,134.87,0.154
39.10,135.01,0.154
39.13,135.15,0.154
39.16,135.29,0.154
39.19,135.43,0.154
39.21,135.57,0.154
39.24,135.72,0.154
39.27,135.86,0.154
39.30,136.00,0.154
39.33,136.14,0.154
39.36,136.28,0.154
39.38,136.42,0.154
39.41,136.56,0.154
39.44,136.71,0.154
39.47,136.85,0.155
39.50,136.99,0.155
39.53,137.14,0.155
39.55,137.28,0.155
39.58,137.42,0.155
39.61,137.56,0.155
39.64,137.71,0.155
39.67,137.85,0.155
39.69,137.99,0.155
39.72,138.13,0.155
39.75,138.27,0.155
39.78,138.41,0.155
39.81,138.55,0.155
39.84,138.70,0.154
39.86,138.84,0.154
39.89,138.98,0.154
39.92,139.12,0.154
39.95,139.26,0.154
39.98,139.40,0.154
40.01,139.54,0.154
40.04,139.69,0.154
40.06,139.83,0.154
40.09,139.97,0.154
40.12,140.11,0.154
40.15,140.25,0.154
40.18,140.39,0.154
40.21,140.54,0.154
40.23,140.68,0.154
40.26,140.82,0.155
40.29,140.96,0.155
40.32,141.10,0.155
40.35,141.24,0.155
40.38,141.39,0.155
40.40,141.53,0.155
40.43,141.67,0.155
40.46,141.81,0.155
40.49,141.95,0.155
40.52,142.09,0.155
40.54,142.24,0.155
40.57,142.38,0.155
40.60,142.52,0.155
40.63,142.66,0.155
40.66,142.80,0.155
40.69,142.94,0.155
40.71,143.08,0.155
40.74,143.23,0.155
40.77,143.37,0.155
40.80,143.51,0.155
40.83,143.65,0.155
40.86,143.79,0.155
40.89,143.93,0.155
40.91,144.08,0.155
40.94,144.22,0.155
40.97,144.36,0.155
41.00,144.50,0.155
41.03,144.64,0.155
41.06,144.79,0.155
41.08,144.93,0.156
41.11,145.07,0.156
41.14,145.21,0.156
41.17,145.35,0.156
41.20,145.49,0.156
41.23,145.63,0.156
41.25,145.78,0.156
41.28,145.92,0.156
41.31,146.06,0.156
41.34,146.20,0.156
41.37,146.34,0.156
41.39,146.48,0.156
41.42,146.63,0.156
41.45,146.77,0.156
41.48,146.91,0.156
41.51,147.05,0.156
41.54,147.19,0.156
41.56,147.33,0.156
41.59,147.48,0.156
41.62,147.62,0.156
41.65,147.76,0.157
41.68,147.90,0.157
41.71,148.04,0.157
41.74,148.19,0.157
41.76,148.33,0.157
41.79,148.47,0.157
41.82,148.61,0.157
41.85,148.75,0.157
41.88,148.89,0.157
41.91,149.04,0.157
41.93,149.18,
41.96,149.32,
41.99,,

[step]
Ramp 10.00 °C/min to -60.00 °C
Time,Temperature,Heat Flow (Normalized)
min,°C,W/g
42.99,150.11,-0.036
43.00,150.11,-0.036
43.02,150.11,-0.036
43.03,150.10,-0.036
43.05,150.09,-0.036
43.06,150.07,-0.036
43.08,150.03,-0.043
43.09,149.98,-0.067
43.11,149.92,-0.096
43.12,149.84,-0.131
43.14,149.75,-0.167
43.15,149.64,-0.205
43.17,149.53,-0.236
43.18,149.42,-0.264
43.20,149.30,-0.287
43.21,149.17,-0.307
43.23,149.04,-0.323
43.24,148.91,-0.336
43.26,148.78,-0.347
43.27,148.64,-0.358
43.29,148.50,-0.364
43.30,148.36,-0.373
43.32,148.22,-0.378
43.33,148.08,-0.384
43.35,147.94,-0.389
43.36,147.79,-0.391
43.38,147.65,-0.395
43.39,147.51,-0.399
43.41,147.36,-0.400
43.42,147.21,-0.402
43.44,147.07,-0.403
43.45,146.92,-0.405
43.47,146.78,-0.406
43.48,146.63,-0.407
43.50,146.48,-0.408
43.51,146.33,-0.408
43.53,146.19,-0.409
43.54,146.04,-0.410
43.56,145.89,-0.410
43.57,145.74,-0.411
43.59,145.60,-0.411
43.60,145.45,-0.411
43.62,145.30,-0.412
43.63,145.15,-0.412
43.65,145.01,-0.412
43.66,144.86,-0.412
43.68,144.71,-0.413
43.69,144.56,-0.413
43.71,144.41,-0.413
43.72,144.26,-0.413
43.74,144.12,-0.414
43.75,143.97,-0.414
43.77,143.82,-0.414
43.78,143.67,-0.415
43.80,143.52,-0.415
43.81,143.37,-0.415
43.83,143.22,-0.415
43.84,143.07,-0.416
43.86,142.92,-0.416
43.87,142.78,-0.416
43.89,142.63,-0.416
43.90,142.48,-0.416
43.92,142.33,-0.417
43.93,142.18,-0.417
43.95,142.03,-0.417
43.96,141.88,-0.417
43.98,141.73,-0.417
43.99,141.58,-0.417
44.01,141.43,-0.418
44.02,141.29,-0.418
44.04,141.14,-0.418
44.05,140.99,-0.418
44.07,140.84,-0.418
44.08,140.69,-0.418
44.10,140.54,-0.418
44.11,140.39,-0.418
44.13,140.24,-0.418
44.14,140.09,-0.418
44.16,139.94,-0.418
44.17,139.79,-0.418
44.19,139.64,-0.418
44.20,139.49,-0.418
44.22,139.34,-0.418
44.23,139.19,-0.418
44.25,139.04,-0.418
44.26,138.89,-0.418
44.28,138.74,-0.418
44.29,138.60,-0.418
44.31,138.45,-0.418
44.32,138.30,-0.418
44.34,138.15,-0.418
44.35,138.00,-0.418
44.37,137.85,-0.418
44.38,137.70,-0.418
44.40,137.55,-0.418
44.41,137.40,-0.418
44.43,137.25,-0.418
44.44,137.10,-0.418
44.46,136.95,-0.418
44.47,136.80,-0.418
44.49,136.65,-0.418
44.50,136.50,-0.418
44.52,136.35,-0.418
44.53,136.20,-0.418
44.55,136.05,-0.418
44.56,135.90,-0.418
44.58,135.75,-0.418
44.59,135.60,-0.418
44.61,135.45,-0.418
44.62,135.30,-0.418
44.64,135.15,-0.417
44.65,135.00,-0.417
44.67,134.85,-0.417
44.68,134.70,-0.417
44.70,134.55,-0.417
44.71,134.40,-0.417
44.73,134.25,-0.417
44.74,134.11,-0.417
44.76,133.96,-0.417
44.77,133.81,-0.417
44.79,133.65,-0.417
44.80,133.51,-0.416
44.82,133.36,-0.416
44.83,133.21,-0.416
44.85,133.06,-0.416
44.86,132.91,-0.416
44.88,132.76,-0.416
44.89,132.61,-0.416
44.91,132.46,-0.416
44.92,132.31,-0.416
44.94,132.16,-0.416
44.95,132.01,-0.416
44.97,131.86,-0.416
44.98,131.71,-0.415
45.00,131.56,-0.415
45.01,131.41,-0.415
45.03,131.26,-0.415
45.04,131.11,-0.415
45.06,130.96,-0.415
45.07,130.81,-0.415
45.09,130.66,-0.415
45.10,130.51,-0.415
45.12,130.36,-0.415
45.13,130.21,-0.414
45.15,130.06,-0.414
45.16,129.91,-0.414
45.18,129.76,-0.414
45.19,129.61,-0.414
45.21,129.46,-0.414
45.22,129.31,-0.414
45.24,129.16,-0.414
45.25,129.01,-0.413
45.27,128.86,-0.413
45.28,128.71,-0.413
45.30,128.56,-0.413
45.31,128.41,-0.413
45.33,128.26,-0.413
45.34,128.11,-0.413
45.36,127.96,-0.413
45.37,127.81,-0.412
45.39,127.66,-0.412
45.40,127.51,-0.412
45.42,127.36,-0.412
45.43,127.21,-0.412
45.45,127.06,-0.412
45.46,126.91,-0.412
45.48,126.76,-0.412
45.49,126.61,-0.412
45.51,126.46,-0.412
45.52,126.31,-0.411
45.54,126.16,-0.411
45.55,126.01,-0.411
45.57,125.86,-0.411
45.58,125.71,-0.411
45.60,125.56,-0.411
45.61,125.41,-0.411
45.63,125.26,-0.411
45.64,125.11,-0.411
45.66,124.97,-0.411
45.67,124.81,-0.410
45.69,124.66,-0.410
45.70,124.51,-0.410
45.72,124.37,-0.410
45.73,124.21,-0.410
45.75,124.06,-0.410
45.76,123.92,-0.410
45.78,123.77,-0.410
45.79,123.61,-0.409
45.81,123.47,-0.409
45.82,123.32,-0.409
45.84,123.17,-0.409
45.85,123.02,-0.409
45.87,122.87,-0.409
45.88,122.72,-0.409
45.90,122.57,-0.408
45.91,122.42,-0.408
45.93,122.27,-0.408
45.94,122.12,-0.408
45.96,121.97,-0.408
45.97,121.82,-0.408
45.99,121.67,-0.408
46.00,121.52,-0.408
46.02,121.37,-0.407
46.03,121.22,-0.407
46.05,121.07,-0.407
46.06,120.92,-0.407
46.08,120.77,-0.407
46.09,120.62,-0.407
46.11,120.47,-0.407
46.12,120.32,-0.407
46.14,120.17,-0.407
46.15,120.02,-0.406
46.17,119.87,-0.406
46.18,119.72,-0.406
46.20,119.57,-0.406
46.21,119.42,-0.406
46.23,119.27,-0.406
46.24,119.12,-0.406
46.26,118.97,-0.406
46.27,118.82,-0.406
46.29,118.67,-0.406
46.30,118.52,-0.405
46.32,118.37,-0.405
46.33,118.22,-0.405
46.35,118.07,-0.405
46.36,117.92,-0.405
46.38,117.77,-0.405
46.39,117.62,-0.405
46.41,117.47,-0.405
46.42,117.32,-0.405
46.44,117.17,-0.404
46.45,117.03,-0.404
46.47,116.88,-0.404
46.48,116.72,-0.404
46.50,116.58,-0.404
46.51,116.43,-0.404
46.53,116.28,-0.404
46.54,116.12,-0.404
46.56,115.97,-0.404
46.57,115.83,-0.404
46.59,115.68,-0.404
46.60,115.53,-0.403
46.62,115.38,-0.403
46.63,115.23,-0.403
46.65,115.08,-0.403
46.66,114.93,-0.403
46.68,114.78,-0.403
46.69,114.63,-0.403
46.71,114.48,-0.403
46.72,114.33,-0.403
46.74,114.18,-0.403
46.75,114.03,-0.403
46.77,113.88,-0.403
46.78,113.73,-0.402
46.80,113.58,-0.402
46.81,113.43,-0.402
46.83,113.28,-0.402
46.84,113.13,-0.402
46.86,112.98,-0.402
46.87,112.83,-0.402
46.89,112.68,-0.402
46.90,112.53,-0.402
46.92,112.38,-0.402
46.93,112.23,-0.401
46.95,112.08,-0.401
46.96,111.93,-0.401
46.98,111.78,-0.401
46.99,111.63,-0.401
47.01,111.48,-0.401
47.02,111.33,-0.401
47.04,111.18,-0.401
47.05,111.03,-0.401
47.07,110.88,-0.401
47.08,110.73,-0.401
47.10,110.58,-0.400
47.11,110.43,-0.401
47.13,110.28,-0.400
47.14,110.13,-0.400
47.16,109.98,-0.400
47.17,109.83,-0.400
47.19,109.68,-0.400
47.20,109.53,-0.400
47.22,109.38,-0.400
47.23,109.23,-0.400
47.25,109.08,-0.400
47.26,108.93,-0.400
47.28,108.78,-0.399
47.29,108.63,-0.399
47.31,108.48,-0.399
47.32,108.33,-0.399
47.34,108.18,-0.399
47.35,108.03,-0.399
47.37,107.89,-0.399
47.38,107.73,-0.399
47.40,107.58,-0.399
47.41,107.44,-0.399
47.43,107.28,-0.399
47.44,107.14,-0.399
47.46,106.99,-0.399
47.47,106.84,-0.398
47.49,106.69,-0.398
47.50,106.54,-0.398
47.52,106.39,-0.398
47.53,106.24,-0.398
47.55,106.09,-0.398
47.56,105.94,-0.398
47.58,105.79,-0.398
47.59,105.64,-0.398
47.61,105.49,-0.398
47.62,105.34,-0.397
47.64,105.19,-0.397
47.65,105.04,-0.397
47.67,104.89,-0.397
47.68,104.74,-0.397
47.70,104.59,-0.397
47.71,104.44,-0.397
47.73,104.29,-0.397
47.74,104.14,-0.397
47.76,103.99,-0.397
47.77,103.84,-0.397
47.79,103.69,-0.396
47.80,103.54,-0.396
47.82,103.39,-0.396
47.83,103.24,-0.396
47.85,103.09,-0.396
47.86,102.94,-0.396
47.88,102.79,-0.396
47.89,102.64,-0.396
47.91,102.49,-0.396
47.92,102.34,-0.396
47.94,102.19,-0.396
47.95,102.04,-0.395
47.97,101.89,-0.395
47.98,101.74,-0.395
48.00,101.59,-0.395
48.01,101.44,-0.395
48.03,101.29,-0.395
48.04,101.14,-0.395
48.06,100.99,-0.395
48.07,100.84,-0.395
[...]
142.62,2.51,0.114
142.65,2.65,0.114
142.68,2.79,0.114
142.71,2.93,0.114
142.74,3.08,0.114
142.77,3.22,0.114
142.79,3.36,0.114
142.82,3.50,0.114
142.85,3.64,0.115
142.88,3.78,0.115
142.91,3.93,0.115
142.93,4.07,0.115
142.96,4.21,0.115
142.99,4.35,0.115
143.02,4.49,0.115
143.05,4.64,0.115
143.08,4.78,0.115
143.10,4.92,0.115
143.13,5.06,0.115
143.16,5.20,0.115
143.19,5.34,0.115
143.22,5.49,0.115
143.25,5.63,0.115
143.28,5.77,0.115
143.30,5.91,0.115
143.33,6.05,0.115
143.36,6.19,0.115
143.39,6.34,0.115
143.42,6.48,0.115
143.45,6.62,0.115
143.47,6.76,0.115
143.50,6.90,0.115
143.53,7.05,0.115
143.56,7.19,0.116
143.59,7.33,0.115
143.62,7.47,0.116
143.64,7.61,0.116
143.67,7.75,0.116
143.70,7.89,0.116
143.73,8.04,0.116
143.76,8.18,0.116
143.78,8.32,0.116
143.81,8.46,0.116
143.84,8.60,0.116
143.87,8.74,0.116
143.90,8.88,0.116
143.93,9.03,0.116
143.95,9.17,0.116
143.98,9.31,0.116
144.01,9.45,0.116
144.04,9.60,0.116
144.07,9.74,0.116
144.10,9.88,0.116
144.13,10.02,0.116
144.15,10.16,0.116
144.18,10.30,0.116
144.21,10.45,0.116
144.24,10.59,0.117
144.27,10.73,0.117
144.30,10.87,0.117
144.32,11.01,0.117
144.35,11.16,0.117
144.38,11.30,0.117
144.41,11.44,0.117
144.44,11.58,0.117
144.47,11.72,0.117
144.49,11.86,0.117
144.52,12.01,0.117
144.55,12.15,0.117
144.58,12.29,0.117
144.61,12.43,0.117
144.63,12.57,0.117
144.66,12.71,0.117
144.69,12.86,0.117
144.72,13.00,0.117
144.75,13.14,0.117
144.78,13.28,0.117
144.80,13.42,0.117
144.83,13.57,0.117
144.86,13.71,0.117
144.89,13.85,0.117
144.92,13.99,0.117
144.95,14.13,0.117
144.98,14.28,0.117
145.00,14.42,0.117
145.03,14.56,0.117
145.06,14.70,0.117
145.09,14.84,0.118
145.12,14.99,0.118
145.15,15.13,0.118
145.17,15.27,0.118
145.20,15.41,0.118
145.23,15.55,0.118
145.26,15.69,0.118
145.29,15.84,0.118
145.32,15.98,0.118
145.34,16.12,0.118
145.37,16.26,0.118
145.40,16.40,0.118
145.43,16.54,0.118
145.46,16.69,0.118
145.48,16.83,0.118
145.51,16.97,0.118
145.54,17.11,0.118
145.57,17.25,0.118
145.60,17.39,0.118
145.63,17.54,0.118
145.65,17.68,0.118
145.68,17.82,0.118
145.71,17.96,0.118
145.74,18.10,0.118
145.77,18.24,0.119
145.80,18.39,0.119
145.83,18.53,0.119
145.85,18.67,0.119
145.88,18.81,0.119
145.91,18.95,0.119
145.94,19.10,0.119
145.97,19.24,0.119
146.00,19.38,0.119
146.02,19.52,0.119
146.05,19.66,0.119
146.08,19.80,0.119
146.11,19.94,0.119
146.14,20.09,0.119
146.17,20.23,0.119
146.19,20.37,0.119
146.22,20.51,0.119
146.25,20.65,0.119
146.28,20.79,0.119
146.31,20.94,0.119
146.33,21.08,0.119
146.36,21.22,0.120
146.39,21.36,0.120
146.42,21.50,0.120
146.45,21.65,0.120
146.48,21.79,0.120
146.50,21.93,0.120
146.53,22.07,0.120
146.56,22.21,0.120
146.59,22.35,0.120
146.62,22.50,0.120
146.65,22.64,0.120
146.68,22.78,0.120
146.70,22.92,0.120
146.73,23.06,0.120
146.76,23.21,0.120
146.79,23.35,0.120
146.82,23.49,0.120
146.85,23.63,0.120
146.87,23.77,0.120
146.90,23.91,0.120
146.93,24.06,0.120
146.96,24.20,0.120
146.99,24.34,0.121
147.02,24.48,0.121
147.04,24.62,0.121
147.07,24.76,0.121
147.10,24.91,0.121
147.13,25.05,0.121
147.16,25.19,0.121
147.18,25.33,0.121
147.21,25.47,0.121
147.24,25.62,0.121
147.27,25.76,0.121
147.30,25.90,0.121
147.33,26.04,0.121
147.35,26.18,0.121
147.38,26.32,0.121
147.41,26.47,0.121
147.44,26.61,0.121
147.47,26.75,0.121
147.50,26.89,0.121
147.53,27.03,0.121
147.55,27.18,0.121
147.58,27.32,0.121
147.61,27.46,0.121
147.64,27.60,0.121
147.67,27.74,0.121
147.70,27.88,0.121
147.72,28.03,0.121
147.75,28.17,0.121
147.78,28.31,0.122
147.81,28.45,0.122
147.84,28.59,0.122
147.87,28.73,0.122
147.89,28.88,0.122
147.92,29.02,0.122
147.95,29.16,0.122
147.98,29.30,0.122
148.01,29.44,0.122
148.03,29.59,0.122
148.06,29.73,0.122
148.09,29.87,0.122
148.12,30.01,0.122
148.15,30.15,0.122
148.18,30.29,0.122
148.20,30.44,0.122
148.23,30.58,0.122
148.26,30.72,0.122
148.29,30.86,0.122
148.32,31.00,0.122
148.35,31.15,0.122
148.38,31.29,0.122
148.40,31.43,0.122
148.43,31.57,0.122
148.46,31.71,0.122
148.49,31.85,0.122
148.52,31.99,0.122
148.55,32.14,0.123
148.57,32.28,0.123
148.60,32.42,0.123
148.63,32.56,0.123
148.66,32.70,0.123
148.69,32.84,0.123
148.72,32.99,0.123
148.74,33.13,0.123
148.77,33.27,0.123
148.80,33.41,0.123
148.83,33.55,0.123
148.86,33.70,0.123
148.88,33.84,0.123
148.91,33.98,0.123
148.94,34.12,0.123
148.97,34.26,0.123
149.00,34.40,0.123
149.03,34.55,0.123
149.05,34.69,0.123
149.08,34.83,0.123
149.11,34.97,0.123
149.14,35.11,0.123
149.17,35.25,0.123
149.20,35.40,0.123
149.23,35.54,0.123
149.25,35.68,0.123
149.28,35.82,0.123
149.31,35.96,0.123
149.34,36.11,0.124
149.37,36.25,0.124
149.40,36.39,0.124
149.42,36.53,0.124
149.45,36.67,0.124
149.48,36.81,0.124
149.51,36.96,0.124
149.54,37.10,0.124
149.57,37.24,0.124
149.59,37.38,0.124
149.62,37.52,0.124
149.65,37.66,0.124
149.68,37.81,0.124
149.71,37.95,0.124
149.73,38.09,0.124
149.76,38.23,0.124
149.79,38.37,0.124
149.82,38.52,0.124
149.85,38.66,0.124
149.88,38.80,0.124
149.90,38.94,0.124
149.93,39.08,0.124
149.96,39.22,0.124
149.99,39.37,0.124
150.02,39.51,0.124
150.05,39.65,0.125
150.08,39.79,0.125
150.10,39.93,0.125
150.13,40.08,0.125
150.16,40.22,0.125
150.19,40.36,0.125
150.22,40.50,0.125
150.25,40.64,0.125
150.27,40.78,0.125
150.30,40.92,0.125
150.33,41.07,0.125
150.36,41.21,0.125
150.39,41.35,0.125
150.42,41.49,0.125
150.44,41.63,0.125
150.47,41.78,0.125
150.50,41.92,0.125
150.53,42.06,0.125
150.56,42.20,0.125
150.58,42.34,0.125
150.61,42.48,0.125
150.64,42.63,0.125
150.67,42.77,0.125
150.70,42.91,0.125
150.73,43.05,0.125
150.75,43.19,0.125
150.78,43.33,0.125
150.81,43.47,0.125
150.84,43.62,0.125
150.87,43.76,0.126
150.90,43.90,0.126
150.93,44.04,0.126
150.95,44.19,0.126
150.98,44.33,0.126
151.01,44.47,0.126
151.04,44.61,0.126
151.07,44.75,0.126
151.10,44.89,0.126
151.12,45.04,0.126
151.15,45.18,0.126
151.18,45.32,0.126
151.21,45.46,0.126
151.24,45.60,0.126
151.27,45.75,0.126
151.29,45.89,0.126
151.32,46.03,0.126
151.35,46.17,0.126
151.38,46.31,0.126
151.41,46.45,0.126
151.43,46.60,0.126
151.46,46.74,0.126
151.49,46.88,0.126
151.52,47.02,0.126
151.55,47.16,0.126
151.58,47.30,0.126
151.60,47.45,0.126
151.63,47.59,0.126
151.66,47.73,0.126
151.69,47.87,0.126
151.72,48.01,0.126
151.75,48.16,0.126
151.78,48.30,0.127
151.80,48.44,0.127
151.83,48.58,0.127
151.86,48.72,0.127
151.89,48.86,0.127
151.92,49.00,0.127
151.95,49.15,0.127
151.97,49.29,0.127
152.00,49.43,0.127
152.03,49.57,0.127
152.06,49.71,0.127
152.09,49.86,0.127
152.12,50.00,0.127
152.14,50.14,0.127
152.17,50.28,0.127
152.20,50.42,0.127
152.23,50.57,0.127
152.26,50.71,0.127
152.28,50.85,0.128
152.31,50.99,0.128
152.34,51.13,0.128
152.37,51.27,0.128
152.40,51.41,0.128
152.43,51.56,0.128
152.45,51.70,0.128
152.48,51.84,0.128
152.51,51.98,0.128
152.54,52.12,0.128
152.57,52.27,0.128
152.60,52.41,0.128
152.63,52.55,0.128
152.65,52.69,0.128
152.68,52.83,0.128
152.71,52.97,0.128
152.74,53.12,0.128
152.77,53.26,0.128
152.80,53.40,0.128
152.82,53.54,0.128
152.85,53.68,0.128
152.88,53.83,0.128
152.91,53.97,0.128
152.94,54.11,0.129
152.97,54.25,0.129
152.99,54.39,0.129
153.02,54.53,0.129
153.05,54.68,0.129
153.08,54.82,0.129
153.11,54.96,0.129
153.13,55.10,0.129
153.16,55.24,0.129
153.19,55.38,0.129
153.22,55.53,0.129
153.25,55.67,0.129
153.28,55.81,0.129
153.30,55.95,0.129
153.33,56.09,0.129
153.36,56.23,0.129
153.39,56.38,0.129
153.42,56.52,0.129
153.45,56.66,0.129
153.48,56.80,0.129
153.50,56.94,0.129
153.53,57.09,0.129
153.56,57.23,0.129
153.59,57.37,0.129
153.62,57.51,0.130
153.65,57.65,0.130
153.67,57.79,0.130
153.70,57.93,0.130
153.73,58.08,0.130
153.76,58.22,0.130
153.79,58.36,0.130
153.82,58.50,0.130
153.84,58.65,0.130
153.87,58.79,0.130
153.90,58.93,0.130
153.93,59.07,0.130
153.96,59.21,0.130
153.98,59.35,0.130
154.01,59.50,0.130
154.04,59.64,0.130
154.07,59.78,0.130
154.10,59.92,0.130
154.13,60.06,0.130
154.15,60.20,0.130
154.18,60.35,0.130
154.21,60.49,0.130
154.24,60.63,0.130
154.27,60.77,0.131
154.30,60.91,0.131
154.33,61.05,0.131
154.35,61.20,0.131
154.38,61.34,0.131
154.41,61.48,0.131
154.44,61.62,0.131
154.47,61.76,0.131
154.50,61.91,0.131
154.52,62.05,0.131
154.55,62.19,0.131
154.58,62.33,0.131
154.61,62.47,0.131
154.64,62.61,0.131
154.67,62.75,0.131
154.69,62.90,0.131
154.72,63.04,0.131
154.75,63.18,0.131
154.78,63.32,0.131
154.81,63.46,0.131
154.83,63.60,0.131
154.86,63.75,0.131
154.89,63.89,0.131
154.92,64.03,0.131
154.95,64.17,0.131
154.98,64.31,0.132
155.00,64.46,0.132
155.03,64.60,0.132
155.06,64.74,0.132
155.09,64.88,0.132
155.12,65.02,0.132
155.15,65.17,0.132
155.18,65.31,0.132
155.20,65.45,0.132
155.23,65.59,0.132
155.26,65.73,0.132
155.29,65.88,0.132
155.32,66.02,0.132
155.35,66.16,0.132
155.37,66.30,0.132
155.40,66.44,0.132
155.43,66.58,0.132
155.46,66.73,0.132
155.49,66.87,0.132
155.52,67.01,0.132
155.54,67.15,0.132
155.57,67.29,0.132
155.60,67.43,0.132
155.63,67.57,0.132
155.66,67.72,0.133
155.68,67.86,0.133
155.71,68.00,0.133
155.74,68.14,0.133
155.77,68.28,0.133
155.80,68.43,0.133
155.83,68.57,0.133
155.85,68.71,0.133
155.88,68.85,0.133
155.91,68.99,0.133
155.94,69.13,0.133
155.97,69.28,0.133
156.00,69.42,0.133
156.03,69.56,0.133
156.05,69.70,0.133
156.08,69.84,0.133
156.11,69.98,0.133
156.14,70.13,0.133
156.17,70.27,0.133
156.20,70.41,0.133
156.22,70.55,0.134
156.25,70.69,0.134
156.28,70.83,0.134
156.31,70.98,0.134
156.34,71.12,0.134
156.37,71.26,0.134
156.39,71.40,0.134
156.42,71.54,0.134
156.45,71.68,0.134
156.48,71.83,0.134
156.51,71.97,0.134
156.53,72.11,0.134
156.56,72.25,0.134
156.59,72.39,0.134
156.62,72.53,0.134
156.65,72.68,0.134
156.68,72.82,0.134
156.70,72.96,0.134
156.73,73.10,0.134
156.76,73.24,0.134
156.79,73.39,0.134
156.82,73.53,0.134
156.85,73.67,0.135
156.88,73.81,0.135
156.90,73.95,0.135
156.93,74.10,0.135
156.96,74.24,0.135
156.99,74.38,0.135
157.02,74.52,0.135
157.05,74.66,0.135
157.07,74.80,0.135
157.10,74.94,0.135
157.13,75.09,0.135
157.16,75.23,0.135
157.19,75.37,0.135
157.22,75.51,0.135
157.24,75.65,0.135
157.27,75.79,0.135
157.30,75.94,0.135
157.33,76.08,0.135
157.36,76.22,0.135
157.38,76.36,0.135
157.41,76.50,0.135
157.44,76.65,0.135
157.47,76.79,0.135
157.50,76.93,0.135
157.53,77.07,0.135
157.55,77.21,0.135
157.58,77.36,0.136
157.61,77.50,0.136
157.64,77.64,0.136
157.67,77.78,0.136
157.70,77.92,0.136
157.73,78.06,0.136
157.75,78.20,0.136
157.78,78.35,0.136
157.81,78.49,0.136
157.84,78.63,0.136
157.87,78.77,0.136
157.90,78.91,0.136
157.92,79.05,0.136
157.95,79.20,0.136
157.98,79.34,0.136
158.01,79.48,0.136
158.04,79.62,0.136
158.07,79.76,0.136
158.09,79.91,0.136
158.12,80.05,0.136
158.15,80.19,0.136
158.18,80.33,0.136
158.21,80.47,0.136
158.23,80.62,0.136
158.26,80.76,0.136
158.29,80.90,0.137
158.32,81.04,0.137
158.35,81.18,0.137
158.38,81.32,0.137
158.40,81.46,0.137
158.43,81.61,0.137
158.46,81.75,0.137
158.49,81.89,0.137
158.52,82.03,0.137
158.55,82.17,0.137
158.58,82.31,0.137
158.60,82.46,0.137
158.63,82.60,0.137
158.66,82.74,0.137
158.69,82.88,0.137
158.72,83.02,0.137
158.75,83.17,0.137
158.77,83.31,0.137
158.80,83.45,0.137
158.83,83.59,0.137
158.86,83.73,0.137
158.89,83.87,0.137
158.92,84.02,0.137
158.94,84.16,0.137
158.97,84.30,0.137
159.00,84.44,0.137
159.03,84.58,0.137
159.06,84.72,0.137
159.08,84.87,0.137
159.11,85.01,0.138
159.14,85.15,0.138
159.17,85.29,0.138
159.20,85.43,0.138
159.23,85.58,0.138
159.25,85.72,0.138
159.28,85.86,0.138
159.31,86.00,0.138
159.34,86.14,0.138
159.37,86.28,0.138
159.40,86.42,0.138
159.43,86.57,0.138
159.45,86.71,0.138
159.48,86.85,0.138
159.51,86.99,0.138
159.54,87.13,0.138
159.57,87.28,0.138
159.60,87.42,0.138
159.62,87.56,0.138
159.65,87.70,0.138
159.68,87.84,0.138
159.71,87.98,0.138
159.74,88.12,0.138
159.77,88.27,0.138
159.79,88.41,0.138
159.82,88.55,0.139
159.85,88.69,0.139
159.88,88.83,0.139
159.91,88.98,0.139
159.93,89.12,0.139
159.96,89.26,0.139
159.99,89.40,0.139
160.02,89.54,0.139
160.05,89.69,0.139
160.08,89.83,0.139
160.10,89.97,0.139
160.13,90.11,0.139
160.16,90.25,0.139
160.19,90.39,0.139
160.22,90.54,0.140
160.25,90.68,0.140
160.28,90.82,0.140
160.30,90.96,0.140
160.33,91.10,0.140
160.36,91.24,0.140
160.39,91.39,0.140
160.42,91.53,0.140
160.45,91.67,0.140
160.47,91.81,0.140
160.50,91.95,0.140
160.53,92.09,0.140
160.56,92.24,0.140
160.59,92.38,0.140
160.62,92.52,0.140
160.64,92.66,0.140
160.67,92.80,0.140
160.70,92.95,0.140
160.73,93.09,0.140
160.76,93.23,0.141
160.78,93.37,0.141
160.81,93.51,0.141
160.84,93.65,0.141
160.87,93.80,0.141
160.90,93.94,0.141
160.93,94.08,0.141
160.95,94.22,0.141
160.98,94.36,0.141
161.01,94.50,0.141
161.04,94.65,0.141
161.07,94.79,0.141
161.10,94.93,0.141
161.13,95.07,0.141
161.15,95.21,0.141
161.18,95.35,0.141
161.21,95.50,0.141
161.24,95.64,0.141
161.27,95.78,0.141
161.30,95.92,0.141
161.32,96.06,0.142
161.35,96.20,0.142
161.38,96.35,0.142
161.41,96.49,0.142
161.44,96.63,0.142
161.47,96.77,0.142
161.49,96.91,0.142
161.52,97.05,0.142
161.55,97.20,0.142
161.58,97.34,0.142
161.61,97.48,0.142
161.63,97.62,0.142
161.66,97.76,0.142
161.69,97.91,0.142
161.72,98.05,0.142
161.75,98.19,0.142
161.78,98.33,0.142
161.80,98.47,0.142
161.83,98.61,0.142
161.86,98.76,0.142
161.89,98.90,0.142
161.92,99.04,0.142
161.95,99.18,0.143
161.98,99.32,0.143
162.00,99.46,0.143
162.03,99.60,0.143
162.06,99.75,0.143
162.09,99.89,0.143
162.12,100.03,0.143
162.15,100.17,0.143
162.17,100.32,0.143
162.20,100.46,0.143
162.23,100.60,0.143
162.26,100.74,0.143
162.29,100.88,0.143
162.32,101.02,0.143
162.34,101.16,0.143
162.37,101.31,0.143
162.40,101.45,0.143
162.43,101.59,0.143
162.46,101.73,0.143
162.48,101.87,0.144
162.51,102.02,0.144
162.54,102.16,0.144
162.57,102.30,0.144
162.60,102.44,0.144
162.63,102.58,0.144
162.65,102.72,0.144
162.68,102.86,0.144
162.71,103.01,0.144
162.74,103.15,0.144
162.77,103.29,0.144
162.80,103.43,0.144
162.83,103.57,0.144
162.85,103.72,0.144
162.88,103.86,0.144
162.91,104.00,0.144
162.94,104.14,0.144
162.97,104.28,0.144
163.00,104.42,0.144
163.02,104.57,0.144
163.05,104.71,0.144
163.08,104.85,0.144
163.11,104.99,0.144
163.14,105.13,0.145
163.17,105.27,0.145
163.19,105.42,0.145
163.22,105.56,0.145
163.25,105.70,0.145
163.28,105.84,0.145
163.31,105.98,0.145
163.33,106.13,0.145
163.36,106.27,0.145
163.39,106.41,0.145
163.42,106.55,0.145
163.45,106.69,0.145
163.48,106.83,0.145
163.50,106.97,0.145
163.53,107.12,0.145
163.56,107.26,0.145
163.59,107.40,0.145
163.62,107.54,0.145
163.65,107.68,0.145
163.68,107.83,0.145
163.70,107.97,0.145
163.73,108.11,0.145
163.76,108.25,0.145
163.79,108.39,0.145
163.82,108.53,0.145
163.85,108.68,0.146
163.87,108.82,0.146
163.90,108.96,0.146
163.93,109.10,0.146
163.96,109.24,0.146
163.99,109.38,0.146
164.02,109.53,0.146
164.04,109.67,0.146
164.07,109.81,0.146
164.10,109.95,0.146
164.13,110.09,0.146
164.16,110.23,0.146
164.18,110.38,0.146
164.21,110.52,0.146
164.24,110.66,0.146
164.27,110.80,0.146
164.30,110.94,0.146
164.33,111.08,0.146
164.35,111.23,0.146
164.38,111.37,0.146
164.41,111.51,0.146
164.44,111.65,0.147
164.47,111.79,0.147
164.50,111.94,0.147
164.53,112.08,0.147
164.55,112.22,0.147
164.58,112.36,0.147
164.61,112.50,0.147
164.64,112.64,0.147
164.67,112.79,0.147
164.70,112.93,0.147
164.72,113.07,0.147
164.75,113.21,0.147
164.78,113.35,0.147
164.81,113.49,0.147
164.84,113.63,0.147
164.87,113.78,0.147
164.89,113.92,0.147
164.92,114.06,0.147
164.95,114.20,0.147
164.98,114.34,0.148
165.01,114.49,0.147
165.03,114.63,0.147
165.06,114.77,0.148
165.09,114.91,0.148
165.12,115.05,0.148
165.15,115.19,0.148
165.18,115.34,0.148
165.20,115.48,0.148
165.23,115.62,0.148
165.26,115.76,0.148
165.29,115.90,0.148
165.32,116.04,0.148
165.35,116.19,0.148
165.38,116.33,0.148
165.40,116.47,0.148
165.43,116.61,0.148
165.46,116.75,0.148
165.49,116.90,0.148
165.52,117.04,0.148
165.55,117.18,0.148
165.57,117.32,0.148
165.60,117.46,0.148
165.63,117.60,0.149
165.66,117.75,0.149
165.69,117.89,0.149
165.72,118.03,0.149
165.74,118.17,0.149
165.77,118.31,0.149
165.80,118.46,0.149
165.83,118.60,0.149
165.86,118.74,0.149
165.88,118.88,0.149
165.91,119.02,0.149
165.94,119.16,0.149
165.97,119.31,0.149
166.00,119.45,0.149
166.03,119.59,0.149
166.05,119.73,0.149
166.08,119.87,0.149
166.11,120.01,0.149
166.14,120.15,0.149
166.17,120.30,0.149
166.20,120.44,0.150
166.23,120.58,0.150
166.25,120.72,0.150
166.28,120.86,0.150
166.31,121.01,0.150
166.34,121.15,0.150
166.37,121.29,0.150
166.40,121.43,0.150
166.42,121.57,0.150
166.45,121.71,0.150
166.48,121.86,0.150
166.51,122.00,0.150
166.54,122.14,0.150
166.57,122.28,0.150
166.59,122.42,0.150
166.62,122.56,0.150
166.65,122.71,0.150
166.68,122.85,0.150
166.71,122.99,0.150
166.73,123.13,0.150
166.76,123.27,0.150
166.79,123.41,0.150
166.82,123.56,0.150
166.85,123.70,0.151
166.88,123.84,0.151
166.90,123.98,0.151
166.93,124.12,0.151
166.96,124.26,0.151
166.99,124.40,0.151
167.02,124.55,0.151
167.05,124.69,0.151
167.08,124.83,0.151
167.10,124.97,0.151
167.13,125.11,0.151
167.16,125.26,0.151
167.19,125.40,0.151
167.22,125.54,0.151
167.25,125.68,0.151
167.27,125.82,0.151
167.30,125.97,0.151
167.33,126.11,0.152
167.36,126.25,0.152
167.39,126.39,0.152
167.42,126.53,0.152
167.44,126.67,0.152
167.47,126.81,0.152
167.50,126.96,0.152
167.53,127.10,0.152
167.56,127.24,0.152
167.58,127.38,0.152
167.61,127.52,0.152
167.64,127.67,0.152
167.67,127.81,0.152
167.70,127.95,0.152
167.73,128.09,0.152
167.75,128.23,0.152
167.78,128.37,0.152
167.81,128.52,0.152
167.84,128.66,0.152
167.87,128.80,0.152
167.90,128.94,0.153
167.93,129.08,0.153
167.95,129.22,0.153
167.98,129.37,0.153
168.01,129.51,0.153
168.04,129.65,0.153
168.07,129.79,0.153
168.10,129.93,0.153
168.12,130.07,0.153
168.15,130.22,0.153
168.18,130.36,0.153
168.21,130.50,0.153
168.24,130.64,0.153
168.27,130.78,0.153
168.29,130.92,0.153
168.32,131.07,0.153
168.35,131.21,0.153
168.38,131.35,0.153
168.41,131.49,0.153
168.43,131.63,0.153
168.46,131.77,0.154
168.49,131.92,0.154
168.52,132.06,0.154
168.55,132.20,0.154
168.58,132.35,0.154
168.60,132.49,0.154
168.63,132.63,0.154
168.66,132.77,0.154
168.69,132.92,0.154
168.72,133.06,0.154
168.75,133.20,0.154
168.78,133.34,0.154
168.80,133.48,0.153
168.83,133.62,0.153
168.86,133.76,0.153
168.89,133.90,0.153
168.92,134.05,0.153
168.95,134.19,0.153
168.97,134.33,0.153
169.00,134.47,0.153
169.03,134.61,0.153
169.06,134.75,0.153
169.09,134.89,0.153
169.12,135.04,0.153
169.14,135.18,0.153
169.17,135.32,0.153
169.20,135.46,0.153
169.23,135.60,0.153
169.26,135.74,0.153
169.28,135.88,0.153
169.31,136.03,0.153
169.34,136.17,0.153
169.37,136.31,0.153
169.40,136.45,0.153
169.43,136.59,0.153
169.45,136.73,0.153
169.48,136.88,0.153
169.51,137.02,0.153
169.54,137.16,0.153
169.57,137.30,0.153
169.60,137.44,0.153
169.63,137.58,0.153
169.65,137.73,0.153
169.68,137.87,0.153
169.71,138.01,0.154
169.74,138.15,0.154
169.77,138.29,0.154
169.80,138.44,0.154
169.82,138.58,0.154
169.85,138.72,0.154
169.88,138.86,0.154
169.91,139.00,0.154
169.94,139.15,0.154
169.97,139.29,0.154
169.99,139.43,0.154
170.02,139.57,0.154
170.05,139.71,0.154
170.08,139.85,0.154
170.11,139.99,0.154
170.13,140.14,0.154
170.16,140.28,0.154
170.19,140.42,0.155
170.22,140.56,0.155
170.25,140.70,0.155
170.28,140.84,0.155
170.30,140.99,0.155
170.33,141.13,0.155
170.36,141.27,0.155
170.39,141.41,0.155
170.42,141.55,0.155
170.45,141.69,0.155
170.48,141.84,0.155
170.50,141.98,0.155
170.53,142.12,0.155
170.56,142.26,0.155
170.59,142.40,0.155
170.62,142.54,0.155
170.65,142.69,0.155
170.67,142.83,0.155
170.70,142.97,0.155
170.73,143.11,0.155
170.76,143.25,0.156
170.79,143.39,0.156
170.82,143.54,0.156
170.84,143.68,0.156
170.87,143.82,0.156
170.90,143.96,0.156
170.93,144.10,0.156
170.96,144.24,0.156
170.98,144.39,0.156
171.01,144.53,0.156
171.04,144.67,0.156
171.07,144.81,0.156
171.10,144.95,0.156
171.13,145.09,0.156
171.15,145.24,0.156
171.18,145.38,0.156
171.21,145.52,0.156
171.24,145.66,0.156
171.27,145.80,0.156
171.30,145.95,0.156
171.33,146.09,0.156
171.35,146.23,0.157
171.38,146.37,0.157
171.41,146.51,0.157
171.44,146.65,0.157
171.47,146.79,0.157
171.50,146.94,0.157
171.52,147.08,0.157
171.55,147.22,0.157
171.58,147.36,0.157
171.61,147.50,0.157
171.64,147.64,0.157
171.67,147.79,0.157
171.69,147.93,0.157
171.72,148.07,0.157
171.75,148.21,0.157
171.78,148.35,0.157
171.81,148.50,0.157
171.83,148.64,0.157
171.86,148.78,0.157
171.89,148.92,0.157
171.92,149.06,0.158
171.95,149.20,
171.98,,
171.98,,