File: DSC/2025_05_01_THC_Caffeine_MC_n60C_220C_5Cmin_x3.csv
Filename,2025_05_01_THC_Caffeine_MC_n60C_220C_5Cmin_x3
Instrument name,DSC2A-00468 (192.168.1.100)
Operator,Yarger
rundate,5/1/2025
Sample name,2025_05_01_THC_Caffeine_MC_n60C_220C_5Cmin_x3
proceduresegments,Data Off ; Equilibrate -60.00 °C; Data On ; Ramp 5.00 °C/min to 220.00 °C; Data Off ; Isothermal 1.0 min; Data On ; Ramp 5.00 °C/min to -60.00 °C; Data Off ; Isothermal 1.0 min; Data On ; Ramp 5.00 °C/min to 220.00 °C; Data Off ; Isothermal 1.0 min; Data On ; Ramp 5.00 °C/min to -60.00 °C; Data Off ; Isothermal 1.0 min; Data On ; Ramp 5.00 °C/min to 220.00 °C
[File Parameters]
Run date,5/1/2025 6:30:47 AM
Trios version,5.1.1.46572
Original File Name,
Current File Name,D:\DSC2500\JYarger\2025_05_01_THC_Caffeine_MC_n60C_220C_5Cmin_x3.tri
[Procedure]
Procedure Name,THC_Caffeine_n60C_220C_5Cmin_x3
Sample Name,2025_05_01_THC_Caffeine_MC_n60C_220C_5Cmin_x3
Sample Mass,8.25 mg
Reference Sample Mass,0 mg
Pan Mass,53.71 mg
Pan Number,15
Reference Pan Mass,53.35 mg
Reference Pan Number,1
Pan Type,Tzero Aluminum Hermetic
Comments,Al Hermetic DSC Consumables sealed Pan/Lid. Y2 Tray (Google Sheet: DSC_Samples_Vext_Y2_Tray_May2025)
Project Name,CA
Operator,Yarger
Test,Custom
Unload Max Temperature,30
Unload Min Temperature,30
Load Max Temperature,30
Load Min Temperature,30
Stop on Gas Flow Error,Yes
[Signal List]
Signal #1,Time (min)
Signal #2,Temperature (°C)
Signal #3,Heat Flow (mW)
Signal #4,Delta T (µV)
Signal #5,Delta Tzero (µV)
Signal #6,Tzero Temperature (°C)
Signal #7,Cell Purge (mL/min)
Signal #8,Heater Temp (°C)
Signal #9,Power Delivered (W)
Signal #10,Reference Junction Temperature (°C)
Signal #11,Flange Temperature (°C)
Signal #12,Heat Flow Phase (rad)
Signal #13,Total Heat Capacity (J/°C)
Signal #14,Heat Capacity (J/°C)
[Configuration]
Company Name,ASU
Instrument Name,DSC2A-00468
Instrument Type,DSC2500
Serial Number,DSC2A-00468
IP,192.168.1.100
Location of Instrument,MRRC
DisplayType,Unknown
Sample Interval ,0.1 s/pt
Selected Heat Flow,T4P
Exotherm Direction,Down
Cell Serial,DRC2-00792
Lid Type,Standard
Cooler,RCS 90
Leave Cooler on at End of Sequence,On
Gas 2,Nitrogen
Gas Selected,Channel 1
Flow Rate,50 mL/min
Secondary Purge,On
Licensed Heat Flow,Heat Flow T4P
Modulation Licensed,Yes
[Versions]
Common IDD Version,1
Cortex Version,VER 2.10.2.31
Driver,5.0.0.6
GDM Version,1.0.3.3
TouchscreenVersion,1.0.0.16145
FEP Version,1.2.1.21
FEP Bootloader,2.0.0.5
AutoSampler Version,2.1.1.26
Auto Sampler Bootloader,2.0.0.5
FCM Version,1.1.0.3
FCM Bootloader,2.0.0.5
[Experiment Logs]
Experiment Log Entry # 1,Data On set to 0
Experiment Log Entry # 3,Equilibrate Segment -60 (C) Started
Experiment Log Entry # 5,Air Cool is off.
Experiment Log Entry # 7,Data On set to 1
Experiment Log Entry # 9,Ramp Segment 5 C/min to 220 Started
Experiment Log Entry # 11,Auto sampler has detected that GDM has gone offline
Experiment Log Entry # 13,Data On set to 0
Experiment Log Entry # 15,Isothermal Segment 1 min started
Experiment Log Entry # 17,Data On set to 1
Experiment Log Entry # 19,Ramp Segment 5 C/min to -60 Started
Experiment Log Entry # 21,Data On set to 0
Experiment Log Entry # 23,Isothermal Segment 1 min started
Experiment Log Entry # 25,Data On set to 1
Experiment Log Entry # 27,Ramp Segment 5 C/min to 220 Started
Experiment Log Entry # 29,Auto sampler has detected that FEP has gone offline
Experiment Log Entry # 31,Data On set to 0
Experiment Log Entry # 33,Isothermal Segment 1 min started
Experiment Log Entry # 35,Data On set to 1
Experiment Log Entry # 37,Ramp Segment 5 C/min to -60 Started
Experiment Log Entry # 39,Data On set to 0
Experiment Log Entry # 41,Isothermal Segment 1 min started
Experiment Log Entry # 43,Data On set to 1
Experiment Log Entry # 45,Ramp Segment 5 C/min to 220 Started
[Method Log]
Method Log Entry # 1,Data Off
Method Log Entry # 2,Equilibrate -60 °C
Method Log Entry # 3,Data On
Method Log Entry # 4,(Ramp 174800) Ramp 5 °C/minute to 220 °C
Method Log Entry # 5,Data Off
Method Log Entry # 6,Isothermal 1 minutes
Method Log Entry # 7,Data On
Method Log Entry # 8,(Ramp 174804) Ramp 5 °C/minute to -60 °C
Method Log Entry # 9,Data Off
Method Log Entry # 10,Isothermal 1 minutes
Method Log Entry # 11,Data On
Method Log Entry # 12,(Ramp 174808) Ramp 5 °C/minute to 220 °C
Method Log Entry # 13,Data Off
Method Log Entry # 14,Isothermal 1 minutes
Method Log Entry # 15,Data On
Method Log Entry # 16,(Ramp 174812) Ramp 5 °C/minute to -60 °C
Method Log Entry # 17,Data Off
Method Log Entry # 18,Isothermal 1 minutes
Method Log Entry # 19,Data On
Method Log Entry # 20,(Ramp 174816) Ramp 5 °C/minute to 220 °C
Cell Serial,DRC2-00792
[T1 Calibration]
Slope,-0.008529666
Offset,9.636258
Initial Temperature,98.23
GUID,f8bfdadc-4977-4fdf-ba6d-0ba9134940c3
[TZero Calibration]
Date Applied,11/29/2022 4:06:13 PM
Description,From -89.059 °C to 396.009 °C at 20.000°C/min
Gas Type,Nitrogen
Pan Type,None
Source Files 1,C:\Users\yargerlab\Desktop\DSC Data\General\TZero_calibration_11_29_22_2nd(2).tri
Source Files 2,C:\Users\yargerlab\Desktop\DSC Data\General\TZero_calibration_11_29_22_2nd(3).tri
Delta T Offset,13.05235
Delta T Slope,-0.007271007
Delta T0 Offset,-13.69128
Delta T0 Slope,0.06063341
[Temperature Calibration]
Date Applied,11/29/2022 7:12:28 PM
Description,From 106.590 °C to 186.590 °C at 10.000°C/min
Gas Type,Nitrogen
Pan Type,Tzero Aluminum Hermetic
Source Files 1,C:\Users\yargerlab\Desktop\DSC Data\General\Indium(6).tri
Measured 1,157.391
Known 1,156.598
[Cell Constant Calibration]
Date Applied,11/29/2022 7:12:29 PM
Description,From 106.590 °C to 186.590 °C at 10.000°C/min
Gas Type,Nitrogen
Pan Type,Tzero Aluminum Hermetic
Source Files 1,C:\Users\yargerlab\Desktop\DSC Data\General\Indium(6).tri
T4P KCell,1.006051
Onset Slope,63.26126 mW/°C
[Direct Cp Calibration]
Date Applied,11/30/2022 11:04:51 AM
Description,From -79.983 °C to 298.409 °C at 10.000°C/min
Gas Type,Nitrogen
Pan Type,Tzero Aluminum Hermetic
Source Files 1,C:\Users\yargerlab\Desktop\DSC Data\General\Sapphire_Heat_Capacity_11_30_22.tri
[Rev Cp Calibration]
Date Applied,11/30/2022 1:58:51 PM
Description,From -79.996 °C to 292.812 °C at 3.000°C/min
Gas Type,Nitrogen
Pan Type,Tzero Aluminum Hermetic
Source Files 1,C:\Users\yargerlab\Desktop\DSC Data\General\Sapphire_MDSC_Calibration_11_30_22.tri
[step]
Ramp 5.00 °C/min to 220.00 °C
Time,Temperature,Heat Flow (Normalized)
min,°C,W/g
0.00,-59.67,-0.047
0.04,-59.70,-0.043
0.08,-59.68,-0.033
0.12,-59.62,-0.019
0.15,-59.52,-0.001
0.19,-59.39,0.020
0.23,-59.24,0.036
0.27,-59.09,0.050
0.31,-58.92,0.059
0.35,-58.76,0.067
0.38,-58.58,0.073
0.42,-58.41,0.077
0.46,-58.23,0.080
0.50,-58.05,0.082
0.54,-57.87,0.084
0.58,-57.68,0.085
0.61,-57.50,0.086
0.65,-57.31,0.087
0.69,-57.12,0.087
0.73,-56.94,0.088
0.77,-56.75,0.088
0.80,-56.56,0.089
0.84,-56.37,0.089
0.88,-56.19,0.090
0.92,-56.00,0.090
0.96,-55.81,0.090
1.00,-55.62,0.091
1.03,-55.43,0.091
1.07,-55.24,0.091
1.11,-55.05,0.091
1.15,-54.86,0.092
1.19,-54.67,0.092
1.23,-54.48,0.092
1.27,-54.29,0.092
1.30,-54.10,0.092
1.34,-53.91,0.092
1.38,-53.72,0.092
1.42,-53.53,0.093
1.46,-53.33,0.093
1.49,-53.14,0.093
1.53,-52.95,0.093
1.57,-52.76,0.093
1.61,-52.57,0.093
1.65,-52.38,0.093
1.69,-52.19,0.093
1.73,-52.00,0.093
1.76,-51.81,0.093
1.80,-51.62,0.093
1.84,-51.43,0.093
1.88,-51.24,0.093
1.92,-51.04,0.093
1.96,-50.85,0.093
1.99,-50.66,0.093
2.03,-50.47,0.093
2.07,-50.28,0.093
2.11,-50.09,0.093
2.15,-49.89,0.094
2.19,-49.70,0.094
2.22,-49.51,0.094
2.26,-49.32,0.094
2.30,-49.13,0.094
2.34,-48.94,0.094
2.38,-48.75,0.094
2.41,-48.56,0.094
2.45,-48.36,0.094
2.49,-48.17,0.094
2.53,-47.98,0.094
2.57,-47.79,0.094
2.61,-47.60,0.094
2.64,-47.41,0.094
2.68,-47.22,0.094
2.72,-47.02,0.094
2.76,-46.83,0.094
2.80,-46.64,0.094
2.84,-46.45,0.095
2.88,-46.26,0.095
2.91,-46.07,0.095
2.95,-45.88,0.095
2.99,-45.69,0.095
3.03,-45.49,0.095
3.07,-45.30,0.095
3.11,-45.11,0.095
3.14,-44.92,0.095
3.18,-44.73,0.095
3.22,-44.54,0.095
3.26,-44.35,0.096
3.30,-44.16,0.096
3.34,-43.97,0.096
3.37,-43.77,0.096
3.41,-43.58,0.096
3.45,-43.39,0.097
3.49,-43.20,0.097
3.53,-43.00,0.097
3.56,-42.81,0.097
3.60,-42.62,0.097
3.64,-42.43,0.098
3.68,-42.24,0.098
3.72,-42.05,0.098
3.76,-41.86,0.098
3.79,-41.66,0.099
3.83,-41.47,0.099
3.87,-41.28,0.099
3.91,-41.09,0.100
3.95,-40.90,0.100
3.99,-40.71,0.100
4.03,-40.51,0.101
4.06,-40.32,0.101
4.10,-40.13,0.102
4.14,-39.94,0.102
4.18,-39.75,0.102
4.22,-39.55,0.103
4.26,-39.36,0.103
4.29,-39.17,0.104
4.33,-38.98,0.104
4.37,-38.79,0.105
4.41,-38.60,0.105
4.45,-38.40,0.106
4.49,-38.21,0.106
4.52,-38.02,0.107
4.56,-37.83,0.107
4.60,-37.64,0.108
4.64,-37.45,0.108
4.68,-37.26,0.109
4.71,-37.06,0.110
4.75,-36.87,0.110
4.79,-36.68,0.111
4.83,-36.49,0.111
4.87,-36.30,0.112
4.91,-36.11,0.113
4.95,-35.92,0.113
4.98,-35.72,0.114
5.02,-35.53,0.114
5.06,-35.34,0.115
5.10,-35.15,0.115
5.14,-34.96,0.116
5.18,-34.77,0.116
5.21,-34.57,0.117
5.25,-34.38,0.117
5.29,-34.19,0.118
5.33,-34.00,0.118
5.37,-33.81,0.118
5.40,-33.62,0.119
5.44,-33.42,0.119
5.48,-33.23,0.119
5.52,-33.04,0.119
5.56,-32.85,0.120
5.60,-32.66,0.120
5.64,-32.46,0.120
5.67,-32.27,0.120
5.71,-32.08,0.120
5.75,-31.89,0.120
5.79,-31.70,0.120
5.83,-31.50,0.120
5.86,-31.31,0.120
5.90,-31.12,0.120
5.94,-30.93,0.120
5.98,-30.74,0.120
6.02,-30.54,0.120
6.06,-30.35,0.120
6.10,-30.16,0.120
6.13,-29.97,0.120
6.17,-29.78,0.120
6.21,-29.59,0.120
6.25,-29.39,0.120
6.29,-29.20,0.120
6.33,-29.01,0.120
6.36,-28.82,0.120
6.40,-28.63,0.119
6.44,-28.44,0.119
6.48,-28.24,0.119
6.52,-28.05,0.119
6.55,-27.86,0.119
6.59,-27.67,0.119
6.63,-27.48,0.119
6.67,-27.28,0.119
6.71,-27.09,0.119
6.75,-26.90,0.119
6.79,-26.71,0.119
6.82,-26.51,0.119
6.86,-26.32,0.119
6.90,-26.13,0.119
6.94,-25.94,0.119
6.98,-25.75,0.119
7.01,-25.56,0.119
7.05,-25.36,0.119
7.09,-25.17,0.119
7.13,-24.98,0.119
7.17,-24.79,0.119
7.21,-24.60,0.119
7.25,-24.41,0.119
7.28,-24.21,0.119
7.32,-24.02,0.119
7.36,-23.83,0.119
7.40,-23.64,0.119
7.44,-23.45,0.119
7.48,-23.25,0.119
7.51,-23.06,0.119
7.55,-22.87,0.119
7.59,-22.68,0.119
7.63,-22.49,0.119
7.67,-22.29,0.119
7.70,-22.10,0.119
7.74,-21.91,0.119
7.78,-21.72,0.120
7.82,-21.53,0.120
7.86,-21.34,0.120
7.90,-21.14,0.120
7.94,-20.95,0.120
7.97,-20.76,0.120
8.01,-20.57,0.120
8.05,-20.38,0.120
8.09,-20.18,0.120
8.13,-19.99,0.120
8.16,-19.80,0.120
8.20,-19.61,0.120
8.24,-19.42,0.120
8.28,-19.22,0.120
8.32,-19.03,0.120
8.36,-18.84,0.120
8.40,-18.65,0.120
8.43,-18.45,0.120
8.47,-18.26,0.120
8.51,-18.07,0.120
8.55,-17.88,0.120
8.59,-17.69,0.120
8.63,-17.49,0.120
8.66,-17.30,0.120
8.70,-17.11,0.120
8.74,-16.92,0.120
8.78,-16.73,0.120
8.82,-16.54,0.120
8.85,-16.35,0.120
8.89,-16.15,0.120
8.93,-15.97,0.120
8.97,-15.77,0.120
9.01,-15.58,0.120
9.05,-15.39,0.120
9.08,-15.20,0.120
9.12,-15.00,0.120
9.16,-14.81,0.120
9.20,-14.62,0.120
9.24,-14.43,0.121
9.28,-14.24,0.121
9.32,-14.04,0.121
9.35,-13.85,0.121
9.39,-13.66,0.121
9.43,-13.47,0.121
9.47,-13.28,0.121
9.51,-13.09,0.121
9.55,-12.89,0.121
9.58,-12.70,0.121
9.62,-12.51,0.121
9.66,-12.32,0.121
9.70,-12.13,0.121
9.74,-11.94,0.121
9.78,-11.74,0.121
9.81,-11.55,0.121
9.85,-11.36,0.121
9.89,-11.17,0.121
9.93,-10.98,0.121
9.97,-10.79,0.121
10.00,-10.59,0.121
10.04,-10.40,0.121
10.08,-10.21,0.121
10.12,-10.02,0.121
10.16,-9.83,0.122
10.20,-9.63,0.122
10.23,-9.44,0.122
10.27,-9.25,0.122
10.31,-9.06,0.122
10.35,-8.87,0.122
10.39,-8.68,0.122
10.43,-8.48,0.122
10.47,-8.29,0.122
10.50,-8.10,0.122
10.54,-7.91,0.122
10.58,-7.72,0.122
10.62,-7.53,0.122
10.66,-7.33,0.122
10.70,-7.14,0.122
10.73,-6.95,0.122
10.77,-6.76,0.122
10.81,-6.57,0.122
10.85,-6.37,0.122
10.89,-6.18,0.122
10.93,-5.99,0.122
10.96,-5.80,0.122
11.00,-5.61,0.122
11.04,-5.41,0.122
11.08,-5.22,0.122
11.12,-5.03,0.122
11.15,-4.84,0.122
11.19,-4.65,0.122
11.23,-4.46,0.123
11.27,-4.27,0.123
11.31,-4.07,0.123
11.35,-3.88,0.123
11.38,-3.69,0.123
11.42,-3.50,0.123
11.46,-3.30,0.123
11.50,-3.11,0.123
11.54,-2.92,0.123
11.58,-2.73,0.123
11.62,-2.54,0.123
11.65,-2.35,0.123
11.69,-2.15,0.123
11.73,-1.96,0.123
11.77,-1.77,0.123
11.81,-1.58,0.123
11.85,-1.39,0.123
11.88,-1.19,0.123
11.92,-1.00,0.123
11.96,-0.81,0.123
12.00,-0.62,0.123
12.04,-0.43,0.123
12.08,-0.24,0.123
12.11,-0.04,0.123
12.15,0.15,0.123
12.19,0.34,0.124
12.23,0.53,0.124
12.27,0.72,0.124
12.30,0.92,0.124
12.34,1.11,0.124
12.38,1.30,0.124
12.42,1.49,0.124
12.46,1.68,0.124
12.50,1.87,0.124
12.53,2.07,0.124
12.57,2.26,0.124
12.61,2.45,0.124
12.65,2.64,0.124
12.69,2.84,0.124
12.73,3.03,0.124
12.77,3.22,0.124
12.80,3.41,0.124
12.84,3.60,0.124
12.88,3.79,0.124
12.92,3.98,0.124
12.96,4.18,0.124
13.00,4.37,0.124
13.03,4.56,0.125
13.07,4.75,0.125
13.11,4.95,0.125
13.15,5.14,0.125
13.19,5.33,0.125
13.23,5.52,0.125
13.26,5.71,0.125
13.30,5.91,0.125
13.34,6.10,0.125
13.38,6.29,0.125
13.42,6.48,0.125
13.45,6.67,0.125
13.49,6.86,0.125
13.53,7.06,0.125
13.57,7.25,0.125
13.61,7.44,0.125
13.65,7.63,0.125
13.68,7.82,0.126
13.72,8.01,0.126
13.76,8.21,0.126
13.80,8.40,0.126
13.84,8.59,0.126
13.88,8.78,0.126
13.92,8.97,0.126
13.95,9.16,0.126
13.99,9.36,0.126
14.03,9.55,0.126
14.07,9.74,0.126
14.11,9.93,0.126
14.15,10.12,0.126
14.18,10.31,0.126
14.22,10.51,0.127
14.26,10.70,0.127
14.30,10.89,0.127
14.34,11.08,0.127
14.38,11.27,0.127
14.41,11.46,0.127
14.45,11.66,0.127
14.49,11.85,0.127
14.53,12.04,0.127
14.57,12.23,0.127
14.60,12.42,0.127
14.64,12.62,0.127
14.68,12.81,0.127
14.72,13.00,0.128
14.76,13.19,0.128
14.80,13.38,0.128
14.83,13.58,0.128
14.87,13.77,0.128
14.91,13.96,0.128
14.95,14.15,0.128
14.99,14.34,0.128
15.03,14.53,0.128
15.07,14.72,0.128
15.10,14.91,0.128
15.14,15.11,0.128
15.18,15.30,0.129
15.22,15.49,0.129
15.26,15.68,0.129
15.30,15.87,0.129
15.33,16.07,0.129
15.37,16.26,0.129
15.41,16.45,0.129
15.45,16.64,0.129
15.49,16.83,0.130
15.53,17.02,0.130
15.56,17.22,0.130
15.60,17.41,0.130
15.64,17.60,0.130
15.68,17.79,0.130
15.72,17.98,0.130
15.75,18.18,0.130
15.79,18.37,0.130
15.83,18.56,0.131
15.87,18.75,0.131
15.91,18.94,0.131
15.95,19.14,0.131
15.98,19.33,0.131
16.02,19.52,0.131
16.06,19.71,0.131
16.10,19.90,0.131
16.14,20.10,0.131
16.18,20.29,0.132
16.22,20.48,0.132
16.25,20.67,0.132
16.29,20.86,0.132
16.33,21.05,0.132
16.37,21.24,0.132
16.41,21.44,0.132
16.45,21.63,0.132
16.48,21.82,0.132
16.52,22.01,0.132
16.56,22.20,0.132
16.60,22.40,0.132
16.64,22.59,0.132
16.68,22.78,0.133
16.71,22.97,0.133
16.75,23.16,0.133
16.79,23.36,0.133
16.83,23.55,0.133
16.87,23.74,0.133
16.90,23.93,0.133
16.94,24.12,0.133
16.98,24.31,0.133
17.02,24.51,0.133
17.06,24.70,0.133
17.10,24.89,0.133
17.13,25.08,0.134
17.17,25.27,0.134
17.21,25.47,0.134
17.25,25.66,0.134
17.29,25.85,0.134
17.33,26.04,0.134
17.37,26.23,0.134
17.40,26.42,0.134
17.44,26.62,0.134
17.48,26.81,0.134
17.52,27.00,0.134
17.56,27.19,0.134
17.59,27.38,0.134
17.63,27.57,0.134
17.67,27.77,0.135
17.71,27.96,0.135
17.75,28.15,0.135
17.79,28.34,0.135
17.83,28.53,0.135
17.86,28.72,0.135
17.90,28.92,0.135
17.94,29.11,0.135
17.98,29.30,0.135
18.02,29.49,0.135
18.06,29.68,0.135
18.09,29.88,0.135
18.13,30.07,0.135
18.17,30.26,0.135
18.21,30.45,0.136
18.25,30.64,0.136
18.28,30.83,0.136
18.32,31.03,0.136
18.36,31.22,0.136
18.40,31.41,0.136
18.44,31.60,0.136
18.48,31.79,0.136
18.52,31.99,0.136
18.55,32.18,0.136
18.59,32.37,0.136
18.63,32.56,0.136
18.67,32.75,0.137
18.71,32.94,0.137
18.74,33.14,0.137
18.78,33.33,0.137
18.82,33.52,0.137
18.86,33.71,0.137
18.90,33.90,0.137
18.94,34.09,0.137
18.98,34.29,0.137
19.01,34.48,0.137
19.05,34.67,0.137
19.09,34.86,0.138
19.13,35.05,0.138
19.17,35.24,0.138
19.21,35.44,0.138
19.24,35.63,0.138
19.28,35.82,0.138
19.32,36.01,0.138
19.36,36.20,0.138
19.40,36.40,0.138
19.43,36.59,0.138
19.47,36.78,0.138
19.51,36.97,0.138
19.55,37.16,0.138
19.59,37.36,0.138
19.63,37.55,0.139
19.67,37.74,0.139
19.70,37.93,0.139
19.74,38.12,0.139
19.78,38.31,0.139
19.82,38.51,0.139
19.86,38.70,0.139
19.89,38.89,0.139
19.93,39.08,0.139
19.97,39.27,0.139
20.01,39.47,0.139
20.05,39.66,0.139
20.09,39.85,0.139
20.13,40.04,0.140
20.16,40.23,0.140
20.20,40.42,0.140
20.24,40.62,0.140
20.28,40.81,0.140
20.32,41.00,0.140
20.36,41.19,0.140
20.39,41.38,0.140
20.43,41.57,0.140
20.47,41.77,0.140
20.51,41.96,0.140
20.55,42.15,0.140
20.58,42.34,0.140
20.62,42.53,0.140
20.66,42.73,0.141
20.70,42.92,0.141
20.74,43.11,0.141
20.78,43.30,0.141
20.82,43.49,0.141
20.85,43.68,0.141
20.89,43.87,0.141
20.93,44.07,0.141
20.97,44.26,0.141
21.01,44.45,0.141
21.04,44.64,0.141
21.08,44.83,0.141
21.12,45.03,0.141
21.16,45.22,0.142
21.20,45.41,0.142
21.24,45.60,0.142
21.28,45.79,0.142
21.31,45.99,0.142
21.35,46.18,0.142
21.39,46.37,0.142
21.43,46.56,0.142
21.47,46.75,0.142
21.51,46.94,0.142
21.54,47.14,0.142
21.58,47.33,0.142
21.62,47.52,0.142
21.66,47.71,0.143
21.70,47.90,0.143
21.73,48.09,0.143
21.77,48.29,0.143
21.81,48.48,0.143
21.85,48.67,0.143
21.89,48.86,0.143
21.93,49.05,0.143
21.97,49.25,0.143
22.00,49.44,0.143
22.04,49.63,0.143
22.08,49.82,0.143
22.12,50.01,0.143
22.16,50.20,0.143
22.19,50.40,0.144
22.23,50.59,0.144
22.27,50.78,0.144
22.31,50.97,0.144
22.35,51.16,0.144
22.39,51.36,0.144
22.43,51.55,0.144
22.46,51.74,0.144
22.50,51.93,0.144
22.54,52.12,0.144
22.58,52.31,0.144
22.62,52.51,0.144
22.66,52.70,0.145
22.69,52.89,0.145
22.73,53.08,0.145
22.77,53.27,0.145
22.81,53.46,0.145
22.85,53.66,0.145
22.88,53.85,0.145
22.92,54.04,0.145
22.96,54.23,0.145
23.00,54.42,0.145
23.04,54.61,0.145
23.08,54.81,0.145
23.12,55.00,0.145
23.15,55.19,0.145
23.19,55.38,0.146
23.23,55.57,0.146
23.27,55.77,0.146
23.31,55.96,0.146
23.34,56.15,0.146
23.38,56.34,0.146
23.42,56.53,0.146
23.46,56.73,0.146
23.50,56.92,0.146
23.54,57.11,0.146
23.58,57.30,0.146
23.61,57.49,0.146
23.65,57.68,0.146
23.69,57.88,0.147
23.73,58.07,0.147
23.77,58.26,0.147
23.81,58.45,0.147
23.84,58.64,0.147
23.88,58.83,0.147
23.92,59.02,0.147
23.96,59.22,0.147
24.00,59.41,0.147
24.03,59.60,0.147
24.07,59.79,0.147
24.11,59.98,0.147
24.15,60.18,0.147
24.19,60.37,0.147
24.23,60.56,0.147
24.27,60.75,0.147
24.30,60.94,0.148
24.34,61.14,0.148
24.38,61.33,0.148
24.42,61.52,0.148
24.46,61.71,0.148
24.49,61.90,0.148
24.53,62.09,0.148
24.57,62.29,0.148
24.61,62.48,0.148
24.65,62.67,0.148
24.69,62.86,0.148
24.73,63.05,0.148
24.76,63.24,0.149
24.80,63.44,0.149
24.84,63.63,0.149
24.88,63.82,0.149
24.92,64.01,0.149
24.96,64.20,0.149
24.99,64.40,0.149
25.03,64.59,0.149
25.07,64.78,0.149
25.11,64.97,0.149
25.15,65.16,0.149
25.18,65.36,0.150
25.22,65.55,0.150
25.26,65.74,0.150
25.30,65.93,0.150
25.34,66.12,0.150
25.38,66.31,0.150
25.42,66.51,0.150
25.45,66.70,0.150
25.49,66.89,0.150
25.53,67.08,0.150
25.57,67.27,0.150
25.61,67.46,0.150
25.64,67.66,0.150
25.68,67.85,0.150
25.72,68.04,0.150
25.76,68.23,0.151
25.80,68.42,0.151
25.84,68.62,0.151
25.88,68.81,0.151
25.91,69.00,0.151
25.95,69.19,0.151
25.99,69.38,0.151
26.03,69.57,0.151
26.07,69.77,0.151
26.11,69.96,0.151
26.14,70.15,0.151
26.18,70.34,0.151
26.22,70.53,0.151
26.26,70.72,0.151
26.30,70.91,0.152
26.33,71.11,0.152
26.37,71.30,0.152
26.41,71.49,0.152
26.45,71.68,0.152
26.49,71.87,0.152
26.53,72.07,0.152
26.57,72.26,0.152
26.60,72.45,0.152
26.64,72.64,0.152
26.68,72.83,0.152
26.72,73.02,0.152
26.76,73.22,0.153
26.79,73.41,0.153
26.83,73.60,0.153
26.87,73.79,0.153
26.91,73.98,0.153
26.95,74.18,0.153
26.99,74.37,0.153
27.03,74.56,0.153
27.06,74.75,0.153
27.10,74.94,0.153
27.14,75.13,0.153
27.18,75.33,0.153
27.22,75.52,0.153
27.26,75.71,0.153
27.29,75.90,0.154
27.33,76.09,0.154
27.37,76.28,0.154
27.41,76.48,0.154
27.45,76.67,0.154
27.48,76.86,0.154
27.52,77.05,0.154
27.56,77.24,0.154
27.60,77.44,0.154
27.64,77.63,0.154
27.68,77.82,0.154
27.72,78.01,0.155
27.75,78.20,0.155
27.79,78.39,0.155
27.83,78.59,0.155
27.87,78.78,0.155
27.91,78.97,0.155
27.94,79.16,0.155
27.98,79.35,0.155
28.02,79.54,0.155
28.06,79.74,0.155
28.10,79.93,0.155
28.14,80.12,0.155
28.18,80.31,0.156
28.21,80.50,0.156
28.25,80.69,0.156
28.29,80.89,0.156
28.33,81.08,0.156
28.37,81.27,0.156
28.41,81.46,0.156
28.44,81.65,0.156
28.48,81.84,0.156
28.52,82.04,0.156
28.56,82.23,0.156
28.60,82.42,0.156
28.63,82.61,0.156
28.67,82.80,0.156
28.71,83.00,0.157
28.75,83.19,0.157
28.79,83.38,0.157
28.83,83.57,0.157
28.87,83.76,0.157
28.90,83.95,0.157
28.94,84.15,0.157
28.98,84.34,0.157
29.02,84.53,0.157
29.06,84.72,0.157
29.09,84.91,0.157
29.13,85.11,0.157
29.17,85.30,0.157
29.21,85.49,0.157
29.25,85.68,0.158
29.29,85.87,0.158
29.33,86.06,0.158
29.36,86.25,0.158
29.40,86.45,0.158
29.44,86.64,0.158
29.48,86.83,0.158
29.52,87.02,0.158
29.56,87.22,0.158
29.59,87.41,0.158
29.63,87.60,0.158
29.67,87.79,0.158
29.71,87.98,0.158
29.75,88.17,0.158
29.78,88.37,0.159
29.82,88.56,0.159
29.86,88.75,0.159
29.90,88.94,0.159
29.94,89.13,0.159
29.98,89.33,0.159
30.02,89.52,0.159
30.05,89.71,0.159
30.09,89.90,0.159
30.13,90.09,0.159
30.17,90.29,0.159
30.21,90.48,0.160
30.24,90.67,0.160
30.28,90.86,0.160
30.32,91.05,0.160
30.36,91.24,0.160
30.40,91.43,0.160
30.44,91.63,0.160
30.48,91.82,0.160
30.51,92.01,0.160
30.55,92.20,0.160
30.59,92.39,0.160
30.63,92.58,0.160
30.67,92.77,0.160
30.71,92.97,0.160
30.74,93.16,0.160
30.78,93.35,0.160
30.82,93.54,0.160
30.86,93.73,0.161
30.90,93.93,0.161
30.93,94.12,0.161
30.97,94.31,0.161
31.01,94.50,0.161
31.05,94.69,0.161
31.09,94.88,0.161
31.13,95.08,0.161
31.17,95.27,0.161
31.20,95.46,0.161
31.24,95.65,0.162
31.28,95.84,0.162
31.32,96.04,0.162
31.36,96.23,0.162
31.39,96.42,0.162
31.43,96.61,0.162
31.47,96.80,0.162
31.51,96.99,0.162
31.55,97.19,0.162
31.59,97.38,0.162
31.63,97.57,0.162
31.66,97.76,0.162
31.70,97.95,0.162
31.74,98.14,0.163
31.78,98.34,0.163
31.82,98.53,0.163
31.86,98.72,0.163
31.89,98.91,0.163
31.93,99.10,0.163
31.97,99.30,0.163
32.01,99.49,0.163
32.05,99.68,0.163
32.08,99.87,0.163
32.12,100.06,0.163
32.16,100.25,0.163
32.20,100.44,0.163
32.24,100.64,0.163
32.28,100.83,0.164
32.32,101.02,0.164
32.35,101.21,0.164
32.39,101.40,0.164
32.43,101.59,0.164
32.47,101.79,0.164
32.51,101.98,0.164
32.54,102.17,0.164
32.58,102.36,0.164
32.62,102.55,0.164
32.66,102.75,0.164
32.70,102.94,0.165
32.74,103.13,0.165
32.78,103.32,0.165
32.81,103.51,0.165
32.85,103.70,0.165
32.89,103.90,0.165
32.93,104.09,0.165
32.97,104.28,0.165
33.01,104.47,0.165
33.04,104.66,0.165
33.08,104.85,0.165
33.12,105.05,0.166
33.16,105.24,0.166
33.20,105.43,0.166
33.23,105.62,0.166
33.27,105.81,0.166
33.31,106.00,0.166
33.35,106.20,0.166
33.39,106.39,0.166
33.43,106.58,0.166
33.47,106.77,0.166
33.50,106.96,0.166
33.54,107.15,0.166
33.58,107.35,0.167
33.62,107.54,0.167
33.66,107.73,0.167
33.69,107.92,0.167
33.73,108.11,0.167
33.77,108.31,0.167
33.81,108.50,0.167
33.85,108.69,0.167
33.89,108.88,0.167
33.93,109.07,0.167
33.96,109.26,0.168
34.00,109.45,0.168
34.04,109.65,0.168
34.08,109.84,0.168
34.12,110.03,0.168
34.16,110.22,0.168
34.19,110.41,0.168
34.23,110.61,0.168
34.27,110.80,0.168
34.31,110.99,0.168
34.35,111.18,0.169
34.39,111.37,0.169
34.42,111.56,0.169
34.46,111.76,0.169
34.50,111.95,0.169
34.54,112.14,0.169
34.58,112.33,0.169
34.61,112.52,0.169
34.65,112.72,0.169
34.69,112.91,0.169
34.73,113.10,0.169
34.77,113.29,0.169
34.81,113.48,0.170
34.84,113.67,0.170
34.88,113.87,0.170
34.92,114.06,0.170
34.96,114.25,0.170
35.00,114.44,0.170
35.04,114.63,0.170
35.08,114.82,0.170
35.11,115.02,0.170
35.15,115.21,0.171
35.19,115.40,0.171
35.23,115.59,0.171
35.27,115.78,0.171
35.31,115.97,0.171
35.34,116.17,0.171
35.38,116.36,0.171
35.42,116.55,0.171
35.46,116.74,0.171
35.50,116.93,0.171
35.54,117.12,0.171
35.57,117.32,0.171
35.61,117.51,0.172
35.65,117.70,0.172
35.69,117.89,0.172
35.73,118.08,0.172
35.76,118.27,0.172
35.80,118.47,0.172
35.84,118.66,0.172
35.88,118.85,0.172
35.92,119.04,0.172
35.96,119.23,0.172
35.99,119.42,0.172
36.03,119.62,0.172
36.07,119.81,0.173
36.11,120.00,0.173
36.15,120.19,0.173
36.19,120.38,0.173
36.23,120.57,0.173
36.26,120.77,0.173
36.30,120.96,0.173
36.34,121.15,0.173
36.38,121.34,0.173
36.42,121.54,0.174
36.46,121.73,0.174
36.49,121.92,0.174
36.53,122.11,0.174
36.57,122.30,0.174
36.61,122.49,0.174
36.65,122.68,0.174
36.69,122.87,0.174
36.72,123.07,0.174
36.76,123.26,0.174
36.80,123.45,0.174
36.84,123.64,0.174
36.88,123.83,0.174
36.91,124.02,0.175
36.95,124.22,0.175
36.99,124.41,0.175
37.03,124.60,0.175
37.07,124.79,0.175
37.11,124.98,0.175
37.14,125.17,0.175
37.18,125.37,0.176
37.22,125.56,0.176
37.26,125.75,0.176
37.30,125.94,0.176
37.34,126.13,0.176
37.38,126.33,0.176
37.41,126.52,0.176
37.45,126.71,0.176
37.49,126.90,0.176
37.53,127.09,0.176
37.57,127.29,0.177
37.61,127.48,0.177
37.64,127.67,0.177
37.68,127.86,0.177
37.72,128.05,0.177
37.76,128.24,0.177
37.80,128.44,0.177
37.84,128.63,0.177
37.87,128.82,0.177
37.91,129.01,0.177
37.95,129.20,0.177
37.99,129.39,0.177
38.03,129.58,0.177
38.06,129.78,0.178
38.10,129.97,0.178
38.14,130.16,0.178
38.18,130.35,0.178
38.22,130.54,0.178
38.26,130.74,0.178
38.29,130.93,0.178
38.33,131.12,0.178
38.37,131.31,0.179
38.41,131.50,0.179
38.45,131.69,0.179
38.49,131.89,0.179
38.53,132.08,0.179
38.56,132.27,0.179
38.60,132.46,0.179
38.64,132.65,0.179
38.68,132.84,0.179
38.72,133.04,0.180
38.76,133.23,0.180
38.79,133.42,0.180
38.83,133.61,0.180
38.87,133.80,0.180
38.91,133.99,0.180
38.95,134.19,0.181
38.99,134.38,0.181
39.02,134.57,0.181
39.06,134.76,0.181
39.10,134.95,0.181
39.14,135.14,0.181
39.18,135.34,0.181
39.21,135.53,0.181
39.25,135.72,0.181
39.29,135.91,0.181
39.33,136.10,0.181
39.37,136.29,0.182
39.41,136.49,0.182
39.44,136.68,0.182
39.48,136.87,0.182
39.52,137.06,0.182
39.56,137.25,0.182
39.60,137.44,0.182
39.64,137.64,0.182
39.68,137.83,0.182
39.71,138.02,0.182
39.75,138.21,0.183
39.79,138.40,0.183
39.83,138.59,0.183
39.87,138.79,0.184
39.91,138.98,0.184
39.94,139.17,0.185
39.98,139.36,0.185
40.02,139.55,0.186
40.06,139.74,0.186
40.10,139.93,0.188
40.14,140.12,0.188
40.17,140.31,0.189
40.21,140.51,0.190
40.25,140.70,0.192
40.29,140.89,0.193
40.33,141.08,0.195
40.36,141.27,0.198
40.40,141.46,0.201
40.44,141.65,0.204
40.48,141.84,0.207
40.52,142.03,0.211
40.56,142.22,0.216
40.59,142.41,0.220
40.63,142.60,0.225
40.67,142.79,0.229
40.71,142.98,0.234
40.75,143.17,0.238
40.79,143.36,0.242
40.83,143.55,0.247
40.86,143.74,0.249
40.90,143.93,0.251
40.94,144.12,0.252
40.98,144.31,0.252
41.02,144.51,0.252
41.06,144.70,0.251
41.09,144.89,0.246
41.13,145.08,0.240
41.17,145.28,0.234
41.21,145.47,0.229
41.25,145.67,0.223
41.29,145.86,0.218
41.32,146.06,0.213
41.36,146.25,0.209
41.40,146.44,0.205
41.44,146.64,0.202
41.48,146.83,0.199
41.51,147.02,0.197
41.55,147.22,0.195
41.59,147.41,0.194
41.63,147.60,0.192
41.67,147.80,0.191
41.71,147.99,0.190
41.74,148.18,0.189
41.78,148.37,0.188
41.82,148.57,0.187
41.86,148.76,0.187
41.90,148.95,0.186
41.94,149.14,0.186
41.98,149.33,0.185
42.01,149.53,0.185
42.05,149.72,0.184
42.09,149.91,0.184
42.13,150.10,0.183
42.17,150.29,0.183
42.21,150.49,0.182
42.24,150.68,0.182
42.28,150.87,0.182
42.32,151.06,0.181
42.36,151.25,0.181
42.40,151.44,0.181
42.44,151.64,0.181
42.47,151.83,0.181
42.51,152.02,0.181
42.55,152.21,0.181
42.59,152.40,0.181
42.63,152.59,0.180
42.66,152.79,0.180
42.70,152.98,0.180
42.74,153.17,0.180
42.78,153.36,0.180
42.82,153.55,0.180
42.86,153.74,0.180
42.89,153.94,0.180
42.93,154.13,0.180
42.97,154.32,0.180
43.01,154.51,0.180
43.05,154.70,0.180
43.09,154.89,0.180
43.13,155.09,0.180
43.16,155.28,0.180
43.20,155.47,0.180
43.24,155.66,0.181
43.28,155.85,0.181
43.32,156.05,0.181
43.36,156.24,0.181
43.39,156.43,0.181
43.43,156.62,0.181
43.47,156.81,0.181
43.51,157.00,0.181
43.55,157.20,0.181
43.59,157.39,0.181
43.62,157.58,0.181
43.66,157.77,0.181
43.70,157.96,0.181
43.74,158.15,0.181
43.78,158.35,0.181
43.81,158.54,0.181
43.85,158.73,0.181
43.89,158.92,0.181
43.93,159.11,0.181
43.97,159.30,0.181
44.01,159.50,0.181
44.04,159.69,0.181
44.08,159.88,0.181
44.12,160.07,0.181
44.16,160.26,0.181
44.20,160.45,0.181
44.24,160.65,0.181
44.28,160.84,0.181
44.31,161.03,0.181
44.35,161.22,0.181
44.39,161.41,0.181
44.43,161.60,0.181
44.47,161.80,0.181
44.51,161.99,0.181
44.54,162.18,0.181
44.58,162.37,0.181
44.62,162.56,0.181
44.66,162.75,0.181
44.70,162.95,0.181
44.74,163.14,0.181
44.77,163.33,0.181
44.81,163.52,0.182
44.85,163.71,0.182
44.89,163.91,0.182
44.93,164.10,0.182
44.96,164.29,0.182
45.00,164.48,0.182
45.04,164.67,0.182
45.08,164.86,0.182
45.12,165.05,0.182
45.16,165.25,0.182
45.19,165.44,0.182
45.23,165.63,0.182
45.27,165.82,0.183
45.31,166.01,0.183
45.35,166.21,0.183
45.39,166.40,0.183
45.43,166.59,0.183
45.46,166.78,0.183
45.50,166.97,0.184
45.54,167.16,0.184
45.58,167.35,0.184
45.62,167.55,0.184
45.66,167.74,0.184
45.69,167.93,0.185
45.73,168.12,0.185
45.77,168.31,0.185
45.81,168.51,0.185
45.85,168.70,0.186
45.89,168.89,0.186
45.92,169.08,0.186
45.96,169.27,0.186
46.00,169.46,0.186
46.04,169.65,0.187
46.08,169.85,0.187
46.11,170.04,0.187
46.15,170.23,0.187
46.19,170.42,0.187
46.23,170.61,0.188
46.27,170.80,0.188
46.31,171.00,0.188
46.34,171.19,0.188
46.38,171.38,0.189
46.42,171.57,0.189
46.46,171.76,0.189
46.50,171.95,0.189
46.54,172.15,0.190
46.58,172.34,0.190
46.61,172.53,0.190
46.65,172.72,0.190
46.69,172.91,0.191
46.73,173.10,0.191
46.77,173.30,0.191
46.81,173.49,0.191
46.84,173.68,0.192
46.88,173.87,0.192
46.92,174.06,0.192
46.96,174.25,0.192
47.00,174.44,0.193
47.04,174.64,0.193
47.07,174.83,0.193
47.11,175.02,0.193
47.15,175.21,0.193
47.19,175.40,0.194
47.23,175.59,0.194
47.26,175.79,0.194
47.30,175.98,0.194
47.34,176.17,0.195
47.38,176.36,0.195
47.42,176.55,0.195
47.46,176.74,0.195
47.49,176.93,0.195
47.53,177.13,0.196
47.57,177.32,0.196
47.61,177.51,0.196
47.65,177.70,0.197
47.69,177.89,0.197
47.73,178.08,0.197
47.76,178.28,0.197
47.80,178.47,0.197
47.84,178.66,0.198
47.88,178.85,0.198
47.92,179.04,0.198
47.96,179.24,0.198
47.99,179.43,0.199
48.03,179.62,0.199
48.07,179.81,0.199
48.11,180.00,0.199
48.15,180.19,0.200
48.19,180.38,0.200
48.22,180.58,0.200
48.26,180.77,0.200
48.30,180.96,0.200
48.34,181.15,0.201
48.38,181.34,0.201
48.41,181.53,0.201
48.45,181.73,0.202
48.49,181.92,0.202
48.53,182.11,0.202
48.57,182.30,0.203
48.61,182.49,0.203
48.64,182.68,0.203
48.68,182.88,0.204
48.72,183.07,0.204
48.76,183.26,0.204
48.80,183.45,0.205
48.84,183.64,0.205
48.88,183.83,0.206
48.91,184.02,0.207
48.95,184.22,0.212
48.99,184.40,0.226
49.03,184.59,0.227
49.07,184.78,0.230
49.11,184.97,0.249
49.14,185.16,0.254
49.18,185.35,0.250
49.22,185.54,0.244
49.26,185.73,0.249
49.30,185.92,0.243
49.34,186.12,0.237
49.37,186.31,0.233
49.41,186.51,0.230
49.45,186.70,0.229
49.49,186.89,0.228
49.53,187.08,0.227
49.56,187.28,0.227
49.60,187.47,0.226
49.64,187.66,0.226
49.68,187.85,0.226
49.72,188.04,0.226
49.76,188.23,0.226
49.79,188.43,0.225
49.83,188.62,0.225
49.87,188.81,0.225
49.91,189.00,0.225
49.95,189.19,0.225
49.99,189.39,0.224
50.03,189.58,0.224
50.06,189.77,0.223
50.10,189.96,0.223
50.14,190.15,0.222
50.18,190.34,0.222
50.22,190.54,0.222
50.26,190.73,0.221
50.29,190.92,0.221
50.33,191.11,0.221
50.37,191.30,0.221
50.41,191.49,0.220
50.45,191.69,0.220
50.49,191.88,0.220
50.52,192.07,0.220
50.56,192.26,0.220
50.60,192.45,0.220
50.64,192.65,0.219
50.68,192.84,0.219
50.71,193.03,0.219
50.75,193.22,0.219
50.79,193.41,0.219
50.83,193.61,0.219
50.87,193.80,0.219
50.91,193.99,0.219
50.94,194.18,0.219
50.98,194.37,0.219
51.02,194.56,0.219
51.06,194.76,0.218
51.10,194.95,0.218
51.14,195.14,0.218
51.18,195.33,0.218
51.21,195.52,0.218
51.25,195.72,0.218
51.29,195.91,0.218
51.33,196.10,0.218
51.37,196.29,0.218
51.41,196.48,0.218
51.44,196.67,0.218
51.48,196.86,0.218
51.52,197.06,0.218
51.56,197.25,0.218
51.60,197.44,0.218
51.64,197.63,0.218
51.67,197.82,0.218
51.71,198.01,0.218
51.75,198.20,0.218
51.79,198.40,0.218
51.83,198.59,0.218
51.86,198.78,0.219
51.90,198.97,0.219
51.94,199.16,0.219
51.98,199.36,0.219
52.02,199.55,0.219
52.06,199.74,0.219
52.09,199.93,0.219
52.13,200.12,0.219
52.17,200.31,0.219
52.21,200.51,0.219
52.25,200.70,0.219
52.29,200.89,0.219
52.33,201.08,0.219
52.36,201.27,0.219
52.40,201.47,0.219
52.44,201.66,0.219
52.48,201.85,0.219
52.52,202.04,0.219
52.56,202.23,0.219
52.59,202.42,0.219
52.63,202.62,0.219
52.67,202.81,0.219
52.71,203.00,0.220
52.75,203.19,0.220
52.79,203.38,0.220
52.82,203.57,0.220
52.86,203.76,0.220
52.90,203.96,0.220
52.94,204.15,0.220
52.98,204.34,0.220
53.01,204.53,0.220
53.05,204.72,0.220
53.09,204.92,0.220
53.13,205.11,0.220
53.17,205.30,0.220
53.21,205.49,0.220
53.24,205.68,0.220
53.28,205.87,0.220
53.32,206.07,0.220
53.36,206.26,0.220
53.40,206.45,0.220
53.44,206.64,0.220
53.48,206.83,0.220
53.51,207.02,0.220
53.55,207.22,0.220
53.59,207.41,0.220
53.63,207.60,0.220
53.67,207.79,0.220
53.71,207.98,0.219
53.74,208.17,0.219
53.78,208.37,0.219
53.82,208.56,0.219
53.86,208.75,0.219
53.90,208.94,0.219
53.94,209.13,0.219
53.97,209.33,0.219
54.01,209.52,0.219
54.05,209.71,0.219
54.09,209.90,0.219
54.13,210.09,0.219
54.16,210.28,0.219
54.20,210.48,0.219
54.24,210.67,0.219
54.28,210.86,0.219
54.32,211.05,0.219
54.36,211.24,0.219
54.39,211.43,0.219
54.43,211.63,0.219
54.47,211.82,0.219
54.51,212.01,0.219
54.55,212.20,0.219
54.59,212.39,0.219
54.63,212.58,0.219
54.66,212.77,0.219
54.70,212.97,0.219
54.74,213.16,0.218
54.78,213.35,0.218
54.82,213.54,0.218
54.86,213.73,0.218
54.89,213.93,0.218
54.93,214.12,0.218
54.97,214.31,0.218
55.01,214.50,0.218
55.05,214.69,0.218
55.09,214.88,0.218
55.12,215.08,0.217
55.16,215.27,0.217
55.20,215.46,0.217
55.24,215.65,0.217
55.28,215.84,0.217
55.31,216.03,0.217
55.35,216.23,0.217
55.39,216.42,0.216
55.43,216.61,0.216
55.47,216.80,0.216
55.51,217.00,0.216
55.54,217.19,0.216
55.58,217.38,0.216
55.62,217.57,0.216
55.66,217.76,0.216
55.70,217.95,0.216
55.74,218.15,0.216
55.78,218.34,0.216
55.81,218.53,0.216
55.85,218.72,0.216
55.89,218.91,0.216
55.93,219.10,
55.97,219.29,
55.99,,

[step]
Ramp 5.00 °C/min to -60.00 °C
Time,Temperature,Heat Flow (Normalized)
min,°C,W/g
56.99,220.09,0.009
57.03,220.09,0.009
57.06,220.07,0.009
57.10,220.01,-0.010
57.14,219.90,-0.046
57.18,219.77,-0.088
57.22,219.62,-0.121
57.26,219.45,-0.145
57.29,219.28,-0.160
57.33,219.11,-0.169
57.37,218.93,-0.177
57.41,218.74,-0.183
57.45,218.56,-0.186
57.49,218.37,-0.189
57.52,218.19,-0.190
57.56,218.00,-0.192
57.60,217.81,-0.193
57.64,217.62,-0.194
57.68,217.43,-0.194
57.71,217.24,-0.195
57.75,217.05,-0.196
57.79,216.86,-0.196
57.83,216.67,-0.197
57.87,216.48,-0.197
57.91,216.29,-0.197
57.94,216.10,-0.198
57.98,215.91,-0.198
58.02,215.72,-0.198
58.06,215.53,-0.199
58.10,215.34,-0.199
58.14,215.15,-0.199
58.18,214.96,-0.199
58.21,214.77,-0.199
58.25,214.58,-0.200
58.29,214.39,-0.200
58.33,214.20,-0.200
58.37,214.00,-0.200
58.41,213.81,-0.200
58.44,213.62,-0.200
58.48,213.43,-0.200
58.52,213.24,-0.200
58.56,213.05,-0.200
58.60,212.86,-0.200
58.64,212.67,-0.201
58.67,212.47,-0.201
58.71,212.28,-0.201
58.75,212.09,-0.201
58.79,211.90,-0.201
58.83,211.71,-0.201
58.86,211.52,-0.201
58.90,211.33,-0.201
58.94,211.14,-0.201
58.98,210.94,-0.201
59.02,210.75,-0.201
59.06,210.56,-0.201
59.09,210.37,-0.201
59.13,210.18,-0.201
59.17,209.99,-0.201
59.21,209.79,-0.201
59.25,209.60,-0.201
59.29,209.41,-0.201
59.33,209.22,-0.201
59.36,209.03,-0.201
59.40,208.84,-0.201
59.44,208.65,-0.201
59.48,208.46,-0.201
59.52,208.26,-0.201
59.56,208.07,-0.201
59.59,207.88,-0.201
59.63,207.69,-0.201
59.67,207.50,-0.201
59.71,207.31,-0.201
59.75,207.12,-0.201
59.79,206.92,-0.201
59.82,206.73,-0.201
59.86,206.54,-0.201
59.90,206.35,-0.201
59.94,206.16,-0.201
59.98,205.97,-0.201
60.01,205.78,-0.201
60.05,205.59,-0.201
60.09,205.39,-0.201
60.13,205.20,-0.201
60.17,205.01,-0.201
60.21,204.82,-0.201
60.24,204.63,-0.201
60.28,204.43,-0.201
60.32,204.24,-0.201
60.36,204.05,-0.201
60.40,203.86,-0.201
60.44,203.67,-0.201
60.48,203.48,-0.201
60.51,203.29,-0.201
60.55,203.09,-0.201
60.59,202.90,-0.201
60.63,202.71,-0.201
60.67,202.52,-0.201
60.71,202.33,-0.201
60.74,202.14,-0.201
60.78,201.94,-0.201
60.82,201.75,-0.201
60.86,201.56,-0.201
60.90,201.37,-0.201
60.94,201.18,-0.201
60.97,200.99,-0.201
61.01,200.80,-0.201
61.05,200.60,-0.201
61.09,200.41,-0.201
61.13,200.22,-0.201
61.16,200.03,-0.201
61.20,199.84,-0.201
61.24,199.65,-0.201
61.28,199.46,-0.201
61.32,199.27,-0.201
61.36,199.07,-0.201
61.39,198.88,-0.201
61.43,198.69,-0.201
61.47,198.50,-0.201
61.51,198.31,-0.201
61.55,198.12,-0.201
61.59,197.93,-0.201
61.63,197.74,-0.201
61.66,197.54,-0.201
61.70,197.35,-0.202
61.74,197.16,-0.202
61.78,196.97,-0.202
61.82,196.77,-0.202
61.86,196.58,-0.202
61.89,196.39,-0.202
61.93,196.20,-0.202
61.97,196.01,-0.202
62.01,195.82,-0.202
62.05,195.63,-0.202
62.09,195.44,-0.202
62.12,195.24,-0.202
62.16,195.05,-0.202
62.20,194.86,-0.202
62.24,194.67,-0.202
62.28,194.48,-0.202
62.31,194.29,-0.202
62.35,194.10,-0.202
62.39,193.90,-0.202
62.43,193.71,-0.202
62.47,193.52,-0.202
62.51,193.33,-0.202
62.54,193.14,-0.202
62.58,192.95,-0.202
62.62,192.75,-0.202
62.66,192.56,-0.202
62.70,192.37,-0.202
62.74,192.18,-0.202
62.78,191.99,-0.202
62.81,191.80,-0.202
62.85,191.61,-0.202
62.89,191.41,-0.202
62.93,191.22,-0.202
62.97,191.03,-0.202
63.01,190.84,-0.202
63.04,190.65,-0.202
63.08,190.46,-0.202
63.12,190.26,-0.202
63.16,190.07,-0.202
63.20,189.88,-0.202
63.24,189.69,-0.202
63.27,189.50,-0.202
63.31,189.31,-0.202
63.35,189.12,-0.202
63.39,188.93,-0.202
63.43,188.73,-0.202
63.46,188.54,-0.202
63.50,188.35,-0.202
63.54,188.16,-0.202
63.58,187.97,-0.203
63.62,187.78,-0.203
63.66,187.58,-0.203
63.69,187.39,-0.203
63.73,187.20,-0.203
63.77,187.01,-0.203
63.81,186.82,-0.203
63.85,186.63,-0.202
63.89,186.44,-0.202
63.93,186.24,-0.202
63.96,186.05,-0.203
64.00,185.86,-0.203
64.04,185.67,-0.203
64.08,185.48,-0.203
64.12,185.29,-0.203
64.16,185.09,-0.203
64.19,184.90,-0.203
64.23,184.71,-0.203
64.27,184.52,-0.203
64.31,184.33,-0.203
64.35,184.14,-0.203
64.39,183.95,-0.202
64.42,183.75,-0.203
64.46,183.56,-0.203
64.50,183.37,-0.203
64.54,183.18,-0.203
64.58,182.99,-0.203
64.61,182.80,-0.203
64.65,182.61,-0.203
64.69,182.41,-0.203
64.73,182.22,-0.203
64.77,182.03,-0.203
64.81,181.84,-0.203
64.84,181.65,-0.203
64.88,181.46,-0.203
64.92,181.27,-0.203
64.96,181.08,-0.204
65.00,180.88,-0.204
65.04,180.69,-0.205
65.08,180.50,-0.205
65.11,180.31,-0.205
65.15,180.12,-0.206
65.19,179.93,-0.207
65.23,179.73,-0.209
65.27,179.54,-0.211
65.31,179.35,-0.214
65.34,179.16,-0.215
65.38,178.97,-0.217
65.42,178.78,-0.218
65.46,178.59,-0.220
65.50,178.40,-0.222
65.54,178.21,-0.223
65.57,178.02,-0.224
65.61,177.83,-0.226
65.65,177.64,-0.228
65.69,177.45,-0.229
65.73,177.26,-0.230
65.76,177.07,-0.233
65.80,176.87,-0.237
65.84,176.68,-0.242
65.88,176.50,-0.244
65.92,176.30,-0.245
65.96,176.11,-0.245
65.99,175.92,-0.245
66.03,175.73,-0.246
66.07,175.54,-0.246
66.11,175.35,-0.247
66.15,175.16,-0.247
66.19,174.97,-0.247
66.23,174.77,-0.247
66.26,174.58,-0.248
66.30,174.39,-0.248
66.34,174.20,-0.249
66.38,174.01,-0.250
66.42,173.82,-0.251
66.46,173.63,-0.251
66.49,173.44,-0.252
66.53,173.25,-0.252
66.57,173.05,-0.252
66.61,172.86,-0.252
66.65,172.67,-0.252
66.69,172.48,-0.252
66.72,172.29,-0.252
66.76,172.10,-0.252
66.80,171.90,-0.252
66.84,171.71,-0.252
66.88,171.52,-0.252
66.91,171.33,-0.252
66.95,171.14,-0.252
66.99,170.95,-0.253
67.03,170.76,-0.253
67.07,170.56,-0.253
67.11,170.37,-0.252
67.14,170.18,-0.252
67.18,169.99,-0.252
67.22,169.80,-0.252
67.26,169.60,-0.251
67.30,169.41,-0.251
67.34,169.22,-0.250
67.38,169.03,-0.249
67.41,168.84,-0.249
67.45,168.64,-0.247
67.49,168.45,-0.246
67.53,168.26,-0.246
67.57,168.07,-0.245
67.61,167.88,-0.245
67.64,167.69,-0.243
67.68,167.50,-0.243
67.72,167.30,-0.242
67.76,167.11,-0.242
67.80,166.92,-0.242
67.84,166.73,-0.242
67.87,166.54,-0.242
67.91,166.35,-0.242
67.95,166.15,-0.242
67.99,165.96,-0.243
68.03,165.77,-0.243
68.06,165.58,-0.244
68.10,165.39,-0.245
68.14,165.20,-0.247
68.18,165.01,-0.248
68.22,164.82,-0.249
68.26,164.63,-0.250
68.30,164.44,-0.251
68.33,164.24,-0.252
68.37,164.05,-0.253
68.41,163.86,-0.255
68.45,163.67,-0.256
68.49,163.48,-0.258
68.53,163.29,-0.258
68.56,163.10,-0.259
68.60,162.91,-0.260
68.64,162.71,-0.260
68.68,162.52,-0.261
68.72,162.33,-0.261
68.75,162.14,-0.262
68.79,161.95,-0.262
68.83,161.76,-0.262
68.87,161.57,-0.263
68.91,161.38,-0.263
68.95,161.18,-0.263
68.99,160.99,-0.263
69.02,160.80,-0.264
69.06,160.61,-0.264
69.10,160.42,-0.263
69.14,160.23,-0.263
69.18,160.03,-0.263
69.21,159.84,-0.263
69.25,159.65,-0.262
69.29,159.46,-0.262
69.33,159.27,-0.262
69.37,159.07,-0.262
69.41,158.88,-0.261
69.45,158.69,-0.260
69.48,158.50,-0.259
69.52,158.31,-0.258
69.56,158.12,-0.257
69.60,157.92,-0.256
69.64,157.73,-0.255
69.68,157.54,-0.254
69.71,157.35,-0.253
[...]
244.93,23.99,0.141
244.97,24.19,0.141
245.01,24.38,0.141
245.05,24.57,0.141
245.08,24.76,0.141
245.12,24.95,0.141
245.16,25.14,0.141
245.20,25.34,0.142
245.24,25.53,0.142
245.28,25.72,0.142
245.31,25.91,0.142
245.35,26.10,0.142
245.39,26.30,0.142
245.43,26.49,0.142
245.47,26.68,0.142
245.50,26.87,0.142
245.54,27.06,0.142
245.58,27.25,0.142
245.62,27.45,0.142
245.66,27.64,0.143
245.70,27.83,0.143
245.73,28.02,0.143
245.77,28.21,0.143
245.81,28.40,0.143
245.85,28.60,0.143
245.89,28.79,0.143
245.93,28.98,0.143
245.97,29.17,0.143
246.00,29.36,0.143
246.04,29.56,0.143
246.08,29.75,0.143
246.12,29.94,0.143
246.16,30.13,0.144
246.20,30.32,0.144
246.23,30.51,0.144
246.27,30.71,0.144
246.31,30.90,0.144
246.35,31.09,0.144
246.39,31.28,0.144
246.43,31.47,0.144
246.46,31.67,0.144
246.50,31.86,0.144
246.54,32.05,0.144
246.58,32.24,0.144
246.62,32.43,0.144
246.65,32.62,0.144
246.69,32.82,0.144
246.73,33.01,0.144
246.77,33.20,0.144
246.81,33.39,0.145
246.85,33.58,0.145
246.88,33.77,0.145
246.92,33.97,0.145
246.96,34.16,0.145
247.00,34.35,0.145
247.04,34.54,0.145
247.08,34.73,0.145
247.12,34.93,0.145
247.15,35.12,0.145
247.19,35.31,0.145
247.23,35.50,0.145
247.27,35.69,0.145
247.31,35.88,0.145
247.35,36.08,0.146
247.38,36.27,0.146
247.42,36.46,0.146
247.46,36.65,0.146
247.50,36.84,0.146
247.54,37.04,0.146
247.58,37.23,0.146
247.61,37.42,0.146
247.65,37.61,0.146
247.69,37.80,0.146
247.73,37.99,0.146
247.77,38.19,0.146
247.80,38.38,0.146
247.84,38.57,0.146
247.88,38.76,0.147
247.92,38.95,0.147
247.96,39.15,0.147
248.00,39.34,0.147
248.03,39.53,0.147
248.07,39.72,0.147
248.11,39.91,0.147
248.15,40.10,0.147
248.19,40.30,0.147
248.23,40.49,0.147
248.27,40.68,0.147
248.30,40.87,0.147
248.34,41.06,0.147
248.38,41.26,0.147
248.42,41.45,0.147
248.46,41.64,0.147
248.50,41.83,0.148
248.53,42.02,0.148
248.57,42.21,0.148
248.61,42.40,0.148
248.65,42.60,0.148
248.69,42.79,0.148
248.73,42.98,0.148
248.76,43.17,0.148
248.80,43.36,0.148
248.84,43.56,0.148
248.88,43.75,0.148
248.92,43.94,0.149
248.95,44.13,0.149
248.99,44.32,0.149
249.03,44.51,0.149
249.07,44.71,0.149
249.11,44.90,0.149
249.15,45.09,0.149
249.18,45.28,0.149
249.22,45.47,0.149
249.26,45.67,0.149
249.30,45.86,0.150
249.34,46.05,0.150
249.38,46.24,0.150
249.42,46.43,0.150
249.45,46.62,0.150
249.49,46.82,0.150
249.53,47.01,0.150
249.57,47.20,0.150
249.61,47.39,0.150
249.65,47.58,0.150
249.68,47.78,0.150
249.72,47.97,0.151
249.76,48.16,0.151
249.80,48.35,0.151
249.84,48.54,0.151
249.88,48.73,0.151
249.91,48.92,0.151
249.95,49.12,0.151
249.99,49.31,0.151
250.03,49.50,0.151
250.07,49.69,0.151
250.10,49.89,0.152
250.14,50.08,0.152
250.18,50.27,0.152
250.22,50.46,0.152
250.26,50.65,0.152
250.30,50.84,0.152
250.33,51.04,0.152
250.37,51.23,0.152
250.41,51.42,0.152
250.45,51.61,0.153
250.49,51.80,0.153
250.53,51.99,0.153
250.57,52.19,0.153
250.60,52.38,0.153
250.64,52.57,0.153
250.68,52.76,0.153
250.72,52.95,0.153
250.76,53.14,0.153
250.80,53.34,0.154
250.83,53.53,0.154
250.87,53.72,0.154
250.91,53.91,0.154
250.95,54.10,0.154
250.99,54.30,0.154
251.03,54.49,0.154
251.06,54.68,0.154
251.10,54.87,0.154
251.14,55.06,0.155
251.18,55.25,0.155
251.22,55.45,0.155
251.25,55.64,0.155
251.29,55.83,0.155
251.33,56.02,0.155
251.37,56.21,0.155
251.41,56.40,0.155
251.45,56.59,0.156
251.48,56.79,0.156
251.52,56.98,0.156
251.56,57.17,0.156
251.60,57.36,0.156
251.64,57.55,0.156
251.68,57.75,0.156
251.72,57.94,0.156
251.75,58.13,0.157
251.79,58.32,0.157
251.83,58.51,0.157
251.87,58.70,0.157
251.91,58.90,0.157
251.95,59.09,0.157
251.98,59.28,0.157
252.02,59.47,0.158
252.06,59.66,0.158
252.10,59.86,0.158
252.14,60.05,0.158
252.18,60.24,0.158
252.21,60.43,0.158
252.25,60.62,0.159
252.29,60.81,0.159
252.33,61.01,0.159
252.37,61.20,0.159
252.40,61.39,0.159
252.44,61.58,0.159
252.48,61.77,0.159
252.52,61.97,0.160
252.56,62.16,0.160
252.60,62.35,0.160
252.63,62.54,0.160
252.67,62.73,0.160
252.71,62.92,0.160
252.75,63.12,0.161
252.79,63.31,0.161
252.83,63.50,0.161
252.87,63.69,0.161
252.90,63.88,0.161
252.94,64.08,0.161
252.98,64.27,0.161
253.02,64.46,0.162
253.06,64.65,0.162
253.10,64.84,0.162
253.13,65.03,0.162
253.17,65.22,0.162
253.21,65.41,0.162
253.25,65.61,0.162
253.29,65.80,0.162
253.33,65.99,0.163
253.36,66.18,0.163
253.40,66.37,0.163
253.44,66.57,0.163
253.48,66.76,0.163
253.52,66.95,0.163
253.55,67.14,0.163
253.59,67.33,0.164
253.63,67.52,0.164
253.67,67.71,0.164
253.71,67.91,0.164
253.75,68.10,0.164
253.78,68.29,0.164
253.82,68.48,0.164
253.86,68.67,0.164
253.90,68.87,0.165
253.94,69.06,0.165
253.98,69.25,0.165
254.02,69.44,0.165
254.05,69.63,0.165
254.09,69.83,0.165
254.13,70.02,0.165
254.17,70.21,0.165
254.21,70.40,0.166
254.25,70.59,0.166
254.28,70.78,0.166
254.32,70.97,0.166
254.36,71.17,0.166
254.40,71.36,0.166
254.44,71.55,0.166
254.48,71.74,0.166
254.51,71.93,0.167
254.55,72.13,0.167
254.59,72.32,0.167
254.63,72.51,0.167
254.67,72.70,0.167
254.70,72.89,0.167
254.74,73.08,0.167
254.78,73.28,0.167
254.82,73.47,0.167
254.86,73.66,0.168
254.90,73.85,0.168
254.93,74.04,0.168
254.97,74.23,0.168
255.01,74.43,0.168
255.05,74.62,0.168
255.09,74.81,0.168
255.13,75.00,0.168
255.17,75.19,0.168
255.20,75.39,0.169
255.24,75.58,0.169
255.28,75.77,0.169
255.32,75.96,0.169
255.36,76.15,0.169
255.40,76.34,0.169
255.43,76.54,0.169
255.47,76.73,0.169
255.51,76.92,0.169
255.55,77.11,0.169
255.59,77.30,0.169
255.63,77.49,0.170
255.66,77.69,0.170
255.70,77.88,0.170
255.74,78.07,0.170
255.78,78.26,0.170
255.82,78.45,0.170
255.85,78.65,0.170
255.89,78.84,0.170
255.93,79.03,0.171
255.97,79.22,0.171
256.01,79.41,0.171
256.05,79.61,0.171
256.08,79.80,0.171
256.12,79.99,0.171
256.16,80.18,0.171
256.20,80.37,0.171
256.24,80.56,0.171
256.28,80.75,0.171
256.32,80.95,0.171
256.35,81.14,0.172
256.39,81.33,0.172
256.43,81.52,0.172
256.47,81.71,0.172
256.51,81.90,0.172
256.55,82.10,0.172
256.58,82.29,0.172
256.62,82.48,0.172
256.66,82.67,0.172
256.70,82.86,0.172
256.74,83.06,0.172
256.78,83.25,0.173
256.81,83.44,0.173
256.85,83.63,0.173
256.89,83.82,0.173
256.93,84.01,0.173
256.97,84.21,0.173
257.00,84.40,0.173
257.04,84.59,0.173
257.08,84.78,0.173
257.12,84.97,0.173
257.16,85.16,0.173
257.20,85.36,0.174
257.23,85.55,0.174
257.27,85.74,0.174
257.31,85.93,0.174
257.35,86.12,0.174
257.39,86.32,0.174
257.43,86.51,0.174
257.47,86.70,0.174
257.50,86.89,0.174
257.54,87.08,0.174
257.58,87.27,0.174
257.62,87.47,0.175
257.66,87.66,0.175
257.70,87.85,0.175
257.73,88.04,0.175
257.77,88.23,0.175
257.81,88.42,0.175
257.85,88.61,0.175
257.89,88.81,0.175
257.93,89.00,0.175
257.96,89.19,0.176
258.00,89.38,0.176
258.04,89.57,0.176
258.08,89.77,0.176
258.12,89.96,0.176
258.15,90.15,0.176
258.19,90.34,0.176
258.23,90.53,0.176
258.27,90.72,0.176
258.31,90.92,0.177
258.35,91.11,0.177
258.38,91.30,0.177
258.42,91.49,0.177
258.46,91.68,0.177
258.50,91.88,0.177
258.54,92.07,0.177
258.58,92.26,0.178
258.62,92.45,0.178
258.65,92.64,0.178
258.69,92.83,0.178
258.73,93.02,0.178
258.77,93.22,0.178
258.81,93.41,0.178
258.85,93.60,0.178
258.88,93.79,0.178
258.92,93.98,0.178
258.96,94.18,0.178
259.00,94.37,0.179
259.04,94.56,0.179
259.08,94.75,0.179
259.11,94.94,0.179
259.15,95.13,0.179
259.19,95.33,0.179
259.23,95.52,0.179
259.27,95.71,0.179
259.30,95.90,0.179
259.34,96.09,0.180
259.38,96.29,0.180
259.42,96.48,0.180
259.46,96.67,0.180
259.50,96.86,0.180
259.53,97.05,0.180
259.57,97.24,0.180
259.61,97.44,0.180
259.65,97.63,0.180
259.69,97.82,0.181
259.73,98.01,0.181
259.77,98.20,0.181
259.80,98.39,0.181
259.84,98.59,0.181
259.88,98.78,0.181
259.92,98.97,0.181
259.96,99.16,0.181
260.00,99.35,0.181
260.03,99.54,0.182
260.07,99.74,0.182
260.11,99.93,0.182
260.15,100.12,0.182
260.19,100.31,0.182
260.23,100.50,0.182
260.26,100.70,0.182
260.30,100.89,0.182
260.34,101.08,0.182
260.38,101.27,0.183
260.42,101.46,0.183
260.45,101.66,0.183
260.49,101.85,0.183
260.53,102.04,0.183
260.57,102.23,0.183
260.61,102.42,0.183
260.65,102.61,0.183
260.68,102.81,0.183
260.72,103.00,0.183
260.76,103.19,0.184
260.80,103.38,0.184
260.84,103.57,0.184
260.88,103.76,0.184
260.92,103.95,0.184
260.95,104.15,0.184
260.99,104.34,0.184
261.03,104.53,0.184
261.07,104.72,0.184
261.11,104.91,0.184
261.15,105.10,0.185
261.18,105.30,0.185
261.22,105.49,0.185
261.26,105.68,0.185
261.30,105.87,0.185
261.34,106.06,0.185
261.38,106.25,0.185
261.41,106.45,0.185
261.45,106.64,0.185
261.49,106.83,0.186
261.53,107.02,0.186
261.57,107.21,0.186
261.60,107.41,0.186
261.64,107.60,0.186
261.68,107.79,0.186
261.72,107.98,0.186
261.76,108.17,0.187
261.80,108.36,0.187
261.83,108.56,0.187
261.87,108.75,0.187
261.91,108.94,0.187
261.95,109.13,0.187
261.99,109.32,0.187
262.03,109.51,0.187
262.07,109.70,0.188
262.10,109.90,0.188
262.14,110.09,0.188
262.18,110.28,0.188
262.22,110.47,0.188
262.26,110.66,0.188
262.30,110.86,0.188
262.33,111.05,0.188
262.37,111.24,0.189
262.41,111.43,0.189
262.45,111.62,0.189
262.49,111.81,0.189
262.53,112.01,0.189
262.56,112.20,0.189
262.60,112.39,0.189
262.64,112.58,0.189
262.68,112.77,0.190
262.72,112.96,0.190
262.75,113.16,0.190
262.79,113.35,0.190
262.83,113.54,0.190
262.87,113.73,0.190
262.91,113.92,0.190
262.95,114.12,0.191
262.98,114.31,0.191
263.02,114.50,0.191
263.06,114.69,0.191
263.10,114.89,0.191
263.14,115.08,0.192
263.18,115.27,0.192
263.22,115.46,0.192
263.25,115.65,0.192
263.29,115.84,0.192
263.33,116.04,0.192
263.37,116.23,0.192
263.41,116.42,0.192
263.45,116.61,0.192
263.48,116.80,0.192
263.52,116.99,0.192
263.56,117.18,0.192
263.60,117.38,0.192
263.64,117.57,0.193
263.68,117.76,0.193
263.71,117.95,0.193
263.75,118.14,0.193
263.79,118.33,0.193
263.83,118.53,0.193
263.87,118.72,0.193
263.90,118.91,0.193
263.94,119.10,0.193
263.98,119.29,0.193
264.02,119.48,0.194
264.06,119.68,0.194
264.10,119.87,0.194
264.13,120.06,0.194
264.17,120.25,0.194
264.21,120.44,0.194
264.25,120.63,0.194
264.29,120.82,0.195
264.33,121.02,0.195
264.37,121.21,0.195
264.40,121.40,0.195
264.44,121.59,0.195
264.48,121.78,0.195
264.52,121.98,0.196
264.56,122.17,0.196
264.60,122.36,0.196
264.63,122.55,0.196
264.67,122.74,0.196
264.71,122.93,0.196
264.75,123.13,0.197
264.79,123.32,0.197
264.83,123.51,0.197
264.86,123.70,0.197
264.90,123.89,0.197
264.94,124.08,0.197
264.98,124.27,0.198
265.02,124.47,0.198
265.05,124.66,0.198
265.09,124.85,0.198
265.13,125.04,0.198
265.17,125.23,0.198
265.21,125.43,0.199
265.25,125.62,0.199
265.28,125.81,0.199
265.32,126.00,0.199
265.36,126.19,0.199
265.40,126.38,0.199
265.44,126.57,0.200
265.48,126.77,0.200
265.52,126.96,0.200
265.55,127.15,0.200
265.59,127.34,0.200
265.63,127.53,0.200
265.67,127.73,0.201
265.71,127.92,0.201
265.75,128.11,0.201
265.78,128.30,0.201
265.82,128.49,0.201
265.86,128.68,0.202
265.90,128.87,0.202
265.94,129.07,0.202
265.98,129.26,0.202
266.01,129.45,0.202
266.05,129.64,0.203
266.09,129.83,0.203
266.13,130.03,0.203
266.17,130.22,0.203
266.20,130.41,0.203
266.24,130.60,0.203
266.28,130.79,0.203
266.32,130.98,0.204
266.36,131.17,0.204
266.40,131.37,0.204
266.43,131.56,0.204
266.47,131.75,0.205
266.51,131.94,0.205
266.55,132.13,0.205
266.59,132.32,0.205
266.63,132.52,0.205
266.67,132.71,0.206
266.70,132.90,0.206
266.74,133.09,0.206
266.78,133.28,0.206
266.82,133.48,0.206
266.86,133.67,0.207
266.90,133.86,0.207
266.93,134.05,0.207
266.97,134.24,0.207
267.01,134.44,0.207
267.05,134.63,0.207
267.09,134.82,0.208
267.13,135.01,0.208
267.16,135.20,0.208
267.20,135.39,0.208
267.24,135.59,0.208
267.28,135.78,0.208
267.32,135.97,0.208
267.35,136.16,0.208
267.39,136.35,0.209
267.43,136.54,0.209
267.47,136.73,0.209
267.51,136.93,0.209
267.55,137.12,0.209
267.58,137.31,0.209
267.62,137.50,0.209
267.66,137.69,0.209
267.70,137.88,0.209
267.74,138.07,0.209
267.78,138.27,0.209
267.82,138.46,0.209
267.85,138.65,0.210
267.89,138.84,0.210
267.93,139.03,0.210
267.97,139.23,0.210
268.01,139.42,0.210
268.05,139.61,0.210
268.08,139.80,0.210
268.12,139.99,0.210
268.16,140.18,0.210
268.20,140.38,0.210
268.24,140.57,0.210
268.28,140.76,0.210
268.31,140.95,0.210
268.35,141.14,0.210
268.39,141.33,0.211
268.43,141.53,0.211
268.47,141.72,0.211
268.50,141.91,0.211
268.54,142.10,0.211
268.58,142.29,0.211
268.62,142.48,0.211
268.66,142.67,0.211
268.70,142.87,0.211
268.73,143.06,0.212
268.77,143.25,0.212
268.81,143.44,0.212
268.85,143.63,0.212
268.89,143.82,0.212
268.93,144.02,0.212
268.97,144.21,0.213
269.00,144.40,0.213
269.04,144.59,0.213
269.08,144.78,0.213
269.12,144.98,0.213
269.16,145.17,0.214
269.20,145.36,0.214
269.23,145.55,0.214
269.27,145.74,0.214
269.31,145.94,0.214
269.35,146.13,0.214
269.39,146.32,0.215
269.43,146.51,0.215
269.46,146.70,0.215
269.50,146.89,0.215
269.54,147.08,0.215
269.58,147.28,0.215
269.62,147.47,0.216
269.65,147.66,0.216
269.69,147.85,0.216
269.73,148.04,0.216
269.77,148.23,0.216
269.81,148.43,0.217
269.85,148.62,0.217
269.88,148.81,0.217
269.92,149.00,0.217
269.96,149.19,0.217
270.00,149.39,0.218
270.04,149.58,0.218
270.08,149.77,0.218
270.12,149.96,0.218
270.15,150.15,0.218
270.19,150.34,0.218
270.23,150.53,0.219
270.27,150.72,0.219
270.31,150.92,0.219
270.35,151.11,0.219
270.38,151.30,0.219
270.42,151.49,0.220
270.46,151.68,0.220
270.50,151.88,0.220
270.54,152.07,0.220
270.58,152.26,0.220
270.61,152.45,0.221
270.65,152.64,0.221
270.69,152.83,0.221
270.73,153.03,0.221
270.77,153.22,0.221
270.80,153.41,0.221
270.84,153.60,0.222
270.88,153.79,0.222
270.92,153.98,0.222
270.96,154.18,0.222
271.00,154.37,0.222
271.03,154.56,0.223
271.07,154.75,0.223
271.11,154.94,0.223
271.15,155.13,0.223
271.19,155.33,0.223
271.23,155.52,0.223
271.27,155.71,0.224
271.30,155.90,0.224
271.34,156.09,0.224
271.38,156.28,0.224
271.42,156.48,0.224
271.46,156.67,0.224
271.50,156.86,0.225
271.53,157.05,0.225
271.57,157.24,0.225
271.61,157.43,0.225
271.65,157.63,0.225
271.69,157.82,0.226
271.73,158.01,0.226
271.76,158.20,0.226
271.80,158.39,0.226
271.84,158.58,0.226
271.88,158.78,0.227
271.92,158.97,0.227
271.95,159.16,0.227
271.99,159.35,0.227
272.03,159.54,0.228
272.07,159.73,0.228
272.11,159.93,0.228
272.15,160.12,0.228
272.18,160.31,0.228
272.22,160.50,0.229
272.26,160.69,0.229
272.30,160.88,0.229
272.34,161.08,0.229
272.38,161.27,0.230
272.42,161.46,0.230
272.45,161.65,0.230
272.49,161.84,0.230
272.53,162.03,0.231
272.57,162.22,0.231
272.61,162.42,0.231
272.65,162.61,0.231
272.68,162.80,0.232
272.72,162.99,0.232
272.76,163.18,0.232
272.80,163.37,0.233
272.84,163.57,0.233
272.88,163.76,0.233
272.91,163.95,0.233
272.95,164.14,0.234
272.99,164.33,0.234
273.03,164.52,0.234
273.07,164.71,0.234
273.11,164.91,0.235
273.14,165.10,0.235
273.18,165.29,0.235
273.22,165.48,0.235
273.26,165.67,0.236
273.30,165.86,0.236
273.33,166.06,0.236
273.37,166.25,0.237
273.41,166.44,0.237
273.45,166.63,0.237
273.49,166.82,0.238
273.53,167.01,0.238
273.57,167.20,0.238
273.60,167.40,0.238
273.64,167.59,0.238
273.68,167.78,0.239
273.72,167.97,0.239
273.76,168.16,0.239
273.79,168.36,0.240
273.83,168.55,0.240
273.87,168.74,0.240
273.91,168.93,0.240
273.95,169.12,0.241
273.99,169.32,0.241
274.03,169.51,0.241
274.06,169.70,0.242
274.10,169.89,0.242
274.14,170.08,0.242
274.18,170.27,0.242
274.22,170.46,0.243
274.26,170.65,0.243
274.29,170.85,0.243
274.33,171.04,0.243
274.37,171.23,0.244
274.41,171.42,0.244
274.45,171.61,0.244
274.48,171.81,0.244
274.52,172.00,0.245
274.56,172.19,0.245
274.60,172.38,0.245
274.64,172.57,0.245
274.68,172.76,0.245
274.72,172.96,0.245
274.75,173.15,0.245
274.79,173.34,0.246
274.83,173.53,0.246
274.87,173.72,0.246
274.91,173.91,0.246
274.94,174.10,0.246
274.98,174.29,0.246
275.02,174.49,0.247
275.06,174.68,0.247
275.10,174.87,0.247
275.14,175.06,0.247
275.18,175.25,0.247
275.21,175.44,0.248
275.25,175.64,0.248
275.29,175.83,0.248
275.33,176.02,0.248
275.37,176.21,0.248
275.41,176.40,0.248
275.44,176.59,0.249
275.48,176.79,0.249
275.52,176.98,0.249
275.56,177.17,0.249
275.60,177.36,0.249
275.63,177.55,0.249
275.67,177.74,0.249
275.71,177.94,0.249
275.75,178.13,0.249
275.79,178.32,0.249
275.83,178.51,0.249
275.87,178.71,0.249
275.90,178.90,0.249
275.94,179.09,0.249
275.98,179.28,0.249
276.02,179.47,0.249
276.06,179.67,0.249
276.09,179.86,0.249
276.13,180.05,0.249
276.17,180.24,0.249
276.21,180.43,0.249
276.25,180.62,0.249
276.29,180.82,0.249
276.33,181.01,0.248
276.36,181.20,0.248
276.40,181.39,0.248
276.44,181.58,0.248
276.48,181.78,0.248
276.52,181.97,0.247
276.56,182.16,0.247
276.59,182.35,0.247
276.63,182.54,0.247
276.67,182.73,0.246
276.71,182.93,0.246
276.75,183.12,0.246
276.78,183.31,0.246
276.82,183.50,0.246
276.86,183.69,0.246
276.90,183.89,0.245
276.94,184.08,0.245
276.98,184.27,0.245
277.02,184.46,0.245
277.05,184.65,0.244
277.09,184.84,0.244
277.13,185.03,0.244
277.17,185.23,0.244
277.21,185.42,0.243
277.24,185.61,0.243
277.28,185.80,0.243
277.32,186.00,0.243
277.36,186.19,0.243
277.40,186.38,0.242
277.44,186.57,0.242
277.48,186.76,0.242
277.51,186.95,0.242
277.55,187.15,0.241
277.59,187.34,0.241
277.63,187.53,0.241
277.67,187.72,0.241
277.71,187.91,0.240
277.74,188.10,0.240
277.78,188.30,0.240
277.82,188.49,0.240
277.86,188.68,0.239
277.90,188.87,0.239
277.93,189.06,0.239
277.97,189.26,0.239
278.01,189.45,0.239
278.05,189.64,0.239
278.09,189.83,0.239
278.13,190.02,0.238
278.17,190.21,0.238
278.20,190.41,0.238
278.24,190.60,0.238
278.28,190.79,0.237
278.32,190.98,0.237
278.36,191.17,0.237
278.39,191.37,0.236
278.43,191.56,0.236
278.47,191.75,0.235
278.51,191.94,0.234
278.55,192.13,0.234
278.59,192.32,0.233
278.63,192.52,0.233
278.66,192.71,0.232
278.70,192.90,0.232
278.74,193.09,0.231
278.78,193.29,0.230
278.82,193.48,0.230
278.86,193.67,0.229
278.89,193.86,0.229
278.93,194.05,0.228
278.97,194.25,0.227
279.01,194.44,0.226
279.05,194.63,0.225
279.08,194.82,0.224
279.12,195.01,0.223
279.16,195.21,0.223
279.20,195.40,0.222
279.24,195.59,0.221
279.28,195.79,0.221
279.32,195.98,0.220
279.35,196.17,0.219
279.39,196.36,0.219
279.43,196.55,0.218
279.47,196.74,0.217
279.51,196.94,0.217
279.54,197.13,0.216
279.58,197.32,0.216
279.62,197.51,0.215
279.66,197.70,0.215
279.70,197.89,0.215
279.74,198.09,0.215
279.78,198.28,0.214
279.81,198.47,0.214
279.85,198.66,0.214
279.89,198.85,0.214
279.93,199.05,0.214
279.97,199.24,0.214
280.01,199.43,0.214
280.04,199.62,0.214
280.08,199.81,0.214
280.12,200.00,0.214
280.16,200.20,0.214
280.20,200.39,0.213
280.23,200.58,0.213
280.27,200.77,0.214
280.31,200.96,0.214
280.35,201.15,0.214
280.39,201.34,0.214
280.43,201.54,0.214
280.47,201.73,0.214
280.50,201.92,0.214
280.54,202.11,0.214
280.58,202.30,0.214
280.62,202.50,0.214
280.66,202.69,0.214
280.69,202.88,0.214
280.73,203.07,0.214
280.77,203.26,0.214
280.81,203.45,0.214
280.85,203.64,0.214
280.89,203.84,0.214
280.93,204.03,0.214
280.96,204.22,0.214
281.00,204.41,0.214
281.04,204.60,0.214
281.08,204.80,0.214
281.12,204.99,0.215
281.16,205.18,0.215
281.19,205.37,0.215
281.23,205.56,0.215
281.27,205.75,0.215
281.31,205.95,0.215
281.35,206.14,0.215
281.38,206.33,0.215
281.42,206.52,0.215
281.46,206.71,0.215
281.50,206.90,0.215
281.54,207.09,0.215
281.58,207.29,0.215
281.62,207.48,0.215
281.65,207.67,0.215
281.69,207.86,0.215
281.73,208.05,0.215
281.77,208.24,0.215
281.81,208.44,0.215
281.84,208.63,0.216
281.88,208.82,0.216
281.92,209.01,0.216
281.96,209.20,0.216
282.00,209.40,0.216
282.04,209.59,0.216
282.08,209.78,0.216
282.11,209.97,0.216
282.15,210.16,0.216
282.19,210.35,0.216
282.23,210.54,0.216
282.27,210.74,0.217
282.31,210.93,0.217
282.34,211.12,0.217
282.38,211.31,0.217
282.42,211.50,0.217
282.46,211.69,0.217
282.50,211.89,0.217
282.53,212.08,0.217
282.57,212.27,0.217
282.61,212.46,0.217
282.65,212.65,0.217
282.69,212.84,0.217
282.73,213.04,0.217
282.77,213.23,0.217
282.80,213.42,0.217
282.84,213.61,0.218
282.88,213.80,0.218
282.92,214.00,0.218
282.96,214.19,0.218
282.99,214.38,0.218
283.03,214.57,0.218
283.07,214.76,0.218
283.11,214.95,0.218
283.15,215.15,0.218
283.19,215.34,0.218
283.23,215.53,0.218
283.26,215.72,0.218
283.30,215.91,0.219
283.34,216.10,0.219
283.38,216.29,0.219
283.42,216.49,0.219
283.46,216.68,0.219
283.49,216.87,0.219
283.53,217.06,0.219
283.57,217.25,0.219
283.61,217.45,0.219
283.65,217.64,0.220
283.68,217.83,0.220
283.72,218.02,0.220
283.76,218.21,0.220
283.80,218.40,0.220
283.84,218.59,0.220
283.88,218.79,0.220
283.92,218.98,0.220
283.95,219.17,
283.98,,