File: DSC/2025_05_01_THC_GlutamicAcid_Slurry_n60C_200C_5Cmin_x3.csv
Filename,2025_05_01_THC_GlutamicAcid_Slurry_n60C_200C_5Cmin_x3
Instrument name,DSC2A-00468 (192.168.1.100)
Operator,Yarger
rundate,5/1/2025
Sample name,2025_05_01_THC_GlutamicAcid_Slurry_n60C_200C_5Cmin_x3
proceduresegments,Data Off ; Equilibrate -60.00 °C; Data On ; Ramp 5.00 °C/min to 200.00 °C; Data Off ; Isothermal 1.0 min; Data On ; Ramp 5.00 °C/min to -60.00 °C; Data Off ; Isothermal 1.0 min; Data On ; Ramp 5.00 °C/min to 200.00 °C; Data Off ; Isothermal 1.0 min; Data On ; Ramp 5.00 °C/min to -60.00 °C; Data Off ; Isothermal 1.0 min; Data On ; Ramp 5.00 °C/min to 200.00 °C
[File Parameters]
Run date,5/1/2025 11:25:17 AM
Trios version,5.1.1.46572
Original File Name,
Current File Name,D:\DSC2500\JYarger\2025_05_01_THC_GlutamicAcid_Slurry_n60C_200C_5Cmin_x3.tri
[Procedure]
Procedure Name,THC_GA_n60C_200C_5Cmin_x3
Sample Name,2025_05_01_THC_GlutamicAcid_Slurry_n60C_200C_5Cmin_x3
Sample Mass,5.89 mg
Reference Sample Mass,0 mg
Pan Mass,54.65 mg
Pan Number,12
Reference Pan Mass,53.35 mg
Reference Pan Number,1
Pan Type,Tzero Aluminum Hermetic
Comments,Al Hermetic DSC Consumables sealed Pan/Lid. Y2 Tray (Google Sheet: DSC_Samples_Vext_Y2_Tray_May2025)
Project Name,CA
Operator,Yarger
Test,Custom
Unload Max Temperature,30
Unload Min Temperature,30
Load Max Temperature,30
Load Min Temperature,30
Stop on Gas Flow Error,Yes
[Signal List]
Signal #1,Time (min)
Signal #2,Temperature (°C)
Signal #3,Heat Flow (mW)
Signal #4,Delta T (µV)
Signal #5,Delta Tzero (µV)
Signal #6,Tzero Temperature (°C)
Signal #7,Cell Purge (mL/min)
Signal #8,Heater Temp (°C)
Signal #9,Power Delivered (W)
Signal #10,Reference Junction Temperature (°C)
Signal #11,Flange Temperature (°C)
Signal #12,Heat Flow Phase (rad)
Signal #13,Total Heat Capacity (J/°C)
Signal #14,Heat Capacity (J/°C)
[Configuration]
Company Name,ASU
Instrument Name,DSC2A-00468
Instrument Type,DSC2500
Serial Number,DSC2A-00468
IP,192.168.1.100
Location of Instrument,MRRC
DisplayType,Unknown
Sample Interval ,0.1 s/pt
Selected Heat Flow,T4P
Exotherm Direction,Down
Cell Serial,DRC2-00792
Lid Type,Standard
Cooler,RCS 90
Leave Cooler on at End of Sequence,On
Gas 2,Nitrogen
Gas Selected,Channel 1
Flow Rate,50 mL/min
Secondary Purge,On
Licensed Heat Flow,Heat Flow T4P
Modulation Licensed,Yes
[Versions]
Common IDD Version,1
Cortex Version,VER 2.10.2.31
Driver,5.0.0.6
GDM Version,1.0.3.3
TouchscreenVersion,1.0.0.16145
FEP Version,1.2.1.21
FEP Bootloader,2.0.0.5
AutoSampler Version,2.1.1.26
Auto Sampler Bootloader,2.0.0.5
FCM Version,1.1.0.3
FCM Bootloader,2.0.0.5
[Experiment Logs]
Experiment Log Entry # 1,Data On set to 0
Experiment Log Entry # 3,Equilibrate Segment -60 (C) Started
Experiment Log Entry # 5,Air Cool is off.
Experiment Log Entry # 7,Data On set to 1
Experiment Log Entry # 9,Ramp Segment 5 C/min to 200 Started
Experiment Log Entry # 11,Data On set to 0
Experiment Log Entry # 13,Isothermal Segment 1 min started
Experiment Log Entry # 15,Data On set to 1
Experiment Log Entry # 17,Ramp Segment 5 C/min to -60 Started
Experiment Log Entry # 19,Data On set to 0
Experiment Log Entry # 21,Isothermal Segment 1 min started
Experiment Log Entry # 23,Data On set to 1
Experiment Log Entry # 25,Ramp Segment 5 C/min to 200 Started
Experiment Log Entry # 27,Data On set to 0
Experiment Log Entry # 29,Isothermal Segment 1 min started
Experiment Log Entry # 31,Data On set to 1
Experiment Log Entry # 33,Ramp Segment 5 C/min to -60 Started
Experiment Log Entry # 35,Data On set to 0
Experiment Log Entry # 37,Isothermal Segment 1 min started
Experiment Log Entry # 39,Data On set to 1
Experiment Log Entry # 41,Ramp Segment 5 C/min to 200 Started
[Method Log]
Method Log Entry # 1,Data Off
Method Log Entry # 2,Equilibrate -60 °C
Method Log Entry # 3,Data On
Method Log Entry # 4,(Ramp 237609) Ramp 5 °C/minute to 200 °C
Method Log Entry # 5,Data Off
Method Log Entry # 6,Isothermal 1 minutes
Method Log Entry # 7,Data On
Method Log Entry # 8,(Ramp 237613) Ramp 5 °C/minute to -60 °C
Method Log Entry # 9,Data Off
Method Log Entry # 10,Isothermal 1 minutes
Method Log Entry # 11,Data On
Method Log Entry # 12,(Ramp 237617) Ramp 5 °C/minute to 200 °C
Method Log Entry # 13,Data Off
Method Log Entry # 14,Isothermal 1 minutes
Method Log Entry # 15,Data On
Method Log Entry # 16,(Ramp 237621) Ramp 5 °C/minute to -60 °C
Method Log Entry # 17,Data Off
Method Log Entry # 18,Isothermal 1 minutes
Method Log Entry # 19,Data On
Method Log Entry # 20,(Ramp 237625) Ramp 5 °C/minute to 200 °C
Cell Serial,DRC2-00792
[T1 Calibration]
Slope,-0.008529666
Offset,9.636258
Initial Temperature,98.23
GUID,f8bfdadc-4977-4fdf-ba6d-0ba9134940c3
[TZero Calibration]
Date Applied,11/29/2022 4:06:13 PM
Description,From -89.059 °C to 396.009 °C at 20.000°C/min
Gas Type,Nitrogen
Pan Type,None
Source Files 1,C:\Users\yargerlab\Desktop\DSC Data\General\TZero_calibration_11_29_22_2nd(2).tri
Source Files 2,C:\Users\yargerlab\Desktop\DSC Data\General\TZero_calibration_11_29_22_2nd(3).tri
Delta T Offset,13.05235
Delta T Slope,-0.007271007
Delta T0 Offset,-13.69128
Delta T0 Slope,0.06063341
[Temperature Calibration]
Date Applied,11/29/2022 7:12:28 PM
Description,From 106.590 °C to 186.590 °C at 10.000°C/min
Gas Type,Nitrogen
Pan Type,Tzero Aluminum Hermetic
Source Files 1,C:\Users\yargerlab\Desktop\DSC Data\General\Indium(6).tri
Measured 1,157.391
Known 1,156.598
[Cell Constant Calibration]
Date Applied,11/29/2022 7:12:29 PM
Description,From 106.590 °C to 186.590 °C at 10.000°C/min
Gas Type,Nitrogen
Pan Type,Tzero Aluminum Hermetic
Source Files 1,C:\Users\yargerlab\Desktop\DSC Data\General\Indium(6).tri
T4P KCell,1.006051
Onset Slope,63.26126 mW/°C
[Direct Cp Calibration]
Date Applied,11/30/2022 11:04:51 AM
Description,From -79.983 °C to 298.409 °C at 10.000°C/min
Gas Type,Nitrogen
Pan Type,Tzero Aluminum Hermetic
Source Files 1,C:\Users\yargerlab\Desktop\DSC Data\General\Sapphire_Heat_Capacity_11_30_22.tri
[Rev Cp Calibration]
Date Applied,11/30/2022 1:58:51 PM
Description,From -79.996 °C to 292.812 °C at 3.000°C/min
Gas Type,Nitrogen
Pan Type,Tzero Aluminum Hermetic
Source Files 1,C:\Users\yargerlab\Desktop\DSC Data\General\Sapphire_MDSC_Calibration_11_30_22.tri
[step]
Ramp 5.00 °C/min to 200.00 °C
Time,Temperature,Heat Flow (Normalized)
min,°C,W/g
0.00,-59.68,-0.056
0.03,-59.70,-0.053
0.07,-59.69,-0.044
0.11,-59.64,-0.038
0.14,-59.55,-0.026
0.18,-59.44,-0.009
0.21,-59.31,0.008
0.24,-59.17,0.023
0.28,-59.02,0.036
0.31,-58.87,0.046
0.35,-58.72,0.054
0.39,-58.56,0.061
0.42,-58.40,0.065
0.45,-58.24,0.069
0.49,-58.07,0.072
0.53,-57.90,0.074
0.56,-57.74,0.076
0.60,-57.57,0.077
0.63,-57.40,0.078
0.67,-57.23,0.079
0.70,-57.06,0.079
0.73,-56.89,0.080
0.77,-56.71,0.081
0.80,-56.54,0.081
0.84,-56.37,0.082
0.88,-56.20,0.082
0.91,-56.03,0.083
0.95,-55.86,0.083
0.98,-55.68,0.083
1.02,-55.51,0.084
1.05,-55.34,0.084
1.08,-55.16,0.084
1.12,-54.99,0.084
1.16,-54.81,0.085
1.19,-54.64,0.085
1.23,-54.47,0.085
1.26,-54.29,0.085
1.29,-54.12,0.085
1.33,-53.95,0.085
1.37,-53.77,0.085
1.40,-53.60,0.086
1.43,-53.42,0.086
1.47,-53.25,0.086
1.51,-53.08,0.086
1.54,-52.90,0.086
1.58,-52.73,0.086
1.61,-52.55,0.086
1.64,-52.38,0.086
1.68,-52.20,0.086
1.72,-52.03,0.086
1.75,-51.85,0.086
1.78,-51.68,0.086
1.82,-51.51,0.086
1.86,-51.33,0.086
1.89,-51.16,0.086
1.93,-50.98,0.086
1.96,-50.81,0.086
1.99,-50.63,0.086
2.03,-50.46,0.086
2.07,-50.28,0.086
2.10,-50.11,0.086
2.14,-49.93,0.086
2.17,-49.76,0.086
2.21,-49.58,0.086
2.24,-49.41,0.086
2.28,-49.23,0.086
2.31,-49.06,0.086
2.34,-48.89,0.086
2.38,-48.71,0.086
2.41,-48.54,0.086
2.45,-48.36,0.085
2.49,-48.18,0.086
2.52,-48.01,0.086
2.56,-47.84,0.086
2.59,-47.66,0.086
2.63,-47.48,0.086
2.66,-47.31,0.086
2.69,-47.14,0.085
2.73,-46.96,0.085
2.76,-46.79,0.085
2.80,-46.61,0.085
2.84,-46.44,0.085
2.87,-46.26,0.085
2.91,-46.09,0.085
2.94,-45.91,0.085
2.98,-45.74,0.086
3.01,-45.56,0.085
3.04,-45.39,0.086
3.08,-45.21,0.085
3.11,-45.04,0.085
3.15,-44.86,0.085
3.19,-44.69,0.085
3.22,-44.51,0.085
3.26,-44.34,0.085
3.29,-44.16,0.085
3.33,-43.99,0.085
3.36,-43.81,0.085
3.39,-43.64,0.085
3.43,-43.46,0.085
3.46,-43.29,0.085
3.50,-43.11,0.085
3.54,-42.94,0.085
3.57,-42.76,0.085
3.61,-42.59,0.085
3.64,-42.41,0.085
3.68,-42.24,0.085
3.71,-42.06,0.086
3.74,-41.89,0.085
3.78,-41.71,0.085
3.81,-41.54,0.085
3.85,-41.36,0.085
3.89,-41.19,0.085
3.92,-41.01,0.085
3.96,-40.84,0.085
3.99,-40.66,0.085
4.03,-40.49,0.085
4.06,-40.31,0.085
4.09,-40.14,0.085
4.13,-39.96,0.085
4.16,-39.79,0.085
4.20,-39.61,0.086
4.24,-39.44,0.086
4.27,-39.26,0.086
4.30,-39.09,0.086
4.34,-38.91,0.086
4.38,-38.74,0.086
4.41,-38.56,0.086
4.45,-38.38,0.086
4.48,-38.21,0.086
4.51,-38.04,0.086
4.55,-37.86,0.086
4.59,-37.69,0.086
4.62,-37.51,0.086
4.65,-37.33,0.086
4.69,-37.16,0.086
4.73,-36.98,0.086
4.76,-36.81,0.086
4.80,-36.63,0.086
4.83,-36.46,0.086
4.86,-36.28,0.086
4.90,-36.11,0.086
4.94,-35.93,0.086
4.97,-35.76,0.086
5.00,-35.58,0.086
5.04,-35.41,0.086
5.08,-35.23,0.086
5.11,-35.06,0.086
5.15,-34.88,0.086
5.18,-34.71,0.086
5.21,-34.53,0.086
5.25,-34.36,0.086
5.29,-34.18,0.086
5.32,-34.01,0.086
5.35,-33.83,0.086
5.39,-33.65,0.086
5.43,-33.48,0.086
5.46,-33.30,0.086
5.50,-33.13,0.086
5.53,-32.95,0.086
5.56,-32.78,0.086
5.60,-32.60,0.086
5.64,-32.43,0.086
5.67,-32.25,0.086
5.70,-32.08,0.086
5.74,-31.90,0.086
5.78,-31.73,0.086
5.81,-31.55,0.086
5.85,-31.38,0.086
5.88,-31.20,0.086
5.91,-31.03,0.086
5.95,-30.85,0.086
5.99,-30.68,0.086
6.02,-30.50,0.086
6.05,-30.33,0.086
6.09,-30.15,0.086
6.13,-29.98,0.086
6.16,-29.80,0.086
6.20,-29.63,0.086
6.23,-29.45,0.086
6.26,-29.28,0.086
6.30,-29.10,0.087
6.34,-28.93,0.087
6.37,-28.75,0.087
6.40,-28.57,0.087
6.44,-28.40,0.087
6.48,-28.22,0.087
6.51,-28.05,0.087
6.55,-27.87,0.087
6.58,-27.70,0.087
6.61,-27.52,0.087
6.65,-27.35,0.087
6.69,-27.17,0.087
6.72,-27.00,0.087
6.75,-26.82,0.087
6.79,-26.65,0.087
6.83,-26.47,0.087
6.86,-26.30,0.087
6.90,-26.12,0.087
6.93,-25.95,0.087
6.96,-25.77,0.087
7.00,-25.60,0.087
7.04,-25.42,0.087
7.07,-25.25,0.087
7.10,-25.07,0.087
7.14,-24.90,0.087
7.18,-24.72,0.087
7.21,-24.55,0.087
7.25,-24.37,0.087
7.28,-24.20,0.087
7.31,-24.02,0.087
7.35,-23.85,0.087
7.39,-23.67,0.087
7.42,-23.49,0.087
7.45,-23.32,0.087
7.49,-23.15,0.087
7.53,-22.97,0.087
7.56,-22.80,0.087
7.60,-22.62,0.087
7.63,-22.44,0.087
7.66,-22.27,0.087
7.70,-22.09,0.087
7.74,-21.92,0.087
7.77,-21.74,0.087
7.80,-21.57,0.087
7.84,-21.39,0.087
7.88,-21.22,0.087
7.91,-21.04,0.087
7.95,-20.87,0.087
7.98,-20.69,0.087
8.01,-20.52,0.087
8.05,-20.34,0.088
8.09,-20.17,0.088
8.12,-19.99,0.088
8.15,-19.82,0.088
8.19,-19.64,0.088
8.23,-19.47,0.088
8.26,-19.29,0.088
8.30,-19.12,0.088
8.33,-18.94,0.088
8.36,-18.77,0.088
8.40,-18.59,0.088
8.44,-18.42,0.088
8.47,-18.24,0.088
8.50,-18.06,0.088
8.54,-17.89,0.088
8.58,-17.72,0.088
8.61,-17.54,0.088
8.65,-17.36,0.088
8.68,-17.19,0.088
8.72,-17.02,0.088
8.75,-16.84,0.088
8.78,-16.66,0.088
8.82,-16.49,0.088
8.85,-16.31,0.088
8.89,-16.14,0.088
8.93,-15.96,0.088
8.96,-15.79,0.088
9.00,-15.61,0.088
9.03,-15.44,0.088
9.07,-15.26,0.088
9.10,-15.09,0.088
9.13,-14.91,0.088
9.17,-14.74,0.088
9.20,-14.56,0.088
9.24,-14.39,0.089
9.28,-14.21,0.089
9.31,-14.04,0.089
9.35,-13.86,0.089
9.38,-13.69,0.089
9.42,-13.51,0.089
9.45,-13.34,0.089
9.48,-13.16,0.089
9.52,-12.99,0.089
9.55,-12.81,0.089
9.59,-12.64,0.089
9.63,-12.46,0.089
9.66,-12.29,0.089
9.70,-12.11,0.089
9.73,-11.94,0.089
9.77,-11.76,0.089
9.80,-11.59,0.089
9.83,-11.41,0.089
9.87,-11.24,0.090
9.90,-11.06,0.090
9.94,-10.89,0.090
9.98,-10.71,0.090
10.01,-10.53,0.090
10.05,-10.36,0.090
10.08,-10.19,0.090
10.12,-10.01,0.090
10.15,-9.84,0.090
10.18,-9.66,0.090
10.22,-9.48,0.090
10.25,-9.31,0.090
10.29,-9.13,0.090
10.33,-8.96,0.091
10.36,-8.78,0.091
10.40,-8.61,0.091
10.43,-8.43,0.091
10.47,-8.26,0.091
10.50,-8.08,0.091
10.53,-7.91,0.091
10.57,-7.73,0.091
10.60,-7.56,0.091
10.64,-7.38,0.091
10.68,-7.21,0.092
10.71,-7.03,0.092
10.75,-6.86,0.092
10.78,-6.68,0.092
10.82,-6.51,0.092
10.85,-6.33,0.092
10.88,-6.16,0.092
10.92,-5.98,0.093
10.95,-5.81,0.093
10.99,-5.63,0.093
11.03,-5.46,0.093
11.06,-5.28,0.093
11.10,-5.11,0.093
11.13,-4.93,0.093
11.17,-4.76,0.094
11.20,-4.58,0.094
11.23,-4.41,0.094
11.27,-4.23,0.094
11.30,-4.06,0.094
11.34,-3.88,0.094
11.38,-3.71,0.095
11.41,-3.53,0.095
11.45,-3.36,0.095
11.48,-3.18,0.095
11.52,-3.01,0.095
11.55,-2.83,0.096
11.58,-2.66,0.096
11.62,-2.48,0.096
11.65,-2.31,0.096
11.69,-2.13,0.096
11.73,-1.96,0.096
11.76,-1.78,0.097
11.80,-1.60,0.097
11.83,-1.43,0.097
11.87,-1.26,0.097
11.90,-1.08,0.097
11.93,-0.91,0.097
11.97,-0.73,0.097
12.00,-0.56,0.097
12.04,-0.38,0.097
12.08,-0.20,0.098
12.11,-0.03,0.098
12.15,0.15,0.098
12.18,0.32,0.098
12.22,0.50,0.098
12.25,0.67,0.098
12.28,0.85,0.098
12.32,1.02,0.098
12.35,1.20,0.098
12.39,1.37,0.098
12.43,1.55,0.098
12.46,1.72,0.098
12.50,1.90,0.098
12.53,2.07,0.098
12.57,2.25,0.098
12.60,2.42,0.098
12.63,2.60,0.098
12.67,2.77,0.098
12.70,2.95,0.098
12.74,3.12,0.098
12.78,3.30,0.098
12.81,3.47,0.098
12.85,3.65,0.098
12.88,3.82,0.098
12.92,4.00,0.098
12.95,4.17,0.098
12.98,4.35,0.098
13.02,4.52,0.098
13.05,4.70,0.098
13.09,4.87,0.098
13.13,5.05,0.098
13.16,5.22,0.098
13.20,5.40,0.098
13.23,5.57,0.098
13.27,5.75,0.098
13.30,5.93,0.098
13.33,6.10,0.098
13.37,6.28,0.098
13.40,6.45,0.098
13.44,6.63,0.098
13.48,6.80,0.099
13.51,6.98,0.099
13.55,7.15,0.099
13.58,7.33,0.099
13.62,7.50,0.099
13.65,7.68,0.099
13.68,7.85,0.099
13.72,8.03,0.099
13.75,8.20,0.099
13.79,8.38,0.099
13.83,8.55,0.099
13.86,8.73,0.099
13.90,8.90,0.099
13.93,9.08,0.099
13.97,9.25,0.099
14.00,9.43,0.099
14.03,9.60,0.099
14.07,9.78,0.099
14.10,9.95,0.099
14.14,10.13,0.099
14.18,10.30,0.099
14.21,10.48,0.099
14.25,10.65,0.099
14.28,10.83,0.099
14.32,11.00,0.100
14.35,11.18,0.100
14.38,11.35,0.100
14.42,11.53,0.100
14.45,11.70,0.100
14.49,11.88,0.100
14.53,12.05,0.100
14.56,12.23,0.100
14.60,12.40,0.100
14.63,12.58,0.100
14.67,12.76,0.100
14.70,12.93,0.100
14.73,13.11,0.100
14.77,13.28,0.100
14.80,13.46,0.100
14.84,13.63,0.100
14.88,13.81,0.100
14.91,13.98,0.100
14.95,14.16,0.100
14.98,14.33,0.100
15.02,14.51,0.101
15.05,14.68,0.101
15.08,14.86,0.101
15.12,15.03,0.101
15.15,15.21,0.101
15.19,15.38,0.101
15.23,15.56,0.101
15.26,15.73,0.101
15.30,15.91,0.101
15.33,16.08,0.101
15.37,16.26,0.101
15.40,16.43,0.101
15.43,16.61,0.101
15.47,16.78,0.101
15.50,16.96,0.101
15.54,17.13,0.101
15.58,17.31,0.101
15.61,17.48,0.101
15.65,17.66,0.101
15.68,17.83,0.101
15.72,18.01,0.101
15.75,18.18,0.101
15.78,18.36,0.101
15.82,18.53,0.101
15.85,18.71,0.102
15.89,18.89,0.102
15.93,19.06,0.102
15.96,19.24,0.102
16.00,19.41,0.102
16.03,19.59,0.102
16.07,19.76,0.102
16.10,19.94,0.102
16.13,20.11,0.102
16.17,20.29,0.102
16.20,20.46,0.102
16.24,20.63,0.102
16.28,20.81,0.102
16.31,20.99,0.102
16.35,21.16,0.102
16.38,21.34,0.102
16.42,21.51,0.102
16.45,21.69,0.102
16.48,21.86,0.102
16.52,22.04,0.102
16.55,22.21,0.102
16.59,22.39,0.102
16.63,22.56,0.102
16.66,22.74,0.102
16.70,22.91,0.102
16.73,23.09,0.103
16.77,23.26,0.103
16.80,23.44,0.103
16.83,23.61,0.103
16.87,23.79,0.103
16.90,23.96,0.103
16.94,24.14,0.103
16.98,24.31,0.103
17.01,24.49,0.103
17.05,24.66,0.103
17.08,24.84,0.103
17.12,25.01,0.103
17.15,25.19,0.103
17.18,25.36,0.103
17.22,25.54,0.103
17.26,25.71,0.103
17.29,25.89,0.103
17.33,26.06,0.104
17.36,26.24,0.104
17.39,26.41,0.104
17.43,26.59,0.104
17.47,26.77,0.104
17.50,26.94,0.104
17.53,27.11,0.104
17.57,27.29,0.104
17.61,27.46,0.104
17.64,27.64,0.104
17.68,27.82,0.104
17.71,27.99,0.104
17.74,28.17,0.104
17.78,28.34,0.104
17.82,28.51,0.104
17.85,28.69,0.104
17.88,28.87,0.104
17.92,29.04,0.104
17.96,29.22,0.104
17.99,29.39,0.104
18.03,29.57,0.105
18.06,29.74,0.105
18.09,29.92,0.105
18.13,30.09,0.105
18.17,30.27,0.105
18.20,30.44,0.105
18.23,30.62,0.105
18.27,30.79,0.105
18.31,30.97,0.105
18.34,31.14,0.105
18.38,31.32,0.105
18.41,31.49,0.105
18.44,31.67,0.105
18.48,31.84,0.105
18.52,32.02,0.105
18.55,32.20,0.105
18.58,32.37,0.105
18.62,32.54,0.105
18.66,32.72,0.105
18.69,32.89,0.105
18.73,33.07,0.105
18.76,33.24,0.105
18.79,33.42,0.105
18.83,33.59,0.106
18.87,33.77,0.106
18.90,33.94,0.106
18.93,34.12,0.106
18.97,34.29,0.106
19.01,34.47,0.106
19.04,34.64,0.106
19.08,34.82,0.106
19.11,35.00,0.106
19.14,35.17,0.106
19.18,35.35,0.106
19.22,35.52,0.106
19.25,35.70,0.106
19.28,35.87,0.106
19.32,36.05,0.106
19.36,36.22,0.106
19.39,36.40,0.106
19.43,36.57,0.106
19.46,36.75,0.106
19.49,36.92,0.106
19.53,37.10,0.106
19.57,37.27,0.106
19.60,37.45,0.106
19.63,37.62,0.107
19.67,37.80,0.107
19.71,37.97,0.107
19.74,38.15,0.107
19.78,38.32,0.107
19.81,38.50,0.107
19.84,38.67,0.107
19.88,38.85,0.107
19.92,39.02,0.107
19.95,39.20,0.107
19.98,39.37,0.107
20.02,39.55,0.107
20.06,39.72,0.107
20.09,39.90,0.107
20.13,40.07,0.107
20.16,40.25,0.107
20.19,40.42,0.107
20.23,40.60,0.107
20.27,40.77,0.107
20.30,40.95,0.107
20.33,41.12,0.107
20.37,41.30,0.107
20.41,41.47,0.107
20.44,41.65,0.108
20.48,41.82,0.108
20.51,42.00,0.108
20.54,42.17,0.108
20.58,42.35,0.108
20.62,42.52,0.108
20.65,42.70,0.108
20.68,42.87,0.108
20.72,43.05,0.108
20.76,43.23,0.108
20.79,43.40,0.108
20.83,43.57,0.108
20.86,43.75,0.108
20.89,43.93,0.108
20.93,44.10,0.108
20.97,44.28,0.108
21.00,44.45,0.108
21.03,44.63,0.108
21.07,44.80,0.108
21.11,44.98,0.108
21.14,45.15,0.108
21.18,45.33,0.108
21.21,45.50,0.109
21.24,45.68,0.109
21.28,45.85,0.109
21.32,46.03,0.109
21.35,46.20,0.109
21.38,46.38,0.109
21.42,46.55,0.109
21.46,46.73,0.109
21.49,46.90,0.109
21.53,47.08,0.109
21.56,47.25,0.109
21.59,47.43,0.109
21.63,47.60,0.109
21.67,47.78,0.109
21.70,47.95,0.109
21.73,48.13,0.109
21.77,48.30,0.110
21.81,48.48,0.110
21.84,48.65,0.110
21.88,48.83,0.110
21.91,49.00,0.110
21.94,49.18,0.110
21.98,49.35,0.110
22.02,49.53,0.110
22.05,49.70,0.110
22.08,49.88,0.110
22.12,50.05,0.110
22.16,50.23,0.110
22.19,50.40,0.110
22.23,50.58,0.110
22.26,50.75,0.110
22.29,50.93,0.110
22.33,51.11,0.110
22.37,51.28,0.110
22.40,51.46,0.110
22.43,51.63,0.110
22.47,51.81,0.111
22.51,51.98,0.111
22.54,52.16,0.111
22.58,52.33,0.111
22.61,52.51,0.111
22.64,52.68,0.111
22.68,52.86,0.111
22.72,53.03,0.111
22.75,53.20,0.111
22.78,53.38,0.111
22.82,53.56,0.111
22.86,53.73,0.111
22.89,53.90,0.111
22.93,54.08,0.111
22.96,54.26,0.111
22.99,54.43,0.111
23.03,54.61,0.111
23.07,54.78,0.111
23.10,54.96,0.111
23.13,55.13,0.111
23.17,55.31,0.111
23.21,55.48,0.112
23.24,55.66,0.112
23.28,55.83,0.112
23.31,56.01,0.112
23.34,56.18,0.112
23.38,56.36,0.112
23.42,56.53,0.112
23.45,56.71,0.112
23.48,56.88,0.112
23.52,57.06,0.112
23.56,57.23,0.112
23.59,57.41,0.112
23.63,57.58,0.112
23.66,57.76,0.112
23.69,57.93,0.112
23.73,58.11,0.112
23.77,58.28,0.112
23.80,58.46,0.112
23.83,58.63,0.112
23.87,58.81,0.112
23.91,58.98,0.112
23.94,59.16,0.112
23.98,59.33,0.112
24.01,59.51,0.112
24.04,59.68,0.112
24.08,59.86,0.112
24.12,60.03,0.112
24.15,60.21,0.112
24.18,60.39,0.112
24.22,60.56,0.113
24.26,60.74,0.113
24.29,60.91,0.113
24.33,61.09,0.113
24.36,61.26,0.113
24.39,61.44,0.113
24.43,61.61,0.113
24.47,61.79,0.113
24.50,61.96,0.113
24.53,62.14,0.113
24.57,62.31,0.113
24.61,62.49,0.113
24.64,62.66,0.113
24.68,62.84,0.113
24.71,63.01,0.113
24.74,63.19,0.113
24.78,63.36,0.113
24.82,63.54,0.113
24.85,63.71,0.113
24.88,63.89,0.113
24.92,64.06,0.113
24.96,64.24,0.113
24.99,64.41,0.113
25.03,64.59,0.114
25.06,64.76,0.114
25.09,64.94,0.114
25.13,65.11,0.114
25.17,65.29,0.114
25.20,65.46,0.114
25.23,65.64,0.114
25.27,65.82,0.114
25.31,65.99,0.114
25.34,66.17,0.114
25.38,66.34,0.114
25.41,66.52,0.114
25.44,66.69,0.114
25.48,66.87,0.114
25.52,67.04,0.114
25.55,67.22,0.114
25.58,67.39,0.114
25.62,67.57,0.114
25.66,67.74,0.114
25.69,67.92,0.114
25.73,68.09,0.114
25.76,68.27,0.114
25.79,68.44,0.114
25.83,68.62,0.114
25.87,68.79,0.114
25.90,68.97,0.114
25.93,69.14,0.114
25.97,69.32,0.114
26.01,69.49,0.115
26.04,69.67,0.115
26.08,69.84,0.115
26.11,70.02,0.115
26.14,70.19,0.115
26.18,70.37,0.115
26.22,70.54,0.115
26.25,70.72,0.115
26.28,70.89,0.115
26.32,71.07,0.115
26.36,71.24,0.115
26.39,71.42,0.115
26.43,71.59,0.115
26.46,71.77,0.115
26.49,71.95,0.115
26.53,72.12,0.115
26.57,72.30,0.115
26.60,72.47,0.115
26.63,72.64,0.115
26.67,72.82,0.115
26.71,72.99,0.115
26.74,73.17,0.115
26.78,73.34,0.115
26.81,73.52,0.116
26.84,73.69,0.116
26.88,73.87,0.116
26.92,74.04,0.115
26.95,74.22,0.116
26.98,74.39,0.116
27.02,74.57,0.116
27.06,74.74,0.116
27.09,74.92,0.116
27.13,75.09,0.116
27.16,75.27,0.116
27.19,75.44,0.116
27.23,75.62,0.116
27.27,75.79,0.116
27.30,75.97,0.116
27.33,76.14,0.116
27.37,76.32,0.116
27.41,76.49,0.116
27.44,76.67,0.116
27.48,76.84,0.116
27.51,77.02,0.116
27.54,77.19,0.116
27.58,77.37,0.116
27.62,77.54,0.116
27.65,77.72,0.116
27.68,77.90,0.117
27.72,78.07,0.117
27.76,78.25,0.117
27.79,78.42,0.117
27.83,78.60,0.117
27.86,78.77,0.117
27.89,78.95,0.117
27.93,79.12,0.117
27.97,79.30,0.117
28.00,79.47,0.117
28.03,79.65,0.117
28.07,79.82,0.117
28.11,80.00,0.117
28.14,80.17,0.117
28.18,80.35,0.117
28.21,80.52,0.117
28.24,80.70,0.117
28.28,80.87,0.117
28.32,81.05,0.117
28.35,81.22,0.117
28.38,81.40,0.117
28.42,81.57,0.117
28.46,81.75,0.117
28.49,81.92,0.117
28.53,82.10,0.117
28.56,82.27,0.117
28.59,82.45,0.117
28.63,82.62,0.117
28.67,82.80,0.117
28.70,82.97,0.117
28.73,83.15,0.117
28.77,83.32,0.117
28.81,83.50,0.117
28.84,83.67,0.117
28.88,83.85,0.117
28.91,84.02,0.117
28.94,84.20,0.117
28.98,84.37,0.117
29.02,84.55,0.117
29.05,84.73,0.117
29.08,84.90,0.117
29.12,85.08,0.117
29.16,85.25,0.117
29.19,85.43,0.118
29.23,85.60,0.118
29.26,85.77,0.118
29.29,85.95,0.118
29.33,86.13,0.118
29.37,86.30,0.118
29.40,86.48,0.118
29.43,86.65,0.118
29.47,86.83,0.118
29.51,87.00,0.118
29.54,87.18,0.118
29.58,87.35,0.118
29.61,87.53,0.118
29.64,87.70,0.118
29.68,87.88,0.118
29.72,88.05,0.118
29.75,88.23,0.118
29.78,88.40,0.118
29.82,88.58,0.118
29.86,88.75,0.118
29.89,88.92,0.118
29.93,89.10,0.118
29.96,89.28,0.118
29.99,89.45,0.118
30.03,89.63,0.118
30.07,89.80,0.118
30.10,89.98,0.118
30.13,90.15,0.118
30.17,90.33,0.118
30.21,90.50,0.118
30.24,90.68,0.118
30.28,90.85,0.119
30.31,91.03,0.118
30.34,91.20,0.118
30.38,91.38,0.118
30.42,91.55,0.119
30.45,91.73,0.119
30.48,91.90,0.119
30.52,92.08,0.119
30.56,92.25,0.119
30.59,92.43,0.119
30.63,92.60,0.119
30.66,92.78,0.119
30.69,92.95,0.119
30.73,93.13,0.119
30.77,93.30,0.119
30.80,93.48,0.119
30.83,93.65,0.119
30.87,93.83,0.119
30.91,94.01,0.119
30.94,94.18,0.119
30.98,94.35,0.119
31.01,94.53,0.119
31.04,94.70,0.119
31.08,94.88,0.119
31.12,95.05,0.119
31.15,95.23,0.119
31.18,95.40,0.119
31.22,95.58,0.119
31.26,95.75,0.119
31.29,95.93,0.119
31.33,96.10,0.119
31.36,96.28,0.119
31.39,96.45,0.119
31.43,96.63,0.119
31.47,96.80,0.119
31.50,96.98,0.119
31.53,97.15,0.119
31.57,97.33,0.120
31.61,97.50,0.120
31.64,97.68,0.120
31.68,97.85,0.120
31.71,98.03,0.120
31.74,98.20,0.120
31.78,98.38,0.120
31.82,98.56,0.120
31.85,98.73,0.120
31.88,98.91,0.120
31.92,99.08,0.120
31.96,99.26,0.120
31.99,99.43,0.120
32.03,99.61,0.120
32.06,99.78,0.120
32.09,99.96,0.120
32.13,100.13,0.120
32.17,100.31,0.120
32.20,100.48,0.120
32.23,100.66,0.120
32.27,100.83,0.120
32.31,101.01,0.120
32.34,101.18,0.120
32.38,101.36,0.120
32.41,101.53,0.120
32.44,101.71,0.120
32.48,101.88,0.120
32.52,102.06,0.120
32.55,102.23,0.120
32.58,102.41,0.120
32.62,102.58,0.120
32.66,102.76,0.120
32.69,102.94,0.120
32.73,103.11,0.121
32.76,103.28,0.121
32.79,103.46,0.121
32.83,103.63,0.121
32.87,103.81,0.121
32.90,103.98,0.121
32.93,104.16,0.121
32.97,104.33,0.121
33.01,104.51,0.121
33.04,104.68,0.121
33.08,104.86,0.121
33.11,105.04,0.121
33.14,105.21,0.121
33.18,105.39,0.121
33.22,105.56,0.121
33.25,105.74,0.121
33.28,105.92,0.121
33.32,106.09,0.121
33.36,106.26,0.121
33.39,106.44,0.121
33.43,106.61,0.121
33.46,106.79,0.120
33.49,106.96,0.120
33.53,107.14,0.120
33.57,107.31,0.120
33.60,107.49,0.120
33.63,107.66,0.120
33.67,107.84,0.120
33.71,108.01,0.120
33.74,108.19,0.120
33.78,108.36,0.120
33.81,108.54,0.120
33.84,108.71,0.120
33.88,108.89,0.120
33.92,109.06,0.120
33.95,109.24,0.120
33.98,109.41,0.120
34.02,109.59,0.120
34.06,109.76,0.120
34.09,109.94,0.120
34.13,110.11,0.120
34.16,110.29,0.120
34.19,110.46,0.120
34.23,110.64,0.120
34.26,110.81,0.120
34.30,110.99,0.120
34.34,111.16,0.120
34.37,111.34,0.120
34.41,111.51,0.120
34.44,111.69,0.120
34.48,111.86,0.120
34.51,112.04,0.120
34.54,112.21,0.120
34.58,112.39,0.120
34.61,112.56,0.120
34.65,112.74,0.120
34.69,112.91,0.120
34.72,113.09,0.120
34.76,113.26,0.120
34.79,113.44,0.120
34.83,113.61,0.120
34.86,113.79,0.120
34.89,113.97,0.120
34.93,114.14,0.120
34.96,114.32,0.120
35.00,114.49,0.120
35.04,114.66,0.120
35.07,114.84,0.119
35.11,115.02,0.119
35.14,115.19,0.119
35.18,115.37,0.119
35.21,115.54,0.119
35.24,115.72,0.119
35.28,115.89,0.119
35.31,116.07,0.119
35.35,116.24,0.119
35.39,116.42,0.119
35.42,116.59,0.119
35.46,116.77,0.119
35.49,116.94,0.119
35.53,117.12,0.119
35.56,117.29,0.119
35.59,117.47,0.119
35.63,117.64,0.119
35.66,117.82,0.119
35.70,117.99,0.119
35.74,118.17,0.119
35.77,118.34,0.119
35.81,118.52,0.119
35.84,118.69,0.119
35.88,118.87,0.119
35.91,119.04,0.119
35.94,119.22,0.119
35.98,119.39,0.119
36.01,119.57,0.119
36.05,119.74,0.118
36.09,119.92,0.118
36.12,120.09,0.118
36.16,120.27,0.118
36.19,120.44,0.118
36.23,120.62,0.118
36.26,120.79,0.118
36.29,120.97,0.118
36.33,121.14,0.118
36.36,121.32,0.118
36.40,121.49,0.118
36.44,121.67,0.118
36.47,121.84,0.118
36.51,122.02,0.118
36.54,122.19,0.118
36.58,122.37,0.118
36.61,122.54,0.118
36.64,122.72,0.118
36.68,122.89,0.118
36.71,123.07,0.118
36.75,123.24,0.118
36.79,123.42,0.118
36.82,123.59,0.118
36.86,123.77,0.118
36.89,123.94,0.118
36.93,124.12,0.118
36.96,124.29,0.118
36.99,124.47,0.117
37.03,124.65,0.117
37.06,124.82,0.117
37.10,124.99,0.117
37.14,125.17,0.117
37.17,125.35,0.117
37.21,125.52,0.117
37.24,125.70,0.117
37.28,125.87,0.117
37.31,126.05,0.117
37.34,126.22,0.117
37.38,126.40,0.117
37.41,126.57,0.117
37.45,126.75,0.117
37.49,126.92,0.117
37.52,127.09,0.116
37.56,127.27,0.116
37.59,127.45,0.116
37.63,127.62,0.116
37.66,127.80,0.116
37.69,127.97,0.116
37.73,128.15,0.116
37.76,128.32,0.116
37.80,128.50,0.116
37.84,128.67,0.116
37.87,128.85,0.116
37.91,129.02,0.116
37.94,129.20,0.116
37.98,129.38,0.116
38.01,129.55,0.116
38.04,129.72,0.116
38.08,129.90,0.116
38.11,130.07,0.116
38.15,130.25,0.116
38.19,130.42,0.115
38.22,130.60,0.115
38.26,130.77,0.115
38.29,130.95,0.115
38.33,131.12,0.115
38.36,131.30,0.115
38.39,131.47,0.115
38.43,131.65,0.115
38.46,131.82,0.115
38.50,132.00,0.115
38.54,132.17,0.114
38.57,132.35,0.114
38.61,132.52,0.114
38.64,132.70,0.114
38.68,132.87,0.114
38.71,133.05,0.114
38.74,133.23,0.114
38.78,133.40,0.114
38.81,133.58,0.114
38.85,133.75,0.114
38.89,133.93,0.114
38.92,134.10,0.114
38.96,134.27,0.114
38.99,134.45,0.113
39.03,134.62,0.113
39.06,134.80,0.113
39.09,134.98,0.113
39.13,135.15,0.113
39.16,135.32,0.113
39.20,135.50,0.113
39.24,135.68,0.113
39.27,135.85,0.113
39.31,136.03,0.113
39.34,136.20,0.113
39.38,136.38,0.113
39.41,136.55,0.113
39.44,136.73,0.113
39.48,136.90,0.112
39.51,137.08,0.112
39.55,137.25,0.112
39.59,137.43,0.112
39.62,137.60,0.112
39.66,137.78,0.112
39.69,137.95,0.112
39.73,138.13,0.112
39.76,138.30,0.111
39.79,138.48,0.111
39.83,138.65,0.111
39.86,138.83,0.111
39.90,139.00,0.111
39.94,139.18,0.111
39.97,139.35,0.111
40.01,139.53,0.111
40.04,139.70,0.111
40.08,139.88,0.111
40.11,140.05,0.111
40.14,140.23,0.111
40.18,140.40,0.111
40.21,140.58,0.110
40.25,140.75,0.110
40.29,140.93,0.110
40.32,141.10,0.110
40.36,141.28,0.110
40.39,141.45,0.110
40.43,141.63,0.110
40.46,141.81,0.110
40.49,141.98,0.110
40.53,142.16,0.110
40.56,142.33,0.110
40.60,142.50,0.110
40.64,142.68,0.110
40.67,142.86,0.110
40.71,143.03,0.109
40.74,143.21,0.109
40.78,143.38,0.109
40.81,143.55,0.109
40.84,143.73,0.109
40.88,143.90,0.109
40.91,144.08,0.109
40.95,144.26,0.109
40.99,144.43,0.109
41.02,144.61,0.109
41.06,144.78,0.109
41.09,144.96,0.109
41.13,145.13,0.109
41.16,145.30,0.109
41.19,145.48,0.108
41.23,145.66,0.108
41.26,145.83,0.108
41.30,146.01,0.108
41.34,146.18,0.108
41.37,146.36,0.108
41.41,146.53,0.108
41.44,146.71,0.108
41.48,146.88,0.108
41.51,147.06,0.108
41.54,147.23,0.108
41.58,147.41,0.108
41.61,147.58,0.108
41.65,147.76,0.108
41.69,147.93,0.108
41.72,148.11,0.108
41.76,148.28,0.108
41.79,148.46,0.108
41.83,148.63,0.107
41.86,148.81,0.107
41.89,148.98,0.107
41.93,149.16,0.107
41.96,149.33,0.107
42.00,149.51,0.107
42.04,149.68,0.107
42.07,149.86,0.107
42.11,150.03,0.107
42.14,150.21,0.107
42.18,150.38,0.107
42.21,150.56,0.107
42.24,150.73,0.107
42.28,150.91,0.107
42.31,151.08,0.107
42.35,151.26,0.107
42.39,151.43,0.107
42.42,151.61,0.107
42.46,151.78,0.107
42.49,151.96,0.107
42.53,152.13,0.107
42.56,152.31,0.107
42.59,152.48,0.107
42.63,152.66,0.107
42.66,152.84,0.107
42.70,153.01,0.107
42.74,153.18,0.107
42.77,153.36,0.107
42.81,153.53,0.107
42.84,153.71,0.107
42.88,153.88,0.107
42.91,154.06,0.106
42.94,154.23,0.106
42.98,154.41,0.106
43.01,154.59,0.106
43.05,154.76,0.106
43.09,154.94,0.106
43.12,155.11,0.106
43.16,155.29,0.106
43.19,155.46,0.107
43.23,155.64,0.107
43.26,155.81,0.107
43.29,155.99,0.107
43.33,156.16,0.106
43.36,156.34,0.106
43.40,156.51,0.106
43.44,156.68,0.106
43.47,156.86,0.106
43.51,157.03,0.106
43.54,157.21,0.106
43.58,157.39,0.106
43.61,157.56,0.106
43.64,157.74,0.107
43.68,157.91,0.107
43.71,158.09,0.107
43.75,158.26,0.107
43.79,158.44,0.107
43.82,158.61,0.107
43.86,158.79,0.107
43.89,158.96,0.107
43.93,159.14,0.107
43.96,159.31,0.107
43.99,159.49,0.107
44.03,159.66,0.107
44.06,159.84,0.107
44.10,160.01,0.107
44.14,160.19,0.107
44.17,160.36,0.107
44.21,160.53,0.107
44.24,160.71,0.107
44.28,160.88,0.107
44.31,161.06,0.107
44.34,161.24,0.107
44.38,161.41,0.107
44.41,161.59,0.107
44.45,161.76,0.107
44.49,161.94,0.107
44.52,162.11,0.108
44.56,162.28,0.108
44.59,162.46,0.108
44.63,162.63,0.108
44.66,162.81,0.108
44.69,162.99,0.108
44.73,163.16,0.108
44.76,163.34,0.108
44.80,163.51,0.108
44.84,163.69,0.108
44.87,163.86,0.108
44.91,164.04,0.109
44.94,164.21,0.109
44.98,164.39,0.109
45.01,164.56,0.109
45.04,164.74,0.109
45.08,164.91,0.109
45.11,165.09,0.109
45.15,165.26,0.109
45.19,165.44,0.109
45.22,165.61,0.109
45.26,165.79,0.110
45.29,165.96,0.110
45.33,166.14,0.110
45.36,166.31,0.110
45.39,166.49,0.110
45.43,166.66,0.110
45.46,166.84,0.110
45.50,167.01,0.111
45.54,167.19,0.111
45.57,167.36,0.111
45.61,167.54,0.111
45.64,167.71,0.111
45.68,167.89,0.111
45.71,168.06,0.111
45.74,168.24,0.112
45.78,168.41,0.112
45.81,168.59,0.112
45.85,168.76,0.112
45.89,168.94,0.112
45.92,169.11,0.113
45.96,169.29,0.113
45.99,169.46,0.113
46.03,169.64,0.113
46.06,169.81,0.113
46.09,169.98,0.114
46.13,170.16,0.114
46.16,170.34,0.114
46.20,170.51,0.114
46.24,170.69,0.115
46.27,170.86,0.115
46.31,171.03,0.115
46.34,171.21,0.115
46.38,171.38,0.116
46.41,171.56,0.116
46.44,171.74,0.116
46.48,171.91,0.117
46.51,172.09,0.117
46.55,172.26,0.117
46.59,172.44,0.118
46.62,172.61,0.118
46.66,172.79,0.118
46.69,172.96,0.119
46.73,173.14,0.119
46.76,173.31,0.119
46.79,173.48,0.119
46.83,173.66,0.120
46.86,173.83,0.120
46.90,174.01,0.121
46.94,174.18,0.121
46.97,174.36,0.121
47.01,174.53,0.122
47.04,174.71,0.122
47.08,174.88,0.122
47.11,175.06,0.123
47.14,175.23,0.123
47.18,175.41,0.124
47.21,175.58,0.124
47.25,175.76,0.124
47.29,175.93,0.125
47.32,176.11,0.125
47.36,176.28,0.126
47.39,176.46,0.126
47.43,176.63,0.126
47.46,176.81,0.127
47.49,176.98,0.127
47.53,177.16,0.128
47.56,177.33,0.128
47.60,177.51,0.129
47.64,177.68,0.129
47.67,177.86,0.130
47.71,178.03,0.130
47.74,178.21,0.131
47.78,178.38,0.131
47.81,178.56,0.132
47.84,178.73,0.132
47.88,178.91,0.133
47.91,179.08,0.133
47.95,179.26,0.134
47.99,179.43,0.134
48.02,179.61,0.135
48.06,179.78,0.135
48.09,179.95,0.136
48.13,180.13,0.136
48.16,180.31,0.136
48.19,180.48,0.137
48.23,180.66,0.138
48.26,180.83,0.138
48.30,181.01,0.139
48.34,181.18,0.139
48.37,181.35,0.140
48.41,181.53,0.140
48.44,181.70,0.141
48.48,181.88,0.141
48.51,182.05,0.141
48.54,182.23,0.142
48.58,182.40,0.143
48.61,182.58,0.143
48.65,182.75,0.143
48.69,182.93,0.144
48.72,183.10,0.144
48.76,183.28,0.144
48.79,183.45,0.145
48.83,183.63,0.145
48.86,183.80,0.145
48.89,183.98,0.146
48.93,184.15,0.146
48.96,184.33,0.147
49.00,184.50,0.147
49.04,184.68,0.147
49.07,184.85,0.147
49.11,185.03,0.148
49.14,185.20,0.148
49.18,185.38,0.148
49.21,185.55,0.148
49.24,185.73,0.149
49.28,185.90,0.149
49.31,186.08,0.149
49.35,186.25,0.150
49.39,186.43,0.150
49.42,186.60,0.150
49.46,186.78,0.151
49.49,186.95,0.151
49.53,187.13,0.151
49.56,187.30,0.152
49.59,187.48,0.152
49.63,187.65,0.152
49.66,187.83,0.153
49.70,188.00,0.153
49.74,188.18,0.153
49.77,188.35,0.154
49.81,188.53,0.154
49.84,188.70,0.155
49.88,188.88,0.155
49.91,189.05,0.156
49.94,189.23,0.156
49.98,189.40,0.157
50.01,189.58,0.157
50.05,189.75,0.158
50.09,189.93,0.159
50.12,190.10,0.159
50.16,190.27,0.160
50.19,190.45,0.161
50.23,190.62,0.162
50.26,190.80,0.163
50.29,190.97,0.163
50.33,191.15,0.165
50.36,191.32,0.166
50.40,191.50,0.167
50.44,191.67,0.168
50.47,191.85,0.169
50.51,192.02,0.171
50.54,192.20,0.173
50.58,192.37,0.174
50.61,192.54,0.175
50.64,192.72,0.177
50.68,192.89,0.180
50.71,193.07,0.182
50.75,193.24,0.184
50.79,193.42,0.187
50.82,193.59,0.190
50.86,193.76,0.193
50.89,193.94,0.197
50.93,194.11,0.201
50.96,194.29,0.204
50.99,194.46,0.208
51.03,194.63,0.212
51.06,194.81,0.217
51.10,194.98,0.222
51.14,195.15,0.228
51.17,195.33,0.233
51.21,195.50,0.239
51.24,195.67,0.244
51.28,195.85,0.252
51.31,196.02,0.259
51.34,196.19,0.269
51.38,196.37,0.277
51.41,196.54,0.287
51.45,196.71,0.298
51.49,196.88,0.310
51.52,197.05,0.324
51.56,197.22,0.337
51.59,197.39,0.353
51.63,197.56,0.371
51.66,197.73,0.391
51.69,197.90,0.412
51.73,198.07,0.437
51.76,198.24,0.464
51.80,198.40,0.494
51.84,198.57,0.525
51.87,198.73,0.561
51.91,198.90,0.601
51.94,199.06,
51.98,199.22,
51.99,,

[step]
Ramp 5.00 °C/min to -60.00 °C
Time,Temperature,Heat Flow (Normalized)
min,°C,W/g
52.99,197.86,7.523
53.02,197.44,8.842
53.06,197.19,9.237
53.09,196.99,9.623
53.13,196.80,9.677
53.16,196.69,9.147
53.20,196.71,7.814
53.23,196.90,5.874
53.27,197.20,4.284
53.30,197.45,3.248
53.34,197.65,2.429
53.37,197.78,1.837
53.41,197.85,1.387
53.44,197.87,1.027
53.48,197.86,0.749
53.51,197.81,0.541
53.55,197.73,0.372
53.58,197.63,0.251
53.62,197.52,0.148
53.65,197.39,0.072
53.69,197.25,0.008
53.72,197.11,-0.038
53.76,196.96,-0.081
53.79,196.80,-0.113
53.83,196.64,-0.139
53.86,196.48,-0.162
53.90,196.32,-0.179
53.93,196.15,-0.194
53.97,195.99,-0.207
54.00,195.82,-0.216
54.04,195.65,-0.227
54.07,195.48,-0.238
54.11,195.31,-0.244
54.14,195.14,-0.249
54.18,194.96,-0.252
54.21,194.79,-0.255
54.25,194.62,-0.260
54.28,194.45,-0.264
54.32,194.27,-0.267
54.35,194.10,-0.270
54.39,193.93,-0.273
54.42,193.75,-0.274
54.46,193.58,-0.276
54.49,193.41,-0.276
54.53,193.23,-0.278
54.56,193.06,-0.280
54.60,192.88,-0.281
54.63,192.71,-0.282
54.67,192.54,-0.283
54.70,192.36,-0.284
54.74,192.19,-0.284
54.77,192.01,-0.285
54.81,191.84,-0.286
54.84,191.66,-0.288
54.88,191.49,-0.289
54.91,191.32,-0.289
54.95,191.14,-0.290
54.98,190.97,-0.290
55.02,190.79,-0.290
55.05,190.62,-0.292
55.09,190.44,-0.292
55.12,190.27,-0.292
55.16,190.09,-0.292
55.19,189.92,-0.293
55.23,189.74,-0.293
55.26,189.57,-0.294
55.30,189.39,-0.294
55.33,189.22,-0.294
55.37,189.04,-0.294
55.40,188.87,-0.294
55.44,188.69,-0.295
55.47,188.52,-0.295
55.51,188.34,-0.295
55.54,188.17,-0.295
55.58,188.00,-0.295
55.61,187.82,-0.295
55.65,187.65,-0.295
55.68,187.47,-0.294
55.72,187.30,-0.295
55.75,187.12,-0.295
55.79,186.95,-0.295
55.82,186.77,-0.295
55.86,186.60,-0.295
55.89,186.42,-0.295
55.93,186.25,-0.295
55.96,186.07,-0.295
56.00,185.90,-0.295
56.03,185.72,-0.295
56.07,185.55,-0.295
56.10,185.37,-0.295
56.14,185.20,-0.294
56.17,185.02,-0.294
56.21,184.85,-0.294
56.24,184.67,-0.294
56.28,184.50,-0.294
56.31,184.32,-0.294
56.35,184.15,-0.294
56.38,183.97,-0.294
56.42,183.80,-0.294
56.45,183.62,-0.294
56.49,183.45,-0.294
56.52,183.27,-0.294
56.56,183.10,-0.293
56.59,182.92,-0.293
56.63,182.75,-0.292
56.66,182.57,-0.292
56.70,182.40,-0.293
56.73,182.22,-0.293
56.77,182.05,-0.293
56.80,181.88,-0.292
56.84,181.70,-0.292
56.87,181.53,-0.292
56.91,181.35,-0.292
56.94,181.18,-0.292
56.98,181.00,-0.291
57.01,180.83,-0.291
57.05,180.65,-0.291
57.08,180.48,-0.291
57.12,180.30,-0.291
57.15,180.13,-0.290
57.19,179.95,-0.290
57.22,179.78,-0.291
57.26,179.60,-0.290
57.29,179.42,-0.290
57.33,179.25,-0.290
57.36,179.07,-0.290
57.40,178.90,-0.290
57.43,178.72,-0.290
57.47,178.55,-0.289
57.50,178.37,-0.289
57.54,178.20,-0.288
57.57,178.02,-0.288
57.61,177.85,-0.288
57.64,177.68,-0.287
57.68,177.50,-0.287
57.71,177.33,-0.287
57.75,177.15,-0.286
57.78,176.98,-0.286
57.82,176.80,-0.286
57.85,176.63,-0.285
57.89,176.45,-0.285
57.92,176.28,-0.285
57.96,176.10,-0.284
57.99,175.93,-0.284
58.03,175.75,-0.284
58.06,175.58,-0.284
58.10,175.40,-0.284
58.13,175.23,-0.284
58.17,175.05,-0.284
58.20,174.88,-0.283
58.24,174.70,-0.283
58.27,174.53,-0.282
58.31,174.35,-0.282
58.34,174.18,-0.282
58.38,174.00,-0.282
58.41,173.83,-0.281
58.45,173.65,-0.282
58.48,173.48,-0.281
58.52,173.30,-0.281
58.55,173.13,-0.281
58.59,172.95,-0.280
58.62,172.78,-0.280
58.66,172.60,-0.280
58.69,172.43,-0.279
58.73,172.25,-0.279
58.76,172.08,-0.279
58.80,171.90,-0.279
58.83,171.73,-0.278
58.87,171.55,-0.278
58.90,171.38,-0.277
58.94,171.20,-0.277
58.97,171.03,-0.277
59.01,170.85,-0.276
59.04,170.68,-0.276
59.08,170.50,-0.276
59.11,170.33,-0.276
59.15,170.15,-0.276
59.18,169.98,-0.276
59.22,169.80,-0.275
59.25,169.63,-0.275
59.29,169.45,-0.274
59.32,169.28,-0.274
59.36,169.10,-0.274
59.39,168.93,-0.274
59.43,168.75,-0.273
59.46,168.58,-0.272
59.50,168.40,-0.272
59.53,168.23,-0.271
59.57,168.05,-0.271
59.60,167.88,-0.271
59.64,167.70,-0.270
59.67,167.53,-0.270
59.71,167.35,-0.270
59.74,167.18,-0.270
59.78,167.00,-0.269
59.81,166.83,-0.268
59.85,166.65,-0.268
59.88,166.48,-0.268
59.92,166.30,-0.268
59.95,166.13,-0.267
59.99,165.95,-0.267
60.02,165.78,-0.267
60.06,165.60,-0.267
60.09,165.43,-0.266
60.13,165.25,-0.266
60.16,165.08,-0.265
60.20,164.90,-0.265
60.23,164.73,-0.265
60.27,164.55,-0.265
60.30,164.38,-0.265
60.34,164.21,-0.264
60.37,164.03,-0.264
60.41,163.85,-0.264
60.44,163.68,-0.263
60.48,163.51,-0.263
60.51,163.33,-0.263
60.55,163.16,-0.262
60.58,162.98,-0.262
60.62,162.81,-0.262
60.65,162.63,-0.261
60.69,162.46,-0.261
60.72,162.28,-0.261
60.76,162.11,-0.261
60.79,161.93,-0.260
60.83,161.76,-0.260
60.86,161.58,-0.259
60.90,161.40,-0.259
60.93,161.23,-0.258
60.97,161.05,-0.258
61.00,160.88,-0.258
61.04,160.70,-0.258
61.07,160.53,-0.258
61.11,160.35,-0.257
61.14,160.18,-0.257
61.18,160.00,-0.257
61.21,159.83,-0.257
61.25,159.65,-0.257
61.28,159.48,-0.256
61.32,159.30,-0.255
61.35,159.13,-0.255
61.39,158.95,-0.255
61.42,158.78,-0.255
61.46,158.61,-0.254
61.49,158.43,-0.253
61.53,158.26,-0.254
61.56,158.08,-0.253
61.60,157.91,-0.253
61.63,157.73,-0.253
61.67,157.56,-0.253
61.70,157.38,-0.253
61.74,157.21,-0.253
61.77,157.03,-0.253
61.81,156.86,-0.252
61.84,156.68,-0.252
61.88,156.51,-0.251
61.91,156.33,-0.251
61.95,156.16,-0.251
61.98,155.98,-0.251
62.02,155.81,-0.251
62.05,155.63,-0.251
62.09,155.45,-0.250
62.12,155.28,-0.250
62.16,155.10,-0.250
62.19,154.93,-0.250
62.23,154.76,-0.249
62.26,154.58,-0.249
62.30,154.41,-0.249
62.33,154.23,-0.248
62.37,154.06,-0.248
62.40,153.88,-0.248
62.44,153.71,-0.248
62.47,153.53,-0.247
62.51,153.36,-0.248
62.54,153.18,-0.247
62.58,153.01,-0.247
62.61,152.83,-0.247
62.65,152.66,-0.247
62.68,152.48,-0.246
62.72,152.31,-0.246
62.75,152.13,-0.246
62.79,151.96,-0.246
62.82,151.78,-0.246
62.86,151.61,-0.245
62.89,151.43,-0.245
62.93,151.26,-0.245
62.96,151.08,-0.245
63.00,150.91,-0.244
63.03,150.73,-0.244
63.07,150.56,-0.244
63.10,150.38,-0.244
63.14,150.21,-0.243
63.17,150.03,-0.243
63.21,149.86,-0.243
63.24,149.68,-0.243
63.28,149.51,-0.243
63.31,149.33,-0.243
63.35,149.16,-0.242
63.38,148.98,-0.242
63.42,148.81,-0.242
63.45,148.63,-0.241
63.49,148.46,-0.241
63.52,148.28,-0.241
63.56,148.11,-0.241
63.59,147.93,-0.240
63.63,147.76,-0.240
63.66,147.58,-0.240
63.70,147.41,-0.240
63.73,147.23,-0.239
63.77,147.06,-0.239
63.80,146.88,-0.239
63.84,146.71,-0.238
63.87,146.53,-0.238
63.91,146.36,-0.238
63.94,146.18,-0.238
63.98,146.01,-0.238
64.01,145.83,-0.238
64.05,145.66,-0.237
64.08,145.48,-0.237
64.12,145.31,-0.237
64.15,145.13,-0.237
64.19,144.96,-0.236
[...]
228.23,20.52,0.094
228.26,20.69,0.094
228.30,20.87,0.094
228.33,21.04,0.094
228.37,21.22,0.094
228.40,21.39,0.094
228.44,21.57,0.094
228.47,21.74,0.094
228.51,21.92,0.094
228.54,22.09,0.095
228.58,22.27,0.095
228.61,22.44,0.095
228.65,22.62,0.095
228.68,22.79,0.095
228.72,22.97,0.095
228.75,23.14,0.095
228.79,23.32,0.095
228.82,23.49,0.095
228.86,23.67,0.095
228.89,23.84,0.095
228.93,24.02,0.095
228.96,24.19,0.095
229.00,24.37,0.096
229.03,24.54,0.096
229.07,24.72,0.096
229.10,24.89,0.096
229.14,25.07,0.096
229.17,25.24,0.096
229.21,25.42,0.096
229.24,25.59,0.096
229.28,25.77,0.096
229.31,25.94,0.096
229.35,26.12,0.096
229.38,26.29,0.096
229.42,26.47,0.096
229.45,26.64,0.096
229.49,26.82,0.096
229.52,27.00,0.097
229.56,27.17,0.097
229.59,27.35,0.097
229.63,27.52,0.097
229.66,27.69,0.097
229.70,27.87,0.097
229.73,28.05,0.097
229.77,28.22,0.097
229.80,28.39,0.097
229.84,28.57,0.097
229.87,28.74,0.097
229.91,28.92,0.097
229.94,29.10,0.097
229.98,29.27,0.098
230.01,29.45,0.098
230.05,29.62,0.098
230.08,29.80,0.098
230.12,29.97,0.098
230.15,30.15,0.098
230.19,30.32,0.098
230.22,30.50,0.098
230.26,30.67,0.098
230.29,30.85,0.098
230.33,31.02,0.098
230.36,31.20,0.098
230.40,31.37,0.099
230.43,31.55,0.099
230.47,31.72,0.099
230.50,31.90,0.099
230.54,32.07,0.099
230.57,32.25,0.099
230.61,32.42,0.099
230.64,32.60,0.099
230.68,32.77,0.099
230.71,32.95,0.099
230.75,33.12,0.099
230.78,33.30,0.099
230.82,33.47,0.099
230.85,33.65,0.100
230.89,33.82,0.100
230.92,34.00,0.100
230.96,34.17,0.100
230.99,34.35,0.100
231.03,34.52,0.100
231.06,34.70,0.100
231.10,34.87,0.100
231.13,35.05,0.100
231.17,35.22,0.100
231.20,35.40,0.100
231.24,35.57,0.100
231.27,35.75,0.100
231.31,35.92,0.101
231.34,36.10,0.101
231.38,36.28,0.101
231.41,36.45,0.101
231.45,36.63,0.101
231.48,36.80,0.101
231.52,36.98,0.101
231.55,37.15,0.101
231.59,37.32,0.101
231.62,37.50,0.101
231.66,37.68,0.101
231.69,37.85,0.101
231.73,38.03,0.101
231.76,38.20,0.102
231.80,38.38,0.102
231.83,38.55,0.102
231.87,38.73,0.102
231.90,38.90,0.102
231.94,39.08,0.102
231.97,39.25,0.102
232.01,39.43,0.102
232.04,39.60,0.103
232.08,39.78,0.103
232.11,39.95,0.103
232.15,40.13,0.103
232.18,40.30,0.103
232.22,40.48,0.103
232.25,40.65,0.103
232.29,40.83,0.103
232.32,41.00,0.103
232.36,41.18,0.103
232.39,41.35,0.103
232.43,41.53,0.103
232.46,41.70,0.103
232.50,41.88,0.103
232.53,42.05,0.104
232.57,42.23,0.104
232.60,42.40,0.104
232.64,42.58,0.104
232.67,42.75,0.104
232.71,42.93,0.104
232.74,43.10,0.104
232.78,43.28,0.104
232.81,43.45,0.104
232.85,43.63,0.104
232.88,43.80,0.105
232.92,43.98,0.105
232.95,44.15,0.105
232.99,44.33,0.105
233.02,44.50,0.105
233.06,44.68,0.105
233.09,44.85,0.105
233.13,45.03,0.105
233.16,45.21,0.105
233.20,45.38,0.105
233.23,45.56,0.105
233.27,45.73,0.106
233.30,45.91,0.106
233.34,46.08,0.106
233.37,46.26,0.106
233.41,46.43,0.106
233.44,46.61,0.106
233.48,46.78,0.106
233.51,46.96,0.106
233.55,47.13,0.106
233.58,47.31,0.106
233.62,47.48,0.106
233.65,47.66,0.107
233.69,47.83,0.107
233.72,48.01,0.107
233.76,48.18,0.107
233.79,48.36,0.107
233.83,48.53,0.107
233.86,48.71,0.107
233.90,48.88,0.107
233.93,49.06,0.107
233.97,49.23,0.107
234.00,49.41,0.107
234.04,49.58,0.107
234.07,49.76,0.107
234.11,49.93,0.108
234.14,50.11,0.108
234.18,50.28,0.108
234.21,50.46,0.108
234.25,50.63,0.108
234.28,50.81,0.108
234.32,50.98,0.108
234.35,51.16,0.108
234.39,51.33,0.108
234.42,51.51,0.109
234.46,51.68,0.109
234.49,51.86,0.109
234.53,52.03,0.109
234.56,52.21,0.109
234.60,52.38,0.109
234.63,52.56,0.109
234.67,52.73,0.109
234.70,52.91,0.109
234.74,53.08,0.109
234.77,53.26,0.109
234.81,53.43,0.109
234.84,53.61,0.109
234.88,53.78,0.110
234.91,53.96,0.110
234.95,54.13,0.110
234.98,54.31,0.110
235.02,54.48,0.110
235.05,54.66,0.110
235.09,54.84,0.110
235.12,55.01,0.110
235.16,55.18,0.110
235.19,55.36,0.110
235.23,55.53,0.110
235.26,55.71,0.111
235.30,55.89,0.111
235.33,56.06,0.111
235.37,56.24,0.111
235.40,56.41,0.111
235.44,56.59,0.111
235.47,56.76,0.111
235.51,56.94,0.111
235.54,57.11,0.111
235.58,57.29,0.111
235.61,57.46,0.111
235.65,57.64,0.112
235.68,57.81,0.112
235.72,57.99,0.112
235.75,58.16,0.112
235.79,58.34,0.112
235.82,58.51,0.112
235.86,58.69,0.112
235.89,58.86,0.112
235.93,59.04,0.112
235.96,59.21,0.112
236.00,59.39,0.113
236.03,59.56,0.113
236.07,59.74,0.113
236.10,59.91,0.113
236.14,60.09,0.113
236.17,60.26,0.113
236.21,60.44,0.113
236.24,60.61,0.113
236.28,60.79,0.113
236.31,60.96,0.114
236.35,61.14,0.114
236.38,61.31,0.114
236.42,61.49,0.114
236.45,61.66,0.114
236.49,61.84,0.114
236.52,62.01,0.114
236.56,62.19,0.114
236.59,62.36,0.114
236.63,62.54,0.114
236.66,62.71,0.114
236.70,62.89,0.115
236.73,63.06,0.115
236.77,63.24,0.115
236.80,63.41,0.115
236.84,63.59,0.115
236.87,63.76,0.115
236.91,63.94,0.115
236.94,64.12,0.115
236.98,64.29,0.115
237.01,64.46,0.115
237.05,64.64,0.115
237.08,64.81,0.116
237.12,64.99,0.116
237.15,65.16,0.116
237.19,65.34,0.116
237.22,65.51,0.116
237.26,65.69,0.116
237.29,65.87,0.116
237.33,66.04,0.116
237.36,66.21,0.117
237.40,66.39,0.117
237.43,66.56,0.117
237.47,66.74,0.117
237.50,66.92,0.117
237.54,67.09,0.117
237.57,67.27,0.117
237.61,67.44,0.117
237.64,67.62,0.117
237.68,67.79,0.117
237.71,67.97,0.117
237.75,68.14,0.117
237.78,68.32,0.118
237.82,68.49,0.118
237.85,68.67,0.118
237.89,68.84,0.118
237.92,69.02,0.118
237.96,69.19,0.118
237.99,69.37,0.118
238.03,69.54,0.118
238.06,69.72,0.118
238.10,69.89,0.118
238.13,70.07,0.118
238.17,70.24,0.119
238.20,70.42,0.119
238.24,70.59,0.119
238.27,70.77,0.119
238.31,70.94,0.119
238.34,71.12,0.119
238.38,71.29,0.119
238.41,71.47,0.119
238.45,71.64,0.119
238.48,71.82,0.119
238.52,71.99,0.120
238.55,72.17,0.120
238.59,72.34,0.120
238.62,72.52,0.120
238.66,72.69,0.120
238.69,72.87,0.120
238.73,73.05,0.120
238.76,73.22,0.120
238.80,73.39,0.121
238.83,73.57,0.121
238.87,73.74,0.121
238.90,73.92,0.121
238.94,74.10,0.121
238.97,74.27,0.121
239.01,74.44,0.121
239.04,74.62,0.121
239.08,74.80,0.121
239.11,74.97,0.121
239.15,75.14,0.121
239.18,75.32,0.121
239.22,75.50,0.121
239.25,75.67,0.122
239.29,75.85,0.122
239.32,76.02,0.122
239.36,76.20,0.122
239.39,76.37,0.122
239.43,76.55,0.122
239.46,76.72,0.122
239.50,76.90,0.122
239.53,77.07,0.122
239.57,77.25,0.123
239.60,77.42,0.123
239.64,77.60,0.123
239.67,77.77,0.123
239.71,77.95,0.123
239.74,78.12,0.123
239.78,78.29,0.123
239.81,78.47,0.123
239.85,78.65,0.123
239.88,78.82,0.123
239.92,79.00,0.123
239.95,79.17,0.124
239.99,79.35,0.124
240.02,79.52,0.124
240.06,79.70,0.124
240.09,79.87,0.124
240.13,80.05,0.124
240.16,80.22,0.124
240.20,80.40,0.124
240.23,80.57,0.124
240.27,80.75,0.124
240.30,80.92,0.124
240.34,81.10,0.125
240.37,81.27,0.125
240.41,81.45,0.125
240.44,81.62,0.125
240.48,81.80,0.125
240.51,81.97,0.125
240.55,82.15,0.125
240.58,82.32,0.125
240.62,82.50,0.125
240.65,82.67,0.125
240.69,82.85,0.126
240.72,83.02,0.126
240.76,83.20,0.126
240.79,83.37,0.126
240.83,83.55,0.126
240.86,83.72,0.126
240.90,83.90,0.126
240.93,84.07,0.126
240.97,84.25,0.126
241.00,84.42,0.126
241.04,84.60,0.126
241.07,84.77,0.127
241.11,84.95,0.127
241.14,85.12,0.127
241.18,85.30,0.127
241.21,85.47,0.127
241.25,85.65,0.127
241.28,85.82,0.127
241.32,86.00,0.127
241.35,86.17,0.127
241.39,86.35,0.127
241.42,86.52,0.127
241.46,86.70,0.127
241.49,86.87,0.128
241.53,87.05,0.128
241.56,87.22,0.128
241.60,87.40,0.128
241.63,87.57,0.128
241.67,87.75,0.128
241.70,87.93,0.128
241.74,88.10,0.128
241.77,88.28,0.129
241.81,88.45,0.129
241.84,88.62,0.129
241.88,88.80,0.129
241.91,88.98,0.129
241.95,89.15,0.129
241.98,89.33,0.129
242.02,89.50,0.129
242.05,89.67,0.129
242.09,89.85,0.129
242.12,90.03,0.130
242.16,90.20,0.130
242.19,90.38,0.130
242.23,90.55,0.130
242.26,90.73,0.130
242.30,90.90,0.130
242.33,91.08,0.130
242.37,91.25,0.130
242.40,91.43,0.131
242.44,91.60,0.131
242.47,91.78,0.131
242.51,91.95,0.131
242.54,92.13,0.131
242.58,92.30,0.131
242.61,92.48,0.131
242.65,92.65,0.131
242.68,92.83,0.131
242.72,93.00,0.131
242.75,93.18,0.131
242.79,93.35,0.131
242.82,93.53,0.132
242.86,93.70,0.132
242.89,93.88,0.132
242.93,94.05,0.132
242.96,94.23,0.132
243.00,94.40,0.132
243.03,94.58,0.133
243.07,94.75,0.133
243.10,94.93,0.133
243.14,95.10,0.133
243.17,95.28,0.133
243.21,95.45,0.133
243.24,95.63,0.133
243.28,95.80,0.133
243.31,95.98,0.133
243.35,96.15,0.133
243.38,96.33,0.133
243.42,96.50,0.134
243.45,96.68,0.134
243.49,96.85,0.134
243.52,97.03,0.134
243.56,97.20,0.134
243.59,97.38,0.134
243.63,97.55,0.134
243.66,97.73,0.134
243.70,97.90,0.135
243.73,98.08,0.135
243.77,98.25,0.135
243.80,98.43,0.135
243.84,98.60,0.135
243.87,98.78,0.135
243.91,98.95,0.135
243.94,99.13,0.135
243.98,99.30,0.136
244.01,99.48,0.136
244.05,99.65,0.136
244.08,99.83,0.136
244.12,100.00,0.136
244.15,100.18,0.136
244.19,100.35,0.136
244.22,100.53,0.136
244.26,100.70,0.136
244.29,100.88,0.137
244.33,101.05,0.137
244.36,101.23,0.137
244.40,101.40,0.137
244.43,101.58,0.137
244.47,101.76,0.137
244.50,101.93,0.137
244.54,102.10,0.138
244.57,102.28,0.138
244.61,102.45,0.138
244.64,102.63,0.138
244.68,102.80,0.138
244.71,102.98,0.138
244.75,103.15,0.138
244.78,103.33,0.138
244.82,103.50,0.138
244.85,103.68,0.138
244.89,103.85,0.138
244.92,104.03,0.138
244.96,104.20,0.139
244.99,104.38,0.139
245.03,104.55,0.139
245.06,104.73,0.139
245.10,104.91,0.139
245.13,105.08,0.139
245.17,105.26,0.139
245.20,105.43,0.140
245.24,105.60,0.140
245.27,105.78,0.140
245.31,105.95,0.140
245.34,106.13,0.140
245.38,106.31,0.140
245.41,106.48,0.140
245.45,106.66,0.140
245.48,106.83,0.140
245.52,107.01,0.140
245.55,107.18,0.140
245.59,107.36,0.141
245.62,107.53,0.141
245.66,107.71,0.141
245.69,107.88,0.141
245.73,108.06,0.141
245.76,108.23,0.141
245.80,108.40,0.142
245.83,108.58,0.142
245.87,108.76,0.142
245.90,108.93,0.142
245.94,109.10,0.142
245.97,109.28,0.142
246.01,109.46,0.142
246.04,109.63,0.142
246.08,109.81,0.142
246.11,109.98,0.142
246.15,110.16,0.142
246.18,110.33,0.142
246.22,110.51,0.142
246.25,110.68,0.143
246.29,110.86,0.143
246.32,111.03,0.143
246.36,111.21,0.143
246.39,111.38,0.143
246.43,111.56,0.143
246.46,111.73,0.144
246.50,111.91,0.144
246.53,112.08,0.144
246.57,112.26,0.144
246.60,112.43,0.144
246.64,112.61,0.144
246.67,112.78,0.144
246.71,112.96,0.144
246.74,113.13,0.144
246.78,113.31,0.144
246.81,113.48,0.145
246.85,113.66,0.145
246.88,113.83,0.145
246.92,114.01,0.145
246.95,114.18,0.145
246.99,114.36,0.145
247.02,114.53,0.145
247.06,114.71,0.145
247.09,114.88,0.145
247.13,115.06,0.146
247.16,115.23,0.146
247.20,115.41,0.146
247.23,115.58,0.146
247.27,115.76,0.146
247.30,115.93,0.146
247.34,116.11,0.146
247.37,116.28,0.146
247.41,116.46,0.147
247.44,116.63,0.147
247.48,116.81,0.147
247.51,116.98,0.147
247.55,117.16,0.147
247.58,117.33,0.147
247.62,117.51,0.147
247.65,117.68,0.147
247.69,117.86,0.148
247.72,118.03,0.148
247.76,118.21,0.148
247.79,118.38,0.148
247.83,118.56,0.148
247.86,118.73,0.148
247.90,118.91,0.148
247.93,119.08,0.148
247.97,119.26,0.148
248.00,119.43,0.149
248.04,119.61,0.149
248.07,119.78,0.149
248.11,119.96,0.149
248.14,120.13,0.149
248.18,120.31,0.149
248.21,120.49,0.149
248.25,120.66,0.149
248.28,120.84,0.149
248.32,121.01,0.150
248.35,121.18,0.150
248.39,121.36,0.150
248.42,121.54,0.150
248.46,121.71,0.149
248.49,121.89,0.150
248.53,122.06,0.150
248.56,122.24,0.150
248.60,122.41,0.150
248.63,122.59,0.150
248.67,122.76,0.151
248.70,122.94,0.151
248.74,123.11,0.151
248.77,123.29,0.151
248.81,123.46,0.151
248.84,123.64,0.151
248.88,123.81,0.151
248.91,123.99,0.151
248.95,124.16,0.151
248.98,124.34,0.151
249.02,124.51,0.151
249.05,124.69,0.151
249.09,124.86,0.151
249.12,125.04,0.151
249.16,125.21,0.151
249.19,125.39,0.151
249.23,125.56,0.152
249.26,125.74,0.152
249.30,125.91,0.152
249.33,126.09,0.152
249.37,126.26,0.152
249.40,126.44,0.152
249.44,126.61,0.152
249.47,126.79,0.152
249.51,126.96,0.152
249.54,127.14,0.153
249.58,127.31,0.153
249.61,127.49,0.153
249.65,127.66,0.153
249.68,127.84,0.153
249.72,128.01,0.153
249.75,128.19,0.153
249.79,128.36,0.153
249.82,128.54,0.153
249.86,128.71,0.153
249.89,128.89,0.153
249.93,129.06,0.154
249.96,129.24,0.154
250.00,129.41,0.154
250.03,129.59,0.154
250.07,129.76,0.154
250.10,129.93,0.154
250.14,130.11,0.154
250.17,130.28,0.154
250.21,130.46,0.154
250.24,130.64,0.155
250.28,130.81,0.155
250.31,130.99,0.155
250.35,131.16,0.155
250.38,131.34,0.155
250.42,131.51,0.155
250.45,131.69,0.155
250.49,131.86,0.156
250.52,132.04,0.156
250.56,132.21,0.156
250.59,132.39,0.156
250.63,132.56,0.156
250.66,132.74,0.156
250.70,132.91,0.156
250.73,133.09,0.156
250.77,133.26,0.156
250.80,133.43,0.157
250.84,133.61,0.157
250.87,133.79,0.157
250.91,133.96,0.157
250.94,134.14,0.157
250.98,134.31,0.157
251.01,134.49,0.157
251.05,134.66,0.157
251.08,134.84,0.158
251.12,135.01,0.158
251.15,135.18,0.158
251.19,135.36,0.158
251.22,135.54,0.158
251.26,135.71,0.158
251.29,135.89,0.158
251.33,136.06,0.158
251.36,136.24,0.158
251.40,136.41,0.159
251.43,136.59,0.159
251.47,136.76,0.159
251.50,136.94,0.159
251.54,137.11,0.159
251.57,137.29,0.159
251.61,137.46,0.160
251.64,137.64,0.160
251.68,137.81,0.160
251.71,137.99,0.160
251.75,138.16,0.160
251.78,138.34,0.160
251.82,138.51,0.160
251.85,138.69,0.161
251.89,138.86,0.161
251.92,139.04,0.161
251.96,139.21,0.161
251.99,139.39,0.161
252.03,139.56,0.161
252.06,139.74,0.161
252.10,139.91,0.161
252.13,140.09,0.161
252.17,140.26,0.162
252.20,140.44,0.162
252.24,140.61,0.162
252.27,140.79,0.162
252.31,140.96,0.162
252.34,141.14,0.162
252.38,141.31,0.162
252.41,141.49,0.162
252.45,141.66,0.162
252.48,141.84,0.162
252.52,142.01,0.163
252.55,142.19,0.163
252.59,142.36,0.163
252.62,142.54,0.163
252.66,142.71,0.163
252.69,142.89,0.163
252.73,143.06,0.164
252.76,143.24,0.164
252.80,143.41,0.164
252.83,143.59,0.164
252.87,143.76,0.164
252.90,143.94,0.164
252.94,144.11,0.164
252.97,144.29,0.164
253.01,144.46,0.164
253.04,144.64,0.164
253.08,144.81,0.165
253.11,144.99,0.165
253.15,145.16,0.165
253.18,145.34,0.165
253.22,145.51,0.165
253.25,145.69,0.165
253.29,145.86,0.166
253.32,146.04,0.166
253.36,146.21,0.166
253.39,146.39,0.166
253.43,146.56,0.166
253.46,146.74,0.166
253.50,146.91,0.166
253.53,147.09,0.166
253.57,147.26,0.166
253.60,147.44,0.166
253.64,147.61,0.166
253.67,147.79,0.167
253.71,147.96,0.167
253.74,148.14,0.167
253.78,148.31,0.167
253.81,148.49,0.167
253.85,148.66,0.167
253.88,148.84,0.167
253.92,149.01,0.167
253.95,149.19,0.167
253.99,149.36,0.168
254.02,149.54,0.168
254.06,149.71,0.168
254.09,149.89,0.168
254.13,150.06,0.168
254.16,150.24,0.168
254.20,150.41,0.168
254.23,150.59,0.168
254.27,150.76,0.169
254.30,150.94,0.177
254.34,151.11,0.183
254.37,151.28,0.186
254.41,151.46,0.188
254.44,151.63,0.191
254.48,151.81,0.195
254.51,151.98,0.198
254.55,152.15,0.198
254.58,152.33,0.199
254.62,152.50,0.199
254.65,152.68,0.199
254.69,152.85,0.200
254.72,153.03,0.200
254.76,153.20,0.201
254.79,153.38,0.201
254.83,153.55,0.202
254.86,153.73,0.202
254.90,153.90,0.203
254.93,154.08,0.204
254.97,154.25,0.204
255.00,154.43,0.204
255.04,154.60,0.205
255.07,154.78,0.205
255.11,154.95,0.205
255.14,155.13,0.206
255.18,155.30,0.206
255.21,155.48,0.206
255.25,155.65,0.207
255.28,155.83,0.207
255.32,156.00,0.208
255.35,156.17,0.208
255.39,156.35,0.208
255.42,156.53,0.208
255.46,156.70,0.209
255.49,156.87,0.209
255.53,157.05,0.204
255.56,157.23,0.198
255.60,157.41,0.196
255.63,157.58,0.193
255.67,157.76,0.191
255.70,157.93,0.189
255.74,158.11,0.188
255.77,158.29,0.187
255.81,158.46,0.186
255.84,158.64,0.186
255.88,158.81,0.185
255.91,158.99,0.185
255.95,159.16,0.184
255.98,159.34,0.184
256.02,159.51,0.183
256.05,159.69,0.183
256.09,159.86,0.182
256.12,160.04,0.182
256.16,160.21,0.181
256.19,160.39,0.181
256.23,160.56,0.181
256.26,160.74,0.181
256.30,160.91,0.189
256.33,161.08,0.193
256.37,161.26,0.195
256.40,161.43,0.197
256.44,161.61,0.199
256.47,161.78,0.201
256.51,161.95,0.203
256.54,162.13,0.205
256.58,162.30,0.205
256.61,162.48,0.206
256.65,162.65,0.206
256.68,162.83,0.206
256.72,163.00,0.207
256.75,163.18,0.207
256.79,163.35,0.208
256.82,163.53,0.208
256.86,163.70,0.208
256.89,163.88,0.208
256.93,164.05,0.209
256.96,164.23,0.209
257.00,164.40,0.209
257.03,164.58,0.209
257.07,164.75,0.209
257.10,164.93,0.209
257.14,165.10,0.209
257.17,165.28,0.209
257.21,165.45,0.209
257.24,165.63,0.209
257.28,165.81,0.210
257.31,165.98,0.210
257.35,166.15,0.210
257.38,166.33,0.210
257.42,166.50,0.210
257.45,166.68,0.210
257.49,166.85,0.211
257.52,167.03,0.211
257.56,167.20,0.211
257.59,167.38,0.211
257.63,167.55,0.211
257.66,167.73,0.211
257.70,167.90,0.211
257.73,168.08,0.210
257.77,168.26,0.209
257.80,168.43,0.210
257.84,168.61,0.210
257.87,168.78,0.210
257.91,168.96,0.210
257.94,169.13,0.210
257.98,169.30,0.209
258.01,169.48,0.209
258.05,169.65,0.210
258.08,169.83,0.210
258.12,170.01,0.210
258.15,170.18,0.211
258.19,170.35,0.211
258.22,170.53,0.211
258.26,170.70,0.211
258.29,170.88,0.212
258.33,171.06,0.212
258.36,171.23,0.212
258.40,171.41,0.212
258.43,171.58,0.213
258.47,171.76,0.213
258.50,171.93,0.213
258.54,172.11,0.213
258.57,172.28,0.213
258.61,172.45,0.213
258.64,172.63,0.213
258.68,172.81,0.213
258.71,172.98,0.213
258.75,173.15,0.213
258.78,173.33,0.213
258.82,173.50,0.214
258.85,173.68,0.214
258.89,173.85,0.213
258.92,174.03,0.214
258.96,174.20,0.214
258.99,174.38,0.214
259.03,174.55,0.214
259.06,174.73,0.214
259.10,174.91,0.214
259.13,175.08,0.214
259.17,175.25,0.214
259.20,175.43,0.214
259.24,175.61,0.214
259.27,175.78,0.214
259.31,175.96,0.214
259.34,176.13,0.214
259.38,176.31,0.214
259.41,176.48,0.214
259.45,176.66,0.215
259.48,176.83,0.214
259.52,177.01,0.214
259.55,177.18,0.215
259.59,177.36,0.215
259.62,177.53,0.215
259.66,177.71,0.215
259.69,177.88,0.215
259.73,178.05,0.215
259.76,178.23,0.215
259.80,178.40,0.215
259.83,178.58,0.214
259.87,178.76,0.214
259.90,178.93,0.214
259.94,179.11,0.215
259.97,179.28,0.215
260.01,179.46,0.215
260.04,179.63,0.215
260.08,179.81,0.215
260.11,179.98,0.215
260.15,180.16,0.215
260.18,180.33,0.215
260.22,180.51,0.214
260.25,180.68,0.214
260.29,180.86,0.214
260.32,181.03,0.214
260.36,181.21,0.214
260.39,181.38,0.214
260.43,181.56,0.214
260.46,181.73,0.214
260.50,181.91,0.214
260.53,182.08,0.214
260.57,182.26,0.214
260.60,182.43,0.214
260.64,182.61,0.213
260.67,182.78,0.213
260.71,182.96,0.213
260.74,183.13,0.213
260.78,183.31,0.213
260.81,183.48,0.213
260.85,183.66,0.213
260.88,183.83,0.213
260.92,184.01,0.213
260.95,184.18,0.213
260.99,184.36,0.213
261.02,184.53,0.213
261.06,184.71,0.213
261.09,184.88,0.213
261.13,185.06,0.213
261.16,185.23,0.213
261.20,185.41,0.213
261.23,185.58,0.213
261.27,185.76,0.213
261.30,185.94,0.213
261.34,186.11,0.214
261.37,186.29,0.214
261.41,186.46,0.214
261.44,186.63,0.214
261.48,186.81,0.215
261.51,186.98,0.215
261.55,187.16,0.215
261.58,187.33,0.215
261.62,187.51,0.214
261.65,187.68,0.214
261.69,187.86,0.215
261.72,188.03,0.215
261.76,188.21,0.215
261.79,188.38,0.215
261.83,188.56,0.215
261.86,188.73,0.215
261.90,188.91,0.215
261.93,189.08,0.215
261.97,189.26,0.215
262.00,189.44,0.215
262.04,189.61,0.215
262.07,189.78,0.215
262.11,189.96,0.215
262.14,190.14,0.215
262.18,190.31,0.216
262.21,190.48,0.216
262.25,190.66,0.216
262.28,190.84,0.216
262.32,191.01,0.216
262.35,191.18,0.216
262.39,191.36,0.216
262.42,191.54,0.216
262.46,191.71,0.216
262.49,191.89,0.216
262.53,192.06,0.216
262.56,192.23,0.216
262.60,192.41,0.216
262.63,192.58,0.216
262.67,192.76,0.215
262.70,192.93,0.214
262.74,193.11,0.214
262.77,193.29,0.214
262.81,193.46,0.213
262.84,193.64,0.213
262.88,193.81,0.213
262.91,193.99,0.213
262.95,194.16,0.213
262.98,194.34,0.213
263.02,194.51,0.213
263.05,194.69,0.212
263.09,194.86,0.212
263.12,195.04,0.212
263.16,195.21,0.212
263.19,195.39,0.212
263.23,195.56,0.212
263.26,195.74,0.212
263.30,195.91,0.211
263.33,196.09,0.212
263.37,196.26,0.211
263.40,196.44,0.211
263.44,196.61,0.211
263.47,196.79,0.211
263.51,196.96,0.210
263.54,197.14,0.210
263.58,197.31,0.210
263.61,197.49,0.209
263.65,197.66,0.209
263.68,197.84,0.208
263.72,198.01,0.207
263.75,198.19,0.207
263.79,198.36,0.206
263.82,198.54,0.206
263.86,198.71,0.205
263.89,198.89,0.204
263.93,199.07,
263.96,199.24,
263.98,,