File: DSC/2025_06_29_Adamantane_n90C_30C_10Cmin_x4.csv
Filename,2025_06_29_Adamantane_n90C_30C_10Cmin_x4
Instrument name,DSC2A-00468 (192.168.1.100)
Operator,Yarger
rundate,6/29/2025
Sample name,2025_06_29_Adamantane_n90C_30C_10Cmin_x4
proceduresegments,Data Off ; Equilibrate -90.00 °C; Data On ; Ramp 10.00 °C/min to 30.00 °C; Data Off ; Isothermal 2.0 min; Data On ; Ramp 10.00 °C/min to -90.00 °C; Data Off ; Isothermal 2.0 min; Data On ; Ramp 10.00 °C/min to 30.00 °C; Data Off ; Isothermal 2.0 min; Data On ; Ramp 10.00 °C/min to -90.00 °C; Data Off ; Isothermal 2.0 min; Data On ; Ramp 10.00 °C/min to 30.00 °C; Data Off ; Isothermal 2.0 min; Data On ; Ramp 10.00 °C/min to -90.00 °C; Data Off ; Isothermal 2.0 min; Data On ; Ramp 10.00 °C/min to 30.00 °C
[File Parameters]
Run date,6/29/2025 5:09:28 PM
Trios version,5.1.1.46572
Original File Name,
Current File Name,D:\DSC2500\Gibbons\2025_06_29_Adamantane_n90C_30C_10Cmin_x4.tri
[Procedure]
Procedure Name,Adam_n90C_30C_10Cmin_x4
Sample Name,2025_06_29_Adamantane_n90C_30C_10Cmin_x4
Sample Mass,6.96 mg
Reference Sample Mass,0 mg
Pan Mass,55.99 mg
Pan Number,7
Reference Pan Mass,56.76 mg
Reference Pan Number,10
Pan Type,Tzero Aluminum Hermetic
Comments,"Run Pan 25 (CBD-24DHBA) with Ref Pan 10, pans upside down and pan 25 was unsealed and lid is bent and 1/2 off!!  The autosampler failed to remove the pans after this run (6/27/25).  On 6/28/25 JLY discovered the DSC with two turned off pans.  Worried that DSC is contaminated.  Run completely empty to see baseline after cleaning and hope the DSC head is okay!!  Then run this Al2O3 powder Std sample with ref pan #10, and In and benzoic Acid... and Now Adamantane.

Al Hermetic DSC Consumables sealed Pan/Lid. Y1 Tray (Google Sheet: DSC_Samples_Y1_Tray_June2025)"
Project Name,Pharma - Cocrystals
Operator,Yarger
Test,Custom
Unload Max Temperature,30
Unload Min Temperature,30
Load Max Temperature,30
Load Min Temperature,30
Stop on Gas Flow Error,Yes
[Signal List]
Signal #1,Time (min)
Signal #2,Temperature (°C)
Signal #3,Heat Flow (mW)
Signal #4,Delta T (µV)
Signal #5,Delta Tzero (µV)
Signal #6,Tzero Temperature (°C)
Signal #7,Cell Purge (mL/min)
Signal #8,Heater Temp (°C)
Signal #9,Power Delivered (W)
Signal #10,Reference Junction Temperature (°C)
Signal #11,Flange Temperature (°C)
Signal #12,Heat Flow Phase (rad)
Signal #13,Total Heat Capacity (J/°C)
Signal #14,Heat Capacity (J/°C)
[Configuration]
Company Name,ASU
Instrument Name,DSC2A-00468
Instrument Type,DSC2500
Serial Number,DSC2A-00468
IP,192.168.1.100
Location of Instrument,MRRC
DisplayType,Unknown
Sample Interval ,0.1 s/pt
Selected Heat Flow,T4P
Exotherm Direction,Down
Cell Serial,DRC2-00792
Lid Type,Standard
Cooler,RCS 90
Leave Cooler on at End of Sequence,On
Gas 2,Nitrogen
Gas Selected,Channel 1
Flow Rate,50 mL/min
Secondary Purge,On
Licensed Heat Flow,Heat Flow T4P
Modulation Licensed,Yes
[Versions]
Common IDD Version,1
Cortex Version,VER 2.10.2.31
Driver,5.0.0.6
GDM Version,1.0.3.3
TouchscreenVersion,1.0.0.16145
FEP Version,1.2.1.21
FEP Bootloader,2.0.0.5
AutoSampler Version,2.1.1.26
Auto Sampler Bootloader,2.0.0.5
FCM Version,1.1.0.3
FCM Bootloader,2.0.0.5
[Experiment Logs]
Experiment Log Entry # 1,Air Cool is off.
Experiment Log Entry # 3,Data On set to 0
Experiment Log Entry # 5,Equilibrate Segment -90 (C) Started
Experiment Log Entry # 7,Data On set to 1
Experiment Log Entry # 9,Ramp Segment 10 C/min to 30 Started
Experiment Log Entry # 11,Data On set to 0
Experiment Log Entry # 13,Isothermal Segment 2 min started
Experiment Log Entry # 15,Data On set to 1
Experiment Log Entry # 17,Ramp Segment 10 C/min to -90 Started
Experiment Log Entry # 19,Data On set to 0
Experiment Log Entry # 21,Isothermal Segment 2 min started
Experiment Log Entry # 23,Data On set to 1
Experiment Log Entry # 25,Ramp Segment 10 C/min to 30 Started
Experiment Log Entry # 27,Data On set to 0
Experiment Log Entry # 29,Isothermal Segment 2 min started
Experiment Log Entry # 31,Data On set to 1
Experiment Log Entry # 33,Ramp Segment 10 C/min to -90 Started
Experiment Log Entry # 35,Data On set to 0
Experiment Log Entry # 37,Isothermal Segment 2 min started
Experiment Log Entry # 39,Data On set to 1
Experiment Log Entry # 41,Ramp Segment 10 C/min to 30 Started
Experiment Log Entry # 43,Data On set to 0
Experiment Log Entry # 45,Isothermal Segment 2 min started
Experiment Log Entry # 47,Data On set to 1
Experiment Log Entry # 49,Ramp Segment 10 C/min to -90 Started
Experiment Log Entry # 51,Ending Experiment because user stopped
[Method Log]
Method Log Entry # 1,Data Off
Method Log Entry # 2,Equilibrate -90 °C
Method Log Entry # 3,Data On
Method Log Entry # 4,(Ramp 711925) Ramp 10 °C/minute to 30 °C
Method Log Entry # 5,Data Off
Method Log Entry # 6,Isothermal 2 minutes
Method Log Entry # 7,Data On
Method Log Entry # 8,(Ramp 711929) Ramp 10 °C/minute to -90 °C
Method Log Entry # 9,Data Off
Method Log Entry # 10,Isothermal 2 minutes
Method Log Entry # 11,Data On
Method Log Entry # 12,(Ramp 711933) Ramp 10 °C/minute to 30 °C
Method Log Entry # 13,Data Off
Method Log Entry # 14,Isothermal 2 minutes
Method Log Entry # 15,Data On
Method Log Entry # 16,(Ramp 711937) Ramp 10 °C/minute to -90 °C
Method Log Entry # 17,Data Off
Method Log Entry # 18,Isothermal 2 minutes
Method Log Entry # 19,Data On
Method Log Entry # 20,(Ramp 711941) Ramp 10 °C/minute to 30 °C
Method Log Entry # 21,Data Off
Method Log Entry # 22,Isothermal 2 minutes
Method Log Entry # 23,Data On
Method Log Entry # 24,(Ramp 711945) Ramp 10 °C/minute to -90 °C
Cell Serial,DRC2-00792
[T1 Calibration]
Slope,-0.008529666
Offset,9.636258
Initial Temperature,98.23
GUID,f8bfdadc-4977-4fdf-ba6d-0ba9134940c3
[TZero Calibration]
Date Applied,11/29/2022 4:06:13 PM
Description,From -89.059 °C to 396.009 °C at 20.000°C/min
Gas Type,Nitrogen
Pan Type,None
Source Files 1,C:\Users\yargerlab\Desktop\DSC Data\General\TZero_calibration_11_29_22_2nd(2).tri
Source Files 2,C:\Users\yargerlab\Desktop\DSC Data\General\TZero_calibration_11_29_22_2nd(3).tri
Delta T Offset,13.05235
Delta T Slope,-0.007271007
Delta T0 Offset,-13.69128
Delta T0 Slope,0.06063341
[Temperature Calibration]
Date Applied,11/29/2022 7:12:28 PM
Description,From 106.590 °C to 186.590 °C at 10.000°C/min
Gas Type,Nitrogen
Pan Type,Tzero Aluminum Hermetic
Source Files 1,C:\Users\yargerlab\Desktop\DSC Data\General\Indium(6).tri
Measured 1,157.391
Known 1,156.598
[Cell Constant Calibration]
Date Applied,11/29/2022 7:12:29 PM
Description,From 106.590 °C to 186.590 °C at 10.000°C/min
Gas Type,Nitrogen
Pan Type,Tzero Aluminum Hermetic
Source Files 1,C:\Users\yargerlab\Desktop\DSC Data\General\Indium(6).tri
T4P KCell,1.006051
Onset Slope,63.26126 mW/°C
[Direct Cp Calibration]
Date Applied,11/30/2022 11:04:51 AM
Description,From -79.983 °C to 298.409 °C at 10.000°C/min
Gas Type,Nitrogen
Pan Type,Tzero Aluminum Hermetic
Source Files 1,C:\Users\yargerlab\Desktop\DSC Data\General\Sapphire_Heat_Capacity_11_30_22.tri
[Rev Cp Calibration]
Date Applied,11/30/2022 1:58:51 PM
Description,From -79.996 °C to 292.812 °C at 3.000°C/min
Gas Type,Nitrogen
Pan Type,Tzero Aluminum Hermetic
Source Files 1,C:\Users\yargerlab\Desktop\DSC Data\General\Sapphire_MDSC_Calibration_11_30_22.tri
[step]
Ramp 10.00 °C/min to 30.00 °C
Time,Temperature,Heat Flow (Normalized)
min,°C,W/g
0.00,-89.89,-0.033
0.01,-89.90,-0.033
0.02,-89.90,-0.031
0.03,-89.91,-0.030
0.03,-89.91,-0.029
0.04,-89.91,-0.027
0.05,-89.91,-0.025
0.06,-89.91,-0.021
0.07,-89.90,-0.018
0.08,-89.90,-0.012
0.08,-89.89,-0.006
0.09,-89.87,0.001
0.10,-89.85,0.009
0.11,-89.82,0.017
0.12,-89.79,0.024
0.13,-89.76,0.034
0.13,-89.72,0.043
0.14,-89.67,0.051
0.15,-89.63,0.059
0.16,-89.58,0.067
0.17,-89.53,0.074
0.18,-89.47,0.081
0.18,-89.42,0.088
0.19,-89.36,0.093
0.20,-89.30,0.100
0.21,-89.24,0.106
0.22,-89.18,0.111
0.23,-89.11,0.115
0.23,-89.05,0.120
0.24,-88.99,0.124
0.25,-88.92,0.128
0.26,-88.85,0.131
0.27,-88.78,0.136
0.28,-88.71,0.140
0.28,-88.64,0.142
0.29,-88.57,0.146
0.30,-88.50,0.149
0.31,-88.43,0.151
0.32,-88.35,0.155
0.33,-88.28,0.157
0.33,-88.21,0.158
0.34,-88.13,0.159
0.35,-88.06,0.162
0.36,-87.98,0.164
0.37,-87.90,0.164
0.38,-87.83,0.167
0.38,-87.75,0.168
0.39,-87.67,0.169
0.40,-87.60,0.171
0.41,-87.52,0.172
0.42,-87.44,0.173
0.43,-87.36,0.174
0.43,-87.28,0.174
0.44,-87.21,0.176
0.45,-87.13,0.177
0.46,-87.04,0.177
0.47,-86.97,0.178
0.48,-86.89,0.179
0.48,-86.81,0.179
0.49,-86.73,0.180
0.50,-86.65,0.181
0.51,-86.56,0.181
0.52,-86.49,0.181
0.53,-86.40,0.182
0.53,-86.32,0.182
0.54,-86.24,0.182
0.55,-86.16,0.183
0.56,-86.08,0.183
0.57,-86.00,0.183
0.58,-85.92,0.184
0.58,-85.84,0.184
0.59,-85.76,0.184
0.60,-85.68,0.184
0.61,-85.59,0.184
0.62,-85.51,0.185
0.63,-85.43,0.185
0.63,-85.35,0.185
0.64,-85.27,0.185
0.65,-85.19,0.185
0.66,-85.11,0.185
0.67,-85.02,0.186
0.68,-84.94,0.186
0.68,-84.86,0.186
0.69,-84.78,0.186
0.70,-84.70,0.187
0.71,-84.61,0.187
0.72,-84.53,0.187
0.73,-84.45,0.187
0.73,-84.37,0.187
0.74,-84.29,0.187
0.75,-84.20,0.187
0.76,-84.12,0.187
0.77,-84.04,0.188
0.78,-83.96,0.188
0.78,-83.88,0.188
0.79,-83.79,0.188
0.80,-83.71,0.188
0.81,-83.62,0.188
0.82,-83.54,0.188
0.83,-83.46,0.188
0.83,-83.38,0.189
0.84,-83.30,0.189
0.85,-83.21,0.189
0.86,-83.13,0.189
0.87,-83.05,0.189
0.88,-82.97,0.189
0.88,-82.88,0.189
0.89,-82.80,0.189
0.90,-82.72,0.189
0.91,-82.64,0.189
0.92,-82.55,0.189
0.93,-82.47,0.190
0.93,-82.39,0.190
0.94,-82.31,0.190
0.95,-82.22,0.190
0.96,-82.14,0.190
0.97,-82.06,0.190
0.98,-81.97,0.190
0.98,-81.89,0.190
0.99,-81.81,0.190
1.00,-81.73,0.190
1.01,-81.64,0.190
1.02,-81.56,0.190
1.03,-81.48,0.191
1.03,-81.39,0.191
1.04,-81.31,0.191
1.05,-81.23,0.191
1.06,-81.14,0.191
1.07,-81.06,0.191
1.08,-80.98,0.191
1.08,-80.90,0.191
1.09,-80.81,0.191
1.10,-80.73,0.191
1.11,-80.65,0.191
1.12,-80.56,0.191
1.13,-80.48,0.192
1.13,-80.40,0.192
1.14,-80.32,0.192
1.15,-80.23,0.192
1.16,-80.15,0.192
1.17,-80.07,0.192
1.18,-79.98,0.192
1.18,-79.90,0.192
1.19,-79.82,0.192
1.20,-79.74,0.192
1.21,-79.65,0.192
1.22,-79.57,0.192
1.23,-79.48,0.193
1.23,-79.40,0.193
1.24,-79.32,0.193
1.25,-79.24,0.193
1.26,-79.15,0.193
1.27,-79.07,0.193
1.28,-78.99,0.193
1.28,-78.90,0.193
1.29,-78.82,0.193
1.30,-78.74,0.193
1.31,-78.65,0.193
1.32,-78.57,0.193
1.33,-78.49,0.193
1.33,-78.40,0.193
1.34,-78.32,0.193
1.35,-78.24,0.193
1.36,-78.15,0.194
1.37,-78.07,0.194
1.38,-77.99,0.194
1.38,-77.90,0.194
1.39,-77.82,0.194
1.40,-77.74,0.194
1.41,-77.66,0.194
1.42,-77.57,0.194
1.43,-77.49,0.194
1.43,-77.40,0.194
1.44,-77.32,0.194
1.45,-77.24,0.194
1.46,-77.16,0.194
1.47,-77.07,0.194
1.48,-76.99,0.194
1.48,-76.91,0.194
1.49,-76.82,0.194
1.50,-76.74,0.195
1.51,-76.66,0.195
1.52,-76.57,0.195
1.53,-76.49,0.195
1.53,-76.41,0.195
1.54,-76.32,0.195
1.55,-76.24,0.195
1.56,-76.16,0.195
1.57,-76.07,0.195
1.58,-75.99,0.195
1.58,-75.91,0.195
1.59,-75.82,0.195
1.60,-75.74,0.195
1.61,-75.66,0.195
1.62,-75.57,0.195
1.63,-75.49,0.196
1.63,-75.41,0.196
1.64,-75.33,0.196
1.65,-75.24,0.196
1.66,-75.16,0.196
1.67,-75.07,0.196
1.68,-74.99,0.196
1.68,-74.91,0.196
1.69,-74.82,0.196
1.70,-74.74,0.196
1.71,-74.66,0.196
1.72,-74.58,0.197
1.73,-74.49,0.197
1.73,-74.41,0.197
1.74,-74.33,0.197
1.75,-74.24,0.197
1.76,-74.16,0.197
1.77,-74.08,0.197
1.78,-73.99,0.197
1.78,-73.91,0.197
1.79,-73.83,0.198
1.80,-73.74,0.198
1.81,-73.66,0.198
1.82,-73.58,0.198
1.83,-73.49,0.198
1.83,-73.41,0.198
1.84,-73.33,0.198
1.85,-73.24,0.198
1.86,-73.16,0.198
1.87,-73.08,0.198
1.88,-73.00,0.199
1.88,-72.91,0.199
1.89,-72.83,0.199
1.90,-72.74,0.199
1.91,-72.66,0.199
1.92,-72.58,0.199
1.93,-72.49,0.199
1.93,-72.41,0.201
1.94,-72.33,0.201
1.95,-72.25,0.201
1.96,-72.16,0.201
1.97,-72.08,0.201
1.98,-72.00,0.201
1.98,-71.91,0.202
1.99,-71.83,0.202
2.00,-71.74,0.202
2.01,-71.66,0.202
2.02,-71.58,0.202
2.03,-71.50,0.202
2.03,-71.41,0.203
2.04,-71.33,0.203
2.05,-71.24,0.203
2.06,-71.16,0.203
2.07,-71.08,0.204
2.08,-71.00,0.204
2.08,-70.91,0.204
2.09,-70.83,0.204
2.10,-70.75,0.204
2.11,-70.66,0.205
2.12,-70.58,0.205
2.13,-70.50,0.205
2.13,-70.41,0.206
2.14,-70.33,0.206
2.15,-70.25,0.206
2.16,-70.16,0.207
2.17,-70.08,0.207
2.18,-70.00,0.207
2.18,-69.92,0.207
2.19,-69.83,0.208
2.20,-69.75,0.208
2.21,-69.66,0.208
2.22,-69.58,0.209
2.23,-69.50,0.209
2.23,-69.42,0.210
2.24,-69.33,0.212
2.25,-69.25,0.212
2.26,-69.17,0.214
2.27,-69.09,0.214
2.28,-69.00,0.215
2.28,-68.92,0.217
2.29,-68.84,0.217
2.30,-68.75,0.218
2.31,-68.67,0.219
2.32,-68.59,0.222
2.33,-68.50,0.223
2.33,-68.42,0.224
2.34,-68.34,0.226
2.35,-68.26,0.227
2.36,-68.17,0.230
2.37,-68.09,0.233
2.38,-68.01,0.234
2.38,-67.93,0.236
2.39,-67.84,0.240
2.40,-67.76,0.241
2.41,-67.68,0.245
2.42,-67.60,0.248
2.43,-67.52,0.253
2.43,-67.43,0.258
2.44,-67.35,0.260
2.45,-67.27,0.266
2.46,-67.19,0.272
2.47,-67.11,0.279
2.48,-67.03,0.287
2.48,-66.95,0.295
2.49,-66.87,0.308
2.50,-66.79,0.321
2.51,-66.71,0.340
2.52,-66.63,0.363
2.53,-66.56,0.391
2.53,-66.48,0.428
2.54,-66.41,0.475
2.55,-66.34,0.523
2.56,-66.27,0.569
2.57,-66.21,0.612
2.58,-66.14,0.646
2.58,-66.08,0.681
2.59,-66.01,0.710
2.60,-65.95,0.738
2.61,-65.88,0.765
2.62,-65.82,0.793
2.63,-65.75,0.818
2.63,-65.68,0.840
2.64,-65.62,0.859
2.65,-65.55,0.877
2.66,-65.48,0.895
2.67,-65.41,0.911
2.68,-65.34,0.927
2.68,-65.27,0.942
2.69,-65.20,0.958
2.70,-65.13,0.971
2.71,-65.06,0.983
2.72,-64.99,0.993
2.73,-64.92,1.002
2.73,-64.85,1.007
2.74,-64.77,1.011
2.75,-64.69,1.017
2.76,-64.62,1.021
2.77,-64.54,1.027
2.78,-64.47,1.031
2.78,-64.39,1.035
2.79,-64.31,1.037
2.80,-64.23,1.035
2.81,-64.15,1.034
2.82,-64.08,1.029
2.83,-63.99,1.023
2.83,-63.91,1.015
2.84,-63.83,1.010
2.85,-63.75,1.003
2.86,-63.66,0.997
2.87,-63.58,0.990
2.88,-63.49,0.983
2.88,-63.41,0.976
2.89,-63.32,0.965
2.90,-63.24,0.952
2.91,-63.15,0.938
2.92,-63.07,0.925
2.93,-62.98,0.913
2.93,-62.89,0.899
2.94,-62.80,0.886
2.95,-62.71,0.874
2.96,-62.62,0.862
2.97,-62.53,0.849
2.98,-62.44,0.834
2.98,-62.35,0.818
2.99,-62.26,0.801
3.00,-62.17,0.781
3.01,-62.08,0.762
3.02,-61.99,0.738
3.03,-61.89,0.715
3.03,-61.80,0.688
3.04,-61.70,0.662
3.05,-61.61,0.633
3.06,-61.51,0.601
3.07,-61.41,0.569
3.08,-61.32,0.533
3.08,-61.22,0.502
3.09,-61.12,0.474
3.10,-61.02,0.447
3.11,-60.92,0.425
3.12,-60.82,0.403
3.13,-60.72,0.386
3.13,-60.63,0.370
3.14,-60.53,0.355
3.15,-60.43,0.343
3.16,-60.34,0.332
3.17,-60.24,0.321
3.18,-60.15,0.312
3.18,-60.05,0.304
3.19,-59.96,0.296
3.20,-59.87,0.288
3.21,-59.78,0.282
3.22,-59.69,0.276
3.23,-59.60,0.271
3.23,-59.51,0.267
3.24,-59.42,0.262
3.25,-59.33,0.257
3.26,-59.24,0.253
3.27,-59.15,0.250
3.28,-59.06,0.247
3.28,-58.97,0.243
3.29,-58.89,0.241
3.30,-58.80,0.237
3.31,-58.71,0.236
3.32,-58.63,0.233
3.33,-58.54,0.231
3.33,-58.45,0.227
3.34,-58.37,0.228
3.35,-58.28,0.226
3.36,-58.20,0.224
3.37,-58.11,0.222
3.38,-58.02,0.219
3.38,-57.94,0.220
3.39,-57.86,0.220
3.40,-57.77,0.219
3.41,-57.69,0.217
3.42,-57.60,0.217
3.43,-57.52,0.216
3.43,-57.43,0.214
3.44,-57.35,0.214
3.45,-57.26,0.213
3.46,-57.18,0.213
3.47,-57.09,0.212
3.48,-57.01,0.212
3.48,-56.92,0.212
3.49,-56.84,0.212
3.50,-56.76,0.211
3.51,-56.67,0.210
3.52,-56.59,0.210
3.53,-56.50,0.210
3.53,-56.42,0.210
3.54,-56.34,0.210
3.55,-56.25,0.209
3.56,-56.17,0.209
3.57,-56.08,0.209
3.58,-56.00,0.209
3.58,-55.92,0.209
3.59,-55.83,0.209
3.60,-55.75,0.209
3.61,-55.67,0.208
3.62,-55.58,0.208
3.63,-55.50,0.208
3.63,-55.41,0.208
3.64,-55.33,0.208
3.65,-55.25,0.208
3.66,-55.16,0.208
3.67,-55.08,0.208
3.68,-55.00,0.207
3.68,-54.91,0.207
3.69,-54.83,0.207
3.70,-54.75,0.207
3.71,-54.66,0.207
3.72,-54.58,0.207
3.73,-54.49,0.207
3.73,-54.41,0.207
3.74,-54.33,0.207
3.75,-54.24,0.207
3.76,-54.16,0.207
3.77,-54.08,0.207
3.78,-53.99,0.207
3.78,-53.91,0.207
3.79,-53.82,0.207
3.80,-53.74,0.207
3.81,-53.66,0.207
3.82,-53.58,0.207
3.83,-53.49,0.207
3.83,-53.41,0.207
3.84,-53.33,0.207
3.85,-53.24,0.207
3.86,-53.16,0.206
3.87,-53.08,0.206
3.88,-52.99,0.206
3.88,-52.91,0.206
3.89,-52.82,0.206
3.90,-52.74,0.206
3.91,-52.66,0.206
3.92,-52.57,0.206
3.93,-52.49,0.206
3.93,-52.41,0.206
3.94,-52.32,0.206
3.95,-52.24,0.206
3.96,-52.15,0.206
3.97,-52.07,0.206
3.98,-51.99,0.206
3.98,-51.91,0.207
3.99,-51.82,0.207
4.00,-51.74,0.207
4.01,-51.66,0.207
4.02,-51.57,0.207
4.03,-51.49,0.207
4.03,-51.40,0.207
4.04,-51.32,0.207
4.05,-51.24,0.207
4.06,-51.15,0.207
4.07,-51.07,0.207
4.08,-50.99,0.207
4.08,-50.90,0.207
4.09,-50.82,0.207
4.10,-50.73,0.207
4.11,-50.65,0.207
4.12,-50.57,0.207
4.13,-50.49,0.207
4.13,-50.40,0.207
4.14,-50.32,0.207
4.15,-50.23,0.207
4.16,-50.15,0.207
4.17,-50.07,0.207
4.18,-49.98,0.207
4.18,-49.90,0.207
4.19,-49.82,0.207
4.20,-49.73,0.207
4.21,-49.65,0.207
4.22,-49.57,0.207
4.23,-49.48,0.207
4.23,-49.40,0.207
4.24,-49.32,0.207
4.25,-49.23,0.207
4.26,-49.15,0.207
4.27,-49.06,0.208
4.28,-48.98,0.208
4.28,-48.90,0.208
4.29,-48.81,0.208
4.30,-48.73,0.208
4.31,-48.65,0.208
4.32,-48.56,0.208
4.33,-48.48,0.208
4.33,-48.40,0.208
4.34,-48.31,0.208
4.35,-48.23,0.208
4.36,-48.15,0.208
4.37,-48.06,0.208
4.38,-47.98,0.208
4.38,-47.90,0.208
4.39,-47.81,0.208
4.40,-47.73,0.208
4.41,-47.64,0.208
4.42,-47.56,0.208
4.43,-47.48,0.208
4.43,-47.40,0.208
4.44,-47.31,0.209
4.45,-47.23,0.209
4.46,-47.15,0.209
4.47,-47.06,0.209
4.48,-46.98,0.209
4.48,-46.89,0.209
4.49,-46.81,0.209
4.50,-46.73,0.209
4.51,-46.64,0.209
4.52,-46.56,0.209
4.53,-46.48,0.209
4.53,-46.39,0.209
4.54,-46.31,0.209
4.55,-46.23,0.209
4.56,-46.14,0.209
4.57,-46.06,0.209
4.58,-45.98,0.209
4.58,-45.89,0.209
4.59,-45.81,0.209
4.60,-45.73,0.209
4.61,-45.64,0.209
4.62,-45.56,0.210
4.63,-45.48,0.210
4.63,-45.39,0.210
4.64,-45.31,0.210
4.65,-45.22,0.210
4.66,-45.14,0.210
4.67,-45.06,0.210
4.68,-44.97,0.210
4.68,-44.89,0.210
4.69,-44.81,0.210
4.70,-44.72,0.210
4.71,-44.64,0.210
4.72,-44.56,0.210
4.73,-44.47,0.210
4.73,-44.39,0.210
4.74,-44.31,0.210
4.75,-44.22,0.210
4.76,-44.14,0.210
4.77,-44.06,0.210
4.78,-43.97,0.210
4.78,-43.89,0.211
4.79,-43.80,0.211
4.80,-43.72,0.211
4.81,-43.64,0.211
4.82,-43.55,0.211
4.83,-43.47,0.211
4.83,-43.39,0.211
4.84,-43.30,0.211
4.85,-43.22,0.211
4.86,-43.14,0.211
4.87,-43.05,0.211
4.88,-42.97,0.211
4.88,-42.89,0.211
4.89,-42.80,0.211
4.90,-42.72,0.211
4.91,-42.64,0.211
4.92,-42.55,0.212
4.93,-42.47,0.212
4.93,-42.39,0.212
4.94,-42.30,0.212
4.95,-42.22,0.212
4.96,-42.13,0.212
4.97,-42.05,0.212
4.98,-41.97,0.212
4.98,-41.88,0.212
4.99,-41.80,0.212
5.00,-41.71,0.212
5.01,-41.63,0.212
5.02,-41.55,0.212
5.03,-41.47,0.212
5.03,-41.38,0.212
5.04,-41.30,0.212
5.05,-41.22,0.212
5.06,-41.13,0.212
5.07,-41.05,0.212
5.08,-40.97,0.212
5.08,-40.88,0.212
5.09,-40.80,0.213
5.10,-40.72,0.213
5.11,-40.63,0.213
5.12,-40.55,0.213
5.13,-40.47,0.213
5.13,-40.38,0.213
5.14,-40.30,0.213
5.15,-40.21,0.213
5.16,-40.13,0.213
5.17,-40.05,0.213
5.18,-39.96,0.213
5.18,-39.88,0.213
5.19,-39.79,0.213
5.20,-39.71,0.213
5.21,-39.63,0.213
5.22,-39.55,0.213
5.23,-39.46,0.213
5.23,-39.38,0.213
5.24,-39.29,0.213
5.25,-39.21,0.214
5.26,-39.13,0.214
5.27,-39.05,0.214
5.28,-38.96,0.214
5.28,-38.88,0.214
5.29,-38.79,0.214
5.30,-38.71,0.214
5.31,-38.63,0.214
5.32,-38.54,0.214
5.33,-38.46,0.214
5.33,-38.38,0.214
5.34,-38.29,0.214
5.35,-38.21,0.214
5.36,-38.13,0.214
5.37,-38.04,0.214
5.38,-37.96,0.214
5.38,-37.88,0.215
5.39,-37.79,0.215
5.40,-37.71,0.215
5.41,-37.63,0.215
5.42,-37.54,0.215
5.43,-37.46,0.215
5.43,-37.38,0.215
5.44,-37.29,0.215
5.45,-37.21,0.215
5.46,-37.13,0.215
5.47,-37.04,0.215
5.48,-36.96,0.215
5.48,-36.87,0.215
5.49,-36.79,0.215
5.50,-36.71,0.215
5.51,-36.63,0.215
5.52,-36.54,0.215
5.53,-36.46,0.215
5.53,-36.37,0.216
5.54,-36.29,0.216
5.55,-36.21,0.216
5.56,-36.12,0.216
5.57,-36.04,0.216
5.58,-35.96,0.216
5.58,-35.87,0.216
5.59,-35.79,0.216
5.60,-35.71,0.216
5.61,-35.62,0.216
5.62,-35.54,0.216
5.63,-35.46,0.216
5.63,-35.37,0.216
5.64,-35.29,0.216
5.65,-35.21,0.216
5.66,-35.12,0.216
5.67,-35.04,0.216
5.68,-34.96,0.216
5.68,-34.87,0.217
5.69,-34.79,0.217
5.70,-34.71,0.217
5.71,-34.62,0.217
5.72,-34.54,0.217
5.73,-34.46,0.217
5.73,-34.37,0.217
5.74,-34.29,0.217
5.75,-34.20,0.217
5.76,-34.12,0.217
5.77,-34.04,0.217
5.78,-33.95,0.217
5.78,-33.87,0.217
5.79,-33.79,0.217
5.80,-33.70,0.217
5.81,-33.62,0.217
5.82,-33.54,0.217
5.83,-33.45,0.217
5.83,-33.37,0.218
5.84,-33.29,0.218
5.85,-33.20,0.218
5.86,-33.12,0.218
5.87,-33.03,0.218
5.88,-32.95,0.218
5.88,-32.87,0.218
5.89,-32.79,0.218
5.90,-32.70,0.218
5.91,-32.62,0.218
5.92,-32.54,0.218
5.93,-32.45,0.218
5.93,-32.37,0.218
5.94,-32.29,0.218
5.95,-32.20,0.218
5.96,-32.12,0.218
5.97,-32.03,0.218
5.98,-31.95,0.218
5.98,-31.87,0.218
5.99,-31.78,0.219
6.00,-31.70,0.219
6.01,-31.62,0.219
6.02,-31.53,0.219
6.03,-31.45,0.219
6.03,-31.37,0.219
6.04,-31.28,0.219
6.05,-31.20,0.219
6.06,-31.12,0.219
6.07,-31.03,0.219
6.08,-30.95,0.219
6.08,-30.87,0.219
6.09,-30.78,0.219
6.10,-30.70,0.219
6.11,-30.62,0.219
6.12,-30.53,0.219
6.13,-30.45,0.219
6.13,-30.37,0.219
6.14,-30.28,0.220
6.15,-30.20,0.220
6.16,-30.11,0.220
6.17,-30.03,0.220
6.18,-29.95,0.220
6.18,-29.87,0.220
6.19,-29.78,0.220
6.20,-29.70,0.220
6.21,-29.61,0.220
6.22,-29.53,0.220
6.23,-29.45,0.220
6.23,-29.36,0.220
6.24,-29.28,0.220
6.25,-29.20,0.220
6.26,-29.11,0.220
6.27,-29.03,0.220
6.28,-28.95,0.221
6.28,-28.86,0.221
6.29,-28.78,0.221
6.30,-28.70,0.221
6.31,-28.61,0.221
6.32,-28.53,0.221
6.33,-28.45,0.221
6.33,-28.36,0.221
6.34,-28.28,0.221
6.35,-28.19,0.221
6.36,-28.11,0.221
6.37,-28.03,0.221
6.38,-27.95,0.221
6.38,-27.86,0.221
6.39,-27.78,0.221
6.40,-27.69,0.221
6.41,-27.61,0.222
6.42,-27.53,0.222
6.43,-27.44,0.222
6.43,-27.36,0.222
6.44,-27.28,0.222
6.45,-27.19,0.222
6.46,-27.11,0.222
6.47,-27.03,0.222
6.48,-26.94,0.222
6.48,-26.86,0.222
6.49,-26.78,0.222
6.50,-26.69,0.222
6.51,-26.61,0.222
6.52,-26.53,0.222
6.53,-26.44,0.222
6.53,-26.36,0.222
6.54,-26.28,0.223
6.55,-26.19,0.223
6.56,-26.11,0.223
6.57,-26.03,0.223
6.58,-25.94,0.223
6.58,-25.86,0.223
6.59,-25.78,0.223
6.60,-25.69,0.223
6.61,-25.61,0.223
6.62,-25.53,0.223
6.63,-25.44,0.223
6.63,-25.36,0.223
6.64,-25.27,0.223
6.65,-25.19,0.223
6.66,-25.11,0.223
6.67,-25.02,0.223
6.68,-24.94,0.223
6.68,-24.86,0.223
6.69,-24.77,0.224
6.70,-24.69,0.224
6.71,-24.61,0.224
6.72,-24.52,0.224
6.73,-24.44,0.224
6.73,-24.36,0.224
6.74,-24.27,0.224
6.75,-24.19,0.224
6.76,-24.11,0.224
6.77,-24.02,0.224
6.78,-23.94,0.224
6.78,-23.86,0.224
6.79,-23.77,0.224
6.80,-23.69,0.224
6.81,-23.61,0.224
6.82,-23.52,0.224
6.83,-23.44,0.225
6.83,-23.36,0.225
6.84,-23.27,0.225
6.85,-23.19,0.225
6.86,-23.11,0.225
6.87,-23.02,0.225
6.88,-22.94,0.225
6.88,-22.86,0.225
6.89,-22.77,0.225
6.90,-22.69,0.225
6.91,-22.60,0.225
6.92,-22.52,0.225
6.93,-22.44,0.225
6.93,-22.36,0.225
6.94,-22.27,0.225
6.95,-22.19,0.226
6.96,-22.10,0.226
6.97,-22.02,0.226
6.98,-21.94,0.226
6.98,-21.85,0.226
6.99,-21.77,0.226
7.00,-21.69,0.226
7.01,-21.60,0.226
7.02,-21.52,0.226
7.03,-21.44,0.226
7.03,-21.35,0.226
7.04,-21.27,0.226
7.05,-21.19,0.226
7.06,-21.10,0.226
7.07,-21.02,0.226
7.08,-20.94,0.227
7.08,-20.85,0.227
7.09,-20.77,0.227
7.10,-20.68,0.227
7.11,-20.60,0.227
7.12,-20.52,0.227
7.13,-20.43,0.227
7.13,-20.35,0.227
7.14,-20.27,0.227
7.15,-20.18,0.227
7.16,-20.10,0.227
7.17,-20.02,0.227
7.18,-19.93,0.227
7.18,-19.85,0.227
7.19,-19.77,0.227
7.20,-19.69,0.227
7.21,-19.60,0.227
7.22,-19.52,0.227
7.23,-19.43,0.228
7.23,-19.35,0.228
7.24,-19.27,0.228
7.25,-19.18,0.228
7.26,-19.10,0.228
7.27,-19.02,0.228
7.28,-18.93,0.228
7.28,-18.85,0.228
7.29,-18.77,0.228
7.30,-18.68,0.228
7.31,-18.60,0.228
7.32,-18.52,0.228
7.33,-18.43,0.228
7.33,-18.35,0.228
7.34,-18.26,0.228
7.35,-18.18,0.228
7.36,-18.10,0.228
7.37,-18.02,0.228
7.38,-17.93,0.229
7.38,-17.85,0.229
7.39,-17.77,0.229
7.40,-17.68,0.229
7.41,-17.60,0.229
7.42,-17.51,0.229
7.43,-17.43,0.229
7.43,-17.35,0.229
7.44,-17.26,0.229
7.45,-17.18,0.229
7.46,-17.10,0.229
7.47,-17.01,0.229
7.48,-16.93,0.229
7.48,-16.85,0.229
7.49,-16.76,0.229
7.50,-16.68,0.229
7.51,-16.60,0.229
7.52,-16.51,0.230
7.53,-16.43,0.230
7.53,-16.35,0.230
7.54,-16.26,0.230
7.55,-16.18,0.230
7.56,-16.10,0.230
7.57,-16.01,0.230
7.58,-15.93,0.230
7.58,-15.85,0.230
7.59,-15.76,0.230
7.60,-15.68,0.230
7.61,-15.60,0.230
7.62,-15.51,0.230
7.63,-15.43,0.230
7.63,-15.35,0.230
7.64,-15.26,0.230
7.65,-15.18,0.231
7.66,-15.10,0.231
7.67,-15.01,0.231
7.68,-14.93,0.231
7.68,-14.84,0.231
7.69,-14.76,0.231
7.70,-14.68,0.231
7.71,-14.59,0.231
7.72,-14.51,0.231
7.73,-14.43,0.231
7.73,-14.35,0.231
7.74,-14.26,0.231
7.75,-14.18,0.231
7.76,-14.09,0.231
7.77,-14.01,0.231
7.78,-13.93,0.231
7.78,-13.84,0.231
7.79,-13.76,0.231
7.80,-13.68,0.232
7.81,-13.59,0.232
7.82,-13.51,0.232
7.83,-13.43,0.232
7.83,-13.34,0.232
7.84,-13.26,0.232
7.85,-13.18,0.232
7.86,-13.09,0.232
7.87,-13.01,0.232
7.88,-12.93,0.232
7.88,-12.84,0.232
7.89,-12.76,0.232
7.90,-12.68,0.232
7.91,-12.59,0.232
7.92,-12.51,0.232
7.93,-12.43,0.232
7.93,-12.34,0.232
7.94,-12.26,0.233
7.95,-12.17,0.233
7.96,-12.09,0.233
7.97,-12.01,0.233
7.98,-11.92,0.233
7.98,-11.84,0.233
7.99,-11.76,0.233
8.00,-11.67,0.233
8.01,-11.59,0.233
8.02,-11.51,0.233
8.03,-11.42,0.233
8.03,-11.34,0.233
8.04,-11.26,0.233
8.05,-11.17,0.233
8.06,-11.09,0.233
8.07,-11.01,0.233
8.08,-10.92,0.234
8.08,-10.84,0.234
8.09,-10.76,0.234
8.10,-10.67,0.234
8.11,-10.59,0.234
8.12,-10.51,0.234
8.13,-10.42,0.234
8.13,-10.34,0.234
8.14,-10.26,0.234
8.15,-10.17,0.234
8.16,-10.09,0.234
8.17,-10.01,0.234
8.18,-9.92,0.234
8.18,-9.84,0.234
8.19,-9.76,0.234
8.20,-9.67,0.234
8.21,-9.59,0.235
8.22,-9.51,0.235
8.23,-9.42,0.235
8.23,-9.34,0.235
8.24,-9.25,0.235
8.25,-9.17,0.235
8.26,-9.09,0.235
8.27,-9.01,0.235
8.28,-8.92,0.235
8.28,-8.84,0.235
8.29,-8.75,0.235
8.30,-8.67,0.235
8.31,-8.59,0.235
8.32,-8.50,0.235
8.33,-8.42,0.235
8.33,-8.34,0.235
8.34,-8.25,0.235
8.35,-8.17,0.236
8.36,-8.09,0.236
8.37,-8.00,0.236
8.38,-7.92,0.236
8.38,-7.84,0.236
8.39,-7.76,0.236
8.40,-7.67,0.236
8.41,-7.59,0.236
8.42,-7.50,0.236
8.43,-7.42,0.236
8.43,-7.34,0.236
8.44,-7.25,0.236
8.45,-7.17,0.236
8.46,-7.09,0.237
8.47,-7.00,0.237
8.48,-6.92,0.237
8.48,-6.84,0.237
8.49,-6.75,0.237
8.50,-6.67,0.237
8.51,-6.59,0.237
8.52,-6.50,0.237
8.53,-6.42,0.237
8.53,-6.33,0.237
8.54,-6.25,0.237
8.55,-6.17,0.237
8.56,-6.09,0.237
8.57,-6.00,0.237
8.58,-5.92,0.237
8.58,-5.84,0.237
8.59,-5.75,0.238
8.60,-5.67,0.238
8.61,-5.59,0.238
8.62,-5.50,0.238
8.63,-5.42,0.238
8.63,-5.33,0.238
8.64,-5.25,0.238
8.65,-5.17,0.238
8.66,-5.08,0.238
8.67,-5.00,0.238
8.68,-4.92,0.238
8.68,-4.83,0.238
8.69,-4.75,0.238
8.70,-4.67,0.238
8.71,-4.58,0.238
8.72,-4.50,0.238
8.73,-4.42,0.239
8.73,-4.33,0.239
8.74,-4.25,0.239
8.75,-4.17,0.239
8.76,-4.08,0.239
8.77,-4.00,0.239
8.78,-3.92,0.239
8.78,-3.83,0.239
8.79,-3.75,0.239
8.80,-3.67,0.239
8.81,-3.58,0.239
8.82,-3.50,0.239
8.83,-3.42,0.239
8.83,-3.33,0.239
8.84,-3.25,0.240
8.85,-3.17,0.240
8.86,-3.08,0.240
8.87,-3.00,0.240
8.88,-2.91,0.240
8.88,-2.83,0.240
8.89,-2.75,0.240
8.90,-2.66,0.240
8.91,-2.58,0.240
8.92,-2.50,0.240
8.93,-2.41,0.240
8.93,-2.33,0.240
8.94,-2.25,0.240
8.95,-2.16,0.241
8.96,-2.08,0.241
8.97,-2.00,0.241
8.98,-1.91,0.241
8.98,-1.83,0.241
8.99,-1.75,0.241
9.00,-1.66,0.242
9.01,-1.58,0.242
9.02,-1.50,0.242
9.03,-1.41,0.243
9.03,-1.33,0.245
9.04,-1.25,0.246
9.05,-1.16,0.247
9.06,-1.08,0.247
9.07,-1.00,0.247
9.08,-0.91,0.247
9.08,-0.83,0.248
9.09,-0.75,0.248
9.10,-0.66,0.248
9.11,-0.58,0.248
9.12,-0.50,0.248
9.13,-0.41,0.248
9.13,-0.33,0.247
9.14,-0.25,0.247
9.15,-0.16,0.247
9.16,-0.08,0.247
9.17,0.00,0.247
9.18,0.09,0.247
9.18,0.17,0.247
9.19,0.26,0.247
9.20,0.34,0.247
9.21,0.42,0.247
9.22,0.51,0.247
9.23,0.59,0.247
9.23,0.67,0.247
9.24,0.76,0.247
9.25,0.84,0.246
9.26,0.92,0.246
9.27,1.01,0.246
9.28,1.09,0.246
9.28,1.17,0.246
9.29,1.26,0.246
9.30,1.34,0.246
9.31,1.42,0.246
9.32,1.51,0.246
9.33,1.59,0.246
9.33,1.67,0.246
9.34,1.76,0.246
9.35,1.84,0.246
9.36,1.92,0.246
9.37,2.01,0.246
9.38,2.09,0.246
9.38,2.18,0.246
9.39,2.26,0.246
9.40,2.34,0.246
9.41,2.43,0.246
9.42,2.51,0.246
9.43,2.59,0.246
9.43,2.67,0.246
9.44,2.76,0.246
9.45,2.84,0.246
9.46,2.93,0.246
9.47,3.01,0.246
9.48,3.09,0.246
9.48,3.18,0.246
9.49,3.26,0.246
9.50,3.34,0.246
9.51,3.43,0.246
9.52,3.51,0.246
9.53,3.59,0.246
9.53,3.68,0.246
9.54,3.76,0.246
9.55,3.84,0.246
9.56,3.93,0.247
9.57,4.01,0.247
9.58,4.10,0.247
9.58,4.18,0.247
9.59,4.26,0.247
9.60,4.35,0.247
9.61,4.43,0.247
9.62,4.51,0.247
9.63,4.59,0.247
9.63,4.68,0.247
9.64,4.76,0.247
9.65,4.85,0.247
9.66,4.93,0.247
9.67,5.01,0.247
9.68,5.10,0.247
9.68,5.18,0.247
9.69,5.26,0.247
9.70,5.35,0.247
9.71,5.43,0.247
9.72,5.51,0.248
9.73,5.60,0.248
9.73,5.68,0.248
9.74,5.76,0.248
9.75,5.85,0.248
9.76,5.93,0.248
9.77,6.01,0.248
9.78,6.10,0.248
9.78,6.18,0.248
9.79,6.27,0.248
9.80,6.35,0.248
9.81,6.43,0.248
9.82,6.52,0.248
9.83,6.60,0.248
9.83,6.68,0.248
9.84,6.77,0.248
9.85,6.85,0.248
9.86,6.93,0.248
9.87,7.02,0.248
9.88,7.10,0.248
9.88,7.18,0.249
9.89,7.27,0.249
9.90,7.35,0.249
9.91,7.43,0.249
9.92,7.52,0.249
9.93,7.60,0.249
9.93,7.68,0.249
9.94,7.76,0.249
9.95,7.85,0.249
9.96,7.93,0.249
9.97,8.02,0.249
9.98,8.10,0.249
9.98,8.18,0.249
9.99,8.27,0.249
10.00,8.35,0.249
10.01,8.43,0.250
10.02,8.52,0.250
10.03,8.60,0.250
10.03,8.68,0.250
10.04,8.77,0.250
10.05,8.85,0.250
10.06,8.93,0.250
10.07,9.02,0.250
10.08,9.10,0.250
10.08,9.18,0.250
10.09,9.27,0.250
10.10,9.35,0.250
10.11,9.44,0.250
10.12,9.52,0.251
10.13,9.60,0.251
10.13,9.69,0.251
10.14,9.77,0.251
10.15,9.85,0.251
10.16,9.94,0.251
10.17,10.02,0.251
10.18,10.10,0.251
10.18,10.19,0.251
10.19,10.27,0.251
10.20,10.35,0.251
10.21,10.44,0.251
10.22,10.52,0.251
10.23,10.60,0.251
10.23,10.69,0.251
10.24,10.77,0.252
10.25,10.85,0.252
10.26,10.94,0.252
10.27,11.02,0.252
10.28,11.10,0.252
10.28,11.19,0.252
10.29,11.27,0.252
10.30,11.35,0.252
10.31,11.44,0.252
10.32,11.52,0.252
10.33,11.60,0.252
10.33,11.69,0.252
10.34,11.77,0.252
10.35,11.85,0.253
10.36,11.94,0.253
10.37,12.02,0.253
10.38,12.10,0.253
10.38,12.19,0.253
10.39,12.27,0.253
10.40,12.35,0.253
10.41,12.44,0.253
10.42,12.52,0.253
10.43,12.61,0.253
10.43,12.69,0.253
10.44,12.77,0.253
10.45,12.86,0.253
10.46,12.94,0.254
10.47,13.02,0.254
10.48,13.11,0.254
10.48,13.19,0.254
10.49,13.27,0.254
10.50,13.36,0.254
10.51,13.44,0.254
10.52,13.52,0.254
10.53,13.61,0.254
10.53,13.69,0.254
10.54,13.77,0.254
10.55,13.86,0.254
10.56,13.94,0.254
10.57,14.02,0.254
10.58,14.11,0.254
10.58,14.19,0.255
10.59,14.27,0.255
10.60,14.36,0.255
10.61,14.44,0.255
10.62,14.52,0.255
10.63,14.61,0.255
10.63,14.69,0.255
10.64,14.77,0.255
10.65,14.86,0.255
10.66,14.94,0.255
10.67,15.02,0.255
10.68,15.11,0.256
10.68,15.19,0.256
10.69,15.28,0.256
10.70,15.36,0.256
10.71,15.44,0.256
10.72,15.52,0.256
10.73,15.61,0.256
10.73,15.69,0.256
10.74,15.78,0.256
10.75,15.86,0.256
10.76,15.94,0.256
10.77,16.03,0.256
10.78,16.11,0.256
10.78,16.19,0.257
10.79,16.28,0.257
10.80,16.36,0.257
10.81,16.44,0.257
10.82,16.53,0.257
10.83,16.61,0.257
10.83,16.69,0.257
10.84,16.78,0.257
10.85,16.86,0.257
10.86,16.94,0.257
10.87,17.03,0.257
10.88,17.11,0.257
10.88,17.19,0.258
10.89,17.28,0.258
10.90,17.36,0.258
10.91,17.44,0.258
10.92,17.53,0.258
10.93,17.61,0.258
10.93,17.69,0.258
10.94,17.78,0.258
10.95,17.86,0.258
10.96,17.94,0.258
10.97,18.03,0.258
10.98,18.11,0.258
10.98,18.19,0.258
10.99,18.28,0.259
11.00,18.36,0.259
11.01,18.44,0.259
11.02,18.53,0.259
11.03,18.61,0.259
11.03,18.69,0.259
11.04,18.78,0.259
11.05,18.86,0.259
11.06,18.94,0.259
11.07,19.03,0.259
11.08,19.11,0.259
11.08,19.19,0.259
11.09,19.28,0.260
11.10,19.36,0.260
11.11,19.44,0.260
11.12,19.53,0.260
11.13,19.61,0.260
11.13,19.70,0.260
11.14,19.78,0.260
11.15,19.86,0.260
11.16,19.95,0.260
11.17,20.03,0.260
11.18,20.11,0.260
11.18,20.20,0.260
11.19,20.28,0.260
11.20,20.36,0.260
11.21,20.45,0.261
11.22,20.53,0.261
11.23,20.61,0.261
11.23,20.70,0.261
11.24,20.78,0.261
11.25,20.86,0.261
11.26,20.95,0.261
11.27,21.03,0.261
11.28,21.11,0.261
11.28,21.20,0.261
11.29,21.28,0.261
11.30,21.36,0.261
11.31,21.45,0.262
11.32,21.53,0.262
11.33,21.61,0.262
11.33,21.70,0.262
11.34,21.78,0.262
11.35,21.86,0.262
11.36,21.95,0.262
11.37,22.03,0.262
11.38,22.12,0.262
11.38,22.20,0.262
11.39,22.28,0.262
11.40,22.37,0.262
11.41,22.45,0.263
11.42,22.53,0.263
11.43,22.62,0.263
11.43,22.70,0.263
11.44,22.78,0.263
11.45,22.87,0.263
11.46,22.95,0.263
11.47,23.03,0.263
11.48,23.12,0.263
11.48,23.20,0.263
11.49,23.28,0.263
11.50,23.37,0.263
11.51,23.45,0.264
11.52,23.53,0.264
11.53,23.62,0.264
11.53,23.70,0.264
11.54,23.78,0.264
11.55,23.87,0.264
11.56,23.95,0.264
11.57,24.03,0.264
11.58,24.12,0.264
11.58,24.20,0.264
11.59,24.28,0.264
11.60,24.37,0.264
11.61,24.45,0.264
11.62,24.53,0.265
11.63,24.62,0.265
11.63,24.70,0.265
11.64,24.78,0.265
11.65,24.87,0.265
11.66,24.95,0.265
11.67,25.04,0.265
11.68,25.12,0.265
11.68,25.20,0.265
11.69,25.28,0.265
11.70,25.37,0.265
11.71,25.45,0.265
11.72,25.53,0.266
11.73,25.62,0.266
11.73,25.70,0.266
11.74,25.79,0.266
11.75,25.87,0.266
11.76,25.95,0.266
11.77,26.04,0.266
11.78,26.12,0.266
11.78,26.20,0.266
11.79,26.29,0.266
11.80,26.37,0.266
11.81,26.45,0.266
11.82,26.54,0.267
11.83,26.62,0.267
11.83,26.70,0.267
11.84,26.79,0.267
11.85,26.87,0.267
11.86,26.95,0.267
11.87,27.04,0.267
11.88,27.12,0.267
11.88,27.20,0.267
11.89,27.29,0.267
11.90,27.37,0.267
11.91,27.45,0.268
11.92,27.54,0.268
11.93,27.62,0.268
11.93,27.70,0.268
11.94,27.79,0.268
11.95,27.87,
11.96,27.95,
11.97,28.04,
11.98,28.12,
11.98,28.20,
11.99,28.29,
12.00,,
12.01,,

[step]
Ramp 10.00 °C/min to -90.00 °C
Time,Temperature,Heat Flow (Normalized)
min,°C,W/g
14.01,30.11,-0.026
14.02,30.11,-0.026
14.03,30.11,-0.026
14.03,30.11,-0.026
14.04,30.11,-0.026
14.05,30.10,-0.026
14.06,30.10,-0.026
14.07,30.09,-0.028
14.08,30.08,-0.032
14.08,30.07,-0.039
14.09,30.06,-0.045
14.10,30.04,-0.052
14.11,30.01,-0.059
14.12,29.99,-0.067
14.13,29.96,-0.076
14.13,29.92,-0.086
14.14,29.88,-0.097
14.15,29.84,-0.107
14.16,29.79,-0.117
14.17,29.74,-0.128
14.18,29.69,-0.140
14.18,29.63,-0.150
14.19,29.58,-0.161
14.20,29.52,-0.171
14.21,29.46,-0.180
14.22,29.39,-0.190
14.23,29.33,-0.199
14.23,29.26,-0.207
14.24,29.20,-0.215
14.25,29.13,-0.220
14.26,29.06,-0.229
14.27,28.99,-0.236
14.28,28.92,-0.240
14.28,28.85,-0.245
14.29,28.78,-0.251
14.30,28.70,-0.254
14.31,28.63,-0.259
14.32,28.56,-0.263
14.33,28.48,-0.269
14.33,28.40,-0.270
14.34,28.33,-0.272
14.35,28.25,-0.276
14.36,28.18,-0.280
14.37,28.10,-0.282
14.38,28.02,-0.285
14.38,27.95,-0.287
14.39,27.87,-0.290
14.40,27.79,-0.290
14.41,27.71,-0.292
14.42,27.63,-0.295
14.43,27.55,-0.296
14.43,27.47,-0.297
14.44,27.40,-0.298
14.45,27.31,-0.300
14.46,27.24,-0.301
14.47,27.16,-0.302
14.48,27.08,-0.303
14.48,27.00,-0.303
14.49,26.91,-0.304
14.50,26.83,-0.305
14.51,26.75,-0.306
14.52,26.67,-0.307
14.53,26.59,-0.308
14.53,26.51,-0.308
14.54,26.43,-0.308
14.55,26.35,-0.309
14.56,26.27,-0.309
14.57,26.19,-0.310
14.58,26.10,-0.310
14.58,26.02,-0.310
14.59,25.94,-0.311
14.60,25.86,-0.311
14.61,25.78,-0.311
14.62,25.70,-0.311
14.63,25.61,-0.312
14.63,25.53,-0.312
14.64,25.45,-0.312
14.65,25.37,-0.312
14.66,25.29,-0.312
14.67,25.20,-0.312
14.68,25.12,-0.313
14.68,25.04,-0.313
14.69,24.96,-0.313
14.70,24.88,-0.313
14.71,24.79,-0.313
14.72,24.71,-0.313
14.73,24.63,-0.313
14.73,24.55,-0.313
14.74,24.46,-0.313
14.75,24.38,-0.313
14.76,24.30,-0.313
14.77,24.22,-0.314
14.78,24.14,-0.314
14.78,24.05,-0.314
14.79,23.97,-0.314
14.80,23.89,-0.314
14.81,23.81,-0.314
14.82,23.72,-0.314
14.83,23.64,-0.314
14.83,23.56,-0.314
14.84,23.47,-0.314
14.85,23.39,-0.314
14.86,23.31,-0.314
14.87,23.23,-0.314
14.88,23.14,-0.314
14.88,23.06,-0.314
14.89,22.98,-0.314
14.90,22.90,-0.314
14.91,22.81,-0.314
14.92,22.73,-0.314
14.93,22.65,-0.314
14.93,22.56,-0.314
14.94,22.48,-0.314
14.95,22.40,-0.314
14.96,22.32,-0.314
14.97,22.23,-0.314
14.98,22.15,-0.314
14.98,22.07,-0.314
14.99,21.98,-0.314
15.00,21.90,-0.314
15.01,21.82,-0.314
15.02,21.74,-0.314
15.03,21.65,-0.314
15.03,21.57,-0.314
15.04,21.49,-0.314
15.05,21.40,-0.314
15.06,21.32,-0.314
15.07,21.24,-0.314
15.08,21.16,-0.314
15.08,21.07,-0.314
15.09,20.99,-0.314
15.10,20.91,-0.314
15.11,20.82,-0.314
15.12,20.74,-0.314
15.13,20.66,-0.314
15.13,20.58,-0.314
15.14,20.49,-0.314
15.15,20.41,-0.314
15.16,20.33,-0.314
15.17,20.24,-0.313
15.18,20.16,-0.313
15.18,20.08,-0.313
15.19,19.99,-0.313
15.20,19.91,-0.313
15.21,19.83,-0.313
15.22,19.74,-0.313
15.23,19.66,-0.313
15.23,19.58,-0.313
15.24,19.49,-0.313
15.25,19.41,-0.313
15.26,19.33,-0.313
15.27,19.25,-0.313
15.28,19.16,-0.313
15.28,19.08,-0.312
15.29,19.00,-0.312
15.30,18.91,-0.312
15.31,18.83,-0.312
15.32,18.75,-0.312
15.33,18.67,-0.312
15.33,18.58,-0.312
15.34,18.50,-0.312
15.35,18.41,-0.312
15.36,18.33,-0.312
15.37,18.25,-0.312
15.38,18.17,-0.311
15.38,18.08,-0.311
15.39,18.00,-0.311
15.40,17.92,-0.311
15.41,17.83,-0.311
15.42,17.75,-0.311
15.43,17.67,-0.311
15.43,17.58,-0.311
15.44,17.50,-0.311
15.45,17.42,-0.311
15.46,17.34,-0.311
15.47,17.25,-0.310
15.48,17.17,-0.310
15.48,17.09,-0.310
15.49,17.00,-0.310
15.50,16.92,-0.310
15.51,16.84,-0.310
15.52,16.75,-0.309
15.53,16.67,-0.309
15.53,16.59,-0.309
15.54,16.50,-0.309
15.55,16.42,-0.309
15.56,16.34,-0.309
15.57,16.26,-0.309
15.58,16.17,-0.309
15.58,16.09,-0.309
15.59,16.00,-0.309
15.60,15.92,-0.309
15.61,15.84,-0.308
15.62,15.76,-0.308
15.63,15.67,-0.308
15.63,15.59,-0.308
15.64,15.51,-0.308
15.65,15.42,-0.308
15.66,15.34,-0.308
15.67,15.26,-0.308
15.68,15.17,-0.307
15.68,15.09,-0.307
15.69,15.01,-0.307
15.70,14.93,-0.307
15.71,14.84,-0.307
15.72,14.76,-0.307
15.73,14.68,-0.307
15.73,14.59,-0.307
15.74,14.51,-0.307
15.75,14.43,-0.306
15.76,14.34,-0.306
15.77,14.26,-0.306
15.78,14.18,-0.306
15.78,14.09,-0.306
15.79,14.01,-0.306
15.80,13.93,-0.306
15.81,13.84,-0.306
15.82,13.76,-0.305
15.83,13.68,-0.305
15.83,13.60,-0.305
15.84,13.51,-0.305
15.85,13.43,-0.305
15.86,13.34,-0.305
15.87,13.26,-0.305
15.88,13.18,-0.305
15.88,13.10,-0.305
15.89,13.01,-0.304
15.90,12.93,-0.304
15.91,12.85,-0.304
15.92,12.76,-0.304
15.93,12.68,-0.304
15.93,12.60,-0.304
15.94,12.51,-0.304
15.95,12.43,-0.304
15.96,12.35,-0.304
15.97,12.26,-0.304
15.98,12.18,-0.303
15.98,12.10,-0.303
15.99,12.01,-0.303
16.00,11.93,-0.303
16.01,11.85,-0.303
16.02,11.76,-0.303
16.03,11.68,-0.303
16.03,11.60,-0.303
16.04,11.51,-0.303
16.05,11.43,-0.302
16.06,11.35,-0.302
16.07,11.26,-0.302
16.08,11.18,-0.302
16.08,11.10,-0.302
16.09,11.02,-0.302
16.10,10.93,-0.302
16.11,10.85,-0.302
16.12,10.77,-0.302
16.13,10.68,-0.302
16.13,10.60,-0.301
16.14,10.52,-0.301
16.15,10.43,-0.301
16.16,10.35,-0.301
16.17,10.27,-0.301
16.18,10.18,-0.301
16.18,10.10,-0.301
16.19,10.02,-0.301
16.20,9.93,-0.301
16.21,9.85,-0.300
16.22,9.77,-0.300
16.23,9.68,-0.300
16.23,9.60,-0.300
16.24,9.52,-0.300
16.25,9.43,-0.300
16.26,9.35,-0.300
16.27,9.27,-0.300
16.28,9.19,-0.299
16.28,9.10,-0.299
16.29,9.02,-0.299
16.30,8.93,-0.299
16.31,8.85,-0.299
16.32,8.77,-0.299
16.33,8.69,-0.299
16.33,8.60,-0.299
16.34,8.52,-0.298
16.35,8.44,-0.298
16.36,8.35,-0.298
16.37,8.27,-0.298
16.38,8.19,-0.298
16.38,8.10,-0.298
16.39,8.02,-0.298
16.40,7.94,-0.297
16.41,7.85,-0.297
16.42,7.77,-0.297
16.43,7.69,-0.297
16.43,7.61,-0.297
16.44,7.52,-0.297
16.45,7.44,-0.297
16.46,7.36,-0.296
16.47,7.27,-0.296
16.48,7.19,-0.296
16.48,7.11,-0.296
16.49,7.02,-0.296
16.50,6.94,-0.296
16.51,6.86,-0.296
16.52,6.77,-0.296
16.53,6.69,-0.296
16.53,6.61,-0.296
16.54,6.52,-0.295
16.55,6.44,-0.295
16.56,6.36,-0.295
16.57,6.27,-0.295
16.58,6.19,-0.295
16.58,6.11,-0.295
16.59,6.03,-0.295
16.60,5.94,-0.295
16.61,5.86,-0.295
16.62,5.78,-0.295
16.63,5.69,-0.295
16.63,5.61,-0.294
16.64,5.53,-0.294
16.65,5.44,-0.294
16.66,5.36,-0.294
16.67,5.28,-0.294
16.68,5.19,-0.294
16.68,5.11,-0.294
16.69,5.03,-0.294
16.70,4.94,-0.294
16.71,4.86,-0.294
16.72,4.78,-0.294
16.73,4.70,-0.293
16.73,4.61,-0.293
16.74,4.53,-0.293
16.75,4.45,-0.293
16.76,4.36,-0.293
16.77,4.28,-0.293
16.78,4.20,-0.293
16.78,4.11,-0.293
16.79,4.03,-0.293
16.80,3.95,-0.293
16.81,3.86,-0.292
16.82,3.78,-0.292
16.83,3.70,-0.292
16.83,3.61,-0.292
16.84,3.53,-0.292
16.85,3.45,-0.292
16.86,3.36,-0.292
16.87,3.28,-0.292
16.88,3.20,-0.292
16.88,3.11,-0.291
16.89,3.03,-0.291
16.90,2.95,-0.291
16.91,2.86,-0.291
16.92,2.78,-0.291
16.93,2.70,-0.291
16.93,2.61,-0.291
16.94,2.53,-0.291
16.95,2.45,-0.291
16.96,2.36,-0.291
16.97,2.28,-0.291
16.98,2.20,-0.290
16.98,2.11,-0.290
16.99,2.03,-0.290
17.00,1.95,-0.290
17.01,1.86,-0.290
17.02,1.78,-0.290
17.03,1.70,-0.290
17.03,1.61,-0.290
17.04,1.53,-0.290
17.05,1.45,-0.289
17.06,1.37,-0.289
17.07,1.28,-0.289
17.08,1.20,-0.289
17.08,1.11,-0.289
17.09,1.03,-0.289
17.10,0.95,-0.289
17.11,0.87,-0.289
17.12,0.78,-0.289
17.13,0.70,-0.289
17.13,0.62,-0.288
17.14,0.53,-0.288
17.15,0.45,-0.288
[...]
73.01,2.66,-0.291
73.02,2.60,-0.291
73.03,2.53,-0.291
73.04,2.46,-0.291
73.04,2.39,-0.291
73.05,2.33,-0.291
73.05,2.26,-0.290
73.06,2.20,-0.290
73.07,2.13,-0.290
73.08,2.06,-0.290
73.08,2.00,-0.290
73.09,1.93,-0.290
73.10,1.86,-0.290
73.10,1.79,-0.290
73.11,1.73,-0.290
73.11,1.66,-0.290
73.12,1.60,-0.290
73.13,1.53,-0.290
73.14,1.46,-0.290
73.14,1.40,-0.289
73.15,1.33,-0.289
73.15,1.26,-0.289
73.16,1.20,-0.289
73.17,1.13,-0.289
73.18,1.06,-0.289
73.18,1.00,-0.289
73.19,0.93,-0.289
73.20,0.86,-0.289
73.20,0.80,-0.289
73.21,0.73,-0.289
73.21,0.66,-0.289
73.22,0.60,-0.289
73.23,0.53,-0.289
73.24,0.46,-0.288
73.24,0.39,-0.288
73.25,0.33,-0.288
73.25,0.26,-0.288
73.26,0.20,-0.288
73.27,0.13,-0.288
73.28,0.06,-0.288
73.28,-0.01,-0.288
73.29,-0.07,-0.288
73.30,-0.14,-0.288
73.30,-0.21,-0.288
73.31,-0.27,-0.288
73.31,-0.34,-0.288
73.32,-0.40,-0.288
73.33,-0.47,-0.288
73.34,-0.54,-0.287
73.34,-0.61,-0.287
73.35,-0.67,-0.287
73.35,-0.74,-0.287
73.36,-0.81,-0.287
73.37,-0.87,-0.287
73.38,-0.94,-0.287
73.38,-1.01,-0.287
73.39,-1.07,-0.287
73.40,-1.14,-0.287
73.40,-1.21,-0.287
73.41,-1.27,-0.287
73.41,-1.34,-0.287
73.42,-1.40,-0.287
73.43,-1.47,-0.286
73.44,-1.54,-0.286
73.44,-1.60,-0.286
73.45,-1.67,-0.286
73.45,-1.74,-0.286
73.46,-1.80,-0.286
73.47,-1.87,-0.286
73.48,-1.94,-0.286
73.48,-2.01,-0.286
73.49,-2.07,-0.286
73.50,-2.14,-0.286
73.50,-2.20,-0.286
73.51,-2.27,-0.286
73.51,-2.34,-0.285
73.52,-2.41,-0.285
73.53,-2.47,-0.285
73.54,-2.54,-0.285
73.54,-2.61,-0.285
73.55,-2.67,-0.285
73.55,-2.74,-0.285
73.56,-2.81,-0.285
73.57,-2.87,-0.285
73.58,-2.94,-0.285
73.58,-3.01,-0.285
73.59,-3.07,-0.285
73.60,-3.14,-0.284
73.60,-3.21,-0.284
73.61,-3.27,-0.284
73.61,-3.34,-0.284
73.62,-3.41,-0.284
73.63,-3.47,-0.284
73.64,-3.54,-0.284
73.64,-3.61,-0.284
73.65,-3.67,-0.284
73.65,-3.74,-0.284
73.66,-3.81,-0.284
73.67,-3.87,-0.284
73.68,-3.94,-0.284
73.68,-4.01,-0.284
73.69,-4.07,-0.284
73.70,-4.14,-0.283
73.70,-4.21,-0.283
73.71,-4.28,-0.283
73.71,-4.34,-0.283
73.72,-4.41,-0.283
73.73,-4.47,-0.283
73.74,-4.54,-0.283
73.74,-4.61,-0.283
73.75,-4.67,-0.283
73.75,-4.74,-0.283
73.76,-4.81,-0.283
73.77,-4.87,-0.283
73.78,-4.94,-0.283
73.78,-5.01,-0.283
73.79,-5.08,-0.283
73.80,-5.14,-0.282
73.80,-5.21,-0.282
73.81,-5.28,-0.282
73.81,-5.34,-0.282
73.82,-5.41,-0.282
73.83,-5.48,-0.282
73.84,-5.54,-0.282
73.84,-5.61,-0.282
73.85,-5.68,-0.282
73.85,-5.74,-0.282
73.86,-5.81,-0.281
73.87,-5.88,-0.281
73.88,-5.94,-0.281
73.88,-6.01,-0.281
73.89,-6.08,-0.281
73.90,-6.14,-0.281
73.90,-6.21,-0.281
73.91,-6.28,-0.281
73.91,-6.34,-0.281
73.92,-6.41,-0.281
73.93,-6.48,-0.281
73.94,-6.54,-0.281
73.94,-6.61,-0.281
73.95,-6.68,-0.281
73.95,-6.74,-0.280
73.96,-6.81,-0.280
73.97,-6.88,-0.280
73.98,-6.94,-0.280
73.98,-7.01,-0.280
73.99,-7.08,-0.280
74.00,-7.14,-0.280
74.00,-7.21,-0.280
74.01,-7.28,-0.280
74.01,-7.35,-0.280
74.02,-7.41,-0.280
74.03,-7.48,-0.280
74.04,-7.55,-0.280
74.04,-7.61,-0.280
74.05,-7.68,-0.280
74.05,-7.74,-0.279
74.06,-7.81,-0.279
74.07,-7.88,-0.279
74.08,-7.95,-0.279
74.08,-8.01,-0.279
74.09,-8.08,-0.279
74.10,-8.15,-0.279
74.10,-8.21,-0.279
74.11,-8.28,-0.279
74.11,-8.35,-0.279
74.12,-8.41,-0.279
74.13,-8.48,-0.279
74.14,-8.55,-0.278
74.14,-8.61,-0.278
74.15,-8.68,-0.278
74.15,-8.75,-0.278
74.16,-8.81,-0.278
74.17,-8.88,-0.278
74.18,-8.95,-0.278
74.18,-9.01,-0.278
74.19,-9.08,-0.278
74.20,-9.15,-0.278
74.20,-9.22,-0.278
74.21,-9.28,-0.278
74.21,-9.35,-0.278
74.22,-9.42,-0.278
74.23,-9.48,-0.278
74.24,-9.55,-0.277
74.24,-9.62,-0.277
74.25,-9.68,-0.277
74.25,-9.75,-0.277
74.26,-9.82,-0.277
74.27,-9.88,-0.277
74.28,-9.95,-0.277
74.28,-10.02,-0.277
74.29,-10.08,-0.277
74.30,-10.15,-0.277
74.30,-10.22,-0.277
74.31,-10.28,-0.276
74.31,-10.35,-0.276
74.32,-10.42,-0.276
74.33,-10.48,-0.276
74.34,-10.55,-0.276
74.34,-10.62,-0.276
74.35,-10.68,-0.276
74.35,-10.75,-0.276
74.36,-10.82,-0.276
74.37,-10.88,-0.276
74.38,-10.95,-0.276
74.38,-11.02,-0.276
74.39,-11.08,-0.276
74.40,-11.15,-0.276
74.40,-11.22,-0.275
74.41,-11.28,-0.275
74.41,-11.35,-0.275
74.42,-11.42,-0.275
74.43,-11.48,-0.275
74.44,-11.55,-0.275
74.44,-11.62,-0.275
74.45,-11.68,-0.275
74.45,-11.75,-0.275
74.46,-11.82,-0.275
74.47,-11.88,-0.275
74.48,-11.95,-0.274
74.48,-12.02,-0.274
74.49,-12.08,-0.274
74.50,-12.15,-0.274
74.50,-12.22,-0.274
74.51,-12.29,-0.274
74.51,-12.35,-0.274
74.52,-12.42,-0.274
74.53,-12.49,-0.274
74.54,-12.55,-0.274
74.54,-12.62,-0.274
74.55,-12.69,-0.274
74.55,-12.75,-0.274
74.56,-12.82,-0.274
74.57,-12.88,-0.274
74.58,-12.95,-0.273
74.58,-13.02,-0.273
74.59,-13.08,-0.273
74.60,-13.15,-0.273
74.60,-13.22,-0.273
74.61,-13.29,-0.273
74.61,-13.35,-0.273
74.62,-13.42,-0.273
74.63,-13.49,-0.273
74.64,-13.55,-0.273
74.64,-13.62,-0.273
74.65,-13.69,-0.273
74.65,-13.75,-0.272
74.66,-13.82,-0.272
74.67,-13.89,-0.272
74.68,-13.95,-0.272
74.68,-14.02,-0.272
74.69,-14.09,-0.272
74.70,-14.15,-0.272
74.70,-14.22,-0.272
74.71,-14.29,-0.272
74.71,-14.35,-0.272
74.72,-14.42,-0.272
74.73,-14.49,-0.272
74.74,-14.55,-0.272
74.74,-14.62,-0.272
74.75,-14.69,-0.271
74.75,-14.75,-0.271
74.76,-14.82,-0.271
74.77,-14.89,-0.271
74.78,-14.95,-0.271
74.78,-15.02,-0.271
74.79,-15.09,-0.271
74.80,-15.15,-0.271
74.80,-15.22,-0.271
74.81,-15.29,-0.271
74.81,-15.35,-0.271
74.82,-15.42,-0.271
74.83,-15.49,-0.271
74.84,-15.56,-0.271
74.84,-15.62,-0.271
74.85,-15.69,-0.271
74.85,-15.75,-0.270
74.86,-15.82,-0.270
74.87,-15.89,-0.270
74.88,-15.96,-0.270
74.88,-16.02,-0.270
74.89,-16.09,-0.270
74.90,-16.16,-0.270
74.90,-16.22,-0.270
74.91,-16.29,-0.270
74.91,-16.36,-0.270
74.92,-16.42,-0.270
74.93,-16.49,-0.270
74.94,-16.56,-0.270
74.94,-16.62,-0.269
74.95,-16.69,-0.269
74.95,-16.76,-0.269
74.96,-16.82,-0.269
74.97,-16.89,-0.269
74.98,-16.96,-0.269
74.98,-17.02,-0.269
74.99,-17.09,-0.269
75.00,-17.16,-0.269
75.00,-17.22,-0.269
75.01,-17.29,-0.269
75.01,-17.36,-0.269
75.02,-17.42,-0.268
75.03,-17.49,-0.268
75.04,-17.56,-0.268
75.04,-17.62,-0.268
75.05,-17.69,-0.268
75.05,-17.76,-0.268
75.06,-17.82,-0.268
75.07,-17.89,-0.268
75.08,-17.96,-0.268
75.08,-18.02,-0.268
75.09,-18.09,-0.268
75.10,-18.16,-0.268
75.10,-18.22,-0.268
75.11,-18.29,-0.267
75.11,-18.36,-0.267
75.12,-18.42,-0.267
75.13,-18.49,-0.267
75.14,-18.56,-0.267
75.14,-18.62,-0.267
75.15,-18.69,-0.267
75.15,-18.76,-0.266
75.16,-18.82,-0.266
75.17,-18.89,-0.266
75.18,-18.96,-0.266
75.18,-19.02,-0.266
75.19,-19.09,-0.266
75.20,-19.16,-0.266
75.20,-19.22,-0.266
75.21,-19.29,-0.266
75.21,-19.36,-0.266
75.22,-19.42,-0.266
75.23,-19.49,-0.266
75.24,-19.56,-0.266
75.24,-19.62,-0.266
75.25,-19.69,-0.266
75.25,-19.76,-0.265
75.26,-19.82,-0.265
75.27,-19.89,-0.265
75.28,-19.96,-0.265
75.28,-20.02,-0.265
75.29,-20.09,-0.265
75.30,-20.16,-0.265
75.30,-20.22,-0.265
75.31,-20.29,-0.265
75.31,-20.36,-0.265
75.32,-20.43,-0.265
75.33,-20.49,-0.265
75.34,-20.56,-0.265
75.34,-20.62,-0.265
75.35,-20.69,-0.265
75.35,-20.76,-0.264
75.36,-20.82,-0.264
75.37,-20.89,-0.264
75.38,-20.96,-0.264
75.38,-21.03,-0.264
75.39,-21.09,-0.264
75.40,-21.16,-0.264
75.40,-21.22,-0.264
75.41,-21.29,-0.264
75.41,-21.36,-0.264
75.42,-21.43,-0.264
75.43,-21.49,-0.264
75.44,-21.56,-0.264
75.44,-21.62,-0.264
75.45,-21.69,-0.263
75.45,-21.76,-0.263
75.46,-21.83,-0.263
75.47,-21.89,-0.263
75.48,-21.96,-0.263
75.48,-22.03,-0.263
75.49,-22.09,-0.263
75.50,-22.16,-0.263
75.50,-22.23,-0.263
75.51,-22.29,-0.263
75.51,-22.36,-0.263
75.52,-22.43,-0.263
75.53,-22.49,-0.263
75.54,-22.56,-0.263
75.54,-22.62,-0.263
75.55,-22.69,-0.262
75.55,-22.76,-0.262
75.56,-22.82,-0.262
75.57,-22.89,-0.262
75.58,-22.96,-0.262
75.58,-23.03,-0.262
75.59,-23.09,-0.262
75.60,-23.16,-0.262
75.60,-23.23,-0.262
75.61,-23.29,-0.262
75.61,-23.36,-0.262
75.62,-23.43,-0.262
75.63,-23.49,-0.262
75.64,-23.56,-0.262
75.64,-23.63,-0.261
75.65,-23.69,-0.261
75.65,-23.76,-0.261
75.66,-23.83,-0.261
75.67,-23.89,-0.261
75.68,-23.96,-0.261
75.68,-24.03,-0.261
75.69,-24.09,-0.261
75.70,-24.16,-0.261
75.70,-24.23,-0.261
75.71,-24.29,-0.261
75.71,-24.36,-0.260
75.72,-24.43,-0.260
75.73,-24.49,-0.260
75.74,-24.56,-0.260
75.74,-24.63,-0.260
75.75,-24.69,-0.260
75.75,-24.76,-0.260
75.76,-24.83,-0.260
75.77,-24.89,-0.260
75.78,-24.96,-0.260
75.78,-25.03,-0.260
75.79,-25.09,-0.259
75.80,-25.16,-0.259
75.80,-25.23,-0.259
75.81,-25.29,-0.259
75.81,-25.36,-0.259
75.82,-25.43,-0.259
75.83,-25.49,-0.259
75.84,-25.56,-0.259
75.84,-25.63,-0.259
75.85,-25.69,-0.259
75.85,-25.76,-0.259
75.86,-25.83,-0.259
75.87,-25.89,-0.259
75.88,-25.96,-0.259
75.88,-26.03,-0.259
75.89,-26.09,-0.259
75.90,-26.16,-0.259
75.90,-26.23,-0.258
75.91,-26.30,-0.258
75.91,-26.36,-0.258
75.92,-26.43,-0.258
75.93,-26.49,-0.258
75.94,-26.56,-0.258
75.94,-26.63,-0.258
75.95,-26.69,-0.258
75.95,-26.76,-0.258
75.96,-26.83,-0.258
75.97,-26.89,-0.258
75.98,-26.96,-0.258
75.98,-27.03,-0.258
75.99,-27.09,-0.258
76.00,-27.16,-0.257
76.00,-27.23,-0.257
76.01,-27.29,-0.257
76.01,-27.36,-0.257
76.02,-27.43,-0.256
76.03,-27.50,-0.256
76.04,-27.56,-0.256
76.04,-27.63,-0.256
76.05,-27.70,-0.256
76.05,-27.76,-0.256
76.06,-27.83,-0.256
76.07,-27.89,-0.256
76.08,-27.96,-0.256
76.08,-28.03,-0.256
76.09,-28.09,-0.256
76.10,-28.16,-0.256
76.10,-28.23,-0.256
76.11,-28.30,-0.256
76.11,-28.36,-0.256
76.12,-28.43,-0.256
76.13,-28.49,-0.256
76.14,-28.56,-0.256
76.14,-28.63,-0.256
76.15,-28.70,-0.255
76.15,-28.76,-0.255
76.16,-28.83,-0.255
76.17,-28.89,-0.255
76.18,-28.96,-0.255
76.18,-29.03,-0.255
76.19,-29.09,-0.255
76.20,-29.16,-0.255
76.20,-29.23,-0.255
76.21,-29.29,-0.255
76.21,-29.36,-0.255
76.22,-29.43,-0.255
76.23,-29.50,-0.255
76.24,-29.56,-0.255
76.24,-29.63,-0.254
76.25,-29.70,-0.254
76.25,-29.76,-0.254
76.26,-29.83,-0.254
76.27,-29.90,-0.254
76.28,-29.96,-0.254
76.28,-30.03,-0.254
76.29,-30.10,-0.254
76.30,-30.16,-0.254
76.30,-30.23,-0.254
76.31,-30.30,-0.254
76.31,-30.36,-0.254
76.32,-30.43,-0.254
76.33,-30.50,-0.254
76.34,-30.56,-0.254
76.34,-30.63,-0.254
76.35,-30.69,-0.253
76.35,-30.76,-0.253
76.36,-30.83,-0.253
76.37,-30.89,-0.253
76.38,-30.96,-0.253
76.38,-31.03,-0.253
76.39,-31.10,-0.253
76.40,-31.16,-0.253
76.40,-31.23,-0.253
76.41,-31.30,-0.253
76.41,-31.36,-0.253
76.42,-31.43,-0.253
76.43,-31.50,-0.253
76.44,-31.56,-0.253
76.44,-31.63,-0.253
76.45,-31.70,-0.253
76.45,-31.76,-0.253
76.46,-31.83,-0.252
76.47,-31.90,-0.252
76.48,-31.96,-0.252
76.48,-32.03,-0.252
76.49,-32.09,-0.252
76.50,-32.16,-0.252
76.50,-32.23,-0.252
76.51,-32.30,-0.252
76.51,-32.36,-0.252
76.52,-32.43,-0.252
76.53,-32.49,-0.252
76.54,-32.56,-0.252
76.54,-32.63,-0.252
76.55,-32.69,-0.251
76.55,-32.76,-0.251
76.56,-32.83,-0.251
76.57,-32.90,-0.251
76.58,-32.96,-0.251
76.58,-33.03,-0.251
76.59,-33.10,-0.251
76.60,-33.16,-0.251
76.60,-33.23,-0.251
76.61,-33.30,-0.251
76.61,-33.36,-0.251
76.62,-33.43,-0.251
76.63,-33.50,-0.250
76.64,-33.56,-0.250
76.64,-33.63,-0.250
76.65,-33.70,-0.250
76.65,-33.76,-0.250
76.66,-33.83,-0.250
76.67,-33.89,-0.250
76.68,-33.96,-0.250
76.68,-34.03,-0.250
76.69,-34.10,-0.250
76.70,-34.16,-0.250
76.70,-34.23,-0.250
76.71,-34.29,-0.250
76.71,-34.36,-0.250
76.72,-34.43,-0.250
76.73,-34.49,-0.249
76.74,-34.56,-0.249
76.74,-34.63,-0.249
76.75,-34.70,-0.249
76.75,-34.76,-0.249
76.76,-34.83,-0.249
76.77,-34.90,-0.249
76.78,-34.96,-0.249
76.78,-35.03,-0.249
76.79,-35.09,-0.249
76.80,-35.16,-0.249
76.80,-35.23,-0.248
76.81,-35.30,-0.248
76.81,-35.36,-0.248
76.82,-35.43,-0.248
76.83,-35.50,-0.248
76.84,-35.56,-0.248
76.84,-35.63,-0.248
76.85,-35.70,-0.248
76.85,-35.76,-0.248
76.86,-35.83,-0.248
76.87,-35.90,-0.248
76.88,-35.96,-0.248
76.88,-36.03,-0.248
76.89,-36.10,-0.248
76.90,-36.16,-0.248
76.90,-36.23,-0.248
76.91,-36.30,-0.248
76.91,-36.36,-0.247
76.92,-36.43,-0.247
76.93,-36.50,-0.247
76.94,-36.56,-0.247
76.94,-36.63,-0.247
76.95,-36.70,-0.247
76.95,-36.76,-0.247
76.96,-36.83,-0.247
76.97,-36.90,-0.247
76.98,-36.96,-0.247
76.98,-37.03,-0.247
76.99,-37.09,-0.247
77.00,-37.16,-0.247
77.00,-37.23,-0.247
77.01,-37.30,-0.247
77.01,-37.36,-0.247
77.02,-37.43,-0.246
77.03,-37.50,-0.246
77.04,-37.56,-0.246
77.04,-37.63,-0.246
77.05,-37.70,-0.246
77.05,-37.76,-0.246
77.06,-37.83,-0.246
77.07,-37.90,-0.246
77.08,-37.96,-0.246
77.08,-38.03,-0.246
77.09,-38.10,-0.246
77.10,-38.16,-0.246
77.10,-38.23,-0.246
77.11,-38.30,-0.246
77.11,-38.36,-0.245
77.12,-38.43,-0.245
77.13,-38.50,-0.245
77.14,-38.56,-0.245
77.14,-38.63,-0.245
77.15,-38.70,-0.245
77.15,-38.76,-0.245
77.16,-38.83,-0.245
77.17,-38.90,-0.245
77.18,-38.96,-0.245
77.18,-39.03,-0.245
77.19,-39.10,-0.245
77.20,-39.16,-0.245
77.20,-39.23,-0.245
77.21,-39.30,-0.245
77.21,-39.36,-0.245
77.22,-39.43,-0.244
77.23,-39.50,-0.244
77.24,-39.56,-0.244
77.24,-39.63,-0.244
77.25,-39.70,-0.244
77.25,-39.76,-0.244
77.26,-39.83,-0.244
77.27,-39.89,-0.244
77.28,-39.96,-0.244
77.28,-40.03,-0.244
77.29,-40.10,-0.244
77.30,-40.16,-0.244
77.30,-40.23,-0.244
77.31,-40.30,-0.244
77.31,-40.36,-0.244
77.32,-40.43,-0.244
77.33,-40.50,-0.244
77.34,-40.56,-0.244
77.34,-40.63,-0.244
77.35,-40.70,-0.244
77.35,-40.76,-0.244
77.36,-40.83,-0.244
77.37,-40.90,-0.244
77.38,-40.96,-0.244
77.38,-41.03,-0.244
77.39,-41.09,-0.244
77.40,-41.16,-0.244
77.40,-41.23,-0.244
77.41,-41.30,-0.244
77.41,-41.36,-0.244
77.42,-41.43,-0.244
77.43,-41.50,-0.244
77.44,-41.56,-0.244
77.44,-41.63,-0.243
77.45,-41.70,-0.243
77.45,-41.76,-0.243
77.46,-41.83,-0.243
77.47,-41.90,-0.243
77.48,-41.96,-0.243
77.48,-42.03,-0.243
77.49,-42.10,-0.243
77.50,-42.16,-0.243
77.50,-42.23,-0.242
77.51,-42.30,-0.242
77.51,-42.36,-0.242
77.52,-42.43,-0.242
77.53,-42.50,-0.242
77.54,-42.56,-0.242
77.54,-42.63,-0.242
77.55,-42.70,-0.241
77.55,-42.76,-0.241
77.56,-42.83,-0.241
77.57,-42.90,-0.241
77.58,-42.96,-0.241
77.58,-43.03,-0.241
77.59,-43.10,-0.241
77.60,-43.16,-0.241
77.60,-43.23,-0.241
77.61,-43.30,-0.241
77.61,-43.36,-0.241
77.62,-43.43,-0.241
77.63,-43.50,-0.241
77.64,-43.56,-0.240
77.64,-43.63,-0.240
77.65,-43.70,-0.240
77.65,-43.76,-0.240
77.66,-43.83,-0.240
77.67,-43.90,-0.240
77.68,-43.96,-0.240
77.68,-44.03,-0.240
77.69,-44.10,-0.240
77.70,-44.16,-0.240
77.70,-44.23,-0.240
77.71,-44.30,-0.240
77.71,-44.36,-0.239
77.72,-44.43,-0.239
77.73,-44.50,-0.239
77.74,-44.56,-0.239
77.74,-44.63,-0.239
77.75,-44.70,-0.239
77.75,-44.76,-0.239
77.76,-44.83,-0.239
77.77,-44.90,-0.239
77.78,-44.96,-0.239
77.78,-45.03,-0.239
77.79,-45.10,-0.239
77.80,-45.16,-0.239
77.80,-45.23,-0.239
77.81,-45.30,-0.238
77.81,-45.36,-0.238
77.82,-45.43,-0.238
77.83,-45.50,-0.238
77.84,-45.56,-0.238
77.84,-45.63,-0.238
77.85,-45.70,-0.238
77.85,-45.76,-0.238
77.86,-45.83,-0.238
77.87,-45.90,-0.238
77.88,-45.96,-0.238
77.88,-46.03,-0.238
77.89,-46.10,-0.237
77.90,-46.16,-0.237
77.90,-46.23,-0.237
77.91,-46.30,-0.237
77.91,-46.36,-0.237
77.92,-46.43,-0.237
77.93,-46.50,-0.237
77.94,-46.57,-0.237
77.94,-46.63,-0.237
77.95,-46.70,-0.237
77.95,-46.76,-0.237
77.96,-46.83,-0.237
77.97,-46.90,-0.237
77.98,-46.96,-0.236
77.98,-47.03,-0.236
77.99,-47.10,-0.236
78.00,-47.16,-0.236
78.00,-47.23,-0.236
78.01,-47.30,-0.236
78.01,-47.36,-0.236
78.02,-47.43,-0.236
78.03,-47.50,-0.236
78.04,-47.56,-0.236
78.04,-47.63,-0.236
78.05,-47.70,-0.235
78.05,-47.76,-0.235
78.06,-47.83,-0.235
78.07,-47.90,-0.235
78.08,-47.96,-0.235
78.08,-48.03,-0.235
78.09,-48.10,-0.235
78.10,-48.16,-0.235
78.10,-48.23,-0.235
78.11,-48.30,-0.235
78.11,-48.36,-0.235
78.12,-48.43,-0.235
78.13,-48.50,-0.235
78.14,-48.56,-0.235
78.14,-48.63,-0.235
78.15,-48.70,-0.235
78.15,-48.76,-0.235
78.16,-48.83,-0.234
78.17,-48.90,-0.234
78.18,-48.96,-0.234
78.18,-49.03,-0.234
78.19,-49.10,-0.234
78.20,-49.16,-0.234
78.20,-49.23,-0.234
78.21,-49.30,-0.234
78.21,-49.36,-0.234
78.22,-49.43,-0.234
78.23,-49.50,-0.234
78.24,-49.56,-0.234
78.24,-49.63,-0.234
78.25,-49.70,-0.234
78.25,-49.76,-0.234
78.26,-49.83,-0.233
78.27,-49.90,-0.233
78.28,-49.96,-0.233
78.28,-50.03,-0.233
78.29,-50.10,-0.233
78.30,-50.16,-0.233
78.30,-50.23,-0.233
78.31,-50.30,-0.233
78.31,-50.36,-0.233
78.32,-50.43,-0.233
78.33,-50.50,-0.233
78.34,-50.56,-0.233
78.34,-50.63,-0.233
78.35,-50.70,-0.233
78.35,-50.76,-0.233
78.36,-50.83,-0.233
78.37,-50.90,-0.233
78.38,-50.96,-0.232
78.38,-51.03,-0.232
78.39,-51.10,-0.232
78.40,-51.16,-0.232
78.40,-51.23,-0.232
78.41,-51.30,-0.232
78.41,-51.36,-0.232
78.42,-51.43,-0.232
78.43,-51.50,-0.232
78.44,-51.56,-0.232
78.44,-51.63,-0.232
78.45,-51.70,-0.232
78.45,-51.76,-0.232
78.46,-51.83,-0.232
78.47,-51.90,-0.232
78.48,-51.96,-0.231
78.48,-52.03,-0.231
78.49,-52.10,-0.231
78.50,-52.16,-0.231
78.50,-52.23,-0.231
78.51,-52.30,-0.231
78.51,-52.36,-0.231
78.52,-52.43,-0.231
78.53,-52.50,-0.231
78.54,-52.56,-0.231
78.54,-52.63,-0.231
78.55,-52.70,-0.230
78.55,-52.76,-0.230
78.56,-52.83,-0.230
78.57,-52.90,-0.230
78.58,-52.97,-0.230
78.58,-53.03,-0.230
78.59,-53.10,-0.230
78.60,-53.16,-0.230
78.60,-53.23,-0.230
78.61,-53.30,-0.230
78.61,-53.36,-0.230
78.62,-53.43,-0.230
78.63,-53.50,-0.230
78.64,-53.56,-0.230
78.64,-53.63,-0.230
78.65,-53.70,-0.230
78.65,-53.77,-0.230
78.66,-53.83,-0.229
78.67,-53.90,-0.229
78.68,-53.96,-0.229
78.68,-54.03,-0.229
78.69,-54.10,-0.229
78.70,-54.16,-0.229
78.70,-54.23,-0.229
78.71,-54.30,-0.229
78.71,-54.36,-0.229
78.72,-54.43,-0.229
78.73,-54.50,-0.229
78.74,-54.56,-0.229
78.74,-54.63,-0.229
78.75,-54.70,-0.228
78.75,-54.76,-0.228
78.76,-54.83,-0.228
78.77,-54.90,-0.228
78.78,-54.96,-0.228
78.78,-55.03,-0.228
78.79,-55.10,-0.228
78.80,-55.16,-0.228
78.80,-55.23,-0.228
78.81,-55.30,-0.228
78.81,-55.36,-0.228
78.82,-55.43,-0.228
78.83,-55.50,-0.228
78.84,-55.56,-0.228
78.84,-55.63,-0.227
78.85,-55.70,-0.227
78.85,-55.76,-0.227
78.86,-55.83,-0.227
78.87,-55.90,-0.227
78.88,-55.96,-0.227
78.88,-56.03,-0.227
78.89,-56.10,-0.227
78.90,-56.16,-0.227
78.90,-56.23,-0.227
78.91,-56.30,-0.226
78.91,-56.36,-0.226
78.92,-56.43,-0.226
78.93,-56.50,-0.226
78.94,-56.56,-0.226
78.94,-56.63,-0.226
78.95,-56.70,-0.226
78.95,-56.76,-0.226
78.96,-56.83,-0.226
78.97,-56.90,-0.226
78.98,-56.96,-0.226
78.98,-57.03,-0.226
78.99,-57.10,-0.226
79.00,-57.16,-0.226
79.00,-57.23,-0.226
79.01,-57.30,-0.225
79.01,-57.36,-0.225
79.02,-57.43,-0.225
79.03,-57.50,-0.225
79.04,-57.56,-0.225
79.04,-57.63,-0.225
79.05,-57.70,-0.225
79.05,-57.76,-0.225
79.06,-57.83,-0.225
79.07,-57.90,-0.225
79.08,-57.96,-0.225
79.08,-58.03,-0.225
79.09,-58.10,-0.225
79.10,-58.16,-0.225
79.10,-58.23,-0.225
79.11,-58.29,-0.224
79.11,-58.36,-0.224
79.12,-58.43,-0.224
79.13,-58.50,-0.224
79.14,-58.56,-0.224
79.14,-58.63,-0.224
79.15,-58.70,-0.224
79.15,-58.76,-0.224
79.16,-58.83,-0.224
79.17,-58.90,-0.224
79.18,-58.96,-0.224
79.18,-59.03,-0.224
79.19,-59.10,-0.224
79.20,-59.16,-0.224
79.20,-59.23,-0.224
79.21,-59.30,-0.224
79.21,-59.36,-0.223
79.22,-59.43,-0.223
79.23,-59.50,-0.223
79.24,-59.56,-0.223
79.24,-59.63,-0.223
79.25,-59.69,-0.223
79.25,-59.76,-0.223
79.26,-59.83,-0.223
79.27,-59.90,-0.223
79.28,-59.96,-0.223
79.28,-60.03,-0.223
79.29,-60.10,-0.223
79.30,-60.16,-0.222
79.30,-60.23,-0.222
79.31,-60.29,-0.222
79.31,-60.36,-0.222
79.32,-60.43,-0.222
79.33,-60.49,-0.222
79.34,-60.56,-0.222
79.34,-60.63,-0.222
79.35,-60.69,-0.222
79.35,-60.76,-0.222
79.36,-60.83,-0.222
79.37,-60.89,-0.222
79.38,-60.96,-0.222
79.38,-61.03,-0.222
79.39,-61.09,-0.222
79.40,-61.16,-0.221
79.40,-61.23,-0.221
79.41,-61.29,-0.221
79.41,-61.36,-0.221
79.42,-61.43,-0.221
79.43,-61.49,-0.221
79.44,-61.56,-0.221
79.44,-61.63,-0.221
79.45,-61.69,-0.221
79.45,-61.76,-0.221
79.46,-61.83,-0.221
79.47,-61.89,-0.221
79.48,-61.96,-0.221
79.48,-62.03,-0.221
79.49,-62.09,-0.221
79.50,-62.16,-0.221
79.50,-62.23,-0.220
79.51,-62.29,-0.220
79.51,-62.36,-0.220
79.52,-62.43,-0.220
79.53,-62.49,-0.220
79.54,-62.56,-0.220
79.54,-62.63,-0.220
79.55,-62.69,-0.220
79.55,-62.76,-0.220
79.56,-62.83,-0.220
79.57,-62.89,-0.220
79.58,-62.96,-0.220
79.58,-63.03,-0.219
79.59,-63.09,-0.219
79.60,-63.16,-0.219
79.60,-63.22,-0.219
79.61,-63.29,-0.219
79.61,-63.36,-0.219
79.62,-63.42,-0.219
79.63,-63.49,-0.219
79.64,-63.56,-0.219
79.64,-63.63,-0.219
79.65,-63.69,-0.219
79.65,-63.76,-0.219
79.66,-63.82,-0.219
79.67,-63.89,-0.219
79.68,-63.96,-0.219
79.68,-64.02,-0.219
79.69,-64.09,-0.218
79.70,-64.16,-0.218
79.70,-64.22,-0.218
79.71,-64.29,-0.218
79.71,-64.36,
79.72,-64.42,
79.73,-64.49,
79.74,-64.56,
79.74,-64.62,
79.75,-64.69,
79.75,-64.76,
79.76,-64.82,
79.77,,
79.77,,