File: DSC/2025_04_23_CBD_Carnitine_MC_ACN_n60C_220C_10Cmin_x3.csv
Filename,2025_04_23_CBD_Carnitine_MC_ACN_n60C_220C_10Cmin_x3
Instrument name,DSC2A-00468 (192.168.1.100)
Operator,Yarger
rundate,4/23/2025
Sample name,2025_04_23_CBD_Carnitine_MC_ACN_n60C_220C_10Cmin_x3
proceduresegments,Data Off ; Equilibrate -60.00 °C; Data On ; Ramp 10.00 °C/min to 220.00 °C; Data Off ; Isothermal 1.0 min; Data On ; Ramp 10.00 °C/min to -60.00 °C; Data Off ; Isothermal 1.0 min; Data On ; Ramp 10.00 °C/min to 220.00 °C; Data Off ; Isothermal 1.0 min; Data On ; Ramp 10.00 °C/min to -60.00 °C; Data Off ; Isothermal 1.0 min; Data On ; Ramp 10.00 °C/min to 220.00 °C
[File Parameters]
Run date,4/23/2025 8:27:17 AM
Trios version,5.1.1.46572
Original File Name,D:\DSC2500\JYarger\2025_04_23_CBD_Carnitine_MC_ACN_n60C_220C_10Cmin_x3.tri
Current File Name,D:\DSC2500\JYarger\2025_04_23_CBD_Carnitine_MC_ACN_n60C_220C_10Cmin_x3.tri
[Procedure]
Procedure Name,CBD_Carnitine_n60_220C_10Cmin_x3
Sample Name,2025_04_23_CBD_Carnitine_MC_ACN_n60C_220C_10Cmin_x3
Sample Mass,4.41 mg
Reference Sample Mass,0 mg
Pan Mass,54.1 mg
Pan Number,18
Reference Pan Mass,52.66 mg
Reference Pan Number,19
Pan Type,Tzero Aluminum Hermetic
Comments,Al Hermetic DSC Consumables sealed Pan/Lid.
Project Name,CA
Operator,Yarger
Test,Custom
Unload Max Temperature,30
Unload Min Temperature,30
Load Max Temperature,30
Load Min Temperature,30
Stop on Gas Flow Error,Yes
[Signal List]
Signal #1,Time (min)
Signal #2,Temperature (°C)
Signal #3,Heat Flow (mW)
Signal #4,Delta T (µV)
Signal #5,Delta Tzero (µV)
Signal #6,Tzero Temperature (°C)
Signal #7,Cell Purge (mL/min)
Signal #8,Heater Temp (°C)
Signal #9,Power Delivered (W)
Signal #10,Reference Junction Temperature (°C)
Signal #11,Flange Temperature (°C)
Signal #12,Heat Flow Phase (rad)
Signal #13,Total Heat Capacity (J/°C)
Signal #14,Heat Capacity (J/°C)
[Configuration]
Company Name,ASU
Instrument Name,DSC2A-00468
Instrument Type,DSC2500
Serial Number,DSC2A-00468
IP,192.168.1.100
Location of Instrument,MRRC
DisplayType,Unknown
Sample Interval ,0.1 s/pt
Selected Heat Flow,T4P
Exotherm Direction,Down
Cell Serial,DRC2-00792
Lid Type,Standard
Cooler,RCS 90
Leave Cooler on at End of Sequence,On
Gas 2,Nitrogen
Gas Selected,Channel 1
Flow Rate,50 mL/min
Secondary Purge,On
Licensed Heat Flow,Heat Flow T4P
Modulation Licensed,Yes
[Versions]
Common IDD Version,1
Cortex Version,VER 2.10.2.31
Driver,5.0.0.6
GDM Version,1.0.3.3
TouchscreenVersion,1.0.0.16145
FEP Version,1.2.1.21
FEP Bootloader,2.0.0.5
AutoSampler Version,2.1.1.26
Auto Sampler Bootloader,2.0.0.5
FCM Version,1.1.0.3
FCM Bootloader,2.0.0.5
[Experiment Logs]
Experiment Log Entry # 1,Data On set to 0
Experiment Log Entry # 3,Equilibrate Segment -60 (C) Started
Experiment Log Entry # 5,Air Cool is off.
Experiment Log Entry # 7,Data On set to 1
Experiment Log Entry # 9,Ramp Segment 10 C/min to 220 Started
Experiment Log Entry # 11,Auto sampler has detected that GDM has gone offline
Experiment Log Entry # 13,Auto sampler has detected that FEP has gone offline
Experiment Log Entry # 15,Data On set to 0
Experiment Log Entry # 17,Isothermal Segment 1 min started
Experiment Log Entry # 19,Data On set to 1
Experiment Log Entry # 21,Ramp Segment 10 C/min to -60 Started
Experiment Log Entry # 23,Data On set to 0
Experiment Log Entry # 25,Isothermal Segment 1 min started
Experiment Log Entry # 27,Data On set to 1
Experiment Log Entry # 29,Ramp Segment 10 C/min to 220 Started
Experiment Log Entry # 31,"An attempt to access flash memory was unsuccessful (ErrCode=3, FlashLoc=5, IsWrite=0)."
Experiment Log Entry # 33,Data On set to 0
Experiment Log Entry # 35,Isothermal Segment 1 min started
Experiment Log Entry # 37,Data On set to 1
Experiment Log Entry # 39,Ramp Segment 10 C/min to -60 Started
Experiment Log Entry # 41,Data On set to 0
Experiment Log Entry # 43,Isothermal Segment 1 min started
Experiment Log Entry # 45,Data On set to 1
Experiment Log Entry # 47,Ramp Segment 10 C/min to 220 Started
[Method Log]
Method Log Entry # 1,Data Off
Method Log Entry # 2,Equilibrate -60 °C
Method Log Entry # 3,Data On
Method Log Entry # 4,(Ramp 1287490) Ramp 10 °C/minute to 220 °C
Method Log Entry # 5,Data Off
Method Log Entry # 6,Isothermal 1 minutes
Method Log Entry # 7,Data On
Method Log Entry # 8,(Ramp 1287494) Ramp 10 °C/minute to -60 °C
Method Log Entry # 9,Data Off
Method Log Entry # 10,Isothermal 1 minutes
Method Log Entry # 11,Data On
Method Log Entry # 12,(Ramp 1287498) Ramp 10 °C/minute to 220 °C
Method Log Entry # 13,Data Off
Method Log Entry # 14,Isothermal 1 minutes
Method Log Entry # 15,Data On
Method Log Entry # 16,(Ramp 1287502) Ramp 10 °C/minute to -60 °C
Method Log Entry # 17,Data Off
Method Log Entry # 18,Isothermal 1 minutes
Method Log Entry # 19,Data On
Method Log Entry # 20,(Ramp 1287506) Ramp 10 °C/minute to 220 °C
Cell Serial,DRC2-00792
[T1 Calibration]
Slope,-0.008529666
Offset,9.636258
Initial Temperature,98.23
GUID,f8bfdadc-4977-4fdf-ba6d-0ba9134940c3
[TZero Calibration]
Date Applied,11/29/2022 4:06:13 PM
Description,From -89.059 °C to 396.009 °C at 20.000°C/min
Gas Type,Nitrogen
Pan Type,None
Source Files 1,C:\Users\yargerlab\Desktop\DSC Data\General\TZero_calibration_11_29_22_2nd(2).tri
Source Files 2,C:\Users\yargerlab\Desktop\DSC Data\General\TZero_calibration_11_29_22_2nd(3).tri
Delta T Offset,13.05235
Delta T Slope,-0.007271007
Delta T0 Offset,-13.69128
Delta T0 Slope,0.06063341
[Temperature Calibration]
Date Applied,11/29/2022 7:12:28 PM
Description,From 106.590 °C to 186.590 °C at 10.000°C/min
Gas Type,Nitrogen
Pan Type,Tzero Aluminum Hermetic
Source Files 1,C:\Users\yargerlab\Desktop\DSC Data\General\Indium(6).tri
Measured 1,157.391
Known 1,156.598
[Cell Constant Calibration]
Date Applied,11/29/2022 7:12:29 PM
Description,From 106.590 °C to 186.590 °C at 10.000°C/min
Gas Type,Nitrogen
Pan Type,Tzero Aluminum Hermetic
Source Files 1,C:\Users\yargerlab\Desktop\DSC Data\General\Indium(6).tri
T4P KCell,1.006051
Onset Slope,63.26126 mW/°C
[Direct Cp Calibration]
Date Applied,11/30/2022 11:04:51 AM
Description,From -79.983 °C to 298.409 °C at 10.000°C/min
Gas Type,Nitrogen
Pan Type,Tzero Aluminum Hermetic
Source Files 1,C:\Users\yargerlab\Desktop\DSC Data\General\Sapphire_Heat_Capacity_11_30_22.tri
[Rev Cp Calibration]
Date Applied,11/30/2022 1:58:51 PM
Description,From -79.996 °C to 292.812 °C at 3.000°C/min
Gas Type,Nitrogen
Pan Type,Tzero Aluminum Hermetic
Source Files 1,C:\Users\yargerlab\Desktop\DSC Data\General\Sapphire_MDSC_Calibration_11_30_22.tri
[step]
Ramp 10.00 °C/min to 220.00 °C
Time,Temperature,Heat Flow (Normalized)
min,°C,W/g
0.00,-59.67,-0.073
0.02,-59.69,-0.072
0.04,-59.69,-0.063
0.06,-59.69,-0.063
0.08,-59.66,-0.068
0.10,-59.62,-0.080
0.12,-59.54,-0.085
0.14,-59.45,-0.085
0.16,-59.33,-0.065
0.18,-59.20,-0.038
0.20,-59.06,-0.009
0.22,-58.90,0.020
0.24,-58.74,0.047
0.26,-58.58,0.070
0.28,-58.41,0.094
0.30,-58.23,0.112
0.32,-58.06,0.128
0.34,-57.88,0.142
0.36,-57.69,0.152
0.38,-57.51,0.160
0.40,-57.33,0.170
0.42,-57.14,0.175
0.44,-56.95,0.180
0.46,-56.76,0.186
0.48,-56.57,0.191
0.50,-56.38,0.194
0.52,-56.19,0.197
0.54,-56.00,0.200
0.56,-55.81,0.201
0.58,-55.62,0.204
0.60,-55.42,0.205
0.62,-55.23,0.206
0.64,-55.03,0.208
0.66,-54.84,0.209
0.68,-54.64,0.210
0.70,-54.45,0.211
0.72,-54.25,0.211
0.74,-54.06,0.212
0.76,-53.86,0.212
0.78,-53.66,0.213
0.80,-53.47,0.213
0.82,-53.27,0.214
0.84,-53.07,0.214
0.86,-52.88,0.215
0.88,-52.68,0.215
0.90,-52.49,0.216
0.92,-52.29,0.216
0.94,-52.09,0.217
0.96,-51.89,0.217
0.98,-51.70,0.217
1.00,-51.50,0.218
1.02,-51.30,0.218
1.04,-51.10,0.219
1.06,-50.90,0.219
1.08,-50.71,0.219
1.10,-50.51,0.220
1.12,-50.31,0.220
1.14,-50.11,0.220
1.16,-49.91,0.220
1.18,-49.71,0.221
1.20,-49.51,0.221
1.22,-49.32,0.221
1.24,-49.12,0.222
1.26,-48.92,0.222
1.28,-48.72,0.222
1.30,-48.52,0.222
1.32,-48.32,0.223
1.34,-48.12,0.223
1.36,-47.92,0.223
1.38,-47.72,0.223
1.40,-47.52,0.223
1.42,-47.32,0.224
1.44,-47.12,0.224
1.46,-46.93,0.224
1.48,-46.73,0.224
1.50,-46.53,0.224
1.52,-46.33,0.225
1.54,-46.13,0.225
1.56,-45.93,0.225
1.58,-45.73,0.225
1.60,-45.53,0.226
1.62,-45.33,0.226
1.64,-45.13,0.226
1.66,-44.93,0.226
1.68,-44.73,0.226
1.70,-44.53,0.226
1.72,-44.33,0.226
1.74,-44.13,0.226
1.76,-43.93,0.226
1.78,-43.73,0.227
1.80,-43.53,0.227
1.82,-43.33,0.227
1.84,-43.13,0.227
1.86,-42.93,0.227
1.88,-42.73,0.227
1.90,-42.53,0.227
1.92,-42.33,0.228
1.94,-42.13,0.228
1.96,-41.93,0.228
1.98,-41.73,0.228
2.00,-41.53,0.228
2.02,-41.33,0.228
2.04,-41.13,0.228
2.06,-40.93,0.228
2.08,-40.73,0.229
2.10,-40.53,0.229
2.12,-40.33,0.229
2.14,-40.13,0.229
2.16,-39.93,0.229
2.18,-39.73,0.229
2.20,-39.53,0.229
2.22,-39.33,0.229
2.24,-39.13,0.229
2.26,-38.93,0.229
2.28,-38.73,0.229
2.30,-38.53,0.229
2.32,-38.33,0.229
2.34,-38.13,0.229
2.36,-37.93,0.229
2.38,-37.73,0.230
2.40,-37.53,0.230
2.42,-37.33,0.230
2.44,-37.13,0.230
2.46,-36.93,0.230
2.48,-36.72,0.230
2.50,-36.52,0.230
2.52,-36.32,0.230
2.54,-36.12,0.230
2.56,-35.92,0.231
2.58,-35.72,0.231
2.60,-35.52,0.231
2.62,-35.32,0.231
2.64,-35.12,0.231
2.66,-34.92,0.231
2.68,-34.72,0.231
2.70,-34.52,0.231
2.72,-34.32,0.231
2.74,-34.12,0.231
2.76,-33.92,0.231
2.78,-33.72,0.232
2.80,-33.52,0.232
2.82,-33.32,0.232
2.84,-33.12,0.232
2.86,-32.92,0.232
2.88,-32.72,0.232
2.90,-32.52,0.232
2.92,-32.32,0.232
2.94,-32.12,0.232
2.96,-31.92,0.232
2.98,-31.72,0.232
3.00,-31.52,0.232
3.02,-31.32,0.233
3.04,-31.12,0.233
3.06,-30.92,0.233
3.08,-30.72,0.233
3.10,-30.52,0.233
3.12,-30.32,0.233
3.14,-30.12,0.233
3.16,-29.92,0.233
3.18,-29.72,0.234
3.20,-29.52,0.234
3.22,-29.32,0.234
3.24,-29.12,0.234
3.26,-28.92,0.234
3.28,-28.71,0.234
3.30,-28.51,0.234
3.32,-28.31,0.234
3.34,-28.11,0.234
3.36,-27.92,0.234
3.38,-27.71,0.234
3.40,-27.51,0.234
3.42,-27.32,0.234
3.44,-27.11,0.235
3.46,-26.91,0.235
3.48,-26.71,0.235
3.50,-26.51,0.235
3.52,-26.31,0.235
3.54,-26.11,0.235
3.56,-25.91,0.235
3.58,-25.71,0.235
3.60,-25.51,0.235
3.62,-25.31,0.235
3.64,-25.11,0.236
3.66,-24.91,0.236
3.68,-24.71,0.236
3.70,-24.51,0.236
3.72,-24.31,0.236
3.74,-24.11,0.236
3.76,-23.91,0.236
3.78,-23.71,0.236
3.80,-23.51,0.237
3.82,-23.31,0.237
3.84,-23.11,0.237
3.86,-22.91,0.237
3.88,-22.71,0.237
3.90,-22.51,0.237
3.92,-22.31,0.237
3.94,-22.11,0.237
3.96,-21.91,0.237
3.98,-21.71,0.237
4.00,-21.51,0.238
4.02,-21.31,0.238
4.04,-21.11,0.238
4.06,-20.91,0.238
4.08,-20.71,0.238
4.10,-20.51,0.238
4.12,-20.31,0.238
4.14,-20.11,0.239
4.16,-19.91,0.239
4.18,-19.70,0.239
4.20,-19.51,0.239
4.22,-19.31,0.239
4.24,-19.10,0.239
4.26,-18.90,0.239
4.28,-18.70,0.239
4.30,-18.50,0.239
4.32,-18.30,0.240
4.34,-18.10,0.240
4.36,-17.90,0.240
4.38,-17.70,0.240
4.40,-17.50,0.240
4.42,-17.30,0.240
4.44,-17.10,0.240
4.46,-16.90,0.240
4.48,-16.70,0.240
4.50,-16.50,0.241
4.52,-16.30,0.241
4.54,-16.10,0.241
4.56,-15.90,0.241
4.58,-15.70,0.241
4.60,-15.50,0.241
4.62,-15.30,0.241
4.64,-15.10,0.242
4.66,-14.90,0.242
4.68,-14.70,0.242
4.70,-14.50,0.242
4.72,-14.30,0.242
4.74,-14.10,0.242
4.76,-13.90,0.242
4.78,-13.70,0.242
4.80,-13.50,0.242
4.82,-13.30,0.243
4.84,-13.10,0.243
4.86,-12.90,0.243
4.88,-12.70,0.243
4.90,-12.50,0.243
4.92,-12.30,0.243
4.94,-12.10,0.243
4.96,-11.90,0.244
4.98,-11.70,0.244
5.00,-11.50,0.244
5.02,-11.30,0.244
5.04,-11.10,0.244
5.06,-10.90,0.244
5.08,-10.69,0.245
5.10,-10.50,0.245
5.12,-10.29,0.245
5.14,-10.09,0.245
5.16,-9.89,0.245
5.18,-9.70,0.245
5.20,-9.50,0.245
5.22,-9.29,0.245
5.24,-9.09,0.246
5.26,-8.89,0.246
5.28,-8.69,0.246
5.30,-8.49,0.246
5.32,-8.29,0.246
5.34,-8.09,0.246
5.36,-7.89,0.247
5.38,-7.69,0.247
5.40,-7.49,0.247
5.42,-7.29,0.247
5.44,-7.09,0.247
5.46,-6.89,0.247
5.48,-6.69,0.247
5.50,-6.49,0.247
5.52,-6.29,0.248
5.54,-6.09,0.248
5.56,-5.89,0.248
5.58,-5.69,0.248
5.60,-5.49,0.248
5.62,-5.29,0.248
5.64,-5.09,0.249
5.66,-4.89,0.249
5.68,-4.69,0.249
5.70,-4.49,0.249
5.72,-4.29,0.249
5.74,-4.09,0.249
5.76,-3.89,0.249
5.78,-3.69,0.250
5.80,-3.49,0.250
5.82,-3.29,0.250
5.84,-3.09,0.250
5.86,-2.89,0.250
5.88,-2.69,0.250
5.90,-2.49,0.250
5.92,-2.29,0.251
5.94,-2.09,0.251
5.96,-1.89,0.251
5.98,-1.68,0.251
6.00,-1.48,0.251
6.02,-1.29,0.251
6.04,-1.09,0.251
6.06,-0.88,0.252
6.08,-0.68,0.252
6.10,-0.48,0.252
6.12,-0.28,0.252
6.14,-0.08,0.252
6.16,0.12,0.252
6.18,0.32,0.252
6.20,0.52,0.252
6.22,0.72,0.253
6.24,0.92,0.253
6.26,1.12,0.253
6.28,1.32,0.253
6.30,1.52,0.253
6.32,1.72,0.254
6.34,1.92,0.254
6.36,2.12,0.254
6.38,2.32,0.254
6.40,2.52,0.254
6.42,2.72,0.254
6.44,2.92,0.254
6.46,3.12,0.255
6.48,3.32,0.255
6.50,3.52,0.255
6.52,3.72,0.255
6.54,3.92,0.256
6.56,4.12,0.256
6.58,4.32,0.256
6.60,4.52,0.256
6.62,4.72,0.256
6.64,4.92,0.256
6.66,5.12,0.256
6.68,5.32,0.257
6.70,5.52,0.257
6.72,5.72,0.257
6.74,5.92,0.257
6.76,6.12,0.257
6.78,6.32,0.258
6.80,6.52,0.258
6.82,6.72,0.258
6.84,6.92,0.258
6.86,7.12,0.258
6.88,7.32,0.259
6.90,7.52,0.259
6.92,7.72,0.259
6.94,7.92,0.259
6.96,8.13,0.259
6.98,8.32,0.260
7.00,8.53,0.260
7.02,8.73,0.260
7.04,8.93,0.260
7.06,9.13,0.260
7.08,9.33,0.261
7.10,9.53,0.261
7.12,9.73,0.261
7.14,9.93,0.261
7.16,10.13,0.261
7.18,10.33,0.262
7.20,10.53,0.262
7.22,10.73,0.262
7.24,10.93,0.262
7.26,11.13,0.263
7.28,11.33,0.263
7.30,11.53,0.263
7.32,11.73,0.263
7.34,11.93,0.263
7.36,12.13,0.264
7.38,12.33,0.264
7.40,12.53,0.264
7.42,12.73,0.264
7.44,12.93,0.264
7.46,13.13,0.265
7.48,13.33,0.265
7.50,13.53,0.265
7.52,13.73,0.265
7.54,13.93,0.266
7.56,14.13,0.266
7.58,14.33,0.266
7.60,14.53,0.266
7.62,14.73,0.267
7.64,14.93,0.267
7.66,15.13,0.267
7.68,15.33,0.268
7.70,15.53,0.268
7.72,15.73,0.268
7.74,15.93,0.269
7.76,16.13,0.269
7.78,16.33,0.269
7.80,16.53,0.269
7.82,16.73,0.270
7.84,16.93,0.270
7.86,17.13,0.270
7.88,17.33,0.271
7.90,17.53,0.271
7.92,17.73,0.272
7.94,17.93,0.272
7.96,18.13,0.272
7.98,18.33,0.272
8.00,18.53,0.273
8.02,18.73,0.273
8.04,18.93,0.274
8.06,19.13,0.274
8.08,19.33,0.274
8.10,19.53,0.274
8.12,19.73,0.275
8.14,19.93,0.275
8.16,20.13,0.275
8.18,20.34,0.276
8.20,20.54,0.277
8.22,20.74,0.277
8.24,20.94,0.278
8.26,21.14,0.278
8.28,21.33,0.279
8.30,21.54,0.279
8.32,21.73,0.280
8.34,21.94,0.280
8.36,22.14,0.281
8.38,22.33,0.281
8.40,22.54,0.282
8.42,22.74,0.282
8.44,22.94,0.283
8.46,23.14,0.283
8.48,23.34,0.284
8.50,23.54,0.285
8.52,23.74,0.285
8.54,23.94,0.286
8.56,24.14,0.286
8.58,24.34,0.287
8.60,24.54,0.287
8.62,24.74,0.288
8.64,24.94,0.288
8.66,25.14,0.289
8.68,25.34,0.289
8.70,25.54,0.290
8.72,25.74,0.290
8.74,25.94,0.290
8.76,26.14,0.291
8.78,26.34,0.291
8.80,26.54,0.292
8.82,26.74,0.292
8.84,26.94,0.292
8.86,27.14,0.293
8.88,27.34,0.293
8.90,27.54,0.294
8.92,27.74,0.294
8.94,27.94,0.294
8.96,28.14,0.295
8.98,28.34,0.295
9.00,28.54,0.296
9.02,28.74,0.296
9.04,28.94,0.296
9.06,29.14,0.296
9.08,29.34,0.297
9.10,29.54,0.297
9.12,29.74,0.297
9.14,29.94,0.297
9.16,30.14,0.298
9.18,30.34,0.298
9.20,30.54,0.298
9.22,30.74,0.299
9.24,30.94,0.299
9.26,31.14,0.299
9.28,31.34,0.299
9.30,31.54,0.300
9.32,31.74,0.300
9.34,31.94,0.300
9.36,32.14,0.300
9.38,32.34,0.301
9.40,32.54,0.301
9.42,32.74,0.302
9.44,32.94,0.302
9.46,33.14,0.302
9.48,33.34,0.303
9.50,33.54,0.303
9.52,33.74,0.305
9.54,33.94,0.305
9.56,34.14,0.305
9.58,34.34,0.306
9.60,34.55,0.306
9.62,34.74,0.307
9.64,34.94,0.307
9.66,35.14,0.308
9.68,35.34,0.309
9.70,35.54,0.309
9.72,35.74,0.310
9.74,35.94,0.311
9.76,36.14,0.312
9.78,36.34,0.314
9.80,36.54,0.315
9.82,36.74,0.316
9.84,36.94,0.318
9.86,37.14,0.319
9.88,37.34,0.321
9.90,37.54,0.322
9.92,37.74,0.323
9.94,37.94,0.325
9.96,38.14,0.326
9.98,38.34,0.328
10.00,38.54,0.330
10.02,38.74,0.331
10.04,38.94,0.335
10.06,39.14,0.336
10.08,39.34,0.339
10.10,39.54,0.339
10.12,39.74,0.341
10.14,39.94,0.343
10.16,40.14,0.344
10.18,40.34,0.347
10.20,40.54,0.348
10.22,40.74,0.351
10.24,40.94,0.352
10.26,41.14,0.354
10.28,41.34,0.355
10.30,41.54,0.358
10.32,41.74,0.360
10.34,41.94,0.362
10.36,42.14,0.363
10.38,42.34,0.365
10.40,42.53,0.367
10.42,42.74,0.369
10.44,42.93,0.371
10.46,43.13,0.372
10.48,43.33,0.374
10.50,43.53,0.377
10.52,43.73,0.379
10.54,43.93,0.381
10.56,44.13,0.384
10.58,44.33,0.388
10.60,44.53,0.390
10.62,44.73,0.392
10.64,44.93,0.395
10.66,45.13,0.398
10.68,45.33,0.400
10.70,45.53,0.404
10.72,45.73,0.406
10.74,45.93,0.409
10.76,46.13,0.412
10.78,46.32,0.418
10.80,46.52,0.420
10.82,46.72,0.424
10.84,46.92,0.427
10.86,47.12,0.431
10.88,47.32,0.434
10.90,47.52,0.440
10.92,47.72,0.443
10.94,47.92,0.448
10.96,48.12,0.452
10.98,48.32,0.456
11.00,48.52,0.461
11.02,48.71,0.466
11.04,48.91,0.472
11.06,49.11,0.477
11.08,49.31,0.483
11.10,49.51,0.489
11.12,49.71,0.493
11.14,49.91,0.501
11.16,50.11,0.505
11.18,50.30,0.511
11.20,50.50,0.518
11.22,50.70,0.523
11.24,50.90,0.530
11.26,51.10,0.540
11.28,51.30,0.545
11.30,51.49,0.551
11.32,51.69,0.560
11.34,51.89,0.567
11.36,52.09,0.575
11.38,52.29,0.582
11.40,52.48,0.591
11.42,52.68,0.599
11.44,52.88,0.607
11.46,53.08,0.617
11.48,53.28,0.625
11.50,53.47,0.633
11.52,53.67,0.642
11.54,53.87,0.650
11.56,54.06,0.658
11.58,54.26,0.669
11.60,54.46,0.679
11.62,54.66,0.684
11.64,54.86,0.694
11.66,55.05,0.704
11.68,55.25,0.711
11.70,55.45,0.721
11.72,55.65,0.730
11.74,55.84,0.740
11.76,56.04,0.748
11.78,56.24,0.760
11.80,56.44,0.770
11.82,56.63,0.782
11.84,56.83,0.792
11.86,57.03,0.804
11.88,57.22,0.814
11.90,57.42,0.825
11.92,57.62,0.837
11.94,57.82,0.849
11.96,58.01,0.865
11.98,58.21,0.878
12.00,58.40,0.893
12.02,58.60,0.907
12.04,58.80,0.923
12.06,58.99,0.933
12.08,59.19,0.938
12.10,59.39,0.936
12.12,59.59,0.936
12.14,59.78,0.934
12.16,59.98,0.931
12.18,60.19,0.924
12.20,60.39,0.916
12.22,60.59,0.901
12.24,60.79,0.889
12.26,61.00,0.872
12.28,61.20,0.858
12.30,61.40,0.839
12.32,61.61,0.823
12.34,61.81,0.806
12.36,62.02,0.787
12.38,62.22,0.774
12.40,62.43,0.762
12.42,62.63,0.751
12.44,62.84,0.746
12.46,63.04,0.737
12.48,63.24,0.729
12.50,63.45,0.722
12.52,63.65,0.717
12.54,63.85,0.712
12.56,64.05,0.709
12.58,64.26,0.707
12.60,64.46,0.705
12.62,64.66,0.702
12.64,64.86,0.698
12.66,65.06,0.688
12.68,65.26,0.675
12.70,65.47,0.659
12.72,65.67,0.640
12.74,65.88,0.616
12.76,66.08,0.593
12.78,66.29,0.567
12.80,66.49,0.544
12.82,66.70,0.521
12.84,66.91,0.497
12.86,67.12,0.478
12.88,67.32,0.461
12.90,67.53,0.445
12.92,67.73,0.434
12.94,67.94,0.424
12.96,68.14,0.417
12.98,68.34,0.412
13.00,68.55,0.408
13.02,68.75,0.403
13.04,68.95,0.402
13.06,69.16,0.400
13.08,69.36,0.399
13.10,69.56,0.397
13.12,69.76,0.396
13.14,69.96,0.395
13.16,70.16,0.394
13.18,70.36,0.394
13.20,70.56,0.393
13.22,70.76,0.393
13.24,70.96,0.393
13.26,71.16,0.393
13.28,71.36,0.392
13.30,71.57,0.392
13.32,71.76,0.392
13.34,71.97,0.392
13.36,72.17,0.392
13.38,72.37,0.392
13.40,72.57,0.392
13.42,72.77,0.392
13.44,72.97,0.392
13.46,73.17,0.391
13.48,73.37,0.391
13.50,73.57,0.391
13.52,73.77,0.391
13.54,73.97,0.391
13.56,74.17,0.391
13.58,74.37,0.391
13.60,74.57,0.391
13.62,74.77,0.392
13.64,74.97,0.392
13.66,75.17,0.392
13.68,75.37,0.392
13.70,75.57,0.392
13.72,75.77,0.392
13.74,75.97,0.392
13.76,76.17,0.392
13.78,76.37,0.393
13.80,76.57,0.393
13.82,76.77,0.393
13.84,76.97,0.393
13.86,77.17,0.393
13.88,77.37,0.394
13.90,77.57,0.394
13.92,77.77,0.394
13.94,77.97,0.394
13.96,78.17,0.394
13.98,78.37,0.395
14.00,78.57,0.395
14.02,78.77,0.395
14.04,78.97,0.395
14.06,79.17,0.395
14.08,79.37,0.395
14.10,79.57,0.395
14.12,79.77,0.396
14.14,79.97,0.396
14.16,80.17,0.396
14.18,80.37,0.396
14.20,80.57,0.396
14.22,80.77,0.396
14.24,80.97,0.396
14.26,81.17,0.396
14.28,81.37,0.397
14.30,81.57,0.397
14.32,81.77,0.397
14.34,81.98,0.397
14.36,82.17,0.397
14.38,82.37,0.398
14.40,82.57,0.398
14.42,82.78,0.398
14.44,82.97,0.398
14.46,83.17,0.398
14.48,83.37,0.398
14.50,83.58,0.398
14.52,83.78,0.398
14.54,83.98,0.399
14.56,84.18,0.399
14.58,84.38,0.399
14.60,84.58,0.399
14.62,84.78,0.399
14.64,84.98,0.399
14.66,85.18,0.399
14.68,85.38,0.399
14.70,85.58,0.399
14.72,85.78,0.400
14.74,85.98,0.400
14.76,86.18,0.400
14.78,86.38,0.400
14.80,86.58,0.400
14.82,86.78,0.400
14.84,86.98,0.401
14.86,87.18,0.401
14.88,87.38,0.401
14.90,87.58,0.401
14.92,87.78,0.401
14.94,87.98,0.401
14.96,88.18,0.402
14.98,88.38,0.402
15.00,88.58,0.402
15.02,88.78,0.402
15.04,88.98,0.402
15.06,89.18,0.402
15.08,89.38,0.403
15.10,89.58,0.403
15.12,89.78,0.403
15.14,89.98,0.403
15.16,90.18,0.403
15.18,90.38,0.404
15.20,90.58,0.404
15.22,90.78,0.404
15.24,90.98,0.404
15.26,91.18,0.404
15.28,91.38,0.404
15.30,91.58,0.405
15.32,91.78,0.405
15.34,91.98,0.405
15.36,92.18,0.405
15.38,92.38,0.405
15.40,92.58,0.406
15.42,92.78,0.406
15.44,92.98,0.406
15.46,93.18,0.406
15.48,93.38,0.406
15.50,93.59,0.406
15.52,93.78,0.407
15.54,93.98,0.407
15.56,94.18,0.407
15.58,94.38,0.407
15.60,94.59,0.407
15.62,94.78,0.407
15.64,94.99,0.408
15.66,95.19,0.408
15.68,95.39,0.408
15.70,95.59,0.408
15.72,95.79,0.409
15.74,95.99,0.409
15.76,96.19,0.409
15.78,96.39,0.409
15.80,96.59,0.409
15.82,96.79,0.409
15.84,96.99,0.409
15.86,97.19,0.409
15.88,97.39,0.410
15.90,97.59,0.410
15.92,97.79,0.410
15.94,97.99,0.410
15.96,98.19,0.410
15.98,98.39,0.410
16.00,98.59,0.410
16.02,98.79,0.410
16.04,98.99,0.410
16.06,99.19,0.411
16.08,99.39,0.411
16.10,99.59,0.411
16.12,99.79,0.411
16.14,99.99,0.411
16.16,100.19,0.411
16.18,100.39,0.411
16.20,100.59,0.411
16.22,100.79,0.411
16.24,100.99,0.411
16.26,101.19,0.411
16.28,101.39,0.411
16.30,101.59,0.411
16.32,101.79,0.411
16.34,101.99,0.412
16.36,102.19,0.412
16.38,102.39,0.412
16.40,102.59,0.412
16.42,102.79,0.412
16.44,102.99,0.412
16.46,103.19,0.412
16.48,103.39,0.412
16.50,103.59,0.412
16.52,103.79,0.412
16.54,103.99,0.412
16.56,104.19,0.412
16.58,104.39,0.412
16.60,104.59,0.412
16.62,104.79,0.412
16.64,105.00,0.412
16.66,105.20,0.412
16.68,105.40,0.413
16.70,105.60,0.413
16.72,105.80,0.413
16.74,106.00,0.413
16.76,106.20,0.413
16.78,106.40,0.413
16.80,106.60,0.413
16.82,106.79,0.413
16.84,107.00,0.413
16.86,107.20,0.413
16.88,107.40,0.413
16.90,107.60,0.413
16.92,107.80,0.413
16.94,108.00,0.413
16.96,108.20,0.413
16.98,108.40,0.413
17.00,108.60,0.413
17.02,108.80,0.413
17.04,109.00,0.413
17.06,109.20,0.413
17.08,109.40,0.413
17.10,109.60,0.413
17.12,109.80,0.413
17.14,110.00,0.413
17.16,110.20,0.413
17.18,110.40,0.413
17.20,110.60,0.413
17.22,110.80,0.413
17.24,111.00,0.413
17.26,111.20,0.413
17.28,111.40,0.413
17.30,111.60,0.413
17.32,111.80,0.413
17.34,112.00,0.413
17.36,112.20,0.412
17.38,112.40,0.412
17.40,112.60,0.412
17.42,112.80,0.412
17.44,113.00,0.412
17.46,113.20,0.412
17.48,113.40,0.412
17.50,113.60,0.412
17.52,113.80,0.411
17.54,114.00,0.411
17.56,114.20,0.411
17.58,114.40,0.411
17.60,114.60,0.411
17.62,114.81,0.411
17.64,115.00,0.411
17.66,115.21,0.411
17.68,115.41,0.411
17.70,115.61,0.411
17.72,115.81,0.411
17.74,116.01,0.411
17.76,116.21,0.411
17.78,116.41,0.410
17.80,116.61,0.410
17.82,116.81,0.410
17.84,117.01,0.410
17.86,117.21,0.410
17.88,117.41,0.410
17.90,117.61,0.410
17.92,117.81,0.409
17.94,118.01,0.409
17.96,118.21,0.409
17.98,118.41,0.409
18.00,118.61,0.409
18.02,118.81,0.409
18.04,119.01,0.409
18.06,119.21,0.409
18.08,119.41,0.409
18.10,119.61,0.409
18.12,119.81,0.409
18.14,120.01,0.409
18.16,120.21,0.409
18.18,120.41,0.409
18.20,120.61,0.409
18.22,120.81,0.409
18.24,121.01,0.409
18.26,121.21,0.409
18.28,121.41,0.409
18.30,121.61,0.409
18.32,121.81,0.409
18.34,122.01,0.408
18.36,122.21,0.408
18.38,122.41,0.408
18.40,122.61,0.408
18.42,122.81,0.408
18.44,123.01,0.408
18.46,123.21,0.408
18.48,123.41,0.408
18.50,123.61,0.409
18.52,123.81,0.409
18.54,124.02,0.409
18.56,124.21,0.409
18.58,124.41,0.409
18.60,124.61,0.409
18.62,124.81,0.409
18.64,125.01,0.409
18.66,125.21,0.410
18.68,125.41,0.410
18.70,125.61,0.410
18.72,125.81,0.410
18.74,126.02,0.410
18.76,126.21,0.410
18.78,126.42,0.410
18.80,126.61,0.411
18.82,126.82,0.411
18.84,127.02,0.411
18.86,127.22,0.411
18.88,127.42,0.412
18.90,127.62,0.412
18.92,127.82,0.412
18.94,128.02,0.412
18.96,128.22,0.412
18.98,128.42,0.413
19.00,128.62,0.413
19.02,128.82,0.413
19.04,129.02,0.413
19.06,129.22,0.414
19.08,129.42,0.414
19.10,129.62,0.415
19.12,129.82,0.415
19.14,130.02,0.415
19.16,130.22,0.415
19.18,130.42,0.416
19.20,130.62,0.416
19.22,130.82,0.416
19.24,131.02,0.417
19.26,131.22,0.417
19.28,131.42,0.418
19.30,131.62,0.418
19.32,131.82,0.418
19.34,132.02,0.419
19.36,132.22,0.419
19.38,132.42,0.419
19.40,132.62,0.420
19.42,132.82,0.420
19.44,133.02,0.421
19.46,133.22,0.421
19.48,133.42,0.422
19.50,133.62,0.422
19.52,133.82,0.423
19.54,134.02,0.423
19.56,134.22,0.423
19.58,134.42,0.424
19.60,134.62,0.424
19.62,134.82,0.425
19.64,135.02,0.426
19.66,135.22,0.426
19.68,135.42,0.427
19.70,135.62,0.427
19.72,135.82,0.428
19.74,136.02,0.428
19.76,136.22,0.429
19.78,136.42,0.429
19.80,136.62,0.430
19.82,136.82,0.431
19.84,137.02,0.431
19.86,137.22,0.432
19.88,137.42,0.433
19.90,137.62,0.433
19.92,137.82,0.434
19.94,138.02,0.435
19.96,138.22,0.436
19.98,138.42,0.437
20.00,138.62,0.438
20.02,138.82,0.438
20.04,139.02,0.440
20.06,139.22,0.441
20.08,139.42,0.441
20.10,139.62,0.442
20.12,139.82,0.443
20.14,140.02,0.443
20.16,140.22,0.444
20.18,140.42,0.445
20.20,140.62,0.446
20.22,140.82,0.448
20.24,141.02,0.449
20.26,141.22,0.452
20.28,141.42,0.452
20.30,141.62,0.453
20.32,141.82,0.454
20.34,142.02,0.455
20.36,142.22,0.456
20.38,142.42,0.457
20.40,142.61,0.458
20.42,142.82,0.459
20.44,143.01,0.462
20.46,143.21,0.463
20.48,143.41,0.465
20.50,143.61,0.466
20.52,143.81,0.467
20.54,144.01,0.469
20.56,144.21,0.471
20.58,144.41,0.473
20.60,144.61,0.474
20.62,144.81,0.475
20.64,145.01,0.476
20.66,145.21,0.478
20.68,145.41,0.479
20.70,145.61,0.480
20.72,145.81,0.483
20.74,146.01,0.484
20.76,146.21,0.485
20.78,146.41,0.487
20.80,146.61,0.487
20.82,146.81,0.489
20.84,147.01,0.492
20.86,147.21,0.493
20.88,147.41,0.496
20.90,147.61,0.499
20.92,147.81,0.502
20.94,148.01,0.504
20.96,148.21,0.505
20.98,148.41,0.506
21.00,148.61,0.508
21.02,148.81,0.509
21.04,149.01,0.511
21.06,149.21,0.513
21.08,149.41,0.515
21.10,149.61,0.518
21.12,149.81,0.521
21.14,150.01,0.523
21.16,150.20,0.525
21.18,150.40,0.528
21.20,150.60,0.531
21.22,150.80,0.533
21.24,151.00,0.536
21.26,151.20,0.538
21.28,151.40,0.541
21.30,151.60,0.545
21.32,151.80,0.546
21.34,152.00,0.550
21.36,152.20,0.553
21.38,152.40,0.556
21.40,152.60,0.560
21.42,152.80,0.564
21.44,153.00,0.567
21.46,153.20,0.570
21.48,153.39,0.574
21.50,153.60,0.576
21.52,153.79,0.581
21.54,153.99,0.584
21.56,154.19,0.589
21.58,154.39,0.594
21.60,154.59,0.598
21.62,154.79,0.603
21.64,154.99,0.606
21.66,155.19,0.609
21.68,155.39,0.614
21.70,155.59,0.619
21.72,155.79,0.624
21.74,155.98,0.628
21.76,156.18,0.632
21.78,156.38,0.637
21.80,156.58,0.642
21.82,156.78,0.648
21.84,156.98,0.654
21.86,157.18,0.659
21.88,157.38,0.662
21.90,157.58,0.668
21.92,157.78,0.674
21.94,157.97,0.679
21.96,158.17,0.686
21.98,158.37,0.691
22.00,158.57,0.697
22.02,158.77,0.704
22.04,158.97,0.709
22.06,159.17,0.713
22.08,159.36,0.719
22.10,159.56,0.725
22.12,159.76,0.730
22.14,159.96,0.738
22.16,160.16,0.743
22.18,160.36,0.749
22.20,160.56,0.757
22.22,160.76,0.762
22.24,160.95,0.768
22.26,161.15,0.775
22.28,161.35,0.779
22.30,161.55,0.786
22.32,161.75,0.791
22.34,161.95,0.797
22.36,162.14,0.804
22.38,162.34,0.810
22.40,162.54,0.818
22.42,162.74,0.826
22.44,162.94,0.830
22.46,163.14,0.837
22.48,163.34,0.843
22.50,163.53,0.850
22.52,163.73,0.856
22.54,163.93,0.861
22.56,164.13,0.865
22.58,164.33,0.872
22.60,164.53,0.878
22.62,164.73,0.886
22.64,164.92,0.892
22.66,165.12,0.899
22.68,165.32,0.905
22.70,165.52,0.912
22.72,165.72,0.915
22.74,165.92,0.921
22.76,166.12,0.927
22.78,166.32,0.932
22.80,166.51,0.938
22.82,166.71,0.944
22.84,166.91,0.948
22.86,167.11,0.956
22.88,167.31,0.963
22.90,167.51,0.968
22.92,167.71,0.972
22.94,167.90,0.976
22.96,168.10,0.982
22.98,168.30,0.988
23.00,168.50,0.994
23.02,168.70,1.000
23.04,168.90,1.005
23.06,169.10,1.013
23.08,169.29,1.016
23.10,169.49,1.023
23.12,169.69,1.029
23.14,169.89,1.035
23.16,170.09,1.040
23.18,170.29,1.048
23.20,170.49,1.057
23.22,170.68,1.065
23.24,170.88,1.075
23.26,171.08,1.081
23.28,171.28,1.095
23.30,171.48,1.103
23.32,171.67,1.112
23.34,171.87,1.124
23.36,172.07,1.210
23.38,172.26,1.206
23.40,172.46,1.209
23.42,172.65,1.221
23.44,172.85,1.237
23.46,173.04,1.248
23.48,173.24,1.252
23.50,173.44,1.252
23.52,173.64,1.248
23.54,173.84,1.233
23.56,174.04,1.221
23.58,174.24,1.200
23.60,174.45,1.184
23.62,174.65,1.164
23.64,174.85,1.147
23.66,175.06,1.132
23.68,175.26,1.129
23.70,175.46,1.124
23.72,175.67,1.123
23.74,175.87,1.114
23.76,176.07,1.107
23.78,176.27,1.104
23.80,176.47,1.108
23.82,176.67,1.109
23.84,176.87,1.116
23.86,177.07,1.120
23.88,177.27,1.131
23.90,177.47,1.137
23.92,177.67,1.143
23.94,177.87,1.146
23.96,178.07,1.144
23.98,178.27,1.135
24.00,178.47,1.122
24.02,178.67,1.122
24.04,178.87,1.122
24.06,179.08,1.106
24.08,179.28,1.086
24.10,179.48,1.085
24.12,179.68,1.053
24.14,179.89,1.028
24.16,180.09,1.026
24.18,180.30,1.009
24.20,180.50,1.001
24.22,180.70,0.987
24.24,180.91,0.986
24.26,181.11,0.976
24.28,181.31,0.975
24.30,181.51,0.954
24.32,181.72,0.944
24.34,181.92,0.923
24.36,182.12,0.919
24.38,182.33,0.917
24.40,182.53,0.907
24.42,182.73,0.900
24.44,182.93,0.889
24.46,183.13,0.876
24.48,183.34,0.876
24.50,183.54,0.873
24.52,183.74,0.870
24.54,183.94,0.859
24.56,184.14,0.847
24.58,184.35,0.849
24.60,184.55,0.847
24.62,184.75,0.835
24.64,184.95,0.824
24.66,185.15,0.819
24.68,185.35,0.816
24.70,185.55,0.820
24.72,185.76,0.819
24.74,185.96,0.805
24.76,186.16,0.805
24.78,186.36,0.799
24.80,186.56,0.792
24.82,186.76,0.786
24.84,186.96,0.783
24.86,187.17,0.782
24.88,187.37,0.781
24.90,187.57,0.777
24.92,187.77,0.777
24.94,187.97,0.779
24.96,188.17,0.791
24.98,188.37,0.800
25.00,188.56,0.805
25.02,188.76,0.806
25.04,188.96,0.803
25.06,189.16,0.784
25.08,189.37,0.783
25.10,189.57,0.783
25.12,189.77,0.797
25.14,189.96,0.816
25.16,190.16,0.818
25.18,190.36,0.816
25.20,190.56,0.814
25.22,190.76,0.814
25.24,190.96,0.815
25.26,191.16,0.825
25.28,191.36,0.867
25.30,191.55,0.874
25.32,191.75,0.890
25.34,191.95,0.908
25.36,192.14,0.894
25.38,192.34,0.893
25.40,192.54,0.907
25.42,192.74,0.923
25.44,192.94,0.944
25.46,193.13,0.960
25.48,193.33,0.983
25.50,193.53,0.984
25.52,193.73,0.980
25.54,193.92,1.009
25.56,194.12,1.053
25.58,194.31,1.068
25.60,194.51,1.053
25.62,194.71,1.038
25.64,194.91,1.080
25.66,195.10,1.063
25.68,195.31,1.047
25.70,195.51,1.019
25.72,195.71,1.025
25.74,195.91,1.026
25.76,196.11,1.076
25.78,196.30,1.120
25.80,196.50,1.114
25.82,196.70,1.110
25.84,196.90,1.075
25.86,197.10,1.095
25.88,197.30,1.096
25.90,197.50,1.096
25.92,197.69,1.138
25.94,197.89,1.115
25.96,198.09,1.115
25.98,198.30,1.065
26.00,198.50,1.057
26.02,198.70,1.121
26.04,198.90,1.121
26.06,199.10,1.066
26.08,199.30,1.064
26.10,199.50,1.093
26.12,199.70,1.054
26.14,199.91,1.041
26.16,200.11,1.033
26.18,200.31,1.025
26.20,200.51,1.000
26.22,200.72,1.018
26.24,200.92,1.007
26.26,201.12,1.028
26.28,201.32,1.042
26.30,201.52,1.037
26.32,201.72,1.018
26.34,201.92,1.011
26.36,202.12,1.012
26.38,202.32,1.004
26.40,202.52,1.003
26.42,202.72,1.018
26.44,202.92,1.025
26.46,203.12,1.007
26.48,203.32,1.005
26.50,203.52,0.989
26.52,203.72,1.011
26.54,203.92,0.983
26.56,204.13,0.984
26.58,204.33,1.007
26.60,204.52,1.037
26.62,204.72,0.996
26.64,204.92,0.999
26.66,205.12,0.987
26.68,205.32,1.014
26.70,205.53,0.986
26.72,205.73,0.979
26.74,205.93,0.998
26.76,206.13,0.999
26.78,206.33,0.998
26.80,206.53,1.031
26.82,206.72,1.061
26.84,206.92,1.037
26.86,207.12,1.023
26.88,207.32,1.032
26.90,207.52,1.063
26.92,207.72,1.053
26.94,207.92,1.034
26.96,208.12,1.005
26.98,208.32,0.985
27.00,208.53,0.983
27.02,208.73,0.965
27.04,208.93,0.947
27.06,209.13,0.948
27.08,209.34,0.963
27.10,209.54,0.952
27.12,209.74,0.952
27.14,209.94,0.969
27.16,210.14,0.951
27.18,210.34,0.946
27.20,210.54,0.948
27.22,210.74,0.946
27.24,210.94,0.920
27.26,211.15,0.903
27.28,211.35,0.894
27.30,211.55,0.895
27.32,211.75,0.898
27.34,211.95,0.899
27.36,212.16,0.896
27.38,212.36,0.883
27.40,212.56,0.881
27.42,212.76,0.864
27.44,212.96,0.842
27.46,213.17,0.823
27.48,213.37,0.819
27.50,213.57,0.832
27.52,213.77,0.832
27.54,213.97,0.823
27.56,214.17,0.817
27.58,214.37,0.811
27.60,214.58,0.803
27.62,214.78,0.783
27.64,214.98,0.777
27.66,215.19,0.764
27.68,215.39,0.758
27.70,215.59,0.754
27.72,215.79,0.746
27.74,215.99,0.737
27.76,216.20,0.730
27.78,216.40,0.728
27.80,216.60,0.727
27.82,216.80,0.723
27.84,217.00,0.717
27.86,217.20,0.716
27.88,217.40,0.713
27.90,217.60,0.710
27.92,217.81,0.698
27.94,218.01,
27.96,218.21,
27.98,218.41,
27.99,,

[step]
Ramp 10.00 °C/min to -60.00 °C
Time,Temperature,Heat Flow (Normalized)
min,°C,W/g
28.99,220.04,0.136
29.01,220.04,0.132
29.03,220.03,0.131
29.05,220.02,0.171
29.07,219.98,0.233
29.09,219.92,0.292
29.11,219.82,0.325
29.13,219.71,0.314
29.15,219.58,0.268
29.17,219.43,0.199
29.19,219.27,0.125
29.21,219.11,0.055
29.23,218.94,-0.004
29.25,218.77,-0.053
29.27,218.59,-0.093
29.29,218.41,-0.125
29.31,218.23,-0.154
29.33,218.04,-0.176
29.35,217.86,-0.196
29.37,217.67,-0.211
29.39,217.48,-0.225
29.41,217.29,-0.239
29.43,217.10,-0.251
29.45,216.90,-0.259
29.47,216.71,-0.266
29.49,216.52,-0.273
29.51,216.32,-0.282
29.53,216.13,-0.286
29.55,215.93,-0.291
29.57,215.74,-0.295
29.59,215.54,-0.299
29.61,215.34,-0.301
29.63,215.15,-0.305
29.65,214.95,-0.307
29.67,214.76,-0.309
29.69,214.56,-0.310
29.71,214.36,-0.313
29.73,214.16,-0.316
29.75,213.96,-0.318
29.77,213.77,-0.321
29.79,213.57,-0.321
29.81,213.37,-0.322
29.83,213.17,-0.323
29.85,212.98,-0.324
29.87,212.78,-0.325
29.89,212.58,-0.325
29.91,212.38,-0.326
29.93,212.18,-0.327
29.95,211.99,-0.328
29.97,211.79,-0.329
29.99,211.59,-0.330
30.01,211.39,-0.330
30.03,211.19,-0.331
30.05,210.99,-0.331
30.07,210.79,-0.332
30.09,210.59,-0.332
30.11,210.39,-0.333
30.13,210.20,-0.334
30.15,210.00,-0.335
30.17,209.80,-0.336
30.19,209.60,-0.337
30.21,209.40,-0.337
30.23,209.20,-0.338
30.25,209.00,-0.338
30.27,208.80,-0.338
30.29,208.60,-0.339
30.31,208.40,-0.340
30.33,208.21,-0.340
30.35,208.01,-0.341
30.37,207.81,-0.341
30.39,207.61,-0.342
30.41,207.41,-0.342
30.43,207.21,-0.342
30.45,207.01,-0.342
30.47,206.81,-0.342
30.49,206.61,-0.343
30.51,206.41,-0.343
30.53,206.21,-0.344
30.55,206.01,-0.345
30.57,205.81,-0.345
30.59,205.61,-0.346
30.61,205.42,-0.346
30.63,205.22,-0.346
30.65,205.02,-0.347
30.67,204.82,-0.347
30.69,204.62,-0.347
30.71,204.42,-0.347
30.73,204.22,-0.348
30.75,204.02,-0.348
30.77,203.82,-0.348
30.79,203.62,-0.348
30.81,203.42,-0.348
30.83,203.22,-0.348
30.85,203.02,-0.349
30.87,202.82,-0.349
30.89,202.62,-0.349
30.91,202.42,-0.350
30.93,202.22,-0.350
30.95,202.02,-0.350
30.97,201.82,-0.350
30.99,201.62,-0.351
31.01,201.42,-0.351
31.03,201.22,-0.351
31.05,201.02,-0.352
31.07,200.83,-0.352
31.09,200.63,-0.352
31.11,200.43,-0.352
31.13,200.23,-0.352
31.15,200.03,-0.352
31.17,199.83,-0.353
31.19,199.63,-0.353
31.21,199.43,-0.353
31.23,199.23,-0.354
31.25,199.03,-0.354
31.27,198.83,-0.354
31.29,198.63,-0.354
31.31,198.43,-0.355
31.33,198.23,-0.355
31.35,198.03,-0.355
31.37,197.83,-0.355
31.39,197.63,-0.355
31.41,197.43,-0.355
31.43,197.23,-0.355
31.45,197.03,-0.355
31.47,196.83,-0.356
31.49,196.63,-0.356
31.51,196.43,-0.356
31.53,196.23,-0.356
31.55,196.03,-0.356
31.57,195.83,-0.356
31.59,195.63,-0.357
31.61,195.44,-0.357
31.63,195.24,-0.357
31.65,195.04,-0.357
31.67,194.84,-0.357
31.69,194.64,-0.358
31.71,194.44,-0.358
31.73,194.24,-0.358
31.75,194.04,-0.358
31.77,193.84,-0.358
31.79,193.64,-0.358
31.81,193.44,-0.358
31.83,193.24,-0.359
31.85,193.04,-0.359
31.87,192.84,-0.359
31.89,192.64,-0.359
31.91,192.44,-0.359
31.93,192.24,-0.359
31.95,192.04,-0.359
31.97,191.84,-0.359
31.99,191.64,-0.359
32.01,191.44,-0.360
32.03,191.24,-0.360
32.05,191.04,-0.360
32.07,190.84,-0.360
32.09,190.64,-0.360
32.11,190.44,-0.360
32.13,190.24,-0.360
32.15,190.05,-0.361
32.17,189.84,-0.361
32.19,189.65,-0.361
32.21,189.45,-0.361
32.23,189.25,-0.361
32.25,189.05,-0.361
32.27,188.85,-0.362
32.29,188.65,-0.362
32.31,188.45,-0.362
32.33,188.25,-0.362
32.35,188.05,-0.362
32.37,187.85,-0.362
32.39,187.65,-0.362
32.41,187.45,-0.363
32.43,187.25,-0.363
32.45,187.05,-0.363
32.47,186.85,-0.363
32.49,186.65,-0.364
32.51,186.45,-0.364
32.53,186.25,-0.364
32.55,186.05,-0.364
32.57,185.85,-0.364
32.59,185.65,-0.364
32.61,185.45,-0.365
32.63,185.25,-0.365
32.65,185.05,-0.365
32.67,184.85,-0.365
32.69,184.65,-0.365
32.71,184.45,-0.366
32.73,184.25,-0.366
32.75,184.05,-0.366
32.77,183.85,-0.366
32.79,183.65,-0.366
32.81,183.45,-0.366
32.83,183.25,-0.366
32.85,183.05,-0.367
32.87,182.85,-0.367
32.89,182.65,-0.367
32.91,182.45,-0.367
32.93,182.26,-0.367
32.95,182.06,-0.367
32.97,181.86,-0.367
32.99,181.66,-0.367
33.01,181.46,-0.367
33.03,181.26,-0.367
33.05,181.06,-0.368
33.07,180.86,-0.368
33.09,180.66,-0.368
33.11,180.46,-0.368
33.13,180.26,-0.368
33.15,180.06,-0.368
33.17,179.86,-0.368
33.19,179.66,-0.369
33.21,179.46,-0.369
33.23,179.26,-0.369
33.25,179.06,-0.369
33.27,178.86,-0.369
33.29,178.66,-0.369
33.31,178.46,-0.369
33.33,178.26,-0.369
33.35,178.06,-0.369
33.37,177.86,-0.370
33.39,177.66,-0.370
33.41,177.46,-0.370
33.43,177.26,-0.370
33.45,177.06,-0.370
33.47,176.86,-0.370
33.49,176.66,-0.370
33.51,176.46,-0.370
33.53,176.26,-0.371
33.55,176.06,-0.371
33.57,175.86,-0.371
33.59,175.66,-0.371
33.61,175.46,-0.371
33.63,175.26,-0.371
33.65,175.06,-0.371
33.67,174.87,-0.371
33.69,174.66,-0.371
33.71,174.46,-0.371
33.73,174.27,-0.372
33.75,174.07,-0.372
33.77,173.87,-0.372
33.79,173.67,-0.372
33.81,173.47,-0.372
33.83,173.27,-0.372
33.85,173.07,-0.372
33.87,172.87,-0.372
33.89,172.67,-0.372
33.91,172.47,-0.372
33.93,172.27,-0.372
33.95,172.07,-0.372
33.97,171.87,-0.372
33.99,171.67,-0.372
34.01,171.47,-0.372
34.03,171.27,-0.373
34.05,171.07,-0.373
34.07,170.87,-0.373
34.09,170.67,-0.373
34.11,170.47,-0.373
34.13,170.27,-0.373
34.15,170.07,-0.373
34.17,169.87,-0.373
34.19,169.67,-0.374
34.21,169.47,-0.374
34.23,169.27,-0.374
34.25,169.07,-0.374
34.27,168.87,-0.374
34.29,168.67,-0.374
34.31,168.47,-0.374
34.33,168.28,-0.375
34.35,168.08,-0.375
34.37,167.87,-0.375
34.39,167.68,-0.375
34.41,167.48,-0.375
34.43,167.28,-0.375
34.45,167.08,-0.376
34.47,166.88,-0.376
34.49,166.68,-0.376
34.51,166.48,-0.376
34.53,166.28,-0.376
34.55,166.08,-0.376
34.57,165.88,-0.376
34.59,165.68,-0.376
34.61,165.48,-0.376
34.63,165.28,-0.376
34.65,165.08,-0.376
34.67,164.88,-0.376
34.69,164.68,-0.376
34.71,164.48,-0.376
34.73,164.28,-0.376
34.75,164.08,-0.377
34.77,163.88,-0.377
34.79,163.68,-0.377
34.81,163.48,-0.377
34.83,163.28,-0.377
34.85,163.08,-0.377
34.87,162.88,-0.377
34.89,162.68,-0.377
34.91,162.48,-0.377
34.93,162.28,-0.378
34.95,162.08,-0.378
34.97,161.88,-0.378
34.99,161.68,-0.378
35.01,161.48,-0.378
35.03,161.28,-0.378
35.05,161.09,-0.378
35.07,160.89,-0.378
35.09,160.68,-0.378
35.11,160.49,-0.378
35.13,160.29,-0.378
35.15,160.09,-0.378
35.17,159.89,-0.378
35.19,159.69,-0.378
35.21,159.49,-0.378
35.23,159.29,-0.378
35.25,159.09,-0.378
35.27,158.89,-0.378
35.29,158.69,-0.378
35.31,158.49,-0.378
35.33,158.29,-0.378
35.35,158.09,-0.378
35.37,157.89,-0.378
35.39,157.69,-0.379
35.41,157.49,-0.379
35.43,157.29,-0.379
35.45,157.09,-0.379
35.47,156.89,-0.379
35.49,156.69,-0.379
35.51,156.49,-0.379
35.53,156.29,-0.379
35.55,156.09,-0.379
35.57,155.89,-0.379
35.59,155.69,-0.379
35.61,155.49,-0.379
35.63,155.29,-0.379
35.65,155.09,-0.379
35.67,154.89,-0.379
35.69,154.69,-0.379
35.71,154.49,-0.379
35.73,154.29,-0.379
35.75,154.09,-0.379
35.77,153.89,-0.379
35.79,153.69,-0.379
35.81,153.49,-0.379
35.83,153.29,-0.379
35.85,153.09,-0.379
35.87,152.90,-0.379
35.89,152.70,-0.379
35.91,152.50,-0.379
35.93,152.30,-0.379
35.95,152.10,-0.379
35.97,151.90,-0.379
35.99,151.70,-0.379
36.01,151.50,-0.379
36.03,151.30,-0.379
36.05,151.10,-0.379
36.07,150.90,-0.379
36.09,150.70,-0.379
36.11,150.50,-0.379
36.13,150.30,-0.379
36.15,150.10,-0.379
36.17,149.90,-0.380
36.19,149.70,-0.380
36.21,149.50,-0.380
36.23,149.30,-0.380
36.25,149.10,-0.380
36.27,148.90,-0.380
36.29,148.70,-0.380
36.31,148.50,-0.380
36.33,148.30,-0.380
36.35,148.10,-0.380
36.37,147.90,-0.380
36.39,147.70,-0.380
36.41,147.50,-0.380
36.43,147.30,-0.380
36.45,147.10,-0.380
36.47,146.90,-0.380
36.49,146.70,-0.380
36.51,146.50,-0.380
36.53,146.30,-0.380
36.55,146.10,-0.380
36.57,145.90,-0.380
36.59,145.70,-0.380
36.61,145.50,-0.380
36.63,145.30,-0.380
36.65,145.10,-0.380
36.67,144.90,-0.380
36.69,144.70,-0.380
36.71,144.50,-0.380
36.73,144.30,-0.380
36.75,144.11,-0.380
36.77,143.91,-0.380
36.79,143.70,-0.380
36.81,143.51,-0.380
36.83,143.31,-0.380
[...]
123.57,14.21,0.286
123.59,14.42,0.286
123.61,14.62,0.287
123.63,14.82,0.287
123.65,15.01,0.287
123.67,15.21,0.287
123.69,15.42,0.287
123.71,15.62,0.288
123.73,15.82,0.288
123.75,16.02,0.288
123.77,16.22,0.288
123.79,16.42,0.288
123.81,16.62,0.289
123.83,16.82,0.289
123.85,17.02,0.289
123.87,17.22,0.289
123.89,17.42,0.289
123.91,17.62,0.289
123.93,17.82,0.290
123.95,18.02,0.290
123.97,18.22,0.290
123.99,18.42,0.290
124.01,18.62,0.290
124.03,18.82,0.291
124.05,19.02,0.291
124.07,19.22,0.291
124.09,19.42,0.291
124.11,19.62,0.291
124.13,19.82,0.291
124.15,20.02,0.291
124.17,20.22,0.291
124.19,20.42,0.291
124.21,20.62,0.291
124.23,20.82,0.292
124.25,21.02,0.292
124.27,21.22,0.292
124.29,21.42,0.292
124.31,21.62,0.293
124.33,21.82,0.293
124.35,22.02,0.293
124.37,22.22,0.293
124.39,22.42,0.293
124.41,22.62,0.294
124.43,22.82,0.294
124.45,23.02,0.294
124.47,23.22,0.294
124.49,23.42,0.295
124.51,23.62,0.295
124.53,23.82,0.295
124.55,24.02,0.295
124.57,24.22,0.296
124.59,24.42,0.296
124.61,24.62,0.296
124.63,24.83,0.296
124.65,25.03,0.296
124.67,25.22,0.297
124.69,25.43,0.297
124.71,25.63,0.297
124.73,25.83,0.297
124.75,26.03,0.297
124.77,26.23,0.298
124.79,26.43,0.298
124.81,26.63,0.298
124.83,26.83,0.298
124.85,27.03,0.299
124.87,27.23,0.299
124.89,27.43,0.299
124.91,27.63,0.299
124.93,27.83,0.300
124.95,28.03,0.300
124.97,28.23,0.300
124.99,28.43,0.300
125.01,28.63,0.300
125.03,28.83,0.301
125.05,29.03,0.301
125.07,29.23,0.301
125.09,29.43,0.301
125.11,29.63,0.302
125.13,29.83,0.302
125.15,30.03,0.302
125.17,30.23,0.302
125.19,30.43,0.302
125.21,30.63,0.303
125.23,30.83,0.303
125.25,31.03,0.303
125.27,31.23,0.303
125.29,31.43,0.303
125.31,31.63,0.304
125.33,31.83,0.304
125.35,32.03,0.304
125.37,32.23,0.304
125.39,32.43,0.305
125.41,32.63,0.305
125.43,32.83,0.305
125.45,33.03,0.305
125.47,33.23,0.305
125.49,33.43,0.306
125.51,33.63,0.306
125.53,33.83,0.306
125.55,34.03,0.306
125.57,34.23,0.307
125.59,34.43,0.307
125.61,34.64,0.307
125.63,34.83,0.307
125.65,35.04,0.308
125.67,35.24,0.308
125.69,35.43,0.308
125.71,35.64,0.308
125.73,35.84,0.309
125.75,36.04,0.309
125.77,36.23,0.309
125.79,36.44,0.309
125.81,36.64,0.309
125.83,36.84,0.310
125.85,37.04,0.310
125.87,37.24,0.310
125.89,37.44,0.310
125.91,37.64,0.310
125.93,37.84,0.311
125.95,38.04,0.311
125.97,38.24,0.311
125.99,38.44,0.311
126.01,38.64,0.311
126.03,38.84,0.312
126.05,39.04,0.312
126.07,39.24,0.312
126.09,39.44,0.312
126.11,39.64,0.312
126.13,39.84,0.313
126.15,40.04,0.313
126.17,40.24,0.313
126.19,40.44,0.313
126.21,40.64,0.314
126.23,40.84,0.314
126.25,41.04,0.314
126.27,41.24,0.314
126.29,41.44,0.314
126.31,41.64,0.315
126.33,41.84,0.315
126.35,42.04,0.315
126.37,42.24,0.315
126.39,42.44,0.316
126.41,42.64,0.316
126.43,42.84,0.316
126.45,43.04,0.316
126.47,43.24,0.317
126.49,43.44,0.317
126.51,43.64,0.317
126.53,43.84,0.318
126.55,44.04,0.318
126.57,44.24,0.318
126.59,44.44,0.318
126.61,44.64,0.318
126.63,44.84,0.319
126.65,45.04,0.319
126.67,45.24,0.319
126.69,45.44,0.319
126.71,45.64,0.319
126.73,45.84,0.320
126.75,46.04,0.320
126.77,46.24,0.320
126.79,46.45,0.320
126.81,46.64,0.321
126.83,46.85,0.321
126.85,47.04,0.321
126.87,47.25,0.322
126.89,47.45,0.322
126.91,47.65,0.322
126.93,47.85,0.322
126.95,48.05,0.323
126.97,48.25,0.323
126.99,48.45,0.323
127.01,48.65,0.323
127.03,48.85,0.323
127.05,49.05,0.324
127.07,49.25,0.325
127.09,49.45,0.325
127.11,49.65,0.325
127.13,49.85,0.325
127.15,50.05,0.325
127.17,50.25,0.326
127.19,50.45,0.326
127.21,50.65,0.326
127.23,50.85,0.326
127.25,51.05,0.326
127.27,51.25,0.327
127.29,51.45,0.327
127.31,51.65,0.327
127.33,51.85,0.327
127.35,52.05,0.328
127.37,52.25,0.328
127.39,52.45,0.328
127.41,52.65,0.329
127.43,52.85,0.329
127.45,53.05,0.329
127.47,53.25,0.329
127.49,53.45,0.329
127.51,53.65,0.330
127.53,53.85,0.330
127.55,54.05,0.330
127.57,54.25,0.330
127.59,54.45,0.331
127.61,54.65,0.331
127.63,54.85,0.331
127.65,55.05,0.331
127.67,55.25,0.331
127.69,55.45,0.332
127.71,55.65,0.332
127.73,55.85,0.332
127.75,56.05,0.333
127.77,56.25,0.333
127.79,56.45,0.333
127.81,56.65,0.333
127.83,56.85,0.334
127.85,57.05,0.334
127.87,57.25,0.334
127.89,57.46,0.335
127.91,57.65,0.335
127.93,57.86,0.335
127.95,58.06,0.335
127.97,58.26,0.336
127.99,58.46,0.336
128.01,58.66,0.336
128.03,58.86,0.336
128.05,59.06,0.336
128.07,59.26,0.337
128.09,59.46,0.337
128.11,59.66,0.337
128.13,59.86,0.338
128.15,60.06,0.338
128.17,60.26,0.338
128.19,60.46,0.338
128.21,60.66,0.338
128.23,60.86,0.339
128.25,61.06,0.339
128.27,61.26,0.340
128.29,61.46,0.340
128.31,61.66,0.341
128.33,61.86,0.341
128.35,62.06,0.341
128.37,62.26,0.341
128.39,62.46,0.341
128.41,62.66,0.341
128.43,62.86,0.341
128.45,63.06,0.342
128.47,63.26,0.342
128.49,63.46,0.342
128.51,63.66,0.342
128.53,63.86,0.342
128.55,64.06,0.342
128.57,64.26,0.343
128.59,64.46,0.343
128.61,64.66,0.343
128.63,64.86,0.343
128.65,65.06,0.343
128.67,65.26,0.344
128.69,65.46,0.344
128.71,65.66,0.344
128.73,65.86,0.345
128.75,66.06,0.345
128.77,66.26,0.345
128.79,66.46,0.345
128.81,66.66,0.345
128.83,66.86,0.346
128.85,67.06,0.346
128.87,67.26,0.346
128.89,67.46,0.346
128.91,67.66,0.346
128.93,67.86,0.347
128.95,68.07,0.347
128.97,68.26,0.347
128.99,68.47,0.347
129.01,68.67,0.348
129.03,68.87,0.348
129.05,69.07,0.348
129.07,69.27,0.348
129.09,69.47,0.348
129.11,69.67,0.349
129.13,69.87,0.349
129.15,70.07,0.349
129.17,70.27,0.349
129.19,70.47,0.350
129.21,70.67,0.350
129.23,70.87,0.350
129.25,71.07,0.350
129.27,71.27,0.350
129.29,71.47,0.351
129.31,71.67,0.351
129.33,71.87,0.351
129.35,72.07,0.351
129.37,72.27,0.351
129.39,72.47,0.351
129.41,72.67,0.352
129.43,72.87,0.352
129.45,73.07,0.352
129.47,73.27,0.352
129.49,73.47,0.352
129.51,73.67,0.353
129.53,73.87,0.353
129.55,74.07,0.353
129.57,74.27,0.354
129.59,74.47,0.354
129.61,74.67,0.354
129.63,74.87,0.355
129.65,75.07,0.355
129.67,75.27,0.355
129.69,75.47,0.355
129.71,75.67,0.356
129.73,75.87,0.356
129.75,76.07,0.356
129.77,76.27,0.356
129.79,76.47,0.356
129.81,76.67,0.356
129.83,76.87,0.357
129.85,77.07,0.357
129.87,77.27,0.357
129.89,77.47,0.357
129.91,77.67,0.357
129.93,77.87,0.357
129.95,78.07,0.357
129.97,78.27,0.358
129.99,78.47,0.358
130.01,78.67,0.358
130.03,78.87,0.358
130.05,79.07,0.358
130.07,79.28,0.359
130.09,79.47,0.359
130.11,79.67,0.359
130.13,79.88,0.359
130.15,80.07,0.359
130.17,80.27,0.360
130.19,80.47,0.360
130.21,80.67,0.360
130.23,80.87,0.360
130.25,81.08,0.360
130.27,81.28,0.360
130.29,81.48,0.361
130.31,81.68,0.361
130.33,81.88,0.361
130.35,82.08,0.362
130.37,82.28,0.362
130.39,82.48,0.362
130.41,82.68,0.363
130.43,82.88,0.363
130.45,83.08,0.363
130.47,83.28,0.363
130.49,83.48,0.364
130.51,83.68,0.364
130.53,83.88,0.364
130.55,84.08,0.364
130.57,84.28,0.364
130.59,84.48,0.364
130.61,84.68,0.364
130.63,84.88,0.364
130.65,85.08,0.365
130.67,85.28,0.365
130.69,85.48,0.365
130.71,85.68,0.365
130.73,85.88,0.366
130.75,86.08,0.366
130.77,86.28,0.366
130.79,86.48,0.366
130.81,86.68,0.366
130.83,86.88,0.367
130.85,87.08,0.367
130.87,87.28,0.367
130.89,87.48,0.367
130.91,87.68,0.368
130.93,87.88,0.368
130.95,88.08,0.368
130.97,88.28,0.369
130.99,88.48,0.369
131.01,88.68,0.369
131.03,88.88,0.369
131.05,89.08,0.370
131.07,89.28,0.370
131.09,89.48,0.370
131.11,89.68,0.371
131.13,89.88,0.371
131.15,90.08,0.371
131.17,90.28,0.372
131.19,90.48,0.372
131.21,90.68,0.372
131.23,90.88,0.372
131.25,91.08,0.372
131.27,91.28,0.373
131.29,91.48,0.373
131.31,91.68,0.373
131.33,91.88,0.374
131.35,92.08,0.374
131.37,92.28,0.374
131.39,92.48,0.374
131.41,92.69,0.375
131.43,92.89,0.375
131.45,93.09,0.375
131.47,93.29,0.375
131.49,93.49,0.376
131.51,93.68,0.376
131.53,93.88,0.376
131.55,94.09,0.376
131.57,94.29,0.376
131.59,94.49,0.377
131.61,94.68,0.377
131.63,94.88,0.377
131.65,95.08,0.377
131.67,95.28,0.377
131.69,95.48,0.377
131.71,95.68,0.377
131.73,95.88,0.377
131.75,96.09,0.378
131.77,96.29,0.378
131.79,96.49,0.378
131.81,96.69,0.378
131.83,96.89,0.379
131.85,97.09,0.379
131.87,97.29,0.379
131.89,97.49,0.379
131.91,97.69,0.379
131.93,97.89,0.380
131.95,98.09,0.380
131.97,98.29,0.380
131.99,98.49,0.381
132.01,98.69,0.381
132.03,98.89,0.381
132.05,99.09,0.381
132.07,99.29,0.381
132.09,99.49,0.382
132.11,99.69,0.382
132.13,99.89,0.382
132.15,100.09,0.382
132.17,100.29,0.382
132.19,100.49,0.383
132.21,100.69,0.383
132.23,100.89,0.383
132.25,101.09,0.383
132.27,101.29,0.384
132.29,101.49,0.384
132.31,101.69,0.384
132.33,101.89,0.384
132.35,102.09,0.384
132.37,102.29,0.384
132.39,102.49,0.385
132.41,102.69,0.385
132.43,102.89,0.385
132.45,103.09,0.385
132.47,103.29,0.385
132.49,103.49,0.385
132.51,103.69,0.386
132.53,103.89,0.386
132.55,104.09,0.386
132.57,104.29,0.386
132.59,104.49,0.387
132.61,104.69,0.387
132.63,104.89,0.387
132.65,105.09,0.388
132.67,105.29,0.388
132.69,105.49,0.388
132.71,105.69,0.388
132.73,105.89,0.388
132.75,106.09,0.388
132.77,106.29,0.389
132.79,106.49,0.389
132.81,106.69,0.389
132.83,106.89,0.389
132.85,107.09,0.389
132.87,107.29,0.389
132.89,107.49,0.390
132.91,107.69,0.390
132.93,107.89,0.390
132.95,108.09,0.390
132.97,108.29,0.390
132.99,108.50,0.390
133.01,108.70,0.391
133.03,108.90,0.391
133.05,109.09,0.392
133.07,109.30,0.392
133.09,109.49,0.392
133.11,109.69,0.392
133.13,109.90,0.392
133.15,110.10,0.392
133.17,110.30,0.392
133.19,110.50,0.393
133.21,110.70,0.393
133.23,110.90,0.393
133.25,111.10,0.394
133.27,111.29,0.394
133.29,111.50,0.394
133.31,111.70,0.394
133.33,111.90,0.394
133.35,112.10,0.394
133.37,112.30,0.395
133.39,112.50,0.395
133.41,112.70,0.395
133.43,112.90,0.395
133.45,113.10,0.396
133.47,113.30,0.396
133.49,113.50,0.396
133.51,113.70,0.397
133.53,113.90,0.397
133.55,114.10,0.397
133.57,114.30,0.397
133.59,114.50,0.397
133.61,114.70,0.397
133.63,114.90,0.397
133.65,115.10,0.397
133.67,115.30,0.398
133.69,115.50,0.398
133.71,115.70,0.398
133.73,115.90,0.399
133.75,116.10,0.399
133.77,116.30,0.399
133.79,116.50,0.399
133.81,116.70,0.400
133.83,116.90,0.400
133.85,117.10,0.400
133.87,117.30,0.400
133.89,117.50,0.400
133.91,117.70,0.400
133.93,117.90,0.400
133.95,118.10,0.401
133.97,118.30,0.401
133.99,118.50,0.401
134.01,118.70,0.401
134.03,118.90,0.401
134.05,119.10,0.402
134.07,119.30,0.402
134.09,119.50,0.402
134.11,119.70,0.402
134.13,119.90,0.403
134.15,120.10,0.403
134.17,120.30,0.403
134.19,120.50,0.403
134.21,120.70,0.404
134.23,120.90,0.404
134.25,121.10,0.404
134.27,121.30,0.404
134.29,121.50,0.404
134.31,121.70,0.405
134.33,121.90,0.405
134.35,122.10,0.405
134.37,122.30,0.405
134.39,122.50,0.405
134.41,122.70,0.406
134.43,122.90,0.406
134.45,123.10,0.406
134.47,123.30,0.406
134.49,123.51,0.406
134.51,123.71,0.407
134.53,123.91,0.407
134.55,124.11,0.407
134.57,124.31,0.407
134.59,124.51,0.408
134.61,124.71,0.408
134.63,124.91,0.408
134.65,125.11,0.409
134.67,125.31,0.409
134.69,125.51,0.409
134.71,125.71,0.409
134.73,125.91,0.409
134.75,126.11,0.409
134.77,126.31,0.410
134.79,126.51,0.410
134.81,126.71,0.410
134.83,126.91,0.410
134.85,127.11,0.411
134.87,127.31,0.411
134.89,127.51,0.411
134.91,127.71,0.411
134.93,127.91,0.411
134.95,128.11,0.411
134.97,128.31,0.411
134.99,128.51,0.412
135.01,128.71,0.412
135.03,128.91,0.412
135.05,129.11,0.412
135.07,129.31,0.413
135.09,129.51,0.413
135.11,129.71,0.413
135.13,129.91,0.414
135.15,130.11,0.414
135.17,130.31,0.414
135.19,130.51,0.414
135.21,130.71,0.414
135.23,130.91,0.415
135.25,131.11,0.415
135.27,131.31,0.415
135.29,131.51,0.415
135.31,131.71,0.415
135.33,131.91,0.416
135.35,132.11,0.416
135.37,132.31,0.416
135.39,132.51,0.416
135.41,132.71,0.416
135.43,132.91,0.417
135.45,133.11,0.417
135.47,133.31,0.417
135.49,133.51,0.417
135.51,133.71,0.417
135.53,133.91,0.418
135.55,134.11,0.418
135.57,134.31,0.418
135.59,134.51,0.418
135.61,134.71,0.419
135.63,134.91,0.419
135.65,135.11,0.419
135.67,135.31,0.419
135.69,135.51,0.419
135.71,135.71,0.419
135.73,135.91,0.420
135.75,136.11,0.420
135.77,136.31,0.420
135.79,136.51,0.420
135.81,136.71,0.420
135.83,136.91,0.420
135.85,137.11,0.420
135.87,137.31,0.421
135.89,137.51,0.421
135.91,137.71,0.422
135.93,137.91,0.422
135.95,138.11,0.422
135.97,138.31,0.422
135.99,138.51,0.423
136.01,138.71,0.423
136.03,138.91,0.423
136.05,139.11,0.423
136.07,139.31,0.424
136.09,139.51,0.424
136.11,139.71,0.424
136.13,139.91,0.424
136.15,140.11,0.424
136.17,140.31,0.424
136.19,140.51,0.424
136.21,140.72,0.425
136.23,140.92,0.425
136.25,141.12,0.425
136.27,141.32,0.425
136.29,141.51,0.426
136.31,141.72,0.426
136.33,141.92,0.426
136.35,142.12,0.426
136.37,142.32,0.426
136.39,142.52,0.427
136.41,142.72,0.427
136.43,142.92,0.427
136.45,143.12,0.427
136.47,143.32,0.427
136.49,143.52,0.428
136.51,143.72,0.428
136.53,143.92,0.428
136.55,144.12,0.428
136.57,144.32,0.429
136.59,144.52,0.429
136.61,144.72,0.429
136.63,144.92,0.429
136.65,145.12,0.430
136.67,145.32,0.430
136.69,145.52,0.430
136.71,145.72,0.430
136.73,145.92,0.430
136.75,146.12,0.430
136.77,146.32,0.431
136.79,146.52,0.431
136.81,146.72,0.431
136.83,146.92,0.431
136.85,147.12,0.431
136.87,147.32,0.431
136.89,147.52,0.432
136.91,147.72,0.432
136.93,147.92,0.432
136.95,148.12,0.432
136.97,148.32,0.433
136.99,148.52,0.433
137.01,148.72,0.433
137.03,148.92,0.433
137.05,149.12,0.433
137.07,149.32,0.433
137.09,149.52,0.434
137.11,149.72,0.434
137.13,149.92,0.434
137.15,150.12,0.434
137.17,150.32,0.435
137.19,150.52,0.435
137.21,150.72,0.435
137.23,150.92,0.435
137.25,151.12,0.436
137.27,151.32,0.436
137.29,151.52,0.436
137.31,151.72,0.436
137.33,151.92,0.436
137.35,152.12,0.436
137.37,152.32,0.437
137.39,152.52,0.437
137.41,152.72,0.437
137.43,152.92,0.437
137.45,153.12,0.437
137.47,153.32,0.438
137.49,153.52,0.438
137.51,153.72,0.438
137.53,153.92,0.439
137.55,154.12,0.439
137.57,154.32,0.439
137.59,154.52,0.439
137.61,154.72,0.439
137.63,154.92,0.439
137.65,155.12,0.439
137.67,155.32,0.440
137.69,155.52,0.440
137.71,155.72,0.440
137.73,155.92,0.440
137.75,156.12,0.441
137.77,156.32,0.441
137.79,156.52,0.439
137.81,156.72,0.439
137.83,156.92,0.439
137.85,157.12,0.440
137.87,157.32,0.440
137.89,157.52,0.441
137.91,157.72,0.441
137.93,157.92,0.441
137.95,158.12,0.441
137.97,158.32,0.441
137.99,158.52,0.442
138.01,158.72,0.442
138.03,158.92,0.442
138.05,159.12,0.442
138.07,159.32,0.443
138.09,159.52,0.443
138.11,159.72,0.443
138.13,159.93,0.443
138.15,160.13,0.443
138.17,160.33,0.443
138.19,160.53,0.444
138.21,160.73,0.444
138.23,160.93,0.444
138.25,161.13,0.444
138.27,161.33,0.445
138.29,161.53,0.445
138.31,161.73,0.445
138.33,161.93,0.445
138.35,162.12,0.445
138.37,162.33,0.446
138.39,162.53,0.446
138.41,162.73,0.446
138.43,162.93,0.446
138.45,163.13,0.446
138.47,163.33,0.446
138.49,163.53,0.447
138.51,163.73,0.447
138.53,163.93,0.447
138.55,164.13,0.447
138.57,164.33,0.447
138.59,164.52,0.448
138.61,164.73,0.448
138.63,164.93,0.448
138.65,165.13,0.448
138.67,165.33,0.448
138.69,165.53,0.448
138.71,165.73,0.448
138.73,165.93,0.449
138.75,166.13,0.449
138.77,166.33,0.449
138.79,166.53,0.449
138.81,166.73,0.450
138.83,166.93,0.450
138.85,167.13,0.450
138.87,167.33,0.450
138.89,167.53,0.450
138.91,167.73,0.450
138.93,167.93,0.451
138.95,168.13,0.451
138.97,168.33,0.451
138.99,168.53,0.451
139.01,168.73,0.451
139.03,168.93,0.451
139.05,169.13,0.452
139.07,169.33,0.452
139.09,169.53,0.452
139.11,169.73,0.452
139.13,169.93,0.452
139.15,170.13,0.453
139.17,170.33,0.453
139.19,170.53,0.453
139.21,170.73,0.453
139.23,170.93,0.453
139.25,171.13,0.454
139.27,171.33,0.454
139.29,171.53,0.454
139.31,171.73,0.454
139.33,171.93,0.454
139.35,172.13,0.454
139.37,172.33,0.455
139.39,172.53,0.455
139.41,172.73,0.455
139.43,172.93,0.455
139.45,173.13,0.456
139.47,173.33,0.456
139.49,173.53,0.456
139.51,173.73,0.456
139.53,173.93,0.457
139.55,174.13,0.457
139.57,174.33,0.457
139.59,174.53,0.457
139.61,174.73,0.457
139.63,174.93,0.457
139.65,175.13,0.457
139.67,175.33,0.458
139.69,175.53,0.458
139.71,175.73,0.458
139.73,175.93,0.458
139.75,176.13,0.458
139.77,176.33,0.458
139.79,176.53,0.459
139.81,176.73,0.459
139.83,176.93,0.459
139.85,177.13,0.460
139.87,177.33,0.460
139.89,177.53,0.460
139.91,177.73,0.460
139.93,177.93,0.460
139.95,178.13,0.460
139.97,178.33,0.461
139.99,178.53,0.461
140.01,178.73,0.461
140.03,178.93,0.461
140.05,179.13,0.462
140.07,179.33,0.462
140.09,179.53,0.462
140.11,179.73,0.462
140.13,179.93,0.462
140.15,180.13,0.462
140.17,180.33,0.463
140.19,180.53,0.463
140.21,180.73,0.463
140.23,180.93,0.463
140.25,181.13,0.463
140.27,181.33,0.463
140.29,181.53,0.464
140.31,181.74,0.464
140.33,181.93,0.464
140.35,182.13,0.464
140.37,182.34,0.464
140.39,182.53,0.465
140.41,182.73,0.465
140.43,182.93,0.465
140.45,183.14,0.465
140.47,183.33,0.465
140.49,183.54,0.465
140.51,183.74,0.466
140.53,183.94,0.466
140.55,184.14,0.466
140.57,184.34,0.466
140.59,184.54,0.466
140.61,184.74,0.467
140.63,184.94,0.467
140.65,185.14,0.467
140.67,185.34,0.467
140.69,185.54,0.467
140.71,185.74,0.467
140.73,185.94,0.468
140.75,186.14,0.468
140.77,186.34,0.468
140.79,186.54,0.468
140.81,186.74,0.468
140.83,186.94,0.468
140.85,187.14,0.469
140.87,187.34,0.469
140.89,187.54,0.469
140.91,187.74,0.469
140.93,187.94,0.469
140.95,188.14,0.469
140.97,188.34,0.470
140.99,188.54,0.470
141.01,188.74,0.470
141.03,188.94,0.470
141.05,189.14,0.471
141.07,189.34,0.471
141.09,189.54,0.471
141.11,189.74,0.471
141.13,189.94,0.471
141.15,190.14,0.471
141.17,190.34,0.471
141.19,190.54,0.471
141.21,190.74,0.472
141.23,190.94,0.472
141.25,191.14,0.472
141.27,191.34,0.472
141.29,191.54,0.472
141.31,191.74,0.473
141.33,191.94,0.473
141.35,192.14,0.473
141.37,192.34,0.473
141.39,192.54,0.473
141.41,192.74,0.473
141.43,192.94,0.474
141.45,193.14,0.474
141.47,193.34,0.474
141.49,193.54,0.474
141.51,193.74,0.475
141.53,193.94,0.475
141.55,194.14,0.475
141.57,194.34,0.475
141.59,194.54,0.475
141.61,194.74,0.475
141.63,194.94,0.475
141.65,195.14,0.476
141.67,195.34,0.476
141.69,195.54,0.476
141.71,195.74,0.476
141.73,195.94,0.476
141.75,196.14,0.476
141.77,196.34,0.477
141.79,196.54,0.477
141.81,196.74,0.477
141.83,196.94,0.477
141.85,197.14,0.477
141.87,197.34,0.477
141.89,197.54,0.477
141.91,197.74,0.478
141.93,197.94,0.478
141.95,198.14,0.478
141.97,198.34,0.478
141.99,198.54,0.478
142.01,198.74,0.478
142.03,198.94,0.479
142.05,199.14,0.479
142.07,199.34,0.479
142.09,199.54,0.479
142.11,199.74,0.480
142.13,199.94,0.480
142.15,200.14,0.480
142.17,200.34,0.480
142.19,200.54,0.480
142.21,200.74,0.480
142.23,200.94,0.481
142.25,201.14,0.481
142.27,201.34,0.481
142.29,201.54,0.481
142.31,201.74,0.481
142.33,201.94,0.482
142.35,202.14,0.482
142.37,202.34,0.482
142.39,202.54,0.482
142.41,202.74,0.482
142.43,202.94,0.482
142.45,203.14,0.482
142.47,203.34,0.482
142.49,203.54,0.483
142.51,203.74,0.483
142.53,203.94,0.483
142.55,204.14,0.483
142.57,204.34,0.483
142.59,204.54,0.483
142.61,204.74,0.483
142.63,204.94,0.483
142.65,205.14,0.484
142.67,205.34,0.484
142.69,205.54,0.484
142.71,205.75,0.484
142.73,205.94,0.484
142.75,206.15,0.484
142.77,206.35,0.484
142.79,206.55,0.484
142.81,206.75,0.485
142.83,206.95,0.485
142.85,207.14,0.485
142.87,207.35,0.485
142.89,207.55,0.485
142.91,207.75,0.485
142.93,207.95,0.485
142.95,208.15,0.486
142.97,208.35,0.486
142.99,208.55,0.486
143.01,208.75,0.486
143.03,208.95,0.486
143.05,209.15,0.486
143.07,209.35,0.487
143.09,209.55,0.487
143.11,209.75,0.487
143.13,209.95,0.487
143.15,210.15,0.487
143.17,210.35,0.487
143.19,210.55,0.487
143.21,210.75,0.487
143.23,210.95,0.487
143.25,211.15,0.487
143.27,211.35,0.488
143.29,211.55,0.488
143.31,211.75,0.488
143.33,211.95,0.488
143.35,212.15,0.488
143.37,212.35,0.488
143.39,212.55,0.488
143.41,212.75,0.488
143.43,212.95,0.488
143.45,213.15,0.488
143.47,213.35,0.488
143.49,213.55,0.488
143.51,213.75,0.489
143.53,213.95,0.489
143.55,214.15,0.489
143.57,214.35,0.489
143.59,214.55,0.489
143.61,214.75,0.489
143.63,214.95,0.489
143.65,215.15,0.489
143.67,215.35,0.489
143.69,215.55,0.490
143.71,215.75,0.490
143.73,215.95,0.490
143.75,216.15,0.490
143.77,216.35,0.490
143.79,216.55,0.490
143.81,216.75,0.490
143.83,216.95,0.490
143.85,217.15,0.491
143.87,217.35,0.491
143.89,217.55,0.491
143.91,217.75,0.491
143.93,217.95,
143.95,218.15,
143.97,218.35,
143.99,,