File: DSC/2025_07_16_CBD_n60_90_10Cmin_x4.csv
Filename,2025_07_16_CBD_n60_90_10Cmin_x4
Instrument name,DSC2A-00468 (192.168.1.100)
Operator,Gibbons
rundate,7/16/2025
Sample name,2025_07_16_CBD_n60_90_10Cmin_x4
proceduresegments,Data Off ; Equilibrate -60.00 °C; Data On ; Ramp 10.00 °C/min to 90.00 °C; Data Off ; Isothermal 2.0 min; Data On ; Ramp 10.00 °C/min to -60.00 °C; Data Off ; Isothermal 2.0 min; Data On ; Ramp 10.00 °C/min to 90.00 °C; Data Off ; Isothermal 2.0 min; Data On ; Ramp 10.00 °C/min to -60.00 °C; Data Off ; Isothermal 2.0 min; Data On ; Ramp 10.00 °C/min to 90.00 °C; Data Off ; Isothermal 2.0 min; Data On ; Ramp 10.00 °C/min to -60.00 °C; Data Off ; Isothermal 2.0 min; Data On ; Ramp 10.00 °C/min to 30.00 °C
[File Parameters]
Run date,7/16/2025 4:15:17 PM
Trios version,5.1.1.46572
Original File Name,
Current File Name,D:\DSC2500\Gibbons\2025_07_16_CBD_n60_90_10Cmin_x4.tri
[Procedure]
Procedure Name,CBD_n60_90_10Cmin_x4
Sample Name,2025_07_16_CBD_n60_90_10Cmin_x4
Sample Mass,6.94 mg
Reference Sample Mass,0 mg
Pan Mass,57.39 mg
Pan Number,11
Reference Pan Mass,56.6 mg
Reference Pan Number,1
Pan Type,Tzero Aluminum Hermetic
Comments,DSC Consumables Al Hermetically Sealed Pan. Y1 Tray (Google Sheet: DSC_Samples_Y1_Tray_June2025).
Project Name,Pharmaceuticals - Cannabinoids
Operator,Gibbons
Test,Custom
Unload Max Temperature,30
Unload Min Temperature,30
Load Max Temperature,30
Load Min Temperature,30
Stop on Gas Flow Error,Yes
[Signal List]
Signal #1,Time (min)
Signal #2,Temperature (°C)
Signal #3,Heat Flow (mW)
Signal #4,Delta T (µV)
Signal #5,Delta Tzero (µV)
Signal #6,Tzero Temperature (°C)
Signal #7,Cell Purge (mL/min)
Signal #8,Heater Temp (°C)
Signal #9,Power Delivered (W)
Signal #10,Reference Junction Temperature (°C)
Signal #11,Flange Temperature (°C)
Signal #12,Heat Flow Phase (rad)
Signal #13,Total Heat Capacity (J/°C)
Signal #14,Heat Capacity (J/°C)
[Configuration]
Company Name,ASU
Instrument Name,DSC2A-00468
Instrument Type,DSC2500
Serial Number,DSC2A-00468
IP,192.168.1.100
Location of Instrument,MRRC
DisplayType,Unknown
Sample Interval ,0.1 s/pt
Selected Heat Flow,T4P
Exotherm Direction,Down
Cell Serial,DRC2-00792
Lid Type,Standard
Cooler,RCS 90
Leave Cooler on at End of Sequence,On
Gas 2,Nitrogen
Gas Selected,Channel 1
Flow Rate,50 mL/min
Secondary Purge,On
Licensed Heat Flow,Heat Flow T4P
Modulation Licensed,Yes
[Versions]
Common IDD Version,1
Cortex Version,VER 2.10.2.31
Driver,5.0.0.6
GDM Version,1.0.3.3
TouchscreenVersion,1.0.0.16145
FEP Version,1.2.1.21
FEP Bootloader,2.0.0.5
AutoSampler Version,2.1.1.26
Auto Sampler Bootloader,2.0.0.5
FCM Version,1.1.0.3
FCM Bootloader,2.0.0.5
[Experiment Logs]
Experiment Log Entry # 1,Data On set to 0
Experiment Log Entry # 3,Equilibrate Segment -60 (C) Started
Experiment Log Entry # 5,Air Cool is off.
Experiment Log Entry # 7,Data On set to 1
Experiment Log Entry # 9,Ramp Segment 10 C/min to 90 Started
Experiment Log Entry # 11,Data On set to 0
Experiment Log Entry # 13,Isothermal Segment 2 min started
Experiment Log Entry # 15,Data On set to 1
Experiment Log Entry # 17,Ramp Segment 10 C/min to -60 Started
Experiment Log Entry # 19,Data On set to 0
Experiment Log Entry # 21,Isothermal Segment 2 min started
Experiment Log Entry # 23,Data On set to 1
Experiment Log Entry # 25,Ramp Segment 10 C/min to 90 Started
Experiment Log Entry # 27,Data On set to 0
Experiment Log Entry # 29,Isothermal Segment 2 min started
Experiment Log Entry # 31,Data On set to 1
Experiment Log Entry # 33,Ramp Segment 10 C/min to -60 Started
Experiment Log Entry # 35,Data On set to 0
Experiment Log Entry # 37,Isothermal Segment 2 min started
Experiment Log Entry # 39,Data On set to 1
Experiment Log Entry # 41,Ramp Segment 10 C/min to 90 Started
Experiment Log Entry # 43,Data On set to 0
Experiment Log Entry # 45,Isothermal Segment 2 min started
Experiment Log Entry # 47,Data On set to 1
Experiment Log Entry # 49,Ramp Segment 10 C/min to -60 Started
Experiment Log Entry # 51,Data On set to 0
Experiment Log Entry # 53,Isothermal Segment 2 min started
Experiment Log Entry # 55,Data On set to 1
Experiment Log Entry # 57,Ramp Segment 10 C/min to 30 Started
[Method Log]
Method Log Entry # 1,Data Off
Method Log Entry # 2,Equilibrate -60 °C
Method Log Entry # 3,Data On
Method Log Entry # 4,(Ramp 58033) Ramp 10 °C/minute to 90 °C
Method Log Entry # 5,Data Off
Method Log Entry # 6,Isothermal 2 minutes
Method Log Entry # 7,Data On
Method Log Entry # 8,(Ramp 58037) Ramp 10 °C/minute to -60 °C
Method Log Entry # 9,Data Off
Method Log Entry # 10,Isothermal 2 minutes
Method Log Entry # 11,Data On
Method Log Entry # 12,(Ramp 58041) Ramp 10 °C/minute to 90 °C
Method Log Entry # 13,Data Off
Method Log Entry # 14,Isothermal 2 minutes
Method Log Entry # 15,Data On
Method Log Entry # 16,(Ramp 58045) Ramp 10 °C/minute to -60 °C
Method Log Entry # 17,Data Off
Method Log Entry # 18,Isothermal 2 minutes
Method Log Entry # 19,Data On
Method Log Entry # 20,(Ramp 58049) Ramp 10 °C/minute to 90 °C
Method Log Entry # 21,Data Off
Method Log Entry # 22,Isothermal 2 minutes
Method Log Entry # 23,Data On
Method Log Entry # 24,(Ramp 58053) Ramp 10 °C/minute to -60 °C
Method Log Entry # 25,Data Off
Method Log Entry # 26,Isothermal 2 minutes
Method Log Entry # 27,Data On
Method Log Entry # 28,(Ramp 58057) Ramp 10 °C/minute to 30 °C
Cell Serial,DRC2-00792
[T1 Calibration]
Slope,-0.008529666
Offset,9.636258
Initial Temperature,98.23
GUID,f8bfdadc-4977-4fdf-ba6d-0ba9134940c3
[TZero Calibration]
Date Applied,11/29/2022 4:06:13 PM
Description,From -89.059 °C to 396.009 °C at 20.000°C/min
Gas Type,Nitrogen
Pan Type,None
Source Files 1,C:\Users\yargerlab\Desktop\DSC Data\General\TZero_calibration_11_29_22_2nd(2).tri
Source Files 2,C:\Users\yargerlab\Desktop\DSC Data\General\TZero_calibration_11_29_22_2nd(3).tri
Delta T Offset,13.05235
Delta T Slope,-0.007271007
Delta T0 Offset,-13.69128
Delta T0 Slope,0.06063341
[Temperature Calibration]
Date Applied,11/29/2022 7:12:28 PM
Description,From 106.590 °C to 186.590 °C at 10.000°C/min
Gas Type,Nitrogen
Pan Type,Tzero Aluminum Hermetic
Source Files 1,C:\Users\yargerlab\Desktop\DSC Data\General\Indium(6).tri
Measured 1,157.391
Known 1,156.598
[Cell Constant Calibration]
Date Applied,11/29/2022 7:12:29 PM
Description,From 106.590 °C to 186.590 °C at 10.000°C/min
Gas Type,Nitrogen
Pan Type,Tzero Aluminum Hermetic
Source Files 1,C:\Users\yargerlab\Desktop\DSC Data\General\Indium(6).tri
T4P KCell,1.006051
Onset Slope,63.26126 mW/°C
[Direct Cp Calibration]
Date Applied,11/30/2022 11:04:51 AM
Description,From -79.983 °C to 298.409 °C at 10.000°C/min
Gas Type,Nitrogen
Pan Type,Tzero Aluminum Hermetic
Source Files 1,C:\Users\yargerlab\Desktop\DSC Data\General\Sapphire_Heat_Capacity_11_30_22.tri
[Rev Cp Calibration]
Date Applied,11/30/2022 1:58:51 PM
Description,From -79.996 °C to 292.812 °C at 3.000°C/min
Gas Type,Nitrogen
Pan Type,Tzero Aluminum Hermetic
Source Files 1,C:\Users\yargerlab\Desktop\DSC Data\General\Sapphire_MDSC_Calibration_11_30_22.tri
[step]
Ramp 10.00 °C/min to 90.00 °C
Time,Temperature,Heat Flow (Normalized)
min,°C,W/g
0.00,-59.71,-0.044
0.01,-59.72,-0.044
0.02,-59.73,-0.042
0.03,-59.73,-0.039
0.04,-59.74,-0.036
0.05,-59.74,-0.032
0.06,-59.73,-0.030
0.07,-59.73,-0.027
0.08,-59.71,-0.024
0.09,-59.70,-0.020
0.10,-59.67,-0.014
0.11,-59.65,-0.010
0.12,-59.61,-0.004
0.13,-59.57,0.003
0.14,-59.52,0.010
0.15,-59.47,0.019
0.16,-59.42,0.028
0.17,-59.36,0.037
0.18,-59.29,0.046
0.19,-59.23,0.055
0.20,-59.16,0.065
0.21,-59.09,0.074
0.22,-59.01,0.083
0.23,-58.93,0.091
0.24,-58.86,0.099
0.25,-58.78,0.107
0.26,-58.69,0.114
0.27,-58.61,0.120
0.28,-58.53,0.126
0.29,-58.44,0.132
0.30,-58.36,0.138
0.31,-58.27,0.143
0.32,-58.18,0.146
0.33,-58.09,0.150
0.34,-58.00,0.154
0.35,-57.91,0.158
0.36,-57.82,0.162
0.37,-57.73,0.163
0.38,-57.64,0.168
0.39,-57.55,0.168
0.40,-57.46,0.173
0.41,-57.36,0.174
0.42,-57.27,0.176
0.43,-57.18,0.177
0.44,-57.08,0.179
0.45,-56.99,0.181
0.46,-56.89,0.182
0.47,-56.80,0.185
0.48,-56.71,0.185
0.49,-56.61,0.186
0.50,-56.51,0.187
0.51,-56.42,0.188
0.52,-56.32,0.190
0.53,-56.23,0.190
0.54,-56.13,0.190
0.55,-56.03,0.191
0.56,-55.94,0.193
0.57,-55.84,0.194
0.58,-55.74,0.194
0.59,-55.65,0.194
0.60,-55.55,0.195
0.61,-55.45,0.195
0.62,-55.36,0.195
0.63,-55.26,0.196
0.64,-55.16,0.196
0.65,-55.06,0.196
0.66,-54.97,0.197
0.67,-54.87,0.197
0.68,-54.77,0.198
0.69,-54.67,0.198
0.70,-54.57,0.198
0.71,-54.48,0.198
0.72,-54.38,0.199
0.73,-54.28,0.199
0.74,-54.18,0.199
0.75,-54.08,0.199
0.76,-53.99,0.200
0.77,-53.89,0.200
0.78,-53.79,0.200
0.79,-53.69,0.200
0.80,-53.59,0.200
0.81,-53.49,0.200
0.82,-53.39,0.200
0.83,-53.30,0.200
0.84,-53.20,0.200
0.85,-53.10,0.201
0.86,-53.00,0.201
0.87,-52.90,0.201
0.88,-52.80,0.201
0.89,-52.70,0.201
0.90,-52.60,0.201
0.91,-52.51,0.201
0.92,-52.41,0.202
0.93,-52.31,0.202
0.94,-52.21,0.202
0.95,-52.11,0.202
0.96,-52.01,0.202
0.97,-51.91,0.202
0.98,-51.81,0.202
0.99,-51.71,0.202
1.00,-51.61,0.203
1.01,-51.52,0.203
1.02,-51.42,0.203
1.03,-51.32,0.203
1.04,-51.22,0.203
1.05,-51.12,0.203
1.06,-51.02,0.203
1.07,-50.92,0.203
1.08,-50.82,0.204
1.09,-50.72,0.204
1.10,-50.62,0.204
1.11,-50.52,0.204
1.12,-50.42,0.204
1.13,-50.32,0.204
1.14,-50.22,0.204
1.15,-50.12,0.204
1.16,-50.03,0.204
1.17,-49.93,0.204
1.18,-49.83,0.205
1.19,-49.73,0.205
1.20,-49.63,0.205
1.21,-49.53,0.205
1.22,-49.43,0.205
1.23,-49.33,0.205
1.24,-49.23,0.205
1.25,-49.13,0.205
1.26,-49.03,0.205
1.27,-48.93,0.205
1.28,-48.83,0.205
1.29,-48.73,0.206
1.30,-48.63,0.206
1.31,-48.53,0.206
1.32,-48.43,0.206
1.33,-48.33,0.206
1.34,-48.23,0.206
1.35,-48.13,0.206
1.36,-48.03,0.206
1.37,-47.93,0.206
1.38,-47.84,0.206
1.39,-47.74,0.206
1.40,-47.64,0.206
1.41,-47.54,0.206
1.42,-47.43,0.207
1.43,-47.33,0.207
1.44,-47.24,0.207
1.45,-47.13,0.207
1.46,-47.04,0.207
1.47,-46.94,0.207
1.48,-46.83,0.207
1.49,-46.74,0.207
1.50,-46.64,0.207
1.51,-46.54,0.207
1.52,-46.44,0.207
1.53,-46.34,0.207
1.54,-46.24,0.207
1.55,-46.14,0.208
1.56,-46.04,0.208
1.57,-45.94,0.208
1.58,-45.84,0.208
1.59,-45.74,0.208
1.60,-45.64,0.208
1.61,-45.54,0.208
1.62,-45.44,0.208
1.63,-45.34,0.208
1.64,-45.24,0.208
1.65,-45.14,0.208
1.66,-45.04,0.208
1.67,-44.94,0.208
1.68,-44.84,0.208
1.69,-44.74,0.208
1.70,-44.64,0.209
1.71,-44.54,0.209
1.72,-44.44,0.209
1.73,-44.34,0.209
1.74,-44.24,0.209
1.75,-44.14,0.209
1.76,-44.04,0.209
1.77,-43.94,0.209
1.78,-43.84,0.209
1.79,-43.74,0.209
1.80,-43.64,0.209
1.81,-43.54,0.209
1.82,-43.44,0.209
1.83,-43.34,0.209
1.84,-43.24,0.209
1.85,-43.14,0.209
1.86,-43.04,0.209
1.87,-42.94,0.210
1.88,-42.84,0.210
1.89,-42.74,0.210
1.90,-42.64,0.210
1.91,-42.54,0.210
1.92,-42.44,0.210
1.93,-42.34,0.210
1.94,-42.24,0.210
1.95,-42.14,0.210
1.96,-42.04,0.210
1.97,-41.94,0.210
1.98,-41.84,0.210
1.99,-41.74,0.210
2.00,-41.64,0.210
2.01,-41.54,0.210
2.02,-41.44,0.210
2.03,-41.34,0.210
2.04,-41.23,0.211
2.05,-41.13,0.211
2.06,-41.03,0.211
2.07,-40.93,0.211
2.08,-40.83,0.211
2.09,-40.73,0.211
2.10,-40.63,0.211
2.11,-40.53,0.211
2.12,-40.44,0.211
2.13,-40.33,0.211
2.14,-40.23,0.211
2.15,-40.13,0.211
2.16,-40.03,0.211
2.17,-39.93,0.211
2.18,-39.83,0.211
2.19,-39.73,0.211
2.20,-39.63,0.211
2.21,-39.53,0.211
2.22,-39.43,0.211
2.23,-39.33,0.211
2.24,-39.23,0.211
2.25,-39.13,0.212
2.26,-39.03,0.212
2.27,-38.93,0.212
2.28,-38.83,0.212
2.29,-38.73,0.212
2.30,-38.63,0.212
2.31,-38.53,0.212
2.32,-38.43,0.212
2.33,-38.33,0.212
2.34,-38.23,0.212
2.35,-38.13,0.212
2.36,-38.03,0.212
2.37,-37.93,0.212
2.38,-37.83,0.212
2.39,-37.73,0.212
2.40,-37.63,0.212
2.41,-37.53,0.212
2.42,-37.43,0.212
2.43,-37.33,0.212
2.44,-37.23,0.213
2.45,-37.13,0.213
2.46,-37.03,0.213
2.47,-36.93,0.213
2.48,-36.83,0.213
2.49,-36.73,0.213
2.50,-36.63,0.213
2.51,-36.53,0.213
2.52,-36.43,0.213
2.53,-36.33,0.213
2.54,-36.23,0.213
2.55,-36.13,0.213
2.56,-36.03,0.213
2.57,-35.93,0.213
2.58,-35.83,0.213
2.59,-35.73,0.213
2.60,-35.63,0.213
2.61,-35.53,0.213
2.62,-35.43,0.213
2.63,-35.33,0.213
2.64,-35.23,0.213
2.65,-35.13,0.214
2.66,-35.03,0.214
2.67,-34.92,0.214
2.68,-34.83,0.214
2.69,-34.73,0.214
2.70,-34.63,0.214
2.71,-34.53,0.214
2.72,-34.42,0.214
2.73,-34.32,0.214
2.74,-34.22,0.214
2.75,-34.12,0.214
2.76,-34.03,0.214
2.77,-33.92,0.214
2.78,-33.82,0.214
2.79,-33.72,0.214
2.80,-33.62,0.214
2.81,-33.52,0.214
2.82,-33.42,0.214
2.83,-33.32,0.214
2.84,-33.22,0.214
2.85,-33.12,0.215
2.86,-33.02,0.215
2.87,-32.92,0.215
2.88,-32.82,0.215
2.89,-32.72,0.215
2.90,-32.62,0.215
2.91,-32.52,0.215
2.92,-32.42,0.215
2.93,-32.32,0.215
2.94,-32.22,0.215
2.95,-32.12,0.215
2.96,-32.02,0.215
2.97,-31.92,0.215
2.98,-31.82,0.215
2.99,-31.72,0.215
3.00,-31.62,0.215
3.01,-31.52,0.215
3.02,-31.42,0.215
3.03,-31.32,0.215
3.04,-31.22,0.215
3.05,-31.12,0.216
3.06,-31.02,0.216
3.07,-30.92,0.216
3.08,-30.82,0.216
3.09,-30.72,0.216
3.10,-30.62,0.216
3.11,-30.52,0.216
3.12,-30.42,0.216
3.13,-30.32,0.216
3.14,-30.22,0.216
3.15,-30.12,0.216
3.16,-30.02,0.216
3.17,-29.92,0.216
3.18,-29.82,0.216
3.19,-29.72,0.216
3.20,-29.62,0.216
3.21,-29.52,0.216
3.22,-29.42,0.216
3.23,-29.32,0.216
3.24,-29.22,0.216
3.25,-29.12,0.216
3.26,-29.02,0.216
3.27,-28.92,0.217
3.28,-28.82,0.217
3.29,-28.72,0.217
3.30,-28.61,0.217
3.31,-28.52,0.217
3.32,-28.42,0.217
3.33,-28.32,0.217
3.34,-28.21,0.217
3.35,-28.12,0.217
3.36,-28.02,0.217
3.37,-27.92,0.217
3.38,-27.81,0.217
3.39,-27.72,0.217
3.40,-27.61,0.217
3.41,-27.51,0.217
3.42,-27.41,0.217
3.43,-27.31,0.217
3.44,-27.21,0.217
3.45,-27.11,0.217
3.46,-27.01,0.217
3.47,-26.91,0.217
3.48,-26.81,0.217
3.49,-26.71,0.217
3.50,-26.61,0.218
3.51,-26.51,0.218
3.52,-26.41,0.218
3.53,-26.31,0.218
3.54,-26.21,0.218
3.55,-26.11,0.218
3.56,-26.01,0.218
3.57,-25.91,0.218
3.58,-25.81,0.218
3.59,-25.71,0.218
3.60,-25.61,0.218
3.61,-25.51,0.218
3.62,-25.41,0.218
3.63,-25.31,0.218
3.64,-25.21,0.218
3.65,-25.11,0.218
3.66,-25.01,0.218
3.67,-24.91,0.218
3.68,-24.81,0.218
3.69,-24.71,0.218
3.70,-24.61,0.218
3.71,-24.51,0.218
3.72,-24.41,0.219
3.73,-24.31,0.219
3.74,-24.21,0.219
3.75,-24.11,0.219
3.76,-24.01,0.219
3.77,-23.91,0.219
3.78,-23.81,0.219
3.79,-23.71,0.219
3.80,-23.61,0.219
3.81,-23.51,0.219
3.82,-23.41,0.219
3.83,-23.31,0.219
3.84,-23.21,0.219
3.85,-23.11,0.219
3.86,-23.01,0.219
3.87,-22.91,0.219
3.88,-22.81,0.219
3.89,-22.71,0.219
3.90,-22.61,0.219
3.91,-22.51,0.219
3.92,-22.41,0.219
3.93,-22.31,0.219
3.94,-22.21,0.219
3.95,-22.11,0.219
3.96,-22.01,0.220
3.97,-21.91,0.220
3.98,-21.81,0.220
3.99,-21.71,0.220
4.00,-21.61,0.220
4.01,-21.51,0.220
4.02,-21.41,0.220
4.03,-21.31,0.220
4.04,-21.21,0.220
4.05,-21.11,0.220
4.06,-21.00,0.220
4.07,-20.90,0.220
4.08,-20.80,0.220
4.09,-20.70,0.220
4.10,-20.60,0.220
4.11,-20.50,0.220
4.12,-20.40,0.220
4.13,-20.31,0.220
4.14,-20.20,0.220
4.15,-20.10,0.220
4.16,-20.00,0.220
4.17,-19.90,0.220
4.18,-19.80,0.221
4.19,-19.70,0.221
4.20,-19.60,0.221
4.21,-19.50,0.221
4.22,-19.40,0.221
4.23,-19.30,0.221
4.24,-19.20,0.221
4.25,-19.10,0.221
4.26,-19.00,0.221
4.27,-18.90,0.221
4.28,-18.80,0.221
4.29,-18.70,0.221
4.30,-18.60,0.221
4.31,-18.50,0.221
4.32,-18.40,0.221
4.33,-18.30,0.221
4.34,-18.20,0.221
4.35,-18.10,0.221
4.36,-18.00,0.221
4.37,-17.90,0.221
4.38,-17.80,0.221
4.39,-17.70,0.221
4.40,-17.60,0.222
4.41,-17.50,0.222
4.42,-17.40,0.222
4.43,-17.30,0.222
4.44,-17.20,0.222
4.45,-17.10,0.222
4.46,-17.00,0.222
4.47,-16.90,0.222
4.48,-16.80,0.222
4.49,-16.70,0.222
4.50,-16.60,0.222
4.51,-16.50,0.222
4.52,-16.40,0.222
4.53,-16.30,0.222
4.54,-16.20,0.222
4.55,-16.10,0.222
4.56,-16.00,0.222
4.57,-15.90,0.222
4.58,-15.80,0.223
4.59,-15.70,0.223
4.60,-15.60,0.223
4.61,-15.50,0.223
4.62,-15.40,0.223
4.63,-15.30,0.223
4.64,-15.20,0.223
4.65,-15.10,0.223
4.66,-15.00,0.223
4.67,-14.90,0.223
4.68,-14.80,0.223
4.69,-14.70,0.223
4.70,-14.60,0.223
4.71,-14.50,0.223
4.72,-14.40,0.223
4.73,-14.30,0.223
4.74,-14.20,0.223
4.75,-14.10,0.223
4.76,-14.00,0.223
4.77,-13.90,0.223
4.78,-13.80,0.224
4.79,-13.70,0.224
4.80,-13.59,0.224
4.81,-13.50,0.224
4.82,-13.40,0.224
4.83,-13.30,0.224
4.84,-13.20,0.224
4.85,-13.10,0.224
4.86,-13.00,0.224
4.87,-12.89,0.224
4.88,-12.79,0.224
4.89,-12.69,0.224
4.90,-12.60,0.224
4.91,-12.49,0.224
4.92,-12.39,0.224
4.93,-12.29,0.224
4.94,-12.19,0.224
4.95,-12.09,0.224
4.96,-11.99,0.224
4.97,-11.89,0.224
4.98,-11.79,0.225
4.99,-11.69,0.225
5.00,-11.59,0.225
5.01,-11.49,0.225
5.02,-11.39,0.225
5.03,-11.29,0.225
5.04,-11.19,0.225
5.05,-11.09,0.225
5.06,-10.99,0.225
5.07,-10.89,0.225
5.08,-10.79,0.225
5.09,-10.69,0.225
5.10,-10.59,0.225
5.11,-10.49,0.225
5.12,-10.39,0.225
5.13,-10.29,0.225
5.14,-10.19,0.225
5.15,-10.09,0.225
5.16,-9.99,0.225
5.17,-9.89,0.226
5.18,-9.79,0.226
5.19,-9.69,0.226
5.20,-9.59,0.226
5.21,-9.49,0.226
5.22,-9.39,0.226
5.23,-9.29,0.226
5.24,-9.19,0.226
5.25,-9.09,0.226
5.26,-8.99,0.226
5.27,-8.89,0.226
5.28,-8.79,0.226
5.29,-8.69,0.226
5.30,-8.59,0.226
5.31,-8.49,0.226
5.32,-8.39,0.226
5.33,-8.29,0.226
5.34,-8.19,0.226
5.35,-8.09,0.226
5.36,-7.99,0.226
5.37,-7.89,0.227
5.38,-7.79,0.227
5.39,-7.69,0.227
5.40,-7.59,0.227
5.41,-7.49,0.227
5.42,-7.39,0.227
5.43,-7.29,0.227
5.44,-7.19,0.227
5.45,-7.09,0.227
5.46,-6.99,0.227
5.47,-6.89,0.227
5.48,-6.79,0.227
5.49,-6.69,0.227
5.50,-6.59,0.227
5.51,-6.49,0.227
5.52,-6.38,0.227
5.53,-6.29,0.227
5.54,-6.19,0.227
5.55,-6.08,0.227
5.56,-5.99,0.227
5.57,-5.88,0.227
5.58,-5.79,0.227
5.59,-5.69,0.228
5.60,-5.58,0.228
5.61,-5.48,0.228
5.62,-5.38,0.228
5.63,-5.29,0.228
5.64,-5.18,0.228
5.65,-5.08,0.228
5.66,-4.98,0.228
5.67,-4.88,0.228
5.68,-4.78,0.228
5.69,-4.68,0.228
5.70,-4.58,0.228
5.71,-4.48,0.228
5.72,-4.38,0.228
5.73,-4.28,0.228
5.74,-4.18,0.228
5.75,-4.08,0.228
5.76,-3.98,0.229
5.77,-3.88,0.229
5.78,-3.78,0.229
5.79,-3.68,0.229
5.80,-3.58,0.229
5.81,-3.48,0.229
5.82,-3.38,0.229
5.83,-3.28,0.229
5.84,-3.18,0.229
5.85,-3.08,0.229
5.86,-2.98,0.229
5.87,-2.88,0.229
5.88,-2.78,0.229
5.89,-2.68,0.229
5.90,-2.58,0.229
5.91,-2.48,0.229
5.92,-2.38,0.229
5.93,-2.28,0.229
5.94,-2.18,0.229
5.95,-2.08,0.229
5.96,-1.98,0.230
5.97,-1.88,0.230
5.98,-1.78,0.230
5.99,-1.68,0.230
6.00,-1.58,0.230
6.01,-1.48,0.230
6.02,-1.38,0.230
6.03,-1.28,0.230
6.04,-1.18,0.230
6.05,-1.08,0.230
6.06,-0.98,0.230
6.07,-0.88,0.230
6.08,-0.78,0.230
6.09,-0.68,0.230
6.10,-0.58,0.230
6.11,-0.48,0.230
6.12,-0.38,0.230
6.13,-0.28,0.230
6.14,-0.18,0.230
6.15,-0.08,0.230
6.16,0.02,0.230
6.17,0.12,0.231
6.18,0.22,0.231
6.19,0.32,0.231
6.20,0.42,0.231
6.21,0.52,0.231
6.22,0.62,0.231
6.23,0.73,0.231
6.24,0.83,0.231
6.25,0.93,0.231
6.26,1.02,0.231
6.27,1.12,0.231
6.28,1.23,0.231
6.29,1.32,0.231
6.30,1.43,0.231
6.31,1.53,0.231
6.32,1.63,0.231
6.33,1.73,0.231
6.34,1.83,0.232
6.35,1.93,0.232
6.36,2.03,0.232
6.37,2.13,0.232
6.38,2.23,0.232
6.39,2.33,0.232
6.40,2.43,0.232
6.41,2.53,0.232
6.42,2.63,0.232
6.43,2.73,0.232
6.44,2.83,0.232
6.45,2.93,0.232
6.46,3.03,0.232
6.47,3.13,0.232
6.48,3.23,0.232
6.49,3.33,0.232
6.50,3.43,0.232
6.51,3.53,0.233
6.52,3.63,0.233
6.53,3.73,0.233
6.54,3.83,0.233
6.55,3.93,0.233
6.56,4.03,0.233
6.57,4.13,0.233
6.58,4.23,0.233
6.59,4.33,0.233
6.60,4.43,0.233
6.61,4.53,0.233
6.62,4.63,0.233
6.63,4.73,0.233
6.64,4.83,0.233
6.65,4.93,0.233
6.66,5.03,0.234
6.67,5.13,0.234
6.68,5.23,0.234
6.69,5.33,0.234
6.70,5.43,0.234
6.71,5.53,0.234
6.72,5.63,0.234
6.73,5.73,0.234
6.74,5.83,0.234
6.75,5.93,0.234
6.76,6.03,0.234
6.77,6.13,0.234
6.78,6.23,0.234
6.79,6.33,0.234
6.80,6.43,0.234
6.81,6.53,0.234
6.82,6.63,0.234
6.83,6.73,0.235
6.84,6.83,0.235
6.85,6.93,0.235
6.86,7.03,0.235
6.87,7.13,0.235
6.88,7.23,0.235
6.89,7.33,0.235
6.90,7.43,0.235
6.91,7.53,0.235
6.92,7.63,0.235
6.93,7.73,0.235
6.94,7.83,0.235
6.95,7.93,0.235
6.96,8.03,0.235
6.97,8.14,0.235
6.98,8.24,0.236
6.99,8.33,0.236
7.00,8.44,0.236
7.01,8.54,0.236
7.02,8.64,0.236
7.03,8.73,0.236
7.04,8.84,0.236
7.05,8.94,0.236
7.06,9.04,0.236
7.07,9.14,0.236
7.08,9.24,0.236
7.09,9.34,0.236
7.10,9.44,0.236
7.11,9.54,0.236
7.12,9.64,0.237
7.13,9.74,0.237
7.14,9.84,0.237
7.15,9.94,0.237
7.16,10.04,0.237
7.17,10.14,0.237
7.18,10.24,0.237
7.19,10.34,0.237
7.20,10.44,0.237
7.21,10.54,0.237
7.22,10.64,0.237
7.23,10.74,0.237
7.24,10.84,0.237
7.25,10.94,0.237
7.26,11.04,0.237
7.27,11.14,0.238
7.28,11.24,0.238
7.29,11.34,0.238
7.30,11.44,0.238
7.31,11.54,0.238
7.32,11.64,0.238
7.33,11.74,0.238
7.34,11.84,0.238
7.35,11.94,0.238
7.36,12.04,0.238
7.37,12.14,0.238
7.38,12.24,0.238
7.39,12.34,0.238
7.40,12.44,0.238
7.41,12.54,0.239
7.42,12.64,0.239
7.43,12.74,0.239
7.44,12.84,0.239
7.45,12.94,0.239
7.46,13.04,0.239
7.47,13.14,0.239
7.48,13.24,0.239
7.49,13.34,0.239
7.50,13.44,0.239
7.51,13.54,0.239
7.52,13.64,0.239
7.53,13.74,0.239
7.54,13.84,0.239
7.55,13.94,0.239
7.56,14.04,0.239
7.57,14.14,0.240
7.58,14.24,0.240
7.59,14.34,0.240
7.60,14.44,0.240
7.61,14.54,0.240
7.62,14.64,0.240
7.63,14.74,0.240
7.64,14.84,0.240
7.65,14.94,0.240
7.66,15.04,0.240
7.67,15.14,0.240
7.68,15.24,0.240
7.69,15.35,0.240
7.70,15.44,0.241
7.71,15.54,0.241
7.72,15.64,0.241
7.73,15.74,0.241
7.74,15.84,0.241
7.75,15.94,0.241
7.76,16.04,0.241
7.77,16.14,0.241
7.78,16.25,0.241
7.79,16.34,0.241
7.80,16.45,0.241
7.81,16.55,0.241
7.82,16.65,0.241
7.83,16.75,0.241
7.84,16.85,0.242
7.85,16.95,0.242
7.86,17.05,0.242
7.87,17.15,0.242
7.88,17.25,0.242
7.89,17.35,0.242
7.90,17.45,0.242
7.91,17.55,0.242
7.92,17.65,0.242
7.93,17.75,0.242
7.94,17.85,0.242
7.95,17.95,0.242
7.96,18.05,0.242
7.97,18.15,0.242
7.98,18.25,0.242
7.99,18.35,0.243
8.00,18.45,0.243
8.01,18.55,0.243
8.02,18.65,0.243
8.03,18.75,0.243
8.04,18.85,0.243
8.05,18.95,0.243
8.06,19.05,0.243
8.07,19.15,0.243
8.08,19.25,0.243
8.09,19.35,0.243
8.10,19.45,0.243
8.11,19.55,0.243
8.12,19.65,0.243
8.13,19.75,0.243
8.14,19.85,0.244
8.15,19.95,0.244
8.16,20.05,0.244
8.17,20.15,0.244
8.18,20.25,0.244
8.19,20.35,0.244
8.20,20.45,0.244
8.21,20.55,0.244
8.22,20.65,0.244
8.23,20.75,0.244
8.24,20.85,0.244
8.25,20.95,0.244
8.26,21.05,0.244
8.27,21.15,0.244
8.28,21.25,0.244
8.29,21.35,0.245
8.30,21.45,0.245
8.31,21.55,0.245
8.32,21.65,0.245
8.33,21.75,0.245
8.34,21.85,0.245
8.35,21.95,0.245
8.36,22.05,0.245
8.37,22.15,0.245
8.38,22.25,0.245
8.39,22.35,0.245
8.40,22.45,0.245
8.41,22.55,0.245
8.42,22.65,0.245
8.43,22.75,0.245
8.44,22.85,0.246
8.45,22.95,0.246
8.46,23.05,0.246
8.47,23.15,0.246
8.48,23.25,0.246
8.49,23.35,0.246
8.50,23.45,0.246
8.51,23.55,0.246
8.52,23.65,0.246
8.53,23.75,0.246
8.54,23.85,0.246
8.55,23.95,0.246
8.56,24.05,0.246
8.57,24.15,0.246
8.58,24.25,0.246
8.59,24.35,0.247
8.60,24.45,0.247
8.61,24.55,0.247
8.62,24.65,0.247
8.63,24.75,0.247
8.64,24.85,0.247
8.65,24.95,0.247
8.66,25.05,0.247
8.67,25.15,0.247
8.68,25.25,0.247
8.69,25.35,0.247
8.70,25.45,0.247
8.71,25.55,0.248
8.72,25.65,0.248
8.73,25.75,0.248
8.74,25.85,0.248
8.75,25.95,0.248
8.76,26.05,0.248
8.77,26.15,0.248
8.78,26.26,0.248
8.79,26.35,0.248
8.80,26.46,0.248
8.81,26.55,0.248
8.82,26.65,0.248
8.83,26.76,0.249
8.84,26.86,0.249
8.85,26.96,0.249
8.86,27.06,0.249
8.87,27.16,0.249
8.88,27.26,0.249
8.89,27.36,0.249
8.90,27.46,0.249
8.91,27.56,0.249
8.92,27.66,0.249
8.93,27.76,0.249
8.94,27.86,0.249
8.95,27.96,0.249
8.96,28.06,0.250
8.97,28.16,0.250
8.98,28.26,0.250
8.99,28.36,0.250
9.00,28.46,0.250
9.01,28.56,0.250
9.02,28.66,0.250
9.03,28.76,0.250
9.04,28.86,0.250
9.05,28.96,0.250
9.06,29.06,0.250
9.07,29.16,0.250
9.08,29.26,0.250
9.09,29.36,0.251
9.10,29.46,0.251
9.11,29.56,0.251
9.12,29.66,0.251
9.13,29.76,0.251
9.14,29.86,0.251
9.15,29.96,0.251
9.16,30.06,0.251
9.17,30.16,0.251
9.18,30.26,0.251
9.19,30.36,0.252
9.20,30.46,0.252
9.21,30.56,0.252
9.22,30.66,0.252
9.23,30.76,0.252
9.24,30.86,0.252
9.25,30.96,0.252
9.26,31.06,0.252
9.27,31.16,0.252
9.28,31.26,0.252
9.29,31.36,0.252
9.30,31.46,0.253
9.31,31.56,0.253
9.32,31.66,0.253
9.33,31.76,0.253
9.34,31.86,0.253
9.35,31.96,0.253
9.36,32.06,0.253
9.37,32.16,0.253
9.38,32.26,0.253
9.39,32.36,0.253
9.40,32.46,0.253
9.41,32.56,0.253
9.42,32.66,0.254
9.43,32.76,0.254
9.44,32.86,0.254
9.45,32.96,0.254
9.46,33.06,0.254
9.47,33.16,0.254
9.48,33.26,0.254
9.49,33.36,0.254
9.50,33.46,0.254
9.51,33.56,0.254
9.52,33.66,0.254
9.53,33.76,0.254
9.54,33.86,0.255
9.55,33.96,0.255
9.56,34.06,0.255
9.57,34.16,0.255
9.58,34.26,0.255
9.59,34.36,0.255
9.60,34.46,0.255
9.61,34.56,0.255
9.62,34.66,0.255
9.63,34.76,0.255
9.64,34.86,0.255
9.65,34.96,0.256
9.66,35.07,0.256
9.67,35.17,0.256
9.68,35.26,0.256
9.69,35.36,0.256
9.70,35.47,0.256
9.71,35.57,0.256
9.72,35.67,0.256
9.73,35.77,0.256
9.74,35.87,0.256
9.75,35.97,0.256
9.76,36.07,0.257
9.77,36.17,0.257
9.78,36.27,0.257
9.79,36.37,0.257
9.80,36.47,0.257
9.81,36.57,0.257
9.82,36.67,0.257
9.83,36.77,0.257
9.84,36.87,0.257
9.85,36.97,0.257
9.86,37.07,0.257
9.87,37.17,0.257
9.88,37.27,0.258
9.89,37.37,0.258
9.90,37.47,0.258
9.91,37.57,0.258
9.92,37.67,0.258
9.93,37.77,0.258
9.94,37.87,0.258
9.95,37.97,0.258
9.96,38.07,0.258
9.97,38.17,0.258
9.98,38.27,0.258
9.99,38.37,0.258
10.00,38.47,0.258
10.01,38.57,0.259
10.02,38.67,0.259
10.03,38.77,0.259
10.04,38.87,0.259
10.05,38.97,0.259
10.06,39.07,0.259
10.07,39.17,0.259
10.08,39.27,0.259
10.09,39.37,0.259
10.10,39.47,0.259
10.11,39.57,0.259
10.12,39.67,0.259
10.13,39.77,0.259
10.14,39.87,0.260
10.15,39.97,0.260
10.16,40.07,0.260
10.17,40.17,0.260
10.18,40.27,0.260
10.19,40.37,0.260
10.20,40.47,0.260
10.21,40.57,0.260
10.22,40.67,0.260
10.23,40.77,0.260
10.24,40.87,0.260
10.25,40.97,0.260
10.26,41.07,0.260
10.27,41.17,0.261
10.28,41.27,0.261
10.29,41.37,0.261
10.30,41.47,0.261
10.31,41.57,0.261
10.32,41.67,0.261
10.33,41.77,0.261
10.34,41.87,0.261
10.35,41.97,0.261
10.36,42.07,0.261
10.37,42.17,0.261
10.38,42.27,0.261
10.39,42.37,0.262
10.40,42.47,0.262
10.41,42.57,0.262
10.42,42.67,0.262
10.43,42.78,0.262
10.44,42.87,0.262
10.45,42.97,0.262
10.46,43.08,0.262
10.47,43.18,0.262
10.48,43.27,0.262
10.49,43.37,0.262
10.50,43.47,0.263
10.51,43.58,0.263
10.52,43.68,0.263
10.53,43.77,0.263
10.54,43.88,0.263
10.55,43.97,0.263
10.56,44.07,0.263
10.57,44.18,0.263
10.58,44.28,0.263
10.59,44.38,0.263
10.60,44.48,0.263
10.61,44.58,0.263
10.62,44.68,0.264
10.63,44.78,0.264
10.64,44.88,0.264
10.65,44.98,0.264
10.66,45.08,0.264
10.67,45.18,0.264
10.68,45.28,0.264
10.69,45.38,0.264
10.70,45.48,0.264
10.71,45.58,0.265
10.72,45.68,0.265
10.73,45.78,0.265
10.74,45.88,0.265
10.75,45.98,0.265
10.76,46.08,0.265
10.77,46.18,0.265
10.78,46.28,0.265
10.79,46.38,0.265
10.80,46.48,0.265
10.81,46.58,0.265
10.82,46.68,0.265
10.83,46.78,0.266
10.84,46.88,0.266
10.85,46.98,0.266
10.86,47.08,0.266
10.87,47.18,0.266
10.88,47.28,0.266
10.89,47.38,0.266
10.90,47.48,0.266
10.91,47.58,0.266
10.92,47.68,0.266
10.93,47.78,0.266
10.94,47.88,0.267
10.95,47.98,0.267
10.96,48.08,0.267
10.97,48.18,0.267
10.98,48.28,0.267
10.99,48.38,0.267
11.00,48.48,0.267
11.01,48.58,0.267
11.02,48.68,0.268
11.03,48.78,0.268
11.04,48.88,0.268
11.05,48.98,0.268
11.06,49.08,0.268
11.07,49.18,0.268
11.08,49.28,0.268
11.09,49.38,0.268
11.10,49.48,0.268
11.11,49.58,0.268
11.12,49.68,0.269
11.13,49.78,0.269
11.14,49.88,0.269
11.15,49.98,0.269
11.16,50.08,0.269
11.17,50.18,0.269
11.18,50.28,0.269
11.19,50.38,0.269
11.20,50.48,0.269
11.21,50.58,0.269
11.22,50.68,0.270
11.23,50.78,0.270
11.24,50.88,0.270
11.25,50.98,0.270
11.26,51.08,0.270
11.27,51.18,0.270
11.28,51.28,0.270
11.29,51.38,0.270
11.30,51.48,0.271
11.31,51.58,0.271
11.32,51.68,0.271
11.33,51.78,0.271
11.34,51.88,0.271
11.35,51.98,0.271
11.36,52.08,0.271
11.37,52.18,0.271
11.38,52.28,0.272
11.39,52.38,0.272
11.40,52.48,0.272
11.41,52.58,0.272
11.42,52.69,0.272
11.43,52.78,0.272
11.44,52.88,0.272
11.45,52.98,0.273
11.46,53.08,0.273
11.47,53.18,0.273
11.48,53.28,0.273
11.49,53.38,0.273
11.50,53.48,0.273
11.51,53.58,0.274
11.52,53.68,0.274
11.53,53.78,0.274
11.54,53.88,0.274
11.55,53.98,0.274
11.56,54.08,0.274
11.57,54.18,0.274
11.58,54.28,0.275
11.59,54.39,0.275
11.60,54.48,0.275
11.61,54.59,0.275
11.62,54.69,0.275
11.63,54.79,0.275
11.64,54.89,0.276
11.65,54.98,0.276
11.66,55.09,0.276
11.67,55.19,0.276
11.68,55.29,0.276
11.69,55.39,0.276
11.70,55.49,0.277
11.71,55.59,0.277
11.72,55.69,0.277
11.73,55.78,0.277
11.74,55.89,0.278
11.75,55.99,0.278
11.76,56.09,0.278
11.77,56.19,0.278
11.78,56.29,0.279
11.79,56.39,0.279
11.80,56.49,0.279
11.81,56.59,0.279
11.82,56.69,0.279
11.83,56.79,0.280
11.84,56.89,0.280
11.85,56.99,0.280
11.86,57.09,0.281
11.87,57.19,0.281
11.88,57.29,0.281
11.89,57.39,0.282
11.90,57.48,0.282
11.91,57.59,0.283
11.92,57.69,0.283
11.93,57.79,0.283
11.94,57.88,0.284
11.95,57.99,0.284
11.96,58.09,0.284
11.97,58.19,0.285
11.98,58.29,0.286
11.99,58.39,0.286
12.00,58.49,0.287
12.01,58.58,0.288
12.02,58.69,0.289
12.03,58.78,0.289
12.04,58.88,0.290
12.05,58.98,0.291
12.06,59.08,0.292
12.07,59.18,0.293
12.08,59.28,0.294
12.09,59.38,0.295
12.10,59.48,0.296
12.11,59.58,0.297
12.12,59.68,0.298
12.13,59.78,0.300
12.14,59.88,0.300
12.15,59.98,0.302
12.16,60.08,0.303
12.17,60.18,0.304
12.18,60.28,0.307
12.19,60.38,0.308
12.20,60.48,0.309
12.21,60.58,0.310
12.22,60.68,0.315
12.23,60.78,0.316
12.24,60.88,0.317
12.25,60.98,0.321
12.26,61.08,0.322
12.27,61.18,0.325
12.28,61.27,0.327
12.29,61.37,0.330
12.30,61.47,0.333
12.31,61.57,0.338
12.32,61.67,0.340
12.33,61.77,0.343
12.34,61.87,0.349
12.35,61.97,0.352
12.36,62.07,0.358
12.37,62.16,0.362
12.38,62.26,0.368
12.39,62.36,0.375
12.40,62.46,0.380
12.41,62.56,0.387
12.42,62.65,0.395
12.43,62.75,0.403
12.44,62.85,0.412
12.45,62.95,0.421
12.46,63.04,0.431
12.47,63.14,0.444
12.48,63.24,0.455
12.49,63.33,0.467
12.50,63.43,0.482
12.51,63.52,0.497
12.52,63.62,0.514
12.53,63.71,0.530
12.54,63.80,0.549
12.55,63.90,0.569
12.56,63.99,0.590
12.57,64.08,0.614
12.58,64.18,0.639
12.59,64.27,0.666
12.60,64.36,0.695
12.61,64.44,0.726
12.62,64.53,0.760
12.63,64.62,0.798
12.64,64.71,0.838
12.65,64.79,0.878
12.66,64.88,0.928
12.67,64.96,0.974
12.68,65.05,1.019
12.69,65.13,1.069
12.70,65.21,1.130
12.71,65.29,1.189
12.72,65.36,1.240
12.73,65.44,1.302
12.74,65.52,1.361
12.75,65.59,1.422
12.76,65.67,1.484
12.77,65.74,1.544
12.78,65.82,1.601
12.79,65.89,1.652
12.80,65.97,1.699
12.81,66.04,1.754
12.82,66.11,1.813
12.83,66.19,1.880
12.84,66.26,1.949
12.85,66.33,2.025
12.86,66.40,2.100
12.87,66.47,2.163
12.88,66.54,2.204
12.89,66.62,2.230
12.90,66.69,2.252
12.91,66.77,2.276
12.92,66.85,2.305
12.93,66.93,2.351
12.94,67.01,2.406
12.95,67.09,2.472
12.96,67.16,2.547
12.97,67.24,2.607
12.98,67.31,2.660
12.99,67.39,2.704
13.00,67.46,2.738
13.01,67.54,2.771
13.02,67.62,2.810
13.03,67.70,2.828
13.04,67.78,2.816
13.05,67.87,2.780
13.06,67.96,2.725
13.07,68.06,2.654
13.08,68.17,2.576
13.09,68.28,2.490
13.10,68.40,2.406
13.11,68.52,2.321
13.12,68.64,2.229
13.13,68.77,2.134
13.14,68.90,2.038
13.15,69.03,1.943
13.16,69.16,1.852
13.17,69.30,1.756
13.18,69.44,1.657
13.19,69.58,1.560
13.20,69.72,1.468
13.21,69.86,1.382
13.22,70.00,1.302
13.23,70.14,1.227
13.24,70.28,1.153
13.25,70.41,1.085
13.26,70.55,1.022
13.27,70.68,0.965
13.28,70.82,0.912
13.29,70.95,0.860
13.30,71.08,0.813
13.31,71.21,0.772
13.32,71.34,0.734
13.33,71.47,0.697
13.34,71.59,0.670
13.35,71.71,0.635
13.36,71.84,0.606
13.37,71.96,0.588
13.38,72.07,0.561
13.39,72.19,0.536
13.40,72.31,0.518
13.41,72.42,0.502
13.42,72.54,0.488
13.43,72.65,0.475
13.44,72.76,0.464
13.45,72.87,0.455
13.46,72.98,0.445
13.47,73.09,0.438
13.48,73.20,0.429
13.49,73.30,0.423
13.50,73.41,0.417
13.51,73.52,0.412
13.52,73.62,0.406
13.53,73.73,0.400
13.54,73.83,0.398
13.55,73.94,0.393
13.56,74.04,0.390
13.57,74.14,0.387
13.58,74.25,0.383
13.59,74.35,0.381
13.60,74.45,0.378
13.61,74.55,0.377
13.62,74.66,0.375
13.63,74.76,0.372
13.64,74.86,0.371
13.65,74.96,0.370
13.66,75.06,0.368
13.67,75.16,0.368
13.68,75.27,0.367
13.69,75.37,0.365
13.70,75.47,0.365
13.71,75.57,0.364
13.72,75.67,0.363
13.73,75.77,0.363
13.74,75.87,0.363
13.75,75.97,0.362
13.76,76.07,0.362
13.77,76.17,0.361
13.78,76.27,0.361
13.79,76.37,0.361
13.80,76.48,0.361
13.81,76.58,0.360
13.82,76.68,0.360
13.83,76.78,0.360
13.84,76.88,0.360
13.85,76.98,0.359
13.86,77.08,0.359
13.87,77.18,0.359
13.88,77.28,0.359
13.89,77.38,0.359
13.90,77.48,0.359
13.91,77.58,0.359
13.92,77.68,0.359
13.93,77.78,0.359
13.94,77.88,0.359
13.95,77.98,0.359
13.96,78.08,0.358
13.97,78.18,0.358
13.98,78.28,0.358
13.99,78.38,0.358
14.00,78.48,0.358
14.01,78.58,0.358
14.02,78.68,0.358
14.03,78.78,0.358
14.04,78.88,0.358
14.05,78.98,0.358
14.06,79.08,0.358
14.07,79.18,0.358
14.08,79.28,0.358
14.09,79.38,0.358
14.10,79.48,0.358
14.11,79.58,0.358
14.12,79.68,0.358
14.13,79.78,0.358
14.14,79.88,0.358
14.15,79.98,0.357
14.16,80.08,0.357
14.17,80.18,0.357
14.18,80.28,0.357
14.19,80.38,0.357
14.20,80.48,0.357
14.21,80.58,0.357
14.22,80.68,0.357
14.23,80.78,0.357
14.24,80.88,0.357
14.25,80.99,0.357
14.26,81.08,0.357
14.27,81.18,0.357
14.28,81.28,0.357
14.29,81.39,0.357
14.30,81.48,0.357
14.31,81.58,0.357
14.32,81.69,0.357
14.33,81.79,0.357
14.34,81.89,0.357
14.35,81.99,0.357
14.36,82.09,0.357
14.37,82.19,0.357
14.38,82.29,0.358
14.39,82.39,0.358
14.40,82.49,0.358
14.41,82.59,0.358
14.42,82.69,0.358
14.43,82.79,0.358
14.44,82.89,0.358
14.45,82.99,0.358
14.46,83.09,0.358
14.47,83.19,0.358
14.48,83.29,0.358
14.49,83.39,0.358
14.50,83.49,0.358
14.51,83.59,0.358
14.52,83.69,0.358
14.53,83.79,0.358
14.54,83.89,0.358
14.55,83.99,0.358
14.56,84.09,0.358
14.57,84.19,0.358
14.58,84.29,0.358
14.59,84.39,0.358
14.60,84.49,0.358
14.61,84.59,0.358
14.62,84.69,0.358
14.63,84.79,0.358
14.64,84.89,0.358
14.65,84.99,0.358
14.66,85.09,0.358
14.67,85.19,0.358
14.68,85.29,0.358
14.69,85.39,0.358
14.70,85.49,0.358
14.71,85.59,0.358
14.72,85.69,0.358
14.73,85.79,0.358
14.74,85.89,0.358
14.75,85.99,0.358
14.76,86.09,0.358
14.77,86.19,0.358
14.78,86.29,0.359
14.79,86.39,0.359
14.80,86.49,0.359
14.81,86.59,0.359
14.82,86.69,0.359
14.83,86.79,0.359
14.84,86.89,0.359
14.85,86.99,0.359
14.86,87.09,0.359
14.87,87.19,0.359
14.88,87.29,0.359
14.89,87.39,0.359
14.90,87.49,0.359
14.91,87.59,0.359
14.92,87.69,0.359
14.93,87.79,0.359
14.94,87.89,
14.95,87.99,
14.96,88.09,
14.97,88.19,
14.98,88.29,
14.99,,
14.99,,

[step]
Ramp 10.00 °C/min to -60.00 °C
Time,Temperature,Heat Flow (Normalized)
min,°C,W/g
16.99,90.11,-0.022
17.00,90.11,-0.022
17.02,90.11,-0.022
17.03,90.11,-0.022
17.04,90.10,-0.022
17.05,90.09,-0.024
17.06,90.08,-0.033
17.08,90.05,-0.044
17.09,90.02,-0.058
17.10,89.99,-0.076
17.11,89.94,-0.097
17.12,89.88,-0.120
17.13,89.82,-0.143
17.14,89.76,-0.168
17.16,89.68,-0.190
17.17,89.60,-0.211
17.18,89.52,-0.230
17.19,89.44,-0.247
17.20,89.35,-0.261
17.22,89.26,-0.276
17.23,89.17,-0.286
17.24,89.07,-0.299
17.25,88.98,-0.307
17.26,88.88,-0.317
17.27,88.78,-0.324
17.28,88.67,-0.331
17.30,88.57,-0.339
17.31,88.47,-0.345
17.32,88.36,-0.351
17.33,88.25,-0.355
17.34,88.15,-0.361
17.36,88.04,-0.363
17.37,87.93,-0.368
17.38,87.82,-0.371
17.39,87.71,-0.373
17.40,87.60,-0.376
17.41,87.49,-0.379
17.43,87.38,-0.380
17.44,87.26,-0.383
17.45,87.15,-0.383
17.46,87.04,-0.385
17.47,86.93,-0.387
17.48,86.81,-0.388
17.49,86.70,-0.388
17.51,86.59,-0.389
17.52,86.47,-0.390
17.53,86.36,-0.390
17.54,86.24,-0.391
17.55,86.13,-0.392
17.57,86.02,-0.392
17.58,85.90,-0.392
17.59,85.79,-0.393
17.60,85.67,-0.394
17.61,85.56,-0.394
17.62,85.44,-0.395
17.63,85.33,-0.395
17.65,85.21,-0.395
17.66,85.10,-0.395
17.67,84.98,-0.395
17.68,84.87,-0.395
17.69,84.75,-0.396
17.71,84.64,-0.396
17.72,84.52,-0.396
17.73,84.41,-0.396
17.74,84.29,-0.396
17.75,84.18,-0.396
17.76,84.06,-0.396
17.78,83.94,-0.397
17.79,83.83,-0.397
17.80,83.71,-0.397
17.81,83.60,-0.397
17.82,83.48,-0.397
17.83,83.36,-0.397
17.84,83.25,-0.397
17.86,83.13,-0.397
17.87,83.02,-0.397
17.88,82.90,-0.397
17.89,82.78,-0.398
17.90,82.67,-0.398
17.92,82.55,-0.398
17.93,82.44,-0.398
17.94,82.32,-0.398
17.95,82.20,-0.398
17.96,82.09,-0.398
17.97,81.97,-0.398
17.98,81.86,-0.398
18.00,81.74,-0.398
18.01,81.62,-0.398
18.02,81.51,-0.398
18.03,81.39,-0.398
18.04,81.28,-0.398
18.06,81.16,-0.398
18.07,81.04,-0.398
18.08,80.93,-0.398
18.09,80.81,-0.398
18.10,80.69,-0.398
18.11,80.58,-0.398
18.13,80.46,-0.398
18.14,80.35,-0.398
18.15,80.23,-0.398
18.16,80.11,-0.398
18.17,80.00,-0.398
18.18,79.88,-0.398
18.19,79.77,-0.398
18.21,79.65,-0.398
18.22,79.53,-0.398
18.23,79.42,-0.398
18.24,79.30,-0.398
18.25,79.18,-0.398
18.27,79.07,-0.398
18.28,78.95,-0.398
18.29,78.84,-0.398
18.30,78.72,-0.398
18.31,78.60,-0.398
18.32,78.49,-0.398
18.33,78.37,-0.398
18.35,78.25,-0.398
18.36,78.14,-0.398
18.37,78.02,-0.398
18.38,77.90,-0.398
18.39,77.79,-0.398
18.41,77.67,-0.398
18.42,77.56,-0.397
18.43,77.44,-0.397
18.44,77.32,-0.397
18.45,77.21,-0.397
18.46,77.09,-0.397
18.48,76.97,-0.397
18.49,76.86,-0.397
18.50,76.74,-0.397
18.51,76.62,-0.397
18.52,76.51,-0.397
18.53,76.39,-0.397
18.54,76.27,-0.397
18.56,76.16,-0.397
18.57,76.04,-0.397
18.58,75.92,-0.397
18.59,75.81,-0.397
18.60,75.69,-0.396
18.62,75.58,-0.396
18.63,75.46,-0.396
18.64,75.34,-0.396
18.65,75.23,-0.396
18.66,75.11,-0.396
18.67,74.99,-0.396
18.68,74.88,-0.396
18.70,74.76,-0.396
18.71,74.65,-0.395
18.72,74.53,-0.395
18.73,74.41,-0.395
18.74,74.29,-0.395
18.76,74.18,-0.395
18.77,74.06,-0.395
18.78,73.95,-0.395
18.79,73.83,-0.395
18.80,73.71,-0.395
18.81,73.60,-0.395
18.83,73.48,-0.395
18.84,73.36,-0.395
18.85,73.25,-0.395
18.86,73.13,-0.394
18.87,73.01,-0.394
18.88,72.90,-0.394
18.89,72.78,-0.394
18.91,72.66,-0.394
18.92,72.55,-0.394
18.93,72.43,-0.394
18.94,72.31,-0.394
18.95,72.20,-0.394
18.97,72.08,-0.394
18.98,71.96,-0.394
18.99,71.85,-0.393
19.00,71.73,-0.393
19.01,71.61,-0.393
19.02,71.50,-0.393
19.03,71.38,-0.393
19.05,71.26,-0.393
19.06,71.15,-0.393
19.07,71.03,-0.393
19.08,70.92,-0.393
19.09,70.80,-0.393
19.11,70.68,-0.392
19.12,70.57,-0.392
19.13,70.45,-0.392
19.14,70.33,-0.392
19.15,70.22,-0.392
19.16,70.10,-0.392
19.18,69.98,-0.392
19.19,69.87,-0.392
19.20,69.75,-0.392
19.21,69.64,-0.392
19.22,69.52,-0.391
19.23,69.40,-0.391
19.24,69.29,-0.391
19.26,69.17,-0.391
19.27,69.05,-0.391
19.28,68.93,-0.391
19.29,68.82,-0.391
19.30,68.70,-0.391
19.32,68.59,-0.391
19.33,68.47,-0.391
19.34,68.35,-0.390
19.35,68.24,-0.390
19.36,68.12,-0.390
19.37,68.00,-0.390
19.38,67.89,-0.390
19.40,67.77,-0.390
19.41,67.65,-0.390
19.42,67.54,-0.390
19.43,67.42,-0.390
19.44,67.30,-0.389
19.46,67.19,-0.389
19.47,67.07,-0.389
19.48,66.95,-0.389
19.49,66.84,-0.389
19.50,66.72,-0.389
19.51,66.60,-0.389
19.53,66.49,-0.389
19.54,66.37,-0.389
19.55,66.25,-0.389
19.56,66.14,-0.388
19.57,66.02,-0.388
19.58,65.91,-0.388
19.59,65.79,-0.388
19.61,65.67,-0.388
19.62,65.56,-0.388
19.63,65.44,-0.388
19.64,65.32,-0.388
19.65,65.21,-0.388
19.67,65.09,-0.388
19.68,64.97,-0.388
19.69,64.86,-0.387
19.70,64.74,-0.387
19.71,64.62,-0.387
19.72,64.51,-0.387
19.73,64.39,-0.387
19.75,64.27,-0.387
19.76,64.16,-0.387
19.77,64.04,-0.387
19.78,63.92,-0.387
19.79,63.81,-0.387
19.81,63.69,-0.387
19.82,63.57,-0.386
19.83,63.46,-0.386
19.84,63.34,-0.386
19.85,63.23,-0.386
19.86,63.11,-0.386
19.88,62.99,-0.386
19.89,62.87,-0.386
19.90,62.76,-0.386
19.91,62.64,-0.386
19.92,62.53,-0.385
19.93,62.41,-0.385
19.94,62.29,-0.385
19.96,62.18,-0.385
19.97,62.06,-0.385
19.98,61.94,-0.385
19.99,61.83,-0.385
20.00,61.71,-0.385
20.02,61.59,-0.385
20.03,61.48,-0.385
20.04,61.36,-0.385
20.05,61.24,-0.384
20.06,61.13,-0.384
20.07,61.01,-0.384
20.08,60.89,-0.384
20.10,60.78,-0.384
20.11,60.66,-0.384
20.12,60.54,-0.384
20.13,60.43,-0.384
20.14,60.31,-0.384
20.16,60.19,-0.384
20.17,60.08,-0.384
20.18,59.96,-0.384
20.19,59.84,-0.384
20.20,59.73,-0.383
20.21,59.61,-0.383
20.23,59.50,-0.383
20.24,59.38,-0.383
20.25,59.26,-0.383
20.26,59.15,-0.383
20.27,59.03,-0.383
20.28,58.91,-0.383
20.29,58.80,-0.383
20.31,58.68,-0.383
20.32,58.56,-0.382
20.33,58.45,-0.382
20.34,58.33,-0.382
20.35,58.21,-0.382
20.37,58.10,-0.382
20.38,57.98,-0.382
20.39,57.86,-0.382
20.40,57.75,-0.382
20.41,57.63,-0.382
20.42,57.51,-0.382
20.43,57.40,-0.382
20.45,57.28,-0.381
20.46,57.16,-0.381
20.47,57.05,-0.381
20.48,56.93,-0.381
20.49,56.81,-0.381
20.51,56.70,-0.381
20.52,56.58,-0.381
20.53,56.46,-0.381
20.54,56.35,-0.381
20.55,56.23,-0.381
20.56,56.11,-0.381
20.58,56.00,-0.380
20.59,55.88,-0.380
20.60,55.76,-0.380
20.61,55.65,-0.380
20.62,55.53,-0.380
20.63,55.41,-0.380
20.64,55.30,-0.380
20.66,55.18,-0.380
20.67,55.07,-0.380
20.68,54.95,-0.380
20.69,54.83,-0.379
20.70,54.72,-0.379
20.72,54.60,-0.379
20.73,54.48,-0.379
20.74,54.37,-0.379
20.75,54.25,-0.379
20.76,54.13,-0.379
20.77,54.02,-0.379
20.78,53.90,-0.379
20.80,53.78,-0.378
20.81,53.67,-0.378
20.82,53.55,-0.378
20.83,53.43,-0.378
20.84,53.32,-0.378
20.86,53.20,-0.378
20.87,53.08,-0.378
20.88,52.97,-0.378
20.89,52.85,-0.378
20.90,52.73,-0.378
20.91,52.62,-0.378
20.93,52.50,-0.378
20.94,52.38,-0.378
[...]
104.08,-40.89,0.183
104.09,-40.82,0.183
104.10,-40.76,0.183
104.10,-40.69,0.184
104.11,-40.62,0.184
104.12,-40.55,0.184
104.12,-40.49,0.184
104.13,-40.42,0.184
104.14,-40.35,0.184
104.14,-40.29,0.184
104.15,-40.22,0.184
104.16,-40.15,0.184
104.16,-40.09,0.184
104.17,-40.02,0.184
104.18,-39.95,0.184
104.18,-39.89,0.184
104.19,-39.82,0.184
104.20,-39.75,0.184
104.20,-39.69,0.184
104.21,-39.62,0.184
104.22,-39.55,0.184
104.22,-39.48,0.184
104.23,-39.42,0.184
104.24,-39.35,0.184
104.24,-39.29,0.184
104.25,-39.22,0.184
104.26,-39.15,0.184
104.26,-39.09,0.185
104.27,-39.02,0.185
104.28,-38.95,0.185
104.28,-38.88,0.185
104.29,-38.82,0.185
104.30,-38.75,0.185
104.30,-38.68,0.185
104.31,-38.62,0.185
104.32,-38.55,0.185
104.32,-38.48,0.185
104.33,-38.42,0.185
104.34,-38.35,0.185
104.34,-38.28,0.185
104.35,-38.22,0.185
104.36,-38.15,0.185
104.36,-38.08,0.185
104.37,-38.01,0.185
104.38,-37.95,0.185
104.38,-37.88,0.185
104.39,-37.81,0.185
104.40,-37.75,0.185
104.40,-37.68,0.185
104.41,-37.61,0.185
104.42,-37.55,0.185
104.42,-37.48,0.186
104.43,-37.41,0.186
104.44,-37.35,0.186
104.44,-37.28,0.186
104.45,-37.21,0.186
104.46,-37.14,0.186
104.46,-37.08,0.186
104.47,-37.01,0.186
104.48,-36.94,0.186
104.48,-36.88,0.186
104.49,-36.81,0.186
104.50,-36.75,0.186
104.50,-36.68,0.186
104.51,-36.61,0.186
104.52,-36.54,0.186
104.52,-36.48,0.186
104.53,-36.41,0.186
104.54,-36.35,0.186
104.54,-36.28,0.186
104.55,-36.21,0.186
104.56,-36.15,0.186
104.56,-36.08,0.186
104.57,-36.01,0.186
104.58,-35.95,0.186
104.58,-35.88,0.186
104.59,-35.81,0.186
104.60,-35.75,0.186
104.60,-35.68,0.186
104.61,-35.61,0.186
104.62,-35.55,0.186
104.62,-35.48,0.186
104.63,-35.41,0.186
104.64,-35.35,0.186
104.64,-35.28,0.186
104.65,-35.21,0.187
104.66,-35.15,0.187
104.66,-35.08,0.187
104.67,-35.01,0.187
104.68,-34.95,0.187
104.68,-34.88,0.187
104.69,-34.81,0.187
104.70,-34.75,0.187
104.70,-34.68,0.187
104.71,-34.61,0.187
104.72,-34.55,0.187
104.72,-34.48,0.187
104.73,-34.41,0.187
104.74,-34.35,0.187
104.74,-34.28,0.187
104.75,-34.21,0.187
104.76,-34.15,0.187
104.76,-34.08,0.187
104.77,-34.01,0.187
104.78,-33.95,0.187
104.78,-33.88,0.187
104.79,-33.81,0.187
104.80,-33.75,0.187
104.80,-33.68,0.187
104.81,-33.61,0.187
104.82,-33.55,0.187
104.82,-33.48,0.187
104.83,-33.41,0.187
104.84,-33.35,0.188
104.84,-33.28,0.188
104.85,-33.21,0.188
104.86,-33.15,0.188
104.86,-33.08,0.188
104.87,-33.01,0.188
104.88,-32.95,0.188
104.88,-32.88,0.188
104.89,-32.81,0.188
104.90,-32.74,0.188
104.90,-32.68,0.188
104.91,-32.61,0.188
104.92,-32.54,0.188
104.92,-32.48,0.188
104.93,-32.41,0.188
104.94,-32.34,0.188
104.94,-32.28,0.188
104.95,-32.21,0.188
104.96,-32.14,0.188
104.96,-32.08,0.188
104.97,-32.01,0.188
104.98,-31.94,0.188
104.98,-31.88,0.188
104.99,-31.81,0.189
105.00,-31.74,0.189
105.00,-31.68,0.189
105.01,-31.61,0.189
105.02,-31.54,0.189
105.02,-31.48,0.189
105.03,-31.41,0.189
105.04,-31.34,0.189
105.04,-31.28,0.189
105.05,-31.21,0.189
105.06,-31.14,0.189
105.06,-31.07,0.189
105.07,-31.01,0.189
105.08,-30.94,0.189
105.08,-30.87,0.189
105.09,-30.81,0.189
105.10,-30.74,0.189
105.10,-30.67,0.189
105.11,-30.61,0.189
105.12,-30.54,0.189
105.12,-30.47,0.190
105.13,-30.41,0.190
105.14,-30.34,0.190
105.14,-30.27,0.190
105.15,-30.21,0.190
105.16,-30.14,0.190
105.16,-30.07,0.190
105.17,-30.01,0.190
105.18,-29.94,0.190
105.18,-29.87,0.190
105.19,-29.81,0.190
105.20,-29.74,0.190
105.20,-29.67,0.190
105.21,-29.61,0.190
105.22,-29.54,0.190
105.22,-29.47,0.190
105.23,-29.41,0.190
105.24,-29.34,0.190
105.24,-29.27,0.190
105.25,-29.21,0.191
105.26,-29.14,0.191
105.26,-29.07,0.191
105.27,-29.01,0.191
105.28,-28.94,0.191
105.28,-28.87,0.191
105.29,-28.80,0.191
105.30,-28.74,0.191
105.30,-28.67,0.191
105.31,-28.61,0.191
105.32,-28.54,0.191
105.32,-28.47,0.191
105.33,-28.41,0.191
105.34,-28.34,0.191
105.34,-28.27,0.191
105.35,-28.20,0.191
105.36,-28.14,0.191
105.36,-28.07,0.191
105.37,-28.00,0.191
105.38,-27.94,0.191
105.38,-27.87,0.191
105.39,-27.81,0.192
105.40,-27.74,0.192
105.40,-27.67,0.192
105.41,-27.60,0.192
105.42,-27.54,0.192
105.42,-27.47,0.192
105.43,-27.40,0.192
105.44,-27.34,0.192
105.44,-27.27,0.192
105.45,-27.20,0.192
105.46,-27.14,0.192
105.46,-27.07,0.192
105.47,-27.00,0.192
105.48,-26.94,0.192
105.48,-26.87,0.192
105.49,-26.80,0.192
105.50,-26.74,0.192
105.50,-26.67,0.193
105.51,-26.60,0.193
105.52,-26.54,0.193
105.52,-26.47,0.193
105.53,-26.40,0.193
105.54,-26.34,0.193
105.54,-26.27,0.193
105.55,-26.20,0.193
105.56,-26.14,0.193
105.56,-26.07,0.193
105.57,-26.00,0.193
105.58,-25.94,0.193
105.58,-25.87,0.193
105.59,-25.80,0.193
105.60,-25.73,0.193
105.60,-25.67,0.194
105.61,-25.60,0.194
105.62,-25.54,0.194
105.62,-25.47,0.194
105.63,-25.40,0.194
105.64,-25.34,0.194
105.64,-25.27,0.194
105.65,-25.20,0.194
105.66,-25.14,0.194
105.66,-25.07,0.194
105.67,-25.00,0.194
105.68,-24.94,0.194
105.68,-24.87,0.194
105.69,-24.80,0.195
105.70,-24.74,0.195
105.70,-24.67,0.195
105.71,-24.60,0.195
105.72,-24.54,0.195
105.72,-24.47,0.195
105.73,-24.40,0.195
105.74,-24.34,0.195
105.74,-24.27,0.195
105.75,-24.20,0.195
105.76,-24.13,0.195
105.76,-24.07,0.195
105.77,-24.00,0.195
105.78,-23.93,0.196
105.78,-23.87,0.196
105.79,-23.80,0.196
105.80,-23.74,0.196
105.80,-23.67,0.196
105.81,-23.60,0.196
105.82,-23.53,0.196
105.82,-23.47,0.196
105.83,-23.40,0.196
105.84,-23.33,0.196
105.84,-23.27,0.196
105.85,-23.20,0.196
105.86,-23.13,0.197
105.86,-23.07,0.197
105.87,-23.00,0.197
105.88,-22.93,0.197
105.88,-22.87,0.197
105.89,-22.80,0.197
105.90,-22.73,0.197
105.90,-22.67,0.197
105.91,-22.60,0.197
105.92,-22.53,0.197
105.92,-22.47,0.198
105.93,-22.40,0.198
105.94,-22.33,0.198
105.94,-22.27,0.198
105.95,-22.20,0.198
105.96,-22.13,0.198
105.96,-22.07,0.198
105.97,-22.00,0.198
105.98,-21.93,0.198
105.98,-21.87,0.199
105.99,-21.80,0.199
106.00,-21.73,0.199
106.00,-21.67,0.199
106.01,-21.60,0.199
106.02,-21.53,0.199
106.02,-21.47,0.199
106.03,-21.40,0.199
106.04,-21.33,0.200
106.04,-21.27,0.200
106.05,-21.20,0.200
106.06,-21.13,0.200
106.06,-21.07,0.200
106.07,-21.00,0.200
106.08,-20.93,0.200
106.08,-20.87,0.201
106.09,-20.80,0.201
106.10,-20.73,0.201
106.10,-20.67,0.202
106.11,-20.60,0.202
106.12,-20.53,0.202
106.12,-20.47,0.202
106.13,-20.40,0.202
106.14,-20.33,0.202
106.14,-20.27,0.202
106.15,-20.20,0.203
106.16,-20.13,0.203
106.16,-20.07,0.203
106.17,-20.00,0.203
106.18,-19.93,0.203
106.18,-19.87,0.203
106.19,-19.80,0.204
106.20,-19.73,0.204
106.20,-19.67,0.204
106.21,-19.60,0.204
106.22,-19.53,0.205
106.22,-19.47,0.205
106.23,-19.40,0.205
106.24,-19.33,0.205
106.24,-19.27,0.205
106.25,-19.20,0.206
106.26,-19.13,0.206
106.26,-19.07,0.207
106.27,-19.00,0.207
106.28,-18.93,0.207
106.28,-18.87,0.207
106.29,-18.80,0.207
106.30,-18.73,0.208
106.30,-18.67,0.208
106.31,-18.60,0.208
106.32,-18.54,0.208
106.32,-18.47,0.208
106.33,-18.40,0.209
106.34,-18.34,0.210
106.34,-18.27,0.210
106.35,-18.20,0.210
106.36,-18.13,0.211
106.36,-18.07,0.211
106.37,-18.00,0.211
106.38,-17.94,0.212
106.38,-17.87,0.213
106.39,-17.80,0.213
106.40,-17.74,0.213
106.40,-17.67,0.214
106.41,-17.60,0.214
106.42,-17.54,0.214
106.42,-17.47,0.215
106.43,-17.40,0.215
106.44,-17.34,0.216
106.44,-17.27,0.216
106.45,-17.20,0.216
106.46,-17.14,0.217
106.46,-17.07,0.217
106.47,-17.00,0.218
106.48,-16.94,0.219
106.48,-16.87,0.220
106.49,-16.80,0.220
106.50,-16.74,0.220
106.50,-16.67,0.221
106.51,-16.60,0.222
106.52,-16.54,0.223
106.52,-16.47,0.224
106.53,-16.41,0.224
106.54,-16.34,0.224
106.54,-16.27,0.225
106.55,-16.20,0.226
106.56,-16.14,0.227
106.56,-16.07,0.228
106.57,-16.01,0.228
106.58,-15.94,0.229
106.58,-15.87,0.230
106.59,-15.81,0.230
106.60,-15.74,0.231
106.60,-15.67,0.232
106.61,-15.61,0.233
106.62,-15.54,0.234
106.62,-15.47,0.235
106.63,-15.41,0.235
106.64,-15.34,0.236
106.64,-15.27,0.238
106.65,-15.21,0.239
106.66,-15.14,0.239
106.66,-15.08,0.240
106.67,-15.01,0.240
106.68,-14.94,0.241
106.68,-14.88,0.242
106.69,-14.81,0.243
106.70,-14.74,0.244
106.70,-14.68,0.245
106.71,-14.61,0.246
106.72,-14.55,0.247
106.72,-14.48,0.248
106.73,-14.41,0.248
106.74,-14.35,0.249
106.74,-14.28,0.251
106.75,-14.21,0.253
106.76,-14.15,0.253
106.76,-14.08,0.254
106.77,-14.02,0.256
106.78,-13.95,0.257
106.78,-13.88,0.258
106.79,-13.82,0.259
106.80,-13.75,0.260
106.80,-13.68,0.261
106.81,-13.62,0.262
106.82,-13.55,0.263
106.82,-13.49,0.265
106.83,-13.42,0.266
106.84,-13.35,0.267
106.84,-13.29,0.268
106.85,-13.22,0.269
106.86,-13.15,0.270
106.86,-13.09,0.272
106.87,-13.02,0.272
106.88,-12.96,0.273
106.88,-12.89,0.275
106.89,-12.83,0.276
106.90,-12.76,0.277
106.90,-12.69,0.279
106.91,-12.63,0.280
106.92,-12.56,0.281
106.92,-12.49,0.281
106.93,-12.43,0.282
106.94,-12.36,0.284
106.94,-12.30,0.285
106.95,-12.23,0.285
106.96,-12.16,0.286
106.96,-12.10,0.287
106.97,-12.03,0.289
106.98,-11.96,0.290
106.98,-11.90,0.290
106.99,-11.83,0.291
107.00,-11.77,0.291
107.00,-11.70,0.292
107.01,-11.63,0.293
107.02,-11.57,0.294
107.02,-11.50,0.294
107.03,-11.43,0.294
107.04,-11.37,0.295
107.04,-11.30,0.296
107.05,-11.24,0.296
107.06,-11.17,0.296
107.06,-11.10,0.296
107.07,-11.04,0.296
107.08,-10.97,0.296
107.08,-10.90,0.296
107.09,-10.84,0.296
107.10,-10.77,0.296
107.10,-10.70,0.296
107.11,-10.64,0.296
107.12,-10.57,0.296
107.12,-10.50,0.296
107.13,-10.44,0.296
107.14,-10.37,0.296
107.14,-10.30,0.296
107.15,-10.23,0.295
107.16,-10.17,0.295
107.16,-10.10,0.295
107.17,-10.04,0.295
107.18,-9.97,0.294
107.18,-9.90,0.293
107.19,-9.83,0.292
107.20,-9.77,0.292
107.20,-9.70,0.291
107.21,-9.63,0.290
107.22,-9.56,0.290
107.22,-9.50,0.289
107.23,-9.43,0.288
107.24,-9.36,0.287
107.24,-9.30,0.286
107.25,-9.23,0.286
107.26,-9.16,0.285
107.26,-9.10,0.285
107.27,-9.03,0.284
107.28,-8.96,0.284
107.28,-8.89,0.283
107.29,-8.83,0.283
107.30,-8.76,0.282
107.30,-8.69,0.282
107.31,-8.63,0.281
107.32,-8.56,0.281
107.32,-8.49,0.281
107.33,-8.43,0.280
107.34,-8.36,0.278
107.34,-8.29,0.278
107.35,-8.22,0.278
107.36,-8.16,0.278
107.36,-8.09,0.278
107.37,-8.02,0.278
107.38,-7.96,0.277
107.38,-7.89,0.277
107.39,-7.82,0.277
107.40,-7.76,0.277
107.40,-7.69,0.277
107.41,-7.62,0.277
107.42,-7.55,0.277
107.42,-7.49,0.277
107.43,-7.42,0.277
107.44,-7.35,0.277
107.44,-7.29,0.277
107.45,-7.22,0.276
107.46,-7.15,0.276
107.46,-7.09,0.276
107.47,-7.02,0.276
107.48,-6.95,0.276
107.48,-6.89,0.276
107.49,-6.82,0.276
107.50,-6.75,0.276
107.50,-6.68,0.276
107.51,-6.62,0.275
107.52,-6.55,0.275
107.52,-6.48,0.275
107.53,-6.42,0.275
107.54,-6.35,0.275
107.54,-6.28,0.275
107.55,-6.22,0.275
107.56,-6.15,0.275
107.56,-6.08,0.275
107.57,-6.02,0.275
107.58,-5.95,0.275
107.58,-5.88,0.275
107.59,-5.82,0.275
107.60,-5.75,0.274
107.60,-5.68,0.274
107.61,-5.61,0.274
107.62,-5.55,0.274
107.62,-5.48,0.274
107.63,-5.41,0.274
107.64,-5.35,0.274
107.64,-5.28,0.274
107.65,-5.22,0.274
107.66,-5.15,0.274
107.66,-5.08,0.274
107.67,-5.01,0.274
107.68,-4.95,0.274
107.68,-4.88,0.274
107.69,-4.81,0.273
107.70,-4.75,0.273
107.70,-4.68,0.273
107.71,-4.61,0.273
107.72,-4.55,0.273
107.72,-4.48,0.273
107.73,-4.41,0.273
107.74,-4.35,0.273
107.74,-4.28,0.273
107.75,-4.21,0.273
107.76,-4.15,0.273
107.76,-4.08,0.273
107.77,-4.01,0.273
107.78,-3.94,0.273
107.78,-3.88,0.273
107.79,-3.81,0.273
107.80,-3.74,0.273
107.80,-3.68,0.273
107.81,-3.61,0.273
107.82,-3.54,0.273
107.82,-3.48,0.273
107.83,-3.41,0.273
107.84,-3.34,0.273
107.84,-3.28,0.273
107.85,-3.21,0.273
107.86,-3.14,0.273
107.86,-3.08,0.273
107.87,-3.01,0.273
107.88,-2.94,0.273
107.88,-2.88,0.273
107.89,-2.81,0.273
107.90,-2.74,0.273
107.90,-2.68,0.273
107.91,-2.61,0.273
107.92,-2.54,0.273
107.92,-2.47,0.273
107.93,-2.41,0.273
107.94,-2.34,0.273
107.94,-2.27,0.273
107.95,-2.21,0.273
107.96,-2.14,0.273
107.96,-2.07,0.273
107.97,-2.01,0.273
107.98,-1.94,0.273
107.98,-1.87,0.273
107.99,-1.81,0.273
108.00,-1.74,0.273
108.00,-1.67,0.273
108.01,-1.61,0.273
108.02,-1.54,0.273
108.02,-1.47,0.273
108.03,-1.41,0.273
108.04,-1.34,0.273
108.04,-1.27,0.273
108.05,-1.21,0.273
108.06,-1.14,0.273
108.06,-1.07,0.273
108.07,-1.01,0.273
108.08,-0.94,0.273
108.08,-0.87,0.273
108.09,-0.81,0.273
108.10,-0.74,0.273
108.10,-0.67,0.273
108.11,-0.60,0.273
108.12,-0.54,0.273
108.12,-0.47,0.273
108.13,-0.41,0.273
108.14,-0.34,0.273
108.14,-0.27,0.273
108.15,-0.21,0.273
108.16,-0.14,0.273
108.16,-0.07,0.273
108.17,0.00,0.273
108.18,0.06,0.273
108.18,0.13,0.273
108.19,0.20,0.273
108.20,0.26,0.273
108.20,0.33,0.273
108.21,0.40,0.273
108.22,0.46,0.273
108.22,0.53,0.273
108.23,0.60,0.273
108.24,0.66,0.273
108.24,0.73,0.273
108.25,0.80,0.273
108.26,0.86,0.273
108.26,0.93,0.273
108.27,1.00,0.273
108.28,1.06,0.273
108.28,1.13,0.273
108.29,1.20,0.273
108.30,1.26,0.273
108.30,1.33,0.273
108.31,1.40,0.273
108.32,1.46,0.273
108.32,1.53,0.273
108.33,1.60,0.273
108.34,1.66,0.273
108.34,1.73,0.273
108.35,1.80,0.273
108.36,1.86,0.273
108.36,1.93,0.273
108.37,2.00,0.273
108.38,2.06,0.273
108.38,2.13,0.273
108.39,2.20,0.273
108.40,2.27,0.273
108.40,2.33,0.273
108.41,2.40,0.274
108.42,2.47,0.274
108.42,2.53,0.274
108.43,2.60,0.274
108.44,2.67,0.274
108.44,2.73,0.274
108.45,2.80,0.274
108.46,2.87,0.274
108.46,2.93,0.274
108.47,3.00,0.274
108.48,3.07,0.274
108.48,3.13,0.274
108.49,3.20,0.274
108.50,3.27,0.274
108.50,3.33,0.274
108.51,3.40,0.274
108.52,3.47,0.274
108.52,3.53,0.274
108.53,3.60,0.274
108.54,3.67,0.274
108.54,3.73,0.274
108.55,3.80,0.274
108.56,3.87,0.274
108.56,3.93,0.274
108.57,4.00,0.274
108.58,4.07,0.274
108.58,4.13,0.274
108.59,4.20,0.274
108.60,4.27,0.274
108.60,4.33,0.274
108.61,4.40,0.274
108.62,4.47,0.274
108.62,4.53,0.275
108.63,4.60,0.275
108.64,4.67,0.275
108.64,4.73,0.275
108.65,4.80,0.275
108.66,4.87,0.275
108.66,4.94,0.275
108.67,5.00,0.275
108.68,5.07,0.275
108.68,5.13,0.275
108.69,5.20,0.275
108.70,5.27,0.275
108.70,5.34,0.275
108.71,5.40,0.275
108.72,5.47,0.275
108.72,5.54,0.275
108.73,5.60,0.275
108.74,5.67,0.275
108.74,5.74,0.275
108.75,5.80,0.275
108.76,5.87,0.275
108.76,5.94,0.275
108.77,6.00,0.275
108.78,6.07,0.275
108.78,6.14,0.275
108.79,6.20,0.275
108.80,6.27,0.276
108.80,6.34,0.276
108.81,6.40,0.276
108.82,6.47,0.276
108.82,6.54,0.276
108.83,6.61,0.276
108.84,6.67,0.276
108.84,6.74,0.276
108.85,6.81,0.276
108.86,6.87,0.276
108.86,6.94,0.276
108.87,7.00,0.276
108.88,7.07,0.276
108.88,7.14,0.276
108.89,7.21,0.276
108.90,7.27,0.276
108.90,7.34,0.276
108.91,7.41,0.276
108.92,7.47,0.276
108.92,7.54,0.276
108.93,7.61,0.276
108.94,7.67,0.276
108.94,7.74,0.276
108.95,7.81,0.276
108.96,7.87,0.276
108.96,7.94,0.276
108.97,8.01,0.276
108.98,8.07,0.277
108.98,8.14,0.277
108.99,8.21,0.277
109.00,8.27,0.277
109.00,8.34,0.277
109.01,8.41,0.277
109.02,8.47,0.277
109.02,8.54,0.277
109.03,8.61,0.277
109.04,8.67,0.277
109.04,8.74,0.277
109.05,8.81,0.277
109.06,8.88,0.277
109.06,8.94,0.277
109.07,9.01,0.277
109.08,9.07,0.277
109.08,9.14,0.277
109.09,9.21,0.277
109.10,9.28,0.277
109.10,9.34,0.277
109.11,9.41,0.277
109.12,9.48,0.277
109.12,9.54,0.277
109.13,9.61,0.277
109.14,9.68,0.277
109.14,9.74,0.277
109.15,9.81,0.277
109.16,9.88,0.277
109.16,9.94,0.277
109.17,10.01,0.277
109.18,10.07,0.278
109.18,10.14,0.278
109.19,10.21,0.278
109.20,10.28,0.278
109.20,10.34,0.278
109.21,10.41,0.278
109.22,10.48,0.278
109.22,10.54,0.278
109.23,10.61,0.278
109.24,10.68,0.278
109.24,10.74,0.278
109.25,10.81,0.278
109.26,10.88,0.278
109.26,10.94,0.278
109.27,11.01,0.278
109.28,11.08,0.278
109.28,11.14,0.278
109.29,11.21,0.278
109.30,11.28,0.278
109.30,11.34,0.278
109.31,11.41,0.278
109.32,11.48,0.278
109.32,11.54,0.278
109.33,11.61,0.278
109.34,11.68,0.278
109.34,11.74,0.278
109.35,11.81,0.278
109.36,11.88,0.278
109.36,11.94,0.279
109.37,12.01,0.279
109.38,12.08,0.279
109.38,12.14,0.279
109.39,12.21,0.279
109.40,12.28,0.279
109.40,12.35,0.279
109.41,12.41,0.279
109.42,12.48,0.279
109.42,12.55,0.279
109.43,12.61,0.279
109.44,12.68,0.279
109.44,12.75,0.279
109.45,12.81,0.279
109.46,12.88,0.279
109.46,12.95,0.279
109.47,13.01,0.279
109.48,13.08,0.279
109.48,13.15,0.279
109.49,13.21,0.279
109.50,13.28,0.279
109.50,13.35,0.279
109.51,13.41,0.279
109.52,13.48,0.280
109.52,13.55,0.280
109.53,13.61,0.280
109.54,13.68,0.280
109.54,13.75,0.280
109.55,13.82,0.280
109.56,13.88,0.280
109.56,13.95,0.280
109.57,14.02,0.280
109.58,14.08,0.280
109.58,14.15,0.280
109.59,14.21,0.280
109.60,14.28,0.280
109.60,14.35,0.280
109.61,14.41,0.280
109.62,14.48,0.280
109.62,14.55,0.280
109.63,14.62,0.280
109.64,14.68,0.280
109.64,14.75,0.280
109.65,14.82,0.280
109.66,14.88,0.280
109.66,14.95,0.280
109.67,15.02,0.280
109.68,15.08,0.280
109.68,15.15,0.281
109.69,15.22,0.281
109.70,15.28,0.281
109.70,15.35,0.281
109.71,15.41,0.281
109.72,15.48,0.281
109.72,15.55,0.281
109.73,15.62,0.281
109.74,15.68,0.281
109.74,15.75,0.281
109.75,15.82,0.281
109.76,15.88,0.281
109.76,15.95,0.281
109.77,16.02,0.281
109.78,16.08,0.281
109.78,16.15,0.281
109.79,16.22,0.281
109.80,16.28,0.281
109.80,16.35,0.281
109.81,16.42,0.281
109.82,16.48,0.281
109.82,16.55,0.281
109.83,16.62,0.281
109.84,16.68,0.281
109.84,16.75,0.281
109.85,16.82,0.282
109.86,16.88,0.282
109.86,16.95,0.282
109.87,17.02,0.282
109.88,17.08,0.282
109.88,17.15,0.282
109.89,17.22,0.282
109.90,17.28,0.282
109.90,17.35,0.282
109.91,17.42,0.282
109.92,17.49,0.282
109.92,17.55,0.282
109.93,17.62,0.282
109.94,17.68,0.282
109.94,17.75,0.282
109.95,17.82,0.282
109.96,17.89,0.282
109.96,17.95,0.282
109.97,18.02,0.282
109.98,18.09,0.282
109.98,18.15,0.282
109.99,18.22,0.282
110.00,18.29,0.282
110.00,18.35,0.282
110.01,18.42,0.282
110.02,18.49,0.282
110.02,18.55,0.282
110.03,18.62,0.283
110.04,18.69,0.283
110.04,18.75,0.283
110.05,18.82,0.283
110.06,18.88,0.283
110.06,18.95,0.283
110.07,19.02,0.283
110.08,19.09,0.283
110.08,19.15,0.283
110.09,19.22,0.283
110.10,19.29,0.283
110.10,19.35,0.283
110.11,19.42,0.283
110.12,19.49,0.283
110.12,19.55,0.283
110.13,19.62,0.283
110.14,19.69,0.283
110.14,19.75,0.283
110.15,19.82,0.283
110.16,19.89,0.283
110.16,19.95,0.283
110.17,20.02,0.283
110.18,20.09,0.283
110.18,20.15,0.283
110.19,20.22,0.284
110.20,20.29,0.284
110.20,20.35,0.284
110.21,20.42,0.284
110.22,20.49,0.284
110.22,20.55,0.284
110.23,20.62,0.284
110.24,20.69,0.284
110.24,20.75,0.284
110.25,20.82,0.284
110.26,20.89,0.284
110.26,20.95,0.284
110.27,21.02,0.284
110.28,21.09,0.284
110.28,21.16,0.284
110.29,21.22,0.284
110.30,21.29,0.284
110.30,21.36,0.284
110.31,21.42,0.284
110.32,21.49,0.284
110.32,21.56,0.284
110.33,21.62,0.284
110.34,21.69,0.284
110.34,21.76,0.284
110.35,21.82,0.284
110.36,21.89,0.284
110.36,21.96,0.285
110.37,22.02,0.285
110.38,22.09,0.285
110.38,22.16,0.285
110.39,22.22,0.285
110.40,22.29,0.285
110.40,22.36,0.285
110.41,22.42,0.285
110.42,22.49,0.285
110.42,22.56,0.285
110.43,22.62,0.285
110.44,22.69,0.285
110.44,22.76,0.285
110.45,22.82,0.285
110.46,22.89,0.285
110.46,22.96,0.285
110.47,23.02,0.285
110.48,23.09,0.285
110.48,23.16,0.285
110.49,23.22,0.285
110.50,23.29,0.285
110.50,23.36,0.285
110.51,23.42,0.285
110.52,23.49,0.285
110.52,23.56,0.285
110.53,23.62,0.285
110.54,23.69,0.285
110.54,23.76,0.286
110.55,23.83,0.286
110.56,23.89,0.286
110.56,23.96,0.286
110.57,24.03,0.286
110.58,24.09,0.286
110.58,24.16,0.286
110.59,24.23,0.286
110.60,24.29,0.286
110.60,24.36,0.286
110.61,24.43,0.286
110.62,24.49,0.286
110.62,24.56,0.286
110.63,24.63,0.286
110.64,24.69,0.286
110.64,24.76,0.286
110.65,24.83,0.286
110.66,24.89,0.286
110.66,24.96,0.286
110.67,25.03,0.286
110.68,25.09,0.286
110.68,25.16,0.286
110.69,25.23,0.286
110.70,25.29,0.287
110.70,25.36,0.287
110.71,25.43,0.287
110.72,25.49,0.287
110.72,25.56,0.287
110.73,25.63,0.287
110.74,25.69,0.287
110.74,25.76,0.287
110.75,25.83,0.287
110.76,25.89,0.287
110.76,25.96,0.287
110.77,26.03,0.287
110.78,26.09,0.287
110.78,26.16,0.287
110.79,26.23,0.287
110.80,26.29,0.287
110.80,26.36,0.287
110.81,26.43,0.287
110.82,26.50,0.287
110.82,26.56,0.287
110.83,26.63,0.287
110.84,26.70,0.287
110.84,26.76,0.287
110.85,26.83,0.287
110.86,26.90,0.288
110.86,26.96,0.288
110.87,27.03,0.288
110.88,27.10,0.288
110.88,27.16,0.288
110.89,27.23,0.288
110.90,27.30,0.288
110.90,27.36,0.288
110.91,27.43,0.288
110.92,27.50,0.288
110.92,27.56,0.288
110.93,27.63,0.288
110.94,27.70,0.288
110.94,27.76,
110.95,27.83,
110.96,27.90,
110.96,27.96,
110.97,28.03,
110.98,28.10,
110.98,28.16,
110.99,,
111.00,,