File: DSC/2025_06_27_CBD_24DHBA_n60_250_10C_min_x4.csv
Filename,2025_06_27_CBD_24DHBA_n60_250_10C_min_x4
Instrument name,DSC2A-00468 (192.168.1.100)
Operator,Gibbons
rundate,6/27/2025
Sample name,2025_06_27_CBD_24DHBA_n60_250_10C_min_x4
proceduresegments,Data Off ; Equilibrate -60.00 °C; Data On ; Ramp 10.00 °C/min to 250.00 °C; Data Off ; Isothermal 2.0 min; Data On ; Ramp 10.00 °C/min to -60.00 °C; Data Off ; Isothermal 2.0 min; Data On ; Ramp 10.00 °C/min to 250.00 °C; Data Off ; Isothermal 2.0 min; Data On ; Ramp 10.00 °C/min to -60.00 °C; Data Off ; Isothermal 2.0 min; Data On ; Ramp 10.00 °C/min to 250.00 °C; Data Off ; Isothermal 2.0 min; Data On ; Ramp 10.00 °C/min to -60.00 °C; Data Off ; Isothermal 2.0 min; Data On ; Ramp 10.00 °C/min to 30.00 °C
[File Parameters]
Run date,6/27/2025 6:35:42 PM
Trios version,5.1.1.46572
Original File Name,
Current File Name,D:\DSC2500\Gibbons\2025_06_27_CBD_24DHBA_n60_250_10C_min_x4.tri
[Procedure]
Procedure Name,CBD_24DHBA_n60_250_10C_min_x4
Sample Name,2025_06_27_CBD_24DHBA_n60_250_10C_min_x4
Sample Mass,4.75 mg
Reference Sample Mass,0 mg
Pan Mass,56.75 mg
Pan Number,25
Reference Pan Mass,56.76 mg
Reference Pan Number,10
Pan Type,Tzero Aluminum Hermetic
Comments,Al Hermetic DSC Consumables sealed Pan/Lid. Y1 Tray (Google Sheet: DSC_Samples_Y1_Tray_June2025)
Project Name,CA
Operator,Gibbons
Test,Custom
Unload Max Temperature,30
Unload Min Temperature,30
Load Max Temperature,30
Load Min Temperature,30
Stop on Gas Flow Error,Yes
[Signal List]
Signal #1,Time (min)
Signal #2,Temperature (°C)
Signal #3,Heat Flow (mW)
Signal #4,Delta T (µV)
Signal #5,Delta Tzero (µV)
Signal #6,Tzero Temperature (°C)
Signal #7,Cell Purge (mL/min)
Signal #8,Heater Temp (°C)
Signal #9,Power Delivered (W)
Signal #10,Reference Junction Temperature (°C)
Signal #11,Flange Temperature (°C)
Signal #12,Heat Flow Phase (rad)
Signal #13,Total Heat Capacity (J/°C)
Signal #14,Heat Capacity (J/°C)
[Configuration]
Company Name,ASU
Instrument Name,DSC2A-00468
Instrument Type,DSC2500
Serial Number,DSC2A-00468
IP,192.168.1.100
Location of Instrument,MRRC
DisplayType,Unknown
Sample Interval ,0.1 s/pt
Selected Heat Flow,T4P
Exotherm Direction,Down
Cell Serial,DRC2-00792
Lid Type,Standard
Cooler,RCS 90
Leave Cooler on at End of Sequence,On
Gas 2,Nitrogen
Gas Selected,Channel 1
Flow Rate,50 mL/min
Secondary Purge,On
Licensed Heat Flow,Heat Flow T4P
Modulation Licensed,Yes
[Versions]
Common IDD Version,1
Cortex Version,VER 2.10.2.31
Driver,5.0.0.6
GDM Version,1.0.3.3
TouchscreenVersion,1.0.0.16145
FEP Version,1.2.1.21
FEP Bootloader,2.0.0.5
AutoSampler Version,2.1.1.26
Auto Sampler Bootloader,2.0.0.5
FCM Version,1.1.0.3
FCM Bootloader,2.0.0.5
[Experiment Logs]
Experiment Log Entry # 1,Data On set to 0
Experiment Log Entry # 3,Equilibrate Segment -60 (C) Started
Experiment Log Entry # 5,Air Cool is off.
Experiment Log Entry # 7,Data On set to 1
Experiment Log Entry # 9,Ramp Segment 10 C/min to 250 Started
Experiment Log Entry # 11,Data On set to 0
Experiment Log Entry # 13,Isothermal Segment 2 min started
Experiment Log Entry # 15,Data On set to 1
Experiment Log Entry # 17,Ramp Segment 10 C/min to -60 Started
Experiment Log Entry # 19,Data On set to 0
Experiment Log Entry # 21,Isothermal Segment 2 min started
Experiment Log Entry # 23,Data On set to 1
Experiment Log Entry # 25,Ramp Segment 10 C/min to 250 Started
Experiment Log Entry # 27,Data On set to 0
Experiment Log Entry # 29,Isothermal Segment 2 min started
Experiment Log Entry # 31,Data On set to 1
Experiment Log Entry # 33,Ramp Segment 10 C/min to -60 Started
Experiment Log Entry # 35,Data On set to 0
Experiment Log Entry # 37,Isothermal Segment 2 min started
Experiment Log Entry # 39,Data On set to 1
Experiment Log Entry # 41,Ramp Segment 10 C/min to 250 Started
Experiment Log Entry # 43,Data On set to 0
Experiment Log Entry # 45,Isothermal Segment 2 min started
Experiment Log Entry # 47,Data On set to 1
Experiment Log Entry # 49,Ramp Segment 10 C/min to -60 Started
Experiment Log Entry # 51,Data On set to 0
Experiment Log Entry # 53,Isothermal Segment 2 min started
Experiment Log Entry # 55,Data On set to 1
Experiment Log Entry # 57,Ramp Segment 10 C/min to 30 Started
[Method Log]
Method Log Entry # 1,Data Off
Method Log Entry # 2,Equilibrate -60 °C
Method Log Entry # 3,Data On
Method Log Entry # 4,(Ramp 483963) Ramp 10 °C/minute to 250 °C
Method Log Entry # 5,Data Off
Method Log Entry # 6,Isothermal 2 minutes
Method Log Entry # 7,Data On
Method Log Entry # 8,(Ramp 483967) Ramp 10 °C/minute to -60 °C
Method Log Entry # 9,Data Off
Method Log Entry # 10,Isothermal 2 minutes
Method Log Entry # 11,Data On
Method Log Entry # 12,(Ramp 483971) Ramp 10 °C/minute to 250 °C
Method Log Entry # 13,Data Off
Method Log Entry # 14,Isothermal 2 minutes
Method Log Entry # 15,Data On
Method Log Entry # 16,(Ramp 483975) Ramp 10 °C/minute to -60 °C
Method Log Entry # 17,Data Off
Method Log Entry # 18,Isothermal 2 minutes
Method Log Entry # 19,Data On
Method Log Entry # 20,(Ramp 483979) Ramp 10 °C/minute to 250 °C
Method Log Entry # 21,Data Off
Method Log Entry # 22,Isothermal 2 minutes
Method Log Entry # 23,Data On
Method Log Entry # 24,(Ramp 483983) Ramp 10 °C/minute to -60 °C
Method Log Entry # 25,Data Off
Method Log Entry # 26,Isothermal 2 minutes
Method Log Entry # 27,Data On
Method Log Entry # 28,(Ramp 483987) Ramp 10 °C/minute to 30 °C
Cell Serial,DRC2-00792
[T1 Calibration]
Slope,-0.008529666
Offset,9.636258
Initial Temperature,98.23
GUID,f8bfdadc-4977-4fdf-ba6d-0ba9134940c3
[TZero Calibration]
Date Applied,11/29/2022 4:06:13 PM
Description,From -89.059 °C to 396.009 °C at 20.000°C/min
Gas Type,Nitrogen
Pan Type,None
Source Files 1,C:\Users\yargerlab\Desktop\DSC Data\General\TZero_calibration_11_29_22_2nd(2).tri
Source Files 2,C:\Users\yargerlab\Desktop\DSC Data\General\TZero_calibration_11_29_22_2nd(3).tri
Delta T Offset,13.05235
Delta T Slope,-0.007271007
Delta T0 Offset,-13.69128
Delta T0 Slope,0.06063341
[Temperature Calibration]
Date Applied,11/29/2022 7:12:28 PM
Description,From 106.590 °C to 186.590 °C at 10.000°C/min
Gas Type,Nitrogen
Pan Type,Tzero Aluminum Hermetic
Source Files 1,C:\Users\yargerlab\Desktop\DSC Data\General\Indium(6).tri
Measured 1,157.391
Known 1,156.598
[Cell Constant Calibration]
Date Applied,11/29/2022 7:12:29 PM
Description,From 106.590 °C to 186.590 °C at 10.000°C/min
Gas Type,Nitrogen
Pan Type,Tzero Aluminum Hermetic
Source Files 1,C:\Users\yargerlab\Desktop\DSC Data\General\Indium(6).tri
T4P KCell,1.006051
Onset Slope,63.26126 mW/°C
[Direct Cp Calibration]
Date Applied,11/30/2022 11:04:51 AM
Description,From -79.983 °C to 298.409 °C at 10.000°C/min
Gas Type,Nitrogen
Pan Type,Tzero Aluminum Hermetic
Source Files 1,C:\Users\yargerlab\Desktop\DSC Data\General\Sapphire_Heat_Capacity_11_30_22.tri
[Rev Cp Calibration]
Date Applied,11/30/2022 1:58:51 PM
Description,From -79.996 °C to 292.812 °C at 3.000°C/min
Gas Type,Nitrogen
Pan Type,Tzero Aluminum Hermetic
Source Files 1,C:\Users\yargerlab\Desktop\DSC Data\General\Sapphire_MDSC_Calibration_11_30_22.tri
[step]
Ramp 10.00 °C/min to 250.00 °C
Time,Temperature,Heat Flow (Normalized)
min,°C,W/g
0.00,-59.69,-0.058
0.02,-59.70,-0.055
0.04,-59.71,-0.049
0.07,-59.70,-0.046
0.09,-59.66,-0.044
0.11,-59.60,-0.041
0.13,-59.52,-0.031
0.15,-59.40,-0.012
0.17,-59.27,0.008
0.19,-59.12,0.030
0.22,-58.96,0.054
0.24,-58.79,0.074
0.26,-58.61,0.091
0.28,-58.43,0.108
0.30,-58.24,0.121
0.33,-58.05,0.133
0.35,-57.86,0.140
0.37,-57.66,0.147
0.39,-57.46,0.155
0.41,-57.26,0.160
0.43,-57.05,0.165
0.45,-56.85,0.168
0.48,-56.64,0.173
0.50,-56.44,0.175
0.52,-56.23,0.178
0.54,-56.02,0.179
0.56,-55.81,0.180
0.58,-55.60,0.182
0.61,-55.39,0.182
0.63,-55.18,0.184
0.65,-54.97,0.185
0.67,-54.76,0.186
0.69,-54.55,0.187
0.72,-54.33,0.187
0.74,-54.12,0.188
0.76,-53.91,0.188
0.78,-53.70,0.189
0.80,-53.48,0.189
0.82,-53.27,0.189
0.85,-53.05,0.190
0.87,-52.84,0.190
0.89,-52.63,0.191
0.91,-52.41,0.191
0.93,-52.20,0.192
0.95,-51.98,0.192
0.98,-51.77,0.192
1.00,-51.56,0.193
1.02,-51.34,0.193
1.04,-51.13,0.193
1.06,-50.91,0.194
1.08,-50.70,0.194
1.11,-50.48,0.194
1.13,-50.27,0.195
1.15,-50.05,0.195
1.17,-49.83,0.195
1.19,-49.62,0.195
1.21,-49.40,0.196
1.23,-49.19,0.196
1.26,-48.97,0.196
1.28,-48.76,0.196
1.30,-48.54,0.196
1.32,-48.33,0.197
1.34,-48.11,0.197
1.37,-47.89,0.197
1.39,-47.68,0.197
1.41,-47.46,0.197
1.43,-47.24,0.197
1.45,-47.03,0.197
1.47,-46.81,0.198
1.49,-46.60,0.198
1.52,-46.38,0.198
1.54,-46.16,0.198
1.56,-45.94,0.198
1.58,-45.73,0.198
1.60,-45.51,0.198
1.63,-45.30,0.199
1.65,-45.08,0.199
1.67,-44.86,0.199
1.69,-44.65,0.199
1.71,-44.43,0.199
1.73,-44.21,0.199
1.76,-44.00,0.199
1.78,-43.78,0.199
1.80,-43.56,0.199
1.82,-43.35,0.199
1.84,-43.13,0.199
1.86,-42.91,0.200
1.88,-42.70,0.200
1.91,-42.48,0.200
1.93,-42.26,0.200
1.95,-42.05,0.200
1.97,-41.83,0.200
1.99,-41.61,0.200
2.02,-41.40,0.200
2.04,-41.18,0.200
2.06,-40.96,0.200
2.08,-40.75,0.200
2.10,-40.53,0.200
2.12,-40.31,0.200
2.14,-40.09,0.201
2.17,-39.88,0.201
2.19,-39.66,0.201
2.21,-39.44,0.201
2.23,-39.23,0.201
2.25,-39.01,0.201
2.28,-38.79,0.201
2.30,-38.57,0.201
2.32,-38.36,0.201
2.34,-38.14,0.201
2.36,-37.92,0.201
2.38,-37.71,0.201
2.41,-37.49,0.201
2.43,-37.27,0.201
2.45,-37.06,0.202
2.47,-36.84,0.202
2.49,-36.62,0.202
2.51,-36.40,0.202
2.54,-36.19,0.202
2.56,-35.97,0.202
2.58,-35.75,0.202
2.60,-35.54,0.202
2.62,-35.32,0.202
2.64,-35.10,0.202
2.66,-34.89,0.202
2.69,-34.67,0.202
2.71,-34.45,0.202
2.73,-34.23,0.202
2.75,-34.02,0.202
2.77,-33.80,0.202
2.79,-33.58,0.202
2.82,-33.37,0.203
2.84,-33.15,0.203
2.86,-32.93,0.203
2.88,-32.72,0.203
2.90,-32.50,0.203
2.93,-32.28,0.203
2.95,-32.07,0.203
2.97,-31.85,0.203
2.99,-31.63,0.203
3.01,-31.42,0.203
3.03,-31.20,0.203
3.06,-30.98,0.203
3.08,-30.76,0.203
3.10,-30.55,0.203
3.12,-30.33,0.203
3.14,-30.11,0.203
3.16,-29.90,0.203
3.19,-29.68,0.203
3.21,-29.46,0.203
3.23,-29.24,0.203
3.25,-29.03,0.204
3.27,-28.81,0.204
3.29,-28.59,0.204
3.31,-28.38,0.204
3.34,-28.16,0.204
3.36,-27.94,0.204
3.38,-27.72,0.204
3.40,-27.51,0.204
3.42,-27.29,0.204
3.44,-27.08,0.204
3.47,-26.86,0.204
3.49,-26.64,0.204
3.51,-26.42,0.204
3.53,-26.21,0.204
3.55,-25.99,0.204
3.58,-25.77,0.205
3.60,-25.55,0.205
3.62,-25.34,0.205
3.64,-25.12,0.205
3.66,-24.90,0.205
3.68,-24.69,0.205
3.71,-24.47,0.205
3.73,-24.25,0.205
3.75,-24.04,0.205
3.77,-23.82,0.205
3.79,-23.60,0.205
3.81,-23.39,0.205
3.84,-23.17,0.205
3.86,-22.95,0.205
3.88,-22.74,0.205
3.90,-22.52,0.206
3.92,-22.30,0.206
3.94,-22.08,0.206
3.96,-21.87,0.206
3.99,-21.65,0.206
4.01,-21.43,0.206
4.03,-21.22,0.206
4.05,-21.00,0.206
4.07,-20.78,0.206
4.09,-20.57,0.206
4.12,-20.35,0.206
4.14,-20.13,0.206
4.16,-19.92,0.207
4.18,-19.70,0.207
4.20,-19.48,0.207
4.23,-19.26,0.207
4.25,-19.05,0.207
4.27,-18.83,0.207
4.29,-18.61,0.207
4.31,-18.40,0.207
4.33,-18.18,0.207
4.35,-17.96,0.207
4.38,-17.74,0.207
4.40,-17.53,0.207
4.42,-17.31,0.208
4.44,-17.09,0.208
4.46,-16.88,0.208
4.49,-16.66,0.208
4.51,-16.44,0.208
4.53,-16.22,0.208
4.55,-16.01,0.208
4.57,-15.79,0.208
4.59,-15.58,0.208
4.61,-15.36,0.208
4.64,-15.14,0.208
4.66,-14.92,0.208
4.68,-14.71,0.208
4.70,-14.49,0.209
4.72,-14.27,0.209
4.75,-14.06,0.209
4.77,-13.84,0.209
4.79,-13.62,0.209
4.81,-13.41,0.209
4.83,-13.19,0.209
4.85,-12.97,0.209
4.88,-12.75,0.209
4.90,-12.54,0.209
4.92,-12.32,0.209
4.94,-12.10,0.209
4.96,-11.89,0.209
4.98,-11.67,0.209
5.00,-11.45,0.210
5.03,-11.24,0.210
5.05,-11.02,0.210
5.07,-10.80,0.210
5.09,-10.59,0.210
5.11,-10.37,0.210
5.14,-10.15,0.210
5.16,-9.93,0.210
5.18,-9.72,0.210
5.20,-9.50,0.210
5.22,-9.28,0.210
5.24,-9.07,0.210
5.26,-8.85,0.210
5.29,-8.63,0.211
5.31,-8.42,0.211
5.33,-8.20,0.211
5.35,-7.98,0.211
5.37,-7.77,0.211
5.40,-7.55,0.211
5.42,-7.33,0.211
5.44,-7.11,0.211
5.46,-6.90,0.211
5.48,-6.68,0.211
5.50,-6.46,0.212
5.53,-6.25,0.212
5.55,-6.03,0.212
5.57,-5.81,0.212
5.59,-5.60,0.212
5.61,-5.38,0.212
5.63,-5.16,0.212
5.65,-4.94,0.212
5.68,-4.73,0.212
5.70,-4.51,0.213
5.72,-4.29,0.213
5.74,-4.08,0.213
5.76,-3.86,0.213
5.79,-3.64,0.213
5.81,-3.43,0.213
5.83,-3.21,0.213
5.85,-2.99,0.213
5.87,-2.78,0.213
5.89,-2.56,0.213
5.91,-2.34,0.214
5.94,-2.13,0.214
5.96,-1.91,0.214
5.98,-1.69,0.214
6.00,-1.47,0.214
6.02,-1.26,0.214
6.05,-1.04,0.214
6.07,-0.82,0.214
6.09,-0.61,0.214
6.11,-0.39,0.214
6.13,-0.17,0.214
6.15,0.04,0.215
6.18,0.26,0.215
6.20,0.48,0.215
6.22,0.70,0.215
6.24,0.91,0.215
6.26,1.13,0.215
6.28,1.35,0.215
6.30,1.56,0.216
6.33,1.78,0.216
6.35,2.00,0.216
6.37,2.22,0.216
6.39,2.43,0.216
6.41,2.65,0.216
6.44,2.87,0.216
6.46,3.08,0.216
6.48,3.30,0.217
6.50,3.52,0.217
6.52,3.74,0.217
6.54,3.95,0.217
6.56,4.17,0.217
6.59,4.38,0.217
6.61,4.60,0.217
6.63,4.82,0.218
6.65,5.04,0.218
6.67,5.25,0.218
6.70,5.47,0.218
6.72,5.69,0.218
6.74,5.90,0.218
6.76,6.12,0.218
6.78,6.34,0.218
6.80,6.55,0.219
6.83,6.77,0.219
6.85,6.99,0.219
6.87,7.20,0.219
6.89,7.42,0.219
6.91,7.64,0.219
6.93,7.86,0.219
6.95,8.07,0.219
6.98,8.29,0.220
7.00,8.51,0.220
7.02,8.72,0.220
7.04,8.94,0.220
7.06,9.16,0.220
7.09,9.38,0.220
7.11,9.59,0.220
7.13,9.81,0.221
7.15,10.03,0.221
7.17,10.24,0.221
7.19,10.46,0.221
7.21,10.68,0.221
7.24,10.89,0.221
7.26,11.11,0.221
7.28,11.33,0.222
7.30,11.55,0.222
7.32,11.76,0.222
7.35,11.98,0.222
7.37,12.19,0.222
7.39,12.41,0.222
7.41,12.63,0.222
7.43,12.84,0.222
7.45,13.06,0.222
7.48,13.28,0.223
7.50,13.50,0.223
7.52,13.71,0.223
7.54,13.93,0.223
7.56,14.15,0.223
7.58,14.36,0.223
7.60,14.58,0.223
7.63,14.80,0.224
7.65,15.01,0.224
7.67,15.23,0.224
7.69,15.45,0.224
7.71,15.66,0.224
7.74,15.88,0.224
7.76,16.10,0.224
7.78,16.32,0.224
7.80,16.53,0.225
7.82,16.75,0.225
7.84,16.97,0.225
7.86,17.18,0.225
7.89,17.40,0.225
7.91,17.62,0.225
7.93,17.83,0.225
7.95,18.05,0.225
7.97,18.27,0.226
8.00,18.48,0.226
8.02,18.70,0.226
8.04,18.92,0.226
8.06,19.14,0.226
8.08,19.35,0.226
8.10,19.57,0.227
8.13,19.79,0.227
8.15,20.00,0.227
8.17,20.22,0.227
8.19,20.44,0.227
8.21,20.65,0.227
8.23,20.87,0.228
8.25,21.09,0.228
8.28,21.30,0.228
8.30,21.52,0.228
8.32,21.74,0.228
8.34,21.95,0.228
8.36,22.17,0.228
8.39,22.39,0.228
8.41,22.61,0.229
8.43,22.82,0.229
8.45,23.04,0.229
8.47,23.26,0.229
8.49,23.47,0.229
8.51,23.69,0.229
8.54,23.91,0.230
8.56,24.12,0.230
8.58,24.34,0.230
8.60,24.56,0.230
8.62,24.78,0.230
8.65,24.99,0.230
8.67,25.21,0.230
8.69,25.43,0.231
8.71,25.64,0.231
8.73,25.86,0.231
8.75,26.08,0.231
8.78,26.29,0.231
8.80,26.51,0.231
8.82,26.73,0.231
8.84,26.95,0.232
8.86,27.16,0.232
8.88,27.38,0.232
8.90,27.60,0.232
8.93,27.81,0.232
8.95,28.03,0.232
8.97,28.25,0.232
8.99,28.46,0.233
9.01,28.68,0.233
9.03,28.90,0.233
9.06,29.11,0.233
9.08,29.33,0.233
9.10,29.55,0.233
9.12,29.76,0.234
9.14,29.98,0.234
9.17,30.20,0.234
9.19,30.42,0.234
9.21,30.63,0.234
9.23,30.85,0.234
9.25,31.07,0.234
9.27,31.28,0.234
9.30,31.50,0.235
9.32,31.72,0.235
9.34,31.93,0.235
9.36,32.15,0.235
9.38,32.37,0.235
9.40,32.58,0.235
9.43,32.80,0.236
9.45,33.02,0.236
9.47,33.24,0.236
9.49,33.45,0.236
9.51,33.67,0.236
9.53,33.89,0.236
9.55,34.10,0.236
9.58,34.32,0.237
9.60,34.54,0.237
9.62,34.76,0.237
9.64,34.97,0.237
9.66,35.19,0.237
9.68,35.40,0.237
9.71,35.62,0.237
9.73,35.84,0.238
9.75,36.06,0.238
9.77,36.27,0.238
9.79,36.49,0.238
9.82,36.71,0.238
9.84,36.92,0.238
9.86,37.14,0.239
9.88,37.36,0.239
9.90,37.57,0.239
9.92,37.79,0.239
9.95,38.01,0.239
9.97,38.23,0.239
9.99,38.44,0.239
10.01,38.66,0.240
10.03,38.88,0.240
10.05,39.09,0.240
10.08,39.31,0.240
10.10,39.53,0.240
10.12,39.74,0.240
10.14,39.96,0.240
10.16,40.18,0.241
10.18,40.39,0.241
10.20,40.61,0.241
10.23,40.83,0.241
10.25,41.04,0.241
10.27,41.26,0.241
10.29,41.48,0.241
10.31,41.69,0.242
10.33,41.91,0.242
10.36,42.13,0.242
10.38,42.35,0.242
10.40,42.56,0.242
10.42,42.78,0.243
10.44,43.00,0.243
10.47,43.21,0.243
10.49,43.43,0.243
10.51,43.65,0.243
10.53,43.86,0.243
10.55,44.08,0.244
10.57,44.30,0.244
10.60,44.52,0.244
10.62,44.73,0.244
10.64,44.95,0.244
10.66,45.17,0.244
10.68,45.38,0.245
10.70,45.60,0.245
10.73,45.82,0.245
10.75,46.03,0.245
10.77,46.25,0.245
10.79,46.47,0.246
10.81,46.68,0.246
10.83,46.90,0.246
10.85,47.12,0.246
10.88,47.34,0.246
10.90,47.55,0.247
10.92,47.77,0.247
10.94,47.99,0.247
10.96,48.20,0.247
10.98,48.42,0.248
11.01,48.64,0.248
11.03,48.85,0.248
11.05,49.07,0.248
11.07,49.29,0.248
11.09,49.50,0.249
11.12,49.72,0.249
11.14,49.94,0.249
11.16,50.16,0.249
11.18,50.37,0.249
11.20,50.59,0.250
11.22,50.81,0.250
11.25,51.02,0.250
11.27,51.24,0.250
11.29,51.45,0.251
11.31,51.67,0.251
11.33,51.89,0.251
11.35,52.11,0.251
11.38,52.32,0.252
11.40,52.54,0.252
11.42,52.76,0.252
11.44,52.97,0.252
11.46,53.19,0.253
11.48,53.41,0.253
11.50,53.62,0.253
11.53,53.84,0.254
11.55,54.06,0.254
11.57,54.27,0.254
11.59,54.49,0.255
11.61,54.71,0.255
11.63,54.93,0.255
11.66,55.14,0.256
11.68,55.36,0.256
11.70,55.57,0.256
11.72,55.79,0.257
11.74,56.01,0.257
11.77,56.23,0.258
11.79,56.44,0.258
11.81,56.66,0.259
11.83,56.88,0.259
11.85,57.09,0.260
11.87,57.31,0.261
11.90,57.53,0.261
11.92,57.74,0.262
11.94,57.96,0.263
11.96,58.17,0.264
11.98,58.39,0.265
12.00,58.61,0.266
12.03,58.83,0.267
12.05,59.04,0.269
12.07,59.26,0.272
12.09,59.48,0.274
12.11,59.69,0.277
12.13,59.91,0.279
12.15,60.12,0.283
12.18,60.34,0.286
12.20,60.56,0.291
12.22,60.77,0.296
12.24,60.99,0.300
12.26,61.20,0.305
12.28,61.42,0.311
12.31,61.63,0.319
12.33,61.85,0.327
12.35,62.06,0.338
12.37,62.28,0.347
12.39,62.49,0.361
12.42,62.71,0.375
12.44,62.92,0.391
12.46,63.13,0.411
12.48,63.34,0.434
12.50,63.55,0.460
12.52,63.76,0.490
12.55,63.97,0.523
12.57,64.18,0.558
12.59,64.39,0.595
12.61,64.59,0.627
12.63,64.80,0.655
12.65,65.01,0.671
12.68,65.22,0.682
12.70,65.43,0.697
12.72,65.64,0.714
12.74,65.85,0.739
12.76,66.06,0.764
12.78,66.27,0.789
12.80,66.48,0.818
12.83,66.69,0.848
12.85,66.90,0.882
12.87,67.10,0.923
12.89,67.31,0.964
12.91,67.51,0.997
12.93,67.72,1.027
12.96,67.93,1.059
12.98,68.13,1.088
13.00,68.34,1.109
13.02,68.55,1.151
13.04,68.76,1.141
13.07,68.97,1.096
13.09,69.19,1.035
13.11,69.42,0.970
13.13,69.65,0.881
13.15,69.89,0.787
13.17,70.13,0.691
13.20,70.37,0.608
13.22,70.61,0.541
13.24,70.85,0.491
13.26,71.09,0.452
13.28,71.32,0.421
13.30,71.55,0.397
13.33,71.78,0.375
13.35,72.01,0.359
13.37,72.23,0.347
13.39,72.46,0.336
13.41,72.68,0.328
13.43,72.90,0.321
13.45,73.12,0.318
13.48,73.34,0.311
13.50,73.56,0.309
13.52,73.78,0.307
13.54,74.00,0.305
13.56,74.22,0.303
13.58,74.43,0.302
13.61,74.65,0.301
13.63,74.87,0.300
13.65,75.09,0.299
13.67,75.30,0.299
13.69,75.52,0.299
13.72,75.74,0.298
13.74,75.95,0.298
13.76,76.17,0.298
13.78,76.39,0.297
13.80,76.61,0.297
13.82,76.82,0.297
13.85,77.04,0.297
13.87,77.26,0.296
13.89,77.47,0.296
13.91,77.69,0.296
13.93,77.91,0.296
13.95,78.13,0.296
13.98,78.34,0.296
14.00,78.56,0.296
14.02,78.78,0.296
14.04,78.99,0.295
14.06,79.21,0.295
14.08,79.43,0.295
14.10,79.64,0.295
14.13,79.86,0.295
14.15,80.08,0.295
14.17,80.30,0.295
14.19,80.51,0.295
14.21,80.73,0.295
14.23,80.95,0.295
14.26,81.16,0.295
14.28,81.38,0.296
14.30,81.60,0.296
14.32,81.81,0.296
14.34,82.03,0.296
14.37,82.25,0.295
14.39,82.46,0.295
14.41,82.68,0.295
14.43,82.90,0.295
14.45,83.12,0.295
14.47,83.33,0.296
14.50,83.55,0.296
14.52,83.76,0.296
14.54,83.98,0.295
14.56,84.20,0.295
14.58,84.42,0.296
14.60,84.63,0.296
14.63,84.85,0.296
14.65,85.07,0.296
14.67,85.28,0.296
14.69,85.50,0.296
14.71,85.72,0.296
14.73,85.94,0.296
14.75,86.15,0.296
14.78,86.37,0.296
14.80,86.58,0.296
14.82,86.80,0.296
14.84,87.02,0.296
14.86,87.23,0.296
14.88,87.45,0.296
14.91,87.67,0.296
14.93,87.89,0.296
14.95,88.10,0.297
14.97,88.32,0.297
14.99,88.54,0.297
15.02,88.75,0.297
15.04,88.97,0.297
15.06,89.19,0.297
15.08,89.40,0.297
15.10,89.62,0.297
15.12,89.84,0.297
15.15,90.05,0.298
15.17,90.27,0.298
15.19,90.49,0.298
15.21,90.71,0.298
15.23,90.92,0.298
15.25,91.14,0.298
15.28,91.36,0.298
15.30,91.57,0.298
15.32,91.79,0.299
15.34,92.01,0.299
15.36,92.22,0.299
15.38,92.44,0.299
15.40,92.66,0.299
15.43,92.87,0.299
15.45,93.09,0.300
15.47,93.31,0.300
15.49,93.53,0.300
15.51,93.74,0.300
15.53,93.96,0.300
15.56,94.18,0.300
15.58,94.39,0.300
15.60,94.61,0.300
15.62,94.83,0.301
15.64,95.04,0.301
15.67,95.26,0.301
15.69,95.48,0.301
15.71,95.70,0.301
15.73,95.91,0.301
15.75,96.13,0.302
15.77,96.35,0.302
15.80,96.56,0.302
15.82,96.78,0.302
15.84,96.99,0.302
15.86,97.21,0.302
15.88,97.43,0.302
15.90,97.65,0.302
15.93,97.86,0.303
15.95,98.08,0.303
15.97,98.30,0.303
15.99,98.51,0.303
16.01,98.73,0.303
16.03,98.95,0.303
16.05,99.16,0.303
16.08,99.38,0.303
16.10,99.60,0.303
16.12,99.81,0.304
16.14,100.03,0.304
16.16,100.25,0.304
16.18,100.47,0.304
16.21,100.68,0.304
16.23,100.90,0.304
16.25,101.12,0.304
16.27,101.33,0.305
16.29,101.55,0.305
16.32,101.77,0.305
16.34,101.98,0.305
16.36,102.20,0.305
16.38,102.42,0.305
16.40,102.64,0.305
16.42,102.85,0.306
16.45,103.07,0.306
16.47,103.29,0.306
16.49,103.50,0.306
16.51,103.72,0.306
16.53,103.94,0.306
16.55,104.15,0.306
16.58,104.37,0.306
16.60,104.59,0.307
16.62,104.80,0.307
16.64,105.02,0.307
16.66,105.24,0.307
16.68,105.46,0.307
16.70,105.68,0.307
16.73,105.90,0.308
16.75,106.11,0.308
16.77,106.33,0.308
16.79,106.55,0.308
16.81,106.76,0.308
16.83,106.98,0.308
16.86,107.20,0.308
16.88,107.41,0.308
16.90,107.63,0.308
16.92,107.85,0.308
16.94,108.06,0.308
16.97,108.28,0.308
16.99,108.50,0.308
17.01,108.71,0.308
17.03,108.93,0.308
17.05,109.14,0.308
17.07,109.36,0.308
17.09,109.58,0.308
17.12,109.79,0.308
17.14,110.01,0.309
17.16,110.23,0.309
17.18,110.45,0.309
17.20,110.66,0.309
17.23,110.88,0.309
17.25,111.10,0.309
17.27,111.31,0.309
17.29,111.53,0.309
17.31,111.75,0.309
17.33,111.96,0.310
17.36,112.18,0.310
17.38,112.40,0.310
17.40,112.61,0.310
17.42,112.83,0.310
17.44,113.05,0.310
17.46,113.26,0.310
17.48,113.48,0.310
17.51,113.69,0.310
17.53,113.91,0.311
17.55,114.13,0.311
17.57,114.34,0.311
17.59,114.56,0.311
17.62,114.78,0.311
17.64,114.99,0.311
17.66,115.21,0.311
17.68,115.43,0.312
17.70,115.64,0.312
17.72,115.86,0.312
17.74,116.08,0.312
17.77,116.30,0.312
17.79,116.51,0.312
17.81,116.73,0.312
17.83,116.95,0.313
17.85,117.16,0.313
17.88,117.38,0.313
17.90,117.60,0.313
17.92,117.81,0.313
17.94,118.03,0.313
17.96,118.25,0.314
17.98,118.46,0.314
18.01,118.68,0.314
18.03,118.90,0.314
18.05,119.11,0.314
18.07,119.33,0.314
18.09,119.55,0.314
18.11,119.77,0.315
18.13,119.98,0.315
18.16,120.20,0.315
18.18,120.42,0.315
18.20,120.63,0.315
18.22,120.85,0.315
18.24,121.07,0.315
18.27,121.28,0.316
18.29,121.50,0.316
18.31,121.72,0.316
18.33,121.93,0.316
18.35,122.15,0.316
18.37,122.37,0.316
18.39,122.58,0.316
18.42,122.80,0.316
18.44,123.02,0.317
18.46,123.23,0.317
18.48,123.45,0.317
18.50,123.67,0.317
18.53,123.89,0.317
18.55,124.10,0.317
18.57,124.32,0.317
18.59,124.54,0.318
18.61,124.75,0.318
18.63,124.97,0.318
18.66,125.19,0.318
18.68,125.40,0.318
18.70,125.62,0.318
18.72,125.84,0.318
18.74,126.05,0.319
18.76,126.27,0.319
18.78,126.49,0.319
18.81,126.71,0.319
18.83,126.92,0.319
18.85,127.14,0.319
18.87,127.36,0.319
18.89,127.57,0.319
18.92,127.79,0.320
18.94,128.00,0.320
18.96,128.22,0.320
18.98,128.44,0.320
19.00,128.66,0.320
19.02,128.87,0.320
19.04,129.09,0.320
19.07,129.31,0.320
19.09,129.52,0.321
19.11,129.74,0.321
19.13,129.96,0.321
19.15,130.17,0.321
19.18,130.39,0.321
19.20,130.61,0.321
19.22,130.82,0.322
19.24,131.04,0.322
19.26,131.26,0.322
19.28,131.47,0.322
19.31,131.69,0.322
19.33,131.91,0.322
19.35,132.13,0.322
19.37,132.34,0.323
19.39,132.56,0.323
19.41,132.77,0.323
19.43,132.99,0.323
19.46,133.21,0.323
19.48,133.43,0.323
19.50,133.64,0.323
19.52,133.86,0.324
19.54,134.08,0.324
19.57,134.29,0.324
19.59,134.51,0.324
19.61,134.73,0.324
19.63,134.94,0.324
19.65,135.16,0.324
19.67,135.38,0.324
19.69,135.59,0.325
19.72,135.81,0.325
19.74,136.03,0.325
19.76,136.24,0.325
19.78,136.46,0.325
19.80,136.68,0.325
19.83,136.90,0.326
19.85,137.11,0.326
19.87,137.33,0.326
19.89,137.55,0.326
19.91,137.76,0.326
19.93,137.98,0.326
19.96,138.20,0.326
19.98,138.41,0.327
20.00,138.63,0.327
20.02,138.85,0.327
20.04,139.06,0.327
20.06,139.28,0.327
20.08,139.50,0.327
20.11,139.71,0.328
20.13,139.93,0.328
20.15,140.15,0.328
20.17,140.36,0.328
20.19,140.58,0.328
20.22,140.80,0.328
20.24,141.02,0.328
20.26,141.23,0.329
20.28,141.45,0.329
20.30,141.66,0.329
20.32,141.88,0.329
20.34,142.10,0.329
20.37,142.31,0.329
20.39,142.53,0.330
20.41,142.75,0.330
20.43,142.97,0.330
20.45,143.18,0.330
20.48,143.40,0.330
20.50,143.62,0.330
20.52,143.83,0.331
20.54,144.05,0.331
20.56,144.27,0.331
20.58,144.48,0.331
20.61,144.70,0.331
20.63,144.92,0.331
20.65,145.13,0.332
20.67,145.35,0.332
20.69,145.57,0.332
20.71,145.78,0.332
20.73,146.00,0.332
20.76,146.22,0.333
20.78,146.44,0.333
20.80,146.65,0.333
20.82,146.87,0.333
20.84,147.09,0.333
20.87,147.30,0.333
20.89,147.52,0.334
20.91,147.74,0.334
20.93,147.95,0.334
20.95,148.17,0.334
20.97,148.39,0.334
20.99,148.60,0.334
21.02,148.82,0.335
21.04,149.04,0.335
21.06,149.25,0.335
21.08,149.47,0.335
21.10,149.69,0.335
21.13,149.90,0.336
21.15,150.12,0.336
21.17,150.34,0.336
21.19,150.55,0.336
21.21,150.77,0.336
21.23,150.99,0.337
21.26,151.20,0.337
21.28,151.42,0.337
21.30,151.64,0.337
21.32,151.85,0.338
21.34,152.07,0.338
21.36,152.29,0.338
21.38,152.51,0.338
21.41,152.72,0.338
21.43,152.94,0.339
21.45,153.16,0.339
21.47,153.37,0.339
21.49,153.59,0.339
21.52,153.81,0.339
21.54,154.02,0.340
21.56,154.24,0.340
21.58,154.46,0.340
21.60,154.67,0.340
21.62,154.89,0.340
21.64,155.11,0.341
21.67,155.33,0.341
21.69,155.54,0.341
21.71,155.76,0.341
21.73,155.98,0.342
21.75,156.19,0.342
21.78,156.41,0.342
21.80,156.63,0.343
21.82,156.84,0.343
21.84,157.06,0.343
21.86,157.28,0.343
21.88,157.49,0.344
21.91,157.71,0.344
21.93,157.93,0.345
21.95,158.14,0.345
21.97,158.36,0.346
21.99,158.58,0.346
22.01,158.79,0.347
22.03,159.01,0.347
22.06,159.22,0.348
22.08,159.44,0.348
22.10,159.66,0.349
22.12,159.87,0.350
22.14,160.09,0.352
22.17,160.31,0.352
22.19,160.52,0.354
22.21,160.74,0.355
22.23,160.96,0.357
22.25,161.17,0.360
22.27,161.39,0.361
22.29,161.60,0.363
22.32,161.82,0.365
22.34,162.04,0.367
22.36,162.25,0.372
22.38,162.47,0.375
22.40,162.69,0.380
22.43,162.90,0.384
22.45,163.12,0.387
22.47,163.33,0.392
22.49,163.55,0.397
22.51,163.77,0.402
22.53,163.98,0.408
22.56,164.20,0.412
22.58,164.41,0.418
22.60,164.63,0.424
22.62,164.85,0.429
22.64,165.06,0.434
22.66,165.28,0.440
22.68,165.49,0.447
22.71,165.71,0.454
22.73,165.92,0.459
22.75,166.14,0.465
22.77,166.35,0.470
22.79,166.57,0.474
22.82,166.78,0.478
22.84,167.00,0.483
22.86,167.21,0.484
22.88,167.43,0.485
22.90,167.65,0.486
22.92,167.86,0.486
22.94,168.08,0.486
22.97,168.30,0.484
22.99,168.51,0.478
23.01,168.73,0.470
23.03,168.95,0.460
23.05,169.17,0.449
23.08,169.39,0.440
23.10,169.61,0.430
23.12,169.83,0.419
23.14,170.05,0.409
23.16,170.27,0.397
23.18,170.49,0.387
23.21,170.71,0.378
23.23,170.93,0.370
23.25,171.15,0.361
23.27,171.36,0.351
23.29,171.58,0.347
23.31,171.80,0.341
23.33,172.02,0.335
23.36,172.24,0.330
23.38,172.46,0.325
23.40,172.67,0.322
23.42,172.89,0.319
23.44,173.11,0.317
23.47,173.33,0.314
23.49,173.55,0.312
23.51,173.76,0.310
23.53,173.98,0.309
23.55,174.20,0.307
23.57,174.42,0.305
23.59,174.63,0.303
23.62,174.85,0.302
23.64,175.07,0.300
23.66,175.29,0.299
23.68,175.50,0.298
23.70,175.72,0.297
23.73,175.94,0.295
23.75,176.15,0.294
23.77,176.37,0.292
23.79,176.59,0.291
23.81,176.81,0.290
23.83,177.02,0.288
23.86,177.24,0.287
23.88,177.46,0.286
23.90,177.67,0.285
23.92,177.89,0.284
23.94,178.11,0.283
23.96,178.33,0.282
23.98,178.54,0.281
24.01,178.76,0.280
24.03,178.98,0.278
24.05,179.20,0.277
24.07,179.41,0.276
24.09,179.63,0.275
24.12,179.85,0.273
24.14,180.07,0.271
24.16,180.28,0.269
24.18,180.50,0.268
24.20,180.72,0.267
24.22,180.93,0.266
24.24,181.15,0.265
24.27,181.37,0.264
24.29,181.58,0.263
24.31,181.80,0.261
24.33,182.02,0.260
24.35,182.23,0.259
24.38,182.45,0.258
24.40,182.67,0.256
24.42,182.89,0.255
24.44,183.10,0.255
24.46,183.32,0.254
24.48,183.54,0.254
24.51,183.75,0.253
24.53,183.97,0.252
24.55,184.19,0.252
24.57,184.40,0.251
24.59,184.62,0.250
24.61,184.84,0.250
24.63,185.06,0.250
24.66,185.27,0.249
24.68,185.49,0.249
24.70,185.71,0.248
24.72,185.92,0.248
24.74,186.14,0.248
24.77,186.36,0.248
24.79,186.57,0.248
24.81,186.79,0.248
24.83,187.01,0.248
24.85,187.22,0.248
24.87,187.44,0.248
24.89,187.65,0.249
24.92,187.87,0.249
24.94,188.09,0.250
24.96,188.31,0.251
24.98,188.52,0.253
25.00,188.74,0.255
25.03,188.96,0.256
25.05,189.17,0.258
25.07,189.39,0.259
25.09,189.60,0.261
25.11,189.82,0.262
25.13,190.04,0.264
25.16,190.25,0.266
25.18,190.47,0.269
25.20,190.69,0.271
25.22,190.90,0.272
25.24,191.12,0.274
25.26,191.33,0.276
25.28,191.55,0.277
25.31,191.77,0.278
25.33,191.98,0.280
25.35,192.20,0.281
25.37,192.42,0.282
25.39,192.63,0.283
25.42,192.85,0.284
25.44,193.07,0.285
25.46,193.28,0.286
25.48,193.50,0.287
25.50,193.72,0.287
25.52,193.93,0.288
25.54,194.15,0.289
25.57,194.37,0.290
25.59,194.58,0.290
25.61,194.80,0.291
25.63,195.02,0.291
25.65,195.23,0.292
25.68,195.45,0.292
25.70,195.67,0.292
25.72,195.88,0.293
25.74,196.10,0.293
25.76,196.32,0.293
25.78,196.53,0.294
25.81,196.75,0.294
25.83,196.97,0.294
25.85,197.18,0.294
25.87,197.40,0.294
25.89,197.62,0.294
25.91,197.84,0.294
25.93,198.05,0.294
25.96,198.27,0.294
25.98,198.49,0.293
26.00,198.70,0.292
26.02,198.92,0.292
26.04,199.14,0.291
26.07,199.35,0.290
26.09,199.57,0.290
26.11,199.79,0.289
26.13,200.01,0.285
26.15,200.22,0.282
26.17,200.44,0.279
26.19,200.66,0.276
26.22,200.88,0.273
26.24,201.09,0.269
26.26,201.31,0.265
26.28,201.53,0.262
26.30,201.75,0.258
26.33,201.96,0.254
26.35,202.18,0.250
26.37,202.40,0.245
26.39,202.62,0.240
26.41,202.83,0.235
26.43,203.05,0.230
26.46,203.27,0.225
26.48,203.49,0.218
26.50,203.71,0.213
26.52,203.93,0.206
26.54,204.14,0.201
26.56,204.36,0.194
26.58,204.58,0.187
26.61,204.80,0.180
26.63,205.02,0.172
26.65,205.24,0.163
26.67,205.45,0.155
26.69,205.67,0.147
26.72,205.89,0.138
26.74,206.11,0.130
26.76,206.33,0.122
26.78,206.55,0.113
26.80,206.77,0.106
26.82,206.99,0.099
26.84,207.21,0.092
26.87,207.43,0.082
26.89,207.64,0.077
26.91,207.86,0.070
26.93,208.08,0.067
26.95,208.30,0.062
26.98,208.52,0.060
27.00,208.74,0.058
27.02,208.95,0.058
27.04,209.17,0.060
27.06,209.39,0.064
27.08,209.60,0.068
27.11,209.82,0.076
27.13,210.03,0.086
27.15,210.25,0.100
27.17,210.46,0.124
27.19,210.67,0.142
27.21,210.89,0.169
27.23,211.10,0.205
27.26,211.30,0.258
27.28,211.51,0.297
27.30,211.72,0.351
27.32,211.92,0.403
27.34,212.13,0.467
27.37,212.33,0.539
27.39,212.53,0.615
27.41,212.73,0.687
27.43,212.93,0.803
27.45,213.12,0.898
27.47,213.31,1.000
27.49,213.50,1.132
27.52,213.69,1.256
27.54,213.88,1.357
27.56,214.07,1.493
27.58,214.25,1.639
27.60,214.43,1.856
27.63,214.61,1.934
27.65,214.78,2.229
27.67,214.95,2.317
27.69,215.13,2.424
27.71,215.32,2.554
27.73,215.49,2.745
27.76,215.66,3.107
27.78,215.82,3.277
27.80,215.99,3.335
27.82,216.17,3.476
27.84,216.35,3.587
27.86,216.53,3.758
27.88,216.71,3.772
27.91,216.91,3.743
27.93,217.12,3.619
27.95,217.36,3.424
27.97,217.60,3.102
27.99,217.86,2.940
28.02,218.14,2.528
28.04,218.43,2.057
28.06,218.74,1.678
28.08,219.04,1.472
28.10,219.32,1.336
28.12,219.59,1.246
28.14,219.85,1.164
28.17,220.10,1.119
28.19,220.34,1.060
28.21,220.58,1.008
28.23,220.82,0.968
28.25,221.05,0.938
28.28,221.28,0.909
28.30,221.50,0.900
28.32,221.73,0.877
28.34,221.95,0.853
28.36,222.17,0.833
28.38,222.40,0.813
28.41,222.62,0.801
28.43,222.84,0.785
28.45,223.06,0.776
28.47,223.28,0.764
28.49,223.50,0.753
28.51,223.72,0.739
28.53,223.94,0.726
28.56,224.16,0.715
28.58,224.38,0.705
28.60,224.60,0.695
28.62,225.13,-0.485
28.64,225.66,-0.166
28.67,225.97,-0.121
28.69,226.22,-0.120
28.71,226.44,-0.120
28.73,226.67,-0.120
28.75,226.89,-0.120
28.77,227.11,-0.121
28.79,227.33,-0.121
28.82,227.55,-0.122
28.84,227.77,-0.122
28.86,227.99,-0.122
28.88,228.21,-0.122
28.90,228.42,-0.122
28.93,228.64,-0.122
28.95,228.86,-0.123
28.97,229.08,-0.123
28.99,229.29,-0.123
29.01,229.51,-0.123
29.03,229.73,-0.123
29.06,229.95,-0.123
29.08,230.16,-0.123
29.10,230.38,-0.124
29.12,230.60,-0.124
29.14,230.82,-0.124
29.16,231.04,-0.124
29.18,231.25,-0.125
29.21,231.47,-0.125
29.23,231.69,-0.125
29.25,231.91,-0.126
29.27,232.12,-0.126
29.29,232.34,-0.126
29.32,232.56,-0.127
29.34,232.78,-0.127
29.36,232.99,-0.128
29.38,233.21,-0.128
29.40,233.43,-0.128
29.42,233.65,-0.129
29.44,233.87,-0.129
29.47,234.08,-0.129
29.49,234.30,-0.130
29.51,234.52,-0.130
29.53,234.74,-0.130
29.55,234.95,-0.130
29.58,235.17,-0.131
29.60,235.39,-0.131
29.62,235.61,-0.131
29.64,235.82,-0.132
29.66,236.04,-0.132
29.68,236.26,-0.132
29.71,236.47,-0.133
29.73,236.69,-0.133
29.75,236.91,-0.133
29.77,237.13,-0.133
29.79,237.34,-0.134
29.81,237.56,-0.134
29.83,237.78,-0.134
29.86,238.00,-0.134
29.88,238.21,-0.135
29.90,238.43,-0.135
29.92,238.65,-0.135
29.94,238.87,-0.135
29.97,239.08,-0.136
29.99,239.30,-0.136
30.01,239.52,-0.136
30.03,239.74,-0.136
30.05,239.95,-0.136
30.07,240.17,-0.137
30.09,240.39,-0.137
30.12,240.60,-0.137
30.14,240.82,-0.137
30.16,241.04,-0.137
30.18,241.25,-0.137
30.20,241.47,-0.138
30.23,241.69,-0.138
30.25,241.90,-0.138
30.27,242.12,-0.138
30.29,242.34,-0.138
30.31,242.56,-0.138
30.33,242.77,-0.138
30.36,242.99,-0.138
30.38,243.21,-0.138
30.40,243.42,-0.139
30.42,243.64,-0.139
30.44,243.86,-0.139
30.46,244.07,-0.139
30.48,244.29,-0.139
30.51,244.51,-0.139
30.53,244.72,-0.139
30.55,244.94,-0.139
30.57,245.16,-0.139
30.59,245.37,-0.139
30.62,245.59,-0.139
30.64,245.81,-0.139
30.66,246.02,-0.139
30.68,246.24,-0.139
30.70,246.46,-0.139
30.72,246.67,-0.140
30.74,246.89,-0.140
30.77,247.11,-0.140
30.79,247.32,-0.140
30.81,247.54,-0.140
30.83,247.76,-0.140
30.85,247.97,-0.140
30.88,248.19,-0.140
30.90,248.41,-0.140
30.92,248.62,-0.140
30.94,248.84,
30.96,249.06,
30.98,249.27,
30.99,,

[step]
Ramp 10.00 °C/min to -60.00 °C
Time,Temperature,Heat Flow (Normalized)
min,°C,W/g
32.99,250.21,-0.050
33.02,250.21,-0.050
33.04,250.20,-0.050
33.06,250.17,-0.050
33.08,250.09,-0.046
33.10,249.97,-0.034
33.12,249.80,-0.023
33.14,249.60,-0.012
33.17,249.39,-0.004
33.19,249.16,0.004
33.21,248.94,0.009
33.23,248.72,0.013
33.25,248.50,0.017
33.28,248.28,0.020
33.30,248.06,0.021
33.32,247.85,0.023
33.34,247.63,0.025
33.36,247.42,0.026
33.38,247.20,0.027
33.41,246.98,0.028
33.43,246.77,0.028
33.45,246.55,0.029
33.47,246.34,0.030
33.49,246.12,0.030
33.51,245.91,0.030
33.53,245.69,0.031
33.56,245.47,0.031
33.58,245.26,0.032
33.60,245.04,0.032
33.62,244.83,0.033
33.64,244.61,0.033
33.67,244.39,0.034
33.69,244.18,0.034
33.71,243.96,0.034
33.73,243.75,0.035
33.75,243.53,0.035
33.77,243.32,0.035
33.79,243.10,0.035
33.82,242.89,0.036
33.84,242.67,0.036
33.86,242.46,0.036
33.88,242.24,0.036
33.90,242.02,0.037
33.93,241.81,0.037
33.95,241.59,0.037
33.97,241.37,0.037
33.99,241.16,0.037
34.01,240.94,0.038
34.03,240.73,0.038
34.06,240.51,0.038
34.08,240.30,0.038
34.10,240.08,0.038
34.12,239.86,0.038
34.14,239.65,0.038
34.16,239.43,0.039
34.19,239.22,0.039
34.21,239.00,0.039
34.23,238.78,0.039
34.25,238.57,0.039
34.27,238.35,0.039
34.29,238.13,0.039
34.31,237.92,0.039
34.34,237.70,0.039
34.36,237.49,0.040
34.38,237.27,0.040
34.40,237.05,0.040
34.42,236.84,0.040
34.44,236.62,0.040
34.47,236.40,0.040
34.49,236.19,0.040
34.51,235.97,0.040
34.53,235.76,0.040
34.55,235.54,0.040
34.58,235.32,0.040
34.60,235.11,0.041
34.62,234.89,0.041
34.64,234.67,0.041
34.66,234.46,0.041
34.68,234.24,0.041
34.71,234.02,0.041
34.73,233.81,0.041
34.75,233.59,0.041
34.77,233.38,0.041
34.79,233.16,0.041
34.81,232.94,0.041
34.84,232.72,0.041
34.86,232.51,0.041
34.88,232.29,0.041
34.90,232.07,0.041
34.92,231.86,0.041
34.94,231.64,0.041
34.96,231.43,0.041
34.99,231.21,0.041
35.01,230.99,0.041
35.03,230.77,0.041
35.05,230.56,0.042
35.07,230.34,0.042
35.09,230.12,0.042
35.12,229.91,0.042
35.14,229.69,0.042
35.16,229.47,0.042
35.18,229.26,0.042
35.20,229.04,0.042
35.23,228.82,0.042
35.25,228.60,0.042
35.27,228.39,0.042
35.29,228.17,0.042
35.31,227.96,0.042
35.33,227.74,0.042
35.36,227.52,0.042
35.38,227.31,0.043
35.40,227.09,0.043
35.42,226.87,0.043
35.44,226.66,0.043
35.46,226.44,0.043
35.49,226.23,0.043
35.51,226.01,0.043
35.53,225.79,0.043
35.55,225.57,0.043
35.57,225.36,0.043
35.59,225.14,0.043
35.61,224.93,0.043
35.64,224.71,0.043
35.66,224.49,0.043
35.68,224.27,0.043
35.70,224.06,0.043
35.72,223.84,0.043
35.74,223.62,0.043
35.77,223.41,0.043
35.79,223.19,0.043
35.81,222.98,0.043
35.83,222.76,0.043
35.85,222.54,0.043
35.88,222.33,0.043
35.90,222.11,0.043
35.92,221.89,0.043
35.94,221.68,0.043
35.96,221.46,0.043
35.98,221.24,0.043
36.01,221.03,0.043
36.03,220.81,0.043
36.05,220.59,0.044
36.07,220.38,0.043
36.09,220.16,0.044
36.11,219.94,0.045
36.14,219.73,0.045
36.16,219.51,0.045
36.18,219.29,0.045
36.20,219.07,0.046
36.22,218.86,0.046
36.24,218.64,0.046
36.26,218.42,0.046
36.29,218.21,0.046
36.31,217.99,0.046
36.33,217.77,0.046
36.35,217.56,0.046
36.37,217.34,0.046
36.39,217.13,0.046
36.42,216.91,0.046
36.44,216.69,0.046
36.46,216.47,0.046
36.48,216.26,0.046
36.50,216.04,0.046
36.53,215.83,0.046
36.55,215.61,0.046
36.57,215.39,0.046
36.59,215.17,0.046
36.61,214.96,0.046
36.63,214.74,0.046
36.66,214.52,0.046
36.68,214.31,0.046
36.70,214.09,0.046
36.72,213.87,0.046
36.74,213.66,0.046
36.76,213.44,0.046
36.79,213.22,0.046
36.81,213.00,0.046
36.83,212.79,0.046
36.85,212.57,0.046
36.87,212.36,0.046
36.89,212.14,0.046
36.91,211.92,0.049
36.94,211.71,0.049
36.96,211.49,0.049
36.98,211.27,0.049
37.00,211.06,0.049
37.02,210.84,0.050
37.04,210.62,0.050
37.07,210.41,0.050
37.09,210.19,0.049
37.11,209.97,0.049
37.13,209.76,0.050
37.15,209.54,0.050
37.18,209.32,0.050
37.20,209.11,0.050
37.22,208.89,0.050
37.24,208.67,0.050
37.26,208.46,0.049
37.28,208.24,0.049
37.31,208.02,0.049
37.33,207.80,0.049
37.35,207.59,0.049
37.37,207.37,0.049
37.39,207.16,0.049
37.41,206.94,0.049
37.44,206.72,0.049
37.46,206.51,0.049
37.48,206.29,0.049
37.50,206.07,0.050
37.52,205.85,0.050
37.54,205.64,0.050
37.56,205.42,0.050
37.59,205.20,0.050
37.61,204.99,0.050
37.63,204.77,0.050
37.65,204.56,0.050
37.67,204.34,0.050
37.69,204.12,0.050
37.72,203.91,0.050
37.74,203.69,0.050
37.76,203.47,0.050
37.78,203.26,0.050
37.80,203.04,0.050
37.83,202.82,0.050
37.85,202.61,0.050
37.87,202.39,0.050
37.89,202.17,0.050
37.91,201.95,0.050
37.93,201.74,0.050
37.96,201.52,0.050
37.98,201.31,0.050
38.00,201.09,0.050
38.02,200.87,0.050
38.04,200.66,0.050
38.06,200.44,0.051
38.09,200.22,0.051
38.11,200.00,0.051
38.13,199.79,0.051
38.15,199.57,0.051
38.17,199.35,0.051
38.19,199.14,0.051
38.21,198.92,0.051
38.24,198.71,0.051
38.26,198.49,0.051
38.28,198.27,0.051
38.30,198.06,0.051
38.32,197.84,0.051
38.34,197.62,0.051
38.37,197.40,0.051
38.39,197.19,0.051
38.41,196.97,0.051
38.43,196.75,0.051
38.45,196.54,0.051
38.48,196.32,0.051
38.50,196.11,0.051
38.52,195.89,0.051
38.54,195.67,0.051
38.56,195.45,0.051
38.58,195.24,0.051
38.61,195.02,0.051
38.63,194.80,0.051
38.65,194.59,0.051
38.67,194.37,0.051
38.69,194.16,0.051
38.71,193.94,0.051
38.74,193.72,0.051
38.76,193.51,0.051
38.78,193.29,0.051
38.80,193.07,0.051
38.82,192.85,0.051
38.84,192.64,0.051
38.86,192.42,0.051
38.89,192.20,0.051
38.91,191.99,0.051
38.93,191.77,0.051
38.95,191.55,0.052
38.97,191.34,0.052
38.99,191.12,0.052
39.02,190.90,0.052
39.04,190.68,0.052
39.06,190.47,0.052
39.08,190.25,0.052
39.10,190.04,0.052
39.13,189.82,0.052
39.15,189.60,0.052
39.17,189.39,0.052
39.19,189.17,0.052
39.21,188.95,0.052
39.23,188.74,0.052
39.26,188.52,0.052
39.28,188.30,0.052
39.30,188.09,0.052
39.32,187.87,0.052
39.34,187.65,0.052
39.36,187.44,0.052
39.39,187.22,0.052
39.41,187.00,0.052
39.43,186.79,0.052
39.45,186.57,0.052
39.47,186.35,0.052
39.49,186.14,0.052
39.51,185.92,0.052
39.54,185.70,0.052
39.56,185.49,0.052
39.58,185.27,0.052
39.60,185.05,0.052
39.62,184.84,0.052
39.64,184.62,0.052
39.67,184.40,0.052
39.69,184.19,0.052
39.71,183.97,0.052
39.73,183.75,0.052
39.75,183.54,0.052
39.78,183.32,0.052
39.80,183.10,0.052
39.82,182.88,0.052
39.84,182.67,0.052
39.86,182.45,0.052
39.88,182.23,0.052
39.91,182.02,0.052
39.93,181.80,0.052
39.95,181.58,0.052
39.97,181.37,0.052
39.99,181.15,0.052
40.01,180.94,0.052
40.04,180.72,0.052
40.06,180.50,0.052
40.08,180.29,0.052
40.10,180.07,0.052
40.12,179.85,0.052
40.14,179.64,0.052
40.16,179.42,0.052
40.19,179.20,0.052
40.21,178.99,0.052
40.23,178.77,0.052
40.25,178.55,0.052
40.27,178.33,0.052
40.29,178.12,0.052
40.32,177.90,0.052
40.34,177.68,0.052
40.36,177.47,0.052
40.38,177.25,0.052
40.40,177.03,0.052
[...]
200.40,-36.85,-0.091
200.41,-36.78,-0.091
200.42,-36.71,-0.091
200.42,-36.65,-0.091
200.43,-36.58,-0.091
200.44,-36.51,-0.091
200.44,-36.45,-0.091
200.45,-36.38,-0.091
200.46,-36.31,-0.091
200.46,-36.24,-0.091
200.47,-36.18,-0.091
200.48,-36.11,-0.091
200.48,-36.04,-0.091
200.49,-35.98,-0.091
200.50,-35.91,-0.091
200.50,-35.84,-0.092
200.51,-35.78,-0.092
200.52,-35.71,-0.092
200.52,-35.65,-0.092
200.53,-35.58,-0.092
200.54,-35.51,-0.092
200.54,-35.44,-0.092
200.55,-35.38,-0.092
200.56,-35.31,-0.092
200.56,-35.24,-0.092
200.57,-35.18,-0.092
200.58,-35.11,-0.092
200.58,-35.04,-0.092
200.59,-34.98,-0.092
200.60,-34.91,-0.092
200.60,-34.84,-0.092
200.61,-34.78,-0.092
200.62,-34.71,-0.092
200.62,-34.64,-0.092
200.63,-34.58,-0.092
200.64,-34.51,-0.092
200.64,-34.44,-0.092
200.65,-34.38,-0.092
200.66,-34.31,-0.093
200.66,-34.24,-0.093
200.67,-34.18,-0.093
200.68,-34.11,-0.093
200.68,-34.04,-0.093
200.69,-33.98,-0.093
200.70,-33.91,-0.093
200.70,-33.84,-0.093
200.71,-33.78,-0.093
200.72,-33.71,-0.093
200.72,-33.64,-0.093
200.73,-33.58,-0.093
200.74,-33.51,-0.093
200.74,-33.44,-0.093
200.75,-33.38,-0.093
200.76,-33.31,-0.093
200.76,-33.24,-0.093
200.77,-33.17,-0.093
200.78,-33.11,-0.093
200.78,-33.04,-0.093
200.79,-32.97,-0.093
200.80,-32.91,-0.093
200.80,-32.84,-0.093
200.81,-32.77,-0.094
200.82,-32.71,-0.094
200.82,-32.64,-0.094
200.83,-32.57,-0.094
200.84,-32.51,-0.094
200.84,-32.44,-0.094
200.85,-32.37,-0.094
200.86,-32.31,-0.094
200.86,-32.24,-0.094
200.87,-32.17,-0.094
200.88,-32.11,-0.094
200.88,-32.04,-0.094
200.89,-31.97,-0.094
200.90,-31.91,-0.094
200.90,-31.84,-0.094
200.91,-31.77,-0.094
200.92,-31.70,-0.094
200.92,-31.64,-0.094
200.93,-31.57,-0.094
200.94,-31.50,-0.094
200.94,-31.44,-0.094
200.95,-31.37,-0.094
200.96,-31.31,-0.094
200.96,-31.24,-0.094
200.97,-31.17,-0.094
200.98,-31.10,-0.094
200.98,-31.04,-0.095
200.99,-30.97,-0.095
201.00,-30.90,-0.095
201.00,-30.84,-0.095
201.01,-30.77,-0.095
201.02,-30.70,-0.095
201.02,-30.64,-0.095
201.03,-30.57,-0.095
201.04,-30.50,-0.095
201.04,-30.44,-0.095
201.05,-30.37,-0.095
201.06,-30.30,-0.095
201.06,-30.23,-0.095
201.07,-30.17,-0.095
201.08,-30.10,-0.095
201.08,-30.03,-0.095
201.09,-29.97,-0.095
201.10,-29.90,-0.095
201.10,-29.83,-0.095
201.11,-29.77,-0.095
201.12,-29.70,-0.095
201.12,-29.63,-0.095
201.13,-29.57,-0.095
201.14,-29.50,-0.095
201.14,-29.43,-0.095
201.15,-29.37,-0.096
201.16,-29.30,-0.096
201.16,-29.23,-0.096
201.17,-29.17,-0.096
201.18,-29.10,-0.096
201.18,-29.03,-0.096
201.19,-28.97,-0.096
201.20,-28.90,-0.096
201.20,-28.84,-0.096
201.21,-28.77,-0.096
201.22,-28.70,-0.096
201.22,-28.63,-0.096
201.23,-28.57,-0.096
201.24,-28.50,-0.096
201.24,-28.43,-0.096
201.25,-28.37,-0.096
201.26,-28.30,-0.096
201.26,-28.23,-0.096
201.27,-28.17,-0.096
201.28,-28.10,-0.096
201.28,-28.03,-0.096
201.29,-27.97,-0.096
201.30,-27.90,-0.096
201.30,-27.83,-0.096
201.31,-27.76,-0.096
201.32,-27.70,-0.096
201.32,-27.63,-0.096
201.33,-27.56,-0.097
201.34,-27.50,-0.097
201.34,-27.43,-0.097
201.35,-27.36,-0.097
201.36,-27.30,-0.097
201.36,-27.23,-0.097
201.37,-27.16,-0.097
201.38,-27.10,-0.097
201.38,-27.03,-0.097
201.39,-26.96,-0.097
201.40,-26.90,-0.097
201.40,-26.83,-0.097
201.41,-26.76,-0.097
201.42,-26.70,-0.097
201.42,-26.63,-0.097
201.43,-26.56,-0.097
201.44,-26.50,-0.097
201.44,-26.43,-0.097
201.45,-26.36,-0.097
201.46,-26.30,-0.097
201.46,-26.23,-0.097
201.47,-26.16,-0.097
201.48,-26.10,-0.097
201.48,-26.03,-0.097
201.49,-25.96,-0.097
201.50,-25.90,-0.097
201.50,-25.83,-0.097
201.51,-25.76,-0.097
201.52,-25.70,-0.097
201.52,-25.63,-0.097
201.53,-25.56,-0.098
201.54,-25.50,-0.098
201.54,-25.43,-0.098
201.55,-25.36,-0.098
201.56,-25.30,-0.098
201.56,-25.23,-0.098
201.57,-25.16,-0.098
201.58,-25.10,-0.098
201.58,-25.03,-0.098
201.59,-24.96,-0.098
201.60,-24.90,-0.098
201.60,-24.83,-0.098
201.61,-24.76,-0.098
201.62,-24.69,-0.098
201.62,-24.63,-0.098
201.63,-24.56,-0.098
201.64,-24.49,-0.098
201.64,-24.43,-0.098
201.65,-24.36,-0.098
201.66,-24.29,-0.098
201.66,-24.23,-0.098
201.67,-24.16,-0.098
201.68,-24.09,-0.098
201.68,-24.03,-0.098
201.69,-23.96,-0.098
201.70,-23.89,-0.098
201.70,-23.83,-0.098
201.71,-23.76,-0.098
201.72,-23.69,-0.099
201.72,-23.63,-0.099
201.73,-23.56,-0.099
201.74,-23.49,-0.099
201.74,-23.43,-0.099
201.75,-23.36,-0.099
201.76,-23.29,-0.099
201.76,-23.23,-0.099
201.77,-23.16,-0.099
201.78,-23.09,-0.099
201.78,-23.03,-0.099
201.79,-22.96,-0.099
201.80,-22.89,-0.099
201.80,-22.83,-0.099
201.81,-22.76,-0.099
201.82,-22.69,-0.099
201.82,-22.63,-0.099
201.83,-22.56,-0.099
201.84,-22.49,-0.099
201.84,-22.42,-0.099
201.85,-22.36,-0.099
201.86,-22.29,-0.099
201.86,-22.23,-0.099
201.87,-22.16,-0.099
201.88,-22.09,-0.099
201.88,-22.02,-0.099
201.89,-21.96,-0.099
201.90,-21.89,-0.099
201.90,-21.83,-0.099
201.91,-21.76,-0.100
201.92,-21.69,-0.100
201.92,-21.62,-0.100
201.93,-21.56,-0.100
201.94,-21.49,-0.100
201.94,-21.42,-0.100
201.95,-21.36,-0.100
201.96,-21.29,-0.100
201.96,-21.22,-0.100
201.97,-21.16,-0.100
201.98,-21.09,-0.100
201.98,-21.02,-0.100
201.99,-20.96,-0.100
202.00,-20.89,-0.100
202.00,-20.83,-0.100
202.01,-20.76,-0.100
202.02,-20.69,-0.100
202.02,-20.62,-0.100
202.03,-20.56,-0.100
202.04,-20.49,-0.100
202.04,-20.42,-0.100
202.05,-20.36,-0.100
202.06,-20.29,-0.100
202.06,-20.22,-0.100
202.07,-20.16,-0.100
202.08,-20.09,-0.100
202.08,-20.02,-0.100
202.09,-19.95,-0.101
202.10,-19.89,-0.101
202.10,-19.82,-0.101
202.11,-19.75,-0.101
202.12,-19.69,-0.101
202.12,-19.62,-0.101
202.13,-19.56,-0.101
202.14,-19.49,-0.101
202.14,-19.42,-0.101
202.15,-19.35,-0.101
202.16,-19.29,-0.101
202.16,-19.22,-0.101
202.17,-19.15,-0.101
202.18,-19.09,-0.101
202.18,-19.02,-0.101
202.19,-18.95,-0.101
202.20,-18.89,-0.101
202.20,-18.82,-0.101
202.21,-18.75,-0.101
202.22,-18.69,-0.101
202.22,-18.62,-0.101
202.23,-18.55,-0.101
202.24,-18.49,-0.101
202.24,-18.42,-0.101
202.25,-18.35,-0.101
202.26,-18.29,-0.101
202.26,-18.22,-0.101
202.27,-18.15,-0.101
202.28,-18.09,-0.102
202.28,-18.02,-0.102
202.29,-17.95,-0.102
202.30,-17.89,-0.102
202.30,-17.82,-0.102
202.31,-17.75,-0.102
202.32,-17.69,-0.102
202.32,-17.62,-0.102
202.33,-17.55,-0.102
202.34,-17.49,-0.102
202.34,-17.42,-0.102
202.35,-17.35,-0.102
202.36,-17.29,-0.102
202.36,-17.22,-0.102
202.37,-17.15,-0.102
202.38,-17.08,-0.102
202.38,-17.02,-0.102
202.39,-16.95,-0.102
202.40,-16.88,-0.102
202.40,-16.82,-0.102
202.41,-16.75,-0.102
202.42,-16.68,-0.102
202.42,-16.62,-0.102
202.43,-16.55,-0.102
202.44,-16.49,-0.102
202.44,-16.42,-0.102
202.45,-16.35,-0.102
202.46,-16.29,-0.102
202.46,-16.22,-0.102
202.47,-16.15,-0.102
202.48,-16.09,-0.103
202.48,-16.02,-0.103
202.49,-15.95,-0.103
202.50,-15.88,-0.103
202.50,-15.82,-0.103
202.51,-15.75,-0.103
202.52,-15.68,-0.103
202.52,-15.62,-0.103
202.53,-15.55,-0.103
202.54,-15.48,-0.103
202.54,-15.42,-0.103
202.55,-15.35,-0.103
202.56,-15.28,-0.103
202.56,-15.22,-0.103
202.57,-15.15,-0.103
202.58,-15.08,-0.103
202.58,-15.02,-0.103
202.59,-14.95,-0.103
202.60,-14.88,-0.103
202.60,-14.82,-0.103
202.61,-14.75,-0.103
202.62,-14.68,-0.103
202.62,-14.62,-0.103
202.63,-14.55,-0.103
202.64,-14.48,-0.103
202.64,-14.42,-0.103
202.65,-14.35,-0.103
202.66,-14.28,-0.103
202.66,-14.22,-0.103
202.67,-14.15,-0.103
202.68,-14.08,-0.103
202.68,-14.01,-0.104
202.69,-13.95,-0.104
202.70,-13.88,-0.104
202.70,-13.81,-0.104
202.71,-13.75,-0.104
202.72,-13.68,-0.104
202.72,-13.61,-0.104
202.73,-13.55,-0.104
202.74,-13.48,-0.104
202.74,-13.41,-0.104
202.75,-13.35,-0.104
202.76,-13.28,-0.104
202.76,-13.21,-0.104
202.77,-13.15,-0.104
202.78,-13.08,-0.104
202.78,-13.01,-0.104
202.79,-12.95,-0.104
202.80,-12.88,-0.104
202.80,-12.81,-0.104
202.81,-12.75,-0.104
202.82,-12.68,-0.104
202.82,-12.61,-0.104
202.83,-12.55,-0.104
202.84,-12.48,-0.104
202.84,-12.41,-0.104
202.85,-12.35,-0.104
202.86,-12.28,-0.104
202.86,-12.21,-0.104
202.87,-12.15,-0.104
202.88,-12.08,-0.104
202.88,-12.01,-0.104
202.89,-11.94,-0.104
202.90,-11.88,-0.104
202.90,-11.81,-0.105
202.91,-11.74,-0.105
202.92,-11.68,-0.105
202.92,-11.61,-0.105
202.93,-11.54,-0.105
202.94,-11.48,-0.105
202.94,-11.41,-0.105
202.95,-11.34,-0.105
202.96,-11.28,-0.105
202.96,-11.21,-0.105
202.97,-11.14,-0.105
202.98,-11.08,-0.105
202.98,-11.01,-0.105
202.99,-10.94,-0.105
203.00,-10.88,-0.105
203.00,-10.81,-0.105
203.01,-10.74,-0.105
203.02,-10.68,-0.105
203.02,-10.61,-0.105
203.03,-10.54,-0.105
203.04,-10.48,-0.105
203.04,-10.41,-0.105
203.05,-10.34,-0.105
203.06,-10.28,-0.105
203.06,-10.21,-0.105
203.07,-10.14,-0.105
203.08,-10.08,-0.105
203.08,-10.01,-0.105
203.09,-9.94,-0.105
203.10,-9.88,-0.105
203.10,-9.81,-0.105
203.11,-9.74,-0.105
203.12,-9.68,-0.105
203.12,-9.61,-0.105
203.13,-9.54,-0.106
203.14,-9.48,-0.106
203.14,-9.41,-0.106
203.15,-9.34,-0.106
203.16,-9.28,-0.106
203.16,-9.21,-0.106
203.17,-9.14,-0.106
203.18,-9.08,-0.106
203.18,-9.01,-0.106
203.19,-8.94,-0.106
203.20,-8.88,-0.106
203.20,-8.81,-0.106
203.21,-8.74,-0.106
203.22,-8.68,-0.106
203.22,-8.61,-0.106
203.23,-8.54,-0.106
203.24,-8.48,-0.106
203.24,-8.41,-0.106
203.25,-8.34,-0.106
203.26,-8.28,-0.106
203.26,-8.21,-0.106
203.27,-8.14,-0.106
203.28,-8.08,-0.106
203.28,-8.01,-0.106
203.29,-7.94,-0.106
203.30,-7.88,-0.106
203.30,-7.81,-0.106
203.31,-7.74,-0.106
203.32,-7.67,-0.106
203.32,-7.61,-0.106
203.33,-7.54,-0.106
203.34,-7.47,-0.106
203.34,-7.41,-0.106
203.35,-7.34,-0.106
203.36,-7.27,-0.106
203.36,-7.21,-0.106
203.37,-7.14,-0.106
203.38,-7.07,-0.106
203.38,-7.01,-0.106
203.39,-6.94,-0.106
203.40,-6.87,-0.107
203.40,-6.81,-0.107
203.41,-6.74,-0.107
203.42,-6.67,-0.107
203.42,-6.61,-0.107
203.43,-6.54,-0.107
203.44,-6.47,-0.107
203.44,-6.41,-0.107
203.45,-6.34,-0.107
203.46,-6.27,-0.107
203.46,-6.20,-0.107
203.47,-6.14,-0.107
203.48,-6.07,-0.107
203.48,-6.00,-0.107
203.49,-5.94,-0.107
203.50,-5.87,-0.107
203.50,-5.80,-0.107
203.51,-5.74,-0.107
203.52,-5.67,-0.107
203.52,-5.60,-0.107
203.53,-5.54,-0.107
203.54,-5.47,-0.107
203.54,-5.40,-0.107
203.55,-5.34,-0.107
203.56,-5.27,-0.107
203.56,-5.20,-0.107
203.57,-5.14,-0.107
203.58,-5.07,-0.107
203.58,-5.00,-0.107
203.59,-4.94,-0.107
203.60,-4.87,-0.107
203.60,-4.80,-0.107
203.61,-4.74,-0.107
203.62,-4.67,-0.107
203.62,-4.60,-0.107
203.63,-4.54,-0.107
203.64,-4.47,-0.108
203.64,-4.40,-0.108
203.65,-4.34,-0.108
203.66,-4.27,-0.108
203.66,-4.20,-0.108
203.67,-4.14,-0.108
203.68,-4.07,-0.108
203.68,-4.00,-0.108
203.69,-3.94,-0.108
203.70,-3.87,-0.108
203.70,-3.80,-0.108
203.71,-3.74,-0.108
203.72,-3.67,-0.108
203.72,-3.60,-0.108
203.73,-3.54,-0.108
203.74,-3.47,-0.108
203.74,-3.40,-0.108
203.75,-3.34,-0.108
203.76,-3.27,-0.108
203.76,-3.20,-0.108
203.77,-3.14,-0.108
203.78,-3.07,-0.108
203.78,-3.00,-0.108
203.79,-2.94,-0.108
203.80,-2.87,-0.108
203.80,-2.80,-0.108
203.81,-2.73,-0.108
203.82,-2.67,-0.108
203.82,-2.60,-0.108
203.83,-2.53,-0.108
203.84,-2.47,-0.108
203.84,-2.40,-0.108
203.85,-2.34,-0.108
203.86,-2.27,-0.108
203.86,-2.20,-0.108
203.87,-2.14,-0.108
203.88,-2.07,-0.109
203.88,-2.00,-0.109
203.89,-1.93,-0.109
203.90,-1.87,-0.109
203.90,-1.80,-0.109
203.91,-1.73,-0.109
203.92,-1.67,-0.109
203.92,-1.60,-0.109
203.93,-1.53,-0.109
203.94,-1.47,-0.109
203.94,-1.40,-0.109
203.95,-1.33,-0.109
203.96,-1.27,-0.109
203.96,-1.20,-0.109
203.97,-1.13,-0.109
203.98,-1.07,-0.109
203.98,-1.00,-0.109
203.99,-0.93,-0.109
204.00,-0.87,-0.109
204.00,-0.80,-0.109
204.01,-0.73,-0.109
204.02,-0.66,-0.109
204.02,-0.60,-0.109
204.03,-0.53,-0.109
204.04,-0.47,-0.109
204.04,-0.40,-0.109
204.05,-0.33,-0.109
204.06,-0.27,-0.109
204.06,-0.20,-0.109
204.07,-0.13,-0.109
204.08,-0.07,-0.109
204.08,0.00,-0.109
204.09,0.07,-0.109
204.10,0.14,-0.109
204.10,0.20,-0.109
204.11,0.27,-0.109
204.12,0.34,-0.109
204.12,0.40,-0.109
204.13,0.47,-0.110
204.14,0.54,-0.110
204.14,0.60,-0.110
204.15,0.67,-0.110
204.16,0.74,-0.110
204.16,0.80,-0.110
204.17,0.87,-0.110
204.18,0.94,-0.110
204.18,1.00,-0.110
204.19,1.07,-0.110
204.20,1.13,-0.110
204.20,1.20,-0.110
204.21,1.27,-0.110
204.22,1.34,-0.110
204.22,1.40,-0.110
204.23,1.47,-0.110
204.24,1.53,-0.110
204.24,1.60,-0.110
204.25,1.67,-0.110
204.26,1.74,-0.110
204.26,1.80,-0.110
204.27,1.87,-0.110
204.28,1.94,-0.110
204.28,2.00,-0.110
204.29,2.07,-0.110
204.30,2.14,-0.110
204.30,2.20,-0.110
204.31,2.27,-0.110
204.32,2.34,-0.110
204.32,2.40,-0.110
204.33,2.47,-0.110
204.34,2.54,-0.110
204.34,2.60,-0.110
204.35,2.67,-0.110
204.36,2.74,-0.110
204.36,2.80,-0.110
204.37,2.87,-0.110
204.38,2.94,-0.110
204.38,3.00,-0.110
204.39,3.07,-0.110
204.40,3.14,-0.110
204.40,3.20,-0.110
204.41,3.27,-0.110
204.42,3.34,-0.110
204.42,3.40,-0.111
204.43,3.47,-0.111
204.44,3.54,-0.111
204.44,3.60,-0.111
204.45,3.67,-0.111
204.46,3.74,-0.111
204.46,3.81,-0.111
204.47,3.87,-0.111
204.48,3.94,-0.111
204.48,4.00,-0.111
204.49,4.07,-0.111
204.50,4.14,-0.111
204.50,4.21,-0.111
204.51,4.27,-0.111
204.52,4.34,-0.111
204.52,4.41,-0.111
204.53,4.47,-0.111
204.54,4.54,-0.111
204.54,4.61,-0.111
204.55,4.67,-0.111
204.56,4.74,-0.111
204.56,4.81,-0.111
204.57,4.87,-0.111
204.58,4.94,-0.111
204.58,5.01,-0.111
204.59,5.07,-0.111
204.60,5.14,-0.111
204.60,5.21,-0.111
204.61,5.27,-0.111
204.62,5.34,-0.111
204.62,5.41,-0.111
204.63,5.47,-0.111
204.64,5.54,-0.111
204.64,5.61,-0.111
204.65,5.67,-0.111
204.66,5.74,-0.111
204.66,5.81,-0.111
204.67,5.87,-0.111
204.68,5.94,-0.111
204.68,6.01,-0.111
204.69,6.08,-0.111
204.70,6.14,-0.111
204.70,6.21,-0.111
204.71,6.28,-0.111
204.72,6.34,-0.112
204.72,6.41,-0.112
204.73,6.48,-0.112
204.74,6.54,-0.112
204.74,6.61,-0.112
204.75,6.67,-0.112
204.76,6.74,-0.112
204.76,6.81,-0.112
204.77,6.88,-0.112
204.78,6.94,-0.112
204.78,7.01,-0.112
204.79,7.08,-0.112
204.80,7.14,-0.112
204.80,7.21,-0.112
204.81,7.28,-0.112
204.82,7.34,-0.112
204.82,7.41,-0.112
204.83,7.48,-0.112
204.84,7.54,-0.112
204.84,7.61,-0.112
204.85,7.68,-0.112
204.86,7.74,-0.112
204.86,7.81,-0.112
204.87,7.88,-0.112
204.88,7.94,-0.112
204.88,8.01,-0.112
204.89,8.08,-0.112
204.90,8.14,-0.112
204.90,8.21,-0.112
204.91,8.28,-0.112
204.92,8.34,-0.112
204.92,8.41,-0.112
204.93,8.48,-0.112
204.94,8.54,-0.112
204.94,8.61,-0.112
204.95,8.68,-0.112
204.96,8.74,-0.112
204.96,8.81,-0.112
204.97,8.88,-0.112
204.98,8.94,-0.112
204.98,9.01,-0.112
204.99,9.08,-0.112
205.00,9.14,-0.112
205.00,9.21,-0.112
205.01,9.28,-0.112
205.02,9.34,-0.112
205.02,9.41,-0.112
205.03,9.48,-0.113
205.04,9.54,-0.113
205.04,9.61,-0.113
205.05,9.68,-0.113
205.06,9.74,-0.113
205.06,9.81,-0.113
205.07,9.88,-0.113
205.08,9.94,-0.113
205.08,10.01,-0.113
205.09,10.08,-0.113
205.10,10.15,-0.113
205.10,10.21,-0.113
205.11,10.28,-0.113
205.12,10.34,-0.113
205.12,10.41,-0.113
205.13,10.48,-0.113
205.14,10.55,-0.113
205.14,10.61,-0.113
205.15,10.68,-0.113
205.16,10.75,-0.113
205.16,10.81,-0.113
205.17,10.88,-0.113
205.18,10.95,-0.113
205.18,11.01,-0.113
205.19,11.08,-0.113
205.20,11.15,-0.113
205.20,11.21,-0.113
205.21,11.28,-0.113
205.22,11.35,-0.113
205.22,11.41,-0.113
205.23,11.48,-0.113
205.24,11.55,-0.113
205.24,11.61,-0.113
205.25,11.68,-0.113
205.26,11.75,-0.113
205.26,11.82,-0.113
205.27,11.88,-0.113
205.28,11.95,-0.113
205.28,12.01,-0.113
205.29,12.08,-0.113
205.30,12.15,-0.113
205.30,12.22,-0.113
205.31,12.28,-0.113
205.32,12.35,-0.113
205.32,12.41,-0.113
205.33,12.48,-0.113
205.34,12.55,-0.113
205.34,12.62,-0.114
205.35,12.68,-0.114
205.36,12.75,-0.114
205.36,12.81,-0.114
205.37,12.88,-0.114
205.38,12.95,-0.114
205.38,13.02,-0.114
205.39,13.08,-0.114
205.40,13.15,-0.114
205.40,13.22,-0.114
205.41,13.28,-0.114
205.42,13.35,-0.114
205.42,13.42,-0.114
205.43,13.48,-0.114
205.44,13.55,-0.114
205.44,13.62,-0.114
205.45,13.68,-0.114
205.46,13.75,-0.114
205.46,13.81,-0.114
205.47,13.88,-0.114
205.48,13.95,-0.114
205.48,14.02,-0.114
205.49,14.08,-0.114
205.50,14.15,-0.114
205.50,14.22,-0.114
205.51,14.28,-0.114
205.52,14.35,-0.114
205.52,14.42,-0.114
205.53,14.48,-0.114
205.54,14.55,-0.114
205.54,14.62,-0.114
205.55,14.68,-0.114
205.56,14.75,-0.114
205.56,14.82,-0.114
205.57,14.88,-0.114
205.58,14.95,-0.114
205.58,15.02,-0.114
205.59,15.08,-0.114
205.60,15.15,-0.114
205.60,15.22,-0.114
205.61,15.28,-0.115
205.62,15.35,-0.115
205.62,15.42,-0.115
205.63,15.48,-0.115
205.64,15.55,-0.115
205.64,15.62,-0.115
205.65,15.68,-0.115
205.66,15.75,-0.115
205.66,15.82,-0.115
205.67,15.88,-0.115
205.68,15.95,-0.115
205.68,16.02,-0.115
205.69,16.08,-0.115
205.70,16.15,-0.115
205.70,16.22,-0.115
205.71,16.29,-0.115
205.72,16.35,-0.115
205.72,16.42,-0.115
205.73,16.48,-0.115
205.74,16.55,-0.115
205.74,16.62,-0.115
205.75,16.68,-0.115
205.76,16.75,-0.115
205.76,16.82,-0.115
205.77,16.88,-0.115
205.78,16.95,-0.115
205.78,17.02,-0.115
205.79,17.09,-0.115
205.80,17.15,-0.115
205.80,17.22,-0.115
205.81,17.28,-0.115
205.82,17.35,-0.115
205.82,17.42,-0.115
205.83,17.49,-0.115
205.84,17.55,-0.115
205.84,17.62,-0.115
205.85,17.69,-0.115
205.86,17.75,-0.115
205.86,17.82,-0.115
205.87,17.88,-0.115
205.88,17.95,-0.115
205.88,18.02,-0.115
205.89,18.09,-0.115
205.90,18.15,-0.115
205.90,18.22,-0.115
205.91,18.29,-0.115
205.92,18.35,-0.115
205.92,18.42,-0.115
205.93,18.49,-0.115
205.94,18.55,-0.115
205.94,18.62,-0.115
205.95,18.69,-0.115
205.96,18.75,-0.115
205.96,18.82,-0.116
205.97,18.89,-0.116
205.98,18.95,-0.116
205.98,19.02,-0.116
205.99,19.09,-0.116
206.00,19.15,-0.116
206.00,19.22,-0.116
206.01,19.29,-0.116
206.02,19.35,-0.116
206.02,19.42,-0.116
206.03,19.49,-0.116
206.04,19.55,-0.116
206.04,19.62,-0.116
206.05,19.69,-0.116
206.06,19.75,-0.116
206.06,19.82,-0.116
206.07,19.89,-0.116
206.08,19.95,-0.116
206.08,20.02,-0.116
206.09,20.09,-0.116
206.10,20.15,-0.116
206.10,20.22,-0.116
206.11,20.29,-0.116
206.12,20.35,-0.116
206.12,20.42,-0.116
206.13,20.49,-0.116
206.14,20.55,-0.116
206.14,20.62,-0.116
206.15,20.69,-0.116
206.16,20.75,-0.116
206.16,20.82,-0.116
206.17,20.89,-0.116
206.18,20.95,-0.116
206.18,21.02,-0.116
206.19,21.09,-0.116
206.20,21.16,-0.116
206.20,21.22,-0.116
206.21,21.29,-0.116
206.22,21.36,-0.116
206.22,21.42,-0.116
206.23,21.49,-0.116
206.24,21.56,-0.116
206.24,21.62,-0.116
206.25,21.69,-0.116
206.26,21.76,-0.116
206.26,21.82,-0.116
206.27,21.89,-0.116
206.28,21.96,-0.116
206.28,22.02,-0.116
206.29,22.09,-0.116
206.30,22.16,-0.116
206.30,22.22,-0.117
206.31,22.29,-0.117
206.32,22.36,-0.117
206.32,22.42,-0.117
206.33,22.49,-0.117
206.34,22.56,-0.117
206.34,22.62,-0.117
206.35,22.69,-0.117
206.36,22.76,-0.117
206.36,22.82,-0.117
206.37,22.89,-0.117
206.38,22.96,-0.117
206.38,23.02,-0.117
206.39,23.09,-0.117
206.40,23.16,-0.117
206.40,23.22,-0.117
206.41,23.29,-0.117
206.42,23.36,-0.117
206.42,23.42,-0.117
206.43,23.49,-0.117
206.44,23.56,-0.117
206.44,23.62,-0.117
206.45,23.69,-0.117
206.46,23.76,-0.117
206.46,23.82,-0.117
206.47,23.89,-0.117
206.48,23.96,-0.117
206.48,24.03,-0.117
206.49,24.09,-0.117
206.50,24.16,-0.117
206.50,24.23,-0.117
206.51,24.29,-0.117
206.52,24.36,-0.117
206.52,24.43,-0.117
206.53,24.49,-0.117
206.54,24.56,-0.117
206.54,24.63,-0.117
206.55,24.69,-0.117
206.56,24.76,-0.117
206.56,24.83,-0.117
206.57,24.89,-0.117
206.58,24.96,-0.117
206.58,25.02,-0.117
206.59,25.09,-0.117
206.60,25.16,-0.117
206.60,25.23,-0.118
206.61,25.29,-0.118
206.62,25.36,-0.118
206.62,25.43,-0.118
206.63,25.49,-0.118
206.64,25.56,-0.118
206.64,25.63,-0.118
206.65,25.69,-0.118
206.66,25.76,-0.118
206.66,25.83,-0.118
206.67,25.89,-0.118
206.68,25.96,-0.118
206.68,26.03,-0.118
206.69,26.09,-0.118
206.70,26.16,-0.118
206.70,26.23,-0.118
206.71,26.29,-0.118
206.72,26.36,-0.118
206.72,26.43,-0.118
206.73,26.49,-0.118
206.74,26.56,-0.118
206.74,26.63,-0.118
206.75,26.69,-0.118
206.76,26.76,-0.118
206.76,26.83,-0.118
206.77,26.89,-0.118
206.78,26.96,-0.118
206.78,27.03,-0.118
206.79,27.10,-0.118
206.80,27.16,-0.118
206.80,27.23,-0.118
206.81,27.29,-0.118
206.82,27.36,-0.118
206.82,27.43,-0.118
206.83,27.49,-0.118
206.84,27.56,-0.118
206.84,27.63,-0.118
206.85,27.70,-0.118
206.86,27.76,-0.118
206.86,27.83,-0.118
206.87,27.90,-0.118
206.88,27.96,-0.118
206.88,28.03,-0.118
206.89,28.10,-0.118
206.90,28.16,-0.118
206.90,28.23,-0.118
206.91,28.30,-0.118
206.92,28.36,-0.118
206.92,28.43,-0.118
206.93,28.50,-0.118
206.94,28.56,-0.118
206.94,28.63,
206.95,28.70,
206.96,28.76,
206.96,28.83,
206.97,28.90,
206.98,28.96,
206.98,29.03,
206.99,,
207.00,,