File: DSC/2025_02_13_Benzoic_Acid_DSC.txt
Filename	2025_02_13_Benzoic_Acid_DSC
Instrument name	DSC2A-00468 (192.168.1.100)
Operator	JLY
rundate	2/13/2025
Sample name	2025_02_13_Benzoic_Acid_DSC
proceduresegments	Data Off ; Equilibrate 30.00 °C; Data On ; Ramp 5.00 °C/min to 150.00 °C
[File Parameters]
Run date	2/13/2025 7:25:54 PM
Trios version	5.1.1.46572
Original File Name
Current File Name	D:\DSC2500\CHM343\2025_02_13_Benzoic_Acid_DSC.tri
[Procedure]
Procedure Name	BA Melting
Sample Name	2025_02_13_Benzoic_Acid_DSC
Sample Mass	2.94 mg
Reference Sample Mass	0 mg
Pan Mass	54.23 mg
Pan Number	20
Reference Pan Mass	54 mg
Reference Pan Number	19
Pan Type	Tzero Aluminum Hermetic
Comments	Al Hermetic Sealed Pan, with ref Al pan
Project Name
Operator	JLY
Test	Custom
Unload Max Temperature	30
Unload Min Temperature	30
Load Max Temperature	30
Load Min Temperature	30
Stop on Gas Flow Error	Yes
[Signal List]
Signal #1	Time (min)
Signal #2	Temperature (°C)
Signal #3	Heat Flow (mW)
Signal #4	Delta T (µV)
Signal #5	Delta Tzero (µV)
Signal #6	Tzero Temperature (°C)
Signal #7	Cell Purge (mL/min)
Signal #8	Heater Temp (°C)
Signal #9	Power Delivered (W)
Signal #10	Reference Junction Temperature (°C)
Signal #11	Flange Temperature (°C)
Signal #12	Heat Flow Phase (rad)
Signal #13	Total Heat Capacity (J/°C)
Signal #14	Heat Capacity (J/°C)
[Configuration]
Company Name	ASU
Instrument Name	DSC2A-00468
Instrument Type	DSC2500
Serial Number	DSC2A-00468
IP	192.168.1.100
Location of Instrument	MRRC
DisplayType	Unknown
Sample Interval 	0.1 s/pt
Selected Heat Flow	T4P
Exotherm Direction	Down
Cell Serial	DRC2-00792
Lid Type	Standard
Cooler	RCS 90
Leave Cooler on at End of Sequence	On
Gas 2	Nitrogen
Gas Selected	Channel 1
Flow Rate	50 mL/min
Secondary Purge	On
Licensed Heat Flow	Heat Flow T4P
Modulation Licensed	Yes
[Versions]
Common IDD Version	1
Cortex Version	VER 2.10.2.31
Driver	5.0.0.6
GDM Version	1.0.3.3
TouchscreenVersion	1.0.0.16145
FEP Version	1.2.1.21
FEP Bootloader	2.0.0.5
AutoSampler Version	2.1.1.26
Auto Sampler Bootloader	2.0.0.5
FCM Version	1.1.0.3
FCM Bootloader	2.0.0.5
[Experiment Logs]
Experiment Log Entry # 1	Data On set to 0
Experiment Log Entry # 3	Equilibrate Segment 30 (C) Started
Experiment Log Entry # 5	Air Cool is off.
Experiment Log Entry # 7	Data On set to 1
Experiment Log Entry # 9	Ramp Segment 5 C/min to 150 Started
[Method Log]
Method Log Entry # 1	Data Off
Method Log Entry # 2	Equilibrate 30 °C
Method Log Entry # 3	Data On
Method Log Entry # 4	(Ramp 50101) Ramp 5 °C/minute to 150 °C
Cell Serial	DRC2-00792
[T1 Calibration]
Slope	-0.008529666
Offset	9.636258
Initial Temperature	98.23
GUID	f8bfdadc-4977-4fdf-ba6d-0ba9134940c3
[TZero Calibration]
Date Applied	11/29/2022 4:06:13 PM
Description	From -89.059 °C to 396.009 °C at 20.000°C/min
Gas Type	Nitrogen
Pan Type	None
Source Files 1	C:\Users\yargerlab\Desktop\DSC Data\General\TZero_calibration_11_29_22_2nd(2).tri
Source Files 2	C:\Users\yargerlab\Desktop\DSC Data\General\TZero_calibration_11_29_22_2nd(3).tri
Delta T Offset	13.05235
Delta T Slope	-0.007271007
Delta T0 Offset	-13.69128
Delta T0 Slope	0.06063341
[Temperature Calibration]
Date Applied	11/29/2022 7:12:28 PM
Description	From 106.590 °C to 186.590 °C at 10.000°C/min
Gas Type	Nitrogen
Pan Type	Tzero Aluminum Hermetic
Source Files 1	C:\Users\yargerlab\Desktop\DSC Data\General\Indium(6).tri
Measured 1	157.391
Known 1	156.598
[Cell Constant Calibration]
Date Applied	11/29/2022 7:12:29 PM
Description	From 106.590 °C to 186.590 °C at 10.000°C/min
Gas Type	Nitrogen
Pan Type	Tzero Aluminum Hermetic
Source Files 1	C:\Users\yargerlab\Desktop\DSC Data\General\Indium(6).tri
T4P KCell	1.006051
Onset Slope	63.26126 mW/°C
[Direct Cp Calibration]
Date Applied	11/30/2022 11:04:51 AM
Description	From -79.983 °C to 298.409 °C at 10.000°C/min
Gas Type	Nitrogen
Pan Type	Tzero Aluminum Hermetic
Source Files 1	C:\Users\yargerlab\Desktop\DSC Data\General\Sapphire_Heat_Capacity_11_30_22.tri
[Rev Cp Calibration]
Date Applied	11/30/2022 1:58:51 PM
Description	From -79.996 °C to 292.812 °C at 3.000°C/min
Gas Type	Nitrogen
Pan Type	Tzero Aluminum Hermetic
Source Files 1	C:\Users\yargerlab\Desktop\DSC Data\General\Sapphire_MDSC_Calibration_11_30_22.tri
[step]
Ramp 5.00 °C/min to 150.00 °C
Time	Temperature	Heat Flow (Normalized)
min	°C	W/g
0.00	30.08	-0.052
0.02	30.07	-0.051
0.03	30.08	-0.049
0.05	30.08	-0.047
0.07	30.09	-0.044
0.08	30.10	-0.040
0.10	30.13	-0.033
0.12	30.16	-0.021
0.13	30.20	-0.006
0.15	30.25	0.009
0.17	30.31	0.023
0.18	30.37	0.035
0.20	30.43	0.049
0.22	30.50	0.057
0.23	30.57	0.066
0.25	30.64	0.072
0.27	30.71	0.078
0.28	30.79	0.083
0.30	30.86	0.087
0.32	30.94	0.092
0.33	31.02	0.095
0.35	31.10	0.097
0.37	31.18	0.100
0.38	31.26	0.102
0.40	31.34	0.103
0.42	31.42	0.104
0.43	31.50	0.106
0.45	31.58	0.107
0.47	31.66	0.107
0.48	31.74	0.108
0.50	31.83	0.108
0.52	31.91	0.109
0.53	31.99	0.109
0.55	32.07	0.110
0.57	32.15	0.110
0.58	32.24	0.111
0.60	32.32	0.111
0.62	32.40	0.111
0.63	32.48	0.112
0.65	32.57	0.112
0.67	32.65	0.112
0.68	32.73	0.113
0.70	32.81	0.113
0.72	32.90	0.113
0.73	32.98	0.114
0.75	33.06	0.114
0.77	33.14	0.114
0.78	33.23	0.115
0.80	33.31	0.115
0.82	33.39	0.115
0.83	33.48	0.115
0.85	33.56	0.115
0.87	33.64	0.115
0.88	33.72	0.116
0.90	33.81	0.116
0.92	33.89	0.116
0.93	33.97	0.116
0.95	34.06	0.116
0.97	34.14	0.116
0.98	34.22	0.116
1.00	34.30	0.116
1.02	34.39	0.116
1.03	34.47	0.116
1.05	34.55	0.117
1.07	34.64	0.117
1.08	34.72	0.117
1.10	34.80	0.117
1.12	34.89	0.117
1.13	34.97	0.117
1.15	35.05	0.117
1.17	35.14	0.117
1.18	35.22	0.117
1.20	35.30	0.117
1.22	35.39	0.117
1.23	35.47	0.117
1.25	35.55	0.117
1.27	35.64	0.117
1.28	35.72	0.117
1.30	35.80	0.117
1.32	35.88	0.117
1.33	35.97	0.117
1.35	36.05	0.117
1.37	36.13	0.117
1.38	36.22	0.117
1.40	36.30	0.117
1.42	36.38	0.117
1.43	36.47	0.117
1.45	36.55	0.117
1.47	36.63	0.117
1.48	36.72	0.117
1.50	36.80	0.117
1.52	36.88	0.117
1.53	36.97	0.117
1.55	37.05	0.117
1.57	37.13	0.117
1.58	37.22	0.117
1.60	37.30	0.117
1.62	37.38	0.117
1.63	37.47	0.117
1.65	37.55	0.117
1.67	37.63	0.116
1.68	37.72	0.116
1.70	37.80	0.116
1.72	37.88	0.116
1.73	37.97	0.116
1.75	38.05	0.116
1.77	38.13	0.116
1.78	38.22	0.116
1.80	38.30	0.116
1.82	38.38	0.116
1.83	38.46	0.116
1.85	38.55	0.116
1.87	38.63	0.116
1.88	38.72	0.116
1.90	38.80	0.116
1.92	38.88	0.116
1.93	38.97	0.116
1.95	39.05	0.116
1.97	39.13	0.116
1.98	39.22	0.116
2.00	39.30	0.116
2.02	39.38	0.116
2.03	39.46	0.116
2.05	39.55	0.116
2.07	39.63	0.116
2.08	39.71	0.116
2.10	39.80	0.116
2.12	39.88	0.116
2.13	39.96	0.116
2.15	40.05	0.116
2.17	40.13	0.116
2.18	40.22	0.116
2.20	40.30	0.116
2.22	40.38	0.116
2.23	40.46	0.116
2.25	40.55	0.116
2.27	40.63	0.116
2.28	40.71	0.116
2.30	40.80	0.116
2.32	40.88	0.116
2.33	40.97	0.116
2.35	41.05	0.116
2.37	41.13	0.116
2.38	41.22	0.116
2.40	41.30	0.116
2.42	41.38	0.116
2.43	41.47	0.116
2.45	41.55	0.116
2.47	41.63	0.116
2.48	41.72	0.116
2.50	41.80	0.116
2.52	41.88	0.116
2.53	41.97	0.116
2.55	42.05	0.116
2.57	42.13	0.116
2.58	42.22	0.116
2.60	42.30	0.116
2.62	42.38	0.116
2.63	42.47	0.116
2.65	42.55	0.116
2.67	42.63	0.116
2.68	42.72	0.116
2.70	42.80	0.116
2.72	42.88	0.115
2.73	42.96	0.115
2.75	43.05	0.116
2.77	43.13	0.115
2.78	43.22	0.116
2.80	43.30	0.116
2.82	43.38	0.115
2.83	43.47	0.115
2.85	43.55	0.115
2.87	43.63	0.115
2.88	43.72	0.115
2.90	43.80	0.115
2.92	43.88	0.115
2.93	43.97	0.115
2.95	44.05	0.115
2.97	44.13	0.115
2.98	44.22	0.115
3.00	44.30	0.115
3.02	44.38	0.115
3.03	44.47	0.115
3.05	44.55	0.115
3.07	44.63	0.115
3.08	44.72	0.115
3.10	44.80	0.115
3.12	44.89	0.115
3.13	44.97	0.115
3.15	45.05	0.115
3.17	45.14	0.115
3.18	45.22	0.115
3.20	45.30	0.115
3.22	45.38	0.115
3.23	45.47	0.115
3.25	45.55	0.115
3.27	45.63	0.115
3.28	45.72	0.115
3.30	45.80	0.115
3.32	45.88	0.115
3.33	45.97	0.115
3.35	46.05	0.116
3.37	46.14	0.116
3.38	46.22	0.116
3.40	46.30	0.116
3.42	46.38	0.115
3.43	46.47	0.116
3.45	46.55	0.116
3.47	46.64	0.116
3.48	46.72	0.116
3.50	46.80	0.116
3.52	46.89	0.116
3.53	46.97	0.116
3.55	47.05	0.116
3.57	47.13	0.116
3.58	47.22	0.116
3.60	47.30	0.116
3.62	47.38	0.116
3.63	47.47	0.116
3.65	47.55	0.116
3.67	47.63	0.116
3.68	47.72	0.116
3.70	47.80	0.116
3.72	47.88	0.116
3.73	47.97	0.116
3.75	48.05	0.116
3.77	48.14	0.116
3.78	48.22	0.116
3.80	48.30	0.116
3.82	48.39	0.116
3.83	48.47	0.116
3.85	48.55	0.116
3.87	48.64	0.116
3.88	48.72	0.116
3.90	48.80	0.116
3.92	48.89	0.116
3.93	48.97	0.116
3.95	49.05	0.116
3.97	49.14	0.116
3.98	49.22	0.116
4.00	49.30	0.116
4.02	49.39	0.116
4.03	49.47	0.116
4.05	49.55	0.116
4.07	49.64	0.116
4.08	49.72	0.116
4.10	49.80	0.116
4.12	49.89	0.116
4.13	49.97	0.116
4.15	50.05	0.116
4.17	50.14	0.116
4.18	50.22	0.116
4.20	50.30	0.116
4.22	50.39	0.116
4.23	50.47	0.116
4.25	50.55	0.116
4.27	50.64	0.116
4.28	50.72	0.116
4.30	50.80	0.116
4.32	50.89	0.116
4.33	50.97	0.116
4.35	51.05	0.116
4.37	51.14	0.116
4.38	51.22	0.116
4.40	51.30	0.116
4.42	51.39	0.116
4.43	51.47	0.117
4.45	51.55	0.116
4.47	51.64	0.116
4.48	51.72	0.117
4.50	51.80	0.117
4.52	51.89	0.117
4.53	51.97	0.117
4.55	52.05	0.117
4.57	52.14	0.117
4.58	52.22	0.117
4.60	52.30	0.117
4.62	52.39	0.117
4.63	52.47	0.117
4.65	52.55	0.117
4.67	52.64	0.117
4.68	52.72	0.117
4.70	52.80	0.117
4.72	52.89	0.117
4.73	52.97	0.117
4.75	53.05	0.117
4.77	53.14	0.117
4.78	53.22	0.117
4.80	53.30	0.117
4.82	53.39	0.117
4.83	53.47	0.117
4.85	53.55	0.117
4.87	53.64	0.117
4.88	53.72	0.117
4.90	53.81	0.117
4.92	53.89	0.117
4.93	53.97	0.117
4.95	54.05	0.117
4.97	54.14	0.117
4.98	54.22	0.117
5.00	54.30	0.117
5.02	54.39	0.117
5.03	54.47	0.117
5.05	54.55	0.117
5.07	54.64	0.117
5.08	54.72	0.117
5.10	54.81	0.117
5.12	54.89	0.117
5.13	54.97	0.117
5.15	55.06	0.117
5.17	55.14	0.117
5.18	55.22	0.117
5.20	55.31	0.118
5.22	55.39	0.118
5.23	55.47	0.117
5.25	55.56	0.117
5.27	55.64	0.118
5.28	55.72	0.118
5.30	55.81	0.118
5.32	55.89	0.118
5.33	55.97	0.118
5.35	56.06	0.118
5.37	56.14	0.118
5.38	56.22	0.118
5.40	56.31	0.118
5.42	56.39	0.118
5.43	56.47	0.118
5.45	56.56	0.118
5.47	56.64	0.118
5.48	56.72	0.118
5.50	56.81	0.118
5.52	56.89	0.118
5.53	56.97	0.118
5.55	57.06	0.118
5.57	57.14	0.118
5.58	57.22	0.118
5.60	57.31	0.118
5.62	57.39	0.118
5.63	57.47	0.118
5.65	57.56	0.118
5.67	57.64	0.118
5.68	57.72	0.118
5.70	57.81	0.118
5.72	57.89	0.118
5.73	57.97	0.118
5.75	58.06	0.118
5.77	58.14	0.118
5.78	58.22	0.118
5.80	58.31	0.118
5.82	58.39	0.118
5.83	58.47	0.118
5.85	58.56	0.118
5.87	58.64	0.119
5.88	58.72	0.119
5.90	58.81	0.119
5.92	58.89	0.119
5.93	58.97	0.119
5.95	59.06	0.119
5.97	59.14	0.119
5.98	59.23	0.119
6.00	59.31	0.119
6.02	59.39	0.119
6.03	59.47	0.119
6.05	59.56	0.119
6.07	59.64	0.119
6.08	59.72	0.119
6.10	59.81	0.119
6.12	59.89	0.119
6.13	59.97	0.119
6.15	60.06	0.119
6.17	60.14	0.119
6.18	60.22	0.119
6.20	60.31	0.119
6.22	60.39	0.119
6.23	60.47	0.119
6.25	60.56	0.119
6.27	60.64	0.119
6.28	60.73	0.119
6.30	60.81	0.119
6.32	60.89	0.119
6.33	60.97	0.119
6.35	61.06	0.119
6.37	61.14	0.119
6.38	61.23	0.119
6.40	61.31	0.119
6.42	61.39	0.119
6.43	61.48	0.119
6.45	61.56	0.119
6.47	61.64	0.119
6.48	61.73	0.119
6.50	61.81	0.119
6.52	61.89	0.119
6.53	61.98	0.119
6.55	62.06	0.119
6.57	62.14	0.120
6.58	62.23	0.119
6.60	62.31	0.120
6.62	62.39	0.120
6.63	62.47	0.120
6.65	62.56	0.120
6.67	62.64	0.120
6.68	62.73	0.120
6.70	62.81	0.120
6.72	62.89	0.120
6.73	62.98	0.120
6.75	63.06	0.120
6.77	63.14	0.120
6.78	63.23	0.120
6.80	63.31	0.120
6.82	63.39	0.120
6.83	63.48	0.120
6.85	63.56	0.120
6.87	63.64	0.120
6.88	63.73	0.120
6.90	63.81	0.120
6.92	63.89	0.120
6.93	63.98	0.120
6.95	64.06	0.120
6.97	64.14	0.120
6.98	64.23	0.120
7.00	64.31	0.120
7.02	64.39	0.120
7.03	64.48	0.120
7.05	64.56	0.120
7.07	64.64	0.120
7.08	64.73	0.120
7.10	64.81	0.120
7.12	64.89	0.120
7.13	64.98	0.120
7.15	65.06	0.120
7.17	65.14	0.120
7.18	65.23	0.120
7.20	65.31	0.120
7.22	65.39	0.120
7.23	65.48	0.120
7.25	65.56	0.120
7.27	65.64	0.120
7.28	65.73	0.120
7.30	65.81	0.121
7.32	65.89	0.121
7.33	65.98	0.121
7.35	66.06	0.121
7.37	66.14	0.121
7.38	66.23	0.121
7.40	66.31	0.121
7.42	66.39	0.121
7.43	66.48	0.121
7.45	66.56	0.121
7.47	66.64	0.121
7.48	66.73	0.121
7.50	66.81	0.121
7.52	66.89	0.121
7.53	66.98	0.121
7.55	67.06	0.121
7.57	67.14	0.121
7.58	67.23	0.121
7.60	67.31	0.121
7.62	67.39	0.121
7.63	67.48	0.121
7.65	67.56	0.121
7.67	67.64	0.121
7.68	67.73	0.121
7.70	67.81	0.121
7.72	67.90	0.121
7.73	67.98	0.121
7.75	68.06	0.121
7.77	68.15	0.121
7.78	68.23	0.121
7.80	68.31	0.121
7.82	68.39	0.122
7.83	68.48	0.122
7.85	68.56	0.122
7.87	68.64	0.122
7.88	68.73	0.122
7.90	68.81	0.122
7.92	68.90	0.122
7.93	68.98	0.122
7.95	69.06	0.122
7.97	69.15	0.122
7.98	69.23	0.122
8.00	69.31	0.122
8.02	69.39	0.122
8.03	69.48	0.122
8.05	69.56	0.122
8.07	69.64	0.122
8.08	69.73	0.122
8.10	69.81	0.122
8.12	69.90	0.122
8.13	69.98	0.122
8.15	70.06	0.122
8.17	70.15	0.122
8.18	70.23	0.122
8.20	70.31	0.122
8.22	70.40	0.122
8.23	70.48	0.122
8.25	70.56	0.122
8.27	70.65	0.122
8.28	70.73	0.122
8.30	70.81	0.122
8.32	70.90	0.122
8.33	70.98	0.122
8.35	71.06	0.122
8.37	71.15	0.122
8.38	71.23	0.122
8.40	71.31	0.122
8.42	71.40	0.122
8.43	71.48	0.123
8.45	71.56	0.123
8.47	71.65	0.123
8.48	71.73	0.123
8.50	71.81	0.123
8.52	71.90	0.123
8.53	71.98	0.123
8.55	72.06	0.123
8.57	72.15	0.123
8.58	72.23	0.123
8.60	72.31	0.123
8.62	72.40	0.123
8.63	72.48	0.123
8.65	72.56	0.123
8.67	72.65	0.123
8.68	72.73	0.123
8.70	72.81	0.123
8.72	72.90	0.123
8.73	72.98	0.123
8.75	73.06	0.123
8.77	73.15	0.123
8.78	73.23	0.123
8.80	73.31	0.123
8.82	73.40	0.123
8.83	73.48	0.123
8.85	73.56	0.123
8.87	73.65	0.123
8.88	73.73	0.123
8.90	73.82	0.123
8.92	73.90	0.124
8.93	73.98	0.124
8.95	74.06	0.124
8.97	74.15	0.124
8.98	74.23	0.124
9.00	74.31	0.124
9.02	74.40	0.124
9.03	74.48	0.124
9.05	74.56	0.124
9.07	74.65	0.124
9.08	74.73	0.124
9.10	74.81	0.124
9.12	74.90	0.124
9.13	74.98	0.124
9.15	75.06	0.124
9.17	75.15	0.124
9.18	75.23	0.124
9.20	75.31	0.124
9.22	75.40	0.124
9.23	75.48	0.124
9.25	75.56	0.124
9.27	75.65	0.124
9.28	75.73	0.124
9.30	75.81	0.124
9.32	75.90	0.124
9.33	75.98	0.124
9.35	76.06	0.124
9.37	76.15	0.124
9.38	76.23	0.124
9.40	76.31	0.124
9.42	76.40	0.124
9.43	76.48	0.124
9.45	76.56	0.124
9.47	76.65	0.124
9.48	76.73	0.124
9.50	76.81	0.124
9.52	76.90	0.124
9.53	76.98	0.125
9.55	77.07	0.125
9.57	77.15	0.125
9.58	77.23	0.125
9.60	77.32	0.125
9.62	77.40	0.125
9.63	77.48	0.125
9.65	77.57	0.125
9.67	77.65	0.125
9.68	77.73	0.125
9.70	77.82	0.125
9.72	77.90	0.125
9.73	77.98	0.125
9.75	78.07	0.125
9.77	78.15	0.125
9.78	78.23	0.125
9.80	78.32	0.125
9.82	78.40	0.125
9.83	78.48	0.125
9.85	78.57	0.125
9.87	78.65	0.125
9.88	78.73	0.125
9.90	78.82	0.125
9.92	78.90	0.125
9.93	78.98	0.125
9.95	79.07	0.125
9.97	79.15	0.126
9.98	79.23	0.126
10.00	79.32	0.126
10.02	79.40	0.126
10.03	79.48	0.126
10.05	79.57	0.126
10.07	79.65	0.126
10.08	79.73	0.126
10.10	79.82	0.126
10.12	79.90	0.126
10.13	79.98	0.126
10.15	80.07	0.126
10.17	80.15	0.126
10.18	80.23	0.126
10.20	80.32	0.126
10.22	80.40	0.126
10.23	80.48	0.126
10.25	80.57	0.126
10.27	80.65	0.126
10.28	80.73	0.126
10.30	80.82	0.126
10.32	80.90	0.126
10.33	80.98	0.126
10.35	81.07	0.126
10.37	81.15	0.126
10.38	81.23	0.126
10.40	81.32	0.126
10.42	81.40	0.126
10.43	81.48	0.126
10.45	81.57	0.126
10.47	81.65	0.126
10.48	81.73	0.126
10.50	81.82	0.126
10.52	81.90	0.126
10.53	81.98	0.126
10.55	82.07	0.126
10.57	82.15	0.127
10.58	82.23	0.126
10.60	82.32	0.126
10.62	82.40	0.127
10.63	82.48	0.127
10.65	82.57	0.127
10.67	82.65	0.127
10.68	82.73	0.127
10.70	82.82	0.127
10.72	82.90	0.127
10.73	82.98	0.127
10.75	83.07	0.127
10.77	83.15	0.127
10.78	83.24	0.127
10.80	83.32	0.127
10.82	83.40	0.127
10.83	83.49	0.127
10.85	83.57	0.127
10.87	83.65	0.127
10.88	83.74	0.127
10.90	83.82	0.127
10.92	83.90	0.127
10.93	83.99	0.127
10.95	84.07	0.127
10.97	84.15	0.127
10.98	84.24	0.127
11.00	84.32	0.127
11.02	84.40	0.127
11.03	84.49	0.127
11.05	84.57	0.127
11.07	84.65	0.127
11.08	84.74	0.127
11.10	84.82	0.127
11.12	84.90	0.127
11.13	84.99	0.127
11.15	85.07	0.127
11.17	85.15	0.127
11.18	85.24	0.127
11.20	85.32	0.127
11.22	85.40	0.127
11.23	85.49	0.127
11.25	85.57	0.127
11.27	85.65	0.127
11.28	85.74	0.127
11.30	85.82	0.127
11.32	85.90	0.127
11.33	85.99	0.127
11.35	86.07	0.128
11.37	86.15	0.128
11.38	86.24	0.128
11.40	86.32	0.128
11.42	86.40	0.128
11.43	86.49	0.128
11.45	86.57	0.128
11.47	86.65	0.128
11.48	86.74	0.128
11.50	86.82	0.128
11.52	86.90	0.128
11.53	86.99	0.128
11.55	87.07	0.128
11.57	87.15	0.128
11.58	87.24	0.128
11.60	87.32	0.128
11.62	87.40	0.128
11.63	87.49	0.128
11.65	87.57	0.128
11.67	87.65	0.128
11.68	87.74	0.128
11.70	87.82	0.128
11.72	87.90	0.128
11.73	87.99	0.128
11.75	88.07	0.128
11.77	88.15	0.128
11.78	88.24	0.128
11.80	88.32	0.128
11.82	88.40	0.128
11.83	88.49	0.129
11.85	88.57	0.129
11.87	88.65	0.129
11.88	88.74	0.129
11.90	88.82	0.129
11.92	88.90	0.129
11.93	88.99	0.129
11.95	89.07	0.129
11.97	89.15	0.129
11.98	89.24	0.129
12.00	89.32	0.129
12.02	89.40	0.129
12.03	89.49	0.129
12.05	89.57	0.129
12.07	89.65	0.129
12.08	89.74	0.129
12.10	89.82	0.129
12.12	89.91	0.129
12.13	89.99	0.129
12.15	90.07	0.129
12.17	90.15	0.129
12.18	90.24	0.129
12.20	90.32	0.129
12.22	90.40	0.129
12.23	90.49	0.129
12.25	90.57	0.129
12.27	90.65	0.129
12.28	90.74	0.129
12.30	90.82	0.129
12.32	90.90	0.129
12.33	90.99	0.129
12.35	91.07	0.130
12.37	91.16	0.130
12.38	91.24	0.130
12.40	91.32	0.130
12.42	91.41	0.130
12.43	91.49	0.130
12.45	91.57	0.130
12.47	91.66	0.130
12.48	91.74	0.130
12.50	91.82	0.130
12.52	91.91	0.130
12.53	91.99	0.130
12.55	92.07	0.130
12.57	92.16	0.130
12.58	92.24	0.130
12.60	92.32	0.130
12.62	92.40	0.130
12.63	92.49	0.130
12.65	92.57	0.130
12.67	92.65	0.130
12.68	92.74	0.131
12.70	92.82	0.131
12.72	92.90	0.131
12.73	92.99	0.131
12.75	93.07	0.131
12.77	93.16	0.131
12.78	93.24	0.131
12.80	93.32	0.131
12.82	93.41	0.131
12.83	93.49	0.131
12.85	93.57	0.131
12.87	93.66	0.131
12.88	93.74	0.131
12.90	93.82	0.131
12.92	93.91	0.131
12.93	93.99	0.131
12.95	94.07	0.131
12.97	94.16	0.131
12.98	94.24	0.131
13.00	94.32	0.131
13.02	94.41	0.131
13.03	94.49	0.131
13.05	94.57	0.132
13.07	94.66	0.132
13.08	94.74	0.132
13.10	94.82	0.132
13.12	94.91	0.132
13.13	94.99	0.132
13.15	95.07	0.132
13.17	95.16	0.132
13.18	95.24	0.132
13.20	95.32	0.132
13.22	95.41	0.132
13.23	95.49	0.132
13.25	95.57	0.132
13.27	95.65	0.132
13.28	95.74	0.132
13.30	95.82	0.132
13.32	95.91	0.132
13.33	95.99	0.132
13.35	96.07	0.132
13.37	96.16	0.132
13.38	96.24	0.132
13.40	96.32	0.132
13.42	96.41	0.132
13.43	96.49	0.133
13.45	96.57	0.132
13.47	96.66	0.133
13.48	96.74	0.133
13.50	96.82	0.133
13.52	96.91	0.133
13.53	96.99	0.133
13.55	97.07	0.133
13.57	97.16	0.133
13.58	97.24	0.133
13.60	97.32	0.133
13.62	97.41	0.133
13.63	97.49	0.133
13.65	97.57	0.133
13.67	97.66	0.133
13.68	97.74	0.133
13.70	97.82	0.133
13.72	97.91	0.133
13.73	97.99	0.133
13.75	98.07	0.133
13.77	98.16	0.133
13.78	98.24	0.133
13.80	98.32	0.133
13.82	98.41	0.133
13.83	98.49	0.133
13.85	98.58	0.133
13.87	98.66	0.133
13.88	98.74	0.133
13.90	98.83	0.133
13.92	98.91	0.133
13.93	98.99	0.133
13.95	99.07	0.134
13.97	99.16	0.133
13.98	99.24	0.134
14.00	99.33	0.134
14.02	99.41	0.134
14.03	99.49	0.134
14.05	99.58	0.134
14.07	99.66	0.134
14.08	99.74	0.134
14.10	99.82	0.134
14.12	99.91	0.134
14.13	99.99	0.134
14.15	100.07	0.134
14.17	100.16	0.134
14.18	100.24	0.134
14.20	100.32	0.134
14.22	100.41	0.134
14.23	100.49	0.134
14.25	100.57	0.134
14.27	100.66	0.134
14.28	100.74	0.134
14.30	100.83	0.134
14.32	100.91	0.134
14.33	100.99	0.134
14.35	101.07	0.134
14.37	101.16	0.134
14.38	101.24	0.134
14.40	101.32	0.135
14.42	101.41	0.135
14.43	101.49	0.135
14.45	101.57	0.135
14.47	101.66	0.135
14.48	101.74	0.135
14.50	101.83	0.135
14.52	101.91	0.135
14.53	101.99	0.135
14.55	102.08	0.135
14.57	102.16	0.135
14.58	102.24	0.135
14.60	102.33	0.135
14.62	102.41	0.135
14.63	102.49	0.135
14.65	102.58	0.135
14.67	102.66	0.135
14.68	102.74	0.135
14.70	102.83	0.135
14.72	102.91	0.135
14.73	102.99	0.136
14.75	103.08	0.136
14.77	103.16	0.136
14.78	103.24	0.136
14.80	103.33	0.136
14.82	103.41	0.136
14.83	103.49	0.136
14.85	103.58	0.136
14.87	103.66	0.136
14.88	103.74	0.136
14.90	103.83	0.136
14.92	103.91	0.136
14.93	103.99	0.136
14.95	104.08	0.136
14.97	104.16	0.136
14.98	104.24	0.136
15.00	104.33	0.136
15.02	104.41	0.136
15.03	104.49	0.136
15.05	104.58	0.136
15.07	104.66	0.137
15.08	104.74	0.137
15.10	104.83	0.137
15.12	104.91	0.137
15.13	104.99	0.137
15.15	105.08	0.137
15.17	105.16	0.137
15.18	105.24	0.137
15.20	105.33	0.137
15.22	105.41	0.137
15.23	105.49	0.137
15.25	105.58	0.137
15.27	105.66	0.137
15.28	105.75	0.137
15.30	105.83	0.137
15.32	105.91	0.138
15.33	105.99	0.138
15.35	106.08	0.138
15.37	106.16	0.138
15.38	106.25	0.138
15.40	106.33	0.138
15.42	106.41	0.138
15.43	106.49	0.138
15.45	106.58	0.138
15.47	106.66	0.138
15.48	106.74	0.138
15.50	106.83	0.138
15.52	106.91	0.138
15.53	107.00	0.138
15.55	107.08	0.138
15.57	107.16	0.138
15.58	107.24	0.138
15.60	107.33	0.138
15.62	107.41	0.138
15.63	107.49	0.138
15.65	107.58	0.139
15.67	107.66	0.139
15.68	107.74	0.139
15.70	107.83	0.139
15.72	107.91	0.139
15.73	107.99	0.139
15.75	108.08	0.139
15.77	108.16	0.139
15.78	108.24	0.139
15.80	108.33	0.139
15.82	108.41	0.139
15.83	108.49	0.139
15.85	108.58	0.139
15.87	108.66	0.139
15.88	108.74	0.139
15.90	108.83	0.139
15.92	108.91	0.139
15.93	108.99	0.139
15.95	109.08	0.139
15.97	109.16	0.139
15.98	109.24	0.140
16.00	109.33	0.140
16.02	109.41	0.140
16.03	109.49	0.140
16.05	109.58	0.140
16.07	109.66	0.140
16.08	109.75	0.140
16.10	109.83	0.140
16.12	109.91	0.140
16.13	109.99	0.140
16.15	110.08	0.140
16.17	110.16	0.140
16.18	110.24	0.140
16.20	110.33	0.140
16.22	110.41	0.140
16.23	110.49	0.141
16.25	110.58	0.141
16.27	110.66	0.141
16.28	110.75	0.141
16.30	110.83	0.141
16.32	110.91	0.141
16.33	110.99	0.141
16.35	111.08	0.141
16.37	111.16	0.141
16.38	111.25	0.141
16.40	111.33	0.141
16.42	111.41	0.141
16.43	111.50	0.141
16.45	111.58	0.141
16.47	111.66	0.141
16.48	111.74	0.142
16.50	111.83	0.142
16.52	111.91	0.142
16.53	111.99	0.142
16.55	112.08	0.142
16.57	112.16	0.142
16.58	112.24	0.142
16.60	112.33	0.142
16.62	112.41	0.142
16.63	112.50	0.142
16.65	112.58	0.142
16.67	112.66	0.142
16.68	112.74	0.142
16.70	112.83	0.142
16.72	112.91	0.142
16.73	113.00	0.142
16.75	113.08	0.143
16.77	113.16	0.143
16.78	113.25	0.143
16.80	113.33	0.143
16.82	113.41	0.143
16.83	113.50	0.143
16.85	113.58	0.143
16.87	113.66	0.143
16.88	113.75	0.143
16.90	113.83	0.143
16.92	113.91	0.143
16.93	113.99	0.143
16.95	114.08	0.143
16.97	114.16	0.143
16.98	114.25	0.144
17.00	114.33	0.144
17.02	114.41	0.144
17.03	114.50	0.144
17.05	114.58	0.144
17.07	114.66	0.144
17.08	114.75	0.144
17.10	114.83	0.144
17.12	114.91	0.144
17.13	115.00	0.144
17.15	115.08	0.145
17.17	115.16	0.145
17.18	115.25	0.145
17.20	115.33	0.145
17.22	115.41	0.145
17.23	115.50	0.145
17.25	115.58	0.145
17.27	115.66	0.145
17.28	115.75	0.145
17.30	115.83	0.146
17.32	115.91	0.146
17.33	116.00	0.146
17.35	116.08	0.146
17.37	116.16	0.146
17.38	116.25	0.146
17.40	116.33	0.146
17.42	116.41	0.146
17.43	116.50	0.146
17.45	116.58	0.147
17.47	116.66	0.147
17.48	116.75	0.147
17.50	116.83	0.147
17.52	116.91	0.147
17.53	117.00	0.148
17.55	117.08	0.148
17.57	117.16	0.148
17.58	117.25	0.148
17.60	117.33	0.148
17.62	117.41	0.149
17.63	117.50	0.149
17.65	117.58	0.149
17.67	117.66	0.149
17.68	117.74	0.150
17.70	117.83	0.150
17.72	117.91	0.150
17.73	117.99	0.150
17.75	118.08	0.151
17.77	118.16	0.151
17.78	118.25	0.151
17.80	118.33	0.152
17.82	118.41	0.152
17.83	118.50	0.152
17.85	118.58	0.153
17.87	118.66	0.153
17.88	118.74	0.153
17.90	118.83	0.154
17.92	118.91	0.154
17.93	119.00	0.155
17.95	119.08	0.155
17.97	119.16	0.156
17.98	119.24	0.156
18.00	119.33	0.157
18.02	119.41	0.158
18.03	119.49	0.159
18.05	119.58	0.160
18.07	119.66	0.161
18.08	119.74	0.163
18.10	119.83	0.164
18.12	119.91	0.166
18.13	119.99	0.168
18.15	120.08	0.172
18.17	120.16	0.176
18.18	120.24	0.181
18.20	120.32	0.187
18.22	120.41	0.192
18.23	120.49	0.201
18.25	120.57	0.207
18.27	120.65	0.217
18.28	120.74	0.229
18.30	120.82	0.239
18.32	120.90	0.254
18.33	120.98	0.274
18.35	121.06	0.296
18.37	121.14	0.323
18.38	121.22	0.356
18.40	121.30	0.402
18.42	121.38	0.460
18.43	121.45	0.531
18.45	121.52	0.625
18.47	121.59	0.746
18.48	121.66	0.887
18.50	121.72	1.053
18.52	121.78	1.231
18.53	121.84	1.408
18.55	121.89	1.589
18.57	121.94	1.836
18.58	121.99	2.116
18.60	122.03	2.420
18.62	122.07	2.701
18.63	122.10	2.997
18.65	122.14	3.292
18.67	122.17	3.579
18.68	122.20	3.836
18.70	122.24	4.076
18.72	122.27	4.326
18.73	122.31	4.546
18.75	122.35	4.715
18.77	122.39	4.846
18.78	122.44	5.004
18.80	122.49	5.119
18.82	122.55	5.156
18.83	122.62	5.172
18.85	122.68	5.248
18.87	122.75	5.303
18.88	122.82	5.323
18.90	122.90	5.282
18.92	122.98	5.211
18.93	123.07	5.141
18.95	123.15	5.090
18.97	123.24	5.064
18.98	123.33	5.091
19.00	123.42	4.959
19.02	123.52	4.646
19.03	123.64	4.232
19.05	123.76	3.966
19.07	123.91	2.955
19.08	124.11	1.917
19.10	124.30	1.518
19.12	124.48	1.273
19.13	124.63	1.084
19.15	124.78	0.934
19.17	124.91	0.801
19.18	125.04	0.694
19.20	125.16	0.606
19.22	125.27	0.533
19.23	125.38	0.473
19.25	125.48	0.423
19.27	125.58	0.382
19.28	125.68	0.350
19.30	125.77	0.319
19.32	125.86	0.299
19.33	125.96	0.280
19.35	126.05	0.264
19.37	126.13	0.251
19.38	126.22	0.240
19.40	126.31	0.232
19.42	126.39	0.224
19.43	126.48	0.218
19.45	126.57	0.216
19.47	126.65	0.211
19.48	126.74	0.210
19.50	126.82	0.206
19.52	126.90	0.205
19.53	126.99	0.203
19.55	127.07	0.202
19.57	127.16	0.201
19.58	127.24	0.200
19.60	127.33	0.200
19.62	127.41	0.199
19.63	127.49	0.199
19.65	127.58	0.198
19.67	127.66	0.197
19.68	127.74	0.197
19.70	127.83	0.197
19.72	127.91	0.196
19.73	127.99	0.196
19.75	128.08	0.196
19.77	128.16	0.195
19.78	128.24	0.195
19.80	128.33	0.195
19.82	128.41	0.195
19.83	128.49	0.194
19.85	128.58	0.194
19.87	128.66	0.194
19.88	128.74	0.194
19.90	128.83	0.194
19.92	128.91	0.194
19.93	128.99	0.194
19.95	129.08	0.193
19.97	129.16	0.193
19.98	129.24	0.193
20.00	129.33	0.193
20.02	129.41	0.193
20.03	129.49	0.193
20.05	129.58	0.193
20.07	129.66	0.193
20.08	129.74	0.193
20.10	129.83	0.193
20.12	129.91	0.193
20.13	129.99	0.193
20.15	130.08	0.193
20.17	130.16	0.193
20.18	130.24	0.193
20.20	130.33	0.193
20.22	130.41	0.193
20.23	130.49	0.193
20.25	130.58	0.193
20.27	130.66	0.193
20.28	130.74	0.193
20.30	130.83	0.193
20.32	130.91	0.193
20.33	130.99	0.193
20.35	131.08	0.193
20.37	131.16	0.193
20.38	131.24	0.193
20.40	131.33	0.193
20.42	131.41	0.194
20.43	131.49	0.194
20.45	131.58	0.194
20.47	131.66	0.194
20.48	131.74	0.194
20.50	131.83	0.194
20.52	131.91	0.194
20.53	131.99	0.194
20.55	132.08	0.194
20.57	132.16	0.194
20.58	132.24	0.194
20.60	132.33	0.194
20.62	132.41	0.194
20.63	132.49	0.194
20.65	132.58	0.194
20.67	132.66	0.194
20.68	132.74	0.194
20.70	132.83	0.195
20.72	132.91	0.195
20.73	132.99	0.195
20.75	133.08	0.195
20.77	133.16	0.195
20.78	133.24	0.195
20.80	133.33	0.195
20.82	133.41	0.195
20.83	133.49	0.195
20.85	133.58	0.195
20.87	133.66	0.195
20.88	133.74	0.195
20.90	133.83	0.195
20.92	133.91	0.195
20.93	133.99	0.196
20.95	134.08	0.196
20.97	134.16	0.196
20.98	134.24	0.196
21.00	134.33	0.196
21.02	134.41	0.196
21.03	134.49	0.196
21.05	134.58	0.196
21.07	134.66	0.196
21.08	134.74	0.196
21.10	134.83	0.196
21.12	134.91	0.196
21.13	134.99	0.196
21.15	135.08	0.196
21.17	135.16	0.197
21.18	135.25	0.197
21.20	135.33	0.197
21.22	135.41	0.197
21.23	135.49	0.197
21.25	135.58	0.197
21.27	135.66	0.197
21.28	135.74	0.197
21.30	135.83	0.197
21.32	135.91	0.197
21.33	135.99	0.197
21.35	136.08	0.197
21.37	136.16	0.197
21.38	136.24	0.197
21.40	136.33	0.197
21.42	136.41	0.197
21.43	136.49	0.197
21.45	136.58	0.198
21.47	136.66	0.198
21.48	136.74	0.198
21.50	136.83	0.198
21.52	136.91	0.198
21.53	136.99	0.198
21.55	137.08	0.198
21.57	137.16	0.198
21.58	137.24	0.198
21.60	137.33	0.198
21.62	137.41	0.198
21.63	137.49	0.198
21.65	137.58	0.198
21.67	137.66	0.198
21.68	137.74	0.198
21.70	137.83	0.199
21.72	137.91	0.199
21.73	137.99	0.199
21.75	138.08	0.199
21.77	138.16	0.199
21.78	138.24	0.199
21.80	138.33	0.199
21.82	138.41	0.199
21.83	138.49	0.199
21.85	138.58	0.199
21.87	138.66	0.199
21.88	138.74	0.199
21.90	138.83	0.199
21.92	138.91	0.199
21.93	139.00	0.199
21.95	139.08	0.199
21.97	139.16	0.199
21.98	139.24	0.199
22.00	139.33	0.200
22.02	139.41	0.200
22.03	139.49	0.200
22.05	139.58	0.200
22.07	139.66	0.200
22.08	139.75	0.200
22.10	139.83	0.200
22.12	139.91	0.200
22.13	140.00	0.200
22.15	140.08	0.200
22.17	140.16	0.200
22.18	140.24	0.200
22.20	140.33	0.201
22.22	140.41	0.200
22.23	140.49	0.201
22.25	140.58	0.201
22.27	140.66	0.201
22.28	140.74	0.201
22.30	140.83	0.201
22.32	140.91	0.201
22.33	141.00	0.201
22.35	141.08	0.201
22.37	141.16	0.201
22.38	141.25	0.201
22.40	141.33	0.201
22.42	141.41	0.201
22.43	141.49	0.201
22.45	141.58	0.201
22.47	141.66	0.201
22.48	141.75	0.201
22.50	141.83	0.201
22.52	141.91	0.202
22.53	142.00	0.202
22.55	142.08	0.202
22.57	142.16	0.202
22.58	142.25	0.202
22.60	142.33	0.202
22.62	142.41	0.202
22.63	142.49	0.202
22.65	142.58	0.202
22.67	142.66	0.202
22.68	142.75	0.202
22.70	142.83	0.202
22.72	142.91	0.203
22.73	143.00	0.203
22.75	143.08	0.203
22.77	143.16	0.203
22.78	143.25	0.203
22.80	143.33	0.203
22.82	143.41	0.203
22.83	143.50	0.203
22.85	143.58	0.203
22.87	143.66	0.203
22.88	143.75	0.203
22.90	143.83	0.203
22.92	143.91	0.203
22.93	144.00	0.204
22.95	144.08	0.204
22.97	144.16	0.204
22.98	144.25	0.204
23.00	144.33	0.204
23.02	144.41	0.204
23.03	144.50	0.204
23.05	144.58	0.204
23.07	144.66	0.204
23.08	144.75	0.204
23.10	144.83	0.204
23.12	144.91	0.204
23.13	145.00	0.204
23.15	145.08	0.204
23.17	145.16	0.204
23.18	145.25	0.204
23.20	145.33	0.204
23.22	145.41	0.204
23.23	145.50	0.204
23.25	145.58	0.204
23.27	145.66	0.204
23.28	145.75	0.204
23.30	145.83	0.204
23.32	145.91	0.205
23.33	146.00	0.205
23.35	146.08	0.205
23.37	146.16	0.205
23.38	146.25	0.205
23.40	146.33	0.205
23.42	146.41	0.205
23.43	146.50	0.205
23.45	146.58	0.205
23.47	146.66	0.205
23.48	146.75	0.205
23.50	146.83	0.205
23.52	146.91	0.205
23.53	147.00	0.205
23.55	147.08	0.205
23.57	147.16	0.205
23.58	147.25	0.205
23.60	147.33	0.205
23.62	147.41	0.205
23.63	147.50	0.205
23.65	147.58	0.206
23.67	147.66	0.206
23.68	147.75	0.206
23.70	147.83	0.206
23.72	147.91	0.206
23.73	148.00	0.206
23.75	148.08	0.206
23.77	148.16	0.206
23.78	148.25	0.206
23.80	148.33	0.206
23.82	148.41	0.206
23.83	148.50	0.206
23.85	148.58	0.206
23.87	148.66	0.207
23.88	148.75	0.207
23.90	148.83	0.207
23.92	148.91	0.207
23.93	149.00	0.207
23.95	149.08
23.97	149.16
23.98	149.24
24.00
24.00