File: DSC/2025_04_21_CBN_Proline_ACN_MC_n60C_150C_5Cmin_x3.csv
Filename,2025_04_21_CBN_Proline_ACN_MC_n60C_150C_5Cmin_x3
Instrument name,DSC2A-00468 (192.168.1.100)
Operator,Yarger
rundate,4/22/2025
Sample name,2025_04_21_CBN_Proline_ACN_MC_n60C_150C_5Cmin_x3
proceduresegments,Data Off ; Equilibrate -60.00 °C; Data On ; Ramp 5.00 °C/min to 150.00 °C; Data Off ; Isothermal 1.0 min; Data On ; Ramp 10.00 °C/min to -60.00 °C; Data Off ; Isothermal 1.0 min; Data On ; Ramp 5.00 °C/min to 150.00 °C; Data Off ; Isothermal 1.0 min; Data On ; Ramp 10.00 °C/min to -60.00 °C; Data Off ; Isothermal 1.0 min; Data On ; Ramp 5.00 °C/min to 150.00 °C
[File Parameters]
Run date,4/22/2025 10:55:21 AM
Trios version,5.1.1.46572
Original File Name,
Current File Name,D:\DSC2500\JYarger\2025_04_21_CBN_Proline_ACN_MC_n60C_150C_5Cmin_x3.tri
[Procedure]
Procedure Name,CBN_Pro_n60_150C_5Cmin_x3
Sample Name,2025_04_21_CBN_Proline_ACN_MC_n60C_150C_5Cmin_x3
Sample Mass,5.09 mg
Reference Sample Mass,0 mg
Pan Mass,52.9 mg
Pan Number,23
Reference Pan Mass,52.66 mg
Reference Pan Number,19
Pan Type,Tzero Aluminum Hermetic
Comments,Al Hermetic DSC Consumables sealed Pan/Lid.
Project Name,CA
Operator,Yarger
Test,Custom
Unload Max Temperature,30
Unload Min Temperature,30
Load Max Temperature,30
Load Min Temperature,30
Stop on Gas Flow Error,Yes
[Signal List]
Signal #1,Time (min)
Signal #2,Temperature (°C)
Signal #3,Heat Flow (mW)
Signal #4,Delta T (µV)
Signal #5,Delta Tzero (µV)
Signal #6,Tzero Temperature (°C)
Signal #7,Cell Purge (mL/min)
Signal #8,Heater Temp (°C)
Signal #9,Power Delivered (W)
Signal #10,Reference Junction Temperature (°C)
Signal #11,Flange Temperature (°C)
Signal #12,Heat Flow Phase (rad)
Signal #13,Total Heat Capacity (J/°C)
Signal #14,Heat Capacity (J/°C)
[Configuration]
Company Name,ASU
Instrument Name,DSC2A-00468
Instrument Type,DSC2500
Serial Number,DSC2A-00468
IP,192.168.1.100
Location of Instrument,MRRC
DisplayType,Unknown
Sample Interval ,0.1 s/pt
Selected Heat Flow,T4P
Exotherm Direction,Down
Cell Serial,DRC2-00792
Lid Type,Standard
Cooler,RCS 90
Leave Cooler on at End of Sequence,On
Gas 2,Nitrogen
Gas Selected,Channel 1
Flow Rate,50 mL/min
Secondary Purge,On
Licensed Heat Flow,Heat Flow T4P
Modulation Licensed,Yes
[Versions]
Common IDD Version,1
Cortex Version,VER 2.10.2.31
Driver,5.0.0.6
GDM Version,1.0.3.3
TouchscreenVersion,1.0.0.16145
FEP Version,1.2.1.21
FEP Bootloader,2.0.0.5
AutoSampler Version,2.1.1.26
Auto Sampler Bootloader,2.0.0.5
FCM Version,1.1.0.3
FCM Bootloader,2.0.0.5
[Experiment Logs]
Experiment Log Entry # 1,Data On set to 0
Experiment Log Entry # 3,Equilibrate Segment -60 (C) Started
Experiment Log Entry # 5,Air Cool is off.
Experiment Log Entry # 7,Data On set to 1
Experiment Log Entry # 9,Ramp Segment 5 C/min to 150 Started
Experiment Log Entry # 11,Data On set to 0
Experiment Log Entry # 13,Isothermal Segment 1 min started
Experiment Log Entry # 15,Data On set to 1
Experiment Log Entry # 17,Ramp Segment 10 C/min to -60 Started
Experiment Log Entry # 19,Data On set to 0
Experiment Log Entry # 21,Isothermal Segment 1 min started
Experiment Log Entry # 23,Data On set to 1
Experiment Log Entry # 25,Ramp Segment 5 C/min to 150 Started
Experiment Log Entry # 27,Data On set to 0
Experiment Log Entry # 29,Isothermal Segment 1 min started
Experiment Log Entry # 31,Data On set to 1
Experiment Log Entry # 33,Ramp Segment 10 C/min to -60 Started
Experiment Log Entry # 35,Data On set to 0
Experiment Log Entry # 37,Isothermal Segment 1 min started
Experiment Log Entry # 39,Data On set to 1
Experiment Log Entry # 41,Ramp Segment 5 C/min to 150 Started
[Method Log]
Method Log Entry # 1,Data Off
Method Log Entry # 2,Equilibrate -60 °C
Method Log Entry # 3,Data On
Method Log Entry # 4,(Ramp 1010392) Ramp 5 °C/minute to 150 °C
Method Log Entry # 5,Data Off
Method Log Entry # 6,Isothermal 1 minutes
Method Log Entry # 7,Data On
Method Log Entry # 8,(Ramp 1010396) Ramp 10 °C/minute to -60 °C
Method Log Entry # 9,Data Off
Method Log Entry # 10,Isothermal 1 minutes
Method Log Entry # 11,Data On
Method Log Entry # 12,(Ramp 1010400) Ramp 5 °C/minute to 150 °C
Method Log Entry # 13,Data Off
Method Log Entry # 14,Isothermal 1 minutes
Method Log Entry # 15,Data On
Method Log Entry # 16,(Ramp 1010404) Ramp 10 °C/minute to -60 °C
Method Log Entry # 17,Data Off
Method Log Entry # 18,Isothermal 1 minutes
Method Log Entry # 19,Data On
Method Log Entry # 20,(Ramp 1010408) Ramp 5 °C/minute to 150 °C
Cell Serial,DRC2-00792
[T1 Calibration]
Slope,-0.008529666
Offset,9.636258
Initial Temperature,98.23
GUID,f8bfdadc-4977-4fdf-ba6d-0ba9134940c3
[TZero Calibration]
Date Applied,11/29/2022 4:06:13 PM
Description,From -89.059 °C to 396.009 °C at 20.000°C/min
Gas Type,Nitrogen
Pan Type,None
Source Files 1,C:\Users\yargerlab\Desktop\DSC Data\General\TZero_calibration_11_29_22_2nd(2).tri
Source Files 2,C:\Users\yargerlab\Desktop\DSC Data\General\TZero_calibration_11_29_22_2nd(3).tri
Delta T Offset,13.05235
Delta T Slope,-0.007271007
Delta T0 Offset,-13.69128
Delta T0 Slope,0.06063341
[Temperature Calibration]
Date Applied,11/29/2022 7:12:28 PM
Description,From 106.590 °C to 186.590 °C at 10.000°C/min
Gas Type,Nitrogen
Pan Type,Tzero Aluminum Hermetic
Source Files 1,C:\Users\yargerlab\Desktop\DSC Data\General\Indium(6).tri
Measured 1,157.391
Known 1,156.598
[Cell Constant Calibration]
Date Applied,11/29/2022 7:12:29 PM
Description,From 106.590 °C to 186.590 °C at 10.000°C/min
Gas Type,Nitrogen
Pan Type,Tzero Aluminum Hermetic
Source Files 1,C:\Users\yargerlab\Desktop\DSC Data\General\Indium(6).tri
T4P KCell,1.006051
Onset Slope,63.26126 mW/°C
[Direct Cp Calibration]
Date Applied,11/30/2022 11:04:51 AM
Description,From -79.983 °C to 298.409 °C at 10.000°C/min
Gas Type,Nitrogen
Pan Type,Tzero Aluminum Hermetic
Source Files 1,C:\Users\yargerlab\Desktop\DSC Data\General\Sapphire_Heat_Capacity_11_30_22.tri
[Rev Cp Calibration]
Date Applied,11/30/2022 1:58:51 PM
Description,From -79.996 °C to 292.812 °C at 3.000°C/min
Gas Type,Nitrogen
Pan Type,Tzero Aluminum Hermetic
Source Files 1,C:\Users\yargerlab\Desktop\DSC Data\General\Sapphire_MDSC_Calibration_11_30_22.tri
[step]
Ramp 5.00 °C/min to 150.00 °C
Time,Temperature,Heat Flow (Normalized)
min,°C,W/g
0.00,-59.69,-0.054
0.03,-59.70,-0.054
0.06,-59.71,-0.045
0.08,-59.69,-0.040
0.11,-59.64,-0.030
0.14,-59.57,-0.013
0.17,-59.48,0.008
0.20,-59.37,0.027
0.23,-59.26,0.042
0.26,-59.15,0.054
0.28,-59.02,0.064
0.31,-58.90,0.071
0.34,-58.77,0.075
0.37,-58.64,0.080
0.40,-58.51,0.083
0.43,-58.38,0.086
0.45,-58.24,0.088
0.48,-58.11,0.089
0.51,-57.97,0.090
0.54,-57.84,0.091
0.57,-57.70,0.092
0.60,-57.57,0.092
0.62,-57.43,0.093
0.65,-57.29,0.094
0.68,-57.15,0.094
0.71,-57.01,0.094
0.74,-56.87,0.095
0.77,-56.73,0.096
0.79,-56.60,0.096
0.82,-56.46,0.096
0.85,-56.32,0.097
0.88,-56.18,0.097
0.91,-56.04,0.097
0.93,-55.90,0.098
0.96,-55.76,0.098
0.99,-55.62,0.098
1.02,-55.48,0.098
1.05,-55.34,0.098
1.08,-55.20,0.099
1.11,-55.06,0.099
1.13,-54.92,0.099
1.16,-54.78,0.099
1.19,-54.64,0.099
1.22,-54.50,0.099
1.25,-54.36,0.099
1.28,-54.22,0.100
1.30,-54.08,0.100
1.33,-53.93,0.100
1.36,-53.79,0.100
1.39,-53.65,0.100
1.42,-53.51,0.100
1.44,-53.37,0.100
1.47,-53.23,0.100
1.50,-53.09,0.100
1.53,-52.95,0.100
1.56,-52.81,0.100
1.59,-52.66,0.100
1.62,-52.52,0.100
1.64,-52.38,0.100
1.67,-52.24,0.100
1.70,-52.10,0.100
1.73,-51.96,0.100
1.76,-51.82,0.100
1.78,-51.68,0.100
1.81,-51.53,0.100
1.84,-51.39,0.100
1.87,-51.25,0.100
1.90,-51.11,0.100
1.93,-50.97,0.100
1.96,-50.83,0.100
1.98,-50.69,0.100
2.01,-50.55,0.100
2.04,-50.40,0.100
2.07,-50.26,0.100
2.10,-50.12,0.100
2.13,-49.98,0.100
2.15,-49.84,0.100
2.18,-49.70,0.100
2.21,-49.56,0.100
2.24,-49.41,0.100
2.27,-49.27,0.100
2.29,-49.13,0.100
2.32,-48.99,0.100
2.35,-48.85,0.100
2.38,-48.71,0.100
2.41,-48.57,0.100
2.44,-48.42,0.100
2.46,-48.28,0.100
2.49,-48.14,0.100
2.52,-48.00,0.100
2.55,-47.86,0.100
2.58,-47.72,0.100
2.61,-47.58,0.100
2.64,-47.44,0.100
2.66,-47.29,0.100
2.69,-47.15,0.100
2.72,-47.01,0.100
2.75,-46.87,0.100
2.78,-46.73,0.100
2.81,-46.58,0.100
2.83,-46.44,0.100
2.86,-46.30,0.100
2.89,-46.16,0.100
2.92,-46.02,0.100
2.95,-45.88,0.100
2.98,-45.74,0.100
3.00,-45.60,0.100
3.03,-45.45,0.100
3.06,-45.31,0.100
3.09,-45.17,0.100
3.12,-45.03,0.100
3.14,-44.89,0.100
3.17,-44.75,0.100
3.20,-44.60,0.100
3.23,-44.46,0.100
3.26,-44.32,0.100
3.29,-44.18,0.100
3.31,-44.04,0.100
3.34,-43.89,0.100
3.37,-43.75,0.100
3.40,-43.61,0.100
3.43,-43.47,0.100
3.46,-43.33,0.100
3.49,-43.19,0.100
3.51,-43.05,0.100
3.54,-42.90,0.100
3.57,-42.76,0.100
3.60,-42.62,0.100
3.63,-42.48,0.100
3.66,-42.34,0.100
3.68,-42.19,0.100
3.71,-42.05,0.100
3.74,-41.91,0.100
3.77,-41.77,0.100
3.80,-41.63,0.100
3.83,-41.49,0.100
3.85,-41.34,0.100
3.88,-41.20,0.100
3.91,-41.06,0.100
3.94,-40.92,0.100
3.97,-40.78,0.100
3.99,-40.63,0.101
4.02,-40.49,0.100
4.05,-40.35,0.101
4.08,-40.21,0.101
4.11,-40.07,0.101
4.14,-39.93,0.101
4.16,-39.78,0.101
4.19,-39.64,0.101
4.22,-39.50,0.101
4.25,-39.36,0.101
4.28,-39.22,0.101
4.31,-39.07,0.101
4.34,-38.93,0.101
4.36,-38.79,0.101
4.39,-38.65,0.101
4.42,-38.51,0.101
4.45,-38.37,0.101
4.48,-38.22,0.101
4.50,-38.08,0.101
4.53,-37.94,0.101
4.56,-37.80,0.101
4.59,-37.66,0.101
4.62,-37.51,0.101
4.65,-37.37,0.101
4.68,-37.23,0.101
4.70,-37.09,0.101
4.73,-36.95,0.101
4.76,-36.80,0.101
4.79,-36.66,0.101
4.82,-36.52,0.101
4.85,-36.38,0.101
4.87,-36.24,0.101
4.90,-36.10,0.101
4.93,-35.95,0.101
4.96,-35.81,0.101
4.99,-35.67,0.101
5.01,-35.53,0.101
5.04,-35.39,0.101
5.07,-35.24,0.101
5.10,-35.10,0.101
5.13,-34.96,0.101
5.16,-34.82,0.101
5.19,-34.68,0.101
5.21,-34.54,0.101
5.24,-34.39,0.101
5.27,-34.25,0.101
5.30,-34.11,0.101
5.33,-33.97,0.101
5.35,-33.83,0.101
5.38,-33.68,0.101
5.41,-33.54,0.101
5.44,-33.40,0.101
5.47,-33.26,0.102
5.50,-33.12,0.102
5.53,-32.97,0.102
5.55,-32.83,0.102
5.58,-32.69,0.102
5.61,-32.55,0.102
5.64,-32.41,0.102
5.67,-32.27,0.102
5.70,-32.13,0.102
5.72,-31.98,0.102
5.75,-31.84,0.102
5.78,-31.70,0.102
5.81,-31.56,0.102
5.84,-31.41,0.102
5.86,-31.27,0.102
5.89,-31.13,0.102
5.92,-30.99,0.102
5.95,-30.85,0.102
5.98,-30.71,0.102
6.01,-30.56,0.102
6.04,-30.42,0.102
6.06,-30.28,0.102
6.09,-30.14,0.102
6.12,-30.00,0.102
6.15,-29.86,0.102
6.18,-29.71,0.102
6.20,-29.57,0.102
6.23,-29.43,0.102
6.26,-29.29,0.102
6.29,-29.15,0.102
6.32,-29.01,0.102
6.35,-28.86,0.102
6.38,-28.72,0.102
6.40,-28.58,0.102
6.43,-28.44,0.102
6.46,-28.30,0.102
6.49,-28.16,0.102
6.52,-28.01,0.102
6.55,-27.87,0.102
6.57,-27.73,0.102
6.60,-27.59,0.103
6.63,-27.45,0.103
6.66,-27.30,0.103
6.69,-27.16,0.103
6.71,-27.02,0.103
6.74,-26.88,0.103
6.77,-26.74,0.103
6.80,-26.59,0.103
6.83,-26.45,0.103
6.86,-26.31,0.103
6.89,-26.17,0.103
6.91,-26.03,0.103
6.94,-25.89,0.103
6.97,-25.74,0.103
7.00,-25.60,0.103
7.03,-25.46,0.103
7.05,-25.32,0.103
7.08,-25.18,0.103
7.11,-25.04,0.103
7.14,-24.89,0.103
7.17,-24.75,0.103
7.20,-24.61,0.103
7.23,-24.47,0.103
7.25,-24.33,0.103
7.28,-24.18,0.103
7.31,-24.04,0.103
7.34,-23.90,0.103
7.37,-23.76,0.103
7.40,-23.62,0.103
7.42,-23.48,0.103
7.45,-23.33,0.103
7.48,-23.19,0.103
7.51,-23.05,0.103
7.54,-22.91,0.104
7.56,-22.77,0.103
7.59,-22.62,0.104
7.62,-22.48,0.104
7.65,-22.34,0.104
7.68,-22.20,0.104
7.71,-22.06,0.104
7.74,-21.92,0.104
7.76,-21.77,0.104
7.79,-21.63,0.104
7.82,-21.49,0.104
7.85,-21.35,0.104
7.88,-21.21,0.104
7.90,-21.06,0.104
7.93,-20.92,0.104
7.96,-20.78,0.104
7.99,-20.64,0.104
8.02,-20.50,0.104
8.05,-20.36,0.104
8.08,-20.21,0.104
8.10,-20.07,0.104
8.13,-19.93,0.104
8.16,-19.79,0.104
8.19,-19.65,0.104
8.22,-19.50,0.104
8.25,-19.36,0.104
8.27,-19.22,0.104
8.30,-19.08,0.104
8.33,-18.94,0.104
8.36,-18.79,0.105
8.39,-18.65,0.105
8.41,-18.51,0.105
8.44,-18.37,0.105
8.47,-18.23,0.105
8.50,-18.08,0.105
8.53,-17.95,0.105
8.56,-17.80,0.105
8.58,-17.66,0.105
8.61,-17.52,0.105
8.64,-17.38,0.105
8.67,-17.24,0.105
8.70,-17.10,0.105
8.73,-16.95,0.105
8.75,-16.81,0.105
8.78,-16.67,0.105
8.81,-16.53,0.105
8.84,-16.39,0.105
8.87,-16.24,0.105
8.90,-16.10,0.105
8.93,-15.96,0.105
8.95,-15.82,0.105
8.98,-15.68,0.105
9.01,-15.54,0.105
9.04,-15.39,0.105
9.07,-15.25,0.105
9.10,-15.11,0.105
9.12,-14.97,0.105
9.15,-14.82,0.106
9.18,-14.68,0.106
9.21,-14.54,0.106
9.24,-14.40,0.106
9.27,-14.26,0.106
9.29,-14.12,0.106
9.32,-13.98,0.106
9.35,-13.83,0.106
9.38,-13.69,0.106
9.41,-13.55,0.106
9.43,-13.41,0.106
9.46,-13.27,0.106
9.49,-13.12,0.106
9.52,-12.98,0.106
9.55,-12.84,0.106
9.58,-12.70,0.106
9.60,-12.56,0.106
9.63,-12.42,0.106
9.66,-12.28,0.106
9.69,-12.13,0.106
9.72,-11.99,0.106
9.75,-11.85,0.106
9.78,-11.71,0.106
9.80,-11.57,0.106
9.83,-11.43,0.106
9.86,-11.28,0.106
9.89,-11.14,0.106
9.92,-11.00,0.106
9.95,-10.86,0.107
9.97,-10.71,0.107
10.00,-10.57,0.107
10.03,-10.43,0.107
10.06,-10.29,0.107
10.09,-10.15,0.107
10.12,-10.01,0.107
10.14,-9.86,0.107
10.17,-9.72,0.107
10.20,-9.58,0.107
10.23,-9.44,0.107
10.26,-9.30,0.107
10.28,-9.16,0.107
10.31,-9.01,0.107
10.34,-8.87,0.107
10.37,-8.73,0.107
10.40,-8.59,0.107
10.43,-8.45,0.107
10.45,-8.31,0.107
10.48,-8.17,0.107
10.51,-8.02,0.107
10.54,-7.88,0.107
10.57,-7.74,0.107
10.60,-7.60,0.108
10.63,-7.45,0.108
10.65,-7.31,0.108
10.68,-7.17,0.108
10.71,-7.03,0.108
10.74,-6.89,0.108
10.77,-6.75,0.108
10.80,-6.60,0.108
10.82,-6.46,0.108
10.85,-6.32,0.108
10.88,-6.18,0.108
10.91,-6.04,0.108
10.94,-5.89,0.108
10.97,-5.75,0.108
10.99,-5.61,0.108
11.02,-5.47,0.108
11.05,-5.33,0.108
11.08,-5.19,0.108
11.11,-5.05,0.108
11.13,-4.90,0.108
11.16,-4.76,0.108
11.19,-4.62,0.108
11.22,-4.48,0.108
11.25,-4.34,0.109
11.28,-4.19,0.109
11.30,-4.05,0.109
11.33,-3.91,0.109
11.36,-3.77,0.109
11.39,-3.63,0.109
11.42,-3.49,0.109
11.45,-3.34,0.109
11.48,-3.20,0.109
11.50,-3.06,0.109
11.53,-2.92,0.109
11.56,-2.78,0.109
11.59,-2.63,0.109
11.62,-2.49,0.109
11.65,-2.35,0.109
11.67,-2.21,0.109
11.70,-2.07,0.109
11.73,-1.93,0.109
11.76,-1.79,0.109
11.79,-1.64,0.109
11.82,-1.50,0.109
11.84,-1.36,0.110
11.87,-1.22,0.110
11.90,-1.08,0.110
11.93,-0.93,0.110
11.96,-0.79,0.110
11.98,-0.65,0.110
12.01,-0.51,0.110
12.04,-0.37,0.110
12.07,-0.23,0.110
12.10,-0.08,0.110
12.13,0.06,0.110
12.15,0.20,0.110
12.18,0.34,0.110
12.21,0.48,0.110
12.24,0.63,0.110
12.27,0.77,0.110
12.30,0.91,0.110
12.33,1.05,0.110
12.35,1.19,0.110
12.38,1.34,0.111
12.41,1.48,0.111
12.44,1.62,0.111
12.47,1.76,0.111
12.50,1.90,0.111
12.52,2.04,0.111
12.55,2.19,0.111
12.58,2.33,0.111
12.61,2.47,0.111
12.64,2.61,0.111
12.67,2.75,0.111
12.69,2.89,0.111
12.72,3.04,0.111
12.75,3.18,0.111
12.78,3.32,0.111
12.81,3.46,0.111
12.83,3.60,0.111
12.86,3.75,0.111
12.89,3.89,0.111
12.92,4.03,0.111
12.95,4.17,0.112
12.98,4.31,0.112
13.00,4.46,0.112
13.03,4.60,0.112
13.06,4.74,0.112
13.09,4.88,0.112
13.12,5.02,0.112
13.15,5.16,0.112
13.18,5.31,0.112
13.20,5.45,0.112
13.23,5.59,0.112
13.26,5.73,0.112
13.29,5.87,0.112
13.32,6.02,0.112
13.35,6.16,0.112
13.37,6.30,0.112
13.40,6.44,0.112
13.43,6.58,0.112
13.46,6.72,0.112
13.49,6.86,0.112
13.52,7.01,0.112
13.54,7.15,0.113
13.57,7.29,0.113
13.60,7.43,0.113
13.63,7.57,0.113
13.66,7.71,0.113
13.68,7.86,0.113
13.71,8.00,0.113
13.74,8.14,0.113
13.77,8.28,0.113
13.80,8.42,0.113
13.83,8.56,0.113
13.85,8.71,0.113
13.88,8.85,0.113
13.91,8.99,0.113
13.94,9.13,0.113
13.97,9.27,0.113
14.00,9.41,0.113
14.03,9.56,0.114
14.05,9.70,0.114
14.08,9.84,0.114
14.11,9.98,0.114
14.14,10.12,0.114
14.17,10.27,0.114
14.20,10.41,0.114
14.22,10.55,0.114
14.25,10.69,0.114
14.28,10.83,0.114
14.31,10.98,0.114
14.34,11.12,0.114
14.37,11.26,0.114
14.39,11.40,0.114
14.42,11.54,0.114
14.45,11.68,0.115
14.48,11.82,0.115
14.51,11.97,0.115
14.53,12.11,0.115
14.56,12.25,0.115
14.59,12.39,0.115
14.62,12.53,0.115
14.65,12.68,0.115
14.68,12.82,0.115
14.70,12.96,0.115
14.73,13.10,0.115
14.76,13.24,0.115
14.79,13.38,0.115
14.82,13.53,0.115
14.85,13.67,0.116
14.88,13.81,0.116
14.90,13.95,0.116
14.93,14.09,0.116
14.96,14.23,0.116
14.99,14.38,0.116
15.02,14.52,0.116
15.05,14.66,0.116
15.07,14.80,0.116
15.10,14.94,0.116
15.13,15.09,0.116
15.16,15.23,0.116
15.19,15.37,0.116
15.22,15.51,0.116
15.24,15.65,0.117
15.27,15.79,0.116
15.30,15.94,0.117
15.33,16.08,0.117
15.36,16.22,0.117
15.38,16.36,0.117
15.41,16.50,0.117
15.44,16.64,0.117
15.47,16.79,0.117
15.50,16.93,0.117
15.53,17.07,0.117
15.55,17.21,0.117
15.58,17.35,0.117
15.61,17.49,0.117
15.64,17.64,0.117
15.67,17.78,0.117
15.70,17.92,0.118
15.73,18.06,0.118
15.75,18.20,0.118
15.78,18.34,0.118
15.81,18.49,0.118
15.84,18.63,0.118
15.87,18.77,0.118
15.90,18.91,0.118
15.92,19.05,0.118
15.95,19.20,0.119
15.98,19.34,0.119
16.01,19.48,0.119
16.04,19.62,0.119
16.07,19.76,0.119
16.09,19.91,0.119
16.12,20.05,0.119
16.15,20.19,0.119
16.18,20.33,0.119
16.21,20.47,0.119
16.23,20.61,0.119
16.26,20.76,0.119
16.29,20.90,0.120
16.32,21.04,0.120
16.35,21.18,0.120
16.38,21.32,0.120
16.40,21.46,0.120
16.43,21.61,0.120
16.46,21.75,0.120
16.49,21.89,0.120
16.52,22.03,0.120
16.55,22.17,0.120
16.58,22.32,0.120
16.60,22.46,0.120
16.63,22.60,0.120
16.66,22.74,0.121
16.69,22.88,0.121
16.72,23.02,0.121
16.75,23.16,0.121
16.77,23.31,0.121
16.80,23.45,0.121
16.83,23.59,0.121
16.86,23.73,0.121
16.89,23.87,0.121
16.92,24.02,0.121
16.94,24.16,0.121
16.97,24.30,0.121
17.00,24.44,0.122
17.03,24.58,0.122
17.06,24.73,0.122
17.08,24.87,0.122
17.11,25.01,0.122
17.14,25.15,0.122
17.17,25.29,0.122
17.20,25.43,0.122
17.23,25.58,0.122
17.26,25.72,0.122
17.28,25.86,0.122
17.31,26.00,0.122
17.34,26.14,0.122
17.37,26.28,0.123
17.40,26.43,0.123
17.43,26.57,0.123
17.45,26.71,0.123
17.48,26.85,0.123
17.51,26.99,0.123
17.54,27.13,0.123
17.57,27.27,0.123
17.59,27.42,0.123
17.62,27.56,0.123
17.65,27.70,0.123
17.68,27.84,0.123
17.71,27.98,0.123
17.74,28.12,0.123
17.77,28.27,0.123
17.79,28.41,0.124
17.82,28.55,0.124
17.85,28.69,0.124
17.88,28.83,0.124
17.91,28.97,0.124
17.93,29.12,0.124
17.96,29.26,0.124
17.99,29.40,0.124
18.02,29.54,0.124
18.05,29.69,0.124
18.08,29.83,0.124
18.11,29.97,0.124
18.13,30.11,0.125
18.16,30.25,0.125
18.19,30.40,0.125
18.22,30.54,0.125
18.25,30.68,0.125
18.28,30.82,0.125
18.30,30.96,0.125
18.33,31.10,0.125
18.36,31.25,0.125
18.39,31.39,0.125
18.42,31.53,0.125
18.44,31.67,0.126
18.47,31.81,0.126
18.50,31.95,0.126
18.53,32.10,0.126
18.56,32.24,0.126
18.59,32.38,0.126
18.62,32.52,0.126
18.64,32.66,0.126
18.67,32.80,0.126
18.70,32.95,0.126
18.73,33.09,0.126
18.76,33.23,0.126
18.78,33.37,0.126
18.81,33.51,0.126
18.84,33.65,0.126
18.87,33.80,0.127
18.90,33.94,0.127
18.93,34.08,0.127
18.96,34.22,0.127
18.98,34.36,0.127
19.01,34.50,0.127
19.04,34.65,0.127
19.07,34.79,0.127
19.10,34.93,0.127
19.13,35.07,0.127
19.15,35.21,0.127
19.18,35.35,0.127
19.21,35.50,0.127
19.24,35.64,0.128
19.27,35.78,0.128
19.29,35.92,0.128
19.32,36.06,0.128
19.35,36.21,0.128
19.38,36.35,0.128
19.41,36.49,0.128
19.44,36.63,0.128
19.47,36.77,0.128
19.49,36.92,0.128
19.52,37.05,0.128
19.55,37.20,0.129
19.58,37.34,0.129
19.61,37.48,0.129
19.63,37.62,0.129
19.66,37.76,0.129
19.69,37.91,0.129
19.72,38.05,0.129
19.75,38.19,0.129
19.78,38.33,0.129
19.81,38.47,0.129
19.83,38.62,0.130
19.86,38.76,0.130
19.89,38.90,0.130
19.92,39.04,0.130
19.95,39.18,0.130
19.98,39.32,0.130
20.00,39.47,0.130
20.03,39.61,0.130
20.06,39.75,0.130
20.09,39.89,0.130
20.12,40.03,0.131
20.14,40.17,0.131
20.17,40.32,0.131
20.20,40.46,0.131
20.23,40.60,0.131
20.26,40.74,0.131
20.29,40.88,0.131
20.32,41.02,0.131
20.34,41.17,0.132
20.37,41.31,0.132
20.40,41.45,0.132
20.43,41.59,0.132
20.46,41.73,0.132
20.48,41.88,0.132
20.51,42.02,0.132
20.54,42.16,0.133
20.57,42.30,0.133
20.60,42.44,0.133
20.63,42.58,0.133
20.66,42.72,0.133
20.68,42.87,0.133
20.71,43.01,0.133
20.74,43.15,0.133
20.77,43.29,0.134
20.80,43.43,0.134
20.83,43.58,0.134
20.85,43.72,0.134
20.88,43.86,0.134
20.91,44.00,0.134
20.94,44.14,0.134
20.97,44.28,0.135
20.99,44.43,0.135
21.02,44.57,0.135
21.05,44.71,0.135
21.08,44.85,0.135
21.11,44.99,0.136
21.14,45.13,0.136
21.17,45.28,0.136
21.19,45.42,0.136
21.22,45.56,0.136
21.25,45.70,0.136
21.28,45.84,0.137
21.31,45.98,0.137
21.33,46.13,0.137
21.36,46.27,0.137
21.39,46.41,0.137
21.42,46.55,0.138
21.45,46.69,0.138
21.48,46.83,0.138
21.51,46.97,0.138
21.53,47.12,0.138
21.56,47.26,0.138
21.59,47.40,0.139
21.62,47.54,0.139
21.65,47.68,0.139
21.68,47.83,0.139
21.70,47.97,0.139
21.73,48.11,0.140
21.76,48.25,0.140
21.79,48.39,0.140
21.82,48.54,0.140
21.84,48.68,0.140
21.87,48.82,0.141
21.90,48.96,0.141
21.93,49.10,0.141
21.96,49.24,0.141
21.99,49.39,0.141
22.02,49.53,0.142
22.04,49.67,0.142
22.07,49.81,0.142
22.10,49.95,0.142
22.13,50.09,0.143
22.16,50.24,0.143
22.18,50.38,0.143
22.21,50.52,0.143
22.24,50.66,0.143
22.27,50.80,0.144
22.30,50.94,0.144
22.33,51.09,0.144
22.36,51.23,0.144
22.38,51.37,0.144
22.41,51.51,0.145
22.44,51.65,0.145
22.47,51.79,0.145
22.50,51.93,0.146
22.53,52.08,0.146
22.55,52.22,0.146
22.58,52.36,0.146
22.61,52.50,0.147
22.64,52.64,0.147
22.67,52.78,0.147
22.69,52.93,0.147
22.72,53.07,0.148
22.75,53.21,0.148
22.78,53.35,0.148
22.81,53.49,0.149
22.84,53.63,0.149
22.87,53.78,0.149
22.89,53.92,0.150
22.92,54.06,0.150
22.95,54.20,0.151
22.98,54.34,0.151
23.01,54.48,0.152
23.03,54.63,0.152
23.06,54.77,0.152
23.09,54.91,0.153
23.12,55.05,0.153
23.15,55.19,0.154
23.18,55.33,0.154
23.21,55.48,0.155
23.23,55.62,0.155
23.26,55.76,0.156
23.29,55.90,0.157
23.32,56.04,0.157
23.35,56.18,0.158
23.38,56.33,0.159
23.40,56.47,0.159
23.43,56.61,0.160
23.46,56.75,0.161
23.49,56.89,0.162
23.52,57.03,0.163
23.54,57.18,0.164
23.57,57.32,0.164
23.60,57.46,0.165
23.63,57.60,0.166
23.66,57.74,0.167
23.69,57.88,0.168
23.72,58.02,0.169
23.74,58.16,0.171
23.77,58.31,0.172
23.80,58.45,0.174
23.83,58.59,0.176
23.86,58.73,0.177
23.88,58.87,0.179
23.91,59.01,0.181
23.94,59.15,0.183
23.97,59.29,0.185
24.00,59.43,0.187
24.03,59.58,0.190
24.06,59.72,0.192
24.08,59.86,0.194
24.11,60.00,0.197
24.14,60.14,0.199
24.17,60.28,0.201
24.20,60.42,0.205
24.23,60.56,0.207
24.25,60.70,0.211
24.28,60.84,0.213
24.31,60.99,0.215
24.34,61.13,0.219
24.37,61.27,0.222
24.39,61.41,0.226
24.42,61.55,0.228
24.45,61.69,0.233
24.48,61.83,0.235
24.51,61.97,0.239
24.54,62.11,0.241
24.57,62.25,0.246
24.59,62.39,0.250
24.62,62.53,0.253
24.65,62.67,0.256
24.68,62.81,0.260
24.71,62.95,0.264
24.73,63.09,0.267
24.76,63.23,0.270
24.79,63.38,0.274
24.82,63.52,0.278
24.85,63.66,0.282
24.88,63.80,0.285
24.91,63.94,0.289
24.93,64.08,0.293
24.96,64.22,0.297
24.99,64.36,0.300
25.02,64.50,0.304
25.05,64.64,0.308
25.08,64.78,0.312
25.10,64.92,0.315
25.13,65.06,0.319
25.16,65.20,0.322
25.19,65.34,0.326
25.22,65.48,0.329
25.24,65.62,0.332
25.27,65.76,0.335
25.30,65.90,0.337
25.33,66.05,0.340
25.36,66.19,0.343
25.39,66.33,0.344
25.42,66.47,0.347
25.44,66.61,0.350
25.47,66.75,0.353
25.50,66.89,0.356
25.53,67.03,0.359
25.56,67.17,0.363
25.58,67.31,0.368
25.61,67.45,0.373
25.64,67.59,0.377
25.67,67.73,0.384
25.70,67.87,0.391
25.73,68.01,0.398
25.76,68.15,0.407
25.78,68.29,0.416
25.81,68.43,0.425
25.84,68.57,0.436
25.87,68.71,0.447
25.90,68.84,0.460
25.93,68.98,0.470
25.95,69.12,0.482
25.98,69.26,0.493
26.01,69.39,0.500
26.04,69.54,0.504
26.07,69.67,0.506
26.09,69.81,0.508
26.12,69.95,0.511
26.15,70.10,0.515
26.18,70.24,0.521
26.21,70.38,0.525
26.24,70.52,0.530
26.27,70.66,0.535
26.29,70.80,0.539
26.32,70.94,0.544
26.35,71.08,0.549
26.38,71.22,0.554
26.41,71.36,0.558
26.43,71.50,0.560
26.46,71.64,0.562
26.49,71.78,0.562
26.52,71.92,0.561
26.55,72.07,0.550
26.58,72.21,0.537
26.61,72.35,0.524
26.63,72.50,0.507
26.66,72.65,0.491
26.69,72.79,0.474
26.72,72.94,0.454
26.75,73.09,0.433
26.78,73.24,0.413
26.80,73.39,0.391
26.83,73.54,0.369
26.86,73.68,0.346
26.89,73.84,0.325
26.92,73.98,0.303
26.94,74.13,0.281
26.97,74.28,0.261
27.00,74.43,0.244
27.03,74.58,0.226
27.06,74.73,0.211
27.09,74.87,0.199
27.12,75.02,0.189
27.14,75.17,0.181
27.17,75.31,0.174
27.20,75.46,0.169
27.23,75.60,0.166
27.26,75.74,0.164
27.28,75.89,0.162
27.31,76.03,0.161
27.34,76.17,0.160
27.37,76.31,0.160
27.40,76.46,0.159
27.43,76.60,0.159
27.46,76.74,0.159
27.48,76.88,0.158
27.51,77.02,0.158
27.54,77.16,0.158
27.57,77.31,0.158
27.60,77.45,0.158
27.63,77.59,0.157
27.65,77.73,0.157
27.68,77.87,0.157
27.71,78.02,0.157
27.74,78.16,0.157
27.77,78.30,0.157
27.79,78.44,0.157
27.82,78.58,0.157
27.85,78.72,0.157
27.88,78.87,0.157
27.91,79.01,0.157
27.94,79.15,0.157
27.97,79.29,0.157
27.99,79.43,0.157
28.02,79.57,0.157
28.05,79.72,0.157
28.08,79.86,0.158
28.11,80.00,0.158
28.13,80.14,0.158
28.16,80.28,0.158
28.19,80.42,0.158
28.22,80.57,0.158
28.25,80.71,0.158
28.28,80.85,0.158
28.31,80.99,0.158
28.33,81.13,0.159
28.36,81.28,0.159
28.39,81.42,0.159
28.42,81.56,0.159
28.45,81.70,0.159
28.48,81.84,0.159
28.50,81.98,0.159
28.53,82.13,0.159
28.56,82.27,0.160
28.59,82.41,0.160
28.62,82.55,0.160
28.64,82.69,0.160
28.67,82.83,0.160
28.70,82.98,0.160
28.73,83.12,0.160
28.76,83.26,0.160
28.79,83.40,0.160
28.82,83.54,0.160
28.84,83.68,0.160
28.87,83.83,0.161
28.90,83.97,0.161
28.93,84.11,0.161
28.96,84.25,0.161
28.98,84.39,0.161
29.01,84.53,0.161
29.04,84.68,0.161
29.07,84.82,0.161
29.10,84.96,0.161
29.13,85.10,0.161
29.16,85.24,0.162
29.18,85.39,0.162
29.21,85.53,0.162
29.24,85.67,0.162
29.27,85.81,0.162
29.30,85.95,0.162
29.33,86.09,0.162
29.35,86.23,0.162
29.38,86.38,0.162
29.41,86.52,0.162
29.44,86.66,0.162
29.47,86.80,0.163
29.49,86.94,0.163
29.52,87.08,0.163
29.55,87.23,0.163
29.58,87.37,0.163
29.61,87.51,0.163
29.64,87.65,0.163
29.67,87.79,0.163
29.69,87.93,0.163
29.72,88.08,0.164
29.75,88.22,0.164
29.78,88.36,0.164
29.81,88.50,0.164
29.83,88.64,0.164
29.86,88.79,0.164
29.89,88.93,0.164
29.92,89.07,0.164
29.95,89.21,0.164
29.98,89.35,0.164
30.01,89.49,0.165
30.03,89.64,0.165
30.06,89.78,0.165
30.09,89.92,0.165
30.12,90.06,0.165
30.15,90.20,0.165
30.18,90.35,0.165
30.20,90.49,0.165
30.23,90.63,0.166
30.26,90.77,0.166
30.29,90.91,0.166
30.32,91.06,0.166
30.34,91.20,0.166
30.37,91.34,0.166
30.40,91.48,0.166
30.43,91.62,0.166
30.46,91.76,0.167
30.49,91.90,0.167
30.52,92.05,0.167
30.54,92.19,0.167
30.57,92.33,0.167
30.60,92.47,0.167
30.63,92.61,0.167
30.66,92.75,0.167
30.68,92.90,0.167
30.71,93.04,0.167
30.74,93.18,0.168
30.77,93.32,0.168
30.80,93.46,0.168
30.83,93.60,0.168
30.86,93.75,0.168
30.88,93.89,0.168
30.91,94.03,0.168
30.94,94.17,0.168
30.97,94.31,0.168
31.00,94.45,0.169
31.03,94.60,0.169
31.05,94.74,0.169
31.08,94.88,0.169
31.11,95.02,0.169
31.14,95.16,0.169
31.17,95.30,0.169
31.19,95.45,0.169
31.22,95.59,0.169
31.25,95.73,0.169
31.28,95.87,0.170
31.31,96.01,0.170
31.34,96.15,0.170
31.37,96.30,0.170
31.39,96.44,0.170
31.42,96.58,0.170
31.45,96.72,0.170
31.48,96.86,0.170
31.51,97.00,0.170
31.53,97.15,0.170
31.56,97.29,0.170
31.59,97.43,0.170
31.62,97.57,0.171
31.65,97.71,0.171
31.68,97.86,0.171
31.71,98.00,0.171
31.73,98.14,0.171
31.76,98.28,0.171
31.79,98.42,0.171
31.82,98.56,0.171
31.85,98.71,0.171
31.88,98.85,0.171
31.90,98.99,0.171
31.93,99.13,0.171
31.96,99.27,0.171
31.99,99.41,0.172
32.02,99.56,0.172
32.04,99.70,0.172
32.07,99.84,0.172
32.10,99.98,0.172
32.13,100.12,0.172
32.16,100.26,0.172
32.19,100.41,0.172
32.22,100.55,0.172
32.24,100.69,0.172
32.27,100.83,0.172
32.30,100.97,0.172
32.33,101.11,0.173
32.36,101.26,0.173
32.38,101.40,0.173
32.41,101.54,0.173
32.44,101.68,0.173
32.47,101.82,0.173
32.50,101.96,0.173
32.53,102.11,0.173
32.56,102.25,0.173
32.58,102.39,0.173
32.61,102.53,0.173
32.64,102.67,0.173
32.67,102.81,0.173
32.70,102.96,0.173
32.73,103.10,0.173
32.75,103.24,0.173
32.78,103.38,0.174
32.81,103.53,0.174
32.84,103.67,0.174
32.87,103.81,0.174
32.89,103.95,0.174
32.92,104.09,0.174
32.95,104.23,0.174
32.98,104.38,0.174
33.01,104.52,0.174
33.04,104.66,0.174
33.07,104.80,0.174
33.09,104.94,0.174
33.12,105.08,0.174
33.15,105.22,0.174
33.18,105.37,0.175
33.21,105.51,0.175
33.23,105.65,0.175
33.26,105.79,0.175
33.29,105.93,0.175
33.32,106.08,0.175
33.35,106.22,0.175
33.38,106.36,0.175
33.41,106.50,0.175
33.43,106.64,0.175
33.46,106.78,0.175
33.49,106.92,0.175
33.52,107.07,0.175
33.55,107.21,0.175
33.58,107.35,0.175
33.60,107.49,0.175
33.63,107.63,0.176
33.66,107.78,0.176
33.69,107.92,0.176
33.72,108.06,0.176
33.74,108.20,0.176
33.77,108.34,0.176
33.80,108.48,0.176
33.83,108.63,0.176
33.86,108.77,0.176
33.89,108.91,0.176
33.92,109.05,0.176
33.94,109.19,0.176
33.97,109.34,0.176
34.00,109.48,0.176
34.03,109.62,0.176
34.06,109.76,0.176
34.08,109.90,0.176
34.11,110.04,0.177
34.14,110.18,0.177
34.17,110.33,0.177
34.20,110.47,0.177
34.23,110.61,0.177
34.26,110.75,0.177
34.28,110.89,0.177
34.31,111.03,0.177
34.34,111.18,0.177
34.37,111.32,0.177
34.40,111.46,0.177
34.43,111.60,0.177
34.45,111.74,0.177
34.48,111.88,0.177
34.51,112.03,0.177
34.54,112.17,0.177
34.57,112.31,0.177
34.59,112.45,0.177
34.62,112.59,0.178
34.65,112.73,0.178
34.68,112.88,0.178
34.71,113.02,0.178
34.74,113.16,0.178
34.76,113.30,0.178
34.79,113.44,0.178
34.82,113.59,0.178
34.85,113.73,0.178
34.88,113.87,0.178
34.91,114.01,0.178
34.94,114.15,0.178
34.96,114.29,0.178
34.99,114.44,0.178
35.02,114.58,0.178
35.05,114.72,0.178
35.08,114.86,0.178
35.11,115.00,0.178
35.13,115.14,0.178
35.16,115.29,0.178
35.19,115.43,0.179
35.22,115.57,0.179
35.25,115.71,0.179
35.28,115.85,0.179
35.30,116.00,0.179
35.33,116.14,0.179
35.36,116.28,0.179
35.39,116.42,0.179
35.42,116.56,0.179
35.44,116.70,0.179
35.47,116.85,0.179
35.50,116.99,0.179
35.53,117.13,0.179
35.56,117.27,0.179
35.59,117.41,0.179
35.61,117.55,0.179
35.64,117.70,0.179
35.67,117.84,0.179
35.70,117.98,0.179
35.73,118.12,0.179
35.76,118.26,0.179
35.79,118.40,0.179
35.81,118.55,0.179
35.84,118.69,0.180
35.87,118.83,0.180
35.90,118.97,0.180
35.93,119.11,0.180
35.96,119.25,0.180
35.98,119.40,0.180
36.01,119.54,0.180
36.04,119.68,0.180
36.07,119.82,0.180
36.10,119.96,0.180
36.13,120.10,0.180
36.15,120.25,0.180
36.18,120.39,0.180
36.21,120.53,0.180
36.24,120.67,0.180
36.27,120.81,0.180
36.29,120.96,0.180
36.32,121.10,0.180
36.35,121.24,0.180
36.38,121.38,0.180
36.41,121.52,0.180
36.44,121.66,0.180
36.46,121.81,0.180
36.49,121.95,0.180
36.52,122.09,0.180
36.55,122.23,0.180
36.58,122.37,0.181
36.61,122.52,0.181
36.64,122.66,0.181
36.66,122.80,0.181
36.69,122.94,0.181
36.72,123.08,0.181
36.75,123.22,0.181
36.78,123.36,0.181
36.81,123.51,0.181
36.83,123.65,0.181
36.86,123.79,0.181
36.89,123.93,0.181
36.92,124.07,0.181
36.95,124.21,0.181
36.98,124.36,0.181
37.00,124.50,0.181
37.03,124.64,0.181
37.06,124.78,0.181
37.09,124.92,0.181
37.12,125.07,0.181
37.14,125.21,0.181
37.17,125.35,0.181
37.20,125.49,0.181
37.23,125.63,0.181
37.26,125.77,0.182
37.29,125.92,0.182
37.31,126.06,0.182
37.34,126.20,0.182
37.37,126.34,0.182
37.40,126.48,0.182
37.43,126.62,0.182
37.46,126.77,0.182
37.49,126.91,0.182
37.51,127.05,0.182
37.54,127.19,0.182
37.57,127.33,0.182
37.60,127.48,0.182
37.63,127.62,0.182
37.66,127.76,0.182
37.68,127.90,0.182
37.71,128.04,0.182
37.74,128.18,0.182
37.77,128.32,0.182
37.80,128.47,0.182
37.83,128.61,0.182
37.85,128.75,0.182
37.88,128.89,0.182
37.91,129.03,0.182
37.94,129.17,0.182
37.97,129.32,0.182
37.99,129.46,0.183
38.02,129.60,0.183
38.05,129.74,0.183
38.08,129.88,0.183
38.11,130.03,0.183
38.14,130.17,0.183
38.16,130.31,0.183
38.19,130.45,0.183
38.22,130.59,0.183
38.25,130.73,0.183
38.28,130.88,0.183
38.31,131.02,0.183
38.34,131.16,0.183
38.36,131.30,0.183
38.39,131.44,0.183
38.42,131.58,0.183
38.45,131.73,0.183
38.48,131.87,0.183
38.51,132.01,0.183
38.53,132.15,0.183
38.56,132.29,0.183
38.59,132.43,0.183
38.62,132.58,0.183
38.65,132.72,0.183
38.68,132.86,0.183
38.70,133.00,0.183
38.73,133.14,0.183
38.76,133.28,0.183
38.79,133.43,0.183
38.82,133.57,0.184
38.84,133.71,0.184
38.87,133.85,0.184
38.90,133.99,0.184
38.93,134.13,0.184
38.96,134.28,0.184
38.99,134.42,0.184
39.01,134.56,0.184
39.04,134.70,0.184
39.07,134.84,0.184
39.10,134.99,0.184
39.13,135.13,0.184
39.16,135.27,0.184
39.19,135.41,0.184
39.21,135.55,0.184
39.24,135.69,0.184
39.27,135.84,0.184
39.30,135.98,0.184
39.33,136.12,0.184
39.36,136.26,0.184
39.38,136.40,0.184
39.41,136.54,0.184
39.44,136.69,0.184
39.47,136.83,0.184
39.50,136.97,0.184
39.53,137.11,0.184
39.55,137.25,0.184
39.58,137.39,0.184
39.61,137.54,0.184
39.64,137.68,0.184
39.67,137.82,0.184
39.69,137.96,0.184
39.72,138.10,0.184
39.75,138.24,0.184
39.78,138.39,0.184
39.81,138.53,0.184
39.84,138.67,0.184
39.86,138.81,0.184
39.89,138.95,0.184
39.92,139.10,0.184
39.95,139.24,0.184
39.98,139.38,0.184
40.01,139.52,0.184
40.04,139.66,0.184
40.06,139.80,0.185
40.09,139.95,0.185
40.12,140.09,0.185
40.15,140.23,0.185
40.18,140.37,0.185
40.21,140.51,0.185
40.23,140.65,0.185
40.26,140.80,0.185
40.29,140.94,0.185
40.32,141.08,0.185
40.35,141.22,0.185
40.38,141.36,0.185
40.40,141.50,0.185
40.43,141.65,0.185
40.46,141.79,0.185
40.49,141.93,0.185
40.52,142.07,0.185
40.54,142.21,0.185
40.57,142.35,0.185
40.60,142.49,0.185
40.63,142.64,0.185
40.66,142.78,0.185
40.69,142.92,0.185
40.71,143.06,0.185
40.74,143.21,0.186
40.77,143.35,0.186
40.80,143.49,0.186
40.83,143.63,0.186
40.86,143.77,0.186
40.89,143.91,0.186
40.91,144.06,0.186
40.94,144.20,0.186
40.97,144.34,0.186
41.00,144.48,0.186
41.03,144.62,0.186
41.06,144.76,0.186
41.08,144.90,0.186
41.11,145.05,0.186
41.14,145.19,0.186
41.17,145.33,0.186
41.20,145.47,0.186
41.23,145.61,0.186
41.25,145.76,0.186
41.28,145.90,0.186
41.31,146.04,0.186
41.34,146.18,0.186
41.37,146.32,0.186
41.39,146.46,0.186
41.42,146.61,0.186
41.45,146.75,0.186
41.48,146.89,0.186
41.51,147.03,0.186
41.54,147.17,0.186
41.56,147.31,0.186
41.59,147.46,0.186
41.62,147.60,0.186
41.65,147.74,0.186
41.68,147.88,0.186
41.71,148.02,0.186
41.74,148.16,0.186
41.76,148.31,0.186
41.79,148.45,0.186
41.82,148.59,0.186
41.85,148.73,0.186
41.88,148.87,0.186
41.91,149.01,0.186
41.93,149.15,
41.96,149.30,
41.99,,

[step]
Ramp 10.00 °C/min to -60.00 °C
Time,Temperature,Heat Flow (Normalized)
min,°C,W/g
42.99,150.12,-0.035
43.00,150.12,-0.035
43.02,150.11,-0.035
43.03,150.11,-0.035
43.05,150.09,-0.035
43.06,150.07,-0.037
43.08,150.04,-0.053
43.09,149.99,-0.079
43.11,149.93,-0.113
43.12,149.85,-0.151
43.14,149.76,-0.194
43.15,149.66,-0.233
43.17,149.55,-0.267
43.18,149.44,-0.299
43.20,149.32,-0.322
43.21,149.20,-0.343
43.23,149.07,-0.362
43.24,148.94,-0.375
43.26,148.81,-0.388
43.27,148.68,-0.398
43.29,148.54,-0.409
43.30,148.40,-0.416
43.32,148.26,-0.423
43.33,148.12,-0.428
43.35,147.98,-0.436
43.36,147.84,-0.437
43.38,147.69,-0.442
43.39,147.55,-0.445
43.41,147.40,-0.446
43.42,147.26,-0.450
43.44,147.11,-0.451
43.45,146.97,-0.453
43.47,146.82,-0.454
43.48,146.67,-0.455
43.50,146.53,-0.455
43.51,146.38,-0.457
43.53,146.23,-0.458
43.54,146.08,-0.458
43.56,145.94,-0.459
43.57,145.79,-0.459
43.59,145.64,-0.460
43.60,145.49,-0.460
43.62,145.35,-0.460
43.63,145.20,-0.460
43.65,145.05,-0.461
43.66,144.90,-0.461
43.68,144.75,-0.461
43.69,144.61,-0.462
43.71,144.46,-0.462
43.72,144.31,-0.462
43.74,144.16,-0.462
43.75,144.01,-0.462
43.77,143.86,-0.462
43.78,143.71,-0.462
43.80,143.57,-0.463
43.81,143.42,-0.463
43.83,143.27,-0.463
43.84,143.12,-0.463
43.86,142.97,-0.463
43.87,142.82,-0.463
43.89,142.67,-0.464
43.90,142.52,-0.464
43.92,142.37,-0.464
43.93,142.23,-0.464
43.95,142.08,-0.464
43.96,141.93,-0.464
43.98,141.78,-0.464
43.99,141.63,-0.464
44.01,141.48,-0.464
44.02,141.33,-0.464
44.04,141.18,-0.464
44.05,141.03,-0.464
44.07,140.88,-0.464
44.08,140.73,-0.464
44.10,140.58,-0.464
44.11,140.43,-0.464
44.13,140.29,-0.464
44.14,140.14,-0.464
44.16,139.99,-0.464
44.17,139.84,-0.464
44.19,139.69,-0.464
44.20,139.54,-0.464
44.22,139.39,-0.464
44.23,139.24,-0.464
44.25,139.09,-0.464
44.26,138.94,-0.464
44.28,138.79,-0.464
44.29,138.64,-0.464
44.31,138.49,-0.464
44.32,138.34,-0.464
44.34,138.19,-0.464
44.35,138.04,-0.464
44.37,137.89,-0.464
44.38,137.74,-0.464
44.40,137.59,-0.464
44.41,137.44,-0.463
44.43,137.29,-0.463
44.44,137.14,-0.463
44.46,137.00,-0.463
44.47,136.85,-0.463
44.49,136.70,-0.463
44.50,136.55,-0.463
44.52,136.40,-0.463
44.53,136.25,-0.463
44.55,136.10,-0.462
44.56,135.95,-0.462
44.58,135.80,-0.462
44.59,135.65,-0.462
44.61,135.50,-0.462
44.62,135.35,-0.462
44.64,135.20,-0.462
44.65,135.05,-0.462
44.67,134.90,-0.461
44.68,134.75,-0.461
44.70,134.60,-0.461
44.71,134.45,-0.461
44.73,134.30,-0.461
44.74,134.15,-0.461
44.76,134.00,-0.461
44.77,133.85,-0.461
44.79,133.70,-0.461
44.80,133.55,-0.460
44.82,133.40,-0.460
44.83,133.25,-0.460
44.85,133.10,-0.460
44.86,132.95,-0.460
44.88,132.80,-0.460
44.89,132.65,-0.460
44.91,132.50,-0.460
44.92,132.35,-0.460
44.94,132.20,-0.460
44.95,132.05,-0.460
44.97,131.90,-0.459
44.98,131.75,-0.459
45.00,131.60,-0.459
45.01,131.45,-0.459
45.03,131.30,-0.459
45.04,131.15,-0.459
45.06,131.00,-0.458
45.07,130.86,-0.458
45.09,130.70,-0.458
45.10,130.55,-0.458
45.12,130.41,-0.458
45.13,130.26,-0.458
45.15,130.11,-0.458
45.16,129.96,-0.458
45.18,129.81,-0.458
45.19,129.66,-0.458
45.21,129.51,-0.457
45.22,129.36,-0.457
45.24,129.21,-0.457
45.25,129.06,-0.457
45.27,128.91,-0.457
45.28,128.76,-0.457
45.30,128.61,-0.457
45.31,128.46,-0.457
45.33,128.31,-0.457
45.34,128.16,-0.457
45.36,128.01,-0.456
45.37,127.86,-0.456
45.39,127.71,-0.456
45.40,127.56,-0.456
45.42,127.41,-0.456
45.43,127.26,-0.456
45.45,127.11,-0.456
45.46,126.96,-0.455
45.48,126.81,-0.455
45.49,126.66,-0.455
45.51,126.51,-0.455
45.52,126.36,-0.455
45.54,126.21,-0.455
45.55,126.06,-0.455
45.57,125.91,-0.455
45.58,125.76,-0.455
45.60,125.61,-0.454
45.61,125.46,-0.454
45.63,125.31,-0.454
45.64,125.16,-0.454
45.66,125.01,-0.454
45.67,124.86,-0.454
45.69,124.71,-0.454
45.70,124.56,-0.454
45.72,124.41,-0.454
45.73,124.26,-0.453
45.75,124.11,-0.453
45.76,123.96,-0.453
45.78,123.81,-0.453
45.79,123.66,-0.453
45.81,123.51,-0.453
45.82,123.36,-0.453
45.84,123.21,-0.453
45.85,123.06,-0.453
45.87,122.91,-0.452
45.88,122.76,-0.452
45.90,122.61,-0.452
45.91,122.46,-0.452
45.93,122.31,-0.452
45.94,122.16,-0.452
45.96,122.01,-0.452
45.97,121.86,-0.452
45.99,121.71,-0.452
46.00,121.56,-0.451
46.02,121.41,-0.451
46.03,121.27,-0.451
46.05,121.12,-0.451
46.06,120.97,-0.451
46.08,120.82,-0.451
46.09,120.67,-0.451
46.11,120.52,-0.451
46.12,120.37,-0.451
46.14,120.22,-0.450
46.15,120.07,-0.450
46.17,119.92,-0.450
46.18,119.77,-0.450
46.20,119.62,-0.450
46.21,119.47,-0.450
46.23,119.32,-0.450
46.24,119.17,-0.450
46.26,119.02,-0.449
46.27,118.87,-0.449
46.29,118.72,-0.449
46.30,118.57,-0.449
46.32,118.42,-0.449
46.33,118.27,-0.449
46.35,118.12,-0.449
46.36,117.97,-0.449
46.38,117.82,-0.449
46.39,117.67,-0.449
46.41,117.52,-0.449
46.42,117.37,-0.448
46.44,117.22,-0.448
46.45,117.07,-0.448
46.47,116.92,-0.448
46.48,116.77,-0.448
46.50,116.62,-0.448
46.51,116.47,-0.448
46.53,116.32,-0.448
46.54,116.17,-0.447
46.56,116.02,-0.447
46.57,115.87,-0.447
46.59,115.72,-0.447
46.60,115.57,-0.447
46.62,115.42,-0.447
46.63,115.27,-0.447
46.65,115.12,-0.447
46.66,114.97,-0.447
46.68,114.82,-0.447
46.69,114.67,-0.447
46.71,114.52,-0.447
46.72,114.37,-0.447
46.74,114.22,-0.446
46.75,114.07,-0.446
46.77,113.92,-0.446
46.78,113.77,-0.446
46.80,113.62,-0.446
46.81,113.47,-0.446
46.83,113.32,-0.446
46.84,113.17,-0.446
46.86,113.02,-0.446
46.87,112.87,-0.446
46.89,112.73,-0.446
46.90,112.57,-0.445
46.92,112.42,-0.445
46.93,112.27,-0.445
46.95,112.12,-0.445
46.96,111.97,-0.445
46.98,111.82,-0.445
46.99,111.68,-0.445
47.01,111.52,-0.445
47.02,111.37,-0.445
47.04,111.22,-0.445
47.05,111.07,-0.444
47.07,110.93,-0.444
47.08,110.78,-0.444
47.10,110.63,-0.444
47.11,110.48,-0.444
47.13,110.33,-0.444
47.14,110.18,-0.444
47.16,110.03,-0.444
47.17,109.88,-0.444
47.19,109.73,-0.443
47.20,109.58,-0.443
47.22,109.43,-0.443
47.23,109.28,-0.443
47.25,109.13,-0.443
47.26,108.98,-0.443
47.28,108.83,-0.443
47.29,108.68,-0.443
47.31,108.53,-0.443
47.32,108.38,-0.442
47.34,108.23,-0.442
47.35,108.08,-0.442
47.37,107.93,-0.442
47.38,107.78,-0.442
47.40,107.63,-0.442
47.41,107.48,-0.442
47.43,107.33,-0.442
47.44,107.18,-0.442
47.46,107.03,-0.442
47.47,106.88,-0.442
47.49,106.73,-0.442
47.50,106.58,-0.442
47.52,106.43,-0.442
47.53,106.28,-0.441
47.55,106.13,-0.441
47.56,105.98,-0.441
47.58,105.83,-0.441
47.59,105.68,-0.441
47.61,105.53,-0.441
47.62,105.38,-0.441
47.64,105.23,-0.440
47.65,105.08,-0.440
47.67,104.93,-0.440
47.68,104.78,-0.440
47.70,104.63,-0.440
47.71,104.48,-0.440
47.73,104.33,-0.440
47.74,104.18,-0.440
47.76,104.03,-0.440
47.77,103.88,-0.440
47.79,103.73,-0.440
47.80,103.58,-0.439
47.82,103.43,-0.439
47.83,103.28,-0.439
47.85,103.13,-0.439
47.86,102.99,-0.439
47.88,102.84,-0.439
47.89,102.69,-0.439
47.91,102.54,-0.439
47.92,102.39,-0.439
47.94,102.24,-0.439
47.95,102.08,-0.438
47.97,101.94,-0.438
47.98,101.79,-0.438
48.00,101.64,-0.438
48.01,101.49,-0.438
48.03,101.34,-0.438
48.04,101.19,-0.438
48.06,101.04,-0.438
[...]
142.62,2.49,0.117
142.65,2.64,0.117
142.68,2.78,0.118
142.71,2.92,0.118
142.74,3.06,0.118
142.77,3.20,0.118
142.79,3.35,0.118
142.82,3.49,0.118
142.85,3.63,0.118
142.88,3.77,0.118
142.91,3.91,0.118
142.93,4.05,0.118
142.96,4.19,0.118
142.99,4.34,0.118
143.02,4.48,0.118
143.05,4.62,0.118
143.08,4.76,0.119
143.10,4.90,0.119
143.13,5.04,0.119
143.16,5.19,0.119
143.19,5.33,0.119
143.22,5.47,0.119
143.25,5.61,0.119
143.28,5.76,0.119
143.30,5.90,0.119
143.33,6.04,0.119
143.36,6.18,0.120
143.39,6.32,0.120
143.42,6.46,0.120
143.45,6.60,0.120
143.47,6.75,0.120
143.50,6.89,0.120
143.53,7.03,0.120
143.56,7.17,0.120
143.59,7.31,0.120
143.62,7.45,0.121
143.64,7.60,0.121
143.67,7.74,0.121
143.70,7.88,0.121
143.73,8.02,0.121
143.76,8.16,0.121
143.78,8.31,0.121
143.81,8.45,0.122
143.84,8.59,0.122
143.87,8.73,0.122
143.90,8.87,0.122
143.93,9.01,0.122
143.95,9.16,0.122
143.98,9.30,0.122
144.01,9.44,0.123
144.04,9.58,0.123
144.07,9.72,0.123
144.10,9.86,0.123
144.13,10.01,0.123
144.15,10.15,0.123
144.18,10.29,0.123
144.21,10.43,0.124
144.24,10.57,0.124
144.27,10.71,0.124
144.30,10.86,0.124
144.32,11.00,0.125
144.35,11.14,0.125
144.38,11.28,0.125
144.41,11.42,0.125
144.44,11.57,0.126
144.47,11.71,0.126
144.49,11.85,0.126
144.52,11.99,0.126
144.55,12.13,0.126
144.58,12.27,0.127
144.61,12.41,0.127
144.63,12.56,0.127
144.66,12.70,0.128
144.69,12.84,0.128
144.72,12.98,0.129
144.75,13.12,0.129
144.78,13.26,0.129
144.80,13.41,0.129
144.83,13.55,0.130
144.86,13.69,0.130
144.89,13.83,0.130
144.92,13.97,0.131
144.95,14.11,0.131
144.98,14.25,0.132
145.00,14.40,0.132
145.03,14.54,0.132
145.06,14.68,0.133
145.09,14.82,0.133
145.12,14.96,0.134
145.15,15.10,0.134
145.17,15.25,0.135
145.20,15.39,0.135
145.23,15.53,0.136
145.26,15.67,0.136
145.29,15.81,0.137
145.32,15.95,0.137
145.34,16.10,0.138
145.37,16.24,0.139
145.40,16.38,0.139
145.43,16.52,0.140
145.46,16.66,0.140
145.48,16.80,0.141
145.51,16.94,0.142
145.54,17.09,0.142
145.57,17.23,0.143
145.60,17.37,0.143
145.63,17.51,0.144
145.65,17.65,0.145
145.68,17.79,0.145
145.71,17.94,0.146
145.74,18.08,0.146
145.77,18.22,0.147
145.80,18.36,0.148
145.83,18.50,0.148
145.85,18.64,0.149
145.88,18.79,0.149
145.91,18.93,0.150
145.94,19.07,0.150
145.97,19.21,0.151
146.00,19.35,0.151
146.02,19.49,0.152
146.05,19.63,0.152
146.08,19.78,0.153
146.11,19.92,0.153
146.14,20.06,0.153
146.17,20.20,0.154
146.19,20.34,0.154
146.22,20.48,0.154
146.25,20.63,0.154
146.28,20.77,0.155
146.31,20.91,0.155
146.33,21.05,0.155
146.36,21.19,0.155
146.39,21.34,0.155
146.42,21.48,0.155
146.45,21.62,0.156
146.48,21.76,0.156
146.50,21.90,0.156
146.53,22.04,0.156
146.56,22.19,0.156
146.59,22.33,0.156
146.62,22.47,0.156
146.65,22.61,0.156
146.68,22.75,0.156
146.70,22.90,0.156
146.73,23.04,0.155
146.76,23.18,0.155
146.79,23.32,0.155
146.82,23.46,0.155
146.85,23.60,0.155
146.87,23.75,0.155
146.90,23.89,0.155
146.93,24.03,0.155
146.96,24.17,0.155
146.99,24.31,0.155
147.02,24.46,0.155
147.04,24.60,0.155
147.07,24.74,0.155
147.10,24.88,0.155
147.13,25.02,0.155
147.16,25.16,0.155
147.18,25.31,0.155
147.21,25.45,0.154
147.24,25.59,0.154
147.27,25.73,0.154
147.30,25.87,0.155
147.33,26.01,0.155
147.35,26.16,0.155
147.38,26.30,0.155
147.41,26.44,0.155
147.44,26.58,0.155
147.47,26.73,0.155
147.50,26.87,0.155
147.53,27.01,0.155
147.55,27.15,0.155
147.58,27.29,0.155
147.61,27.43,0.155
147.64,27.58,0.155
147.67,27.72,0.155
147.70,27.86,0.155
147.72,28.00,0.155
147.75,28.14,0.155
147.78,28.28,0.155
147.81,28.43,0.155
147.84,28.57,0.155
147.87,28.71,0.155
147.89,28.85,0.155
147.92,28.99,0.155
147.95,29.13,0.155
147.98,29.28,0.155
148.01,29.42,0.155
148.03,29.56,0.155
148.06,29.70,0.155
148.09,29.84,0.155
148.12,29.99,0.155
148.15,30.13,0.155
148.18,30.27,0.155
148.20,30.41,0.155
148.23,30.55,0.155
148.26,30.69,0.155
148.29,30.83,0.155
148.32,30.98,0.155
148.35,31.12,0.155
148.38,31.26,0.155
148.40,31.40,0.155
148.43,31.54,0.155
148.46,31.69,0.156
148.49,31.83,0.156
148.52,31.97,0.156
148.55,32.11,0.156
148.57,32.25,0.156
148.60,32.39,0.156
148.63,32.54,0.156
148.66,32.68,0.156
148.69,32.82,0.156
148.72,32.96,0.156
148.74,33.10,0.156
148.77,33.24,0.156
148.80,33.39,0.156
148.83,33.53,0.156
148.86,33.67,0.156
148.88,33.81,0.156
148.91,33.95,0.156
148.94,34.10,0.156
148.97,34.24,0.156
149.00,34.38,0.156
149.03,34.52,0.156
149.05,34.66,0.156
149.08,34.80,0.156
149.11,34.95,0.156
149.14,35.09,0.156
149.17,35.23,0.156
149.20,35.37,0.156
149.23,35.51,0.156
149.25,35.66,0.157
149.28,35.80,0.156
149.31,35.94,0.157
149.34,36.08,0.157
149.37,36.22,0.157
149.40,36.36,0.157
149.42,36.50,0.157
149.45,36.65,0.157
149.48,36.79,0.157
149.51,36.93,0.157
149.54,37.07,0.157
149.57,37.21,0.157
149.59,37.36,0.157
149.62,37.50,0.157
149.65,37.64,0.157
149.68,37.78,0.157
149.71,37.92,0.157
149.73,38.06,0.157
149.76,38.21,0.157
149.79,38.35,0.157
149.82,38.49,0.157
149.85,38.63,0.157
149.88,38.77,0.157
149.90,38.92,0.157
149.93,39.06,0.158
149.96,39.20,0.158
149.99,39.34,0.158
150.02,39.48,0.158
150.05,39.62,0.158
150.08,39.77,0.158
150.10,39.91,0.158
150.13,40.05,0.158
150.16,40.19,0.158
150.19,40.33,0.158
150.22,40.47,0.158
150.25,40.62,0.158
150.27,40.76,0.158
150.30,40.90,0.158
150.33,41.04,0.158
150.36,41.18,0.158
150.39,41.33,0.158
150.42,41.47,0.158
150.44,41.61,0.158
150.47,41.75,0.158
150.50,41.89,0.159
150.53,42.03,0.159
150.56,42.18,0.159
150.58,42.32,0.159
150.61,42.46,0.159
150.64,42.60,0.159
150.67,42.74,0.159
150.70,42.88,0.159
150.73,43.03,0.159
150.75,43.17,0.159
150.78,43.31,0.159
150.81,43.45,0.159
150.84,43.59,0.159
150.87,43.73,0.159
150.90,43.88,0.159
150.93,44.02,0.159
150.95,44.16,0.159
150.98,44.30,0.159
151.01,44.44,0.159
151.04,44.59,0.159
151.07,44.73,0.159
151.10,44.87,0.159
151.12,45.01,0.159
151.15,45.15,0.159
151.18,45.30,0.159
151.21,45.44,0.160
151.24,45.58,0.160
151.27,45.72,0.160
151.29,45.86,0.160
151.32,46.00,0.160
151.35,46.15,0.160
151.38,46.29,0.160
151.41,46.43,0.160
151.43,46.57,0.160
151.46,46.71,0.160
151.49,46.85,0.160
151.52,47.00,0.160
151.55,47.14,0.160
151.58,47.28,0.160
151.60,47.42,0.160
151.63,47.56,0.160
151.66,47.71,0.160
151.69,47.85,0.160
151.72,47.99,0.160
151.75,48.13,0.160
151.78,48.27,0.160
151.80,48.41,0.160
151.83,48.56,0.160
151.86,48.70,0.161
151.89,48.84,0.161
151.92,48.98,0.161
151.95,49.12,0.161
151.97,49.27,0.161
152.00,49.41,0.161
152.03,49.55,0.161
152.06,49.69,0.161
152.09,49.83,0.161
152.12,49.97,0.161
152.14,50.11,0.161
152.17,50.26,0.161
152.20,50.40,0.161
152.23,50.54,0.161
152.26,50.68,0.161
152.28,50.82,0.161
152.31,50.96,0.161
152.34,51.11,0.161
152.37,51.25,0.161
152.40,51.39,0.161
152.43,51.53,0.161
152.45,51.67,0.162
152.48,51.82,0.162
152.51,51.96,0.162
152.54,52.10,0.162
152.57,52.24,0.162
152.60,52.38,0.162
152.63,52.52,0.162
152.65,52.67,0.162
152.68,52.81,0.162
152.71,52.95,0.162
152.74,53.09,0.162
152.77,53.23,0.162
152.80,53.37,0.162
152.82,53.52,0.162
152.85,53.66,0.162
152.88,53.80,0.162
152.91,53.94,0.162
152.94,54.08,0.162
152.97,54.23,0.162
152.99,54.37,0.163
153.02,54.51,0.163
153.05,54.65,0.163
153.08,54.79,0.163
153.11,54.93,0.163
153.13,55.08,0.163
153.16,55.22,0.163
153.19,55.36,0.163
153.22,55.50,0.163
153.25,55.64,0.163
153.28,55.78,0.163
153.30,55.93,0.163
153.33,56.07,0.163
153.36,56.21,0.163
153.39,56.35,0.163
153.42,56.49,0.163
153.45,56.64,0.163
153.48,56.78,0.163
153.50,56.92,0.163
153.53,57.06,0.163
153.56,57.20,0.163
153.59,57.35,0.163
153.62,57.49,0.163
153.65,57.63,0.163
153.67,57.77,0.164
153.70,57.91,0.164
153.73,58.05,0.164
153.76,58.20,0.164
153.79,58.34,0.164
153.82,58.48,0.164
153.84,58.62,0.164
153.87,58.76,0.164
153.90,58.90,0.164
153.93,59.05,0.164
153.96,59.19,0.164
153.98,59.33,0.164
154.01,59.47,0.164
154.04,59.61,0.164
154.07,59.75,0.164
154.10,59.90,0.164
154.13,60.04,0.164
154.15,60.18,0.164
154.18,60.32,0.164
154.21,60.46,0.164
154.24,60.61,0.164
154.27,60.75,0.164
154.30,60.89,0.164
154.33,61.03,0.164
154.35,61.17,0.165
154.38,61.31,0.165
154.41,61.46,0.165
154.44,61.60,0.165
154.47,61.74,0.165
154.50,61.88,0.165
154.52,62.02,0.165
154.55,62.16,0.165
154.58,62.31,0.165
154.61,62.45,0.165
154.64,62.59,0.165
154.67,62.73,0.165
154.69,62.87,0.165
154.72,63.01,0.165
154.75,63.16,0.165
154.78,63.30,0.165
154.81,63.44,0.165
154.83,63.58,0.165
154.86,63.72,0.165
154.89,63.87,0.165
154.92,64.01,0.165
154.95,64.15,0.165
154.98,64.29,0.165
155.00,64.43,0.165
155.03,64.57,0.165
155.06,64.72,0.166
155.09,64.86,0.166
155.12,65.00,0.166
155.15,65.14,0.166
155.18,65.28,0.166
155.20,65.42,0.166
155.23,65.57,0.166
155.26,65.71,0.166
155.29,65.85,0.166
155.32,65.99,0.166
155.35,66.13,0.166
155.37,66.28,0.166
155.40,66.42,0.166
155.43,66.56,0.166
155.46,66.70,0.166
155.49,66.84,0.166
155.52,66.99,0.166
155.54,67.13,0.166
155.57,67.27,0.166
155.60,67.41,0.166
155.63,67.55,0.166
155.66,67.70,0.166
155.68,67.84,0.166
155.71,67.98,0.166
155.74,68.12,0.166
155.77,68.26,0.166
155.80,68.40,0.166
155.83,68.55,0.166
155.85,68.69,0.166
155.88,68.83,0.166
155.91,68.97,0.166
155.94,69.11,0.166
155.97,69.25,0.166
156.00,69.40,0.166
156.03,69.54,0.166
156.05,69.68,0.166
156.08,69.82,0.166
156.11,69.96,0.166
156.14,70.10,0.167
156.17,70.24,0.167
156.20,70.39,0.167
156.22,70.53,0.167
156.25,70.67,0.167
156.28,70.81,0.167
156.31,70.95,0.167
156.34,71.09,0.167
156.37,71.24,0.167
156.39,71.38,0.167
156.42,71.52,0.167
156.45,71.66,0.167
156.48,71.80,0.167
156.51,71.94,0.167
156.53,72.09,0.167
156.56,72.23,0.167
156.59,72.37,0.167
156.62,72.51,0.168
156.65,72.65,0.168
156.68,72.79,0.168
156.70,72.94,0.168
156.73,73.08,0.168
156.76,73.22,0.168
156.79,73.36,0.168
156.82,73.50,0.168
156.85,73.65,0.168
156.88,73.79,0.168
156.90,73.93,0.168
156.93,74.07,0.168
156.96,74.21,0.168
156.99,74.35,0.168
157.02,74.50,0.168
157.05,74.64,0.168
157.07,74.78,0.168
157.10,74.92,0.168
157.13,75.06,0.168
157.16,75.20,0.168
157.19,75.35,0.169
157.22,75.49,0.169
157.24,75.63,0.169
157.27,75.77,0.169
157.30,75.91,0.169
157.33,76.05,0.169
157.36,76.20,0.169
157.38,76.34,0.169
157.41,76.48,0.169
157.44,76.62,0.170
157.47,76.76,0.170
157.50,76.90,0.170
157.53,77.05,0.170
157.55,77.19,0.170
157.58,77.33,0.170
157.61,77.47,0.170
157.64,77.61,0.170
157.67,77.76,0.170
157.70,77.90,0.170
157.73,78.04,0.170
157.75,78.18,0.170
157.78,78.32,0.170
157.81,78.46,0.170
157.84,78.61,0.170
157.87,78.75,0.170
157.90,78.89,0.171
157.92,79.03,0.171
157.95,79.17,0.171
157.98,79.31,0.171
158.01,79.46,0.171
158.04,79.60,0.171
158.07,79.74,0.171
158.09,79.88,0.171
158.12,80.02,0.171
158.15,80.16,0.171
158.18,80.31,0.171
158.21,80.45,0.171
158.23,80.59,0.171
158.26,80.73,0.171
158.29,80.87,0.171
158.32,81.01,0.171
158.35,81.16,0.171
158.38,81.30,0.172
158.40,81.44,0.172
158.43,81.58,0.172
158.46,81.72,0.172
158.49,81.86,0.172
158.52,82.01,0.172
158.55,82.15,0.172
158.58,82.29,0.172
158.60,82.43,0.172
158.63,82.57,0.172
158.66,82.72,0.172
158.69,82.86,0.172
158.72,83.00,0.172
158.75,83.14,0.172
158.77,83.28,0.172
158.80,83.43,0.172
158.83,83.57,0.173
158.86,83.71,0.173
158.89,83.85,0.173
158.92,83.99,0.173
158.94,84.13,0.173
158.97,84.27,0.173
159.00,84.42,0.173
159.03,84.56,0.173
159.06,84.70,0.173
159.08,84.84,0.173
159.11,84.98,0.173
159.14,85.12,0.173
159.17,85.27,0.173
159.20,85.41,0.173
159.23,85.55,0.173
159.25,85.69,0.173
159.28,85.83,0.173
159.31,85.98,0.173
159.34,86.12,0.173
159.37,86.26,0.173
159.40,86.40,0.173
159.43,86.54,0.173
159.45,86.68,0.173
159.48,86.83,0.173
159.51,86.97,0.173
159.54,87.11,0.173
159.57,87.25,0.173
159.60,87.39,0.173
159.62,87.54,0.173
159.65,87.68,0.173
159.68,87.82,0.173
159.71,87.96,0.173
159.74,88.10,0.173
159.77,88.24,0.173
159.79,88.38,0.173
159.82,88.53,0.173
159.85,88.67,0.173
159.88,88.81,0.173
159.91,88.95,0.173
159.93,89.09,0.173
159.96,89.24,0.173
159.99,89.38,0.173
160.02,89.52,0.173
160.05,89.66,0.173
160.08,89.80,0.173
160.10,89.94,0.174
160.13,90.09,0.174
160.16,90.23,0.174
160.19,90.37,0.174
160.22,90.51,0.174
160.25,90.65,0.174
160.28,90.80,0.174
160.30,90.94,0.174
160.33,91.08,0.174
160.36,91.22,0.174
160.39,91.36,0.174
160.42,91.50,0.174
160.45,91.65,0.174
160.47,91.79,0.174
160.50,91.93,0.174
160.53,92.07,0.174
160.56,92.21,0.174
160.59,92.35,0.174
160.62,92.50,0.174
160.64,92.64,0.174
160.67,92.78,0.174
160.70,92.92,0.175
160.73,93.06,0.175
160.76,93.20,0.175
160.78,93.35,0.175
160.81,93.49,0.175
160.84,93.63,0.175
160.87,93.77,0.175
160.90,93.91,0.175
160.93,94.05,0.175
160.95,94.19,0.175
160.98,94.34,0.175
161.01,94.48,0.175
161.04,94.62,0.175
161.07,94.76,0.175
161.10,94.90,0.175
161.13,95.05,0.176
161.15,95.19,0.176
161.18,95.33,0.176
161.21,95.47,0.176
161.24,95.61,0.176
161.27,95.76,0.176
161.30,95.90,0.176
161.32,96.04,0.176
161.35,96.18,0.176
161.38,96.32,0.176
161.41,96.46,0.176
161.44,96.61,0.176
161.47,96.75,0.176
161.49,96.89,0.176
161.52,97.03,0.176
161.55,97.17,0.176
161.58,97.31,0.176
161.61,97.46,0.176
161.63,97.60,0.176
161.66,97.74,0.176
161.69,97.88,0.176
161.72,98.02,0.176
161.75,98.16,0.177
161.78,98.31,0.177
161.80,98.45,0.177
161.83,98.59,0.177
161.86,98.73,0.177
161.89,98.87,0.177
161.92,99.02,0.177
161.95,99.16,0.177
161.98,99.30,0.177
162.00,99.44,0.177
162.03,99.58,0.177
162.06,99.72,0.177
162.09,99.87,0.177
162.12,100.01,0.177
162.15,100.15,0.177
162.17,100.29,0.177
162.20,100.43,0.177
162.23,100.57,0.177
162.26,100.72,0.177
162.29,100.86,0.177
162.32,101.00,0.177
162.34,101.14,0.177
162.37,101.28,0.177
162.40,101.42,0.178
162.43,101.56,0.178
162.46,101.71,0.178
162.48,101.85,0.178
162.51,101.99,0.178
162.54,102.13,0.178
162.57,102.27,0.178
162.60,102.42,0.178
162.63,102.56,0.178
162.65,102.70,0.178
162.68,102.84,0.178
162.71,102.98,0.178
162.74,103.13,0.178
162.77,103.27,0.178
162.80,103.41,0.178
162.83,103.55,0.178
162.85,103.69,0.178
162.88,103.83,0.178
162.91,103.98,0.178
162.94,104.12,0.179
162.97,104.26,0.179
163.00,104.40,0.179
163.02,104.54,0.179
163.05,104.68,0.179
163.08,104.83,0.179
163.11,104.97,0.179
163.14,105.11,0.179
163.17,105.25,0.179
163.19,105.39,0.179
163.22,105.53,0.179
163.25,105.68,0.179
163.28,105.82,0.179
163.31,105.96,0.179
163.33,106.10,0.179
163.36,106.24,0.179
163.39,106.39,0.179
163.42,106.53,0.179
163.45,106.67,0.179
163.48,106.81,0.179
163.50,106.95,0.180
163.53,107.09,0.180
163.56,107.24,0.180
163.59,107.38,0.180
163.62,107.52,0.180
163.65,107.66,0.180
163.68,107.80,0.180
163.70,107.95,0.180
163.73,108.09,0.180
163.76,108.23,0.180
163.79,108.37,0.180
163.82,108.51,0.180
163.85,108.65,0.180
163.87,108.79,0.180
163.90,108.94,0.180
163.93,109.08,0.180
163.96,109.22,0.180
163.99,109.36,0.180
164.02,109.50,0.180
164.04,109.64,0.180
164.07,109.79,0.180
164.10,109.93,0.180
164.13,110.07,0.180
164.16,110.21,0.180
164.18,110.35,0.180
164.21,110.49,0.180
164.24,110.64,0.181
164.27,110.78,0.181
164.30,110.92,0.181
164.33,111.06,0.181
164.35,111.20,0.181
164.38,111.35,0.181
164.41,111.49,0.181
164.44,111.63,0.181
164.47,111.77,0.181
164.50,111.91,0.181
164.53,112.05,0.181
164.55,112.19,0.181
164.58,112.34,0.181
164.61,112.48,0.181
164.64,112.62,0.181
164.67,112.76,0.181
164.70,112.90,0.181
164.72,113.04,0.181
164.75,113.19,0.181
164.78,113.33,0.182
164.81,113.47,0.182
164.84,113.61,0.182
164.87,113.75,0.182
164.89,113.90,0.182
164.92,114.04,0.182
164.95,114.18,0.182
164.98,114.32,0.182
165.01,114.46,0.182
165.03,114.60,0.182
165.06,114.75,0.182
165.09,114.89,0.182
165.12,115.03,0.182
165.15,115.17,0.182
165.18,115.31,0.182
165.20,115.45,0.182
165.23,115.60,0.182
165.26,115.74,0.182
165.29,115.88,0.182
165.32,116.02,0.182
165.35,116.16,0.182
165.38,116.30,0.182
165.40,116.45,0.182
165.43,116.59,0.183
165.46,116.73,0.183
165.49,116.87,0.183
165.52,117.01,0.183
165.55,117.16,0.183
165.57,117.30,0.183
165.60,117.44,0.183
165.63,117.58,0.183
165.66,117.72,0.183
165.69,117.86,0.183
165.72,118.01,0.183
165.74,118.15,0.183
165.77,118.29,0.183
165.80,118.43,0.183
165.83,118.57,0.183
165.86,118.71,0.183
165.88,118.86,0.184
165.91,119.00,0.184
165.94,119.14,0.184
165.97,119.28,0.184
166.00,119.42,0.184
166.03,119.56,0.184
166.05,119.71,0.184
166.08,119.85,0.184
166.11,119.99,0.184
166.14,120.13,0.184
166.17,120.27,0.184
166.20,120.42,0.184
166.23,120.56,0.184
166.25,120.70,0.184
166.28,120.84,0.184
166.31,120.98,0.184
166.34,121.12,0.184
166.37,121.27,0.184
166.40,121.41,0.184
166.42,121.55,0.184
166.45,121.69,0.184
166.48,121.83,0.184
166.51,121.97,0.185
166.54,122.12,0.185
166.57,122.26,0.185
166.59,122.40,0.185
166.62,122.54,0.185
166.65,122.68,0.185
166.68,122.83,0.185
166.71,122.97,0.185
166.73,123.11,0.185
166.76,123.25,0.185
166.79,123.39,0.185
166.82,123.53,0.185
166.85,123.67,0.185
166.88,123.82,0.185
166.90,123.96,0.185
166.93,124.10,0.185
166.96,124.24,0.185
166.99,124.38,0.185
167.02,124.52,0.185
167.05,124.67,0.185
167.08,124.81,0.185
167.10,124.95,0.185
167.13,125.09,0.185
167.16,125.23,0.185
167.19,125.37,0.186
167.22,125.52,0.186
167.25,125.66,0.186
167.27,125.80,0.186
167.30,125.94,0.186
167.33,126.08,0.186
167.36,126.22,0.186
167.39,126.37,0.186
167.42,126.51,0.186
167.44,126.65,0.186
167.47,126.79,0.186
167.50,126.93,0.186
167.53,127.07,0.186
167.56,127.22,0.186
167.58,127.36,0.186
167.61,127.50,0.186
167.64,127.64,0.186
167.67,127.78,0.187
167.70,127.92,0.187
167.73,128.07,0.187
167.75,128.21,0.187
167.78,128.35,0.187
167.81,128.49,0.187
167.84,128.63,0.187
167.87,128.77,0.187
167.90,128.92,0.187
167.93,129.06,0.187
167.95,129.20,0.187
167.98,129.34,0.187
168.01,129.48,0.187
168.04,129.63,0.187
168.07,129.77,0.187
168.10,129.91,0.187
168.12,130.05,0.188
168.15,130.19,0.188
168.18,130.34,0.188
168.21,130.48,0.188
168.24,130.62,0.188
168.27,130.76,0.188
168.29,130.90,0.188
168.32,131.04,0.188
168.35,131.18,0.188
168.38,131.33,0.188
168.41,131.47,0.188
168.43,131.61,0.188
168.46,131.75,0.188
168.49,131.89,0.188
168.52,132.03,0.188
168.55,132.18,0.188
168.58,132.32,0.188
168.60,132.46,0.188
168.63,132.60,0.188
168.66,132.74,0.188
168.69,132.89,0.188
168.72,133.03,0.188
168.75,133.17,0.188
168.78,133.31,0.188
168.80,133.45,0.188
168.83,133.59,0.188
168.86,133.74,0.188
168.89,133.88,0.188
168.92,134.02,0.188
168.95,134.16,0.189
168.97,134.30,0.189
169.00,134.44,0.189
169.03,134.59,0.189
169.06,134.73,0.189
169.09,134.87,0.189
169.12,135.01,0.189
169.14,135.15,0.189
169.17,135.29,0.189
169.20,135.44,0.189
169.23,135.58,0.189
169.26,135.72,0.189
169.28,135.86,0.189
169.31,136.00,0.189
169.34,136.14,0.189
169.37,136.29,0.189
169.40,136.43,0.190
169.43,136.57,0.190
169.45,136.71,0.190
169.48,136.85,0.190
169.51,137.00,0.190
169.54,137.14,0.190
169.57,137.28,0.190
169.60,137.42,0.190
169.63,137.56,0.190
169.65,137.71,0.190
169.68,137.85,0.190
169.71,137.99,0.190
169.74,138.13,0.190
169.77,138.27,0.190
169.80,138.41,0.190
169.82,138.56,0.190
169.85,138.70,0.190
169.88,138.84,0.190
169.91,138.98,0.190
169.94,139.12,0.190
169.97,139.26,0.190
169.99,139.40,0.190
170.02,139.54,0.191
170.05,139.69,0.191
170.08,139.83,0.191
170.11,139.97,0.191
170.13,140.11,0.191
170.16,140.25,0.191
170.19,140.39,0.191
170.22,140.54,0.191
170.25,140.68,0.191
170.28,140.82,0.191
170.30,140.96,0.191
170.33,141.10,0.191
170.36,141.24,0.191
170.39,141.39,0.191
170.42,141.53,0.191
170.45,141.67,0.191
170.48,141.81,0.192
170.50,141.95,0.192
170.53,142.10,0.192
170.56,142.24,0.192
170.59,142.38,0.192
170.62,142.52,0.192
170.65,142.66,0.192
170.67,142.80,0.192
170.70,142.95,0.192
170.73,143.09,0.192
170.76,143.23,0.192
170.79,143.37,0.192
170.82,143.51,0.192
170.84,143.66,0.193
170.87,143.80,0.193
170.90,143.94,0.193
170.93,144.08,0.193
170.96,144.22,0.193
170.98,144.36,0.193
171.01,144.50,0.193
171.04,144.65,0.193
171.07,144.79,0.193
171.10,144.93,0.193
171.13,145.07,0.193
171.15,145.21,0.193
171.18,145.36,0.193
171.21,145.50,0.193
171.24,145.64,0.193
171.27,145.78,0.194
171.30,145.92,0.194
171.33,146.07,0.194
171.35,146.21,0.194
171.38,146.35,0.194
171.41,146.49,0.194
171.44,146.63,0.194
171.47,146.77,0.194
171.50,146.91,0.194
171.52,147.06,0.194
171.55,147.20,0.194
171.58,147.34,0.194
171.61,147.48,0.194
171.64,147.62,0.194
171.67,147.76,0.194
171.69,147.90,0.195
171.72,148.05,0.195
171.75,148.19,0.195
171.78,148.33,0.195
171.81,148.47,0.195
171.83,148.61,0.195
171.86,148.76,0.195
171.89,148.90,0.195
171.92,149.04,0.195
171.95,149.18,
171.98,,
171.98,,