File: DSC/2025_06_03_Nifedipine2_0C_195C_10Cmin_x3.csv
Filename,2025_06_03_Nifedipine2_0C_195C_10Cmin_x3
Instrument name,DSC2A-00468 (192.168.1.100)
Operator,Yarger
rundate,6/3/2025
Sample name,2025_06_03_Nifedipine2_0C_195C_10Cmin_x3
proceduresegments,Data Off ; Equilibrate 0.00 °C; Data On ; Ramp 10.00 °C/min to 195.00 °C; Data Off ; Isothermal 1.0 min; Data On ; Ramp 10.00 °C/min to 0.00 °C; Data Off ; Isothermal 1.0 min; Data On ; Ramp 10.00 °C/min to 195.00 °C; Data Off ; Isothermal 1.0 min; Data On ; Ramp 10.00 °C/min to 0.00 °C; Data Off ; Isothermal 1.0 min; Data On ; Ramp 10.00 °C/min to 30.00 °C
[File Parameters]
Run date,6/3/2025 2:22:01 PM
Trios version,5.1.1.46572
Original File Name,
Current File Name,D:\DSC2500\JYarger\2025_06_03_Nifedipine2_0C_195C_10Cmin_x3.tri
[Procedure]
Procedure Name,NIF_0C_195C_10Cmin_x3
Sample Name,2025_06_03_Nifedipine2_0C_195C_10Cmin_x3
Sample Mass,25.9 mg
Reference Sample Mass,0 mg
Pan Mass,55.92 mg
Pan Number,23
Reference Pan Mass,55.79 mg
Reference Pan Number,1
Pan Type,Tzero Aluminum Hermetic
Comments,Al Hermetic DSC Consumables sealed Pan/Lid. A2 Tray (Google Sheet: DSC_Samples_A2_Tray_May2025)
Project Name,CA
Operator,Yarger
Test,Custom
Unload Max Temperature,30
Unload Min Temperature,30
Load Max Temperature,30
Load Min Temperature,30
Stop on Gas Flow Error,Yes
[Signal List]
Signal #1,Time (min)
Signal #2,Temperature (°C)
Signal #3,Heat Flow (mW)
Signal #4,Delta T (µV)
Signal #5,Delta Tzero (µV)
Signal #6,Tzero Temperature (°C)
Signal #7,Cell Purge (mL/min)
Signal #8,Heater Temp (°C)
Signal #9,Power Delivered (W)
Signal #10,Reference Junction Temperature (°C)
Signal #11,Flange Temperature (°C)
Signal #12,Heat Flow Phase (rad)
Signal #13,Total Heat Capacity (J/°C)
Signal #14,Heat Capacity (J/°C)
[Configuration]
Company Name,ASU
Instrument Name,DSC2A-00468
Instrument Type,DSC2500
Serial Number,DSC2A-00468
IP,192.168.1.100
Location of Instrument,MRRC
DisplayType,Unknown
Sample Interval ,0.1 s/pt
Selected Heat Flow,T4P
Exotherm Direction,Down
Cell Serial,DRC2-00792
Lid Type,Standard
Cooler,RCS 90
Leave Cooler on at End of Sequence,On
Gas 2,Nitrogen
Gas Selected,Channel 1
Flow Rate,50 mL/min
Secondary Purge,On
Licensed Heat Flow,Heat Flow T4P
Modulation Licensed,Yes
[Versions]
Common IDD Version,1
Cortex Version,VER 2.10.2.31
Driver,5.0.0.6
GDM Version,1.0.3.3
TouchscreenVersion,1.0.0.16145
FEP Version,1.2.1.21
FEP Bootloader,2.0.0.5
AutoSampler Version,2.1.1.26
Auto Sampler Bootloader,2.0.0.5
FCM Version,1.1.0.3
FCM Bootloader,2.0.0.5
[Experiment Logs]
Experiment Log Entry # 1,Data On set to 0
Experiment Log Entry # 3,Equilibrate Segment 0 (C) Started
Experiment Log Entry # 5,Air Cool is off.
Experiment Log Entry # 7,Data On set to 1
Experiment Log Entry # 9,Ramp Segment 10 C/min to 195 Started
Experiment Log Entry # 11,Data On set to 0
Experiment Log Entry # 13,Isothermal Segment 1 min started
Experiment Log Entry # 15,Data On set to 1
Experiment Log Entry # 17,Ramp Segment 10 C/min to 0 Started
Experiment Log Entry # 19,Data On set to 0
Experiment Log Entry # 21,Isothermal Segment 1 min started
Experiment Log Entry # 23,Data On set to 1
Experiment Log Entry # 25,Ramp Segment 10 C/min to 195 Started
Experiment Log Entry # 27,Data On set to 0
Experiment Log Entry # 29,Isothermal Segment 1 min started
Experiment Log Entry # 31,Data On set to 1
Experiment Log Entry # 33,Ramp Segment 10 C/min to 0 Started
Experiment Log Entry # 35,Data On set to 0
Experiment Log Entry # 37,Isothermal Segment 1 min started
Experiment Log Entry # 39,Data On set to 1
Experiment Log Entry # 41,Ramp Segment 10 C/min to 30 Started
[Method Log]
Method Log Entry # 1,Data Off
Method Log Entry # 2,Equilibrate 0 °C
Method Log Entry # 3,Data On
Method Log Entry # 4,(Ramp 877155) Ramp 10 °C/minute to 195 °C
Method Log Entry # 5,Data Off
Method Log Entry # 6,Isothermal 1 minutes
Method Log Entry # 7,Data On
Method Log Entry # 8,(Ramp 877159) Ramp 10 °C/minute to 0 °C
Method Log Entry # 9,Data Off
Method Log Entry # 10,Isothermal 1 minutes
Method Log Entry # 11,Data On
Method Log Entry # 12,(Ramp 877163) Ramp 10 °C/minute to 195 °C
Method Log Entry # 13,Data Off
Method Log Entry # 14,Isothermal 1 minutes
Method Log Entry # 15,Data On
Method Log Entry # 16,(Ramp 877167) Ramp 10 °C/minute to 0 °C
Method Log Entry # 17,Data Off
Method Log Entry # 18,Isothermal 1 minutes
Method Log Entry # 19,Data On
Method Log Entry # 20,(Ramp 877171) Ramp 10 °C/minute to 30 °C
Cell Serial,DRC2-00792
[T1 Calibration]
Slope,-0.008529666
Offset,9.636258
Initial Temperature,98.23
GUID,f8bfdadc-4977-4fdf-ba6d-0ba9134940c3
[TZero Calibration]
Date Applied,11/29/2022 4:06:13 PM
Description,From -89.059 °C to 396.009 °C at 20.000°C/min
Gas Type,Nitrogen
Pan Type,None
Source Files 1,C:\Users\yargerlab\Desktop\DSC Data\General\TZero_calibration_11_29_22_2nd(2).tri
Source Files 2,C:\Users\yargerlab\Desktop\DSC Data\General\TZero_calibration_11_29_22_2nd(3).tri
Delta T Offset,13.05235
Delta T Slope,-0.007271007
Delta T0 Offset,-13.69128
Delta T0 Slope,0.06063341
[Temperature Calibration]
Date Applied,11/29/2022 7:12:28 PM
Description,From 106.590 °C to 186.590 °C at 10.000°C/min
Gas Type,Nitrogen
Pan Type,Tzero Aluminum Hermetic
Source Files 1,C:\Users\yargerlab\Desktop\DSC Data\General\Indium(6).tri
Measured 1,157.391
Known 1,156.598
[Cell Constant Calibration]
Date Applied,11/29/2022 7:12:29 PM
Description,From 106.590 °C to 186.590 °C at 10.000°C/min
Gas Type,Nitrogen
Pan Type,Tzero Aluminum Hermetic
Source Files 1,C:\Users\yargerlab\Desktop\DSC Data\General\Indium(6).tri
T4P KCell,1.006051
Onset Slope,63.26126 mW/°C
[Direct Cp Calibration]
Date Applied,11/30/2022 11:04:51 AM
Description,From -79.983 °C to 298.409 °C at 10.000°C/min
Gas Type,Nitrogen
Pan Type,Tzero Aluminum Hermetic
Source Files 1,C:\Users\yargerlab\Desktop\DSC Data\General\Sapphire_Heat_Capacity_11_30_22.tri
[Rev Cp Calibration]
Date Applied,11/30/2022 1:58:51 PM
Description,From -79.996 °C to 292.812 °C at 3.000°C/min
Gas Type,Nitrogen
Pan Type,Tzero Aluminum Hermetic
Source Files 1,C:\Users\yargerlab\Desktop\DSC Data\General\Sapphire_MDSC_Calibration_11_30_22.tri
[step]
Ramp 10.00 °C/min to 195.00 °C
Time,Temperature,Heat Flow (Normalized)
min,°C,W/g
0.00,0.20,-0.043
0.01,0.20,-0.042
0.03,0.19,-0.040
0.04,0.18,-0.037
0.05,0.19,-0.034
0.07,0.19,-0.033
0.08,0.20,-0.032
0.09,0.23,-0.031
0.11,0.26,-0.029
0.12,0.31,-0.025
0.13,0.36,-0.019
0.15,0.43,-0.011
0.16,0.50,-0.001
0.17,0.58,0.010
0.19,0.66,0.021
0.20,0.74,0.032
0.21,0.83,0.042
0.23,0.92,0.051
0.24,1.01,0.060
0.25,1.11,0.068
0.27,1.21,0.076
0.28,1.31,0.083
0.29,1.42,0.090
0.31,1.52,0.096
0.32,1.63,0.102
0.33,1.74,0.108
0.35,1.85,0.113
0.36,1.96,0.118
0.37,2.08,0.122
0.39,2.19,0.127
0.40,2.31,0.130
0.41,2.43,0.134
0.43,2.55,0.137
0.44,2.67,0.141
0.45,2.79,0.143
0.47,2.91,0.146
0.48,3.03,0.149
0.49,3.16,0.151
0.51,3.28,0.153
0.52,3.40,0.155
0.53,3.53,0.157
0.55,3.65,0.159
0.56,3.78,0.160
0.57,3.91,0.162
0.59,4.04,0.163
0.60,4.16,0.165
0.61,4.29,0.166
0.63,4.42,0.167
0.64,4.55,0.168
0.65,4.68,0.169
0.67,4.80,0.170
0.68,4.93,0.171
0.69,5.06,0.171
0.71,5.19,0.172
0.72,5.32,0.173
0.73,5.45,0.173
0.75,5.58,0.174
0.76,5.71,0.175
0.77,5.84,0.175
0.79,5.97,0.176
0.80,6.10,0.176
0.81,6.24,0.176
0.83,6.37,0.177
0.84,6.50,0.177
0.85,6.63,0.177
0.87,6.76,0.178
0.88,6.89,0.178
0.89,7.02,0.179
0.91,7.16,0.179
0.92,7.29,0.179
0.93,7.42,0.179
0.95,7.55,0.179
0.96,7.68,0.180
0.97,7.81,0.180
0.99,7.95,0.180
1.00,8.08,0.180
1.01,8.21,0.180
1.03,8.34,0.181
1.04,8.47,0.181
1.05,8.61,0.181
1.07,8.74,0.181
1.08,8.87,0.181
1.09,9.01,0.181
1.11,9.14,0.182
1.12,9.27,0.182
1.13,9.40,0.182
1.15,9.53,0.182
1.16,9.67,0.182
1.17,9.80,0.182
1.19,9.93,0.182
1.20,10.06,0.182
1.21,10.20,0.183
1.23,10.33,0.183
1.24,10.46,0.183
1.25,10.60,0.183
1.27,10.73,0.183
1.28,10.86,0.183
1.29,10.99,0.183
1.31,11.13,0.183
1.32,11.26,0.183
1.33,11.39,0.184
1.35,11.53,0.184
1.36,11.66,0.184
1.37,11.79,0.184
1.39,11.93,0.184
1.40,12.06,0.184
1.41,12.19,0.184
1.43,12.32,0.184
1.44,12.46,0.184
1.45,12.59,0.184
1.47,12.72,0.185
1.48,12.86,0.185
1.49,12.99,0.185
1.51,13.12,0.185
1.52,13.26,0.185
1.53,13.39,0.185
1.55,13.52,0.185
1.56,13.66,0.185
1.57,13.79,0.185
1.59,13.92,0.185
1.60,14.06,0.185
1.61,14.19,0.185
1.63,14.32,0.185
1.64,14.46,0.186
1.65,14.59,0.186
1.67,14.72,0.186
1.68,14.85,0.186
1.69,14.99,0.186
1.71,15.12,0.186
1.72,15.25,0.186
1.73,15.39,0.186
1.75,15.52,0.186
1.76,15.65,0.186
1.77,15.79,0.186
1.79,15.92,0.186
1.80,16.05,0.186
1.81,16.19,0.187
1.83,16.32,0.187
1.84,16.46,0.187
1.85,16.59,0.187
1.87,16.72,0.187
1.88,16.85,0.187
1.89,16.99,0.187
1.91,17.12,0.187
1.92,17.25,0.187
1.93,17.39,0.187
1.95,17.52,0.187
1.96,17.65,0.187
1.97,17.79,0.188
1.99,17.92,0.188
2.00,18.05,0.188
2.01,18.19,0.188
2.03,18.32,0.188
2.04,18.46,0.188
2.05,18.59,0.188
2.07,18.72,0.188
2.08,18.86,0.188
2.09,18.99,0.188
2.11,19.12,0.188
2.12,19.25,0.188
2.13,19.39,0.188
2.15,19.52,0.188
2.16,19.66,0.189
2.17,19.79,0.189
2.19,19.92,0.189
2.20,20.06,0.189
2.21,20.19,0.189
2.23,20.32,0.189
2.24,20.46,0.189
2.25,20.59,0.189
2.27,20.72,0.189
2.28,20.86,0.189
2.29,20.99,0.189
2.31,21.12,0.189
2.32,21.26,0.189
2.33,21.39,0.190
2.35,21.52,0.190
2.36,21.66,0.190
2.37,21.79,0.190
2.39,21.92,0.190
2.40,22.06,0.190
2.41,22.19,0.190
2.43,22.32,0.190
2.44,22.46,0.190
2.45,22.59,0.190
2.47,22.73,0.190
2.48,22.86,0.190
2.49,22.99,0.190
2.51,23.12,0.190
2.52,23.26,0.191
2.53,23.39,0.191
2.55,23.53,0.191
2.56,23.66,0.191
2.57,23.79,0.191
2.59,23.93,0.191
2.60,24.06,0.191
2.61,24.19,0.191
2.63,24.33,0.191
2.64,24.46,0.191
2.65,24.59,0.191
2.67,24.73,0.191
2.68,24.86,0.191
2.69,24.99,0.191
2.71,25.13,0.191
2.72,25.26,0.192
2.73,25.39,0.192
2.75,25.53,0.192
2.76,25.66,0.192
2.77,25.79,0.192
2.79,25.93,0.192
2.80,26.06,0.192
2.81,26.19,0.192
2.83,26.33,0.192
2.84,26.46,0.192
2.85,26.59,0.192
2.87,26.73,0.192
2.88,26.86,0.192
2.89,26.99,0.193
2.91,27.13,0.193
2.92,27.26,0.193
2.93,27.39,0.193
2.95,27.53,0.193
2.96,27.66,0.193
2.97,27.79,0.193
2.99,27.93,0.193
3.00,28.06,0.193
3.01,28.19,0.193
3.03,28.33,0.193
3.04,28.46,0.193
3.05,28.60,0.193
3.07,28.73,0.193
3.08,28.86,0.194
3.09,29.00,0.194
3.11,29.13,0.194
3.12,29.26,0.194
3.13,29.40,0.194
3.15,29.53,0.194
3.16,29.66,0.194
3.17,29.80,0.194
3.19,29.93,0.194
3.20,30.06,0.194
3.21,30.20,0.194
3.23,30.33,0.194
3.24,30.46,0.194
3.25,30.60,0.194
3.27,30.73,0.194
3.28,30.86,0.195
3.29,31.00,0.195
3.31,31.13,0.195
3.32,31.26,0.195
3.33,31.40,0.195
3.35,31.53,0.195
3.36,31.67,0.195
3.37,31.80,0.195
3.39,31.93,0.195
3.40,32.06,0.195
3.41,32.20,0.195
3.43,32.33,0.195
3.44,32.47,0.195
3.45,32.60,0.195
3.47,32.73,0.195
3.48,32.87,0.196
3.49,33.00,0.196
3.51,33.13,0.196
3.52,33.27,0.196
3.53,33.40,0.196
3.55,33.53,0.196
3.56,33.67,0.196
3.57,33.80,0.196
3.59,33.93,0.196
3.60,34.07,0.196
3.61,34.20,0.196
3.63,34.33,0.196
3.64,34.47,0.196
3.65,34.60,0.196
3.67,34.74,0.196
3.68,34.87,0.197
3.69,35.00,0.197
3.71,35.13,0.197
3.72,35.27,0.197
3.73,35.40,0.197
3.75,35.53,0.197
3.76,35.67,0.197
3.77,35.80,0.197
3.79,35.94,0.197
3.80,36.07,0.197
3.81,36.20,0.197
3.83,36.34,0.197
3.84,36.47,0.197
3.85,36.60,0.197
3.87,36.74,0.197
3.88,36.87,0.197
3.89,37.00,0.198
3.91,37.14,0.198
3.92,37.27,0.198
3.93,37.40,0.198
3.95,37.54,0.198
3.96,37.67,0.198
3.97,37.80,0.198
3.99,37.94,0.198
4.00,38.07,0.198
4.01,38.20,0.198
4.03,38.34,0.198
4.04,38.47,0.198
4.05,38.60,0.198
4.07,38.74,0.198
4.08,38.87,0.198
4.09,39.00,0.198
4.11,39.14,0.199
4.12,39.27,0.199
4.13,39.41,0.199
4.15,39.54,0.199
4.16,39.67,0.199
4.17,39.81,0.199
4.19,39.94,0.199
4.20,40.07,0.199
4.21,40.21,0.199
4.23,40.34,0.199
4.24,40.47,0.199
4.25,40.61,0.199
4.27,40.74,0.199
4.28,40.87,0.199
4.29,41.01,0.199
4.31,41.14,0.200
4.32,41.27,0.200
4.33,41.41,0.200
4.35,41.54,0.200
4.36,41.68,0.200
4.37,41.81,0.200
4.39,41.94,0.200
4.40,42.07,0.200
4.41,42.21,0.200
4.43,42.34,0.200
4.44,42.48,0.200
4.45,42.61,0.200
4.47,42.74,0.200
4.48,42.88,0.200
4.49,43.01,0.200
4.51,43.14,0.201
4.52,43.27,0.201
4.53,43.41,0.201
4.55,43.54,0.201
4.56,43.67,0.201
4.57,43.81,0.201
4.59,43.94,0.201
4.60,44.08,0.201
4.61,44.21,0.201
4.63,44.34,0.201
4.64,44.48,0.201
4.65,44.61,0.201
4.67,44.74,0.201
4.68,44.88,0.201
4.69,45.01,0.201
4.71,45.14,0.201
4.72,45.28,0.202
4.73,45.41,0.202
4.75,45.54,0.202
4.76,45.68,0.202
4.77,45.81,0.202
4.79,45.94,0.202
4.80,46.08,0.202
4.81,46.21,0.202
4.83,46.34,0.202
4.84,46.48,0.202
4.85,46.61,0.202
4.87,46.75,0.202
4.88,46.88,0.202
4.89,47.01,0.202
4.91,47.14,0.203
4.92,47.28,0.203
4.93,47.41,0.203
4.95,47.55,0.203
4.96,47.68,0.203
4.97,47.81,0.203
4.99,47.94,0.203
5.00,48.08,0.203
5.01,48.21,0.203
5.03,48.35,0.203
5.04,48.48,0.203
5.05,48.61,0.203
5.07,48.75,0.203
5.08,48.88,0.203
5.09,49.01,0.203
5.11,49.15,0.204
5.12,49.28,0.204
5.13,49.41,0.204
5.15,49.55,0.204
5.16,49.68,0.204
5.17,49.81,0.204
5.19,49.95,0.204
5.20,50.08,0.204
5.21,50.21,0.204
5.23,50.35,0.204
5.24,50.48,0.204
5.25,50.61,0.204
5.27,50.75,0.204
5.28,50.88,0.204
5.29,51.02,0.204
5.31,51.15,0.205
5.32,51.28,0.205
5.33,51.42,0.205
5.35,51.55,0.205
5.36,51.68,0.205
5.37,51.82,0.205
5.39,51.95,0.205
5.40,52.08,0.205
5.41,52.22,0.205
5.43,52.35,0.205
5.44,52.48,0.205
5.45,52.62,0.205
5.47,52.75,0.205
5.48,52.88,0.205
5.49,53.02,0.205
5.51,53.15,0.206
5.52,53.28,0.206
5.53,53.42,0.206
5.55,53.55,0.206
5.56,53.69,0.206
5.57,53.82,0.206
5.59,53.95,0.206
5.60,54.09,0.206
5.61,54.22,0.206
5.63,54.35,0.206
5.64,54.49,0.206
5.65,54.62,0.206
5.67,54.75,0.206
5.68,54.89,0.206
5.69,55.02,0.206
5.71,55.15,0.206
5.72,55.29,0.206
5.73,55.42,0.207
5.75,55.55,0.207
5.76,55.69,0.207
5.77,55.82,0.207
5.79,55.95,0.207
5.80,56.09,0.207
5.81,56.22,0.207
5.83,56.35,0.207
5.84,56.49,0.207
5.85,56.62,0.207
5.87,56.75,0.207
5.88,56.89,0.207
5.89,57.02,0.207
5.91,57.15,0.207
5.92,57.29,0.208
5.93,57.42,0.208
5.95,57.55,0.208
5.96,57.69,0.208
5.97,57.82,0.208
5.99,57.95,0.208
6.00,58.09,0.208
6.01,58.22,0.208
6.03,58.35,0.208
6.04,58.49,0.208
6.05,58.62,0.208
6.07,58.76,0.208
6.08,58.89,0.208
6.09,59.02,0.208
6.11,59.16,0.208
6.12,59.29,0.208
6.13,59.42,0.208
6.15,59.56,0.209
6.16,59.69,0.209
6.17,59.82,0.209
6.19,59.96,0.209
6.20,60.09,0.209
6.21,60.22,0.209
6.23,60.36,0.209
6.24,60.49,0.209
6.25,60.62,0.209
6.27,60.76,0.209
6.28,60.89,0.209
6.29,61.02,0.209
6.31,61.16,0.209
6.32,61.29,0.209
6.33,61.42,0.209
6.35,61.56,0.209
6.36,61.69,0.210
6.37,61.83,0.210
6.39,61.96,0.210
6.40,62.09,0.210
6.41,62.23,0.210
6.43,62.36,0.210
6.44,62.49,0.210
6.45,62.63,0.210
6.47,62.76,0.210
6.48,62.89,0.210
6.49,63.03,0.210
6.51,63.16,0.210
6.52,63.29,0.210
6.53,63.43,0.210
6.55,63.56,0.210
6.56,63.69,0.211
6.57,63.83,0.211
6.59,63.96,0.211
6.60,64.09,0.211
6.61,64.23,0.211
6.63,64.36,0.211
6.64,64.49,0.211
6.65,64.63,0.211
6.67,64.76,0.211
6.68,64.89,0.211
6.69,65.03,0.211
6.71,65.16,0.211
6.72,65.29,0.211
6.73,65.43,0.211
6.75,65.56,0.211
6.76,65.69,0.211
6.77,65.83,0.212
6.79,65.96,0.212
6.80,66.10,0.212
6.81,66.23,0.212
6.83,66.36,0.212
6.84,66.50,0.212
6.85,66.63,0.212
6.87,66.76,0.212
6.88,66.90,0.212
6.89,67.03,0.212
6.91,67.16,0.212
6.92,67.29,0.212
6.93,67.43,0.212
6.95,67.56,0.212
6.96,67.70,0.212
6.97,67.83,0.212
6.99,67.96,0.212
7.00,68.10,0.212
7.01,68.23,0.212
7.03,68.36,0.213
7.04,68.50,0.213
7.05,68.63,0.213
7.07,68.76,0.213
7.08,68.90,0.213
7.09,69.03,0.213
7.11,69.16,0.213
7.12,69.30,0.213
7.13,69.43,0.213
7.15,69.57,0.213
7.16,69.70,0.213
7.17,69.83,0.213
7.19,69.97,0.213
7.20,70.10,0.213
7.21,70.23,0.213
7.23,70.36,0.214
7.24,70.50,0.214
7.25,70.63,0.214
7.27,70.77,0.214
7.28,70.90,0.214
7.29,71.03,0.214
7.31,71.17,0.214
7.32,71.30,0.214
7.33,71.43,0.214
7.35,71.57,0.214
7.36,71.70,0.214
7.37,71.83,0.214
7.39,71.97,0.214
7.40,72.10,0.214
7.41,72.23,0.215
7.43,72.37,0.215
7.44,72.50,0.215
7.45,72.63,0.215
7.47,72.77,0.215
7.48,72.90,0.215
7.49,73.03,0.215
7.51,73.17,0.215
7.52,73.30,0.215
7.53,73.44,0.215
7.55,73.57,0.215
7.56,73.70,0.215
7.57,73.83,0.215
7.59,73.97,0.215
7.60,74.10,0.215
7.61,74.24,0.215
7.63,74.37,0.216
7.64,74.50,0.216
7.65,74.64,0.216
7.67,74.77,0.216
7.68,74.90,0.216
7.69,75.04,0.216
7.71,75.17,0.216
7.72,75.30,0.216
7.73,75.44,0.216
7.75,75.57,0.216
7.76,75.70,0.216
7.77,75.84,0.216
7.79,75.97,0.216
7.80,76.10,0.216
7.81,76.24,0.216
7.83,76.37,0.216
7.84,76.50,0.217
7.85,76.64,0.217
7.87,76.77,0.217
7.88,76.90,0.217
7.89,77.04,0.217
7.91,77.17,0.217
7.92,77.30,0.217
7.93,77.44,0.217
7.95,77.57,0.217
7.96,77.71,0.217
7.97,77.84,0.217
7.99,77.97,0.217
8.00,78.11,0.217
8.01,78.24,0.217
8.03,78.37,0.218
8.04,78.51,0.218
8.05,78.64,0.218
8.07,78.77,0.218
8.08,78.91,0.218
8.09,79.04,0.218
8.11,79.17,0.218
8.12,79.31,0.218
8.13,79.44,0.218
8.15,79.57,0.218
8.16,79.71,0.218
8.17,79.84,0.218
8.19,79.97,0.218
8.20,80.11,0.218
8.21,80.24,0.218
8.23,80.37,0.218
8.24,80.51,0.219
8.25,80.64,0.219
8.27,80.78,0.219
8.28,80.91,0.219
8.29,81.04,0.219
8.31,81.17,0.219
8.32,81.31,0.219
8.33,81.44,0.219
8.35,81.57,0.219
8.36,81.71,0.219
8.37,81.84,0.219
8.39,81.97,0.219
8.40,82.11,0.219
8.41,82.24,0.219
8.43,82.38,0.219
8.44,82.51,0.219
8.45,82.64,0.219
8.47,82.78,0.220
8.48,82.91,0.220
8.49,83.04,0.220
8.51,83.18,0.220
8.52,83.31,0.220
8.53,83.44,0.220
8.55,83.58,0.220
8.56,83.71,0.220
8.57,83.84,0.220
8.59,83.98,0.220
8.60,84.11,0.220
8.61,84.24,0.220
8.63,84.38,0.220
8.64,84.51,0.220
8.65,84.64,0.220
8.67,84.78,0.220
8.68,84.91,0.220
8.69,85.04,0.220
8.71,85.18,0.221
8.72,85.31,0.221
8.73,85.44,0.221
8.75,85.58,0.221
8.76,85.71,0.221
8.77,85.85,0.221
8.79,85.98,0.221
8.80,86.11,0.221
8.81,86.24,0.221
8.83,86.38,0.221
8.84,86.51,0.221
8.85,86.65,0.221
8.87,86.78,0.221
8.88,86.91,0.221
8.89,87.05,0.221
8.91,87.18,0.221
8.92,87.31,0.222
8.93,87.45,0.222
8.95,87.58,0.222
8.96,87.71,0.222
8.97,87.85,0.222
8.99,87.98,0.222
9.00,88.11,0.222
9.01,88.25,0.222
9.03,88.38,0.222
9.04,88.51,0.222
9.05,88.65,0.222
9.07,88.78,0.222
9.08,88.91,0.222
9.09,89.05,0.222
9.11,89.18,0.222
9.12,89.32,0.222
9.13,89.45,0.222
9.15,89.58,0.222
9.16,89.72,0.222
9.17,89.85,0.223
9.19,89.98,0.223
9.20,90.12,0.223
9.21,90.25,0.223
9.23,90.38,0.223
9.24,90.51,0.223
9.25,90.65,0.223
9.27,90.78,0.223
9.28,90.92,0.223
9.29,91.05,0.223
9.31,91.18,0.223
9.32,91.32,0.223
9.33,91.45,0.223
9.35,91.58,0.223
9.36,91.72,0.223
9.37,91.85,0.223
9.39,91.98,0.224
9.40,92.12,0.224
9.41,92.25,0.224
9.43,92.38,0.224
9.44,92.52,0.224
9.45,92.65,0.224
9.47,92.78,0.224
9.48,92.92,0.224
9.49,93.05,0.224
9.51,93.18,0.224
9.52,93.32,0.224
9.53,93.45,0.224
9.55,93.58,0.224
9.56,93.72,0.224
9.57,93.85,0.224
9.59,93.99,0.224
9.60,94.12,0.225
9.61,94.25,0.225
9.63,94.39,0.225
9.64,94.52,0.225
9.65,94.65,0.225
9.67,94.79,0.225
9.68,94.92,0.225
9.69,95.05,0.225
9.71,95.19,0.225
9.72,95.32,0.225
9.73,95.45,0.225
9.75,95.59,0.225
9.76,95.72,0.225
9.77,95.85,0.225
9.79,95.99,0.225
9.80,96.12,0.226
9.81,96.25,0.226
9.83,96.39,0.226
9.84,96.52,0.226
9.85,96.65,0.226
9.87,96.79,0.226
9.88,96.92,0.226
9.89,97.06,0.226
9.91,97.19,0.226
9.92,97.32,0.226
9.93,97.45,0.226
9.95,97.59,0.226
9.96,97.72,0.226
9.97,97.86,0.226
9.99,97.99,0.226
10.00,98.12,0.226
10.01,98.26,0.227
10.03,98.39,0.227
10.04,98.52,0.227
10.05,98.66,0.227
10.07,98.79,0.227
10.08,98.92,0.227
10.09,99.06,0.227
10.11,99.19,0.227
10.12,99.32,0.227
10.13,99.46,0.227
10.15,99.59,0.227
10.16,99.72,0.227
10.17,99.86,0.227
10.19,99.99,0.227
10.20,100.12,0.227
10.21,100.26,0.227
10.23,100.39,0.228
10.24,100.52,0.228
10.25,100.66,0.228
10.27,100.79,0.228
10.28,100.92,0.228
10.29,101.06,0.228
10.31,101.19,0.228
10.32,101.32,0.228
10.33,101.46,0.228
10.35,101.59,0.228
10.36,101.73,0.228
10.37,101.86,0.228
10.39,101.99,0.228
10.40,102.13,0.228
10.41,102.26,0.228
10.43,102.39,0.228
10.44,102.53,0.228
10.45,102.66,0.228
10.47,102.79,0.228
10.48,102.93,0.229
10.49,103.06,0.229
10.51,103.19,0.229
10.52,103.33,0.229
10.53,103.46,0.229
10.55,103.59,0.229
10.56,103.73,0.229
10.57,103.86,0.229
10.59,103.99,0.229
10.60,104.13,0.229
10.61,104.26,0.229
10.63,104.39,0.229
10.64,104.53,0.229
10.65,104.66,0.229
10.67,104.79,0.229
10.68,104.93,0.229
10.69,105.06,0.229
10.71,105.20,0.230
10.72,105.33,0.230
10.73,105.46,0.230
10.75,105.60,0.230
10.76,105.73,0.230
10.77,105.86,0.230
10.79,106.00,0.230
10.80,106.13,0.230
10.81,106.26,0.230
10.83,106.40,0.230
10.84,106.53,0.230
10.85,106.66,0.230
10.87,106.79,0.230
10.88,106.93,0.230
10.89,107.06,0.230
10.91,107.20,0.230
10.92,107.33,0.231
10.93,107.46,0.231
10.95,107.59,0.231
10.96,107.73,0.231
10.97,107.86,0.231
10.99,108.00,0.231
11.00,108.13,0.231
11.01,108.26,0.231
11.03,108.40,0.231
11.04,108.53,0.231
11.05,108.66,0.231
11.07,108.80,0.231
11.08,108.93,0.231
11.09,109.06,0.231
11.11,109.20,0.231
11.12,109.33,0.231
11.13,109.46,0.231
11.15,109.60,0.232
11.16,109.73,0.232
11.17,109.86,0.232
11.19,110.00,0.232
11.20,110.13,0.232
11.21,110.27,0.232
11.23,110.40,0.232
11.24,110.53,0.232
11.25,110.66,0.232
11.27,110.80,0.232
11.28,110.93,0.232
11.29,111.06,0.232
11.31,111.20,0.232
11.32,111.33,0.232
11.33,111.46,0.232
11.35,111.60,0.232
11.36,111.73,0.232
11.37,111.87,0.233
11.39,112.00,0.233
11.40,112.13,0.233
11.41,112.26,0.233
11.43,112.40,0.233
11.44,112.53,0.233
11.45,112.67,0.233
11.47,112.80,0.233
11.48,112.93,0.233
11.49,113.07,0.233
11.51,113.20,0.233
11.52,113.33,0.233
11.53,113.47,0.233
11.55,113.60,0.233
11.56,113.73,0.233
11.57,113.87,0.233
11.59,114.00,0.233
11.60,114.13,0.234
11.61,114.27,0.234
11.63,114.40,0.234
11.64,114.53,0.234
11.65,114.67,0.234
11.67,114.80,0.234
11.68,114.93,0.234
11.69,115.07,0.234
11.71,115.20,0.234
11.72,115.33,0.234
11.73,115.47,0.234
11.75,115.60,0.234
11.76,115.73,0.234
11.77,115.87,0.234
11.79,116.00,0.234
11.80,116.13,0.234
11.81,116.27,0.234
11.83,116.40,0.235
11.84,116.53,0.235
11.85,116.67,0.235
11.87,116.80,0.235
11.88,116.93,0.235
11.89,117.07,0.235
11.91,117.20,0.235
11.92,117.34,0.235
11.93,117.47,0.235
11.95,117.60,0.235
11.96,117.74,0.235
11.97,117.87,0.235
11.99,118.00,0.235
12.00,118.14,0.235
12.01,118.27,0.236
12.03,118.40,0.236
12.04,118.54,0.236
12.05,118.67,0.236
12.07,118.80,0.236
12.08,118.94,0.236
12.09,119.07,0.236
12.11,119.20,0.236
12.12,119.34,0.236
12.13,119.47,0.236
12.15,119.60,0.236
12.16,119.74,0.236
12.17,119.87,0.236
12.19,120.00,0.236
12.20,120.14,0.236
12.21,120.27,0.236
12.23,120.40,0.236
12.24,120.54,0.236
12.25,120.67,0.236
12.27,120.80,0.237
12.28,120.94,0.237
12.29,121.07,0.237
12.31,121.21,0.237
12.32,121.34,0.237
12.33,121.47,0.237
12.35,121.61,0.237
12.36,121.74,0.237
12.37,121.87,0.237
12.39,122.00,0.237
12.40,122.14,0.237
12.41,122.27,0.237
12.43,122.41,0.237
12.44,122.54,0.237
12.45,122.67,0.237
12.47,122.81,0.237
12.48,122.94,0.238
12.49,123.07,0.238
12.51,123.21,0.238
12.52,123.34,0.238
12.53,123.47,0.238
12.55,123.61,0.238
12.56,123.74,0.238
12.57,123.87,0.238
12.59,124.01,0.238
12.60,124.14,0.238
12.61,124.27,0.238
12.63,124.41,0.238
12.64,124.54,0.238
12.65,124.67,0.238
12.67,124.81,0.238
12.68,124.94,0.238
12.69,125.07,0.239
12.71,125.21,0.239
12.72,125.34,0.239
12.73,125.47,0.239
12.75,125.61,0.239
12.76,125.74,0.239
12.77,125.87,0.239
12.79,126.01,0.239
12.80,126.14,0.239
12.81,126.28,0.239
12.83,126.41,0.239
12.84,126.54,0.239
12.85,126.68,0.239
12.87,126.81,0.239
12.88,126.94,0.239
12.89,127.07,0.239
12.91,127.21,0.240
12.92,127.34,0.240
12.93,127.48,0.240
12.95,127.61,0.240
12.96,127.74,0.240
12.97,127.88,0.240
12.99,128.01,0.240
13.00,128.14,0.240
13.01,128.28,0.240
13.03,128.41,0.240
13.04,128.54,0.240
13.05,128.68,0.240
13.07,128.81,0.240
13.08,128.94,0.240
13.09,129.08,0.240
13.11,129.21,0.240
13.12,129.34,0.241
13.13,129.48,0.241
13.15,129.61,0.241
13.16,129.74,0.241
13.17,129.88,0.241
13.19,130.01,0.241
13.20,130.14,0.241
13.21,130.28,0.241
13.23,130.41,0.241
13.24,130.54,0.241
13.25,130.68,0.241
13.27,130.81,0.241
13.28,130.95,0.241
13.29,131.08,0.242
13.31,131.22,0.242
13.32,131.35,0.243
13.33,131.49,0.243
13.35,131.62,0.243
13.36,131.75,0.243
13.37,131.89,0.243
13.39,132.02,0.243
13.40,132.15,0.244
13.41,132.29,0.244
13.43,132.42,0.244
13.44,132.55,0.244
13.45,132.69,0.244
13.47,132.82,0.244
13.48,132.95,0.244
13.49,133.09,0.244
13.51,133.22,0.244
13.52,133.35,0.244
13.53,133.49,0.244
13.55,133.62,0.243
13.56,133.75,0.243
13.57,133.89,0.243
13.59,134.02,0.243
13.60,134.15,0.244
13.61,134.29,0.244
13.63,134.42,0.244
13.64,134.55,0.244
13.65,134.68,0.244
13.67,134.82,0.244
13.68,134.95,0.244
13.69,135.08,0.244
13.71,135.22,0.244
13.72,135.35,0.244
13.73,135.48,0.244
13.75,135.62,0.244
13.76,135.75,0.244
13.77,135.88,0.244
13.79,136.02,0.244
13.80,136.15,0.244
13.81,136.28,0.244
13.83,136.42,0.244
13.84,136.55,0.244
13.85,136.68,0.244
13.87,136.82,0.244
13.88,136.95,0.244
13.89,137.08,0.244
13.91,137.22,0.244
13.92,137.35,0.244
13.93,137.48,0.244
13.95,137.62,0.244
13.96,137.75,0.244
13.97,137.88,0.245
13.99,138.02,0.245
14.00,138.15,0.245
14.01,138.28,0.245
14.03,138.42,0.245
14.04,138.55,0.245
14.05,138.68,0.245
14.07,138.82,0.245
14.08,138.95,0.245
14.09,139.08,0.245
14.11,139.22,0.245
14.12,139.35,0.245
14.13,139.48,0.245
14.15,139.62,0.245
14.16,139.75,0.246
14.17,139.88,0.246
14.19,140.02,0.246
14.20,140.15,0.246
14.21,140.28,0.246
14.23,140.42,0.246
14.24,140.55,0.246
14.25,140.68,0.246
14.27,140.82,0.246
14.28,140.95,0.246
14.29,141.08,0.246
14.31,141.22,0.246
14.32,141.35,0.247
14.33,141.48,0.247
14.35,141.62,0.247
14.36,141.75,0.247
14.37,141.88,0.247
14.39,142.02,0.247
14.40,142.15,0.247
14.41,142.28,0.247
14.43,142.42,0.247
14.44,142.55,0.247
14.45,142.68,0.247
14.47,142.82,0.247
14.48,142.95,0.248
14.49,143.08,0.248
14.51,143.22,0.248
14.52,143.35,0.248
14.53,143.48,0.248
14.55,143.62,0.248
14.56,143.75,0.248
14.57,143.89,0.248
14.59,144.02,0.249
14.60,144.15,0.249
14.61,144.29,0.249
14.63,144.42,0.249
14.64,144.55,0.249
14.65,144.69,0.249
14.67,144.82,0.249
14.68,144.95,0.249
14.69,145.09,0.249
14.71,145.22,0.249
14.72,145.35,0.249
14.73,145.49,0.249
14.75,145.62,0.249
14.76,145.75,0.249
14.77,145.89,0.250
14.79,146.02,0.250
14.80,146.15,0.250
14.81,146.28,0.250
14.83,146.42,0.250
14.84,146.55,0.250
14.85,146.68,0.250
14.87,146.82,0.250
14.88,146.95,0.250
14.89,147.08,0.250
14.91,147.22,0.251
14.92,147.35,0.251
14.93,147.48,0.251
14.95,147.62,0.251
14.96,147.75,0.251
14.97,147.88,0.251
14.99,148.02,0.251
15.00,148.15,0.251
15.01,148.28,0.251
15.03,148.42,0.251
15.04,148.55,0.251
15.05,148.69,0.251
15.07,148.82,0.252
15.08,148.95,0.252
15.09,149.09,0.252
15.11,149.22,0.252
15.12,149.35,0.252
15.13,149.49,0.252
15.15,149.62,0.253
15.16,149.75,0.253
15.17,149.89,0.253
15.19,150.02,0.253
15.20,150.15,0.253
15.21,150.28,0.253
15.23,150.42,0.253
15.24,150.55,0.254
15.25,150.69,0.254
15.27,150.82,0.254
15.28,150.95,0.254
15.29,151.09,0.254
15.31,151.22,0.254
15.32,151.35,0.254
15.33,151.48,0.254
15.35,151.62,0.255
15.36,151.75,0.255
15.37,151.88,0.255
15.39,152.02,0.255
15.40,152.15,0.255
15.41,152.28,0.255
15.43,152.42,0.255
15.44,152.55,0.255
15.45,152.69,0.255
15.47,152.82,0.255
15.48,152.95,0.256
15.49,153.08,0.256
15.51,153.22,0.256
15.52,153.35,0.256
15.53,153.48,0.256
15.55,153.62,0.257
15.56,153.75,0.257
15.57,153.88,0.257
15.59,154.02,0.257
15.60,154.15,0.257
15.61,154.28,0.258
15.63,154.42,0.258
15.64,154.55,0.258
15.65,154.68,0.258
15.67,154.82,0.258
15.68,154.95,0.258
15.69,155.08,0.258
15.71,155.22,0.259
15.72,155.35,0.259
15.73,155.48,0.259
15.75,155.62,0.259
15.76,155.75,0.259
15.77,155.88,0.259
15.79,156.01,0.259
15.80,156.15,0.260
15.81,156.28,0.260
15.83,156.42,0.260
15.84,156.55,0.260
15.85,156.68,0.261
15.87,156.81,0.261
15.88,156.95,0.261
15.89,157.08,0.262
15.91,157.21,0.262
15.92,157.35,0.262
15.93,157.48,0.262
15.95,157.61,0.263
15.96,157.75,0.263
15.97,157.88,0.263
15.99,158.01,0.263
16.00,158.15,0.264
16.01,158.28,0.264
16.03,158.41,0.264
16.04,158.54,0.265
16.05,158.68,0.265
16.07,158.81,0.265
16.08,158.94,0.266
16.09,159.08,0.266
16.11,159.21,0.266
16.12,159.34,0.266
16.13,159.48,0.267
16.15,159.61,0.267
16.16,159.74,0.268
16.17,159.88,0.268
16.19,160.01,0.268
16.20,160.14,0.269
16.21,160.28,0.269
16.23,160.41,0.269
16.24,160.54,0.270
16.25,160.67,0.270
16.27,160.81,0.270
16.28,160.94,0.271
16.29,161.07,0.271
16.31,161.20,0.272
16.32,161.34,0.272
16.33,161.47,0.273
16.35,161.60,0.273
16.36,161.74,0.274
16.37,161.87,0.275
16.39,162.00,0.275
16.40,162.13,0.276
16.41,162.27,0.276
16.43,162.40,0.277
16.44,162.53,0.277
16.45,162.66,0.278
16.47,162.80,0.279
16.48,162.93,0.280
16.49,163.06,0.280
16.51,163.20,0.281
16.52,163.33,0.282
16.53,163.46,0.283
16.55,163.59,0.283
16.56,163.73,0.285
16.57,163.86,0.286
16.59,163.99,0.286
16.60,164.12,0.287
16.61,164.26,0.288
16.63,164.39,0.289
16.64,164.52,0.290
16.65,164.65,0.291
16.67,164.78,0.293
16.68,164.92,0.293
16.69,165.05,0.295
16.71,165.18,0.296
16.72,165.31,0.297
16.73,165.44,0.299
16.75,165.57,0.300
16.76,165.70,0.302
16.77,165.84,0.303
16.79,165.97,0.305
16.80,166.10,0.306
16.81,166.23,0.308
16.83,166.36,0.310
16.84,166.49,0.312
16.85,166.62,0.314
16.87,166.75,0.316
16.88,166.88,0.319
16.89,167.01,0.321
16.91,167.14,0.324
16.92,167.27,0.326
16.93,167.40,0.329
16.95,167.53,0.332
16.96,167.66,0.335
16.97,167.79,0.339
16.99,167.92,0.342
17.00,168.05,0.346
17.01,168.18,0.350
17.03,168.31,0.354
17.04,168.43,0.359
17.05,168.56,0.363
17.07,168.69,0.368
17.08,168.82,0.373
17.09,168.94,0.379
17.11,169.07,0.385
17.12,169.20,0.391
17.13,169.32,0.398
17.15,169.45,0.405
17.16,169.57,0.413
17.17,169.69,0.421
17.19,169.81,0.430
17.20,169.94,0.439
17.21,170.06,0.449
17.23,170.18,0.460
17.24,170.30,0.472
17.25,170.42,0.484
17.27,170.53,0.497
17.28,170.65,0.512
17.29,170.77,0.527
17.31,170.88,0.543
17.32,170.99,0.561
17.33,171.10,0.579
17.35,171.21,0.599
17.36,171.32,0.620
17.37,171.43,0.642
17.39,171.53,0.664
17.40,171.64,0.689
17.41,171.74,0.714
17.43,171.84,0.741
17.44,171.93,0.769
17.45,172.03,0.799
17.47,172.12,0.829
17.48,172.22,0.861
17.49,172.31,0.895
17.51,172.40,0.929
17.52,172.48,0.963
17.53,172.57,1.000
17.55,172.65,1.042
17.56,172.73,1.080
17.57,172.81,1.121
17.59,172.89,1.167
17.60,172.96,1.217
17.61,173.03,1.264
17.63,173.10,1.306
17.64,173.17,1.353
17.65,173.23,1.403
17.67,173.30,1.452
17.68,173.36,1.501
17.69,173.42,1.546
17.71,173.49,1.595
17.72,173.55,1.644
17.73,173.61,1.697
17.75,173.67,1.753
17.76,173.73,1.799
17.77,173.79,1.849
17.79,173.85,1.896
17.80,173.91,1.947
17.81,173.97,2.002
17.83,174.02,2.064
17.84,174.07,2.116
17.85,174.13,2.167
17.87,174.18,2.218
17.88,174.24,2.278
17.89,174.28,2.356
17.91,174.32,2.431
17.92,174.36,2.477
17.93,174.42,2.500
17.95,174.48,2.532
17.96,174.55,2.533
17.97,174.64,2.522
17.99,174.75,2.497
18.00,174.87,2.457
18.01,175.01,2.426
18.03,175.16,2.406
18.04,175.30,2.391
18.05,175.46,2.377
18.07,175.61,2.361
18.08,175.76,2.341
18.09,175.92,2.321
18.11,176.07,2.306
18.12,176.23,2.293
18.13,176.39,2.281
18.15,176.54,2.272
18.16,176.69,2.258
18.17,176.85,2.240
18.19,177.01,2.220
18.20,177.16,2.206
18.21,177.32,2.196
18.23,177.47,2.182
18.24,177.63,2.162
18.25,177.79,2.135
18.27,177.95,2.105
18.28,178.12,2.072
18.29,178.29,2.034
18.31,178.47,1.991
18.32,178.65,1.937
18.33,178.85,1.869
18.35,179.05,1.797
18.36,179.27,1.703
18.37,179.50,1.598
18.39,179.75,1.485
18.40,180.02,1.371
18.41,180.28,1.269
18.43,180.55,1.182
18.44,180.82,1.105
18.45,181.08,1.036
18.47,181.33,0.973
18.48,181.58,0.917
18.49,181.82,0.866
18.51,182.05,0.819
18.52,182.28,0.777
18.53,182.50,0.738
18.55,182.71,0.703
18.56,182.91,0.671
18.57,183.11,0.640
18.59,183.30,0.613
18.60,183.49,0.588
18.61,183.68,0.564
18.63,183.86,0.543
18.64,184.03,0.523
18.65,184.21,0.505
18.67,184.38,0.489
18.68,184.55,0.474
18.69,184.71,0.460
18.71,184.87,0.448
18.72,185.03,0.436
18.73,185.19,0.425
18.75,185.34,0.415
18.76,185.50,0.406
18.77,185.65,0.398
18.79,185.80,0.390
18.80,185.95,0.383
18.81,186.10,0.376
18.83,186.24,0.370
18.84,186.39,0.365
18.85,186.53,0.361
18.87,186.68,0.356
18.88,186.82,0.351
18.89,186.96,0.348
18.91,187.10,0.344
18.92,187.24,0.341
18.93,187.38,0.338
18.95,187.52,0.335
18.96,187.66,0.333
18.97,187.80,0.331
18.99,187.94,0.328
19.00,188.07,0.327
19.01,188.21,0.325
19.03,188.35,0.323
19.04,188.49,0.322
19.05,188.62,0.320
19.07,188.76,0.319
19.08,188.89,0.318
19.09,189.03,0.317
19.11,189.17,0.316
19.12,189.30,0.315
19.13,189.44,0.315
19.15,189.57,0.314
19.16,189.71,0.314
19.17,189.84,0.313
19.19,189.97,0.312
19.20,190.11,0.312
19.21,190.24,0.311
19.23,190.38,0.311
19.24,190.51,0.311
19.25,190.65,0.311
19.27,190.78,0.310
19.28,190.91,0.310
19.29,191.05,0.310
19.31,191.18,0.310
19.32,191.32,0.310
19.33,191.45,0.309
19.35,191.58,0.309
19.36,191.72,0.309
19.37,191.85,0.309
19.39,191.98,0.309
19.40,192.12,0.309
19.41,192.25,0.309
19.43,192.39,0.309
19.44,192.52,0.309
19.45,192.65,
19.47,192.79,
19.48,192.92,
19.49,193.06,
19.51,,

[step]
Ramp 10.00 °C/min to 0.00 °C
Time,Temperature,Heat Flow (Normalized)
min,°C,W/g
20.51,195.11,-0.024
20.52,195.11,-0.024
20.53,195.11,-0.025
20.55,195.11,-0.025
20.56,195.10,-0.025
20.57,195.09,-0.025
20.59,195.06,-0.025
20.60,195.03,-0.029
20.61,194.99,-0.036
20.63,194.94,-0.047
20.64,194.88,-0.061
20.65,194.81,-0.078
20.67,194.74,-0.096
20.68,194.66,-0.115
20.69,194.57,-0.134
20.71,194.48,-0.152
20.72,194.39,-0.169
20.73,194.30,-0.184
20.75,194.20,-0.198
20.76,194.10,-0.211
20.77,193.99,-0.223
20.79,193.89,-0.234
20.80,193.78,-0.243
20.81,193.67,-0.252
20.83,193.56,-0.260
20.84,193.45,-0.268
20.85,193.33,-0.275
20.87,193.22,-0.282
20.88,193.10,-0.287
20.89,192.98,-0.293
20.91,192.86,-0.298
20.92,192.74,-0.303
20.93,192.62,-0.307
20.95,192.50,-0.311
20.96,192.37,-0.314
20.97,192.25,-0.317
20.99,192.13,-0.320
21.00,192.00,-0.323
21.01,191.88,-0.325
21.03,191.75,-0.328
21.04,191.62,-0.330
21.05,191.50,-0.332
21.07,191.37,-0.334
21.08,191.24,-0.335
21.09,191.11,-0.336
21.11,190.98,-0.338
21.12,190.86,-0.339
21.13,190.73,-0.340
21.15,190.60,-0.341
21.16,190.47,-0.341
21.17,190.34,-0.343
21.19,190.21,-0.343
21.20,190.08,-0.344
21.21,189.95,-0.345
21.23,189.82,-0.345
21.24,189.69,-0.346
21.25,189.56,-0.346
21.27,189.43,-0.347
21.28,189.29,-0.347
21.29,189.16,-0.347
21.31,189.03,-0.348
21.32,188.90,-0.348
21.33,188.77,-0.348
21.35,188.64,-0.348
21.36,188.50,-0.349
21.37,188.37,-0.349
21.39,188.24,-0.349
21.40,188.11,-0.349
21.41,187.98,-0.349
21.43,187.84,-0.349
21.44,187.71,-0.349
21.45,187.58,-0.349
21.47,187.45,-0.349
21.48,187.32,-0.349
21.49,187.18,-0.349
21.51,187.05,-0.349
21.52,186.92,-0.349
21.53,186.79,-0.349
21.55,186.65,-0.349
21.56,186.52,-0.349
21.57,186.39,-0.349
21.59,186.26,-0.349
21.60,186.12,-0.349
21.61,185.99,-0.350
21.63,185.86,-0.350
21.64,185.73,-0.350
21.65,185.59,-0.350
21.67,185.46,-0.350
21.68,185.33,-0.350
21.69,185.19,-0.349
21.71,185.06,-0.349
21.72,184.93,-0.349
21.73,184.80,-0.349
21.75,184.66,-0.349
21.76,184.53,-0.349
21.77,184.40,-0.349
21.79,184.26,-0.349
21.80,184.13,-0.349
21.81,184.00,-0.349
21.83,183.87,-0.349
21.84,183.73,-0.349
21.85,183.60,-0.349
21.87,183.47,-0.349
21.88,183.33,-0.349
21.89,183.20,-0.349
21.91,183.07,-0.349
21.92,182.94,-0.348
21.93,182.80,-0.348
21.95,182.67,-0.348
21.96,182.54,-0.348
21.97,182.40,-0.348
21.99,182.27,-0.348
22.00,182.14,-0.348
22.01,182.00,-0.348
22.03,181.87,-0.348
22.04,181.74,-0.348
22.05,181.60,-0.347
22.07,181.47,-0.347
22.08,181.34,-0.347
22.09,181.21,-0.347
22.11,181.07,-0.347
22.12,180.94,-0.347
22.13,180.81,-0.347
22.15,180.67,-0.347
22.16,180.54,-0.347
22.17,180.41,-0.347
22.19,180.27,-0.347
22.20,180.14,-0.347
22.21,180.01,-0.346
22.23,179.87,-0.346
22.24,179.74,-0.346
22.25,179.61,-0.346
22.27,179.47,-0.346
22.28,179.34,-0.346
22.29,179.21,-0.346
22.31,179.08,-0.346
22.32,178.94,-0.346
22.33,178.81,-0.346
22.35,178.68,-0.345
22.36,178.54,-0.345
22.37,178.41,-0.345
22.39,178.28,-0.345
22.40,178.14,-0.345
22.41,178.01,-0.345
22.43,177.88,-0.345
22.44,177.74,-0.345
22.45,177.61,-0.345
22.47,177.48,-0.345
22.48,177.34,-0.345
22.49,177.21,-0.345
22.51,177.08,-0.345
22.52,176.94,-0.344
22.53,176.81,-0.344
22.55,176.68,-0.344
22.56,176.55,-0.344
22.57,176.41,-0.344
22.59,176.28,-0.344
22.60,176.15,-0.344
22.61,176.01,-0.344
22.63,175.88,-0.344
22.64,175.75,-0.344
22.65,175.61,-0.344
22.67,175.48,-0.344
22.68,175.35,-0.343
22.69,175.21,-0.343
22.71,175.08,-0.343
22.72,174.95,-0.343
22.73,174.81,-0.343
22.75,174.68,-0.343
22.76,174.55,-0.343
22.77,174.41,-0.343
22.79,174.28,-0.343
22.80,174.15,-0.343
22.81,174.02,-0.343
22.83,173.88,-0.343
22.84,173.75,-0.343
22.85,173.62,-0.342
22.87,173.48,-0.342
22.88,173.35,-0.342
22.89,173.22,-0.342
22.91,173.08,-0.342
22.92,172.95,-0.342
22.93,172.82,-0.342
22.95,172.68,-0.342
22.96,172.55,-0.342
22.97,172.42,-0.342
22.99,172.28,-0.342
23.00,172.15,-0.342
23.01,172.02,-0.341
23.03,171.88,-0.341
23.04,171.75,-0.341
23.05,171.62,-0.341
23.07,171.49,-0.341
23.08,171.35,-0.341
23.09,171.22,-0.341
23.11,171.09,-0.341
23.12,170.95,-0.341
23.13,170.82,-0.341
23.15,170.69,-0.340
23.16,170.55,-0.340
23.17,170.42,-0.340
23.19,170.29,-0.340
23.20,170.15,-0.340
23.21,170.02,-0.340
23.23,169.89,-0.340
23.24,169.75,-0.340
23.25,169.62,-0.340
23.27,169.49,-0.340
23.28,169.35,-0.340
23.29,169.22,-0.340
23.31,169.09,-0.340
23.32,168.95,-0.340
23.33,168.82,-0.339
23.35,168.69,-0.339
23.36,168.55,-0.339
23.37,168.42,-0.339
23.39,168.29,-0.339
23.40,168.15,-0.339
23.41,168.02,-0.339
23.43,167.89,-0.339
23.44,167.76,-0.339
23.45,167.62,-0.339
23.47,167.49,-0.339
23.48,167.36,-0.339
23.49,167.22,-0.338
23.51,167.09,-0.338
23.52,166.96,-0.338
23.53,166.82,-0.338
23.55,166.69,-0.338
23.56,166.56,-0.338
23.57,166.42,-0.338
23.59,166.29,-0.338
23.60,166.16,-0.338
23.61,166.02,-0.338
23.63,165.89,-0.338
23.64,165.76,-0.338
23.65,165.62,-0.338
23.67,165.49,-0.338
23.68,165.36,-0.337
23.69,165.22,-0.337
23.71,165.09,-0.337
23.72,164.96,-0.337
23.73,164.82,-0.337
23.75,164.69,-0.337
23.76,164.56,-0.337
23.77,164.43,-0.337
23.79,164.29,-0.337
23.80,164.16,-0.337
23.81,164.03,-0.337
23.83,163.89,-0.337
23.84,163.76,-0.337
23.85,163.63,-0.337
23.87,163.49,-0.337
23.88,163.36,-0.337
23.89,163.23,-0.337
23.91,163.09,-0.336
23.92,162.96,-0.336
23.93,162.83,-0.336
23.95,162.69,-0.336
23.96,162.56,-0.336
23.97,162.43,-0.336
23.99,162.29,-0.336
24.00,162.16,-0.336
24.01,162.03,-0.336
24.03,161.89,-0.336
24.04,161.76,-0.336
24.05,161.63,-0.336
24.07,161.50,-0.336
24.08,161.36,-0.336
24.09,161.23,-0.336
24.11,161.10,-0.336
24.12,160.96,-0.335
24.13,160.83,-0.335
24.15,160.70,-0.335
24.16,160.56,-0.335
24.17,160.43,-0.335
24.19,160.30,-0.335
24.20,160.16,-0.335
24.21,160.03,-0.335
24.23,159.90,-0.335
24.24,159.76,-0.335
24.25,159.63,-0.335
24.27,159.50,-0.335
24.28,159.36,-0.335
24.29,159.23,-0.335
24.31,159.10,-0.335
24.32,158.97,-0.335
24.33,158.83,-0.335
24.35,158.70,-0.334
24.36,158.57,-0.334
24.37,158.43,-0.334
24.39,158.30,-0.334
24.40,158.17,-0.334
24.41,158.03,-0.334
24.43,157.90,-0.334
24.44,157.77,-0.334
24.45,157.63,-0.334
24.47,157.50,-0.334
24.48,157.37,-0.334
24.49,157.23,-0.334
24.51,157.10,-0.334
24.52,156.97,-0.334
24.53,156.83,-0.334
24.55,156.70,-0.334
24.56,156.57,-0.334
24.57,156.43,-0.334
24.59,156.30,-0.334
24.60,156.17,-0.334
24.61,156.03,-0.333
24.63,155.90,-0.333
24.64,155.77,-0.333
24.65,155.63,-0.333
24.67,155.50,-0.333
24.68,155.37,-0.333
24.69,155.24,-0.333
24.71,155.10,-0.333
24.72,154.97,-0.333
24.73,154.84,-0.333
24.75,154.70,-0.333
24.76,154.57,-0.333
24.77,154.43,-0.333
24.79,154.30,-0.333
24.80,154.17,-0.333
24.81,154.04,-0.333
24.83,153.90,-0.333
24.84,153.77,-0.333
24.85,153.64,-0.333
24.87,153.50,-0.333
24.88,153.37,-0.333
24.89,153.24,-0.332
24.91,153.10,-0.332
24.92,152.97,-0.332
24.93,152.84,-0.332
24.95,152.71,-0.332
24.96,152.57,-0.332
24.97,152.44,-0.332
24.99,152.31,-0.332
25.00,152.17,-0.332
25.01,152.04,-0.332
25.03,151.91,-0.332
25.04,151.77,-0.332
25.05,151.64,-0.332
25.07,151.51,-0.332
25.08,151.37,-0.332
25.09,151.24,-0.332
25.11,151.11,-0.331
25.12,150.98,-0.331
25.13,150.84,-0.331
25.15,150.71,-0.331
25.16,150.58,-0.331
25.17,150.44,-0.331
25.19,150.31,-0.331
25.20,150.18,-0.331
25.21,150.04,-0.331
25.23,149.91,-0.331
25.24,149.78,-0.331
25.25,149.64,-0.331
25.27,149.51,-0.331
25.28,149.38,-0.331
25.29,149.25,-0.331
25.31,149.11,-0.331
25.32,148.98,-0.330
25.33,148.85,-0.330
25.35,148.71,-0.330
25.36,148.58,-0.330
25.37,148.45,-0.330
25.39,148.31,-0.330
25.40,148.18,-0.330
25.41,148.05,-0.330
25.43,147.91,-0.330
25.44,147.78,-0.330
25.45,147.65,-0.330
25.47,147.51,-0.330
25.48,147.38,-0.330
25.49,147.25,-0.330
25.51,147.12,-0.330
25.52,146.98,-0.330
[...]
78.08,31.47,-0.249
78.09,31.33,-0.248
78.11,31.20,-0.248
78.12,31.07,-0.248
78.13,30.94,-0.247
78.15,30.80,-0.247
78.16,30.67,-0.246
78.17,30.53,-0.246
78.19,30.40,-0.246
78.20,30.27,-0.246
78.21,30.13,-0.246
78.23,30.00,-0.246
78.24,29.87,-0.246
78.25,29.73,-0.246
78.27,29.60,-0.245
78.28,29.47,-0.244
78.29,29.33,-0.244
78.31,29.20,-0.244
78.32,29.07,-0.244
78.33,28.93,-0.243
78.35,28.80,-0.242
78.36,28.67,-0.242
78.37,28.53,-0.242
78.39,28.40,-0.241
78.40,28.26,-0.241
78.41,28.13,-0.232
78.43,27.99,-0.236
78.44,27.86,-0.235
78.45,27.72,-0.234
78.47,27.59,-0.238
78.48,27.46,-0.237
78.49,27.32,-0.237
78.51,27.19,-0.237
78.52,27.06,-0.237
78.53,26.92,-0.237
78.55,26.79,-0.236
78.56,26.66,-0.235
78.57,26.52,-0.235
78.59,26.39,-0.234
78.60,26.25,-0.234
78.61,26.12,-0.229
78.63,25.99,-0.237
78.64,25.86,-0.236
78.65,25.72,-0.235
78.67,25.59,-0.234
78.68,25.45,-0.232
78.69,25.32,-0.232
78.71,25.19,-0.231
78.72,25.05,-0.231
78.73,24.92,-0.230
78.75,24.79,-0.230
78.76,24.65,-0.230
78.77,24.52,-0.229
78.79,24.39,-0.229
78.80,24.25,-0.228
78.81,24.12,-0.228
78.83,23.98,-0.228
78.84,23.85,-0.228
78.85,23.72,-0.228
78.87,23.58,-0.227
78.88,23.45,-0.227
78.89,23.32,-0.227
78.91,23.18,-0.226
78.92,23.05,-0.226
78.93,22.91,-0.226
78.95,22.78,-0.226
78.96,22.65,-0.225
78.97,22.51,-0.225
78.99,22.38,-0.225
79.00,22.25,-0.225
79.01,22.11,-0.224
79.03,21.98,-0.224
79.04,21.85,-0.224
79.05,21.71,-0.224
79.07,21.58,-0.224
79.08,21.45,-0.223
79.09,21.31,-0.223
79.11,21.18,-0.223
79.12,21.04,-0.223
79.13,20.91,-0.223
79.15,20.78,-0.223
79.16,20.64,-0.222
79.17,20.51,-0.222
79.19,20.38,-0.222
79.20,20.24,-0.222
79.21,20.11,-0.222
79.23,19.98,-0.221
79.24,19.84,-0.221
79.25,19.71,-0.221
79.27,19.58,-0.221
79.28,19.44,-0.220
79.29,19.31,-0.220
79.31,19.18,-0.220
79.32,19.04,-0.220
79.33,18.91,-0.220
79.35,18.78,-0.219
79.36,18.64,-0.219
79.37,18.51,-0.219
79.39,18.38,-0.219
79.40,18.24,-0.218
79.41,18.11,-0.219
79.43,17.98,-0.219
79.44,17.84,-0.219
79.45,17.71,-0.218
79.47,17.58,-0.218
79.48,17.44,-0.218
79.49,17.31,-0.217
79.51,17.18,-0.217
79.52,17.04,-0.217
79.53,16.91,-0.217
79.55,16.78,-0.216
79.56,16.64,-0.216
79.57,16.51,-0.216
79.59,16.38,-0.216
79.60,16.24,-0.216
79.61,16.11,-0.216
79.63,15.97,-0.216
79.64,15.84,-0.215
79.65,15.71,-0.215
79.67,15.57,-0.215
79.68,15.44,-0.215
79.69,15.31,-0.215
79.71,15.17,-0.215
79.72,15.04,-0.217
79.73,14.91,-0.217
79.75,14.77,-0.216
79.76,14.64,-0.215
79.77,14.51,-0.214
79.79,14.37,-0.214
79.80,14.24,-0.214
79.81,14.11,-0.213
79.83,13.98,-0.213
79.84,13.84,-0.213
79.85,13.71,-0.213
79.87,13.57,-0.212
79.88,13.44,-0.212
79.89,13.31,-0.212
79.91,13.17,-0.212
79.92,13.04,-0.212
79.93,12.91,-0.211
79.95,12.77,-0.211
79.96,12.64,-0.211
79.97,12.51,-0.211
79.99,12.37,-0.211
80.00,12.24,-0.211
80.01,12.11,-0.211
80.03,11.98,-0.210
80.04,11.84,-0.210
80.05,11.71,-0.210
80.07,11.57,-0.210
80.08,11.44,-0.210
80.09,11.31,-0.210
80.11,11.17,-0.209
80.12,11.04,-0.212
80.13,10.92,-0.225
80.15,10.78,-0.214
80.16,10.65,-0.212
80.17,10.52,-0.210
80.19,10.38,-0.210
80.20,10.25,-0.210
80.21,10.11,-0.210
80.23,9.98,-0.210
80.24,9.85,-0.209
80.25,9.71,-0.209
80.27,9.58,-0.209
80.28,9.45,-0.209
80.29,9.31,-0.209
80.31,9.18,-0.209
80.32,9.05,-0.209
80.33,8.91,-0.209
80.35,8.78,-0.208
80.36,8.65,-0.208
80.37,8.51,-0.208
80.39,8.38,-0.208
80.40,8.25,-0.208
80.41,8.11,-0.208
80.43,7.98,-0.208
80.44,7.85,-0.208
80.45,7.71,-0.208
80.47,7.58,-0.207
80.48,7.45,-0.207
80.49,7.31,-0.207
80.51,7.18,-0.207
80.52,7.05,-0.207
80.53,6.91,-0.207
80.55,6.78,-0.207
80.56,6.65,-0.211
80.57,6.52,-0.210
80.59,6.38,-0.207
80.60,6.25,-0.206
80.61,6.11,-0.206
80.63,5.98,-0.206
80.64,5.85,-0.206
80.65,5.72,-0.206
80.67,5.58,-0.205
80.68,5.45,-0.205
80.69,5.31,-0.205
80.71,5.18,-0.205
80.72,5.05,-0.205
80.73,4.91,-0.205
80.75,4.78,-0.205
80.76,4.65,-0.205
80.77,4.51,-0.205
80.79,4.38,-0.204
80.80,4.25,-0.204
80.81,4.11,-0.204
80.83,3.98,-0.204
80.84,3.85,-0.204
80.85,3.71,-0.204
80.87,3.58,-0.204
80.88,3.45,-0.204
80.89,3.31,-0.204
80.91,3.18,-0.203
80.92,3.05,-0.203
80.93,2.91,-0.203
80.95,2.78,-0.203
80.96,2.64,
80.97,2.51,
80.99,2.38,
81.00,,
81.00,,

[step]
Ramp 10.00 °C/min to 30.00 °C
Time,Temperature,Heat Flow (Normalized)
min,°C,W/g
82.01,0.14,-0.007
82.01,0.14,-0.007
82.01,0.14,-0.007
82.02,0.14,-0.007
82.02,0.13,-0.007
82.02,0.13,-0.007
82.03,0.14,-0.007
82.03,0.14,-0.007
82.03,0.14,-0.007
82.04,0.14,-0.007
82.04,0.14,-0.007
82.04,0.14,-0.007
82.05,0.14,-0.007
82.05,0.14,-0.007
82.05,0.14,-0.007
82.06,0.15,-0.007
82.06,0.15,-0.007
82.06,0.15,-0.007
82.07,0.15,-0.007
82.07,0.16,-0.007
82.07,0.16,-0.007
82.08,0.17,-0.007
82.08,0.17,-0.007
82.08,0.18,-0.007
82.09,0.18,-0.007
82.09,0.19,-0.007
82.09,0.20,-0.007
82.10,0.21,-0.007
82.10,0.21,-0.007
82.10,0.22,-0.007
82.11,0.23,-0.007
82.11,0.25,-0.006
82.11,0.26,-0.005
82.12,0.27,-0.003
82.12,0.28,-0.002
82.12,0.29,0.000
82.13,0.31,0.002
82.13,0.32,0.003
82.13,0.33,0.005
82.14,0.35,0.007
82.14,0.37,0.009
82.14,0.38,0.011
82.15,0.40,0.014
82.15,0.42,0.016
82.15,0.43,0.019
82.16,0.45,0.021
82.16,0.47,0.024
82.16,0.49,0.027
82.17,0.51,0.030
82.17,0.53,0.032
82.17,0.55,0.035
82.18,0.56,0.038
82.18,0.58,0.041
82.18,0.61,0.044
82.19,0.63,0.046
82.19,0.65,0.049
82.19,0.67,0.052
82.20,0.69,0.054
82.20,0.71,0.057
82.20,0.73,0.059
82.21,0.75,0.062
82.21,0.78,0.064
82.21,0.80,0.067
82.22,0.82,0.069
82.22,0.84,0.072
82.22,0.87,0.074
82.23,0.89,0.076
82.23,0.91,0.078
82.23,0.94,0.080
82.24,0.96,0.082
82.24,0.98,0.084
82.24,1.01,0.086
82.25,1.03,0.088
82.25,1.06,0.090
82.25,1.08,0.092
82.26,1.11,0.094
82.26,1.13,0.095
82.26,1.16,0.097
82.27,1.18,0.099
82.27,1.21,0.101
82.27,1.23,0.102
82.28,1.26,0.104
82.28,1.28,0.105
82.28,1.31,0.107
82.29,1.34,0.109
82.29,1.36,0.110
82.29,1.39,0.112
82.30,1.42,0.113
82.30,1.44,0.115
82.30,1.47,0.116
82.31,1.50,0.118
82.31,1.52,0.119
82.31,1.55,0.121
82.32,1.58,0.122
82.32,1.61,0.123
82.32,1.63,0.125
82.33,1.66,0.126
82.33,1.69,0.127
82.33,1.72,0.128
82.34,1.75,0.129
82.34,1.77,0.131
82.34,1.80,0.132
82.35,1.83,0.133
82.35,1.86,0.134
82.35,1.89,0.136
82.36,1.92,0.137
82.36,1.94,0.138
82.36,1.97,0.139
82.37,2.00,0.139
82.37,2.03,0.141
82.37,2.06,0.142
82.38,2.09,0.142
82.38,2.12,0.143
82.38,2.15,0.144
82.39,2.18,0.145
82.39,2.21,0.146
82.39,2.24,0.147
82.40,2.27,0.148
82.40,2.29,0.149
82.40,2.32,0.150
82.41,2.35,0.150
82.41,2.38,0.151
82.41,2.41,0.152
82.42,2.44,0.153
82.42,2.47,0.154
82.42,2.50,0.154
82.43,2.54,0.155
82.43,2.57,0.155
82.43,2.60,0.156
82.44,2.63,0.157
82.44,2.66,0.158
82.44,2.69,0.159
82.45,2.72,0.159
82.45,2.75,0.160
82.45,2.78,0.160
82.46,2.81,0.161
82.46,2.84,0.161
82.46,2.87,0.162
82.47,2.90,0.162
82.47,2.93,0.163
82.47,2.96,0.164
82.48,2.99,0.164
82.48,3.03,0.165
82.48,3.06,0.165
82.49,3.09,0.166
82.49,3.12,0.166
82.49,3.15,0.167
82.50,3.18,0.167
82.50,3.21,0.168
82.50,3.24,0.168
82.51,3.27,0.168
82.51,3.31,0.169
82.51,3.34,0.169
82.52,3.37,0.170
82.52,3.40,0.170
82.52,3.43,0.171
82.53,3.46,0.171
82.53,3.49,0.172
82.53,3.53,0.172
82.54,3.56,0.172
82.54,3.59,0.173
82.54,3.62,0.173
82.55,3.65,0.173
82.55,3.68,0.174
82.55,3.72,0.174
82.56,3.75,0.174
82.56,3.78,0.175
82.56,3.81,0.175
82.57,3.84,0.175
82.57,3.88,0.176
82.57,3.91,0.176
82.58,3.94,0.176
82.58,3.97,0.177
82.58,4.00,0.177
82.59,4.04,0.177
82.59,4.07,0.178
82.59,4.10,0.178
82.60,4.13,0.178
82.60,4.16,0.178
82.60,4.19,0.178
82.61,4.23,0.179
82.61,4.26,0.179
82.61,4.29,0.179
82.62,4.32,0.180
82.62,4.36,0.180
82.62,4.39,0.180
82.63,4.42,0.180
82.63,4.45,0.180
82.63,4.48,0.180
82.64,4.52,0.181
82.64,4.55,0.181
82.64,4.58,0.181
82.65,4.61,0.182
82.65,4.64,0.182
82.65,4.68,0.182
82.66,4.71,0.182
82.66,4.74,0.182
82.66,4.78,0.182
82.67,4.81,0.182
82.67,4.84,0.183
82.67,4.87,0.183
82.68,4.91,0.183
82.68,4.94,0.183
82.68,4.97,0.183
82.69,5.00,0.184
82.69,5.03,0.184
82.69,5.07,0.184
82.70,5.10,0.184
82.70,5.13,0.184
82.70,5.16,0.184
82.71,5.20,0.185
82.71,5.23,0.185
82.71,5.26,0.185
82.72,5.29,0.185
82.72,5.33,0.185
82.72,5.36,0.185
82.73,5.39,0.185
82.73,5.43,0.186
82.73,5.46,0.186
82.74,5.49,0.186
82.74,5.52,0.186
82.74,5.56,0.186
82.75,5.59,0.186
82.75,5.62,0.186
82.75,5.65,0.186
82.76,5.69,0.186
82.76,5.72,0.186
82.76,5.75,0.187
82.77,5.78,0.187
82.77,5.82,0.187
82.77,5.85,0.187
82.78,5.88,0.187
82.78,5.92,0.187
82.78,5.95,0.187
82.79,5.98,0.187
82.79,6.01,0.187
82.79,6.05,0.188
82.80,6.08,0.188
82.80,6.11,0.188
82.80,6.14,0.188
82.81,6.18,0.188
82.81,6.21,0.188
82.81,6.24,0.188
82.82,6.28,0.188
82.82,6.31,0.188
82.82,6.34,0.188
82.83,6.37,0.188
82.83,6.41,0.188
82.83,6.44,0.188
82.84,6.47,0.189
82.84,6.51,0.189
82.84,6.54,0.189
82.85,6.57,0.189
82.85,6.60,0.189
82.85,6.64,0.189
82.86,6.67,0.189
82.86,6.70,0.189
82.86,6.74,0.189
82.87,6.77,0.189
82.87,6.80,0.189
82.87,6.83,0.189
82.88,6.87,0.189
82.88,6.90,0.189
82.88,6.93,0.190
82.89,6.97,0.190
82.89,7.00,0.190
82.89,7.03,0.190
82.90,7.06,0.190
82.90,7.10,0.190
82.90,7.13,0.190
82.91,7.16,0.190
82.91,7.20,0.190
82.91,7.23,0.190
82.92,7.26,0.190
82.92,7.29,0.190
82.92,7.33,0.190
82.93,7.36,0.190
82.93,7.40,0.190
82.93,7.43,0.190
82.94,7.46,0.191
82.94,7.49,0.191
82.94,7.53,0.191
82.95,7.56,0.191
82.95,7.59,0.191
82.95,7.63,0.191
82.96,7.66,0.191
82.96,7.69,0.191
82.96,7.72,0.191
82.97,7.76,0.191
82.97,7.79,0.191
82.97,7.82,0.191
82.98,7.86,0.191
82.98,7.89,0.191
82.98,7.92,0.191
82.99,7.96,0.191
82.99,7.99,0.191
82.99,8.02,0.191
83.00,8.05,0.191
83.00,8.09,0.192
83.00,8.12,0.192
83.01,8.15,0.192
83.01,8.19,0.192
83.01,8.22,0.192
83.02,8.25,0.192
83.02,8.29,0.192
83.02,8.32,0.192
83.03,8.35,0.192
83.03,8.39,0.192
83.03,8.42,0.192
83.04,8.45,0.192
83.04,8.49,0.192
83.04,8.52,0.192
83.05,8.55,0.192
83.05,8.58,0.192
83.05,8.62,0.192
83.06,8.65,0.192
83.06,8.68,0.192
83.06,8.72,0.192
83.07,8.75,0.192
83.07,8.78,0.192
83.07,8.82,0.192
83.08,8.85,0.192
83.08,8.88,0.192
83.08,8.92,0.192
83.09,8.95,0.192
83.09,8.98,0.192
83.09,9.01,0.193
83.10,9.05,0.193
83.10,9.08,0.193
83.10,9.12,0.193
83.11,9.15,0.193
83.11,9.18,0.193
83.11,9.21,0.193
83.12,9.25,0.193
83.12,9.28,0.193
83.12,9.31,0.193
83.13,9.35,0.193
83.13,9.38,0.193
83.13,9.41,0.193
83.14,9.45,0.193
83.14,9.48,0.193
83.14,9.51,0.193
83.15,9.55,0.193
83.15,9.58,0.193
83.15,9.61,0.193
83.16,9.65,0.193
83.16,9.68,0.193
83.16,9.71,0.193
83.17,9.75,0.193
83.17,9.78,0.193
83.17,9.81,0.193
83.18,9.85,0.193
83.18,9.88,0.194
83.18,9.91,0.194
83.19,9.95,0.194
83.19,9.98,0.194
83.19,10.01,0.194
83.20,10.04,0.194
83.20,10.08,0.194
83.20,10.11,0.194
83.21,10.14,0.194
83.21,10.18,0.194
83.21,10.21,0.194
83.22,10.24,0.194
83.22,10.28,0.194
83.22,10.31,0.194
83.23,10.34,0.194
83.23,10.38,0.194
83.23,10.41,0.194
83.24,10.44,0.194
83.24,10.48,0.194
83.24,10.51,0.194
83.25,10.54,0.194
83.25,10.58,0.194
83.25,10.61,0.194
83.26,10.64,0.194
83.26,10.68,0.194
83.26,10.71,0.194
83.27,10.74,0.194
83.27,10.77,0.194
83.27,10.81,0.194
83.28,10.84,0.194
83.28,10.87,0.194
83.28,10.91,0.194
83.29,10.94,0.194
83.29,10.97,0.194
83.29,11.01,0.194
83.30,11.04,0.194
83.30,11.07,0.194
83.30,11.11,0.194
83.31,11.14,0.194
83.31,11.17,0.194
83.31,11.21,0.194
83.32,11.24,0.195
83.32,11.27,0.195
83.32,11.31,0.195
83.33,11.34,0.195
83.33,11.37,0.195
83.33,11.41,0.195
83.34,11.44,0.195
83.34,11.47,0.195
83.34,11.51,0.195
83.35,11.54,0.195
83.35,11.57,0.195
83.35,11.61,0.195
83.36,11.64,0.195
83.36,11.67,0.195
83.36,11.71,0.195
83.37,11.74,0.195
83.37,11.77,0.195
83.37,11.81,0.195
83.38,11.84,0.195
83.38,11.87,0.195
83.38,11.90,0.195
83.39,11.94,0.195
83.39,11.97,0.195
83.39,12.00,0.195
83.40,12.04,0.195
83.40,12.07,0.195
83.40,12.11,0.195
83.41,12.14,0.195
83.41,12.17,0.195
83.41,12.21,0.195
83.42,12.24,0.195
83.42,12.27,0.195
83.42,12.30,0.195
83.43,12.34,0.195
83.43,12.37,0.195
83.43,12.40,0.195
83.44,12.44,0.195
83.44,12.47,0.195
83.44,12.50,0.195
83.45,12.54,0.196
83.45,12.57,0.196
83.45,12.60,0.196
83.46,12.64,0.196
83.46,12.67,0.196
83.46,12.70,0.196
83.47,12.74,0.196
83.47,12.77,0.196
83.47,12.80,0.196
83.48,12.84,0.196
83.48,12.87,0.196
83.48,12.90,0.196
83.49,12.94,0.196
83.49,12.97,0.196
83.49,13.00,0.196
83.50,13.04,0.196
83.50,13.07,0.196
83.50,13.10,0.196
83.51,13.14,0.196
83.51,13.17,0.196
83.51,13.20,0.196
83.52,13.24,0.196
83.52,13.27,0.196
83.52,13.30,0.196
83.53,13.34,0.196
83.53,13.37,0.196
83.53,13.40,0.196
83.54,13.43,0.196
83.54,13.47,0.196
83.54,13.50,0.196
83.55,13.53,0.196
83.55,13.57,0.196
83.55,13.60,0.196
83.56,13.64,0.196
83.56,13.67,0.196
83.56,13.70,0.196
83.57,13.73,0.196
83.57,13.77,0.196
83.57,13.80,0.196
83.58,13.83,0.196
83.58,13.87,0.196
83.58,13.90,0.196
83.59,13.93,0.196
83.59,13.97,0.196
83.59,14.00,0.196
83.60,14.03,0.197
83.60,14.07,0.197
83.60,14.10,0.197
83.61,14.13,0.197
83.61,14.17,0.197
83.61,14.20,0.197
83.62,14.23,0.197
83.62,14.27,0.197
83.62,14.30,0.197
83.63,14.33,0.197
83.63,14.37,0.197
83.63,14.40,0.197
83.64,14.43,0.197
83.64,14.47,0.197
83.64,14.50,0.197
83.65,14.53,0.197
83.65,14.57,0.197
83.65,14.60,0.197
83.66,14.63,0.197
83.66,14.67,0.197
83.66,14.70,0.197
83.67,14.73,0.197
83.67,14.77,0.197
83.67,14.80,0.197
83.68,14.83,0.197
83.68,14.87,0.197
83.68,14.90,0.197
83.69,14.94,0.197
83.69,14.97,0.197
83.69,15.00,0.197
83.70,15.03,0.197
83.70,15.07,0.197
83.70,15.10,0.197
83.71,15.13,0.197
83.71,15.17,0.197
83.71,15.20,0.197
83.72,15.23,0.197
83.72,15.27,0.197
83.72,15.30,0.197
83.73,15.33,0.197
83.73,15.37,0.197
83.73,15.40,0.197
83.74,15.43,0.198
83.74,15.47,0.198
83.74,15.50,0.198
83.75,15.53,0.198
83.75,15.57,0.198
83.75,15.60,0.198
83.76,15.63,0.198
83.76,15.67,0.198
83.76,15.70,0.198
83.77,15.73,0.198
83.77,15.77,0.198
83.77,15.80,0.198
83.78,15.83,0.198
83.78,15.87,0.198
83.78,15.90,0.198
83.79,15.93,0.198
83.79,15.97,0.198
83.79,16.00,0.198
83.80,16.03,0.198
83.80,16.07,0.198
83.80,16.10,0.198
83.81,16.13,0.198
83.81,16.17,0.198
83.81,16.20,0.198
83.82,16.23,0.198
83.82,16.27,0.198
83.82,16.30,0.198
83.83,16.33,0.198
83.83,16.37,0.198
83.83,16.40,0.198
83.84,16.43,0.198
83.84,16.47,0.198
83.84,16.50,0.198
83.85,16.53,0.198
83.85,16.57,0.198
83.85,16.60,0.198
83.86,16.63,0.198
83.86,16.67,0.198
83.86,16.70,0.198
83.87,16.73,0.198
83.87,16.77,0.198
83.87,16.80,0.198
83.88,16.83,0.198
83.88,16.87,0.198
83.88,16.90,0.198
83.89,16.93,0.198
83.89,16.97,0.199
83.89,17.00,0.199
83.90,17.03,0.199
83.90,17.07,0.199
83.90,17.10,0.199
83.91,17.13,0.199
83.91,17.17,0.199
83.91,17.20,0.199
83.92,17.23,0.199
83.92,17.27,0.199
83.92,17.30,0.199
83.93,17.33,0.199
83.93,17.37,0.199
83.93,17.40,0.199
83.94,17.43,0.199
83.94,17.47,0.199
83.94,17.50,0.199
83.95,17.53,0.199
83.95,17.57,0.199
83.95,17.60,0.199
83.96,17.63,0.199
83.96,17.67,0.199
83.96,17.70,0.199
83.97,17.73,0.199
83.97,17.77,0.199
83.97,17.80,0.199
83.98,17.83,0.199
83.98,17.87,0.199
83.98,17.90,0.199
83.99,17.93,0.199
83.99,17.97,0.199
83.99,18.00,0.199
84.00,18.03,0.199
84.00,18.07,0.199
84.00,18.10,0.199
84.01,18.13,0.199
84.01,18.17,0.199
84.01,18.20,0.199
84.02,18.23,0.200
84.02,18.27,0.200
84.02,18.30,0.200
84.03,18.33,0.200
84.03,18.37,0.200
84.03,18.40,0.200
84.04,18.43,0.200
84.04,18.47,0.200
84.04,18.50,0.200
84.05,18.53,0.200
84.05,18.57,0.200
84.05,18.60,0.200
84.06,18.63,0.200
84.06,18.67,0.200
84.06,18.70,0.200
84.07,18.73,0.200
84.07,18.77,0.200
84.07,18.80,0.200
84.08,18.83,0.200
84.08,18.87,0.200
84.08,18.90,0.200
84.09,18.93,0.200
84.09,18.97,0.200
84.09,19.00,0.200
84.10,19.03,0.200
84.10,19.07,0.200
84.10,19.10,0.200
84.11,19.13,0.200
84.11,19.17,0.200
84.11,19.20,0.200
84.12,19.23,0.200
84.12,19.27,0.200
84.12,19.30,0.200
84.13,19.33,0.200
84.13,19.37,0.200
84.13,19.40,0.200
84.14,19.43,0.200
84.14,19.47,0.200
84.14,19.50,0.200
84.15,19.53,0.200
84.15,19.57,0.200
84.15,19.60,0.200
84.16,19.63,0.200
84.16,19.67,0.201
84.16,19.70,0.201
84.17,19.73,0.201
84.17,19.77,0.201
84.17,19.80,0.201
84.18,19.83,0.201
84.18,19.87,0.201
84.18,19.90,0.201
84.19,19.93,0.201
84.19,19.97,0.201
84.19,20.00,0.201
84.20,20.03,0.201
84.20,20.07,0.201
84.20,20.10,0.201
84.21,20.13,0.201
84.21,20.17,0.201
84.21,20.20,0.201
84.22,20.23,0.201
84.22,20.27,0.201
84.22,20.30,0.201
84.23,20.33,0.201
84.23,20.37,0.201
84.23,20.40,0.201
84.24,20.43,0.201
84.24,20.47,0.201
84.24,20.50,0.201
84.25,20.53,0.201
84.25,20.57,0.201
84.25,20.60,0.201
84.26,20.63,0.201
84.26,20.67,0.201
84.26,20.70,0.201
84.27,20.74,0.201
84.27,20.77,0.201
84.27,20.80,0.201
84.28,20.84,0.201
84.28,20.87,0.201
84.28,20.90,0.201
84.29,20.93,0.201
84.29,20.97,0.201
84.29,21.00,0.201
84.30,21.04,0.201
84.30,21.07,0.201
84.30,21.10,0.201
84.31,21.14,0.201
84.31,21.17,0.201
84.31,21.20,0.201
84.32,21.24,0.201
84.32,21.27,0.201
84.32,21.30,0.201
84.33,21.33,0.202
84.33,21.37,0.202
84.33,21.40,0.202
84.34,21.43,0.202
84.34,21.47,0.202
84.34,21.50,0.202
84.35,21.53,0.202
84.35,21.57,0.202
84.35,21.60,0.202
84.36,21.63,0.202
84.36,21.67,0.202
84.36,21.70,0.202
84.37,21.74,0.202
84.37,21.77,0.202
84.37,21.80,0.202
84.38,21.84,0.202
84.38,21.87,0.202
84.38,21.90,0.202
84.39,21.94,0.202
84.39,21.97,0.202
84.39,22.00,0.202
84.40,22.03,0.202
84.40,22.07,0.202
84.40,22.10,0.202
84.41,22.13,0.202
84.41,22.17,0.202
84.41,22.20,0.202
84.42,22.24,0.202
84.42,22.27,0.202
84.42,22.30,0.202
84.43,22.34,0.202
84.43,22.37,0.202
84.43,22.40,0.202
84.44,22.44,0.202
84.44,22.47,0.202
84.44,22.50,0.202
84.45,22.54,0.202
84.45,22.57,0.202
84.45,22.60,0.202
84.46,22.64,0.202
84.46,22.67,0.202
84.46,22.70,0.202
84.47,22.74,0.202
84.47,22.77,0.202
84.47,22.80,0.202
84.48,22.84,0.202
84.48,22.87,0.202
84.48,22.90,0.203
84.49,22.94,0.203
84.49,22.97,0.203
84.49,23.00,0.203
84.50,23.04,0.203
84.50,23.07,0.203
84.50,23.10,0.203
84.51,23.14,0.203
84.51,23.17,0.203
84.51,23.20,0.203
84.52,23.24,0.203
84.52,23.27,0.203
84.52,23.30,0.203
84.53,23.34,0.203
84.53,23.37,0.203
84.53,23.40,0.203
84.54,23.44,0.203
84.54,23.47,0.203
84.54,23.50,0.203
84.55,23.54,0.203
84.55,23.57,0.203
84.55,23.60,0.203
84.56,23.64,0.203
84.56,23.67,0.203
84.56,23.70,0.203
84.57,23.74,0.203
84.57,23.77,0.203
84.57,23.80,0.203
84.58,23.84,0.203
84.58,23.87,0.203
84.58,23.90,0.203
84.59,23.94,0.203
84.59,23.97,0.203
84.59,24.00,0.203
84.60,24.04,0.203
84.60,24.07,0.203
84.60,24.10,0.203
84.61,24.14,0.203
84.61,24.17,0.203
84.61,24.20,0.203
84.62,24.24,0.203
84.62,24.27,0.203
84.62,24.30,0.203
84.63,24.34,0.203
84.63,24.37,0.203
84.63,24.40,0.203
84.64,24.44,0.203
84.64,24.47,0.203
84.64,24.50,0.203
84.65,24.54,0.204
84.65,24.57,0.204
84.65,24.60,0.204
84.66,24.64,0.204
84.66,24.67,0.204
84.66,24.70,0.204
84.67,24.74,0.204
84.67,24.77,0.204
84.67,24.80,0.204
84.68,24.84,0.204
84.68,24.87,0.204
84.68,24.90,0.204
84.69,24.94,0.204
84.69,24.97,0.204
84.69,25.00,0.204
84.70,25.04,0.204
84.70,25.07,0.204
84.70,25.10,0.204
84.71,25.14,0.204
84.71,25.17,0.204
84.71,25.20,0.204
84.72,25.24,0.204
84.72,25.27,0.204
84.72,25.30,0.204
84.73,25.34,0.204
84.73,25.37,0.204
84.73,25.40,0.204
84.74,25.44,0.204
84.74,25.47,0.204
84.74,25.50,0.204
84.75,25.54,0.204
84.75,25.57,0.204
84.75,25.60,0.204
84.76,25.64,0.204
84.76,25.67,0.204
84.76,25.70,0.204
84.77,25.74,0.204
84.77,25.77,0.204
84.77,25.80,0.204
84.78,25.84,0.204
84.78,25.87,0.204
84.78,25.90,0.204
84.79,25.94,0.204
84.79,25.97,0.205
84.79,26.00,0.205
84.80,26.04,0.205
84.80,26.07,0.205
84.80,26.10,0.205
84.81,26.14,0.205
84.81,26.17,0.205
84.81,26.20,0.205
84.82,26.24,0.205
84.82,26.27,0.205
84.82,26.30,0.205
84.83,26.34,0.205
84.83,26.37,0.205
84.83,26.40,0.205
84.84,26.44,0.205
84.84,26.47,0.205
84.84,26.51,0.205
84.85,26.54,0.205
84.85,26.57,0.205
84.85,26.60,0.205
84.86,26.64,0.205
84.86,26.67,0.205
84.86,26.70,0.205
84.87,26.74,0.205
84.87,26.77,0.205
84.87,26.80,0.205
84.88,26.84,0.205
84.88,26.87,0.205
84.88,26.90,0.205
84.89,26.94,0.205
84.89,26.97,0.205
84.89,27.00,0.205
84.90,27.04,0.205
84.90,27.07,0.205
84.90,27.10,0.205
84.91,27.14,0.205
84.91,27.17,0.205
84.91,27.20,0.205
84.92,27.24,0.205
84.92,27.27,0.205
84.92,27.30,0.205
84.93,27.34,0.206
84.93,27.37,0.206
84.93,27.40,0.206
84.94,27.44,0.206
84.94,27.47,0.206
84.94,27.51,0.206
84.95,27.54,0.206
84.95,27.57,
84.95,27.61,
84.96,27.64,
84.96,27.67,
84.96,27.71,
84.97,27.74,
84.97,27.77,
84.97,27.80,
84.98,27.84,
84.98,27.87,
84.98,27.91,
84.99,27.94,
84.99,27.97,
84.99,28.01,
85.00,28.04,
85.00,,
85.00,,
85.00,,