File: DSC/2025_06_28_CBD_Benzoic_Acid_n60_150_10C_min_x4.csv
Filename,2025_06_28_CBD_Benzoic_Acid_n60_150_10C_min_x4
Instrument name,DSC2A-00468 (192.168.1.100)
Operator,Yarger
rundate,6/29/2025
Sample name,2025_06_28_CBD_Benzoic_Acid_n60_150_10C_min_x4
proceduresegments,Data Off ; Equilibrate -60.00 °C; Data On ; Ramp 10.00 °C/min to 150.00 °C; Data Off ; Isothermal 2.0 min; Data On ; Ramp 10.00 °C/min to -60.00 °C; Data Off ; Isothermal 2.0 min; Data On ; Ramp 10.00 °C/min to 150.00 °C; Data Off ; Isothermal 2.0 min; Data On ; Ramp 10.00 °C/min to -60.00 °C; Data Off ; Isothermal 2.0 min; Data On ; Ramp 10.00 °C/min to 150.00 °C; Data Off ; Isothermal 2.0 min; Data On ; Ramp 10.00 °C/min to -60.00 °C; Data Off ; Isothermal 2.0 min; Data On ; Ramp 10.00 °C/min to 30.00 °C
[File Parameters]
Run date,6/29/2025 6:41:20 PM
Trios version,5.1.1.46572
Original File Name,
Current File Name,D:\DSC2500\Gibbons\2025_06_28_CBD_Benzoic_Acid_n60_150_10C_min_x4.tri
[Procedure]
Procedure Name,CBD_Benzoic_Acid_n60_150_10C_min_x4
Sample Name,2025_06_28_CBD_Benzoic_Acid_n60_150_10C_min_x4
Sample Mass,4.51 mg
Reference Sample Mass,0 mg
Pan Mass,56.63 mg
Pan Number,30
Reference Pan Mass,56.76 mg
Reference Pan Number,10
Pan Type,Tzero Aluminum Hermetic
Comments,Al Hermetic DSC Consumables sealed Pan/Lid. Y1 Tray (Google Sheet: DSC_Samples_Y1_Tray_June2025). Run AFTER failed/leaked DSC pan #25 was removed and DSC was cleaned and baseline and stds checked.
Project Name,CA
Operator,Yarger
Test,Custom
Unload Max Temperature,30
Unload Min Temperature,30
Load Max Temperature,30
Load Min Temperature,30
Stop on Gas Flow Error,Yes
[Signal List]
Signal #1,Time (min)
Signal #2,Temperature (°C)
Signal #3,Heat Flow (mW)
Signal #4,Delta T (µV)
Signal #5,Delta Tzero (µV)
Signal #6,Tzero Temperature (°C)
Signal #7,Cell Purge (mL/min)
Signal #8,Heater Temp (°C)
Signal #9,Power Delivered (W)
Signal #10,Reference Junction Temperature (°C)
Signal #11,Flange Temperature (°C)
Signal #12,Heat Flow Phase (rad)
Signal #13,Total Heat Capacity (J/°C)
Signal #14,Heat Capacity (J/°C)
[Configuration]
Company Name,ASU
Instrument Name,DSC2A-00468
Instrument Type,DSC2500
Serial Number,DSC2A-00468
IP,192.168.1.100
Location of Instrument,MRRC
DisplayType,Unknown
Sample Interval ,0.1 s/pt
Selected Heat Flow,T4P
Exotherm Direction,Down
Cell Serial,DRC2-00792
Lid Type,Standard
Cooler,RCS 90
Leave Cooler on at End of Sequence,On
Gas 2,Nitrogen
Gas Selected,Channel 1
Flow Rate,50 mL/min
Secondary Purge,On
Licensed Heat Flow,Heat Flow T4P
Modulation Licensed,Yes
[Versions]
Common IDD Version,1
Cortex Version,VER 2.10.2.31
Driver,5.0.0.6
GDM Version,1.0.3.3
TouchscreenVersion,1.0.0.16145
FEP Version,1.2.1.21
FEP Bootloader,2.0.0.5
AutoSampler Version,2.1.1.26
Auto Sampler Bootloader,2.0.0.5
FCM Version,1.1.0.3
FCM Bootloader,2.0.0.5
[Experiment Logs]
Experiment Log Entry # 1,Air Cool is off.
Experiment Log Entry # 3,Data On set to 0
Experiment Log Entry # 5,Equilibrate Segment -60 (C) Started
Experiment Log Entry # 7,Data On set to 1
Experiment Log Entry # 9,Ramp Segment 10 C/min to 150 Started
Experiment Log Entry # 11,Data On set to 0
Experiment Log Entry # 13,Isothermal Segment 2 min started
Experiment Log Entry # 15,Data On set to 1
Experiment Log Entry # 17,Ramp Segment 10 C/min to -60 Started
Experiment Log Entry # 19,Data On set to 0
Experiment Log Entry # 21,Isothermal Segment 2 min started
Experiment Log Entry # 23,Data On set to 1
Experiment Log Entry # 25,Ramp Segment 10 C/min to 150 Started
Experiment Log Entry # 27,Data On set to 0
Experiment Log Entry # 29,Isothermal Segment 2 min started
Experiment Log Entry # 31,Data On set to 1
Experiment Log Entry # 33,Ramp Segment 10 C/min to -60 Started
Experiment Log Entry # 35,Data On set to 0
Experiment Log Entry # 37,Isothermal Segment 2 min started
Experiment Log Entry # 39,Data On set to 1
Experiment Log Entry # 41,Ramp Segment 10 C/min to 150 Started
Experiment Log Entry # 43,Data On set to 0
Experiment Log Entry # 45,Isothermal Segment 2 min started
Experiment Log Entry # 47,Data On set to 1
Experiment Log Entry # 49,Ramp Segment 10 C/min to -60 Started
Experiment Log Entry # 51,Data On set to 0
Experiment Log Entry # 53,Isothermal Segment 2 min started
Experiment Log Entry # 55,Data On set to 1
Experiment Log Entry # 57,Ramp Segment 10 C/min to 30 Started
[Method Log]
Method Log Entry # 1,Data Off
Method Log Entry # 2,Equilibrate -60 °C
Method Log Entry # 3,Data On
Method Log Entry # 4,(Ramp 735727) Ramp 10 °C/minute to 150 °C
Method Log Entry # 5,Data Off
Method Log Entry # 6,Isothermal 2 minutes
Method Log Entry # 7,Data On
Method Log Entry # 8,(Ramp 735731) Ramp 10 °C/minute to -60 °C
Method Log Entry # 9,Data Off
Method Log Entry # 10,Isothermal 2 minutes
Method Log Entry # 11,Data On
Method Log Entry # 12,(Ramp 735735) Ramp 10 °C/minute to 150 °C
Method Log Entry # 13,Data Off
Method Log Entry # 14,Isothermal 2 minutes
Method Log Entry # 15,Data On
Method Log Entry # 16,(Ramp 735739) Ramp 10 °C/minute to -60 °C
Method Log Entry # 17,Data Off
Method Log Entry # 18,Isothermal 2 minutes
Method Log Entry # 19,Data On
Method Log Entry # 20,(Ramp 735743) Ramp 10 °C/minute to 150 °C
Method Log Entry # 21,Data Off
Method Log Entry # 22,Isothermal 2 minutes
Method Log Entry # 23,Data On
Method Log Entry # 24,(Ramp 735747) Ramp 10 °C/minute to -60 °C
Method Log Entry # 25,Data Off
Method Log Entry # 26,Isothermal 2 minutes
Method Log Entry # 27,Data On
Method Log Entry # 28,(Ramp 735751) Ramp 10 °C/minute to 30 °C
Cell Serial,DRC2-00792
[T1 Calibration]
Slope,-0.008529666
Offset,9.636258
Initial Temperature,98.23
GUID,f8bfdadc-4977-4fdf-ba6d-0ba9134940c3
[TZero Calibration]
Date Applied,11/29/2022 4:06:13 PM
Description,From -89.059 °C to 396.009 °C at 20.000°C/min
Gas Type,Nitrogen
Pan Type,None
Source Files 1,C:\Users\yargerlab\Desktop\DSC Data\General\TZero_calibration_11_29_22_2nd(2).tri
Source Files 2,C:\Users\yargerlab\Desktop\DSC Data\General\TZero_calibration_11_29_22_2nd(3).tri
Delta T Offset,13.05235
Delta T Slope,-0.007271007
Delta T0 Offset,-13.69128
Delta T0 Slope,0.06063341
[Temperature Calibration]
Date Applied,11/29/2022 7:12:28 PM
Description,From 106.590 °C to 186.590 °C at 10.000°C/min
Gas Type,Nitrogen
Pan Type,Tzero Aluminum Hermetic
Source Files 1,C:\Users\yargerlab\Desktop\DSC Data\General\Indium(6).tri
Measured 1,157.391
Known 1,156.598
[Cell Constant Calibration]
Date Applied,11/29/2022 7:12:29 PM
Description,From 106.590 °C to 186.590 °C at 10.000°C/min
Gas Type,Nitrogen
Pan Type,Tzero Aluminum Hermetic
Source Files 1,C:\Users\yargerlab\Desktop\DSC Data\General\Indium(6).tri
T4P KCell,1.006051
Onset Slope,63.26126 mW/°C
[Direct Cp Calibration]
Date Applied,11/30/2022 11:04:51 AM
Description,From -79.983 °C to 298.409 °C at 10.000°C/min
Gas Type,Nitrogen
Pan Type,Tzero Aluminum Hermetic
Source Files 1,C:\Users\yargerlab\Desktop\DSC Data\General\Sapphire_Heat_Capacity_11_30_22.tri
[Rev Cp Calibration]
Date Applied,11/30/2022 1:58:51 PM
Description,From -79.996 °C to 292.812 °C at 3.000°C/min
Gas Type,Nitrogen
Pan Type,Tzero Aluminum Hermetic
Source Files 1,C:\Users\yargerlab\Desktop\DSC Data\General\Sapphire_MDSC_Calibration_11_30_22.tri
[step]
Ramp 10.00 °C/min to 150.00 °C
Time,Temperature,Heat Flow (Normalized)
min,°C,W/g
0.00,-59.71,-0.042
0.01,-59.73,-0.041
0.03,-59.73,-0.038
0.05,-59.74,-0.034
0.06,-59.73,-0.030
0.08,-59.71,-0.026
0.09,-59.68,-0.021
0.11,-59.64,-0.015
0.12,-59.59,-0.005
0.14,-59.52,0.005
0.15,-59.44,0.019
0.16,-59.35,0.032
0.18,-59.25,0.045
0.19,-59.15,0.058
0.21,-59.04,0.073
0.23,-58.92,0.086
0.24,-58.80,0.095
0.26,-58.67,0.106
0.27,-58.55,0.113
0.29,-58.42,0.123
0.30,-58.29,0.131
0.31,-58.15,0.136
0.33,-58.02,0.139
0.35,-57.88,0.146
0.36,-57.75,0.149
0.38,-57.61,0.153
0.39,-57.47,0.156
0.40,-57.33,0.158
0.42,-57.19,0.161
0.44,-57.05,0.163
0.45,-56.90,0.165
0.46,-56.76,0.166
0.48,-56.62,0.168
0.50,-56.47,0.169
0.51,-56.33,0.169
0.53,-56.18,0.171
0.54,-56.04,0.172
0.55,-55.89,0.172
0.57,-55.75,0.173
0.58,-55.60,0.173
0.60,-55.46,0.174
0.62,-55.31,0.174
0.63,-55.16,0.174
0.65,-55.02,0.175
0.66,-54.87,0.176
0.68,-54.72,0.176
0.69,-54.58,0.176
0.70,-54.43,0.176
0.72,-54.28,0.177
0.73,-54.14,0.177
0.75,-53.99,0.177
0.77,-53.84,0.178
0.78,-53.69,0.178
0.80,-53.54,0.178
0.81,-53.39,0.178
0.83,-53.25,0.178
0.84,-53.10,0.179
0.85,-52.95,0.179
0.87,-52.80,0.179
0.88,-52.65,0.180
0.90,-52.50,0.180
0.92,-52.35,0.180
0.93,-52.21,0.180
0.95,-52.06,0.180
0.96,-51.91,0.181
0.98,-51.76,0.181
0.99,-51.61,0.181
1.00,-51.46,0.181
1.02,-51.32,0.181
1.03,-51.17,0.181
1.05,-51.02,0.181
1.07,-50.87,0.181
1.08,-50.72,0.182
1.09,-50.57,0.182
1.11,-50.42,0.182
1.13,-50.27,0.182
1.14,-50.12,0.182
1.16,-49.97,0.182
1.17,-49.83,0.182
1.18,-49.67,0.182
1.20,-49.52,0.182
1.22,-49.38,0.182
1.23,-49.23,0.183
1.24,-49.08,0.183
1.26,-48.93,0.183
1.28,-48.78,0.183
1.29,-48.63,0.183
1.31,-48.48,0.183
1.32,-48.33,0.183
1.33,-48.18,0.183
1.35,-48.03,0.183
1.37,-47.88,0.183
1.38,-47.73,0.183
1.39,-47.58,0.183
1.41,-47.43,0.183
1.43,-47.28,0.183
1.44,-47.13,0.183
1.46,-46.98,0.183
1.47,-46.83,0.184
1.48,-46.68,0.184
1.50,-46.53,0.184
1.52,-46.38,0.184
1.53,-46.23,0.184
1.54,-46.08,0.184
1.56,-45.93,0.184
1.58,-45.78,0.184
1.59,-45.63,0.184
1.61,-45.48,0.184
1.62,-45.33,0.184
1.63,-45.18,0.184
1.65,-45.03,0.184
1.67,-44.88,0.184
1.68,-44.73,0.184
1.69,-44.58,0.184
1.71,-44.43,0.184
1.73,-44.28,0.184
1.74,-44.13,0.184
1.76,-43.98,0.184
1.77,-43.83,0.184
1.78,-43.68,0.184
1.80,-43.53,0.184
1.82,-43.38,0.184
1.83,-43.23,0.184
1.84,-43.08,0.184
1.86,-42.93,0.184
1.88,-42.78,0.184
1.89,-42.63,0.184
1.91,-42.48,0.184
1.92,-42.33,0.184
1.93,-42.18,0.185
1.95,-42.03,0.185
1.97,-41.88,0.184
1.98,-41.73,0.185
1.99,-41.58,0.185
2.01,-41.43,0.185
2.03,-41.28,0.185
2.04,-41.13,0.185
2.06,-40.98,0.185
2.07,-40.83,0.185
2.08,-40.68,0.185
2.10,-40.53,0.185
2.12,-40.38,0.185
2.13,-40.23,0.185
2.14,-40.08,0.185
2.16,-39.93,0.185
2.18,-39.78,0.185
2.19,-39.63,0.185
2.21,-39.48,0.185
2.22,-39.33,0.185
2.24,-39.18,0.185
2.25,-39.03,0.185
2.26,-38.88,0.185
2.28,-38.73,0.185
2.29,-38.58,0.185
2.31,-38.42,0.185
2.33,-38.28,0.185
2.34,-38.13,0.185
2.36,-37.97,0.185
2.37,-37.82,0.185
2.39,-37.68,0.185
2.40,-37.52,0.185
2.41,-37.37,0.185
2.43,-37.22,0.185
2.44,-37.07,0.185
2.46,-36.92,0.185
2.48,-36.77,0.185
2.49,-36.62,0.185
2.51,-36.47,0.185
2.52,-36.32,0.185
2.54,-36.17,0.185
2.55,-36.02,0.185
2.56,-35.87,0.185
2.58,-35.72,0.185
2.59,-35.57,0.186
2.61,-35.42,0.186
2.63,-35.27,0.186
2.64,-35.12,0.186
2.66,-34.97,0.186
2.67,-34.82,0.186
2.69,-34.67,0.186
2.70,-34.52,0.186
2.71,-34.37,0.186
2.73,-34.22,0.186
2.74,-34.07,0.186
2.76,-33.92,0.186
2.78,-33.77,0.186
2.79,-33.62,0.186
2.81,-33.47,0.186
2.82,-33.32,0.186
2.84,-33.17,0.186
2.85,-33.02,0.186
2.86,-32.87,0.186
2.88,-32.72,0.186
2.89,-32.57,0.186
2.91,-32.41,0.186
2.93,-32.27,0.186
2.94,-32.12,0.186
2.96,-31.97,0.186
2.97,-31.81,0.186
2.99,-31.67,0.186
3.00,-31.51,0.186
3.01,-31.37,0.186
3.03,-31.21,0.186
3.04,-31.06,0.186
3.06,-30.91,0.186
3.08,-30.76,0.186
3.09,-30.61,0.186
3.11,-30.46,0.186
3.12,-30.31,0.186
3.14,-30.16,0.187
3.15,-30.01,0.187
3.16,-29.86,0.187
3.18,-29.71,0.187
3.19,-29.56,0.187
3.21,-29.41,0.187
3.23,-29.26,0.187
3.24,-29.11,0.187
3.26,-28.96,0.187
3.27,-28.81,0.187
3.29,-28.66,0.187
3.30,-28.51,0.187
3.31,-28.36,0.187
3.33,-28.21,0.187
3.34,-28.06,0.187
3.36,-27.91,0.187
3.38,-27.76,0.187
3.39,-27.61,0.187
3.41,-27.46,0.187
3.42,-27.31,0.187
3.44,-27.16,0.187
3.45,-27.01,0.187
3.46,-26.86,0.188
3.48,-26.71,0.188
3.49,-26.56,0.188
3.51,-26.41,0.188
3.53,-26.26,0.188
3.54,-26.11,0.188
3.56,-25.95,0.188
3.57,-25.81,0.188
3.59,-25.66,0.188
3.60,-25.51,0.188
3.61,-25.36,0.188
3.63,-25.20,0.188
3.64,-25.05,0.188
3.66,-24.90,0.188
3.68,-24.75,0.188
3.69,-24.60,0.188
3.71,-24.45,0.188
3.72,-24.30,0.188
3.74,-24.15,0.188
3.75,-24.00,0.188
3.76,-23.85,0.188
3.78,-23.70,0.188
3.79,-23.55,0.188
3.81,-23.40,0.189
3.83,-23.25,0.189
3.84,-23.10,0.189
3.86,-22.95,0.189
3.87,-22.80,0.189
3.89,-22.65,0.189
3.90,-22.50,0.189
3.91,-22.35,0.189
3.93,-22.20,0.189
3.94,-22.05,0.189
3.96,-21.90,0.189
3.98,-21.75,0.189
3.99,-21.60,0.189
4.01,-21.45,0.189
4.02,-21.30,0.189
4.04,-21.15,0.189
4.05,-21.00,0.189
4.06,-20.85,0.189
4.08,-20.70,0.189
4.09,-20.55,0.190
4.11,-20.40,0.190
4.13,-20.25,0.190
4.14,-20.10,0.190
4.16,-19.95,0.190
4.17,-19.80,0.190
4.19,-19.65,0.190
4.20,-19.50,0.190
4.21,-19.35,0.190
4.23,-19.20,0.190
4.24,-19.05,0.190
4.26,-18.90,0.190
4.28,-18.75,0.190
4.29,-18.59,0.190
4.30,-18.44,0.190
4.32,-18.29,0.190
4.34,-18.14,0.190
4.35,-18.00,0.190
4.36,-17.84,0.190
4.38,-17.69,0.190
4.40,-17.54,0.190
4.41,-17.39,0.191
4.43,-17.24,0.191
4.44,-17.09,0.191
4.45,-16.94,0.191
4.47,-16.79,0.191
4.49,-16.64,0.191
4.50,-16.49,0.191
4.51,-16.34,0.191
4.53,-16.19,0.191
4.55,-16.04,0.191
4.56,-15.89,0.191
4.58,-15.74,0.191
4.59,-15.59,0.191
4.60,-15.44,0.191
4.62,-15.29,0.191
4.64,-15.14,0.191
4.65,-14.99,0.191
4.66,-14.84,0.191
4.68,-14.69,0.191
4.70,-14.54,0.191
4.71,-14.39,0.191
4.73,-14.24,0.191
4.74,-14.09,0.192
4.75,-13.94,0.192
4.77,-13.79,0.192
4.79,-13.64,0.192
4.80,-13.49,0.192
4.81,-13.34,0.192
4.83,-13.19,0.192
4.85,-13.04,0.192
4.86,-12.89,0.192
4.88,-12.74,0.192
4.89,-12.59,0.192
4.90,-12.44,0.192
4.92,-12.29,0.192
4.94,-12.14,0.192
4.95,-11.99,0.192
4.96,-11.84,0.192
4.98,-11.69,0.192
5.00,-11.54,0.192
5.01,-11.39,0.192
5.03,-11.24,0.192
5.04,-11.09,0.192
5.05,-10.94,0.193
5.07,-10.79,0.193
5.09,-10.64,0.193
5.10,-10.49,0.193
5.11,-10.34,0.193
5.13,-10.18,0.193
5.15,-10.03,0.193
5.16,-9.88,0.193
5.18,-9.73,0.193
5.19,-9.58,0.193
5.20,-9.43,0.193
5.22,-9.28,0.193
5.24,-9.13,0.193
5.25,-8.98,0.193
5.26,-8.83,0.193
5.28,-8.68,0.193
5.30,-8.53,0.193
5.31,-8.38,0.193
5.33,-8.23,0.193
5.34,-8.08,0.194
5.35,-7.93,0.194
5.37,-7.78,0.194
5.39,-7.63,0.194
5.40,-7.48,0.194
5.41,-7.33,0.194
5.43,-7.18,0.194
5.45,-7.03,0.194
5.46,-6.88,0.194
5.48,-6.73,0.194
5.49,-6.58,0.194
5.50,-6.43,0.194
5.52,-6.28,0.194
5.54,-6.13,0.194
5.55,-5.98,0.194
5.56,-5.83,0.194
5.58,-5.68,0.194
5.60,-5.53,0.195
5.61,-5.38,0.195
5.63,-5.23,0.195
5.64,-5.08,0.195
5.65,-4.93,0.195
5.67,-4.78,0.195
5.69,-4.63,0.195
5.70,-4.48,0.195
5.71,-4.33,0.195
5.73,-4.17,0.195
5.75,-4.03,0.195
5.76,-3.88,0.195
5.78,-3.73,0.196
5.79,-3.58,0.196
5.80,-3.43,0.196
5.82,-3.28,0.196
5.84,-3.12,0.196
5.85,-2.97,0.196
5.86,-2.82,0.196
5.88,-2.68,0.196
5.90,-2.53,0.196
5.91,-2.37,0.196
5.93,-2.22,0.196
5.94,-2.07,0.196
5.95,-1.92,0.196
5.97,-1.77,0.196
5.99,-1.62,0.196
6.00,-1.47,0.197
6.01,-1.32,0.197
6.03,-1.17,0.197
6.05,-1.02,0.197
6.06,-0.87,0.197
6.08,-0.72,0.197
6.09,-0.57,0.197
6.10,-0.42,0.197
6.12,-0.27,0.197
6.14,-0.12,0.197
6.15,0.03,0.197
6.16,0.18,0.197
6.18,0.33,0.197
6.20,0.48,0.197
6.21,0.63,0.198
6.23,0.78,0.198
6.24,0.93,0.198
6.25,1.08,0.198
6.27,1.23,0.198
6.29,1.38,0.198
6.30,1.53,0.198
6.31,1.68,0.198
6.33,1.83,0.198
6.35,1.98,0.198
6.36,2.13,0.198
6.38,2.28,0.198
6.39,2.43,0.198
6.40,2.58,0.198
6.42,2.73,0.198
6.44,2.88,0.198
6.45,3.03,0.199
6.46,3.18,0.199
6.48,3.33,0.199
6.50,3.48,0.199
6.51,3.63,0.199
6.53,3.79,0.199
6.54,3.94,0.199
6.55,4.08,0.199
6.57,4.24,0.199
6.59,4.39,0.199
6.60,4.54,0.199
6.61,4.69,0.199
6.63,4.84,0.199
6.65,4.99,0.200
6.66,5.14,0.200
6.68,5.29,0.200
6.69,5.44,0.200
6.70,5.59,0.200
6.72,5.74,0.200
6.74,5.89,0.200
6.75,6.04,0.200
6.76,6.19,0.200
6.78,6.34,0.200
6.80,6.49,0.200
6.81,6.64,0.200
6.83,6.79,0.200
6.84,6.94,0.201
6.85,7.09,0.201
6.87,7.24,0.201
6.89,7.39,0.201
6.90,7.54,0.201
6.91,7.69,0.201
6.93,7.84,0.201
6.95,7.99,0.201
6.96,8.14,0.201
6.98,8.29,0.201
6.99,8.44,0.201
7.00,8.59,0.201
7.02,8.74,0.201
7.04,8.89,0.202
7.05,9.04,0.202
7.06,9.19,0.202
7.08,9.34,0.202
7.10,9.49,0.202
7.11,9.64,0.202
7.13,9.79,0.202
7.14,9.94,0.202
7.15,10.09,0.202
7.17,10.24,0.203
7.19,10.39,0.203
7.20,10.54,0.203
7.21,10.69,0.203
7.23,10.84,0.203
7.25,10.99,0.203
7.26,11.14,0.203
7.28,11.29,0.203
7.29,11.45,0.203
7.30,11.59,0.203
7.32,11.74,0.203
7.34,11.89,0.203
7.35,12.04,0.203
7.36,12.20,0.204
7.38,12.35,0.204
7.40,12.50,0.204
7.41,12.65,0.204
7.43,12.80,0.204
7.44,12.95,0.204
7.45,13.10,0.204
7.47,13.25,0.204
7.49,13.40,0.204
7.50,13.55,0.204
7.51,13.70,0.205
7.53,13.85,0.205
7.55,14.00,0.205
7.56,14.15,0.205
7.58,14.30,0.205
7.59,14.45,0.205
7.60,14.60,0.205
7.62,14.75,0.205
7.64,14.90,0.205
7.65,15.05,0.205
7.66,15.20,0.206
7.68,15.35,0.206
7.70,15.50,0.206
7.71,15.65,0.206
7.73,15.80,0.206
7.74,15.95,0.206
7.75,16.10,0.206
7.77,16.25,0.206
7.79,16.40,0.206
7.80,16.55,0.206
7.81,16.70,0.207
7.83,16.85,0.207
7.85,17.00,0.207
7.86,17.15,0.207
7.88,17.30,0.207
7.89,17.45,0.207
7.90,17.60,0.207
7.92,17.75,0.207
7.94,17.90,0.207
7.95,18.05,0.207
7.96,18.20,0.207
7.98,18.35,0.208
8.00,18.50,0.208
8.01,18.65,0.208
8.03,18.80,0.208
8.04,18.95,0.208
8.05,19.10,0.208
8.07,19.25,0.208
8.09,19.40,0.208
8.10,19.55,0.208
8.11,19.70,0.208
8.13,19.85,0.209
8.15,20.00,0.209
8.16,20.15,0.209
8.18,20.30,0.209
8.19,20.45,0.209
8.20,20.60,0.209
8.22,20.75,0.209
8.24,20.90,0.209
8.25,21.05,0.209
8.26,21.20,0.209
8.28,21.35,0.209
8.30,21.50,0.209
8.31,21.66,0.210
8.33,21.80,0.210
8.34,21.96,0.210
8.35,22.11,0.210
8.37,22.25,0.210
8.39,22.40,0.210
8.40,22.56,0.210
8.41,22.71,0.210
8.43,22.86,0.210
8.45,23.01,0.211
8.46,23.16,0.211
8.48,23.31,0.211
8.49,23.46,0.211
8.50,23.61,0.211
8.52,23.75,0.211
8.53,23.91,0.211
8.55,24.06,0.211
8.57,24.21,0.211
8.58,24.36,0.211
8.60,24.51,0.212
8.61,24.66,0.212
8.63,24.81,0.212
8.64,24.96,0.212
8.65,25.11,0.212
8.67,25.26,0.212
8.68,25.41,0.212
8.70,25.56,0.212
8.72,25.71,0.212
8.73,25.86,0.213
8.75,26.01,0.213
8.76,26.16,0.213
8.78,26.31,0.213
8.79,26.46,0.213
8.80,26.61,0.213
8.82,26.76,0.213
8.83,26.91,0.213
8.85,27.06,0.213
8.87,27.21,0.214
8.88,27.36,0.214
8.90,27.51,0.214
8.91,27.66,0.214
8.93,27.81,0.214
8.94,27.96,0.214
8.95,28.11,0.214
8.97,28.26,0.214
8.98,28.41,0.214
9.00,28.56,0.214
9.02,28.71,0.215
9.03,28.86,0.215
9.05,29.01,0.215
9.06,29.16,0.215
9.08,29.31,0.215
9.09,29.46,0.215
9.10,29.61,0.215
9.12,29.76,0.215
9.13,29.91,0.216
9.15,30.06,0.216
9.17,30.22,0.216
9.18,30.37,0.216
9.20,30.52,0.216
9.21,30.67,0.216
9.23,30.82,0.216
9.24,30.97,0.216
9.25,31.12,0.216
9.27,31.27,0.217
9.28,31.42,0.217
9.30,31.57,0.217
9.32,31.72,0.217
9.33,31.87,0.217
9.35,32.02,0.217
9.36,32.17,0.217
9.38,32.32,0.217
9.39,32.47,0.217
9.40,32.62,0.218
9.42,32.77,0.218
9.43,32.92,0.218
9.45,33.07,0.218
9.47,33.22,0.218
9.48,33.37,0.218
9.50,33.52,0.218
9.51,33.67,0.218
9.53,33.82,0.219
9.54,33.97,0.219
9.55,34.12,0.219
9.57,34.27,0.219
9.58,34.42,0.219
9.60,34.57,0.219
9.62,34.72,0.219
9.63,34.87,0.219
9.65,35.02,0.219
9.66,35.17,0.219
9.68,35.32,0.220
9.69,35.47,0.220
9.70,35.62,0.220
9.72,35.77,0.220
9.73,35.92,0.220
9.75,36.07,0.220
9.77,36.22,0.220
9.78,36.37,0.221
9.80,36.52,0.221
9.81,36.67,0.221
9.83,36.82,0.221
9.84,36.97,0.221
9.85,37.12,0.221
9.87,37.27,0.221
9.88,37.42,0.221
9.90,37.57,0.221
9.92,37.72,0.222
9.93,37.87,0.222
9.95,38.02,0.222
9.96,38.17,0.222
9.98,38.33,0.222
9.99,38.48,0.222
10.00,38.63,0.222
10.02,38.78,0.222
10.03,38.93,0.223
10.05,39.08,0.223
10.07,39.23,0.223
10.08,39.38,0.223
10.10,39.53,0.223
10.11,39.68,0.223
10.13,39.83,0.223
10.14,39.98,0.224
10.15,40.13,0.224
10.17,40.28,0.224
10.18,40.43,0.224
10.20,40.58,0.224
10.22,40.73,0.224
10.23,40.88,0.224
10.25,41.03,0.225
10.26,41.18,0.225
10.28,41.33,0.225
10.29,41.48,0.225
10.30,41.63,0.225
10.32,41.78,0.225
10.33,41.93,0.226
10.35,42.08,0.226
10.37,42.23,0.226
10.38,42.38,0.226
10.40,42.53,0.226
10.41,42.68,0.226
10.43,42.83,0.227
10.44,42.98,0.227
10.45,43.13,0.227
10.47,43.28,0.227
10.48,43.43,0.227
10.50,43.58,0.227
10.52,43.73,0.228
10.53,43.88,0.228
10.55,44.03,0.228
10.56,44.18,0.228
10.58,44.33,0.228
10.59,44.48,0.229
10.60,44.63,0.229
10.62,44.78,0.229
10.63,44.93,0.229
10.65,45.08,0.230
10.67,45.23,0.230
10.68,45.38,0.230
10.70,45.53,0.230
10.71,45.68,0.231
10.73,45.83,0.231
10.74,45.98,0.231
10.75,46.13,0.231
10.77,46.28,0.232
10.78,46.43,0.232
10.80,46.58,0.232
10.82,46.73,0.233
10.83,46.88,0.233
10.85,47.03,0.233
10.86,47.18,0.234
10.88,47.33,0.234
10.89,47.48,0.234
10.90,47.63,0.235
10.92,47.78,0.235
10.93,47.93,0.236
10.95,48.08,0.236
10.97,48.23,0.237
10.98,48.38,0.237
11.00,48.53,0.238
11.01,48.68,0.239
11.03,48.83,0.239
11.04,48.98,0.240
11.05,49.13,0.242
11.07,49.28,0.242
11.08,49.43,0.244
11.10,49.58,0.245
11.12,49.73,0.245
11.13,49.88,0.247
11.15,50.03,0.249
11.16,50.18,0.250
11.18,50.33,0.252
11.19,50.48,0.253
11.20,50.63,0.255
11.22,50.78,0.258
11.23,50.93,0.260
11.25,51.08,0.263
11.27,51.23,0.265
11.28,51.38,0.269
11.30,51.53,0.272
11.31,51.68,0.275
11.33,51.83,0.279
11.34,51.98,0.282
11.35,52.13,0.287
11.37,52.27,0.291
11.38,52.42,0.298
11.40,52.57,0.302
11.42,52.72,0.308
11.43,52.87,0.313
11.45,53.02,0.321
11.46,53.17,0.328
11.48,53.32,0.336
11.49,53.46,0.344
11.50,53.61,0.351
11.52,53.76,0.362
11.53,53.91,0.374
11.55,54.06,0.383
11.57,54.20,0.396
11.58,54.35,0.405
11.60,54.50,0.417
11.61,54.64,0.427
11.63,54.79,0.438
11.64,54.94,0.446
11.65,55.08,0.453
11.67,55.23,0.459
11.68,55.38,0.460
11.70,55.53,0.460
11.72,55.68,0.458
11.73,55.83,0.455
11.75,55.98,0.448
11.76,56.13,0.435
11.78,56.28,0.424
11.79,56.43,0.412
11.80,56.59,0.398
11.82,56.74,0.386
11.83,56.89,0.374
11.85,57.05,0.359
11.87,57.20,0.346
11.88,57.35,0.337
11.90,57.51,0.324
11.91,57.66,0.314
11.93,57.81,0.307
11.94,57.97,0.297
11.95,58.12,0.292
11.97,58.27,0.284
11.98,58.43,0.281
12.00,58.58,0.277
12.02,58.73,0.273
12.03,58.88,0.271
12.05,59.03,0.268
12.06,59.18,0.265
12.08,59.34,0.264
12.09,59.49,0.263
12.10,59.64,0.262
12.12,59.79,0.261
12.13,59.94,0.261
12.15,60.09,0.260
12.17,60.24,0.260
12.18,60.39,0.259
12.20,60.54,0.259
12.21,60.69,0.259
12.23,60.84,0.259
12.24,60.99,0.258
12.25,61.15,0.258
12.27,61.29,0.258
12.28,61.45,0.258
12.30,61.60,0.258
12.32,61.75,0.257
12.33,61.90,0.257
12.35,62.05,0.257
12.36,62.20,0.257
12.38,62.35,0.257
12.39,62.50,0.257
12.40,62.65,0.257
12.42,62.80,0.256
12.43,62.95,0.256
12.45,63.10,0.256
12.47,63.25,0.256
12.48,63.40,0.256
12.50,63.55,0.256
12.51,63.70,0.256
12.53,63.85,0.256
12.54,64.00,0.256
12.55,64.15,0.256
12.57,64.30,0.256
12.58,64.45,0.256
12.60,64.60,0.256
12.62,64.75,0.256
12.63,64.90,0.257
12.65,65.05,0.257
12.66,65.20,0.257
12.68,65.35,0.257
12.69,65.50,0.257
12.70,65.65,0.257
12.72,65.80,0.257
12.73,65.95,0.257
12.75,66.10,0.257
12.77,66.25,0.257
12.78,66.40,0.257
12.80,66.55,0.258
12.81,66.70,0.258
12.83,66.85,0.258
12.84,67.00,0.258
12.85,67.15,0.258
12.87,67.30,0.258
12.88,67.45,0.258
12.90,67.60,0.259
12.92,67.75,0.259
12.93,67.90,0.259
12.95,68.05,0.259
12.96,68.20,0.259
12.98,68.35,0.259
12.99,68.50,0.260
13.00,68.65,0.260
13.02,68.80,0.260
13.03,68.95,0.260
13.05,69.10,0.260
13.07,69.25,0.260
13.08,69.40,0.261
13.10,69.55,0.261
13.11,69.70,0.261
13.13,69.85,0.261
13.14,70.00,0.261
13.15,70.15,0.262
13.17,70.30,0.262
13.18,70.45,0.262
13.20,70.60,0.262
13.22,70.75,0.262
13.23,70.90,0.263
13.25,71.06,0.263
13.26,71.21,0.263
13.28,71.36,0.263
13.29,71.51,0.264
13.30,71.66,0.264
13.32,71.81,0.264
13.33,71.96,0.264
13.35,72.11,0.264
13.37,72.26,0.264
13.38,72.41,0.265
13.40,72.56,0.265
13.41,72.71,0.265
13.43,72.86,0.265
13.44,73.01,0.266
13.45,73.16,0.266
13.47,73.31,0.266
13.48,73.46,0.266
13.50,73.61,0.266
13.52,73.76,0.267
13.53,73.91,0.267
13.55,74.06,0.267
13.56,74.21,0.267
13.58,74.36,0.267
13.59,74.51,0.268
13.60,74.66,0.268
13.62,74.81,0.268
13.63,74.96,0.268
13.65,75.11,0.269
13.67,75.26,0.269
13.68,75.41,0.269
13.70,75.56,0.269
13.71,75.71,0.270
13.73,75.86,0.270
13.74,76.01,0.270
13.75,76.16,0.270
13.77,76.31,0.271
13.78,76.46,0.271
13.80,76.61,0.271
13.82,76.76,0.271
13.83,76.91,0.272
13.85,77.06,0.272
13.86,77.21,0.272
13.88,77.36,0.272
13.89,77.51,0.273
13.90,77.66,0.273
13.92,77.81,0.273
13.93,77.96,0.273
13.95,78.11,0.274
13.97,78.26,0.274
13.98,78.41,0.274
14.00,78.56,0.275
14.01,78.71,0.275
14.03,78.86,0.275
14.04,79.01,0.275
14.05,79.16,0.276
14.07,79.31,0.276
14.08,79.46,0.276
14.10,79.61,0.277
14.12,79.76,0.277
14.13,79.91,0.277
14.15,80.06,0.278
14.16,80.21,0.278
14.18,80.36,0.278
14.19,80.51,0.278
14.20,80.66,0.279
14.22,80.81,0.279
14.23,80.96,0.279
14.25,81.11,0.280
14.27,81.26,0.280
14.28,81.41,0.280
14.30,81.56,0.280
14.31,81.71,0.281
14.33,81.86,0.281
14.34,82.01,0.281
14.35,82.16,0.281
14.37,82.31,0.282
14.38,82.46,0.282
14.40,82.61,0.282
14.42,82.76,0.283
14.43,82.91,0.283
14.45,83.06,0.283
14.46,83.21,0.284
14.48,83.36,0.284
14.49,83.51,0.284
14.50,83.66,0.284
14.52,83.81,0.285
14.53,83.96,0.285
14.55,84.11,0.285
14.57,84.26,0.286
14.58,84.41,0.286
14.60,84.56,0.286
14.61,84.72,0.287
14.63,84.86,0.287
14.64,85.01,0.288
14.65,85.16,0.288
14.67,85.31,0.288
14.68,85.47,0.289
14.70,85.61,0.289
14.72,85.77,0.289
14.73,85.92,0.290
14.75,86.07,0.290
14.76,86.22,0.291
14.78,86.36,0.291
14.79,86.52,0.291
14.80,86.67,0.292
14.82,86.82,0.292
14.83,86.97,0.293
14.85,87.12,0.293
14.87,87.27,0.293
14.88,87.42,0.294
14.90,87.57,0.294
14.91,87.72,0.295
14.93,87.87,0.295
14.94,88.02,0.296
14.95,88.17,0.296
14.97,88.32,0.297
14.98,88.47,0.297
15.00,88.62,0.298
15.02,88.77,0.298
15.03,88.92,0.299
15.05,89.07,0.299
15.06,89.22,0.300
15.08,89.37,0.300
15.09,89.52,0.301
15.10,89.67,0.301
15.12,89.82,0.302
15.13,89.97,0.302
15.15,90.12,0.303
15.17,90.27,0.303
15.18,90.42,0.304
15.20,90.57,0.304
15.21,90.72,0.305
15.23,90.87,0.306
15.24,91.02,0.306
15.25,91.17,0.307
15.27,91.32,0.308
15.28,91.47,0.308
15.30,91.62,0.309
15.32,91.77,0.309
15.33,91.92,0.310
15.35,92.07,0.311
15.36,92.22,0.312
15.38,92.37,0.312
15.39,92.52,0.313
15.40,92.67,0.314
15.42,92.82,0.315
15.43,92.97,0.316
15.45,93.12,0.316
15.47,93.27,0.317
15.48,93.42,0.318
15.50,93.57,0.318
15.51,93.72,0.319
15.53,93.87,0.320
15.54,94.02,0.321
15.55,94.17,0.322
15.57,94.31,0.322
15.58,94.47,0.323
15.60,94.62,0.324
15.62,94.77,0.325
15.63,94.91,0.326
15.65,95.07,0.326
15.66,95.21,0.327
15.68,95.36,0.328
15.69,95.52,0.329
15.70,95.66,0.330
15.72,95.81,0.331
15.73,95.96,0.333
15.75,96.11,0.333
15.77,96.26,0.335
15.78,96.41,0.336
15.80,96.56,0.337
15.81,96.71,0.337
15.83,96.86,0.338
15.84,97.01,0.339
15.85,97.16,0.341
15.87,97.31,0.342
15.88,97.46,0.343
15.90,97.61,0.344
15.92,97.76,0.346
15.93,97.91,0.347
15.95,98.06,0.349
15.96,98.21,0.350
15.98,98.36,0.351
15.99,98.51,0.353
16.00,98.66,0.354
16.02,98.81,0.355
16.03,98.96,0.357
16.05,99.11,0.358
16.07,99.26,0.359
16.08,99.41,0.361
16.10,99.56,0.362
16.11,99.71,0.363
16.13,99.86,0.366
16.14,100.01,0.368
16.15,100.16,0.369
16.17,100.31,0.371
16.18,100.46,0.372
16.20,100.61,0.375
16.22,100.76,0.377
16.23,100.91,0.378
16.25,101.06,0.380
16.26,101.21,0.382
16.28,101.36,0.383
16.29,101.51,0.385
16.30,101.66,0.388
16.32,101.81,0.390
16.33,101.95,0.391
16.35,102.10,0.393
16.37,102.25,0.396
16.38,102.40,0.398
16.40,102.55,0.400
16.41,102.70,0.403
16.43,102.85,0.404
16.44,103.00,0.407
16.45,103.15,0.409
16.47,103.30,0.411
16.48,103.45,0.413
16.50,103.60,0.415
16.52,103.75,0.419
16.53,103.90,0.421
16.55,104.05,0.424
16.56,104.20,0.426
16.58,104.35,0.430
16.59,104.50,0.433
16.60,104.65,0.436
16.62,104.80,0.438
16.63,104.95,0.441
16.65,105.09,0.446
16.67,105.24,0.448
16.68,105.39,0.450
16.70,105.54,0.454
16.71,105.69,0.457
16.73,105.84,0.459
16.74,105.99,0.462
16.75,106.14,0.467
16.77,106.29,0.470
16.78,106.44,0.474
16.80,106.59,0.477
16.82,106.74,0.482
16.83,106.89,0.485
16.85,107.03,0.489
16.86,107.18,0.493
16.88,107.33,0.497
16.89,107.48,0.502
16.90,107.63,0.506
16.92,107.78,0.512
16.93,107.93,0.515
16.95,108.08,0.521
16.97,108.23,0.524
16.98,108.38,0.530
17.00,108.52,0.537
17.01,108.67,0.541
17.03,108.82,0.546
17.04,108.97,0.555
17.05,109.12,0.560
17.07,109.27,0.564
17.08,109.42,0.569
17.10,109.57,0.577
17.12,109.71,0.582
17.13,109.86,0.589
17.14,110.01,0.596
17.16,110.16,0.603
17.18,110.31,0.609
17.19,110.45,0.617
17.21,110.60,0.625
17.22,110.75,0.631
17.23,110.90,0.640
17.25,111.05,0.649
17.27,111.20,0.656
17.28,111.34,0.666
17.29,111.49,0.675
17.31,111.64,0.691
17.33,111.79,0.697
17.34,111.93,0.704
17.36,112.08,0.713
17.37,112.23,0.724
17.38,112.38,0.734
17.40,112.52,0.746
17.42,112.67,0.754
17.43,112.82,0.768
17.44,112.96,0.781
17.46,113.11,0.794
17.48,113.26,0.808
17.49,113.40,0.820
17.51,113.55,0.835
17.52,113.70,0.853
17.53,113.84,0.886
17.55,113.99,0.916
17.57,114.13,0.915
17.58,114.28,0.923
17.59,114.42,0.937
17.61,114.57,0.955
17.63,114.72,0.973
17.64,114.86,0.996
17.66,115.01,1.014
17.67,115.15,1.036
17.68,115.30,1.055
17.70,115.44,1.078
17.72,115.59,1.099
17.73,115.73,1.121
17.74,115.87,1.145
17.76,116.02,1.175
17.78,116.16,1.203
17.79,116.31,1.234
17.81,116.45,1.265
17.82,116.59,1.295
17.83,116.73,1.323
17.85,116.87,1.354
17.87,117.01,1.383
17.88,117.16,1.415
17.89,117.30,1.451
17.91,117.44,1.499
17.93,117.58,1.545
17.94,117.72,1.590
17.96,117.86,1.641
17.97,117.99,1.711
17.98,118.13,1.789
18.00,118.26,1.876
18.02,118.39,1.962
18.03,118.52,2.053
18.04,118.65,2.159
18.06,118.77,2.286
18.08,118.90,2.453
18.09,119.01,2.714
18.11,119.11,2.929
18.12,119.21,3.058
18.13,119.32,3.149
18.15,119.43,3.288
18.17,119.54,3.481
18.18,119.65,3.641
18.19,119.76,3.760
18.21,119.87,3.823
18.23,119.99,3.881
18.24,120.11,3.926
18.26,120.23,3.986
18.27,120.36,4.017
18.28,120.49,4.048
18.30,120.63,4.024
18.32,120.77,3.942
18.33,120.93,3.784
18.34,121.10,3.567
18.36,121.28,3.178
18.38,121.49,2.659
18.39,121.73,2.010
18.41,121.99,1.506
18.42,122.24,1.300
18.43,122.48,1.155
18.45,122.70,1.035
18.47,122.92,0.935
18.48,123.12,0.852
18.49,123.32,0.773
18.51,123.51,0.710
18.53,123.69,0.660
18.54,123.87,0.612
18.56,124.05,0.573
18.57,124.22,0.540
18.58,124.39,0.508
18.60,124.55,0.485
18.62,124.72,0.463
18.63,124.88,0.445
18.64,125.04,0.431
18.66,125.19,0.416
18.68,125.35,0.406
18.69,125.51,0.394
18.71,125.66,0.387
18.72,125.82,0.380
18.73,125.97,0.374
18.75,126.12,0.369
18.77,126.28,0.365
18.78,126.43,0.360
18.79,126.58,0.358
18.81,126.73,0.355
18.83,126.89,0.352
18.84,127.04,0.351
18.86,127.19,0.350
18.87,127.34,0.348
18.88,127.49,0.347
18.90,127.64,0.346
18.92,127.79,0.346
18.93,127.94,0.344
18.94,128.09,0.344
18.96,128.25,0.343
18.98,128.40,0.343
18.99,128.55,0.342
19.01,128.70,0.342
19.02,128.85,0.341
19.03,129.00,0.341
19.05,129.15,0.340
19.07,129.30,0.340
19.08,129.45,0.340
19.09,129.60,0.340
19.11,129.75,0.339
19.13,129.90,0.339
19.14,130.05,0.339
19.16,130.20,0.338
19.17,130.35,0.338
19.18,130.50,0.338
19.20,130.65,0.337
19.22,130.80,0.337
19.23,130.95,0.337
19.24,131.10,0.336
19.26,131.25,0.336
19.28,131.40,0.336
19.29,131.55,0.335
19.31,131.70,0.335
19.32,131.85,0.335
19.33,132.00,0.334
19.35,132.15,0.334
19.37,132.30,0.334
19.38,132.45,0.334
19.39,132.60,0.333
19.41,132.75,0.333
19.43,132.90,0.333
19.44,133.05,0.332
19.46,133.20,0.332
19.47,133.35,0.332
19.48,133.51,0.332
19.50,133.66,0.331
19.52,133.81,0.331
19.53,133.96,0.331
19.54,134.11,0.330
19.56,134.26,0.330
19.58,134.41,0.330
19.59,134.56,0.329
19.61,134.71,0.329
19.62,134.86,0.329
19.63,135.01,0.328
19.65,135.16,0.328
19.67,135.31,0.328
19.68,135.46,0.327
19.69,135.61,0.327
19.71,135.76,0.327
19.73,135.91,0.326
19.74,136.06,0.326
19.76,136.21,0.325
19.77,136.36,0.325
19.78,136.51,0.325
19.80,136.66,0.324
19.82,136.81,0.324
19.83,136.96,0.324
19.84,137.11,0.323
19.86,137.26,0.323
19.88,137.41,0.323
19.89,137.56,0.322
19.91,137.71,0.322
19.92,137.86,0.321
19.93,138.01,0.321
19.95,138.16,0.321
19.97,138.31,0.320
19.98,138.46,0.320
19.99,138.61,0.319
20.01,138.76,0.319
20.03,138.91,0.319
20.04,139.07,0.318
20.06,139.22,0.318
20.07,139.37,0.317
20.08,139.52,0.317
20.10,139.67,0.316
20.12,139.82,0.316
20.13,139.97,0.315
20.14,140.12,0.315
20.16,140.27,0.314
20.18,140.42,0.314
20.19,140.57,0.314
20.21,140.72,0.313
20.22,140.87,0.312
20.23,141.02,0.312
20.25,141.17,0.312
20.27,141.32,0.311
20.28,141.47,0.310
20.29,141.62,0.310
20.31,141.77,0.310
20.33,141.92,0.309
20.34,142.07,0.309
20.36,142.22,0.308
20.37,142.37,0.308
20.38,142.52,0.307
20.40,142.67,0.307
20.42,142.82,0.306
20.43,142.97,0.306
20.44,143.12,0.305
20.46,143.27,0.305
20.48,143.42,0.304
20.49,143.57,0.303
20.51,143.72,0.303
20.52,143.87,0.302
20.53,144.02,0.302
20.55,144.17,0.301
20.57,144.32,0.300
20.58,144.47,0.300
20.59,144.62,0.299
20.61,144.77,0.299
20.63,144.93,0.298
20.64,145.08,0.298
20.66,145.23,0.297
20.67,145.38,0.296
20.68,145.53,0.296
20.70,145.68,0.295
20.72,145.83,0.295
20.73,145.98,0.293
20.74,146.13,0.293
20.76,146.28,0.292
20.78,146.43,0.292
20.79,146.58,0.291
20.81,146.73,0.290
20.82,146.88,0.289
20.83,147.03,0.289
20.85,147.18,0.288
20.87,147.33,0.287
20.88,147.48,0.287
20.89,147.63,0.286
20.91,147.78,0.285
20.93,147.93,0.284
20.94,148.08,
20.96,148.23,
20.97,148.38,
20.98,,
20.99,,

[step]
Ramp 10.00 °C/min to -60.00 °C
Time,Temperature,Heat Flow (Normalized)
min,°C,W/g
22.99,150.15,-0.141
23.01,150.15,-0.141
23.02,150.15,-0.140
23.04,150.14,-0.140
23.05,150.13,-0.140
23.07,150.11,-0.156
23.08,150.07,-0.177
23.10,150.02,-0.206
23.11,149.96,-0.239
23.13,149.88,-0.276
23.14,149.79,-0.310
23.16,149.70,-0.344
23.17,149.59,-0.373
23.19,149.48,-0.397
23.20,149.36,-0.418
23.22,149.24,-0.436
23.23,149.11,-0.452
23.25,148.99,-0.464
23.26,148.85,-0.475
23.28,148.72,-0.485
23.29,148.58,-0.493
23.31,148.45,-0.499
23.32,148.31,-0.504
23.34,148.17,-0.512
23.35,148.02,-0.513
23.37,147.88,-0.517
23.38,147.74,-0.520
23.40,147.59,-0.521
23.41,147.45,-0.523
23.43,147.30,-0.524
23.44,147.16,-0.525
23.46,147.01,-0.526
23.47,146.86,-0.526
23.49,146.72,-0.527
23.50,146.57,-0.528
23.52,146.42,-0.528
23.53,146.28,-0.528
23.55,146.13,-0.528
23.56,145.98,-0.528
23.58,145.83,-0.528
23.59,145.68,-0.528
23.61,145.54,-0.528
23.62,145.39,-0.528
23.64,145.24,-0.528
23.65,145.09,-0.528
23.67,144.94,-0.528
23.68,144.79,-0.527
23.70,144.64,-0.527
23.71,144.50,-0.527
23.73,144.35,-0.527
23.74,144.20,-0.526
23.76,144.05,-0.526
23.77,143.90,-0.525
23.79,143.75,-0.525
23.80,143.60,-0.525
23.82,143.45,-0.524
23.83,143.30,-0.524
23.85,143.15,-0.524
23.86,143.00,-0.523
23.88,142.86,-0.522
23.89,142.71,-0.521
23.91,142.56,-0.520
23.92,142.41,-0.519
23.94,142.26,-0.519
23.95,142.11,-0.518
23.97,141.96,-0.518
23.98,141.81,-0.517
24.00,141.66,-0.516
24.01,141.51,-0.516
24.03,141.36,-0.515
24.04,141.21,-0.515
24.06,141.06,-0.515
24.07,140.91,-0.514
24.09,140.77,-0.514
24.10,140.62,-0.513
24.12,140.46,-0.513
24.13,140.32,-0.513
24.15,140.17,-0.512
24.16,140.02,-0.511
24.18,139.87,-0.510
24.19,139.72,-0.510
24.21,139.57,-0.509
24.22,139.42,-0.509
24.24,139.27,-0.508
24.25,139.12,-0.508
24.27,138.97,-0.508
24.28,138.82,-0.507
24.30,138.67,-0.506
24.31,138.52,-0.506
24.33,138.37,-0.504
24.34,138.22,-0.504
24.36,138.07,-0.503
24.37,137.92,-0.503
24.39,137.77,-0.502
24.40,137.62,-0.502
24.42,137.47,-0.501
24.43,137.32,-0.501
24.45,137.17,-0.501
24.46,137.02,-0.500
24.48,136.87,-0.500
24.49,136.72,-0.499
24.51,136.57,-0.499
24.52,136.42,-0.499
24.54,136.27,-0.498
24.55,136.12,-0.498
24.57,135.97,-0.497
24.58,135.82,-0.497
24.60,135.67,-0.496
24.61,135.52,-0.496
24.63,135.37,-0.495
24.64,135.22,-0.494
24.66,135.07,-0.494
24.67,134.92,-0.494
24.69,134.77,-0.493
24.70,134.62,-0.493
24.72,134.47,-0.492
24.73,134.32,-0.492
24.75,134.17,-0.491
24.76,134.02,-0.491
24.78,133.87,-0.491
24.79,133.72,-0.490
24.81,133.57,-0.490
24.82,133.42,-0.489
24.84,133.27,-0.489
24.85,133.12,-0.489
24.87,132.98,-0.488
24.88,132.82,-0.488
24.90,132.68,-0.487
24.91,132.53,-0.487
24.93,132.38,-0.486
24.94,132.23,-0.486
24.96,132.08,-0.486
24.97,131.93,-0.485
24.99,131.78,-0.485
25.00,131.63,-0.484
25.02,131.48,-0.484
25.03,131.33,-0.484
25.05,131.18,-0.483
25.06,131.03,-0.483
25.08,130.88,-0.483
25.09,130.73,-0.482
25.11,130.58,-0.482
25.12,130.43,-0.481
25.14,130.28,-0.481
25.15,130.13,-0.481
25.17,129.98,-0.480
25.18,129.83,-0.480
25.20,129.68,-0.480
25.21,129.53,-0.479
25.23,129.38,-0.479
25.24,129.23,-0.479
25.26,129.08,-0.478
25.27,128.93,-0.478
25.29,128.78,-0.478
25.30,128.63,-0.477
25.32,128.48,-0.477
25.33,128.33,-0.477
25.35,128.18,-0.476
25.36,128.03,-0.476
25.38,127.88,-0.476
25.39,127.73,-0.476
25.41,127.58,-0.475
25.42,127.43,-0.475
25.44,127.28,-0.475
25.45,127.13,-0.474
25.47,126.98,-0.474
25.48,126.83,-0.474
25.50,126.68,-0.474
25.51,126.53,-0.473
25.53,126.38,-0.473
25.54,126.23,-0.473
25.56,126.08,-0.472
25.57,125.93,-0.472
25.59,125.78,-0.472
25.60,125.63,-0.472
25.62,125.48,-0.471
25.63,125.33,-0.471
25.65,125.18,-0.471
25.66,125.03,-0.470
25.68,124.88,-0.470
25.69,124.73,-0.470
25.71,124.58,-0.470
25.72,124.43,-0.469
25.74,124.28,-0.469
25.75,124.13,-0.469
25.77,123.98,-0.469
25.78,123.83,-0.468
25.80,123.68,-0.468
25.81,123.53,-0.468
25.83,123.38,-0.467
25.84,123.23,-0.467
25.86,123.08,-0.467
25.87,122.93,-0.467
25.89,122.78,-0.466
25.90,122.63,-0.466
25.92,122.48,-0.466
25.93,122.33,-0.465
25.95,122.18,-0.465
25.96,122.03,-0.465
25.98,121.88,-0.464
25.99,121.73,-0.464
26.01,121.58,-0.464
26.02,121.43,-0.464
26.04,121.28,-0.463
26.05,121.13,-0.463
26.07,120.98,-0.463
26.08,120.83,-0.463
26.10,120.68,-0.462
26.11,120.53,-0.462
26.13,120.38,-0.462
26.14,120.23,-0.462
26.16,120.08,-0.461
26.17,119.93,-0.461
26.19,119.78,-0.461
26.20,119.63,-0.461
26.22,119.48,-0.461
26.23,119.34,-0.460
26.25,119.19,-0.460
26.26,119.04,-0.460
26.28,118.89,-0.460
26.29,118.74,-0.459
26.31,118.59,-0.459
26.32,118.44,-0.459
26.34,118.29,-0.459
26.35,118.14,-0.458
26.37,117.99,-0.458
26.38,117.84,-0.458
26.40,117.69,-0.458
26.41,117.54,-0.457
26.43,117.39,-0.457
26.44,117.24,-0.457
26.46,117.09,-0.457
26.47,116.94,-0.456
26.49,116.79,-0.456
26.50,116.64,-0.456
26.52,116.49,-0.456
26.53,116.34,-0.455
26.55,116.19,-0.455
26.56,116.04,-0.455
26.58,115.89,-0.455
26.59,115.74,-0.455
26.61,115.59,-0.455
26.62,115.44,-0.454
26.64,115.29,-0.454
26.65,115.14,-0.454
26.67,114.99,-0.454
26.68,114.84,-0.454
26.70,114.69,-0.453
26.71,114.54,-0.453
26.73,114.39,-0.453
26.74,114.24,-0.453
26.76,114.09,-0.453
26.77,113.94,-0.452
26.79,113.79,-0.452
26.80,113.64,-0.452
26.82,113.49,-0.452
26.83,113.34,-0.452
26.85,113.19,-0.451
26.86,113.04,-0.451
26.88,112.89,-0.451
26.89,112.74,-0.451
26.91,112.59,-0.451
26.92,112.44,-0.450
26.94,112.29,-0.450
26.95,112.14,-0.450
26.97,111.99,-0.450
26.98,111.84,-0.450
27.00,111.69,-0.449
27.01,111.54,-0.449
27.03,111.39,-0.449
27.04,111.24,-0.449
27.06,111.09,-0.449
27.07,110.94,-0.449
27.09,110.79,-0.448
27.10,110.64,-0.448
27.12,110.49,-0.448
27.13,110.34,-0.448
27.15,110.19,-0.448
27.16,110.04,-0.447
27.18,109.89,-0.447
27.19,109.74,-0.447
27.21,109.59,-0.447
27.22,109.44,-0.446
27.24,109.29,-0.446
27.25,109.14,-0.446
27.27,108.99,-0.446
27.28,108.84,-0.446
27.30,108.69,-0.445
27.31,108.54,-0.445
27.33,108.39,-0.445
27.34,108.24,-0.445
27.36,108.09,-0.445
27.37,107.94,-0.444
27.39,107.79,-0.444
27.40,107.64,-0.444
27.42,107.49,-0.444
27.43,107.34,-0.443
27.45,107.19,-0.443
27.46,107.04,-0.443
27.48,106.89,-0.443
27.49,106.75,-0.443
27.51,106.60,-0.443
27.52,106.45,-0.442
27.54,106.30,-0.442
27.55,106.15,-0.442
27.57,106.00,-0.442
27.58,105.85,-0.441
27.60,105.70,-0.441
27.61,105.55,-0.441
27.63,105.40,-0.441
27.64,105.25,-0.441
27.66,105.10,-0.441
27.67,104.95,-0.441
27.69,104.80,-0.440
27.70,104.65,-0.440
27.72,104.50,-0.440
27.73,104.35,-0.439
27.75,104.20,-0.439
27.76,104.05,-0.439
27.78,103.90,-0.439
27.79,103.75,-0.439
27.81,103.60,-0.439
27.82,103.45,-0.438
27.84,103.30,-0.438
27.85,103.15,-0.438
27.87,103.00,-0.438
27.88,102.85,-0.438
27.90,102.70,-0.438
27.91,102.55,-0.438
27.93,102.40,-0.437
27.94,102.25,-0.437
27.96,102.10,-0.437
27.97,101.95,-0.437
27.99,101.80,-0.437
28.00,101.65,-0.437
28.02,101.50,-0.436
28.03,101.35,-0.436
28.05,101.20,-0.436
28.06,101.05,-0.436
28.08,100.90,-0.436
28.09,100.75,-0.436
28.11,100.60,-0.435
28.12,100.45,-0.435
28.14,100.30,-0.435
28.15,100.15,-0.435
28.17,100.00,-0.435
28.18,99.85,-0.434
28.20,99.70,-0.434
28.21,99.55,-0.434
28.23,99.40,-0.434
28.24,99.25,-0.434
28.26,99.10,-0.434
28.27,98.95,-0.433
28.29,98.80,-0.433
28.30,98.65,-0.433
28.32,98.50,-0.433
28.33,98.35,-0.433
28.35,98.20,-0.433
28.36,98.05,-0.432
28.38,97.90,-0.432
28.39,97.75,-0.432
28.41,97.60,-0.432
28.42,97.45,-0.432
28.44,97.30,-0.432
28.45,97.15,-0.431
28.47,97.00,-0.431
28.48,96.85,-0.431
28.50,96.70,-0.431
28.51,96.55,-0.431
28.53,96.40,-0.430
28.54,96.25,-0.430
28.56,96.10,-0.430
28.57,95.95,-0.430
28.59,95.81,-0.430
28.60,95.65,-0.429
28.62,95.50,-0.429
28.63,95.35,-0.429
28.65,95.20,-0.429
28.66,95.05,-0.429
[...]
140.08,-40.88,0.194
140.08,-40.81,0.194
140.09,-40.74,0.194
140.10,-40.68,0.194
140.10,-40.61,0.194
140.11,-40.55,0.194
140.12,-40.48,0.194
140.12,-40.41,0.194
140.13,-40.34,0.194
140.13,-40.28,0.194
140.14,-40.21,0.194
140.15,-40.14,0.194
140.15,-40.08,0.194
140.16,-40.01,0.194
140.17,-39.94,0.194
140.18,-39.88,0.194
140.18,-39.81,0.195
140.19,-39.74,0.194
140.20,-39.68,0.195
140.20,-39.61,0.195
140.21,-39.54,0.195
140.22,-39.48,0.195
140.22,-39.41,0.195
140.23,-39.34,0.195
140.23,-39.28,0.195
140.24,-39.21,0.195
140.25,-39.14,0.195
140.25,-39.08,0.195
140.26,-39.01,0.195
140.27,-38.94,0.195
140.28,-38.87,0.195
140.28,-38.81,0.195
140.29,-38.74,0.195
140.30,-38.68,0.195
140.30,-38.61,0.195
140.31,-38.54,0.195
140.32,-38.48,0.195
140.32,-38.41,0.195
140.33,-38.34,0.195
140.33,-38.28,0.195
140.34,-38.21,0.195
140.35,-38.14,0.195
140.35,-38.07,0.195
140.36,-38.01,0.195
140.37,-37.94,0.195
140.38,-37.87,0.195
140.38,-37.81,0.195
140.39,-37.74,0.195
140.40,-37.67,0.195
140.40,-37.61,0.195
140.41,-37.54,0.195
140.42,-37.47,0.195
140.42,-37.41,0.195
140.43,-37.34,0.195
140.43,-37.27,0.195
140.44,-37.21,0.195
140.45,-37.14,0.195
140.45,-37.07,0.195
140.46,-37.01,0.195
140.47,-36.94,0.195
140.48,-36.87,0.195
140.48,-36.81,0.195
140.49,-36.74,0.195
140.50,-36.67,0.196
140.50,-36.61,0.196
140.51,-36.54,0.196
140.52,-36.47,0.196
140.52,-36.40,0.196
140.53,-36.34,0.196
140.53,-36.27,0.196
140.54,-36.21,0.196
140.55,-36.14,0.196
140.55,-36.07,0.196
140.56,-36.00,0.196
140.57,-35.94,0.196
140.58,-35.87,0.196
140.58,-35.80,0.196
140.59,-35.74,0.196
140.60,-35.67,0.196
140.60,-35.60,0.196
140.61,-35.54,0.196
140.62,-35.47,0.196
140.62,-35.40,0.196
140.63,-35.34,0.196
140.63,-35.27,0.196
140.64,-35.20,0.196
140.65,-35.14,0.196
140.65,-35.07,0.196
140.66,-35.00,0.196
140.67,-34.94,0.196
140.68,-34.87,0.196
140.68,-34.80,0.196
140.69,-34.73,0.196
140.70,-34.67,0.196
140.70,-34.60,0.196
140.71,-34.53,0.196
140.72,-34.47,0.196
140.72,-34.40,0.196
140.73,-34.33,0.196
140.73,-34.27,0.196
140.74,-34.20,0.196
140.75,-34.14,0.196
140.75,-34.07,0.196
140.76,-34.00,0.196
140.77,-33.94,0.196
140.78,-33.87,0.196
140.78,-33.80,0.196
140.79,-33.73,0.196
140.80,-33.67,0.196
140.80,-33.60,0.196
140.81,-33.53,0.196
140.82,-33.47,0.196
140.82,-33.40,0.196
140.83,-33.33,0.197
140.83,-33.27,0.197
140.84,-33.20,0.196
140.85,-33.13,0.197
140.85,-33.07,0.197
140.86,-33.00,0.197
140.87,-32.93,0.197
140.88,-32.87,0.197
140.88,-32.80,0.197
140.89,-32.73,0.197
140.90,-32.67,0.197
140.90,-32.60,0.197
140.91,-32.53,0.197
140.92,-32.47,0.197
140.92,-32.40,0.197
140.93,-32.33,0.197
140.93,-32.26,0.197
140.94,-32.20,0.197
140.95,-32.13,0.197
140.95,-32.07,0.197
140.96,-32.00,0.197
140.97,-31.93,0.197
140.98,-31.86,0.197
140.98,-31.80,0.197
140.99,-31.73,0.197
141.00,-31.66,0.197
141.00,-31.60,0.197
141.01,-31.53,0.197
141.02,-31.46,0.197
141.02,-31.40,0.197
141.03,-31.33,0.197
141.03,-31.26,0.197
141.04,-31.20,0.197
141.05,-31.13,0.197
141.05,-31.06,0.197
141.06,-31.00,0.197
141.07,-30.93,0.197
141.08,-30.86,0.197
141.08,-30.80,0.197
141.09,-30.73,0.197
141.10,-30.66,0.198
141.10,-30.60,0.198
141.11,-30.53,0.198
141.12,-30.46,0.198
141.12,-30.40,0.198
141.13,-30.33,0.198
141.13,-30.26,0.198
141.14,-30.20,0.198
141.15,-30.13,0.198
141.15,-30.06,0.198
141.16,-30.00,0.198
141.17,-29.93,0.198
141.18,-29.86,0.198
141.18,-29.80,0.198
141.19,-29.73,0.198
141.20,-29.66,0.198
141.20,-29.60,0.198
141.21,-29.53,0.198
141.22,-29.46,0.198
141.22,-29.39,0.198
141.23,-29.33,0.198
141.23,-29.26,0.198
141.24,-29.19,0.198
141.25,-29.13,0.198
141.25,-29.06,0.198
141.26,-28.99,0.198
141.27,-28.93,0.198
141.28,-28.86,0.198
141.28,-28.79,0.198
141.29,-28.73,0.198
141.30,-28.66,0.198
141.30,-28.59,0.198
141.31,-28.53,0.198
141.32,-28.46,0.198
141.32,-28.39,0.199
141.33,-28.33,0.199
141.33,-28.26,0.199
141.34,-28.19,0.199
141.35,-28.13,0.199
141.35,-28.06,0.199
141.36,-27.99,0.199
141.37,-27.93,0.199
141.38,-27.86,0.199
141.38,-27.79,0.199
141.39,-27.73,0.199
141.40,-27.66,0.199
141.40,-27.59,0.199
141.41,-27.53,0.199
141.42,-27.46,0.199
141.42,-27.39,0.199
141.43,-27.33,0.199
141.43,-27.26,0.199
141.44,-27.19,0.199
141.45,-27.13,0.199
141.45,-27.06,0.199
141.46,-26.99,0.199
141.47,-26.92,0.199
141.48,-26.86,0.199
141.48,-26.79,0.199
141.49,-26.72,0.199
141.50,-26.66,0.199
141.50,-26.59,0.199
141.51,-26.52,0.199
141.52,-26.46,0.199
141.52,-26.39,0.199
141.53,-26.32,0.199
141.53,-26.26,0.199
141.54,-26.19,0.199
141.55,-26.12,0.200
141.55,-26.06,0.200
141.56,-25.99,0.200
141.57,-25.92,0.200
141.58,-25.86,0.200
141.58,-25.79,0.200
141.59,-25.72,0.200
141.60,-25.66,0.200
141.60,-25.59,0.200
141.61,-25.52,0.200
141.62,-25.46,0.200
141.62,-25.39,0.200
141.63,-25.32,0.200
141.63,-25.26,0.200
141.64,-25.19,0.200
141.65,-25.12,0.200
141.65,-25.06,0.200
141.66,-24.99,0.200
141.67,-24.92,0.200
141.68,-24.86,0.200
141.68,-24.79,0.200
141.69,-24.72,0.200
141.70,-24.65,0.200
141.70,-24.59,0.200
141.71,-24.52,0.200
141.72,-24.45,0.200
141.72,-24.39,0.200
141.73,-24.32,0.200
141.73,-24.25,0.200
141.74,-24.19,0.201
141.75,-24.12,0.201
141.75,-24.05,0.201
141.76,-23.99,0.201
141.77,-23.92,0.201
141.78,-23.85,0.201
141.78,-23.78,0.201
141.79,-23.72,0.201
141.80,-23.65,0.201
141.80,-23.59,0.201
141.81,-23.52,0.201
141.82,-23.45,0.201
141.82,-23.39,0.201
141.83,-23.32,0.201
141.83,-23.25,0.201
141.84,-23.19,0.201
141.85,-23.12,0.201
141.85,-23.05,0.201
141.86,-22.99,0.201
141.87,-22.92,0.201
141.88,-22.85,0.201
141.88,-22.79,0.201
141.89,-22.72,0.202
141.90,-22.65,0.202
141.90,-22.58,0.202
141.91,-22.52,0.202
141.92,-22.45,0.202
141.92,-22.38,0.202
141.93,-22.32,0.202
141.93,-22.25,0.202
141.94,-22.18,0.202
141.95,-22.12,0.202
141.95,-22.05,0.202
141.96,-21.98,0.202
141.97,-21.92,0.202
141.98,-21.85,0.202
141.98,-21.78,0.202
141.99,-21.72,0.202
142.00,-21.65,0.202
142.00,-21.58,0.202
142.01,-21.52,0.202
142.02,-21.45,0.203
142.02,-21.38,0.203
142.03,-21.32,0.203
142.03,-21.25,0.203
142.04,-21.18,0.203
142.05,-21.12,0.203
142.05,-21.05,0.203
142.06,-20.98,0.203
142.07,-20.92,0.203
142.08,-20.85,0.203
142.08,-20.78,0.203
142.09,-20.72,0.203
142.10,-20.65,0.203
142.10,-20.58,0.203
142.11,-20.52,0.203
142.12,-20.45,0.203
142.12,-20.38,0.203
142.13,-20.32,0.204
142.13,-20.25,0.204
142.14,-20.18,0.204
142.15,-20.12,0.204
142.15,-20.05,0.204
142.16,-19.98,0.204
142.17,-19.92,0.204
142.18,-19.85,0.204
142.18,-19.78,0.204
142.19,-19.72,0.204
142.20,-19.65,0.204
142.20,-19.58,0.204
142.21,-19.52,0.204
142.22,-19.45,0.204
142.22,-19.38,0.204
142.23,-19.32,0.204
142.23,-19.25,0.205
142.24,-19.18,0.205
142.25,-19.12,0.205
142.25,-19.05,0.205
142.26,-18.98,0.205
142.27,-18.92,0.205
142.28,-18.85,0.205
142.28,-18.78,0.205
142.29,-18.72,0.205
142.30,-18.65,0.205
142.30,-18.58,0.205
142.31,-18.52,0.205
142.32,-18.45,0.205
142.32,-18.38,0.206
142.33,-18.31,0.206
142.33,-18.25,0.206
142.34,-18.18,0.206
142.35,-18.11,0.206
142.35,-18.05,0.206
142.36,-17.98,0.206
142.37,-17.91,0.206
142.38,-17.85,0.206
142.38,-17.78,0.206
142.39,-17.71,0.207
142.40,-17.65,0.207
142.40,-17.58,0.207
142.41,-17.51,0.207
142.42,-17.45,0.207
142.42,-17.38,0.207
142.43,-17.31,0.207
142.43,-17.25,0.207
142.44,-17.18,0.207
142.45,-17.11,0.207
142.45,-17.05,0.207
142.46,-16.98,0.207
142.47,-16.91,0.207
142.48,-16.84,0.208
142.48,-16.78,0.208
142.49,-16.71,0.208
142.50,-16.65,0.208
142.50,-16.58,0.208
142.51,-16.51,0.208
142.52,-16.45,0.208
142.52,-16.38,0.208
142.53,-16.31,0.208
142.53,-16.25,0.208
142.54,-16.18,0.208
142.55,-16.11,0.209
142.55,-16.05,0.209
142.56,-15.98,0.209
142.57,-15.91,0.209
142.58,-15.84,0.209
142.58,-15.78,0.209
142.59,-15.71,0.209
142.60,-15.65,0.209
142.60,-15.58,0.209
142.61,-15.51,0.209
142.62,-15.44,0.209
142.62,-15.38,0.210
142.63,-15.31,0.210
142.63,-15.24,0.210
142.64,-15.18,0.210
142.65,-15.11,0.210
142.65,-15.04,0.210
142.66,-14.98,0.210
142.67,-14.91,0.210
142.68,-14.84,0.210
142.68,-14.78,0.210
142.69,-14.71,0.210
142.70,-14.65,0.210
142.70,-14.58,0.210
142.71,-14.51,0.211
142.72,-14.44,0.211
142.72,-14.38,0.211
142.73,-14.31,0.211
142.73,-14.24,0.211
142.74,-14.18,0.211
142.75,-14.11,0.211
142.75,-14.04,0.211
142.76,-13.98,0.211
142.77,-13.91,0.211
142.78,-13.84,0.211
142.78,-13.78,0.211
142.79,-13.71,0.211
142.80,-13.64,0.211
142.80,-13.58,0.211
142.81,-13.51,0.212
142.82,-13.44,0.212
142.82,-13.38,0.212
142.83,-13.31,0.212
142.83,-13.24,0.212
142.84,-13.17,0.212
142.85,-13.11,0.212
142.85,-13.04,0.212
142.86,-12.97,0.212
142.87,-12.91,0.212
142.88,-12.84,0.212
142.88,-12.77,0.212
142.89,-12.71,0.212
142.90,-12.64,0.212
142.90,-12.57,0.212
142.91,-12.51,0.212
142.92,-12.44,0.212
142.92,-12.37,0.213
142.93,-12.31,0.213
142.93,-12.24,0.213
142.94,-12.17,0.213
142.95,-12.11,0.213
142.95,-12.04,0.213
142.96,-11.97,0.213
142.97,-11.91,0.213
142.98,-11.84,0.213
142.98,-11.77,0.213
142.99,-11.71,0.213
143.00,-11.64,0.213
143.00,-11.57,0.213
143.01,-11.50,0.213
143.02,-11.44,0.213
143.02,-11.37,0.214
143.03,-11.31,0.214
143.03,-11.24,0.214
143.04,-11.17,0.214
143.05,-11.10,0.214
143.05,-11.04,0.214
143.06,-10.97,0.214
143.07,-10.91,0.214
143.08,-10.84,0.214
143.08,-10.77,0.214
143.09,-10.71,0.214
143.10,-10.64,0.214
143.10,-10.57,0.214
143.11,-10.50,0.214
143.12,-10.44,0.214
143.12,-10.37,0.214
143.13,-10.31,0.214
143.13,-10.24,0.214
143.14,-10.17,0.214
143.15,-10.11,0.214
143.15,-10.04,0.214
143.16,-9.97,0.214
143.17,-9.90,0.214
143.18,-9.84,0.214
143.18,-9.77,0.214
143.19,-9.70,0.214
143.20,-9.64,0.214
143.20,-9.57,0.214
143.21,-9.50,0.214
143.22,-9.44,0.214
143.22,-9.37,0.214
143.23,-9.30,0.214
143.23,-9.24,0.214
143.24,-9.17,0.214
143.25,-9.10,0.214
143.25,-9.04,0.214
143.26,-8.97,0.214
143.27,-8.90,0.214
143.28,-8.84,0.214
143.28,-8.77,0.214
143.29,-8.70,0.214
143.30,-8.64,0.214
143.30,-8.57,0.214
143.31,-8.50,0.214
143.32,-8.44,0.215
143.32,-8.37,0.215
143.33,-8.30,0.215
143.33,-8.24,0.215
143.34,-8.17,0.215
143.35,-8.10,0.215
143.35,-8.04,0.215
143.36,-7.97,0.215
143.37,-7.90,0.215
143.38,-7.84,0.215
143.38,-7.77,0.215
143.39,-7.70,0.215
143.40,-7.64,0.215
143.40,-7.57,0.215
143.41,-7.50,0.215
143.42,-7.44,0.215
143.42,-7.37,0.215
143.43,-7.30,0.215
143.43,-7.24,0.215
143.44,-7.17,0.215
143.45,-7.10,0.215
143.45,-7.04,0.215
143.46,-6.97,0.215
143.47,-6.90,0.215
143.48,-6.84,0.215
143.48,-6.77,0.215
143.49,-6.70,0.215
143.50,-6.64,0.215
143.50,-6.57,0.215
143.51,-6.50,0.215
143.52,-6.44,0.215
143.52,-6.37,0.215
143.53,-6.30,0.215
143.53,-6.23,0.215
143.54,-6.17,0.215
143.55,-6.10,0.215
143.55,-6.04,0.215
143.56,-5.97,0.215
143.57,-5.90,0.215
143.58,-5.83,0.215
143.58,-5.77,0.215
143.59,-5.70,0.215
143.60,-5.63,0.215
143.60,-5.57,0.215
143.61,-5.50,0.215
143.62,-5.43,0.215
143.62,-5.37,0.215
143.63,-5.30,0.215
143.63,-5.23,0.215
143.64,-5.17,0.216
143.65,-5.10,0.216
143.65,-5.03,0.216
143.66,-4.97,0.216
143.67,-4.90,0.216
143.68,-4.83,0.216
143.68,-4.76,0.216
143.69,-4.70,0.216
143.70,-4.63,0.216
143.70,-4.56,0.216
143.71,-4.50,0.216
143.72,-4.43,0.216
143.72,-4.36,0.216
143.73,-4.30,0.216
143.73,-4.23,0.216
143.74,-4.16,0.216
143.75,-4.10,0.216
143.75,-4.03,0.216
143.76,-3.96,0.216
143.77,-3.90,0.216
143.78,-3.83,0.216
143.78,-3.76,0.216
143.79,-3.70,0.216
143.80,-3.63,0.216
143.80,-3.56,0.216
143.81,-3.49,0.216
143.82,-3.43,0.216
143.82,-3.36,0.216
143.83,-3.30,0.216
143.83,-3.23,0.217
143.84,-3.16,0.217
143.85,-3.10,0.217
143.85,-3.03,0.217
143.86,-2.96,0.217
143.87,-2.89,0.217
143.88,-2.83,0.217
143.88,-2.76,0.217
143.89,-2.69,0.217
143.90,-2.63,0.217
143.90,-2.56,0.217
143.91,-2.49,0.217
143.92,-2.43,0.217
143.92,-2.36,0.217
143.93,-2.29,0.217
143.93,-2.23,0.217
143.94,-2.16,0.217
143.95,-2.09,0.217
143.95,-2.03,0.217
143.96,-1.96,0.217
143.97,-1.89,0.217
143.98,-1.82,0.217
143.98,-1.76,0.217
143.99,-1.69,0.217
144.00,-1.63,0.217
144.00,-1.56,0.217
144.01,-1.49,0.217
144.02,-1.43,0.217
144.02,-1.36,0.218
144.03,-1.29,0.218
144.03,-1.23,0.218
144.04,-1.16,0.218
144.05,-1.09,0.218
144.05,-1.02,0.218
144.06,-0.96,0.218
144.07,-0.89,0.218
144.08,-0.83,0.218
144.08,-0.76,0.218
144.09,-0.69,0.218
144.10,-0.63,0.218
144.10,-0.56,0.218
144.11,-0.49,0.218
144.12,-0.42,0.218
144.12,-0.36,0.218
144.13,-0.29,0.218
144.13,-0.22,0.218
144.14,-0.16,0.218
144.15,-0.09,0.218
144.15,-0.02,0.218
144.16,0.04,0.218
144.17,0.11,0.218
144.18,0.18,0.218
144.18,0.24,0.218
144.19,0.31,0.218
144.20,0.38,0.218
144.20,0.44,0.218
144.21,0.51,0.218
144.22,0.58,0.218
144.22,0.64,0.218
144.23,0.71,0.218
144.23,0.78,0.218
144.24,0.84,0.218
144.25,0.91,0.218
144.25,0.98,0.218
144.26,1.04,0.218
144.27,1.11,0.218
144.28,1.18,0.218
144.28,1.24,0.218
144.29,1.31,0.218
144.30,1.38,0.218
144.30,1.44,0.218
144.31,1.51,0.218
144.32,1.58,0.218
144.32,1.64,0.218
144.33,1.71,0.218
144.33,1.78,0.218
144.34,1.85,0.218
144.35,1.91,0.218
144.35,1.98,0.218
144.36,2.05,0.218
144.37,2.11,0.218
144.38,2.18,0.218
144.38,2.24,0.218
144.39,2.31,0.218
144.40,2.38,0.218
144.40,2.44,0.218
144.41,2.51,0.218
144.42,2.58,0.218
144.42,2.65,0.218
144.43,2.71,0.218
144.43,2.78,0.219
144.44,2.85,0.219
144.45,2.91,0.219
144.45,2.98,0.219
144.46,3.05,0.219
144.47,3.11,0.219
144.48,3.18,0.219
144.48,3.25,0.219
144.49,3.31,0.219
144.50,3.38,0.219
144.50,3.45,0.219
144.51,3.51,0.219
144.52,3.58,0.219
144.52,3.65,0.219
144.53,3.71,0.219
144.53,3.78,0.219
144.54,3.85,0.219
144.55,3.91,0.219
144.55,3.98,0.219
144.56,4.05,0.219
144.57,4.12,0.219
144.58,4.18,0.219
144.58,4.25,0.219
144.59,4.32,0.219
144.60,4.38,0.219
144.60,4.45,0.219
144.61,4.52,0.219
144.62,4.58,0.219
144.62,4.65,0.219
144.63,4.72,0.220
144.63,4.78,0.220
144.64,4.85,0.220
144.65,4.92,0.220
144.65,4.98,0.220
144.66,5.05,0.220
144.67,5.12,0.220
144.68,5.18,0.220
144.68,5.25,0.220
144.69,5.32,0.220
144.70,5.38,0.220
144.70,5.45,0.220
144.71,5.52,0.220
144.72,5.58,0.220
144.72,5.65,0.220
144.73,5.72,0.220
144.73,5.78,0.220
144.74,5.85,0.220
144.75,5.92,0.220
144.75,5.98,0.220
144.76,6.05,0.220
144.77,6.12,0.220
144.78,6.18,0.220
144.78,6.25,0.220
144.79,6.32,0.220
144.80,6.39,0.220
144.80,6.45,0.220
144.81,6.52,0.221
144.82,6.59,0.221
144.82,6.65,0.221
144.83,6.72,0.221
144.83,6.79,0.221
144.84,6.85,0.221
144.85,6.92,0.221
144.85,6.99,0.221
144.86,7.05,0.221
144.87,7.12,0.221
144.88,7.19,0.221
144.88,7.25,0.221
144.89,7.32,0.221
144.90,7.39,0.221
144.90,7.45,0.221
144.91,7.52,0.221
144.92,7.59,0.221
144.92,7.65,0.221
144.93,7.72,0.221
144.93,7.79,0.221
144.94,7.85,0.221
144.95,7.92,0.221
144.95,7.99,0.221
144.96,8.05,0.221
144.97,8.12,0.221
144.98,8.19,0.221
144.98,8.25,0.222
144.99,8.32,0.222
145.00,8.39,0.222
145.00,8.45,0.222
145.01,8.52,0.222
145.02,8.59,0.222
145.02,8.65,0.222
145.03,8.72,0.222
145.03,8.79,0.222
145.04,8.85,0.222
145.05,8.92,0.222
145.05,8.99,0.222
145.06,9.05,0.222
145.07,9.12,0.222
145.08,9.19,0.222
145.08,9.25,0.222
145.09,9.32,0.222
145.10,9.39,0.222
145.10,9.45,0.222
145.11,9.52,0.222
145.12,9.59,0.222
145.12,9.65,0.223
145.13,9.72,0.223
145.13,9.79,0.223
145.14,9.85,0.223
145.15,9.92,0.223
145.15,9.99,0.223
145.16,10.06,0.223
145.17,10.12,0.223
145.18,10.19,0.223
145.18,10.26,0.223
145.19,10.32,0.223
145.20,10.39,0.223
145.20,10.46,0.223
145.21,10.52,0.223
145.22,10.59,0.223
145.22,10.66,0.223
145.23,10.72,0.223
145.23,10.79,0.223
145.24,10.86,0.223
145.25,10.92,0.223
145.25,10.99,0.223
145.26,11.06,0.224
145.27,11.13,0.224
145.28,11.19,0.224
145.28,11.26,0.224
145.29,11.32,0.224
145.30,11.39,0.224
145.30,11.46,0.224
145.31,11.53,0.224
145.32,11.59,0.224
145.32,11.66,0.224
145.33,11.72,0.224
145.33,11.79,0.224
145.34,11.86,0.224
145.35,11.92,0.224
145.35,11.99,0.224
145.36,12.06,0.224
145.37,12.13,0.224
145.38,12.19,0.224
145.38,12.26,0.224
145.39,12.32,0.225
145.40,12.39,0.225
145.40,12.46,0.225
145.41,12.53,0.225
145.42,12.59,0.225
145.42,12.66,0.225
145.43,12.73,0.225
145.43,12.79,0.225
145.44,12.86,0.225
145.45,12.93,0.225
145.45,12.99,0.225
145.46,13.06,0.225
145.47,13.13,0.225
145.48,13.19,0.225
145.48,13.26,0.226
145.49,13.33,0.226
145.50,13.39,0.226
145.50,13.46,0.226
145.51,13.53,0.226
145.52,13.59,0.226
145.52,13.66,0.226
145.53,13.73,0.226
145.53,13.79,0.226
145.54,13.86,0.226
145.55,13.93,0.226
145.55,13.99,0.226
145.56,14.06,0.226
145.57,14.13,0.226
145.58,14.19,0.226
145.58,14.26,0.227
145.59,14.33,0.227
145.60,14.39,0.227
145.60,14.46,0.227
145.61,14.53,0.227
145.62,14.59,0.227
145.62,14.66,0.227
145.63,14.73,0.227
145.63,14.80,0.227
145.64,14.86,0.227
145.65,14.93,0.227
145.65,14.99,0.227
145.66,15.06,0.227
145.67,15.13,0.227
145.68,15.20,0.227
145.68,15.26,0.227
145.69,15.33,0.227
145.70,15.39,0.227
145.70,15.46,0.228
145.71,15.53,0.228
145.72,15.60,0.228
145.72,15.66,0.228
145.73,15.73,0.228
145.73,15.80,0.228
145.74,15.86,0.228
145.75,15.93,0.228
145.75,16.00,0.228
145.76,16.06,0.228
145.77,16.13,0.228
145.78,16.20,0.228
145.78,16.26,0.228
145.79,16.33,0.228
145.80,16.40,0.228
145.80,16.46,0.228
145.81,16.53,0.228
145.82,16.60,0.229
145.82,16.66,0.229
145.83,16.73,0.229
145.83,16.80,0.229
145.84,16.86,0.229
145.85,16.93,0.229
145.85,17.00,0.229
145.86,17.06,0.229
145.87,17.13,0.229
145.88,17.20,0.229
145.88,17.26,0.229
145.89,17.33,0.229
145.90,17.40,0.229
145.90,17.46,0.229
145.91,17.53,0.230
145.92,17.60,0.230
145.92,17.66,0.230
145.93,17.73,0.230
145.93,17.80,0.230
145.94,17.86,0.230
145.95,17.93,0.230
145.95,18.00,0.230
145.96,18.06,0.230
145.97,18.13,0.230
145.98,18.20,0.230
145.98,18.27,0.230
145.99,18.33,0.230
146.00,18.40,0.230
146.00,18.47,0.230
146.01,18.53,0.230
146.02,18.60,0.231
146.02,18.67,0.231
146.03,18.73,0.231
146.03,18.80,0.231
146.04,18.87,0.231
146.05,18.93,0.231
146.05,19.00,0.231
146.06,19.07,0.231
146.07,19.13,0.231
146.08,19.20,0.231
146.08,19.27,0.231
146.09,19.33,0.231
146.10,19.40,0.231
146.10,19.47,0.231
146.11,19.53,0.232
146.12,19.60,0.232
146.12,19.67,0.232
146.13,19.73,0.232
146.13,19.80,0.232
146.14,19.87,0.232
146.15,19.93,0.232
146.15,20.00,0.232
146.16,20.07,0.232
146.17,20.13,0.232
146.18,20.20,0.232
146.18,20.27,0.232
146.19,20.33,0.232
146.20,20.40,0.232
146.20,20.47,0.232
146.21,20.53,0.232
146.22,20.60,0.233
146.22,20.67,0.233
146.23,20.73,0.233
146.23,20.80,0.233
146.24,20.87,0.233
146.25,20.93,0.233
146.25,21.00,0.233
146.26,21.07,0.233
146.27,21.13,0.233
146.28,21.20,0.233
146.28,21.27,0.233
146.29,21.33,0.233
146.30,21.40,0.233
146.30,21.47,0.233
146.31,21.53,0.233
146.32,21.60,0.233
146.32,21.67,0.233
146.33,21.73,0.233
146.33,21.80,0.233
146.34,21.87,0.234
146.35,21.93,0.234
146.35,22.00,0.234
146.36,22.07,0.234
146.37,22.13,0.234
146.38,22.20,0.234
146.38,22.27,0.234
146.39,22.33,0.234
146.40,22.40,0.234
146.40,22.47,0.234
146.41,22.53,0.234
146.42,22.60,0.234
146.42,22.67,0.234
146.43,22.73,0.234
146.43,22.80,0.234
146.44,22.87,0.234
146.45,22.93,0.235
146.45,23.00,0.235
146.46,23.07,0.235
146.47,23.13,0.235
146.48,23.20,0.235
146.48,23.27,0.235
146.49,23.33,0.235
146.50,23.40,0.235
146.50,23.47,0.235
146.51,23.54,0.235
146.52,23.60,0.235
146.52,23.67,0.235
146.53,23.74,0.235
146.53,23.80,0.235
146.54,23.87,0.235
146.55,23.94,0.235
146.55,24.00,0.235
146.56,24.07,0.236
146.57,24.13,0.236
146.58,24.20,0.236
146.58,24.27,0.236
146.59,24.34,0.236
146.60,24.40,0.236
146.60,24.47,0.236
146.61,24.54,0.236
146.62,24.60,0.236
146.62,24.67,0.236
146.63,24.74,0.236
146.63,24.80,0.236
146.64,24.87,0.236
146.65,24.94,0.236
146.65,25.00,0.236
146.66,25.07,0.236
146.67,25.14,0.237
146.68,25.20,0.237
146.68,25.27,0.237
146.69,25.34,0.237
146.70,25.40,0.237
146.70,25.47,0.237
146.71,25.54,0.237
146.72,25.60,0.237
146.72,25.67,0.237
146.73,25.74,0.237
146.73,25.80,0.237
146.74,25.87,0.237
146.75,25.94,0.237
146.75,26.00,0.237
146.76,26.07,0.237
146.77,26.14,0.237
146.78,26.20,0.238
146.78,26.27,0.238
146.79,26.34,0.238
146.80,26.41,0.238
146.80,26.47,0.238
146.81,26.54,0.238
146.82,26.60,0.238
146.82,26.67,0.238
146.83,26.74,0.238
146.83,26.81,0.238
146.84,26.87,0.238
146.85,26.94,0.238
146.85,27.01,0.238
146.86,27.07,0.238
146.87,27.14,0.238
146.88,27.21,0.238
146.88,27.27,0.238
146.89,27.34,0.238
146.90,27.41,0.239
146.90,27.47,0.239
146.91,27.54,0.239
146.92,27.61,0.239
146.92,27.67,0.239
146.93,27.74,0.239
146.93,27.81,0.239
146.94,27.87,
146.95,27.94,
146.95,28.01,
146.96,28.07,
146.97,28.14,
146.98,28.21,
146.98,28.27,
146.99,,
146.99,,