File: DSC/2025_04_23_CBD_Carnitine_MC_Heptane_n60C_220C_10Cmin_x3.csv
Filename,2025_04_23_CBD_Carnitine_MC_Heptane_n60C_220C_10Cmin_x3
Instrument name,DSC2A-00468 (192.168.1.100)
Operator,Yarger
rundate,4/23/2025
Sample name,2025_04_23_CBD_Carnitine_MC_Heptane_n60C_220C_10Cmin_x3
proceduresegments,Data Off ; Equilibrate -60.00 °C; Data On ; Ramp 10.00 °C/min to 220.00 °C; Data Off ; Isothermal 1.0 min; Data On ; Ramp 10.00 °C/min to -60.00 °C; Data Off ; Isothermal 1.0 min; Data On ; Ramp 10.00 °C/min to 220.00 °C; Data Off ; Isothermal 1.0 min; Data On ; Ramp 10.00 °C/min to -60.00 °C; Data Off ; Isothermal 1.0 min; Data On ; Ramp 10.00 °C/min to 220.00 °C
[File Parameters]
Run date,4/23/2025 5:52:53 AM
Trios version,5.1.1.46572
Original File Name,D:\DSC2500\JYarger\2025_04_23_CBD_Carnitine_MC_Heptane_n60C_220C_10Cmin_x3.tri
Current File Name,D:\DSC2500\JYarger\2025_04_23_CBD_Carnitine_MC_Heptane_n60C_220C_10Cmin_x3.tri
[Procedure]
Procedure Name,CBD_Carnitine_n60_220C_10Cmin_x3
Sample Name,2025_04_23_CBD_Carnitine_MC_Heptane_n60C_220C_10Cmin_x3
Sample Mass,5.01 mg
Reference Sample Mass,0 mg
Pan Mass,53 mg
Pan Number,22
Reference Pan Mass,52.66 mg
Reference Pan Number,19
Pan Type,Tzero Aluminum Hermetic
Comments,Al Hermetic DSC Consumables sealed Pan/Lid.
Project Name,CA
Operator,Yarger
Test,Custom
Unload Max Temperature,30
Unload Min Temperature,30
Load Max Temperature,30
Load Min Temperature,30
Stop on Gas Flow Error,Yes
[Signal List]
Signal #1,Time (min)
Signal #2,Temperature (°C)
Signal #3,Heat Flow (mW)
Signal #4,Delta T (µV)
Signal #5,Delta Tzero (µV)
Signal #6,Tzero Temperature (°C)
Signal #7,Cell Purge (mL/min)
Signal #8,Heater Temp (°C)
Signal #9,Power Delivered (W)
Signal #10,Reference Junction Temperature (°C)
Signal #11,Flange Temperature (°C)
Signal #12,Heat Flow Phase (rad)
Signal #13,Total Heat Capacity (J/°C)
Signal #14,Heat Capacity (J/°C)
[Configuration]
Company Name,ASU
Instrument Name,DSC2A-00468
Instrument Type,DSC2500
Serial Number,DSC2A-00468
IP,192.168.1.100
Location of Instrument,MRRC
DisplayType,Unknown
Sample Interval ,0.1 s/pt
Selected Heat Flow,T4P
Exotherm Direction,Down
Cell Serial,DRC2-00792
Lid Type,Standard
Cooler,RCS 90
Leave Cooler on at End of Sequence,On
Gas 2,Nitrogen
Gas Selected,Channel 1
Flow Rate,50 mL/min
Secondary Purge,On
Licensed Heat Flow,Heat Flow T4P
Modulation Licensed,Yes
[Versions]
Common IDD Version,1
Cortex Version,VER 2.10.2.31
Driver,5.0.0.6
GDM Version,1.0.3.3
TouchscreenVersion,1.0.0.16145
FEP Version,1.2.1.21
FEP Bootloader,2.0.0.5
AutoSampler Version,2.1.1.26
Auto Sampler Bootloader,2.0.0.5
FCM Version,1.1.0.3
FCM Bootloader,2.0.0.5
[Experiment Logs]
Experiment Log Entry # 1,Data On set to 0
Experiment Log Entry # 3,Equilibrate Segment -60 (C) Started
Experiment Log Entry # 5,Data On set to 1
Experiment Log Entry # 7,Ramp Segment 10 C/min to 220 Started
Experiment Log Entry # 9,Data On set to 0
Experiment Log Entry # 11,Isothermal Segment 1 min started
Experiment Log Entry # 13,Data On set to 1
Experiment Log Entry # 15,Ramp Segment 10 C/min to -60 Started
Experiment Log Entry # 17,Data On set to 0
Experiment Log Entry # 19,Isothermal Segment 1 min started
Experiment Log Entry # 21,Data On set to 1
Experiment Log Entry # 23,Ramp Segment 10 C/min to 220 Started
Experiment Log Entry # 25,Data On set to 0
Experiment Log Entry # 27,Isothermal Segment 1 min started
Experiment Log Entry # 29,Data On set to 1
Experiment Log Entry # 31,Ramp Segment 10 C/min to -60 Started
Experiment Log Entry # 33,Data On set to 0
Experiment Log Entry # 35,Isothermal Segment 1 min started
Experiment Log Entry # 37,Data On set to 1
Experiment Log Entry # 39,Ramp Segment 10 C/min to 220 Started
[Method Log]
Method Log Entry # 1,Data Off
Method Log Entry # 2,Equilibrate -60 °C
Method Log Entry # 3,Data On
Method Log Entry # 4,(Ramp 1254389) Ramp 10 °C/minute to 220 °C
Method Log Entry # 5,Data Off
Method Log Entry # 6,Isothermal 1 minutes
Method Log Entry # 7,Data On
Method Log Entry # 8,(Ramp 1254393) Ramp 10 °C/minute to -60 °C
Method Log Entry # 9,Data Off
Method Log Entry # 10,Isothermal 1 minutes
Method Log Entry # 11,Data On
Method Log Entry # 12,(Ramp 1254397) Ramp 10 °C/minute to 220 °C
Method Log Entry # 13,Data Off
Method Log Entry # 14,Isothermal 1 minutes
Method Log Entry # 15,Data On
Method Log Entry # 16,(Ramp 1254401) Ramp 10 °C/minute to -60 °C
Method Log Entry # 17,Data Off
Method Log Entry # 18,Isothermal 1 minutes
Method Log Entry # 19,Data On
Method Log Entry # 20,(Ramp 1254405) Ramp 10 °C/minute to 220 °C
Cell Serial,DRC2-00792
[T1 Calibration]
Slope,-0.008529666
Offset,9.636258
Initial Temperature,98.23
GUID,f8bfdadc-4977-4fdf-ba6d-0ba9134940c3
[TZero Calibration]
Date Applied,11/29/2022 4:06:13 PM
Description,From -89.059 °C to 396.009 °C at 20.000°C/min
Gas Type,Nitrogen
Pan Type,None
Source Files 1,C:\Users\yargerlab\Desktop\DSC Data\General\TZero_calibration_11_29_22_2nd(2).tri
Source Files 2,C:\Users\yargerlab\Desktop\DSC Data\General\TZero_calibration_11_29_22_2nd(3).tri
Delta T Offset,13.05235
Delta T Slope,-0.007271007
Delta T0 Offset,-13.69128
Delta T0 Slope,0.06063341
[Temperature Calibration]
Date Applied,11/29/2022 7:12:28 PM
Description,From 106.590 °C to 186.590 °C at 10.000°C/min
Gas Type,Nitrogen
Pan Type,Tzero Aluminum Hermetic
Source Files 1,C:\Users\yargerlab\Desktop\DSC Data\General\Indium(6).tri
Measured 1,157.391
Known 1,156.598
[Cell Constant Calibration]
Date Applied,11/29/2022 7:12:29 PM
Description,From 106.590 °C to 186.590 °C at 10.000°C/min
Gas Type,Nitrogen
Pan Type,Tzero Aluminum Hermetic
Source Files 1,C:\Users\yargerlab\Desktop\DSC Data\General\Indium(6).tri
T4P KCell,1.006051
Onset Slope,63.26126 mW/°C
[Direct Cp Calibration]
Date Applied,11/30/2022 11:04:51 AM
Description,From -79.983 °C to 298.409 °C at 10.000°C/min
Gas Type,Nitrogen
Pan Type,Tzero Aluminum Hermetic
Source Files 1,C:\Users\yargerlab\Desktop\DSC Data\General\Sapphire_Heat_Capacity_11_30_22.tri
[Rev Cp Calibration]
Date Applied,11/30/2022 1:58:51 PM
Description,From -79.996 °C to 292.812 °C at 3.000°C/min
Gas Type,Nitrogen
Pan Type,Tzero Aluminum Hermetic
Source Files 1,C:\Users\yargerlab\Desktop\DSC Data\General\Sapphire_MDSC_Calibration_11_30_22.tri
[step]
Ramp 10.00 °C/min to 220.00 °C
Time,Temperature,Heat Flow (Normalized)
min,°C,W/g
0.00,-59.68,-0.063
0.02,-59.69,-0.060
0.04,-59.70,-0.053
0.06,-59.69,-0.052
0.08,-59.67,-0.053
0.10,-59.62,-0.055
0.12,-59.55,-0.055
0.14,-59.45,-0.047
0.16,-59.34,-0.025
0.18,-59.21,-0.001
0.20,-59.07,0.023
0.22,-58.91,0.047
0.24,-58.75,0.071
0.26,-58.58,0.091
0.28,-58.41,0.109
0.30,-58.24,0.123
0.32,-58.06,0.136
0.34,-57.88,0.146
0.36,-57.70,0.156
0.38,-57.51,0.161
0.40,-57.33,0.169
0.42,-57.14,0.174
0.44,-56.95,0.177
0.46,-56.76,0.181
0.48,-56.57,0.185
0.50,-56.38,0.188
0.52,-56.19,0.190
0.54,-56.00,0.191
0.56,-55.81,0.193
0.58,-55.61,0.194
0.60,-55.42,0.196
0.62,-55.23,0.197
0.64,-55.03,0.197
0.66,-54.84,0.198
0.68,-54.64,0.199
0.70,-54.45,0.199
0.72,-54.25,0.200
0.74,-54.05,0.200
0.76,-53.86,0.201
0.78,-53.66,0.201
0.80,-53.46,0.202
0.82,-53.27,0.202
0.84,-53.07,0.203
0.86,-52.87,0.203
0.88,-52.68,0.204
0.90,-52.48,0.204
0.92,-52.28,0.204
0.94,-52.08,0.205
0.96,-51.89,0.205
0.98,-51.69,0.206
1.00,-51.49,0.206
1.02,-51.29,0.206
1.04,-51.10,0.207
1.06,-50.90,0.207
1.08,-50.70,0.207
1.10,-50.50,0.208
1.12,-50.30,0.208
1.14,-50.10,0.208
1.16,-49.91,0.208
1.18,-49.71,0.208
1.20,-49.51,0.209
1.22,-49.31,0.209
1.24,-49.11,0.209
1.26,-48.91,0.210
1.28,-48.71,0.210
1.30,-48.51,0.210
1.32,-48.31,0.210
1.34,-48.11,0.210
1.36,-47.92,0.211
1.38,-47.72,0.211
1.40,-47.52,0.211
1.42,-47.32,0.211
1.44,-47.12,0.211
1.46,-46.92,0.211
1.48,-46.72,0.211
1.50,-46.52,0.211
1.52,-46.32,0.212
1.54,-46.12,0.212
1.56,-45.92,0.212
1.58,-45.72,0.212
1.60,-45.52,0.212
1.62,-45.32,0.212
1.64,-45.12,0.212
1.66,-44.92,0.212
1.68,-44.72,0.213
1.70,-44.52,0.213
1.72,-44.32,0.213
1.74,-44.13,0.213
1.76,-43.93,0.213
1.78,-43.73,0.213
1.80,-43.53,0.213
1.82,-43.32,0.213
1.84,-43.13,0.214
1.86,-42.92,0.214
1.88,-42.72,0.214
1.90,-42.52,0.214
1.92,-42.32,0.214
1.94,-42.12,0.214
1.96,-41.93,0.214
1.98,-41.73,0.214
2.00,-41.52,0.215
2.02,-41.32,0.215
2.04,-41.12,0.215
2.06,-40.92,0.215
2.08,-40.72,0.215
2.10,-40.52,0.215
2.12,-40.32,0.215
2.14,-40.13,0.215
2.16,-39.92,0.215
2.18,-39.72,0.215
2.20,-39.52,0.215
2.22,-39.32,0.215
2.24,-39.12,0.216
2.26,-38.92,0.216
2.28,-38.72,0.216
2.30,-38.52,0.216
2.32,-38.32,0.216
2.34,-38.12,0.216
2.36,-37.92,0.216
2.38,-37.72,0.216
2.40,-37.52,0.216
2.42,-37.32,0.216
2.44,-37.12,0.216
2.46,-36.92,0.216
2.48,-36.72,0.216
2.50,-36.52,0.217
2.52,-36.32,0.217
2.54,-36.12,0.217
2.56,-35.92,0.217
2.58,-35.72,0.217
2.60,-35.52,0.217
2.62,-35.32,0.217
2.64,-35.12,0.217
2.66,-34.92,0.217
2.68,-34.72,0.217
2.70,-34.52,0.217
2.72,-34.32,0.217
2.74,-34.12,0.217
2.76,-33.92,0.217
2.78,-33.72,0.217
2.80,-33.52,0.217
2.82,-33.32,0.218
2.84,-33.12,0.218
2.86,-32.92,0.218
2.88,-32.71,0.218
2.90,-32.52,0.218
2.92,-32.32,0.218
2.94,-32.12,0.218
2.96,-31.91,0.218
2.98,-31.71,0.218
3.00,-31.52,0.218
3.02,-31.31,0.218
3.04,-31.11,0.218
3.06,-30.92,0.218
3.08,-30.71,0.218
3.10,-30.51,0.219
3.12,-30.31,0.219
3.14,-30.11,0.219
3.16,-29.91,0.219
3.18,-29.71,0.219
3.20,-29.51,0.219
3.22,-29.31,0.219
3.24,-29.11,0.219
3.26,-28.91,0.219
3.28,-28.71,0.219
3.30,-28.51,0.219
3.32,-28.31,0.219
3.34,-28.11,0.220
3.36,-27.91,0.220
3.38,-27.71,0.220
3.40,-27.51,0.220
3.42,-27.31,0.220
3.44,-27.11,0.220
3.46,-26.91,0.220
3.48,-26.71,0.220
3.50,-26.51,0.220
3.52,-26.31,0.220
3.54,-26.11,0.220
3.56,-25.91,0.220
3.58,-25.71,0.221
3.60,-25.51,0.221
3.62,-25.31,0.221
3.64,-25.11,0.221
3.66,-24.91,0.221
3.68,-24.71,0.221
3.70,-24.51,0.221
3.72,-24.31,0.221
3.74,-24.11,0.221
3.76,-23.91,0.221
3.78,-23.70,0.221
3.80,-23.51,0.221
3.82,-23.30,0.222
3.84,-23.10,0.222
3.86,-22.90,0.222
3.88,-22.70,0.222
3.90,-22.50,0.222
3.92,-22.30,0.222
3.94,-22.10,0.222
3.96,-21.90,0.222
3.98,-21.70,0.222
4.00,-21.50,0.223
4.02,-21.30,0.223
4.04,-21.10,0.223
4.06,-20.90,0.223
4.08,-20.70,0.223
4.10,-20.50,0.223
4.12,-20.30,0.223
4.14,-20.10,0.223
4.16,-19.90,0.223
4.18,-19.70,0.223
4.20,-19.50,0.223
4.22,-19.30,0.223
4.24,-19.10,0.224
4.26,-18.90,0.224
4.28,-18.70,0.224
4.30,-18.50,0.224
4.32,-18.30,0.224
4.34,-18.10,0.224
4.36,-17.90,0.224
4.38,-17.70,0.224
4.40,-17.50,0.224
4.42,-17.30,0.224
4.44,-17.10,0.225
4.46,-16.90,0.225
4.48,-16.70,0.225
4.50,-16.50,0.225
4.52,-16.30,0.225
4.54,-16.10,0.225
4.56,-15.90,0.225
4.58,-15.70,0.225
4.60,-15.50,0.225
4.62,-15.29,0.225
4.64,-15.10,0.226
4.66,-14.90,0.226
4.68,-14.70,0.226
4.70,-14.50,0.226
4.72,-14.29,0.226
4.74,-14.09,0.226
4.76,-13.89,0.226
4.78,-13.69,0.226
4.80,-13.49,0.226
4.82,-13.29,0.226
4.84,-13.09,0.227
4.86,-12.89,0.227
4.88,-12.69,0.227
4.90,-12.49,0.227
4.92,-12.29,0.227
4.94,-12.09,0.227
4.96,-11.89,0.227
4.98,-11.69,0.227
5.00,-11.49,0.227
5.02,-11.29,0.228
5.04,-11.09,0.228
5.06,-10.89,0.228
5.08,-10.69,0.228
5.10,-10.49,0.228
5.12,-10.29,0.228
5.14,-10.09,0.228
5.16,-9.89,0.228
5.18,-9.69,0.228
5.20,-9.49,0.229
5.22,-9.29,0.229
5.24,-9.09,0.229
5.26,-8.89,0.229
5.28,-8.69,0.229
5.30,-8.49,0.229
5.32,-8.29,0.229
5.34,-8.09,0.229
5.36,-7.89,0.229
5.38,-7.69,0.230
5.40,-7.49,0.230
5.42,-7.29,0.230
5.44,-7.09,0.230
5.46,-6.89,0.230
5.48,-6.69,0.230
5.50,-6.49,0.230
5.52,-6.29,0.231
5.54,-6.09,0.231
5.56,-5.89,0.231
5.58,-5.69,0.231
5.60,-5.49,0.231
5.62,-5.29,0.231
5.64,-5.09,0.232
5.66,-4.88,0.232
5.68,-4.69,0.232
5.70,-4.49,0.232
5.72,-4.29,0.232
5.74,-4.08,0.232
5.76,-3.88,0.232
5.78,-3.68,0.232
5.80,-3.48,0.232
5.82,-3.28,0.233
5.84,-3.08,0.233
5.86,-2.88,0.233
5.88,-2.68,0.233
5.90,-2.48,0.233
5.92,-2.28,0.233
5.94,-2.08,0.233
5.96,-1.88,0.233
5.98,-1.68,0.234
6.00,-1.48,0.234
6.02,-1.28,0.234
6.04,-1.08,0.234
6.06,-0.88,0.234
6.08,-0.68,0.234
6.10,-0.48,0.234
6.12,-0.28,0.234
6.14,-0.08,0.235
6.16,0.12,0.235
6.18,0.32,0.235
6.20,0.52,0.235
6.22,0.72,0.235
6.24,0.92,0.235
6.26,1.12,0.235
6.28,1.32,0.235
6.30,1.52,0.235
6.32,1.72,0.236
6.34,1.92,0.236
6.36,2.12,0.236
6.38,2.32,0.236
6.40,2.52,0.236
6.42,2.72,0.236
6.44,2.93,0.236
6.46,3.12,0.237
6.48,3.32,0.237
6.50,3.52,0.237
6.52,3.73,0.237
6.54,3.92,0.237
6.56,4.13,0.237
6.58,4.33,0.238
6.60,4.53,0.238
6.62,4.73,0.238
6.64,4.93,0.238
6.66,5.13,0.238
6.68,5.33,0.238
6.70,5.53,0.239
6.72,5.73,0.239
6.74,5.93,0.239
6.76,6.13,0.239
6.78,6.33,0.239
6.80,6.53,0.239
6.82,6.73,0.239
6.84,6.93,0.240
6.86,7.13,0.240
6.88,7.33,0.240
6.90,7.53,0.240
6.92,7.73,0.240
6.94,7.93,0.240
6.96,8.13,0.241
6.98,8.33,0.241
7.00,8.53,0.241
7.02,8.73,0.241
7.04,8.93,0.241
7.06,9.13,0.242
7.08,9.33,0.242
7.10,9.53,0.242
7.12,9.73,0.242
7.14,9.93,0.242
7.16,10.13,0.243
7.18,10.33,0.243
7.20,10.53,0.243
7.22,10.73,0.243
7.24,10.93,0.243
7.26,11.13,0.243
7.28,11.33,0.243
7.30,11.53,0.244
7.32,11.73,0.244
7.34,11.93,0.244
7.36,12.13,0.244
7.38,12.33,0.244
7.40,12.53,0.244
7.42,12.73,0.245
7.44,12.94,0.245
7.46,13.14,0.245
7.48,13.33,0.245
7.50,13.53,0.246
7.52,13.74,0.246
7.54,13.94,0.246
7.56,14.14,0.246
7.58,14.34,0.246
7.60,14.54,0.246
7.62,14.74,0.247
7.64,14.94,0.247
7.66,15.14,0.247
7.68,15.34,0.247
7.70,15.54,0.248
7.72,15.74,0.248
7.74,15.94,0.248
7.76,16.14,0.248
7.78,16.34,0.249
7.80,16.54,0.249
7.82,16.74,0.249
7.84,16.94,0.249
7.86,17.14,0.249
7.88,17.34,0.250
7.90,17.54,0.250
7.92,17.74,0.250
7.94,17.94,0.250
7.96,18.14,0.250
7.98,18.34,0.250
8.00,18.54,0.251
8.02,18.74,0.251
8.04,18.94,0.251
8.06,19.14,0.251
8.08,19.34,0.251
8.10,19.54,0.251
8.12,19.74,0.251
8.14,19.94,0.252
8.16,20.14,0.252
8.18,20.34,0.252
8.20,20.54,0.252
8.22,20.74,0.253
8.24,20.94,0.253
8.26,21.14,0.253
8.28,21.34,0.253
8.30,21.54,0.253
8.32,21.74,0.254
8.34,21.94,0.254
8.36,22.14,0.254
8.38,22.34,0.254
8.40,22.54,0.254
8.42,22.74,0.255
8.44,22.94,0.255
8.46,23.14,0.255
8.48,23.34,0.255
8.50,23.55,0.255
8.52,23.74,0.256
8.54,23.95,0.256
8.56,24.15,0.256
8.58,24.35,0.256
8.60,24.54,0.256
8.62,24.75,0.257
8.64,24.94,0.257
8.66,25.15,0.257
8.68,25.35,0.257
8.70,25.55,0.257
8.72,25.75,0.258
8.74,25.95,0.258
8.76,26.15,0.258
8.78,26.35,0.258
8.80,26.55,0.258
8.82,26.75,0.259
8.84,26.95,0.259
8.86,27.15,0.259
8.88,27.35,0.259
8.90,27.55,0.259
8.92,27.75,0.260
8.94,27.95,0.260
8.96,28.15,0.260
8.98,28.35,0.260
9.00,28.55,0.260
9.02,28.75,0.261
9.04,28.95,0.261
9.06,29.15,0.261
9.08,29.35,0.261
9.10,29.55,0.262
9.12,29.75,0.262
9.14,29.95,0.262
9.16,30.15,0.262
9.18,30.35,0.262
9.20,30.55,0.263
9.22,30.75,0.263
9.24,30.95,0.263
9.26,31.15,0.263
9.28,31.35,0.264
9.30,31.55,0.264
9.32,31.75,0.264
9.34,31.95,0.264
9.36,32.15,0.264
9.38,32.35,0.265
9.40,32.55,0.265
9.42,32.75,0.265
9.44,32.95,0.266
9.46,33.15,0.266
9.48,33.35,0.266
9.50,33.55,0.266
9.52,33.75,0.267
9.54,33.95,0.267
9.56,34.15,0.267
9.58,34.35,0.267
9.60,34.55,0.268
9.62,34.75,0.268
9.64,34.95,0.268
9.66,35.15,0.269
9.68,35.35,0.269
9.70,35.55,0.269
9.72,35.76,0.270
9.74,35.95,0.270
9.76,36.16,0.270
9.78,36.35,0.271
9.80,36.55,0.271
9.82,36.75,0.272
9.84,36.96,0.273
9.86,37.16,0.273
9.88,37.36,0.274
9.90,37.56,0.274
9.92,37.75,0.274
9.94,37.95,0.275
9.96,38.16,0.276
9.98,38.35,0.276
10.00,38.55,0.277
10.02,38.75,0.277
10.04,38.95,0.278
10.06,39.15,0.278
10.08,39.35,0.279
10.10,39.56,0.279
10.12,39.76,0.280
10.14,39.95,0.281
10.16,40.15,0.282
10.18,40.36,0.282
10.20,40.56,0.283
10.22,40.76,0.284
10.24,40.95,0.285
10.26,41.15,0.285
10.28,41.36,0.286
10.30,41.56,0.287
10.32,41.76,0.287
10.34,41.96,0.288
10.36,42.15,0.289
10.38,42.36,0.290
10.40,42.56,0.290
10.42,42.75,0.291
10.44,42.96,0.292
10.46,43.16,0.292
10.48,43.35,0.294
10.50,43.55,0.295
10.52,43.75,0.295
10.54,43.95,0.297
10.56,44.15,0.298
10.58,44.35,0.299
10.60,44.55,0.299
10.62,44.75,0.301
10.64,44.95,0.303
10.66,45.15,0.304
10.68,45.35,0.305
10.70,45.55,0.306
10.72,45.75,0.308
10.74,45.95,0.309
10.76,46.15,0.310
10.78,46.35,0.312
10.80,46.55,0.313
10.82,46.75,0.314
10.84,46.95,0.316
10.86,47.15,0.317
10.88,47.35,0.321
10.90,47.55,0.323
10.92,47.75,0.326
10.94,47.95,0.328
10.96,48.15,0.331
10.98,48.35,0.333
11.00,48.55,0.335
11.02,48.75,0.338
11.04,48.95,0.340
11.06,49.15,0.345
11.08,49.35,0.348
11.10,49.55,0.350
11.12,49.74,0.353
11.14,49.94,0.357
11.16,50.14,0.360
11.18,50.34,0.365
11.20,50.54,0.368
11.22,50.74,0.373
11.24,50.94,0.377
11.26,51.14,0.380
11.28,51.34,0.386
11.30,51.54,0.391
11.32,51.73,0.395
11.34,51.93,0.400
11.36,52.13,0.407
11.38,52.33,0.412
11.40,52.53,0.418
11.42,52.73,0.423
11.44,52.92,0.430
11.46,53.12,0.438
11.48,53.32,0.443
11.50,53.52,0.452
11.52,53.72,0.458
11.54,53.91,0.467
11.56,54.11,0.474
11.58,54.31,0.486
11.60,54.51,0.492
11.62,54.70,0.503
11.64,54.90,0.513
11.66,55.10,0.523
11.68,55.30,0.535
11.70,55.49,0.546
11.72,55.69,0.557
11.74,55.89,0.568
11.76,56.08,0.582
11.78,56.28,0.594
11.80,56.47,0.609
11.82,56.67,0.621
11.84,56.87,0.636
11.86,57.06,0.649
11.88,57.26,0.665
11.90,57.45,0.679
11.92,57.65,0.694
11.94,57.84,0.708
11.96,58.04,0.723
11.98,58.23,0.737
12.00,58.43,0.752
12.02,58.62,0.767
12.04,58.82,0.785
12.06,59.01,0.801
12.08,59.21,0.819
12.10,59.40,0.833
12.12,59.60,0.852
12.14,59.79,0.876
12.16,59.98,0.901
12.18,60.18,0.928
12.20,60.37,0.955
12.22,60.56,0.987
12.24,60.75,1.018
12.26,60.94,1.044
12.28,61.13,1.067
12.30,61.33,1.087
12.32,61.52,1.110
12.34,61.71,1.124
12.36,61.90,1.129
12.38,62.10,1.131
12.40,62.30,1.133
12.42,62.49,1.131
12.44,62.69,1.130
12.46,62.89,1.121
12.48,63.09,1.103
12.50,63.30,1.083
12.52,63.50,1.055
12.54,63.71,1.025
12.56,63.92,0.990
12.58,64.13,0.950
12.60,64.34,0.910
12.62,64.55,0.865
12.64,64.76,0.820
12.66,64.98,0.774
12.68,65.19,0.728
12.70,65.41,0.682
12.72,65.62,0.641
12.74,65.84,0.601
12.76,66.05,0.566
12.78,66.27,0.536
12.80,66.48,0.512
12.82,66.69,0.491
12.84,66.90,0.476
12.86,67.11,0.466
12.88,67.31,0.457
12.90,67.52,0.450
12.92,67.72,0.447
12.94,67.93,0.445
12.96,68.13,0.444
12.98,68.33,0.446
13.00,68.53,0.447
13.02,68.73,0.452
13.04,68.93,0.462
13.06,69.13,0.482
13.08,69.33,0.505
13.10,69.52,0.538
13.12,69.71,0.585
13.14,69.90,0.649
13.16,70.09,0.734
13.18,70.27,0.842
13.20,70.44,0.974
13.22,70.60,1.119
13.24,70.77,1.264
13.26,70.93,1.389
13.28,71.09,1.455
13.30,71.26,1.469
13.32,71.44,1.402
13.34,71.64,1.292
13.36,71.85,1.159
13.38,72.07,1.021
13.40,72.30,0.900
13.42,72.54,0.781
13.44,72.77,0.693
13.46,73.00,0.619
13.48,73.23,0.567
13.50,73.45,0.528
13.52,73.67,0.498
13.54,73.89,0.476
13.56,74.11,0.454
13.58,74.32,0.440
13.60,74.53,0.427
13.62,74.73,0.415
13.64,74.94,0.406
13.66,75.15,0.399
13.68,75.35,0.394
13.70,75.56,0.388
13.72,75.76,0.384
13.74,75.96,0.380
13.76,76.16,0.378
13.78,76.36,0.375
13.80,76.57,0.373
13.82,76.77,0.372
13.84,76.97,0.370
13.86,77.17,0.368
13.88,77.37,0.367
13.90,77.57,0.366
13.92,77.77,0.366
13.94,77.97,0.365
13.96,78.17,0.364
13.98,78.38,0.364
14.00,78.58,0.364
14.02,78.78,0.362
14.04,78.98,0.362
14.06,79.18,0.361
14.08,79.38,0.361
14.10,79.58,0.360
14.12,79.78,0.360
14.14,79.98,0.359
14.16,80.18,0.359
14.18,80.38,0.358
14.20,80.58,0.356
14.22,80.78,0.356
14.24,80.98,0.355
14.26,81.18,0.355
14.28,81.38,0.354
14.30,81.58,0.354
14.32,81.78,0.353
14.34,81.98,0.353
14.36,82.18,0.352
14.38,82.39,0.351
14.40,82.59,0.350
14.42,82.79,0.350
14.44,82.99,0.349
14.46,83.19,0.348
14.48,83.39,0.347
14.50,83.59,0.346
14.52,83.79,0.346
14.54,83.99,0.345
14.56,84.19,0.344
14.58,84.39,0.343
14.60,84.59,0.343
14.62,84.79,0.342
14.64,84.99,0.341
14.66,85.19,0.341
14.68,85.39,0.340
14.70,85.59,0.339
14.72,85.79,0.338
14.74,85.99,0.338
14.76,86.19,0.337
14.78,86.39,0.336
14.80,86.59,0.336
14.82,86.79,0.335
14.84,86.99,0.334
14.86,87.20,0.334
14.88,87.40,0.333
14.90,87.60,0.332
14.92,87.80,0.332
14.94,88.00,0.331
14.96,88.20,0.331
14.98,88.40,0.330
15.00,88.60,0.329
15.02,88.80,0.329
15.04,89.00,0.328
15.06,89.20,0.328
15.08,89.40,0.328
15.10,89.60,0.327
15.12,89.80,0.327
15.14,90.00,0.326
15.16,90.20,0.326
15.18,90.40,0.325
15.20,90.60,0.325
15.22,90.80,0.324
15.24,91.00,0.324
15.26,91.20,0.323
15.28,91.40,0.323
15.30,91.60,0.323
15.32,91.80,0.322
15.34,92.00,0.322
15.36,92.20,0.322
15.38,92.40,0.321
15.40,92.61,0.321
15.42,92.80,0.321
15.44,93.01,0.321
15.46,93.21,0.321
15.48,93.41,0.320
15.50,93.61,0.320
15.52,93.81,0.320
15.54,94.01,0.320
15.56,94.21,0.320
15.58,94.41,0.320
15.60,94.61,0.320
15.62,94.81,0.320
15.64,95.01,0.320
15.66,95.21,0.320
15.68,95.41,0.320
15.70,95.61,0.320
15.72,95.81,0.320
15.74,96.01,0.320
15.76,96.21,0.320
15.78,96.41,0.321
15.80,96.61,0.321
15.82,96.81,0.321
15.84,97.01,0.321
15.86,97.21,0.322
15.88,97.41,0.322
15.90,97.61,0.323
15.92,97.81,0.323
15.94,98.01,0.323
15.96,98.21,0.324
15.98,98.41,0.324
16.00,98.61,0.324
16.02,98.81,0.325
16.04,99.01,0.325
16.06,99.21,0.326
16.08,99.41,0.326
16.10,99.61,0.327
16.12,99.81,0.327
16.14,100.01,0.328
16.16,100.21,0.329
16.18,100.41,0.329
16.20,100.61,0.330
16.22,100.81,0.330
16.24,101.01,0.330
16.26,101.21,0.331
16.28,101.41,0.332
16.30,101.61,0.332
16.32,101.81,0.333
16.34,102.01,0.334
16.36,102.21,0.334
16.38,102.41,0.335
16.40,102.61,0.336
16.42,102.81,0.337
16.44,103.01,0.339
16.46,103.21,0.339
16.48,103.41,0.340
16.50,103.61,0.341
16.52,103.81,0.341
16.54,104.01,0.342
16.56,104.21,0.343
16.58,104.41,0.343
16.60,104.61,0.344
16.62,104.81,0.345
16.64,105.01,0.345
16.66,105.21,0.346
16.68,105.41,0.347
16.70,105.61,0.348
16.72,105.81,0.349
16.74,106.01,0.351
16.76,106.21,0.352
16.78,106.41,0.353
16.80,106.61,0.354
16.82,106.81,0.355
16.84,107.01,0.356
16.86,107.21,0.357
16.88,107.41,0.359
16.90,107.61,0.359
16.92,107.81,0.361
16.94,108.01,0.363
16.96,108.20,0.364
16.98,108.40,0.365
17.00,108.60,0.366
17.02,108.80,0.367
17.04,109.00,0.368
17.06,109.20,0.369
17.08,109.40,0.371
17.10,109.60,0.372
17.12,109.80,0.375
17.14,110.00,0.375
17.16,110.20,0.378
17.18,110.40,0.379
17.20,110.60,0.381
17.22,110.80,0.382
17.24,111.00,0.383
17.26,111.20,0.385
17.28,111.40,0.386
17.30,111.60,0.387
17.32,111.80,0.388
17.34,112.00,0.389
17.36,112.20,0.390
17.38,112.40,0.392
17.40,112.60,0.394
17.42,112.80,0.395
17.44,113.00,0.397
17.46,113.20,0.398
17.48,113.40,0.399
17.50,113.60,0.400
17.52,113.80,0.401
17.54,114.00,0.403
17.56,114.20,0.405
17.58,114.40,0.406
17.60,114.60,0.407
17.62,114.80,0.409
17.64,115.00,0.410
17.66,115.20,0.412
17.68,115.40,0.413
17.70,115.60,0.416
17.72,115.80,0.417
17.74,115.99,0.418
17.76,116.19,0.419
17.78,116.39,0.421
17.80,116.59,0.422
17.82,116.79,0.423
17.84,116.99,0.425
17.86,117.19,0.427
17.88,117.39,0.429
17.90,117.59,0.430
17.92,117.79,0.432
17.94,117.99,0.434
17.96,118.19,0.436
17.98,118.39,0.437
18.00,118.59,0.439
18.02,118.79,0.440
18.04,118.99,0.442
18.06,119.19,0.443
18.08,119.39,0.445
18.10,119.59,0.447
18.12,119.79,0.449
18.14,119.99,0.450
18.16,120.19,0.453
18.18,120.39,0.455
18.20,120.59,0.456
18.22,120.79,0.457
18.24,120.99,0.459
18.26,121.19,0.460
18.28,121.39,0.461
18.30,121.59,0.463
18.32,121.79,0.464
18.34,121.99,0.465
18.36,122.19,0.466
18.38,122.39,0.466
18.40,122.59,0.468
18.42,122.79,0.469
18.44,122.99,0.470
18.46,123.18,0.471
18.48,123.39,0.473
18.50,123.58,0.474
18.52,123.79,0.476
18.54,123.98,0.478
18.56,124.18,0.479
18.58,124.38,0.480
18.60,124.58,0.481
18.62,124.78,0.482
18.64,124.98,0.483
18.66,125.18,0.484
18.68,125.38,0.485
18.70,125.58,0.486
18.72,125.78,0.487
18.74,125.98,0.488
18.76,126.18,0.490
18.78,126.38,0.492
18.80,126.58,0.493
18.82,126.78,0.494
18.84,126.98,0.495
18.86,127.18,0.498
18.88,127.38,0.499
18.90,127.58,0.501
18.92,127.78,0.502
18.94,127.98,0.504
18.96,128.18,0.507
18.98,128.38,0.511
19.00,128.58,0.513
19.02,128.78,0.516
19.04,128.98,0.519
19.06,129.18,0.521
19.08,129.38,0.525
19.10,129.58,0.527
19.12,129.77,0.531
19.14,129.97,0.533
19.16,130.17,0.537
19.18,130.37,0.541
19.20,130.57,0.546
19.22,130.77,0.550
19.24,130.97,0.555
19.26,131.17,0.560
19.28,131.37,0.565
19.30,131.57,0.571
19.32,131.76,0.576
19.34,131.96,0.583
19.36,132.16,0.588
19.38,132.36,0.595
19.40,132.56,0.602
19.42,132.76,0.612
19.44,132.96,0.622
19.46,133.15,0.635
19.48,133.35,0.646
19.50,133.55,0.659
19.52,133.74,0.670
19.54,133.94,0.681
19.56,134.14,0.688
19.58,134.33,0.696
19.60,134.53,0.700
19.62,134.73,0.701
19.64,134.93,0.702
19.66,135.13,0.703
19.68,135.33,0.695
19.70,135.53,0.679
19.72,135.73,0.663
19.74,135.93,0.643
19.76,136.14,0.619
19.78,136.35,0.596
19.80,136.55,0.571
19.82,136.76,0.548
19.84,136.96,0.525
19.86,137.17,0.504
19.88,137.38,0.487
19.90,137.59,0.470
19.92,137.79,0.461
19.94,138.00,0.450
19.96,138.20,0.439
19.98,138.40,0.430
20.00,138.61,0.424
20.02,138.81,0.420
20.04,139.01,0.414
20.06,139.21,0.412
20.08,139.42,0.409
20.10,139.62,0.408
20.12,139.82,0.407
20.14,140.02,0.405
20.16,140.22,0.404
20.18,140.42,0.404
20.20,140.62,0.403
20.22,140.82,0.403
20.24,141.02,0.403
20.26,141.22,0.403
20.28,141.42,0.403
20.30,141.62,0.402
20.32,141.82,0.402
20.34,142.02,0.402
20.36,142.22,0.402
20.38,142.42,0.402
20.40,142.62,0.402
20.42,142.82,0.402
20.44,143.02,0.402
20.46,143.22,0.403
20.48,143.42,0.403
20.50,143.62,0.403
20.52,143.82,0.403
20.54,144.03,0.403
20.56,144.22,0.403
20.58,144.42,0.403
20.60,144.62,0.404
20.62,144.83,0.404
20.64,145.03,0.404
20.66,145.23,0.404
20.68,145.43,0.404
20.70,145.63,0.405
20.72,145.83,0.405
20.74,146.03,0.405
20.76,146.23,0.405
20.78,146.43,0.406
20.80,146.63,0.406
20.82,146.83,0.406
20.84,147.03,0.406
20.86,147.23,0.407
20.88,147.43,0.408
20.90,147.63,0.410
20.92,147.83,0.410
20.94,148.03,0.411
20.96,148.23,0.412
20.98,148.43,0.413
21.00,148.63,0.414
21.02,148.82,0.415
21.04,149.02,0.417
21.06,149.22,0.418
21.08,149.42,0.420
21.10,149.62,0.420
21.12,149.82,0.423
21.14,150.02,0.425
21.16,150.22,0.428
21.18,150.42,0.430
21.20,150.62,0.433
21.22,150.82,0.435
21.24,151.02,0.437
21.26,151.22,0.439
21.28,151.42,0.441
21.30,151.62,0.443
21.32,151.82,0.447
21.34,152.02,0.449
21.36,152.22,0.452
21.38,152.42,0.455
21.40,152.62,0.458
21.42,152.82,0.462
21.44,153.01,0.465
21.46,153.21,0.469
21.48,153.41,0.472
21.50,153.61,0.477
21.52,153.81,0.481
21.54,154.01,0.485
21.56,154.21,0.489
21.58,154.41,0.491
21.60,154.61,0.496
21.62,154.81,0.502
21.64,155.01,0.505
21.66,155.21,0.505
21.68,155.41,0.506
21.70,155.61,0.507
21.72,155.80,0.509
21.74,156.00,0.510
21.76,156.20,0.512
21.78,156.40,0.516
21.80,156.60,0.516
21.82,156.80,0.519
21.84,157.00,0.522
21.86,157.20,0.524
21.88,157.40,0.526
21.90,157.60,0.528
21.92,157.80,0.532
21.94,158.00,0.533
21.96,158.20,0.534
21.98,158.40,0.536
22.00,158.60,0.541
22.02,158.79,0.547
22.04,158.99,0.549
22.06,159.19,0.549
22.08,159.39,0.550
22.10,159.59,0.553
22.12,159.79,0.556
22.14,159.99,0.557
22.16,160.19,0.563
22.18,160.39,0.564
22.20,160.59,0.566
22.22,160.79,0.569
22.24,160.99,0.577
22.26,161.19,0.579
22.28,161.39,0.580
22.30,161.59,0.580
22.32,161.79,0.580
22.34,161.99,0.580
22.36,162.19,0.581
22.38,162.39,0.581
22.40,162.59,0.585
22.42,162.78,0.593
22.44,162.98,0.597
22.46,163.18,0.595
22.48,163.38,0.594
22.50,163.58,0.594
22.52,163.78,0.600
22.54,163.98,0.601
22.56,164.18,0.600
22.58,164.38,0.601
22.60,164.58,0.601
22.62,164.78,0.600
22.64,164.98,0.601
22.66,165.18,0.605
22.68,165.38,0.612
22.70,165.58,0.611
22.72,165.78,0.611
22.74,165.98,0.611
22.76,166.18,0.613
22.78,166.38,0.613
22.80,166.58,0.613
22.82,166.78,0.614
22.84,166.98,0.617
22.86,167.18,0.621
22.88,167.38,0.622
22.90,167.58,0.620
22.92,167.78,0.619
22.94,167.98,0.624
22.96,168.18,0.624
22.98,168.38,0.654
23.00,168.57,0.694
23.02,168.77,0.690
23.04,168.97,0.680
23.06,169.17,0.676
23.08,169.36,0.676
23.10,169.57,0.675
23.12,169.76,0.678
23.14,169.96,0.687
23.16,170.16,0.685
23.18,170.36,0.686
23.20,170.56,0.687
23.22,170.76,0.689
23.24,170.96,0.692
23.26,171.16,0.703
23.28,171.36,0.712
23.30,171.56,0.712
23.32,171.76,0.733
23.34,171.95,0.746
23.36,172.15,0.763
23.38,172.35,0.785
23.40,172.54,0.829
23.42,172.73,0.872
23.44,172.92,0.875
23.46,173.12,0.869
23.48,173.32,0.865
23.50,173.52,0.853
23.52,173.72,0.843
23.54,173.92,0.843
23.56,174.12,0.836
23.58,174.32,0.819
23.60,174.52,0.815
23.62,174.73,0.810
23.64,174.93,0.809
23.66,175.13,0.806
23.68,175.33,0.808
23.70,175.53,0.807
23.72,175.73,0.803
23.74,175.93,0.804
23.76,176.13,0.807
23.78,176.33,0.811
23.80,176.53,0.810
23.82,176.73,0.808
23.84,176.93,0.813
23.86,177.13,0.813
23.88,177.33,0.814
23.90,177.53,0.818
23.92,177.73,0.815
23.94,177.93,0.825
23.96,178.13,0.826
23.98,178.33,0.826
24.00,178.53,0.827
24.02,178.73,0.828
24.04,178.93,0.828
24.06,179.13,0.823
24.08,179.33,0.823
24.10,179.53,0.820
24.12,179.73,0.820
24.14,179.93,0.818
24.16,180.13,0.817
24.18,180.33,0.815
24.20,180.53,0.806
24.22,180.73,0.796
24.24,180.94,0.801
24.26,181.14,0.801
24.28,181.34,0.800
24.30,181.54,0.799
24.32,181.74,0.796
24.34,181.94,0.802
24.36,182.14,0.802
24.38,182.34,0.797
24.40,182.54,0.786
24.42,182.74,0.786
24.44,182.94,0.787
24.46,183.14,0.793
24.48,183.34,0.793
24.50,183.54,0.795
24.52,183.74,0.796
24.54,183.94,0.776
24.56,184.14,0.780
24.58,184.34,0.797
24.60,184.54,0.798
24.62,184.74,0.801
24.64,184.94,0.799
24.66,185.14,0.796
24.68,185.34,0.797
24.70,185.54,0.804
24.72,185.74,0.809
24.74,185.94,0.803
24.76,186.14,0.792
24.78,186.34,0.792
24.80,186.54,0.793
24.82,186.74,0.790
24.84,186.94,0.788
24.86,187.14,0.791
24.88,187.34,0.811
24.90,187.54,0.835
24.92,187.74,0.825
24.94,187.94,0.818
24.96,188.14,0.814
24.98,188.34,0.786
25.00,188.54,0.748
25.02,188.75,0.712
25.04,188.96,0.704
25.06,189.16,0.705
25.08,189.36,0.715
25.10,189.56,0.718
25.12,189.77,0.712
25.14,189.97,0.704
25.16,190.17,0.699
25.18,190.37,0.697
25.20,190.57,0.684
25.22,190.77,0.672
25.24,190.98,0.661
25.26,191.18,0.654
25.28,191.38,0.656
25.30,191.58,0.658
25.32,191.78,0.659
25.34,191.98,0.661
25.36,192.18,0.672
25.38,192.38,0.671
25.40,192.58,0.671
25.42,192.78,0.650
25.44,192.99,0.649
25.46,193.19,0.649
25.48,193.39,0.632
25.50,193.59,0.616
25.52,193.79,0.621
25.54,193.99,0.620
25.56,194.20,0.616
25.58,194.39,0.619
25.60,194.59,0.634
25.62,194.79,0.647
25.64,194.99,0.645
25.66,195.19,0.597
25.68,195.40,0.585
25.70,195.60,0.581
25.72,195.80,0.588
25.74,196.00,0.624
25.76,196.19,0.685
25.78,196.38,0.763
25.80,196.57,0.908
25.82,196.74,1.158
25.84,196.89,1.429
25.86,197.03,1.739
25.88,197.16,1.992
25.90,197.31,2.011
25.92,197.48,1.953
25.94,197.66,1.923
25.96,197.85,1.873
25.98,198.05,1.880
26.00,198.25,1.818
26.02,198.45,1.801
26.04,198.66,1.764
26.06,198.86,1.815
26.08,199.07,1.747
26.10,199.27,1.765
26.12,199.48,1.720
26.14,199.68,1.692
26.16,199.89,1.673
26.18,200.08,1.809
26.20,200.28,1.768
26.22,200.48,1.723
26.24,200.68,1.690
26.26,200.89,1.671
26.28,201.09,1.672
26.30,201.30,1.598
26.32,201.51,1.590
26.34,201.72,1.610
26.36,201.92,1.623
26.38,202.12,1.538
26.40,202.33,1.528
26.42,202.54,1.495
26.44,202.75,1.443
26.46,202.95,1.437
26.48,203.16,1.415
26.50,203.36,1.434
26.52,203.57,1.400
26.54,203.77,1.385
26.56,203.97,1.525
26.58,204.16,1.527
26.60,204.36,1.437
26.62,204.56,1.487
26.64,204.76,1.457
26.66,204.97,1.399
26.68,205.17,1.373
26.70,205.38,1.324
26.72,205.59,1.313
26.74,205.80,1.279
26.76,206.01,1.253
26.78,206.21,1.228
26.80,206.42,1.212
26.82,206.63,1.188
26.84,206.83,1.183
26.86,207.04,1.159
26.88,207.24,1.139
26.90,207.45,1.128
26.92,207.66,1.104
26.94,207.86,1.093
26.96,208.07,1.070
26.98,208.27,1.052
27.00,208.47,1.050
27.02,208.68,1.042
27.04,208.88,1.008
27.06,209.09,0.979
27.08,209.30,0.964
27.10,209.50,0.950
27.12,209.71,0.932
27.14,209.91,0.948
27.16,210.11,0.939
27.18,210.31,0.970
27.20,210.51,0.968
27.22,210.71,0.906
27.24,210.92,0.901
27.26,211.12,0.909
27.28,211.32,0.893
27.30,211.53,0.885
27.32,211.73,0.859
27.34,211.94,0.843
27.36,212.14,0.836
27.38,212.34,0.828
27.40,212.54,0.838
27.42,212.75,0.812
27.44,212.95,0.782
27.46,213.16,0.762
27.48,213.36,0.748
27.50,213.56,0.731
27.52,213.77,0.731
27.54,213.97,0.718
27.56,214.18,0.698
27.58,214.38,0.684
27.60,214.58,0.681
27.62,214.79,0.670
27.64,214.99,0.660
27.66,215.19,0.655
27.68,215.39,0.646
27.70,215.60,0.640
27.72,215.80,0.639
27.74,216.00,0.632
27.76,216.20,0.629
27.78,216.40,0.627
27.80,216.61,0.615
27.82,216.81,0.600
27.84,217.01,0.589
27.86,217.21,0.583
27.88,217.42,0.583
27.90,217.62,0.580
27.92,217.82,0.574
27.94,218.02,
27.96,218.22,
27.98,218.42,
27.99,,

[step]
Ramp 10.00 °C/min to -60.00 °C
Time,Temperature,Heat Flow (Normalized)
min,°C,W/g
28.99,220.03,0.129
29.01,220.03,0.126
29.03,220.03,0.126
29.05,220.01,0.172
29.07,219.97,0.248
29.09,219.90,0.332
29.11,219.80,0.393
29.13,219.67,0.413
29.15,219.54,0.390
29.17,219.38,0.337
29.19,219.22,0.272
29.21,219.06,0.208
29.23,218.89,0.150
29.25,218.71,0.101
29.27,218.54,0.062
29.29,218.36,0.027
29.31,218.18,-0.001
29.33,217.99,-0.027
29.35,217.81,-0.048
29.37,217.62,-0.064
29.39,217.43,-0.080
29.41,217.24,-0.096
29.43,217.05,-0.110
29.45,216.86,-0.119
29.47,216.67,-0.131
29.49,216.47,-0.139
29.51,216.28,-0.146
29.53,216.09,-0.153
29.55,215.89,-0.158
29.57,215.70,-0.163
29.59,215.50,-0.170
29.61,215.30,-0.173
29.63,215.11,-0.178
29.65,214.91,-0.182
29.67,214.72,-0.186
29.69,214.52,-0.189
29.71,214.32,-0.192
29.73,214.13,-0.195
29.75,213.93,-0.196
29.77,213.73,-0.199
29.79,213.53,-0.202
29.81,213.34,-0.203
29.83,213.14,-0.204
29.85,212.94,-0.206
29.87,212.74,-0.208
29.89,212.55,-0.209
29.91,212.35,-0.211
29.93,212.15,-0.212
29.95,211.95,-0.214
29.97,211.75,-0.215
29.99,211.55,-0.217
30.01,211.36,-0.217
30.03,211.16,-0.218
30.05,210.96,-0.219
30.07,210.76,-0.220
30.09,210.56,-0.220
30.11,210.36,-0.220
30.13,210.16,-0.221
30.15,209.96,-0.222
30.17,209.77,-0.223
30.19,209.57,-0.224
30.21,209.37,-0.225
30.23,209.17,-0.226
30.25,208.97,-0.226
30.27,208.77,-0.227
30.29,208.57,-0.228
30.31,208.37,-0.228
30.33,208.17,-0.229
30.35,207.97,-0.230
30.37,207.78,-0.230
30.39,207.58,-0.231
30.41,207.38,-0.231
30.43,207.18,-0.231
30.45,206.98,-0.231
30.47,206.78,-0.232
30.49,206.58,-0.232
30.51,206.38,-0.233
30.53,206.18,-0.233
30.55,205.98,-0.234
30.57,205.78,-0.235
30.59,205.58,-0.235
30.61,205.39,-0.235
30.63,205.18,-0.236
30.65,204.99,-0.236
30.67,204.79,-0.236
30.69,204.59,-0.236
30.71,204.39,-0.236
30.73,204.19,-0.237
30.75,203.99,-0.238
30.77,203.79,-0.238
30.79,203.59,-0.238
30.81,203.39,-0.238
30.83,203.19,-0.239
30.85,202.99,-0.239
30.87,202.79,-0.239
30.89,202.59,-0.239
30.91,202.39,-0.240
30.93,202.19,-0.240
30.95,201.99,-0.240
30.97,201.79,-0.240
30.99,201.59,-0.240
31.01,201.39,-0.241
31.03,201.19,-0.241
31.05,200.99,-0.241
31.07,200.79,-0.241
31.09,200.59,-0.242
31.11,200.40,-0.242
31.13,200.20,-0.242
31.15,200.00,-0.242
31.17,199.80,-0.242
31.19,199.60,-0.242
31.21,199.40,-0.243
31.23,199.20,-0.243
31.25,199.00,-0.243
31.27,198.80,-0.243
31.29,198.60,-0.243
31.31,198.40,-0.243
31.33,198.20,-0.243
31.35,198.00,-0.243
31.37,197.80,-0.243
31.39,197.60,-0.243
31.41,197.40,-0.243
31.43,197.20,-0.243
31.45,197.00,-0.243
31.47,196.80,-0.243
31.49,196.60,-0.244
31.51,196.40,-0.244
31.53,196.20,-0.244
31.55,196.00,-0.244
31.57,195.80,-0.244
31.59,195.60,-0.245
31.61,195.40,-0.245
31.63,195.20,-0.245
31.65,195.00,-0.245
31.67,194.81,-0.245
31.69,194.61,-0.245
31.71,194.41,-0.245
31.73,194.21,-0.244
31.75,194.01,-0.244
31.77,193.81,-0.245
31.79,193.61,-0.245
31.81,193.41,-0.245
31.83,193.21,-0.245
31.85,193.01,-0.245
31.87,192.81,-0.245
31.89,192.61,-0.245
31.91,192.41,-0.245
31.93,192.21,-0.245
31.95,192.01,-0.245
31.97,191.81,-0.245
31.99,191.61,-0.245
32.01,191.41,-0.245
32.03,191.21,-0.245
32.05,191.01,-0.245
32.07,190.81,-0.246
32.09,190.61,-0.246
32.11,190.41,-0.246
32.13,190.21,-0.246
32.15,190.01,-0.246
32.17,189.81,-0.246
32.19,189.61,-0.246
32.21,189.41,-0.246
32.23,189.21,-0.246
32.25,189.01,-0.246
32.27,188.81,-0.246
32.29,188.61,-0.246
32.31,188.41,-0.246
32.33,188.21,-0.246
32.35,188.01,-0.246
32.37,187.81,-0.246
32.39,187.61,-0.246
32.41,187.41,-0.246
32.43,187.21,-0.247
32.45,187.02,-0.247
32.47,186.82,-0.247
32.49,186.62,-0.247
32.51,186.42,-0.247
32.53,186.22,-0.247
32.55,186.02,-0.247
32.57,185.82,-0.247
32.59,185.62,-0.247
32.61,185.42,-0.247
32.63,185.22,-0.247
32.65,185.02,-0.247
32.67,184.82,-0.247
32.69,184.62,-0.247
32.71,184.42,-0.247
32.73,184.22,-0.247
32.75,184.02,-0.247
32.77,183.82,-0.247
32.79,183.62,-0.247
32.81,183.42,-0.247
32.83,183.22,-0.248
32.85,183.02,-0.248
32.87,182.82,-0.248
32.89,182.62,-0.248
32.91,182.42,-0.248
32.93,182.22,-0.248
32.95,182.02,-0.248
32.97,181.82,-0.248
32.99,181.62,-0.248
33.01,181.42,-0.248
33.03,181.22,-0.248
33.05,181.02,-0.248
33.07,180.82,-0.248
33.09,180.62,-0.248
33.11,180.42,-0.248
33.13,180.22,-0.248
33.15,180.02,-0.248
33.17,179.82,-0.248
33.19,179.62,-0.248
33.21,179.42,-0.248
33.23,179.22,-0.248
33.25,179.02,-0.248
33.27,178.83,-0.249
33.29,178.62,-0.249
33.31,178.43,-0.248
33.33,178.23,-0.249
33.35,178.02,-0.249
33.37,177.82,-0.249
33.39,177.63,-0.249
33.41,177.43,-0.249
33.43,177.23,-0.249
33.45,177.03,-0.249
33.47,176.83,-0.249
33.49,176.63,-0.249
33.51,176.43,-0.249
33.53,176.23,-0.249
33.55,176.03,-0.249
33.57,175.83,-0.249
33.59,175.63,-0.249
33.61,175.43,-0.249
33.63,175.23,-0.249
33.65,175.03,-0.249
33.67,174.83,-0.249
33.69,174.63,-0.249
33.71,174.43,-0.249
33.73,174.23,-0.249
33.75,174.03,-0.249
33.77,173.83,-0.249
33.79,173.63,-0.249
33.81,173.43,-0.249
33.83,173.23,-0.249
33.85,173.03,-0.249
33.87,172.83,-0.249
33.89,172.64,-0.249
33.91,172.43,-0.249
33.93,172.23,-0.249
33.95,172.03,-0.249
33.97,171.83,-0.250
33.99,171.63,-0.250
34.01,171.44,-0.250
34.03,171.24,-0.250
34.05,171.04,-0.250
34.07,170.84,-0.249
34.09,170.64,-0.249
34.11,170.43,-0.250
34.13,170.24,-0.250
34.15,170.04,-0.250
34.17,169.84,-0.250
34.19,169.64,-0.250
34.21,169.44,-0.250
34.23,169.24,-0.250
34.25,169.04,-0.251
34.27,168.84,-0.251
34.29,168.64,-0.251
34.31,168.44,-0.251
34.33,168.24,-0.250
34.35,168.04,-0.250
34.37,167.84,-0.250
34.39,167.64,-0.250
34.41,167.44,-0.250
34.43,167.24,-0.250
34.45,167.04,-0.250
34.47,166.84,-0.250
34.49,166.64,-0.250
34.51,166.44,-0.250
34.53,166.24,-0.250
34.55,166.04,-0.250
34.57,165.84,-0.250
34.59,165.64,-0.250
34.61,165.44,-0.250
34.63,165.24,-0.250
34.65,165.04,-0.250
34.67,164.84,-0.250
34.69,164.64,-0.250
34.71,164.44,-0.250
34.73,164.24,-0.250
34.75,164.04,-0.250
34.77,163.85,-0.251
34.79,163.65,-0.251
34.81,163.45,-0.251
34.83,163.25,-0.251
34.85,163.05,-0.251
34.87,162.85,-0.251
34.89,162.65,-0.251
34.91,162.45,-0.251
34.93,162.25,-0.251
34.95,162.05,-0.251
34.97,161.85,-0.251
34.99,161.65,-0.251
35.01,161.45,-0.251
35.03,161.25,-0.251
35.05,161.05,-0.251
35.07,160.85,-0.251
35.09,160.65,-0.251
35.11,160.45,-0.251
35.13,160.25,-0.251
35.15,160.05,-0.251
35.17,159.85,-0.251
35.19,159.65,-0.251
35.21,159.45,-0.251
35.23,159.25,-0.251
35.25,159.05,-0.251
35.27,158.85,-0.251
35.29,158.65,-0.251
35.31,158.45,-0.251
35.33,158.25,-0.251
35.35,158.05,-0.251
35.37,157.85,-0.251
35.39,157.65,-0.251
35.41,157.45,-0.251
35.43,157.25,-0.251
35.45,157.05,-0.252
35.47,156.85,-0.251
35.49,156.65,-0.251
35.51,156.45,-0.251
35.53,156.25,-0.252
35.55,156.05,-0.252
35.57,155.85,-0.251
35.59,155.65,-0.251
35.61,155.45,-0.251
35.63,155.25,-0.251
35.65,155.06,-0.252
35.67,154.86,-0.252
35.69,154.66,-0.252
35.71,154.46,-0.252
35.73,154.26,-0.252
35.75,154.06,-0.252
35.77,153.86,-0.252
35.79,153.66,-0.252
35.81,153.46,-0.252
35.83,153.26,-0.252
35.85,153.06,-0.252
35.87,152.86,-0.252
35.89,152.66,-0.252
35.91,152.46,-0.252
35.93,152.26,-0.252
35.95,152.06,-0.252
35.97,151.86,-0.252
35.99,151.66,-0.252
36.01,151.46,-0.252
36.03,151.26,-0.252
36.05,151.06,-0.252
36.07,150.86,-0.252
36.09,150.66,-0.252
36.11,150.46,-0.252
36.13,150.26,-0.252
36.15,150.06,-0.252
36.17,149.86,-0.252
36.19,149.66,-0.252
36.21,149.46,-0.252
36.23,149.26,-0.252
36.25,149.06,-0.252
36.27,148.86,-0.252
36.29,148.66,-0.252
36.31,148.46,-0.252
36.33,148.26,-0.252
36.35,148.06,-0.252
36.37,147.86,-0.252
36.39,147.66,-0.252
36.41,147.46,-0.252
36.43,147.26,-0.252
36.45,147.06,-0.252
36.47,146.87,-0.252
36.49,146.66,-0.253
36.51,146.47,-0.253
36.53,146.27,-0.253
36.55,146.07,-0.253
36.57,145.87,-0.253
36.59,145.67,-0.253
36.61,145.47,-0.253
36.63,145.27,-0.253
36.65,145.07,-0.253
36.67,144.87,-0.253
36.69,144.67,-0.253
36.71,144.47,-0.253
36.73,144.27,-0.253
36.75,144.07,-0.252
36.77,143.87,-0.252
36.79,143.67,-0.252
36.81,143.47,-0.252
36.83,143.27,-0.253
36.85,143.07,-0.253
36.87,142.87,-0.253
36.89,142.67,-0.253
36.91,142.47,-0.253
36.93,142.27,-0.253
36.95,142.07,-0.253
36.97,141.87,-0.253
36.99,141.67,-0.253
37.01,141.47,-0.253
37.03,141.27,-0.253
37.05,141.07,-0.253
37.07,140.87,-0.253
37.09,140.67,-0.253
37.11,140.47,-0.253
37.13,140.27,-0.253
[...]
123.57,14.25,0.178
123.59,14.45,0.178
123.61,14.65,0.178
123.63,14.85,0.179
123.65,15.05,0.179
123.67,15.25,0.179
123.69,15.45,0.179
123.71,15.65,0.179
123.73,15.85,0.179
123.75,16.05,0.179
123.77,16.25,0.179
123.79,16.45,0.180
123.81,16.65,0.180
123.83,16.85,0.180
123.85,17.05,0.180
123.87,17.25,0.180
123.89,17.45,0.180
123.91,17.65,0.180
123.93,17.85,0.180
123.95,18.05,0.180
123.97,18.25,0.180
123.99,18.45,0.180
124.01,18.65,0.181
124.03,18.86,0.181
124.05,19.05,0.181
124.07,19.26,0.181
124.09,19.46,0.181
124.11,19.65,0.181
124.13,19.86,0.181
124.15,20.06,0.181
124.17,20.26,0.181
124.19,20.46,0.181
124.21,20.66,0.181
124.23,20.86,0.182
124.25,21.06,0.182
124.27,21.26,0.182
124.29,21.46,0.182
124.31,21.66,0.182
124.33,21.86,0.182
124.35,22.06,0.182
124.37,22.26,0.183
124.39,22.46,0.183
124.41,22.66,0.183
124.43,22.86,0.183
124.45,23.06,0.183
124.47,23.26,0.183
124.49,23.46,0.184
124.51,23.66,0.184
124.53,23.86,0.184
124.55,24.06,0.184
124.57,24.26,0.184
124.59,24.46,0.184
124.61,24.66,0.184
124.63,24.86,0.184
124.65,25.06,0.185
124.67,25.26,0.185
124.69,25.46,0.185
124.71,25.66,0.185
124.73,25.86,0.185
124.75,26.06,0.185
124.77,26.26,0.185
124.79,26.46,0.185
124.81,26.66,0.185
124.83,26.86,0.186
124.85,27.06,0.186
124.87,27.26,0.186
124.89,27.46,0.186
124.91,27.66,0.186
124.93,27.86,0.187
124.95,28.06,0.187
124.97,28.26,0.187
124.99,28.46,0.187
125.01,28.66,0.187
125.03,28.86,0.187
125.05,29.06,0.187
125.07,29.27,0.188
125.09,29.47,0.188
125.11,29.67,0.188
125.13,29.87,0.188
125.15,30.06,0.188
125.17,30.26,0.189
125.19,30.46,0.189
125.21,30.67,0.189
125.23,30.87,0.189
125.25,31.07,0.189
125.27,31.27,0.189
125.29,31.47,0.189
125.31,31.67,0.189
125.33,31.87,0.190
125.35,32.07,0.190
125.37,32.27,0.190
125.39,32.47,0.190
125.41,32.67,0.190
125.43,32.87,0.190
125.45,33.07,0.190
125.47,33.27,0.190
125.49,33.47,0.191
125.51,33.67,0.191
125.53,33.87,0.191
125.55,34.07,0.191
125.57,34.27,0.191
125.59,34.47,0.191
125.61,34.67,0.191
125.63,34.87,0.191
125.65,35.07,0.191
125.67,35.27,0.192
125.69,35.47,0.192
125.71,35.67,0.192
125.73,35.87,0.192
125.75,36.07,0.192
125.77,36.27,0.192
125.79,36.47,0.192
125.81,36.67,0.192
125.83,36.87,0.192
125.85,37.07,0.193
125.87,37.27,0.193
125.89,37.47,0.193
125.91,37.67,0.193
125.93,37.87,0.193
125.95,38.07,0.193
125.97,38.27,0.193
125.99,38.47,0.193
126.01,38.67,0.194
126.03,38.87,0.194
126.05,39.08,0.194
126.07,39.27,0.194
126.09,39.47,0.194
126.11,39.68,0.194
126.13,39.88,0.194
126.15,40.08,0.194
126.17,40.28,0.194
126.19,40.48,0.195
126.21,40.68,0.195
126.23,40.88,0.195
126.25,41.08,0.195
126.27,41.28,0.195
126.29,41.48,0.195
126.31,41.68,0.195
126.33,41.88,0.196
126.35,42.08,0.196
126.37,42.28,0.196
126.39,42.48,0.196
126.41,42.68,0.196
126.43,42.88,0.196
126.45,43.08,0.196
126.47,43.28,0.196
126.49,43.48,0.197
126.51,43.68,0.197
126.53,43.88,0.197
126.55,44.08,0.197
126.57,44.28,0.197
126.59,44.48,0.197
126.61,44.68,0.197
126.63,44.88,0.197
126.65,45.08,0.198
126.67,45.28,0.198
126.69,45.48,0.198
126.71,45.68,0.198
126.73,45.88,0.198
126.75,46.08,0.198
126.77,46.28,0.198
126.79,46.48,0.198
126.81,46.68,0.199
126.83,46.88,0.199
126.85,47.08,0.199
126.87,47.28,0.199
126.89,47.48,0.199
126.91,47.68,0.199
126.93,47.88,0.200
126.95,48.08,0.200
126.97,48.28,0.200
126.99,48.48,0.200
127.01,48.68,0.200
127.03,48.88,0.200
127.05,49.08,0.200
127.07,49.28,0.201
127.09,49.48,0.201
127.11,49.68,0.201
127.13,49.88,0.201
127.15,50.08,0.201
127.17,50.28,0.201
127.19,50.49,0.201
127.21,50.68,0.201
127.23,50.88,0.202
127.25,51.08,0.202
127.27,51.28,0.202
127.29,51.49,0.202
127.31,51.69,0.202
127.33,51.89,0.202
127.35,52.09,0.203
127.37,52.29,0.203
127.39,52.49,0.203
127.41,52.69,0.203
127.43,52.89,0.203
127.45,53.09,0.203
127.47,53.29,0.204
127.49,53.49,0.204
127.51,53.69,0.204
127.53,53.89,0.204
127.55,54.09,0.204
127.57,54.29,0.204
127.59,54.49,0.205
127.61,54.69,0.205
127.63,54.89,0.205
127.65,55.09,0.205
127.67,55.29,0.205
127.69,55.49,0.205
127.71,55.69,0.206
127.73,55.89,0.206
127.75,56.09,0.206
127.77,56.29,0.206
127.79,56.49,0.206
127.81,56.69,0.206
127.83,56.89,0.206
127.85,57.09,0.206
127.87,57.29,0.206
127.89,57.49,0.207
127.91,57.69,0.207
127.93,57.89,0.207
127.95,58.09,0.207
127.97,58.29,0.207
127.99,58.49,0.207
128.01,58.69,0.207
128.03,58.89,0.207
128.05,59.09,0.208
128.07,59.29,0.208
128.09,59.49,0.208
128.11,59.69,0.208
128.13,59.89,0.208
128.15,60.09,0.208
128.17,60.29,0.208
128.19,60.49,0.209
128.21,60.69,0.209
128.23,60.89,0.209
128.25,61.09,0.209
128.27,61.29,0.209
128.29,61.49,0.209
128.31,61.70,0.210
128.33,61.89,0.210
128.35,62.10,0.210
128.37,62.30,0.210
128.39,62.50,0.210
128.41,62.70,0.210
128.43,62.90,0.210
128.45,63.10,0.211
128.47,63.30,0.211
128.49,63.50,0.211
128.51,63.70,0.211
128.53,63.90,0.211
128.55,64.10,0.212
128.57,64.30,0.212
128.59,64.50,0.212
128.61,64.70,0.212
128.63,64.90,0.212
128.65,65.10,0.212
128.67,65.30,0.213
128.69,65.50,0.213
128.71,65.70,0.213
128.73,65.90,0.213
128.75,66.10,0.213
128.77,66.30,0.213
128.79,66.50,0.214
128.81,66.70,0.214
128.83,66.90,0.214
128.85,67.10,0.214
128.87,67.30,0.214
128.89,67.50,0.214
128.91,67.70,0.214
128.93,67.90,0.215
128.95,68.10,0.215
128.97,68.30,0.215
128.99,68.50,0.215
129.01,68.70,0.215
129.03,68.90,0.215
129.05,69.10,0.215
129.07,69.30,0.216
129.09,69.50,0.216
129.11,69.70,0.216
129.13,69.90,0.216
129.15,70.10,0.216
129.17,70.30,0.217
129.19,70.50,0.217
129.21,70.70,0.217
129.23,70.90,0.217
129.25,71.10,0.217
129.27,71.30,0.217
129.29,71.50,0.218
129.31,71.70,0.218
129.33,71.90,0.218
129.35,72.10,0.218
129.37,72.30,0.218
129.39,72.51,0.218
129.41,72.71,0.219
129.43,72.91,0.219
129.45,73.10,0.219
129.47,73.31,0.219
129.49,73.51,0.219
129.51,73.71,0.219
129.53,73.91,0.220
129.55,74.10,0.220
129.57,74.31,0.220
129.59,74.51,0.220
129.61,74.71,0.220
129.63,74.91,0.220
129.65,75.11,0.221
129.67,75.31,0.221
129.69,75.51,0.221
129.71,75.71,0.221
129.73,75.91,0.221
129.75,76.11,0.221
129.77,76.31,0.222
129.79,76.51,0.222
129.81,76.71,0.222
129.83,76.91,0.222
129.85,77.11,0.222
129.87,77.31,0.222
129.89,77.51,0.222
129.91,77.71,0.223
129.93,77.91,0.223
129.95,78.11,0.223
129.97,78.31,0.223
129.99,78.51,0.223
130.01,78.71,0.223
130.03,78.91,0.224
130.05,79.11,0.224
130.07,79.31,0.224
130.09,79.51,0.224
130.11,79.71,0.224
130.13,79.91,0.224
130.15,80.11,0.224
130.17,80.31,0.224
130.19,80.51,0.225
130.21,80.71,0.225
130.23,80.91,0.225
130.25,81.11,0.225
130.27,81.31,0.225
130.29,81.51,0.225
130.31,81.71,0.225
130.33,81.91,0.225
130.35,82.11,0.225
130.37,82.31,0.226
130.39,82.51,0.226
130.41,82.71,0.226
130.43,82.91,0.226
130.45,83.11,0.226
130.47,83.31,0.226
130.49,83.51,0.226
130.51,83.72,0.226
130.53,83.91,0.227
130.55,84.12,0.227
130.57,84.32,0.227
130.59,84.52,0.227
130.61,84.72,0.227
130.63,84.92,0.227
130.65,85.12,0.227
130.67,85.32,0.227
130.69,85.52,0.227
130.71,85.72,0.227
130.73,85.92,0.227
130.75,86.12,0.227
130.77,86.32,0.227
130.79,86.52,0.227
130.81,86.72,0.227
130.83,86.92,0.228
130.85,87.12,0.228
130.87,87.32,0.228
130.89,87.52,0.228
130.91,87.72,0.228
130.93,87.92,0.228
130.95,88.12,0.229
130.97,88.32,0.229
130.99,88.52,0.229
131.01,88.72,0.229
131.03,88.92,0.229
131.05,89.12,0.229
131.07,89.32,0.229
131.09,89.52,0.229
131.11,89.72,0.230
131.13,89.92,0.230
131.15,90.12,0.230
131.17,90.32,0.230
131.19,90.52,0.230
131.21,90.72,0.230
131.23,90.92,0.230
131.25,91.12,0.230
131.27,91.32,0.231
131.29,91.52,0.231
131.31,91.72,0.231
131.33,91.92,0.231
131.35,92.12,0.231
131.37,92.32,0.231
131.39,92.52,0.231
131.41,92.72,0.232
131.43,92.92,0.232
131.45,93.12,0.232
131.47,93.32,0.232
131.49,93.52,0.232
131.51,93.72,0.232
131.53,93.92,0.232
131.55,94.12,0.232
131.57,94.32,0.233
131.59,94.52,0.233
131.61,94.72,0.233
131.63,94.92,0.233
131.65,95.12,0.233
131.67,95.32,0.233
131.69,95.52,0.233
131.71,95.73,0.233
131.73,95.92,0.234
131.75,96.12,0.234
131.77,96.33,0.234
131.79,96.53,0.234
131.81,96.73,0.234
131.83,96.93,0.234
131.85,97.13,0.234
131.87,97.32,0.235
131.89,97.53,0.235
131.91,97.73,0.235
131.93,97.93,0.235
131.95,98.13,0.235
131.97,98.33,0.235
131.99,98.53,0.235
132.01,98.73,0.235
132.03,98.93,0.235
132.05,99.13,0.235
132.07,99.33,0.235
132.09,99.53,0.236
132.11,99.73,0.236
132.13,99.93,0.236
132.15,100.13,0.236
132.17,100.33,0.237
132.19,100.53,0.237
132.21,100.73,0.237
132.23,100.93,0.237
132.25,101.13,0.238
132.27,101.33,0.238
132.29,101.53,0.238
132.31,101.73,0.238
132.33,101.93,0.238
132.35,102.13,0.238
132.37,102.33,0.238
132.39,102.53,0.238
132.41,102.73,0.238
132.43,102.93,0.238
132.45,103.13,0.238
132.47,103.33,0.238
132.49,103.53,0.238
132.51,103.73,0.239
132.53,103.93,0.239
132.55,104.13,0.239
132.57,104.33,0.239
132.59,104.53,0.239
132.61,104.73,0.239
132.63,104.93,0.239
132.65,105.13,0.239
132.67,105.33,0.240
132.69,105.53,0.240
132.71,105.73,0.240
132.73,105.93,0.240
132.75,106.13,0.241
132.77,106.33,0.241
132.79,106.53,0.241
132.81,106.73,0.241
132.83,106.93,0.241
132.85,107.13,0.241
132.87,107.33,0.241
132.89,107.53,0.241
132.91,107.73,0.242
132.93,107.93,0.242
132.95,108.13,0.242
132.97,108.33,0.242
132.99,108.53,0.242
133.01,108.73,0.242
133.03,108.93,0.243
133.05,109.13,0.243
133.07,109.33,0.243
133.09,109.53,0.243
133.11,109.73,0.243
133.13,109.93,0.243
133.15,110.13,0.243
133.17,110.33,0.243
133.19,110.53,0.243
133.21,110.73,0.244
133.23,110.94,0.244
133.25,111.13,0.244
133.27,111.34,0.244
133.29,111.54,0.244
133.31,111.74,0.244
133.33,111.94,0.244
133.35,112.14,0.245
133.37,112.34,0.245
133.39,112.54,0.245
133.41,112.74,0.245
133.43,112.94,0.245
133.45,113.14,0.245
133.47,113.34,0.245
133.49,113.54,0.246
133.51,113.74,0.246
133.53,113.94,0.246
133.55,114.14,0.246
133.57,114.34,0.246
133.59,114.54,0.246
133.61,114.74,0.246
133.63,114.94,0.246
133.65,115.14,0.247
133.67,115.34,0.247
133.69,115.54,0.247
133.71,115.74,0.247
133.73,115.94,0.247
133.75,116.14,0.248
133.77,116.34,0.248
133.79,116.54,0.248
133.81,116.74,0.248
133.83,116.94,0.248
133.85,117.14,0.247
133.87,117.34,0.247
133.89,117.54,0.248
133.91,117.74,0.248
133.93,117.94,0.249
133.95,118.14,0.249
133.97,118.34,0.249
133.99,118.54,0.249
134.01,118.74,0.249
134.03,118.94,0.249
134.05,119.14,0.249
134.07,119.34,0.249
134.09,119.54,0.250
134.11,119.74,0.250
134.13,119.94,0.250
134.15,120.14,0.250
134.17,120.34,0.250
134.19,120.54,0.250
134.21,120.74,0.250
134.23,120.94,0.250
134.25,121.14,0.250
134.27,121.34,0.250
134.29,121.54,0.250
134.31,121.74,0.250
134.33,121.94,0.251
134.35,122.14,0.252
134.37,122.34,0.252
134.39,122.54,0.252
134.41,122.74,0.252
134.43,122.94,0.253
134.45,123.14,0.253
134.47,123.34,0.253
134.49,123.54,0.253
134.51,123.74,0.253
134.53,123.94,0.253
134.55,124.14,0.252
134.57,124.34,0.252
134.59,124.55,0.253
134.61,124.75,0.253
134.63,124.95,0.254
134.65,125.14,0.254
134.67,125.34,0.255
134.69,125.54,0.255
134.71,125.74,0.254
134.73,125.94,0.254
134.75,126.14,0.254
134.77,126.35,0.254
134.79,126.55,0.255
134.81,126.75,0.255
134.83,126.95,0.255
134.85,127.14,0.255
134.87,127.35,0.255
134.89,127.54,0.255
134.91,127.74,0.256
134.93,127.94,0.256
134.95,128.14,0.255
134.97,128.35,0.255
134.99,128.55,0.255
135.01,128.75,0.255
135.03,128.95,0.255
135.05,129.15,0.255
135.07,129.35,0.255
135.09,129.55,0.256
135.11,129.75,0.256
135.13,129.95,0.257
135.15,130.15,0.257
135.17,130.35,0.258
135.19,130.55,0.258
135.21,130.75,0.258
135.23,130.95,0.257
135.25,131.15,0.258
135.27,131.35,0.258
135.29,131.55,0.258
135.31,131.75,0.258
135.33,131.95,0.258
135.35,132.15,0.258
135.37,132.35,0.258
135.39,132.55,0.258
135.41,132.75,0.258
135.43,132.95,0.258
135.45,133.15,0.258
135.47,133.35,0.259
135.49,133.55,0.259
135.51,133.75,0.259
135.53,133.95,0.259
135.55,134.15,0.259
135.57,134.35,0.259
135.59,134.55,0.259
135.61,134.75,0.260
135.63,134.95,0.260
135.65,135.15,0.261
135.67,135.35,0.261
135.69,135.55,0.261
135.71,135.75,0.261
135.73,135.95,0.261
135.75,136.15,0.261
135.77,136.35,0.261
135.79,136.55,0.261
135.81,136.75,0.261
135.83,136.95,0.261
135.85,137.15,0.261
135.87,137.35,0.261
135.89,137.55,0.261
135.91,137.75,0.261
135.93,137.95,0.262
135.95,138.15,0.262
135.97,138.35,0.262
135.99,138.55,0.262
136.01,138.75,0.262
136.03,138.95,0.262
136.05,139.15,0.262
136.07,139.35,0.262
136.09,139.55,0.263
136.11,139.75,0.263
136.13,139.95,0.263
136.15,140.15,0.263
136.17,140.35,0.263
136.19,140.55,0.263
136.21,140.75,0.263
136.23,140.95,0.263
136.25,141.15,0.264
136.27,141.35,0.264
136.29,141.55,0.264
136.31,141.75,0.264
136.33,141.96,0.264
136.35,142.15,0.264
136.37,142.35,0.265
136.39,142.55,0.265
136.41,142.75,0.265
136.43,142.95,0.265
136.45,143.15,0.265
136.47,143.35,0.265
136.49,143.55,0.265
136.51,143.75,0.265
136.53,143.95,0.265
136.55,144.15,0.265
136.57,144.35,0.266
136.59,144.55,0.266
136.61,144.76,0.266
136.63,144.95,0.266
136.65,145.15,0.266
136.67,145.36,0.266
136.69,145.55,0.266
136.71,145.76,0.267
136.73,145.96,0.267
136.75,146.16,0.267
136.77,146.36,0.267
136.79,146.56,0.267
136.81,146.76,0.267
136.83,146.96,0.267
136.85,147.16,0.268
136.87,147.36,0.268
136.89,147.56,0.268
136.91,147.76,0.268
136.93,147.96,0.268
136.95,148.16,0.268
136.97,148.36,0.268
136.99,148.56,0.269
137.01,148.76,0.269
137.03,148.96,0.269
137.05,149.16,0.269
137.07,149.36,0.269
137.09,149.56,0.269
137.11,149.76,0.269
137.13,149.96,0.269
137.15,150.16,0.269
137.17,150.36,0.270
137.19,150.56,0.270
137.21,150.76,0.270
137.23,150.96,0.270
137.25,151.16,0.270
137.27,151.36,0.270
137.29,151.56,0.271
137.31,151.76,0.271
137.33,151.96,0.271
137.35,152.16,0.271
137.37,152.36,0.271
137.39,152.56,0.271
137.41,152.76,0.272
137.43,152.96,0.272
137.45,153.16,0.272
137.47,153.36,0.272
137.49,153.56,0.272
137.51,153.76,0.272
137.53,153.96,0.272
137.55,154.16,0.272
137.57,154.36,0.272
137.59,154.56,0.272
137.61,154.76,0.273
137.63,154.96,0.273
137.65,155.16,0.273
137.67,155.36,0.273
137.69,155.56,0.274
137.71,155.76,0.274
137.73,155.96,0.274
137.75,156.16,0.274
137.77,156.36,0.274
137.79,156.56,0.274
137.81,156.76,0.274
137.83,156.96,0.274
137.85,157.16,0.275
137.87,157.36,0.275
137.89,157.56,0.275
137.91,157.76,0.275
137.93,157.96,0.275
137.95,158.16,0.275
137.97,158.36,0.275
137.99,158.56,0.275
138.01,158.76,0.275
138.03,158.96,0.275
138.05,159.16,0.276
138.07,159.36,0.276
138.09,159.56,0.276
138.11,159.76,0.276
138.13,159.96,0.276
138.15,160.16,0.276
138.17,160.37,0.276
138.19,160.56,0.276
138.21,160.76,0.276
138.23,160.96,0.277
138.25,161.16,0.277
138.27,161.36,0.277
138.29,161.56,0.277
138.31,161.76,0.277
138.33,161.96,0.277
138.35,162.16,0.277
138.37,162.36,0.277
138.39,162.56,0.277
138.41,162.76,0.277
138.43,162.96,0.277
138.45,163.16,0.278
138.47,163.37,0.278
138.49,163.56,0.278
138.51,163.76,0.278
138.53,163.96,0.279
138.55,164.16,0.279
138.57,164.36,0.278
138.59,164.57,0.278
138.61,164.77,0.278
138.63,164.97,0.279
138.65,165.17,0.279
138.67,165.37,0.279
138.69,165.57,0.279
138.71,165.77,0.280
138.73,165.97,0.280
138.75,166.17,0.280
138.77,166.37,0.280
138.79,166.57,0.280
138.81,166.77,0.281
138.83,166.97,0.281
138.85,167.17,0.281
138.87,167.37,0.281
138.89,167.57,0.281
138.91,167.77,0.281
138.93,167.97,0.281
138.95,168.17,0.281
138.97,168.37,0.281
138.99,168.57,0.281
139.01,168.77,0.281
139.03,168.97,0.281
139.05,169.17,0.281
139.07,169.37,0.281
139.09,169.57,0.282
139.11,169.77,0.282
139.13,169.97,0.282
139.15,170.17,0.282
139.17,170.37,0.282
139.19,170.57,0.283
139.21,170.77,0.283
139.23,170.97,0.283
139.25,171.17,0.283
139.27,171.37,0.283
139.29,171.57,0.283
139.31,171.77,0.283
139.33,171.97,0.284
139.35,172.17,0.284
139.37,172.37,0.283
139.39,172.57,0.283
139.41,172.77,0.283
139.43,172.97,0.284
139.45,173.17,0.284
139.47,173.37,0.284
139.49,173.57,0.284
139.51,173.77,0.284
139.53,173.97,0.284
139.55,174.17,0.284
139.57,174.37,0.284
139.59,174.57,0.285
139.61,174.77,0.285
139.63,174.97,0.285
139.65,175.17,0.285
139.67,175.37,0.285
139.69,175.57,0.286
139.71,175.77,0.286
139.73,175.97,0.286
139.75,176.17,0.286
139.77,176.37,0.286
139.79,176.57,0.286
139.81,176.77,0.286
139.83,176.97,0.286
139.85,177.17,0.286
139.87,177.37,0.286
139.89,177.57,0.287
139.91,177.77,0.287
139.93,177.97,0.287
139.95,178.17,0.287
139.97,178.37,0.287
139.99,178.57,0.287
140.01,178.77,0.287
140.03,178.97,0.288
140.05,179.17,0.288
140.07,179.37,0.288
140.09,179.57,0.288
140.11,179.77,0.288
140.13,179.97,0.288
140.15,180.17,0.288
140.17,180.37,0.288
140.19,180.57,0.288
140.21,180.77,0.288
140.23,180.97,0.288
140.25,181.17,0.289
140.27,181.37,0.289
140.29,181.57,0.289
140.31,181.77,0.289
140.33,181.97,0.289
140.35,182.17,0.290
140.37,182.37,0.290
140.39,182.57,0.290
140.41,182.77,0.290
140.43,182.97,0.290
140.45,183.17,0.290
140.47,183.37,0.290
140.49,183.58,0.290
140.51,183.78,0.290
140.53,183.98,0.290
140.55,184.18,0.290
140.57,184.38,0.291
140.59,184.58,0.291
140.61,184.78,0.292
140.63,184.98,0.292
140.65,185.18,0.292
140.67,185.38,0.292
140.69,185.58,0.292
140.71,185.78,0.292
140.73,185.98,0.292
140.75,186.18,0.292
140.77,186.38,0.292
140.79,186.58,0.293
140.81,186.78,0.293
140.83,186.98,0.293
140.85,187.18,0.293
140.87,187.38,0.293
140.89,187.58,0.293
140.91,187.78,0.293
140.93,187.98,0.293
140.95,188.18,0.293
140.97,188.38,0.293
140.99,188.58,0.293
141.01,188.78,0.293
141.03,188.98,0.293
141.05,189.18,0.294
141.07,189.38,0.294
141.09,189.58,0.294
141.11,189.78,0.294
141.13,189.98,0.294
141.15,190.18,0.294
141.17,190.38,0.294
141.19,190.58,0.294
141.21,190.78,0.294
141.23,190.98,0.294
141.25,191.18,0.294
141.27,191.38,0.295
141.29,191.58,0.295
141.31,191.78,0.295
141.33,191.98,0.295
141.35,192.18,0.295
141.37,192.38,0.295
141.39,192.58,0.295
141.41,192.78,0.295
141.43,192.98,0.295
141.45,193.18,0.295
141.47,193.38,0.296
141.49,193.58,0.296
141.51,193.78,0.296
141.53,193.98,0.296
141.55,194.18,0.297
141.57,194.38,0.297
141.59,194.58,0.297
141.61,194.78,0.297
141.63,194.98,0.297
141.65,195.18,0.297
141.67,195.38,0.297
141.69,195.58,0.297
141.71,195.78,0.297
141.73,195.98,0.298
141.75,196.18,0.298
141.77,196.38,0.298
141.79,196.58,0.298
141.81,196.78,0.298
141.83,196.98,0.298
141.85,197.18,0.298
141.87,197.38,0.298
141.89,197.58,0.298
141.91,197.78,0.298
141.93,197.98,0.298
141.95,198.18,0.298
141.97,198.38,0.298
141.99,198.58,0.299
142.01,198.78,0.299
142.03,198.98,0.299
142.05,199.18,0.299
142.07,199.38,0.299
142.09,199.58,0.300
142.11,199.78,0.300
142.13,199.98,0.300
142.15,200.18,0.300
142.17,200.38,0.300
142.19,200.58,0.300
142.21,200.78,0.300
142.23,200.98,0.300
142.25,201.18,0.300
142.27,201.38,0.300
142.29,201.58,0.300
142.31,201.78,0.300
142.33,201.98,0.300
142.35,202.18,0.300
142.37,202.38,0.300
142.39,202.58,0.300
142.41,202.78,0.301
142.43,202.98,0.301
142.45,203.18,0.301
142.47,203.38,0.301
142.49,203.58,0.302
142.51,203.78,0.302
142.53,203.98,0.302
142.55,204.18,0.302
142.57,204.38,0.302
142.59,204.58,0.301
142.61,204.78,0.301
142.63,204.98,0.302
142.65,205.18,0.302
142.67,205.38,0.301
142.69,205.58,0.301
142.71,205.78,0.301
142.73,205.98,0.301
142.75,206.18,0.301
142.77,206.38,0.301
142.79,206.58,0.302
142.81,206.78,0.302
142.83,206.98,0.302
142.85,207.18,0.302
142.87,207.38,0.302
142.89,207.58,0.303
142.91,207.78,0.303
142.93,207.98,0.303
142.95,208.19,0.303
142.97,208.38,0.303
142.99,208.58,0.303
143.01,208.78,0.303
143.03,208.98,0.303
143.05,209.19,0.303
143.07,209.39,0.303
143.09,209.59,0.303
143.11,209.79,0.303
143.13,209.99,0.304
143.15,210.19,0.304
143.17,210.39,0.304
143.19,210.59,0.304
143.21,210.78,0.304
143.23,210.99,0.304
143.25,211.18,0.304
143.27,211.38,0.304
143.29,211.59,0.304
143.31,211.79,0.304
143.33,211.99,0.304
143.35,212.19,0.304
143.37,212.39,0.305
143.39,212.59,0.305
143.41,212.79,0.305
143.43,212.99,0.305
143.45,213.19,0.305
143.47,213.39,0.305
143.49,213.59,0.305
143.51,213.79,0.305
143.53,213.99,0.305
143.55,214.19,0.305
143.57,214.39,0.305
143.59,214.59,0.305
143.61,214.79,0.306
143.63,214.99,0.306
143.65,215.19,0.306
143.67,215.39,0.306
143.69,215.59,0.306
143.71,215.79,0.306
143.73,215.99,0.306
143.75,216.19,0.306
143.77,216.39,0.306
143.79,216.59,0.306
143.81,216.79,0.306
143.83,216.99,0.307
143.85,217.19,0.307
143.87,217.39,0.307
143.89,217.59,0.307
143.91,217.79,0.307
143.93,217.99,
143.95,218.19,
143.97,218.39,
143.99,,