File: DSC/2025_04_25_CBN_Caffeine_MC_n60C_250C_10Cmin_x3.csv
Filename,2025_04_25_CBN_Caffeine_MC_n60C_250C_10Cmin_x3
Instrument name,DSC2A-00468 (192.168.1.100)
Operator,Yarger
rundate,4/25/2025
Sample name,2025_04_25_CBN_Caffeine_MC_n60C_250C_10Cmin_x3
proceduresegments,Data Off ; Equilibrate -60.00 °C; Data On ; Ramp 10.00 °C/min to 250.00 °C; Data Off ; Isothermal 0.1 min; Data On ; Ramp 10.00 °C/min to -60.00 °C; Data Off ; Isothermal 1.0 min; Data On ; Ramp 10.00 °C/min to 250.00 °C; Data Off ; Isothermal 0.1 min; Data On ; Ramp 10.00 °C/min to -60.00 °C; Data Off ; Isothermal 1.0 min; Data On ; Ramp 10.00 °C/min to 250.00 °C
[File Parameters]
Run date,4/25/2025 2:41:32 PM
Trios version,5.1.1.46572
Original File Name,
Current File Name,D:\DSC2500\JYarger\2025_04_25_CBN_Caffeine_MC_n60C_250C_10Cmin_x3.tri
[Procedure]
Procedure Name,CBN_Caff_n60_250C_10Cmin_x3
Sample Name,2025_04_25_CBN_Caffeine_MC_n60C_250C_10Cmin_x3
Sample Mass,5.52 mg
Reference Sample Mass,0 mg
Pan Mass,53.25 mg
Pan Number,31
Reference Pan Mass,52.66 mg
Reference Pan Number,19
Pan Type,Tzero Aluminum Hermetic
Comments,Al Hermetic DSC Consumables sealed Pan/Lid.
Project Name,CA
Operator,Yarger
Test,Custom
Unload Max Temperature,30
Unload Min Temperature,30
Load Max Temperature,30
Load Min Temperature,30
Stop on Gas Flow Error,Yes
[Signal List]
Signal #1,Time (min)
Signal #2,Temperature (°C)
Signal #3,Heat Flow (mW)
Signal #4,Delta T (µV)
Signal #5,Delta Tzero (µV)
Signal #6,Tzero Temperature (°C)
Signal #7,Cell Purge (mL/min)
Signal #8,Heater Temp (°C)
Signal #9,Power Delivered (W)
Signal #10,Reference Junction Temperature (°C)
Signal #11,Flange Temperature (°C)
Signal #12,Heat Flow Phase (rad)
Signal #13,Total Heat Capacity (J/°C)
Signal #14,Heat Capacity (J/°C)
[Configuration]
Company Name,ASU
Instrument Name,DSC2A-00468
Instrument Type,DSC2500
Serial Number,DSC2A-00468
IP,192.168.1.100
Location of Instrument,MRRC
DisplayType,Unknown
Sample Interval ,0.1 s/pt
Selected Heat Flow,T4P
Exotherm Direction,Down
Cell Serial,DRC2-00792
Lid Type,Standard
Cooler,RCS 90
Leave Cooler on at End of Sequence,On
Gas 2,Nitrogen
Gas Selected,Channel 1
Flow Rate,50 mL/min
Secondary Purge,On
Licensed Heat Flow,Heat Flow T4P
Modulation Licensed,Yes
[Versions]
Common IDD Version,1
Cortex Version,VER 2.10.2.31
Driver,5.0.0.6
GDM Version,1.0.3.3
TouchscreenVersion,1.0.0.16145
FEP Version,1.2.1.21
FEP Bootloader,2.0.0.5
AutoSampler Version,2.1.1.26
Auto Sampler Bootloader,2.0.0.5
FCM Version,1.1.0.3
FCM Bootloader,2.0.0.5
[Experiment Logs]
Experiment Log Entry # 1,Data On set to 0
Experiment Log Entry # 3,Equilibrate Segment -60 (C) Started
Experiment Log Entry # 5,Air Cool is off.
Experiment Log Entry # 7,Data On set to 1
Experiment Log Entry # 9,Ramp Segment 10 C/min to 250 Started
Experiment Log Entry # 11,Data On set to 0
Experiment Log Entry # 13,Isothermal Segment 0.1 min started
Experiment Log Entry # 15,Data On set to 1
Experiment Log Entry # 17,Ramp Segment 10 C/min to -60 Started
Experiment Log Entry # 19,Data On set to 0
Experiment Log Entry # 21,Isothermal Segment 1 min started
Experiment Log Entry # 23,Data On set to 1
Experiment Log Entry # 25,Ramp Segment 10 C/min to 250 Started
Experiment Log Entry # 27,Data On set to 0
Experiment Log Entry # 29,Isothermal Segment 0.1 min started
Experiment Log Entry # 31,Data On set to 1
Experiment Log Entry # 33,Ramp Segment 10 C/min to -60 Started
Experiment Log Entry # 35,Data On set to 0
Experiment Log Entry # 37,Isothermal Segment 1 min started
Experiment Log Entry # 39,Data On set to 1
Experiment Log Entry # 41,Ramp Segment 10 C/min to 250 Started
[Method Log]
Method Log Entry # 1,Data Off
Method Log Entry # 2,Equilibrate -60 °C
Method Log Entry # 3,Data On
Method Log Entry # 4,(Ramp 364353) Ramp 10 °C/minute to 250 °C
Method Log Entry # 5,Data Off
Method Log Entry # 6,Isothermal 0.1 minutes
Method Log Entry # 7,Data On
Method Log Entry # 8,(Ramp 364357) Ramp 10 °C/minute to -60 °C
Method Log Entry # 9,Data Off
Method Log Entry # 10,Isothermal 1 minutes
Method Log Entry # 11,Data On
Method Log Entry # 12,(Ramp 364361) Ramp 10 °C/minute to 250 °C
Method Log Entry # 13,Data Off
Method Log Entry # 14,Isothermal 0.1 minutes
Method Log Entry # 15,Data On
Method Log Entry # 16,(Ramp 364365) Ramp 10 °C/minute to -60 °C
Method Log Entry # 17,Data Off
Method Log Entry # 18,Isothermal 1 minutes
Method Log Entry # 19,Data On
Method Log Entry # 20,(Ramp 364369) Ramp 10 °C/minute to 250 °C
Cell Serial,DRC2-00792
[T1 Calibration]
Slope,-0.008529666
Offset,9.636258
Initial Temperature,98.23
GUID,f8bfdadc-4977-4fdf-ba6d-0ba9134940c3
[TZero Calibration]
Date Applied,11/29/2022 4:06:13 PM
Description,From -89.059 °C to 396.009 °C at 20.000°C/min
Gas Type,Nitrogen
Pan Type,None
Source Files 1,C:\Users\yargerlab\Desktop\DSC Data\General\TZero_calibration_11_29_22_2nd(2).tri
Source Files 2,C:\Users\yargerlab\Desktop\DSC Data\General\TZero_calibration_11_29_22_2nd(3).tri
Delta T Offset,13.05235
Delta T Slope,-0.007271007
Delta T0 Offset,-13.69128
Delta T0 Slope,0.06063341
[Temperature Calibration]
Date Applied,11/29/2022 7:12:28 PM
Description,From 106.590 °C to 186.590 °C at 10.000°C/min
Gas Type,Nitrogen
Pan Type,Tzero Aluminum Hermetic
Source Files 1,C:\Users\yargerlab\Desktop\DSC Data\General\Indium(6).tri
Measured 1,157.391
Known 1,156.598
[Cell Constant Calibration]
Date Applied,11/29/2022 7:12:29 PM
Description,From 106.590 °C to 186.590 °C at 10.000°C/min
Gas Type,Nitrogen
Pan Type,Tzero Aluminum Hermetic
Source Files 1,C:\Users\yargerlab\Desktop\DSC Data\General\Indium(6).tri
T4P KCell,1.006051
Onset Slope,63.26126 mW/°C
[Direct Cp Calibration]
Date Applied,11/30/2022 11:04:51 AM
Description,From -79.983 °C to 298.409 °C at 10.000°C/min
Gas Type,Nitrogen
Pan Type,Tzero Aluminum Hermetic
Source Files 1,C:\Users\yargerlab\Desktop\DSC Data\General\Sapphire_Heat_Capacity_11_30_22.tri
[Rev Cp Calibration]
Date Applied,11/30/2022 1:58:51 PM
Description,From -79.996 °C to 292.812 °C at 3.000°C/min
Gas Type,Nitrogen
Pan Type,Tzero Aluminum Hermetic
Source Files 1,C:\Users\yargerlab\Desktop\DSC Data\General\Sapphire_MDSC_Calibration_11_30_22.tri
[step]
Ramp 10.00 °C/min to 250.00 °C
Time,Temperature,Heat Flow (Normalized)
min,°C,W/g
0.00,-59.68,-0.063
0.02,-59.69,-0.060
0.04,-59.70,-0.054
0.07,-59.68,-0.054
0.09,-59.65,-0.057
0.11,-59.59,-0.062
0.13,-59.50,-0.063
0.15,-59.38,-0.054
0.17,-59.25,-0.030
0.19,-59.09,-0.006
0.22,-58.93,0.019
0.24,-58.76,0.044
0.26,-58.58,0.065
0.28,-58.39,0.084
0.30,-58.20,0.098
0.33,-58.01,0.113
0.35,-57.81,0.123
0.37,-57.62,0.133
0.39,-57.42,0.141
0.41,-57.22,0.147
0.43,-57.02,0.153
0.45,-56.81,0.158
0.48,-56.60,0.160
0.50,-56.40,0.166
0.52,-56.19,0.167
0.54,-55.98,0.168
0.56,-55.77,0.171
0.58,-55.56,0.173
0.61,-55.35,0.174
0.63,-55.14,0.176
0.65,-54.93,0.177
0.67,-54.72,0.178
0.69,-54.51,0.178
0.72,-54.30,0.179
0.74,-54.09,0.179
0.76,-53.87,0.180
0.78,-53.66,0.181
0.80,-53.45,0.181
0.82,-53.24,0.182
0.85,-53.02,0.182
0.87,-52.81,0.182
0.89,-52.59,0.183
0.91,-52.38,0.183
0.93,-52.17,0.184
0.95,-51.95,0.184
0.98,-51.74,0.184
1.00,-51.53,0.185
1.02,-51.31,0.185
1.04,-51.10,0.185
1.06,-50.88,0.186
1.08,-50.67,0.186
1.11,-50.45,0.186
1.13,-50.24,0.187
1.15,-50.02,0.187
1.17,-49.81,0.187
1.19,-49.59,0.187
1.21,-49.38,0.188
1.23,-49.16,0.188
1.26,-48.94,0.188
1.28,-48.73,0.188
1.30,-48.51,0.188
1.32,-48.30,0.189
1.34,-48.08,0.189
1.37,-47.86,0.189
1.39,-47.65,0.189
1.41,-47.43,0.189
1.43,-47.22,0.190
1.45,-47.00,0.190
1.47,-46.79,0.190
1.49,-46.57,0.190
1.52,-46.35,0.190
1.54,-46.14,0.190
1.56,-45.92,0.190
1.58,-45.71,0.191
1.60,-45.49,0.191
1.63,-45.27,0.191
1.65,-45.05,0.191
1.67,-44.84,0.191
1.69,-44.62,0.191
1.71,-44.41,0.191
1.73,-44.19,0.192
1.76,-43.97,0.192
1.78,-43.76,0.192
1.80,-43.54,0.192
1.82,-43.32,0.192
1.84,-43.11,0.192
1.86,-42.89,0.192
1.88,-42.67,0.192
1.91,-42.46,0.192
1.93,-42.24,0.193
1.95,-42.02,0.193
1.97,-41.81,0.193
1.99,-41.59,0.193
2.02,-41.37,0.193
2.04,-41.16,0.193
2.06,-40.94,0.193
2.08,-40.72,0.193
2.10,-40.51,0.193
2.12,-40.29,0.193
2.14,-40.07,0.193
2.17,-39.85,0.194
2.19,-39.64,0.194
2.21,-39.42,0.194
2.23,-39.21,0.194
2.25,-38.99,0.194
2.28,-38.77,0.194
2.30,-38.55,0.194
2.32,-38.34,0.194
2.34,-38.12,0.194
2.36,-37.90,0.194
2.38,-37.69,0.195
2.41,-37.47,0.195
2.43,-37.25,0.195
2.45,-37.03,0.195
2.47,-36.82,0.195
2.49,-36.60,0.195
2.51,-36.38,0.195
2.54,-36.17,0.195
2.56,-35.95,0.195
2.58,-35.73,0.195
2.60,-35.52,0.195
2.62,-35.30,0.195
2.64,-35.08,0.195
2.66,-34.87,0.196
2.69,-34.65,0.196
2.71,-34.43,0.196
2.73,-34.22,0.196
2.75,-34.00,0.196
2.77,-33.78,0.196
2.79,-33.56,0.196
2.82,-33.35,0.196
2.84,-33.13,0.196
2.86,-32.91,0.196
2.88,-32.70,0.196
2.90,-32.48,0.196
2.93,-32.26,0.196
2.95,-32.05,0.197
2.97,-31.83,0.197
2.99,-31.61,0.197
3.01,-31.39,0.197
3.03,-31.18,0.197
3.06,-30.96,0.197
3.08,-30.74,0.197
3.10,-30.53,0.197
3.12,-30.31,0.197
3.14,-30.09,0.197
3.16,-29.88,0.198
3.19,-29.66,0.198
3.21,-29.44,0.198
3.23,-29.23,0.198
3.25,-29.01,0.198
3.27,-28.79,0.198
3.29,-28.57,0.198
3.31,-28.36,0.198
3.34,-28.14,0.198
3.36,-27.92,0.198
3.38,-27.71,0.198
3.40,-27.49,0.199
3.42,-27.27,0.199
3.44,-27.06,0.199
3.47,-26.84,0.199
3.49,-26.62,0.199
3.51,-26.41,0.199
3.53,-26.19,0.199
3.55,-25.97,0.199
3.58,-25.75,0.199
3.60,-25.54,0.199
3.62,-25.32,0.199
3.64,-25.10,0.199
3.66,-24.89,0.200
3.68,-24.67,0.200
3.71,-24.45,0.200
3.73,-24.24,0.200
3.75,-24.02,0.200
3.77,-23.80,0.200
3.79,-23.58,0.200
3.81,-23.37,0.200
3.84,-23.15,0.200
3.86,-22.93,0.200
3.88,-22.72,0.200
3.90,-22.50,0.201
3.92,-22.28,0.201
3.94,-22.07,0.201
3.96,-21.85,0.201
3.99,-21.63,0.201
4.01,-21.42,0.201
4.03,-21.20,0.201
4.05,-20.98,0.201
4.07,-20.76,0.201
4.09,-20.55,0.202
4.12,-20.33,0.202
4.14,-20.12,0.202
4.16,-19.90,0.202
4.18,-19.68,0.202
4.20,-19.46,0.202
4.23,-19.25,0.202
4.25,-19.03,0.202
4.27,-18.81,0.202
4.29,-18.60,0.203
4.31,-18.38,0.203
4.33,-18.16,0.203
4.35,-17.95,0.203
4.38,-17.73,0.203
4.40,-17.51,0.203
4.42,-17.29,0.203
4.44,-17.08,0.203
4.46,-16.86,0.203
4.49,-16.64,0.204
4.51,-16.43,0.204
4.53,-16.21,0.204
4.55,-15.99,0.204
4.57,-15.78,0.204
4.59,-15.56,0.204
4.61,-15.34,0.204
4.64,-15.12,0.204
4.66,-14.91,0.204
4.68,-14.69,0.205
4.70,-14.48,0.205
4.72,-14.26,0.205
4.75,-14.04,0.205
4.77,-13.82,0.205
4.79,-13.61,0.205
4.81,-13.39,0.205
4.83,-13.17,0.205
4.85,-12.96,0.206
4.88,-12.74,0.206
4.90,-12.52,0.206
4.92,-12.31,0.206
4.94,-12.09,0.206
4.96,-11.87,0.206
4.98,-11.66,0.206
5.00,-11.44,0.206
5.03,-11.22,0.206
5.05,-11.00,0.207
5.07,-10.79,0.207
5.09,-10.57,0.207
5.11,-10.35,0.207
5.14,-10.14,0.207
5.16,-9.92,0.207
5.18,-9.70,0.207
5.20,-9.49,0.207
5.22,-9.27,0.208
5.24,-9.05,0.208
5.26,-8.83,0.208
5.29,-8.62,0.208
5.31,-8.40,0.208
5.33,-8.18,0.208
5.35,-7.97,0.208
5.37,-7.75,0.208
5.40,-7.53,0.209
5.42,-7.32,0.209
5.44,-7.10,0.209
5.46,-6.88,0.209
5.48,-6.67,0.209
5.50,-6.45,0.209
5.53,-6.23,0.209
5.55,-6.01,0.210
5.57,-5.80,0.210
5.59,-5.58,0.210
5.61,-5.36,0.210
5.63,-5.15,0.210
5.65,-4.93,0.210
5.68,-4.71,0.210
5.70,-4.50,0.210
5.72,-4.28,0.211
5.74,-4.06,0.211
5.76,-3.85,0.211
5.79,-3.63,0.211
5.81,-3.41,0.211
5.83,-3.19,0.211
5.85,-2.98,0.211
5.87,-2.76,0.212
5.89,-2.54,0.212
5.91,-2.33,0.212
5.94,-2.11,0.212
5.96,-1.89,0.212
5.98,-1.68,0.212
6.00,-1.46,0.212
6.02,-1.24,0.212
6.05,-1.03,0.213
6.07,-0.81,0.213
6.09,-0.59,0.213
6.11,-0.38,0.213
6.13,-0.16,0.213
6.15,0.06,0.213
6.18,0.28,0.214
6.20,0.49,0.214
6.22,0.71,0.214
6.24,0.93,0.214
6.26,1.14,0.214
6.28,1.36,0.214
6.30,1.58,0.215
6.33,1.80,0.215
6.35,2.01,0.215
6.37,2.23,0.215
6.39,2.45,0.215
6.41,2.66,0.215
6.44,2.88,0.215
6.46,3.10,0.215
6.48,3.31,0.216
6.50,3.53,0.216
6.52,3.75,0.216
6.54,3.96,0.216
6.56,4.18,0.216
6.59,4.40,0.216
6.61,4.61,0.217
6.63,4.83,0.217
6.65,5.05,0.217
6.67,5.27,0.217
6.70,5.48,0.217
6.72,5.70,0.217
6.74,5.92,0.217
6.76,6.13,0.217
6.78,6.35,0.218
6.80,6.57,0.218
6.83,6.78,0.218
6.85,7.00,0.218
6.87,7.22,0.218
6.89,7.43,0.219
6.91,7.65,0.219
6.93,7.87,0.219
6.95,8.08,0.219
6.98,8.30,0.219
7.00,8.52,0.219
7.02,8.74,0.219
7.04,8.95,0.219
7.06,9.17,0.220
7.09,9.39,0.220
7.11,9.60,0.220
7.13,9.82,0.220
7.15,10.04,0.220
7.17,10.25,0.220
7.19,10.47,0.221
7.21,10.69,0.221
7.24,10.90,0.221
7.26,11.12,0.221
7.28,11.34,0.221
7.30,11.55,0.221
7.32,11.77,0.222
7.35,11.99,0.222
7.37,12.21,0.222
7.39,12.42,0.222
7.41,12.64,0.222
7.43,12.86,0.222
7.45,13.07,0.222
7.48,13.29,0.223
7.50,13.51,0.223
7.52,13.72,0.223
7.54,13.94,0.223
7.56,14.16,0.223
7.58,14.37,0.224
7.60,14.59,0.224
7.63,14.81,0.224
7.65,15.03,0.224
7.67,15.24,0.225
7.69,15.46,0.225
7.71,15.68,0.225
7.74,15.89,0.225
7.76,16.11,0.225
7.78,16.33,0.225
7.80,16.54,0.225
7.82,16.76,0.226
7.84,16.98,0.226
7.86,17.19,0.226
7.89,17.41,0.226
7.91,17.63,0.226
7.93,17.84,0.226
7.95,18.06,0.227
7.97,18.28,0.227
8.00,18.50,0.227
8.02,18.71,0.227
8.04,18.93,0.227
8.06,19.15,0.227
8.08,19.36,0.227
8.10,19.58,0.227
8.13,19.80,0.228
8.15,20.01,0.228
8.17,20.23,0.228
8.19,20.45,0.228
8.21,20.66,0.228
8.23,20.88,0.228
8.25,21.10,0.229
8.28,21.32,0.229
8.30,21.53,0.229
8.32,21.75,0.229
8.34,21.97,0.229
8.36,22.18,0.229
8.39,22.40,0.230
8.41,22.62,0.230
8.43,22.83,0.230
8.45,23.05,0.230
8.47,23.27,0.230
8.49,23.48,0.230
8.51,23.70,0.231
8.54,23.92,0.231
8.56,24.13,0.231
8.58,24.35,0.231
8.60,24.57,0.231
8.62,24.78,0.232
8.65,25.00,0.232
8.67,25.22,0.232
8.69,25.44,0.232
8.71,25.65,0.233
8.73,25.87,0.233
8.75,26.09,0.233
8.78,26.30,0.233
8.80,26.52,0.233
8.82,26.74,0.233
8.84,26.95,0.234
8.86,27.17,0.234
8.88,27.39,0.234
8.90,27.61,0.234
8.93,27.82,0.234
8.95,28.04,0.235
8.97,28.25,0.235
8.99,28.47,0.235
9.01,28.69,0.235
9.03,28.91,0.235
9.06,29.12,0.236
9.08,29.34,0.236
9.10,29.56,0.236
9.12,29.77,0.236
9.14,29.99,0.237
9.17,30.21,0.237
9.19,30.42,0.237
9.21,30.64,0.237
9.23,30.86,0.237
9.25,31.08,0.238
9.27,31.29,0.238
9.30,31.51,0.238
9.32,31.73,0.238
9.34,31.94,0.238
9.36,32.16,0.239
9.38,32.38,0.239
9.40,32.59,0.239
9.43,32.81,0.239
9.45,33.03,0.239
9.47,33.25,0.239
9.49,33.46,0.239
9.51,33.68,0.240
9.53,33.89,0.240
9.55,34.11,0.240
9.58,34.33,0.240
9.60,34.54,0.240
9.62,34.76,0.241
9.64,34.98,0.241
9.66,35.20,0.241
9.68,35.41,0.241
9.71,35.63,0.241
9.73,35.85,0.242
9.75,36.06,0.242
9.77,36.28,0.242
9.79,36.50,0.242
9.82,36.71,0.242
9.84,36.93,0.243
9.86,37.15,0.243
9.88,37.37,0.243
9.90,37.58,0.243
9.92,37.80,0.244
9.95,38.01,0.244
9.97,38.23,0.244
9.99,38.45,0.244
10.01,38.67,0.244
10.03,38.88,0.245
10.05,39.10,0.245
10.08,39.32,0.245
10.10,39.53,0.245
10.12,39.75,0.246
10.14,39.97,0.246
10.16,40.18,0.246
10.18,40.40,0.247
10.20,40.62,0.247
10.23,40.83,0.247
10.25,41.05,0.248
10.27,41.27,0.248
10.29,41.48,0.249
10.31,41.70,0.249
10.33,41.92,0.249
10.36,42.13,0.249
10.38,42.35,0.250
10.40,42.57,0.250
10.42,42.78,0.251
10.44,43.00,0.252
10.47,43.22,0.252
10.49,43.43,0.253
10.51,43.65,0.253
10.53,43.87,0.254
10.55,44.08,0.255
10.57,44.30,0.256
10.60,44.52,0.256
10.62,44.73,0.257
10.64,44.95,0.259
10.66,45.17,0.261
10.68,45.38,0.262
10.70,45.60,0.265
10.73,45.82,0.266
10.75,46.03,0.268
10.77,46.25,0.270
10.79,46.46,0.272
10.81,46.68,0.274
10.83,46.90,0.276
10.85,47.11,0.279
10.88,47.33,0.281
10.90,47.55,0.284
10.92,47.76,0.286
10.94,47.98,0.288
10.96,48.19,0.291
10.98,48.41,0.294
11.01,48.63,0.296
11.03,48.84,0.299
11.05,49.06,0.303
11.07,49.27,0.305
11.09,49.49,0.308
11.12,49.70,0.312
11.14,49.92,0.315
11.16,50.14,0.319
11.18,50.35,0.322
11.20,50.57,0.326
11.22,50.78,0.330
11.25,51.00,0.334
11.27,51.22,0.338
11.29,51.43,0.344
11.31,51.65,0.348
11.33,51.86,0.351
11.35,52.08,0.358
11.38,52.29,0.364
11.40,52.51,0.368
11.42,52.72,0.372
11.44,52.94,0.379
11.46,53.15,0.385
11.48,53.37,0.392
11.50,53.58,0.397
11.53,53.79,0.402
11.55,54.01,0.408
11.57,54.23,0.415
11.59,54.44,0.422
11.61,54.65,0.428
11.63,54.87,0.435
11.66,55.08,0.441
11.68,55.30,0.449
11.70,55.51,0.456
11.72,55.73,0.464
11.74,55.94,0.470
11.77,56.16,0.479
11.79,56.37,0.486
11.81,56.58,0.494
11.83,56.80,0.500
11.85,57.01,0.509
11.87,57.23,0.516
11.90,57.44,0.525
11.92,57.65,0.532
11.94,57.87,0.540
11.96,58.08,0.547
11.98,58.29,0.555
12.00,58.51,0.563
12.03,58.72,0.574
12.05,58.94,0.583
12.07,59.15,0.592
12.09,59.36,0.600
12.11,59.58,0.609
12.13,59.79,0.616
12.15,60.01,0.621
12.18,60.22,0.627
12.20,60.44,0.634
12.22,60.65,0.645
12.24,60.86,0.651
12.26,61.08,0.655
12.28,61.29,0.657
12.31,61.51,0.658
12.33,61.72,0.658
12.35,61.94,0.659
12.37,62.16,0.659
12.39,62.37,0.659
12.42,62.59,0.660
12.44,62.81,0.660
12.46,63.02,0.661
12.48,63.24,0.661
12.50,63.45,0.663
12.52,63.67,0.667
12.55,63.89,0.668
12.57,64.10,0.670
12.59,64.32,0.670
12.61,64.54,0.670
12.63,64.75,0.669
12.65,64.97,0.665
12.68,65.19,0.660
12.70,65.41,0.654
12.72,65.63,0.649
12.74,65.84,0.644
12.76,66.06,0.639
12.78,66.28,0.635
12.80,66.50,0.631
12.83,66.72,0.627
12.85,66.94,0.622
12.87,67.16,0.618
12.89,67.38,0.614
12.91,67.59,0.610
12.93,67.81,0.605
12.96,68.03,0.601
12.98,68.25,0.598
13.00,68.47,0.595
13.02,68.69,0.590
13.04,68.90,0.586
13.07,69.12,0.582
13.09,69.34,0.578
13.11,69.56,0.575
13.13,69.78,0.572
13.15,70.00,0.569
13.17,70.21,0.566
13.20,70.43,0.561
13.22,70.65,0.558
13.24,70.87,0.553
13.26,71.09,0.551
13.28,71.31,0.547
13.30,71.53,0.543
13.33,71.74,0.539
13.35,71.96,0.535
13.37,72.18,0.531
13.39,72.40,0.527
13.41,72.62,0.523
13.43,72.83,0.519
13.45,73.05,0.514
13.48,73.27,0.509
13.50,73.49,0.504
13.52,73.71,0.500
13.54,73.93,0.494
13.56,74.15,0.488
13.58,74.37,0.481
13.61,74.58,0.475
13.63,74.80,0.469
13.65,75.02,0.462
13.67,75.24,0.456
13.69,75.46,0.447
13.72,75.68,0.439
13.74,75.90,0.430
13.76,76.12,0.421
13.78,76.34,0.411
13.80,76.56,0.402
13.82,76.78,0.393
13.85,77.00,0.383
13.87,77.22,0.375
13.89,77.44,0.368
13.91,77.66,0.358
13.93,77.88,0.353
13.95,78.10,0.349
13.98,78.32,0.346
14.00,78.54,0.344
14.02,78.76,0.342
14.04,78.98,0.341
14.06,79.19,0.340
14.08,79.41,0.339
14.10,79.63,0.338
14.13,79.85,0.338
14.15,80.07,0.337
14.17,80.28,0.337
14.19,80.50,0.336
14.21,80.72,0.336
14.23,80.93,0.336
14.26,81.15,0.335
14.28,81.37,0.335
14.30,81.59,0.335
14.32,81.80,0.335
14.34,82.02,0.334
14.37,82.24,0.334
14.39,82.45,0.334
14.41,82.67,0.334
14.43,82.89,0.334
14.45,83.10,0.333
14.47,83.32,0.333
14.50,83.54,0.333
14.52,83.75,0.333
14.54,83.97,0.333
14.56,84.19,0.333
14.58,84.41,0.332
14.60,84.62,0.332
14.63,84.84,0.332
14.65,85.06,0.332
14.67,85.27,0.332
14.69,85.49,0.332
14.71,85.71,0.332
14.73,85.92,0.332
14.75,86.14,0.332
14.78,86.36,0.332
14.80,86.58,0.332
14.82,86.79,0.332
14.84,87.01,0.332
14.86,87.23,0.332
14.88,87.44,0.332
14.91,87.66,0.332
14.93,87.88,0.332
14.95,88.09,0.332
14.97,88.31,0.332
14.99,88.53,0.332
15.02,88.74,0.332
15.04,88.96,0.332
15.06,89.18,0.333
15.08,89.39,0.333
15.10,89.61,0.333
15.12,89.83,0.333
15.15,90.04,0.333
15.17,90.26,0.333
15.19,90.48,0.333
15.21,90.69,0.334
15.23,90.91,0.334
15.25,91.13,0.334
15.28,91.35,0.334
15.30,91.56,0.334
15.32,91.78,0.334
15.34,92.00,0.334
15.36,92.21,0.335
15.38,92.43,0.335
15.40,92.65,0.335
15.43,92.86,0.335
15.45,93.08,0.335
15.47,93.30,0.335
15.49,93.51,0.335
15.51,93.73,0.336
15.53,93.95,0.336
15.56,94.17,0.336
15.58,94.38,0.336
15.60,94.60,0.336
15.62,94.82,0.336
15.64,95.03,0.337
15.67,95.25,0.337
15.69,95.47,0.337
15.71,95.68,0.337
15.73,95.90,0.337
15.75,96.12,0.338
15.77,96.33,0.338
15.80,96.55,0.338
15.82,96.77,0.338
15.84,96.98,0.338
15.86,97.20,0.338
15.88,97.42,0.339
15.90,97.63,0.339
15.93,97.85,0.339
15.95,98.07,0.339
15.97,98.28,0.339
15.99,98.50,0.339
16.01,98.72,0.340
16.03,98.94,0.340
16.05,99.15,0.340
16.08,99.37,0.340
16.10,99.59,0.340
16.12,99.80,0.341
16.14,100.02,0.341
16.16,100.24,0.341
16.18,100.45,0.341
16.21,100.67,0.341
16.23,100.89,0.341
16.25,101.10,0.342
16.27,101.32,0.342
16.29,101.54,0.342
16.32,101.75,0.342
16.34,101.97,0.342
16.36,102.19,0.343
16.38,102.40,0.343
16.40,102.62,0.343
16.42,102.84,0.343
16.45,103.05,0.343
16.47,103.27,0.344
16.49,103.49,0.344
16.51,103.70,0.344
16.53,103.92,0.344
16.55,104.14,0.345
16.58,104.36,0.345
16.60,104.57,0.345
16.62,104.79,0.345
16.64,105.00,0.345
16.66,105.22,0.346
16.68,105.44,0.346
16.70,105.66,0.346
16.73,105.87,0.346
16.75,106.09,0.347
16.77,106.31,0.347
16.79,106.52,0.347
16.81,106.74,0.347
16.83,106.96,0.347
16.86,107.18,0.348
16.88,107.39,0.348
16.90,107.61,0.348
16.92,107.83,0.348
16.94,108.04,0.349
16.97,108.26,0.349
16.99,108.48,0.349
17.01,108.69,0.349
17.03,108.91,0.350
17.05,109.13,0.350
17.07,109.34,0.350
17.09,109.56,0.350
17.12,109.78,0.351
17.14,109.99,0.351
17.16,110.21,0.351
17.18,110.43,0.351
17.20,110.64,0.352
17.23,110.86,0.352
17.25,111.08,0.352
17.27,111.29,0.352
17.29,111.51,0.353
17.31,111.73,0.353
17.33,111.94,0.353
17.36,112.16,0.354
17.38,112.38,0.354
17.40,112.59,0.354
17.42,112.81,0.354
17.44,113.03,0.355
17.46,113.24,0.355
17.48,113.46,0.355
17.51,113.68,0.355
17.53,113.89,0.356
17.55,114.11,0.356
17.57,114.33,0.356
17.59,114.54,0.356
17.62,114.76,0.357
17.64,114.98,0.357
17.66,115.20,0.357
17.68,115.41,0.358
17.70,115.63,0.358
17.72,115.85,0.358
17.74,116.06,0.358
17.77,116.28,0.359
17.79,116.50,0.359
17.81,116.71,0.359
17.83,116.93,0.360
17.85,117.15,0.360
17.88,117.36,0.360
17.90,117.58,0.360
17.92,117.80,0.361
17.94,118.01,0.361
17.96,118.23,0.361
17.98,118.45,0.362
18.01,118.66,0.362
18.03,118.88,0.363
18.05,119.10,0.363
18.07,119.31,0.363
18.09,119.53,0.364
18.11,119.75,0.364
18.13,119.96,0.364
18.16,120.18,0.364
18.18,120.40,0.365
18.20,120.61,0.365
18.22,120.83,0.365
18.24,121.05,0.366
18.27,121.26,0.366
18.29,121.48,0.366
18.31,121.70,0.367
18.33,121.91,0.367
18.35,122.13,0.367
18.37,122.35,0.367
18.39,122.56,0.368
18.42,122.78,0.368
18.44,123.00,0.368
18.46,123.21,0.368
18.48,123.43,0.369
18.50,123.65,0.369
18.53,123.86,0.369
18.55,124.08,0.370
18.57,124.30,0.370
18.59,124.52,0.370
18.61,124.73,0.370
18.63,124.95,0.371
18.66,125.17,0.371
18.68,125.38,0.371
18.70,125.60,0.371
18.72,125.82,0.372
18.74,126.03,0.372
18.76,126.25,0.372
18.78,126.47,0.373
18.81,126.68,0.373
18.83,126.90,0.373
18.85,127.12,0.373
18.87,127.33,0.374
18.89,127.55,0.374
18.92,127.77,0.374
18.94,127.99,0.375
18.96,128.20,0.375
18.98,128.42,0.375
19.00,128.64,0.375
19.02,128.85,0.376
19.04,129.07,0.376
19.07,129.29,0.376
19.09,129.50,0.377
19.11,129.72,0.377
19.13,129.94,0.377
19.15,130.15,0.377
19.18,130.37,0.378
19.20,130.59,0.378
19.22,130.80,0.378
19.24,131.02,0.378
19.26,131.24,0.379
19.28,131.45,0.379
19.31,131.67,0.379
19.33,131.89,0.379
19.35,132.10,0.380
19.37,132.32,0.380
19.39,132.54,0.380
19.41,132.75,0.381
19.43,132.97,0.381
19.46,133.19,0.381
19.48,133.40,0.381
19.50,133.62,0.382
19.52,133.84,0.382
19.54,134.05,0.382
19.57,134.27,0.382
19.59,134.49,0.383
19.61,134.70,0.383
19.63,134.92,0.383
19.65,135.14,0.384
19.67,135.35,0.384
19.69,135.57,0.384
19.72,135.79,0.384
19.74,136.00,0.385
19.76,136.22,0.385
19.78,136.44,0.385
19.80,136.65,0.386
19.83,136.87,0.386
19.85,137.09,0.386
19.87,137.31,0.387
19.89,137.52,0.387
19.91,137.74,0.387
19.93,137.96,0.388
19.96,138.17,0.388
19.98,138.39,0.389
20.00,138.61,0.389
20.02,138.82,0.389
20.04,139.04,0.390
20.06,139.26,0.390
20.08,139.47,0.390
20.11,139.69,0.391
20.13,139.91,0.391
20.15,140.12,0.391
20.17,140.34,0.392
20.19,140.55,0.392
20.22,140.77,0.393
20.24,140.99,0.393
20.26,141.21,0.394
20.28,141.42,0.394
20.30,141.64,0.395
20.32,141.86,0.395
20.34,142.07,0.396
20.37,142.29,0.397
20.39,142.50,0.397
20.41,142.72,0.398
20.43,142.94,0.398
20.45,143.16,0.400
20.48,143.37,0.401
20.50,143.59,0.402
20.52,143.80,0.402
20.54,144.02,0.404
20.56,144.24,0.405
20.58,144.45,0.407
20.61,144.67,0.408
20.63,144.89,0.410
20.65,145.10,0.412
20.67,145.32,0.413
20.69,145.54,0.415
20.71,145.75,0.416
20.73,145.97,0.418
20.76,146.19,0.420
20.78,146.40,0.421
20.80,146.62,0.421
20.82,146.83,0.422
20.84,147.05,0.423
20.87,147.27,0.423
20.89,147.49,0.424
20.91,147.70,0.425
20.93,147.92,0.425
20.95,148.14,0.426
20.97,148.35,0.426
20.99,148.57,0.426
21.02,148.79,0.427
21.04,149.00,0.427
21.06,149.22,0.427
21.08,149.44,0.427
21.10,149.65,0.428
21.13,149.87,0.428
21.15,150.09,0.428
21.17,150.30,0.428
21.19,150.52,0.428
21.21,150.74,0.428
21.23,150.95,0.428
21.26,151.17,0.428
21.28,151.39,0.428
21.30,151.60,0.428
21.32,151.82,0.428
21.34,152.04,0.428
21.36,152.26,0.428
21.38,152.47,0.428
21.41,152.69,0.428
21.43,152.91,0.428
21.45,153.12,0.428
21.47,153.34,0.428
21.49,153.56,0.428
21.52,153.77,0.428
21.54,153.99,0.428
21.56,154.21,0.428
21.58,154.42,0.428
21.60,154.64,0.428
21.62,154.86,0.428
21.64,155.07,0.428
21.67,155.29,0.428
21.69,155.51,0.427
21.71,155.72,0.427
21.73,155.94,0.427
21.75,156.16,0.427
21.78,156.38,0.427
21.80,156.59,0.427
21.82,156.81,0.427
21.84,157.03,0.427
21.86,157.24,0.426
21.88,157.46,0.426
21.91,157.68,0.426
21.93,157.89,0.426
21.95,158.11,0.426
21.97,158.33,0.426
21.99,158.55,0.426
22.01,158.76,0.425
22.03,158.98,0.425
22.06,159.20,0.425
22.08,159.41,0.425
22.10,159.63,0.425
22.12,159.85,0.425
22.14,160.06,0.424
22.17,160.28,0.424
22.19,160.50,0.424
22.21,160.71,0.424
22.23,160.93,0.424
22.25,161.15,0.424
22.27,161.36,0.424
22.29,161.58,0.423
22.32,161.80,0.423
22.34,162.01,0.423
22.36,162.23,0.423
22.38,162.45,0.423
22.40,162.66,0.423
22.43,162.88,0.423
22.45,163.10,0.422
22.47,163.32,0.422
22.49,163.53,0.422
22.51,163.75,0.422
22.53,163.97,0.422
22.56,164.18,0.422
22.58,164.40,0.421
22.60,164.62,0.421
22.62,164.83,0.421
22.64,165.05,0.421
22.66,165.27,0.421
22.68,165.49,0.420
22.71,165.70,0.420
22.73,165.92,0.420
22.75,166.14,0.420
22.77,166.35,0.420
22.79,166.57,0.420
22.82,166.79,0.420
22.84,167.00,0.420
22.86,167.22,0.420
22.88,167.44,0.419
22.90,167.65,0.419
22.92,167.87,0.419
22.94,168.09,0.419
22.97,168.30,0.419
22.99,168.52,0.419
23.01,168.74,0.419
23.03,168.95,0.419
23.05,169.17,0.419
23.08,169.39,0.420
23.10,169.60,0.420
23.12,169.82,0.420
23.14,170.04,0.420
23.16,170.25,0.420
23.18,170.47,0.420
23.21,170.69,0.420
23.23,170.90,0.420
23.25,171.12,0.420
23.27,171.34,0.420
23.29,171.56,0.421
23.31,171.77,0.421
23.33,171.99,0.421
23.36,172.21,0.421
23.38,172.42,0.421
23.40,172.64,0.421
23.42,172.86,0.421
23.44,173.07,0.422
23.47,173.29,0.422
23.49,173.51,0.422
23.51,173.72,0.422
23.53,173.94,0.422
23.55,174.16,0.422
23.57,174.37,0.422
23.59,174.59,0.422
23.62,174.81,0.422
23.64,175.02,0.422
23.66,175.24,0.422
23.68,175.46,0.422
23.70,175.67,0.422
23.73,175.89,0.422
23.75,176.11,0.422
23.77,176.32,0.422
23.79,176.54,0.422
23.81,176.76,0.422
23.83,176.98,0.422
23.86,177.19,0.422
23.88,177.41,0.422
23.90,177.63,0.422
23.92,177.84,0.422
23.94,178.06,0.422
23.96,178.28,0.421
23.98,178.49,0.421
24.01,178.71,0.421
24.03,178.93,0.421
24.05,179.15,0.421
24.07,179.36,0.421
24.09,179.58,0.421
24.12,179.80,0.421
24.14,180.01,0.420
24.16,180.23,0.420
24.18,180.45,0.420
24.20,180.66,0.420
24.22,180.88,0.420
24.24,181.10,0.419
24.27,181.31,0.419
24.29,181.53,0.419
24.31,181.75,0.418
24.33,181.96,0.418
24.35,182.18,0.418
24.38,182.40,0.417
24.40,182.62,0.417
24.42,182.83,0.416
24.44,183.05,0.416
24.46,183.27,0.416
24.48,183.48,0.415
24.51,183.70,0.415
24.53,183.92,0.414
24.55,184.14,0.414
24.57,184.35,0.413
24.59,184.57,0.412
24.61,184.79,0.411
24.63,185.00,0.410
24.66,185.22,0.410
24.68,185.44,0.409
24.70,185.65,0.408
24.72,185.87,0.407
24.74,186.09,0.406
24.77,186.31,0.405
24.79,186.52,0.403
24.81,186.74,0.402
24.83,186.96,0.401
24.85,187.17,0.400
24.87,187.39,0.399
24.89,187.61,0.398
24.92,187.83,0.397
24.94,188.04,0.395
24.96,188.26,0.394
24.98,188.48,0.393
25.00,188.69,0.391
25.03,188.91,0.389
25.05,189.13,0.388
25.07,189.35,0.387
25.09,189.56,0.386
25.11,189.78,0.386
25.13,190.00,0.385
25.16,190.21,0.384
25.18,190.43,0.383
25.20,190.65,0.382
25.22,190.87,0.381
25.24,191.08,0.381
25.26,191.30,0.380
25.28,191.52,0.379
25.31,191.73,0.379
25.33,191.95,0.379
25.35,192.17,0.378
25.37,192.39,0.378
25.39,192.60,0.377
25.42,192.82,0.377
25.44,193.04,0.376
25.46,193.25,0.376
25.48,193.47,0.376
25.50,193.69,0.375
25.52,193.90,0.375
25.54,194.12,0.374
25.57,194.34,0.374
25.59,194.56,0.373
25.61,194.77,0.373
25.63,194.99,0.372
25.65,195.21,0.372
25.68,195.42,0.371
25.70,195.64,0.371
25.72,195.86,0.370
25.74,196.07,0.370
25.76,196.29,0.370
25.78,196.51,0.369
25.81,196.72,0.369
25.83,196.94,0.368
25.85,197.16,0.368
25.87,197.37,0.368
25.89,197.59,0.367
25.91,197.81,0.367
25.93,198.03,0.366
25.96,198.24,0.366
25.98,198.46,0.366
26.00,198.68,0.365
26.02,198.89,0.365
26.04,199.11,0.365
26.07,199.33,0.364
26.09,199.54,0.364
26.11,199.76,0.364
26.13,199.98,0.363
26.15,200.19,0.363
26.17,200.41,0.363
26.19,200.63,0.363
26.22,200.84,0.362
26.24,201.06,0.362
26.26,201.28,0.362
26.28,201.50,0.362
26.30,201.71,0.361
26.33,201.93,0.361
26.35,202.15,0.361
26.37,202.36,0.361
26.39,202.58,0.360
26.41,202.80,0.360
26.43,203.01,0.360
26.46,203.23,0.360
26.48,203.45,0.360
26.50,203.67,0.359
26.52,203.88,0.359
26.54,204.10,0.359
26.56,204.31,0.359
26.58,204.53,0.358
26.61,204.75,0.358
26.63,204.97,0.358
26.65,205.18,0.358
26.67,205.40,0.357
26.69,205.61,0.357
26.72,205.83,0.357
26.74,206.05,0.357
26.76,206.27,0.356
26.78,206.48,0.356
26.80,206.70,0.356
26.82,206.92,0.356
26.84,207.13,0.356
26.87,207.35,0.356
26.89,207.57,0.356
26.91,207.78,0.356
26.93,208.00,0.355
26.95,208.22,0.355
26.98,208.44,0.355
27.00,208.65,0.355
27.02,208.87,0.355
27.04,209.09,0.355
27.06,209.30,0.355
27.08,209.52,0.355
27.11,209.73,0.355
27.13,209.95,0.355
27.15,210.17,0.355
27.17,210.38,0.355
27.19,210.60,0.355
27.21,210.82,0.355
27.23,211.03,0.355
27.26,211.25,0.355
27.28,211.47,0.355
27.30,211.68,0.355
27.32,211.90,0.355
27.34,212.12,0.355
27.37,212.33,0.355
27.39,212.55,0.355
27.41,212.77,0.355
27.43,212.99,0.355
27.45,213.20,0.355
27.47,213.42,0.355
27.49,213.64,0.355
27.52,213.85,0.355
27.54,214.07,0.355
27.56,214.29,0.355
27.58,214.51,0.355
27.60,214.72,0.355
27.63,214.94,0.355
27.65,215.15,0.355
27.67,215.37,0.355
27.69,215.59,0.355
27.71,215.80,0.355
27.73,216.02,0.355
27.76,216.24,0.355
27.78,216.45,0.355
27.80,216.67,0.355
27.82,216.89,0.355
27.84,217.10,0.355
27.86,217.32,0.355
27.88,217.54,0.355
27.91,217.75,0.355
27.93,217.97,0.356
27.95,218.19,0.356
27.97,218.41,0.356
27.99,218.62,0.356
28.02,218.84,0.356
28.04,219.06,0.356
28.06,219.27,0.356
28.08,219.49,0.356
28.10,219.71,0.356
28.12,219.92,0.356
28.14,220.14,0.356
28.17,220.36,0.356
28.19,220.57,0.356
28.21,220.79,0.356
28.23,221.01,0.356
28.25,221.22,0.356
28.28,221.44,0.356
28.30,221.66,0.356
28.32,221.87,0.356
28.34,222.09,0.356
28.36,222.31,0.356
28.38,222.52,0.356
28.41,222.74,0.356
28.43,222.96,0.356
28.45,223.17,0.356
28.47,223.39,0.356
28.49,223.61,0.356
28.51,223.82,0.356
28.53,224.04,0.356
28.56,224.26,0.356
28.58,224.47,0.356
28.60,224.69,0.356
28.62,224.91,0.356
28.64,225.13,0.356
28.67,225.34,0.356
28.69,225.56,0.356
28.71,225.77,0.356
28.73,225.99,0.356
28.75,226.21,0.356
28.77,226.43,0.356
28.79,226.64,0.356
28.82,226.86,0.356
28.84,227.08,0.356
28.86,227.29,0.356
28.88,227.51,0.356
28.90,227.73,0.356
28.93,227.94,0.356
28.95,228.16,0.356
28.97,228.38,0.356
28.99,228.59,0.356
29.01,228.81,0.356
29.03,229.03,0.356
29.06,229.24,0.356
29.08,229.46,0.356
29.10,229.68,0.356
29.12,229.89,0.356
29.14,230.11,0.356
29.16,230.33,0.356
29.18,230.55,0.356
29.21,230.76,0.356
29.23,230.98,0.356
29.25,231.20,0.356
29.27,231.41,0.356
29.29,231.63,0.356
29.32,231.85,0.356
29.34,232.06,0.356
29.36,232.28,0.355
29.38,232.50,0.355
29.40,232.71,0.355
29.42,232.93,0.355
29.44,233.15,0.355
29.47,233.36,0.355
29.49,233.58,0.355
29.51,233.80,0.355
29.53,234.01,0.355
29.55,234.23,0.355
29.58,234.45,0.355
29.60,234.66,0.355
29.62,234.88,0.355
29.64,235.10,0.355
29.66,235.31,0.355
29.68,235.53,0.355
29.71,235.75,0.355
29.73,235.96,0.355
29.75,236.18,0.355
29.77,236.40,0.354
29.79,236.61,0.354
29.81,236.83,0.355
29.83,237.05,0.355
29.86,237.26,0.355
29.88,237.48,0.355
29.90,237.70,0.355
29.92,237.91,0.355
29.94,238.13,0.355
29.97,238.35,0.355
29.99,238.56,0.355
30.01,238.78,0.355
30.03,239.00,0.355
30.05,239.21,0.355
30.07,239.43,0.355
30.09,239.65,0.355
30.12,239.86,0.355
30.14,240.08,0.355
30.16,240.30,0.355
30.18,240.52,0.355
30.20,240.73,0.355
30.23,240.95,0.355
30.25,241.17,0.355
30.27,241.38,0.355
30.29,241.60,0.355
30.31,241.81,0.355
30.33,242.03,0.355
30.36,242.25,0.355
30.38,242.47,0.355
30.40,242.68,0.355
30.42,242.90,0.355
30.44,243.12,0.355
30.46,243.33,0.355
30.48,243.55,0.355
30.51,243.77,0.355
30.53,243.98,0.355
30.55,244.20,0.355
30.57,244.42,0.355
30.59,244.63,0.355
30.62,244.85,0.355
30.64,245.07,0.355
30.66,245.28,0.355
30.68,245.50,0.355
30.70,245.72,0.355
30.72,245.94,0.355
30.74,246.15,0.355
30.77,246.37,0.355
30.79,246.58,0.355
30.81,246.80,0.355
30.83,247.02,0.355
30.85,247.24,0.355
30.88,247.45,0.355
30.90,247.67,0.355
30.92,247.89,0.355
30.94,248.10,
30.96,248.32,
30.98,248.54,
30.99,,

[step]
Ramp 10.00 °C/min to -60.00 °C
Time,Temperature,Heat Flow (Normalized)
min,°C,W/g
31.09,249.52,0.364
31.12,249.65,0.353
31.14,249.74,0.318
31.16,249.80,0.275
31.18,249.83,0.226
31.20,249.81,0.165
31.22,249.75,0.088
31.24,249.66,0.000
31.27,249.54,-0.091
31.29,249.40,-0.173
31.31,249.24,-0.239
31.33,249.06,-0.293
31.35,248.88,-0.335
31.38,248.69,-0.368
31.40,248.50,-0.390
31.42,248.30,-0.409
31.44,248.10,-0.424
31.46,247.90,-0.435
31.48,247.69,-0.443
31.51,247.49,-0.450
31.53,247.28,-0.456
31.55,247.07,-0.459
31.57,246.86,-0.462
31.59,246.65,-0.467
31.61,246.43,-0.468
31.63,246.22,-0.469
31.66,246.01,-0.470
31.68,245.80,-0.471
31.70,245.58,-0.471
31.72,245.37,-0.472
31.74,245.16,-0.472
31.77,244.94,-0.472
31.79,244.73,-0.473
31.81,244.52,-0.473
31.83,244.30,-0.473
31.85,244.09,-0.473
31.87,243.88,-0.473
31.89,243.66,-0.473
31.92,243.45,-0.473
31.94,243.23,-0.473
31.96,243.02,-0.473
31.98,242.80,-0.473
32.00,242.59,-0.473
32.03,242.37,-0.473
32.05,242.16,-0.473
32.07,241.94,-0.473
32.09,241.73,-0.473
32.11,241.51,-0.473
32.13,241.30,-0.473
32.16,241.08,-0.472
32.18,240.87,-0.472
32.20,240.65,-0.472
32.22,240.44,-0.472
32.24,240.22,-0.472
32.26,240.01,-0.471
32.28,239.79,-0.471
32.31,239.58,-0.471
32.33,239.36,-0.470
32.35,239.14,-0.470
32.37,238.93,-0.470
32.39,238.71,-0.470
32.42,238.50,-0.469
32.44,238.28,-0.469
32.46,238.07,-0.469
32.48,237.85,-0.468
32.50,237.63,-0.468
32.52,237.42,-0.468
32.54,237.20,-0.467
32.57,236.99,-0.467
32.59,236.77,-0.467
32.61,236.56,-0.466
32.63,236.34,-0.466
32.65,236.12,-0.466
32.68,235.91,-0.465
32.70,235.69,-0.465
32.72,235.47,-0.465
32.74,235.26,-0.464
32.76,235.04,-0.464
32.78,234.83,-0.464
32.81,234.61,-0.463
32.83,234.39,-0.463
32.85,234.18,-0.463
32.87,233.96,-0.463
32.89,233.75,-0.462
32.91,233.53,-0.462
32.93,233.31,-0.461
32.96,233.10,-0.461
32.98,232.88,-0.460
33.00,232.67,-0.460
33.02,232.45,-0.460
33.04,232.23,-0.460
33.07,232.02,-0.459
33.09,231.80,-0.459
33.11,231.58,-0.459
33.13,231.37,-0.458
33.15,231.15,-0.458
33.17,230.93,-0.458
33.19,230.72,-0.458
33.22,230.50,-0.458
33.24,230.28,-0.457
33.26,230.07,-0.457
33.28,229.85,-0.457
33.30,229.64,-0.456
33.33,229.42,-0.456
33.35,229.21,-0.456
33.37,228.99,-0.455
33.39,228.77,-0.455
33.41,228.56,-0.455
33.43,228.34,-0.455
33.46,228.12,-0.454
33.48,227.91,-0.454
33.50,227.69,-0.454
33.52,227.47,-0.454
33.54,227.26,-0.453
33.56,227.04,-0.453
33.58,226.82,-0.453
33.61,226.61,-0.453
33.63,226.39,-0.453
33.65,226.17,-0.452
33.67,225.96,-0.452
33.69,225.74,-0.452
33.72,225.53,-0.452
33.74,225.31,-0.451
33.76,225.09,-0.451
33.78,224.88,-0.451
33.80,224.66,-0.451
33.82,224.44,-0.451
33.84,224.23,-0.450
33.87,224.01,-0.450
33.89,223.79,-0.450
33.91,223.58,-0.450
33.93,223.36,-0.450
33.95,223.15,-0.449
33.98,222.93,-0.449
34.00,222.71,-0.449
34.02,222.50,-0.449
34.04,222.28,-0.449
34.06,222.07,-0.448
34.08,221.85,-0.448
34.11,221.63,-0.448
34.13,221.42,-0.448
34.15,221.20,-0.448
34.17,220.98,-0.448
34.19,220.77,-0.447
34.21,220.55,-0.447
34.24,220.33,-0.447
34.26,220.12,-0.447
34.28,219.90,-0.447
34.30,219.68,-0.446
34.32,219.47,-0.446
34.34,219.25,-0.446
34.36,219.03,-0.446
34.39,218.82,-0.446
34.41,218.60,-0.446
34.43,218.38,-0.446
34.45,218.17,-0.446
34.47,217.95,-0.445
34.49,217.73,-0.445
34.52,217.52,-0.445
34.54,217.30,-0.445
34.56,217.09,-0.445
34.58,216.87,-0.444
34.60,216.65,-0.444
34.63,216.44,-0.444
34.65,216.22,-0.444
34.67,216.00,-0.444
34.69,215.79,-0.444
34.71,215.57,-0.443
34.73,215.35,-0.443
34.76,215.14,-0.443
34.78,214.92,-0.443
34.80,214.71,-0.443
34.82,214.49,-0.443
34.84,214.27,-0.443
34.86,214.06,-0.443
34.89,213.84,-0.442
34.91,213.62,-0.442
34.93,213.41,-0.442
34.95,213.19,-0.442
34.97,212.97,-0.442
34.99,212.76,-0.442
35.01,212.54,-0.441
35.04,212.33,-0.441
35.06,212.11,-0.441
35.08,211.89,-0.441
35.10,211.68,-0.441
35.12,211.46,-0.441
35.14,211.24,-0.440
35.17,211.03,-0.440
35.19,210.81,-0.440
35.21,210.59,-0.440
35.23,210.38,-0.440
35.25,210.16,-0.440
35.28,209.95,-0.440
35.30,209.73,-0.440
35.32,209.51,-0.440
35.34,209.30,-0.440
35.36,209.08,-0.440
35.38,208.86,-0.440
35.41,208.65,-0.440
35.43,208.43,-0.439
35.45,208.21,-0.439
35.47,208.00,-0.439
35.49,207.78,-0.439
35.51,207.56,-0.439
35.54,207.35,-0.439
35.56,207.13,-0.439
35.58,206.92,-0.439
35.60,206.70,-0.439
35.62,206.48,-0.438
35.64,206.27,-0.438
35.66,206.05,-0.438
35.69,205.83,-0.438
35.71,205.62,-0.438
35.73,205.40,-0.438
35.75,205.18,-0.438
35.77,204.97,-0.438
35.79,204.75,-0.438
35.82,204.54,-0.437
35.84,204.32,-0.437
35.86,204.10,-0.437
35.88,203.88,-0.437
35.90,203.67,-0.437
35.93,203.45,-0.437
35.95,203.24,-0.437
35.97,203.02,-0.437
35.99,202.80,-0.437
36.01,202.59,-0.437
36.03,202.37,-0.437
36.06,202.15,-0.437
36.08,201.94,-0.437
36.10,201.72,-0.436
36.12,201.51,-0.436
36.14,201.29,-0.436
36.16,201.07,-0.436
36.19,200.85,-0.436
36.21,200.64,-0.436
36.23,200.42,-0.436
36.25,200.20,-0.436
36.27,199.99,-0.436
36.29,199.77,-0.436
36.31,199.56,-0.436
36.34,199.34,-0.436
36.36,199.13,-0.435
36.38,198.91,-0.435
36.40,198.69,-0.435
36.42,198.48,-0.435
36.44,198.26,-0.435
36.47,198.04,-0.435
36.49,197.83,-0.435
36.51,197.61,-0.435
36.53,197.39,-0.435
36.55,197.18,-0.435
36.58,196.96,-0.435
36.60,196.74,-0.435
36.62,196.53,-0.434
36.64,196.31,-0.434
36.66,196.09,-0.434
36.68,195.88,-0.434
36.71,195.66,-0.434
36.73,195.44,-0.434
36.75,195.23,-0.434
36.77,195.01,-0.434
36.79,194.80,-0.434
36.81,194.58,-0.434
36.84,194.36,-0.434
36.86,194.15,-0.434
36.88,193.93,-0.434
36.90,193.71,-0.434
36.92,193.50,-0.434
36.94,193.28,-0.433
36.96,193.06,-0.433
36.99,192.85,-0.433
37.01,192.63,-0.433
37.03,192.42,-0.433
37.05,192.20,-0.433
37.07,191.98,-0.433
37.09,191.77,-0.433
37.12,191.55,-0.433
37.14,191.33,-0.433
37.16,191.12,-0.433
37.18,190.90,-0.433
37.20,190.69,-0.432
37.23,190.47,-0.432
37.25,190.25,-0.432
37.27,190.04,-0.432
37.29,189.82,-0.432
37.31,189.60,-0.432
37.33,189.39,-0.432
37.36,189.17,-0.432
37.38,188.95,-0.432
37.40,188.74,-0.432
37.42,188.52,-0.432
37.44,188.30,-0.432
37.46,188.09,-0.432
37.49,187.87,-0.432
37.51,187.65,-0.432
37.53,187.44,-0.432
37.55,187.22,-0.432
37.57,187.00,-0.431
37.59,186.79,-0.431
37.61,186.57,-0.431
37.64,186.36,-0.431
37.66,186.14,-0.431
37.68,185.92,-0.431
37.70,185.71,-0.431
37.72,185.49,-0.431
37.74,185.27,-0.431
37.77,185.06,-0.431
37.79,184.84,-0.431
37.81,184.62,-0.431
37.83,184.41,-0.431
37.85,184.19,-0.430
37.88,183.97,-0.430
37.90,183.76,-0.430
37.92,183.54,-0.430
37.94,183.33,-0.430
37.96,183.11,-0.430
37.98,182.89,-0.430
38.01,182.68,-0.430
38.03,182.46,-0.430
38.05,182.24,-0.430
38.07,182.03,-0.430
38.09,181.81,-0.430
38.11,181.60,-0.430
38.14,181.38,-0.430
38.16,181.16,-0.430
38.18,180.95,-0.429
38.20,180.73,-0.429
38.22,180.51,-0.429
38.24,180.30,-0.429
38.26,180.08,-0.429
38.29,179.86,-0.429
38.31,179.65,-0.429
38.33,179.43,-0.429
38.35,179.21,-0.429
38.37,179.00,-0.429
38.39,178.78,-0.429
38.42,178.57,-0.429
38.44,178.35,-0.429
38.46,178.13,-0.429
38.48,177.92,-0.429
38.50,177.70,-0.429
38.53,177.48,-0.428
38.55,177.27,-0.428
38.57,177.05,-0.428
38.59,176.83,-0.428
38.61,176.62,-0.428
38.63,176.40,-0.428
38.66,176.18,-0.428
38.68,175.97,-0.428
38.70,175.75,-0.428
38.72,175.54,-0.428
38.74,175.32,-0.428
38.76,175.10,-0.428
38.79,174.89,-0.428
38.81,174.67,-0.428
38.83,174.45,-0.428
38.85,174.24,-0.428
38.87,174.02,-0.428
38.89,173.80,-0.428
38.91,173.59,-0.427
38.94,173.37,-0.427
38.96,173.15,-0.427
38.98,172.94,-0.427
39.00,172.72,-0.427
39.02,172.50,-0.427
39.04,172.29,-0.427
39.07,172.07,-0.427
39.09,171.85,-0.427
39.11,171.64,-0.427
39.13,171.42,-0.427
39.15,171.21,-0.427
39.18,170.99,-0.427
39.20,170.77,-0.426
39.22,170.56,-0.426
39.24,170.34,-0.426
39.26,170.12,-0.426
[...]
135.20,28.33,0.299
135.22,28.55,0.299
135.24,28.76,0.299
135.26,28.98,0.299
135.29,29.20,0.299
135.31,29.41,0.299
135.33,29.63,0.300
135.35,29.85,0.300
135.37,30.07,0.300
135.39,30.28,0.300
135.41,30.50,0.300
135.44,30.72,0.300
135.46,30.94,0.300
135.48,31.15,0.301
135.50,31.37,0.301
135.52,31.59,0.301
135.55,31.80,0.301
135.57,32.02,0.301
135.59,32.24,0.301
135.61,32.45,0.301
135.63,32.67,0.301
135.65,32.89,0.302
135.68,33.10,0.302
135.70,33.32,0.302
135.72,33.54,0.302
135.74,33.75,0.302
135.76,33.97,0.302
135.78,34.19,0.302
135.80,34.41,0.303
135.83,34.62,0.303
135.85,34.84,0.303
135.87,35.05,0.303
135.89,35.27,0.303
135.91,35.49,0.303
135.94,35.70,0.303
135.96,35.92,0.303
135.98,36.14,0.304
136.00,36.36,0.304
136.02,36.57,0.304
136.04,36.79,0.304
136.06,37.01,0.304
136.09,37.22,0.304
136.11,37.44,0.304
136.13,37.66,0.305
136.15,37.87,0.305
136.17,38.09,0.305
136.20,38.31,0.305
136.22,38.53,0.305
136.24,38.74,0.305
136.26,38.96,0.305
136.28,39.18,0.305
136.30,39.39,0.306
136.33,39.61,0.306
136.35,39.83,0.306
136.37,40.04,0.306
136.39,40.26,0.306
136.41,40.48,0.306
136.43,40.70,0.306
136.45,40.91,0.306
136.48,41.13,0.307
136.50,41.35,0.307
136.52,41.56,0.307
136.54,41.78,0.307
136.56,42.00,0.307
136.58,42.21,0.307
136.61,42.43,0.307
136.63,42.65,0.307
136.65,42.86,0.308
136.67,43.08,0.308
136.69,43.30,0.308
136.72,43.51,0.308
136.74,43.73,0.308
136.76,43.95,0.308
136.78,44.17,0.308
136.80,44.38,0.308
136.82,44.60,0.309
136.85,44.82,0.309
136.87,45.03,0.309
136.89,45.25,0.309
136.91,45.47,0.309
136.93,45.68,0.309
136.95,45.90,0.309
136.98,46.12,0.309
137.00,46.33,0.310
137.02,46.55,0.310
137.04,46.77,0.310
137.06,46.99,0.310
137.08,47.20,0.310
137.10,47.42,0.310
137.13,47.64,0.311
137.15,47.85,0.311
137.17,48.07,0.311
137.19,48.29,0.311
137.21,48.50,0.311
137.23,48.72,0.311
137.26,48.94,0.311
137.28,49.15,0.311
137.30,49.37,0.312
137.32,49.59,0.312
137.34,49.80,0.312
137.37,50.02,0.312
137.39,50.24,0.312
137.41,50.46,0.312
137.43,50.67,0.312
137.45,50.89,0.312
137.47,51.11,0.313
137.50,51.32,0.313
137.52,51.54,0.313
137.54,51.76,0.313
137.56,51.97,0.313
137.58,52.19,0.313
137.60,52.41,0.313
137.63,52.62,0.313
137.65,52.84,0.314
137.67,53.06,0.314
137.69,53.27,0.314
137.71,53.49,0.314
137.73,53.71,0.314
137.75,53.92,0.314
137.78,54.14,0.314
137.80,54.36,0.314
137.82,54.58,0.314
137.84,54.79,0.314
137.86,55.01,0.315
137.88,55.23,0.315
137.91,55.44,0.315
137.93,55.66,0.315
137.95,55.88,0.315
137.97,56.09,0.315
137.99,56.31,0.315
138.02,56.53,0.315
138.04,56.75,0.315
138.06,56.96,0.316
138.08,57.18,0.316
138.10,57.40,0.316
138.12,57.61,0.316
138.15,57.83,0.316
138.17,58.05,0.316
138.19,58.26,0.316
138.21,58.48,0.316
138.23,58.70,0.317
138.25,58.92,0.317
138.28,59.13,0.317
138.30,59.35,0.317
138.32,59.57,0.317
138.34,59.78,0.317
138.36,60.00,0.317
138.38,60.22,0.317
138.40,60.43,0.317
138.43,60.65,0.317
138.45,60.87,0.317
138.47,61.08,0.318
138.49,61.30,0.318
138.51,61.52,0.318
138.53,61.73,0.318
138.56,61.95,0.318
138.58,62.17,0.318
138.60,62.39,0.318
138.62,62.60,0.318
138.64,62.82,0.318
138.67,63.04,0.318
138.69,63.25,0.318
138.71,63.47,0.318
138.73,63.69,0.318
138.75,63.90,0.319
138.77,64.12,0.319
138.80,64.34,0.319
138.82,64.56,0.319
138.84,64.77,0.319
138.86,64.99,0.319
138.88,65.21,0.319
138.90,65.42,0.319
138.93,65.64,0.319
138.95,65.86,0.319
138.97,66.07,0.319
138.99,66.29,0.319
139.01,66.51,0.319
139.03,66.72,0.319
139.05,66.94,0.319
139.08,67.16,0.320
139.10,67.37,0.320
139.12,67.59,0.320
139.14,67.81,0.320
139.16,68.02,0.320
139.18,68.24,0.320
139.21,68.46,0.320
139.23,68.68,0.320
139.25,68.89,0.320
139.27,69.11,0.320
139.29,69.33,0.320
139.32,69.54,0.320
139.34,69.76,0.320
139.36,69.98,0.320
139.38,70.19,0.320
139.40,70.41,0.320
139.42,70.63,0.320
139.45,70.84,0.320
139.47,71.06,0.320
139.49,71.28,0.320
139.51,71.50,0.320
139.53,71.71,0.320
139.55,71.93,0.320
139.58,72.15,0.320
139.60,72.36,0.320
139.62,72.58,0.320
139.64,72.80,0.320
139.66,73.02,0.321
139.68,73.23,0.320
139.70,73.45,0.320
139.73,73.67,0.320
139.75,73.88,0.320
139.77,74.10,0.320
139.79,74.32,0.320
139.81,74.53,0.320
139.83,74.75,0.321
139.86,74.97,0.321
139.88,75.18,0.321
139.90,75.40,0.321
139.92,75.62,0.320
139.94,75.83,0.321
139.97,76.05,0.321
139.99,76.27,0.321
140.01,76.48,0.321
140.03,76.70,0.321
140.05,76.92,0.321
140.07,77.14,0.321
140.10,77.35,0.321
140.12,77.57,0.321
140.14,77.79,0.321
140.16,78.00,0.321
140.18,78.22,0.321
140.20,78.44,0.321
140.23,78.65,0.321
140.25,78.87,0.322
140.27,79.09,0.322
140.29,79.31,0.322
140.31,79.52,0.322
140.33,79.74,0.322
140.35,79.95,0.322
140.38,80.17,0.322
140.40,80.39,0.322
140.42,80.61,0.322
140.44,80.82,0.322
140.46,81.04,0.322
140.48,81.26,0.323
140.51,81.47,0.323
140.53,81.69,0.323
140.55,81.91,0.323
140.57,82.12,0.323
140.59,82.34,0.323
140.62,82.56,0.323
140.64,82.77,0.323
140.66,82.99,0.323
140.68,83.21,0.324
140.70,83.42,0.324
140.72,83.64,0.324
140.75,83.86,0.324
140.77,84.08,0.324
140.79,84.29,0.324
140.81,84.51,0.325
140.83,84.73,0.325
140.85,84.94,0.325
140.88,85.16,0.325
140.90,85.38,0.325
140.92,85.59,0.325
140.94,85.81,0.326
140.96,86.03,0.326
140.98,86.24,0.326
141.00,86.46,0.326
141.03,86.68,0.326
141.05,86.89,0.327
141.07,87.11,0.327
141.09,87.33,0.327
141.11,87.54,0.327
141.13,87.76,0.328
141.16,87.98,0.328
141.18,88.19,0.328
141.20,88.41,0.329
141.22,88.63,0.329
141.24,88.84,0.329
141.27,89.06,0.329
141.29,89.28,0.330
141.31,89.49,0.330
141.33,89.71,0.330
141.35,89.93,0.331
141.37,90.15,0.331
141.40,90.36,0.331
141.42,90.58,0.332
141.44,90.80,0.332
141.46,91.01,0.332
141.48,91.23,0.333
141.50,91.44,0.333
141.53,91.66,0.333
141.55,91.88,0.334
141.57,92.10,0.334
141.59,92.31,0.334
141.61,92.53,0.335
141.63,92.75,0.335
141.65,92.96,0.335
141.68,93.18,0.336
141.70,93.40,0.336
141.72,93.61,0.336
141.74,93.83,0.337
141.76,94.05,0.337
141.78,94.26,0.337
141.81,94.48,0.338
141.83,94.70,0.338
141.85,94.91,0.339
141.87,95.13,0.339
141.89,95.35,0.340
141.92,95.56,0.340
141.94,95.78,0.340
141.96,96.00,0.341
141.98,96.21,0.341
142.00,96.43,0.341
142.02,96.65,0.341
142.05,96.86,0.342
142.07,97.08,0.342
142.09,97.30,0.342
142.11,97.52,0.343
142.13,97.73,0.343
142.15,97.95,0.343
142.18,98.17,0.344
142.20,98.38,0.344
142.22,98.60,0.344
142.24,98.82,0.345
142.26,99.03,0.345
142.28,99.25,0.345
142.30,99.47,0.346
142.33,99.68,0.346
142.35,99.90,0.346
142.37,100.12,0.346
142.39,100.33,0.347
142.41,100.55,0.347
142.43,100.77,0.347
142.46,100.99,0.347
142.48,101.20,0.348
142.50,101.42,0.348
142.52,101.64,0.348
142.54,101.85,0.348
142.57,102.07,0.349
142.59,102.29,0.349
142.61,102.50,0.349
142.63,102.72,0.349
142.65,102.94,0.349
142.67,103.15,0.350
142.70,103.37,0.350
142.72,103.59,0.350
142.74,103.80,0.350
142.76,104.02,0.351
142.78,104.24,0.351
142.80,104.45,0.351
142.83,104.67,0.351
142.85,104.89,0.351
142.87,105.10,0.352
142.89,105.32,0.352
142.91,105.54,0.352
142.93,105.75,0.352
142.95,105.97,0.352
142.98,106.19,0.353
143.00,106.40,0.353
143.02,106.62,0.353
143.04,106.84,0.353
143.06,107.05,0.353
143.08,107.27,0.354
143.11,107.49,0.354
143.13,107.71,0.354
143.15,107.92,0.354
143.17,108.14,0.355
143.19,108.36,0.355
143.22,108.57,0.355
143.24,108.79,0.355
143.26,109.01,0.355
143.28,109.22,0.356
143.30,109.44,0.356
143.32,109.66,0.356
143.35,109.87,0.356
143.37,110.09,0.356
143.39,110.31,0.357
143.41,110.53,0.357
143.43,110.74,0.357
143.45,110.96,0.357
143.48,111.17,0.357
143.50,111.39,0.358
143.52,111.61,0.358
143.54,111.83,0.358
143.56,112.04,0.358
143.58,112.26,0.358
143.60,112.48,0.359
143.63,112.69,0.359
143.65,112.91,0.359
143.67,113.13,0.359
143.69,113.34,0.359
143.71,113.56,0.360
143.73,113.78,0.360
143.76,113.99,0.360
143.78,114.21,0.360
143.80,114.43,0.360
143.82,114.64,0.360
143.84,114.86,0.360
143.87,115.08,0.361
143.89,115.30,0.361
143.91,115.51,0.361
143.93,115.73,0.361
143.95,115.95,0.361
143.97,116.16,0.361
144.00,116.38,0.362
144.02,116.60,0.362
144.04,116.81,0.362
144.06,117.03,0.362
144.08,117.25,0.362
144.10,117.46,0.362
144.13,117.68,0.363
144.15,117.90,0.363
144.17,118.11,0.363
144.19,118.33,0.363
144.21,118.55,0.363
144.23,118.76,0.363
144.25,118.98,0.364
144.28,119.20,0.364
144.30,119.41,0.364
144.32,119.63,0.364
144.34,119.85,0.364
144.36,120.06,0.365
144.38,120.28,0.365
144.41,120.50,0.365
144.43,120.71,0.365
144.45,120.93,0.366
144.47,121.15,0.366
144.49,121.37,0.366
144.52,121.58,0.366
144.54,121.80,0.366
144.56,122.02,0.367
144.58,122.23,0.367
144.60,122.45,0.367
144.62,122.67,0.367
144.65,122.88,0.368
144.67,123.10,0.368
144.69,123.32,0.368
144.71,123.54,0.368
144.73,123.75,0.369
144.75,123.97,0.369
144.78,124.18,0.369
144.80,124.40,0.369
144.82,124.62,0.370
144.84,124.84,0.370
144.86,125.05,0.370
144.88,125.27,0.370
144.90,125.49,0.371
144.93,125.70,0.371
144.95,125.92,0.371
144.97,126.13,0.371
144.99,126.35,0.372
145.01,126.57,0.372
145.03,126.78,0.372
145.06,127.00,0.372
145.08,127.22,0.373
145.10,127.44,0.373
145.12,127.65,0.373
145.14,127.87,0.374
145.17,128.08,0.374
145.19,128.30,0.374
145.21,128.52,0.374
145.23,128.74,0.375
145.25,128.95,0.375
145.27,129.17,0.376
145.30,129.39,0.376
145.32,129.60,0.376
145.34,129.82,0.376
145.36,130.04,0.377
145.38,130.25,0.377
145.40,130.47,0.377
145.43,130.69,0.377
145.45,130.90,0.378
145.47,131.12,0.378
145.49,131.34,0.379
145.51,131.55,0.379
145.53,131.77,0.379
145.55,131.99,0.379
145.58,132.20,0.380
145.60,132.42,0.380
145.62,132.64,0.380
145.64,132.86,0.380
145.66,133.07,0.381
145.68,133.29,0.381
145.71,133.50,0.381
145.73,133.72,0.382
145.75,133.94,0.382
145.77,134.16,0.382
145.79,134.37,0.382
145.82,134.59,0.383
145.84,134.80,0.383
145.86,135.02,0.383
145.88,135.24,0.384
145.90,135.45,0.384
145.92,135.67,0.384
145.95,135.89,0.385
145.97,136.10,0.385
145.99,136.32,0.385
146.01,136.54,0.385
146.03,136.76,0.386
146.05,136.97,0.386
146.08,137.19,0.386
146.10,137.41,0.387
146.12,137.62,0.387
146.14,137.84,0.387
146.16,138.06,0.388
146.18,138.27,0.388
146.20,138.49,0.388
146.23,138.71,0.389
146.25,138.92,0.389
146.27,139.14,0.389
146.29,139.36,0.389
146.31,139.57,0.390
146.33,139.79,0.390
146.36,140.01,0.390
146.38,140.22,0.391
146.40,140.44,0.391
146.42,140.66,0.391
146.44,140.87,0.392
146.47,141.09,0.392
146.49,141.31,0.392
146.51,141.52,0.393
146.53,141.74,0.393
146.55,141.96,0.393
146.57,142.18,0.394
146.60,142.39,0.394
146.62,142.61,0.394
146.64,142.83,0.395
146.66,143.04,0.395
146.68,143.26,0.395
146.70,143.47,0.396
146.73,143.69,0.396
146.75,143.91,0.396
146.77,144.13,0.397
146.79,144.34,0.397
146.81,144.56,0.397
146.83,144.77,0.398
146.85,144.99,0.398
146.88,145.21,0.398
146.90,145.43,0.398
146.92,145.64,0.399
146.94,145.86,0.399
146.96,146.08,0.400
146.98,146.29,0.400
147.01,146.51,0.400
147.03,146.73,0.401
147.05,146.94,0.401
147.07,147.16,0.401
147.09,147.38,0.402
147.12,147.59,0.402
147.14,147.81,0.402
147.16,148.03,0.402
147.18,148.24,0.403
147.20,148.46,0.403
147.22,148.68,0.404
147.25,148.89,0.404
147.27,149.11,0.404
147.29,149.33,0.405
147.31,149.54,0.405
147.33,149.76,0.405
147.35,149.98,0.406
147.38,150.19,0.406
147.40,150.41,0.406
147.42,150.63,0.407
147.44,150.84,0.407
147.46,151.06,0.407
147.48,151.28,0.408
147.50,151.49,0.408
147.53,151.71,0.409
147.55,151.93,0.409
147.57,152.14,0.409
147.59,152.36,0.410
147.61,152.58,0.410
147.63,152.79,0.411
147.66,153.01,0.411
147.68,153.23,0.412
147.70,153.44,0.413
147.72,153.66,0.413
147.74,153.88,0.413
147.77,154.09,0.413
147.79,154.31,0.414
147.81,154.53,0.414
147.83,154.74,0.415
147.85,154.96,0.415
147.87,155.18,0.416
147.90,155.39,0.416
147.92,155.61,0.417
147.94,155.83,0.417
147.96,156.04,0.417
147.98,156.26,0.418
148.00,156.48,0.418
148.03,156.70,0.418
148.05,156.91,0.419
148.07,157.13,0.419
148.09,157.34,0.420
148.11,157.56,0.420
148.13,157.78,0.420
148.15,157.99,0.421
148.18,158.21,0.421
148.20,158.43,0.422
148.22,158.65,0.422
148.24,158.86,0.422
148.26,159.08,0.423
148.28,159.30,0.423
148.31,159.51,0.424
148.33,159.73,0.424
148.35,159.94,0.425
148.37,160.16,0.425
148.39,160.38,0.425
148.42,160.60,0.426
148.44,160.81,0.426
148.46,161.03,0.427
148.48,161.24,0.427
148.50,161.46,0.428
148.52,161.68,0.428
148.55,161.89,0.428
148.57,162.11,0.429
148.59,162.33,0.429
148.61,162.54,0.430
148.63,162.76,0.430
148.65,162.98,0.431
148.68,163.20,0.431
148.70,163.41,0.432
148.72,163.63,0.432
148.74,163.85,0.432
148.76,164.06,0.432
148.78,164.28,0.433
148.80,164.49,0.433
148.83,164.71,0.434
148.85,164.93,0.434
148.87,165.15,0.434
148.89,165.36,0.435
148.91,165.58,0.435
148.93,165.80,0.435
148.96,166.01,0.436
148.98,166.23,0.436
149.00,166.45,0.436
149.02,166.66,0.437
149.04,166.88,0.437
149.07,167.10,0.437
149.09,167.31,0.437
149.11,167.53,0.438
149.13,167.75,0.438
149.15,167.96,0.438
149.17,168.18,0.438
149.20,168.40,0.439
149.22,168.62,0.439
149.24,168.83,0.439
149.26,169.05,0.439
149.28,169.27,0.439
149.30,169.48,0.440
149.33,169.70,0.440
149.35,169.92,0.440
149.37,170.13,0.439
149.39,170.35,0.439
149.41,170.57,0.439
149.43,170.78,0.439
149.45,171.00,0.438
149.48,171.22,0.438
149.50,171.44,0.438
149.52,171.65,0.437
149.54,171.87,0.437
149.56,172.09,0.436
149.58,172.30,0.436
149.61,172.52,0.435
149.63,172.74,0.435
149.65,172.95,0.434
149.67,173.17,0.434
149.69,173.39,0.433
149.72,173.61,0.432
149.74,173.82,0.431
149.76,174.04,0.431
149.78,174.26,0.430
149.80,174.47,0.429
149.82,174.69,0.428
149.85,174.91,0.427
149.87,175.12,0.427
149.89,175.34,0.425
149.91,175.56,0.424
149.93,175.78,0.423
149.95,175.99,0.422
149.98,176.21,0.422
150.00,176.43,0.421
150.02,176.64,0.420
150.04,176.86,0.420
150.06,177.08,0.419
150.08,177.30,0.418
150.10,177.51,0.418
150.13,177.73,0.417
150.15,177.95,0.417
150.17,178.16,0.416
150.19,178.38,0.415
150.21,178.60,0.414
150.23,178.82,0.414
150.26,179.03,0.413
150.28,179.25,0.412
150.30,179.47,0.411
150.32,179.68,0.410
150.34,179.90,0.410
150.37,180.12,0.409
150.39,180.34,0.407
150.41,180.55,0.407
150.43,180.77,0.406
150.45,180.99,0.405
150.47,181.20,0.404
150.50,181.42,0.403
150.52,181.64,0.403
150.54,181.85,0.402
150.56,182.07,0.401
150.58,182.29,0.400
150.60,182.51,0.399
150.63,182.72,0.398
150.65,182.94,0.398
150.67,183.16,0.397
150.69,183.37,0.397
150.71,183.59,0.396
150.73,183.81,0.395
150.75,184.03,0.395
150.78,184.24,0.394
150.80,184.46,0.393
150.82,184.68,0.393
150.84,184.89,0.392
150.86,185.11,0.391
150.88,185.33,0.391
150.91,185.54,0.390
150.93,185.76,0.390
150.95,185.98,0.389
150.97,186.19,0.389
150.99,186.41,0.388
151.02,186.63,0.388
151.04,186.85,0.388
151.06,187.06,0.387
151.08,187.28,0.387
151.10,187.50,0.387
151.12,187.71,0.386
151.15,187.93,0.386
151.17,188.15,0.386
151.19,188.36,0.385
151.21,188.58,0.385
151.23,188.80,0.385
151.25,189.01,0.385
151.28,189.23,0.385
151.30,189.45,0.384
151.32,189.66,0.384
151.34,189.88,0.384
151.36,190.10,0.384
151.38,190.31,0.384
151.40,190.53,0.384
151.43,190.75,0.384
151.45,190.96,0.384
151.47,191.18,0.384
151.49,191.40,0.384
151.51,191.61,0.384
151.53,191.83,0.384
151.56,192.05,0.384
151.58,192.27,0.384
151.60,192.48,0.384
151.62,192.70,0.384
151.64,192.92,0.384
151.67,193.13,0.384
151.69,193.35,0.384
151.71,193.57,0.384
151.73,193.78,0.384
151.75,194.00,0.384
151.77,194.22,0.384
151.80,194.43,0.384
151.82,194.65,0.384
151.84,194.87,0.384
151.86,195.08,0.384
151.88,195.30,0.384
151.90,195.52,0.384
151.93,195.74,0.384
151.95,195.95,0.385
151.97,196.17,0.385
151.99,196.39,0.385
152.01,196.60,0.385
152.03,196.82,0.385
152.05,197.03,0.385
152.08,197.25,0.385
152.10,197.47,0.385
152.12,197.69,0.385
152.14,197.90,0.385
152.16,198.12,0.385
152.18,198.34,0.385
152.21,198.55,0.385
152.23,198.77,0.386
152.25,198.99,0.386
152.27,199.20,0.386
152.29,199.42,0.386
152.32,199.64,0.386
152.34,199.85,0.386
152.36,200.07,0.386
152.38,200.29,0.386
152.40,200.50,0.386
152.42,200.72,0.386
152.45,200.94,0.386
152.47,201.15,0.386
152.49,201.37,0.386
152.51,201.59,0.386
152.53,201.80,0.386
152.55,202.02,0.387
152.58,202.24,0.387
152.60,202.45,0.387
152.62,202.67,0.387
152.64,202.89,0.387
152.66,203.10,0.387
152.68,203.32,0.387
152.70,203.54,0.387
152.73,203.75,0.387
152.75,203.97,0.387
152.77,204.19,0.387
152.79,204.40,0.388
152.81,204.62,0.388
152.83,204.84,0.388
152.86,205.06,0.388
152.88,205.27,0.388
152.90,205.49,0.388
152.92,205.71,0.388
152.94,205.92,0.388
152.97,206.14,0.388
152.99,206.36,0.388
153.01,206.57,0.388
153.03,206.79,0.388
153.05,207.01,0.389
153.07,207.22,0.389
153.10,207.44,0.389
153.12,207.66,0.389
153.14,207.87,0.389
153.16,208.09,0.389
153.18,208.31,0.389
153.20,208.52,0.389
153.23,208.74,0.389
153.25,208.96,0.389
153.27,209.17,0.389
153.29,209.39,0.389
153.31,209.61,0.389
153.33,209.82,0.390
153.35,210.04,0.390
153.38,210.26,0.390
153.40,210.47,0.390
153.42,210.69,0.390
153.44,210.91,0.390
153.46,211.13,0.390
153.48,211.34,0.390
153.51,211.56,0.390
153.53,211.78,0.390
153.55,211.99,0.390
153.57,212.21,0.390
153.59,212.43,0.390
153.62,212.64,0.390
153.64,212.86,0.390
153.66,213.08,0.391
153.68,213.29,0.391
153.70,213.51,0.391
153.72,213.73,0.391
153.75,213.94,0.391
153.77,214.16,0.391
153.79,214.38,0.391
153.81,214.59,0.391
153.83,214.81,0.391
153.85,215.03,0.391
153.88,215.25,0.391
153.90,215.46,0.392
153.92,215.68,0.392
153.94,215.89,0.392
153.96,216.11,0.392
153.98,216.33,0.392
154.00,216.54,0.392
154.03,216.76,0.392
154.05,216.98,0.392
154.07,217.20,0.392
154.09,217.41,0.392
154.11,217.63,0.392
154.13,217.85,0.392
154.16,218.06,0.392
154.18,218.28,0.392
154.20,218.50,0.392
154.22,218.71,0.393
154.24,218.93,0.393
154.27,219.15,0.393
154.29,219.36,0.393
154.31,219.58,0.393
154.33,219.80,0.393
154.35,220.01,0.393
154.37,220.23,0.393
154.40,220.45,0.393
154.42,220.66,0.393
154.44,220.88,0.393
154.46,221.10,0.394
154.48,221.31,0.394
154.50,221.53,0.394
154.53,221.75,0.394
154.55,221.96,0.394
154.57,222.18,0.394
154.59,222.40,0.394
154.61,222.61,0.394
154.63,222.83,0.394
154.65,223.05,0.394
154.68,223.26,0.394
154.70,223.48,0.394
154.72,223.70,0.394
154.74,223.91,0.394
154.76,224.13,0.394
154.78,224.35,0.394
154.81,224.56,0.394
154.83,224.78,0.395
154.85,225.00,0.395
154.87,225.21,0.395
154.89,225.43,0.395
154.92,225.65,0.395
154.94,225.86,0.395
154.96,226.08,0.395
154.98,226.30,0.395
155.00,226.52,0.395
155.02,226.73,0.395
155.05,226.95,0.395
155.07,227.17,0.395
155.09,227.38,0.395
155.11,227.60,0.395
155.13,227.82,0.395
155.15,228.03,0.395
155.18,228.25,0.395
155.20,228.47,0.395
155.22,228.68,0.396
155.24,228.90,0.396
155.26,229.12,0.396
155.28,229.33,0.396
155.30,229.55,0.396
155.33,229.77,0.396
155.35,229.98,0.396
155.37,230.20,0.396
155.39,230.42,0.396
155.41,230.63,0.396
155.43,230.85,0.396
155.46,231.07,0.396
155.48,231.29,0.397
155.50,231.50,0.397
155.52,231.72,0.397
155.54,231.93,0.397
155.57,232.15,0.397
155.59,232.37,0.397
155.61,232.58,0.397
155.63,232.80,0.397
155.65,233.02,0.397
155.67,233.23,0.397
155.70,233.45,0.397
155.72,233.67,0.397
155.74,233.88,0.397
155.76,234.10,0.397
155.78,234.32,0.397
155.80,234.53,0.397
155.83,234.75,0.397
155.85,234.97,0.398
155.87,235.18,0.398
155.89,235.40,0.398
155.91,235.62,0.398
155.93,235.84,0.398
155.95,236.05,0.398
155.98,236.27,0.398
156.00,236.49,0.398
156.02,236.70,0.398
156.04,236.92,0.398
156.06,237.14,0.398
156.08,237.35,0.399
156.11,237.57,0.399
156.13,237.79,0.399
156.15,238.00,0.399
156.17,238.22,0.399
156.19,238.44,0.399
156.22,238.65,0.399
156.24,238.87,0.399
156.26,239.09,0.399
156.28,239.30,0.399
156.30,239.52,0.399
156.32,239.74,0.400
156.35,239.95,0.400
156.37,240.17,0.400
156.39,240.39,0.400
156.41,240.60,0.400
156.43,240.82,0.400
156.45,241.04,0.400
156.48,241.25,0.400
156.50,241.47,0.400
156.52,241.69,0.400
156.54,241.90,0.400
156.56,242.12,0.400
156.58,242.34,0.400
156.60,242.55,0.401
156.63,242.77,0.401
156.65,242.99,0.401
156.67,243.20,0.401
156.69,243.42,0.401
156.71,243.64,0.401
156.73,243.85,0.401
156.76,244.07,0.401
156.78,244.29,0.401
156.80,244.50,0.401
156.82,244.72,0.402
156.84,244.94,0.402
156.87,245.15,0.402
156.89,245.37,0.402
156.91,245.59,0.402
156.93,245.81,0.402
156.95,246.02,0.402
156.97,246.24,0.402
157.00,246.46,0.402
157.02,246.67,0.403
157.04,246.89,0.403
157.06,247.11,0.403
157.08,247.32,0.403
157.10,247.54,0.403
157.13,247.76,0.403
157.15,247.97,0.403
157.17,248.19,
157.19,248.41,
157.20,,