File: DSC/2025_06_15_THC_Sorbic_Acid_Slurry_n60C_150C_10Cmin_x3.csv
Filename,2025_06_15_THC_Sorbic_Acid_Slurry_n60C_150C_10Cmin_x3
Instrument name,DSC2A-00468 (192.168.1.100)
Operator,Yarger
rundate,6/15/2025
Sample name,2025_06_15_THC_Sorbic_Acid_Slurry_n60C_150C_10Cmin_x3
proceduresegments,Data Off ; Equilibrate -60.00 °C; Data On ; Ramp 10.00 °C/min to 150.00 °C; Data Off ; Isothermal 2.0 min; Data On ; Ramp 10.00 °C/min to -60.00 °C; Data Off ; Isothermal 2.0 min; Data On ; Ramp 10.00 °C/min to 150.00 °C; Data Off ; Isothermal 2.0 min; Data On ; Ramp 10.00 °C/min to -60.00 °C; Data Off ; Isothermal 2.0 min; Data On ; Ramp 10.00 °C/min to 30.00 °C
[File Parameters]
Run date,6/15/2025 5:22:08 AM
Trios version,5.1.1.46572
Original File Name,
Current File Name,D:\DSC2500\JYarger\2025_06_15_THC_Sorbic_Acid_Slurry_n60C_150C_10Cmin_x3.tri
[Procedure]
Procedure Name,THC_SA_n60C_150C_10Cmin_x3
Sample Name,2025_06_15_THC_Sorbic_Acid_Slurry_n60C_150C_10Cmin_x3
Sample Mass,2.08 mg
Reference Sample Mass,0 mg
Pan Mass,56.51 mg
Pan Number,36
Reference Pan Mass,57.05 mg
Reference Pan Number,28
Pan Type,Tzero Aluminum Hermetic
Comments,Al Hermetic DSC Consumables sealed Pan/Lid. A2 Tray (Google Sheet: DSC_Samples_A2_Tray_May2025)
Project Name,CA
Operator,Yarger
Test,Custom
Unload Max Temperature,30
Unload Min Temperature,30
Load Max Temperature,30
Load Min Temperature,30
Stop on Gas Flow Error,Yes
[Signal List]
Signal #1,Time (min)
Signal #2,Temperature (°C)
Signal #3,Heat Flow (mW)
Signal #4,Delta T (µV)
Signal #5,Delta Tzero (µV)
Signal #6,Tzero Temperature (°C)
Signal #7,Cell Purge (mL/min)
Signal #8,Heater Temp (°C)
Signal #9,Power Delivered (W)
Signal #10,Reference Junction Temperature (°C)
Signal #11,Flange Temperature (°C)
Signal #12,Heat Flow Phase (rad)
Signal #13,Total Heat Capacity (J/°C)
Signal #14,Heat Capacity (J/°C)
[Configuration]
Company Name,ASU
Instrument Name,DSC2A-00468
Instrument Type,DSC2500
Serial Number,DSC2A-00468
IP,192.168.1.100
Location of Instrument,MRRC
DisplayType,Unknown
Sample Interval ,0.1 s/pt
Selected Heat Flow,T4P
Exotherm Direction,Down
Cell Serial,DRC2-00792
Lid Type,Standard
Cooler,RCS 90
Leave Cooler on at End of Sequence,On
Gas 2,Nitrogen
Gas Selected,Channel 1
Flow Rate,50 mL/min
Secondary Purge,On
Licensed Heat Flow,Heat Flow T4P
Modulation Licensed,Yes
[Versions]
Common IDD Version,1
Cortex Version,VER 2.10.2.31
Driver,5.0.0.6
GDM Version,1.0.3.3
TouchscreenVersion,1.0.0.16145
FEP Version,1.2.1.21
FEP Bootloader,2.0.0.5
AutoSampler Version,2.1.1.26
Auto Sampler Bootloader,2.0.0.5
FCM Version,1.1.0.3
FCM Bootloader,2.0.0.5
[Experiment Logs]
Experiment Log Entry # 1,Data On set to 0
Experiment Log Entry # 3,Equilibrate Segment -60 (C) Started
Experiment Log Entry # 5,Air Cool is off.
Experiment Log Entry # 7,Data On set to 1
Experiment Log Entry # 9,Ramp Segment 10 C/min to 150 Started
Experiment Log Entry # 11,Data On set to 0
Experiment Log Entry # 13,Isothermal Segment 2 min started
Experiment Log Entry # 15,Data On set to 1
Experiment Log Entry # 17,Ramp Segment 10 C/min to -60 Started
Experiment Log Entry # 19,Data On set to 0
Experiment Log Entry # 21,Isothermal Segment 2 min started
Experiment Log Entry # 23,Data On set to 1
Experiment Log Entry # 25,Ramp Segment 10 C/min to 150 Started
Experiment Log Entry # 27,Data On set to 0
Experiment Log Entry # 29,Isothermal Segment 2 min started
Experiment Log Entry # 31,Data On set to 1
Experiment Log Entry # 33,Ramp Segment 10 C/min to -60 Started
Experiment Log Entry # 35,Data On set to 0
Experiment Log Entry # 37,Isothermal Segment 2 min started
Experiment Log Entry # 39,Data On set to 1
Experiment Log Entry # 41,Ramp Segment 10 C/min to 30 Started
[Method Log]
Method Log Entry # 1,Data Off
Method Log Entry # 2,Equilibrate -60 °C
Method Log Entry # 3,Data On
Method Log Entry # 4,(Ramp 301702) Ramp 10 °C/minute to 150 °C
Method Log Entry # 5,Data Off
Method Log Entry # 6,Isothermal 2 minutes
Method Log Entry # 7,Data On
Method Log Entry # 8,(Ramp 301706) Ramp 10 °C/minute to -60 °C
Method Log Entry # 9,Data Off
Method Log Entry # 10,Isothermal 2 minutes
Method Log Entry # 11,Data On
Method Log Entry # 12,(Ramp 301710) Ramp 10 °C/minute to 150 °C
Method Log Entry # 13,Data Off
Method Log Entry # 14,Isothermal 2 minutes
Method Log Entry # 15,Data On
Method Log Entry # 16,(Ramp 301714) Ramp 10 °C/minute to -60 °C
Method Log Entry # 17,Data Off
Method Log Entry # 18,Isothermal 2 minutes
Method Log Entry # 19,Data On
Method Log Entry # 20,(Ramp 301718) Ramp 10 °C/minute to 30 °C
Cell Serial,DRC2-00792
[T1 Calibration]
Slope,-0.008529666
Offset,9.636258
Initial Temperature,98.23
GUID,f8bfdadc-4977-4fdf-ba6d-0ba9134940c3
[TZero Calibration]
Date Applied,11/29/2022 4:06:13 PM
Description,From -89.059 °C to 396.009 °C at 20.000°C/min
Gas Type,Nitrogen
Pan Type,None
Source Files 1,C:\Users\yargerlab\Desktop\DSC Data\General\TZero_calibration_11_29_22_2nd(2).tri
Source Files 2,C:\Users\yargerlab\Desktop\DSC Data\General\TZero_calibration_11_29_22_2nd(3).tri
Delta T Offset,13.05235
Delta T Slope,-0.007271007
Delta T0 Offset,-13.69128
Delta T0 Slope,0.06063341
[Temperature Calibration]
Date Applied,11/29/2022 7:12:28 PM
Description,From 106.590 °C to 186.590 °C at 10.000°C/min
Gas Type,Nitrogen
Pan Type,Tzero Aluminum Hermetic
Source Files 1,C:\Users\yargerlab\Desktop\DSC Data\General\Indium(6).tri
Measured 1,157.391
Known 1,156.598
[Cell Constant Calibration]
Date Applied,11/29/2022 7:12:29 PM
Description,From 106.590 °C to 186.590 °C at 10.000°C/min
Gas Type,Nitrogen
Pan Type,Tzero Aluminum Hermetic
Source Files 1,C:\Users\yargerlab\Desktop\DSC Data\General\Indium(6).tri
T4P KCell,1.006051
Onset Slope,63.26126 mW/°C
[Direct Cp Calibration]
Date Applied,11/30/2022 11:04:51 AM
Description,From -79.983 °C to 298.409 °C at 10.000°C/min
Gas Type,Nitrogen
Pan Type,Tzero Aluminum Hermetic
Source Files 1,C:\Users\yargerlab\Desktop\DSC Data\General\Sapphire_Heat_Capacity_11_30_22.tri
[Rev Cp Calibration]
Date Applied,11/30/2022 1:58:51 PM
Description,From -79.996 °C to 292.812 °C at 3.000°C/min
Gas Type,Nitrogen
Pan Type,Tzero Aluminum Hermetic
Source Files 1,C:\Users\yargerlab\Desktop\DSC Data\General\Sapphire_MDSC_Calibration_11_30_22.tri
[step]
Ramp 10.00 °C/min to 150.00 °C
Time,Temperature,Heat Flow (Normalized)
min,°C,W/g
0.00,-59.69,-0.110
0.01,-59.70,-0.108
0.03,-59.71,-0.103
0.05,-59.71,-0.096
0.06,-59.70,-0.091
0.08,-59.68,-0.089
0.09,-59.65,-0.088
0.11,-59.61,-0.087
0.12,-59.55,-0.085
0.14,-59.48,-0.076
0.15,-59.40,-0.058
0.16,-59.30,-0.033
0.18,-59.20,-0.010
0.19,-59.10,0.017
0.21,-58.98,0.039
0.23,-58.86,0.066
0.24,-58.75,0.082
0.26,-58.62,0.104
0.27,-58.49,0.119
0.29,-58.36,0.138
0.30,-58.23,0.151
0.31,-58.10,0.164
0.33,-57.96,0.170
0.35,-57.83,0.184
0.36,-57.69,0.189
0.38,-57.55,0.197
0.39,-57.41,0.205
0.40,-57.27,0.207
0.42,-57.13,0.214
0.44,-56.99,0.216
0.45,-56.85,0.220
0.46,-56.71,0.224
0.48,-56.56,0.228
0.50,-56.42,0.230
0.51,-56.28,0.231
0.53,-56.13,0.235
0.54,-55.99,0.237
0.55,-55.84,0.238
0.57,-55.70,0.240
0.58,-55.55,0.241
0.60,-55.41,0.242
0.62,-55.26,0.243
0.63,-55.11,0.244
0.65,-54.97,0.246
0.66,-54.82,0.246
0.68,-54.68,0.248
0.69,-54.53,0.248
0.70,-54.38,0.249
0.72,-54.24,0.250
0.73,-54.09,0.250
0.75,-53.94,0.251
0.77,-53.79,0.252
0.78,-53.65,0.252
0.80,-53.50,0.253
0.81,-53.35,0.254
0.83,-53.21,0.255
0.84,-53.06,0.255
0.85,-52.91,0.256
0.87,-52.76,0.256
0.88,-52.61,0.257
0.90,-52.46,0.258
0.92,-52.32,0.258
0.93,-52.17,0.259
0.95,-52.02,0.259
0.96,-51.87,0.260
0.98,-51.72,0.260
0.99,-51.57,0.261
1.00,-51.43,0.261
1.02,-51.28,0.261
1.03,-51.13,0.262
1.05,-50.98,0.262
1.07,-50.83,0.263
1.08,-50.68,0.263
1.09,-50.53,0.263
1.11,-50.38,0.264
1.13,-50.24,0.264
1.14,-50.09,0.264
1.16,-49.94,0.265
1.17,-49.79,0.265
1.18,-49.64,0.265
1.20,-49.49,0.265
1.22,-49.34,0.265
1.23,-49.19,0.266
1.24,-49.04,0.266
1.26,-48.89,0.266
1.28,-48.74,0.266
1.29,-48.59,0.266
1.31,-48.44,0.266
1.32,-48.30,0.267
1.33,-48.15,0.267
1.35,-48.00,0.267
1.37,-47.85,0.267
1.38,-47.70,0.267
1.39,-47.55,0.267
1.41,-47.40,0.268
1.43,-47.25,0.268
1.44,-47.10,0.268
1.46,-46.95,0.268
1.47,-46.80,0.268
1.48,-46.65,0.268
1.50,-46.50,0.268
1.52,-46.35,0.269
1.53,-46.20,0.269
1.54,-46.05,0.269
1.56,-45.90,0.269
1.58,-45.75,0.269
1.59,-45.60,0.269
1.61,-45.45,0.269
1.62,-45.30,0.269
1.63,-45.15,0.269
1.65,-45.00,0.269
1.67,-44.85,0.270
1.68,-44.70,0.270
1.69,-44.55,0.270
1.71,-44.40,0.270
1.73,-44.25,0.270
1.74,-44.10,0.270
1.76,-43.95,0.270
1.77,-43.80,0.270
1.78,-43.65,0.270
1.80,-43.50,0.270
1.82,-43.35,0.270
1.83,-43.20,0.270
1.84,-43.05,0.271
1.86,-42.90,0.270
1.88,-42.75,0.270
1.89,-42.60,0.271
1.91,-42.45,0.271
1.92,-42.30,0.271
1.93,-42.15,0.271
1.95,-42.00,0.271
1.97,-41.85,0.271
1.98,-41.70,0.271
1.99,-41.55,0.271
2.01,-41.40,0.271
2.03,-41.25,0.271
2.04,-41.10,0.271
2.06,-40.95,0.271
2.07,-40.80,0.271
2.08,-40.65,0.271
2.10,-40.50,0.271
2.12,-40.35,0.271
2.13,-40.20,0.271
2.14,-40.05,0.271
2.16,-39.90,0.271
2.18,-39.75,0.271
2.19,-39.60,0.271
2.21,-39.45,0.271
2.22,-39.30,0.271
2.24,-39.15,0.271
2.25,-39.00,0.271
2.26,-38.85,0.271
2.28,-38.70,0.271
2.29,-38.55,0.271
2.31,-38.40,0.271
2.33,-38.25,0.271
2.34,-38.10,0.271
2.36,-37.95,0.271
2.37,-37.79,0.271
2.39,-37.64,0.271
2.40,-37.49,0.271
2.41,-37.34,0.271
2.43,-37.19,0.271
2.44,-37.04,0.271
2.46,-36.89,0.271
2.48,-36.74,0.271
2.49,-36.59,0.271
2.51,-36.44,0.271
2.52,-36.29,0.271
2.54,-36.14,0.271
2.55,-35.99,0.271
2.56,-35.84,0.271
2.58,-35.69,0.271
2.59,-35.54,0.271
2.61,-35.39,0.271
2.63,-35.24,0.271
2.64,-35.09,0.271
2.66,-34.94,0.271
2.67,-34.79,0.271
2.69,-34.64,0.271
2.70,-34.49,0.271
2.71,-34.34,0.271
2.73,-34.19,0.271
2.74,-34.04,0.271
2.76,-33.89,0.271
2.78,-33.74,0.271
2.79,-33.59,0.271
2.81,-33.44,0.271
2.82,-33.29,0.271
2.84,-33.14,0.271
2.85,-32.99,0.271
2.86,-32.84,0.271
2.88,-32.69,0.271
2.89,-32.54,0.271
2.91,-32.39,0.271
2.93,-32.24,0.271
2.94,-32.09,0.271
2.96,-31.94,0.271
2.97,-31.79,0.271
2.99,-31.64,0.271
3.00,-31.49,0.271
3.01,-31.34,0.271
3.03,-31.19,0.271
3.04,-31.03,0.271
3.06,-30.88,0.271
3.08,-30.73,0.271
3.09,-30.59,0.272
3.11,-30.44,0.272
3.12,-30.28,0.272
3.14,-30.13,0.272
3.15,-29.99,0.272
3.16,-29.83,0.272
3.18,-29.68,0.272
3.19,-29.53,0.272
3.21,-29.38,0.272
3.23,-29.23,0.272
3.24,-29.08,0.272
3.26,-28.93,0.272
3.27,-28.78,0.272
3.29,-28.63,0.272
3.30,-28.48,0.272
3.31,-28.33,0.272
3.33,-28.18,0.272
3.34,-28.03,0.272
3.36,-27.88,0.272
3.38,-27.73,0.272
3.39,-27.58,0.272
3.41,-27.43,0.272
3.42,-27.28,0.272
3.44,-27.13,0.272
3.45,-26.98,0.272
3.46,-26.83,0.273
3.48,-26.68,0.273
3.49,-26.53,0.273
3.51,-26.38,0.273
3.53,-26.23,0.273
3.54,-26.08,0.273
3.56,-25.93,0.273
3.57,-25.78,0.273
3.59,-25.63,0.273
3.60,-25.48,0.273
3.61,-25.33,0.273
3.63,-25.18,0.273
3.64,-25.03,0.273
3.66,-24.88,0.273
3.68,-24.73,0.273
3.69,-24.58,0.273
3.71,-24.43,0.274
3.72,-24.28,0.274
3.74,-24.13,0.274
3.75,-23.98,0.274
3.76,-23.83,0.274
3.78,-23.67,0.274
3.79,-23.52,0.274
3.81,-23.37,0.274
3.83,-23.22,0.274
3.84,-23.07,0.274
3.86,-22.92,0.275
3.87,-22.77,0.275
3.89,-22.62,0.275
3.90,-22.47,0.275
3.91,-22.32,0.275
3.93,-22.17,0.275
3.94,-22.02,0.275
3.96,-21.87,0.275
3.98,-21.72,0.275
3.99,-21.57,0.275
4.01,-21.42,0.276
4.02,-21.27,0.276
4.04,-21.12,0.276
4.05,-20.97,0.276
4.06,-20.82,0.276
4.08,-20.67,0.276
4.09,-20.52,0.276
4.11,-20.37,0.276
4.13,-20.22,0.276
4.14,-20.07,0.276
4.16,-19.92,0.277
4.17,-19.77,0.277
4.19,-19.62,0.277
4.20,-19.47,0.277
4.21,-19.32,0.277
4.23,-19.17,0.277
4.24,-19.02,0.277
4.26,-18.87,0.278
4.28,-18.72,0.278
4.29,-18.57,0.278
4.30,-18.42,0.278
4.32,-18.27,0.278
4.34,-18.12,0.278
4.35,-17.97,0.279
4.36,-17.82,0.279
4.38,-17.67,0.279
4.40,-17.52,0.279
4.41,-17.37,0.279
4.43,-17.22,0.280
4.44,-17.07,0.280
4.45,-16.92,0.280
4.47,-16.77,0.280
4.49,-16.62,0.280
4.50,-16.47,0.281
4.51,-16.31,0.281
4.53,-16.17,0.281
4.55,-16.02,0.282
4.56,-15.86,0.282
4.58,-15.72,0.282
4.59,-15.56,0.282
4.60,-15.41,0.283
4.62,-15.26,0.283
4.64,-15.11,0.284
4.65,-14.97,0.284
4.66,-14.81,0.284
4.68,-14.66,0.284
4.70,-14.51,0.285
4.71,-14.36,0.285
4.73,-14.21,0.285
4.74,-14.06,0.286
4.75,-13.91,0.286
4.77,-13.76,0.287
4.79,-13.61,0.287
4.80,-13.46,0.288
4.81,-13.31,0.288
4.83,-13.16,0.289
4.85,-13.01,0.289
4.86,-12.86,0.290
4.88,-12.71,0.290
4.89,-12.56,0.291
4.90,-12.41,0.291
4.92,-12.26,0.293
4.94,-12.11,0.293
4.95,-11.96,0.294
4.96,-11.81,0.294
4.98,-11.66,0.295
5.00,-11.51,0.296
5.01,-11.36,0.297
5.03,-11.21,0.298
5.04,-11.06,0.298
5.05,-10.91,0.299
5.07,-10.76,0.300
5.09,-10.61,0.300
5.10,-10.46,0.301
5.11,-10.31,0.301
5.13,-10.16,0.302
5.15,-10.01,0.303
5.16,-9.86,0.303
5.18,-9.71,0.304
5.19,-9.56,0.305
5.20,-9.41,0.305
5.22,-9.26,0.306
5.24,-9.11,0.307
5.25,-8.96,0.307
5.26,-8.81,0.308
5.28,-8.66,0.309
5.30,-8.51,0.309
5.31,-8.36,0.310
5.33,-8.21,0.310
5.34,-8.06,0.311
5.35,-7.91,0.312
5.37,-7.76,0.312
5.39,-7.61,0.313
5.40,-7.46,0.313
5.41,-7.31,0.314
5.43,-7.16,0.314
5.45,-7.01,0.315
5.46,-6.86,0.315
5.48,-6.71,0.316
5.49,-6.56,0.316
5.50,-6.41,0.317
5.52,-6.26,0.317
5.54,-6.11,0.317
5.55,-5.96,0.318
5.56,-5.81,0.318
5.58,-5.66,0.318
5.60,-5.51,0.319
5.61,-5.36,0.319
5.63,-5.21,0.319
5.64,-5.06,0.319
5.65,-4.91,0.320
5.67,-4.76,0.320
5.69,-4.61,0.320
5.70,-4.45,0.320
5.71,-4.30,0.320
5.73,-4.15,0.320
5.75,-4.00,0.320
5.76,-3.85,0.320
5.78,-3.70,0.320
5.79,-3.55,0.321
5.80,-3.40,0.321
5.82,-3.25,0.321
5.84,-3.10,0.321
5.85,-2.95,0.321
5.86,-2.80,0.321
5.88,-2.65,0.321
5.90,-2.50,0.321
5.91,-2.35,0.321
5.93,-2.20,0.321
5.94,-2.05,0.321
5.95,-1.90,0.321
5.97,-1.75,0.321
5.99,-1.60,0.321
6.00,-1.45,0.321
6.01,-1.30,0.321
6.03,-1.15,0.321
6.05,-1.00,0.321
6.06,-0.85,0.321
6.08,-0.70,0.321
6.09,-0.55,0.321
6.10,-0.40,0.321
6.12,-0.25,0.321
6.14,-0.10,0.321
6.15,0.05,0.321
6.16,0.20,0.321
6.18,0.35,0.321
6.20,0.50,0.321
6.21,0.65,0.321
6.23,0.80,0.321
6.24,0.95,0.321
6.25,1.10,0.321
6.27,1.25,0.321
6.29,1.40,0.321
6.30,1.55,0.321
6.31,1.70,0.321
6.33,1.85,0.321
6.35,2.00,0.321
6.36,2.15,0.321
6.38,2.31,0.321
6.39,2.46,0.321
6.40,2.61,0.321
6.42,2.76,0.321
6.44,2.90,0.321
6.45,3.06,0.321
6.46,3.21,0.321
6.48,3.36,0.321
6.50,3.51,0.321
6.51,3.66,0.321
6.53,3.81,0.321
6.54,3.96,0.321
6.55,4.11,0.322
6.57,4.26,0.322
6.59,4.41,0.322
6.60,4.56,0.322
6.61,4.71,0.322
6.63,4.86,0.322
6.65,5.01,0.322
6.66,5.16,0.322
6.68,5.31,0.322
6.69,5.46,0.322
6.70,5.61,0.322
6.72,5.76,0.322
6.74,5.91,0.322
6.75,6.06,0.322
6.76,6.21,0.322
6.78,6.36,0.322
6.80,6.51,0.322
6.81,6.66,0.322
6.83,6.81,0.322
6.84,6.96,0.323
6.85,7.11,0.323
6.87,7.26,0.323
6.89,7.41,0.323
6.90,7.56,0.323
6.91,7.71,0.323
6.93,7.86,0.323
6.95,8.01,0.323
6.96,8.16,0.323
6.98,8.31,0.323
6.99,8.46,0.324
7.00,8.61,0.324
7.02,8.76,0.324
7.04,8.91,0.324
7.05,9.06,0.324
7.06,9.21,0.324
7.08,9.36,0.324
7.10,9.52,0.325
7.11,9.66,0.325
7.13,9.82,0.325
7.14,9.96,0.325
7.15,10.12,0.325
7.17,10.27,0.325
7.19,10.42,0.325
7.20,10.57,0.325
7.21,10.72,0.325
7.23,10.87,0.326
7.25,11.02,0.326
7.26,11.17,0.325
7.28,11.32,0.326
7.29,11.47,0.326
7.30,11.62,0.326
7.32,11.77,0.326
7.34,11.92,0.326
7.35,12.07,0.326
7.36,12.22,0.326
7.38,12.37,0.326
7.40,12.52,0.326
7.41,12.67,0.327
7.43,12.82,0.327
7.44,12.97,0.327
7.45,13.12,0.327
7.47,13.27,0.327
7.49,13.42,0.327
7.50,13.57,0.327
7.51,13.72,0.327
7.53,13.87,0.327
7.55,14.02,0.328
7.56,14.17,0.328
7.58,14.32,0.328
7.59,14.47,0.328
7.60,14.62,0.328
7.62,14.77,0.328
7.64,14.92,0.328
7.65,15.07,0.329
7.66,15.22,0.329
7.68,15.37,0.329
7.70,15.52,0.329
7.71,15.67,0.329
7.73,15.82,0.329
7.74,15.97,0.329
7.75,16.12,0.329
7.77,16.27,0.330
7.79,16.42,0.330
7.80,16.57,0.330
7.81,16.72,0.330
7.83,16.87,0.330
7.85,17.02,0.330
7.86,17.17,0.330
7.88,17.32,0.330
7.89,17.47,0.331
7.90,17.62,0.331
7.92,17.77,0.331
7.94,17.92,0.331
7.95,18.07,0.331
7.96,18.22,0.331
7.98,18.38,0.331
8.00,18.52,0.331
8.01,18.67,0.332
8.03,18.83,0.332
8.04,18.98,0.332
8.05,19.13,0.332
8.07,19.28,0.332
8.09,19.43,0.333
8.10,19.58,0.333
8.11,19.73,0.333
8.13,19.88,0.333
8.15,20.03,0.333
8.16,20.17,0.333
8.18,20.33,0.333
8.19,20.48,0.333
8.20,20.63,0.334
8.22,20.78,0.334
8.24,20.93,0.334
8.25,21.08,0.334
8.26,21.23,0.334
8.28,21.38,0.334
8.30,21.53,0.334
8.31,21.68,0.335
8.33,21.83,0.335
8.34,21.98,0.335
8.35,22.13,0.335
8.37,22.28,0.335
8.39,22.43,0.336
8.40,22.58,0.336
8.41,22.73,0.336
8.43,22.88,0.336
8.45,23.03,0.336
8.46,23.18,0.336
8.48,23.33,0.337
8.49,23.48,0.337
8.50,23.63,0.337
8.52,23.78,0.337
8.53,23.93,0.337
8.55,24.08,0.338
8.57,24.23,0.338
8.58,24.38,0.338
8.60,24.53,0.338
8.61,24.68,0.338
8.63,24.83,0.339
8.64,24.98,0.339
8.65,25.13,0.339
8.67,25.28,0.339
8.68,25.43,0.340
8.70,25.58,0.340
8.72,25.73,0.340
8.73,25.88,0.341
8.75,26.03,0.341
8.76,26.18,0.341
8.78,26.33,0.342
8.79,26.48,0.342
8.80,26.63,0.342
8.82,26.78,0.342
8.83,26.93,0.343
8.85,27.08,0.343
8.87,27.23,0.343
8.88,27.38,0.344
8.90,27.53,0.344
8.91,27.68,0.344
8.93,27.83,0.345
8.94,27.98,0.345
8.95,28.14,0.345
8.97,28.29,0.346
8.98,28.43,0.346
9.00,28.59,0.346
9.02,28.74,0.347
9.03,28.89,0.347
9.05,29.04,0.347
9.06,29.19,0.347
9.08,29.34,0.348
9.09,29.49,0.348
9.10,29.64,0.348
9.12,29.79,0.349
9.13,29.94,0.349
9.15,30.09,0.349
9.17,30.24,0.349
9.18,30.39,0.350
9.20,30.54,0.350
9.21,30.69,0.350
9.23,30.84,0.351
9.24,30.99,0.351
9.25,31.14,0.351
9.27,31.29,0.352
9.28,31.44,0.352
9.30,31.59,0.352
9.32,31.74,0.353
9.33,31.89,0.353
9.35,32.04,0.353
9.36,32.19,0.354
9.38,32.34,0.354
9.39,32.49,0.355
9.40,32.64,0.355
9.42,32.79,0.355
9.43,32.94,0.356
9.45,33.09,0.356
9.47,33.24,0.356
9.48,33.39,0.357
9.50,33.54,0.357
9.51,33.69,0.357
9.53,33.84,0.358
9.54,33.99,0.358
9.55,34.14,0.359
9.57,34.29,0.359
9.58,34.44,0.359
9.60,34.59,0.360
9.62,34.74,0.360
9.63,34.89,0.360
9.65,35.04,0.361
9.66,35.19,0.361
9.68,35.34,0.361
9.69,35.49,0.362
9.70,35.64,0.362
9.72,35.79,0.362
9.73,35.94,0.363
9.75,36.09,0.363
9.77,36.24,0.363
9.78,36.39,0.364
9.80,36.54,0.364
9.81,36.69,0.365
9.83,36.84,0.365
9.84,36.99,0.365
9.85,37.14,0.366
9.87,37.29,0.366
9.88,37.44,0.366
9.90,37.59,0.366
9.92,37.74,0.367
9.93,37.89,0.367
9.95,38.04,0.367
9.96,38.19,0.367
9.98,38.34,0.368
9.99,38.49,0.368
10.00,38.64,0.368
10.02,38.79,0.368
10.03,38.95,0.369
10.05,39.09,0.369
10.07,39.24,0.369
10.08,39.40,0.369
10.10,39.54,0.370
10.11,39.70,0.370
10.13,39.85,0.370
10.14,40.00,0.371
10.15,40.15,0.371
10.17,40.30,0.371
10.18,40.45,0.371
10.20,40.60,0.372
10.22,40.75,0.372
10.23,40.90,0.372
10.25,41.05,0.372
10.26,41.20,0.373
10.28,41.35,0.373
10.29,41.50,0.373
10.30,41.65,0.374
10.32,41.80,0.374
10.33,41.95,0.374
10.35,42.10,0.374
10.37,42.25,0.374
10.38,42.40,0.375
10.40,42.55,0.375
10.41,42.70,0.375
10.43,42.85,0.375
10.44,43.00,0.375
10.45,43.15,0.376
10.47,43.30,0.376
10.48,43.45,0.376
10.50,43.60,0.376
10.52,43.75,0.377
10.53,43.90,0.377
10.55,44.05,0.377
10.56,44.20,0.377
10.58,44.35,0.378
10.59,44.50,0.378
10.60,44.65,0.378
10.62,44.80,0.378
10.63,44.95,0.379
10.65,45.10,0.379
10.67,45.25,0.379
10.68,45.40,0.379
10.70,45.55,0.379
10.71,45.70,0.380
10.73,45.85,0.380
10.74,46.00,0.380
10.75,46.15,0.380
10.77,46.30,0.380
10.78,46.45,0.381
10.80,46.60,0.381
10.82,46.75,0.381
10.83,46.90,0.382
10.85,47.05,0.382
10.86,47.20,0.382
10.88,47.35,0.382
10.89,47.51,0.382
10.90,47.66,0.383
10.92,47.80,0.383
10.93,47.96,0.383
10.95,48.11,0.383
10.97,48.25,0.384
10.98,48.41,0.384
11.00,48.56,0.384
11.01,48.71,0.384
11.03,48.86,0.384
11.04,49.00,0.385
11.05,49.16,0.385
11.07,49.31,0.385
11.08,49.46,0.386
11.10,49.61,0.386
11.12,49.76,0.386
11.13,49.91,0.386
11.15,50.06,0.387
11.16,50.21,0.387
11.18,50.36,0.387
11.19,50.51,0.387
11.20,50.66,0.388
11.22,50.81,0.388
11.23,50.96,0.388
11.25,51.11,0.388
11.27,51.26,0.389
11.28,51.41,0.389
11.30,51.56,0.389
11.31,51.71,0.389
11.33,51.86,0.390
11.34,52.01,0.390
11.35,52.16,0.390
11.37,52.31,0.391
11.38,52.46,0.391
11.40,52.61,0.391
11.42,52.76,0.391
11.43,52.91,0.392
11.45,53.06,0.392
11.46,53.21,0.392
11.48,53.36,0.392
11.49,53.51,0.393
11.50,53.66,0.393
11.52,53.81,0.393
11.53,53.96,0.394
11.55,54.11,0.394
11.57,54.26,0.394
11.58,54.41,0.394
11.60,54.56,0.395
11.61,54.71,0.395
11.63,54.86,0.395
11.64,55.01,0.395
11.65,55.16,0.396
11.67,55.31,0.396
11.68,55.46,0.396
11.70,55.61,0.396
11.72,55.76,0.397
11.73,55.91,0.397
11.75,56.06,0.397
11.76,56.21,0.398
11.78,56.36,0.398
11.79,56.51,0.398
11.80,56.66,0.398
11.82,56.81,0.399
11.83,56.96,0.399
11.85,57.11,0.399
11.87,57.26,0.399
11.88,57.41,0.400
11.90,57.56,0.400
11.91,57.71,0.400
11.93,57.86,0.401
11.94,58.01,0.401
11.95,58.16,0.401
11.97,58.32,0.401
11.98,58.46,0.402
12.00,58.61,0.402
12.02,58.76,0.402
12.03,58.91,0.402
12.05,59.06,0.403
12.06,59.22,0.403
12.08,59.36,0.403
12.09,59.52,0.403
12.10,59.66,0.404
12.12,59.82,0.404
12.13,59.96,0.404
12.15,60.12,0.405
12.17,60.27,0.405
12.18,60.42,0.406
12.20,60.57,0.406
12.21,60.72,0.406
12.23,60.87,0.406
12.24,61.02,0.407
12.25,61.17,0.408
12.27,61.32,0.408
12.28,61.47,0.408
12.30,61.62,0.409
12.32,61.77,0.409
12.33,61.92,0.409
12.35,62.07,0.409
12.36,62.22,0.410
12.38,62.37,0.410
12.39,62.52,0.410
12.40,62.67,0.411
12.42,62.82,0.411
12.43,62.97,0.411
12.45,63.12,0.412
12.47,63.27,0.412
12.48,63.42,0.412
12.50,63.57,0.414
12.51,63.72,0.414
12.53,63.87,0.414
12.54,64.02,0.414
12.55,64.17,0.415
12.57,64.32,0.415
12.58,64.47,0.415
12.60,64.62,0.416
12.62,64.77,0.416
12.63,64.92,0.416
12.65,65.07,0.416
12.66,65.22,0.417
12.68,65.37,0.417
12.69,65.52,0.417
12.70,65.67,0.418
12.72,65.82,0.418
12.73,65.97,0.419
12.75,66.12,0.419
12.77,66.27,0.419
12.78,66.42,0.419
12.80,66.57,0.420
12.81,66.72,0.420
12.83,66.87,0.420
12.84,67.02,0.421
12.85,67.17,0.421
12.87,67.32,0.422
12.88,67.47,0.422
12.90,67.62,0.422
12.92,67.77,0.423
12.93,67.92,0.423
12.95,68.07,0.423
12.96,68.22,0.424
12.98,68.37,0.424
12.99,68.52,0.425
13.00,68.67,0.425
13.02,68.82,0.426
13.03,68.97,0.426
13.05,69.12,0.426
13.07,69.27,0.427
13.08,69.42,0.427
13.10,69.57,0.427
13.11,69.72,0.428
13.13,69.88,0.428
13.14,70.02,0.429
13.15,70.18,0.429
13.17,70.32,0.429
13.18,70.48,0.430
13.20,70.63,0.430
13.22,70.78,0.431
13.23,70.93,0.431
13.25,71.08,0.432
13.26,71.23,0.432
13.28,71.38,0.432
13.29,71.53,0.433
13.30,71.68,0.433
13.32,71.83,0.434
13.33,71.98,0.434
13.35,72.13,0.434
13.37,72.28,0.435
13.38,72.43,0.435
13.40,72.58,0.436
13.41,72.73,0.436
13.43,72.88,0.436
13.44,73.03,0.437
13.45,73.18,0.438
13.47,73.33,0.438
13.48,73.48,0.438
13.50,73.63,0.439
13.52,73.78,0.439
13.53,73.93,0.440
13.55,74.08,0.440
13.56,74.23,0.441
13.58,74.38,0.441
13.59,74.53,0.442
13.60,74.68,0.442
13.62,74.83,0.443
13.63,74.98,0.443
13.65,75.13,0.443
13.67,75.28,0.444
13.68,75.43,0.444
13.70,75.58,0.445
13.71,75.73,0.445
13.73,75.88,0.445
13.74,76.03,0.446
13.75,76.18,0.446
13.77,76.33,0.447
13.78,76.48,0.447
13.80,76.63,0.448
13.82,76.78,0.448
13.83,76.93,0.449
13.85,77.08,0.449
13.86,77.23,0.450
13.88,77.38,0.450
13.89,77.53,0.451
13.90,77.68,0.451
13.92,77.83,0.452
13.93,77.98,0.452
13.95,78.13,0.453
13.97,78.28,0.453
13.98,78.43,0.454
14.00,78.58,0.454
14.01,78.73,0.455
14.03,78.88,0.456
14.04,79.03,0.457
14.05,79.18,0.457
14.07,79.33,0.458
14.08,79.48,0.458
14.10,79.63,0.459
14.12,79.78,0.459
14.13,79.93,0.460
14.15,80.08,0.460
14.16,80.23,0.461
14.18,80.38,0.461
14.19,80.53,0.462
14.20,80.68,0.462
14.22,80.83,0.463
14.23,80.98,0.463
14.25,81.13,0.464
14.27,81.28,0.465
14.28,81.43,0.466
14.30,81.58,0.466
14.31,81.73,0.467
14.33,81.88,0.468
14.34,82.03,0.468
14.35,82.18,0.469
14.37,82.33,0.469
14.38,82.48,0.469
14.40,82.63,0.470
14.42,82.78,0.470
14.43,82.93,0.471
14.45,83.08,0.471
14.46,83.23,0.472
14.48,83.38,0.473
14.49,83.53,0.473
14.50,83.68,0.474
14.52,83.83,0.474
14.53,83.98,0.475
14.55,84.13,0.475
14.57,84.28,0.476
14.58,84.43,0.476
14.60,84.58,0.477
14.61,84.73,0.477
14.63,84.88,0.478
14.64,85.03,0.478
14.65,85.18,0.479
14.67,85.33,0.479
14.68,85.48,0.480
14.70,85.63,0.481
14.72,85.78,0.481
14.73,85.93,0.482
14.75,86.08,0.483
14.76,86.24,0.483
14.78,86.39,0.484
14.79,86.53,0.485
14.80,86.68,0.485
14.82,86.84,0.486
14.83,86.99,0.487
14.85,87.14,0.488
14.87,87.29,0.488
14.88,87.44,0.489
14.90,87.59,0.490
14.91,87.74,0.490
14.93,87.89,0.491
14.94,88.04,0.492
14.95,88.19,0.492
14.97,88.34,0.493
14.98,88.49,0.494
15.00,88.64,0.494
15.02,88.79,0.495
15.03,88.94,0.496
15.05,89.09,0.497
15.06,89.24,0.498
15.08,89.39,0.498
15.09,89.54,0.499
15.10,89.69,0.500
15.12,89.84,0.501
15.13,89.99,0.502
15.15,90.14,0.502
15.17,90.29,0.503
15.18,90.44,0.504
15.20,90.59,0.505
15.21,90.74,0.506
15.23,90.89,0.506
15.24,91.04,0.507
15.25,91.19,0.508
15.27,91.34,0.509
15.28,91.49,0.510
15.30,91.64,0.510
15.32,91.79,0.511
15.33,91.94,0.512
15.35,92.09,0.513
15.36,92.24,0.515
15.38,92.39,0.516
15.39,92.54,0.516
15.40,92.69,0.517
15.42,92.84,0.518
15.43,92.99,0.519
15.45,93.14,0.520
15.47,93.29,0.520
15.48,93.44,0.522
15.50,93.59,0.523
15.51,93.74,0.525
15.53,93.89,0.526
15.54,94.04,0.526
15.55,94.19,0.527
15.57,94.34,0.528
15.58,94.49,0.529
15.60,94.64,0.530
15.62,94.79,0.531
15.63,94.94,0.532
15.65,95.09,0.532
15.66,95.24,0.534
15.68,95.39,0.534
15.69,95.54,0.535
15.70,95.69,0.536
15.72,95.84,0.537
15.73,95.99,0.538
15.75,96.14,0.540
15.77,96.29,0.541
15.78,96.44,0.542
15.80,96.59,0.543
15.81,96.74,0.545
15.83,96.89,0.546
15.84,97.04,0.548
15.85,97.19,0.549
15.87,97.34,0.550
15.88,97.49,0.551
15.90,97.64,0.552
15.92,97.79,0.554
15.93,97.94,0.555
15.95,98.09,0.557
15.96,98.24,0.558
15.98,98.39,0.559
15.99,98.54,0.561
16.00,98.69,0.562
16.02,98.84,0.563
16.03,98.99,0.564
16.05,99.14,0.566
16.07,99.29,0.568
16.08,99.44,0.569
16.10,99.59,0.571
16.11,99.74,0.572
16.13,99.89,0.573
16.14,100.04,0.574
16.15,100.19,0.575
16.17,100.34,0.578
16.18,100.49,0.579
16.20,100.64,0.580
16.22,100.79,0.581
16.23,100.94,0.583
16.25,101.09,0.584
16.26,101.24,0.585
16.28,101.39,0.587
16.29,101.54,0.589
16.30,101.69,0.590
16.32,101.84,0.592
16.33,101.99,0.593
16.35,102.14,0.595
16.37,102.29,0.596
16.38,102.44,0.599
16.40,102.59,0.600
16.41,102.74,0.602
16.43,102.89,0.604
16.44,103.04,0.606
16.45,103.19,0.609
16.47,103.34,0.610
16.48,103.49,0.613
16.50,103.64,0.614
16.52,103.79,0.616
16.53,103.94,0.619
16.55,104.09,0.620
16.56,104.24,0.622
16.58,104.39,0.624
16.59,104.54,0.626
16.60,104.69,0.627
16.62,104.84,0.629
16.63,104.99,0.632
16.65,105.14,0.634
16.67,105.29,0.636
16.68,105.44,0.638
16.70,105.59,0.640
16.71,105.74,0.642
16.73,105.89,0.643
16.74,106.04,0.645
16.75,106.19,0.647
16.77,106.34,0.651
16.78,106.49,0.652
16.80,106.64,0.656
16.82,106.79,0.658
16.83,106.93,0.659
16.85,107.09,0.663
16.86,107.24,0.665
16.88,107.38,0.668
16.89,107.54,0.670
16.90,107.68,0.673
16.92,107.83,0.675
16.93,107.98,0.677
16.95,108.13,0.679
16.97,108.28,0.682
16.98,108.43,0.683
17.00,108.58,0.685
17.01,108.73,0.687
17.03,108.88,0.689
17.04,109.03,0.691
17.05,109.18,0.695
17.07,109.33,0.698
17.08,109.48,0.701
17.10,109.63,0.702
17.12,109.78,0.705
17.13,109.93,0.707
17.14,110.08,0.710
17.16,110.23,0.712
17.18,110.38,0.714
17.19,110.53,0.717
17.21,110.68,0.719
17.22,110.83,0.720
17.23,110.98,0.722
17.25,111.13,0.725
17.27,111.28,0.728
17.28,111.43,0.730
17.29,111.58,0.732
17.31,111.73,0.735
17.33,111.88,0.737
17.34,112.03,0.741
17.36,112.18,0.743
17.37,112.33,0.746
17.38,112.48,0.748
17.40,112.63,0.750
17.42,112.78,0.753
17.43,112.93,0.754
17.44,113.08,0.759
17.46,113.23,0.761
17.48,113.38,0.763
17.49,113.53,0.765
17.51,113.68,0.771
17.52,113.83,0.773
17.53,113.98,0.776
17.55,114.13,0.779
17.57,114.28,0.780
17.58,114.43,0.783
17.59,114.58,0.787
17.61,114.73,0.791
17.63,114.88,0.794
17.64,115.03,0.798
17.66,115.18,0.800
17.67,115.33,0.804
17.68,115.48,0.810
17.70,115.63,0.813
17.72,115.78,0.817
17.73,115.92,0.821
17.74,116.08,0.824
17.76,116.22,0.827
17.78,116.37,0.830
17.79,116.52,0.833
17.81,116.67,0.837
17.82,116.82,0.840
17.83,116.97,0.848
17.85,117.12,0.853
17.87,117.27,0.859
17.88,117.42,0.861
17.89,117.57,0.864
17.91,117.72,0.869
17.93,117.87,0.871
17.94,118.02,0.877
17.96,118.17,0.882
17.97,118.32,0.887
17.98,118.47,0.889
18.00,118.62,0.891
18.02,118.77,0.891
18.03,118.92,0.894
18.04,119.07,0.895
18.06,119.22,0.896
18.08,119.37,0.897
18.09,119.52,0.899
18.11,119.67,0.899
18.12,119.82,0.900
18.13,119.97,0.900
18.15,120.12,0.901
18.17,120.27,0.901
18.18,120.42,0.901
18.19,120.57,0.901
18.21,120.72,0.902
18.23,120.87,0.902
18.24,121.02,0.902
18.26,121.17,0.903
18.27,121.32,0.903
18.28,121.47,0.905
18.30,121.62,0.906
18.32,121.77,0.906
18.33,121.92,0.907
18.34,122.07,0.908
18.36,122.22,0.909
18.38,122.38,0.910
18.39,122.53,0.910
18.41,122.68,0.911
18.42,122.83,0.911
18.43,122.98,0.911
18.45,123.13,0.911
18.47,123.28,0.909
18.48,123.43,0.908
18.49,123.58,0.908
18.51,123.73,0.908
18.53,123.88,0.907
18.54,124.03,0.906
18.56,124.18,0.905
18.57,124.33,0.905
18.58,124.48,0.903
18.60,124.63,0.902
18.62,124.78,0.900
18.63,124.93,0.899
18.64,125.08,0.898
18.66,125.23,0.897
18.68,125.38,0.895
18.69,125.53,0.895
18.71,125.68,0.894
18.72,125.83,0.893
18.73,125.98,0.893
18.75,126.13,0.893
18.77,126.28,0.893
18.78,126.43,0.892
18.79,126.58,0.892
18.81,126.73,0.884
18.83,126.88,0.869
18.84,127.03,0.853
18.86,127.18,0.833
18.87,127.33,0.822
18.88,127.48,0.810
18.90,127.64,0.803
18.92,127.79,0.799
18.93,127.94,0.792
18.94,128.09,0.778
18.96,128.24,0.769
18.98,128.39,0.765
18.99,128.54,0.759
19.01,128.69,0.748
19.02,128.84,0.738
19.03,128.99,0.720
19.05,129.15,0.708
19.07,129.30,0.697
19.08,129.45,0.681
19.09,129.60,0.667
19.11,129.75,0.647
19.13,129.91,0.630
19.14,130.06,0.613
19.16,130.21,0.601
19.17,130.36,0.583
19.18,130.51,0.568
19.20,130.67,0.552
19.22,130.82,0.529
19.23,130.97,0.510
19.24,131.13,0.492
19.26,131.28,0.479
19.28,131.43,0.470
19.29,131.58,0.461
19.31,131.73,0.461
19.32,131.88,0.455
19.33,132.04,0.451
19.35,132.19,0.450
19.37,132.34,0.446
19.38,132.49,0.444
19.39,132.64,0.443
19.41,132.79,0.441
19.43,132.94,0.441
19.44,133.09,0.440
19.46,133.24,0.439
19.47,133.39,0.439
19.48,133.54,0.438
19.50,133.69,0.438
19.52,133.84,0.437
19.53,133.99,0.437
19.54,134.14,0.436
19.56,134.29,0.436
19.58,134.44,0.435
19.59,134.59,0.435
19.61,134.74,0.434
19.62,134.89,0.434
19.63,135.04,0.433
19.65,135.19,0.433
19.67,135.34,0.432
19.68,135.49,0.432
19.69,135.64,0.432
19.71,135.79,0.431
19.73,135.94,0.431
19.74,136.09,0.430
19.76,136.24,0.430
19.77,136.39,0.430
19.78,136.54,0.430
19.80,136.69,0.429
19.82,136.84,0.429
19.83,136.99,0.429
19.84,137.14,0.429
19.86,137.29,0.429
19.88,137.44,0.428
19.89,137.59,0.428
19.91,137.74,0.428
19.92,137.89,0.428
19.93,138.04,0.428
19.95,138.19,0.427
19.97,138.34,0.427
19.98,138.49,0.427
19.99,138.64,0.427
20.01,138.79,0.427
20.03,138.94,0.427
20.04,139.10,0.427
20.06,139.25,0.427
20.07,139.40,0.426
20.08,139.55,0.426
20.10,139.70,0.426
20.12,139.85,0.426
20.13,140.00,0.426
20.14,140.15,0.426
20.16,140.30,0.426
20.18,140.45,0.426
20.19,140.60,0.426
20.21,140.75,0.426
20.22,140.90,0.426
20.23,141.05,0.426
20.25,141.20,0.426
20.27,141.35,0.425
20.28,141.50,0.425
20.29,141.65,0.425
20.31,141.80,0.425
20.33,141.95,0.425
20.34,142.10,0.425
20.36,142.25,0.425
20.37,142.40,0.425
20.38,142.55,0.425
20.40,142.70,0.424
20.42,142.85,0.425
20.43,143.00,0.424
20.44,143.15,0.424
20.46,143.30,0.424
20.48,143.45,0.424
20.49,143.60,0.424
20.51,143.75,0.424
20.52,143.90,0.424
20.53,144.05,0.424
20.55,144.20,0.424
20.57,144.35,0.424
20.58,144.50,0.424
20.59,144.65,0.424
20.61,144.80,0.424
20.63,144.95,0.424
20.64,145.10,0.424
20.66,145.25,0.423
20.67,145.40,0.423
20.68,145.55,0.423
20.70,145.70,0.423
20.72,145.85,0.423
20.73,146.00,0.423
20.74,146.15,0.423
20.76,146.30,0.423
20.78,146.45,0.423
20.79,146.60,0.423
20.81,146.75,0.423
20.82,146.90,0.422
20.83,147.05,0.422
20.85,147.20,0.422
20.87,147.35,0.422
20.88,147.50,0.422
20.89,147.65,0.422
20.91,147.80,0.422
20.93,147.95,0.422
20.94,148.10,
20.96,148.25,
20.97,148.40,
20.98,,
20.99,,

[step]
Ramp 10.00 °C/min to -60.00 °C
Time,Temperature,Heat Flow (Normalized)
min,°C,W/g
22.99,150.12,-0.140
23.01,150.12,-0.140
23.02,150.12,-0.140
23.04,150.12,-0.140
23.05,150.10,-0.139
23.07,150.08,-0.131
23.08,150.04,-0.119
23.10,149.98,-0.115
23.11,149.91,-0.120
23.13,149.83,-0.176
23.14,149.73,-0.220
23.16,149.63,-0.272
23.17,149.52,-0.324
23.19,149.40,-0.372
23.20,149.28,-0.413
23.22,149.16,-0.447
23.23,149.03,-0.477
23.25,148.90,-0.503
23.26,148.77,-0.526
23.28,148.64,-0.543
23.29,148.50,-0.563
23.31,148.36,-0.579
23.32,148.22,-0.591
23.34,148.08,-0.600
23.35,147.94,-0.608
23.37,147.80,-0.621
23.38,147.66,-0.629
23.40,147.51,-0.633
23.41,147.37,-0.640
23.43,147.22,-0.643
23.44,147.08,-0.647
23.46,146.93,-0.654
23.47,146.78,-0.657
23.49,146.64,-0.658
23.50,146.49,-0.659
23.52,146.34,-0.661
23.53,146.20,-0.662
23.55,146.05,-0.665
23.56,145.90,-0.666
23.58,145.75,-0.667
23.59,145.61,-0.667
23.61,145.46,-0.668
23.62,145.31,-0.669
23.64,145.16,-0.671
23.65,145.01,-0.672
23.67,144.87,-0.673
23.68,144.72,-0.673
23.70,144.57,-0.674
23.71,144.42,-0.674
23.73,144.27,-0.675
23.74,144.13,-0.675
23.76,143.98,-0.675
23.77,143.83,-0.676
23.79,143.68,-0.676
23.80,143.53,-0.676
23.82,143.38,-0.676
23.83,143.23,-0.677
23.85,143.08,-0.677
23.86,142.93,-0.677
23.88,142.79,-0.678
23.89,142.64,-0.678
23.91,142.49,-0.678
23.92,142.34,-0.678
23.94,142.19,-0.678
23.95,142.04,-0.678
23.97,141.89,-0.678
23.98,141.74,-0.678
24.00,141.59,-0.679
24.01,141.44,-0.679
24.03,141.29,-0.679
24.04,141.14,-0.679
24.06,140.99,-0.679
24.07,140.84,-0.679
24.09,140.70,-0.679
24.10,140.55,-0.679
24.12,140.40,-0.678
24.13,140.25,-0.678
24.15,140.10,-0.678
24.16,139.95,-0.678
24.18,139.80,-0.678
24.19,139.65,-0.678
24.21,139.50,-0.678
24.22,139.35,-0.677
24.24,139.20,-0.677
24.25,139.05,-0.677
24.27,138.90,-0.677
24.28,138.75,-0.676
24.30,138.60,-0.676
24.31,138.45,-0.676
24.33,138.30,-0.676
24.34,138.15,-0.676
24.36,138.01,-0.675
24.37,137.86,-0.675
24.39,137.71,-0.675
24.40,137.56,-0.675
24.42,137.41,-0.674
24.43,137.26,-0.674
24.45,137.11,-0.674
24.46,136.96,-0.674
24.48,136.81,-0.673
24.49,136.66,-0.672
24.51,136.51,-0.672
24.52,136.36,-0.672
24.54,136.21,-0.672
24.55,136.06,-0.672
24.57,135.91,-0.672
24.58,135.76,-0.671
24.60,135.61,-0.671
24.61,135.46,-0.671
24.63,135.31,-0.670
24.64,135.16,-0.670
24.66,135.01,-0.670
24.67,134.86,-0.669
24.69,134.71,-0.669
24.70,134.56,-0.669
24.72,134.41,-0.669
24.73,134.26,-0.668
24.75,134.11,-0.668
24.76,133.96,-0.668
24.78,133.81,-0.668
24.79,133.66,-0.667
24.81,133.51,-0.667
24.82,133.36,-0.667
24.84,133.21,-0.666
24.85,133.06,-0.666
24.87,132.91,-0.666
24.88,132.76,-0.665
24.90,132.61,-0.665
24.91,132.46,-0.665
24.93,132.32,-0.665
24.94,132.16,-0.664
24.96,132.02,-0.664
24.97,131.87,-0.664
24.99,131.72,-0.663
25.00,131.57,-0.663
25.02,131.42,-0.663
25.03,131.27,-0.662
25.05,131.12,-0.662
25.06,130.97,-0.662
25.08,130.82,-0.661
25.09,130.67,-0.661
25.11,130.52,-0.661
25.12,130.37,-0.661
25.14,130.22,-0.660
25.15,130.07,-0.660
25.17,129.92,-0.660
25.18,129.77,-0.659
25.20,129.62,-0.659
25.21,129.47,-0.659
25.23,129.32,-0.658
25.24,129.17,-0.658
25.26,129.02,-0.658
25.27,128.87,-0.658
25.29,128.72,-0.658
25.30,128.57,-0.657
25.32,128.42,-0.657
25.33,128.27,-0.657
25.35,128.12,-0.657
25.36,127.97,-0.656
25.38,127.82,-0.656
25.39,127.67,-0.656
25.41,127.52,-0.656
25.42,127.37,-0.655
25.44,127.22,-0.655
25.45,127.07,-0.655
25.47,126.92,-0.655
25.48,126.77,-0.654
25.50,126.62,-0.654
25.51,126.47,-0.654
25.53,126.32,-0.653
25.54,126.17,-0.653
25.56,126.02,-0.653
25.57,125.87,-0.653
25.59,125.72,-0.652
25.60,125.57,-0.652
25.62,125.42,-0.652
25.63,125.27,-0.651
25.65,125.12,-0.651
25.66,124.97,-0.651
25.68,124.82,-0.650
25.69,124.67,-0.650
25.71,124.52,-0.650
25.72,124.37,-0.650
25.74,124.22,-0.649
25.75,124.07,-0.649
25.77,123.92,-0.649
25.78,123.77,-0.649
25.80,123.62,-0.648
25.81,123.47,-0.648
25.83,123.32,-0.648
25.84,123.17,-0.648
25.86,123.02,-0.647
25.87,122.87,-0.647
25.89,122.72,-0.647
25.90,122.57,-0.646
25.92,122.43,-0.646
25.93,122.27,-0.646
25.95,122.13,-0.646
25.96,121.98,-0.646
25.98,121.82,-0.645
25.99,121.67,-0.645
26.01,121.53,-0.645
26.02,121.38,-0.645
26.04,121.23,-0.644
26.05,121.08,-0.644
26.07,120.93,-0.644
26.08,120.78,-0.643
26.10,120.63,-0.643
26.11,120.48,-0.643
26.13,120.33,-0.642
26.14,120.18,-0.642
26.16,120.03,-0.642
26.17,119.88,-0.642
26.19,119.73,-0.642
26.20,119.58,-0.641
26.22,119.43,-0.641
26.23,119.28,-0.640
26.25,119.13,-0.640
26.26,118.98,-0.640
26.28,118.83,-0.639
26.29,118.68,-0.639
26.31,118.53,-0.639
26.32,118.38,-0.639
26.34,118.23,-0.639
26.35,118.08,-0.638
26.37,117.93,-0.638
26.38,117.78,-0.638
26.40,117.63,-0.638
26.41,117.48,-0.637
26.43,117.33,-0.637
26.44,117.18,-0.637
26.46,117.03,-0.637
26.47,116.88,-0.637
26.49,116.73,-0.636
26.50,116.58,-0.636
26.52,116.43,-0.636
26.53,116.28,-0.636
26.55,116.13,-0.636
26.56,115.98,-0.635
26.58,115.83,-0.635
26.59,115.68,-0.635
26.61,115.53,-0.635
26.62,115.38,-0.634
26.64,115.23,-0.634
26.65,115.08,-0.634
26.67,114.93,-0.634
26.68,114.78,-0.633
26.70,114.63,-0.633
26.71,114.48,-0.633
26.73,114.33,-0.633
26.74,114.18,-0.632
26.76,114.03,-0.632
26.77,113.88,-0.632
26.79,113.73,-0.632
26.80,113.58,-0.632
26.82,113.43,-0.631
26.83,113.28,-0.631
26.85,113.13,-0.631
26.86,112.98,-0.631
26.88,112.83,-0.631
26.89,112.68,-0.630
26.91,112.53,-0.630
26.92,112.38,-0.630
26.94,112.23,-0.630
26.95,112.08,-0.630
26.97,111.93,-0.629
26.98,111.78,-0.629
27.00,111.63,-0.629
27.01,111.48,-0.629
27.03,111.33,-0.628
27.04,111.18,-0.628
27.06,111.03,-0.628
27.07,110.88,-0.627
27.09,110.73,-0.627
27.10,110.58,-0.627
27.12,110.43,-0.627
27.13,110.28,-0.627
27.15,110.13,-0.627
27.16,109.98,-0.627
27.18,109.84,-0.630
27.19,109.69,-0.632
27.21,109.54,-0.636
27.22,109.39,-0.643
27.24,109.24,-0.646
27.25,109.09,-0.647
27.27,108.94,-0.647
27.28,108.79,-0.648
27.30,108.64,-0.650
27.31,108.49,-0.660
27.33,108.34,-0.703
27.34,108.19,-0.763
27.36,108.05,-0.761
27.37,107.90,-0.749
27.39,107.75,-0.759
27.40,107.60,-0.782
27.42,107.46,-0.955
27.43,107.32,-1.956
27.45,107.23,-3.203
27.46,107.13,-3.281
27.48,107.02,-3.054
27.49,106.90,-3.246
27.51,106.78,-3.320
27.52,106.66,-3.250
27.54,106.52,-3.214
27.55,106.39,-3.065
27.57,106.24,-2.709
27.58,106.08,-2.397
27.60,105.92,-2.189
27.61,105.75,-2.036
27.63,105.58,-1.931
27.64,105.42,-1.842
27.66,105.26,-1.754
27.67,105.09,-1.662
27.69,104.93,-1.593
27.70,104.77,-1.526
27.72,104.61,-1.476
27.73,104.45,-1.425
27.75,104.29,-1.384
27.76,104.13,-1.347
27.78,103.97,-1.311
27.79,103.81,-1.280
27.81,103.66,-1.252
27.82,103.50,-1.224
27.84,103.35,-1.205
27.85,103.19,-1.180
27.87,103.04,-1.162
27.88,102.88,-1.138
27.90,102.73,-1.124
27.91,102.58,-1.106
27.93,102.42,-1.089
27.94,102.27,-1.078
27.96,102.12,-1.065
27.97,101.97,-1.058
27.99,101.81,-1.049
28.00,101.66,-1.045
28.02,101.51,-1.043
28.03,101.36,-1.045
28.05,101.21,-1.044
28.06,101.06,-1.015
28.08,100.91,-1.006
28.09,100.75,-0.990
28.11,100.60,-0.980
28.12,100.45,-0.974
28.14,100.30,-0.968
28.15,100.15,-0.963
28.17,100.00,-0.955
28.18,99.85,-0.950
28.20,99.70,-0.942
28.21,99.55,-0.936
28.23,99.40,-0.930
28.24,99.24,-0.925
28.26,99.09,-0.922
28.27,98.94,-0.914
28.29,98.79,-0.912
28.30,98.64,-0.903
28.32,98.49,-0.900
28.33,98.34,-0.898
28.35,98.19,-0.893
28.36,98.04,-0.891
28.38,97.89,-0.885
28.39,97.74,-0.883
28.41,97.59,-0.878
28.42,97.44,-0.876
28.44,97.29,-0.873
28.45,97.14,-0.869
28.47,96.99,-0.863
28.48,96.84,-0.860
28.50,96.69,-0.858
28.51,96.53,-0.854
28.53,96.39,-0.851
28.54,96.23,-0.847
28.56,96.09,-0.845
28.57,95.94,-0.841
28.59,95.78,-0.838
28.60,95.63,-0.837
28.62,95.48,-0.832
28.63,95.33,-0.829
28.65,95.18,-0.827
28.66,95.03,-0.824
28.68,94.88,-0.819
28.69,94.73,-0.817
28.71,94.58,-0.814
28.72,94.43,-0.812
28.74,94.28,-0.810
28.75,94.13,-0.808
28.77,93.98,-0.805
28.78,93.83,-0.802
28.80,93.68,-0.799
28.81,93.53,-0.798
28.83,93.38,-0.796
28.84,93.23,-0.793
28.86,93.08,-0.791
28.87,92.93,-0.790
28.89,92.78,-0.786
28.90,92.63,-0.782
28.92,92.48,-0.779
28.93,92.33,-0.778
28.95,92.18,-0.777
28.96,92.03,-0.775
28.98,91.88,-0.774
28.99,91.73,-0.770
29.01,91.58,-0.769
29.02,91.43,-0.768
29.04,91.28,-0.767
29.05,91.13,-0.765
29.07,90.98,-0.763
29.08,90.83,-0.760
29.10,90.68,-0.758
29.11,90.53,-0.757
29.13,90.38,-0.756
29.14,90.23,-0.754
29.16,90.08,-0.753
29.17,89.93,-0.752
29.19,89.78,-0.751
29.20,89.63,-0.750
29.22,89.48,-0.748
29.23,89.33,-0.746
29.25,89.18,-0.744
29.26,89.03,-0.743
29.28,88.88,-0.741
29.29,88.73,-0.739
29.31,88.58,-0.738
29.32,88.43,-0.736
29.34,88.28,-0.734
29.35,88.13,-0.732
29.37,87.98,-0.731
29.38,87.83,-0.729
29.40,87.68,-0.727
29.41,87.53,-0.727
29.43,87.38,-0.724
29.44,87.23,-0.723
[...]
93.77,-43.91,0.262
93.78,-43.84,0.262
93.78,-43.77,0.262
93.79,-43.71,0.262
93.80,-43.64,0.262
93.80,-43.57,0.262
93.81,-43.51,0.262
93.82,-43.44,0.262
93.82,-43.37,0.262
93.83,-43.31,0.262
93.84,-43.24,0.263
93.84,-43.17,0.263
93.85,-43.11,0.263
93.86,-43.04,0.263
93.86,-42.97,0.263
93.87,-42.91,0.263
93.88,-42.84,0.263
93.88,-42.77,0.263
93.89,-42.71,0.263
93.90,-42.64,0.263
93.90,-42.57,0.263
93.91,-42.51,0.263
93.92,-42.44,0.263
93.92,-42.37,0.263
93.93,-42.31,0.263
93.94,-42.24,0.263
93.94,-42.17,0.263
93.95,-42.11,0.263
93.96,-42.04,0.263
93.96,-41.97,0.263
93.97,-41.90,0.263
93.98,-41.84,0.263
93.98,-41.77,0.263
93.99,-41.70,0.263
94.00,-41.64,0.264
94.00,-41.57,0.264
94.01,-41.51,0.263
94.02,-41.44,0.264
94.02,-41.37,0.264
94.03,-41.31,0.264
94.04,-41.24,0.264
94.04,-41.17,0.264
94.05,-41.10,0.264
94.06,-41.04,0.264
94.06,-40.97,0.264
94.07,-40.91,0.264
94.08,-40.84,0.264
94.08,-40.77,0.264
94.09,-40.70,0.264
94.10,-40.64,0.264
94.10,-40.57,0.264
94.11,-40.50,0.264
94.12,-40.44,0.264
94.12,-40.37,0.264
94.13,-40.30,0.264
94.14,-40.24,0.264
94.14,-40.17,0.264
94.15,-40.10,0.264
94.16,-40.04,0.264
94.16,-39.97,0.264
94.17,-39.90,0.264
94.18,-39.84,0.264
94.18,-39.77,0.264
94.19,-39.70,0.264
94.20,-39.64,0.265
94.20,-39.57,0.265
94.21,-39.50,0.265
94.22,-39.44,0.264
94.22,-39.37,0.264
94.23,-39.30,0.264
94.24,-39.24,0.264
94.24,-39.17,0.265
94.25,-39.10,0.265
94.26,-39.04,0.265
94.26,-38.97,0.265
94.27,-38.90,0.265
94.28,-38.84,0.265
94.28,-38.77,0.265
94.29,-38.70,0.265
94.30,-38.64,0.265
94.30,-38.57,0.265
94.31,-38.50,0.265
94.32,-38.43,0.265
94.32,-38.37,0.265
94.33,-38.30,0.265
94.34,-38.23,0.265
94.34,-38.17,0.265
94.35,-38.10,0.265
94.36,-38.04,0.265
94.36,-37.97,0.265
94.37,-37.90,0.265
94.38,-37.84,0.265
94.38,-37.77,0.265
94.39,-37.70,0.265
94.40,-37.63,0.265
94.40,-37.57,0.265
94.41,-37.50,0.265
94.42,-37.43,0.265
94.42,-37.37,0.265
94.43,-37.30,0.265
94.44,-37.23,0.265
94.44,-37.17,0.265
94.45,-37.10,0.265
94.46,-37.03,0.265
94.46,-36.97,0.265
94.47,-36.90,0.265
94.48,-36.83,0.265
94.48,-36.77,0.266
94.49,-36.70,0.266
94.50,-36.63,0.266
94.50,-36.57,0.266
94.51,-36.50,0.266
94.52,-36.43,0.266
94.52,-36.37,0.266
94.53,-36.30,0.266
94.54,-36.23,0.266
94.54,-36.16,0.266
94.55,-36.10,0.266
94.56,-36.03,0.266
94.56,-35.96,0.266
94.57,-35.90,0.266
94.58,-35.83,0.266
94.58,-35.77,0.266
94.59,-35.70,0.266
94.60,-35.63,0.266
94.60,-35.56,0.266
94.61,-35.50,0.266
94.62,-35.43,0.266
94.62,-35.37,0.266
94.63,-35.30,0.266
94.64,-35.23,0.266
94.64,-35.16,0.266
94.65,-35.10,0.266
94.66,-35.03,0.266
94.66,-34.96,0.266
94.67,-34.90,0.267
94.68,-34.83,0.267
94.68,-34.76,0.267
94.69,-34.70,0.267
94.70,-34.63,0.267
94.70,-34.56,0.267
94.71,-34.50,0.267
94.72,-34.43,0.267
94.72,-34.36,0.267
94.73,-34.30,0.267
94.74,-34.23,0.267
94.74,-34.16,0.267
94.75,-34.10,0.267
94.76,-34.03,0.267
94.76,-33.96,0.267
94.77,-33.89,0.267
94.78,-33.83,0.267
94.78,-33.76,0.267
94.79,-33.69,0.267
94.80,-33.63,0.267
94.80,-33.56,0.267
94.81,-33.49,0.267
94.82,-33.43,0.267
94.82,-33.36,0.267
94.83,-33.29,0.267
94.84,-33.23,0.267
94.84,-33.16,0.267
94.85,-33.09,0.267
94.86,-33.03,0.268
94.86,-32.96,0.268
94.87,-32.90,0.268
94.88,-32.83,0.268
94.88,-32.76,0.268
94.89,-32.69,0.268
94.90,-32.63,0.268
94.90,-32.56,0.268
94.91,-32.49,0.268
94.92,-32.43,0.268
94.92,-32.36,0.268
94.93,-32.29,0.268
94.94,-32.23,0.268
94.94,-32.16,0.268
94.95,-32.09,0.268
94.96,-32.02,0.268
94.96,-31.96,0.268
94.97,-31.89,0.268
94.98,-31.82,0.268
94.98,-31.76,0.268
94.99,-31.69,0.268
95.00,-31.62,0.268
95.00,-31.56,0.268
95.01,-31.49,0.268
95.02,-31.43,0.268
95.02,-31.36,0.268
95.03,-31.29,0.269
95.04,-31.23,0.269
95.04,-31.16,0.269
95.05,-31.09,0.269
95.06,-31.02,0.269
95.06,-30.96,0.269
95.07,-30.89,0.269
95.08,-30.82,0.269
95.08,-30.76,0.269
95.09,-30.69,0.269
95.10,-30.62,0.269
95.10,-30.56,0.269
95.11,-30.49,0.269
95.12,-30.42,0.269
95.12,-30.36,0.269
95.13,-30.29,0.269
95.14,-30.22,0.269
95.14,-30.16,0.269
95.15,-30.09,0.269
95.16,-30.02,0.269
95.16,-29.96,0.269
95.17,-29.89,0.269
95.18,-29.82,0.269
95.18,-29.76,0.269
95.19,-29.69,0.270
95.20,-29.62,0.270
95.20,-29.55,0.270
95.21,-29.49,0.270
95.22,-29.42,0.270
95.22,-29.36,0.270
95.23,-29.29,0.270
95.24,-29.22,0.270
95.24,-29.16,0.270
95.25,-29.09,0.270
95.26,-29.02,0.270
95.26,-28.96,0.270
95.27,-28.89,0.270
95.28,-28.82,0.270
95.28,-28.76,0.271
95.29,-28.69,0.271
95.30,-28.62,0.271
95.30,-28.56,0.271
95.31,-28.49,0.271
95.32,-28.42,0.271
95.32,-28.35,0.271
95.33,-28.29,0.271
95.34,-28.22,0.271
95.34,-28.15,0.271
95.35,-28.09,0.271
95.36,-28.02,0.271
95.36,-27.95,0.271
95.37,-27.89,0.271
95.38,-27.82,0.271
95.38,-27.75,0.271
95.39,-27.69,0.272
95.40,-27.62,0.272
95.40,-27.55,0.272
95.41,-27.49,0.272
95.42,-27.42,0.272
95.42,-27.35,0.272
95.43,-27.29,0.272
95.44,-27.22,0.272
95.44,-27.15,0.272
95.45,-27.08,0.272
95.46,-27.02,0.272
95.46,-26.95,0.272
95.47,-26.89,0.273
95.48,-26.82,0.273
95.48,-26.75,0.273
95.49,-26.69,0.273
95.50,-26.62,0.273
95.50,-26.55,0.273
95.51,-26.48,0.273
95.52,-26.42,0.273
95.52,-26.35,0.273
95.53,-26.28,0.273
95.54,-26.22,0.273
95.54,-26.15,0.274
95.55,-26.08,0.274
95.56,-26.02,0.274
95.56,-25.95,0.274
95.57,-25.88,0.274
95.58,-25.82,0.274
95.58,-25.75,0.274
95.59,-25.69,0.274
95.60,-25.62,0.274
95.60,-25.55,0.274
95.61,-25.48,0.274
95.62,-25.42,0.274
95.62,-25.35,0.275
95.63,-25.28,0.275
95.64,-25.22,0.275
95.64,-25.15,0.275
95.65,-25.08,0.275
95.66,-25.02,0.275
95.66,-24.95,0.275
95.67,-24.88,0.275
95.68,-24.82,0.275
95.68,-24.75,0.275
95.69,-24.68,0.276
95.70,-24.62,0.276
95.70,-24.55,0.276
95.71,-24.48,0.276
95.72,-24.42,0.276
95.72,-24.35,0.276
95.73,-24.28,0.276
95.74,-24.22,0.276
95.74,-24.15,0.276
95.75,-24.08,0.277
95.76,-24.02,0.277
95.76,-23.95,0.277
95.77,-23.88,0.277
95.78,-23.81,0.277
95.78,-23.75,0.277
95.79,-23.68,0.277
95.80,-23.61,0.278
95.80,-23.55,0.278
95.81,-23.48,0.278
95.82,-23.41,0.278
95.82,-23.35,0.278
95.83,-23.28,0.278
95.84,-23.22,0.278
95.84,-23.15,0.279
95.85,-23.08,0.279
95.86,-23.02,0.279
95.86,-22.95,0.279
95.87,-22.88,0.279
95.88,-22.82,0.279
95.88,-22.75,0.279
95.89,-22.68,0.279
95.90,-22.61,0.280
95.90,-22.55,0.280
95.91,-22.48,0.280
95.92,-22.41,0.280
95.92,-22.35,0.280
95.93,-22.28,0.280
95.94,-22.21,0.280
95.94,-22.15,0.281
95.95,-22.08,0.281
95.96,-22.01,0.281
95.96,-21.95,0.281
95.97,-21.88,0.281
95.98,-21.81,0.281
95.98,-21.75,0.282
95.99,-21.68,0.282
96.00,-21.61,0.282
96.00,-21.55,0.282
96.01,-21.48,0.282
96.02,-21.41,0.282
96.02,-21.35,0.282
96.03,-21.28,0.283
96.04,-21.21,0.283
96.04,-21.15,0.283
96.05,-21.08,0.283
96.06,-21.01,0.283
96.06,-20.95,0.284
96.07,-20.88,0.284
96.08,-20.81,0.284
96.08,-20.75,0.284
96.09,-20.68,0.285
96.10,-20.61,0.285
96.10,-20.55,0.285
96.11,-20.48,0.285
96.12,-20.41,0.285
96.12,-20.35,0.286
96.13,-20.28,0.286
96.14,-20.21,0.286
96.14,-20.15,0.286
96.15,-20.08,0.286
96.16,-20.01,0.286
96.16,-19.95,0.287
96.17,-19.88,0.287
96.18,-19.81,0.287
96.18,-19.75,0.288
96.19,-19.68,0.288
96.20,-19.61,0.288
96.20,-19.55,0.288
96.21,-19.48,0.288
96.22,-19.41,0.289
96.22,-19.35,0.289
96.23,-19.28,0.289
96.24,-19.21,0.289
96.24,-19.15,0.289
96.25,-19.08,0.289
96.26,-19.01,0.290
96.26,-18.95,0.290
96.27,-18.88,0.290
96.28,-18.81,0.290
96.28,-18.75,0.291
96.29,-18.68,0.291
96.30,-18.61,0.291
96.30,-18.54,0.291
96.31,-18.48,0.292
96.32,-18.41,0.292
96.32,-18.35,0.292
96.33,-18.28,0.292
96.34,-18.21,0.293
96.34,-18.14,0.293
96.35,-18.08,0.293
96.36,-18.01,0.293
96.36,-17.94,0.293
96.37,-17.88,0.294
96.38,-17.81,0.294
96.38,-17.74,0.294
96.39,-17.68,0.294
96.40,-17.61,0.295
96.40,-17.54,0.295
96.41,-17.48,0.295
96.42,-17.41,0.295
96.42,-17.34,0.296
96.43,-17.28,0.296
96.44,-17.21,0.296
96.44,-17.14,0.297
96.45,-17.08,0.297
96.46,-17.01,0.297
96.46,-16.94,0.297
96.47,-16.88,0.297
96.48,-16.81,0.298
96.48,-16.74,0.298
96.49,-16.68,0.298
96.50,-16.61,0.298
96.50,-16.54,0.299
96.51,-16.48,0.299
96.52,-16.41,0.299
96.52,-16.34,0.300
96.53,-16.28,0.300
96.54,-16.21,0.300
96.54,-16.14,0.301
96.55,-16.08,0.301
96.56,-16.01,0.301
96.56,-15.94,0.301
96.57,-15.88,0.301
96.58,-15.81,0.302
96.58,-15.74,0.302
96.59,-15.68,0.302
96.60,-15.61,0.302
96.60,-15.54,0.303
96.61,-15.48,0.303
96.62,-15.41,0.304
96.62,-15.34,0.304
96.63,-15.28,0.304
96.64,-15.21,0.305
96.64,-15.14,0.305
96.65,-15.08,0.305
96.66,-15.01,0.305
96.66,-14.94,0.306
96.67,-14.87,0.306
96.68,-14.81,0.306
96.68,-14.74,0.307
96.69,-14.68,0.307
96.70,-14.61,0.307
96.70,-14.54,0.308
96.71,-14.47,0.308
96.72,-14.41,0.308
96.72,-14.34,0.308
96.73,-14.27,0.308
96.74,-14.21,0.309
96.74,-14.14,0.309
96.75,-14.07,0.309
96.76,-14.01,0.309
96.76,-13.94,0.310
96.77,-13.87,0.310
96.78,-13.81,0.310
96.78,-13.74,0.311
96.79,-13.67,0.311
96.80,-13.61,0.311
96.80,-13.54,0.311
96.81,-13.47,0.312
96.82,-13.41,0.312
96.82,-13.34,0.312
96.83,-13.27,0.312
96.84,-13.21,0.312
96.84,-13.14,0.313
96.85,-13.07,0.313
96.86,-13.01,0.313
96.86,-12.94,0.313
96.87,-12.87,0.314
96.88,-12.81,0.314
96.88,-12.74,0.314
96.89,-12.67,0.314
96.90,-12.61,0.314
96.90,-12.54,0.315
96.91,-12.47,0.315
96.92,-12.41,0.315
96.92,-12.34,0.316
96.93,-12.27,0.316
96.94,-12.21,0.316
96.94,-12.14,0.316
96.95,-12.07,0.316
96.96,-12.01,0.317
96.96,-11.94,0.317
96.97,-11.87,0.317
96.98,-11.81,0.317
96.98,-11.74,0.318
96.99,-11.67,0.318
97.00,-11.61,0.318
97.00,-11.54,0.318
97.01,-11.47,0.318
97.02,-11.40,0.319
97.02,-11.34,0.319
97.03,-11.27,0.319
97.04,-11.21,0.319
97.04,-11.14,0.319
97.05,-11.07,0.320
97.06,-11.00,0.320
97.06,-10.94,0.320
97.07,-10.87,0.320
97.08,-10.80,0.320
97.08,-10.74,0.320
97.09,-10.67,0.321
97.10,-10.61,0.321
97.10,-10.54,0.321
97.11,-10.47,0.321
97.12,-10.40,0.321
97.12,-10.34,0.321
97.13,-10.27,0.321
97.14,-10.20,0.321
97.14,-10.14,0.321
97.15,-10.07,0.321
97.16,-10.00,0.322
97.16,-9.94,0.322
97.17,-9.87,0.322
97.18,-9.80,0.322
97.18,-9.74,0.322
97.19,-9.67,0.322
97.20,-9.60,0.322
97.20,-9.54,0.322
97.21,-9.47,0.322
97.22,-9.40,0.322
97.22,-9.33,0.322
97.23,-9.27,0.322
97.24,-9.20,0.322
97.24,-9.13,0.322
97.25,-9.07,0.322
97.26,-9.00,0.322
97.26,-8.93,0.323
97.27,-8.87,0.323
97.28,-8.80,0.323
97.28,-8.74,0.323
97.29,-8.67,0.323
97.30,-8.60,0.323
97.30,-8.53,0.323
97.31,-8.47,0.323
97.32,-8.40,0.323
97.32,-8.34,0.323
97.33,-8.27,0.323
97.34,-8.20,0.323
97.34,-8.13,0.323
97.35,-8.07,0.323
97.36,-8.00,0.323
97.36,-7.93,0.323
97.37,-7.87,0.323
97.38,-7.80,0.323
97.38,-7.73,0.323
97.39,-7.67,0.323
97.40,-7.60,0.323
97.40,-7.53,0.323
97.41,-7.47,0.323
97.42,-7.40,0.323
97.42,-7.33,0.323
97.43,-7.27,0.323
97.44,-7.20,0.323
97.44,-7.13,0.323
97.45,-7.07,0.323
97.46,-7.00,0.323
97.46,-6.93,0.323
97.47,-6.87,0.323
97.48,-6.80,0.323
97.48,-6.73,0.323
97.49,-6.66,0.323
97.50,-6.60,0.323
97.50,-6.53,0.323
97.51,-6.46,0.323
97.52,-6.40,0.323
97.52,-6.33,0.323
97.53,-6.26,0.323
97.54,-6.20,0.323
97.54,-6.13,0.323
97.55,-6.06,0.324
97.56,-6.00,0.324
97.56,-5.93,0.324
97.57,-5.86,0.324
97.58,-5.80,0.324
97.58,-5.73,0.324
97.59,-5.67,0.323
97.60,-5.60,0.324
97.60,-5.53,0.324
97.61,-5.46,0.324
97.62,-5.40,0.324
97.62,-5.33,0.324
97.63,-5.26,0.324
97.64,-5.20,0.324
97.64,-5.13,0.324
97.65,-5.06,0.324
97.66,-5.00,0.324
97.66,-4.93,0.324
97.67,-4.86,0.324
97.68,-4.80,0.324
97.68,-4.73,0.324
97.69,-4.66,0.324
97.70,-4.60,0.324
97.70,-4.53,0.324
97.71,-4.46,0.324
97.72,-4.39,0.324
97.72,-4.33,0.324
97.73,-4.26,0.324
97.74,-4.20,0.324
97.74,-4.13,0.324
97.75,-4.06,0.324
97.76,-4.00,0.324
97.76,-3.93,0.324
97.77,-3.86,0.324
97.78,-3.79,0.324
97.78,-3.73,0.324
97.79,-3.66,0.324
97.80,-3.59,0.324
97.80,-3.53,0.324
97.81,-3.46,0.324
97.82,-3.40,0.324
97.82,-3.33,0.324
97.83,-3.26,0.324
97.84,-3.19,0.324
97.84,-3.13,0.324
97.85,-3.06,0.324
97.86,-2.99,0.324
97.86,-2.93,0.324
97.87,-2.86,0.324
97.88,-2.79,0.324
97.88,-2.73,0.324
97.89,-2.66,0.324
97.90,-2.59,0.324
97.90,-2.53,0.324
97.91,-2.46,0.324
97.92,-2.39,0.324
97.92,-2.33,0.324
97.93,-2.26,0.324
97.94,-2.19,0.324
97.94,-2.13,0.325
97.95,-2.06,0.325
97.96,-1.99,0.325
97.96,-1.92,0.325
97.97,-1.86,0.325
97.98,-1.79,0.325
97.98,-1.72,0.325
97.99,-1.66,0.325
98.00,-1.59,0.325
98.00,-1.52,0.325
98.01,-1.46,0.325
98.02,-1.39,0.325
98.02,-1.32,0.325
98.03,-1.26,0.325
98.04,-1.19,0.325
98.04,-1.12,0.325
98.05,-1.06,0.325
98.06,-0.99,0.325
98.06,-0.92,0.325
98.07,-0.86,0.325
98.08,-0.79,0.325
98.08,-0.72,0.325
98.09,-0.66,0.325
98.10,-0.59,0.325
98.10,-0.52,0.325
98.11,-0.46,0.325
98.12,-0.39,0.325
98.12,-0.32,0.325
98.13,-0.26,0.325
98.14,-0.19,0.325
98.14,-0.12,0.325
98.15,-0.06,0.325
98.16,0.01,0.325
98.16,0.08,0.325
98.17,0.14,0.325
98.18,0.21,0.325
98.18,0.28,0.325
98.19,0.34,0.325
98.20,0.41,0.325
98.20,0.48,0.325
98.21,0.55,0.325
98.22,0.61,0.325
98.22,0.68,0.325
98.23,0.74,0.325
98.24,0.81,0.325
98.24,0.88,0.325
98.25,0.94,0.325
98.26,1.01,0.325
98.26,1.08,0.325
98.27,1.14,0.325
98.28,1.21,0.325
98.28,1.28,0.325
98.29,1.35,0.325
98.30,1.41,0.326
98.30,1.48,0.326
98.31,1.55,0.326
98.32,1.61,0.326
98.32,1.68,0.326
98.33,1.75,0.326
98.34,1.81,0.326
98.34,1.88,0.326
98.35,1.95,0.326
98.36,2.01,0.326
98.36,2.08,0.326
98.37,2.15,0.326
98.38,2.22,0.326
98.38,2.28,0.326
98.39,2.35,0.326
98.40,2.41,0.326
98.40,2.48,0.326
98.41,2.55,0.326
98.42,2.61,0.326
98.42,2.68,0.326
98.43,2.75,0.326
98.44,2.81,0.326
98.44,2.88,0.326
98.45,2.95,0.326
98.46,3.02,0.326
98.46,3.08,0.327
98.47,3.15,0.327
98.48,3.22,0.327
98.48,3.28,0.327
98.49,3.35,0.327
98.50,3.42,0.327
98.50,3.48,0.327
98.51,3.55,0.327
98.52,3.62,0.327
98.52,3.68,0.327
98.53,3.75,0.327
98.54,3.82,0.327
98.54,3.88,0.327
98.55,3.95,0.327
98.56,4.02,0.327
98.56,4.08,0.327
98.57,4.15,0.327
98.58,4.22,0.327
98.58,4.28,0.327
98.59,4.35,0.327
98.60,4.42,0.327
98.60,4.48,0.327
98.61,4.55,0.327
98.62,4.62,0.327
98.62,4.68,0.327
98.63,4.75,0.328
98.64,4.82,0.328
98.64,4.88,0.328
98.65,4.95,0.328
98.66,5.02,0.328
98.66,5.08,0.328
98.67,5.15,0.328
98.68,5.22,0.328
98.68,5.28,0.328
98.69,5.35,0.328
98.70,5.42,0.328
98.70,5.49,0.328
98.71,5.55,0.328
98.72,5.62,0.328
98.72,5.68,0.328
98.73,5.75,0.328
98.74,5.82,0.328
98.74,5.89,0.328
98.75,5.95,0.328
98.76,6.02,0.328
98.76,6.09,0.328
98.77,6.15,0.328
98.78,6.22,0.328
98.78,6.29,0.329
98.79,6.35,0.328
98.80,6.42,0.329
98.80,6.48,0.329
98.81,6.55,0.329
98.82,6.62,0.329
98.82,6.69,0.329
98.83,6.75,0.329
98.84,6.82,0.329
98.84,6.89,0.329
98.85,6.95,0.329
98.86,7.02,0.329
98.86,7.09,0.329
98.87,7.15,0.329
98.88,7.22,0.329
98.88,7.29,0.329
98.89,7.35,0.329
98.90,7.42,0.329
98.90,7.49,0.329
98.91,7.55,0.329
98.92,7.62,0.329
98.92,7.69,0.329
98.93,7.75,0.330
98.94,7.82,0.330
98.94,7.89,0.330
98.95,7.96,0.330
98.96,8.02,0.330
98.96,8.09,0.330
98.97,8.15,0.330
98.98,8.22,0.330
98.98,8.29,0.330
98.99,8.36,0.330
99.00,8.42,0.330
99.00,8.49,0.330
99.01,8.56,0.330
99.02,8.62,0.330
99.02,8.69,0.330
99.03,8.76,0.330
99.04,8.82,0.331
99.04,8.89,0.331
99.05,8.96,0.331
99.06,9.02,0.331
99.06,9.09,0.331
99.07,9.16,0.331
99.08,9.22,0.331
99.08,9.29,0.331
99.09,9.36,0.331
99.10,9.42,0.331
99.10,9.49,0.331
99.11,9.56,0.331
99.12,9.62,0.331
99.12,9.69,0.331
99.13,9.76,0.331
99.14,9.82,0.331
99.14,9.89,0.331
99.15,9.96,0.332
99.16,10.02,0.332
99.16,10.09,0.332
99.17,10.16,0.332
99.18,10.22,0.332
99.18,10.29,0.332
99.19,10.36,0.332
99.20,10.42,0.332
99.20,10.49,0.332
99.21,10.56,0.332
99.22,10.62,0.332
99.22,10.69,0.332
99.23,10.76,0.332
99.24,10.82,0.332
99.24,10.89,0.332
99.25,10.96,0.332
99.26,11.02,0.332
99.26,11.09,0.332
99.27,11.16,0.332
99.28,11.23,0.332
99.28,11.29,0.332
99.29,11.36,0.333
99.30,11.42,0.333
99.30,11.49,0.333
99.31,11.56,0.333
99.32,11.63,0.333
99.32,11.69,0.333
99.33,11.76,0.333
99.34,11.83,0.333
99.34,11.89,0.333
99.35,11.96,0.333
99.36,12.03,0.333
99.36,12.09,0.333
99.37,12.16,0.333
99.38,12.23,0.333
99.38,12.29,0.333
99.39,12.36,0.333
99.40,12.43,0.333
99.40,12.49,0.333
99.41,12.56,0.333
99.42,12.63,0.333
99.42,12.69,0.333
99.43,12.76,0.333
99.44,12.83,0.334
99.44,12.89,0.334
99.45,12.96,0.334
99.46,13.03,0.334
99.46,13.09,0.334
99.47,13.16,0.334
99.48,13.23,0.334
99.48,13.29,0.334
99.49,13.36,0.334
99.50,13.43,0.334
99.50,13.49,0.334
99.51,13.56,0.334
99.52,13.63,0.334
99.52,13.69,0.334
99.53,13.76,0.334
99.54,13.83,0.334
99.54,13.89,0.334
99.55,13.96,0.334
99.56,14.03,0.334
99.56,14.09,0.335
99.57,14.16,0.335
99.58,14.23,0.335
99.58,14.30,0.335
99.59,14.36,0.335
99.60,14.43,0.335
99.60,14.50,0.335
99.61,14.56,0.335
99.62,14.63,0.335
99.62,14.70,0.335
99.63,14.76,0.335
99.64,14.83,0.335
99.64,14.90,0.335
99.65,14.96,0.335
99.66,15.03,0.335
99.66,15.10,0.335
99.67,15.16,0.335
99.68,15.23,0.335
99.68,15.30,0.335
99.69,15.36,0.336
99.70,15.43,0.336
99.70,15.50,0.336
99.71,15.56,0.336
99.72,15.63,0.336
99.72,15.70,0.336
99.73,15.76,0.336
99.74,15.83,0.336
99.74,15.90,0.336
99.75,15.96,0.336
99.76,16.03,0.336
99.76,16.10,0.336
99.77,16.16,0.336
99.78,16.23,0.336
99.78,16.30,0.336
99.79,16.37,0.336
99.80,16.43,0.337
99.80,16.50,0.337
99.81,16.56,0.337
99.82,16.63,0.337
99.82,16.70,0.337
99.83,16.77,0.337
99.84,16.83,0.337
99.84,16.90,0.337
99.85,16.96,0.337
99.86,17.03,0.337
99.86,17.10,0.337
99.87,17.16,0.337
99.88,17.23,0.337
99.88,17.30,0.337
99.89,17.37,0.337
99.90,17.43,0.337
99.90,17.50,0.337
99.91,17.57,0.337
99.92,17.63,0.337
99.92,17.70,0.337
99.93,17.77,0.337
99.94,17.83,0.337
99.94,17.90,0.338
99.95,17.97,0.338
99.96,18.03,0.338
99.96,18.10,0.338
99.97,18.17,0.338
99.98,18.23,0.338
99.98,18.30,0.338
99.99,18.37,0.338
100.00,18.43,0.338
100.00,18.50,0.338
100.01,18.57,0.338
100.02,18.63,0.338
100.02,18.70,0.338
100.03,18.77,0.338
100.04,18.83,0.338
100.04,18.90,0.339
100.05,18.97,0.339
100.06,19.03,0.339
100.06,19.10,0.339
100.07,19.17,0.339
100.08,19.23,0.339
100.08,19.30,0.339
100.09,19.37,0.339
100.10,19.43,0.339
100.10,19.50,0.339
100.11,19.57,0.339
100.12,19.63,0.339
100.12,19.70,0.339
100.13,19.77,0.339
100.14,19.83,0.339
100.14,19.90,0.340
100.15,19.97,0.340
100.16,20.04,0.340
100.16,20.10,0.340
100.17,20.17,0.340
100.18,20.24,0.340
100.18,20.30,0.340
100.19,20.37,0.340
100.20,20.44,0.340
100.20,20.50,0.340
100.21,20.57,0.340
100.22,20.63,0.340
100.22,20.70,0.340
100.23,20.77,0.340
100.24,20.84,0.340
100.24,20.90,0.340
100.25,20.97,0.340
100.26,21.04,0.341
100.26,21.10,0.341
100.27,21.17,0.341
100.28,21.24,0.341
100.28,21.30,0.341
100.29,21.37,0.341
100.30,21.44,0.341
100.30,21.50,0.341
100.31,21.57,0.341
100.32,21.64,0.341
100.32,21.70,0.341
100.33,21.77,0.342
100.34,21.84,0.342
100.34,21.91,0.342
100.35,21.97,0.342
100.36,22.04,0.342
100.36,22.10,0.342
100.37,22.17,0.342
100.38,22.24,0.342
100.38,22.30,0.342
100.39,22.37,0.342
100.40,22.44,0.342
100.40,22.51,0.342
100.41,22.57,0.342
100.42,22.64,0.342
100.42,22.70,0.342
100.43,22.77,0.342
100.44,22.84,0.342
100.44,22.91,0.342
100.45,22.97,0.342
100.46,23.04,0.342
100.46,23.11,0.342
100.47,23.17,0.342
100.48,23.24,0.342
100.48,23.31,0.342
100.49,23.37,0.342
100.50,23.44,0.343
100.50,23.51,0.343
100.51,23.57,0.343
100.52,23.64,0.343
100.52,23.71,0.343
100.53,23.77,0.343
100.54,23.84,0.343
100.54,23.91,0.343
100.55,23.97,0.343
100.56,24.04,0.343
100.56,24.11,0.343
100.57,24.17,0.343
100.58,24.24,0.343
100.58,24.31,0.343
100.59,24.37,0.344
100.60,24.44,0.344
100.60,24.51,0.344
100.61,24.57,0.344
100.62,24.64,0.344
100.62,24.71,0.344
100.63,24.77,0.344
100.64,24.84,0.344
100.64,24.91,0.344
100.65,24.97,0.344
100.66,25.04,0.344
100.66,25.11,0.344
100.67,25.18,0.344
100.68,25.24,0.344
100.68,25.31,0.344
100.69,25.37,0.345
100.70,25.44,0.345
100.70,25.51,0.345
100.71,25.57,0.345
100.72,25.64,0.345
100.72,25.71,0.345
100.73,25.78,0.345
100.74,25.84,0.345
100.74,25.91,0.345
100.75,25.98,0.345
100.76,26.04,0.345
100.76,26.11,0.345
100.77,26.18,0.345
100.78,26.24,0.345
100.78,26.31,0.345
100.79,26.38,0.346
100.80,26.44,0.346
100.80,26.51,0.346
100.81,26.58,0.346
100.82,26.64,0.346
100.82,26.71,0.346
100.83,26.78,0.346
100.84,26.84,0.346
100.84,26.91,0.346
100.85,26.98,0.346
100.86,27.04,0.346
100.86,27.11,0.346
100.87,27.18,0.346
100.88,27.24,0.346
100.88,27.31,0.346
100.89,27.38,0.346
100.90,27.44,0.347
100.90,27.51,0.347
100.91,27.58,0.347
100.92,27.64,0.347
100.92,27.71,0.347
100.93,27.78,0.347
100.94,27.85,0.347
100.94,27.91,
100.95,27.98,
100.96,28.05,
100.96,28.11,
100.97,28.18,
100.98,28.25,
100.98,28.31,
100.99,,
101.00,,