File: DSC/2025_04_21_CBN_Glutamic_Acid_MC_n60C_150C_5Cmin_x3.csv
Filename,2025_04_21_CBN_Glutamic_Acid_MC_n60C_150C_5Cmin_x3
Instrument name,DSC2A-00468 (192.168.1.100)
Operator,Yarger
rundate,4/22/2025
Sample name,2025_04_21_CBN_Glutamic_Acid_MC_n60C_150C_5Cmin_x3
proceduresegments,Data Off ; Equilibrate -60.00 °C; Data On ; Ramp 5.00 °C/min to 150.00 °C; Data Off ; Isothermal 1.0 min; Data On ; Ramp 10.00 °C/min to -60.00 °C; Data Off ; Isothermal 1.0 min; Data On ; Ramp 5.00 °C/min to 150.00 °C; Data Off ; Isothermal 1.0 min; Data On ; Ramp 10.00 °C/min to -60.00 °C; Data Off ; Isothermal 1.0 min; Data On ; Ramp 5.00 °C/min to 150.00 °C
[File Parameters]
Run date,4/22/2025 4:52:29 AM
Trios version,5.1.1.46572
Original File Name,
Current File Name,D:\DSC2500\JYarger\2025_04_21_CBN_Glutamic_Acid_MC_n60C_150C_5Cmin_x3.tri
[Procedure]
Procedure Name,CBN_Glutamic_Acid_n60_150C_5Cmin_x3
Sample Name,2025_04_21_CBN_Glutamic_Acid_MC_n60C_150C_5Cmin_x3
Sample Mass,5.77 mg
Reference Sample Mass,0 mg
Pan Mass,52.44 mg
Pan Number,12
Reference Pan Mass,52.66 mg
Reference Pan Number,19
Pan Type,Tzero Aluminum Hermetic
Comments,Al Hermetic DSC Consumables sealed Pan/Lid.
Project Name,CA
Operator,Yarger
Test,Custom
Unload Max Temperature,30
Unload Min Temperature,30
Load Max Temperature,30
Load Min Temperature,30
Stop on Gas Flow Error,Yes
[Signal List]
Signal #1,Time (min)
Signal #2,Temperature (°C)
Signal #3,Heat Flow (mW)
Signal #4,Delta T (µV)
Signal #5,Delta Tzero (µV)
Signal #6,Tzero Temperature (°C)
Signal #7,Cell Purge (mL/min)
Signal #8,Heater Temp (°C)
Signal #9,Power Delivered (W)
Signal #10,Reference Junction Temperature (°C)
Signal #11,Flange Temperature (°C)
Signal #12,Heat Flow Phase (rad)
Signal #13,Total Heat Capacity (J/°C)
Signal #14,Heat Capacity (J/°C)
[Configuration]
Company Name,ASU
Instrument Name,DSC2A-00468
Instrument Type,DSC2500
Serial Number,DSC2A-00468
IP,192.168.1.100
Location of Instrument,MRRC
DisplayType,Unknown
Sample Interval ,0.1 s/pt
Selected Heat Flow,T4P
Exotherm Direction,Down
Cell Serial,DRC2-00792
Lid Type,Standard
Cooler,RCS 90
Leave Cooler on at End of Sequence,On
Gas 2,Nitrogen
Gas Selected,Channel 1
Flow Rate,50 mL/min
Secondary Purge,On
Licensed Heat Flow,Heat Flow T4P
Modulation Licensed,Yes
[Versions]
Common IDD Version,1
Cortex Version,VER 2.10.2.31
Driver,5.0.0.6
GDM Version,1.0.3.3
TouchscreenVersion,1.0.0.16145
FEP Version,1.2.1.21
FEP Bootloader,2.0.0.5
AutoSampler Version,2.1.1.26
Auto Sampler Bootloader,2.0.0.5
FCM Version,1.1.0.3
FCM Bootloader,2.0.0.5
[Experiment Logs]
Experiment Log Entry # 1,Data On set to 0
Experiment Log Entry # 3,Equilibrate Segment -60 (C) Started
Experiment Log Entry # 5,Air Cool is off.
Experiment Log Entry # 7,Data On set to 1
Experiment Log Entry # 9,Ramp Segment 5 C/min to 150 Started
Experiment Log Entry # 11,Data On set to 0
Experiment Log Entry # 13,Isothermal Segment 1 min started
Experiment Log Entry # 15,Data On set to 1
Experiment Log Entry # 17,Ramp Segment 10 C/min to -60 Started
Experiment Log Entry # 19,Data On set to 0
Experiment Log Entry # 21,Isothermal Segment 1 min started
Experiment Log Entry # 23,Data On set to 1
Experiment Log Entry # 25,Ramp Segment 5 C/min to 150 Started
Experiment Log Entry # 27,Auto sampler has detected that FCM has gone offline
Experiment Log Entry # 29,Data On set to 0
Experiment Log Entry # 31,Isothermal Segment 1 min started
Experiment Log Entry # 33,Data On set to 1
Experiment Log Entry # 35,Ramp Segment 10 C/min to -60 Started
Experiment Log Entry # 37,Data On set to 0
Experiment Log Entry # 39,Isothermal Segment 1 min started
Experiment Log Entry # 41,Data On set to 1
Experiment Log Entry # 43,Ramp Segment 5 C/min to 150 Started
[Method Log]
Method Log Entry # 1,Data Off
Method Log Entry # 2,Equilibrate -60 °C
Method Log Entry # 3,Data On
Method Log Entry # 4,(Ramp 932502) Ramp 5 °C/minute to 150 °C
Method Log Entry # 5,Data Off
Method Log Entry # 6,Isothermal 1 minutes
Method Log Entry # 7,Data On
Method Log Entry # 8,(Ramp 932506) Ramp 10 °C/minute to -60 °C
Method Log Entry # 9,Data Off
Method Log Entry # 10,Isothermal 1 minutes
Method Log Entry # 11,Data On
Method Log Entry # 12,(Ramp 932510) Ramp 5 °C/minute to 150 °C
Method Log Entry # 13,Data Off
Method Log Entry # 14,Isothermal 1 minutes
Method Log Entry # 15,Data On
Method Log Entry # 16,(Ramp 932514) Ramp 10 °C/minute to -60 °C
Method Log Entry # 17,Data Off
Method Log Entry # 18,Isothermal 1 minutes
Method Log Entry # 19,Data On
Method Log Entry # 20,(Ramp 932518) Ramp 5 °C/minute to 150 °C
Cell Serial,DRC2-00792
[T1 Calibration]
Slope,-0.008529666
Offset,9.636258
Initial Temperature,98.23
GUID,f8bfdadc-4977-4fdf-ba6d-0ba9134940c3
[TZero Calibration]
Date Applied,11/29/2022 4:06:13 PM
Description,From -89.059 °C to 396.009 °C at 20.000°C/min
Gas Type,Nitrogen
Pan Type,None
Source Files 1,C:\Users\yargerlab\Desktop\DSC Data\General\TZero_calibration_11_29_22_2nd(2).tri
Source Files 2,C:\Users\yargerlab\Desktop\DSC Data\General\TZero_calibration_11_29_22_2nd(3).tri
Delta T Offset,13.05235
Delta T Slope,-0.007271007
Delta T0 Offset,-13.69128
Delta T0 Slope,0.06063341
[Temperature Calibration]
Date Applied,11/29/2022 7:12:28 PM
Description,From 106.590 °C to 186.590 °C at 10.000°C/min
Gas Type,Nitrogen
Pan Type,Tzero Aluminum Hermetic
Source Files 1,C:\Users\yargerlab\Desktop\DSC Data\General\Indium(6).tri
Measured 1,157.391
Known 1,156.598
[Cell Constant Calibration]
Date Applied,11/29/2022 7:12:29 PM
Description,From 106.590 °C to 186.590 °C at 10.000°C/min
Gas Type,Nitrogen
Pan Type,Tzero Aluminum Hermetic
Source Files 1,C:\Users\yargerlab\Desktop\DSC Data\General\Indium(6).tri
T4P KCell,1.006051
Onset Slope,63.26126 mW/°C
[Direct Cp Calibration]
Date Applied,11/30/2022 11:04:51 AM
Description,From -79.983 °C to 298.409 °C at 10.000°C/min
Gas Type,Nitrogen
Pan Type,Tzero Aluminum Hermetic
Source Files 1,C:\Users\yargerlab\Desktop\DSC Data\General\Sapphire_Heat_Capacity_11_30_22.tri
[Rev Cp Calibration]
Date Applied,11/30/2022 1:58:51 PM
Description,From -79.996 °C to 292.812 °C at 3.000°C/min
Gas Type,Nitrogen
Pan Type,Tzero Aluminum Hermetic
Source Files 1,C:\Users\yargerlab\Desktop\DSC Data\General\Sapphire_MDSC_Calibration_11_30_22.tri
[step]
Ramp 5.00 °C/min to 150.00 °C
Time,Temperature,Heat Flow (Normalized)
min,°C,W/g
0.00,-59.68,-0.056
0.03,-59.70,-0.055
0.06,-59.70,-0.048
0.08,-59.68,-0.050
0.11,-59.63,-0.052
0.14,-59.55,-0.051
0.17,-59.46,-0.032
0.20,-59.35,-0.013
0.23,-59.24,0.002
0.26,-59.13,0.017
0.28,-59.01,0.026
0.31,-58.88,0.033
0.34,-58.75,0.040
0.37,-58.63,0.045
0.40,-58.49,0.049
0.43,-58.36,0.053
0.45,-58.23,0.055
0.48,-58.09,0.057
0.51,-57.96,0.059
0.54,-57.82,0.060
0.57,-57.69,0.061
0.60,-57.55,0.061
0.62,-57.41,0.062
0.65,-57.28,0.063
0.68,-57.14,0.063
0.71,-57.00,0.064
0.74,-56.86,0.064
0.77,-56.72,0.064
0.79,-56.58,0.065
0.82,-56.44,0.065
0.85,-56.30,0.065
0.88,-56.16,0.066
0.91,-56.03,0.066
0.93,-55.89,0.066
0.96,-55.75,0.067
0.99,-55.61,0.067
1.02,-55.47,0.067
1.05,-55.33,0.067
1.08,-55.18,0.067
1.11,-55.04,0.068
1.13,-54.90,0.068
1.16,-54.76,0.068
1.19,-54.62,0.068
1.22,-54.48,0.068
1.25,-54.34,0.068
1.28,-54.20,0.068
1.30,-54.06,0.068
1.33,-53.92,0.068
1.36,-53.78,0.069
1.39,-53.64,0.069
1.42,-53.50,0.069
1.44,-53.36,0.069
1.47,-53.21,0.069
1.50,-53.07,0.069
1.53,-52.93,0.069
1.56,-52.79,0.069
1.59,-52.65,0.069
1.62,-52.51,0.069
1.64,-52.37,0.069
1.67,-52.23,0.069
1.70,-52.09,0.069
1.73,-51.94,0.069
1.76,-51.80,0.069
1.78,-51.66,0.069
1.81,-51.52,0.069
1.84,-51.38,0.069
1.87,-51.24,0.069
1.90,-51.10,0.069
1.93,-50.95,0.069
1.96,-50.81,0.069
1.98,-50.67,0.069
2.01,-50.53,0.069
2.04,-50.39,0.069
2.07,-50.25,0.069
2.10,-50.11,0.069
2.13,-49.97,0.069
2.15,-49.82,0.069
2.18,-49.68,0.069
2.21,-49.54,0.069
2.24,-49.40,0.069
2.27,-49.26,0.069
2.29,-49.12,0.069
2.32,-48.97,0.069
2.35,-48.83,0.069
2.38,-48.69,0.069
2.41,-48.55,0.069
2.44,-48.41,0.069
2.46,-48.27,0.069
2.49,-48.13,0.069
2.52,-47.98,0.069
2.55,-47.84,0.069
2.58,-47.70,0.069
2.61,-47.56,0.069
2.64,-47.42,0.069
2.66,-47.28,0.069
2.69,-47.14,0.069
2.72,-46.99,0.069
2.75,-46.85,0.069
2.78,-46.71,0.069
2.81,-46.57,0.069
2.83,-46.43,0.069
2.86,-46.29,0.069
2.89,-46.15,0.069
2.92,-46.00,0.069
2.95,-45.86,0.069
2.98,-45.72,0.069
3.00,-45.58,0.069
3.03,-45.44,0.069
3.06,-45.30,0.069
3.09,-45.15,0.069
3.12,-45.01,0.068
3.14,-44.87,0.068
3.17,-44.73,0.069
3.20,-44.59,0.069
3.23,-44.45,0.069
3.26,-44.30,0.068
3.29,-44.16,0.069
3.31,-44.02,0.068
3.34,-43.88,0.068
3.37,-43.74,0.068
3.40,-43.60,0.068
3.43,-43.45,0.068
3.46,-43.31,0.068
3.49,-43.17,0.068
3.51,-43.03,0.068
3.54,-42.89,0.068
3.57,-42.74,0.068
3.60,-42.60,0.068
3.63,-42.46,0.068
3.66,-42.32,0.068
3.68,-42.18,0.069
3.71,-42.04,0.068
3.74,-41.90,0.068
3.77,-41.75,0.068
3.80,-41.61,0.068
3.83,-41.47,0.068
3.85,-41.33,0.068
3.88,-41.19,0.069
3.91,-41.04,0.068
3.94,-40.90,0.069
3.97,-40.76,0.069
3.99,-40.62,0.069
4.02,-40.48,0.069
4.05,-40.34,0.069
4.08,-40.19,0.069
4.11,-40.05,0.069
4.14,-39.91,0.069
4.16,-39.77,0.069
4.19,-39.63,0.069
4.22,-39.48,0.069
4.25,-39.34,0.069
4.28,-39.20,0.069
4.31,-39.06,0.069
4.34,-38.92,0.069
4.36,-38.78,0.069
4.39,-38.63,0.069
4.42,-38.49,0.069
4.45,-38.35,0.069
4.48,-38.21,0.069
4.50,-38.07,0.069
4.53,-37.92,0.069
4.56,-37.78,0.069
4.59,-37.64,0.069
4.62,-37.50,0.069
4.65,-37.36,0.069
4.68,-37.22,0.069
4.70,-37.07,0.069
4.73,-36.93,0.069
4.76,-36.79,0.069
4.79,-36.65,0.069
4.82,-36.51,0.069
4.85,-36.36,0.069
4.87,-36.22,0.069
4.90,-36.08,0.069
4.93,-35.94,0.069
4.96,-35.80,0.069
4.99,-35.66,0.069
5.01,-35.51,0.069
5.04,-35.37,0.069
5.07,-35.23,0.069
5.10,-35.09,0.069
5.13,-34.95,0.069
5.16,-34.80,0.069
5.19,-34.66,0.069
5.21,-34.52,0.069
5.24,-34.38,0.069
5.27,-34.24,0.069
5.30,-34.09,0.069
5.33,-33.95,0.069
5.35,-33.81,0.069
5.38,-33.67,0.069
5.41,-33.53,0.069
5.44,-33.39,0.069
5.47,-33.24,0.069
5.50,-33.10,0.069
5.53,-32.96,0.069
5.55,-32.82,0.069
5.58,-32.68,0.069
5.61,-32.53,0.069
5.64,-32.39,0.069
5.67,-32.25,0.069
5.70,-32.11,0.069
5.72,-31.97,0.069
5.75,-31.83,0.069
5.78,-31.68,0.069
5.81,-31.54,0.069
5.84,-31.40,0.069
5.86,-31.26,0.069
5.89,-31.12,0.069
5.92,-30.98,0.069
5.95,-30.83,0.069
5.98,-30.69,0.069
6.01,-30.55,0.069
6.04,-30.41,0.069
6.06,-30.27,0.070
6.09,-30.13,0.069
6.12,-29.98,0.069
6.15,-29.84,0.070
6.18,-29.70,0.069
6.20,-29.56,0.070
6.23,-29.41,0.070
6.26,-29.27,0.070
6.29,-29.13,0.070
6.32,-28.99,0.070
6.35,-28.85,0.070
6.38,-28.71,0.070
6.40,-28.56,0.070
6.43,-28.42,0.070
6.46,-28.28,0.070
6.49,-28.14,0.070
6.52,-28.00,0.070
6.55,-27.86,0.070
6.57,-27.71,0.070
6.60,-27.57,0.070
6.63,-27.43,0.070
6.66,-27.29,0.070
6.69,-27.15,0.070
6.71,-27.01,0.070
6.74,-26.86,0.070
6.77,-26.72,0.070
6.80,-26.58,0.070
6.83,-26.44,0.070
6.86,-26.30,0.070
6.89,-26.15,0.070
6.91,-26.01,0.070
6.94,-25.87,0.070
6.97,-25.73,0.070
7.00,-25.59,0.070
7.03,-25.44,0.070
7.05,-25.30,0.070
7.08,-25.16,0.070
7.11,-25.02,0.070
7.14,-24.88,0.070
7.17,-24.74,0.070
7.20,-24.59,0.070
7.23,-24.45,0.070
7.25,-24.31,0.070
7.28,-24.17,0.070
7.31,-24.03,0.070
7.34,-23.89,0.070
7.37,-23.74,0.070
7.40,-23.60,0.070
7.42,-23.46,0.070
7.45,-23.32,0.070
7.48,-23.18,0.070
7.51,-23.04,0.071
7.54,-22.89,0.071
7.56,-22.75,0.071
7.59,-22.61,0.071
7.62,-22.47,0.071
7.65,-22.32,0.071
7.68,-22.18,0.071
7.71,-22.04,0.071
7.74,-21.90,0.071
7.76,-21.76,0.071
7.79,-21.62,0.071
7.82,-21.47,0.071
7.85,-21.33,0.071
7.88,-21.19,0.071
7.90,-21.05,0.071
7.93,-20.91,0.071
7.96,-20.77,0.071
7.99,-20.62,0.071
8.02,-20.48,0.071
8.05,-20.34,0.071
8.08,-20.20,0.071
8.10,-20.06,0.071
8.13,-19.91,0.071
8.16,-19.77,0.071
8.19,-19.63,0.071
8.22,-19.49,0.071
8.25,-19.35,0.071
8.27,-19.21,0.071
8.30,-19.06,0.071
8.33,-18.92,0.071
8.36,-18.78,0.071
8.39,-18.64,0.071
8.41,-18.50,0.071
8.44,-18.36,0.071
8.47,-18.21,0.071
8.50,-18.07,0.071
8.53,-17.93,0.071
8.56,-17.79,0.071
8.58,-17.65,0.072
8.61,-17.51,0.072
8.64,-17.36,0.072
8.67,-17.22,0.072
8.70,-17.08,0.072
8.73,-16.94,0.072
8.75,-16.80,0.072
8.78,-16.65,0.072
8.81,-16.51,0.072
8.84,-16.37,0.072
8.87,-16.23,0.072
8.90,-16.09,0.072
8.93,-15.94,0.072
8.95,-15.80,0.072
8.98,-15.66,0.072
9.01,-15.52,0.072
9.04,-15.38,0.072
9.07,-15.24,0.072
9.10,-15.10,0.072
9.12,-14.95,0.072
9.15,-14.81,0.072
9.18,-14.67,0.072
9.21,-14.53,0.072
9.24,-14.39,0.072
9.27,-14.24,0.072
9.29,-14.10,0.072
9.32,-13.96,0.072
9.35,-13.82,0.072
9.38,-13.68,0.072
9.41,-13.53,0.072
9.43,-13.39,0.072
9.46,-13.25,0.072
9.49,-13.11,0.072
9.52,-12.97,0.073
9.55,-12.83,0.073
9.58,-12.68,0.073
9.60,-12.54,0.073
9.63,-12.40,0.073
9.66,-12.26,0.073
9.69,-12.12,0.073
9.72,-11.98,0.073
9.75,-11.83,0.073
9.78,-11.69,0.073
9.80,-11.55,0.073
9.83,-11.41,0.073
9.86,-11.27,0.073
9.89,-11.13,0.073
9.92,-10.98,0.073
9.95,-10.84,0.073
9.97,-10.70,0.073
10.00,-10.56,0.073
10.03,-10.42,0.073
10.06,-10.27,0.073
10.09,-10.13,0.073
10.12,-9.99,0.073
10.14,-9.85,0.073
10.17,-9.71,0.073
10.20,-9.57,0.073
10.23,-9.42,0.073
10.26,-9.28,0.073
10.28,-9.14,0.073
10.31,-9.00,0.073
10.34,-8.86,0.073
10.37,-8.72,0.073
10.40,-8.57,0.073
10.43,-8.43,0.073
10.45,-8.29,0.073
10.48,-8.15,0.073
10.51,-8.01,0.073
10.54,-7.87,0.074
10.57,-7.72,0.074
10.60,-7.58,0.074
10.63,-7.44,0.074
10.65,-7.30,0.074
10.68,-7.16,0.074
10.71,-7.01,0.074
10.74,-6.87,0.074
10.77,-6.73,0.074
10.80,-6.59,0.074
10.82,-6.45,0.074
10.85,-6.30,0.074
10.88,-6.16,0.074
10.91,-6.02,0.074
10.94,-5.88,0.074
10.97,-5.74,0.074
10.99,-5.60,0.074
11.02,-5.45,0.074
11.05,-5.31,0.074
11.08,-5.17,0.074
11.11,-5.03,0.074
11.13,-4.89,0.074
11.16,-4.75,0.074
11.19,-4.60,0.074
11.22,-4.46,0.074
11.25,-4.32,0.074
11.28,-4.18,0.075
11.30,-4.04,0.075
11.33,-3.90,0.075
11.36,-3.75,0.075
11.39,-3.61,0.075
11.42,-3.47,0.075
11.45,-3.33,0.075
11.48,-3.19,0.075
11.50,-3.04,0.075
11.53,-2.90,0.075
11.56,-2.76,0.075
11.59,-2.62,0.075
11.62,-2.48,0.075
11.65,-2.34,0.075
11.67,-2.19,0.075
11.70,-2.05,0.075
11.73,-1.91,0.075
11.76,-1.77,0.075
11.79,-1.63,0.075
11.82,-1.48,0.075
11.84,-1.34,0.075
11.87,-1.20,0.075
11.90,-1.06,0.075
11.93,-0.92,0.075
11.96,-0.78,0.075
11.98,-0.63,0.075
12.01,-0.49,0.075
12.04,-0.35,0.076
12.07,-0.21,0.076
12.10,-0.07,0.076
12.13,0.07,0.076
12.15,0.22,0.076
12.18,0.36,0.076
12.21,0.50,0.076
12.24,0.64,0.076
12.27,0.78,0.076
12.30,0.92,0.076
12.33,1.07,0.076
12.35,1.21,0.076
12.38,1.35,0.076
12.41,1.49,0.076
12.44,1.63,0.076
12.47,1.78,0.076
12.50,1.92,0.076
12.52,2.06,0.076
12.55,2.20,0.076
12.58,2.34,0.076
12.61,2.48,0.076
12.64,2.63,0.076
12.67,2.77,0.076
12.69,2.91,0.076
12.72,3.05,0.076
12.75,3.19,0.076
12.78,3.34,0.076
12.81,3.48,0.076
12.83,3.62,0.076
12.86,3.76,0.076
12.89,3.90,0.076
12.92,4.04,0.076
12.95,4.19,0.076
12.98,4.33,0.076
13.00,4.47,0.077
13.03,4.61,0.077
13.06,4.75,0.077
13.09,4.89,0.077
13.12,5.04,0.077
13.15,5.18,0.077
13.18,5.32,0.077
13.20,5.46,0.077
13.23,5.60,0.077
13.26,5.74,0.077
13.29,5.89,0.077
13.32,6.03,0.077
13.35,6.17,0.077
13.37,6.31,0.077
13.40,6.45,0.077
13.43,6.60,0.077
13.46,6.74,0.077
13.49,6.88,0.077
13.52,7.02,0.077
13.54,7.16,0.077
13.57,7.30,0.077
13.60,7.45,0.077
13.63,7.59,0.077
13.66,7.73,0.077
13.68,7.87,0.077
13.71,8.01,0.077
13.74,8.15,0.077
13.77,8.30,0.077
13.80,8.44,0.077
13.83,8.58,0.078
13.85,8.72,0.078
13.88,8.86,0.078
13.91,9.01,0.078
13.94,9.15,0.078
13.97,9.29,0.078
14.00,9.43,0.078
14.03,9.57,0.078
14.05,9.71,0.078
14.08,9.86,0.078
14.11,10.00,0.078
14.14,10.14,0.078
14.17,10.28,0.078
14.20,10.42,0.078
14.22,10.57,0.078
14.25,10.71,0.078
14.28,10.85,0.078
14.31,10.99,0.078
14.34,11.13,0.078
14.37,11.27,0.078
14.39,11.41,0.078
14.42,11.56,0.078
14.45,11.70,0.078
14.48,11.84,0.079
14.51,11.98,0.079
14.53,12.12,0.079
14.56,12.27,0.079
14.59,12.41,0.079
14.62,12.55,0.079
14.65,12.69,0.079
14.68,12.83,0.079
14.70,12.97,0.079
14.73,13.12,0.079
14.76,13.26,0.079
14.79,13.40,0.079
14.82,13.54,0.079
14.85,13.68,0.079
14.88,13.82,0.079
14.90,13.97,0.079
14.93,14.11,0.079
14.96,14.25,0.079
14.99,14.39,0.079
15.02,14.53,0.079
15.05,14.68,0.079
15.07,14.82,0.079
15.10,14.96,0.079
15.13,15.10,0.079
15.16,15.24,0.079
15.19,15.38,0.079
15.22,15.53,0.079
15.24,15.67,0.079
15.27,15.81,0.079
15.30,15.95,0.079
15.33,16.09,0.079
15.36,16.23,0.079
15.38,16.38,0.080
15.41,16.52,0.080
15.44,16.66,0.080
15.47,16.80,0.080
15.50,16.94,0.080
15.53,17.09,0.080
15.55,17.23,0.080
15.58,17.37,0.080
15.61,17.51,0.080
15.64,17.65,0.080
15.67,17.80,0.080
15.70,17.94,0.080
15.73,18.08,0.080
15.75,18.22,0.080
15.78,18.36,0.080
15.81,18.50,0.081
15.84,18.65,0.081
15.87,18.79,0.081
15.90,18.93,0.081
15.92,19.07,0.081
15.95,19.21,0.081
15.98,19.35,0.081
16.01,19.50,0.081
16.04,19.64,0.081
16.07,19.78,0.081
16.09,19.92,0.081
16.12,20.06,0.081
16.15,20.21,0.081
16.18,20.35,0.081
16.21,20.49,0.081
16.23,20.63,0.081
16.26,20.77,0.081
16.29,20.91,0.081
16.32,21.05,0.081
16.35,21.20,0.081
16.38,21.34,0.082
16.40,21.48,0.082
16.43,21.62,0.082
16.46,21.76,0.082
16.49,21.90,0.082
16.52,22.05,0.082
16.55,22.19,0.082
16.58,22.33,0.082
16.60,22.47,0.082
16.63,22.61,0.082
16.66,22.76,0.082
16.69,22.90,0.082
16.72,23.04,0.082
16.75,23.18,0.082
16.77,23.32,0.082
16.80,23.46,0.082
16.83,23.61,0.082
16.86,23.75,0.083
16.89,23.89,0.083
16.92,24.03,0.083
16.94,24.17,0.083
16.97,24.31,0.083
17.00,24.46,0.083
17.03,24.60,0.083
17.06,24.74,0.083
17.08,24.88,0.083
17.11,25.02,0.083
17.14,25.17,0.083
17.17,25.31,0.083
17.20,25.45,0.083
17.23,25.59,0.083
17.26,25.73,0.083
17.28,25.88,0.083
17.31,26.02,0.084
17.34,26.16,0.084
17.37,26.30,0.084
17.40,26.44,0.084
17.43,26.58,0.084
17.45,26.73,0.084
17.48,26.87,0.084
17.51,27.01,0.084
17.54,27.15,0.084
17.57,27.29,0.084
17.59,27.44,0.084
17.62,27.58,0.084
17.65,27.72,0.084
17.68,27.86,0.084
17.71,28.00,0.084
17.74,28.14,0.084
17.77,28.28,0.084
17.79,28.43,0.085
17.82,28.57,0.084
17.85,28.71,0.084
17.88,28.85,0.085
17.91,28.99,0.085
17.93,29.14,0.085
17.96,29.28,0.085
17.99,29.42,0.085
18.02,29.56,0.085
18.05,29.70,0.085
18.08,29.84,0.085
18.11,29.99,0.085
18.13,30.13,0.085
18.16,30.27,0.085
18.19,30.41,0.085
18.22,30.55,0.085
18.25,30.69,0.085
18.28,30.84,0.085
18.30,30.98,0.085
18.33,31.12,0.086
18.36,31.26,0.086
18.39,31.40,0.086
18.42,31.54,0.086
18.44,31.69,0.086
18.47,31.83,0.086
18.50,31.97,0.086
18.53,32.11,0.086
18.56,32.25,0.086
18.59,32.39,0.086
18.62,32.53,0.086
18.64,32.68,0.086
18.67,32.82,0.086
18.70,32.96,0.086
18.73,33.10,0.086
18.76,33.24,0.086
18.78,33.39,0.086
18.81,33.53,0.086
18.84,33.67,0.086
18.87,33.81,0.087
18.90,33.95,0.087
18.93,34.10,0.087
18.96,34.24,0.087
18.98,34.38,0.087
19.01,34.52,0.087
19.04,34.66,0.087
19.07,34.81,0.087
19.10,34.95,0.087
19.13,35.09,0.087
19.15,35.23,0.087
19.18,35.37,0.087
19.21,35.51,0.087
19.24,35.66,0.087
19.27,35.80,0.087
19.29,35.94,0.087
19.32,36.08,0.088
19.35,36.22,0.088
19.38,36.36,0.088
19.41,36.51,0.088
19.44,36.65,0.088
19.47,36.79,0.088
19.49,36.93,0.088
19.52,37.07,0.088
19.55,37.21,0.088
19.58,37.36,0.088
19.61,37.50,0.088
19.63,37.64,0.088
19.66,37.78,0.088
19.69,37.92,0.088
19.72,38.07,0.088
19.75,38.21,0.088
19.78,38.35,0.088
19.81,38.49,0.088
19.83,38.63,0.089
19.86,38.77,0.089
19.89,38.92,0.089
19.92,39.06,0.089
19.95,39.20,0.089
19.98,39.34,0.089
20.00,39.48,0.089
20.03,39.62,0.089
20.06,39.77,0.089
20.09,39.91,0.089
20.12,40.05,0.089
20.14,40.19,0.089
20.17,40.33,0.089
20.20,40.48,0.089
20.23,40.62,0.089
20.26,40.76,0.090
20.29,40.90,0.090
20.32,41.04,0.090
20.34,41.18,0.090
20.37,41.32,0.090
20.40,41.47,0.090
20.43,41.61,0.090
20.46,41.75,0.090
20.48,41.89,0.090
20.51,42.03,0.090
20.54,42.18,0.090
20.57,42.32,0.090
20.60,42.46,0.090
20.63,42.60,0.090
20.66,42.74,0.090
20.68,42.88,0.090
20.71,43.02,0.090
20.74,43.17,0.090
20.77,43.31,0.090
20.80,43.45,0.091
20.83,43.59,0.091
20.85,43.74,0.091
20.88,43.88,0.091
20.91,44.02,0.091
20.94,44.16,0.091
20.97,44.30,0.091
20.99,44.44,0.091
21.02,44.59,0.091
21.05,44.73,0.091
21.08,44.87,0.091
21.11,45.01,0.091
21.14,45.15,0.091
21.17,45.29,0.091
21.19,45.44,0.091
21.22,45.58,0.092
21.25,45.72,0.092
21.28,45.86,0.092
21.31,46.00,0.092
21.33,46.14,0.092
21.36,46.29,0.092
21.39,46.43,0.092
21.42,46.57,0.092
21.45,46.71,0.092
21.48,46.85,0.092
21.51,46.99,0.092
21.53,47.14,0.092
21.56,47.28,0.092
21.59,47.42,0.092
21.62,47.56,0.092
21.65,47.70,0.092
21.68,47.85,0.092
21.70,47.99,0.092
21.73,48.13,0.093
21.76,48.27,0.093
21.79,48.41,0.093
21.82,48.56,0.093
21.84,48.70,0.093
21.87,48.84,0.093
21.90,48.98,0.093
21.93,49.12,0.093
21.96,49.26,0.093
21.99,49.40,0.093
22.02,49.55,0.093
22.04,49.69,0.093
22.07,49.83,0.093
22.10,49.97,0.093
22.13,50.11,0.093
22.16,50.25,0.093
22.18,50.40,0.093
22.21,50.54,0.093
22.24,50.68,0.093
22.27,50.82,0.093
22.30,50.96,0.094
22.33,51.10,0.094
22.36,51.25,0.094
22.38,51.39,0.094
22.41,51.53,0.094
22.44,51.67,0.094
22.47,51.81,0.094
22.50,51.96,0.094
22.53,52.10,0.094
22.55,52.24,0.094
22.58,52.38,0.094
22.61,52.52,0.094
22.64,52.66,0.094
22.67,52.81,0.094
22.69,52.95,0.094
22.72,53.09,0.094
22.75,53.23,0.094
22.78,53.37,0.095
22.81,53.51,0.095
22.84,53.66,0.095
22.87,53.80,0.095
22.89,53.94,0.095
22.92,54.08,0.095
22.95,54.22,0.095
22.98,54.37,0.095
23.01,54.51,0.095
23.03,54.65,0.095
23.06,54.79,0.095
23.09,54.93,0.095
23.12,55.07,0.095
23.15,55.22,0.095
23.18,55.36,0.095
23.21,55.50,0.095
23.23,55.64,0.095
23.26,55.78,0.096
23.29,55.92,0.096
23.32,56.07,0.096
23.35,56.21,0.096
23.38,56.35,0.096
23.40,56.49,0.096
23.43,56.63,0.096
23.46,56.78,0.096
23.49,56.92,0.096
23.52,57.06,0.096
23.54,57.20,0.096
23.57,57.34,0.096
23.60,57.48,0.096
23.63,57.62,0.096
23.66,57.77,0.096
23.69,57.91,0.096
23.72,58.05,0.096
23.74,58.19,0.096
23.77,58.33,0.097
23.80,58.48,0.097
23.83,58.62,0.097
23.86,58.76,0.097
23.88,58.90,0.097
23.91,59.04,0.097
23.94,59.18,0.097
23.97,59.32,0.097
24.00,59.47,0.097
24.03,59.61,0.097
24.06,59.75,0.097
24.08,59.89,0.097
24.11,60.03,0.097
24.14,60.18,0.097
24.17,60.32,0.097
24.20,60.46,0.098
24.23,60.60,0.098
24.25,60.74,0.098
24.28,60.88,0.098
24.31,61.03,0.098
24.34,61.17,0.098
24.37,61.31,0.098
24.39,61.45,0.098
24.42,61.59,0.098
24.45,61.73,0.098
24.48,61.88,0.098
24.51,62.02,0.098
24.54,62.16,0.098
24.57,62.30,0.098
24.59,62.44,0.099
24.62,62.59,0.099
24.65,62.73,0.099
24.68,62.87,0.099
24.71,63.01,0.099
24.73,63.15,0.099
24.76,63.29,0.099
24.79,63.44,0.099
24.82,63.58,0.099
24.85,63.72,0.099
24.88,63.86,0.100
24.91,64.00,0.100
24.93,64.15,0.100
24.96,64.29,0.100
24.99,64.43,0.100
25.02,64.57,0.100
25.05,64.71,0.100
25.08,64.85,0.100
25.10,64.99,0.100
25.13,65.14,0.101
25.16,65.28,0.101
25.19,65.42,0.101
25.22,65.56,0.101
25.24,65.70,0.101
25.27,65.84,0.101
25.30,65.99,0.101
25.33,66.13,0.101
25.36,66.27,0.102
25.39,66.41,0.102
25.42,66.55,0.102
25.44,66.70,0.102
25.47,66.84,0.103
25.50,66.98,0.103
25.53,67.12,0.103
25.56,67.26,0.103
25.58,67.40,0.103
25.61,67.54,0.104
25.64,67.69,0.104
25.67,67.83,0.104
25.70,67.97,0.104
25.73,68.11,0.105
25.76,68.25,0.105
25.78,68.40,0.105
25.81,68.54,0.106
25.84,68.68,0.106
25.87,68.82,0.107
25.90,68.96,0.107
25.93,69.10,0.107
25.95,69.24,0.108
25.98,69.39,0.109
26.01,69.53,0.109
26.04,69.67,0.110
26.07,69.81,0.111
26.09,69.95,0.112
26.12,70.09,0.112
26.15,70.23,0.114
26.18,70.38,0.115
26.21,70.52,0.116
26.24,70.66,0.117
26.27,70.80,0.119
26.29,70.94,0.122
26.32,71.08,0.125
26.35,71.22,0.128
26.38,71.36,0.131
26.41,71.50,0.135
26.43,71.64,0.139
26.46,71.78,0.144
26.49,71.92,0.149
26.52,72.06,0.156
26.55,72.20,0.162
26.58,72.34,0.169
26.61,72.48,0.178
26.63,72.62,0.188
26.66,72.76,0.199
26.69,72.90,0.211
26.72,73.03,0.225
26.75,73.17,0.243
26.78,73.31,0.262
26.80,73.44,0.284
26.83,73.57,0.310
26.86,73.71,0.339
26.89,73.84,0.373
26.92,73.97,0.413
26.94,74.09,0.456
26.97,74.22,0.503
27.00,74.34,0.554
27.03,74.47,0.614
27.06,74.59,0.680
27.09,74.70,0.753
27.12,74.82,0.832
27.14,74.93,0.920
27.17,75.04,1.007
27.20,75.15,1.095
27.23,75.25,1.225
27.26,75.35,1.349
27.28,75.45,1.427
27.31,75.56,1.479
27.34,75.68,1.521
27.37,75.79,1.568
27.40,75.92,1.611
27.43,76.04,1.629
27.46,76.18,1.550
27.48,76.34,1.459
27.51,76.50,1.351
27.54,76.69,1.118
27.57,76.91,0.793
27.60,77.14,0.574
27.63,77.36,0.440
27.65,77.56,0.355
27.68,77.75,0.296
27.71,77.93,0.251
27.74,78.10,0.218
27.77,78.26,0.193
27.79,78.41,0.175
27.82,78.56,0.160
27.85,78.71,0.150
27.88,78.86,0.142
27.91,79.01,0.137
27.94,79.15,0.133
27.97,79.30,0.130
27.99,79.44,0.128
28.02,79.59,0.127
28.05,79.73,0.126
28.08,79.87,0.125
28.11,80.01,0.125
28.13,80.15,0.124
28.16,80.30,0.124
28.19,80.44,0.123
28.22,80.58,0.123
28.25,80.72,0.123
28.28,80.86,0.122
28.31,81.01,0.122
28.33,81.15,0.122
28.36,81.29,0.122
28.39,81.43,0.121
28.42,81.57,0.121
28.45,81.72,0.121
28.48,81.86,0.121
28.50,82.00,0.121
28.53,82.14,0.121
28.56,82.28,0.121
28.59,82.42,0.120
28.62,82.56,0.120
28.64,82.71,0.120
28.67,82.85,0.120
28.70,82.99,0.120
28.73,83.13,0.120
28.76,83.27,0.120
28.79,83.42,0.120
28.82,83.56,0.120
28.84,83.70,0.120
28.87,83.84,0.120
28.90,83.98,0.120
28.93,84.12,0.120
28.96,84.27,0.120
28.98,84.41,0.120
29.01,84.55,0.120
29.04,84.69,0.120
29.07,84.83,0.120
29.10,84.97,0.120
29.13,85.11,0.120
29.16,85.26,0.120
29.18,85.40,0.120
29.21,85.54,0.120
29.24,85.68,0.120
29.27,85.82,0.120
29.30,85.97,0.120
29.33,86.11,0.120
29.35,86.25,0.120
29.38,86.39,0.120
29.41,86.53,0.120
29.44,86.68,0.120
29.47,86.82,0.120
29.49,86.96,0.120
29.52,87.10,0.120
29.55,87.24,0.120
29.58,87.38,0.121
29.61,87.53,0.121
29.64,87.67,0.121
29.67,87.81,0.121
29.69,87.95,0.121
29.72,88.09,0.121
29.75,88.23,0.121
29.78,88.38,0.121
29.81,88.52,0.121
29.83,88.66,0.121
29.86,88.80,0.121
29.89,88.94,0.121
29.92,89.08,0.121
29.95,89.23,0.121
29.98,89.37,0.121
30.01,89.51,0.121
30.03,89.65,0.121
30.06,89.79,0.121
30.09,89.93,0.121
30.12,90.08,0.121
30.15,90.22,0.121
30.18,90.36,0.121
30.20,90.50,0.121
30.23,90.64,0.121
30.26,90.79,0.121
30.29,90.93,0.122
30.32,91.07,0.122
30.34,91.21,0.122
30.37,91.35,0.122
30.40,91.49,0.122
30.43,91.64,0.122
30.46,91.78,0.122
30.49,91.92,0.122
30.52,92.06,0.122
30.54,92.20,0.122
30.57,92.34,0.122
30.60,92.49,0.122
30.63,92.63,0.122
30.66,92.77,0.122
30.68,92.91,0.122
30.71,93.05,0.122
30.74,93.19,0.122
30.77,93.34,0.122
30.80,93.48,0.122
30.83,93.62,0.122
30.86,93.76,0.122
30.88,93.90,0.122
30.91,94.04,0.122
30.94,94.19,0.122
30.97,94.33,0.122
31.00,94.47,0.122
31.03,94.61,0.122
31.05,94.75,0.122
31.08,94.89,0.122
31.11,95.04,0.122
31.14,95.18,0.122
31.17,95.32,0.122
31.19,95.46,0.123
31.22,95.60,0.123
31.25,95.75,0.123
31.28,95.89,0.123
31.31,96.03,0.123
31.34,96.17,0.123
31.37,96.31,0.123
31.39,96.46,0.123
31.42,96.60,0.123
31.45,96.74,0.123
31.48,96.88,0.123
31.51,97.02,0.123
31.53,97.16,0.123
31.56,97.31,0.123
31.59,97.45,0.123
31.62,97.59,0.123
31.65,97.73,0.123
31.68,97.87,0.123
31.71,98.01,0.123
31.73,98.16,0.123
31.76,98.30,0.123
31.79,98.44,0.123
31.82,98.58,0.123
31.85,98.72,0.123
31.88,98.86,0.123
31.90,99.01,0.123
31.93,99.15,0.123
31.96,99.29,0.123
31.99,99.43,0.123
32.02,99.57,0.123
32.04,99.71,0.123
32.07,99.85,0.123
32.10,100.00,0.123
32.13,100.14,0.123
32.16,100.28,0.123
32.19,100.42,0.123
32.22,100.56,0.123
32.24,100.71,0.124
32.27,100.85,0.124
32.30,100.99,0.124
32.33,101.13,0.124
32.36,101.27,0.124
32.38,101.41,0.124
32.41,101.56,0.124
32.44,101.70,0.124
32.47,101.84,0.124
32.50,101.98,0.124
32.53,102.12,0.124
32.56,102.27,0.124
32.58,102.41,0.124
32.61,102.55,0.124
32.64,102.69,0.124
32.67,102.83,0.124
32.70,102.97,0.124
32.73,103.12,0.124
32.75,103.26,0.124
32.78,103.40,0.124
32.81,103.54,0.124
32.84,103.68,0.124
32.87,103.82,0.125
32.89,103.97,0.125
32.92,104.11,0.125
32.95,104.25,0.125
32.98,104.39,0.125
33.01,104.53,0.125
33.04,104.68,0.125
33.07,104.82,0.125
33.09,104.96,0.125
33.12,105.10,0.125
33.15,105.24,0.125
33.18,105.38,0.125
33.21,105.53,0.125
33.23,105.67,0.125
33.26,105.81,0.125
33.29,105.95,0.125
33.32,106.09,0.125
33.35,106.23,0.125
33.38,106.38,0.125
33.41,106.52,0.125
33.43,106.66,0.125
33.46,106.80,0.125
33.49,106.94,0.125
33.52,107.08,0.125
33.55,107.23,0.125
33.58,107.37,0.125
33.60,107.51,0.125
33.63,107.65,0.125
33.66,107.79,0.125
33.69,107.94,0.125
33.72,108.08,0.125
33.74,108.22,0.125
33.77,108.36,0.125
33.80,108.50,0.125
33.83,108.64,0.126
33.86,108.79,0.126
33.89,108.93,0.126
33.92,109.07,0.126
33.94,109.21,0.126
33.97,109.35,0.126
34.00,109.49,0.126
34.03,109.63,0.126
34.06,109.78,0.126
34.08,109.92,0.126
34.11,110.06,0.126
34.14,110.20,0.126
34.17,110.34,0.126
34.20,110.49,0.126
34.23,110.63,0.126
34.26,110.77,0.126
34.28,110.91,0.126
34.31,111.05,0.126
34.34,111.19,0.126
34.37,111.34,0.126
34.40,111.48,0.126
34.43,111.62,0.126
34.45,111.76,0.126
34.48,111.90,0.126
34.51,112.04,0.126
34.54,112.19,0.126
34.57,112.33,0.126
34.59,112.47,0.126
34.62,112.61,0.126
34.65,112.75,0.127
34.68,112.90,0.127
34.71,113.04,0.127
34.74,113.18,0.127
34.76,113.32,0.127
34.79,113.46,0.127
34.82,113.60,0.127
34.85,113.75,0.127
34.88,113.89,0.127
34.91,114.03,0.127
34.94,114.17,0.127
34.96,114.31,0.127
34.99,114.45,0.127
35.02,114.60,0.127
35.05,114.74,0.127
35.08,114.88,0.127
35.11,115.02,0.127
35.13,115.16,0.127
35.16,115.30,0.127
35.19,115.45,0.127
35.22,115.59,0.127
35.25,115.73,0.127
35.28,115.87,0.127
35.30,116.01,0.127
35.33,116.15,0.127
35.36,116.30,0.127
35.39,116.44,0.127
35.42,116.58,0.127
35.44,116.72,0.127
35.47,116.86,0.128
35.50,117.01,0.128
35.53,117.15,0.128
35.56,117.29,0.128
35.59,117.43,0.128
35.61,117.57,0.128
35.64,117.71,0.128
35.67,117.86,0.128
35.70,118.00,0.128
35.73,118.14,0.128
35.76,118.28,0.128
35.79,118.42,0.128
35.81,118.56,0.128
35.84,118.71,0.128
35.87,118.85,0.128
35.90,118.99,0.128
35.93,119.13,0.128
35.96,119.27,0.128
35.98,119.41,0.128
36.01,119.56,0.128
36.04,119.70,0.128
36.07,119.84,0.128
36.10,119.98,0.128
36.13,120.12,0.128
36.15,120.26,0.128
36.18,120.41,0.128
36.21,120.55,0.128
36.24,120.69,0.128
36.27,120.83,0.128
36.29,120.97,0.128
36.32,121.11,0.129
36.35,121.25,0.128
36.38,121.40,0.129
36.41,121.54,0.129
36.44,121.68,0.129
36.46,121.82,0.129
36.49,121.96,0.129
36.52,122.11,0.129
36.55,122.25,0.129
36.58,122.39,0.129
36.61,122.53,0.129
36.64,122.67,0.129
36.66,122.81,0.129
36.69,122.96,0.129
36.72,123.10,0.129
36.75,123.24,0.129
36.78,123.38,0.129
36.81,123.52,0.129
36.83,123.66,0.129
36.86,123.81,0.129
36.89,123.95,0.129
36.92,124.09,0.129
36.95,124.23,0.129
36.98,124.37,0.129
37.00,124.51,0.130
37.03,124.66,0.129
37.06,124.80,0.130
37.09,124.94,0.130
37.12,125.08,0.130
37.14,125.22,0.130
37.17,125.36,0.130
37.20,125.51,0.130
37.23,125.65,0.130
37.26,125.79,0.130
37.29,125.93,0.130
37.31,126.07,0.130
37.34,126.22,0.130
37.37,126.36,0.130
37.40,126.50,0.130
37.43,126.64,0.130
37.46,126.78,0.130
37.49,126.93,0.130
37.51,127.07,0.130
37.54,127.21,0.130
37.57,127.35,0.130
37.60,127.49,0.130
37.63,127.63,0.130
37.66,127.77,0.130
37.68,127.92,0.130
37.71,128.06,0.130
37.74,128.20,0.130
37.77,128.34,0.130
37.80,128.48,0.130
37.83,128.62,0.130
37.85,128.77,0.130
37.88,128.91,0.130
37.91,129.05,0.130
37.94,129.19,0.130
37.97,129.33,0.131
37.99,129.47,0.131
38.02,129.62,0.131
38.05,129.76,0.131
38.08,129.90,0.131
38.11,130.04,0.131
38.14,130.18,0.131
38.16,130.33,0.131
38.19,130.47,0.131
38.22,130.61,0.131
38.25,130.75,0.131
38.28,130.89,0.131
38.31,131.04,0.131
38.34,131.18,0.131
38.36,131.32,0.131
38.39,131.46,0.131
38.42,131.60,0.131
38.45,131.74,0.131
38.48,131.89,0.131
38.51,132.03,0.131
38.53,132.17,0.131
38.56,132.31,0.131
38.59,132.45,0.131
38.62,132.59,0.131
38.65,132.73,0.131
38.68,132.88,0.131
38.70,133.02,0.131
38.73,133.16,0.131
38.76,133.30,0.131
38.79,133.44,0.131
38.82,133.59,0.131
38.84,133.73,0.131
38.87,133.87,0.131
38.90,134.01,0.132
38.93,134.15,0.132
38.96,134.29,0.132
38.99,134.43,0.132
39.01,134.58,0.132
39.04,134.72,0.132
39.07,134.86,0.132
39.10,135.00,0.132
39.13,135.14,0.132
39.16,135.29,0.132
39.19,135.43,0.132
39.21,135.57,0.132
39.24,135.71,0.132
39.27,135.85,0.132
39.30,135.99,0.132
39.33,136.13,0.132
39.36,136.28,0.132
39.38,136.42,0.132
39.41,136.56,0.132
39.44,136.70,0.132
39.47,136.84,0.132
39.50,136.99,0.132
39.53,137.13,0.132
39.55,137.27,0.132
39.58,137.41,0.132
39.61,137.55,0.132
39.64,137.70,0.132
39.67,137.84,0.132
39.69,137.98,0.132
39.72,138.12,0.132
39.75,138.26,0.132
39.78,138.40,0.132
39.81,138.54,0.132
39.84,138.69,0.133
39.86,138.83,0.133
39.89,138.97,0.133
39.92,139.11,0.133
39.95,139.25,0.133
39.98,139.39,0.133
40.01,139.54,0.133
40.04,139.68,0.133
40.06,139.82,0.133
40.09,139.96,0.133
40.12,140.10,0.133
40.15,140.24,0.133
40.18,140.39,0.133
40.21,140.53,0.133
40.23,140.67,0.133
40.26,140.81,0.133
40.29,140.95,0.133
40.32,141.10,0.133
40.35,141.24,0.133
40.38,141.38,0.133
40.40,141.52,0.133
40.43,141.66,0.133
40.46,141.80,0.133
40.49,141.94,0.133
40.52,142.09,0.133
40.54,142.23,0.133
40.57,142.37,0.133
40.60,142.51,0.133
40.63,142.65,0.133
40.66,142.79,0.133
40.69,142.94,0.133
40.71,143.08,0.133
40.74,143.22,0.133
40.77,143.36,0.133
40.80,143.50,0.133
40.83,143.65,0.134
40.86,143.79,0.134
40.89,143.93,0.134
40.91,144.07,0.134
40.94,144.21,0.134
40.97,144.35,0.134
41.00,144.49,0.134
41.03,144.64,0.134
41.06,144.78,0.134
41.08,144.92,0.134
41.11,145.06,0.134
41.14,145.20,0.134
41.17,145.35,0.134
41.20,145.49,0.134
41.23,145.63,0.134
41.25,145.77,0.134
41.28,145.91,0.134
41.31,146.06,0.134
41.34,146.20,0.134
41.37,146.34,0.134
41.39,146.48,0.134
41.42,146.62,0.134
41.45,146.76,0.134
41.48,146.90,0.134
41.51,147.05,0.134
41.54,147.19,0.134
41.56,147.33,0.134
41.59,147.47,0.134
41.62,147.61,0.134
41.65,147.75,0.134
41.68,147.90,0.134
41.71,148.04,0.134
41.74,148.18,0.134
41.76,148.32,0.134
41.79,148.46,0.134
41.82,148.61,0.134
41.85,148.75,0.134
41.88,148.89,0.134
41.91,149.03,0.134
41.93,149.17,
41.96,149.31,
41.99,,

[step]
Ramp 10.00 °C/min to -60.00 °C
Time,Temperature,Heat Flow (Normalized)
min,°C,W/g
42.99,150.12,-0.033
43.00,150.12,-0.033
43.02,150.11,-0.033
43.03,150.11,-0.033
43.05,150.09,-0.031
43.06,150.07,-0.022
43.08,150.03,-0.019
43.09,149.98,-0.020
43.11,149.91,-0.045
43.12,149.83,-0.074
43.14,149.74,-0.107
43.15,149.64,-0.140
43.17,149.53,-0.173
43.18,149.42,-0.200
43.20,149.30,-0.224
43.21,149.17,-0.243
43.23,149.05,-0.260
43.24,148.92,-0.272
43.26,148.79,-0.286
43.27,148.65,-0.294
43.29,148.51,-0.306
43.30,148.37,-0.310
43.32,148.24,-0.320
43.33,148.10,-0.325
43.35,147.95,-0.331
43.36,147.81,-0.333
43.38,147.67,-0.338
43.39,147.52,-0.340
43.41,147.38,-0.342
43.42,147.23,-0.345
43.44,147.09,-0.348
43.45,146.94,-0.349
43.47,146.80,-0.350
43.48,146.65,-0.352
43.50,146.50,-0.353
43.51,146.36,-0.353
43.53,146.21,-0.354
43.54,146.06,-0.355
43.56,145.92,-0.355
43.57,145.77,-0.356
43.59,145.62,-0.356
43.60,145.47,-0.356
43.62,145.32,-0.357
43.63,145.18,-0.357
43.65,145.03,-0.357
43.66,144.88,-0.358
43.68,144.73,-0.358
43.69,144.58,-0.358
43.71,144.44,-0.359
43.72,144.29,-0.359
43.74,144.14,-0.359
43.75,143.99,-0.359
43.77,143.84,-0.359
43.78,143.69,-0.360
43.80,143.54,-0.360
43.81,143.40,-0.360
43.83,143.25,-0.360
43.84,143.10,-0.360
43.86,142.95,-0.360
43.87,142.80,-0.361
43.89,142.65,-0.361
43.90,142.50,-0.361
43.92,142.35,-0.361
43.93,142.21,-0.361
43.95,142.06,-0.361
43.96,141.91,-0.362
43.98,141.76,-0.362
43.99,141.61,-0.362
44.01,141.46,-0.362
44.02,141.31,-0.362
44.04,141.16,-0.362
44.05,141.01,-0.362
44.07,140.86,-0.362
44.08,140.71,-0.362
44.10,140.56,-0.362
44.11,140.41,-0.362
44.13,140.26,-0.363
44.14,140.12,-0.363
44.16,139.97,-0.363
44.17,139.82,-0.363
44.19,139.67,-0.363
44.20,139.52,-0.363
44.22,139.37,-0.363
44.23,139.22,-0.363
44.25,139.07,-0.363
44.26,138.92,-0.363
44.28,138.77,-0.363
44.29,138.62,-0.363
44.31,138.47,-0.363
44.32,138.32,-0.363
44.34,138.17,-0.363
44.35,138.02,-0.363
44.37,137.87,-0.363
44.38,137.72,-0.363
44.40,137.57,-0.363
44.41,137.42,-0.363
44.43,137.27,-0.363
44.44,137.12,-0.363
44.46,136.97,-0.363
44.47,136.82,-0.362
44.49,136.67,-0.362
44.50,136.52,-0.362
44.52,136.37,-0.362
44.53,136.22,-0.362
44.55,136.08,-0.362
44.56,135.92,-0.362
44.58,135.77,-0.362
44.59,135.63,-0.362
44.61,135.48,-0.362
44.62,135.33,-0.362
44.64,135.18,-0.362
44.65,135.03,-0.362
44.67,134.88,-0.362
44.68,134.73,-0.362
44.70,134.58,-0.362
44.71,134.43,-0.361
44.73,134.28,-0.361
44.74,134.13,-0.361
44.76,133.98,-0.361
44.77,133.83,-0.361
44.79,133.68,-0.361
44.80,133.53,-0.361
44.82,133.38,-0.361
44.83,133.23,-0.361
44.85,133.08,-0.361
44.86,132.93,-0.361
44.88,132.78,-0.361
44.89,132.63,-0.360
44.91,132.48,-0.360
44.92,132.33,-0.360
44.94,132.18,-0.360
44.95,132.03,-0.360
44.97,131.88,-0.360
44.98,131.73,-0.360
45.00,131.58,-0.360
45.01,131.43,-0.360
45.03,131.28,-0.360
45.04,131.13,-0.360
45.06,130.98,-0.360
45.07,130.83,-0.360
45.09,130.68,-0.359
45.10,130.53,-0.359
45.12,130.38,-0.359
45.13,130.24,-0.359
45.15,130.09,-0.359
45.16,129.94,-0.359
45.18,129.79,-0.359
45.19,129.64,-0.359
45.21,129.49,-0.359
45.22,129.34,-0.359
45.24,129.19,-0.359
45.25,129.04,-0.359
45.27,128.89,-0.359
45.28,128.74,-0.359
45.30,128.59,-0.359
45.31,128.44,-0.358
45.33,128.29,-0.358
45.34,128.14,-0.358
45.36,127.99,-0.358
45.37,127.84,-0.358
45.39,127.69,-0.358
45.40,127.54,-0.358
45.42,127.39,-0.358
45.43,127.24,-0.358
45.45,127.09,-0.358
45.46,126.94,-0.358
45.48,126.79,-0.358
45.49,126.64,-0.357
45.51,126.49,-0.357
45.52,126.34,-0.357
45.54,126.19,-0.357
45.55,126.04,-0.357
45.57,125.89,-0.357
45.58,125.74,-0.357
45.60,125.59,-0.357
45.61,125.44,-0.357
45.63,125.29,-0.357
45.64,125.14,-0.356
45.66,124.99,-0.356
45.67,124.84,-0.356
45.69,124.69,-0.356
45.70,124.54,-0.356
45.72,124.39,-0.356
45.73,124.24,-0.356
45.75,124.09,-0.356
45.76,123.94,-0.356
45.78,123.79,-0.356
45.79,123.64,-0.356
45.81,123.49,-0.356
45.82,123.34,-0.356
45.84,123.19,-0.356
45.85,123.04,-0.355
45.87,122.89,-0.355
45.88,122.75,-0.355
45.90,122.59,-0.355
45.91,122.44,-0.355
45.93,122.30,-0.355
45.94,122.15,-0.355
45.96,121.99,-0.355
45.97,121.85,-0.355
45.99,121.69,-0.355
46.00,121.55,-0.355
46.02,121.40,-0.355
46.03,121.25,-0.355
46.05,121.10,-0.354
46.06,120.95,-0.354
46.08,120.80,-0.354
46.09,120.65,-0.354
46.11,120.50,-0.354
46.12,120.35,-0.354
46.14,120.20,-0.354
46.15,120.05,-0.354
46.17,119.90,-0.354
46.18,119.75,-0.354
46.20,119.60,-0.354
46.21,119.45,-0.354
46.23,119.30,-0.353
46.24,119.15,-0.353
46.26,119.00,-0.353
46.27,118.85,-0.353
46.29,118.70,-0.353
46.30,118.55,-0.353
46.32,118.40,-0.353
46.33,118.25,-0.353
46.35,118.10,-0.353
46.36,117.95,-0.353
46.38,117.80,-0.353
46.39,117.65,-0.353
46.41,117.50,-0.352
46.42,117.35,-0.352
46.44,117.20,-0.352
46.45,117.05,-0.352
46.47,116.90,-0.352
46.48,116.75,-0.352
46.50,116.60,-0.352
46.51,116.45,-0.352
46.53,116.30,-0.352
46.54,116.15,-0.352
46.56,116.00,-0.351
46.57,115.85,-0.351
46.59,115.70,-0.351
46.60,115.55,-0.351
46.62,115.40,-0.351
46.63,115.25,-0.351
46.65,115.10,-0.351
46.66,114.95,-0.351
46.68,114.80,-0.351
46.69,114.65,-0.351
46.71,114.50,-0.351
46.72,114.35,-0.351
46.74,114.20,-0.350
46.75,114.05,-0.350
46.77,113.90,-0.350
46.78,113.75,-0.350
46.80,113.60,-0.350
46.81,113.45,-0.350
46.83,113.30,-0.350
46.84,113.15,-0.350
46.86,113.00,-0.350
46.87,112.85,-0.350
46.89,112.70,-0.350
46.90,112.55,-0.350
46.92,112.40,-0.350
46.93,112.25,-0.350
46.95,112.10,-0.350
46.96,111.96,-0.350
46.98,111.81,-0.350
46.99,111.65,-0.349
47.01,111.51,-0.349
47.02,111.35,-0.349
47.04,111.20,-0.349
47.05,111.06,-0.349
47.07,110.90,-0.349
47.08,110.76,-0.349
47.10,110.61,-0.349
47.11,110.46,-0.349
47.13,110.31,-0.349
47.14,110.16,-0.349
47.16,110.01,-0.348
47.17,109.86,-0.348
47.19,109.71,-0.348
47.20,109.56,-0.348
47.22,109.41,-0.348
47.23,109.26,-0.348
47.25,109.11,-0.348
47.26,108.96,-0.348
47.28,108.81,-0.348
47.29,108.66,-0.348
47.31,108.51,-0.348
47.32,108.36,-0.348
47.34,108.21,-0.347
47.35,108.06,-0.347
47.37,107.91,-0.347
47.38,107.76,-0.347
47.40,107.61,-0.347
47.41,107.46,-0.347
47.43,107.31,-0.347
47.44,107.16,-0.347
47.46,107.01,-0.347
47.47,106.86,-0.347
47.49,106.71,-0.347
47.50,106.56,-0.347
47.52,106.41,-0.346
47.53,106.26,-0.346
47.55,106.11,-0.346
47.56,105.96,-0.346
47.58,105.81,-0.346
47.59,105.66,-0.346
47.61,105.51,-0.346
47.62,105.36,-0.346
47.64,105.21,-0.346
47.65,105.06,-0.346
47.67,104.91,-0.346
47.68,104.76,-0.346
47.70,104.61,-0.346
47.71,104.46,-0.346
47.73,104.31,-0.345
47.74,104.16,-0.345
47.76,104.01,-0.345
47.77,103.86,-0.345
47.79,103.71,-0.345
47.80,103.56,-0.345
47.82,103.41,-0.345
47.83,103.26,-0.345
47.85,103.11,-0.345
47.86,102.96,-0.345
47.88,102.81,-0.345
47.89,102.66,-0.345
47.91,102.51,-0.345
47.92,102.36,-0.345
47.94,102.21,-0.344
47.95,102.06,-0.344
47.97,101.91,-0.344
47.98,101.76,-0.344
[...]
142.62,2.49,0.112
142.65,2.64,0.112
142.68,2.78,0.112
142.71,2.92,0.111
142.74,3.06,0.111
142.77,3.20,0.111
142.79,3.34,0.111
142.82,3.49,0.111
142.85,3.63,0.110
142.88,3.77,0.110
142.91,3.92,0.110
142.93,4.06,0.110
142.96,4.20,0.109
142.99,4.34,0.109
143.02,4.48,0.109
143.05,4.62,0.108
143.08,4.77,0.108
143.10,4.91,0.107
143.13,5.05,0.107
143.16,5.19,0.107
143.19,5.33,0.107
143.22,5.48,0.107
143.25,5.62,0.107
143.28,5.76,0.106
143.30,5.90,0.106
143.33,6.04,0.106
143.36,6.19,0.106
143.39,6.33,0.106
143.42,6.47,0.106
143.45,6.61,0.106
143.47,6.75,0.106
143.50,6.89,0.106
143.53,7.03,0.106
143.56,7.18,0.106
143.59,7.32,0.106
143.62,7.46,0.106
143.64,7.60,0.105
143.67,7.74,0.105
143.70,7.88,0.105
143.73,8.02,0.105
143.76,8.17,0.105
143.78,8.31,0.105
143.81,8.45,0.105
143.84,8.59,0.105
143.87,8.74,0.106
143.90,8.88,0.106
143.93,9.02,0.106
143.95,9.16,0.106
143.98,9.30,0.106
144.01,9.45,0.106
144.04,9.59,0.106
144.07,9.73,0.106
144.10,9.87,0.106
144.13,10.01,0.106
144.15,10.15,0.106
144.18,10.30,0.106
144.21,10.44,0.106
144.24,10.58,0.106
144.27,10.72,0.106
144.30,10.86,0.106
144.32,11.01,0.106
144.35,11.15,0.106
144.38,11.29,0.106
144.41,11.43,0.106
144.44,11.57,0.106
144.47,11.72,0.106
144.49,11.85,0.106
144.52,12.00,0.106
144.55,12.14,0.106
144.58,12.28,0.106
144.61,12.42,0.106
144.63,12.56,0.106
144.66,12.71,0.106
144.69,12.85,0.106
144.72,12.99,0.106
144.75,13.13,0.106
144.78,13.27,0.106
144.80,13.41,0.106
144.83,13.56,0.106
144.86,13.70,0.106
144.89,13.84,0.106
144.92,13.98,0.106
144.95,14.12,0.107
144.98,14.26,0.107
145.00,14.41,0.107
145.03,14.55,0.106
145.06,14.69,0.107
145.09,14.83,0.107
145.12,14.97,0.107
145.15,15.12,0.107
145.17,15.26,0.106
145.20,15.40,0.107
145.23,15.54,0.107
145.26,15.68,0.107
145.29,15.82,0.107
145.32,15.97,0.107
145.34,16.11,0.107
145.37,16.25,0.107
145.40,16.39,0.107
145.43,16.53,0.107
145.46,16.67,0.107
145.48,16.82,0.107
145.51,16.96,0.107
145.54,17.10,0.107
145.57,17.24,0.107
145.60,17.38,0.107
145.63,17.53,0.107
145.65,17.67,0.107
145.68,17.81,0.107
145.71,17.95,0.107
145.74,18.09,0.107
145.77,18.24,0.107
145.80,18.38,0.108
145.83,18.52,0.108
145.85,18.66,0.108
145.88,18.80,0.108
145.91,18.94,0.108
145.94,19.08,0.108
145.97,19.23,0.108
146.00,19.37,0.108
146.02,19.51,0.108
146.05,19.65,0.108
146.08,19.79,0.108
146.11,19.93,0.108
146.14,20.08,0.108
146.17,20.22,0.108
146.19,20.36,0.108
146.22,20.50,0.108
146.25,20.64,0.108
146.28,20.79,0.108
146.31,20.93,0.108
146.33,21.07,0.108
146.36,21.21,0.108
146.39,21.35,0.108
146.42,21.49,0.108
146.45,21.64,0.108
146.48,21.78,0.109
146.50,21.92,0.109
146.53,22.06,0.109
146.56,22.20,0.109
146.59,22.35,0.109
146.62,22.49,0.109
146.65,22.63,0.109
146.68,22.77,0.109
146.70,22.91,0.109
146.73,23.05,0.109
146.76,23.20,0.109
146.79,23.34,0.109
146.82,23.48,0.109
146.85,23.62,0.109
146.87,23.76,0.109
146.90,23.90,0.109
146.93,24.05,0.109
146.96,24.19,0.109
146.99,24.33,0.109
147.02,24.47,0.109
147.04,24.61,0.109
147.07,24.75,0.109
147.10,24.90,0.109
147.13,25.04,0.109
147.16,25.18,0.110
147.18,25.32,0.110
147.21,25.46,0.110
147.24,25.60,0.110
147.27,25.75,0.110
147.30,25.89,0.110
147.33,26.03,0.110
147.35,26.17,0.110
147.38,26.31,0.110
147.41,26.46,0.110
147.44,26.60,0.110
147.47,26.74,0.110
147.50,26.88,0.110
147.53,27.02,0.110
147.55,27.17,0.110
147.58,27.31,0.110
147.61,27.45,0.110
147.64,27.59,0.110
147.67,27.73,0.110
147.70,27.87,0.110
147.72,28.02,0.110
147.75,28.16,0.110
147.78,28.30,0.110
147.81,28.44,0.111
147.84,28.58,0.110
147.87,28.72,0.111
147.89,28.86,0.111
147.92,29.01,0.111
147.95,29.15,0.111
147.98,29.29,0.111
148.01,29.43,0.111
148.03,29.57,0.111
148.06,29.72,0.111
148.09,29.86,0.111
148.12,30.00,0.111
148.15,30.14,0.111
148.18,30.28,0.111
148.20,30.42,0.111
148.23,30.57,0.111
148.26,30.71,0.111
148.29,30.85,0.111
148.32,30.99,0.111
148.35,31.13,0.111
148.38,31.27,0.111
148.40,31.42,0.111
148.43,31.56,0.111
148.46,31.70,0.111
148.49,31.84,0.111
148.52,31.98,0.111
148.55,32.13,0.111
148.57,32.27,0.111
148.60,32.41,0.111
148.63,32.55,0.111
148.66,32.69,0.111
148.69,32.84,0.112
148.72,32.98,0.112
148.74,33.12,0.112
148.77,33.26,0.112
148.80,33.40,0.112
148.83,33.54,0.112
148.86,33.69,0.112
148.88,33.83,0.112
148.91,33.97,0.112
148.94,34.11,0.112
148.97,34.25,0.112
149.00,34.39,0.112
149.03,34.54,0.112
149.05,34.68,0.112
149.08,34.82,0.112
149.11,34.96,0.112
149.14,35.10,0.112
149.17,35.24,0.112
149.20,35.39,0.112
149.23,35.53,0.112
149.25,35.67,0.112
149.28,35.81,0.112
149.31,35.95,0.112
149.34,36.09,0.112
149.37,36.24,0.112
149.40,36.38,0.112
149.42,36.52,0.112
149.45,36.66,0.113
149.48,36.81,0.113
149.51,36.95,0.113
149.54,37.09,0.113
149.57,37.23,0.113
149.59,37.37,0.113
149.62,37.51,0.113
149.65,37.66,0.113
149.68,37.80,0.113
149.71,37.94,0.113
149.73,38.08,0.113
149.76,38.22,0.113
149.79,38.36,0.113
149.82,38.51,0.113
149.85,38.65,0.113
149.88,38.79,0.113
149.90,38.93,0.113
149.93,39.07,0.113
149.96,39.21,0.113
149.99,39.36,0.113
150.02,39.50,0.113
150.05,39.64,0.113
150.08,39.78,0.113
150.10,39.92,0.113
150.13,40.07,0.113
150.16,40.21,0.113
150.19,40.35,0.113
150.22,40.49,0.113
150.25,40.63,0.113
150.27,40.77,0.113
150.30,40.92,0.113
150.33,41.06,0.113
150.36,41.20,0.113
150.39,41.34,0.113
150.42,41.48,0.113
150.44,41.62,0.114
150.47,41.76,0.114
150.50,41.91,0.114
150.53,42.05,0.114
150.56,42.19,0.114
150.58,42.33,0.114
150.61,42.47,0.114
150.64,42.62,0.114
150.67,42.76,0.114
150.70,42.90,0.114
150.73,43.04,0.114
150.75,43.18,0.114
150.78,43.33,0.114
150.81,43.47,0.114
150.84,43.61,0.114
150.87,43.75,0.114
150.90,43.89,0.114
150.93,44.03,0.114
150.95,44.17,0.114
150.98,44.32,0.114
151.01,44.46,0.114
151.04,44.60,0.114
151.07,44.74,0.114
151.10,44.88,0.114
151.12,45.03,0.115
151.15,45.17,0.115
151.18,45.31,0.115
151.21,45.45,0.115
151.24,45.59,0.115
151.27,45.74,0.115
151.29,45.88,0.115
151.32,46.02,0.115
151.35,46.16,0.115
151.38,46.30,0.115
151.41,46.45,0.115
151.43,46.59,0.115
151.46,46.73,0.115
151.49,46.87,0.115
151.52,47.01,0.115
151.55,47.15,0.115
151.58,47.30,0.115
151.60,47.44,0.115
151.63,47.58,0.115
151.66,47.72,0.115
151.69,47.86,0.115
151.72,48.00,0.115
151.75,48.15,0.115
151.78,48.29,0.115
151.80,48.43,0.115
151.83,48.57,0.115
151.86,48.71,0.115
151.89,48.85,0.116
151.92,48.99,0.116
151.95,49.14,0.116
151.97,49.28,0.116
152.00,49.42,0.116
152.03,49.56,0.116
152.06,49.70,0.116
152.09,49.85,0.116
152.12,49.99,0.116
152.14,50.13,0.116
152.17,50.27,0.116
152.20,50.41,0.116
152.23,50.56,0.116
152.26,50.70,0.116
152.28,50.84,0.116
152.31,50.98,0.116
152.34,51.12,0.116
152.37,51.26,0.116
152.40,51.40,0.116
152.43,51.55,0.116
152.45,51.69,0.116
152.48,51.83,0.116
152.51,51.97,0.116
152.54,52.11,0.116
152.57,52.26,0.117
152.60,52.40,0.117
152.63,52.54,0.117
152.65,52.68,0.117
152.68,52.82,0.117
152.71,52.96,0.117
152.74,53.11,0.117
152.77,53.25,0.117
152.80,53.39,0.117
152.82,53.53,0.117
152.85,53.67,0.117
152.88,53.81,0.117
152.91,53.96,0.117
152.94,54.10,0.117
152.97,54.24,0.117
152.99,54.38,0.117
153.02,54.52,0.117
153.05,54.67,0.117
153.08,54.81,0.117
153.11,54.95,0.117
153.13,55.09,0.117
153.16,55.23,0.117
153.19,55.37,0.117
153.22,55.52,0.117
153.25,55.66,0.117
153.28,55.80,0.117
153.30,55.94,0.117
153.33,56.08,0.117
153.36,56.23,0.117
153.39,56.37,0.118
153.42,56.51,0.118
153.45,56.65,0.118
153.48,56.79,0.118
153.50,56.93,0.118
153.53,57.08,0.118
153.56,57.22,0.118
153.59,57.36,0.118
153.62,57.50,0.118
153.65,57.64,0.118
153.67,57.78,0.118
153.70,57.93,0.118
153.73,58.07,0.118
153.76,58.21,0.118
153.79,58.35,0.118
153.82,58.49,0.118
153.84,58.64,0.118
153.87,58.78,0.118
153.90,58.92,0.118
153.93,59.06,0.118
153.96,59.20,0.118
153.98,59.34,0.118
154.01,59.48,0.118
154.04,59.63,0.119
154.07,59.77,0.118
154.10,59.91,0.119
154.13,60.05,0.119
154.15,60.20,0.119
154.18,60.34,0.119
154.21,60.48,0.119
154.24,60.62,0.119
154.27,60.76,0.119
154.30,60.90,0.119
154.33,61.05,0.119
154.35,61.19,0.119
154.38,61.33,0.119
154.41,61.47,0.119
154.44,61.61,0.119
154.47,61.75,0.119
154.50,61.90,0.119
154.52,62.04,0.119
154.55,62.18,0.119
154.58,62.32,0.119
154.61,62.46,0.119
154.64,62.60,0.119
154.67,62.74,0.119
154.69,62.89,0.119
154.72,63.03,0.119
154.75,63.17,0.119
154.78,63.31,0.119
154.81,63.45,0.119
154.83,63.60,0.119
154.86,63.74,0.119
154.89,63.88,0.119
154.92,64.02,0.119
154.95,64.16,0.119
154.98,64.30,0.119
155.00,64.45,0.119
155.03,64.59,0.119
155.06,64.73,0.119
155.09,64.87,0.119
155.12,65.01,0.119
155.15,65.16,0.119
155.18,65.30,0.120
155.20,65.44,0.120
155.23,65.58,0.120
155.26,65.72,0.120
155.29,65.87,0.120
155.32,66.01,0.120
155.35,66.15,0.120
155.37,66.29,0.120
155.40,66.43,0.120
155.43,66.57,0.120
155.46,66.72,0.120
155.49,66.86,0.120
155.52,67.00,0.120
155.54,67.14,0.120
155.57,67.28,0.120
155.60,67.42,0.120
155.63,67.56,0.120
155.66,67.71,0.120
155.68,67.85,0.120
155.71,67.99,0.120
155.74,68.13,0.120
155.77,68.27,0.120
155.80,68.42,0.120
155.83,68.56,0.120
155.85,68.70,0.120
155.88,68.84,0.120
155.91,68.98,0.120
155.94,69.12,0.121
155.97,69.27,0.121
156.00,69.41,0.121
156.03,69.55,0.121
156.05,69.69,0.121
156.08,69.83,0.121
156.11,69.97,0.121
156.14,70.12,0.121
156.17,70.26,0.121
156.20,70.40,0.121
156.22,70.54,0.121
156.25,70.68,0.121
156.28,70.83,0.121
156.31,70.97,0.121
156.34,71.11,0.121
156.37,71.25,0.121
156.39,71.39,0.121
156.42,71.53,0.121
156.45,71.68,0.121
156.48,71.82,0.121
156.51,71.96,0.121
156.53,72.10,0.121
156.56,72.24,0.121
156.59,72.38,0.121
156.62,72.53,0.121
156.65,72.67,0.121
156.68,72.81,0.121
156.70,72.95,0.121
156.73,73.09,0.122
156.76,73.23,0.122
156.79,73.37,0.122
156.82,73.52,0.122
156.85,73.66,0.122
156.88,73.80,0.122
156.90,73.94,0.122
156.93,74.08,0.122
156.96,74.23,0.122
156.99,74.37,0.122
157.02,74.51,0.122
157.05,74.65,0.122
157.07,74.79,0.122
157.10,74.94,0.122
157.13,75.08,0.122
157.16,75.22,0.122
157.19,75.36,0.122
157.22,75.50,0.122
157.24,75.64,0.122
157.27,75.79,0.122
157.30,75.93,0.122
157.33,76.07,0.122
157.36,76.21,0.122
157.38,76.35,0.122
157.41,76.50,0.122
157.44,76.64,0.122
157.47,76.78,0.122
157.50,76.92,0.122
157.53,77.06,0.122
157.55,77.20,0.122
157.58,77.34,0.123
157.61,77.49,0.123
157.64,77.63,0.123
157.67,77.77,0.123
157.70,77.91,0.123
157.73,78.05,0.123
157.75,78.20,0.123
157.78,78.34,0.123
157.81,78.48,0.123
157.84,78.62,0.123
157.87,78.76,0.123
157.90,78.90,0.123
157.92,79.05,0.123
157.95,79.19,0.123
157.98,79.33,0.123
158.01,79.47,0.123
158.04,79.61,0.123
158.07,79.75,0.123
158.09,79.90,0.123
158.12,80.04,0.123
158.15,80.18,0.123
158.18,80.32,0.123
158.21,80.46,0.123
158.23,80.60,0.123
158.26,80.75,0.123
158.29,80.89,0.123
158.32,81.03,0.123
158.35,81.17,0.123
158.38,81.31,0.123
158.40,81.45,0.123
158.43,81.60,0.123
158.46,81.74,0.123
158.49,81.88,0.123
158.52,82.02,0.123
158.55,82.16,0.123
158.58,82.31,0.123
158.60,82.45,0.124
158.63,82.59,0.124
158.66,82.73,0.124
158.69,82.87,0.124
158.72,83.01,0.124
158.75,83.16,0.124
158.77,83.30,0.124
158.80,83.44,0.124
158.83,83.58,0.124
158.86,83.72,0.124
158.89,83.86,0.124
158.92,84.01,0.124
158.94,84.15,0.124
158.97,84.29,0.124
159.00,84.43,0.124
159.03,84.57,0.124
159.06,84.71,0.124
159.08,84.86,0.124
159.11,85.00,0.124
159.14,85.14,0.124
159.17,85.28,0.124
159.20,85.42,0.124
159.23,85.56,0.124
159.25,85.71,0.124
159.28,85.85,0.124
159.31,85.99,0.124
159.34,86.13,0.124
159.37,86.27,0.124
159.40,86.42,0.124
159.43,86.56,0.124
159.45,86.70,0.124
159.48,86.84,0.124
159.51,86.98,0.124
159.54,87.13,0.124
159.57,87.27,0.124
159.60,87.41,0.124
159.62,87.55,0.124
159.65,87.69,0.124
159.68,87.83,0.124
159.71,87.98,0.124
159.74,88.12,0.124
159.77,88.26,0.124
159.79,88.40,0.124
159.82,88.54,0.124
159.85,88.68,0.124
159.88,88.83,0.125
159.91,88.97,0.125
159.93,89.11,0.125
159.96,89.25,0.125
159.99,89.39,0.125
160.02,89.53,0.125
160.05,89.68,0.125
160.08,89.82,0.125
160.10,89.96,0.125
160.13,90.10,0.125
160.16,90.24,0.125
160.19,90.39,0.125
160.22,90.53,0.125
160.25,90.67,0.125
160.28,90.81,0.125
160.30,90.95,0.125
160.33,91.09,0.125
160.36,91.23,0.125
160.39,91.38,0.125
160.42,91.52,0.125
160.45,91.66,0.125
160.47,91.80,0.125
160.50,91.94,0.126
160.53,92.09,0.126
160.56,92.23,0.126
160.59,92.37,0.126
160.62,92.51,0.126
160.64,92.65,0.126
160.67,92.79,0.126
160.70,92.94,0.126
160.73,93.08,0.126
160.76,93.22,0.126
160.78,93.36,0.126
160.81,93.50,0.126
160.84,93.65,0.126
160.87,93.79,0.126
160.90,93.93,0.126
160.93,94.07,0.126
160.95,94.21,0.126
160.98,94.35,0.126
161.01,94.49,0.126
161.04,94.64,0.126
161.07,94.78,0.126
161.10,94.92,0.126
161.13,95.06,0.126
161.15,95.20,0.126
161.18,95.34,0.126
161.21,95.49,0.126
161.24,95.63,0.126
161.27,95.77,0.126
161.30,95.91,0.126
161.32,96.06,0.126
161.35,96.20,0.126
161.38,96.34,0.127
161.41,96.48,0.127
161.44,96.62,0.127
161.47,96.76,0.127
161.49,96.90,0.127
161.52,97.04,0.127
161.55,97.19,0.127
161.58,97.33,0.127
161.61,97.47,0.127
161.63,97.61,0.127
161.66,97.75,0.127
161.69,97.90,0.127
161.72,98.04,0.127
161.75,98.18,0.127
161.78,98.32,0.127
161.80,98.46,0.127
161.83,98.60,0.127
161.86,98.75,0.127
161.89,98.89,0.127
161.92,99.03,0.127
161.95,99.17,0.127
161.98,99.31,0.127
162.00,99.45,0.127
162.03,99.60,0.127
162.06,99.74,0.127
162.09,99.88,0.127
162.12,100.02,0.127
162.15,100.16,0.127
162.17,100.31,0.127
162.20,100.45,0.127
162.23,100.59,0.127
162.26,100.73,0.127
162.29,100.87,0.127
162.32,101.01,0.128
162.34,101.16,0.128
162.37,101.30,0.128
162.40,101.44,0.128
162.43,101.58,0.128
162.46,101.72,0.128
162.48,101.86,0.128
162.51,102.01,0.128
162.54,102.15,0.128
162.57,102.29,0.128
162.60,102.43,0.128
162.63,102.57,0.128
162.65,102.72,0.128
162.68,102.86,0.128
162.71,103.00,0.128
162.74,103.14,0.128
162.77,103.28,0.128
162.80,103.42,0.128
162.83,103.56,0.128
162.85,103.71,0.128
162.88,103.85,0.128
162.91,103.99,0.128
162.94,104.13,0.128
162.97,104.27,0.128
163.00,104.42,0.128
163.02,104.56,0.128
163.05,104.70,0.128
163.08,104.84,0.128
163.11,104.98,0.128
163.14,105.12,0.128
163.17,105.27,0.128
163.19,105.41,0.128
163.22,105.55,0.128
163.25,105.69,0.129
163.28,105.83,0.129
163.31,105.97,0.129
163.33,106.12,0.129
163.36,106.26,0.129
163.39,106.40,0.129
163.42,106.54,0.129
163.45,106.68,0.129
163.48,106.83,0.129
163.50,106.97,0.129
163.53,107.11,0.129
163.56,107.25,0.129
163.59,107.39,0.129
163.62,107.53,0.129
163.65,107.67,0.129
163.68,107.82,0.129
163.70,107.96,0.129
163.73,108.10,0.129
163.76,108.24,0.129
163.79,108.38,0.129
163.82,108.53,0.129
163.85,108.67,0.129
163.87,108.81,0.129
163.90,108.95,0.129
163.93,109.09,0.129
163.96,109.23,0.129
163.99,109.38,0.129
164.02,109.52,0.129
164.04,109.66,0.129
164.07,109.80,0.129
164.10,109.94,0.129
164.13,110.08,0.129
164.16,110.23,0.129
164.18,110.37,0.129
164.21,110.51,0.129
164.24,110.65,0.129
164.27,110.79,0.130
164.30,110.94,0.130
164.33,111.08,0.130
164.35,111.22,0.130
164.38,111.36,0.130
164.41,111.50,0.130
164.44,111.64,0.130
164.47,111.79,0.130
164.50,111.93,0.130
164.53,112.07,0.130
164.55,112.21,0.130
164.58,112.35,0.130
164.61,112.49,0.130
164.64,112.64,0.130
164.67,112.78,0.130
164.70,112.92,0.130
164.72,113.06,0.130
164.75,113.20,0.130
164.78,113.34,0.130
164.81,113.49,0.130
164.84,113.63,0.130
164.87,113.77,0.130
164.89,113.91,0.130
164.92,114.05,0.130
164.95,114.20,0.130
164.98,114.34,0.130
165.01,114.48,0.130
165.03,114.62,0.130
165.06,114.76,0.130
165.09,114.90,0.130
165.12,115.04,0.130
165.15,115.19,0.130
165.18,115.33,0.130
165.20,115.47,0.130
165.23,115.61,0.130
165.26,115.75,0.131
165.29,115.90,0.131
165.32,116.04,0.131
165.35,116.18,0.131
165.38,116.32,0.131
165.40,116.46,0.131
165.43,116.60,0.131
165.46,116.74,0.131
165.49,116.89,0.131
165.52,117.03,0.131
165.55,117.17,0.131
165.57,117.31,0.131
165.60,117.45,0.131
165.63,117.60,0.131
165.66,117.74,0.131
165.69,117.88,0.131
165.72,118.02,0.131
165.74,118.16,0.131
165.77,118.30,0.131
165.80,118.45,0.131
165.83,118.59,0.131
165.86,118.73,0.131
165.88,118.87,0.131
165.91,119.01,0.131
165.94,119.15,0.131
165.97,119.30,0.131
166.00,119.44,0.131
166.03,119.58,0.131
166.05,119.72,0.131
166.08,119.86,0.131
166.11,120.01,0.131
166.14,120.15,0.131
166.17,120.29,0.131
166.20,120.43,0.131
166.23,120.57,0.131
166.25,120.71,0.132
166.28,120.86,0.131
166.31,121.00,0.131
166.34,121.14,0.131
166.37,121.28,0.131
166.40,121.42,0.131
166.42,121.56,0.131
166.45,121.71,0.131
166.48,121.85,0.131
166.51,121.99,0.131
166.54,122.13,0.132
166.57,122.27,0.132
166.59,122.41,0.132
166.62,122.56,0.132
166.65,122.70,0.132
166.68,122.84,0.132
166.71,122.98,0.132
166.73,123.12,0.132
166.76,123.26,0.132
166.79,123.41,0.132
166.82,123.55,0.132
166.85,123.69,0.132
166.88,123.83,0.132
166.90,123.97,0.132
166.93,124.11,0.132
166.96,124.26,0.132
166.99,124.40,0.132
167.02,124.54,0.132
167.05,124.68,0.132
167.08,124.82,0.132
167.10,124.96,0.132
167.13,125.10,0.132
167.16,125.25,0.132
167.19,125.39,0.132
167.22,125.53,0.132
167.25,125.67,0.132
167.27,125.82,0.132
167.30,125.96,0.132
167.33,126.10,0.132
167.36,126.24,0.132
167.39,126.38,0.132
167.42,126.52,0.132
167.44,126.66,0.132
167.47,126.81,0.133
167.50,126.95,0.133
167.53,127.09,0.133
167.56,127.23,0.133
167.58,127.37,0.133
167.61,127.52,0.133
167.64,127.66,0.133
167.67,127.80,0.133
167.70,127.94,0.133
167.73,128.08,0.133
167.75,128.22,0.133
167.78,128.37,0.133
167.81,128.51,0.133
167.84,128.65,0.133
167.87,128.79,0.133
167.90,128.93,0.133
167.93,129.07,0.133
167.95,129.21,0.133
167.98,129.36,0.133
168.01,129.50,0.133
168.04,129.64,0.133
168.07,129.78,0.133
168.10,129.92,0.133
168.12,130.07,0.133
168.15,130.21,0.133
168.18,130.35,0.133
168.21,130.49,0.133
168.24,130.63,0.133
168.27,130.77,0.133
168.29,130.92,0.133
168.32,131.06,0.133
168.35,131.20,0.133
168.38,131.34,0.133
168.41,131.48,0.133
168.43,131.63,0.133
168.46,131.77,0.133
168.49,131.91,0.134
168.52,132.05,0.134
168.55,132.19,0.134
168.58,132.33,0.134
168.60,132.48,0.134
168.63,132.62,0.134
168.66,132.76,0.134
168.69,132.90,0.134
168.72,133.04,0.134
168.75,133.18,0.134
168.78,133.32,0.134
168.80,133.47,0.134
168.83,133.61,0.134
168.86,133.75,0.134
168.89,133.89,0.134
168.92,134.03,0.134
168.95,134.18,0.134
168.97,134.32,0.134
169.00,134.46,0.134
169.03,134.60,0.134
169.06,134.74,0.134
169.09,134.89,0.134
169.12,135.03,0.134
169.14,135.17,0.134
169.17,135.31,0.134
169.20,135.45,0.134
169.23,135.59,0.134
169.26,135.73,0.134
169.28,135.88,0.134
169.31,136.02,0.134
169.34,136.16,0.134
169.37,136.30,0.134
169.40,136.44,0.134
169.43,136.58,0.134
169.45,136.73,0.134
169.48,136.87,0.134
169.51,137.01,0.134
169.54,137.15,0.134
169.57,137.29,0.134
169.60,137.44,0.135
169.63,137.58,0.135
169.65,137.72,0.135
169.68,137.86,0.135
169.71,138.00,0.135
169.74,138.14,0.135
169.77,138.29,0.135
169.80,138.43,0.135
169.82,138.57,0.135
169.85,138.71,0.135
169.88,138.85,0.135
169.91,138.99,0.135
169.94,139.13,0.135
169.97,139.28,0.135
169.99,139.42,0.135
170.02,139.56,0.135
170.05,139.70,0.135
170.08,139.84,0.135
170.11,139.99,0.135
170.13,140.13,0.135
170.16,140.27,0.135
170.19,140.41,0.135
170.22,140.55,0.135
170.25,140.70,0.135
170.28,140.84,0.135
170.30,140.98,0.135
170.33,141.12,0.135
170.36,141.26,0.135
170.39,141.40,0.135
170.42,141.54,0.135
170.45,141.69,0.135
170.48,141.83,0.135
170.50,141.97,0.135
170.53,142.11,0.135
170.56,142.25,0.135
170.59,142.39,0.135
170.62,142.54,0.135
170.65,142.68,0.135
170.67,142.82,0.135
170.70,142.96,0.135
170.73,143.10,0.135
170.76,143.25,0.135
170.79,143.39,0.135
170.82,143.53,0.135
170.84,143.67,0.136
170.87,143.81,0.136
170.90,143.96,0.136
170.93,144.10,0.136
170.96,144.24,0.136
170.98,144.38,0.136
171.01,144.52,0.136
171.04,144.66,0.136
171.07,144.80,0.136
171.10,144.95,0.136
171.13,145.09,0.136
171.15,145.23,0.136
171.18,145.37,0.136
171.21,145.51,0.136
171.24,145.65,0.136
171.27,145.80,0.136
171.30,145.94,0.136
171.33,146.08,0.136
171.35,146.22,0.136
171.38,146.36,0.136
171.41,146.50,0.136
171.44,146.65,0.136
171.47,146.79,0.136
171.50,146.93,0.136
171.52,147.07,0.136
171.55,147.21,0.136
171.58,147.35,0.136
171.61,147.50,0.136
171.64,147.64,0.136
171.67,147.78,0.136
171.69,147.92,0.136
171.72,148.06,0.136
171.75,148.20,0.136
171.78,148.35,0.136
171.81,148.49,0.136
171.83,148.63,0.136
171.86,148.77,0.136
171.89,148.91,0.136
171.92,149.05,0.136
171.95,149.20,
171.98,,
171.98,,