File: DSC/2025_05_08_CBN_Isonicotinamide_MC_n60C_170C_5Cmin_x3.csv
Filename,2025_05_08_CBN_Isonicotinamide_MC_n60C_170C_5Cmin_x3
Instrument name,DSC2A-00468 (192.168.1.100)
Operator,Yarger
rundate,5/9/2025
Sample name,2025_05_08_CBN_Isonicotinamide_MC_n60C_170C_5Cmin_x3
proceduresegments,Data Off ; Equilibrate -60.00 °C; Data On ; Ramp 5.00 °C/min to 170.00 °C; Data Off ; Isothermal 1.0 min; Data On ; Ramp 5.00 °C/min to -60.00 °C; Data Off ; Isothermal 1.0 min; Data On ; Ramp 5.00 °C/min to 170.00 °C; Data Off ; Isothermal 1.0 min; Data On ; Ramp 5.00 °C/min to -60.00 °C; Data Off ; Isothermal 1.0 min; Data On ; Ramp 5.00 °C/min to 30.00 °C
[File Parameters]
Run date,5/9/2025 5:51:23 AM
Trios version,5.1.1.46572
Original File Name,
Current File Name,D:\DSC2500\JYarger\2025_05_08_CBN_Isonicotinamide_MC_n60C_170C_5Cmin_x3.tri
[Procedure]
Procedure Name,CBN_INA_n60C_170C_5Cmin_x3
Sample Name,2025_05_08_CBN_Isonicotinamide_MC_n60C_170C_5Cmin_x3
Sample Mass,4.62 mg
Reference Sample Mass,0 mg
Pan Mass,56.39 mg
Pan Number,34
Reference Pan Mass,57.13 mg
Reference Pan Number,37
Pan Type,Tzero Aluminum Hermetic
Comments,Al Hermetic DSC Consumables sealed Pan/Lid. Y2 Tray (Google Sheet: DSC_Samples_Vext_Y2_Tray_May2025)
Project Name,CA
Operator,Yarger
Test,Custom
Unload Max Temperature,30
Unload Min Temperature,30
Load Max Temperature,30
Load Min Temperature,30
Stop on Gas Flow Error,Yes
[Signal List]
Signal #1,Time (min)
Signal #2,Temperature (°C)
Signal #3,Heat Flow (mW)
Signal #4,Delta T (µV)
Signal #5,Delta Tzero (µV)
Signal #6,Tzero Temperature (°C)
Signal #7,Cell Purge (mL/min)
Signal #8,Heater Temp (°C)
Signal #9,Power Delivered (W)
Signal #10,Reference Junction Temperature (°C)
Signal #11,Flange Temperature (°C)
Signal #12,Heat Flow Phase (rad)
Signal #13,Total Heat Capacity (J/°C)
Signal #14,Heat Capacity (J/°C)
[Configuration]
Company Name,ASU
Instrument Name,DSC2A-00468
Instrument Type,DSC2500
Serial Number,DSC2A-00468
IP,192.168.1.100
Location of Instrument,MRRC
DisplayType,Unknown
Sample Interval ,0.1 s/pt
Selected Heat Flow,T4P
Exotherm Direction,Down
Cell Serial,DRC2-00792
Lid Type,Standard
Cooler,RCS 90
Leave Cooler on at End of Sequence,On
Gas 2,Nitrogen
Gas Selected,Channel 1
Flow Rate,50 mL/min
Secondary Purge,On
Licensed Heat Flow,Heat Flow T4P
Modulation Licensed,Yes
[Versions]
Common IDD Version,1
Cortex Version,VER 2.10.2.31
Driver,5.0.0.6
GDM Version,1.0.3.3
TouchscreenVersion,1.0.0.16145
FEP Version,1.2.1.21
FEP Bootloader,2.0.0.5
AutoSampler Version,2.1.1.26
Auto Sampler Bootloader,2.0.0.5
FCM Version,1.1.0.3
FCM Bootloader,2.0.0.5
[Experiment Logs]
Experiment Log Entry # 2,Data On set to 0
Experiment Log Entry # 4,Equilibrate Segment -60 (C) Started
Experiment Log Entry # 6,Air Cool is off.
Experiment Log Entry # 8,Data On set to 1
Experiment Log Entry # 10,Ramp Segment 5 C/min to 170 Started
Experiment Log Entry # 12,Data On set to 0
Experiment Log Entry # 14,Isothermal Segment 1 min started
Experiment Log Entry # 16,Data On set to 1
Experiment Log Entry # 18,Ramp Segment 5 C/min to -60 Started
Experiment Log Entry # 20,Data On set to 0
Experiment Log Entry # 22,Isothermal Segment 1 min started
Experiment Log Entry # 24,Data On set to 1
Experiment Log Entry # 26,Ramp Segment 5 C/min to 170 Started
Experiment Log Entry # 28,Data On set to 0
Experiment Log Entry # 30,Isothermal Segment 1 min started
Experiment Log Entry # 32,Data On set to 1
Experiment Log Entry # 34,Ramp Segment 5 C/min to -60 Started
Experiment Log Entry # 36,Data On set to 0
Experiment Log Entry # 38,Isothermal Segment 1 min started
Experiment Log Entry # 40,Data On set to 1
Experiment Log Entry # 42,Ramp Segment 5 C/min to 30 Started
[Method Log]
Method Log Entry # 1,Data Off
Method Log Entry # 2,Equilibrate -60 °C
Method Log Entry # 3,Data On
Method Log Entry # 4,(Ramp 508451) Ramp 5 °C/minute to 170 °C
Method Log Entry # 5,Data Off
Method Log Entry # 6,Isothermal 1 minutes
Method Log Entry # 7,Data On
Method Log Entry # 8,(Ramp 508455) Ramp 5 °C/minute to -60 °C
Method Log Entry # 9,Data Off
Method Log Entry # 10,Isothermal 1 minutes
Method Log Entry # 11,Data On
Method Log Entry # 12,(Ramp 508459) Ramp 5 °C/minute to 170 °C
Method Log Entry # 13,Data Off
Method Log Entry # 14,Isothermal 1 minutes
Method Log Entry # 15,Data On
Method Log Entry # 16,(Ramp 508463) Ramp 5 °C/minute to -60 °C
Method Log Entry # 17,Data Off
Method Log Entry # 18,Isothermal 1 minutes
Method Log Entry # 19,Data On
Method Log Entry # 20,(Ramp 508467) Ramp 5 °C/minute to 30 °C
Cell Serial,DRC2-00792
[T1 Calibration]
Slope,-0.008529666
Offset,9.636258
Initial Temperature,98.23
GUID,f8bfdadc-4977-4fdf-ba6d-0ba9134940c3
[TZero Calibration]
Date Applied,11/29/2022 4:06:13 PM
Description,From -89.059 °C to 396.009 °C at 20.000°C/min
Gas Type,Nitrogen
Pan Type,None
Source Files 1,C:\Users\yargerlab\Desktop\DSC Data\General\TZero_calibration_11_29_22_2nd(2).tri
Source Files 2,C:\Users\yargerlab\Desktop\DSC Data\General\TZero_calibration_11_29_22_2nd(3).tri
Delta T Offset,13.05235
Delta T Slope,-0.007271007
Delta T0 Offset,-13.69128
Delta T0 Slope,0.06063341
[Temperature Calibration]
Date Applied,11/29/2022 7:12:28 PM
Description,From 106.590 °C to 186.590 °C at 10.000°C/min
Gas Type,Nitrogen
Pan Type,Tzero Aluminum Hermetic
Source Files 1,C:\Users\yargerlab\Desktop\DSC Data\General\Indium(6).tri
Measured 1,157.391
Known 1,156.598
[Cell Constant Calibration]
Date Applied,11/29/2022 7:12:29 PM
Description,From 106.590 °C to 186.590 °C at 10.000°C/min
Gas Type,Nitrogen
Pan Type,Tzero Aluminum Hermetic
Source Files 1,C:\Users\yargerlab\Desktop\DSC Data\General\Indium(6).tri
T4P KCell,1.006051
Onset Slope,63.26126 mW/°C
[Direct Cp Calibration]
Date Applied,11/30/2022 11:04:51 AM
Description,From -79.983 °C to 298.409 °C at 10.000°C/min
Gas Type,Nitrogen
Pan Type,Tzero Aluminum Hermetic
Source Files 1,C:\Users\yargerlab\Desktop\DSC Data\General\Sapphire_Heat_Capacity_11_30_22.tri
[Rev Cp Calibration]
Date Applied,11/30/2022 1:58:51 PM
Description,From -79.996 °C to 292.812 °C at 3.000°C/min
Gas Type,Nitrogen
Pan Type,Tzero Aluminum Hermetic
Source Files 1,C:\Users\yargerlab\Desktop\DSC Data\General\Sapphire_MDSC_Calibration_11_30_22.tri
[step]
Ramp 5.00 °C/min to 170.00 °C
Time,Temperature,Heat Flow (Normalized)
min,°C,W/g
0.00,-59.66,-0.066
0.03,-59.68,-0.064
0.06,-59.68,-0.051
0.09,-59.65,-0.036
0.13,-59.58,-0.019
0.16,-59.48,-0.003
0.19,-59.37,0.012
0.22,-59.25,0.027
0.25,-59.12,0.038
0.29,-58.99,0.048
0.32,-58.85,0.058
0.35,-58.71,0.064
0.38,-58.57,0.070
0.41,-58.42,0.074
0.44,-58.28,0.078
0.48,-58.13,0.081
0.51,-57.98,0.083
0.54,-57.83,0.085
0.57,-57.68,0.086
0.60,-57.52,0.087
0.63,-57.37,0.088
0.67,-57.22,0.089
0.70,-57.07,0.090
0.73,-56.91,0.091
0.76,-56.76,0.091
0.79,-56.60,0.092
0.82,-56.45,0.093
0.85,-56.29,0.093
0.89,-56.13,0.094
0.92,-55.98,0.094
0.95,-55.82,0.095
0.98,-55.67,0.095
1.01,-55.51,0.096
1.05,-55.35,0.096
1.08,-55.20,0.096
1.11,-55.04,0.096
1.14,-54.88,0.097
1.17,-54.73,0.097
1.20,-54.57,0.097
1.23,-54.41,0.097
1.27,-54.26,0.097
1.30,-54.10,0.097
1.33,-53.94,0.098
1.36,-53.78,0.098
1.39,-53.63,0.098
1.43,-53.47,0.098
1.46,-53.31,0.098
1.49,-53.15,0.098
1.52,-53.00,0.098
1.55,-52.84,0.098
1.58,-52.68,0.098
1.62,-52.52,0.098
1.65,-52.36,0.098
1.68,-52.21,0.098
1.71,-52.05,0.098
1.74,-51.89,0.098
1.77,-51.73,0.098
1.81,-51.58,0.098
1.84,-51.42,0.098
1.87,-51.26,0.098
1.90,-51.10,0.098
1.93,-50.94,0.098
1.96,-50.79,0.098
1.99,-50.63,0.098
2.03,-50.47,0.098
2.06,-50.31,0.098
2.09,-50.15,0.098
2.12,-50.00,0.098
2.15,-49.84,0.098
2.19,-49.68,0.098
2.22,-49.52,0.098
2.25,-49.36,0.098
2.28,-49.21,0.098
2.31,-49.05,0.098
2.34,-48.89,0.098
2.38,-48.73,0.098
2.41,-48.57,0.098
2.44,-48.41,0.098
2.47,-48.25,0.098
2.50,-48.10,0.098
2.53,-47.94,0.098
2.56,-47.78,0.098
2.60,-47.62,0.098
2.63,-47.46,0.098
2.66,-47.31,0.098
2.69,-47.15,0.098
2.72,-46.99,0.098
2.76,-46.83,0.098
2.79,-46.67,0.098
2.82,-46.52,0.098
2.85,-46.36,0.098
2.88,-46.20,0.098
2.91,-46.04,0.098
2.94,-45.88,0.098
2.98,-45.73,0.098
3.01,-45.57,0.098
3.04,-45.41,0.098
3.07,-45.25,0.098
3.10,-45.09,0.098
3.14,-44.93,0.098
3.17,-44.78,0.098
3.20,-44.62,0.098
3.23,-44.46,0.098
3.26,-44.30,0.098
3.29,-44.14,0.098
3.33,-43.98,0.098
3.36,-43.82,0.098
3.39,-43.67,0.098
3.42,-43.51,0.098
3.45,-43.35,0.098
3.48,-43.19,0.098
3.51,-43.03,0.098
3.55,-42.87,0.098
3.58,-42.72,0.098
3.61,-42.56,0.098
3.64,-42.40,0.098
3.67,-42.24,0.098
3.71,-42.08,0.098
3.74,-41.92,0.098
3.77,-41.76,0.098
3.80,-41.60,0.098
3.83,-41.45,0.098
3.86,-41.29,0.098
3.89,-41.13,0.098
3.93,-40.97,0.098
3.96,-40.81,0.098
3.99,-40.65,0.098
4.02,-40.49,0.098
4.05,-40.34,0.098
4.09,-40.18,0.098
4.12,-40.02,0.098
4.15,-39.86,0.098
4.18,-39.70,0.098
4.21,-39.54,0.098
4.24,-39.38,0.098
4.28,-39.22,0.098
4.31,-39.07,0.098
4.34,-38.91,0.098
4.37,-38.75,0.098
4.40,-38.59,0.098
4.43,-38.43,0.098
4.46,-38.27,0.098
4.50,-38.12,0.098
4.53,-37.96,0.098
4.56,-37.80,0.098
4.59,-37.64,0.098
4.62,-37.48,0.098
4.65,-37.33,0.098
4.69,-37.17,0.098
4.72,-37.01,0.098
4.75,-36.85,0.098
4.78,-36.69,0.098
4.81,-36.54,0.098
4.85,-36.38,0.098
4.88,-36.22,0.098
4.91,-36.06,0.098
4.94,-35.90,0.098
4.97,-35.74,0.098
5.00,-35.58,0.098
5.04,-35.42,0.098
5.07,-35.27,0.098
5.10,-35.11,0.099
5.13,-34.95,0.099
5.16,-34.79,0.099
5.19,-34.63,0.099
5.23,-34.47,0.099
5.26,-34.31,0.099
5.29,-34.15,0.099
5.32,-34.00,0.099
5.35,-33.84,0.099
5.38,-33.68,0.099
5.41,-33.52,0.099
5.45,-33.36,0.099
5.48,-33.20,0.099
5.51,-33.04,0.099
5.54,-32.88,0.099
5.57,-32.73,0.099
5.60,-32.57,0.099
5.64,-32.41,0.099
5.67,-32.25,0.099
5.70,-32.09,0.099
5.73,-31.93,0.099
5.76,-31.78,0.099
5.80,-31.62,0.099
5.83,-31.46,0.099
5.86,-31.30,0.099
5.89,-31.14,0.099
5.92,-30.98,0.099
5.95,-30.82,0.099
5.99,-30.67,0.099
6.02,-30.51,0.099
6.05,-30.35,0.099
6.08,-30.19,0.099
6.11,-30.03,0.099
6.14,-29.87,0.099
6.18,-29.71,0.099
6.21,-29.56,0.099
6.24,-29.40,0.099
6.27,-29.24,0.099
6.30,-29.08,0.099
6.33,-28.92,0.099
6.36,-28.76,0.099
6.40,-28.61,0.099
6.43,-28.45,0.099
6.46,-28.28,0.099
6.49,-28.13,0.099
6.52,-27.97,0.099
6.55,-27.81,0.099
6.59,-27.65,0.099
6.62,-27.49,0.099
6.65,-27.34,0.099
6.68,-27.18,0.099
6.71,-27.02,0.099
6.75,-26.86,0.099
6.78,-26.70,0.099
6.81,-26.54,0.099
6.84,-26.38,0.099
6.87,-26.23,0.099
6.90,-26.07,0.099
6.94,-25.91,0.099
6.97,-25.75,0.099
7.00,-25.59,0.099
7.03,-25.43,0.099
7.06,-25.28,0.099
7.09,-25.12,0.099
7.13,-24.96,0.100
7.16,-24.80,0.100
7.19,-24.64,0.100
7.22,-24.48,0.100
7.25,-24.33,0.100
7.28,-24.17,0.100
7.31,-24.01,0.100
7.35,-23.85,0.100
7.38,-23.69,0.100
7.41,-23.53,0.100
7.44,-23.37,0.100
7.47,-23.21,0.100
7.50,-23.06,0.100
7.54,-22.90,0.100
7.57,-22.74,0.100
7.60,-22.58,0.100
7.63,-22.42,0.100
7.66,-22.27,0.100
7.70,-22.11,0.100
7.73,-21.95,0.100
7.76,-21.79,0.100
7.79,-21.63,0.100
7.82,-21.47,0.100
7.85,-21.32,0.100
7.89,-21.16,0.100
7.92,-21.00,0.100
7.95,-20.84,0.100
7.98,-20.68,0.100
8.01,-20.52,0.100
8.04,-20.37,0.100
8.08,-20.21,0.100
8.11,-20.05,0.100
8.14,-19.89,0.100
8.17,-19.73,0.100
8.20,-19.57,0.100
8.23,-19.41,0.100
8.26,-19.26,0.100
8.30,-19.10,0.100
8.33,-18.94,0.100
8.36,-18.78,0.100
8.39,-18.62,0.100
8.42,-18.46,0.101
8.45,-18.31,0.101
8.49,-18.15,0.101
8.52,-17.99,0.101
8.55,-17.83,0.101
8.58,-17.67,0.101
8.61,-17.51,0.101
8.65,-17.35,0.101
8.68,-17.20,0.101
8.71,-17.04,0.101
8.74,-16.88,0.101
8.77,-16.72,0.101
8.80,-16.56,0.101
8.83,-16.40,0.101
8.87,-16.24,0.101
8.90,-16.09,0.101
8.93,-15.93,0.101
8.96,-15.77,0.101
8.99,-15.61,0.101
9.03,-15.45,0.101
9.06,-15.29,0.101
9.09,-15.14,0.101
9.12,-14.98,0.101
9.15,-14.82,0.101
9.18,-14.66,0.101
9.22,-14.50,0.101
9.25,-14.34,0.101
9.28,-14.18,0.101
9.31,-14.02,0.101
9.34,-13.87,0.101
9.37,-13.71,0.101
9.40,-13.55,0.102
9.44,-13.39,0.102
9.47,-13.23,0.102
9.50,-13.08,0.102
9.53,-12.92,0.102
9.56,-12.76,0.102
9.60,-12.60,0.102
9.63,-12.44,0.102
9.66,-12.28,0.102
9.69,-12.12,0.102
9.72,-11.97,0.102
9.75,-11.81,0.102
9.78,-11.65,0.102
9.82,-11.49,0.102
9.85,-11.33,0.102
9.88,-11.17,0.102
9.91,-11.02,0.102
9.94,-10.86,0.102
9.98,-10.70,0.102
10.01,-10.54,0.102
10.04,-10.38,0.102
10.07,-10.22,0.102
10.10,-10.06,0.102
10.13,-9.91,0.102
10.17,-9.75,0.102
10.20,-9.59,0.102
10.23,-9.43,0.102
10.26,-9.27,0.102
10.29,-9.11,0.102
10.32,-8.96,0.102
10.35,-8.80,0.102
10.39,-8.64,0.102
10.42,-8.48,0.102
10.45,-8.32,0.102
10.48,-8.16,0.102
10.51,-8.00,0.102
10.55,-7.85,0.102
10.58,-7.69,0.102
10.61,-7.53,0.103
10.64,-7.37,0.103
10.67,-7.21,0.103
10.70,-7.05,0.103
10.73,-6.90,0.103
10.77,-6.74,0.103
10.80,-6.58,0.103
10.83,-6.42,0.103
10.86,-6.26,0.103
10.89,-6.10,0.103
10.93,-5.94,0.103
10.96,-5.79,0.103
10.99,-5.63,0.103
11.02,-5.47,0.103
11.05,-5.31,0.103
11.08,-5.15,0.103
11.12,-4.99,0.103
11.15,-4.84,0.103
11.18,-4.68,0.103
11.21,-4.52,0.103
11.24,-4.36,0.103
11.27,-4.20,0.103
11.30,-4.04,0.103
11.34,-3.88,0.103
11.37,-3.73,0.104
11.40,-3.57,0.104
11.43,-3.41,0.104
11.46,-3.25,0.104
11.50,-3.09,0.104
11.53,-2.93,0.104
11.56,-2.78,0.104
11.59,-2.62,0.104
11.62,-2.46,0.104
11.65,-2.30,0.104
11.68,-2.14,0.104
11.72,-1.98,0.104
11.75,-1.82,0.104
11.78,-1.67,0.104
11.81,-1.51,0.104
11.84,-1.35,0.104
11.88,-1.19,0.104
11.91,-1.03,0.104
11.94,-0.87,0.104
11.97,-0.72,0.104
12.00,-0.56,0.104
12.03,-0.40,0.104
12.07,-0.24,0.104
12.10,-0.08,0.104
12.13,0.08,0.104
12.16,0.24,0.104
12.19,0.39,0.104
12.22,0.55,0.104
12.25,0.71,0.104
12.29,0.87,0.105
12.32,1.03,0.105
12.35,1.19,0.105
12.38,1.34,0.105
12.41,1.50,0.105
12.45,1.66,0.105
12.48,1.82,0.105
12.51,1.98,0.105
12.54,2.14,0.105
12.57,2.29,0.105
12.60,2.46,0.105
12.63,2.61,0.105
12.67,2.77,0.105
12.70,2.93,0.105
12.73,3.09,0.105
12.76,3.25,0.105
12.79,3.41,0.105
12.83,3.56,0.105
12.86,3.72,0.105
12.89,3.88,0.105
12.92,4.04,0.105
12.95,4.20,0.105
12.98,4.36,0.105
13.02,4.51,0.105
13.05,4.67,0.105
13.08,4.83,0.106
13.11,4.99,0.106
13.14,5.15,0.106
13.17,5.31,0.106
13.20,5.46,0.106
13.24,5.62,0.106
13.27,5.78,0.106
13.30,5.94,0.106
13.33,6.10,0.106
13.36,6.26,0.106
13.40,6.42,0.106
13.43,6.58,0.106
13.46,6.73,0.106
13.49,6.89,0.106
13.52,7.05,0.106
13.55,7.21,0.106
13.58,7.37,0.106
13.62,7.52,0.106
13.65,7.69,0.106
13.68,7.84,0.107
13.71,8.00,0.107
13.74,8.16,0.107
13.78,8.32,0.107
13.81,8.47,0.107
13.84,8.63,0.107
13.87,8.79,0.107
13.90,8.95,0.107
13.93,9.11,0.107
13.97,9.27,0.107
14.00,9.43,0.107
14.03,9.58,0.107
14.06,9.74,0.107
14.09,9.90,0.107
14.12,10.06,0.107
14.15,10.22,0.107
14.19,10.38,0.107
14.22,10.53,0.107
14.25,10.69,0.107
14.28,10.85,0.107
14.31,11.01,0.108
14.35,11.17,0.108
14.38,11.33,0.108
14.41,11.49,0.108
14.44,11.64,0.108
14.47,11.80,0.108
14.50,11.96,0.108
14.53,12.12,0.108
14.57,12.28,0.108
14.60,12.44,0.108
14.63,12.60,0.108
14.66,12.75,0.108
14.69,12.91,0.108
14.73,13.07,0.108
14.76,13.23,0.108
14.79,13.39,0.108
14.82,13.55,0.108
14.85,13.71,0.108
14.88,13.86,0.108
14.92,14.02,0.109
14.95,14.18,0.109
14.98,14.34,0.109
15.01,14.50,0.109
15.04,14.66,0.109
15.07,14.81,0.109
15.10,14.97,0.109
15.14,15.13,0.109
15.17,15.29,0.109
15.20,15.45,0.109
15.23,15.61,0.109
15.26,15.76,0.109
15.30,15.92,0.109
15.33,16.08,0.109
15.36,16.24,0.109
15.39,16.40,0.109
15.42,16.56,0.109
15.45,16.71,0.109
15.48,16.87,0.109
15.52,17.03,0.109
15.55,17.19,0.109
15.58,17.35,0.110
15.61,17.51,0.110
15.64,17.67,0.110
15.68,17.82,0.110
15.71,17.98,0.110
15.74,18.14,0.110
15.77,18.30,0.110
15.80,18.46,0.110
15.83,18.62,0.110
15.87,18.78,0.110
15.90,18.93,0.110
15.93,19.09,0.110
15.96,19.25,0.110
15.99,19.41,0.110
16.02,19.57,0.110
16.05,19.72,0.110
16.09,19.88,0.110
16.12,20.04,0.110
16.15,20.20,0.110
16.18,20.36,0.110
16.21,20.52,0.110
16.25,20.68,0.110
16.28,20.83,0.111
16.31,20.99,0.111
16.34,21.15,0.111
16.37,21.31,0.111
16.40,21.47,0.111
16.43,21.63,0.111
16.47,21.78,0.111
16.50,21.94,0.111
16.53,22.10,0.111
16.56,22.26,0.111
16.59,22.42,0.111
16.63,22.58,0.111
16.66,22.74,0.111
16.69,22.89,0.111
16.72,23.05,0.111
16.75,23.21,0.111
16.78,23.37,0.111
16.82,23.53,0.111
16.85,23.69,0.112
16.88,23.85,0.112
16.91,24.00,0.112
16.94,24.16,0.112
16.97,24.32,0.112
17.00,24.48,0.112
17.04,24.64,0.112
17.07,24.80,0.112
17.10,24.96,0.112
17.13,25.11,0.112
17.16,25.27,0.112
17.19,25.43,0.112
17.23,25.59,0.112
17.26,25.75,0.112
17.29,25.90,0.112
17.32,26.06,0.112
17.35,26.22,0.112
17.38,26.38,0.112
17.42,26.54,0.112
17.45,26.70,0.112
17.48,26.86,0.113
17.51,27.01,0.113
17.54,27.17,0.113
17.58,27.33,0.113
17.61,27.49,0.113
17.64,27.65,0.113
17.67,27.81,0.113
17.70,27.97,0.113
17.73,28.12,0.113
17.77,28.28,0.113
17.80,28.44,0.113
17.83,28.60,0.113
17.86,28.76,0.113
17.89,28.92,0.113
17.92,29.07,0.113
17.96,29.23,0.113
17.99,29.39,0.113
18.02,29.55,0.113
18.05,29.71,0.113
18.08,29.87,0.114
18.11,30.02,0.114
18.14,30.18,0.114
18.18,30.34,0.114
18.21,30.50,0.114
18.24,30.66,0.114
18.27,30.82,0.114
18.30,30.97,0.114
18.33,31.13,0.114
18.37,31.29,0.114
18.40,31.45,0.114
18.43,31.61,0.114
18.46,31.77,0.114
18.49,31.93,0.114
18.53,32.08,0.114
18.56,32.24,0.114
18.59,32.40,0.114
18.62,32.56,0.114
18.65,32.72,0.114
18.68,32.88,0.115
18.72,33.03,0.115
18.75,33.19,0.115
18.78,33.35,0.115
18.81,33.51,0.115
18.84,33.67,0.115
18.87,33.83,0.115
18.91,33.99,0.115
18.94,34.14,0.115
18.97,34.30,0.115
19.00,34.46,0.115
19.03,34.62,0.115
19.06,34.78,0.115
19.09,34.94,0.115
19.13,35.09,0.115
19.16,35.25,0.116
19.19,35.41,0.116
19.22,35.57,0.116
19.25,35.73,0.116
19.28,35.89,0.116
19.32,36.04,0.116
19.35,36.20,0.116
19.38,36.36,0.116
19.41,36.52,0.116
19.44,36.68,0.116
19.48,36.84,0.116
19.51,37.00,0.116
19.54,37.15,0.116
19.57,37.31,0.116
19.60,37.47,0.116
19.63,37.63,0.116
19.67,37.79,0.116
19.70,37.95,0.116
19.73,38.10,0.116
19.76,38.26,0.117
19.79,38.42,0.117
19.82,38.58,0.117
19.86,38.74,0.117
19.89,38.90,0.117
19.92,39.06,0.117
19.95,39.21,0.117
19.98,39.37,0.117
20.01,39.53,0.117
20.04,39.69,0.117
20.08,39.85,0.117
20.11,40.01,0.117
20.14,40.16,0.117
20.17,40.32,0.117
20.20,40.48,0.117
20.23,40.64,0.118
20.27,40.80,0.118
20.30,40.96,0.118
20.33,41.11,0.118
20.36,41.27,0.118
20.39,41.43,0.118
20.43,41.59,0.118
20.46,41.75,0.118
20.49,41.90,0.118
20.52,42.06,0.118
20.55,42.22,0.119
20.58,42.38,0.119
20.62,42.54,0.119
20.65,42.70,0.119
20.68,42.86,0.119
20.71,43.02,0.119
20.74,43.17,0.119
20.77,43.33,0.119
20.81,43.49,0.119
20.84,43.65,0.119
20.87,43.81,0.120
20.90,43.96,0.120
20.93,44.12,0.120
20.96,44.28,0.120
20.99,44.44,0.120
21.03,44.60,0.120
21.06,44.76,0.120
21.09,44.92,0.120
21.12,45.07,0.121
21.15,45.23,0.121
21.18,45.39,0.121
21.22,45.55,0.121
21.25,45.71,0.121
21.28,45.87,0.121
21.31,46.03,0.121
21.34,46.18,0.121
21.38,46.34,0.122
21.41,46.50,0.122
21.44,46.66,0.122
21.47,46.82,0.122
21.50,46.98,0.122
21.53,47.13,0.122
21.57,47.29,0.122
21.60,47.45,0.123
21.63,47.61,0.123
21.66,47.77,0.123
21.69,47.93,0.123
21.72,48.09,0.123
21.76,48.24,0.123
21.79,48.40,0.123
21.82,48.56,0.124
21.85,48.72,0.124
21.88,48.88,0.124
21.91,49.04,0.124
21.94,49.19,0.124
21.98,49.35,0.124
22.01,49.51,0.125
22.04,49.67,0.125
22.07,49.83,0.125
22.10,49.99,0.125
22.13,50.15,0.125
22.17,50.31,0.126
22.20,50.46,0.126
22.23,50.62,0.126
22.26,50.78,0.126
22.29,50.94,0.127
22.33,51.10,0.127
22.36,51.26,0.127
22.39,51.41,0.127
22.42,51.57,0.128
22.45,51.73,0.128
22.48,51.89,0.128
22.52,52.05,0.129
22.55,52.21,0.129
22.58,52.36,0.129
22.61,52.52,0.130
22.64,52.68,0.130
22.67,52.84,0.130
22.71,53.00,0.131
22.74,53.15,0.131
22.77,53.31,0.132
22.80,53.47,0.132
22.83,53.63,0.133
22.86,53.79,0.134
22.89,53.94,0.134
22.93,54.10,0.135
22.96,54.26,0.136
22.99,54.42,0.136
23.02,54.57,0.137
23.05,54.73,0.138
23.08,54.89,0.140
23.12,55.05,0.141
23.15,55.21,0.143
23.18,55.37,0.144
23.21,55.52,0.146
23.24,55.68,0.148
23.28,55.84,0.151
23.31,56.00,0.152
23.34,56.15,0.155
23.37,56.31,0.157
23.40,56.47,0.160
23.43,56.63,0.163
23.47,56.78,0.166
23.50,56.94,0.170
23.53,57.10,0.173
23.56,57.26,0.177
23.59,57.41,0.180
23.62,57.57,0.185
23.66,57.73,0.188
23.69,57.89,0.193
23.72,58.04,0.198
23.75,58.20,0.201
23.78,58.36,0.207
23.81,58.51,0.210
23.84,58.67,0.215
23.88,58.83,0.219
23.91,58.99,0.225
23.94,59.14,0.229
23.97,59.30,0.234
24.00,59.46,0.239
24.03,59.61,0.244
24.07,59.77,0.249
24.10,59.93,0.254
24.13,60.08,0.259
24.16,60.24,0.265
24.19,60.40,0.270
24.23,60.55,0.275
24.26,60.71,0.281
24.29,60.87,0.287
24.32,61.02,0.292
24.35,61.18,0.298
24.38,61.34,0.303
24.42,61.49,0.309
24.45,61.65,0.315
24.48,61.81,0.320
24.51,61.96,0.325
24.54,62.12,0.332
24.57,62.28,0.337
24.61,62.43,0.343
24.64,62.59,0.348
24.67,62.75,0.355
24.70,62.90,0.360
24.73,63.06,0.366
24.76,63.22,0.371
24.79,63.37,0.377
24.83,63.53,0.382
24.86,63.69,0.387
24.89,63.84,0.393
24.92,64.00,0.397
24.95,64.16,0.402
24.98,64.31,0.405
25.02,64.47,0.411
25.05,64.63,0.416
25.08,64.78,0.422
25.11,64.94,0.429
25.14,65.10,0.435
25.18,65.25,0.448
25.21,65.41,0.460
25.24,65.56,0.467
25.27,65.72,0.474
25.30,65.88,0.478
25.33,66.03,0.479
25.37,66.19,0.481
25.40,66.35,0.491
25.43,66.50,0.537
25.46,66.65,0.546
25.49,66.81,0.542
25.52,66.96,0.542
25.56,67.12,0.539
25.59,67.28,0.536
25.62,67.44,0.529
25.65,67.60,0.521
25.68,67.76,0.518
25.71,67.92,0.512
25.74,68.08,0.508
25.78,68.24,0.501
25.81,68.40,0.496
25.84,68.56,0.490
25.87,68.72,0.483
25.90,68.88,0.479
25.93,69.04,0.474
25.97,69.20,0.469
26.00,69.36,0.464
26.03,69.52,0.458
26.06,69.68,0.453
26.09,69.84,0.445
26.13,70.01,0.438
26.16,70.17,0.432
26.19,70.33,0.426
26.22,70.49,0.420
26.25,70.65,0.415
26.28,70.81,0.408
26.32,70.97,0.402
26.35,71.13,0.396
26.38,71.29,0.390
26.41,71.45,0.383
26.44,71.61,0.378
26.47,71.77,0.371
26.51,71.93,0.365
26.54,72.09,0.361
26.57,72.25,0.356
26.60,72.41,0.351
26.63,72.57,0.346
26.66,72.73,0.342
26.69,72.89,0.337
26.73,73.05,0.333
26.76,73.21,0.328
26.79,73.37,0.325
26.82,73.53,0.321
26.85,73.69,0.317
26.88,73.85,0.313
26.92,74.01,0.308
26.95,74.17,0.305
26.98,74.33,0.302
27.01,74.49,0.298
27.04,74.65,0.294
27.08,74.81,0.290
27.11,74.97,0.286
27.14,75.13,0.282
27.17,75.29,0.278
27.20,75.45,0.274
27.23,75.61,0.269
27.27,75.77,0.264
27.30,75.93,0.257
27.33,76.09,0.250
27.36,76.25,0.242
27.39,76.41,0.233
27.42,76.57,0.224
27.46,76.73,0.216
27.49,76.89,0.208
27.52,77.05,0.202
27.55,77.21,0.197
27.58,77.37,0.193
27.61,77.53,0.189
27.64,77.69,0.186
27.68,77.85,0.184
27.71,78.01,0.182
27.74,78.17,0.180
27.77,78.33,0.179
27.80,78.49,0.179
27.83,78.65,0.178
27.87,78.81,0.177
27.90,78.97,0.177
27.93,79.12,0.176
27.96,79.28,0.176
27.99,79.44,0.175
28.03,79.60,0.175
28.06,79.76,0.174
28.09,79.92,0.174
28.12,80.07,0.173
28.15,80.23,0.173
28.18,80.39,0.173
28.22,80.55,0.172
28.25,80.71,0.172
28.28,80.86,0.172
28.31,81.02,0.172
28.34,81.18,0.171
28.37,81.34,0.171
28.41,81.50,0.171
28.44,81.66,0.171
28.47,81.82,0.171
28.50,81.97,0.171
28.53,82.13,0.170
28.56,82.29,0.170
28.59,82.45,0.170
28.63,82.61,0.170
28.66,82.77,0.170
28.69,82.93,0.170
28.72,83.08,0.170
28.75,83.24,0.170
28.78,83.40,0.170
28.82,83.56,0.170
28.85,83.72,0.170
28.88,83.88,0.170
28.91,84.04,0.170
28.94,84.19,0.169
28.98,84.35,0.169
29.01,84.51,0.169
29.04,84.67,0.169
29.07,84.83,0.169
29.10,84.99,0.169
29.13,85.14,0.169
29.17,85.30,0.169
29.20,85.46,0.169
29.23,85.62,0.169
29.26,85.78,0.170
29.29,85.94,0.170
29.32,86.09,0.170
29.36,86.25,0.170
29.39,86.41,0.170
29.42,86.57,0.170
29.45,86.73,0.170
29.48,86.89,0.170
29.51,87.05,0.170
29.54,87.20,0.170
29.58,87.36,0.170
29.61,87.52,0.170
29.64,87.68,0.170
29.67,87.84,0.170
29.70,88.00,0.170
29.73,88.15,0.170
29.77,88.31,0.170
29.80,88.47,0.170
29.83,88.63,0.170
29.86,88.79,0.170
29.89,88.95,0.170
29.93,89.10,0.170
29.96,89.26,0.170
29.99,89.42,0.171
30.02,89.58,0.171
30.05,89.74,0.171
30.08,89.90,0.171
30.12,90.06,0.171
30.15,90.21,0.171
30.18,90.37,0.171
30.21,90.53,0.171
30.24,90.69,0.171
30.27,90.85,0.171
30.31,91.01,0.171
30.34,91.16,0.171
30.37,91.32,0.171
30.40,91.48,0.172
30.43,91.64,0.172
30.46,91.80,0.172
30.49,91.96,0.172
30.53,92.11,0.172
30.56,92.27,0.172
30.59,92.43,0.172
30.62,92.59,0.172
30.65,92.75,0.172
30.68,92.91,0.172
30.72,93.06,0.172
30.75,93.22,0.172
30.78,93.38,0.172
30.81,93.54,0.173
30.84,93.70,0.173
30.88,93.86,0.173
30.91,94.02,0.173
30.94,94.17,0.173
30.97,94.33,0.173
31.00,94.49,0.173
31.03,94.65,0.173
31.07,94.81,0.173
31.10,94.97,0.173
31.13,95.13,0.173
31.16,95.28,0.174
31.19,95.44,0.174
31.22,95.60,0.174
31.26,95.76,0.174
31.29,95.92,0.174
31.32,96.07,0.174
31.35,96.23,0.174
31.38,96.39,0.174
31.41,96.55,0.174
31.44,96.71,0.174
31.48,96.87,0.174
31.51,97.03,0.175
31.54,97.18,0.175
31.57,97.34,0.175
31.60,97.50,0.175
31.63,97.66,0.175
31.67,97.82,0.175
31.70,97.98,0.175
31.73,98.13,0.175
31.76,98.29,0.176
31.79,98.45,0.176
31.83,98.61,0.176
31.86,98.77,0.176
31.89,98.93,0.176
31.92,99.08,0.176
31.95,99.24,0.176
31.98,99.40,0.176
32.02,99.56,0.177
32.05,99.72,0.177
32.08,99.88,0.177
32.11,100.03,0.177
32.14,100.19,0.177
32.17,100.35,0.177
32.21,100.51,0.178
32.24,100.67,0.178
32.27,100.83,0.178
32.30,100.98,0.178
32.33,101.14,0.178
32.36,101.30,0.178
32.39,101.46,0.178
32.43,101.62,0.178
32.46,101.78,0.178
32.49,101.93,0.179
32.52,102.09,0.179
32.55,102.25,0.179
32.58,102.41,0.179
32.62,102.57,0.179
32.65,102.73,0.179
32.68,102.88,0.180
32.71,103.04,0.180
32.74,103.20,0.180
32.78,103.36,0.180
32.81,103.52,0.180
32.84,103.68,0.180
32.87,103.83,0.180
32.90,103.99,0.181
32.93,104.15,0.181
32.97,104.31,0.181
33.00,104.47,0.181
33.03,104.63,0.181
33.06,104.79,0.182
33.09,104.94,0.182
33.12,105.10,0.182
33.16,105.26,0.182
33.19,105.42,0.182
33.22,105.58,0.183
33.25,105.74,0.183
33.28,105.90,0.183
33.31,106.06,0.183
33.34,106.21,0.183
33.38,106.37,0.184
33.41,106.53,0.184
33.44,106.69,0.184
33.47,106.85,0.184
33.50,107.01,0.184
33.53,107.17,0.184
33.57,107.32,0.184
33.60,107.48,0.184
33.63,107.64,0.185
33.66,107.80,0.185
33.69,107.96,0.185
33.73,108.11,0.185
33.76,108.27,0.185
33.79,108.43,0.185
33.82,108.59,0.185
33.85,108.75,0.185
33.88,108.91,0.186
33.92,109.06,0.186
33.95,109.22,0.186
33.98,109.38,0.186
34.01,109.54,0.187
34.04,109.70,0.187
34.07,109.86,0.187
34.11,110.01,0.187
34.14,110.17,0.188
34.17,110.33,0.188
34.20,110.49,0.188
34.23,110.65,0.188
34.26,110.80,0.189
34.29,110.96,0.189
34.33,111.12,0.189
34.36,111.28,0.189
34.39,111.44,0.190
34.42,111.59,0.190
34.45,111.75,0.190
34.49,111.91,0.191
34.52,112.07,0.191
34.55,112.23,0.191
34.58,112.39,0.192
34.61,112.54,0.192
34.64,112.70,0.192
34.68,112.86,0.192
34.71,113.02,0.193
34.74,113.18,0.193
34.77,113.34,0.193
34.80,113.50,0.194
34.83,113.65,0.194
34.86,113.81,0.194
34.90,113.97,0.195
34.93,114.13,0.195
34.96,114.29,0.195
34.99,114.44,0.195
35.02,114.60,0.196
35.06,114.76,0.196
35.09,114.92,0.196
35.12,115.08,0.197
35.15,115.24,0.197
35.18,115.39,0.198
35.21,115.55,0.198
35.24,115.71,0.198
35.28,115.87,0.199
35.31,116.03,0.199
35.34,116.19,0.200
35.37,116.34,0.200
35.40,116.50,0.201
35.44,116.66,0.201
35.47,116.82,0.202
35.50,116.98,0.202
35.53,117.13,0.203
35.56,117.29,0.203
35.59,117.45,0.204
35.63,117.61,0.204
35.66,117.77,0.204
35.69,117.93,0.205
35.72,118.08,0.205
35.75,118.24,0.206
35.78,118.40,0.206
35.81,118.56,0.207
35.85,118.72,0.207
35.88,118.88,0.207
35.91,119.04,0.207
35.94,119.19,0.207
35.97,119.35,0.208
36.01,119.51,0.208
36.04,119.67,0.208
36.07,119.83,0.208
36.10,119.99,0.208
36.13,120.15,0.206
36.16,120.31,0.204
36.19,120.46,0.203
36.23,120.62,0.202
36.26,120.78,0.201
36.29,120.94,0.200
36.32,121.10,0.200
36.35,121.26,0.198
36.39,121.42,0.197
36.42,121.58,0.196
36.45,121.73,0.196
36.48,121.89,0.195
36.51,122.05,0.194
36.54,122.21,0.194
36.58,122.37,0.193
36.61,122.52,0.193
36.64,122.68,0.193
36.67,122.84,0.193
36.70,123.00,0.193
36.73,123.16,0.193
36.76,123.31,0.194
36.80,123.47,0.194
36.83,123.63,0.194
36.86,123.79,0.195
36.89,123.94,0.195
36.92,124.10,0.196
36.96,124.26,0.196
36.99,124.42,0.197
37.02,124.58,0.198
37.05,124.74,0.199
37.08,124.90,0.199
37.11,125.06,0.200
37.14,125.21,0.201
37.18,125.37,0.202
37.21,125.53,0.203
37.24,125.69,0.203
37.27,125.85,0.204
37.30,126.01,0.205
37.34,126.17,0.205
37.37,126.32,0.206
37.40,126.48,0.206
37.43,126.64,0.207
37.46,126.80,0.207
37.49,126.96,0.208
37.53,127.11,0.208
37.56,127.27,0.209
37.59,127.43,0.209
37.62,127.59,0.209
37.65,127.75,0.210
37.68,127.90,0.210
37.71,128.06,0.211
37.75,128.22,0.211
37.78,128.38,0.212
37.81,128.54,0.212
37.84,128.69,0.213
37.87,128.85,0.213
37.91,129.01,0.214
37.94,129.17,0.214
37.97,129.33,0.215
38.00,129.49,0.215
38.03,129.65,0.216
38.06,129.80,0.216
38.09,129.96,0.217
38.13,130.12,0.217
38.16,130.28,0.217
38.19,130.44,0.218
38.22,130.60,0.218
38.25,130.75,0.219
38.29,130.91,0.219
38.32,131.07,0.220
38.35,131.23,0.220
38.38,131.39,0.221
38.41,131.54,0.221
38.44,131.70,0.221
38.48,131.86,0.222
38.51,132.02,0.222
38.54,132.18,0.223
38.57,132.34,0.223
38.60,132.50,0.223
38.63,132.65,0.224
38.66,132.81,0.224
38.70,132.97,0.224
38.73,133.13,0.225
38.76,133.29,0.225
38.79,133.44,0.225
38.82,133.60,0.226
38.86,133.76,0.226
38.89,133.92,0.226
38.92,134.08,0.226
38.95,134.24,0.226
38.98,134.40,0.227
39.01,134.55,0.227
39.04,134.71,0.227
39.08,134.87,0.227
39.11,135.03,0.227
39.14,135.19,0.228
39.17,135.35,0.228
39.20,135.50,0.228
39.24,135.66,0.228
39.27,135.82,0.228
39.30,135.98,0.228
39.33,136.14,0.228
39.36,136.29,0.228
39.39,136.45,0.228
39.43,136.61,0.228
39.46,136.77,0.228
39.49,136.93,0.228
39.52,137.09,0.228
39.55,137.25,0.228
39.58,137.40,0.228
39.61,137.56,0.228
39.65,137.72,0.228
39.68,137.88,0.228
39.71,138.04,0.227
39.74,138.20,0.227
39.77,138.35,0.227
39.81,138.51,0.226
39.84,138.67,0.226
39.87,138.83,0.226
39.90,138.99,0.225
39.93,139.15,0.225
39.96,139.31,0.224
39.99,139.47,0.224
40.03,139.62,0.223
40.06,139.78,0.222
40.09,139.94,0.222
40.12,140.10,0.221
40.15,140.26,0.221
40.19,140.42,0.220
40.22,140.57,0.219
40.25,140.73,0.219
40.28,140.89,0.218
40.31,141.05,0.217
40.34,141.21,0.216
40.38,141.37,0.216
40.41,141.53,0.215
40.44,141.69,0.214
40.47,141.84,0.214
40.50,142.00,0.213
40.53,142.16,0.212
40.56,142.32,0.211
40.60,142.48,0.210
40.63,142.64,0.209
40.66,142.80,0.208
40.69,142.95,0.207
40.72,143.11,0.206
40.76,143.27,0.205
40.79,143.43,0.204
40.82,143.59,0.202
40.85,143.75,0.201
40.88,143.91,0.200
40.91,144.07,0.199
40.94,144.22,0.197
40.98,144.38,0.196
41.01,144.54,0.195
41.04,144.70,0.193
41.07,144.86,0.192
41.10,145.02,0.191
41.14,145.18,0.190
41.17,145.34,0.188
41.20,145.50,0.187
41.23,145.65,0.186
41.26,145.81,0.185
41.29,145.97,0.183
41.33,146.13,0.182
41.36,146.29,0.181
41.39,146.45,0.180
41.42,146.61,0.179
41.45,146.77,0.178
41.48,146.92,0.177
41.51,147.08,0.176
41.55,147.24,0.175
41.58,147.40,0.174
41.61,147.56,0.173
41.64,147.72,0.173
41.67,147.88,0.172
41.71,148.03,0.171
41.74,148.19,0.170
41.77,148.35,0.169
41.80,148.51,0.169
41.83,148.67,0.168
41.86,148.83,0.168
41.89,148.99,0.167
41.93,149.14,0.166
41.96,149.30,0.166
41.99,149.46,0.165
42.02,149.62,0.165
42.05,149.78,0.164
42.09,149.94,0.164
42.12,150.09,0.164
42.15,150.25,0.163
42.18,150.41,0.163
42.21,150.57,0.163
42.24,150.73,0.163
42.28,150.89,0.162
42.31,151.05,0.162
42.34,151.20,0.162
42.37,151.36,0.162
42.40,151.52,0.162
42.43,151.68,0.162
42.46,151.84,0.162
42.50,152.00,0.162
42.53,152.15,0.161
42.56,152.31,0.161
42.59,152.47,0.161
42.62,152.63,0.161
42.66,152.79,0.161
42.69,152.95,0.161
42.72,153.10,0.161
42.75,153.26,0.161
42.78,153.42,0.161
42.81,153.58,0.161
42.84,153.74,0.161
42.88,153.90,0.161
42.91,154.05,0.161
42.94,154.21,0.161
42.97,154.37,0.161
43.00,154.53,0.161
43.04,154.69,0.161
43.07,154.85,0.161
43.10,155.01,0.161
43.13,155.16,0.161
43.16,155.32,0.161
43.19,155.48,0.161
43.23,155.64,0.161
43.26,155.80,0.161
43.29,155.95,0.161
43.32,156.11,0.161
43.35,156.27,0.161
43.38,156.43,0.161
43.41,156.59,0.161
43.45,156.75,0.161
43.48,156.90,0.161
43.51,157.06,0.161
43.54,157.22,0.161
43.57,157.38,0.162
43.61,157.54,0.162
43.64,157.70,0.162
43.67,157.85,0.162
43.70,158.01,0.162
43.73,158.17,0.162
43.76,158.33,0.162
43.79,158.49,0.162
43.83,158.65,0.162
43.86,158.81,0.162
43.89,158.96,0.162
43.92,159.12,0.162
43.95,159.28,0.162
43.99,159.44,0.163
44.02,159.60,0.163
44.05,159.76,0.163
44.08,159.91,0.163
44.11,160.07,0.163
44.14,160.23,0.163
44.18,160.39,0.163
44.21,160.55,0.163
44.24,160.71,0.163
44.27,160.86,0.163
44.30,161.02,0.163
44.33,161.18,0.164
44.36,161.34,0.164
44.40,161.50,0.164
44.43,161.66,0.164
44.46,161.81,0.164
44.49,161.97,0.164
44.52,162.13,0.164
44.56,162.29,0.164
44.59,162.45,0.164
44.62,162.60,0.164
44.65,162.76,0.164
44.68,162.92,0.164
44.71,163.08,0.164
44.74,163.24,0.164
44.78,163.40,0.165
44.81,163.56,0.165
44.84,163.71,0.165
44.87,163.87,0.165
44.90,164.03,0.165
44.94,164.19,0.165
44.97,164.35,0.165
45.00,164.51,0.165
45.03,164.66,0.166
45.06,164.82,0.166
45.09,164.98,0.166
45.13,165.14,0.166
45.16,165.30,0.166
45.19,165.46,0.166
45.22,165.62,0.166
45.25,165.77,0.166
45.28,165.93,0.166
45.31,166.09,0.166
45.35,166.25,0.166
45.38,166.41,0.166
45.41,166.56,0.166
45.44,166.72,0.166
45.47,166.88,0.166
45.51,167.04,0.167
45.54,167.20,0.167
45.57,167.36,0.167
45.60,167.52,0.167
45.63,167.67,0.167
45.66,167.83,0.167
45.69,167.99,0.167
45.73,168.15,0.167
45.76,168.31,0.167
45.79,168.46,0.167
45.82,168.62,0.167
45.85,168.78,0.167
45.89,168.94,0.167
45.92,169.10,0.167
45.95,169.25,
45.98,,
45.98,,

[step]
Ramp 5.00 °C/min to -60.00 °C
Time,Temperature,Heat Flow (Normalized)
min,°C,W/g
46.99,170.12,-0.058
47.02,170.12,-0.058
47.05,170.11,-0.058
47.08,170.07,-0.075
47.11,170.01,-0.106
47.14,169.91,-0.140
47.18,169.80,-0.174
47.21,169.67,-0.203
47.24,169.54,-0.221
47.27,169.40,-0.237
47.30,169.26,-0.246
47.33,169.11,-0.255
47.36,168.96,-0.262
47.40,168.81,-0.265
47.43,168.66,-0.268
47.46,168.50,-0.271
47.49,168.35,-0.273
47.52,168.19,-0.273
47.56,168.04,-0.274
47.59,167.88,-0.275
47.62,167.73,-0.276
47.65,167.57,-0.276
47.68,167.41,-0.277
47.71,167.26,-0.278
47.74,167.10,-0.278
47.78,166.94,-0.279
47.81,166.79,-0.279
47.84,166.63,-0.279
47.87,166.47,-0.280
47.90,166.31,-0.280
47.94,166.16,-0.280
47.97,166.00,-0.280
48.00,165.84,-0.280
48.03,165.69,-0.280
48.06,165.53,-0.281
48.09,165.37,-0.281
48.13,165.21,-0.281
48.16,165.05,-0.281
48.19,164.90,-0.281
48.22,164.74,-0.281
48.25,164.58,-0.281
48.28,164.42,-0.281
48.31,164.27,-0.281
48.35,164.11,-0.281
48.38,163.95,-0.281
48.41,163.79,-0.281
48.44,163.63,-0.281
48.47,163.48,-0.281
48.51,163.32,-0.281
48.54,163.16,-0.281
48.57,163.00,-0.281
48.60,162.84,-0.280
48.63,162.69,-0.280
48.66,162.53,-0.280
48.69,162.37,-0.280
48.73,162.21,-0.280
48.76,162.05,-0.280
48.79,161.90,-0.280
48.82,161.74,-0.280
48.85,161.58,-0.280
48.89,161.42,-0.280
48.92,161.26,-0.280
48.95,161.11,-0.279
48.98,160.95,-0.279
49.01,160.79,-0.279
49.04,160.63,-0.279
49.08,160.47,-0.279
49.11,160.31,-0.279
49.14,160.16,-0.279
49.17,160.00,-0.279
49.20,159.84,-0.279
49.23,159.68,-0.279
49.26,159.52,-0.279
49.30,159.37,-0.278
49.33,159.21,-0.278
49.36,159.05,-0.278
49.39,158.89,-0.278
49.42,158.73,-0.278
49.46,158.57,-0.278
49.49,158.42,-0.278
49.52,158.26,-0.277
49.55,158.10,-0.277
49.58,157.94,-0.277
49.61,157.78,-0.277
49.64,157.62,-0.277
49.68,157.46,-0.277
49.71,157.31,-0.277
49.74,157.15,-0.277
49.77,156.99,-0.277
49.80,156.83,-0.277
49.84,156.68,-0.276
49.87,156.52,-0.276
49.90,156.36,-0.276
49.93,156.20,-0.276
49.96,156.04,-0.276
49.99,155.88,-0.276
50.03,155.73,-0.276
50.06,155.57,-0.276
50.09,155.41,-0.276
50.12,155.25,-0.276
50.15,155.09,-0.276
50.18,154.93,-0.276
50.21,154.78,-0.275
50.25,154.62,-0.275
50.28,154.46,-0.275
50.31,154.30,-0.275
50.34,154.14,-0.275
50.37,153.99,-0.275
50.41,153.83,-0.275
50.44,153.67,-0.275
50.47,153.51,-0.274
50.50,153.35,-0.274
50.53,153.19,-0.274
50.56,153.04,-0.274
50.59,152.88,-0.274
50.63,152.72,-0.274
50.66,152.56,-0.274
50.69,152.40,-0.274
50.72,152.24,-0.274
50.75,152.09,-0.274
50.79,151.93,-0.274
50.82,151.77,-0.274
50.85,151.61,-0.274
50.88,151.45,-0.274
50.91,151.29,-0.274
50.94,151.14,-0.274
50.98,150.98,-0.274
51.01,150.82,-0.274
51.04,150.66,-0.273
51.07,150.50,-0.273
51.10,150.34,-0.273
51.13,150.18,-0.273
51.16,150.03,-0.273
51.20,149.87,-0.273
51.23,149.71,-0.273
51.26,149.55,-0.273
51.29,149.39,-0.273
51.32,149.23,-0.272
51.36,149.08,-0.272
51.39,148.92,-0.272
51.42,148.76,-0.272
51.45,148.60,-0.272
51.48,148.44,-0.272
51.51,148.29,-0.272
51.54,148.13,-0.272
51.58,147.97,-0.271
51.61,147.81,-0.271
51.64,147.66,-0.271
51.67,147.50,-0.271
51.70,147.34,-0.271
51.74,147.18,-0.271
51.77,147.02,-0.271
51.80,146.86,-0.271
51.83,146.71,-0.271
51.86,146.55,-0.271
51.89,146.39,-0.270
51.93,146.23,-0.270
51.96,146.07,-0.270
51.99,145.92,-0.270
52.02,145.76,-0.270
52.05,145.60,-0.270
52.08,145.44,-0.270
52.11,145.28,-0.270
52.15,145.12,-0.270
52.18,144.97,-0.270
52.21,144.81,-0.270
52.24,144.65,-0.270
52.27,144.49,-0.270
52.31,144.33,-0.270
52.34,144.17,-0.270
52.37,144.02,-0.270
52.40,143.86,-0.270
52.43,143.70,-0.270
52.46,143.54,-0.270
52.49,143.39,-0.269
52.53,143.23,-0.269
52.56,143.07,-0.269
52.59,142.91,-0.269
52.62,142.75,-0.269
52.65,142.60,-0.269
52.69,142.44,-0.269
52.72,142.28,-0.269
52.75,142.12,-0.269
52.78,141.96,-0.269
52.81,141.80,-0.269
52.84,141.64,-0.270
52.88,141.48,-0.270
52.91,141.32,-0.270
52.94,141.17,-0.270
52.97,141.01,-0.269
53.00,140.85,-0.269
53.03,140.69,-0.269
53.06,140.53,-0.269
53.10,140.37,-0.269
53.13,140.22,-0.269
53.16,140.06,-0.269
53.19,139.90,-0.269
53.22,139.74,-0.268
53.26,139.59,-0.268
53.29,139.43,-0.268
53.32,139.27,-0.268
53.35,139.11,-0.268
53.38,138.95,-0.268
53.41,138.79,-0.268
53.44,138.64,-0.268
53.48,138.48,-0.268
53.51,138.32,-0.268
53.54,138.16,-0.268
53.57,138.00,-0.268
53.60,137.84,-0.268
53.64,137.69,-0.267
53.67,137.53,-0.267
53.70,137.37,-0.267
53.73,137.21,-0.267
53.76,137.05,-0.267
53.79,136.89,-0.267
53.83,136.74,-0.267
53.86,136.58,-0.267
53.89,136.42,-0.267
53.92,136.26,-0.267
53.95,136.10,-0.267
53.98,135.95,-0.267
54.01,135.79,-0.267
54.05,135.63,-0.267
54.08,135.47,-0.267
54.11,135.31,-0.267
54.14,135.15,-0.266
54.17,135.00,-0.266
54.21,134.84,-0.266
54.24,134.68,-0.266
54.27,134.52,-0.266
54.30,134.36,-0.266
54.33,134.21,-0.266
54.36,134.05,-0.266
54.39,133.89,-0.266
54.43,133.73,-0.266
54.46,133.57,-0.266
54.49,133.41,-0.266
54.52,133.25,-0.266
54.55,133.10,-0.266
54.59,132.94,-0.266
54.62,132.78,-0.266
54.65,132.62,-0.266
54.68,132.46,-0.266
54.71,132.31,-0.266
54.74,132.15,-0.266
54.78,131.99,-0.266
54.81,131.83,-0.265
54.84,131.67,-0.265
54.87,131.51,-0.265
54.90,131.36,-0.265
54.93,131.20,-0.265
54.96,131.04,-0.265
55.00,130.88,-0.265
55.03,130.72,-0.265
55.06,130.57,-0.265
55.09,130.41,-0.265
55.12,130.25,-0.265
55.16,130.09,-0.265
55.19,129.93,-0.265
55.22,129.78,-0.265
55.25,129.62,-0.265
55.28,129.46,-0.265
55.31,129.30,-0.265
55.34,129.14,-0.265
55.38,128.98,-0.265
55.41,128.83,-0.265
55.44,128.67,-0.264
55.47,128.51,-0.264
55.50,128.35,-0.264
55.54,128.19,-0.264
55.57,128.04,-0.264
55.60,127.88,-0.264
55.63,127.72,-0.264
55.66,127.56,-0.264
55.69,127.40,-0.264
55.73,127.24,-0.264
55.76,127.08,-0.264
55.79,126.93,-0.264
55.82,126.77,-0.264
55.85,126.61,-0.264
55.88,126.45,-0.264
55.91,126.29,-0.264
55.95,126.14,-0.264
55.98,125.98,-0.263
56.01,125.82,-0.264
56.04,125.66,-0.263
56.07,125.50,-0.263
56.11,125.35,-0.263
56.14,125.19,-0.263
56.17,125.03,-0.263
56.20,124.87,-0.263
56.23,124.71,-0.263
56.26,124.55,-0.263
56.29,124.39,-0.263
56.33,124.24,-0.263
56.36,124.08,-0.263
56.39,123.92,-0.263
56.42,123.76,-0.263
56.45,123.60,-0.263
56.49,123.44,-0.263
56.52,123.29,-0.263
56.55,123.13,-0.263
56.58,122.97,-0.263
56.61,122.81,-0.263
56.64,122.65,-0.263
56.68,122.50,-0.263
56.71,122.34,-0.262
56.74,122.18,-0.262
56.77,122.02,-0.262
56.80,121.86,-0.262
56.83,121.70,-0.262
56.86,121.55,-0.262
56.90,121.39,-0.262
56.93,121.23,-0.262
56.96,121.07,-0.262
56.99,120.91,-0.262
57.02,120.76,-0.262
57.06,120.60,-0.262
57.09,120.44,-0.262
57.12,120.28,-0.262
57.15,120.12,-0.262
57.18,119.96,-0.262
57.21,119.81,-0.262
57.24,119.65,-0.262
57.28,119.49,-0.262
57.31,119.33,-0.261
57.34,119.17,-0.261
57.37,119.01,-0.261
57.40,118.86,-0.261
57.44,118.70,-0.261
57.47,118.54,-0.261
57.50,118.38,-0.261
57.53,118.22,-0.261
57.56,118.07,-0.261
57.59,117.91,-0.261
57.63,117.75,-0.261
57.66,117.59,-0.261
57.69,117.43,-0.261
57.72,117.27,-0.261
57.75,117.11,-0.261
57.78,116.96,-0.261
57.81,116.80,-0.261
57.85,116.64,-0.261
57.88,116.48,-0.261
57.91,116.32,-0.261
57.94,116.17,-0.260
57.97,116.01,-0.260
58.01,115.85,-0.260
58.04,115.69,-0.260
58.07,115.53,-0.260
58.10,115.37,-0.260
58.13,115.22,-0.260
58.16,115.06,-0.260
58.19,114.90,-0.260
58.23,114.74,-0.260
58.26,114.58,-0.260
[...]
192.16,-39.88,0.103
192.17,-39.81,0.103
192.18,-39.75,0.102
192.20,-39.68,0.103
192.21,-39.61,0.103
192.23,-39.55,0.103
192.24,-39.48,0.103
192.25,-39.41,0.103
192.27,-39.35,0.103
192.28,-39.28,0.103
192.29,-39.21,0.103
192.30,-39.14,0.103
192.32,-39.08,0.103
192.33,-39.01,0.103
192.35,-38.95,0.103
192.36,-38.88,0.103
192.37,-38.81,0.103
192.38,-38.74,0.103
192.40,-38.68,0.103
192.41,-38.61,0.103
192.43,-38.54,0.103
192.44,-38.48,0.103
192.45,-38.41,0.103
192.47,-38.34,0.103
192.48,-38.28,0.103
192.49,-38.21,0.103
192.50,-38.14,0.103
192.52,-38.08,0.103
192.53,-38.01,0.103
192.55,-37.94,0.103
192.56,-37.88,0.103
192.57,-37.81,0.103
192.58,-37.74,0.103
192.60,-37.68,0.103
192.61,-37.61,0.103
192.63,-37.54,0.103
192.64,-37.48,0.103
192.65,-37.41,0.103
192.67,-37.34,0.103
192.68,-37.28,0.103
192.69,-37.21,0.103
192.70,-37.14,0.103
192.72,-37.07,0.103
192.73,-37.01,0.103
192.75,-36.94,0.103
192.76,-36.88,0.103
192.77,-36.81,0.103
192.78,-36.74,0.103
192.80,-36.68,0.103
192.81,-36.61,0.103
192.83,-36.54,0.103
192.84,-36.48,0.103
192.85,-36.41,0.103
192.87,-36.34,0.103
192.88,-36.28,0.103
192.89,-36.21,0.103
192.90,-36.14,0.103
192.92,-36.08,0.103
192.93,-36.01,0.103
192.95,-35.94,0.103
192.96,-35.88,0.103
192.97,-35.81,0.103
192.98,-35.74,0.103
193.00,-35.68,0.103
193.01,-35.61,0.103
193.03,-35.54,0.103
193.04,-35.48,0.103
193.05,-35.41,0.103
193.07,-35.34,0.103
193.08,-35.27,0.103
193.09,-35.21,0.103
193.10,-35.14,0.103
193.12,-35.07,0.103
193.13,-35.01,0.103
193.15,-34.94,0.103
193.16,-34.87,0.103
193.17,-34.81,0.103
193.18,-34.74,0.103
193.20,-34.67,0.103
193.21,-34.61,0.103
193.23,-34.54,0.103
193.24,-34.47,0.103
193.25,-34.41,0.103
193.27,-34.34,0.103
193.28,-34.27,0.103
193.29,-34.21,0.103
193.30,-34.14,0.103
193.32,-34.07,0.103
193.33,-34.01,0.103
193.35,-33.94,0.103
193.36,-33.87,0.103
193.37,-33.81,0.103
193.38,-33.74,0.103
193.40,-33.67,0.103
193.41,-33.61,0.103
193.43,-33.54,0.103
193.44,-33.47,0.103
193.45,-33.41,0.103
193.47,-33.34,0.103
193.48,-33.27,0.103
193.49,-33.21,0.103
193.50,-33.14,0.103
193.52,-33.07,0.103
193.53,-33.01,0.103
193.55,-32.94,0.103
193.56,-32.87,0.103
193.57,-32.81,0.103
193.58,-32.74,0.103
193.60,-32.67,0.103
193.61,-32.61,0.103
193.63,-32.54,0.103
193.64,-32.47,0.103
193.65,-32.40,0.103
193.67,-32.34,0.103
193.68,-32.27,0.103
193.69,-32.20,0.103
193.70,-32.14,0.103
193.72,-32.07,0.103
193.73,-32.01,0.103
193.75,-31.94,0.103
193.76,-31.87,0.103
193.77,-31.80,0.103
193.78,-31.74,0.103
193.80,-31.67,0.103
193.81,-31.60,0.103
193.83,-31.54,0.103
193.84,-31.47,0.103
193.85,-31.40,0.103
193.87,-31.34,0.103
193.88,-31.27,0.103
193.89,-31.20,0.103
193.90,-31.14,0.103
193.92,-31.07,0.103
193.93,-31.00,0.103
193.95,-30.94,0.103
193.96,-30.87,0.103
193.97,-30.81,0.103
193.98,-30.74,0.103
194.00,-30.67,0.103
194.01,-30.61,0.103
194.03,-30.54,0.103
194.04,-30.48,0.103
194.05,-30.41,0.103
194.07,-30.34,0.103
194.08,-30.28,0.103
194.09,-30.21,0.103
194.10,-30.14,0.103
194.12,-30.07,0.103
194.13,-30.01,0.103
194.15,-29.94,0.103
194.16,-29.87,0.103
194.17,-29.81,0.103
194.18,-29.74,0.103
194.20,-29.67,0.103
194.21,-29.61,0.103
194.23,-29.54,0.103
194.24,-29.47,0.103
194.25,-29.41,0.103
194.27,-29.34,0.103
194.28,-29.27,0.103
194.29,-29.21,0.103
194.30,-29.14,0.103
194.32,-29.07,0.103
194.33,-29.00,0.103
194.35,-28.94,0.103
194.36,-28.87,0.104
194.37,-28.80,0.104
194.38,-28.74,0.104
194.40,-28.67,0.104
194.41,-28.60,0.104
194.43,-28.54,0.104
194.44,-28.47,0.104
194.45,-28.40,0.104
194.47,-28.34,0.104
194.48,-28.27,0.104
194.49,-28.20,0.104
194.50,-28.14,0.104
194.52,-28.07,0.104
194.53,-28.00,0.104
194.55,-27.94,0.104
194.56,-27.87,0.104
194.57,-27.80,0.104
194.58,-27.74,0.104
194.60,-27.67,0.104
194.61,-27.60,0.104
194.63,-27.54,0.104
194.64,-27.47,0.104
194.65,-27.40,0.104
194.67,-27.33,0.104
194.68,-27.27,0.104
194.69,-27.20,0.104
194.70,-27.13,0.104
194.72,-27.07,0.104
194.73,-27.00,0.104
194.75,-26.93,0.104
194.76,-26.87,0.104
194.77,-26.80,0.104
194.78,-26.73,0.104
194.80,-26.67,0.104
194.81,-26.60,0.104
194.83,-26.53,0.104
194.84,-26.47,0.104
194.85,-26.40,0.104
194.87,-26.33,0.104
194.88,-26.27,0.104
194.89,-26.20,0.104
194.90,-26.13,0.104
194.92,-26.07,0.104
194.93,-26.00,0.104
194.95,-25.93,0.104
194.96,-25.87,0.104
194.97,-25.80,0.104
194.98,-25.73,0.104
195.00,-25.67,0.104
195.01,-25.60,0.104
195.03,-25.53,0.104
195.04,-25.46,0.104
195.05,-25.40,0.104
195.07,-25.33,0.104
195.08,-25.26,0.104
195.09,-25.20,0.104
195.10,-25.13,0.104
195.12,-25.07,0.104
195.13,-25.00,0.104
195.15,-24.93,0.104
195.16,-24.86,0.104
195.17,-24.80,0.104
195.18,-24.73,0.104
195.20,-24.66,0.104
195.21,-24.60,0.104
195.23,-24.53,0.104
195.24,-24.46,0.104
195.25,-24.40,0.104
195.27,-24.33,0.104
195.28,-24.26,0.104
195.29,-24.20,0.104
195.30,-24.13,0.104
195.32,-24.06,0.104
195.33,-24.00,0.104
195.35,-23.93,0.104
195.36,-23.86,0.104
195.37,-23.80,0.104
195.38,-23.73,0.104
195.40,-23.66,0.104
195.41,-23.59,0.104
195.43,-23.53,0.104
195.44,-23.46,0.104
195.45,-23.39,0.105
195.47,-23.33,0.105
195.48,-23.26,0.105
195.49,-23.19,0.104
195.50,-23.13,0.105
195.52,-23.06,0.105
195.53,-22.99,0.105
195.55,-22.93,0.105
195.56,-22.86,0.105
195.57,-22.79,0.105
195.58,-22.73,0.105
195.60,-22.66,0.105
195.61,-22.59,0.105
195.63,-22.53,0.105
195.64,-22.46,0.105
195.65,-22.39,0.105
195.67,-22.32,0.105
195.68,-22.26,0.105
195.69,-22.19,0.105
195.70,-22.12,0.105
195.72,-22.06,0.105
195.73,-21.99,0.105
195.75,-21.92,0.105
195.76,-21.86,0.105
195.77,-21.79,0.105
195.78,-21.72,0.105
195.80,-21.66,0.105
195.81,-21.59,0.105
195.83,-21.52,0.105
195.84,-21.46,0.105
195.85,-21.39,0.105
195.87,-21.32,0.105
195.88,-21.26,0.105
195.89,-21.19,0.105
195.90,-21.12,0.105
195.92,-21.06,0.105
195.93,-20.99,0.105
195.95,-20.93,0.105
195.96,-20.86,0.105
195.97,-20.79,0.105
195.98,-20.73,0.105
196.00,-20.66,0.105
196.01,-20.59,0.105
196.03,-20.53,0.105
196.04,-20.46,0.105
196.05,-20.39,0.105
196.07,-20.33,0.105
196.08,-20.26,0.105
196.09,-20.19,0.105
196.10,-20.13,0.105
196.12,-20.06,0.105
196.13,-19.99,0.105
196.15,-19.93,0.105
196.16,-19.86,0.105
196.17,-19.79,0.105
196.18,-19.73,0.105
196.20,-19.66,0.105
196.21,-19.59,0.105
196.23,-19.53,0.105
196.24,-19.46,0.105
196.25,-19.39,0.105
196.27,-19.33,0.105
196.28,-19.26,0.105
196.29,-19.19,0.105
196.30,-19.12,0.105
196.32,-19.06,0.105
196.33,-18.99,0.105
196.35,-18.92,0.105
196.36,-18.86,0.105
196.37,-18.79,0.105
196.38,-18.72,0.105
196.40,-18.66,0.105
196.41,-18.59,0.105
196.43,-18.52,0.105
196.44,-18.46,0.105
196.45,-18.39,0.105
196.47,-18.32,0.105
196.48,-18.26,0.105
196.49,-18.19,0.105
196.50,-18.12,0.105
196.52,-18.06,0.105
196.53,-17.99,0.105
196.55,-17.92,0.105
196.56,-17.86,0.105
196.57,-17.79,0.105
196.58,-17.72,0.105
196.60,-17.66,0.105
196.61,-17.59,0.106
196.63,-17.52,0.105
196.64,-17.46,0.105
196.65,-17.39,0.105
196.67,-17.32,0.105
196.68,-17.26,0.105
196.69,-17.19,0.105
196.70,-17.12,0.105
196.72,-17.06,0.105
196.73,-16.99,0.105
196.75,-16.92,0.105
196.76,-16.86,0.105
196.77,-16.79,0.105
196.78,-16.73,0.105
196.80,-16.66,0.105
196.81,-16.59,0.105
196.83,-16.52,0.105
196.84,-16.46,0.105
196.85,-16.39,0.105
196.87,-16.32,0.105
196.88,-16.26,0.106
196.89,-16.19,0.106
196.90,-16.12,0.106
196.92,-16.06,0.106
196.93,-15.99,0.106
196.95,-15.92,0.106
196.96,-15.86,0.106
196.97,-15.79,0.106
196.98,-15.72,0.106
197.00,-15.66,0.106
197.01,-15.59,0.106
197.03,-15.52,0.106
197.04,-15.46,0.106
197.05,-15.39,0.106
197.07,-15.32,0.106
197.08,-15.26,0.106
197.09,-15.19,0.106
197.10,-15.12,0.106
197.12,-15.06,0.106
197.13,-14.99,0.106
197.15,-14.92,0.106
197.16,-14.86,0.106
197.17,-14.79,0.106
197.18,-14.72,0.106
197.20,-14.65,0.106
197.21,-14.59,0.106
197.23,-14.52,0.106
197.24,-14.46,0.106
197.25,-14.39,0.106
197.27,-14.32,0.106
197.28,-14.26,0.106
197.29,-14.19,0.106
197.30,-14.12,0.106
197.32,-14.06,0.106
197.33,-13.99,0.106
197.35,-13.92,0.106
197.36,-13.85,0.106
197.37,-13.79,0.106
197.38,-13.72,0.106
197.40,-13.65,0.106
197.41,-13.59,0.106
197.43,-13.52,0.106
197.44,-13.45,0.106
197.45,-13.39,0.106
197.47,-13.32,0.106
197.48,-13.25,0.106
197.49,-13.19,0.106
197.50,-13.12,0.106
197.52,-13.05,0.106
197.53,-12.99,0.106
197.55,-12.92,0.106
197.56,-12.85,0.106
197.57,-12.79,0.106
197.58,-12.72,0.106
197.60,-12.65,0.106
197.61,-12.59,0.106
197.63,-12.52,0.106
197.64,-12.45,0.106
197.65,-12.39,0.106
197.67,-12.32,0.107
197.68,-12.25,0.107
197.69,-12.19,0.107
197.70,-12.12,0.107
197.72,-12.05,0.107
197.73,-11.99,0.107
197.75,-11.92,0.107
197.76,-11.85,0.107
197.77,-11.79,0.107
197.78,-11.72,0.107
197.80,-11.65,0.107
197.81,-11.59,0.107
197.83,-11.52,0.107
197.84,-11.45,0.107
197.85,-11.39,0.107
197.87,-11.32,0.107
197.88,-11.25,0.107
197.89,-11.19,0.107
197.90,-11.12,0.107
197.92,-11.05,0.107
197.93,-10.99,0.107
197.95,-10.92,0.107
197.96,-10.85,0.107
197.97,-10.79,0.107
197.98,-10.72,0.107
198.00,-10.65,0.107
198.01,-10.58,0.107
198.03,-10.52,0.107
198.04,-10.45,0.107
198.05,-10.38,0.107
198.07,-10.32,0.107
198.08,-10.25,0.107
198.09,-10.18,0.107
198.10,-10.12,0.107
198.12,-10.05,0.107
198.13,-9.98,0.107
198.15,-9.92,0.107
198.16,-9.85,0.107
198.17,-9.79,0.107
198.18,-9.72,0.107
198.20,-9.65,0.107
198.21,-9.59,0.107
198.23,-9.52,0.107
198.24,-9.45,0.107
198.25,-9.39,0.107
198.27,-9.32,0.107
198.28,-9.25,0.107
198.29,-9.19,0.107
198.30,-9.12,0.107
198.32,-9.05,0.107
198.33,-8.98,0.107
198.35,-8.92,0.107
198.36,-8.85,0.107
198.37,-8.78,0.107
198.38,-8.72,0.107
198.40,-8.65,0.107
198.41,-8.59,0.107
198.43,-8.52,0.107
198.44,-8.45,0.108
198.45,-8.38,0.108
198.47,-8.32,0.108
198.48,-8.25,0.108
198.49,-8.18,0.108
198.50,-8.12,0.108
198.52,-8.05,0.108
198.53,-7.98,0.108
198.55,-7.92,0.108
198.56,-7.85,0.108
198.57,-7.78,0.108
198.58,-7.72,0.108
198.60,-7.65,0.108
198.61,-7.58,0.108
198.63,-7.52,0.108
198.64,-7.45,0.108
198.65,-7.38,0.108
198.67,-7.32,0.108
198.68,-7.25,0.108
198.69,-7.18,0.108
198.70,-7.12,0.108
198.72,-7.05,0.108
198.73,-6.98,0.108
198.75,-6.92,0.108
198.76,-6.85,0.108
198.77,-6.78,0.108
198.78,-6.72,0.108
198.80,-6.65,0.108
198.81,-6.58,0.108
198.83,-6.52,0.108
198.84,-6.45,0.108
198.85,-6.38,0.108
198.87,-6.32,0.108
198.88,-6.25,0.108
198.89,-6.18,0.108
198.90,-6.12,0.108
198.92,-6.05,0.108
198.93,-5.98,0.108
198.95,-5.91,0.109
198.96,-5.85,0.109
198.97,-5.78,0.109
198.98,-5.71,0.109
199.00,-5.65,0.109
199.01,-5.58,0.109
199.03,-5.51,0.109
199.04,-5.45,0.109
199.05,-5.38,0.109
199.07,-5.31,0.109
199.08,-5.25,0.109
199.09,-5.18,0.109
199.10,-5.11,0.109
199.12,-5.05,0.109
199.13,-4.98,0.109
199.15,-4.91,0.109
199.16,-4.84,0.109
199.17,-4.78,0.109
199.18,-4.71,0.109
199.20,-4.65,0.109
199.21,-4.58,0.109
199.23,-4.51,0.109
199.24,-4.45,0.109
199.25,-4.38,0.109
199.27,-4.31,0.109
199.28,-4.25,0.110
199.29,-4.18,0.110
199.30,-4.11,0.110
199.32,-4.05,0.110
199.33,-3.98,0.110
199.35,-3.91,0.110
199.36,-3.85,0.110
199.37,-3.78,0.110
199.38,-3.71,0.110
199.40,-3.65,0.110
199.41,-3.58,0.110
199.43,-3.51,0.110
199.44,-3.45,0.110
199.45,-3.38,0.110
199.47,-3.31,0.110
199.48,-3.25,0.110
199.49,-3.18,0.110
199.50,-3.11,0.110
199.52,-3.05,0.111
199.53,-2.98,0.111
199.55,-2.91,0.111
199.56,-2.85,0.111
199.57,-2.78,0.111
199.58,-2.71,0.111
199.60,-2.65,0.111
199.61,-2.58,0.111
199.63,-2.51,0.111
199.64,-2.45,0.111
199.65,-2.38,0.111
199.67,-2.31,0.111
199.68,-2.25,0.111
199.69,-2.18,0.111
199.70,-2.11,0.112
199.72,-2.05,0.112
199.73,-1.98,0.112
199.75,-1.91,0.112
199.76,-1.85,0.112
199.77,-1.78,0.112
199.78,-1.71,0.112
199.80,-1.65,0.112
199.81,-1.58,0.112
199.83,-1.51,0.112
199.84,-1.45,0.113
199.85,-1.38,0.113
199.87,-1.31,0.113
199.88,-1.25,0.113
199.89,-1.18,0.113
199.90,-1.11,0.113
199.92,-1.05,0.113
199.93,-0.98,0.113
199.95,-0.91,0.113
199.96,-0.85,0.114
199.97,-0.78,0.114
199.98,-0.71,0.114
200.00,-0.65,0.114
200.01,-0.58,0.114
200.03,-0.51,0.114
200.04,-0.45,0.114
200.05,-0.38,0.114
200.07,-0.31,0.114
200.08,-0.25,0.115
200.09,-0.18,0.115
200.10,-0.11,0.115
200.12,-0.05,0.115
200.13,0.02,0.115
200.15,0.09,0.115
200.16,0.15,0.116
200.17,0.22,0.116
200.18,0.29,0.116
200.20,0.35,0.116
200.21,0.42,0.116
200.23,0.49,0.116
200.24,0.55,0.116
200.25,0.62,0.117
200.27,0.69,0.117
200.28,0.75,0.117
200.29,0.82,0.117
200.30,0.89,0.117
200.32,0.95,0.118
200.33,1.02,0.118
200.35,1.09,0.118
200.36,1.15,0.118
200.37,1.22,0.118
200.38,1.29,0.119
200.40,1.35,0.119
200.41,1.42,0.119
200.43,1.49,0.119
200.44,1.55,0.120
200.45,1.62,0.120
200.47,1.69,0.120
200.48,1.75,0.120
200.49,1.82,0.120
200.50,1.89,0.121
200.52,1.95,0.121
200.53,2.02,0.121
200.55,2.09,0.122
200.56,2.15,0.122
200.57,2.22,0.122
200.58,2.29,0.122
200.60,2.35,0.123
200.61,2.42,0.123
200.63,2.49,0.123
200.64,2.55,0.123
200.65,2.62,0.124
200.67,2.69,0.124
200.68,2.75,0.125
200.69,2.82,0.125
200.70,2.89,0.125
200.72,2.95,0.126
200.73,3.02,0.126
200.75,3.09,0.126
200.76,3.15,0.127
200.77,3.22,0.127
200.78,3.29,0.128
200.80,3.35,0.128
200.81,3.42,0.128
200.83,3.48,0.129
200.84,3.55,0.129
200.85,3.62,0.129
200.87,3.69,0.130
200.88,3.75,0.130
200.89,3.82,0.131
200.90,3.88,0.131
200.92,3.95,0.132
200.93,4.02,0.132
200.95,4.08,0.133
200.96,4.15,0.133
200.97,4.22,0.134
200.98,4.28,0.135
201.00,4.35,0.135
201.01,4.42,0.136
201.03,4.48,0.136
201.04,4.55,0.137
201.05,4.62,0.137
201.07,4.68,0.138
201.08,4.75,0.138
201.09,4.82,0.139
201.10,4.88,0.140
201.12,4.95,0.140
201.13,5.02,0.141
201.15,5.08,0.141
201.16,5.15,0.142
201.17,5.21,0.142
201.18,5.28,0.143
201.20,5.35,0.143
201.21,5.41,0.144
201.23,5.48,0.144
201.24,5.55,0.144
201.25,5.61,0.145
201.27,5.68,0.145
201.28,5.75,0.146
201.29,5.81,0.146
201.30,5.88,0.146
201.32,5.95,0.147
201.33,6.01,0.147
201.35,6.08,0.148
201.36,6.15,0.148
201.37,6.21,0.149
201.38,6.28,0.149
201.40,6.35,0.149
201.41,6.41,0.150
201.43,6.48,0.150
201.44,6.55,0.150
201.45,6.61,0.150
201.47,6.68,0.151
201.48,6.75,0.151
201.49,6.81,0.151
201.50,6.88,0.151
201.52,6.95,0.151
201.53,7.01,0.152
201.55,7.08,0.152
201.56,7.15,0.152
201.57,7.21,0.152
201.58,7.28,0.152
201.60,7.35,0.152
201.61,7.41,0.152
201.63,7.48,0.152
201.64,7.55,0.152
201.65,7.61,0.152
201.67,7.68,0.152
201.68,7.75,0.152
201.69,7.82,0.152
201.70,7.88,0.152
201.72,7.95,0.152
201.73,8.02,0.151
201.75,8.08,0.151
201.76,8.15,0.151
201.77,8.22,0.151
201.78,8.28,0.151
201.80,8.35,0.151
201.81,8.42,0.150
201.83,8.48,0.150
201.84,8.55,0.150
201.85,8.62,0.150
201.87,8.68,0.149
201.88,8.75,0.149
201.89,8.82,0.149
201.90,8.89,0.149
201.92,8.95,0.148
201.93,9.02,0.148
201.95,9.08,0.148
201.96,9.15,0.148
201.97,9.22,0.147
201.98,9.29,0.147
202.00,9.35,0.147
202.01,9.42,0.147
202.03,9.49,0.146
202.04,9.55,0.146
202.05,9.62,0.146
202.07,9.69,0.146
202.08,9.75,0.146
202.09,9.82,0.146
202.10,9.89,0.145
202.12,9.95,0.145
202.13,10.02,0.145
202.15,10.09,0.145
202.16,10.15,0.145
202.17,10.22,0.145
202.18,10.29,0.144
202.20,10.35,0.144
202.21,10.42,0.144
202.23,10.49,0.144
202.24,10.55,0.144
202.25,10.62,0.144
202.27,10.69,0.144
202.28,10.75,0.143
202.29,10.82,0.143
202.30,10.89,0.143
202.32,10.95,0.143
202.33,11.02,0.143
202.35,11.09,0.143
202.36,11.16,0.143
202.37,11.22,0.143
202.38,11.29,0.143
202.40,11.36,0.143
202.41,11.42,0.142
202.43,11.49,0.142
202.44,11.56,0.142
202.45,11.62,0.142
202.47,11.69,0.142
202.48,11.76,0.142
202.49,11.82,0.142
202.50,11.89,0.142
202.52,11.96,0.142
202.53,12.02,0.142
202.55,12.09,0.142
202.56,12.16,0.142
202.57,12.22,0.142
202.58,12.29,0.142
202.60,12.36,0.142
202.61,12.42,0.142
202.63,12.49,0.142
202.64,12.56,0.142
202.65,12.62,0.142
202.67,12.69,0.142
202.68,12.76,0.142
202.69,12.82,0.142
202.70,12.89,0.142
202.72,12.96,0.142
202.73,13.02,0.142
202.75,13.09,0.141
202.76,13.16,0.141
202.77,13.22,0.141
202.78,13.29,0.141
202.80,13.36,0.141
202.81,13.42,0.141
202.83,13.49,0.141
202.84,13.56,0.141
202.85,13.62,0.141
202.87,13.69,0.141
202.88,13.76,0.141
202.89,13.82,0.141
202.90,13.89,0.141
202.92,13.96,0.141
202.93,14.02,0.141
202.95,14.09,0.141
202.96,14.16,0.141
202.97,14.22,0.141
202.98,14.29,0.141
203.00,14.36,0.141
203.01,14.42,0.141
203.03,14.49,0.141
203.04,14.56,0.141
203.05,14.62,0.141
203.07,14.69,0.141
203.08,14.76,0.141
203.09,14.82,0.141
203.10,14.89,0.141
203.12,14.96,0.141
203.13,15.02,0.141
203.15,15.09,0.141
203.16,15.16,0.141
203.17,15.23,0.141
203.18,15.29,0.141
203.20,15.36,0.141
203.21,15.43,0.141
203.23,15.49,0.141
203.24,15.56,0.141
203.25,15.63,0.141
203.27,15.69,0.141
203.28,15.76,0.141
203.29,15.83,0.141
203.30,15.89,0.141
203.32,15.96,0.141
203.33,16.02,0.141
203.35,16.09,0.141
203.36,16.16,0.141
203.37,16.23,0.141
203.38,16.29,0.141
203.40,16.36,0.141
203.41,16.43,0.141
203.43,16.49,0.141
203.44,16.56,0.141
203.45,16.63,0.141
203.47,16.69,0.141
203.48,16.76,0.141
203.49,16.83,0.141
203.50,16.89,0.141
203.52,16.96,0.141
203.53,17.03,0.141
203.55,17.09,0.142
203.56,17.16,0.142
203.57,17.23,0.142
203.58,17.29,0.142
203.60,17.36,0.142
203.61,17.43,0.142
203.63,17.49,0.142
203.64,17.56,0.142
203.65,17.63,0.142
203.67,17.69,0.142
203.68,17.76,0.142
203.69,17.83,0.142
203.70,17.89,0.142
203.72,17.96,0.142
203.73,18.03,0.142
203.75,18.09,0.142
203.76,18.16,0.142
203.77,18.23,0.142
203.78,18.29,0.142
203.80,18.36,0.142
203.81,18.43,0.142
203.83,18.49,0.142
203.84,18.56,0.142
203.85,18.63,0.142
203.87,18.69,0.142
203.88,18.76,0.142
203.89,18.83,0.142
203.90,18.89,0.142
203.92,18.96,0.142
203.93,19.03,0.142
203.95,19.10,0.142
203.96,19.16,0.142
203.97,19.23,0.142
203.98,19.30,0.142
204.00,19.36,0.142
204.01,19.43,0.142
204.03,19.49,0.142
204.04,19.56,0.142
204.05,19.63,0.142
204.07,19.69,0.142
204.08,19.76,0.142
204.09,19.83,0.142
204.10,19.89,0.142
204.12,19.96,0.142
204.13,20.03,0.142
204.15,20.09,0.142
204.16,20.16,0.142
204.17,20.23,0.142
204.18,20.30,0.142
204.20,20.36,0.142
204.21,20.43,0.142
204.23,20.50,0.142
204.24,20.56,0.142
204.25,20.63,0.142
204.27,20.70,0.142
204.28,20.76,0.142
204.29,20.83,0.142
204.30,20.90,0.142
204.32,20.96,0.142
204.33,21.03,0.142
204.35,21.10,0.142
204.36,21.16,0.142
204.37,21.23,0.142
204.38,21.30,0.142
204.40,21.36,0.142
204.41,21.43,0.142
204.43,21.50,0.142
204.44,21.56,0.142
204.45,21.63,0.142
204.47,21.70,0.142
204.48,21.76,0.142
204.49,21.83,0.142
204.50,21.90,0.142
204.52,21.96,0.142
204.53,22.03,0.142
204.55,22.10,0.142
204.56,22.16,0.142
204.57,22.23,0.142
204.58,22.30,0.142
204.60,22.36,0.142
204.61,22.43,0.142
204.63,22.50,0.142
204.64,22.56,0.142
204.65,22.63,0.142
204.67,22.70,0.142
204.68,22.76,0.143
204.69,22.83,0.143
204.70,22.90,0.143
204.72,22.96,0.143
204.73,23.03,0.143
204.75,23.10,0.143
204.76,23.16,0.143
204.77,23.23,0.143
204.78,23.30,0.143
204.80,23.36,0.143
204.81,23.43,0.143
204.83,23.50,0.143
204.84,23.56,0.143
204.85,23.63,0.143
204.87,23.70,0.143
204.88,23.76,0.143
204.89,23.83,0.143
204.90,23.90,0.143
204.92,23.97,0.143
204.93,24.03,0.143
204.95,24.10,0.143
204.96,24.17,0.143
204.97,24.23,0.143
204.98,24.30,0.143
205.00,24.37,0.143
205.01,24.43,0.143
205.03,24.50,0.143
205.04,24.57,0.143
205.05,24.63,0.143
205.07,24.70,0.143
205.08,24.77,0.143
205.09,24.83,0.143
205.10,24.90,0.143
205.12,24.97,0.143
205.13,25.03,0.143
205.15,25.10,0.143
205.16,25.17,0.143
205.17,25.23,0.143
205.18,25.30,0.143
205.20,25.37,0.143
205.21,25.43,0.143
205.23,25.50,0.143
205.24,25.57,0.143
205.25,25.63,0.143
205.27,25.70,0.143
205.28,25.77,0.143
205.29,25.83,0.143
205.30,25.90,0.143
205.32,25.97,0.143
205.33,26.03,0.143
205.35,26.10,0.143
205.36,26.17,0.143
205.37,26.23,0.143
205.38,26.30,0.143
205.40,26.37,0.143
205.41,26.43,0.143
205.43,26.50,0.143
205.44,26.57,0.143
205.45,26.63,0.143
205.47,26.70,0.143
205.48,26.77,0.143
205.49,26.83,0.143
205.50,26.90,0.144
205.52,26.97,0.144
205.53,27.03,0.144
205.55,27.10,0.144
205.56,27.17,0.144
205.57,27.24,0.144
205.58,27.30,0.144
205.60,27.37,0.144
205.61,27.43,0.144
205.63,27.50,0.144
205.64,27.57,0.144
205.65,27.63,0.144
205.67,27.70,0.144
205.68,27.77,0.144
205.69,27.83,0.144
205.70,27.90,0.144
205.72,27.97,0.144
205.73,28.03,0.144
205.75,28.10,0.144
205.76,28.17,0.144
205.77,28.23,0.144
205.78,28.30,0.144
205.80,28.37,0.144
205.81,28.43,0.144
205.83,28.50,0.144
205.84,28.57,0.144
205.85,28.64,0.144
205.87,28.70,0.144
205.88,28.77,0.144
205.89,28.84,0.144
205.90,28.90,0.144
205.92,28.97,0.144
205.93,29.04,
205.95,29.10,
205.96,29.17,
205.97,29.24,
205.98,,