File: DSC/2025_06_15_CBN_Succinic_Acid_Slurry_n60C_200C_10Cmin_x3.csv
Filename,2025_06_15_CBN_Succinic_Acid_Slurry_n60C_200C_10Cmin_x3
Instrument name,DSC2A-00468 (192.168.1.100)
Operator,Yarger
rundate,6/15/2025
Sample name,2025_06_15_CBN_Succinic_Acid_Slurry_n60C_200C_10Cmin_x3
proceduresegments,Data Off ; Equilibrate -60.00 °C; Data On ; Ramp 10.00 °C/min to 200.00 °C; Data Off ; Isothermal 2.0 min; Data On ; Ramp 10.00 °C/min to -60.00 °C; Data Off ; Isothermal 2.0 min; Data On ; Ramp 10.00 °C/min to 200.00 °C; Data Off ; Isothermal 2.0 min; Data On ; Ramp 10.00 °C/min to -60.00 °C; Data Off ; Isothermal 2.0 min; Data On ; Ramp 10.00 °C/min to 30.00 °C
[File Parameters]
Run date,6/15/2025 1:07:24 AM
Trios version,5.1.1.46572
Original File Name,
Current File Name,D:\DSC2500\JYarger\2025_06_15_CBN_Succinic_Acid_Slurry_n60C_200C_10Cmin_x3.tri
[Procedure]
Procedure Name,CBN_SA_n60C_200C_10Cmin_x3
Sample Name,2025_06_15_CBN_Succinic_Acid_Slurry_n60C_200C_10Cmin_x3
Sample Mass,7.93 mg
Reference Sample Mass,0 mg
Pan Mass,57 mg
Pan Number,40
Reference Pan Mass,57.05 mg
Reference Pan Number,28
Pan Type,Tzero Aluminum Hermetic
Comments,Al Hermetic DSC Consumables sealed Pan/Lid. A2 Tray (Google Sheet: DSC_Samples_A2_Tray_May2025)
Project Name,CA
Operator,Yarger
Test,Custom
Unload Max Temperature,30
Unload Min Temperature,30
Load Max Temperature,30
Load Min Temperature,30
Stop on Gas Flow Error,Yes
[Signal List]
Signal #1,Time (min)
Signal #2,Temperature (°C)
Signal #3,Heat Flow (mW)
Signal #4,Delta T (µV)
Signal #5,Delta Tzero (µV)
Signal #6,Tzero Temperature (°C)
Signal #7,Cell Purge (mL/min)
Signal #8,Heater Temp (°C)
Signal #9,Power Delivered (W)
Signal #10,Reference Junction Temperature (°C)
Signal #11,Flange Temperature (°C)
Signal #12,Heat Flow Phase (rad)
Signal #13,Total Heat Capacity (J/°C)
Signal #14,Heat Capacity (J/°C)
[Configuration]
Company Name,ASU
Instrument Name,DSC2A-00468
Instrument Type,DSC2500
Serial Number,DSC2A-00468
IP,192.168.1.100
Location of Instrument,MRRC
DisplayType,Unknown
Sample Interval ,0.1 s/pt
Selected Heat Flow,T4P
Exotherm Direction,Down
Cell Serial,DRC2-00792
Lid Type,Standard
Cooler,RCS 90
Leave Cooler on at End of Sequence,On
Gas 2,Nitrogen
Gas Selected,Channel 1
Flow Rate,50 mL/min
Secondary Purge,On
Licensed Heat Flow,Heat Flow T4P
Modulation Licensed,Yes
[Versions]
Common IDD Version,1
Cortex Version,VER 2.10.2.31
Driver,5.0.0.6
GDM Version,1.0.3.3
TouchscreenVersion,1.0.0.16145
FEP Version,1.2.1.21
FEP Bootloader,2.0.0.5
AutoSampler Version,2.1.1.26
Auto Sampler Bootloader,2.0.0.5
FCM Version,1.1.0.3
FCM Bootloader,2.0.0.5
[Experiment Logs]
Experiment Log Entry # 1,Data On set to 0
Experiment Log Entry # 3,Equilibrate Segment -60 (C) Started
Experiment Log Entry # 5,Air Cool is off.
Experiment Log Entry # 7,Data On set to 1
Experiment Log Entry # 9,Ramp Segment 10 C/min to 200 Started
Experiment Log Entry # 11,Data On set to 0
Experiment Log Entry # 13,Isothermal Segment 2 min started
Experiment Log Entry # 15,Data On set to 1
Experiment Log Entry # 17,Ramp Segment 10 C/min to -60 Started
Experiment Log Entry # 19,Data On set to 0
Experiment Log Entry # 21,Isothermal Segment 2 min started
Experiment Log Entry # 23,Data On set to 1
Experiment Log Entry # 25,Ramp Segment 10 C/min to 200 Started
Experiment Log Entry # 27,Data On set to 0
Experiment Log Entry # 29,Isothermal Segment 2 min started
Experiment Log Entry # 31,Data On set to 1
Experiment Log Entry # 33,Ramp Segment 10 C/min to -60 Started
Experiment Log Entry # 35,Data On set to 0
Experiment Log Entry # 37,Isothermal Segment 2 min started
Experiment Log Entry # 39,Data On set to 1
Experiment Log Entry # 41,Ramp Segment 10 C/min to 30 Started
[Method Log]
Method Log Entry # 1,Data Off
Method Log Entry # 2,Equilibrate -60 °C
Method Log Entry # 3,Data On
Method Log Entry # 4,(Ramp 247160) Ramp 10 °C/minute to 200 °C
Method Log Entry # 5,Data Off
Method Log Entry # 6,Isothermal 2 minutes
Method Log Entry # 7,Data On
Method Log Entry # 8,(Ramp 247164) Ramp 10 °C/minute to -60 °C
Method Log Entry # 9,Data Off
Method Log Entry # 10,Isothermal 2 minutes
Method Log Entry # 11,Data On
Method Log Entry # 12,(Ramp 247168) Ramp 10 °C/minute to 200 °C
Method Log Entry # 13,Data Off
Method Log Entry # 14,Isothermal 2 minutes
Method Log Entry # 15,Data On
Method Log Entry # 16,(Ramp 247172) Ramp 10 °C/minute to -60 °C
Method Log Entry # 17,Data Off
Method Log Entry # 18,Isothermal 2 minutes
Method Log Entry # 19,Data On
Method Log Entry # 20,(Ramp 247176) Ramp 10 °C/minute to 30 °C
Cell Serial,DRC2-00792
[T1 Calibration]
Slope,-0.008529666
Offset,9.636258
Initial Temperature,98.23
GUID,f8bfdadc-4977-4fdf-ba6d-0ba9134940c3
[TZero Calibration]
Date Applied,11/29/2022 4:06:13 PM
Description,From -89.059 °C to 396.009 °C at 20.000°C/min
Gas Type,Nitrogen
Pan Type,None
Source Files 1,C:\Users\yargerlab\Desktop\DSC Data\General\TZero_calibration_11_29_22_2nd(2).tri
Source Files 2,C:\Users\yargerlab\Desktop\DSC Data\General\TZero_calibration_11_29_22_2nd(3).tri
Delta T Offset,13.05235
Delta T Slope,-0.007271007
Delta T0 Offset,-13.69128
Delta T0 Slope,0.06063341
[Temperature Calibration]
Date Applied,11/29/2022 7:12:28 PM
Description,From 106.590 °C to 186.590 °C at 10.000°C/min
Gas Type,Nitrogen
Pan Type,Tzero Aluminum Hermetic
Source Files 1,C:\Users\yargerlab\Desktop\DSC Data\General\Indium(6).tri
Measured 1,157.391
Known 1,156.598
[Cell Constant Calibration]
Date Applied,11/29/2022 7:12:29 PM
Description,From 106.590 °C to 186.590 °C at 10.000°C/min
Gas Type,Nitrogen
Pan Type,Tzero Aluminum Hermetic
Source Files 1,C:\Users\yargerlab\Desktop\DSC Data\General\Indium(6).tri
T4P KCell,1.006051
Onset Slope,63.26126 mW/°C
[Direct Cp Calibration]
Date Applied,11/30/2022 11:04:51 AM
Description,From -79.983 °C to 298.409 °C at 10.000°C/min
Gas Type,Nitrogen
Pan Type,Tzero Aluminum Hermetic
Source Files 1,C:\Users\yargerlab\Desktop\DSC Data\General\Sapphire_Heat_Capacity_11_30_22.tri
[Rev Cp Calibration]
Date Applied,11/30/2022 1:58:51 PM
Description,From -79.996 °C to 292.812 °C at 3.000°C/min
Gas Type,Nitrogen
Pan Type,Tzero Aluminum Hermetic
Source Files 1,C:\Users\yargerlab\Desktop\DSC Data\General\Sapphire_MDSC_Calibration_11_30_22.tri
[step]
Ramp 10.00 °C/min to 200.00 °C
Time,Temperature,Heat Flow (Normalized)
min,°C,W/g
0.00,-59.67,-0.055
0.02,-59.68,-0.053
0.04,-59.69,-0.048
0.05,-59.69,-0.044
0.07,-59.67,-0.041
0.09,-59.63,-0.038
0.11,-59.58,-0.033
0.13,-59.50,-0.025
0.15,-59.41,-0.013
0.16,-59.30,0.000
0.18,-59.18,0.016
0.20,-59.05,0.031
0.22,-58.92,0.048
0.24,-58.78,0.062
0.26,-58.63,0.077
0.28,-58.48,0.090
0.29,-58.32,0.100
0.31,-58.16,0.110
0.33,-58.00,0.118
0.35,-57.84,0.126
0.37,-57.68,0.133
0.39,-57.51,0.139
0.40,-57.34,0.145
0.42,-57.18,0.148
0.44,-57.01,0.152
0.46,-56.83,0.155
0.48,-56.66,0.158
0.50,-56.49,0.162
0.51,-56.31,0.164
0.53,-56.14,0.165
0.55,-55.96,0.168
0.57,-55.79,0.169
0.59,-55.61,0.171
0.60,-55.44,0.172
0.62,-55.26,0.174
0.64,-55.08,0.175
0.66,-54.90,0.175
0.68,-54.72,0.176
0.70,-54.55,0.177
0.72,-54.37,0.178
0.73,-54.19,0.178
0.75,-54.01,0.179
0.77,-53.83,0.179
0.79,-53.65,0.180
0.81,-53.47,0.180
0.83,-53.29,0.181
0.84,-53.11,0.181
0.86,-52.93,0.182
0.88,-52.75,0.182
0.90,-52.57,0.182
0.92,-52.39,0.183
0.93,-52.21,0.183
0.95,-52.03,0.183
0.97,-51.84,0.184
0.99,-51.66,0.184
1.01,-51.48,0.184
1.03,-51.30,0.184
1.05,-51.12,0.185
1.06,-50.94,0.185
1.08,-50.75,0.185
1.10,-50.57,0.185
1.12,-50.39,0.186
1.14,-50.21,0.186
1.16,-50.03,0.186
1.17,-49.84,0.186
1.19,-49.66,0.186
1.21,-49.48,0.187
1.23,-49.30,0.187
1.25,-49.11,0.187
1.27,-48.93,0.187
1.28,-48.75,0.188
1.30,-48.57,0.188
1.32,-48.38,0.188
1.34,-48.20,0.188
1.36,-48.02,0.188
1.38,-47.84,0.188
1.39,-47.65,0.189
1.41,-47.47,0.189
1.43,-47.29,0.189
1.45,-47.11,0.189
1.47,-46.92,0.189
1.48,-46.74,0.190
1.50,-46.56,0.190
1.52,-46.37,0.190
1.54,-46.19,0.190
1.56,-46.01,0.190
1.58,-45.82,0.190
1.59,-45.64,0.190
1.61,-45.46,0.191
1.63,-45.27,0.191
1.65,-45.09,0.191
1.67,-44.91,0.191
1.69,-44.72,0.191
1.71,-44.54,0.191
1.72,-44.36,0.191
1.74,-44.18,0.192
1.76,-43.99,0.192
1.78,-43.81,0.192
1.80,-43.63,0.192
1.82,-43.44,0.192
1.83,-43.26,0.192
1.85,-43.08,0.192
1.87,-42.89,0.192
1.89,-42.71,0.193
1.91,-42.52,0.193
1.93,-42.34,0.193
1.94,-42.16,0.193
1.96,-41.97,0.193
1.98,-41.79,0.193
2.00,-41.61,0.193
2.02,-41.43,0.193
2.03,-41.24,0.194
2.05,-41.06,0.194
2.07,-40.87,0.194
2.09,-40.69,0.194
2.11,-40.51,0.194
2.13,-40.32,0.194
2.14,-40.14,0.194
2.16,-39.96,0.194
2.18,-39.77,0.194
2.20,-39.59,0.195
2.22,-39.41,0.195
2.24,-39.22,0.195
2.26,-39.04,0.195
2.27,-38.86,0.195
2.29,-38.67,0.195
2.31,-38.49,0.195
2.33,-38.31,0.195
2.35,-38.12,0.195
2.36,-37.94,0.195
2.38,-37.75,0.195
2.40,-37.57,0.196
2.42,-37.39,0.196
2.44,-37.20,0.196
2.46,-37.02,0.196
2.48,-36.84,0.196
2.49,-36.65,0.196
2.51,-36.47,0.196
2.53,-36.28,0.196
2.55,-36.10,0.196
2.57,-35.92,0.196
2.59,-35.74,0.197
2.60,-35.55,0.197
2.62,-35.37,0.197
2.64,-35.19,0.197
2.66,-35.00,0.197
2.68,-34.82,0.197
2.69,-34.63,0.197
2.71,-34.45,0.197
2.73,-34.27,0.197
2.75,-34.08,0.198
2.77,-33.90,0.198
2.79,-33.72,0.198
2.81,-33.53,0.198
2.82,-33.35,0.198
2.84,-33.16,0.198
2.86,-32.98,0.198
2.88,-32.80,0.198
2.90,-32.61,0.198
2.91,-32.43,0.198
2.93,-32.25,0.199
2.95,-32.06,0.199
2.97,-31.88,0.199
2.99,-31.69,0.199
3.01,-31.51,0.199
3.03,-31.33,0.199
3.04,-31.15,0.199
3.06,-30.96,0.199
3.08,-30.78,0.199
3.10,-30.59,0.199
3.12,-30.41,0.200
3.14,-30.23,0.200
3.15,-30.04,0.200
3.17,-29.86,0.200
3.19,-29.68,0.200
3.21,-29.49,0.200
3.23,-29.31,0.200
3.24,-29.13,0.200
3.26,-28.94,0.200
3.28,-28.76,0.200
3.30,-28.58,0.201
3.32,-28.39,0.201
3.34,-28.21,0.201
3.36,-28.02,0.201
3.37,-27.84,0.201
3.39,-27.66,0.201
3.41,-27.47,0.201
3.43,-27.29,0.201
3.45,-27.11,0.202
3.46,-26.92,0.202
3.48,-26.74,0.202
3.50,-26.56,0.202
3.52,-26.37,0.202
3.54,-26.19,0.202
3.56,-26.01,0.202
3.58,-25.82,0.202
3.59,-25.64,0.202
3.61,-25.46,0.203
3.63,-25.27,0.203
3.65,-25.09,0.203
3.67,-24.90,0.203
3.69,-24.72,0.203
3.70,-24.54,0.203
3.72,-24.35,0.203
3.74,-24.17,0.203
3.76,-23.99,0.203
3.78,-23.80,0.204
3.79,-23.62,0.204
3.81,-23.44,0.204
3.83,-23.25,0.204
3.85,-23.07,0.204
3.87,-22.88,0.204
3.89,-22.70,0.204
3.91,-22.52,0.204
3.92,-22.33,0.205
3.94,-22.15,0.205
3.96,-21.97,0.205
3.98,-21.78,0.205
4.00,-21.60,0.205
4.01,-21.42,0.205
4.03,-21.23,0.205
4.05,-21.05,0.205
4.07,-20.86,0.205
4.09,-20.68,0.206
4.11,-20.50,0.206
4.13,-20.32,0.206
4.14,-20.13,0.206
4.16,-19.95,0.206
4.18,-19.77,0.206
4.20,-19.58,0.206
4.22,-19.40,0.206
4.24,-19.21,0.207
4.25,-19.03,0.207
4.27,-18.85,0.207
4.29,-18.66,0.207
4.31,-18.48,0.207
4.33,-18.30,0.207
4.35,-18.11,0.207
4.36,-17.93,0.207
4.38,-17.74,0.207
4.40,-17.56,0.208
4.42,-17.38,0.208
4.44,-17.19,0.208
4.45,-17.01,0.208
4.47,-16.83,0.208
4.49,-16.64,0.208
4.51,-16.46,0.208
4.53,-16.28,0.208
4.55,-16.09,0.209
4.56,-15.91,0.209
4.58,-15.72,0.209
4.60,-15.54,0.209
4.62,-15.36,0.209
4.64,-15.17,0.209
4.66,-14.99,0.209
4.68,-14.81,0.209
4.69,-14.62,0.210
4.71,-14.44,0.210
4.73,-14.26,0.210
4.75,-14.07,0.210
4.77,-13.89,0.210
4.79,-13.71,0.210
4.80,-13.52,0.210
4.82,-13.34,0.210
4.84,-13.16,0.210
4.86,-12.97,0.211
4.88,-12.79,0.211
4.90,-12.61,0.211
4.91,-12.42,0.211
4.93,-12.24,0.211
4.95,-12.05,0.211
4.97,-11.87,0.211
4.99,-11.69,0.211
5.00,-11.50,0.212
5.02,-11.32,0.212
5.04,-11.14,0.212
5.06,-10.95,0.212
5.08,-10.77,0.212
5.10,-10.59,0.212
5.11,-10.40,0.212
5.13,-10.22,0.212
5.15,-10.04,0.213
5.17,-9.85,0.213
5.19,-9.67,0.213
5.21,-9.49,0.213
5.23,-9.30,0.213
5.24,-9.12,0.213
5.26,-8.94,0.213
5.28,-8.75,0.213
5.30,-8.57,0.214
5.32,-8.39,0.214
5.34,-8.20,0.214
5.35,-8.02,0.214
5.37,-7.83,0.214
5.39,-7.65,0.214
5.41,-7.47,0.214
5.43,-7.28,0.215
5.45,-7.10,0.215
5.46,-6.92,0.215
5.48,-6.73,0.215
5.50,-6.55,0.215
5.52,-6.36,0.215
5.54,-6.18,0.216
5.55,-6.00,0.216
5.57,-5.81,0.216
5.59,-5.63,0.216
5.61,-5.45,0.216
5.63,-5.26,0.216
5.65,-5.08,0.217
5.66,-4.90,0.217
5.68,-4.71,0.217
5.70,-4.53,0.217
5.72,-4.35,0.217
5.74,-4.16,0.217
5.76,-3.98,0.217
5.78,-3.80,0.218
5.79,-3.61,0.218
5.81,-3.43,0.218
5.83,-3.25,0.218
5.85,-3.06,0.218
5.87,-2.88,0.218
5.89,-2.69,0.218
5.90,-2.51,0.219
5.92,-2.33,0.219
5.94,-2.14,0.219
5.96,-1.96,0.219
5.98,-1.78,0.219
6.00,-1.59,0.220
6.01,-1.41,0.220
6.03,-1.23,0.220
6.05,-1.04,0.220
6.07,-0.86,0.220
6.09,-0.68,0.220
6.10,-0.49,0.220
6.12,-0.31,0.221
6.14,-0.13,0.221
6.16,0.06,0.221
6.18,0.24,0.221
6.20,0.43,0.221
6.21,0.61,0.221
6.23,0.79,0.221
6.25,0.98,0.222
6.27,1.16,0.222
6.29,1.34,0.222
6.31,1.53,0.222
6.33,1.71,0.222
6.34,1.89,0.222
6.36,2.08,0.222
6.38,2.26,0.222
6.40,2.44,0.222
6.42,2.63,0.223
6.44,2.81,0.223
6.45,3.00,0.223
6.47,3.18,0.223
6.49,3.36,0.223
6.51,3.55,0.223
6.53,3.73,0.223
6.55,3.91,0.224
6.56,4.10,0.224
6.58,4.28,0.224
6.60,4.46,0.224
6.62,4.65,0.224
6.64,4.83,0.224
6.65,5.01,0.225
6.67,5.20,0.225
6.69,5.38,0.225
6.71,5.56,0.225
6.73,5.75,0.225
6.75,5.93,0.225
6.76,6.12,0.225
6.78,6.30,0.226
6.80,6.48,0.226
6.82,6.67,0.226
6.84,6.85,0.226
6.86,7.03,0.226
6.88,7.22,0.226
6.89,7.40,0.226
6.91,7.58,0.227
6.93,7.77,0.227
6.95,7.95,0.227
6.97,8.13,0.227
6.99,8.32,0.227
7.00,8.50,0.227
7.02,8.68,0.228
7.04,8.87,0.228
7.06,9.05,0.228
7.08,9.24,0.228
7.10,9.42,0.228
7.11,9.60,0.228
7.13,9.79,0.228
7.15,9.97,0.229
7.17,10.15,0.229
7.19,10.34,0.229
7.20,10.52,0.229
7.22,10.70,0.229
7.24,10.89,0.229
7.26,11.07,0.230
7.28,11.25,0.230
7.30,11.44,0.230
7.31,11.62,0.230
7.33,11.80,0.230
7.35,11.99,0.230
7.37,12.17,0.231
7.39,12.36,0.231
7.41,12.54,0.231
7.43,12.72,0.231
7.44,12.91,0.231
7.46,13.09,0.231
7.48,13.27,0.232
7.50,13.46,0.232
7.52,13.64,0.232
7.54,13.82,0.232
7.55,14.01,0.232
7.57,14.19,0.232
7.59,14.37,0.233
7.61,14.56,0.233
7.63,14.74,0.233
7.65,14.92,0.233
7.66,15.11,0.233
7.68,15.29,0.233
7.70,15.48,0.234
7.72,15.66,0.234
7.74,15.84,0.234
7.75,16.03,0.234
7.77,16.21,0.234
7.79,16.39,0.234
7.81,16.58,0.234
7.83,16.76,0.235
7.85,16.94,0.235
7.86,17.13,0.235
7.88,17.31,0.235
7.90,17.49,0.235
7.92,17.68,0.235
7.94,17.86,0.236
7.96,18.04,0.236
7.98,18.23,0.236
7.99,18.41,0.236
8.01,18.60,0.236
8.03,18.78,0.236
8.05,18.96,0.237
8.07,19.14,0.237
8.09,19.33,0.237
8.10,19.51,0.237
8.12,19.70,0.237
8.14,19.88,0.237
8.16,20.06,0.238
8.18,20.25,0.238
8.20,20.43,0.238
8.21,20.61,0.238
8.23,20.80,0.238
8.25,20.98,0.238
8.27,21.16,0.239
8.29,21.35,0.239
8.30,21.53,0.239
8.32,21.71,0.239
8.34,21.90,0.239
8.36,22.08,0.239
8.38,22.26,0.240
8.40,22.45,0.240
8.41,22.63,0.240
8.43,22.82,0.240
8.45,23.00,0.240
8.47,23.18,0.240
8.49,23.37,0.240
8.51,23.55,0.241
8.53,23.73,0.241
8.54,23.92,0.241
8.56,24.10,0.241
8.58,24.28,0.241
8.60,24.47,0.241
8.62,24.65,0.242
8.63,24.83,0.242
8.65,25.02,0.242
8.67,25.20,0.242
8.69,25.38,0.242
8.71,25.57,0.243
8.73,25.75,0.243
8.75,25.94,0.243
8.76,26.12,0.243
8.78,26.30,0.243
8.80,26.49,0.243
8.82,26.67,0.243
8.84,26.85,0.244
8.85,27.04,0.244
8.87,27.22,0.244
8.89,27.40,0.244
8.91,27.59,0.244
8.93,27.77,0.245
8.95,27.96,0.245
8.97,28.14,0.245
8.98,28.32,0.245
9.00,28.50,0.245
9.02,28.69,0.245
9.04,28.87,0.245
9.06,29.06,0.246
9.08,29.24,0.246
9.09,29.42,0.246
9.11,29.61,0.246
9.13,29.79,0.246
9.15,29.97,0.246
9.17,30.16,0.247
9.18,30.34,0.247
9.20,30.52,0.247
9.22,30.71,0.247
9.24,30.89,0.247
9.26,31.08,0.247
9.28,31.26,0.247
9.30,31.44,0.248
9.31,31.62,0.248
9.33,31.81,0.248
9.35,31.99,0.248
9.37,32.18,0.248
9.39,32.36,0.248
9.40,32.54,0.249
9.42,32.73,0.249
9.44,32.91,0.249
9.46,33.09,0.249
9.48,33.28,0.249
9.50,33.46,0.249
9.52,33.64,0.250
9.53,33.83,0.250
9.55,34.01,0.250
9.57,34.19,0.250
9.59,34.38,0.250
9.61,34.56,0.250
9.63,34.74,0.251
9.64,34.93,0.251
9.66,35.11,0.251
9.68,35.29,0.251
9.70,35.48,0.251
9.72,35.66,0.251
9.73,35.84,0.252
9.75,36.03,0.252
9.77,36.21,0.252
9.79,36.39,0.252
9.81,36.58,0.252
9.83,36.76,0.252
9.85,36.95,0.253
9.86,37.13,0.253
9.88,37.31,0.253
9.90,37.50,0.253
9.92,37.68,0.253
9.94,37.86,0.253
9.95,38.05,0.253
9.97,38.23,0.254
9.99,38.41,0.254
10.01,38.60,0.254
10.03,38.78,0.254
10.05,38.96,0.254
10.07,39.15,0.254
10.08,39.33,0.255
10.10,39.51,0.255
10.12,39.70,0.255
10.14,39.88,0.255
10.16,40.07,0.255
10.18,40.25,0.255
10.19,40.43,0.256
10.21,40.62,0.256
10.23,40.80,0.256
10.25,40.98,0.256
10.27,41.17,0.256
10.28,41.35,0.256
10.30,41.53,0.256
10.32,41.72,0.257
10.34,41.90,0.257
10.36,42.09,0.257
10.38,42.27,0.257
10.40,42.45,0.257
10.41,42.64,0.257
10.43,42.82,0.257
10.45,43.00,0.258
10.47,43.19,0.258
10.49,43.37,0.258
10.50,43.55,0.258
10.52,43.74,0.258
10.54,43.92,0.258
10.56,44.10,0.258
10.58,44.29,0.259
10.60,44.47,0.259
10.62,44.65,0.259
10.63,44.84,0.259
10.65,45.02,0.259
10.67,45.20,0.259
10.69,45.39,0.260
10.71,45.57,0.260
10.73,45.76,0.260
10.74,45.94,0.260
10.76,46.12,0.260
10.78,46.30,0.260
10.80,46.49,0.260
10.82,46.67,0.261
10.83,46.85,0.261
10.85,47.04,0.261
10.87,47.22,0.261
10.89,47.41,0.261
10.91,47.59,0.262
10.93,47.77,0.262
10.95,47.96,0.262
10.96,48.14,0.262
10.98,48.32,0.262
11.00,48.51,0.262
11.02,48.69,0.263
11.04,48.87,0.263
11.05,49.06,0.263
11.07,49.24,0.263
11.09,49.43,0.263
11.11,49.61,0.263
11.13,49.79,0.264
11.15,49.98,0.264
11.17,50.16,0.264
11.18,50.34,0.264
11.20,50.53,0.264
11.22,50.71,0.264
11.24,50.89,0.264
11.26,51.08,0.264
11.28,51.26,0.265
11.29,51.44,0.265
11.31,51.63,0.265
11.33,51.81,0.265
11.35,51.99,0.265
11.37,52.18,0.265
11.38,52.36,0.266
11.40,52.55,0.266
11.42,52.73,0.266
11.44,52.91,0.266
11.46,53.10,0.266
11.48,53.28,0.266
11.50,53.46,0.266
11.51,53.64,0.267
11.53,53.83,0.267
11.55,54.01,0.267
11.57,54.20,0.267
11.59,54.38,0.267
11.60,54.56,0.267
11.62,54.75,0.267
11.64,54.93,0.268
11.66,55.11,0.268
11.68,55.30,0.268
11.70,55.48,0.268
11.72,55.66,0.268
11.73,55.85,0.268
11.75,56.03,0.268
11.77,56.21,0.269
11.79,56.40,0.269
11.81,56.58,0.269
11.83,56.76,0.269
11.84,56.95,0.269
11.86,57.13,0.269
11.88,57.31,0.269
11.90,57.50,0.270
11.92,57.68,0.270
11.93,57.87,0.270
11.95,58.05,0.270
11.97,58.23,0.270
11.99,58.42,0.270
12.01,58.60,0.271
12.03,58.78,0.271
12.05,58.97,0.271
12.06,59.15,0.271
12.08,59.33,0.271
12.10,59.52,0.271
12.12,59.70,0.271
12.14,59.88,0.272
12.15,60.07,0.272
12.17,60.25,0.272
12.19,60.43,0.272
12.21,60.62,0.272
12.23,60.80,0.272
12.25,60.99,0.273
12.27,61.17,0.273
12.28,61.35,0.273
12.30,61.54,0.273
12.32,61.72,0.273
12.34,61.90,0.273
12.36,62.09,0.274
12.38,62.27,0.274
12.39,62.45,0.274
12.41,62.64,0.274
12.43,62.82,0.275
12.45,63.00,0.275
12.47,63.19,0.275
12.48,63.37,0.275
12.50,63.55,0.275
12.52,63.74,0.276
12.54,63.92,0.276
12.56,64.10,0.276
12.58,64.29,0.276
12.60,64.47,0.276
12.61,64.65,0.276
12.63,64.84,0.277
12.65,65.02,0.277
12.67,65.20,0.277
12.69,65.39,0.277
12.70,65.57,0.277
12.72,65.76,0.278
12.74,65.94,0.278
12.76,66.12,0.278
12.78,66.31,0.278
12.80,66.49,0.278
12.82,66.67,0.279
12.83,66.86,0.279
12.85,67.04,0.279
12.87,67.22,0.280
12.89,67.41,0.280
12.91,67.59,0.280
12.93,67.77,0.281
12.94,67.96,0.281
12.96,68.14,0.281
12.98,68.32,0.282
13.00,68.51,0.282
13.02,68.69,0.282
13.03,68.87,0.283
13.05,69.06,0.283
13.07,69.24,0.284
13.09,69.42,0.284
13.11,69.61,0.285
13.13,69.79,0.286
13.15,69.97,0.287
13.16,70.16,0.288
13.18,70.34,0.289
13.20,70.52,0.290
13.22,70.71,0.292
13.24,70.89,0.295
13.25,71.07,0.296
13.27,71.25,0.298
13.29,71.44,0.300
13.31,71.62,0.302
13.33,71.80,0.307
13.35,71.98,0.309
13.37,72.17,0.313
13.38,72.35,0.318
13.40,72.53,0.323
13.42,72.71,0.328
13.44,72.89,0.336
13.46,73.07,0.343
13.48,73.25,0.354
13.49,73.43,0.365
13.51,73.61,0.377
13.53,73.79,0.394
13.55,73.97,0.414
13.57,74.14,0.434
13.58,74.32,0.459
13.60,74.49,0.489
13.62,74.66,0.525
13.64,74.83,0.569
13.66,74.99,0.625
13.68,75.15,0.693
13.70,75.31,0.770
13.71,75.46,0.853
13.73,75.61,0.931
13.75,75.75,1.015
13.77,75.90,1.082
13.79,76.04,1.151
13.80,76.19,1.206
13.82,76.34,1.258
13.84,76.49,1.304
13.86,76.65,1.344
13.88,76.80,1.380
13.90,76.96,1.406
13.92,77.13,1.426
13.93,77.29,1.443
13.95,77.46,1.456
13.97,77.63,1.467
13.99,77.81,1.480
14.01,77.98,1.485
14.03,78.16,1.486
14.04,78.34,1.481
14.06,78.52,1.472
14.08,78.70,1.461
14.10,78.89,1.446
14.12,79.08,1.428
14.13,79.27,1.401
14.15,79.46,1.367
14.17,79.66,1.324
14.19,79.86,1.275
14.21,80.06,1.220
14.23,80.26,1.164
14.25,80.47,1.098
14.26,80.69,1.018
14.28,80.90,0.926
14.30,81.13,0.835
14.32,81.35,0.756
14.34,81.58,0.690
14.35,81.80,0.638
14.37,82.02,0.586
14.39,82.23,0.553
14.41,82.44,0.517
14.43,82.65,0.490
14.45,82.85,0.466
14.47,83.05,0.446
14.48,83.25,0.428
14.50,83.45,0.414
14.52,83.65,0.401
14.54,83.84,0.390
14.56,84.03,0.380
14.58,84.23,0.372
14.59,84.42,0.364
14.61,84.61,0.359
14.63,84.79,0.354
14.65,84.98,0.350
14.67,85.17,0.345
14.68,85.36,0.342
14.70,85.54,0.340
14.72,85.73,0.337
14.74,85.91,0.336
14.76,86.10,0.334
14.78,86.28,0.332
14.80,86.47,0.331
14.81,86.65,0.330
14.83,86.84,0.330
14.85,87.02,0.329
14.87,87.20,0.328
14.89,87.39,0.328
14.90,87.57,0.328
14.92,87.76,0.327
14.94,87.94,0.327
14.96,88.12,0.327
14.98,88.31,0.327
15.00,88.49,0.326
15.02,88.68,0.326
15.03,88.86,0.326
15.05,89.04,0.326
15.07,89.23,0.326
15.09,89.41,0.326
15.11,89.59,0.326
15.13,89.78,0.326
15.14,89.96,0.326
15.16,90.14,0.325
15.18,90.33,0.325
15.20,90.51,0.325
15.22,90.70,0.325
15.23,90.88,0.325
15.25,91.06,0.325
15.27,91.25,0.325
15.29,91.43,0.325
15.31,91.61,0.325
15.33,91.80,0.325
15.35,91.98,0.325
15.36,92.16,0.326
15.38,92.35,0.326
15.40,92.53,0.326
15.42,92.71,0.326
15.44,92.90,0.326
15.45,93.08,0.326
15.47,93.27,0.326
15.49,93.45,0.326
15.51,93.63,0.326
15.53,93.82,0.326
15.55,94.00,0.326
15.57,94.18,0.326
15.58,94.37,0.326
15.60,94.55,0.327
15.62,94.73,0.327
15.64,94.92,0.327
15.66,95.10,0.327
15.68,95.28,0.327
15.69,95.47,0.327
15.71,95.65,0.327
15.73,95.84,0.327
15.75,96.02,0.328
15.77,96.20,0.328
15.78,96.39,0.328
15.80,96.57,0.328
15.82,96.75,0.328
15.84,96.94,0.328
15.86,97.12,0.328
15.88,97.30,0.328
15.90,97.49,0.329
15.91,97.67,0.329
15.93,97.86,0.329
15.95,98.04,0.329
15.97,98.22,0.329
15.99,98.41,0.329
16.00,98.59,0.329
16.02,98.77,0.329
16.04,98.96,0.330
16.06,99.14,0.330
16.08,99.33,0.330
16.10,99.51,0.330
16.12,99.69,0.330
16.13,99.87,0.330
16.15,100.06,0.330
16.17,100.24,0.330
16.19,100.42,0.331
16.21,100.61,0.331
16.23,100.79,0.331
16.24,100.98,0.331
16.26,101.16,0.331
16.28,101.34,0.331
16.30,101.53,0.331
16.32,101.71,0.331
16.33,101.89,0.332
16.35,102.08,0.332
16.37,102.26,0.332
16.39,102.44,0.332
16.41,102.63,0.332
16.43,102.81,0.332
16.45,103.00,0.332
16.46,103.18,0.333
16.48,103.36,0.333
16.50,103.55,0.333
16.52,103.73,0.333
16.54,103.91,0.333
16.55,104.10,0.333
16.57,104.28,0.333
16.59,104.46,0.333
16.61,104.65,0.334
16.63,104.83,0.334
16.65,105.02,0.334
16.67,105.20,0.334
16.68,105.39,0.334
16.70,105.57,0.334
16.72,105.75,0.335
16.74,105.94,0.335
16.76,106.12,0.335
16.78,106.30,0.335
16.79,106.49,0.335
16.81,106.67,0.335
16.83,106.85,0.335
16.85,107.04,0.335
16.87,107.22,0.335
16.88,107.40,0.335
16.90,107.59,0.336
16.92,107.77,0.336
16.94,107.95,0.336
16.96,108.14,0.336
16.98,108.32,0.336
17.00,108.50,0.336
17.01,108.68,0.336
17.03,108.87,0.336
17.05,109.05,0.336
17.07,109.23,0.336
17.09,109.42,0.336
17.11,109.60,0.336
17.12,109.78,0.336
17.14,109.97,0.337
17.16,110.15,0.337
17.18,110.33,0.337
17.20,110.52,0.337
17.22,110.70,0.337
17.23,110.88,0.337
17.25,111.07,0.337
17.27,111.25,0.337
17.29,111.43,0.338
17.31,111.62,0.338
17.33,111.80,0.338
17.34,111.98,0.338
17.36,112.17,0.338
17.38,112.35,0.338
17.40,112.53,0.338
17.42,112.72,0.339
17.43,112.90,0.339
17.45,113.08,0.339
17.47,113.27,0.339
17.49,113.45,0.339
17.51,113.63,0.339
17.53,113.82,0.340
17.54,114.00,0.340
17.56,114.19,0.340
17.58,114.37,0.340
17.60,114.55,0.340
17.62,114.74,0.340
17.64,114.92,0.340
17.66,115.10,0.341
17.67,115.29,0.341
17.69,115.47,0.341
17.71,115.65,0.341
17.73,115.84,0.341
17.75,116.02,0.341
17.77,116.20,0.341
17.78,116.39,0.342
17.80,116.57,0.342
17.82,116.75,0.342
17.84,116.94,0.342
17.86,117.12,0.342
17.88,117.30,0.342
17.89,117.49,0.343
17.91,117.67,0.343
17.93,117.85,0.343
17.95,118.04,0.343
17.97,118.22,0.343
17.98,118.41,0.343
18.00,118.59,0.344
18.02,118.77,0.344
18.04,118.96,0.344
18.06,119.14,0.344
18.08,119.33,0.344
18.09,119.51,0.344
18.11,119.69,0.345
18.13,119.88,0.345
18.15,120.06,0.345
18.17,120.24,0.345
18.19,120.43,0.345
18.21,120.61,0.345
18.22,120.79,0.345
18.24,120.98,0.346
18.26,121.16,0.346
18.28,121.34,0.346
18.30,121.53,0.346
18.32,121.71,0.346
18.33,121.89,0.346
18.35,122.08,0.346
18.37,122.26,0.346
18.39,122.44,0.347
18.41,122.63,0.347
18.43,122.81,0.347
18.44,122.99,0.347
18.46,123.18,0.347
18.48,123.36,0.347
18.50,123.55,0.347
18.52,123.73,0.347
18.53,123.91,0.348
18.55,124.10,0.348
18.57,124.28,0.348
18.59,124.46,0.348
18.61,124.65,0.348
18.63,124.83,0.348
18.64,125.01,0.348
18.66,125.20,0.349
18.68,125.38,0.349
18.70,125.56,0.349
18.72,125.75,0.349
18.74,125.93,0.349
18.76,126.11,0.349
18.77,126.29,0.349
18.79,126.48,0.349
18.81,126.66,0.349
18.83,126.84,0.350
18.85,127.03,0.350
18.87,127.21,0.350
18.88,127.40,0.350
18.90,127.58,0.350
18.92,127.76,0.350
18.94,127.95,0.350
18.96,128.13,0.351
18.98,128.31,0.351
18.99,128.50,0.351
19.01,128.68,0.351
19.03,128.86,0.351
19.05,129.05,0.352
19.07,129.23,0.352
19.08,129.41,0.352
19.10,129.60,0.352
19.12,129.78,0.352
19.14,129.96,0.352
19.16,130.15,0.352
19.18,130.33,0.353
19.19,130.51,0.353
19.21,130.70,0.353
19.23,130.88,0.353
19.25,131.06,0.353
19.27,131.25,0.353
19.29,131.43,0.354
19.31,131.61,0.354
19.32,131.80,0.354
19.34,131.98,0.354
19.36,132.17,0.354
19.38,132.35,0.354
19.40,132.53,0.355
19.42,132.72,0.355
19.43,132.90,0.355
19.45,133.08,0.355
19.47,133.27,0.355
19.49,133.45,0.355
19.51,133.63,0.356
19.53,133.82,0.356
19.54,134.00,0.356
19.56,134.18,0.356
19.58,134.37,0.356
19.60,134.55,0.356
19.62,134.73,0.357
19.63,134.92,0.357
19.65,135.10,0.357
19.67,135.28,0.357
19.69,135.47,0.357
19.71,135.65,0.358
19.73,135.83,0.358
19.74,136.02,0.358
19.76,136.20,0.358
19.78,136.38,0.359
19.80,136.57,0.359
19.82,136.75,0.359
19.84,136.93,0.360
19.86,137.12,0.360
19.87,137.30,0.360
19.89,137.49,0.360
19.91,137.67,0.361
19.93,137.85,0.361
19.95,138.04,0.361
19.97,138.22,0.362
19.98,138.40,0.362
20.00,138.59,0.362
20.02,138.77,0.362
20.04,138.95,0.362
20.06,139.14,0.362
20.08,139.32,0.363
20.09,139.50,0.363
20.11,139.68,0.363
20.13,139.87,0.363
20.15,140.05,0.363
20.17,140.24,0.364
20.18,140.42,0.364
20.20,140.60,0.364
20.22,140.79,0.364
20.24,140.97,0.365
20.26,141.15,0.365
20.28,141.33,0.365
20.29,141.52,0.365
20.31,141.70,0.365
20.33,141.88,0.366
20.35,142.07,0.366
20.37,142.25,0.366
20.39,142.43,0.367
20.41,142.62,0.367
20.42,142.80,0.367
20.44,142.99,0.368
20.46,143.17,0.368
20.48,143.35,0.368
20.50,143.54,0.368
20.52,143.72,0.369
20.53,143.90,0.369
20.55,144.09,0.369
20.57,144.27,0.370
20.59,144.45,0.370
20.61,144.64,0.370
20.63,144.82,0.370
20.64,145.00,0.371
20.66,145.18,0.371
20.68,145.37,0.371
20.70,145.55,0.371
20.72,145.74,0.372
20.73,145.92,0.372
20.75,146.10,0.372
20.77,146.29,0.373
20.79,146.47,0.373
20.81,146.65,0.373
20.83,146.84,0.374
20.84,147.02,0.374
20.86,147.20,0.374
20.88,147.39,0.375
20.90,147.57,0.376
20.92,147.75,0.376
20.94,147.94,0.377
20.96,148.12,0.378
20.97,148.30,0.378
20.99,148.49,0.379
21.01,148.67,0.379
21.03,148.85,0.379
21.05,149.04,0.380
21.07,149.22,0.380
21.08,149.40,0.381
21.10,149.59,0.381
21.12,149.77,0.381
21.14,149.95,0.382
21.16,150.13,0.383
21.18,150.32,0.383
21.19,150.50,0.386
21.21,150.68,0.387
21.23,150.87,0.387
21.25,151.05,0.388
21.27,151.23,0.388
21.28,151.42,0.388
21.30,151.60,0.388
21.32,151.78,0.389
21.34,151.97,0.389
21.36,152.15,0.389
21.38,152.33,0.390
21.39,152.52,0.390
21.41,152.70,0.390
21.43,152.88,0.390
21.45,153.07,0.391
21.47,153.25,0.391
21.49,153.44,0.392
21.51,153.62,0.392
21.52,153.80,0.393
21.54,153.99,0.393
21.56,154.17,0.393
21.58,154.35,0.394
21.60,154.53,0.394
21.62,154.72,0.394
21.63,154.90,0.395
21.65,155.08,0.395
21.67,155.27,0.395
21.69,155.45,0.396
21.71,155.63,0.396
21.73,155.82,0.397
21.74,156.00,0.397
21.76,156.18,0.397
21.78,156.37,0.398
21.80,156.55,0.398
21.82,156.73,0.398
21.83,156.92,0.399
21.85,157.10,0.399
21.87,157.28,0.399
21.89,157.47,0.400
21.91,157.65,0.400
21.93,157.83,0.400
21.94,158.02,0.400
21.96,158.20,0.401
21.98,158.38,0.401
22.00,158.57,0.401
22.02,158.75,0.401
22.04,158.93,0.401
22.06,159.12,0.402
22.07,159.30,0.402
22.09,159.49,0.402
22.11,159.67,0.402
22.13,159.85,0.402
22.15,160.04,0.402
22.17,160.22,0.402
22.18,160.40,0.402
22.20,160.59,0.403
22.22,160.77,0.403
22.24,160.95,0.403
22.26,161.14,0.403
22.28,161.32,0.403
22.29,161.50,0.403
22.31,161.69,0.403
22.33,161.87,0.403
22.35,162.05,0.403
22.37,162.24,0.403
22.38,162.42,0.403
22.40,162.60,0.404
22.42,162.79,0.404
22.44,162.97,0.404
22.46,163.15,0.404
22.48,163.34,0.404
22.49,163.52,0.404
22.51,163.71,0.405
22.53,163.89,0.405
22.55,164.07,0.405
22.57,164.26,0.405
22.59,164.44,0.405
22.61,164.62,0.406
22.62,164.80,0.406
22.64,164.99,0.406
22.66,165.17,0.407
22.68,165.35,0.407
22.70,165.54,0.407
22.72,165.72,0.408
22.73,165.90,0.408
22.75,166.09,0.409
22.77,166.27,0.409
22.79,166.45,0.410
22.81,166.64,0.410
22.83,166.82,0.411
22.84,167.00,0.412
22.86,167.18,0.412
22.88,167.37,0.413
22.90,167.55,0.414
22.92,167.74,0.415
22.93,167.92,0.416
22.95,168.10,0.417
22.97,168.28,0.418
22.99,168.47,0.419
23.01,168.65,0.419
23.03,168.83,0.420
23.04,169.02,0.421
23.06,169.20,0.422
23.08,169.38,0.423
23.10,169.57,0.424
23.12,169.75,0.425
23.14,169.93,0.426
23.16,170.12,0.427
23.17,170.30,0.428
23.19,170.48,0.429
23.21,170.67,0.431
23.23,170.85,0.432
23.25,171.03,0.433
23.27,171.22,0.434
23.28,171.40,0.436
23.30,171.58,0.437
23.32,171.77,0.438
23.34,171.95,0.439
23.36,172.13,0.440
23.38,172.31,0.441
23.39,172.50,0.442
23.41,172.68,0.444
23.43,172.86,0.446
23.45,173.05,0.447
23.47,173.23,0.449
23.48,173.41,0.450
23.50,173.60,0.452
23.52,173.78,0.453
23.54,173.96,0.455
23.56,174.14,0.456
23.58,174.33,0.458
23.59,174.51,0.460
23.61,174.69,0.461
23.63,174.88,0.463
23.65,175.06,0.465
23.67,175.24,0.467
23.69,175.42,0.469
23.71,175.61,0.471
23.72,175.79,0.473
23.74,175.97,0.474
23.76,176.15,0.477
23.78,176.34,0.478
23.80,176.52,0.481
23.82,176.70,0.484
23.83,176.88,0.485
23.85,177.07,0.488
23.87,177.25,0.490
23.89,177.43,0.493
23.91,177.61,0.495
23.93,177.80,0.498
23.94,177.98,0.501
23.96,178.16,0.504
23.98,178.34,0.507
24.00,178.53,0.509
24.02,178.71,0.513
24.03,178.89,0.517
24.05,179.07,0.519
24.07,179.26,0.524
24.09,179.44,0.526
24.11,179.62,0.530
24.13,179.80,0.534
24.14,179.98,0.537
24.16,180.16,0.542
24.18,180.34,0.546
24.20,180.53,0.550
24.22,180.71,0.556
24.24,180.89,0.564
24.26,181.07,0.565
24.27,181.25,0.571
24.29,181.43,0.577
24.31,181.61,0.582
24.33,181.79,0.588
24.35,181.98,0.595
24.37,182.16,0.602
24.38,182.34,0.607
24.40,182.52,0.615
24.42,182.70,0.623
24.44,182.88,0.630
24.46,183.06,0.638
24.48,183.24,0.646
24.49,183.42,0.654
24.51,183.60,0.665
24.53,183.78,0.674
24.55,183.96,0.685
24.57,184.14,0.697
24.58,184.32,0.710
24.60,184.49,0.723
24.62,184.67,0.736
24.64,184.85,0.751
24.66,185.03,0.766
24.68,185.21,0.782
24.69,185.38,0.801
24.71,185.56,0.822
24.73,185.73,0.847
24.75,185.91,0.879
24.77,186.08,0.949
24.79,186.23,1.072
24.81,186.38,1.266
24.82,186.50,1.491
24.84,186.61,1.732
24.86,186.71,2.073
24.88,186.78,2.321
24.90,186.86,2.543
24.92,186.94,2.775
24.93,187.02,3.012
24.95,187.10,3.239
24.97,187.18,3.444
24.99,187.26,3.669
25.01,187.35,3.884
25.03,187.43,4.080
25.04,187.52,4.264
25.06,187.61,4.453
25.08,187.71,4.620
25.10,187.81,4.750
25.12,187.93,4.837
25.13,188.06,4.857
25.15,188.20,4.817
25.17,188.37,4.704
25.19,188.57,4.519
25.21,188.79,4.256
25.23,189.04,3.960
25.24,189.32,3.614
25.26,189.61,3.337
25.28,189.91,3.043
25.30,190.21,2.755
25.32,190.52,2.437
25.34,190.84,2.061
25.36,191.17,1.696
25.37,191.49,1.460
25.39,191.80,1.307
25.41,192.09,1.188
25.43,192.36,1.089
25.45,192.61,1.006
25.47,192.86,0.937
25.48,193.09,0.878
25.50,193.32,0.828
25.52,193.54,0.786
25.54,193.75,0.751
25.56,193.96,0.724
25.58,194.17,0.694
25.59,194.37,0.675
25.61,194.57,0.658
25.63,194.76,0.642
25.65,194.96,0.628
25.67,195.15,0.617
25.68,195.34,0.607
25.70,195.53,0.599
25.72,195.72,0.591
25.74,195.91,0.585
25.76,196.10,0.577
25.78,196.28,0.574
25.79,196.47,0.569
25.81,196.66,0.565
25.83,196.84,0.562
25.85,197.03,0.557
25.87,197.21,0.555
25.89,197.40,0.551
25.91,197.58,0.549
25.92,197.77,0.546
25.94,197.95,
25.96,198.14,
25.98,198.32,
25.99,,

[step]
Ramp 10.00 °C/min to -60.00 °C
Time,Temperature,Heat Flow (Normalized)
min,°C,W/g
27.99,200.13,-0.081
28.01,200.13,-0.082
28.03,200.13,-0.082
28.05,200.12,-0.082
28.07,200.10,-0.093
28.08,200.06,-0.111
28.10,199.99,-0.139
28.12,199.91,-0.175
28.14,199.82,-0.217
28.16,199.70,-0.260
28.18,199.58,-0.301
28.19,199.44,-0.336
28.21,199.30,-0.366
28.23,199.15,-0.392
28.25,199.00,-0.413
28.27,198.84,-0.432
28.29,198.68,-0.447
28.31,198.51,-0.460
28.32,198.35,-0.471
28.34,198.18,-0.482
28.36,198.01,-0.490
28.38,197.83,-0.497
28.40,197.66,-0.503
28.42,197.49,-0.508
28.43,197.31,-0.513
28.45,197.13,-0.517
28.47,196.95,-0.520
28.49,196.78,-0.522
28.51,196.60,-0.524
28.53,196.42,-0.526
28.54,196.24,-0.528
28.56,196.06,-0.529
28.58,195.88,-0.530
28.60,195.70,-0.531
28.62,195.52,-0.533
28.63,195.34,-0.533
28.65,195.16,-0.534
28.67,194.98,-0.534
28.69,194.80,-0.535
28.71,194.62,-0.535
28.73,194.44,-0.535
28.74,194.25,-0.536
28.76,194.07,-0.536
28.78,193.89,-0.536
28.80,193.71,-0.536
28.82,193.53,-0.536
28.84,193.35,-0.536
28.86,193.17,-0.537
28.87,192.98,-0.537
28.89,192.80,-0.537
28.91,192.62,-0.537
28.93,192.44,-0.537
28.95,192.26,-0.537
28.97,192.07,-0.538
28.98,191.89,-0.538
29.00,191.71,-0.538
29.02,191.52,-0.538
29.04,191.34,-0.538
29.06,191.16,-0.538
29.08,190.98,-0.538
29.09,190.80,-0.538
29.11,190.61,-0.538
29.13,190.43,-0.538
29.15,190.25,-0.538
29.17,190.07,-0.537
29.18,189.88,-0.537
29.20,189.70,-0.537
29.22,189.52,-0.537
29.24,189.33,-0.537
29.26,189.15,-0.537
29.28,188.97,-0.537
29.29,188.79,-0.537
29.31,188.60,-0.536
29.33,188.42,-0.536
29.35,188.24,-0.536
29.37,188.06,-0.536
29.39,187.87,-0.535
29.41,187.69,-0.535
29.42,187.51,-0.534
29.44,187.32,-0.534
29.46,187.14,-0.534
29.48,186.96,-0.534
29.50,186.77,-0.533
29.52,186.59,-0.533
29.53,186.41,-0.533
29.55,186.23,-0.533
29.57,186.04,-0.532
29.59,185.86,-0.532
29.61,185.68,-0.532
29.63,185.49,-0.531
29.64,185.31,-0.531
29.66,185.13,-0.531
29.68,184.94,-0.530
29.70,184.76,-0.530
29.72,184.58,-0.530
29.73,184.40,-0.529
29.75,184.21,-0.529
29.77,184.03,-0.528
29.79,183.85,-0.528
29.81,183.66,-0.527
29.83,183.48,-0.527
29.84,183.30,-0.527
29.86,183.11,-0.526
29.88,182.93,-0.526
29.90,182.75,-0.526
29.92,182.56,-0.525
29.94,182.38,-0.525
29.96,182.20,-0.525
29.97,182.02,-0.525
29.99,181.83,-0.524
30.01,181.65,-0.524
30.03,181.47,-0.523
30.05,181.28,-0.523
30.07,181.10,-0.522
30.08,180.92,-0.522
30.10,180.73,-0.522
30.12,180.55,-0.521
30.14,180.37,-0.521
30.16,180.18,-0.521
30.18,180.00,-0.520
30.19,179.82,-0.520
30.21,179.63,-0.519
30.23,179.45,-0.519
30.25,179.27,-0.519
30.27,179.08,-0.518
30.28,178.90,-0.518
30.30,178.72,-0.517
30.32,178.53,-0.517
30.34,178.35,-0.516
30.36,178.17,-0.516
30.38,177.99,-0.516
30.39,177.80,-0.515
30.41,177.62,-0.515
30.43,177.44,-0.515
30.45,177.25,-0.514
30.47,177.07,-0.514
30.49,176.89,-0.514
30.51,176.70,-0.513
30.52,176.52,-0.513
30.54,176.34,-0.512
30.56,176.15,-0.512
30.58,175.97,-0.512
30.60,175.79,-0.511
30.62,175.60,-0.511
30.63,175.42,-0.511
30.65,175.24,-0.510
30.67,175.05,-0.510
30.69,174.87,-0.510
30.71,174.69,-0.509
30.73,174.50,-0.509
30.74,174.32,-0.509
30.76,174.14,-0.508
30.78,173.95,-0.508
30.80,173.77,-0.508
30.82,173.59,-0.508
30.83,173.40,-0.507
30.85,173.22,-0.507
30.87,173.04,-0.506
30.89,172.85,-0.506
30.91,172.67,-0.506
30.93,172.49,-0.505
30.94,172.30,-0.505
30.96,172.12,-0.504
30.98,171.94,-0.504
31.00,171.75,-0.503
31.02,171.57,-0.503
31.04,171.39,-0.503
31.06,171.21,-0.502
31.07,171.02,-0.502
31.09,170.84,-0.502
31.11,170.66,-0.501
31.13,170.47,-0.501
31.15,170.29,-0.501
31.17,170.11,-0.500
31.18,169.92,-0.500
31.20,169.74,-0.500
31.22,169.55,-0.500
31.24,169.37,-0.500
31.26,169.19,-0.499
31.28,169.01,-0.499
31.29,168.82,-0.499
31.31,168.64,-0.499
31.33,168.46,-0.505
31.35,168.28,-0.525
31.37,168.28,-7.449
31.38,170.12,-17.749
31.40,170.75,-10.089
31.42,170.73,-7.708
31.44,170.49,-6.429
31.46,170.15,-5.584
31.48,169.77,-4.904
31.49,169.37,-4.328
31.51,168.96,-3.834
31.53,168.56,-3.415
31.55,168.16,-3.069
31.57,167.79,-2.778
31.59,167.43,-2.532
31.61,167.09,-2.318
31.62,166.76,-2.133
31.64,166.45,-1.971
31.66,166.16,-1.828
31.68,165.87,-1.702
31.70,165.60,-1.594
31.72,165.34,-1.495
31.73,165.08,-1.411
31.75,164.84,-1.333
31.77,164.60,-1.258
31.79,164.37,-1.193
31.81,164.14,-1.136
31.83,163.92,-1.086
31.84,163.70,-1.042
31.86,163.49,-0.999
31.88,163.27,-0.961
31.90,163.07,-0.927
31.92,162.86,-0.897
31.93,162.66,-0.868
31.95,162.45,-0.841
31.97,162.25,-0.817
31.99,162.06,-0.795
32.01,161.86,-0.774
32.03,161.66,-0.757
32.04,161.47,-0.741
32.06,161.28,-0.726
32.08,161.08,-0.712
32.10,160.89,-0.698
32.12,160.70,-0.686
32.14,160.51,-0.676
32.16,160.32,-0.665
32.17,160.13,-0.656
32.19,159.94,-0.648
32.21,159.76,-0.638
32.23,159.57,-0.630
32.25,159.38,-0.622
32.27,159.19,-0.615
32.28,159.00,-0.610
32.30,158.82,-0.602
32.32,158.63,-0.596
32.34,158.44,-0.590
32.36,158.26,-0.585
32.38,158.07,-0.580
32.39,157.89,-0.576
32.41,157.70,-0.571
32.43,157.51,-0.565
32.45,157.33,-0.562
32.47,157.14,-0.558
32.48,156.96,-0.553
32.50,156.77,-0.549
32.52,156.59,-0.545
32.54,156.40,-0.542
32.56,156.22,-0.538
32.58,156.03,-0.535
32.59,155.85,-0.532
32.61,155.66,-0.529
32.63,155.48,-0.526
32.65,155.29,-0.523
32.67,155.11,-0.521
32.69,154.92,-0.517
32.71,154.74,-0.515
32.72,154.56,-0.514
32.74,154.37,-0.511
32.76,154.19,-0.509
32.78,154.00,-0.506
32.80,153.82,-0.504
32.82,153.63,-0.502
32.83,153.45,-0.501
32.85,153.26,-0.497
32.87,153.08,-0.496
32.89,152.90,-0.494
32.91,152.71,-0.492
32.93,152.53,-0.490
32.94,152.34,-0.489
32.96,152.16,-0.488
32.98,151.98,-0.485
33.00,151.79,-0.484
33.02,151.61,-0.483
33.03,151.43,-0.482
33.05,151.24,-0.481
33.07,151.06,-0.480
33.09,150.87,-0.477
33.11,150.69,-0.476
33.13,150.51,-0.475
33.14,150.32,-0.474
33.16,150.14,-0.473
33.18,149.95,-0.473
33.20,149.77,-0.472
33.22,149.59,-0.470
33.24,149.40,-0.469
33.26,149.22,-0.469
33.27,149.04,-0.467
33.29,148.85,-0.467
33.31,148.67,-0.465
33.33,148.49,-0.465
33.35,148.30,-0.464
33.37,148.12,-0.463
33.38,147.94,-0.463
33.40,147.75,-0.462
33.42,147.57,-0.460
33.44,147.39,-0.460
33.46,147.20,-0.459
33.48,147.02,-0.459
33.49,146.84,-0.458
33.51,146.65,-0.457
33.53,146.47,-0.457
33.55,146.29,-0.457
33.57,146.10,-0.456
33.58,145.92,-0.456
33.60,145.73,-0.456
33.62,145.55,-0.455
33.64,145.37,-0.455
33.66,145.19,-0.454
33.68,145.00,-0.453
33.69,144.82,-0.452
33.71,144.63,-0.452
33.73,144.45,-0.452
33.75,144.27,-0.451
33.77,144.09,-0.450
33.79,143.90,-0.450
33.81,143.72,-0.449
33.82,143.54,-0.449
33.84,143.35,-0.448
33.86,143.17,-0.448
33.88,142.99,-0.447
33.90,142.80,-0.447
33.92,142.62,-0.447
33.93,142.43,-0.447
33.95,142.25,-0.446
33.97,142.07,-0.446
33.99,141.88,-0.445
34.01,141.70,-0.445
34.03,141.52,-0.444
34.04,141.33,-0.444
34.06,141.15,-0.443
34.08,140.97,-0.443
34.10,140.78,-0.442
34.12,140.60,-0.442
34.14,140.42,-0.441
34.15,140.23,-0.441
34.17,140.05,-0.441
34.19,139.87,-0.440
34.21,139.68,-0.439
34.23,139.50,-0.439
34.24,139.32,-0.438
34.26,139.13,-0.438
34.28,138.95,-0.437
34.30,138.77,-0.437
34.32,138.59,-0.436
34.34,138.40,-0.436
34.36,138.22,-0.436
34.37,138.03,-0.435
34.39,137.85,-0.435
34.41,137.67,-0.435
34.43,137.48,-0.434
34.45,137.30,-0.434
34.46,137.12,-0.434
34.48,136.93,-0.433
34.50,136.75,-0.433
34.52,136.57,-0.433
34.54,136.38,-0.432
34.56,136.20,-0.432
34.58,136.02,-0.431
34.59,135.83,-0.431
34.61,135.65,-0.431
34.63,135.47,-0.430
34.65,135.28,-0.430
34.67,135.10,-0.430
34.69,134.92,-0.429
34.70,134.73,-0.429
34.72,134.55,-0.429
34.74,134.37,-0.429
34.76,134.18,-0.428
34.78,134.00,-0.428
34.79,133.82,-0.428
34.81,133.64,-0.427
34.83,133.45,-0.427
34.85,133.27,-0.426
34.87,133.09,-0.426
34.89,132.90,-0.426
34.91,132.72,-0.425
34.92,132.54,-0.425
34.94,132.35,-0.425
34.96,132.17,-0.424
34.98,131.99,-0.424
35.00,131.80,-0.424
35.01,131.62,-0.423
35.03,131.44,-0.423
35.05,131.25,-0.423
35.07,131.07,-0.422
35.09,130.89,-0.422
35.11,130.71,-0.422
35.13,130.52,-0.422
35.14,130.34,-0.421
35.16,130.16,-0.421
35.18,129.97,-0.421
35.20,129.79,-0.420
35.22,129.61,-0.420
[...]
114.07,-40.93,0.197
114.08,-40.86,0.197
114.09,-40.79,0.197
114.09,-40.73,0.197
114.10,-40.66,0.198
114.11,-40.59,0.198
114.11,-40.53,0.198
114.12,-40.46,0.198
114.13,-40.39,0.198
114.13,-40.33,0.198
114.14,-40.26,0.198
114.15,-40.19,0.198
114.15,-40.13,0.198
114.16,-40.06,0.198
114.17,-39.99,0.198
114.17,-39.93,0.198
114.18,-39.86,0.198
114.19,-39.79,0.198
114.19,-39.73,0.198
114.20,-39.66,0.198
114.21,-39.59,0.198
114.21,-39.52,0.198
114.22,-39.46,0.198
114.23,-39.39,0.198
114.23,-39.32,0.198
114.24,-39.26,0.198
114.25,-39.19,0.198
114.25,-39.12,0.199
114.26,-39.06,0.199
114.27,-38.99,0.199
114.27,-38.93,0.199
114.28,-38.86,0.199
114.29,-38.79,0.199
114.29,-38.72,0.199
114.30,-38.66,0.199
114.31,-38.59,0.199
114.31,-38.52,0.199
114.32,-38.46,0.199
114.33,-38.39,0.199
114.33,-38.32,0.199
114.34,-38.26,0.199
114.35,-38.19,0.199
114.35,-38.12,0.199
114.36,-38.06,0.199
114.37,-37.99,0.199
114.37,-37.92,0.199
114.38,-37.86,0.199
114.39,-37.79,0.199
114.39,-37.72,0.199
114.40,-37.66,0.199
114.41,-37.59,0.200
114.41,-37.52,0.200
114.42,-37.46,0.200
114.43,-37.39,0.200
114.43,-37.32,0.200
114.44,-37.26,0.200
114.45,-37.19,0.200
114.45,-37.12,0.200
114.46,-37.06,0.200
114.47,-36.99,0.200
114.47,-36.92,0.200
114.48,-36.86,0.200
114.49,-36.79,0.200
114.49,-36.72,0.200
114.50,-36.65,0.200
114.51,-36.59,0.200
114.51,-36.52,0.200
114.52,-36.45,0.200
114.53,-36.39,0.200
114.53,-36.32,0.200
114.54,-36.25,0.200
114.55,-36.19,0.200
114.55,-36.12,0.200
114.56,-36.06,0.200
114.57,-35.99,0.200
114.57,-35.92,0.200
114.58,-35.85,0.201
114.59,-35.79,0.201
114.59,-35.72,0.201
114.60,-35.65,0.201
114.61,-35.59,0.201
114.61,-35.52,0.201
114.62,-35.45,0.201
114.63,-35.39,0.201
114.63,-35.32,0.201
114.64,-35.25,0.201
114.65,-35.19,0.201
114.65,-35.12,0.201
114.66,-35.05,0.201
114.67,-34.99,0.201
114.67,-34.92,0.201
114.68,-34.85,0.201
114.69,-34.79,0.201
114.69,-34.72,0.201
114.70,-34.65,0.201
114.71,-34.59,0.201
114.71,-34.52,0.201
114.72,-34.45,0.201
114.73,-34.39,0.202
114.73,-34.32,0.202
114.74,-34.25,0.202
114.75,-34.18,0.202
114.75,-34.12,0.202
114.76,-34.05,0.202
114.77,-33.98,0.202
114.77,-33.92,0.202
114.78,-33.85,0.202
114.79,-33.78,0.202
114.79,-33.72,0.202
114.80,-33.65,0.202
114.81,-33.58,0.202
114.81,-33.52,0.202
114.82,-33.45,0.202
114.83,-33.39,0.202
114.83,-33.32,0.202
114.84,-33.25,0.202
114.85,-33.18,0.202
114.85,-33.12,0.202
114.86,-33.05,0.202
114.87,-32.98,0.202
114.87,-32.92,0.202
114.88,-32.85,0.202
114.89,-32.78,0.202
114.89,-32.72,0.203
114.90,-32.65,0.203
114.91,-32.58,0.203
114.91,-32.52,0.203
114.92,-32.45,0.203
114.93,-32.38,0.203
114.93,-32.32,0.203
114.94,-32.25,0.203
114.95,-32.18,0.203
114.95,-32.11,0.203
114.96,-32.05,0.203
114.97,-31.98,0.203
114.97,-31.92,0.203
114.98,-31.85,0.203
114.99,-31.78,0.203
114.99,-31.71,0.203
115.00,-31.65,0.203
115.01,-31.58,0.203
115.01,-31.52,0.203
115.02,-31.45,0.203
115.03,-31.38,0.203
115.03,-31.31,0.203
115.04,-31.25,0.203
115.05,-31.18,0.203
115.05,-31.11,0.203
115.06,-31.05,0.204
115.07,-30.98,0.204
115.07,-30.91,0.204
115.08,-30.85,0.204
115.09,-30.78,0.204
115.09,-30.71,0.204
115.10,-30.65,0.204
115.11,-30.58,0.204
115.11,-30.51,0.204
115.12,-30.45,0.204
115.13,-30.38,0.204
115.13,-30.31,0.204
115.14,-30.25,0.204
115.15,-30.18,0.204
115.15,-30.11,0.204
115.16,-30.05,0.204
115.17,-29.98,0.204
115.17,-29.91,0.204
115.18,-29.85,0.204
115.19,-29.78,0.204
115.19,-29.71,0.204
115.20,-29.64,0.204
115.21,-29.58,0.204
115.21,-29.51,0.205
115.22,-29.44,0.205
115.23,-29.38,0.205
115.23,-29.31,0.205
115.24,-29.24,0.205
115.25,-29.18,0.205
115.25,-29.11,0.205
115.26,-29.04,0.205
115.27,-28.98,0.205
115.27,-28.91,0.205
115.28,-28.84,0.205
115.29,-28.78,0.205
115.29,-28.71,0.205
115.30,-28.64,0.205
115.31,-28.58,0.205
115.31,-28.51,0.205
115.32,-28.44,0.205
115.33,-28.38,0.205
115.33,-28.31,0.205
115.34,-28.24,0.205
115.35,-28.18,0.205
115.35,-28.11,0.205
115.36,-28.04,0.205
115.37,-27.98,0.206
115.37,-27.91,0.206
115.38,-27.84,0.206
115.39,-27.78,0.206
115.39,-27.71,0.206
115.40,-27.64,0.206
115.41,-27.58,0.206
115.41,-27.51,0.206
115.42,-27.44,0.206
115.43,-27.38,0.206
115.43,-27.31,0.206
115.44,-27.24,0.206
115.45,-27.18,0.206
115.45,-27.11,0.206
115.46,-27.04,0.206
115.47,-26.98,0.206
115.47,-26.91,0.206
115.48,-26.84,0.206
115.49,-26.77,0.206
115.49,-26.71,0.206
115.50,-26.64,0.206
115.51,-26.58,0.206
115.51,-26.51,0.206
115.52,-26.44,0.207
115.53,-26.37,0.207
115.53,-26.31,0.207
115.54,-26.24,0.207
115.55,-26.17,0.207
115.55,-26.11,0.207
115.56,-26.04,0.207
115.57,-25.97,0.207
115.57,-25.91,0.207
115.58,-25.84,0.207
115.59,-25.77,0.207
115.59,-25.71,0.207
115.60,-25.64,0.207
115.61,-25.57,0.207
115.61,-25.51,0.207
115.62,-25.44,0.207
115.63,-25.37,0.207
115.63,-25.31,0.207
115.64,-25.24,0.207
115.65,-25.17,0.207
115.65,-25.11,0.207
115.66,-25.04,0.207
115.67,-24.97,0.208
115.67,-24.91,0.208
115.68,-24.84,0.208
115.69,-24.77,0.208
115.69,-24.71,0.208
115.70,-24.64,0.208
115.71,-24.57,0.208
115.71,-24.50,0.208
115.72,-24.44,0.208
115.73,-24.37,0.208
115.73,-24.31,0.208
115.74,-24.24,0.208
115.75,-24.17,0.208
115.75,-24.10,0.208
115.76,-24.04,0.208
115.77,-23.97,0.208
115.77,-23.91,0.208
115.78,-23.84,0.208
115.79,-23.77,0.208
115.79,-23.71,0.208
115.80,-23.64,0.208
115.81,-23.57,0.209
115.81,-23.51,0.209
115.82,-23.44,0.209
115.83,-23.37,0.209
115.83,-23.30,0.209
115.84,-23.24,0.209
115.85,-23.17,0.209
115.85,-23.11,0.209
115.86,-23.04,0.209
115.87,-22.97,0.209
115.87,-22.90,0.209
115.88,-22.84,0.209
115.89,-22.77,0.209
115.89,-22.70,0.209
115.90,-22.64,0.209
115.91,-22.57,0.209
115.91,-22.50,0.209
115.92,-22.44,0.209
115.93,-22.37,0.209
115.93,-22.30,0.209
115.94,-22.24,0.210
115.95,-22.17,0.210
115.95,-22.10,0.210
115.96,-22.04,0.210
115.97,-21.97,0.210
115.97,-21.90,0.210
115.98,-21.84,0.210
115.99,-21.77,0.210
115.99,-21.70,0.210
116.00,-21.64,0.210
116.01,-21.57,0.210
116.01,-21.50,0.210
116.02,-21.44,0.210
116.03,-21.37,0.210
116.03,-21.30,0.210
116.04,-21.24,0.210
116.05,-21.17,0.210
116.05,-21.10,0.210
116.06,-21.04,0.210
116.07,-20.97,0.211
116.07,-20.90,0.211
116.08,-20.83,0.211
116.09,-20.77,0.211
116.09,-20.70,0.211
116.10,-20.63,0.211
116.11,-20.57,0.211
116.11,-20.50,0.211
116.12,-20.43,0.211
116.13,-20.37,0.211
116.13,-20.30,0.211
116.14,-20.23,0.211
116.15,-20.17,0.211
116.15,-20.10,0.211
116.16,-20.03,0.211
116.17,-19.97,0.211
116.17,-19.90,0.211
116.18,-19.83,0.211
116.19,-19.77,0.211
116.19,-19.70,0.211
116.20,-19.63,0.212
116.21,-19.57,0.212
116.21,-19.50,0.212
116.22,-19.43,0.212
116.23,-19.37,0.212
116.23,-19.30,0.212
116.24,-19.23,0.212
116.25,-19.17,0.212
116.25,-19.10,0.212
116.26,-19.03,0.212
116.27,-18.97,0.212
116.27,-18.90,0.212
116.28,-18.83,0.212
116.29,-18.77,0.212
116.29,-18.70,0.212
116.30,-18.63,0.212
116.31,-18.57,0.212
116.31,-18.50,0.213
116.32,-18.43,0.213
116.33,-18.37,0.213
116.33,-18.30,0.213
116.34,-18.23,0.213
116.35,-18.17,0.213
116.35,-18.10,0.213
116.36,-18.03,0.213
116.37,-17.97,0.213
116.37,-17.90,0.213
116.38,-17.83,0.213
116.39,-17.76,0.213
116.39,-17.70,0.213
116.40,-17.63,0.213
116.41,-17.56,0.213
116.41,-17.50,0.213
116.42,-17.43,0.213
116.43,-17.36,0.214
116.43,-17.30,0.214
116.44,-17.23,0.214
116.45,-17.16,0.214
116.45,-17.10,0.214
116.46,-17.03,0.214
116.47,-16.96,0.214
116.47,-16.90,0.214
116.48,-16.83,0.214
116.49,-16.76,0.214
116.49,-16.70,0.214
116.50,-16.63,0.214
116.51,-16.56,0.214
116.51,-16.50,0.215
116.52,-16.43,0.215
116.53,-16.36,0.215
116.53,-16.30,0.215
116.54,-16.23,0.215
116.55,-16.16,0.215
116.55,-16.10,0.215
116.56,-16.03,0.215
116.57,-15.96,0.215
116.57,-15.90,0.215
116.58,-15.83,0.215
116.59,-15.76,0.215
116.59,-15.70,0.215
116.60,-15.63,0.215
116.61,-15.56,0.216
116.61,-15.50,0.216
116.62,-15.43,0.216
116.63,-15.36,0.216
116.63,-15.30,0.216
116.64,-15.23,0.216
116.65,-15.16,0.216
116.65,-15.10,0.216
116.66,-15.03,0.216
116.67,-14.96,0.216
116.67,-14.89,0.216
116.68,-14.83,0.216
116.69,-14.76,0.216
116.69,-14.69,0.217
116.70,-14.63,0.217
116.71,-14.56,0.217
116.71,-14.49,0.217
116.72,-14.43,0.217
116.73,-14.36,0.217
116.73,-14.29,0.217
116.74,-14.23,0.217
116.75,-14.16,0.217
116.75,-14.10,0.217
116.76,-14.03,0.217
116.77,-13.96,0.218
116.77,-13.90,0.218
116.78,-13.83,0.218
116.79,-13.76,0.218
116.79,-13.69,0.218
116.80,-13.63,0.218
116.81,-13.56,0.218
116.81,-13.50,0.218
116.82,-13.43,0.218
116.83,-13.36,0.218
116.83,-13.30,0.219
116.84,-13.23,0.219
116.85,-13.16,0.219
116.85,-13.10,0.219
116.86,-13.03,0.219
116.87,-12.96,0.220
116.87,-12.89,0.220
116.88,-12.83,0.220
116.89,-12.76,0.220
116.89,-12.69,0.220
116.90,-12.63,0.220
116.91,-12.56,0.220
116.91,-12.49,0.220
116.92,-12.43,0.221
116.93,-12.36,0.221
116.93,-12.29,0.221
116.94,-12.23,0.221
116.95,-12.16,0.221
116.95,-12.10,0.221
116.96,-12.03,0.221
116.97,-11.96,0.221
116.97,-11.90,0.222
116.98,-11.83,0.222
116.99,-11.76,0.222
116.99,-11.69,0.222
117.00,-11.63,0.222
117.01,-11.56,0.222
117.01,-11.50,0.223
117.02,-11.43,0.223
117.03,-11.36,0.223
117.03,-11.30,0.223
117.04,-11.23,0.223
117.05,-11.16,0.223
117.05,-11.10,0.223
117.06,-11.03,0.224
117.07,-10.96,0.224
117.07,-10.89,0.224
117.08,-10.83,0.224
117.09,-10.76,0.224
117.09,-10.69,0.225
117.10,-10.63,0.225
117.11,-10.56,0.225
117.11,-10.49,0.226
117.12,-10.43,0.226
117.13,-10.36,0.226
117.13,-10.30,0.226
117.14,-10.23,0.226
117.15,-10.16,0.227
117.15,-10.10,0.227
117.16,-10.03,0.227
117.17,-9.96,0.227
117.17,-9.90,0.228
117.18,-9.83,0.229
117.19,-9.76,0.229
117.19,-9.70,0.229
117.20,-9.63,0.229
117.21,-9.57,0.229
117.21,-9.50,0.230
117.22,-9.43,0.231
117.23,-9.36,0.231
117.23,-9.30,0.231
117.24,-9.23,0.231
117.25,-9.16,0.232
117.25,-9.10,0.232
117.26,-9.03,0.233
117.27,-8.97,0.233
117.27,-8.90,0.233
117.28,-8.83,0.234
117.29,-8.77,0.234
117.29,-8.70,0.234
117.30,-8.63,0.235
117.31,-8.57,0.236
117.31,-8.50,0.236
117.32,-8.43,0.237
117.33,-8.37,0.238
117.33,-8.30,0.238
117.34,-8.23,0.238
117.35,-8.17,0.239
117.35,-8.10,0.239
117.36,-8.03,0.240
117.37,-7.97,0.240
117.37,-7.90,0.241
117.38,-7.83,0.242
117.39,-7.77,0.242
117.39,-7.70,0.242
117.40,-7.63,0.243
117.41,-7.57,0.243
117.41,-7.50,0.244
117.42,-7.44,0.244
117.43,-7.37,0.245
117.43,-7.30,0.245
117.44,-7.23,0.246
117.45,-7.17,0.247
117.45,-7.10,0.247
117.46,-7.04,0.248
117.47,-6.97,0.248
117.47,-6.90,0.250
117.48,-6.84,0.251
117.49,-6.77,0.251
117.49,-6.70,0.252
117.50,-6.64,0.252
117.51,-6.57,0.253
117.51,-6.50,0.253
117.52,-6.44,0.254
117.53,-6.37,0.255
117.53,-6.31,0.255
117.54,-6.24,0.256
117.55,-6.17,0.256
117.55,-6.11,0.257
117.56,-6.04,0.258
117.57,-5.97,0.258
117.57,-5.91,0.259
117.58,-5.84,0.260
117.59,-5.77,0.260
117.59,-5.71,0.261
117.60,-5.64,0.263
117.61,-5.58,0.263
117.61,-5.51,0.263
117.62,-5.44,0.264
117.63,-5.38,0.265
117.63,-5.31,0.267
117.64,-5.24,0.267
117.65,-5.18,0.268
117.65,-5.11,0.268
117.66,-5.04,0.269
117.67,-4.98,0.270
117.67,-4.91,0.270
117.68,-4.85,0.271
117.69,-4.78,0.272
117.69,-4.71,0.272
117.70,-4.65,0.273
117.71,-4.58,0.274
117.71,-4.51,0.274
117.72,-4.45,0.274
117.73,-4.38,0.275
117.73,-4.31,0.275
117.74,-4.25,0.276
117.75,-4.18,0.277
117.75,-4.11,0.278
117.76,-4.05,0.278
117.77,-3.98,0.278
117.77,-3.92,0.279
117.78,-3.85,0.280
117.79,-3.78,0.280
117.79,-3.72,0.281
117.80,-3.65,0.281
117.81,-3.58,0.282
117.81,-3.52,0.282
117.82,-3.45,0.283
117.83,-3.38,0.283
117.83,-3.32,0.283
117.84,-3.25,0.283
117.85,-3.19,0.284
117.85,-3.12,0.284
117.86,-3.05,0.284
117.87,-2.99,0.284
117.87,-2.92,0.285
117.88,-2.85,0.285
117.89,-2.79,0.285
117.89,-2.72,0.285
117.90,-2.65,0.285
117.91,-2.59,0.285
117.91,-2.52,0.285
117.92,-2.45,0.285
117.93,-2.38,0.285
117.93,-2.32,0.285
117.94,-2.25,0.285
117.95,-2.18,0.285
117.95,-2.12,0.285
117.96,-2.05,0.285
117.97,-1.98,0.285
117.97,-1.92,0.285
117.98,-1.85,0.285
117.99,-1.78,0.285
117.99,-1.72,0.285
118.00,-1.65,0.285
118.01,-1.58,0.285
118.01,-1.52,0.285
118.02,-1.45,0.285
118.03,-1.38,0.285
118.03,-1.32,0.284
118.04,-1.25,0.284
118.05,-1.18,0.284
118.05,-1.12,0.284
118.06,-1.05,0.284
118.07,-0.98,0.284
118.07,-0.92,0.284
118.08,-0.85,0.284
118.09,-0.78,0.284
118.09,-0.71,0.283
118.10,-0.65,0.283
118.11,-0.58,0.283
118.11,-0.51,0.283
118.12,-0.45,0.283
118.13,-0.38,0.283
118.13,-0.31,0.282
118.14,-0.25,0.282
118.15,-0.18,0.282
118.15,-0.11,0.282
118.16,-0.05,0.282
118.17,0.02,0.282
118.17,0.09,0.282
118.18,0.16,0.282
118.19,0.22,0.282
118.19,0.29,0.281
118.20,0.36,0.281
118.21,0.42,0.281
118.21,0.49,0.281
118.22,0.56,0.281
118.23,0.62,0.281
118.23,0.69,0.280
118.24,0.76,0.280
118.25,0.82,0.280
118.25,0.89,0.280
118.26,0.96,0.280
118.27,1.02,0.280
118.27,1.09,0.279
118.28,1.16,0.279
118.29,1.22,0.279
118.29,1.29,0.279
118.30,1.36,0.279
118.31,1.43,0.279
118.31,1.49,0.279
118.32,1.56,0.278
118.33,1.63,0.278
118.33,1.69,0.278
118.34,1.76,0.278
118.35,1.83,0.278
118.35,1.89,0.278
118.36,1.96,0.278
118.37,2.03,0.278
118.37,2.09,0.278
118.38,2.16,0.278
118.39,2.23,0.278
118.39,2.30,0.278
118.40,2.36,0.277
118.41,2.43,0.277
118.41,2.50,0.277
118.42,2.56,0.277
118.43,2.63,0.277
118.43,2.70,0.277
118.44,2.76,0.277
118.45,2.83,0.277
118.45,2.90,0.277
118.46,2.96,0.277
118.47,3.03,0.277
118.47,3.10,0.277
118.48,3.16,0.277
118.49,3.23,0.277
118.49,3.30,0.276
118.50,3.36,0.276
118.51,3.43,0.276
118.51,3.50,0.276
118.52,3.56,0.276
118.53,3.63,0.276
118.53,3.70,0.276
118.54,3.76,0.276
118.55,3.83,0.276
118.55,3.90,0.276
118.56,3.96,0.276
118.57,4.03,0.276
118.57,4.10,0.276
118.58,4.17,0.276
118.59,4.23,0.276
118.59,4.30,0.276
118.60,4.37,0.276
118.61,4.43,0.276
118.61,4.50,0.276
118.62,4.57,0.276
118.63,4.63,0.276
118.63,4.70,0.276
118.64,4.77,0.276
118.65,4.83,0.276
118.65,4.90,0.276
118.66,4.97,0.276
118.67,5.03,0.276
118.67,5.10,0.276
118.68,5.17,0.276
118.69,5.23,0.275
118.69,5.30,0.275
118.70,5.37,0.275
118.71,5.44,0.275
118.71,5.50,0.275
118.72,5.57,0.275
118.73,5.63,0.275
118.73,5.70,0.275
118.74,5.77,0.275
118.75,5.84,0.275
118.75,5.90,0.275
118.76,5.97,0.275
118.77,6.04,0.275
118.77,6.10,0.275
118.78,6.17,0.275
118.79,6.24,0.275
118.79,6.30,0.275
118.80,6.37,0.275
118.81,6.44,0.275
118.81,6.50,0.275
118.82,6.57,0.275
118.83,6.64,0.275
118.83,6.70,0.275
118.84,6.77,0.276
118.85,6.84,0.276
118.85,6.90,0.276
118.86,6.97,0.276
118.87,7.04,0.276
118.87,7.10,0.276
118.88,7.17,0.276
118.89,7.24,0.276
118.89,7.30,0.276
118.90,7.37,0.276
118.91,7.44,0.276
118.91,7.50,0.276
118.92,7.57,0.276
118.93,7.64,0.276
118.93,7.70,0.276
118.94,7.77,0.276
118.95,7.84,0.276
118.95,7.91,0.276
118.96,7.97,0.276
118.97,8.04,0.276
118.97,8.10,0.276
118.98,8.17,0.276
118.99,8.24,0.276
118.99,8.30,0.276
119.00,8.37,0.276
119.01,8.44,0.276
119.01,8.50,0.276
119.02,8.57,0.276
119.03,8.64,0.276
119.03,8.71,0.276
119.04,8.77,0.276
119.05,8.84,0.276
119.05,8.91,0.276
119.06,8.97,0.276
119.07,9.04,0.276
119.07,9.11,0.277
119.08,9.17,0.277
119.09,9.24,0.277
119.09,9.31,0.277
119.10,9.37,0.277
119.11,9.44,0.277
119.11,9.51,0.277
119.12,9.57,0.277
119.13,9.64,0.277
119.13,9.71,0.277
119.14,9.77,0.277
119.15,9.84,0.277
119.15,9.91,0.277
119.16,9.97,0.277
119.17,10.04,0.277
119.17,10.11,0.277
119.18,10.17,0.277
119.19,10.24,0.277
119.19,10.31,0.277
119.20,10.37,0.277
119.21,10.44,0.277
119.21,10.51,0.277
119.22,10.57,0.277
119.23,10.64,0.277
119.23,10.71,0.277
119.24,10.77,0.277
119.25,10.84,0.278
119.25,10.91,0.278
119.26,10.97,0.278
119.27,11.04,0.278
119.27,11.11,0.278
119.28,11.18,0.278
119.29,11.24,0.278
119.29,11.31,0.278
119.30,11.38,0.278
119.31,11.44,0.278
119.31,11.51,0.278
119.32,11.58,0.278
119.33,11.64,0.278
119.33,11.71,0.278
119.34,11.77,0.278
119.35,11.84,0.278
119.35,11.91,0.278
119.36,11.98,0.278
119.37,12.04,0.278
119.37,12.11,0.278
119.38,12.18,0.278
119.39,12.24,0.279
119.39,12.31,0.279
119.40,12.38,0.279
119.41,12.44,0.279
119.41,12.51,0.279
119.42,12.58,0.279
119.43,12.64,0.279
119.43,12.71,0.279
119.44,12.78,0.279
119.45,12.84,0.279
119.45,12.91,0.279
119.46,12.98,0.279
119.47,13.04,0.279
119.47,13.11,0.279
119.48,13.18,0.279
119.49,13.24,0.279
119.49,13.31,0.279
119.50,13.38,0.279
119.51,13.44,0.279
119.51,13.51,0.279
119.52,13.58,0.279
119.53,13.65,0.279
119.53,13.71,0.279
119.54,13.78,0.279
119.55,13.84,0.279
119.55,13.91,0.280
119.56,13.98,0.280
119.57,14.05,0.280
119.57,14.11,0.280
119.58,14.18,0.280
119.59,14.25,0.280
119.59,14.31,0.280
119.60,14.38,0.280
119.61,14.45,0.280
119.61,14.51,0.280
119.62,14.58,0.280
119.63,14.65,0.280
119.63,14.71,0.280
119.64,14.78,0.280
119.65,14.85,0.280
119.65,14.91,0.280
119.66,14.98,0.280
119.67,15.05,0.280
119.67,15.11,0.280
119.68,15.18,0.280
119.69,15.25,0.280
119.69,15.31,0.280
119.70,15.38,0.281
119.71,15.45,0.281
119.71,15.51,0.281
119.72,15.58,0.281
119.73,15.65,0.281
119.73,15.71,0.281
119.74,15.78,0.281
119.75,15.85,0.281
119.75,15.92,0.281
119.76,15.98,0.281
119.77,16.05,0.281
119.77,16.11,0.281
119.78,16.18,0.281
119.79,16.25,0.281
119.79,16.32,0.281
119.80,16.38,0.281
119.81,16.45,0.281
119.81,16.51,0.281
119.82,16.58,0.281
119.83,16.65,0.282
119.83,16.72,0.282
119.84,16.78,0.282
119.85,16.85,0.282
119.85,16.91,0.282
119.86,16.98,0.282
119.87,17.05,0.282
119.87,17.12,0.282
119.88,17.18,0.282
119.89,17.25,0.282
119.89,17.32,0.282
119.90,17.38,0.282
119.91,17.45,0.282
119.91,17.52,0.282
119.92,17.58,0.282
119.93,17.65,0.282
119.93,17.72,0.282
119.94,17.78,0.282
119.95,17.85,0.282
119.95,17.92,0.282
119.96,17.98,0.282
119.97,18.05,0.283
119.97,18.11,0.283
119.98,18.18,0.283
119.99,18.25,0.283
119.99,18.32,0.283
120.00,18.38,0.283
120.01,18.45,0.283
120.01,18.52,0.283
120.02,18.58,0.283
120.03,18.65,0.283
120.03,18.72,0.283
120.04,18.79,0.283
120.05,18.85,0.283
120.05,18.92,0.283
120.06,18.98,0.283
120.07,19.05,0.283
120.07,19.12,0.283
120.08,19.19,0.283
120.09,19.25,0.283
120.09,19.32,0.283
120.10,19.38,0.283
120.11,19.45,0.284
120.11,19.52,0.284
120.12,19.59,0.284
120.13,19.65,0.284
120.13,19.72,0.284
120.14,19.79,0.284
120.15,19.85,0.284
120.15,19.92,0.284
120.16,19.99,0.284
120.17,20.05,0.284
120.17,20.12,0.284
120.18,20.18,0.284
120.19,20.25,0.284
120.19,20.32,0.284
120.20,20.39,0.284
120.21,20.45,0.284
120.21,20.52,0.284
120.22,20.59,0.284
120.23,20.65,0.284
120.23,20.72,0.284
120.24,20.79,0.284
120.25,20.85,0.285
120.25,20.92,0.285
120.26,20.99,0.285
120.27,21.05,0.285
120.27,21.12,0.285
120.28,21.19,0.285
120.29,21.25,0.285
120.29,21.32,0.285
120.30,21.39,0.285
120.31,21.45,0.285
120.31,21.52,0.285
120.32,21.59,0.285
120.33,21.65,0.285
120.33,21.72,0.285
120.34,21.79,0.285
120.35,21.85,0.285
120.35,21.92,0.285
120.36,21.99,0.285
120.37,22.05,0.285
120.37,22.12,0.285
120.38,22.19,0.286
120.39,22.26,0.286
120.39,22.32,0.286
120.40,22.39,0.286
120.41,22.46,0.286
120.41,22.52,0.286
120.42,22.59,0.286
120.43,22.65,0.286
120.43,22.72,0.286
120.44,22.79,0.286
120.45,22.85,0.286
120.45,22.92,0.286
120.46,22.99,0.286
120.47,23.05,0.286
120.47,23.12,0.286
120.48,23.19,0.286
120.49,23.26,0.286
120.49,23.32,0.286
120.50,23.39,0.286
120.51,23.45,0.286
120.51,23.52,0.286
120.52,23.59,0.287
120.53,23.66,0.287
120.53,23.72,0.287
120.54,23.79,0.287
120.55,23.86,0.287
120.55,23.92,0.287
120.56,23.99,0.287
120.57,24.06,0.287
120.57,24.12,0.287
120.58,24.19,0.287
120.59,24.26,0.287
120.59,24.32,0.287
120.60,24.39,0.287
120.61,24.45,0.287
120.61,24.52,0.287
120.62,24.59,0.287
120.63,24.66,0.288
120.63,24.72,0.288
120.64,24.79,0.288
120.65,24.86,0.288
120.65,24.92,0.288
120.66,24.99,0.288
120.67,25.06,0.288
120.67,25.12,0.288
120.68,25.19,0.288
120.69,25.26,0.288
120.69,25.32,0.288
120.70,25.39,0.288
120.71,25.46,0.288
120.71,25.52,0.288
120.72,25.59,0.288
120.73,25.66,0.288
120.73,25.72,0.288
120.74,25.79,0.288
120.75,25.86,0.289
120.75,25.92,0.289
120.76,25.99,0.289
120.77,26.06,0.289
120.77,26.12,0.289
120.78,26.19,0.289
120.79,26.26,0.289
120.79,26.32,0.289
120.80,26.39,0.289
120.81,26.46,0.289
120.81,26.53,0.289
120.82,26.59,0.289
120.83,26.66,0.289
120.83,26.73,0.289
120.84,26.79,0.289
120.85,26.86,0.289
120.85,26.93,0.289
120.86,26.99,0.289
120.87,27.06,0.289
120.87,27.13,0.289
120.88,27.19,0.290
120.89,27.26,0.290
120.89,27.33,0.290
120.90,27.39,0.290
120.91,27.46,0.290
120.91,27.53,0.290
120.92,27.59,0.290
120.93,27.66,0.290
120.93,27.73,0.290
120.94,27.79,
120.95,27.86,
120.95,27.93,
120.96,27.99,
120.97,28.06,
120.97,28.13,
120.98,28.19,
120.99,,
120.99,,