File: DSC/2025_02_13_CBN_FluoroWorks_DSC.txt
Filename	2025_02_13_CBN_FluoroWorks_DSC
Instrument name	DSC2A-00468 (192.168.1.100)
Operator	JLY
rundate	2/13/2025
Sample name	2025_02_13_CBN_FluoroWorks_DSC
proceduresegments	Data Off ; Equilibrate -40.00 °C; Data On ; Ramp 5.00 °C/min to 120.00 °C; Data Off ; Isothermal 1.0 min; Data On ; Ramp 5.00 °C/min to -40.00 °C; Data Off ; Isothermal 1.0 min; Data On ; Ramp 5.00 °C/min to 120.00 °C; Data Off ; Isothermal 1.0 min; Data On ; Ramp 5.00 °C/min to -40.00 °C; Data Off ; Isothermal 1.0 min; Data On ; Ramp 5.00 °C/min to 120.00 °C
[File Parameters]
Run date	2/13/2025 9:16:15 PM
Trios version	5.1.1.46572
Original File Name
Current File Name	D:\DSC2500\CHM343\2025_02_13_CBN_FluoroWorks_DSC.tri
[Procedure]
Procedure Name	CBN Melting x3
Sample Name	2025_02_13_CBN_FluoroWorks_DSC
Sample Mass	3.81 mg
Reference Sample Mass	0 mg
Pan Mass	54.49 mg
Pan Number	13
Reference Pan Mass	54 mg
Reference Pan Number	19
Pan Type	Tzero Aluminum Hermetic
Comments	Al Hermetic Sealed Pan, with ref Al pan.  FloroWorks CBN.
Project Name
Operator	JLY
Test	Custom
Unload Max Temperature	30
Unload Min Temperature	30
Load Max Temperature	30
Load Min Temperature	30
Stop on Gas Flow Error	Yes
[Signal List]
Signal #1	Time (min)
Signal #2	Temperature (°C)
Signal #3	Heat Flow (mW)
Signal #4	Delta T (µV)
Signal #5	Delta Tzero (µV)
Signal #6	Tzero Temperature (°C)
Signal #7	Cell Purge (mL/min)
Signal #8	Heater Temp (°C)
Signal #9	Power Delivered (W)
Signal #10	Reference Junction Temperature (°C)
Signal #11	Flange Temperature (°C)
Signal #12	Heat Flow Phase (rad)
Signal #13	Total Heat Capacity (J/°C)
Signal #14	Heat Capacity (J/°C)
[Configuration]
Company Name	ASU
Instrument Name	DSC2A-00468
Instrument Type	DSC2500
Serial Number	DSC2A-00468
IP	192.168.1.100
Location of Instrument	MRRC
DisplayType	Unknown
Sample Interval 	0.1 s/pt
Selected Heat Flow	T4P
Exotherm Direction	Down
Cell Serial	DRC2-00792
Lid Type	Standard
Cooler	RCS 90
Leave Cooler on at End of Sequence	On
Gas 2	Nitrogen
Gas Selected	Channel 1
Flow Rate	50 mL/min
Secondary Purge	On
Licensed Heat Flow	Heat Flow T4P
Modulation Licensed	Yes
[Versions]
Common IDD Version	1
Cortex Version	VER 2.10.2.31
Driver	5.0.0.6
GDM Version	1.0.3.3
TouchscreenVersion	1.0.0.16145
FEP Version	1.2.1.21
FEP Bootloader	2.0.0.5
AutoSampler Version	2.1.1.26
Auto Sampler Bootloader	2.0.0.5
FCM Version	1.1.0.3
FCM Bootloader	2.0.0.5
[Experiment Logs]
Experiment Log Entry # 1	Data On set to 0
Experiment Log Entry # 3	Equilibrate Segment -40 (C) Started
Experiment Log Entry # 5	Air Cool is off.
Experiment Log Entry # 7	Data On set to 1
Experiment Log Entry # 9	Ramp Segment 5 C/min to 120 Started
Experiment Log Entry # 11	Data On set to 0
Experiment Log Entry # 13	Isothermal Segment 1 min started
Experiment Log Entry # 15	Data On set to 1
Experiment Log Entry # 17	Ramp Segment 5 C/min to -40 Started
Experiment Log Entry # 19	Data On set to 0
Experiment Log Entry # 21	Isothermal Segment 1 min started
Experiment Log Entry # 23	Data On set to 1
Experiment Log Entry # 25	Ramp Segment 5 C/min to 120 Started
Experiment Log Entry # 27	Data On set to 0
Experiment Log Entry # 29	Isothermal Segment 1 min started
Experiment Log Entry # 31	Data On set to 1
Experiment Log Entry # 33	Ramp Segment 5 C/min to -40 Started
Experiment Log Entry # 35	Data On set to 0
Experiment Log Entry # 37	Isothermal Segment 1 min started
Experiment Log Entry # 39	Data On set to 1
Experiment Log Entry # 41	Ramp Segment 5 C/min to 120 Started
[Method Log]
Method Log Entry # 1	Data Off
Method Log Entry # 2	Equilibrate -40 °C
Method Log Entry # 3	Data On
Method Log Entry # 4	(Ramp 65057) Ramp 5 °C/minute to 120 °C
Method Log Entry # 5	Data Off
Method Log Entry # 6	Isothermal 1 minutes
Method Log Entry # 7	Data On
Method Log Entry # 8	(Ramp 65061) Ramp 5 °C/minute to -40 °C
Method Log Entry # 9	Data Off
Method Log Entry # 10	Isothermal 1 minutes
Method Log Entry # 11	Data On
Method Log Entry # 12	(Ramp 65065) Ramp 5 °C/minute to 120 °C
Method Log Entry # 13	Data Off
Method Log Entry # 14	Isothermal 1 minutes
Method Log Entry # 15	Data On
Method Log Entry # 16	(Ramp 65069) Ramp 5 °C/minute to -40 °C
Method Log Entry # 17	Data Off
Method Log Entry # 18	Isothermal 1 minutes
Method Log Entry # 19	Data On
Method Log Entry # 20	(Ramp 65073) Ramp 5 °C/minute to 120 °C
Cell Serial	DRC2-00792
[T1 Calibration]
Slope	-0.008529666
Offset	9.636258
Initial Temperature	98.23
GUID	f8bfdadc-4977-4fdf-ba6d-0ba9134940c3
[TZero Calibration]
Date Applied	11/29/2022 4:06:13 PM
Description	From -89.059 °C to 396.009 °C at 20.000°C/min
Gas Type	Nitrogen
Pan Type	None
Source Files 1	C:\Users\yargerlab\Desktop\DSC Data\General\TZero_calibration_11_29_22_2nd(2).tri
Source Files 2	C:\Users\yargerlab\Desktop\DSC Data\General\TZero_calibration_11_29_22_2nd(3).tri
Delta T Offset	13.05235
Delta T Slope	-0.007271007
Delta T0 Offset	-13.69128
Delta T0 Slope	0.06063341
[Temperature Calibration]
Date Applied	11/29/2022 7:12:28 PM
Description	From 106.590 °C to 186.590 °C at 10.000°C/min
Gas Type	Nitrogen
Pan Type	Tzero Aluminum Hermetic
Source Files 1	C:\Users\yargerlab\Desktop\DSC Data\General\Indium(6).tri
Measured 1	157.391
Known 1	156.598
[Cell Constant Calibration]
Date Applied	11/29/2022 7:12:29 PM
Description	From 106.590 °C to 186.590 °C at 10.000°C/min
Gas Type	Nitrogen
Pan Type	Tzero Aluminum Hermetic
Source Files 1	C:\Users\yargerlab\Desktop\DSC Data\General\Indium(6).tri
T4P KCell	1.006051
Onset Slope	63.26126 mW/°C
[Direct Cp Calibration]
Date Applied	11/30/2022 11:04:51 AM
Description	From -79.983 °C to 298.409 °C at 10.000°C/min
Gas Type	Nitrogen
Pan Type	Tzero Aluminum Hermetic
Source Files 1	C:\Users\yargerlab\Desktop\DSC Data\General\Sapphire_Heat_Capacity_11_30_22.tri
[Rev Cp Calibration]
Date Applied	11/30/2022 1:58:51 PM
Description	From -79.996 °C to 292.812 °C at 3.000°C/min
Gas Type	Nitrogen
Pan Type	Tzero Aluminum Hermetic
Source Files 1	C:\Users\yargerlab\Desktop\DSC Data\General\Sapphire_MDSC_Calibration_11_30_22.tri
[step]
Ramp 5.00 °C/min to 120.00 °C
Time	Temperature	Heat Flow (Normalized)
min	°C	W/g
0.00	-39.70	-0.087
0.02	-39.71	-0.089
0.04	-39.72	-0.076
0.07	-39.73	-0.070
0.09	-39.72	-0.070
0.11	-39.70	-0.072
0.13	-39.66	-0.075
0.15	-39.61	-0.078
0.17	-39.55	-0.078
0.19	-39.48	-0.074
0.22	-39.40	-0.058
0.24	-39.32	-0.041
0.26	-39.23	-0.025
0.28	-39.14	-0.014
0.30	-39.05	0.001
0.33	-38.96	0.010
0.35	-38.86	0.020
0.37	-38.76	0.027
0.39	-38.66	0.032
0.41	-38.56	0.039
0.43	-38.47	0.043
0.45	-38.36	0.046
0.48	-38.26	0.050
0.50	-38.16	0.052
0.52	-38.06	0.053
0.54	-37.95	0.055
0.56	-37.85	0.056
0.58	-37.75	0.058
0.61	-37.64	0.058
0.63	-37.54	0.059
0.65	-37.43	0.060
0.67	-37.33	0.061
0.69	-37.22	0.061
0.72	-37.12	0.062
0.74	-37.01	0.062
0.76	-36.91	0.063
0.78	-36.80	0.063
0.80	-36.69	0.064
0.82	-36.59	0.064
0.85	-36.48	0.065
0.87	-36.37	0.065
0.89	-36.27	0.065
0.91	-36.16	0.066
0.93	-36.06	0.066
0.95	-35.95	0.066
0.98	-35.84	0.067
1.00	-35.74	0.067
1.02	-35.63	0.067
1.04	-35.52	0.067
1.06	-35.42	0.067
1.08	-35.31	0.068
1.11	-35.20	0.068
1.13	-35.09	0.068
1.15	-34.99	0.068
1.17	-34.88	0.068
1.19	-34.77	0.068
1.21	-34.66	0.068
1.23	-34.56	0.068
1.26	-34.45	0.068
1.28	-34.34	0.068
1.30	-34.23	0.068
1.32	-34.13	0.068
1.34	-34.02	0.068
1.37	-33.91	0.068
1.39	-33.80	0.069
1.41	-33.69	0.069
1.43	-33.59	0.069
1.45	-33.48	0.069
1.47	-33.37	0.069
1.49	-33.26	0.069
1.52	-33.15	0.069
1.54	-33.05	0.068
1.56	-32.94	0.068
1.58	-32.83	0.069
1.60	-32.72	0.068
1.63	-32.61	0.068
1.65	-32.51	0.068
1.67	-32.40	0.068
1.69	-32.29	0.068
1.71	-32.18	0.068
1.73	-32.07	0.068
1.76	-31.96	0.068
1.78	-31.86	0.068
1.80	-31.75	0.068
1.82	-31.64	0.068
1.84	-31.53	0.068
1.86	-31.42	0.068
1.88	-31.32	0.068
1.91	-31.21	0.068
1.93	-31.10	0.068
1.95	-30.99	0.068
1.97	-30.88	0.068
1.99	-30.77	0.068
2.02	-30.67	0.068
2.04	-30.56	0.068
2.06	-30.45	0.068
2.08	-30.34	0.068
2.10	-30.23	0.068
2.12	-30.12	0.068
2.14	-30.02	0.067
2.17	-29.91	0.067
2.19	-29.80	0.067
2.21	-29.69	0.067
2.23	-29.58	0.067
2.25	-29.47	0.067
2.28	-29.37	0.067
2.30	-29.26	0.067
2.32	-29.15	0.067
2.34	-29.04	0.067
2.36	-28.93	0.067
2.38	-28.82	0.067
2.41	-28.72	0.067
2.43	-28.61	0.067
2.45	-28.50	0.067
2.47	-28.39	0.067
2.49	-28.28	0.067
2.51	-28.17	0.067
2.54	-28.07	0.067
2.56	-27.96	0.067
2.58	-27.85	0.067
2.60	-27.74	0.067
2.62	-27.63	0.067
2.64	-27.52	0.067
2.66	-27.41	0.066
2.69	-27.31	0.066
2.71	-27.20	0.066
2.73	-27.09	0.066
2.75	-26.98	0.066
2.77	-26.87	0.066
2.79	-26.77	0.066
2.82	-26.66	0.066
2.84	-26.55	0.066
2.86	-26.44	0.066
2.88	-26.33	0.066
2.90	-26.22	0.066
2.93	-26.12	0.066
2.95	-26.01	0.066
2.97	-25.90	0.066
2.99	-25.79	0.066
3.01	-25.68	0.066
3.03	-25.57	0.066
3.06	-25.46	0.066
3.08	-25.36	0.066
3.10	-25.25	0.066
3.12	-25.14	0.066
3.14	-25.03	0.066
3.16	-24.92	0.066
3.19	-24.81	0.066
3.21	-24.71	0.066
3.23	-24.60	0.066
3.25	-24.49	0.066
3.27	-24.38	0.066
3.29	-24.27	0.066
3.31	-24.16	0.066
3.34	-24.06	0.066
3.36	-23.95	0.065
3.38	-23.84	0.065
3.40	-23.73	0.065
3.42	-23.62	0.066
3.44	-23.51	0.065
3.47	-23.40	0.065
3.49	-23.30	0.065
3.51	-23.19	0.065
3.53	-23.08	0.065
3.55	-22.97	0.065
3.58	-22.86	0.065
3.60	-22.75	0.065
3.62	-22.64	0.065
3.64	-22.54	0.065
3.66	-22.43	0.065
3.68	-22.32	0.065
3.71	-22.21	0.065
3.73	-22.10	0.065
3.75	-21.99	0.065
3.77	-21.89	0.065
3.79	-21.78	0.065
3.81	-21.67	0.065
3.84	-21.56	0.065
3.86	-21.45	0.065
3.88	-21.35	0.065
3.90	-21.24	0.065
3.92	-21.13	0.065
3.94	-21.02	0.065
3.96	-20.91	0.065
3.99	-20.80	0.065
4.01	-20.69	0.065
4.03	-20.59	0.065
4.05	-20.48	0.065
4.07	-20.37	0.065
4.09	-20.26	0.065
4.12	-20.15	0.065
4.14	-20.04	0.065
4.16	-19.94	0.065
4.18	-19.83	0.065
4.20	-19.72	0.065
4.23	-19.61	0.065
4.25	-19.50	0.065
4.27	-19.39	0.065
4.29	-19.29	0.065
4.31	-19.18	0.065
4.33	-19.07	0.065
4.35	-18.96	0.065
4.38	-18.85	0.065
4.40	-18.74	0.065
4.42	-18.63	0.065
4.44	-18.53	0.065
4.46	-18.42	0.065
4.49	-18.31	0.065
4.51	-18.20	0.065
4.53	-18.09	0.065
4.55	-17.98	0.065
4.57	-17.87	0.065
4.59	-17.77	0.065
4.61	-17.66	0.065
4.64	-17.55	0.065
4.66	-17.44	0.065
4.68	-17.33	0.065
4.70	-17.22	0.065
4.72	-17.12	0.065
4.75	-17.01	0.065
4.77	-16.90	0.065
4.79	-16.79	0.065
4.81	-16.68	0.065
4.83	-16.57	0.065
4.85	-16.47	0.065
4.88	-16.36	0.065
4.90	-16.25	0.065
4.92	-16.14	0.065
4.94	-16.03	0.065
4.96	-15.92	0.065
4.98	-15.82	0.065
5.00	-15.71	0.065
5.03	-15.60	0.065
5.05	-15.49	0.065
5.07	-15.38	0.065
5.09	-15.27	0.065
5.11	-15.16	0.065
5.14	-15.06	0.065
5.16	-14.95	0.065
5.18	-14.84	0.065
5.20	-14.73	0.065
5.22	-14.62	0.065
5.24	-14.51	0.065
5.26	-14.41	0.065
5.29	-14.30	0.065
5.31	-14.19	0.065
5.33	-14.08	0.065
5.35	-13.97	0.065
5.37	-13.86	0.065
5.40	-13.75	0.065
5.42	-13.65	0.065
5.44	-13.54	0.065
5.46	-13.43	0.065
5.48	-13.32	0.065
5.50	-13.21	0.065
5.53	-13.11	0.065
5.55	-13.00	0.065
5.57	-12.89	0.065
5.59	-12.78	0.065
5.61	-12.67	0.065
5.63	-12.56	0.065
5.65	-12.45	0.065
5.68	-12.34	0.065
5.70	-12.24	0.065
5.72	-12.13	0.065
5.74	-12.02	0.065
5.76	-11.91	0.065
5.79	-11.80	0.065
5.81	-11.70	0.065
5.83	-11.59	0.065
5.85	-11.48	0.065
5.87	-11.37	0.065
5.89	-11.26	0.065
5.91	-11.15	0.065
5.94	-11.04	0.065
5.96	-10.94	0.065
5.98	-10.83	0.065
6.00	-10.72	0.065
6.02	-10.61	0.065
6.05	-10.50	0.065
6.07	-10.39	0.065
6.09	-10.29	0.065
6.11	-10.18	0.065
6.13	-10.07	0.065
6.15	-9.96	0.065
6.18	-9.85	0.065
6.20	-9.74	0.065
6.22	-9.64	0.065
6.24	-9.53	0.065
6.26	-9.42	0.065
6.28	-9.31	0.065
6.30	-9.20	0.065
6.33	-9.09	0.065
6.35	-8.99	0.065
6.37	-8.88	0.065
6.39	-8.77	0.065
6.41	-8.66	0.065
6.44	-8.55	0.065
6.46	-8.44	0.065
6.48	-8.34	0.065
6.50	-8.23	0.065
6.52	-8.12	0.065
6.54	-8.01	0.066
6.56	-7.90	0.066
6.59	-7.79	0.066
6.61	-7.69	0.066
6.63	-7.58	0.066
6.65	-7.47	0.066
6.67	-7.36	0.066
6.70	-7.25	0.066
6.72	-7.14	0.066
6.74	-7.03	0.066
6.76	-6.92	0.066
6.78	-6.82	0.066
6.80	-6.71	0.066
6.83	-6.60	0.066
6.85	-6.49	0.066
6.87	-6.38	0.066
6.89	-6.28	0.066
6.91	-6.17	0.066
6.93	-6.06	0.066
6.95	-5.95	0.066
6.98	-5.84	0.066
7.00	-5.73	0.066
7.02	-5.63	0.066
7.04	-5.52	0.066
7.06	-5.41	0.066
7.09	-5.30	0.066
7.11	-5.19	0.066
7.13	-5.08	0.066
7.15	-4.97	0.066
7.17	-4.87	0.066
7.19	-4.76	0.066
7.21	-4.65	0.066
7.24	-4.54	0.066
7.26	-4.43	0.066
7.28	-4.32	0.066
7.30	-4.22	0.066
7.32	-4.11	0.066
7.35	-4.00	0.066
7.37	-3.89	0.066
7.39	-3.78	0.066
7.41	-3.67	0.066
7.43	-3.56	0.066
7.45	-3.46	0.066
7.48	-3.35	0.066
7.50	-3.24	0.066
7.52	-3.13	0.066
7.54	-3.02	0.067
7.56	-2.92	0.067
7.58	-2.81	0.067
7.60	-2.70	0.067
7.63	-2.59	0.067
7.65	-2.48	0.067
7.67	-2.37	0.067
7.69	-2.26	0.067
7.71	-2.16	0.067
7.74	-2.05	0.067
7.76	-1.94	0.067
7.78	-1.83	0.067
7.80	-1.72	0.067
7.82	-1.61	0.067
7.84	-1.51	0.067
7.86	-1.40	0.067
7.89	-1.29	0.067
7.91	-1.18	0.067
7.93	-1.07	0.067
7.95	-0.96	0.067
7.97	-0.86	0.067
8.00	-0.75	0.067
8.02	-0.64	0.067
8.04	-0.53	0.067
8.06	-0.42	0.067
8.08	-0.31	0.067
8.10	-0.20	0.067
8.13	-0.10	0.067
8.15	0.01	0.067
8.17	0.12	0.067
8.19	0.23	0.067
8.21	0.34	0.067
8.23	0.45	0.067
8.25	0.55	0.067
8.28	0.66	0.067
8.30	0.77	0.067
8.32	0.88	0.067
8.34	0.99	0.067
8.36	1.10	0.067
8.39	1.21	0.067
8.41	1.31	0.067
8.43	1.42	0.067
8.45	1.53	0.067
8.47	1.64	0.068
8.49	1.75	0.068
8.51	1.86	0.068
8.54	1.96	0.068
8.56	2.07	0.068
8.58	2.18	0.068
8.60	2.29	0.068
8.62	2.40	0.068
8.65	2.51	0.068
8.67	2.62	0.068
8.69	2.72	0.068
8.71	2.83	0.068
8.73	2.94	0.068
8.75	3.05	0.068
8.78	3.16	0.068
8.80	3.26	0.068
8.82	3.37	0.068
8.84	3.48	0.068
8.86	3.59	0.068
8.88	3.70	0.068
8.90	3.81	0.068
8.93	3.91	0.068
8.95	4.02	0.068
8.97	4.13	0.068
8.99	4.24	0.068
9.01	4.35	0.068
9.03	4.46	0.068
9.06	4.57	0.068
9.08	4.67	0.068
9.10	4.78	0.068
9.12	4.89	0.068
9.14	5.00	0.068
9.17	5.11	0.068
9.19	5.22	0.068
9.21	5.32	0.068
9.23	5.43	0.068
9.25	5.54	0.068
9.27	5.65	0.068
9.30	5.76	0.068
9.32	5.87	0.068
9.34	5.98	0.068
9.36	6.08	0.068
9.38	6.19	0.068
9.40	6.30	0.068
9.43	6.41	0.068
9.45	6.52	0.068
9.47	6.63	0.068
9.49	6.73	0.068
9.51	6.84	0.068
9.53	6.95	0.069
9.55	7.06	0.069
9.58	7.17	0.069
9.60	7.27	0.069
9.62	7.38	0.069
9.64	7.49	0.069
9.66	7.60	0.069
9.68	7.71	0.069
9.71	7.82	0.069
9.73	7.93	0.069
9.75	8.03	0.069
9.77	8.14	0.069
9.79	8.25	0.069
9.82	8.36	0.069
9.84	8.47	0.069
9.86	8.57	0.069
9.88	8.68	0.069
9.90	8.79	0.069
9.92	8.90	0.069
9.95	9.01	0.069
9.97	9.12	0.069
9.99	9.23	0.069
10.01	9.33	0.069
10.03	9.44	0.069
10.05	9.55	0.069
10.08	9.66	0.069
10.10	9.77	0.069
10.12	9.88	0.069
10.14	9.98	0.069
10.16	10.09	0.069
10.18	10.20	0.069
10.20	10.31	0.069
10.23	10.42	0.069
10.25	10.52	0.069
10.27	10.63	0.069
10.29	10.74	0.070
10.31	10.85	0.070
10.33	10.96	0.069
10.36	11.07	0.069
10.38	11.18	0.069
10.40	11.29	0.070
10.42	11.40	0.070
10.44	11.50	0.070
10.47	11.61	0.070
10.49	11.72	0.070
10.51	11.83	0.070
10.53	11.94	0.070
10.55	12.04	0.070
10.57	12.15	0.070
10.60	12.26	0.070
10.62	12.37	0.070
10.64	12.48	0.070
10.66	12.59	0.070
10.68	12.70	0.070
10.70	12.80	0.070
10.73	12.91	0.070
10.75	13.02	0.070
10.77	13.13	0.070
10.79	13.24	0.070
10.81	13.35	0.070
10.83	13.45	0.070
10.85	13.56	0.070
10.88	13.67	0.070
10.90	13.78	0.070
10.92	13.89	0.071
10.94	14.00	0.071
10.96	14.10	0.071
10.98	14.21	0.071
11.01	14.32	0.071
11.03	14.43	0.071
11.05	14.54	0.071
11.07	14.65	0.071
11.09	14.75	0.071
11.12	14.86	0.071
11.14	14.97	0.071
11.16	15.08	0.071
11.18	15.19	0.071
11.20	15.30	0.071
11.22	15.40	0.071
11.25	15.51	0.071
11.27	15.62	0.071
11.29	15.73	0.071
11.31	15.84	0.071
11.33	15.95	0.071
11.35	16.06	0.071
11.38	16.16	0.071
11.40	16.27	0.071
11.42	16.38	0.071
11.44	16.49	0.071
11.46	16.60	0.071
11.48	16.71	0.071
11.50	16.82	0.071
11.53	16.92	0.071
11.55	17.03	0.071
11.57	17.14	0.071
11.59	17.25	0.072
11.61	17.36	0.072
11.63	17.46	0.072
11.66	17.57	0.072
11.68	17.68	0.072
11.70	17.79	0.072
11.72	17.90	0.072
11.74	18.01	0.072
11.77	18.12	0.072
11.79	18.22	0.072
11.81	18.33	0.072
11.83	18.44	0.072
11.85	18.55	0.072
11.87	18.66	0.072
11.90	18.77	0.072
11.92	18.88	0.072
11.94	18.98	0.072
11.96	19.09	0.072
11.98	19.20	0.072
12.00	19.31	0.072
12.03	19.42	0.072
12.05	19.53	0.072
12.07	19.63	0.072
12.09	19.74	0.072
12.11	19.85	0.072
12.13	19.96	0.072
12.15	20.07	0.072
12.18	20.18	0.072
12.20	20.28	0.072
12.22	20.39	0.072
12.24	20.50	0.072
12.26	20.61	0.072
12.28	20.72	0.072
12.31	20.83	0.072
12.33	20.93	0.072
12.35	21.04	0.072
12.37	21.15	0.072
12.39	21.26	0.072
12.42	21.37	0.073
12.44	21.48	0.073
12.46	21.58	0.073
12.48	21.69	0.073
12.50	21.80	0.073
12.52	21.91	0.073
12.55	22.02	0.073
12.57	22.13	0.073
12.59	22.23	0.073
12.61	22.34	0.073
12.63	22.45	0.073
12.65	22.56	0.073
12.68	22.67	0.073
12.70	22.78	0.073
12.72	22.89	0.073
12.74	22.99	0.073
12.76	23.10	0.073
12.78	23.21	0.073
12.80	23.32	0.073
12.83	23.43	0.073
12.85	23.54	0.073
12.87	23.64	0.073
12.89	23.75	0.073
12.91	23.86	0.073
12.93	23.97	0.073
12.96	24.08	0.073
12.98	24.18	0.073
13.00	24.29	0.073
13.02	24.40	0.073
13.04	24.51	0.074
13.07	24.62	0.074
13.09	24.73	0.074
13.11	24.84	0.074
13.13	24.94	0.074
13.15	25.05	0.074
13.17	25.16	0.074
13.20	25.27	0.074
13.22	25.38	0.074
13.24	25.49	0.074
13.26	25.59	0.074
13.28	25.70	0.074
13.30	25.81	0.074
13.33	25.92	0.074
13.35	26.03	0.074
13.37	26.14	0.074
13.39	26.24	0.074
13.41	26.35	0.074
13.43	26.46	0.074
13.45	26.57	0.074
13.48	26.68	0.074
13.50	26.79	0.074
13.52	26.90	0.074
13.54	27.00	0.074
13.56	27.11	0.074
13.58	27.22	0.074
13.61	27.33	0.074
13.63	27.44	0.074
13.65	27.55	0.074
13.67	27.66	0.074
13.69	27.76	0.075
13.72	27.87	0.075
13.74	27.98	0.075
13.76	28.09	0.075
13.78	28.20	0.075
13.80	28.31	0.075
13.82	28.41	0.075
13.85	28.52	0.075
13.87	28.63	0.075
13.89	28.74	0.075
13.91	28.85	0.075
13.93	28.95	0.075
13.95	29.06	0.075
13.98	29.17	0.075
14.00	29.28	0.075
14.02	29.39	0.075
14.04	29.50	0.075
14.06	29.61	0.075
14.08	29.71	0.076
14.10	29.82	0.076
14.13	29.93	0.076
14.15	30.04	0.076
14.17	30.15	0.076
14.19	30.26	0.076
14.21	30.36	0.076
14.23	30.47	0.076
14.26	30.58	0.076
14.28	30.69	0.076
14.30	30.80	0.076
14.32	30.91	0.076
14.34	31.01	0.076
14.37	31.12	0.076
14.39	31.23	0.076
14.41	31.34	0.077
14.43	31.45	0.077
14.45	31.56	0.077
14.47	31.66	0.077
14.50	31.77	0.077
14.52	31.88	0.077
14.54	31.99	0.077
14.56	32.10	0.077
14.58	32.21	0.077
14.60	32.31	0.077
14.63	32.42	0.077
14.65	32.53	0.077
14.67	32.64	0.077
14.69	32.75	0.077
14.71	32.86	0.077
14.73	32.97	0.077
14.75	33.08	0.078
14.78	33.18	0.078
14.80	33.29	0.078
14.82	33.40	0.078
14.84	33.51	0.078
14.86	33.62	0.078
14.88	33.72	0.078
14.91	33.83	0.078
14.93	33.94	0.078
14.95	34.05	0.078
14.97	34.16	0.078
14.99	34.27	0.078
15.02	34.37	0.078
15.04	34.48	0.078
15.06	34.59	0.078
15.08	34.70	0.078
15.10	34.81	0.078
15.12	34.92	0.078
15.15	35.02	0.078
15.17	35.13	0.078
15.19	35.24	0.078
15.21	35.35	0.078
15.23	35.46	0.078
15.25	35.57	0.078
15.28	35.67	0.079
15.30	35.78	0.079
15.32	35.89	0.079
15.34	36.00	0.079
15.36	36.11	0.079
15.38	36.22	0.079
15.40	36.33	0.079
15.43	36.44	0.079
15.45	36.54	0.079
15.47	36.65	0.079
15.49	36.76	0.079
15.51	36.87	0.079
15.53	36.98	0.079
15.56	37.09	0.079
15.58	37.19	0.079
15.60	37.30	0.079
15.62	37.41	0.079
15.64	37.52	0.079
15.67	37.63	0.079
15.69	37.74	0.079
15.71	37.84	0.079
15.73	37.95	0.080
15.75	38.06	0.080
15.77	38.17	0.080
15.80	38.28	0.080
15.82	38.39	0.080
15.84	38.49	0.080
15.86	38.60	0.080
15.88	38.71	0.080
15.90	38.82	0.080
15.93	38.93	0.080
15.95	39.04	0.080
15.97	39.14	0.080
15.99	39.25	0.080
16.01	39.36	0.080
16.03	39.47	0.080
16.05	39.58	0.080
16.08	39.69	0.080
16.10	39.79	0.080
16.12	39.90	0.080
16.14	40.01	0.080
16.16	40.12	0.080
16.18	40.23	0.080
16.21	40.34	0.080
16.23	40.44	0.080
16.25	40.55	0.081
16.27	40.66	0.081
16.29	40.77	0.081
16.32	40.88	0.081
16.34	40.99	0.081
16.36	41.10	0.081
16.38	41.20	0.081
16.40	41.31	0.081
16.42	41.42	0.081
16.45	41.53	0.081
16.47	41.64	0.081
16.49	41.75	0.081
16.51	41.85	0.081
16.53	41.96	0.081
16.55	42.07	0.081
16.58	42.18	0.081
16.60	42.29	0.081
16.62	42.39	0.082
16.64	42.50	0.082
16.66	42.61	0.082
16.68	42.72	0.082
16.70	42.83	0.082
16.73	42.94	0.082
16.75	43.05	0.082
16.77	43.15	0.082
16.79	43.26	0.082
16.81	43.37	0.082
16.83	43.48	0.082
16.86	43.59	0.082
16.88	43.70	0.082
16.90	43.80	0.082
16.92	43.91	0.082
16.94	44.02	0.082
16.97	44.13	0.082
16.99	44.24	0.082
17.01	44.35	0.082
17.03	44.46	0.082
17.05	44.56	0.082
17.07	44.67	0.082
17.09	44.78	0.083
17.12	44.89	0.083
17.14	45.00	0.083
17.16	45.11	0.083
17.18	45.21	0.083
17.20	45.32	0.083
17.23	45.43	0.083
17.25	45.54	0.083
17.27	45.65	0.083
17.29	45.76	0.083
17.31	45.86	0.083
17.33	45.97	0.083
17.36	46.08	0.083
17.38	46.19	0.083
17.40	46.30	0.083
17.42	46.41	0.083
17.44	46.51	0.083
17.46	46.62	0.083
17.48	46.73	0.084
17.51	46.84	0.084
17.53	46.95	0.084
17.55	47.06	0.084
17.57	47.16	0.084
17.59	47.27	0.084
17.62	47.38	0.084
17.64	47.49	0.084
17.66	47.60	0.084
17.68	47.71	0.084
17.70	47.82	0.084
17.72	47.92	0.084
17.74	48.03	0.084
17.77	48.14	0.084
17.79	48.25	0.084
17.81	48.36	0.084
17.83	48.47	0.084
17.85	48.58	0.084
17.88	48.68	0.085
17.90	48.79	0.085
17.92	48.90	0.085
17.94	49.01	0.085
17.96	49.12	0.085
17.98	49.22	0.085
18.01	49.33	0.085
18.03	49.44	0.085
18.05	49.55	0.085
18.07	49.66	0.085
18.09	49.77	0.085
18.11	49.87	0.085
18.13	49.98	0.085
18.16	50.09	0.085
18.18	50.20	0.085
18.20	50.31	0.085
18.22	50.42	0.085
18.24	50.53	0.085
18.27	50.63	0.085
18.29	50.74	0.085
18.31	50.85	0.085
18.33	50.96	0.085
18.35	51.07	0.085
18.37	51.18	0.085
18.39	51.28	0.085
18.42	51.39	0.085
18.44	51.50	0.086
18.46	51.61	0.086
18.48	51.72	0.086
18.50	51.83	0.086
18.53	51.94	0.086
18.55	52.04	0.086
18.57	52.15	0.086
18.59	52.26	0.086
18.61	52.37	0.086
18.63	52.48	0.086
18.66	52.59	0.086
18.68	52.69	0.087
18.70	52.80	0.087
18.72	52.91	0.087
18.74	53.02	0.087
18.76	53.13	0.087
18.78	53.24	0.087
18.81	53.34	0.087
18.83	53.45	0.087
18.85	53.56	0.087
18.87	53.67	0.087
18.89	53.78	0.087
18.92	53.88	0.087
18.94	53.99	0.087
18.96	54.10	0.087
18.98	54.21	0.087
19.00	54.32	0.087
19.02	54.43	0.087
19.04	54.54	0.087
19.07	54.65	0.087
19.09	54.75	0.087
19.11	54.86	0.088
19.13	54.97	0.088
19.15	55.08	0.088
19.18	55.19	0.088
19.20	55.29	0.088
19.22	55.40	0.088
19.24	55.51	0.088
19.26	55.62	0.088
19.28	55.73	0.088
19.31	55.84	0.088
19.33	55.94	0.088
19.35	56.05	0.088
19.37	56.16	0.088
19.39	56.27	0.088
19.41	56.38	0.088
19.43	56.49	0.089
19.46	56.59	0.089
19.48	56.70	0.089
19.50	56.81	0.089
19.52	56.92	0.089
19.54	57.03	0.089
19.57	57.14	0.089
19.59	57.25	0.089
19.61	57.35	0.089
19.63	57.46	0.089
19.65	57.57	0.089
19.67	57.68	0.089
19.69	57.79	0.089
19.72	57.90	0.090
19.74	58.00	0.090
19.76	58.11	0.090
19.78	58.22	0.090
19.80	58.33	0.090
19.83	58.44	0.090
19.85	58.54	0.090
19.87	58.65	0.090
19.89	58.76	0.090
19.91	58.87	0.090
19.93	58.98	0.090
19.96	59.09	0.090
19.98	59.19	0.090
20.00	59.30	0.091
20.02	59.41	0.091
20.04	59.52	0.091
20.06	59.63	0.091
20.08	59.74	0.091
20.11	59.85	0.091
20.13	59.95	0.091
20.15	60.06	0.091
20.17	60.17	0.091
20.19	60.28	0.091
20.22	60.39	0.092
20.24	60.50	0.092
20.26	60.60	0.092
20.28	60.71	0.092
20.30	60.82	0.092
20.32	60.93	0.092
20.34	61.04	0.092
20.37	61.15	0.092
20.39	61.26	0.093
20.41	61.36	0.093
20.43	61.47	0.093
20.45	61.58	0.093
20.48	61.69	0.093
20.50	61.80	0.093
20.52	61.91	0.093
20.54	62.02	0.093
20.56	62.12	0.094
20.58	62.23	0.094
20.61	62.34	0.094
20.63	62.45	0.094
20.65	62.55	0.094
20.67	62.66	0.094
20.69	62.77	0.094
20.71	62.88	0.095
20.73	62.99	0.095
20.76	63.10	0.095
20.78	63.21	0.095
20.80	63.31	0.095
20.82	63.42	0.095
20.84	63.53	0.096
20.87	63.64	0.096
20.89	63.75	0.096
20.91	63.86	0.096
20.93	63.96	0.096
20.95	64.07	0.097
20.97	64.18	0.097
20.99	64.29	0.097
21.02	64.40	0.097
21.04	64.50	0.098
21.06	64.61	0.098
21.08	64.72	0.098
21.10	64.83	0.098
21.13	64.94	0.098
21.15	65.05	0.099
21.17	65.15	0.099
21.19	65.26	0.099
21.21	65.37	0.099
21.23	65.48	0.100
21.26	65.59	0.100
21.28	65.70	0.100
21.30	65.81	0.100
21.32	65.91	0.101
21.34	66.02	0.101
21.36	66.13	0.101
21.38	66.24	0.101
21.41	66.35	0.102
21.43	66.45	0.102
21.45	66.56	0.102
21.47	66.67	0.103
21.49	66.78	0.103
21.52	66.89	0.103
21.54	67.00	0.104
21.56	67.10	0.104
21.58	67.21	0.104
21.60	67.32	0.105
21.62	67.43	0.105
21.64	67.54	0.106
21.67	67.65	0.106
21.69	67.76	0.107
21.71	67.86	0.107
21.73	67.97	0.108
21.75	68.08	0.108
21.78	68.19	0.109
21.80	68.30	0.109
21.82	68.41	0.110
21.84	68.51	0.110
21.86	68.62	0.111
21.88	68.73	0.112
21.91	68.84	0.112
21.93	68.95	0.113
21.95	69.05	0.114
21.97	69.16	0.115
21.99	69.27	0.116
22.01	69.38	0.117
22.03	69.49	0.118
22.06	69.59	0.119
22.08	69.70	0.120
22.10	69.81	0.121
22.12	69.92	0.122
22.14	70.03	0.124
22.17	70.14	0.126
22.19	70.24	0.128
22.21	70.35	0.130
22.23	70.46	0.131
22.25	70.57	0.133
22.27	70.67	0.135
22.29	70.78	0.137
22.32	70.89	0.139
22.34	71.00	0.142
22.36	71.11	0.145
22.38	71.21	0.148
22.40	71.32	0.152
22.43	71.43	0.155
22.45	71.54	0.159
22.47	71.64	0.163
22.49	71.75	0.167
22.51	71.86	0.171
22.53	71.97	0.177
22.56	72.07	0.182
22.58	72.18	0.185
22.60	72.29	0.192
22.62	72.40	0.200
22.64	72.50	0.205
22.66	72.61	0.213
22.68	72.72	0.220
22.71	72.82	0.227
22.73	72.93	0.236
22.75	73.03	0.245
22.77	73.14	0.254
22.79	73.25	0.266
22.82	73.35	0.279
22.84	73.46	0.290
22.86	73.57	0.304
22.88	73.67	0.319
22.90	73.77	0.334
22.92	73.88	0.353
22.94	73.99	0.372
22.97	74.09	0.392
22.99	74.19	0.418
23.01	74.29	0.442
23.03	74.40	0.471
23.05	74.50	0.505
23.08	74.60	0.539
23.10	74.70	0.582
23.12	74.80	0.632
23.14	74.89	0.687
23.16	74.99	0.753
23.18	75.08	0.830
23.21	75.17	0.917
23.23	75.26	1.007
23.25	75.35	1.106
23.27	75.43	1.202
23.29	75.52	1.305
23.31	75.60	1.404
23.33	75.69	1.513
23.36	75.77	1.623
23.38	75.85	1.686
23.40	75.94	1.744
23.42	76.03	1.803
23.44	76.12	1.863
23.47	76.21	1.936
23.49	76.30	2.016
23.51	76.39	2.124
23.53	76.47	2.166
23.55	76.57	2.187
23.57	76.66	2.198
23.59	76.77	2.143
23.62	76.88	2.030
23.64	77.00	1.883
23.66	77.14	1.720
23.68	77.28	1.544
23.70	77.42	1.366
23.73	77.57	1.170
23.75	77.72	0.984
23.77	77.88	0.807
23.79	78.03	0.648
23.81	78.18	0.526
23.83	78.32	0.438
23.86	78.46	0.374
23.88	78.60	0.324
23.90	78.73	0.287
23.92	78.85	0.253
23.94	78.97	0.228
23.96	79.09	0.208
23.98	79.21	0.191
24.01	79.32	0.176
24.03	79.44	0.166
24.05	79.55	0.157
24.07	79.66	0.152
24.09	79.77	0.146
24.12	79.88	0.141
24.14	79.99	0.138
24.16	80.10	0.135
24.18	80.21	0.133
24.20	80.32	0.131
24.22	80.43	0.130
24.24	80.54	0.129
24.27	80.65	0.129
24.29	80.76	0.128
24.31	80.87	0.127
24.33	80.97	0.127
24.35	81.08	0.126
24.38	81.19	0.126
24.40	81.30	0.125
24.42	81.41	0.125
24.44	81.52	0.125
24.46	81.63	0.124
24.48	81.73	0.124
24.51	81.84	0.124
24.53	81.95	0.124
24.55	82.06	0.123
24.57	82.17	0.123
24.59	82.28	0.123
24.61	82.38	0.123
24.63	82.49	0.122
24.66	82.60	0.122
24.68	82.71	0.122
24.70	82.82	0.122
24.72	82.93	0.122
24.74	83.04	0.122
24.77	83.14	0.122
24.79	83.25	0.122
24.81	83.36	0.122
24.83	83.47	0.122
24.85	83.58	0.121
24.87	83.69	0.121
24.89	83.79	0.121
24.92	83.90	0.121
24.94	84.01	0.121
24.96	84.12	0.121
24.98	84.23	0.121
25.00	84.34	0.121
25.03	84.44	0.121
25.05	84.55	0.121
25.07	84.66	0.121
25.09	84.77	0.121
25.11	84.88	0.121
25.13	84.99	0.121
25.16	85.09	0.121
25.18	85.20	0.121
25.20	85.31	0.121
25.22	85.42	0.121
25.24	85.53	0.121
25.26	85.64	0.121
25.28	85.74	0.121
25.31	85.85	0.121
25.33	85.96	0.121
25.35	86.07	0.121
25.37	86.18	0.121
25.39	86.29	0.121
25.42	86.40	0.121
25.44	86.51	0.121
25.46	86.61	0.121
25.48	86.72	0.121
25.50	86.83	0.122
25.52	86.94	0.122
25.54	87.05	0.122
25.57	87.16	0.122
25.59	87.26	0.122
25.61	87.37	0.122
25.63	87.48	0.122
25.65	87.59	0.122
25.68	87.70	0.122
25.70	87.81	0.122
25.72	87.91	0.122
25.74	88.02	0.122
25.76	88.13	0.122
25.78	88.24	0.122
25.81	88.35	0.122
25.83	88.45	0.122
25.85	88.56	0.122
25.87	88.67	0.122
25.89	88.78	0.122
25.91	88.89	0.122
25.93	89.00	0.122
25.96	89.10	0.122
25.98	89.21	0.122
26.00	89.32	0.122
26.02	89.43	0.122
26.04	89.54	0.122
26.07	89.65	0.122
26.09	89.75	0.122
26.11	89.86	0.122
26.13	89.97	0.122
26.15	90.08	0.122
26.17	90.19	0.122
26.19	90.30	0.123
26.22	90.40	0.123
26.24	90.51	0.123
26.26	90.62	0.123
26.28	90.73	0.123
26.30	90.84	0.123
26.33	90.95	0.123
26.35	91.06	0.123
26.37	91.16	0.123
26.39	91.27	0.123
26.41	91.38	0.123
26.43	91.49	0.123
26.46	91.60	0.123
26.48	91.71	0.123
26.50	91.81	0.123
26.52	91.92	0.123
26.54	92.03	0.123
26.56	92.14	0.123
26.58	92.25	0.123
26.61	92.36	0.123
26.63	92.46	0.123
26.65	92.57	0.123
26.67	92.68	0.123
26.69	92.79	0.123
26.72	92.90	0.123
26.74	93.01	0.123
26.76	93.11	0.123
26.78	93.22	0.124
26.80	93.33	0.124
26.82	93.44	0.124
26.84	93.55	0.124
26.87	93.66	0.124
26.89	93.76	0.124
26.91	93.87	0.124
26.93	93.98	0.124
26.95	94.09	0.124
26.98	94.20	0.124
27.00	94.31	0.124
27.02	94.42	0.124
27.04	94.52	0.124
27.06	94.63	0.124
27.08	94.74	0.124
27.11	94.85	0.124
27.13	94.96	0.124
27.15	95.06	0.124
27.17	95.17	0.124
27.19	95.28	0.124
27.21	95.39	0.124
27.23	95.50	0.124
27.26	95.61	0.125
27.28	95.71	0.125
27.30	95.83	0.125
27.32	95.93	0.125
27.34	96.04	0.125
27.37	96.15	0.125
27.39	96.26	0.125
27.41	96.37	0.125
27.43	96.48	0.125
27.45	96.58	0.125
27.47	96.69	0.125
27.49	96.80	0.125
27.52	96.91	0.125
27.54	97.02	0.125
27.56	97.13	0.125
27.58	97.23	0.125
27.60	97.34	0.125
27.63	97.45	0.125
27.65	97.56	0.125
27.67	97.67	0.125
27.69	97.78	0.125
27.71	97.88	0.125
27.73	97.99	0.125
27.76	98.10	0.125
27.78	98.21	0.125
27.80	98.32	0.125
27.82	98.43	0.125
27.84	98.53	0.125
27.86	98.64	0.125
27.88	98.75	0.125
27.91	98.86	0.126
27.93	98.97	0.126
27.95	99.08	0.126
27.97	99.18	0.126
27.99	99.29	0.126
28.02	99.40	0.126
28.04	99.51	0.126
28.06	99.62	0.126
28.08	99.73	0.126
28.10	99.83	0.126
28.12	99.94	0.126
28.14	100.05	0.126
28.17	100.16	0.126
28.19	100.27	0.126
28.21	100.38	0.126
28.23	100.48	0.126
28.25	100.59	0.126
28.28	100.70	0.126
28.30	100.81	0.126
28.32	100.92	0.126
28.34	101.03	0.126
28.36	101.14	0.126
28.38	101.24	0.126
28.41	101.35	0.126
28.43	101.46	0.126
28.45	101.57	0.126
28.47	101.68	0.126
28.49	101.78	0.126
28.51	101.89	0.127
28.53	102.00	0.127
28.56	102.11	0.127
28.58	102.22	0.127
28.60	102.33	0.127
28.62	102.44	0.127
28.64	102.54	0.127
28.67	102.65	0.127
28.69	102.76	0.127
28.71	102.87	0.127
28.73	102.98	0.127
28.75	103.09	0.127
28.77	103.19	0.127
28.79	103.30	0.127
28.82	103.41	0.127
28.84	103.52	0.127
28.86	103.63	0.127
28.88	103.74	0.127
28.90	103.84	0.127
28.93	103.95	0.127
28.95	104.06	0.127
28.97	104.17	0.127
28.99	104.28	0.127
29.01	104.39	0.127
29.03	104.49	0.128
29.06	104.60	0.127
29.08	104.71	0.128
29.10	104.82	0.128
29.12	104.93	0.128
29.14	105.04	0.128
29.16	105.14	0.128
29.18	105.25	0.128
29.21	105.36	0.128
29.23	105.47	0.128
29.25	105.58	0.128
29.27	105.69	0.128
29.29	105.80	0.128
29.32	105.90	0.128
29.34	106.01	0.128
29.36	106.12	0.128
29.38	106.23	0.128
29.40	106.34	0.128
29.42	106.45	0.128
29.44	106.55	0.128
29.47	106.66	0.128
29.49	106.77	0.128
29.51	106.88	0.128
29.53	106.99	0.128
29.55	107.10	0.128
29.58	107.20	0.129
29.60	107.31	0.129
29.62	107.42	0.129
29.64	107.53	0.129
29.66	107.64	0.129
29.68	107.75	0.129
29.71	107.85	0.129
29.73	107.96	0.129
29.75	108.07	0.129
29.77	108.18	0.129
29.79	108.29	0.129
29.81	108.40	0.129
29.83	108.51	0.129
29.86	108.61	0.129
29.88	108.72	0.129
29.90	108.83	0.129
29.92	108.94	0.129
29.94	109.05	0.129
29.97	109.15	0.129
29.99	109.26	0.129
30.01	109.37	0.129
30.03	109.48	0.129
30.05	109.59	0.129
30.07	109.70	0.129
30.09	109.81	0.129
30.12	109.91	0.129
30.14	110.02	0.129
30.16	110.13	0.129
30.18	110.24	0.129
30.20	110.35	0.129
30.23	110.45	0.129
30.25	110.56	0.130
30.27	110.67	0.129
30.29	110.78	0.130
30.31	110.89	0.130
30.33	111.00	0.130
30.36	111.11	0.130
30.38	111.21	0.130
30.40	111.32	0.130
30.42	111.43	0.130
30.44	111.54	0.130
30.46	111.65	0.130
30.48	111.76	0.130
30.51	111.86	0.130
30.53	111.97	0.130
30.55	112.08	0.130
30.57	112.19	0.130
30.59	112.30	0.130
30.62	112.41	0.130
30.64	112.51	0.130
30.66	112.62	0.130
30.68	112.73	0.130
30.70	112.84	0.130
30.72	112.95	0.130
30.74	113.06	0.130
30.77	113.16	0.130
30.79	113.27	0.130
30.81	113.38	0.130
30.83	113.49	0.131
30.85	113.60	0.131
30.88	113.71	0.131
30.90	113.81	0.131
30.92	113.92	0.131
30.94	114.03	0.131
30.96	114.14	0.131
30.98	114.25	0.131
31.01	114.36	0.131
31.03	114.46	0.131
31.05	114.57	0.131
31.07	114.68	0.131
31.09	114.79	0.131
31.11	114.90	0.131
31.13	115.01	0.131
31.16	115.12	0.131
31.18	115.22	0.131
31.20	115.33	0.131
31.22	115.44	0.131
31.24	115.55	0.131
31.27	115.66	0.131
31.29	115.77	0.131
31.31	115.87	0.131
31.33	115.98	0.131
31.35	116.09	0.131
31.37	116.20	0.131
31.39	116.31	0.131
31.42	116.41	0.131
31.44	116.52	0.132
31.46	116.63	0.132
31.48	116.74	0.132
31.50	116.85	0.132
31.53	116.96	0.132
31.55	117.06	0.132
31.57	117.17	0.132
31.59	117.28	0.132
31.61	117.39	0.132
31.63	117.50	0.132
31.66	117.61	0.132
31.68	117.72	0.132
31.70	117.82	0.132
31.72	117.93	0.132
31.74	118.04	0.132
31.76	118.15	0.132
31.78	118.26	0.132
31.81	118.37	0.132
31.83	118.48	0.132
31.85	118.58	0.132
31.87	118.69	0.132
31.89	118.80	0.133
31.92	118.91	0.133
31.94	119.02
31.96	119.13
31.98	119.23
31.99

[step]
Ramp 5.00 °C/min to -40.00 °C
Time	Temperature	Heat Flow (Normalized)
min	°C	W/g
32.99	120.10	-0.036
33.02	120.10	-0.037
33.04	120.10	-0.037
33.06	120.09	-0.033
33.08	120.06	-0.016
33.10	120.02	-0.014
33.12	119.97	-0.018
33.14	119.90	-0.056
33.17	119.83	-0.084
33.19	119.74	-0.109
33.21	119.66	-0.129
33.23	119.57	-0.147
33.25	119.47	-0.157
33.28	119.38	-0.167
33.30	119.28	-0.175
33.32	119.18	-0.183
33.34	119.08	-0.187
33.36	118.98	-0.191
33.38	118.87	-0.195
33.41	118.77	-0.197
33.43	118.67	-0.200
33.45	118.56	-0.201
33.47	118.46	-0.202
33.49	118.35	-0.204
33.51	118.25	-0.204
33.53	118.14	-0.205
33.56	118.03	-0.206
33.58	117.93	-0.206
33.60	117.82	-0.207
33.62	117.71	-0.208
33.64	117.61	-0.208
33.67	117.50	-0.208
33.69	117.39	-0.209
33.71	117.29	-0.209
33.73	117.18	-0.210
33.75	117.07	-0.210
33.77	116.97	-0.210
33.79	116.86	-0.211
33.82	116.75	-0.211
33.84	116.64	-0.211
33.86	116.53	-0.212
33.88	116.43	-0.212
33.90	116.32	-0.212
33.93	116.21	-0.212
33.95	116.10	-0.213
33.97	116.00	-0.213
33.99	115.89	-0.213
34.01	115.78	-0.213
34.03	115.67	-0.213
34.06	115.56	-0.213
34.08	115.46	-0.214
34.10	115.35	-0.213
34.12	115.24	-0.214
34.14	115.13	-0.214
34.16	115.03	-0.214
34.19	114.92	-0.214
34.21	114.81	-0.214
34.23	114.70	-0.214
34.25	114.59	-0.214
34.27	114.49	-0.214
34.29	114.38	-0.214
34.31	114.27	-0.214
34.34	114.16	-0.214
34.36	114.05	-0.214
34.38	113.95	-0.214
34.40	113.84	-0.214
34.42	113.73	-0.214
34.44	113.62	-0.214
34.47	113.51	-0.214
34.49	113.41	-0.214
34.51	113.30	-0.214
34.53	113.19	-0.214
34.55	113.08	-0.214
34.58	112.97	-0.214
34.60	112.86	-0.214
34.62	112.76	-0.214
34.64	112.65	-0.214
34.66	112.54	-0.214
34.68	112.43	-0.214
34.71	112.33	-0.214
34.73	112.22	-0.214
34.75	112.11	-0.214
34.77	112.00	-0.214
34.79	111.89	-0.214
34.81	111.78	-0.214
34.84	111.68	-0.214
34.86	111.57	-0.214
34.88	111.46	-0.214
34.90	111.35	-0.214
34.92	111.24	-0.214
34.94	111.13	-0.213
34.96	111.03	-0.213
34.99	110.92	-0.213
35.01	110.81	-0.213
35.03	110.70	-0.213
35.05	110.59	-0.213
35.07	110.48	-0.213
35.09	110.38	-0.213
35.12	110.27	-0.213
35.14	110.16	-0.213
35.16	110.05	-0.213
35.18	109.94	-0.213
35.20	109.83	-0.213
35.23	109.73	-0.213
35.25	109.62	-0.213
35.27	109.51	-0.213
35.29	109.40	-0.213
35.31	109.29	-0.213
35.33	109.19	-0.213
35.36	109.08	-0.212
35.38	108.97	-0.212
35.40	108.86	-0.212
35.42	108.75	-0.212
35.44	108.64	-0.212
35.46	108.54	-0.212
35.49	108.43	-0.212
35.51	108.32	-0.212
35.53	108.21	-0.212
35.55	108.10	-0.212
35.57	108.00	-0.212
35.59	107.89	-0.212
35.61	107.78	-0.212
35.64	107.67	-0.212
35.66	107.56	-0.212
35.68	107.45	-0.212
35.70	107.35	-0.212
35.72	107.24	-0.212
35.74	107.13	-0.212
35.77	107.02	-0.212
35.79	106.91	-0.212
35.81	106.80	-0.212
35.83	106.70	-0.211
35.85	106.59	-0.211
35.88	106.48	-0.211
35.90	106.37	-0.211
35.92	106.26	-0.211
35.94	106.15	-0.211
35.96	106.05	-0.211
35.98	105.94	-0.211
36.01	105.83	-0.211
36.03	105.72	-0.211
36.05	105.61	-0.211
36.07	105.50	-0.211
36.09	105.40	-0.211
36.11	105.29	-0.211
36.14	105.18	-0.211
36.16	105.07	-0.211
36.18	104.96	-0.211
36.20	104.86	-0.211
36.22	104.75	-0.211
36.24	104.64	-0.211
36.26	104.53	-0.210
36.29	104.42	-0.210
36.31	104.31	-0.210
36.33	104.21	-0.210
36.35	104.10	-0.210
36.37	103.99	-0.210
36.39	103.88	-0.210
36.42	103.77	-0.210
36.44	103.66	-0.210
36.46	103.56	-0.210
36.48	103.45	-0.210
36.50	103.34	-0.210
36.53	103.23	-0.210
36.55	103.12	-0.210
36.57	103.01	-0.210
36.59	102.91	-0.210
36.61	102.80	-0.210
36.63	102.69	-0.210
36.66	102.58	-0.210
36.68	102.47	-0.210
36.70	102.37	-0.209
36.72	102.26	-0.209
36.74	102.15	-0.209
36.76	102.04	-0.209
36.79	101.93	-0.209
36.81	101.82	-0.209
36.83	101.72	-0.209
36.85	101.61	-0.209
36.87	101.50	-0.209
36.89	101.39	-0.209
36.91	101.28	-0.209
36.94	101.17	-0.209
36.96	101.07	-0.209
36.98	100.96	-0.209
37.00	100.85	-0.209
37.02	100.74	-0.209
37.04	100.63	-0.209
37.07	100.53	-0.209
37.09	100.42	-0.209
37.11	100.31	-0.209
37.13	100.20	-0.208
37.15	100.09	-0.208
37.18	99.98	-0.208
37.20	99.87	-0.208
37.22	99.77	-0.208
37.24	99.66	-0.208
37.26	99.55	-0.208
37.28	99.44	-0.208
37.31	99.33	-0.208
37.33	99.23	-0.208
37.35	99.12	-0.208
37.37	99.01	-0.208
37.39	98.90	-0.208
37.41	98.79	-0.208
37.44	98.68	-0.208
37.46	98.58	-0.208
37.48	98.47	-0.208
37.50	98.36	-0.208
37.52	98.25	-0.208
37.54	98.14	-0.208
37.56	98.03	-0.208
37.59	97.93	-0.208
37.61	97.82	-0.208
37.63	97.71	-0.208
37.65	97.60	-0.207
37.67	97.49	-0.208
37.69	97.39	-0.208
37.72	97.28	-0.207
37.74	97.17	-0.207
37.76	97.06	-0.207
37.78	96.95	-0.207
37.80	96.84	-0.207
37.83	96.74	-0.207
37.85	96.63	-0.207
37.87	96.52	-0.207
37.89	96.41	-0.207
37.91	96.30	-0.207
37.93	96.19	-0.207
37.96	96.09	-0.207
37.98	95.98	-0.207
38.00	95.87	-0.207
38.02	95.76	-0.207
38.04	95.65	-0.207
38.06	95.54	-0.207
38.09	95.44	-0.207
38.11	95.33	-0.207
38.13	95.22	-0.207
38.15	95.11	-0.207
38.17	95.00	-0.207
38.19	94.90	-0.207
38.21	94.79	-0.207
38.24	94.68	-0.206
38.26	94.57	-0.206
38.28	94.46	-0.206
38.30	94.35	-0.206
38.32	94.25	-0.206
38.34	94.14	-0.206
38.37	94.03	-0.206
38.39	93.92	-0.206
38.41	93.81	-0.206
38.43	93.70	-0.206
38.45	93.60	-0.206
38.48	93.49	-0.206
38.50	93.38	-0.206
38.52	93.27	-0.206
38.54	93.16	-0.206
38.56	93.05	-0.206
38.58	92.95	-0.206
38.61	92.84	-0.206
38.63	92.73	-0.206
38.65	92.62	-0.206
38.67	92.51	-0.206
38.69	92.41	-0.206
38.71	92.30	-0.205
38.74	92.19	-0.205
38.76	92.08	-0.205
38.78	91.97	-0.205
38.80	91.86	-0.205
38.82	91.75	-0.205
38.84	91.65	-0.205
38.86	91.54	-0.205
38.89	91.43	-0.205
38.91	91.32	-0.205
38.93	91.21	-0.205
38.95	91.11	-0.205
38.97	91.00	-0.205
38.99	90.89	-0.205
39.02	90.78	-0.205
39.04	90.67	-0.205
39.06	90.56	-0.205
39.08	90.45	-0.205
39.10	90.35	-0.205
39.13	90.24	-0.205
39.15	90.13	-0.204
39.17	90.02	-0.204
39.19	89.91	-0.204
39.21	89.81	-0.204
39.23	89.70	-0.204
39.26	89.59	-0.204
39.28	89.48	-0.204
39.30	89.37	-0.204
39.32	89.27	-0.204
39.34	89.16	-0.204
39.36	89.05	-0.204
39.39	88.94	-0.204
39.41	88.83	-0.204
39.43	88.72	-0.204
39.45	88.61	-0.204
39.47	88.51	-0.204
39.49	88.40	-0.204
39.51	88.29	-0.204
39.54	88.18	-0.203
39.56	88.07	-0.203
39.58	87.97	-0.203
39.60	87.86	-0.203
39.62	87.75	-0.203
39.64	87.64	-0.203
39.67	87.53	-0.203
39.69	87.42	-0.203
39.71	87.32	-0.203
39.73	87.21	-0.203
39.75	87.10	-0.203
39.78	86.99	-0.203
39.80	86.88	-0.203
39.82	86.77	-0.203
39.84	86.67	-0.203
39.86	86.56	-0.203
39.88	86.45	-0.203
39.91	86.34	-0.203
39.93	86.23	-0.203
39.95	86.13	-0.203
39.97	86.02	-0.203
39.99	85.91	-0.203
40.01	85.80	-0.203
40.04	85.69	-0.203
40.06	85.58	-0.203
40.08	85.47	-0.203
40.10	85.37	-0.203
40.12	85.26	-0.203
40.14	85.15	-0.203
40.16	85.04	-0.203
40.19	84.93	-0.203
40.21	84.82	-0.203
40.23	84.72	-0.203
40.25	84.61	-0.203
40.27	84.50	-0.203
40.29	84.39	-0.203
40.32	84.28	-0.203
40.34	84.18	-0.202
40.36	84.07	-0.202
40.38	83.96	-0.202
40.40	83.85	-0.202
40.43	83.74	-0.202
40.45	83.63	-0.202
40.47	83.53	-0.202
40.49	83.42	-0.202
40.51	83.31	-0.202
40.53	83.20	-0.202
40.56	83.09	-0.202
40.58	82.99	-0.202
40.60	82.88	-0.202
40.62	82.77	-0.202
40.64	82.66	-0.202
40.66	82.55	-0.202
40.69	82.44	-0.202
40.71	82.34	-0.202
40.73	82.23	-0.202
40.75	82.12	-0.202
40.77	82.01	-0.202
40.79	81.90	-0.202
40.81	81.79	-0.202
40.84	81.69	-0.202
40.86	81.58	-0.202
40.88	81.47	-0.202
40.90	81.36	-0.202
40.92	81.25	-0.202
40.94	81.14	-0.202
40.97	81.04	-0.202
40.99	80.93	-0.202
41.01	80.82	-0.202
41.03	80.71	-0.202
41.05	80.60	-0.202
41.08	80.49	-0.202
41.10	80.39	-0.202
41.12	80.28	-0.202
[...]
141.35	5.99	0.116
141.37	6.10	0.115
141.40	6.21	0.115
141.42	6.32	0.115
141.44	6.42	0.115
141.46	6.53	0.114
141.48	6.64	0.114
141.50	6.75	0.114
141.53	6.86	0.114
141.55	6.97	0.114
141.57	7.08	0.114
141.59	7.18	0.114
141.61	7.29	0.114
141.63	7.40	0.114
141.65	7.51	0.114
141.68	7.62	0.114
141.70	7.73	0.113
141.72	7.84	0.113
141.74	7.94	0.113
141.76	8.05	0.113
141.78	8.16	0.113
141.81	8.27	0.113
141.83	8.38	0.113
141.85	8.49	0.113
141.87	8.59	0.113
141.89	8.70	0.113
141.92	8.81	0.113
141.94	8.92	0.113
141.96	9.03	0.113
141.98	9.14	0.113
142.00	9.24	0.113
142.02	9.35	0.113
142.05	9.46	0.113
142.07	9.57	0.113
142.09	9.68	0.113
142.11	9.79	0.113
142.13	9.90	0.113
142.15	10.00	0.113
142.18	10.11	0.113
142.20	10.22	0.113
142.22	10.33	0.113
142.24	10.44	0.113
142.26	10.55	0.113
142.28	10.65	0.113
142.30	10.76	0.113
142.33	10.87	0.113
142.35	10.98	0.113
142.37	11.09	0.113
142.39	11.20	0.113
142.41	11.30	0.113
142.43	11.41	0.113
142.46	11.52	0.113
142.48	11.63	0.113
142.50	11.74	0.113
142.52	11.85	0.113
142.54	11.95	0.113
142.57	12.06	0.113
142.59	12.17	0.113
142.61	12.28	0.113
142.63	12.39	0.113
142.65	12.50	0.113
142.67	12.60	0.113
142.70	12.71	0.113
142.72	12.82	0.113
142.74	12.93	0.113
142.76	13.04	0.114
142.78	13.15	0.114
142.80	13.26	0.114
142.83	13.36	0.114
142.85	13.47	0.114
142.87	13.58	0.114
142.89	13.69	0.114
142.91	13.80	0.114
142.93	13.91	0.114
142.95	14.01	0.114
142.98	14.12	0.114
143.00	14.23	0.114
143.02	14.34	0.114
143.04	14.45	0.114
143.06	14.56	0.114
143.08	14.66	0.114
143.11	14.77	0.114
143.13	14.88	0.114
143.15	14.99	0.114
143.17	15.10	0.114
143.19	15.21	0.114
143.22	15.31	0.114
143.24	15.42	0.114
143.26	15.53	0.114
143.28	15.64	0.114
143.30	15.75	0.114
143.32	15.86	0.114
143.35	15.97	0.114
143.37	16.07	0.114
143.39	16.18	0.114
143.41	16.29	0.114
143.43	16.40	0.114
143.45	16.51	0.114
143.48	16.62	0.114
143.50	16.72	0.114
143.52	16.83	0.114
143.54	16.94	0.114
143.56	17.05	0.114
143.58	17.16	0.114
143.60	17.27	0.114
143.63	17.37	0.114
143.65	17.48	0.114
143.67	17.59	0.114
143.69	17.70	0.114
143.71	17.81	0.114
143.73	17.92	0.114
143.76	18.02	0.114
143.78	18.13	0.114
143.80	18.24	0.115
143.82	18.35	0.115
143.84	18.46	0.115
143.87	18.57	0.115
143.89	18.68	0.115
143.91	18.79	0.115
143.93	18.89	0.115
143.95	19.00	0.115
143.97	19.11	0.115
144.00	19.22	0.115
144.02	19.33	0.115
144.04	19.43	0.115
144.06	19.54	0.115
144.08	19.65	0.115
144.10	19.76	0.115
144.13	19.87	0.115
144.15	19.98	0.115
144.17	20.08	0.115
144.19	20.19	0.115
144.21	20.30	0.115
144.23	20.41	0.115
144.25	20.52	0.115
144.28	20.63	0.115
144.30	20.73	0.115
144.32	20.84	0.115
144.34	20.95	0.115
144.36	21.06	0.115
144.38	21.17	0.115
144.41	21.28	0.115
144.43	21.39	0.115
144.45	21.50	0.115
144.47	21.60	0.115
144.49	21.71	0.115
144.52	21.82	0.115
144.54	21.93	0.115
144.56	22.04	0.115
144.58	22.14	0.115
144.60	22.25	0.115
144.62	22.36	0.115
144.65	22.47	0.115
144.67	22.58	0.115
144.69	22.69	0.116
144.71	22.80	0.115
144.73	22.90	0.115
144.75	23.01	0.115
144.78	23.12	0.115
144.80	23.23	0.115
144.82	23.34	0.115
144.84	23.45	0.115
144.86	23.55	0.115
144.88	23.66	0.116
144.90	23.77	0.116
144.93	23.88	0.116
144.95	23.99	0.116
144.97	24.10	0.116
144.99	24.20	0.116
145.01	24.31	0.116
145.03	24.42	0.116
145.06	24.53	0.116
145.08	24.64	0.116
145.10	24.75	0.116
145.12	24.85	0.116
145.14	24.96	0.116
145.17	25.07	0.116
145.19	25.18	0.116
145.21	25.29	0.116
145.23	25.40	0.116
145.25	25.51	0.116
145.27	25.61	0.116
145.30	25.72	0.116
145.32	25.83	0.116
145.34	25.94	0.116
145.36	26.05	0.116
145.38	26.16	0.116
145.40	26.26	0.116
145.43	26.37	0.116
145.45	26.48	0.116
145.47	26.59	0.116
145.49	26.70	0.116
145.51	26.81	0.116
145.53	26.91	0.116
145.55	27.02	0.116
145.58	27.13	0.116
145.60	27.24	0.116
145.62	27.35	0.117
145.64	27.46	0.117
145.66	27.57	0.117
145.68	27.67	0.117
145.71	27.78	0.117
145.73	27.89	0.117
145.75	28.00	0.117
145.77	28.11	0.117
145.79	28.22	0.117
145.82	28.32	0.117
145.84	28.43	0.117
145.86	28.54	0.117
145.88	28.65	0.117
145.90	28.76	0.117
145.92	28.87	0.117
145.95	28.97	0.117
145.97	29.08	0.117
145.99	29.19	0.117
146.01	29.30	0.117
146.03	29.41	0.117
146.05	29.52	0.117
146.08	29.62	0.117
146.10	29.73	0.117
146.12	29.84	0.117
146.14	29.95	0.117
146.16	30.06	0.117
146.18	30.17	0.118
146.20	30.28	0.118
146.23	30.38	0.118
146.25	30.49	0.118
146.27	30.60	0.118
146.29	30.71	0.118
146.31	30.82	0.118
146.33	30.93	0.118
146.36	31.03	0.118
146.38	31.14	0.118
146.40	31.25	0.118
146.42	31.36	0.118
146.44	31.47	0.118
146.47	31.58	0.118
146.49	31.68	0.118
146.51	31.79	0.118
146.53	31.90	0.118
146.55	32.01	0.118
146.57	32.12	0.118
146.60	32.23	0.119
146.62	32.33	0.119
146.64	32.44	0.119
146.66	32.55	0.119
146.68	32.66	0.119
146.70	32.77	0.119
146.73	32.88	0.119
146.75	32.99	0.119
146.77	33.10	0.119
146.79	33.20	0.119
146.81	33.31	0.119
146.83	33.42	0.119
146.85	33.53	0.119
146.88	33.64	0.119
146.90	33.74	0.119
146.92	33.85	0.119
146.94	33.96	0.119
146.96	34.07	0.119
146.98	34.18	0.119
147.01	34.29	0.119
147.03	34.39	0.119
147.05	34.50	0.119
147.07	34.61	0.119
147.09	34.72	0.119
147.12	34.83	0.119
147.14	34.94	0.119
147.16	35.05	0.119
147.18	35.15	0.119
147.20	35.26	0.119
147.22	35.37	0.119
147.25	35.48	0.119
147.27	35.59	0.119
147.29	35.69	0.119
147.31	35.80	0.119
147.33	35.91	0.119
147.35	36.02	0.119
147.38	36.13	0.119
147.40	36.24	0.119
147.42	36.35	0.119
147.44	36.45	0.120
147.46	36.56	0.120
147.48	36.67	0.120
147.50	36.78	0.120
147.53	36.89	0.120
147.55	37.00	0.120
147.57	37.10	0.120
147.59	37.21	0.120
147.61	37.32	0.120
147.63	37.43	0.120
147.66	37.54	0.120
147.68	37.65	0.120
147.70	37.76	0.120
147.72	37.86	0.120
147.74	37.97	0.120
147.77	38.08	0.120
147.79	38.19	0.120
147.81	38.30	0.120
147.83	38.41	0.120
147.85	38.51	0.120
147.87	38.62	0.120
147.90	38.73	0.120
147.92	38.84	0.120
147.94	38.95	0.120
147.96	39.06	0.120
147.98	39.16	0.120
148.00	39.27	0.120
148.03	39.38	0.120
148.05	39.49	0.120
148.07	39.60	0.120
148.09	39.71	0.120
148.11	39.82	0.120
148.13	39.92	0.120
148.15	40.03	0.120
148.18	40.14	0.120
148.20	40.25	0.120
148.22	40.36	0.120
148.24	40.47	0.121
148.26	40.57	0.121
148.28	40.68	0.121
148.31	40.79	0.121
148.33	40.90	0.121
148.35	41.01	0.121
148.37	41.12	0.121
148.39	41.22	0.121
148.42	41.33	0.121
148.44	41.44	0.121
148.46	41.55	0.121
148.48	41.66	0.121
148.50	41.77	0.121
148.52	41.88	0.121
148.55	41.98	0.121
148.57	42.09	0.121
148.59	42.20	0.121
148.61	42.31	0.121
148.63	42.42	0.121
148.65	42.53	0.121
148.68	42.63	0.121
148.70	42.74	0.121
148.72	42.85	0.121
148.74	42.96	0.121
148.76	43.07	0.121
148.78	43.17	0.121
148.80	43.28	0.121
148.83	43.39	0.121
148.85	43.50	0.121
148.87	43.61	0.121
148.89	43.72	0.121
148.91	43.83	0.121
148.93	43.94	0.121
148.96	44.04	0.121
148.98	44.15	0.121
149.00	44.26	0.121
149.02	44.37	0.121
149.04	44.48	0.121
149.07	44.58	0.122
149.09	44.69	0.122
149.11	44.80	0.122
149.13	44.91	0.122
149.15	45.02	0.122
149.17	45.13	0.122
149.20	45.24	0.122
149.22	45.34	0.122
149.24	45.45	0.122
149.26	45.56	0.122
149.28	45.67	0.122
149.30	45.78	0.122
149.33	45.88	0.122
149.35	45.99	0.122
149.37	46.10	0.122
149.39	46.21	0.122
149.41	46.32	0.122
149.43	46.43	0.122
149.45	46.53	0.122
149.48	46.64	0.122
149.50	46.75	0.122
149.52	46.86	0.122
149.54	46.97	0.122
149.56	47.08	0.122
149.58	47.18	0.122
149.61	47.29	0.122
149.63	47.40	0.122
149.65	47.51	0.122
149.67	47.62	0.122
149.69	47.73	0.122
149.72	47.84	0.122
149.74	47.95	0.123
149.76	48.05	0.123
149.78	48.16	0.123
149.80	48.27	0.123
149.82	48.38	0.123
149.85	48.49	0.123
149.87	48.60	0.123
149.89	48.70	0.123
149.91	48.81	0.123
149.93	48.92	0.123
149.95	49.03	0.123
149.98	49.14	0.123
150.00	49.25	0.123
150.02	49.35	0.123
150.04	49.46	0.123
150.06	49.57	0.123
150.08	49.68	0.123
150.10	49.79	0.123
150.13	49.90	0.123
150.15	50.01	0.123
150.17	50.11	0.123
150.19	50.22	0.123
150.21	50.33	0.123
150.23	50.44	0.123
150.26	50.55	0.123
150.28	50.66	0.123
150.30	50.76	0.123
150.32	50.87	0.123
150.34	50.98	0.123
150.37	51.09	0.123
150.39	51.20	0.123
150.41	51.31	0.123
150.43	51.41	0.123
150.45	51.52	0.123
150.47	51.63	0.123
150.50	51.74	0.123
150.52	51.85	0.123
150.54	51.96	0.123
150.56	52.06	0.123
150.58	52.17	0.123
150.60	52.28	0.123
150.63	52.39	0.124
150.65	52.50	0.123
150.67	52.61	0.124
150.69	52.71	0.124
150.71	52.82	0.124
150.73	52.93	0.124
150.75	53.04	0.124
150.78	53.15	0.124
150.80	53.26	0.124
150.82	53.37	0.124
150.84	53.47	0.124
150.86	53.58	0.124
150.88	53.69	0.124
150.91	53.80	0.124
150.93	53.91	0.124
150.95	54.02	0.124
150.97	54.12	0.124
150.99	54.23	0.124
151.02	54.34	0.124
151.04	54.45	0.124
151.06	54.56	0.124
151.08	54.67	0.124
151.10	54.77	0.124
151.12	54.88	0.124
151.15	54.99	0.124
151.17	55.10	0.124
151.19	55.21	0.124
151.21	55.32	0.124
151.23	55.42	0.124
151.25	55.53	0.124
151.28	55.64	0.124
151.30	55.75	0.124
151.32	55.86	0.124
151.34	55.97	0.124
151.36	56.07	0.125
151.38	56.18	0.125
151.40	56.29	0.125
151.43	56.40	0.125
151.45	56.51	0.125
151.47	56.62	0.125
151.49	56.73	0.125
151.51	56.83	0.125
151.53	56.94	0.125
151.56	57.05	0.125
151.58	57.16	0.125
151.60	57.27	0.125
151.62	57.38	0.125
151.64	57.48	0.125
151.67	57.59	0.125
151.69	57.70	0.125
151.71	57.81	0.125
151.73	57.92	0.125
151.75	58.03	0.125
151.77	58.13	0.125
151.80	58.24	0.125
151.82	58.35	0.125
151.84	58.46	0.125
151.86	58.57	0.125
151.88	58.68	0.125
151.90	58.78	0.125
151.93	58.89	0.125
151.95	59.00	0.125
151.97	59.11	0.125
151.99	59.22	0.125
152.01	59.33	0.125
152.03	59.44	0.125
152.05	59.54	0.125
152.08	59.65	0.125
152.10	59.76	0.125
152.12	59.87	0.125
152.14	59.98	0.125
152.16	60.09	0.125
152.18	60.19	0.125
152.21	60.30	0.125
152.23	60.41	0.125
152.25	60.52	0.126
152.27	60.63	0.126
152.29	60.74	0.126
152.32	60.85	0.126
152.34	60.95	0.126
152.36	61.06	0.126
152.38	61.17	0.126
152.40	61.28	0.126
152.42	61.39	0.126
152.45	61.50	0.126
152.47	61.60	0.126
152.49	61.71	0.126
152.51	61.82	0.126
152.53	61.93	0.126
152.55	62.04	0.126
152.58	62.15	0.126
152.60	62.25	0.126
152.62	62.36	0.126
152.64	62.47	0.126
152.66	62.58	0.126
152.68	62.69	0.126
152.70	62.80	0.126
152.73	62.90	0.126
152.75	63.01	0.126
152.77	63.12	0.126
152.79	63.23	0.126
152.81	63.34	0.126
152.83	63.45	0.126
152.86	63.56	0.126
152.88	63.66	0.126
152.90	63.77	0.126
152.92	63.88	0.126
152.94	63.99	0.126
152.97	64.10	0.126
152.99	64.20	0.126
153.01	64.31	0.126
153.03	64.42	0.126
153.05	64.53	0.126
153.07	64.64	0.126
153.10	64.75	0.126
153.12	64.85	0.126
153.14	64.96	0.126
153.16	65.07	0.126
153.18	65.18	0.126
153.20	65.29	0.126
153.23	65.40	0.126
153.25	65.51	0.127
153.27	65.61	0.127
153.29	65.72	0.127
153.31	65.83	0.127
153.33	65.94	0.127
153.35	66.05	0.127
153.38	66.16	0.127
153.40	66.26	0.127
153.42	66.37	0.127
153.44	66.48	0.127
153.46	66.59	0.127
153.48	66.70	0.127
153.51	66.81	0.127
153.53	66.91	0.127
153.55	67.02	0.127
153.57	67.13	0.127
153.59	67.24	0.127
153.62	67.35	0.127
153.64	67.46	0.127
153.66	67.56	0.127
153.68	67.67	0.127
153.70	67.78	0.127
153.72	67.89	0.127
153.75	68.00	0.127
153.77	68.11	0.127
153.79	68.22	0.127
153.81	68.32	0.127
153.83	68.43	0.127
153.85	68.54	0.127
153.88	68.65	0.127
153.90	68.76	0.127
153.92	68.87	0.127
153.94	68.97	0.127
153.96	69.08	0.127
153.98	69.19	0.128
154.00	69.30	0.128
154.03	69.41	0.128
154.05	69.52	0.128
154.07	69.63	0.128
154.09	69.73	0.128
154.11	69.84	0.128
154.13	69.95	0.128
154.16	70.06	0.128
154.18	70.17	0.128
154.20	70.28	0.128
154.22	70.38	0.128
154.24	70.49	0.128
154.27	70.60	0.128
154.29	70.71	0.128
154.31	70.82	0.128
154.33	70.93	0.128
154.35	71.03	0.128
154.37	71.14	0.128
154.40	71.25	0.128
154.42	71.36	0.128
154.44	71.47	0.128
154.46	71.58	0.128
154.48	71.68	0.128
154.50	71.79	0.128
154.53	71.90	0.128
154.55	72.01	0.128
154.57	72.12	0.128
154.59	72.23	0.128
154.61	72.33	0.128
154.63	72.44	0.128
154.65	72.55	0.128
154.68	72.66	0.128
154.70	72.77	0.128
154.72	72.88	0.128
154.74	72.98	0.128
154.76	73.09	0.128
154.78	73.20	0.128
154.81	73.31	0.128
154.83	73.42	0.128
154.85	73.53	0.128
154.87	73.64	0.128
154.89	73.74	0.129
154.92	73.85	0.129
154.94	73.96	0.129
154.96	74.07	0.129
154.98	74.18	0.129
155.00	74.29	0.129
155.02	74.40	0.129
155.05	74.50	0.129
155.07	74.61	0.129
155.09	74.72	0.129
155.11	74.83	0.129
155.13	74.94	0.129
155.15	75.04	0.129
155.18	75.15	0.129
155.20	75.26	0.129
155.22	75.37	0.129
155.24	75.48	0.129
155.26	75.59	0.129
155.28	75.70	0.129
155.30	75.81	0.129
155.33	75.91	0.129
155.35	76.02	0.129
155.37	76.13	0.129
155.39	76.24	0.129
155.41	76.35	0.129
155.43	76.45	0.129
155.46	76.56	0.129
155.48	76.67	0.129
155.50	76.78	0.129
155.52	76.89	0.129
155.54	76.99	0.129
155.57	77.10	0.129
155.59	77.21	0.129
155.61	77.32	0.129
155.63	77.43	0.129
155.65	77.54	0.129
155.67	77.64	0.129
155.70	77.75	0.129
155.72	77.86	0.129
155.74	77.97	0.129
155.76	78.08	0.129
155.78	78.19	0.130
155.80	78.30	0.130
155.83	78.41	0.130
155.85	78.51	0.130
155.87	78.62	0.130
155.89	78.73	0.130
155.91	78.84	0.130
155.93	78.95	0.130
155.95	79.05	0.130
155.98	79.16	0.130
156.00	79.27	0.130
156.02	79.38	0.130
156.04	79.49	0.130
156.06	79.60	0.130
156.08	79.70	0.130
156.11	79.81	0.130
156.13	79.92	0.130
156.15	80.03	0.130
156.17	80.14	0.130
156.19	80.25	0.130
156.22	80.36	0.130
156.24	80.46	0.130
156.26	80.57	0.130
156.28	80.68	0.130
156.30	80.79	0.130
156.32	80.90	0.130
156.35	81.01	0.130
156.37	81.11	0.130
156.39	81.22	0.130
156.41	81.33	0.130
156.43	81.44	0.130
156.45	81.55	0.130
156.48	81.66	0.131
156.50	81.76	0.130
156.52	81.87	0.130
156.54	81.98	0.131
156.56	82.09	0.131
156.58	82.20	0.131
156.60	82.31	0.131
156.63	82.42	0.130
156.65	82.52	0.130
156.67	82.63	0.130
156.69	82.74	0.130
156.71	82.85	0.130
156.73	82.96	0.131
156.76	83.06	0.131
156.78	83.17	0.131
156.80	83.28	0.131
156.82	83.39	0.131
156.84	83.50	0.131
156.87	83.61	0.131
156.89	83.72	0.131
156.91	83.82	0.131
156.93	83.93	0.131
156.95	84.04	0.131
156.97	84.15	0.131
157.00	84.26	0.131
157.02	84.37	0.131
157.04	84.47	0.131
157.06	84.58	0.131
157.08	84.69	0.131
157.10	84.80	0.131
157.13	84.91	0.131
157.15	85.02	0.131
157.17	85.12	0.131
157.19	85.23	0.131
157.21	85.34	0.131
157.23	85.45	0.131
157.25	85.56	0.131
157.28	85.67	0.131
157.30	85.77	0.131
157.32	85.88	0.131
157.34	85.99	0.131
157.36	86.10	0.131
157.38	86.21	0.131
157.41	86.32	0.131
157.43	86.43	0.131
157.45	86.53	0.131
157.47	86.64	0.131
157.49	86.75	0.131
157.52	86.86	0.131
157.54	86.97	0.131
157.56	87.08	0.131
157.58	87.18	0.131
157.60	87.29	0.131
157.62	87.40	0.131
157.65	87.51	0.131
157.67	87.62	0.131
157.69	87.73	0.131
157.71	87.83	0.131
157.73	87.94	0.131
157.75	88.05	0.131
157.78	88.16	0.131
157.80	88.27	0.131
157.82	88.38	0.131
157.84	88.48	0.131
157.86	88.59	0.131
157.88	88.70	0.131
157.90	88.81	0.131
157.93	88.92	0.131
157.95	89.03	0.131
157.97	89.13	0.131
157.99	89.24	0.131
158.01	89.35	0.131
158.03	89.46	0.132
158.06	89.57	0.132
158.08	89.68	0.132
158.10	89.78	0.132
158.12	89.89	0.132
158.14	90.00	0.132
158.17	90.11	0.132
158.19	90.22	0.132
158.21	90.33	0.132
158.23	90.43	0.132
158.25	90.54	0.132
158.27	90.65	0.132
158.30	90.76	0.132
158.32	90.87	0.132
158.34	90.98	0.132
158.36	91.08	0.132
158.38	91.19	0.132
158.40	91.30	0.132
158.43	91.41	0.132
158.45	91.52	0.132
158.47	91.63	0.132
158.49	91.74	0.132
158.51	91.84	0.132
158.53	91.95	0.132
158.55	92.06	0.132
158.58	92.17	0.132
158.60	92.28	0.132
158.62	92.38	0.132
158.64	92.49	0.133
158.66	92.60	0.133
158.68	92.71	0.133
158.71	92.82	0.133
158.73	92.93	0.133
158.75	93.04	0.133
158.77	93.14	0.133
158.79	93.25	0.133
158.82	93.36	0.133
158.84	93.47	0.133
158.86	93.58	0.133
158.88	93.69	0.133
158.90	93.79	0.133
158.92	93.90	0.133
158.95	94.01	0.133
158.97	94.12	0.133
158.99	94.23	0.133
159.01	94.34	0.133
159.03	94.44	0.133
159.05	94.55	0.133
159.08	94.66	0.133
159.10	94.77	0.133
159.12	94.88	0.133
159.14	94.99	0.133
159.16	95.10	0.133
159.18	95.20	0.133
159.20	95.31	0.133
159.23	95.42	0.133
159.25	95.53	0.133
159.27	95.64	0.133
159.29	95.75	0.133
159.31	95.86	0.133
159.33	95.96	0.133
159.36	96.07	0.134
159.38	96.18	0.134
159.40	96.29	0.134
159.42	96.40	0.134
159.44	96.50	0.134
159.47	96.61	0.134
159.49	96.72	0.134
159.51	96.83	0.134
159.53	96.94	0.134
159.55	97.05	0.134
159.57	97.15	0.134
159.60	97.26	0.134
159.62	97.37	0.134
159.64	97.48	0.134
159.66	97.59	0.134
159.68	97.70	0.134
159.70	97.81	0.134
159.73	97.91	0.134
159.75	98.02	0.134
159.77	98.13	0.134
159.79	98.24	0.134
159.81	98.35	0.134
159.83	98.46	0.134
159.85	98.56	0.134
159.88	98.67	0.134
159.90	98.78	0.134
159.92	98.89	0.134
159.94	99.00	0.134
159.96	99.11	0.134
159.98	99.21	0.134
160.01	99.32	0.134
160.03	99.43	0.134
160.05	99.54	0.134
160.07	99.65	0.134
160.09	99.76	0.135
160.12	99.86	0.135
160.14	99.97	0.135
160.16	100.08	0.135
160.18	100.19	0.135
160.20	100.30	0.135
160.22	100.41	0.135
160.25	100.51	0.135
160.27	100.62	0.135
160.29	100.73	0.135
160.31	100.84	0.135
160.33	100.95	0.135
160.35	101.06	0.135
160.38	101.16	0.135
160.40	101.27	0.135
160.42	101.38	0.135
160.44	101.49	0.135
160.46	101.60	0.135
160.48	101.71	0.135
160.50	101.82	0.135
160.53	101.92	0.135
160.55	102.03	0.135
160.57	102.14	0.135
160.59	102.25	0.135
160.61	102.36	0.135
160.63	102.47	0.135
160.66	102.57	0.135
160.68	102.68	0.135
160.70	102.79	0.135
160.72	102.90	0.135
160.74	103.01	0.135
160.77	103.12	0.135
160.79	103.22	0.135
160.81	103.33	0.135
160.83	103.44	0.135
160.85	103.55	0.135
160.87	103.66	0.135
160.90	103.77	0.135
160.92	103.87	0.135
160.94	103.98	0.135
160.96	104.09	0.135
160.98	104.20	0.135
161.00	104.31	0.135
161.03	104.42	0.135
161.05	104.52	0.135
161.07	104.63	0.135
161.09	104.74	0.135
161.11	104.85	0.136
161.13	104.96	0.136
161.15	105.07	0.136
161.18	105.17	0.136
161.20	105.28	0.136
161.22	105.39	0.136
161.24	105.50	0.136
161.26	105.61	0.136
161.28	105.72	0.136
161.31	105.83	0.136
161.33	105.93	0.136
161.35	106.04	0.136
161.37	106.15	0.136
161.39	106.26	0.136
161.42	106.37	0.136
161.44	106.48	0.136
161.46	106.58	0.136
161.48	106.69	0.136
161.50	106.80	0.136
161.52	106.91	0.136
161.55	107.02	0.136
161.57	107.12	0.136
161.59	107.24	0.136
161.61	107.34	0.136
161.63	107.45	0.136
161.65	107.56	0.136
161.68	107.67	0.136
161.70	107.78	0.136
161.72	107.88	0.136
161.74	107.99	0.136
161.76	108.10	0.136
161.78	108.21	0.136
161.80	108.32	0.136
161.83	108.43	0.136
161.85	108.53	0.136
161.87	108.64	0.136
161.89	108.75	0.136
161.91	108.86	0.136
161.93	108.97	0.136
161.96	109.08	0.137
161.98	109.19	0.137
162.00	109.29	0.137
162.02	109.40	0.137
162.04	109.51	0.137
162.07	109.62	0.137
162.09	109.73	0.137
162.11	109.84	0.137
162.13	109.94	0.137
162.15	110.05	0.137
162.17	110.16	0.137
162.20	110.27	0.137
162.22	110.38	0.137
162.24	110.49	0.137
162.26	110.59	0.137
162.28	110.70	0.137
162.30	110.81	0.137
162.33	110.92	0.137
162.35	111.03	0.137
162.37	111.14	0.137
162.39	111.24	0.137
162.41	111.35	0.137
162.43	111.46	0.137
162.45	111.57	0.137
162.48	111.68	0.137
162.50	111.78	0.137
162.52	111.89	0.137
162.54	112.00	0.137
162.56	112.11	0.137
162.58	112.22	0.137
162.61	112.33	0.137
162.63	112.44	0.137
162.65	112.55	0.137
162.67	112.65	0.138
162.69	112.76	0.138
162.72	112.87	0.138
162.74	112.98	0.138
162.76	113.09	0.138
162.78	113.19	0.138
162.80	113.30	0.137
162.82	113.41	0.137
162.85	113.52	0.137
162.87	113.63	0.137
162.89	113.74	0.137
162.91	113.84	0.137
162.93	113.95	0.138
162.95	114.06	0.138
162.98	114.17	0.138
163.00	114.28	0.138
163.02	114.39	0.138
163.04	114.50	0.138
163.06	114.60	0.138
163.08	114.71	0.138
163.10	114.82	0.138
163.13	114.93	0.138
163.15	115.04	0.138
163.17	115.15	0.138
163.19	115.25	0.138
163.21	115.36	0.138
163.23	115.47	0.138
163.26	115.58	0.138
163.28	115.69	0.138
163.30	115.79	0.138
163.32	115.90	0.138
163.34	116.01	0.138
163.37	116.12	0.138
163.39	116.23	0.138
163.41	116.34	0.138
163.43	116.45	0.138
163.45	116.55	0.138
163.47	116.66	0.138
163.50	116.77	0.138
163.52	116.88	0.138
163.54	116.99	0.138
163.56	117.10	0.138
163.58	117.21	0.138
163.60	117.31	0.138
163.63	117.42	0.138
163.65	117.53	0.138
163.67	117.64	0.138
163.69	117.75	0.138
163.71	117.85	0.138
163.73	117.96	0.138
163.75	118.07	0.138
163.78	118.18	0.138
163.80	118.29	0.138
163.82	118.40	0.138
163.84	118.50	0.139
163.86	118.61	0.139
163.88	118.72	0.139
163.91	118.83	0.139
163.93	118.94	0.138
163.95	119.05
163.97	119.16
163.99