File: DSC/2025_05_20_CBN_Sorbic_Acid_MC_n60C_150C_5Cmin_x3.csv
Filename,2025_05_20_CBN_Sorbic_Acid_MC_n60C_150C_5Cmin_x3
Instrument name,DSC2A-00468 (192.168.1.100)
Operator,Yarger
rundate,5/21/2025
Sample name,2025_05_20_CBN_Sorbic_Acid_MC_n60C_150C_5Cmin_x3
proceduresegments,Data Off ; Equilibrate -60.00 °C; Data On ; Ramp 5.00 °C/min to 150.00 °C; Data Off ; Isothermal 1.0 min; Data On ; Ramp 5.00 °C/min to -60.00 °C; Data Off ; Isothermal 1.0 min; Data On ; Ramp 5.00 °C/min to 150.00 °C; Data Off ; Isothermal 1.0 min; Data On ; Ramp 5.00 °C/min to -60.00 °C; Data Off ; Isothermal 1.0 min; Data On ; Ramp 5.00 °C/min to 30.00 °C
[File Parameters]
Run date,5/21/2025 8:07:38 AM
Trios version,5.1.1.46572
Original File Name,
Current File Name,D:\DSC2500\JYarger\2025_05_20_CBN_Sorbic_Acid_MC_n60C_150C_5Cmin_x3.tri
[Procedure]
Procedure Name,CBN_SA_n60C_150C_5Cmin_x3
Sample Name,2025_05_20_CBN_Sorbic_Acid_MC_n60C_150C_5Cmin_x3
Sample Mass,4.68 mg
Reference Sample Mass,0 mg
Pan Mass,57.27 mg
Pan Number,49
Reference Pan Mass,57.13 mg
Reference Pan Number,37
Pan Type,Tzero Aluminum Hermetic
Comments,Al Hermetic DSC Consumables sealed Pan/Lid. Y2 Tray (Google Sheet: DSC_Samples_Vext_Y2_Tray_May2025)
Project Name,CA
Operator,Yarger
Test,Custom
Unload Max Temperature,30
Unload Min Temperature,30
Load Max Temperature,30
Load Min Temperature,30
Stop on Gas Flow Error,Yes
[Signal List]
Signal #1,Time (min)
Signal #2,Temperature (°C)
Signal #3,Heat Flow (mW)
Signal #4,Delta T (µV)
Signal #5,Delta Tzero (µV)
Signal #6,Tzero Temperature (°C)
Signal #7,Cell Purge (mL/min)
Signal #8,Heater Temp (°C)
Signal #9,Power Delivered (W)
Signal #10,Reference Junction Temperature (°C)
Signal #11,Flange Temperature (°C)
Signal #12,Heat Flow Phase (rad)
Signal #13,Total Heat Capacity (J/°C)
Signal #14,Heat Capacity (J/°C)
[Configuration]
Company Name,ASU
Instrument Name,DSC2A-00468
Instrument Type,DSC2500
Serial Number,DSC2A-00468
IP,192.168.1.100
Location of Instrument,MRRC
DisplayType,Unknown
Sample Interval ,0.1 s/pt
Selected Heat Flow,T4P
Exotherm Direction,Down
Cell Serial,DRC2-00792
Lid Type,Standard
Cooler,RCS 90
Leave Cooler on at End of Sequence,On
Gas 2,Nitrogen
Gas Selected,Channel 1
Flow Rate,50 mL/min
Secondary Purge,On
Licensed Heat Flow,Heat Flow T4P
Modulation Licensed,Yes
[Versions]
Common IDD Version,1
Cortex Version,VER 2.10.2.31
Driver,5.0.0.6
GDM Version,1.0.3.3
TouchscreenVersion,1.0.0.16145
FEP Version,1.2.1.21
FEP Bootloader,2.0.0.5
AutoSampler Version,2.1.1.26
Auto Sampler Bootloader,2.0.0.5
FCM Version,1.1.0.3
FCM Bootloader,2.0.0.5
[Experiment Logs]
Experiment Log Entry # 1,Data On set to 0
Experiment Log Entry # 3,Equilibrate Segment -60 (C) Started
Experiment Log Entry # 5,Air Cool is off.
Experiment Log Entry # 7,Data On set to 1
Experiment Log Entry # 9,Ramp Segment 5 C/min to 150 Started
Experiment Log Entry # 11,Data On set to 0
Experiment Log Entry # 13,Isothermal Segment 1 min started
Experiment Log Entry # 15,Data On set to 1
Experiment Log Entry # 17,Ramp Segment 5 C/min to -60 Started
Experiment Log Entry # 19,Data On set to 0
Experiment Log Entry # 21,Isothermal Segment 1 min started
Experiment Log Entry # 23,Data On set to 1
Experiment Log Entry # 25,Ramp Segment 5 C/min to 150 Started
Experiment Log Entry # 27,Data On set to 0
Experiment Log Entry # 29,Isothermal Segment 1 min started
Experiment Log Entry # 31,Data On set to 1
Experiment Log Entry # 33,Ramp Segment 5 C/min to -60 Started
Experiment Log Entry # 35,Data On set to 0
Experiment Log Entry # 37,Isothermal Segment 1 min started
Experiment Log Entry # 39,Data On set to 1
Experiment Log Entry # 41,Ramp Segment 5 C/min to 30 Started
[Method Log]
Method Log Entry # 1,Data Off
Method Log Entry # 2,Equilibrate -60 °C
Method Log Entry # 3,Data On
Method Log Entry # 4,(Ramp 215270) Ramp 5 °C/minute to 150 °C
Method Log Entry # 5,Data Off
Method Log Entry # 6,Isothermal 1 minutes
Method Log Entry # 7,Data On
Method Log Entry # 8,(Ramp 215274) Ramp 5 °C/minute to -60 °C
Method Log Entry # 9,Data Off
Method Log Entry # 10,Isothermal 1 minutes
Method Log Entry # 11,Data On
Method Log Entry # 12,(Ramp 215278) Ramp 5 °C/minute to 150 °C
Method Log Entry # 13,Data Off
Method Log Entry # 14,Isothermal 1 minutes
Method Log Entry # 15,Data On
Method Log Entry # 16,(Ramp 215282) Ramp 5 °C/minute to -60 °C
Method Log Entry # 17,Data Off
Method Log Entry # 18,Isothermal 1 minutes
Method Log Entry # 19,Data On
Method Log Entry # 20,(Ramp 215286) Ramp 5 °C/minute to 30 °C
Cell Serial,DRC2-00792
[T1 Calibration]
Slope,-0.008529666
Offset,9.636258
Initial Temperature,98.23
GUID,f8bfdadc-4977-4fdf-ba6d-0ba9134940c3
[TZero Calibration]
Date Applied,11/29/2022 4:06:13 PM
Description,From -89.059 °C to 396.009 °C at 20.000°C/min
Gas Type,Nitrogen
Pan Type,None
Source Files 1,C:\Users\yargerlab\Desktop\DSC Data\General\TZero_calibration_11_29_22_2nd(2).tri
Source Files 2,C:\Users\yargerlab\Desktop\DSC Data\General\TZero_calibration_11_29_22_2nd(3).tri
Delta T Offset,13.05235
Delta T Slope,-0.007271007
Delta T0 Offset,-13.69128
Delta T0 Slope,0.06063341
[Temperature Calibration]
Date Applied,11/29/2022 7:12:28 PM
Description,From 106.590 °C to 186.590 °C at 10.000°C/min
Gas Type,Nitrogen
Pan Type,Tzero Aluminum Hermetic
Source Files 1,C:\Users\yargerlab\Desktop\DSC Data\General\Indium(6).tri
Measured 1,157.391
Known 1,156.598
[Cell Constant Calibration]
Date Applied,11/29/2022 7:12:29 PM
Description,From 106.590 °C to 186.590 °C at 10.000°C/min
Gas Type,Nitrogen
Pan Type,Tzero Aluminum Hermetic
Source Files 1,C:\Users\yargerlab\Desktop\DSC Data\General\Indium(6).tri
T4P KCell,1.006051
Onset Slope,63.26126 mW/°C
[Direct Cp Calibration]
Date Applied,11/30/2022 11:04:51 AM
Description,From -79.983 °C to 298.409 °C at 10.000°C/min
Gas Type,Nitrogen
Pan Type,Tzero Aluminum Hermetic
Source Files 1,C:\Users\yargerlab\Desktop\DSC Data\General\Sapphire_Heat_Capacity_11_30_22.tri
[Rev Cp Calibration]
Date Applied,11/30/2022 1:58:51 PM
Description,From -79.996 °C to 292.812 °C at 3.000°C/min
Gas Type,Nitrogen
Pan Type,Tzero Aluminum Hermetic
Source Files 1,C:\Users\yargerlab\Desktop\DSC Data\General\Sapphire_MDSC_Calibration_11_30_22.tri
[step]
Ramp 5.00 °C/min to 150.00 °C
Time,Temperature,Heat Flow (Normalized)
min,°C,W/g
0.00,-59.68,-0.051
0.03,-59.70,-0.052
0.06,-59.71,-0.041
0.08,-59.69,-0.020
0.11,-59.64,0.000
0.14,-59.57,0.020
0.17,-59.47,0.037
0.20,-59.37,0.050
0.23,-59.26,0.060
0.26,-59.15,0.068
0.28,-59.03,0.075
0.31,-58.91,0.081
0.34,-58.79,0.086
0.37,-58.66,0.090
0.40,-58.54,0.093
0.43,-58.40,0.097
0.45,-58.27,0.098
0.48,-58.14,0.101
0.51,-58.00,0.102
0.54,-57.87,0.103
0.57,-57.73,0.104
0.60,-57.60,0.104
0.62,-57.46,0.105
0.65,-57.32,0.106
0.68,-57.19,0.106
0.71,-57.05,0.107
0.74,-56.91,0.107
0.77,-56.77,0.108
0.79,-56.63,0.108
0.82,-56.49,0.108
0.85,-56.35,0.109
0.88,-56.21,0.109
0.91,-56.08,0.110
0.93,-55.94,0.110
0.96,-55.80,0.110
0.99,-55.65,0.110
1.02,-55.51,0.110
1.05,-55.37,0.111
1.08,-55.24,0.111
1.11,-55.10,0.111
1.13,-54.95,0.111
1.16,-54.81,0.111
1.19,-54.67,0.111
1.22,-54.53,0.111
1.25,-54.39,0.112
1.28,-54.25,0.112
1.30,-54.11,0.112
1.33,-53.97,0.112
1.36,-53.83,0.112
1.39,-53.69,0.112
1.42,-53.55,0.112
1.44,-53.41,0.112
1.47,-53.26,0.112
1.50,-53.12,0.112
1.53,-52.98,0.112
1.56,-52.84,0.112
1.59,-52.70,0.112
1.62,-52.56,0.112
1.64,-52.42,0.112
1.67,-52.28,0.112
1.70,-52.14,0.112
1.73,-51.99,0.112
1.76,-51.85,0.112
1.78,-51.71,0.112
1.81,-51.57,0.112
1.84,-51.43,0.112
1.87,-51.29,0.112
1.90,-51.15,0.112
1.93,-51.01,0.112
1.96,-50.87,0.112
1.98,-50.72,0.112
2.01,-50.58,0.112
2.04,-50.44,0.112
2.07,-50.30,0.112
2.10,-50.16,0.112
2.13,-50.01,0.112
2.15,-49.87,0.112
2.18,-49.73,0.112
2.21,-49.59,0.112
2.24,-49.45,0.112
2.27,-49.31,0.112
2.29,-49.17,0.112
2.32,-49.02,0.112
2.35,-48.88,0.112
2.38,-48.74,0.112
2.41,-48.60,0.112
2.44,-48.46,0.112
2.46,-48.32,0.112
2.49,-48.18,0.112
2.52,-48.03,0.112
2.55,-47.89,0.112
2.58,-47.75,0.112
2.61,-47.61,0.112
2.64,-47.47,0.112
2.66,-47.33,0.112
2.69,-47.18,0.112
2.72,-47.04,0.112
2.75,-46.90,0.112
2.78,-46.76,0.112
2.81,-46.62,0.112
2.83,-46.48,0.112
2.86,-46.34,0.112
2.89,-46.20,0.112
2.92,-46.05,0.112
2.95,-45.91,0.112
2.98,-45.77,0.112
3.00,-45.63,0.112
3.03,-45.49,0.112
3.06,-45.35,0.112
3.09,-45.20,0.112
3.12,-45.06,0.112
3.14,-44.92,0.112
3.17,-44.78,0.112
3.20,-44.64,0.112
3.23,-44.49,0.112
3.26,-44.35,0.112
3.29,-44.21,0.112
3.31,-44.07,0.112
3.34,-43.93,0.112
3.37,-43.79,0.112
3.40,-43.64,0.112
3.43,-43.50,0.112
3.46,-43.36,0.112
3.49,-43.22,0.112
3.51,-43.08,0.112
3.54,-42.94,0.112
3.57,-42.79,0.112
3.60,-42.65,0.112
3.63,-42.51,0.112
3.66,-42.37,0.112
3.68,-42.23,0.112
3.71,-42.09,0.112
3.74,-41.94,0.112
3.77,-41.80,0.112
3.80,-41.66,0.112
3.83,-41.52,0.112
3.85,-41.38,0.112
3.88,-41.23,0.112
3.91,-41.09,0.112
3.94,-40.95,0.112
3.97,-40.81,0.112
3.99,-40.67,0.112
4.02,-40.52,0.112
4.05,-40.38,0.112
4.08,-40.24,0.112
4.11,-40.10,0.112
4.14,-39.96,0.113
4.16,-39.82,0.113
4.19,-39.67,0.113
4.22,-39.53,0.113
4.25,-39.39,0.113
4.28,-39.25,0.113
4.31,-39.11,0.113
4.34,-38.96,0.113
4.36,-38.82,0.113
4.39,-38.68,0.113
4.42,-38.54,0.113
4.45,-38.39,0.113
4.48,-38.25,0.113
4.50,-38.11,0.113
4.53,-37.97,0.113
4.56,-37.83,0.113
4.59,-37.69,0.113
4.62,-37.54,0.113
4.65,-37.40,0.113
4.68,-37.26,0.113
4.70,-37.12,0.113
4.73,-36.98,0.113
4.76,-36.83,0.113
4.79,-36.69,0.113
4.82,-36.55,0.113
4.85,-36.41,0.113
4.87,-36.27,0.113
4.90,-36.13,0.113
4.93,-35.98,0.113
4.96,-35.84,0.113
4.99,-35.70,0.113
5.01,-35.56,0.113
5.04,-35.42,0.113
5.07,-35.28,0.113
5.10,-35.13,0.113
5.13,-34.99,0.113
5.16,-34.85,0.113
5.19,-34.71,0.113
5.21,-34.57,0.113
5.24,-34.43,0.113
5.27,-34.28,0.113
5.30,-34.14,0.114
5.33,-34.00,0.113
5.35,-33.86,0.114
5.38,-33.72,0.113
5.41,-33.57,0.113
5.44,-33.43,0.114
5.47,-33.29,0.114
5.50,-33.15,0.114
5.53,-33.01,0.114
5.55,-32.86,0.114
5.58,-32.72,0.114
5.61,-32.58,0.114
5.64,-32.44,0.114
5.67,-32.30,0.114
5.70,-32.15,0.114
5.72,-32.01,0.114
5.75,-31.87,0.114
5.78,-31.73,0.114
5.81,-31.59,0.114
5.84,-31.45,0.114
5.86,-31.30,0.114
5.89,-31.16,0.114
5.92,-31.02,0.114
5.95,-30.88,0.114
5.98,-30.74,0.114
6.01,-30.60,0.114
6.04,-30.45,0.114
6.06,-30.31,0.115
6.09,-30.17,0.115
6.12,-30.03,0.115
6.15,-29.89,0.115
6.18,-29.75,0.115
6.20,-29.60,0.115
6.23,-29.46,0.115
6.26,-29.32,0.115
6.29,-29.18,0.115
6.32,-29.04,0.115
6.35,-28.89,0.115
6.38,-28.75,0.115
6.40,-28.61,0.115
6.43,-28.47,0.115
6.46,-28.33,0.115
6.49,-28.18,0.115
6.52,-28.04,0.115
6.55,-27.90,0.115
6.57,-27.76,0.115
6.60,-27.62,0.115
6.63,-27.48,0.115
6.66,-27.33,0.115
6.69,-27.19,0.115
6.71,-27.05,0.115
6.74,-26.91,0.115
6.77,-26.77,0.115
6.80,-26.63,0.115
6.83,-26.48,0.115
6.86,-26.34,0.115
6.89,-26.20,0.115
6.91,-26.06,0.115
6.94,-25.92,0.115
6.97,-25.77,0.115
7.00,-25.63,0.116
7.03,-25.49,0.116
7.05,-25.35,0.116
7.08,-25.21,0.116
7.11,-25.06,0.116
7.14,-24.92,0.116
7.17,-24.78,0.116
7.20,-24.64,0.116
7.23,-24.50,0.116
7.25,-24.36,0.116
7.28,-24.21,0.116
7.31,-24.07,0.116
7.34,-23.93,0.116
7.37,-23.79,0.116
7.40,-23.65,0.116
7.42,-23.51,0.116
7.45,-23.36,0.116
7.48,-23.22,0.116
7.51,-23.08,0.116
7.54,-22.94,0.116
7.56,-22.80,0.116
7.59,-22.65,0.116
7.62,-22.51,0.116
7.65,-22.37,0.116
7.68,-22.23,0.116
7.71,-22.09,0.116
7.74,-21.95,0.116
7.76,-21.80,0.116
7.79,-21.66,0.117
7.82,-21.52,0.117
7.85,-21.38,0.117
7.88,-21.24,0.117
7.90,-21.10,0.117
7.93,-20.95,0.117
7.96,-20.81,0.117
7.99,-20.67,0.117
8.02,-20.53,0.117
8.05,-20.39,0.117
8.08,-20.24,0.117
8.10,-20.10,0.117
8.13,-19.96,0.117
8.16,-19.82,0.117
8.19,-19.68,0.117
8.22,-19.53,0.117
8.25,-19.39,0.117
8.27,-19.25,0.117
8.30,-19.11,0.117
8.33,-18.97,0.117
8.36,-18.83,0.117
8.39,-18.68,0.117
8.41,-18.54,0.117
8.44,-18.40,0.117
8.47,-18.26,0.117
8.50,-18.12,0.117
8.53,-17.98,0.117
8.56,-17.83,0.117
8.58,-17.69,0.117
8.61,-17.55,0.117
8.64,-17.41,0.117
8.67,-17.27,0.117
8.70,-17.13,0.117
8.73,-16.98,0.118
8.75,-16.84,0.118
8.78,-16.70,0.118
8.81,-16.56,0.118
8.84,-16.42,0.118
8.87,-16.27,0.118
8.90,-16.13,0.118
8.93,-15.99,0.118
8.95,-15.85,0.118
8.98,-15.71,0.118
9.01,-15.56,0.118
9.04,-15.42,0.118
9.07,-15.28,0.118
9.10,-15.14,0.118
9.12,-15.00,0.118
9.15,-14.86,0.118
9.18,-14.71,0.118
9.21,-14.57,0.118
9.24,-14.43,0.118
9.27,-14.29,0.118
9.29,-14.15,0.118
9.32,-14.00,0.119
9.35,-13.86,0.119
9.38,-13.72,0.119
9.41,-13.58,0.119
9.43,-13.44,0.119
9.46,-13.30,0.119
9.49,-13.15,0.119
9.52,-13.01,0.119
9.55,-12.87,0.119
9.58,-12.73,0.119
9.60,-12.59,0.119
9.63,-12.45,0.119
9.66,-12.30,0.119
9.69,-12.16,0.119
9.72,-12.02,0.119
9.75,-11.88,0.119
9.78,-11.74,0.119
9.80,-11.59,0.119
9.83,-11.45,0.119
9.86,-11.31,0.119
9.89,-11.17,0.119
9.92,-11.03,0.119
9.95,-10.89,0.119
9.97,-10.75,0.119
10.00,-10.60,0.120
10.03,-10.46,0.119
10.06,-10.32,0.120
10.09,-10.18,0.120
10.12,-10.03,0.120
10.14,-9.89,0.120
10.17,-9.75,0.120
10.20,-9.61,0.120
10.23,-9.47,0.120
10.26,-9.33,0.120
10.28,-9.18,0.120
10.31,-9.04,0.120
10.34,-8.90,0.120
10.37,-8.76,0.120
10.40,-8.62,0.120
10.43,-8.47,0.120
10.45,-8.33,0.120
10.48,-8.19,0.120
10.51,-8.05,0.120
10.54,-7.91,0.120
10.57,-7.77,0.120
10.60,-7.63,0.120
10.63,-7.48,0.120
10.65,-7.34,0.120
10.68,-7.20,0.120
10.71,-7.06,0.120
10.74,-6.92,0.120
10.77,-6.77,0.120
10.80,-6.63,0.120
10.82,-6.49,0.120
10.85,-6.35,0.121
10.88,-6.21,0.121
10.91,-6.07,0.121
10.94,-5.92,0.121
10.97,-5.78,0.121
10.99,-5.64,0.121
11.02,-5.50,0.121
11.05,-5.36,0.121
11.08,-5.22,0.121
11.11,-5.07,0.121
11.13,-4.93,0.121
11.16,-4.79,0.121
11.19,-4.65,0.121
11.22,-4.51,0.121
11.25,-4.36,0.121
11.28,-4.22,0.121
11.30,-4.08,0.121
11.33,-3.94,0.121
11.36,-3.80,0.121
11.39,-3.66,0.121
11.42,-3.51,0.122
11.45,-3.37,0.122
11.48,-3.23,0.122
11.50,-3.09,0.122
11.53,-2.95,0.122
11.56,-2.80,0.122
11.59,-2.66,0.122
11.62,-2.52,0.122
11.65,-2.38,0.122
11.67,-2.24,0.122
11.70,-2.10,0.122
11.73,-1.95,0.122
11.76,-1.81,0.122
11.79,-1.67,0.122
11.82,-1.53,0.122
11.84,-1.39,0.122
11.87,-1.25,0.122
11.90,-1.10,0.122
11.93,-0.96,0.122
11.96,-0.82,0.122
11.98,-0.68,0.122
12.01,-0.54,0.123
12.04,-0.39,0.123
12.07,-0.25,0.123
12.10,-0.11,0.123
12.13,0.03,0.123
12.15,0.17,0.123
12.18,0.32,0.123
12.21,0.46,0.123
12.24,0.60,0.123
12.27,0.74,0.123
12.30,0.88,0.123
12.33,1.02,0.123
12.35,1.17,0.123
12.38,1.31,0.123
12.41,1.45,0.123
12.44,1.59,0.123
12.47,1.73,0.123
12.50,1.88,0.123
12.52,2.02,0.123
12.55,2.16,0.123
12.58,2.30,0.123
12.61,2.44,0.123
12.64,2.58,0.123
12.67,2.73,0.124
12.69,2.87,0.124
12.72,3.01,0.124
12.75,3.15,0.124
12.78,3.29,0.124
12.81,3.43,0.124
12.83,3.58,0.124
12.86,3.72,0.124
12.89,3.86,0.124
12.92,4.00,0.124
12.95,4.14,0.124
12.98,4.29,0.124
13.00,4.43,0.124
13.03,4.57,0.124
13.06,4.71,0.124
13.09,4.85,0.124
13.12,4.99,0.124
13.15,5.13,0.125
13.18,5.28,0.125
13.20,5.42,0.125
13.23,5.56,0.125
13.26,5.70,0.125
13.29,5.84,0.125
13.32,5.99,0.125
13.35,6.13,0.125
13.37,6.27,0.125
13.40,6.41,0.125
13.43,6.55,0.125
13.46,6.69,0.125
13.49,6.84,0.125
13.52,6.98,0.125
13.54,7.12,0.125
13.57,7.26,0.125
13.60,7.40,0.125
13.63,7.55,0.125
13.66,7.69,0.126
13.68,7.83,0.126
13.71,7.97,0.126
13.74,8.11,0.126
13.77,8.25,0.126
13.80,8.40,0.126
13.83,8.54,0.126
13.85,8.68,0.126
13.88,8.82,0.126
13.91,8.96,0.126
13.94,9.10,0.126
13.97,9.25,0.126
14.00,9.39,0.126
14.03,9.53,0.126
14.05,9.67,0.126
14.08,9.81,0.126
14.11,9.96,0.126
14.14,10.10,0.126
14.17,10.24,0.126
14.20,10.38,0.127
14.22,10.52,0.127
14.25,10.66,0.127
14.28,10.81,0.127
14.31,10.95,0.127
14.34,11.09,0.127
14.37,11.23,0.127
14.39,11.37,0.127
14.42,11.51,0.127
14.45,11.66,0.127
14.48,11.80,0.127
14.51,11.94,0.127
14.53,12.08,0.127
14.56,12.22,0.127
14.59,12.37,0.127
14.62,12.51,0.127
14.65,12.65,0.128
14.68,12.79,0.128
14.70,12.93,0.128
14.73,13.08,0.128
14.76,13.22,0.128
14.79,13.36,0.128
14.82,13.50,0.128
14.85,13.64,0.128
14.88,13.78,0.128
14.90,13.93,0.128
14.93,14.07,0.128
14.96,14.21,0.128
14.99,14.35,0.128
15.02,14.49,0.128
15.05,14.63,0.128
15.07,14.77,0.128
15.10,14.92,0.128
15.13,15.06,0.128
15.16,15.20,0.129
15.19,15.34,0.129
15.22,15.49,0.129
15.24,15.63,0.129
15.27,15.77,0.129
15.30,15.91,0.129
15.33,16.05,0.129
15.36,16.19,0.129
15.38,16.33,0.129
15.41,16.48,0.129
15.44,16.62,0.129
15.47,16.76,0.129
15.50,16.90,0.129
15.53,17.05,0.129
15.55,17.19,0.130
15.58,17.33,0.130
15.61,17.48,0.130
15.64,17.62,0.130
15.67,17.76,0.130
15.70,17.90,0.130
15.73,18.04,0.130
15.75,18.18,0.130
15.78,18.33,0.130
15.81,18.47,0.130
15.84,18.61,0.130
15.87,18.75,0.130
15.90,18.89,0.130
15.92,19.03,0.130
15.95,19.18,0.130
15.98,19.32,0.130
16.01,19.46,0.130
16.04,19.60,0.130
16.07,19.74,0.130
16.09,19.88,0.130
16.12,20.02,0.130
16.15,20.17,0.130
16.18,20.31,0.130
16.21,20.45,0.130
16.23,20.59,0.130
16.26,20.73,0.130
16.29,20.87,0.131
16.32,21.01,0.131
16.35,21.16,0.131
16.38,21.30,0.131
16.40,21.44,0.131
16.43,21.58,0.131
16.46,21.72,0.131
16.49,21.86,0.131
16.52,22.01,0.131
16.55,22.15,0.131
16.58,22.29,0.131
16.60,22.43,0.131
16.63,22.57,0.131
16.66,22.72,0.132
16.69,22.86,0.132
16.72,23.00,0.132
16.75,23.14,0.132
16.77,23.28,0.132
16.80,23.42,0.132
16.83,23.57,0.132
16.86,23.71,0.132
16.89,23.85,0.132
16.92,23.99,0.132
16.94,24.13,0.132
16.97,24.27,0.132
17.00,24.42,0.132
17.03,24.56,0.132
17.06,24.70,0.132
17.08,24.84,0.132
17.11,24.98,0.133
17.14,25.12,0.133
17.17,25.27,0.133
17.20,25.41,0.133
17.23,25.55,0.133
17.26,25.69,0.133
17.28,25.83,0.133
17.31,25.98,0.133
17.34,26.12,0.133
17.37,26.26,0.133
17.40,26.40,0.133
17.43,26.54,0.133
17.45,26.68,0.133
17.48,26.83,0.133
17.51,26.97,0.133
17.54,27.11,0.134
17.57,27.25,0.134
17.59,27.39,0.134
17.62,27.53,0.134
17.65,27.68,0.134
17.68,27.82,0.134
17.71,27.96,0.134
17.74,28.10,0.134
17.77,28.24,0.134
17.79,28.39,0.134
17.82,28.53,0.134
17.85,28.67,0.134
17.88,28.81,0.134
17.91,28.95,0.134
17.93,29.09,0.134
17.96,29.24,0.134
17.99,29.38,0.134
18.02,29.52,0.134
18.05,29.66,0.135
18.08,29.80,0.135
18.11,29.95,0.135
18.13,30.09,0.135
18.16,30.23,0.135
18.19,30.37,0.135
18.22,30.51,0.135
18.25,30.65,0.135
18.28,30.80,0.135
18.30,30.94,0.135
18.33,31.08,0.135
18.36,31.22,0.135
18.39,31.36,0.135
18.42,31.50,0.136
18.44,31.65,0.136
18.47,31.79,0.136
18.50,31.93,0.136
18.53,32.07,0.136
18.56,32.21,0.136
18.59,32.36,0.136
18.62,32.50,0.136
18.64,32.64,0.136
18.67,32.78,0.136
18.70,32.92,0.136
18.73,33.06,0.136
18.76,33.20,0.136
18.78,33.35,0.136
18.81,33.49,0.136
18.84,33.63,0.137
18.87,33.77,0.137
18.90,33.91,0.137
18.93,34.06,0.137
18.96,34.20,0.137
18.98,34.34,0.137
19.01,34.48,0.137
19.04,34.62,0.137
19.07,34.76,0.137
19.10,34.91,0.137
19.13,35.05,0.137
19.15,35.19,0.137
19.18,35.33,0.137
19.21,35.47,0.137
19.24,35.62,0.138
19.27,35.76,0.138
19.29,35.90,0.138
19.32,36.04,0.138
19.35,36.18,0.138
19.38,36.32,0.138
19.41,36.47,0.138
19.44,36.61,0.138
19.47,36.75,0.138
19.49,36.89,0.138
19.52,37.03,0.138
19.55,37.17,0.138
19.58,37.32,0.138
19.61,37.46,0.138
19.63,37.60,0.138
19.66,37.74,0.138
19.69,37.88,0.138
19.72,38.03,0.139
19.75,38.17,0.139
19.78,38.31,0.139
19.81,38.45,0.139
19.83,38.59,0.139
19.86,38.73,0.139
19.89,38.88,0.139
19.92,39.02,0.139
19.95,39.16,0.139
19.98,39.30,0.139
20.00,39.44,0.139
20.03,39.59,0.139
20.06,39.73,0.139
20.09,39.87,0.139
20.12,40.01,0.139
20.14,40.15,0.139
20.17,40.29,0.140
20.20,40.44,0.140
20.23,40.58,0.140
20.26,40.72,0.140
20.29,40.86,0.140
20.32,41.00,0.140
20.34,41.14,0.140
20.37,41.29,0.140
20.40,41.43,0.140
20.43,41.57,0.140
20.46,41.71,0.140
20.48,41.85,0.140
20.51,41.99,0.140
20.54,42.14,0.140
20.57,42.28,0.141
20.60,42.42,0.141
20.63,42.56,0.141
20.66,42.70,0.141
20.68,42.84,0.141
20.71,42.99,0.141
20.74,43.13,0.141
20.77,43.27,0.141
20.80,43.41,0.142
20.83,43.55,0.142
20.85,43.70,0.142
20.88,43.84,0.142
20.91,43.98,0.142
20.94,44.12,0.142
20.97,44.26,0.142
20.99,44.41,0.142
21.02,44.55,0.142
21.05,44.69,0.142
21.08,44.83,0.142
21.11,44.97,0.142
21.14,45.12,0.143
21.17,45.26,0.143
21.19,45.40,0.143
21.22,45.54,0.143
21.25,45.68,0.143
21.28,45.82,0.143
21.31,45.97,0.143
21.33,46.11,0.143
21.36,46.25,0.143
21.39,46.39,0.143
21.42,46.53,0.143
21.45,46.67,0.143
21.48,46.82,0.143
21.51,46.96,0.143
21.53,47.10,0.143
21.56,47.24,0.143
21.59,47.38,0.143
21.62,47.52,0.143
21.65,47.67,0.144
21.68,47.81,0.144
21.70,47.95,0.144
21.73,48.09,0.144
21.76,48.23,0.144
21.79,48.37,0.144
21.82,48.52,0.144
21.84,48.66,0.144
21.87,48.80,0.144
21.90,48.94,0.144
21.93,49.08,0.144
21.96,49.22,0.144
21.99,49.37,0.144
22.02,49.51,0.145
22.04,49.65,0.145
22.07,49.79,0.145
22.10,49.93,0.145
22.13,50.07,0.145
22.16,50.22,0.145
22.18,50.36,0.145
22.21,50.50,0.145
22.24,50.64,0.145
22.27,50.78,0.145
22.30,50.92,0.145
22.33,51.07,0.145
22.36,51.21,0.146
22.38,51.35,0.146
22.41,51.49,0.146
22.44,51.63,0.146
22.47,51.78,0.146
22.50,51.92,0.146
22.53,52.06,0.146
22.55,52.20,0.146
22.58,52.34,0.146
22.61,52.48,0.146
22.64,52.63,0.146
22.67,52.77,0.146
22.69,52.91,0.146
22.72,53.05,0.146
22.75,53.19,0.147
22.78,53.33,0.147
22.81,53.48,0.147
22.84,53.62,0.147
22.87,53.76,0.147
22.89,53.90,0.147
22.92,54.04,0.147
22.95,54.18,0.147
22.98,54.33,0.147
23.01,54.47,0.147
23.03,54.61,0.147
23.06,54.75,0.148
23.09,54.89,0.148
23.12,55.03,0.148
23.15,55.18,0.148
23.18,55.32,0.148
23.21,55.46,0.148
23.23,55.60,0.148
23.26,55.74,0.148
23.29,55.89,0.148
23.32,56.03,0.149
23.35,56.17,0.149
23.38,56.31,0.149
23.40,56.45,0.149
23.43,56.59,0.149
23.46,56.74,0.149
23.49,56.88,0.149
23.52,57.02,0.149
23.54,57.16,0.149
23.57,57.30,0.150
23.60,57.44,0.150
23.63,57.59,0.150
23.66,57.73,0.150
23.69,57.87,0.150
23.72,58.01,0.150
23.74,58.15,0.150
23.77,58.30,0.151
23.80,58.44,0.151
23.83,58.58,0.151
23.86,58.72,0.151
23.88,58.86,0.151
23.91,59.00,0.151
23.94,59.14,0.152
23.97,59.29,0.152
24.00,59.43,0.152
24.03,59.57,0.152
24.06,59.71,0.152
24.08,59.85,0.153
24.11,59.99,0.153
24.14,60.14,0.153
24.17,60.28,0.153
24.20,60.42,0.153
24.23,60.56,0.154
24.25,60.70,0.154
24.28,60.85,0.154
24.31,60.99,0.155
24.34,61.13,0.155
24.37,61.27,0.155
24.39,61.41,0.156
24.42,61.55,0.156
24.45,61.69,0.157
24.48,61.84,0.157
24.51,61.98,0.157
24.54,62.12,0.158
24.57,62.26,0.159
24.59,62.40,0.159
24.62,62.54,0.160
24.65,62.69,0.160
24.68,62.83,0.161
24.71,62.97,0.162
24.73,63.11,0.163
24.76,63.25,0.164
24.79,63.39,0.166
24.82,63.53,0.167
24.85,63.67,0.169
24.88,63.81,0.172
24.91,63.96,0.174
24.93,64.10,0.177
24.96,64.24,0.180
24.99,64.38,0.183
25.02,64.52,0.189
25.05,64.66,0.192
25.08,64.80,0.197
25.10,64.94,0.203
25.13,65.08,0.210
25.16,65.22,0.217
25.19,65.36,0.225
25.22,65.50,0.235
25.24,65.64,0.243
25.27,65.78,0.256
25.30,65.92,0.269
25.33,66.05,0.282
25.36,66.19,0.301
25.39,66.33,0.319
25.42,66.46,0.341
25.44,66.60,0.365
25.47,66.74,0.394
25.50,66.87,0.422
25.53,67.00,0.455
25.56,67.13,0.490
25.58,67.26,0.528
25.61,67.40,0.569
25.64,67.52,0.612
25.67,67.65,0.655
25.70,67.78,0.702
25.73,67.91,0.752
25.76,68.03,0.827
25.78,68.15,0.921
25.81,68.27,0.977
25.84,68.39,1.033
25.87,68.52,1.072
25.90,68.64,1.114
25.93,68.76,1.234
25.95,68.88,1.302
25.98,69.00,1.333
26.01,69.13,1.363
26.04,69.25,1.411
26.07,69.38,1.490
26.09,69.50,1.609
26.12,69.61,1.694
26.15,69.73,1.721
26.18,69.86,1.720
26.21,69.99,1.691
26.24,70.14,1.622
26.27,70.30,1.529
26.29,70.46,1.424
26.32,70.63,1.316
26.35,70.80,1.206
26.38,70.98,1.092
26.41,71.15,0.994
26.43,71.33,0.896
26.46,71.50,0.810
26.49,71.67,0.734
26.52,71.84,0.667
26.55,72.00,0.610
26.58,72.16,0.559
26.61,72.32,0.514
26.63,72.48,0.476
26.66,72.64,0.444
26.69,72.79,0.417
26.72,72.94,0.393
26.75,73.09,0.373
26.78,73.24,0.356
26.80,73.39,0.342
26.83,73.54,0.329
26.86,73.69,0.320
26.89,73.83,0.311
26.92,73.98,0.303
26.94,74.12,0.298
26.97,74.26,0.293
27.00,74.41,0.288
27.03,74.55,0.285
27.06,74.70,0.282
27.09,74.84,0.279
27.12,74.98,0.277
27.14,75.12,0.275
27.17,75.27,0.274
27.20,75.41,0.272
27.23,75.55,0.272
27.26,75.69,0.271
27.28,75.84,0.271
27.31,75.98,0.270
27.34,76.12,0.269
27.37,76.26,0.269
27.40,76.40,0.268
27.43,76.54,0.268
27.46,76.69,0.267
27.48,76.83,0.267
27.51,76.97,0.267
27.54,77.11,0.267
27.57,77.25,0.267
27.60,77.40,0.267
27.63,77.54,0.267
27.65,77.68,0.266
27.68,77.82,0.266
27.71,77.96,0.266
27.74,78.11,0.267
27.77,78.25,0.267
27.79,78.39,0.267
27.82,78.53,0.267
27.85,78.67,0.267
27.88,78.81,0.267
27.91,78.96,0.267
27.94,79.10,0.268
27.97,79.24,0.268
27.99,79.38,0.268
28.02,79.52,0.268
28.05,79.66,0.269
28.08,79.81,0.269
28.11,79.95,0.269
28.13,80.09,0.269
28.16,80.23,0.270
28.19,80.37,0.270
28.22,80.51,0.270
28.25,80.66,0.271
28.28,80.80,0.271
28.31,80.94,0.271
28.33,81.08,0.271
28.36,81.22,0.272
28.39,81.36,0.272
28.42,81.51,0.272
28.45,81.65,0.272
28.48,81.79,0.273
28.50,81.93,0.273
28.53,82.07,0.273
28.56,82.21,0.273
28.59,82.36,0.273
28.62,82.50,0.274
28.64,82.64,0.274
28.67,82.78,0.274
28.70,82.92,0.274
28.73,83.06,0.274
28.76,83.21,0.274
28.79,83.35,0.275
28.82,83.49,0.275
28.84,83.63,0.275
28.87,83.77,0.275
28.90,83.92,0.275
28.93,84.06,0.275
28.96,84.20,0.275
28.98,84.34,0.275
29.01,84.48,0.275
29.04,84.62,0.275
29.07,84.77,0.275
29.10,84.91,0.275
29.13,85.05,0.275
29.16,85.19,0.275
29.18,85.33,0.275
29.21,85.47,0.275
29.24,85.62,0.274
29.27,85.76,0.274
29.30,85.90,0.274
29.33,86.04,0.274
29.35,86.18,0.273
29.38,86.33,0.273
29.41,86.47,0.273
29.44,86.61,0.273
29.47,86.75,0.272
29.49,86.89,0.272
29.52,87.03,0.271
29.55,87.18,0.271
29.58,87.32,0.271
29.61,87.46,0.270
29.64,87.60,0.270
29.67,87.75,0.269
29.69,87.89,0.269
29.72,88.03,0.268
29.75,88.17,0.267
29.78,88.31,0.267
29.81,88.45,0.266
29.83,88.60,0.265
29.86,88.74,0.265
29.89,88.88,0.264
29.92,89.02,0.263
29.95,89.16,0.263
29.98,89.31,0.262
30.01,89.45,0.261
30.03,89.59,0.261
30.06,89.73,0.260
30.09,89.87,0.259
30.12,90.02,0.259
30.15,90.16,0.258
30.18,90.30,0.258
30.20,90.44,0.257
30.23,90.58,0.256
30.26,90.72,0.256
30.29,90.87,0.255
30.32,91.01,0.255
30.34,91.15,0.255
30.37,91.29,0.254
30.40,91.44,0.254
30.43,91.58,0.254
30.46,91.72,0.254
30.49,91.86,0.254
30.52,92.00,0.253
30.54,92.14,0.253
30.57,92.28,0.253
30.60,92.43,0.253
30.63,92.57,0.254
30.66,92.71,0.254
30.68,92.85,0.254
30.71,92.99,0.254
30.74,93.13,0.255
30.77,93.28,0.255
30.80,93.42,0.255
30.83,93.56,0.256
30.86,93.70,0.257
30.88,93.84,0.257
30.91,93.98,0.258
30.94,94.12,0.259
30.97,94.27,0.260
31.00,94.41,0.261
31.03,94.55,0.262
31.05,94.69,0.263
31.08,94.83,0.264
31.11,94.97,0.265
31.14,95.11,0.267
31.17,95.26,0.268
31.19,95.40,0.269
31.22,95.54,0.270
31.25,95.68,0.271
31.28,95.82,0.272
31.31,95.96,0.273
31.34,96.10,0.274
31.37,96.25,0.275
31.39,96.39,0.276
31.42,96.53,0.277
31.45,96.67,0.278
31.48,96.81,0.279
31.51,96.95,0.280
31.53,97.10,0.280
31.56,97.24,0.281
31.59,97.38,0.282
31.62,97.52,0.282
31.65,97.66,0.283
31.68,97.80,0.283
31.71,97.94,0.283
31.73,98.09,0.283
31.76,98.23,0.283
31.79,98.37,0.283
31.82,98.51,0.283
31.85,98.65,0.282
31.88,98.80,0.281
31.90,98.94,0.280
31.93,99.08,0.278
31.96,99.22,0.277
31.99,99.37,0.276
32.02,99.51,0.275
32.04,99.65,0.274
32.07,99.79,0.272
32.10,99.94,0.271
32.13,100.08,0.269
32.16,100.22,0.268
32.19,100.36,0.266
32.22,100.51,0.265
32.24,100.65,0.263
32.27,100.79,0.262
32.30,100.93,0.259
32.33,101.07,0.258
32.36,101.22,0.256
32.38,101.36,0.254
32.41,101.50,0.252
32.44,101.64,0.251
32.47,101.79,0.250
32.50,101.93,0.249
32.53,102.07,0.247
32.56,102.21,0.245
32.58,102.35,0.243
32.61,102.50,0.241
32.64,102.64,0.240
32.67,102.78,0.238
32.70,102.92,0.236
32.73,103.07,0.235
32.75,103.21,0.234
32.78,103.35,0.232
32.81,103.49,0.231
32.84,103.63,0.229
32.87,103.78,0.228
32.89,103.92,0.226
32.92,104.06,0.224
32.95,104.20,0.223
32.98,104.35,0.221
33.01,104.49,0.219
33.04,104.63,0.217
33.07,104.77,0.216
33.09,104.91,0.215
33.12,105.06,0.215
33.15,105.20,0.214
33.18,105.34,0.213
33.21,105.48,0.211
33.23,105.63,0.209
33.26,105.77,0.208
33.29,105.91,0.207
33.32,106.05,0.205
33.35,106.19,0.204
33.38,106.34,0.203
33.41,106.48,0.202
33.43,106.62,0.201
33.46,106.76,0.200
33.49,106.90,0.200
33.52,107.05,0.199
33.55,107.19,0.198
33.58,107.33,0.197
33.60,107.47,0.197
33.63,107.61,0.196
33.66,107.76,0.195
33.69,107.90,0.195
33.72,108.04,0.194
33.74,108.18,0.193
33.77,108.32,0.193
33.80,108.46,0.192
33.83,108.61,0.192
33.86,108.75,0.191
33.89,108.89,0.191
33.92,109.03,0.190
33.94,109.17,0.190
33.97,109.31,0.190
34.00,109.46,0.189
34.03,109.60,0.189
34.06,109.74,0.189
34.08,109.88,0.189
34.11,110.03,0.188
34.14,110.17,0.188
34.17,110.31,0.188
34.20,110.45,0.188
34.23,110.59,0.188
34.26,110.73,0.187
34.28,110.88,0.187
34.31,111.02,0.187
34.34,111.16,0.187
34.37,111.30,0.187
34.40,111.44,0.186
34.43,111.58,0.186
34.45,111.73,0.186
34.48,111.87,0.186
34.51,112.01,0.186
34.54,112.15,0.186
34.57,112.29,0.186
34.59,112.43,0.186
34.62,112.58,0.186
34.65,112.72,0.186
34.68,112.86,0.186
34.71,113.00,0.186
34.74,113.14,0.186
34.76,113.28,0.186
34.79,113.43,0.186
34.82,113.57,0.186
34.85,113.71,0.186
34.88,113.85,0.186
34.91,113.99,0.186
34.94,114.13,0.186
34.96,114.28,0.186
34.99,114.42,0.186
35.02,114.56,0.186
35.05,114.70,0.186
35.08,114.84,0.186
35.11,114.99,0.186
35.13,115.13,0.187
35.16,115.27,0.187
35.19,115.41,0.187
35.22,115.55,0.187
35.25,115.69,0.187
35.28,115.84,0.187
35.30,115.98,0.187
35.33,116.12,0.187
35.36,116.26,0.187
35.39,116.40,0.187
35.42,116.55,0.187
35.44,116.69,0.187
35.47,116.83,0.187
35.50,116.97,0.187
35.53,117.11,0.187
35.56,117.25,0.187
35.59,117.40,0.187
35.61,117.54,0.187
35.64,117.68,0.187
35.67,117.82,0.187
35.70,117.96,0.187
35.73,118.10,0.187
35.76,118.24,0.187
35.79,118.39,0.187
35.81,118.53,0.187
35.84,118.67,0.187
35.87,118.81,0.187
35.90,118.95,0.187
35.93,119.09,0.187
35.96,119.24,0.187
35.98,119.38,0.187
36.01,119.52,0.187
36.04,119.66,0.187
36.07,119.80,0.187
36.10,119.95,0.187
36.13,120.09,0.187
36.15,120.23,0.187
36.18,120.37,0.187
36.21,120.51,0.187
36.24,120.65,0.187
36.27,120.80,0.187
36.29,120.94,0.187
36.32,121.08,0.187
36.35,121.22,0.187
36.38,121.36,0.187
36.41,121.51,0.187
36.44,121.65,0.187
36.46,121.79,0.187
36.49,121.93,0.187
36.52,122.07,0.187
36.55,122.21,0.187
36.58,122.36,0.187
36.61,122.50,0.187
36.64,122.64,0.187
36.66,122.78,0.187
36.69,122.92,0.187
36.72,123.06,0.187
36.75,123.21,0.187
36.78,123.35,0.187
36.81,123.49,0.187
36.83,123.63,0.187
36.86,123.77,0.187
36.89,123.91,0.187
36.92,124.06,0.187
36.95,124.20,0.187
36.98,124.34,0.187
37.00,124.48,0.187
37.03,124.62,0.187
37.06,124.76,0.187
37.09,124.91,0.187
37.12,125.05,0.187
37.14,125.19,0.187
37.17,125.33,0.187
37.20,125.47,0.187
37.23,125.61,0.187
37.26,125.76,0.187
37.29,125.90,0.187
37.31,126.04,0.187
37.34,126.18,0.187
37.37,126.32,0.187
37.40,126.46,0.187
37.43,126.61,0.187
37.46,126.75,0.187
37.49,126.89,0.187
37.51,127.03,0.187
37.54,127.17,0.187
37.57,127.32,0.187
37.60,127.46,0.187
37.63,127.60,0.187
37.66,127.74,0.187
37.68,127.88,0.188
37.71,128.03,0.188
37.74,128.17,0.188
37.77,128.31,0.188
37.80,128.45,0.188
37.83,128.59,0.188
37.85,128.74,0.188
37.88,128.88,0.188
37.91,129.02,0.188
37.94,129.16,0.188
37.97,129.30,0.187
37.99,129.44,0.187
38.02,129.58,0.188
38.05,129.73,0.188
38.08,129.87,0.188
38.11,130.01,0.188
38.14,130.15,0.188
38.16,130.29,0.188
38.19,130.43,0.188
38.22,130.58,0.188
38.25,130.72,0.188
38.28,130.86,0.188
38.31,131.00,0.188
38.34,131.14,0.188
38.36,131.28,0.188
38.39,131.43,0.188
38.42,131.57,0.188
38.45,131.71,0.188
38.48,131.85,0.188
38.51,131.99,0.188
38.53,132.13,0.188
38.56,132.28,0.188
38.59,132.42,0.188
38.62,132.56,0.188
38.65,132.70,0.188
38.68,132.84,0.188
38.70,132.99,0.188
38.73,133.13,0.188
38.76,133.27,0.188
38.79,133.41,0.188
38.82,133.55,0.188
38.84,133.69,0.188
38.87,133.83,0.188
38.90,133.98,0.188
38.93,134.12,0.188
38.96,134.26,0.188
38.99,134.40,0.188
39.01,134.54,0.188
39.04,134.69,0.188
39.07,134.83,0.188
39.10,134.97,0.188
39.13,135.11,0.188
39.16,135.25,0.188
39.19,135.39,0.188
39.21,135.54,0.188
39.24,135.68,0.188
39.27,135.82,0.189
39.30,135.96,0.189
39.33,136.10,0.189
39.36,136.24,0.189
39.38,136.39,0.189
39.41,136.53,0.189
39.44,136.67,0.189
39.47,136.81,0.189
39.50,136.95,0.189
39.53,137.09,0.189
39.55,137.24,0.189
39.58,137.38,0.189
39.61,137.52,0.189
39.64,137.66,0.189
39.67,137.80,0.189
39.69,137.94,0.189
39.72,138.09,0.189
39.75,138.23,0.189
39.78,138.37,0.189
39.81,138.51,0.189
39.84,138.65,0.189
39.86,138.79,0.189
39.89,138.94,0.189
39.92,139.08,0.189
39.95,139.22,0.189
39.98,139.36,0.189
40.01,139.50,0.189
40.04,139.65,0.189
40.06,139.79,0.189
40.09,139.93,0.189
40.12,140.07,0.189
40.15,140.21,0.189
40.18,140.35,0.189
40.21,140.50,0.189
40.23,140.64,0.189
40.26,140.78,0.189
40.29,140.92,0.189
40.32,141.06,0.189
40.35,141.21,0.189
40.38,141.35,0.190
40.40,141.49,0.190
40.43,141.63,0.190
40.46,141.77,0.190
40.49,141.91,0.190
40.52,142.06,0.190
40.54,142.20,0.190
40.57,142.34,0.190
40.60,142.48,0.190
40.63,142.62,0.190
40.66,142.76,0.190
40.69,142.90,0.190
40.71,143.05,0.190
40.74,143.19,0.190
40.77,143.33,0.190
40.80,143.47,0.190
40.83,143.61,0.190
40.86,143.76,0.190
40.89,143.90,0.190
40.91,144.04,0.190
40.94,144.18,0.190
40.97,144.32,0.190
41.00,144.46,0.190
41.03,144.61,0.190
41.06,144.75,0.190
41.08,144.89,0.190
41.11,145.03,0.190
41.14,145.17,0.190
41.17,145.31,0.190
41.20,145.46,0.190
41.23,145.60,0.190
41.25,145.74,0.190
41.28,145.88,0.190
41.31,146.02,0.190
41.34,146.17,0.190
41.37,146.31,0.190
41.39,146.45,0.190
41.42,146.59,0.190
41.45,146.73,0.190
41.48,146.87,0.190
41.51,147.02,0.190
41.54,147.16,0.190
41.56,147.30,0.190
41.59,147.44,0.190
41.62,147.58,0.190
41.65,147.72,0.190
41.68,147.86,0.190
41.71,148.01,0.190
41.74,148.15,0.190
41.76,148.29,0.191
41.79,148.43,0.191
41.82,148.57,0.191
41.85,148.72,0.191
41.88,148.86,0.191
41.91,149.00,0.191
41.93,149.14,
41.96,149.28,
41.99,,

[step]
Ramp 5.00 °C/min to -60.00 °C
Time,Temperature,Heat Flow (Normalized)
min,°C,W/g
42.99,150.12,-0.048
43.01,150.12,-0.048
43.04,150.11,-0.050
43.07,150.08,-0.077
43.10,150.04,-0.113
43.13,149.96,-0.149
43.16,149.87,-0.182
43.19,149.77,-0.206
43.21,149.65,-0.223
43.24,149.53,-0.235
43.27,149.41,-0.246
43.30,149.28,-0.254
43.33,149.15,-0.261
43.36,149.02,-0.265
43.38,148.89,-0.269
43.41,148.75,-0.272
43.44,148.61,-0.273
43.47,148.48,-0.275
43.50,148.34,-0.276
43.53,148.20,-0.277
43.55,148.06,-0.277
43.58,147.92,-0.278
43.61,147.78,-0.278
43.64,147.64,-0.279
43.67,147.50,-0.279
43.69,147.36,-0.280
43.72,147.22,-0.280
43.75,147.08,-0.280
43.78,146.94,-0.281
43.81,146.80,-0.281
43.84,146.66,-0.281
43.86,146.52,-0.281
43.89,146.38,-0.281
43.92,146.24,-0.282
43.95,146.10,-0.281
43.98,145.96,-0.281
44.01,145.82,-0.282
44.04,145.68,-0.282
44.06,145.53,-0.282
44.09,145.39,-0.282
44.12,145.25,-0.282
44.15,145.11,-0.282
44.18,144.97,-0.282
44.21,144.83,-0.282
44.23,144.69,-0.282
44.26,144.55,-0.282
44.29,144.41,-0.281
44.32,144.26,-0.281
44.35,144.12,-0.281
44.38,143.98,-0.281
44.40,143.84,-0.281
44.43,143.70,-0.281
44.46,143.56,-0.281
44.49,143.42,-0.281
44.52,143.27,-0.281
44.54,143.13,-0.281
44.57,142.99,-0.281
44.60,142.85,-0.280
44.63,142.71,-0.280
44.66,142.57,-0.280
44.69,142.43,-0.280
44.71,142.28,-0.280
44.74,142.14,-0.280
44.77,142.00,-0.280
44.80,141.86,-0.279
44.83,141.72,-0.279
44.86,141.58,-0.279
44.89,141.44,-0.279
44.91,141.29,-0.279
44.94,141.15,-0.279
44.97,141.01,-0.279
45.00,140.87,-0.279
45.03,140.73,-0.279
45.06,140.59,-0.278
45.08,140.44,-0.278
45.11,140.30,-0.278
45.14,140.16,-0.278
45.17,140.02,-0.278
45.20,139.88,-0.278
45.23,139.74,-0.278
45.25,139.59,-0.277
45.28,139.45,-0.277
45.31,139.31,-0.277
45.34,139.17,-0.277
45.37,139.03,-0.277
45.39,138.89,-0.277
45.42,138.75,-0.277
45.45,138.60,-0.277
45.48,138.46,-0.276
45.51,138.32,-0.276
45.54,138.18,-0.276
45.56,138.04,-0.276
45.59,137.90,-0.276
45.62,137.75,-0.276
45.65,137.61,-0.275
45.68,137.47,-0.275
45.71,137.33,-0.275
45.74,137.19,-0.275
45.76,137.05,-0.275
45.79,136.91,-0.275
45.82,136.76,-0.275
45.85,136.62,-0.275
45.88,136.48,-0.274
45.91,136.34,-0.274
45.93,136.20,-0.274
45.96,136.06,-0.274
45.99,135.91,-0.274
46.02,135.77,-0.274
46.05,135.63,-0.274
46.08,135.49,-0.274
46.10,135.35,-0.273
46.13,135.21,-0.273
46.16,135.06,-0.273
46.19,134.92,-0.273
46.22,134.78,-0.273
46.24,134.64,-0.273
46.27,134.50,-0.273
46.30,134.35,-0.273
46.33,134.21,-0.273
46.36,134.07,-0.273
46.39,133.93,-0.273
46.41,133.79,-0.272
46.44,133.65,-0.272
46.47,133.51,-0.272
46.50,133.37,-0.272
46.53,133.22,-0.272
46.56,133.08,-0.272
46.59,132.94,-0.272
46.61,132.80,-0.272
46.64,132.66,-0.271
46.67,132.52,-0.271
46.70,132.37,-0.271
46.73,132.23,-0.271
46.76,132.09,-0.271
46.78,131.95,-0.271
46.81,131.81,-0.271
46.84,131.67,-0.271
46.87,131.52,-0.271
46.90,131.38,-0.271
46.93,131.24,-0.270
46.95,131.10,-0.270
46.98,130.96,-0.270
47.01,130.82,-0.270
47.04,130.68,-0.270
47.07,130.53,-0.270
47.09,130.39,-0.270
47.12,130.25,-0.270
47.15,130.11,-0.270
47.18,129.97,-0.269
47.21,129.83,-0.269
47.24,129.68,-0.269
47.26,129.54,-0.269
47.29,129.40,-0.269
47.32,129.26,-0.269
47.35,129.12,-0.269
47.38,128.98,-0.269
47.41,128.84,-0.269
47.44,128.69,-0.269
47.46,128.55,-0.269
47.49,128.41,-0.268
47.52,128.27,-0.268
47.55,128.13,-0.268
47.58,127.98,-0.268
47.61,127.84,-0.268
47.63,127.70,-0.268
47.66,127.56,-0.268
47.69,127.42,-0.268
47.72,127.28,-0.268
47.75,127.14,-0.268
47.78,126.99,-0.268
47.80,126.85,-0.267
47.83,126.71,-0.267
47.86,126.57,-0.267
47.89,126.43,-0.267
47.92,126.29,-0.267
47.94,126.14,-0.267
47.97,126.00,-0.267
48.00,125.86,-0.267
48.03,125.72,-0.267
48.06,125.58,-0.267
48.09,125.44,-0.267
48.11,125.30,-0.266
48.14,125.15,-0.266
48.17,125.01,-0.266
48.20,124.87,-0.266
48.23,124.73,-0.266
48.26,124.59,-0.266
48.29,124.45,-0.266
48.31,124.30,-0.266
48.34,124.16,-0.266
48.37,124.02,-0.266
48.40,123.88,-0.266
48.43,123.74,-0.266
48.46,123.60,-0.266
48.48,123.45,-0.265
48.51,123.31,-0.265
48.54,123.17,-0.265
48.57,123.03,-0.265
48.60,122.89,-0.265
48.63,122.75,-0.265
48.65,122.60,-0.265
48.68,122.46,-0.265
48.71,122.32,-0.265
48.74,122.18,-0.265
48.77,122.04,-0.265
48.79,121.90,-0.265
48.82,121.75,-0.265
48.85,121.61,-0.265
48.88,121.47,-0.264
48.91,121.33,-0.264
48.94,121.19,-0.264
48.96,121.05,-0.264
48.99,120.91,-0.264
49.02,120.76,-0.264
49.05,120.62,-0.264
49.08,120.48,-0.264
49.11,120.34,-0.264
49.14,120.20,-0.264
49.16,120.06,-0.264
49.19,119.91,-0.264
49.22,119.77,-0.264
49.25,119.63,-0.264
49.28,119.49,-0.263
49.31,119.35,-0.263
49.33,119.21,-0.263
49.36,119.07,-0.263
49.39,118.92,-0.263
49.42,118.78,-0.263
49.45,118.64,-0.263
49.48,118.50,-0.263
49.50,118.36,-0.263
49.53,118.22,-0.263
49.56,118.07,-0.263
49.59,117.93,-0.263
49.62,117.79,-0.263
49.64,117.65,-0.263
49.67,117.51,-0.263
49.70,117.37,-0.263
49.73,117.22,-0.263
49.76,117.08,-0.263
49.79,116.94,-0.262
49.81,116.80,-0.262
49.84,116.66,-0.262
49.87,116.52,-0.262
49.90,116.37,-0.262
49.93,116.23,-0.262
49.96,116.09,-0.262
49.99,115.95,-0.262
50.01,115.81,-0.262
50.04,115.67,-0.262
50.07,115.52,-0.262
50.10,115.38,-0.262
50.13,115.24,-0.262
50.16,115.10,-0.261
50.18,114.96,-0.261
50.21,114.82,-0.261
50.24,114.67,-0.261
50.27,114.53,-0.261
50.30,114.39,-0.261
50.33,114.25,-0.261
50.35,114.11,-0.261
50.38,113.97,-0.261
50.41,113.83,-0.261
50.44,113.69,-0.261
50.47,113.54,-0.261
50.49,113.40,-0.261
50.52,113.26,-0.261
50.55,113.12,-0.260
50.58,112.97,-0.260
50.61,112.84,-0.260
50.64,112.69,-0.260
50.66,112.55,-0.260
50.69,112.41,-0.260
50.72,112.27,-0.260
50.75,112.13,-0.260
50.78,111.98,-0.260
50.81,111.84,-0.260
50.84,111.70,-0.260
50.86,111.56,-0.260
50.89,111.42,-0.260
50.92,111.28,-0.260
50.95,111.14,-0.259
50.98,110.99,-0.259
51.01,110.85,-0.259
51.03,110.71,-0.259
51.06,110.57,-0.259
51.09,110.43,-0.259
51.12,110.29,-0.259
51.15,110.14,-0.259
51.18,110.00,-0.259
51.20,109.86,-0.259
51.23,109.72,-0.259
51.26,109.58,-0.259
51.29,109.44,-0.259
51.32,109.30,-0.259
51.34,109.15,-0.259
51.37,109.01,-0.259
51.40,108.87,-0.259
51.43,108.73,-0.259
51.46,108.59,-0.258
51.49,108.45,-0.259
51.51,108.30,-0.258
51.54,108.16,-0.258
51.57,108.02,-0.258
51.60,107.88,-0.258
51.63,107.74,-0.258
51.66,107.60,-0.258
51.69,107.45,-0.258
51.71,107.31,-0.258
51.74,107.17,-0.258
51.77,107.03,-0.258
51.80,106.89,-0.258
51.83,106.75,-0.258
51.86,106.61,-0.258
51.88,106.46,-0.258
51.91,106.32,-0.257
51.94,106.18,-0.257
51.97,106.04,-0.257
52.00,105.90,-0.257
52.03,105.76,-0.257
52.05,105.61,-0.257
52.08,105.47,-0.257
52.11,105.33,-0.257
52.14,105.19,-0.257
52.17,105.05,-0.257
52.19,104.91,-0.257
52.22,104.76,-0.257
52.25,104.62,-0.257
52.28,104.48,-0.257
52.31,104.34,-0.257
52.34,104.20,-0.257
52.36,104.06,-0.257
52.39,103.92,-0.257
52.42,103.77,-0.257
52.45,103.63,-0.257
52.48,103.49,-0.257
52.51,103.35,-0.257
[...]
176.16,-39.90,0.113
176.18,-39.83,0.113
176.19,-39.76,0.113
176.20,-39.70,0.113
176.22,-39.63,0.113
176.23,-39.56,0.113
176.24,-39.50,0.113
176.25,-39.43,0.113
176.27,-39.36,0.113
176.28,-39.29,0.113
176.30,-39.23,0.113
176.31,-39.16,0.113
176.32,-39.09,0.113
176.33,-39.03,0.113
176.35,-38.96,0.113
176.36,-38.89,0.113
176.38,-38.83,0.113
176.39,-38.76,0.114
176.40,-38.69,0.114
176.42,-38.63,0.114
176.43,-38.56,0.114
176.44,-38.49,0.114
176.45,-38.43,0.114
176.47,-38.36,0.114
176.48,-38.29,0.114
176.50,-38.23,0.114
176.51,-38.16,0.114
176.52,-38.09,0.114
176.53,-38.03,0.114
176.55,-37.96,0.114
176.56,-37.89,0.114
176.58,-37.83,0.114
176.59,-37.76,0.114
176.60,-37.69,0.114
176.62,-37.63,0.114
176.63,-37.56,0.114
176.64,-37.49,0.114
176.65,-37.43,0.114
176.67,-37.36,0.114
176.68,-37.29,0.114
176.70,-37.23,0.114
176.71,-37.16,0.114
176.72,-37.09,0.114
176.73,-37.02,0.114
176.75,-36.96,0.114
176.76,-36.89,0.114
176.78,-36.82,0.114
176.79,-36.76,0.114
176.80,-36.69,0.114
176.82,-36.62,0.114
176.83,-36.56,0.114
176.84,-36.49,0.114
176.85,-36.42,0.114
176.87,-36.36,0.114
176.88,-36.29,0.114
176.90,-36.22,0.114
176.91,-36.16,0.114
176.92,-36.09,0.114
176.93,-36.02,0.114
176.95,-35.96,0.114
176.96,-35.89,0.114
176.98,-35.82,0.114
176.99,-35.76,0.114
177.00,-35.69,0.114
177.02,-35.62,0.114
177.03,-35.56,0.114
177.04,-35.49,0.114
177.05,-35.42,0.114
177.07,-35.36,0.114
177.08,-35.29,0.114
177.10,-35.22,0.114
177.11,-35.16,0.114
177.12,-35.09,0.115
177.13,-35.02,0.114
177.15,-34.96,0.114
177.16,-34.89,0.114
177.18,-34.82,0.115
177.19,-34.75,0.115
177.20,-34.69,0.115
177.22,-34.62,0.115
177.23,-34.56,0.115
177.24,-34.49,0.115
177.25,-34.42,0.115
177.27,-34.35,0.115
177.28,-34.29,0.115
177.30,-34.22,0.115
177.31,-34.15,0.115
177.32,-34.09,0.115
177.33,-34.02,0.115
177.35,-33.95,0.115
177.36,-33.89,0.115
177.38,-33.82,0.115
177.39,-33.75,0.115
177.40,-33.69,0.115
177.42,-33.62,0.115
177.43,-33.55,0.115
177.44,-33.49,0.115
177.45,-33.42,0.115
177.47,-33.35,0.115
177.48,-33.29,0.115
177.50,-33.22,0.115
177.51,-33.15,0.115
177.52,-33.09,0.115
177.53,-33.02,0.115
177.55,-32.95,0.115
177.56,-32.89,0.115
177.58,-32.82,0.115
177.59,-32.75,0.115
177.60,-32.69,0.115
177.62,-32.62,0.115
177.63,-32.55,0.115
177.64,-32.49,0.115
177.65,-32.42,0.115
177.67,-32.35,0.115
177.68,-32.29,0.115
177.70,-32.22,0.115
177.71,-32.15,0.115
177.72,-32.09,0.115
177.73,-32.02,0.115
177.75,-31.95,0.115
177.76,-31.89,0.115
177.78,-31.82,0.115
177.79,-31.75,0.115
177.80,-31.69,0.115
177.82,-31.62,0.116
177.83,-31.55,0.116
177.84,-31.48,0.116
177.85,-31.42,0.116
177.87,-31.35,0.116
177.88,-31.28,0.116
177.90,-31.21,0.116
177.91,-31.15,0.116
177.92,-31.08,0.116
177.93,-31.01,0.116
177.95,-30.95,0.116
177.96,-30.88,0.116
177.98,-30.81,0.116
177.99,-30.75,0.116
178.00,-30.68,0.116
178.02,-30.61,0.116
178.03,-30.55,0.116
178.04,-30.48,0.116
178.05,-30.41,0.116
178.07,-30.35,0.116
178.08,-30.28,0.116
178.10,-30.21,0.116
178.11,-30.15,0.116
178.12,-30.08,0.116
178.13,-30.01,0.116
178.15,-29.95,0.116
178.16,-29.88,0.116
178.18,-29.81,0.116
178.19,-29.75,0.116
178.20,-29.68,0.116
178.22,-29.61,0.116
178.23,-29.55,0.116
178.24,-29.48,0.116
178.25,-29.41,0.116
178.27,-29.35,0.116
178.28,-29.28,0.116
178.30,-29.21,0.116
178.31,-29.15,0.116
178.32,-29.08,0.116
178.33,-29.01,0.116
178.35,-28.95,0.116
178.36,-28.88,0.117
178.38,-28.81,0.117
178.39,-28.75,0.117
178.40,-28.68,0.117
178.42,-28.61,0.117
178.43,-28.55,0.117
178.44,-28.48,0.117
178.45,-28.41,0.117
178.47,-28.35,0.117
178.48,-28.28,0.117
178.50,-28.21,0.117
178.51,-28.15,0.117
178.52,-28.08,0.117
178.53,-28.01,0.117
178.55,-27.95,0.117
178.56,-27.88,0.117
178.58,-27.81,0.117
178.59,-27.75,0.117
178.60,-27.68,0.117
178.62,-27.62,0.117
178.63,-27.55,0.117
178.64,-27.48,0.117
178.65,-27.42,0.117
178.67,-27.35,0.117
178.68,-27.28,0.117
178.70,-27.22,0.117
178.71,-27.15,0.118
178.72,-27.08,0.118
178.73,-27.02,0.118
178.75,-26.95,0.118
178.76,-26.88,0.118
178.78,-26.81,0.118
178.79,-26.75,0.118
178.80,-26.68,0.118
178.82,-26.61,0.118
178.83,-26.55,0.118
178.84,-26.48,0.118
178.85,-26.41,0.118
178.87,-26.35,0.118
178.88,-26.28,0.118
178.90,-26.21,0.118
178.91,-26.15,0.118
178.92,-26.08,0.118
178.93,-26.01,0.118
178.95,-25.95,0.118
178.96,-25.88,0.119
178.98,-25.81,0.119
178.99,-25.75,0.119
179.00,-25.68,0.119
179.02,-25.61,0.119
179.03,-25.55,0.119
179.04,-25.48,0.119
179.05,-25.41,0.119
179.07,-25.35,0.119
179.08,-25.28,0.119
179.10,-25.21,0.119
179.11,-25.15,0.119
179.12,-25.08,0.119
179.13,-25.01,0.119
179.15,-24.95,0.119
179.16,-24.88,0.119
179.18,-24.81,0.119
179.19,-24.75,0.119
179.20,-24.68,0.120
179.22,-24.61,0.120
179.23,-24.55,0.120
179.24,-24.48,0.120
179.25,-24.41,0.120
179.27,-24.35,0.120
179.28,-24.28,0.120
179.30,-24.21,0.120
179.31,-24.15,0.120
179.32,-24.08,0.120
179.33,-24.01,0.120
179.35,-23.94,0.120
179.36,-23.88,0.120
179.38,-23.81,0.120
179.39,-23.74,0.121
179.40,-23.68,0.121
179.42,-23.61,0.121
179.43,-23.54,0.121
179.44,-23.48,0.121
179.45,-23.41,0.121
179.47,-23.35,0.121
179.48,-23.28,0.121
179.50,-23.21,0.121
179.51,-23.15,0.121
179.52,-23.08,0.121
179.53,-23.02,0.121
179.55,-22.95,0.121
179.56,-22.88,0.121
179.58,-22.82,0.121
179.59,-22.75,0.121
179.60,-22.68,0.121
179.62,-22.62,0.121
179.63,-22.55,0.122
179.64,-22.49,0.122
179.65,-22.42,0.122
179.67,-22.35,0.122
179.68,-22.28,0.122
179.70,-22.22,0.122
179.71,-22.15,0.122
179.72,-22.08,0.123
179.73,-22.02,0.123
179.75,-21.95,0.123
179.76,-21.88,0.123
179.78,-21.82,0.123
179.79,-21.75,0.123
179.80,-21.68,0.123
179.82,-21.62,0.123
179.83,-21.55,0.124
179.84,-21.48,0.124
179.85,-21.42,0.124
179.87,-21.35,0.124
179.88,-21.28,0.124
179.90,-21.22,0.125
179.91,-21.15,0.125
179.92,-21.08,0.125
179.93,-21.01,0.125
179.95,-20.95,0.125
179.96,-20.88,0.125
179.98,-20.81,0.126
179.99,-20.75,0.126
180.00,-20.68,0.126
180.02,-20.61,0.126
180.03,-20.55,0.126
180.04,-20.48,0.126
180.05,-20.41,0.126
180.07,-20.35,0.126
180.08,-20.28,0.127
180.10,-20.21,0.127
180.11,-20.15,0.127
180.12,-20.08,0.127
180.13,-20.01,0.127
180.15,-19.95,0.127
180.16,-19.88,0.127
180.18,-19.81,0.128
180.19,-19.75,0.128
180.20,-19.68,0.128
180.22,-19.61,0.128
180.23,-19.55,0.128
180.24,-19.48,0.128
180.25,-19.41,0.128
180.27,-19.35,0.129
180.28,-19.28,0.129
180.30,-19.21,0.129
180.31,-19.15,0.129
180.32,-19.08,0.129
180.33,-19.01,0.129
180.35,-18.95,0.130
180.36,-18.88,0.130
180.38,-18.81,0.130
180.39,-18.74,0.130
180.40,-18.68,0.130
180.42,-18.61,0.130
180.43,-18.55,0.131
180.44,-18.48,0.131
180.45,-18.41,0.131
180.47,-18.35,0.131
180.48,-18.28,0.131
180.50,-18.21,0.131
180.51,-18.14,0.132
180.52,-18.08,0.132
180.53,-18.01,0.132
180.55,-17.95,0.132
180.56,-17.88,0.133
180.58,-17.81,0.133
180.59,-17.75,0.133
180.60,-17.68,0.133
180.62,-17.61,0.133
180.63,-17.55,0.134
180.64,-17.48,0.134
180.65,-17.41,0.134
180.67,-17.35,0.134
180.68,-17.28,0.135
180.70,-17.21,0.135
180.71,-17.15,0.135
180.72,-17.08,0.135
180.73,-17.01,0.135
180.75,-16.95,0.136
180.76,-16.88,0.136
180.78,-16.81,0.136
180.79,-16.75,0.136
180.80,-16.68,0.137
180.82,-16.61,0.137
180.83,-16.55,0.137
180.84,-16.48,0.137
180.85,-16.41,0.137
180.87,-16.34,0.138
180.88,-16.28,0.138
180.90,-16.21,0.138
180.91,-16.15,0.138
180.92,-16.08,0.139
180.93,-16.01,0.139
180.95,-15.94,0.139
180.96,-15.88,0.139
180.98,-15.81,0.140
180.99,-15.75,0.140
181.00,-15.68,0.140
181.02,-15.61,0.141
181.03,-15.54,0.141
181.04,-15.48,0.141
181.05,-15.41,0.142
181.07,-15.34,0.142
181.08,-15.28,0.142
181.10,-15.21,0.143
181.11,-15.14,0.143
181.12,-15.07,0.144
181.13,-15.01,0.144
181.15,-14.94,0.144
181.16,-14.87,0.144
181.18,-14.81,0.145
181.19,-14.74,0.145
181.20,-14.67,0.145
181.22,-14.60,0.145
181.23,-14.54,0.146
181.24,-14.47,0.146
181.25,-14.41,0.146
181.27,-14.34,0.146
181.28,-14.27,0.146
181.30,-14.21,0.147
181.31,-14.14,0.147
181.32,-14.08,0.147
181.33,-14.01,0.147
181.35,-13.94,0.147
181.36,-13.88,0.147
181.38,-13.81,0.148
181.39,-13.74,0.148
181.40,-13.68,0.148
181.42,-13.61,0.149
181.43,-13.54,0.149
181.44,-13.48,0.149
181.45,-13.41,0.149
181.47,-13.34,0.149
181.48,-13.28,0.150
181.50,-13.21,0.150
181.51,-13.14,0.150
181.52,-13.08,0.150
181.53,-13.01,0.151
181.55,-12.94,0.151
181.56,-12.88,0.151
181.58,-12.81,0.151
181.59,-12.74,0.151
181.60,-12.68,0.152
181.62,-12.61,0.152
181.63,-12.54,0.152
181.64,-12.48,0.152
181.65,-12.41,0.152
181.67,-12.34,0.152
181.68,-12.28,0.153
181.70,-12.21,0.153
181.71,-12.15,0.153
181.72,-12.08,0.153
181.73,-12.01,0.153
181.75,-11.94,0.153
181.76,-11.88,0.154
181.78,-11.81,0.154
181.79,-11.74,0.154
181.80,-11.68,0.154
181.82,-11.61,0.154
181.83,-11.54,0.154
181.84,-11.48,0.155
181.85,-11.41,0.155
181.87,-11.35,0.155
181.88,-11.28,0.155
181.90,-11.21,0.155
181.91,-11.15,0.155
181.92,-11.08,0.155
181.93,-11.01,0.155
181.95,-10.95,0.155
181.96,-10.88,0.155
181.98,-10.81,0.156
181.99,-10.74,0.156
182.00,-10.68,0.156
182.02,-10.61,0.156
182.03,-10.54,0.156
182.04,-10.48,0.156
182.05,-10.41,0.156
182.07,-10.35,0.156
182.08,-10.28,0.156
182.10,-10.21,0.156
182.11,-10.14,0.156
182.12,-10.08,0.156
182.13,-10.01,0.156
182.15,-9.94,0.156
182.16,-9.88,0.156
182.18,-9.81,0.156
182.19,-9.74,0.156
182.20,-9.68,0.156
182.22,-9.61,0.156
182.23,-9.54,0.156
182.24,-9.48,0.156
182.25,-9.41,0.156
182.27,-9.34,0.156
182.28,-9.28,0.156
182.30,-9.21,0.156
182.31,-9.14,0.156
182.32,-9.08,0.156
182.33,-9.01,0.156
182.35,-8.94,0.155
182.36,-8.88,0.155
182.38,-8.81,0.155
182.39,-8.74,0.155
182.40,-8.68,0.155
182.42,-8.61,0.155
182.43,-8.55,0.155
182.44,-8.48,0.155
182.45,-8.41,0.155
182.47,-8.34,0.155
182.48,-8.28,0.155
182.50,-8.21,0.155
182.51,-8.15,0.155
182.52,-8.08,0.155
182.53,-8.01,0.154
182.55,-7.94,0.154
182.56,-7.88,0.154
182.58,-7.81,0.154
182.59,-7.74,0.154
182.60,-7.68,0.154
182.62,-7.61,0.154
182.63,-7.54,0.154
182.64,-7.48,0.154
182.65,-7.41,0.154
182.67,-7.34,0.154
182.68,-7.27,0.154
182.70,-7.21,0.154
182.71,-7.14,0.154
182.72,-7.07,0.154
182.73,-7.01,0.154
182.75,-6.94,0.154
182.76,-6.87,0.154
182.78,-6.80,0.154
182.79,-6.74,0.154
182.80,-6.67,0.154
182.82,-6.61,0.154
182.83,-6.54,0.153
182.84,-6.47,0.153
182.85,-6.40,0.153
182.87,-6.34,0.153
182.88,-6.27,0.153
182.90,-6.21,0.153
182.91,-6.14,0.153
182.92,-6.07,0.153
182.93,-6.00,0.153
182.95,-5.94,0.153
182.96,-5.87,0.153
182.98,-5.81,0.153
182.99,-5.74,0.153
183.00,-5.67,0.153
183.02,-5.61,0.153
183.03,-5.54,0.153
183.04,-5.47,0.153
183.05,-5.40,0.153
183.07,-5.34,0.153
183.08,-5.27,0.153
183.10,-5.20,0.153
183.11,-5.14,0.153
183.12,-5.07,0.153
183.13,-5.01,0.152
183.15,-4.94,0.152
183.16,-4.87,0.152
183.18,-4.81,0.152
183.19,-4.74,0.152
183.20,-4.67,0.152
183.22,-4.61,0.152
183.23,-4.54,0.152
183.24,-4.47,0.152
183.25,-4.41,0.152
183.27,-4.34,0.152
183.28,-4.27,0.152
183.30,-4.20,0.152
183.31,-4.14,0.152
183.32,-4.07,0.152
183.33,-4.00,0.152
183.35,-3.94,0.152
183.36,-3.87,0.152
183.38,-3.80,0.152
183.39,-3.74,0.152
183.40,-3.67,0.152
183.42,-3.61,0.152
183.43,-3.54,0.152
183.44,-3.47,0.152
183.45,-3.41,0.152
183.47,-3.34,0.152
183.48,-3.27,0.152
183.50,-3.20,0.152
183.51,-3.14,0.152
183.52,-3.07,0.152
183.53,-3.00,0.152
183.55,-2.94,0.152
183.56,-2.87,0.152
183.58,-2.81,0.152
183.59,-2.74,0.152
183.60,-2.67,0.152
183.62,-2.61,0.152
183.63,-2.54,0.152
183.64,-2.47,0.152
183.65,-2.40,0.152
183.67,-2.34,0.152
183.68,-2.27,0.152
183.70,-2.20,0.152
183.71,-2.14,0.152
183.72,-2.07,0.152
183.73,-2.00,0.153
183.75,-1.94,0.152
183.76,-1.87,0.153
183.78,-1.80,0.153
183.79,-1.74,0.153
183.80,-1.67,0.153
183.82,-1.60,0.153
183.83,-1.53,0.153
183.84,-1.47,0.153
183.85,-1.40,0.153
183.87,-1.33,0.153
183.88,-1.27,0.153
183.90,-1.20,0.153
183.91,-1.13,0.153
183.92,-1.07,0.153
183.93,-1.00,0.153
183.95,-0.93,0.153
183.96,-0.87,0.153
183.98,-0.80,0.153
183.99,-0.73,0.153
184.00,-0.67,0.153
184.02,-0.60,0.153
184.03,-0.53,0.153
184.04,-0.47,0.153
184.05,-0.40,0.153
184.07,-0.33,0.153
184.08,-0.27,0.153
184.10,-0.20,0.153
184.11,-0.13,0.153
184.12,-0.07,0.153
184.13,0.00,0.153
184.15,0.07,0.153
184.16,0.13,0.153
184.18,0.20,0.153
184.19,0.27,0.153
184.20,0.33,0.153
184.22,0.40,0.153
184.23,0.46,0.153
184.24,0.53,0.153
184.25,0.60,0.153
184.27,0.66,0.153
184.28,0.73,0.153
184.30,0.80,0.153
184.31,0.87,0.153
184.32,0.93,0.153
184.33,1.00,0.153
184.35,1.07,0.153
184.36,1.13,0.153
184.38,1.20,0.153
184.39,1.27,0.153
184.40,1.33,0.153
184.42,1.40,0.153
184.43,1.47,0.153
184.44,1.54,0.153
184.45,1.60,0.153
184.47,1.67,0.153
184.48,1.73,0.153
184.50,1.80,0.153
184.51,1.87,0.153
184.52,1.94,0.153
184.53,2.00,0.153
184.55,2.07,0.153
184.56,2.14,0.153
184.58,2.20,0.153
184.59,2.27,0.153
184.60,2.34,0.153
184.62,2.40,0.153
184.63,2.47,0.153
184.64,2.54,0.153
184.65,2.60,0.153
184.67,2.67,0.153
184.68,2.74,0.153
184.70,2.80,0.153
184.71,2.87,0.153
184.72,2.94,0.153
184.73,3.00,0.153
184.75,3.07,0.153
184.76,3.14,0.153
184.78,3.20,0.153
184.79,3.27,0.153
184.80,3.34,0.153
184.82,3.40,0.153
184.83,3.47,0.154
184.84,3.54,0.153
184.85,3.60,0.153
184.87,3.67,0.153
184.88,3.74,0.153
184.90,3.80,0.153
184.91,3.87,0.153
184.92,3.94,0.153
184.93,4.00,0.153
184.95,4.07,0.153
184.96,4.14,0.153
184.98,4.20,0.153
184.99,4.27,0.153
185.00,4.34,0.153
185.02,4.40,0.153
185.03,4.47,0.153
185.04,4.54,0.153
185.05,4.61,0.153
185.07,4.67,0.153
185.08,4.74,0.153
185.10,4.81,0.153
185.11,4.87,0.153
185.12,4.94,0.153
185.13,5.00,0.153
185.15,5.07,0.153
185.16,5.14,0.153
185.18,5.20,0.153
185.19,5.27,0.153
185.20,5.34,0.153
185.22,5.40,0.153
185.23,5.47,0.153
185.24,5.54,0.153
185.25,5.60,0.153
185.27,5.67,0.153
185.28,5.74,0.153
185.30,5.81,0.154
185.31,5.87,0.154
185.32,5.94,0.153
185.33,6.00,0.154
185.35,6.07,0.153
185.36,6.14,0.153
185.38,6.21,0.153
185.39,6.27,0.153
185.40,6.34,0.153
185.42,6.41,0.153
185.43,6.47,0.153
185.44,6.54,0.153
185.45,6.61,0.153
185.47,6.67,0.153
185.48,6.74,0.153
185.50,6.81,0.153
185.51,6.87,0.153
185.52,6.94,0.153
185.53,7.01,0.153
185.55,7.07,0.153
185.56,7.14,0.153
185.58,7.21,0.153
185.59,7.27,0.153
185.60,7.34,0.153
185.62,7.41,0.153
185.63,7.47,0.153
185.64,7.54,0.153
185.65,7.61,0.153
185.67,7.67,0.153
185.68,7.74,0.153
185.70,7.81,0.153
185.71,7.87,0.153
185.72,7.94,0.153
185.73,8.01,0.153
185.75,8.07,0.153
185.76,8.14,0.153
185.78,8.21,0.153
185.79,8.28,0.153
185.80,8.34,0.153
185.82,8.41,0.153
185.83,8.47,0.153
185.84,8.54,0.153
185.85,8.61,0.153
185.87,8.67,0.153
185.88,8.74,0.153
185.90,8.81,0.153
185.91,8.88,0.153
185.92,8.94,0.153
185.93,9.01,0.153
185.95,9.07,0.153
185.96,9.14,0.153
185.98,9.21,0.153
185.99,9.27,0.153
186.00,9.34,0.153
186.02,9.41,0.153
186.03,9.48,0.153
186.04,9.54,0.153
186.05,9.61,0.153
186.07,9.68,0.153
186.08,9.74,0.153
186.10,9.81,0.153
186.11,9.87,0.153
186.12,9.94,0.153
186.13,10.01,0.153
186.15,10.08,0.153
186.16,10.14,0.153
186.18,10.21,0.153
186.19,10.27,0.153
186.20,10.34,0.153
186.22,10.41,0.153
186.23,10.47,0.153
186.24,10.54,0.153
186.25,10.61,0.153
186.27,10.68,0.153
186.28,10.74,0.153
186.30,10.81,0.153
186.31,10.88,0.153
186.32,10.94,0.153
186.33,11.01,0.153
186.35,11.08,0.153
186.36,11.14,0.153
186.38,11.21,0.153
186.39,11.28,0.153
186.40,11.34,0.153
186.42,11.41,0.153
186.43,11.48,0.153
186.44,11.54,0.153
186.45,11.61,0.153
186.47,11.68,0.153
186.48,11.74,0.153
186.50,11.81,0.153
186.51,11.88,0.153
186.52,11.94,0.153
186.53,12.01,0.153
186.55,12.08,0.153
186.56,12.14,0.153
186.58,12.21,0.153
186.59,12.28,0.153
186.60,12.34,0.153
186.62,12.41,0.153
186.63,12.48,0.153
186.64,12.55,0.153
186.65,12.61,0.153
186.67,12.68,0.153
186.68,12.74,0.153
186.70,12.81,0.153
186.71,12.88,0.153
186.72,12.95,0.153
186.73,13.01,0.153
186.75,13.08,0.153
186.76,13.15,0.153
186.78,13.21,0.153
186.79,13.28,0.153
186.80,13.35,0.153
186.82,13.41,0.153
186.83,13.48,0.153
186.84,13.55,0.153
186.85,13.61,0.153
186.87,13.68,0.153
186.88,13.75,0.153
186.90,13.81,0.153
186.91,13.88,0.153
186.92,13.95,0.153
186.93,14.01,0.153
186.95,14.08,0.153
186.96,14.15,0.153
186.98,14.21,0.153
186.99,14.28,0.153
187.00,14.35,0.153
187.02,14.41,0.153
187.03,14.48,0.153
187.04,14.55,0.153
187.05,14.61,0.153
187.07,14.68,0.153
187.08,14.75,0.153
187.10,14.81,0.153
187.11,14.88,0.153
187.12,14.95,0.153
187.13,15.01,0.153
187.15,15.08,0.153
187.16,15.15,0.153
187.18,15.21,0.153
187.19,15.28,0.153
187.20,15.35,0.153
187.22,15.42,0.153
187.23,15.48,0.153
187.24,15.55,0.153
187.25,15.61,0.153
187.27,15.68,0.153
187.28,15.75,0.153
187.30,15.81,0.153
187.31,15.88,0.153
187.32,15.95,0.153
187.33,16.01,0.153
187.35,16.08,0.153
187.36,16.15,0.153
187.38,16.21,0.153
187.39,16.28,0.153
187.40,16.35,0.153
187.42,16.41,0.153
187.43,16.48,0.153
187.44,16.55,0.153
187.45,16.61,0.153
187.47,16.68,0.153
187.48,16.75,0.154
187.50,16.82,0.154
187.51,16.88,0.154
187.52,16.95,0.154
187.53,17.02,0.154
187.55,17.08,0.154
187.56,17.15,0.154
187.58,17.22,0.154
187.59,17.28,0.154
187.60,17.35,0.154
187.62,17.42,0.154
187.63,17.48,0.154
187.64,17.55,0.154
187.65,17.62,0.154
187.67,17.68,0.154
187.68,17.75,0.154
187.70,17.82,0.154
187.71,17.88,0.154
187.72,17.95,0.154
187.73,18.02,0.154
187.75,18.08,0.154
187.76,18.15,0.154
187.78,18.22,0.154
187.79,18.28,0.154
187.80,18.35,0.154
187.82,18.42,0.154
187.83,18.48,0.154
187.84,18.55,0.154
187.85,18.62,0.154
187.87,18.68,0.154
187.88,18.75,0.154
187.90,18.82,0.154
187.91,18.88,0.154
187.92,18.95,0.154
187.93,19.02,0.154
187.95,19.08,0.154
187.96,19.15,0.154
187.98,19.21,0.154
187.99,19.28,0.154
188.00,19.35,0.154
188.02,19.42,0.154
188.03,19.48,0.154
188.04,19.55,0.154
188.05,19.62,0.154
188.07,19.68,0.154
188.08,19.75,0.154
188.10,19.82,0.154
188.11,19.88,0.154
188.12,19.95,0.154
188.13,20.02,0.154
188.15,20.08,0.154
188.16,20.15,0.154
188.18,20.22,0.155
188.19,20.28,0.155
188.20,20.35,0.155
188.22,20.42,0.155
188.23,20.48,0.155
188.24,20.55,0.155
188.25,20.62,0.155
188.27,20.68,0.155
188.28,20.75,0.155
188.30,20.82,0.155
188.31,20.88,0.155
188.32,20.95,0.155
188.33,21.02,0.155
188.35,21.08,0.155
188.36,21.15,0.155
188.38,21.22,0.155
188.39,21.28,0.155
188.40,21.35,0.155
188.42,21.42,0.155
188.43,21.48,0.155
188.44,21.55,0.155
188.45,21.62,0.155
188.47,21.68,0.155
188.48,21.75,0.155
188.50,21.82,0.155
188.51,21.89,0.155
188.52,21.95,0.155
188.53,22.02,0.155
188.55,22.09,0.155
188.56,22.15,0.155
188.58,22.22,0.155
188.59,22.28,0.155
188.60,22.35,0.155
188.62,22.42,0.155
188.63,22.49,0.155
188.64,22.55,0.155
188.65,22.62,0.155
188.67,22.69,0.155
188.68,22.75,0.155
188.70,22.82,0.155
188.71,22.89,0.155
188.72,22.95,0.155
188.73,23.02,0.155
188.75,23.09,0.155
188.76,23.15,0.155
188.78,23.22,0.155
188.79,23.29,0.156
188.80,23.35,0.156
188.82,23.42,0.156
188.83,23.49,0.156
188.84,23.55,0.156
188.85,23.62,0.156
188.87,23.69,0.156
188.88,23.75,0.156
188.90,23.82,0.156
188.91,23.89,0.156
188.92,23.95,0.156
188.93,24.02,0.156
188.95,24.09,0.156
188.96,24.15,0.156
188.98,24.22,0.156
188.99,24.29,0.156
189.00,24.35,0.156
189.02,24.42,0.156
189.03,24.49,0.156
189.04,24.55,0.156
189.05,24.62,0.156
189.07,24.69,0.156
189.08,24.75,0.156
189.10,24.82,0.156
189.11,24.89,0.156
189.12,24.95,0.156
189.13,25.02,0.156
189.15,25.09,0.156
189.16,25.15,0.156
189.18,25.22,0.156
189.19,25.29,0.156
189.20,25.35,0.156
189.22,25.42,0.156
189.23,25.49,0.156
189.24,25.55,0.156
189.25,25.62,0.156
189.27,25.69,0.156
189.28,25.75,0.157
189.30,25.82,0.157
189.31,25.89,0.157
189.32,25.95,0.157
189.33,26.02,0.157
189.35,26.09,0.157
189.36,26.15,0.157
189.38,26.22,0.157
189.39,26.29,0.157
189.40,26.35,0.157
189.42,26.42,0.157
189.43,26.49,0.157
189.44,26.55,0.157
189.45,26.62,0.157
189.47,26.69,0.157
189.48,26.75,0.157
189.50,26.82,0.157
189.51,26.89,0.157
189.52,26.96,0.157
189.53,27.02,0.157
189.55,27.09,0.157
189.56,27.16,0.157
189.58,27.22,0.157
189.59,27.29,0.157
189.60,27.36,0.157
189.62,27.42,0.157
189.63,27.49,0.157
189.64,27.56,0.157
189.65,27.62,0.157
189.67,27.69,0.157
189.68,27.76,0.158
189.70,27.82,0.158
189.71,27.89,0.158
189.72,27.96,0.158
189.73,28.02,0.158
189.75,28.09,0.158
189.76,28.15,0.158
189.78,28.22,0.158
189.79,28.29,0.158
189.80,28.36,0.158
189.82,28.42,0.158
189.83,28.49,0.158
189.84,28.56,0.158
189.85,28.62,0.158
189.87,28.69,0.158
189.88,28.76,0.158
189.90,28.82,0.158
189.91,28.89,0.158
189.92,28.95,0.158
189.93,29.02,
189.95,29.09,
189.96,29.16,
189.98,29.22,
189.99,,