File: DSC/2025_05_29_Nifedipine_0C_190C_150C_5Cmin_x3.csv
Filename,2025_05_29_Nifedipine_0C_190C_150C_5Cmin_x3
Instrument name,DSC2A-00468 (192.168.1.100)
Operator,Yarger
rundate,5/29/2025
Sample name,2025_05_29_Nifedipine_0C_190C_150C_5Cmin_x3
proceduresegments,Data Off ; Equilibrate 0.00 °C; Data On ; Ramp 5.00 °C/min to 190.00 °C; Data Off ; Isothermal 1.0 min; Data On ; Ramp 20.00 °C/min to 0.00 °C; Data Off ; Isothermal 2.0 min; Data On ; Ramp 5.00 °C/min to 190.00 °C; Data Off ; Isothermal 1.0 min; Data On ; Ramp 20.00 °C/min to 0.00 °C; Data Off ; Isothermal 2.0 min; Ramp 5.00 °C/min to 140.00 °C; Data Off ; Isothermal 1.0 min; Data On ; Ramp 20.00 °C/min to 0.00 °C; Data Off ; Isothermal 2.0 min; Data On ; Ramp 5.00 °C/min to 30.00 °C
[File Parameters]
Run date,5/29/2025 8:50:57 PM
Trios version,5.1.1.46572
Original File Name,
Current File Name,D:\DSC2500\JYarger\2025_05_29_Nifedipine_0C_190C_150C_5Cmin_x3.tri
[Procedure]
Procedure Name,Nidedipine_0C_190C_140C_5Cmin_x4
Sample Name,2025_05_29_Nifedipine_0C_190C_150C_5Cmin_x3
Sample Mass,28.14 mg
Reference Sample Mass,0 mg
Pan Mass,55.89 mg
Pan Number,4
Reference Pan Mass,55.79 mg
Reference Pan Number,1
Pan Type,Tzero Aluminum Hermetic
Comments,Al Hermetic DSC Consumables sealed Pan/Lid. A2 Tray (Google Sheet: DSC_Samples_A2_Tray_May2025)
Project Name,CA
Operator,Yarger
Test,Custom
Unload Max Temperature,30
Unload Min Temperature,30
Load Max Temperature,30
Load Min Temperature,30
Stop on Gas Flow Error,Yes
[Signal List]
Signal #1,Time (min)
Signal #2,Temperature (°C)
Signal #3,Heat Flow (mW)
Signal #4,Delta T (µV)
Signal #5,Delta Tzero (µV)
Signal #6,Tzero Temperature (°C)
Signal #7,Cell Purge (mL/min)
Signal #8,Heater Temp (°C)
Signal #9,Power Delivered (W)
Signal #10,Reference Junction Temperature (°C)
Signal #11,Flange Temperature (°C)
Signal #12,Heat Flow Phase (rad)
Signal #13,Total Heat Capacity (J/°C)
Signal #14,Heat Capacity (J/°C)
[Configuration]
Company Name,ASU
Instrument Name,DSC2A-00468
Instrument Type,DSC2500
Serial Number,DSC2A-00468
IP,192.168.1.100
Location of Instrument,MRRC
DisplayType,Unknown
Sample Interval ,0.1 s/pt
Selected Heat Flow,T4P
Exotherm Direction,Down
Cell Serial,DRC2-00792
Lid Type,Standard
Cooler,RCS 90
Leave Cooler on at End of Sequence,On
Gas 2,Nitrogen
Gas Selected,Channel 1
Flow Rate,50 mL/min
Secondary Purge,On
Licensed Heat Flow,Heat Flow T4P
Modulation Licensed,Yes
[Versions]
Common IDD Version,1
Cortex Version,VER 2.10.2.31
Driver,5.0.0.6
GDM Version,1.0.3.3
TouchscreenVersion,1.0.0.16145
FEP Version,1.2.1.21
FEP Bootloader,2.0.0.5
AutoSampler Version,2.1.1.26
Auto Sampler Bootloader,2.0.0.5
FCM Version,1.1.0.3
FCM Bootloader,2.0.0.5
[Experiment Logs]
Experiment Log Entry # 1,Data On set to 0
Experiment Log Entry # 3,Equilibrate Segment 0 (C) Started
Experiment Log Entry # 5,Air Cool is off.
Experiment Log Entry # 7,Data On set to 1
Experiment Log Entry # 9,Ramp Segment 5 C/min to 190 Started
Experiment Log Entry # 11,Data On set to 0
Experiment Log Entry # 13,Isothermal Segment 1 min started
Experiment Log Entry # 15,Data On set to 1
Experiment Log Entry # 17,Ramp Segment 20 C/min to 0 Started
Experiment Log Entry # 19,Data On set to 0
Experiment Log Entry # 21,Isothermal Segment 2 min started
Experiment Log Entry # 23,Data On set to 1
Experiment Log Entry # 25,Ramp Segment 5 C/min to 190 Started
Experiment Log Entry # 27,Data On set to 0
Experiment Log Entry # 29,Isothermal Segment 1 min started
Experiment Log Entry # 31,Data On set to 1
Experiment Log Entry # 33,Ramp Segment 20 C/min to 0 Started
Experiment Log Entry # 35,Data On set to 0
Experiment Log Entry # 37,Isothermal Segment 2 min started
Experiment Log Entry # 39,Ramp Segment 5 C/min to 140 Started
Experiment Log Entry # 41,Data On set to 0
Experiment Log Entry # 43,Isothermal Segment 1 min started
Experiment Log Entry # 45,Data On set to 1
Experiment Log Entry # 47,Ramp Segment 20 C/min to 0 Started
Experiment Log Entry # 49,Data On set to 0
Experiment Log Entry # 51,Isothermal Segment 2 min started
Experiment Log Entry # 53,Data On set to 1
Experiment Log Entry # 55,Ramp Segment 5 C/min to 30 Started
[Method Log]
Method Log Entry # 1,Data Off
Method Log Entry # 2,Equilibrate 0 °C
Method Log Entry # 3,Data On
Method Log Entry # 4,(Ramp 489875) Ramp 5 °C/minute to 190 °C
Method Log Entry # 5,Data Off
Method Log Entry # 6,Isothermal 1 minutes
Method Log Entry # 7,Data On
Method Log Entry # 8,(Ramp 489879) Ramp 20 °C/minute to 0 °C
Method Log Entry # 9,Data Off
Method Log Entry # 10,Isothermal 2 minutes
Method Log Entry # 11,Data On
Method Log Entry # 12,(Ramp 489883) Ramp 5 °C/minute to 190 °C
Method Log Entry # 13,Data Off
Method Log Entry # 14,Isothermal 1 minutes
Method Log Entry # 15,Data On
Method Log Entry # 16,(Ramp 489887) Ramp 20 °C/minute to 0 °C
Method Log Entry # 17,Data Off
Method Log Entry # 18,Isothermal 2 minutes
Method Log Entry # 19,(Ramp 489890) Ramp 5 °C/minute to 140 °C
Method Log Entry # 20,Data Off
Method Log Entry # 21,Isothermal 1 minutes
Method Log Entry # 22,Data On
Method Log Entry # 23,(Ramp 489894) Ramp 20 °C/minute to 0 °C
Method Log Entry # 24,Data Off
Method Log Entry # 25,Isothermal 2 minutes
Method Log Entry # 26,Data On
Method Log Entry # 27,(Ramp 489898) Ramp 5 °C/minute to 30 °C
Cell Serial,DRC2-00792
[T1 Calibration]
Slope,-0.008529666
Offset,9.636258
Initial Temperature,98.23
GUID,f8bfdadc-4977-4fdf-ba6d-0ba9134940c3
[TZero Calibration]
Date Applied,11/29/2022 4:06:13 PM
Description,From -89.059 °C to 396.009 °C at 20.000°C/min
Gas Type,Nitrogen
Pan Type,None
Source Files 1,C:\Users\yargerlab\Desktop\DSC Data\General\TZero_calibration_11_29_22_2nd(2).tri
Source Files 2,C:\Users\yargerlab\Desktop\DSC Data\General\TZero_calibration_11_29_22_2nd(3).tri
Delta T Offset,13.05235
Delta T Slope,-0.007271007
Delta T0 Offset,-13.69128
Delta T0 Slope,0.06063341
[Temperature Calibration]
Date Applied,11/29/2022 7:12:28 PM
Description,From 106.590 °C to 186.590 °C at 10.000°C/min
Gas Type,Nitrogen
Pan Type,Tzero Aluminum Hermetic
Source Files 1,C:\Users\yargerlab\Desktop\DSC Data\General\Indium(6).tri
Measured 1,157.391
Known 1,156.598
[Cell Constant Calibration]
Date Applied,11/29/2022 7:12:29 PM
Description,From 106.590 °C to 186.590 °C at 10.000°C/min
Gas Type,Nitrogen
Pan Type,Tzero Aluminum Hermetic
Source Files 1,C:\Users\yargerlab\Desktop\DSC Data\General\Indium(6).tri
T4P KCell,1.006051
Onset Slope,63.26126 mW/°C
[Direct Cp Calibration]
Date Applied,11/30/2022 11:04:51 AM
Description,From -79.983 °C to 298.409 °C at 10.000°C/min
Gas Type,Nitrogen
Pan Type,Tzero Aluminum Hermetic
Source Files 1,C:\Users\yargerlab\Desktop\DSC Data\General\Sapphire_Heat_Capacity_11_30_22.tri
[Rev Cp Calibration]
Date Applied,11/30/2022 1:58:51 PM
Description,From -79.996 °C to 292.812 °C at 3.000°C/min
Gas Type,Nitrogen
Pan Type,Tzero Aluminum Hermetic
Source Files 1,C:\Users\yargerlab\Desktop\DSC Data\General\Sapphire_MDSC_Calibration_11_30_22.tri
[step]
Ramp 5.00 °C/min to 190.00 °C
Time,Temperature,Heat Flow (Normalized)
min,°C,W/g
0.00,0.25,-0.061
0.03,0.23,-0.059
0.05,0.22,-0.053
0.08,0.22,-0.048
0.11,0.24,-0.047
0.13,0.29,-0.045
0.16,0.36,-0.040
0.19,0.43,-0.031
0.21,0.52,-0.020
0.24,0.61,-0.010
0.27,0.70,0.000
0.29,0.79,0.009
0.32,0.90,0.017
0.35,1.00,0.024
0.37,1.11,0.030
0.40,1.22,0.036
0.43,1.33,0.041
0.45,1.45,0.046
0.48,1.57,0.051
0.51,1.68,0.054
0.53,1.81,0.057
0.56,1.93,0.060
0.59,2.05,0.063
0.61,2.17,0.065
0.64,2.30,0.067
0.67,2.42,0.069
0.69,2.55,0.070
0.72,2.68,0.071
0.75,2.81,0.073
0.77,2.93,0.074
0.80,3.06,0.075
0.83,3.19,0.076
0.85,3.32,0.077
0.88,3.45,0.077
0.91,3.58,0.078
0.93,3.71,0.078
0.96,3.84,0.079
0.99,3.97,0.079
1.01,4.11,0.079
1.04,4.24,0.080
1.07,4.37,0.080
1.09,4.50,0.081
1.12,4.63,0.081
1.15,4.76,0.081
1.17,4.90,0.081
1.20,5.03,0.081
1.23,5.16,0.081
1.25,5.29,0.082
1.28,5.43,0.082
1.31,5.56,0.082
1.33,5.69,0.082
1.36,5.82,0.082
1.39,5.96,0.082
1.41,6.09,0.082
1.44,6.22,0.083
1.47,6.36,0.083
1.49,6.49,0.083
1.52,6.62,0.083
1.55,6.75,0.083
1.57,6.89,0.083
1.60,7.02,0.083
1.63,7.15,0.083
1.65,7.29,0.083
1.68,7.42,0.083
1.71,7.55,0.084
1.73,7.69,0.084
1.76,7.82,0.084
1.79,7.95,0.084
1.81,8.09,0.084
1.84,8.22,0.084
1.87,8.35,0.084
1.89,8.49,0.084
1.92,8.62,0.084
1.95,8.75,0.084
1.97,8.89,0.084
2.00,9.02,0.084
2.03,9.15,0.084
2.05,9.28,0.084
2.08,9.42,0.084
2.11,9.55,0.084
2.13,9.68,0.084
2.16,9.82,0.084
2.19,9.95,0.084
2.21,10.08,0.084
2.24,10.22,0.085
2.27,10.35,0.085
2.29,10.49,0.085
2.32,10.62,0.085
2.35,10.75,0.085
2.37,10.89,0.085
2.40,11.02,0.085
2.43,11.15,0.085
2.45,11.29,0.085
2.48,11.42,0.085
2.51,11.55,0.085
2.53,11.69,0.085
2.56,11.82,0.085
2.59,11.95,0.085
2.61,12.09,0.085
2.64,12.22,0.085
2.67,12.35,0.085
2.69,12.48,0.085
2.72,12.62,0.085
2.75,12.75,0.085
2.77,12.89,0.085
2.80,13.02,0.085
2.83,13.15,0.085
2.85,13.28,0.085
2.88,13.42,0.085
2.91,13.55,0.085
2.93,13.69,0.085
2.96,13.82,0.085
2.99,13.95,0.085
3.01,14.09,0.085
3.04,14.22,0.085
3.07,14.35,0.085
3.09,14.49,0.086
3.12,14.62,0.086
3.15,14.75,0.086
3.17,14.89,0.086
3.20,15.02,0.086
3.23,15.15,0.086
3.25,15.29,0.086
3.28,15.42,0.086
3.31,15.55,0.086
3.33,15.69,0.086
3.36,15.82,0.086
3.39,15.95,0.086
3.41,16.09,0.086
3.44,16.22,0.086
3.47,16.35,0.086
3.49,16.49,0.086
3.52,16.62,0.086
3.55,16.75,0.086
3.57,16.89,0.086
3.60,17.02,0.086
3.63,17.15,0.086
3.65,17.29,0.086
3.68,17.42,0.086
3.71,17.55,0.086
3.73,17.69,0.086
3.76,17.82,0.086
3.79,17.96,0.086
3.81,18.09,0.086
3.84,18.22,0.086
3.87,18.36,0.086
3.89,18.49,0.086
3.92,18.62,0.086
3.95,18.76,0.086
3.97,18.89,0.087
4.00,19.02,0.087
4.03,19.16,0.087
4.05,19.29,0.087
4.08,19.42,0.087
4.11,19.56,0.087
4.13,19.69,0.087
4.16,19.82,0.087
4.19,19.96,0.087
4.21,20.09,0.087
4.24,20.22,0.087
4.27,20.36,0.087
4.29,20.49,0.087
4.32,20.62,0.087
4.35,20.76,0.087
4.37,20.89,0.087
4.40,21.02,0.087
4.43,21.16,0.087
4.45,21.29,0.087
4.48,21.42,0.087
4.51,21.56,0.087
4.53,21.69,0.087
4.56,21.82,0.087
4.59,21.96,0.087
4.61,22.09,0.087
4.64,22.22,0.087
4.67,22.36,0.087
4.69,22.49,0.087
4.72,22.62,0.087
4.75,22.76,0.087
4.77,22.89,0.087
4.80,23.02,0.087
4.83,23.16,0.087
4.85,23.29,0.087
4.88,23.42,0.087
4.91,23.56,0.088
4.93,23.69,0.088
4.96,23.83,0.088
4.99,23.96,0.088
5.01,24.09,0.088
5.04,24.23,0.088
5.07,24.36,0.088
5.09,24.49,0.088
5.12,24.63,0.088
5.15,24.76,0.088
5.17,24.89,0.088
5.20,25.03,0.088
5.23,25.16,0.088
5.25,25.29,0.088
5.28,25.42,0.088
5.31,25.56,0.088
5.33,25.69,0.088
5.36,25.83,0.088
5.39,25.96,0.088
5.41,26.09,0.088
5.44,26.23,0.088
5.47,26.36,0.088
5.49,26.49,0.088
5.52,26.63,0.088
5.55,26.76,0.088
5.57,26.89,0.088
5.60,27.03,0.088
5.63,27.16,0.088
5.65,27.29,0.088
5.68,27.43,0.088
5.71,27.56,0.088
5.73,27.69,0.088
5.76,27.83,0.088
5.79,27.96,0.089
5.81,28.10,0.089
5.84,28.23,0.089
5.87,28.36,0.089
5.89,28.49,0.089
5.92,28.63,0.089
5.95,28.76,0.089
5.97,28.89,0.089
6.00,29.03,0.089
6.03,29.16,0.089
6.05,29.29,0.089
6.08,29.43,0.089
6.11,29.56,0.089
6.13,29.70,0.089
6.16,29.83,0.089
6.19,29.96,0.089
6.21,30.10,0.089
6.24,30.23,0.089
6.27,30.36,0.089
6.29,30.50,0.089
6.32,30.63,0.089
6.35,30.76,0.089
6.37,30.90,0.089
6.40,31.03,0.089
6.43,31.16,0.089
6.45,31.30,0.089
6.48,31.43,0.089
6.51,31.56,0.089
6.53,31.70,0.089
6.56,31.83,0.089
6.59,31.96,0.089
6.61,32.10,0.089
6.64,32.23,0.089
6.67,32.36,0.089
6.69,32.50,0.089
6.72,32.63,0.089
6.75,32.76,0.090
6.77,32.90,0.090
6.80,33.03,0.090
6.83,33.16,0.090
6.85,33.30,0.090
6.88,33.43,0.090
6.91,33.56,0.090
6.93,33.70,0.090
6.96,33.83,0.090
6.99,33.96,0.090
7.01,34.10,0.090
7.04,34.23,0.090
7.07,34.36,0.090
7.09,34.50,0.090
7.12,34.63,0.090
7.15,34.76,0.090
7.17,34.90,0.090
7.20,35.03,0.090
7.23,35.17,0.090
7.25,35.30,0.090
7.28,35.43,0.090
7.31,35.57,0.090
7.33,35.70,0.090
7.36,35.83,0.090
7.39,35.97,0.090
7.41,36.10,0.090
7.44,36.23,0.090
7.47,36.37,0.090
7.49,36.50,0.090
7.52,36.63,0.090
7.55,36.77,0.090
7.57,36.90,0.090
7.60,37.03,0.090
7.63,37.17,0.090
7.65,37.30,0.090
7.68,37.43,0.091
7.71,37.57,0.091
7.73,37.70,0.091
7.76,37.83,0.091
7.79,37.97,0.091
7.81,38.10,0.091
7.84,38.23,0.091
7.87,38.37,0.091
7.89,38.50,0.091
7.92,38.63,0.091
7.95,38.77,0.091
7.97,38.90,0.091
8.00,39.03,0.091
8.03,39.17,0.091
8.05,39.30,0.091
8.08,39.43,0.091
8.11,39.57,0.091
8.13,39.70,0.091
8.16,39.84,0.091
8.19,39.97,0.091
8.21,40.10,0.091
8.24,40.23,0.091
8.27,40.37,0.091
8.29,40.50,0.091
8.32,40.63,0.091
8.35,40.77,0.091
8.37,40.90,0.091
8.40,41.04,0.091
8.43,41.17,0.091
8.45,41.30,0.091
8.48,41.44,0.091
8.51,41.57,0.091
8.53,41.70,0.091
8.56,41.84,0.091
8.59,41.97,0.092
8.61,42.10,0.092
8.64,42.24,0.092
8.67,42.37,0.092
8.69,42.50,0.092
8.72,42.64,0.092
8.75,42.77,0.092
8.77,42.90,0.092
8.80,43.04,0.092
8.83,43.17,0.092
8.85,43.30,0.092
8.88,43.44,0.092
8.91,43.57,0.092
8.93,43.70,0.092
8.96,43.84,0.092
8.99,43.97,0.092
9.01,44.10,0.092
9.04,44.24,0.092
9.07,44.37,0.092
9.09,44.50,0.092
9.12,44.64,0.092
9.15,44.77,0.092
9.17,44.90,0.092
9.20,45.04,0.092
9.23,45.17,0.092
9.25,45.30,0.092
9.28,45.44,0.092
9.31,45.57,0.092
9.33,45.70,0.092
9.36,45.84,0.092
9.39,45.97,0.092
9.41,46.10,0.092
9.44,46.24,0.092
9.47,46.37,0.093
9.49,46.51,0.093
9.52,46.64,0.093
9.55,46.77,0.093
9.57,46.90,0.093
9.60,47.04,0.093
9.63,47.17,0.093
9.65,47.30,0.093
9.68,47.44,0.093
9.71,47.57,0.093
9.73,47.71,0.093
9.76,47.84,0.093
9.79,47.97,0.093
9.81,48.10,0.093
9.84,48.24,0.093
9.87,48.37,0.093
9.89,48.51,0.093
9.92,48.64,0.093
9.95,48.77,0.093
9.97,48.91,0.093
10.00,49.04,0.093
10.03,49.17,0.093
10.05,49.31,0.093
10.08,49.44,0.093
10.11,49.57,0.093
10.13,49.71,0.093
10.16,49.84,0.093
10.19,49.97,0.093
10.21,50.11,0.093
10.24,50.24,0.093
10.27,50.37,0.093
10.29,50.51,0.093
10.32,50.64,0.093
10.35,50.77,0.094
10.37,50.91,0.094
10.40,51.04,0.094
10.43,51.17,0.094
10.45,51.31,0.094
10.48,51.44,0.094
10.51,51.57,0.094
10.53,51.71,0.094
10.56,51.84,0.094
10.59,51.97,0.094
10.61,52.11,0.094
10.64,52.24,0.094
10.67,52.37,0.094
10.69,52.51,0.094
10.72,52.64,0.094
10.75,52.77,0.094
10.77,52.91,0.094
10.80,53.04,0.094
10.83,53.17,0.094
10.85,53.31,0.094
10.88,53.44,0.094
10.91,53.57,0.094
10.93,53.71,0.094
10.96,53.84,0.094
10.99,53.97,0.094
11.01,54.11,0.094
11.04,54.24,0.094
11.07,54.37,0.094
11.09,54.51,0.094
11.12,54.64,0.094
11.15,54.78,0.094
11.17,54.91,0.094
11.20,55.04,0.094
11.23,55.17,0.094
11.25,55.31,0.094
11.28,55.44,0.095
11.31,55.58,0.095
11.33,55.71,0.095
11.36,55.84,0.095
11.39,55.98,0.095
11.41,56.11,0.095
11.44,56.24,0.095
11.47,56.38,0.095
11.49,56.51,0.095
11.52,56.64,0.095
11.55,56.78,0.095
11.57,56.91,0.095
11.60,57.04,0.095
11.63,57.18,0.095
11.65,57.31,0.095
11.68,57.44,0.095
11.71,57.58,0.095
11.73,57.71,0.095
11.76,57.84,0.095
11.79,57.98,0.095
11.81,58.11,0.095
11.84,58.24,0.095
11.87,58.38,0.095
11.89,58.51,0.095
11.92,58.64,0.095
11.95,58.78,0.095
11.97,58.91,0.095
12.00,59.04,0.095
12.03,59.18,0.095
12.05,59.31,0.095
12.08,59.45,0.095
12.11,59.58,0.095
12.13,59.71,0.095
12.16,59.85,0.095
12.19,59.98,0.095
12.21,60.11,0.095
12.24,60.25,0.095
12.27,60.38,0.095
12.29,60.51,0.095
12.32,60.65,0.095
12.35,60.78,0.096
12.37,60.91,0.096
12.40,61.05,0.096
12.43,61.18,0.096
12.45,61.31,0.096
12.48,61.45,0.096
12.51,61.58,0.096
12.53,61.71,0.096
12.56,61.85,0.096
12.59,61.98,0.096
12.61,62.11,0.096
12.64,62.25,0.096
12.67,62.38,0.096
12.69,62.51,0.096
12.72,62.65,0.096
12.75,62.78,0.096
12.77,62.91,0.096
12.80,63.05,0.096
12.83,63.18,0.096
12.85,63.31,0.096
12.88,63.45,0.096
12.91,63.58,0.096
12.93,63.71,0.096
12.96,63.85,0.096
12.99,63.98,0.096
13.01,64.11,0.096
13.04,64.25,0.096
13.07,64.38,0.096
13.09,64.51,0.096
13.12,64.65,0.096
13.15,64.78,0.096
13.17,64.91,0.096
13.20,65.05,0.096
13.23,65.18,0.096
13.25,65.31,0.096
13.28,65.45,0.097
13.31,65.58,0.097
13.33,65.71,0.097
13.36,65.85,0.097
13.39,65.98,0.097
13.41,66.11,0.097
13.44,66.25,0.097
13.47,66.38,0.097
13.49,66.52,0.097
13.52,66.65,0.097
13.55,66.78,0.097
13.57,66.91,0.097
13.60,67.05,0.097
13.63,67.18,0.097
13.65,67.32,0.097
13.68,67.45,0.097
13.71,67.58,0.097
13.73,67.72,0.097
13.76,67.85,0.097
13.79,67.98,0.097
13.81,68.12,0.097
13.84,68.25,0.097
13.87,68.38,0.097
13.89,68.52,0.097
13.92,68.65,0.097
13.95,68.78,0.097
13.97,68.92,0.097
14.00,69.05,0.097
14.03,69.18,0.097
14.05,69.32,0.097
14.08,69.45,0.097
14.11,69.58,0.097
14.13,69.72,0.097
14.16,69.85,0.097
14.19,69.98,0.097
14.21,70.12,0.097
14.24,70.25,0.097
14.27,70.38,0.097
14.29,70.52,0.098
14.32,70.65,0.098
14.35,70.78,0.098
14.37,70.92,0.098
14.40,71.05,0.098
14.43,71.18,0.098
14.45,71.32,0.098
14.48,71.45,0.098
14.51,71.58,0.098
14.53,71.72,0.098
14.56,71.85,0.098
14.59,71.98,0.098
14.61,72.12,0.098
14.64,72.25,0.098
14.67,72.38,0.098
14.69,72.52,0.098
14.72,72.65,0.098
14.75,72.78,0.098
14.77,72.92,0.098
14.80,73.05,0.098
14.83,73.18,0.098
14.85,73.32,0.098
14.88,73.45,0.098
14.91,73.58,0.098
14.93,73.72,0.098
14.96,73.85,0.098
14.99,73.99,0.098
15.01,74.12,0.098
15.04,74.25,0.098
15.07,74.39,0.098
15.09,74.52,0.098
15.12,74.65,0.098
15.15,74.79,0.099
15.17,74.92,0.099
15.20,75.05,0.099
15.23,75.18,0.099
15.25,75.32,0.099
15.28,75.45,0.099
15.31,75.59,0.099
15.33,75.72,0.099
15.36,75.85,0.099
15.39,75.99,0.099
15.41,76.12,0.099
15.44,76.25,0.099
15.47,76.39,0.099
15.49,76.52,0.099
15.52,76.65,0.099
15.55,76.79,0.099
15.57,76.92,0.099
15.60,77.05,0.099
15.63,77.19,0.099
15.65,77.32,0.099
15.68,77.45,0.099
15.71,77.59,0.099
15.73,77.72,0.099
15.76,77.85,0.099
15.79,77.99,0.099
15.81,78.12,0.099
15.84,78.25,0.099
15.87,78.39,0.099
15.89,78.52,0.099
15.92,78.65,0.099
15.95,78.79,0.099
15.97,78.92,0.099
16.00,79.05,0.099
16.03,79.19,0.099
16.05,79.32,0.099
16.08,79.45,0.099
16.11,79.59,0.100
16.13,79.72,0.100
16.16,79.85,0.100
16.19,79.99,0.100
16.21,80.12,0.100
16.24,80.25,0.100
16.27,80.39,0.100
16.29,80.52,0.100
16.32,80.65,0.100
16.35,80.79,0.100
16.37,80.92,0.100
16.40,81.05,0.100
16.43,81.19,0.100
16.45,81.32,0.100
16.48,81.46,0.100
16.51,81.59,0.100
16.53,81.72,0.100
16.56,81.85,0.100
16.59,81.99,0.100
16.61,82.12,0.100
16.64,82.25,0.100
16.67,82.39,0.100
16.69,82.52,0.100
16.72,82.66,0.100
16.75,82.79,0.100
16.77,82.92,0.100
16.80,83.06,0.100
16.83,83.19,0.100
16.85,83.32,0.100
16.88,83.46,0.100
16.91,83.59,0.100
16.93,83.72,0.100
16.96,83.86,0.100
16.99,83.99,0.100
17.01,84.12,0.100
17.04,84.26,0.100
17.07,84.39,0.100
17.09,84.52,0.100
17.12,84.66,0.100
17.15,84.79,0.101
17.17,84.92,0.101
17.20,85.06,0.101
17.23,85.19,0.101
17.25,85.32,0.101
17.28,85.46,0.101
17.31,85.59,0.101
17.33,85.72,0.101
17.36,85.86,0.101
17.39,85.99,0.101
17.41,86.12,0.101
17.44,86.26,0.101
17.47,86.39,0.101
17.49,86.52,0.101
17.52,86.66,0.101
17.55,86.79,0.101
17.57,86.92,0.101
17.60,87.06,0.101
17.63,87.19,0.101
17.65,87.33,0.101
17.68,87.46,0.101
17.71,87.59,0.101
17.73,87.72,0.101
17.76,87.86,0.101
17.79,87.99,0.101
17.81,88.13,0.101
17.84,88.26,0.101
17.87,88.39,0.101
17.89,88.53,0.101
17.92,88.66,0.101
17.95,88.79,0.101
17.97,88.93,0.101
18.00,89.06,0.101
18.03,89.19,0.101
18.05,89.33,0.101
18.08,89.46,0.101
18.11,89.59,0.101
18.13,89.73,0.101
18.16,89.86,0.101
18.19,89.99,0.102
18.21,90.13,0.102
18.24,90.26,0.102
18.27,90.39,0.102
18.29,90.53,0.102
18.32,90.66,0.102
18.35,90.79,0.102
18.37,90.93,0.102
18.40,91.06,0.102
18.43,91.19,0.102
18.45,91.33,0.102
18.48,91.46,0.102
18.51,91.59,0.102
18.53,91.73,0.102
18.56,91.86,0.102
18.59,91.99,0.102
18.61,92.13,0.102
18.64,92.26,0.102
18.67,92.39,0.102
18.69,92.53,0.102
18.72,92.66,0.102
18.75,92.79,0.102
18.77,92.93,0.102
18.80,93.06,0.102
18.83,93.19,0.102
18.85,93.33,0.102
18.88,93.46,0.102
18.91,93.59,0.102
18.93,93.73,0.102
18.96,93.86,0.102
18.99,93.99,0.102
19.01,94.13,0.102
19.04,94.26,0.102
19.07,94.39,0.102
19.09,94.53,0.103
19.12,94.66,0.103
19.15,94.79,0.103
19.17,94.93,0.103
19.20,95.06,0.103
19.23,95.20,0.103
19.25,95.33,0.103
19.28,95.46,0.103
19.31,95.60,0.103
19.33,95.73,0.103
19.36,95.86,0.103
19.39,95.99,0.103
19.41,96.13,0.103
19.44,96.26,0.103
19.47,96.40,0.103
19.49,96.53,0.103
19.52,96.66,0.103
19.55,96.79,0.103
19.57,96.93,0.103
19.60,97.06,0.103
19.63,97.19,0.103
19.65,97.33,0.103
19.68,97.46,0.103
19.71,97.60,0.103
19.73,97.73,0.103
19.76,97.86,0.103
19.79,98.00,0.103
19.81,98.13,0.103
19.84,98.26,0.103
19.87,98.40,0.103
19.89,98.53,0.103
19.92,98.66,0.103
19.95,98.80,0.103
19.97,98.93,0.103
20.00,99.06,0.103
20.03,99.20,0.103
20.05,99.33,0.104
20.08,99.46,0.104
20.11,99.60,0.104
20.13,99.73,0.104
20.16,99.86,0.104
20.19,100.00,0.104
20.21,100.13,0.104
20.24,100.26,0.104
20.27,100.40,0.104
20.29,100.53,0.104
20.32,100.66,0.104
20.35,100.80,0.104
20.37,100.93,0.104
20.40,101.06,0.104
20.43,101.20,0.104
20.45,101.33,0.104
20.48,101.46,0.104
20.51,101.60,0.104
20.53,101.73,0.104
20.56,101.86,0.104
20.59,102.00,0.104
20.61,102.13,0.104
20.64,102.26,0.104
20.67,102.40,0.104
20.69,102.53,0.104
20.72,102.67,0.104
20.75,102.80,0.104
20.77,102.93,0.104
20.80,103.07,0.104
20.83,103.20,0.104
20.85,103.33,0.104
20.88,103.47,0.104
20.91,103.60,0.104
20.93,103.73,0.104
20.96,103.87,0.104
20.99,104.00,0.104
21.01,104.13,0.104
21.04,104.27,0.104
21.07,104.40,0.105
21.09,104.53,0.105
21.12,104.67,0.105
21.15,104.80,0.105
21.17,104.93,0.105
21.20,105.06,0.105
21.23,105.20,0.105
21.25,105.33,0.105
21.28,105.47,0.105
21.31,105.60,0.105
21.33,105.73,0.105
21.36,105.87,0.105
21.39,106.00,0.105
21.41,106.13,0.105
21.44,106.27,0.105
21.47,106.40,0.105
21.49,106.53,0.105
21.52,106.67,0.105
21.55,106.80,0.105
21.57,106.93,0.105
21.60,107.07,0.105
21.63,107.20,0.105
21.65,107.33,0.105
21.68,107.47,0.105
21.71,107.60,0.105
21.73,107.73,0.105
21.76,107.87,0.105
21.79,108.00,0.105
21.81,108.13,0.105
21.84,108.27,0.105
21.87,108.40,0.105
21.89,108.53,0.105
21.92,108.67,0.105
21.95,108.80,0.105
21.97,108.93,0.105
22.00,109.07,0.105
22.03,109.20,0.105
22.05,109.33,0.105
22.08,109.47,0.105
22.11,109.60,0.105
22.13,109.73,0.105
22.16,109.87,0.105
22.19,110.00,0.105
22.21,110.13,0.106
22.24,110.27,0.106
22.27,110.40,0.106
22.29,110.53,0.106
22.32,110.67,0.106
22.35,110.80,0.106
22.37,110.93,0.106
22.40,111.07,0.106
22.43,111.20,0.106
22.45,111.33,0.106
22.48,111.47,0.106
22.51,111.60,0.106
22.53,111.73,0.106
22.56,111.87,0.106
22.59,112.00,0.106
22.61,112.13,0.106
22.64,112.27,0.106
22.67,112.40,0.106
22.69,112.54,0.106
22.72,112.67,0.106
22.75,112.80,0.106
22.77,112.93,0.106
22.80,113.07,0.106
22.83,113.20,0.106
22.85,113.33,0.106
22.88,113.47,0.106
22.91,113.60,0.106
22.93,113.73,0.106
22.96,113.87,0.106
22.99,114.00,0.106
23.01,114.13,0.106
23.04,114.27,0.106
23.07,114.40,0.106
23.09,114.53,0.106
23.12,114.67,0.106
23.15,114.80,0.106
23.17,114.94,0.107
23.20,115.07,0.107
23.23,115.20,0.107
23.25,115.34,0.107
23.28,115.47,0.107
23.31,115.60,0.107
23.33,115.74,0.107
23.36,115.87,0.107
23.39,116.00,0.107
23.41,116.14,0.107
23.44,116.27,0.107
23.47,116.40,0.107
23.49,116.54,0.107
23.52,116.67,0.107
23.55,116.80,0.107
23.57,116.94,0.107
23.60,117.07,0.107
23.63,117.20,0.107
23.65,117.34,0.107
23.68,117.47,0.107
23.71,117.60,0.107
23.73,117.74,0.107
23.76,117.87,0.107
23.79,118.00,0.107
23.81,118.14,0.107
23.84,118.27,0.107
23.87,118.40,0.107
23.89,118.54,0.107
23.92,118.67,0.107
23.95,118.80,0.107
23.97,118.94,0.107
24.00,119.07,0.107
24.03,119.20,0.107
24.05,119.34,0.107
24.08,119.47,0.107
24.11,119.60,0.107
24.13,119.74,0.107
24.16,119.87,0.107
24.19,120.00,0.107
24.21,120.14,0.108
24.24,120.27,0.108
24.27,120.40,0.108
24.29,120.54,0.108
24.32,120.67,0.108
24.35,120.80,0.108
24.37,120.94,0.108
24.40,121.07,0.108
24.43,121.20,0.108
24.45,121.34,0.108
24.48,121.48,0.108
24.51,121.61,0.108
24.53,121.74,0.108
24.56,121.88,0.108
24.59,122.01,0.108
24.61,122.14,0.109
24.64,122.27,0.108
24.67,122.41,0.108
24.69,122.54,0.108
24.72,122.67,0.108
24.75,122.81,0.108
24.77,122.94,0.108
24.80,123.07,0.108
24.83,123.21,0.108
24.85,123.34,0.108
24.88,123.47,0.108
24.91,123.61,0.108
24.93,123.74,0.108
24.96,123.87,0.108
24.99,124.01,0.108
25.01,124.14,0.108
25.04,124.27,0.108
25.07,124.41,0.108
25.09,124.54,0.108
25.12,124.67,0.108
25.15,124.81,0.108
25.17,124.94,0.108
25.20,125.07,0.108
25.23,125.21,0.108
25.25,125.34,0.108
25.28,125.47,0.108
25.31,125.61,0.108
25.33,125.74,0.108
25.36,125.87,0.109
25.39,126.01,0.109
25.41,126.14,0.109
25.44,126.27,0.109
25.47,126.41,0.109
25.49,126.54,0.109
25.52,126.67,0.109
25.55,126.81,0.109
25.57,126.94,0.109
25.60,127.07,0.109
25.63,127.21,0.109
25.65,127.34,0.109
25.68,127.47,0.109
25.71,127.61,0.109
25.73,127.74,0.109
25.76,127.88,0.109
25.79,128.01,0.109
25.81,128.14,0.109
25.84,128.27,0.109
25.87,128.41,0.109
25.89,128.54,0.109
25.92,128.67,0.109
25.95,128.81,0.109
25.97,128.94,0.109
26.00,129.07,0.109
26.03,129.21,0.109
26.05,129.34,0.109
26.08,129.47,0.109
26.11,129.61,0.109
26.13,129.74,0.109
26.16,129.87,0.109
26.19,130.01,0.109
26.21,130.14,0.109
26.24,130.27,0.109
26.27,130.41,0.109
26.29,130.54,0.109
26.32,130.67,0.109
26.35,130.81,0.110
26.37,130.94,0.110
26.40,131.07,0.110
26.43,131.21,0.110
26.45,131.34,0.110
26.48,131.47,0.110
26.51,131.61,0.110
26.53,131.74,0.110
26.56,131.87,0.110
26.59,132.01,0.110
26.61,132.14,0.110
26.64,132.27,0.110
26.67,132.41,0.110
26.69,132.54,0.110
26.72,132.67,0.110
26.75,132.81,0.110
26.77,132.94,0.110
26.80,133.08,0.110
26.83,133.21,0.110
26.85,133.34,0.110
26.88,133.47,0.110
26.91,133.61,0.110
26.93,133.74,0.110
26.96,133.87,0.110
26.99,134.01,0.110
27.01,134.14,0.110
27.04,134.28,0.110
27.07,134.41,0.110
27.09,134.54,0.110
27.12,134.68,0.110
27.15,134.81,0.110
27.17,134.94,0.110
27.20,135.08,0.110
27.23,135.21,0.110
27.25,135.34,0.110
27.28,135.47,0.110
27.31,135.61,0.110
27.33,135.74,0.111
27.36,135.88,0.111
27.39,136.01,0.111
27.41,136.14,0.111
27.44,136.27,0.111
27.47,136.41,0.111
27.49,136.54,0.111
27.52,136.67,0.111
27.55,136.81,0.111
27.57,136.94,0.111
27.60,137.07,0.111
27.63,137.21,0.111
27.65,137.34,0.111
27.68,137.48,0.111
27.71,137.61,0.111
27.73,137.74,0.111
27.76,137.88,0.111
27.79,138.01,0.111
27.81,138.14,0.111
27.84,138.27,0.111
27.87,138.41,0.111
27.89,138.54,0.111
27.92,138.67,0.111
27.95,138.81,0.111
27.97,138.94,0.111
28.00,139.07,0.111
28.03,139.21,0.111
28.05,139.34,0.111
28.08,139.48,0.111
28.11,139.61,0.111
28.13,139.74,0.111
28.16,139.88,0.111
28.19,140.01,0.112
28.21,140.14,0.112
28.24,140.28,0.112
28.27,140.41,0.112
28.29,140.54,0.112
28.32,140.68,0.112
28.35,140.81,0.112
28.37,140.94,0.112
28.40,141.08,0.112
28.43,141.21,0.112
28.45,141.34,0.112
28.48,141.48,0.112
28.51,141.61,0.112
28.53,141.74,0.112
28.56,141.88,0.112
28.59,142.01,0.112
28.61,142.14,0.112
28.64,142.28,0.112
28.67,142.41,0.112
28.69,142.54,0.112
28.72,142.68,0.112
28.75,142.81,0.112
28.77,142.94,0.112
28.80,143.08,0.112
28.83,143.21,0.112
28.85,143.34,0.112
28.88,143.48,0.112
28.91,143.61,0.112
28.93,143.74,0.112
28.96,143.88,0.112
28.99,144.01,0.112
29.01,144.14,0.112
29.04,144.28,0.112
29.07,144.41,0.112
29.09,144.54,0.112
29.12,144.68,0.113
29.15,144.81,0.113
29.17,144.94,0.113
29.20,145.08,0.113
29.23,145.21,0.113
29.25,145.34,0.113
29.28,145.48,0.113
29.31,145.61,0.113
29.33,145.75,0.113
29.36,145.88,0.113
29.39,146.01,0.113
29.41,146.14,0.113
29.44,146.28,0.113
29.47,146.41,0.113
29.49,146.54,0.113
29.52,146.68,0.113
29.55,146.81,0.113
29.57,146.94,0.113
29.60,147.08,0.113
29.63,147.21,0.113
29.65,147.34,0.113
29.68,147.48,0.113
29.71,147.61,0.113
29.73,147.74,0.113
29.76,147.88,0.113
29.79,148.01,0.114
29.81,148.14,0.114
29.84,148.28,0.114
29.87,148.41,0.114
29.89,148.54,0.114
29.92,148.68,0.114
29.95,148.81,0.114
29.97,148.94,0.114
30.00,149.08,0.114
30.03,149.21,0.114
30.05,149.34,0.114
30.08,149.48,0.114
30.11,149.61,0.114
30.13,149.74,0.114
30.16,149.88,0.114
30.19,150.01,0.114
30.21,150.14,0.114
30.24,150.28,0.114
30.27,150.41,0.114
30.29,150.54,0.114
30.32,150.68,0.114
30.35,150.81,0.114
30.37,150.94,0.114
30.40,151.08,0.114
30.43,151.21,0.115
30.45,151.34,0.115
30.48,151.48,0.115
30.51,151.61,0.115
30.53,151.74,0.115
30.56,151.88,0.115
30.59,152.01,0.115
30.61,152.14,0.115
30.64,152.28,0.115
30.67,152.41,0.115
30.69,152.54,0.115
30.72,152.68,0.115
30.75,152.81,0.115
30.77,152.94,0.115
30.80,153.08,0.115
30.83,153.21,0.116
30.85,153.34,0.116
30.88,153.48,0.116
30.91,153.61,0.116
30.93,153.74,0.116
30.96,153.88,0.116
30.99,154.01,0.116
31.01,154.14,0.116
31.04,154.28,0.116
31.07,154.41,0.116
31.09,154.54,0.126
31.12,154.67,0.122
31.15,154.80,0.120
31.17,154.94,0.120
31.20,155.07,0.120
31.23,155.20,0.120
31.25,155.34,0.120
31.28,155.47,0.120
31.31,155.60,0.120
31.33,155.74,0.120
31.36,155.87,0.120
31.39,156.01,0.120
31.41,156.14,0.119
31.44,156.27,0.119
31.47,156.41,0.119
31.49,156.54,0.119
31.52,156.67,0.119
31.55,156.81,0.119
31.57,156.94,0.119
31.60,157.07,0.119
31.63,157.20,0.119
31.65,157.34,0.120
31.68,157.47,0.120
31.71,157.60,0.120
31.73,157.74,0.120
31.76,157.87,0.120
31.79,158.01,0.120
31.81,158.14,0.120
31.84,158.27,0.120
31.87,158.40,0.120
31.89,158.54,0.120
31.92,158.67,0.120
31.95,158.80,0.120
31.97,158.94,0.120
32.00,159.07,0.120
32.03,159.20,0.121
32.05,159.34,0.121
32.08,159.47,0.121
32.11,159.60,0.121
32.13,159.74,0.121
32.16,159.87,0.121
32.19,160.00,0.121
32.21,160.14,0.121
32.24,160.27,0.122
32.27,160.40,0.122
32.29,160.54,0.122
32.32,160.67,0.122
32.35,160.80,0.122
32.37,160.93,0.122
32.40,161.07,0.122
32.43,161.20,0.123
32.45,161.33,0.123
32.48,161.47,0.123
32.51,161.60,0.123
32.53,161.73,0.124
32.56,161.87,0.124
32.59,162.00,0.124
32.61,162.13,0.124
32.64,162.26,0.125
32.67,162.40,0.125
32.69,162.53,0.125
32.72,162.66,0.126
32.75,162.80,0.126
32.77,162.93,0.126
32.80,163.06,0.127
32.83,163.19,0.127
32.85,163.33,0.128
32.88,163.46,0.128
32.91,163.59,0.128
32.93,163.73,0.129
32.96,163.86,0.129
32.99,163.99,0.130
33.01,164.13,0.130
33.04,164.26,0.131
33.07,164.39,0.131
33.09,164.52,0.132
33.12,164.65,0.132
33.15,164.79,0.133
33.17,164.92,0.134
33.20,165.05,0.134
33.23,165.19,0.135
33.25,165.32,0.136
33.28,165.45,0.137
33.31,165.58,0.137
33.33,165.71,0.138
33.36,165.85,0.139
33.39,165.98,0.140
33.41,166.11,0.141
33.44,166.24,0.142
33.47,166.37,0.143
33.49,166.50,0.145
33.52,166.64,0.146
33.55,166.77,0.147
33.57,166.90,0.149
33.60,167.03,0.151
33.63,167.16,0.152
33.65,167.29,0.154
33.68,167.42,0.156
33.71,167.55,0.158
33.73,167.68,0.160
33.76,167.81,0.162
33.79,167.94,0.164
33.81,168.07,0.167
33.84,168.20,0.170
33.87,168.33,0.173
33.89,168.46,0.176
33.92,168.59,0.179
33.95,168.72,0.183
33.97,168.84,0.187
34.00,168.97,0.192
34.03,169.10,0.196
34.05,169.22,0.201
34.08,169.35,0.206
34.11,169.47,0.212
34.13,169.60,0.218
34.16,169.72,0.225
34.19,169.84,0.233
34.21,169.97,0.240
34.24,170.09,0.248
34.27,170.21,0.257
34.29,170.32,0.267
34.32,170.44,0.277
34.35,170.56,0.288
34.37,170.68,0.300
34.40,170.79,0.313
34.43,170.90,0.326
34.45,171.02,0.341
34.48,171.13,0.356
34.51,171.24,0.371
34.53,171.35,0.388
34.56,171.45,0.406
34.59,171.56,0.424
34.61,171.66,0.444
34.64,171.76,0.464
34.67,171.87,0.485
34.69,171.96,0.507
34.72,172.06,0.532
34.75,172.16,0.557
34.77,172.25,0.593
34.80,172.32,0.651
34.83,172.38,0.691
34.85,172.45,0.719
34.88,172.53,0.756
34.91,172.59,0.824
34.93,172.65,0.845
34.96,172.73,0.868
34.99,172.81,0.902
35.01,172.90,0.934
35.04,172.98,0.969
35.07,173.05,1.005
35.09,173.13,1.038
35.12,173.20,1.080
35.15,173.28,1.114
35.17,173.35,1.152
35.20,173.42,1.189
35.23,173.50,1.225
35.25,173.57,1.268
35.28,173.64,1.308
35.31,173.71,1.349
35.33,173.77,1.399
35.36,173.82,1.462
35.39,173.86,1.527
35.41,173.91,1.564
35.44,173.97,1.611
35.47,174.02,1.663
35.49,174.07,1.713
35.52,174.12,1.759
35.55,174.20,1.749
35.57,174.32,1.717
35.60,174.48,1.666
35.63,174.65,1.636
35.65,174.83,1.615
35.68,175.00,1.588
35.71,175.18,1.557
35.73,175.36,1.524
35.76,175.55,1.494
35.79,175.73,1.464
35.81,175.91,1.428
35.84,176.11,1.391
35.87,176.29,1.360
35.89,176.48,1.333
35.92,176.66,1.301
35.95,176.85,1.257
35.97,177.06,1.195
36.00,177.28,1.125
36.03,177.52,1.043
36.05,177.78,0.943
36.08,178.06,0.825
36.11,178.36,0.713
36.13,178.66,0.630
36.16,178.94,0.562
36.19,179.19,0.504
36.21,179.44,0.454
36.24,179.66,0.411
36.27,179.88,0.373
36.29,180.08,0.341
36.32,180.27,0.314
36.35,180.46,0.290
36.37,180.64,0.269
36.40,180.81,0.252
36.43,180.98,0.237
36.45,181.14,0.224
36.48,181.30,0.213
36.51,181.45,0.203
36.53,181.60,0.195
36.56,181.75,0.189
36.59,181.90,0.183
36.61,182.04,0.177
36.64,182.18,0.173
36.67,182.33,0.169
36.69,182.47,0.166
36.72,182.61,0.163
36.75,182.74,0.160
36.77,182.88,0.158
36.80,183.02,0.156
36.83,183.16,0.155
36.85,183.29,0.154
36.88,183.43,0.153
36.91,183.57,0.152
36.93,183.70,0.151
36.96,183.83,0.150
36.99,183.97,0.150
37.01,184.10,0.149
37.04,184.24,0.149
37.07,184.37,0.149
37.09,184.51,0.149
37.12,184.64,0.148
37.15,184.78,0.148
37.17,184.91,0.148
37.20,185.04,0.148
37.23,185.17,0.148
37.25,185.31,0.148
37.28,185.44,0.147
37.31,185.58,0.147
37.33,185.71,0.147
37.36,185.84,0.147
37.39,185.98,0.147
37.41,186.11,0.147
37.44,186.24,0.147
37.47,186.38,0.146
37.49,186.51,0.146
37.52,186.65,0.146
37.55,186.78,0.146
37.57,186.91,0.146
37.60,187.05,0.146
37.63,187.18,0.146
37.65,187.31,0.146
37.68,187.45,0.146
37.71,187.58,0.146
37.73,187.71,0.146
37.76,187.85,0.146
37.79,187.98,0.145
37.81,188.11,0.145
37.84,188.25,0.145
37.87,188.38,0.145
37.89,188.51,0.145
37.92,188.65,0.145
37.95,188.78,0.145
37.97,188.91,
38.00,189.05,
38.01,,

[step]
Ramp 20.00 °C/min to 0.00 °C
Time,Temperature,Heat Flow (Normalized)
min,°C,W/g
39.01,190.12,-0.018
39.02,190.12,-0.018
39.03,190.12,-0.018
39.03,190.12,-0.018
39.04,190.11,-0.019
39.04,190.11,-0.019
39.05,190.11,-0.019
39.06,190.10,-0.019
39.06,190.09,-0.018
39.07,190.07,-0.017
39.08,190.06,-0.015
39.09,190.03,-0.015
39.09,190.00,-0.015
39.10,189.97,-0.015
39.11,189.93,-0.017
39.11,189.88,-0.023
39.12,189.84,-0.030
39.13,189.78,-0.038
39.13,189.72,-0.048
39.14,189.66,-0.060
39.14,189.59,-0.073
39.15,189.52,-0.087
39.16,189.44,-0.103
39.16,189.37,-0.119
39.17,189.29,-0.136
39.18,189.21,-0.153
39.19,189.12,-0.170
39.19,189.04,-0.187
39.20,188.95,-0.203
39.21,188.86,-0.219
39.21,188.78,-0.235
39.22,188.68,-0.250
39.23,188.59,-0.264
39.23,188.50,-0.278
39.24,188.40,-0.291
39.24,188.31,-0.305
39.25,188.21,-0.317
39.26,188.11,-0.329
39.26,188.01,-0.341
39.27,187.91,-0.353
39.28,187.80,-0.364
39.29,187.70,-0.375
39.29,187.60,-0.385
39.30,187.49,-0.395
39.31,187.38,-0.404
39.31,187.28,-0.414
39.32,187.17,-0.423
39.33,187.06,-0.432
39.33,186.95,-0.440
39.34,186.84,-0.448
39.34,186.73,-0.456
39.35,186.61,-0.464
39.36,186.50,-0.471
39.36,186.39,-0.478
39.37,186.27,-0.485
39.38,186.16,-0.492
39.39,186.04,-0.498
39.39,185.93,-0.504
39.40,185.81,-0.510
39.41,185.69,-0.515
39.41,185.57,-0.521
39.42,185.46,-0.526
39.43,185.34,-0.531
39.43,185.22,-0.536
39.44,185.10,-0.541
39.44,184.98,-0.545
39.45,184.86,-0.549
39.46,184.74,-0.554
39.46,184.61,-0.558
39.47,184.49,-0.561
39.48,184.37,-0.565
39.49,184.25,-0.569
39.49,184.12,-0.572
39.50,184.00,-0.575
39.51,183.88,-0.579
39.51,183.75,-0.582
39.52,183.63,-0.585
39.53,183.51,-0.588
39.53,183.38,-0.591
39.54,183.26,-0.593
39.54,183.13,-0.596
39.55,183.01,-0.598
39.56,182.88,-0.601
39.56,182.75,-0.603
39.57,182.63,-0.605
39.58,182.50,-0.607
39.59,182.37,-0.609
39.59,182.25,-0.611
39.60,182.12,-0.613
39.61,181.99,-0.615
39.61,181.87,-0.617
39.62,181.74,-0.619
39.63,181.61,-0.620
39.63,181.48,-0.621
39.64,181.36,-0.623
39.64,181.23,-0.625
39.65,181.10,-0.626
39.66,180.97,-0.627
39.66,180.84,-0.629
39.67,180.71,-0.630
39.68,180.58,-0.631
39.69,180.46,-0.632
39.69,180.33,-0.633
39.70,180.20,-0.634
39.71,180.07,-0.635
39.71,179.94,-0.636
39.72,179.81,-0.637
39.73,179.68,-0.638
39.73,179.55,-0.639
39.74,179.42,-0.640
39.74,179.29,-0.641
39.75,179.16,-0.641
39.76,179.03,-0.642
39.76,178.90,-0.643
39.77,178.77,-0.644
39.78,178.64,-0.644
39.79,178.51,-0.645
39.79,178.38,-0.645
39.80,178.25,-0.646
39.81,178.12,-0.646
39.81,177.99,-0.647
39.82,177.86,-0.648
39.83,177.72,-0.648
39.83,177.59,-0.648
39.84,177.46,-0.649
39.84,177.33,-0.649
39.85,177.20,-0.649
39.86,177.07,-0.650
39.86,176.94,-0.651
39.87,176.81,-0.651
39.88,176.68,-0.651
39.89,176.55,-0.651
39.89,176.41,-0.652
39.90,176.28,-0.652
39.91,176.15,-0.652
39.91,176.02,-0.652
39.92,175.89,-0.653
39.93,175.76,-0.653
39.93,175.63,-0.653
39.94,175.49,-0.653
39.94,175.36,-0.654
39.95,175.23,-0.654
39.96,175.10,-0.654
39.96,174.97,-0.654
39.97,174.83,-0.654
39.98,174.70,-0.655
39.99,174.57,-0.655
39.99,174.44,-0.655
40.00,174.31,-0.655
40.01,174.17,-0.655
40.01,174.04,-0.655
40.02,173.91,-0.655
40.03,173.78,-0.655
40.03,173.65,-0.655
40.04,173.51,-0.655
40.04,173.38,-0.656
40.05,173.25,-0.656
40.06,173.12,-0.656
40.06,172.98,-0.656
40.07,172.85,-0.656
40.08,172.72,-0.656
40.09,172.59,-0.656
40.09,172.46,-0.656
40.10,172.32,-0.656
40.11,172.19,-0.656
40.11,172.06,-0.656
40.12,171.93,-0.656
40.13,171.79,-0.656
40.13,171.66,-0.656
40.14,171.53,-0.656
40.14,171.40,-0.656
40.15,171.26,-0.656
40.16,171.13,-0.656
40.16,171.00,-0.656
40.17,170.87,-0.656
40.18,170.73,-0.656
40.19,170.60,-0.656
40.19,170.47,-0.656
40.20,170.34,-0.656
40.21,170.20,-0.656
40.21,170.07,-0.656
40.22,169.94,-0.656
40.23,169.81,-0.656
40.23,169.67,-0.656
40.24,169.54,-0.656
40.24,169.41,-0.656
40.25,169.28,-0.656
40.26,169.14,-0.656
40.26,169.01,-0.656
40.27,168.88,-0.656
40.28,168.75,-0.656
40.29,168.61,-0.656
40.29,168.48,-0.656
40.30,168.35,-0.656
40.31,168.21,-0.656
40.31,168.08,-0.656
40.32,167.95,-0.656
40.33,167.82,-0.656
40.33,167.68,-0.656
40.34,167.55,-0.656
40.34,167.42,-0.656
40.35,167.29,-0.656
40.36,167.15,-0.656
40.36,167.02,-0.656
40.37,166.89,-0.656
40.38,166.76,-0.656
40.39,166.62,-0.656
40.39,166.49,-0.656
40.40,166.36,-0.656
40.41,166.22,-0.656
40.41,166.09,-0.656
40.42,165.96,-0.655
40.43,165.83,-0.655
40.43,165.69,-0.655
40.44,165.56,-0.655
40.44,165.43,-0.655
40.45,165.30,-0.655
40.46,165.16,-0.655
40.46,165.03,-0.655
40.47,164.90,-0.655
40.48,164.77,-0.655
40.49,164.63,-0.655
40.49,164.50,-0.655
40.50,164.37,-0.655
40.51,164.23,-0.655
40.51,164.10,-0.655
40.52,163.97,-0.655
40.53,163.84,-0.655
40.53,163.70,-0.654
40.54,163.57,-0.654
40.54,163.44,-0.654
40.55,163.30,-0.654
40.56,163.17,-0.654
40.56,163.04,-0.654
40.57,162.91,-0.654
40.58,162.77,-0.654
40.59,162.64,-0.654
40.59,162.51,-0.654
40.60,162.37,-0.654
40.61,162.24,-0.654
40.61,162.11,-0.653
40.62,161.97,-0.653
40.63,161.84,-0.653
40.63,161.71,-0.653
40.64,161.58,-0.653
40.64,161.44,-0.653
40.65,161.31,-0.653
40.66,161.18,-0.653
40.66,161.04,-0.653
40.67,160.91,-0.653
40.68,160.78,-0.653
40.69,160.65,-0.653
40.69,160.51,-0.652
40.70,160.38,-0.652
40.71,160.25,-0.652
40.71,160.11,-0.652
40.72,159.98,-0.652
40.73,159.85,-0.652
40.73,159.71,-0.652
40.74,159.58,-0.652
40.74,159.45,-0.652
40.75,159.32,-0.652
40.76,159.18,-0.652
40.76,159.05,-0.652
40.77,158.92,-0.652
40.78,158.78,-0.651
40.79,158.65,-0.651
40.79,158.52,-0.651
40.80,158.39,-0.651
40.81,158.25,-0.651
40.81,158.12,-0.651
40.82,157.99,-0.651
40.83,157.85,-0.651
40.83,157.72,-0.651
40.84,157.59,-0.651
40.84,157.45,-0.651
40.85,157.32,-0.651
40.86,157.19,-0.651
40.86,157.06,-0.651
40.87,156.92,-0.651
40.88,156.79,-0.651
40.89,156.66,-0.651
40.89,156.53,-0.651
40.90,156.39,-0.650
40.91,156.26,-0.650
40.91,156.13,-0.650
40.92,155.99,-0.650
40.93,155.86,-0.650
40.93,155.73,-0.650
40.94,155.59,-0.650
40.94,155.46,-0.650
40.95,155.33,-0.649
40.96,155.20,-0.649
40.96,155.06,-0.649
40.97,154.93,-0.649
40.98,154.80,-0.649
40.99,154.66,-0.649
40.99,154.53,-0.649
41.00,154.40,-0.649
41.01,154.26,-0.649
41.01,154.13,-0.648
41.02,154.00,-0.648
41.03,153.87,-0.648
41.03,153.73,-0.648
41.04,153.60,-0.648
41.04,153.47,-0.648
41.05,153.33,-0.648
41.06,153.20,-0.648
41.06,153.07,-0.648
41.07,152.93,-0.648
41.08,152.80,-0.648
41.09,152.67,-0.648
41.09,152.54,-0.648
41.10,152.40,-0.648
41.11,152.27,-0.648
41.11,152.14,-0.648
41.12,152.00,-0.647
41.13,151.87,-0.647
41.13,151.74,-0.647
41.14,151.61,-0.647
41.14,151.47,-0.647
41.15,151.34,-0.647
41.16,151.21,-0.647
41.16,151.07,-0.647
41.17,150.94,-0.646
41.18,150.81,-0.646
41.19,150.67,-0.646
41.19,150.54,-0.646
41.20,150.41,-0.646
41.21,150.28,-0.646
41.21,150.14,-0.646
41.22,150.01,-0.646
41.23,149.88,-0.645
41.23,149.75,-0.645
41.24,149.61,-0.645
41.24,149.48,-0.645
41.25,149.35,-0.645
41.26,149.21,-0.645
41.26,149.08,-0.645
41.27,148.95,-0.645
41.28,148.81,-0.645
41.29,148.68,-0.644
41.29,148.55,-0.644
41.30,148.41,-0.644
41.31,148.28,-0.644
41.31,148.15,-0.644
41.32,148.01,-0.644
41.33,147.88,-0.644
41.33,147.75,-0.644
41.34,147.62,-0.644
41.34,147.48,-0.644
41.35,147.35,-0.644
[...]
139.66,2.38,0.077
139.67,2.40,0.077
139.67,2.43,0.077
139.68,2.45,0.078
139.68,2.48,0.078
139.68,2.50,0.078
139.69,2.53,0.078
139.70,2.55,0.078
139.70,2.57,0.079
139.70,2.60,0.079
139.71,2.62,0.079
139.72,2.65,0.079
139.72,2.67,0.079
139.73,2.69,0.079
139.73,2.72,0.079
139.73,2.74,0.080
139.74,2.77,0.080
139.75,2.79,0.080
139.75,2.82,0.080
139.75,2.84,0.080
139.76,2.87,0.080
139.77,2.89,0.080
139.77,2.91,0.081
139.78,2.94,0.081
139.78,2.96,0.081
139.78,2.99,0.081
139.79,3.01,0.081
139.80,3.04,0.081
139.80,3.06,0.081
139.80,3.08,0.081
139.81,3.11,0.081
139.82,3.13,0.082
139.82,3.16,0.082
139.83,3.18,0.082
139.83,3.21,0.082
139.83,3.23,0.082
139.84,3.25,0.082
139.85,3.28,0.082
139.85,3.30,0.082
139.85,3.33,0.082
139.86,3.35,0.082
139.87,3.38,0.082
139.87,3.40,0.082
139.88,3.43,0.082
139.88,3.45,0.082
139.88,3.48,0.082
139.89,3.50,0.082
139.90,3.53,0.082
139.90,3.55,0.082
139.90,3.57,0.083
139.91,3.60,0.083
139.92,3.62,0.083
139.92,3.65,0.083
139.93,3.67,0.083
139.93,3.70,0.083
139.93,3.72,0.083
139.94,3.75,0.083
139.95,3.77,0.083
139.95,3.80,0.083
139.95,3.82,0.083
139.96,3.85,0.083
139.97,3.87,0.083
139.97,3.90,0.083
139.98,3.92,0.084
139.98,3.95,0.084
139.98,3.97,0.084
139.99,3.99,0.084
140.00,4.02,0.084
140.00,4.04,0.084
140.00,4.07,0.084
140.01,4.09,0.084
140.02,4.12,0.084
140.02,4.14,0.084
140.03,4.17,0.084
140.03,4.19,0.084
140.03,4.22,0.084
140.04,4.24,0.084
140.05,4.27,0.084
140.05,4.29,0.084
140.05,4.32,0.084
140.06,4.34,0.084
140.07,4.36,0.084
140.07,4.39,0.084
140.08,4.41,0.084
140.08,4.44,0.084
140.08,4.47,0.084
140.09,4.49,0.084
140.10,4.51,0.084
140.10,4.54,0.084
140.10,4.56,0.084
140.11,4.59,0.084
140.12,4.61,0.084
140.12,4.64,0.084
140.13,4.66,0.084
140.13,4.69,0.084
140.13,4.71,0.084
140.14,4.74,0.084
140.15,4.76,0.085
140.15,4.79,0.085
140.15,4.81,0.085
140.16,4.84,0.085
140.17,4.86,0.085
140.17,4.89,0.085
140.18,4.91,0.085
140.18,4.94,0.085
140.18,4.96,0.085
140.19,4.99,0.085
140.20,5.01,0.085
140.20,5.04,0.085
140.20,5.06,0.085
140.21,5.09,0.085
140.22,5.11,0.085
140.22,5.13,0.085
140.23,5.16,0.085
140.23,5.18,0.085
140.23,5.21,0.085
140.24,5.23,0.085
140.25,5.26,0.085
140.25,5.28,0.085
140.25,5.31,0.085
140.26,5.33,0.085
140.27,5.36,0.085
140.27,5.38,0.085
140.28,5.41,0.085
140.28,5.43,0.085
140.28,5.46,0.085
140.29,5.48,0.085
140.30,5.51,0.085
140.30,5.53,0.085
140.30,5.56,0.085
140.31,5.58,0.085
140.32,5.61,0.085
140.32,5.63,0.085
140.33,5.66,0.085
140.33,5.68,0.085
140.33,5.71,0.085
140.34,5.73,0.085
140.35,5.76,0.085
140.35,5.78,0.085
140.35,5.81,0.085
140.36,5.83,0.085
140.37,5.86,0.085
140.37,5.88,0.085
140.38,5.91,0.085
140.38,5.93,0.086
140.38,5.96,0.086
140.39,5.98,0.086
140.40,6.01,0.086
140.40,6.03,0.086
140.40,6.06,0.086
140.41,6.08,0.086
140.42,6.11,0.086
140.42,6.13,0.086
140.43,6.16,0.086
140.43,6.18,0.086
140.43,6.21,0.086
140.44,6.23,0.086
140.45,6.26,0.086
140.45,6.28,0.086
140.45,6.31,0.086
140.46,6.33,0.086
140.47,6.36,0.086
140.47,6.38,0.086
140.48,6.41,0.086
140.48,6.43,0.086
140.48,6.46,0.086
140.49,6.48,0.086
140.50,6.51,0.086
140.50,6.53,0.086
140.50,6.56,0.086
140.51,6.58,0.086
140.52,6.60,0.086
140.52,6.63,0.086
140.53,6.66,0.086
140.53,6.68,0.086
140.53,6.71,0.086
140.54,6.73,0.086
140.55,6.76,0.086
140.55,6.78,0.086
140.55,6.81,0.086
140.56,6.83,0.086
140.57,6.85,0.086
140.57,6.88,0.086
140.58,6.91,0.086
140.58,6.93,0.086
140.58,6.96,0.086
140.59,6.98,0.086
140.60,7.01,0.086
140.60,7.03,0.086
140.60,7.05,0.086
140.61,7.08,0.086
140.62,7.10,0.086
140.62,7.13,0.086
140.63,7.16,0.086
140.63,7.18,0.086
140.63,7.21,0.086
140.64,7.23,0.086
140.65,7.25,0.086
140.65,7.28,0.086
140.65,7.31,0.086
140.66,7.33,0.086
140.67,7.35,0.086
140.67,7.38,0.086
140.68,7.41,0.086
140.68,7.43,0.086
140.68,7.46,0.086
140.69,7.48,0.086
140.70,7.50,0.086
140.70,7.53,0.086
140.70,7.55,0.086
140.71,7.58,0.086
140.72,7.60,0.086
140.72,7.63,0.086
140.73,7.65,0.086
140.73,7.68,0.087
140.73,7.71,0.087
140.74,7.73,0.087
140.75,7.75,0.087
140.75,7.78,0.087
140.75,7.80,0.087
140.76,7.83,0.087
140.77,7.85,0.087
140.77,7.88,0.087
140.78,7.91,0.087
140.78,7.93,0.087
140.78,7.95,0.087
140.79,7.98,0.087
140.80,8.00,0.087
140.80,8.03,0.087
140.80,8.05,0.087
140.81,8.08,0.087
140.82,8.10,0.087
140.82,8.13,0.087
140.83,8.15,0.087
140.83,8.18,0.087
140.83,8.21,0.087
140.84,8.23,0.087
140.85,8.25,0.087
140.85,8.28,0.087
140.85,8.30,0.087
140.86,8.33,0.087
140.87,8.35,0.087
140.87,8.38,0.087
140.88,8.40,0.087
140.88,8.43,0.087
140.88,8.45,0.087
140.89,8.48,0.087
140.90,8.50,0.087
140.90,8.53,0.087
140.90,8.56,0.087
140.91,8.58,0.087
140.92,8.60,0.087
140.92,8.63,0.087
140.93,8.65,0.087
140.93,8.68,0.087
140.93,8.70,0.087
140.94,8.73,0.087
140.95,8.75,0.087
140.95,8.78,0.087
140.95,8.81,0.087
140.96,8.83,0.087
140.97,8.85,0.087
140.97,8.88,0.087
140.98,8.90,0.087
140.98,8.93,0.087
140.98,8.96,0.087
140.99,8.98,0.087
141.00,9.00,0.087
141.00,9.03,0.087
141.00,9.05,0.087
141.01,9.08,0.087
141.02,9.10,0.087
141.02,9.13,0.087
141.03,9.15,0.087
141.03,9.18,0.087
141.03,9.20,0.087
141.04,9.23,0.087
141.05,9.26,0.087
141.05,9.28,0.087
141.05,9.30,0.087
141.06,9.33,0.087
141.07,9.35,0.087
141.07,9.38,0.087
141.08,9.40,0.087
141.08,9.43,0.087
141.08,9.45,0.087
141.09,9.48,0.087
141.10,9.50,0.087
141.10,9.53,0.087
141.10,9.55,0.087
141.11,9.58,0.087
141.12,9.60,0.087
141.12,9.63,0.087
141.13,9.66,0.087
141.13,9.68,0.087
141.13,9.70,0.087
141.14,9.73,0.087
141.15,9.75,0.087
141.15,9.78,0.087
141.15,9.80,0.087
141.16,9.83,0.087
141.17,9.85,0.087
141.17,9.88,0.087
141.18,9.90,0.087
141.18,9.93,0.087
141.18,9.95,0.087
141.19,9.98,0.087
141.20,10.00,0.087
141.20,10.03,0.087
141.20,10.06,0.087
141.21,10.08,0.087
141.22,10.11,0.087
141.22,10.13,0.087
141.23,10.15,0.087
141.23,10.18,0.087
141.23,10.20,0.087
141.24,10.23,0.087
141.25,10.25,0.087
141.25,10.28,0.087
141.25,10.30,0.087
141.26,10.33,0.087
141.27,10.35,0.087
141.27,10.38,0.087
141.28,10.40,0.087
141.28,10.43,0.087
141.28,10.45,0.087
141.29,10.48,0.087
141.30,10.50,0.087
141.30,10.53,0.087
141.30,10.55,0.087
141.31,10.58,0.087
141.32,10.61,0.087
141.32,10.63,0.087
141.33,10.65,0.087
141.33,10.68,0.087
141.33,10.71,0.087
141.34,10.73,0.087
141.35,10.76,0.087
141.35,10.78,0.087
141.35,10.80,0.087
141.36,10.83,0.087
141.37,10.86,0.087
141.37,10.88,0.087
141.38,10.91,0.087
141.38,10.93,0.087
141.38,10.95,0.087
141.39,10.98,0.087
141.40,11.01,0.087
141.40,11.03,0.087
141.40,11.06,0.087
141.41,11.08,0.087
141.42,11.11,0.088
141.42,11.13,0.088
141.43,11.16,0.088
141.43,11.18,0.088
141.43,11.20,0.088
141.44,11.23,0.088
141.45,11.25,0.088
141.45,11.28,0.088
141.45,11.30,0.088
141.46,11.33,0.088
141.47,11.35,0.088
141.47,11.38,0.088
141.48,11.41,0.088
141.48,11.43,0.088
141.48,11.45,0.088
141.49,11.48,0.088
141.50,11.51,0.088
141.50,11.53,0.088
141.50,11.56,0.088
141.51,11.58,0.088
141.52,11.60,0.088
141.52,11.63,0.088
141.53,11.65,0.088
141.53,11.68,0.088
141.53,11.71,0.088
141.54,11.73,0.088
141.55,11.75,0.088
141.55,11.78,0.088
141.55,11.81,0.088
141.56,11.83,0.088
141.57,11.85,0.088
141.57,11.88,0.088
141.58,11.90,0.088
141.58,11.93,0.088
141.58,11.95,0.088
141.59,11.98,0.088
141.60,12.00,0.088
141.60,12.03,0.088
141.60,12.06,0.088
141.61,12.08,0.088
141.62,12.10,0.088
141.62,12.13,0.088
141.63,12.15,0.088
141.63,12.18,0.088
141.63,12.20,0.088
141.64,12.23,0.088
141.65,12.26,0.088
141.65,12.28,0.088
141.65,12.31,0.088
141.66,12.33,0.088
141.67,12.35,0.088
141.67,12.38,0.088
141.68,12.40,0.088
141.68,12.43,0.088
141.68,12.45,0.088
141.69,12.48,0.088
141.70,12.50,0.088
141.70,12.53,0.088
141.70,12.55,0.088
141.71,12.58,0.088
141.72,12.60,0.088
141.72,12.63,0.088
141.73,12.65,0.088
141.73,12.68,0.088
141.73,12.70,0.088
141.74,12.73,0.088
141.75,12.75,0.088
141.75,12.78,0.088
141.75,12.80,0.088
141.76,12.83,0.088
141.77,12.85,0.088
141.77,12.88,0.088
141.78,12.91,0.088
141.78,12.93,0.088
141.78,12.95,0.088
141.79,12.98,0.088
141.80,13.00,0.088
141.80,13.03,0.088
141.80,13.05,0.088
141.81,13.08,0.088
141.82,13.11,0.088
141.82,13.13,0.088
141.83,13.15,0.088
141.83,13.18,0.088
141.83,13.20,0.088
141.84,13.23,0.088
141.85,13.25,0.088
141.85,13.28,0.088
141.85,13.31,0.088
141.86,13.33,0.088
141.87,13.36,0.088
141.87,13.38,0.088
141.88,13.41,0.088
141.88,13.43,0.088
141.88,13.45,0.088
141.89,13.48,0.088
141.90,13.51,0.088
141.90,13.53,0.088
141.90,13.56,0.088
141.91,13.58,0.088
141.92,13.61,0.088
141.92,13.63,0.088
141.93,13.66,0.088
141.93,13.68,0.088
141.93,13.71,0.088
141.94,13.73,0.088
141.95,13.76,0.088
141.95,13.78,0.088
141.95,13.81,0.088
141.96,13.83,0.088
141.97,13.86,0.088
141.97,13.88,0.088
141.98,13.90,0.088
141.98,13.93,0.088
141.98,13.96,0.088
141.99,13.98,0.088
142.00,14.01,0.088
142.00,14.03,0.088
142.00,14.06,0.088
142.01,14.08,0.088
142.02,14.11,0.088
142.02,14.13,0.088
142.03,14.15,0.088
142.03,14.18,0.088
142.03,14.21,0.088
142.04,14.23,0.088
142.05,14.26,0.088
142.05,14.28,0.088
142.05,14.31,0.088
142.06,14.33,0.088
142.07,14.36,0.088
142.07,14.38,0.088
142.08,14.41,0.088
142.08,14.43,0.088
142.08,14.45,0.088
142.09,14.48,0.088
142.10,14.51,0.088
142.10,14.53,0.088
142.10,14.56,0.088
142.11,14.58,0.088
142.12,14.61,0.088
142.12,14.63,0.088
142.13,14.66,0.088
142.13,14.68,0.088
142.13,14.71,0.088
142.14,14.73,0.088
142.15,14.76,0.088
142.15,14.78,0.088
142.15,14.80,0.088
142.16,14.83,0.088
142.17,14.86,0.088
142.17,14.88,0.088
142.18,14.91,0.088
142.18,14.93,0.088
142.18,14.96,0.088
142.19,14.98,0.088
142.20,15.01,0.088
142.20,15.03,0.088
142.20,15.06,0.088
142.21,15.08,0.088
142.22,15.11,0.088
142.22,15.13,0.088
142.23,15.16,0.088
142.23,15.18,0.088
142.23,15.21,0.088
142.24,15.23,0.088
142.25,15.26,0.088
142.25,15.28,0.088
142.25,15.31,0.088
142.26,15.33,0.088
142.27,15.36,0.088
142.27,15.38,0.088
142.28,15.41,0.088
142.28,15.43,0.089
142.28,15.45,0.089
142.29,15.48,0.089
142.30,15.51,0.089
142.30,15.53,0.089
142.30,15.56,0.089
142.31,15.58,0.089
142.32,15.61,0.089
142.32,15.63,0.089
142.33,15.66,0.089
142.33,15.68,0.089
142.33,15.70,0.089
142.34,15.73,0.089
142.35,15.76,0.089
142.35,15.78,0.089
142.35,15.81,0.089
142.36,15.83,0.089
142.37,15.86,0.089
142.37,15.88,0.089
142.38,15.91,0.089
142.38,15.93,0.089
142.38,15.96,0.089
142.39,15.98,0.089
142.40,16.01,0.089
142.40,16.03,0.089
142.40,16.06,0.089
142.41,16.08,0.089
142.42,16.11,0.089
142.42,16.13,0.089
142.43,16.16,0.089
142.43,16.18,0.089
142.43,16.21,0.089
142.44,16.23,0.089
142.45,16.26,0.089
142.45,16.28,0.089
142.45,16.31,0.089
142.46,16.33,0.089
142.47,16.36,0.089
142.47,16.38,0.089
142.48,16.41,0.089
142.48,16.43,0.089
142.48,16.46,0.089
142.49,16.48,0.089
142.50,16.51,0.089
142.50,16.53,0.089
142.50,16.56,0.089
142.51,16.58,0.089
142.52,16.61,0.089
142.52,16.63,0.089
142.53,16.66,0.089
142.53,16.68,0.089
142.53,16.71,0.089
142.54,16.73,0.089
142.55,16.76,0.089
142.55,16.78,0.089
142.55,16.81,0.089
142.56,16.83,0.089
142.57,16.86,0.089
142.57,16.88,0.089
142.58,16.91,0.089
142.58,16.93,0.089
142.58,16.96,0.089
142.59,16.98,0.089
142.60,17.01,0.089
142.60,17.03,0.089
142.60,17.06,0.089
142.61,17.08,0.089
142.62,17.11,0.089
142.62,17.13,0.089
142.63,17.16,0.089
142.63,17.18,0.089
142.63,17.21,0.089
142.64,17.23,0.089
142.65,17.26,0.089
142.65,17.28,0.089
142.65,17.31,0.089
142.66,17.33,0.089
142.67,17.36,0.089
142.67,17.38,0.089
142.68,17.41,0.089
142.68,17.43,0.089
142.68,17.46,0.089
142.69,17.48,0.089
142.70,17.51,0.089
142.70,17.53,0.089
142.70,17.56,0.089
142.71,17.58,0.089
142.72,17.61,0.089
142.72,17.63,0.089
142.73,17.66,0.089
142.73,17.68,0.089
142.73,17.71,0.089
142.74,17.73,0.089
142.75,17.76,0.089
142.75,17.78,0.089
142.75,17.81,0.089
142.76,17.83,0.089
142.77,17.86,0.089
142.77,17.88,0.089
142.78,17.91,0.089
142.78,17.93,0.089
142.78,17.96,0.089
142.79,17.98,0.089
142.80,18.01,0.089
142.80,18.03,0.089
142.80,18.06,0.089
142.81,18.08,0.089
142.82,18.11,0.089
142.82,18.13,0.089
142.83,18.16,0.089
142.83,18.18,0.089
142.83,18.21,0.089
142.84,18.23,0.089
142.85,18.26,0.089
142.85,18.28,0.089
142.85,18.31,0.089
142.86,18.33,0.089
142.87,18.36,0.089
142.87,18.38,0.089
142.88,18.41,0.089
142.88,18.43,0.089
142.88,18.46,0.089
142.89,18.48,0.089
142.90,18.51,0.089
142.90,18.53,0.089
142.90,18.56,0.089
142.91,18.58,0.089
142.92,18.61,0.089
142.92,18.63,0.089
142.93,18.66,0.089
142.93,18.68,0.089
142.93,18.71,0.089
142.94,18.73,0.089
142.95,18.76,0.089
142.95,18.78,0.089
142.95,18.81,0.089
142.96,18.83,0.089
142.97,18.86,0.089
142.97,18.88,0.089
142.98,18.91,0.089
142.98,18.93,0.089
142.98,18.96,0.089
142.99,18.98,0.089
143.00,19.01,0.089
143.00,19.03,0.089
143.00,19.06,0.089
143.01,19.08,0.089
143.02,19.11,0.089
143.02,19.13,0.089
143.03,19.16,0.089
143.03,19.18,0.089
143.03,19.21,0.089
143.04,19.23,0.089
143.05,19.26,0.089
143.05,19.28,0.089
143.05,19.31,0.089
143.06,19.33,0.089
143.07,19.36,0.089
143.07,19.38,0.089
143.08,19.41,0.089
143.08,19.43,0.089
143.08,19.46,0.089
143.09,19.48,0.089
143.10,19.51,0.089
143.10,19.53,0.089
143.10,19.56,0.089
143.11,19.58,0.089
143.12,19.61,0.089
143.12,19.63,0.089
143.13,19.66,0.090
143.13,19.68,0.090
143.13,19.71,0.090
143.14,19.73,0.090
143.15,19.76,0.090
143.15,19.78,0.090
143.15,19.81,0.090
143.16,19.83,0.090
143.17,19.86,0.090
143.17,19.88,0.090
143.18,19.91,0.090
143.18,19.93,0.090
143.18,19.96,0.090
143.19,19.98,0.090
143.20,20.01,0.090
143.20,20.03,0.090
143.20,20.06,0.090
143.21,20.08,0.090
143.22,20.11,0.090
143.22,20.13,0.090
143.23,20.16,0.090
143.23,20.18,0.090
143.23,20.21,0.090
143.24,20.23,0.090
143.25,20.26,0.090
143.25,20.28,0.090
143.25,20.31,0.090
143.26,20.33,0.090
143.27,20.36,0.090
143.27,20.38,0.090
143.28,20.41,0.090
143.28,20.43,0.090
143.28,20.46,0.090
143.29,20.48,0.090
143.30,20.51,0.090
143.30,20.53,0.090
143.30,20.56,0.090
143.31,20.58,0.090
143.32,20.61,0.090
143.32,20.63,0.090
143.33,20.66,0.090
143.33,20.68,0.090
143.33,20.71,0.090
143.34,20.73,0.090
143.35,20.76,0.090
143.35,20.78,0.090
143.35,20.81,0.090
143.36,20.83,0.090
143.37,20.86,0.090
143.37,20.88,0.090
143.38,20.91,0.090
143.38,20.93,0.090
143.38,20.96,0.090
143.39,20.98,0.090
143.40,21.01,0.090
143.40,21.03,0.090
143.40,21.06,0.090
143.41,21.08,0.090
143.42,21.11,0.090
143.42,21.13,0.090
143.43,21.16,0.090
143.43,21.18,0.090
143.43,21.21,0.090
143.44,21.23,0.090
143.45,21.26,0.090
143.45,21.28,0.090
143.45,21.31,0.090
143.46,21.33,0.090
143.47,21.36,0.090
143.47,21.38,0.090
143.48,21.41,0.090
143.48,21.43,0.090
143.48,21.46,0.090
143.49,21.48,0.090
143.50,21.51,0.090
143.50,21.53,0.090
143.50,21.56,0.090
143.51,21.58,0.090
143.52,21.61,0.090
143.52,21.63,0.090
143.53,21.66,0.090
143.53,21.68,0.090
143.53,21.71,0.090
143.54,21.73,0.090
143.55,21.76,0.090
143.55,21.78,0.090
143.55,21.81,0.090
143.56,21.83,0.090
143.57,21.86,0.090
143.57,21.88,0.090
143.58,21.91,0.090
143.58,21.93,0.090
143.58,21.96,0.090
143.59,21.98,0.090
143.60,22.01,0.090
143.60,22.03,0.090
143.60,22.06,0.090
143.61,22.08,0.090
143.62,22.11,0.090
143.62,22.13,0.090
143.63,22.16,0.090
143.63,22.18,0.090
143.63,22.21,0.090
143.64,22.23,0.090
143.65,22.26,0.090
143.65,22.28,0.090
143.65,22.31,0.090
143.66,22.33,0.090
143.67,22.36,0.090
143.67,22.38,0.090
143.68,22.41,0.090
143.68,22.43,0.090
143.68,22.46,0.090
143.69,22.48,0.090
143.70,22.51,0.090
143.70,22.53,0.090
143.70,22.56,0.090
143.71,22.58,0.090
143.72,22.61,0.090
143.72,22.64,0.090
143.73,22.66,0.090
143.73,22.68,0.090
143.73,22.71,0.090
143.74,22.73,0.090
143.75,22.76,0.090
143.75,22.78,0.090
143.75,22.81,0.090
143.76,22.83,0.090
143.77,22.86,0.090
143.77,22.88,0.090
143.78,22.91,0.090
143.78,22.93,0.090
143.78,22.96,0.090
143.79,22.98,0.090
143.80,23.01,0.090
143.80,23.03,0.090
143.80,23.06,0.090
143.81,23.08,0.090
143.82,23.11,0.090
143.82,23.13,0.090
143.83,23.16,0.090
143.83,23.18,0.090
143.83,23.21,0.090
143.84,23.23,0.090
143.85,23.26,0.090
143.85,23.28,0.090
143.85,23.31,0.090
143.86,23.34,0.090
143.87,23.36,0.090
143.87,23.38,0.090
143.88,23.41,0.090
143.88,23.43,0.090
143.88,23.46,0.090
143.89,23.49,0.090
143.90,23.51,0.090
143.90,23.53,0.091
143.90,23.56,0.091
143.91,23.58,0.091
143.92,23.61,0.091
143.92,23.63,0.091
143.93,23.66,0.091
143.93,23.69,0.091
143.93,23.71,0.091
143.94,23.74,0.091
143.95,23.76,0.091
143.95,23.78,0.091
143.95,23.81,0.091
143.96,23.84,0.091
143.97,23.86,0.091
143.97,23.89,0.091
143.98,23.91,0.091
143.98,23.94,0.091
143.98,23.96,0.091
143.99,23.99,0.091
144.00,24.01,0.091
144.00,24.04,0.091
144.00,24.06,0.091
144.01,24.09,0.091
144.02,24.11,0.091
144.02,24.14,0.091
144.03,24.16,0.091
144.03,24.19,0.091
144.03,24.21,0.091
144.04,24.24,0.091
144.05,24.26,0.091
144.05,24.29,0.091
144.05,24.31,0.091
144.06,24.34,0.091
144.07,24.36,0.091
144.07,24.39,0.091
144.08,24.41,0.091
144.08,24.44,0.091
144.08,24.46,0.091
144.09,24.49,0.091
144.10,24.51,0.091
144.10,24.54,0.091
144.10,24.56,0.091
144.11,24.59,0.091
144.12,24.61,0.091
144.12,24.63,0.091
144.13,24.66,0.091
144.13,24.68,0.091
144.13,24.71,0.091
144.14,24.74,0.091
144.15,24.76,0.091
144.15,24.79,0.091
144.15,24.81,0.091
144.16,24.84,0.091
144.17,24.86,0.091
144.17,24.89,0.091
144.18,24.91,0.091
144.18,24.94,0.091
144.18,24.96,0.091
144.19,24.98,0.091
144.20,25.01,0.091
144.20,25.04,0.091
144.20,25.06,0.091
144.21,25.08,0.091
144.22,25.11,0.091
144.22,25.13,0.091
144.23,25.16,0.091
144.23,25.18,0.091
144.23,25.21,0.091
144.24,25.23,0.091
144.25,25.26,0.091
144.25,25.28,0.091
144.25,25.31,0.091
144.26,25.33,0.091
144.27,25.36,0.091
144.27,25.38,0.091
144.28,25.41,0.091
144.28,25.43,0.091
144.28,25.46,0.091
144.29,25.48,0.091
144.30,25.51,0.091
144.30,25.53,0.091
144.30,25.56,0.091
144.31,25.58,0.091
144.32,25.61,0.091
144.32,25.64,0.091
144.33,25.66,0.091
144.33,25.69,0.091
144.33,25.71,0.091
144.34,25.74,0.091
144.35,25.76,0.091
144.35,25.79,0.091
144.35,25.81,0.091
144.36,25.83,0.091
144.37,25.86,0.091
144.37,25.88,0.091
144.38,25.91,0.091
144.38,25.94,0.091
144.38,25.96,0.091
144.39,25.99,0.091
144.40,26.01,0.091
144.40,26.03,0.091
144.40,26.06,0.091
144.41,26.09,0.091
144.42,26.11,0.091
144.42,26.14,0.091
144.43,26.16,0.091
144.43,26.19,0.091
144.43,26.21,0.091
144.44,26.24,0.091
144.45,26.26,0.091
144.45,26.29,0.091
144.45,26.31,0.091
144.46,26.34,0.091
144.47,26.36,0.091
144.47,26.39,0.091
144.48,26.41,0.091
144.48,26.44,0.091
144.48,26.46,0.091
144.49,26.49,0.091
144.50,26.51,0.091
144.50,26.54,0.091
144.50,26.56,0.091
144.51,26.59,0.091
144.52,26.61,0.091
144.52,26.64,0.091
144.53,26.66,0.091
144.53,26.69,0.091
144.53,26.71,0.091
144.54,26.74,0.091
144.55,26.76,0.091
144.55,26.79,0.091
144.55,26.81,0.091
144.56,26.84,0.091
144.57,26.86,0.091
144.57,26.89,0.091
144.58,26.91,0.091
144.58,26.94,0.091
144.58,26.96,0.091
144.59,26.98,0.091
144.60,27.01,0.091
144.60,27.04,0.091
144.60,27.06,0.091
144.61,27.09,0.091
144.62,27.11,0.091
144.62,27.14,0.091
144.63,27.16,0.091
144.63,27.19,0.091
144.63,27.21,0.091
144.64,27.24,0.091
144.65,27.26,0.091
144.65,27.29,0.091
144.65,27.31,0.091
144.66,27.34,0.091
144.67,27.36,0.091
144.67,27.39,0.091
144.68,27.41,0.091
144.68,27.44,0.091
144.68,27.46,0.091
144.69,27.49,0.091
144.70,27.51,0.091
144.70,27.54,0.091
144.70,27.56,0.091
144.71,27.59,0.091
144.72,27.61,0.091
144.72,27.64,0.091
144.73,27.66,0.091
144.73,27.69,0.091
144.73,27.71,0.091
144.74,27.74,0.092
144.75,27.76,0.092
144.75,27.79,0.092
144.75,27.81,0.092
144.76,27.84,0.092
144.77,27.86,0.092
144.77,27.89,0.092
144.78,27.91,0.092
144.78,27.94,0.092
144.78,27.96,0.092
144.79,27.99,0.092
144.80,28.01,0.092
144.80,28.04,0.092
144.80,28.06,0.092
144.81,28.09,0.092
144.82,28.11,0.092
144.82,28.14,0.092
144.83,28.16,0.092
144.83,28.19,0.092
144.83,28.21,0.092
144.84,28.24,0.092
144.85,28.26,0.092
144.85,28.29,0.092
144.85,28.31,0.092
144.86,28.34,0.092
144.87,28.36,0.092
144.87,28.39,0.092
144.88,28.41,0.092
144.88,28.44,0.092
144.88,28.46,0.092
144.89,28.49,0.092
144.90,28.51,0.092
144.90,28.54,0.092
144.90,28.56,0.092
144.91,28.59,0.092
144.92,28.61,0.092
144.92,28.64,0.092
144.93,28.66,0.092
144.93,28.69,0.092
144.93,28.71,0.092
144.94,28.74,0.092
144.95,28.76,0.092
144.95,28.79,0.092
144.95,28.81,0.092
144.96,28.84,
144.97,28.86,
144.97,28.89,
144.98,28.91,
144.98,28.94,
144.98,28.96,
144.99,28.99,
145.00,29.01,
145.00,29.04,
145.00,29.06,
145.01,,
145.02,,