File: DSC/2025_06_01_Felodipine_0C_160C_10Cmin_x3.csv
Filename,2025_06_01_Felodipine_0C_160C_10Cmin_x3
Instrument name,DSC2A-00468 (192.168.1.100)
Operator,Yarger
rundate,6/1/2025
Sample name,2025_06_01_Felodipine_0C_160C_10Cmin_x3
proceduresegments,Data Off ; Equilibrate 0.00 °C; Data On ; Ramp 10.00 °C/min to 160.00 °C; Data Off ; Isothermal 1.0 min; Data On ; Ramp 10.00 °C/min to 0.00 °C; Data Off ; Isothermal 1.0 min; Data On ; Ramp 10.00 °C/min to 160.00 °C; Data Off ; Isothermal 1.0 min; Data On ; Ramp 10.00 °C/min to 0.00 °C; Data Off ; Isothermal 1.0 min; Data On ; Ramp 10.00 °C/min to 30.00 °C
[File Parameters]
Run date,6/1/2025 7:39:32 PM
Trios version,5.1.1.46572
Original File Name,
Current File Name,D:\DSC2500\JYarger\2025_06_01_Felodipine_0C_160C_10Cmin_x3.tri
[Procedure]
Procedure Name,FEL_0C_160C_10Cmin_x3
Sample Name,2025_06_01_Felodipine_0C_160C_10Cmin_x3
Sample Mass,9.77 mg
Reference Sample Mass,0 mg
Pan Mass,56.97 mg
Pan Number,16
Reference Pan Mass,56.96 mg
Reference Pan Number,10
Pan Type,Tzero Aluminum Hermetic
Comments,Al Hermetic DSC Consumables sealed Pan/Lid. A2 Tray (Google Sheet: DSC_Samples_A2_Tray_May2025)
Project Name,CA
Operator,Yarger
Test,Custom
Unload Max Temperature,30
Unload Min Temperature,30
Load Max Temperature,30
Load Min Temperature,30
Stop on Gas Flow Error,Yes
[Signal List]
Signal #1,Time (min)
Signal #2,Temperature (°C)
Signal #3,Heat Flow (mW)
Signal #4,Delta T (µV)
Signal #5,Delta Tzero (µV)
Signal #6,Tzero Temperature (°C)
Signal #7,Cell Purge (mL/min)
Signal #8,Heater Temp (°C)
Signal #9,Power Delivered (W)
Signal #10,Reference Junction Temperature (°C)
Signal #11,Flange Temperature (°C)
Signal #12,Heat Flow Phase (rad)
Signal #13,Total Heat Capacity (J/°C)
Signal #14,Heat Capacity (J/°C)
[Configuration]
Company Name,ASU
Instrument Name,DSC2A-00468
Instrument Type,DSC2500
Serial Number,DSC2A-00468
IP,192.168.1.100
Location of Instrument,MRRC
DisplayType,Unknown
Sample Interval ,0.1 s/pt
Selected Heat Flow,T4P
Exotherm Direction,Down
Cell Serial,DRC2-00792
Lid Type,Standard
Cooler,RCS 90
Leave Cooler on at End of Sequence,On
Gas 2,Nitrogen
Gas Selected,Channel 1
Flow Rate,50 mL/min
Secondary Purge,On
Licensed Heat Flow,Heat Flow T4P
Modulation Licensed,Yes
[Versions]
Common IDD Version,1
Cortex Version,VER 2.10.2.31
Driver,5.0.0.6
GDM Version,1.0.3.3
TouchscreenVersion,1.0.0.16145
FEP Version,1.2.1.21
FEP Bootloader,2.0.0.5
AutoSampler Version,2.1.1.26
Auto Sampler Bootloader,2.0.0.5
FCM Version,1.1.0.3
FCM Bootloader,2.0.0.5
[Experiment Logs]
Experiment Log Entry # 1,Data On set to 0
Experiment Log Entry # 3,Equilibrate Segment 0 (C) Started
Experiment Log Entry # 5,Data On set to 1
Experiment Log Entry # 7,Ramp Segment 10 C/min to 160 Started
Experiment Log Entry # 9,Data On set to 0
Experiment Log Entry # 11,Isothermal Segment 1 min started
Experiment Log Entry # 13,Data On set to 1
Experiment Log Entry # 15,Ramp Segment 10 C/min to 0 Started
Experiment Log Entry # 17,Data On set to 0
Experiment Log Entry # 19,Isothermal Segment 1 min started
Experiment Log Entry # 21,Data On set to 1
Experiment Log Entry # 23,Ramp Segment 10 C/min to 160 Started
Experiment Log Entry # 25,Data On set to 0
Experiment Log Entry # 27,Isothermal Segment 1 min started
Experiment Log Entry # 29,Data On set to 1
Experiment Log Entry # 31,Ramp Segment 10 C/min to 0 Started
Experiment Log Entry # 33,Data On set to 0
Experiment Log Entry # 35,Isothermal Segment 1 min started
Experiment Log Entry # 37,Data On set to 1
Experiment Log Entry # 39,Ramp Segment 10 C/min to 30 Started
[Method Log]
Method Log Entry # 1,Data Off
Method Log Entry # 2,Equilibrate 0 °C
Method Log Entry # 3,Data On
Method Log Entry # 4,(Ramp 747673) Ramp 10 °C/minute to 160 °C
Method Log Entry # 5,Data Off
Method Log Entry # 6,Isothermal 1 minutes
Method Log Entry # 7,Data On
Method Log Entry # 8,(Ramp 747677) Ramp 10 °C/minute to 0 °C
Method Log Entry # 9,Data Off
Method Log Entry # 10,Isothermal 1 minutes
Method Log Entry # 11,Data On
Method Log Entry # 12,(Ramp 747681) Ramp 10 °C/minute to 160 °C
Method Log Entry # 13,Data Off
Method Log Entry # 14,Isothermal 1 minutes
Method Log Entry # 15,Data On
Method Log Entry # 16,(Ramp 747685) Ramp 10 °C/minute to 0 °C
Method Log Entry # 17,Data Off
Method Log Entry # 18,Isothermal 1 minutes
Method Log Entry # 19,Data On
Method Log Entry # 20,(Ramp 747689) Ramp 10 °C/minute to 30 °C
Cell Serial,DRC2-00792
[T1 Calibration]
Slope,-0.008529666
Offset,9.636258
Initial Temperature,98.23
GUID,f8bfdadc-4977-4fdf-ba6d-0ba9134940c3
[TZero Calibration]
Date Applied,11/29/2022 4:06:13 PM
Description,From -89.059 °C to 396.009 °C at 20.000°C/min
Gas Type,Nitrogen
Pan Type,None
Source Files 1,C:\Users\yargerlab\Desktop\DSC Data\General\TZero_calibration_11_29_22_2nd(2).tri
Source Files 2,C:\Users\yargerlab\Desktop\DSC Data\General\TZero_calibration_11_29_22_2nd(3).tri
Delta T Offset,13.05235
Delta T Slope,-0.007271007
Delta T0 Offset,-13.69128
Delta T0 Slope,0.06063341
[Temperature Calibration]
Date Applied,11/29/2022 7:12:28 PM
Description,From 106.590 °C to 186.590 °C at 10.000°C/min
Gas Type,Nitrogen
Pan Type,Tzero Aluminum Hermetic
Source Files 1,C:\Users\yargerlab\Desktop\DSC Data\General\Indium(6).tri
Measured 1,157.391
Known 1,156.598
[Cell Constant Calibration]
Date Applied,11/29/2022 7:12:29 PM
Description,From 106.590 °C to 186.590 °C at 10.000°C/min
Gas Type,Nitrogen
Pan Type,Tzero Aluminum Hermetic
Source Files 1,C:\Users\yargerlab\Desktop\DSC Data\General\Indium(6).tri
T4P KCell,1.006051
Onset Slope,63.26126 mW/°C
[Direct Cp Calibration]
Date Applied,11/30/2022 11:04:51 AM
Description,From -79.983 °C to 298.409 °C at 10.000°C/min
Gas Type,Nitrogen
Pan Type,Tzero Aluminum Hermetic
Source Files 1,C:\Users\yargerlab\Desktop\DSC Data\General\Sapphire_Heat_Capacity_11_30_22.tri
[Rev Cp Calibration]
Date Applied,11/30/2022 1:58:51 PM
Description,From -79.996 °C to 292.812 °C at 3.000°C/min
Gas Type,Nitrogen
Pan Type,Tzero Aluminum Hermetic
Source Files 1,C:\Users\yargerlab\Desktop\DSC Data\General\Sapphire_MDSC_Calibration_11_30_22.tri
[step]
Ramp 10.00 °C/min to 160.00 °C
Time,Temperature,Heat Flow (Normalized)
min,°C,W/g
0.00,0.13,-0.031
0.01,0.13,-0.031
0.02,0.13,-0.029
0.03,0.13,-0.027
0.05,0.13,-0.025
0.06,0.14,-0.023
0.07,0.15,-0.021
0.08,0.16,-0.017
0.09,0.18,-0.012
0.11,0.22,-0.007
0.12,0.26,0.000
0.13,0.31,0.009
0.14,0.36,0.019
0.15,0.42,0.030
0.16,0.49,0.041
0.18,0.57,0.052
0.19,0.64,0.062
0.20,0.72,0.072
0.21,0.81,0.081
0.22,0.90,0.089
0.23,0.98,0.096
0.24,1.07,0.103
0.26,1.17,0.110
0.27,1.26,0.115
0.28,1.36,0.120
0.29,1.46,0.126
0.30,1.56,0.130
0.31,1.66,0.134
0.33,1.76,0.139
0.34,1.87,0.141
0.35,1.97,0.145
0.36,2.08,0.149
0.37,2.18,0.151
0.39,2.29,0.154
0.40,2.40,0.156
0.41,2.51,0.158
0.42,2.62,0.161
0.43,2.73,0.162
0.44,2.84,0.163
0.45,2.95,0.165
0.47,3.06,0.166
0.48,3.17,0.167
0.49,3.28,0.168
0.50,3.39,0.170
0.51,3.51,0.171
0.53,3.62,0.172
0.54,3.73,0.173
0.55,3.85,0.173
0.56,3.96,0.174
0.57,4.07,0.175
0.58,4.19,0.175
0.60,4.30,0.175
0.61,4.41,0.176
0.62,4.53,0.177
0.63,4.64,0.177
0.64,4.76,0.177
0.65,4.87,0.178
0.67,4.98,0.178
0.68,5.10,0.178
0.69,5.21,0.179
0.70,5.33,0.179
0.71,5.44,0.179
0.72,5.56,0.179
0.73,5.67,0.180
0.75,5.79,0.180
0.76,5.90,0.180
0.77,6.02,0.180
0.78,6.13,0.180
0.79,6.25,0.181
0.80,6.36,0.181
0.82,6.48,0.181
0.83,6.59,0.181
0.84,6.71,0.181
0.85,6.83,0.181
0.86,6.94,0.182
0.88,7.06,0.182
0.89,7.17,0.182
0.90,7.29,0.182
0.91,7.40,0.182
0.92,7.52,0.182
0.93,7.63,0.183
0.95,7.75,0.183
0.96,7.87,0.183
0.97,7.98,0.183
0.98,8.10,0.183
0.99,8.21,0.183
1.00,8.33,0.184
1.02,8.44,0.184
1.03,8.56,0.184
1.04,8.68,0.184
1.05,8.79,0.184
1.06,8.91,0.184
1.07,9.03,0.184
1.08,9.14,0.185
1.10,9.26,0.185
1.11,9.37,0.185
1.12,9.49,0.185
1.13,9.61,0.185
1.14,9.72,0.185
1.16,9.84,0.185
1.17,9.95,0.186
1.18,10.07,0.186
1.19,10.19,0.186
1.20,10.30,0.186
1.21,10.42,0.186
1.23,10.53,0.186
1.24,10.65,0.186
1.25,10.77,0.186
1.26,10.88,0.187
1.27,11.00,0.187
1.28,11.12,0.187
1.29,11.23,0.187
1.31,11.35,0.187
1.32,11.47,0.187
1.33,11.58,0.187
1.34,11.70,0.188
1.35,11.81,0.188
1.37,11.93,0.188
1.38,12.05,0.188
1.39,12.16,0.188
1.40,12.28,0.188
1.41,12.40,0.188
1.42,12.51,0.188
1.43,12.63,0.188
1.45,12.75,0.189
1.46,12.86,0.189
1.47,12.98,0.189
1.48,13.10,0.189
1.49,13.21,0.189
1.51,13.33,0.189
1.52,13.45,0.189
1.53,13.56,0.189
1.54,13.68,0.190
1.55,13.79,0.190
1.56,13.91,0.190
1.58,14.03,0.190
1.59,14.15,0.190
1.60,14.26,0.190
1.61,14.38,0.190
1.62,14.49,0.190
1.63,14.61,0.191
1.64,14.73,0.191
1.66,14.84,0.191
1.67,14.96,0.191
1.68,15.08,0.191
1.69,15.19,0.191
1.70,15.31,0.191
1.72,15.43,0.191
1.73,15.54,0.191
1.74,15.66,0.192
1.75,15.78,0.192
1.76,15.89,0.192
1.77,16.01,0.192
1.78,16.13,0.192
1.80,16.24,0.192
1.81,16.36,0.192
1.82,16.48,0.192
1.83,16.59,0.192
1.84,16.71,0.193
1.86,16.83,0.193
1.87,16.94,0.193
1.88,17.06,0.193
1.89,17.18,0.193
1.90,17.29,0.193
1.91,17.41,0.193
1.93,17.53,0.193
1.94,17.64,0.193
1.95,17.76,0.194
1.96,17.88,0.194
1.97,17.99,0.194
1.98,18.11,0.194
1.99,18.23,0.194
2.01,18.34,0.194
2.02,18.46,0.194
2.03,18.58,0.194
2.04,18.69,0.194
2.05,18.81,0.194
2.07,18.93,0.195
2.08,19.04,0.195
2.09,19.16,0.195
2.10,19.28,0.195
2.11,19.39,0.195
2.12,19.51,0.195
2.14,19.63,0.195
2.15,19.74,0.195
2.16,19.86,0.195
2.17,19.98,0.195
2.18,20.09,0.196
2.19,20.21,0.196
2.21,20.33,0.196
2.22,20.44,0.196
2.23,20.56,0.196
2.24,20.68,0.196
2.25,20.79,0.196
2.26,20.91,0.196
2.28,21.03,0.196
2.29,21.14,0.197
2.30,21.26,0.197
2.31,21.38,0.197
2.32,21.49,0.197
2.33,21.61,0.197
2.34,21.73,0.197
2.36,21.84,0.197
2.37,21.96,0.197
2.38,22.08,0.197
2.39,22.19,0.197
2.40,22.31,0.198
2.41,22.43,0.198
2.43,22.54,0.198
2.44,22.66,0.198
2.45,22.78,0.198
2.46,22.89,0.198
2.47,23.01,0.198
2.49,23.13,0.198
2.50,23.25,0.198
2.51,23.36,0.199
2.52,23.48,0.199
2.53,23.59,0.199
2.54,23.71,0.199
2.56,23.83,0.199
2.57,23.94,0.199
2.58,24.06,0.199
2.59,24.18,0.199
2.60,24.29,0.199
2.61,24.41,0.200
2.63,24.53,0.200
2.64,24.64,0.200
2.65,24.76,0.200
2.66,24.88,0.200
2.67,24.99,0.200
2.68,25.11,0.200
2.69,25.23,0.200
2.71,25.35,0.201
2.72,25.46,0.201
2.73,25.58,0.201
2.74,25.70,0.201
2.75,25.81,0.201
2.76,25.93,0.201
2.78,26.05,0.201
2.79,26.16,0.202
2.80,26.28,0.202
2.81,26.40,0.202
2.82,26.51,0.202
2.84,26.63,0.202
2.85,26.75,0.202
2.86,26.86,0.202
2.87,26.98,0.202
2.88,27.10,0.203
2.89,27.21,0.203
2.91,27.33,0.203
2.92,27.45,0.203
2.93,27.56,0.203
2.94,27.68,0.203
2.95,27.80,0.203
2.96,27.91,0.203
2.98,28.03,0.204
2.99,28.15,0.204
3.00,28.27,0.204
3.01,28.38,0.204
3.02,28.50,0.204
3.03,28.62,0.204
3.04,28.73,0.204
3.06,28.85,0.204
3.07,28.96,0.205
3.08,29.08,0.205
3.09,29.20,0.205
3.10,29.31,0.205
3.11,29.43,0.205
3.13,29.55,0.205
3.14,29.67,0.205
3.15,29.78,0.205
3.16,29.90,0.206
3.17,30.02,0.206
3.19,30.13,0.206
3.20,30.25,0.206
3.21,30.36,0.206
3.22,30.48,0.206
3.23,30.60,0.207
3.24,30.72,0.207
3.26,30.83,0.207
3.27,30.95,0.207
3.28,31.07,0.207
3.29,31.18,0.207
3.30,31.30,0.207
3.31,31.42,0.208
3.33,31.53,0.208
3.34,31.65,0.208
3.35,31.77,0.208
3.36,31.88,0.208
3.37,32.00,0.208
3.38,32.12,0.208
3.39,32.23,0.209
3.41,32.35,0.209
3.42,32.47,0.209
3.43,32.58,0.209
3.44,32.70,0.209
3.45,32.82,0.209
3.46,32.93,0.209
3.48,33.05,0.209
3.49,33.17,0.210
3.50,33.28,0.210
3.51,33.40,0.210
3.52,33.52,0.210
3.54,33.63,0.210
3.55,33.75,0.210
3.56,33.87,0.210
3.57,33.99,0.210
3.58,34.10,0.210
3.59,34.22,0.210
3.61,34.33,0.210
3.62,34.45,0.210
3.63,34.57,0.210
3.64,34.69,0.211
3.65,34.80,0.211
3.66,34.92,0.211
3.68,35.03,0.211
3.69,35.15,0.211
3.70,35.27,0.211
3.71,35.38,0.211
3.72,35.50,0.211
3.73,35.62,0.211
3.74,35.73,0.212
3.76,35.85,0.212
3.77,35.97,0.212
3.78,36.09,0.212
3.79,36.20,0.212
3.80,36.32,0.212
3.81,36.43,0.213
3.83,36.55,0.213
3.84,36.67,0.213
3.85,36.78,0.213
3.86,36.90,0.213
3.87,37.02,0.214
3.89,37.13,0.214
3.90,37.25,0.214
3.91,37.37,0.215
3.92,37.48,0.215
3.93,37.60,0.216
3.94,37.72,0.216
3.96,37.84,0.216
3.97,37.95,0.217
3.98,38.07,0.217
3.99,38.19,0.217
4.00,38.30,0.218
4.01,38.42,0.218
4.03,38.54,0.218
4.04,38.65,0.219
4.05,38.77,0.219
4.06,38.89,0.219
4.07,39.00,0.220
4.08,39.12,0.220
4.09,39.24,0.221
4.11,39.35,0.221
4.12,39.47,0.222
4.13,39.58,0.223
4.14,39.70,0.223
4.15,39.82,0.224
4.16,39.93,0.225
4.18,40.05,0.225
4.19,40.17,0.226
4.20,40.28,0.227
4.21,40.40,0.228
4.22,40.51,0.229
4.24,40.63,0.230
4.25,40.75,0.231
4.26,40.86,0.232
4.27,40.98,0.232
4.28,41.10,0.234
4.29,41.21,0.236
4.30,41.33,0.237
4.32,41.45,0.238
4.33,41.56,0.240
4.34,41.68,0.241
4.35,41.79,0.243
4.36,41.91,0.245
4.38,42.02,0.247
4.39,42.14,0.248
4.40,42.26,0.251
4.41,42.37,0.253
4.42,42.49,0.255
4.43,42.60,0.259
4.45,42.72,0.261
4.46,42.83,0.264
4.47,42.95,0.268
4.48,43.06,0.271
4.49,43.18,0.276
4.50,43.29,0.280
4.51,43.41,0.284
4.53,43.52,0.289
4.54,43.64,0.294
4.55,43.75,0.299
4.56,43.86,0.306
4.57,43.98,0.313
4.59,44.09,0.318
4.60,44.20,0.325
4.61,44.32,0.333
4.62,44.43,0.339
4.63,44.54,0.346
4.64,44.65,0.354
4.65,44.77,0.360
4.67,44.88,0.366
4.68,44.99,0.372
4.69,45.10,0.379
4.70,45.22,0.383
4.71,45.33,0.388
4.73,45.44,0.392
4.74,45.56,0.396
4.75,45.67,0.399
4.76,45.78,0.401
4.77,45.90,0.405
4.78,46.01,0.406
4.80,46.13,0.408
4.81,46.24,0.408
4.82,46.35,0.410
4.83,46.47,0.411
4.84,46.59,0.412
4.85,46.70,0.413
4.86,46.82,0.413
4.88,46.93,0.414
4.89,47.05,0.414
4.90,47.16,0.415
4.91,47.28,0.415
4.92,47.40,0.416
4.94,47.51,0.416
4.95,47.63,0.417
4.96,47.75,0.417
4.97,47.86,0.418
4.98,47.98,0.418
4.99,48.09,0.418
5.00,48.21,0.418
5.02,48.33,0.418
5.03,48.44,0.418
5.04,48.56,0.418
5.05,48.68,0.418
5.06,48.79,0.418
5.08,48.91,0.418
5.09,49.03,0.418
5.10,49.15,0.418
5.11,49.26,0.418
5.12,49.38,0.417
5.13,49.50,0.415
5.15,49.61,0.413
5.16,49.73,0.411
5.17,49.85,0.407
5.18,49.97,0.404
5.19,50.09,0.400
5.20,50.20,0.395
5.21,50.32,0.391
5.23,50.44,0.385
5.24,50.56,0.380
5.25,50.68,0.373
5.26,50.80,0.366
5.27,50.92,0.359
5.29,51.04,0.352
5.30,51.16,0.344
5.31,51.28,0.337
5.32,51.40,0.330
5.33,51.53,0.324
5.34,51.65,0.318
5.35,51.77,0.313
5.37,51.89,0.310
5.38,52.01,0.306
5.39,52.13,0.302
5.40,52.25,0.300
5.41,52.37,0.298
5.43,52.49,0.296
5.44,52.61,0.295
5.45,52.73,0.294
5.46,52.85,0.292
5.47,52.96,0.292
5.48,53.08,0.291
5.50,53.20,0.289
5.51,53.32,0.289
5.52,53.44,0.289
5.53,53.55,0.288
5.54,53.67,0.287
5.55,53.79,0.287
5.56,53.91,0.286
5.58,54.03,0.286
5.59,54.14,0.286
5.60,54.26,0.285
5.61,54.38,0.285
5.62,54.50,0.285
5.64,54.61,0.285
5.65,54.73,0.285
5.66,54.85,0.284
5.67,54.96,0.284
5.68,55.08,0.284
5.69,55.20,0.284
5.70,55.32,0.284
5.72,55.43,0.284
5.73,55.55,0.284
5.74,55.67,0.284
5.75,55.78,0.284
5.76,55.90,0.284
5.78,56.02,0.284
5.79,56.13,0.283
5.80,56.25,0.283
5.81,56.37,0.283
5.82,56.48,0.283
5.83,56.60,0.283
5.85,56.72,0.283
5.86,56.84,0.283
5.87,56.95,0.283
5.88,57.07,0.283
5.89,57.19,0.283
5.90,57.30,0.283
5.91,57.42,0.283
5.93,57.54,0.283
5.94,57.65,0.283
5.95,57.77,0.283
5.96,57.89,0.283
5.97,58.00,0.283
5.99,58.12,0.283
6.00,58.24,0.283
6.01,58.35,0.283
6.02,58.47,0.283
6.03,58.59,0.283
6.04,58.70,0.283
6.05,58.82,0.283
6.07,58.94,0.283
6.08,59.05,0.283
6.09,59.17,0.283
6.10,59.29,0.283
6.11,59.40,0.283
6.13,59.52,0.283
6.14,59.64,0.283
6.15,59.76,0.283
6.16,59.87,0.283
6.17,59.99,0.283
6.18,60.11,0.283
6.20,60.22,0.283
6.21,60.34,0.283
6.22,60.46,0.283
6.23,60.57,0.283
6.24,60.69,0.283
6.25,60.81,0.283
6.26,60.92,0.283
6.28,61.04,0.283
6.29,61.16,0.283
6.30,61.27,0.283
6.31,61.39,0.283
6.32,61.51,0.283
6.34,61.62,0.283
6.35,61.74,0.283
6.36,61.86,0.283
6.37,61.97,0.283
6.38,62.09,0.283
6.39,62.21,0.283
6.40,62.33,0.283
6.42,62.44,0.283
6.43,62.56,0.283
6.44,62.67,0.284
6.45,62.79,0.284
6.46,62.91,0.284
6.48,63.02,0.284
6.49,63.14,0.284
6.50,63.26,0.284
6.51,63.37,0.284
6.52,63.49,0.284
6.53,63.61,0.284
6.55,63.73,0.284
6.56,63.84,0.284
6.57,63.96,0.284
6.58,64.08,0.284
6.59,64.19,0.284
6.60,64.31,0.284
6.61,64.43,0.284
6.63,64.54,0.284
6.64,64.66,0.285
6.65,64.78,0.285
6.66,64.89,0.285
6.67,65.01,0.285
6.69,65.13,0.285
6.70,65.25,0.285
6.71,65.36,0.285
6.72,65.48,0.285
6.73,65.59,0.285
6.74,65.71,0.285
6.75,65.83,0.285
6.77,65.95,0.285
6.78,66.06,0.285
6.79,66.18,0.285
6.80,66.30,0.285
6.81,66.41,0.285
6.83,66.53,0.285
6.84,66.65,0.285
6.85,66.76,0.285
6.86,66.88,0.286
6.87,67.00,0.286
6.88,67.11,0.286
6.90,67.23,0.286
6.91,67.35,0.286
6.92,67.46,0.286
6.93,67.58,0.286
6.94,67.70,0.286
6.95,67.81,0.286
6.96,67.93,0.286
6.98,68.05,0.286
6.99,68.16,0.286
7.00,68.28,0.286
7.01,68.40,0.286
7.02,68.51,0.286
7.04,68.63,0.286
7.05,68.75,0.286
7.06,68.86,0.286
7.07,68.98,0.287
7.08,69.10,0.287
7.09,69.21,0.287
7.10,69.33,0.287
7.12,69.45,0.287
7.13,69.56,0.287
7.14,69.68,0.287
7.15,69.80,0.287
7.16,69.91,0.287
7.18,70.03,0.287
7.19,70.15,0.287
7.20,70.27,0.287
7.21,70.38,0.287
7.22,70.50,0.287
7.23,70.62,0.288
7.25,70.73,0.288
7.26,70.85,0.288
7.27,70.97,0.288
7.28,71.08,0.288
7.29,71.20,0.288
7.30,71.32,0.288
7.31,71.43,0.288
7.33,71.55,0.288
7.34,71.67,0.288
7.35,71.78,0.288
7.36,71.90,0.288
7.37,72.02,0.288
7.39,72.13,0.288
7.40,72.25,0.288
7.41,72.37,0.288
7.42,72.48,0.288
7.43,72.60,0.288
7.44,72.72,0.289
7.45,72.84,0.289
7.47,72.95,0.289
7.48,73.07,0.289
7.49,73.19,0.289
7.50,73.30,0.289
7.51,73.42,0.289
7.53,73.54,0.289
7.54,73.65,0.289
7.55,73.77,0.289
7.56,73.89,0.289
7.57,74.00,0.289
7.58,74.12,0.289
7.60,74.24,0.289
7.61,74.35,0.289
7.62,74.47,0.290
7.63,74.59,0.290
7.64,74.71,0.290
7.65,74.82,0.290
7.66,74.94,0.290
7.68,75.06,0.290
7.69,75.17,0.290
7.70,75.29,0.290
7.71,75.40,0.290
7.72,75.52,0.290
7.74,75.64,0.290
7.75,75.76,0.290
7.76,75.87,0.290
7.77,75.99,0.290
7.78,76.11,0.290
7.79,76.22,0.290
7.80,76.34,0.290
7.82,76.46,0.290
7.83,76.57,0.291
7.84,76.69,0.291
7.85,76.81,0.291
7.86,76.92,0.291
7.88,77.04,0.291
7.89,77.16,0.291
7.90,77.27,0.291
7.91,77.39,0.291
7.92,77.51,0.291
7.93,77.62,0.291
7.95,77.74,0.291
7.96,77.86,0.291
7.97,77.97,0.291
7.98,78.09,0.291
7.99,78.21,0.291
8.00,78.32,0.292
8.01,78.44,0.292
8.03,78.56,0.292
8.04,78.67,0.292
8.05,78.79,0.292
8.06,78.91,0.292
8.07,79.03,0.292
8.09,79.14,0.292
8.10,79.26,0.292
8.11,79.38,0.292
8.12,79.49,0.292
8.13,79.61,0.292
8.14,79.73,0.292
8.15,79.84,0.292
8.17,79.96,0.292
8.18,80.08,0.292
8.19,80.19,0.292
8.20,80.31,0.293
8.21,80.43,0.293
8.23,80.54,0.293
8.24,80.66,0.293
8.25,80.78,0.293
8.26,80.89,0.293
8.27,81.01,0.293
8.28,81.13,0.293
8.30,81.24,0.293
8.31,81.36,0.293
8.32,81.48,0.293
8.33,81.59,0.293
8.34,81.71,0.293
8.35,81.83,0.293
8.36,81.94,0.293
8.38,82.06,0.293
8.39,82.18,0.293
8.40,82.29,0.293
8.41,82.41,0.293
8.42,82.53,0.293
8.44,82.65,0.293
8.45,82.76,0.294
8.46,82.88,0.294
8.47,82.99,0.294
8.48,83.11,0.294
8.49,83.23,0.294
8.50,83.34,0.294
8.52,83.46,0.294
8.53,83.58,0.294
8.54,83.69,0.294
8.55,83.81,0.294
8.56,83.93,0.294
8.58,84.05,0.294
8.59,84.16,0.294
8.60,84.28,0.294
8.61,84.40,0.294
8.62,84.51,0.294
8.63,84.63,0.294
8.65,84.75,0.294
8.66,84.87,0.294
8.67,84.98,0.294
8.68,85.10,0.294
8.69,85.21,0.294
8.70,85.33,0.294
8.72,85.45,0.294
8.73,85.56,0.295
8.74,85.68,0.295
8.75,85.80,0.295
8.76,85.92,0.295
8.77,86.03,0.295
8.78,86.15,0.295
8.80,86.27,0.295
8.81,86.38,0.295
8.82,86.50,0.295
8.83,86.62,0.295
8.84,86.73,0.295
8.85,86.85,0.295
8.87,86.97,0.295
8.88,87.08,0.295
8.89,87.20,0.295
8.90,87.32,0.295
8.91,87.43,0.295
8.93,87.55,0.295
8.94,87.67,0.295
8.95,87.78,0.295
8.96,87.90,0.295
8.97,88.02,0.296
8.98,88.13,0.296
9.00,88.25,0.296
9.01,88.37,0.296
9.02,88.48,0.296
9.03,88.60,0.296
9.04,88.72,0.296
9.05,88.83,0.296
9.07,88.95,0.296
9.08,89.07,0.296
9.09,89.19,0.296
9.10,89.30,0.296
9.11,89.42,0.296
9.12,89.54,0.296
9.13,89.65,0.296
9.15,89.77,0.296
9.16,89.89,0.296
9.17,90.00,0.297
9.18,90.12,0.297
9.19,90.24,0.297
9.20,90.35,0.297
9.22,90.47,0.297
9.23,90.59,0.297
9.24,90.70,0.297
9.25,90.82,0.297
9.26,90.94,0.297
9.28,91.05,0.297
9.29,91.17,0.297
9.30,91.29,0.297
9.31,91.40,0.297
9.32,91.52,0.297
9.33,91.64,0.297
9.35,91.76,0.298
9.36,91.87,0.298
9.37,91.99,0.298
9.38,92.11,0.298
9.39,92.22,0.298
9.40,92.34,0.298
9.42,92.46,0.298
9.43,92.57,0.298
9.44,92.69,0.298
9.45,92.81,0.298
9.46,92.92,0.298
9.47,93.04,0.298
9.48,93.16,0.298
9.50,93.28,0.299
9.51,93.39,0.299
9.52,93.51,0.299
9.53,93.63,0.299
9.54,93.75,0.299
9.55,93.86,0.299
9.57,93.98,0.299
9.58,94.10,0.299
9.59,94.21,0.299
9.60,94.33,0.299
9.61,94.45,0.299
9.63,94.56,0.299
9.64,94.68,0.299
9.65,94.80,0.300
9.66,94.91,0.300
9.67,95.03,0.300
9.68,95.15,0.300
9.70,95.26,0.300
9.71,95.38,0.300
9.72,95.50,0.300
9.73,95.61,0.300
9.74,95.73,0.300
9.75,95.85,0.300
9.77,95.96,0.300
9.78,96.08,0.300
9.79,96.20,0.300
9.80,96.31,0.300
9.81,96.43,0.300
9.82,96.55,0.300
9.83,96.66,0.300
9.85,96.78,0.300
9.86,96.90,0.300
9.87,97.01,0.300
9.88,97.13,0.300
9.89,97.25,0.300
9.90,97.36,0.300
9.92,97.48,0.300
9.93,97.60,0.300
9.94,97.71,0.300
9.95,97.83,0.300
9.96,97.95,0.300
9.98,98.06,0.300
9.99,98.18,0.300
10.00,98.30,0.300
10.01,98.41,0.301
10.02,98.53,0.301
10.03,98.65,0.301
10.05,98.76,0.301
10.06,98.88,0.301
10.07,99.00,0.301
10.08,99.11,0.301
10.09,99.23,0.301
10.10,99.35,0.301
10.12,99.46,0.301
10.13,99.58,0.301
10.14,99.70,0.301
10.15,99.81,0.301
10.16,99.93,0.301
10.17,100.05,0.301
10.18,100.16,0.301
10.20,100.28,0.301
10.21,100.40,0.301
10.22,100.51,0.301
10.23,100.63,0.301
10.24,100.75,0.302
10.25,100.87,0.302
10.27,100.98,0.302
10.28,101.10,0.302
10.29,101.21,0.302
10.30,101.33,0.302
10.31,101.45,0.302
10.33,101.56,0.302
10.34,101.68,0.302
10.35,101.80,0.302
10.36,101.91,0.302
10.37,102.03,0.302
10.38,102.15,0.302
10.40,102.27,0.302
10.41,102.38,0.302
10.42,102.50,0.302
10.43,102.62,0.302
10.44,102.73,0.303
10.45,102.85,0.303
10.47,102.97,0.303
10.48,103.08,0.303
10.49,103.20,0.303
10.50,103.32,0.303
10.51,103.43,0.303
10.52,103.55,0.303
10.53,103.67,0.303
10.55,103.78,0.303
10.56,103.90,0.303
10.57,104.02,0.303
10.58,104.13,0.303
10.59,104.25,0.303
10.60,104.37,0.303
10.62,104.48,0.303
10.63,104.60,0.303
10.64,104.72,0.303
10.65,104.83,0.303
10.66,104.95,0.303
10.68,105.07,0.304
10.69,105.19,0.304
10.70,105.30,0.304
10.71,105.42,0.304
10.72,105.54,0.304
10.73,105.65,0.304
10.75,105.77,0.304
10.76,105.89,0.304
10.77,106.00,0.304
10.78,106.12,0.304
10.79,106.24,0.304
10.80,106.35,0.304
10.82,106.47,0.304
10.83,106.59,0.304
10.84,106.70,0.304
10.85,106.82,0.304
10.86,106.94,0.304
10.87,107.05,0.304
10.88,107.17,0.304
10.90,107.29,0.304
10.91,107.40,0.304
10.92,107.52,0.304
10.93,107.64,0.304
10.94,107.75,0.304
10.95,107.87,0.305
10.97,107.99,0.305
10.98,108.10,0.305
10.99,108.22,0.305
11.00,108.34,0.305
11.01,108.45,0.305
11.03,108.57,0.305
11.04,108.69,0.305
11.05,108.81,0.305
11.06,108.92,0.305
11.07,109.04,0.305
11.08,109.15,0.305
11.10,109.27,0.305
11.11,109.39,0.305
11.12,109.50,0.305
11.13,109.62,0.305
11.14,109.74,0.305
11.15,109.86,0.305
11.17,109.97,0.305
11.18,110.09,0.305
11.19,110.20,0.305
11.20,110.32,0.306
11.21,110.44,0.306
11.22,110.56,0.306
11.23,110.67,0.306
11.25,110.79,0.306
11.26,110.91,0.306
11.27,111.02,0.306
11.28,111.14,0.306
11.29,111.26,0.306
11.30,111.37,0.306
11.32,111.49,0.306
11.33,111.61,0.306
11.34,111.73,0.306
11.35,111.84,0.306
11.36,111.96,0.306
11.38,112.08,0.306
11.39,112.19,0.306
11.40,112.31,0.306
11.41,112.43,0.306
11.42,112.54,0.306
11.43,112.66,0.306
11.45,112.78,0.306
11.46,112.89,0.306
11.47,113.01,0.306
11.48,113.12,0.306
11.49,113.24,0.306
11.50,113.36,0.307
11.52,113.48,0.306
11.53,113.59,0.306
11.54,113.71,0.306
11.55,113.83,0.307
11.56,113.94,0.307
11.57,114.06,0.307
11.58,114.18,0.307
11.60,114.29,0.307
11.61,114.41,0.307
11.62,114.53,0.307
11.63,114.64,0.307
11.64,114.76,0.307
11.65,114.88,0.307
11.67,114.99,0.307
11.68,115.11,0.307
11.69,115.23,0.307
11.70,115.35,0.307
11.71,115.46,0.307
11.73,115.58,0.307
11.74,115.69,0.307
11.75,115.81,0.307
11.76,115.93,0.307
11.77,116.05,0.307
11.78,116.16,0.307
11.80,116.28,0.307
11.81,116.40,0.307
11.82,116.51,0.307
11.83,116.63,0.307
11.84,116.75,0.307
11.85,116.86,0.308
11.87,116.98,0.308
11.88,117.10,0.308
11.89,117.21,0.308
11.90,117.33,0.308
11.91,117.45,0.308
11.92,117.56,0.308
11.93,117.68,0.308
11.95,117.80,0.308
11.96,117.91,0.308
11.97,118.03,0.308
11.98,118.15,0.308
11.99,118.26,0.308
12.00,118.38,0.308
12.02,118.50,0.308
12.03,118.61,0.308
12.04,118.73,0.308
12.05,118.85,0.308
12.06,118.96,0.308
12.08,119.08,0.308
12.09,119.20,0.308
12.10,119.31,0.308
12.11,119.43,0.308
12.12,119.55,0.308
12.13,119.67,0.308
12.15,119.78,0.308
12.16,119.90,0.308
12.17,120.02,0.308
12.18,120.13,0.308
12.19,120.25,0.308
12.20,120.37,0.308
12.22,120.48,0.308
12.23,120.60,0.309
12.24,120.72,0.309
12.25,120.83,0.309
12.26,120.95,0.309
12.27,121.07,0.309
12.28,121.18,0.309
12.30,121.30,0.309
12.31,121.42,0.309
12.32,121.53,0.309
12.33,121.65,0.309
12.34,121.77,0.309
12.35,121.89,0.309
12.37,122.00,0.309
12.38,122.12,0.309
12.39,122.23,0.309
12.40,122.35,0.309
12.41,122.47,0.309
12.43,122.58,0.309
12.44,122.70,0.309
12.45,122.82,0.309
12.46,122.93,0.309
12.47,123.05,0.309
12.48,123.17,0.309
12.50,123.28,0.309
12.51,123.40,0.309
12.52,123.52,0.309
12.53,123.63,0.309
12.54,123.75,0.309
12.55,123.87,0.309
12.57,123.99,0.309
12.58,124.10,0.309
12.59,124.22,0.309
12.60,124.34,0.309
12.61,124.45,0.309
12.62,124.57,0.309
12.63,124.69,0.310
12.65,124.80,0.310
12.66,124.92,0.310
12.67,125.03,0.310
12.68,125.15,0.310
12.69,125.27,0.310
12.70,125.39,0.310
12.72,125.50,0.310
12.73,125.62,0.310
12.74,125.74,0.310
12.75,125.85,0.310
12.76,125.97,0.310
12.78,126.09,0.310
12.79,126.20,0.310
12.80,126.32,0.310
12.81,126.43,0.310
12.82,126.55,0.310
12.83,126.67,0.310
12.85,126.79,0.310
12.86,126.90,0.310
12.87,127.02,0.310
12.88,127.13,0.310
12.89,127.25,0.310
12.90,127.37,0.310
12.92,127.49,0.310
12.93,127.60,0.310
12.94,127.72,0.310
12.95,127.84,0.311
12.96,127.95,0.311
12.97,128.07,0.311
12.98,128.19,0.311
13.00,128.30,0.311
13.01,128.42,0.311
13.02,128.54,0.311
13.03,128.65,0.311
13.04,128.77,0.311
13.05,128.89,0.311
13.07,129.01,0.311
13.08,129.12,0.311
13.09,129.24,0.311
13.10,129.36,0.311
13.11,129.47,0.311
13.13,129.59,0.311
13.14,129.71,0.311
13.15,129.82,0.311
13.16,129.94,0.311
13.17,130.06,0.311
13.18,130.17,0.311
13.20,130.29,0.311
13.21,130.41,0.311
13.22,130.52,0.312
13.23,130.64,0.312
13.24,130.76,0.312
13.25,130.87,0.312
13.27,130.99,0.312
13.28,131.11,0.312
13.29,131.22,0.312
13.30,131.34,0.312
13.31,131.46,0.312
13.32,131.57,0.312
13.33,131.69,0.312
13.35,131.81,0.312
13.36,131.92,0.312
13.37,132.04,0.312
13.38,132.16,0.312
13.39,132.28,0.312
13.40,132.39,0.312
13.42,132.51,0.312
13.43,132.63,0.312
13.44,132.74,0.312
13.45,132.86,0.312
13.46,132.98,0.312
13.48,133.09,0.312
13.49,133.21,0.313
13.50,133.33,0.313
13.51,133.44,0.313
13.52,133.56,0.313
13.53,133.68,0.313
13.55,133.79,0.313
13.56,133.91,0.313
13.57,134.03,0.313
13.58,134.15,0.313
13.59,134.26,0.313
13.60,134.38,0.313
13.62,134.50,0.313
13.63,134.61,0.313
13.64,134.73,0.313
13.65,134.85,0.313
13.66,134.96,0.313
13.67,135.08,0.313
13.68,135.20,0.313
13.70,135.31,0.313
13.71,135.43,0.313
13.72,135.55,0.313
13.73,135.66,0.313
13.74,135.78,0.313
13.75,135.90,0.313
13.77,136.01,0.313
13.78,136.13,0.313
13.79,136.25,0.313
13.80,136.36,0.313
13.81,136.48,0.313
13.83,136.60,0.313
13.84,136.72,0.313
13.85,136.83,0.313
13.86,136.95,0.313
13.87,137.06,0.313
13.88,137.18,0.313
13.90,137.30,0.313
13.91,137.42,0.313
13.92,137.53,0.313
13.93,137.65,0.313
13.94,137.77,0.313
13.95,137.88,0.313
13.97,138.00,0.313
13.98,138.12,0.313
13.99,138.23,0.313
14.00,138.35,0.313
14.01,138.47,0.313
14.02,138.58,0.313
14.03,138.70,0.313
14.05,138.82,0.313
14.06,138.93,0.313
14.07,139.05,0.313
14.08,139.17,0.313
14.09,139.28,0.313
14.10,139.40,0.313
14.12,139.52,0.313
14.13,139.63,0.313
14.14,139.75,0.313
14.15,139.87,0.313
14.16,139.98,0.313
14.18,140.10,0.313
14.19,140.22,0.313
14.20,140.33,0.313
14.21,140.45,0.314
14.22,140.57,0.314
14.23,140.68,0.314
14.25,140.80,0.314
14.26,140.92,0.314
14.27,141.03,0.314
14.28,141.15,0.314
14.29,141.27,0.314
14.30,141.38,0.314
14.32,141.50,0.314
14.33,141.62,0.314
14.34,141.73,0.314
14.35,141.85,0.314
14.36,141.97,0.314
14.37,142.08,0.314
14.38,142.20,0.314
14.40,142.32,0.314
14.41,142.43,0.314
14.42,142.55,0.314
14.43,142.67,0.314
14.44,142.79,0.314
14.45,142.90,0.314
14.47,143.02,0.314
14.48,143.14,0.314
14.49,143.25,0.314
14.50,143.37,0.314
14.51,143.49,0.314
14.53,143.60,0.314
14.54,143.72,0.314
14.55,143.84,0.314
14.56,143.95,0.314
14.57,144.07,0.314
14.58,144.19,0.315
14.60,144.30,0.315
14.61,144.42,0.315
14.62,144.54,0.315
14.63,144.65,0.315
14.64,144.77,0.315
14.65,144.89,0.315
14.67,145.00,0.315
14.68,145.12,0.315
14.69,145.24,0.315
14.70,145.36,0.315
14.71,145.47,0.315
14.72,145.59,0.315
14.73,145.71,0.315
14.75,145.82,0.315
14.76,145.94,0.315
14.77,146.06,0.315
14.78,146.17,0.315
14.79,146.29,0.315
14.80,146.41,0.315
14.82,146.52,0.315
14.83,146.64,0.315
14.84,146.76,0.315
14.85,146.87,0.315
14.86,146.99,0.315
14.88,147.11,0.315
14.89,147.22,0.315
14.90,147.34,0.315
14.91,147.46,0.315
14.92,147.57,0.315
14.93,147.69,0.315
14.95,147.81,0.315
14.96,147.92,0.315
14.97,148.04,0.315
14.98,148.16,0.315
14.99,148.27,0.315
15.00,148.39,0.315
15.02,148.51,0.316
15.03,148.62,0.316
15.04,148.74,0.316
15.05,148.86,0.316
15.06,148.97,0.316
15.07,149.09,0.316
15.08,149.21,0.316
15.10,149.33,0.316
15.11,149.44,0.316
15.12,149.56,0.316
15.13,149.68,0.316
15.14,149.79,0.316
15.15,149.91,0.316
15.17,150.03,0.316
15.18,150.14,0.316
15.19,150.26,0.316
15.20,150.38,0.316
15.21,150.49,0.316
15.23,150.61,0.316
15.24,150.73,0.316
15.25,150.84,0.316
15.26,150.96,0.316
15.27,151.08,0.316
15.28,151.19,0.316
15.30,151.31,0.316
15.31,151.43,0.316
15.32,151.54,0.316
15.33,151.66,0.316
15.34,151.78,0.316
15.35,151.89,0.316
15.37,152.01,0.316
15.38,152.13,0.317
15.39,152.25,0.317
15.40,152.36,0.317
15.41,152.48,0.317
15.42,152.60,0.317
15.43,152.71,0.317
15.45,152.83,0.317
15.46,152.95,0.317
15.47,153.06,0.317
15.48,153.18,0.317
15.49,153.30,0.317
15.50,153.41,0.317
15.52,153.53,0.317
15.53,153.65,0.317
15.54,153.76,0.317
15.55,153.88,0.317
15.56,154.00,0.317
15.58,154.11,0.317
15.59,154.23,0.317
15.60,154.35,0.317
15.61,154.46,0.317
15.62,154.58,0.317
15.63,154.70,0.317
15.65,154.81,0.317
15.66,154.93,0.317
15.67,155.05,0.317
15.68,155.16,0.317
15.69,155.28,0.317
15.70,155.40,0.317
15.72,155.51,0.317
15.73,155.63,0.317
15.74,155.75,0.317
15.75,155.86,0.317
15.76,155.98,0.317
15.77,156.10,0.317
15.78,156.21,0.317
15.80,156.33,0.317
15.81,156.45,0.317
15.82,156.56,0.317
15.83,156.68,0.317
15.84,156.80,0.317
15.85,156.91,0.317
15.87,157.03,0.317
15.88,157.15,0.317
15.89,157.26,0.317
15.90,157.38,0.317
15.91,157.50,0.317
15.93,157.61,0.317
15.94,157.73,0.317
15.95,157.85,
15.96,157.97,
15.97,158.08,
15.98,158.20,
16.00,158.32,
16.00,,

[step]
Ramp 10.00 °C/min to 0.00 °C
Time,Temperature,Heat Flow (Normalized)
min,°C,W/g
17.01,160.09,-0.009
17.02,160.09,-0.009
17.03,160.09,-0.009
17.04,160.09,-0.009
17.05,160.08,-0.010
17.07,160.07,-0.014
17.08,160.06,-0.023
17.09,160.04,-0.032
17.10,160.01,-0.044
17.11,159.97,-0.059
17.12,159.92,-0.078
17.13,159.87,-0.097
17.15,159.81,-0.118
17.16,159.74,-0.139
17.17,159.66,-0.158
17.18,159.59,-0.176
17.19,159.50,-0.193
17.21,159.42,-0.207
17.22,159.33,-0.221
17.23,159.24,-0.233
17.24,159.14,-0.243
17.25,159.05,-0.253
17.26,158.95,-0.261
17.28,158.85,-0.268
17.29,158.75,-0.276
17.30,158.65,-0.282
17.31,158.54,-0.287
17.32,158.44,-0.293
17.33,158.33,-0.297
17.34,158.22,-0.302
17.36,158.12,-0.306
17.37,158.01,-0.308
17.38,157.90,-0.311
17.39,157.79,-0.314
17.40,157.68,-0.317
17.42,157.57,-0.319
17.43,157.46,-0.321
17.44,157.34,-0.323
17.45,157.23,-0.324
17.46,157.12,-0.325
17.47,157.01,-0.327
17.48,156.89,-0.327
17.50,156.78,-0.329
17.51,156.67,-0.330
17.52,156.55,-0.331
17.53,156.44,-0.331
17.54,156.33,-0.332
17.56,156.21,-0.332
17.57,156.10,-0.333
17.58,155.98,-0.333
17.59,155.87,-0.334
17.60,155.75,-0.334
17.61,155.64,-0.334
17.63,155.52,-0.335
17.64,155.41,-0.335
17.65,155.30,-0.335
17.66,155.18,-0.335
17.67,155.07,-0.335
17.68,154.95,-0.335
17.69,154.83,-0.336
17.71,154.72,-0.336
17.72,154.60,-0.336
17.73,154.49,-0.337
17.74,154.37,-0.337
17.75,154.26,-0.337
17.77,154.14,-0.337
17.78,154.03,-0.337
17.79,153.91,-0.337
17.80,153.80,-0.338
17.81,153.68,-0.338
17.82,153.56,-0.338
17.83,153.45,-0.338
17.85,153.33,-0.338
17.86,153.22,-0.338
17.87,153.10,-0.338
17.88,152.99,-0.338
17.89,152.87,-0.338
17.91,152.76,-0.338
17.92,152.64,-0.339
17.93,152.52,-0.339
17.94,152.41,-0.339
17.95,152.29,-0.339
17.96,152.17,-0.339
17.98,152.06,-0.339
17.99,151.94,-0.339
18.00,151.83,-0.339
18.01,151.71,-0.339
18.02,151.60,-0.339
18.03,151.48,-0.339
18.04,151.36,-0.339
18.06,151.25,-0.339
18.07,151.13,-0.339
18.08,151.02,-0.339
18.09,150.90,-0.339
18.10,150.78,-0.339
18.12,150.67,-0.340
18.13,150.55,-0.340
18.14,150.43,-0.340
18.15,150.32,-0.340
18.16,150.20,-0.340
18.17,150.09,-0.340
18.18,149.97,-0.340
18.20,149.85,-0.340
18.21,149.74,-0.340
18.22,149.62,-0.340
18.23,149.51,-0.340
18.24,149.39,-0.340
18.26,149.27,-0.340
18.27,149.16,-0.340
18.28,149.04,-0.340
18.29,148.92,-0.340
18.30,148.81,-0.340
18.31,148.69,-0.340
18.33,148.58,-0.340
18.34,148.46,-0.340
18.35,148.34,-0.340
18.36,148.23,-0.340
18.37,148.11,-0.340
18.38,147.99,-0.340
18.39,147.88,-0.340
18.41,147.76,-0.340
18.42,147.65,-0.340
18.43,147.53,-0.340
18.44,147.41,-0.340
18.45,147.30,-0.340
18.47,147.18,-0.340
18.48,147.06,-0.340
18.49,146.95,-0.340
18.50,146.83,-0.340
18.51,146.72,-0.340
18.52,146.60,-0.340
18.53,146.48,-0.340
18.55,146.37,-0.340
18.56,146.25,-0.340
18.57,146.13,-0.340
18.58,146.02,-0.340
18.59,145.90,-0.340
18.61,145.78,-0.340
18.62,145.67,-0.340
18.63,145.55,-0.340
18.64,145.43,-0.340
18.65,145.32,-0.340
18.66,145.20,-0.340
18.68,145.08,-0.340
18.69,144.97,-0.340
18.70,144.85,-0.340
18.71,144.73,-0.340
18.72,144.62,-0.340
18.73,144.50,-0.340
18.74,144.39,-0.340
18.76,144.27,-0.339
18.77,144.15,-0.339
18.78,144.04,-0.339
18.79,143.92,-0.339
18.80,143.80,-0.339
18.82,143.69,-0.339
18.83,143.57,-0.339
18.84,143.45,-0.339
18.85,143.34,-0.339
18.86,143.22,-0.339
18.87,143.10,-0.339
18.88,142.99,-0.339
18.90,142.87,-0.339
18.91,142.76,-0.339
18.92,142.64,-0.339
18.93,142.52,-0.339
18.94,142.41,-0.339
18.96,142.29,-0.339
18.97,142.17,-0.339
18.98,142.06,-0.339
18.99,141.94,-0.339
19.00,141.82,-0.339
19.01,141.71,-0.339
19.03,141.59,-0.339
19.04,141.47,-0.339
19.05,141.36,-0.338
19.06,141.24,-0.338
19.07,141.13,-0.338
19.08,141.01,-0.338
19.09,140.89,-0.338
19.11,140.77,-0.338
19.12,140.66,-0.338
19.13,140.54,-0.338
19.14,140.42,-0.338
19.15,140.31,-0.338
19.17,140.19,-0.338
19.18,140.07,-0.338
19.19,139.96,-0.338
19.20,139.84,-0.338
19.21,139.73,-0.338
19.22,139.61,-0.338
19.23,139.49,-0.338
19.25,139.38,-0.338
19.26,139.26,-0.338
19.27,139.14,-0.338
19.28,139.02,-0.338
19.29,138.91,-0.338
19.31,138.79,-0.338
19.32,138.68,-0.338
19.33,138.56,-0.338
19.34,138.44,-0.338
19.35,138.33,-0.338
19.36,138.21,-0.338
19.38,138.09,-0.337
19.39,137.98,-0.337
19.40,137.86,-0.337
19.41,137.74,-0.337
19.42,137.63,-0.337
19.43,137.51,-0.337
19.44,137.39,-0.337
19.46,137.28,-0.337
19.47,137.16,-0.337
19.48,137.05,-0.337
19.49,136.93,-0.337
19.50,136.81,-0.337
19.52,136.70,-0.337
19.53,136.58,-0.337
19.54,136.46,-0.337
19.55,136.34,-0.337
19.56,136.23,-0.337
19.57,136.11,-0.336
19.58,136.00,-0.336
19.60,135.88,-0.336
19.61,135.76,-0.336
19.62,135.64,-0.336
19.63,135.53,-0.336
19.64,135.41,-0.336
19.66,135.30,-0.336
19.67,135.18,-0.336
19.68,135.06,-0.336
19.69,134.95,-0.336
19.70,134.83,-0.336
19.71,134.71,-0.336
19.73,134.60,-0.336
19.74,134.48,-0.336
19.75,134.37,-0.336
19.76,134.25,-0.336
19.77,134.13,-0.336
19.78,134.02,-0.336
19.79,133.90,-0.336
19.81,133.78,-0.335
19.82,133.67,-0.335
19.83,133.55,-0.335
19.84,133.43,-0.335
19.85,133.32,-0.335
19.87,133.20,-0.335
19.88,133.08,-0.335
19.89,132.97,-0.335
19.90,132.85,-0.335
19.91,132.73,-0.335
19.92,132.62,-0.335
19.93,132.50,-0.335
19.95,132.39,-0.335
19.96,132.27,-0.335
19.97,132.15,-0.335
19.98,132.04,-0.335
19.99,131.92,-0.335
20.01,131.80,-0.335
20.02,131.69,-0.335
20.03,131.57,-0.335
20.04,131.45,-0.335
20.05,131.34,-0.335
20.06,131.22,-0.335
20.08,131.10,-0.335
20.09,130.99,-0.335
20.10,130.87,-0.335
20.11,130.76,-0.334
20.12,130.64,-0.334
20.13,130.52,-0.334
20.14,130.41,-0.334
20.16,130.29,-0.334
20.17,130.17,-0.334
20.18,130.06,-0.334
20.19,129.94,-0.334
20.20,129.82,-0.334
20.22,129.71,-0.334
20.23,129.59,-0.334
20.24,129.47,-0.334
20.25,129.36,-0.334
20.26,129.24,-0.334
20.27,129.12,-0.334
20.28,129.01,-0.334
20.30,128.89,-0.334
20.31,128.77,-0.334
20.32,128.66,-0.334
20.33,128.54,-0.334
20.34,128.42,-0.334
20.36,128.31,-0.334
20.37,128.19,-0.333
20.38,128.07,-0.333
20.39,127.96,-0.333
20.40,127.84,-0.333
20.41,127.72,-0.333
20.43,127.61,-0.333
20.44,127.49,-0.333
20.45,127.38,-0.333
20.46,127.26,-0.333
20.47,127.14,-0.333
20.48,127.03,-0.333
20.49,126.91,-0.333
20.51,126.79,-0.333
20.52,126.68,-0.333
20.53,126.56,-0.333
20.54,126.44,-0.333
20.55,126.33,-0.333
20.57,126.21,-0.333
20.58,126.10,-0.333
20.59,125.98,-0.333
20.60,125.86,-0.333
20.61,125.74,-0.333
20.62,125.63,-0.333
20.63,125.51,-0.333
20.65,125.40,-0.333
20.66,125.28,-0.333
20.67,125.16,-0.333
20.68,125.04,-0.333
20.69,124.93,-0.332
20.71,124.81,-0.332
20.72,124.69,-0.332
20.73,124.58,-0.332
20.74,124.46,-0.332
20.75,124.34,-0.332
20.76,124.23,-0.332
20.78,124.11,-0.332
20.79,123.99,-0.332
20.80,123.88,-0.332
20.81,123.76,-0.332
20.82,123.65,-0.332
20.83,123.53,-0.332
20.84,123.41,-0.332
20.86,123.30,-0.332
20.87,123.18,-0.332
20.88,123.06,-0.332
20.89,122.95,-0.332
20.90,122.83,-0.332
20.92,122.71,-0.331
20.93,122.60,-0.331
20.94,122.48,-0.331
20.95,122.36,-0.331
20.96,122.25,-0.331
20.97,122.13,-0.331
20.98,122.02,-0.331
21.00,121.90,-0.331
21.01,121.78,-0.331
21.02,121.67,-0.331
21.03,121.55,-0.331
21.04,121.43,-0.331
21.06,121.31,-0.331
21.07,121.20,-0.331
21.08,121.08,-0.331
21.09,120.97,-0.331
21.10,120.85,-0.331
21.11,120.73,-0.331
21.13,120.62,-0.331
21.14,120.50,-0.331
21.15,120.38,-0.331
21.16,120.27,-0.330
21.17,120.15,-0.330
21.18,120.04,-0.330
21.19,119.92,-0.330
21.21,119.80,-0.330
21.22,119.69,-0.330
21.23,119.57,-0.330
21.24,119.45,-0.330
21.25,119.34,-0.330
21.27,119.22,-0.330
21.28,119.10,-0.330
21.29,118.99,-0.330
21.30,118.87,-0.330
21.31,118.76,-0.330
21.32,118.64,-0.330
21.33,118.52,-0.330
21.35,118.40,-0.330
21.36,118.29,-0.330
21.37,118.17,-0.330
21.38,118.05,-0.330
21.39,117.94,-0.330
21.41,117.82,-0.330
21.42,117.70,-0.330
21.43,117.59,-0.330
21.44,117.47,-0.330
21.45,117.36,-0.329
21.46,117.24,-0.329
21.48,117.12,-0.329
21.49,117.01,-0.329
21.50,116.89,-0.329
21.51,116.77,-0.329
21.52,116.66,-0.329
21.53,116.54,-0.329
21.54,116.42,-0.329
21.56,116.31,-0.329
21.57,116.19,-0.329
21.58,116.07,-0.329
21.59,115.96,-0.329
21.60,115.84,-0.329
21.62,115.72,-0.329
21.63,115.61,-0.329
21.64,115.49,-0.329
21.65,115.37,-0.329
21.66,115.26,-0.329
21.67,115.14,-0.329
21.68,115.02,-0.329
21.70,114.91,-0.329
21.71,114.79,-0.329
21.72,114.68,-0.329
21.73,114.56,-0.328
21.74,114.44,-0.328
21.76,114.33,-0.328
21.77,114.21,-0.328
21.78,114.09,-0.328
21.79,113.98,-0.328
21.80,113.86,-0.328
21.81,113.74,-0.328
21.83,113.63,-0.328
21.84,113.51,-0.328
21.85,113.39,-0.328
21.86,113.28,-0.328
21.87,113.16,-0.328
21.88,113.04,-0.328
21.89,112.93,-0.328
21.91,112.81,-0.328
21.92,112.69,-0.328
21.93,112.58,-0.328
21.94,112.46,-0.328
21.95,112.34,-0.328
21.97,112.23,-0.328
21.98,112.11,-0.328
21.99,111.99,-0.328
22.00,111.88,-0.328
22.01,111.76,-0.328
22.02,111.64,-0.327
22.03,111.53,-0.327
22.05,111.41,-0.327
22.06,111.29,-0.327
22.07,111.18,-0.327
22.08,111.06,-0.327
22.09,110.95,-0.327
22.11,110.83,-0.327
22.12,110.71,-0.327
22.13,110.60,-0.327
22.14,110.48,-0.327
22.15,110.36,-0.327
22.16,110.24,-0.327
22.18,110.13,-0.327
22.19,110.01,-0.327
22.20,109.90,-0.327
22.21,109.78,-0.327
22.22,109.66,-0.327
22.23,109.55,-0.327
22.24,109.43,-0.326
22.26,109.31,-0.326
22.27,109.20,-0.326
22.28,109.08,-0.326
22.29,108.96,-0.326
22.30,108.85,-0.326
22.32,108.73,-0.326
22.33,108.62,-0.326
22.34,108.50,-0.326
22.35,108.38,-0.326
22.36,108.27,-0.326
22.37,108.15,-0.326
22.38,108.03,-0.326
22.40,107.92,-0.326
22.41,107.80,-0.326
22.42,107.68,-0.326
22.43,107.57,-0.326
22.44,107.45,-0.326
22.46,107.33,-0.326
22.47,107.22,-0.326
22.48,107.10,-0.326
22.49,106.98,-0.326
22.50,106.87,-0.326
22.51,106.75,-0.326
22.53,106.63,-0.325
22.54,106.52,-0.325
22.55,106.40,-0.325
22.56,106.28,-0.325
22.57,106.17,-0.325
[...]
64.44,27.59,-0.223
64.45,27.47,-0.223
64.46,27.36,-0.223
64.47,27.24,-0.223
64.48,27.12,-0.222
64.49,27.01,-0.222
64.51,26.89,-0.222
64.52,26.77,-0.222
64.53,26.66,-0.221
64.54,26.54,-0.221
64.55,26.42,-0.221
64.56,26.31,-0.221
64.58,26.19,-0.221
64.59,26.07,-0.221
64.60,25.96,-0.220
64.61,25.84,-0.220
64.62,25.72,-0.220
64.64,25.61,-0.220
64.65,25.49,-0.220
64.66,25.37,-0.220
64.67,25.26,-0.219
64.68,25.14,-0.219
64.69,25.02,-0.219
64.71,24.91,-0.219
64.72,24.79,-0.219
64.73,24.67,-0.218
64.74,24.56,-0.218
64.75,24.44,-0.218
64.76,24.32,-0.218
64.78,24.21,-0.218
64.79,24.09,-0.218
64.80,23.97,-0.217
64.81,23.86,-0.217
64.82,23.74,-0.217
64.83,23.62,-0.217
64.84,23.51,-0.217
64.86,23.39,-0.216
64.87,23.27,-0.216
64.88,23.16,-0.216
64.89,23.04,-0.216
64.90,22.92,-0.215
64.91,22.81,-0.215
64.93,22.69,-0.215
64.94,22.57,-0.215
64.95,22.46,-0.215
64.96,22.34,-0.214
64.97,22.22,-0.214
64.99,22.11,-0.214
65.00,21.99,-0.214
65.01,21.87,-0.214
65.02,21.76,-0.214
65.03,21.64,-0.213
65.04,21.52,-0.213
65.06,21.41,-0.213
65.07,21.29,-0.213
65.08,21.17,-0.213
65.09,21.06,-0.213
65.10,20.94,-0.213
65.11,20.82,-0.212
65.13,20.71,-0.212
65.14,20.59,-0.212
65.15,20.47,-0.212
65.16,20.36,-0.212
65.17,20.24,-0.212
65.18,20.13,-0.211
65.19,20.01,-0.211
65.21,19.89,-0.211
65.22,19.78,-0.211
65.23,19.66,-0.211
65.24,19.54,-0.210
65.25,19.43,-0.210
65.26,19.31,-0.210
65.28,19.19,-0.210
65.29,19.08,-0.210
65.30,18.96,-0.209
65.31,18.84,-0.209
65.32,18.73,-0.209
65.34,18.61,-0.209
65.35,18.49,-0.209
65.36,18.38,-0.209
65.37,18.26,-0.209
65.38,18.14,-0.208
65.39,18.03,-0.208
65.41,17.91,-0.208
65.42,17.79,-0.208
65.43,17.68,-0.208
65.44,17.56,-0.207
65.45,17.45,-0.207
65.46,17.33,-0.207
65.48,17.21,-0.207
65.49,17.10,-0.207
65.50,16.98,-0.207
65.51,16.86,-0.207
65.52,16.75,-0.206
65.53,16.63,-0.206
65.54,16.51,-0.206
65.56,16.40,-0.206
65.57,16.28,-0.206
65.58,16.16,-0.206
65.59,16.05,-0.205
65.60,15.93,-0.205
65.61,15.81,-0.205
65.63,15.70,-0.205
65.64,15.58,-0.205
65.65,15.46,-0.205
65.66,15.35,-0.204
65.67,15.23,-0.204
65.69,15.11,-0.204
65.70,15.00,-0.204
65.71,14.88,-0.204
65.72,14.77,-0.204
65.73,14.65,-0.204
65.74,14.53,-0.203
65.76,14.41,-0.203
65.77,14.30,-0.203
65.78,14.18,-0.203
65.79,14.07,-0.203
65.80,13.95,-0.203
65.81,13.83,-0.203
65.83,13.72,-0.202
65.84,13.60,-0.202
65.85,13.48,-0.202
65.86,13.37,-0.202
65.87,13.25,-0.202
65.88,13.13,-0.202
65.89,13.02,-0.202
65.91,12.90,-0.201
65.92,12.78,-0.201
65.93,12.67,-0.201
65.94,12.55,-0.201
65.95,12.44,-0.201
65.96,12.32,-0.201
65.98,12.20,-0.201
65.99,12.09,-0.200
66.00,11.97,-0.200
66.01,11.85,-0.200
66.02,11.74,-0.200
66.04,11.62,-0.200
66.05,11.50,-0.200
66.06,11.39,-0.199
66.07,11.27,-0.199
66.08,11.15,-0.199
66.09,11.04,-0.199
66.11,10.92,-0.199
66.12,10.80,-0.199
66.13,10.69,-0.199
66.14,10.57,-0.199
66.15,10.45,-0.198
66.16,10.34,-0.198
66.18,10.22,-0.198
66.19,10.11,-0.198
66.20,9.99,-0.198
66.21,9.87,-0.198
66.22,9.76,-0.198
66.23,9.64,-0.197
66.24,9.52,-0.197
66.26,9.41,-0.197
66.27,9.29,-0.197
66.28,9.17,-0.197
66.29,9.06,-0.197
66.30,8.94,-0.197
66.31,8.82,-0.197
66.33,8.71,-0.196
66.34,8.59,-0.196
66.35,8.47,-0.196
66.36,8.36,-0.196
66.37,8.24,-0.196
66.39,8.12,-0.196
66.40,8.01,-0.196
66.41,7.89,-0.196
66.42,7.78,-0.195
66.43,7.66,-0.195
66.44,7.54,-0.195
66.46,7.43,-0.195
66.47,7.31,-0.195
66.48,7.19,-0.195
66.49,7.07,-0.194
66.50,6.96,-0.194
66.51,6.84,-0.194
66.53,6.72,-0.194
66.54,6.61,-0.194
66.55,6.49,-0.194
66.56,6.37,-0.194
66.57,6.26,-0.194
66.58,6.14,-0.193
66.59,6.03,-0.193
66.61,5.91,-0.193
66.62,5.79,-0.193
66.63,5.68,-0.193
66.64,5.56,-0.193
66.65,5.44,-0.193
66.66,5.33,-0.193
66.68,5.21,-0.193
66.69,5.09,-0.192
66.70,4.98,-0.192
66.71,4.86,-0.192
66.72,4.74,-0.192
66.74,4.63,-0.192
66.75,4.51,-0.192
66.76,4.39,-0.192
66.77,4.28,-0.192
66.78,4.16,-0.191
66.79,4.04,-0.191
66.81,3.93,-0.244
66.82,3.83,-0.427
66.83,3.73,-0.278
66.84,3.61,-0.234
66.85,3.49,-0.219
66.86,3.37,-0.214
66.88,3.25,-0.211
66.89,3.14,-0.208
66.90,3.02,-0.207
66.91,2.90,-0.206
66.92,2.78,-0.206
66.93,2.66,-0.205
66.94,2.54,-0.205
66.96,2.43,
66.97,2.31,
66.98,2.19,
66.99,2.07,
67.00,,
67.01,,

[step]
Ramp 10.00 °C/min to 30.00 °C
Time,Temperature,Heat Flow (Normalized)
min,°C,W/g
68.01,0.13,-0.012
68.01,0.13,-0.012
68.01,0.13,-0.012
68.02,0.13,-0.012
68.02,0.13,-0.012
68.03,0.13,-0.012
68.03,0.13,-0.012
68.03,0.13,-0.012
68.04,0.13,-0.012
68.04,0.13,-0.012
68.04,0.13,-0.012
68.04,0.13,-0.012
68.05,0.14,-0.012
68.05,0.14,-0.012
68.06,0.14,-0.012
68.06,0.14,-0.012
68.06,0.14,-0.012
68.06,0.14,-0.012
68.07,0.15,-0.012
68.07,0.15,-0.012
68.08,0.16,-0.011
68.08,0.16,-0.011
68.08,0.16,-0.011
68.09,0.17,-0.011
68.09,0.18,-0.010
68.09,0.18,-0.009
68.09,0.19,-0.008
68.10,0.20,-0.007
68.10,0.21,-0.005
68.11,0.22,-0.003
68.11,0.23,-0.001
68.11,0.24,0.000
68.11,0.25,0.002
68.12,0.26,0.004
68.12,0.28,0.006
68.13,0.29,0.009
68.13,0.31,0.011
68.13,0.32,0.013
68.14,0.33,0.015
68.14,0.35,0.018
68.14,0.37,0.021
68.14,0.39,0.024
68.15,0.40,0.027
68.15,0.42,0.030
68.16,0.44,0.032
68.16,0.46,0.035
68.16,0.48,0.037
68.16,0.50,0.041
68.17,0.52,0.044
68.17,0.54,0.048
68.18,0.56,0.050
68.18,0.59,0.053
68.18,0.61,0.056
68.19,0.63,0.059
68.19,0.65,0.062
68.19,0.67,0.065
68.19,0.70,0.067
68.20,0.72,0.070
68.20,0.74,0.072
68.21,0.77,0.075
68.21,0.79,0.077
68.21,0.82,0.079
68.21,0.84,0.082
68.22,0.87,0.085
68.22,0.89,0.087
68.23,0.92,0.089
68.23,0.94,0.091
68.23,0.97,0.093
68.24,0.99,0.095
68.24,1.02,0.096
68.24,1.05,0.098
68.24,1.07,0.100
68.25,1.10,0.102
68.25,1.13,0.104
68.26,1.15,0.106
68.26,1.18,0.107
68.26,1.21,0.109
68.26,1.23,0.111
68.27,1.26,0.113
68.27,1.29,0.114
68.28,1.32,0.115
68.28,1.34,0.117
68.28,1.37,0.118
68.29,1.40,0.120
68.29,1.43,0.121
68.29,1.46,0.123
68.30,1.49,0.124
68.30,1.52,0.125
68.30,1.54,0.126
68.30,1.57,0.127
68.31,1.60,0.129
68.31,1.63,0.130
68.31,1.66,0.132
68.32,1.69,0.133
68.32,1.72,0.134
68.33,1.75,0.134
68.33,1.78,0.135
68.33,1.81,0.136
68.34,1.84,0.137
68.34,1.87,0.138
68.34,1.90,0.139
68.35,1.93,0.140
68.35,1.96,0.141
68.35,1.99,0.142
68.35,2.02,0.143
68.36,2.05,0.144
68.36,2.08,0.145
68.36,2.11,0.146
68.37,2.14,0.146
68.37,2.17,0.147
68.38,2.20,0.148
68.38,2.23,0.148
68.38,2.26,0.149
68.39,2.29,0.150
68.39,2.33,0.151
68.39,2.36,0.152
68.40,2.39,0.152
68.40,2.42,0.153
68.40,2.45,0.152
68.40,2.48,0.153
68.41,2.51,0.154
68.41,2.54,0.155
68.41,2.58,0.156
68.42,2.61,0.156
68.42,2.64,0.156
68.43,2.67,0.156
68.43,2.70,0.157
68.43,2.73,0.158
68.44,2.76,0.158
68.44,2.79,0.159
68.44,2.83,0.159
68.45,2.86,0.160
68.45,2.89,0.160
68.45,2.92,0.160
68.45,2.95,0.160
68.46,2.99,0.161
68.46,3.02,0.161
68.46,3.05,0.162
68.47,3.08,0.163
68.47,3.11,0.163
68.48,3.15,0.163
68.48,3.18,0.163
68.48,3.21,0.163
68.49,3.24,0.164
68.49,3.27,0.164
68.49,3.30,0.164
68.50,3.34,0.165
68.50,3.37,0.165
68.50,3.40,0.165
68.50,3.43,0.165
68.51,3.46,0.165
68.51,3.50,0.166
68.51,3.53,0.166
68.52,3.56,0.166
68.52,3.59,0.166
68.53,3.63,0.167
68.53,3.66,0.167
68.53,3.69,0.167
68.54,3.72,0.168
68.54,3.75,0.168
68.54,3.79,0.168
68.55,3.82,0.168
68.55,3.85,0.169
68.55,3.88,0.169
68.55,3.92,0.169
68.56,3.95,0.169
68.56,3.98,0.169
68.56,4.01,0.169
68.57,4.05,0.169
68.57,4.08,0.169
68.58,4.11,0.170
68.58,4.14,0.170
68.58,4.18,0.170
68.59,4.21,0.170
68.59,4.24,0.170
68.59,4.27,0.170
68.60,4.31,0.170
68.60,4.34,0.171
68.60,4.37,0.171
68.60,4.40,0.171
68.61,4.44,0.171
68.61,4.47,0.171
68.61,4.50,0.171
68.62,4.53,0.171
68.62,4.57,0.171
68.63,4.60,0.171
68.63,4.63,0.172
68.63,4.67,0.172
68.64,4.70,0.172
68.64,4.73,0.172
68.64,4.77,0.172
68.65,4.80,0.172
68.65,4.83,0.172
68.65,4.86,0.172
68.65,4.89,0.173
68.66,4.93,0.173
68.66,4.96,0.173
68.66,4.99,0.173
68.67,5.03,0.173
68.67,5.06,0.173
68.68,5.09,0.173
68.68,5.12,0.173
68.68,5.16,0.173
68.69,5.19,0.173
68.69,5.22,0.173
68.69,5.26,0.174
68.70,5.29,0.174
68.70,5.32,0.174
68.70,5.35,0.174
68.70,5.39,0.174
68.71,5.42,0.174
68.71,5.45,0.174
68.71,5.49,0.174
68.72,5.52,0.174
68.72,5.55,0.174
68.73,5.58,0.174
68.73,5.62,0.175
68.73,5.65,0.175
68.74,5.68,0.175
68.74,5.71,0.175
68.74,5.75,0.175
68.75,5.78,0.175
68.75,5.81,0.175
68.75,5.85,0.175
68.75,5.88,0.175
68.76,5.91,0.175
68.76,5.95,0.175
68.76,5.98,0.175
68.77,6.01,0.175
68.77,6.05,0.175
68.78,6.08,0.175
68.78,6.11,0.175
68.78,6.14,0.175
68.79,6.18,0.175
68.79,6.21,0.175
68.79,6.24,0.175
68.80,6.27,0.175
68.80,6.31,0.175
68.80,6.34,0.175
68.80,6.38,0.176
68.81,6.41,0.176
68.81,6.44,0.176
68.81,6.47,0.176
68.82,6.51,0.176
68.82,6.54,0.176
68.83,6.57,0.176
68.83,6.61,0.176
68.83,6.64,0.176
68.84,6.67,0.176
68.84,6.70,0.176
68.84,6.74,0.176
68.85,6.77,0.176
68.85,6.80,0.176
68.85,6.84,0.176
68.85,6.87,0.176
68.86,6.90,0.176
68.86,6.94,0.176
68.86,6.97,0.176
68.87,7.00,0.176
68.87,7.03,0.176
68.88,7.07,0.176
68.88,7.10,0.176
68.88,7.13,0.176
68.89,7.17,0.176
68.89,7.20,0.176
68.89,7.23,0.176
68.90,7.27,0.176
68.90,7.30,0.177
68.90,7.33,0.177
68.90,7.37,0.177
68.91,7.40,0.177
68.91,7.43,0.177
68.91,7.46,0.177
68.92,7.50,0.177
68.92,7.53,0.177
68.93,7.56,0.177
68.93,7.60,0.177
68.93,7.63,0.177
68.94,7.66,0.177
68.94,7.70,0.177
68.94,7.73,0.177
68.95,7.76,0.177
68.95,7.80,0.177
68.95,7.83,0.177
68.95,7.86,0.177
68.96,7.89,0.177
68.96,7.93,0.177
68.96,7.96,0.177
68.97,8.00,0.177
68.97,8.03,0.177
68.98,8.06,0.177
68.98,8.09,0.177
68.98,8.13,0.177
68.99,8.16,0.177
68.99,8.19,0.177
68.99,8.23,0.178
69.00,8.26,0.178
69.00,8.29,0.178
69.00,8.33,0.178
69.00,8.36,0.178
69.01,8.39,0.178
69.01,8.43,0.178
69.01,8.46,0.178
69.02,8.49,0.178
69.02,8.53,0.178
69.03,8.56,0.178
69.03,8.59,0.178
69.03,8.62,0.178
69.04,8.66,0.178
69.04,8.69,0.178
69.04,8.72,0.178
69.05,8.76,0.178
69.05,8.79,0.178
69.05,8.82,0.178
69.05,8.86,0.178
69.06,8.89,0.178
69.06,8.92,0.178
69.06,8.96,0.178
69.07,8.99,0.178
69.07,9.02,0.178
69.08,9.06,0.178
69.08,9.09,0.178
69.08,9.12,0.178
69.09,9.15,0.178
69.09,9.19,0.178
69.09,9.22,0.178
69.10,9.26,0.178
69.10,9.29,0.178
69.10,9.32,0.179
69.10,9.35,0.179
69.11,9.39,0.179
69.11,9.42,0.179
69.11,9.45,0.179
69.12,9.49,0.179
69.12,9.52,0.179
69.13,9.55,0.179
69.13,9.59,0.179
69.13,9.62,0.179
69.14,9.65,0.179
69.14,9.69,0.179
69.14,9.72,0.179
69.15,9.75,0.179
69.15,9.79,0.179
69.15,9.82,0.179
69.15,9.85,0.179
69.16,9.89,0.179
69.16,9.92,0.179
69.16,9.95,0.179
69.17,9.98,0.179
69.17,10.02,0.179
69.18,10.05,0.179
69.18,10.08,0.179
69.18,10.12,0.179
69.19,10.15,0.179
69.19,10.19,0.179
69.19,10.22,0.179
69.20,10.25,0.179
69.20,10.28,0.179
69.20,10.32,0.180
69.20,10.35,0.180
69.21,10.38,0.180
69.21,10.42,0.180
69.21,10.45,0.180
69.22,10.48,0.180
69.22,10.52,0.180
69.23,10.55,0.180
69.23,10.58,0.180
69.23,10.62,0.180
69.24,10.65,0.180
69.24,10.68,0.180
69.24,10.72,0.180
69.25,10.75,0.180
69.25,10.78,0.180
69.25,10.82,0.180
69.25,10.85,0.180
69.26,10.88,0.180
69.26,10.92,0.180
69.26,10.95,0.180
69.27,10.98,0.180
69.27,11.01,0.180
69.28,11.05,0.180
69.28,11.08,0.180
69.28,11.11,0.180
69.29,11.15,0.180
69.29,11.18,0.180
69.29,11.21,0.180
69.30,11.25,0.180
69.30,11.28,0.180
69.30,11.31,0.180
69.30,11.35,0.180
69.31,11.38,0.180
69.31,11.41,0.180
69.31,11.45,0.180
69.32,11.48,0.180
69.32,11.51,0.180
69.33,11.55,0.180
69.33,11.58,0.180
69.33,11.61,0.180
69.34,11.65,0.181
69.34,11.68,0.181
69.34,11.71,0.181
69.35,11.75,0.181
69.35,11.78,0.181
69.35,11.81,0.181
69.35,11.85,0.181
69.36,11.88,0.181
69.36,11.91,0.181
69.36,11.95,0.181
69.37,11.98,0.181
69.37,12.01,0.181
69.38,12.05,0.181
69.38,12.08,0.181
69.38,12.11,0.181
69.39,12.15,0.181
69.39,12.18,0.181
69.39,12.21,0.181
69.40,12.25,0.181
69.40,12.28,0.181
69.40,12.31,0.181
69.40,12.35,0.181
69.41,12.38,0.181
69.41,12.41,0.181
69.41,12.45,0.181
69.42,12.48,0.181
69.42,12.51,0.181
69.43,12.55,0.181
69.43,12.58,0.181
69.43,12.61,0.181
69.44,12.65,0.181
69.44,12.68,0.181
69.44,12.71,0.181
69.45,12.75,0.181
69.45,12.78,0.181
69.45,12.81,0.181
69.45,12.85,0.181
69.46,12.88,0.181
69.46,12.91,0.181
69.46,12.95,0.181
69.47,12.98,0.181
69.47,13.01,0.181
69.48,13.05,0.181
69.48,13.08,0.182
69.48,13.11,0.182
69.49,13.14,0.182
69.49,13.18,0.182
69.49,13.21,0.182
69.50,13.25,0.182
69.50,13.28,0.182
69.50,13.31,0.182
69.50,13.35,0.182
69.51,13.38,0.182
69.51,13.41,0.182
69.51,13.44,0.182
69.52,13.48,0.182
69.52,13.51,0.182
69.53,13.54,0.182
69.53,13.58,0.182
69.53,13.61,0.182
69.54,13.65,0.182
69.54,13.68,0.182
69.54,13.71,0.182
69.55,13.75,0.182
69.55,13.78,0.182
69.55,13.81,0.182
69.55,13.85,0.182
69.56,13.88,0.182
69.56,13.91,0.182
69.56,13.94,0.182
69.57,13.98,0.182
69.57,14.01,0.182
69.58,14.05,0.182
69.58,14.08,0.182
69.58,14.11,0.182
69.59,14.15,0.182
69.59,14.18,0.182
69.59,14.21,0.182
69.60,14.24,0.182
69.60,14.28,0.182
69.60,14.31,0.182
69.60,14.34,0.182
69.61,14.38,0.182
69.61,14.41,0.182
69.61,14.45,0.182
69.62,14.48,0.182
69.62,14.51,0.182
69.63,14.54,0.183
69.63,14.58,0.183
69.63,14.61,0.183
69.64,14.64,0.183
69.64,14.68,0.183
69.64,14.71,0.183
69.65,14.75,0.183
69.65,14.78,0.183
69.65,14.81,0.183
69.65,14.84,0.183
69.66,14.88,0.183
69.66,14.91,0.183
69.66,14.94,0.183
69.67,14.98,0.183
69.67,15.01,0.183
69.68,15.05,0.183
69.68,15.08,0.183
69.68,15.11,0.183
69.69,15.15,0.183
69.69,15.18,0.183
69.69,15.21,0.183
69.70,15.25,0.183
69.70,15.28,0.183
69.70,15.31,0.183
69.70,15.34,0.183
69.71,15.38,0.183
69.71,15.41,0.183
69.71,15.45,0.183
69.72,15.48,0.183
69.72,15.51,0.183
69.73,15.54,0.183
69.73,15.58,0.183
69.73,15.61,0.183
69.74,15.65,0.183
69.74,15.68,0.183
69.74,15.71,0.183
69.75,15.74,0.183
69.75,15.78,0.183
69.75,15.81,0.183
69.75,15.84,0.183
69.76,15.88,0.183
69.76,15.91,0.183
69.76,15.95,0.183
69.77,15.98,0.183
69.77,16.01,0.183
69.78,16.04,0.183
69.78,16.08,0.183
69.78,16.11,0.183
69.79,16.14,0.183
69.79,16.18,0.184
69.79,16.21,0.184
69.80,16.24,0.184
69.80,16.28,0.184
69.80,16.31,0.184
69.80,16.34,0.184
69.81,16.38,0.184
69.81,16.41,0.184
69.81,16.45,0.184
69.82,16.48,0.184
69.82,16.51,0.184
69.83,16.54,0.184
69.83,16.58,0.184
69.83,16.61,0.184
69.84,16.64,0.184
69.84,16.68,0.184
69.84,16.71,0.184
69.85,16.74,0.184
69.85,16.78,0.184
69.85,16.81,0.184
69.85,16.84,0.184
69.86,16.88,0.184
69.86,16.91,0.184
69.86,16.94,0.184
69.87,16.98,0.184
69.87,17.01,0.184
69.88,17.05,0.184
69.88,17.08,0.184
69.88,17.11,0.184
69.89,17.14,0.184
69.89,17.18,0.184
69.89,17.21,0.184
69.90,17.24,0.184
69.90,17.28,0.184
69.90,17.31,0.184
69.90,17.34,0.184
69.91,17.38,0.184
69.91,17.41,0.184
69.91,17.45,0.184
69.92,17.48,0.184
69.92,17.51,0.184
69.93,17.55,0.184
69.93,17.58,0.184
69.93,17.61,0.184
69.94,17.64,0.184
69.94,17.68,0.184
69.94,17.71,0.184
69.95,17.74,0.184
69.95,17.78,0.184
69.95,17.81,0.184
69.95,17.84,0.184
69.96,17.88,0.184
69.96,17.91,0.184
69.96,17.94,0.184
69.97,17.98,0.184
69.97,18.01,0.184
69.98,18.05,0.184
69.98,18.08,0.184
69.98,18.11,0.185
69.99,18.14,0.185
69.99,18.18,0.185
69.99,18.21,0.185
70.00,18.25,0.185
70.00,18.28,0.185
70.00,18.31,0.185
70.00,18.35,0.185
70.01,18.38,0.185
70.01,18.41,0.185
70.01,18.44,0.185
70.02,18.48,0.185
70.02,18.51,0.185
70.03,18.55,0.185
70.03,18.58,0.185
70.03,18.61,0.185
70.04,18.64,0.185
70.04,18.68,0.185
70.04,18.71,0.185
70.05,18.74,0.185
70.05,18.78,0.185
70.05,18.81,0.185
70.05,18.84,0.185
70.06,18.88,0.185
70.06,18.91,0.185
70.06,18.94,0.185
70.07,18.98,0.185
70.07,19.01,0.185
70.08,19.04,0.185
70.08,19.08,0.185
70.08,19.11,0.185
70.09,19.14,0.185
70.09,19.18,0.185
70.09,19.21,0.185
70.10,19.24,0.185
70.10,19.28,0.185
70.10,19.31,0.185
70.10,19.34,0.185
70.11,19.38,0.185
70.11,19.41,0.185
70.11,19.44,0.185
70.12,19.48,0.185
70.12,19.51,0.185
70.13,19.55,0.185
70.13,19.58,0.185
70.13,19.61,0.185
70.14,19.65,0.185
70.14,19.68,0.185
70.14,19.71,0.185
70.15,19.75,0.185
70.15,19.78,0.185
70.15,19.81,0.185
70.15,19.85,0.185
70.16,19.88,0.185
70.16,19.91,0.185
70.16,19.94,0.185
70.17,19.98,0.186
70.17,20.01,0.186
70.18,20.05,0.186
70.18,20.08,0.186
70.18,20.11,0.186
70.19,20.15,0.186
70.19,20.18,0.186
70.19,20.21,0.186
70.20,20.25,0.186
70.20,20.28,0.186
70.20,20.31,0.186
70.20,20.35,0.186
70.21,20.38,0.186
70.21,20.41,0.186
70.21,20.45,0.186
70.22,20.48,0.186
70.22,20.51,0.186
70.23,20.55,0.186
70.23,20.58,0.186
70.23,20.61,0.186
70.24,20.65,0.186
70.24,20.68,0.186
70.24,20.71,0.186
70.25,20.75,0.186
70.25,20.78,0.186
70.25,20.81,0.186
70.25,20.85,0.186
70.26,20.88,0.186
70.26,20.91,0.186
70.26,20.95,0.186
70.27,20.98,0.186
70.27,21.01,0.186
70.28,21.05,0.186
70.28,21.08,0.186
70.28,21.11,0.186
70.29,21.15,0.186
70.29,21.18,0.186
70.29,21.21,0.186
70.30,21.25,0.186
70.30,21.28,0.186
70.30,21.31,0.186
70.30,21.35,0.186
70.31,21.38,0.186
70.31,21.41,0.186
70.31,21.45,0.186
70.32,21.48,0.186
70.32,21.51,0.186
70.33,21.55,0.186
70.33,21.58,0.186
70.33,21.61,0.186
70.34,21.65,0.186
70.34,21.68,0.186
70.34,21.71,0.187
70.35,21.75,0.187
70.35,21.78,0.187
70.35,21.81,0.187
70.35,21.85,0.187
70.36,21.88,0.187
70.36,21.91,0.187
70.36,21.95,0.187
70.37,21.98,0.187
70.37,22.01,0.187
70.38,22.05,0.187
70.38,22.08,0.187
70.38,22.11,0.187
70.39,22.15,0.187
70.39,22.18,0.187
70.39,22.21,0.187
70.40,22.25,0.187
70.40,22.28,0.187
70.40,22.32,0.187
70.40,22.35,0.187
70.41,22.38,0.187
70.41,22.41,0.187
70.41,22.45,0.187
70.42,22.48,0.187
70.42,22.51,0.187
70.43,22.55,0.187
70.43,22.58,0.187
70.43,22.61,0.187
70.44,22.65,0.187
70.44,22.68,0.187
70.44,22.71,0.187
70.45,22.75,0.187
70.45,22.78,0.187
70.45,22.81,0.187
70.45,22.85,0.187
70.46,22.88,0.187
70.46,22.91,0.187
70.46,22.95,0.187
70.47,22.98,0.187
70.47,23.01,0.187
70.48,23.05,0.187
70.48,23.08,0.187
70.48,23.11,0.187
70.49,23.15,0.187
70.49,23.18,0.187
70.49,23.21,0.187
70.50,23.25,0.187
70.50,23.28,0.187
70.50,23.32,0.187
70.50,23.35,0.187
70.51,23.38,0.187
70.51,23.41,0.187
70.51,23.45,0.187
70.52,23.48,0.187
70.52,23.52,0.187
70.53,23.55,0.188
70.53,23.58,0.188
70.53,23.62,0.188
70.54,23.65,0.188
70.54,23.68,0.188
70.54,23.72,0.188
70.55,23.75,0.188
70.55,23.78,0.188
70.55,23.82,0.188
70.55,23.85,0.188
70.56,23.88,0.188
70.56,23.92,0.188
70.56,23.95,0.188
70.57,23.98,0.188
70.57,24.02,0.188
70.58,24.05,0.188
70.58,24.08,0.188
70.58,24.12,0.188
70.59,24.15,0.188
70.59,24.18,0.188
70.59,24.22,0.188
70.60,24.25,0.188
70.60,24.28,0.188
70.60,24.32,0.188
70.60,24.35,0.188
70.61,24.38,0.188
70.61,24.42,0.188
70.61,24.45,0.188
70.62,24.48,0.188
70.62,24.51,0.188
70.63,24.55,0.188
70.63,24.58,0.188
70.63,24.62,0.188
70.64,24.65,0.188
70.64,24.68,0.188
70.64,24.71,0.188
70.65,24.75,0.188
70.65,24.78,0.188
70.65,24.82,0.188
70.65,24.85,0.188
70.66,24.88,0.188
70.66,24.92,0.188
70.66,24.95,0.188
70.67,24.98,0.188
70.67,25.02,0.188
70.68,25.05,0.188
70.68,25.08,0.188
70.68,25.12,0.188
70.69,25.15,0.188
70.69,25.18,0.188
70.69,25.22,0.189
70.70,25.25,0.189
70.70,25.28,0.189
70.70,25.32,0.189
70.70,25.35,0.189
70.71,25.38,0.189
70.71,25.42,0.189
70.71,25.45,0.189
70.72,25.48,0.189
70.72,25.52,0.189
70.73,25.55,0.189
70.73,25.58,0.189
70.73,25.62,0.189
70.74,25.65,0.189
70.74,25.68,0.189
70.74,25.72,0.189
70.75,25.75,0.189
70.75,25.78,0.189
70.75,25.82,0.189
70.75,25.85,0.189
70.76,25.88,0.189
70.76,25.92,0.189
70.76,25.95,0.189
70.77,25.98,0.189
70.77,26.02,0.189
70.78,26.05,0.189
70.78,26.08,0.189
70.78,26.12,0.189
70.79,26.15,0.189
70.79,26.18,0.189
70.79,26.22,0.189
70.80,26.25,0.189
70.80,26.28,0.189
70.80,26.32,0.189
70.80,26.35,0.189
70.81,26.38,0.189
70.81,26.42,0.189
70.81,26.45,0.189
70.82,26.48,0.189
70.82,26.52,0.189
70.83,26.55,0.189
70.83,26.58,0.189
70.83,26.62,0.189
70.84,26.65,0.189
70.84,26.68,0.189
70.84,26.72,0.189
70.85,26.75,0.189
70.85,26.78,0.189
70.85,26.82,0.189
70.85,26.85,0.189
70.86,26.88,0.189
70.86,26.92,0.189
70.86,26.95,0.189
70.87,26.98,0.189
70.87,27.02,0.190
70.88,27.05,0.190
70.88,27.08,0.190
70.88,27.12,0.190
70.89,27.15,0.190
70.89,27.18,0.190
70.89,27.22,0.190
70.90,27.25,0.190
70.90,27.28,0.190
70.90,27.32,0.190
70.90,27.35,0.190
70.91,27.38,0.190
70.91,27.42,0.190
70.91,27.45,0.190
70.92,27.48,0.190
70.92,27.52,0.190
70.93,27.55,0.190
70.93,27.58,0.190
70.93,27.62,0.190
70.94,27.65,0.190
70.94,27.68,0.190
70.94,27.72,0.190
70.95,27.75,0.190
70.95,27.79,0.190
70.95,27.82,
70.95,27.85,
70.96,27.88,
70.96,27.92,
70.96,27.95,
70.97,27.98,
70.97,28.02,
70.98,28.05,
70.98,28.09,
70.98,28.12,
70.99,28.15,
70.99,28.19,
70.99,28.22,
71.00,28.25,
71.00,28.29,
71.00,,
71.00,,
71.01,,