File: DSC/2025_02_10_Indium_Std_DSC.txt
Filename	2025_02_10_Indium_Std_DSC
Instrument name	DSC2A-00468 (192.168.1.100)
Operator	JLY
rundate	2/10/2025
Sample name	2025_02_10_Indium_Std_DSC
proceduresegments	Data Off ; Equilibrate 30.00 °C; Data On ; Ramp 5.00 °C/min to 200.00 °C
[File Parameters]
Run date	2/10/2025 5:28:57 PM
Trios version	5.1.1.46572
Original File Name
Current File Name	D:\DSC2500\CHM343\2025_02_10_Indium_Std_DSC.tri
[Procedure]
Procedure Name	Indium Std Melting
Sample Name	2025_02_10_Indium_Std_DSC
Sample Mass	2.26 mg
Reference Sample Mass	0 mg
Pan Mass	54.24 mg
Pan Number	25
Reference Pan Mass	54 mg
Reference Pan Number	19
Pan Type	Tzero Aluminum Hermetic
Comments	Al Hermetic Sealed Pan, with ref Al pan
Project Name
Operator	JLY
Test	Custom
Unload Max Temperature	30
Unload Min Temperature	30
Load Max Temperature	30
Load Min Temperature	30
Stop on Gas Flow Error	Yes
[Signal List]
Signal #1	Time (min)
Signal #2	Temperature (°C)
Signal #3	Heat Flow (mW)
Signal #4	Delta T (µV)
Signal #5	Delta Tzero (µV)
Signal #6	Tzero Temperature (°C)
Signal #7	Cell Purge (mL/min)
Signal #8	Heater Temp (°C)
Signal #9	Power Delivered (W)
Signal #10	Reference Junction Temperature (°C)
Signal #11	Flange Temperature (°C)
Signal #12	Heat Flow Phase (rad)
Signal #13	Total Heat Capacity (J/°C)
Signal #14	Heat Capacity (J/°C)
[Configuration]
Company Name	ASU
Instrument Name	DSC2A-00468
Instrument Type	DSC2500
Serial Number	DSC2A-00468
IP	192.168.1.100
Location of Instrument	MRRC
DisplayType	Unknown
Sample Interval 	0.1 s/pt
Selected Heat Flow	T4P
Exotherm Direction	Down
Cell Serial	DRC2-00792
Lid Type	Standard
Cooler	RCS 90
Leave Cooler on at End of Sequence	On
Gas 2	Nitrogen
Gas Selected	Channel 1
Flow Rate	50 mL/min
Secondary Purge	On
Licensed Heat Flow	Heat Flow T4P
Modulation Licensed	Yes
[Versions]
Common IDD Version	1
Cortex Version	VER 2.10.2.31
Driver	5.0.0.6
GDM Version	1.0.3.3
TouchscreenVersion	1.0.0.16145
FEP Version	1.2.1.21
FEP Bootloader	2.0.0.5
AutoSampler Version	2.1.1.26
Auto Sampler Bootloader	2.0.0.5
FCM Version	1.1.0.3
FCM Bootloader	2.0.0.5
[Experiment Logs]
Experiment Log Entry # 1	Data On set to 0
Experiment Log Entry # 3	Equilibrate Segment 30 (C) Started
Experiment Log Entry # 5	Air Cool is off.
Experiment Log Entry # 7	Data On set to 1
Experiment Log Entry # 9	Ramp Segment 5 C/min to 200 Started
[Method Log]
Method Log Entry # 1	Data Off
Method Log Entry # 2	Equilibrate 30 °C
Method Log Entry # 3	Data On
Method Log Entry # 4	(Ramp 17707) Ramp 5 °C/minute to 200 °C
Cell Serial	DRC2-00792
[T1 Calibration]
Slope	-0.008529666
Offset	9.636258
Initial Temperature	98.23
GUID	f8bfdadc-4977-4fdf-ba6d-0ba9134940c3
[TZero Calibration]
Date Applied	11/29/2022 4:06:13 PM
Description	From -89.059 °C to 396.009 °C at 20.000°C/min
Gas Type	Nitrogen
Pan Type	None
Source Files 1	C:\Users\yargerlab\Desktop\DSC Data\General\TZero_calibration_11_29_22_2nd(2).tri
Source Files 2	C:\Users\yargerlab\Desktop\DSC Data\General\TZero_calibration_11_29_22_2nd(3).tri
Delta T Offset	13.05235
Delta T Slope	-0.007271007
Delta T0 Offset	-13.69128
Delta T0 Slope	0.06063341
[Temperature Calibration]
Date Applied	11/29/2022 7:12:28 PM
Description	From 106.590 °C to 186.590 °C at 10.000°C/min
Gas Type	Nitrogen
Pan Type	Tzero Aluminum Hermetic
Source Files 1	C:\Users\yargerlab\Desktop\DSC Data\General\Indium(6).tri
Measured 1	157.391
Known 1	156.598
[Cell Constant Calibration]
Date Applied	11/29/2022 7:12:29 PM
Description	From 106.590 °C to 186.590 °C at 10.000°C/min
Gas Type	Nitrogen
Pan Type	Tzero Aluminum Hermetic
Source Files 1	C:\Users\yargerlab\Desktop\DSC Data\General\Indium(6).tri
T4P KCell	1.006051
Onset Slope	63.26126 mW/°C
[Direct Cp Calibration]
Date Applied	11/30/2022 11:04:51 AM
Description	From -79.983 °C to 298.409 °C at 10.000°C/min
Gas Type	Nitrogen
Pan Type	Tzero Aluminum Hermetic
Source Files 1	C:\Users\yargerlab\Desktop\DSC Data\General\Sapphire_Heat_Capacity_11_30_22.tri
[Rev Cp Calibration]
Date Applied	11/30/2022 1:58:51 PM
Description	From -79.996 °C to 292.812 °C at 3.000°C/min
Gas Type	Nitrogen
Pan Type	Tzero Aluminum Hermetic
Source Files 1	C:\Users\yargerlab\Desktop\DSC Data\General\Sapphire_MDSC_Calibration_11_30_22.tri
[step]
Ramp 5.00 °C/min to 200.00 °C
Time	Temperature	Heat Flow (Normalized)
min	°C	W/g
0.00	30.06	-0.052
0.02	30.06	-0.051
0.05	30.07	-0.050
0.07	30.08	-0.047
0.09	30.11	-0.023
0.12	30.15	0.000
0.14	30.22	0.016
0.16	30.29	0.024
0.19	30.38	0.029
0.21	30.48	0.032
0.23	30.58	0.035
0.26	30.68	0.037
0.28	30.78	0.038
0.30	30.89	0.040
0.33	31.00	0.041
0.35	31.11	0.042
0.37	31.23	0.043
0.40	31.34	0.044
0.42	31.45	0.044
0.44	31.57	0.045
0.47	31.68	0.045
0.49	31.80	0.046
0.51	31.91	0.046
0.54	32.03	0.046
0.56	32.14	0.047
0.58	32.26	0.047
0.61	32.38	0.047
0.63	32.49	0.048
0.65	32.61	0.048
0.68	32.72	0.048
0.70	32.84	0.048
0.72	32.95	0.048
0.75	33.07	0.048
0.77	33.19	0.048
0.79	33.30	0.049
0.82	33.42	0.049
0.84	33.53	0.049
0.86	33.65	0.049
0.89	33.77	0.049
0.91	33.88	0.049
0.93	34.00	0.048
0.96	34.12	0.048
0.98	34.23	0.048
1.00	34.35	0.048
1.03	34.46	0.048
1.05	34.58	0.048
1.07	34.70	0.048
1.10	34.81	0.048
1.12	34.93	0.048
1.14	35.05	0.048
1.17	35.16	0.048
1.19	35.28	0.048
1.21	35.40	0.048
1.24	35.51	0.047
1.26	35.63	0.047
1.28	35.75	0.047
1.31	35.86	0.047
1.33	35.98	0.047
1.35	36.10	0.047
1.38	36.21	0.047
1.40	36.33	0.047
1.42	36.44	0.047
1.45	36.56	0.047
1.47	36.68	0.046
1.49	36.79	0.046
1.52	36.91	0.046
1.54	37.03	0.046
1.56	37.14	0.046
1.59	37.26	0.046
1.61	37.38	0.046
1.63	37.49	0.046
1.66	37.61	0.045
1.68	37.73	0.045
1.70	37.84	0.045
1.73	37.96	0.045
1.75	38.08	0.045
1.77	38.19	0.045
1.80	38.31	0.045
1.82	38.43	0.045
1.84	38.54	0.045
1.87	38.66	0.044
1.89	38.78	0.044
1.91	38.89	0.044
1.94	39.01	0.044
1.96	39.13	0.044
1.98	39.24	0.044
2.01	39.36	0.044
2.03	39.48	0.044
2.05	39.59	0.044
2.08	39.71	0.044
2.10	39.83	0.044
2.12	39.94	0.043
2.15	40.06	0.043
2.17	40.18	0.043
2.19	40.29	0.043
2.22	40.41	0.043
2.24	40.53	0.043
2.26	40.64	0.043
2.29	40.76	0.043
2.31	40.88	0.043
2.33	40.99	0.043
2.36	41.11	0.042
2.38	41.23	0.042
2.40	41.34	0.042
2.43	41.46	0.042
2.45	41.58	0.042
2.47	41.69	0.042
2.50	41.81	0.042
2.52	41.93	0.042
2.54	42.04	0.042
2.57	42.16	0.042
2.59	42.28	0.042
2.61	42.39	0.042
2.64	42.51	0.042
2.66	42.63	0.042
2.68	42.75	0.042
2.71	42.86	0.042
2.73	42.98	0.042
2.75	43.10	0.042
2.78	43.21	0.042
2.80	43.33	0.041
2.82	43.45	0.041
2.85	43.56	0.041
2.87	43.68	0.041
2.89	43.80	0.041
2.92	43.91	0.041
2.94	44.03	0.041
2.96	44.15	0.041
2.99	44.26	0.041
3.01	44.38	0.041
3.03	44.50	0.041
3.06	44.61	0.041
3.08	44.73	0.041
3.10	44.85	0.041
3.13	44.96	0.041
3.15	45.08	0.041
3.17	45.20	0.041
3.20	45.31	0.041
3.22	45.43	0.041
3.24	45.55	0.040
3.27	45.66	0.040
3.29	45.78	0.040
3.31	45.90	0.040
3.34	46.01	0.040
3.36	46.13	0.040
3.38	46.25	0.040
3.41	46.36	0.040
3.43	46.48	0.040
3.45	46.60	0.040
3.48	46.71	0.040
3.50	46.83	0.040
3.52	46.95	0.040
3.55	47.06	0.040
3.57	47.18	0.040
3.59	47.30	0.040
3.62	47.41	0.040
3.64	47.53	0.040
3.66	47.65	0.040
3.69	47.76	0.040
3.71	47.88	0.040
3.73	48.00	0.040
3.76	48.11	0.040
3.78	48.23	0.040
3.80	48.35	0.040
3.83	48.47	0.040
3.85	48.58	0.040
3.87	48.70	0.040
3.90	48.81	0.039
3.92	48.93	0.040
3.94	49.05	0.040
3.97	49.17	0.039
3.99	49.28	0.039
4.01	49.40	0.039
4.04	49.52	0.039
4.06	49.63	0.039
4.08	49.75	0.039
4.11	49.87	0.039
4.13	49.98	0.039
4.15	50.10	0.039
4.18	50.22	0.039
4.20	50.33	0.039
4.22	50.45	0.039
4.25	50.57	0.039
4.27	50.68	0.039
4.29	50.80	0.039
4.32	50.92	0.039
4.34	51.03	0.039
4.36	51.15	0.039
4.39	51.27	0.039
4.41	51.38	0.039
4.43	51.50	0.039
4.46	51.62	0.039
4.48	51.73	0.039
4.50	51.85	0.039
4.53	51.97	0.039
4.55	52.08	0.039
4.57	52.20	0.039
4.60	52.32	0.039
4.62	52.43	0.039
4.64	52.55	0.039
4.67	52.67	0.039
4.69	52.78	0.039
4.71	52.90	0.039
4.74	53.02	0.039
4.76	53.13	0.039
4.78	53.25	0.039
4.81	53.37	0.039
4.83	53.49	0.039
4.85	53.60	0.039
4.88	53.72	0.039
4.90	53.84	0.039
4.92	53.95	0.039
4.95	54.07	0.039
4.97	54.19	0.039
4.99	54.30	0.038
5.02	54.42	0.038
5.04	54.54	0.038
5.06	54.65	0.038
5.09	54.77	0.039
5.11	54.89	0.039
5.13	55.00	0.038
5.16	55.12	0.038
5.18	55.24	0.039
5.20	55.35	0.038
5.23	55.47	0.038
5.25	55.59	0.039
5.27	55.70	0.039
5.30	55.82	0.038
5.32	55.94	0.039
5.34	56.05	0.039
5.37	56.17	0.039
5.39	56.29	0.039
5.41	56.40	0.039
5.44	56.52	0.039
5.46	56.64	0.039
5.48	56.75	0.039
5.51	56.87	0.039
5.53	56.99	0.039
5.55	57.10	0.039
5.58	57.22	0.039
5.60	57.34	0.039
5.62	57.45	0.039
5.65	57.57	0.039
5.67	57.69	0.039
5.69	57.80	0.039
5.72	57.92	0.039
5.74	58.04	0.039
5.76	58.15	0.039
5.79	58.27	0.039
5.81	58.39	0.039
5.83	58.51	0.039
5.86	58.62	0.039
5.88	58.74	0.039
5.90	58.86	0.039
5.93	58.97	0.039
5.95	59.09	0.039
5.97	59.21	0.039
6.00	59.32	0.039
6.02	59.44	0.039
6.04	59.56	0.039
6.07	59.67	0.038
6.09	59.79	0.038
6.11	59.90	0.039
6.14	60.02	0.038
6.16	60.14	0.038
6.18	60.25	0.039
6.21	60.37	0.039
6.23	60.49	0.038
6.25	60.60	0.038
6.28	60.72	0.038
6.30	60.84	0.038
6.32	60.96	0.038
6.35	61.07	0.038
6.37	61.19	0.038
6.39	61.31	0.038
6.42	61.42	0.038
6.44	61.54	0.038
6.46	61.66	0.038
6.49	61.77	0.038
6.51	61.89	0.038
6.53	62.01	0.038
6.56	62.12	0.038
6.58	62.24	0.038
6.60	62.36	0.038
6.63	62.47	0.038
6.65	62.59	0.038
6.67	62.71	0.038
6.70	62.82	0.038
6.72	62.94	0.038
6.74	63.06	0.038
6.77	63.17	0.038
6.79	63.29	0.038
6.81	63.41	0.038
6.84	63.52	0.038
6.86	63.64	0.038
6.88	63.76	0.038
6.91	63.87	0.038
6.93	63.99	0.038
6.95	64.11	0.038
6.98	64.22	0.038
7.00	64.34	0.038
7.02	64.46	0.038
7.05	64.58	0.038
7.07	64.69	0.038
7.09	64.81	0.038
7.12	64.92	0.038
7.14	65.04	0.038
7.16	65.16	0.038
7.19	65.27	0.038
7.21	65.39	0.038
7.23	65.51	0.038
7.26	65.63	0.038
7.28	65.74	0.038
7.30	65.86	0.038
7.33	65.97	0.038
7.35	66.09	0.038
7.37	66.21	0.038
7.40	66.32	0.038
7.42	66.44	0.038
7.44	66.56	0.038
7.47	66.67	0.038
7.49	66.79	0.038
7.51	66.91	0.038
7.54	67.02	0.038
7.56	67.14	0.038
7.58	67.26	0.038
7.61	67.37	0.038
7.63	67.49	0.038
7.65	67.61	0.038
7.68	67.73	0.038
7.70	67.84	0.038
7.72	67.96	0.038
7.75	68.08	0.038
7.77	68.19	0.038
7.79	68.31	0.038
7.82	68.43	0.038
7.84	68.54	0.038
7.86	68.66	0.038
7.89	68.78	0.038
7.91	68.89	0.038
7.93	69.01	0.038
7.96	69.13	0.038
7.98	69.24	0.038
8.00	69.36	0.038
8.03	69.48	0.038
8.05	69.59	0.038
8.07	69.71	0.038
8.10	69.83	0.038
8.12	69.94	0.038
8.14	70.06	0.038
8.17	70.18	0.038
8.19	70.29	0.038
8.21	70.41	0.038
8.24	70.53	0.038
8.26	70.64	0.038
8.28	70.76	0.038
8.31	70.88	0.038
8.33	70.99	0.038
8.35	71.11	0.038
8.38	71.23	0.038
8.40	71.34	0.038
8.42	71.46	0.038
8.45	71.58	0.038
8.47	71.69	0.038
8.49	71.81	0.038
8.52	71.93	0.038
8.54	72.04	0.038
8.56	72.16	0.038
8.59	72.28	0.038
8.61	72.39	0.038
8.63	72.51	0.038
8.66	72.63	0.038
8.68	72.75	0.038
8.70	72.86	0.038
8.73	72.98	0.038
8.75	73.10	0.038
8.77	73.21	0.038
8.80	73.33	0.038
8.82	73.44	0.038
8.84	73.56	0.038
8.87	73.68	0.038
8.89	73.79	0.038
8.91	73.91	0.038
8.94	74.03	0.038
8.96	74.15	0.038
8.98	74.26	0.038
9.01	74.38	0.038
9.03	74.50	0.038
9.05	74.61	0.038
9.08	74.73	0.038
9.10	74.85	0.038
9.12	74.96	0.038
9.15	75.08	0.038
9.17	75.20	0.038
9.19	75.31	0.038
9.22	75.43	0.038
9.24	75.55	0.038
9.26	75.66	0.038
9.29	75.78	0.038
9.31	75.90	0.038
9.33	76.01	0.038
9.36	76.13	0.038
9.38	76.25	0.038
9.40	76.36	0.038
9.43	76.48	0.038
9.45	76.60	0.038
9.47	76.71	0.038
9.50	76.83	0.038
9.52	76.95	0.038
9.54	77.06	0.038
9.57	77.18	0.038
9.59	77.30	0.038
9.61	77.41	0.038
9.64	77.53	0.038
9.66	77.65	0.038
9.68	77.76	0.038
9.71	77.88	0.038
9.73	78.00	0.038
9.75	78.11	0.038
9.78	78.23	0.038
9.80	78.35	0.038
9.82	78.47	0.038
9.85	78.58	0.038
9.87	78.70	0.038
9.89	78.82	0.038
9.92	78.93	0.039
9.94	79.05	0.038
9.96	79.16	0.038
9.99	79.28	0.039
10.01	79.40	0.038
10.03	79.52	0.039
10.06	79.63	0.038
10.08	79.75	0.038
10.10	79.87	0.039
10.13	79.98	0.038
10.15	80.10	0.038
10.17	80.22	0.038
10.20	80.33	0.038
10.22	80.45	0.038
10.24	80.57	0.038
10.27	80.68	0.038
10.29	80.80	0.038
10.31	80.92	0.038
10.34	81.03	0.038
10.36	81.15	0.038
10.38	81.27	0.038
10.41	81.38	0.038
10.43	81.50	0.038
10.45	81.62	0.038
10.48	81.73	0.038
10.50	81.85	0.038
10.52	81.97	0.038
10.55	82.08	0.038
10.57	82.20	0.038
10.59	82.32	0.038
10.62	82.43	0.038
10.64	82.55	0.038
10.66	82.67	0.038
10.69	82.78	0.038
10.71	82.90	0.038
10.73	83.02	0.038
10.76	83.13	0.038
10.78	83.25	0.038
10.80	83.37	0.038
10.83	83.48	0.038
10.85	83.60	0.038
10.87	83.72	0.038
10.90	83.83	0.038
10.92	83.95	0.038
10.94	84.07	0.038
10.97	84.18	0.038
10.99	84.30	0.038
11.01	84.42	0.038
11.04	84.53	0.038
11.06	84.65	0.038
11.08	84.77	0.038
11.11	84.89	0.038
11.13	85.00	0.038
11.15	85.12	0.038
11.18	85.23	0.038
11.20	85.35	0.038
11.22	85.47	0.038
11.25	85.58	0.038
11.27	85.70	0.038
11.29	85.82	0.038
11.32	85.93	0.037
11.34	86.05	0.038
11.36	86.17	0.038
11.39	86.29	0.037
11.41	86.40	0.038
11.43	86.52	0.038
11.46	86.64	0.038
11.48	86.75	0.038
11.50	86.87	0.038
11.53	86.99	0.038
11.55	87.10	0.038
11.57	87.22	0.038
11.60	87.34	0.038
11.62	87.45	0.038
11.64	87.57	0.038
11.67	87.69	0.038
11.69	87.80	0.038
11.71	87.92	0.038
11.74	88.04	0.038
11.76	88.15	0.038
11.78	88.27	0.038
11.81	88.39	0.038
11.83	88.50	0.038
11.85	88.62	0.038
11.88	88.74	0.038
11.90	88.85	0.038
11.92	88.97	0.038
11.95	89.09	0.038
11.97	89.20	0.038
11.99	89.32	0.038
12.02	89.44	0.038
12.04	89.55	0.038
12.06	89.67	0.038
12.09	89.79	0.038
12.11	89.90	0.038
12.13	90.02	0.038
12.16	90.14	0.038
12.18	90.25	0.038
12.20	90.37	0.038
12.23	90.49	0.038
12.25	90.60	0.038
12.27	90.72	0.038
12.30	90.84	0.038
12.32	90.95	0.038
12.34	91.07	0.038
12.37	91.19	0.038
12.39	91.30	0.038
12.41	91.42	0.038
12.44	91.54	0.038
12.46	91.66	0.038
12.48	91.77	0.038
12.51	91.89	0.038
12.53	92.00	0.038
12.55	92.12	0.038
12.58	92.24	0.038
12.60	92.36	0.038
12.62	92.47	0.038
12.65	92.59	0.038
12.67	92.70	0.038
12.69	92.82	0.038
12.72	92.94	0.038
12.74	93.06	0.038
12.76	93.17	0.038
12.79	93.29	0.038
12.81	93.40	0.038
12.83	93.52	0.038
12.86	93.64	0.038
12.88	93.76	0.038
12.90	93.87	0.038
12.93	93.99	0.038
12.95	94.11	0.039
12.97	94.22	0.039
13.00	94.34	0.039
13.02	94.46	0.039
13.04	94.57	0.039
13.07	94.69	0.039
13.09	94.81	0.039
13.11	94.92	0.039
13.14	95.04	0.039
13.16	95.16	0.039
13.18	95.27	0.039
13.21	95.39	0.039
13.23	95.51	0.039
13.25	95.62	0.039
13.28	95.74	0.039
13.30	95.86	0.039
13.32	95.97	0.039
13.35	96.09	0.039
13.37	96.21	0.039
13.39	96.32	0.039
13.42	96.44	0.039
13.44	96.56	0.039
13.46	96.67	0.039
13.49	96.79	0.039
13.51	96.91	0.039
13.53	97.02	0.039
13.56	97.14	0.039
13.58	97.26	0.039
13.60	97.37	0.039
13.63	97.49	0.039
13.65	97.61	0.039
13.67	97.72	0.039
13.70	97.84	0.039
13.72	97.96	0.039
13.74	98.07	0.039
13.77	98.19	0.039
13.79	98.31	0.039
13.81	98.42	0.039
13.84	98.54	0.039
13.86	98.66	0.039
13.88	98.77	0.039
13.91	98.89	0.039
13.93	99.01	0.039
13.95	99.12	0.039
13.98	99.24	0.039
14.00	99.36	0.039
14.02	99.48	0.039
14.05	99.59	0.039
14.07	99.71	0.039
14.09	99.82	0.039
14.12	99.94	0.039
14.14	100.06	0.039
14.16	100.17	0.039
14.19	100.29	0.039
14.21	100.41	0.039
14.23	100.53	0.039
14.26	100.64	0.039
14.28	100.76	0.039
14.30	100.87	0.039
14.33	100.99	0.039
14.35	101.11	0.039
14.37	101.23	0.039
14.40	101.34	0.039
14.42	101.46	0.039
14.44	101.58	0.039
14.47	101.69	0.039
14.49	101.81	0.039
14.51	101.93	0.039
14.54	102.04	0.039
14.56	102.16	0.039
14.58	102.28	0.040
14.61	102.39	0.039
14.63	102.51	0.040
14.65	102.63	0.040
14.68	102.74	0.040
14.70	102.86	0.040
14.72	102.97	0.040
14.75	103.09	0.040
14.77	103.21	0.040
14.79	103.33	0.040
14.82	103.44	0.040
14.84	103.56	0.040
14.86	103.67	0.040
14.89	103.79	0.040
14.91	103.91	0.040
14.93	104.03	0.040
14.96	104.14	0.039
14.98	104.26	0.039
15.00	104.38	0.040
15.03	104.49	0.039
15.05	104.61	0.039
15.07	104.73	0.039
15.10	104.84	0.039
15.12	104.96	0.039
15.14	105.08	0.039
15.17	105.19	0.039
15.19	105.31	0.039
15.21	105.43	0.039
15.24	105.54	0.039
15.26	105.66	0.040
15.28	105.78	0.039
15.31	105.89	0.040
15.33	106.01	0.040
15.35	106.13	0.040
15.38	106.24	0.039
15.40	106.36	0.039
15.42	106.48	0.039
15.45	106.59	0.039
15.47	106.71	0.040
15.49	106.83	0.040
15.52	106.94	0.040
15.54	107.06	0.040
15.56	107.18	0.040
15.59	107.29	0.040
15.61	107.41	0.040
15.63	107.53	0.040
15.66	107.65	0.040
15.68	107.76	0.040
15.70	107.88	0.040
15.73	108.00	0.040
15.75	108.11	0.040
15.77	108.23	0.040
15.80	108.34	0.040
15.82	108.46	0.040
15.84	108.58	0.040
15.87	108.70	0.040
15.89	108.81	0.040
15.91	108.93	0.040
15.94	109.05	0.040
15.96	109.16	0.040
15.98	109.28	0.040
16.01	109.40	0.040
16.03	109.51	0.040
16.05	109.63	0.040
16.08	109.75	0.040
16.10	109.86	0.040
16.12	109.98	0.040
16.15	110.10	0.040
16.17	110.21	0.040
16.19	110.33	0.040
16.22	110.45	0.040
16.24	110.56	0.040
16.26	110.68	0.040
16.29	110.80	0.040
16.31	110.91	0.040
16.33	111.03	0.040
16.36	111.14	0.040
16.38	111.26	0.040
16.40	111.38	0.040
16.43	111.50	0.040
16.45	111.61	0.040
16.47	111.73	0.040
16.50	111.85	0.040
16.52	111.96	0.040
16.54	112.08	0.040
16.57	112.20	0.040
16.59	112.31	0.040
16.61	112.43	0.040
16.64	112.55	0.040
16.66	112.66	0.041
16.68	112.78	0.041
16.71	112.90	0.040
16.73	113.01	0.040
16.75	113.13	0.040
16.78	113.25	0.040
16.80	113.36	0.040
16.82	113.48	0.040
16.85	113.60	0.040
16.87	113.71	0.040
16.89	113.83	0.040
16.92	113.95	0.040
16.94	114.06	0.040
16.96	114.18	0.040
16.99	114.30	0.040
17.01	114.41	0.041
17.03	114.53	0.041
17.06	114.65	0.041
17.08	114.76	0.041
17.10	114.88	0.041
17.13	115.00	0.041
17.15	115.11	0.041
17.17	115.23	0.041
17.20	115.35	0.041
17.22	115.46	0.041
17.24	115.58	0.041
17.27	115.70	0.041
17.29	115.82	0.041
17.31	115.93	0.041
17.34	116.05	0.041
17.36	116.16	0.041
17.38	116.28	0.041
17.41	116.40	0.041
17.43	116.51	0.041
17.45	116.63	0.041
17.48	116.75	0.041
17.50	116.86	0.041
17.52	116.98	0.041
17.55	117.10	0.041
17.57	117.21	0.041
17.59	117.33	0.041
17.62	117.45	0.041
17.64	117.57	0.041
17.66	117.68	0.041
17.69	117.80	0.041
17.71	117.91	0.041
17.73	118.03	0.041
17.76	118.15	0.041
17.78	118.26	0.041
17.80	118.38	0.041
17.83	118.50	0.041
17.85	118.62	0.041
17.87	118.73	0.041
17.90	118.85	0.041
17.92	118.97	0.041
17.94	119.08	0.041
17.97	119.20	0.041
17.99	119.31	0.041
18.01	119.43	0.041
18.04	119.55	0.041
18.06	119.66	0.041
18.08	119.78	0.041
18.11	119.90	0.041
18.13	120.02	0.041
18.15	120.13	0.041
18.18	120.25	0.041
18.20	120.37	0.041
18.22	120.48	0.041
18.25	120.60	0.041
18.27	120.72	0.041
18.29	120.83	0.041
18.32	120.95	0.041
18.34	121.07	0.041
18.36	121.18	0.041
18.39	121.30	0.041
18.41	121.42	0.041
18.43	121.53	0.041
18.46	121.65	0.042
18.48	121.77	0.042
18.50	121.88	0.041
18.53	122.00	0.041
18.55	122.12	0.042
18.57	122.23	0.041
18.60	122.35	0.041
18.62	122.47	0.042
18.64	122.58	0.042
18.67	122.70	0.042
18.69	122.82	0.042
18.71	122.93	0.042
18.74	123.05	0.042
18.76	123.17	0.042
18.78	123.28	0.042
18.81	123.40	0.042
18.83	123.52	0.042
18.85	123.63	0.042
18.88	123.75	0.042
18.90	123.87	0.042
18.92	123.98	0.042
18.95	124.10	0.042
18.97	124.22	0.042
18.99	124.33	0.042
19.02	124.45	0.042
19.04	124.57	0.042
19.06	124.68	0.042
19.09	124.80	0.042
19.11	124.92	0.042
19.13	125.03	0.042
19.16	125.15	0.042
19.18	125.27	0.042
19.20	125.38	0.042
19.23	125.50	0.042
19.25	125.62	0.042
19.27	125.73	0.042
19.30	125.85	0.042
19.32	125.97	0.042
19.34	126.09	0.042
19.37	126.20	0.042
19.39	126.32	0.042
19.41	126.44	0.042
19.44	126.55	0.042
19.46	126.67	0.042
19.48	126.78	0.042
19.51	126.90	0.042
19.53	127.02	0.042
19.55	127.13	0.042
19.58	127.25	0.042
19.60	127.37	0.042
19.62	127.49	0.042
19.65	127.60	0.042
19.67	127.72	0.042
19.69	127.83	0.042
19.72	127.95	0.042
19.74	128.07	0.042
19.76	128.19	0.042
19.79	128.30	0.042
19.81	128.42	0.042
19.83	128.53	0.043
19.86	128.65	0.042
19.88	128.77	0.043
19.90	128.88	0.043
19.93	129.00	0.043
19.95	129.12	0.043
19.97	129.23	0.043
20.00	129.35	0.043
20.02	129.47	0.043
20.04	129.59	0.043
20.07	129.70	0.043
20.09	129.82	0.043
20.11	129.93	0.043
20.14	130.05	0.043
20.16	130.17	0.043
20.18	130.29	0.043
20.21	130.40	0.043
20.23	130.52	0.043
20.25	130.64	0.043
20.28	130.75	0.043
20.30	130.87	0.043
20.32	130.99	0.043
20.35	131.10	0.043
20.37	131.22	0.043
20.39	131.34	0.043
20.42	131.45	0.043
20.44	131.57	0.043
20.46	131.69	0.043
20.49	131.80	0.043
20.51	131.92	0.043
20.53	132.04	0.043
20.56	132.15	0.043
20.58	132.27	0.043
20.60	132.39	0.043
20.63	132.50	0.043
20.65	132.62	0.043
20.67	132.74	0.043
20.70	132.85	0.043
20.72	132.97	0.043
20.74	133.09	0.043
20.77	133.20	0.043
20.79	133.32	0.043
20.81	133.44	0.043
20.84	133.55	0.043
20.86	133.67	0.043
20.88	133.79	0.043
20.91	133.90	0.043
20.93	134.02	0.043
20.95	134.14	0.043
20.98	134.25	0.043
21.00	134.37	0.043
21.02	134.49	0.043
21.05	134.60	0.043
21.07	134.72	0.043
21.09	134.84	0.043
21.12	134.95	0.043
21.14	135.07	0.043
21.16	135.19	0.043
21.19	135.30	0.043
21.21	135.42	0.043
21.23	135.54	0.043
21.26	135.65	0.043
21.28	135.77	0.043
21.30	135.89	0.043
21.33	136.00	0.043
21.35	136.12	0.043
21.37	136.24	0.043
21.40	136.35	0.043
21.42	136.47	0.043
21.44	136.59	0.043
21.47	136.70	0.043
21.49	136.82	0.043
21.51	136.94	0.043
21.54	137.05	0.043
21.56	137.17	0.043
21.58	137.29	0.043
21.61	137.40	0.043
21.63	137.52	0.043
21.65	137.64	0.043
21.68	137.75	0.043
21.70	137.87	0.043
21.72	137.99	0.043
21.75	138.10	0.043
21.77	138.22	0.043
21.79	138.34	0.043
21.82	138.45	0.043
21.84	138.57	0.043
21.86	138.69	0.043
21.89	138.80	0.043
21.91	138.92	0.043
21.93	139.04	0.043
21.96	139.15	0.043
21.98	139.27	0.043
22.00	139.39	0.043
22.03	139.50	0.044
22.05	139.62	0.044
22.07	139.74	0.044
22.10	139.86	0.044
22.12	139.97	0.044
22.14	140.09	0.044
22.17	140.20	0.044
22.19	140.32	0.044
22.21	140.44	0.044
22.24	140.55	0.044
22.26	140.67	0.044
22.28	140.79	0.044
22.31	140.90	0.044
22.33	141.02	0.044
22.35	141.14	0.044
22.38	141.26	0.044
22.40	141.37	0.044
22.42	141.49	0.044
22.45	141.61	0.044
22.47	141.72	0.044
22.49	141.84	0.044
22.52	141.95	0.044
22.54	142.07	0.044
22.56	142.19	0.044
22.59	142.31	0.044
22.61	142.42	0.044
22.63	142.54	0.044
22.66	142.65	0.044
22.68	142.77	0.045
22.70	142.89	0.045
22.73	143.01	0.045
22.75	143.12	0.045
22.77	143.24	0.045
22.80	143.35	0.045
22.82	143.47	0.045
22.84	143.59	0.045
22.87	143.71	0.045
22.89	143.82	0.045
22.91	143.94	0.045
22.94	144.06	0.045
22.96	144.17	0.045
22.98	144.29	0.045
23.01	144.41	0.045
23.03	144.52	0.045
23.05	144.64	0.045
23.08	144.76	0.045
23.10	144.87	0.045
23.12	144.99	0.045
23.15	145.11	0.045
23.17	145.22	0.045
23.19	145.34	0.045
23.22	145.46	0.045
23.24	145.57	0.045
23.26	145.69	0.045
23.29	145.81	0.045
23.31	145.92	0.045
23.33	146.04	0.045
23.36	146.16	0.045
23.38	146.27	0.045
23.40	146.39	0.045
23.43	146.51	0.045
23.45	146.62	0.045
23.47	146.74	0.045
23.50	146.86	0.045
23.52	146.97	0.045
23.54	147.09	0.046
23.57	147.21	0.045
23.59	147.32	0.046
23.61	147.44	0.046
23.64	147.56	0.046
23.66	147.67	0.046
23.68	147.79	0.046
23.71	147.91	0.046
23.73	148.02	0.046
23.75	148.14	0.046
23.78	148.26	0.046
23.80	148.37	0.046
23.82	148.49	0.046
23.85	148.61	0.046
23.87	148.72	0.046
23.89	148.84	0.046
23.92	148.96	0.046
23.94	149.07	0.046
23.96	149.19	0.046
23.99	149.31	0.046
24.01	149.42	0.046
24.03	149.54	0.046
24.06	149.66	0.046
24.08	149.77	0.046
24.10	149.89	0.046
24.13	150.01	0.046
24.15	150.12	0.046
24.17	150.24	0.046
24.20	150.36	0.046
24.22	150.47	0.046
24.24	150.59	0.046
24.27	150.71	0.046
24.29	150.82	0.046
24.31	150.94	0.046
24.34	151.06	0.046
24.36	151.17	0.046
24.38	151.29	0.046
24.41	151.41	0.046
24.43	151.52	0.046
24.45	151.64	0.046
24.48	151.76	0.046
24.50	151.87	0.046
24.52	151.99	0.046
24.55	152.11	0.046
24.57	152.22	0.046
24.59	152.34	0.046
24.62	152.46	0.046
24.64	152.57	0.046
24.66	152.69	0.046
24.69	152.81	0.046
24.71	152.92	0.046
24.73	153.04	0.046
24.76	153.16	0.046
24.78	153.28	0.046
24.80	153.39	0.046
24.83	153.51	0.046
24.85	153.62	0.046
24.87	153.74	0.046
24.90	153.86	0.046
24.92	153.97	0.046
24.94	154.09	0.046
24.97	154.21	0.046
24.99	154.32	0.046
25.01	154.44	0.046
25.04	154.56	0.046
25.06	154.67	0.047
25.08	154.79	0.047
25.11	154.91	0.047
25.13	155.03	0.047
25.15	155.14	0.047
25.18	155.26	0.047
25.20	155.37	0.047
25.22	155.49	0.047
25.25	155.61	0.047
25.27	155.72	0.047
25.29	155.84	0.047
25.32	155.96	0.047
25.34	156.07	0.047
25.36	156.19	0.047
25.39	156.31	0.047
25.41	156.42	0.047
25.43	156.54	0.049
25.46	156.66	0.095
25.48	156.77	0.211
25.50	156.87	0.437
25.53	156.97	0.668
25.55	157.06	0.856
25.57	157.15	1.038
25.60	157.24	1.224
25.62	157.34	1.410
25.64	157.43	1.581
25.67	157.52	1.738
25.69	157.62	1.899
25.71	157.71	2.100
25.74	157.80	2.258
25.76	157.90	2.315
25.78	158.04	1.053
25.81	158.22	0.604
25.83	158.39	0.448
25.85	158.54	0.342
25.88	158.69	0.261
25.90	158.82	0.205
25.92	158.95	0.161
25.95	159.08	0.129
25.97	159.21	0.109
25.99	159.33	0.090
26.02	159.45	0.079
26.04	159.57	0.072
26.06	159.69	0.066
26.09	159.80	0.062
26.11	159.92	0.061
26.13	160.04	0.059
26.16	160.16	0.057
26.18	160.27	0.056
26.20	160.39	0.055
26.23	160.51	0.054
26.25	160.62	0.054
26.27	160.74	0.053
26.30	160.86	0.053
26.32	160.98	0.052
26.34	161.09	0.052
26.37	161.21	0.051
26.39	161.33	0.051
26.41	161.44	0.051
26.44	161.56	0.050
26.46	161.68	0.050
26.48	161.79	0.050
26.51	161.91	0.050
26.53	162.03	0.049
26.55	162.14	0.049
26.58	162.26	0.049
26.60	162.38	0.049
26.62	162.49	0.049
26.65	162.61	0.049
26.67	162.73	0.049
26.69	162.84	0.048
26.72	162.96	0.048
26.74	163.08	0.048
26.76	163.19	0.048
26.79	163.31	0.048
26.81	163.43	0.048
26.83	163.54	0.048
26.86	163.66	0.048
26.88	163.78	0.048
26.90	163.89	0.048
26.93	164.01	0.048
26.95	164.13	0.048
26.97	164.24	0.048
27.00	164.36	0.048
27.02	164.48	0.048
27.04	164.59	0.048
27.07	164.71	0.048
27.09	164.83	0.048
27.11	164.94	0.048
27.14	165.06	0.048
27.16	165.18	0.048
27.18	165.29	0.048
27.21	165.41	0.048
27.23	165.53	0.048
27.25	165.64	0.048
27.28	165.76	0.048
27.30	165.88	0.048
27.32	165.99	0.048
27.35	166.11	0.048
27.37	166.23	0.048
27.39	166.34	0.048
27.42	166.46	0.048
27.44	166.58	0.048
27.46	166.69	0.048
27.49	166.81	0.048
27.51	166.93	0.048
27.53	167.04	0.048
27.56	167.16	0.048
27.58	167.28	0.048
27.60	167.39	0.049
27.63	167.51	0.049
27.65	167.63	0.049
27.67	167.74	0.049
27.70	167.86	0.049
27.72	167.98	0.049
27.74	168.09	0.049
27.77	168.21	0.049
27.79	168.33	0.049
27.81	168.44	0.049
27.84	168.56	0.049
27.86	168.68	0.049
27.88	168.79	0.049
27.91	168.91	0.049
27.93	169.03	0.049
27.95	169.14	0.049
27.98	169.26	0.049
28.00	169.38	0.049
28.02	169.49	0.049
28.05	169.61	0.049
28.07	169.73	0.049
28.09	169.84	0.049
28.12	169.96	0.049
28.14	170.08	0.049
28.16	170.19	0.049
28.19	170.31	0.049
28.21	170.43	0.049
28.23	170.54	0.049
28.26	170.66	0.049
28.28	170.78	0.049
28.30	170.89	0.049
28.33	171.01	0.049
28.35	171.13	0.049
28.37	171.24	0.049
28.40	171.36	0.049
28.42	171.48	0.049
28.44	171.59	0.049
28.47	171.71	0.049
28.49	171.83	0.049
28.51	171.94	0.049
28.54	172.06	0.049
28.56	172.18	0.049
28.58	172.29	0.049
28.61	172.41	0.049
28.63	172.53	0.049
28.65	172.65	0.049
28.68	172.76	0.050
28.70	172.88	0.050
28.72	172.99	0.050
28.75	173.11	0.050
28.77	173.23	0.050
28.79	173.34	0.050
28.82	173.46	0.050
28.84	173.58	0.050
28.86	173.69	0.050
28.89	173.81	0.050
28.91	173.93	0.050
28.93	174.04	0.050
28.96	174.16	0.050
28.98	174.28	0.050
29.00	174.39	0.050
29.03	174.51	0.050
29.05	174.63	0.050
29.07	174.74	0.050
29.10	174.86	0.050
29.12	174.98	0.050
29.14	175.09	0.050
29.17	175.21	0.050
29.19	175.33	0.050
29.21	175.45	0.050
29.24	175.56	0.050
29.26	175.68	0.050
29.28	175.80	0.050
29.31	175.91	0.050
29.33	176.03	0.050
29.35	176.14	0.050
29.38	176.26	0.050
29.40	176.38	0.050
29.42	176.49	0.051
29.45	176.61	0.051
29.47	176.73	0.051
29.49	176.84	0.051
29.52	176.96	0.051
29.54	177.08	0.051
29.56	177.19	0.051
29.59	177.31	0.051
29.61	177.43	0.051
29.63	177.54	0.051
29.66	177.66	0.051
29.68	177.78	0.051
29.70	177.89	0.051
29.73	178.01	0.051
29.75	178.13	0.051
29.77	178.24	0.051
29.80	178.36	0.051
29.82	178.48	0.051
29.84	178.60	0.051
29.87	178.71	0.051
29.89	178.83	0.051
29.91	178.95	0.051
29.94	179.06	0.051
29.96	179.18	0.051
29.98	179.30	0.051
30.01	179.41	0.051
30.03	179.53	0.051
30.05	179.64	0.051
30.08	179.76	0.051
30.10	179.88	0.051
30.12	179.99	0.051
30.15	180.11	0.051
30.17	180.23	0.051
30.19	180.34	0.051
30.22	180.46	0.051
30.24	180.58	0.052
30.26	180.70	0.051
30.29	180.81	0.051
30.31	180.93	0.052
30.33	181.05	0.051
30.36	181.16	0.052
30.38	181.28	0.052
30.40	181.40	0.052
30.43	181.51	0.052
30.45	181.63	0.052
30.47	181.75	0.051
30.50	181.86	0.052
30.52	181.98	0.051
30.54	182.09	0.051
30.57	182.21	0.052
30.59	182.33	0.052
30.61	182.45	0.052
30.64	182.56	0.052
30.66	182.68	0.052
30.68	182.80	0.052
30.71	182.91	0.052
30.73	183.03	0.052
30.75	183.15	0.052
30.78	183.26	0.052
30.80	183.38	0.052
30.82	183.50	0.052
30.85	183.61	0.052
30.87	183.73	0.052
30.89	183.85	0.052
30.92	183.96	0.052
30.94	184.08	0.052
30.96	184.20	0.052
30.99	184.31	0.052
31.01	184.43	0.052
31.03	184.54	0.052
31.06	184.66	0.052
31.08	184.78	0.052
31.10	184.89	0.052
31.13	185.01	0.052
31.15	185.13	0.053
31.17	185.24	0.053
31.20	185.36	0.053
31.22	185.48	0.053
31.24	185.60	0.053
31.27	185.71	0.053
31.29	185.83	0.053
31.31	185.95	0.053
31.34	186.06	0.053
31.36	186.18	0.053
31.38	186.30	0.053
31.41	186.41	0.053
31.43	186.53	0.053
31.45	186.65	0.053
31.48	186.76	0.053
31.50	186.88	0.053
31.52	187.00	0.053
31.55	187.11	0.053
31.57	187.23	0.053
31.59	187.35	0.053
31.62	187.46	0.053
31.64	187.58	0.053
31.66	187.70	0.053
31.69	187.81	0.053
31.71	187.93	0.053
31.73	188.04	0.053
31.76	188.16	0.053
31.78	188.28	0.053
31.80	188.39	0.053
31.83	188.51	0.053
31.85	188.63	0.053
31.87	188.75	0.053
31.90	188.86	0.053
31.92	188.98	0.053
31.94	189.10	0.053
31.97	189.21	0.053
31.99	189.33	0.053
32.01	189.45	0.053
32.04	189.56	0.053
32.06	189.68	0.053
32.08	189.80	0.053
32.11	189.91	0.053
32.13	190.03	0.053
32.15	190.15	0.053
32.18	190.26	0.053
32.20	190.38	0.053
32.22	190.50	0.054
32.25	190.61	0.054
32.27	190.73	0.054
32.29	190.85	0.054
32.32	190.96	0.054
32.34	191.08	0.054
32.36	191.20	0.054
32.39	191.31	0.054
32.41	191.43	0.054
32.43	191.54	0.054
32.46	191.66	0.054
32.48	191.78	0.054
32.50	191.90	0.054
32.53	192.01	0.054
32.55	192.13	0.054
32.57	192.25	0.054
32.60	192.36	0.054
32.62	192.48	0.054
32.64	192.60	0.054
32.67	192.71	0.054
32.69	192.83	0.054
32.71	192.95	0.054
32.74	193.06	0.054
32.76	193.18	0.054
32.78	193.30	0.054
32.81	193.41	0.054
32.83	193.53	0.054
32.85	193.65	0.054
32.88	193.76	0.054
32.90	193.88	0.054
32.92	194.00	0.054
32.95	194.11	0.054
32.97	194.23	0.054
32.99	194.35	0.054
33.02	194.46	0.054
33.04	194.58	0.054
33.06	194.70	0.054
33.09	194.81	0.054
33.11	194.93	0.054
33.13	195.05	0.054
33.16	195.16	0.054
33.18	195.28	0.055
33.20	195.40	0.055
33.23	195.51	0.055
33.25	195.63	0.055
33.27	195.75	0.055
33.30	195.86	0.055
33.32	195.98	0.055
33.34	196.10	0.055
33.37	196.21	0.055
33.39	196.33	0.055
33.41	196.45	0.055
33.44	196.56	0.055
33.46	196.68	0.055
33.48	196.80	0.055
33.51	196.91	0.055
33.53	197.03	0.055
33.55	197.15	0.055
33.58	197.26	0.055
33.60	197.38	0.055
33.62	197.50	0.055
33.65	197.61	0.055
33.67	197.73	0.055
33.69	197.85	0.055
33.72	197.96	0.055
33.74	198.08	0.055
33.76	198.20	0.055
33.79	198.31	0.055
33.81	198.43	0.055
33.83	198.55	0.055
33.86	198.66	0.055
33.88	198.78	0.055
33.90	198.90	0.055
33.93	199.01	0.055
33.95	199.13
33.97	199.25
34.00
34.00