File: DSC/2025_04_21_CBD_Carnitine_MC_n60C_150C_5Cmin_x3.csv
Filename,2025_04_21_CBD_Carnitine_MC_n60C_150C_5Cmin_x3
Instrument name,DSC2A-00468 (192.168.1.100)
Operator,Yarger
rundate,4/22/2025
Sample name,2025_04_21_CBD_Carnitine_MC_n60C_150C_5Cmin_x3
proceduresegments,Data Off ; Equilibrate -60.00 °C; Data On ; Ramp 5.00 °C/min to 150.00 °C; Data Off ; Isothermal 1.0 min; Data On ; Ramp 10.00 °C/min to -60.00 °C; Data Off ; Isothermal 1.0 min; Data On ; Ramp 5.00 °C/min to 150.00 °C; Data Off ; Isothermal 1.0 min; Data On ; Ramp 10.00 °C/min to -60.00 °C; Data Off ; Isothermal 1.0 min; Data On ; Ramp 5.00 °C/min to 150.00 °C
[File Parameters]
Run date,4/22/2025 1:50:56 AM
Trios version,5.1.1.46572
Original File Name,
Current File Name,D:\DSC2500\JYarger\2025_04_21_CBD_Carnitine_MC_n60C_150C_5Cmin_x3.tri
[Procedure]
Procedure Name,CBD_Carnitine_n60_150C_5Cmin_x3
Sample Name,2025_04_21_CBD_Carnitine_MC_n60C_150C_5Cmin_x3
Sample Mass,5.32 mg
Reference Sample Mass,0 mg
Pan Mass,52.83 mg
Pan Number,21
Reference Pan Mass,52.66 mg
Reference Pan Number,19
Pan Type,Tzero Aluminum Hermetic
Comments,Al Hermetic DSC Consumables sealed Pan/Lid.
Project Name,CA
Operator,Yarger
Test,Custom
Unload Max Temperature,30
Unload Min Temperature,30
Load Max Temperature,30
Load Min Temperature,30
Stop on Gas Flow Error,Yes
[Signal List]
Signal #1,Time (min)
Signal #2,Temperature (°C)
Signal #3,Heat Flow (mW)
Signal #4,Delta T (µV)
Signal #5,Delta Tzero (µV)
Signal #6,Tzero Temperature (°C)
Signal #7,Cell Purge (mL/min)
Signal #8,Heater Temp (°C)
Signal #9,Power Delivered (W)
Signal #10,Reference Junction Temperature (°C)
Signal #11,Flange Temperature (°C)
Signal #12,Heat Flow Phase (rad)
Signal #13,Total Heat Capacity (J/°C)
Signal #14,Heat Capacity (J/°C)
[Configuration]
Company Name,ASU
Instrument Name,DSC2A-00468
Instrument Type,DSC2500
Serial Number,DSC2A-00468
IP,192.168.1.100
Location of Instrument,MRRC
DisplayType,Unknown
Sample Interval ,0.1 s/pt
Selected Heat Flow,T4P
Exotherm Direction,Down
Cell Serial,DRC2-00792
Lid Type,Standard
Cooler,RCS 90
Leave Cooler on at End of Sequence,On
Gas 2,Nitrogen
Gas Selected,Channel 1
Flow Rate,50 mL/min
Secondary Purge,On
Licensed Heat Flow,Heat Flow T4P
Modulation Licensed,Yes
[Versions]
Common IDD Version,1
Cortex Version,VER 2.10.2.31
Driver,5.0.0.6
GDM Version,1.0.3.3
TouchscreenVersion,1.0.0.16145
FEP Version,1.2.1.21
FEP Bootloader,2.0.0.5
AutoSampler Version,2.1.1.26
Auto Sampler Bootloader,2.0.0.5
FCM Version,1.1.0.3
FCM Bootloader,2.0.0.5
[Experiment Logs]
Experiment Log Entry # 1,Data On set to 0
Experiment Log Entry # 3,Equilibrate Segment -60 (C) Started
Experiment Log Entry # 5,Air Cool is off.
Experiment Log Entry # 7,Data On set to 1
Experiment Log Entry # 9,Ramp Segment 5 C/min to 150 Started
Experiment Log Entry # 11,Data On set to 0
Experiment Log Entry # 13,Isothermal Segment 1 min started
Experiment Log Entry # 15,Data On set to 1
Experiment Log Entry # 17,Ramp Segment 10 C/min to -60 Started
Experiment Log Entry # 19,Data On set to 0
Experiment Log Entry # 21,Isothermal Segment 1 min started
Experiment Log Entry # 23,Data On set to 1
Experiment Log Entry # 25,Ramp Segment 5 C/min to 150 Started
Experiment Log Entry # 27,Data On set to 0
Experiment Log Entry # 29,Isothermal Segment 1 min started
Experiment Log Entry # 31,Data On set to 1
Experiment Log Entry # 33,Ramp Segment 10 C/min to -60 Started
Experiment Log Entry # 35,Data On set to 0
Experiment Log Entry # 37,Isothermal Segment 1 min started
Experiment Log Entry # 39,Data On set to 1
Experiment Log Entry # 41,Ramp Segment 5 C/min to 150 Started
Experiment Log Entry # 43,Auto sampler has detected that FEP has gone offline
[Method Log]
Method Log Entry # 1,Data Off
Method Log Entry # 2,Equilibrate -60 °C
Method Log Entry # 3,Data On
Method Log Entry # 4,(Ramp 893649) Ramp 5 °C/minute to 150 °C
Method Log Entry # 5,Data Off
Method Log Entry # 6,Isothermal 1 minutes
Method Log Entry # 7,Data On
Method Log Entry # 8,(Ramp 893653) Ramp 10 °C/minute to -60 °C
Method Log Entry # 9,Data Off
Method Log Entry # 10,Isothermal 1 minutes
Method Log Entry # 11,Data On
Method Log Entry # 12,(Ramp 893657) Ramp 5 °C/minute to 150 °C
Method Log Entry # 13,Data Off
Method Log Entry # 14,Isothermal 1 minutes
Method Log Entry # 15,Data On
Method Log Entry # 16,(Ramp 893661) Ramp 10 °C/minute to -60 °C
Method Log Entry # 17,Data Off
Method Log Entry # 18,Isothermal 1 minutes
Method Log Entry # 19,Data On
Method Log Entry # 20,(Ramp 893665) Ramp 5 °C/minute to 150 °C
Cell Serial,DRC2-00792
[T1 Calibration]
Slope,-0.008529666
Offset,9.636258
Initial Temperature,98.23
GUID,f8bfdadc-4977-4fdf-ba6d-0ba9134940c3
[TZero Calibration]
Date Applied,11/29/2022 4:06:13 PM
Description,From -89.059 °C to 396.009 °C at 20.000°C/min
Gas Type,Nitrogen
Pan Type,None
Source Files 1,C:\Users\yargerlab\Desktop\DSC Data\General\TZero_calibration_11_29_22_2nd(2).tri
Source Files 2,C:\Users\yargerlab\Desktop\DSC Data\General\TZero_calibration_11_29_22_2nd(3).tri
Delta T Offset,13.05235
Delta T Slope,-0.007271007
Delta T0 Offset,-13.69128
Delta T0 Slope,0.06063341
[Temperature Calibration]
Date Applied,11/29/2022 7:12:28 PM
Description,From 106.590 °C to 186.590 °C at 10.000°C/min
Gas Type,Nitrogen
Pan Type,Tzero Aluminum Hermetic
Source Files 1,C:\Users\yargerlab\Desktop\DSC Data\General\Indium(6).tri
Measured 1,157.391
Known 1,156.598
[Cell Constant Calibration]
Date Applied,11/29/2022 7:12:29 PM
Description,From 106.590 °C to 186.590 °C at 10.000°C/min
Gas Type,Nitrogen
Pan Type,Tzero Aluminum Hermetic
Source Files 1,C:\Users\yargerlab\Desktop\DSC Data\General\Indium(6).tri
T4P KCell,1.006051
Onset Slope,63.26126 mW/°C
[Direct Cp Calibration]
Date Applied,11/30/2022 11:04:51 AM
Description,From -79.983 °C to 298.409 °C at 10.000°C/min
Gas Type,Nitrogen
Pan Type,Tzero Aluminum Hermetic
Source Files 1,C:\Users\yargerlab\Desktop\DSC Data\General\Sapphire_Heat_Capacity_11_30_22.tri
[Rev Cp Calibration]
Date Applied,11/30/2022 1:58:51 PM
Description,From -79.996 °C to 292.812 °C at 3.000°C/min
Gas Type,Nitrogen
Pan Type,Tzero Aluminum Hermetic
Source Files 1,C:\Users\yargerlab\Desktop\DSC Data\General\Sapphire_MDSC_Calibration_11_30_22.tri
[step]
Ramp 5.00 °C/min to 150.00 °C
Time,Temperature,Heat Flow (Normalized)
min,°C,W/g
0.00,-59.66,-0.094
0.03,-59.68,-0.091
0.06,-59.68,-0.084
0.08,-59.66,-0.108
0.11,-59.60,-0.137
0.14,-59.51,-0.147
0.17,-59.41,-0.140
0.20,-59.31,-0.111
0.23,-59.20,-0.084
0.26,-59.09,-0.061
0.28,-58.97,-0.043
0.31,-58.85,-0.030
0.34,-58.72,-0.017
0.37,-58.60,-0.006
0.40,-58.47,0.003
0.43,-58.34,0.012
0.45,-58.21,0.017
0.48,-58.07,0.022
0.51,-57.94,0.027
0.54,-57.81,0.030
0.57,-57.67,0.033
0.60,-57.54,0.036
0.62,-57.40,0.037
0.65,-57.26,0.039
0.68,-57.13,0.040
0.71,-56.99,0.042
0.74,-56.85,0.043
0.77,-56.71,0.043
0.79,-56.57,0.044
0.82,-56.43,0.045
0.85,-56.30,0.046
0.88,-56.16,0.046
0.91,-56.02,0.047
0.93,-55.88,0.047
0.96,-55.74,0.048
0.99,-55.60,0.048
1.02,-55.46,0.049
1.05,-55.32,0.049
1.08,-55.18,0.049
1.11,-55.04,0.050
1.13,-54.90,0.050
1.16,-54.76,0.050
1.19,-54.62,0.051
1.22,-54.48,0.051
1.25,-54.34,0.051
1.28,-54.20,0.051
1.30,-54.06,0.052
1.33,-53.91,0.052
1.36,-53.77,0.052
1.39,-53.63,0.052
1.42,-53.49,0.052
1.44,-53.35,0.052
1.47,-53.21,0.052
1.50,-53.07,0.053
1.53,-52.93,0.053
1.56,-52.79,0.053
1.59,-52.65,0.053
1.62,-52.51,0.053
1.64,-52.36,0.053
1.67,-52.22,0.053
1.70,-52.08,0.053
1.73,-51.94,0.053
1.76,-51.80,0.053
1.78,-51.66,0.053
1.81,-51.52,0.053
1.84,-51.38,0.053
1.87,-51.24,0.053
1.90,-51.09,0.053
1.93,-50.95,0.053
1.96,-50.81,0.053
1.98,-50.67,0.053
2.01,-50.53,0.053
2.04,-50.39,0.053
2.07,-50.25,0.053
2.10,-50.10,0.053
2.13,-49.96,0.053
2.15,-49.82,0.053
2.18,-49.68,0.053
2.21,-49.54,0.053
2.24,-49.40,0.053
2.27,-49.25,0.053
2.29,-49.11,0.053
2.32,-48.97,0.053
2.35,-48.83,0.053
2.38,-48.69,0.053
2.41,-48.55,0.053
2.44,-48.41,0.053
2.46,-48.27,0.053
2.49,-48.12,0.053
2.52,-47.98,0.053
2.55,-47.84,0.053
2.58,-47.70,0.053
2.61,-47.56,0.053
2.64,-47.42,0.053
2.66,-47.28,0.053
2.69,-47.13,0.053
2.72,-46.99,0.053
2.75,-46.85,0.053
2.78,-46.71,0.053
2.81,-46.57,0.053
2.83,-46.43,0.054
2.86,-46.29,0.054
2.89,-46.15,0.053
2.92,-46.01,0.053
2.95,-45.87,0.053
2.98,-45.72,0.053
3.00,-45.58,0.052
3.03,-45.44,0.052
3.06,-45.30,0.052
3.09,-45.16,0.052
3.12,-45.01,0.052
3.14,-44.87,0.052
3.17,-44.73,0.052
3.20,-44.59,0.052
3.23,-44.45,0.052
3.26,-44.30,0.052
3.29,-44.16,0.052
3.31,-44.02,0.052
3.34,-43.88,0.052
3.37,-43.74,0.052
3.40,-43.60,0.052
3.43,-43.45,0.052
3.46,-43.31,0.052
3.49,-43.17,0.052
3.51,-43.03,0.052
3.54,-42.89,0.052
3.57,-42.74,0.052
3.60,-42.60,0.053
3.63,-42.46,0.053
3.66,-42.32,0.053
3.68,-42.18,0.052
3.71,-42.03,0.052
3.74,-41.89,0.052
3.77,-41.75,0.052
3.80,-41.61,0.052
3.83,-41.47,0.052
3.85,-41.32,0.052
3.88,-41.18,0.052
3.91,-41.04,0.052
3.94,-40.90,0.052
3.97,-40.76,0.052
3.99,-40.62,0.052
4.02,-40.47,0.052
4.05,-40.33,0.052
4.08,-40.19,0.052
4.11,-40.05,0.052
4.14,-39.91,0.052
4.16,-39.76,0.052
4.19,-39.62,0.052
4.22,-39.48,0.052
4.25,-39.34,0.052
4.28,-39.20,0.052
4.31,-39.06,0.052
4.34,-38.91,0.052
4.36,-38.77,0.052
4.39,-38.63,0.052
4.42,-38.49,0.052
4.45,-38.34,0.052
4.48,-38.20,0.052
4.50,-38.06,0.052
4.53,-37.92,0.052
4.56,-37.78,0.052
4.59,-37.63,0.052
4.62,-37.50,0.052
4.65,-37.35,0.052
4.68,-37.21,0.052
4.70,-37.07,0.052
4.73,-36.93,0.052
4.76,-36.79,0.052
4.79,-36.64,0.052
4.82,-36.50,0.052
4.85,-36.36,0.052
4.87,-36.22,0.052
4.90,-36.08,0.052
4.93,-35.93,0.052
4.96,-35.79,0.052
4.99,-35.65,0.052
5.01,-35.51,0.052
5.04,-35.37,0.052
5.07,-35.23,0.052
5.10,-35.08,0.052
5.13,-34.94,0.052
5.16,-34.80,0.052
5.19,-34.66,0.052
5.21,-34.52,0.052
5.24,-34.37,0.052
5.27,-34.23,0.052
5.30,-34.09,0.052
5.33,-33.95,0.052
5.35,-33.81,0.052
5.38,-33.66,0.052
5.41,-33.52,0.052
5.44,-33.38,0.052
5.47,-33.24,0.052
5.50,-33.10,0.052
5.53,-32.96,0.052
5.55,-32.81,0.052
5.58,-32.67,0.052
5.61,-32.53,0.052
5.64,-32.39,0.052
5.67,-32.25,0.052
5.70,-32.11,0.052
5.72,-31.96,0.052
5.75,-31.82,0.052
5.78,-31.68,0.052
5.81,-31.54,0.052
5.84,-31.40,0.052
5.86,-31.26,0.052
5.89,-31.11,0.052
5.92,-30.97,0.052
5.95,-30.83,0.052
5.98,-30.69,0.052
6.01,-30.55,0.052
6.04,-30.40,0.052
6.06,-30.26,0.052
6.09,-30.12,0.052
6.12,-29.98,0.052
6.15,-29.84,0.052
6.18,-29.70,0.052
6.20,-29.55,0.052
6.23,-29.41,0.052
6.26,-29.27,0.052
6.29,-29.13,0.052
6.32,-28.99,0.052
6.35,-28.84,0.052
6.38,-28.70,0.052
6.40,-28.56,0.052
6.43,-28.42,0.052
6.46,-28.28,0.052
6.49,-28.14,0.052
6.52,-27.99,0.052
6.55,-27.85,0.052
6.57,-27.71,0.052
6.60,-27.57,0.052
6.63,-27.43,0.052
6.66,-27.28,0.052
6.69,-27.14,0.052
6.71,-27.00,0.052
6.74,-26.86,0.052
6.77,-26.72,0.052
6.80,-26.58,0.052
6.83,-26.43,0.052
6.86,-26.29,0.052
6.89,-26.15,0.052
6.91,-26.01,0.052
6.94,-25.87,0.052
6.97,-25.72,0.052
7.00,-25.58,0.052
7.03,-25.44,0.052
7.05,-25.30,0.052
7.08,-25.16,0.052
7.11,-25.02,0.052
7.14,-24.87,0.052
7.17,-24.73,0.052
7.20,-24.59,0.052
7.23,-24.45,0.052
7.25,-24.31,0.052
7.28,-24.17,0.052
7.31,-24.02,0.052
7.34,-23.88,0.052
7.37,-23.74,0.052
7.40,-23.60,0.052
7.42,-23.46,0.052
7.45,-23.32,0.052
7.48,-23.17,0.052
7.51,-23.03,0.052
7.54,-22.89,0.052
7.56,-22.75,0.052
7.59,-22.60,0.052
7.62,-22.46,0.052
7.65,-22.32,0.052
7.68,-22.18,0.052
7.71,-22.04,0.052
7.74,-21.90,0.052
7.76,-21.76,0.052
7.79,-21.61,0.052
7.82,-21.47,0.052
7.85,-21.33,0.052
7.88,-21.19,0.052
7.90,-21.05,0.052
7.93,-20.90,0.052
7.96,-20.76,0.052
7.99,-20.62,0.052
8.02,-20.48,0.052
8.05,-20.34,0.052
8.08,-20.19,0.052
8.10,-20.05,0.052
8.13,-19.91,0.052
8.16,-19.77,0.052
8.19,-19.63,0.052
8.22,-19.49,0.052
8.25,-19.34,0.052
8.27,-19.20,0.052
8.30,-19.06,0.052
8.33,-18.92,0.052
8.36,-18.78,0.052
8.39,-18.64,0.052
8.41,-18.49,0.052
8.44,-18.35,0.052
8.47,-18.21,0.052
8.50,-18.07,0.052
8.53,-17.93,0.052
8.56,-17.78,0.052
8.58,-17.64,0.052
8.61,-17.50,0.052
8.64,-17.36,0.052
8.67,-17.22,0.052
8.70,-17.07,0.052
8.73,-16.93,0.052
8.75,-16.79,0.052
8.78,-16.65,0.052
8.81,-16.50,0.052
8.84,-16.36,0.052
8.87,-16.22,0.053
8.90,-16.08,0.053
8.93,-15.94,0.053
8.95,-15.80,0.053
8.98,-15.65,0.053
9.01,-15.51,0.053
9.04,-15.37,0.053
9.07,-15.23,0.053
9.10,-15.09,0.053
9.12,-14.95,0.052
9.15,-14.80,0.052
9.18,-14.66,0.052
9.21,-14.52,0.052
9.24,-14.38,0.052
9.27,-14.24,0.052
9.29,-14.10,0.052
9.32,-13.95,0.052
9.35,-13.81,0.052
9.38,-13.67,0.052
9.41,-13.53,0.052
9.43,-13.39,0.052
9.46,-13.25,0.052
9.49,-13.10,0.052
9.52,-12.96,0.052
9.55,-12.82,0.052
9.58,-12.68,0.052
9.60,-12.54,0.052
9.63,-12.39,0.052
9.66,-12.25,0.052
9.69,-12.11,0.052
9.72,-11.97,0.052
9.75,-11.83,0.052
9.78,-11.69,0.052
9.80,-11.54,0.052
9.83,-11.40,0.052
9.86,-11.26,0.052
9.89,-11.12,0.053
9.92,-10.98,0.052
9.95,-10.84,0.052
9.97,-10.69,0.053
10.00,-10.55,0.053
10.03,-10.41,0.053
10.06,-10.27,0.053
10.09,-10.13,0.053
10.12,-9.99,0.052
10.14,-9.84,0.052
10.17,-9.70,0.052
10.20,-9.56,0.052
10.23,-9.42,0.052
10.26,-9.28,0.052
10.28,-9.14,0.052
10.31,-9.00,0.052
10.34,-8.85,0.052
10.37,-8.71,0.053
10.40,-8.57,0.053
10.43,-8.43,0.053
10.45,-8.29,0.053
10.48,-8.15,0.053
10.51,-8.00,0.053
10.54,-7.86,0.053
10.57,-7.72,0.052
10.60,-7.58,0.053
10.63,-7.43,0.053
10.65,-7.29,0.053
10.68,-7.15,0.053
10.71,-7.01,0.053
10.74,-6.87,0.053
10.77,-6.73,0.053
10.80,-6.58,0.053
10.82,-6.44,0.053
10.85,-6.30,0.053
10.88,-6.16,0.053
10.91,-6.02,0.053
10.94,-5.88,0.053
10.97,-5.73,0.053
10.99,-5.59,0.053
11.02,-5.45,0.053
11.05,-5.31,0.053
11.08,-5.17,0.053
11.11,-5.02,0.053
11.13,-4.88,0.053
11.16,-4.74,0.053
11.19,-4.60,0.053
11.22,-4.46,0.053
11.25,-4.32,0.053
11.28,-4.17,0.053
11.30,-4.03,0.053
11.33,-3.89,0.053
11.36,-3.75,0.053
11.39,-3.61,0.053
11.42,-3.46,0.053
11.45,-3.32,0.053
11.48,-3.18,0.053
11.50,-3.04,0.053
11.53,-2.90,0.053
11.56,-2.76,0.053
11.59,-2.62,0.053
11.62,-2.47,0.053
11.65,-2.33,0.053
11.67,-2.19,0.053
11.70,-2.05,0.053
11.73,-1.91,0.053
11.76,-1.76,0.053
11.79,-1.62,0.053
11.82,-1.48,0.053
11.84,-1.34,0.053
11.87,-1.20,0.053
11.90,-1.06,0.053
11.93,-0.91,0.053
11.96,-0.77,0.053
11.98,-0.63,0.053
12.01,-0.49,0.053
12.04,-0.35,0.054
12.07,-0.21,0.053
12.10,-0.06,0.053
12.13,0.08,0.053
12.15,0.22,0.053
12.18,0.36,0.054
12.21,0.50,0.054
12.24,0.64,0.054
12.27,0.79,0.054
12.30,0.93,0.054
12.33,1.07,0.054
12.35,1.21,0.054
12.38,1.35,0.054
12.41,1.50,0.054
12.44,1.64,0.054
12.47,1.78,0.054
12.50,1.92,0.054
12.52,2.06,0.054
12.55,2.21,0.054
12.58,2.35,0.054
12.61,2.49,0.054
12.64,2.63,0.054
12.67,2.77,0.054
12.69,2.92,0.054
12.72,3.06,0.054
12.75,3.20,0.054
12.78,3.34,0.054
12.81,3.48,0.054
12.83,3.62,0.054
12.86,3.77,0.054
12.89,3.91,0.054
12.92,4.05,0.054
12.95,4.19,0.054
12.98,4.33,0.054
13.00,4.47,0.054
13.03,4.62,0.054
13.06,4.76,0.054
13.09,4.90,0.054
13.12,5.04,0.054
13.15,5.18,0.055
13.18,5.32,0.055
13.20,5.47,0.055
13.23,5.61,0.055
13.26,5.75,0.055
13.29,5.89,0.055
13.32,6.03,0.055
13.35,6.18,0.055
13.37,6.32,0.055
13.40,6.46,0.055
13.43,6.60,0.055
13.46,6.74,0.055
13.49,6.88,0.055
13.52,7.03,0.055
13.54,7.17,0.055
13.57,7.31,0.055
13.60,7.45,0.055
13.63,7.59,0.055
13.66,7.74,0.055
13.68,7.88,0.055
13.71,8.02,0.055
13.74,8.16,0.055
13.77,8.30,0.055
13.80,8.44,0.055
13.83,8.59,0.055
13.85,8.73,0.055
13.88,8.87,0.055
13.91,9.01,0.055
13.94,9.15,0.055
13.97,9.29,0.055
14.00,9.44,0.055
14.03,9.58,0.055
14.05,9.72,0.055
14.08,9.86,0.055
14.11,10.00,0.055
14.14,10.14,0.055
14.17,10.29,0.055
14.20,10.43,0.055
14.22,10.57,0.055
14.25,10.71,0.056
14.28,10.85,0.056
14.31,10.99,0.056
14.34,11.14,0.056
14.37,11.28,0.056
14.39,11.42,0.056
14.42,11.56,0.056
14.45,11.70,0.056
14.48,11.85,0.056
14.51,11.99,0.056
14.53,12.13,0.056
14.56,12.27,0.056
14.59,12.41,0.056
14.62,12.55,0.056
14.65,12.70,0.056
14.68,12.84,0.056
14.70,12.98,0.056
14.73,13.12,0.056
14.76,13.26,0.056
14.79,13.40,0.056
14.82,13.55,0.056
14.85,13.69,0.056
14.88,13.83,0.056
14.90,13.97,0.057
14.93,14.11,0.057
14.96,14.25,0.057
14.99,14.40,0.057
15.02,14.54,0.057
15.05,14.68,0.057
15.07,14.82,0.057
15.10,14.96,0.057
15.13,15.11,0.057
15.16,15.25,0.057
15.19,15.39,0.057
15.22,15.53,0.057
15.24,15.67,0.057
15.27,15.81,0.057
15.30,15.96,0.057
15.33,16.10,0.057
15.36,16.24,0.057
15.38,16.38,0.057
15.41,16.52,0.057
15.44,16.66,0.057
15.47,16.81,0.057
15.50,16.95,0.057
15.53,17.09,0.057
15.55,17.23,0.057
15.58,17.37,0.057
15.61,17.51,0.057
15.64,17.66,0.058
15.67,17.80,0.058
15.70,17.94,0.058
15.73,18.08,0.058
15.75,18.22,0.058
15.78,18.37,0.058
15.81,18.51,0.058
15.84,18.65,0.058
15.87,18.79,0.058
15.90,18.93,0.058
15.92,19.07,0.058
15.95,19.22,0.058
15.98,19.36,0.058
16.01,19.50,0.058
16.04,19.64,0.058
16.07,19.78,0.058
16.09,19.93,0.058
16.12,20.07,0.058
16.15,20.21,0.058
16.18,20.35,0.058
16.21,20.49,0.058
16.23,20.63,0.058
16.26,20.78,0.058
16.29,20.92,0.058
16.32,21.06,0.058
16.35,21.20,0.059
16.38,21.34,0.059
16.40,21.48,0.059
16.43,21.63,0.059
16.46,21.77,0.059
16.49,21.91,0.059
16.52,22.05,0.059
16.55,22.19,0.059
16.58,22.34,0.059
16.60,22.48,0.059
16.63,22.62,0.059
16.66,22.76,0.059
16.69,22.90,0.059
16.72,23.04,0.059
16.75,23.19,0.059
16.77,23.33,0.059
16.80,23.47,0.059
16.83,23.61,0.059
16.86,23.75,0.059
16.89,23.89,0.059
16.92,24.04,0.059
16.94,24.18,0.059
16.97,24.32,0.059
17.00,24.46,0.059
17.03,24.60,0.059
17.06,24.75,0.060
17.08,24.89,0.060
17.11,25.03,0.060
17.14,25.17,0.060
17.17,25.31,0.060
17.20,25.45,0.060
17.23,25.59,0.060
17.26,25.74,0.060
17.28,25.88,0.060
17.31,26.02,0.060
17.34,26.16,0.060
17.37,26.30,0.060
17.40,26.45,0.060
17.43,26.59,0.060
17.45,26.73,0.060
17.48,26.87,0.060
17.51,27.01,0.060
17.54,27.15,0.060
17.57,27.30,0.060
17.59,27.44,0.060
17.62,27.58,0.060
17.65,27.72,0.060
17.68,27.86,0.060
17.71,28.00,0.060
17.74,28.15,0.061
17.77,28.29,0.061
17.79,28.43,0.061
17.82,28.57,0.061
17.85,28.71,0.061
17.88,28.86,0.061
17.91,29.00,0.061
17.93,29.14,0.061
17.96,29.28,0.061
17.99,29.42,0.061
18.02,29.57,0.061
18.05,29.71,0.061
18.08,29.85,0.061
18.11,29.99,0.061
18.13,30.13,0.061
18.16,30.27,0.061
18.19,30.42,0.061
18.22,30.56,0.061
18.25,30.70,0.061
18.28,30.84,0.061
18.30,30.98,0.061
18.33,31.12,0.061
18.36,31.27,0.062
18.39,31.41,0.062
18.42,31.55,0.062
18.44,31.69,0.062
18.47,31.83,0.062
18.50,31.97,0.062
18.53,32.12,0.062
18.56,32.26,0.062
18.59,32.40,0.062
18.62,32.54,0.062
18.64,32.68,0.062
18.67,32.83,0.062
18.70,32.97,0.062
18.73,33.11,0.062
18.76,33.25,0.063
18.78,33.39,0.063
18.81,33.53,0.063
18.84,33.68,0.063
18.87,33.82,0.063
18.90,33.96,0.063
18.93,34.10,0.063
18.96,34.24,0.063
18.98,34.38,0.064
19.01,34.53,0.064
19.04,34.67,0.064
19.07,34.81,0.064
19.10,34.95,0.064
19.13,35.09,0.064
19.15,35.23,0.064
19.18,35.37,0.064
19.21,35.52,0.064
19.24,35.66,0.064
19.27,35.80,0.064
19.29,35.94,0.065
19.32,36.08,0.065
19.35,36.23,0.065
19.38,36.37,0.065
19.41,36.51,0.065
19.44,36.65,0.065
19.47,36.79,0.066
19.49,36.94,0.066
19.52,37.08,0.066
19.55,37.22,0.066
19.58,37.36,0.066
19.61,37.50,0.067
19.63,37.64,0.067
19.66,37.79,0.067
19.69,37.93,0.067
19.72,38.07,0.067
19.75,38.21,0.067
19.78,38.35,0.068
19.81,38.49,0.068
19.83,38.63,0.068
19.86,38.78,0.068
19.89,38.92,0.068
19.92,39.06,0.069
19.95,39.20,0.069
19.98,39.34,0.069
20.00,39.48,0.069
20.03,39.63,0.069
20.06,39.77,0.069
20.09,39.91,0.070
20.12,40.05,0.070
20.14,40.19,0.070
20.17,40.33,0.070
20.20,40.47,0.070
20.23,40.62,0.070
20.26,40.76,0.071
20.29,40.90,0.071
20.32,41.04,0.071
20.34,41.18,0.072
20.37,41.32,0.072
20.40,41.47,0.072
20.43,41.61,0.072
20.46,41.75,0.073
20.48,41.89,0.073
20.51,42.03,0.073
20.54,42.18,0.073
20.57,42.32,0.074
20.60,42.46,0.074
20.63,42.60,0.074
20.66,42.74,0.074
20.68,42.88,0.075
20.71,43.03,0.075
20.74,43.17,0.075
20.77,43.31,0.076
20.80,43.45,0.076
20.83,43.59,0.076
20.85,43.74,0.077
20.88,43.88,0.077
20.91,44.02,0.077
20.94,44.16,0.077
20.97,44.30,0.078
20.99,44.44,0.078
21.02,44.58,0.078
21.05,44.73,0.079
21.08,44.87,0.079
21.11,45.01,0.079
21.14,45.15,0.080
21.17,45.29,0.080
21.19,45.43,0.081
21.22,45.58,0.081
21.25,45.72,0.082
21.28,45.86,0.082
21.31,46.00,0.082
21.33,46.14,0.083
21.36,46.28,0.083
21.39,46.42,0.084
21.42,46.57,0.084
21.45,46.71,0.085
21.48,46.85,0.085
21.51,46.99,0.086
21.53,47.13,0.087
21.56,47.27,0.087
21.59,47.42,0.088
21.62,47.56,0.088
21.65,47.70,0.089
21.68,47.84,0.090
21.70,47.98,0.091
21.73,48.12,0.092
21.76,48.26,0.092
21.79,48.41,0.093
21.82,48.55,0.094
21.84,48.69,0.095
21.87,48.83,0.096
21.90,48.97,0.097
21.93,49.11,0.098
21.96,49.25,0.099
21.99,49.39,0.100
22.02,49.54,0.101
22.04,49.68,0.103
22.07,49.82,0.104
22.10,49.96,0.105
22.13,50.10,0.106
22.16,50.24,0.109
22.18,50.38,0.111
22.21,50.53,0.112
22.24,50.67,0.113
22.27,50.81,0.114
22.30,50.95,0.116
22.33,51.09,0.118
22.36,51.23,0.120
22.38,51.37,0.123
22.41,51.51,0.124
22.44,51.65,0.126
22.47,51.80,0.128
22.50,51.94,0.130
22.53,52.08,0.132
22.55,52.22,0.135
22.58,52.36,0.138
22.61,52.50,0.141
22.64,52.64,0.144
22.67,52.78,0.146
22.69,52.92,0.148
22.72,53.06,0.152
22.75,53.20,0.156
22.78,53.34,0.159
22.81,53.49,0.161
22.84,53.63,0.165
22.87,53.76,0.167
22.89,53.91,0.170
22.92,54.05,0.175
22.95,54.19,0.178
22.98,54.33,0.182
23.01,54.47,0.186
23.03,54.61,0.189
23.06,54.75,0.192
23.09,54.89,0.198
23.12,55.03,0.202
23.15,55.17,0.209
23.18,55.31,0.212
23.21,55.45,0.216
23.23,55.59,0.219
23.26,55.73,0.222
23.29,55.87,0.230
23.32,56.01,0.235
23.35,56.15,0.238
23.38,56.29,0.242
23.40,56.43,0.247
23.43,56.57,0.254
23.46,56.71,0.258
23.49,56.85,0.263
23.52,56.99,0.266
23.54,57.13,0.271
23.57,57.27,0.274
23.60,57.41,0.279
23.63,57.55,0.283
23.66,57.69,0.289
23.69,57.83,0.293
23.72,57.97,0.297
23.74,58.11,0.300
23.77,58.25,0.307
23.80,58.39,0.312
23.83,58.53,0.316
23.86,58.67,0.319
23.88,58.81,0.326
23.91,58.95,0.334
23.94,59.09,0.342
23.97,59.23,0.348
24.00,59.37,0.355
24.03,59.51,0.363
24.06,59.65,0.368
24.08,59.79,0.375
24.11,59.93,0.381
24.14,60.07,0.387
24.17,60.21,0.395
24.20,60.35,0.403
24.23,60.48,0.410
24.25,60.62,0.415
24.28,60.76,0.421
24.31,60.90,0.424
24.34,61.04,0.428
24.37,61.18,0.433
24.39,61.32,0.436
24.42,61.46,0.437
24.45,61.60,0.437
24.48,61.75,0.437
24.51,61.89,0.438
24.54,62.03,0.438
24.57,62.17,0.437
24.59,62.32,0.436
24.62,62.46,0.433
24.65,62.60,0.427
24.68,62.74,0.418
24.71,62.89,0.411
24.73,63.03,0.401
24.76,63.18,0.393
24.79,63.32,0.382
24.82,63.47,0.371
24.85,63.61,0.359
24.88,63.76,0.346
24.91,63.90,0.333
24.93,64.05,0.320
24.96,64.20,0.304
24.99,64.34,0.289
25.02,64.49,0.274
25.05,64.64,0.259
25.08,64.79,0.244
25.10,64.93,0.229
25.13,65.08,0.215
25.16,65.23,0.202
25.19,65.38,0.189
25.22,65.52,0.178
25.24,65.67,0.168
25.27,65.81,0.159
25.30,65.96,0.150
25.33,66.10,0.144
25.36,66.25,0.140
25.39,66.39,0.138
25.42,66.53,0.136
25.44,66.68,0.133
25.47,66.82,0.131
25.50,66.96,0.131
25.53,67.11,0.130
25.56,67.25,0.130
25.58,67.39,0.130
25.61,67.53,0.130
25.64,67.67,0.130
25.67,67.82,0.130
25.70,67.96,0.131
25.73,68.10,0.133
25.76,68.24,0.136
25.78,68.38,0.140
25.81,68.52,0.147
25.84,68.66,0.155
25.87,68.80,0.166
25.90,68.94,0.180
25.93,69.07,0.198
25.95,69.21,0.219
25.98,69.34,0.245
26.01,69.48,0.278
26.04,69.61,0.319
26.07,69.74,0.368
26.09,69.86,0.423
26.12,69.98,0.485
26.15,70.11,0.545
26.18,70.23,0.598
26.21,70.35,0.638
26.24,70.48,0.657
26.27,70.61,0.650
26.29,70.75,0.622
26.32,70.90,0.579
26.35,71.05,0.520
26.38,71.21,0.461
26.41,71.37,0.400
26.43,71.53,0.344
26.46,71.69,0.295
26.49,71.85,0.253
26.52,72.01,0.219
26.55,72.17,0.192
26.58,72.32,0.171
26.61,72.47,0.153
26.63,72.62,0.142
26.66,72.77,0.133
26.69,72.91,0.124
26.72,73.06,0.118
26.75,73.20,0.113
26.78,73.35,0.107
26.80,73.49,0.105
26.83,73.64,0.102
26.86,73.78,0.101
26.89,73.92,0.099
26.92,74.06,0.098
26.94,74.21,0.097
26.97,74.35,0.096
27.00,74.49,0.096
27.03,74.63,0.095
27.06,74.77,0.094
27.09,74.92,0.094
27.12,75.06,0.093
27.14,75.20,0.092
27.17,75.34,0.091
27.20,75.49,0.091
27.23,75.63,0.091
27.26,75.77,0.090
27.28,75.91,0.090
27.31,76.05,0.089
27.34,76.19,0.089
27.37,76.34,0.089
27.40,76.48,0.088
27.43,76.62,0.088
27.46,76.76,0.087
27.48,76.90,0.087
27.51,77.05,0.087
27.54,77.19,0.086
27.57,77.33,0.086
27.60,77.47,0.086
27.63,77.61,0.085
27.65,77.75,0.085
27.68,77.90,0.085
27.71,78.04,0.085
27.74,78.18,0.084
27.77,78.32,0.084
27.79,78.46,0.084
27.82,78.60,0.083
27.85,78.75,0.083
27.88,78.89,0.083
27.91,79.03,0.082
27.94,79.17,0.082
27.97,79.31,0.082
27.99,79.46,0.081
28.02,79.60,0.081
28.05,79.74,0.081
28.08,79.88,0.080
28.11,80.02,0.080
28.13,80.17,0.080
28.16,80.31,0.080
28.19,80.45,0.079
28.22,80.59,0.079
28.25,80.73,0.079
28.28,80.87,0.078
28.31,81.02,0.078
28.33,81.16,0.078
28.36,81.30,0.078
28.39,81.44,0.077
28.42,81.58,0.077
28.45,81.73,0.077
28.48,81.87,0.076
28.50,82.01,0.076
28.53,82.15,0.076
28.56,82.30,0.076
28.59,82.44,0.075
28.62,82.58,0.075
28.64,82.72,0.075
28.67,82.86,0.075
28.70,83.00,0.074
28.73,83.15,0.074
28.76,83.29,0.074
28.79,83.43,0.073
28.82,83.57,0.073
28.84,83.71,0.073
28.87,83.85,0.073
28.90,84.00,0.072
28.93,84.14,0.072
28.96,84.28,0.072
28.98,84.42,0.071
29.01,84.56,0.071
29.04,84.71,0.071
29.07,84.85,0.070
29.10,84.99,0.070
29.13,85.13,0.070
29.16,85.27,0.069
29.18,85.42,0.069
29.21,85.56,0.069
29.24,85.70,0.068
29.27,85.84,0.068
29.30,85.99,0.068
29.33,86.13,0.068
29.35,86.27,0.068
29.38,86.41,0.067
29.41,86.55,0.067
29.44,86.69,0.067
29.47,86.84,0.066
29.49,86.98,0.066
29.52,87.12,0.066
29.55,87.26,0.066
29.58,87.40,0.065
29.61,87.55,0.065
29.64,87.69,0.065
29.67,87.83,0.065
29.69,87.97,0.064
29.72,88.11,0.064
29.75,88.25,0.064
29.78,88.39,0.063
29.81,88.54,0.063
29.83,88.68,0.063
29.86,88.82,0.063
29.89,88.96,0.062
29.92,89.10,0.062
29.95,89.24,0.062
29.98,89.39,0.062
30.01,89.53,0.062
30.03,89.67,0.062
30.06,89.81,0.062
30.09,89.95,0.061
30.12,90.09,0.061
30.15,90.24,0.061
30.18,90.38,0.061
30.20,90.52,0.061
30.23,90.66,0.061
30.26,90.80,0.061
30.29,90.95,0.061
30.32,91.09,0.061
30.34,91.23,0.061
30.37,91.37,0.061
30.40,91.51,0.060
30.43,91.65,0.061
30.46,91.80,0.061
30.49,91.94,0.060
30.52,92.08,0.060
30.54,92.22,0.060
30.57,92.36,0.060
30.60,92.50,0.060
30.63,92.65,0.060
30.66,92.79,0.060
30.68,92.93,0.060
30.71,93.07,0.060
30.74,93.21,0.061
30.77,93.36,0.061
30.80,93.50,0.061
30.83,93.64,0.061
30.86,93.78,0.061
30.88,93.92,0.061
30.91,94.06,0.061
30.94,94.20,0.061
30.97,94.35,0.061
31.00,94.49,0.061
31.03,94.63,0.061
31.05,94.77,0.061
31.08,94.91,0.061
31.11,95.05,0.061
31.14,95.20,0.062
31.17,95.34,0.062
31.19,95.48,0.062
31.22,95.62,0.062
31.25,95.76,0.062
31.28,95.91,0.062
31.31,96.05,0.062
31.34,96.19,0.062
31.37,96.33,0.063
31.39,96.47,0.063
31.42,96.61,0.063
31.45,96.75,0.063
31.48,96.90,0.063
31.51,97.04,0.063
31.53,97.18,0.064
31.56,97.32,0.064
31.59,97.46,0.064
31.62,97.60,0.064
31.65,97.75,0.064
31.68,97.89,0.064
31.71,98.03,0.065
31.73,98.17,0.065
31.76,98.31,0.065
31.79,98.45,0.065
31.82,98.60,0.065
31.85,98.74,0.066
31.88,98.88,0.066
31.90,99.02,0.066
31.93,99.16,0.067
31.96,99.31,0.067
31.99,99.45,0.067
32.02,99.59,0.067
32.04,99.73,0.068
32.07,99.87,0.068
32.10,100.01,0.068
32.13,100.15,0.068
32.16,100.30,0.069
32.19,100.44,0.069
32.22,100.58,0.069
32.24,100.72,0.069
32.27,100.86,0.070
32.30,101.00,0.070
32.33,101.15,0.071
32.36,101.29,0.071
32.38,101.43,0.071
32.41,101.57,0.072
32.44,101.71,0.072
32.47,101.85,0.072
32.50,102.00,0.073
32.53,102.14,0.073
32.56,102.28,0.073
32.58,102.42,0.074
32.61,102.56,0.074
32.64,102.70,0.075
32.67,102.85,0.075
32.70,102.99,0.076
32.73,103.13,0.076
32.75,103.27,0.076
32.78,103.41,0.077
32.81,103.55,0.077
32.84,103.69,0.077
32.87,103.84,0.078
32.89,103.98,0.078
32.92,104.12,0.079
32.95,104.26,0.079
32.98,104.40,0.079
33.01,104.54,0.079
33.04,104.69,0.080
33.07,104.83,0.080
33.09,104.97,0.081
33.12,105.11,0.081
33.15,105.25,0.081
33.18,105.39,0.082
33.21,105.54,0.082
33.23,105.68,0.083
33.26,105.82,0.083
33.29,105.96,0.083
33.32,106.10,0.084
33.35,106.24,0.084
33.38,106.39,0.085
33.41,106.53,0.085
33.43,106.67,0.086
33.46,106.81,0.086
33.49,106.95,0.087
33.52,107.09,0.087
33.55,107.23,0.087
33.58,107.38,0.088
33.60,107.52,0.088
33.63,107.66,0.089
33.66,107.80,0.089
33.69,107.94,0.089
33.72,108.08,0.090
33.74,108.23,0.090
33.77,108.37,0.090
33.80,108.51,0.091
33.83,108.65,0.091
33.86,108.79,0.091
33.89,108.93,0.092
33.92,109.08,0.092
33.94,109.22,0.092
33.97,109.36,0.092
34.00,109.50,0.093
34.03,109.64,0.093
34.06,109.78,0.094
34.08,109.93,0.094
34.11,110.07,0.094
34.14,110.21,0.094
34.17,110.35,0.094
34.20,110.49,0.094
34.23,110.63,0.094
34.26,110.77,0.094
34.28,110.92,0.094
34.31,111.06,0.094
34.34,111.20,0.094
34.37,111.34,0.094
34.40,111.48,0.095
34.43,111.63,0.095
34.45,111.77,0.095
34.48,111.91,0.096
34.51,112.05,0.096
34.54,112.19,0.096
34.57,112.33,0.097
34.59,112.47,0.097
34.62,112.62,0.097
34.65,112.76,0.098
34.68,112.90,0.098
34.71,113.04,0.099
34.74,113.18,0.099
34.76,113.32,0.099
34.79,113.47,0.100
34.82,113.61,0.101
34.85,113.75,0.101
34.88,113.89,0.102
34.91,114.03,0.102
34.94,114.17,0.103
34.96,114.31,0.103
34.99,114.46,0.104
35.02,114.60,0.104
35.05,114.74,0.105
35.08,114.88,0.105
35.11,115.02,0.106
35.13,115.16,0.106
35.16,115.31,0.107
35.19,115.45,0.108
35.22,115.59,0.108
35.25,115.73,0.109
35.28,115.87,0.109
35.30,116.01,0.109
35.33,116.16,0.110
35.36,116.30,0.110
35.39,116.44,0.111
35.42,116.58,0.112
35.44,116.72,0.112
35.47,116.86,0.113
35.50,117.00,0.113
35.53,117.14,0.114
35.56,117.29,0.115
35.59,117.43,0.115
35.61,117.57,0.116
35.64,117.71,0.117
35.67,117.85,0.118
35.70,117.99,0.119
35.73,118.14,0.119
35.76,118.28,0.120
35.79,118.42,0.121
35.81,118.56,0.122
35.84,118.70,0.122
35.87,118.84,0.123
35.90,118.99,0.124
35.93,119.13,0.124
35.96,119.27,0.125
35.98,119.41,0.126
36.01,119.55,0.127
36.04,119.69,0.127
36.07,119.83,0.128
36.10,119.98,0.128
36.13,120.12,0.129
36.15,120.26,0.130
36.18,120.40,0.130
36.21,120.54,0.131
36.24,120.68,0.132
36.27,120.82,0.132
36.29,120.97,0.133
36.32,121.11,0.134
36.35,121.25,0.135
36.38,121.39,0.135
36.41,121.53,0.136
36.44,121.67,0.137
36.46,121.81,0.138
36.49,121.96,0.138
36.52,122.10,0.139
36.55,122.24,0.140
36.58,122.38,0.141
36.61,122.52,0.142
36.64,122.66,0.143
36.66,122.80,0.144
36.69,122.95,0.144
36.72,123.09,0.145
36.75,123.23,0.146
36.78,123.37,0.147
36.81,123.51,0.148
36.83,123.65,0.148
36.86,123.79,0.149
36.89,123.94,0.150
36.92,124.08,0.150
36.95,124.22,0.151
36.98,124.36,0.152
37.00,124.50,0.152
37.03,124.64,0.153
37.06,124.79,0.154
37.09,124.93,0.155
37.12,125.07,0.156
37.14,125.21,0.156
37.17,125.35,0.157
37.20,125.49,0.159
37.23,125.63,0.160
37.26,125.77,0.166
37.29,125.91,0.167
37.31,126.06,0.167
37.34,126.20,0.167
37.37,126.34,0.167
37.40,126.48,0.168
37.43,126.62,0.168
37.46,126.76,0.168
37.49,126.91,0.169
37.51,127.05,0.169
37.54,127.19,0.170
37.57,127.33,0.170
37.60,127.47,0.171
37.63,127.62,0.172
37.66,127.76,0.172
37.68,127.90,0.173
37.71,128.04,0.173
37.74,128.18,0.174
37.77,128.32,0.175
37.80,128.46,0.175
37.83,128.60,0.176
37.85,128.74,0.177
37.88,128.89,0.179
37.91,129.03,0.180
37.94,129.17,0.181
37.97,129.31,0.181
37.99,129.45,0.182
38.02,129.59,0.183
38.05,129.73,0.183
38.08,129.88,0.184
38.11,130.02,0.184
38.14,130.16,0.185
38.16,130.30,0.186
38.19,130.44,0.187
38.22,130.58,0.188
38.25,130.73,0.189
38.28,130.87,0.190
38.31,131.01,0.191
38.34,131.15,0.193
38.36,131.29,0.195
38.39,131.43,0.197
38.42,131.57,0.200
38.45,131.71,0.202
38.48,131.85,0.204
38.51,132.00,0.207
38.53,132.14,0.209
38.56,132.28,0.211
38.59,132.42,0.217
38.62,132.56,0.221
38.65,132.70,0.224
38.68,132.84,0.227
38.70,132.98,0.232
38.73,133.12,0.235
38.76,133.26,0.238
38.79,133.40,0.243
38.82,133.54,0.248
38.84,133.68,0.253
38.87,133.82,0.257
38.90,133.96,0.257
38.93,134.11,0.257
38.96,134.25,0.257
38.99,134.39,0.257
39.01,134.53,0.256
39.04,134.67,0.254
39.07,134.82,0.251
39.10,134.96,0.246
39.13,135.10,0.241
39.16,135.25,0.236
39.19,135.39,0.229
39.21,135.53,0.222
39.24,135.68,0.215
39.27,135.82,0.209
39.30,135.96,0.200
39.33,136.11,0.192
39.36,136.25,0.185
39.38,136.40,0.175
39.41,136.54,0.167
39.44,136.69,0.159
39.47,136.83,0.152
39.50,136.97,0.146
39.53,137.12,0.139
39.55,137.26,0.133
39.58,137.41,0.128
39.61,137.55,0.123
39.64,137.69,0.117
39.67,137.83,0.113
39.69,137.98,0.112
39.72,138.12,0.110
39.75,138.26,0.109
39.78,138.41,0.109
39.81,138.55,0.108
39.84,138.69,0.107
39.86,138.83,0.107
39.89,138.98,0.107
39.92,139.12,0.106
39.95,139.26,0.106
39.98,139.40,0.106
40.01,139.54,0.105
40.04,139.68,0.105
40.06,139.83,0.105
40.09,139.97,0.105
40.12,140.11,0.105
40.15,140.25,0.105
40.18,140.39,0.105
40.21,140.53,0.105
40.23,140.67,0.105
40.26,140.82,0.106
40.29,140.96,0.106
40.32,141.10,0.107
40.35,141.24,0.107
40.38,141.38,0.108
40.40,141.53,0.108
40.43,141.67,0.109
40.46,141.81,0.109
40.49,141.95,0.110
40.52,142.09,0.111
40.54,142.23,0.111
40.57,142.37,0.112
40.60,142.51,0.112
40.63,142.65,0.113
40.66,142.80,0.115
40.69,142.94,0.116
40.71,143.08,0.118
40.74,143.22,0.119
40.77,143.36,0.120
40.80,143.50,0.120
40.83,143.65,0.121
40.86,143.79,0.122
40.89,143.93,0.123
40.91,144.07,0.124
40.94,144.21,0.125
40.97,144.35,0.125
41.00,144.49,0.126
41.03,144.63,0.127
41.06,144.78,0.128
41.08,144.92,0.129
41.11,145.06,0.130
41.14,145.20,0.130
41.17,145.34,0.132
41.20,145.48,0.133
41.23,145.62,0.134
41.25,145.76,0.136
41.28,145.91,0.136
41.31,146.05,0.137
41.34,146.19,0.138
41.37,146.33,0.139
41.39,146.47,0.140
41.42,146.61,0.140
41.45,146.76,0.141
41.48,146.90,0.142
41.51,147.04,0.143
41.54,147.18,0.144
41.56,147.32,0.144
41.59,147.46,0.145
41.62,147.60,0.145
41.65,147.75,0.146
41.68,147.89,0.146
41.71,148.03,0.147
41.74,148.17,0.147
41.76,148.31,0.148
41.79,148.45,0.149
41.82,148.60,0.149
41.85,148.74,0.150
41.88,148.88,0.150
41.91,149.02,0.151
41.93,149.16,
41.96,149.30,
41.99,,

[step]
Ramp 10.00 °C/min to -60.00 °C
Time,Temperature,Heat Flow (Normalized)
min,°C,W/g
42.99,150.11,-0.010
43.00,150.11,-0.010
43.02,150.11,-0.011
43.03,150.10,-0.008
43.05,150.09,0.021
43.06,150.06,0.061
43.08,150.01,0.105
43.09,149.95,0.140
43.11,149.88,0.154
43.12,149.79,0.144
43.14,149.69,0.113
43.15,149.59,0.073
43.17,149.47,0.025
43.18,149.36,-0.019
43.20,149.24,-0.059
43.21,149.12,-0.093
43.23,149.00,-0.122
43.24,148.87,-0.148
43.26,148.74,-0.169
43.27,148.61,-0.189
43.29,148.47,-0.205
43.30,148.34,-0.223
43.32,148.20,-0.238
43.33,148.06,-0.250
43.35,147.92,-0.261
43.36,147.78,-0.273
43.38,147.64,-0.283
43.39,147.50,-0.289
43.41,147.36,-0.297
43.42,147.21,-0.305
43.44,147.07,-0.308
43.45,146.93,-0.315
43.47,146.78,-0.321
43.48,146.64,-0.323
43.50,146.49,-0.328
43.51,146.34,-0.334
43.53,146.20,-0.334
43.54,146.05,-0.337
43.56,145.91,-0.338
43.57,145.76,-0.342
43.59,145.61,-0.344
43.60,145.47,-0.347
43.62,145.32,-0.348
43.63,145.17,-0.349
43.65,145.02,-0.350
43.66,144.88,-0.351
43.68,144.73,-0.351
43.69,144.58,-0.353
43.71,144.43,-0.354
43.72,144.28,-0.356
43.74,144.14,-0.357
43.75,143.99,-0.358
43.77,143.84,-0.358
43.78,143.69,-0.358
43.80,143.54,-0.358
43.81,143.40,-0.359
43.83,143.25,-0.359
43.84,143.10,-0.360
43.86,142.95,-0.360
43.87,142.80,-0.361
43.89,142.65,-0.361
43.90,142.50,-0.362
43.92,142.35,-0.363
43.93,142.21,-0.364
43.95,142.06,-0.366
43.96,141.91,-0.366
43.98,141.76,-0.366
43.99,141.61,-0.366
44.01,141.46,-0.367
44.02,141.31,-0.367
44.04,141.16,-0.367
44.05,141.01,-0.368
44.07,140.86,-0.368
44.08,140.72,-0.368
44.10,140.57,-0.369
44.11,140.42,-0.369
44.13,140.27,-0.369
44.14,140.12,-0.369
44.16,139.97,-0.370
44.17,139.82,-0.370
44.19,139.67,-0.370
44.20,139.52,-0.370
44.22,139.37,-0.370
44.23,139.22,-0.370
44.25,139.07,-0.371
44.26,138.92,-0.371
44.28,138.77,-0.371
44.29,138.62,-0.371
44.31,138.47,-0.371
44.32,138.32,-0.372
44.34,138.17,-0.372
44.35,138.03,-0.372
44.37,137.87,-0.372
44.38,137.73,-0.373
44.40,137.58,-0.373
44.41,137.43,-0.373
44.43,137.28,-0.373
44.44,137.13,-0.373
44.46,136.98,-0.373
44.47,136.83,-0.373
44.49,136.68,-0.373
44.50,136.53,-0.373
44.52,136.38,-0.374
44.53,136.23,-0.374
44.55,136.08,-0.374
44.56,135.93,-0.374
44.58,135.78,-0.374
44.59,135.63,-0.374
44.61,135.48,-0.374
44.62,135.33,-0.374
44.64,135.18,-0.374
44.65,135.03,-0.374
44.67,134.88,-0.374
44.68,134.73,-0.374
44.70,134.58,-0.374
44.71,134.43,-0.374
44.73,134.28,-0.374
44.74,134.13,-0.374
44.76,133.98,-0.374
44.77,133.84,-0.374
44.79,133.68,-0.374
44.80,133.54,-0.374
44.82,133.39,-0.374
44.83,133.24,-0.374
44.85,133.09,-0.374
44.86,132.94,-0.374
44.88,132.79,-0.374
44.89,132.64,-0.374
44.91,132.49,-0.374
44.92,132.34,-0.374
44.94,132.19,-0.374
44.95,132.04,-0.374
44.97,131.89,-0.374
44.98,131.74,-0.374
45.00,131.59,-0.374
45.01,131.44,-0.374
45.03,131.29,-0.374
45.04,131.14,-0.374
45.06,130.99,-0.374
45.07,130.84,-0.374
45.09,130.69,-0.374
45.10,130.54,-0.374
45.12,130.39,-0.374
45.13,130.24,-0.374
45.15,130.09,-0.373
45.16,129.94,-0.373
45.18,129.79,-0.373
45.19,129.64,-0.373
45.21,129.49,-0.373
45.22,129.34,-0.373
45.24,129.19,-0.373
45.25,129.04,-0.373
45.27,128.89,-0.373
45.28,128.74,-0.373
45.30,128.59,-0.373
45.31,128.44,-0.373
45.33,128.29,-0.373
45.34,128.14,-0.373
45.36,127.99,-0.373
45.37,127.84,-0.373
45.39,127.69,-0.373
45.40,127.54,-0.373
45.42,127.39,-0.373
45.43,127.24,-0.373
45.45,127.09,-0.372
45.46,126.94,-0.372
45.48,126.80,-0.372
45.49,126.64,-0.372
45.51,126.50,-0.372
45.52,126.35,-0.372
45.54,126.20,-0.372
45.55,126.05,-0.371
45.57,125.90,-0.371
45.58,125.75,-0.371
45.60,125.60,-0.371
45.61,125.45,-0.371
45.63,125.30,-0.371
45.64,125.15,-0.370
45.66,125.00,-0.370
45.67,124.85,-0.370
45.69,124.70,-0.370
45.70,124.55,-0.370
45.72,124.40,-0.370
45.73,124.25,-0.370
45.75,124.10,-0.370
45.76,123.95,-0.370
45.78,123.80,-0.370
45.79,123.65,-0.369
45.81,123.50,-0.369
45.82,123.35,-0.369
45.84,123.20,-0.369
45.85,123.05,-0.369
45.87,122.90,-0.369
45.88,122.75,-0.369
45.90,122.60,-0.369
45.91,122.45,-0.369
45.93,122.30,-0.369
45.94,122.15,-0.369
45.96,122.00,-0.369
45.97,121.85,-0.369
45.99,121.70,-0.368
46.00,121.55,-0.368
46.02,121.40,-0.368
46.03,121.25,-0.368
46.05,121.10,-0.368
46.06,120.95,-0.368
46.08,120.80,-0.368
46.09,120.65,-0.367
46.11,120.50,-0.367
46.12,120.35,-0.367
46.14,120.20,-0.367
46.15,120.05,-0.366
46.17,119.90,-0.366
46.18,119.75,-0.366
46.20,119.60,-0.366
46.21,119.45,-0.366
46.23,119.30,-0.366
46.24,119.15,-0.366
46.26,119.00,-0.366
46.27,118.85,-0.366
46.29,118.70,-0.365
46.30,118.55,-0.365
46.32,118.40,-0.365
46.33,118.25,-0.365
46.35,118.10,-0.365
46.36,117.95,-0.365
46.38,117.80,-0.365
46.39,117.65,-0.365
46.41,117.50,-0.365
46.42,117.35,-0.364
46.44,117.20,-0.364
46.45,117.05,-0.364
46.47,116.90,-0.364
46.48,116.75,-0.364
46.50,116.60,-0.364
46.51,116.45,-0.364
46.53,116.31,-0.364
46.54,116.15,-0.363
46.56,116.01,-0.363
46.57,115.86,-0.363
46.59,115.71,-0.363
46.60,115.56,-0.363
46.62,115.41,-0.363
46.63,115.26,-0.363
46.65,115.11,-0.363
46.66,114.96,-0.362
46.68,114.81,-0.362
46.69,114.66,-0.362
46.71,114.51,-0.362
46.72,114.36,-0.362
46.74,114.21,-0.362
46.75,114.06,-0.362
46.77,113.91,-0.361
46.78,113.76,-0.361
46.80,113.61,-0.361
46.81,113.46,-0.361
46.83,113.31,-0.361
46.84,113.16,-0.361
46.86,113.01,-0.361
46.87,112.86,-0.361
46.89,112.71,-0.360
46.90,112.56,-0.360
46.92,112.41,-0.360
46.93,112.26,-0.360
46.95,112.11,-0.360
46.96,111.96,-0.360
46.98,111.81,-0.359
46.99,111.66,-0.359
47.01,111.51,-0.359
47.02,111.36,-0.359
47.04,111.21,-0.359
47.05,111.06,-0.359
47.07,110.91,-0.359
47.08,110.76,-0.358
47.10,110.61,-0.358
47.11,110.46,-0.358
47.13,110.31,-0.358
47.14,110.16,-0.358
47.16,110.01,-0.358
47.17,109.86,-0.358
47.19,109.71,-0.357
47.20,109.56,-0.357
47.22,109.41,-0.357
47.23,109.26,-0.357
47.25,109.11,-0.357
47.26,108.96,-0.356
47.28,108.81,-0.356
47.29,108.66,-0.356
47.31,108.51,-0.356
47.32,108.36,-0.356
47.34,108.21,-0.356
47.35,108.06,-0.356
47.37,107.91,-0.355
47.38,107.76,-0.355
47.40,107.61,-0.355
47.41,107.46,-0.355
47.43,107.31,-0.355
47.44,107.16,-0.355
47.46,107.01,-0.354
47.47,106.86,-0.354
47.49,106.71,-0.354
47.50,106.56,-0.354
47.52,106.41,-0.354
47.53,106.26,-0.354
47.55,106.11,-0.354
47.56,105.96,-0.353
47.58,105.81,-0.353
47.59,105.66,-0.353
47.61,105.51,-0.353
47.62,105.36,-0.353
47.64,105.21,-0.353
47.65,105.06,-0.352
47.67,104.91,-0.352
47.68,104.76,-0.352
47.70,104.62,-0.352
47.71,104.46,-0.352
47.73,104.32,-0.352
47.74,104.17,-0.351
47.76,104.02,-0.351
47.77,103.87,-0.351
47.79,103.72,-0.351
47.80,103.57,-0.351
47.82,103.42,-0.350
47.83,103.27,-0.350
47.85,103.12,-0.350
47.86,102.97,-0.350
47.88,102.82,-0.350
47.89,102.67,-0.350
47.91,102.52,-0.349
47.92,102.37,-0.349
47.94,102.22,-0.349
47.95,102.07,-0.349
47.97,101.92,-0.349
47.98,101.77,-0.348
48.00,101.62,-0.348
[...]
142.62,2.50,0.099
142.65,2.64,0.099
142.68,2.78,0.100
142.71,2.92,0.100
142.74,3.07,0.100
142.77,3.21,0.100
142.79,3.35,0.100
142.82,3.49,0.100
142.85,3.63,0.100
142.88,3.77,0.100
142.91,3.92,0.100
142.93,4.06,0.100
142.96,4.20,0.100
142.99,4.34,0.100
143.02,4.48,0.100
143.05,4.62,0.100
143.08,4.77,0.100
143.10,4.91,0.100
143.13,5.05,0.100
143.16,5.19,0.100
143.19,5.33,0.100
143.22,5.48,0.100
143.25,5.62,0.100
143.28,5.76,0.100
143.30,5.90,0.100
143.33,6.04,0.100
143.36,6.18,0.100
143.39,6.33,0.100
143.42,6.47,0.100
143.45,6.61,0.100
143.47,6.75,0.100
143.50,6.89,0.100
143.53,7.04,0.100
143.56,7.18,0.100
143.59,7.32,0.100
143.62,7.46,0.100
143.64,7.60,0.100
143.67,7.75,0.100
143.70,7.89,0.100
143.73,8.03,0.100
143.76,8.17,0.100
143.78,8.31,0.100
143.81,8.45,0.100
143.84,8.59,0.100
143.87,8.74,0.100
143.90,8.88,0.100
143.93,9.02,0.100
143.95,9.16,0.100
143.98,9.30,0.100
144.01,9.45,0.100
144.04,9.59,0.100
144.07,9.73,0.100
144.10,9.87,0.100
144.13,10.01,0.100
144.15,10.16,0.100
144.18,10.30,0.100
144.21,10.44,0.100
144.24,10.58,0.100
144.27,10.72,0.100
144.30,10.87,0.100
144.32,11.01,0.100
144.35,11.15,0.100
144.38,11.29,0.100
144.41,11.43,0.100
144.44,11.57,0.100
144.47,11.72,0.100
144.49,11.86,0.100
144.52,12.00,0.101
144.55,12.14,0.101
144.58,12.28,0.101
144.61,12.42,0.101
144.63,12.57,0.101
144.66,12.71,0.101
144.69,12.85,0.101
144.72,12.99,0.101
144.75,13.13,0.101
144.78,13.27,0.101
144.80,13.41,0.101
144.83,13.56,0.101
144.86,13.70,0.101
144.89,13.84,0.101
144.92,13.98,0.101
144.95,14.13,0.101
144.98,14.27,0.101
145.00,14.41,0.101
145.03,14.55,0.101
145.06,14.69,0.100
145.09,14.83,0.100
145.12,14.97,0.100
145.15,15.12,0.100
145.17,15.26,0.100
145.20,15.40,0.100
145.23,15.54,0.100
145.26,15.68,0.100
145.29,15.83,0.100
145.32,15.97,0.100
145.34,16.11,0.101
145.37,16.25,0.100
145.40,16.39,0.100
145.43,16.53,0.100
145.46,16.68,0.101
145.48,16.82,0.101
145.51,16.96,0.101
145.54,17.10,0.101
145.57,17.24,0.101
145.60,17.39,0.101
145.63,17.53,0.101
145.65,17.67,0.101
145.68,17.81,0.101
145.71,17.95,0.101
145.74,18.09,0.101
145.77,18.24,0.101
145.80,18.38,0.101
145.83,18.52,0.101
145.85,18.66,0.101
145.88,18.80,0.101
145.91,18.94,0.101
145.94,19.09,0.101
145.97,19.23,0.101
146.00,19.37,0.101
146.02,19.51,0.101
146.05,19.65,0.101
146.08,19.79,0.101
146.11,19.94,0.101
146.14,20.08,0.101
146.17,20.22,0.101
146.19,20.36,0.101
146.22,20.50,0.101
146.25,20.65,0.101
146.28,20.79,0.101
146.31,20.93,0.102
146.33,21.07,0.101
146.36,21.21,0.101
146.39,21.35,0.101
146.42,21.50,0.101
146.45,21.64,0.101
146.48,21.78,0.102
146.50,21.92,0.102
146.53,22.06,0.102
146.56,22.20,0.102
146.59,22.35,0.102
146.62,22.49,0.102
146.65,22.63,0.102
146.68,22.77,0.102
146.70,22.91,0.102
146.73,23.06,0.102
146.76,23.20,0.102
146.79,23.34,0.102
146.82,23.48,0.102
146.85,23.62,0.102
146.87,23.76,0.102
146.90,23.91,0.102
146.93,24.05,0.102
146.96,24.19,0.102
146.99,24.33,0.102
147.02,24.47,0.102
147.04,24.62,0.102
147.07,24.76,0.102
147.10,24.90,0.102
147.13,25.04,0.102
147.16,25.18,0.102
147.18,25.32,0.102
147.21,25.47,0.102
147.24,25.61,0.102
147.27,25.75,0.102
147.30,25.89,0.102
147.33,26.03,0.102
147.35,26.18,0.102
147.38,26.32,0.102
147.41,26.46,0.102
147.44,26.60,0.102
147.47,26.74,0.102
147.50,26.88,0.103
147.53,27.03,0.103
147.55,27.16,0.103
147.58,27.31,0.103
147.61,27.45,0.102
147.64,27.59,0.102
147.67,27.73,0.102
147.70,27.87,0.102
147.72,28.02,0.102
147.75,28.16,0.102
147.78,28.30,0.102
147.81,28.44,0.102
147.84,28.58,0.102
147.87,28.73,0.102
147.89,28.87,0.102
147.92,29.01,0.102
147.95,29.15,0.103
147.98,29.29,0.103
148.01,29.44,0.103
148.03,29.58,0.103
148.06,29.72,0.103
148.09,29.86,0.103
148.12,30.00,0.103
148.15,30.14,0.103
148.18,30.28,0.103
148.20,30.43,0.103
148.23,30.57,0.103
148.26,30.71,0.103
148.29,30.85,0.103
148.32,30.99,0.103
148.35,31.14,0.103
148.38,31.28,0.103
148.40,31.42,0.103
148.43,31.56,0.103
148.46,31.70,0.103
148.49,31.84,0.103
148.52,31.99,0.103
148.55,32.13,0.103
148.57,32.27,0.103
148.60,32.41,0.103
148.63,32.55,0.103
148.66,32.69,0.103
148.69,32.84,0.103
148.72,32.98,0.103
148.74,33.12,0.103
148.77,33.26,0.103
148.80,33.41,0.103
148.83,33.55,0.103
148.86,33.69,0.103
148.88,33.83,0.103
148.91,33.97,0.103
148.94,34.11,0.103
148.97,34.26,0.103
149.00,34.40,0.104
149.03,34.54,0.104
149.05,34.68,0.104
149.08,34.82,0.104
149.11,34.96,0.104
149.14,35.11,0.104
149.17,35.25,0.104
149.20,35.39,0.104
149.23,35.53,0.104
149.25,35.67,0.104
149.28,35.81,0.104
149.31,35.96,0.104
149.34,36.10,0.104
149.37,36.24,0.104
149.40,36.38,0.104
149.42,36.52,0.104
149.45,36.67,0.104
149.48,36.81,0.104
149.51,36.95,0.104
149.54,37.09,0.104
149.57,37.23,0.104
149.59,37.37,0.104
149.62,37.52,0.104
149.65,37.66,0.104
149.68,37.80,0.104
149.71,37.94,0.104
149.73,38.08,0.104
149.76,38.22,0.104
149.79,38.37,0.104
149.82,38.51,0.104
149.85,38.65,0.104
149.88,38.79,0.104
149.90,38.93,0.104
149.93,39.07,0.104
149.96,39.22,0.104
149.99,39.36,0.104
150.02,39.50,0.104
150.05,39.64,0.104
150.08,39.78,0.104
150.10,39.93,0.105
150.13,40.07,0.105
150.16,40.21,0.105
150.19,40.35,0.105
150.22,40.49,0.105
150.25,40.64,0.105
150.27,40.78,0.105
150.30,40.92,0.105
150.33,41.06,0.105
150.36,41.20,0.105
150.39,41.34,0.105
150.42,41.48,0.105
150.44,41.63,0.105
150.47,41.77,0.105
150.50,41.91,0.105
150.53,42.05,0.105
150.56,42.19,0.105
150.58,42.34,0.105
150.61,42.48,0.105
150.64,42.62,0.105
150.67,42.76,0.105
150.70,42.90,0.105
150.73,43.04,0.105
150.75,43.19,0.105
150.78,43.33,0.105
150.81,43.47,0.105
150.84,43.61,0.105
150.87,43.75,0.105
150.90,43.90,0.105
150.93,44.04,0.105
150.95,44.18,0.105
150.98,44.32,0.105
151.01,44.46,0.105
151.04,44.60,0.105
151.07,44.75,0.105
151.10,44.89,0.106
151.12,45.03,0.106
151.15,45.17,0.106
151.18,45.31,0.106
151.21,45.46,0.106
151.24,45.60,0.106
151.27,45.74,0.106
151.29,45.88,0.106
151.32,46.02,0.106
151.35,46.16,0.106
151.38,46.30,0.106
151.41,46.45,0.106
151.43,46.59,0.106
151.46,46.73,0.106
151.49,46.87,0.106
151.52,47.01,0.106
151.55,47.15,0.106
151.58,47.30,0.106
151.60,47.44,0.106
151.63,47.58,0.106
151.66,47.72,0.106
151.69,47.86,0.106
151.72,48.01,0.106
151.75,48.15,0.106
151.78,48.29,0.106
151.80,48.43,0.106
151.83,48.57,0.106
151.86,48.71,0.106
151.89,48.86,0.106
151.92,49.00,0.106
151.95,49.14,0.106
151.97,49.28,0.106
152.00,49.42,0.106
152.03,49.57,0.106
152.06,49.71,0.106
152.09,49.85,0.106
152.12,49.99,0.106
152.14,50.13,0.107
152.17,50.27,0.107
152.20,50.42,0.107
152.23,50.56,0.107
152.26,50.70,0.107
152.28,50.84,0.107
152.31,50.98,0.107
152.34,51.13,0.107
152.37,51.27,0.107
152.40,51.41,0.107
152.43,51.55,0.107
152.45,51.69,0.107
152.48,51.83,0.107
152.51,51.97,0.107
152.54,52.11,0.107
152.57,52.26,0.107
152.60,52.40,0.107
152.63,52.54,0.107
152.65,52.68,0.107
152.68,52.82,0.107
152.71,52.97,0.107
152.74,53.11,0.107
152.77,53.25,0.107
152.80,53.39,0.107
152.82,53.53,0.107
152.85,53.67,0.108
152.88,53.82,0.108
152.91,53.96,0.108
152.94,54.10,0.108
152.97,54.24,0.108
152.99,54.38,0.108
153.02,54.53,0.108
153.05,54.67,0.108
153.08,54.81,0.108
153.11,54.95,0.108
153.13,55.09,0.108
153.16,55.24,0.108
153.19,55.38,0.108
153.22,55.52,0.108
153.25,55.66,0.108
153.28,55.80,0.108
153.30,55.94,0.108
153.33,56.09,0.108
153.36,56.23,0.108
153.39,56.37,0.108
153.42,56.51,0.108
153.45,56.65,0.108
153.48,56.79,0.108
153.50,56.94,0.108
153.53,57.08,0.108
153.56,57.22,0.108
153.59,57.36,0.108
153.62,57.50,0.108
153.65,57.65,0.108
153.67,57.79,0.108
153.70,57.93,0.109
153.73,58.07,0.109
153.76,58.21,0.109
153.79,58.35,0.109
153.82,58.50,0.109
153.84,58.64,0.109
153.87,58.78,0.109
153.90,58.92,0.109
153.93,59.06,0.109
153.96,59.21,0.109
153.98,59.35,0.109
154.01,59.49,0.109
154.04,59.63,0.109
154.07,59.77,0.109
154.10,59.91,0.109
154.13,60.06,0.109
154.15,60.20,0.109
154.18,60.34,0.109
154.21,60.48,0.109
154.24,60.62,0.109
154.27,60.76,0.109
154.30,60.91,0.109
154.33,61.05,0.109
154.35,61.19,0.109
154.38,61.33,0.109
154.41,61.47,0.109
154.44,61.62,0.109
154.47,61.76,0.109
154.50,61.90,0.109
154.52,62.04,0.109
154.55,62.18,0.109
154.58,62.32,0.110
154.61,62.46,0.110
154.64,62.61,0.110
154.67,62.75,0.110
154.69,62.89,0.110
154.72,63.03,0.110
154.75,63.17,0.109
154.78,63.32,0.109
154.81,63.46,0.109
154.83,63.60,0.109
154.86,63.74,0.110
154.89,63.88,0.110
154.92,64.02,0.110
154.95,64.17,0.110
154.98,64.31,0.110
155.00,64.45,0.110
155.03,64.59,0.110
155.06,64.73,0.110
155.09,64.87,0.110
155.12,65.02,0.110
155.15,65.16,0.110
155.18,65.30,0.110
155.20,65.44,0.110
155.23,65.58,0.110
155.26,65.73,0.110
155.29,65.87,0.110
155.32,66.01,0.110
155.35,66.15,0.110
155.37,66.29,0.110
155.40,66.43,0.110
155.43,66.58,0.110
155.46,66.72,0.110
155.49,66.86,0.110
155.52,67.00,0.110
155.54,67.14,0.111
155.57,67.28,0.111
155.60,67.43,0.111
155.63,67.57,0.111
155.66,67.71,0.111
155.68,67.85,0.111
155.71,67.99,0.111
155.74,68.14,0.111
155.77,68.28,0.111
155.80,68.42,0.111
155.83,68.56,0.111
155.85,68.70,0.111
155.88,68.84,0.111
155.91,68.99,0.111
155.94,69.13,0.111
155.97,69.27,0.111
156.00,69.41,0.111
156.03,69.55,0.111
156.05,69.69,0.111
156.08,69.84,0.111
156.11,69.98,0.111
156.14,70.12,0.111
156.17,70.26,0.111
156.20,70.40,0.111
156.22,70.54,0.111
156.25,70.69,0.111
156.28,70.83,0.111
156.31,70.97,0.112
156.34,71.11,0.112
156.37,71.25,0.112
156.39,71.39,0.112
156.42,71.54,0.112
156.45,71.68,0.112
156.48,71.82,0.112
156.51,71.96,0.112
156.53,72.10,0.112
156.56,72.25,0.112
156.59,72.39,0.112
156.62,72.53,0.112
156.65,72.67,0.112
156.68,72.81,0.112
156.70,72.95,0.112
156.73,73.10,0.112
156.76,73.24,0.112
156.79,73.38,0.112
156.82,73.52,0.112
156.85,73.66,0.113
156.88,73.80,0.113
156.90,73.95,0.113
156.93,74.09,0.112
156.96,74.23,0.113
156.99,74.37,0.113
157.02,74.51,0.113
157.05,74.65,0.113
157.07,74.80,0.113
157.10,74.94,0.113
157.13,75.08,0.113
157.16,75.22,0.113
157.19,75.36,0.113
157.22,75.51,0.113
157.24,75.65,0.113
157.27,75.79,0.113
157.30,75.93,0.113
157.33,76.07,0.113
157.36,76.21,0.113
157.38,76.36,0.114
157.41,76.50,0.114
157.44,76.64,0.114
157.47,76.78,0.114
157.50,76.92,0.113
157.53,77.06,0.113
157.55,77.21,0.114
157.58,77.35,0.114
157.61,77.49,0.114
157.64,77.63,0.114
157.67,77.77,0.114
157.70,77.91,0.114
157.73,78.06,0.114
157.75,78.20,0.114
157.78,78.34,0.114
157.81,78.48,0.114
157.84,78.62,0.114
157.87,78.76,0.114
157.90,78.91,0.114
157.92,79.05,0.114
157.95,79.19,0.114
157.98,79.33,0.114
158.01,79.47,0.114
158.04,79.61,0.114
158.07,79.76,0.115
158.09,79.90,0.115
158.12,80.04,0.115
158.15,80.18,0.115
158.18,80.32,0.115
158.21,80.47,0.115
158.23,80.61,0.115
158.26,80.75,0.115
158.29,80.89,0.115
158.32,81.03,0.114
158.35,81.18,0.115
158.38,81.32,0.115
158.40,81.46,0.115
158.43,81.60,0.115
158.46,81.74,0.115
158.49,81.89,0.115
158.52,82.03,0.115
158.55,82.17,0.115
158.58,82.31,0.115
158.60,82.45,0.115
158.63,82.59,0.115
158.66,82.73,0.115
158.69,82.88,0.115
158.72,83.02,0.115
158.75,83.16,0.115
158.77,83.30,0.115
158.80,83.44,0.115
158.83,83.59,0.115
158.86,83.73,0.115
158.89,83.87,0.115
158.92,84.01,0.115
158.94,84.15,0.115
158.97,84.29,0.115
159.00,84.43,0.115
159.03,84.58,0.115
159.06,84.72,0.115
159.08,84.86,0.115
159.11,85.00,0.115
159.14,85.14,0.115
159.17,85.28,0.115
159.20,85.43,0.115
159.23,85.57,0.115
159.25,85.71,0.115
159.28,85.85,0.115
159.31,85.99,0.115
159.34,86.14,0.115
159.37,86.28,0.115
159.40,86.42,0.115
159.43,86.56,0.115
159.45,86.70,0.115
159.48,86.84,0.115
159.51,86.98,0.116
159.54,87.13,0.115
159.57,87.27,0.115
159.60,87.41,0.115
159.62,87.55,0.116
159.65,87.69,0.116
159.68,87.84,0.116
159.71,87.98,0.116
159.74,88.12,0.116
159.77,88.26,0.116
159.79,88.40,0.116
159.82,88.54,0.116
159.85,88.69,0.116
159.88,88.83,0.116
159.91,88.97,0.116
159.93,89.11,0.116
159.96,89.25,0.116
159.99,89.40,0.116
160.02,89.54,0.116
160.05,89.68,0.116
160.08,89.82,0.117
160.10,89.96,0.117
160.13,90.10,0.117
160.16,90.24,0.117
160.19,90.39,0.116
160.22,90.53,0.116
160.25,90.67,0.116
160.28,90.81,0.117
160.30,90.95,0.117
160.33,91.10,0.117
160.36,91.24,0.117
160.39,91.38,0.117
160.42,91.52,0.117
160.45,91.66,0.117
160.47,91.80,0.117
160.50,91.94,0.117
160.53,92.09,0.117
160.56,92.23,0.117
160.59,92.37,0.117
160.62,92.51,0.117
160.64,92.65,0.117
160.67,92.80,0.117
160.70,92.94,0.117
160.73,93.08,0.117
160.76,93.22,0.118
160.78,93.36,0.118
160.81,93.50,0.118
160.84,93.65,0.118
160.87,93.79,0.118
160.90,93.93,0.118
160.93,94.07,0.118
160.95,94.21,0.118
160.98,94.35,0.118
161.01,94.50,0.118
161.04,94.64,0.118
161.07,94.78,0.118
161.10,94.92,0.118
161.13,95.06,0.118
161.15,95.20,0.118
161.18,95.35,0.118
161.21,95.49,0.118
161.24,95.63,0.119
161.27,95.77,0.119
161.30,95.91,0.119
161.32,96.06,0.119
161.35,96.20,0.119
161.38,96.34,0.119
161.41,96.48,0.119
161.44,96.62,0.119
161.47,96.76,0.119
161.49,96.91,0.119
161.52,97.05,0.119
161.55,97.19,0.119
161.58,97.33,0.119
161.61,97.47,0.119
161.63,97.61,0.119
161.66,97.76,0.119
161.69,97.90,0.119
161.72,98.04,0.119
161.75,98.18,0.119
161.78,98.32,0.119
161.80,98.47,0.119
161.83,98.61,0.120
161.86,98.75,0.120
161.89,98.89,0.120
161.92,99.03,0.120
161.95,99.17,0.120
161.98,99.31,0.120
162.00,99.46,0.120
162.03,99.60,0.120
162.06,99.74,0.120
162.09,99.88,0.120
162.12,100.02,0.120
162.15,100.17,0.120
162.17,100.31,0.120
162.20,100.45,0.120
162.23,100.59,0.120
162.26,100.73,0.120
162.29,100.87,0.120
162.32,101.02,0.120
162.34,101.16,0.120
162.37,101.30,0.120
162.40,101.44,0.120
162.43,101.58,0.120
162.46,101.72,0.120
162.48,101.87,0.121
162.51,102.01,0.121
162.54,102.15,0.121
162.57,102.29,0.121
162.60,102.43,0.121
162.63,102.57,0.121
162.65,102.72,0.121
162.68,102.86,0.121
162.71,103.00,0.121
162.74,103.14,0.121
162.77,103.28,0.121
162.80,103.43,0.121
162.83,103.57,0.121
162.85,103.71,0.121
162.88,103.85,0.121
162.91,103.99,0.121
162.94,104.13,0.121
162.97,104.28,0.121
163.00,104.42,0.121
163.02,104.56,0.121
163.05,104.70,0.121
163.08,104.84,0.122
163.11,104.98,0.122
163.14,105.12,0.122
163.17,105.27,0.122
163.19,105.41,0.122
163.22,105.55,0.122
163.25,105.69,0.122
163.28,105.83,0.122
163.31,105.98,0.122
163.33,106.12,0.122
163.36,106.26,0.122
163.39,106.40,0.122
163.42,106.54,0.122
163.45,106.68,0.122
163.48,106.82,0.122
163.50,106.97,0.122
163.53,107.11,0.122
163.56,107.25,0.122
163.59,107.39,0.122
163.62,107.53,0.122
163.65,107.68,0.122
163.68,107.82,0.122
163.70,107.96,0.122
163.73,108.10,0.122
163.76,108.24,0.122
163.79,108.38,0.123
163.82,108.53,0.123
163.85,108.67,0.123
163.87,108.81,0.123
163.90,108.95,0.123
163.93,109.09,0.122
163.96,109.24,0.123
163.99,109.38,0.123
164.02,109.52,0.123
164.04,109.66,0.123
164.07,109.80,0.123
164.10,109.94,0.123
164.13,110.08,0.123
164.16,110.23,0.123
164.18,110.37,0.123
164.21,110.51,0.123
164.24,110.65,0.123
164.27,110.80,0.123
164.30,110.94,0.123
164.33,111.08,0.124
164.35,111.22,0.124
164.38,111.36,0.124
164.41,111.50,0.124
164.44,111.65,0.124
164.47,111.79,0.124
164.50,111.93,0.124
164.53,112.07,0.124
164.55,112.21,0.124
164.58,112.35,0.124
164.61,112.49,0.124
164.64,112.64,0.124
164.67,112.78,0.124
164.70,112.92,0.124
164.72,113.06,0.124
164.75,113.20,0.124
164.78,113.34,0.124
164.81,113.49,0.124
164.84,113.63,0.124
164.87,113.77,0.124
164.89,113.91,0.124
164.92,114.06,0.124
164.95,114.20,0.124
164.98,114.34,0.125
165.01,114.48,0.125
165.03,114.62,0.125
165.06,114.77,0.125
165.09,114.91,0.125
165.12,115.05,0.125
165.15,115.19,0.125
165.18,115.33,0.125
165.20,115.47,0.125
165.23,115.61,0.125
165.26,115.75,0.125
165.29,115.90,0.125
165.32,116.04,0.125
165.35,116.18,0.125
165.38,116.32,0.125
165.40,116.46,0.125
165.43,116.60,0.125
165.46,116.75,0.125
165.49,116.89,0.125
165.52,117.03,0.125
165.55,117.17,0.125
165.57,117.31,0.125
165.60,117.45,0.125
165.63,117.60,0.125
165.66,117.74,0.125
165.69,117.88,0.125
165.72,118.02,0.125
165.74,118.16,0.125
165.77,118.31,0.125
165.80,118.45,0.126
165.83,118.59,0.126
165.86,118.73,0.126
165.88,118.87,0.126
165.91,119.01,0.126
165.94,119.15,0.126
165.97,119.30,0.126
166.00,119.44,0.126
166.03,119.58,0.126
166.05,119.72,0.126
166.08,119.86,0.126
166.11,120.01,0.126
166.14,120.15,0.126
166.17,120.29,0.126
166.20,120.43,0.126
166.23,120.57,0.126
166.25,120.71,0.126
166.28,120.86,0.126
166.31,121.00,0.127
166.34,121.14,0.127
166.37,121.28,0.127
166.40,121.42,0.127
166.42,121.57,0.127
166.45,121.71,0.127
166.48,121.85,0.127
166.51,121.99,0.127
166.54,122.13,0.127
166.57,122.27,0.127
166.59,122.42,0.127
166.62,122.56,0.127
166.65,122.70,0.127
166.68,122.84,0.127
166.71,122.98,0.127
166.73,123.12,0.127
166.76,123.27,0.127
166.79,123.41,0.128
166.82,123.55,0.128
166.85,123.69,0.128
166.88,123.83,0.128
166.90,123.97,0.128
166.93,124.12,0.128
166.96,124.26,0.128
166.99,124.40,0.128
167.02,124.54,0.128
167.05,124.68,0.128
167.08,124.82,0.128
167.10,124.97,0.128
167.13,125.11,0.128
167.16,125.25,0.128
167.19,125.39,0.128
167.22,125.53,0.128
167.25,125.67,0.128
167.27,125.81,0.129
167.30,125.96,0.129
167.33,126.10,0.129
167.36,126.24,0.129
167.39,126.38,0.129
167.42,126.52,0.129
167.44,126.67,0.129
167.47,126.81,0.129
167.50,126.95,0.129
167.53,127.09,0.129
167.56,127.23,0.129
167.58,127.38,0.129
167.61,127.52,0.130
167.64,127.66,0.130
167.67,127.80,0.130
167.70,127.94,0.130
167.73,128.08,0.130
167.75,128.22,0.130
167.78,128.36,0.130
167.81,128.51,0.130
167.84,128.65,0.131
167.87,128.79,0.131
167.90,128.93,0.132
167.93,129.07,0.132
167.95,129.21,0.132
167.98,129.36,0.133
168.01,129.50,0.133
168.04,129.64,0.133
168.07,129.78,0.133
168.10,129.92,0.133
168.12,130.07,0.133
168.15,130.21,0.133
168.18,130.35,0.133
168.21,130.49,0.133
168.24,130.63,0.133
168.27,130.77,0.133
168.29,130.92,0.133
168.32,131.06,0.133
168.35,131.20,0.133
168.38,131.34,0.133
168.41,131.48,0.133
168.43,131.63,0.133
168.46,131.77,0.133
168.49,131.91,0.133
168.52,132.05,0.133
168.55,132.19,0.132
168.58,132.33,0.132
168.60,132.48,0.132
168.63,132.62,0.132
168.66,132.76,0.132
168.69,132.90,0.132
168.72,133.04,0.132
168.75,133.18,0.132
168.78,133.33,0.132
168.80,133.47,0.132
168.83,133.61,0.132
168.86,133.75,0.132
168.89,133.89,0.132
168.92,134.03,0.132
168.95,134.18,0.132
168.97,134.32,0.132
169.00,134.46,0.132
169.03,134.60,0.132
169.06,134.74,0.132
169.09,134.89,0.132
169.12,135.03,0.132
169.14,135.17,0.132
169.17,135.31,0.132
169.20,135.45,0.132
169.23,135.59,0.132
169.26,135.74,0.133
169.28,135.88,0.133
169.31,136.02,0.133
169.34,136.16,0.133
169.37,136.30,0.133
169.40,136.44,0.133
169.43,136.59,0.133
169.45,136.73,0.133
169.48,136.87,0.133
169.51,137.01,0.133
169.54,137.15,0.133
169.57,137.29,0.133
169.60,137.44,0.134
169.63,137.58,0.134
169.65,137.72,0.134
169.68,137.86,0.134
169.71,138.00,0.134
169.74,138.14,0.134
169.77,138.28,0.134
169.80,138.43,0.134
169.82,138.57,0.134
169.85,138.71,0.135
169.88,138.85,0.135
169.91,138.99,0.138
169.94,139.13,0.141
169.97,139.27,0.142
169.99,139.42,0.142
170.02,139.56,0.142
170.05,139.70,0.142
170.08,139.84,0.142
170.11,139.98,0.142
170.13,140.13,0.141
170.16,140.27,0.141
170.19,140.41,0.140
170.22,140.55,0.140
170.25,140.69,0.139
170.28,140.83,0.139
170.30,140.98,0.139
170.33,141.12,0.138
170.36,141.26,0.138
170.39,141.40,0.138
170.42,141.54,0.137
170.45,141.69,0.137
170.48,141.83,0.137
170.50,141.97,0.137
170.53,142.11,0.137
170.56,142.25,0.136
170.59,142.39,0.136
170.62,142.53,0.136
170.65,142.68,0.136
170.67,142.82,0.136
170.70,142.96,0.136
170.73,143.10,0.136
170.76,143.24,0.137
170.79,143.39,0.137
170.82,143.53,0.137
170.84,143.67,0.138
170.87,143.81,0.138
170.90,143.95,0.138
170.93,144.09,0.138
170.96,144.24,0.139
170.98,144.38,0.139
171.01,144.52,0.139
171.04,144.66,0.139
171.07,144.80,0.139
171.10,144.94,0.139
171.13,145.09,0.139
171.15,145.23,0.139
171.18,145.37,0.139
171.21,145.51,0.139
171.24,145.65,0.139
171.27,145.80,0.139
171.30,145.94,0.139
171.33,146.08,0.139
171.35,146.22,0.139
171.38,146.36,0.139
171.41,146.50,0.139
171.44,146.65,0.140
171.47,146.79,0.140
171.50,146.93,0.140
171.52,147.07,0.140
171.55,147.21,0.140
171.58,147.35,0.140
171.61,147.49,0.140
171.64,147.64,0.141
171.67,147.78,0.141
171.69,147.92,0.142
171.72,148.06,0.142
171.75,148.20,0.142
171.78,148.34,0.142
171.81,148.49,0.143
171.83,148.63,0.144
171.86,148.77,0.144
171.89,148.91,0.144
171.92,149.05,0.145
171.95,149.19,
171.98,,
171.98,,