File: DSC/2025_07_16_Adamantane_n90_30C_10Cmin_x4.csv
Filename,2025_07_16_Adamantane_n90_30C_10Cmin_x4
Instrument name,DSC2A-00468 (192.168.1.100)
Operator,Gibbons
rundate,7/16/2025
Sample name,2025_07_16_Adamantane_n90_30C_10Cmin_x4
proceduresegments,Data Off ; Equilibrate -90.00 °C; Data On ; Ramp 10.00 °C/min to 30.00 °C; Data Off ; Isothermal 2.0 min; Data On ; Ramp 10.00 °C/min to -90.00 °C; Data Off ; Isothermal 2.0 min; Data On ; Ramp 10.00 °C/min to 30.00 °C; Data Off ; Isothermal 2.0 min; Data On ; Ramp 10.00 °C/min to -90.00 °C; Data Off ; Isothermal 2.0 min; Data On ; Ramp 10.00 °C/min to 30.00 °C; Data Off ; Isothermal 2.0 min; Data On ; Ramp 10.00 °C/min to -90.00 °C; Data Off ; Isothermal 2.0 min; Data On ; Ramp 10.00 °C/min to 30.00 °C
[File Parameters]
Run date,7/16/2025 2:24:06 PM
Trios version,5.1.1.46572
Original File Name,
Current File Name,D:\DSC2500\Gibbons\2025_07_16_Adamantane_n90_30C_10Cmin_x4.tri
[Procedure]
Procedure Name,Adamantane_n90_30C_10Cmin_x4
Sample Name,2025_07_16_Adamantane_n90_30C_10Cmin_x4
Sample Mass,9.51 mg
Reference Sample Mass,0 mg
Pan Mass,56.36 mg
Pan Number,3
Reference Pan Mass,56.6 mg
Reference Pan Number,1
Pan Type,Tzero Aluminum Hermetic
Comments,DSC Consumables Al Hermetically Sealed Pan. Y1 Tray (Google Sheet: DSC_Samples_Y1_Tray_June2025).
Project Name,Pharmaceuticals - Cannabinoids
Operator,Gibbons
Test,Custom
Unload Max Temperature,30
Unload Min Temperature,30
Load Max Temperature,30
Load Min Temperature,30
Stop on Gas Flow Error,Yes
[Signal List]
Signal #1,Time (min)
Signal #2,Temperature (°C)
Signal #3,Heat Flow (mW)
Signal #4,Delta T (µV)
Signal #5,Delta Tzero (µV)
Signal #6,Tzero Temperature (°C)
Signal #7,Cell Purge (mL/min)
Signal #8,Heater Temp (°C)
Signal #9,Power Delivered (W)
Signal #10,Reference Junction Temperature (°C)
Signal #11,Flange Temperature (°C)
Signal #12,Heat Flow Phase (rad)
Signal #13,Total Heat Capacity (J/°C)
Signal #14,Heat Capacity (J/°C)
[Configuration]
Company Name,ASU
Instrument Name,DSC2A-00468
Instrument Type,DSC2500
Serial Number,DSC2A-00468
IP,192.168.1.100
Location of Instrument,MRRC
DisplayType,Unknown
Sample Interval ,0.1 s/pt
Selected Heat Flow,T4P
Exotherm Direction,Down
Cell Serial,DRC2-00792
Lid Type,Standard
Cooler,RCS 90
Leave Cooler on at End of Sequence,On
Gas 2,Nitrogen
Gas Selected,Channel 1
Flow Rate,50 mL/min
Secondary Purge,On
Licensed Heat Flow,Heat Flow T4P
Modulation Licensed,Yes
[Versions]
Common IDD Version,1
Cortex Version,VER 2.10.2.31
Driver,5.0.0.6
GDM Version,1.0.3.3
TouchscreenVersion,1.0.0.16145
FEP Version,1.2.1.21
FEP Bootloader,2.0.0.5
AutoSampler Version,2.1.1.26
Auto Sampler Bootloader,2.0.0.5
FCM Version,1.1.0.3
FCM Bootloader,2.0.0.5
[Experiment Logs]
Experiment Log Entry # 1,Air Cool is off.
Experiment Log Entry # 3,Data On set to 0
Experiment Log Entry # 5,Equilibrate Segment -90 (C) Started
Experiment Log Entry # 7,Data On set to 1
Experiment Log Entry # 9,Ramp Segment 10 C/min to 30 Started
Experiment Log Entry # 11,Data On set to 0
Experiment Log Entry # 13,Isothermal Segment 2 min started
Experiment Log Entry # 15,Data On set to 1
Experiment Log Entry # 17,Ramp Segment 10 C/min to -90 Started
Experiment Log Entry # 19,Data On set to 0
Experiment Log Entry # 21,Isothermal Segment 2 min started
Experiment Log Entry # 23,Data On set to 1
Experiment Log Entry # 25,Ramp Segment 10 C/min to 30 Started
Experiment Log Entry # 27,Data On set to 0
Experiment Log Entry # 29,Isothermal Segment 2 min started
Experiment Log Entry # 31,Data On set to 1
Experiment Log Entry # 33,Ramp Segment 10 C/min to -90 Started
Experiment Log Entry # 35,Data On set to 0
Experiment Log Entry # 37,Isothermal Segment 2 min started
Experiment Log Entry # 39,Data On set to 1
Experiment Log Entry # 41,Ramp Segment 10 C/min to 30 Started
Experiment Log Entry # 43,Data On set to 0
Experiment Log Entry # 45,Isothermal Segment 2 min started
Experiment Log Entry # 47,Data On set to 1
Experiment Log Entry # 49,Ramp Segment 10 C/min to -90 Started
Experiment Log Entry # 51,Data On set to 0
Experiment Log Entry # 53,Isothermal Segment 2 min started
Experiment Log Entry # 55,Data On set to 1
Experiment Log Entry # 57,Ramp Segment 10 C/min to 30 Started
[Method Log]
Method Log Entry # 1,Data Off
Method Log Entry # 2,Equilibrate -90 °C
Method Log Entry # 3,Data On
Method Log Entry # 4,(Ramp 29418) Ramp 10 °C/minute to 30 °C
Method Log Entry # 5,Data Off
Method Log Entry # 6,Isothermal 2 minutes
Method Log Entry # 7,Data On
Method Log Entry # 8,(Ramp 29422) Ramp 10 °C/minute to -90 °C
Method Log Entry # 9,Data Off
Method Log Entry # 10,Isothermal 2 minutes
Method Log Entry # 11,Data On
Method Log Entry # 12,(Ramp 29426) Ramp 10 °C/minute to 30 °C
Method Log Entry # 13,Data Off
Method Log Entry # 14,Isothermal 2 minutes
Method Log Entry # 15,Data On
Method Log Entry # 16,(Ramp 29430) Ramp 10 °C/minute to -90 °C
Method Log Entry # 17,Data Off
Method Log Entry # 18,Isothermal 2 minutes
Method Log Entry # 19,Data On
Method Log Entry # 20,(Ramp 29434) Ramp 10 °C/minute to 30 °C
Method Log Entry # 21,Data Off
Method Log Entry # 22,Isothermal 2 minutes
Method Log Entry # 23,Data On
Method Log Entry # 24,(Ramp 29438) Ramp 10 °C/minute to -90 °C
Method Log Entry # 25,Data Off
Method Log Entry # 26,Isothermal 2 minutes
Method Log Entry # 27,Data On
Method Log Entry # 28,(Ramp 29442) Ramp 10 °C/minute to 30 °C
Cell Serial,DRC2-00792
[T1 Calibration]
Slope,-0.008529666
Offset,9.636258
Initial Temperature,98.23
GUID,f8bfdadc-4977-4fdf-ba6d-0ba9134940c3
[TZero Calibration]
Date Applied,11/29/2022 4:06:13 PM
Description,From -89.059 °C to 396.009 °C at 20.000°C/min
Gas Type,Nitrogen
Pan Type,None
Source Files 1,C:\Users\yargerlab\Desktop\DSC Data\General\TZero_calibration_11_29_22_2nd(2).tri
Source Files 2,C:\Users\yargerlab\Desktop\DSC Data\General\TZero_calibration_11_29_22_2nd(3).tri
Delta T Offset,13.05235
Delta T Slope,-0.007271007
Delta T0 Offset,-13.69128
Delta T0 Slope,0.06063341
[Temperature Calibration]
Date Applied,11/29/2022 7:12:28 PM
Description,From 106.590 °C to 186.590 °C at 10.000°C/min
Gas Type,Nitrogen
Pan Type,Tzero Aluminum Hermetic
Source Files 1,C:\Users\yargerlab\Desktop\DSC Data\General\Indium(6).tri
Measured 1,157.391
Known 1,156.598
[Cell Constant Calibration]
Date Applied,11/29/2022 7:12:29 PM
Description,From 106.590 °C to 186.590 °C at 10.000°C/min
Gas Type,Nitrogen
Pan Type,Tzero Aluminum Hermetic
Source Files 1,C:\Users\yargerlab\Desktop\DSC Data\General\Indium(6).tri
T4P KCell,1.006051
Onset Slope,63.26126 mW/°C
[Direct Cp Calibration]
Date Applied,11/30/2022 11:04:51 AM
Description,From -79.983 °C to 298.409 °C at 10.000°C/min
Gas Type,Nitrogen
Pan Type,Tzero Aluminum Hermetic
Source Files 1,C:\Users\yargerlab\Desktop\DSC Data\General\Sapphire_Heat_Capacity_11_30_22.tri
[Rev Cp Calibration]
Date Applied,11/30/2022 1:58:51 PM
Description,From -79.996 °C to 292.812 °C at 3.000°C/min
Gas Type,Nitrogen
Pan Type,Tzero Aluminum Hermetic
Source Files 1,C:\Users\yargerlab\Desktop\DSC Data\General\Sapphire_MDSC_Calibration_11_30_22.tri
[step]
Ramp 10.00 °C/min to 30.00 °C
Time,Temperature,Heat Flow (Normalized)
min,°C,W/g
0.00,-89.91,-0.027
0.01,-89.91,-0.027
0.02,-89.92,-0.025
0.03,-89.92,-0.024
0.03,-89.93,-0.023
0.04,-89.93,-0.022
0.05,-89.92,-0.020
0.06,-89.92,-0.018
0.07,-89.92,-0.017
0.08,-89.91,-0.016
0.08,-89.90,-0.014
0.09,-89.88,-0.012
0.10,-89.86,-0.009
0.11,-89.83,-0.005
0.12,-89.80,-0.002
0.13,-89.76,0.003
0.13,-89.72,0.010
0.14,-89.68,0.015
0.15,-89.64,0.020
0.16,-89.59,0.027
0.17,-89.53,0.034
0.18,-89.48,0.041
0.18,-89.43,0.047
0.19,-89.37,0.053
0.20,-89.31,0.059
0.21,-89.25,0.064
0.22,-89.19,0.069
0.23,-89.13,0.074
0.23,-89.06,0.079
0.24,-89.00,0.083
0.25,-88.94,0.086
0.26,-88.87,0.090
0.27,-88.80,0.094
0.28,-88.73,0.098
0.28,-88.66,0.101
0.29,-88.59,0.104
0.30,-88.52,0.106
0.31,-88.45,0.110
0.32,-88.38,0.113
0.33,-88.30,0.115
0.33,-88.23,0.117
0.34,-88.15,0.120
0.35,-88.08,0.121
0.36,-88.01,0.124
0.37,-87.93,0.126
0.38,-87.85,0.128
0.38,-87.78,0.130
0.39,-87.70,0.131
0.40,-87.62,0.132
0.41,-87.55,0.133
0.42,-87.47,0.134
0.43,-87.39,0.136
0.43,-87.31,0.137
0.44,-87.23,0.139
0.45,-87.15,0.139
0.46,-87.08,0.139
0.47,-87.00,0.141
0.48,-86.92,0.143
0.48,-86.84,0.143
0.49,-86.76,0.143
0.50,-86.68,0.144
0.51,-86.60,0.145
0.52,-86.52,0.145
0.53,-86.44,0.145
0.53,-86.36,0.146
0.54,-86.28,0.147
0.55,-86.20,0.147
0.56,-86.12,0.147
0.57,-86.04,0.148
0.58,-85.96,0.149
0.58,-85.87,0.149
0.59,-85.79,0.149
0.60,-85.71,0.150
0.61,-85.63,0.150
0.62,-85.55,0.150
0.63,-85.47,0.150
0.63,-85.39,0.151
0.64,-85.31,0.151
0.65,-85.22,0.151
0.66,-85.14,0.151
0.67,-85.06,0.152
0.68,-84.98,0.152
0.68,-84.90,0.152
0.69,-84.82,0.152
0.70,-84.73,0.152
0.71,-84.65,0.152
0.72,-84.57,0.153
0.73,-84.49,0.153
0.73,-84.41,0.153
0.74,-84.32,0.153
0.75,-84.24,0.154
0.76,-84.16,0.154
0.77,-84.08,0.154
0.78,-84.00,0.154
0.78,-83.91,0.154
0.79,-83.83,0.155
0.80,-83.75,0.155
0.81,-83.67,0.155
0.82,-83.58,0.155
0.83,-83.50,0.155
0.83,-83.42,0.155
0.84,-83.34,0.155
0.85,-83.26,0.155
0.86,-83.17,0.155
0.87,-83.09,0.156
0.88,-83.01,0.156
0.88,-82.92,0.156
0.89,-82.84,0.156
0.90,-82.76,0.156
0.91,-82.68,0.156
0.92,-82.60,0.156
0.93,-82.51,0.156
0.93,-82.43,0.156
0.94,-82.35,0.156
0.95,-82.26,0.156
0.96,-82.18,0.156
0.97,-82.10,0.156
0.98,-82.02,0.157
0.98,-81.93,0.157
0.99,-81.85,0.157
1.00,-81.77,0.157
1.01,-81.69,0.157
1.02,-81.60,0.157
1.03,-81.52,0.157
1.03,-81.44,0.157
1.04,-81.35,0.157
1.05,-81.27,0.157
1.06,-81.19,0.157
1.07,-81.11,0.158
1.08,-81.02,0.158
1.08,-80.94,0.158
1.09,-80.86,0.158
1.10,-80.78,0.158
1.11,-80.69,0.158
1.12,-80.61,0.158
1.13,-80.53,0.158
1.13,-80.44,0.159
1.14,-80.36,0.159
1.15,-80.28,0.159
1.16,-80.19,0.159
1.17,-80.11,0.159
1.18,-80.03,0.159
1.18,-79.94,0.159
1.19,-79.86,0.159
1.20,-79.78,0.159
1.21,-79.70,0.159
1.22,-79.61,0.159
1.23,-79.53,0.159
1.23,-79.45,0.160
1.24,-79.37,0.160
1.25,-79.28,0.160
1.26,-79.20,0.160
1.27,-79.11,0.160
1.28,-79.03,0.160
1.28,-78.95,0.160
1.29,-78.87,0.160
1.30,-78.78,0.160
1.31,-78.70,0.160
1.32,-78.62,0.161
1.33,-78.53,0.161
1.33,-78.45,0.161
1.34,-78.37,0.161
1.35,-78.28,0.161
1.36,-78.20,0.161
1.37,-78.12,0.161
1.38,-78.03,0.161
1.38,-77.95,0.161
1.39,-77.87,0.161
1.40,-77.78,0.161
1.41,-77.70,0.161
1.42,-77.62,0.161
1.43,-77.54,0.161
1.43,-77.45,0.161
1.44,-77.37,0.161
1.45,-77.29,0.162
1.46,-77.20,0.162
1.47,-77.12,0.162
1.48,-77.04,0.162
1.48,-76.95,0.162
1.49,-76.87,0.162
1.50,-76.79,0.162
1.51,-76.70,0.162
1.52,-76.62,0.162
1.53,-76.54,0.162
1.53,-76.45,0.163
1.54,-76.37,0.163
1.55,-76.29,0.163
1.56,-76.21,0.163
1.57,-76.12,0.163
1.58,-76.04,0.163
1.58,-75.96,0.163
1.59,-75.87,0.164
1.60,-75.79,0.164
1.61,-75.71,0.164
1.62,-75.62,0.164
1.63,-75.54,0.164
1.63,-75.46,0.164
1.64,-75.37,0.164
1.65,-75.29,0.164
1.66,-75.21,0.164
1.67,-75.12,0.164
1.68,-75.04,0.164
1.68,-74.96,0.164
1.69,-74.87,0.164
1.70,-74.79,0.164
1.71,-74.71,0.165
1.72,-74.62,0.165
1.73,-74.54,0.165
1.73,-74.46,0.165
1.74,-74.37,0.165
1.75,-74.29,0.165
1.76,-74.21,0.165
1.77,-74.12,0.165
1.78,-74.04,0.165
1.78,-73.96,0.165
1.79,-73.87,0.165
1.80,-73.79,0.166
1.81,-73.71,0.166
1.82,-73.62,0.166
1.83,-73.54,0.166
1.83,-73.46,0.166
1.84,-73.37,0.166
1.85,-73.29,0.166
1.86,-73.21,0.166
1.87,-73.12,0.167
1.88,-73.04,0.167
1.88,-72.96,0.167
1.89,-72.87,0.167
1.90,-72.79,0.167
1.91,-72.71,0.167
1.92,-72.63,0.167
1.93,-72.54,0.167
1.93,-72.46,0.168
1.94,-72.38,0.168
1.95,-72.29,0.168
1.96,-72.21,0.168
1.97,-72.12,0.168
1.98,-72.04,0.169
1.98,-71.96,0.169
1.99,-71.88,0.169
2.00,-71.80,0.170
2.01,-71.71,0.170
2.02,-71.63,0.170
2.03,-71.54,0.170
2.03,-71.46,0.170
2.04,-71.38,0.170
2.05,-71.29,0.170
2.06,-71.21,0.171
2.07,-71.13,0.171
2.08,-71.05,0.171
2.08,-70.96,0.171
2.09,-70.88,0.172
2.10,-70.80,0.172
2.11,-70.71,0.172
2.12,-70.63,0.172
2.13,-70.55,0.173
2.13,-70.46,0.173
2.14,-70.38,0.173
2.15,-70.30,0.173
2.16,-70.21,0.174
2.17,-70.13,0.174
2.18,-70.05,0.174
2.18,-69.96,0.174
2.19,-69.88,0.175
2.20,-69.80,0.176
2.21,-69.72,0.176
2.22,-69.63,0.177
2.23,-69.55,0.177
2.23,-69.46,0.178
2.24,-69.38,0.179
2.25,-69.30,0.179
2.26,-69.22,0.180
2.27,-69.14,0.180
2.28,-69.05,0.181
2.28,-68.97,0.181
2.29,-68.89,0.182
2.30,-68.80,0.183
2.31,-68.72,0.185
2.32,-68.64,0.186
2.33,-68.55,0.186
2.33,-68.47,0.188
2.34,-68.39,0.189
2.35,-68.31,0.191
2.36,-68.22,0.192
2.37,-68.14,0.194
2.38,-68.06,0.195
2.38,-67.98,0.197
2.39,-67.89,0.199
2.40,-67.81,0.202
2.41,-67.73,0.204
2.42,-67.65,0.206
2.43,-67.57,0.209
2.43,-67.49,0.213
2.44,-67.40,0.216
2.45,-67.32,0.218
2.46,-67.24,0.223
2.47,-67.16,0.228
2.48,-67.08,0.233
2.48,-67.00,0.239
2.49,-66.92,0.247
2.50,-66.84,0.256
2.51,-66.76,0.267
2.52,-66.68,0.280
2.53,-66.61,0.298
2.53,-66.53,0.321
2.54,-66.46,0.351
2.55,-66.39,0.384
2.56,-66.32,0.420
2.57,-66.25,0.452
2.58,-66.18,0.484
2.58,-66.12,0.512
2.59,-66.06,0.538
2.60,-65.99,0.562
2.61,-65.93,0.582
2.62,-65.86,0.600
2.63,-65.80,0.618
2.63,-65.73,0.634
2.64,-65.66,0.652
2.65,-65.60,0.667
2.66,-65.53,0.681
2.67,-65.46,0.695
2.68,-65.40,0.707
2.68,-65.33,0.719
2.69,-65.26,0.731
2.70,-65.19,0.743
2.71,-65.12,0.752
2.72,-65.05,0.760
2.73,-64.97,0.771
2.73,-64.90,0.781
2.74,-64.83,0.790
2.75,-64.76,0.803
2.76,-64.69,0.812
2.77,-64.61,0.820
2.78,-64.54,0.828
2.78,-64.47,0.835
2.79,-64.39,0.840
2.80,-64.32,0.846
2.81,-64.24,0.851
2.82,-64.17,0.855
2.83,-64.09,0.858
2.83,-64.01,0.860
2.84,-63.93,0.862
2.85,-63.86,0.862
2.86,-63.78,0.859
2.87,-63.70,0.857
2.88,-63.62,0.855
2.88,-63.54,0.853
2.89,-63.45,0.850
2.90,-63.37,0.846
2.91,-63.29,0.842
2.92,-63.21,0.839
2.93,-63.12,0.835
2.93,-63.04,0.828
2.94,-62.95,0.822
2.95,-62.87,0.815
2.96,-62.78,0.809
2.97,-62.70,0.802
2.98,-62.61,0.794
2.98,-62.52,0.785
2.99,-62.43,0.775
3.00,-62.35,0.763
3.01,-62.26,0.750
3.02,-62.17,0.736
3.03,-62.08,0.721
3.03,-61.99,0.707
3.04,-61.90,0.689
3.05,-61.80,0.671
3.06,-61.71,0.653
3.07,-61.61,0.633
3.08,-61.52,0.612
3.08,-61.43,0.592
3.09,-61.33,0.573
3.10,-61.23,0.551
3.11,-61.14,0.532
3.12,-61.04,0.506
3.13,-60.94,0.479
3.13,-60.84,0.452
3.14,-60.74,0.426
3.15,-60.64,0.405
3.16,-60.54,0.385
3.17,-60.44,0.367
3.18,-60.34,0.350
3.18,-60.24,0.336
3.19,-60.14,0.322
3.20,-60.04,0.310
3.21,-59.94,0.299
3.22,-59.84,0.289
3.23,-59.75,0.280
3.23,-59.65,0.272
3.24,-59.55,0.265
3.25,-59.46,0.258
3.26,-59.37,0.252
3.27,-59.27,0.246
3.28,-59.18,0.240
3.28,-59.09,0.235
3.29,-59.00,0.230
3.30,-58.91,0.227
3.31,-58.82,0.224
3.32,-58.72,0.219
3.33,-58.64,0.216
3.33,-58.55,0.213
3.34,-58.46,0.210
3.35,-58.37,0.207
3.36,-58.28,0.205
3.37,-58.20,0.202
3.38,-58.11,0.201
3.38,-58.02,0.199
3.39,-57.93,0.196
3.40,-57.84,0.195
3.41,-57.76,0.194
3.42,-57.67,0.192
3.43,-57.58,0.191
3.43,-57.50,0.189
3.44,-57.41,0.188
3.45,-57.33,0.187
3.46,-57.24,0.187
3.47,-57.15,0.185
3.48,-57.07,0.185
3.48,-56.99,0.184
3.49,-56.90,0.182
3.50,-56.81,0.182
3.51,-56.73,0.182
3.52,-56.64,0.182
3.53,-56.56,0.181
3.53,-56.48,0.181
3.54,-56.39,0.180
3.55,-56.30,0.180
3.56,-56.22,0.179
3.57,-56.14,0.179
3.58,-56.05,0.179
3.58,-55.97,0.178
3.59,-55.88,0.178
3.60,-55.80,0.178
3.61,-55.72,0.177
3.62,-55.63,0.177
3.63,-55.55,0.177
3.63,-55.46,0.177
3.64,-55.38,0.177
3.65,-55.30,0.176
3.66,-55.21,0.176
3.67,-55.13,0.176
3.68,-55.04,0.176
3.68,-54.96,0.176
3.69,-54.88,0.176
3.70,-54.79,0.176
3.71,-54.71,0.176
3.72,-54.63,0.175
3.73,-54.54,0.175
3.73,-54.46,0.175
3.74,-54.38,0.175
3.75,-54.29,0.175
3.76,-54.21,0.175
3.77,-54.13,0.175
3.78,-54.04,0.175
3.78,-53.96,0.175
3.79,-53.87,0.175
3.80,-53.79,0.175
3.81,-53.71,0.175
3.82,-53.62,0.175
3.83,-53.54,0.175
3.83,-53.45,0.175
3.84,-53.37,0.175
3.85,-53.29,0.174
3.86,-53.20,0.174
3.87,-53.12,0.174
3.88,-53.04,0.174
3.88,-52.95,0.174
3.89,-52.87,0.174
3.90,-52.79,0.174
3.91,-52.70,0.174
3.92,-52.62,0.174
3.93,-52.54,0.174
3.93,-52.45,0.174
3.94,-52.37,0.174
3.95,-52.28,0.174
3.96,-52.20,0.174
3.97,-52.12,0.174
3.98,-52.04,0.174
3.98,-51.95,0.174
3.99,-51.87,0.174
4.00,-51.78,0.174
4.01,-51.70,0.174
4.02,-51.62,0.174
4.03,-51.53,0.174
4.03,-51.45,0.174
4.04,-51.37,0.174
4.05,-51.28,0.174
4.06,-51.20,0.174
4.07,-51.12,0.174
4.08,-51.03,0.174
4.08,-50.95,0.174
4.09,-50.87,0.174
4.10,-50.78,0.174
4.11,-50.70,0.174
4.12,-50.62,0.174
4.13,-50.53,0.174
4.13,-50.45,0.174
4.14,-50.37,0.174
4.15,-50.28,0.174
4.16,-50.20,0.174
4.17,-50.12,0.174
4.18,-50.03,0.174
4.18,-49.95,0.174
4.19,-49.87,0.174
4.20,-49.78,0.174
4.21,-49.70,0.174
4.22,-49.62,0.174
4.23,-49.54,0.174
4.23,-49.45,0.174
4.24,-49.37,0.174
4.25,-49.29,0.174
4.26,-49.20,0.174
4.27,-49.12,0.174
4.28,-49.03,0.174
4.28,-48.95,0.174
4.29,-48.87,0.174
4.30,-48.79,0.174
4.31,-48.70,0.174
4.32,-48.62,0.174
4.33,-48.54,0.174
4.33,-48.45,0.174
4.34,-48.37,0.174
4.35,-48.29,0.175
4.36,-48.20,0.175
4.37,-48.12,0.175
4.38,-48.04,0.175
4.38,-47.95,0.175
4.39,-47.87,0.175
4.40,-47.78,0.175
4.41,-47.70,0.175
4.42,-47.62,0.175
4.43,-47.53,0.175
4.43,-47.45,0.175
4.44,-47.37,0.175
4.45,-47.28,0.175
4.46,-47.20,0.175
4.47,-47.12,0.175
4.48,-47.03,0.175
4.48,-46.95,0.175
4.49,-46.87,0.175
4.50,-46.78,0.176
4.51,-46.70,0.176
4.52,-46.61,0.176
4.53,-46.53,0.176
4.53,-46.45,0.176
4.54,-46.36,0.176
4.55,-46.28,0.176
4.56,-46.20,0.176
4.57,-46.11,0.176
4.58,-46.03,0.176
4.58,-45.95,0.176
4.59,-45.86,0.176
4.60,-45.78,0.176
4.61,-45.70,0.176
4.62,-45.61,0.176
4.63,-45.53,0.176
4.63,-45.44,0.176
4.64,-45.36,0.176
4.65,-45.28,0.177
4.66,-45.19,0.177
4.67,-45.11,0.177
4.68,-45.03,0.177
4.68,-44.94,0.177
4.69,-44.86,0.177
4.70,-44.77,0.177
4.71,-44.69,0.177
4.72,-44.61,0.177
4.73,-44.52,0.177
4.73,-44.44,0.177
4.74,-44.35,0.177
4.75,-44.27,0.177
4.76,-44.19,0.178
4.77,-44.10,0.178
4.78,-44.02,0.178
4.78,-43.93,0.178
4.79,-43.85,0.178
4.80,-43.77,0.178
4.81,-43.68,0.178
4.82,-43.60,0.178
4.83,-43.52,0.178
4.83,-43.43,0.178
4.84,-43.35,0.178
4.85,-43.26,0.178
4.86,-43.18,0.178
4.87,-43.10,0.178
4.88,-43.02,0.178
4.88,-42.93,0.178
4.89,-42.85,0.178
4.90,-42.77,0.178
4.91,-42.68,0.178
4.92,-42.60,0.178
4.93,-42.51,0.178
4.93,-42.43,0.178
4.94,-42.35,0.178
4.95,-42.26,0.179
4.96,-42.18,0.179
4.97,-42.10,0.179
4.98,-42.02,0.179
4.98,-41.93,0.179
4.99,-41.85,0.179
5.00,-41.76,0.179
5.01,-41.68,0.179
5.02,-41.60,0.179
5.03,-41.51,0.179
5.03,-41.43,0.179
5.04,-41.35,0.179
5.05,-41.26,0.179
5.06,-41.18,0.179
5.07,-41.10,0.179
5.08,-41.01,0.179
5.08,-40.93,0.179
5.09,-40.85,0.179
5.10,-40.76,0.179
5.11,-40.68,0.179
5.12,-40.60,0.179
5.13,-40.51,0.179
5.13,-40.43,0.179
5.14,-40.35,0.179
5.15,-40.26,0.179
5.16,-40.18,0.180
5.17,-40.10,0.180
5.18,-40.01,0.180
5.18,-39.93,0.180
5.19,-39.84,0.180
5.20,-39.76,0.180
5.21,-39.68,0.180
5.22,-39.59,0.180
5.23,-39.51,0.180
5.23,-39.43,0.180
5.24,-39.34,0.180
5.25,-39.26,0.180
5.26,-39.18,0.180
5.27,-39.09,0.180
5.28,-39.01,0.180
5.28,-38.93,0.180
5.29,-38.84,0.180
5.30,-38.76,0.180
5.31,-38.68,0.180
5.32,-38.59,0.180
5.33,-38.51,0.180
5.33,-38.43,0.180
5.34,-38.34,0.180
5.35,-38.26,0.180
5.36,-38.18,0.181
5.37,-38.09,0.181
5.38,-38.01,0.181
5.38,-37.92,0.181
5.39,-37.84,0.181
5.40,-37.76,0.181
5.41,-37.67,0.181
5.42,-37.59,0.181
5.43,-37.51,0.181
5.43,-37.42,0.181
5.44,-37.34,0.181
5.45,-37.26,0.181
5.46,-37.18,0.181
5.47,-37.09,0.181
5.48,-37.01,0.181
5.48,-36.92,0.181
5.49,-36.84,0.181
5.50,-36.76,0.181
5.51,-36.67,0.181
5.52,-36.59,0.181
5.53,-36.51,0.181
5.53,-36.42,0.181
5.54,-36.34,0.182
5.55,-36.26,0.182
5.56,-36.17,0.182
5.57,-36.09,0.182
5.58,-36.01,0.182
5.58,-35.92,0.182
5.59,-35.84,0.182
5.60,-35.76,0.182
5.61,-35.67,0.182
5.62,-35.59,0.182
5.63,-35.51,0.182
5.63,-35.42,0.182
5.64,-35.34,0.182
5.65,-35.25,0.182
5.66,-35.17,0.182
5.67,-35.09,0.182
5.68,-35.01,0.182
5.68,-34.92,0.182
5.69,-34.84,0.182
5.70,-34.75,0.182
5.71,-34.67,0.183
5.72,-34.59,0.183
5.73,-34.50,0.183
5.73,-34.42,0.183
5.74,-34.34,0.183
5.75,-34.25,0.183
5.76,-34.17,0.183
5.77,-34.09,0.183
5.78,-34.00,0.183
5.78,-33.92,0.183
5.79,-33.84,0.183
5.80,-33.75,0.183
5.81,-33.67,0.183
5.82,-33.59,0.183
5.83,-33.50,0.183
5.83,-33.42,0.183
5.84,-33.34,0.183
5.85,-33.25,0.183
5.86,-33.17,0.184
5.87,-33.09,0.184
5.88,-33.00,0.184
5.88,-32.92,0.184
5.89,-32.84,0.184
5.90,-32.75,0.184
5.91,-32.67,0.184
5.92,-32.58,0.184
5.93,-32.50,0.184
5.93,-32.42,0.184
5.94,-32.34,0.184
5.95,-32.25,0.184
5.96,-32.17,0.184
5.97,-32.08,0.184
5.98,-32.00,0.184
5.98,-31.92,0.184
5.99,-31.83,0.184
6.00,-31.75,0.184
6.01,-31.67,0.184
6.02,-31.58,0.184
6.03,-31.50,0.185
6.03,-31.42,0.185
6.04,-31.33,0.185
6.05,-31.25,0.185
6.06,-31.17,0.185
6.07,-31.08,0.185
6.08,-31.00,0.185
6.08,-30.92,0.185
6.09,-30.83,0.185
6.10,-30.75,0.185
6.11,-30.66,0.185
6.12,-30.58,0.185
6.13,-30.50,0.185
6.13,-30.42,0.185
6.14,-30.33,0.185
6.15,-30.25,0.185
6.16,-30.16,0.185
6.17,-30.08,0.185
6.18,-30.00,0.185
6.18,-29.91,0.185
6.19,-29.83,0.186
6.20,-29.75,0.186
6.21,-29.66,0.186
6.22,-29.58,0.186
6.23,-29.50,0.186
6.23,-29.41,0.186
6.24,-29.33,0.186
6.25,-29.25,0.186
6.26,-29.16,0.186
6.27,-29.08,0.186
6.28,-29.00,0.186
6.28,-28.91,0.186
6.29,-28.83,0.186
6.30,-28.75,0.186
6.31,-28.66,0.186
6.32,-28.58,0.186
6.33,-28.49,0.186
6.33,-28.41,0.187
6.34,-28.33,0.187
6.35,-28.25,0.187
6.36,-28.16,0.187
6.37,-28.08,0.187
6.38,-28.00,0.187
6.38,-27.91,0.187
6.39,-27.83,0.187
6.40,-27.75,0.187
6.41,-27.66,0.187
6.42,-27.58,0.187
6.43,-27.49,0.187
6.43,-27.41,0.187
6.44,-27.33,0.187
6.45,-27.24,0.187
6.46,-27.16,0.187
6.47,-27.08,0.187
6.48,-26.99,0.187
6.48,-26.91,0.187
6.49,-26.83,0.187
6.50,-26.74,0.187
6.51,-26.66,0.188
6.52,-26.58,0.188
6.53,-26.49,0.188
6.53,-26.41,0.188
6.54,-26.33,0.188
6.55,-26.24,0.188
6.56,-26.16,0.188
6.57,-26.08,0.188
6.58,-25.99,0.188
6.58,-25.91,0.188
6.59,-25.83,0.188
6.60,-25.74,0.188
6.61,-25.66,0.188
6.62,-25.57,0.188
6.63,-25.49,0.188
6.63,-25.41,0.188
6.64,-25.32,0.188
6.65,-25.24,0.188
6.66,-25.16,0.188
6.67,-25.07,0.188
6.68,-24.99,0.188
6.68,-24.91,0.189
6.69,-24.82,0.189
6.70,-24.74,0.189
6.71,-24.66,0.189
6.72,-24.57,0.189
6.73,-24.49,0.189
6.73,-24.41,0.189
6.74,-24.32,0.189
6.75,-24.24,0.189
6.76,-24.16,0.189
6.77,-24.07,0.189
6.78,-23.99,0.189
6.78,-23.91,0.189
6.79,-23.82,0.189
6.80,-23.74,0.189
6.81,-23.66,0.189
6.82,-23.57,0.189
6.83,-23.49,0.189
6.83,-23.41,0.189
6.84,-23.32,0.189
6.85,-23.24,0.189
6.86,-23.16,0.190
6.87,-23.07,0.190
6.88,-22.99,0.190
6.88,-22.91,0.190
6.89,-22.82,0.190
6.90,-22.74,0.190
6.91,-22.65,0.190
6.92,-22.57,0.190
6.93,-22.49,0.190
6.93,-22.40,0.190
6.94,-22.32,0.190
6.95,-22.24,0.190
6.96,-22.15,0.190
6.97,-22.07,0.190
6.98,-21.99,0.190
6.98,-21.90,0.190
6.99,-21.82,0.190
7.00,-21.74,0.191
7.01,-21.65,0.191
7.02,-21.57,0.191
7.03,-21.49,0.191
7.03,-21.40,0.191
7.04,-21.32,0.191
7.05,-21.24,0.191
7.06,-21.15,0.191
7.07,-21.07,0.191
7.08,-20.99,0.191
7.08,-20.90,0.191
7.09,-20.82,0.191
7.10,-20.73,0.191
7.11,-20.65,0.191
7.12,-20.57,0.191
7.13,-20.49,0.191
7.13,-20.40,0.191
7.14,-20.32,0.191
7.15,-20.24,0.191
7.16,-20.15,0.192
7.17,-20.07,0.192
7.18,-19.98,0.192
7.18,-19.90,0.192
7.19,-19.82,0.192
7.20,-19.73,0.192
7.21,-19.65,0.192
7.22,-19.57,0.192
7.23,-19.48,0.192
7.23,-19.40,0.192
7.24,-19.32,0.192
7.25,-19.23,0.192
7.26,-19.15,0.192
7.27,-19.07,0.192
7.28,-18.98,0.192
7.28,-18.90,0.192
7.29,-18.82,0.192
7.30,-18.73,0.192
7.31,-18.65,0.193
7.32,-18.57,0.193
7.33,-18.48,0.193
7.33,-18.40,0.193
7.34,-18.32,0.193
7.35,-18.23,0.193
7.36,-18.15,0.193
7.37,-18.07,0.193
7.38,-17.98,0.193
7.38,-17.90,0.193
7.39,-17.82,0.193
7.40,-17.73,0.193
7.41,-17.65,0.193
7.42,-17.57,0.193
7.43,-17.48,0.193
7.43,-17.40,0.193
7.44,-17.31,0.193
7.45,-17.23,0.194
7.46,-17.15,0.194
7.47,-17.06,0.194
7.48,-16.98,0.194
7.48,-16.90,0.194
7.49,-16.81,0.194
7.50,-16.73,0.194
7.51,-16.65,0.194
7.52,-16.56,0.194
7.53,-16.48,0.194
7.53,-16.40,0.194
7.54,-16.31,0.194
7.55,-16.23,0.194
7.56,-16.15,0.194
7.57,-16.06,0.194
7.58,-15.98,0.195
7.58,-15.90,0.195
7.59,-15.81,0.195
7.60,-15.73,0.195
7.61,-15.64,0.195
7.62,-15.56,0.195
7.63,-15.48,0.195
7.63,-15.39,0.195
7.64,-15.31,0.195
7.65,-15.23,0.195
7.66,-15.14,0.195
7.67,-15.06,0.195
7.68,-14.98,0.195
7.68,-14.90,0.195
7.69,-14.81,0.195
7.70,-14.73,0.195
7.71,-14.65,0.195
7.72,-14.56,0.195
7.73,-14.48,0.195
7.73,-14.39,0.195
7.74,-14.31,0.196
7.75,-14.23,0.196
7.76,-14.14,0.196
7.77,-14.06,0.196
7.78,-13.98,0.196
7.78,-13.89,0.196
7.79,-13.81,0.196
7.80,-13.73,0.196
7.81,-13.64,0.196
7.82,-13.56,0.196
7.83,-13.48,0.196
7.83,-13.39,0.196
7.84,-13.31,0.196
7.85,-13.23,0.196
7.86,-13.14,0.196
7.87,-13.06,0.196
7.88,-12.98,0.196
7.88,-12.89,0.196
7.89,-12.81,0.197
7.90,-12.73,0.197
7.91,-12.64,0.197
7.92,-12.56,0.197
7.93,-12.48,0.197
7.93,-12.39,0.197
7.94,-12.31,0.197
7.95,-12.23,0.197
7.96,-12.14,0.197
7.97,-12.06,0.197
7.98,-11.97,0.197
7.98,-11.89,0.197
7.99,-11.81,0.197
8.00,-11.73,0.197
8.01,-11.64,0.197
8.02,-11.56,0.197
8.03,-11.47,0.197
8.03,-11.39,0.198
8.04,-11.31,0.198
8.05,-11.22,0.198
8.06,-11.14,0.198
8.07,-11.06,0.198
8.08,-10.97,0.198
8.08,-10.89,0.198
8.09,-10.81,0.198
8.10,-10.72,0.198
8.11,-10.64,0.198
8.12,-10.56,0.198
8.13,-10.47,0.198
8.13,-10.39,0.198
8.14,-10.31,0.198
8.15,-10.22,0.198
8.16,-10.14,0.198
8.17,-10.06,0.198
8.18,-9.97,0.198
8.18,-9.89,0.199
8.19,-9.81,0.199
8.20,-9.72,0.199
8.21,-9.64,0.199
8.22,-9.56,0.199
8.23,-9.47,0.199
8.23,-9.39,0.199
8.24,-9.31,0.199
8.25,-9.22,0.199
8.26,-9.14,0.199
8.27,-9.06,0.199
8.28,-8.97,0.199
8.28,-8.89,0.199
8.29,-8.81,0.199
8.30,-8.72,0.199
8.31,-8.64,0.199
8.32,-8.56,0.199
8.33,-8.47,0.200
8.33,-8.39,0.200
8.34,-8.31,0.200
8.35,-8.22,0.200
8.36,-8.14,0.200
8.37,-8.06,0.200
8.38,-7.97,0.200
8.38,-7.89,0.200
8.39,-7.81,0.200
8.40,-7.72,0.200
8.41,-7.64,0.200
8.42,-7.56,0.200
8.43,-7.47,0.200
8.43,-7.39,0.200
8.44,-7.30,0.200
8.45,-7.22,0.201
8.46,-7.14,0.201
8.47,-7.06,0.201
8.48,-6.97,0.201
8.48,-6.89,0.201
8.49,-6.80,0.201
8.50,-6.72,0.201
8.51,-6.64,0.201
8.52,-6.55,0.201
8.53,-6.47,0.201
8.53,-6.39,0.201
8.54,-6.30,0.201
8.55,-6.22,0.201
8.56,-6.14,0.201
8.57,-6.05,0.201
8.58,-5.97,0.201
8.58,-5.89,0.202
8.59,-5.80,0.202
8.60,-5.72,0.202
8.61,-5.64,0.202
8.62,-5.55,0.202
8.63,-5.47,0.202
8.63,-5.39,0.202
8.64,-5.30,0.202
8.65,-5.22,0.202
8.66,-5.14,0.202
8.67,-5.05,0.202
8.68,-4.97,0.202
8.68,-4.88,0.202
8.69,-4.80,0.202
8.70,-4.72,0.202
8.71,-4.63,0.203
8.72,-4.55,0.203
8.73,-4.47,0.203
8.73,-4.38,0.203
8.74,-4.30,0.203
8.75,-4.22,0.203
8.76,-4.13,0.203
8.77,-4.05,0.203
8.78,-3.97,0.203
8.78,-3.88,0.203
8.79,-3.80,0.203
8.80,-3.72,0.203
8.81,-3.63,0.203
8.82,-3.55,0.204
8.83,-3.47,0.204
8.83,-3.38,0.204
8.84,-3.30,0.204
8.85,-3.22,0.204
8.86,-3.13,0.204
8.87,-3.05,0.204
8.88,-2.97,0.204
8.88,-2.88,0.204
8.89,-2.80,0.204
8.90,-2.72,0.204
8.91,-2.63,0.204
8.92,-2.55,0.204
8.93,-2.47,0.204
8.93,-2.38,0.205
8.94,-2.30,0.205
8.95,-2.22,0.205
8.96,-2.13,0.205
8.97,-2.05,0.205
8.98,-1.96,0.205
8.98,-1.88,0.205
8.99,-1.80,0.205
9.00,-1.72,0.205
9.01,-1.63,0.206
9.02,-1.55,0.206
9.03,-1.46,0.207
9.03,-1.38,0.209
9.04,-1.30,0.210
9.05,-1.22,0.210
9.06,-1.13,0.211
9.07,-1.05,0.211
9.08,-0.97,0.211
9.08,-0.88,0.211
9.09,-0.80,0.211
9.10,-0.72,0.211
9.11,-0.63,0.211
9.12,-0.55,0.211
9.13,-0.47,0.211
9.13,-0.38,0.211
9.14,-0.30,0.211
9.15,-0.22,0.211
9.16,-0.13,0.211
9.17,-0.05,0.211
9.18,0.03,0.211
9.18,0.12,0.211
9.19,0.20,0.211
9.20,0.29,0.211
9.21,0.37,0.211
9.22,0.45,0.211
9.23,0.54,0.211
9.23,0.62,0.211
9.24,0.70,0.211
9.25,0.79,0.211
9.26,0.87,0.211
9.27,0.96,0.211
9.28,1.04,0.210
9.28,1.12,0.210
9.29,1.21,0.210
9.30,1.29,0.210
9.31,1.37,0.210
9.32,1.46,0.210
9.33,1.54,0.210
9.33,1.62,0.210
9.34,1.71,0.210
9.35,1.79,0.210
9.36,1.87,0.210
9.37,1.96,0.210
9.38,2.04,0.210
9.38,2.12,0.210
9.39,2.21,0.210
9.40,2.29,0.210
9.41,2.37,0.210
9.42,2.46,0.210
9.43,2.54,0.210
9.43,2.62,0.210
9.44,2.71,0.210
9.45,2.79,0.210
9.46,2.88,0.210
9.47,2.96,0.210
9.48,3.04,0.210
9.48,3.13,0.210
9.49,3.21,0.210
9.50,3.29,0.210
9.51,3.38,0.210
9.52,3.46,0.210
9.53,3.54,0.210
9.53,3.63,0.210
9.54,3.71,0.210
9.55,3.79,0.210
9.56,3.88,0.210
9.57,3.96,0.210
9.58,4.04,0.210
9.58,4.13,0.210
9.59,4.21,0.210
9.60,4.29,0.210
9.61,4.38,0.211
9.62,4.46,0.211
9.63,4.54,0.211
9.63,4.63,0.211
9.64,4.71,0.211
9.65,4.79,0.211
9.66,4.88,0.211
9.67,4.96,0.211
9.68,5.05,0.211
9.68,5.13,0.211
9.69,5.21,0.211
9.70,5.30,0.211
9.71,5.38,0.211
9.72,5.46,0.211
9.73,5.55,0.211
9.73,5.63,0.211
9.74,5.71,0.211
9.75,5.80,0.211
9.76,5.88,0.211
9.77,5.96,0.211
9.78,6.05,0.211
9.78,6.13,0.211
9.79,6.21,0.211
9.80,6.30,0.211
9.81,6.38,0.211
9.82,6.46,0.212
9.83,6.55,0.212
9.83,6.63,0.212
9.84,6.71,0.212
9.85,6.80,0.212
9.86,6.88,0.212
9.87,6.96,0.212
9.88,7.05,0.212
9.88,7.13,0.212
9.89,7.21,0.212
9.90,7.30,0.212
9.91,7.38,0.212
9.92,7.46,0.212
9.93,7.55,0.212
9.93,7.63,0.212
9.94,7.71,0.212
9.95,7.80,0.212
9.96,7.88,0.212
9.97,7.96,0.212
9.98,8.05,0.213
9.98,8.13,0.213
9.99,8.21,0.213
10.00,8.30,0.213
10.01,8.38,0.213
10.02,8.46,0.213
10.03,8.55,0.213
10.03,8.63,0.213
10.04,8.72,0.213
10.05,8.80,0.213
10.06,8.88,0.213
10.07,8.97,0.213
10.08,9.05,0.213
10.08,9.13,0.214
10.09,9.22,0.214
10.10,9.30,0.214
10.11,9.38,0.214
10.12,9.47,0.214
10.13,9.55,0.214
10.13,9.63,0.214
10.14,9.72,0.214
10.15,9.80,0.214
10.16,9.88,0.214
10.17,9.97,0.214
10.18,10.05,0.214
10.18,10.13,0.214
10.19,10.22,0.214
10.20,10.30,0.214
10.21,10.38,0.214
10.22,10.47,0.215
10.23,10.55,0.215
10.23,10.63,0.215
10.24,10.72,0.215
10.25,10.80,0.215
10.26,10.88,0.215
10.27,10.97,0.215
10.28,11.05,0.215
10.28,11.13,0.215
10.29,11.22,0.215
10.30,11.30,0.215
10.31,11.38,0.215
10.32,11.47,0.215
10.33,11.55,0.215
10.33,11.63,0.215
10.34,11.72,0.216
10.35,11.80,0.216
10.36,11.88,0.216
10.37,11.97,0.216
10.38,12.05,0.216
10.38,12.13,0.216
10.39,12.22,0.216
10.40,12.30,0.216
10.41,12.39,0.216
10.42,12.47,0.216
10.43,12.55,0.216
10.43,12.64,0.216
10.44,12.72,0.216
10.45,12.80,0.216
10.46,12.89,0.217
10.47,12.97,0.217
10.48,13.05,0.217
10.48,13.14,0.217
10.49,13.22,0.217
10.50,13.30,0.217
10.51,13.39,0.217
10.52,13.47,0.217
10.53,13.55,0.217
10.53,13.64,0.217
10.54,13.72,0.217
10.55,13.80,0.217
10.56,13.89,0.217
10.57,13.97,0.217
10.58,14.05,0.217
10.58,14.14,0.217
10.59,14.22,0.218
10.60,14.30,0.218
10.61,14.39,0.218
10.62,14.47,0.218
10.63,14.55,0.218
10.63,14.64,0.218
10.64,14.72,0.218
10.65,14.81,0.218
10.66,14.89,0.218
10.67,14.97,0.218
10.68,15.06,0.218
10.68,15.14,0.218
10.69,15.22,0.219
10.70,15.31,0.219
10.71,15.39,0.219
10.72,15.47,0.219
10.73,15.56,0.219
10.73,15.64,0.219
10.74,15.72,0.219
10.75,15.81,0.219
10.76,15.89,0.220
10.77,15.97,0.220
10.78,16.06,0.220
10.78,16.14,0.220
10.79,16.22,0.220
10.80,16.31,0.220
10.81,16.39,0.220
10.82,16.47,0.220
10.83,16.56,0.220
10.83,16.64,0.220
10.84,16.72,0.220
10.85,16.81,0.220
10.86,16.89,0.220
10.87,16.97,0.220
10.88,17.06,0.220
10.88,17.14,0.220
10.89,17.22,0.220
10.90,17.31,0.220
10.91,17.39,0.220
10.92,17.47,0.220
10.93,17.56,0.221
10.93,17.64,0.221
10.94,17.72,0.221
10.95,17.81,0.221
10.96,17.89,0.221
10.97,17.97,0.221
10.98,18.06,0.221
10.98,18.14,0.221
10.99,18.22,0.221
11.00,18.31,0.221
11.01,18.39,0.221
11.02,18.47,0.221
11.03,18.56,0.221
11.03,18.64,0.222
11.04,18.73,0.222
11.05,18.81,0.222
11.06,18.89,0.222
11.07,18.98,0.222
11.08,19.06,0.222
11.08,19.14,0.222
11.09,19.23,0.222
11.10,19.31,0.222
11.11,19.39,0.222
11.12,19.48,0.222
11.13,19.56,0.222
11.13,19.64,0.222
11.14,19.73,0.222
11.15,19.81,0.222
11.16,19.89,0.223
11.17,19.98,0.223
11.18,20.06,0.223
11.18,20.14,0.223
11.19,20.23,0.223
11.20,20.31,0.223
11.21,20.39,0.223
11.22,20.48,0.223
11.23,20.56,0.223
11.23,20.64,0.223
11.24,20.73,0.223
11.25,20.81,0.223
11.26,20.89,0.223
11.27,20.98,0.223
11.28,21.06,0.223
11.28,21.14,0.224
11.29,21.23,0.224
11.30,21.31,0.224
11.31,21.39,0.224
11.32,21.48,0.224
11.33,21.56,0.224
11.33,21.64,0.224
11.34,21.73,0.224
11.35,21.81,0.224
11.36,21.89,0.224
11.37,21.98,0.224
11.38,22.06,0.224
11.38,22.14,0.224
11.39,22.23,0.224
11.40,22.31,0.225
11.41,22.40,0.225
11.42,22.48,0.225
11.43,22.56,0.225
11.43,22.64,0.225
11.44,22.73,0.225
11.45,22.81,0.225
11.46,22.89,0.225
11.47,22.98,0.225
11.48,23.06,0.225
11.48,23.15,0.225
11.49,23.23,0.225
11.50,23.31,0.225
11.51,23.40,0.225
11.52,23.48,0.226
11.53,23.56,0.226
11.53,23.65,0.226
11.54,23.73,0.226
11.55,23.81,0.226
11.56,23.90,0.226
11.57,23.98,0.226
11.58,24.06,0.226
11.58,24.15,0.226
11.59,24.23,0.226
11.60,24.31,0.226
11.61,24.40,0.226
11.62,24.48,0.226
11.63,24.56,0.226
11.63,24.65,0.227
11.64,24.73,0.227
11.65,24.81,0.227
11.66,24.90,0.227
11.67,24.98,0.227
11.68,25.06,0.227
11.68,25.15,0.227
11.69,25.23,0.227
11.70,25.31,0.227
11.71,25.40,0.227
11.72,25.48,0.227
11.73,25.56,0.227
11.73,25.65,0.227
11.74,25.73,0.228
11.75,25.81,0.228
11.76,25.90,0.228
11.77,25.98,0.228
11.78,26.06,0.228
11.78,26.15,0.228
11.79,26.23,0.228
11.80,26.32,0.228
11.81,26.40,0.228
11.82,26.48,0.228
11.83,26.57,0.228
11.83,26.65,0.228
11.84,26.73,0.228
11.85,26.82,0.228
11.86,26.90,0.229
11.87,26.98,0.229
11.88,27.07,0.229
11.88,27.15,0.229
11.89,27.23,0.229
11.90,27.32,0.229
11.91,27.40,0.229
11.92,27.48,0.229
11.93,27.57,0.229
11.93,27.65,0.229
11.94,27.73,0.229
11.95,27.82,
11.96,27.90,
11.97,27.98,
11.98,28.07,
11.98,28.15,
11.99,28.23,
12.00,,
12.01,,

[step]
Ramp 10.00 °C/min to -90.00 °C
Time,Temperature,Heat Flow (Normalized)
min,°C,W/g
14.01,30.09,-0.013
14.02,30.09,-0.013
14.03,30.09,-0.013
14.03,30.09,-0.013
14.04,30.09,-0.013
14.05,30.09,-0.013
14.06,30.08,-0.013
14.07,30.08,-0.013
14.08,30.07,-0.014
14.08,30.06,-0.014
14.09,30.04,-0.016
14.10,30.02,-0.019
14.11,30.00,-0.024
14.12,29.97,-0.028
14.13,29.94,-0.034
14.13,29.91,-0.040
14.14,29.87,-0.047
14.15,29.83,-0.054
14.16,29.78,-0.062
14.17,29.73,-0.072
14.18,29.68,-0.080
14.18,29.63,-0.089
14.19,29.57,-0.099
14.20,29.51,-0.107
14.21,29.45,-0.117
14.22,29.39,-0.125
14.23,29.33,-0.133
14.23,29.26,-0.141
14.24,29.20,-0.149
14.25,29.13,-0.156
14.26,29.06,-0.162
14.27,28.99,-0.168
14.28,28.92,-0.174
14.28,28.85,-0.179
14.29,28.78,-0.184
14.30,28.71,-0.190
14.31,28.64,-0.193
14.32,28.56,-0.196
14.33,28.49,-0.201
14.33,28.41,-0.204
14.34,28.34,-0.208
14.35,28.26,-0.211
14.36,28.19,-0.213
14.37,28.11,-0.215
14.38,28.03,-0.219
14.38,27.96,-0.222
14.39,27.88,-0.222
14.40,27.80,-0.225
14.41,27.72,-0.227
14.42,27.65,-0.229
14.43,27.57,-0.230
14.43,27.49,-0.232
14.44,27.41,-0.233
14.45,27.33,-0.235
14.46,27.25,-0.236
14.47,27.17,-0.237
14.48,27.09,-0.238
14.48,27.01,-0.239
14.49,26.93,-0.239
14.50,26.85,-0.241
14.51,26.77,-0.242
14.52,26.69,-0.242
14.53,26.61,-0.243
14.53,26.53,-0.243
14.54,26.45,-0.244
14.55,26.37,-0.244
14.56,26.29,-0.245
14.57,26.21,-0.245
14.58,26.13,-0.246
14.58,26.05,-0.246
14.59,25.96,-0.247
14.60,25.88,-0.247
14.61,25.80,-0.248
14.62,25.72,-0.248
14.63,25.64,-0.248
14.63,25.56,-0.248
14.64,25.48,-0.248
14.65,25.39,-0.248
14.66,25.31,-0.248
14.67,25.23,-0.249
14.68,25.15,-0.249
14.68,25.07,-0.249
14.69,24.98,-0.249
14.70,24.90,-0.249
14.71,24.82,-0.249
14.72,24.74,-0.249
14.73,24.66,-0.249
14.73,24.57,-0.250
14.74,24.49,-0.250
14.75,24.41,-0.250
14.76,24.33,-0.250
14.77,24.24,-0.250
14.78,24.16,-0.250
14.78,24.08,-0.250
14.79,24.00,-0.250
14.80,23.91,-0.250
14.81,23.83,-0.250
14.82,23.75,-0.250
14.83,23.67,-0.250
14.83,23.58,-0.250
14.84,23.50,-0.250
14.85,23.42,-0.250
14.86,23.34,-0.250
14.87,23.25,-0.250
14.88,23.17,-0.250
14.88,23.09,-0.251
14.89,23.01,-0.251
14.90,22.93,-0.251
14.91,22.84,-0.251
14.92,22.76,-0.251
14.93,22.68,-0.251
14.93,22.59,-0.251
14.94,22.51,-0.251
14.95,22.43,-0.251
14.96,22.35,-0.251
14.97,22.26,-0.251
14.98,22.18,-0.251
14.98,22.10,-0.251
14.99,22.02,-0.251
15.00,21.93,-0.251
15.01,21.85,-0.251
15.02,21.77,-0.251
15.03,21.68,-0.251
15.03,21.60,-0.251
15.04,21.52,-0.250
15.05,21.44,-0.250
15.06,21.35,-0.250
15.07,21.27,-0.250
15.08,21.19,-0.250
15.08,21.10,-0.250
15.09,21.02,-0.250
15.10,20.94,-0.250
15.11,20.86,-0.250
15.12,20.77,-0.250
15.13,20.69,-0.250
15.13,20.61,-0.250
15.14,20.52,-0.250
15.15,20.44,-0.250
15.16,20.36,-0.250
15.17,20.27,-0.250
15.18,20.19,-0.250
15.18,20.11,-0.250
15.19,20.03,-0.250
15.20,19.94,-0.250
15.21,19.86,-0.250
15.22,19.78,-0.250
15.23,19.69,-0.250
15.23,19.61,-0.250
15.24,19.53,-0.249
15.25,19.44,-0.249
15.26,19.36,-0.249
15.27,19.28,-0.249
15.28,19.20,-0.249
15.28,19.11,-0.249
15.29,19.03,-0.249
15.30,18.95,-0.249
15.31,18.86,-0.249
15.32,18.78,-0.249
15.33,18.70,-0.249
15.33,18.61,-0.249
15.34,18.53,-0.249
15.35,18.45,-0.249
15.36,18.36,-0.249
15.37,18.28,-0.248
15.38,18.20,-0.248
15.38,18.12,-0.248
15.39,18.03,-0.248
15.40,17.95,-0.248
15.41,17.87,-0.248
15.42,17.78,-0.248
15.43,17.70,-0.248
15.43,17.62,-0.248
15.44,17.53,-0.248
15.45,17.45,-0.248
15.46,17.37,-0.247
15.47,17.29,-0.247
15.48,17.20,-0.247
15.48,17.12,-0.247
15.49,17.04,-0.247
15.50,16.95,-0.247
15.51,16.87,-0.247
15.52,16.79,-0.247
15.53,16.70,-0.247
15.53,16.62,-0.247
15.54,16.54,-0.246
15.55,16.45,-0.246
15.56,16.37,-0.246
15.57,16.29,-0.246
15.58,16.20,-0.246
15.58,16.12,-0.246
15.59,16.04,-0.246
15.60,15.95,-0.246
15.61,15.87,-0.246
15.62,15.79,-0.246
15.63,15.70,-0.246
15.63,15.62,-0.246
15.64,15.54,-0.245
15.65,15.46,-0.245
15.66,15.37,-0.245
15.67,15.29,-0.245
15.68,15.21,-0.245
15.68,15.12,-0.245
15.69,15.04,-0.245
15.70,14.96,-0.245
15.71,14.87,-0.245
15.72,14.79,-0.245
15.73,14.71,-0.245
15.73,14.62,-0.244
15.74,14.54,-0.244
15.75,14.46,-0.244
15.76,14.37,-0.244
15.77,14.29,-0.244
15.78,14.21,-0.244
15.78,14.13,-0.244
15.79,14.04,-0.244
15.80,13.96,-0.243
15.81,13.88,-0.243
15.82,13.79,-0.243
15.83,13.71,-0.243
15.83,13.63,-0.243
15.84,13.54,-0.243
15.85,13.46,-0.243
15.86,13.38,-0.243
15.87,13.29,-0.243
15.88,13.21,-0.243
15.88,13.13,-0.243
15.89,13.04,-0.243
15.90,12.96,-0.243
15.91,12.88,-0.243
15.92,12.79,-0.242
15.93,12.71,-0.242
15.93,12.63,-0.242
15.94,12.55,-0.242
15.95,12.46,-0.242
15.96,12.38,-0.242
15.97,12.30,-0.242
15.98,12.21,-0.242
15.98,12.13,-0.242
15.99,12.05,-0.242
16.00,11.96,-0.242
16.01,11.88,-0.241
16.02,11.79,-0.241
16.03,11.71,-0.241
16.03,11.63,-0.241
16.04,11.55,-0.241
16.05,11.46,-0.241
16.06,11.38,-0.241
16.07,11.30,-0.241
16.08,11.21,-0.241
16.08,11.13,-0.241
16.09,11.05,-0.241
16.10,10.96,-0.241
16.11,10.88,-0.240
16.12,10.80,-0.240
16.13,10.71,-0.240
16.13,10.63,-0.240
16.14,10.55,-0.240
16.15,10.47,-0.240
16.16,10.38,-0.240
16.17,10.30,-0.240
16.18,10.22,-0.240
16.18,10.13,-0.240
16.19,10.05,-0.239
16.20,9.97,-0.239
16.21,9.88,-0.239
16.22,9.80,-0.239
16.23,9.72,-0.239
16.23,9.63,-0.239
16.24,9.55,-0.239
16.25,9.47,-0.239
16.26,9.39,-0.239
16.27,9.30,-0.239
16.28,9.22,-0.239
16.28,9.14,-0.238
16.29,9.05,-0.238
16.30,8.97,-0.238
16.31,8.89,-0.238
16.32,8.80,-0.238
16.33,8.72,-0.238
16.33,8.64,-0.238
16.34,8.55,-0.238
16.35,8.47,-0.238
16.36,8.39,-0.238
16.37,8.30,-0.238
16.38,8.22,-0.238
16.38,8.14,-0.237
16.39,8.05,-0.237
16.40,7.97,-0.237
16.41,7.89,-0.237
16.42,7.80,-0.237
16.43,7.72,-0.237
16.43,7.64,-0.237
16.44,7.55,-0.237
16.45,7.47,-0.237
16.46,7.39,-0.237
16.47,7.31,-0.237
16.48,7.22,-0.236
16.48,7.14,-0.236
16.49,7.06,-0.236
16.50,6.97,-0.236
16.51,6.89,-0.236
16.52,6.81,-0.236
16.53,6.72,-0.236
16.53,6.64,-0.236
16.54,6.56,-0.236
16.55,6.47,-0.236
16.56,6.39,-0.235
16.57,6.31,-0.235
16.58,6.22,-0.235
16.58,6.14,-0.235
16.59,6.06,-0.235
16.60,5.97,-0.235
16.61,5.89,-0.235
16.62,5.81,-0.235
16.63,5.72,-0.235
16.63,5.64,-0.235
16.64,5.56,-0.235
16.65,5.47,-0.235
16.66,5.39,-0.235
16.67,5.31,-0.235
16.68,5.22,-0.234
16.68,5.14,-0.234
16.69,5.06,-0.234
16.70,4.97,-0.234
16.71,4.89,-0.234
16.72,4.81,-0.234
16.73,4.72,-0.234
16.73,4.64,-0.234
16.74,4.56,-0.234
16.75,4.48,-0.233
16.76,4.39,-0.233
16.77,4.31,-0.233
16.78,4.23,-0.233
16.78,4.14,-0.233
16.79,4.06,-0.233
16.80,3.97,-0.233
16.81,3.89,-0.233
16.82,3.81,-0.233
16.83,3.72,-0.233
16.83,3.64,-0.232
16.84,3.56,-0.232
16.85,3.48,-0.232
16.86,3.39,-0.232
16.87,3.31,-0.232
16.88,3.22,-0.232
16.88,3.14,-0.232
16.89,3.06,-0.232
16.90,2.98,-0.232
16.91,2.89,-0.231
16.92,2.81,-0.231
16.93,2.72,-0.231
16.93,2.64,-0.231
16.94,2.56,-0.231
16.95,2.48,-0.231
16.96,2.39,-0.231
16.97,2.31,-0.231
16.98,2.22,-0.231
16.98,2.14,-0.231
16.99,2.06,-0.231
17.00,1.97,-0.231
17.01,1.89,-0.231
17.02,1.81,-0.231
17.03,1.73,-0.231
17.03,1.64,-0.231
17.04,1.56,-0.230
17.05,1.48,-0.230
17.06,1.39,-0.230
17.07,1.31,-0.230
17.08,1.22,-0.230
17.08,1.14,-0.230
17.09,1.06,-0.230
17.10,0.97,-0.230
17.11,0.89,-0.230
17.12,0.81,-0.230
17.13,0.72,-0.230
17.13,0.64,-0.229
17.14,0.56,-0.229
17.15,0.47,-0.229
17.16,0.39,-0.229
17.17,0.31,-0.229
17.18,0.22,-0.229
17.18,0.14,-0.229
17.19,0.06,-0.229
17.20,-0.03,-0.229
17.21,-0.11,-0.229
17.22,-0.20,-0.229
[...]
87.17,-63.13,0.833
87.18,-63.05,0.825
87.19,-62.96,0.819
87.19,-62.87,0.811
87.20,-62.79,0.804
87.21,-62.70,0.797
87.22,-62.62,0.788
87.23,-62.53,0.778
87.24,-62.44,0.768
87.24,-62.35,0.755
87.25,-62.26,0.741
87.26,-62.17,0.726
87.27,-62.08,0.712
87.28,-61.99,0.694
87.29,-61.90,0.676
87.29,-61.80,0.659
87.30,-61.71,0.640
87.31,-61.61,0.621
87.32,-61.52,0.599
87.33,-61.42,0.578
87.34,-61.33,0.558
87.34,-61.23,0.538
87.35,-61.13,0.514
87.36,-61.03,0.486
87.37,-60.93,0.457
87.38,-60.83,0.431
87.39,-60.73,0.410
87.39,-60.63,0.389
87.40,-60.53,0.370
87.41,-60.43,0.353
87.42,-60.33,0.338
87.43,-60.23,0.325
87.44,-60.13,0.311
87.44,-60.03,0.301
87.45,-59.93,0.291
87.46,-59.84,0.282
87.47,-59.74,0.273
87.48,-59.65,0.267
87.49,-59.55,0.260
87.49,-59.46,0.252
87.50,-59.37,0.246
87.51,-59.27,0.242
87.52,-59.18,0.237
87.53,-59.09,0.231
87.54,-59.00,0.228
87.54,-58.91,0.224
87.55,-58.82,0.220
87.56,-58.73,0.217
87.57,-58.64,0.214
87.58,-58.55,0.210
87.59,-58.46,0.209
87.59,-58.37,0.205
87.60,-58.28,0.203
87.61,-58.20,0.201
87.62,-58.11,0.198
87.63,-58.02,0.197
87.64,-57.94,0.195
87.64,-57.85,0.194
87.65,-57.76,0.193
87.66,-57.68,0.191
87.67,-57.59,0.189
87.68,-57.51,0.189
87.69,-57.42,0.187
87.69,-57.33,0.187
87.70,-57.25,0.185
87.71,-57.16,0.184
87.72,-57.08,0.184
87.73,-56.99,0.183
87.74,-56.91,0.182
87.74,-56.82,0.182
87.75,-56.74,0.182
87.76,-56.65,0.180
87.77,-56.57,0.180
87.78,-56.48,0.179
87.79,-56.40,0.179
87.79,-56.32,0.179
87.80,-56.23,0.179
87.81,-56.15,0.178
87.82,-56.06,0.178
87.83,-55.98,0.177
87.84,-55.90,0.177
87.84,-55.81,0.177
87.85,-55.73,0.177
87.86,-55.64,0.176
87.87,-55.56,0.176
87.88,-55.48,0.176
87.89,-55.39,0.176
87.89,-55.31,0.176
87.90,-55.22,0.176
87.91,-55.14,0.176
87.92,-55.06,0.176
87.93,-54.97,0.176
87.94,-54.89,0.175
87.94,-54.81,0.175
87.95,-54.72,0.175
87.96,-54.64,0.175
87.97,-54.55,0.175
87.98,-54.47,0.175
87.99,-54.39,0.175
87.99,-54.30,0.175
88.00,-54.22,0.175
88.01,-54.13,0.175
88.02,-54.05,0.175
88.03,-53.97,0.175
88.04,-53.88,0.175
88.04,-53.80,0.175
88.05,-53.72,0.175
88.06,-53.63,0.175
88.07,-53.55,0.175
88.08,-53.47,0.175
88.09,-53.38,0.175
88.09,-53.30,0.175
88.10,-53.22,0.175
88.11,-53.13,0.175
88.12,-53.05,0.174
88.13,-52.97,0.174
88.14,-52.88,0.174
88.14,-52.80,0.174
88.15,-52.71,0.174
88.16,-52.63,0.174
88.17,-52.55,0.174
88.18,-52.46,0.174
88.19,-52.38,0.174
88.19,-52.30,0.174
88.20,-52.21,0.174
88.21,-52.13,0.174
88.22,-52.05,0.174
88.23,-51.96,0.174
88.24,-51.88,0.174
88.24,-51.79,0.174
88.25,-51.71,0.174
88.26,-51.63,0.174
88.27,-51.54,0.174
88.28,-51.46,0.174
88.29,-51.38,0.174
88.29,-51.29,0.174
88.30,-51.21,0.174
88.31,-51.13,0.174
88.32,-51.04,0.174
88.33,-50.96,0.174
88.34,-50.88,0.174
88.34,-50.79,0.174
88.35,-50.71,0.174
88.36,-50.62,0.174
88.37,-50.54,0.175
88.38,-50.46,0.175
88.39,-50.37,0.175
88.39,-50.29,0.175
88.40,-50.21,0.175
88.41,-50.12,0.175
88.42,-50.04,0.175
88.43,-49.96,0.175
88.44,-49.87,0.175
88.44,-49.79,0.175
88.45,-49.71,0.175
88.46,-49.62,0.175
88.47,-49.54,0.175
88.48,-49.46,0.175
88.49,-49.37,0.175
88.49,-49.29,0.175
88.50,-49.21,0.175
88.51,-49.12,0.175
88.52,-49.04,0.175
88.53,-48.96,0.175
88.54,-48.87,0.175
88.54,-48.79,0.175
88.55,-48.71,0.175
88.56,-48.62,0.175
88.57,-48.54,0.175
88.58,-48.45,0.175
88.59,-48.37,0.175
88.59,-48.29,0.175
88.60,-48.21,0.175
88.61,-48.12,0.175
88.62,-48.04,0.175
88.63,-47.96,0.175
88.64,-47.87,0.176
88.64,-47.79,0.176
88.65,-47.70,0.176
88.66,-47.62,0.176
88.67,-47.54,0.176
88.68,-47.45,0.176
88.69,-47.37,0.176
88.69,-47.29,0.176
88.70,-47.20,0.176
88.71,-47.12,0.176
88.72,-47.04,0.176
88.73,-46.95,0.176
88.74,-46.87,0.176
88.74,-46.79,0.176
88.75,-46.70,0.176
88.76,-46.62,0.176
88.77,-46.53,0.176
88.78,-46.45,0.176
88.79,-46.37,0.176
88.79,-46.28,0.176
88.80,-46.20,0.176
88.81,-46.12,0.176
88.82,-46.03,0.176
88.83,-45.95,0.177
88.84,-45.87,0.177
88.84,-45.78,0.177
88.85,-45.70,0.177
88.86,-45.62,0.177
88.87,-45.53,0.177
88.88,-45.45,0.177
88.89,-45.37,0.177
88.89,-45.28,0.177
88.90,-45.20,0.177
88.91,-45.12,0.177
88.92,-45.03,0.177
88.93,-44.95,0.177
88.94,-44.86,0.177
88.94,-44.78,0.177
88.95,-44.70,0.177
88.96,-44.61,0.177
88.97,-44.53,0.177
88.98,-44.45,0.177
88.99,-44.36,0.178
88.99,-44.28,0.178
89.00,-44.20,0.178
89.01,-44.11,0.178
89.02,-44.03,0.178
89.03,-43.95,0.178
89.04,-43.86,0.178
89.04,-43.78,0.178
89.05,-43.70,0.178
89.06,-43.61,0.178
89.07,-43.53,0.178
89.08,-43.45,0.178
89.09,-43.36,0.178
89.09,-43.28,0.178
89.10,-43.19,0.178
89.11,-43.11,0.178
89.12,-43.03,0.178
89.13,-42.94,0.178
89.14,-42.86,0.178
89.14,-42.78,0.178
89.15,-42.69,0.178
89.16,-42.61,0.179
89.17,-42.53,0.179
89.18,-42.44,0.179
89.19,-42.36,0.179
89.19,-42.27,0.179
89.20,-42.19,0.179
89.21,-42.11,0.179
89.22,-42.02,0.179
89.23,-41.94,0.179
89.24,-41.86,0.179
89.24,-41.77,0.179
89.25,-41.69,0.179
89.26,-41.60,0.179
89.27,-41.52,0.179
89.28,-41.44,0.179
89.29,-41.35,0.180
89.29,-41.27,0.180
89.30,-41.19,0.180
89.31,-41.10,0.180
89.32,-41.02,0.180
89.33,-40.94,0.180
89.34,-40.85,0.180
89.34,-40.77,0.180
89.35,-40.68,0.180
89.36,-40.60,0.180
89.37,-40.52,0.180
89.38,-40.43,0.180
89.39,-40.35,0.180
89.39,-40.27,0.180
89.40,-40.18,0.180
89.41,-40.10,0.180
89.42,-40.02,0.180
89.43,-39.93,0.180
89.44,-39.85,0.180
89.44,-39.77,0.180
89.45,-39.68,0.181
89.46,-39.60,0.181
89.47,-39.52,0.181
89.48,-39.43,0.181
89.49,-39.35,0.181
89.49,-39.27,0.181
89.50,-39.18,0.181
89.51,-39.10,0.181
89.52,-39.01,0.181
89.53,-38.93,0.181
89.54,-38.85,0.181
89.54,-38.76,0.181
89.55,-38.68,0.181
89.56,-38.60,0.181
89.57,-38.51,0.181
89.58,-38.43,0.181
89.59,-38.35,0.181
89.59,-38.26,0.181
89.60,-38.18,0.181
89.61,-38.10,0.181
89.62,-38.01,0.181
89.63,-37.93,0.181
89.64,-37.85,0.181
89.64,-37.76,0.181
89.65,-37.68,0.181
89.66,-37.60,0.181
89.67,-37.51,0.182
89.68,-37.43,0.182
89.69,-37.34,0.182
89.69,-37.26,0.182
89.70,-37.18,0.182
89.71,-37.09,0.182
89.72,-37.01,0.182
89.73,-36.93,0.182
89.74,-36.84,0.182
89.74,-36.76,0.182
89.75,-36.68,0.182
89.76,-36.59,0.182
89.77,-36.51,0.182
89.78,-36.43,0.182
89.79,-36.34,0.182
89.79,-36.26,0.182
89.80,-36.18,0.182
89.81,-36.09,0.182
89.82,-36.01,0.182
89.83,-35.93,0.182
89.84,-35.85,0.182
89.84,-35.76,0.182
89.85,-35.68,0.182
89.86,-35.59,0.183
89.87,-35.51,0.183
89.88,-35.43,0.183
89.89,-35.34,0.183
89.89,-35.26,0.183
89.90,-35.18,0.183
89.91,-35.09,0.183
89.92,-35.01,0.183
89.93,-34.93,0.183
89.94,-34.84,0.183
89.94,-34.76,0.183
89.95,-34.68,0.183
89.96,-34.59,0.183
89.97,-34.51,0.183
89.98,-34.43,0.183
89.99,-34.34,0.183
89.99,-34.26,0.183
90.00,-34.18,0.183
90.01,-34.09,0.183
90.02,-34.01,0.184
90.03,-33.93,0.184
90.04,-33.84,0.184
90.04,-33.76,0.184
90.05,-33.68,0.184
90.06,-33.59,0.184
90.07,-33.51,0.184
90.08,-33.42,0.184
90.09,-33.34,0.184
90.09,-33.26,0.184
90.10,-33.18,0.184
90.11,-33.09,0.184
90.12,-33.01,0.184
90.13,-32.93,0.184
90.14,-32.84,0.184
90.14,-32.76,0.184
90.15,-32.67,0.184
90.16,-32.59,0.184
90.17,-32.51,0.184
90.18,-32.42,0.184
90.19,-32.34,0.185
90.19,-32.26,0.185
90.20,-32.17,0.185
90.21,-32.09,0.185
90.22,-32.01,0.185
90.23,-31.92,0.185
90.24,-31.84,0.185
90.24,-31.76,0.185
90.25,-31.67,0.185
90.26,-31.59,0.185
90.27,-31.51,0.185
90.28,-31.42,0.185
90.29,-31.34,0.185
90.29,-31.26,0.185
90.30,-31.17,0.185
90.31,-31.09,0.185
90.32,-31.01,0.185
90.33,-30.92,0.185
90.34,-30.84,0.185
90.34,-30.76,0.186
90.35,-30.67,0.186
90.36,-30.59,0.186
90.37,-30.51,0.186
90.38,-30.42,0.186
90.39,-30.34,0.186
90.39,-30.25,0.186
90.40,-30.17,0.186
90.41,-30.09,0.186
90.42,-30.01,0.186
90.43,-29.92,0.186
90.44,-29.84,0.186
90.44,-29.75,0.186
90.45,-29.67,0.186
90.46,-29.59,0.186
90.47,-29.51,0.186
90.48,-29.42,0.186
90.49,-29.34,0.186
90.49,-29.25,0.186
90.50,-29.17,0.187
90.51,-29.09,0.187
90.52,-29.00,0.187
90.53,-28.92,0.187
90.54,-28.84,0.187
90.54,-28.75,0.187
90.55,-28.67,0.187
90.56,-28.59,0.187
90.57,-28.50,0.187
90.58,-28.42,0.187
90.59,-28.34,0.187
90.59,-28.25,0.187
90.60,-28.17,0.187
90.61,-28.09,0.187
90.62,-28.00,0.187
90.63,-27.92,0.187
90.64,-27.84,0.187
90.64,-27.75,0.187
90.65,-27.67,0.187
90.66,-27.59,0.188
90.67,-27.50,0.188
90.68,-27.42,0.188
90.69,-27.34,0.188
90.69,-27.25,0.188
90.70,-27.17,0.188
90.71,-27.09,0.188
90.72,-27.00,0.188
90.73,-26.92,0.188
90.74,-26.83,0.188
90.74,-26.75,0.188
90.75,-26.67,0.188
90.76,-26.58,0.188
90.77,-26.50,0.189
90.78,-26.42,0.189
90.79,-26.33,0.189
90.79,-26.25,0.189
90.80,-26.17,0.189
90.81,-26.08,0.189
90.82,-26.00,0.189
90.83,-25.92,0.189
90.84,-25.83,0.189
90.84,-25.75,0.189
90.85,-25.67,0.189
90.86,-25.58,0.189
90.87,-25.50,0.189
90.88,-25.42,0.189
90.89,-25.33,0.189
90.89,-25.25,0.189
90.90,-25.17,0.189
90.91,-25.08,0.189
90.92,-25.00,0.189
90.93,-24.92,0.189
90.94,-24.83,0.189
90.94,-24.75,0.189
90.95,-24.67,0.190
90.96,-24.58,0.190
90.97,-24.50,0.190
90.98,-24.42,0.190
90.99,-24.33,0.190
90.99,-24.25,0.190
91.00,-24.17,0.190
91.01,-24.08,0.190
91.02,-24.00,0.190
91.03,-23.92,0.190
91.04,-23.83,0.190
91.04,-23.75,0.190
91.05,-23.66,0.190
91.06,-23.58,0.190
91.07,-23.50,0.190
91.08,-23.41,0.190
91.09,-23.33,0.190
91.09,-23.25,0.190
91.10,-23.16,0.190
91.11,-23.08,0.190
91.12,-23.00,0.190
91.13,-22.91,0.190
91.14,-22.83,0.191
91.14,-22.75,0.191
91.15,-22.66,0.191
91.16,-22.58,0.191
91.17,-22.50,0.191
91.18,-22.41,0.191
91.19,-22.33,0.191
91.19,-22.24,0.191
91.20,-22.16,0.191
91.21,-22.08,0.191
91.22,-21.99,0.191
91.23,-21.91,0.191
91.24,-21.83,0.191
91.24,-21.74,0.191
91.25,-21.66,0.191
91.26,-21.58,0.191
91.27,-21.49,0.192
91.28,-21.41,0.192
91.29,-21.33,0.192
91.29,-21.24,0.192
91.30,-21.16,0.192
91.31,-21.08,0.192
91.32,-20.99,0.192
91.33,-20.91,0.192
91.34,-20.83,0.192
91.34,-20.74,0.192
91.35,-20.66,0.192
91.36,-20.58,0.192
91.37,-20.49,0.192
91.38,-20.41,0.192
91.39,-20.32,0.192
91.39,-20.24,0.193
91.40,-20.16,0.193
91.41,-20.07,0.193
91.42,-19.99,0.193
91.43,-19.91,0.193
91.44,-19.83,0.193
91.44,-19.74,0.193
91.45,-19.66,0.193
91.46,-19.58,0.193
91.47,-19.49,0.193
91.48,-19.41,0.193
91.49,-19.32,0.193
91.49,-19.24,0.193
91.50,-19.16,0.193
91.51,-19.07,0.193
91.52,-18.99,0.193
91.53,-18.91,0.193
91.54,-18.82,0.193
91.54,-18.74,0.193
91.55,-18.66,0.193
91.56,-18.57,0.193
91.57,-18.49,0.193
91.58,-18.41,0.194
91.59,-18.32,0.194
91.59,-18.24,0.194
91.60,-18.16,0.194
91.61,-18.07,0.194
91.62,-17.99,0.194
91.63,-17.91,0.194
91.64,-17.82,0.194
91.64,-17.74,0.194
91.65,-17.66,0.194
91.66,-17.57,0.194
91.67,-17.49,0.194
91.68,-17.40,0.194
91.69,-17.32,0.194
91.69,-17.24,0.194
91.70,-17.15,0.194
91.71,-17.07,0.194
91.72,-16.99,0.194
91.73,-16.90,0.194
91.74,-16.82,0.195
91.74,-16.74,0.195
91.75,-16.65,0.195
91.76,-16.57,0.195
91.77,-16.49,0.195
91.78,-16.40,0.195
91.79,-16.32,0.195
91.79,-16.24,0.195
91.80,-16.15,0.195
91.81,-16.07,0.195
91.82,-15.99,0.195
91.83,-15.90,0.195
91.84,-15.82,0.195
91.84,-15.74,0.195
91.85,-15.65,0.195
91.86,-15.57,0.195
91.87,-15.49,0.195
91.88,-15.40,0.196
91.89,-15.32,0.196
91.89,-15.23,0.196
91.90,-15.15,0.196
91.91,-15.07,0.196
91.92,-14.99,0.196
91.93,-14.90,0.196
91.94,-14.82,0.196
91.94,-14.73,0.196
91.95,-14.65,0.196
91.96,-14.57,0.196
91.97,-14.48,0.196
91.98,-14.40,0.196
91.99,-14.32,0.196
91.99,-14.23,0.196
92.00,-14.15,0.196
92.01,-14.07,0.197
92.02,-13.98,0.197
92.03,-13.90,0.197
92.04,-13.82,0.197
92.04,-13.73,0.197
92.05,-13.65,0.197
92.06,-13.57,0.197
92.07,-13.48,0.197
92.08,-13.40,0.197
92.09,-13.32,0.197
92.09,-13.23,0.197
92.10,-13.15,0.197
92.11,-13.07,0.197
92.12,-12.98,0.197
92.13,-12.90,0.197
92.14,-12.82,0.197
92.14,-12.73,0.197
92.15,-12.65,0.197
92.16,-12.57,0.197
92.17,-12.48,0.198
92.18,-12.40,0.198
92.19,-12.31,0.198
92.19,-12.23,0.198
92.20,-12.15,0.198
92.21,-12.07,0.198
92.22,-11.98,0.198
92.23,-11.90,0.198
92.24,-11.81,0.198
92.24,-11.73,0.198
92.25,-11.65,0.198
92.26,-11.57,0.198
92.27,-11.48,0.198
92.28,-11.40,0.198
92.29,-11.32,0.198
92.29,-11.23,0.198
92.30,-11.15,0.198
92.31,-11.06,0.198
92.32,-10.98,0.199
92.33,-10.90,0.199
92.34,-10.82,0.199
92.34,-10.73,0.199
92.35,-10.65,0.199
92.36,-10.56,0.199
92.37,-10.48,0.199
92.38,-10.40,0.199
92.39,-10.31,0.199
92.39,-10.23,0.199
92.40,-10.15,0.199
92.41,-10.06,0.199
92.42,-9.98,0.199
92.43,-9.90,0.199
92.44,-9.81,0.200
92.44,-9.73,0.200
92.45,-9.65,0.200
92.46,-9.56,0.200
92.47,-9.48,0.200
92.48,-9.40,0.200
92.49,-9.31,0.200
92.49,-9.23,0.200
92.50,-9.15,0.200
92.51,-9.06,0.200
92.52,-8.98,0.200
92.53,-8.90,0.200
92.54,-8.81,0.200
92.54,-8.73,0.200
92.55,-8.64,0.200
92.56,-8.56,0.200
92.57,-8.48,0.201
92.58,-8.40,0.201
92.59,-8.31,0.201
92.59,-8.23,0.201
92.60,-8.14,0.201
92.61,-8.06,0.201
92.62,-7.98,0.201
92.63,-7.89,0.201
92.64,-7.81,0.201
92.64,-7.73,0.201
92.65,-7.64,0.201
92.66,-7.56,0.201
92.67,-7.48,0.201
92.68,-7.39,0.201
92.69,-7.31,0.202
92.69,-7.23,0.202
92.70,-7.14,0.202
92.71,-7.06,0.202
92.72,-6.98,0.202
92.73,-6.89,0.202
92.74,-6.81,0.202
92.74,-6.73,0.202
92.75,-6.64,0.202
92.76,-6.56,0.202
92.77,-6.48,0.202
92.78,-6.39,0.202
92.79,-6.31,0.202
92.79,-6.23,0.202
92.80,-6.14,0.202
92.81,-6.06,0.202
92.82,-5.98,0.202
92.83,-5.89,0.203
92.84,-5.81,0.203
92.84,-5.73,0.203
92.85,-5.64,0.203
92.86,-5.56,0.203
92.87,-5.47,0.203
92.88,-5.39,0.203
92.89,-5.31,0.203
92.89,-5.22,0.203
92.90,-5.14,0.203
92.91,-5.06,0.203
92.92,-4.97,0.203
92.93,-4.89,0.203
92.94,-4.81,0.203
92.94,-4.72,0.203
92.95,-4.64,0.204
92.96,-4.56,0.204
92.97,-4.47,0.204
92.98,-4.39,0.204
92.99,-4.31,0.204
92.99,-4.22,0.204
93.00,-4.14,0.204
93.01,-4.06,0.204
93.02,-3.97,0.204
93.03,-3.89,0.204
93.04,-3.81,0.204
93.04,-3.72,0.204
93.05,-3.64,0.204
93.06,-3.56,0.204
93.07,-3.47,0.204
93.08,-3.39,0.204
93.09,-3.31,0.204
93.09,-3.22,0.204
93.10,-3.14,0.204
93.11,-3.06,0.205
93.12,-2.97,0.205
93.13,-2.89,0.205
93.14,-2.81,0.205
93.14,-2.72,0.205
93.15,-2.64,0.205
93.16,-2.56,0.205
93.17,-2.47,0.205
93.18,-2.39,0.205
93.19,-2.31,0.205
93.19,-2.22,0.205
93.20,-2.14,0.205
93.21,-2.05,0.206
93.22,-1.97,0.206
93.23,-1.89,0.206
93.24,-1.80,0.206
93.24,-1.72,0.206
93.25,-1.64,0.207
93.26,-1.56,0.207
93.27,-1.47,0.208
93.28,-1.39,0.209
93.29,-1.31,0.209
93.29,-1.22,0.210
93.30,-1.14,0.210
93.31,-1.06,0.211
93.32,-0.97,0.211
93.33,-0.89,0.211
93.34,-0.81,0.211
93.34,-0.72,0.211
93.35,-0.64,0.211
93.36,-0.56,0.212
93.37,-0.47,0.212
93.38,-0.39,0.212
93.39,-0.31,0.212
93.39,-0.22,0.212
93.40,-0.14,0.211
93.41,-0.06,0.211
93.42,0.03,0.211
93.43,0.11,0.211
93.44,0.20,0.211
93.44,0.28,0.211
93.45,0.36,0.211
93.46,0.45,0.211
93.47,0.53,0.211
93.48,0.61,0.211
93.49,0.70,0.211
93.49,0.78,0.211
93.50,0.86,0.211
93.51,0.95,0.211
93.52,1.03,0.211
93.53,1.12,0.211
93.54,1.20,0.211
93.54,1.28,0.211
93.55,1.37,0.211
93.56,1.45,0.211
93.57,1.53,0.211
93.58,1.61,0.211
93.59,1.70,0.211
93.59,1.78,0.211
93.60,1.87,0.211
93.61,1.95,0.211
93.62,2.03,0.211
93.63,2.12,0.211
93.64,2.20,0.211
93.64,2.28,0.211
93.65,2.37,0.211
93.66,2.45,0.211
93.67,2.53,0.211
93.68,2.62,0.210
93.69,2.70,0.211
93.69,2.78,0.210
93.70,2.87,0.211
93.71,2.95,0.211
93.72,3.04,0.211
93.73,3.12,0.211
93.74,3.20,0.211
93.74,3.28,0.211
93.75,3.37,0.211
93.76,3.45,0.211
93.77,3.54,0.211
93.78,3.62,0.211
93.79,3.70,0.211
93.79,3.79,0.211
93.80,3.87,0.211
93.81,3.95,0.211
93.82,4.04,0.211
93.83,4.12,0.211
93.84,4.20,0.211
93.84,4.29,0.211
93.85,4.37,0.211
93.86,4.45,0.211
93.87,4.54,0.211
93.88,4.62,0.211
93.89,4.70,0.211
93.89,4.79,0.211
93.90,4.87,0.211
93.91,4.95,0.211
93.92,5.04,0.211
93.93,5.12,0.211
93.94,5.20,0.211
93.94,5.29,0.211
93.95,5.37,0.211
93.96,5.45,0.211
93.97,5.54,0.212
93.98,5.62,0.212
93.99,5.71,0.212
93.99,5.79,0.212
94.00,5.87,0.212
94.01,5.95,0.212
94.02,6.04,0.212
94.03,6.12,0.212
94.04,6.21,0.212
94.04,6.29,0.212
94.05,6.37,0.212
94.06,6.46,0.212
94.07,6.54,0.212
94.08,6.62,0.212
94.09,6.71,0.212
94.09,6.79,0.212
94.10,6.87,0.212
94.11,6.96,0.212
94.12,7.04,0.213
94.13,7.12,0.213
94.14,7.21,0.213
94.14,7.29,0.213
94.15,7.37,0.213
94.16,7.46,0.213
94.17,7.54,0.213
94.18,7.62,0.213
94.19,7.71,0.213
94.19,7.79,0.213
94.20,7.87,0.213
94.21,7.96,0.213
94.22,8.04,0.213
94.23,8.12,0.213
94.24,8.21,0.214
94.24,8.29,0.214
94.25,8.37,0.214
94.26,8.46,0.214
94.27,8.54,0.214
94.28,8.62,0.214
94.29,8.71,0.214
94.29,8.79,0.214
94.30,8.88,0.214
94.31,8.96,0.214
94.32,9.04,0.214
94.33,9.12,0.214
94.34,9.21,0.214
94.34,9.29,0.214
94.35,9.38,0.214
94.36,9.46,0.215
94.37,9.54,0.215
94.38,9.63,0.215
94.39,9.71,0.215
94.39,9.79,0.215
94.40,9.88,0.215
94.41,9.96,0.215
94.42,10.04,0.215
94.43,10.13,0.215
94.44,10.21,0.215
94.44,10.29,0.215
94.45,10.38,0.215
94.46,10.46,0.215
94.47,10.54,0.215
94.48,10.63,0.216
94.49,10.71,0.216
94.49,10.79,0.216
94.50,10.88,0.216
94.51,10.96,0.216
94.52,11.04,0.216
94.53,11.13,0.216
94.54,11.21,0.216
94.54,11.29,0.216
94.55,11.38,0.216
94.56,11.46,0.216
94.57,11.54,0.216
94.58,11.63,0.216
94.59,11.71,0.216
94.59,11.79,0.216
94.60,11.88,0.217
94.61,11.96,0.217
94.62,12.05,0.217
94.63,12.13,0.217
94.64,12.21,0.217
94.64,12.30,0.217
94.65,12.38,0.217
94.66,12.46,0.217
94.67,12.54,0.217
94.68,12.63,0.217
94.69,12.71,0.217
94.69,12.80,0.217
94.70,12.88,0.217
94.71,12.96,0.217
94.72,13.05,0.217
94.73,13.13,0.217
94.74,13.21,0.218
94.74,13.30,0.218
94.75,13.38,0.218
94.76,13.46,0.218
94.77,13.55,0.218
94.78,13.63,0.218
94.79,13.71,0.218
94.79,13.80,0.218
94.80,13.88,0.218
94.81,13.96,0.218
94.82,14.05,0.218
94.83,14.13,0.218
94.84,14.21,0.218
94.84,14.30,0.218
94.85,14.38,0.218
94.86,14.46,0.218
94.87,14.55,0.219
94.88,14.63,0.219
94.89,14.71,0.219
94.89,14.80,0.219
94.90,14.88,0.219
94.91,14.96,0.219
94.92,15.05,0.219
94.93,15.13,0.219
94.94,15.21,0.219
94.94,15.30,0.219
94.95,15.38,0.219
94.96,15.46,0.219
94.97,15.55,0.219
94.98,15.63,0.219
94.99,15.72,0.220
94.99,15.80,0.220
95.00,15.88,0.220
95.01,15.97,0.220
95.02,16.05,0.220
95.03,16.13,0.220
95.04,16.22,0.220
95.04,16.30,0.220
95.05,16.38,0.220
95.06,16.47,0.220
95.07,16.55,0.220
95.08,16.63,0.220
95.09,16.72,0.220
95.09,16.80,0.221
95.10,16.88,0.221
95.11,16.97,0.221
95.12,17.05,0.221
95.13,17.13,0.221
95.14,17.22,0.221
95.14,17.30,0.221
95.15,17.38,0.221
95.16,17.47,0.221
95.17,17.55,0.221
95.18,17.63,0.221
95.19,17.72,0.221
95.19,17.80,0.221
95.20,17.88,0.221
95.21,17.97,0.222
95.22,18.05,0.222
95.23,18.13,0.222
95.24,18.22,0.222
95.24,18.30,0.222
95.25,18.38,0.222
95.26,18.47,0.222
95.27,18.55,0.222
95.28,18.63,0.222
95.29,18.72,0.222
95.29,18.80,0.222
95.30,18.89,0.222
95.31,18.97,0.222
95.32,19.05,0.222
95.33,19.13,0.223
95.34,19.22,0.223
95.34,19.30,0.223
95.35,19.39,0.223
95.36,19.47,0.223
95.37,19.55,0.223
95.38,19.64,0.223
95.39,19.72,0.223
95.39,19.80,0.223
95.40,19.89,0.223
95.41,19.97,0.223
95.42,20.05,0.223
95.43,20.14,0.223
95.44,20.22,0.223
95.44,20.30,0.223
95.45,20.39,0.223
95.46,20.47,0.223
95.47,20.55,0.224
95.48,20.64,0.224
95.49,20.72,0.224
95.49,20.80,0.224
95.50,20.89,0.224
95.51,20.97,0.224
95.52,21.05,0.224
95.53,21.14,0.224
95.54,21.22,0.224
95.54,21.30,0.224
95.55,21.39,0.224
95.56,21.47,0.224
95.57,21.55,0.224
95.58,21.64,0.225
95.59,21.72,0.225
95.59,21.81,0.225
95.60,21.89,0.225
95.61,21.97,0.225
95.62,22.06,0.225
95.63,22.14,0.225
95.64,22.22,0.225
95.64,22.31,0.225
95.65,22.39,0.225
95.66,22.47,0.225
95.67,22.55,0.225
95.68,22.64,0.225
95.69,22.72,0.225
95.69,22.80,0.225
95.70,22.89,0.225
95.71,22.97,0.226
95.72,23.06,0.226
95.73,23.14,0.226
95.74,23.22,0.226
95.74,23.31,0.226
95.75,23.39,0.226
95.76,23.47,0.226
95.77,23.56,0.226
95.78,23.64,0.226
95.79,23.72,0.226
95.79,23.81,0.226
95.80,23.89,0.226
95.81,23.97,0.226
95.82,24.06,0.226
95.83,24.14,0.227
95.84,24.22,0.227
95.84,24.31,0.227
95.85,24.39,0.227
95.86,24.47,0.227
95.87,24.56,0.227
95.88,24.64,0.227
95.89,24.72,0.227
95.89,24.81,0.227
95.90,24.89,0.227
95.91,24.98,0.227
95.92,25.06,0.227
95.93,25.14,0.227
95.94,25.22,0.227
95.94,25.31,0.228
95.95,25.39,0.228
95.96,25.48,0.228
95.97,25.56,0.228
95.98,25.64,0.228
95.99,25.72,0.228
95.99,25.81,0.228
96.00,25.89,0.228
96.01,25.98,0.228
96.02,26.06,0.228
96.03,26.14,0.228
96.04,26.22,0.228
96.04,26.31,0.228
96.05,26.39,0.228
96.06,26.47,0.229
96.07,26.56,0.229
96.08,26.64,0.229
96.09,26.73,0.229
96.09,26.81,0.229
96.10,26.89,0.229
96.11,26.98,0.229
96.12,27.06,0.229
96.13,27.14,0.229
96.14,27.23,0.229
96.14,27.31,
96.15,27.39,
96.16,27.48,
96.17,27.56,
96.18,27.64,
96.19,27.73,
96.19,,
96.20,,