File: DSC/2025_04_23_CBN_Pro_MC_n60C_120C_10Cmin_x3.csv
Filename,2025_04_23_CBN_Pro_MC_n60C_120C_10Cmin_x3
Instrument name,DSC2A-00468 (192.168.1.100)
Operator,Yarger
rundate,4/23/2025
Sample name,2025_04_23_CBN_Pro_MC_n60C_120C_10Cmin_x3
proceduresegments,Data Off ; Equilibrate -60.00 °C; Data On ; Ramp 10.00 °C/min to 120.00 °C; Data Off ; Isothermal 1.0 min; Data On ; Ramp 10.00 °C/min to -60.00 °C; Data Off ; Isothermal 2.0 min; Data On ; Ramp 10.00 °C/min to 120.00 °C; Data Off ; Isothermal 1.0 min; Data On ; Ramp 10.00 °C/min to -60.00 °C; Data Off ; Isothermal 2.0 min; Data On ; Ramp 10.00 °C/min to 120.00 °C
[File Parameters]
Run date,4/23/2025 1:33:24 AM
Trios version,5.1.1.46572
Original File Name,D:\DSC2500\JYarger\2025_04_23_CBN_Pro_MC_n60C_120C_10Cmin_x3.tri
Current File Name,D:\DSC2500\JYarger\2025_04_23_CBN_Pro_MC_n60C_120C_10Cmin_x3.tri
[Procedure]
Procedure Name,CBN_Pro_n60_120C_10Cmin_x3
Sample Name,2025_04_23_CBN_Pro_MC_n60C_120C_10Cmin_x3
Sample Mass,5.05 mg
Reference Sample Mass,0 mg
Pan Mass,52.9 mg
Pan Number,24
Reference Pan Mass,52.66 mg
Reference Pan Number,19
Pan Type,Tzero Aluminum Hermetic
Comments,Al Hermetic DSC Consumables sealed Pan/Lid.
Project Name,CA
Operator,Yarger
Test,Custom
Unload Max Temperature,30
Unload Min Temperature,30
Load Max Temperature,30
Load Min Temperature,30
Stop on Gas Flow Error,Yes
[Signal List]
Signal #1,Time (min)
Signal #2,Temperature (°C)
Signal #3,Heat Flow (mW)
Signal #4,Delta T (µV)
Signal #5,Delta Tzero (µV)
Signal #6,Tzero Temperature (°C)
Signal #7,Cell Purge (mL/min)
Signal #8,Heater Temp (°C)
Signal #9,Power Delivered (W)
Signal #10,Reference Junction Temperature (°C)
Signal #11,Flange Temperature (°C)
Signal #12,Heat Flow Phase (rad)
Signal #13,Total Heat Capacity (J/°C)
Signal #14,Heat Capacity (J/°C)
[Configuration]
Company Name,ASU
Instrument Name,DSC2A-00468
Instrument Type,DSC2500
Serial Number,DSC2A-00468
IP,192.168.1.100
Location of Instrument,MRRC
DisplayType,Unknown
Sample Interval ,0.1 s/pt
Selected Heat Flow,T4P
Exotherm Direction,Down
Cell Serial,DRC2-00792
Lid Type,Standard
Cooler,RCS 90
Leave Cooler on at End of Sequence,On
Gas 2,Nitrogen
Gas Selected,Channel 1
Flow Rate,50 mL/min
Secondary Purge,On
Licensed Heat Flow,Heat Flow T4P
Modulation Licensed,Yes
[Versions]
Common IDD Version,1
Cortex Version,VER 2.10.2.31
Driver,5.0.0.6
GDM Version,1.0.3.3
TouchscreenVersion,1.0.0.16145
FEP Version,1.2.1.21
FEP Bootloader,2.0.0.5
AutoSampler Version,2.1.1.26
Auto Sampler Bootloader,2.0.0.5
FCM Version,1.1.0.3
FCM Bootloader,2.0.0.5
[Experiment Logs]
Experiment Log Entry # 1,Air Cool is off.
Experiment Log Entry # 3,Data On set to 0
Experiment Log Entry # 5,Equilibrate Segment -60 (C) Started
Experiment Log Entry # 7,Data On set to 1
Experiment Log Entry # 9,Ramp Segment 10 C/min to 120 Started
Experiment Log Entry # 11,Data On set to 0
Experiment Log Entry # 13,Isothermal Segment 1 min started
Experiment Log Entry # 15,Data On set to 1
Experiment Log Entry # 17,Ramp Segment 10 C/min to -60 Started
Experiment Log Entry # 19,Data On set to 0
Experiment Log Entry # 21,Isothermal Segment 2 min started
Experiment Log Entry # 23,Data On set to 1
Experiment Log Entry # 25,Ramp Segment 10 C/min to 120 Started
Experiment Log Entry # 27,Data On set to 0
Experiment Log Entry # 29,Isothermal Segment 1 min started
Experiment Log Entry # 31,Data On set to 1
Experiment Log Entry # 33,Ramp Segment 10 C/min to -60 Started
Experiment Log Entry # 35,Data On set to 0
Experiment Log Entry # 37,Isothermal Segment 2 min started
Experiment Log Entry # 39,Data On set to 1
Experiment Log Entry # 41,Ramp Segment 10 C/min to 120 Started
[Method Log]
Method Log Entry # 1,Data Off
Method Log Entry # 2,Equilibrate -60 °C
Method Log Entry # 3,Data On
Method Log Entry # 4,(Ramp 1198999) Ramp 10 °C/minute to 120 °C
Method Log Entry # 5,Data Off
Method Log Entry # 6,Isothermal 1 minutes
Method Log Entry # 7,Data On
Method Log Entry # 8,(Ramp 1199003) Ramp 10 °C/minute to -60 °C
Method Log Entry # 9,Data Off
Method Log Entry # 10,Isothermal 2 minutes
Method Log Entry # 11,Data On
Method Log Entry # 12,(Ramp 1199007) Ramp 10 °C/minute to 120 °C
Method Log Entry # 13,Data Off
Method Log Entry # 14,Isothermal 1 minutes
Method Log Entry # 15,Data On
Method Log Entry # 16,(Ramp 1199011) Ramp 10 °C/minute to -60 °C
Method Log Entry # 17,Data Off
Method Log Entry # 18,Isothermal 2 minutes
Method Log Entry # 19,Data On
Method Log Entry # 20,(Ramp 1199015) Ramp 10 °C/minute to 120 °C
Cell Serial,DRC2-00792
[T1 Calibration]
Slope,-0.008529666
Offset,9.636258
Initial Temperature,98.23
GUID,f8bfdadc-4977-4fdf-ba6d-0ba9134940c3
[TZero Calibration]
Date Applied,11/29/2022 4:06:13 PM
Description,From -89.059 °C to 396.009 °C at 20.000°C/min
Gas Type,Nitrogen
Pan Type,None
Source Files 1,C:\Users\yargerlab\Desktop\DSC Data\General\TZero_calibration_11_29_22_2nd(2).tri
Source Files 2,C:\Users\yargerlab\Desktop\DSC Data\General\TZero_calibration_11_29_22_2nd(3).tri
Delta T Offset,13.05235
Delta T Slope,-0.007271007
Delta T0 Offset,-13.69128
Delta T0 Slope,0.06063341
[Temperature Calibration]
Date Applied,11/29/2022 7:12:28 PM
Description,From 106.590 °C to 186.590 °C at 10.000°C/min
Gas Type,Nitrogen
Pan Type,Tzero Aluminum Hermetic
Source Files 1,C:\Users\yargerlab\Desktop\DSC Data\General\Indium(6).tri
Measured 1,157.391
Known 1,156.598
[Cell Constant Calibration]
Date Applied,11/29/2022 7:12:29 PM
Description,From 106.590 °C to 186.590 °C at 10.000°C/min
Gas Type,Nitrogen
Pan Type,Tzero Aluminum Hermetic
Source Files 1,C:\Users\yargerlab\Desktop\DSC Data\General\Indium(6).tri
T4P KCell,1.006051
Onset Slope,63.26126 mW/°C
[Direct Cp Calibration]
Date Applied,11/30/2022 11:04:51 AM
Description,From -79.983 °C to 298.409 °C at 10.000°C/min
Gas Type,Nitrogen
Pan Type,Tzero Aluminum Hermetic
Source Files 1,C:\Users\yargerlab\Desktop\DSC Data\General\Sapphire_Heat_Capacity_11_30_22.tri
[Rev Cp Calibration]
Date Applied,11/30/2022 1:58:51 PM
Description,From -79.996 °C to 292.812 °C at 3.000°C/min
Gas Type,Nitrogen
Pan Type,Tzero Aluminum Hermetic
Source Files 1,C:\Users\yargerlab\Desktop\DSC Data\General\Sapphire_MDSC_Calibration_11_30_22.tri
[step]
Ramp 10.00 °C/min to 120.00 °C
Time,Temperature,Heat Flow (Normalized)
min,°C,W/g
0.00,-59.68,-0.051
0.01,-59.69,-0.052
0.03,-59.70,-0.048
0.04,-59.70,-0.044
0.05,-59.70,-0.044
0.07,-59.69,-0.046
0.08,-59.67,-0.051
0.09,-59.64,-0.062
0.11,-59.60,-0.070
0.12,-59.54,-0.073
0.13,-59.48,-0.073
0.15,-59.41,-0.071
0.16,-59.33,-0.061
0.17,-59.24,-0.042
0.19,-59.15,-0.026
0.20,-59.05,-0.009
0.21,-58.95,0.008
0.23,-58.84,0.024
0.24,-58.74,0.038
0.25,-58.63,0.051
0.27,-58.51,0.065
0.28,-58.40,0.075
0.29,-58.28,0.087
0.31,-58.16,0.094
0.32,-58.04,0.102
0.33,-57.92,0.109
0.35,-57.80,0.116
0.36,-57.68,0.121
0.37,-57.56,0.125
0.39,-57.43,0.129
0.40,-57.31,0.134
0.41,-57.18,0.137
0.43,-57.06,0.139
0.44,-56.93,0.141
0.45,-56.81,0.144
0.47,-56.68,0.146
0.48,-56.55,0.147
0.49,-56.43,0.149
0.51,-56.30,0.150
0.52,-56.17,0.151
0.53,-56.04,0.154
0.55,-55.91,0.155
0.56,-55.79,0.156
0.57,-55.66,0.156
0.59,-55.53,0.157
0.60,-55.40,0.157
0.61,-55.27,0.158
0.63,-55.14,0.158
0.64,-55.01,0.159
0.65,-54.88,0.159
0.67,-54.75,0.159
0.68,-54.62,0.160
0.69,-54.49,0.160
0.71,-54.36,0.160
0.72,-54.23,0.161
0.73,-54.10,0.161
0.75,-53.97,0.162
0.76,-53.84,0.162
0.77,-53.71,0.162
0.79,-53.58,0.162
0.80,-53.44,0.163
0.81,-53.31,0.163
0.83,-53.18,0.163
0.84,-53.05,0.163
0.85,-52.92,0.163
0.87,-52.79,0.164
0.88,-52.66,0.164
0.89,-52.53,0.164
0.91,-52.39,0.164
0.92,-52.26,0.164
0.93,-52.13,0.165
0.95,-52.00,0.165
0.96,-51.87,0.165
0.97,-51.73,0.165
0.99,-51.60,0.165
1.00,-51.47,0.165
1.01,-51.34,0.166
1.03,-51.21,0.166
1.04,-51.08,0.166
1.05,-50.94,0.166
1.07,-50.81,0.166
1.08,-50.68,0.166
1.09,-50.55,0.167
1.11,-50.41,0.167
1.12,-50.28,0.167
1.13,-50.15,0.167
1.15,-50.02,0.167
1.16,-49.88,0.167
1.17,-49.75,0.167
1.19,-49.62,0.168
1.20,-49.49,0.168
1.21,-49.35,0.168
1.23,-49.22,0.168
1.24,-49.09,0.168
1.25,-48.96,0.168
1.27,-48.82,0.168
1.28,-48.69,0.168
1.29,-48.56,0.168
1.31,-48.42,0.168
1.32,-48.29,0.169
1.33,-48.16,0.169
1.35,-48.03,0.169
1.36,-47.89,0.169
1.37,-47.76,0.169
1.39,-47.63,0.169
1.40,-47.49,0.169
1.41,-47.36,0.169
1.43,-47.23,0.169
1.44,-47.10,0.169
1.45,-46.96,0.169
1.47,-46.83,0.170
1.48,-46.70,0.170
1.49,-46.56,0.170
1.51,-46.43,0.170
1.52,-46.30,0.170
1.53,-46.16,0.170
1.55,-46.03,0.170
1.56,-45.90,0.170
1.57,-45.77,0.170
1.59,-45.63,0.170
1.60,-45.50,0.170
1.61,-45.36,0.170
1.63,-45.23,0.170
1.64,-45.10,0.170
1.65,-44.97,0.170
1.67,-44.83,0.170
1.68,-44.70,0.171
1.69,-44.57,0.171
1.71,-44.43,0.171
1.72,-44.30,0.171
1.73,-44.17,0.171
1.75,-44.03,0.171
1.76,-43.90,0.171
1.77,-43.77,0.171
1.79,-43.64,0.171
1.80,-43.50,0.171
1.81,-43.37,0.171
1.83,-43.24,0.171
1.84,-43.10,0.171
1.85,-42.97,0.171
1.87,-42.83,0.171
1.88,-42.70,0.171
1.89,-42.57,0.171
1.91,-42.43,0.171
1.92,-42.30,0.171
1.93,-42.17,0.171
1.95,-42.03,0.171
1.96,-41.90,0.171
1.97,-41.77,0.171
1.99,-41.63,0.171
2.00,-41.50,0.171
2.01,-41.37,0.171
2.03,-41.23,0.172
2.04,-41.10,0.172
2.05,-40.97,0.172
2.07,-40.83,0.172
2.08,-40.70,0.172
2.09,-40.57,0.172
2.11,-40.43,0.172
2.12,-40.30,0.172
2.13,-40.17,0.172
2.15,-40.03,0.172
2.16,-39.90,0.172
2.17,-39.77,0.172
2.19,-39.63,0.172
2.20,-39.50,0.172
2.21,-39.37,0.172
2.23,-39.23,0.172
2.24,-39.10,0.172
2.25,-38.97,0.172
2.27,-38.83,0.172
2.28,-38.70,0.172
2.29,-38.57,0.172
2.31,-38.43,0.172
2.32,-38.30,0.172
2.33,-38.17,0.172
2.35,-38.03,0.172
2.36,-37.90,0.172
2.37,-37.76,0.172
2.39,-37.63,0.173
2.40,-37.50,0.173
2.41,-37.37,0.173
2.43,-37.23,0.173
2.44,-37.10,0.173
2.45,-36.96,0.173
2.47,-36.83,0.173
2.48,-36.70,0.173
2.49,-36.56,0.173
2.51,-36.43,0.173
2.52,-36.30,0.173
2.53,-36.16,0.173
2.55,-36.03,0.173
2.56,-35.90,0.173
2.57,-35.76,0.173
2.59,-35.63,0.173
2.60,-35.49,0.173
2.61,-35.36,0.173
2.63,-35.23,0.173
2.64,-35.09,0.173
2.65,-34.96,0.173
2.67,-34.83,0.173
2.68,-34.69,0.173
2.69,-34.56,0.173
2.71,-34.43,0.174
2.72,-34.29,0.174
2.73,-34.16,0.174
2.75,-34.03,0.174
2.76,-33.89,0.174
2.77,-33.76,0.174
2.79,-33.63,0.174
2.80,-33.49,0.174
2.81,-33.36,0.174
2.83,-33.23,0.174
2.84,-33.09,0.174
2.85,-32.96,0.174
2.87,-32.83,0.174
2.88,-32.69,0.174
2.89,-32.56,0.174
2.91,-32.42,0.174
2.92,-32.29,0.174
2.93,-32.16,0.174
2.95,-32.02,0.174
2.96,-31.89,0.174
2.97,-31.76,0.174
2.99,-31.62,0.174
3.00,-31.49,0.174
3.01,-31.35,0.174
3.03,-31.22,0.174
3.04,-31.09,0.174
3.05,-30.96,0.174
3.07,-30.82,0.174
3.08,-30.69,0.174
3.09,-30.56,0.174
3.11,-30.42,0.174
3.12,-30.29,0.175
3.13,-30.15,0.175
3.15,-30.02,0.175
3.16,-29.89,0.175
3.17,-29.75,0.175
3.19,-29.62,0.175
3.20,-29.49,0.175
3.21,-29.35,0.175
3.23,-29.22,0.175
3.24,-29.09,0.175
3.25,-28.95,0.175
3.27,-28.82,0.175
3.28,-28.69,0.175
3.29,-28.55,0.175
3.31,-28.42,0.175
3.32,-28.29,0.175
3.33,-28.15,0.175
3.35,-28.02,0.175
3.36,-27.89,0.175
3.37,-27.75,0.175
3.39,-27.62,0.175
3.40,-27.48,0.175
3.41,-27.35,0.175
3.43,-27.22,0.176
3.44,-27.09,0.176
3.45,-26.95,0.176
3.47,-26.82,0.176
3.48,-26.69,0.176
3.49,-26.55,0.176
3.51,-26.42,0.176
3.52,-26.28,0.176
3.53,-26.15,0.176
3.55,-26.02,0.176
3.56,-25.88,0.176
3.57,-25.75,0.176
3.59,-25.62,0.176
3.60,-25.48,0.176
3.61,-25.35,0.176
3.63,-25.22,0.176
3.64,-25.08,0.176
3.65,-24.95,0.176
3.67,-24.82,0.176
3.68,-24.68,0.176
3.69,-24.55,0.176
3.71,-24.42,0.176
3.72,-24.28,0.176
3.73,-24.15,0.177
3.75,-24.02,0.177
3.76,-23.88,0.177
3.77,-23.75,0.177
3.79,-23.62,0.177
3.80,-23.48,0.177
3.81,-23.35,0.177
3.83,-23.22,0.177
3.84,-23.08,0.177
3.85,-22.95,0.177
3.87,-22.81,0.177
3.88,-22.68,0.177
3.89,-22.55,0.177
3.91,-22.41,0.177
3.92,-22.28,0.177
3.93,-22.15,0.177
3.95,-22.01,0.177
3.96,-21.88,0.177
3.97,-21.75,0.178
3.99,-21.61,0.178
4.00,-21.48,0.178
4.01,-21.34,0.178
4.03,-21.21,0.178
4.04,-21.08,0.178
4.05,-20.94,0.178
4.07,-20.81,0.178
4.08,-20.68,0.178
4.09,-20.54,0.178
4.11,-20.41,0.178
4.12,-20.28,0.178
4.13,-20.14,0.178
4.15,-20.01,0.178
4.16,-19.88,0.178
4.17,-19.74,0.178
4.19,-19.61,0.179
4.20,-19.47,0.179
4.21,-19.34,0.179
4.23,-19.21,0.179
4.24,-19.08,0.179
4.25,-18.94,0.179
4.27,-18.81,0.179
4.28,-18.67,0.179
4.29,-18.54,0.179
4.31,-18.41,0.179
4.32,-18.27,0.179
4.33,-18.14,0.179
4.35,-18.01,0.179
4.36,-17.87,0.179
4.37,-17.74,0.179
4.39,-17.61,0.179
4.40,-17.47,0.179
4.41,-17.34,0.179
4.43,-17.21,0.179
4.44,-17.07,0.179
4.45,-16.94,0.179
4.47,-16.81,0.180
4.48,-16.67,0.180
4.49,-16.54,0.180
4.51,-16.40,0.180
4.52,-16.27,0.180
4.53,-16.14,0.180
4.55,-16.01,0.180
4.56,-15.87,0.180
4.57,-15.74,0.180
4.59,-15.61,0.180
4.60,-15.47,0.180
4.61,-15.34,0.180
4.63,-15.20,0.180
4.64,-15.07,0.181
4.65,-14.94,0.181
4.67,-14.80,0.181
4.68,-14.67,0.181
4.69,-14.54,0.181
4.71,-14.40,0.181
4.72,-14.27,0.181
4.73,-14.14,0.181
4.75,-14.00,0.181
4.76,-13.87,0.181
4.77,-13.74,0.181
4.79,-13.60,0.181
4.80,-13.47,0.181
4.81,-13.34,0.181
4.83,-13.20,0.181
4.84,-13.07,0.181
4.85,-12.94,0.181
4.87,-12.80,0.182
4.88,-12.67,0.182
4.89,-12.54,0.182
4.91,-12.40,0.182
4.92,-12.27,0.182
4.93,-12.13,0.182
4.95,-12.00,0.182
4.96,-11.87,0.182
4.97,-11.74,0.182
4.99,-11.60,0.182
5.00,-11.47,0.182
5.01,-11.33,0.182
5.03,-11.20,0.182
5.04,-11.07,0.183
5.05,-10.93,0.183
5.07,-10.80,0.183
5.08,-10.67,0.183
5.09,-10.53,0.183
5.11,-10.40,0.183
5.12,-10.27,0.183
5.13,-10.13,0.183
5.15,-10.00,0.183
5.16,-9.87,0.183
5.17,-9.73,0.183
5.19,-9.60,0.183
5.20,-9.47,0.183
5.21,-9.33,0.183
5.23,-9.20,0.184
5.24,-9.07,0.184
5.25,-8.93,0.184
5.27,-8.80,0.184
5.28,-8.67,0.184
5.29,-8.53,0.184
5.31,-8.40,0.184
5.32,-8.27,0.184
5.33,-8.13,0.184
5.35,-8.00,0.184
5.36,-7.86,0.184
5.37,-7.73,0.184
5.39,-7.60,0.184
5.40,-7.47,0.184
5.41,-7.33,0.185
5.43,-7.20,0.185
5.44,-7.06,0.185
5.45,-6.93,0.185
5.47,-6.80,0.185
5.48,-6.66,0.185
5.49,-6.53,0.185
5.51,-6.40,0.185
5.52,-6.26,0.185
5.53,-6.13,0.185
5.55,-6.00,0.185
5.56,-5.86,0.186
5.57,-5.73,0.186
5.59,-5.60,0.186
5.60,-5.46,0.186
5.61,-5.33,0.186
5.63,-5.20,0.186
5.64,-5.06,0.186
5.65,-4.93,0.186
5.67,-4.79,0.186
5.68,-4.66,0.186
5.69,-4.53,0.186
5.71,-4.39,0.186
5.72,-4.26,0.186
5.73,-4.13,0.187
5.75,-3.99,0.187
5.76,-3.86,0.187
5.77,-3.72,0.187
5.79,-3.59,0.187
5.80,-3.46,0.187
5.81,-3.33,0.187
5.83,-3.19,0.187
5.84,-3.06,0.187
5.85,-2.92,0.187
5.87,-2.79,0.187
5.88,-2.66,0.187
5.89,-2.52,0.187
5.91,-2.39,0.188
5.92,-2.26,0.188
5.93,-2.12,0.188
5.95,-1.99,0.188
5.96,-1.86,0.188
5.97,-1.72,0.188
5.99,-1.59,0.188
6.00,-1.46,0.188
6.01,-1.32,0.188
6.03,-1.19,0.188
6.04,-1.06,0.188
6.05,-0.92,0.188
6.07,-0.79,0.188
6.08,-0.66,0.189
6.09,-0.52,0.189
6.11,-0.39,0.189
6.12,-0.25,0.189
6.13,-0.12,0.189
6.15,0.01,0.189
6.16,0.14,0.189
6.17,0.28,0.189
6.19,0.41,0.189
6.20,0.54,0.189
6.21,0.68,0.189
6.23,0.81,0.189
6.24,0.95,0.189
6.25,1.08,0.189
6.27,1.21,0.190
6.28,1.35,0.190
6.29,1.48,0.190
6.31,1.61,0.190
6.32,1.75,0.190
6.33,1.88,0.190
6.35,2.01,0.190
6.36,2.15,0.190
6.37,2.28,0.190
6.39,2.41,0.190
6.40,2.55,0.191
6.41,2.68,0.191
6.43,2.81,0.191
6.44,2.95,0.191
6.45,3.08,0.191
6.47,3.22,0.191
6.48,3.35,0.191
6.49,3.48,0.191
6.51,3.61,0.191
6.52,3.75,0.191
6.53,3.88,0.192
6.55,4.02,0.192
6.56,4.15,0.192
6.57,4.28,0.192
6.59,4.42,0.192
6.60,4.55,0.192
6.61,4.68,0.192
6.63,4.82,0.192
6.64,4.95,0.192
6.65,5.08,0.193
6.67,5.22,0.193
6.68,5.35,0.193
6.69,5.48,0.193
6.71,5.62,0.193
6.72,5.75,0.193
6.73,5.89,0.193
6.75,6.02,0.193
6.76,6.15,0.193
6.77,6.29,0.193
6.79,6.42,0.193
6.80,6.55,0.194
6.81,6.69,0.194
6.83,6.82,0.194
6.84,6.95,0.194
6.85,7.09,0.194
6.87,7.22,0.194
6.88,7.35,0.194
6.89,7.49,0.194
6.91,7.62,0.194
6.92,7.75,0.194
6.93,7.89,0.195
6.95,8.02,0.195
6.96,8.15,0.195
6.97,8.29,0.195
6.99,8.42,0.195
7.00,8.55,0.195
7.01,8.69,0.195
7.03,8.82,0.195
7.04,8.95,0.195
7.05,9.09,0.195
7.07,9.22,0.196
7.08,9.36,0.196
7.09,9.49,0.196
7.11,9.62,0.196
7.12,9.76,0.196
7.13,9.89,0.196
7.15,10.02,0.196
7.16,10.16,0.196
7.17,10.29,0.196
7.19,10.42,0.196
7.20,10.56,0.196
7.21,10.69,0.197
7.23,10.82,0.197
7.24,10.96,0.197
7.25,11.09,0.197
7.27,11.22,0.197
7.28,11.36,0.197
7.29,11.49,0.197
7.31,11.62,0.197
7.32,11.76,0.197
7.33,11.89,0.198
7.35,12.02,0.198
7.36,12.16,0.198
7.37,12.29,0.198
7.39,12.43,0.198
7.40,12.56,0.198
7.41,12.69,0.198
7.43,12.82,0.198
7.44,12.96,0.198
7.45,13.09,0.199
7.47,13.23,0.199
7.48,13.36,0.199
7.49,13.49,0.199
7.51,13.62,0.199
7.52,13.76,0.199
7.53,13.89,0.199
7.55,14.03,0.199
7.56,14.16,0.200
7.57,14.29,0.200
7.59,14.43,0.200
7.60,14.56,0.200
7.61,14.69,0.200
7.63,14.83,0.200
7.64,14.96,0.201
7.65,15.09,0.201
7.67,15.23,0.201
7.68,15.36,0.201
7.69,15.49,0.201
7.71,15.63,0.201
7.72,15.76,0.201
7.73,15.89,0.201
7.75,16.03,0.201
7.76,16.16,0.202
7.77,16.29,0.202
7.79,16.43,0.202
7.80,16.56,0.202
7.81,16.69,0.202
7.83,16.83,0.202
7.84,16.96,0.202
7.85,17.10,0.202
7.87,17.23,0.203
7.88,17.36,0.203
7.89,17.50,0.203
7.91,17.63,0.203
7.92,17.76,0.203
7.93,17.90,0.203
7.95,18.03,0.203
7.96,18.16,0.203
7.97,18.30,0.203
7.99,18.43,0.203
8.00,18.56,0.203
8.01,18.70,0.204
8.03,18.83,0.204
8.04,18.96,0.204
8.05,19.10,0.204
8.07,19.23,0.204
8.08,19.36,0.204
8.09,19.50,0.204
8.11,19.63,0.204
8.12,19.76,0.205
8.13,19.90,0.205
8.15,20.03,0.205
8.16,20.16,0.205
8.17,20.30,0.205
8.19,20.43,0.206
8.20,20.56,0.206
8.21,20.70,0.206
8.23,20.83,0.206
8.24,20.96,0.206
8.25,21.10,0.206
8.27,21.23,0.207
8.28,21.37,0.207
8.29,21.50,0.207
8.31,21.63,0.207
8.32,21.77,0.207
8.33,21.90,0.207
8.35,22.03,0.208
8.36,22.17,0.208
8.37,22.30,0.208
8.39,22.43,0.208
8.40,22.57,0.208
8.41,22.70,0.208
8.43,22.83,0.208
8.44,22.97,0.209
8.45,23.10,0.209
8.47,23.23,0.209
8.48,23.37,0.209
8.49,23.50,0.209
8.51,23.63,0.209
8.52,23.77,0.210
8.53,23.90,0.210
8.55,24.03,0.210
8.56,24.17,0.210
8.57,24.30,0.210
8.59,24.43,0.210
8.60,24.57,0.210
8.61,24.70,0.211
8.63,24.83,0.211
8.64,24.97,0.211
8.65,25.10,0.211
8.67,25.24,0.211
8.68,25.37,0.211
8.69,25.50,0.211
8.71,25.63,0.212
8.72,25.77,0.212
8.73,25.90,0.212
8.75,26.03,0.212
8.76,26.17,0.212
8.77,26.30,0.212
8.79,26.44,0.213
8.80,26.57,0.213
8.81,26.70,0.213
8.83,26.84,0.213
8.84,26.97,0.213
8.85,27.10,0.213
8.87,27.24,0.214
8.88,27.37,0.214
8.89,27.51,0.214
8.91,27.64,0.214
8.92,27.77,0.214
8.93,27.90,0.214
8.95,28.04,0.214
8.96,28.17,0.215
8.97,28.30,0.215
8.99,28.44,0.215
9.00,28.57,0.215
9.01,28.70,0.215
9.03,28.84,0.215
9.04,28.97,0.215
9.05,29.11,0.216
9.07,29.24,0.216
9.08,29.37,0.216
9.09,29.51,0.216
9.11,29.64,0.216
9.12,29.77,0.216
9.13,29.91,0.216
9.15,30.04,0.217
9.16,30.17,0.217
9.17,30.31,0.217
9.19,30.44,0.217
9.20,30.57,0.217
9.21,30.71,0.217
9.23,30.84,0.217
9.24,30.97,0.218
9.25,31.11,0.218
9.27,31.24,0.218
9.28,31.37,0.218
9.29,31.51,0.218
9.31,31.64,0.218
9.32,31.77,0.219
9.33,31.91,0.219
9.35,32.04,0.219
9.36,32.18,0.219
9.37,32.31,0.219
9.39,32.44,0.219
9.40,32.57,0.219
9.41,32.71,0.220
9.43,32.84,0.220
9.44,32.98,0.220
9.45,33.11,0.220
9.47,33.24,0.220
9.48,33.38,0.220
9.49,33.51,0.220
9.51,33.64,0.220
9.52,33.78,0.221
9.53,33.91,0.221
9.55,34.04,0.221
9.56,34.18,0.221
9.57,34.31,0.221
9.59,34.44,0.221
9.60,34.58,0.222
9.61,34.71,0.222
9.63,34.84,0.222
9.64,34.98,0.222
9.65,35.11,0.222
9.67,35.24,0.222
9.68,35.38,0.223
9.69,35.51,0.223
9.71,35.64,0.223
9.72,35.78,0.223
9.73,35.91,0.223
9.75,36.04,0.223
9.76,36.18,0.223
9.77,36.31,0.224
9.79,36.45,0.224
9.80,36.58,0.224
9.81,36.71,0.225
9.83,36.85,0.225
9.84,36.98,0.225
9.85,37.11,0.225
9.87,37.25,0.226
9.88,37.38,0.226
9.89,37.51,0.226
9.91,37.65,0.226
9.92,37.78,0.226
9.93,37.91,0.226
9.95,38.05,0.226
9.96,38.18,0.226
9.97,38.31,0.226
9.99,38.45,0.227
10.00,38.58,0.227
10.01,38.71,0.227
10.03,38.85,0.227
10.04,38.98,0.227
10.05,39.11,0.227
10.07,39.25,0.227
10.08,39.38,0.228
10.09,39.51,0.228
10.11,39.65,0.228
10.12,39.78,0.228
10.13,39.91,0.228
10.15,40.05,0.228
10.16,40.18,0.228
10.17,40.31,0.229
10.19,40.45,0.229
10.20,40.58,0.229
10.21,40.71,0.229
10.23,40.85,0.229
10.24,40.98,0.229
10.25,41.12,0.230
10.27,41.25,0.230
10.28,41.38,0.230
10.29,41.52,0.230
10.31,41.65,0.230
10.32,41.78,0.230
10.33,41.91,0.231
10.35,42.05,0.231
10.36,42.18,0.231
10.37,42.32,0.231
10.39,42.45,0.231
10.40,42.58,0.232
10.41,42.72,0.232
10.43,42.85,0.232
10.44,42.98,0.232
10.45,43.12,0.232
10.47,43.25,0.233
10.48,43.38,0.233
10.49,43.52,0.233
10.51,43.65,0.233
10.52,43.78,0.233
10.53,43.92,0.234
10.55,44.05,0.234
10.56,44.18,0.234
10.57,44.32,0.234
10.59,44.45,0.235
10.60,44.58,0.235
10.61,44.72,0.235
10.63,44.85,0.235
10.64,44.98,0.236
10.65,45.12,0.236
10.67,45.25,0.236
10.68,45.38,0.236
10.69,45.52,0.236
10.71,45.65,0.237
10.72,45.78,0.238
10.73,45.92,0.238
10.75,46.05,0.238
10.76,46.18,0.238
10.77,46.32,0.238
10.79,46.45,0.239
10.80,46.58,0.239
10.81,46.72,0.239
10.83,46.85,0.239
10.84,46.98,0.240
10.85,47.12,0.240
10.87,47.25,0.240
10.88,47.39,0.241
10.89,47.52,0.241
10.91,47.65,0.241
10.92,47.79,0.241
10.93,47.92,0.242
10.95,48.05,0.242
10.96,48.19,0.242
10.97,48.32,0.243
10.99,48.45,0.243
11.00,48.59,0.243
11.01,48.72,0.243
11.03,48.85,0.244
11.04,48.99,0.244
11.05,49.12,0.244
11.07,49.25,0.245
11.08,49.39,0.245
11.09,49.52,0.245
11.11,49.65,0.246
11.12,49.79,0.246
11.13,49.92,0.246
11.15,50.05,0.247
11.16,50.19,0.247
11.17,50.32,0.248
11.19,50.45,0.248
11.20,50.59,0.248
11.21,50.72,0.248
11.23,50.85,0.249
11.24,50.99,0.249
11.25,51.12,0.249
11.27,51.25,0.250
11.28,51.39,0.250
11.29,51.52,0.250
11.31,51.65,0.251
11.32,51.79,0.251
11.33,51.92,0.252
11.35,52.05,0.252
11.36,52.19,0.253
11.37,52.32,0.253
11.39,52.45,0.253
11.40,52.59,0.254
11.41,52.72,0.254
11.43,52.85,0.254
11.44,52.99,0.255
11.45,53.12,0.255
11.47,53.25,0.255
11.48,53.39,0.256
11.49,53.52,0.257
11.51,53.65,0.257
11.52,53.79,0.258
11.53,53.92,0.259
11.55,54.05,0.259
11.56,54.19,0.259
11.57,54.32,0.260
11.59,54.45,0.260
11.60,54.58,0.261
11.61,54.72,0.261
11.63,54.85,0.263
11.64,54.99,0.263
11.65,55.12,0.264
11.67,55.25,0.265
11.68,55.39,0.266
11.69,55.52,0.266
11.71,55.65,0.267
11.72,55.79,0.268
11.73,55.92,0.269
11.75,56.05,0.270
11.76,56.18,0.270
11.77,56.32,0.271
11.79,56.45,0.272
11.80,56.58,0.273
11.81,56.72,0.275
11.83,56.85,0.276
11.84,56.98,0.277
11.85,57.12,0.278
11.87,57.25,0.279
11.88,57.38,0.281
11.89,57.52,0.281
11.91,57.65,0.284
11.92,57.78,0.286
11.93,57.92,0.288
11.95,58.05,0.289
11.96,58.18,0.290
11.97,58.31,0.292
11.99,58.45,0.294
12.00,58.58,0.295
12.01,58.71,0.298
12.03,58.85,0.301
12.04,58.98,0.302
12.05,59.11,0.304
12.07,59.24,0.307
12.08,59.38,0.310
12.09,59.51,0.313
12.11,59.64,0.316
12.12,59.78,0.318
12.13,59.91,0.321
12.15,60.04,0.325
12.16,60.17,0.328
12.17,60.31,0.331
12.19,60.44,0.334
12.20,60.57,0.338
12.21,60.70,0.341
12.23,60.83,0.345
12.24,60.97,0.348
12.25,61.10,0.353
12.27,61.23,0.356
12.28,61.36,0.361
12.29,61.50,0.367
12.31,61.63,0.371
12.32,61.76,0.376
12.33,61.89,0.381
12.35,62.03,0.385
12.36,62.16,0.392
12.37,62.29,0.396
12.39,62.42,0.403
12.40,62.55,0.408
12.41,62.68,0.415
12.43,62.82,0.417
12.44,62.95,0.426
12.45,63.08,0.432
12.47,63.21,0.438
12.48,63.34,0.445
12.49,63.47,0.450
12.51,63.60,0.457
12.52,63.74,0.464
12.53,63.87,0.471
12.55,64.00,0.477
12.56,64.13,0.486
12.57,64.26,0.490
12.59,64.39,0.499
12.60,64.52,0.505
12.61,64.65,0.512
12.63,64.79,0.520
12.64,64.92,0.524
12.65,65.05,0.533
12.67,65.18,0.538
12.68,65.31,0.545
12.69,65.44,0.551
12.71,65.57,0.557
12.72,65.70,0.566
12.73,65.84,0.570
12.75,65.97,0.576
12.76,66.10,0.584
12.77,66.23,0.588
12.79,66.36,0.595
12.80,66.49,0.602
12.81,66.62,0.606
12.83,66.75,0.613
12.84,66.88,0.619
12.85,67.02,0.625
12.87,67.15,0.629
12.88,67.28,0.636
12.89,67.41,0.642
12.91,67.54,0.647
12.92,67.67,0.655
12.93,67.80,0.660
12.95,67.94,0.666
12.96,68.07,0.675
12.97,68.20,0.681
12.99,68.33,0.690
13.00,68.46,0.697
13.01,68.59,0.706
13.03,68.72,0.716
13.04,68.85,0.727
13.05,68.98,0.737
13.07,69.11,0.750
13.08,69.24,0.762
13.09,69.37,0.777
13.11,69.50,0.794
13.12,69.63,0.811
13.13,69.76,0.832
13.15,69.89,0.854
13.16,70.02,0.876
13.17,70.14,0.900
13.19,70.27,0.927
13.20,70.40,0.953
13.21,70.52,0.976
13.23,70.65,0.995
13.24,70.77,1.013
13.25,70.90,1.026
13.27,71.03,1.036
13.28,71.16,1.043
13.29,71.29,1.047
13.31,71.41,1.051
13.32,71.55,1.056
13.33,71.68,1.059
13.35,71.81,1.065
13.36,71.94,1.069
13.37,72.07,1.076
13.39,72.20,1.079
13.40,72.33,1.088
13.41,72.46,1.094
13.43,72.59,1.104
13.44,72.72,1.110
13.45,72.86,1.116
13.47,72.99,1.118
13.48,73.12,1.119
13.49,73.25,1.115
13.51,73.39,1.107
13.52,73.52,1.089
13.53,73.66,1.071
13.55,73.79,1.049
13.56,73.93,1.023
13.57,74.07,0.994
13.59,74.21,0.962
13.60,74.35,0.926
13.61,74.49,0.887
13.63,74.64,0.847
13.64,74.78,0.803
13.65,74.93,0.758
13.67,75.07,0.711
13.68,75.22,0.663
13.69,75.37,0.617
13.71,75.52,0.573
13.72,75.66,0.534
13.73,75.81,0.495
13.75,75.96,0.463
13.76,76.10,0.435
13.77,76.25,0.412
13.79,76.39,0.392
13.80,76.54,0.373
13.81,76.68,0.361
13.83,76.82,0.350
13.84,76.96,0.340
13.85,77.10,0.331
13.87,77.24,0.323
13.88,77.38,0.319
13.89,77.51,0.313
13.91,77.65,0.308
13.92,77.79,0.304
13.93,77.93,0.301
13.95,78.06,0.299
13.96,78.20,0.296
13.97,78.33,0.294
13.99,78.47,0.292
14.00,78.60,0.291
14.01,78.74,0.288
14.03,78.87,0.288
14.04,79.00,0.287
14.05,79.14,0.286
14.07,79.27,0.286
14.08,79.41,0.285
14.09,79.54,0.285
14.11,79.68,0.285
14.12,79.81,0.284
14.13,79.94,0.284
14.15,80.08,0.284
14.16,80.21,0.283
14.17,80.34,0.283
14.19,80.48,0.283
14.20,80.61,0.283
14.21,80.74,0.283
14.23,80.88,0.282
14.24,81.01,0.282
14.25,81.15,0.282
14.27,81.28,0.282
14.28,81.41,0.282
14.29,81.55,0.282
14.31,81.68,0.282
14.32,81.81,0.281
14.33,81.95,0.281
14.35,82.08,0.281
14.36,82.21,0.281
14.37,82.35,0.281
14.39,82.48,0.281
14.40,82.61,0.281
14.41,82.75,0.281
14.43,82.88,0.281
14.44,83.01,0.281
14.45,83.15,0.281
14.47,83.28,0.281
14.48,83.41,0.281
14.49,83.55,0.281
14.51,83.68,0.281
14.52,83.81,0.281
14.53,83.95,0.281
14.55,84.08,0.281
14.56,84.21,0.281
14.57,84.35,0.281
14.59,84.48,0.281
14.60,84.61,0.281
14.61,84.75,0.281
14.63,84.88,0.281
14.64,85.02,0.281
14.65,85.15,0.281
14.67,85.28,0.281
14.68,85.42,0.281
14.69,85.55,0.281
14.71,85.68,0.281
14.72,85.82,0.281
14.73,85.95,0.281
14.75,86.08,0.282
14.76,86.22,0.282
14.77,86.35,0.282
14.79,86.48,0.282
14.80,86.62,0.282
14.81,86.75,0.282
14.83,86.88,0.282
14.84,87.02,0.282
14.85,87.15,0.282
14.87,87.28,0.283
14.88,87.42,0.283
14.89,87.55,0.283
14.91,87.68,0.283
14.92,87.82,0.283
14.93,87.95,0.283
14.95,88.08,0.283
14.96,88.22,0.283
14.97,88.35,0.284
14.99,88.49,0.284
15.00,88.62,0.284
15.01,88.75,0.284
15.03,88.88,0.284
15.04,89.02,0.284
15.05,89.15,0.284
15.07,89.29,0.285
15.08,89.42,0.285
15.09,89.55,0.285
15.11,89.69,0.285
15.12,89.82,0.285
15.13,89.95,0.285
15.15,90.09,0.286
15.16,90.22,0.286
15.17,90.35,0.286
15.19,90.49,0.286
15.20,90.62,0.286
15.21,90.75,0.286
15.23,90.89,0.287
15.24,91.02,0.287
15.25,91.15,0.287
15.27,91.29,0.287
15.28,91.42,0.287
15.29,91.55,0.288
15.31,91.69,0.288
15.32,91.82,0.288
15.33,91.95,0.288
15.35,92.09,0.288
15.36,92.22,0.288
15.37,92.35,0.289
15.39,92.49,0.289
15.40,92.62,0.289
15.41,92.75,0.289
15.43,92.89,0.289
15.44,93.02,0.290
15.45,93.15,0.290
15.47,93.29,0.290
15.48,93.42,0.290
15.49,93.55,0.290
15.51,93.69,0.291
15.52,93.82,0.291
15.53,93.95,0.291
15.55,94.09,0.291
15.56,94.22,0.291
15.57,94.35,0.291
15.59,94.49,0.292
15.60,94.62,0.292
15.61,94.75,0.292
15.63,94.89,0.292
15.64,95.02,0.292
15.65,95.15,0.293
15.67,95.29,0.293
15.68,95.42,0.293
15.69,95.56,0.293
15.71,95.69,0.293
15.72,95.82,0.294
15.73,95.96,0.294
15.75,96.09,0.294
15.76,96.22,0.294
15.77,96.36,0.295
15.79,96.49,0.295
15.80,96.62,0.295
15.81,96.76,0.295
15.83,96.89,0.295
15.84,97.02,0.295
15.85,97.15,0.296
15.87,97.29,0.296
15.88,97.42,0.296
15.89,97.55,0.296
15.91,97.69,0.296
15.92,97.82,0.296
15.93,97.96,0.297
15.95,98.09,0.297
15.96,98.22,0.297
15.97,98.36,0.297
15.99,98.49,0.297
16.00,98.62,0.297
16.01,98.75,0.298
16.03,98.89,0.298
16.04,99.02,0.298
16.05,99.16,0.298
16.07,99.29,0.298
16.08,99.42,0.299
16.09,99.56,0.299
16.11,99.69,0.299
16.12,99.82,0.299
16.13,99.96,0.299
16.15,100.09,0.300
16.16,100.22,0.300
16.17,100.36,0.300
16.19,100.49,0.300
16.20,100.62,0.300
16.21,100.76,0.300
16.23,100.89,0.301
16.24,101.02,0.301
16.25,101.16,0.301
16.27,101.29,0.301
16.28,101.42,0.301
16.29,101.56,0.301
16.31,101.69,0.301
16.32,101.82,0.301
16.33,101.96,0.302
16.35,102.09,0.302
16.36,102.23,0.302
16.37,102.36,0.302
16.39,102.49,0.302
16.40,102.62,0.302
16.41,102.76,0.302
16.43,102.89,0.303
16.44,103.03,0.303
16.45,103.16,0.303
16.47,103.29,0.303
16.48,103.43,0.303
16.49,103.56,0.303
16.51,103.69,0.303
16.52,103.83,0.303
16.53,103.96,0.304
16.55,104.09,0.304
16.56,104.23,0.304
16.57,104.36,0.304
16.59,104.49,0.304
16.60,104.63,0.304
16.61,104.76,0.304
16.63,104.89,0.304
16.64,105.03,0.305
16.65,105.16,0.305
16.67,105.29,0.305
16.68,105.43,0.305
16.69,105.56,0.305
16.71,105.69,0.305
16.72,105.83,0.305
16.73,105.96,0.305
16.75,106.09,0.306
16.76,106.23,0.306
16.77,106.36,0.306
16.79,106.49,0.306
16.80,106.63,0.306
16.81,106.76,0.306
16.83,106.90,0.306
16.84,107.03,0.306
16.85,107.16,0.306
16.87,107.29,0.307
16.88,107.43,0.307
16.89,107.56,0.307
16.91,107.70,0.307
16.92,107.83,0.307
16.93,107.96,0.307
16.95,108.10,0.307
16.96,108.23,0.307
16.97,108.36,0.308
16.99,108.50,0.308
17.00,108.63,0.308
17.01,108.76,0.308
17.03,108.90,0.308
17.04,109.03,0.308
17.05,109.16,0.308
17.07,109.30,0.308
17.08,109.43,0.309
17.09,109.56,0.309
17.11,109.70,0.309
17.12,109.83,0.309
17.13,109.96,0.309
17.15,110.10,0.309
17.16,110.23,0.309
17.17,110.36,0.309
17.19,110.50,0.309
17.20,110.63,0.309
17.21,110.76,0.309
17.23,110.90,0.310
17.24,111.03,0.310
17.25,111.16,0.310
17.27,111.30,0.310
17.28,111.43,0.310
17.29,111.57,0.310
17.31,111.70,0.310
17.32,111.83,0.310
17.33,111.97,0.310
17.35,112.10,0.310
17.36,112.23,0.311
17.37,112.37,0.311
17.39,112.50,0.311
17.40,112.63,0.311
17.41,112.77,0.311
17.43,112.90,0.311
17.44,113.03,0.311
17.45,113.17,0.311
17.47,113.30,0.311
17.48,113.43,0.312
17.49,113.57,0.312
17.51,113.70,0.312
17.52,113.83,0.312
17.53,113.97,0.312
17.55,114.10,0.312
17.56,114.23,0.312
17.57,114.37,0.312
17.59,114.50,0.312
17.60,114.63,0.312
17.61,114.77,0.313
17.63,114.90,0.313
17.64,115.03,0.313
17.65,115.17,0.313
17.67,115.30,0.313
17.68,115.43,0.313
17.69,115.57,0.313
17.71,115.70,0.313
17.72,115.83,0.313
17.73,115.97,0.313
17.75,116.10,0.313
17.76,116.23,0.313
17.77,116.37,0.314
17.79,116.50,0.314
17.80,116.63,0.314
17.81,116.77,0.314
17.83,116.90,0.314
17.84,117.04,0.314
17.85,117.17,0.314
17.87,117.30,0.314
17.88,117.44,0.314
17.89,117.57,0.314
17.91,117.70,0.315
17.92,117.84,0.315
17.93,117.97,0.315
17.95,118.10,
17.96,118.24,
17.97,118.37,
17.99,,
17.99,,

[step]
Ramp 10.00 °C/min to -60.00 °C
Time,Temperature,Heat Flow (Normalized)
min,°C,W/g
18.99,120.10,-0.034
19.01,120.10,-0.034
19.02,120.10,-0.034
19.03,120.10,-0.035
19.05,120.09,-0.032
19.06,120.07,-0.022
19.07,120.04,-0.012
19.09,120.01,-0.008
19.10,119.96,-0.012
19.11,119.89,-0.029
19.13,119.82,-0.061
19.14,119.74,-0.093
19.15,119.65,-0.127
19.17,119.55,-0.161
19.18,119.46,-0.190
19.19,119.35,-0.215
19.21,119.25,-0.239
19.22,119.14,-0.255
19.23,119.03,-0.269
19.25,118.91,-0.286
19.26,118.80,-0.296
19.27,118.68,-0.305
19.29,118.56,-0.318
19.30,118.44,-0.324
19.31,118.31,-0.333
19.33,118.19,-0.340
19.34,118.06,-0.345
19.35,117.94,-0.352
19.37,117.81,-0.354
19.38,117.69,-0.358
19.39,117.56,-0.363
19.41,117.43,-0.365
19.42,117.30,-0.367
19.43,117.17,-0.370
19.45,117.05,-0.371
19.46,116.92,-0.373
19.47,116.79,-0.374
19.49,116.66,-0.375
19.50,116.53,-0.377
19.51,116.39,-0.378
19.53,116.27,-0.379
19.54,116.13,-0.379
19.55,116.00,-0.380
19.57,115.87,-0.381
19.58,115.74,-0.382
19.59,115.61,-0.382
19.61,115.48,-0.382
19.62,115.35,-0.382
19.63,115.22,-0.383
19.65,115.09,-0.383
19.66,114.95,-0.383
19.67,114.82,-0.383
19.69,114.69,-0.384
19.70,114.56,-0.384
19.71,114.43,-0.384
19.73,114.29,-0.384
19.74,114.16,-0.385
19.75,114.03,-0.385
19.77,113.90,-0.385
19.78,113.77,-0.385
19.79,113.63,-0.385
19.81,113.50,-0.385
19.82,113.37,-0.386
19.83,113.24,-0.386
19.85,113.10,-0.386
19.86,112.97,-0.386
19.87,112.84,-0.386
19.89,112.71,-0.386
19.90,112.58,-0.386
19.91,112.44,-0.387
19.93,112.31,-0.387
19.94,112.18,-0.387
19.95,112.05,-0.387
19.97,111.91,-0.387
19.98,111.78,-0.387
19.99,111.65,-0.387
20.01,111.52,-0.387
20.02,111.38,-0.387
20.03,111.25,-0.387
20.05,111.12,-0.387
20.06,110.98,-0.387
20.07,110.85,-0.387
20.09,110.72,-0.387
20.10,110.59,-0.387
20.11,110.45,-0.387
20.13,110.32,-0.387
20.14,110.19,-0.388
20.15,110.06,-0.388
20.17,109.92,-0.388
20.18,109.79,-0.388
20.19,109.66,-0.387
20.21,109.52,-0.388
20.22,109.39,-0.388
20.23,109.26,-0.388
20.25,109.12,-0.388
20.26,108.99,-0.387
20.27,108.86,-0.387
20.29,108.73,-0.387
20.30,108.59,-0.387
20.31,108.46,-0.387
20.33,108.33,-0.387
20.34,108.20,-0.387
20.35,108.06,-0.387
20.37,107.93,-0.387
20.38,107.80,-0.387
20.39,107.66,-0.387
20.41,107.53,-0.387
20.42,107.40,-0.387
20.43,107.27,-0.387
20.45,107.13,-0.386
20.46,107.00,-0.386
20.47,106.87,-0.386
20.49,106.73,-0.386
20.50,106.60,-0.386
20.51,106.47,-0.386
20.53,106.33,-0.386
20.54,106.20,-0.386
20.55,106.07,-0.386
20.57,105.93,-0.386
20.58,105.80,-0.386
20.59,105.67,-0.386
20.61,105.54,-0.385
20.62,105.40,-0.385
20.63,105.27,-0.385
20.65,105.14,-0.385
20.66,105.00,-0.385
20.67,104.87,-0.385
20.69,104.74,-0.385
20.70,104.60,-0.385
20.71,104.47,-0.385
20.73,104.34,-0.384
20.74,104.20,-0.384
20.75,104.07,-0.384
20.77,103.94,-0.384
20.78,103.80,-0.384
20.79,103.67,-0.384
20.81,103.54,-0.384
20.82,103.41,-0.384
20.83,103.27,-0.384
20.85,103.14,-0.384
20.86,103.01,-0.383
20.87,102.87,-0.383
20.89,102.74,-0.383
20.90,102.61,-0.383
20.91,102.47,-0.383
20.93,102.34,-0.383
20.94,102.21,-0.383
20.95,102.07,-0.383
20.97,101.94,-0.383
20.98,101.81,-0.383
20.99,101.67,-0.382
21.01,101.54,-0.382
21.02,101.41,-0.382
21.03,101.27,-0.382
21.05,101.14,-0.382
21.06,101.01,-0.382
21.07,100.87,-0.382
21.09,100.74,-0.382
21.10,100.61,-0.381
21.11,100.47,-0.381
21.13,100.34,-0.381
21.14,100.21,-0.381
21.15,100.08,-0.381
21.17,99.94,-0.381
21.18,99.81,-0.381
21.19,99.68,-0.380
21.21,99.54,-0.380
21.22,99.41,-0.380
21.23,99.28,-0.380
21.25,99.14,-0.380
21.26,99.01,-0.380
21.27,98.88,-0.380
21.29,98.74,-0.380
21.30,98.61,-0.379
21.31,98.48,-0.379
21.33,98.34,-0.379
21.34,98.21,-0.379
21.35,98.08,-0.379
21.37,97.94,-0.379
21.38,97.81,-0.379
21.39,97.68,-0.379
21.41,97.55,-0.379
21.42,97.41,-0.379
21.43,97.28,-0.378
21.45,97.15,-0.378
21.46,97.01,-0.378
21.47,96.88,-0.378
21.49,96.75,-0.378
21.50,96.61,-0.378
21.51,96.48,-0.378
21.53,96.35,-0.377
21.54,96.21,-0.377
21.55,96.08,-0.377
21.57,95.95,-0.377
21.58,95.81,-0.377
21.59,95.68,-0.377
21.61,95.55,-0.377
21.62,95.41,-0.376
21.63,95.28,-0.376
21.65,95.15,-0.376
21.66,95.02,-0.376
21.67,94.88,-0.376
21.69,94.75,-0.376
21.70,94.62,-0.376
21.71,94.48,-0.376
21.73,94.35,-0.376
21.74,94.21,-0.375
21.75,94.08,-0.375
21.77,93.95,-0.375
21.78,93.82,-0.375
21.79,93.68,-0.375
21.81,93.55,-0.375
21.82,93.42,-0.375
21.83,93.28,-0.375
21.85,93.15,-0.375
21.86,93.02,-0.374
21.87,92.88,-0.374
21.89,92.75,-0.374
21.90,92.62,-0.374
21.91,92.48,-0.374
21.93,92.35,-0.374
21.94,92.22,-0.374
21.95,92.08,-0.374
21.97,91.95,-0.374
21.98,91.82,-0.374
21.99,91.69,-0.373
22.01,91.55,-0.373
22.02,91.42,-0.373
22.03,91.29,-0.373
22.05,91.15,-0.373
22.06,91.02,-0.373
22.07,90.89,-0.373
22.09,90.75,-0.373
22.10,90.62,-0.372
22.11,90.49,-0.372
22.13,90.35,-0.372
22.14,90.22,-0.372
22.15,90.09,-0.372
22.17,89.95,-0.372
22.18,89.82,-0.372
22.19,89.69,-0.371
22.21,89.55,-0.371
22.22,89.42,-0.371
22.23,89.29,-0.371
22.25,89.15,-0.371
22.26,89.02,-0.371
22.27,88.89,-0.370
22.29,88.75,-0.370
22.30,88.62,-0.370
22.31,88.49,-0.370
22.33,88.35,-0.370
22.34,88.22,-0.370
22.35,88.09,-0.370
22.37,87.96,-0.370
22.38,87.82,-0.369
22.39,87.69,-0.369
22.41,87.56,-0.369
22.42,87.42,-0.369
22.43,87.29,-0.369
22.45,87.16,-0.369
22.46,87.02,-0.369
22.47,86.89,-0.368
22.49,86.76,-0.368
22.50,86.62,-0.368
22.51,86.49,-0.368
22.53,86.36,-0.368
22.54,86.23,-0.368
22.55,86.09,-0.368
22.57,85.96,-0.368
22.58,85.83,-0.368
22.59,85.69,-0.367
22.61,85.56,-0.367
22.62,85.43,-0.367
22.63,85.29,-0.367
22.65,85.16,-0.367
22.66,85.03,-0.367
22.67,84.89,-0.367
22.69,84.76,-0.367
22.70,84.63,-0.367
22.71,84.49,-0.367
22.73,84.36,-0.367
22.74,84.23,-0.366
22.75,84.09,-0.366
22.77,83.96,-0.366
22.78,83.83,-0.366
22.79,83.69,-0.366
22.81,83.56,-0.366
22.82,83.43,-0.366
22.83,83.30,-0.366
22.85,83.16,-0.366
22.86,83.03,-0.366
22.87,82.90,-0.366
22.89,82.76,-0.365
22.90,82.63,-0.365
22.91,82.49,-0.365
22.93,82.36,-0.365
22.94,82.23,-0.365
22.95,82.09,-0.365
22.97,81.96,-0.365
22.98,81.83,-0.365
22.99,81.70,-0.365
23.01,81.56,-0.365
23.02,81.43,-0.365
23.03,81.30,-0.365
23.05,81.16,-0.365
23.06,81.03,-0.365
23.07,80.90,-0.365
23.09,80.76,-0.365
23.10,80.63,-0.364
23.11,80.50,-0.364
23.13,80.36,-0.364
23.14,80.23,-0.364
23.15,80.10,-0.364
23.17,79.96,-0.364
23.18,79.83,-0.364
23.19,79.70,-0.364
23.21,79.57,-0.364
23.22,79.43,-0.364
23.23,79.30,-0.364
23.25,79.16,-0.363
23.26,79.03,-0.363
23.27,78.90,-0.363
23.29,78.77,-0.363
23.30,78.63,-0.363
23.31,78.50,-0.363
23.33,78.37,-0.363
23.34,78.23,-0.363
23.35,78.10,-0.363
23.37,77.97,-0.363
23.38,77.83,-0.362
23.39,77.70,-0.362
23.41,77.57,-0.362
23.42,77.43,-0.362
23.43,77.30,-0.362
23.45,77.17,-0.362
23.46,77.03,-0.362
23.47,76.90,-0.362
23.49,76.77,-0.362
23.50,76.63,-0.362
23.51,76.50,-0.362
23.53,76.37,-0.361
23.54,76.24,-0.361
23.55,76.10,-0.361
23.57,75.97,-0.361
23.58,75.84,-0.361
23.59,75.70,-0.361
23.61,75.57,-0.361
23.62,75.44,-0.361
23.63,75.30,-0.361
23.65,75.17,-0.360
23.66,75.04,-0.360
23.67,74.90,-0.360
23.69,74.77,-0.360
23.70,74.64,-0.360
23.71,74.50,-0.360
23.73,74.37,-0.360
23.74,74.24,-0.360
23.75,74.10,-0.360
23.77,73.97,-0.360
23.78,73.84,-0.359
23.79,73.70,-0.359
23.81,73.57,-0.359
23.82,73.44,-0.359
23.83,73.30,-0.359
23.85,73.17,-0.359
23.86,73.04,-0.359
23.87,72.90,-0.359
23.89,72.77,-0.359
23.90,72.64,-0.358
23.91,72.50,-0.358
23.93,72.37,-0.358
23.94,72.24,-0.358
23.95,72.11,-0.358
23.97,71.97,-0.358
23.98,71.84,-0.358
23.99,71.71,-0.358
24.01,71.57,-0.358
24.02,71.44,-0.358
24.03,71.30,-0.358
24.05,71.17,-0.357
24.06,71.04,-0.357
24.07,70.91,-0.357
24.09,70.77,-0.357
24.10,70.64,-0.357
24.11,70.51,-0.357
24.13,70.37,-0.357
24.14,70.24,-0.357
24.15,70.11,-0.357
24.17,69.97,-0.356
24.18,69.84,-0.356
24.19,69.71,-0.356
24.21,69.57,-0.356
24.22,69.44,-0.356
24.23,69.31,-0.356
24.25,69.17,-0.356
24.26,69.04,-0.356
24.27,68.91,-0.356
24.29,68.78,-0.356
24.30,68.64,-0.355
24.31,68.51,-0.355
24.33,68.37,-0.355
24.34,68.24,-0.355
24.35,68.11,-0.355
24.37,67.98,-0.355
24.38,67.84,-0.355
24.39,67.71,-0.355
24.41,67.58,-0.355
24.42,67.44,-0.355
24.43,67.31,-0.354
24.45,67.18,-0.354
24.46,67.04,-0.354
24.47,66.91,-0.354
24.49,66.78,-0.354
24.50,66.64,-0.354
24.51,66.51,-0.354
24.53,66.38,-0.354
24.54,66.24,-0.353
24.55,66.11,-0.353
24.57,65.98,-0.353
24.58,65.84,-0.353
24.59,65.71,-0.353
24.61,65.58,-0.353
24.62,65.44,-0.353
24.63,65.31,-0.353
24.65,65.18,-0.353
24.66,65.04,-0.353
24.67,64.91,-0.353
24.69,64.78,-0.353
24.70,64.64,-0.353
24.71,64.51,-0.352
24.73,64.38,-0.352
24.74,64.24,-0.352
24.75,64.11,-0.352
24.77,63.98,-0.352
24.78,63.84,-0.352
24.79,63.71,-0.352
24.81,63.58,-0.352
24.82,63.45,-0.352
24.83,63.31,-0.351
24.85,63.18,-0.351
24.86,63.05,-0.351
24.87,62.91,-0.351
24.89,62.78,-0.351
24.90,62.65,-0.351
24.91,62.52,-0.351
24.93,62.38,-0.350
24.94,62.25,-0.350
24.95,62.11,-0.350
24.97,61.98,-0.350
24.98,61.85,-0.350
24.99,61.71,-0.350
25.01,61.58,-0.350
25.02,61.45,-0.350
25.03,61.32,-0.350
25.05,61.18,-0.350
25.06,61.05,-0.349
25.07,60.92,-0.349
25.09,60.78,-0.349
25.10,60.65,-0.349
25.11,60.52,-0.349
25.13,60.38,-0.349
25.14,60.25,-0.349
25.15,60.12,-0.349
25.17,59.98,-0.349
25.18,59.85,-0.349
25.19,59.72,-0.349
25.21,59.58,-0.348
25.22,59.45,-0.348
25.23,59.32,-0.348
25.25,59.18,-0.348
25.26,59.05,-0.348
25.27,58.92,-0.348
25.29,58.78,-0.348
25.30,58.65,-0.348
25.31,58.52,-0.347
25.33,58.39,-0.347
25.34,58.25,-0.347
25.35,58.12,-0.347
25.37,57.99,-0.347
25.38,57.85,-0.347
25.39,57.72,-0.347
25.41,57.59,-0.347
25.42,57.45,-0.346
25.43,57.32,-0.346
25.45,57.19,-0.346
25.46,57.05,-0.346
25.47,56.92,-0.346
25.49,56.79,-0.346
25.50,56.65,-0.346
25.51,56.52,-0.346
25.53,56.39,-0.346
25.54,56.25,-0.346
25.55,56.12,-0.346
25.57,55.99,-0.345
25.58,55.86,-0.345
25.59,55.72,-0.345
25.61,55.59,-0.345
25.62,55.45,-0.345
25.63,55.32,-0.345
25.65,55.19,-0.345
25.66,55.06,-0.345
[...]
81.33,-28.31,0.173
81.34,-28.17,0.173
81.35,-28.04,0.173
81.37,-27.91,0.173
81.38,-27.77,0.173
81.39,-27.64,0.173
81.41,-27.51,0.173
81.42,-27.37,0.174
81.43,-27.24,0.174
81.45,-27.11,0.174
81.46,-26.97,0.174
81.47,-26.84,0.174
81.49,-26.71,0.174
81.50,-26.57,0.174
81.51,-26.44,0.174
81.53,-26.30,0.174
81.54,-26.17,0.174
81.55,-26.04,0.174
81.57,-25.90,0.174
81.58,-25.77,0.174
81.59,-25.64,0.174
81.61,-25.50,0.174
81.62,-25.37,0.174
81.63,-25.24,0.174
81.65,-25.10,0.174
81.66,-24.97,0.174
81.67,-24.84,0.174
81.69,-24.70,0.175
81.70,-24.57,0.175
81.71,-24.44,0.175
81.73,-24.30,0.175
81.74,-24.17,0.175
81.75,-24.03,0.175
81.77,-23.90,0.175
81.78,-23.77,0.175
81.79,-23.63,0.175
81.81,-23.50,0.175
81.82,-23.37,0.175
81.83,-23.23,0.175
81.85,-23.10,0.175
81.86,-22.97,0.175
81.87,-22.83,0.175
81.89,-22.70,0.175
81.90,-22.57,0.175
81.91,-22.43,0.175
81.93,-22.30,0.176
81.94,-22.17,0.176
81.95,-22.03,0.176
81.97,-21.90,0.176
81.98,-21.77,0.176
81.99,-21.63,0.176
82.01,-21.50,0.176
82.02,-21.36,0.176
82.03,-21.23,0.176
82.05,-21.10,0.176
82.06,-20.96,0.176
82.07,-20.83,0.176
82.09,-20.70,0.176
82.10,-20.57,0.176
82.11,-20.43,0.176
82.13,-20.30,0.177
82.14,-20.16,0.177
82.15,-20.03,0.177
82.17,-19.90,0.177
82.18,-19.76,0.177
82.19,-19.63,0.177
82.21,-19.50,0.177
82.22,-19.36,0.177
82.23,-19.23,0.177
82.25,-19.10,0.177
82.26,-18.96,0.177
82.27,-18.83,0.177
82.29,-18.70,0.177
82.30,-18.56,0.177
82.31,-18.43,0.177
82.33,-18.30,0.177
82.34,-18.16,0.177
82.35,-18.03,0.177
82.37,-17.89,0.178
82.38,-17.76,0.178
82.39,-17.63,0.178
82.41,-17.49,0.178
82.42,-17.36,0.178
82.43,-17.23,0.178
82.45,-17.09,0.178
82.46,-16.96,0.178
82.47,-16.83,0.178
82.49,-16.69,0.178
82.50,-16.56,0.178
82.51,-16.43,0.178
82.53,-16.29,0.178
82.54,-16.16,0.178
82.55,-16.03,0.178
82.57,-15.89,0.178
82.58,-15.76,0.179
82.59,-15.63,0.179
82.61,-15.49,0.179
82.62,-15.36,0.179
82.63,-15.22,0.179
82.65,-15.09,0.179
82.66,-14.96,0.179
82.67,-14.83,0.179
82.69,-14.69,0.179
82.70,-14.56,0.179
82.71,-14.42,0.179
82.73,-14.29,0.179
82.74,-14.16,0.179
82.75,-14.02,0.179
82.77,-13.89,0.179
82.78,-13.76,0.179
82.79,-13.62,0.179
82.81,-13.49,0.179
82.82,-13.36,0.180
82.83,-13.22,0.180
82.85,-13.09,0.180
82.86,-12.96,0.180
82.87,-12.82,0.180
82.89,-12.69,0.180
82.90,-12.55,0.180
82.91,-12.42,0.180
82.93,-12.29,0.180
82.94,-12.15,0.180
82.95,-12.02,0.180
82.97,-11.88,0.180
82.98,-11.75,0.180
82.99,-11.62,0.181
83.01,-11.48,0.181
83.02,-11.35,0.181
83.03,-11.21,0.181
83.05,-11.08,0.181
83.06,-10.95,0.181
83.07,-10.81,0.181
83.09,-10.68,0.181
83.10,-10.55,0.181
83.11,-10.41,0.182
83.13,-10.28,0.182
83.14,-10.15,0.182
83.15,-10.01,0.182
83.17,-9.88,0.182
83.18,-9.75,0.182
83.19,-9.61,0.182
83.21,-9.48,0.182
83.22,-9.35,0.182
83.23,-9.21,0.182
83.25,-9.08,0.182
83.26,-8.95,0.182
83.27,-8.81,0.182
83.29,-8.68,0.182
83.30,-8.55,0.182
83.31,-8.41,0.182
83.33,-8.28,0.182
83.34,-8.15,0.182
83.35,-8.01,0.182
83.37,-7.88,0.182
83.38,-7.75,0.183
83.39,-7.61,0.183
83.41,-7.48,0.183
83.42,-7.35,0.183
83.43,-7.21,0.183
83.45,-7.08,0.183
83.46,-6.95,0.183
83.47,-6.81,0.183
83.49,-6.68,0.183
83.50,-6.55,0.183
83.51,-6.41,0.183
83.53,-6.28,0.183
83.54,-6.15,0.183
83.55,-6.01,0.184
83.57,-5.88,0.184
83.58,-5.75,0.184
83.59,-5.61,0.184
83.61,-5.48,0.184
83.62,-5.35,0.184
83.63,-5.21,0.184
83.65,-5.08,0.184
83.66,-4.95,0.184
83.67,-4.81,0.184
83.69,-4.68,0.184
83.70,-4.55,0.184
83.71,-4.41,0.185
83.73,-4.28,0.185
83.74,-4.15,0.185
83.75,-4.01,0.185
83.77,-3.88,0.185
83.78,-3.75,0.185
83.79,-3.61,0.185
83.81,-3.48,0.185
83.82,-3.34,0.185
83.83,-3.21,0.185
83.85,-3.08,0.185
83.86,-2.94,0.186
83.87,-2.81,0.186
83.89,-2.68,0.186
83.90,-2.54,0.186
83.91,-2.41,0.186
83.93,-2.28,0.186
83.94,-2.14,0.186
83.95,-2.01,0.186
83.97,-1.88,0.186
83.98,-1.74,0.186
83.99,-1.61,0.186
84.01,-1.48,0.187
84.02,-1.34,0.187
84.03,-1.21,0.187
84.05,-1.08,0.187
84.06,-0.94,0.187
84.07,-0.81,0.187
84.09,-0.67,0.187
84.10,-0.54,0.187
84.11,-0.41,0.187
84.13,-0.27,0.187
84.14,-0.14,0.188
84.15,-0.01,0.188
84.17,0.13,0.188
84.18,0.26,0.188
84.19,0.39,0.188
84.21,0.53,0.188
84.22,0.66,0.188
84.23,0.79,0.188
84.25,0.93,0.188
84.26,1.06,0.189
84.27,1.19,0.189
84.29,1.33,0.189
84.30,1.46,0.189
84.31,1.59,0.189
84.33,1.73,0.189
84.34,1.86,0.189
84.35,1.99,0.189
84.37,2.13,0.189
84.38,2.26,0.190
84.39,2.39,0.190
84.41,2.53,0.190
84.42,2.66,0.190
84.43,2.79,0.190
84.45,2.93,0.190
84.46,3.06,0.190
84.47,3.19,0.191
84.49,3.33,0.191
84.50,3.46,0.191
84.51,3.60,0.191
84.53,3.73,0.191
84.54,3.86,0.191
84.55,4.00,0.191
84.57,4.13,0.192
84.58,4.26,0.192
84.59,4.40,0.192
84.61,4.53,0.192
84.62,4.66,0.192
84.63,4.80,0.192
84.65,4.93,0.192
84.66,5.06,0.193
84.67,5.20,0.193
84.69,5.33,0.193
84.70,5.46,0.193
84.71,5.60,0.193
84.73,5.73,0.193
84.74,5.86,0.194
84.75,6.00,0.194
84.77,6.13,0.194
84.78,6.26,0.194
84.79,6.40,0.194
84.81,6.53,0.195
84.82,6.66,0.195
84.83,6.80,0.195
84.85,6.93,0.195
84.86,7.06,0.195
84.87,7.20,0.196
84.89,7.33,0.196
84.90,7.47,0.196
84.91,7.60,0.196
84.93,7.73,0.196
84.94,7.86,0.197
84.95,8.00,0.197
84.97,8.13,0.197
84.98,8.27,0.197
84.99,8.40,0.197
85.01,8.53,0.198
85.02,8.67,0.198
85.03,8.80,0.198
85.05,8.93,0.198
85.06,9.06,0.198
85.07,9.20,0.199
85.09,9.33,0.199
85.10,9.47,0.199
85.11,9.60,0.200
85.13,9.73,0.200
85.14,9.87,0.200
85.15,10.00,0.200
85.17,10.13,0.201
85.18,10.27,0.201
85.19,10.40,0.202
85.21,10.53,0.202
85.22,10.67,0.202
85.23,10.80,0.202
85.25,10.93,0.203
85.26,11.07,0.203
85.27,11.20,0.204
85.29,11.33,0.204
85.30,11.47,0.204
85.31,11.60,0.205
85.33,11.73,0.205
85.34,11.87,0.205
85.35,12.00,0.206
85.37,12.13,0.206
85.38,12.27,0.207
85.39,12.40,0.207
85.41,12.53,0.208
85.42,12.67,0.208
85.43,12.80,0.208
85.45,12.93,0.209
85.46,13.07,0.210
85.47,13.20,0.210
85.49,13.33,0.211
85.50,13.47,0.212
85.51,13.60,0.213
85.53,13.73,0.213
85.54,13.87,0.214
85.55,14.00,0.215
85.57,14.13,0.215
85.58,14.27,0.217
85.59,14.40,0.218
85.61,14.53,0.220
85.62,14.66,0.221
85.63,14.80,0.221
85.65,14.93,0.223
85.66,15.06,0.224
85.67,15.20,0.225
85.69,15.33,0.226
85.70,15.46,0.227
85.71,15.60,0.227
85.73,15.73,0.228
85.74,15.86,0.230
85.75,16.00,0.231
85.77,16.13,0.232
85.78,16.26,0.233
85.79,16.40,0.235
85.81,16.53,0.236
85.82,16.66,0.238
85.83,16.79,0.239
85.85,16.93,0.239
85.86,17.06,0.241
85.87,17.20,0.242
85.89,17.33,0.244
85.90,17.46,0.245
85.91,17.59,0.247
85.93,17.73,0.247
85.94,17.86,0.248
85.95,17.99,0.249
85.97,18.13,0.251
85.98,18.26,0.252
85.99,18.39,0.252
86.01,18.52,0.253
86.02,18.66,0.254
86.03,18.79,0.255
86.05,18.92,0.256
86.06,19.06,0.258
86.07,19.19,0.259
86.09,19.32,0.260
86.10,19.46,0.261
86.11,19.59,0.262
86.13,19.72,0.263
86.14,19.86,0.263
86.15,19.99,0.263
86.17,20.12,0.264
86.18,20.26,0.264
86.19,20.39,0.265
86.21,20.52,0.265
86.22,20.66,0.265
86.23,20.79,0.265
86.25,20.92,0.266
86.26,21.06,0.266
86.27,21.19,0.266
86.29,21.32,0.266
86.30,21.46,0.266
86.31,21.59,0.266
86.33,21.72,0.266
86.34,21.86,0.267
86.35,21.99,0.267
86.37,22.12,0.267
86.38,22.26,0.267
86.39,22.39,0.267
86.41,22.52,0.267
86.42,22.66,0.267
86.43,22.79,0.267
86.45,22.92,0.267
86.46,23.06,0.267
86.47,23.19,0.267
86.49,23.33,0.266
86.50,23.46,0.266
86.51,23.59,0.266
86.53,23.73,0.266
86.54,23.86,0.266
86.55,23.99,0.266
86.57,24.13,0.266
86.58,24.26,0.266
86.59,24.39,0.266
86.61,24.53,0.266
86.62,24.66,0.265
86.63,24.80,0.265
86.65,24.93,0.265
86.66,25.06,0.265
86.67,25.20,0.265
86.69,25.33,0.265
86.70,25.46,0.265
86.71,25.60,0.265
86.73,25.73,0.264
86.74,25.86,0.264
86.75,26.00,0.264
86.77,26.13,0.264
86.78,26.27,0.264
86.79,26.40,0.264
86.81,26.53,0.264
86.82,26.67,0.264
86.83,26.80,0.264
86.85,26.93,0.264
86.86,27.07,0.264
86.87,27.20,0.264
86.89,27.33,0.264
86.90,27.47,0.264
86.91,27.60,0.264
86.93,27.74,0.264
86.94,27.87,0.264
86.95,28.00,0.264
86.97,28.14,0.264
86.98,28.27,0.264
86.99,28.40,0.264
87.01,28.54,0.264
87.02,28.67,0.264
87.03,28.80,0.264
87.05,28.94,0.264
87.06,29.07,0.264
87.07,29.20,0.264
87.09,29.34,0.264
87.10,29.47,0.264
87.11,29.60,0.264
87.13,29.74,0.264
87.14,29.87,0.264
87.15,30.00,0.264
87.17,30.14,0.264
87.18,30.27,0.264
87.19,30.40,0.264
87.21,30.54,0.264
87.22,30.67,0.264
87.23,30.80,0.264
87.25,30.94,0.264
87.26,31.07,0.264
87.27,31.21,0.264
87.29,31.34,0.264
87.30,31.47,0.264
87.31,31.61,0.264
87.33,31.74,0.264
87.34,31.87,0.264
87.35,32.01,0.264
87.37,32.14,0.264
87.38,32.27,0.264
87.39,32.41,0.264
87.41,32.54,0.264
87.42,32.67,0.264
87.43,32.81,0.264
87.45,32.94,0.264
87.46,33.07,0.264
87.47,33.21,0.265
87.49,33.34,0.264
87.50,33.48,0.265
87.51,33.61,0.265
87.53,33.74,0.265
87.54,33.88,0.265
87.55,34.01,0.265
87.57,34.14,0.265
87.58,34.27,0.265
87.59,34.41,0.265
87.61,34.54,0.265
87.62,34.67,0.265
87.63,34.81,0.265
87.65,34.94,0.265
87.66,35.07,0.265
87.67,35.21,0.265
87.69,35.34,0.265
87.70,35.48,0.265
87.71,35.61,0.265
87.73,35.74,0.265
87.74,35.88,0.266
87.75,36.01,0.266
87.77,36.14,0.266
87.78,36.28,0.266
87.79,36.41,0.266
87.81,36.54,0.266
87.82,36.68,0.266
87.83,36.81,0.266
87.85,36.95,0.266
87.86,37.08,0.266
87.87,37.21,0.266
87.89,37.34,0.266
87.90,37.48,0.266
87.91,37.61,0.266
87.93,37.75,0.266
87.94,37.88,0.266
87.95,38.01,0.267
87.97,38.15,0.267
87.98,38.28,0.267
87.99,38.41,0.267
88.01,38.55,0.267
88.02,38.68,0.267
88.03,38.81,0.267
88.05,38.95,0.267
88.06,39.08,0.267
88.07,39.21,0.267
88.09,39.35,0.267
88.10,39.48,0.267
88.11,39.61,0.267
88.13,39.75,0.267
88.14,39.88,0.267
88.15,40.01,0.267
88.17,40.15,0.267
88.18,40.28,0.268
88.19,40.41,0.268
88.21,40.55,0.268
88.22,40.68,0.268
88.23,40.82,0.268
88.25,40.95,0.268
88.26,41.08,0.268
88.27,41.22,0.268
88.29,41.35,0.268
88.30,41.48,0.268
88.31,41.62,0.268
88.33,41.75,0.268
88.34,41.88,0.268
88.35,42.02,0.268
88.37,42.15,0.269
88.38,42.28,0.269
88.39,42.42,0.269
88.41,42.55,0.269
88.42,42.68,0.269
88.43,42.82,0.269
88.45,42.95,0.269
88.46,43.08,0.269
88.47,43.22,0.269
88.49,43.35,0.269
88.50,43.49,0.269
88.51,43.62,0.269
88.53,43.75,0.269
88.54,43.89,0.269
88.55,44.02,0.270
88.57,44.15,0.270
88.58,44.29,0.270
88.59,44.42,0.270
88.61,44.55,0.270
88.62,44.69,0.270
88.63,44.82,0.270
88.65,44.95,0.270
88.66,45.09,0.270
88.67,45.22,0.270
88.69,45.36,0.270
88.70,45.49,0.270
88.71,45.62,0.271
88.73,45.75,0.271
88.74,45.89,0.271
88.75,46.02,0.271
88.77,46.15,0.271
88.78,46.29,0.271
88.79,46.42,0.271
88.81,46.55,0.271
88.82,46.69,0.271
88.83,46.82,0.271
88.85,46.95,0.271
88.86,47.09,0.271
88.87,47.22,0.271
88.89,47.36,0.271
88.90,47.49,0.271
88.91,47.62,0.272
88.93,47.76,0.272
88.94,47.89,0.272
88.95,48.02,0.272
88.97,48.16,0.272
88.98,48.29,0.272
88.99,48.42,0.272
89.01,48.56,0.272
89.02,48.69,0.272
89.03,48.82,0.272
89.05,48.96,0.272
89.06,49.09,0.272
89.07,49.22,0.272
89.09,49.36,0.273
89.10,49.49,0.273
89.11,49.62,0.273
89.13,49.76,0.273
89.14,49.89,0.273
89.15,50.03,0.273
89.17,50.16,0.273
89.18,50.29,0.273
89.19,50.43,0.273
89.21,50.56,0.273
89.22,50.69,0.273
89.23,50.83,0.274
89.25,50.96,0.274
89.26,51.09,0.274
89.27,51.23,0.274
89.29,51.36,0.274
89.30,51.49,0.274
89.31,51.63,0.274
89.33,51.76,0.274
89.34,51.89,0.274
89.35,52.03,0.274
89.37,52.16,0.274
89.38,52.29,0.274
89.39,52.43,0.274
89.41,52.56,0.274
89.42,52.69,0.274
89.43,52.83,0.275
89.45,52.96,0.275
89.46,53.09,0.275
89.47,53.23,0.275
89.49,53.36,0.275
89.50,53.50,0.275
89.51,53.63,0.275
89.53,53.76,0.275
89.54,53.90,0.275
89.55,54.03,0.275
89.57,54.16,0.275
89.58,54.30,0.275
89.59,54.43,0.276
89.61,54.56,0.276
89.62,54.70,0.276
89.63,54.83,0.276
89.65,54.96,0.276
89.66,55.10,0.276
89.67,55.23,0.276
89.69,55.36,0.276
89.70,55.50,0.276
89.71,55.63,0.276
89.73,55.76,0.276
89.74,55.90,0.276
89.75,56.03,0.276
89.77,56.16,0.276
89.78,56.30,0.276
89.79,56.43,0.276
89.81,56.57,0.276
89.82,56.70,0.276
89.83,56.83,0.277
89.85,56.97,0.277
89.86,57.10,0.277
89.87,57.23,0.277
89.89,57.37,0.277
89.90,57.50,0.277
89.91,57.63,0.277
89.93,57.77,0.277
89.94,57.90,0.277
89.95,58.03,0.277
89.97,58.17,0.277
89.98,58.30,0.277
89.99,58.43,0.277
90.01,58.57,0.277
90.02,58.70,0.277
90.03,58.83,0.278
90.05,58.97,0.278
90.06,59.10,0.278
90.07,59.23,0.278
90.09,59.37,0.278
90.10,59.50,0.278
90.11,59.63,0.278
90.13,59.77,0.278
90.14,59.90,0.278
90.15,60.04,0.278
90.17,60.17,0.278
90.18,60.30,0.278
90.19,60.44,0.278
90.21,60.57,0.278
90.22,60.70,0.279
90.23,60.84,0.279
90.25,60.97,0.279
90.26,61.10,0.279
90.27,61.24,0.279
90.29,61.37,0.279
90.30,61.50,0.279
90.31,61.64,0.279
90.33,61.77,0.279
90.34,61.90,0.279
90.35,62.04,0.279
90.37,62.17,0.279
90.38,62.30,0.279
90.39,62.44,0.279
90.41,62.57,0.279
90.42,62.70,0.279
90.43,62.84,0.279
90.45,62.97,0.280
90.46,63.10,0.280
90.47,63.24,0.280
90.49,63.37,0.280
90.50,63.50,0.280
90.51,63.64,0.280
90.53,63.77,0.280
90.54,63.91,0.280
90.55,64.04,0.280
90.57,64.17,0.280
90.58,64.31,0.280
90.59,64.44,0.280
90.61,64.57,0.281
90.62,64.71,0.281
90.63,64.84,0.281
90.65,64.97,0.281
90.66,65.11,0.281
90.67,65.24,0.281
90.69,65.37,0.281
90.70,65.51,0.281
90.71,65.64,0.281
90.73,65.78,0.281
90.74,65.91,0.281
90.75,66.04,0.282
90.77,66.17,0.282
90.78,66.31,0.282
90.79,66.44,0.282
90.81,66.58,0.282
90.82,66.71,0.282
90.83,66.84,0.282
90.85,66.98,0.282
90.86,67.11,0.282
90.87,67.24,0.282
90.89,67.38,0.282
90.90,67.51,0.282
90.91,67.64,0.282
90.93,67.78,0.282
90.94,67.91,0.282
90.95,68.04,0.282
90.97,68.18,0.283
90.98,68.31,0.283
90.99,68.44,0.283
91.01,68.58,0.283
91.02,68.71,0.283
91.03,68.84,0.283
91.05,68.98,0.283
91.06,69.11,0.283
91.07,69.24,0.283
91.09,69.38,0.283
91.10,69.51,0.283
91.11,69.64,0.283
91.13,69.78,0.283
91.14,69.91,0.283
91.15,70.05,0.284
91.17,70.18,0.284
91.18,70.31,0.284
91.19,70.45,0.284
91.21,70.58,0.284
91.22,70.71,0.284
91.23,70.85,0.284
91.25,70.98,0.284
91.26,71.11,0.284
91.27,71.25,0.284
91.29,71.38,0.284
91.30,71.51,0.284
91.31,71.65,0.285
91.33,71.78,0.285
91.34,71.91,0.285
91.35,72.05,0.285
91.37,72.18,0.285
91.38,72.31,0.285
91.39,72.45,0.285
91.41,72.58,0.285
91.42,72.71,0.285
91.43,72.85,0.285
91.45,72.98,0.285
91.46,73.12,0.285
91.47,73.25,0.285
91.49,73.38,0.285
91.50,73.52,0.286
91.51,73.65,0.286
91.53,73.78,0.286
91.54,73.92,0.286
91.55,74.05,0.286
91.57,74.18,0.286
91.58,74.32,0.286
91.59,74.45,0.286
91.61,74.58,0.286
91.62,74.72,0.286
91.63,74.85,0.286
91.65,74.98,0.286
91.66,75.12,0.286
91.67,75.25,0.287
91.69,75.38,0.287
91.70,75.52,0.287
91.71,75.65,0.287
91.73,75.79,0.287
91.74,75.92,0.287
91.75,76.05,0.287
91.77,76.18,0.287
91.78,76.32,0.287
91.79,76.45,0.287
91.81,76.58,0.287
91.82,76.72,0.287
91.83,76.85,0.287
91.85,76.99,0.287
91.86,77.12,0.287
91.87,77.25,0.288
91.89,77.39,0.288
91.90,77.52,0.288
91.91,77.65,0.288
91.93,77.79,0.288
91.94,77.92,0.288
91.95,78.05,0.288
91.97,78.19,0.288
91.98,78.32,0.288
91.99,78.45,0.288
92.01,78.59,0.288
92.02,78.72,0.288
92.03,78.85,0.288
92.05,78.99,0.289
92.06,79.12,0.289
92.07,79.25,0.289
92.09,79.39,0.289
92.10,79.52,0.289
92.11,79.66,0.289
92.13,79.79,0.289
92.14,79.92,0.289
92.15,80.06,0.289
92.17,80.19,0.289
92.18,80.32,0.289
92.19,80.46,0.289
92.21,80.59,0.289
92.22,80.72,0.289
92.23,80.86,0.289
92.25,80.99,0.290
92.26,81.12,0.290
92.27,81.26,0.290
92.29,81.39,0.290
92.30,81.52,0.290
92.31,81.66,0.290
92.33,81.79,0.290
92.34,81.92,0.290
92.35,82.06,0.290
92.37,82.19,0.290
92.38,82.32,0.290
92.39,82.46,0.290
92.41,82.59,0.290
92.42,82.72,0.290
92.43,82.86,0.290
92.45,82.99,0.290
92.46,83.13,0.290
92.47,83.26,0.291
92.49,83.39,0.291
92.50,83.53,0.291
92.51,83.66,0.291
92.53,83.79,0.291
92.54,83.93,0.291
92.55,84.06,0.291
92.57,84.19,0.291
92.58,84.33,0.291
92.59,84.46,0.291
92.61,84.59,0.291
92.62,84.73,0.291
92.63,84.86,0.291
92.65,84.99,0.291
92.66,85.13,0.291
92.67,85.26,0.291
92.69,85.39,0.291
92.70,85.53,0.291
92.71,85.66,0.291
92.73,85.79,0.291
92.74,85.93,0.291
92.75,86.06,0.291
92.77,86.19,0.291
92.78,86.33,0.291
92.79,86.46,0.291
92.81,86.60,0.292
92.82,86.73,0.292
92.83,86.86,0.292
92.85,87.00,0.292
92.86,87.13,0.292
92.87,87.26,0.292
92.89,87.40,0.292
92.90,87.53,0.292
92.91,87.66,0.292
92.93,87.80,0.292
92.94,87.93,0.292
92.95,88.06,0.292
92.97,88.20,0.292
92.98,88.33,0.292
92.99,88.46,0.292
93.01,88.60,0.293
93.02,88.73,0.293
93.03,88.86,0.293
93.05,89.00,0.293
93.06,89.13,0.293
93.07,89.26,0.293
93.09,89.40,0.293
93.10,89.53,0.293
93.11,89.66,0.293
93.13,89.80,0.293
93.14,89.93,0.293
93.15,90.06,0.293
93.17,90.20,0.293
93.18,90.33,0.294
93.19,90.46,0.294
93.21,90.60,0.294
93.22,90.73,0.294
93.23,90.87,0.294
93.25,91.00,0.294
93.26,91.13,0.294
93.27,91.26,0.294
93.29,91.40,0.294
93.30,91.53,0.294
93.31,91.67,0.294
93.33,91.80,0.295
93.34,91.93,0.295
93.35,92.07,0.295
93.37,92.20,0.295
93.38,92.33,0.295
93.39,92.47,0.295
93.41,92.60,0.295
93.42,92.73,0.295
93.43,92.87,0.295
93.45,93.00,0.295
93.46,93.13,0.295
93.47,93.27,0.295
93.49,93.40,0.295
93.50,93.53,0.295
93.51,93.67,0.296
93.53,93.80,0.296
93.54,93.93,0.296
93.55,94.07,0.296
93.57,94.20,0.296
93.58,94.33,0.296
93.59,94.47,0.296
93.61,94.60,0.296
93.62,94.73,0.296
93.63,94.87,0.296
93.65,95.00,0.297
93.66,95.13,0.297
93.67,95.27,0.297
93.69,95.40,0.297
93.70,95.53,0.297
93.71,95.67,0.297
93.73,95.80,0.297
93.74,95.94,0.297
93.75,96.07,0.297
93.77,96.20,0.297
93.78,96.34,0.297
93.79,96.47,0.297
93.81,96.60,0.297
93.82,96.74,0.297
93.83,96.87,0.298
93.85,97.00,0.298
93.86,97.14,0.298
93.87,97.27,0.298
93.89,97.40,0.298
93.90,97.54,0.298
93.91,97.67,0.298
93.93,97.80,0.298
93.94,97.94,0.298
93.95,98.07,0.298
93.97,98.20,0.298
93.98,98.34,0.298
93.99,98.47,0.298
94.01,98.60,0.298
94.02,98.74,0.298
94.03,98.87,0.299
94.05,99.01,0.299
94.06,99.14,0.299
94.07,99.27,0.299
94.09,99.41,0.299
94.10,99.54,0.299
94.11,99.67,0.299
94.13,99.81,0.299
94.14,99.94,0.299
94.15,100.07,0.300
94.17,100.21,0.300
94.18,100.34,0.300
94.19,100.47,0.300
94.21,100.61,0.300
94.22,100.74,0.300
94.23,100.87,0.300
94.25,101.01,0.300
94.26,101.14,0.300
94.27,101.28,0.300
94.29,101.41,0.300
94.30,101.54,0.300
94.31,101.67,0.300
94.33,101.81,0.300
94.34,101.94,0.300
94.35,102.07,0.301
94.37,102.21,0.301
94.38,102.34,0.301
94.39,102.48,0.301
94.41,102.61,0.301
94.42,102.74,0.301
94.43,102.88,0.301
94.45,103.01,0.301
94.46,103.14,0.301
94.47,103.28,0.301
94.49,103.41,0.301
94.50,103.54,0.301
94.51,103.68,0.301
94.53,103.81,0.301
94.54,103.94,0.301
94.55,104.08,0.301
94.57,104.21,0.301
94.58,104.34,0.302
94.59,104.48,0.302
94.61,104.61,0.302
94.62,104.74,0.302
94.63,104.88,0.302
94.65,105.01,0.302
94.66,105.14,0.302
94.67,105.28,0.302
94.69,105.41,0.302
94.70,105.54,0.302
94.71,105.68,0.302
94.73,105.81,0.302
94.74,105.94,0.302
94.75,106.08,0.302
94.77,106.21,0.302
94.78,106.34,0.302
94.79,106.48,0.302
94.81,106.61,0.302
94.82,106.74,0.303
94.83,106.88,0.303
94.85,107.01,0.303
94.86,107.14,0.303
94.87,107.28,0.303
94.89,107.41,0.303
94.90,107.54,0.303
94.91,107.68,0.303
94.93,107.81,0.303
94.94,107.95,0.303
94.95,108.08,0.304
94.97,108.21,0.304
94.98,108.35,0.304
94.99,108.48,0.304
95.01,108.61,0.304
95.02,108.75,0.304
95.03,108.88,0.304
95.05,109.01,0.304
95.06,109.15,0.304
95.07,109.28,0.304
95.09,109.41,0.304
95.10,109.55,0.304
95.11,109.68,0.305
95.13,109.81,0.305
95.14,109.95,0.305
95.15,110.08,0.305
95.17,110.22,0.305
95.18,110.35,0.305
95.19,110.48,0.305
95.21,110.62,0.305
95.22,110.75,0.305
95.23,110.88,0.305
95.25,111.02,0.305
95.26,111.15,0.305
95.27,111.28,0.305
95.29,111.42,0.305
95.30,111.55,0.306
95.31,111.68,0.306
95.33,111.82,0.306
95.34,111.95,0.306
95.35,112.08,0.306
95.37,112.22,0.306
95.38,112.35,0.306
95.39,112.48,0.306
95.41,112.62,0.306
95.42,112.75,0.306
95.43,112.88,0.306
95.45,113.02,0.306
95.46,113.15,0.306
95.47,113.28,0.306
95.49,113.42,0.306
95.50,113.55,0.307
95.51,113.68,0.307
95.53,113.82,0.307
95.54,113.95,0.307
95.55,114.08,0.307
95.57,114.22,0.307
95.58,114.35,0.307
95.59,114.48,0.307
95.61,114.62,0.307
95.62,114.75,0.307
95.63,114.88,0.307
95.65,115.02,0.307
95.66,115.15,0.307
95.67,115.28,0.307
95.69,115.42,0.307
95.70,115.55,0.308
95.71,115.68,0.308
95.73,115.82,0.308
95.74,115.95,0.308
95.75,116.08,0.308
95.77,116.22,0.308
95.78,116.35,0.308
95.79,116.48,0.308
95.81,116.62,0.308
95.82,116.75,0.308
95.83,116.89,0.308
95.85,117.02,0.308
95.86,117.15,0.308
95.87,117.28,0.308
95.89,117.42,0.309
95.90,117.55,0.309
95.91,117.69,0.309
95.93,117.82,0.309
95.94,117.95,
95.95,118.09,
95.97,118.22,
95.98,118.35,
95.99,,