File: DSC/2025_06_19_CBD_n60_100C_5Cmin_x3.csv
Filename,2025_06_19_CBD_n60_100C_5Cmin_x3
Instrument name,DSC2A-00468 (192.168.1.100)
Operator,Gibbons
rundate,6/20/2025
Sample name,2025_06_19_CBD_n60_100C_5Cmin_x3
proceduresegments,Data Off ; Equilibrate -60.00 °C; Data On ; Ramp 5.00 °C/min to 100.00 °C; Data Off ; Isothermal 1.0 min; Data On ; Ramp 5.00 °C/min to -60.00 °C; Data Off ; Isothermal 1.0 min; Data On ; Ramp 5.00 °C/min to 100.00 °C; Data Off ; Isothermal 1.0 min; Data On ; Ramp 5.00 °C/min to -60.00 °C; Data Off ; Isothermal 1.0 min; Data On ; Ramp 5.00 °C/min to 100.00 °C; Data Off ; Isothermal 1.0 min; Data On ; Ramp 5.00 °C/min to 30.00 °C
[File Parameters]
Run date,6/20/2025 3:58:17 PM
Trios version,5.1.1.46572
Original File Name,
Current File Name,D:\DSC2500\Gibbons\2025_06_19_CBD_n60_100C_5Cmin_x3.tri
[Procedure]
Procedure Name,CBD_n60_100C_5Cmin_x3
Sample Name,2025_06_19_CBD_n60_100C_5Cmin_x3
Sample Mass,10.77 mg
Reference Sample Mass,0 mg
Pan Mass,55.73 mg
Pan Number,53
Reference Pan Mass,55.79 mg
Reference Pan Number,1
Pan Type,Tzero Aluminum Hermetic
Comments,Al Hermetic DSC Consumables sealed Pan/Lid. A2 Tray (Google Sheet: DSC_Samples_A2_Tray_May2025)
Project Name,CA
Operator,Gibbons
Test,Custom
Unload Max Temperature,30
Unload Min Temperature,30
Load Max Temperature,30
Load Min Temperature,30
Stop on Gas Flow Error,Yes
[Signal List]
Signal #1,Time (min)
Signal #2,Temperature (°C)
Signal #3,Heat Flow (mW)
Signal #4,Delta T (µV)
Signal #5,Delta Tzero (µV)
Signal #6,Tzero Temperature (°C)
Signal #7,Cell Purge (mL/min)
Signal #8,Heater Temp (°C)
Signal #9,Power Delivered (W)
Signal #10,Reference Junction Temperature (°C)
Signal #11,Flange Temperature (°C)
Signal #12,Heat Flow Phase (rad)
Signal #13,Total Heat Capacity (J/°C)
Signal #14,Heat Capacity (J/°C)
[Configuration]
Company Name,ASU
Instrument Name,DSC2A-00468
Instrument Type,DSC2500
Serial Number,DSC2A-00468
IP,192.168.1.100
Location of Instrument,MRRC
DisplayType,Unknown
Sample Interval ,0.1 s/pt
Selected Heat Flow,T4P
Exotherm Direction,Down
Cell Serial,DRC2-00792
Lid Type,Standard
Cooler,RCS 90
Leave Cooler on at End of Sequence,On
Gas 2,Nitrogen
Gas Selected,Channel 1
Flow Rate,50 mL/min
Secondary Purge,On
Licensed Heat Flow,Heat Flow T4P
Modulation Licensed,Yes
[Versions]
Common IDD Version,1
Cortex Version,VER 2.10.2.31
Driver,5.0.0.6
GDM Version,1.0.3.3
TouchscreenVersion,1.0.0.16145
FEP Version,1.2.1.21
FEP Bootloader,2.0.0.5
AutoSampler Version,2.1.1.26
Auto Sampler Bootloader,2.0.0.5
FCM Version,1.1.0.3
FCM Bootloader,2.0.0.5
[Experiment Logs]
Experiment Log Entry # 1,Data On set to 0
Experiment Log Entry # 3,Equilibrate Segment -60 (C) Started
Experiment Log Entry # 5,Air Cool is off.
Experiment Log Entry # 7,Data On set to 1
Experiment Log Entry # 9,Ramp Segment 5 C/min to 100 Started
Experiment Log Entry # 11,Data On set to 0
Experiment Log Entry # 13,Isothermal Segment 1 min started
Experiment Log Entry # 15,Data On set to 1
Experiment Log Entry # 17,Ramp Segment 5 C/min to -60 Started
Experiment Log Entry # 19,Data On set to 0
Experiment Log Entry # 21,Isothermal Segment 1 min started
Experiment Log Entry # 23,Data On set to 1
Experiment Log Entry # 25,Ramp Segment 5 C/min to 100 Started
Experiment Log Entry # 27,Auto sampler has detected that FCM has gone offline
Experiment Log Entry # 29,Data On set to 0
Experiment Log Entry # 31,Isothermal Segment 1 min started
Experiment Log Entry # 33,Data On set to 1
Experiment Log Entry # 35,Ramp Segment 5 C/min to -60 Started
Experiment Log Entry # 37,Data On set to 0
Experiment Log Entry # 39,Isothermal Segment 1 min started
Experiment Log Entry # 41,Data On set to 1
Experiment Log Entry # 43,Ramp Segment 5 C/min to 100 Started
Experiment Log Entry # 45,Data On set to 0
Experiment Log Entry # 47,Isothermal Segment 1 min started
Experiment Log Entry # 49,Data On set to 1
Experiment Log Entry # 51,Ramp Segment 5 C/min to 30 Started
[Method Log]
Method Log Entry # 1,Data Off
Method Log Entry # 2,Equilibrate -60 °C
Method Log Entry # 3,Data On
Method Log Entry # 4,(Ramp 709711) Ramp 5 °C/minute to 100 °C
Method Log Entry # 5,Data Off
Method Log Entry # 6,Isothermal 1 minutes
Method Log Entry # 7,Data On
Method Log Entry # 8,(Ramp 709715) Ramp 5 °C/minute to -60 °C
Method Log Entry # 9,Data Off
Method Log Entry # 10,Isothermal 1 minutes
Method Log Entry # 11,Data On
Method Log Entry # 12,(Ramp 709719) Ramp 5 °C/minute to 100 °C
Method Log Entry # 13,Data Off
Method Log Entry # 14,Isothermal 1 minutes
Method Log Entry # 15,Data On
Method Log Entry # 16,(Ramp 709723) Ramp 5 °C/minute to -60 °C
Method Log Entry # 17,Data Off
Method Log Entry # 18,Isothermal 1 minutes
Method Log Entry # 19,Data On
Method Log Entry # 20,(Ramp 709727) Ramp 5 °C/minute to 100 °C
Method Log Entry # 21,Data Off
Method Log Entry # 22,Isothermal 1 minutes
Method Log Entry # 23,Data On
Method Log Entry # 24,(Ramp 709731) Ramp 5 °C/minute to 30 °C
Cell Serial,DRC2-00792
[T1 Calibration]
Slope,-0.008529666
Offset,9.636258
Initial Temperature,98.23
GUID,f8bfdadc-4977-4fdf-ba6d-0ba9134940c3
[TZero Calibration]
Date Applied,11/29/2022 4:06:13 PM
Description,From -89.059 °C to 396.009 °C at 20.000°C/min
Gas Type,Nitrogen
Pan Type,None
Source Files 1,C:\Users\yargerlab\Desktop\DSC Data\General\TZero_calibration_11_29_22_2nd(2).tri
Source Files 2,C:\Users\yargerlab\Desktop\DSC Data\General\TZero_calibration_11_29_22_2nd(3).tri
Delta T Offset,13.05235
Delta T Slope,-0.007271007
Delta T0 Offset,-13.69128
Delta T0 Slope,0.06063341
[Temperature Calibration]
Date Applied,11/29/2022 7:12:28 PM
Description,From 106.590 °C to 186.590 °C at 10.000°C/min
Gas Type,Nitrogen
Pan Type,Tzero Aluminum Hermetic
Source Files 1,C:\Users\yargerlab\Desktop\DSC Data\General\Indium(6).tri
Measured 1,157.391
Known 1,156.598
[Cell Constant Calibration]
Date Applied,11/29/2022 7:12:29 PM
Description,From 106.590 °C to 186.590 °C at 10.000°C/min
Gas Type,Nitrogen
Pan Type,Tzero Aluminum Hermetic
Source Files 1,C:\Users\yargerlab\Desktop\DSC Data\General\Indium(6).tri
T4P KCell,1.006051
Onset Slope,63.26126 mW/°C
[Direct Cp Calibration]
Date Applied,11/30/2022 11:04:51 AM
Description,From -79.983 °C to 298.409 °C at 10.000°C/min
Gas Type,Nitrogen
Pan Type,Tzero Aluminum Hermetic
Source Files 1,C:\Users\yargerlab\Desktop\DSC Data\General\Sapphire_Heat_Capacity_11_30_22.tri
[Rev Cp Calibration]
Date Applied,11/30/2022 1:58:51 PM
Description,From -79.996 °C to 292.812 °C at 3.000°C/min
Gas Type,Nitrogen
Pan Type,Tzero Aluminum Hermetic
Source Files 1,C:\Users\yargerlab\Desktop\DSC Data\General\Sapphire_MDSC_Calibration_11_30_22.tri
[step]
Ramp 5.00 °C/min to 100.00 °C
Time,Temperature,Heat Flow (Normalized)
min,°C,W/g
0.00,-59.64,-0.063
0.02,-59.66,-0.064
0.04,-59.67,-0.057
0.07,-59.66,-0.057
0.09,-59.64,-0.061
0.11,-59.61,-0.064
0.13,-59.55,-0.065
0.15,-59.49,-0.053
0.17,-59.42,-0.039
0.19,-59.35,-0.025
0.22,-59.27,-0.011
0.24,-59.19,0.002
0.26,-59.10,0.011
0.28,-59.02,0.020
0.30,-58.93,0.027
0.33,-58.84,0.034
0.35,-58.74,0.040
0.37,-58.65,0.046
0.39,-58.55,0.050
0.41,-58.46,0.055
0.43,-58.36,0.058
0.45,-58.26,0.062
0.48,-58.16,0.063
0.50,-58.06,0.066
0.52,-57.96,0.067
0.54,-57.85,0.070
0.56,-57.75,0.071
0.58,-57.65,0.073
0.61,-57.54,0.074
0.63,-57.44,0.075
0.65,-57.33,0.075
0.67,-57.23,0.076
0.69,-57.13,0.077
0.72,-57.02,0.077
0.74,-56.91,0.078
0.76,-56.81,0.078
0.78,-56.70,0.079
0.80,-56.60,0.079
0.82,-56.49,0.079
0.85,-56.39,0.080
0.87,-56.28,0.080
0.89,-56.17,0.080
0.91,-56.07,0.080
0.93,-55.96,0.081
0.95,-55.85,0.081
0.98,-55.74,0.081
1.00,-55.64,0.081
1.02,-55.53,0.081
1.04,-55.42,0.082
1.06,-55.32,0.082
1.08,-55.21,0.082
1.11,-55.10,0.082
1.13,-54.99,0.082
1.15,-54.89,0.083
1.17,-54.78,0.083
1.19,-54.67,0.083
1.21,-54.56,0.083
1.23,-54.46,0.083
1.26,-54.35,0.083
1.28,-54.24,0.083
1.30,-54.14,0.084
1.32,-54.03,0.084
1.34,-53.92,0.084
1.37,-53.81,0.084
1.39,-53.70,0.084
1.41,-53.60,0.084
1.43,-53.49,0.084
1.45,-53.38,0.084
1.47,-53.27,0.084
1.49,-53.17,0.084
1.52,-53.06,0.085
1.54,-52.95,0.085
1.56,-52.84,0.085
1.58,-52.73,0.085
1.60,-52.63,0.085
1.63,-52.52,0.085
1.65,-52.41,0.085
1.67,-52.30,0.085
1.69,-52.19,0.085
1.71,-52.09,0.085
1.73,-51.98,0.085
1.76,-51.87,0.085
1.78,-51.76,0.085
1.80,-51.65,0.085
1.82,-51.54,0.085
1.84,-51.44,0.085
1.86,-51.33,0.085
1.88,-51.22,0.085
1.91,-51.11,0.085
1.93,-51.00,0.085
1.95,-50.90,0.085
1.97,-50.79,0.085
1.99,-50.68,0.085
2.02,-50.57,0.085
2.04,-50.46,0.085
2.06,-50.36,0.085
2.08,-50.25,0.086
2.10,-50.14,0.086
2.12,-50.03,0.086
2.14,-49.92,0.086
2.17,-49.82,0.086
2.19,-49.70,0.086
2.21,-49.60,0.086
2.23,-49.49,0.086
2.25,-49.38,0.086
2.28,-49.27,0.086
2.30,-49.17,0.086
2.32,-49.06,0.086
2.34,-48.95,0.086
2.36,-48.84,0.086
2.38,-48.73,0.086
2.41,-48.62,0.086
2.43,-48.52,0.086
2.45,-48.41,0.086
2.47,-48.30,0.086
2.49,-48.19,0.086
2.51,-48.08,0.086
2.54,-47.98,0.086
2.56,-47.87,0.086
2.58,-47.76,0.086
2.60,-47.65,0.086
2.62,-47.54,0.086
2.64,-47.43,0.086
2.66,-47.32,0.086
2.69,-47.22,0.086
2.71,-47.11,0.086
2.73,-47.00,0.086
2.75,-46.89,0.086
2.77,-46.78,0.086
2.79,-46.68,0.086
2.82,-46.57,0.086
2.84,-46.46,0.086
2.86,-46.35,0.086
2.88,-46.24,0.086
2.90,-46.14,0.086
2.93,-46.03,0.086
2.95,-45.92,0.086
2.97,-45.81,0.086
2.99,-45.70,0.086
3.01,-45.59,0.086
3.03,-45.49,0.086
3.06,-45.38,0.086
3.08,-45.27,0.086
3.10,-45.16,0.086
3.12,-45.05,0.086
3.14,-44.94,0.087
3.16,-44.84,0.087
3.19,-44.73,0.087
3.21,-44.62,0.087
3.23,-44.51,0.087
3.25,-44.40,0.087
3.27,-44.30,0.087
3.29,-44.19,0.087
3.31,-44.08,0.087
3.34,-43.97,0.087
3.36,-43.86,0.087
3.38,-43.75,0.087
3.40,-43.64,0.087
3.42,-43.54,0.087
3.44,-43.43,0.087
3.47,-43.32,0.087
3.49,-43.21,0.087
3.51,-43.10,0.087
3.53,-42.99,0.087
3.55,-42.89,0.087
3.58,-42.78,0.087
3.60,-42.67,0.087
3.62,-42.56,0.087
3.64,-42.45,0.087
3.66,-42.35,0.087
3.68,-42.24,0.087
3.71,-42.13,0.087
3.73,-42.02,0.087
3.75,-41.91,0.087
3.77,-41.80,0.087
3.79,-41.69,0.087
3.81,-41.59,0.087
3.84,-41.48,0.087
3.86,-41.37,0.087
3.88,-41.26,0.087
3.90,-41.15,0.087
3.92,-41.04,0.087
3.94,-40.94,0.087
3.96,-40.83,0.087
3.99,-40.72,0.087
4.01,-40.61,0.087
4.03,-40.50,0.087
4.05,-40.39,0.088
4.07,-40.29,0.087
4.09,-40.18,0.088
4.12,-40.07,0.088
4.14,-39.96,0.088
4.16,-39.85,0.088
4.18,-39.74,0.088
4.20,-39.64,0.088
4.23,-39.53,0.088
4.25,-39.42,0.088
4.27,-39.31,0.088
4.29,-39.20,0.088
4.31,-39.09,0.088
4.33,-38.99,0.088
4.35,-38.88,0.088
4.38,-38.77,0.088
4.40,-38.66,0.088
4.42,-38.55,0.088
4.44,-38.44,0.088
4.46,-38.33,0.088
4.49,-38.23,0.088
4.51,-38.12,0.088
4.53,-38.01,0.088
4.55,-37.90,0.088
4.57,-37.79,0.088
4.59,-37.68,0.088
4.61,-37.57,0.088
4.64,-37.47,0.088
4.66,-37.36,0.088
4.68,-37.25,0.088
4.70,-37.14,0.088
4.72,-37.03,0.088
4.75,-36.92,0.088
4.77,-36.81,0.088
4.79,-36.71,0.088
4.81,-36.60,0.088
4.83,-36.49,0.088
4.85,-36.38,0.089
4.88,-36.27,0.089
4.90,-36.17,0.089
4.92,-36.05,0.089
4.94,-35.95,0.089
4.96,-35.84,0.089
4.98,-35.73,0.089
5.00,-35.62,0.089
5.03,-35.51,0.089
5.05,-35.40,0.089
5.07,-35.30,0.089
5.09,-35.19,0.089
5.11,-35.08,0.089
5.14,-34.97,0.089
5.16,-34.86,0.089
5.18,-34.75,0.089
5.20,-34.64,0.089
5.22,-34.54,0.089
5.24,-34.43,0.089
5.26,-34.32,0.089
5.29,-34.21,0.089
5.31,-34.10,0.089
5.33,-33.99,0.089
5.35,-33.89,0.089
5.37,-33.78,0.089
5.40,-33.67,0.089
5.42,-33.56,0.089
5.44,-33.45,0.089
5.46,-33.34,0.089
5.48,-33.24,0.089
5.50,-33.13,0.089
5.53,-33.02,0.089
5.55,-32.91,0.089
5.57,-32.80,0.089
5.59,-32.69,0.089
5.61,-32.59,0.089
5.63,-32.48,0.089
5.65,-32.37,0.089
5.68,-32.26,0.089
5.70,-32.15,0.089
5.72,-32.04,0.089
5.74,-31.94,0.089
5.76,-31.83,0.089
5.79,-31.72,0.089
5.81,-31.61,0.089
5.83,-31.50,0.089
5.85,-31.39,0.089
5.87,-31.28,0.089
5.89,-31.18,0.089
5.91,-31.07,0.089
5.94,-30.96,0.090
5.96,-30.85,0.090
5.98,-30.74,0.090
6.00,-30.63,0.090
6.02,-30.52,0.090
6.05,-30.41,0.090
6.07,-30.31,0.090
6.09,-30.20,0.090
6.11,-30.09,0.090
6.13,-29.98,0.090
6.15,-29.88,0.090
6.18,-29.77,0.090
6.20,-29.66,0.090
6.22,-29.55,0.090
6.24,-29.44,0.090
6.26,-29.33,0.090
6.28,-29.22,0.090
6.30,-29.11,0.090
6.33,-29.01,0.090
6.35,-28.90,0.090
6.37,-28.79,0.090
6.39,-28.68,0.090
6.41,-28.57,0.090
6.44,-28.46,0.090
6.46,-28.36,0.090
6.48,-28.25,0.090
6.50,-28.14,0.090
6.52,-28.03,0.090
6.54,-27.92,0.090
6.56,-27.81,0.090
6.59,-27.71,0.090
6.61,-27.60,0.090
6.63,-27.49,0.090
6.65,-27.38,0.090
6.67,-27.27,0.090
6.70,-27.16,0.090
6.72,-27.06,0.090
6.74,-26.95,0.090
6.76,-26.84,0.090
6.78,-26.73,0.090
6.80,-26.62,0.090
6.83,-26.51,0.090
6.85,-26.40,0.090
6.87,-26.30,0.090
6.89,-26.19,0.090
6.91,-26.08,0.090
6.93,-25.97,0.090
6.95,-25.86,0.090
6.98,-25.75,0.090
7.00,-25.65,0.090
7.02,-25.54,0.090
7.04,-25.43,0.090
7.06,-25.32,0.091
7.09,-25.21,0.091
7.11,-25.10,0.091
7.13,-25.00,0.091
7.15,-24.89,0.091
7.17,-24.78,0.091
7.19,-24.67,0.091
7.21,-24.56,0.091
7.24,-24.45,0.091
7.26,-24.34,0.091
7.28,-24.24,0.091
7.30,-24.13,0.091
7.32,-24.02,0.091
7.35,-23.91,0.091
7.37,-23.80,0.091
7.39,-23.69,0.091
7.41,-23.59,0.091
7.43,-23.48,0.091
7.45,-23.37,0.091
7.48,-23.26,0.091
7.50,-23.15,0.091
7.52,-23.04,0.091
7.54,-22.94,0.091
7.56,-22.83,0.091
7.58,-22.72,0.091
7.60,-22.61,0.091
7.63,-22.50,0.091
7.65,-22.39,0.091
7.67,-22.28,0.091
7.69,-22.18,0.091
7.71,-22.07,0.091
7.74,-21.96,0.091
7.76,-21.85,0.091
7.78,-21.74,0.091
7.80,-21.64,0.091
7.82,-21.53,0.091
7.84,-21.42,0.091
7.86,-21.31,0.091
7.89,-21.20,0.091
7.91,-21.09,0.091
7.93,-20.98,0.091
7.95,-20.88,0.091
7.97,-20.77,0.091
8.00,-20.66,0.091
8.02,-20.55,0.091
8.04,-20.44,0.091
8.06,-20.33,0.091
8.08,-20.22,0.092
8.10,-20.12,0.092
8.13,-20.01,0.092
8.15,-19.90,0.092
8.17,-19.79,0.092
8.19,-19.68,0.092
8.21,-19.58,0.092
8.23,-19.47,0.092
8.25,-19.36,0.092
8.28,-19.25,0.092
8.30,-19.14,0.092
8.32,-19.03,0.092
8.34,-18.92,0.092
8.36,-18.82,0.092
8.39,-18.71,0.092
8.41,-18.60,0.092
8.43,-18.49,0.092
8.45,-18.38,0.092
8.47,-18.27,0.092
8.49,-18.17,0.092
8.51,-18.06,0.092
8.54,-17.95,0.092
8.56,-17.84,0.092
8.58,-17.73,0.092
8.60,-17.62,0.092
8.62,-17.52,0.092
8.65,-17.41,0.092
8.67,-17.30,0.092
8.69,-17.19,0.092
8.71,-17.08,0.092
8.73,-16.97,0.092
8.75,-16.86,0.092
8.78,-16.76,0.092
8.80,-16.65,0.092
8.82,-16.54,0.092
8.84,-16.43,0.092
8.86,-16.32,0.092
8.88,-16.21,0.092
8.90,-16.10,0.092
8.93,-16.00,0.092
8.95,-15.89,0.092
8.97,-15.78,0.092
8.99,-15.67,0.092
9.01,-15.56,0.092
9.03,-15.45,0.092
9.06,-15.34,0.092
9.08,-15.24,0.092
9.10,-15.13,0.093
9.12,-15.02,0.093
9.14,-14.91,0.093
9.17,-14.80,0.093
9.19,-14.70,0.093
9.21,-14.59,0.093
9.23,-14.48,0.093
9.25,-14.37,0.093
9.27,-14.26,0.093
9.30,-14.15,0.093
9.32,-14.04,0.093
9.34,-13.94,0.093
9.36,-13.83,0.093
9.38,-13.72,0.093
9.40,-13.61,0.093
9.43,-13.50,0.093
9.45,-13.39,0.093
9.47,-13.29,0.093
9.49,-13.18,0.093
9.51,-13.07,0.093
9.53,-12.96,0.093
9.55,-12.85,0.093
9.58,-12.74,0.093
9.60,-12.64,0.093
9.62,-12.53,0.093
9.64,-12.42,0.093
9.66,-12.31,0.093
9.68,-12.20,0.093
9.71,-12.09,0.093
9.73,-11.98,0.093
9.75,-11.88,0.093
9.77,-11.77,0.093
9.79,-11.66,0.093
9.82,-11.55,0.093
9.84,-11.44,0.093
9.86,-11.33,0.093
9.88,-11.23,0.093
9.90,-11.12,0.093
9.92,-11.01,0.093
9.95,-10.90,0.093
9.97,-10.79,0.093
9.99,-10.68,0.093
10.01,-10.57,0.093
10.03,-10.47,0.093
10.05,-10.36,0.093
10.08,-10.25,0.093
10.10,-10.14,0.093
10.12,-10.03,0.094
10.14,-9.92,0.094
10.16,-9.82,0.094
10.18,-9.71,0.094
10.20,-9.60,0.094
10.23,-9.49,0.094
10.25,-9.38,0.094
10.27,-9.27,0.094
10.29,-9.17,0.094
10.31,-9.06,0.094
10.33,-8.95,0.094
10.36,-8.84,0.094
10.38,-8.73,0.094
10.40,-8.62,0.094
10.42,-8.52,0.094
10.44,-8.41,0.094
10.47,-8.30,0.094
10.49,-8.19,0.094
10.51,-8.08,0.094
10.53,-7.97,0.094
10.55,-7.87,0.094
10.57,-7.76,0.094
10.60,-7.65,0.094
10.62,-7.54,0.094
10.64,-7.43,0.094
10.66,-7.32,0.094
10.68,-7.21,0.094
10.70,-7.11,0.094
10.73,-7.00,0.094
10.75,-6.89,0.094
10.77,-6.78,0.094
10.79,-6.67,0.094
10.81,-6.57,0.094
10.83,-6.46,0.094
10.85,-6.35,0.094
10.88,-6.24,0.094
10.90,-6.13,0.094
10.92,-6.02,0.094
10.94,-5.91,0.094
10.96,-5.81,0.095
10.98,-5.70,0.095
11.01,-5.59,0.095
11.03,-5.48,0.095
11.05,-5.37,0.095
11.07,-5.26,0.095
11.09,-5.15,0.095
11.12,-5.05,0.095
11.14,-4.94,0.095
11.16,-4.83,0.095
11.18,-4.72,0.095
11.20,-4.61,0.095
11.22,-4.51,0.095
11.25,-4.40,0.095
11.27,-4.29,0.095
11.29,-4.18,0.095
11.31,-4.07,0.095
11.33,-3.96,0.095
11.35,-3.85,0.095
11.38,-3.74,0.095
11.40,-3.64,0.095
11.42,-3.53,0.095
11.44,-3.42,0.095
11.46,-3.31,0.095
11.48,-3.20,0.095
11.50,-3.09,0.095
11.53,-2.99,0.095
11.55,-2.88,0.095
11.57,-2.77,0.095
11.59,-2.66,0.095
11.61,-2.55,0.095
11.63,-2.44,0.095
11.66,-2.34,0.095
11.68,-2.23,0.096
11.70,-2.12,0.096
11.72,-2.01,0.096
11.74,-1.90,0.096
11.77,-1.79,0.096
11.79,-1.69,0.096
11.81,-1.58,0.096
11.83,-1.47,0.096
11.85,-1.36,0.096
11.87,-1.25,0.096
11.90,-1.14,0.096
11.92,-1.03,0.096
11.94,-0.93,0.096
11.96,-0.82,0.096
11.98,-0.71,0.096
12.00,-0.60,0.096
12.03,-0.49,0.096
12.05,-0.38,0.096
12.07,-0.28,0.096
12.09,-0.17,0.096
12.11,-0.06,0.096
12.13,0.05,0.096
12.15,0.16,0.096
12.18,0.27,0.096
12.20,0.37,0.096
12.22,0.48,0.096
12.24,0.59,0.096
12.26,0.70,0.096
12.28,0.81,0.096
12.31,0.92,0.096
12.33,1.03,0.096
12.35,1.13,0.096
12.37,1.24,0.096
12.39,1.35,0.096
12.42,1.46,0.096
12.44,1.57,0.096
12.46,1.68,0.096
12.48,1.79,0.096
12.50,1.89,0.097
12.52,2.00,0.097
12.55,2.11,0.097
12.57,2.22,0.097
12.59,2.33,0.097
12.61,2.44,0.097
12.63,2.54,0.097
12.65,2.65,0.097
12.68,2.76,0.097
12.70,2.87,0.097
12.72,2.98,0.097
12.74,3.09,0.097
12.76,3.19,0.097
12.78,3.30,0.097
12.80,3.41,0.097
12.83,3.52,0.097
12.85,3.63,0.097
12.87,3.74,0.097
12.89,3.84,0.097
12.91,3.95,0.097
12.93,4.06,0.097
12.96,4.17,0.097
12.98,4.28,0.097
13.00,4.39,0.097
13.02,4.50,0.097
13.04,4.60,0.097
13.07,4.71,0.097
13.09,4.82,0.097
13.11,4.93,0.097
13.13,5.04,0.097
13.15,5.14,0.097
13.17,5.25,0.098
13.20,5.36,0.098
13.22,5.47,0.098
13.24,5.58,0.098
13.26,5.69,0.098
13.28,5.79,0.098
13.30,5.90,0.098
13.33,6.01,0.098
13.35,6.12,0.098
13.37,6.23,0.098
13.39,6.34,0.098
13.41,6.44,0.098
13.43,6.55,0.098
13.45,6.66,0.098
13.48,6.77,0.098
13.50,6.88,0.098
13.52,6.98,0.098
13.54,7.09,0.098
13.56,7.20,0.098
13.58,7.31,0.098
13.61,7.42,0.098
13.63,7.53,0.098
13.65,7.63,0.098
13.67,7.74,0.098
13.69,7.85,0.098
13.72,7.96,0.098
13.74,8.07,0.098
13.76,8.18,0.098
13.78,8.29,0.098
13.80,8.40,0.098
13.82,8.50,0.098
13.85,8.61,0.098
13.87,8.72,0.099
13.89,8.83,0.099
13.91,8.94,0.099
13.93,9.05,0.099
13.95,9.15,0.099
13.98,9.26,0.099
14.00,9.37,0.099
14.02,9.48,0.099
14.04,9.59,0.099
14.06,9.70,0.099
14.08,9.81,0.099
14.10,9.91,0.099
14.13,10.02,0.099
14.15,10.13,0.099
14.17,10.24,0.099
14.19,10.35,0.099
14.21,10.46,0.099
14.23,10.56,0.099
14.26,10.67,0.099
14.28,10.78,0.099
14.30,10.89,0.099
14.32,11.00,0.099
14.34,11.11,0.099
14.37,11.22,0.099
14.39,11.32,0.099
14.41,11.43,0.099
14.43,11.54,0.099
14.45,11.65,0.100
14.47,11.76,0.100
14.50,11.86,0.100
14.52,11.97,0.100
14.54,12.08,0.099
14.56,12.19,0.100
14.58,12.30,0.099
14.60,12.41,0.099
14.63,12.51,0.100
14.65,12.62,0.100
14.67,12.73,0.100
14.69,12.84,0.100
14.71,12.95,0.100
14.73,13.06,0.100
14.75,13.17,0.100
14.78,13.27,0.100
14.80,13.38,0.100
14.82,13.49,0.100
14.84,13.60,0.100
14.86,13.71,0.100
14.88,13.82,0.100
14.91,13.92,0.100
14.93,14.03,0.100
14.95,14.14,0.100
14.97,14.25,0.100
14.99,14.36,0.100
15.02,14.47,0.100
15.04,14.58,0.100
15.06,14.68,0.100
15.08,14.79,0.100
15.10,14.90,0.100
15.12,15.01,0.100
15.15,15.12,0.100
15.17,15.23,0.101
15.19,15.34,0.101
15.21,15.44,0.101
15.23,15.55,0.101
15.25,15.66,0.101
15.28,15.77,0.101
15.30,15.88,0.101
15.32,15.99,0.101
15.34,16.09,0.101
15.36,16.20,0.101
15.38,16.31,0.101
15.40,16.42,0.101
15.43,16.53,0.101
15.45,16.64,0.101
15.47,16.74,0.101
15.49,16.85,0.101
15.51,16.96,0.101
15.53,17.07,0.101
15.56,17.18,0.101
15.58,17.29,0.101
15.60,17.40,0.101
15.62,17.50,0.101
15.64,17.61,0.101
15.67,17.72,0.101
15.69,17.83,0.101
15.71,17.94,0.101
15.73,18.05,0.101
15.75,18.15,0.102
15.77,18.26,0.102
15.80,18.37,0.102
15.82,18.48,0.102
15.84,18.59,0.102
15.86,18.70,0.102
15.88,18.81,0.102
15.90,18.91,0.102
15.93,19.02,0.102
15.95,19.13,0.102
15.97,19.24,0.102
15.99,19.35,0.102
16.01,19.46,0.102
16.03,19.56,0.102
16.05,19.67,0.102
16.08,19.78,0.102
16.10,19.89,0.102
16.12,20.00,0.102
16.14,20.11,0.102
16.16,20.21,0.102
16.18,20.32,0.102
16.21,20.43,0.102
16.23,20.54,0.102
16.25,20.65,0.102
16.27,20.76,0.102
16.29,20.86,0.102
16.32,20.97,0.102
16.34,21.08,0.102
16.36,21.19,0.103
16.38,21.30,0.103
16.40,21.41,0.103
16.42,21.51,0.103
16.45,21.62,0.103
16.47,21.73,0.103
16.49,21.84,0.103
16.51,21.95,0.103
16.53,22.06,0.103
16.55,22.16,0.103
16.58,22.27,0.103
16.60,22.38,0.103
16.62,22.49,0.103
16.64,22.60,0.103
16.66,22.71,0.103
16.68,22.81,0.103
16.70,22.92,0.103
16.73,23.03,0.103
16.75,23.14,0.103
16.77,23.25,0.103
16.79,23.36,0.103
16.81,23.47,0.103
16.83,23.57,0.103
16.86,23.68,0.103
16.88,23.79,0.103
16.90,23.90,0.103
16.92,24.01,0.103
16.94,24.12,0.104
16.97,24.22,0.104
16.99,24.33,0.104
17.01,24.44,0.104
17.03,24.55,0.104
17.05,24.66,0.104
17.07,24.77,0.104
17.09,24.88,0.104
17.12,24.98,0.104
17.14,25.09,0.104
17.16,25.20,0.104
17.18,25.31,0.104
17.20,25.42,0.104
17.23,25.53,0.104
17.25,25.63,0.104
17.27,25.74,0.104
17.29,25.85,0.104
17.31,25.96,0.104
17.33,26.07,0.104
17.36,26.18,0.104
17.38,26.28,0.104
17.40,26.39,0.104
17.42,26.50,0.104
17.44,26.61,0.105
17.46,26.72,0.105
17.48,26.83,0.105
17.51,26.93,0.105
17.53,27.04,0.105
17.55,27.15,0.105
17.57,27.26,0.105
17.59,27.37,0.105
17.62,27.48,0.105
17.64,27.58,0.105
17.66,27.69,0.105
17.68,27.80,0.105
17.70,27.91,0.105
17.72,28.02,0.105
17.74,28.13,0.105
17.77,28.24,0.105
17.79,28.34,0.105
17.81,28.45,0.105
17.83,28.56,0.105
17.85,28.67,0.105
17.88,28.78,0.105
17.90,28.89,0.105
17.92,29.00,0.105
17.94,29.10,0.105
17.96,29.21,0.105
17.98,29.32,0.105
18.01,29.43,0.105
18.03,29.54,0.105
18.05,29.65,0.106
18.07,29.75,0.106
18.09,29.86,0.106
18.11,29.97,0.106
18.13,30.08,0.106
18.16,30.19,0.106
18.18,30.30,0.106
18.20,30.40,0.106
18.22,30.51,0.106
18.24,30.62,0.106
18.27,30.73,0.106
18.29,30.84,0.106
18.31,30.95,0.106
18.33,31.05,0.106
18.35,31.16,0.106
18.37,31.27,0.106
18.39,31.38,0.106
18.42,31.49,0.106
18.44,31.60,0.106
18.46,31.70,0.106
18.48,31.81,0.106
18.50,31.92,0.106
18.53,32.03,0.106
18.55,32.14,0.106
18.57,32.25,0.106
18.59,32.36,0.106
18.61,32.46,0.107
18.63,32.57,0.107
18.66,32.68,0.107
18.68,32.79,0.107
18.70,32.90,0.107
18.72,33.01,0.107
18.74,33.12,0.107
18.76,33.22,0.107
18.78,33.33,0.107
18.81,33.44,0.107
18.83,33.55,0.107
18.85,33.66,0.107
18.87,33.77,0.107
18.89,33.87,0.107
18.92,33.98,0.107
18.94,34.09,0.107
18.96,34.20,0.107
18.98,34.31,0.107
19.00,34.42,0.107
19.02,34.52,0.107
19.04,34.63,0.108
19.07,34.74,0.108
19.09,34.85,0.108
19.11,34.96,0.108
19.13,35.07,0.108
19.15,35.18,0.108
19.18,35.28,0.108
19.20,35.39,0.108
19.22,35.50,0.108
19.24,35.61,0.108
19.26,35.72,0.108
19.28,35.83,0.108
19.31,35.93,0.108
19.33,36.04,0.108
19.35,36.15,0.108
19.37,36.26,0.108
19.39,36.37,0.108
19.41,36.47,0.108
19.43,36.58,0.108
19.46,36.69,0.108
19.48,36.80,0.108
19.50,36.91,0.108
19.52,37.02,0.108
19.54,37.13,0.108
19.57,37.23,0.108
19.59,37.34,0.108
19.61,37.45,0.108
19.63,37.56,0.108
19.65,37.67,0.108
19.67,37.77,0.108
19.69,37.88,0.108
19.72,37.99,0.109
19.74,38.10,0.109
19.76,38.21,0.109
19.78,38.32,0.109
19.80,38.42,0.109
19.83,38.53,0.109
19.85,38.64,0.109
19.87,38.75,0.109
19.89,38.86,0.109
19.91,38.97,0.109
19.93,39.07,0.109
19.96,39.18,0.109
19.98,39.29,0.109
20.00,39.40,0.109
20.02,39.51,0.109
20.04,39.62,0.109
20.06,39.73,0.109
20.08,39.83,0.109
20.11,39.94,0.109
20.13,40.05,0.109
20.15,40.16,0.109
20.17,40.27,0.109
20.19,40.38,0.109
20.22,40.48,0.109
20.24,40.59,0.110
20.26,40.70,0.110
20.28,40.81,0.110
20.30,40.92,0.110
20.32,41.03,0.110
20.34,41.13,0.110
20.37,41.24,0.110
20.39,41.35,0.110
20.41,41.46,0.110
20.43,41.57,0.110
20.45,41.68,0.110
20.48,41.78,0.110
20.50,41.89,0.110
20.52,42.00,0.110
20.54,42.11,0.110
20.56,42.22,0.110
20.58,42.33,0.110
20.61,42.43,0.110
20.63,42.54,0.110
20.65,42.65,0.110
20.67,42.76,0.110
20.69,42.87,0.110
20.71,42.98,0.110
20.73,43.09,0.110
20.76,43.19,0.110
20.78,43.30,0.110
20.80,43.41,0.111
20.82,43.52,0.111
20.84,43.63,0.111
20.87,43.74,0.111
20.89,43.84,0.111
20.91,43.95,0.111
20.93,44.06,0.111
20.95,44.17,0.111
20.97,44.28,0.111
20.99,44.39,0.111
21.02,44.49,0.111
21.04,44.60,0.111
21.06,44.71,0.111
21.08,44.82,0.111
21.10,44.93,0.111
21.13,45.04,0.111
21.15,45.15,0.111
21.17,45.25,0.111
21.19,45.36,0.111
21.21,45.47,0.111
21.23,45.58,0.111
21.26,45.69,0.111
21.28,45.80,0.111
21.30,45.90,0.112
21.32,46.01,0.112
21.34,46.12,0.112
21.36,46.23,0.112
21.38,46.34,0.112
21.41,46.44,0.112
21.43,46.55,0.112
21.45,46.66,0.112
21.47,46.77,0.112
21.49,46.88,0.112
21.52,46.99,0.112
21.54,47.10,0.112
21.56,47.20,0.112
21.58,47.31,0.112
21.60,47.42,0.112
21.62,47.53,0.112
21.64,47.64,0.112
21.67,47.75,0.112
21.69,47.85,0.112
21.71,47.96,0.112
21.73,48.07,0.112
21.75,48.18,0.113
21.78,48.29,0.113
21.80,48.40,0.113
21.82,48.50,0.113
21.84,48.61,0.113
21.86,48.72,0.113
21.88,48.83,0.113
21.91,48.94,0.113
21.93,49.05,0.113
21.95,49.15,0.113
21.97,49.26,0.113
21.99,49.37,0.113
22.01,49.48,0.113
22.03,49.59,0.113
22.06,49.70,0.113
22.08,49.80,0.113
22.10,49.91,0.113
22.12,50.02,0.113
22.14,50.13,0.113
22.17,50.24,0.113
22.19,50.35,0.113
22.21,50.45,0.114
22.23,50.56,0.114
22.25,50.67,0.114
22.27,50.78,0.114
22.29,50.89,0.114
22.32,51.00,0.114
22.34,51.11,0.114
22.36,51.21,0.114
22.38,51.32,0.114
22.40,51.43,0.114
22.43,51.54,0.114
22.45,51.65,0.114
22.47,51.76,0.114
22.49,51.86,0.114
22.51,51.97,0.114
22.53,52.08,0.114
22.56,52.19,0.114
22.58,52.30,0.114
22.60,52.41,0.114
22.62,52.51,0.115
22.64,52.62,0.115
22.66,52.73,0.115
22.68,52.84,0.115
22.71,52.95,0.115
22.73,53.06,0.115
22.75,53.16,0.115
22.77,53.27,0.115
22.79,53.38,0.115
22.82,53.49,0.115
22.84,53.60,0.115
22.86,53.71,0.115
22.88,53.82,0.115
22.90,53.92,0.115
22.92,54.03,0.116
22.94,54.14,0.116
22.97,54.25,0.116
22.99,54.36,0.116
23.01,54.47,0.116
23.03,54.57,0.116
23.05,54.68,0.116
23.08,54.79,0.116
23.10,54.90,0.116
23.12,55.01,0.116
23.14,55.11,0.116
23.16,55.22,0.117
23.18,55.33,0.117
23.21,55.44,0.117
23.23,55.55,0.117
23.25,55.66,0.117
23.27,55.76,0.117
23.29,55.87,0.117
23.31,55.98,0.117
23.33,56.09,0.117
23.36,56.20,0.117
23.38,56.31,0.117
23.40,56.41,0.118
23.42,56.52,0.118
23.44,56.63,0.118
23.47,56.74,0.118
23.49,56.85,0.118
23.51,56.96,0.118
23.53,57.06,0.118
23.55,57.17,0.118
23.57,57.28,0.119
23.59,57.39,0.119
23.62,57.50,0.119
23.64,57.60,0.119
23.66,57.71,0.119
23.68,57.82,0.119
23.70,57.93,0.119
23.73,58.04,0.120
23.75,58.15,0.120
23.77,58.25,0.120
23.79,58.36,0.121
23.81,58.47,0.121
23.83,58.58,0.121
23.86,58.69,0.121
23.88,58.80,0.121
23.90,58.90,0.122
23.92,59.01,0.122
23.94,59.12,0.122
23.96,59.23,0.123
23.98,59.34,0.123
24.01,59.45,0.123
24.03,59.55,0.124
24.05,59.66,0.124
24.07,59.77,0.125
24.09,59.88,0.125
24.12,59.99,0.125
24.14,60.09,0.126
24.16,60.20,0.126
24.18,60.31,0.127
24.20,60.42,0.127
24.22,60.53,0.128
24.24,60.63,0.129
24.27,60.74,0.130
24.29,60.85,0.131
24.31,60.96,0.132
24.33,61.07,0.134
24.35,61.17,0.135
24.38,61.28,0.136
24.40,61.39,0.138
24.42,61.50,0.139
24.44,61.60,0.141
24.46,61.71,0.143
24.48,61.82,0.145
24.51,61.92,0.148
24.53,62.03,0.150
24.55,62.14,0.152
24.57,62.25,0.155
24.59,62.35,0.158
24.61,62.46,0.162
24.63,62.56,0.166
24.66,62.67,0.169
24.68,62.78,0.174
24.70,62.88,0.179
24.72,62.99,0.185
24.74,63.09,0.191
24.77,63.19,0.197
24.79,63.30,0.205
24.81,63.40,0.212
24.83,63.51,0.221
24.85,63.61,0.229
24.87,63.71,0.239
24.89,63.81,0.250
24.92,63.91,0.261
24.94,64.02,0.272
24.96,64.12,0.286
24.98,64.22,0.299
25.00,64.31,0.314
25.03,64.41,0.330
25.05,64.51,0.345
25.07,64.61,0.364
25.09,64.70,0.381
25.11,64.80,0.401
25.13,64.89,0.422
25.16,64.99,0.445
25.18,65.08,0.470
25.20,65.17,0.496
25.22,65.26,0.524
25.24,65.35,0.554
25.26,65.44,0.585
25.28,65.52,0.617
25.31,65.61,0.651
25.33,65.70,0.681
25.35,65.78,0.711
25.37,65.87,0.744
25.39,65.95,0.778
25.42,66.04,0.814
25.44,66.12,0.858
25.46,66.20,0.902
25.48,66.28,0.941
25.50,66.36,0.981
25.52,66.43,1.023
25.54,66.51,1.079
25.57,66.58,1.122
25.59,66.66,1.168
25.61,66.73,1.226
25.63,66.80,1.301
25.65,66.86,1.380
25.68,66.92,1.438
25.70,66.99,1.490
25.72,67.05,1.541
25.74,67.12,1.590
25.76,67.19,1.629
25.78,67.27,1.664
25.81,67.35,1.681
25.83,67.44,1.677
25.85,67.54,1.643
25.87,67.65,1.597
25.89,67.78,1.544
25.91,67.91,1.485
25.93,68.05,1.421
25.96,68.20,1.350
25.98,68.35,1.274
26.00,68.51,1.193
26.02,68.67,1.111
26.04,68.84,1.028
26.07,69.00,0.947
26.09,69.17,0.868
26.11,69.33,0.790
26.13,69.50,0.716
26.15,69.67,0.648
26.17,69.83,0.585
26.19,69.98,0.530
26.22,70.14,0.484
26.24,70.29,0.437
26.26,70.43,0.404
26.28,70.58,0.365
26.30,70.71,0.335
26.33,70.85,0.307
26.35,70.98,0.284
26.37,71.11,0.263
26.39,71.24,0.245
26.41,71.37,0.230
26.43,71.49,0.218
26.46,71.61,0.208
26.48,71.73,0.199
26.50,71.85,0.193
26.52,71.96,0.186
26.54,72.08,0.181
26.56,72.19,0.177
26.58,72.30,0.173
26.61,72.41,0.170
26.63,72.53,0.167
26.65,72.64,0.165
26.67,72.75,0.164
26.69,72.86,0.162
26.72,72.97,0.161
26.74,73.08,0.160
26.76,73.19,0.159
26.78,73.30,0.158
26.80,73.41,0.158
26.82,73.52,0.157
26.84,73.62,0.157
26.87,73.73,0.156
26.89,73.84,0.156
26.91,73.95,0.156
26.93,74.06,0.156
26.95,74.17,0.156
26.98,74.28,0.155
27.00,74.39,0.155
27.02,74.49,0.155
27.04,74.60,0.155
27.06,74.71,0.155
27.08,74.82,0.155
27.11,74.93,0.155
27.13,75.04,0.154
27.15,75.15,0.154
27.17,75.25,0.154
27.19,75.36,0.154
27.21,75.47,0.154
27.23,75.58,0.154
27.26,75.69,0.154
27.28,75.80,0.154
27.30,75.90,0.154
27.32,76.01,0.154
27.34,76.12,0.154
27.37,76.23,0.153
27.39,76.34,0.153
27.41,76.45,0.153
27.43,76.56,0.153
27.45,76.66,0.153
27.47,76.77,0.153
27.49,76.88,0.153
27.52,76.99,0.153
27.54,77.10,0.153
27.56,77.20,0.153
27.58,77.31,0.153
27.60,77.42,0.153
27.63,77.53,0.153
27.65,77.64,0.153
27.67,77.75,0.153
27.69,77.85,0.153
27.71,77.96,0.153
27.73,78.07,0.153
27.76,78.18,0.153
27.78,78.29,0.153
27.80,78.40,0.153
27.82,78.51,0.153
27.84,78.61,0.153
27.86,78.72,0.153
27.88,78.83,0.153
27.91,78.94,0.153
27.93,79.05,0.153
27.95,79.16,0.153
27.97,79.26,0.153
27.99,79.37,0.153
28.02,79.48,0.153
28.04,79.59,0.153
28.06,79.70,0.153
28.08,79.81,0.153
28.10,79.91,0.153
28.12,80.02,0.154
28.14,80.13,0.153
28.17,80.24,0.153
28.19,80.35,0.154
28.21,80.46,0.154
28.23,80.57,0.154
28.25,80.67,0.154
28.28,80.78,0.154
28.30,80.89,0.154
28.32,81.00,0.154
28.34,81.11,0.154
28.36,81.22,0.154
28.38,81.32,0.154
28.41,81.43,0.154
28.43,81.54,0.154
28.45,81.65,0.154
28.47,81.76,0.154
28.49,81.87,0.154
28.51,81.97,0.154
28.53,82.08,0.154
28.56,82.19,0.154
28.58,82.30,0.154
28.60,82.41,0.154
28.62,82.52,0.154
28.64,82.62,0.154
28.67,82.73,0.154
28.69,82.84,0.154
28.71,82.95,0.154
28.73,83.06,0.154
28.75,83.17,0.154
28.77,83.28,0.154
28.79,83.38,0.154
28.82,83.49,0.154
28.84,83.60,0.154
28.86,83.71,0.154
28.88,83.82,0.154
28.90,83.92,0.154
28.93,84.03,0.154
28.95,84.14,0.154
28.97,84.25,0.154
28.99,84.36,0.154
29.01,84.47,0.154
29.03,84.58,0.154
29.06,84.68,0.154
29.08,84.79,0.154
29.10,84.90,0.154
29.12,85.01,0.154
29.14,85.12,0.154
29.16,85.23,0.154
29.18,85.34,0.154
29.21,85.44,0.154
29.23,85.55,0.154
29.25,85.66,0.154
29.27,85.77,0.154
29.29,85.88,0.154
29.32,85.99,0.154
29.34,86.09,0.154
29.36,86.20,0.154
29.38,86.31,0.154
29.40,86.42,0.154
29.42,86.53,0.154
29.44,86.63,0.154
29.47,86.74,0.154
29.49,86.85,0.154
29.51,86.96,0.154
29.53,87.07,0.154
29.55,87.18,0.154
29.58,87.29,0.154
29.60,87.39,0.154
29.62,87.50,0.154
29.64,87.61,0.154
29.66,87.72,0.154
29.68,87.83,0.155
29.71,87.94,0.155
29.73,88.04,0.155
29.75,88.15,0.155
29.77,88.26,0.155
29.79,88.37,0.155
29.81,88.48,0.155
29.83,88.59,0.155
29.86,88.70,0.155
29.88,88.80,0.155
29.90,88.91,0.155
29.92,89.02,0.155
29.94,89.13,0.155
29.97,89.24,0.155
29.99,89.35,0.155
30.01,89.45,0.155
30.03,89.56,0.155
30.05,89.67,0.155
30.07,89.78,0.155
30.09,89.89,0.155
30.12,90.00,0.155
30.14,90.11,0.155
30.16,90.21,0.155
30.18,90.32,0.155
30.20,90.43,0.155
30.23,90.54,0.155
30.25,90.65,0.155
30.27,90.75,0.155
30.29,90.86,0.155
30.31,90.97,0.155
30.33,91.08,0.155
30.36,91.19,0.155
30.38,91.30,0.155
30.40,91.41,0.155
30.42,91.51,0.155
30.44,91.62,0.155
30.46,91.73,0.155
30.48,91.84,0.155
30.51,91.95,0.155
30.53,92.06,0.155
30.55,92.16,0.155
30.57,92.27,0.155
30.59,92.38,0.155
30.62,92.49,0.155
30.64,92.60,0.155
30.66,92.71,0.155
30.68,92.82,0.155
30.70,92.92,0.155
30.72,93.03,0.155
30.74,93.14,0.155
30.77,93.25,0.155
30.79,93.36,0.155
30.81,93.47,0.155
30.83,93.57,0.156
30.85,93.68,0.156
30.88,93.79,0.156
30.90,93.90,0.156
30.92,94.01,0.156
30.94,94.12,0.156
30.96,94.22,0.156
30.98,94.33,0.156
31.01,94.44,0.156
31.03,94.55,0.156
31.05,94.66,0.156
31.07,94.77,0.156
31.09,94.87,0.156
31.11,94.98,0.156
31.13,95.09,0.156
31.16,95.20,0.156
31.18,95.31,0.156
31.20,95.42,0.156
31.22,95.52,0.156
31.24,95.63,0.156
31.27,95.74,0.156
31.29,95.85,0.156
31.31,95.96,0.156
31.33,96.07,0.156
31.35,96.18,0.156
31.37,96.28,0.156
31.39,96.39,0.156
31.42,96.50,0.156
31.44,96.61,0.156
31.46,96.72,0.156
31.48,96.83,0.156
31.50,96.94,0.156
31.53,97.04,0.156
31.55,97.15,0.156
31.57,97.26,0.156
31.59,97.37,0.156
31.61,97.48,0.156
31.63,97.59,0.156
31.66,97.69,0.156
31.68,97.80,0.156
31.70,97.91,0.156
31.72,98.02,0.156
31.74,98.13,0.156
31.76,98.24,0.156
31.78,98.34,0.156
31.81,98.45,0.156
31.83,98.56,0.156
31.85,98.67,0.156
31.87,98.78,0.156
31.89,98.88,0.157
31.92,98.99,0.157
31.94,99.10,
31.96,99.21,
31.98,,
31.98,,

[step]
Ramp 5.00 °C/min to -60.00 °C
Time,Temperature,Heat Flow (Normalized)
min,°C,W/g
32.98,100.12,-0.019
33.01,100.12,-0.019
33.03,100.12,-0.019
33.05,100.11,-0.013
33.07,100.08,-0.005
33.09,100.05,-0.005
33.12,99.99,-0.018
33.14,99.93,-0.040
33.16,99.86,-0.063
33.18,99.79,-0.084
33.20,99.71,-0.101
33.22,99.62,-0.114
33.24,99.54,-0.126
33.27,99.45,-0.136
33.29,99.35,-0.145
33.31,99.26,-0.152
33.33,99.16,-0.158
33.35,99.06,-0.164
33.38,98.97,-0.168
33.40,98.87,-0.173
33.42,98.76,-0.176
33.44,98.66,-0.178
33.46,98.56,-0.180
33.48,98.45,-0.183
33.51,98.35,-0.184
33.53,98.25,-0.185
33.55,98.14,-0.187
33.57,98.04,-0.188
33.59,97.93,-0.188
33.61,97.83,-0.189
33.63,97.72,-0.189
33.66,97.61,-0.190
33.68,97.51,-0.190
33.70,97.40,-0.190
33.72,97.29,-0.191
33.74,97.19,-0.191
33.77,97.08,-0.191
33.79,96.97,-0.192
33.81,96.86,-0.192
33.83,96.76,-0.192
33.85,96.65,-0.192
33.87,96.54,-0.193
33.89,96.44,-0.193
33.92,96.33,-0.193
33.94,96.22,-0.193
33.96,96.11,-0.193
33.98,96.01,-0.193
34.00,95.90,-0.194
34.03,95.79,-0.194
34.05,95.68,-0.194
34.07,95.57,-0.194
34.09,95.47,-0.194
34.11,95.36,-0.194
34.13,95.25,-0.194
34.16,95.14,-0.194
34.18,95.03,-0.194
34.20,94.93,-0.195
34.22,94.82,-0.195
34.24,94.71,-0.195
34.26,94.60,-0.195
34.29,94.49,-0.195
34.31,94.39,-0.195
34.33,94.28,-0.195
34.35,94.17,-0.195
34.37,94.06,-0.195
34.39,93.95,-0.195
34.41,93.85,-0.195
34.44,93.74,-0.195
34.46,93.63,-0.195
34.48,93.52,-0.195
34.50,93.41,-0.195
34.52,93.30,-0.195
34.54,93.20,-0.195
34.57,93.09,-0.195
34.59,92.98,-0.195
34.61,92.87,-0.195
34.63,92.76,-0.195
34.65,92.66,-0.195
34.68,92.55,-0.194
34.70,92.44,-0.195
34.72,92.33,-0.194
34.74,92.22,-0.194
34.76,92.12,-0.194
34.78,92.01,-0.194
34.81,91.90,-0.194
34.83,91.79,-0.194
34.85,91.68,-0.194
34.87,91.57,-0.194
34.89,91.47,-0.194
34.91,91.36,-0.194
34.94,91.25,-0.194
34.96,91.14,-0.194
34.98,91.03,-0.194
35.00,90.93,-0.194
35.02,90.82,-0.194
35.04,90.71,-0.194
35.06,90.60,-0.194
35.09,90.49,-0.194
35.11,90.38,-0.194
35.13,90.28,-0.194
35.15,90.17,-0.194
35.17,90.06,-0.194
35.19,89.95,-0.194
35.22,89.84,-0.193
35.24,89.73,-0.193
35.26,89.63,-0.193
35.28,89.52,-0.193
35.30,89.41,-0.193
35.33,89.30,-0.193
35.35,89.19,-0.193
35.37,89.09,-0.193
35.39,88.98,-0.193
35.41,88.87,-0.193
35.43,88.76,-0.193
35.46,88.65,-0.193
35.48,88.54,-0.193
35.50,88.43,-0.193
35.52,88.33,-0.193
35.54,88.22,-0.193
35.56,88.11,-0.193
35.59,88.00,-0.193
35.61,87.89,-0.192
35.63,87.79,-0.192
35.65,87.68,-0.192
35.67,87.57,-0.192
35.69,87.46,-0.192
35.71,87.35,-0.192
35.74,87.24,-0.192
35.76,87.14,-0.192
35.78,87.03,-0.192
35.80,86.92,-0.192
35.82,86.81,-0.192
35.84,86.70,-0.192
35.87,86.59,-0.192
35.89,86.49,-0.192
35.91,86.38,-0.192
35.93,86.27,-0.192
35.95,86.16,-0.192
35.98,86.05,-0.192
36.00,85.95,-0.192
36.02,85.84,-0.192
36.04,85.73,-0.192
36.06,85.62,-0.192
36.08,85.51,-0.192
36.11,85.40,-0.192
36.13,85.29,-0.192
36.15,85.19,-0.192
36.17,85.08,-0.191
36.19,84.97,-0.191
36.21,84.86,-0.191
36.24,84.75,-0.191
36.26,84.64,-0.191
36.28,84.54,-0.191
36.30,84.43,-0.191
36.32,84.32,-0.191
36.34,84.21,-0.191
36.36,84.10,-0.191
36.39,84.00,-0.191
36.41,83.89,-0.191
36.43,83.78,-0.191
36.45,83.67,-0.191
36.47,83.56,-0.191
36.49,83.45,-0.191
36.52,83.35,-0.191
36.54,83.24,-0.191
36.56,83.13,-0.191
36.58,83.02,-0.191
36.60,82.91,-0.191
36.63,82.81,-0.191
36.65,82.70,-0.191
36.67,82.59,-0.191
36.69,82.48,-0.191
36.71,82.37,-0.191
36.73,82.26,-0.191
36.76,82.16,-0.190
36.78,82.05,-0.190
36.80,81.94,-0.190
36.82,81.83,-0.190
36.84,81.72,-0.190
36.86,81.61,-0.190
36.89,81.51,-0.190
36.91,81.40,-0.190
36.93,81.29,-0.190
36.95,81.18,-0.190
36.97,81.07,-0.190
36.99,80.96,-0.190
37.01,80.86,-0.190
37.04,80.75,-0.190
37.06,80.64,-0.190
37.08,80.53,-0.190
37.10,80.42,-0.190
37.12,80.31,-0.190
37.14,80.21,-0.190
37.17,80.10,-0.190
37.19,79.99,-0.190
37.21,79.88,-0.190
37.23,79.77,-0.190
37.25,79.66,-0.190
37.28,79.56,-0.190
37.30,79.45,-0.190
37.32,79.34,-0.190
37.34,79.23,-0.190
37.36,79.12,-0.190
37.38,79.01,-0.190
37.41,78.91,-0.189
37.43,78.80,-0.189
37.45,78.69,-0.189
37.47,78.58,-0.189
37.49,78.47,-0.189
37.51,78.37,-0.189
37.54,78.26,-0.189
37.56,78.15,-0.189
37.58,78.04,-0.189
37.60,77.93,-0.189
37.62,77.82,-0.189
37.64,77.72,-0.189
37.66,77.61,-0.189
37.69,77.50,-0.189
37.71,77.39,-0.189
37.73,77.28,-0.189
37.75,77.17,-0.189
37.77,77.07,-0.189
37.79,76.96,-0.189
37.82,76.85,-0.189
37.84,76.74,-0.189
37.86,76.63,-0.189
37.88,76.52,-0.189
37.90,76.42,-0.189
37.93,76.31,-0.189
37.95,76.20,-0.189
37.97,76.09,-0.189
37.99,75.98,-0.188
38.01,75.87,-0.188
38.03,75.77,-0.188
38.06,75.66,-0.188
38.08,75.55,-0.188
38.10,75.44,-0.188
38.12,75.33,-0.188
38.14,75.22,-0.188
38.16,75.12,-0.188
38.19,75.01,-0.188
38.21,74.90,-0.188
38.23,74.79,-0.188
38.25,74.68,-0.188
38.27,74.58,-0.188
38.29,74.47,-0.188
38.31,74.36,-0.188
38.34,74.25,-0.188
38.36,74.14,-0.188
38.38,74.03,-0.188
38.40,73.93,-0.188
38.42,73.82,-0.188
38.44,73.71,-0.188
38.47,73.60,-0.188
38.49,73.49,-0.188
38.51,73.39,-0.187
38.53,73.28,-0.187
38.55,73.17,-0.187
38.58,73.06,-0.187
38.60,72.95,-0.187
38.62,72.84,-0.187
38.64,72.74,-0.187
38.66,72.63,-0.187
38.68,72.52,-0.187
38.71,72.41,-0.187
38.73,72.30,-0.187
38.75,72.19,-0.187
38.77,72.09,-0.187
38.79,71.98,-0.187
38.81,71.87,-0.187
38.84,71.76,-0.187
38.86,71.65,-0.187
38.88,71.54,-0.187
38.90,71.44,-0.187
38.92,71.33,-0.187
38.94,71.22,-0.187
38.96,71.11,-0.187
38.99,71.00,-0.187
39.01,70.89,-0.187
39.03,70.79,-0.187
39.05,70.68,-0.187
39.07,70.57,-0.186
39.09,70.46,-0.186
39.12,70.35,-0.186
39.14,70.25,-0.186
39.16,70.14,-0.186
39.18,70.03,-0.186
39.20,69.92,-0.186
39.23,69.81,-0.186
39.25,69.70,-0.186
39.27,69.60,-0.186
39.29,69.49,-0.186
39.31,69.38,-0.186
39.33,69.27,-0.186
39.36,69.16,-0.186
39.38,69.05,-0.186
39.40,68.95,-0.186
39.42,68.84,-0.186
39.44,68.73,-0.186
39.46,68.62,-0.186
39.49,68.51,-0.186
39.51,68.40,-0.186
39.53,68.30,-0.186
39.55,68.19,-0.186
39.57,68.08,-0.186
39.59,67.97,-0.185
39.61,67.86,-0.186
39.64,67.75,-0.185
39.66,67.64,-0.185
39.68,67.54,-0.185
39.70,67.43,-0.185
39.72,67.32,-0.185
39.74,67.21,-0.185
39.77,67.11,-0.185
39.79,67.00,-0.185
39.81,66.89,-0.185
39.83,66.78,-0.185
39.85,66.67,-0.185
39.88,66.56,-0.185
39.90,66.45,-0.185
39.92,66.35,-0.185
39.94,66.24,-0.185
39.96,66.13,-0.185
39.98,66.02,-0.185
40.01,65.91,-0.185
40.03,65.81,-0.185
40.05,65.70,-0.185
40.07,65.59,-0.185
40.09,65.48,-0.185
40.11,65.37,-0.185
40.14,65.26,-0.185
40.16,65.16,-0.185
40.18,65.05,-0.184
40.20,64.94,-0.184
40.22,64.83,-0.184
40.24,64.72,-0.184
40.26,64.61,-0.184
40.29,64.51,-0.184
40.31,64.40,-0.184
40.33,64.29,-0.184
40.35,64.18,-0.184
40.37,64.07,-0.184
40.39,63.97,-0.184
40.42,63.86,-0.184
40.44,63.75,-0.184
40.46,63.64,-0.184
40.48,63.53,-0.184
40.50,63.42,-0.184
40.53,63.31,-0.184
40.55,63.21,-0.184
40.57,63.10,-0.184
40.59,62.99,-0.184
40.61,62.88,-0.184
40.63,62.77,-0.184
[...]
168.98,81.04,-0.185
168.99,80.99,-0.185
169.00,80.95,-0.185
169.01,80.90,-0.185
169.02,80.84,-0.185
169.03,80.79,-0.185
169.04,80.74,-0.185
169.05,80.70,-0.185
169.06,80.65,-0.185
169.07,80.60,-0.185
169.08,80.54,-0.185
169.09,80.50,-0.185
169.10,80.44,-0.185
169.11,80.39,-0.185
169.12,80.35,-0.185
169.13,80.30,-0.185
169.14,80.24,-0.185
169.15,80.19,-0.185
169.16,80.15,-0.185
169.17,80.10,-0.185
169.18,80.04,-0.185
169.19,80.00,-0.185
169.20,79.95,-0.185
169.21,79.90,-0.185
169.22,79.85,-0.185
169.23,79.79,-0.185
169.24,79.75,-0.185
169.25,79.70,-0.185
169.26,79.65,-0.185
169.27,79.60,-0.185
169.28,79.54,-0.185
169.29,79.50,-0.185
169.30,79.44,-0.185
169.31,79.40,-0.185
169.32,79.35,-0.185
169.33,79.29,-0.185
169.34,79.25,-0.185
169.35,79.20,-0.185
169.36,79.15,-0.185
169.37,79.10,-0.185
169.38,79.05,-0.185
169.39,79.00,-0.185
169.40,78.95,-0.185
169.41,78.90,-0.185
169.42,78.85,-0.185
169.43,78.80,-0.185
169.44,78.75,-0.185
169.45,78.70,-0.185
169.46,78.65,-0.185
169.47,78.60,-0.185
169.48,78.55,-0.185
169.49,78.50,-0.185
169.50,78.45,-0.185
169.51,78.40,-0.185
169.52,78.35,-0.185
169.53,78.30,-0.185
169.54,78.25,-0.185
169.55,78.20,-0.185
169.56,78.15,-0.185
169.57,78.10,-0.184
169.58,78.05,-0.184
169.59,78.00,-0.184
169.60,77.95,-0.184
169.61,77.90,-0.184
169.62,77.85,-0.184
169.63,77.80,-0.184
169.64,77.75,-0.184
169.65,77.70,-0.184
169.66,77.65,-0.184
169.67,77.60,-0.184
169.68,77.55,-0.184
169.69,77.50,-0.184
169.70,77.45,-0.184
169.71,77.40,-0.184
169.72,77.35,-0.184
169.73,77.30,-0.184
169.74,77.25,-0.184
169.75,77.20,-0.184
169.76,77.15,-0.184
169.77,77.10,-0.184
169.78,77.05,-0.184
169.79,77.00,-0.184
169.80,76.95,-0.184
169.81,76.90,-0.184
169.82,76.85,-0.184
169.83,76.80,-0.184
169.84,76.75,-0.184
169.85,76.70,-0.184
169.86,76.65,-0.184
169.87,76.60,-0.184
169.88,76.55,-0.184
169.89,76.50,-0.184
169.90,76.45,-0.184
169.91,76.40,-0.184
169.92,76.35,-0.184
169.93,76.30,-0.184
169.94,76.25,-0.184
169.95,76.20,-0.184
169.96,76.15,-0.184
169.97,76.10,-0.184
169.98,76.05,-0.184
169.99,76.00,-0.184
170.00,75.95,-0.184
170.01,75.90,-0.184
170.02,75.85,-0.183
170.03,75.80,-0.183
170.04,75.75,-0.183
170.05,75.70,-0.183
170.06,75.65,-0.183
170.07,75.60,-0.183
170.08,75.55,-0.183
170.09,75.50,-0.183
170.10,75.45,-0.183
170.11,75.40,-0.183
170.12,75.35,-0.183
170.13,75.30,-0.183
170.14,75.25,-0.183
170.15,75.20,-0.183
170.16,75.15,-0.183
170.17,75.10,-0.183
170.18,75.05,-0.183
170.19,75.00,-0.183
170.20,74.95,-0.183
170.21,74.90,-0.183
170.22,74.85,-0.183
170.23,74.80,-0.183
170.24,74.75,-0.183
170.25,74.70,-0.183
170.26,74.65,-0.183
170.27,74.60,-0.183
170.28,74.55,-0.183
170.29,74.50,-0.183
170.30,74.45,-0.183
170.31,74.40,-0.183
170.32,74.35,-0.183
170.33,74.30,-0.183
170.34,74.25,-0.183
170.35,74.20,-0.183
170.36,74.15,-0.183
170.37,74.10,-0.183
170.38,74.05,-0.183
170.39,74.00,-0.183
170.40,73.95,-0.183
170.41,73.90,-0.183
170.42,73.85,-0.183
170.43,73.80,-0.183
170.44,73.75,-0.183
170.45,73.70,-0.183
170.46,73.65,-0.183
170.47,73.60,-0.183
170.48,73.55,-0.183
170.49,73.50,-0.183
170.50,73.45,-0.183
170.51,73.40,-0.183
170.52,73.35,-0.183
170.53,73.30,-0.183
170.54,73.25,-0.183
170.55,73.20,-0.183
170.56,73.15,-0.183
170.57,73.10,-0.182
170.58,73.05,-0.182
170.59,73.00,-0.182
170.60,72.95,-0.182
170.61,72.90,-0.182
170.62,72.85,-0.182
170.63,72.80,-0.182
170.64,72.75,-0.182
170.65,72.70,-0.182
170.66,72.65,-0.182
170.67,72.60,-0.182
170.68,72.55,-0.182
170.69,72.50,-0.182
170.70,72.45,-0.182
170.71,72.40,-0.182
170.72,72.35,-0.182
170.73,72.30,-0.182
170.74,72.25,-0.182
170.75,72.20,-0.182
170.76,72.15,-0.182
170.77,72.10,-0.182
170.78,72.05,-0.182
170.79,72.00,-0.182
170.80,71.95,-0.182
170.81,71.90,-0.182
170.82,71.85,-0.182
170.83,71.80,-0.182
170.84,71.75,-0.182
170.85,71.70,-0.182
170.86,71.65,-0.182
170.87,71.60,-0.182
170.88,71.55,-0.182
170.89,71.50,-0.182
170.90,71.45,-0.182
170.91,71.40,-0.182
170.92,71.35,-0.182
170.93,71.30,-0.182
170.94,71.25,-0.182
170.95,71.20,-0.182
170.96,71.15,-0.182
170.97,71.10,-0.182
170.98,71.05,-0.182
170.99,71.00,-0.182
171.00,70.95,-0.182
171.01,70.90,-0.182
171.02,70.85,-0.182
171.03,70.80,-0.182
171.04,70.75,-0.182
171.05,70.70,-0.182
171.06,70.65,-0.181
171.07,70.60,-0.181
171.08,70.55,-0.181
171.09,70.50,-0.181
171.10,70.45,-0.181
171.11,70.40,-0.181
171.12,70.35,-0.181
171.13,70.30,-0.181
171.14,70.25,-0.181
171.15,70.20,-0.181
171.16,70.15,-0.181
171.17,70.10,-0.181
171.18,70.05,-0.181
171.19,70.00,-0.181
171.20,69.95,-0.181
171.21,69.90,-0.181
171.22,69.85,-0.181
171.23,69.80,-0.181
171.24,69.75,-0.181
171.25,69.70,-0.181
171.26,69.65,-0.181
171.27,69.60,-0.181
171.28,69.55,-0.181
171.29,69.50,-0.181
171.30,69.45,-0.181
171.31,69.40,-0.181
171.32,69.35,-0.181
171.33,69.30,-0.181
171.34,69.25,-0.181
171.35,69.20,-0.181
171.36,69.15,-0.181
171.37,69.10,-0.181
171.38,69.05,-0.181
171.39,69.00,-0.181
171.40,68.95,-0.181
171.41,68.90,-0.181
171.42,68.85,-0.181
171.43,68.80,-0.181
171.44,68.75,-0.181
171.45,68.70,-0.181
171.46,68.65,-0.181
171.47,68.60,-0.181
171.48,68.55,-0.181
171.49,68.50,-0.181
171.50,68.45,-0.181
171.51,68.40,-0.181
171.52,68.35,-0.181
171.53,68.30,-0.181
171.54,68.25,-0.181
171.55,68.20,-0.181
171.56,68.15,-0.181
171.57,68.10,-0.180
171.58,68.05,-0.180
171.59,68.00,-0.180
171.60,67.95,-0.180
171.61,67.90,-0.180
171.62,67.85,-0.180
171.63,67.80,-0.180
171.64,67.75,-0.180
171.65,67.70,-0.180
171.66,67.65,-0.180
171.67,67.60,-0.180
171.68,67.55,-0.180
171.69,67.50,-0.180
171.70,67.45,-0.180
171.71,67.40,-0.180
171.72,67.35,-0.180
171.73,67.30,-0.180
171.74,67.25,-0.180
171.75,67.20,-0.180
171.76,67.15,-0.180
171.77,67.10,-0.180
171.78,67.05,-0.180
171.79,67.00,-0.180
171.80,66.95,-0.180
171.81,66.90,-0.180
171.82,66.85,-0.180
171.83,66.80,-0.180
171.84,66.75,-0.180
171.85,66.70,-0.180
171.86,66.65,-0.180
171.87,66.60,-0.180
171.88,66.55,-0.180
171.89,66.50,-0.180
171.90,66.45,-0.180
171.91,66.40,-0.180
171.92,66.35,-0.180
171.93,66.30,-0.180
171.94,66.25,-0.180
171.95,66.20,-0.180
171.96,66.15,-0.180
171.97,66.10,-0.180
171.98,66.05,-0.180
171.99,66.00,-0.180
172.00,65.95,-0.180
172.01,65.90,-0.180
172.02,65.85,-0.180
172.03,65.80,-0.179
172.04,65.75,-0.179
172.05,65.70,-0.180
172.06,65.65,-0.180
172.07,65.60,-0.180
172.08,65.55,-0.180
172.09,65.50,-0.179
172.10,65.45,-0.179
172.11,65.40,-0.179
172.12,65.35,-0.179
172.13,65.30,-0.179
172.14,65.25,-0.179
172.15,65.20,-0.179
172.16,65.15,-0.179
172.17,65.10,-0.179
172.18,65.05,-0.179
172.19,65.00,-0.179
172.20,64.95,-0.179
172.21,64.90,-0.179
172.22,64.85,-0.179
172.23,64.80,-0.179
172.24,64.75,-0.179
172.25,64.70,-0.179
172.26,64.65,-0.179
172.27,64.60,-0.179
172.28,64.55,-0.179
172.29,64.50,-0.179
172.30,64.45,-0.179
172.31,64.40,-0.179
172.32,64.35,-0.179
172.33,64.30,-0.179
172.34,64.25,-0.179
172.35,64.20,-0.179
172.36,64.15,-0.179
172.37,64.10,-0.179
172.38,64.05,-0.179
172.39,64.00,-0.179
172.40,63.95,-0.179
172.41,63.90,-0.179
172.42,63.85,-0.179
172.43,63.80,-0.179
172.44,63.75,-0.179
172.45,63.70,-0.179
172.46,63.65,-0.179
172.47,63.60,-0.179
172.48,63.55,-0.179
172.49,63.50,-0.179
172.50,63.45,-0.179
172.51,63.40,-0.179
172.52,63.35,-0.179
172.53,63.30,-0.179
172.54,63.25,-0.179
172.55,63.20,-0.179
172.56,63.15,-0.179
172.57,63.10,-0.179
172.58,63.05,-0.179
172.59,63.00,-0.179
172.60,62.95,-0.179
172.61,62.90,-0.179
172.62,62.85,-0.179
172.63,62.80,-0.179
172.64,62.75,-0.179
172.65,62.70,-0.179
172.66,62.65,-0.179
172.67,62.60,-0.178
172.68,62.55,-0.178
172.69,62.50,-0.178
172.70,62.45,-0.178
172.71,62.40,-0.178
172.72,62.35,-0.178
172.73,62.30,-0.178
172.74,62.25,-0.178
172.75,62.20,-0.178
172.76,62.15,-0.178
172.77,62.10,-0.178
172.78,62.05,-0.178
172.79,62.00,-0.178
172.80,61.95,-0.178
172.81,61.90,-0.178
172.82,61.85,-0.178
172.83,61.80,-0.178
172.84,61.75,-0.178
172.85,61.70,-0.178
172.86,61.65,-0.178
172.87,61.61,-0.178
172.88,61.55,-0.178
172.89,61.51,-0.178
172.90,61.45,-0.178
172.91,61.40,-0.178
172.92,61.35,-0.178
172.93,61.30,-0.178
172.94,61.25,-0.178
172.95,61.20,-0.178
172.96,61.15,-0.178
172.97,61.10,-0.178
172.98,61.06,-0.178
172.99,61.00,-0.178
173.00,60.96,-0.178
173.01,60.90,-0.178
173.02,60.86,-0.178
173.03,60.81,-0.178
173.04,60.75,-0.178
173.05,60.70,-0.178
173.06,60.65,-0.178
173.07,60.60,-0.178
173.08,60.55,-0.178
173.09,60.51,-0.178
173.10,60.45,-0.178
173.11,60.40,-0.178
173.12,60.35,-0.178
173.13,60.30,-0.178
173.14,60.25,-0.177
173.15,60.20,-0.177
173.16,60.16,-0.177
173.17,60.10,-0.177
173.18,60.05,-0.177
173.19,60.01,-0.177
173.20,59.95,-0.177
173.21,59.91,-0.177
173.22,59.86,-0.177
173.23,59.80,-0.177
173.24,59.76,-0.177
173.25,59.70,-0.177
173.26,59.65,-0.177
173.27,59.60,-0.177
173.28,59.56,-0.177
173.29,59.51,-0.177
173.30,59.46,-0.177
173.31,59.41,-0.177
173.32,59.36,-0.177
173.33,59.31,-0.177
173.34,59.26,-0.177
173.35,59.21,-0.177
173.36,59.15,-0.177
173.37,59.10,-0.177
173.38,59.06,-0.177
173.39,59.01,-0.177
173.40,58.96,-0.177
173.41,58.90,-0.177
173.42,58.85,-0.177
173.43,58.81,-0.177
173.44,58.76,-0.177
173.45,58.71,-0.177
173.46,58.66,-0.177
173.47,58.61,-0.177
173.48,58.55,-0.177
173.49,58.51,-0.177
173.50,58.45,-0.177
173.51,58.41,-0.177
173.52,58.36,-0.177
173.53,58.30,-0.177
173.54,58.25,-0.177
173.55,58.21,-0.177
173.56,58.15,-0.177
173.57,58.11,-0.177
173.58,58.05,-0.177
173.59,58.00,-0.177
173.60,57.96,-0.177
173.61,57.90,-0.177
173.62,57.86,-0.177
173.63,57.81,-0.177
173.64,57.76,-0.177
173.65,57.70,-0.177
173.66,57.65,-0.177
173.67,57.61,-0.176
173.68,57.55,-0.176
173.69,57.51,-0.176
173.70,57.46,-0.176
173.71,57.41,-0.176
173.72,57.36,-0.176
173.73,57.31,-0.176
173.74,57.26,-0.176
173.75,57.21,-0.176
173.76,57.16,-0.176
173.77,57.11,-0.176
173.78,57.06,-0.176
173.79,57.01,-0.176
173.80,56.96,-0.176
173.81,56.91,-0.176
173.82,56.86,-0.176
173.83,56.81,-0.176
173.84,56.76,-0.176
173.85,56.71,-0.176
173.86,56.66,-0.176
173.87,56.61,-0.176
173.88,56.56,-0.176
173.89,56.51,-0.176
173.90,56.46,-0.176
173.91,56.41,-0.176
173.92,56.36,-0.176
173.93,56.31,-0.176
173.94,56.26,-0.176
173.95,56.21,-0.176
173.96,56.16,-0.176
173.97,56.11,-0.176
173.98,56.06,-0.176
173.99,56.01,-0.176
174.00,55.96,-0.176
174.01,55.91,-0.176
174.02,55.86,-0.176
174.03,55.80,-0.176
174.04,55.76,-0.176
174.05,55.70,-0.176
174.06,55.65,-0.176
174.07,55.61,-0.176
174.08,55.56,-0.176
174.09,55.51,-0.176
174.10,55.46,-0.176
174.11,55.41,-0.175
174.12,55.36,-0.175
174.13,55.30,-0.175
174.14,55.26,-0.175
174.15,55.21,-0.175
174.16,55.16,-0.175
174.17,55.11,-0.175
174.18,55.06,-0.175
174.19,55.01,-0.175
174.20,54.96,-0.175
174.21,54.91,-0.175
174.22,54.86,-0.175
174.23,54.81,-0.175
174.24,54.76,-0.175
174.25,54.71,-0.175
174.26,54.66,-0.175
174.27,54.61,-0.175
174.28,54.56,-0.175
174.29,54.51,-0.175
174.30,54.46,-0.175
174.31,54.41,-0.175
174.32,54.36,-0.175
174.33,54.31,-0.175
174.34,54.26,-0.175
174.35,54.21,-0.175
174.36,54.16,-0.175
174.37,54.11,-0.175
174.38,54.06,-0.175
174.39,54.01,-0.175
174.40,53.96,-0.175
174.41,53.91,-0.175
174.42,53.86,-0.175
174.43,53.81,-0.175
174.44,53.76,-0.175
174.45,53.71,-0.175
174.46,53.66,-0.175
174.47,53.61,-0.175
174.48,53.56,-0.175
174.49,53.51,-0.175
174.50,53.46,-0.175
174.51,53.41,-0.175
174.52,53.36,-0.175
174.53,53.31,-0.175
174.54,53.26,-0.175
174.55,53.21,-0.175
174.56,53.16,-0.175
174.57,53.11,-0.175
174.58,53.06,-0.175
174.59,53.01,-0.175
174.60,52.96,-0.175
174.61,52.91,-0.175
174.62,52.86,-0.175
174.63,52.81,-0.175
174.64,52.76,-0.175
174.65,52.71,-0.175
174.66,52.66,-0.175
174.67,52.61,-0.175
174.68,52.56,-0.175
174.69,52.51,-0.174
174.70,52.46,-0.174
174.71,52.41,-0.174
174.72,52.36,-0.174
174.73,52.31,-0.174
174.74,52.26,-0.174
174.75,52.21,-0.174
174.76,52.16,-0.174
174.77,52.11,-0.174
174.78,52.06,-0.174
174.79,52.01,-0.174
174.80,51.96,-0.174
174.81,51.91,-0.174
174.82,51.86,-0.174
174.83,51.81,-0.174
174.84,51.76,-0.174
174.85,51.71,-0.174
174.86,51.66,-0.174
174.87,51.61,-0.174
174.88,51.56,-0.174
174.89,51.51,-0.174
174.90,51.46,-0.174
174.91,51.41,-0.174
174.92,51.36,-0.174
174.93,51.31,-0.174
174.94,51.26,-0.174
174.95,51.21,-0.174
174.96,51.16,-0.174
174.97,51.11,-0.174
174.98,51.06,-0.174
174.99,51.01,-0.174
175.00,50.96,-0.174
175.01,50.91,-0.174
175.02,50.86,-0.174
175.03,50.81,-0.174
175.04,50.76,-0.174
175.05,50.71,-0.174
175.06,50.66,-0.174
175.07,50.61,-0.174
175.08,50.56,-0.174
175.09,50.51,-0.174
175.10,50.46,-0.174
175.11,50.41,-0.174
175.12,50.36,-0.174
175.13,50.31,-0.173
175.14,50.26,-0.173
175.15,50.21,-0.173
175.16,50.16,-0.173
175.17,50.11,-0.173
175.18,50.06,-0.173
175.19,50.01,-0.173
175.20,49.96,-0.173
175.21,49.91,-0.173
175.22,49.86,-0.173
175.23,49.81,-0.173
175.24,49.76,-0.173
175.25,49.71,-0.173
175.26,49.66,-0.173
175.27,49.61,-0.173
175.28,49.56,-0.173
175.29,49.51,-0.173
175.30,49.46,-0.173
175.31,49.41,-0.173
175.32,49.36,-0.173
175.33,49.31,-0.173
175.34,49.26,-0.173
175.35,49.21,-0.173
175.36,49.16,-0.173
175.37,49.11,-0.173
175.38,49.06,-0.173
175.39,49.01,-0.173
175.40,48.96,-0.173
175.41,48.91,-0.173
175.42,48.86,-0.173
175.43,48.81,-0.173
175.44,48.76,-0.173
175.45,48.71,-0.173
175.46,48.66,-0.173
175.47,48.61,-0.173
175.48,48.56,-0.173
175.49,48.51,-0.173
175.50,48.46,-0.173
175.51,48.41,-0.173
175.52,48.36,-0.173
175.53,48.31,-0.173
175.54,48.26,-0.173
175.55,48.21,-0.173
175.56,48.16,-0.173
175.57,48.11,-0.173
175.58,48.06,-0.173
175.59,48.01,-0.173
175.60,47.96,-0.173
175.61,47.91,-0.172
175.62,47.86,-0.173
175.63,47.81,-0.172
175.64,47.76,-0.172
175.65,47.71,-0.172
175.66,47.66,-0.172
175.67,47.61,-0.172
175.68,47.56,-0.172
175.69,47.51,-0.172
175.70,47.46,-0.172
175.71,47.41,-0.172
175.72,47.36,-0.172
175.73,47.31,-0.172
175.74,47.26,-0.172
175.75,47.21,-0.172
175.76,47.16,-0.172
175.77,47.11,-0.172
175.78,47.06,-0.172
175.79,47.01,-0.172
175.80,46.96,-0.172
175.81,46.91,-0.172
175.82,46.86,-0.172
175.83,46.81,-0.172
175.84,46.76,-0.172
175.85,46.71,-0.172
175.86,46.66,-0.172
175.87,46.61,-0.172
175.88,46.56,-0.172
175.89,46.51,-0.172
175.90,46.46,-0.172
175.91,46.41,-0.172
175.92,46.36,-0.172
175.93,46.31,-0.172
175.94,46.26,-0.172
175.95,46.21,-0.172
175.96,46.16,-0.172
175.97,46.11,-0.172
175.98,46.06,-0.172
175.99,46.01,-0.172
176.00,45.96,-0.172
176.01,45.91,-0.172
176.02,45.86,-0.172
176.03,45.81,-0.172
176.04,45.76,-0.172
176.05,45.71,-0.172
176.06,45.66,-0.172
176.07,45.61,-0.172
176.08,45.56,-0.171
176.09,45.51,-0.171
176.10,45.46,-0.171
176.11,45.41,-0.171
176.12,45.36,-0.171
176.13,45.31,-0.171
176.14,45.26,-0.171
176.15,45.21,-0.171
176.16,45.16,-0.171
176.17,45.11,-0.171
176.18,45.06,-0.171
176.19,45.01,-0.171
176.20,44.96,-0.171
176.21,44.91,-0.171
176.22,44.86,-0.171
176.23,44.81,-0.171
176.24,44.76,-0.171
176.25,44.71,-0.171
176.26,44.66,-0.171
176.27,44.61,-0.171
176.28,44.56,-0.171
176.29,44.51,-0.171
176.30,44.46,-0.171
176.31,44.41,-0.171
176.32,44.36,-0.171
176.33,44.31,-0.171
176.34,44.26,-0.171
176.35,44.21,-0.171
176.36,44.16,-0.171
176.37,44.11,-0.171
176.38,44.06,-0.171
176.39,44.01,-0.171
176.40,43.96,-0.171
176.41,43.91,-0.171
176.42,43.86,-0.171
176.43,43.81,-0.171
176.44,43.76,-0.171
176.45,43.71,-0.171
176.46,43.66,-0.171
176.47,43.61,-0.171
176.48,43.56,-0.171
176.49,43.51,-0.170
176.50,43.46,-0.170
176.51,43.41,-0.170
176.52,43.36,-0.170
176.53,43.31,-0.170
176.54,43.26,-0.170
176.55,43.21,-0.170
176.56,43.16,-0.170
176.57,43.11,-0.170
176.58,43.06,-0.170
176.59,43.01,-0.170
176.60,42.96,-0.170
176.61,42.91,-0.170
176.62,42.86,-0.170
176.63,42.81,-0.170
176.64,42.76,-0.170
176.65,42.71,-0.170
176.66,42.66,-0.170
176.67,42.61,-0.170
176.68,42.56,-0.170
176.69,42.51,-0.170
176.70,42.46,-0.170
176.71,42.41,-0.170
176.72,42.36,-0.170
176.73,42.31,-0.170
176.74,42.26,-0.170
176.75,42.21,-0.170
176.76,42.16,-0.170
176.77,42.11,-0.170
176.78,42.06,-0.170
176.79,42.01,-0.170
176.80,41.96,-0.170
176.81,41.91,-0.170
176.82,41.86,-0.170
176.83,41.81,-0.170
176.84,41.76,-0.170
176.85,41.71,-0.170
176.86,41.66,-0.170
176.87,41.61,-0.170
176.88,41.56,-0.170
176.89,41.51,-0.170
176.90,41.46,-0.170
176.91,41.41,-0.170
176.92,41.36,-0.170
176.93,41.31,-0.170
176.94,41.26,-0.170
176.95,41.21,-0.170
176.96,41.16,-0.170
176.97,41.11,-0.170
176.98,41.07,-0.170
176.99,41.01,-0.169
177.00,40.96,-0.169
177.01,40.91,-0.169
177.02,40.86,-0.169
177.03,40.81,-0.169
177.04,40.76,-0.169
177.05,40.71,-0.169
177.06,40.66,-0.169
177.07,40.61,-0.169
177.08,40.56,-0.169
177.09,40.51,-0.169
177.10,40.46,-0.169
177.11,40.41,-0.169
177.12,40.37,-0.169
177.13,40.31,-0.169
177.14,40.26,-0.169
177.15,40.21,-0.169
177.16,40.16,-0.169
177.17,40.11,-0.169
177.18,40.06,-0.169
177.19,40.01,-0.169
177.20,39.96,-0.169
177.21,39.91,-0.169
177.22,39.86,-0.169
177.23,39.81,-0.169
177.24,39.76,-0.169
177.25,39.72,-0.169
177.26,39.66,-0.169
177.27,39.61,-0.169
177.28,39.56,-0.169
177.29,39.51,-0.169
177.30,39.46,-0.169
177.31,39.41,-0.169
177.32,39.36,-0.169
177.33,39.31,-0.169
177.34,39.26,-0.169
177.35,39.21,-0.169
177.36,39.16,-0.169
177.37,39.11,-0.169
177.38,39.06,-0.169
177.39,39.01,-0.169
177.40,38.96,-0.169
177.41,38.91,-0.169
177.42,38.86,-0.169
177.43,38.81,-0.169
177.44,38.76,-0.169
177.45,38.71,-0.169
177.46,38.66,-0.169
177.47,38.61,-0.169
177.48,38.56,-0.169
177.49,38.51,-0.169
177.50,38.46,-0.168
177.51,38.41,-0.168
177.52,38.37,-0.168
177.53,38.31,-0.168
177.54,38.27,-0.168
177.55,38.21,-0.168
177.56,38.16,-0.168
177.57,38.12,-0.168
177.58,38.07,-0.168
177.59,38.01,-0.168
177.60,37.96,-0.168
177.61,37.92,-0.168
177.62,37.87,-0.168
177.63,37.82,-0.168
177.64,37.76,-0.168
177.65,37.71,-0.168
177.66,37.67,-0.168
177.67,37.62,-0.168
177.68,37.56,-0.168
177.69,37.52,-0.168
177.70,37.47,-0.168
177.71,37.42,-0.168
177.72,37.37,-0.168
177.73,37.31,-0.168
177.74,37.26,-0.168
177.75,37.22,-0.168
177.76,37.17,-0.168
177.77,37.11,-0.168
177.78,37.07,-0.168
177.79,37.02,-0.168
177.80,36.96,-0.168
177.81,36.91,-0.168
177.82,36.87,-0.168
177.83,36.81,-0.168
177.84,36.77,-0.168
177.85,36.72,-0.168
177.86,36.66,-0.168
177.87,36.62,-0.168
177.88,36.57,-0.168
177.89,36.52,-0.168
177.90,36.47,-0.168
177.91,36.42,-0.167
177.92,36.37,-0.168
177.93,36.32,-0.167
177.94,36.27,-0.167
177.95,36.22,-0.167
177.96,36.17,-0.167
177.97,36.12,-0.167
177.98,36.07,-0.167
177.99,36.02,-0.167
178.00,35.97,-0.167
178.01,35.92,-0.167
178.02,35.87,-0.167
178.03,35.82,-0.167
178.04,35.77,-0.167
178.05,35.72,-0.167
178.06,35.66,-0.167
178.07,35.62,-0.167
178.08,35.57,-0.167
178.09,35.52,-0.167
178.10,35.47,-0.167
178.11,35.42,-0.167
178.12,35.37,-0.167
178.13,35.32,-0.167
178.14,35.27,-0.167
178.15,35.22,-0.167
178.16,35.17,-0.167
178.17,35.12,-0.167
178.18,35.07,-0.167
178.19,35.02,-0.167
178.20,34.97,-0.167
178.21,34.92,-0.167
178.22,34.87,-0.167
178.23,34.82,-0.167
178.24,34.77,-0.167
178.25,34.72,-0.167
178.26,34.67,-0.167
178.27,34.62,-0.167
178.28,34.57,-0.167
178.29,34.52,-0.167
178.30,34.47,-0.167
178.31,34.42,-0.167
178.32,34.37,-0.167
178.33,34.32,-0.167
178.34,34.27,-0.167
178.35,34.22,-0.167
178.36,34.17,-0.167
178.37,34.12,-0.167
178.38,34.07,-0.166
178.39,34.02,-0.166
178.40,33.97,-0.166
178.41,33.92,-0.166
178.42,33.87,-0.166
178.43,33.82,-0.166
178.44,33.77,-0.166
178.45,33.72,-0.166
178.46,33.67,-0.166
178.47,33.62,-0.166
178.48,33.57,-0.166
178.49,33.52,-0.166
178.50,33.47,-0.166
178.51,33.42,-0.166
178.52,33.37,-0.166
178.53,33.32,-0.166
178.54,33.27,-0.166
178.55,33.22,-0.166
178.56,33.17,-0.166
178.57,33.12,-0.166
178.58,33.07,-0.166
178.59,33.02,-0.166
178.60,32.97,-0.166
178.61,32.92,-0.166
178.62,32.87,-0.166
178.63,32.82,-0.166
178.64,32.77,-0.166
178.65,32.72,-0.166
178.66,32.67,-0.166
178.67,32.62,-0.166
178.68,32.57,-0.166
178.69,32.52,-0.166
178.70,32.47,-0.166
178.71,32.42,-0.166
178.72,32.37,-0.166
178.73,32.32,-0.166
178.74,32.27,-0.166
178.75,32.22,-0.166
178.76,32.17,-0.166
178.77,32.12,-0.166
178.78,32.07,-0.166
178.79,32.02,-0.165
178.80,31.97,-0.165
178.81,31.92,-0.165
178.82,31.87,-0.165
178.83,31.82,-0.165
178.84,31.77,-0.165
178.85,31.72,-0.165
178.86,31.67,-0.165
178.87,31.62,-0.165
178.88,31.57,-0.165
178.89,31.52,-0.165
178.90,31.47,-0.165
178.91,31.42,-0.165
178.92,31.37,-0.165
178.93,31.32,-0.165
178.94,31.27,
178.95,31.22,
178.96,31.17,
178.97,31.12,
178.98,31.07,
178.98,,