File: DSC/2025_05_20_CBD_Sorbic_Acid_MC_n60C_150C_5Cmin_x3.csv
Filename,2025_05_20_CBD_Sorbic_Acid_MC_n60C_150C_5Cmin_x3
Instrument name,DSC2A-00468 (192.168.1.100)
Operator,Yarger
rundate,5/21/2025
Sample name,2025_05_20_CBD_Sorbic_Acid_MC_n60C_150C_5Cmin_x3
proceduresegments,Data Off ; Equilibrate -60.00 °C; Data On ; Ramp 5.00 °C/min to 150.00 °C; Data Off ; Isothermal 1.0 min; Data On ; Ramp 5.00 °C/min to -60.00 °C; Data Off ; Isothermal 1.0 min; Data On ; Ramp 5.00 °C/min to 150.00 °C; Data Off ; Isothermal 1.0 min; Data On ; Ramp 5.00 °C/min to -60.00 °C; Data Off ; Isothermal 1.0 min; Data On ; Ramp 5.00 °C/min to 30.00 °C
[File Parameters]
Run date,5/21/2025 4:51:14 AM
Trios version,5.1.1.46572
Original File Name,
Current File Name,D:\DSC2500\JYarger\2025_05_20_CBD_Sorbic_Acid_MC_n60C_150C_5Cmin_x3.tri
[Procedure]
Procedure Name,CBD_SA_n60C_150C_5Cmin_x3
Sample Name,2025_05_20_CBD_Sorbic_Acid_MC_n60C_150C_5Cmin_x3
Sample Mass,5.33 mg
Reference Sample Mass,0 mg
Pan Mass,56.99 mg
Pan Number,45
Reference Pan Mass,57.13 mg
Reference Pan Number,37
Pan Type,Tzero Aluminum Hermetic
Comments,Al Hermetic DSC Consumables sealed Pan/Lid. Y2 Tray (Google Sheet: DSC_Samples_Vext_Y2_Tray_May2025)
Project Name,CA
Operator,Yarger
Test,Custom
Unload Max Temperature,30
Unload Min Temperature,30
Load Max Temperature,30
Load Min Temperature,30
Stop on Gas Flow Error,Yes
[Signal List]
Signal #1,Time (min)
Signal #2,Temperature (°C)
Signal #3,Heat Flow (mW)
Signal #4,Delta T (µV)
Signal #5,Delta Tzero (µV)
Signal #6,Tzero Temperature (°C)
Signal #7,Cell Purge (mL/min)
Signal #8,Heater Temp (°C)
Signal #9,Power Delivered (W)
Signal #10,Reference Junction Temperature (°C)
Signal #11,Flange Temperature (°C)
Signal #12,Heat Flow Phase (rad)
Signal #13,Total Heat Capacity (J/°C)
Signal #14,Heat Capacity (J/°C)
[Configuration]
Company Name,ASU
Instrument Name,DSC2A-00468
Instrument Type,DSC2500
Serial Number,DSC2A-00468
IP,192.168.1.100
Location of Instrument,MRRC
DisplayType,Unknown
Sample Interval ,0.1 s/pt
Selected Heat Flow,T4P
Exotherm Direction,Down
Cell Serial,DRC2-00792
Lid Type,Standard
Cooler,RCS 90
Leave Cooler on at End of Sequence,On
Gas 2,Nitrogen
Gas Selected,Channel 1
Flow Rate,50 mL/min
Secondary Purge,On
Licensed Heat Flow,Heat Flow T4P
Modulation Licensed,Yes
[Versions]
Common IDD Version,1
Cortex Version,VER 2.10.2.31
Driver,5.0.0.6
GDM Version,1.0.3.3
TouchscreenVersion,1.0.0.16145
FEP Version,1.2.1.21
FEP Bootloader,2.0.0.5
AutoSampler Version,2.1.1.26
Auto Sampler Bootloader,2.0.0.5
FCM Version,1.1.0.3
FCM Bootloader,2.0.0.5
[Experiment Logs]
Experiment Log Entry # 1,Data On set to 0
Experiment Log Entry # 3,Equilibrate Segment -60 (C) Started
Experiment Log Entry # 5,Air Cool is off.
Experiment Log Entry # 7,Data On set to 1
Experiment Log Entry # 9,Ramp Segment 5 C/min to 150 Started
Experiment Log Entry # 11,Data On set to 0
Experiment Log Entry # 13,Isothermal Segment 1 min started
Experiment Log Entry # 15,Data On set to 1
Experiment Log Entry # 17,Ramp Segment 5 C/min to -60 Started
Experiment Log Entry # 19,Data On set to 0
Experiment Log Entry # 21,Isothermal Segment 1 min started
Experiment Log Entry # 23,Data On set to 1
Experiment Log Entry # 25,Ramp Segment 5 C/min to 150 Started
Experiment Log Entry # 27,Data On set to 0
Experiment Log Entry # 29,Isothermal Segment 1 min started
Experiment Log Entry # 31,Data On set to 1
Experiment Log Entry # 33,Ramp Segment 5 C/min to -60 Started
Experiment Log Entry # 35,Data On set to 0
Experiment Log Entry # 37,Isothermal Segment 1 min started
Experiment Log Entry # 39,Data On set to 1
Experiment Log Entry # 41,Ramp Segment 5 C/min to 30 Started
[Method Log]
Method Log Entry # 1,Data Off
Method Log Entry # 2,Equilibrate -60 °C
Method Log Entry # 3,Data On
Method Log Entry # 4,(Ramp 173265) Ramp 5 °C/minute to 150 °C
Method Log Entry # 5,Data Off
Method Log Entry # 6,Isothermal 1 minutes
Method Log Entry # 7,Data On
Method Log Entry # 8,(Ramp 173269) Ramp 5 °C/minute to -60 °C
Method Log Entry # 9,Data Off
Method Log Entry # 10,Isothermal 1 minutes
Method Log Entry # 11,Data On
Method Log Entry # 12,(Ramp 173273) Ramp 5 °C/minute to 150 °C
Method Log Entry # 13,Data Off
Method Log Entry # 14,Isothermal 1 minutes
Method Log Entry # 15,Data On
Method Log Entry # 16,(Ramp 173277) Ramp 5 °C/minute to -60 °C
Method Log Entry # 17,Data Off
Method Log Entry # 18,Isothermal 1 minutes
Method Log Entry # 19,Data On
Method Log Entry # 20,(Ramp 173281) Ramp 5 °C/minute to 30 °C
Cell Serial,DRC2-00792
[T1 Calibration]
Slope,-0.008529666
Offset,9.636258
Initial Temperature,98.23
GUID,f8bfdadc-4977-4fdf-ba6d-0ba9134940c3
[TZero Calibration]
Date Applied,11/29/2022 4:06:13 PM
Description,From -89.059 °C to 396.009 °C at 20.000°C/min
Gas Type,Nitrogen
Pan Type,None
Source Files 1,C:\Users\yargerlab\Desktop\DSC Data\General\TZero_calibration_11_29_22_2nd(2).tri
Source Files 2,C:\Users\yargerlab\Desktop\DSC Data\General\TZero_calibration_11_29_22_2nd(3).tri
Delta T Offset,13.05235
Delta T Slope,-0.007271007
Delta T0 Offset,-13.69128
Delta T0 Slope,0.06063341
[Temperature Calibration]
Date Applied,11/29/2022 7:12:28 PM
Description,From 106.590 °C to 186.590 °C at 10.000°C/min
Gas Type,Nitrogen
Pan Type,Tzero Aluminum Hermetic
Source Files 1,C:\Users\yargerlab\Desktop\DSC Data\General\Indium(6).tri
Measured 1,157.391
Known 1,156.598
[Cell Constant Calibration]
Date Applied,11/29/2022 7:12:29 PM
Description,From 106.590 °C to 186.590 °C at 10.000°C/min
Gas Type,Nitrogen
Pan Type,Tzero Aluminum Hermetic
Source Files 1,C:\Users\yargerlab\Desktop\DSC Data\General\Indium(6).tri
T4P KCell,1.006051
Onset Slope,63.26126 mW/°C
[Direct Cp Calibration]
Date Applied,11/30/2022 11:04:51 AM
Description,From -79.983 °C to 298.409 °C at 10.000°C/min
Gas Type,Nitrogen
Pan Type,Tzero Aluminum Hermetic
Source Files 1,C:\Users\yargerlab\Desktop\DSC Data\General\Sapphire_Heat_Capacity_11_30_22.tri
[Rev Cp Calibration]
Date Applied,11/30/2022 1:58:51 PM
Description,From -79.996 °C to 292.812 °C at 3.000°C/min
Gas Type,Nitrogen
Pan Type,Tzero Aluminum Hermetic
Source Files 1,C:\Users\yargerlab\Desktop\DSC Data\General\Sapphire_MDSC_Calibration_11_30_22.tri
[step]
Ramp 5.00 °C/min to 150.00 °C
Time,Temperature,Heat Flow (Normalized)
min,°C,W/g
0.00,-59.68,-0.056
0.03,-59.70,-0.056
0.06,-59.71,-0.044
0.08,-59.69,-0.029
0.11,-59.63,-0.013
0.14,-59.56,0.003
0.17,-59.47,0.020
0.20,-59.37,0.032
0.23,-59.26,0.045
0.26,-59.15,0.055
0.28,-59.03,0.064
0.31,-58.91,0.071
0.34,-58.79,0.078
0.37,-58.66,0.083
0.40,-58.53,0.087
0.43,-58.40,0.091
0.45,-58.27,0.093
0.48,-58.14,0.096
0.51,-58.00,0.097
0.54,-57.87,0.098
0.57,-57.73,0.099
0.60,-57.59,0.100
0.62,-57.46,0.101
0.65,-57.32,0.102
0.68,-57.18,0.103
0.71,-57.05,0.103
0.74,-56.91,0.104
0.77,-56.77,0.104
0.79,-56.63,0.105
0.82,-56.49,0.105
0.85,-56.35,0.106
0.88,-56.21,0.106
0.91,-56.07,0.106
0.93,-55.93,0.107
0.96,-55.79,0.107
0.99,-55.65,0.107
1.02,-55.51,0.108
1.05,-55.38,0.108
1.08,-55.23,0.108
1.11,-55.09,0.108
1.13,-54.95,0.108
1.16,-54.81,0.109
1.19,-54.67,0.109
1.22,-54.53,0.109
1.25,-54.39,0.109
1.28,-54.25,0.109
1.30,-54.11,0.109
1.33,-53.97,0.109
1.36,-53.83,0.109
1.39,-53.69,0.109
1.42,-53.55,0.109
1.44,-53.40,0.109
1.47,-53.26,0.109
1.50,-53.12,0.109
1.53,-52.98,0.109
1.56,-52.84,0.110
1.59,-52.70,0.110
1.62,-52.56,0.110
1.64,-52.42,0.110
1.67,-52.28,0.110
1.70,-52.13,0.110
1.73,-51.99,0.110
1.76,-51.85,0.110
1.78,-51.71,0.110
1.81,-51.57,0.110
1.84,-51.43,0.110
1.87,-51.29,0.110
1.90,-51.14,0.110
1.93,-51.00,0.110
1.96,-50.86,0.110
1.98,-50.72,0.110
2.01,-50.58,0.110
2.04,-50.44,0.110
2.07,-50.30,0.110
2.10,-50.16,0.110
2.13,-50.01,0.110
2.15,-49.87,0.110
2.18,-49.73,0.110
2.21,-49.59,0.110
2.24,-49.45,0.110
2.27,-49.30,0.110
2.29,-49.16,0.109
2.32,-49.02,0.109
2.35,-48.88,0.109
2.38,-48.74,0.109
2.41,-48.60,0.109
2.44,-48.46,0.109
2.46,-48.31,0.109
2.49,-48.17,0.109
2.52,-48.03,0.109
2.55,-47.89,0.109
2.58,-47.75,0.109
2.61,-47.61,0.109
2.64,-47.47,0.109
2.66,-47.32,0.109
2.69,-47.18,0.109
2.72,-47.04,0.109
2.75,-46.90,0.109
2.78,-46.76,0.109
2.81,-46.62,0.109
2.83,-46.48,0.109
2.86,-46.34,0.109
2.89,-46.19,0.109
2.92,-46.05,0.109
2.95,-45.91,0.109
2.98,-45.77,0.109
3.00,-45.63,0.109
3.03,-45.48,0.109
3.06,-45.34,0.109
3.09,-45.20,0.109
3.12,-45.06,0.109
3.14,-44.92,0.109
3.17,-44.78,0.109
3.20,-44.63,0.109
3.23,-44.49,0.110
3.26,-44.35,0.109
3.29,-44.21,0.110
3.31,-44.07,0.110
3.34,-43.93,0.109
3.37,-43.78,0.110
3.40,-43.64,0.110
3.43,-43.50,0.110
3.46,-43.36,0.110
3.49,-43.22,0.110
3.51,-43.07,0.110
3.54,-42.94,0.110
3.57,-42.79,0.110
3.60,-42.65,0.110
3.63,-42.51,0.110
3.66,-42.37,0.110
3.68,-42.23,0.110
3.71,-42.09,0.110
3.74,-41.94,0.110
3.77,-41.80,0.110
3.80,-41.66,0.110
3.83,-41.52,0.110
3.85,-41.37,0.110
3.88,-41.23,0.110
3.91,-41.09,0.110
3.94,-40.95,0.110
3.97,-40.81,0.110
3.99,-40.66,0.110
4.02,-40.52,0.110
4.05,-40.38,0.110
4.08,-40.24,0.110
4.11,-40.10,0.110
4.14,-39.95,0.110
4.16,-39.81,0.110
4.19,-39.67,0.110
4.22,-39.53,0.110
4.25,-39.39,0.110
4.28,-39.24,0.110
4.31,-39.10,0.110
4.34,-38.96,0.110
4.36,-38.82,0.110
4.39,-38.68,0.110
4.42,-38.54,0.110
4.45,-38.39,0.110
4.48,-38.25,0.110
4.50,-38.11,0.110
4.53,-37.97,0.110
4.56,-37.83,0.110
4.59,-37.68,0.110
4.62,-37.54,0.110
4.65,-37.40,0.110
4.68,-37.26,0.110
4.70,-37.12,0.110
4.73,-36.98,0.110
4.76,-36.83,0.110
4.79,-36.69,0.110
4.82,-36.55,0.110
4.85,-36.41,0.110
4.87,-36.27,0.110
4.90,-36.13,0.110
4.93,-35.98,0.110
4.96,-35.84,0.110
4.99,-35.70,0.110
5.01,-35.56,0.110
5.04,-35.42,0.110
5.07,-35.27,0.110
5.10,-35.13,0.110
5.13,-34.99,0.110
5.16,-34.85,0.110
5.19,-34.71,0.110
5.21,-34.57,0.110
5.24,-34.42,0.110
5.27,-34.28,0.110
5.30,-34.14,0.110
5.33,-34.00,0.111
5.35,-33.85,0.111
5.38,-33.71,0.111
5.41,-33.57,0.111
5.44,-33.43,0.111
5.47,-33.29,0.111
5.50,-33.15,0.111
5.53,-33.00,0.111
5.55,-32.86,0.111
5.58,-32.72,0.111
5.61,-32.58,0.111
5.64,-32.44,0.111
5.67,-32.29,0.111
5.70,-32.15,0.111
5.72,-32.01,0.111
5.75,-31.87,0.111
5.78,-31.73,0.111
5.81,-31.58,0.111
5.84,-31.44,0.111
5.86,-31.30,0.111
5.89,-31.16,0.111
5.92,-31.02,0.111
5.95,-30.88,0.111
5.98,-30.73,0.111
6.01,-30.59,0.111
6.04,-30.45,0.111
6.06,-30.31,0.111
6.09,-30.17,0.111
6.12,-30.02,0.111
6.15,-29.88,0.111
6.18,-29.74,0.111
6.20,-29.60,0.111
6.23,-29.46,0.111
6.26,-29.32,0.111
6.29,-29.18,0.111
6.32,-29.04,0.111
6.35,-28.89,0.111
6.38,-28.75,0.111
6.40,-28.61,0.111
6.43,-28.47,0.111
6.46,-28.32,0.111
6.49,-28.18,0.111
6.52,-28.04,0.111
6.55,-27.90,0.111
6.57,-27.76,0.111
6.60,-27.62,0.111
6.63,-27.47,0.111
6.66,-27.33,0.111
6.69,-27.19,0.111
6.71,-27.05,0.111
6.74,-26.91,0.111
6.77,-26.76,0.111
6.80,-26.62,0.112
6.83,-26.48,0.112
6.86,-26.34,0.111
6.89,-26.20,0.112
6.91,-26.05,0.112
6.94,-25.91,0.112
6.97,-25.77,0.112
7.00,-25.63,0.112
7.03,-25.49,0.112
7.05,-25.35,0.112
7.08,-25.20,0.112
7.11,-25.06,0.112
7.14,-24.92,0.112
7.17,-24.78,0.112
7.20,-24.63,0.112
7.23,-24.49,0.112
7.25,-24.35,0.112
7.28,-24.21,0.112
7.31,-24.07,0.112
7.34,-23.93,0.112
7.37,-23.78,0.112
7.40,-23.64,0.112
7.42,-23.50,0.112
7.45,-23.36,0.112
7.48,-23.22,0.112
7.51,-23.08,0.112
7.54,-22.94,0.112
7.56,-22.79,0.112
7.59,-22.65,0.112
7.62,-22.51,0.112
7.65,-22.37,0.112
7.68,-22.23,0.112
7.71,-22.08,0.112
7.74,-21.94,0.112
7.76,-21.80,0.112
7.79,-21.66,0.112
7.82,-21.52,0.112
7.85,-21.38,0.112
7.88,-21.23,0.112
7.90,-21.09,0.112
7.93,-20.95,0.112
7.96,-20.81,0.112
7.99,-20.67,0.112
8.02,-20.53,0.112
8.05,-20.38,0.112
8.08,-20.24,0.112
8.10,-20.10,0.112
8.13,-19.96,0.112
8.16,-19.82,0.112
8.19,-19.67,0.113
8.22,-19.53,0.113
8.25,-19.39,0.113
8.27,-19.25,0.113
8.30,-19.10,0.113
8.33,-18.96,0.113
8.36,-18.82,0.113
8.39,-18.68,0.113
8.41,-18.54,0.113
8.44,-18.40,0.113
8.47,-18.25,0.113
8.50,-18.11,0.113
8.53,-17.97,0.113
8.56,-17.83,0.113
8.58,-17.69,0.113
8.61,-17.55,0.113
8.64,-17.41,0.113
8.67,-17.26,0.113
8.70,-17.12,0.113
8.73,-16.98,0.113
8.75,-16.84,0.113
8.78,-16.70,0.113
8.81,-16.55,0.113
8.84,-16.41,0.113
8.87,-16.27,0.113
8.90,-16.13,0.113
8.93,-15.99,0.113
8.95,-15.84,0.113
8.98,-15.70,0.113
9.01,-15.56,0.113
9.04,-15.42,0.113
9.07,-15.28,0.113
9.10,-15.14,0.113
9.12,-14.99,0.113
9.15,-14.85,0.113
9.18,-14.71,0.113
9.21,-14.57,0.113
9.24,-14.43,0.113
9.27,-14.29,0.113
9.29,-14.14,0.113
9.32,-14.00,0.113
9.35,-13.86,0.113
9.38,-13.72,0.113
9.41,-13.58,0.113
9.43,-13.43,0.113
9.46,-13.29,0.114
9.49,-13.15,0.114
9.52,-13.01,0.114
9.55,-12.87,0.114
9.58,-12.73,0.114
9.60,-12.58,0.114
9.63,-12.44,0.114
9.66,-12.30,0.114
9.69,-12.16,0.114
9.72,-12.02,0.114
9.75,-11.88,0.114
9.78,-11.73,0.114
9.80,-11.59,0.114
9.83,-11.45,0.114
9.86,-11.31,0.114
9.89,-11.17,0.114
9.92,-11.03,0.114
9.95,-10.88,0.114
9.97,-10.74,0.114
10.00,-10.60,0.114
10.03,-10.46,0.114
10.06,-10.32,0.114
10.09,-10.17,0.114
10.12,-10.03,0.114
10.14,-9.89,0.114
10.17,-9.75,0.114
10.20,-9.61,0.115
10.23,-9.47,0.115
10.26,-9.32,0.115
10.28,-9.18,0.115
10.31,-9.04,0.115
10.34,-8.90,0.115
10.37,-8.76,0.115
10.40,-8.61,0.115
10.43,-8.47,0.115
10.45,-8.33,0.115
10.48,-8.19,0.115
10.51,-8.05,0.115
10.54,-7.90,0.115
10.57,-7.76,0.115
10.60,-7.62,0.115
10.63,-7.48,0.115
10.65,-7.34,0.115
10.68,-7.20,0.115
10.71,-7.06,0.115
10.74,-6.91,0.115
10.77,-6.77,0.115
10.80,-6.63,0.115
10.82,-6.49,0.115
10.85,-6.35,0.115
10.88,-6.20,0.115
10.91,-6.06,0.115
10.94,-5.92,0.115
10.97,-5.78,0.115
10.99,-5.64,0.115
11.02,-5.49,0.115
11.05,-5.35,0.116
11.08,-5.21,0.116
11.11,-5.07,0.116
11.13,-4.93,0.116
11.16,-4.79,0.116
11.19,-4.64,0.116
11.22,-4.50,0.116
11.25,-4.36,0.116
11.28,-4.22,0.116
11.30,-4.08,0.116
11.33,-3.94,0.116
11.36,-3.79,0.116
11.39,-3.65,0.116
11.42,-3.51,0.116
11.45,-3.37,0.116
11.48,-3.23,0.116
11.50,-3.09,0.116
11.53,-2.94,0.116
11.56,-2.80,0.116
11.59,-2.66,0.116
11.62,-2.52,0.116
11.65,-2.38,0.116
11.67,-2.23,0.116
11.70,-2.09,0.116
11.73,-1.95,0.116
11.76,-1.81,0.116
11.79,-1.67,0.116
11.82,-1.52,0.116
11.84,-1.38,0.116
11.87,-1.24,0.117
11.90,-1.10,0.117
11.93,-0.96,0.117
11.96,-0.82,0.117
11.98,-0.67,0.117
12.01,-0.53,0.117
12.04,-0.39,0.117
12.07,-0.25,0.117
12.10,-0.11,0.117
12.13,0.03,0.117
12.15,0.18,0.117
12.18,0.32,0.117
12.21,0.46,0.117
12.24,0.60,0.117
12.27,0.74,0.117
12.30,0.89,0.117
12.33,1.03,0.117
12.35,1.17,0.117
12.38,1.31,0.117
12.41,1.45,0.117
12.44,1.59,0.117
12.47,1.74,0.117
12.50,1.88,0.117
12.52,2.02,0.117
12.55,2.16,0.117
12.58,2.30,0.117
12.61,2.45,0.117
12.64,2.59,0.117
12.67,2.73,0.117
12.69,2.87,0.117
12.72,3.01,0.117
12.75,3.15,0.117
12.78,3.30,0.117
12.81,3.44,0.117
12.83,3.58,0.117
12.86,3.72,0.117
12.89,3.86,0.117
12.92,4.00,0.117
12.95,4.15,0.117
12.98,4.29,0.117
13.00,4.43,0.117
13.03,4.57,0.117
13.06,4.71,0.117
13.09,4.85,0.118
13.12,5.00,0.117
13.15,5.14,0.118
13.18,5.28,0.118
13.20,5.42,0.118
13.23,5.56,0.118
13.26,5.71,0.118
13.29,5.85,0.118
13.32,5.99,0.118
13.35,6.13,0.118
13.37,6.27,0.118
13.40,6.42,0.118
13.43,6.56,0.118
13.46,6.70,0.118
13.49,6.84,0.118
13.52,6.98,0.118
13.54,7.12,0.118
13.57,7.27,0.118
13.60,7.41,0.118
13.63,7.55,0.118
13.66,7.69,0.118
13.68,7.83,0.118
13.71,7.97,0.118
13.74,8.12,0.118
13.77,8.26,0.119
13.80,8.40,0.119
13.83,8.54,0.119
13.85,8.68,0.119
13.88,8.83,0.119
13.91,8.97,0.119
13.94,9.11,0.119
13.97,9.25,0.119
14.00,9.39,0.119
14.03,9.53,0.119
14.05,9.68,0.119
14.08,9.82,0.119
14.11,9.96,0.119
14.14,10.10,0.119
14.17,10.24,0.119
14.20,10.39,0.119
14.22,10.53,0.119
14.25,10.67,0.119
14.28,10.81,0.119
14.31,10.95,0.120
14.34,11.09,0.120
14.37,11.24,0.120
14.39,11.38,0.120
14.42,11.52,0.120
14.45,11.66,0.120
14.48,11.80,0.120
14.51,11.95,0.120
14.53,12.09,0.120
14.56,12.23,0.120
14.59,12.37,0.120
14.62,12.51,0.120
14.65,12.65,0.120
14.68,12.80,0.120
14.70,12.94,0.120
14.73,13.08,0.120
14.76,13.22,0.120
14.79,13.36,0.120
14.82,13.50,0.120
14.85,13.65,0.120
14.88,13.79,0.120
14.90,13.93,0.120
14.93,14.07,0.120
14.96,14.21,0.120
14.99,14.35,0.120
15.02,14.50,0.120
15.05,14.64,0.121
15.07,14.78,0.121
15.10,14.92,0.121
15.13,15.06,0.121
15.16,15.21,0.121
15.19,15.35,0.121
15.22,15.49,0.121
15.24,15.63,0.121
15.27,15.77,0.121
15.30,15.91,0.121
15.33,16.06,0.121
15.36,16.20,0.121
15.38,16.34,0.121
15.41,16.48,0.121
15.44,16.62,0.121
15.47,16.76,0.121
15.50,16.91,0.121
15.53,17.05,0.121
15.55,17.19,0.121
15.58,17.33,0.121
15.61,17.47,0.121
15.64,17.61,0.121
15.67,17.76,0.121
15.70,17.90,0.121
15.73,18.04,0.121
15.75,18.18,0.122
15.78,18.33,0.122
15.81,18.47,0.122
15.84,18.61,0.122
15.87,18.75,0.122
15.90,18.89,0.122
15.92,19.03,0.122
15.95,19.17,0.122
15.98,19.32,0.122
16.01,19.46,0.122
16.04,19.60,0.122
16.07,19.74,0.122
16.09,19.88,0.122
16.12,20.03,0.122
16.15,20.17,0.122
16.18,20.31,0.122
16.21,20.45,0.122
16.23,20.59,0.122
16.26,20.74,0.122
16.29,20.88,0.122
16.32,21.02,0.122
16.35,21.16,0.123
16.38,21.30,0.123
16.40,21.44,0.123
16.43,21.59,0.123
16.46,21.73,0.123
16.49,21.87,0.123
16.52,22.01,0.123
16.55,22.15,0.123
16.58,22.29,0.123
16.60,22.44,0.123
16.63,22.58,0.123
16.66,22.72,0.123
16.69,22.86,0.123
16.72,23.00,0.123
16.75,23.14,0.123
16.77,23.29,0.123
16.80,23.43,0.123
16.83,23.57,0.123
16.86,23.71,0.123
16.89,23.85,0.124
16.92,23.99,0.124
16.94,24.14,0.124
16.97,24.28,0.124
17.00,24.42,0.124
17.03,24.56,0.124
17.06,24.70,0.124
17.08,24.85,0.124
17.11,24.99,0.124
17.14,25.13,0.124
17.17,25.27,0.124
17.20,25.41,0.124
17.23,25.55,0.124
17.26,25.70,0.124
17.28,25.84,0.124
17.31,25.98,0.125
17.34,26.12,0.125
17.37,26.27,0.125
17.40,26.41,0.125
17.43,26.55,0.125
17.45,26.69,0.125
17.48,26.83,0.125
17.51,26.97,0.125
17.54,27.11,0.125
17.57,27.26,0.125
17.59,27.40,0.125
17.62,27.54,0.125
17.65,27.68,0.125
17.68,27.82,0.125
17.71,27.96,0.125
17.74,28.11,0.125
17.77,28.25,0.125
17.79,28.39,0.126
17.82,28.53,0.126
17.85,28.67,0.126
17.88,28.81,0.126
17.91,28.96,0.126
17.93,29.10,0.126
17.96,29.24,0.126
17.99,29.38,0.126
18.02,29.52,0.126
18.05,29.67,0.126
18.08,29.81,0.126
18.11,29.95,0.126
18.13,30.09,0.126
18.16,30.23,0.126
18.19,30.38,0.126
18.22,30.52,0.127
18.25,30.66,0.127
18.28,30.80,0.127
18.30,30.94,0.127
18.33,31.08,0.127
18.36,31.23,0.127
18.39,31.37,0.127
18.42,31.51,0.127
18.44,31.65,0.127
18.47,31.79,0.127
18.50,31.93,0.127
18.53,32.08,0.127
18.56,32.22,0.127
18.59,32.36,0.127
18.62,32.50,0.128
18.64,32.64,0.128
18.67,32.79,0.128
18.70,32.93,0.128
18.73,33.07,0.128
18.76,33.21,0.128
18.78,33.35,0.128
18.81,33.49,0.128
18.84,33.63,0.128
18.87,33.78,0.128
18.90,33.92,0.128
18.93,34.06,0.128
18.96,34.20,0.129
18.98,34.34,0.129
19.01,34.49,0.129
19.04,34.63,0.129
19.07,34.77,0.129
19.10,34.91,0.129
19.13,35.05,0.129
19.15,35.19,0.129
19.18,35.34,0.129
19.21,35.48,0.129
19.24,35.62,0.129
19.27,35.76,0.129
19.29,35.90,0.130
19.32,36.04,0.130
19.35,36.19,0.130
19.38,36.33,0.130
19.41,36.47,0.130
19.44,36.61,0.130
19.47,36.75,0.130
19.49,36.89,0.130
19.52,37.04,0.130
19.55,37.18,0.130
19.58,37.32,0.130
19.61,37.46,0.130
19.63,37.60,0.131
19.66,37.75,0.131
19.69,37.89,0.131
19.72,38.03,0.131
19.75,38.17,0.131
19.78,38.31,0.131
19.81,38.45,0.131
19.83,38.60,0.131
19.86,38.74,0.131
19.89,38.88,0.131
19.92,39.02,0.131
19.95,39.16,0.132
19.98,39.31,0.132
20.00,39.45,0.132
20.03,39.59,0.132
20.06,39.73,0.132
20.09,39.87,0.132
20.12,40.02,0.132
20.14,40.16,0.132
20.17,40.30,0.132
20.20,40.44,0.132
20.23,40.58,0.132
20.26,40.72,0.133
20.29,40.87,0.133
20.32,41.01,0.133
20.34,41.15,0.133
20.37,41.29,0.133
20.40,41.43,0.133
20.43,41.58,0.133
20.46,41.72,0.133
20.48,41.86,0.134
20.51,42.00,0.134
20.54,42.14,0.134
20.57,42.28,0.134
20.60,42.42,0.134
20.63,42.57,0.134
20.66,42.71,0.134
20.68,42.85,0.134
20.71,42.99,0.134
20.74,43.13,0.135
20.77,43.27,0.135
20.80,43.42,0.135
20.83,43.56,0.135
20.85,43.70,0.135
20.88,43.84,0.135
20.91,43.98,0.135
20.94,44.13,0.135
20.97,44.27,0.135
20.99,44.41,0.136
21.02,44.55,0.136
21.05,44.69,0.136
21.08,44.83,0.136
21.11,44.97,0.136
21.14,45.12,0.136
21.17,45.26,0.137
21.19,45.40,0.137
21.22,45.54,0.137
21.25,45.68,0.137
21.28,45.82,0.137
21.31,45.97,0.137
21.33,46.11,0.138
21.36,46.25,0.138
21.39,46.39,0.138
21.42,46.53,0.138
21.45,46.67,0.138
21.48,46.82,0.139
21.51,46.96,0.139
21.53,47.10,0.139
21.56,47.24,0.139
21.59,47.38,0.139
21.62,47.52,0.140
21.65,47.67,0.140
21.68,47.81,0.140
21.70,47.95,0.140
21.73,48.09,0.141
21.76,48.23,0.141
21.79,48.38,0.141
21.82,48.52,0.141
21.84,48.66,0.142
21.87,48.80,0.142
21.90,48.94,0.142
21.93,49.08,0.142
21.96,49.22,0.143
21.99,49.37,0.143
22.02,49.51,0.144
22.04,49.65,0.144
22.07,49.79,0.144
22.10,49.93,0.145
22.13,50.07,0.145
22.16,50.22,0.145
22.18,50.36,0.146
22.21,50.50,0.146
22.24,50.64,0.146
22.27,50.78,0.147
22.30,50.92,0.147
22.33,51.06,0.148
22.36,51.21,0.148
22.38,51.35,0.149
22.41,51.49,0.149
22.44,51.63,0.150
22.47,51.77,0.150
22.50,51.92,0.151
22.53,52.06,0.152
22.55,52.20,0.152
22.58,52.34,0.153
22.61,52.48,0.154
22.64,52.62,0.155
22.67,52.76,0.155
22.69,52.91,0.156
22.72,53.05,0.157
22.75,53.19,0.158
22.78,53.33,0.159
22.81,53.47,0.160
22.84,53.61,0.161
22.87,53.75,0.163
22.89,53.89,0.164
22.92,54.04,0.165
22.95,54.18,0.167
22.98,54.32,0.168
23.01,54.46,0.170
23.03,54.60,0.172
23.06,54.74,0.174
23.09,54.88,0.176
23.12,55.02,0.179
23.15,55.16,0.182
23.18,55.30,0.184
23.21,55.45,0.187
23.23,55.59,0.190
23.26,55.73,0.194
23.29,55.87,0.197
23.32,56.01,0.201
23.35,56.15,0.205
23.38,56.29,0.209
23.40,56.43,0.214
23.43,56.57,0.219
23.46,56.71,0.225
23.49,56.85,0.229
23.52,56.99,0.236
23.54,57.13,0.242
23.57,57.27,0.248
23.60,57.41,0.256
23.63,57.55,0.264
23.66,57.69,0.273
23.69,57.82,0.282
23.72,57.96,0.292
23.74,58.10,0.304
23.77,58.24,0.318
23.80,58.38,0.328
23.83,58.52,0.344
23.86,58.65,0.360
23.88,58.79,0.376
23.91,58.92,0.395
23.94,59.06,0.417
23.97,59.19,0.440
24.00,59.33,0.466
24.03,59.46,0.497
24.06,59.59,0.531
24.08,59.72,0.575
24.11,59.85,0.623
24.14,59.97,0.676
24.17,60.10,0.726
24.20,60.22,0.775
24.23,60.34,0.832
24.25,60.46,0.894
24.28,60.59,0.953
24.31,60.71,0.987
24.34,60.83,1.028
24.37,60.96,1.064
24.39,61.09,1.072
24.42,61.22,1.069
24.45,61.36,1.064
24.48,61.50,1.067
24.51,61.64,1.063
24.54,61.78,1.072
24.57,61.92,1.068
24.59,62.07,1.056
24.62,62.21,1.082
24.65,62.35,1.042
24.68,62.50,0.957
24.71,62.67,0.839
24.73,62.84,0.714
24.76,63.02,0.599
24.79,63.20,0.505
24.82,63.38,0.430
24.85,63.55,0.375
24.88,63.72,0.333
24.91,63.88,0.300
24.93,64.04,0.275
24.96,64.19,0.256
24.99,64.34,0.241
25.02,64.49,0.230
25.05,64.64,0.220
25.08,64.79,0.214
25.10,64.93,0.208
25.13,65.08,0.203
25.16,65.22,0.201
25.19,65.36,0.199
25.22,65.51,0.197
25.24,65.65,0.196
25.27,65.79,0.195
25.30,65.94,0.194
25.33,66.08,0.194
25.36,66.22,0.194
25.39,66.36,0.193
25.42,66.50,0.193
25.44,66.65,0.192
25.47,66.79,0.192
25.50,66.93,0.192
25.53,67.07,0.192
25.56,67.21,0.191
25.58,67.35,0.191
25.61,67.50,0.191
25.64,67.64,0.191
25.67,67.78,0.191
25.70,67.92,0.191
25.73,68.06,0.191
25.76,68.21,0.191
25.78,68.35,0.191
25.81,68.49,0.191
25.84,68.63,0.191
25.87,68.77,0.191
25.90,68.91,0.191
25.93,69.05,0.191
25.95,69.20,0.192
25.98,69.34,0.192
26.01,69.48,0.192
26.04,69.62,0.192
26.07,69.76,0.192
26.09,69.90,0.193
26.12,70.05,0.193
26.15,70.19,0.193
26.18,70.33,0.193
26.21,70.47,0.193
26.24,70.61,0.194
26.27,70.75,0.194
26.29,70.90,0.194
26.32,71.04,0.194
26.35,71.18,0.194
26.38,71.32,0.195
26.41,71.46,0.195
26.43,71.61,0.195
26.46,71.75,0.195
26.49,71.89,0.196
26.52,72.03,0.196
26.55,72.17,0.196
26.58,72.31,0.196
26.61,72.46,0.197
26.63,72.60,0.197
26.66,72.74,0.197
26.69,72.88,0.198
26.72,73.02,0.198
26.75,73.16,0.198
26.78,73.30,0.198
26.80,73.45,0.199
26.83,73.59,0.199
26.86,73.73,0.199
26.89,73.87,0.199
26.92,74.01,0.200
26.94,74.15,0.200
26.97,74.30,0.200
27.00,74.44,0.200
27.03,74.58,0.201
27.06,74.72,0.201
27.09,74.86,0.201
27.12,75.00,0.202
27.14,75.15,0.202
27.17,75.29,0.202
27.20,75.43,0.202
27.23,75.57,0.203
27.26,75.71,0.203
27.28,75.85,0.203
27.31,76.00,0.204
27.34,76.14,0.204
27.37,76.28,0.204
27.40,76.42,0.204
27.43,76.56,0.205
27.46,76.71,0.205
27.48,76.85,0.205
27.51,76.99,0.206
27.54,77.13,0.206
27.57,77.27,0.206
27.60,77.41,0.206
27.63,77.55,0.207
27.65,77.70,0.207
27.68,77.84,0.207
27.71,77.98,0.208
27.74,78.12,0.208
27.77,78.26,0.208
27.79,78.40,0.209
27.82,78.54,0.209
27.85,78.69,0.209
27.88,78.83,0.210
27.91,78.97,0.210
27.94,79.11,0.210
27.97,79.25,0.211
27.99,79.40,0.211
28.02,79.54,0.211
28.05,79.68,0.212
28.08,79.82,0.212
28.11,79.96,0.213
28.13,80.10,0.213
28.16,80.25,0.213
28.19,80.39,0.213
28.22,80.53,0.214
28.25,80.67,0.214
28.28,80.81,0.214
28.31,80.95,0.215
28.33,81.10,0.215
28.36,81.24,0.216
28.39,81.38,0.216
28.42,81.52,0.216
28.45,81.66,0.217
28.48,81.80,0.217
28.50,81.95,0.218
28.53,82.09,0.218
28.56,82.23,0.218
28.59,82.37,0.219
28.62,82.51,0.219
28.64,82.65,0.219
28.67,82.79,0.220
28.70,82.94,0.220
28.73,83.08,0.220
28.76,83.22,0.221
28.79,83.36,0.221
28.82,83.50,0.221
28.84,83.64,0.222
28.87,83.79,0.222
28.90,83.93,0.222
28.93,84.07,0.223
28.96,84.21,0.223
28.98,84.35,0.224
29.01,84.50,0.224
29.04,84.64,0.224
29.07,84.78,0.225
29.10,84.92,0.225
29.13,85.06,0.226
29.16,85.20,0.226
29.18,85.34,0.226
29.21,85.49,0.227
29.24,85.63,0.227
29.27,85.77,0.227
29.30,85.91,0.228
29.33,86.05,0.228
29.35,86.20,0.229
29.38,86.34,0.229
29.41,86.48,0.229
29.44,86.62,0.230
29.47,86.76,0.230
29.49,86.90,0.230
29.52,87.04,0.231
29.55,87.19,0.231
29.58,87.33,0.231
29.61,87.47,0.232
29.64,87.61,0.232
29.67,87.75,0.232
29.69,87.89,0.233
29.72,88.04,0.233
29.75,88.18,0.234
29.78,88.32,0.234
29.81,88.46,0.234
29.83,88.60,0.235
29.86,88.74,0.235
29.89,88.89,0.236
29.92,89.03,0.236
29.95,89.17,0.236
29.98,89.31,0.237
30.01,89.45,0.237
30.03,89.59,0.237
30.06,89.74,0.238
30.09,89.88,0.238
30.12,90.02,0.238
30.15,90.16,0.239
30.18,90.30,0.239
30.20,90.44,0.239
30.23,90.58,0.240
30.26,90.73,0.240
30.29,90.87,0.241
30.32,91.01,0.241
30.34,91.15,0.241
30.37,91.29,0.242
30.40,91.43,0.242
30.43,91.58,0.243
30.46,91.72,0.243
30.49,91.86,0.243
30.52,92.00,0.244
30.54,92.14,0.244
30.57,92.28,0.245
30.60,92.43,0.245
30.63,92.57,0.246
30.66,92.71,0.246
30.68,92.85,0.246
30.71,92.99,0.247
30.74,93.13,0.247
30.77,93.28,0.248
30.80,93.42,0.248
30.83,93.56,0.248
30.86,93.70,0.249
30.88,93.84,0.249
30.91,93.98,0.250
30.94,94.13,0.250
30.97,94.27,0.251
31.00,94.41,0.251
31.03,94.55,0.251
31.05,94.69,0.252
31.08,94.83,0.252
31.11,94.97,0.253
31.14,95.12,0.253
31.17,95.26,0.254
31.19,95.40,0.254
31.22,95.54,0.254
31.25,95.68,0.255
31.28,95.82,0.255
31.31,95.97,0.256
31.34,96.11,0.256
31.37,96.25,0.257
31.39,96.39,0.257
31.42,96.53,0.258
31.45,96.67,0.258
31.48,96.82,0.258
31.51,96.96,0.259
31.53,97.10,0.259
31.56,97.24,0.260
31.59,97.38,0.260
31.62,97.52,0.261
31.65,97.66,0.261
31.68,97.81,0.261
31.71,97.95,0.262
31.73,98.09,0.262
31.76,98.23,0.263
31.79,98.37,0.263
31.82,98.51,0.264
31.85,98.66,0.264
31.88,98.80,0.265
31.90,98.94,0.265
31.93,99.08,0.265
31.96,99.22,0.266
31.99,99.37,0.266
32.02,99.51,0.267
32.04,99.65,0.267
32.07,99.79,0.268
32.10,99.93,0.268
32.13,100.07,0.269
32.16,100.21,0.269
32.19,100.36,0.269
32.22,100.50,0.270
32.24,100.64,0.270
32.27,100.78,0.271
32.30,100.92,0.271
32.33,101.06,0.272
32.36,101.20,0.272
32.38,101.35,0.272
32.41,101.49,0.273
32.44,101.63,0.273
32.47,101.77,0.274
32.50,101.91,0.274
32.53,102.06,0.275
32.56,102.20,0.275
32.58,102.34,0.275
32.61,102.48,0.276
32.64,102.62,0.276
32.67,102.76,0.277
32.70,102.91,0.277
32.73,103.05,0.277
32.75,103.19,0.278
32.78,103.33,0.278
32.81,103.47,0.278
32.84,103.61,0.279
32.87,103.76,0.279
32.89,103.90,0.279
32.92,104.04,0.280
32.95,104.18,0.280
32.98,104.32,0.281
33.01,104.46,0.281
33.04,104.60,0.281
33.07,104.75,0.281
33.09,104.89,0.282
33.12,105.03,0.282
33.15,105.17,0.282
33.18,105.31,0.282
33.21,105.46,0.283
33.23,105.60,0.283
33.26,105.74,0.283
33.29,105.88,0.283
33.32,106.02,0.284
33.35,106.16,0.284
33.38,106.30,0.284
33.41,106.45,0.284
33.43,106.59,0.285
33.46,106.73,0.285
33.49,106.87,0.285
33.52,107.01,0.285
33.55,107.15,0.286
33.58,107.30,0.286
33.60,107.44,0.286
33.63,107.58,0.286
33.66,107.72,0.286
33.69,107.86,0.286
33.72,108.01,0.286
33.74,108.15,0.286
33.77,108.29,0.286
33.80,108.43,0.286
33.83,108.57,0.286
33.86,108.71,0.286
33.89,108.86,0.286
33.92,109.00,0.286
33.94,109.14,0.286
33.97,109.28,0.285
34.00,109.42,0.285
34.03,109.57,0.285
34.06,109.71,0.285
34.08,109.85,0.284
34.11,109.99,0.284
34.14,110.13,0.284
34.17,110.28,0.283
34.20,110.42,0.283
34.23,110.56,0.283
34.26,110.70,0.282
34.28,110.84,0.282
34.31,110.99,0.281
34.34,111.13,0.281
34.37,111.27,0.281
34.40,111.41,0.280
34.43,111.55,0.280
34.45,111.70,0.279
34.48,111.84,0.279
34.51,111.98,0.278
34.54,112.12,0.278
34.57,112.26,0.277
34.59,112.40,0.277
34.62,112.55,0.276
34.65,112.69,0.276
34.68,112.83,0.276
34.71,112.97,0.275
34.74,113.11,0.275
34.76,113.25,0.274
34.79,113.40,0.274
34.82,113.54,0.273
34.85,113.68,0.273
34.88,113.82,0.273
34.91,113.96,0.272
34.94,114.11,0.272
34.96,114.25,0.272
34.99,114.39,0.271
35.02,114.53,0.271
35.05,114.67,0.271
35.08,114.82,0.271
35.11,114.96,0.270
35.13,115.10,0.270
35.16,115.24,0.270
35.19,115.38,0.270
35.22,115.53,0.270
35.25,115.67,0.269
35.28,115.81,0.269
35.30,115.95,0.269
35.33,116.09,0.269
35.36,116.23,0.269
35.39,116.37,0.269
35.42,116.52,0.269
35.44,116.66,0.269
35.47,116.80,0.268
35.50,116.94,0.268
35.53,117.08,0.268
35.56,117.23,0.268
35.59,117.37,0.268
35.61,117.51,0.268
35.64,117.65,0.268
35.67,117.79,0.268
35.70,117.93,0.267
35.73,118.08,0.267
35.76,118.22,0.267
35.79,118.36,0.267
35.81,118.50,0.266
35.84,118.64,0.266
35.87,118.79,0.265
35.90,118.93,0.265
35.93,119.07,0.265
35.96,119.21,0.264
35.98,119.35,0.263
36.01,119.50,0.261
36.04,119.64,0.259
36.07,119.78,0.259
36.10,119.92,0.258
36.13,120.07,0.257
36.15,120.21,0.256
36.18,120.35,0.255
36.21,120.49,0.254
36.24,120.63,0.252
36.27,120.78,0.251
36.29,120.92,0.250
36.32,121.06,0.249
36.35,121.20,0.247
36.38,121.34,0.244
36.41,121.49,0.242
36.44,121.63,0.240
36.46,121.77,0.237
36.49,121.91,0.233
36.52,122.06,0.229
36.55,122.20,0.224
36.58,122.34,0.223
36.61,122.49,0.220
36.64,122.63,0.217
36.66,122.77,0.213
36.69,122.92,0.209
36.72,123.06,0.205
36.75,123.20,0.199
36.78,123.34,0.196
36.81,123.49,0.192
36.83,123.63,0.188
36.86,123.77,0.183
36.89,123.92,0.179
36.92,124.06,0.175
36.95,124.20,0.171
36.98,124.35,0.167
37.00,124.49,0.164
37.03,124.63,0.160
37.06,124.77,0.156
37.09,124.92,0.154
37.12,125.06,0.150
37.14,125.20,0.147
37.17,125.35,0.145
37.20,125.49,0.142
37.23,125.63,0.140
37.26,125.77,0.140
37.29,125.92,0.139
37.31,126.06,0.138
37.34,126.20,0.138
37.37,126.34,0.137
37.40,126.48,0.136
37.43,126.63,0.136
37.46,126.77,0.135
37.49,126.91,0.135
37.51,127.05,0.134
37.54,127.19,0.134
37.57,127.34,0.134
37.60,127.48,0.134
37.63,127.62,0.133
37.66,127.76,0.133
37.68,127.90,0.133
37.71,128.05,0.133
37.74,128.19,0.133
37.77,128.33,0.133
37.80,128.47,0.133
37.83,128.61,0.132
37.85,128.75,0.132
37.88,128.89,0.132
37.91,129.04,0.132
37.94,129.18,0.131
37.97,129.32,0.131
37.99,129.46,0.131
38.02,129.60,0.131
38.05,129.75,0.130
38.08,129.89,0.130
38.11,130.03,0.130
38.14,130.17,0.129
38.16,130.31,0.129
38.19,130.45,0.129
38.22,130.60,0.129
38.25,130.74,0.129
38.28,130.88,0.129
38.31,131.02,0.129
38.34,131.16,0.130
38.36,131.30,0.130
38.39,131.44,0.131
38.42,131.59,0.131
38.45,131.73,0.132
38.48,131.87,0.133
38.51,132.01,0.134
38.53,132.15,0.135
38.56,132.29,0.136
38.59,132.43,0.138
38.62,132.58,0.139
38.65,132.72,0.140
38.68,132.86,0.141
38.70,133.00,0.142
38.73,133.14,0.143
38.76,133.28,0.144
38.79,133.42,0.145
38.82,133.56,0.146
38.84,133.71,0.147
38.87,133.85,0.148
38.90,133.99,0.149
38.93,134.13,0.150
38.96,134.27,0.151
38.99,134.41,0.152
39.01,134.56,0.153
39.04,134.70,0.155
39.07,134.84,0.156
39.10,134.98,0.157
39.13,135.12,0.158
39.16,135.27,0.159
39.19,135.41,0.160
39.21,135.55,0.161
39.24,135.69,0.162
39.27,135.83,0.163
39.30,135.97,0.163
39.33,136.12,0.164
39.36,136.26,0.165
39.38,136.40,0.166
39.41,136.54,0.166
39.44,136.68,0.167
39.47,136.82,0.167
39.50,136.96,0.168
39.53,137.10,0.169
39.55,137.24,0.169
39.58,137.38,0.170
39.61,137.52,0.171
39.64,137.67,0.172
39.67,137.81,0.173
39.69,137.95,0.174
39.72,138.09,0.174
39.75,138.23,0.175
39.78,138.38,0.176
39.81,138.52,0.176
39.84,138.66,0.177
39.86,138.80,0.177
39.89,138.94,0.178
39.92,139.08,0.178
39.95,139.23,0.179
39.98,139.37,0.179
40.01,139.51,0.180
40.04,139.65,0.180
40.06,139.79,0.181
40.09,139.93,0.181
40.12,140.08,0.181
40.15,140.22,0.182
40.18,140.36,0.182
40.21,140.50,0.182
40.23,140.64,0.183
40.26,140.78,0.183
40.29,140.92,0.184
40.32,141.07,0.184
40.35,141.21,0.184
40.38,141.35,0.185
40.40,141.49,0.185
40.43,141.63,0.185
40.46,141.77,0.185
40.49,141.91,0.186
40.52,142.06,0.186
40.54,142.20,0.186
40.57,142.34,0.187
40.60,142.48,0.187
40.63,142.62,0.187
40.66,142.76,0.187
40.69,142.91,0.187
40.71,143.05,0.188
40.74,143.19,0.188
40.77,143.33,0.188
40.80,143.47,0.188
40.83,143.61,0.188
40.86,143.76,0.189
40.89,143.90,0.189
40.91,144.04,0.189
40.94,144.18,0.189
40.97,144.32,0.189
41.00,144.46,0.189
41.03,144.60,0.189
41.06,144.75,0.190
41.08,144.89,0.190
41.11,145.03,0.190
41.14,145.17,0.190
41.17,145.32,0.190
41.20,145.46,0.190
41.23,145.60,0.190
41.25,145.74,0.191
41.28,145.88,0.191
41.31,146.02,0.191
41.34,146.17,0.191
41.37,146.31,0.191
41.39,146.45,0.191
41.42,146.59,0.191
41.45,146.73,0.191
41.48,146.87,0.191
41.51,147.01,0.191
41.54,147.16,0.191
41.56,147.30,0.191
41.59,147.44,0.192
41.62,147.58,0.192
41.65,147.72,0.192
41.68,147.87,0.192
41.71,148.01,0.192
41.74,148.15,0.192
41.76,148.29,0.192
41.79,148.43,0.192
41.82,148.57,0.192
41.85,148.72,0.192
41.88,148.86,0.192
41.91,149.00,0.192
41.93,149.14,
41.96,149.28,
41.99,,

[step]
Ramp 5.00 °C/min to -60.00 °C
Time,Temperature,Heat Flow (Normalized)
min,°C,W/g
42.99,150.12,-0.040
43.01,150.12,-0.040
43.04,150.11,-0.041
43.07,150.09,-0.063
43.10,150.04,-0.092
43.13,149.96,-0.129
43.16,149.87,-0.159
43.19,149.77,-0.186
43.21,149.65,-0.205
43.24,149.53,-0.218
43.27,149.41,-0.230
43.30,149.28,-0.238
43.33,149.15,-0.247
43.36,149.02,-0.251
43.38,148.89,-0.254
43.41,148.75,-0.257
43.44,148.62,-0.260
43.47,148.48,-0.262
43.50,148.34,-0.263
43.53,148.20,-0.264
43.55,148.06,-0.265
43.58,147.92,-0.265
43.61,147.79,-0.266
43.64,147.65,-0.266
43.67,147.51,-0.266
43.69,147.37,-0.267
43.72,147.23,-0.267
43.75,147.09,-0.268
43.78,146.95,-0.268
43.81,146.80,-0.268
43.84,146.66,-0.268
43.86,146.52,-0.269
43.89,146.38,-0.269
43.92,146.24,-0.269
43.95,146.10,-0.269
43.98,145.96,-0.269
44.01,145.82,-0.269
44.04,145.68,-0.269
44.06,145.54,-0.269
44.09,145.40,-0.270
44.12,145.26,-0.270
44.15,145.11,-0.270
44.18,144.97,-0.270
44.21,144.83,-0.270
44.23,144.69,-0.270
44.26,144.55,-0.269
44.29,144.41,-0.269
44.32,144.27,-0.269
44.35,144.13,-0.269
44.38,143.98,-0.269
44.40,143.84,-0.269
44.43,143.70,-0.269
44.46,143.56,-0.269
44.49,143.42,-0.269
44.52,143.28,-0.269
44.54,143.14,-0.269
44.57,142.99,-0.269
44.60,142.85,-0.269
44.63,142.71,-0.269
44.66,142.57,-0.269
44.69,142.43,-0.268
44.71,142.29,-0.268
44.74,142.15,-0.268
44.77,142.00,-0.268
44.80,141.86,-0.268
44.83,141.72,-0.268
44.86,141.58,-0.268
44.89,141.44,-0.268
44.91,141.30,-0.268
44.94,141.16,-0.268
44.97,141.01,-0.268
45.00,140.87,-0.267
45.03,140.73,-0.267
45.06,140.59,-0.267
45.08,140.45,-0.267
45.11,140.31,-0.267
45.14,140.17,-0.267
45.17,140.02,-0.267
45.20,139.88,-0.267
45.23,139.74,-0.267
45.25,139.60,-0.266
45.28,139.46,-0.266
45.31,139.32,-0.266
45.34,139.17,-0.266
45.37,139.03,-0.266
45.39,138.89,-0.266
45.42,138.75,-0.266
45.45,138.61,-0.266
45.48,138.47,-0.266
45.51,138.32,-0.266
45.54,138.18,-0.265
45.56,138.04,-0.265
45.59,137.90,-0.265
45.62,137.76,-0.265
45.65,137.62,-0.265
45.68,137.48,-0.265
45.71,137.33,-0.265
45.74,137.19,-0.265
45.76,137.05,-0.264
45.79,136.91,-0.264
45.82,136.77,-0.264
45.85,136.63,-0.264
45.88,136.48,-0.264
45.91,136.34,-0.264
45.93,136.20,-0.264
45.96,136.06,-0.264
45.99,135.92,-0.264
46.02,135.78,-0.264
46.05,135.63,-0.264
46.08,135.49,-0.263
46.10,135.35,-0.263
46.13,135.21,-0.263
46.16,135.07,-0.263
46.19,134.93,-0.263
46.22,134.78,-0.263
46.24,134.64,-0.263
46.27,134.50,-0.263
46.30,134.36,-0.262
46.33,134.22,-0.262
46.36,134.08,-0.262
46.39,133.94,-0.262
46.41,133.79,-0.262
46.44,133.65,-0.262
46.47,133.51,-0.262
46.50,133.37,-0.262
46.53,133.23,-0.262
46.56,133.09,-0.262
46.59,132.94,-0.262
46.61,132.80,-0.262
46.64,132.66,-0.262
46.67,132.52,-0.262
46.70,132.38,-0.262
46.73,132.24,-0.262
46.76,132.09,-0.262
46.78,131.95,-0.261
46.81,131.81,-0.261
46.84,131.67,-0.261
46.87,131.53,-0.261
46.90,131.39,-0.261
46.93,131.24,-0.261
46.95,131.10,-0.261
46.98,130.96,-0.261
47.01,130.82,-0.261
47.04,130.68,-0.261
47.07,130.54,-0.261
47.09,130.40,-0.261
47.12,130.25,-0.260
47.15,130.11,-0.260
47.18,129.97,-0.260
47.21,129.83,-0.260
47.24,129.69,-0.260
47.26,129.55,-0.260
47.29,129.40,-0.260
47.32,129.26,-0.260
47.35,129.12,-0.260
47.38,128.98,-0.260
47.41,128.84,-0.260
47.44,128.70,-0.260
47.46,128.55,-0.260
47.49,128.41,-0.259
47.52,128.27,-0.259
47.55,128.13,-0.259
47.58,127.99,-0.259
47.61,127.85,-0.259
47.63,127.71,-0.259
47.66,127.56,-0.259
47.69,127.42,-0.259
47.72,127.28,-0.259
47.75,127.14,-0.259
47.78,127.00,-0.259
47.80,126.86,-0.259
47.83,126.71,-0.259
47.86,126.57,-0.259
47.89,126.43,-0.258
47.92,126.29,-0.258
47.94,126.15,-0.258
47.97,126.01,-0.258
48.00,125.87,-0.258
48.03,125.72,-0.258
48.06,125.58,-0.258
48.09,125.44,-0.258
48.11,125.30,-0.258
48.14,125.16,-0.258
48.17,125.01,-0.258
48.20,124.87,-0.258
48.23,124.73,-0.258
48.26,124.59,-0.258
48.29,124.45,-0.258
48.31,124.31,-0.258
48.34,124.17,-0.257
48.37,124.02,-0.257
48.40,123.88,-0.257
48.43,123.74,-0.257
48.46,123.60,-0.257
48.48,123.46,-0.257
48.51,123.32,-0.257
48.54,123.18,-0.257
48.57,123.03,-0.257
48.60,122.89,-0.257
48.63,122.75,-0.257
48.65,122.61,-0.257
48.68,122.47,-0.257
48.71,122.32,-0.257
48.74,122.18,-0.257
48.77,122.04,-0.256
48.79,121.90,-0.256
48.82,121.76,-0.256
48.85,121.62,-0.256
48.88,121.48,-0.256
48.91,121.33,-0.256
48.94,121.19,-0.256
48.96,121.05,-0.256
48.99,120.91,-0.256
49.02,120.77,-0.256
49.05,120.63,-0.256
49.08,120.48,-0.256
49.11,120.34,-0.256
49.14,120.20,-0.256
49.16,120.06,-0.256
49.19,119.92,-0.256
49.22,119.78,-0.255
49.25,119.64,-0.255
49.28,119.49,-0.255
49.31,119.35,-0.255
49.33,119.21,-0.255
49.36,119.07,-0.255
49.39,118.93,-0.255
49.42,118.79,-0.255
49.45,118.64,-0.255
49.48,118.50,-0.255
49.50,118.36,-0.255
49.53,118.22,-0.255
49.56,118.08,-0.255
49.59,117.94,-0.255
49.62,117.79,-0.255
49.64,117.65,-0.255
49.67,117.51,-0.255
49.70,117.37,-0.254
49.73,117.23,-0.254
49.76,117.09,-0.254
49.79,116.95,-0.254
49.81,116.80,-0.254
49.84,116.66,-0.254
49.87,116.52,-0.254
49.90,116.38,-0.254
49.93,116.24,-0.254
49.96,116.10,-0.254
49.99,115.96,-0.254
50.01,115.81,-0.254
50.04,115.67,-0.254
50.07,115.53,-0.254
50.10,115.39,-0.254
50.13,115.25,-0.254
50.16,115.10,-0.254
50.18,114.96,-0.254
50.21,114.82,-0.253
50.24,114.68,-0.253
50.27,114.54,-0.253
50.30,114.40,-0.253
50.33,114.25,-0.253
50.35,114.11,-0.253
50.38,113.97,-0.253
50.41,113.83,-0.253
50.44,113.69,-0.253
50.47,113.55,-0.253
50.49,113.40,-0.253
50.52,113.26,-0.253
50.55,113.12,-0.253
50.58,112.98,-0.253
50.61,112.84,-0.253
50.64,112.70,-0.253
50.66,112.55,-0.252
50.69,112.41,-0.253
50.72,112.27,-0.252
50.75,112.13,-0.252
50.78,111.99,-0.252
50.81,111.85,-0.252
50.84,111.71,-0.252
50.86,111.56,-0.252
50.89,111.42,-0.252
50.92,111.28,-0.252
50.95,111.14,-0.252
50.98,111.00,-0.252
51.01,110.86,-0.252
51.03,110.71,-0.252
51.06,110.57,-0.252
51.09,110.43,-0.252
51.12,110.29,-0.252
51.15,110.15,-0.251
51.18,110.01,-0.251
51.20,109.86,-0.252
51.23,109.72,-0.251
51.26,109.58,-0.251
51.29,109.44,-0.251
51.32,109.30,-0.251
51.34,109.16,-0.251
51.37,109.02,-0.251
51.40,108.87,-0.251
51.43,108.73,-0.251
51.46,108.59,-0.251
51.49,108.45,-0.251
51.51,108.31,-0.251
51.54,108.17,-0.251
51.57,108.02,-0.251
51.60,107.88,-0.251
51.63,107.74,-0.250
51.66,107.60,-0.250
51.69,107.46,-0.250
51.71,107.32,-0.250
51.74,107.18,-0.250
51.77,107.03,-0.250
51.80,106.89,-0.250
51.83,106.75,-0.250
51.86,106.61,-0.250
51.88,106.47,-0.250
51.91,106.32,-0.250
51.94,106.18,-0.250
51.97,106.04,-0.250
52.00,105.90,-0.250
52.03,105.76,-0.250
52.05,105.62,-0.250
52.08,105.48,-0.250
52.11,105.33,-0.250
52.14,105.19,-0.250
52.17,105.05,-0.250
52.19,104.91,-0.250
52.22,104.77,-0.250
52.25,104.63,-0.249
52.28,104.48,-0.249
52.31,104.34,-0.249
52.34,104.20,-0.249
52.36,104.06,-0.249
52.39,103.92,-0.249
52.42,103.78,-0.249
52.45,103.63,-0.249
52.48,103.49,-0.249
52.51,103.35,-0.249
[...]
176.16,-39.90,0.112
176.17,-39.84,0.112
176.19,-39.77,0.112
176.20,-39.70,0.112
176.21,-39.63,0.112
176.23,-39.57,0.112
176.24,-39.50,0.112
176.25,-39.43,0.112
176.27,-39.37,0.112
176.28,-39.30,0.112
176.29,-39.23,0.112
176.31,-39.17,0.112
176.32,-39.10,0.112
176.33,-39.03,0.112
176.35,-38.97,0.112
176.36,-38.90,0.113
176.37,-38.83,0.113
176.39,-38.77,0.113
176.40,-38.70,0.113
176.41,-38.63,0.113
176.43,-38.57,0.113
176.44,-38.50,0.113
176.45,-38.43,0.113
176.47,-38.37,0.113
176.48,-38.30,0.113
176.49,-38.23,0.113
176.51,-38.16,0.113
176.52,-38.10,0.113
176.53,-38.03,0.113
176.55,-37.96,0.113
176.56,-37.90,0.113
176.57,-37.83,0.113
176.59,-37.76,0.113
176.60,-37.70,0.113
176.61,-37.63,0.113
176.63,-37.56,0.113
176.64,-37.50,0.113
176.65,-37.43,0.113
176.67,-37.36,0.113
176.68,-37.30,0.113
176.69,-37.23,0.113
176.71,-37.16,0.113
176.72,-37.10,0.113
176.73,-37.03,0.113
176.75,-36.96,0.113
176.76,-36.90,0.113
176.77,-36.83,0.113
176.79,-36.76,0.113
176.80,-36.70,0.113
176.81,-36.63,0.113
176.83,-36.56,0.113
176.84,-36.50,0.113
176.85,-36.43,0.113
176.87,-36.36,0.113
176.88,-36.30,0.113
176.89,-36.23,0.113
176.91,-36.16,0.113
176.92,-36.10,0.113
176.93,-36.03,0.113
176.95,-35.96,0.113
176.96,-35.90,0.113
176.97,-35.83,0.113
176.99,-35.76,0.113
177.00,-35.70,0.113
177.01,-35.63,0.113
177.03,-35.56,0.113
177.04,-35.50,0.113
177.05,-35.43,0.113
177.07,-35.36,0.113
177.08,-35.29,0.113
177.09,-35.23,0.113
177.11,-35.16,0.113
177.12,-35.09,0.113
177.13,-35.03,0.113
177.15,-34.96,0.113
177.16,-34.89,0.113
177.17,-34.83,0.113
177.19,-34.76,0.113
177.20,-34.69,0.113
177.21,-34.63,0.114
177.23,-34.56,0.114
177.24,-34.49,0.114
177.25,-34.43,0.114
177.27,-34.36,0.114
177.28,-34.29,0.114
177.29,-34.23,0.114
177.31,-34.16,0.114
177.32,-34.09,0.114
177.33,-34.02,0.114
177.35,-33.96,0.114
177.36,-33.89,0.114
177.37,-33.83,0.114
177.39,-33.76,0.114
177.40,-33.69,0.114
177.41,-33.63,0.114
177.43,-33.56,0.114
177.44,-33.49,0.114
177.45,-33.43,0.114
177.47,-33.36,0.114
177.48,-33.29,0.114
177.49,-33.23,0.114
177.51,-33.16,0.114
177.52,-33.09,0.114
177.53,-33.03,0.114
177.55,-32.96,0.114
177.56,-32.89,0.114
177.57,-32.82,0.114
177.59,-32.76,0.114
177.60,-32.69,0.114
177.61,-32.63,0.114
177.63,-32.56,0.114
177.64,-32.49,0.114
177.65,-32.42,0.114
177.67,-32.36,0.114
177.68,-32.29,0.114
177.69,-32.22,0.114
177.71,-32.16,0.114
177.72,-32.09,0.114
177.73,-32.02,0.114
177.75,-31.96,0.114
177.76,-31.89,0.114
177.77,-31.82,0.114
177.79,-31.76,0.114
177.80,-31.69,0.114
177.81,-31.62,0.114
177.83,-31.56,0.115
177.84,-31.49,0.115
177.85,-31.42,0.115
177.87,-31.36,0.115
177.88,-31.29,0.115
177.89,-31.22,0.115
177.91,-31.16,0.115
177.92,-31.09,0.115
177.93,-31.02,0.115
177.95,-30.96,0.115
177.96,-30.89,0.115
177.97,-30.82,0.115
177.99,-30.76,0.115
178.00,-30.69,0.115
178.01,-30.62,0.115
178.03,-30.56,0.115
178.04,-30.49,0.115
178.05,-30.42,0.115
178.07,-30.36,0.115
178.08,-30.29,0.115
178.09,-30.22,0.115
178.11,-30.15,0.115
178.12,-30.09,0.115
178.13,-30.02,0.115
178.15,-29.95,0.115
178.16,-29.89,0.115
178.17,-29.82,0.115
178.19,-29.75,0.115
178.20,-29.69,0.115
178.21,-29.62,0.115
178.23,-29.55,0.115
178.24,-29.49,0.115
178.25,-29.42,0.115
178.27,-29.35,0.115
178.28,-29.29,0.115
178.29,-29.22,0.115
178.31,-29.15,0.115
178.32,-29.09,0.115
178.33,-29.02,0.115
178.35,-28.95,0.115
178.36,-28.89,0.115
178.37,-28.82,0.116
178.39,-28.75,0.116
178.40,-28.69,0.116
178.41,-28.62,0.116
178.43,-28.55,0.116
178.44,-28.49,0.116
178.45,-28.42,0.116
178.47,-28.35,0.116
178.48,-28.29,0.116
178.49,-28.22,0.116
178.51,-28.15,0.116
178.52,-28.09,0.116
178.53,-28.02,0.116
178.55,-27.95,0.116
178.56,-27.89,0.116
178.57,-27.82,0.116
178.59,-27.75,0.116
178.60,-27.69,0.116
178.61,-27.62,0.116
178.63,-27.55,0.116
178.64,-27.49,0.116
178.65,-27.42,0.116
178.67,-27.35,0.116
178.68,-27.29,0.116
178.69,-27.22,0.116
178.71,-27.15,0.116
178.72,-27.09,0.116
178.73,-27.02,0.116
178.75,-26.95,0.116
178.76,-26.89,0.117
178.77,-26.82,0.117
178.79,-26.75,0.117
178.80,-26.69,0.117
178.81,-26.62,0.117
178.83,-26.55,0.117
178.84,-26.49,0.117
178.85,-26.42,0.117
178.87,-26.35,0.117
178.88,-26.28,0.117
178.89,-26.22,0.117
178.91,-26.15,0.117
178.92,-26.08,0.117
178.93,-26.02,0.117
178.95,-25.95,0.117
178.96,-25.89,0.117
178.97,-25.82,0.117
178.99,-25.75,0.117
179.00,-25.69,0.117
179.01,-25.62,0.117
179.03,-25.55,0.117
179.04,-25.49,0.117
179.05,-25.42,0.118
179.07,-25.35,0.118
179.08,-25.29,0.118
179.09,-25.22,0.118
179.11,-25.15,0.118
179.12,-25.08,0.118
179.13,-25.02,0.118
179.15,-24.95,0.118
179.16,-24.89,0.118
179.17,-24.82,0.118
179.19,-24.75,0.118
179.20,-24.68,0.118
179.21,-24.62,0.118
179.23,-24.55,0.118
179.24,-24.48,0.119
179.25,-24.42,0.119
179.27,-24.35,0.119
179.28,-24.28,0.119
179.29,-24.22,0.119
179.31,-24.15,0.119
179.32,-24.08,0.119
179.33,-24.02,0.119
179.35,-23.95,0.119
179.36,-23.89,0.119
179.37,-23.82,0.119
179.39,-23.75,0.119
179.40,-23.68,0.119
179.41,-23.62,0.119
179.43,-23.55,0.120
179.44,-23.48,0.120
179.45,-23.42,0.120
179.47,-23.35,0.120
179.48,-23.28,0.120
179.49,-23.22,0.120
179.51,-23.15,0.120
179.52,-23.08,0.120
179.53,-23.02,0.120
179.55,-22.95,0.120
179.56,-22.88,0.120
179.57,-22.82,0.120
179.59,-22.75,0.121
179.60,-22.68,0.121
179.61,-22.62,0.121
179.63,-22.55,0.121
179.64,-22.48,0.121
179.65,-22.42,0.121
179.67,-22.35,0.121
179.68,-22.28,0.121
179.69,-22.22,0.121
179.71,-22.15,0.122
179.72,-22.08,0.122
179.73,-22.02,0.122
179.75,-21.95,0.122
179.76,-21.88,0.122
179.77,-21.82,0.122
179.79,-21.75,0.122
179.80,-21.68,0.122
179.81,-21.62,0.123
179.83,-21.55,0.123
179.84,-21.48,0.123
179.85,-21.42,0.123
179.87,-21.35,0.123
179.88,-21.28,0.123
179.89,-21.22,0.123
179.91,-21.15,0.123
179.92,-21.08,0.124
179.93,-21.02,0.124
179.95,-20.95,0.124
179.96,-20.88,0.124
179.97,-20.82,0.124
179.99,-20.75,0.124
180.00,-20.68,0.125
180.01,-20.62,0.125
180.03,-20.55,0.125
180.04,-20.48,0.125
180.05,-20.42,0.125
180.07,-20.35,0.125
180.08,-20.28,0.126
180.09,-20.22,0.126
180.11,-20.15,0.126
180.12,-20.08,0.126
180.13,-20.02,0.126
180.15,-19.95,0.127
180.16,-19.88,0.127
180.17,-19.82,0.127
180.19,-19.75,0.127
180.20,-19.69,0.127
180.21,-19.62,0.128
180.23,-19.55,0.128
180.24,-19.49,0.128
180.25,-19.42,0.128
180.27,-19.35,0.128
180.28,-19.29,0.129
180.29,-19.22,0.129
180.31,-19.15,0.129
180.32,-19.09,0.130
180.33,-19.02,0.130
180.35,-18.95,0.130
180.36,-18.89,0.130
180.37,-18.82,0.131
180.39,-18.75,0.131
180.40,-18.68,0.131
180.41,-18.62,0.131
180.43,-18.55,0.132
180.44,-18.49,0.132
180.45,-18.42,0.132
180.47,-18.35,0.133
180.48,-18.29,0.133
180.49,-18.22,0.133
180.51,-18.15,0.133
180.52,-18.09,0.134
180.53,-18.02,0.134
180.55,-17.95,0.134
180.56,-17.89,0.135
180.57,-17.82,0.135
180.59,-17.75,0.135
180.60,-17.69,0.135
180.61,-17.62,0.136
180.63,-17.55,0.136
180.64,-17.49,0.136
180.65,-17.42,0.137
180.67,-17.35,0.137
180.68,-17.29,0.137
180.69,-17.22,0.138
180.71,-17.15,0.139
180.72,-17.09,0.139
180.73,-17.02,0.139
180.75,-16.95,0.139
180.76,-16.89,0.140
180.77,-16.82,0.140
180.79,-16.75,0.140
180.80,-16.69,0.140
180.81,-16.62,0.141
180.83,-16.55,0.141
180.84,-16.49,0.141
180.85,-16.42,0.142
180.87,-16.36,0.142
180.88,-16.29,0.142
180.89,-16.22,0.143
180.91,-16.15,0.143
180.92,-16.09,0.143
180.93,-16.02,0.143
180.95,-15.96,0.143
180.96,-15.89,0.144
180.97,-15.82,0.144
180.99,-15.76,0.144
181.00,-15.69,0.144
181.01,-15.62,0.144
181.03,-15.56,0.145
181.04,-15.49,0.145
181.05,-15.42,0.145
181.07,-15.35,0.145
181.08,-15.29,0.145
181.09,-15.22,0.145
181.11,-15.15,0.146
181.12,-15.09,0.146
181.13,-15.02,0.146
181.15,-14.95,0.146
181.16,-14.89,0.146
181.17,-14.82,0.146
181.19,-14.75,0.146
181.20,-14.69,0.146
181.21,-14.62,0.147
181.23,-14.55,0.147
181.24,-14.49,0.147
181.25,-14.42,0.147
181.27,-14.35,0.147
181.28,-14.29,0.147
181.29,-14.22,0.147
181.31,-14.15,0.147
181.32,-14.09,0.147
181.33,-14.02,0.147
181.35,-13.95,0.147
181.36,-13.89,0.147
181.37,-13.82,0.147
181.39,-13.75,0.147
181.40,-13.69,0.147
181.41,-13.62,0.147
181.43,-13.55,0.147
181.44,-13.49,0.147
181.45,-13.42,0.146
181.47,-13.35,0.146
181.48,-13.29,0.146
181.49,-13.22,0.146
181.51,-13.15,0.146
181.52,-13.09,0.146
181.53,-13.02,0.146
181.55,-12.95,0.146
181.56,-12.89,0.146
181.57,-12.82,0.146
181.59,-12.75,0.146
181.60,-12.68,0.146
181.61,-12.62,0.146
181.63,-12.55,0.145
181.64,-12.49,0.145
181.65,-12.42,0.145
181.67,-12.35,0.145
181.68,-12.28,0.145
181.69,-12.22,0.145
181.71,-12.15,0.145
181.72,-12.08,0.145
181.73,-12.02,0.145
181.75,-11.95,0.145
181.76,-11.88,0.144
181.77,-11.82,0.144
181.79,-11.75,0.144
181.80,-11.68,0.144
181.81,-11.62,0.144
181.83,-11.55,0.144
181.84,-11.48,0.144
181.85,-11.42,0.144
181.87,-11.35,0.144
181.88,-11.28,0.144
181.89,-11.21,0.144
181.91,-11.15,0.144
181.92,-11.08,0.144
181.93,-11.02,0.143
181.95,-10.95,0.143
181.96,-10.88,0.143
181.97,-10.81,0.143
181.99,-10.75,0.143
182.00,-10.68,0.143
182.01,-10.61,0.143
182.03,-10.55,0.143
182.04,-10.48,0.143
182.05,-10.41,0.143
182.07,-10.35,0.143
182.08,-10.28,0.143
182.09,-10.22,0.143
182.11,-10.15,0.143
182.12,-10.08,0.143
182.13,-10.01,0.143
182.15,-9.95,0.143
182.16,-9.88,0.143
182.17,-9.81,0.143
182.19,-9.75,0.143
182.20,-9.68,0.143
182.21,-9.61,0.143
182.23,-9.54,0.143
182.24,-9.47,0.143
182.25,-9.41,0.143
182.27,-9.34,0.143
182.28,-9.27,0.143
182.29,-9.21,0.143
182.31,-9.14,0.143
182.32,-9.07,0.143
182.33,-9.01,0.143
182.35,-8.94,0.143
182.36,-8.87,0.143
182.37,-8.81,0.142
182.39,-8.74,0.142
182.40,-8.67,0.142
182.41,-8.61,0.142
182.43,-8.54,0.142
182.44,-8.47,0.142
182.45,-8.41,0.142
182.47,-8.34,0.142
182.48,-8.27,0.142
182.49,-8.21,0.142
182.51,-8.14,0.142
182.52,-8.07,0.142
182.53,-8.01,0.142
182.55,-7.94,0.142
182.56,-7.87,0.142
182.57,-7.81,0.142
182.59,-7.74,0.142
182.60,-7.67,0.142
182.61,-7.61,0.142
182.63,-7.54,0.142
182.64,-7.47,0.142
182.65,-7.41,0.142
182.67,-7.34,0.142
182.68,-7.27,0.142
182.69,-7.21,0.142
182.71,-7.14,0.142
182.72,-7.08,0.142
182.73,-7.01,0.142
182.75,-6.94,0.142
182.76,-6.87,0.142
182.77,-6.81,0.142
182.79,-6.74,0.142
182.80,-6.67,0.142
182.81,-6.61,0.142
182.83,-6.54,0.142
182.84,-6.48,0.142
182.85,-6.41,0.142
182.87,-6.34,0.142
182.88,-6.28,0.142
182.89,-6.21,0.142
182.91,-6.14,0.142
182.92,-6.07,0.142
182.93,-6.01,0.142
182.95,-5.94,0.142
182.96,-5.88,0.142
182.97,-5.81,0.142
182.99,-5.74,0.142
183.00,-5.68,0.142
183.01,-5.61,0.142
183.03,-5.54,0.142
183.04,-5.47,0.142
183.05,-5.41,0.142
183.07,-5.34,0.142
183.08,-5.28,0.142
183.09,-5.21,0.142
183.11,-5.14,0.142
183.12,-5.08,0.142
183.13,-5.01,0.142
183.15,-4.94,0.142
183.16,-4.87,0.142
183.17,-4.81,0.142
183.19,-4.74,0.142
183.20,-4.67,0.142
183.21,-4.61,0.142
183.23,-4.54,0.142
183.24,-4.47,0.142
183.25,-4.41,0.142
183.27,-4.34,0.142
183.28,-4.27,0.142
183.29,-4.21,0.142
183.31,-4.14,0.142
183.32,-4.07,0.142
183.33,-4.01,0.142
183.35,-3.94,0.142
183.36,-3.87,0.142
183.37,-3.81,0.142
183.39,-3.74,0.142
183.40,-3.67,0.142
183.41,-3.61,0.142
183.43,-3.54,0.142
183.44,-3.47,0.142
183.45,-3.41,0.142
183.47,-3.34,0.142
183.48,-3.27,0.142
183.49,-3.21,0.142
183.51,-3.14,0.142
183.52,-3.07,0.142
183.53,-3.01,0.142
183.55,-2.94,0.142
183.56,-2.87,0.142
183.57,-2.81,0.142
183.59,-2.74,0.142
183.60,-2.67,0.142
183.61,-2.61,0.143
183.63,-2.54,0.143
183.64,-2.47,0.143
183.65,-2.41,0.143
183.67,-2.34,0.143
183.68,-2.27,0.143
183.69,-2.21,0.143
183.71,-2.14,0.143
183.72,-2.07,0.143
183.73,-2.01,0.143
183.75,-1.94,0.143
183.76,-1.87,0.143
183.77,-1.80,0.143
183.79,-1.74,0.143
183.80,-1.67,0.143
183.81,-1.61,0.143
183.83,-1.54,0.143
183.84,-1.47,0.143
183.85,-1.41,0.143
183.87,-1.34,0.143
183.88,-1.27,0.143
183.89,-1.21,0.143
183.91,-1.14,0.143
183.92,-1.07,0.143
183.93,-1.00,0.143
183.95,-0.94,0.143
183.96,-0.87,0.143
183.97,-0.80,0.143
183.99,-0.74,0.143
184.00,-0.67,0.143
184.01,-0.60,0.143
184.03,-0.54,0.143
184.04,-0.47,0.143
184.05,-0.40,0.143
184.07,-0.34,0.143
184.08,-0.27,0.143
184.09,-0.20,0.143
184.11,-0.14,0.143
184.12,-0.07,0.143
184.13,0.00,0.143
184.15,0.07,0.143
184.16,0.13,0.143
184.17,0.20,0.143
184.19,0.26,0.143
184.20,0.33,0.143
184.21,0.40,0.143
184.23,0.46,0.143
184.24,0.53,0.143
184.25,0.60,0.143
184.27,0.66,0.143
184.28,0.73,0.143
184.29,0.80,0.143
184.31,0.87,0.143
184.32,0.93,0.143
184.33,1.00,0.143
184.35,1.06,0.143
184.36,1.13,0.143
184.37,1.20,0.143
184.39,1.26,0.143
184.40,1.33,0.143
184.41,1.40,0.143
184.43,1.47,0.143
184.44,1.53,0.143
184.45,1.60,0.143
184.47,1.67,0.143
184.48,1.73,0.143
184.49,1.80,0.143
184.51,1.86,0.143
184.52,1.93,0.143
184.53,2.00,0.143
184.55,2.06,0.143
184.56,2.13,0.143
184.57,2.20,0.143
184.59,2.26,0.143
184.60,2.33,0.143
184.61,2.40,0.143
184.63,2.46,0.143
184.64,2.53,0.143
184.65,2.60,0.143
184.67,2.66,0.143
184.68,2.73,0.144
184.69,2.80,0.143
184.71,2.86,0.143
184.72,2.93,0.144
184.73,3.00,0.144
184.75,3.06,0.144
184.76,3.13,0.144
184.77,3.20,0.144
184.79,3.27,0.144
184.80,3.33,0.144
184.81,3.40,0.144
184.83,3.47,0.144
184.84,3.53,0.144
184.85,3.60,0.144
184.87,3.67,0.144
184.88,3.73,0.144
184.89,3.80,0.144
184.91,3.87,0.144
184.92,3.93,0.144
184.93,4.00,0.144
184.95,4.07,0.144
184.96,4.13,0.144
184.97,4.20,0.144
184.99,4.27,0.144
185.00,4.33,0.144
185.01,4.40,0.144
185.03,4.47,0.144
185.04,4.53,0.144
185.05,4.60,0.144
185.07,4.67,0.144
185.08,4.73,0.144
185.09,4.80,0.144
185.11,4.87,0.144
185.12,4.93,0.144
185.13,5.00,0.144
185.15,5.07,0.144
185.16,5.13,0.144
185.17,5.20,0.144
185.19,5.27,0.144
185.20,5.33,0.144
185.21,5.40,0.144
185.23,5.47,0.144
185.24,5.53,0.144
185.25,5.60,0.144
185.27,5.67,0.144
185.28,5.73,0.144
185.29,5.80,0.144
185.31,5.87,0.144
185.32,5.93,0.144
185.33,6.00,0.144
185.35,6.07,0.144
185.36,6.13,0.144
185.37,6.20,0.144
185.39,6.27,0.144
185.40,6.34,0.144
185.41,6.40,0.144
185.43,6.47,0.144
185.44,6.54,0.144
185.45,6.60,0.144
185.47,6.67,0.144
185.48,6.73,0.144
185.49,6.80,0.144
185.51,6.87,0.144
185.52,6.93,0.144
185.53,7.00,0.144
185.55,7.07,0.144
185.56,7.14,0.144
185.57,7.20,0.144
185.59,7.27,0.144
185.60,7.33,0.144
185.61,7.40,0.144
185.63,7.47,0.144
185.64,7.53,0.144
185.65,7.60,0.144
185.67,7.67,0.144
185.68,7.73,0.144
185.69,7.80,0.144
185.71,7.87,0.144
185.72,7.93,0.145
185.73,8.00,0.145
185.75,8.07,0.145
185.76,8.13,0.145
185.77,8.20,0.145
185.79,8.27,0.145
185.80,8.34,0.145
185.81,8.40,0.145
185.83,8.47,0.145
185.84,8.54,0.145
185.85,8.60,0.145
185.87,8.67,0.145
185.88,8.74,0.145
185.89,8.80,0.145
185.91,8.87,0.145
185.92,8.94,0.145
185.93,9.00,0.145
185.95,9.07,0.145
185.96,9.14,0.145
185.97,9.21,0.145
185.99,9.27,0.145
186.00,9.34,0.145
186.01,9.40,0.145
186.03,9.47,0.145
186.04,9.54,0.145
186.05,9.61,0.145
186.07,9.67,0.145
186.08,9.74,0.145
186.09,9.81,0.145
186.11,9.87,0.145
186.12,9.94,0.145
186.13,10.00,0.145
186.15,10.07,0.145
186.16,10.14,0.145
186.17,10.21,0.145
186.19,10.27,0.145
186.20,10.34,0.145
186.21,10.41,0.145
186.23,10.47,0.145
186.24,10.54,0.145
186.25,10.61,0.145
186.27,10.67,0.145
186.28,10.74,0.145
186.29,10.81,0.145
186.31,10.87,0.145
186.32,10.94,0.145
186.33,11.01,0.145
186.35,11.07,0.145
186.36,11.14,0.145
186.37,11.21,0.145
186.39,11.27,0.145
186.40,11.34,0.145
186.41,11.41,0.145
186.43,11.47,0.145
186.44,11.54,0.145
186.45,11.61,0.145
186.47,11.67,0.145
186.48,11.74,0.145
186.49,11.81,0.145
186.51,11.87,0.145
186.52,11.94,0.145
186.53,12.01,0.145
186.55,12.07,0.145
186.56,12.14,0.145
186.57,12.21,0.145
186.59,12.27,0.145
186.60,12.34,0.145
186.61,12.41,0.145
186.63,12.48,0.145
186.64,12.54,0.145
186.65,12.61,0.145
186.67,12.67,0.145
186.68,12.74,0.145
186.69,12.81,0.145
186.71,12.87,0.145
186.72,12.94,0.145
186.73,13.01,0.145
186.75,13.07,0.145
186.76,13.14,0.145
186.77,13.21,0.145
186.79,13.27,0.145
186.80,13.34,0.145
186.81,13.41,0.145
186.83,13.47,0.145
186.84,13.54,0.145
186.85,13.61,0.145
186.87,13.67,0.145
186.88,13.74,0.145
186.89,13.81,0.145
186.91,13.87,0.145
186.92,13.94,0.145
186.93,14.01,0.145
186.95,14.07,0.145
186.96,14.14,0.145
186.97,14.21,0.145
186.99,14.28,0.145
187.00,14.34,0.145
187.01,14.41,0.145
187.03,14.47,0.145
187.04,14.54,0.145
187.05,14.61,0.145
187.07,14.67,0.145
187.08,14.74,0.145
187.09,14.81,0.145
187.11,14.87,0.145
187.12,14.94,0.145
187.13,15.01,0.145
187.15,15.07,0.145
187.16,15.14,0.145
187.17,15.21,0.145
187.19,15.28,0.145
187.20,15.34,0.145
187.21,15.41,0.145
187.23,15.48,0.145
187.24,15.54,0.145
187.25,15.61,0.145
187.27,15.68,0.145
187.28,15.74,0.145
187.29,15.81,0.145
187.31,15.88,0.145
187.32,15.94,0.145
187.33,16.01,0.145
187.35,16.08,0.145
187.36,16.14,0.145
187.37,16.21,0.145
187.39,16.28,0.145
187.40,16.34,0.145
187.41,16.41,0.145
187.43,16.48,0.145
187.44,16.54,0.145
187.45,16.61,0.145
187.47,16.68,0.145
187.48,16.74,0.145
187.49,16.81,0.145
187.51,16.88,0.145
187.52,16.94,0.145
187.53,17.01,0.145
187.55,17.08,0.145
187.56,17.15,0.145
187.57,17.21,0.145
187.59,17.28,0.145
187.60,17.35,0.145
187.61,17.41,0.145
187.63,17.48,0.145
187.64,17.55,0.145
187.65,17.61,0.145
187.67,17.68,0.145
187.68,17.75,0.145
187.69,17.81,0.145
187.71,17.88,0.145
187.72,17.94,0.145
187.73,18.01,0.145
187.75,18.08,0.145
187.76,18.15,0.145
187.77,18.21,0.145
187.79,18.28,0.145
187.80,18.35,0.145
187.81,18.41,0.145
187.83,18.48,0.146
187.84,18.54,0.146
187.85,18.61,0.145
187.87,18.68,0.146
187.88,18.75,0.146
187.89,18.81,0.146
187.91,18.88,0.146
187.92,18.95,0.146
187.93,19.01,0.146
187.95,19.08,0.146
187.96,19.15,0.146
187.97,19.21,0.146
187.99,19.28,0.146
188.00,19.35,0.146
188.01,19.41,0.145
188.03,19.48,0.145
188.04,19.55,0.146
188.05,19.61,0.145
188.07,19.68,0.145
188.08,19.75,0.145
188.09,19.81,0.145
188.11,19.88,0.145
188.12,19.95,0.146
188.13,20.01,0.146
188.15,20.08,0.146
188.16,20.15,0.146
188.17,20.21,0.146
188.19,20.28,0.146
188.20,20.35,0.146
188.21,20.41,0.146
188.23,20.48,0.146
188.24,20.55,0.146
188.25,20.61,0.146
188.27,20.68,0.146
188.28,20.75,0.146
188.29,20.81,0.146
188.31,20.88,0.146
188.32,20.95,0.146
188.33,21.01,0.146
188.35,21.08,0.146
188.36,21.15,0.146
188.37,21.22,0.146
188.39,21.28,0.146
188.40,21.35,0.146
188.41,21.42,0.146
188.43,21.48,0.146
188.44,21.55,0.146
188.45,21.61,0.146
188.47,21.68,0.146
188.48,21.75,0.146
188.49,21.82,0.146
188.51,21.88,0.146
188.52,21.95,0.146
188.53,22.02,0.146
188.55,22.08,0.146
188.56,22.15,0.146
188.57,22.22,0.146
188.59,22.28,0.146
188.60,22.35,0.146
188.61,22.42,0.146
188.63,22.48,0.146
188.64,22.55,0.146
188.65,22.62,0.146
188.67,22.68,0.146
188.68,22.75,0.146
188.69,22.82,0.146
188.71,22.88,0.146
188.72,22.95,0.146
188.73,23.02,0.146
188.75,23.08,0.146
188.76,23.15,0.146
188.77,23.22,0.146
188.79,23.28,0.146
188.80,23.35,0.146
188.81,23.42,0.146
188.83,23.48,0.146
188.84,23.55,0.146
188.85,23.62,0.146
188.87,23.68,0.146
188.88,23.75,0.146
188.89,23.82,0.146
188.91,23.88,0.146
188.92,23.95,0.146
188.93,24.02,0.146
188.95,24.08,0.146
188.96,24.15,0.146
188.97,24.22,0.146
188.99,24.28,0.146
189.00,24.35,0.146
189.01,24.42,0.146
189.03,24.48,0.146
189.04,24.55,0.146
189.05,24.62,0.146
189.07,24.68,0.146
189.08,24.75,0.146
189.09,24.82,0.147
189.11,24.89,0.147
189.12,24.95,0.147
189.13,25.02,0.147
189.15,25.08,0.147
189.16,25.15,0.147
189.17,25.22,0.147
189.19,25.28,0.147
189.20,25.35,0.147
189.21,25.42,0.147
189.23,25.49,0.147
189.24,25.55,0.147
189.25,25.62,0.147
189.27,25.69,0.147
189.28,25.75,0.147
189.29,25.82,0.147
189.31,25.89,0.147
189.32,25.95,0.147
189.33,26.02,0.147
189.35,26.09,0.147
189.36,26.15,0.147
189.37,26.22,0.147
189.39,26.28,0.147
189.40,26.35,0.147
189.41,26.42,0.147
189.43,26.48,0.147
189.44,26.55,0.147
189.45,26.62,0.147
189.47,26.69,0.147
189.48,26.75,0.148
189.49,26.82,0.148
189.51,26.89,0.148
189.52,26.95,0.148
189.53,27.02,0.148
189.55,27.09,0.148
189.56,27.15,0.148
189.57,27.22,0.148
189.59,27.29,0.148
189.60,27.35,0.148
189.61,27.42,0.148
189.63,27.49,0.148
189.64,27.55,0.148
189.65,27.62,0.148
189.67,27.69,0.148
189.68,27.75,0.148
189.69,27.82,0.148
189.71,27.89,0.148
189.72,27.95,0.148
189.73,28.02,0.149
189.75,28.09,0.149
189.76,28.15,0.149
189.77,28.22,0.149
189.79,28.29,0.149
189.80,28.35,0.149
189.81,28.42,0.149
189.83,28.49,0.149
189.84,28.55,0.149
189.85,28.62,0.149
189.87,28.68,0.149
189.88,28.75,0.149
189.89,28.82,0.149
189.91,28.89,0.149
189.92,28.95,0.149
189.93,29.02,
189.95,29.09,
189.96,29.15,
189.97,29.22,
189.98,,