File: DSC/2025_04_24_CBG_Isonicotinamide_MC_n60C_180C_5Cmin_x3.csv
Filename,2025_04_24_CBG_Isonicotinamide_MC_n60C_180C_5Cmin_x3
Instrument name,DSC2A-00468 (192.168.1.100)
Operator,Yarger
rundate,4/24/2025
Sample name,2025_04_24_CBG_Isonicotinamide_MC_n60C_180C_5Cmin_x3
proceduresegments,Data Off ; Equilibrate -60.00 °C; Data On ; Ramp 5.00 °C/min to 180.00 °C; Data Off ; Isothermal 1.0 min; Data On ; Ramp 5.00 °C/min to -60.00 °C; Data Off ; Isothermal 1.0 min; Data On ; Ramp 5.00 °C/min to 180.00 °C; Data Off ; Isothermal 1.0 min; Data On ; Ramp 5.00 °C/min to -60.00 °C; Data Off ; Isothermal 1.0 min; Data On ; Ramp 5.00 °C/min to 180.00 °C
[File Parameters]
Run date,4/24/2025 9:42:49 AM
Trios version,5.1.1.46572
Original File Name,
Current File Name,D:\DSC2500\JYarger\2025_04_24_CBG_Isonicotinamide_MC_n60C_180C_5Cmin_x3.tri
[Procedure]
Procedure Name,CBG_INA_n60_180C_5Cmin_x3
Sample Name,2025_04_24_CBG_Isonicotinamide_MC_n60C_180C_5Cmin_x3
Sample Mass,5.52 mg
Reference Sample Mass,0 mg
Pan Mass,52.86 mg
Pan Number,38
Reference Pan Mass,52.66 mg
Reference Pan Number,19
Pan Type,Tzero Aluminum Hermetic
Comments,Al Hermetic DSC Consumables sealed Pan/Lid.
Project Name,CA
Operator,Yarger
Test,Custom
Unload Max Temperature,30
Unload Min Temperature,30
Load Max Temperature,30
Load Min Temperature,30
Stop on Gas Flow Error,Yes
[Signal List]
Signal #1,Time (min)
Signal #2,Temperature (°C)
Signal #3,Heat Flow (mW)
Signal #4,Delta T (µV)
Signal #5,Delta Tzero (µV)
Signal #6,Tzero Temperature (°C)
Signal #7,Cell Purge (mL/min)
Signal #8,Heater Temp (°C)
Signal #9,Power Delivered (W)
Signal #10,Reference Junction Temperature (°C)
Signal #11,Flange Temperature (°C)
Signal #12,Heat Flow Phase (rad)
Signal #13,Total Heat Capacity (J/°C)
Signal #14,Heat Capacity (J/°C)
[Configuration]
Company Name,ASU
Instrument Name,DSC2A-00468
Instrument Type,DSC2500
Serial Number,DSC2A-00468
IP,192.168.1.100
Location of Instrument,MRRC
DisplayType,Unknown
Sample Interval ,0.1 s/pt
Selected Heat Flow,T4P
Exotherm Direction,Down
Cell Serial,DRC2-00792
Lid Type,Standard
Cooler,RCS 90
Leave Cooler on at End of Sequence,On
Gas 2,Nitrogen
Gas Selected,Channel 1
Flow Rate,50 mL/min
Secondary Purge,On
Licensed Heat Flow,Heat Flow T4P
Modulation Licensed,Yes
[Versions]
Common IDD Version,1
Cortex Version,VER 2.10.2.31
Driver,5.0.0.6
GDM Version,1.0.3.3
TouchscreenVersion,1.0.0.16145
FEP Version,1.2.1.21
FEP Bootloader,2.0.0.5
AutoSampler Version,2.1.1.26
Auto Sampler Bootloader,2.0.0.5
FCM Version,1.1.0.3
FCM Bootloader,2.0.0.5
[Experiment Logs]
Experiment Log Entry # 1,Data On set to 0
Experiment Log Entry # 3,Equilibrate Segment -60 (C) Started
Experiment Log Entry # 5,Air Cool is off.
Experiment Log Entry # 7,Data On set to 1
Experiment Log Entry # 9,Ramp Segment 5 C/min to 180 Started
Experiment Log Entry # 11,Data On set to 0
Experiment Log Entry # 13,Isothermal Segment 1 min started
Experiment Log Entry # 15,Data On set to 1
Experiment Log Entry # 17,Ramp Segment 5 C/min to -60 Started
Experiment Log Entry # 19,Data On set to 0
Experiment Log Entry # 21,Isothermal Segment 1 min started
Experiment Log Entry # 23,Data On set to 1
Experiment Log Entry # 25,Ramp Segment 5 C/min to 180 Started
Experiment Log Entry # 27,Auto sampler has detected that FEP has gone offline
Experiment Log Entry # 29,Data On set to 0
Experiment Log Entry # 31,Isothermal Segment 1 min started
Experiment Log Entry # 33,Data On set to 1
Experiment Log Entry # 35,Ramp Segment 5 C/min to -60 Started
Experiment Log Entry # 37,Data On set to 0
Experiment Log Entry # 39,Isothermal Segment 1 min started
Experiment Log Entry # 41,Data On set to 1
Experiment Log Entry # 43,Ramp Segment 5 C/min to 180 Started
[Method Log]
Method Log Entry # 1,Data Off
Method Log Entry # 2,Equilibrate -60 °C
Method Log Entry # 3,Data On
Method Log Entry # 4,(Ramp 261249) Ramp 5 °C/minute to 180 °C
Method Log Entry # 5,Data Off
Method Log Entry # 6,Isothermal 1 minutes
Method Log Entry # 7,Data On
Method Log Entry # 8,(Ramp 261253) Ramp 5 °C/minute to -60 °C
Method Log Entry # 9,Data Off
Method Log Entry # 10,Isothermal 1 minutes
Method Log Entry # 11,Data On
Method Log Entry # 12,(Ramp 261257) Ramp 5 °C/minute to 180 °C
Method Log Entry # 13,Data Off
Method Log Entry # 14,Isothermal 1 minutes
Method Log Entry # 15,Data On
Method Log Entry # 16,(Ramp 261261) Ramp 5 °C/minute to -60 °C
Method Log Entry # 17,Data Off
Method Log Entry # 18,Isothermal 1 minutes
Method Log Entry # 19,Data On
Method Log Entry # 20,(Ramp 261265) Ramp 5 °C/minute to 180 °C
Cell Serial,DRC2-00792
[T1 Calibration]
Slope,-0.008529666
Offset,9.636258
Initial Temperature,98.23
GUID,f8bfdadc-4977-4fdf-ba6d-0ba9134940c3
[TZero Calibration]
Date Applied,11/29/2022 4:06:13 PM
Description,From -89.059 °C to 396.009 °C at 20.000°C/min
Gas Type,Nitrogen
Pan Type,None
Source Files 1,C:\Users\yargerlab\Desktop\DSC Data\General\TZero_calibration_11_29_22_2nd(2).tri
Source Files 2,C:\Users\yargerlab\Desktop\DSC Data\General\TZero_calibration_11_29_22_2nd(3).tri
Delta T Offset,13.05235
Delta T Slope,-0.007271007
Delta T0 Offset,-13.69128
Delta T0 Slope,0.06063341
[Temperature Calibration]
Date Applied,11/29/2022 7:12:28 PM
Description,From 106.590 °C to 186.590 °C at 10.000°C/min
Gas Type,Nitrogen
Pan Type,Tzero Aluminum Hermetic
Source Files 1,C:\Users\yargerlab\Desktop\DSC Data\General\Indium(6).tri
Measured 1,157.391
Known 1,156.598
[Cell Constant Calibration]
Date Applied,11/29/2022 7:12:29 PM
Description,From 106.590 °C to 186.590 °C at 10.000°C/min
Gas Type,Nitrogen
Pan Type,Tzero Aluminum Hermetic
Source Files 1,C:\Users\yargerlab\Desktop\DSC Data\General\Indium(6).tri
T4P KCell,1.006051
Onset Slope,63.26126 mW/°C
[Direct Cp Calibration]
Date Applied,11/30/2022 11:04:51 AM
Description,From -79.983 °C to 298.409 °C at 10.000°C/min
Gas Type,Nitrogen
Pan Type,Tzero Aluminum Hermetic
Source Files 1,C:\Users\yargerlab\Desktop\DSC Data\General\Sapphire_Heat_Capacity_11_30_22.tri
[Rev Cp Calibration]
Date Applied,11/30/2022 1:58:51 PM
Description,From -79.996 °C to 292.812 °C at 3.000°C/min
Gas Type,Nitrogen
Pan Type,Tzero Aluminum Hermetic
Source Files 1,C:\Users\yargerlab\Desktop\DSC Data\General\Sapphire_MDSC_Calibration_11_30_22.tri
[step]
Ramp 5.00 °C/min to 180.00 °C
Time,Temperature,Heat Flow (Normalized)
min,°C,W/g
0.00,-59.66,-0.091
0.03,-59.68,-0.086
0.07,-59.68,-0.085
0.10,-59.64,-0.106
0.13,-59.55,-0.114
0.17,-59.44,-0.100
0.20,-59.32,-0.067
0.23,-59.19,-0.038
0.27,-59.06,-0.015
0.30,-58.91,0.001
0.33,-58.77,0.015
0.37,-58.62,0.027
0.40,-58.47,0.037
0.43,-58.32,0.044
0.47,-58.16,0.050
0.50,-58.00,0.055
0.53,-57.84,0.058
0.57,-57.69,0.061
0.60,-57.53,0.063
0.63,-57.37,0.065
0.67,-57.20,0.066
0.70,-57.04,0.068
0.73,-56.88,0.069
0.77,-56.72,0.070
0.80,-56.55,0.070
0.83,-56.39,0.071
0.87,-56.23,0.072
0.90,-56.06,0.072
0.93,-55.90,0.073
0.97,-55.74,0.073
1.00,-55.57,0.074
1.03,-55.41,0.074
1.07,-55.24,0.075
1.10,-55.08,0.075
1.13,-54.91,0.076
1.17,-54.75,0.076
1.20,-54.58,0.077
1.23,-54.41,0.077
1.27,-54.25,0.077
1.30,-54.08,0.077
1.33,-53.92,0.078
1.37,-53.75,0.078
1.40,-53.59,0.078
1.43,-53.42,0.078
1.47,-53.26,0.078
1.50,-53.09,0.079
1.53,-52.93,0.079
1.57,-52.76,0.079
1.60,-52.59,0.079
1.63,-52.43,0.079
1.67,-52.26,0.079
1.70,-52.09,0.079
1.73,-51.93,0.079
1.77,-51.76,0.079
1.80,-51.60,0.080
1.83,-51.43,0.080
1.87,-51.26,0.080
1.90,-51.10,0.080
1.93,-50.93,0.080
1.97,-50.77,0.080
2.00,-50.60,0.080
2.03,-50.43,0.080
2.07,-50.27,0.080
2.10,-50.10,0.080
2.13,-49.93,0.080
2.17,-49.77,0.080
2.20,-49.60,0.080
2.23,-49.43,0.080
2.27,-49.27,0.080
2.30,-49.10,0.080
2.33,-48.93,0.080
2.37,-48.77,0.080
2.40,-48.60,0.080
2.43,-48.43,0.080
2.47,-48.27,0.080
2.50,-48.10,0.080
2.53,-47.94,0.080
2.57,-47.77,0.080
2.60,-47.60,0.080
2.63,-47.44,0.080
2.67,-47.27,0.080
2.70,-47.10,0.080
2.73,-46.94,0.080
2.77,-46.77,0.080
2.80,-46.60,0.080
2.83,-46.44,0.080
2.87,-46.27,0.080
2.90,-46.10,0.080
2.93,-45.94,0.080
2.97,-45.77,0.080
3.00,-45.60,0.080
3.03,-45.44,0.080
3.07,-45.27,0.080
3.10,-45.10,0.080
3.13,-44.94,0.080
3.17,-44.77,0.080
3.20,-44.60,0.080
3.23,-44.44,0.080
3.27,-44.27,0.080
3.30,-44.11,0.080
3.33,-43.94,0.080
3.37,-43.77,0.080
3.40,-43.61,0.080
3.43,-43.44,0.080
3.47,-43.27,0.080
3.50,-43.11,0.080
3.53,-42.94,0.080
3.57,-42.77,0.080
3.60,-42.60,0.080
3.63,-42.44,0.080
3.67,-42.27,0.080
3.70,-42.11,0.080
3.73,-41.94,0.080
3.77,-41.77,0.081
3.80,-41.61,0.080
3.83,-41.44,0.081
3.87,-41.27,0.080
3.90,-41.10,0.080
3.93,-40.94,0.080
3.97,-40.77,0.080
4.00,-40.60,0.080
4.03,-40.44,0.081
4.07,-40.27,0.081
4.10,-40.10,0.081
4.13,-39.94,0.081
4.17,-39.77,0.081
4.20,-39.60,0.081
4.23,-39.44,0.081
4.27,-39.27,0.081
4.30,-39.10,0.081
4.33,-38.93,0.081
4.37,-38.77,0.081
4.40,-38.60,0.081
4.43,-38.43,0.081
4.47,-38.27,0.081
4.50,-38.10,0.081
4.53,-37.93,0.081
4.57,-37.77,0.081
4.60,-37.60,0.081
4.63,-37.43,0.081
4.67,-37.27,0.081
4.70,-37.10,0.081
4.73,-36.93,0.081
4.77,-36.76,0.081
4.80,-36.60,0.081
4.83,-36.43,0.081
4.87,-36.26,0.081
4.90,-36.10,0.081
4.93,-35.93,0.081
4.97,-35.76,0.081
5.00,-35.60,0.081
5.03,-35.43,0.081
5.07,-35.27,0.081
5.10,-35.10,0.081
5.13,-34.93,0.081
5.17,-34.76,0.081
5.20,-34.60,0.081
5.23,-34.43,0.081
5.27,-34.26,0.081
5.30,-34.10,0.081
5.33,-33.93,0.081
5.37,-33.76,0.081
5.40,-33.60,0.081
5.43,-33.43,0.081
5.47,-33.26,0.081
5.50,-33.09,0.081
5.53,-32.93,0.082
5.57,-32.76,0.082
5.60,-32.59,0.082
5.63,-32.43,0.082
5.67,-32.26,0.082
5.70,-32.09,0.082
5.73,-31.93,0.082
5.77,-31.76,0.082
5.80,-31.60,0.082
5.83,-31.43,0.082
5.87,-31.27,0.082
5.90,-31.10,0.082
5.93,-30.93,0.082
5.97,-30.76,0.082
6.00,-30.60,0.082
6.03,-30.43,0.082
6.07,-30.26,0.082
6.10,-30.09,0.082
6.13,-29.93,0.082
6.17,-29.76,0.082
6.20,-29.59,0.082
6.23,-29.43,0.082
6.27,-29.26,0.082
6.30,-29.09,0.082
6.33,-28.93,0.082
6.37,-28.76,0.082
6.40,-28.59,0.082
6.43,-28.43,0.082
6.47,-28.26,0.083
6.50,-28.09,0.083
6.53,-27.92,0.083
6.57,-27.76,0.083
6.60,-27.59,0.083
6.63,-27.42,0.083
6.67,-27.26,0.083
6.70,-27.09,0.083
6.73,-26.92,0.083
6.77,-26.76,0.083
6.80,-26.59,0.083
6.83,-26.42,0.083
6.87,-26.25,0.083
6.90,-26.09,0.083
6.93,-25.92,0.083
6.97,-25.76,0.083
7.00,-25.59,0.083
7.03,-25.42,0.083
7.07,-25.25,0.083
7.10,-25.09,0.083
7.13,-24.92,0.084
7.17,-24.76,0.084
7.20,-24.59,0.084
7.23,-24.42,0.084
7.27,-24.25,0.084
7.30,-24.09,0.084
7.33,-23.92,0.084
7.37,-23.75,0.084
7.40,-23.59,0.084
7.43,-23.42,0.084
7.47,-23.25,0.084
7.50,-23.09,0.084
7.53,-22.92,0.084
7.57,-22.75,0.084
7.60,-22.59,0.084
7.63,-22.42,0.084
7.67,-22.25,0.084
7.70,-22.09,0.084
7.73,-21.92,0.084
7.77,-21.75,0.085
7.80,-21.58,0.085
7.83,-21.42,0.085
7.87,-21.25,0.085
7.90,-21.08,0.085
7.93,-20.92,0.085
7.97,-20.75,0.085
8.00,-20.58,0.085
8.03,-20.42,0.085
8.07,-20.25,0.085
8.10,-20.08,0.085
8.13,-19.92,0.085
8.17,-19.75,0.085
8.20,-19.58,0.085
8.23,-19.42,0.086
8.27,-19.25,0.086
8.30,-19.08,0.086
8.33,-18.92,0.086
8.37,-18.75,0.086
8.40,-18.58,0.086
8.43,-18.42,0.086
8.47,-18.25,0.086
8.50,-18.08,0.086
8.53,-17.92,0.086
8.57,-17.75,0.086
8.60,-17.58,0.086
8.63,-17.42,0.086
8.67,-17.25,0.086
8.70,-17.08,0.086
8.73,-16.92,0.086
8.77,-16.75,0.086
8.80,-16.58,0.086
8.83,-16.41,0.086
8.87,-16.25,0.086
8.90,-16.08,0.086
8.93,-15.91,0.086
8.97,-15.75,0.086
9.00,-15.58,0.086
9.03,-15.41,0.086
9.07,-15.25,0.086
9.10,-15.08,0.086
9.13,-14.91,0.086
9.17,-14.75,0.086
9.20,-14.58,0.086
9.23,-14.41,0.087
9.27,-14.25,0.087
9.30,-14.08,0.087
9.33,-13.91,0.087
9.37,-13.75,0.087
9.40,-13.58,0.087
9.43,-13.41,0.087
9.47,-13.25,0.087
9.50,-13.08,0.087
9.53,-12.91,0.087
9.57,-12.75,0.087
9.60,-12.58,0.087
9.63,-12.41,0.087
9.67,-12.24,0.087
9.70,-12.08,0.087
9.73,-11.91,0.087
9.77,-11.75,0.087
9.80,-11.58,0.087
9.83,-11.41,0.087
9.87,-11.24,0.087
9.90,-11.08,0.088
9.93,-10.91,0.088
9.97,-10.74,0.088
10.00,-10.58,0.088
10.03,-10.41,0.088
10.07,-10.24,0.088
10.10,-10.08,0.088
10.13,-9.91,0.088
10.17,-9.74,0.088
10.20,-9.58,0.088
10.23,-9.41,0.088
10.27,-9.24,0.088
10.30,-9.08,0.088
10.33,-8.91,0.088
10.37,-8.74,0.088
10.40,-8.57,0.088
10.43,-8.41,0.088
10.47,-8.24,0.088
10.50,-8.07,0.088
10.53,-7.91,0.088
10.57,-7.74,0.088
10.60,-7.57,0.088
10.63,-7.41,0.088
10.67,-7.24,0.088
10.70,-7.07,0.089
10.73,-6.91,0.089
10.77,-6.74,0.089
10.80,-6.57,0.089
10.83,-6.41,0.089
10.87,-6.24,0.089
10.90,-6.07,0.089
10.93,-5.91,0.089
10.97,-5.74,0.089
11.00,-5.57,0.089
11.03,-5.41,0.089
11.07,-5.24,0.089
11.10,-5.07,0.089
11.13,-4.91,0.089
11.17,-4.74,0.089
11.20,-4.57,0.089
11.23,-4.41,0.089
11.27,-4.24,0.089
11.30,-4.07,0.089
11.33,-3.91,0.090
11.37,-3.74,0.090
11.40,-3.57,0.090
11.43,-3.41,0.090
11.47,-3.24,0.090
11.50,-3.07,0.090
11.53,-2.91,0.090
11.57,-2.74,0.090
11.60,-2.57,0.090
11.63,-2.41,0.090
11.67,-2.24,0.090
11.70,-2.07,0.090
11.73,-1.90,0.090
11.77,-1.74,0.090
11.80,-1.57,0.090
11.83,-1.40,0.090
11.87,-1.24,0.090
11.90,-1.07,0.090
11.93,-0.90,0.091
11.97,-0.74,0.091
12.00,-0.57,0.091
12.03,-0.40,0.091
12.07,-0.24,0.091
12.10,-0.07,0.091
12.13,0.10,0.091
12.17,0.26,0.091
12.20,0.43,0.091
12.23,0.60,0.091
12.27,0.76,0.091
12.30,0.93,0.091
12.33,1.10,0.091
12.37,1.27,0.091
12.40,1.43,0.091
12.43,1.60,0.091
12.47,1.77,0.091
12.50,1.93,0.091
12.53,2.10,0.091
12.57,2.27,0.091
12.60,2.43,0.091
12.63,2.60,0.091
12.67,2.77,0.091
12.70,2.93,0.091
12.73,3.10,0.091
12.77,3.27,0.091
12.80,3.44,0.091
12.83,3.60,0.091
12.87,3.77,0.092
12.90,3.94,0.092
12.93,4.10,0.092
12.97,4.27,0.092
13.00,4.44,0.092
13.03,4.60,0.092
13.07,4.77,0.092
13.10,4.94,0.092
13.13,5.10,0.092
13.17,5.27,0.092
13.20,5.44,0.092
13.23,5.60,0.092
13.27,5.77,0.092
13.30,5.94,0.092
13.33,6.10,0.092
13.37,6.27,0.092
13.40,6.44,0.092
13.43,6.60,0.092
13.47,6.77,0.092
13.50,6.94,0.092
13.53,7.10,0.092
13.57,7.27,0.093
13.60,7.44,0.093
13.63,7.60,0.093
13.67,7.77,0.093
13.70,7.94,0.093
13.73,8.10,0.093
13.77,8.27,0.093
13.80,8.44,0.093
13.83,8.60,0.093
13.87,8.77,0.093
13.90,8.94,0.093
13.93,9.10,0.093
13.97,9.27,0.093
14.00,9.44,0.093
14.03,9.61,0.093
14.07,9.77,0.093
14.10,9.94,0.093
14.13,10.11,0.093
14.17,10.27,0.093
14.20,10.44,0.093
14.23,10.60,0.093
14.27,10.77,0.093
14.30,10.94,0.093
14.33,11.11,0.094
14.37,11.27,0.094
14.40,11.44,0.094
14.43,11.61,0.094
14.47,11.77,0.094
14.50,11.94,0.094
14.53,12.11,0.094
14.57,12.27,0.094
14.60,12.44,0.094
14.63,12.61,0.094
14.67,12.77,0.094
14.70,12.94,0.094
14.73,13.11,0.094
14.77,13.27,0.094
14.80,13.44,0.094
14.83,13.61,0.094
14.87,13.77,0.094
14.90,13.94,0.094
14.93,14.11,0.095
14.97,14.27,0.095
15.00,14.44,0.095
15.03,14.61,0.095
15.07,14.77,0.095
15.10,14.94,0.095
15.13,15.11,0.095
15.17,15.27,0.095
15.20,15.44,0.095
15.23,15.61,0.095
15.27,15.77,0.095
15.30,15.94,0.096
15.33,16.11,0.096
15.37,16.28,0.096
15.40,16.44,0.096
15.43,16.61,0.096
15.47,16.77,0.096
15.50,16.94,0.096
15.53,17.11,0.096
15.57,17.28,0.096
15.60,17.44,0.096
15.63,17.61,0.097
15.67,17.78,0.097
15.70,17.94,0.097
15.73,18.11,0.097
15.77,18.28,0.097
15.80,18.44,0.097
15.83,18.61,0.097
15.87,18.78,0.097
15.90,18.94,0.097
15.93,19.11,0.097
15.97,19.28,0.097
16.00,19.44,0.097
16.03,19.61,0.097
16.07,19.78,0.098
16.10,19.94,0.098
16.13,20.11,0.098
16.17,20.28,0.098
16.20,20.44,0.098
16.23,20.61,0.098
16.27,20.78,0.098
16.30,20.94,0.098
16.33,21.11,0.099
16.37,21.28,0.099
16.40,21.44,0.099
16.43,21.61,0.099
16.47,21.78,0.099
16.50,21.94,0.099
16.53,22.11,0.099
16.57,22.28,0.100
16.60,22.45,0.100
16.63,22.61,0.100
16.67,22.78,0.100
16.70,22.95,0.100
16.73,23.11,0.101
16.77,23.28,0.101
16.80,23.45,0.101
16.83,23.61,0.101
16.87,23.78,0.101
16.90,23.95,0.101
16.93,24.11,0.102
16.97,24.28,0.102
17.00,24.45,0.102
17.03,24.61,0.102
17.07,24.78,0.102
17.10,24.95,0.103
17.13,25.11,0.103
17.17,25.28,0.103
17.20,25.45,0.103
17.23,25.61,0.103
17.27,25.78,0.104
17.30,25.95,0.104
17.33,26.11,0.104
17.37,26.28,0.104
17.40,26.45,0.104
17.43,26.61,0.105
17.47,26.78,0.105
17.50,26.95,0.105
17.53,27.11,0.105
17.57,27.28,0.105
17.60,27.45,0.106
17.63,27.61,0.106
17.67,27.78,0.106
17.70,27.95,0.106
17.73,28.11,0.106
17.77,28.28,0.107
17.80,28.45,0.107
17.83,28.61,0.107
17.87,28.78,0.107
17.90,28.95,0.107
17.93,29.11,0.108
17.97,29.28,0.108
18.00,29.45,0.108
18.03,29.61,0.108
18.07,29.78,0.108
18.10,29.95,0.109
18.13,30.11,0.109
18.17,30.28,0.109
18.20,30.45,0.109
18.23,30.61,0.109
18.27,30.78,0.110
18.30,30.94,0.110
18.33,31.11,0.110
18.37,31.28,0.111
18.40,31.45,0.111
18.43,31.61,0.111
18.47,31.78,0.112
18.50,31.95,0.112
18.53,32.11,0.113
18.57,32.28,0.113
18.60,32.45,0.114
18.63,32.61,0.115
18.67,32.78,0.115
18.70,32.94,0.116
18.73,33.11,0.117
18.77,33.28,0.118
18.80,33.44,0.119
18.83,33.61,0.119
18.87,33.78,0.121
18.90,33.94,0.122
18.93,34.11,0.123
18.97,34.27,0.124
19.00,34.44,0.126
19.03,34.61,0.127
19.07,34.77,0.129
19.10,34.94,0.133
19.13,35.10,0.135
19.17,35.27,0.138
19.20,35.44,0.140
19.23,35.60,0.146
19.27,35.77,0.149
19.30,35.93,0.152
19.33,36.10,0.156
19.37,36.26,0.160
19.40,36.43,0.166
19.43,36.59,0.172
19.47,36.76,0.177
19.50,36.92,0.184
19.53,37.09,0.191
19.57,37.25,0.197
19.60,37.42,0.207
19.63,37.58,0.216
19.67,37.74,0.225
19.70,37.91,0.235
19.73,38.07,0.245
19.77,38.23,0.257
19.80,38.39,0.270
19.83,38.56,0.281
19.87,38.72,0.295
19.90,38.88,0.308
19.93,39.04,0.321
19.97,39.20,0.333
20.00,39.36,0.346
20.03,39.53,0.361
20.07,39.69,0.373
20.10,39.85,0.387
20.13,40.01,0.399
20.17,40.17,0.413
20.20,40.34,0.425
20.23,40.50,0.438
20.27,40.66,0.449
20.30,40.82,0.461
20.33,40.98,0.473
20.37,41.14,0.485
20.40,41.31,0.497
20.43,41.47,0.507
20.47,41.63,0.519
20.50,41.79,0.532
20.53,41.95,0.543
20.57,42.12,0.556
20.60,42.28,0.569
20.63,42.44,0.581
20.67,42.60,0.594
20.70,42.76,0.607
20.73,42.93,0.623
20.77,43.09,0.640
20.80,43.25,0.656
20.83,43.41,0.672
20.87,43.57,0.689
20.90,43.73,0.710
20.93,43.89,0.733
20.97,44.05,0.755
21.00,44.21,0.778
21.03,44.36,0.810
21.07,44.52,0.831
21.10,44.67,0.854
21.13,44.83,0.893
21.17,44.98,0.932
21.20,45.14,0.963
21.23,45.29,0.991
21.27,45.45,1.013
21.30,45.61,1.030
21.33,45.76,1.046
21.37,45.92,1.052
21.40,46.09,1.058
21.43,46.25,1.062
21.47,46.41,1.064
21.50,46.58,1.071
21.53,46.75,1.062
21.57,46.91,1.059
21.60,47.08,1.051
21.63,47.25,1.049
21.67,47.42,1.040
21.70,47.59,1.037
21.73,47.76,1.014
21.77,47.94,0.971
21.80,48.12,0.892
21.83,48.31,0.788
21.87,48.51,0.692
21.90,48.71,0.603
21.93,48.92,0.524
21.97,49.11,0.454
22.00,49.31,0.396
22.03,49.50,0.344
22.07,49.69,0.302
22.10,49.88,0.268
22.13,50.06,0.241
22.17,50.24,0.221
22.20,50.41,0.205
22.23,50.59,0.194
22.27,50.76,0.187
22.30,50.93,0.179
22.33,51.10,0.175
22.37,51.27,0.172
22.40,51.44,0.170
22.43,51.61,0.168
22.47,51.77,0.167
22.50,51.94,0.166
22.53,52.11,0.165
22.57,52.27,0.164
22.60,52.44,0.164
22.63,52.61,0.163
22.67,52.78,0.163
22.70,52.94,0.162
22.73,53.11,0.162
22.77,53.28,0.161
22.80,53.45,0.161
22.83,53.61,0.161
22.87,53.78,0.160
22.90,53.95,0.160
22.93,54.11,0.160
22.97,54.28,0.160
23.00,54.45,0.159
23.03,54.61,0.159
23.07,54.78,0.159
23.10,54.95,0.159
23.13,55.11,0.159
23.17,55.28,0.159
23.20,55.45,0.159
23.23,55.61,0.159
23.27,55.78,0.159
23.30,55.95,0.159
23.33,56.11,0.159
23.37,56.28,0.158
23.40,56.45,0.158
23.43,56.61,0.158
23.47,56.78,0.158
23.50,56.95,0.158
23.53,57.11,0.158
23.57,57.28,0.158
23.60,57.45,0.158
23.63,57.62,0.158
23.67,57.78,0.158
23.70,57.95,0.158
23.73,58.12,0.159
23.77,58.28,0.159
23.80,58.45,0.159
23.83,58.62,0.159
23.87,58.78,0.158
23.90,58.95,0.158
23.93,59.12,0.158
23.97,59.28,0.158
24.00,59.45,0.158
24.03,59.62,0.158
24.07,59.78,0.158
24.10,59.95,0.158
24.13,60.12,0.158
24.17,60.28,0.158
24.20,60.45,0.158
24.23,60.62,0.158
24.27,60.78,0.158
24.30,60.95,0.159
24.33,61.12,0.159
24.37,61.28,0.159
24.40,61.45,0.159
24.43,61.62,0.159
24.47,61.78,0.159
24.50,61.95,0.159
24.53,62.12,0.159
24.57,62.28,0.159
24.60,62.45,0.159
24.63,62.62,0.159
24.67,62.78,0.159
24.70,62.95,0.159
24.73,63.12,0.159
24.77,63.28,0.159
24.80,63.45,0.159
24.83,63.62,0.160
24.87,63.78,0.160
24.90,63.95,0.160
24.93,64.12,0.160
24.97,64.28,0.160
25.00,64.45,0.160
25.03,64.62,0.160
25.07,64.78,0.160
25.10,64.95,0.160
25.13,65.12,0.160
25.17,65.29,0.160
25.20,65.45,0.161
25.23,65.62,0.161
25.27,65.78,0.161
25.30,65.95,0.161
25.33,66.12,0.161
25.37,66.29,0.161
25.40,66.45,0.161
25.43,66.62,0.161
25.47,66.79,0.161
25.50,66.95,0.161
25.53,67.12,0.161
25.57,67.29,0.161
25.60,67.45,0.161
25.63,67.62,0.161
25.67,67.79,0.161
25.70,67.95,0.161
25.73,68.12,0.161
25.77,68.29,0.161
25.80,68.45,0.162
25.83,68.62,0.162
25.87,68.79,0.162
25.90,68.95,0.162
25.93,69.12,0.162
25.97,69.29,0.162
26.00,69.45,0.162
26.03,69.62,0.162
26.07,69.79,0.162
26.10,69.96,0.162
26.13,70.12,0.163
26.17,70.29,0.163
26.20,70.45,0.163
26.23,70.62,0.163
26.27,70.79,0.163
26.30,70.95,0.163
26.33,71.12,0.163
26.37,71.29,0.163
26.40,71.46,0.163
26.43,71.62,0.163
26.47,71.79,0.163
26.50,71.96,0.163
26.53,72.12,0.164
26.57,72.29,0.164
26.60,72.45,0.164
26.63,72.62,0.164
26.67,72.79,0.164
26.70,72.96,0.164
26.73,73.12,0.164
26.77,73.29,0.164
26.80,73.46,0.164
26.83,73.62,0.164
26.87,73.79,0.164
26.90,73.96,0.164
26.93,74.12,0.164
26.97,74.29,0.165
27.00,74.46,0.165
27.03,74.62,0.165
27.07,74.79,0.165
27.10,74.96,0.165
27.13,75.12,0.165
27.17,75.29,0.165
27.20,75.45,0.165
27.23,75.62,0.165
27.27,75.79,0.165
27.30,75.96,0.165
27.33,76.12,0.165
27.37,76.29,0.166
27.40,76.46,0.166
27.43,76.62,0.166
27.47,76.79,0.166
27.50,76.96,0.166
27.53,77.12,0.166
27.57,77.29,0.166
27.60,77.46,0.167
27.63,77.62,0.167
27.67,77.79,0.167
27.70,77.96,0.167
27.73,78.12,0.167
27.77,78.29,0.167
27.80,78.46,0.167
27.83,78.62,0.167
27.87,78.79,0.168
27.90,78.96,0.168
27.93,79.12,0.168
27.97,79.29,0.168
28.00,79.46,0.168
28.03,79.62,0.168
28.07,79.79,0.168
28.10,79.96,0.168
28.13,80.12,0.168
28.17,80.29,0.169
28.20,80.46,0.169
28.23,80.63,0.169
28.27,80.79,0.169
28.30,80.96,0.169
28.33,81.12,0.169
28.37,81.29,0.169
28.40,81.46,0.169
28.43,81.63,0.169
28.47,81.79,0.170
28.50,81.96,0.170
28.53,82.12,0.170
28.57,82.29,0.170
28.60,82.46,0.170
28.63,82.63,0.170
28.67,82.79,0.171
28.70,82.96,0.171
28.73,83.12,0.171
28.77,83.29,0.171
28.80,83.46,0.171
28.83,83.63,0.171
28.87,83.79,0.171
28.90,83.96,0.171
28.93,84.13,0.172
28.97,84.29,0.172
29.00,84.46,0.172
29.03,84.63,0.172
29.07,84.79,0.172
29.10,84.96,0.172
29.13,85.13,0.172
29.17,85.29,0.173
29.20,85.46,0.173
29.23,85.63,0.173
29.27,85.80,0.173
29.30,85.96,0.173
29.33,86.13,0.173
29.37,86.29,0.173
29.40,86.46,0.173
29.43,86.63,0.173
29.47,86.79,0.173
29.50,86.96,0.173
29.53,87.13,0.174
29.57,87.29,0.174
29.60,87.46,0.174
29.63,87.63,0.174
29.67,87.79,0.174
29.70,87.96,0.174
29.73,88.13,0.174
29.77,88.29,0.175
29.80,88.46,0.175
29.83,88.63,0.175
29.87,88.80,0.175
29.90,88.96,0.176
29.93,89.13,0.176
29.97,89.30,0.176
30.00,89.46,0.176
30.03,89.63,0.176
30.07,89.79,0.177
30.10,89.96,0.177
30.13,90.13,0.177
30.17,90.29,0.177
30.20,90.46,0.177
30.23,90.63,0.177
30.27,90.79,0.177
30.30,90.96,0.178
30.33,91.13,0.178
30.37,91.29,0.178
30.40,91.46,0.178
30.43,91.63,0.179
30.47,91.79,0.179
30.50,91.96,0.179
30.53,92.13,0.179
30.57,92.29,0.179
30.60,92.46,0.180
30.63,92.63,0.180
30.67,92.79,0.180
30.70,92.96,0.180
30.73,93.13,0.180
30.77,93.29,0.181
30.80,93.46,0.181
30.83,93.63,0.181
30.87,93.79,0.182
30.90,93.96,0.182
30.93,94.13,0.182
30.97,94.29,0.182
31.00,94.46,0.182
31.03,94.63,0.183
31.07,94.79,0.183
31.10,94.96,0.183
31.13,95.13,0.183
31.17,95.29,0.183
31.20,95.46,0.184
31.23,95.63,0.184
31.27,95.80,0.184
31.30,95.96,0.185
31.33,96.13,0.185
31.37,96.30,0.185
31.40,96.46,0.185
31.43,96.63,0.185
31.47,96.80,0.186
31.50,96.96,0.186
31.53,97.13,0.186
31.57,97.29,0.186
31.60,97.46,0.186
31.63,97.63,0.187
31.67,97.80,0.187
31.70,97.96,0.187
31.73,98.13,0.187
31.77,98.30,0.188
31.80,98.46,0.188
31.83,98.63,0.188
31.87,98.80,0.188
31.90,98.96,0.188
31.93,99.13,0.189
31.97,99.29,0.189
32.00,99.46,0.189
32.03,99.63,0.189
32.07,99.79,0.190
32.10,99.96,0.190
32.13,100.13,0.190
32.17,100.30,0.190
32.20,100.46,0.191
32.23,100.63,0.191
32.27,100.79,0.191
32.30,100.96,0.191
32.33,101.13,0.192
32.37,101.30,0.192
32.40,101.46,0.192
32.43,101.63,0.192
32.47,101.79,0.193
32.50,101.96,0.193
32.53,102.13,0.193
32.57,102.30,0.193
32.60,102.46,0.194
32.63,102.63,0.194
32.67,102.79,0.194
32.70,102.96,0.194
32.73,103.13,0.195
32.77,103.30,0.195
32.80,103.46,0.195
32.83,103.63,0.195
32.87,103.79,0.196
32.90,103.96,0.196
32.93,104.13,0.196
32.97,104.29,0.196
33.00,104.46,0.197
33.03,104.63,0.197
33.07,104.79,0.197
33.10,104.96,0.197
33.13,105.13,0.198
33.17,105.29,0.198
33.20,105.46,0.198
33.23,105.63,0.198
33.27,105.79,0.199
33.30,105.96,0.199
33.33,106.13,0.199
33.37,106.29,0.199
33.40,106.46,0.200
33.43,106.63,0.200
33.47,106.79,0.200
33.50,106.96,0.200
33.53,107.13,0.200
33.57,107.29,0.201
33.60,107.46,0.201
33.63,107.63,0.201
33.67,107.79,0.201
33.70,107.96,0.201
33.73,108.13,0.202
33.77,108.29,0.202
33.80,108.46,0.202
33.83,108.63,0.203
33.87,108.79,0.203
33.90,108.96,0.203
33.93,109.13,0.203
33.97,109.29,0.203
34.00,109.46,0.203
34.03,109.63,0.203
34.07,109.79,0.203
34.10,109.96,0.203
34.13,110.13,0.203
34.17,110.29,0.204
34.20,110.46,0.204
34.23,110.63,0.204
34.27,110.79,0.204
34.30,110.96,0.204
34.33,111.13,0.204
34.37,111.30,0.204
34.40,111.46,0.204
34.43,111.63,0.204
34.47,111.80,0.204
34.50,111.96,0.203
34.53,112.13,0.203
34.57,112.30,0.203
34.60,112.46,0.203
34.63,112.63,0.202
34.67,112.80,0.201
34.70,112.96,0.201
34.73,113.13,0.200
34.77,113.30,0.199
34.80,113.47,0.199
34.83,113.63,0.198
34.87,113.80,0.198
34.90,113.97,0.197
34.93,114.13,0.196
34.97,114.30,0.196
35.00,114.47,0.195
35.03,114.64,0.195
35.07,114.80,0.195
35.10,114.97,0.195
35.13,115.14,0.195
35.17,115.30,0.196
35.20,115.47,0.196
35.23,115.63,0.196
35.27,115.80,0.196
35.30,115.97,0.197
35.33,116.13,0.197
35.37,116.30,0.197
35.40,116.47,0.198
35.43,116.63,0.198
35.47,116.80,0.199
35.50,116.97,0.200
35.53,117.13,0.200
35.57,117.30,0.201
35.60,117.47,0.201
35.63,117.63,0.202
35.67,117.80,0.202
35.70,117.96,0.203
35.73,118.13,0.203
35.77,118.30,0.204
35.80,118.47,0.204
35.83,118.63,0.205
35.87,118.80,0.205
35.90,118.96,0.205
35.93,119.13,0.206
35.97,119.30,0.206
36.00,119.47,0.207
36.03,119.63,0.207
36.07,119.80,0.207
36.10,119.96,0.208
36.13,120.13,0.208
36.17,120.30,0.208
36.20,120.46,0.209
36.23,120.63,0.209
36.27,120.80,0.209
36.30,120.96,0.210
36.33,121.13,0.210
36.37,121.30,0.210
36.40,121.46,0.210
36.43,121.63,0.211
36.47,121.80,0.211
36.50,121.96,0.211
36.53,122.13,0.211
36.57,122.30,0.211
36.60,122.46,0.211
36.63,122.63,0.212
36.67,122.80,0.212
36.70,122.96,0.212
36.73,123.13,0.212
36.77,123.30,0.212
36.80,123.46,0.213
36.83,123.63,0.213
36.87,123.80,0.213
36.90,123.96,0.213
36.93,124.13,0.213
36.97,124.30,0.213
37.00,124.46,0.214
37.03,124.63,0.214
37.07,124.80,0.214
37.10,124.97,0.214
37.13,125.13,0.214
37.17,125.30,0.215
37.20,125.46,0.215
37.23,125.63,0.215
37.27,125.80,0.215
37.30,125.97,0.215
37.33,126.13,0.216
37.37,126.30,0.216
37.40,126.47,0.216
37.43,126.63,0.216
37.47,126.80,0.216
37.50,126.97,0.216
37.53,127.13,0.216
37.57,127.30,0.216
37.60,127.47,0.215
37.63,127.63,0.215
37.67,127.80,0.215
37.70,127.97,0.214
37.73,128.13,0.214
37.77,128.30,0.214
37.80,128.47,0.213
37.83,128.63,0.213
37.87,128.80,0.213
37.90,128.97,0.212
37.93,129.14,0.212
37.97,129.30,0.211
38.00,129.47,0.211
38.03,129.64,0.211
38.07,129.80,0.210
38.10,129.97,0.209
38.13,130.14,0.209
38.17,130.31,0.208
38.20,130.47,0.208
38.23,130.64,0.207
38.27,130.80,0.207
38.30,130.97,0.206
38.33,131.14,0.206
38.37,131.30,0.205
38.40,131.47,0.204
38.43,131.64,0.204
38.47,131.81,0.203
38.50,131.97,0.202
38.53,132.14,0.202
38.57,132.31,0.201
38.60,132.47,0.201
38.63,132.64,0.200
38.67,132.81,0.199
38.70,132.98,0.198
38.73,133.14,0.198
38.77,133.31,0.197
38.80,133.48,0.196
38.83,133.64,0.195
38.87,133.81,0.194
38.90,133.98,0.193
38.93,134.14,0.192
38.97,134.31,0.192
39.00,134.48,0.191
39.03,134.65,0.190
39.07,134.81,0.189
39.10,134.98,0.188
39.13,135.15,0.187
39.17,135.31,0.186
39.20,135.48,0.185
39.23,135.65,0.185
39.27,135.82,0.184
39.30,135.98,0.183
39.33,136.15,0.182
39.37,136.32,0.181
39.40,136.48,0.180
39.43,136.65,0.179
39.47,136.82,0.179
39.50,136.98,0.178
39.53,137.15,0.177
39.57,137.32,0.176
39.60,137.49,0.175
39.63,137.65,0.175
39.67,137.82,0.174
39.70,137.99,0.173
39.73,138.15,0.173
39.77,138.32,0.172
39.80,138.49,0.171
39.83,138.65,0.171
39.87,138.82,0.171
39.90,138.99,0.170
39.93,139.15,0.170
39.97,139.32,0.169
40.00,139.49,0.169
40.03,139.65,0.168
40.07,139.82,0.168
40.10,139.99,0.168
40.13,140.16,0.168
40.17,140.32,0.167
40.20,140.49,0.167
40.23,140.66,0.167
40.27,140.82,0.166
40.30,140.99,0.166
40.33,141.16,0.166
40.37,141.32,0.166
40.40,141.49,0.165
40.43,141.66,0.165
40.47,141.82,0.165
40.50,141.99,0.164
40.53,142.16,0.164
40.57,142.32,0.164
40.60,142.49,0.164
40.63,142.66,0.163
40.67,142.82,0.163
40.70,142.99,0.163
40.73,143.16,0.163
40.77,143.32,0.163
40.80,143.49,0.162
40.83,143.66,0.162
40.87,143.82,0.162
40.90,143.99,0.162
40.93,144.16,0.161
40.97,144.32,0.161
41.00,144.49,0.161
41.03,144.66,0.161
41.07,144.83,0.161
41.10,144.99,0.160
41.13,145.16,0.160
41.17,145.33,0.160
41.20,145.49,0.160
41.23,145.66,0.159
41.27,145.83,0.159
41.30,145.99,0.159
41.33,146.16,0.159
41.37,146.33,0.159
41.40,146.49,0.158
41.43,146.66,0.158
41.47,146.83,0.158
41.50,146.99,0.158
41.53,147.16,0.158
41.57,147.33,0.158
41.60,147.49,0.157
41.63,147.66,0.157
41.67,147.83,0.157
41.70,148.00,0.157
41.73,148.16,0.157
41.77,148.33,0.157
41.80,148.49,0.157
41.83,148.66,0.156
41.87,148.83,0.156
41.90,148.99,0.156
41.93,149.16,0.156
41.97,149.33,0.156
42.00,149.49,0.155
42.03,149.66,0.155
42.07,149.83,0.155
42.10,150.00,0.155
42.13,150.16,0.155
42.17,150.33,0.155
42.20,150.50,0.155
42.23,150.66,0.155
42.27,150.83,0.155
42.30,150.99,0.155
42.33,151.16,0.155
42.37,151.33,0.155
42.40,151.50,0.155
42.43,151.66,0.155
42.47,151.83,0.155
42.50,151.99,0.155
42.53,152.16,0.155
42.57,152.33,0.155
42.60,152.49,0.155
42.63,152.66,0.155
42.67,152.83,0.155
42.70,152.99,0.155
42.73,153.16,0.155
42.77,153.33,0.155
42.80,153.50,0.155
42.83,153.66,0.155
42.87,153.83,0.155
42.90,154.00,0.155
42.93,154.16,0.155
42.97,154.33,0.155
43.00,154.50,0.156
43.03,154.66,0.156
43.07,154.83,0.155
43.10,155.00,0.155
43.13,155.16,0.156
43.17,155.33,0.156
43.20,155.50,0.156
43.23,155.66,0.156
43.27,155.83,0.156
43.30,156.00,0.156
43.33,156.16,0.156
43.37,156.33,0.156
43.40,156.50,0.156
43.43,156.66,0.156
43.47,156.83,0.156
43.50,157.00,0.156
43.53,157.16,0.157
43.57,157.33,0.157
43.60,157.50,0.157
43.63,157.66,0.157
43.67,157.83,0.157
43.70,158.00,0.157
43.73,158.16,0.157
43.77,158.33,0.157
43.80,158.50,0.157
43.83,158.66,0.157
43.87,158.83,0.157
43.90,159.00,0.157
43.93,159.16,0.157
43.97,159.33,0.158
44.00,159.50,0.158
44.03,159.66,0.158
44.07,159.83,0.158
44.10,160.00,0.158
44.13,160.16,0.158
44.17,160.33,0.158
44.20,160.50,0.158
44.23,160.66,0.158
44.27,160.83,0.158
44.30,161.00,0.159
44.33,161.16,0.159
44.37,161.33,0.159
44.40,161.50,0.159
44.43,161.66,0.159
44.47,161.83,0.159
44.50,162.00,0.159
44.53,162.16,0.159
44.57,162.33,0.159
44.60,162.50,0.159
44.63,162.66,0.160
44.67,162.83,0.160
44.70,163.00,0.160
44.73,163.16,0.160
44.77,163.33,0.160
44.80,163.50,0.160
44.83,163.66,0.160
44.87,163.83,0.160
44.90,164.00,0.161
44.93,164.16,0.161
44.97,164.33,0.161
45.00,164.50,0.161
45.03,164.66,0.161
45.07,164.83,0.161
45.10,165.00,0.161
45.13,165.16,0.161
45.17,165.33,0.161
45.20,165.50,0.162
45.23,165.66,0.162
45.27,165.83,0.162
45.30,166.00,0.162
45.33,166.16,0.162
45.37,166.33,0.162
45.40,166.50,0.162
45.43,166.66,0.162
45.47,166.83,0.162
45.50,167.00,0.162
45.53,167.16,0.162
45.57,167.33,0.163
45.60,167.50,0.163
45.63,167.66,0.163
45.67,167.83,0.163
45.70,168.00,0.163
45.73,168.17,0.163
45.77,168.33,0.163
45.80,168.50,0.164
45.83,168.66,0.164
45.87,168.83,0.164
45.90,169.00,0.164
45.93,169.16,0.164
45.97,169.33,0.164
46.00,169.50,0.164
46.03,169.66,0.164
46.07,169.83,0.164
46.10,170.00,0.164
46.13,170.16,0.165
46.17,170.33,0.165
46.20,170.50,0.165
46.23,170.66,0.165
46.27,170.83,0.165
46.30,171.00,0.165
46.33,171.16,0.165
46.37,171.33,0.166
46.40,171.50,0.166
46.43,171.66,0.166
46.47,171.83,0.166
46.50,172.00,0.166
46.53,172.16,0.166
46.57,172.33,0.166
46.60,172.50,0.166
46.63,172.66,0.166
46.67,172.83,0.167
46.70,173.00,0.167
46.73,173.16,0.167
46.77,173.33,0.167
46.80,173.50,0.167
46.83,173.66,0.167
46.87,173.83,0.167
46.90,174.00,0.167
46.93,174.16,0.167
46.97,174.33,0.168
47.00,174.50,0.168
47.03,174.66,0.168
47.07,174.83,0.168
47.10,175.00,0.168
47.13,175.16,0.168
47.17,175.33,0.168
47.20,175.50,0.168
47.23,175.66,0.169
47.27,175.83,0.169
47.30,176.00,0.169
47.33,176.16,0.169
47.37,176.33,0.169
47.40,176.50,0.169
47.43,176.66,0.170
47.47,176.83,0.170
47.50,177.00,0.170
47.53,177.16,0.170
47.57,177.33,0.170
47.60,177.50,0.170
47.63,177.66,0.170
47.67,177.83,0.171
47.70,178.00,0.171
47.73,178.16,0.171
47.77,178.33,0.171
47.80,178.50,0.171
47.83,178.66,0.172
47.87,178.83,0.172
47.90,179.00,0.172
47.93,179.16,
47.97,179.33,
47.99,,

[step]
Ramp 5.00 °C/min to -60.00 °C
Time,Temperature,Heat Flow (Normalized)
min,°C,W/g
48.99,180.11,-0.043
49.02,180.11,-0.043
49.05,180.10,-0.028
49.09,180.06,-0.010
49.12,179.98,-0.020
49.15,179.87,-0.073
49.19,179.75,-0.125
49.22,179.62,-0.164
49.25,179.47,-0.191
49.29,179.32,-0.210
49.32,179.17,-0.220
49.35,179.02,-0.231
49.39,178.86,-0.236
49.42,178.70,-0.239
49.45,178.53,-0.244
49.49,178.37,-0.246
49.52,178.21,-0.248
49.55,178.05,-0.249
49.59,177.88,-0.250
49.62,177.72,-0.251
49.65,177.55,-0.251
49.69,177.39,-0.252
49.72,177.23,-0.252
49.75,177.06,-0.252
49.79,176.89,-0.253
49.82,176.73,-0.253
49.85,176.57,-0.253
49.89,176.40,-0.254
49.92,176.23,-0.254
49.95,176.07,-0.254
49.99,175.90,-0.254
50.02,175.74,-0.254
50.05,175.57,-0.254
50.09,175.41,-0.254
50.12,175.24,-0.254
50.15,175.07,-0.254
50.19,174.91,-0.254
50.22,174.74,-0.255
50.25,174.58,-0.255
50.29,174.41,-0.255
50.32,174.24,-0.255
50.35,174.08,-0.255
50.39,173.91,-0.255
50.42,173.74,-0.255
50.45,173.58,-0.254
50.49,173.41,-0.254
50.52,173.24,-0.254
50.55,173.08,-0.254
50.59,172.91,-0.254
50.62,172.75,-0.254
50.65,172.58,-0.254
50.69,172.41,-0.253
50.72,172.25,-0.253
50.75,172.08,-0.253
50.79,171.91,-0.253
50.82,171.75,-0.253
50.85,171.58,-0.253
50.89,171.41,-0.253
50.92,171.25,-0.253
50.95,171.08,-0.252
50.99,170.91,-0.252
51.02,170.75,-0.252
51.05,170.58,-0.252
51.09,170.41,-0.252
51.12,170.25,-0.252
51.15,170.08,-0.252
51.19,169.92,-0.252
51.22,169.75,-0.251
51.25,169.58,-0.251
51.29,169.42,-0.251
51.32,169.25,-0.251
51.35,169.08,-0.251
51.39,168.92,-0.251
51.42,168.75,-0.251
51.45,168.58,-0.251
51.49,168.42,-0.250
51.52,168.25,-0.250
51.55,168.08,-0.250
51.59,167.92,-0.250
51.62,167.75,-0.250
51.65,167.58,-0.250
51.69,167.42,-0.250
51.72,167.25,-0.249
51.75,167.08,-0.249
51.79,166.92,-0.249
51.82,166.75,-0.249
51.85,166.58,-0.249
51.89,166.42,-0.249
51.92,166.25,-0.249
51.95,166.08,-0.249
51.99,165.92,-0.249
52.02,165.75,-0.248
52.05,165.58,-0.248
52.09,165.42,-0.248
52.12,165.25,-0.248
52.15,165.09,-0.248
52.19,164.92,-0.248
52.22,164.75,-0.248
52.25,164.59,-0.248
52.29,164.42,-0.247
52.32,164.25,-0.247
52.35,164.09,-0.247
52.39,163.92,-0.248
52.42,163.75,-0.248
52.45,163.59,-0.247
52.49,163.42,-0.247
52.52,163.25,-0.247
52.55,163.09,-0.247
52.59,162.92,-0.247
52.62,162.75,-0.247
52.65,162.59,-0.247
52.69,162.42,-0.247
52.72,162.26,-0.247
52.75,162.09,-0.246
52.79,161.92,-0.246
52.82,161.75,-0.246
52.85,161.59,-0.246
52.89,161.42,-0.246
52.92,161.26,-0.246
52.95,161.09,-0.246
52.99,160.92,-0.246
53.02,160.75,-0.246
53.05,160.59,-0.246
53.09,160.42,-0.246
53.12,160.26,-0.246
53.15,160.09,-0.246
53.19,159.92,-0.246
53.22,159.76,-0.246
53.25,159.59,-0.246
53.29,159.42,-0.246
53.32,159.26,-0.246
53.35,159.09,-0.246
53.39,158.92,-0.246
53.42,158.76,-0.246
53.45,158.59,-0.246
53.49,158.42,-0.246
53.52,158.26,-0.246
53.55,158.09,-0.245
53.59,157.92,-0.245
53.62,157.76,-0.245
53.65,157.59,-0.245
53.69,157.42,-0.245
53.72,157.26,-0.245
53.75,157.09,-0.245
53.79,156.93,-0.245
53.82,156.76,-0.245
53.85,156.59,-0.245
53.89,156.43,-0.245
53.92,156.26,-0.245
53.95,156.09,-0.245
53.99,155.93,-0.245
54.02,155.76,-0.245
54.05,155.59,-0.245
54.09,155.43,-0.244
54.12,155.26,-0.244
54.15,155.09,-0.244
54.19,154.93,-0.245
54.22,154.76,-0.245
54.25,154.59,-0.245
54.29,154.43,-0.244
54.32,154.26,-0.244
54.35,154.09,-0.244
54.39,153.93,-0.244
54.42,153.76,-0.244
54.45,153.59,-0.244
54.49,153.43,-0.244
54.52,153.26,-0.244
54.55,153.09,-0.244
54.59,152.93,-0.244
54.62,152.76,-0.244
54.65,152.59,-0.244
54.69,152.43,-0.244
54.72,152.26,-0.244
54.75,152.09,-0.244
54.79,151.93,-0.243
54.82,151.76,-0.244
54.85,151.60,-0.244
54.89,151.43,-0.243
54.92,151.26,-0.244
54.95,151.10,-0.244
54.99,150.93,-0.243
55.02,150.76,-0.243
55.05,150.59,-0.243
55.09,150.43,-0.243
55.12,150.26,-0.243
55.15,150.10,-0.243
55.19,149.93,-0.243
55.22,149.76,-0.243
55.25,149.60,-0.243
55.29,149.43,-0.243
55.32,149.26,-0.243
55.35,149.10,-0.243
55.39,148.93,-0.243
55.42,148.76,-0.243
55.45,148.60,-0.243
55.49,148.43,-0.243
55.52,148.26,-0.243
55.55,148.10,-0.243
55.59,147.93,-0.243
55.62,147.76,-0.243
55.65,147.60,-0.243
55.69,147.43,-0.243
55.72,147.26,-0.242
55.75,147.10,-0.242
55.79,146.93,-0.242
55.82,146.76,-0.242
55.85,146.60,-0.242
55.89,146.43,-0.242
55.92,146.26,-0.242
55.95,146.10,-0.242
55.99,145.93,-0.242
56.02,145.76,-0.242
56.05,145.60,-0.242
56.09,145.43,-0.242
56.12,145.26,-0.242
56.15,145.10,-0.242
56.19,144.93,-0.242
56.22,144.76,-0.242
56.25,144.60,-0.242
56.29,144.43,-0.242
56.32,144.27,-0.242
56.35,144.10,-0.241
56.39,143.93,-0.241
56.42,143.77,-0.241
56.45,143.60,-0.241
56.49,143.43,-0.241
56.52,143.27,-0.241
56.55,143.10,-0.241
56.59,142.93,-0.241
56.62,142.77,-0.241
56.65,142.60,-0.241
56.69,142.43,-0.242
56.72,142.27,-0.241
56.75,142.10,-0.241
56.79,141.93,-0.241
56.82,141.77,-0.241
56.85,141.60,-0.241
56.89,141.44,-0.241
56.92,141.27,-0.241
56.95,141.10,-0.241
56.99,140.94,-0.241
57.02,140.77,-0.241
57.05,140.60,-0.241
57.09,140.44,-0.241
57.12,140.27,-0.241
57.15,140.10,-0.241
57.19,139.94,-0.241
57.22,139.77,-0.241
57.25,139.60,-0.241
57.29,139.44,-0.241
57.32,139.27,-0.241
57.35,139.10,-0.241
57.39,138.94,-0.241
57.42,138.77,-0.241
57.45,138.60,-0.241
57.49,138.44,-0.241
57.52,138.27,-0.241
57.55,138.10,-0.241
57.59,137.94,-0.241
57.62,137.77,-0.241
57.65,137.60,-0.241
57.69,137.44,-0.241
57.72,137.27,-0.241
57.75,137.10,-0.241
57.79,136.94,-0.241
57.82,136.77,-0.241
57.85,136.60,-0.241
57.89,136.44,-0.241
57.92,136.27,-0.240
57.95,136.10,-0.240
57.99,135.94,-0.240
58.02,135.77,-0.240
58.05,135.61,-0.240
58.09,135.44,-0.240
58.12,135.27,-0.240
58.15,135.11,-0.240
58.19,134.94,-0.240
58.22,134.77,-0.240
58.25,134.61,-0.240
58.29,134.44,-0.240
58.32,134.27,-0.240
58.35,134.11,-0.240
58.39,133.94,-0.240
58.42,133.77,-0.240
58.45,133.61,-0.240
58.49,133.44,-0.240
58.52,133.27,-0.240
58.55,133.11,-0.240
58.59,132.94,-0.240
58.62,132.77,-0.240
58.65,132.61,-0.240
58.69,132.44,-0.240
58.72,132.27,-0.240
58.75,132.11,-0.240
58.79,131.94,-0.240
58.82,131.77,-0.240
58.85,131.61,-0.240
58.89,131.44,-0.240
58.92,131.27,-0.240
58.95,131.11,-0.240
58.99,130.94,-0.240
59.02,130.77,-0.240
59.05,130.61,-0.240
59.09,130.44,-0.240
59.12,130.27,-0.240
59.15,130.11,-0.240
59.19,129.94,-0.239
59.22,129.78,-0.239
59.25,129.61,-0.239
59.29,129.44,-0.239
59.32,129.28,-0.239
59.35,129.11,-0.239
59.39,128.94,-0.239
59.42,128.78,-0.239
59.45,128.61,-0.239
59.49,128.44,-0.239
59.52,128.28,-0.239
59.55,128.11,-0.239
59.59,127.94,-0.239
59.62,127.78,-0.238
59.65,127.61,-0.239
59.69,127.44,-0.239
59.72,127.28,-0.239
59.75,127.11,-0.239
59.79,126.94,-0.238
59.82,126.78,-0.239
59.85,126.61,-0.238
59.89,126.44,-0.238
59.92,126.28,-0.238
59.95,126.11,-0.238
59.99,125.95,-0.238
60.02,125.78,-0.238
60.05,125.61,-0.238
60.09,125.44,-0.238
60.12,125.28,-0.238
60.15,125.11,-0.238
60.19,124.95,-0.238
60.22,124.78,-0.238
60.25,124.61,-0.238
60.29,124.45,-0.238
60.32,124.28,-0.238
60.35,124.11,-0.238
60.39,123.95,-0.238
60.42,123.78,-0.238
60.45,123.61,-0.238
60.49,123.45,-0.238
60.52,123.28,-0.238
60.55,123.11,-0.238
60.59,122.95,-0.238
60.62,122.78,-0.238
60.65,122.61,-0.238
60.69,122.45,-0.238
60.72,122.28,-0.238
60.75,122.11,-0.238
60.79,121.95,-0.238
60.82,121.78,-0.238
60.85,121.61,-0.238
60.89,121.45,-0.238
60.92,121.28,-0.237
60.95,121.11,-0.237
60.99,120.95,-0.237
61.02,120.78,-0.238
61.05,120.61,-0.237
61.09,120.45,-0.237
61.12,120.28,-0.237
[...]
209.72,7.96,0.143
209.75,8.12,0.143
209.79,8.29,0.143
209.82,8.46,0.143
209.85,8.62,0.143
209.89,8.79,0.143
209.92,8.96,0.143
209.95,9.12,0.143
209.99,9.29,0.143
210.02,9.46,0.143
210.05,9.63,0.144
210.09,9.79,0.144
210.12,9.96,0.144
210.15,10.13,0.144
210.19,10.29,0.144
210.22,10.46,0.144
210.25,10.63,0.144
210.29,10.79,0.144
210.32,10.96,0.144
210.35,11.13,0.144
210.39,11.29,0.144
210.42,11.46,0.144
210.45,11.63,0.144
210.49,11.79,0.144
210.52,11.96,0.144
210.55,12.13,0.144
210.59,12.29,0.144
210.62,12.46,0.144
210.65,12.63,0.144
210.69,12.79,0.144
210.72,12.96,0.144
210.75,13.13,0.144
210.79,13.29,0.144
210.82,13.46,0.144
210.85,13.63,0.144
210.89,13.79,0.145
210.92,13.96,0.145
210.95,14.13,0.145
210.99,14.30,0.145
211.02,14.46,0.145
211.05,14.63,0.145
211.09,14.80,0.145
211.12,14.96,0.145
211.15,15.13,0.145
211.19,15.30,0.145
211.22,15.46,0.145
211.25,15.63,0.145
211.29,15.80,0.145
211.32,15.96,0.145
211.35,16.13,0.145
211.39,16.30,0.145
211.42,16.46,0.145
211.45,16.63,0.145
211.49,16.80,0.145
211.52,16.96,0.146
211.55,17.13,0.146
211.59,17.30,0.146
211.62,17.46,0.146
211.65,17.63,0.146
211.69,17.80,0.146
211.72,17.96,0.146
211.75,18.13,0.146
211.79,18.30,0.146
211.82,18.47,0.146
211.85,18.63,0.146
211.89,18.80,0.146
211.92,18.97,0.146
211.95,19.13,0.146
211.99,19.30,0.146
212.02,19.47,0.146
212.05,19.63,0.146
212.09,19.80,0.146
212.12,19.97,0.146
212.15,20.13,0.146
212.19,20.30,0.146
212.22,20.47,0.146
212.25,20.63,0.146
212.29,20.80,0.146
212.32,20.97,0.147
212.35,21.13,0.147
212.39,21.30,0.147
212.42,21.47,0.147
212.45,21.63,0.147
212.49,21.80,0.147
212.52,21.97,0.147
212.55,22.13,0.147
212.59,22.30,0.147
212.62,22.47,0.147
212.65,22.63,0.147
212.69,22.80,0.147
212.72,22.97,0.147
212.75,23.13,0.147
212.79,23.30,0.147
212.82,23.47,0.147
212.85,23.64,0.147
212.89,23.80,0.147
212.92,23.97,0.148
212.95,24.14,0.148
212.99,24.30,0.148
213.02,24.47,0.148
213.05,24.63,0.148
213.09,24.80,0.148
213.12,24.97,0.148
213.15,25.14,0.148
213.19,25.30,0.148
213.22,25.47,0.148
213.25,25.64,0.148
213.29,25.80,0.148
213.32,25.97,0.148
213.35,26.14,0.148
213.39,26.30,0.148
213.42,26.47,0.148
213.45,26.64,0.148
213.49,26.80,0.148
213.52,26.97,0.148
213.55,27.14,0.148
213.59,27.30,0.149
213.62,27.47,0.149
213.65,27.64,0.149
213.69,27.80,0.149
213.72,27.97,0.149
213.75,28.14,0.149
213.79,28.31,0.149
213.82,28.47,0.149
213.85,28.64,0.149
213.89,28.81,0.149
213.92,28.97,0.149
213.95,29.14,0.150
213.99,29.31,0.149
214.02,29.47,0.149
214.05,29.64,0.150
214.09,29.81,0.150
214.12,29.97,0.150
214.15,30.14,0.150
214.19,30.31,0.150
214.22,30.47,0.150
214.25,30.64,0.150
214.29,30.80,0.150
214.32,30.97,0.150
214.35,31.14,0.150
214.39,31.31,0.150
214.42,31.47,0.150
214.45,31.64,0.150
214.49,31.81,0.150
214.52,31.97,0.150
214.55,32.14,0.150
214.59,32.31,0.150
214.62,32.47,0.151
214.65,32.64,0.151
214.69,32.81,0.151
214.72,32.97,0.151
214.75,33.14,0.151
214.79,33.31,0.151
214.82,33.47,0.151
214.85,33.64,0.151
214.89,33.81,0.151
214.92,33.98,0.151
214.95,34.14,0.151
214.99,34.31,0.151
215.02,34.47,0.151
215.05,34.64,0.151
215.09,34.81,0.151
215.12,34.98,0.151
215.15,35.14,0.151
215.19,35.31,0.151
215.22,35.48,0.151
215.25,35.64,0.151
215.29,35.81,0.151
215.32,35.98,0.151
215.35,36.14,0.152
215.39,36.31,0.152
215.42,36.48,0.152
215.45,36.65,0.152
215.49,36.81,0.152
215.52,36.98,0.152
215.55,37.15,0.152
215.59,37.31,0.152
215.62,37.48,0.152
215.65,37.65,0.152
215.69,37.81,0.152
215.72,37.98,0.152
215.75,38.15,0.152
215.79,38.31,0.152
215.82,38.48,0.152
215.85,38.64,0.152
215.89,38.81,0.152
215.92,38.98,0.152
215.95,39.15,0.152
215.99,39.31,0.152
216.02,39.48,0.152
216.05,39.65,0.153
216.09,39.81,0.152
216.12,39.98,0.153
216.15,40.15,0.153
216.19,40.31,0.153
216.22,40.48,0.153
216.25,40.65,0.153
216.29,40.81,0.153
216.32,40.98,0.153
216.35,41.15,0.153
216.39,41.31,0.153
216.42,41.48,0.153
216.45,41.65,0.153
216.49,41.81,0.153
216.52,41.98,0.153
216.55,42.15,0.153
216.59,42.31,0.153
216.62,42.48,0.153
216.65,42.65,0.153
216.69,42.81,0.153
216.72,42.98,0.153
216.75,43.15,0.153
216.79,43.32,0.154
216.82,43.48,0.154
216.85,43.65,0.154
216.89,43.82,0.154
216.92,43.98,0.154
216.95,44.15,0.154
216.99,44.32,0.154
217.02,44.48,0.154
217.05,44.65,0.154
217.09,44.82,0.154
217.12,44.98,0.154
217.15,45.15,0.154
217.19,45.32,0.154
217.22,45.48,0.154
217.25,45.65,0.154
217.29,45.81,0.154
217.32,45.98,0.154
217.35,46.15,0.155
217.39,46.32,0.155
217.42,46.48,0.155
217.45,46.65,0.155
217.49,46.82,0.155
217.52,46.98,0.155
217.55,47.15,0.155
217.59,47.32,0.155
217.62,47.48,0.155
217.65,47.65,0.155
217.69,47.82,0.155
217.72,47.99,0.155
217.75,48.15,0.155
217.79,48.32,0.155
217.82,48.49,0.155
217.85,48.65,0.156
217.89,48.82,0.156
217.92,48.99,0.156
217.95,49.15,0.155
217.99,49.32,0.155
218.02,49.49,0.156
218.05,49.65,0.156
218.09,49.82,0.156
218.12,49.99,0.156
218.15,50.15,0.156
218.19,50.32,0.156
218.22,50.49,0.156
218.25,50.65,0.156
218.29,50.82,0.156
218.32,50.99,0.156
218.35,51.15,0.156
218.39,51.32,0.156
218.42,51.49,0.156
218.45,51.65,0.156
218.49,51.82,0.156
218.52,51.99,0.156
218.55,52.15,0.156
218.59,52.32,0.156
218.62,52.49,0.156
218.65,52.65,0.156
218.69,52.82,0.156
218.72,52.99,0.156
218.75,53.16,0.156
218.79,53.32,0.156
218.82,53.49,0.156
218.85,53.65,0.156
218.89,53.82,0.156
218.92,53.99,0.156
218.95,54.16,0.157
218.99,54.32,0.157
219.02,54.49,0.157
219.05,54.66,0.157
219.09,54.82,0.157
219.12,54.99,0.157
219.15,55.16,0.157
219.19,55.32,0.157
219.22,55.49,0.157
219.25,55.66,0.157
219.29,55.82,0.157
219.32,55.99,0.157
219.35,56.16,0.157
219.39,56.33,0.157
219.42,56.49,0.157
219.45,56.66,0.157
219.49,56.82,0.157
219.52,56.99,0.157
219.55,57.16,0.157
219.59,57.32,0.157
219.62,57.49,0.157
219.65,57.66,0.157
219.69,57.82,0.157
219.72,57.99,0.157
219.75,58.16,0.157
219.79,58.32,0.157
219.82,58.49,0.157
219.85,58.66,0.157
219.89,58.83,0.157
219.92,58.99,0.157
219.95,59.16,0.157
219.99,59.33,0.157
220.02,59.49,0.157
220.05,59.66,0.157
220.09,59.83,0.157
220.12,59.99,0.157
220.15,60.16,0.157
220.19,60.33,0.156
220.22,60.49,0.156
220.25,60.66,0.156
220.29,60.83,0.156
220.32,60.99,0.156
220.35,61.16,0.155
220.39,61.33,0.155
220.42,61.49,0.155
220.45,61.66,0.155
220.49,61.83,0.154
220.52,62.00,0.154
220.55,62.16,0.153
220.59,62.33,0.153
220.62,62.50,0.152
220.65,62.66,0.151
220.69,62.83,0.150
220.72,63.00,0.149
220.75,63.17,0.148
220.79,63.33,0.147
220.82,63.50,0.146
220.85,63.67,0.145
220.89,63.83,0.144
220.92,64.00,0.143
220.95,64.17,0.142
220.99,64.34,0.140
221.02,64.50,0.139
221.05,64.67,0.138
221.09,64.84,0.136
221.12,65.01,0.134
221.15,65.17,0.133
221.19,65.34,0.131
221.22,65.51,0.130
221.25,65.67,0.127
221.29,65.84,0.126
221.32,66.01,0.124
221.35,66.18,0.121
221.39,66.35,0.119
221.42,66.51,0.116
221.45,66.68,0.113
221.49,66.85,0.111
221.52,67.02,0.107
221.55,67.18,0.103
221.59,67.35,0.099
221.62,67.52,0.095
221.65,67.69,0.091
221.69,67.86,0.086
221.72,68.03,0.083
221.75,68.19,0.079
221.79,68.36,0.075
221.82,68.53,0.071
221.85,68.70,0.067
221.89,68.87,0.065
221.92,69.03,0.062
221.95,69.20,0.059
221.99,69.37,0.056
222.02,69.54,0.055
222.05,69.71,0.054
222.09,69.87,0.053
222.12,70.04,0.052
222.15,70.21,0.052
222.19,70.37,0.051
222.22,70.54,0.051
222.25,70.71,0.051
222.29,70.87,0.051
222.32,71.04,0.052
222.35,71.21,0.053
222.39,71.37,0.054
222.42,71.54,0.055
222.45,71.71,0.056
222.49,71.87,0.058
222.52,72.04,0.060
222.55,72.20,0.062
222.59,72.37,0.064
222.62,72.53,0.065
222.65,72.70,0.067
222.69,72.87,0.068
222.72,73.03,0.070
222.75,73.20,0.071
222.79,73.36,0.073
222.82,73.53,0.075
222.85,73.70,0.077
222.89,73.86,0.079
222.92,74.03,0.081
222.95,74.19,0.083
222.99,74.36,0.085
223.02,74.53,0.086
223.05,74.69,0.088
223.09,74.86,0.089
223.12,75.02,0.091
223.15,75.19,0.093
223.19,75.36,0.095
223.22,75.52,0.097
223.25,75.69,0.099
223.29,75.86,0.102
223.32,76.02,0.104
223.35,76.19,0.106
223.39,76.35,0.108
223.42,76.52,0.111
223.45,76.69,0.113
223.49,76.85,0.115
223.52,77.02,0.117
223.55,77.18,0.121
223.59,77.35,0.122
223.62,77.51,0.123
223.65,77.68,0.124
223.69,77.85,0.125
223.72,78.01,0.127
223.75,78.18,0.128
223.79,78.35,0.129
223.82,78.51,0.130
223.85,78.68,0.131
223.89,78.85,0.132
223.92,79.01,0.134
223.95,79.18,0.135
223.99,79.34,0.138
224.02,79.51,0.140
224.05,79.67,0.141
224.09,79.84,0.142
224.12,80.01,0.144
224.15,80.17,0.145
224.19,80.34,0.146
224.22,80.51,0.148
224.25,80.67,0.149
224.29,80.84,0.150
224.32,81.01,0.151
224.35,81.17,0.152
224.39,81.34,0.153
224.42,81.50,0.154
224.45,81.67,0.155
224.49,81.84,0.156
224.52,82.00,0.156
224.55,82.17,0.157
224.59,82.34,0.157
224.62,82.51,0.158
224.65,82.67,0.159
224.69,82.84,0.159
224.72,83.01,0.160
224.75,83.17,0.160
224.79,83.34,0.161
224.82,83.51,0.162
224.85,83.67,0.162
224.89,83.84,0.163
224.92,84.01,0.163
224.95,84.17,0.164
224.99,84.34,0.164
225.02,84.51,0.164
225.05,84.67,0.165
225.09,84.84,0.165
225.12,85.01,0.165
225.15,85.17,0.166
225.19,85.34,0.166
225.22,85.51,0.167
225.25,85.67,0.167
225.29,85.84,0.167
225.32,86.00,0.168
225.35,86.17,0.168
225.39,86.34,0.168
225.42,86.50,0.169
225.45,86.67,0.169
225.49,86.84,0.169
225.52,87.01,0.170
225.55,87.17,0.170
225.59,87.34,0.170
225.62,87.50,0.170
225.65,87.67,0.171
225.69,87.84,0.171
225.72,88.00,0.171
225.75,88.17,0.171
225.79,88.34,0.172
225.82,88.50,0.172
225.85,88.67,0.172
225.89,88.84,0.173
225.92,89.00,0.173
225.95,89.17,0.173
225.99,89.34,0.173
226.02,89.50,0.173
226.05,89.67,0.174
226.09,89.84,0.174
226.12,90.00,0.174
226.15,90.17,0.175
226.19,90.34,0.175
226.22,90.50,0.175
226.25,90.67,0.175
226.29,90.84,0.176
226.32,91.00,0.176
226.35,91.17,0.176
226.39,91.34,0.176
226.42,91.51,0.177
226.45,91.67,0.177
226.49,91.84,0.177
226.52,92.00,0.177
226.55,92.17,0.177
226.59,92.34,0.178
226.62,92.51,0.178
226.65,92.67,0.178
226.69,92.84,0.179
226.72,93.00,0.179
226.75,93.17,0.179
226.79,93.34,0.179
226.82,93.50,0.180
226.85,93.67,0.180
226.89,93.84,0.180
226.92,94.00,0.180
226.95,94.17,0.181
226.99,94.34,0.181
227.02,94.50,0.181
227.05,94.67,0.181
227.09,94.84,0.182
227.12,95.00,0.182
227.15,95.17,0.182
227.19,95.34,0.182
227.22,95.51,0.183
227.25,95.67,0.183
227.29,95.84,0.183
227.32,96.01,0.184
227.35,96.17,0.184
227.39,96.34,0.184
227.42,96.51,0.184
227.45,96.67,0.185
227.49,96.84,0.185
227.52,97.00,0.185
227.55,97.17,0.185
227.59,97.34,0.185
227.62,97.50,0.186
227.65,97.67,0.186
227.69,97.84,0.186
227.72,98.00,0.187
227.75,98.17,0.187
227.79,98.34,0.187
227.82,98.50,0.187
227.85,98.67,0.188
227.89,98.84,0.188
227.92,99.01,0.188
227.95,99.17,0.189
227.99,99.34,0.189
228.02,99.51,0.189
228.05,99.67,0.190
228.09,99.84,0.190
228.12,100.00,0.190
228.15,100.17,0.190
228.19,100.34,0.191
228.22,100.50,0.191
228.25,100.67,0.191
228.29,100.84,0.192
228.32,101.00,0.192
228.35,101.17,0.192
228.39,101.34,0.193
228.42,101.50,0.193
228.45,101.67,0.193
228.49,101.84,0.193
228.52,102.00,0.194
228.55,102.17,0.194
228.59,102.34,0.194
228.62,102.50,0.195
228.65,102.67,0.195
228.69,102.84,0.195
228.72,103.00,0.196
228.75,103.17,0.196
228.79,103.34,0.196
228.82,103.50,0.197
228.85,103.67,0.197
228.89,103.84,0.197
228.92,104.00,0.198
228.95,104.17,0.198
228.99,104.34,0.198
229.02,104.50,0.199
229.05,104.67,0.199
229.09,104.84,0.199
229.12,105.00,0.200
229.15,105.17,0.200
229.19,105.34,0.200
229.22,105.50,0.201
229.25,105.67,0.201
229.29,105.84,0.201
229.32,106.00,0.202
229.35,106.17,0.202
229.39,106.34,0.203
229.42,106.50,0.203
229.45,106.67,0.203
229.49,106.84,0.204
229.52,107.00,0.204
229.55,107.17,0.204
229.59,107.34,0.205
229.62,107.50,0.205
229.65,107.67,0.205
229.69,107.84,0.206
229.72,108.00,0.206
229.75,108.17,0.207
229.79,108.34,0.207
229.82,108.50,0.207
229.85,108.67,0.208
229.89,108.84,0.208
229.92,109.00,0.209
229.95,109.17,0.209
229.99,109.33,0.210
230.02,109.50,0.210
230.05,109.67,0.210
230.09,109.83,0.211
230.12,110.00,0.211
230.15,110.17,0.212
230.19,110.33,0.212
230.22,110.50,0.212
230.25,110.67,0.213
230.29,110.84,0.213
230.32,111.00,0.214
230.35,111.17,0.214
230.39,111.34,0.215
230.42,111.50,0.215
230.45,111.67,0.215
230.49,111.83,0.216
230.52,112.00,0.216
230.55,112.17,0.217
230.59,112.34,0.217
230.62,112.50,0.217
230.65,112.67,0.218
230.69,112.83,0.218
230.72,113.00,0.218
230.75,113.17,0.219
230.79,113.33,0.219
230.82,113.50,0.220
230.85,113.67,0.220
230.89,113.83,0.220
230.92,114.00,0.220
230.95,114.17,0.221
230.99,114.33,0.221
231.02,114.50,0.221
231.05,114.67,0.221
231.09,114.83,0.222
231.12,115.00,0.222
231.15,115.17,0.222
231.19,115.33,0.222
231.22,115.50,0.222
231.25,115.67,0.223
231.29,115.83,0.223
231.32,116.00,0.223
231.35,116.17,0.223
231.39,116.33,0.223
231.42,116.50,0.223
231.45,116.67,0.223
231.49,116.83,0.223
231.52,117.00,0.223
231.55,117.17,0.223
231.59,117.34,0.223
231.62,117.50,0.223
231.65,117.67,0.222
231.69,117.84,0.222
231.72,118.00,0.222
231.75,118.17,0.221
231.79,118.34,0.221
231.82,118.51,0.220
231.85,118.67,0.220
231.89,118.84,0.219
231.92,119.01,0.218
231.95,119.17,0.217
231.99,119.34,0.216
232.02,119.51,0.214
232.05,119.67,0.213
232.09,119.84,0.211
232.12,120.01,0.210
232.15,120.18,0.209
232.19,120.34,0.207
232.22,120.51,0.206
232.25,120.68,0.205
232.29,120.84,0.204
232.32,121.01,0.201
232.35,121.18,0.200
232.39,121.35,0.199
232.42,121.51,0.198
232.45,121.68,0.197
232.49,121.85,0.196
232.52,122.02,0.195
232.55,122.18,0.193
232.59,122.35,0.192
232.62,122.52,0.191
232.65,122.68,0.191
232.69,122.85,0.190
232.72,123.02,0.189
232.75,123.19,0.188
232.79,123.35,0.187
232.82,123.52,0.187
232.85,123.69,0.186
232.89,123.85,0.185
232.92,124.02,0.184
232.95,124.19,0.184
232.99,124.35,0.183
233.02,124.52,0.183
233.05,124.69,0.182
233.09,124.85,0.182
233.12,125.02,0.181
233.15,125.19,0.181
233.19,125.35,0.180
233.22,125.52,0.180
233.25,125.69,0.180
233.29,125.86,0.179
233.32,126.02,0.179
233.35,126.19,0.178
233.39,126.36,0.178
233.42,126.52,0.178
233.45,126.69,0.178
233.49,126.86,0.177
233.52,127.02,0.177
233.55,127.19,0.177
233.59,127.36,0.177
233.62,127.52,0.176
233.65,127.69,0.176
233.69,127.86,0.176
233.72,128.02,0.176
233.75,128.19,0.176
233.79,128.36,0.175
233.82,128.52,0.175
233.85,128.69,0.175
233.89,128.86,0.175
233.92,129.02,0.175
233.95,129.19,0.175
233.99,129.36,0.175
234.02,129.52,0.175
234.05,129.69,0.175
234.09,129.86,0.175
234.12,130.02,0.175
234.15,130.19,0.175
234.19,130.36,0.175
234.22,130.52,0.175
234.25,130.69,0.175
234.29,130.86,0.175
234.32,131.02,0.175
234.35,131.19,0.175
234.39,131.36,0.175
234.42,131.52,0.175
234.45,131.69,0.175
234.49,131.86,0.175
234.52,132.02,0.175
234.55,132.19,0.175
234.59,132.36,0.175
234.62,132.53,0.175
234.65,132.69,0.175
234.69,132.86,0.175
234.72,133.03,0.175
234.75,133.19,0.175
234.79,133.36,0.175
234.82,133.53,0.175
234.85,133.69,0.175
234.89,133.86,0.175
234.92,134.03,0.175
234.95,134.19,0.175
234.99,134.36,0.175
235.02,134.53,0.175
235.05,134.69,0.175
235.09,134.86,0.175
235.12,135.03,0.175
235.15,135.19,0.175
235.19,135.36,0.175
235.22,135.53,0.175
235.25,135.69,0.175
235.29,135.86,0.175
235.32,136.03,0.175
235.35,136.19,0.175
235.39,136.36,0.175
235.42,136.53,0.176
235.45,136.69,0.176
235.49,136.86,0.176
235.52,137.03,0.176
235.55,137.19,0.176
235.59,137.36,0.176
235.62,137.53,0.176
235.65,137.69,0.176
235.69,137.86,0.176
235.72,138.03,0.176
235.75,138.19,0.176
235.79,138.36,0.176
235.82,138.53,0.176
235.85,138.69,0.176
235.89,138.86,0.176
235.92,139.03,0.176
235.95,139.20,0.176
235.99,139.36,0.176
236.02,139.53,0.176
236.05,139.70,0.176
236.09,139.86,0.176
236.12,140.03,0.176
236.15,140.19,0.176
236.19,140.36,0.176
236.22,140.53,0.176
236.25,140.69,0.176
236.29,140.86,0.176
236.32,141.03,0.177
236.35,141.19,0.177
236.39,141.36,0.177
236.42,141.53,0.177
236.45,141.69,0.177
236.49,141.86,0.177
236.52,142.03,0.177
236.55,142.19,0.177
236.59,142.36,0.177
236.62,142.53,0.177
236.65,142.70,0.177
236.69,142.86,0.177
236.72,143.03,0.177
236.75,143.19,0.177
236.79,143.36,0.177
236.82,143.53,0.177
236.85,143.69,0.177
236.89,143.86,0.177
236.92,144.03,0.177
236.95,144.20,0.177
236.99,144.36,0.177
237.02,144.53,0.177
237.05,144.70,0.177
237.09,144.86,0.177
237.12,145.03,0.177
237.15,145.20,0.178
237.19,145.36,0.177
237.22,145.53,0.177
237.25,145.70,0.178
237.29,145.86,0.178
237.32,146.03,0.178
237.35,146.20,0.178
237.39,146.36,0.178
237.42,146.53,0.178
237.45,146.70,0.178
237.49,146.86,0.178
237.52,147.03,0.178
237.55,147.20,0.178
237.59,147.36,0.178
237.62,147.53,0.178
237.65,147.70,0.178
237.69,147.86,0.178
237.72,148.03,0.178
237.75,148.20,0.178
237.79,148.36,0.178
237.82,148.53,0.178
237.85,148.70,0.178
237.89,148.86,0.178
237.92,149.03,0.178
237.95,149.20,0.178
237.99,149.36,0.178
238.02,149.53,0.178
238.05,149.70,0.178
238.09,149.86,0.178
238.12,150.03,0.178
238.15,150.20,0.178
238.19,150.36,0.178
238.22,150.53,0.178
238.25,150.70,0.178
238.29,150.86,0.178
238.32,151.03,0.178
238.35,151.20,0.178
238.39,151.36,0.178
238.42,151.53,0.178
238.45,151.70,0.178
238.49,151.86,0.178
238.52,152.03,0.178
238.55,152.20,0.178
238.59,152.36,0.178
238.62,152.53,0.178
238.65,152.70,0.178
238.69,152.86,0.178
238.72,153.03,0.178
238.75,153.20,0.178
238.79,153.36,0.179
238.82,153.53,0.179
238.85,153.70,0.179
238.89,153.86,0.179
238.92,154.03,0.179
238.95,154.20,0.179
238.99,154.37,0.179
239.02,154.53,0.179
239.05,154.70,0.179
239.09,154.86,0.179
239.12,155.03,0.179
239.15,155.20,0.179
239.19,155.37,0.179
239.22,155.53,0.179
239.25,155.70,0.179
239.29,155.87,0.179
239.32,156.03,0.179
239.35,156.20,0.179
239.39,156.37,0.179
239.42,156.53,0.179
239.45,156.70,0.179
239.49,156.87,0.179
239.52,157.03,0.179
239.55,157.20,0.179
239.59,157.37,0.179
239.62,157.53,0.179
239.65,157.70,0.179
239.69,157.87,0.179
239.72,158.03,0.179
239.75,158.20,0.179
239.79,158.37,0.179
239.82,158.53,0.179
239.85,158.70,0.179
239.89,158.87,0.179
239.92,159.03,0.179
239.95,159.20,0.180
239.99,159.37,0.180
240.02,159.53,0.179
240.05,159.70,0.179
240.09,159.87,0.179
240.12,160.03,0.179
240.15,160.20,0.180
240.19,160.37,0.180
240.22,160.53,0.180
240.25,160.70,0.180
240.29,160.87,0.180
240.32,161.03,0.180
240.35,161.20,0.180
240.39,161.37,0.180
240.42,161.53,0.180
240.45,161.70,0.180
240.49,161.87,0.180
240.52,162.03,0.180
240.55,162.20,0.180
240.59,162.37,0.180
240.62,162.53,0.180
240.65,162.70,0.180
240.69,162.87,0.180
240.72,163.03,0.180
240.75,163.20,0.180
240.79,163.37,0.180
240.82,163.53,0.181
240.85,163.70,0.181
240.89,163.87,0.181
240.92,164.03,0.181
240.95,164.20,0.181
240.99,164.37,0.181
241.02,164.53,0.181
241.05,164.70,0.181
241.09,164.87,0.181
241.12,165.03,0.181
241.15,165.20,0.181
241.19,165.37,0.181
241.22,165.53,0.181
241.25,165.70,0.181
241.29,165.87,0.181
241.32,166.04,0.181
241.35,166.20,0.181
241.39,166.37,0.181
241.42,166.53,0.181
241.45,166.70,0.181
241.49,166.87,0.181
241.52,167.04,0.181
241.55,167.20,0.181
241.59,167.37,0.181
241.62,167.54,0.181
241.65,167.70,0.181
241.69,167.87,0.181
241.72,168.04,0.181
241.75,168.20,0.181
241.79,168.37,0.181
241.82,168.53,0.181
241.85,168.70,0.181
241.89,168.87,0.181
241.92,169.03,0.181
241.95,169.20,0.181
241.99,169.37,0.181
242.02,169.53,0.181
242.05,169.70,0.181
242.09,169.87,0.181
242.12,170.03,0.181
242.15,170.20,0.181
242.19,170.37,0.182
242.22,170.53,0.182
242.25,170.70,0.182
242.29,170.87,0.182
242.32,171.03,0.182
242.35,171.20,0.182
242.39,171.37,0.182
242.42,171.53,0.182
242.45,171.70,0.182
242.49,171.87,0.182
242.52,172.04,0.182
242.55,172.20,0.182
242.59,172.37,0.182
242.62,172.53,0.182
242.65,172.70,0.182
242.69,172.87,0.182
242.72,173.03,0.182
242.75,173.20,0.182
242.79,173.37,0.182
242.82,173.53,0.182
242.85,173.70,0.182
242.89,173.87,0.182
242.92,174.03,0.182
242.95,174.20,0.182
242.99,174.37,0.182
243.02,174.53,0.182
243.05,174.70,0.183
243.09,174.87,0.183
243.12,175.03,0.182
243.15,175.20,0.183
243.19,175.37,0.183
243.22,175.54,0.183
243.25,175.70,0.183
243.29,175.87,0.183
243.32,176.03,0.183
243.35,176.20,0.183
243.39,176.37,0.183
243.42,176.53,0.183
243.45,176.70,0.183
243.49,176.87,0.183
243.52,177.04,0.183
243.55,177.20,0.183
243.59,177.37,0.183
243.62,177.54,0.183
243.65,177.70,0.183
243.69,177.87,0.183
243.72,178.04,0.183
243.75,178.20,0.184
243.79,178.37,0.184
243.82,178.54,0.184
243.85,178.70,0.184
243.89,178.87,0.183
243.92,179.03,0.183
243.95,179.20,
243.98,,