File: DSC/2025_07_01_d9THC_n60_100_10C_min_x4.csv
Filename,2025_07_01_d9THC_n60_100_10C_min_x4
Instrument name,DSC2A-00468 (192.168.1.100)
Operator,Gibbons
rundate,7/2/2025
Sample name,2025_07_01_d9THC_n60_100_10C_min_x4
proceduresegments,Data Off ; Equilibrate -60.00 °C; Data On ; Ramp 10.00 °C/min to 100.00 °C; Data Off ; Isothermal 2.0 min; Data On ; Ramp 10.00 °C/min to -60.00 °C; Data Off ; Isothermal 2.0 min; Data On ; Ramp 10.00 °C/min to 100.00 °C; Data Off ; Isothermal 2.0 min; Data On ; Ramp 10.00 °C/min to -60.00 °C; Data Off ; Isothermal 2.0 min; Data On ; Ramp 10.00 °C/min to 100.00 °C; Data Off ; Isothermal 2.0 min; Data On ; Ramp 10.00 °C/min to -60.00 °C; Data Off ; Isothermal 2.0 min; Data On ; Ramp 10.00 °C/min to 30.00 °C
[File Parameters]
Run date,7/2/2025 4:00:51 AM
Trios version,5.1.1.46572
Original File Name,
Current File Name,D:\DSC2500\Gibbons\2025_07_01_d9THC_n60_100_10C_min_x4.tri
[Procedure]
Procedure Name,d9THC_n60_100_10C_min_x4
Sample Name,2025_07_01_d9THC_n60_100_10C_min_x4
Sample Mass,18.23 mg
Reference Sample Mass,0 mg
Pan Mass,57.5 mg
Pan Number,18
Reference Pan Mass,57.15 mg
Reference Pan Number,28
Pan Type,Tzero Aluminum Hermetic
Comments,DSC Consumables Al Hermetically Sealed Pan. Y1 Tray (Google Sheet: DSC_Samples_Y1_Tray_June2025).
Project Name,Pharma - Cocrystals
Operator,Gibbons
Test,Custom
Unload Max Temperature,30
Unload Min Temperature,30
Load Max Temperature,30
Load Min Temperature,30
Stop on Gas Flow Error,Yes
[Signal List]
Signal #1,Time (min)
Signal #2,Temperature (°C)
Signal #3,Heat Flow (mW)
Signal #4,Delta T (µV)
Signal #5,Delta Tzero (µV)
Signal #6,Tzero Temperature (°C)
Signal #7,Cell Purge (mL/min)
Signal #8,Heater Temp (°C)
Signal #9,Power Delivered (W)
Signal #10,Reference Junction Temperature (°C)
Signal #11,Flange Temperature (°C)
Signal #12,Heat Flow Phase (rad)
Signal #13,Total Heat Capacity (J/°C)
Signal #14,Heat Capacity (J/°C)
[Configuration]
Company Name,ASU
Instrument Name,DSC2A-00468
Instrument Type,DSC2500
Serial Number,DSC2A-00468
IP,192.168.1.100
Location of Instrument,MRRC
DisplayType,Unknown
Sample Interval ,0.1 s/pt
Selected Heat Flow,T4P
Exotherm Direction,Down
Cell Serial,DRC2-00792
Lid Type,Standard
Cooler,RCS 90
Leave Cooler on at End of Sequence,On
Gas 2,Nitrogen
Gas Selected,Channel 1
Flow Rate,50 mL/min
Secondary Purge,On
Licensed Heat Flow,Heat Flow T4P
Modulation Licensed,Yes
[Versions]
Common IDD Version,1
Cortex Version,VER 2.10.2.31
Driver,5.0.0.6
GDM Version,1.0.3.3
TouchscreenVersion,1.0.0.16145
FEP Version,1.2.1.21
FEP Bootloader,2.0.0.5
AutoSampler Version,2.1.1.26
Auto Sampler Bootloader,2.0.0.5
FCM Version,1.1.0.3
FCM Bootloader,2.0.0.5
[Experiment Logs]
Experiment Log Entry # 1,Air Cool is off.
Experiment Log Entry # 3,Data On set to 0
Experiment Log Entry # 5,Equilibrate Segment -60 (C) Started
Experiment Log Entry # 7,Data On set to 1
Experiment Log Entry # 9,Ramp Segment 10 C/min to 100 Started
Experiment Log Entry # 11,Data On set to 0
Experiment Log Entry # 13,Isothermal Segment 2 min started
Experiment Log Entry # 15,Data On set to 1
Experiment Log Entry # 17,Ramp Segment 10 C/min to -60 Started
Experiment Log Entry # 19,Data On set to 0
Experiment Log Entry # 21,Isothermal Segment 2 min started
Experiment Log Entry # 23,Data On set to 1
Experiment Log Entry # 25,Ramp Segment 10 C/min to 100 Started
Experiment Log Entry # 27,Data On set to 0
Experiment Log Entry # 29,Isothermal Segment 2 min started
Experiment Log Entry # 31,Data On set to 1
Experiment Log Entry # 33,Ramp Segment 10 C/min to -60 Started
Experiment Log Entry # 35,Data On set to 0
Experiment Log Entry # 37,Isothermal Segment 2 min started
Experiment Log Entry # 39,Data On set to 1
Experiment Log Entry # 41,Ramp Segment 10 C/min to 100 Started
Experiment Log Entry # 43,Data On set to 0
Experiment Log Entry # 45,Isothermal Segment 2 min started
Experiment Log Entry # 47,Data On set to 1
Experiment Log Entry # 49,Ramp Segment 10 C/min to -60 Started
Experiment Log Entry # 51,Data On set to 0
Experiment Log Entry # 53,Isothermal Segment 2 min started
Experiment Log Entry # 55,Data On set to 1
Experiment Log Entry # 57,Ramp Segment 10 C/min to 30 Started
[Method Log]
Method Log Entry # 1,Data Off
Method Log Entry # 2,Equilibrate -60 °C
Method Log Entry # 3,Data On
Method Log Entry # 4,(Ramp 1148094) Ramp 10 °C/minute to 100 °C
Method Log Entry # 5,Data Off
Method Log Entry # 6,Isothermal 2 minutes
Method Log Entry # 7,Data On
Method Log Entry # 8,(Ramp 1148098) Ramp 10 °C/minute to -60 °C
Method Log Entry # 9,Data Off
Method Log Entry # 10,Isothermal 2 minutes
Method Log Entry # 11,Data On
Method Log Entry # 12,(Ramp 1148102) Ramp 10 °C/minute to 100 °C
Method Log Entry # 13,Data Off
Method Log Entry # 14,Isothermal 2 minutes
Method Log Entry # 15,Data On
Method Log Entry # 16,(Ramp 1148106) Ramp 10 °C/minute to -60 °C
Method Log Entry # 17,Data Off
Method Log Entry # 18,Isothermal 2 minutes
Method Log Entry # 19,Data On
Method Log Entry # 20,(Ramp 1148110) Ramp 10 °C/minute to 100 °C
Method Log Entry # 21,Data Off
Method Log Entry # 22,Isothermal 2 minutes
Method Log Entry # 23,Data On
Method Log Entry # 24,(Ramp 1148114) Ramp 10 °C/minute to -60 °C
Method Log Entry # 25,Data Off
Method Log Entry # 26,Isothermal 2 minutes
Method Log Entry # 27,Data On
Method Log Entry # 28,(Ramp 1148118) Ramp 10 °C/minute to 30 °C
Cell Serial,DRC2-00792
[T1 Calibration]
Slope,-0.008529666
Offset,9.636258
Initial Temperature,98.23
GUID,f8bfdadc-4977-4fdf-ba6d-0ba9134940c3
[TZero Calibration]
Date Applied,11/29/2022 4:06:13 PM
Description,From -89.059 °C to 396.009 °C at 20.000°C/min
Gas Type,Nitrogen
Pan Type,None
Source Files 1,C:\Users\yargerlab\Desktop\DSC Data\General\TZero_calibration_11_29_22_2nd(2).tri
Source Files 2,C:\Users\yargerlab\Desktop\DSC Data\General\TZero_calibration_11_29_22_2nd(3).tri
Delta T Offset,13.05235
Delta T Slope,-0.007271007
Delta T0 Offset,-13.69128
Delta T0 Slope,0.06063341
[Temperature Calibration]
Date Applied,11/29/2022 7:12:28 PM
Description,From 106.590 °C to 186.590 °C at 10.000°C/min
Gas Type,Nitrogen
Pan Type,Tzero Aluminum Hermetic
Source Files 1,C:\Users\yargerlab\Desktop\DSC Data\General\Indium(6).tri
Measured 1,157.391
Known 1,156.598
[Cell Constant Calibration]
Date Applied,11/29/2022 7:12:29 PM
Description,From 106.590 °C to 186.590 °C at 10.000°C/min
Gas Type,Nitrogen
Pan Type,Tzero Aluminum Hermetic
Source Files 1,C:\Users\yargerlab\Desktop\DSC Data\General\Indium(6).tri
T4P KCell,1.006051
Onset Slope,63.26126 mW/°C
[Direct Cp Calibration]
Date Applied,11/30/2022 11:04:51 AM
Description,From -79.983 °C to 298.409 °C at 10.000°C/min
Gas Type,Nitrogen
Pan Type,Tzero Aluminum Hermetic
Source Files 1,C:\Users\yargerlab\Desktop\DSC Data\General\Sapphire_Heat_Capacity_11_30_22.tri
[Rev Cp Calibration]
Date Applied,11/30/2022 1:58:51 PM
Description,From -79.996 °C to 292.812 °C at 3.000°C/min
Gas Type,Nitrogen
Pan Type,Tzero Aluminum Hermetic
Source Files 1,C:\Users\yargerlab\Desktop\DSC Data\General\Sapphire_MDSC_Calibration_11_30_22.tri
[step]
Ramp 10.00 °C/min to 100.00 °C
Time,Temperature,Heat Flow (Normalized)
min,°C,W/g
0.00,-59.66,-0.044
0.01,-59.67,-0.043
0.02,-59.67,-0.041
0.03,-59.68,-0.038
0.05,-59.69,-0.036
0.06,-59.68,-0.034
0.07,-59.68,-0.032
0.08,-59.66,-0.029
0.09,-59.64,-0.025
0.11,-59.61,-0.020
0.12,-59.58,-0.014
0.13,-59.54,-0.007
0.14,-59.49,0.002
0.15,-59.43,0.011
0.16,-59.37,0.021
0.18,-59.31,0.031
0.19,-59.23,0.042
0.20,-59.16,0.051
0.21,-59.08,0.061
0.22,-59.01,0.070
0.23,-58.92,0.079
0.24,-58.83,0.087
0.26,-58.74,0.094
0.27,-58.65,0.101
0.28,-58.56,0.107
0.29,-58.47,0.113
0.30,-58.37,0.118
0.31,-58.28,0.123
0.33,-58.18,0.128
0.34,-58.08,0.132
0.35,-57.98,0.136
0.36,-57.88,0.139
0.37,-57.77,0.143
0.39,-57.67,0.146
0.40,-57.57,0.149
0.41,-57.46,0.152
0.42,-57.36,0.154
0.43,-57.25,0.156
0.44,-57.14,0.158
0.45,-57.04,0.160
0.47,-56.93,0.162
0.48,-56.82,0.164
0.49,-56.71,0.166
0.50,-56.60,0.167
0.51,-56.49,0.169
0.53,-56.38,0.169
0.54,-56.27,0.170
0.55,-56.16,0.172
0.56,-56.05,0.173
0.57,-55.94,0.174
0.58,-55.82,0.174
0.60,-55.71,0.175
0.61,-55.60,0.177
0.62,-55.49,0.177
0.63,-55.37,0.178
0.64,-55.26,0.179
0.65,-55.15,0.179
0.67,-55.04,0.179
0.68,-54.92,0.180
0.69,-54.81,0.181
0.70,-54.70,0.181
0.71,-54.58,0.182
0.72,-54.47,0.182
0.73,-54.35,0.182
0.75,-54.24,0.183
0.76,-54.13,0.183
0.77,-54.01,0.183
0.78,-53.90,0.183
0.79,-53.78,0.184
0.80,-53.67,0.184
0.82,-53.55,0.185
0.83,-53.44,0.185
0.84,-53.32,0.185
0.85,-53.21,0.185
0.86,-53.09,0.186
0.88,-52.98,0.186
0.89,-52.87,0.186
0.90,-52.75,0.187
0.91,-52.64,0.187
0.92,-52.52,0.187
0.93,-52.40,0.187
0.95,-52.29,0.187
0.96,-52.17,0.187
0.97,-52.06,0.187
0.98,-51.94,0.187
0.99,-51.83,0.187
1.00,-51.71,0.188
1.02,-51.60,0.188
1.03,-51.48,0.188
1.04,-51.36,0.188
1.05,-51.25,0.188
1.06,-51.13,0.188
1.07,-51.02,0.188
1.08,-50.90,0.189
1.10,-50.79,0.189
1.11,-50.67,0.189
1.12,-50.55,0.189
1.13,-50.44,0.189
1.14,-50.32,0.189
1.16,-50.21,0.189
1.17,-50.09,0.189
1.18,-49.97,0.189
1.19,-49.86,0.190
1.20,-49.74,0.190
1.21,-49.63,0.190
1.23,-49.51,0.190
1.24,-49.39,0.190
1.25,-49.28,0.190
1.26,-49.16,0.190
1.27,-49.05,0.190
1.28,-48.93,0.191
1.29,-48.81,0.191
1.31,-48.70,0.191
1.32,-48.58,0.191
1.33,-48.46,0.191
1.34,-48.35,0.191
1.35,-48.23,0.191
1.37,-48.11,0.191
1.38,-48.00,0.191
1.39,-47.88,0.191
1.40,-47.77,0.192
1.41,-47.65,0.192
1.42,-47.53,0.192
1.43,-47.42,0.192
1.45,-47.30,0.192
1.46,-47.18,0.192
1.47,-47.07,0.192
1.48,-46.95,0.192
1.49,-46.83,0.192
1.51,-46.72,0.193
1.52,-46.60,0.193
1.53,-46.48,0.193
1.54,-46.37,0.193
1.55,-46.25,0.193
1.56,-46.13,0.193
1.58,-46.02,0.193
1.59,-45.90,0.193
1.60,-45.79,0.193
1.61,-45.67,0.193
1.62,-45.55,0.194
1.63,-45.44,0.194
1.64,-45.32,0.194
1.66,-45.20,0.194
1.67,-45.09,0.194
1.68,-44.97,0.194
1.69,-44.85,0.194
1.70,-44.74,0.194
1.72,-44.62,0.194
1.73,-44.50,0.194
1.74,-44.39,0.195
1.75,-44.27,0.195
1.76,-44.15,0.195
1.77,-44.04,0.195
1.78,-43.92,0.195
1.80,-43.80,0.195
1.81,-43.69,0.195
1.82,-43.57,0.195
1.83,-43.46,0.195
1.84,-43.34,0.195
1.86,-43.22,0.195
1.87,-43.11,0.196
1.88,-42.99,0.196
1.89,-42.87,0.196
1.90,-42.76,0.196
1.91,-42.64,0.196
1.93,-42.52,0.196
1.94,-42.40,0.196
1.95,-42.29,0.196
1.96,-42.17,0.196
1.97,-42.06,0.196
1.98,-41.94,0.196
1.99,-41.82,0.197
2.01,-41.71,0.197
2.02,-41.59,0.197
2.03,-41.47,0.197
2.04,-41.35,0.197
2.05,-41.24,0.197
2.07,-41.12,0.197
2.08,-41.00,0.197
2.09,-40.89,0.197
2.10,-40.77,0.197
2.11,-40.65,0.198
2.12,-40.54,0.198
2.14,-40.42,0.198
2.15,-40.30,0.198
2.16,-40.19,0.198
2.17,-40.07,0.198
2.18,-39.95,0.198
2.19,-39.84,0.198
2.21,-39.72,0.198
2.22,-39.60,0.198
2.23,-39.49,0.198
2.24,-39.37,0.198
2.25,-39.25,0.199
2.26,-39.14,0.199
2.28,-39.02,0.199
2.29,-38.90,0.199
2.30,-38.79,0.199
2.31,-38.67,0.199
2.32,-38.55,0.199
2.33,-38.44,0.199
2.34,-38.32,0.199
2.36,-38.20,0.199
2.37,-38.09,0.199
2.38,-37.97,0.199
2.39,-37.85,0.199
2.40,-37.73,0.200
2.41,-37.62,0.200
2.43,-37.50,0.200
2.44,-37.38,0.200
2.45,-37.27,0.200
2.46,-37.15,0.200
2.47,-37.03,0.200
2.49,-36.92,0.200
2.50,-36.80,0.200
2.51,-36.68,0.200
2.52,-36.57,0.200
2.53,-36.45,0.201
2.54,-36.33,0.201
2.56,-36.22,0.201
2.57,-36.10,0.201
2.58,-35.98,0.201
2.59,-35.87,0.201
2.60,-35.75,0.201
2.61,-35.63,0.201
2.63,-35.52,0.201
2.64,-35.40,0.201
2.65,-35.28,0.201
2.66,-35.17,0.202
2.67,-35.05,0.202
2.68,-34.93,0.202
2.69,-34.82,0.202
2.71,-34.70,0.202
2.72,-34.58,0.202
2.73,-34.46,0.202
2.74,-34.35,0.202
2.75,-34.23,0.202
2.76,-34.11,0.202
2.78,-34.00,0.202
2.79,-33.88,0.203
2.80,-33.77,0.203
2.81,-33.65,0.203
2.82,-33.53,0.203
2.84,-33.41,0.203
2.85,-33.30,0.203
2.86,-33.18,0.203
2.87,-33.06,0.203
2.88,-32.95,0.203
2.89,-32.83,0.203
2.91,-32.71,0.203
2.92,-32.60,0.203
2.93,-32.48,0.203
2.94,-32.36,0.204
2.95,-32.25,0.204
2.96,-32.13,0.204
2.98,-32.01,0.204
2.99,-31.89,0.204
3.00,-31.78,0.204
3.01,-31.66,0.204
3.02,-31.54,0.204
3.03,-31.43,0.204
3.04,-31.31,0.204
3.06,-31.20,0.205
3.07,-31.08,0.205
3.08,-30.96,0.205
3.09,-30.84,0.205
3.10,-30.73,0.205
3.11,-30.61,0.205
3.13,-30.49,0.205
3.14,-30.38,0.205
3.15,-30.26,0.205
3.16,-30.14,0.205
3.17,-30.03,0.205
3.19,-29.91,0.205
3.20,-29.79,0.205
3.21,-29.68,0.206
3.22,-29.56,0.206
3.23,-29.44,0.206
3.24,-29.33,0.206
3.26,-29.21,0.206
3.27,-29.09,0.206
3.28,-28.98,0.206
3.29,-28.86,0.206
3.30,-28.74,0.206
3.31,-28.62,0.206
3.33,-28.51,0.207
3.34,-28.39,0.207
3.35,-28.28,0.207
3.36,-28.16,0.207
3.37,-28.04,0.207
3.38,-27.92,0.207
3.39,-27.81,0.207
3.41,-27.69,0.207
3.42,-27.57,0.207
3.43,-27.46,0.207
3.44,-27.34,0.207
3.45,-27.22,0.207
3.46,-27.11,0.208
3.48,-26.99,0.208
3.49,-26.87,0.208
3.50,-26.76,0.208
3.51,-26.64,0.208
3.52,-26.52,0.208
3.54,-26.41,0.208
3.55,-26.29,0.208
3.56,-26.17,0.208
3.57,-26.06,0.208
3.58,-25.94,0.209
3.59,-25.82,0.209
3.61,-25.71,0.209
3.62,-25.59,0.209
3.63,-25.47,0.209
3.64,-25.36,0.209
3.65,-25.24,0.209
3.66,-25.12,0.209
3.68,-25.01,0.209
3.69,-24.89,0.209
3.70,-24.77,0.209
3.71,-24.66,0.210
3.72,-24.54,0.210
3.73,-24.42,0.210
3.74,-24.31,0.210
3.76,-24.19,0.210
3.77,-24.07,0.210
3.78,-23.95,0.210
3.79,-23.84,0.210
3.80,-23.72,0.210
3.81,-23.60,0.210
3.83,-23.49,0.211
3.84,-23.37,0.211
3.85,-23.25,0.211
3.86,-23.14,0.211
3.87,-23.02,0.211
3.89,-22.90,0.211
3.90,-22.79,0.211
3.91,-22.67,0.211
3.92,-22.55,0.211
3.93,-22.44,0.211
3.94,-22.32,0.211
3.96,-22.20,0.212
3.97,-22.09,0.212
3.98,-21.97,0.212
3.99,-21.85,0.212
4.00,-21.74,0.212
4.01,-21.62,0.212
4.03,-21.50,0.212
4.04,-21.39,0.212
4.05,-21.27,0.212
4.06,-21.15,0.212
4.07,-21.04,0.213
4.08,-20.92,0.213
4.09,-20.80,0.213
4.11,-20.69,0.213
4.12,-20.57,0.213
4.13,-20.45,0.213
4.14,-20.34,0.213
4.15,-20.22,0.213
4.16,-20.10,0.213
4.18,-19.98,0.213
4.19,-19.87,0.213
4.20,-19.75,0.214
4.21,-19.63,0.214
4.22,-19.52,0.214
4.24,-19.40,0.214
4.25,-19.28,0.214
4.26,-19.17,0.214
4.27,-19.05,0.214
4.28,-18.93,0.214
4.29,-18.82,0.214
4.30,-18.70,0.215
4.32,-18.58,0.215
4.33,-18.47,0.215
4.34,-18.35,0.215
4.35,-18.23,0.215
4.36,-18.12,0.215
4.38,-18.00,0.215
4.39,-17.88,0.215
4.40,-17.77,0.215
4.41,-17.65,0.216
4.42,-17.53,0.216
4.43,-17.42,0.216
4.45,-17.30,0.216
4.46,-17.18,0.216
4.47,-17.07,0.216
4.48,-16.95,0.216
4.49,-16.83,0.216
4.50,-16.72,0.217
4.51,-16.60,0.217
4.53,-16.48,0.217
4.54,-16.37,0.217
4.55,-16.25,0.217
4.56,-16.13,0.217
4.57,-16.02,0.217
4.59,-15.90,0.217
4.60,-15.78,0.217
4.61,-15.67,0.218
4.62,-15.55,0.218
4.63,-15.43,0.218
4.64,-15.32,0.218
4.65,-15.20,0.218
4.67,-15.08,0.218
4.68,-14.97,0.218
4.69,-14.85,0.218
4.70,-14.73,0.219
4.71,-14.62,0.219
4.73,-14.50,0.219
4.74,-14.38,0.219
4.75,-14.27,0.219
4.76,-14.15,0.219
4.77,-14.03,0.220
4.78,-13.91,0.220
4.80,-13.80,0.220
4.81,-13.68,0.220
4.82,-13.56,0.220
4.83,-13.45,0.220
4.84,-13.33,0.220
4.85,-13.21,0.220
4.86,-13.10,0.221
4.88,-12.98,0.221
4.89,-12.87,0.221
4.90,-12.75,0.221
4.91,-12.63,0.221
4.92,-12.52,0.222
4.94,-12.40,0.222
4.95,-12.28,0.222
4.96,-12.16,0.222
4.97,-12.05,0.222
4.98,-11.93,0.222
4.99,-11.81,0.223
5.00,-11.70,0.223
5.02,-11.58,0.223
5.03,-11.47,0.223
5.04,-11.35,0.223
5.05,-11.23,0.224
5.06,-11.12,0.224
5.08,-11.00,0.224
5.09,-10.88,0.224
5.10,-10.77,0.224
5.11,-10.65,0.224
5.12,-10.53,0.224
5.13,-10.42,0.225
5.15,-10.30,0.225
5.16,-10.18,0.225
5.17,-10.07,0.225
5.18,-9.95,0.226
5.19,-9.83,0.226
5.20,-9.72,0.226
5.21,-9.60,0.227
5.23,-9.48,0.227
5.24,-9.37,0.227
5.25,-9.25,0.227
5.26,-9.13,0.228
5.27,-9.02,0.228
5.29,-8.90,0.228
5.30,-8.79,0.229
5.31,-8.67,0.229
5.32,-8.55,0.229
5.33,-8.43,0.230
5.34,-8.32,0.230
5.35,-8.20,0.230
5.37,-8.09,0.231
5.38,-7.97,0.231
5.39,-7.85,0.231
5.40,-7.74,0.232
5.41,-7.62,0.232
5.43,-7.50,0.233
5.44,-7.39,0.233
5.45,-7.27,0.233
5.46,-7.15,0.234
5.47,-7.04,0.234
5.48,-6.92,0.235
5.50,-6.80,0.235
5.51,-6.69,0.235
5.52,-6.57,0.236
5.53,-6.45,0.236
5.54,-6.34,0.237
5.55,-6.22,0.238
5.56,-6.11,0.238
5.58,-5.99,0.238
5.59,-5.87,0.239
5.60,-5.76,0.239
5.61,-5.64,0.240
5.62,-5.53,0.241
5.64,-5.41,0.241
5.65,-5.29,0.242
5.66,-5.18,0.243
5.67,-5.06,0.243
5.68,-4.94,0.243
5.69,-4.83,0.244
5.70,-4.71,0.245
5.72,-4.60,0.246
5.73,-4.48,0.246
5.74,-4.37,0.247
5.75,-4.25,0.248
5.76,-4.13,0.249
5.78,-4.02,0.249
5.79,-3.90,0.250
5.80,-3.79,0.251
5.81,-3.67,0.252
5.82,-3.55,0.253
5.83,-3.44,0.253
5.85,-3.32,0.255
5.86,-3.21,0.255
5.87,-3.09,0.257
5.88,-2.97,0.257
5.89,-2.86,0.258
5.90,-2.74,0.259
5.91,-2.63,0.260
5.93,-2.51,0.261
5.94,-2.40,0.262
5.95,-2.28,0.264
5.96,-2.17,0.264
5.97,-2.05,0.266
5.99,-1.93,0.267
6.00,-1.82,0.268
6.01,-1.70,0.269
6.02,-1.59,0.270
6.03,-1.47,0.271
6.04,-1.36,0.272
6.05,-1.24,0.273
6.07,-1.13,0.275
6.08,-1.01,0.276
6.09,-0.90,0.278
6.10,-0.78,0.279
6.11,-0.66,0.280
6.13,-0.55,0.281
6.14,-0.43,0.283
6.15,-0.32,0.284
6.16,-0.20,0.285
6.17,-0.09,0.287
6.18,0.03,0.288
6.20,0.14,0.289
6.21,0.26,0.291
6.22,0.37,0.292
6.23,0.49,0.293
6.24,0.60,0.295
6.25,0.72,0.296
6.26,0.83,0.297
6.28,0.95,0.298
6.29,1.06,0.300
6.30,1.18,0.301
6.31,1.29,0.302
6.32,1.41,0.303
6.34,1.52,0.304
6.35,1.64,0.305
6.36,1.75,0.306
6.37,1.87,0.307
6.38,1.98,0.308
6.39,2.10,0.309
6.40,2.21,0.310
6.42,2.33,0.311
6.43,2.45,0.311
6.44,2.56,0.312
6.45,2.68,0.312
6.46,2.79,0.313
6.48,2.91,0.314
6.49,3.02,0.314
6.50,3.14,0.314
6.51,3.26,0.315
6.52,3.37,0.315
6.53,3.49,0.315
6.55,3.60,0.315
6.56,3.72,0.315
6.57,3.84,0.315
6.58,3.95,0.315
6.59,4.07,0.315
6.60,4.19,0.315
6.61,4.30,0.315
6.63,4.42,0.315
6.64,4.54,0.315
6.65,4.65,0.315
6.66,4.77,0.315
6.67,4.89,0.315
6.69,5.01,0.315
6.70,5.12,0.315
6.71,5.24,0.315
6.72,5.36,0.315
6.73,5.47,0.315
6.74,5.59,0.314
6.75,5.71,0.314
6.77,5.83,0.314
6.78,5.94,0.314
6.79,6.06,0.314
6.80,6.18,0.313
6.81,6.30,0.313
6.83,6.41,0.313
6.84,6.53,0.313
6.85,6.65,0.313
6.86,6.76,0.313
6.87,6.88,0.312
6.88,7.00,0.312
6.90,7.11,0.312
6.91,7.23,0.312
6.92,7.35,0.312
6.93,7.47,0.312
6.94,7.58,0.312
6.95,7.70,0.312
6.96,7.82,0.312
6.98,7.93,0.312
6.99,8.05,0.312
7.00,8.17,0.312
7.01,8.29,0.311
7.02,8.40,0.311
7.04,8.52,0.311
7.05,8.64,0.311
7.06,8.75,0.311
7.07,8.87,0.311
7.08,8.99,0.311
7.09,9.11,0.311
7.10,9.22,0.311
7.12,9.34,0.311
7.13,9.45,0.311
7.14,9.57,0.311
7.15,9.69,0.311
7.16,9.81,0.311
7.18,9.92,0.311
7.19,10.04,0.311
7.20,10.16,0.311
7.21,10.27,0.311
7.22,10.39,0.311
7.23,10.51,0.311
7.25,10.63,0.311
7.26,10.74,0.311
7.27,10.86,0.311
7.28,10.98,0.311
7.29,11.09,0.311
7.30,11.21,0.311
7.31,11.33,0.311
7.33,11.44,0.311
7.34,11.56,0.311
7.35,11.68,0.311
7.36,11.79,0.311
7.37,11.91,0.311
7.39,12.03,0.311
7.40,12.14,0.311
7.41,12.26,0.311
7.42,12.38,0.311
7.43,12.49,0.311
7.44,12.61,0.311
7.45,12.73,0.311
7.47,12.84,0.311
7.48,12.96,0.311
7.49,13.08,0.311
7.50,13.20,0.311
7.51,13.31,0.311
7.53,13.43,0.311
7.54,13.55,0.311
7.55,13.66,0.312
7.56,13.78,0.312
7.57,13.90,0.312
7.58,14.01,0.312
7.60,14.13,0.312
7.61,14.25,0.312
7.62,14.36,0.312
7.63,14.48,0.312
7.64,14.60,0.312
7.65,14.71,0.312
7.66,14.83,0.312
7.68,14.95,0.312
7.69,15.07,0.312
7.70,15.18,0.312
7.71,15.30,0.313
7.72,15.42,0.313
7.74,15.53,0.313
7.75,15.65,0.313
7.76,15.77,0.313
7.77,15.88,0.313
7.78,16.00,0.313
7.79,16.12,0.313
7.80,16.23,0.313
7.82,16.35,0.313
7.83,16.47,0.313
7.84,16.58,0.313
7.85,16.70,0.313
7.86,16.82,0.313
7.88,16.93,0.313
7.89,17.05,0.313
7.90,17.17,0.314
7.91,17.28,0.314
7.92,17.40,0.314
7.93,17.52,0.314
7.95,17.64,0.314
7.96,17.75,0.314
7.97,17.87,0.314
7.98,17.99,0.314
7.99,18.10,0.314
8.00,18.22,0.314
8.01,18.34,0.314
8.03,18.45,0.314
8.04,18.57,0.315
8.05,18.69,0.315
8.06,18.80,0.315
8.07,18.92,0.315
8.09,19.04,0.315
8.10,19.15,0.315
8.11,19.27,0.315
8.12,19.39,0.315
8.13,19.50,0.315
8.14,19.62,0.315
8.15,19.74,0.315
8.17,19.85,0.316
8.18,19.97,0.316
8.19,20.09,0.316
8.20,20.20,0.316
8.21,20.32,0.316
8.23,20.44,0.316
8.24,20.55,0.316
8.25,20.67,0.316
8.26,20.79,0.316
8.27,20.90,0.316
8.28,21.02,0.316
8.30,21.14,0.317
8.31,21.25,0.317
8.32,21.37,0.317
8.33,21.49,0.317
8.34,21.61,0.317
8.35,21.72,0.317
8.36,21.84,0.317
8.38,21.96,0.317
8.39,22.07,0.317
8.40,22.19,0.317
8.41,22.31,0.317
8.42,22.42,0.318
8.44,22.54,0.318
8.45,22.66,0.318
8.46,22.77,0.318
8.47,22.89,0.318
8.48,23.01,0.318
8.49,23.12,0.318
8.50,23.24,0.318
8.52,23.36,0.318
8.53,23.47,0.318
8.54,23.59,0.318
8.55,23.71,0.319
8.56,23.82,0.319
8.58,23.94,0.319
8.59,24.06,0.319
8.60,24.17,0.319
8.61,24.29,0.319
8.62,24.41,0.319
8.63,24.52,0.319
8.65,24.64,0.319
8.66,24.76,0.319
8.67,24.87,0.319
8.68,24.99,0.320
8.69,25.11,0.320
8.70,25.22,0.320
8.72,25.34,0.320
8.73,25.46,0.320
8.74,25.57,0.320
8.75,25.69,0.320
8.76,25.81,0.320
8.77,25.92,0.320
8.78,26.04,0.320
8.80,26.16,0.320
8.81,26.28,0.320
8.82,26.39,0.321
8.83,26.51,0.321
8.84,26.63,0.321
8.85,26.74,0.321
8.87,26.86,0.321
8.88,26.98,0.321
8.89,27.09,0.321
8.90,27.21,0.321
8.91,27.33,0.321
8.93,27.44,0.321
8.94,27.56,0.321
8.95,27.68,0.322
8.96,27.79,0.322
8.97,27.91,0.322
8.98,28.03,0.322
9.00,28.14,0.322
9.01,28.26,0.322
9.02,28.38,0.322
9.03,28.49,0.322
9.04,28.61,0.322
9.05,28.73,0.322
9.07,28.84,0.322
9.08,28.96,0.322
9.09,29.08,0.323
9.10,29.20,0.323
9.11,29.31,0.323
9.12,29.43,0.323
9.13,29.55,0.323
9.15,29.66,0.323
9.16,29.78,0.323
9.17,29.90,0.323
9.18,30.01,0.323
9.19,30.13,0.323
9.20,30.25,0.324
9.22,30.36,0.324
9.23,30.48,0.324
9.24,30.60,0.324
9.25,30.72,0.324
9.26,30.83,0.324
9.28,30.95,0.324
9.29,31.07,0.324
9.30,31.18,0.324
9.31,31.30,0.324
9.32,31.42,0.324
9.33,31.53,0.324
9.35,31.65,0.324
9.36,31.77,0.324
9.37,31.88,0.325
9.38,32.00,0.325
9.39,32.12,0.325
9.40,32.23,0.325
9.42,32.35,0.325
9.43,32.47,0.325
9.44,32.58,0.325
9.45,32.70,0.325
9.46,32.82,0.325
9.47,32.93,0.325
9.48,33.05,0.325
9.50,33.17,0.325
9.51,33.28,0.326
9.52,33.40,0.326
9.53,33.52,0.326
9.54,33.64,0.326
9.55,33.75,0.326
9.57,33.87,0.326
9.58,33.99,0.326
9.59,34.10,0.326
9.60,34.22,0.326
9.61,34.34,0.326
9.63,34.45,0.326
9.64,34.57,0.326
9.65,34.69,0.326
9.66,34.80,0.326
9.67,34.92,0.327
9.68,35.04,0.327
9.70,35.15,0.327
9.71,35.27,0.327
9.72,35.39,0.327
9.73,35.50,0.327
9.74,35.62,0.327
9.75,35.74,0.327
9.77,35.86,0.327
9.78,35.97,0.327
9.79,36.09,0.327
9.80,36.20,0.327
9.81,36.32,0.327
9.82,36.44,0.327
9.83,36.56,0.328
9.85,36.67,0.328
9.86,36.79,0.328
9.87,36.91,0.328
9.88,37.02,0.328
9.89,37.14,0.328
9.90,37.26,0.328
9.92,37.37,0.328
9.93,37.49,0.328
9.94,37.61,0.328
9.95,37.72,0.328
9.96,37.84,0.328
9.98,37.96,0.328
9.99,38.07,0.329
10.00,38.19,0.329
10.01,38.31,0.329
10.02,38.43,0.329
10.03,38.54,0.329
10.05,38.66,0.329
10.06,38.78,0.329
10.07,38.89,0.329
10.08,39.01,0.329
10.09,39.13,0.329
10.10,39.24,0.329
10.12,39.36,0.329
10.13,39.48,0.329
10.14,39.59,0.329
10.15,39.71,0.330
10.16,39.83,0.330
10.17,39.94,0.330
10.18,40.06,0.330
10.20,40.18,0.330
10.21,40.29,0.330
10.22,40.41,0.330
10.23,40.53,0.330
10.24,40.65,0.330
10.25,40.76,0.330
10.27,40.88,0.330
10.28,41.00,0.330
10.29,41.11,0.331
10.30,41.23,0.331
10.31,41.34,0.331
10.33,41.46,0.331
10.34,41.58,0.331
10.35,41.70,0.331
10.36,41.81,0.331
10.37,41.93,0.331
10.38,42.05,0.331
10.40,42.16,0.331
10.41,42.28,0.331
10.42,42.40,0.331
10.43,42.51,0.331
10.44,42.63,0.332
10.45,42.75,0.332
10.47,42.86,0.332
10.48,42.98,0.332
10.49,43.10,0.332
10.50,43.21,0.332
10.51,43.33,0.332
10.52,43.45,0.332
10.53,43.56,0.332
10.55,43.68,0.332
10.56,43.80,0.332
10.57,43.92,0.332
10.58,44.03,0.333
10.59,44.15,0.333
10.60,44.27,0.333
10.62,44.38,0.333
10.63,44.50,0.333
10.64,44.62,0.333
10.65,44.73,0.333
10.66,44.85,0.333
10.68,44.97,0.333
10.69,45.08,0.333
10.70,45.20,0.333
10.71,45.32,0.333
10.72,45.43,0.333
10.73,45.55,0.333
10.75,45.67,0.334
10.76,45.79,0.334
10.77,45.90,0.334
10.78,46.02,0.334
10.79,46.13,0.334
10.80,46.25,0.334
10.82,46.37,0.334
10.83,46.48,0.334
10.84,46.60,0.334
10.85,46.72,0.334
10.86,46.84,0.334
10.87,46.95,0.335
10.88,47.07,0.335
10.90,47.19,0.335
10.91,47.30,0.335
10.92,47.42,0.335
10.93,47.54,0.335
10.94,47.65,0.335
10.95,47.77,0.335
10.97,47.89,0.335
10.98,48.00,0.335
10.99,48.12,0.335
11.00,48.24,0.335
11.01,48.36,0.336
11.03,48.47,0.336
11.04,48.59,0.336
11.05,48.71,0.336
11.06,48.82,0.336
11.07,48.94,0.336
11.08,49.06,0.336
11.10,49.17,0.336
11.11,49.29,0.336
11.12,49.41,0.336
11.13,49.52,0.336
11.14,49.64,0.337
11.15,49.76,0.337
11.17,49.87,0.337
11.18,49.99,0.337
11.19,50.11,0.337
11.20,50.22,0.337
11.21,50.34,0.337
11.22,50.46,0.337
11.23,50.57,0.337
11.25,50.69,0.337
11.26,50.81,0.337
11.27,50.92,0.337
11.28,51.04,0.337
11.29,51.16,0.337
11.30,51.27,0.337
11.32,51.39,0.337
11.33,51.51,0.338
11.34,51.63,0.338
11.35,51.74,0.338
11.36,51.86,0.338
11.38,51.97,0.338
11.39,52.09,0.338
11.40,52.21,0.338
11.41,52.33,0.338
11.42,52.44,0.338
11.43,52.56,0.338
11.45,52.68,0.338
11.46,52.79,0.338
11.47,52.91,0.338
11.48,53.03,0.338
11.49,53.14,0.338
11.50,53.26,0.339
11.52,53.38,0.339
11.53,53.49,0.339
11.54,53.61,0.339
11.55,53.73,0.339
11.56,53.84,0.339
11.57,53.96,0.339
11.58,54.08,0.339
11.60,54.19,0.339
11.61,54.31,0.339
11.62,54.43,0.339
11.63,54.55,0.339
11.64,54.66,0.339
11.65,54.78,0.339
11.67,54.90,0.339
11.68,55.01,0.340
11.69,55.13,0.340
11.70,55.25,0.340
11.71,55.36,0.340
11.73,55.48,0.340
11.74,55.60,0.340
11.75,55.71,0.340
11.76,55.83,0.340
11.77,55.95,0.340
11.78,56.06,0.340
11.80,56.18,0.340
11.81,56.30,0.340
11.82,56.41,0.341
11.83,56.53,0.341
11.84,56.65,0.341
11.85,56.76,0.341
11.87,56.88,0.341
11.88,57.00,0.341
11.89,57.11,0.341
11.90,57.23,0.341
11.91,57.35,0.341
11.92,57.46,0.341
11.93,57.58,0.341
11.95,57.70,0.341
11.96,57.81,0.341
11.97,57.93,0.341
11.98,58.05,0.342
11.99,58.17,0.342
12.00,58.28,0.342
12.02,58.40,0.342
12.03,58.52,0.342
12.04,58.63,0.342
12.05,58.75,0.342
12.06,58.87,0.342
12.08,58.98,0.342
12.09,59.10,0.342
12.10,59.22,0.342
12.11,59.33,0.342
12.12,59.45,0.342
12.13,59.57,0.342
12.15,59.69,0.342
12.16,59.80,0.342
12.17,59.92,0.342
12.18,60.04,0.342
12.19,60.15,0.343
12.20,60.27,0.343
12.22,60.38,0.343
12.23,60.50,0.343
12.24,60.62,0.343
12.25,60.74,0.343
12.26,60.85,0.343
12.27,60.97,0.343
12.28,61.09,0.343
12.30,61.20,0.343
12.31,61.32,0.343
12.32,61.44,0.343
12.33,61.55,0.343
12.34,61.67,0.343
12.35,61.79,0.343
12.37,61.90,0.343
12.38,62.02,0.344
12.39,62.14,0.344
12.40,62.26,0.344
12.41,62.37,0.344
12.43,62.49,0.344
12.44,62.61,0.344
12.45,62.72,0.344
12.46,62.84,0.344
12.47,62.96,0.344
12.48,63.07,0.344
12.50,63.19,0.344
12.51,63.31,0.344
12.52,63.42,0.344
12.53,63.54,0.344
12.54,63.66,0.344
12.55,63.77,0.345
12.57,63.89,0.345
12.58,64.01,0.345
12.59,64.12,0.345
12.60,64.24,0.345
12.61,64.36,0.345
12.62,64.48,0.345
12.63,64.59,0.345
12.65,64.71,0.345
12.66,64.83,0.345
12.67,64.94,0.345
12.68,65.06,0.345
12.69,65.18,0.345
12.70,65.29,0.345
12.72,65.41,0.346
12.73,65.53,0.346
12.74,65.64,0.346
12.75,65.76,0.346
12.76,65.88,0.346
12.78,66.00,0.346
12.79,66.11,0.346
12.80,66.23,0.346
12.81,66.35,0.346
12.82,66.46,0.346
12.83,66.58,0.346
12.85,66.70,0.346
12.86,66.81,0.346
12.87,66.93,0.346
12.88,67.05,0.346
12.89,67.16,0.347
12.90,67.28,0.347
12.92,67.40,0.347
12.93,67.51,0.347
12.94,67.63,0.347
12.95,67.75,0.347
12.96,67.86,0.347
12.97,67.98,0.347
12.98,68.10,0.347
13.00,68.21,0.347
13.01,68.33,0.347
13.02,68.45,0.347
13.03,68.56,0.347
13.04,68.68,0.347
13.05,68.80,0.347
13.07,68.91,0.347
13.08,69.03,0.347
13.09,69.15,0.348
13.10,69.26,0.348
13.11,69.38,0.348
13.13,69.50,0.348
13.14,69.61,0.348
13.15,69.73,0.348
13.16,69.85,0.348
13.17,69.97,0.348
13.18,70.08,0.348
13.20,70.20,0.348
13.21,70.31,0.348
13.22,70.43,0.348
13.23,70.55,0.348
13.24,70.67,0.349
13.25,70.78,0.349
13.27,70.90,0.349
13.28,71.02,0.349
13.29,71.13,0.349
13.30,71.25,0.349
13.31,71.37,0.349
13.32,71.48,0.349
13.33,71.60,0.349
13.35,71.72,0.349
13.36,71.83,0.349
13.37,71.95,0.349
13.38,72.07,0.349
13.39,72.18,0.349
13.40,72.30,0.349
13.42,72.42,0.349
13.43,72.54,0.349
13.44,72.65,0.349
13.45,72.77,0.350
13.46,72.89,0.350
13.48,73.00,0.350
13.49,73.12,0.350
13.50,73.23,0.350
13.51,73.35,0.350
13.52,73.47,0.350
13.53,73.59,0.350
13.55,73.70,0.350
13.56,73.82,0.350
13.57,73.94,0.350
13.58,74.05,0.350
13.59,74.17,0.350
13.60,74.29,0.350
13.62,74.40,0.350
13.63,74.52,0.350
13.64,74.64,0.350
13.65,74.75,0.350
13.66,74.87,0.350
13.67,74.99,0.351
13.68,75.10,0.351
13.70,75.22,0.351
13.71,75.34,0.351
13.72,75.45,0.351
13.73,75.57,0.351
13.74,75.69,0.351
13.75,75.81,0.351
13.77,75.92,0.351
13.78,76.04,0.351
13.79,76.16,0.351
13.80,76.27,0.351
13.81,76.39,0.351
13.83,76.51,0.351
13.84,76.62,0.351
13.85,76.74,0.351
13.86,76.86,0.351
13.87,76.97,0.351
13.88,77.09,0.352
13.90,77.21,0.352
13.91,77.32,0.352
13.92,77.44,0.352
13.93,77.56,0.352
13.94,77.67,0.352
13.95,77.79,0.352
13.97,77.91,0.352
13.98,78.02,0.352
13.99,78.14,0.352
14.00,78.26,0.352
14.01,78.37,0.352
14.02,78.49,0.352
14.03,78.61,0.352
14.05,78.73,0.352
14.06,78.84,0.353
14.07,78.96,0.353
14.08,79.08,0.353
14.09,79.19,0.353
14.10,79.31,0.353
14.12,79.43,0.353
14.13,79.54,0.353
14.14,79.66,0.353
14.15,79.78,0.353
14.16,79.89,0.353
14.18,80.01,0.353
14.19,80.13,0.353
14.20,80.24,0.353
14.21,80.36,0.353
14.22,80.48,0.353
14.23,80.59,0.353
14.25,80.71,0.353
14.26,80.83,0.353
14.27,80.94,0.353
14.28,81.06,0.353
14.29,81.18,0.354
14.30,81.30,0.354
14.32,81.41,0.354
14.33,81.53,0.354
14.34,81.65,0.354
14.35,81.76,0.354
14.36,81.88,0.354
14.37,82.00,0.354
14.38,82.11,0.354
14.40,82.23,0.354
14.41,82.35,0.354
14.42,82.46,0.354
14.43,82.58,0.354
14.44,82.70,0.354
14.45,82.81,0.354
14.47,82.93,0.354
14.48,83.05,0.354
14.49,83.17,0.354
14.50,83.28,0.354
14.51,83.40,0.354
14.53,83.51,0.354
14.54,83.63,0.354
14.55,83.75,0.354
14.56,83.87,0.355
14.57,83.98,0.355
14.58,84.10,0.355
14.60,84.22,0.355
14.61,84.33,0.355
14.62,84.45,0.355
14.63,84.57,0.355
14.64,84.68,0.355
14.65,84.80,0.355
14.67,84.92,0.355
14.68,85.03,0.355
14.69,85.15,0.355
14.70,85.27,0.355
14.71,85.38,0.355
14.72,85.50,0.355
14.73,85.62,0.355
14.75,85.73,0.355
14.76,85.85,0.355
14.77,85.97,0.355
14.78,86.08,0.355
14.79,86.20,0.355
14.80,86.32,0.355
14.82,86.44,0.356
14.83,86.55,0.356
14.84,86.67,0.356
14.85,86.78,0.356
14.86,86.90,0.356
14.88,87.02,0.356
14.89,87.14,0.356
14.90,87.25,0.356
14.91,87.37,0.356
14.92,87.49,0.356
14.93,87.60,0.356
14.95,87.72,0.356
14.96,87.84,0.356
14.97,87.95,0.356
14.98,88.07,0.356
14.99,88.19,0.356
15.00,88.31,0.356
15.02,88.42,0.356
15.03,88.54,0.357
15.04,88.66,0.357
15.05,88.77,0.357
15.06,88.89,0.357
15.07,89.01,0.357
15.08,89.13,0.357
15.10,89.24,0.357
15.11,89.36,0.357
15.12,89.48,0.357
15.13,89.59,0.358
15.14,89.71,0.358
15.15,89.83,0.358
15.17,89.94,0.358
15.18,90.06,0.358
15.19,90.18,0.358
15.20,90.29,0.358
15.21,90.41,0.358
15.23,90.53,0.358
15.24,90.64,0.358
15.25,90.76,0.358
15.26,90.88,0.358
15.27,90.99,0.358
15.28,91.11,0.358
15.30,91.23,0.358
15.31,91.34,0.358
15.32,91.46,0.358
15.33,91.58,0.358
15.34,91.69,0.358
15.35,91.81,0.358
15.37,91.93,0.358
15.38,92.04,0.358
15.39,92.16,0.358
15.40,92.28,0.358
15.41,92.39,0.358
15.42,92.51,0.358
15.43,92.63,0.358
15.45,92.75,0.358
15.46,92.86,0.358
15.47,92.98,0.358
15.48,93.10,0.358
15.49,93.21,0.358
15.50,93.33,0.358
15.52,93.45,0.358
15.53,93.56,0.359
15.54,93.68,0.359
15.55,93.80,0.359
15.56,93.91,0.359
15.58,94.03,0.359
15.59,94.15,0.359
15.60,94.26,0.359
15.61,94.38,0.359
15.62,94.50,0.359
15.63,94.61,0.359
15.65,94.73,0.359
15.66,94.85,0.359
15.67,94.96,0.359
15.68,95.08,0.359
15.69,95.20,0.359
15.70,95.31,0.359
15.72,95.43,0.359
15.73,95.55,0.359
15.74,95.67,0.359
15.75,95.78,0.359
15.76,95.90,0.360
15.77,96.02,0.360
15.78,96.13,0.360
15.80,96.25,0.360
15.81,96.37,0.360
15.82,96.48,0.360
15.83,96.60,0.360
15.84,96.72,0.360
15.85,96.83,0.360
15.87,96.95,0.360
15.88,97.07,0.360
15.89,97.18,0.360
15.90,97.30,0.360
15.91,97.42,0.360
15.93,97.53,0.360
15.94,97.65,
15.95,97.77,
15.96,97.88,
15.97,98.00,
15.98,98.12,
15.99,,

[step]
Ramp 10.00 °C/min to -60.00 °C
Time,Temperature,Heat Flow (Normalized)
min,°C,W/g
17.99,100.13,-0.011
18.01,100.13,-0.011
18.02,100.13,-0.011
18.03,100.12,-0.011
18.04,100.12,-0.011
18.05,100.11,-0.011
18.06,100.09,-0.013
18.08,100.07,-0.019
18.09,100.04,-0.026
18.10,100.01,-0.037
18.11,99.96,-0.050
18.12,99.91,-0.067
18.13,99.85,-0.085
18.14,99.79,-0.105
18.16,99.73,-0.123
18.17,99.65,-0.142
18.18,99.58,-0.159
18.19,99.50,-0.175
18.20,99.42,-0.190
18.22,99.34,-0.204
18.23,99.26,-0.216
18.24,99.17,-0.228
18.25,99.08,-0.239
18.26,98.99,-0.249
18.27,98.90,-0.258
18.28,98.80,-0.268
18.30,98.71,-0.277
18.31,98.61,-0.284
18.32,98.51,-0.291
18.33,98.41,-0.298
18.34,98.31,-0.304
18.36,98.21,-0.309
18.37,98.11,-0.315
18.38,98.00,-0.319
18.39,97.90,-0.324
18.40,97.79,-0.328
18.41,97.68,-0.332
18.43,97.58,-0.336
18.44,97.47,-0.339
18.45,97.36,-0.342
18.46,97.25,-0.345
18.47,97.14,-0.347
18.48,97.03,-0.350
18.49,96.92,-0.352
18.51,96.81,-0.354
18.52,96.70,-0.356
18.53,96.59,-0.358
18.54,96.48,-0.359
18.55,96.37,-0.360
18.57,96.25,-0.362
18.58,96.14,-0.363
18.59,96.03,-0.365
18.60,95.91,-0.366
18.61,95.80,-0.367
18.62,95.69,-0.367
18.63,95.58,-0.368
18.65,95.46,-0.369
18.66,95.35,-0.370
18.67,95.23,-0.371
18.68,95.12,-0.371
18.69,95.01,-0.372
18.71,94.89,-0.372
18.72,94.78,-0.372
18.73,94.66,-0.373
18.74,94.55,-0.373
18.75,94.43,-0.374
18.76,94.32,-0.374
18.78,94.20,-0.375
18.79,94.09,-0.375
18.80,93.97,-0.375
18.81,93.86,-0.375
18.82,93.74,-0.375
18.83,93.63,-0.376
18.84,93.51,-0.376
18.86,93.40,-0.376
18.87,93.28,-0.376
18.88,93.16,-0.377
18.89,93.05,-0.377
18.90,92.93,-0.377
18.92,92.82,-0.377
18.93,92.70,-0.377
18.94,92.59,-0.377
18.95,92.47,-0.377
18.96,92.36,-0.377
18.97,92.24,-0.377
18.98,92.12,-0.377
19.00,92.01,-0.377
19.01,91.89,-0.377
19.02,91.78,-0.377
19.03,91.66,-0.378
19.04,91.54,-0.378
19.06,91.43,-0.378
19.07,91.31,-0.378
19.08,91.19,-0.378
19.09,91.08,-0.378
19.10,90.96,-0.378
19.11,90.85,-0.378
19.13,90.73,-0.378
19.14,90.61,-0.378
19.15,90.50,-0.378
19.16,90.38,-0.378
19.17,90.27,-0.378
19.18,90.15,-0.378
19.19,90.03,-0.378
19.21,89.92,-0.378
19.22,89.80,-0.378
19.23,89.69,-0.378
19.24,89.57,-0.378
19.25,89.45,-0.378
19.27,89.34,-0.378
19.28,89.22,-0.378
19.29,89.10,-0.378
19.30,88.99,-0.378
19.31,88.87,-0.378
19.32,88.75,-0.378
19.33,88.64,-0.378
19.35,88.52,-0.378
19.36,88.40,-0.378
19.37,88.29,-0.378
19.38,88.17,-0.378
19.39,88.06,-0.378
19.41,87.94,-0.378
19.42,87.82,-0.378
19.43,87.71,-0.378
19.44,87.59,-0.378
19.45,87.47,-0.378
19.46,87.36,-0.378
19.48,87.24,-0.378
19.49,87.12,-0.378
19.50,87.01,-0.377
19.51,86.89,-0.377
19.52,86.78,-0.377
19.53,86.66,-0.377
19.54,86.54,-0.377
19.56,86.43,-0.377
19.57,86.31,-0.377
19.58,86.19,-0.377
19.59,86.08,-0.377
19.60,85.96,-0.377
19.62,85.84,-0.377
19.63,85.73,-0.377
19.64,85.61,-0.377
19.65,85.49,-0.377
19.66,85.38,-0.377
19.67,85.26,-0.377
19.68,85.15,-0.377
19.70,85.03,-0.377
19.71,84.91,-0.377
19.72,84.80,-0.377
19.73,84.68,-0.377
19.74,84.56,-0.377
19.76,84.45,-0.377
19.77,84.33,-0.376
19.78,84.21,-0.376
19.79,84.10,-0.376
19.80,83.98,-0.376
19.81,83.86,-0.376
19.83,83.75,-0.376
19.84,83.63,-0.376
19.85,83.51,-0.376
19.86,83.40,-0.376
19.87,83.28,-0.376
19.88,83.17,-0.376
19.89,83.05,-0.376
19.91,82.93,-0.376
19.92,82.82,-0.376
19.93,82.70,-0.376
19.94,82.58,-0.376
19.95,82.47,-0.376
19.97,82.35,-0.376
19.98,82.23,-0.376
19.99,82.12,-0.376
20.00,82.00,-0.375
20.01,81.88,-0.375
20.02,81.77,-0.375
20.03,81.65,-0.375
20.05,81.53,-0.375
20.06,81.42,-0.375
20.07,81.30,-0.375
20.08,81.18,-0.375
20.09,81.07,-0.375
20.11,80.95,-0.375
20.12,80.84,-0.375
20.13,80.72,-0.375
20.14,80.60,-0.375
20.15,80.49,-0.375
20.16,80.37,-0.375
20.18,80.25,-0.375
20.19,80.14,-0.375
20.20,80.02,-0.375
20.21,79.90,-0.375
20.22,79.79,-0.375
20.23,79.67,-0.374
20.24,79.55,-0.374
20.26,79.44,-0.374
20.27,79.32,-0.374
20.28,79.20,-0.374
20.29,79.09,-0.374
20.30,78.97,-0.374
20.32,78.85,-0.374
20.33,78.74,-0.374
20.34,78.62,-0.374
20.35,78.51,-0.374
20.36,78.39,-0.374
20.37,78.27,-0.374
20.38,78.16,-0.374
20.40,78.04,-0.374
20.41,77.92,-0.373
20.42,77.81,-0.373
20.43,77.69,-0.373
20.44,77.57,-0.373
20.46,77.46,-0.373
20.47,77.34,-0.373
20.48,77.22,-0.373
20.49,77.11,-0.373
20.50,76.99,-0.373
20.51,76.87,-0.373
20.53,76.76,-0.373
20.54,76.64,-0.373
20.55,76.52,-0.373
20.56,76.41,-0.373
20.57,76.29,-0.373
20.58,76.17,-0.373
20.59,76.06,-0.373
20.61,75.94,-0.373
20.62,75.82,-0.372
20.63,75.71,-0.372
20.64,75.59,-0.372
20.65,75.47,-0.372
20.67,75.36,-0.372
20.68,75.24,-0.372
20.69,75.12,-0.372
20.70,75.01,-0.372
20.71,74.89,-0.372
20.72,74.78,-0.372
20.73,74.66,-0.372
20.75,74.54,-0.372
20.76,74.42,-0.372
20.77,74.31,-0.371
20.78,74.19,-0.371
20.79,74.08,-0.371
20.81,73.96,-0.371
20.82,73.84,-0.371
20.83,73.73,-0.371
20.84,73.61,-0.371
20.85,73.49,-0.371
20.86,73.38,-0.371
20.88,73.26,-0.371
20.89,73.14,-0.371
20.90,73.03,-0.371
20.91,72.91,-0.371
20.92,72.80,-0.371
20.93,72.68,-0.370
20.94,72.56,-0.370
20.96,72.45,-0.370
20.97,72.33,-0.370
20.98,72.21,-0.370
20.99,72.09,-0.370
21.00,71.98,-0.370
21.02,71.86,-0.370
21.03,71.75,-0.370
21.04,71.63,-0.370
21.05,71.51,-0.370
21.06,71.40,-0.370
21.07,71.28,-0.370
21.08,71.16,-0.369
21.10,71.05,-0.369
21.11,70.93,-0.369
21.12,70.81,-0.369
21.13,70.70,-0.369
21.14,70.58,-0.369
21.16,70.46,-0.369
21.17,70.35,-0.369
21.18,70.23,-0.369
21.19,70.11,-0.369
21.20,70.00,-0.369
21.21,69.88,-0.369
21.23,69.76,-0.369
21.24,69.65,-0.369
21.25,69.53,-0.369
21.26,69.41,-0.369
21.27,69.30,-0.368
21.28,69.18,-0.368
21.29,69.06,-0.368
21.31,68.95,-0.368
21.32,68.83,-0.368
21.33,68.71,-0.368
21.34,68.60,-0.368
21.35,68.48,-0.368
21.37,68.37,-0.368
21.38,68.25,-0.368
21.39,68.13,-0.368
21.40,68.02,-0.368
21.41,67.90,-0.368
21.42,67.78,-0.367
21.43,67.67,-0.367
21.45,67.55,-0.367
21.46,67.43,-0.367
21.47,67.32,-0.367
21.48,67.20,-0.367
21.49,67.08,-0.367
21.51,66.97,-0.367
21.52,66.85,-0.367
21.53,66.73,-0.367
21.54,66.62,-0.367
21.55,66.50,-0.367
21.56,66.39,-0.367
21.58,66.27,-0.367
21.59,66.15,-0.366
21.60,66.03,-0.366
21.61,65.92,-0.366
21.62,65.80,-0.366
21.63,65.68,-0.366
21.64,65.57,-0.366
21.66,65.45,-0.366
21.67,65.34,-0.366
21.68,65.22,-0.366
21.69,65.10,-0.366
21.70,64.99,-0.366
21.72,64.87,-0.366
21.73,64.75,-0.366
21.74,64.64,-0.365
21.75,64.52,-0.365
21.76,64.40,-0.365
21.77,64.29,-0.365
21.78,64.17,-0.365
21.80,64.05,-0.365
21.81,63.94,-0.365
21.82,63.82,-0.365
21.83,63.70,-0.365
21.84,63.59,-0.365
21.86,63.47,-0.365
21.87,63.35,-0.365
21.88,63.24,-0.365
21.89,63.12,-0.364
21.90,63.00,-0.364
21.91,62.89,-0.364
21.93,62.77,-0.364
21.94,62.65,-0.364
21.95,62.54,-0.364
21.96,62.42,-0.364
21.97,62.30,-0.364
21.98,62.19,-0.364
21.99,62.07,-0.364
22.01,61.95,-0.364
22.02,61.84,-0.364
22.03,61.72,-0.364
22.04,61.61,-0.364
22.05,61.49,-0.364
22.07,61.37,-0.364
22.08,61.26,-0.363
22.09,61.14,-0.363
22.10,61.02,-0.363
22.11,60.91,-0.363
22.12,60.79,-0.363
22.13,60.67,-0.363
22.15,60.56,-0.363
22.16,60.44,-0.363
22.17,60.32,-0.363
22.18,60.21,-0.363
22.19,60.09,-0.363
22.21,59.97,-0.363
22.22,59.86,-0.363
22.23,59.74,-0.363
22.24,59.62,-0.362
22.25,59.51,-0.362
22.26,59.39,-0.362
22.28,59.27,-0.362
22.29,59.16,-0.362
22.30,59.04,-0.362
22.31,58.93,-0.362
22.32,58.81,-0.362
22.33,58.69,-0.362
22.34,58.57,-0.362
22.36,58.46,-0.362
22.37,58.34,-0.362
22.38,58.23,-0.362
22.39,58.11,-0.362
22.40,57.99,-0.362
22.42,57.88,-0.361
22.43,57.76,-0.361
22.44,57.64,-0.361
22.45,57.53,-0.361
22.46,57.41,-0.361
22.47,57.29,-0.361
22.48,57.18,-0.361
22.50,57.06,-0.361
22.51,56.94,-0.361
22.52,56.83,-0.361
22.53,56.71,-0.361
22.54,56.59,-0.361
22.56,56.48,-0.361
22.57,56.36,-0.360
22.58,56.24,-0.360
22.59,56.13,-0.360
22.60,56.01,-0.360
22.61,55.89,-0.360
22.63,55.78,-0.360
22.64,55.66,-0.360
22.65,55.54,-0.360
22.66,55.43,-0.360
22.67,55.31,-0.360
22.68,55.20,-0.360
22.69,55.08,-0.360
22.71,54.96,-0.360
22.72,54.84,-0.360
22.73,54.73,-0.359
22.74,54.61,-0.359
22.75,54.50,-0.359
22.77,54.38,-0.359
22.78,54.26,-0.359
22.79,54.15,-0.359
22.80,54.03,-0.359
22.81,53.91,-0.359
22.82,53.80,-0.359
22.83,53.68,-0.359
22.85,53.56,-0.359
22.86,53.45,-0.359
22.87,53.33,-0.359
22.88,53.21,-0.359
22.89,53.10,-0.358
22.91,52.98,-0.358
22.92,52.86,-0.358
22.93,52.75,-0.358
22.94,52.63,-0.358
22.95,52.51,-0.358
22.96,52.40,-0.358
22.98,52.28,-0.358
22.99,52.16,-0.358
23.00,52.05,-0.358
23.01,51.93,-0.358
23.02,51.82,-0.358
23.03,51.70,-0.358
23.04,51.58,-0.357
23.06,51.47,-0.357
23.07,51.35,-0.357
23.08,51.23,-0.357
23.09,51.12,-0.357
23.10,51.00,-0.357
23.12,50.88,-0.357
23.13,50.77,-0.357
23.14,50.65,-0.357
23.15,50.53,-0.357
23.16,50.42,-0.357
23.17,50.30,-0.357
23.18,50.18,-0.357
23.20,50.07,-0.356
23.21,49.95,-0.356
23.22,49.83,-0.356
23.23,49.72,-0.356
23.24,49.60,-0.356
23.26,49.48,-0.356
23.27,49.37,-0.356
23.28,49.25,-0.356
[...]
110.08,-41.03,0.179
110.09,-40.96,0.180
110.10,-40.90,0.180
110.10,-40.83,0.180
110.11,-40.77,0.180
110.11,-40.70,0.180
110.12,-40.63,0.180
110.13,-40.56,0.180
110.14,-40.50,0.180
110.14,-40.43,0.180
110.15,-40.36,0.180
110.15,-40.30,0.180
110.16,-40.23,0.180
110.17,-40.16,0.180
110.18,-40.10,0.180
110.18,-40.03,0.180
110.19,-39.96,0.180
110.20,-39.90,0.180
110.20,-39.83,0.180
110.21,-39.76,0.180
110.21,-39.70,0.180
110.22,-39.63,0.180
110.23,-39.56,0.180
110.24,-39.50,0.181
110.24,-39.43,0.181
110.25,-39.36,0.181
110.25,-39.30,0.181
110.26,-39.23,0.181
110.27,-39.16,0.181
110.28,-39.10,0.181
110.28,-39.03,0.181
110.29,-38.96,0.181
110.30,-38.90,0.181
110.30,-38.83,0.181
110.31,-38.76,0.181
110.31,-38.70,0.181
110.32,-38.63,0.181
110.33,-38.56,0.181
110.34,-38.50,0.181
110.34,-38.43,0.181
110.35,-38.36,0.181
110.35,-38.29,0.181
110.36,-38.23,0.181
110.37,-38.16,0.181
110.38,-38.10,0.181
110.38,-38.03,0.182
110.39,-37.96,0.182
110.40,-37.90,0.182
110.40,-37.83,0.182
110.41,-37.76,0.182
110.41,-37.69,0.182
110.42,-37.63,0.182
110.43,-37.56,0.182
110.44,-37.50,0.182
110.44,-37.43,0.182
110.45,-37.36,0.182
110.45,-37.29,0.182
110.46,-37.23,0.182
110.47,-37.16,0.182
110.48,-37.10,0.182
110.48,-37.03,0.182
110.49,-36.96,0.182
110.50,-36.89,0.182
110.50,-36.83,0.182
110.51,-36.76,0.182
110.51,-36.69,0.182
110.52,-36.63,0.182
110.53,-36.56,0.183
110.54,-36.49,0.183
110.54,-36.43,0.183
110.55,-36.36,0.183
110.55,-36.29,0.183
110.56,-36.23,0.183
110.57,-36.16,0.183
110.58,-36.09,0.183
110.58,-36.03,0.183
110.59,-35.96,0.183
110.60,-35.89,0.183
110.60,-35.83,0.183
110.61,-35.76,0.183
110.61,-35.69,0.183
110.62,-35.63,0.183
110.63,-35.56,0.183
110.64,-35.49,0.183
110.64,-35.43,0.183
110.65,-35.36,0.183
110.65,-35.29,0.183
110.66,-35.23,0.183
110.67,-35.16,0.183
110.68,-35.09,0.184
110.68,-35.03,0.184
110.69,-34.96,0.184
110.70,-34.89,0.184
110.70,-34.83,0.184
110.71,-34.76,0.184
110.71,-34.69,0.184
110.72,-34.63,0.184
110.73,-34.56,0.184
110.74,-34.49,0.184
110.74,-34.43,0.184
110.75,-34.36,0.184
110.75,-34.29,0.184
110.76,-34.22,0.184
110.77,-34.16,0.184
110.78,-34.09,0.184
110.78,-34.02,0.184
110.79,-33.96,0.184
110.80,-33.89,0.184
110.80,-33.83,0.184
110.81,-33.76,0.184
110.81,-33.69,0.185
110.82,-33.62,0.185
110.83,-33.56,0.185
110.84,-33.49,0.185
110.84,-33.42,0.185
110.85,-33.36,0.185
110.85,-33.29,0.185
110.86,-33.22,0.185
110.87,-33.16,0.185
110.88,-33.09,0.185
110.88,-33.02,0.185
110.89,-32.96,0.185
110.90,-32.89,0.185
110.90,-32.82,0.185
110.91,-32.76,0.185
110.91,-32.69,0.185
110.92,-32.62,0.185
110.93,-32.56,0.185
110.94,-32.49,0.185
110.94,-32.42,0.185
110.95,-32.36,0.185
110.95,-32.29,0.185
110.96,-32.22,0.186
110.97,-32.16,0.186
110.98,-32.09,0.186
110.98,-32.02,0.186
110.99,-31.96,0.186
111.00,-31.89,0.186
111.00,-31.82,0.186
111.01,-31.75,0.186
111.01,-31.69,0.186
111.02,-31.62,0.186
111.03,-31.56,0.186
111.04,-31.49,0.186
111.04,-31.42,0.186
111.05,-31.36,0.186
111.05,-31.29,0.186
111.06,-31.22,0.186
111.07,-31.15,0.186
111.08,-31.09,0.186
111.08,-31.02,0.186
111.09,-30.95,0.187
111.10,-30.89,0.187
111.10,-30.82,0.187
111.11,-30.75,0.187
111.11,-30.69,0.187
111.12,-30.62,0.187
111.13,-30.55,0.187
111.14,-30.49,0.187
111.14,-30.42,0.187
111.15,-30.36,0.187
111.15,-30.29,0.187
111.16,-30.22,0.187
111.17,-30.15,0.187
111.18,-30.09,0.187
111.18,-30.02,0.187
111.19,-29.95,0.187
111.20,-29.89,0.187
111.20,-29.82,0.187
111.21,-29.75,0.187
111.21,-29.69,0.187
111.22,-29.62,0.187
111.23,-29.55,0.187
111.24,-29.49,0.187
111.24,-29.42,0.188
111.25,-29.35,0.188
111.25,-29.29,0.188
111.26,-29.22,0.188
111.27,-29.15,0.188
111.28,-29.09,0.188
111.28,-29.02,0.188
111.29,-28.95,0.188
111.30,-28.88,0.188
111.30,-28.82,0.188
111.31,-28.75,0.188
111.31,-28.68,0.188
111.32,-28.62,0.188
111.33,-28.55,0.188
111.34,-28.49,0.188
111.34,-28.42,0.188
111.35,-28.35,0.188
111.35,-28.28,0.188
111.36,-28.22,0.188
111.37,-28.15,0.189
111.38,-28.09,0.189
111.38,-28.02,0.189
111.39,-27.95,0.189
111.40,-27.88,0.189
111.40,-27.82,0.189
111.41,-27.75,0.189
111.41,-27.68,0.189
111.42,-27.62,0.189
111.43,-27.55,0.189
111.44,-27.48,0.189
111.44,-27.42,0.189
111.45,-27.35,0.189
111.45,-27.28,0.189
111.46,-27.22,0.189
111.47,-27.15,0.189
111.48,-27.08,0.189
111.48,-27.02,0.189
111.49,-26.95,0.189
111.50,-26.88,0.189
111.50,-26.82,0.189
111.51,-26.75,0.190
111.51,-26.68,0.190
111.52,-26.62,0.190
111.53,-26.55,0.190
111.54,-26.48,0.190
111.54,-26.42,0.190
111.55,-26.35,0.190
111.55,-26.28,0.190
111.56,-26.22,0.190
111.57,-26.15,0.190
111.58,-26.08,0.190
111.58,-26.02,0.190
111.59,-25.95,0.190
111.60,-25.88,0.190
111.60,-25.82,0.190
111.61,-25.75,0.190
111.61,-25.68,0.190
111.62,-25.62,0.190
111.63,-25.55,0.190
111.64,-25.48,0.190
111.64,-25.42,0.190
111.65,-25.35,0.191
111.65,-25.28,0.191
111.66,-25.22,0.191
111.67,-25.15,0.191
111.68,-25.08,0.191
111.68,-25.02,0.191
111.69,-24.95,0.191
111.70,-24.88,0.191
111.70,-24.82,0.191
111.71,-24.75,0.191
111.71,-24.68,0.191
111.72,-24.61,0.191
111.73,-24.55,0.191
111.74,-24.48,0.191
111.74,-24.42,0.191
111.75,-24.35,0.191
111.75,-24.28,0.192
111.76,-24.22,0.192
111.77,-24.15,0.192
111.78,-24.08,0.192
111.78,-24.02,0.192
111.79,-23.95,0.192
111.80,-23.88,0.192
111.80,-23.82,0.192
111.81,-23.75,0.192
111.81,-23.68,0.192
111.82,-23.61,0.192
111.83,-23.55,0.192
111.84,-23.48,0.192
111.84,-23.41,0.192
111.85,-23.35,0.192
111.85,-23.28,0.192
111.86,-23.22,0.192
111.87,-23.15,0.192
111.88,-23.08,0.192
111.88,-23.01,0.192
111.89,-22.95,0.192
111.90,-22.88,0.193
111.90,-22.81,0.193
111.91,-22.75,0.193
111.91,-22.68,0.193
111.92,-22.61,0.193
111.93,-22.55,0.193
111.94,-22.48,0.193
111.94,-22.41,0.193
111.95,-22.35,0.193
111.95,-22.28,0.193
111.96,-22.22,0.193
111.97,-22.15,0.193
111.98,-22.08,0.193
111.98,-22.01,0.193
111.99,-21.95,0.194
112.00,-21.88,0.194
112.00,-21.81,0.194
112.01,-21.75,0.194
112.01,-21.68,0.194
112.02,-21.61,0.194
112.03,-21.55,0.194
112.04,-21.48,0.194
112.04,-21.41,0.194
112.05,-21.34,0.194
112.05,-21.28,0.194
112.06,-21.21,0.194
112.07,-21.15,0.194
112.08,-21.08,0.194
112.08,-21.01,0.194
112.09,-20.95,0.194
112.10,-20.88,0.194
112.10,-20.81,0.194
112.11,-20.75,0.194
112.11,-20.68,0.194
112.12,-20.61,0.195
112.13,-20.55,0.195
112.14,-20.48,0.195
112.14,-20.41,0.195
112.15,-20.35,0.195
112.15,-20.28,0.195
112.16,-20.21,0.195
112.17,-20.14,0.195
112.18,-20.08,0.195
112.18,-20.01,0.195
112.19,-19.94,0.195
112.20,-19.88,0.195
112.20,-19.81,0.195
112.21,-19.74,0.195
112.21,-19.68,0.195
112.22,-19.61,0.195
112.23,-19.54,0.196
112.24,-19.48,0.196
112.24,-19.41,0.196
112.25,-19.34,0.196
112.25,-19.28,0.196
112.26,-19.21,0.196
112.27,-19.14,0.196
112.28,-19.08,0.196
112.28,-19.01,0.196
112.29,-18.94,0.196
112.30,-18.88,0.196
112.30,-18.81,0.196
112.31,-18.74,0.196
112.31,-18.68,0.196
112.32,-18.61,0.196
112.33,-18.54,0.196
112.34,-18.48,0.197
112.34,-18.41,0.197
112.35,-18.34,0.197
112.35,-18.28,0.197
112.36,-18.21,0.197
112.37,-18.14,0.197
112.38,-18.08,0.197
112.38,-18.01,0.197
112.39,-17.94,0.197
112.40,-17.87,0.197
112.40,-17.81,0.197
112.41,-17.74,0.197
112.41,-17.68,0.197
112.42,-17.61,0.197
112.43,-17.54,0.197
112.44,-17.48,0.197
112.44,-17.41,0.198
112.45,-17.34,0.198
112.45,-17.28,0.198
112.46,-17.21,0.198
112.47,-17.14,0.198
112.48,-17.08,0.198
112.48,-17.01,0.198
112.49,-16.94,0.198
112.50,-16.87,0.198
112.50,-16.81,0.198
112.51,-16.74,0.198
112.51,-16.67,0.198
112.52,-16.61,0.198
112.53,-16.54,0.198
112.54,-16.48,0.198
112.54,-16.41,0.199
112.55,-16.34,0.199
112.55,-16.28,0.199
112.56,-16.21,0.199
112.57,-16.14,0.199
112.58,-16.07,0.199
112.58,-16.01,0.199
112.59,-15.94,0.199
112.60,-15.87,0.199
112.60,-15.81,0.199
112.61,-15.74,0.199
112.61,-15.68,0.199
112.62,-15.61,0.199
112.63,-15.54,0.199
112.64,-15.47,0.199
112.64,-15.41,0.199
112.65,-15.34,0.199
112.65,-15.27,0.200
112.66,-15.21,0.200
112.67,-15.14,0.200
112.68,-15.08,0.200
112.68,-15.01,0.200
112.69,-14.94,0.200
112.70,-14.88,0.200
112.70,-14.81,0.200
112.71,-14.74,0.200
112.71,-14.68,0.200
112.72,-14.61,0.200
112.73,-14.54,0.200
112.74,-14.47,0.200
112.74,-14.41,0.200
112.75,-14.34,0.200
112.75,-14.28,0.201
112.76,-14.21,0.201
112.77,-14.14,0.201
112.78,-14.07,0.201
112.78,-14.01,0.201
112.79,-13.94,0.201
112.80,-13.88,0.201
112.80,-13.81,0.201
112.81,-13.74,0.201
112.81,-13.67,0.201
112.82,-13.61,0.201
112.83,-13.54,0.202
112.84,-13.48,0.202
112.84,-13.41,0.202
112.85,-13.34,0.202
112.85,-13.28,0.202
112.86,-13.21,0.202
112.87,-13.14,0.202
112.88,-13.07,0.202
112.88,-13.01,0.202
112.89,-12.94,0.202
112.90,-12.87,0.202
112.90,-12.81,0.202
112.91,-12.74,0.202
112.91,-12.67,0.203
112.92,-12.61,0.203
112.93,-12.54,0.203
112.94,-12.47,0.203
112.94,-12.41,0.203
112.95,-12.34,0.203
112.95,-12.27,0.203
112.96,-12.21,0.204
112.97,-12.14,0.204
112.98,-12.07,0.204
112.98,-12.01,0.204
112.99,-11.94,0.204
113.00,-11.88,0.204
113.00,-11.81,0.204
113.01,-11.74,0.204
113.01,-11.67,0.204
113.02,-11.61,0.205
113.03,-11.54,0.205
113.04,-11.47,0.205
113.04,-11.41,0.205
113.05,-11.34,0.205
113.05,-11.28,0.205
113.06,-11.21,0.205
113.07,-11.14,0.205
113.08,-11.08,0.205
113.08,-11.01,0.206
113.09,-10.94,0.206
113.10,-10.88,0.206
113.10,-10.81,0.206
113.11,-10.74,0.206
113.11,-10.68,0.206
113.12,-10.61,0.206
113.13,-10.54,0.207
113.14,-10.48,0.207
113.14,-10.41,0.207
113.15,-10.34,0.207
113.15,-10.28,0.207
113.16,-10.21,0.207
113.17,-10.14,0.207
113.18,-10.08,0.208
113.18,-10.01,0.208
113.19,-9.94,0.208
113.20,-9.88,0.208
113.20,-9.81,0.208
113.21,-9.74,0.208
113.21,-9.68,0.209
113.22,-9.61,0.209
113.23,-9.54,0.209
113.24,-9.48,0.209
113.24,-9.41,0.209
113.25,-9.34,0.210
113.25,-9.28,0.210
113.26,-9.21,0.210
113.27,-9.14,0.210
113.28,-9.08,0.210
113.28,-9.01,0.210
113.29,-8.95,0.211
113.30,-8.88,0.211
113.30,-8.81,0.211
113.31,-8.75,0.211
113.31,-8.68,0.211
113.32,-8.61,0.211
113.33,-8.55,0.211
113.34,-8.48,0.212
113.34,-8.41,0.212
113.35,-8.35,0.212
113.35,-8.28,0.212
113.36,-8.21,0.212
113.37,-8.15,0.213
113.38,-8.08,0.213
113.38,-8.01,0.213
113.39,-7.95,0.213
113.40,-7.88,0.214
113.40,-7.81,0.214
113.41,-7.75,0.214
113.41,-7.68,0.214
113.42,-7.61,0.215
113.43,-7.55,0.215
113.44,-7.48,0.215
113.44,-7.42,0.215
113.45,-7.35,0.215
113.45,-7.28,0.216
113.46,-7.22,0.216
113.47,-7.15,0.216
113.48,-7.08,0.216
113.48,-7.02,0.217
113.49,-6.95,0.217
113.50,-6.88,0.217
113.50,-6.82,0.218
113.51,-6.75,0.218
113.51,-6.68,0.218
113.52,-6.62,0.218
113.53,-6.55,0.219
113.54,-6.48,0.219
113.54,-6.42,0.219
113.55,-6.35,0.220
113.55,-6.28,0.220
113.56,-6.22,0.220
113.57,-6.15,0.221
113.58,-6.09,0.221
113.58,-6.02,0.221
113.59,-5.95,0.222
113.60,-5.89,0.222
113.60,-5.82,0.222
113.61,-5.76,0.223
113.61,-5.69,0.223
113.62,-5.62,0.223
113.63,-5.55,0.223
113.64,-5.49,0.224
113.64,-5.42,0.224
113.65,-5.36,0.225
113.65,-5.29,0.225
113.66,-5.22,0.225
113.67,-5.16,0.226
113.68,-5.09,0.226
113.68,-5.02,0.227
113.69,-4.96,0.227
113.70,-4.89,0.228
113.70,-4.82,0.228
113.71,-4.76,0.228
113.71,-4.69,0.229
113.72,-4.63,0.229
113.73,-4.56,0.229
113.74,-4.49,0.230
113.74,-4.43,0.230
113.75,-4.36,0.231
113.75,-4.30,0.232
113.76,-4.23,0.232
113.77,-4.16,0.232
113.78,-4.10,0.233
113.78,-4.03,0.234
113.79,-3.96,0.234
113.80,-3.90,0.234
113.80,-3.83,0.235
113.81,-3.76,0.235
113.81,-3.70,0.236
113.82,-3.63,0.236
113.83,-3.57,0.237
113.84,-3.50,0.238
113.84,-3.43,0.238
113.85,-3.37,0.238
113.85,-3.30,0.239
113.86,-3.24,0.239
113.87,-3.17,0.240
113.88,-3.10,0.240
113.88,-3.04,0.241
113.89,-2.97,0.242
113.90,-2.91,0.242
113.90,-2.84,0.243
113.91,-2.77,0.244
113.91,-2.71,0.244
113.92,-2.64,0.244
113.93,-2.58,0.245
113.94,-2.51,0.246
113.94,-2.44,0.247
113.95,-2.38,0.247
113.95,-2.31,0.248
113.96,-2.24,0.249
113.97,-2.18,0.250
113.98,-2.11,0.250
113.98,-2.05,0.250
113.99,-1.98,0.252
114.00,-1.92,0.253
114.00,-1.85,0.253
114.01,-1.78,0.254
114.01,-1.72,0.255
114.02,-1.65,0.255
114.03,-1.59,0.256
114.04,-1.52,0.257
114.04,-1.45,0.257
114.05,-1.39,0.258
114.05,-1.32,0.259
114.06,-1.26,0.259
114.07,-1.19,0.260
114.08,-1.13,0.261
114.08,-1.06,0.262
114.09,-0.99,0.263
114.10,-0.93,0.264
114.10,-0.86,0.264
114.11,-0.80,0.265
114.11,-0.73,0.266
114.12,-0.67,0.266
114.13,-0.60,0.268
114.14,-0.54,0.269
114.14,-0.47,0.269
114.15,-0.40,0.270
114.15,-0.34,0.271
114.16,-0.27,0.272
114.17,-0.21,0.273
114.18,-0.14,0.273
114.18,-0.08,0.274
114.19,-0.01,0.275
114.20,0.06,0.276
114.20,0.12,0.276
114.21,0.19,0.277
114.21,0.25,0.278
114.22,0.32,0.278
114.23,0.38,0.279
114.24,0.45,0.280
114.24,0.52,0.281
114.25,0.58,0.282
114.25,0.65,0.283
114.26,0.71,0.283
114.27,0.78,0.284
114.28,0.84,0.285
114.28,0.91,0.285
114.29,0.98,0.286
114.30,1.04,0.287
114.30,1.11,0.287
114.31,1.17,0.288
114.31,1.24,0.289
114.32,1.30,0.290
114.33,1.37,0.290
114.34,1.44,0.290
114.34,1.50,0.291
114.35,1.57,0.292
114.35,1.63,0.293
114.36,1.70,0.293
114.37,1.76,0.293
114.38,1.83,0.294
114.38,1.90,0.295
114.39,1.96,0.295
114.40,2.03,0.296
114.40,2.09,0.296
114.41,2.16,0.296
114.41,2.23,0.297
114.42,2.29,0.297
114.43,2.36,0.298
114.44,2.43,0.298
114.44,2.49,0.298
114.45,2.56,0.298
114.45,2.62,0.298
114.46,2.69,0.299
114.47,2.76,0.299
114.48,2.82,0.299
114.48,2.89,0.299
114.49,2.96,0.300
114.50,3.02,0.300
114.50,3.09,0.300
114.51,3.15,0.300
114.51,3.22,0.300
114.52,3.29,0.300
114.53,3.35,0.300
114.54,3.42,0.300
114.54,3.49,0.300
114.55,3.55,0.300
114.55,3.62,0.300
114.56,3.69,0.300
114.57,3.75,0.300
114.58,3.82,0.300
114.58,3.89,0.300
114.59,3.95,0.300
114.60,4.02,0.300
114.60,4.09,0.300
114.61,4.15,0.300
114.61,4.22,0.300
114.62,4.29,0.300
114.63,4.35,0.300
114.64,4.42,0.300
114.64,4.49,0.300
114.65,4.56,0.299
114.65,4.62,0.299
114.66,4.69,0.299
114.67,4.76,0.299
114.68,4.82,0.298
114.68,4.89,0.298
114.69,4.96,0.298
114.70,5.02,0.297
114.70,5.09,0.297
114.71,5.16,0.297
114.71,5.23,0.297
114.72,5.29,0.296
114.73,5.36,0.296
114.74,5.43,0.296
114.74,5.49,0.296
114.75,5.56,0.295
114.75,5.63,0.295
114.76,5.70,0.295
114.77,5.76,0.294
114.78,5.83,0.294
114.78,5.90,0.294
114.79,5.96,0.294
114.80,6.03,0.293
114.80,6.10,0.293
114.81,6.16,0.293
114.81,6.23,0.293
114.82,6.30,0.293
114.83,6.37,0.293
114.84,6.43,0.293
114.84,6.50,0.292
114.85,6.57,0.292
114.85,6.63,0.292
114.86,6.70,0.292
114.87,6.77,0.292
114.88,6.84,0.292
114.88,6.90,0.292
114.89,6.97,0.292
114.90,7.04,0.292
114.90,7.10,0.291
114.91,7.17,0.291
114.91,7.24,0.291
114.92,7.31,0.291
114.93,7.37,0.291
114.94,7.44,0.291
114.94,7.51,0.291
114.95,7.57,0.291
114.95,7.64,0.291
114.96,7.71,0.291
114.97,7.77,0.291
114.98,7.84,0.291
114.98,7.91,0.290
114.99,7.97,0.290
115.00,8.04,0.290
115.00,8.11,0.290
115.01,8.17,0.290
115.01,8.24,0.290
115.02,8.31,0.290
115.03,8.38,0.290
115.04,8.44,0.290
115.04,8.51,0.290
115.05,8.58,0.290
115.05,8.64,0.290
115.06,8.71,0.290
115.07,8.78,0.290
115.08,8.84,0.290
115.08,8.91,0.290
115.09,8.98,0.290
115.10,9.05,0.290
115.10,9.11,0.290
115.11,9.18,0.290
115.11,9.24,0.290
115.12,9.31,0.290
115.13,9.38,0.290
115.14,9.45,0.290
115.14,9.51,0.289
115.15,9.58,0.289
115.15,9.65,0.289
115.16,9.71,0.289
115.17,9.78,0.289
115.18,9.85,0.289
115.18,9.91,0.289
115.19,9.98,0.289
115.20,10.05,0.289
115.20,10.12,0.289
115.21,10.18,0.289
115.21,10.25,0.289
115.22,10.32,0.289
115.23,10.38,0.289
115.24,10.45,0.289
115.24,10.52,0.289
115.25,10.58,0.289
115.25,10.65,0.289
115.26,10.72,0.289
115.27,10.78,0.289
115.28,10.85,0.289
115.28,10.92,0.289
115.29,10.98,0.289
115.30,11.05,0.289
115.30,11.12,0.289
115.31,11.18,0.289
115.31,11.25,0.289
115.32,11.32,0.289
115.33,11.38,0.289
115.34,11.45,0.289
115.34,11.52,0.289
115.35,11.58,0.289
115.35,11.65,0.289
115.36,11.72,0.289
115.37,11.78,0.289
115.38,11.85,0.289
115.38,11.92,0.289
115.39,11.99,0.289
115.40,12.05,0.289
115.40,12.12,0.289
115.41,12.19,0.289
115.41,12.25,0.289
115.42,12.32,0.289
115.43,12.39,0.289
115.44,12.45,0.289
115.44,12.52,0.289
115.45,12.59,0.289
115.45,12.65,0.289
115.46,12.72,0.289
115.47,12.79,0.289
115.48,12.85,0.289
115.48,12.92,0.289
115.49,12.99,0.289
115.50,13.05,0.289
115.50,13.12,0.289
115.51,13.19,0.289
115.51,13.25,0.289
115.52,13.32,0.289
115.53,13.39,0.290
115.54,13.45,0.290
115.54,13.52,0.290
115.55,13.59,0.290
115.55,13.65,0.290
115.56,13.72,0.290
115.57,13.79,0.290
115.58,13.85,0.290
115.58,13.92,0.290
115.59,13.99,0.290
115.60,14.06,0.290
115.60,14.12,0.290
115.61,14.19,0.290
115.61,14.26,0.290
115.62,14.32,0.290
115.63,14.39,0.290
115.64,14.46,0.290
115.64,14.52,0.290
115.65,14.59,0.290
115.65,14.66,0.290
115.66,14.72,0.290
115.67,14.79,0.290
115.68,14.86,0.290
115.68,14.92,0.290
115.69,14.99,0.290
115.70,15.06,0.290
115.70,15.12,0.290
115.71,15.19,0.290
115.71,15.26,0.290
115.72,15.32,0.290
115.73,15.39,0.290
115.74,15.46,0.290
115.74,15.52,0.290
115.75,15.59,0.290
115.75,15.66,0.290
115.76,15.72,0.291
115.77,15.79,0.291
115.78,15.86,0.291
115.78,15.93,0.291
115.79,15.99,0.291
115.80,16.06,0.291
115.80,16.13,0.291
115.81,16.19,0.291
115.81,16.26,0.291
115.82,16.32,0.291
115.83,16.39,0.291
115.84,16.46,0.291
115.84,16.53,0.291
115.85,16.59,0.291
115.85,16.66,0.291
115.86,16.73,0.291
115.87,16.79,0.291
115.88,16.86,0.291
115.88,16.93,0.291
115.89,16.99,0.291
115.90,17.06,0.291
115.90,17.13,0.291
115.91,17.19,0.291
115.91,17.26,0.291
115.92,17.33,0.291
115.93,17.39,0.291
115.94,17.46,0.291
115.94,17.53,0.291
115.95,17.59,0.292
115.95,17.66,0.292
115.96,17.73,0.292
115.97,17.79,0.292
115.98,17.86,0.292
115.98,17.93,0.292
115.99,17.99,0.292
116.00,18.06,0.292
116.00,18.13,0.292
116.01,18.19,0.292
116.01,18.26,0.292
116.02,18.33,0.292
116.03,18.40,0.292
116.04,18.46,0.292
116.04,18.53,0.292
116.05,18.59,0.292
116.05,18.66,0.292
116.06,18.73,0.292
116.07,18.80,0.292
116.08,18.86,0.292
116.08,18.93,0.292
116.09,19.00,0.292
116.10,19.06,0.292
116.10,19.13,0.293
116.11,19.20,0.293
116.11,19.26,0.293
116.12,19.33,0.293
116.13,19.40,0.293
116.14,19.46,0.293
116.14,19.53,0.293
116.15,19.60,0.293
116.15,19.66,0.293
116.16,19.73,0.293
116.17,19.80,0.293
116.18,19.86,0.293
116.18,19.93,0.293
116.19,20.00,0.293
116.20,20.06,0.293
116.20,20.13,0.293
116.21,20.20,0.293
116.21,20.26,0.293
116.22,20.33,0.293
116.23,20.40,0.293
116.24,20.46,0.294
116.24,20.53,0.294
116.25,20.60,0.294
116.25,20.66,0.294
116.26,20.73,0.294
116.27,20.80,0.294
116.28,20.87,0.294
116.28,20.93,0.294
116.29,21.00,0.294
116.30,21.07,0.294
116.30,21.13,0.294
116.31,21.20,0.294
116.31,21.27,0.294
116.32,21.33,0.294
116.33,21.40,0.294
116.34,21.47,0.294
116.34,21.53,0.294
116.35,21.60,0.294
116.35,21.67,0.294
116.36,21.73,0.294
116.37,21.80,0.294
116.38,21.87,0.294
116.38,21.93,0.294
116.39,22.00,0.295
116.40,22.07,0.295
116.40,22.13,0.295
116.41,22.20,0.295
116.41,22.27,0.295
116.42,22.33,0.295
116.43,22.40,0.295
116.44,22.47,0.295
116.44,22.53,0.295
116.45,22.60,0.295
116.45,22.67,0.295
116.46,22.73,0.295
116.47,22.80,0.295
116.48,22.87,0.295
116.48,22.93,0.295
116.49,23.00,0.295
116.50,23.07,0.295
116.50,23.13,0.295
116.51,23.20,0.295
116.51,23.27,0.295
116.52,23.33,0.296
116.53,23.40,0.296
116.54,23.47,0.296
116.54,23.54,0.296
116.55,23.60,0.296
116.55,23.67,0.296
116.56,23.74,0.296
116.57,23.80,0.296
116.58,23.87,0.296
116.58,23.93,0.296
116.59,24.00,0.296
116.60,24.07,0.296
116.60,24.13,0.296
116.61,24.20,0.296
116.61,24.27,0.296
116.62,24.34,0.296
116.63,24.40,0.296
116.64,24.47,0.296
116.64,24.54,0.296
116.65,24.60,0.297
116.65,24.67,0.297
116.66,24.74,0.297
116.67,24.80,0.297
116.68,24.87,0.297
116.68,24.94,0.297
116.69,25.00,0.297
116.70,25.07,0.297
116.70,25.14,0.297
116.71,25.20,0.297
116.71,25.27,0.297
116.72,25.34,0.297
116.73,25.40,0.297
116.74,25.47,0.297
116.74,25.54,0.297
116.75,25.60,0.297
116.75,25.67,0.297
116.76,25.74,0.297
116.77,25.80,0.297
116.78,25.87,0.297
116.78,25.94,0.297
116.79,26.00,0.297
116.80,26.07,0.298
116.80,26.14,0.298
116.81,26.20,0.298
116.81,26.27,0.298
116.82,26.34,0.298
116.83,26.40,0.298
116.84,26.47,0.298
116.84,26.54,0.298
116.85,26.60,0.298
116.85,26.67,0.298
116.86,26.74,0.298
116.87,26.81,0.298
116.88,26.87,0.298
116.88,26.94,0.298
116.89,27.01,0.298
116.90,27.07,0.298
116.90,27.14,0.298
116.91,27.21,0.298
116.91,27.27,0.298
116.92,27.34,0.298
116.93,27.41,0.298
116.94,27.47,0.298
116.94,27.54,
116.95,27.61,
116.95,27.67,
116.96,27.74,
116.97,27.81,
116.98,27.87,
116.98,27.94,
116.99,,
116.99,,