File: DSC/2025_07_02_Ibuprofen_n80C_100C_20Cmin_x4-2.csv
Filename,2025_07_02_Ibuprofen_n80C_100C_20Cmin_x4
Instrument name,DSC2A-00468 (192.168.1.100)
Operator,Gibbons
rundate,7/3/2025
Sample name,2025_07_02_Ibuprofen_n80C_100C_20Cmin_x4
proceduresegments,Data Off ; Equilibrate -80.00 °C; Data On ; Ramp 20.00 °C/min to 100.00 °C; Data Off ; Isothermal 2.0 min; Data On ; Ramp 20.00 °C/min to -80.00 °C; Data Off ; Isothermal 2.0 min; Data On ; Ramp 20.00 °C/min to 100.00 °C; Data Off ; Isothermal 2.0 min; Data On ; Ramp 20.00 °C/min to -80.00 °C; Data Off ; Isothermal 2.0 min; Data On ; Ramp 20.00 °C/min to 100.00 °C; Data Off ; Isothermal 2.0 min; Data On ; Ramp 20.00 °C/min to -80.00 °C; Data Off ; Isothermal 2.0 min; Data On ; Ramp 20.00 °C/min to 30.00 °C
[File Parameters]
Run date,7/3/2025 3:38:54 PM
Trios version,5.1.1.46572
Original File Name,
Current File Name,D:\DSC2500\Gibbons\2025_07_02_Ibuprofen_n80C_100C_20Cmin_x4.tri
[Procedure]
Procedure Name,Ibuprofen_n80C_100C_20Cmin_x4
Sample Name,2025_07_02_Ibuprofen_n80C_100C_20Cmin_x4
Sample Mass,4.27 mg
Reference Sample Mass,0 mg
Pan Mass,57.45 mg
Pan Number,33
Reference Pan Mass,56.76 mg
Reference Pan Number,10
Pan Type,Tzero Aluminum Hermetic
Comments,DSC Consumables Al Hermetically Sealed Pan. Y1 Tray (Google Sheet: DSC_Samples_Y1_Tray_June2025).
Project Name,Pharma - Cocrystals
Operator,Gibbons
Test,Custom
Unload Max Temperature,30
Unload Min Temperature,30
Load Max Temperature,30
Load Min Temperature,30
Stop on Gas Flow Error,Yes
[Signal List]
Signal #1,Time (min)
Signal #2,Temperature (°C)
Signal #3,Heat Flow (mW)
Signal #4,Delta T (µV)
Signal #5,Delta Tzero (µV)
Signal #6,Tzero Temperature (°C)
Signal #7,Cell Purge (mL/min)
Signal #8,Heater Temp (°C)
Signal #9,Power Delivered (W)
Signal #10,Reference Junction Temperature (°C)
Signal #11,Flange Temperature (°C)
Signal #12,Heat Flow Phase (rad)
Signal #13,Total Heat Capacity (J/°C)
Signal #14,Heat Capacity (J/°C)
[Configuration]
Company Name,ASU
Instrument Name,DSC2A-00468
Instrument Type,DSC2500
Serial Number,DSC2A-00468
IP,192.168.1.100
Location of Instrument,MRRC
DisplayType,Unknown
Sample Interval ,0.1 s/pt
Selected Heat Flow,T4P
Exotherm Direction,Down
Cell Serial,DRC2-00792
Lid Type,Standard
Cooler,RCS 90
Leave Cooler on at End of Sequence,On
Gas 2,Nitrogen
Gas Selected,Channel 1
Flow Rate,50 mL/min
Secondary Purge,On
Licensed Heat Flow,Heat Flow T4P
Modulation Licensed,Yes
[Versions]
Common IDD Version,1
Cortex Version,VER 2.10.2.31
Driver,5.0.0.6
GDM Version,1.0.3.3
TouchscreenVersion,1.0.0.16145
FEP Version,1.2.1.21
FEP Bootloader,2.0.0.5
AutoSampler Version,2.1.1.26
Auto Sampler Bootloader,2.0.0.5
FCM Version,1.1.0.3
FCM Bootloader,2.0.0.5
[Experiment Logs]
Experiment Log Entry # 1,Data On set to 0
Experiment Log Entry # 3,Equilibrate Segment -80 (C) Started
Experiment Log Entry # 5,Air Cool is off.
Experiment Log Entry # 7,Data On set to 1
Experiment Log Entry # 9,Ramp Segment 20 C/min to 100 Started
Experiment Log Entry # 11,Data On set to 0
Experiment Log Entry # 13,Isothermal Segment 2 min started
Experiment Log Entry # 15,Data On set to 1
Experiment Log Entry # 17,Ramp Segment 20 C/min to -80 Started
Experiment Log Entry # 19,Data On set to 0
Experiment Log Entry # 21,Isothermal Segment 2 min started
Experiment Log Entry # 23,Data On set to 1
Experiment Log Entry # 25,Ramp Segment 20 C/min to 100 Started
Experiment Log Entry # 27,Data On set to 0
Experiment Log Entry # 29,Isothermal Segment 2 min started
Experiment Log Entry # 31,Data On set to 1
Experiment Log Entry # 33,Ramp Segment 20 C/min to -80 Started
Experiment Log Entry # 35,Data On set to 0
Experiment Log Entry # 37,Isothermal Segment 2 min started
Experiment Log Entry # 39,Data On set to 1
Experiment Log Entry # 41,Ramp Segment 20 C/min to 100 Started
Experiment Log Entry # 43,Data On set to 0
Experiment Log Entry # 45,Isothermal Segment 2 min started
Experiment Log Entry # 47,Data On set to 1
Experiment Log Entry # 49,Ramp Segment 20 C/min to -80 Started
Experiment Log Entry # 51,Data On set to 0
Experiment Log Entry # 53,Isothermal Segment 2 min started
Experiment Log Entry # 55,Data On set to 1
Experiment Log Entry # 57,Ramp Segment 20 C/min to 30 Started
[Method Log]
Method Log Entry # 1,Data Off
Method Log Entry # 2,Equilibrate -80 °C
Method Log Entry # 3,Data On
Method Log Entry # 4,(Ramp 1360763) Ramp 20 °C/minute to 100 °C
Method Log Entry # 5,Data Off
Method Log Entry # 6,Isothermal 2 minutes
Method Log Entry # 7,Data On
Method Log Entry # 8,(Ramp 1360767) Ramp 20 °C/minute to -80 °C
Method Log Entry # 9,Data Off
Method Log Entry # 10,Isothermal 2 minutes
Method Log Entry # 11,Data On
Method Log Entry # 12,(Ramp 1360771) Ramp 20 °C/minute to 100 °C
Method Log Entry # 13,Data Off
Method Log Entry # 14,Isothermal 2 minutes
Method Log Entry # 15,Data On
Method Log Entry # 16,(Ramp 1360775) Ramp 20 °C/minute to -80 °C
Method Log Entry # 17,Data Off
Method Log Entry # 18,Isothermal 2 minutes
Method Log Entry # 19,Data On
Method Log Entry # 20,(Ramp 1360779) Ramp 20 °C/minute to 100 °C
Method Log Entry # 21,Data Off
Method Log Entry # 22,Isothermal 2 minutes
Method Log Entry # 23,Data On
Method Log Entry # 24,(Ramp 1360783) Ramp 20 °C/minute to -80 °C
Method Log Entry # 25,Data Off
Method Log Entry # 26,Isothermal 2 minutes
Method Log Entry # 27,Data On
Method Log Entry # 28,(Ramp 1360787) Ramp 20 °C/minute to 30 °C
Cell Serial,DRC2-00792
[T1 Calibration]
Slope,-0.008529666
Offset,9.636258
Initial Temperature,98.23
GUID,f8bfdadc-4977-4fdf-ba6d-0ba9134940c3
[TZero Calibration]
Date Applied,11/29/2022 4:06:13 PM
Description,From -89.059 °C to 396.009 °C at 20.000°C/min
Gas Type,Nitrogen
Pan Type,None
Source Files 1,C:\Users\yargerlab\Desktop\DSC Data\General\TZero_calibration_11_29_22_2nd(2).tri
Source Files 2,C:\Users\yargerlab\Desktop\DSC Data\General\TZero_calibration_11_29_22_2nd(3).tri
Delta T Offset,13.05235
Delta T Slope,-0.007271007
Delta T0 Offset,-13.69128
Delta T0 Slope,0.06063341
[Temperature Calibration]
Date Applied,11/29/2022 7:12:28 PM
Description,From 106.590 °C to 186.590 °C at 10.000°C/min
Gas Type,Nitrogen
Pan Type,Tzero Aluminum Hermetic
Source Files 1,C:\Users\yargerlab\Desktop\DSC Data\General\Indium(6).tri
Measured 1,157.391
Known 1,156.598
[Cell Constant Calibration]
Date Applied,11/29/2022 7:12:29 PM
Description,From 106.590 °C to 186.590 °C at 10.000°C/min
Gas Type,Nitrogen
Pan Type,Tzero Aluminum Hermetic
Source Files 1,C:\Users\yargerlab\Desktop\DSC Data\General\Indium(6).tri
T4P KCell,1.006051
Onset Slope,63.26126 mW/°C
[Direct Cp Calibration]
Date Applied,11/30/2022 11:04:51 AM
Description,From -79.983 °C to 298.409 °C at 10.000°C/min
Gas Type,Nitrogen
Pan Type,Tzero Aluminum Hermetic
Source Files 1,C:\Users\yargerlab\Desktop\DSC Data\General\Sapphire_Heat_Capacity_11_30_22.tri
[Rev Cp Calibration]
Date Applied,11/30/2022 1:58:51 PM
Description,From -79.996 °C to 292.812 °C at 3.000°C/min
Gas Type,Nitrogen
Pan Type,Tzero Aluminum Hermetic
Source Files 1,C:\Users\yargerlab\Desktop\DSC Data\General\Sapphire_MDSC_Calibration_11_30_22.tri
[step]
Ramp 20.00 °C/min to 100.00 °C
Time,Temperature,Heat Flow (Normalized)
min,°C,W/g
0.00,-79.74,-0.050
0.01,-79.74,-0.050
0.01,-79.74,-0.049
0.02,-79.74,-0.047
0.03,-79.74,-0.046
0.03,-79.74,-0.045
0.04,-79.74,-0.044
0.05,-79.74,-0.044
0.05,-79.73,-0.045
0.06,-79.71,-0.046
0.07,-79.70,-0.053
0.07,-79.68,-0.062
0.08,-79.65,-0.071
0.09,-79.62,-0.079
0.09,-79.58,-0.086
0.10,-79.54,-0.090
0.11,-79.50,-0.093
0.11,-79.44,-0.097
0.12,-79.38,-0.096
0.13,-79.32,-0.094
0.13,-79.26,-0.090
0.14,-79.18,-0.087
0.15,-79.11,-0.072
0.15,-79.03,-0.056
0.16,-78.95,-0.043
0.17,-78.86,-0.027
0.17,-78.77,-0.011
0.18,-78.68,0.007
0.19,-78.59,0.025
0.19,-78.49,0.041
0.20,-78.39,0.057
0.21,-78.29,0.072
0.21,-78.19,0.088
0.22,-78.09,0.106
0.23,-77.99,0.120
0.23,-77.88,0.133
0.24,-77.78,0.146
0.25,-77.67,0.160
0.25,-77.56,0.172
0.26,-77.45,0.183
0.27,-77.34,0.193
0.27,-77.23,0.204
0.28,-77.12,0.215
0.29,-77.00,0.224
0.29,-76.89,0.232
0.30,-76.77,0.240
0.31,-76.66,0.249
0.31,-76.54,0.255
0.32,-76.42,0.264
0.33,-76.30,0.271
0.33,-76.19,0.276
0.34,-76.07,0.282
0.35,-75.94,0.289
0.35,-75.82,0.295
0.36,-75.70,0.300
0.37,-75.58,0.306
0.37,-75.46,0.312
0.38,-75.34,0.316
0.39,-75.21,0.322
0.39,-75.09,0.325
0.40,-74.96,0.328
0.41,-74.84,0.334
0.41,-74.72,0.339
0.42,-74.59,0.344
0.43,-74.47,0.345
0.43,-74.34,0.347
0.44,-74.21,0.354
0.45,-74.09,0.356
0.45,-73.96,0.356
0.46,-73.83,0.363
0.47,-73.71,0.367
0.47,-73.58,0.367
0.48,-73.45,0.367
0.49,-73.32,0.371
0.49,-73.20,0.373
0.50,-73.07,0.374
0.51,-72.94,0.378
0.51,-72.81,0.380
0.52,-72.68,0.381
0.53,-72.55,0.383
0.53,-72.43,0.385
0.54,-72.30,0.385
0.55,-72.17,0.388
0.55,-72.04,0.390
0.56,-71.91,0.391
0.57,-71.78,0.392
0.57,-71.65,0.394
0.58,-71.52,0.396
0.59,-71.39,0.396
0.59,-71.26,0.397
0.60,-71.13,0.398
0.61,-71.00,0.400
0.61,-70.87,0.400
0.62,-70.74,0.401
0.63,-70.61,0.402
0.63,-70.48,0.403
0.64,-70.35,0.404
0.65,-70.22,0.404
0.65,-70.09,0.405
0.66,-69.96,0.407
0.67,-69.83,0.407
0.67,-69.70,0.407
0.68,-69.56,0.407
0.69,-69.43,0.408
0.69,-69.30,0.409
0.70,-69.17,0.410
0.71,-69.04,0.410
0.71,-68.91,0.411
0.72,-68.78,0.412
0.73,-68.65,0.413
0.73,-68.52,0.413
0.74,-68.38,0.414
0.75,-68.25,0.414
0.75,-68.12,0.415
0.76,-67.99,0.415
0.77,-67.86,0.415
0.77,-67.73,0.416
0.78,-67.60,0.416
0.79,-67.46,0.417
0.79,-67.33,0.418
0.80,-67.20,0.418
0.81,-67.07,0.418
0.81,-66.94,0.419
0.82,-66.81,0.419
0.83,-66.67,0.419
0.83,-66.54,0.420
0.84,-66.41,0.420
0.85,-66.28,0.420
0.85,-66.15,0.421
0.86,-66.01,0.421
0.87,-65.88,0.421
0.87,-65.75,0.421
0.88,-65.62,0.421
0.89,-65.49,0.421
0.89,-65.35,0.422
0.90,-65.22,0.422
0.91,-65.09,0.423
0.91,-64.96,0.423
0.92,-64.82,0.423
0.93,-64.69,0.423
0.93,-64.56,0.424
0.94,-64.43,0.424
0.95,-64.30,0.424
0.95,-64.16,0.424
0.96,-64.03,0.425
0.97,-63.90,0.425
0.97,-63.76,0.425
0.98,-63.63,0.425
0.99,-63.50,0.426
0.99,-63.37,0.426
1.00,-63.23,0.426
1.01,-63.10,0.427
1.01,-62.97,0.427
1.02,-62.84,0.427
1.03,-62.70,0.427
1.03,-62.57,0.427
1.04,-62.44,0.428
1.05,-62.31,0.428
1.05,-62.17,0.428
1.06,-62.04,0.429
1.07,-61.91,0.429
1.07,-61.77,0.429
1.08,-61.64,0.429
1.09,-61.51,0.430
1.09,-61.38,0.430
1.10,-61.24,0.430
1.11,-61.11,0.430
1.11,-60.98,0.430
1.12,-60.85,0.431
1.13,-60.71,0.431
1.13,-60.58,0.431
1.14,-60.45,0.431
1.15,-60.31,0.432
1.15,-60.18,0.432
1.16,-60.05,0.432
1.17,-59.92,0.432
1.17,-59.78,0.433
1.18,-59.65,0.433
1.19,-59.52,0.433
1.19,-59.38,0.434
1.20,-59.25,0.434
1.21,-59.12,0.434
1.21,-58.99,0.434
1.22,-58.85,0.434
1.23,-58.72,0.435
1.23,-58.59,0.435
1.24,-58.45,0.435
1.25,-58.32,0.435
1.25,-58.19,0.435
1.26,-58.05,0.435
1.27,-57.92,0.436
1.27,-57.79,0.436
1.28,-57.65,0.436
1.29,-57.52,0.436
1.29,-57.39,0.436
1.30,-57.25,0.437
1.31,-57.12,0.437
1.31,-56.99,0.437
1.32,-56.86,0.437
1.33,-56.72,0.437
1.33,-56.59,0.438
1.34,-56.46,0.438
1.35,-56.32,0.438
1.35,-56.19,0.439
1.36,-56.06,0.439
1.37,-55.92,0.439
1.37,-55.79,0.439
1.38,-55.66,0.440
1.39,-55.52,0.440
1.39,-55.39,0.440
1.40,-55.26,0.440
1.41,-55.13,0.441
1.41,-54.99,0.441
1.42,-54.86,0.442
1.43,-54.73,0.442
1.43,-54.59,0.442
1.44,-54.46,0.442
1.45,-54.33,0.442
1.45,-54.19,0.443
1.46,-54.06,0.443
1.47,-53.93,0.443
1.47,-53.79,0.443
1.48,-53.66,0.443
1.49,-53.52,0.444
1.49,-53.39,0.444
1.50,-53.26,0.444
1.51,-53.12,0.444
1.51,-52.99,0.444
1.52,-52.86,0.444
1.53,-52.73,0.445
1.53,-52.59,0.445
1.54,-52.46,0.445
1.55,-52.32,0.445
1.55,-52.19,0.445
1.56,-52.06,0.446
1.57,-51.92,0.446
1.57,-51.79,0.446
1.58,-51.66,0.446
1.59,-51.52,0.447
1.59,-51.39,0.448
1.60,-51.26,0.448
1.61,-51.12,0.448
1.61,-50.99,0.448
1.62,-50.86,0.448
1.63,-50.72,0.449
1.63,-50.59,0.449
1.64,-50.46,0.449
1.65,-50.32,0.449
1.65,-50.19,0.449
1.66,-50.06,0.449
1.67,-49.92,0.450
1.67,-49.79,0.450
1.68,-49.66,0.450
1.69,-49.52,0.450
1.69,-49.39,0.451
1.70,-49.26,0.451
1.71,-49.12,0.451
1.71,-48.99,0.451
1.72,-48.86,0.451
1.73,-48.72,0.451
1.73,-48.59,0.451
1.74,-48.45,0.452
1.75,-48.32,0.452
1.75,-48.19,0.452
1.76,-48.05,0.452
1.77,-47.92,0.452
1.77,-47.79,0.452
1.78,-47.66,0.452
1.79,-47.52,0.453
1.79,-47.39,0.453
1.80,-47.25,0.453
1.81,-47.12,0.453
1.81,-46.99,0.453
1.82,-46.85,0.453
1.83,-46.72,0.453
1.83,-46.59,0.454
1.84,-46.45,0.454
1.85,-46.32,0.454
1.85,-46.18,0.454
1.86,-46.05,0.454
1.87,-45.92,0.455
1.87,-45.78,0.455
1.88,-45.65,0.455
1.89,-45.52,0.455
1.89,-45.38,0.455
1.90,-45.25,0.455
1.91,-45.12,0.456
1.91,-44.98,0.456
1.92,-44.85,0.456
1.93,-44.72,0.456
1.93,-44.58,0.456
1.94,-44.45,0.456
1.95,-44.31,0.457
1.95,-44.18,0.457
1.96,-44.05,0.457
1.97,-43.91,0.457
1.97,-43.78,0.457
1.98,-43.65,0.457
1.99,-43.51,0.457
1.99,-43.38,0.458
2.00,-43.25,0.458
2.01,-43.11,0.458
2.01,-42.98,0.458
2.02,-42.85,0.458
2.03,-42.71,0.458
2.03,-42.58,0.459
2.04,-42.44,0.459
2.05,-42.31,0.459
2.05,-42.18,0.459
2.06,-42.04,0.459
2.07,-41.91,0.460
2.07,-41.78,0.460
2.08,-41.64,0.460
2.09,-41.51,0.460
2.09,-41.38,0.460
2.10,-41.24,0.461
2.11,-41.11,0.461
2.11,-40.98,0.461
2.12,-40.84,0.461
2.13,-40.71,0.461
2.13,-40.58,0.461
2.14,-40.44,0.461
2.15,-40.31,0.462
2.15,-40.18,0.462
2.16,-40.04,0.462
2.17,-39.91,0.462
2.17,-39.77,0.462
2.18,-39.64,0.462
2.19,-39.51,0.462
2.19,-39.37,0.463
2.20,-39.24,0.463
2.21,-39.11,0.463
2.21,-38.97,0.463
2.22,-38.84,0.463
2.23,-38.71,0.463
2.23,-38.57,0.464
2.24,-38.44,0.464
2.25,-38.30,0.464
2.25,-38.17,0.464
2.26,-38.04,0.464
2.27,-37.90,0.464
2.27,-37.77,0.464
2.28,-37.64,0.465
2.29,-37.50,0.465
2.29,-37.37,0.465
2.30,-37.24,0.465
2.31,-37.10,0.466
2.31,-36.97,0.466
2.32,-36.84,0.466
2.33,-36.70,0.466
2.33,-36.57,0.466
2.34,-36.43,0.466
2.35,-36.30,0.466
2.35,-36.17,0.467
2.36,-36.03,0.467
2.37,-35.90,0.467
2.37,-35.77,0.467
2.38,-35.63,0.467
2.39,-35.50,0.467
2.39,-35.36,0.467
2.40,-35.23,0.468
2.41,-35.10,0.468
2.41,-34.96,0.468
2.42,-34.83,0.468
2.43,-34.70,0.468
2.43,-34.56,0.468
2.44,-34.43,0.468
2.45,-34.30,0.469
2.45,-34.16,0.469
2.46,-34.03,0.469
2.47,-33.90,0.469
2.47,-33.76,0.469
2.48,-33.63,0.469
2.49,-33.50,0.470
2.49,-33.36,0.470
2.50,-33.23,0.470
2.51,-33.09,0.470
2.51,-32.96,0.470
2.52,-32.83,0.471
2.53,-32.69,0.471
2.53,-32.56,0.471
2.54,-32.43,0.471
2.55,-32.29,0.471
2.55,-32.16,0.471
2.56,-32.02,0.471
2.57,-31.89,0.472
2.57,-31.76,0.472
2.58,-31.63,0.472
2.59,-31.49,0.472
2.59,-31.36,0.472
2.60,-31.23,0.472
2.61,-31.09,0.473
2.61,-30.96,0.473
2.62,-30.82,0.473
2.63,-30.69,0.473
2.63,-30.56,0.473
2.64,-30.42,0.473
2.65,-30.29,0.473
2.65,-30.16,0.474
2.66,-30.02,0.474
2.67,-29.89,0.474
2.67,-29.75,0.474
2.68,-29.62,0.474
2.69,-29.49,0.474
2.69,-29.35,0.475
2.70,-29.22,0.475
2.71,-29.09,0.475
2.71,-28.95,0.475
2.72,-28.82,0.476
2.73,-28.69,0.476
2.73,-28.55,0.476
2.74,-28.42,0.476
2.75,-28.28,0.476
2.75,-28.15,0.476
2.76,-28.02,0.476
2.77,-27.88,0.477
2.77,-27.75,0.477
2.78,-27.62,0.477
2.79,-27.48,0.477
2.79,-27.35,0.478
2.80,-27.22,0.478
2.81,-27.08,0.478
2.81,-26.95,0.478
2.82,-26.81,0.478
2.83,-26.68,0.478
2.83,-26.55,0.478
2.84,-26.42,0.478
2.85,-26.28,0.479
2.85,-26.15,0.479
2.86,-26.02,0.479
2.87,-25.88,0.479
2.87,-25.75,0.479
2.88,-25.61,0.479
2.89,-25.48,0.480
2.89,-25.34,0.480
2.90,-25.21,0.480
2.91,-25.08,0.480
2.91,-24.95,0.480
2.92,-24.81,0.480
2.93,-24.68,0.481
2.93,-24.54,0.481
2.94,-24.41,0.481
2.95,-24.28,0.481
2.95,-24.14,0.482
2.96,-24.01,0.482
2.97,-23.88,0.482
2.97,-23.74,0.482
2.98,-23.61,0.482
2.99,-23.48,0.482
2.99,-23.34,0.482
3.00,-23.21,0.483
3.01,-23.07,0.483
3.01,-22.94,0.483
3.02,-22.81,0.483
3.03,-22.67,0.483
3.03,-22.54,0.483
3.04,-22.41,0.483
3.05,-22.27,0.483
3.05,-22.14,0.484
3.06,-22.01,0.484
3.07,-21.87,0.484
3.07,-21.74,0.484
3.08,-21.60,0.484
3.09,-21.47,0.484
3.09,-21.34,0.485
3.10,-21.20,0.485
3.11,-21.07,0.485
3.11,-20.94,0.485
3.12,-20.80,0.485
3.13,-20.67,0.486
3.13,-20.54,0.486
3.14,-20.40,0.486
3.15,-20.27,0.486
3.15,-20.14,0.486
3.16,-20.00,0.486
3.17,-19.87,0.486
3.17,-19.73,0.487
3.18,-19.60,0.487
3.19,-19.47,0.487
3.19,-19.33,0.487
3.20,-19.20,0.487
3.21,-19.07,0.487
3.21,-18.93,0.487
3.22,-18.80,0.487
3.23,-18.66,0.488
3.23,-18.53,0.488
3.24,-18.40,0.488
3.25,-18.26,0.488
3.25,-18.13,0.488
3.26,-18.00,0.489
3.27,-17.86,0.489
3.27,-17.73,0.489
3.28,-17.60,0.489
3.29,-17.46,0.489
3.29,-17.33,0.489
3.30,-17.19,0.489
3.31,-17.06,0.490
3.31,-16.93,0.490
3.32,-16.80,0.490
3.33,-16.66,0.490
3.33,-16.53,0.490
3.34,-16.39,0.490
3.35,-16.26,0.490
3.35,-16.13,0.491
3.36,-15.99,0.491
3.37,-15.86,0.491
3.37,-15.73,0.491
3.38,-15.59,0.491
3.39,-15.46,0.491
3.39,-15.32,0.492
3.40,-15.19,0.492
3.41,-15.06,0.492
3.41,-14.92,0.492
3.42,-14.79,0.492
3.43,-14.66,0.493
3.43,-14.52,0.493
3.44,-14.39,0.493
3.45,-14.26,0.493
3.45,-14.12,0.493
3.46,-13.99,0.493
3.47,-13.85,0.494
3.47,-13.72,0.494
3.48,-13.59,0.494
3.49,-13.45,0.494
3.49,-13.32,0.494
3.50,-13.19,0.494
3.51,-13.05,0.495
3.51,-12.92,0.495
3.52,-12.79,0.495
3.53,-12.65,0.495
3.53,-12.52,0.495
3.54,-12.39,0.496
3.55,-12.25,0.496
3.55,-12.12,0.496
3.56,-11.99,0.496
3.57,-11.85,0.496
3.57,-11.72,0.496
3.58,-11.58,0.497
3.59,-11.45,0.497
3.59,-11.32,0.497
3.60,-11.18,0.497
3.61,-11.05,0.498
3.61,-10.92,0.498
3.62,-10.78,0.498
3.63,-10.65,0.498
3.63,-10.52,0.498
3.64,-10.38,0.498
3.65,-10.25,0.499
3.65,-10.12,0.499
3.66,-9.98,0.499
3.67,-9.85,0.499
3.67,-9.72,0.499
3.68,-9.58,0.499
3.69,-9.45,0.499
3.69,-9.31,0.500
3.70,-9.18,0.500
3.71,-9.05,0.500
3.71,-8.91,0.501
3.72,-8.78,0.501
3.73,-8.65,0.501
3.73,-8.51,0.501
3.74,-8.38,0.501
3.75,-8.24,0.501
3.75,-8.11,0.501
3.76,-7.98,0.502
3.77,-7.84,0.502
3.77,-7.71,0.502
3.78,-7.58,0.502
3.79,-7.44,0.502
3.79,-7.31,0.503
3.80,-7.17,0.503
3.81,-7.04,0.503
3.81,-6.91,0.503
3.82,-6.77,0.503
3.83,-6.64,0.503
3.83,-6.51,0.504
3.84,-6.37,0.504
3.85,-6.24,0.504
3.85,-6.11,0.504
3.86,-5.97,0.505
3.87,-5.84,0.505
3.87,-5.71,0.505
3.88,-5.57,0.505
3.89,-5.44,0.505
3.89,-5.31,0.505
3.90,-5.17,0.505
3.91,-5.04,0.506
3.91,-4.91,0.506
3.92,-4.77,0.506
3.93,-4.64,0.506
3.93,-4.51,0.506
3.94,-4.37,0.506
3.95,-4.24,0.506
3.95,-4.10,0.507
3.96,-3.97,0.507
3.97,-3.84,0.507
3.97,-3.70,0.507
3.98,-3.57,0.507
3.99,-3.44,0.508
3.99,-3.30,0.508
4.00,-3.17,0.508
4.01,-3.03,0.508
4.01,-2.90,0.508
4.02,-2.77,0.509
4.03,-2.63,0.509
4.03,-2.50,0.509
4.04,-2.37,0.509
4.05,-2.23,0.510
4.05,-2.10,0.510
4.06,-1.97,0.510
4.07,-1.83,0.510
4.07,-1.70,0.510
4.08,-1.56,0.510
4.09,-1.43,0.511
4.09,-1.30,0.511
4.10,-1.16,0.511
4.11,-1.03,0.511
4.11,-0.90,0.512
4.12,-0.76,0.512
4.13,-0.63,0.512
4.13,-0.50,0.512
4.14,-0.36,0.512
4.15,-0.23,0.513
4.15,-0.09,0.513
4.16,0.04,0.513
4.17,0.17,0.513
4.17,0.31,0.513
4.18,0.44,0.514
4.19,0.57,0.514
4.19,0.71,0.514
4.20,0.84,0.514
4.21,0.97,0.515
4.21,1.11,0.515
4.22,1.24,0.515
4.23,1.37,0.515
4.23,1.51,0.516
4.24,1.64,0.516
4.25,1.78,0.516
4.25,1.91,0.516
4.26,2.04,0.517
4.27,2.18,0.517
4.27,2.31,0.517
4.28,2.44,0.517
4.29,2.58,0.518
4.29,2.71,0.518
4.30,2.84,0.518
4.31,2.98,0.518
4.31,3.11,0.518
4.32,3.25,0.519
4.33,3.38,0.519
4.33,3.51,0.519
4.34,3.65,0.519
4.35,3.78,0.520
4.35,3.91,0.520
4.36,4.05,0.520
4.37,4.18,0.520
4.37,4.31,0.520
4.38,4.45,0.521
4.39,4.58,0.521
4.39,4.71,0.521
4.40,4.85,0.522
4.41,4.98,0.522
4.41,5.12,0.522
4.42,5.25,0.522
4.43,5.38,0.523
4.43,5.52,0.523
4.44,5.65,0.523
4.45,5.78,0.523
4.45,5.92,0.524
4.46,6.05,0.524
4.47,6.19,0.524
4.47,6.32,0.524
4.48,6.45,0.525
4.49,6.59,0.526
4.49,6.72,0.526
4.50,6.85,0.526
4.51,6.99,0.526
4.51,7.12,0.527
4.52,7.25,0.527
4.53,7.39,0.527
4.53,7.52,0.527
4.54,7.65,0.527
4.55,7.79,0.528
4.55,7.92,0.528
4.56,8.06,0.528
4.57,8.19,0.528
4.57,8.32,0.528
4.58,8.45,0.528
4.59,8.59,0.529
4.59,8.72,0.529
4.60,8.85,0.529
4.61,8.99,0.529
4.61,9.12,0.529
4.62,9.26,0.530
4.63,9.39,0.530
4.63,9.52,0.530
4.64,9.66,0.531
4.65,9.79,0.531
4.65,9.92,0.531
4.66,10.06,0.532
4.67,10.19,0.532
4.67,10.32,0.532
4.68,10.46,0.532
4.69,10.59,0.533
4.69,10.73,0.533
4.70,10.86,0.533
4.71,10.99,0.534
4.71,11.13,0.534
4.72,11.26,0.534
4.73,11.39,0.534
4.73,11.53,0.535
4.74,11.66,0.535
4.75,11.79,0.536
4.75,11.93,0.536
4.76,12.06,0.536
4.77,12.20,0.536
4.77,12.33,0.536
4.78,12.46,0.537
4.79,12.60,0.537
4.79,12.73,0.537
4.80,12.86,0.537
4.81,13.00,0.538
4.81,13.13,0.538
4.82,13.27,0.538
4.83,13.40,0.538
4.83,13.53,0.539
4.84,13.67,0.539
4.85,13.80,0.539
4.85,13.93,0.539
4.86,14.07,0.540
4.87,14.20,0.540
4.87,14.33,0.541
4.88,14.47,0.541
4.89,14.60,0.541
4.89,14.73,0.541
4.90,14.87,0.541
4.91,15.00,0.542
4.91,15.14,0.542
4.92,15.27,0.542
4.93,15.40,0.542
4.93,15.54,0.543
4.94,15.67,0.543
4.95,15.80,0.543
4.95,15.94,0.544
4.96,16.07,0.544
4.97,16.21,0.544
4.97,16.34,0.544
4.98,16.47,0.544
4.99,16.61,0.545
4.99,16.74,0.545
5.00,16.87,0.545
5.01,17.01,0.545
5.01,17.14,0.546
5.02,17.27,0.546
5.03,17.41,0.546
5.03,17.54,0.546
5.04,17.67,0.546
5.05,17.81,0.547
5.05,17.94,0.547
5.06,18.08,0.547
5.07,18.21,0.548
5.07,18.34,0.548
5.08,18.48,0.548
5.09,18.61,0.548
5.09,18.74,0.548
5.10,18.88,0.549
5.11,19.01,0.549
5.11,19.14,0.549
5.12,19.28,0.549
5.13,19.41,0.550
5.13,19.54,0.550
5.14,19.68,0.550
5.15,19.81,0.550
5.15,19.94,0.551
5.16,20.08,0.551
5.17,20.21,0.551
5.17,20.35,0.551
5.18,20.48,0.552
5.19,20.61,0.552
5.19,20.75,0.552
5.20,20.88,0.552
5.21,21.01,0.553
5.21,21.15,0.553
5.22,21.28,0.553
5.23,21.41,0.553
5.23,21.55,0.554
5.24,21.68,0.554
5.25,21.82,0.554
5.25,21.95,0.554
5.26,22.08,0.555
5.27,22.21,0.555
5.27,22.35,0.555
5.28,22.48,0.555
5.29,22.62,0.556
5.29,22.75,0.556
5.30,22.88,0.556
5.31,23.02,0.557
5.31,23.15,0.558
5.32,23.29,0.558
5.33,23.42,0.558
5.33,23.55,0.558
5.34,23.68,0.559
5.35,23.82,0.559
5.35,23.95,0.559
5.36,24.09,0.560
5.37,24.22,0.560
5.37,24.35,0.560
5.38,24.49,0.560
5.39,24.62,0.560
5.39,24.75,0.561
5.40,24.89,0.561
5.41,25.02,0.561
5.41,25.15,0.562
5.42,25.29,0.562
5.43,25.42,0.562
5.43,25.55,0.563
5.44,25.69,0.564
5.45,25.82,0.564
5.45,25.95,0.564
5.46,26.09,0.564
5.47,26.22,0.565
5.47,26.36,0.565
5.48,26.49,0.565
5.49,26.62,0.566
5.49,26.76,0.566
5.50,26.89,0.566
5.51,27.02,0.566
5.51,27.16,0.566
5.52,27.29,0.567
5.53,27.42,0.567
5.53,27.56,0.567
5.54,27.69,0.568
5.55,27.83,0.568
5.55,27.96,0.569
5.56,28.09,0.569
5.57,28.23,0.569
5.57,28.36,0.569
5.58,28.49,0.569
5.59,28.63,0.570
5.59,28.76,0.570
5.60,28.89,0.570
5.61,29.03,0.570
5.61,29.16,0.570
5.62,29.29,0.571
5.63,29.43,0.571
5.63,29.56,0.571
5.64,29.69,0.571
5.65,29.83,0.571
5.65,29.96,0.572
5.66,30.10,0.572
5.67,30.23,0.572
5.67,30.36,0.572
5.68,30.50,0.572
5.69,30.63,0.572
5.69,30.76,0.573
5.70,30.90,0.573
5.71,31.03,0.573
5.71,31.16,0.574
5.72,31.30,0.574
5.73,31.43,0.574
5.73,31.56,0.574
5.74,31.70,0.574
5.75,31.83,0.575
5.75,31.97,0.575
5.76,32.10,0.575
5.77,32.23,0.575
5.77,32.37,0.576
5.78,32.50,0.576
5.79,32.63,0.576
5.79,32.77,0.576
5.80,32.90,0.576
5.81,33.03,0.577
5.81,33.17,0.577
5.82,33.30,0.577
5.83,33.44,0.577
5.83,33.57,0.577
5.84,33.70,0.578
5.85,33.84,0.578
5.85,33.97,0.578
5.86,34.10,0.578
5.87,34.24,0.579
5.87,34.37,0.579
5.88,34.50,0.580
5.89,34.64,0.580
5.89,34.77,0.580
5.90,34.90,0.580
5.91,35.04,0.581
5.91,35.17,0.581
5.92,35.30,0.581
5.93,35.44,0.581
5.93,35.57,0.581
5.94,35.71,0.582
5.95,35.84,0.582
5.95,35.97,0.583
5.96,36.11,0.583
5.97,36.24,0.583
5.97,36.38,0.583
5.98,36.51,0.584
5.99,36.64,0.584
5.99,36.78,0.584
6.00,36.91,0.584
6.01,37.04,0.585
6.01,37.18,0.585
6.02,37.31,0.585
6.03,37.44,0.585
6.03,37.58,0.586
6.04,37.71,0.586
6.05,37.84,0.586
6.05,37.98,0.586
6.06,38.11,0.586
6.07,38.24,0.587
6.07,38.38,0.587
6.08,38.51,0.587
6.09,38.65,0.588
6.09,38.78,0.588
6.10,38.91,0.588
6.11,39.05,0.588
6.11,39.18,0.589
6.12,39.31,0.589
6.13,39.45,0.589
6.13,39.58,0.589
6.14,39.71,0.589
6.15,39.85,0.590
6.15,39.98,0.590
6.16,40.12,0.591
6.17,40.25,0.591
6.17,40.38,0.591
6.18,40.52,0.591
6.19,40.65,0.591
6.19,40.78,0.592
6.20,40.92,0.592
6.21,41.05,0.593
6.21,41.18,0.593
6.22,41.32,0.593
6.23,41.45,0.593
6.23,41.58,0.594
6.24,41.72,0.594
6.25,41.85,0.594
6.25,41.98,0.594
6.26,42.12,0.594
6.27,42.25,0.595
6.27,42.39,0.595
6.28,42.52,0.595
6.29,42.65,0.595
6.29,42.79,0.596
6.30,42.92,0.596
6.31,43.05,0.596
6.31,43.19,0.597
6.32,43.32,0.597
6.33,43.45,0.597
6.33,43.59,0.597
6.34,43.72,0.598
6.35,43.85,0.598
6.35,43.99,0.598
6.36,44.12,0.599
6.37,44.25,0.599
6.37,44.39,0.599
6.38,44.52,0.600
6.39,44.66,0.600
6.39,44.79,0.600
6.40,44.92,0.600
6.41,45.06,0.601
6.41,45.19,0.601
6.42,45.33,0.601
6.43,45.46,0.602
6.43,45.59,0.603
6.44,45.72,0.603
6.45,45.86,0.603
6.45,45.99,0.603
6.46,46.13,0.603
6.47,46.26,0.604
6.47,46.40,0.604
6.48,46.53,0.604
6.49,46.66,0.605
6.49,46.80,0.605
6.50,46.93,0.605
6.51,47.06,0.605
6.51,47.20,0.605
6.52,47.33,0.606
6.53,47.46,0.606
6.53,47.60,0.606
6.54,47.73,0.607
6.55,47.87,0.607
6.55,48.00,0.607
6.56,48.13,0.607
6.57,48.27,0.608
6.57,48.40,0.608
6.58,48.54,0.609
6.59,48.67,0.609
6.59,48.80,0.609
6.60,48.94,0.610
6.61,49.07,0.610
6.61,49.20,0.610
6.62,49.34,0.611
6.63,49.47,0.611
6.63,49.60,0.611
6.64,49.74,0.611
6.65,49.87,0.611
6.65,50.01,0.612
6.66,50.14,0.612
6.67,50.27,0.612
6.67,50.41,0.612
6.68,50.54,0.612
6.69,50.67,0.613
6.69,50.81,0.613
6.70,50.94,0.613
6.71,51.07,0.613
6.71,51.21,0.613
6.72,51.34,0.614
6.73,51.47,0.614
6.73,51.61,0.614
6.74,51.74,0.614
6.75,51.87,0.615
6.75,52.01,0.615
6.76,52.14,0.615
6.77,52.27,0.616
6.77,52.41,0.616
6.78,52.54,0.616
6.79,52.68,0.616
6.79,52.81,0.616
6.80,52.94,0.616
6.81,53.07,0.617
6.81,53.21,0.617
6.82,53.34,0.617
6.83,53.48,0.617
6.83,53.61,0.617
6.84,53.74,0.618
6.85,53.88,0.618
6.85,54.01,0.619
6.86,54.14,0.619
6.87,54.28,0.619
6.87,54.41,0.619
6.88,54.54,0.620
6.89,54.68,0.620
6.89,54.81,0.621
6.90,54.95,0.621
6.91,55.08,0.621
6.91,55.21,0.621
6.92,55.34,0.621
6.93,55.48,0.622
6.93,55.61,0.622
6.94,55.74,0.622
6.95,55.88,0.622
6.95,56.01,0.623
6.96,56.14,0.623
6.97,56.28,0.623
6.97,56.41,0.623
6.98,56.54,0.623
6.99,56.68,0.624
6.99,56.81,0.624
7.00,56.95,0.624
7.01,57.08,0.624
7.01,57.21,0.624
7.02,57.35,0.625
7.03,57.48,0.625
7.03,57.61,0.625
7.04,57.75,0.626
7.05,57.88,0.626
7.05,58.01,0.626
7.06,58.15,0.626
7.07,58.28,0.626
7.07,58.41,0.627
7.08,58.55,0.627
7.09,58.68,0.627
7.09,58.81,0.628
7.10,58.95,0.628
7.11,59.08,0.628
7.11,59.21,0.628
7.12,59.35,0.628
7.13,59.48,0.629
7.13,59.61,0.630
7.14,59.75,0.630
7.15,59.88,0.630
7.15,60.02,0.630
7.16,60.15,0.630
7.17,60.28,0.631
7.17,60.42,0.631
7.18,60.55,0.631
7.19,60.68,0.631
7.19,60.82,0.632
7.20,60.95,0.632
7.21,61.08,0.633
7.21,61.22,0.633
7.22,61.35,0.633
7.23,61.48,0.633
7.23,61.62,0.634
7.24,61.75,0.634
7.25,61.89,0.634
7.25,62.02,0.634
7.26,62.15,0.635
7.27,62.29,0.635
7.27,62.42,0.635
7.28,62.55,0.636
7.29,62.69,0.636
7.29,62.82,0.636
7.30,62.95,0.636
7.31,63.09,0.637
7.31,63.22,0.637
7.32,63.36,0.637
7.33,63.49,0.637
7.33,63.62,0.638
7.34,63.76,0.638
7.35,63.89,0.638
7.35,64.02,0.639
7.36,64.16,0.639
7.37,64.29,0.639
7.37,64.42,0.639
7.38,64.56,0.640
7.39,64.69,0.640
7.39,64.82,0.641
7.40,64.96,0.641
7.41,65.09,0.641
7.41,65.22,0.642
7.42,65.36,0.642
7.43,65.49,0.642
7.43,65.63,0.643
7.44,65.76,0.643
7.45,65.89,0.643
7.45,66.03,0.643
7.46,66.16,0.644
7.47,66.29,0.644
7.47,66.43,0.645
7.48,66.56,0.646
7.49,66.70,0.646
7.49,66.83,0.646
7.50,66.96,0.646
7.51,67.10,0.647
7.51,67.23,0.647
7.52,67.36,0.647
7.53,67.50,0.647
7.53,67.63,0.648
7.54,67.76,0.648
7.55,67.90,0.648
7.55,68.03,0.649
7.56,68.16,0.649
7.57,68.30,0.649
7.57,68.43,0.650
7.58,68.57,0.651
7.59,68.70,0.651
7.59,68.83,0.651
7.60,68.96,0.652
7.61,69.10,0.652
7.61,69.23,0.652
7.62,69.37,0.653
7.63,69.50,0.654
7.63,69.63,0.654
7.64,69.77,0.655
7.65,69.90,0.655
7.65,70.03,0.655
7.66,70.17,0.656
7.67,70.30,0.656
7.67,70.43,0.657
7.68,70.57,0.657
7.69,70.70,0.657
7.69,70.83,0.658
7.70,70.97,0.659
7.71,71.10,0.660
7.71,71.23,0.661
7.72,71.37,0.662
7.73,71.50,0.663
7.73,71.63,0.664
7.74,71.77,0.667
7.75,71.90,0.668
7.75,72.04,0.669
7.76,72.17,0.672
7.77,72.30,0.674
7.77,72.44,0.677
7.78,72.57,0.680
7.79,72.70,0.683
7.79,72.83,0.685
7.80,72.97,0.690
7.81,73.10,0.696
7.81,73.23,0.704
7.82,73.37,0.711
7.83,73.50,0.721
7.83,73.63,0.735
7.84,73.76,0.756
7.85,73.89,0.786
7.85,74.02,0.825
7.86,74.15,0.890
7.87,74.28,0.983
7.87,74.40,1.108
7.88,74.52,1.267
7.89,74.64,1.452
7.89,74.75,1.664
7.90,74.86,1.896
7.91,74.96,2.148
7.91,75.06,2.413
7.92,75.15,2.688
7.93,75.24,2.975
7.93,75.32,3.270
7.94,75.40,3.561
7.95,75.48,3.855
7.95,75.55,4.144
7.96,75.63,4.430
7.97,75.69,4.716
7.97,75.76,5.002
7.98,75.83,5.295
7.99,75.89,5.598
7.99,75.95,5.914
8.00,76.01,6.239
8.01,76.07,6.559
8.01,76.12,6.852
8.02,76.18,7.117
8.03,76.24,7.346
8.03,76.30,7.545
8.04,76.36,7.716
8.05,76.42,7.853
8.05,76.49,7.963
8.06,76.56,8.063
8.07,76.64,8.161
8.07,76.72,8.228
8.08,76.80,8.250
8.09,76.89,8.219
8.09,76.99,8.133
8.10,77.10,8.029
8.11,77.21,7.942
8.11,77.32,7.877
8.12,77.44,7.842
8.13,77.56,7.865
8.13,77.68,7.941
8.14,77.80,7.992
8.15,77.92,7.924
8.15,78.05,7.734
8.16,78.18,7.481
8.17,78.33,7.191
8.17,78.48,6.866
8.18,78.64,6.548
8.19,78.81,6.221
8.19,78.99,5.865
8.20,79.17,5.506
8.21,79.36,5.149
8.21,79.55,4.771
8.22,79.75,4.380
8.23,79.95,3.951
8.23,80.16,3.491
8.24,80.38,3.130
8.25,80.59,2.886
8.25,80.80,2.702
8.26,81.01,2.554
8.27,81.22,2.427
8.27,81.42,2.314
8.28,81.61,2.214
8.29,81.81,2.121
8.29,81.99,2.039
8.30,82.18,1.960
8.31,82.36,1.883
8.31,82.54,1.815
8.32,82.72,1.751
8.33,82.89,1.689
8.33,83.06,1.633
8.34,83.23,1.581
8.35,83.40,1.530
8.35,83.56,1.484
8.36,83.73,1.442
8.37,83.89,1.400
8.37,84.05,1.359
8.38,84.20,1.323
8.39,84.36,1.289
8.39,84.51,1.257
8.40,84.67,1.227
8.41,84.82,1.199
8.41,84.97,1.171
8.42,85.12,1.148
8.43,85.27,1.129
8.43,85.42,1.104
8.44,85.57,1.076
8.45,85.71,1.056
8.45,85.86,1.046
8.46,86.00,1.035
8.47,86.15,1.016
8.47,86.29,0.997
8.48,86.43,0.981
8.49,86.57,0.969
8.49,86.72,0.958
8.50,86.86,0.946
8.51,87.00,0.936
8.51,87.14,0.926
8.52,87.28,0.916
8.53,87.42,0.909
8.53,87.56,0.900
8.54,87.70,0.890
8.55,87.83,0.885
8.55,87.97,0.880
8.56,88.11,0.872
8.57,88.25,0.865
8.57,88.39,0.861
8.58,88.52,0.855
8.59,88.66,0.849
8.59,88.80,0.845
8.60,88.93,0.842
8.61,89.07,0.837
8.61,89.20,0.832
8.62,89.34,0.829
8.63,89.48,0.826
8.63,89.61,0.824
8.64,89.75,0.821
8.65,89.88,0.819
8.65,90.02,0.815
8.66,90.15,0.813
8.67,90.29,0.812
8.67,90.42,0.811
8.68,90.56,0.809
8.69,90.69,0.807
8.69,90.83,0.805
8.70,90.96,0.803
8.71,91.10,0.803
8.71,91.23,0.802
8.72,91.37,0.800
8.73,91.50,0.799
8.73,91.64,0.799
8.74,91.77,0.798
8.75,91.91,0.797
8.75,92.04,0.797
8.76,92.18,0.796
8.77,92.31,0.796
8.77,92.44,0.795
8.78,92.58,0.794
8.79,92.71,0.793
8.79,92.85,0.793
8.80,92.98,0.793
8.81,93.11,0.793
8.81,93.25,0.792
8.82,93.38,0.792
8.83,93.52,0.792
8.83,93.65,0.792
8.84,93.78,0.791
8.85,93.92,0.791
8.85,94.05,0.791
8.86,94.18,0.791
8.87,94.32,0.791
8.87,94.45,0.791
8.88,94.59,0.791
8.89,94.72,0.791
8.89,94.85,0.791
8.90,94.99,0.791
8.91,95.12,0.790
8.91,95.26,0.790
8.92,95.39,0.790
8.93,95.52,0.790
8.93,95.66,0.790
8.94,95.79,
8.95,95.92,
8.95,96.06,
8.96,96.19,
8.97,96.32,
8.97,96.46,
8.98,96.59,
8.99,96.72,
8.99,,
9.00,,

[step]
Ramp 20.00 °C/min to -80.00 °C
Time,Temperature,Heat Flow (Normalized)
min,°C,W/g
11.00,100.13,-0.044
11.00,100.13,-0.044
11.01,100.13,-0.044
11.02,100.13,-0.044
11.02,100.12,-0.044
11.03,100.12,-0.044
11.04,100.11,-0.044
11.04,100.11,-0.043
11.05,100.10,-0.042
11.06,100.08,-0.036
11.06,100.06,-0.028
11.07,100.04,-0.020
11.08,100.01,-0.016
11.08,99.98,-0.015
11.09,99.94,-0.016
11.10,99.89,-0.019
11.10,99.84,-0.021
11.11,99.79,-0.042
11.12,99.73,-0.062
11.12,99.66,-0.084
11.13,99.59,-0.110
11.14,99.51,-0.136
11.14,99.43,-0.165
11.15,99.35,-0.198
11.16,99.26,-0.231
11.16,99.17,-0.263
11.17,99.08,-0.295
11.18,98.98,-0.328
11.18,98.88,-0.359
11.19,98.78,-0.389
11.20,98.68,-0.418
11.20,98.58,-0.443
11.21,98.47,-0.469
11.22,98.36,-0.491
11.22,98.26,-0.513
11.23,98.15,-0.534
11.24,98.04,-0.552
11.24,97.93,-0.569
11.25,97.81,-0.584
11.26,97.70,-0.599
11.26,97.58,-0.614
11.27,97.47,-0.629
11.28,97.35,-0.641
11.28,97.23,-0.655
11.29,97.11,-0.666
11.30,96.99,-0.675
11.30,96.88,-0.686
11.31,96.75,-0.696
11.32,96.63,-0.706
11.32,96.51,-0.714
11.33,96.39,-0.721
11.34,96.27,-0.730
11.34,96.14,-0.737
11.35,96.02,-0.745
11.36,95.89,-0.753
11.36,95.77,-0.758
11.37,95.64,-0.762
11.38,95.52,-0.769
11.38,95.39,-0.774
11.39,95.27,-0.778
11.40,95.14,-0.784
11.40,95.01,-0.787
11.41,94.88,-0.792
11.42,94.76,-0.796
11.42,94.63,-0.798
11.43,94.50,-0.802
11.44,94.37,-0.806
11.44,94.24,-0.809
11.45,94.12,-0.811
11.46,93.99,-0.814
11.46,93.86,-0.817
11.47,93.73,-0.820
11.48,93.60,-0.820
11.48,93.47,-0.821
11.49,93.34,-0.824
11.50,93.21,-0.827
11.50,93.08,-0.829
11.51,92.95,-0.830
11.52,92.82,-0.830
11.52,92.69,-0.832
11.53,92.56,-0.833
11.54,92.43,-0.834
11.54,92.30,-0.836
11.55,92.17,-0.837
11.56,92.04,-0.837
11.56,91.91,-0.838
11.57,91.78,-0.838
11.58,91.65,-0.839
11.58,91.52,-0.840
11.59,91.39,-0.841
11.60,91.25,-0.841
11.60,91.12,-0.842
11.61,90.99,-0.842
11.62,90.86,-0.842
11.62,90.73,-0.843
11.63,90.60,-0.843
11.64,90.47,-0.843
11.64,90.33,-0.843
11.65,90.20,-0.844
11.66,90.07,-0.844
11.66,89.94,-0.844
11.67,89.81,-0.845
11.68,89.68,-0.845
11.68,89.54,-0.845
11.69,89.41,-0.845
11.70,89.28,-0.845
11.70,89.15,-0.845
11.71,89.02,-0.846
11.72,88.89,-0.846
11.72,88.75,-0.846
11.73,88.62,-0.846
11.74,88.49,-0.846
11.74,88.36,-0.846
11.75,88.23,-0.846
11.76,88.09,-0.846
11.76,87.96,-0.847
11.77,87.83,-0.847
11.78,87.70,-0.847
11.78,87.57,-0.847
11.79,87.43,-0.847
11.80,87.30,-0.847
11.80,87.17,-0.847
11.81,87.04,-0.847
11.82,86.91,-0.847
11.82,86.77,-0.847
11.83,86.64,-0.847
11.84,86.51,-0.847
11.84,86.38,-0.847
11.85,86.24,-0.847
11.86,86.11,-0.847
11.86,85.98,-0.847
11.87,85.85,-0.847
11.88,85.72,-0.847
11.88,85.58,-0.847
11.89,85.45,-0.847
11.90,85.32,-0.847
11.90,85.18,-0.847
11.91,85.05,-0.847
11.92,84.92,-0.848
11.92,84.79,-0.848
11.93,84.65,-0.848
11.94,84.52,-0.848
11.94,84.39,-0.848
11.95,84.26,-0.848
11.96,84.13,-0.848
11.96,83.99,-0.848
11.97,83.86,-0.848
11.98,83.73,-0.848
11.98,83.60,-0.848
11.99,83.46,-0.848
12.00,83.33,-0.847
12.00,83.20,-0.847
12.01,83.07,-0.847
12.02,82.93,-0.847
12.02,82.80,-0.847
12.03,82.67,-0.847
12.04,82.54,-0.847
12.04,82.40,-0.847
12.05,82.27,-0.847
12.06,82.14,-0.847
12.06,82.00,-0.847
12.07,81.87,-0.847
12.08,81.74,-0.847
12.08,81.61,-0.847
12.09,81.47,-0.847
12.10,81.34,-0.847
12.10,81.21,-0.847
12.11,81.07,-0.847
12.12,80.94,-0.847
12.12,80.81,-0.847
12.13,80.68,-0.847
12.14,80.54,-0.846
12.14,80.41,-0.846
12.15,80.28,-0.846
12.16,80.15,-0.846
12.16,80.01,-0.846
12.17,79.88,-0.846
12.18,79.75,-0.846
12.18,79.62,-0.846
12.19,79.48,-0.846
12.20,79.35,-0.846
12.20,79.22,-0.846
12.21,79.09,-0.845
12.22,78.95,-0.845
12.22,78.82,-0.845
12.23,78.69,-0.845
12.24,78.55,-0.845
12.24,78.42,-0.845
12.25,78.29,-0.845
12.26,78.15,-0.845
12.26,78.02,-0.844
12.27,77.89,-0.844
12.28,77.76,-0.844
12.28,77.62,-0.844
12.29,77.49,-0.843
12.30,77.36,-0.843
12.30,77.23,-0.843
12.31,77.09,-0.843
12.32,76.96,-0.843
12.32,76.83,-0.842
12.33,76.69,-0.842
12.34,76.56,-0.842
12.34,76.43,-0.842
12.35,76.30,-0.842
12.36,76.16,-0.842
12.36,76.03,-0.841
12.37,75.90,-0.841
12.38,75.76,-0.841
12.38,75.63,-0.841
12.39,75.50,-0.841
12.40,75.37,-0.840
12.40,75.23,-0.839
12.41,75.10,-0.839
12.42,74.97,-0.839
12.42,74.83,-0.838
12.43,74.70,-0.838
12.44,74.57,-0.838
12.44,74.43,-0.838
12.45,74.30,-0.837
12.46,74.17,-0.837
12.46,74.04,-0.837
12.47,73.90,-0.837
12.48,73.77,-0.837
12.48,73.64,-0.837
12.49,73.51,-0.836
12.50,73.37,-0.836
12.50,73.24,-0.836
12.51,73.11,-0.836
12.52,72.97,-0.836
12.52,72.84,-0.835
12.53,72.71,-0.835
12.54,72.57,-0.835
12.54,72.44,-0.834
12.55,72.31,-0.834
12.56,72.18,-0.834
12.56,72.04,-0.834
12.57,71.91,-0.833
12.58,71.78,-0.833
12.58,71.64,-0.833
12.59,71.51,-0.833
12.60,71.38,-0.833
12.60,71.25,-0.832
12.61,71.11,-0.832
12.62,70.98,-0.832
12.62,70.85,-0.832
12.63,70.71,-0.832
12.64,70.58,-0.831
12.64,70.45,-0.831
12.65,70.32,-0.831
12.66,70.18,-0.831
12.66,70.05,-0.831
12.67,69.92,-0.830
12.68,69.78,-0.830
12.68,69.65,-0.830
12.69,69.52,-0.830
12.70,69.38,-0.829
12.70,69.25,-0.829
12.71,69.12,-0.829
12.72,68.98,-0.829
12.72,68.85,-0.828
12.73,68.72,-0.828
12.74,68.59,-0.828
12.74,68.45,-0.828
12.75,68.32,-0.827
12.76,68.19,-0.827
12.76,68.05,-0.827
12.77,67.92,-0.827
12.78,67.79,-0.826
12.78,67.66,-0.826
12.79,67.52,-0.826
12.80,67.39,-0.825
12.80,67.26,-0.825
12.81,67.12,-0.825
12.82,66.99,-0.824
12.82,66.86,-0.824
12.83,66.73,-0.824
12.84,66.59,-0.824
12.84,66.46,-0.824
12.85,66.33,-0.823
12.86,66.19,-0.823
12.86,66.06,-0.823
12.87,65.93,-0.823
12.88,65.80,-0.823
12.88,65.66,-0.822
12.89,65.53,-0.822
12.90,65.40,-0.821
12.90,65.26,-0.821
12.91,65.13,-0.821
12.92,65.00,-0.821
12.92,64.86,-0.820
12.93,64.73,-0.820
12.94,64.60,-0.820
12.94,64.47,-0.820
12.95,64.33,-0.819
12.96,64.20,-0.819
12.96,64.07,-0.819
12.97,63.93,-0.819
12.98,63.80,-0.818
12.98,63.67,-0.818
12.99,63.53,-0.818
13.00,63.40,-0.817
13.00,63.27,-0.817
13.01,63.14,-0.817
13.02,63.00,-0.816
13.02,62.87,-0.816
13.03,62.74,-0.816
13.04,62.60,-0.816
13.04,62.47,-0.815
13.05,62.34,-0.815
13.06,62.20,-0.815
13.06,62.07,-0.814
13.07,61.94,-0.814
13.08,61.80,-0.814
13.08,61.67,-0.813
13.09,61.54,-0.812
13.10,61.41,-0.812
13.10,61.27,-0.812
13.11,61.14,-0.812
13.12,61.01,-0.811
13.12,60.87,-0.811
13.13,60.74,-0.811
13.14,60.61,-0.811
13.14,60.48,-0.810
13.15,60.34,-0.810
13.16,60.21,-0.809
13.16,60.08,-0.809
13.17,59.94,-0.809
13.18,59.81,-0.809
13.18,59.68,-0.808
13.19,59.55,-0.808
13.20,59.41,-0.808
13.20,59.28,-0.808
13.21,59.15,-0.808
13.22,59.01,-0.807
13.22,58.88,-0.807
13.23,58.75,-0.807
13.24,58.62,-0.807
13.24,58.48,-0.806
13.25,58.35,-0.806
13.26,58.22,-0.806
13.26,58.08,-0.806
13.27,57.95,-0.805
13.28,57.82,-0.805
13.28,57.69,-0.805
13.29,57.55,-0.805
13.30,57.42,-0.804
13.30,57.29,-0.804
13.31,57.15,-0.804
13.32,57.02,-0.804
13.32,56.89,-0.804
13.33,56.75,-0.803
13.34,56.62,-0.803
13.34,56.49,-0.803
13.35,56.36,-0.803
13.36,56.22,-0.802
13.36,56.09,-0.802
13.37,55.96,-0.802
13.38,55.82,-0.802
13.38,55.69,-0.801
13.39,55.56,-0.801
13.40,55.42,-0.801
13.40,55.29,-0.800
13.41,55.16,-0.800
13.42,55.03,-0.800
13.42,54.89,-0.800
13.43,54.76,-0.800
13.44,54.63,-0.799
13.44,54.49,-0.799
13.45,54.36,-0.799
13.46,54.23,-0.799
13.46,54.10,-0.798
13.47,53.96,-0.798
13.48,53.83,-0.798
13.48,53.70,-0.798
13.49,53.56,-0.797
13.50,53.43,-0.797
13.50,53.30,-0.797
13.51,53.16,-0.797
13.52,53.03,-0.796
13.52,52.90,-0.796
13.53,52.76,-0.796
13.54,52.63,-0.795
13.54,52.50,-0.795
13.55,52.37,-0.795
13.56,52.23,-0.795
13.56,52.10,-0.795
13.57,51.97,-0.794
13.58,51.83,-0.794
13.58,51.70,-0.793
13.59,51.57,-0.793
13.60,51.44,-0.793
13.60,51.30,-0.793
13.61,51.17,-0.792
13.62,51.04,-0.792
13.62,50.90,-0.792
13.63,50.77,-0.792
13.64,50.64,-0.791
13.64,50.50,-0.791
13.65,50.37,-0.791
13.66,50.24,-0.790
13.66,50.11,-0.790
13.67,49.97,-0.790
13.68,49.84,-0.789
13.68,49.71,-0.789
13.69,49.57,-0.789
13.70,49.44,-0.789
13.70,49.31,-0.788
13.71,49.18,-0.788
13.72,49.04,-0.788
13.72,48.91,-0.788
13.73,48.78,-0.787
13.74,48.64,-0.787
13.74,48.51,-0.787
13.75,48.38,-0.787
13.76,48.25,-0.787
13.76,48.11,-0.786
13.77,47.98,-0.786
13.78,47.85,-0.786
13.78,47.71,-0.785
13.79,47.58,-0.784
13.80,47.45,-0.784
13.80,47.32,-0.784
13.81,47.18,-0.783
13.82,47.05,-0.783
13.82,46.92,-0.783
13.83,46.78,-0.783
13.84,46.65,-0.783
13.84,46.52,-0.782
13.85,46.39,-0.782
13.86,46.25,-0.782
13.86,46.12,-0.782
13.87,45.99,-0.781
13.88,45.85,-0.781
13.88,45.72,-0.781
13.89,45.59,-0.781
13.90,45.46,-0.780
13.90,45.32,-0.780
13.91,45.19,-0.779
13.92,45.06,-0.779
13.92,44.92,-0.779
13.93,44.79,-0.779
13.94,44.66,-0.779
13.94,44.53,-0.778
13.95,44.39,-0.778
13.96,44.26,-0.777
13.96,44.13,-0.777
13.97,44.00,-0.777
13.98,43.86,-0.777
13.98,43.73,-0.776
13.99,43.60,-0.776
14.00,43.46,-0.776
14.00,43.33,-0.776
14.01,43.20,-0.775
14.02,43.07,-0.775
14.02,42.93,-0.775
14.03,42.80,-0.774
14.04,42.67,-0.774
14.04,42.53,-0.774
14.05,42.40,-0.774
14.06,42.27,-0.773
14.06,42.14,-0.773
14.07,42.00,-0.773
14.08,41.87,-0.773
14.08,41.74,-0.772
14.09,41.60,-0.772
14.10,41.47,-0.771
14.10,41.34,-0.771
14.11,41.21,-0.771
14.12,41.07,-0.771
14.12,40.94,-0.770
14.13,40.81,-0.770
14.14,40.67,-0.770
14.14,40.54,-0.769
14.15,40.41,-0.769
14.16,40.28,-0.769
14.16,40.14,-0.769
14.17,40.01,-0.769
14.18,39.88,-0.768
14.18,39.74,-0.768
14.19,39.61,-0.768
14.20,39.48,-0.768
14.20,39.35,-0.766
14.21,39.21,-0.765
14.22,39.08,-0.765
14.22,38.95,-0.765
14.23,38.81,-0.765
14.24,38.68,-0.765
14.24,38.55,-0.765
14.25,38.41,-0.765
14.26,38.28,-0.764
14.26,38.15,-0.764
14.27,38.02,-0.764
14.28,37.88,-0.763
[...]
66.21,-80.34,-0.018
66.21,-80.31,-0.018
66.22,-80.26,-0.018
66.23,-80.22,-0.017
66.23,-80.17,-0.011
66.24,-80.12,0.001
66.24,-80.07,0.011
66.24,-80.02,0.020
66.25,-79.96,0.031
66.26,-79.90,0.042
66.26,-79.84,0.053
66.26,-79.78,0.063
66.27,-79.72,0.074
66.28,-79.65,0.086
66.28,-79.58,0.097
66.29,-79.51,0.111
66.29,-79.44,0.122
66.29,-79.37,0.134
66.30,-79.30,0.145
66.31,-79.22,0.157
66.31,-79.15,0.166
66.31,-79.07,0.177
66.32,-79.00,0.188
66.33,-78.92,0.198
66.33,-78.84,0.206
66.34,-78.76,0.215
66.34,-78.68,0.223
66.34,-78.60,0.233
66.35,-78.52,0.240
66.36,-78.44,0.247
66.36,-78.35,0.253
66.36,-78.27,0.260
66.37,-78.18,0.268
66.38,-78.10,0.275
66.38,-78.02,0.281
66.39,-77.93,0.284
66.39,-77.84,0.291
66.39,-77.76,0.296
66.40,-77.67,0.302
66.41,-77.58,0.307
66.41,-77.50,0.313
66.41,-77.41,0.315
66.42,-77.32,0.319
66.43,-77.23,0.324
66.43,-77.14,0.329
66.44,-77.05,0.334
66.44,-76.96,0.337
66.44,-76.87,0.339
66.45,-76.78,0.343
66.46,-76.69,0.345
66.46,-76.59,0.351
66.46,-76.50,0.353
66.47,-76.41,0.356
66.48,-76.32,0.359
66.48,-76.23,0.363
66.49,-76.13,0.365
66.49,-76.04,0.367
66.49,-75.95,0.370
66.50,-75.85,0.375
66.51,-75.76,0.377
66.51,-75.67,0.379
66.51,-75.57,0.379
66.52,-75.48,0.380
66.53,-75.38,0.382
66.53,-75.29,0.385
66.54,-75.20,0.387
66.54,-75.10,0.389
66.54,-75.00,0.390
66.55,-74.91,0.393
66.56,-74.81,0.396
66.56,-74.72,0.398
66.56,-74.62,0.398
66.57,-74.53,0.400
66.58,-74.43,0.402
66.58,-74.34,0.403
66.59,-74.24,0.404
66.59,-74.15,0.405
66.59,-74.05,0.408
66.60,-73.95,0.409
66.61,-73.86,0.409
66.61,-73.76,0.411
66.61,-73.66,0.412
66.62,-73.57,0.412
66.63,-73.47,0.412
66.63,-73.37,0.413
66.64,-73.28,0.415
66.64,-73.18,0.416
66.64,-73.08,0.416
66.65,-72.98,0.417
66.66,-72.89,0.419
66.66,-72.79,0.421
66.66,-72.69,0.421
66.67,-72.60,0.422
66.68,-72.50,0.422
66.68,-72.40,0.423
66.69,-72.30,0.424
66.69,-72.20,0.425
66.69,-72.11,0.426
66.70,-72.01,0.426
66.71,-71.91,0.427
66.71,-71.82,0.428
66.71,-71.72,0.428
66.72,-71.62,0.429
66.73,-71.52,0.429
66.73,-71.42,0.430
66.74,-71.33,0.430
66.74,-71.23,0.431
66.74,-71.13,0.432
66.75,-71.03,0.433
66.76,-70.94,0.433
66.76,-70.84,0.433
66.76,-70.74,0.433
66.77,-70.64,0.434
66.78,-70.54,0.434
66.78,-70.44,0.435
66.79,-70.35,0.436
66.79,-70.25,0.436
66.79,-70.15,0.436
66.80,-70.05,0.437
66.81,-69.95,0.437
66.81,-69.86,0.438
66.81,-69.76,0.438
66.82,-69.66,0.438
66.83,-69.56,0.439
66.83,-69.46,0.440
66.84,-69.36,0.441
66.84,-69.26,0.441
66.84,-69.16,0.441
66.85,-69.07,0.442
66.86,-68.97,0.443
66.86,-68.87,0.443
66.86,-68.77,0.443
66.87,-68.67,0.443
66.88,-68.57,0.443
66.88,-68.47,0.444
66.89,-68.37,0.445
66.89,-68.28,0.445
66.89,-68.18,0.446
66.90,-68.08,0.446
66.91,-67.98,0.446
66.91,-67.88,0.446
66.91,-67.78,0.446
66.92,-67.68,0.447
66.93,-67.58,0.447
66.93,-67.48,0.447
66.94,-67.39,0.447
66.94,-67.29,0.447
66.94,-67.19,0.447
66.95,-67.09,0.447
66.96,-66.99,0.448
66.96,-66.89,0.448
66.96,-66.79,0.448
66.97,-66.69,0.448
66.98,-66.59,0.448
66.98,-66.49,0.448
66.99,-66.39,0.448
66.99,-66.30,0.448
66.99,-66.20,0.448
67.00,-66.10,0.448
67.01,-66.00,0.448
67.01,-65.90,0.448
67.01,-65.80,0.448
67.02,-65.70,0.448
67.03,-65.60,0.448
67.03,-65.50,0.448
67.04,-65.40,0.448
67.04,-65.30,0.448
67.04,-65.20,0.448
67.05,-65.10,0.448
67.06,-65.01,0.448
67.06,-64.90,0.446
67.06,-64.81,0.445
67.07,-64.71,0.445
67.08,-64.61,0.445
67.08,-64.51,0.445
67.09,-64.41,0.445
67.09,-64.31,0.445
67.09,-64.21,0.445
67.10,-64.11,0.445
67.11,-64.01,0.445
67.11,-63.91,0.445
67.11,-63.81,0.445
67.12,-63.71,0.445
67.13,-63.61,0.445
67.13,-63.51,0.445
67.14,-63.41,0.445
67.14,-63.31,0.445
67.14,-63.21,0.445
67.15,-63.11,0.445
67.16,-63.01,0.445
67.16,-62.91,0.445
67.16,-62.81,0.445
67.17,-62.71,0.445
67.18,-62.61,0.445
67.18,-62.52,0.445
67.19,-62.42,0.445
67.19,-62.32,0.445
67.19,-62.22,0.445
67.20,-62.12,0.445
67.21,-62.02,0.445
67.21,-61.92,0.445
67.21,-61.82,0.446
67.22,-61.72,0.446
67.23,-61.62,0.446
67.23,-61.52,0.446
67.24,-61.42,0.446
67.24,-61.32,0.446
67.24,-61.22,0.446
67.25,-61.12,0.446
67.26,-61.02,0.446
67.26,-60.92,0.446
67.26,-60.82,0.446
67.27,-60.72,0.446
67.28,-60.62,0.446
67.28,-60.52,0.447
67.29,-60.42,0.447
67.29,-60.32,0.447
67.29,-60.22,0.447
67.30,-60.12,0.447
67.31,-60.02,0.447
67.31,-59.92,0.447
67.31,-59.82,0.447
67.32,-59.72,0.448
67.33,-59.63,0.448
67.33,-59.53,0.448
67.34,-59.43,0.448
67.34,-59.33,0.448
67.34,-59.23,0.448
67.35,-59.13,0.449
67.36,-59.03,0.449
67.36,-58.93,0.449
67.36,-58.83,0.449
67.37,-58.73,0.449
67.38,-58.63,0.449
67.38,-58.53,0.449
67.39,-58.43,0.450
67.39,-58.33,0.450
67.39,-58.23,0.450
67.40,-58.13,0.450
67.41,-58.03,0.451
67.41,-57.93,0.451
67.41,-57.83,0.451
67.42,-57.73,0.451
67.43,-57.63,0.451
67.43,-57.53,0.451
67.44,-57.43,0.452
67.44,-57.33,0.452
67.44,-57.23,0.452
67.45,-57.13,0.452
67.46,-57.03,0.452
67.46,-56.93,0.453
67.46,-56.83,0.453
67.47,-56.73,0.454
67.48,-56.63,0.454
67.48,-56.53,0.454
67.49,-56.43,0.454
67.49,-56.33,0.454
67.49,-56.23,0.454
67.50,-56.13,0.454
67.51,-56.03,0.455
67.51,-55.93,0.455
67.51,-55.83,0.455
67.52,-55.73,0.455
67.53,-55.63,0.455
67.53,-55.53,0.456
67.54,-55.43,0.456
67.54,-55.33,0.457
67.54,-55.23,0.457
67.55,-55.13,0.457
67.56,-55.03,0.457
67.56,-54.93,0.458
67.56,-54.83,0.458
67.57,-54.73,0.459
67.58,-54.63,0.459
67.58,-54.53,0.459
67.59,-54.43,0.459
67.59,-54.33,0.460
67.59,-54.23,0.460
67.60,-54.13,0.460
67.61,-54.03,0.460
67.61,-53.93,0.460
67.61,-53.83,0.460
67.62,-53.73,0.460
67.63,-53.63,0.461
67.63,-53.53,0.461
67.64,-53.43,0.462
67.64,-53.33,0.463
67.64,-53.23,0.463
67.65,-53.13,0.463
67.66,-53.03,0.463
67.66,-52.93,0.464
67.66,-52.83,0.464
67.67,-52.73,0.464
67.68,-52.63,0.464
67.68,-52.53,0.464
67.69,-52.43,0.464
67.69,-52.33,0.464
67.69,-52.23,0.465
67.70,-52.13,0.466
67.71,-52.03,0.466
67.71,-51.93,0.466
67.71,-51.83,0.467
67.72,-51.73,0.467
67.73,-51.63,0.467
67.73,-51.53,0.467
67.74,-51.43,0.468
67.74,-51.33,0.468
67.74,-51.23,0.468
67.75,-51.13,0.468
67.76,-51.03,0.469
67.76,-50.93,0.470
67.76,-50.83,0.471
67.77,-50.73,0.471
67.78,-50.63,0.472
67.78,-50.53,0.472
67.79,-50.43,0.472
67.79,-50.33,0.472
67.79,-50.23,0.473
67.80,-50.13,0.475
67.81,-50.03,0.475
67.81,-49.93,0.475
67.81,-49.83,0.476
67.82,-49.73,0.477
67.83,-49.63,0.478
67.83,-49.53,0.479
67.84,-49.43,0.479
67.84,-49.33,0.479
67.84,-49.23,0.480
67.85,-49.13,0.480
67.86,-49.03,0.482
67.86,-48.93,0.484
67.86,-48.83,0.485
67.87,-48.73,0.486
67.88,-48.63,0.486
67.88,-48.53,0.486
67.89,-48.43,0.487
67.89,-48.33,0.488
67.89,-48.23,0.490
67.90,-48.13,0.492
67.91,-48.03,0.494
67.91,-47.93,0.496
67.91,-47.83,0.497
67.92,-47.73,0.497
67.93,-47.63,0.498
67.93,-47.53,0.498
67.94,-47.43,0.500
67.94,-47.33,0.502
67.94,-47.23,0.504
67.95,-47.13,0.506
67.96,-47.03,0.508
67.96,-46.94,0.510
67.96,-46.84,0.510
67.97,-46.74,0.511
67.98,-46.64,0.514
67.98,-46.54,0.518
67.99,-46.44,0.519
67.99,-46.34,0.519
67.99,-46.24,0.521
68.00,-46.14,0.525
68.01,-46.04,0.528
68.01,-45.94,0.530
68.01,-45.84,0.531
68.02,-45.74,0.535
68.03,-45.64,0.539
68.03,-45.54,0.542
68.04,-45.44,0.542
68.04,-45.34,0.544
68.04,-45.24,0.551
68.05,-45.14,0.555
68.06,-45.04,0.556
68.06,-44.94,0.557
68.06,-44.84,0.561
68.07,-44.75,0.565
68.08,-44.65,0.571
68.08,-44.55,0.575
68.09,-44.45,0.581
68.09,-44.35,0.584
68.09,-44.25,0.587
68.10,-44.15,0.590
68.11,-44.05,0.595
68.11,-43.95,0.601
68.11,-43.85,0.606
68.12,-43.75,0.611
68.13,-43.66,0.615
68.13,-43.56,0.620
68.14,-43.46,0.625
68.14,-43.36,0.629
68.14,-43.26,0.637
68.15,-43.16,0.641
68.16,-43.06,0.645
68.16,-42.96,0.647
68.16,-42.87,0.654
68.17,-42.77,0.659
68.18,-42.67,0.663
68.18,-42.57,0.665
68.19,-42.47,0.670
68.19,-42.37,0.673
68.19,-42.27,0.676
68.20,-42.18,0.676
68.21,-42.08,0.680
68.21,-41.98,0.683
68.21,-41.88,0.685
68.22,-41.78,0.683
68.23,-41.68,0.682
68.23,-41.58,0.684
68.24,-41.48,0.685
68.24,-41.38,0.684
68.24,-41.28,0.680
68.25,-41.18,0.679
68.26,-41.08,0.678
68.26,-40.98,0.675
68.26,-40.88,0.673
68.27,-40.78,0.671
68.28,-40.68,0.668
68.28,-40.58,0.664
68.29,-40.48,0.660
68.29,-40.38,0.657
68.30,-40.28,0.653
68.30,-40.18,0.650
68.30,-40.08,0.649
68.31,-39.98,0.645
68.31,-39.88,0.641
68.32,-39.78,0.638
68.33,-39.68,0.639
68.33,-39.58,0.639
68.34,-39.48,0.637
68.34,-39.38,0.634
68.35,-39.27,0.634
68.35,-39.18,0.634
68.35,-39.07,0.633
68.36,-38.97,0.631
68.36,-38.87,0.630
68.37,-38.77,0.630
68.38,-38.67,0.630
68.38,-38.57,0.629
68.39,-38.47,0.629
68.39,-38.37,0.629
68.40,-38.27,0.628
68.40,-38.17,0.628
68.40,-38.07,0.628
68.41,-37.97,0.627
68.41,-37.87,0.626
68.42,-37.76,0.626
68.43,-37.66,0.626
68.43,-37.56,0.626
68.44,-37.46,0.626
68.44,-37.36,0.625
68.45,-37.26,0.625
68.45,-37.16,0.625
68.45,-37.06,0.625
68.46,-36.96,0.624
68.46,-36.86,0.624
68.47,-36.76,0.624
68.48,-36.66,0.624
68.48,-36.56,0.624
68.49,-36.46,0.624
68.49,-36.36,0.623
68.50,-36.26,0.623
68.50,-36.16,0.623
68.50,-36.06,0.623
68.51,-35.96,0.623
68.51,-35.86,0.622
68.52,-35.76,0.622
68.53,-35.66,0.622
68.53,-35.55,0.622
68.54,-35.46,0.622
68.54,-35.35,0.622
68.55,-35.25,0.622
68.55,-35.16,0.622
68.55,-35.06,0.622
68.56,-34.95,0.621
68.56,-34.85,0.621
68.57,-34.75,0.621
68.58,-34.65,0.621
68.58,-34.55,0.621
68.59,-34.45,0.621
68.59,-34.35,0.621
68.60,-34.25,0.621
68.60,-34.15,0.621
68.60,-34.05,0.621
68.61,-33.95,0.621
68.61,-33.85,0.621
68.62,-33.75,0.621
68.63,-33.65,0.621
68.63,-33.55,0.621
68.64,-33.45,0.621
68.64,-33.35,0.620
68.65,-33.25,0.620
68.65,-33.15,0.620
68.65,-33.05,0.620
68.66,-32.95,0.620
68.66,-32.85,0.620
68.67,-32.75,0.620
68.68,-32.65,0.620
68.68,-32.55,0.620
68.69,-32.45,0.620
68.69,-32.35,0.620
68.70,-32.25,0.620
68.70,-32.14,0.620
68.70,-32.04,0.620
68.71,-31.95,0.620
68.71,-31.85,0.620
68.72,-31.74,0.620
68.73,-31.64,0.620
68.73,-31.55,0.620
68.74,-31.45,0.620
68.74,-31.34,0.620
68.75,-31.24,0.620
68.75,-31.14,0.620
68.75,-31.04,0.620
68.76,-30.94,0.620
68.76,-30.84,0.620
68.77,-30.74,0.620
68.78,-30.64,0.620
68.78,-30.54,0.620
68.79,-30.44,0.620
68.79,-30.34,0.620
68.80,-30.24,0.620
68.80,-30.14,0.620
68.80,-30.04,0.620
68.81,-29.94,0.620
68.81,-29.84,0.620
68.82,-29.74,0.620
68.83,-29.64,0.620
68.83,-29.54,0.620
68.84,-29.44,0.620
68.84,-29.34,0.620
68.85,-29.24,0.620
68.85,-29.14,0.620
68.85,-29.04,0.620
68.86,-28.94,0.620
68.86,-28.84,0.620
68.87,-28.74,0.620
68.88,-28.64,0.620
68.88,-28.54,0.620
68.89,-28.44,0.620
68.89,-28.34,0.620
68.90,-28.24,0.620
68.90,-28.14,0.620
68.90,-28.04,0.620
68.91,-27.93,0.620
68.91,-27.84,0.620
68.92,-27.74,0.620
68.93,-27.64,0.620
68.93,-27.54,0.620
68.94,-27.43,0.620
68.94,-27.33,0.620
68.95,-27.23,0.620
68.95,-27.13,0.620
68.95,-27.03,0.620
68.96,-26.93,0.620
68.96,-26.83,0.620
68.97,-26.73,0.620
68.98,-26.63,0.620
68.98,-26.53,0.620
68.99,-26.43,0.620
68.99,-26.33,0.620
69.00,-26.23,0.620
69.00,-26.13,0.620
69.00,-26.03,0.620
69.01,-25.93,0.620
69.01,-25.83,0.620
69.02,-25.73,0.620
69.03,-25.63,0.620
69.03,-25.53,0.620
69.04,-25.43,0.620
69.04,-25.33,0.621
69.05,-25.23,0.621
69.05,-25.13,0.621
69.05,-25.03,0.621
69.06,-24.93,0.621
69.06,-24.83,0.621
69.07,-24.73,0.621
69.08,-24.63,0.621
69.08,-24.53,0.621
69.09,-24.43,0.621
69.09,-24.33,0.621
69.10,-24.23,0.621
69.10,-24.13,0.621
69.10,-24.03,0.621
69.11,-23.93,0.621
69.11,-23.83,0.621
69.12,-23.72,0.621
69.13,-23.63,0.621
69.13,-23.52,0.621
69.14,-23.42,0.621
69.14,-23.33,0.621
69.15,-23.22,0.621
69.15,-23.12,0.621
69.15,-23.02,0.621
69.16,-22.92,0.621
69.16,-22.82,0.622
69.17,-22.72,0.622
69.18,-22.62,0.622
69.18,-22.52,0.622
69.19,-22.42,0.622
69.19,-22.32,0.622
69.20,-22.22,0.622
69.20,-22.12,0.622
69.20,-22.02,0.622
69.21,-21.92,0.622
69.21,-21.82,0.622
69.22,-21.72,0.622
69.23,-21.62,0.622
69.23,-21.52,0.622
69.24,-21.42,0.622
69.24,-21.32,0.622
69.25,-21.22,0.622
69.25,-21.12,0.622
69.25,-21.02,0.622
69.26,-20.92,0.623
69.26,-20.82,0.623
69.27,-20.72,0.623
69.28,-20.62,0.623
69.28,-20.52,0.623
69.29,-20.42,0.623
69.29,-20.32,0.623
69.30,-20.22,0.623
69.30,-20.12,0.623
69.30,-20.02,0.623
69.31,-19.92,0.623
69.31,-19.82,0.623
69.32,-19.71,0.623
69.33,-19.61,0.623
69.33,-19.52,0.623
69.34,-19.41,0.623
69.34,-19.32,0.623
69.35,-19.21,0.624
69.35,-19.11,0.624
69.35,-19.01,0.624
69.36,-18.91,0.624
69.36,-18.81,0.624
69.37,-18.71,0.624
69.38,-18.61,0.624
69.38,-18.51,0.624
69.39,-18.41,0.624
69.39,-18.31,0.624
69.40,-18.21,0.624
69.40,-18.11,0.624
69.40,-18.01,0.624
69.41,-17.91,0.624
69.41,-17.81,0.624
69.42,-17.71,0.624
69.43,-17.61,0.624
69.43,-17.51,0.624
69.44,-17.41,0.625
69.44,-17.31,0.625
69.45,-17.21,0.625
69.45,-17.11,0.625
69.45,-17.01,0.625
69.46,-16.91,0.625
69.46,-16.81,0.625
69.47,-16.71,0.625
69.48,-16.61,0.625
69.48,-16.51,0.625
69.49,-16.41,0.625
69.49,-16.31,0.625
69.50,-16.21,0.625
69.50,-16.11,0.625
69.50,-16.01,0.625
69.51,-15.91,0.626
69.51,-15.81,0.626
69.52,-15.71,0.626
69.53,-15.60,0.626
69.53,-15.51,0.626
69.54,-15.40,0.626
69.54,-15.30,0.626
69.55,-15.20,0.626
69.55,-15.10,0.626
69.55,-15.00,0.626
69.56,-14.90,0.626
69.56,-14.80,0.626
69.57,-14.70,0.626
69.58,-14.60,0.626
69.58,-14.50,0.626
69.59,-14.40,0.627
69.59,-14.30,0.627
69.60,-14.20,0.627
69.60,-14.10,0.627
69.60,-14.00,0.627
69.61,-13.90,0.627
69.61,-13.80,0.627
69.62,-13.70,0.627
69.63,-13.60,0.627
69.63,-13.50,0.627
69.64,-13.40,0.627
69.64,-13.30,0.627
69.65,-13.20,0.628
69.65,-13.10,0.628
69.65,-13.00,0.628
69.66,-12.90,0.628
69.66,-12.80,0.628
69.67,-12.70,0.628
69.68,-12.60,0.628
69.68,-12.50,0.628
69.69,-12.40,0.628
69.69,-12.30,0.628
69.70,-12.20,0.628
69.70,-12.10,0.628
69.70,-12.00,0.628
69.71,-11.90,0.628
69.71,-11.80,0.628
69.72,-11.70,0.628
69.73,-11.60,0.628
69.73,-11.50,0.629
69.74,-11.40,0.629
69.74,-11.30,0.629
69.75,-11.20,0.629
69.75,-11.10,0.629
69.75,-11.00,0.629
69.76,-10.89,0.629
69.76,-10.79,0.629
69.77,-10.69,0.629
69.78,-10.59,0.629
69.78,-10.49,0.629
69.79,-10.39,0.629
69.79,-10.29,0.629
69.80,-10.19,0.629
69.80,-10.09,0.629
69.80,-9.99,0.630
69.81,-9.89,0.630
69.81,-9.79,0.630
69.82,-9.69,0.630
69.83,-9.59,0.630
69.83,-9.49,0.630
69.84,-9.39,0.630
69.84,-9.29,0.630
69.85,-9.19,0.630
69.85,-9.09,0.630
69.85,-8.99,0.630
69.86,-8.89,0.630
69.86,-8.79,0.630
69.87,-8.69,0.630
69.88,-8.59,0.630
69.88,-8.49,0.630
69.89,-8.39,0.631
69.89,-8.29,0.631
69.90,-8.19,0.631
69.90,-8.09,0.631
69.90,-7.99,0.631
69.91,-7.89,0.631
69.91,-7.79,0.631
69.92,-7.69,0.631
69.93,-7.59,0.631
69.93,-7.49,0.631
69.94,-7.39,0.631
69.94,-7.29,0.631
69.95,-7.19,0.632
69.95,-7.09,0.632
69.95,-6.99,0.632
69.96,-6.89,0.632
69.96,-6.79,0.632
69.97,-6.69,0.632
69.98,-6.59,0.632
69.98,-6.48,0.632
69.99,-6.38,0.632
69.99,-6.28,0.632
70.00,-6.19,0.632
70.00,-6.08,0.632
70.00,-5.99,0.633
70.01,-5.88,0.633
70.01,-5.78,0.633
70.02,-5.68,0.633
70.03,-5.58,0.633
70.03,-5.48,0.633
70.04,-5.38,0.633
70.04,-5.28,0.633
70.05,-5.18,0.633
70.05,-5.08,0.634
70.05,-4.98,0.634
70.06,-4.88,0.634
70.06,-4.78,0.634
70.07,-4.68,0.634
70.08,-4.58,0.634
70.08,-4.48,0.634
70.09,-4.38,0.634
70.09,-4.28,0.634
70.10,-4.18,0.634
70.10,-4.08,0.634
70.10,-3.98,0.634
70.11,-3.88,0.635
70.11,-3.78,0.635
70.12,-3.68,0.635
70.13,-3.58,0.635
70.13,-3.48,0.635
70.14,-3.38,0.635
70.14,-3.28,0.635
70.15,-3.18,0.635
70.15,-3.08,0.635
70.15,-2.98,0.635
70.16,-2.88,0.635
70.16,-2.78,0.635
70.17,-2.68,0.636
70.18,-2.58,0.636
70.18,-2.48,0.636
70.19,-2.38,0.636
70.19,-2.28,0.636
70.20,-2.18,0.636
70.20,-2.07,0.636
70.20,-1.97,0.636
70.21,-1.88,0.636
70.21,-1.77,0.636
70.22,-1.67,0.636
70.23,-1.57,0.637
70.23,-1.48,0.637
70.24,-1.37,0.637
70.24,-1.27,0.637
70.25,-1.17,0.637
70.25,-1.07,0.637
70.25,-0.97,0.637
70.26,-0.87,0.637
70.26,-0.77,0.637
70.27,-0.67,0.637
70.28,-0.57,0.638
70.28,-0.47,0.638
70.29,-0.37,0.638
70.29,-0.27,0.638
70.30,-0.17,0.638
70.30,-0.07,0.638
70.30,0.03,0.638
70.31,0.13,0.638
70.31,0.23,0.638
70.32,0.33,0.639
70.33,0.43,0.639
70.33,0.53,0.639
70.34,0.63,0.639
70.34,0.73,0.639
70.35,0.83,0.639
70.35,0.93,0.639
70.35,1.03,0.639
70.36,1.13,0.639
70.36,1.23,0.639
70.37,1.33,0.639
70.38,1.43,0.639
70.38,1.53,0.639
70.39,1.63,0.640
70.39,1.73,0.640
70.40,1.83,0.640
70.40,1.93,0.640
70.40,2.03,0.640
70.41,2.13,0.640
70.41,2.23,0.640
70.42,2.33,0.640
70.43,2.43,0.640
70.43,2.54,0.641
70.44,2.63,0.641
70.44,2.73,0.641
70.45,2.83,0.641
70.45,2.93,0.641
70.45,3.04,0.641
70.46,3.14,0.641
70.46,3.24,0.641
70.47,3.34,0.641
70.48,3.44,0.641
70.48,3.54,0.641
70.49,3.64,0.642
70.49,3.74,0.642
70.50,3.84,0.642
70.50,3.94,0.642
70.50,4.04,0.642
70.51,4.14,0.642
70.51,4.24,0.642
70.52,4.34,0.642
70.53,4.44,0.643
70.53,4.54,0.643
70.54,4.64,0.643
70.54,4.74,0.643
70.55,4.84,0.643
70.55,4.94,0.643
70.55,5.04,0.643
70.56,5.14,0.643
70.56,5.24,0.643
70.57,5.34,0.643
70.58,5.44,0.644
70.58,5.54,0.644
70.59,5.64,0.644
70.59,5.74,0.644
70.60,5.84,0.644
70.60,5.94,0.644
70.60,6.04,0.644
70.61,6.14,0.644
70.61,6.24,0.645
70.62,6.34,0.645
70.63,6.44,0.645
70.63,6.54,0.645
70.64,6.64,0.646
70.64,6.74,0.646
70.65,6.84,0.646
70.65,6.94,0.646
70.65,7.05,0.646
70.66,7.15,0.646
70.66,7.24,0.646
70.67,7.34,0.647
70.68,7.45,0.647
70.68,7.55,0.647
70.69,7.65,0.647
70.69,7.75,0.647
70.70,7.85,0.647
70.70,7.95,0.647
70.70,8.05,0.647
70.71,8.15,0.647
70.71,8.25,0.648
70.72,8.35,0.648
70.73,8.45,0.648
70.73,8.55,0.648
70.74,8.65,0.648
70.74,8.75,0.648
70.75,8.85,0.648
70.75,8.95,0.648
70.75,9.05,0.649
70.76,9.15,0.649
70.76,9.25,0.649
70.77,9.35,0.649
70.78,9.45,0.649
70.78,9.55,0.649
70.79,9.65,0.649
70.79,9.75,0.649
70.80,9.85,0.650
70.80,9.95,0.650
70.80,10.05,0.650
70.81,10.15,0.650
70.81,10.25,0.650
70.82,10.35,0.650
70.83,10.45,0.650
70.83,10.55,0.650
70.84,10.65,0.651
70.84,10.75,0.651
70.85,10.85,0.651
70.85,10.95,0.651
70.85,11.05,0.651
70.86,11.15,0.651
70.86,11.25,0.651
70.87,11.35,0.651
70.88,11.45,0.652
70.88,11.55,0.652
70.89,11.65,0.652
70.89,11.75,0.652
70.90,11.85,0.652
70.90,11.95,0.652
70.90,12.05,0.652
70.91,12.15,0.653
70.91,12.25,0.653
70.92,12.35,0.653
70.93,12.45,0.653
70.93,12.55,0.653
70.94,12.65,0.653
70.94,12.76,0.653
70.95,12.86,0.653
70.95,12.96,0.654
70.95,13.06,0.654
70.96,13.16,0.654
70.96,13.26,0.654
70.97,13.36,0.654
70.98,13.46,0.655
70.98,13.56,0.655
70.99,13.66,0.655
70.99,13.76,0.655
71.00,13.86,0.655
71.00,13.96,0.655
71.00,14.06,0.655
71.01,14.16,0.656
71.01,14.26,0.656
71.02,14.36,0.656
71.03,14.46,0.656
71.03,14.56,0.656
71.04,14.66,0.657
71.04,14.76,0.657
71.05,14.86,0.657
71.05,14.96,0.657
71.05,15.06,0.657
71.06,15.16,0.657
71.06,15.26,0.658
71.07,15.36,0.658
71.08,15.46,0.658
71.08,15.56,0.658
71.09,15.66,0.658
71.09,15.76,0.658
71.10,15.86,0.658
71.10,15.96,0.658
71.10,16.06,0.659
71.11,16.17,0.659
71.11,16.26,0.659
71.12,16.36,0.659
71.13,16.46,0.659
71.13,16.57,0.660
71.14,16.66,0.660
71.14,16.77,0.660
71.15,16.87,0.660
71.15,16.97,0.660
71.15,17.07,0.660
71.16,17.17,0.660
71.16,17.27,0.661
71.17,17.37,0.661
71.18,17.47,0.661
71.18,17.57,0.661
71.19,17.67,0.661
71.19,17.77,0.661
71.20,17.87,0.661
71.20,17.97,0.662
71.20,18.07,0.662
71.21,18.17,0.662
71.21,18.27,0.662
71.22,18.37,0.662
71.23,18.47,0.663
71.23,18.57,0.663
71.24,18.67,0.663
71.24,18.77,0.663
71.25,18.87,0.663
71.25,18.97,0.663
71.25,19.07,0.663
71.26,19.17,0.663
71.26,19.27,0.664
71.27,19.37,0.664
71.28,19.47,0.664
71.28,19.57,0.664
71.29,19.67,0.665
71.29,19.77,0.665
71.30,19.87,0.665
71.30,19.97,0.665
71.30,20.07,0.665
71.31,20.17,0.665
71.31,20.27,0.665
71.32,20.37,0.665
71.33,20.47,0.665
71.33,20.57,0.666
71.34,20.67,0.666
71.34,20.78,0.666
71.35,20.88,0.666
71.35,20.97,0.666
71.35,21.08,0.666
71.36,21.18,0.666
71.36,21.28,0.667
71.37,21.38,0.667
71.38,21.48,0.667
71.38,21.58,0.667
71.39,21.68,0.667
71.39,21.78,0.667
71.40,21.88,0.667
71.40,21.98,0.668
71.40,22.08,0.668
71.41,22.18,0.668
71.41,22.28,0.668
71.42,22.38,0.668
71.43,22.48,0.669
71.43,22.58,0.669
71.44,22.68,0.669
71.44,22.78,0.669
71.45,22.88,0.669
71.45,22.98,0.669
71.45,23.08,0.669
71.46,23.18,0.670
71.46,23.28,0.670
71.47,23.38,0.670
71.48,23.48,0.670
71.48,23.58,0.670
71.49,23.68,0.670
71.49,23.78,0.670
71.50,23.88,0.671
71.50,23.98,0.671
71.50,24.08,0.671
71.51,24.18,0.671
71.51,24.28,0.671
71.52,24.38,0.671
71.53,24.48,0.671
71.53,24.58,0.672
71.54,24.68,0.672
71.54,24.78,0.672
71.55,24.88,0.672
71.55,24.98,
71.55,25.08,
71.56,25.18,
71.56,25.28,
71.57,25.38,
71.58,25.49,
71.58,25.58,
71.59,25.69,
71.59,25.79,
71.60,25.89,
71.60,,
71.60,,