File: DSC/2025_05_29_Felodipine_0C_160C_5Cmin_x3.csv
Filename,2025_05_29_Felodipine_0C_160C_5Cmin_x3
Instrument name,DSC2A-00468 (192.168.1.100)
Operator,Yarger
rundate,5/29/2025
Sample name,2025_05_29_Felodipine_0C_160C_5Cmin_x3
proceduresegments,Data Off ; Equilibrate 0.00 °C; Data On ; Ramp 5.00 °C/min to 160.00 °C; Data Off ; Isothermal 1.0 min; Data On ; Ramp 5.00 °C/min to 0.00 °C; Data Off ; Isothermal 1.0 min; Data On ; Ramp 5.00 °C/min to 160.00 °C; Data Off ; Isothermal 1.0 min; Data On ; Ramp 5.00 °C/min to 0.00 °C; Data Off ; Isothermal 1.0 min; Data On ; Ramp 5.00 °C/min to 30.00 °C
[File Parameters]
Run date,5/29/2025 11:19:48 PM
Trios version,5.1.1.46572
Original File Name,
Current File Name,D:\DSC2500\JYarger\2025_05_29_Felodipine_0C_160C_5Cmin_x3.tri
[Procedure]
Procedure Name,FEL_0C_160C_5Cmin_x3
Sample Name,2025_05_29_Felodipine_0C_160C_5Cmin_x3
Sample Mass,56.97 mg
Reference Sample Mass,0 mg
Pan Mass,9.77 mg
Pan Number,16
Reference Pan Mass,56.96 mg
Reference Pan Number,10
Pan Type,Tzero Aluminum Hermetic
Comments,Al Hermetic DSC Consumables sealed Pan/Lid. A2 Tray (Google Sheet: DSC_Samples_A2_Tray_May2025)
Project Name,CA
Operator,Yarger
Test,Custom
Unload Max Temperature,30
Unload Min Temperature,30
Load Max Temperature,30
Load Min Temperature,30
Stop on Gas Flow Error,Yes
[Signal List]
Signal #1,Time (min)
Signal #2,Temperature (°C)
Signal #3,Heat Flow (mW)
Signal #4,Delta T (µV)
Signal #5,Delta Tzero (µV)
Signal #6,Tzero Temperature (°C)
Signal #7,Cell Purge (mL/min)
Signal #8,Heater Temp (°C)
Signal #9,Power Delivered (W)
Signal #10,Reference Junction Temperature (°C)
Signal #11,Flange Temperature (°C)
Signal #12,Heat Flow Phase (rad)
Signal #13,Total Heat Capacity (J/°C)
Signal #14,Heat Capacity (J/°C)
[Configuration]
Company Name,ASU
Instrument Name,DSC2A-00468
Instrument Type,DSC2500
Serial Number,DSC2A-00468
IP,192.168.1.100
Location of Instrument,MRRC
DisplayType,Unknown
Sample Interval ,0.1 s/pt
Selected Heat Flow,T4P
Exotherm Direction,Down
Cell Serial,DRC2-00792
Lid Type,Standard
Cooler,RCS 90
Leave Cooler on at End of Sequence,On
Gas 2,Nitrogen
Gas Selected,Channel 1
Flow Rate,50 mL/min
Secondary Purge,On
Licensed Heat Flow,Heat Flow T4P
Modulation Licensed,Yes
[Versions]
Common IDD Version,1
Cortex Version,VER 2.10.2.31
Driver,5.0.0.6
GDM Version,1.0.3.3
TouchscreenVersion,1.0.0.16145
FEP Version,1.2.1.21
FEP Bootloader,2.0.0.5
AutoSampler Version,2.1.1.26
Auto Sampler Bootloader,2.0.0.5
FCM Version,1.1.0.3
FCM Bootloader,2.0.0.5
[Experiment Logs]
Experiment Log Entry # 1,Data On set to 0
Experiment Log Entry # 3,Equilibrate Segment 0 (C) Started
Experiment Log Entry # 5,Air Cool is off.
Experiment Log Entry # 7,Data On set to 1
Experiment Log Entry # 9,Ramp Segment 5 C/min to 160 Started
Experiment Log Entry # 11,Data On set to 0
Experiment Log Entry # 13,Isothermal Segment 1 min started
Experiment Log Entry # 15,Data On set to 1
Experiment Log Entry # 17,Ramp Segment 5 C/min to 0 Started
Experiment Log Entry # 19,Data On set to 0
Experiment Log Entry # 21,Isothermal Segment 1 min started
Experiment Log Entry # 23,Data On set to 1
Experiment Log Entry # 25,Ramp Segment 5 C/min to 160 Started
Experiment Log Entry # 27,Data On set to 0
Experiment Log Entry # 29,Isothermal Segment 1 min started
Experiment Log Entry # 31,Data On set to 1
Experiment Log Entry # 33,Ramp Segment 5 C/min to 0 Started
Experiment Log Entry # 35,Data On set to 0
Experiment Log Entry # 37,Isothermal Segment 1 min started
Experiment Log Entry # 39,Data On set to 1
Experiment Log Entry # 41,Ramp Segment 5 C/min to 30 Started
[Method Log]
Method Log Entry # 1,Data Off
Method Log Entry # 2,Equilibrate 0 °C
Method Log Entry # 3,Data On
Method Log Entry # 4,(Ramp 527864) Ramp 5 °C/minute to 160 °C
Method Log Entry # 5,Data Off
Method Log Entry # 6,Isothermal 1 minutes
Method Log Entry # 7,Data On
Method Log Entry # 8,(Ramp 527868) Ramp 5 °C/minute to 0 °C
Method Log Entry # 9,Data Off
Method Log Entry # 10,Isothermal 1 minutes
Method Log Entry # 11,Data On
Method Log Entry # 12,(Ramp 527872) Ramp 5 °C/minute to 160 °C
Method Log Entry # 13,Data Off
Method Log Entry # 14,Isothermal 1 minutes
Method Log Entry # 15,Data On
Method Log Entry # 16,(Ramp 527876) Ramp 5 °C/minute to 0 °C
Method Log Entry # 17,Data Off
Method Log Entry # 18,Isothermal 1 minutes
Method Log Entry # 19,Data On
Method Log Entry # 20,(Ramp 527880) Ramp 5 °C/minute to 30 °C
Cell Serial,DRC2-00792
[T1 Calibration]
Slope,-0.008529666
Offset,9.636258
Initial Temperature,98.23
GUID,f8bfdadc-4977-4fdf-ba6d-0ba9134940c3
[TZero Calibration]
Date Applied,11/29/2022 4:06:13 PM
Description,From -89.059 °C to 396.009 °C at 20.000°C/min
Gas Type,Nitrogen
Pan Type,None
Source Files 1,C:\Users\yargerlab\Desktop\DSC Data\General\TZero_calibration_11_29_22_2nd(2).tri
Source Files 2,C:\Users\yargerlab\Desktop\DSC Data\General\TZero_calibration_11_29_22_2nd(3).tri
Delta T Offset,13.05235
Delta T Slope,-0.007271007
Delta T0 Offset,-13.69128
Delta T0 Slope,0.06063341
[Temperature Calibration]
Date Applied,11/29/2022 7:12:28 PM
Description,From 106.590 °C to 186.590 °C at 10.000°C/min
Gas Type,Nitrogen
Pan Type,Tzero Aluminum Hermetic
Source Files 1,C:\Users\yargerlab\Desktop\DSC Data\General\Indium(6).tri
Measured 1,157.391
Known 1,156.598
[Cell Constant Calibration]
Date Applied,11/29/2022 7:12:29 PM
Description,From 106.590 °C to 186.590 °C at 10.000°C/min
Gas Type,Nitrogen
Pan Type,Tzero Aluminum Hermetic
Source Files 1,C:\Users\yargerlab\Desktop\DSC Data\General\Indium(6).tri
T4P KCell,1.006051
Onset Slope,63.26126 mW/°C
[Direct Cp Calibration]
Date Applied,11/30/2022 11:04:51 AM
Description,From -79.983 °C to 298.409 °C at 10.000°C/min
Gas Type,Nitrogen
Pan Type,Tzero Aluminum Hermetic
Source Files 1,C:\Users\yargerlab\Desktop\DSC Data\General\Sapphire_Heat_Capacity_11_30_22.tri
[Rev Cp Calibration]
Date Applied,11/30/2022 1:58:51 PM
Description,From -79.996 °C to 292.812 °C at 3.000°C/min
Gas Type,Nitrogen
Pan Type,Tzero Aluminum Hermetic
Source Files 1,C:\Users\yargerlab\Desktop\DSC Data\General\Sapphire_MDSC_Calibration_11_30_22.tri
[step]
Ramp 5.00 °C/min to 160.00 °C
Time,Temperature,Heat Flow (Normalized)
min,°C,W/g
0.00,0.13,-0.007
0.02,0.13,-0.007
0.04,0.12,-0.006
0.07,0.13,-0.005
0.09,0.14,-0.005
0.11,0.16,-0.004
0.13,0.20,-0.003
0.15,0.25,-0.002
0.17,0.31,0.000
0.19,0.38,0.001
0.22,0.46,0.003
0.24,0.54,0.005
0.26,0.62,0.006
0.28,0.71,0.007
0.30,0.80,0.008
0.33,0.89,0.009
0.35,0.99,0.010
0.37,1.09,0.010
0.39,1.18,0.011
0.41,1.28,0.011
0.43,1.38,0.012
0.45,1.49,0.012
0.48,1.59,0.012
0.50,1.69,0.013
0.52,1.80,0.013
0.54,1.90,0.013
0.56,2.00,0.013
0.58,2.11,0.013
0.61,2.21,0.013
0.63,2.32,0.013
0.65,2.43,0.014
0.67,2.53,0.014
0.69,2.64,0.014
0.72,2.74,0.014
0.74,2.85,0.014
0.76,2.96,0.014
0.78,3.06,0.014
0.80,3.17,0.014
0.82,3.28,0.014
0.85,3.38,0.014
0.87,3.49,0.014
0.89,3.60,0.014
0.91,3.71,0.014
0.93,3.81,0.014
0.95,3.92,0.014
0.98,4.03,0.014
1.00,4.13,0.014
1.02,4.24,0.014
1.04,4.35,0.014
1.06,4.46,0.014
1.08,4.57,0.014
1.11,4.67,0.014
1.13,4.78,0.014
1.15,4.89,0.014
1.17,5.00,0.014
1.19,5.10,0.014
1.21,5.21,0.014
1.23,5.32,0.014
1.26,5.43,0.015
1.28,5.54,0.015
1.30,5.64,0.015
1.32,5.75,0.015
1.34,5.86,0.015
1.37,5.97,0.015
1.39,6.08,0.015
1.41,6.18,0.015
1.43,6.29,0.015
1.45,6.40,0.015
1.47,6.51,0.015
1.49,6.62,0.015
1.52,6.72,0.015
1.54,6.83,0.015
1.56,6.94,0.015
1.58,7.05,0.015
1.60,7.16,0.015
1.63,7.27,0.015
1.65,7.37,0.015
1.67,7.48,0.015
1.69,7.59,0.015
1.71,7.70,0.015
1.73,7.81,0.015
1.76,7.91,0.015
1.78,8.02,0.015
1.80,8.13,0.015
1.82,8.24,0.015
1.84,8.35,0.015
1.86,8.46,0.015
1.88,8.57,0.015
1.91,8.67,0.015
1.93,8.78,0.015
1.95,8.89,0.015
1.97,9.00,0.015
1.99,9.11,0.015
2.02,9.21,0.015
2.04,9.32,0.015
2.06,9.43,0.015
2.08,9.54,0.015
2.10,9.65,0.015
2.12,9.76,0.015
2.14,9.87,0.015
2.17,9.97,0.015
2.19,10.08,0.015
2.21,10.19,0.015
2.23,10.30,0.015
2.25,10.41,0.015
2.28,10.51,0.015
2.30,10.62,0.015
2.32,10.73,0.015
2.34,10.84,0.015
2.36,10.95,0.015
2.38,11.06,0.015
2.41,11.16,0.015
2.43,11.27,0.015
2.45,11.38,0.015
2.47,11.49,0.015
2.49,11.60,0.015
2.51,11.71,0.015
2.54,11.81,0.015
2.56,11.92,0.015
2.58,12.03,0.015
2.60,12.14,0.015
2.62,12.25,0.015
2.64,12.36,0.015
2.66,12.47,0.015
2.69,12.57,0.015
2.71,12.68,0.015
2.73,12.79,0.015
2.75,12.90,0.015
2.77,13.01,0.015
2.79,13.12,0.015
2.82,13.22,0.015
2.84,13.33,0.015
2.86,13.44,0.015
2.88,13.55,0.015
2.90,13.66,0.015
2.93,13.77,0.015
2.95,13.88,0.015
2.97,13.98,0.015
2.99,14.09,0.015
3.01,14.20,0.015
3.03,14.31,0.015
3.06,14.42,0.015
3.08,14.53,0.015
3.10,14.63,0.015
3.12,14.74,0.015
3.14,14.85,0.015
3.16,14.96,0.015
3.19,15.07,0.015
3.21,15.18,0.015
3.23,15.28,0.015
3.25,15.39,0.015
3.27,15.50,0.015
3.29,15.61,0.015
3.31,15.72,0.015
3.34,15.83,0.015
3.36,15.94,0.015
3.38,16.04,0.015
3.40,16.15,0.015
3.42,16.26,0.015
3.44,16.37,0.015
3.47,16.48,0.015
3.49,16.58,0.015
3.51,16.69,0.015
3.53,16.80,0.015
3.55,16.91,0.015
3.58,17.02,0.015
3.60,17.13,0.015
3.62,17.24,0.015
3.64,17.34,0.015
3.66,17.45,0.015
3.68,17.56,0.015
3.71,17.67,0.015
3.73,17.78,0.015
3.75,17.88,0.015
3.77,17.99,0.015
3.79,18.10,0.015
3.81,18.21,0.015
3.84,18.32,0.015
3.86,18.43,0.015
3.88,18.54,0.015
3.90,18.64,0.015
3.92,18.75,0.015
3.94,18.86,0.015
3.96,18.97,0.015
3.99,19.08,0.015
4.01,19.19,0.015
4.03,19.30,0.015
4.05,19.40,0.015
4.07,19.51,0.015
4.09,19.62,0.015
4.12,19.73,0.015
4.14,19.84,0.015
4.16,19.95,0.015
4.18,20.05,0.015
4.20,20.16,0.015
4.23,20.27,0.015
4.25,20.38,0.015
4.27,20.49,0.015
4.29,20.60,0.015
4.31,20.70,0.015
4.33,20.81,0.015
4.35,20.92,0.015
4.38,21.03,0.015
4.40,21.14,0.015
4.42,21.25,0.015
4.44,21.35,0.015
4.46,21.46,0.015
4.49,21.57,0.015
4.51,21.68,0.015
4.53,21.79,0.015
4.55,21.90,0.015
4.57,22.01,0.015
4.59,22.11,0.015
4.61,22.22,0.015
4.64,22.33,0.015
4.66,22.44,0.015
4.68,22.55,0.015
4.70,22.66,0.015
4.72,22.76,0.015
4.75,22.87,0.015
4.77,22.98,0.015
4.79,23.09,0.015
4.81,23.20,0.015
4.83,23.31,0.015
4.85,23.41,0.015
4.88,23.52,0.015
4.90,23.63,0.015
4.92,23.74,0.015
4.94,23.85,0.015
4.96,23.96,0.015
4.98,24.06,0.015
5.00,24.17,0.015
5.03,24.28,0.015
5.05,24.39,0.015
5.07,24.50,0.015
5.09,24.61,0.015
5.11,24.72,0.015
5.14,24.83,0.015
5.16,24.93,0.015
5.18,25.04,0.015
5.20,25.15,0.015
5.22,25.26,0.015
5.24,25.37,0.015
5.26,25.47,0.015
5.29,25.58,0.015
5.31,25.69,0.015
5.33,25.80,0.015
5.35,25.91,0.015
5.37,26.02,0.015
5.40,26.12,0.015
5.42,26.23,0.015
5.44,26.34,0.015
5.46,26.45,0.015
5.48,26.56,0.015
5.50,26.67,0.015
5.53,26.78,0.015
5.55,26.88,0.015
5.57,26.99,0.015
5.59,27.10,0.015
5.61,27.21,0.015
5.63,27.32,0.015
5.65,27.42,0.015
5.68,27.53,0.015
5.70,27.64,0.015
5.72,27.75,0.015
5.74,27.86,0.015
5.76,27.97,0.015
5.79,28.07,0.015
5.81,28.18,0.015
5.83,28.29,0.015
5.85,28.40,0.015
5.87,28.51,0.015
5.89,28.62,0.015
5.91,28.73,0.015
5.94,28.83,0.015
5.96,28.94,0.015
5.98,29.05,0.015
6.00,29.16,0.015
6.02,29.27,0.015
6.05,29.38,0.015
6.07,29.49,0.015
6.09,29.60,0.015
6.11,29.70,0.015
6.13,29.81,0.015
6.15,29.92,0.015
6.18,30.03,0.015
6.20,30.14,0.015
6.22,30.24,0.015
6.24,30.35,0.015
6.26,30.46,0.015
6.28,30.57,0.015
6.30,30.68,0.015
6.33,30.79,0.015
6.35,30.89,0.015
6.37,31.00,0.015
6.39,31.11,0.015
6.41,31.22,0.015
6.44,31.33,0.015
6.46,31.44,0.015
6.48,31.55,0.015
6.50,31.65,0.015
6.52,31.76,0.015
6.54,31.87,0.015
6.56,31.98,0.015
6.59,32.09,0.015
6.61,32.20,0.015
6.63,32.30,0.015
6.65,32.41,0.015
6.67,32.52,0.015
6.70,32.63,0.015
6.72,32.74,0.015
6.74,32.85,0.015
6.76,32.95,0.015
6.78,33.06,0.015
6.80,33.17,0.015
6.83,33.28,0.015
6.85,33.39,0.015
6.87,33.50,0.015
6.89,33.61,0.015
6.91,33.71,0.015
6.93,33.82,0.015
6.95,33.93,0.015
6.98,34.04,0.015
7.00,34.15,0.015
7.02,34.25,0.015
7.04,34.36,0.015
7.06,34.47,0.015
7.09,34.58,0.015
7.11,34.69,0.015
7.13,34.80,0.015
7.15,34.91,0.015
7.17,35.01,0.015
7.19,35.12,0.015
7.21,35.23,0.015
7.24,35.34,0.015
7.26,35.45,0.015
7.28,35.56,0.015
7.30,35.66,0.015
7.32,35.77,0.016
7.35,35.88,0.016
7.37,35.99,0.016
7.39,36.10,0.016
7.41,36.21,0.016
7.43,36.31,0.016
7.45,36.42,0.016
7.48,36.53,0.016
7.50,36.64,0.016
7.52,36.75,0.016
7.54,36.86,0.016
7.56,36.96,0.016
7.58,37.07,0.016
7.60,37.18,0.016
7.63,37.29,0.016
7.65,37.40,0.016
7.67,37.51,0.016
7.69,37.62,0.016
7.71,37.72,0.016
7.74,37.83,0.016
7.76,37.94,0.016
7.78,38.05,0.016
7.80,38.16,0.016
7.82,38.27,0.016
7.84,38.37,0.016
7.86,38.48,0.016
7.89,38.59,0.016
7.91,38.70,0.016
7.93,38.81,0.016
7.95,38.92,0.016
7.97,39.02,0.016
8.00,39.13,0.016
8.02,39.24,0.016
8.04,39.35,0.016
8.06,39.46,0.016
8.08,39.57,0.016
8.10,39.68,0.016
8.13,39.78,0.016
8.15,39.89,0.016
8.17,40.00,0.016
8.19,40.11,0.016
8.21,40.22,0.016
8.23,40.33,0.016
8.25,40.43,0.016
8.28,40.54,0.016
8.30,40.65,0.016
8.32,40.76,0.016
8.34,40.87,0.016
8.36,40.98,0.016
8.39,41.08,0.016
8.41,41.19,0.016
8.43,41.30,0.016
8.45,41.41,0.016
8.47,41.52,0.016
8.49,41.63,0.016
8.51,41.74,0.016
8.54,41.84,0.016
8.56,41.95,0.016
8.58,42.06,0.016
8.60,42.17,0.016
8.62,42.28,0.016
8.65,42.38,0.016
8.67,42.49,0.016
8.69,42.60,0.016
8.71,42.71,0.016
8.73,42.82,0.016
8.75,42.93,0.016
8.78,43.04,0.016
8.80,43.14,0.016
8.82,43.25,0.016
8.84,43.36,0.016
8.86,43.47,0.016
8.88,43.58,0.016
8.90,43.69,0.016
8.93,43.79,0.016
8.95,43.90,0.016
8.97,44.01,0.016
8.99,44.12,0.016
9.01,44.23,0.016
9.03,44.34,0.016
9.06,44.44,0.016
9.08,44.55,0.016
9.10,44.66,0.016
9.12,44.77,0.016
9.14,44.88,0.016
9.17,44.99,0.016
9.19,45.09,0.016
9.21,45.20,0.016
9.23,45.31,0.016
9.25,45.42,0.016
9.27,45.53,0.016
9.30,45.64,0.016
9.32,45.75,0.016
9.34,45.86,0.016
9.36,45.96,0.016
9.38,46.07,0.016
9.40,46.18,0.016
9.43,46.29,0.016
9.45,46.40,0.016
9.47,46.51,0.016
9.49,46.61,0.016
9.51,46.72,0.016
9.53,46.83,0.016
9.55,46.94,0.016
9.58,47.05,0.016
9.60,47.16,0.016
9.62,47.26,0.016
9.64,47.37,0.016
9.66,47.48,0.016
9.68,47.59,0.016
9.71,47.70,0.016
9.73,47.81,0.016
9.75,47.92,0.016
9.77,48.02,0.016
9.79,48.13,0.016
9.82,48.24,0.016
9.84,48.35,0.016
9.86,48.46,0.016
9.88,48.56,0.016
9.90,48.67,0.016
9.92,48.78,0.016
9.95,48.89,0.016
9.97,49.00,0.016
9.99,49.11,0.016
10.01,49.21,0.016
10.03,49.32,0.016
10.05,49.43,0.016
10.08,49.54,0.016
10.10,49.65,0.016
10.12,49.76,0.016
10.14,49.87,0.016
10.16,49.97,0.016
10.18,50.08,0.016
10.20,50.19,0.016
10.23,50.30,0.016
10.25,50.41,0.016
10.27,50.52,0.016
10.29,50.62,0.016
10.31,50.73,0.016
10.33,50.84,0.016
10.36,50.95,0.016
10.38,51.06,0.016
10.40,51.17,0.016
10.42,51.28,0.016
10.44,51.38,0.016
10.47,51.49,0.016
10.49,51.60,0.016
10.51,51.71,0.016
10.53,51.82,0.016
10.55,51.93,0.016
10.57,52.04,0.016
10.60,52.14,0.016
10.62,52.25,0.016
10.64,52.36,0.016
10.66,52.47,0.016
10.68,52.58,0.016
10.70,52.68,0.016
10.73,52.79,0.016
10.75,52.90,0.016
10.77,53.01,0.016
10.79,53.12,0.016
10.81,53.23,0.016
10.83,53.33,0.016
10.85,53.44,0.016
10.88,53.55,0.016
10.90,53.66,0.016
10.92,53.77,0.016
10.94,53.88,0.016
10.96,53.98,0.016
10.98,54.09,0.016
11.01,54.20,0.016
11.03,54.31,0.016
11.05,54.42,0.016
11.07,54.53,0.016
11.09,54.63,0.016
11.12,54.74,0.016
11.14,54.85,0.016
11.16,54.96,0.016
11.18,55.07,0.016
11.20,55.18,0.016
11.22,55.29,0.016
11.25,55.39,0.016
11.27,55.50,0.016
11.29,55.61,0.016
11.31,55.72,0.016
11.33,55.83,0.016
11.35,55.93,0.016
11.38,56.04,0.016
11.40,56.15,0.016
11.42,56.26,0.016
11.44,56.37,0.016
11.46,56.48,0.016
11.48,56.59,0.016
11.50,56.69,0.016
11.53,56.80,0.016
11.55,56.91,0.016
11.57,57.02,0.016
11.59,57.13,0.016
11.61,57.24,0.016
11.63,57.35,0.016
11.66,57.45,0.016
11.68,57.56,0.016
11.70,57.67,0.016
11.72,57.78,0.016
11.74,57.89,0.016
11.77,57.99,0.016
11.79,58.10,0.016
11.81,58.21,0.016
11.83,58.32,0.016
11.85,58.43,0.016
11.87,58.54,0.016
11.90,58.65,0.016
11.92,58.75,0.016
11.94,58.86,0.016
11.96,58.97,0.016
11.98,59.08,0.016
12.00,59.19,0.016
12.03,59.30,0.016
12.05,59.40,0.016
12.07,59.51,0.016
12.09,59.62,0.016
12.11,59.73,0.016
12.13,59.84,0.016
12.15,59.95,0.016
12.18,60.05,0.016
12.20,60.16,0.016
12.22,60.27,0.016
12.24,60.38,0.016
12.26,60.49,0.016
12.28,60.60,0.016
12.31,60.71,0.016
12.33,60.81,0.016
12.35,60.92,0.016
12.37,61.03,0.016
12.39,61.14,0.016
12.42,61.25,0.016
12.44,61.36,0.016
12.46,61.46,0.016
12.48,61.57,0.016
12.50,61.68,0.016
12.52,61.79,0.016
12.55,61.90,0.016
12.57,62.01,0.016
12.59,62.11,0.016
12.61,62.22,0.016
12.63,62.33,0.016
12.65,62.44,0.016
12.68,62.55,0.016
12.70,62.66,0.016
12.72,62.76,0.017
12.74,62.87,0.017
12.76,62.98,0.017
12.78,63.09,0.017
12.80,63.20,0.017
12.83,63.31,0.017
12.85,63.41,0.017
12.87,63.52,0.017
12.89,63.63,0.017
12.91,63.74,0.017
12.93,63.85,0.017
12.96,63.96,0.017
12.98,64.07,0.017
13.00,64.17,0.017
13.02,64.28,0.017
13.04,64.39,0.017
13.07,64.50,0.017
13.09,64.61,0.017
13.11,64.72,0.017
13.13,64.82,0.017
13.15,64.93,0.017
13.17,65.04,0.017
13.20,65.15,0.017
13.22,65.26,0.017
13.24,65.37,0.017
13.26,65.48,0.017
13.28,65.58,0.017
13.30,65.69,0.017
13.33,65.80,0.017
13.35,65.91,0.017
13.37,66.02,0.017
13.39,66.13,0.017
13.41,66.23,0.017
13.43,66.34,0.017
13.45,66.45,0.017
13.48,66.56,0.017
13.50,66.67,0.017
13.52,66.78,0.017
13.54,66.88,0.017
13.56,66.99,0.017
13.58,67.10,0.017
13.61,67.21,0.017
13.63,67.32,0.017
13.65,67.43,0.017
13.67,67.53,0.017
13.69,67.64,0.017
13.72,67.75,0.017
13.74,67.86,0.017
13.76,67.97,0.017
13.78,68.08,0.017
13.80,68.18,0.017
13.82,68.29,0.017
13.85,68.40,0.017
13.87,68.51,0.017
13.89,68.62,0.017
13.91,68.73,0.017
13.93,68.83,0.017
13.95,68.94,0.017
13.98,69.05,0.017
14.00,69.16,0.017
14.02,69.27,0.017
14.04,69.38,0.017
14.06,69.48,0.017
14.08,69.59,0.017
14.10,69.70,0.017
14.13,69.81,0.017
14.15,69.92,0.017
14.17,70.03,0.017
14.19,70.13,0.017
14.21,70.24,0.017
14.23,70.35,0.017
14.26,70.46,0.017
14.28,70.57,0.017
14.30,70.68,0.017
14.32,70.79,0.017
14.34,70.90,0.017
14.37,71.00,0.017
14.39,71.11,0.017
14.41,71.22,0.017
14.43,71.33,0.017
14.45,71.44,0.017
14.47,71.55,0.017
14.50,71.65,0.017
14.52,71.76,0.017
14.54,71.87,0.017
14.56,71.98,0.017
14.58,72.09,0.017
14.60,72.20,0.017
14.63,72.30,0.017
14.65,72.41,0.017
14.67,72.52,0.017
14.69,72.63,0.017
14.71,72.74,0.017
14.73,72.85,0.017
14.75,72.95,0.017
14.78,73.06,0.017
14.80,73.17,0.017
14.82,73.28,0.017
14.84,73.39,0.017
14.86,73.49,0.017
14.88,73.60,0.017
14.91,73.71,0.017
14.93,73.82,0.017
14.95,73.93,0.017
14.97,74.04,0.017
14.99,74.15,0.017
15.02,74.26,0.017
15.04,74.36,0.017
15.06,74.47,0.017
15.08,74.58,0.017
15.10,74.69,0.017
15.12,74.80,0.017
15.15,74.90,0.017
15.17,75.01,0.017
15.19,75.12,0.017
15.21,75.23,0.017
15.23,75.34,0.017
15.25,75.45,0.017
15.28,75.55,0.017
15.30,75.66,0.017
15.32,75.77,0.017
15.34,75.88,0.017
15.36,75.99,0.017
15.38,76.10,0.017
15.40,76.21,0.017
15.43,76.31,0.017
15.45,76.42,0.017
15.47,76.53,0.017
15.49,76.64,0.017
15.51,76.75,0.017
15.53,76.86,0.017
15.56,76.96,0.017
15.58,77.07,0.017
15.60,77.18,0.017
15.62,77.29,0.017
15.64,77.40,0.017
15.67,77.51,0.017
15.69,77.61,0.017
15.71,77.72,0.017
15.73,77.83,0.017
15.75,77.94,0.017
15.77,78.05,0.017
15.80,78.16,0.017
15.82,78.27,0.017
15.84,78.37,0.017
15.86,78.48,0.017
15.88,78.59,0.017
15.90,78.70,0.017
15.93,78.81,0.017
15.95,78.92,0.017
15.97,79.02,0.017
15.99,79.13,0.017
16.01,79.24,0.017
16.03,79.35,0.017
16.05,79.46,0.017
16.08,79.57,0.017
16.10,79.67,0.017
16.12,79.78,0.017
16.14,79.89,0.017
16.16,80.00,0.017
16.18,80.11,0.017
16.21,80.22,0.017
16.23,80.32,0.017
16.25,80.43,0.017
16.27,80.54,0.017
16.29,80.65,0.017
16.32,80.76,0.017
16.34,80.87,0.017
16.36,80.98,0.017
16.38,81.08,0.017
16.40,81.19,0.017
16.42,81.30,0.017
16.45,81.41,0.017
16.47,81.52,0.017
16.49,81.63,0.017
16.51,81.73,0.017
16.53,81.84,0.017
16.55,81.95,0.017
16.58,82.06,0.017
16.60,82.17,0.017
16.62,82.28,0.017
16.64,82.38,0.017
16.66,82.49,0.017
16.68,82.60,0.017
16.70,82.71,0.017
16.73,82.82,0.017
16.75,82.93,0.017
16.77,83.04,0.017
16.79,83.14,0.017
16.81,83.25,0.017
16.83,83.36,0.017
16.86,83.47,0.017
16.88,83.58,0.017
16.90,83.68,0.017
16.92,83.79,0.017
16.94,83.90,0.017
16.97,84.01,0.017
16.99,84.12,0.017
17.01,84.23,0.017
17.03,84.34,0.017
17.05,84.44,0.017
17.07,84.55,0.017
17.09,84.66,0.017
17.12,84.77,0.017
17.14,84.88,0.017
17.16,84.98,0.017
17.18,85.09,0.017
17.20,85.20,0.017
17.23,85.31,0.017
17.25,85.42,0.017
17.27,85.53,0.017
17.29,85.64,0.017
17.31,85.74,0.017
17.33,85.85,0.017
17.36,85.96,0.017
17.38,86.07,0.017
17.40,86.18,0.017
17.42,86.29,0.017
17.44,86.39,0.017
17.46,86.50,0.017
17.48,86.61,0.017
17.51,86.72,0.017
17.53,86.83,0.017
17.55,86.94,0.017
17.57,87.05,0.017
17.59,87.15,0.017
17.62,87.26,0.017
17.64,87.37,0.017
17.66,87.48,0.017
17.68,87.59,0.017
17.70,87.70,0.017
17.72,87.80,0.017
17.74,87.91,0.017
17.77,88.02,0.017
17.79,88.13,0.017
17.81,88.24,0.017
17.83,88.35,0.017
17.85,88.45,0.017
17.88,88.56,0.017
17.90,88.67,0.017
17.92,88.78,0.017
17.94,88.89,0.017
17.96,89.00,0.017
17.98,89.10,0.017
18.01,89.21,0.017
18.03,89.32,0.017
18.05,89.43,0.017
18.07,89.54,0.017
18.09,89.65,0.017
18.11,89.75,0.017
18.13,89.86,0.017
18.16,89.97,0.017
18.18,90.08,0.017
18.20,90.19,0.017
18.22,90.30,0.018
18.24,90.41,0.018
18.27,90.51,0.018
18.29,90.62,0.018
18.31,90.73,0.018
18.33,90.84,0.018
18.35,90.95,0.018
18.37,91.06,0.018
18.39,91.16,0.018
18.42,91.27,0.018
18.44,91.38,0.018
18.46,91.49,0.018
18.48,91.60,0.018
18.50,91.71,0.018
18.53,91.81,0.018
18.55,91.92,0.018
18.57,92.03,0.018
18.59,92.14,0.018
18.61,92.25,0.018
18.63,92.36,0.018
18.66,92.46,0.018
18.68,92.57,0.018
18.70,92.68,0.018
18.72,92.79,0.018
18.74,92.90,0.018
18.76,93.01,0.018
18.78,93.12,0.018
18.81,93.22,0.018
18.83,93.33,0.018
18.85,93.44,0.018
18.87,93.55,0.018
18.89,93.66,0.018
18.92,93.77,0.018
18.94,93.87,0.018
18.96,93.98,0.018
18.98,94.09,0.018
19.00,94.20,0.018
19.02,94.31,0.018
19.04,94.42,0.018
19.07,94.52,0.018
19.09,94.63,0.018
19.11,94.74,0.018
19.13,94.85,0.018
19.15,94.96,0.018
19.18,95.07,0.018
19.20,95.18,0.018
19.22,95.28,0.018
19.24,95.39,0.018
19.26,95.50,0.018
19.28,95.61,0.018
19.31,95.72,0.018
19.33,95.82,0.018
19.35,95.93,0.018
19.37,96.04,0.018
19.39,96.15,0.018
19.41,96.26,0.018
19.43,96.37,0.018
19.46,96.48,0.018
19.48,96.58,0.018
19.50,96.69,0.018
19.52,96.80,0.018
19.54,96.91,0.018
19.57,97.02,0.018
19.59,97.13,0.018
19.61,97.23,0.018
19.63,97.34,0.018
19.65,97.45,0.018
19.67,97.56,0.018
19.69,97.67,0.018
19.72,97.78,0.018
19.74,97.88,0.018
19.76,97.99,0.018
19.78,98.10,0.018
19.80,98.21,0.018
19.83,98.32,0.018
19.85,98.43,0.018
19.87,98.54,0.018
19.89,98.64,0.018
19.91,98.75,0.018
19.93,98.86,0.018
19.96,98.97,0.018
19.98,99.08,0.018
20.00,99.18,0.018
20.02,99.29,0.018
20.04,99.40,0.018
20.06,99.51,0.018
20.08,99.62,0.018
20.11,99.73,0.018
20.13,99.84,0.018
20.15,99.94,0.018
20.17,100.05,0.018
20.19,100.16,0.018
20.22,100.27,0.018
20.24,100.38,0.018
20.26,100.49,0.018
20.28,100.60,0.018
20.30,100.70,0.018
20.32,100.81,0.018
20.34,100.92,0.018
20.37,101.03,0.018
20.39,101.14,0.018
20.41,101.24,0.018
20.43,101.35,0.018
20.45,101.46,0.018
20.48,101.57,0.018
20.50,101.68,0.018
20.52,101.79,0.018
20.54,101.89,0.018
20.56,102.00,0.018
20.58,102.11,0.018
20.61,102.22,0.018
20.63,102.33,0.018
20.65,102.44,0.018
20.67,102.54,0.018
20.69,102.65,0.018
20.71,102.76,0.018
20.73,102.87,0.018
20.76,102.98,0.018
20.78,103.09,0.018
20.80,103.20,0.018
20.82,103.30,0.018
20.84,103.41,0.018
20.87,103.52,0.018
20.89,103.63,0.018
20.91,103.74,0.018
20.93,103.85,0.018
20.95,103.95,0.018
20.97,104.06,0.018
20.99,104.17,0.018
21.02,104.28,0.018
21.04,104.39,0.018
21.06,104.49,0.018
21.08,104.60,0.018
21.10,104.71,0.018
21.13,104.82,0.018
21.15,104.93,0.018
21.17,105.04,0.018
21.19,105.15,0.018
21.21,105.25,0.018
21.23,105.36,0.018
21.26,105.47,0.018
21.28,105.58,0.018
21.30,105.69,0.018
21.32,105.80,0.018
21.34,105.90,0.018
21.36,106.01,0.018
21.38,106.12,0.018
21.41,106.23,0.018
21.43,106.34,0.018
21.45,106.45,0.018
21.47,106.55,0.018
21.49,106.66,0.018
21.52,106.77,0.018
21.54,106.88,0.018
21.56,106.99,0.018
21.58,107.10,0.018
21.60,107.20,0.018
21.62,107.31,0.018
21.64,107.42,0.018
21.67,107.53,0.018
21.69,107.64,0.018
21.71,107.75,0.018
21.73,107.86,0.018
21.75,107.96,0.018
21.78,108.07,0.018
21.80,108.18,0.018
21.82,108.29,0.018
21.84,108.40,0.018
21.86,108.50,0.018
21.88,108.61,0.018
21.91,108.72,0.018
21.93,108.83,0.018
21.95,108.94,0.018
21.97,109.05,0.018
21.99,109.16,0.018
22.01,109.26,0.018
22.03,109.37,0.018
22.06,109.48,0.018
22.08,109.59,0.018
22.10,109.70,0.018
22.12,109.81,0.018
22.14,109.91,0.018
22.17,110.02,0.018
22.19,110.13,0.018
22.21,110.24,0.018
22.23,110.35,0.018
22.25,110.46,0.018
22.27,110.56,0.018
22.29,110.67,0.018
22.32,110.78,0.018
22.34,110.89,0.018
22.36,111.00,0.018
22.38,111.11,0.018
22.40,111.21,0.018
22.43,111.32,0.018
22.45,111.43,0.018
22.47,111.54,0.018
22.49,111.65,0.018
22.51,111.76,0.018
22.53,111.87,0.018
22.56,111.97,0.018
22.58,112.08,0.018
22.60,112.19,0.018
22.62,112.30,0.018
22.64,112.41,0.018
22.66,112.51,0.018
22.68,112.62,0.018
22.71,112.73,0.018
22.73,112.84,0.018
22.75,112.95,0.018
22.77,113.06,0.018
22.79,113.17,0.018
22.82,113.27,0.018
22.84,113.38,0.018
22.86,113.49,0.018
22.88,113.60,0.018
22.90,113.71,0.018
22.92,113.82,0.018
22.94,113.92,0.018
22.97,114.03,0.018
22.99,114.14,0.018
23.01,114.25,0.018
23.03,114.36,0.018
23.05,114.47,0.019
23.08,114.57,0.019
23.10,114.68,0.019
23.12,114.79,0.019
23.14,114.90,0.019
23.16,115.01,0.019
23.18,115.12,0.019
23.21,115.22,0.019
23.23,115.33,0.019
23.25,115.44,0.019
23.27,115.55,0.019
23.29,115.66,0.019
23.31,115.77,0.019
23.33,115.88,0.019
23.36,115.98,0.019
23.38,116.09,0.019
23.40,116.20,0.019
23.42,116.31,0.019
23.44,116.42,0.019
23.47,116.53,0.019
23.49,116.63,0.019
23.51,116.74,0.019
23.53,116.85,0.019
23.55,116.96,0.019
23.57,117.07,0.019
23.59,117.18,0.019
23.62,117.28,0.019
23.64,117.39,0.019
23.66,117.50,0.019
23.68,117.61,0.019
23.70,117.72,0.019
23.73,117.83,0.019
23.75,117.93,0.019
23.77,118.04,0.019
23.79,118.15,0.019
23.81,118.26,0.019
23.83,118.37,0.019
23.86,118.48,0.019
23.88,118.58,0.019
23.90,118.69,0.019
23.92,118.80,0.019
23.94,118.91,0.019
23.96,119.02,0.019
23.98,119.12,0.019
24.01,119.23,0.019
24.03,119.34,0.019
24.05,119.45,0.019
24.07,119.56,0.019
24.09,119.67,0.019
24.12,119.78,0.019
24.14,119.88,0.019
24.16,119.99,0.019
24.18,120.10,0.019
24.20,120.21,0.019
24.22,120.32,0.019
24.24,120.43,0.019
24.27,120.53,0.019
24.29,120.64,0.019
24.31,120.75,0.019
24.33,120.86,0.019
24.35,120.97,0.019
24.38,121.08,0.019
24.40,121.18,0.019
24.42,121.29,0.019
24.44,121.40,0.019
24.46,121.51,0.019
24.48,121.62,0.019
24.51,121.73,0.019
24.53,121.84,0.019
24.55,121.94,0.019
24.57,122.05,0.019
24.59,122.16,0.019
24.61,122.27,0.019
24.63,122.38,0.019
24.66,122.49,0.019
24.68,122.59,0.019
24.70,122.70,0.019
24.72,122.81,0.019
24.74,122.92,0.019
24.77,123.03,0.019
24.79,123.14,0.019
24.81,123.24,0.019
24.83,123.35,0.019
24.85,123.46,0.019
24.87,123.57,0.019
24.89,123.68,0.019
24.92,123.79,0.019
24.94,123.89,0.019
24.96,124.00,0.019
24.98,124.11,0.019
25.00,124.22,0.019
25.03,124.33,0.019
25.05,124.44,0.019
25.07,124.54,0.019
25.09,124.65,0.019
25.11,124.76,0.019
25.13,124.87,0.019
25.16,124.98,0.019
25.18,125.09,0.019
25.20,125.19,0.019
25.22,125.30,0.019
25.24,125.41,0.019
25.26,125.52,0.019
25.28,125.63,0.019
25.31,125.74,0.019
25.33,125.84,0.019
25.35,125.95,0.019
25.37,126.06,0.019
25.39,126.17,0.019
25.42,126.28,0.019
25.44,126.39,0.019
25.46,126.50,0.019
25.48,126.60,0.019
25.50,126.71,0.019
25.52,126.82,0.019
25.54,126.93,0.019
25.57,127.04,0.019
25.59,127.14,0.019
25.61,127.25,0.019
25.63,127.36,0.019
25.65,127.47,0.019
25.68,127.58,0.019
25.70,127.69,0.019
25.72,127.80,0.019
25.74,127.90,0.019
25.76,128.01,0.019
25.78,128.12,0.019
25.81,128.23,0.019
25.83,128.34,0.019
25.85,128.45,0.019
25.87,128.55,0.019
25.89,128.66,0.019
25.91,128.77,0.019
25.93,128.88,0.019
25.96,128.99,0.019
25.98,129.10,0.019
26.00,129.20,0.019
26.02,129.31,0.019
26.04,129.42,0.019
26.07,129.53,0.019
26.09,129.64,0.019
26.11,129.75,0.019
26.13,129.85,0.019
26.15,129.96,0.019
26.17,130.07,0.019
26.19,130.18,0.019
26.22,130.29,0.019
26.24,130.40,0.019
26.26,130.50,0.019
26.28,130.61,0.019
26.30,130.72,0.019
26.33,130.83,0.019
26.35,130.94,0.019
26.37,131.05,0.019
26.39,131.15,0.019
26.41,131.26,0.019
26.43,131.37,0.019
26.46,131.48,0.019
26.48,131.59,0.019
26.50,131.70,0.019
26.52,131.81,0.019
26.54,131.91,0.019
26.56,132.02,0.019
26.58,132.13,0.019
26.61,132.24,0.019
26.63,132.35,0.019
26.65,132.46,0.019
26.67,132.56,0.019
26.69,132.67,0.019
26.72,132.78,0.019
26.74,132.89,0.019
26.76,133.00,0.019
26.78,133.11,0.019
26.80,133.21,0.019
26.82,133.32,0.019
26.84,133.43,0.019
26.87,133.54,0.019
26.89,133.65,0.019
26.91,133.75,0.019
26.93,133.86,0.019
26.95,133.97,0.019
26.98,134.08,0.020
27.00,134.19,0.020
27.02,134.30,0.020
27.04,134.41,0.020
27.06,134.51,0.020
27.08,134.62,0.020
27.11,134.73,0.020
27.13,134.84,0.020
27.15,134.95,0.020
27.17,135.06,0.020
27.19,135.16,0.020
27.21,135.27,0.020
27.23,135.38,0.020
27.26,135.49,0.020
27.28,135.60,0.020
27.30,135.70,0.020
27.32,135.81,0.020
27.34,135.92,0.020
27.37,136.03,0.020
27.39,136.14,0.020
27.41,136.25,0.020
27.43,136.35,0.020
27.45,136.46,0.020
27.47,136.57,0.020
27.49,136.68,0.020
27.52,136.79,0.020
27.54,136.89,0.020
27.56,137.00,0.020
27.58,137.11,0.020
27.60,137.22,0.020
27.63,137.33,0.020
27.65,137.44,0.021
27.67,137.54,0.021
27.69,137.65,0.021
27.71,137.76,0.021
27.73,137.87,0.021
27.76,137.98,0.021
27.78,138.08,0.021
27.80,138.19,0.022
27.82,138.30,0.022
27.84,138.41,0.022
27.86,138.51,0.022
27.88,138.62,0.023
27.91,138.73,0.023
27.93,138.84,0.023
27.95,138.94,0.024
27.97,139.05,0.024
27.99,139.16,0.025
28.02,139.27,0.025
28.04,139.37,0.026
28.06,139.48,0.026
28.08,139.58,0.027
28.10,139.69,0.028
28.12,139.80,0.029
28.14,139.90,0.029
28.17,140.01,0.030
28.19,140.11,0.031
28.21,140.22,0.033
28.23,140.32,0.034
28.25,140.43,0.035
28.28,140.53,0.037
28.30,140.64,0.039
28.32,140.74,0.041
28.34,140.84,0.044
28.36,140.94,0.046
28.38,141.04,0.049
28.41,141.14,0.053
28.43,141.24,0.056
28.45,141.33,0.060
28.47,141.43,0.064
28.49,141.53,0.068
28.51,141.62,0.073
28.53,141.71,0.078
28.56,141.81,0.083
28.58,141.90,0.089
28.60,141.99,0.095
28.62,142.08,0.101
28.64,142.16,0.108
28.67,142.25,0.114
28.69,142.34,0.122
28.71,142.42,0.128
28.73,142.51,0.135
28.75,142.59,0.142
28.77,142.67,0.150
28.79,142.76,0.157
28.82,142.84,0.165
28.84,142.92,0.173
28.86,143.00,0.181
28.88,143.08,0.190
28.90,143.16,0.199
28.93,143.24,0.208
28.95,143.32,0.216
28.97,143.40,0.225
28.99,143.48,0.233
29.01,143.56,0.240
29.03,143.64,0.244
29.06,143.73,0.246
29.08,143.83,0.248
29.10,143.93,0.249
29.12,144.03,0.251
29.14,144.12,0.256
29.16,144.21,0.266
29.18,144.30,0.278
29.21,144.37,0.292
29.23,144.44,0.307
29.25,144.51,0.319
29.27,144.58,0.328
29.29,144.65,0.335
29.32,144.73,0.339
29.34,144.82,0.337
29.36,144.92,0.327
29.38,145.05,0.313
29.40,145.19,0.297
29.42,145.34,0.280
29.44,145.49,0.262
29.47,145.65,0.243
29.49,145.82,0.223
29.51,145.99,0.202
29.53,146.17,0.181
29.55,146.35,0.159
29.58,146.53,0.137
29.60,146.71,0.117
29.62,146.89,0.099
29.64,147.06,0.085
29.66,147.23,0.072
29.68,147.38,0.063
29.71,147.53,0.056
29.73,147.67,0.050
29.75,147.81,0.045
29.77,147.94,0.041
29.79,148.07,0.038
29.81,148.19,0.036
29.83,148.31,0.033
29.86,148.43,0.032
29.88,148.55,0.031
29.90,148.66,0.029
29.92,148.78,0.029
29.94,148.89,0.028
29.97,149.00,0.027
29.99,149.12,0.027
30.01,149.23,0.026
30.03,149.34,0.026
30.05,149.45,0.026
30.07,149.56,0.025
30.09,149.66,0.025
30.12,149.77,0.025
30.14,149.88,0.025
30.16,149.99,0.025
30.18,150.10,0.025
30.20,150.21,0.025
30.23,150.32,0.025
30.25,150.43,0.025
30.27,150.53,0.025
30.29,150.64,0.025
30.31,150.75,0.025
30.33,150.86,0.025
30.36,150.97,0.025
30.38,151.08,0.025
30.40,151.19,0.025
30.42,151.30,0.025
30.44,151.40,0.025
30.46,151.51,0.025
30.48,151.62,0.025
30.51,151.73,0.025
30.53,151.84,0.025
30.55,151.95,0.025
30.57,152.05,0.025
30.59,152.16,0.025
30.62,152.27,0.025
30.64,152.38,0.025
30.66,152.49,0.025
30.68,152.60,0.025
30.70,152.70,0.025
30.72,152.81,0.025
30.74,152.92,0.025
30.77,153.03,0.025
30.79,153.14,0.025
30.81,153.25,0.025
30.83,153.35,0.025
30.85,153.46,0.025
30.88,153.57,0.025
30.90,153.68,0.025
30.92,153.79,0.025
30.94,153.90,0.025
30.96,154.01,0.025
30.98,154.11,0.025
31.01,154.22,0.025
31.03,154.33,0.025
31.05,154.44,0.025
31.07,154.55,0.025
31.09,154.66,0.025
31.11,154.77,0.025
31.13,154.88,0.025
31.16,154.99,0.025
31.18,155.10,0.025
31.20,155.20,0.025
31.22,155.31,0.025
31.24,155.42,0.025
31.27,155.53,0.025
31.29,155.64,0.025
31.31,155.75,0.025
31.33,155.85,0.025
31.35,155.96,0.025
31.37,156.07,0.025
31.39,156.18,0.025
31.42,156.29,0.025
31.44,156.39,0.025
31.46,156.50,0.025
31.48,156.61,0.025
31.50,156.72,0.025
31.53,156.83,0.025
31.55,156.93,0.025
31.57,157.04,0.025
31.59,157.15,0.025
31.61,157.26,0.025
31.63,157.37,0.025
31.66,157.47,0.025
31.68,157.58,0.025
31.70,157.69,0.025
31.72,157.80,0.025
31.74,157.91,0.025
31.76,158.02,0.025
31.78,158.12,0.025
31.81,158.23,0.025
31.83,158.34,0.025
31.85,158.45,0.025
31.87,158.56,0.025
31.89,158.67,0.025
31.92,158.77,0.025
31.94,158.88,0.025
31.96,158.99,
31.98,159.10,
32.00,159.21,
32.01,,

[step]
Ramp 5.00 °C/min to 0.00 °C
Time,Temperature,Heat Flow (Normalized)
min,°C,W/g
33.01,160.10,-0.002
33.03,160.10,-0.002
33.06,160.10,-0.002
33.08,160.09,-0.002
33.10,160.07,-0.003
33.12,160.04,-0.005
33.14,159.99,-0.007
33.16,159.93,-0.011
33.18,159.85,-0.014
33.21,159.78,-0.017
33.23,159.69,-0.019
33.25,159.61,-0.021
33.27,159.52,-0.023
33.29,159.42,-0.024
33.32,159.33,-0.025
33.34,159.23,-0.026
33.36,159.13,-0.027
33.38,159.03,-0.027
33.40,158.92,-0.028
33.42,158.82,-0.028
33.44,158.72,-0.028
33.47,158.62,-0.029
33.49,158.51,-0.029
33.51,158.40,-0.029
33.53,158.30,-0.029
33.55,158.19,-0.029
33.58,158.09,-0.029
33.60,157.98,-0.029
33.62,157.87,-0.029
33.64,157.77,-0.029
33.66,157.66,-0.029
33.68,157.55,-0.030
33.71,157.45,-0.030
33.73,157.34,-0.030
33.75,157.23,-0.030
33.77,157.12,-0.030
33.79,157.02,-0.030
33.81,156.91,-0.030
33.83,156.80,-0.030
33.86,156.70,-0.030
33.88,156.59,-0.030
33.90,156.48,-0.030
33.92,156.38,-0.030
33.94,156.27,-0.030
33.97,156.16,-0.030
33.99,156.05,-0.030
34.01,155.95,-0.030
34.03,155.84,-0.030
34.05,155.73,-0.030
34.07,155.62,-0.030
34.09,155.51,-0.030
34.12,155.41,-0.030
34.14,155.30,-0.030
34.16,155.19,-0.030
34.18,155.08,-0.030
34.20,154.98,-0.030
34.23,154.87,-0.030
34.25,154.76,-0.030
34.27,154.65,-0.030
34.29,154.54,-0.030
34.31,154.43,-0.030
34.33,154.33,-0.030
34.36,154.22,-0.030
34.38,154.11,-0.030
34.40,154.00,-0.030
34.42,153.89,-0.030
34.44,153.78,-0.030
34.46,153.68,-0.030
34.49,153.57,-0.030
34.51,153.46,-0.030
34.53,153.35,-0.030
34.55,153.24,-0.030
34.57,153.13,-0.030
34.59,153.03,-0.030
34.61,152.92,-0.030
34.64,152.81,-0.030
34.66,152.70,-0.030
34.68,152.59,-0.030
34.70,152.49,-0.030
34.72,152.38,-0.030
34.74,152.27,-0.030
34.77,152.16,-0.030
34.79,152.05,-0.030
34.81,151.95,-0.030
34.83,151.84,-0.030
34.85,151.73,-0.030
34.88,151.62,-0.030
34.90,151.51,-0.030
34.92,151.41,-0.030
34.94,151.30,-0.030
34.96,151.19,-0.030
34.98,151.08,-0.030
35.01,150.97,-0.030
35.03,150.86,-0.030
35.05,150.76,-0.030
35.07,150.65,-0.030
35.09,150.54,-0.030
35.11,150.43,-0.030
35.14,150.32,-0.030
35.16,150.21,-0.030
35.18,150.10,-0.030
35.20,150.00,-0.030
35.22,149.89,-0.030
35.24,149.78,-0.030
35.26,149.67,-0.030
35.29,149.57,-0.030
35.31,149.46,-0.030
35.33,149.35,-0.030
35.35,149.24,-0.030
35.37,149.13,-0.030
35.39,149.02,-0.030
35.42,148.91,-0.030
35.44,148.80,-0.030
35.46,148.70,-0.030
35.48,148.59,-0.030
35.50,148.48,-0.030
35.53,148.37,-0.030
35.55,148.26,-0.030
35.57,148.15,-0.030
35.59,148.05,-0.030
35.61,147.94,-0.030
35.63,147.83,-0.030
35.66,147.72,-0.030
35.68,147.61,-0.030
35.70,147.51,-0.030
35.72,147.40,-0.030
35.74,147.29,-0.030
35.76,147.18,-0.030
35.79,147.07,-0.030
35.81,146.97,-0.030
35.83,146.86,-0.030
35.85,146.75,-0.030
35.87,146.64,-0.030
35.89,146.53,-0.030
35.91,146.42,-0.030
35.94,146.32,-0.030
35.96,146.21,-0.030
35.98,146.10,-0.030
36.00,145.99,-0.030
36.02,145.88,-0.030
36.04,145.78,-0.030
36.07,145.67,-0.030
36.09,145.56,-0.030
36.11,145.45,-0.030
36.13,145.34,-0.030
36.15,145.23,-0.030
36.18,145.13,-0.030
36.20,145.02,-0.030
36.22,144.91,-0.030
36.24,144.80,-0.030
36.26,144.69,-0.030
36.28,144.59,-0.030
36.31,144.48,-0.030
36.33,144.37,-0.030
36.35,144.26,-0.030
36.37,144.15,-0.030
36.39,144.04,-0.030
36.41,143.94,-0.030
36.44,143.83,-0.030
36.46,143.72,-0.030
36.48,143.61,-0.030
36.50,143.50,-0.030
36.52,143.39,-0.030
36.54,143.29,-0.030
36.56,143.18,-0.030
36.59,143.07,-0.030
36.61,142.96,-0.030
36.63,142.85,-0.030
36.65,142.75,-0.030
36.67,142.64,-0.030
36.69,142.53,-0.030
36.72,142.42,-0.030
36.74,142.31,-0.030
36.76,142.20,-0.030
36.78,142.09,-0.030
36.80,141.99,-0.030
36.83,141.88,-0.030
36.85,141.77,-0.030
36.87,141.66,-0.030
36.89,141.55,-0.030
36.91,141.45,-0.030
36.93,141.34,-0.030
36.96,141.23,-0.030
36.98,141.12,-0.030
37.00,141.01,-0.030
37.02,140.90,-0.030
37.04,140.80,-0.030
37.06,140.69,-0.030
37.09,140.58,-0.030
37.11,140.47,-0.030
37.13,140.36,-0.030
37.15,140.26,-0.030
37.17,140.15,-0.030
37.19,140.04,-0.030
37.21,139.93,-0.030
37.24,139.82,-0.030
37.26,139.71,-0.030
37.28,139.61,-0.030
37.30,139.50,-0.030
37.32,139.39,-0.030
37.34,139.28,-0.030
37.37,139.17,-0.030
37.39,139.07,-0.030
37.41,138.96,-0.030
37.43,138.85,-0.030
37.45,138.74,-0.030
37.48,138.63,-0.030
37.50,138.52,-0.030
37.52,138.42,-0.030
37.54,138.31,-0.030
37.56,138.20,-0.030
37.58,138.09,-0.030
37.61,137.98,-0.030
37.63,137.87,-0.030
37.65,137.77,-0.030
37.67,137.66,-0.030
37.69,137.55,-0.030
37.71,137.44,-0.030
37.74,137.33,-0.030
37.76,137.22,-0.030
37.78,137.12,-0.030
37.80,137.01,-0.030
37.82,136.90,-0.030
37.84,136.79,-0.030
37.86,136.68,-0.030
37.89,136.57,-0.030
37.91,136.47,-0.030
37.93,136.36,-0.030
37.95,136.25,-0.030
37.97,136.14,-0.030
37.99,136.03,-0.030
38.02,135.93,-0.030
38.04,135.82,-0.030
38.06,135.71,-0.030
38.08,135.60,-0.030
38.10,135.49,-0.030
38.13,135.38,-0.030
38.15,135.28,-0.030
38.17,135.17,-0.030
38.19,135.06,-0.030
38.21,134.95,-0.030
38.23,134.84,-0.030
38.26,134.73,-0.030
38.28,134.63,-0.030
38.30,134.52,-0.030
38.32,134.41,-0.030
38.34,134.30,-0.030
38.36,134.19,-0.030
38.39,134.09,-0.030
38.41,133.98,-0.030
38.43,133.87,-0.030
38.45,133.76,-0.030
38.47,133.65,-0.030
38.49,133.54,-0.030
38.51,133.43,-0.030
38.54,133.33,-0.030
38.56,133.22,-0.030
38.58,133.11,-0.030
38.60,133.00,-0.030
38.62,132.89,-0.030
38.64,132.78,-0.030
38.67,132.68,-0.030
38.69,132.57,-0.030
38.71,132.46,-0.030
38.73,132.35,-0.030
38.75,132.24,-0.030
38.78,132.14,-0.030
38.80,132.03,-0.030
38.82,131.92,-0.030
38.84,131.81,-0.030
38.86,131.70,-0.030
38.88,131.59,-0.030
38.91,131.49,-0.029
38.93,131.38,-0.030
38.95,131.27,-0.029
38.97,131.16,-0.029
38.99,131.05,-0.029
39.01,130.95,-0.029
39.04,130.84,-0.029
39.06,130.73,-0.029
39.08,130.62,-0.029
39.10,130.51,-0.029
39.12,130.40,-0.029
39.14,130.30,-0.029
39.16,130.19,-0.029
39.19,130.08,-0.029
39.21,129.97,-0.029
39.23,129.86,-0.029
39.25,129.75,-0.029
39.27,129.65,-0.029
39.29,129.54,-0.029
39.32,129.43,-0.029
39.34,129.32,-0.029
39.36,129.21,-0.029
39.38,129.10,-0.029
39.40,129.00,-0.029
39.43,128.89,-0.029
39.45,128.78,-0.029
39.47,128.67,-0.029
39.49,128.56,-0.029
39.51,128.45,-0.029
39.53,128.35,-0.029
39.56,128.24,-0.029
39.58,128.13,-0.029
39.60,128.02,-0.029
39.62,127.91,-0.029
39.64,127.81,-0.029
39.66,127.70,-0.029
39.69,127.59,-0.029
39.71,127.48,-0.029
39.73,127.37,-0.029
39.75,127.26,-0.029
39.77,127.16,-0.029
39.79,127.05,-0.029
39.81,126.94,-0.029
39.84,126.83,-0.029
39.86,126.72,-0.029
39.88,126.61,-0.029
39.90,126.51,-0.029
39.92,126.40,-0.029
39.94,126.29,-0.029
39.97,126.18,-0.029
39.99,126.07,-0.029
40.01,125.97,-0.029
40.03,125.86,-0.029
40.05,125.75,-0.029
40.08,125.64,-0.029
40.10,125.53,-0.029
40.12,125.42,-0.029
40.14,125.32,-0.029
40.16,125.21,-0.029
40.18,125.10,-0.029
40.21,124.99,-0.029
40.23,124.88,-0.029
40.25,124.77,-0.029
40.27,124.67,-0.029
40.29,124.56,-0.029
40.31,124.45,-0.029
40.34,124.34,-0.029
40.36,124.23,-0.029
40.38,124.13,-0.029
40.40,124.02,-0.029
40.42,123.91,-0.029
40.44,123.80,-0.029
40.46,123.69,-0.029
40.49,123.58,-0.029
40.51,123.48,-0.029
40.53,123.37,-0.029
40.55,123.26,-0.029
40.57,123.15,-0.029
40.59,123.04,-0.029
40.62,122.93,-0.029
40.64,122.83,-0.029
40.66,122.72,-0.029
40.68,122.61,-0.029
40.70,122.50,-0.029
40.73,122.39,-0.029
40.75,122.28,-0.029
40.77,122.17,-0.029
[...]
132.65,2.49,0.013
132.66,2.52,0.013
132.66,2.54,0.013
132.67,2.57,0.013
132.68,2.59,0.013
132.68,2.62,0.013
132.69,2.64,0.013
132.69,2.67,0.013
132.70,2.69,0.013
132.70,2.72,0.013
132.70,2.74,0.013
132.71,2.77,0.013
132.71,2.79,0.013
132.72,2.82,0.013
132.73,2.84,0.013
132.73,2.86,0.013
132.74,2.89,0.013
132.74,2.91,0.013
132.75,2.94,0.013
132.75,2.96,0.013
132.75,2.99,0.013
132.76,3.01,0.013
132.76,3.04,0.013
132.77,3.06,0.013
132.78,3.09,0.013
132.78,3.11,0.013
132.79,3.14,0.013
132.79,3.16,0.013
132.80,3.18,0.013
132.80,3.21,0.013
132.80,3.24,0.013
132.81,3.26,0.013
132.81,3.29,0.013
132.82,3.31,0.013
132.83,3.33,0.013
132.83,3.36,0.013
132.84,3.38,0.013
132.84,3.41,0.013
132.85,3.43,0.013
132.85,3.46,0.013
132.85,3.48,0.013
132.86,3.51,0.013
132.86,3.53,0.013
132.87,3.56,0.013
132.88,3.58,0.013
132.88,3.61,0.013
132.89,3.63,0.013
132.89,3.66,0.014
132.90,3.68,0.014
132.90,3.71,0.014
132.90,3.73,0.014
132.91,3.76,0.014
132.91,3.78,0.014
132.92,3.80,0.014
132.93,3.83,0.014
132.93,3.85,0.014
132.94,3.88,0.014
132.94,3.91,0.014
132.95,3.93,0.014
132.95,3.95,0.014
132.95,3.98,0.014
132.96,4.00,0.014
132.96,4.03,0.014
132.97,4.05,0.014
132.98,4.08,0.014
132.98,4.10,0.014
132.99,4.13,0.014
132.99,4.15,0.014
133.00,4.18,0.014
133.00,4.20,0.014
133.00,4.23,0.014
133.01,4.25,0.014
133.01,4.28,0.014
133.02,4.30,0.014
133.03,4.33,0.014
133.03,4.35,0.014
133.04,4.38,0.014
133.04,4.40,0.014
133.05,4.43,0.014
133.05,4.45,0.014
133.05,4.47,0.014
133.06,4.50,0.014
133.06,4.52,0.014
133.07,4.55,0.014
133.08,4.58,0.014
133.08,4.60,0.014
133.09,4.62,0.014
133.09,4.65,0.014
133.10,4.67,0.014
133.10,4.70,0.014
133.10,4.72,0.014
133.11,4.75,0.014
133.11,4.77,0.014
133.12,4.80,0.014
133.13,4.82,0.014
133.13,4.85,0.014
133.14,4.87,0.014
133.14,4.90,0.014
133.15,4.92,0.014
133.15,4.95,0.014
133.15,4.97,0.014
133.16,5.00,0.014
133.16,5.02,0.014
133.17,5.05,0.014
133.18,5.07,0.014
133.18,5.10,0.014
133.19,5.12,0.014
133.19,5.15,0.014
133.20,5.17,0.014
133.20,5.20,0.014
133.20,5.22,0.014
133.21,5.25,0.014
133.21,5.27,0.014
133.22,5.30,0.014
133.23,5.32,0.014
133.23,5.35,0.014
133.24,5.37,0.014
133.24,5.40,0.014
133.25,5.42,0.014
133.25,5.45,0.014
133.25,5.47,0.014
133.26,5.50,0.014
133.26,5.52,0.014
133.27,5.55,0.014
133.28,5.57,0.014
133.28,5.60,0.014
133.29,5.62,0.014
133.29,5.65,0.014
133.30,5.67,0.014
133.30,5.69,0.014
133.30,5.72,0.014
133.31,5.75,0.014
133.31,5.77,0.014
133.32,5.80,0.014
133.33,5.82,0.014
133.33,5.84,0.014
133.34,5.87,0.014
133.34,5.90,0.014
133.35,5.92,0.014
133.35,5.95,0.014
133.35,5.97,0.014
133.36,5.99,0.014
133.36,6.02,0.014
133.37,6.05,0.014
133.38,6.07,0.014
133.38,6.09,0.014
133.39,6.12,0.014
133.39,6.14,0.014
133.40,6.17,0.014
133.40,6.19,0.014
133.40,6.22,0.014
133.41,6.24,0.014
133.41,6.27,0.014
133.42,6.29,0.014
133.43,6.32,0.014
133.43,6.34,0.014
133.44,6.37,0.014
133.44,6.40,0.014
133.45,6.42,0.014
133.45,6.44,0.014
133.45,6.47,0.014
133.46,6.49,0.014
133.46,6.52,0.014
133.47,6.54,0.014
133.48,6.57,0.014
133.48,6.59,0.014
133.49,6.62,0.014
133.49,6.64,0.014
133.50,6.67,0.014
133.50,6.69,0.014
133.50,6.72,0.014
133.51,6.74,0.014
133.51,6.77,0.014
133.52,6.79,0.014
133.53,6.82,0.014
133.53,6.84,0.014
133.54,6.87,0.014
133.54,6.89,0.014
133.55,6.92,0.014
133.55,6.94,0.014
133.55,6.97,0.014
133.56,6.99,0.014
133.56,7.02,0.014
133.57,7.04,0.014
133.58,7.07,0.014
133.58,7.09,0.014
133.59,7.12,0.014
133.59,7.14,0.014
133.60,7.17,0.014
133.60,7.19,0.014
133.60,7.22,0.014
133.61,7.24,0.014
133.61,7.27,0.014
133.62,7.29,0.014
133.63,7.32,0.014
133.63,7.34,0.014
133.64,7.37,0.014
133.64,7.39,0.014
133.65,7.42,0.014
133.65,7.44,0.014
133.65,7.47,0.014
133.66,7.49,0.014
133.66,7.52,0.014
133.67,7.54,0.014
133.68,7.57,0.014
133.68,7.59,0.014
133.69,7.62,0.014
133.69,7.64,0.014
133.70,7.67,0.014
133.70,7.69,0.014
133.70,7.72,0.014
133.71,7.74,0.014
133.71,7.77,0.014
133.72,7.79,0.014
133.73,7.82,0.014
133.73,7.84,0.014
133.74,7.87,0.014
133.74,7.89,0.014
133.75,7.92,0.014
133.75,7.94,0.014
133.75,7.97,0.014
133.76,7.99,0.014
133.76,8.02,0.014
133.77,8.04,0.014
133.78,8.07,0.014
133.78,8.09,0.014
133.79,8.12,0.014
133.79,8.14,0.014
133.80,8.17,0.014
133.80,8.19,0.014
133.80,8.22,0.014
133.81,8.24,0.014
133.81,8.27,0.014
133.82,8.29,0.014
133.83,8.32,0.014
133.83,8.34,0.014
133.84,8.37,0.014
133.84,8.39,0.014
133.85,8.42,0.014
133.85,8.44,0.014
133.85,8.47,0.014
133.86,8.49,0.014
133.86,8.52,0.014
133.87,8.54,0.014
133.88,8.57,0.014
133.88,8.59,0.014
133.89,8.62,0.014
133.89,8.64,0.014
133.90,8.67,0.014
133.90,8.69,0.014
133.90,8.72,0.014
133.91,8.74,0.014
133.91,8.77,0.014
133.92,8.79,0.014
133.93,8.82,0.014
133.93,8.84,0.014
133.94,8.87,0.014
133.94,8.89,0.014
133.95,8.92,0.014
133.95,8.94,0.014
133.95,8.97,0.014
133.96,8.99,0.014
133.96,9.02,0.014
133.97,9.04,0.014
133.98,9.07,0.014
133.98,9.09,0.014
133.99,9.12,0.014
133.99,9.14,0.014
134.00,9.17,0.014
134.00,9.19,0.014
134.00,9.22,0.014
134.01,9.24,0.014
134.01,9.27,0.014
134.02,9.29,0.014
134.03,9.32,0.014
134.03,9.34,0.014
134.04,9.37,0.014
134.04,9.39,0.014
134.05,9.42,0.014
134.05,9.44,0.014
134.05,9.47,0.014
134.06,9.49,0.014
134.06,9.52,0.014
134.07,9.54,0.014
134.08,9.57,0.014
134.08,9.59,0.014
134.09,9.62,0.014
134.09,9.64,0.014
134.10,9.67,0.014
134.10,9.69,0.014
134.10,9.72,0.014
134.11,9.74,0.014
134.11,9.77,0.014
134.12,9.79,0.014
134.13,9.82,0.014
134.13,9.84,0.014
134.14,9.87,0.014
134.14,9.89,0.014
134.15,9.92,0.014
134.15,9.94,0.014
134.15,9.97,0.014
134.16,9.99,0.014
134.16,10.02,0.014
134.17,10.04,0.014
134.18,10.07,0.014
134.18,10.09,0.014
134.19,10.12,0.014
134.19,10.14,0.014
134.20,10.17,0.014
134.20,10.19,0.014
134.20,10.22,0.014
134.21,10.24,0.014
134.21,10.27,0.014
134.22,10.29,0.014
134.23,10.32,0.014
134.23,10.34,0.014
134.24,10.37,0.014
134.24,10.39,0.014
134.25,10.42,0.014
134.25,10.44,0.014
134.25,10.47,0.014
134.26,10.49,0.014
134.26,10.52,0.014
134.27,10.54,0.014
134.28,10.57,0.014
134.28,10.59,0.014
134.29,10.62,0.014
134.29,10.64,0.014
134.30,10.67,0.014
134.30,10.69,0.014
134.30,10.72,0.014
134.31,10.74,0.014
134.31,10.77,0.014
134.32,10.79,0.014
134.33,10.82,0.014
134.33,10.84,0.014
134.34,10.87,0.014
134.34,10.89,0.014
134.35,10.92,0.014
134.35,10.94,0.014
134.35,10.97,0.014
134.36,10.99,0.014
134.36,11.02,0.014
134.37,11.04,0.014
134.38,11.07,0.014
134.38,11.09,0.014
134.39,11.12,0.014
134.39,11.14,0.014
134.40,11.17,0.014
134.40,11.19,0.014
134.40,11.22,0.014
134.41,11.24,0.014
134.41,11.27,0.014
134.42,11.29,0.014
134.43,11.32,0.014
134.43,11.34,0.014
134.44,11.37,0.014
134.44,11.39,0.014
134.45,11.42,0.014
134.45,11.44,0.014
134.45,11.47,0.014
134.46,11.49,0.014
134.46,11.52,0.014
134.47,11.54,0.014
134.48,11.57,0.014
134.48,11.59,0.014
134.49,11.62,0.014
134.49,11.64,0.014
134.50,11.67,0.014
134.50,11.69,0.014
134.50,11.72,0.014
134.51,11.74,0.014
134.51,11.77,0.014
134.52,11.79,0.014
134.53,11.82,0.014
134.53,11.84,0.014
134.54,11.87,0.014
134.54,11.89,0.014
134.55,11.92,0.014
134.55,11.94,0.014
134.55,11.97,0.014
134.56,11.99,0.014
134.56,12.02,0.014
134.57,12.04,0.014
134.58,12.07,0.014
134.58,12.09,0.014
134.59,12.12,0.014
134.59,12.14,0.014
134.60,12.17,0.014
134.60,12.19,0.014
134.60,12.22,0.014
134.61,12.24,0.014
134.61,12.27,0.014
134.62,12.29,0.014
134.63,12.32,0.014
134.63,12.34,0.014
134.64,12.37,0.014
134.64,12.39,0.014
134.65,12.42,0.014
134.65,12.44,0.014
134.65,12.47,0.014
134.66,12.49,0.014
134.66,12.52,0.014
134.67,12.54,0.014
134.68,12.57,0.014
134.68,12.59,0.014
134.69,12.62,0.014
134.69,12.64,0.014
134.70,12.67,0.014
134.70,12.69,0.014
134.70,12.72,0.014
134.71,12.74,0.014
134.71,12.77,0.014
134.72,12.79,0.014
134.73,12.82,0.014
134.73,12.84,0.014
134.74,12.87,0.014
134.74,12.89,0.014
134.75,12.92,0.014
134.75,12.94,0.014
134.75,12.97,0.014
134.76,12.99,0.014
134.76,13.02,0.014
134.77,13.04,0.014
134.78,13.07,0.014
134.78,13.09,0.014
134.79,13.12,0.014
134.79,13.14,0.014
134.80,13.17,0.014
134.80,13.19,0.014
134.80,13.22,0.014
134.81,13.24,0.014
134.81,13.27,0.014
134.82,13.29,0.014
134.83,13.32,0.014
134.83,13.35,0.014
134.84,13.37,0.014
134.84,13.39,0.014
134.85,13.42,0.014
134.85,13.44,0.014
134.85,13.47,0.014
134.86,13.49,0.014
134.86,13.52,0.014
134.87,13.54,0.014
134.88,13.57,0.014
134.88,13.59,0.014
134.89,13.62,0.014
134.89,13.64,0.014
134.90,13.67,0.014
134.90,13.69,0.014
134.90,13.72,0.014
134.91,13.74,0.014
134.91,13.77,0.014
134.92,13.79,0.014
134.93,13.82,0.014
134.93,13.84,0.014
134.94,13.87,0.014
134.94,13.89,0.014
134.95,13.92,0.014
134.95,13.94,0.014
134.95,13.97,0.014
134.96,14.00,0.014
134.96,14.02,0.014
134.97,14.04,0.014
134.98,14.07,0.014
134.98,14.09,0.014
134.99,14.12,0.014
134.99,14.15,0.014
135.00,14.17,0.014
135.00,14.19,0.014
135.00,14.22,0.014
135.01,14.24,0.014
135.01,14.27,0.014
135.02,14.29,0.014
135.03,14.32,0.014
135.03,14.34,0.014
135.04,14.37,0.014
135.04,14.39,0.014
135.05,14.42,0.014
135.05,14.45,0.014
135.05,14.47,0.014
135.06,14.50,0.014
135.06,14.52,0.014
135.07,14.54,0.014
135.08,14.57,0.014
135.08,14.60,0.014
135.09,14.62,0.014
135.09,14.65,0.014
135.10,14.67,0.014
135.10,14.70,0.014
135.10,14.72,0.014
135.11,14.75,0.014
135.11,14.77,0.014
135.12,14.80,0.014
135.13,14.82,0.014
135.13,14.85,0.014
135.14,14.87,0.014
135.14,14.90,0.014
135.15,14.92,0.014
135.15,14.95,0.014
135.15,14.97,0.014
135.16,15.00,0.014
135.16,15.02,0.014
135.17,15.05,0.014
135.18,15.07,0.014
135.18,15.10,0.014
135.19,15.12,0.014
135.19,15.15,0.014
135.20,15.17,0.014
135.20,15.20,0.014
135.20,15.22,0.014
135.21,15.25,0.014
135.21,15.27,0.014
135.22,15.30,0.014
135.23,15.32,0.014
135.23,15.35,0.014
135.24,15.37,0.014
135.24,15.40,0.014
135.25,15.42,0.014
135.25,15.45,0.014
135.25,15.47,0.014
135.26,15.50,0.014
135.26,15.52,0.014
135.27,15.55,0.014
135.28,15.57,0.014
135.28,15.60,0.014
135.29,15.62,0.014
135.29,15.65,0.014
135.30,15.67,0.014
135.30,15.70,0.014
135.30,15.72,0.014
135.31,15.75,0.014
135.31,15.77,0.014
135.32,15.80,0.014
135.33,15.82,0.014
135.33,15.85,0.014
135.34,15.87,0.014
135.34,15.90,0.014
135.35,15.92,0.014
135.35,15.95,0.014
135.35,15.97,0.014
135.36,16.00,0.014
135.36,16.02,0.014
135.37,16.05,0.014
135.38,16.07,0.014
135.38,16.10,0.014
135.39,16.12,0.014
135.39,16.15,0.014
135.40,16.17,0.014
135.40,16.20,0.014
135.40,16.22,0.014
135.41,16.25,0.014
135.41,16.27,0.014
135.42,16.30,0.014
135.43,16.32,0.014
135.43,16.35,0.014
135.44,16.37,0.014
135.44,16.39,0.014
135.45,16.42,0.014
135.45,16.44,0.014
135.45,16.47,0.014
135.46,16.50,0.014
135.46,16.52,0.014
135.47,16.55,0.014
135.48,16.57,0.014
135.48,16.60,0.014
135.49,16.62,0.014
135.49,16.65,0.014
135.50,16.67,0.014
135.50,16.70,0.014
135.50,16.72,0.014
135.51,16.75,0.014
135.51,16.77,0.014
135.52,16.80,0.014
135.53,16.82,0.014
135.53,16.85,0.014
135.54,16.87,0.014
135.54,16.90,0.014
135.55,16.92,0.014
135.55,16.95,0.014
135.55,16.97,0.014
135.56,17.00,0.014
135.56,17.02,0.015
135.57,17.05,0.014
135.58,17.07,0.014
135.58,17.10,0.014
135.59,17.12,0.015
135.59,17.15,0.015
135.60,17.17,0.015
135.60,17.20,0.015
135.60,17.22,0.015
135.61,17.24,0.015
135.61,17.27,0.015
135.62,17.29,0.015
135.63,17.32,0.015
135.63,17.35,0.015
135.64,17.37,0.015
135.64,17.40,0.015
135.65,17.42,0.015
135.65,17.45,0.015
135.65,17.47,0.015
135.66,17.49,0.015
135.66,17.52,0.015
135.67,17.54,0.015
135.68,17.57,0.015
135.68,17.59,0.015
135.69,17.62,0.015
135.69,17.65,0.015
135.70,17.67,0.015
135.70,17.70,0.015
135.70,17.72,0.015
135.71,17.74,0.015
135.71,17.77,0.015
135.72,17.79,0.015
135.73,17.82,0.015
135.73,17.84,0.015
135.74,17.87,0.015
135.74,17.90,0.015
135.75,17.92,0.015
135.75,17.95,0.015
135.75,17.97,0.015
135.76,18.00,0.015
135.76,18.02,0.015
135.77,18.05,0.015
135.78,18.07,0.015
135.78,18.10,0.015
135.79,18.12,0.015
135.79,18.15,0.015
135.80,18.17,0.015
135.80,18.20,0.015
135.80,18.22,0.015
135.81,18.25,0.015
135.81,18.27,0.015
135.82,18.30,0.015
135.83,18.32,0.015
135.83,18.35,0.015
135.84,18.37,0.015
135.84,18.40,0.015
135.85,18.42,0.015
135.85,18.45,0.015
135.85,18.47,0.015
135.86,18.50,0.015
135.86,18.52,0.015
135.87,18.55,0.015
135.88,18.57,0.015
135.88,18.60,0.015
135.89,18.62,0.015
135.89,18.65,0.015
135.90,18.67,0.015
135.90,18.70,0.015
135.90,18.72,0.015
135.91,18.75,0.015
135.91,18.77,0.015
135.92,18.80,0.015
135.93,18.82,0.015
135.93,18.85,0.015
135.94,18.87,0.015
135.94,18.90,0.015
135.95,18.92,0.015
135.95,18.95,0.015
135.95,18.97,0.015
135.96,19.00,0.015
135.96,19.02,0.015
135.97,19.05,0.015
135.98,19.07,0.015
135.98,19.10,0.015
135.99,19.12,0.015
135.99,19.15,0.015
136.00,19.17,0.015
136.00,19.20,0.015
136.00,19.22,0.015
136.01,19.25,0.015
136.01,19.27,0.015
136.02,19.30,0.015
136.03,19.32,0.015
136.03,19.35,0.015
136.04,19.37,0.015
136.04,19.40,0.015
136.05,19.42,0.015
136.05,19.45,0.015
136.05,19.47,0.015
136.06,19.50,0.015
136.06,19.52,0.015
136.07,19.55,0.015
136.08,19.57,0.015
136.08,19.60,0.015
136.09,19.62,0.015
136.09,19.65,0.015
136.10,19.67,0.015
136.10,19.70,0.015
136.10,19.72,0.015
136.11,19.75,0.015
136.11,19.77,0.015
136.12,19.80,0.015
136.13,19.82,0.015
136.13,19.85,0.015
136.14,19.87,0.015
136.14,19.90,0.015
136.15,19.92,0.015
136.15,19.95,0.015
136.15,19.97,0.015
136.16,20.00,0.015
136.16,20.02,0.015
136.17,20.05,0.015
136.18,20.07,0.015
136.18,20.10,0.015
136.19,20.12,0.015
136.19,20.15,0.015
136.20,20.17,0.015
136.20,20.20,0.015
136.20,20.22,0.015
136.21,20.25,0.015
136.21,20.27,0.015
136.22,20.30,0.015
136.23,20.32,0.015
136.23,20.35,0.015
136.24,20.37,0.015
136.24,20.40,0.015
136.25,20.42,0.015
136.25,20.45,0.015
136.25,20.47,0.015
136.26,20.50,0.015
136.26,20.52,0.015
136.27,20.55,0.015
136.28,20.57,0.015
136.28,20.60,0.015
136.29,20.62,0.015
136.29,20.65,0.015
136.30,20.67,0.015
136.30,20.70,0.015
136.30,20.72,0.015
136.31,20.75,0.015
136.31,20.77,0.015
136.32,20.80,0.015
136.33,20.82,0.015
136.33,20.85,0.015
136.34,20.87,0.015
136.34,20.90,0.015
136.35,20.92,0.015
136.35,20.95,0.015
136.35,20.97,0.015
136.36,21.00,0.015
136.36,21.02,0.015
136.37,21.05,0.015
136.38,21.07,0.015
136.38,21.10,0.015
136.39,21.12,0.015
136.39,21.15,0.015
136.40,21.17,0.015
136.40,21.20,0.015
136.40,21.22,0.015
136.41,21.25,0.015
136.41,21.27,0.015
136.42,21.30,0.015
136.43,21.32,0.015
136.43,21.35,0.015
136.44,21.37,0.015
136.44,21.40,0.015
136.45,21.42,0.015
136.45,21.45,0.015
136.45,21.47,0.015
136.46,21.50,0.015
136.46,21.52,0.015
136.47,21.55,0.015
136.48,21.57,0.015
136.48,21.60,0.015
136.49,21.62,0.015
136.49,21.65,0.015
136.50,21.67,0.015
136.50,21.70,0.015
136.50,21.72,0.015
136.51,21.75,0.015
136.51,21.77,0.015
136.52,21.80,0.015
136.53,21.82,0.015
136.53,21.85,0.015
136.53,21.87,0.015
136.54,21.90,0.015
136.55,21.92,0.015
136.55,21.95,0.015
136.55,21.97,0.015
136.56,22.00,0.015
136.57,22.02,0.015
136.57,22.05,0.015
136.58,22.07,0.015
136.58,22.10,0.015
136.58,22.12,0.015
136.59,22.15,0.015
136.60,22.17,0.015
136.60,22.20,0.015
136.60,22.22,0.015
136.61,22.25,0.015
136.62,22.27,0.015
136.62,22.30,0.015
136.63,22.32,0.015
136.63,22.35,0.015
136.63,22.37,0.015
136.64,22.40,0.015
136.65,22.43,0.015
136.65,22.45,0.015
136.65,22.47,0.015
136.66,22.50,0.015
136.67,22.52,0.015
136.67,22.55,0.015
136.68,22.57,0.015
136.68,22.60,0.015
136.68,22.62,0.015
136.69,22.65,0.015
136.70,22.68,0.015
136.70,22.70,0.015
136.70,22.72,0.015
136.71,22.75,0.015
136.72,22.77,0.015
136.72,22.80,0.015
136.73,22.82,0.015
136.73,22.85,0.015
136.73,22.87,0.015
136.74,22.90,0.015
136.75,22.92,0.015
136.75,22.95,0.015
136.75,22.97,0.015
136.76,23.00,0.015
136.77,23.02,0.015
136.77,23.05,0.015
136.78,23.07,0.015
136.78,23.10,0.015
136.78,23.12,0.015
136.79,23.15,0.015
136.80,23.17,0.015
136.80,23.20,0.015
136.80,23.22,0.015
136.81,23.25,0.015
136.82,23.27,0.015
136.82,23.30,0.015
136.83,23.32,0.015
136.83,23.35,0.015
136.83,23.37,0.015
136.84,23.40,0.015
136.85,23.42,0.015
136.85,23.45,0.015
136.85,23.47,0.015
136.86,23.50,0.015
136.87,23.52,0.015
136.87,23.55,0.015
136.88,23.57,0.015
136.88,23.60,0.015
136.88,23.62,0.015
136.89,23.65,0.015
136.90,23.67,0.015
136.90,23.70,0.015
136.90,23.72,0.015
136.91,23.75,0.015
136.92,23.78,0.015
136.92,23.80,0.015
136.93,23.83,0.015
136.93,23.85,0.015
136.93,23.87,0.015
136.94,23.90,0.015
136.95,23.92,0.015
136.95,23.95,0.015
136.95,23.97,0.015
136.96,24.00,0.015
136.97,24.02,0.015
136.97,24.05,0.015
136.98,24.08,0.015
136.98,24.10,0.015
136.98,24.12,0.015
136.99,24.15,0.015
137.00,24.17,0.015
137.00,24.20,0.015
137.00,24.22,0.015
137.01,24.25,0.015
137.02,24.27,0.015
137.02,24.30,0.015
137.03,24.32,0.015
137.03,24.35,0.015
137.03,24.37,0.015
137.04,24.40,0.015
137.05,24.42,0.015
137.05,24.45,0.015
137.05,24.48,0.015
137.06,24.50,0.015
137.07,24.52,0.015
137.07,24.55,0.015
137.08,24.57,0.015
137.08,24.60,0.015
137.08,24.62,0.015
137.09,24.65,0.015
137.10,24.67,0.015
137.10,24.70,0.015
137.10,24.72,0.015
137.11,24.75,0.015
137.12,24.77,0.015
137.12,24.80,0.015
137.13,24.82,0.015
137.13,24.85,0.015
137.13,24.87,0.015
137.14,24.90,0.015
137.15,24.93,0.015
137.15,24.95,0.015
137.15,24.98,0.015
137.16,25.00,0.015
137.17,25.03,0.015
137.17,25.05,0.015
137.18,25.07,0.015
137.18,25.10,0.015
137.18,25.13,0.015
137.19,25.15,0.015
137.20,25.17,0.015
137.20,25.20,0.015
137.20,25.23,0.015
137.21,25.25,0.015
137.22,25.28,0.015
137.22,25.30,0.015
137.23,25.33,0.015
137.23,25.35,0.015
137.23,25.38,0.015
137.24,25.40,0.015
137.25,25.43,0.015
137.25,25.45,0.015
137.25,25.48,0.015
137.26,25.50,0.015
137.27,25.53,0.015
137.27,25.55,0.015
137.28,25.58,0.015
137.28,25.60,0.015
137.28,25.63,0.015
137.29,25.65,0.015
137.30,25.68,0.015
137.30,25.70,0.015
137.30,25.73,0.015
137.31,25.75,0.015
137.32,25.78,0.015
137.32,25.80,0.015
137.33,25.83,0.015
137.33,25.85,0.015
137.33,25.88,0.015
137.34,25.90,0.015
137.35,25.93,0.015
137.35,25.95,0.015
137.35,25.98,0.015
137.36,26.00,0.015
137.37,26.03,0.015
137.37,26.05,0.015
137.38,26.08,0.015
137.38,26.10,0.015
137.38,26.13,0.015
137.39,26.15,0.015
137.40,26.18,0.015
137.40,26.20,0.015
137.40,26.23,0.015
137.41,26.25,0.015
137.42,26.28,0.015
137.42,26.30,0.015
137.43,26.33,0.015
137.43,26.35,0.015
137.43,26.38,0.015
137.44,26.40,0.015
137.45,26.43,0.015
137.45,26.45,0.015
137.45,26.48,0.015
137.46,26.50,0.015
137.47,26.53,0.015
137.47,26.55,0.015
137.48,26.58,0.015
137.48,26.60,0.015
137.48,26.63,0.015
137.49,26.65,0.015
137.50,26.68,0.015
137.50,26.70,0.015
137.50,26.73,0.015
137.51,26.75,0.015
137.52,26.78,0.015
137.52,26.80,0.015
137.53,26.83,0.015
137.53,26.85,0.015
137.53,26.88,0.015
137.54,26.90,0.015
137.55,26.93,0.015
137.55,26.95,0.015
137.55,26.98,0.015
137.56,27.00,0.015
137.57,27.03,0.015
137.57,27.05,0.015
137.58,27.08,0.015
137.58,27.10,0.015
137.58,27.13,0.015
137.59,27.15,0.015
137.60,27.18,0.015
137.60,27.20,0.015
137.60,27.23,0.015
137.61,27.25,0.015
137.62,27.28,0.015
137.62,27.30,0.015
137.63,27.33,0.015
137.63,27.35,0.015
137.63,27.38,0.015
137.64,27.40,0.015
137.65,27.43,0.015
137.65,27.45,0.015
137.65,27.48,0.015
137.66,27.50,0.015
137.67,27.53,0.015
137.67,27.55,0.015
137.68,27.58,0.015
137.68,27.60,0.015
137.68,27.63,0.015
137.69,27.65,0.015
137.70,27.68,0.015
137.70,27.70,0.015
137.70,27.73,0.015
137.71,27.75,0.015
137.72,27.78,0.015
137.72,27.80,0.015
137.73,27.83,0.015
137.73,27.85,0.015
137.73,27.88,0.015
137.74,27.90,0.015
137.75,27.93,0.015
137.75,27.95,0.015
137.75,27.98,0.015
137.76,28.00,0.015
137.77,28.03,0.015
137.77,28.05,0.015
137.78,28.08,0.015
137.78,28.10,0.015
137.78,28.13,0.015
137.79,28.15,0.015
137.80,28.18,0.015
137.80,28.20,0.015
137.80,28.23,0.015
137.81,28.25,0.015
137.82,28.28,0.015
137.82,28.30,0.015
137.83,28.33,0.015
137.83,28.35,0.015
137.83,28.38,0.015
137.84,28.40,0.015
137.85,28.43,0.015
137.85,28.45,0.015
137.85,28.48,0.015
137.86,28.50,0.015
137.87,28.53,0.015
137.87,28.55,0.015
137.88,28.58,0.015
137.88,28.60,0.015
137.88,28.63,0.015
137.89,28.65,0.015
137.90,28.68,0.015
137.90,28.70,0.015
137.90,28.73,0.015
137.91,28.75,0.015
137.92,28.78,0.015
137.92,28.80,0.015
137.93,28.83,0.015
137.93,28.85,0.015
137.93,28.88,0.015
137.94,28.90,0.015
137.95,28.93,0.015
137.95,28.95,0.015
137.95,28.98,
137.96,29.00,
137.97,29.03,
137.97,29.05,
137.98,29.08,
137.98,29.10,
137.98,29.13,
137.99,29.15,
138.00,29.18,
138.00,29.20,
138.00,,
138.01,,