File: DSC/2025_05_29_Nifedipine_0C_190C_5Cmin_x3.csv
Filename,2025_05_29_Nifedipine_0C_190C_5Cmin_x3
Instrument name,DSC2A-00468 (192.168.1.100)
Operator,Yarger
rundate,5/29/2025
Sample name,2025_05_29_Nifedipine_0C_190C_5Cmin_x3
proceduresegments,Data Off ; Equilibrate 0.00 °C; Data On ; Ramp 5.00 °C/min to 190.00 °C; Data Off ; Isothermal 1.0 min; Data On ; Ramp 5.00 °C/min to 0.00 °C; Data Off ; Isothermal 1.0 min; Data On ; Ramp 5.00 °C/min to 190.00 °C; Data Off ; Isothermal 1.0 min; Data On ; Ramp 5.00 °C/min to 0.00 °C; Data Off ; Isothermal 1.0 min; Data On ; Ramp 5.00 °C/min to 30.00 °C
[File Parameters]
Run date,5/29/2025 3:12:33 PM
Trios version,5.1.1.46572
Original File Name,
Current File Name,D:\DSC2500\JYarger\2025_05_29_Nifedipine_0C_190C_5Cmin_x3.tri
[Procedure]
Procedure Name,Nidedipine_0C_190C_x3
Sample Name,2025_05_29_Nifedipine_0C_190C_5Cmin_x3
Sample Mass,10.58 mg
Reference Sample Mass,0 mg
Pan Mass,55.87 mg
Pan Number,7
Reference Pan Mass,55.79 mg
Reference Pan Number,1
Pan Type,Tzero Aluminum Hermetic
Comments,Al Hermetic DSC Consumables sealed Pan/Lid. A2 Tray (Google Sheet: DSC_Samples_A2_Tray_May2025)
Project Name,CA
Operator,Yarger
Test,Custom
Unload Max Temperature,30
Unload Min Temperature,30
Load Max Temperature,30
Load Min Temperature,30
Stop on Gas Flow Error,Yes
[Signal List]
Signal #1,Time (min)
Signal #2,Temperature (°C)
Signal #3,Heat Flow (mW)
Signal #4,Delta T (µV)
Signal #5,Delta Tzero (µV)
Signal #6,Tzero Temperature (°C)
Signal #7,Cell Purge (mL/min)
Signal #8,Heater Temp (°C)
Signal #9,Power Delivered (W)
Signal #10,Reference Junction Temperature (°C)
Signal #11,Flange Temperature (°C)
Signal #12,Heat Flow Phase (rad)
Signal #13,Total Heat Capacity (J/°C)
Signal #14,Heat Capacity (J/°C)
[Configuration]
Company Name,ASU
Instrument Name,DSC2A-00468
Instrument Type,DSC2500
Serial Number,DSC2A-00468
IP,192.168.1.100
Location of Instrument,MRRC
DisplayType,Unknown
Sample Interval ,0.1 s/pt
Selected Heat Flow,T4P
Exotherm Direction,Down
Cell Serial,DRC2-00792
Lid Type,Standard
Cooler,RCS 90
Leave Cooler on at End of Sequence,On
Gas 2,Nitrogen
Gas Selected,Channel 1
Flow Rate,50 mL/min
Secondary Purge,On
Licensed Heat Flow,Heat Flow T4P
Modulation Licensed,Yes
[Versions]
Common IDD Version,1
Cortex Version,VER 2.10.2.31
Driver,5.0.0.6
GDM Version,1.0.3.3
TouchscreenVersion,1.0.0.16145
FEP Version,1.2.1.21
FEP Bootloader,2.0.0.5
AutoSampler Version,2.1.1.26
Auto Sampler Bootloader,2.0.0.5
FCM Version,1.1.0.3
FCM Bootloader,2.0.0.5
[Experiment Logs]
Experiment Log Entry # 1,Data On set to 0
Experiment Log Entry # 3,Equilibrate Segment 0 (C) Started
Experiment Log Entry # 5,Air Cool is off.
Experiment Log Entry # 7,Data On set to 1
Experiment Log Entry # 9,Ramp Segment 5 C/min to 190 Started
Experiment Log Entry # 11,Data On set to 0
Experiment Log Entry # 13,Isothermal Segment 1 min started
Experiment Log Entry # 15,Data On set to 1
Experiment Log Entry # 17,Ramp Segment 5 C/min to 0 Started
Experiment Log Entry # 19,Data On set to 0
Experiment Log Entry # 21,Isothermal Segment 1 min started
Experiment Log Entry # 23,Data On set to 1
Experiment Log Entry # 25,Ramp Segment 5 C/min to 190 Started
Experiment Log Entry # 27,Ramp Segment 5 C/min to 190 Started
Experiment Log Entry # 29,User modified running procedure
Experiment Log Entry # 31,Data On set to 0
Experiment Log Entry # 33,Isothermal Segment 1 min started
Experiment Log Entry # 35,Data On set to 1
Experiment Log Entry # 37,Ramp Segment 20 C/min to 0 Started
Experiment Log Entry # 39,Data On set to 0
Experiment Log Entry # 41,Isothermal Segment 2 min started
Experiment Log Entry # 43,Data On set to 1
Experiment Log Entry # 45,Ramp Segment 5 C/min to 30 Started
[Method Log]
Method Log Entry # 1,Data Off
Method Log Entry # 2,Equilibrate 0 °C
Method Log Entry # 3,Data On
Method Log Entry # 4,(Ramp 416151) Ramp 5 °C/minute to 190 °C
Method Log Entry # 5,Data Off
Method Log Entry # 6,Isothermal 1 minutes
Method Log Entry # 7,Data On
Method Log Entry # 8,(Ramp 416155) Ramp 5 °C/minute to 0 °C
Method Log Entry # 9,Data Off
Method Log Entry # 10,Isothermal 1 minutes
Method Log Entry # 11,Data On
Method Log Entry # 12,(Ramp 416159) Ramp 5 °C/minute to 190 °C
Method Log Entry # 13,Data Off
Method Log Entry # 14,Isothermal 1 minutes
Method Log Entry # 15,Data On
Method Log Entry # 16,(Ramp 416163) Ramp 20 °C/minute to 0 °C
Method Log Entry # 17,Data Off
Method Log Entry # 18,Isothermal 2 minutes
Method Log Entry # 19,Data On
Method Log Entry # 20,(Ramp 416167) Ramp 5 °C/minute to 30 °C
Cell Serial,DRC2-00792
[T1 Calibration]
Slope,-0.008529666
Offset,9.636258
Initial Temperature,98.23
GUID,f8bfdadc-4977-4fdf-ba6d-0ba9134940c3
[TZero Calibration]
Date Applied,11/29/2022 4:06:13 PM
Description,From -89.059 °C to 396.009 °C at 20.000°C/min
Gas Type,Nitrogen
Pan Type,None
Source Files 1,C:\Users\yargerlab\Desktop\DSC Data\General\TZero_calibration_11_29_22_2nd(2).tri
Source Files 2,C:\Users\yargerlab\Desktop\DSC Data\General\TZero_calibration_11_29_22_2nd(3).tri
Delta T Offset,13.05235
Delta T Slope,-0.007271007
Delta T0 Offset,-13.69128
Delta T0 Slope,0.06063341
[Temperature Calibration]
Date Applied,11/29/2022 7:12:28 PM
Description,From 106.590 °C to 186.590 °C at 10.000°C/min
Gas Type,Nitrogen
Pan Type,Tzero Aluminum Hermetic
Source Files 1,C:\Users\yargerlab\Desktop\DSC Data\General\Indium(6).tri
Measured 1,157.391
Known 1,156.598
[Cell Constant Calibration]
Date Applied,11/29/2022 7:12:29 PM
Description,From 106.590 °C to 186.590 °C at 10.000°C/min
Gas Type,Nitrogen
Pan Type,Tzero Aluminum Hermetic
Source Files 1,C:\Users\yargerlab\Desktop\DSC Data\General\Indium(6).tri
T4P KCell,1.006051
Onset Slope,63.26126 mW/°C
[Direct Cp Calibration]
Date Applied,11/30/2022 11:04:51 AM
Description,From -79.983 °C to 298.409 °C at 10.000°C/min
Gas Type,Nitrogen
Pan Type,Tzero Aluminum Hermetic
Source Files 1,C:\Users\yargerlab\Desktop\DSC Data\General\Sapphire_Heat_Capacity_11_30_22.tri
[Rev Cp Calibration]
Date Applied,11/30/2022 1:58:51 PM
Description,From -79.996 °C to 292.812 °C at 3.000°C/min
Gas Type,Nitrogen
Pan Type,Tzero Aluminum Hermetic
Source Files 1,C:\Users\yargerlab\Desktop\DSC Data\General\Sapphire_MDSC_Calibration_11_30_22.tri
[step]
Ramp 5.00 °C/min to 190.00 °C
Time,Temperature,Heat Flow (Normalized)
min,°C,W/g
0.00,0.14,-0.036
0.03,0.13,-0.035
0.05,0.13,-0.030
0.08,0.13,-0.025
0.11,0.16,-0.017
0.13,0.21,-0.008
0.16,0.27,0.004
0.19,0.35,0.017
0.21,0.44,0.029
0.24,0.54,0.039
0.27,0.65,0.048
0.29,0.76,0.055
0.32,0.87,0.062
0.35,0.98,0.068
0.37,1.10,0.072
0.40,1.22,0.076
0.43,1.35,0.079
0.45,1.47,0.082
0.48,1.60,0.084
0.51,1.72,0.085
0.53,1.85,0.086
0.56,1.98,0.088
0.59,2.11,0.088
0.61,2.24,0.089
0.64,2.37,0.090
0.67,2.50,0.090
0.69,2.62,0.090
0.72,2.75,0.091
0.75,2.88,0.091
0.77,3.02,0.091
0.80,3.15,0.092
0.83,3.28,0.092
0.85,3.41,0.092
0.88,3.54,0.092
0.91,3.68,0.093
0.93,3.81,0.093
0.96,3.94,0.093
0.99,4.07,0.093
1.01,4.21,0.094
1.04,4.34,0.094
1.07,4.47,0.094
1.09,4.60,0.094
1.12,4.73,0.094
1.15,4.87,0.094
1.17,5.00,0.094
1.20,5.13,0.095
1.23,5.27,0.095
1.25,5.40,0.095
1.28,5.53,0.095
1.31,5.67,0.095
1.33,5.80,0.095
1.36,5.93,0.095
1.39,6.07,0.095
1.41,6.20,0.095
1.44,6.33,0.095
1.47,6.46,0.095
1.49,6.60,0.095
1.52,6.73,0.096
1.55,6.86,0.096
1.57,7.00,0.096
1.60,7.13,0.096
1.63,7.26,0.096
1.65,7.40,0.096
1.68,7.53,0.096
1.71,7.66,0.096
1.73,7.80,0.096
1.76,7.93,0.096
1.79,8.06,0.096
1.81,8.20,0.096
1.84,8.33,0.096
1.87,8.46,0.096
1.89,8.60,0.096
1.92,8.73,0.096
1.95,8.86,0.096
1.97,9.00,0.096
2.00,9.13,0.096
2.03,9.26,0.096
2.05,9.40,0.096
2.08,9.53,0.096
2.11,9.66,0.096
2.13,9.80,0.096
2.16,9.93,0.096
2.19,10.06,0.096
2.21,10.20,0.096
2.24,10.33,0.096
2.27,10.46,0.096
2.29,10.60,0.096
2.32,10.73,0.096
2.35,10.86,0.096
2.37,11.00,0.096
2.40,11.13,0.096
2.43,11.26,0.096
2.45,11.40,0.096
2.48,11.53,0.096
2.51,11.66,0.096
2.53,11.80,0.096
2.56,11.93,0.096
2.59,12.06,0.096
2.61,12.20,0.096
2.64,12.33,0.096
2.67,12.47,0.096
2.69,12.60,0.096
2.72,12.73,0.096
2.75,12.86,0.096
2.77,13.00,0.096
2.80,13.13,0.097
2.83,13.27,0.097
2.85,13.40,0.097
2.88,13.53,0.097
2.91,13.66,0.097
2.93,13.80,0.097
2.96,13.93,0.097
2.99,14.07,0.097
3.01,14.20,0.097
3.04,14.33,0.097
3.07,14.47,0.097
3.09,14.60,0.097
3.12,14.74,0.097
3.15,14.87,0.097
3.17,15.00,0.097
3.20,15.14,0.097
3.23,15.27,0.097
3.25,15.40,0.097
3.28,15.54,0.097
3.31,15.67,0.097
3.33,15.80,0.097
3.36,15.94,0.097
3.39,16.07,0.097
3.41,16.20,0.097
3.44,16.34,0.097
3.47,16.47,0.097
3.49,16.60,0.097
3.52,16.73,0.097
3.55,16.87,0.097
3.57,17.00,0.097
3.60,17.13,0.097
3.63,17.27,0.097
3.65,17.40,0.097
3.68,17.53,0.097
3.71,17.67,0.097
3.73,17.80,0.097
3.76,17.93,0.097
3.79,18.07,0.097
3.81,18.20,0.097
3.84,18.34,0.097
3.87,18.47,0.097
3.89,18.60,0.097
3.92,18.74,0.097
3.95,18.87,0.098
3.97,19.00,0.098
4.00,19.14,0.098
4.03,19.27,0.098
4.05,19.40,0.098
4.08,19.54,0.098
4.11,19.67,0.098
4.13,19.80,0.098
4.16,19.94,0.098
4.19,20.07,0.098
4.21,20.20,0.098
4.24,20.34,0.098
4.27,20.47,0.098
4.29,20.60,0.098
4.32,20.74,0.098
4.35,20.87,0.098
4.37,21.00,0.098
4.40,21.14,0.098
4.43,21.27,0.098
4.45,21.40,0.098
4.48,21.54,0.098
4.51,21.67,0.098
4.53,21.80,0.098
4.56,21.94,0.098
4.59,22.07,0.098
4.61,22.20,0.098
4.64,22.34,0.098
4.67,22.47,0.098
4.69,22.61,0.098
4.72,22.74,0.098
4.75,22.87,0.098
4.77,23.00,0.098
4.80,23.14,0.098
4.83,23.27,0.098
4.85,23.40,0.098
4.88,23.54,0.098
4.91,23.67,0.098
4.93,23.80,0.098
4.96,23.94,0.098
4.99,24.07,0.099
5.01,24.20,0.099
5.04,24.34,0.099
5.07,24.47,0.099
5.09,24.60,0.099
5.12,24.74,0.099
5.15,24.87,0.099
5.17,25.00,0.099
5.20,25.14,0.099
5.23,25.27,0.099
5.25,25.40,0.099
5.28,25.54,0.099
5.31,25.67,0.099
5.33,25.81,0.099
5.36,25.94,0.099
5.39,26.07,0.099
5.41,26.21,0.099
5.44,26.34,0.099
5.47,26.47,0.099
5.49,26.61,0.099
5.52,26.74,0.099
5.55,26.87,0.099
5.57,27.01,0.100
5.60,27.14,0.100
5.63,27.28,0.100
5.65,27.41,0.099
5.68,27.54,0.100
5.71,27.68,0.100
5.73,27.81,0.099
5.76,27.94,0.100
5.79,28.08,0.100
5.81,28.21,0.100
5.84,28.34,0.100
5.87,28.47,0.100
5.89,28.61,0.100
5.92,28.74,0.100
5.95,28.87,0.100
5.97,29.01,0.100
6.00,29.14,0.100
6.03,29.27,0.100
6.05,29.41,0.100
6.08,29.54,0.100
6.11,29.68,0.100
6.13,29.81,0.100
6.16,29.94,0.100
6.19,30.08,0.100
6.21,30.21,0.100
6.24,30.34,0.100
6.27,30.48,0.100
6.29,30.61,0.100
6.32,30.74,0.100
6.35,30.88,0.100
6.37,31.01,0.100
6.40,31.14,0.100
6.43,31.28,0.100
6.45,31.41,0.100
6.48,31.54,0.100
6.51,31.68,0.100
6.53,31.81,0.100
6.56,31.94,0.100
6.59,32.08,0.100
6.61,32.21,0.100
6.64,32.34,0.100
6.67,32.48,0.101
6.69,32.61,0.101
6.72,32.75,0.101
6.75,32.88,0.101
6.77,33.01,0.101
6.80,33.14,0.101
6.83,33.28,0.101
6.85,33.41,0.101
6.88,33.55,0.101
6.91,33.68,0.101
6.93,33.81,0.101
6.96,33.95,0.101
6.99,34.08,0.101
7.01,34.21,0.101
7.04,34.35,0.101
7.07,34.48,0.101
7.09,34.61,0.101
7.12,34.75,0.101
7.15,34.88,0.101
7.17,35.01,0.101
7.20,35.15,0.101
7.23,35.28,0.101
7.25,35.41,0.101
7.28,35.55,0.101
7.31,35.68,0.101
7.33,35.81,0.101
7.36,35.95,0.101
7.39,36.08,0.101
7.41,36.21,0.101
7.44,36.35,0.101
7.47,36.48,0.101
7.49,36.61,0.101
7.52,36.75,0.102
7.55,36.88,0.102
7.57,37.02,0.102
7.60,37.15,0.102
7.63,37.28,0.102
7.65,37.41,0.102
7.68,37.55,0.102
7.71,37.68,0.102
7.73,37.81,0.102
7.76,37.95,0.102
7.79,38.08,0.102
7.81,38.22,0.102
7.84,38.35,0.102
7.87,38.48,0.102
7.89,38.61,0.102
7.92,38.75,0.102
7.95,38.88,0.102
7.97,39.02,0.102
8.00,39.15,0.102
8.03,39.28,0.102
8.05,39.41,0.102
8.08,39.55,0.102
8.11,39.68,0.102
8.13,39.81,0.102
8.16,39.95,0.102
8.19,40.08,0.102
8.21,40.22,0.102
8.24,40.35,0.102
8.27,40.48,0.102
8.29,40.62,0.102
8.32,40.75,0.102
8.35,40.88,0.103
8.37,41.02,0.103
8.40,41.15,0.103
8.43,41.28,0.103
8.45,41.42,0.103
8.48,41.55,0.103
8.51,41.68,0.103
8.53,41.82,0.103
8.56,41.95,0.103
8.59,42.08,0.103
8.61,42.22,0.103
8.64,42.35,0.103
8.67,42.49,0.103
8.69,42.62,0.103
8.72,42.75,0.103
8.75,42.89,0.103
8.77,43.02,0.103
8.80,43.15,0.103
8.83,43.29,0.103
8.85,43.42,0.103
8.88,43.55,0.103
8.91,43.69,0.103
8.93,43.82,0.103
8.96,43.95,0.103
8.99,44.09,0.103
9.01,44.22,0.103
9.04,44.35,0.103
9.07,44.49,0.103
9.09,44.62,0.103
9.12,44.75,0.103
9.15,44.88,0.103
9.17,45.02,0.103
9.20,45.15,0.103
9.23,45.28,0.103
9.25,45.42,0.103
9.28,45.55,0.103
9.31,45.69,0.104
9.33,45.82,0.104
9.36,45.95,0.104
9.39,46.08,0.104
9.41,46.22,0.104
9.44,46.35,0.104
9.47,46.49,0.104
9.49,46.62,0.104
9.52,46.75,0.104
9.55,46.89,0.104
9.57,47.02,0.104
9.60,47.15,0.104
9.63,47.29,0.104
9.65,47.42,0.104
9.68,47.55,0.104
9.71,47.69,0.104
9.73,47.82,0.104
9.76,47.96,0.104
9.79,48.09,0.104
9.81,48.22,0.104
9.84,48.35,0.104
9.87,48.49,0.104
9.89,48.62,0.104
9.92,48.75,0.104
9.95,48.89,0.104
9.97,49.02,0.104
10.00,49.16,0.104
10.03,49.29,0.104
10.05,49.42,0.104
10.08,49.55,0.104
10.11,49.69,0.105
10.13,49.82,0.105
10.16,49.96,0.105
10.19,50.09,0.105
10.21,50.22,0.105
10.24,50.35,0.105
10.27,50.49,0.105
10.29,50.62,0.105
10.32,50.76,0.105
10.35,50.89,0.105
10.37,51.02,0.105
10.40,51.15,0.105
10.43,51.29,0.105
10.45,51.42,0.105
10.48,51.56,0.105
10.51,51.69,0.105
10.53,51.82,0.105
10.56,51.96,0.105
10.59,52.09,0.105
10.61,52.22,0.105
10.64,52.36,0.105
10.67,52.49,0.105
10.69,52.62,0.105
10.72,52.76,0.105
10.75,52.89,0.105
10.77,53.02,0.105
10.80,53.16,0.105
10.83,53.29,0.105
10.85,53.42,0.105
10.88,53.56,0.105
10.91,53.69,0.105
10.93,53.82,0.105
10.96,53.96,0.105
10.99,54.09,0.105
11.01,54.22,0.106
11.04,54.36,0.106
11.07,54.49,0.106
11.09,54.62,0.106
11.12,54.76,0.106
11.15,54.89,0.106
11.17,55.02,0.106
11.20,55.16,0.106
11.23,55.29,0.106
11.25,55.43,0.106
11.28,55.56,0.106
11.31,55.69,0.106
11.33,55.83,0.106
11.36,55.96,0.106
11.39,56.09,0.106
11.41,56.23,0.106
11.44,56.36,0.106
11.47,56.49,0.106
11.49,56.63,0.106
11.52,56.76,0.106
11.55,56.89,0.106
11.57,57.03,0.106
11.60,57.16,0.106
11.63,57.29,0.106
11.65,57.43,0.106
11.68,57.56,0.106
11.71,57.69,0.106
11.73,57.83,0.106
11.76,57.96,0.106
11.79,58.09,0.106
11.81,58.23,0.106
11.84,58.36,0.106
11.87,58.49,0.106
11.89,58.63,0.106
11.92,58.76,0.106
11.95,58.89,0.106
11.97,59.03,0.106
12.00,59.16,0.106
12.03,59.29,0.107
12.05,59.43,0.107
12.08,59.56,0.107
12.11,59.69,0.107
12.13,59.83,0.107
12.16,59.96,0.107
12.19,60.09,0.107
12.21,60.23,0.107
12.24,60.36,0.107
12.27,60.50,0.107
12.29,60.63,0.107
12.32,60.76,0.107
12.35,60.90,0.107
12.37,61.03,0.107
12.40,61.16,0.107
12.43,61.29,0.107
12.45,61.43,0.107
12.48,61.56,0.107
12.51,61.70,0.107
12.53,61.83,0.107
12.56,61.96,0.107
12.59,62.10,0.107
12.61,62.23,0.107
12.64,62.36,0.107
12.67,62.50,0.107
12.69,62.63,0.107
12.72,62.76,0.107
12.75,62.90,0.107
12.77,63.03,0.107
12.80,63.16,0.107
12.83,63.30,0.107
12.85,63.43,0.107
12.88,63.56,0.107
12.91,63.70,0.108
12.93,63.83,0.108
12.96,63.96,0.108
12.99,64.10,0.108
13.01,64.23,0.108
13.04,64.36,0.108
13.07,64.50,0.108
13.09,64.63,0.108
13.12,64.76,0.108
13.15,64.90,0.108
13.17,65.03,0.108
13.20,65.16,0.108
13.23,65.30,0.108
13.25,65.43,0.108
13.28,65.56,0.108
13.31,65.70,0.108
13.33,65.83,0.108
13.36,65.96,0.108
13.39,66.10,0.108
13.41,66.23,0.108
13.44,66.37,0.108
13.47,66.50,0.108
13.49,66.63,0.108
13.52,66.77,0.108
13.55,66.90,0.108
13.57,67.03,0.108
13.60,67.17,0.108
13.63,67.30,0.108
13.65,67.43,0.108
13.68,67.56,0.108
13.71,67.70,0.108
13.73,67.83,0.108
13.76,67.97,0.108
13.79,68.10,0.108
13.81,68.23,0.108
13.84,68.37,0.108
13.87,68.50,0.109
13.89,68.63,0.109
13.92,68.77,0.109
13.95,68.90,0.109
13.97,69.03,0.109
14.00,69.17,0.109
14.03,69.30,0.109
14.05,69.43,0.109
14.08,69.57,0.109
14.11,69.70,0.109
14.13,69.83,0.109
14.16,69.97,0.109
14.19,70.10,0.109
14.21,70.23,0.109
14.24,70.37,0.109
14.27,70.50,0.109
14.29,70.63,0.109
14.32,70.77,0.109
14.35,70.90,0.109
14.37,71.03,0.109
14.40,71.17,0.109
14.43,71.30,0.109
14.45,71.44,0.109
14.48,71.57,0.109
14.51,71.70,0.109
14.53,71.83,0.109
14.56,71.97,0.109
14.59,72.10,0.109
14.61,72.24,0.109
14.64,72.37,0.109
14.67,72.50,0.109
14.69,72.64,0.109
14.72,72.77,0.110
14.75,72.90,0.110
14.77,73.04,0.110
14.80,73.17,0.110
14.83,73.30,0.110
14.85,73.44,0.110
14.88,73.57,0.110
14.91,73.70,0.110
14.93,73.84,0.110
14.96,73.97,0.110
14.99,74.10,0.110
15.01,74.24,0.110
15.04,74.37,0.110
15.07,74.50,0.110
15.09,74.64,0.110
15.12,74.77,0.110
15.15,74.90,0.110
15.17,75.04,0.110
15.20,75.17,0.110
15.23,75.30,0.110
15.25,75.44,0.110
15.28,75.57,0.110
15.31,75.70,0.110
15.33,75.84,0.110
15.36,75.97,0.110
15.39,76.10,0.110
15.41,76.24,0.110
15.44,76.37,0.110
15.47,76.50,0.110
15.49,76.64,0.110
15.52,76.77,0.111
15.55,76.90,0.111
15.57,77.04,0.111
15.60,77.17,0.111
15.63,77.30,0.111
15.65,77.44,0.111
15.68,77.57,0.111
15.71,77.70,0.111
15.73,77.84,0.111
15.76,77.97,0.111
15.79,78.10,0.111
15.81,78.24,0.111
15.84,78.37,0.111
15.87,78.51,0.111
15.89,78.64,0.111
15.92,78.77,0.111
15.95,78.91,0.111
15.97,79.04,0.111
16.00,79.17,0.111
16.03,79.31,0.111
16.05,79.44,0.111
16.08,79.57,0.111
16.11,79.71,0.111
16.13,79.84,0.111
16.16,79.97,0.111
16.19,80.11,0.111
16.21,80.24,0.111
16.24,80.37,0.111
16.27,80.51,0.112
16.29,80.64,0.112
16.32,80.77,0.112
16.35,80.91,0.112
16.37,81.04,0.112
16.40,81.17,0.112
16.43,81.31,0.112
16.45,81.44,0.112
16.48,81.57,0.112
16.51,81.71,0.112
16.53,81.84,0.112
16.56,81.97,0.112
16.59,82.11,0.112
16.61,82.24,0.112
16.64,82.37,0.112
16.67,82.51,0.112
16.69,82.64,0.112
16.72,82.77,0.112
16.75,82.91,0.112
16.77,83.04,0.112
16.80,83.17,0.112
16.83,83.31,0.112
16.85,83.44,0.112
16.88,83.57,0.112
16.91,83.71,0.112
16.93,83.84,0.112
16.96,83.97,0.112
16.99,84.11,0.112
17.01,84.24,0.112
17.04,84.37,0.112
17.07,84.51,0.112
17.09,84.64,0.112
17.12,84.77,0.112
17.15,84.91,0.112
17.17,85.04,0.112
17.20,85.17,0.112
17.23,85.31,0.112
17.25,85.44,0.112
17.28,85.58,0.112
17.31,85.71,0.112
17.33,85.84,0.112
17.36,85.98,0.112
17.39,86.11,0.112
17.41,86.24,0.112
17.44,86.37,0.112
17.47,86.51,0.112
17.49,86.64,0.112
17.52,86.77,0.112
17.55,86.91,0.112
17.57,87.04,0.112
17.60,87.17,0.112
17.63,87.31,0.113
17.65,87.44,0.113
17.68,87.58,0.113
17.71,87.71,0.113
17.73,87.84,0.113
17.76,87.98,0.113
17.79,88.11,0.113
17.81,88.24,0.113
17.84,88.38,0.113
17.87,88.51,0.113
17.89,88.64,0.113
17.92,88.78,0.113
17.95,88.91,0.113
17.97,89.04,0.113
18.00,89.18,0.113
18.03,89.31,0.113
18.05,89.44,0.113
18.08,89.58,0.113
18.11,89.71,0.113
18.13,89.84,0.113
18.16,89.98,0.113
18.19,90.11,0.113
18.21,90.24,0.113
18.24,90.38,0.113
18.27,90.51,0.113
18.29,90.64,0.113
18.32,90.78,0.113
18.35,90.91,0.113
18.37,91.04,0.113
18.40,91.18,0.113
18.43,91.31,0.113
18.45,91.44,0.113
18.48,91.58,0.113
18.51,91.71,0.114
18.53,91.84,0.114
18.56,91.98,0.114
18.59,92.11,0.114
18.61,92.24,0.114
18.64,92.38,0.114
18.67,92.51,0.114
18.69,92.64,0.114
18.72,92.78,0.114
18.75,92.91,0.114
18.77,93.05,0.114
18.80,93.18,0.114
18.83,93.31,0.114
18.85,93.45,0.114
18.88,93.58,0.114
18.91,93.71,0.114
18.93,93.85,0.114
18.96,93.98,0.114
18.99,94.11,0.114
19.01,94.25,0.114
19.04,94.38,0.114
19.07,94.51,0.114
19.09,94.65,0.114
19.12,94.78,0.114
19.15,94.91,0.114
19.17,95.05,0.114
19.20,95.18,0.114
19.23,95.31,0.115
19.25,95.45,0.115
19.28,95.58,0.115
19.31,95.71,0.115
19.33,95.85,0.115
19.36,95.98,0.115
19.39,96.11,0.115
19.41,96.25,0.115
19.44,96.38,0.115
19.47,96.51,0.115
19.49,96.65,0.115
19.52,96.78,0.115
19.55,96.91,0.115
19.57,97.05,0.115
19.60,97.18,0.115
19.63,97.31,0.115
19.65,97.45,0.115
19.68,97.58,0.115
19.71,97.71,0.115
19.73,97.85,0.115
19.76,97.98,0.115
19.79,98.11,0.115
19.81,98.25,0.115
19.84,98.38,0.115
19.87,98.51,0.115
19.89,98.65,0.115
19.92,98.78,0.115
19.95,98.91,0.115
19.97,99.05,0.115
20.00,99.18,0.115
20.03,99.32,0.115
20.05,99.45,0.115
20.08,99.58,0.115
20.11,99.72,0.115
20.13,99.85,0.115
20.16,99.98,0.115
20.19,100.12,0.116
20.21,100.25,0.116
20.24,100.38,0.116
20.27,100.52,0.116
20.29,100.65,0.116
20.32,100.78,0.116
20.35,100.92,0.116
20.37,101.05,0.116
20.40,101.18,0.116
20.43,101.32,0.116
20.45,101.45,0.116
20.48,101.58,0.116
20.51,101.71,0.116
20.53,101.85,0.116
20.56,101.98,0.116
20.59,102.12,0.116
20.61,102.25,0.116
20.64,102.38,0.116
20.67,102.52,0.116
20.69,102.65,0.116
20.72,102.78,0.116
20.75,102.92,0.116
20.77,103.05,0.116
20.80,103.18,0.116
20.83,103.32,0.116
20.85,103.45,0.116
20.88,103.58,0.116
20.91,103.72,0.116
20.93,103.85,0.116
20.96,103.98,0.116
20.99,104.12,0.116
21.01,104.25,0.116
21.04,104.38,0.116
21.07,104.52,0.116
21.09,104.65,0.116
21.12,104.78,0.117
21.15,104.92,0.117
21.17,105.05,0.117
21.20,105.19,0.117
21.23,105.32,0.117
21.25,105.45,0.117
21.28,105.59,0.117
21.31,105.72,0.117
21.33,105.85,0.117
21.36,105.99,0.117
21.39,106.12,0.117
21.41,106.25,0.117
21.44,106.38,0.117
21.47,106.52,0.117
21.49,106.65,0.117
21.52,106.79,0.117
21.55,106.92,0.117
21.57,107.05,0.117
21.60,107.18,0.117
21.63,107.32,0.117
21.65,107.45,0.117
21.68,107.59,0.117
21.71,107.72,0.117
21.73,107.85,0.117
21.76,107.98,0.117
21.79,108.12,0.117
21.81,108.25,0.117
21.84,108.39,0.117
21.87,108.52,0.117
21.89,108.65,0.117
21.92,108.79,0.117
21.95,108.92,0.117
21.97,109.05,0.118
22.00,109.19,0.118
22.03,109.32,0.118
22.05,109.45,0.118
22.08,109.59,0.118
22.11,109.72,0.118
22.13,109.85,0.118
22.16,109.99,0.118
22.19,110.12,0.118
22.21,110.25,0.118
22.24,110.39,0.118
22.27,110.52,0.118
22.29,110.65,0.118
22.32,110.79,0.118
22.35,110.92,0.118
22.37,111.05,0.118
22.40,111.19,0.118
22.43,111.32,0.117
22.45,111.45,0.117
22.48,111.59,0.117
22.51,111.72,0.117
22.53,111.85,0.118
22.56,111.99,0.118
22.59,112.12,0.118
22.61,112.25,0.118
22.64,112.39,0.118
22.67,112.52,0.118
22.69,112.65,0.118
22.72,112.79,0.118
22.75,112.92,0.118
22.77,113.05,0.118
22.80,113.19,0.118
22.83,113.32,0.118
22.85,113.45,0.118
22.88,113.59,0.118
22.91,113.72,0.119
22.93,113.85,0.119
22.96,113.99,0.119
22.99,114.12,0.119
23.01,114.25,0.119
23.04,114.39,0.119
23.07,114.52,0.119
23.09,114.65,0.119
23.12,114.79,0.119
23.15,114.92,0.119
23.17,115.05,0.119
23.20,115.19,0.119
23.23,115.32,0.119
23.25,115.45,0.119
23.28,115.59,0.119
23.31,115.72,0.119
23.33,115.86,0.119
23.36,115.99,0.119
23.39,116.12,0.119
23.41,116.26,0.119
23.44,116.39,0.119
23.47,116.52,0.119
23.49,116.66,0.119
23.52,116.79,0.119
23.55,116.92,0.120
23.57,117.05,0.120
23.60,117.19,0.120
23.63,117.32,0.120
23.65,117.45,0.120
23.68,117.59,0.120
23.71,117.72,0.120
23.73,117.85,0.120
23.76,117.99,0.120
23.79,118.12,0.120
23.81,118.25,0.120
23.84,118.39,0.120
23.87,118.52,0.120
23.89,118.65,0.120
23.92,118.79,0.120
23.95,118.92,0.120
23.97,119.05,0.120
24.00,119.19,0.120
24.03,119.32,0.120
24.05,119.45,0.120
24.08,119.59,0.120
24.11,119.72,0.120
24.13,119.86,0.120
24.16,119.99,0.120
24.19,120.12,0.120
24.21,120.26,0.120
24.24,120.39,0.120
24.27,120.52,0.120
24.29,120.66,0.121
24.32,120.79,0.121
24.35,120.92,0.121
24.37,121.06,0.121
24.40,121.19,0.121
24.43,121.32,0.121
24.45,121.46,0.121
24.48,121.59,0.121
24.51,121.72,0.121
24.53,121.86,0.121
24.56,121.99,0.121
24.59,122.12,0.121
24.61,122.26,0.121
24.64,122.39,0.121
24.67,122.52,0.121
24.69,122.66,0.121
24.72,122.79,0.121
24.75,122.93,0.121
24.77,123.06,0.121
24.80,123.19,0.121
24.83,123.32,0.121
24.85,123.46,0.121
24.88,123.59,0.121
24.91,123.73,0.121
24.93,123.86,0.121
24.96,123.99,0.121
24.99,124.12,0.121
25.01,124.26,0.121
25.04,124.39,0.121
25.07,124.52,0.121
25.09,124.66,0.121
25.12,124.79,0.121
25.15,124.92,0.121
25.17,125.06,0.121
25.20,125.19,0.121
25.23,125.32,0.121
25.25,125.46,0.121
25.28,125.59,0.121
25.31,125.72,0.121
25.33,125.86,0.121
25.36,125.99,0.122
25.39,126.13,0.122
25.41,126.26,0.122
25.44,126.39,0.122
25.47,126.53,0.122
25.49,126.66,0.122
25.52,126.79,0.122
25.55,126.93,0.122
25.57,127.06,0.122
25.60,127.19,0.122
25.63,127.32,0.122
25.65,127.46,0.122
25.68,127.59,0.122
25.71,127.73,0.122
25.73,127.86,0.122
25.76,127.99,0.122
25.79,128.13,0.122
25.81,128.26,0.122
25.84,128.39,0.122
25.87,128.53,0.122
25.89,128.66,0.122
25.92,128.79,0.122
25.95,128.93,0.122
25.97,129.06,0.122
26.00,129.19,0.122
26.03,129.33,0.122
26.05,129.46,0.122
26.08,129.59,0.122
26.11,129.73,0.122
26.13,129.86,0.122
26.16,129.99,0.122
26.19,130.13,0.122
26.21,130.26,0.123
26.24,130.39,0.123
26.27,130.53,0.123
26.29,130.66,0.123
26.32,130.79,0.123
26.35,130.93,0.123
26.37,131.06,0.123
26.40,131.19,0.123
26.43,131.33,0.123
26.45,131.46,0.123
26.48,131.59,0.123
26.51,131.73,0.123
26.53,131.86,0.123
26.56,131.99,0.123
26.59,132.13,0.123
26.61,132.26,0.123
26.64,132.39,0.123
26.67,132.53,0.123
26.69,132.66,0.123
26.72,132.79,0.123
26.75,132.93,0.123
26.77,133.06,0.123
26.80,133.19,0.123
26.83,133.33,0.123
26.85,133.46,0.123
26.88,133.59,0.123
26.91,133.73,0.123
26.93,133.86,0.123
26.96,134.00,0.123
26.99,134.13,0.123
27.01,134.26,0.123
27.04,134.40,0.123
27.07,134.53,0.124
27.09,134.66,0.124
27.12,134.80,0.124
27.15,134.93,0.124
27.17,135.06,0.124
27.20,135.20,0.124
27.23,135.33,0.124
27.25,135.46,0.124
27.28,135.59,0.124
27.31,135.73,0.124
27.33,135.86,0.124
27.36,135.99,0.124
27.39,136.13,0.124
27.41,136.26,0.124
27.44,136.39,0.124
27.47,136.53,0.124
27.49,136.66,0.124
27.52,136.79,0.124
27.55,136.93,0.124
27.57,137.06,0.124
27.60,137.19,0.124
27.63,137.33,0.124
27.65,137.46,0.124
27.68,137.60,0.124
27.71,137.73,0.124
27.73,137.86,0.124
27.76,137.99,0.124
27.79,138.13,0.124
27.81,138.26,0.124
27.84,138.39,0.124
27.87,138.53,0.124
27.89,138.66,0.124
27.92,138.80,0.124
27.95,138.93,0.124
27.97,139.06,0.124
28.00,139.20,0.125
28.03,139.33,0.125
28.05,139.46,0.125
28.08,139.59,0.125
28.11,139.73,0.125
28.13,139.86,0.125
28.16,140.00,0.125
28.19,140.13,0.125
28.21,140.26,0.125
28.24,140.40,0.125
28.27,140.53,0.125
28.29,140.66,0.125
28.32,140.80,0.125
28.35,140.93,0.125
28.37,141.06,0.125
28.40,141.20,0.125
28.43,141.33,0.125
28.45,141.46,0.125
28.48,141.60,0.125
28.51,141.73,0.125
28.53,141.86,0.125
28.56,142.00,0.125
28.59,142.13,0.125
28.61,142.26,0.125
28.64,142.40,0.125
28.67,142.53,0.125
28.69,142.66,0.125
28.72,142.80,0.125
28.75,142.93,0.125
28.77,143.06,0.125
28.80,143.20,0.125
28.83,143.33,0.125
28.85,143.46,0.125
28.88,143.60,0.125
28.91,143.73,0.125
28.93,143.86,0.126
28.96,144.00,0.126
28.99,144.13,0.126
29.01,144.26,0.126
29.04,144.40,0.126
29.07,144.53,0.126
29.09,144.66,0.126
29.12,144.80,0.126
29.15,144.93,0.126
29.17,145.06,0.126
29.20,145.20,0.126
29.23,145.33,0.126
29.25,145.46,0.126
29.28,145.60,0.126
29.31,145.73,0.126
29.33,145.86,0.126
29.36,146.00,0.126
29.39,146.13,0.126
29.41,146.26,0.126
29.44,146.40,0.126
29.47,146.53,0.126
29.49,146.66,0.126
29.52,146.80,0.126
29.55,146.93,0.127
29.57,147.06,0.127
29.60,147.20,0.127
29.63,147.33,0.127
29.65,147.46,0.127
29.68,147.60,0.127
29.71,147.73,0.127
29.73,147.86,0.127
29.76,148.00,0.127
29.79,148.13,0.127
29.81,148.27,0.127
29.84,148.40,0.127
29.87,148.53,0.127
29.89,148.66,0.127
29.92,148.80,0.127
29.95,148.93,0.127
29.97,149.06,0.127
30.00,149.20,0.127
30.03,149.33,0.127
30.05,149.47,0.127
30.08,149.60,0.128
30.11,149.73,0.128
30.13,149.87,0.128
30.16,150.00,0.128
30.19,150.13,0.128
30.21,150.26,0.128
30.24,150.40,0.128
30.27,150.53,0.128
30.29,150.66,0.128
30.32,150.80,0.128
30.35,150.93,0.128
30.37,151.07,0.128
30.40,151.20,0.128
30.43,151.33,0.128
30.45,151.47,0.128
30.48,151.60,0.128
30.51,151.73,0.129
30.53,151.87,0.129
30.56,152.00,0.129
30.59,152.13,0.129
30.61,152.27,0.129
30.64,152.40,0.129
30.67,152.53,0.129
30.69,152.67,0.129
30.72,152.80,0.129
30.75,152.93,0.129
30.77,153.06,0.129
30.80,153.20,0.129
30.83,153.33,0.129
30.85,153.47,0.129
30.88,153.60,0.129
30.91,153.73,0.129
30.93,153.86,0.130
30.96,154.00,0.130
30.99,154.13,0.130
31.01,154.26,0.130
31.04,154.40,0.130
31.07,154.53,0.130
31.09,154.66,0.130
31.12,154.80,0.130
31.15,154.93,0.130
31.17,155.07,0.130
31.20,155.20,0.130
31.23,155.33,0.130
31.25,155.47,0.131
31.28,155.60,0.131
31.31,155.73,0.131
31.33,155.86,0.131
31.36,156.00,0.131
31.39,156.13,0.131
31.41,156.27,0.131
31.44,156.40,0.131
31.47,156.54,0.132
31.49,156.67,0.132
31.52,156.81,0.132
31.55,156.94,0.132
31.57,157.07,0.132
31.60,157.21,0.132
31.63,157.34,0.132
31.65,157.47,0.132
31.68,157.60,0.132
31.71,157.74,0.132
31.73,157.87,0.132
31.76,158.00,0.133
31.79,158.14,0.133
31.81,158.27,0.133
31.84,158.40,0.133
31.87,158.54,0.133
31.89,158.67,0.133
31.92,158.80,0.133
31.95,158.93,0.133
31.97,159.07,0.133
32.00,159.20,0.133
32.03,159.33,0.133
32.05,159.46,0.133
32.08,159.60,0.134
32.11,159.73,0.134
32.13,159.86,0.134
32.16,160.00,0.134
32.19,160.13,0.134
32.21,160.26,0.134
32.24,160.40,0.135
32.27,160.53,0.135
32.29,160.66,0.135
32.32,160.80,0.135
32.35,160.93,0.135
32.37,161.06,0.136
32.40,161.20,0.136
32.43,161.33,0.136
32.45,161.46,0.137
32.48,161.60,0.137
32.51,161.73,0.137
32.53,161.86,0.137
32.56,162.00,0.138
32.59,162.13,0.138
32.61,162.26,0.138
32.64,162.39,0.139
32.67,162.53,0.139
32.69,162.66,0.139
32.72,162.79,0.140
32.75,162.93,0.140
32.77,163.06,0.141
32.80,163.20,0.141
32.83,163.33,0.142
32.85,163.46,0.142
32.88,163.59,0.142
32.91,163.73,0.143
32.93,163.86,0.143
32.96,163.99,0.144
32.99,164.13,0.144
33.01,164.26,0.145
33.04,164.39,0.145
33.07,164.52,0.146
33.09,164.66,0.148
33.12,164.79,0.149
33.15,164.92,0.150
33.17,165.05,0.150
33.20,165.19,0.152
33.23,165.32,0.153
33.25,165.45,0.154
33.28,165.59,0.155
33.31,165.72,0.156
33.33,165.85,0.157
33.36,165.98,0.159
33.39,166.12,0.161
33.41,166.25,0.162
33.44,166.38,0.164
33.47,166.51,0.166
33.49,166.64,0.169
33.52,166.78,0.170
33.55,166.91,0.172
33.57,167.04,0.175
33.60,167.18,0.178
33.63,167.31,0.181
33.65,167.44,0.184
33.68,167.57,0.188
33.71,167.70,0.190
33.73,167.84,0.193
33.76,167.97,0.198
33.79,168.10,0.201
33.81,168.23,0.206
33.84,168.36,0.211
33.87,168.49,0.215
33.89,168.62,0.221
33.92,168.75,0.228
33.95,168.88,0.235
33.97,169.01,0.242
34.00,169.14,0.251
34.03,169.26,0.260
34.05,169.39,0.270
34.08,169.52,0.281
34.11,169.65,0.294
34.13,169.78,0.306
34.16,169.90,0.321
34.19,170.03,0.336
34.21,170.15,0.354
34.24,170.27,0.372
34.27,170.39,0.392
34.29,170.52,0.415
34.32,170.63,0.440
34.35,170.75,0.468
34.37,170.87,0.498
34.40,170.98,0.532
34.43,171.10,0.566
34.45,171.21,0.602
34.48,171.32,0.646
34.51,171.43,0.687
34.53,171.54,0.733
34.56,171.65,0.782
34.59,171.75,0.833
34.61,171.85,0.891
34.64,171.95,0.958
34.67,172.05,1.028
34.69,172.14,1.097
34.72,172.23,1.165
34.75,172.32,1.253
34.77,172.41,1.327
34.80,172.49,1.415
34.83,172.57,1.511
34.85,172.65,1.612
34.88,172.73,1.696
34.91,172.80,1.786
34.93,172.88,1.896
34.96,172.95,2.019
34.99,173.01,2.154
35.01,173.07,2.247
35.04,173.14,2.356
35.07,173.20,2.476
35.09,173.27,2.574
35.12,173.34,2.654
35.15,173.43,2.682
35.17,173.54,2.671
35.20,173.66,2.659
35.23,173.79,2.629
35.25,173.94,2.574
35.28,174.10,2.440
35.31,174.30,2.258
35.33,174.53,2.045
35.36,174.78,1.783
35.39,175.05,1.506
35.41,175.34,1.222
35.44,175.63,0.955
35.47,175.92,0.743
35.49,176.19,0.602
35.52,176.43,0.500
35.55,176.64,0.424
35.57,176.84,0.364
35.60,177.02,0.315
35.63,177.19,0.278
35.65,177.36,0.249
35.68,177.52,0.227
35.71,177.67,0.210
35.73,177.81,0.195
35.76,177.96,0.185
35.79,178.10,0.177
35.81,178.24,0.171
35.84,178.38,0.166
35.87,178.52,0.162
35.89,178.65,0.159
35.92,178.79,0.157
35.95,178.92,0.155
35.97,179.06,0.153
36.00,179.19,0.152
36.03,179.33,0.152
36.05,179.46,0.151
36.08,179.59,0.151
36.11,179.73,0.151
36.13,179.86,0.150
36.16,179.99,0.150
36.19,180.13,0.150
36.21,180.26,0.150
36.24,180.40,0.150
36.27,180.53,0.150
36.29,180.66,0.150
36.32,180.80,0.149
36.35,180.93,0.149
36.37,181.06,0.149
36.40,181.20,0.149
36.43,181.33,0.149
36.45,181.46,0.149
36.48,181.59,0.149
36.51,181.73,0.149
36.53,181.86,0.149
36.56,182.00,0.149
36.59,182.13,0.149
36.61,182.26,0.149
36.64,182.40,0.149
36.67,182.53,0.149
36.69,182.66,0.149
36.72,182.80,0.149
36.75,182.93,0.149
36.77,183.06,0.148
36.80,183.20,0.148
36.83,183.33,0.148
36.85,183.46,0.148
36.88,183.60,0.148
36.91,183.73,0.148
36.93,183.86,0.148
36.96,184.00,0.148
36.99,184.13,0.148
37.01,184.26,0.148
37.04,184.40,0.148
37.07,184.53,0.148
37.09,184.66,0.148
37.12,184.80,0.148
37.15,184.93,0.148
37.17,185.07,0.148
37.20,185.20,0.148
37.23,185.33,0.148
37.25,185.47,0.148
37.28,185.60,0.148
37.31,185.73,0.147
37.33,185.86,0.147
37.36,186.00,0.147
37.39,186.13,0.147
37.41,186.27,0.147
37.44,186.40,0.147
37.47,186.53,0.147
37.49,186.67,0.147
37.52,186.80,0.147
37.55,186.93,0.146
37.57,187.07,0.146
37.60,187.20,0.146
37.63,187.33,0.146
37.65,187.47,0.146
37.68,187.60,0.146
37.71,187.73,0.146
37.73,187.87,0.146
37.76,188.00,0.146
37.79,188.13,0.146
37.81,188.27,0.145
37.84,188.40,0.145
37.87,188.53,0.145
37.89,188.67,0.145
37.92,188.80,0.145
37.95,188.93,0.145
37.97,189.07,
38.00,189.20,
38.01,,

[step]
Ramp 5.00 °C/min to 0.00 °C
Time,Temperature,Heat Flow (Normalized)
min,°C,W/g
39.01,190.11,-0.036
39.04,190.11,-0.036
39.06,190.11,-0.037
39.09,190.09,-0.043
39.12,190.05,-0.058
39.14,189.99,-0.080
39.17,189.91,-0.105
39.20,189.82,-0.129
39.23,189.72,-0.149
39.25,189.61,-0.164
39.28,189.50,-0.175
39.31,189.38,-0.184
39.33,189.26,-0.190
39.36,189.14,-0.196
39.39,189.02,-0.200
39.41,188.89,-0.203
39.44,188.76,-0.205
39.46,188.64,-0.207
39.49,188.51,-0.209
39.52,188.38,-0.210
39.54,188.25,-0.210
39.57,188.12,-0.211
39.60,187.99,-0.211
39.63,187.86,-0.212
39.65,187.72,-0.212
39.68,187.59,-0.212
39.71,187.46,-0.212
39.73,187.33,-0.213
39.76,187.20,-0.213
39.79,187.07,-0.213
39.81,186.93,-0.213
39.84,186.80,-0.213
39.86,186.67,-0.213
39.89,186.54,-0.213
39.92,186.40,-0.213
39.94,186.27,-0.213
39.97,186.14,-0.213
40.00,186.01,-0.213
40.03,185.87,-0.213
40.05,185.74,-0.213
40.08,185.61,-0.213
40.11,185.48,-0.213
40.13,185.34,-0.213
40.16,185.21,-0.213
40.19,185.08,-0.213
40.21,184.94,-0.213
40.24,184.81,-0.213
40.26,184.68,-0.213
40.29,184.55,-0.213
40.32,184.41,-0.212
40.34,184.28,-0.212
40.37,184.15,-0.212
40.40,184.01,-0.212
40.43,183.88,-0.212
40.45,183.75,-0.212
40.48,183.61,-0.212
40.51,183.48,-0.212
40.53,183.35,-0.212
40.56,183.21,-0.211
40.59,183.08,-0.211
40.61,182.95,-0.211
40.64,182.81,-0.211
40.66,182.68,-0.211
40.69,182.55,-0.210
40.72,182.42,-0.210
40.74,182.28,-0.210
40.77,182.15,-0.210
40.80,182.02,-0.210
40.83,181.88,-0.210
40.85,181.75,-0.210
40.88,181.62,-0.210
40.91,181.48,-0.209
40.93,181.35,-0.209
40.96,181.22,-0.209
40.99,181.08,-0.209
41.01,180.95,-0.209
41.04,180.82,-0.209
41.06,180.68,-0.209
41.09,180.55,-0.208
41.12,180.42,-0.208
41.14,180.28,-0.208
41.17,180.15,-0.208
41.20,180.02,-0.208
41.23,179.88,-0.208
41.25,179.75,-0.208
41.28,179.62,-0.208
41.31,179.48,-0.207
41.33,179.35,-0.207
41.36,179.22,-0.207
41.39,179.09,-0.207
41.41,178.95,-0.207
41.44,178.82,-0.207
41.46,178.68,-0.207
41.49,178.55,-0.206
41.52,178.42,-0.206
41.54,178.29,-0.206
41.57,178.15,-0.206
41.60,178.02,-0.206
41.63,177.89,-0.206
41.65,177.75,-0.206
41.68,177.62,-0.206
41.71,177.49,-0.206
41.73,177.35,-0.206
41.76,177.22,-0.206
41.79,177.09,-0.205
41.81,176.95,-0.205
41.84,176.82,-0.205
41.86,176.69,-0.205
41.89,176.55,-0.205
41.92,176.42,-0.205
41.94,176.29,-0.205
41.97,176.15,-0.205
42.00,176.02,-0.205
42.03,175.89,-0.204
42.05,175.75,-0.204
42.08,175.62,-0.204
42.11,175.49,-0.204
42.13,175.35,-0.204
42.16,175.22,-0.204
42.19,175.09,-0.204
42.21,174.95,-0.204
42.24,174.82,-0.204
42.26,174.69,-0.203
42.29,174.55,-0.203
42.32,174.42,-0.203
42.34,174.29,-0.203
42.37,174.16,-0.203
42.40,174.02,-0.203
42.43,173.89,-0.203
42.45,173.75,-0.203
42.48,173.62,-0.203
42.51,173.49,-0.203
42.53,173.35,-0.203
42.56,173.22,-0.203
42.59,173.09,-0.203
42.61,172.95,-0.203
42.64,172.82,-0.202
42.66,172.69,-0.202
42.69,172.55,-0.202
42.72,172.42,-0.202
42.74,172.29,-0.202
42.77,172.16,-0.202
42.80,172.02,-0.202
42.83,171.89,-0.202
42.85,171.76,-0.201
42.88,171.62,-0.201
42.91,171.49,-0.201
42.93,171.36,-0.201
42.96,171.22,-0.201
42.99,171.09,-0.201
43.01,170.96,-0.201
43.04,170.82,-0.201
43.06,170.69,-0.201
43.09,170.56,-0.201
43.12,170.42,-0.201
43.14,170.29,-0.201
43.17,170.16,-0.201
43.20,170.02,-0.201
43.23,169.89,-0.201
43.25,169.76,-0.201
43.28,169.62,-0.201
43.31,169.49,-0.201
43.33,169.36,-0.201
43.36,169.22,-0.200
43.39,169.09,-0.200
43.41,168.96,-0.200
43.44,168.82,-0.200
43.46,168.69,-0.200
43.49,168.56,-0.200
43.52,168.43,-0.200
43.54,168.29,-0.200
43.57,168.16,-0.199
43.60,168.03,-0.199
43.63,167.89,-0.199
43.65,167.76,-0.199
43.68,167.63,-0.199
43.71,167.49,-0.199
43.73,167.36,-0.199
43.76,167.23,-0.199
43.79,167.09,-0.199
43.81,166.96,-0.199
43.84,166.83,-0.199
43.86,166.69,-0.199
43.89,166.56,-0.199
43.92,166.43,-0.199
43.94,166.29,-0.199
43.97,166.16,-0.199
44.00,166.02,-0.199
44.03,165.89,-0.199
44.05,165.76,-0.199
44.08,165.62,-0.199
44.11,165.49,-0.199
44.13,165.36,-0.199
44.16,165.23,-0.199
44.19,165.09,-0.199
44.21,164.96,-0.199
44.24,164.82,-0.198
44.26,164.69,-0.198
44.29,164.56,-0.198
44.32,164.42,-0.198
44.34,164.29,-0.198
44.37,164.16,-0.198
44.40,164.02,-0.198
44.43,163.89,-0.198
44.45,163.76,-0.198
44.48,163.63,-0.198
44.51,163.49,-0.198
44.53,163.36,-0.197
44.56,163.23,-0.197
44.59,163.09,-0.197
44.61,162.96,-0.197
44.64,162.83,-0.197
44.66,162.70,-0.197
44.69,162.56,-0.197
44.72,162.43,-0.197
44.74,162.30,-0.197
44.77,162.16,-0.197
44.80,162.03,-0.197
44.83,161.90,-0.197
44.85,161.76,-0.197
44.88,161.63,-0.197
44.91,161.49,-0.197
44.93,161.36,-0.197
44.96,161.22,-0.197
44.99,161.09,-0.197
45.01,160.96,-0.197
45.04,160.82,-0.197
45.06,160.69,-0.197
45.09,160.56,-0.197
45.12,160.43,-0.196
45.14,160.29,-0.196
45.17,160.16,-0.196
45.20,160.03,-0.196
45.23,159.90,-0.196
45.25,159.76,-0.195
45.28,159.63,-0.195
45.31,159.50,-0.195
45.33,159.37,-0.195
45.36,159.23,-0.195
45.39,159.10,-0.195
45.41,158.96,-0.195
45.44,158.83,-0.195
45.46,158.70,-0.196
45.49,158.56,-0.196
45.52,158.43,-0.196
45.54,158.30,-0.196
45.57,158.16,-0.196
45.60,158.03,-0.196
45.63,157.90,-0.196
45.65,157.76,-0.195
45.68,157.63,-0.195
45.71,157.50,-0.195
45.73,157.36,-0.195
45.76,157.23,-0.195
45.79,157.10,-0.195
45.81,156.96,-0.195
45.84,156.83,-0.195
45.86,156.70,-0.195
45.89,156.57,-0.195
45.92,156.43,-0.195
45.94,156.30,-0.195
45.97,156.17,-0.195
46.00,156.03,-0.195
46.03,155.90,-0.195
46.05,155.77,-0.195
46.08,155.63,-0.195
46.11,155.50,-0.195
46.13,155.37,-0.195
46.16,155.23,-0.195
46.19,155.10,-0.195
46.21,154.97,-0.195
46.24,154.83,-0.195
46.26,154.70,-0.195
46.29,154.57,-0.194
46.32,154.43,-0.194
46.34,154.30,-0.194
46.37,154.16,-0.194
46.40,154.03,-0.195
46.43,153.90,-0.194
46.45,153.76,-0.194
46.48,153.63,-0.194
46.51,153.50,-0.194
46.53,153.37,-0.194
46.56,153.23,-0.194
46.59,153.10,-0.194
46.61,152.97,-0.194
46.64,152.83,-0.194
46.66,152.70,-0.194
46.69,152.57,-0.194
46.72,152.43,-0.194
46.74,152.30,-0.194
46.77,152.17,-0.194
46.80,152.03,-0.194
46.83,151.90,-0.194
46.85,151.77,-0.194
46.88,151.63,-0.194
46.91,151.50,-0.193
46.93,151.37,-0.193
46.96,151.23,-0.193
46.99,151.10,-0.193
47.01,150.97,-0.193
47.04,150.83,-0.193
47.06,150.70,-0.193
47.09,150.57,-0.193
47.12,150.44,-0.193
47.14,150.30,-0.193
47.17,150.17,-0.193
47.20,150.04,-0.193
47.23,149.90,-0.193
47.25,149.77,-0.193
47.28,149.64,-0.193
47.31,149.50,-0.193
47.33,149.37,-0.193
47.36,149.24,-0.193
47.39,149.10,-0.193
47.41,148.97,-0.193
47.44,148.84,-0.193
47.46,148.70,-0.193
47.49,148.57,-0.193
47.52,148.44,-0.193
47.54,148.30,-0.193
47.57,148.17,-0.193
47.60,148.04,-0.193
47.63,147.90,-0.193
47.65,147.77,-0.193
47.68,147.63,-0.193
47.71,147.50,-0.193
47.73,147.37,-0.193
47.76,147.23,-0.193
47.79,147.10,-0.193
47.81,146.97,-0.193
47.84,146.83,-0.192
47.86,146.70,-0.192
47.89,146.57,-0.192
47.92,146.43,-0.192
47.94,146.30,-0.192
47.97,146.17,-0.192
48.00,146.04,-0.192
48.03,145.90,-0.192
48.05,145.77,-0.192
48.08,145.64,-0.192
48.11,145.50,-0.192
48.13,145.37,-0.192
48.16,145.24,-0.192
48.19,145.10,-0.192
48.21,144.97,-0.192
48.24,144.84,-0.192
48.26,144.70,-0.192
48.29,144.57,-0.192
48.32,144.44,-0.191
48.34,144.30,-0.191
48.37,144.17,-0.191
48.40,144.04,-0.191
48.43,143.90,-0.191
48.45,143.77,-0.191
48.48,143.64,-0.191
48.51,143.51,-0.191
48.53,143.37,-0.191
48.56,143.24,-0.191
48.59,143.11,-0.191
48.61,142.97,-0.191
48.64,142.84,-0.191
48.66,142.71,-0.191
48.69,142.57,-0.191
48.72,142.44,-0.191
48.74,142.31,-0.191
48.77,142.17,-0.191
48.80,142.04,-0.191
48.83,141.91,-0.191
48.85,141.77,-0.191
48.88,141.64,-0.191
48.91,141.51,-0.191
48.93,141.37,-0.191
48.96,141.24,-0.191
48.99,141.11,-0.191
49.01,140.97,-0.191
49.04,140.84,-0.191
49.06,140.71,-0.190
49.09,140.57,-0.190
49.12,140.44,-0.190
49.14,140.31,-0.190
49.17,140.17,-0.190
49.20,140.04,-0.190
49.23,139.91,-0.190
49.25,139.77,-0.190
49.28,139.64,-0.190
49.31,139.51,-0.190
49.33,139.37,-0.190
[...]
129.16,2.47,0.094
129.16,2.50,0.094
129.17,2.52,0.094
129.17,2.55,0.094
129.18,2.57,0.094
129.18,2.60,0.094
129.19,2.62,0.094
129.19,2.65,0.094
129.20,2.67,0.094
129.20,2.70,0.094
129.21,2.72,0.095
129.21,2.75,0.095
129.22,2.77,0.095
129.22,2.79,0.095
129.23,2.82,0.095
129.23,2.84,0.095
129.24,2.87,0.095
129.24,2.89,0.095
129.25,2.92,0.095
129.25,2.94,0.095
129.26,2.97,0.095
129.26,2.99,0.095
129.27,3.02,0.095
129.27,3.04,0.095
129.28,3.07,0.095
129.28,3.09,0.096
129.29,3.12,0.096
129.29,3.14,0.096
129.30,3.17,0.096
129.30,3.19,0.096
129.31,3.21,0.096
129.31,3.24,0.096
129.32,3.26,0.096
129.32,3.29,0.096
129.33,3.31,0.096
129.33,3.34,0.096
129.34,3.36,0.096
129.34,3.39,0.096
129.35,3.41,0.096
129.35,3.44,0.096
129.36,3.46,0.096
129.36,3.49,0.096
129.37,3.51,0.096
129.37,3.54,0.096
129.38,3.56,0.096
129.38,3.58,0.096
129.39,3.61,0.096
129.39,3.63,0.096
129.40,3.66,0.096
129.40,3.68,0.096
129.41,3.71,0.096
129.41,3.73,0.096
129.42,3.76,0.097
129.42,3.78,0.097
129.43,3.81,0.097
129.43,3.83,0.097
129.44,3.86,0.097
129.44,3.88,0.097
129.45,3.91,0.097
129.45,3.93,0.097
129.46,3.96,0.097
129.46,3.98,0.097
129.47,4.01,0.097
129.47,4.03,0.097
129.48,4.06,0.097
129.48,4.08,0.097
129.49,4.11,0.097
129.49,4.13,0.097
129.50,4.16,0.097
129.50,4.18,0.097
129.51,4.20,0.097
129.51,4.23,0.097
129.52,4.26,0.097
129.52,4.28,0.097
129.53,4.31,0.097
129.53,4.33,0.097
129.54,4.35,0.097
129.54,4.38,0.097
129.55,4.40,0.097
129.55,4.43,0.097
129.56,4.45,0.097
129.56,4.48,0.097
129.57,4.50,0.097
129.57,4.53,0.097
129.58,4.55,0.097
129.58,4.58,0.097
129.59,4.60,0.097
129.59,4.63,0.097
129.60,4.65,0.098
129.60,4.68,0.098
129.61,4.70,0.098
129.61,4.73,0.098
129.62,4.75,0.098
129.62,4.78,0.098
129.63,4.80,0.098
129.63,4.83,0.098
129.64,4.85,0.098
129.64,4.88,0.098
129.65,4.90,0.098
129.65,4.93,0.098
129.66,4.95,0.098
129.66,4.98,0.098
129.67,5.00,0.098
129.67,5.03,0.098
129.68,5.05,0.098
129.68,5.08,0.098
129.69,5.10,0.098
129.69,5.13,0.098
129.70,5.15,0.098
129.70,5.18,0.098
129.71,5.20,0.098
129.71,5.23,0.098
129.72,5.25,0.098
129.72,5.27,0.098
129.73,5.30,0.098
129.73,5.32,0.098
129.74,5.35,0.098
129.74,5.37,0.098
129.75,5.40,0.098
129.75,5.42,0.098
129.76,5.45,0.098
129.76,5.47,0.098
129.77,5.50,0.098
129.77,5.52,0.098
129.78,5.55,0.098
129.78,5.57,0.098
129.79,5.60,0.098
129.79,5.62,0.098
129.80,5.65,0.098
129.80,5.67,0.098
129.81,5.70,0.098
129.81,5.72,0.098
129.82,5.75,0.098
129.82,5.77,0.098
129.83,5.80,0.098
129.83,5.82,0.098
129.84,5.85,0.098
129.84,5.87,0.098
129.85,5.90,0.098
129.85,5.92,0.098
129.86,5.95,0.098
129.86,5.97,0.098
129.87,6.00,0.098
129.87,6.02,0.098
129.88,6.05,0.098
129.88,6.07,0.098
129.89,6.10,0.098
129.89,6.12,0.099
129.90,6.15,0.099
129.90,6.17,0.099
129.91,6.20,0.099
129.91,6.22,0.099
129.92,6.25,0.099
129.92,6.27,0.099
129.93,6.30,0.099
129.93,6.32,0.099
129.94,6.35,0.099
129.94,6.37,0.099
129.95,6.40,0.099
129.95,6.42,0.099
129.96,6.45,0.099
129.96,6.47,0.099
129.97,6.50,0.099
129.97,6.52,0.099
129.98,6.55,0.099
129.98,6.57,0.099
129.99,6.60,0.099
129.99,6.62,0.099
130.00,6.65,0.099
130.00,6.67,0.099
130.01,6.70,0.099
130.01,6.72,0.099
130.02,6.75,0.099
130.02,6.77,0.099
130.03,6.80,0.099
130.03,6.82,0.099
130.04,6.85,0.099
130.04,6.87,0.099
130.05,6.90,0.099
130.05,6.92,0.099
130.06,6.95,0.099
130.06,6.97,0.099
130.07,7.00,0.099
130.07,7.02,0.099
130.08,7.05,0.099
130.08,7.07,0.099
130.09,7.10,0.099
130.09,7.12,0.099
130.10,7.15,0.099
130.10,7.17,0.099
130.11,7.20,0.099
130.11,7.22,0.099
130.12,7.25,0.099
130.12,7.27,0.099
130.13,7.30,0.099
130.13,7.32,0.099
130.14,7.35,0.099
130.14,7.37,0.099
130.15,7.40,0.099
130.15,7.42,0.099
130.16,7.45,0.099
130.16,7.47,0.099
130.17,7.50,0.099
130.17,7.52,0.099
130.18,7.55,0.099
130.18,7.57,0.099
130.19,7.60,0.099
130.19,7.62,0.099
130.20,7.65,0.099
130.20,7.67,0.099
130.21,7.70,0.099
130.21,7.72,0.099
130.22,7.75,0.099
130.22,7.77,0.099
130.23,7.80,0.099
130.23,7.82,0.099
130.24,7.85,0.099
130.24,7.87,0.099
130.25,7.90,0.099
130.25,7.92,0.099
130.26,7.95,0.099
130.26,7.97,0.099
130.27,8.00,0.099
130.27,8.02,0.099
130.28,8.05,0.099
130.28,8.07,0.099
130.29,8.10,0.099
130.29,8.12,0.099
130.30,8.15,0.099
130.30,8.17,0.099
130.31,8.20,0.099
130.31,8.22,0.099
130.32,8.24,0.099
130.32,8.27,0.099
130.33,8.30,0.099
130.33,8.32,0.099
130.34,8.35,0.099
130.34,8.37,0.099
130.35,8.40,0.099
130.35,8.42,0.099
130.36,8.45,0.099
130.36,8.47,0.099
130.37,8.49,0.099
130.37,8.52,0.099
130.38,8.54,0.099
130.38,8.57,0.099
130.39,8.60,0.099
130.39,8.62,0.099
130.40,8.65,0.099
130.40,8.67,0.099
130.41,8.70,0.099
130.41,8.72,0.099
130.42,8.75,0.099
130.42,8.77,0.099
130.43,8.80,0.099
130.43,8.82,0.099
130.44,8.85,0.099
130.44,8.87,0.099
130.45,8.90,0.099
130.45,8.92,0.099
130.46,8.95,0.099
130.46,8.97,0.099
130.47,9.00,0.099
130.47,9.02,0.099
130.48,9.05,0.099
130.48,9.07,0.099
130.49,9.10,0.099
130.49,9.12,0.099
130.50,9.15,0.099
130.50,9.17,0.099
130.51,9.20,0.099
130.51,9.22,0.099
130.52,9.25,0.099
130.52,9.27,0.099
130.53,9.30,0.099
130.53,9.32,0.099
130.54,9.34,0.099
130.54,9.37,0.099
130.55,9.39,0.099
130.55,9.42,0.099
130.56,9.45,0.099
130.56,9.47,0.099
130.57,9.50,0.099
130.57,9.52,0.099
130.58,9.55,0.099
130.58,9.57,0.099
130.59,9.60,0.099
130.59,9.62,0.099
130.60,9.65,0.099
130.60,9.67,0.099
130.61,9.70,0.099
130.61,9.72,0.099
130.62,9.75,0.099
130.62,9.77,0.099
130.63,9.80,0.099
130.63,9.82,0.099
130.64,9.85,0.099
130.64,9.87,0.099
130.65,9.89,0.099
130.65,9.92,0.099
130.66,9.95,0.099
130.66,9.97,0.099
130.67,10.00,0.099
130.67,10.02,0.099
130.68,10.05,0.099
130.68,10.07,0.099
130.69,10.10,0.099
130.69,10.12,0.099
130.70,10.15,0.099
130.70,10.17,0.099
130.71,10.20,0.099
130.71,10.22,0.099
130.72,10.25,0.099
130.72,10.27,0.099
130.73,10.30,0.099
130.73,10.32,0.099
130.74,10.35,0.099
130.74,10.37,0.099
130.75,10.40,0.099
130.75,10.42,0.099
130.76,10.45,0.099
130.76,10.47,0.099
130.77,10.50,0.099
130.77,10.52,0.099
130.78,10.55,0.099
130.78,10.57,0.099
130.79,10.60,0.099
130.79,10.62,0.099
130.80,10.65,0.099
130.80,10.67,0.099
130.81,10.70,0.099
130.81,10.72,0.099
130.82,10.75,0.099
130.82,10.77,0.099
130.83,10.80,0.099
130.83,10.82,0.099
130.84,10.85,0.099
130.84,10.87,0.099
130.85,10.90,0.099
130.85,10.92,0.099
130.86,10.95,0.099
130.86,10.97,0.099
130.87,11.00,0.099
130.87,11.02,0.099
130.88,11.05,0.099
130.88,11.07,0.099
130.89,11.10,0.099
130.89,11.12,0.099
130.90,11.15,0.099
130.90,11.17,0.100
130.91,11.20,0.100
130.91,11.22,0.100
130.92,11.25,0.100
130.92,11.27,0.100
130.93,11.30,0.100
130.93,11.32,0.100
130.94,11.35,0.100
130.94,11.37,0.100
130.95,11.40,0.100
130.95,11.42,0.100
130.96,11.45,0.100
130.96,11.47,0.100
130.97,11.50,0.100
130.97,11.52,0.100
130.98,11.55,0.100
130.98,11.57,0.100
130.99,11.60,0.100
130.99,11.62,0.100
131.00,11.65,0.100
131.00,11.67,0.100
131.01,11.70,0.100
131.01,11.72,0.100
131.02,11.75,0.100
131.02,11.77,0.100
131.03,11.80,0.100
131.03,11.82,0.100
131.04,11.85,0.100
131.04,11.87,0.100
131.05,11.89,0.100
131.05,11.92,0.100
131.06,11.94,0.100
131.06,11.97,0.100
131.07,12.00,0.100
131.07,12.02,0.100
131.08,12.05,0.100
131.08,12.07,0.100
131.09,12.10,0.100
131.09,12.12,0.100
131.10,12.15,0.100
131.10,12.17,0.100
131.11,12.20,0.100
131.11,12.22,0.100
131.12,12.25,0.100
131.12,12.27,0.100
131.13,12.30,0.100
131.13,12.32,0.100
131.14,12.35,0.100
131.14,12.37,0.100
131.15,12.40,0.100
131.15,12.42,0.100
131.16,12.45,0.100
131.16,12.47,0.100
131.17,12.50,0.100
131.17,12.52,0.100
131.18,12.55,0.100
131.18,12.57,0.100
131.19,12.60,0.100
131.19,12.62,0.100
131.20,12.65,0.100
131.20,12.67,0.100
131.21,12.70,0.100
131.21,12.72,0.100
131.22,12.75,0.100
131.22,12.77,0.100
131.23,12.80,0.100
131.23,12.82,0.100
131.24,12.85,0.100
131.24,12.87,0.100
131.25,12.90,0.100
131.25,12.92,0.100
131.26,12.95,0.100
131.26,12.97,0.100
131.27,13.00,0.100
131.27,13.02,0.100
131.28,13.05,0.100
131.28,13.07,0.100
131.29,13.10,0.100
131.29,13.12,0.100
131.30,13.15,0.100
131.30,13.17,0.100
131.31,13.20,0.100
131.31,13.22,0.100
131.32,13.25,0.100
131.32,13.27,0.100
131.33,13.30,0.100
131.33,13.32,0.100
131.34,13.35,0.100
131.34,13.37,0.100
131.35,13.40,0.100
131.35,13.42,0.100
131.36,13.45,0.100
131.36,13.47,0.100
131.37,13.50,0.100
131.37,13.52,0.100
131.38,13.55,0.100
131.38,13.57,0.100
131.39,13.60,0.100
131.39,13.62,0.100
131.40,13.65,0.100
131.40,13.67,0.100
131.41,13.70,0.100
131.41,13.72,0.100
131.42,13.75,0.100
131.42,13.77,0.100
131.43,13.80,0.100
131.43,13.82,0.100
131.44,13.85,0.100
131.44,13.87,0.100
131.45,13.90,0.100
131.45,13.92,0.100
131.46,13.95,0.100
131.46,13.97,0.100
131.47,14.00,0.100
131.47,14.02,0.100
131.48,14.05,0.100
131.48,14.07,0.100
131.49,14.10,0.100
131.49,14.12,0.100
131.50,14.15,0.100
131.50,14.17,0.100
131.51,14.20,0.100
131.51,14.22,0.100
131.52,14.25,0.100
131.52,14.27,0.100
131.53,14.30,0.100
131.53,14.32,0.100
131.54,14.35,0.100
131.54,14.37,0.100
131.55,14.40,0.100
131.55,14.42,0.100
131.56,14.45,0.100
131.56,14.47,0.100
131.57,14.50,0.100
131.57,14.52,0.100
131.58,14.55,0.100
131.58,14.57,0.100
131.59,14.60,0.100
131.59,14.62,0.100
131.60,14.65,0.100
131.60,14.67,0.100
131.61,14.70,0.100
131.61,14.72,0.100
131.62,14.75,0.100
131.62,14.77,0.100
131.63,14.80,0.100
131.63,14.82,0.100
131.64,14.85,0.100
131.64,14.87,0.100
131.65,14.90,0.100
131.65,14.92,0.100
131.66,14.95,0.100
131.66,14.97,0.100
131.67,15.00,0.100
131.67,15.02,0.100
131.68,15.05,0.100
131.68,15.07,0.100
131.69,15.10,0.100
131.69,15.12,0.100
131.70,15.15,0.100
131.70,15.17,0.100
131.71,15.20,0.100
131.71,15.22,0.100
131.72,15.25,0.100
131.72,15.27,0.100
131.73,15.30,0.100
131.73,15.32,0.100
131.74,15.35,0.100
131.74,15.37,0.100
131.75,15.40,0.100
131.75,15.42,0.100
131.76,15.45,0.100
131.76,15.47,0.100
131.77,15.50,0.100
131.77,15.52,0.100
131.78,15.55,0.100
131.78,15.57,0.100
131.79,15.60,0.100
131.79,15.62,0.100
131.80,15.65,0.100
131.80,15.67,0.100
131.81,15.70,0.100
131.81,15.72,0.100
131.82,15.75,0.100
131.82,15.77,0.100
131.83,15.80,0.100
131.83,15.82,0.100
131.84,15.85,0.100
131.84,15.87,0.100
131.85,15.90,0.100
131.85,15.92,0.100
131.86,15.95,0.100
131.86,15.97,0.100
131.87,16.00,0.100
131.87,16.02,0.100
131.88,16.05,0.100
131.88,16.07,0.100
131.89,16.10,0.100
131.89,16.12,0.100
131.90,16.15,0.100
131.90,16.17,0.100
131.91,16.20,0.100
131.91,16.22,0.100
131.92,16.25,0.100
131.92,16.27,0.100
131.93,16.30,0.100
131.93,16.32,0.100
131.94,16.35,0.100
131.94,16.37,0.100
131.95,16.40,0.100
131.95,16.42,0.100
131.96,16.45,0.100
131.96,16.47,0.100
131.97,16.50,0.100
131.97,16.53,0.100
131.98,16.55,0.100
131.98,16.57,0.100
131.99,16.60,0.100
131.99,16.62,0.100
132.00,16.65,0.100
132.00,16.67,0.100
132.01,16.70,0.100
132.01,16.73,0.100
132.02,16.75,0.100
132.02,16.77,0.100
132.03,16.80,0.100
132.03,16.82,0.100
132.04,16.85,0.100
132.04,16.87,0.100
132.05,16.90,0.100
132.05,16.93,0.100
132.06,16.95,0.100
132.06,16.97,0.100
132.07,17.00,0.100
132.07,17.03,0.100
132.08,17.05,0.100
132.08,17.07,0.100
132.09,17.10,0.100
132.09,17.13,0.100
132.10,17.15,0.100
132.10,17.17,0.100
132.11,17.20,0.100
132.11,17.23,0.100
132.12,17.25,0.100
132.12,17.28,0.100
132.13,17.30,0.100
132.13,17.32,0.100
132.14,17.35,0.100
132.14,17.37,0.100
132.15,17.40,0.100
132.15,17.43,0.100
132.16,17.45,0.100
132.16,17.47,0.100
132.17,17.50,0.100
132.17,17.52,0.101
132.18,17.55,0.101
132.18,17.57,0.101
132.19,17.60,0.101
132.19,17.63,0.101
132.20,17.65,0.101
132.20,17.67,0.101
132.21,17.70,0.101
132.21,17.73,0.101
132.22,17.75,0.101
132.22,17.77,0.101
132.23,17.80,0.101
132.23,17.82,0.101
132.24,17.85,0.101
132.24,17.88,0.101
132.25,17.90,0.101
132.25,17.92,0.101
132.26,17.95,0.101
132.26,17.97,0.101
132.27,18.00,0.101
132.27,18.02,0.101
132.28,18.05,0.101
132.28,18.08,0.101
132.29,18.10,0.101
132.29,18.12,0.101
132.30,18.15,0.101
132.30,18.18,0.101
132.31,18.20,0.101
132.31,18.22,0.101
132.32,18.25,0.101
132.32,18.27,0.101
132.33,18.30,0.101
132.33,18.33,0.101
132.34,18.35,0.101
132.34,18.37,0.101
132.35,18.40,0.101
132.35,18.43,0.101
132.36,18.45,0.101
132.36,18.48,0.101
132.37,18.50,0.101
132.37,18.53,0.101
132.38,18.55,0.101
132.38,18.58,0.101
132.39,18.60,0.101
132.39,18.63,0.101
132.40,18.65,0.101
132.40,18.68,0.101
132.41,18.70,0.101
132.41,18.73,0.101
132.42,18.75,0.101
132.42,18.78,0.101
132.43,18.80,0.101
132.43,18.83,0.101
132.44,18.85,0.101
132.44,18.88,0.101
132.45,18.90,0.101
132.45,18.93,0.101
132.46,18.95,0.101
132.46,18.98,0.101
132.47,19.00,0.101
132.47,19.03,0.101
132.48,19.05,0.101
132.48,19.08,0.101
132.49,19.10,0.101
132.49,19.13,0.101
132.50,19.15,0.101
132.50,19.18,0.101
132.51,19.20,0.101
132.51,19.23,0.101
132.52,19.25,0.101
132.52,19.28,0.101
132.53,19.30,0.101
132.53,19.33,0.101
132.54,19.35,0.101
132.54,19.38,0.101
132.55,19.40,0.101
132.55,19.43,0.101
132.56,19.45,0.101
132.56,19.48,0.101
132.57,19.50,0.101
132.57,19.53,0.101
132.58,19.55,0.101
132.58,19.58,0.101
132.59,19.60,0.101
132.59,19.63,0.101
132.60,19.65,0.101
132.60,19.68,0.101
132.61,19.70,0.101
132.61,19.73,0.101
132.62,19.75,0.101
132.62,19.78,0.101
132.63,19.80,0.101
132.63,19.83,0.101
132.64,19.85,0.101
132.64,19.88,0.101
132.65,19.90,0.101
132.65,19.93,0.101
132.66,19.95,0.101
132.66,19.98,0.101
132.67,20.00,0.101
132.67,20.03,0.101
132.68,20.05,0.101
132.68,20.08,0.101
132.69,20.10,0.101
132.69,20.13,0.101
132.70,20.15,0.101
132.70,20.18,0.101
132.71,20.20,0.101
132.71,20.23,0.101
132.72,20.25,0.101
132.72,20.28,0.101
132.73,20.30,0.101
132.73,20.33,0.101
132.74,20.35,0.101
132.74,20.38,0.101
132.75,20.40,0.101
132.75,20.43,0.101
132.76,20.45,0.101
132.76,20.48,0.101
132.77,20.50,0.101
132.77,20.53,0.101
132.78,20.55,0.101
132.78,20.58,0.101
132.79,20.60,0.101
132.79,20.63,0.101
132.80,20.65,0.101
132.80,20.68,0.101
132.81,20.70,0.101
132.81,20.73,0.101
132.82,20.75,0.101
132.82,20.78,0.101
132.83,20.80,0.101
132.83,20.83,0.101
132.84,20.85,0.101
132.84,20.88,0.101
132.85,20.90,0.101
132.85,20.93,0.101
132.86,20.95,0.101
132.86,20.98,0.101
132.87,21.00,0.101
132.87,21.03,0.101
132.88,21.05,0.101
132.88,21.08,0.101
132.89,21.10,0.101
132.89,21.13,0.101
132.90,21.15,0.101
132.90,21.18,0.101
132.91,21.20,0.101
132.91,21.23,0.101
132.92,21.25,0.101
132.92,21.28,0.101
132.93,21.30,0.101
132.93,21.33,0.101
132.94,21.35,0.101
132.94,21.38,0.101
132.95,21.40,0.101
132.95,21.43,0.101
132.96,21.45,0.101
132.96,21.48,0.101
132.97,21.50,0.101
132.97,21.53,0.101
132.98,21.55,0.101
132.98,21.58,0.101
132.99,21.60,0.101
132.99,21.63,0.101
133.00,21.65,0.101
133.00,21.68,0.101
133.01,21.70,0.101
133.01,21.73,0.101
133.02,21.75,0.101
133.02,21.78,0.101
133.03,21.80,0.101
133.03,21.83,0.101
133.04,21.85,0.101
133.04,21.88,0.101
133.05,21.90,0.101
133.05,21.93,0.101
133.06,21.95,0.101
133.06,21.98,0.101
133.07,22.00,0.101
133.07,22.03,0.102
133.08,22.05,0.102
133.08,22.08,0.102
133.09,22.10,0.102
133.09,22.13,0.102
133.10,22.15,0.102
133.10,22.18,0.102
133.11,22.20,0.102
133.11,22.23,0.102
133.12,22.25,0.102
133.12,22.28,0.102
133.13,22.30,0.102
133.13,22.33,0.102
133.14,22.35,0.102
133.14,22.38,0.102
133.15,22.40,0.102
133.15,22.43,0.102
133.16,22.45,0.102
133.16,22.48,0.102
133.17,22.50,0.102
133.17,22.53,0.102
133.18,22.55,0.102
133.18,22.58,0.102
133.19,22.60,0.102
133.19,22.63,0.102
133.20,22.65,0.102
133.20,22.68,0.102
133.21,22.70,0.102
133.21,22.73,0.102
133.22,22.75,0.102
133.22,22.78,0.102
133.23,22.80,0.102
133.23,22.83,0.102
133.24,22.85,0.102
133.24,22.88,0.102
133.25,22.90,0.102
133.25,22.93,0.102
133.26,22.95,0.102
133.26,22.98,0.102
133.27,23.00,0.102
133.27,23.03,0.102
133.28,23.05,0.102
133.28,23.08,0.102
133.29,23.10,0.102
133.29,23.13,0.102
133.30,23.15,0.102
133.30,23.18,0.102
133.31,23.20,0.102
133.31,23.23,0.102
133.32,23.25,0.102
133.32,23.28,0.102
133.33,23.30,0.102
133.33,23.33,0.102
133.34,23.35,0.102
133.34,23.38,0.102
133.35,23.40,0.102
133.35,23.43,0.102
133.36,23.45,0.102
133.36,23.48,0.102
133.37,23.50,0.102
133.37,23.53,0.102
133.38,23.55,0.102
133.38,23.58,0.102
133.39,23.60,0.102
133.39,23.63,0.102
133.40,23.65,0.102
133.40,23.68,0.102
133.41,23.70,0.102
133.41,23.73,0.102
133.42,23.75,0.102
133.42,23.78,0.102
133.43,23.80,0.102
133.43,23.83,0.102
133.44,23.85,0.102
133.44,23.88,0.102
133.45,23.90,0.102
133.45,23.93,0.102
133.46,23.95,0.102
133.46,23.98,0.102
133.47,24.00,0.102
133.47,24.03,0.102
133.48,24.05,0.102
133.48,24.08,0.102
133.49,24.10,0.102
133.49,24.13,0.102
133.50,24.15,0.102
133.50,24.18,0.102
133.51,24.20,0.102
133.51,24.23,0.102
133.52,24.25,0.102
133.52,24.28,0.102
133.53,24.30,0.102
133.53,24.33,0.102
133.54,24.35,0.102
133.54,24.38,0.102
133.55,24.40,0.102
133.55,24.43,0.102
133.56,24.45,0.102
133.56,24.48,0.102
133.57,24.50,0.102
133.57,24.53,0.102
133.58,24.55,0.102
133.58,24.58,0.102
133.59,24.60,0.102
133.59,24.63,0.102
133.60,24.65,0.102
133.60,24.68,0.102
133.61,24.70,0.102
133.61,24.73,0.102
133.62,24.75,0.102
133.62,24.78,0.102
133.63,24.80,0.102
133.63,24.83,0.102
133.64,24.85,0.102
133.64,24.88,0.102
133.65,24.90,0.102
133.65,24.93,0.102
133.66,24.95,0.102
133.66,24.98,0.102
133.67,25.00,0.102
133.67,25.03,0.102
133.68,25.05,0.102
133.68,25.08,0.102
133.69,25.10,0.102
133.69,25.13,0.102
133.70,25.15,0.102
133.70,25.18,0.102
133.71,25.20,0.102
133.71,25.23,0.102
133.72,25.25,0.102
133.72,25.28,0.102
133.73,25.30,0.102
133.73,25.33,0.102
133.74,25.35,0.102
133.74,25.38,0.102
133.75,25.40,0.102
133.75,25.43,0.102
133.76,25.45,0.102
133.76,25.48,0.102
133.77,25.50,0.103
133.77,25.53,0.103
133.78,25.55,0.103
133.78,25.58,0.103
133.79,25.60,0.103
133.79,25.63,0.103
133.80,25.65,0.103
133.80,25.68,0.103
133.81,25.70,0.103
133.81,25.73,0.103
133.82,25.75,0.103
133.82,25.78,0.103
133.83,25.80,0.103
133.83,25.83,0.103
133.84,25.85,0.103
133.84,25.88,0.103
133.85,25.90,0.103
133.85,25.93,0.103
133.86,25.95,0.103
133.86,25.98,0.103
133.87,26.00,0.103
133.87,26.03,0.103
133.88,26.05,0.103
133.88,26.08,0.103
133.89,26.10,0.103
133.89,26.13,0.103
133.90,26.15,0.103
133.90,26.18,0.103
133.91,26.20,0.103
133.91,26.23,0.103
133.92,26.25,0.103
133.92,26.28,0.103
133.93,26.30,0.103
133.93,26.33,0.103
133.94,26.35,0.103
133.94,26.38,0.103
133.95,26.40,0.103
133.95,26.43,0.103
133.96,26.45,0.103
133.96,26.48,0.103
133.97,26.50,0.103
133.97,26.53,0.103
133.98,26.55,0.103
133.98,26.58,0.103
133.99,26.60,0.103
133.99,26.63,0.103
134.00,26.65,0.103
134.00,26.68,0.103
134.01,26.70,0.103
134.01,26.73,0.103
134.02,26.75,0.103
134.02,26.78,0.103
134.03,26.80,0.103
134.03,26.83,0.103
134.04,26.85,0.103
134.04,26.88,0.103
134.05,26.90,0.103
134.05,26.93,0.103
134.06,26.95,0.103
134.06,26.98,0.103
134.07,27.00,0.103
134.07,27.03,0.103
134.08,27.05,0.103
134.08,27.08,0.103
134.09,27.10,0.103
134.09,27.13,0.103
134.10,27.15,0.103
134.10,27.18,0.103
134.11,27.20,0.103
134.11,27.23,0.103
134.12,27.25,0.103
134.12,27.28,0.103
134.13,27.30,0.103
134.13,27.33,0.103
134.14,27.35,0.103
134.14,27.38,0.103
134.15,27.40,0.103
134.15,27.43,0.103
134.16,27.45,0.103
134.16,27.48,0.103
134.17,27.50,0.103
134.17,27.53,0.103
134.18,27.55,0.103
134.18,27.58,0.103
134.19,27.60,0.103
134.19,27.63,0.103
134.20,27.65,0.103
134.20,27.68,0.103
134.21,27.70,0.103
134.21,27.73,0.103
134.22,27.75,0.103
134.22,27.78,0.103
134.23,27.80,0.103
134.23,27.83,0.103
134.24,27.85,0.103
134.24,27.88,0.103
134.25,27.90,0.103
134.25,27.93,0.104
134.26,27.95,0.104
134.26,27.98,0.104
134.27,28.00,0.104
134.27,28.03,0.104
134.28,28.05,0.104
134.28,28.08,0.104
134.29,28.10,0.104
134.29,28.13,0.104
134.30,28.15,0.104
134.30,28.18,0.104
134.31,28.20,0.104
134.31,28.23,0.104
134.32,28.25,0.104
134.32,28.28,0.104
134.33,28.30,0.104
134.33,28.33,0.104
134.34,28.35,0.104
134.34,28.38,0.104
134.35,28.40,0.104
134.35,28.43,0.104
134.36,28.45,0.104
134.36,28.48,0.104
134.37,28.50,0.104
134.37,28.53,0.104
134.38,28.55,0.104
134.38,28.58,0.104
134.39,28.60,0.104
134.39,28.63,0.104
134.40,28.65,0.104
134.40,28.68,0.104
134.41,28.70,0.104
134.41,28.73,0.104
134.42,28.75,0.104
134.42,28.78,0.104
134.43,28.80,0.104
134.43,28.83,0.104
134.44,28.85,0.104
134.44,28.88,0.104
134.45,28.91,0.104
134.45,28.93,0.104
134.46,28.95,
134.46,28.98,
134.47,29.00,
134.47,29.03,
134.48,29.05,
134.48,29.08,
134.49,29.11,
134.49,29.13,
134.50,29.15,
134.50,29.18,
134.51,,
134.51,,