File: DSC/2025_06_17_CBD_n60_150C_10Cmin_x3.csv
Filename,2025_06_17_CBD_n60_150C_10Cmin_x3
Instrument name,DSC2A-00468 (192.168.1.100)
Operator,Gibbons
rundate,6/17/2025
Sample name,2025_06_17_CBD_n60_150C_10Cmin_x3
proceduresegments,Data Off ; Equilibrate -60.00 °C; Data On ; Ramp 10.00 °C/min to 150.00 °C; Data Off ; Isothermal 1.0 min; Data On ; Ramp 10.00 °C/min to -60.00 °C; Data Off ; Isothermal 1.0 min; Data On ; Ramp 10.00 °C/min to 150.00 °C; Data Off ; Isothermal 1.0 min; Data On ; Ramp 10.00 °C/min to -60.00 °C; Data Off ; Isothermal 1.0 min; Data On ; Ramp 10.00 °C/min to 150.00 °C
[File Parameters]
Run date,6/17/2025 1:10:37 PM
Trios version,5.1.1.46572
Original File Name,
Current File Name,D:\DSC2500\Gibbons\2025_06_17_CBD_n60_150C_10Cmin_x3.tri
[Procedure]
Procedure Name,CBD_n60_150C_10Cmin_x3
Sample Name,2025_06_17_CBD_n60_150C_10Cmin_x3
Sample Mass,4.37 mg
Reference Sample Mass,0 mg
Pan Mass,56.27 mg
Pan Number,47
Reference Pan Mass,55.79 mg
Reference Pan Number,1
Pan Type,Tzero Aluminum Hermetic
Comments,Al Hermetic DSC Consumables sealed Pan/Lid. A2 Tray (Google Sheet: DSC_Samples_A2_Tray_May2025)
Project Name,CA
Operator,Gibbons
Test,Custom
Unload Max Temperature,30
Unload Min Temperature,30
Load Max Temperature,30
Load Min Temperature,30
Stop on Gas Flow Error,Yes
[Signal List]
Signal #1,Time (min)
Signal #2,Temperature (°C)
Signal #3,Heat Flow (mW)
Signal #4,Delta T (µV)
Signal #5,Delta Tzero (µV)
Signal #6,Tzero Temperature (°C)
Signal #7,Cell Purge (mL/min)
Signal #8,Heater Temp (°C)
Signal #9,Power Delivered (W)
Signal #10,Reference Junction Temperature (°C)
Signal #11,Flange Temperature (°C)
Signal #12,Heat Flow Phase (rad)
Signal #13,Total Heat Capacity (J/°C)
Signal #14,Heat Capacity (J/°C)
[Configuration]
Company Name,ASU
Instrument Name,DSC2A-00468
Instrument Type,DSC2500
Serial Number,DSC2A-00468
IP,192.168.1.100
Location of Instrument,MRRC
DisplayType,Unknown
Sample Interval ,0.1 s/pt
Selected Heat Flow,T4P
Exotherm Direction,Down
Cell Serial,DRC2-00792
Lid Type,Standard
Cooler,RCS 90
Leave Cooler on at End of Sequence,On
Gas 2,Nitrogen
Gas Selected,Channel 1
Flow Rate,50 mL/min
Secondary Purge,On
Licensed Heat Flow,Heat Flow T4P
Modulation Licensed,Yes
[Versions]
Common IDD Version,1
Cortex Version,VER 2.10.2.31
Driver,5.0.0.6
GDM Version,1.0.3.3
TouchscreenVersion,1.0.0.16145
FEP Version,1.2.1.21
FEP Bootloader,2.0.0.5
AutoSampler Version,2.1.1.26
Auto Sampler Bootloader,2.0.0.5
FCM Version,1.1.0.3
FCM Bootloader,2.0.0.5
[Experiment Logs]
Experiment Log Entry # 1,Data On set to 0
Experiment Log Entry # 3,Equilibrate Segment -60 (C) Started
Experiment Log Entry # 5,Air Cool is off.
Experiment Log Entry # 7,Data On set to 1
Experiment Log Entry # 9,Ramp Segment 10 C/min to 150 Started
Experiment Log Entry # 11,Data On set to 0
Experiment Log Entry # 13,Isothermal Segment 1 min started
Experiment Log Entry # 15,Data On set to 1
Experiment Log Entry # 17,Ramp Segment 10 C/min to -60 Started
Experiment Log Entry # 19,Data On set to 0
Experiment Log Entry # 21,Isothermal Segment 1 min started
Experiment Log Entry # 23,Data On set to 1
Experiment Log Entry # 25,Ramp Segment 10 C/min to 150 Started
Experiment Log Entry # 27,Auto sampler has detected that FEP has gone offline
Experiment Log Entry # 29,Data On set to 0
Experiment Log Entry # 31,Isothermal Segment 1 min started
Experiment Log Entry # 33,Data On set to 1
Experiment Log Entry # 35,Ramp Segment 10 C/min to -60 Started
Experiment Log Entry # 37,Data On set to 0
Experiment Log Entry # 39,Isothermal Segment 1 min started
Experiment Log Entry # 41,Data On set to 1
Experiment Log Entry # 43,Ramp Segment 10 C/min to 150 Started
Experiment Log Entry # 45,Auto sampler has detected that FEP has gone offline
[Method Log]
Method Log Entry # 1,Data Off
Method Log Entry # 2,Equilibrate -60 °C
Method Log Entry # 3,Data On
Method Log Entry # 4,(Ramp 500679) Ramp 10 °C/minute to 150 °C
Method Log Entry # 5,Data Off
Method Log Entry # 6,Isothermal 1 minutes
Method Log Entry # 7,Data On
Method Log Entry # 8,(Ramp 500683) Ramp 10 °C/minute to -60 °C
Method Log Entry # 9,Data Off
Method Log Entry # 10,Isothermal 1 minutes
Method Log Entry # 11,Data On
Method Log Entry # 12,(Ramp 500687) Ramp 10 °C/minute to 150 °C
Method Log Entry # 13,Data Off
Method Log Entry # 14,Isothermal 1 minutes
Method Log Entry # 15,Data On
Method Log Entry # 16,(Ramp 500691) Ramp 10 °C/minute to -60 °C
Method Log Entry # 17,Data Off
Method Log Entry # 18,Isothermal 1 minutes
Method Log Entry # 19,Data On
Method Log Entry # 20,(Ramp 500695) Ramp 10 °C/minute to 150 °C
Cell Serial,DRC2-00792
[T1 Calibration]
Slope,-0.008529666
Offset,9.636258
Initial Temperature,98.23
GUID,f8bfdadc-4977-4fdf-ba6d-0ba9134940c3
[TZero Calibration]
Date Applied,11/29/2022 4:06:13 PM
Description,From -89.059 °C to 396.009 °C at 20.000°C/min
Gas Type,Nitrogen
Pan Type,None
Source Files 1,C:\Users\yargerlab\Desktop\DSC Data\General\TZero_calibration_11_29_22_2nd(2).tri
Source Files 2,C:\Users\yargerlab\Desktop\DSC Data\General\TZero_calibration_11_29_22_2nd(3).tri
Delta T Offset,13.05235
Delta T Slope,-0.007271007
Delta T0 Offset,-13.69128
Delta T0 Slope,0.06063341
[Temperature Calibration]
Date Applied,11/29/2022 7:12:28 PM
Description,From 106.590 °C to 186.590 °C at 10.000°C/min
Gas Type,Nitrogen
Pan Type,Tzero Aluminum Hermetic
Source Files 1,C:\Users\yargerlab\Desktop\DSC Data\General\Indium(6).tri
Measured 1,157.391
Known 1,156.598
[Cell Constant Calibration]
Date Applied,11/29/2022 7:12:29 PM
Description,From 106.590 °C to 186.590 °C at 10.000°C/min
Gas Type,Nitrogen
Pan Type,Tzero Aluminum Hermetic
Source Files 1,C:\Users\yargerlab\Desktop\DSC Data\General\Indium(6).tri
T4P KCell,1.006051
Onset Slope,63.26126 mW/°C
[Direct Cp Calibration]
Date Applied,11/30/2022 11:04:51 AM
Description,From -79.983 °C to 298.409 °C at 10.000°C/min
Gas Type,Nitrogen
Pan Type,Tzero Aluminum Hermetic
Source Files 1,C:\Users\yargerlab\Desktop\DSC Data\General\Sapphire_Heat_Capacity_11_30_22.tri
[Rev Cp Calibration]
Date Applied,11/30/2022 1:58:51 PM
Description,From -79.996 °C to 292.812 °C at 3.000°C/min
Gas Type,Nitrogen
Pan Type,Tzero Aluminum Hermetic
Source Files 1,C:\Users\yargerlab\Desktop\DSC Data\General\Sapphire_MDSC_Calibration_11_30_22.tri
[step]
Ramp 10.00 °C/min to 150.00 °C
Time,Temperature,Heat Flow (Normalized)
min,°C,W/g
0.00,-59.67,-0.071
0.01,-59.68,-0.071
0.03,-59.69,-0.065
0.05,-59.69,-0.061
0.06,-59.69,-0.062
0.08,-59.67,-0.066
0.09,-59.63,-0.082
0.11,-59.59,-0.095
0.12,-59.53,-0.101
0.14,-59.46,-0.103
0.15,-59.38,-0.100
0.16,-59.29,-0.094
0.18,-59.19,-0.071
0.19,-59.08,-0.052
0.21,-58.97,-0.031
0.23,-58.85,-0.011
0.24,-58.73,0.009
0.26,-58.61,0.024
0.27,-58.49,0.042
0.29,-58.36,0.058
0.30,-58.23,0.071
0.31,-58.10,0.082
0.33,-57.97,0.094
0.35,-57.83,0.102
0.36,-57.70,0.111
0.38,-57.56,0.118
0.39,-57.42,0.125
0.40,-57.28,0.133
0.42,-57.14,0.137
0.44,-57.01,0.140
0.45,-56.86,0.145
0.46,-56.72,0.148
0.48,-56.58,0.151
0.50,-56.44,0.155
0.51,-56.29,0.157
0.53,-56.15,0.159
0.54,-56.01,0.162
0.55,-55.86,0.163
0.57,-55.72,0.165
0.58,-55.57,0.166
0.60,-55.43,0.168
0.62,-55.28,0.169
0.63,-55.14,0.170
0.65,-54.99,0.171
0.66,-54.85,0.172
0.68,-54.70,0.174
0.69,-54.55,0.174
0.70,-54.41,0.175
0.72,-54.26,0.175
0.73,-54.11,0.175
0.75,-53.97,0.176
0.77,-53.82,0.176
0.78,-53.67,0.176
0.80,-53.53,0.176
0.81,-53.38,0.176
0.83,-53.23,0.177
0.84,-53.09,0.177
0.85,-52.94,0.177
0.87,-52.79,0.178
0.88,-52.64,0.178
0.90,-52.49,0.178
0.92,-52.35,0.179
0.93,-52.20,0.179
0.95,-52.05,0.179
0.96,-51.90,0.180
0.98,-51.75,0.180
0.99,-51.60,0.181
1.00,-51.46,0.181
1.02,-51.31,0.181
1.03,-51.16,0.181
1.05,-51.01,0.182
1.07,-50.86,0.182
1.08,-50.71,0.182
1.09,-50.56,0.182
1.11,-50.41,0.183
1.13,-50.26,0.183
1.14,-50.11,0.183
1.16,-49.97,0.183
1.17,-49.82,0.184
1.18,-49.67,0.184
1.20,-49.52,0.184
1.22,-49.37,0.184
1.23,-49.22,0.184
1.24,-49.07,0.184
1.26,-48.92,0.185
1.28,-48.77,0.185
1.29,-48.62,0.185
1.31,-48.47,0.185
1.32,-48.32,0.185
1.33,-48.17,0.185
1.35,-48.02,0.185
1.37,-47.88,0.186
1.38,-47.73,0.186
1.39,-47.58,0.186
1.41,-47.43,0.186
1.43,-47.28,0.186
1.44,-47.13,0.186
1.46,-46.98,0.186
1.47,-46.83,0.186
1.48,-46.68,0.187
1.50,-46.53,0.187
1.52,-46.38,0.187
1.53,-46.23,0.187
1.54,-46.08,0.187
1.56,-45.93,0.187
1.58,-45.78,0.187
1.59,-45.63,0.188
1.61,-45.48,0.188
1.62,-45.33,0.188
1.63,-45.18,0.188
1.65,-45.03,0.188
1.67,-44.88,0.188
1.68,-44.73,0.188
1.69,-44.58,0.188
1.71,-44.43,0.188
1.73,-44.28,0.188
1.74,-44.13,0.189
1.76,-43.98,0.189
1.77,-43.83,0.189
1.78,-43.68,0.189
1.80,-43.53,0.189
1.82,-43.38,0.189
1.83,-43.23,0.189
1.84,-43.08,0.189
1.86,-42.93,0.189
1.88,-42.78,0.189
1.89,-42.63,0.190
1.91,-42.48,0.190
1.92,-42.33,0.190
1.93,-42.18,0.190
1.95,-42.03,0.190
1.97,-41.88,0.190
1.98,-41.73,0.190
1.99,-41.58,0.190
2.01,-41.43,0.190
2.03,-41.27,0.190
2.04,-41.13,0.190
2.06,-40.98,0.190
2.07,-40.83,0.190
2.08,-40.68,0.190
2.10,-40.53,0.190
2.12,-40.38,0.190
2.13,-40.22,0.190
2.14,-40.07,0.191
2.16,-39.93,0.191
2.18,-39.77,0.191
2.19,-39.62,0.191
2.21,-39.47,0.191
2.22,-39.32,0.191
2.24,-39.17,0.191
2.25,-39.02,0.191
2.26,-38.87,0.191
2.28,-38.72,0.191
2.29,-38.57,0.191
2.31,-38.42,0.191
2.33,-38.27,0.191
2.34,-38.12,0.191
2.36,-37.97,0.191
2.37,-37.82,0.191
2.39,-37.67,0.192
2.40,-37.52,0.192
2.41,-37.37,0.192
2.43,-37.22,0.192
2.44,-37.07,0.192
2.46,-36.92,0.192
2.48,-36.77,0.192
2.49,-36.62,0.192
2.51,-36.47,0.192
2.52,-36.32,0.192
2.54,-36.17,0.192
2.55,-36.02,0.192
2.56,-35.87,0.192
2.58,-35.72,0.192
2.59,-35.57,0.192
2.61,-35.42,0.192
2.63,-35.27,0.192
2.64,-35.12,0.192
2.66,-34.97,0.192
2.67,-34.82,0.192
2.69,-34.67,0.192
2.70,-34.51,0.192
2.71,-34.36,0.192
2.73,-34.21,0.192
2.74,-34.06,0.192
2.76,-33.91,0.193
2.78,-33.76,0.193
2.79,-33.61,0.193
2.81,-33.46,0.193
2.82,-33.31,0.193
2.84,-33.16,0.193
2.85,-33.01,0.194
2.86,-32.86,0.194
2.88,-32.71,0.194
2.89,-32.56,0.194
2.91,-32.41,0.194
2.93,-32.26,0.194
2.94,-32.11,0.194
2.96,-31.96,0.194
2.97,-31.81,0.194
2.99,-31.66,0.194
3.00,-31.51,0.194
3.01,-31.36,0.194
3.03,-31.21,0.194
3.04,-31.06,0.194
3.06,-30.91,0.194
3.08,-30.76,0.194
3.09,-30.61,0.194
3.11,-30.46,0.194
3.12,-30.31,0.194
3.14,-30.16,0.194
3.15,-30.01,0.194
3.16,-29.86,0.194
3.18,-29.71,0.194
3.19,-29.56,0.194
3.21,-29.41,0.194
3.23,-29.26,0.194
3.24,-29.11,0.194
3.26,-28.96,0.194
3.27,-28.80,0.194
3.29,-28.66,0.194
3.30,-28.51,0.194
3.31,-28.36,0.194
3.33,-28.21,0.194
3.34,-28.06,0.194
3.36,-27.91,0.194
3.38,-27.76,0.194
3.39,-27.61,0.194
3.41,-27.46,0.194
3.42,-27.31,0.194
3.44,-27.16,0.194
3.45,-27.00,0.194
3.46,-26.85,0.194
3.48,-26.71,0.194
3.49,-26.56,0.195
3.51,-26.40,0.195
3.53,-26.26,0.195
3.54,-26.11,0.195
3.56,-25.95,0.195
3.57,-25.80,0.195
3.59,-25.65,0.195
3.60,-25.50,0.195
3.61,-25.35,0.195
3.63,-25.20,0.195
3.64,-25.05,0.195
3.66,-24.90,0.195
3.68,-24.75,0.195
3.69,-24.60,0.195
3.71,-24.45,0.195
3.72,-24.30,0.195
3.74,-24.15,0.195
3.75,-24.00,0.195
3.76,-23.85,0.195
3.78,-23.70,0.196
3.79,-23.55,0.196
3.81,-23.40,0.196
3.83,-23.25,0.196
3.84,-23.10,0.196
3.86,-22.95,0.196
3.87,-22.80,0.196
3.89,-22.65,0.196
3.90,-22.50,0.196
3.91,-22.35,0.196
3.93,-22.20,0.196
3.94,-22.05,0.196
3.96,-21.90,0.196
3.98,-21.75,0.196
3.99,-21.60,0.196
4.01,-21.45,0.196
4.02,-21.30,0.196
4.04,-21.15,0.196
4.05,-21.00,0.197
4.06,-20.85,0.197
4.08,-20.70,0.197
4.09,-20.55,0.197
4.11,-20.40,0.197
4.13,-20.25,0.197
4.14,-20.10,0.197
4.16,-19.95,0.197
4.17,-19.80,0.197
4.19,-19.65,0.197
4.20,-19.50,0.197
4.21,-19.35,0.197
4.23,-19.20,0.197
4.24,-19.05,0.197
4.26,-18.90,0.197
4.28,-18.75,0.197
4.29,-18.60,0.197
4.30,-18.45,0.197
4.32,-18.29,0.198
4.34,-18.14,0.198
4.35,-18.00,0.198
4.36,-17.84,0.198
4.38,-17.69,0.198
4.40,-17.55,0.198
4.41,-17.39,0.198
4.43,-17.25,0.198
4.44,-17.10,0.198
4.45,-16.94,0.198
4.47,-16.80,0.198
4.49,-16.64,0.198
4.50,-16.49,0.198
4.51,-16.34,0.198
4.53,-16.19,0.198
4.55,-16.04,0.198
4.56,-15.89,0.198
4.58,-15.74,0.198
4.59,-15.59,0.198
4.60,-15.44,0.198
4.62,-15.29,0.198
4.64,-15.14,0.199
4.65,-14.99,0.199
4.66,-14.84,0.199
4.68,-14.69,0.199
4.70,-14.54,0.199
4.71,-14.39,0.199
4.73,-14.24,0.199
4.74,-14.09,0.199
4.75,-13.94,0.199
4.77,-13.79,0.199
4.79,-13.64,0.199
4.80,-13.49,0.199
4.81,-13.34,0.199
4.83,-13.19,0.199
4.85,-13.04,0.199
4.86,-12.89,0.199
4.88,-12.74,0.199
4.89,-12.59,0.199
4.90,-12.44,0.200
4.92,-12.29,0.200
4.94,-12.14,0.200
4.95,-11.99,0.200
4.96,-11.84,0.200
4.98,-11.69,0.200
5.00,-11.54,0.200
5.01,-11.39,0.200
5.03,-11.24,0.200
5.04,-11.09,0.200
5.05,-10.94,0.200
5.07,-10.79,0.200
5.09,-10.64,0.200
5.10,-10.49,0.200
5.11,-10.34,0.200
5.13,-10.19,0.200
5.15,-10.04,0.200
5.16,-9.89,0.201
5.18,-9.73,0.201
5.19,-9.59,0.201
5.20,-9.44,0.201
5.22,-9.28,0.201
5.24,-9.13,0.201
5.25,-8.98,0.201
5.26,-8.83,0.201
5.28,-8.68,0.201
5.30,-8.53,0.201
5.31,-8.38,0.201
5.33,-8.23,0.201
5.34,-8.08,0.201
5.35,-7.93,0.201
5.37,-7.78,0.201
5.39,-7.63,0.202
5.40,-7.48,0.202
5.41,-7.33,0.202
5.43,-7.18,0.202
5.45,-7.03,0.202
5.46,-6.88,0.202
5.48,-6.73,0.202
5.49,-6.58,0.202
5.50,-6.43,0.202
5.52,-6.28,0.202
5.54,-6.13,0.202
5.55,-5.98,0.202
5.56,-5.83,0.202
5.58,-5.68,0.202
5.60,-5.53,0.202
5.61,-5.38,0.202
5.63,-5.23,0.202
5.64,-5.08,0.202
5.65,-4.93,0.203
5.67,-4.78,0.203
5.69,-4.63,0.203
5.70,-4.48,0.203
5.71,-4.33,0.203
5.73,-4.18,0.203
5.75,-4.03,0.203
5.76,-3.88,0.203
5.78,-3.73,0.203
5.79,-3.58,0.203
5.80,-3.43,0.203
5.82,-3.28,0.203
5.84,-3.13,0.203
5.85,-2.98,0.204
5.86,-2.83,0.204
5.88,-2.68,0.204
5.90,-2.52,0.204
5.91,-2.38,0.204
5.93,-2.23,0.204
5.94,-2.07,0.204
5.95,-1.92,0.204
5.97,-1.77,0.204
5.99,-1.62,0.204
6.00,-1.47,0.205
6.01,-1.32,0.205
6.03,-1.17,0.205
6.05,-1.02,0.205
6.06,-0.87,0.205
6.08,-0.72,0.205
6.09,-0.57,0.205
6.10,-0.42,0.205
6.12,-0.27,0.205
6.14,-0.12,0.205
6.15,0.03,0.205
6.16,0.18,0.205
6.18,0.33,0.206
6.20,0.48,0.206
6.21,0.63,0.206
6.23,0.78,0.206
6.24,0.93,0.206
6.25,1.08,0.206
6.27,1.23,0.206
6.29,1.38,0.206
6.30,1.53,0.206
6.31,1.68,0.206
6.33,1.83,0.206
6.35,1.98,0.206
6.36,2.13,0.206
6.38,2.28,0.206
6.39,2.43,0.207
6.40,2.58,0.207
6.42,2.73,0.207
6.44,2.88,0.207
6.45,3.03,0.207
6.46,3.18,0.207
6.48,3.33,0.207
6.50,3.48,0.207
6.51,3.63,0.207
6.53,3.78,0.207
6.54,3.93,0.207
6.55,4.08,0.207
6.57,4.23,0.207
6.59,4.38,0.208
6.60,4.53,0.208
6.61,4.68,0.208
6.63,4.83,0.208
6.65,4.99,0.208
6.66,5.14,0.208
6.68,5.29,0.208
6.69,5.44,0.208
6.70,5.59,0.208
6.72,5.74,0.208
6.74,5.89,0.209
6.75,6.04,0.209
6.76,6.19,0.209
6.78,6.34,0.209
6.80,6.49,0.209
6.81,6.64,0.209
6.83,6.79,0.209
6.84,6.94,0.209
6.85,7.09,0.209
6.87,7.24,0.209
6.89,7.39,0.209
6.90,7.54,0.209
6.91,7.69,0.210
6.93,7.84,0.210
6.95,7.99,0.210
6.96,8.14,0.210
6.98,8.29,0.210
6.99,8.44,0.210
7.00,8.59,0.210
7.02,8.74,0.210
7.04,8.89,0.210
7.05,9.04,0.210
7.06,9.19,0.211
7.08,9.34,0.211
7.10,9.49,0.211
7.11,9.64,0.211
7.13,9.79,0.211
7.14,9.94,0.211
7.15,10.09,0.211
7.17,10.24,0.211
7.19,10.39,0.211
7.20,10.54,0.211
7.21,10.69,0.211
7.23,10.84,0.211
7.25,10.99,0.212
7.26,11.14,0.212
7.28,11.29,0.212
7.29,11.44,0.212
7.30,11.59,0.212
7.32,11.74,0.212
7.34,11.89,0.212
7.35,12.04,0.212
7.36,12.19,0.212
7.38,12.34,0.212
7.40,12.49,0.213
7.41,12.64,0.213
7.43,12.79,0.213
7.44,12.94,0.213
7.45,13.09,0.213
7.47,13.24,0.213
7.49,13.39,0.213
7.50,13.54,0.213
7.51,13.70,0.213
7.53,13.84,0.214
7.55,14.00,0.214
7.56,14.15,0.214
7.58,14.30,0.214
7.59,14.45,0.214
7.60,14.59,0.214
7.62,14.75,0.214
7.64,14.90,0.214
7.65,15.05,0.214
7.66,15.20,0.215
7.68,15.35,0.215
7.70,15.49,0.215
7.71,15.65,0.215
7.73,15.80,0.215
7.74,15.95,0.215
7.75,16.10,0.215
7.77,16.25,0.215
7.79,16.40,0.215
7.80,16.55,0.215
7.81,16.70,0.215
7.83,16.85,0.215
7.85,17.00,0.216
7.86,17.15,0.216
7.88,17.30,0.216
7.89,17.45,0.216
7.90,17.60,0.216
7.92,17.75,0.216
7.94,17.90,0.216
7.95,18.05,0.216
7.96,18.20,0.217
7.98,18.35,0.217
8.00,18.50,0.217
8.01,18.65,0.217
8.03,18.80,0.217
8.04,18.95,0.217
8.05,19.10,0.217
8.07,19.25,0.218
8.09,19.40,0.218
8.10,19.55,0.218
8.11,19.70,0.218
8.13,19.85,0.218
8.15,20.00,0.218
8.16,20.15,0.218
8.18,20.30,0.218
8.19,20.45,0.218
8.20,20.60,0.219
8.22,20.75,0.219
8.24,20.90,0.219
8.25,21.05,0.219
8.26,21.20,0.219
8.28,21.35,0.219
8.30,21.50,0.219
8.31,21.65,0.219
8.33,21.80,0.219
8.34,21.95,0.220
8.35,22.10,0.220
8.37,22.25,0.220
8.39,22.40,0.220
8.40,22.56,0.220
8.41,22.70,0.220
8.43,22.85,0.220
8.45,23.00,0.220
8.46,23.16,0.221
8.48,23.30,0.221
8.49,23.46,0.221
8.50,23.61,0.221
8.52,23.76,0.221
8.53,23.91,0.221
8.55,24.06,0.221
8.57,24.21,0.221
8.58,24.36,0.221
8.60,24.51,0.221
8.61,24.66,0.222
8.63,24.81,0.222
8.64,24.96,0.222
8.65,25.11,0.222
8.67,25.26,0.222
8.68,25.41,0.222
8.70,25.56,0.222
8.72,25.71,0.223
8.73,25.86,0.223
8.75,26.01,0.223
8.76,26.16,0.223
8.78,26.31,0.223
8.79,26.46,0.223
8.80,26.61,0.223
8.82,26.76,0.223
8.83,26.91,0.223
8.85,27.06,0.224
8.87,27.21,0.224
8.88,27.36,0.224
8.90,27.51,0.224
8.91,27.66,0.224
8.93,27.81,0.224
8.94,27.96,0.224
8.95,28.11,0.224
8.97,28.26,0.225
8.98,28.41,0.225
9.00,28.56,0.225
9.02,28.71,0.225
9.03,28.86,0.225
9.05,29.01,0.225
9.06,29.16,0.225
9.08,29.31,0.225
9.09,29.46,0.225
9.10,29.61,0.226
9.12,29.76,0.226
9.13,29.91,0.226
9.15,30.06,0.226
9.17,30.21,0.226
9.18,30.36,0.226
9.20,30.51,0.226
9.21,30.66,0.226
9.23,30.81,0.227
9.24,30.96,0.227
9.25,31.12,0.227
9.27,31.27,0.227
9.28,31.42,0.227
9.30,31.56,0.227
9.32,31.72,0.227
9.33,31.86,0.227
9.35,32.02,0.228
9.36,32.17,0.228
9.38,32.32,0.228
9.39,32.47,0.228
9.40,32.62,0.228
9.42,32.76,0.228
9.43,32.91,0.228
9.45,33.07,0.228
9.47,33.22,0.228
9.48,33.37,0.229
9.50,33.52,0.229
9.51,33.67,0.229
9.53,33.82,0.229
9.54,33.97,0.229
9.55,34.12,0.229
9.57,34.27,0.229
9.58,34.42,0.229
9.60,34.57,0.230
9.62,34.72,0.230
9.63,34.87,0.230
9.65,35.02,0.230
9.66,35.17,0.230
9.68,35.32,0.230
9.69,35.47,0.230
9.70,35.62,0.230
9.72,35.77,0.231
9.73,35.92,0.231
9.75,36.07,0.231
9.77,36.22,0.231
9.78,36.37,0.231
9.80,36.52,0.231
9.81,36.67,0.231
9.83,36.82,0.231
9.84,36.97,0.232
9.85,37.12,0.232
9.87,37.27,0.232
9.88,37.42,0.232
9.90,37.57,0.232
9.92,37.72,0.232
9.93,37.87,0.232
9.95,38.02,0.232
9.96,38.17,0.233
9.98,38.32,0.233
9.99,38.47,0.233
10.00,38.62,0.233
10.02,38.77,0.233
10.03,38.92,0.233
10.05,39.07,0.234
10.07,39.22,0.234
10.08,39.37,0.234
10.10,39.52,0.234
10.11,39.67,0.234
10.13,39.82,0.234
10.14,39.97,0.234
10.15,40.12,0.234
10.17,40.27,0.235
10.18,40.42,0.235
10.20,40.57,0.235
10.22,40.72,0.235
10.23,40.87,0.235
10.25,41.02,0.235
10.26,41.18,0.235
10.28,41.32,0.235
10.29,41.47,0.236
10.30,41.63,0.236
10.32,41.78,0.236
10.33,41.93,0.236
10.35,42.08,0.236
10.37,42.23,0.236
10.38,42.38,0.236
10.40,42.53,0.237
10.41,42.68,0.237
10.43,42.83,0.237
10.44,42.97,0.237
10.45,43.13,0.237
10.47,43.28,0.237
10.48,43.43,0.237
10.50,43.58,0.237
10.52,43.73,0.238
10.53,43.88,0.238
10.55,44.03,0.238
10.56,44.18,0.238
10.58,44.33,0.238
10.59,44.48,0.238
10.60,44.63,0.238
10.62,44.78,0.239
10.63,44.93,0.239
10.65,45.08,0.239
10.67,45.23,0.239
10.68,45.38,0.239
10.70,45.53,0.240
10.71,45.68,0.240
10.73,45.83,0.240
10.74,45.98,0.240
10.75,46.13,0.240
10.77,46.28,0.240
10.78,46.43,0.240
10.80,46.58,0.240
10.82,46.73,0.241
10.83,46.88,0.241
10.85,47.03,0.241
10.86,47.18,0.241
10.88,47.33,0.241
10.89,47.48,0.241
10.90,47.63,0.241
10.92,47.78,0.241
10.93,47.93,0.242
10.95,48.08,0.242
10.97,48.23,0.242
10.98,48.38,0.242
11.00,48.53,0.242
11.01,48.68,0.242
11.03,48.83,0.242
11.04,48.98,0.242
11.05,49.13,0.243
11.07,49.28,0.243
11.08,49.43,0.243
11.10,49.58,0.243
11.12,49.73,0.243
11.13,49.88,0.243
11.15,50.03,0.243
11.16,50.18,0.244
11.18,50.33,0.244
11.19,50.48,0.244
11.20,50.63,0.244
11.22,50.78,0.244
11.23,50.93,0.244
11.25,51.08,0.244
11.27,51.23,0.245
11.28,51.38,0.245
11.30,51.53,0.245
11.31,51.69,0.245
11.33,51.83,0.245
11.34,51.98,0.245
11.35,52.14,0.246
11.37,52.29,0.246
11.38,52.44,0.246
11.40,52.59,0.246
11.42,52.74,0.246
11.43,52.89,0.246
11.45,53.04,0.247
11.46,53.19,0.247
11.48,53.34,0.247
11.49,53.49,0.247
11.50,53.64,0.247
11.52,53.79,0.247
11.53,53.94,0.248
11.55,54.09,0.248
11.57,54.24,0.248
11.58,54.39,0.248
11.60,54.54,0.248
11.61,54.69,0.249
11.63,54.84,0.249
11.64,54.99,0.249
11.65,55.14,0.249
11.67,55.29,0.250
11.68,55.44,0.250
11.70,55.59,0.250
11.72,55.74,0.250
11.73,55.89,0.250
11.75,56.04,0.251
11.76,56.19,0.251
11.78,56.34,0.251
11.79,56.49,0.251
11.80,56.64,0.252
11.82,56.79,0.252
11.83,56.94,0.252
11.85,57.09,0.253
11.87,57.24,0.253
11.88,57.39,0.253
11.90,57.54,0.254
11.91,57.69,0.254
11.93,57.84,0.254
11.94,57.99,0.255
11.95,58.14,0.255
11.97,58.29,0.255
11.98,58.44,0.256
12.00,58.59,0.256
12.02,58.74,0.257
12.03,58.89,0.257
12.05,59.04,0.258
12.06,59.19,0.258
12.08,59.34,0.259
12.09,59.49,0.260
12.10,59.64,0.262
12.12,59.79,0.263
12.13,59.94,0.263
12.15,60.09,0.265
12.17,60.24,0.266
12.18,60.39,0.268
12.20,60.54,0.269
12.21,60.69,0.270
12.23,60.84,0.272
12.24,60.99,0.277
12.25,61.14,0.280
12.27,61.29,0.283
12.28,61.44,0.287
12.30,61.59,0.291
12.32,61.74,0.294
12.33,61.89,0.299
12.35,62.03,0.304
12.36,62.18,0.311
12.38,62.33,0.316
12.39,62.48,0.323
12.40,62.63,0.331
12.42,62.78,0.342
12.43,62.92,0.352
12.45,63.07,0.364
12.47,63.22,0.377
12.48,63.37,0.394
12.50,63.51,0.413
12.51,63.66,0.436
12.53,63.81,0.456
12.54,63.95,0.486
12.55,64.09,0.516
12.57,64.24,0.550
12.58,64.38,0.590
12.60,64.52,0.635
12.62,64.66,0.688
12.63,64.80,0.747
12.65,64.93,0.817
12.66,65.07,0.894
12.68,65.20,0.982
12.69,65.33,1.079
12.70,65.46,1.181
12.72,65.58,1.293
12.73,65.70,1.411
12.75,65.83,1.541
12.77,65.94,1.673
12.78,66.06,1.803
12.80,66.17,1.951
12.81,66.29,2.084
12.83,66.40,2.213
12.84,66.51,2.332
12.85,66.62,2.421
12.87,66.74,2.511
12.88,66.86,2.618
12.90,66.98,2.727
12.92,67.09,2.854
12.93,67.21,2.972
12.95,67.33,3.042
12.96,67.45,3.048
12.98,67.58,2.989
12.99,67.72,2.902
13.00,67.87,2.805
13.02,68.03,2.692
13.03,68.19,2.572
13.05,68.36,2.443
13.07,68.54,2.301
13.08,68.72,2.159
13.10,68.90,2.005
13.11,69.09,1.839
13.13,69.28,1.679
13.14,69.47,1.517
13.15,69.66,1.370
13.17,69.86,1.238
13.18,70.05,1.117
13.20,70.24,1.009
13.22,70.42,0.906
13.23,70.61,0.833
13.25,70.79,0.755
13.26,70.97,0.694
13.28,71.15,0.637
13.29,71.32,0.589
13.30,71.49,0.552
13.32,71.66,0.520
13.33,71.83,0.496
13.35,71.99,0.471
13.37,72.15,0.454
13.38,72.32,0.436
13.40,72.47,0.423
13.41,72.63,0.409
13.43,72.79,0.397
13.44,72.95,0.389
13.45,73.10,0.380
13.47,73.26,0.373
13.48,73.41,0.367
13.50,73.56,0.362
13.52,73.72,0.357
13.53,73.87,0.354
13.55,74.02,0.350
13.56,74.17,0.347
13.58,74.33,0.345
13.59,74.48,0.343
13.60,74.63,0.342
13.62,74.78,0.341
13.63,74.93,0.339
13.65,75.08,0.338
13.67,75.23,0.337
13.68,75.39,0.336
13.70,75.54,0.336
13.71,75.69,0.335
13.73,75.84,0.334
13.74,75.99,0.334
13.75,76.14,0.334
13.77,76.29,0.333
13.78,76.44,0.333
13.80,76.59,0.332
13.82,76.74,0.332
13.83,76.89,0.332
13.85,77.04,0.332
13.86,77.19,0.332
13.88,77.34,0.331
13.89,77.49,0.331
13.90,77.64,0.331
13.92,77.79,0.331
13.93,77.94,0.331
13.95,78.09,0.331
13.97,78.24,0.330
13.98,78.39,0.330
14.00,78.54,0.330
14.01,78.69,0.330
14.03,78.84,0.330
14.04,78.99,0.330
14.05,79.14,0.330
14.07,79.29,0.330
14.08,79.44,0.330
14.10,79.59,0.330
14.12,79.74,0.330
14.13,79.90,0.330
14.15,80.04,0.330
14.16,80.20,0.330
14.18,80.34,0.330
14.19,80.50,0.330
14.20,80.64,0.330
14.22,80.80,0.330
14.23,80.95,0.330
14.25,81.10,0.330
14.27,81.25,0.330
14.28,81.40,0.330
14.30,81.55,0.330
14.31,81.70,0.330
14.33,81.85,0.330
14.34,82.00,0.330
14.35,82.15,0.330
14.37,82.30,0.330
14.38,82.45,0.330
14.40,82.60,0.330
14.42,82.75,0.330
14.43,82.90,0.330
14.45,83.05,0.330
14.46,83.20,0.330
14.48,83.35,0.330
14.49,83.50,0.330
14.50,83.65,0.330
14.52,83.80,0.330
14.53,83.95,0.330
14.55,84.10,0.330
14.57,84.25,0.330
14.58,84.40,0.330
14.60,84.55,0.330
14.61,84.70,0.330
14.63,84.85,0.330
14.64,85.00,0.330
14.65,85.15,0.330
14.67,85.30,0.330
14.68,85.45,0.330
14.70,85.60,0.330
14.72,85.75,0.330
14.73,85.90,0.330
14.75,86.05,0.330
14.76,86.20,0.330
14.78,86.35,0.330
14.79,86.50,0.330
14.80,86.65,0.330
14.82,86.80,0.330
14.83,86.95,0.331
14.85,87.10,0.331
14.87,87.25,0.331
14.88,87.40,0.331
14.90,87.55,0.331
14.91,87.70,0.331
14.93,87.85,0.331
14.94,88.00,0.331
14.95,88.15,0.331
14.97,88.30,0.331
14.98,88.45,0.331
15.00,88.60,0.331
15.02,88.75,0.331
15.03,88.90,0.331
15.05,89.05,0.331
15.06,89.20,0.331
15.08,89.35,0.331
15.09,89.50,0.331
15.10,89.65,0.331
15.12,89.80,0.331
15.13,89.95,0.332
15.15,90.10,0.332
15.17,90.25,0.332
15.18,90.40,0.332
15.20,90.55,0.332
15.21,90.70,0.332
15.23,90.85,0.332
15.24,91.00,0.332
15.25,91.15,0.332
15.27,91.30,0.332
15.28,91.45,0.332
15.30,91.61,0.332
15.32,91.76,0.332
15.33,91.91,0.332
15.35,92.06,0.333
15.36,92.20,0.333
15.38,92.36,0.333
15.39,92.51,0.333
15.40,92.66,0.333
15.42,92.81,0.333
15.43,92.96,0.333
15.45,93.11,0.333
15.47,93.26,0.334
15.48,93.41,0.334
15.50,93.56,0.334
15.51,93.71,0.334
15.53,93.86,0.334
15.54,94.01,0.334
15.55,94.16,0.334
15.57,94.31,0.334
15.58,94.46,0.334
15.60,94.61,0.334
15.62,94.76,0.334
15.63,94.91,0.334
15.65,95.06,0.334
15.66,95.21,0.334
15.68,95.36,0.335
15.69,95.51,0.335
15.70,95.66,0.335
15.72,95.81,0.335
15.73,95.96,0.335
15.75,96.11,0.335
15.77,96.26,0.335
15.78,96.41,0.335
15.80,96.56,0.335
15.81,96.71,0.335
15.83,96.86,0.335
15.84,97.01,0.335
15.85,97.16,0.336
15.87,97.31,0.336
15.88,97.46,0.336
15.90,97.61,0.336
15.92,97.76,0.336
15.93,97.91,0.336
15.95,98.06,0.336
15.96,98.21,0.336
15.98,98.36,0.336
15.99,98.51,0.336
16.00,98.66,0.336
16.02,98.81,0.336
16.03,98.96,0.336
16.05,99.11,0.336
16.07,99.27,0.337
16.08,99.41,0.337
16.10,99.56,0.337
16.11,99.72,0.337
16.13,99.87,0.337
16.14,100.02,0.337
16.15,100.17,0.337
16.17,100.32,0.337
16.18,100.47,0.337
16.20,100.62,0.337
16.22,100.77,0.337
16.23,100.92,0.338
16.25,101.07,0.338
16.26,101.22,0.338
16.28,101.37,0.338
16.29,101.52,0.338
16.30,101.67,0.338
16.32,101.82,0.338
16.33,101.97,0.338
16.35,102.12,0.338
16.37,102.27,0.338
16.38,102.42,0.338
16.40,102.57,0.338
16.41,102.72,0.338
16.43,102.87,0.339
16.44,103.02,0.339
16.45,103.17,0.339
16.47,103.32,0.339
16.48,103.47,0.339
16.50,103.62,0.339
16.52,103.77,0.339
16.53,103.92,0.339
16.55,104.07,0.339
16.56,104.22,0.339
16.58,104.37,0.339
16.59,104.52,0.339
16.60,104.67,0.339
16.62,104.82,0.339
16.63,104.97,0.339
16.65,105.12,0.339
16.67,105.27,0.339
16.68,105.42,0.339
16.70,105.57,0.339
16.71,105.72,0.339
16.73,105.87,0.339
16.74,106.02,0.340
16.75,106.17,0.340
16.77,106.32,0.340
16.78,106.47,0.340
16.80,106.62,0.340
16.82,106.77,0.340
16.83,106.92,0.340
16.85,107.07,0.340
16.86,107.22,0.340
16.88,107.37,0.340
16.89,107.52,0.340
16.90,107.67,0.340
16.92,107.82,0.340
16.93,107.97,0.340
16.95,108.12,0.340
16.97,108.27,0.340
16.98,108.42,0.340
17.00,108.57,0.340
17.01,108.72,0.341
17.03,108.87,0.341
17.04,109.02,0.341
17.05,109.17,0.341
17.07,109.32,0.341
17.08,109.47,0.341
17.10,109.62,0.341
17.12,109.77,0.341
17.13,109.92,0.341
17.14,110.08,0.341
17.16,110.23,0.341
17.18,110.37,0.341
17.19,110.52,0.341
17.21,110.68,0.341
17.22,110.82,0.341
17.23,110.98,0.341
17.25,111.13,0.341
17.27,111.28,0.341
17.28,111.42,0.341
17.29,111.58,0.341
17.31,111.73,0.341
17.33,111.88,0.342
17.34,112.03,0.342
17.36,112.18,0.342
17.37,112.33,0.342
17.38,112.48,0.342
17.40,112.63,0.342
17.42,112.78,0.342
17.43,112.93,0.342
17.44,113.08,0.342
17.46,113.23,0.342
17.48,113.38,0.342
17.49,113.53,0.342
17.51,113.68,0.342
17.52,113.83,0.342
17.53,113.98,0.342
17.55,114.13,0.343
17.57,114.28,0.343
17.58,114.43,0.343
17.59,114.58,0.343
17.61,114.73,0.343
17.63,114.88,0.343
17.64,115.03,0.343
17.66,115.18,0.343
17.67,115.33,0.343
17.68,115.48,0.343
17.70,115.63,0.343
17.72,115.78,0.343
17.73,115.93,0.343
17.74,116.08,0.343
17.76,116.23,0.343
17.78,116.38,0.343
17.79,116.53,0.343
17.81,116.68,0.343
17.82,116.83,0.343
17.83,116.98,0.343
17.85,117.13,0.343
17.87,117.28,0.343
17.88,117.43,0.343
17.89,117.58,0.343
17.91,117.73,0.343
17.93,117.88,0.343
17.94,118.03,0.344
17.96,118.18,0.344
17.97,118.33,0.344
17.98,118.48,0.344
18.00,118.63,0.344
18.02,118.78,0.344
18.03,118.93,0.344
18.04,119.08,0.344
18.06,119.23,0.344
18.08,119.38,0.344
18.09,119.53,0.344
18.11,119.68,0.344
18.12,119.83,0.344
18.13,119.99,0.344
18.15,120.14,0.344
18.17,120.29,0.344
18.18,120.44,0.344
18.19,120.59,0.345
18.21,120.74,0.345
18.23,120.89,0.345
18.24,121.04,0.345
18.26,121.19,0.345
18.27,121.34,0.345
18.28,121.49,0.345
18.30,121.64,0.345
18.32,121.79,0.345
18.33,121.94,0.345
18.34,122.09,0.345
18.36,122.24,0.345
18.38,122.39,0.345
18.39,122.54,0.345
18.41,122.69,0.345
18.42,122.84,0.345
18.43,122.99,0.345
18.45,123.14,0.345
18.47,123.29,0.345
18.48,123.44,0.345
18.49,123.59,0.345
18.51,123.74,0.345
18.53,123.89,0.345
18.54,124.04,0.345
18.56,124.19,0.345
18.57,124.34,0.345
18.58,124.49,0.345
18.60,124.64,0.345
18.62,124.79,0.345
18.63,124.94,0.345
18.64,125.09,0.345
18.66,125.24,0.345
18.68,125.39,0.345
18.69,125.54,0.345
18.71,125.69,0.345
18.72,125.84,0.345
18.73,125.99,0.345
18.75,126.14,0.346
18.77,126.29,0.346
18.78,126.44,0.346
18.79,126.59,0.346
18.81,126.74,0.346
18.83,126.89,0.346
18.84,127.04,0.346
18.86,127.19,0.346
18.87,127.34,0.346
18.88,127.49,0.346
18.90,127.64,0.346
18.92,127.79,0.346
18.93,127.94,0.346
18.94,128.09,0.346
18.96,128.24,0.347
18.98,128.39,0.347
18.99,128.54,0.347
19.01,128.69,0.347
19.02,128.84,0.347
19.03,128.99,0.347
19.05,129.14,0.347
19.07,129.29,0.347
19.08,129.44,0.347
19.09,129.59,0.347
19.11,129.74,0.347
19.13,129.89,0.347
19.14,130.04,0.347
19.16,130.19,0.347
19.17,130.34,0.347
19.18,130.49,0.347
19.20,130.64,0.347
19.22,130.79,0.347
19.23,130.94,0.347
19.24,131.10,0.347
19.26,131.24,0.347
19.28,131.39,0.347
19.29,131.54,0.347
19.31,131.69,0.347
19.32,131.84,0.347
19.33,131.99,0.347
19.35,132.14,0.347
19.37,132.29,0.347
19.38,132.44,0.347
19.39,132.59,0.347
19.41,132.75,0.347
19.43,132.90,0.347
19.44,133.04,0.347
19.46,133.20,0.347
19.47,133.35,0.347
19.48,133.50,0.347
19.50,133.65,0.347
19.52,133.80,0.347
19.53,133.95,0.347
19.54,134.10,0.347
19.56,134.25,0.347
19.58,134.40,0.347
19.59,134.55,0.347
19.61,134.70,0.347
19.62,134.85,0.347
19.63,135.00,0.347
19.65,135.15,0.347
19.67,135.30,0.347
19.68,135.45,0.347
19.69,135.60,0.347
19.71,135.75,0.346
19.73,135.90,0.346
19.74,136.05,0.346
19.76,136.20,0.346
19.77,136.35,0.347
19.78,136.50,0.346
19.80,136.65,0.347
19.82,136.80,0.346
19.83,136.95,0.346
19.84,137.10,0.347
19.86,137.25,0.347
19.88,137.40,0.346
19.89,137.55,0.346
19.91,137.70,0.346
19.92,137.85,0.346
19.93,138.00,0.346
19.95,138.15,0.346
19.97,138.30,0.346
19.98,138.45,0.346
19.99,138.60,0.346
20.01,138.75,0.346
20.03,138.90,0.346
20.04,139.05,0.346
20.06,139.20,0.346
20.07,139.35,0.346
20.08,139.50,0.346
20.10,139.65,0.346
20.12,139.80,0.346
20.13,139.95,0.346
20.14,140.10,0.346
20.16,140.25,0.346
20.18,140.40,0.346
20.19,140.55,0.346
20.21,140.70,0.346
20.22,140.85,0.346
20.23,141.00,0.346
20.25,141.15,0.346
20.27,141.30,0.346
20.28,141.45,0.346
20.29,141.60,0.346
20.31,141.75,0.346
20.33,141.90,0.346
20.34,142.05,0.346
20.36,142.20,0.346
20.37,142.35,0.345
20.38,142.50,0.345
20.40,142.65,0.345
20.42,142.80,0.345
20.43,142.95,0.345
20.44,143.10,0.345
20.46,143.25,0.345
20.48,143.40,0.345
20.49,143.55,0.345
20.51,143.70,0.345
20.52,143.85,0.345
20.53,144.00,0.345
20.55,144.15,0.345
20.57,144.31,0.345
20.58,144.45,0.345
20.59,144.60,0.345
20.61,144.75,0.345
20.63,144.90,0.353
20.64,145.05,0.353
20.66,145.20,0.352
20.67,145.35,0.351
20.68,145.50,0.351
20.70,145.65,0.350
20.72,145.81,0.350
20.73,145.96,0.350
20.74,146.11,0.349
20.76,146.26,0.349
20.78,146.41,0.349
20.79,146.56,0.349
20.81,146.71,0.348
20.82,146.86,0.348
20.83,147.01,0.348
20.85,147.16,0.348
20.87,147.31,0.347
20.88,147.46,0.347
20.89,147.61,0.347
20.91,147.76,0.346
20.93,147.91,0.346
20.94,148.06,
20.96,148.21,
20.97,148.36,
20.98,,
20.99,,

[step]
Ramp 10.00 °C/min to -60.00 °C
Time,Temperature,Heat Flow (Normalized)
min,°C,W/g
21.99,150.11,-0.058
22.01,150.11,-0.058
22.02,150.11,-0.058
22.04,150.10,-0.058
22.05,150.09,-0.051
22.07,150.06,-0.033
22.08,150.03,-0.021
22.10,149.97,-0.018
22.11,149.90,-0.025
22.13,149.82,-0.055
22.14,149.73,-0.091
22.16,149.63,-0.130
22.17,149.52,-0.173
22.19,149.41,-0.207
22.20,149.29,-0.239
22.22,149.17,-0.266
22.23,149.05,-0.291
22.25,148.92,-0.309
22.26,148.79,-0.328
22.28,148.66,-0.342
22.29,148.52,-0.356
22.31,148.38,-0.369
22.32,148.25,-0.378
22.34,148.11,-0.388
22.35,147.97,-0.393
22.37,147.83,-0.401
22.38,147.68,-0.409
22.40,147.54,-0.412
22.41,147.40,-0.417
22.43,147.25,-0.421
22.44,147.11,-0.424
22.46,146.96,-0.428
22.47,146.82,-0.430
22.49,146.67,-0.432
22.50,146.52,-0.434
22.52,146.38,-0.435
22.53,146.23,-0.436
22.55,146.08,-0.437
22.56,145.94,-0.438
22.58,145.79,-0.438
22.59,145.64,-0.439
22.61,145.49,-0.440
22.62,145.35,-0.440
22.64,145.20,-0.441
22.65,145.05,-0.441
22.67,144.90,-0.442
22.68,144.75,-0.442
22.70,144.61,-0.443
22.71,144.46,-0.443
22.73,144.31,-0.443
22.74,144.16,-0.444
22.76,144.01,-0.444
22.77,143.86,-0.444
22.79,143.71,-0.444
22.80,143.57,-0.444
22.82,143.42,-0.445
22.83,143.27,-0.445
22.85,143.12,-0.445
22.86,142.97,-0.445
22.88,142.82,-0.445
22.89,142.67,-0.445
22.91,142.52,-0.446
22.92,142.37,-0.446
22.94,142.22,-0.446
22.95,142.08,-0.446
22.97,141.93,-0.446
22.98,141.78,-0.446
23.00,141.63,-0.446
23.01,141.48,-0.446
23.03,141.33,-0.446
23.04,141.18,-0.446
23.06,141.03,-0.446
23.07,140.88,-0.446
23.09,140.73,-0.446
23.10,140.58,-0.446
23.12,140.43,-0.446
23.13,140.28,-0.446
23.15,140.14,-0.446
23.16,139.99,-0.446
23.18,139.84,-0.446
23.19,139.69,-0.446
23.21,139.54,-0.446
23.22,139.39,-0.446
23.24,139.24,-0.446
23.25,139.09,-0.446
23.27,138.94,-0.445
23.28,138.79,-0.445
23.30,138.64,-0.445
23.31,138.49,-0.445
23.33,138.34,-0.445
23.34,138.19,-0.445
23.36,138.04,-0.445
23.37,137.89,-0.445
23.39,137.74,-0.444
23.40,137.59,-0.444
23.42,137.44,-0.444
23.43,137.29,-0.444
23.45,137.15,-0.444
23.46,137.00,-0.444
23.48,136.85,-0.444
23.49,136.70,-0.444
23.51,136.55,-0.444
23.52,136.40,-0.444
23.54,136.25,-0.443
23.55,136.10,-0.443
23.57,135.95,-0.443
23.58,135.80,-0.443
23.60,135.65,-0.443
23.61,135.50,-0.442
23.63,135.35,-0.442
23.64,135.20,-0.442
23.66,135.05,-0.442
23.67,134.90,-0.442
23.69,134.75,-0.442
23.70,134.60,-0.442
23.72,134.45,-0.441
23.73,134.30,-0.441
23.75,134.15,-0.441
23.76,134.00,-0.441
23.78,133.85,-0.440
23.79,133.70,-0.440
23.81,133.55,-0.440
23.82,133.40,-0.440
23.84,133.25,-0.440
23.85,133.10,-0.440
23.87,132.95,-0.439
23.88,132.80,-0.439
23.90,132.65,-0.439
23.91,132.50,-0.439
23.93,132.35,-0.439
23.94,132.20,-0.438
23.96,132.05,-0.438
23.97,131.90,-0.438
23.99,131.75,-0.438
24.00,131.61,-0.438
24.02,131.45,-0.438
24.03,131.30,-0.438
24.05,131.16,-0.438
24.06,131.01,-0.437
24.08,130.86,-0.437
24.09,130.70,-0.437
24.11,130.56,-0.437
24.12,130.41,-0.437
24.14,130.26,-0.437
24.15,130.11,-0.436
24.17,129.96,-0.436
24.18,129.81,-0.436
24.20,129.66,-0.436
24.21,129.51,-0.436
24.23,129.36,-0.436
24.24,129.21,-0.436
24.26,129.06,-0.435
24.27,128.91,-0.435
24.29,128.76,-0.435
24.30,128.61,-0.435
24.32,128.46,-0.435
24.33,128.31,-0.434
24.35,128.16,-0.434
24.36,128.01,-0.434
24.38,127.86,-0.434
24.39,127.71,-0.434
24.41,127.56,-0.433
24.42,127.41,-0.433
24.44,127.26,-0.433
24.45,127.11,-0.433
24.47,126.96,-0.433
24.48,126.81,-0.433
24.50,126.66,-0.432
24.51,126.51,-0.432
24.53,126.36,-0.432
24.54,126.21,-0.432
24.56,126.06,-0.432
24.57,125.91,-0.432
24.59,125.76,-0.432
24.60,125.61,-0.431
24.62,125.46,-0.431
24.63,125.31,-0.431
24.65,125.16,-0.431
24.66,125.01,-0.431
24.68,124.86,-0.430
24.69,124.71,-0.430
24.71,124.56,-0.430
24.72,124.41,-0.430
24.74,124.26,-0.430
24.75,124.11,-0.430
24.77,123.96,-0.430
24.78,123.81,-0.429
24.80,123.66,-0.429
24.81,123.51,-0.429
24.83,123.36,-0.429
24.84,123.21,-0.429
24.86,123.06,-0.428
24.87,122.91,-0.428
24.89,122.76,-0.428
24.90,122.61,-0.428
24.92,122.46,-0.428
24.93,122.31,-0.428
24.95,122.16,-0.428
24.96,122.01,-0.427
24.98,121.86,-0.427
24.99,121.71,-0.427
25.01,121.57,-0.427
25.02,121.41,-0.427
25.04,121.26,-0.427
25.05,121.11,-0.427
25.07,120.96,-0.426
25.08,120.81,-0.426
25.10,120.66,-0.426
25.11,120.51,-0.426
25.13,120.36,-0.426
25.14,120.21,-0.426
25.16,120.07,-0.426
25.17,119.92,-0.426
25.19,119.77,-0.425
25.20,119.62,-0.425
25.22,119.47,-0.425
25.23,119.32,-0.425
25.25,119.17,-0.425
25.26,119.02,-0.425
25.28,118.87,-0.424
25.29,118.72,-0.424
25.31,118.57,-0.424
25.32,118.42,-0.424
25.34,118.27,-0.424
25.35,118.12,-0.423
25.37,117.97,-0.423
25.38,117.82,-0.423
25.40,117.67,-0.423
25.41,117.52,-0.423
25.43,117.37,-0.423
25.44,117.22,-0.423
25.46,117.07,-0.423
25.47,116.92,-0.423
25.49,116.77,-0.422
25.50,116.62,-0.422
25.52,116.47,-0.422
25.53,116.32,-0.422
25.55,116.17,-0.422
25.56,116.02,-0.422
25.58,115.87,-0.422
25.59,115.72,-0.421
25.61,115.57,-0.421
25.62,115.42,-0.421
25.64,115.27,-0.421
25.65,115.12,-0.421
25.67,114.97,-0.421
25.68,114.82,-0.421
25.70,114.67,-0.421
25.71,114.52,-0.421
25.73,114.37,-0.420
25.74,114.22,-0.420
25.76,114.07,-0.420
25.77,113.92,-0.420
25.79,113.77,-0.420
25.80,113.62,-0.420
25.82,113.47,-0.419
25.83,113.32,-0.419
25.85,113.17,-0.419
25.86,113.02,-0.419
25.88,112.87,-0.419
25.89,112.72,-0.419
25.91,112.57,-0.419
25.92,112.42,-0.419
25.94,112.27,-0.418
25.95,112.12,-0.418
25.97,111.97,-0.418
25.98,111.82,-0.418
26.00,111.67,-0.418
26.01,111.52,-0.418
26.03,111.38,-0.418
26.04,111.22,-0.417
26.06,111.08,-0.417
26.07,110.93,-0.417
26.09,110.77,-0.417
26.10,110.63,-0.417
26.12,110.47,-0.417
26.13,110.33,-0.417
26.15,110.18,-0.416
26.16,110.03,-0.416
26.18,109.88,-0.416
26.19,109.73,-0.416
26.21,109.58,-0.416
26.22,109.43,-0.416
26.24,109.28,-0.416
26.25,109.13,-0.415
26.27,108.98,-0.415
26.28,108.83,-0.415
26.30,108.68,-0.415
26.31,108.53,-0.415
26.33,108.38,-0.415
26.34,108.23,-0.415
26.36,108.08,-0.415
26.37,107.93,-0.414
26.39,107.78,-0.414
26.40,107.63,-0.414
26.42,107.48,-0.414
26.43,107.33,-0.414
26.45,107.18,-0.414
26.46,107.03,-0.414
26.48,106.88,-0.414
26.49,106.73,-0.414
26.51,106.58,-0.413
26.52,106.43,-0.413
26.54,106.28,-0.413
26.55,106.13,-0.413
26.57,105.98,-0.413
26.58,105.83,-0.413
26.60,105.68,-0.413
26.61,105.53,-0.413
26.63,105.38,-0.412
26.64,105.23,-0.412
26.66,105.08,-0.412
26.67,104.93,-0.412
26.69,104.78,-0.412
26.70,104.63,-0.412
26.72,104.48,-0.412
26.73,104.33,-0.412
26.75,104.18,-0.412
26.76,104.03,-0.411
26.78,103.88,-0.411
26.79,103.73,-0.411
26.81,103.58,-0.411
26.82,103.43,-0.411
26.84,103.28,-0.411
26.85,103.13,-0.411
26.87,102.98,-0.410
26.88,102.83,-0.410
26.90,102.68,-0.410
26.91,102.53,-0.410
26.93,102.38,-0.410
26.94,102.24,-0.410
26.96,102.08,-0.410
26.97,101.94,-0.410
26.99,101.79,-0.410
27.00,101.64,-0.409
27.02,101.49,-0.409
27.03,101.34,-0.409
27.05,101.19,-0.409
27.06,101.04,-0.409
27.08,100.89,-0.409
27.09,100.74,-0.409
27.11,100.59,-0.409
27.12,100.44,-0.409
27.14,100.29,-0.409
27.15,100.14,-0.408
27.17,99.99,-0.408
27.18,99.84,-0.408
27.20,99.69,-0.408
27.21,99.54,-0.408
27.23,99.39,-0.408
27.24,99.24,-0.408
27.26,99.09,-0.408
27.27,98.94,-0.407
27.29,98.79,-0.407
27.30,98.64,-0.407
27.32,98.49,-0.407
27.33,98.34,-0.407
27.35,98.19,-0.407
27.36,98.04,-0.407
27.38,97.89,-0.407
27.39,97.74,-0.406
27.41,97.59,-0.406
27.42,97.44,-0.406
27.44,97.29,-0.406
27.45,97.14,-0.406
27.47,96.99,-0.406
27.48,96.84,-0.406
27.50,96.69,-0.405
27.51,96.54,-0.405
27.53,96.39,-0.405
27.54,96.24,-0.405
27.56,96.09,-0.405
27.57,95.94,-0.405
27.59,95.79,-0.405
27.60,95.64,-0.405
27.62,95.49,-0.405
27.63,95.34,-0.405
27.65,95.19,-0.404
27.66,95.04,-0.404
27.68,94.89,-0.404
27.69,94.74,-0.404
27.71,94.59,-0.404
27.72,94.44,-0.403
27.74,94.29,-0.403
27.75,94.14,-0.403
27.77,93.99,-0.403
27.78,93.84,-0.403
27.80,93.69,-0.403
27.81,93.54,-0.403
27.83,93.39,-0.403
27.84,93.25,-0.402
27.86,93.09,-0.402
27.87,92.95,-0.402
27.89,92.79,-0.402
27.90,92.65,-0.402
27.92,92.50,-0.402
27.93,92.34,-0.402
27.95,92.20,-0.402
27.96,92.05,-0.401
27.98,91.90,-0.401
27.99,91.75,-0.401
28.01,91.60,-0.401
28.02,91.45,-0.401
28.04,91.30,-0.401
28.05,91.15,-0.401
28.07,91.00,-0.400
28.08,90.85,-0.400
28.10,90.70,-0.400
28.11,90.55,-0.400
28.13,90.40,-0.400
28.14,90.25,-0.400
28.16,90.10,-0.400
28.17,89.95,-0.399
28.19,89.80,-0.399
28.20,89.65,-0.399
28.22,89.50,-0.399
28.23,89.35,-0.399
28.25,89.20,-0.399
28.26,89.05,-0.399
28.28,88.90,-0.399
28.29,88.75,-0.399
28.31,88.60,-0.398
28.32,88.45,-0.398
28.34,88.30,-0.398
28.35,88.15,-0.398
28.37,88.00,-0.398
28.38,87.85,-0.398
[...]
93.05,-11.08,0.271
93.06,-10.93,0.271
93.08,-10.78,0.271
93.09,-10.63,0.271
93.11,-10.48,0.271
93.12,-10.33,0.271
93.14,-10.18,0.271
93.15,-10.03,0.271
93.17,-9.88,0.271
93.18,-9.73,0.269
93.20,-9.58,0.269
93.21,-9.43,0.267
93.23,-9.28,0.266
93.24,-9.13,0.264
93.26,-8.98,0.263
93.27,-8.83,0.262
93.29,-8.67,0.260
93.30,-8.53,0.260
93.32,-8.37,0.259
93.33,-8.22,0.258
93.35,-8.07,0.256
93.36,-7.92,0.256
93.38,-7.77,0.255
93.39,-7.62,0.255
93.41,-7.47,0.255
93.42,-7.32,0.254
93.44,-7.17,0.254
93.45,-7.02,0.254
93.47,-6.87,0.253
93.48,-6.72,0.253
93.50,-6.57,0.253
93.51,-6.42,0.252
93.53,-6.27,0.252
93.54,-6.12,0.252
93.56,-5.97,0.252
93.57,-5.82,0.252
93.59,-5.67,0.251
93.60,-5.52,0.251
93.62,-5.37,0.251
93.63,-5.22,0.251
93.65,-5.07,0.251
93.66,-4.92,0.250
93.68,-4.77,0.250
93.69,-4.61,0.250
93.71,-4.47,0.250
93.72,-4.32,0.250
93.74,-4.17,0.250
93.75,-4.01,0.250
93.77,-3.86,0.249
93.78,-3.71,0.249
93.80,-3.56,0.249
93.81,-3.41,0.249
93.83,-3.26,0.249
93.84,-3.11,0.249
93.86,-2.96,0.249
93.87,-2.81,0.249
93.89,-2.66,0.249
93.90,-2.51,0.249
93.92,-2.36,0.249
93.93,-2.21,0.249
93.95,-2.06,0.249
93.96,-1.91,0.249
93.98,-1.76,0.249
93.99,-1.61,0.249
94.01,-1.46,0.249
94.02,-1.31,0.249
94.04,-1.16,0.249
94.05,-1.01,0.249
94.07,-0.86,0.249
94.08,-0.71,0.249
94.10,-0.56,0.249
94.11,-0.41,0.249
94.13,-0.26,0.249
94.14,-0.11,0.249
94.16,0.04,0.249
94.17,0.19,0.249
94.19,0.34,0.250
94.20,0.49,0.250
94.22,0.64,0.250
94.23,0.79,0.250
94.25,0.94,0.250
94.26,1.09,0.250
94.28,1.24,0.250
94.29,1.39,0.250
94.31,1.54,0.250
94.32,1.69,0.250
94.34,1.85,0.250
94.35,1.99,0.250
94.37,2.14,0.250
94.38,2.30,0.250
94.40,2.45,0.250
94.41,2.59,0.250
94.43,2.75,0.250
94.44,2.90,0.250
94.46,3.05,0.250
94.47,3.20,0.250
94.49,3.35,0.251
94.50,3.50,0.251
94.52,3.65,0.251
94.53,3.80,0.251
94.55,3.95,0.251
94.56,4.10,0.251
94.58,4.25,0.251
94.59,4.40,0.251
94.61,4.55,0.251
94.62,4.70,0.251
94.64,4.85,0.251
94.65,5.00,0.252
94.67,5.15,0.252
94.68,5.30,0.252
94.70,5.45,0.252
94.71,5.60,0.252
94.73,5.75,0.252
94.74,5.90,0.252
94.76,6.05,0.252
94.77,6.20,0.252
94.79,6.35,0.252
94.80,6.50,0.252
94.82,6.65,0.252
94.83,6.80,0.252
94.85,6.95,0.253
94.86,7.10,0.253
94.88,7.25,0.253
94.89,7.40,0.253
94.91,7.55,0.253
94.92,7.70,0.253
94.94,7.85,0.253
94.95,8.00,0.253
94.97,8.15,0.253
94.98,8.30,0.253
95.00,8.45,0.253
95.01,8.60,0.253
95.03,8.75,0.253
95.04,8.90,0.254
95.06,9.05,0.254
95.07,9.21,0.254
95.09,9.35,0.254
95.10,9.51,0.254
95.12,9.65,0.254
95.13,9.80,0.254
95.15,9.95,0.254
95.16,10.11,0.254
95.18,10.26,0.254
95.19,10.41,0.254
95.21,10.56,0.254
95.22,10.71,0.254
95.24,10.86,0.255
95.25,11.01,0.255
95.27,11.16,0.255
95.28,11.31,0.255
95.30,11.46,0.255
95.31,11.61,0.255
95.33,11.76,0.255
95.34,11.91,0.255
95.36,12.06,0.255
95.37,12.21,0.255
95.39,12.36,0.256
95.40,12.51,0.256
95.42,12.66,0.256
95.43,12.81,0.256
95.45,12.96,0.256
95.46,13.11,0.256
95.48,13.26,0.256
95.49,13.41,0.256
95.51,13.56,0.256
95.52,13.71,0.256
95.54,13.86,0.257
95.55,14.01,0.257
95.57,14.16,0.257
95.58,14.31,0.257
95.60,14.46,0.257
95.61,14.61,0.257
95.63,14.76,0.257
95.64,14.91,0.257
95.66,15.06,0.257
95.67,15.21,0.257
95.69,15.36,0.257
95.70,15.51,0.258
95.72,15.66,0.258
95.73,15.81,0.258
95.75,15.96,0.258
95.76,16.11,0.258
95.78,16.26,0.258
95.79,16.41,0.258
95.81,16.56,0.258
95.82,16.71,0.258
95.84,16.86,0.259
95.85,17.01,0.259
95.87,17.16,0.259
95.88,17.31,0.259
95.90,17.46,0.259
95.91,17.61,0.259
95.93,17.76,0.259
95.94,17.91,0.260
95.96,18.06,0.260
95.97,18.22,0.260
95.99,18.37,0.260
96.00,18.52,0.260
96.02,18.67,0.260
96.03,18.82,0.260
96.05,18.97,0.260
96.06,19.12,0.261
96.08,19.27,0.261
96.09,19.42,0.261
96.11,19.57,0.261
96.12,19.72,0.261
96.14,19.87,0.261
96.15,20.02,0.261
96.17,20.17,0.261
96.18,20.32,0.261
96.20,20.47,0.261
96.21,20.62,0.261
96.23,20.77,0.262
96.24,20.92,0.262
96.26,21.07,0.262
96.27,21.22,0.262
96.29,21.37,0.262
96.30,21.52,0.262
96.32,21.67,0.262
96.33,21.82,0.262
96.35,21.97,0.263
96.36,22.12,0.263
96.38,22.27,0.263
96.39,22.42,0.263
96.41,22.57,0.263
96.42,22.72,0.263
96.44,22.87,0.263
96.45,23.02,0.263
96.47,23.17,0.263
96.48,23.32,0.264
96.50,23.47,0.264
96.51,23.62,0.264
96.53,23.77,0.264
96.54,23.92,0.264
96.56,24.07,0.264
96.57,24.22,0.264
96.59,24.37,0.264
96.60,24.52,0.264
96.62,24.67,0.264
96.63,24.82,0.265
96.65,24.97,0.265
96.66,25.12,0.265
96.68,25.27,0.265
96.69,25.42,0.265
96.71,25.57,0.265
96.72,25.72,0.265
96.74,25.88,0.265
96.75,26.02,0.265
96.77,26.17,0.266
96.78,26.33,0.266
96.80,26.47,0.266
96.81,26.63,0.266
96.83,26.78,0.266
96.84,26.93,0.266
96.86,27.08,0.266
96.87,27.23,0.266
96.89,27.38,0.266
96.90,27.53,0.267
96.92,27.68,0.267
96.93,27.83,0.267
96.95,27.98,0.267
96.96,28.13,0.267
96.98,28.28,0.267
96.99,28.43,0.267
97.01,28.58,0.267
97.02,28.73,0.267
97.04,28.88,0.268
97.05,29.03,0.268
97.07,29.18,0.268
97.08,29.33,0.268
97.10,29.48,0.268
97.11,29.63,0.268
97.13,29.78,0.268
97.14,29.93,0.268
97.16,30.08,0.268
97.17,30.23,0.268
97.19,30.38,0.268
97.20,30.53,0.269
97.22,30.68,0.269
97.23,30.83,0.269
97.25,30.98,0.269
97.26,31.13,0.269
97.28,31.28,0.269
97.29,31.43,0.269
97.31,31.58,0.269
97.32,31.73,0.269
97.34,31.88,0.269
97.35,32.03,0.270
97.37,32.18,0.270
97.38,32.33,0.270
97.40,32.48,0.270
97.41,32.63,0.270
97.43,32.78,0.270
97.44,32.93,0.270
97.46,33.08,0.270
97.47,33.23,0.270
97.49,33.38,0.270
97.50,33.53,0.270
97.52,33.68,0.271
97.53,33.83,0.271
97.55,33.98,0.271
97.56,34.13,0.271
97.58,34.28,0.271
97.59,34.43,0.271
97.61,34.58,0.271
97.62,34.73,0.271
97.64,34.88,0.271
97.65,35.03,0.271
97.67,35.18,0.271
97.68,35.33,0.271
97.70,35.48,0.272
97.71,35.63,0.272
97.73,35.78,0.272
97.74,35.93,0.272
97.76,36.09,0.272
97.77,36.24,0.272
97.79,36.39,0.272
97.80,36.54,0.272
97.82,36.69,0.272
97.83,36.84,0.273
97.85,36.99,0.273
97.86,37.14,0.273
97.88,37.29,0.273
97.89,37.44,0.273
97.91,37.59,0.273
97.92,37.74,0.273
97.94,37.89,0.273
97.95,38.04,0.273
97.97,38.19,0.273
97.98,38.34,0.274
98.00,38.49,0.274
98.01,38.64,0.274
98.03,38.79,0.274
98.04,38.94,0.274
98.06,39.09,0.274
98.07,39.24,0.274
98.09,39.39,0.274
98.10,39.54,0.274
98.12,39.69,0.274
98.13,39.84,0.275
98.15,39.99,0.275
98.16,40.14,0.275
98.18,40.29,0.275
98.19,40.44,0.275
98.21,40.59,0.275
98.22,40.74,0.275
98.24,40.89,0.275
98.25,41.04,0.275
98.27,41.19,0.276
98.28,41.34,0.276
98.30,41.49,0.276
98.31,41.64,0.276
98.33,41.79,0.276
98.34,41.94,0.276
98.36,42.09,0.276
98.37,42.24,0.276
98.39,42.39,0.276
98.40,42.54,0.276
98.42,42.69,0.276
98.43,42.84,0.277
98.45,42.99,0.277
98.46,43.14,0.277
98.48,43.29,0.277
98.49,43.44,0.277
98.51,43.59,0.277
98.52,43.75,0.277
98.54,43.90,0.277
98.55,44.04,0.277
98.57,44.19,0.277
98.58,44.35,0.278
98.60,44.50,0.278
98.61,44.65,0.278
98.63,44.80,0.278
98.64,44.95,0.278
98.66,45.10,0.278
98.67,45.25,0.278
98.69,45.40,0.278
98.70,45.55,0.278
98.72,45.70,0.278
98.73,45.85,0.279
98.75,46.00,0.279
98.76,46.15,0.279
98.78,46.30,0.279
98.79,46.45,0.279
98.81,46.60,0.279
98.82,46.75,0.279
98.84,46.90,0.279
98.85,47.05,0.279
98.87,47.20,0.279
98.88,47.35,0.279
98.90,47.50,0.280
98.91,47.65,0.280
98.93,47.80,0.280
98.94,47.95,0.280
98.96,48.10,0.280
98.97,48.25,0.280
98.99,48.40,0.280
99.00,48.55,0.280
99.02,48.70,0.280
99.03,48.85,0.280
99.05,49.00,0.280
99.06,49.15,0.281
99.08,49.30,0.281
99.09,49.45,0.281
99.11,49.60,0.281
99.12,49.75,0.281
99.14,49.90,0.281
99.15,50.05,0.281
99.17,50.20,0.281
99.18,50.35,0.281
99.20,50.50,0.281
99.21,50.65,0.281
99.23,50.80,0.282
99.24,50.95,0.282
99.26,51.10,0.282
99.27,51.25,0.282
99.29,51.40,0.282
99.30,51.55,0.282
99.32,51.70,0.282
99.33,51.85,0.282
99.35,52.00,0.282
99.36,52.15,0.282
99.38,52.30,0.282
99.39,52.45,0.282
99.41,52.60,0.282
99.42,52.75,0.283
99.44,52.90,0.283
99.45,53.05,0.283
99.47,53.20,0.283
99.48,53.36,0.283
99.50,53.51,0.283
99.51,53.66,0.283
99.53,53.81,0.283
99.54,53.96,0.283
99.56,54.11,0.283
99.57,54.26,0.283
99.59,54.41,0.283
99.60,54.56,0.283
99.62,54.71,0.284
99.63,54.86,0.284
99.65,55.01,0.284
99.66,55.16,0.284
99.68,55.31,0.284
99.69,55.46,0.284
99.71,55.61,0.284
99.72,55.76,0.284
99.74,55.91,0.284
99.75,56.06,0.284
99.77,56.21,0.285
99.78,56.36,0.285
99.80,56.51,0.285
99.81,56.66,0.285
99.83,56.81,0.285
99.84,56.96,0.285
99.86,57.11,0.285
99.87,57.26,0.285
99.89,57.41,0.285
99.90,57.56,0.285
99.92,57.71,0.285
99.93,57.86,0.286
99.95,58.01,0.286
99.96,58.16,0.286
99.98,58.31,0.286
99.99,58.46,0.286
100.01,58.61,0.286
100.02,58.76,0.286
100.04,58.91,0.286
100.05,59.06,0.286
100.07,59.21,0.286
100.08,59.36,0.287
100.10,59.51,0.287
100.11,59.66,0.287
100.13,59.81,0.287
100.14,59.96,0.287
100.16,60.11,0.287
100.17,60.26,0.287
100.19,60.41,0.287
100.20,60.56,0.287
100.22,60.71,0.287
100.23,60.86,0.287
100.25,61.01,0.288
100.26,61.16,0.288
100.28,61.31,0.288
100.29,61.46,0.288
100.31,61.61,0.288
100.32,61.76,0.288
100.34,61.91,0.288
100.35,62.06,0.288
100.37,62.21,0.288
100.38,62.36,0.288
100.40,62.52,0.288
100.41,62.66,0.288
100.43,62.81,0.288
100.44,62.96,0.289
100.46,63.12,0.289
100.47,63.27,0.289
100.49,63.42,0.289
100.50,63.57,0.289
100.52,63.72,0.289
100.53,63.87,0.289
100.55,64.02,0.289
100.56,64.17,0.289
100.58,64.32,0.289
100.59,64.47,0.289
100.61,64.62,0.290
100.62,64.77,0.290
100.64,64.92,0.290
100.65,65.07,0.290
100.67,65.22,0.290
100.68,65.37,0.290
100.70,65.52,0.290
100.71,65.67,0.290
100.73,65.82,0.290
100.74,65.97,0.290
100.76,66.12,0.290
100.77,66.27,0.290
100.79,66.42,0.290
100.80,66.57,0.291
100.82,66.72,0.291
100.83,66.87,0.291
100.85,67.02,0.291
100.86,67.17,0.291
100.88,67.32,0.291
100.89,67.47,0.291
100.91,67.62,0.291
100.92,67.77,0.291
100.94,67.92,0.291
100.95,68.07,0.291
100.97,68.22,0.291
100.98,68.37,0.291
101.00,68.52,0.292
101.01,68.67,0.292
101.03,68.82,0.292
101.04,68.97,0.292
101.06,69.12,0.292
101.07,69.27,0.292
101.09,69.42,0.292
101.10,69.57,0.292
101.12,69.72,0.292
101.13,69.87,0.292
101.15,70.02,0.292
101.16,70.17,0.293
101.18,70.32,0.293
101.19,70.47,0.293
101.21,70.62,0.293
101.22,70.77,0.293
101.24,70.92,0.293
101.25,71.07,0.293
101.27,71.22,0.293
101.28,71.38,0.293
101.30,71.52,0.293
101.31,71.67,0.293
101.33,71.82,0.293
101.34,71.98,0.294
101.36,72.12,0.294
101.37,72.28,0.294
101.39,72.43,0.294
101.40,72.57,0.294
101.42,72.73,0.294
101.43,72.88,0.294
101.45,73.03,0.294
101.46,73.18,0.294
101.48,73.33,0.294
101.49,73.48,0.294
101.51,73.63,0.294
101.52,73.78,0.295
101.54,73.93,0.295
101.55,74.08,0.295
101.57,74.23,0.295
101.58,74.38,0.295
101.60,74.53,0.295
101.61,74.68,0.295
101.63,74.83,0.295
101.64,74.98,0.295
101.66,75.13,0.295
101.67,75.28,0.295
101.69,75.43,0.295
101.70,75.58,0.295
101.72,75.73,0.296
101.73,75.88,0.296
101.75,76.03,0.296
101.76,76.18,0.296
101.78,76.33,0.296
101.79,76.48,0.296
101.81,76.63,0.296
101.82,76.78,0.296
101.84,76.93,0.296
101.85,77.08,0.296
101.87,77.23,0.296
101.88,77.38,0.296
101.90,77.53,0.296
101.91,77.68,0.296
101.93,77.83,0.297
101.94,77.98,0.297
101.96,78.13,0.297
101.97,78.28,0.297
101.99,78.43,0.297
102.00,78.58,0.297
102.02,78.73,0.297
102.03,78.88,0.297
102.05,79.03,0.297
102.06,79.18,0.297
102.08,79.33,0.297
102.09,79.48,0.297
102.11,79.63,0.298
102.12,79.78,0.298
102.14,79.93,0.298
102.15,80.08,0.298
102.17,80.23,0.298
102.18,80.38,0.298
102.20,80.53,0.298
102.21,80.68,0.298
102.23,80.83,0.298
102.24,80.98,0.298
102.26,81.13,0.298
102.27,81.28,0.298
102.29,81.43,0.298
102.30,81.58,0.298
102.32,81.74,0.298
102.33,81.88,0.298
102.35,82.03,0.298
102.36,82.19,0.298
102.38,82.34,0.299
102.39,82.49,0.299
102.41,82.63,0.299
102.42,82.79,0.299
102.44,82.94,0.299
102.45,83.09,0.299
102.47,83.24,0.299
102.48,83.39,0.299
102.50,83.54,0.299
102.51,83.69,0.299
102.53,83.84,0.299
102.54,83.99,0.299
102.56,84.14,0.299
102.57,84.29,0.299
102.59,84.44,0.299
102.60,84.59,0.299
102.62,84.74,0.299
102.63,84.89,0.299
102.65,85.04,0.299
102.66,85.19,0.299
102.68,85.34,0.299
102.69,85.49,0.299
102.71,85.64,0.300
102.72,85.79,0.300
102.74,85.94,0.300
102.75,86.09,0.300
102.77,86.24,0.300
102.78,86.39,0.300
102.80,86.54,0.300
102.81,86.69,0.300
102.83,86.84,0.300
102.84,86.99,0.300
102.86,87.14,0.300
102.87,87.29,0.300
102.89,87.44,0.300
102.90,87.59,0.300
102.92,87.74,0.301
102.93,87.89,0.301
102.95,88.04,0.301
102.96,88.19,0.301
102.98,88.34,0.301
102.99,88.49,0.301
103.01,88.64,0.301
103.02,88.79,0.301
103.04,88.94,0.301
103.05,89.09,0.301
103.07,89.24,0.301
103.08,89.39,0.301
103.10,89.54,0.301
103.11,89.69,0.302
103.13,89.84,0.302
103.14,89.99,0.302
103.16,90.14,0.302
103.17,90.29,0.302
103.19,90.44,0.302
103.20,90.59,0.302
103.22,90.74,0.302
103.23,90.89,0.302
103.25,91.04,0.302
103.26,91.19,0.303
103.28,91.34,0.303
103.29,91.49,0.303
103.31,91.64,0.303
103.32,91.79,0.303
103.34,91.94,0.303
103.35,92.09,0.303
103.37,92.24,0.303
103.38,92.39,0.303
103.40,92.54,0.303
103.41,92.69,0.303
103.43,92.84,0.304
103.44,92.99,0.304
103.46,93.14,0.304
103.47,93.30,0.304
103.49,93.45,0.304
103.50,93.60,0.304
103.52,93.75,0.304
103.53,93.90,0.304
103.55,94.05,0.304
103.56,94.20,0.304
103.58,94.35,0.304
103.59,94.50,0.305
103.61,94.65,0.305
103.62,94.80,0.305
103.64,94.95,0.305
103.65,95.10,0.305
103.67,95.25,0.305
103.68,95.40,0.305
103.70,95.55,0.305
103.71,95.70,0.305
103.73,95.85,0.305
103.74,96.00,0.305
103.76,96.15,0.305
103.77,96.30,0.305
103.79,96.45,0.305
103.80,96.60,0.306
103.82,96.75,0.306
103.83,96.90,0.306
103.85,97.05,0.306
103.86,97.20,0.306
103.88,97.35,0.306
103.89,97.50,0.306
103.91,97.65,0.306
103.92,97.80,0.306
103.94,97.95,0.306
103.95,98.10,0.306
103.97,98.25,0.306
103.98,98.40,0.306
104.00,98.55,0.307
104.01,98.70,0.307
104.03,98.85,0.307
104.04,99.00,0.307
104.06,99.15,0.307
104.07,99.30,0.307
104.09,99.45,0.307
104.10,99.60,0.307
104.12,99.75,0.307
104.13,99.90,0.307
104.15,100.05,0.307
104.16,100.20,0.307
104.18,100.35,0.307
104.19,100.50,0.307
104.21,100.65,0.308
104.22,100.80,0.308
104.24,100.95,0.308
104.25,101.10,0.308
104.27,101.25,0.308
104.28,101.40,0.308
104.30,101.55,0.308
104.31,101.70,0.308
104.33,101.86,0.308
104.34,102.01,0.308
104.36,102.16,0.308
104.37,102.31,0.308
104.39,102.46,0.308
104.40,102.61,0.308
104.42,102.76,0.309
104.43,102.91,0.309
104.45,103.06,0.309
104.46,103.21,0.309
104.48,103.36,0.309
104.49,103.51,0.309
104.51,103.66,0.309
104.52,103.81,0.309
104.54,103.96,0.309
104.55,104.11,0.309
104.57,104.26,0.309
104.58,104.41,0.309
104.60,104.56,0.309
104.61,104.71,0.309
104.63,104.86,0.309
104.64,105.01,0.310
104.66,105.16,0.310
104.67,105.31,0.310
104.69,105.46,0.310
104.70,105.61,0.310
104.72,105.76,0.310
104.73,105.91,0.310
104.75,106.06,0.310
104.76,106.21,0.310
104.78,106.36,0.310
104.79,106.51,0.310
104.81,106.66,0.310
104.82,106.81,0.310
104.84,106.96,0.310
104.85,107.11,0.310
104.87,107.26,0.310
104.88,107.41,0.310
104.90,107.56,0.310
104.91,107.71,0.311
104.93,107.86,0.311
104.94,108.01,0.311
104.96,108.16,0.311
104.97,108.31,0.311
104.99,108.46,0.311
105.00,108.61,0.311
105.02,108.76,0.311
105.03,108.91,0.311
105.05,109.06,0.311
105.06,109.21,0.311
105.08,109.36,0.311
105.09,109.51,0.311
105.11,109.66,0.311
105.12,109.82,0.311
105.14,109.96,0.311
105.15,110.12,0.311
105.17,110.27,0.312
105.18,110.42,0.312
105.20,110.57,0.312
105.21,110.72,0.312
105.23,110.87,0.312
105.24,111.02,0.312
105.26,111.17,0.312
105.27,111.32,0.312
105.29,111.47,0.312
105.30,111.62,0.312
105.32,111.77,0.312
105.33,111.92,0.312
105.35,112.07,0.312
105.36,112.22,0.312
105.38,112.37,0.312
105.39,112.52,0.313
105.41,112.67,0.313
105.42,112.82,0.313
105.44,112.97,0.313
105.45,113.12,0.313
105.47,113.27,0.313
105.48,113.42,0.313
105.50,113.57,0.313
105.51,113.72,0.313
105.53,113.87,0.313
105.54,114.02,0.313
105.56,114.17,0.313
105.57,114.32,0.313
105.59,114.47,0.313
105.60,114.62,0.313
105.62,114.77,0.313
105.63,114.92,0.313
105.65,115.07,0.313
105.66,115.22,0.313
105.68,115.37,0.313
105.69,115.52,0.313
105.71,115.67,0.313
105.72,115.82,0.314
105.74,115.97,0.314
105.75,116.12,0.314
105.77,116.27,0.314
105.78,116.42,0.314
105.80,116.57,0.314
105.81,116.72,0.314
105.83,116.87,0.314
105.84,117.02,0.314
105.86,117.17,0.314
105.87,117.32,0.314
105.89,117.47,0.314
105.90,117.62,0.314
105.92,117.77,0.314
105.93,117.92,0.314
105.95,118.07,0.314
105.96,118.22,0.314
105.98,118.37,0.314
105.99,118.52,0.314
106.01,118.67,0.314
106.02,118.82,0.314
106.04,118.97,0.314
106.05,119.12,0.314
106.07,119.27,0.314
106.08,119.42,0.314
106.10,119.57,0.314
106.11,119.72,0.314
106.13,119.87,0.315
106.14,120.02,0.315
106.16,120.17,0.315
106.17,120.32,0.315
106.19,120.47,0.315
106.20,120.62,0.315
106.22,120.77,0.315
106.23,120.92,0.315
106.25,121.07,0.315
106.26,121.22,0.315
106.28,121.37,0.315
106.29,121.52,0.315
106.31,121.67,0.315
106.32,121.82,0.315
106.34,121.97,0.315
106.35,122.12,0.315
106.37,122.27,0.315
106.38,122.42,0.315
106.40,122.57,0.315
106.41,122.72,0.315
106.43,122.87,0.315
106.44,123.02,0.315
106.46,123.17,0.315
106.47,123.32,0.315
106.49,123.47,0.315
106.50,123.62,0.315
106.52,123.77,0.315
106.53,123.93,0.315
106.55,124.08,0.315
106.56,124.23,0.315
106.58,124.37,0.315
106.59,124.52,0.315
106.61,124.68,0.315
106.62,124.83,0.315
106.64,124.98,0.315
106.65,125.13,0.315
106.67,125.28,0.316
106.68,125.43,0.316
106.70,125.58,0.316
106.71,125.73,0.316
106.73,125.88,0.316
106.74,126.03,0.316
106.76,126.18,0.316
106.77,126.33,0.316
106.79,126.48,0.316
106.80,126.63,0.316
106.82,126.78,0.316
106.83,126.93,0.316
106.85,127.08,0.316
106.86,127.23,0.316
106.88,127.38,0.316
106.89,127.53,0.316
106.91,127.68,0.316
106.92,127.83,0.316
106.94,127.98,0.316
106.95,128.13,0.316
106.97,128.28,0.316
106.98,128.43,0.316
107.00,128.58,0.316
107.01,128.73,0.316
107.03,128.88,0.316
107.04,129.03,0.316
107.06,129.18,0.316
107.07,129.33,0.316
107.09,129.48,0.316
107.10,129.63,0.316
107.12,129.78,0.316
107.13,129.93,0.316
107.15,130.08,0.316
107.16,130.23,0.316
107.18,130.38,0.316
107.19,130.53,0.316
107.21,130.68,0.316
107.22,130.83,0.316
107.24,130.98,0.316
107.25,131.13,0.316
107.27,131.28,0.316
107.28,131.43,0.316
107.30,131.58,0.316
107.31,131.73,0.316
107.33,131.88,0.316
107.34,132.03,0.316
107.36,132.18,0.316
107.37,132.33,0.316
107.39,132.48,0.316
107.40,132.63,0.316
107.42,132.78,0.316
107.43,132.93,0.316
107.45,133.08,0.316
107.46,133.23,0.316
107.48,133.38,0.316
107.49,133.53,0.316
107.51,133.68,0.316
107.52,133.83,0.316
107.54,133.99,0.316
107.55,134.14,0.316
107.57,134.29,0.316
107.58,134.43,0.316
107.60,134.59,0.316
107.61,134.73,0.316
107.63,134.89,0.316
107.64,135.04,0.316
107.66,135.19,0.316
107.67,135.34,0.316
107.69,135.49,0.316
107.70,135.64,0.316
107.72,135.79,0.316
107.73,135.94,0.316
107.75,136.09,0.316
107.76,136.24,0.316
107.78,136.39,0.316
107.79,136.54,0.316
107.81,136.69,0.316
107.82,136.84,0.316
107.84,136.99,0.316
107.85,137.14,0.316
107.87,137.29,0.316
107.88,137.44,0.316
107.90,137.59,0.316
107.91,137.74,0.316
107.93,137.89,0.316
107.94,138.04,0.316
107.96,138.19,0.316
107.97,138.34,0.316
107.99,138.49,0.316
108.00,138.64,0.316
108.02,138.79,0.316
108.03,138.94,0.316
108.05,139.09,0.316
108.06,139.24,0.316
108.08,139.39,0.316
108.09,139.54,0.316
108.11,139.69,0.316
108.12,139.84,0.316
108.14,139.99,0.315
108.15,140.14,0.315
108.17,140.29,0.315
108.18,140.44,0.315
108.20,140.59,0.315
108.21,140.74,0.315
108.23,140.90,0.315
108.24,141.05,0.315
108.26,141.20,0.315
108.27,141.35,0.315
108.29,141.50,0.315
108.30,141.65,0.315
108.32,141.80,0.316
108.33,141.96,0.316
108.35,142.10,0.316
108.36,142.25,0.316
108.38,142.41,0.316
108.39,142.56,0.316
108.41,142.71,0.316
108.42,142.85,0.315
108.44,143.00,0.315
108.45,143.16,0.315
108.47,143.30,0.315
108.48,143.45,0.315
108.50,143.60,0.315
108.51,143.75,0.315
108.53,143.90,0.314
108.54,144.05,0.314
108.56,144.20,0.314
108.57,144.35,0.314
108.59,144.50,0.314
108.60,144.65,0.313
108.62,144.80,0.313
108.63,144.95,0.313
108.65,145.10,0.313
108.66,145.25,0.313
108.68,145.40,0.313
108.69,145.55,0.313
108.71,145.70,0.312
108.72,145.85,0.312
108.74,146.00,0.312
108.75,146.15,0.312
108.77,146.30,0.312
108.78,146.45,0.312
108.80,146.60,0.312
108.81,146.75,0.311
108.83,146.90,0.311
108.84,147.05,0.311
108.86,147.20,0.311
108.87,147.35,0.311
108.89,147.50,0.311
108.90,147.65,0.311
108.92,147.80,0.311
108.93,147.95,0.311
108.95,148.10,
108.96,148.25,
108.98,148.40,
108.99,,