File: XRD/2025_06_03_CBD_3_60_8min.csv
[Measurement conditions]
Sample identification,2025_06_03_CBD_3_60_8min
Comment - 1,"Crystalline CBD Standard"
Anode material,Cu
K-Alpha1 wavelength,1.5405980
K-Alpha2 wavelength,1.5444260
Ratio K-Alpha2/K-Alpha1,0.500
Divergence slit,Fixed,0.76mm
Monochromator used,NO
Generator voltage, 40
Tube current, 15
File date and time,03/Jun/2025 15:14
Unit cell,
h k l, 0 0 0
Scan axis,Gonio
Scan range,2.995000000,60.000344240
Scan step size,0.0108664
No. of points, 5246
Scan type,CONTINUOUS
Time per step,18.870
[Scan points]
Angle, TimePerStep, Intensity, ESD
3.000433220, 18.870, 43855.0, 209.4159
3.043898980, 18.870, 41588.0, 203.9314
3.087364740, 18.870, 39528.0, 198.8165
3.130830500, 18.870, 37677.0, 194.1056
3.174296260, 18.870, 35630.0, 188.7591
3.217762020, 18.870, 33357.0, 182.6390
3.261227780, 18.870, 31845.0, 178.4517
3.304693540, 18.870, 30003.0, 173.2137
3.348159300, 18.870, 28187.0, 167.8898
3.391625060, 18.870, 26776.0, 163.6337
3.435090820, 18.870, 24965.0, 158.0032
3.478556580, 18.870, 23674.0, 153.8636
3.522022340, 18.870, 22418.0, 149.7264
3.565488100, 18.870, 20620.0, 143.5967
3.608953860, 18.870, 19615.0, 140.0536
3.652419620, 18.870, 18232.0, 135.0259
3.695885380, 18.870, 17309.0, 131.5637
3.739351140, 18.870, 16173.0, 127.1731
3.782816900, 18.870, 15082.0, 122.8088
3.826282660, 18.870, 13979.0, 118.2328
3.869748420, 18.870, 13078.0, 114.3591
3.913214180, 18.870, 12219.0, 110.5396
3.956679940, 18.870, 11413.0, 106.8316
4.000145700, 18.870, 10608.0, 102.9951
4.043611460, 18.870, 9826.0, 99.1262
4.087077220, 18.870, 8989.0, 94.8103
4.130542980, 18.870, 8447.0, 91.9076
4.174008740, 18.870, 7784.0, 88.2270
4.217474500, 18.870, 7086.0, 84.1784
4.260940260, 18.870, 6696.0, 81.8291
4.304406020, 18.870, 6200.0, 78.7401
4.347871780, 18.870, 5699.0, 75.4917
4.391337540, 18.870, 5206.0, 72.1526
4.434803300, 18.870, 4789.0, 69.2026
4.478269060, 18.870, 4487.0, 66.9851
4.521734820, 18.870, 4080.0, 63.8749
4.565200580, 18.870, 3771.0, 61.4085
4.608666340, 18.870, 3439.0, 58.6430
4.652132100, 18.870, 3198.0, 56.5509
4.695597860, 18.870, 3047.0, 55.1996
4.739063620, 18.870, 2921.0, 54.0463
4.782529380, 18.870, 2692.0, 51.8845
4.825995140, 18.870, 2597.0, 50.9608
4.869460900, 18.870, 2534.0, 50.3389
4.912926660, 18.870, 2421.0, 49.2037
4.956392420, 18.870, 2533.0, 50.3289
4.999858180, 18.870, 2633.0, 51.3128
5.043323940, 18.870, 2919.0, 54.0278
5.086789700, 18.870, 3068.0, 55.3895
5.130255460, 18.870, 2948.0, 54.2955
5.173721220, 18.870, 2871.0, 53.5817
5.217186980, 18.870, 2660.0, 51.5752
5.260652740, 18.870, 2438.0, 49.3761
5.304118500, 18.870, 2231.0, 47.2335
5.347584260, 18.870, 2134.0, 46.1952
5.391050020, 18.870, 2173.0, 46.6154
5.434515780, 18.870, 2003.0, 44.7549
5.477981540, 18.870, 1941.0, 44.0568
5.521447300, 18.870, 1868.0, 43.2204
5.564913060, 18.870, 1719.0, 41.4608
5.608378820, 18.870, 1637.0, 40.4599
5.651844580, 18.870, 1552.0, 39.3954
5.695310340, 18.870, 1425.0, 37.7492
5.738776100, 18.870, 1369.0, 37.0000
5.782241860, 18.870, 1339.0, 36.5923
5.825707620, 18.870, 1373.0, 37.0540
5.869173380, 18.870, 1304.0, 36.1109
5.912639140, 18.870, 1304.0, 36.1109
5.956104900, 18.870, 1317.0, 36.2905
5.999570660, 18.870, 1274.0, 35.6931
6.043036420, 18.870, 1214.0, 34.8425
6.086502180, 18.870, 1161.0, 34.0735
6.129967940, 18.870, 1206.0, 34.7275
6.173433700, 18.870, 1210.0, 34.7851
6.216899460, 18.870, 1184.0, 34.4093
6.260365220, 18.870, 1221.0, 34.9428
6.303830980, 18.870, 1096.0, 33.1059
6.347296740, 18.870, 1153.0, 33.9559
6.390762500, 18.870, 1126.0, 33.5559
6.434228260, 18.870, 1121.0, 33.4813
6.477694020, 18.870, 1112.0, 33.3467
6.521159780, 18.870, 1083.0, 32.9090
6.564625540, 18.870, 1032.0, 32.1248
6.608091300, 18.870, 1053.0, 32.4500
6.651557060, 18.870, 1071.0, 32.7261
6.695022820, 18.870, 992.0, 31.4960
6.738488580, 18.870, 985.0, 31.3847
6.781954340, 18.870, 983.0, 31.3528
6.825420100, 18.870, 937.0, 30.6105
6.868885860, 18.870, 939.0, 30.6431
6.912351620, 18.870, 984.0, 31.3688
6.955817380, 18.870, 934.0, 30.5614
6.999283140, 18.870, 956.0, 30.9192
7.042748900, 18.870, 932.0, 30.5287
7.086214660, 18.870, 933.0, 30.5450
7.129680420, 18.870, 943.0, 30.7083
7.173146180, 18.870, 925.0, 30.4138
7.216611940, 18.870, 871.0, 29.5127
7.260077700, 18.870, 897.0, 29.9500
7.303543460, 18.870, 927.0, 30.4467
7.347009220, 18.870, 837.0, 28.9310
7.390474980, 18.870, 855.0, 29.2404
7.433940740, 18.870, 833.0, 28.8617
7.477406500, 18.870, 859.0, 29.3087
7.520872260, 18.870, 844.0, 29.0517
7.564338020, 18.870, 870.0, 29.4958
7.607803780, 18.870, 887.0, 29.7825
7.651269540, 18.870, 873.0, 29.5466
7.694735300, 18.870, 834.0, 28.8791
7.738201060, 18.870, 851.0, 29.1719
7.781666820, 18.870, 802.0, 28.3196
7.825132580, 18.870, 832.0, 28.8444
7.868598340, 18.870, 894.0, 29.8998
7.912064100, 18.870, 885.0, 29.7489
7.955529860, 18.870, 890.0, 29.8329
7.998995620, 18.870, 922.0, 30.3645
8.042461380, 18.870, 1000.0, 31.6228
8.085927140, 18.870, 1070.0, 32.7109
8.129392900, 18.870, 1138.0, 33.7343
8.172858660, 18.870, 1246.0, 35.2987
8.216324420, 18.870, 1363.0, 36.9188
8.259790180, 18.870, 1442.0, 37.9737
8.303255940, 18.870, 1539.0, 39.2301
8.346721700, 18.870, 1432.0, 37.8418
8.390187460, 18.870, 1228.0, 35.0428
8.433653220, 18.870, 1038.0, 32.2180
8.477118980, 18.870, 950.0, 30.8221
8.520584740, 18.870, 917.0, 30.2820
8.564050500, 18.870, 889.0, 29.8161
8.607516260, 18.870, 894.0, 29.8998
8.650982020, 18.870, 953.0, 30.8707
8.694447780, 18.870, 940.0, 30.6594
8.737913540, 18.870, 929.0, 30.4795
8.781379300, 18.870, 1041.0, 32.2645
8.824845060, 18.870, 1097.0, 33.1210
8.868310820, 18.870, 1133.0, 33.6601
8.911776580, 18.870, 1273.0, 35.6791
8.955242340, 18.870, 1336.0, 36.5513
8.998708100, 18.870, 1540.0, 39.2428
9.042173860, 18.870, 1725.0, 41.5331
9.085639620, 18.870, 1972.0, 44.4072
9.129105380, 18.870, 2462.0, 49.6185
9.172571140, 18.870, 3322.0, 57.6368
9.216036900, 18.870, 4739.0, 68.8404
9.259502660, 18.870, 6867.0, 82.8674
9.302968420, 18.870, 7849.0, 88.5946
9.346434180, 18.870, 8501.0, 92.2009
9.389899940, 18.870, 8817.0, 93.8989
9.433365700, 18.870, 7508.0, 86.6487
9.476831460, 18.870, 7431.0, 86.2032
9.520297220, 18.870, 10885.0, 104.3312
9.563762980, 18.870, 17073.0, 130.6637
9.607228740, 18.870, 22641.0, 150.4693
9.650694500, 18.870, 27026.0, 164.3959
9.694160260, 18.870, 30114.0, 173.5339
9.737626020, 18.870, 27154.0, 164.7847
9.781091780, 18.870, 15654.0, 125.1159
9.824557540, 18.870, 7667.0, 87.5614
9.868023300, 18.870, 4769.0, 69.0579
9.911489060, 18.870, 4252.0, 65.2074
9.954954820, 18.870, 4944.0, 70.3136
9.998420580, 18.870, 6388.0, 79.9250
10.041886340, 18.870, 9136.0, 95.5824
10.085352100, 18.870, 14164.0, 119.0126
10.128817860, 18.870, 19673.0, 140.2605
10.172283620, 18.870, 23310.0, 152.6761
10.215749380, 18.870, 24392.0, 156.1794
10.259215140, 18.870, 19550.0, 139.8213
10.302680900, 18.870, 13127.0, 114.5731
10.346146660, 18.870, 8188.0, 90.4876
10.389612420, 18.870, 4864.0, 69.7424
10.433078180, 18.870, 2605.0, 51.0392
10.476543940, 18.870, 1635.0, 40.4351
10.520009700, 18.870, 1526.0, 39.0640
10.563475460, 18.870, 1449.0, 38.0657
10.606941220, 18.870, 1341.0, 36.6197
10.650406980, 18.870, 1264.0, 35.5528
10.693872740, 18.870, 1202.0, 34.6699
10.737338500, 18.870, 1246.0, 35.2987
10.780804260, 18.870, 1207.0, 34.7419
10.824270020, 18.870, 1232.0, 35.0999
10.867735780, 18.870, 1201.0, 34.6554
10.911201540, 18.870, 1110.0, 33.3167
10.954667300, 18.870, 1214.0, 34.8425
10.998133060, 18.870, 1124.0, 33.5261
11.041598820, 18.870, 1222.0, 34.9571
11.085064580, 18.870, 1134.0, 33.6749
11.128530340, 18.870, 1169.0, 34.1906
11.171996100, 18.870, 1190.0, 34.4964
11.215461860, 18.870, 1220.0, 34.9285
11.258927620, 18.870, 1280.0, 35.7771
11.302393380, 18.870, 1365.0, 36.9459
11.345859140, 18.870, 1487.0, 38.5616
11.389324900, 18.870, 1440.0, 37.9473
11.432790660, 18.870, 1699.0, 41.2189
11.476256420, 18.870, 1787.0, 42.2729
11.519722180, 18.870, 2295.0, 47.9062
11.563187940, 18.870, 3022.0, 54.9727
11.606653700, 18.870, 4248.0, 65.1767
11.650119460, 18.870, 5684.0, 75.3923
11.693585220, 18.870, 6623.0, 81.3818
11.737050980, 18.870, 6431.0, 80.1935
11.780516740, 18.870, 5299.0, 72.7942
11.823982500, 18.870, 3521.0, 59.3380
11.867448260, 18.870, 2077.0, 45.5741
11.910914020, 18.870, 1492.0, 38.6264
11.954379780, 18.870, 1244.0, 35.2704
11.997845540, 18.870, 1270.0, 35.6371
12.041311300, 18.870, 1318.0, 36.3043
12.084777060, 18.870, 1247.0, 35.3129
12.128242820, 18.870, 1358.0, 36.8511
12.171708580, 18.870, 1437.0, 37.9078
12.215174340, 18.870, 1499.0, 38.7169
12.258640100, 18.870, 1895.0, 43.5316
12.302105860, 18.870, 2235.0, 47.2758
12.345571620, 18.870, 2853.0, 53.4135
12.389037380, 18.870, 3345.0, 57.8360
12.432503140, 18.870, 3699.0, 60.8194
12.475968900, 18.870, 3864.0, 62.1611
12.519434660, 18.870, 4011.0, 63.3325
12.562900420, 18.870, 3979.0, 63.0793
12.606366180, 18.870, 2953.0, 54.3415
12.649831940, 18.870, 1819.0, 42.6497
12.693297700, 18.870, 1659.0, 40.7308
12.736763460, 18.870, 1621.0, 40.2616
12.780229220, 18.870, 1779.0, 42.1782
12.823694980, 18.870, 2047.0, 45.2438
12.867160740, 18.870, 2463.0, 49.6286
12.910626500, 18.870, 3199.0, 56.5597
12.954092260, 18.870, 4410.0, 66.4078
12.997558020, 18.870, 5976.0, 77.3046
13.041023780, 18.870, 7345.0, 85.7030
13.084489540, 18.870, 7987.0, 89.3700
13.127955300, 18.870, 8106.0, 90.0333
13.171421060, 18.870, 7586.0, 87.0976
13.214886820, 18.870, 5745.0, 75.7958
13.258352580, 18.870, 4063.0, 63.7417
13.301818340, 18.870, 2695.0, 51.9134
13.345284100, 18.870, 1851.0, 43.0232
13.388749860, 18.870, 1624.0, 40.2989
13.432215620, 18.870, 1686.0, 41.0609
13.475681380, 18.870, 1899.0, 43.5775
13.519147140, 18.870, 1961.0, 44.2832
13.562612900, 18.870, 2542.0, 50.4183
13.606078660, 18.870, 3338.0, 57.7754
13.649544420, 18.870, 4333.0, 65.8255
13.693010180, 18.870, 5606.0, 74.8732
13.736475940, 18.870, 6024.0, 77.6144
13.779941700, 18.870, 5033.0, 70.9436
13.823407460, 18.870, 4210.0, 64.8845
13.866873220, 18.870, 3193.0, 56.5066
13.910338980, 18.870, 1978.0, 44.4747
13.953804740, 18.870, 1393.0, 37.3229
13.997270500, 18.870, 1072.0, 32.7414
14.040736260, 18.870, 1009.0, 31.7648
14.084202020, 18.870, 1045.0, 32.3265
14.127667780, 18.870, 953.0, 30.8707
14.171133540, 18.870, 976.0, 31.2410
14.214599300, 18.870, 854.0, 29.2233
14.258065060, 18.870, 914.0, 30.2324
14.301530820, 18.870, 877.0, 29.6142
14.344996580, 18.870, 945.0, 30.7409
14.388462340, 18.870, 934.0, 30.5614
14.431928100, 18.870, 930.0, 30.4959
14.475393860, 18.870, 912.0, 30.1993
14.518859620, 18.870, 985.0, 31.3847
14.562325380, 18.870, 1094.0, 33.0757
14.605791140, 18.870, 1120.0, 33.4664
14.649256900, 18.870, 1209.0, 34.7707
14.692722660, 18.870, 1332.0, 36.4966
14.736188420, 18.870, 1378.0, 37.1214
14.779654180, 18.870, 1598.0, 39.9750
14.823119940, 18.870, 2005.0, 44.7772
14.866585700, 18.870, 2876.0, 53.6284
14.910051460, 18.870, 3831.0, 61.8951
14.953517220, 18.870, 5017.0, 70.8308
14.996982980, 18.870, 6483.0, 80.5171
15.040448740, 18.870, 8350.0, 91.3783
15.083914500, 18.870, 10353.0, 101.7497
15.127380260, 18.870, 10446.0, 102.2057
15.170846020, 18.870, 7501.0, 86.6083
15.214311780, 18.870, 4428.0, 66.5432
15.257777540, 18.870, 3697.0, 60.8030
15.301243300, 18.870, 3456.0, 58.7878
15.344709060, 18.870, 3172.0, 56.3205
15.388174820, 18.870, 2754.0, 52.4786
15.431640580, 18.870, 2136.0, 46.2169
15.475106340, 18.870, 1615.0, 40.1871
15.518572100, 18.870, 1307.0, 36.1525
15.562037860, 18.870, 1078.0, 32.8329
15.605503620, 18.870, 1012.0, 31.8119
15.648969380, 18.870, 1055.0, 32.4808
15.692435140, 18.870, 994.0, 31.5278
15.735900900, 18.870, 1013.0, 31.8277
15.779366660, 18.870, 1035.0, 32.1714
15.822832420, 18.870, 1052.0, 32.4345
15.866298180, 18.870, 1126.0, 33.5559
15.909763940, 18.870, 1160.0, 34.0588
15.953229700, 18.870, 1248.0, 35.3270
15.996695460, 18.870, 1405.0, 37.4833
16.040161220, 18.870, 1418.0, 37.6563
16.083626980, 18.870, 1435.0, 37.8814
16.127092740, 18.870, 1343.0, 36.6470
16.170558500, 18.870, 1170.0, 34.2053
16.214024260, 18.870, 1147.0, 33.8674
16.257490020, 18.870, 1078.0, 32.8329
16.300955780, 18.870, 1076.0, 32.8024
16.344421540, 18.870, 1117.0, 33.4215
16.387887300, 18.870, 1252.0, 35.3836
16.431353060, 18.870, 1395.0, 37.3497
16.474818820, 18.870, 1476.0, 38.4187
16.518284580, 18.870, 1664.0, 40.7922
16.561750340, 18.870, 1734.0, 41.6413
16.605216100, 18.870, 1731.0, 41.6053
16.648681860, 18.870, 1703.0, 41.2674
16.692147620, 18.870, 1680.0, 40.9878
16.735613380, 18.870, 1569.0, 39.6106
16.779079140, 18.870, 1642.0, 40.5216
16.822544900, 18.870, 1828.0, 42.7551
16.866010660, 18.870, 2152.0, 46.3897
16.909476420, 18.870, 2262.0, 47.5605
16.952942180, 18.870, 2500.0, 50.0000
16.996407940, 18.870, 2571.0, 50.7050
17.039873700, 18.870, 2629.0, 51.2738
17.083339460, 18.870, 2979.0, 54.5802
17.126805220, 18.870, 3533.0, 59.4390
17.170270980, 18.870, 4944.0, 70.3136
17.213736740, 18.870, 7137.0, 84.4808
17.257202500, 18.870, 11419.0, 106.8597
17.300668260, 18.870, 17631.0, 132.7818
17.344134020, 18.870, 25020.0, 158.1771
17.387599780, 18.870, 26324.0, 162.2467
17.431065540, 18.870, 19803.0, 140.7231
17.474531300, 18.870, 10168.0, 100.8365
17.517997060, 18.870, 4602.0, 67.8380
17.561462820, 18.870, 3055.0, 55.2721
17.604928580, 18.870, 2332.0, 48.2908
17.648394340, 18.870, 1956.0, 44.2267
17.691860100, 18.870, 1879.0, 43.3474
17.735325860, 18.870, 1969.0, 44.3734
17.778791620, 18.870, 2024.0, 44.9889
17.822257380, 18.870, 2195.0, 46.8508
17.865723140, 18.870, 3684.0, 60.6960
17.909188900, 18.870, 4002.0, 63.2614
17.952654660, 18.870, 7747.0, 88.0170
17.996120420, 18.870, 5394.0, 73.4439
18.039586180, 18.870, 2537.0, 50.3686
18.083051940, 18.870, 1532.0, 39.1408
18.126517700, 18.870, 1434.0, 37.8682
18.169983460, 18.870, 1416.0, 37.6298
18.213449220, 18.870, 1473.0, 38.3797
18.256914980, 18.870, 1443.0, 37.9868
18.300380740, 18.870, 1619.0, 40.2368
18.343846500, 18.870, 1689.0, 41.0974
18.387312260, 18.870, 1894.0, 43.5201
18.430778020, 18.870, 2232.0, 47.2440
18.474243780, 18.870, 2817.0, 53.0754
18.517709540, 18.870, 3715.0, 60.9508
18.561175300, 18.870, 4896.0, 69.9714
18.604641060, 18.870, 7057.0, 84.0060
18.648106820, 18.870, 10504.0, 102.4890
18.691572580, 18.870, 15258.0, 123.5233
18.735038340, 18.870, 19886.0, 141.0177
18.778504100, 18.870, 23147.0, 152.1414
18.821969860, 18.870, 22615.0, 150.3828
18.865435620, 18.870, 17754.0, 133.2441
18.908901380, 18.870, 11673.0, 108.0417
18.952367140, 18.870, 8518.0, 92.2930
18.995832900, 18.870, 7060.0, 84.0238
19.039298660, 18.870, 5435.0, 73.7225
19.082764420, 18.870, 3545.0, 59.5399
19.126230180, 18.870, 2734.0, 52.2877
19.169695940, 18.870, 2519.0, 50.1896
19.213161700, 18.870, 2297.0, 47.9270
19.256627460, 18.870, 2141.0, 46.2709
19.300093220, 18.870, 2278.0, 47.7284
19.343558980, 18.870, 2895.0, 53.8052
19.387024740, 18.870, 3661.0, 60.5062
19.430490500, 18.870, 4542.0, 67.3944
19.473956260, 18.870, 4904.0, 70.0286
19.517422020, 18.870, 4771.0, 69.0724
19.560887780, 18.870, 4148.0, 64.4050
19.604353540, 18.870, 3124.0, 55.8928
19.647819300, 18.870, 2334.0, 48.3115
19.691285060, 18.870, 1975.0, 44.4410
19.734750820, 18.870, 1902.0, 43.6119
19.778216580, 18.870, 1900.0, 43.5890
19.821682340, 18.870, 1747.0, 41.7971
19.865148100, 18.870, 1681.0, 41.0000
19.908613860, 18.870, 1537.0, 39.2046
19.952079620, 18.870, 1572.0, 39.6485
19.995545380, 18.870, 1563.0, 39.5348
20.039011140, 18.870, 1529.0, 39.1024
20.082476900, 18.870, 1638.0, 40.4722
20.125942660, 18.870, 1703.0, 41.2674
20.169408420, 18.870, 1747.0, 41.7971
20.212874180, 18.870, 2085.0, 45.6618
20.256339940, 18.870, 2515.0, 50.1498
20.299805700, 18.870, 3676.0, 60.6300
20.343271460, 18.870, 5619.0, 74.9600
20.386737220, 18.870, 8301.0, 91.1098
20.430202980, 18.870, 10722.0, 103.5471
20.473668740, 18.870, 11735.0, 108.3282
20.517134500, 18.870, 11679.0, 108.0694
20.560600260, 18.870, 10727.0, 103.5712
20.604066020, 18.870, 7965.0, 89.2468
20.647531780, 18.870, 5301.0, 72.8080
20.690997540, 18.870, 3798.0, 61.6279
20.734463300, 18.870, 3451.0, 58.7452
20.777929060, 18.870, 3599.0, 59.9917
20.821394820, 18.870, 3478.0, 58.9746
20.864860580, 18.870, 3428.0, 58.5491
20.908326340, 18.870, 3305.0, 57.4891
20.951792100, 18.870, 2820.0, 53.1037
20.995257860, 18.870, 2270.0, 47.6445
21.038723620, 18.870, 1842.0, 42.9185
21.082189380, 18.870, 1583.0, 39.7869
21.125655140, 18.870, 1492.0, 38.6264
21.169120900, 18.870, 1514.0, 38.9102
21.212586660, 18.870, 1564.0, 39.5474
21.256052420, 18.870, 1633.0, 40.4104
21.299518180, 18.870, 1639.0, 40.4846
21.342983940, 18.870, 1868.0, 43.2204
21.386449700, 18.870, 2383.0, 48.8160
21.429915460, 18.870, 2967.0, 54.4702
21.473381220, 18.870, 4025.0, 63.4429
21.516846980, 18.870, 5075.0, 71.2390
21.560312740, 18.870, 6806.0, 82.4985
21.603778500, 18.870, 9098.0, 95.3834
21.647244260, 18.870, 8810.0, 93.8616
21.690710020, 18.870, 7709.0, 87.8009
21.734175780, 18.870, 6434.0, 80.2122
21.777641540, 18.870, 4601.0, 67.8307
21.821107300, 18.870, 3584.0, 59.8665
21.864573060, 18.870, 4077.0, 63.8514
21.908038820, 18.870, 5608.0, 74.8866
21.951504580, 18.870, 7766.0, 88.1249
21.994970340, 18.870, 11440.0, 106.9579
22.038436100, 18.870, 15202.0, 123.2964
22.081901860, 18.870, 17966.0, 134.0373
22.125367620, 18.870, 18904.0, 137.4918
22.168833380, 18.870, 17737.0, 133.1803
22.212299140, 18.870, 16533.0, 128.5807
22.255764900, 18.870, 14331.0, 119.7122
22.299230660, 18.870, 9005.0, 94.8947
22.342696420, 18.870, 4644.0, 68.1469
22.386162180, 18.870, 2646.0, 51.4393
22.429627940, 18.870, 2831.0, 53.2071
22.473093700, 18.870, 3741.0, 61.1637
22.516559460, 18.870, 5117.0, 71.5332
22.560025220, 18.870, 6323.0, 79.5173
22.603490980, 18.870, 7455.0, 86.3423
22.646956740, 18.870, 9153.0, 95.6713
22.690422500, 18.870, 8852.0, 94.0851
22.733888260, 18.870, 7208.0, 84.8999
22.777354020, 18.870, 5417.0, 73.6003
22.820819780, 18.870, 3671.0, 60.5888
22.864285540, 18.870, 2833.0, 53.2259
22.907751300, 18.870, 2444.0, 49.4368
22.951217060, 18.870, 2363.0, 48.6107
22.994682820, 18.870, 2280.0, 47.7493
23.038148580, 18.870, 2197.0, 46.8722
23.081614340, 18.870, 2111.0, 45.9456
23.125080100, 18.870, 1956.0, 44.2267
23.168545860, 18.870, 1772.0, 42.0951
23.212011620, 18.870, 1708.0, 41.3280
23.255477380, 18.870, 1580.0, 39.7492
23.298943140, 18.870, 1518.0, 38.9615
23.342408900, 18.870, 1571.0, 39.6358
23.385874660, 18.870, 1513.0, 38.8973
23.429340420, 18.870, 1635.0, 40.4351
23.472806180, 18.870, 1850.0, 43.0116
23.516271940, 18.870, 2335.0, 48.3218
23.559737700, 18.870, 3091.0, 55.5968
23.603203460, 18.870, 3548.0, 59.5651
23.646669220, 18.870, 4028.0, 63.4665
23.690134980, 18.870, 3643.0, 60.3573
23.733600740, 18.870, 3345.0, 57.8360
23.777066500, 18.870, 3471.0, 58.9152
23.820532260, 18.870, 3066.0, 55.3715
23.863998020, 18.870, 2550.0, 50.4975
23.907463780, 18.870, 2157.0, 46.4435
23.950929540, 18.870, 1901.0, 43.6005
23.994395300, 18.870, 1578.0, 39.7240
24.037861060, 18.870, 1555.0, 39.4335
24.081326820, 18.870, 1430.0, 37.8153
24.124792580, 18.870, 1503.0, 38.7685
24.168258340, 18.870, 1733.0, 41.6293
24.211724100, 18.870, 2146.0, 46.3249
24.255189860, 18.870, 2409.0, 49.0816
24.298655620, 18.870, 2906.0, 53.9073
24.342121380, 18.870, 3035.0, 55.0908
24.385587140, 18.870, 3111.0, 55.7763
24.429052900, 18.870, 3425.0, 58.5235
24.472518660, 18.870, 3197.0, 56.5420
24.515984420, 18.870, 2578.0, 50.7740
24.559450180, 18.870, 2186.0, 46.7547
24.602915940, 18.870, 1857.0, 43.0929
24.646381700, 18.870, 1983.0, 44.5309
24.689847460, 18.870, 1912.0, 43.7264
24.733313220, 18.870, 1969.0, 44.3734
24.776778980, 18.870, 1717.0, 41.4367
24.820244740, 18.870, 1551.0, 39.3827
24.863710500, 18.870, 1408.0, 37.5233
24.907176260, 18.870, 1300.0, 36.0555
24.950642020, 18.870, 1357.0, 36.8375
24.994107780, 18.870, 1331.0, 36.4829
25.037573540, 18.870, 1645.0, 40.5586
25.081039300, 18.870, 1948.0, 44.1362
25.124505060, 18.870, 2206.0, 46.9681
25.167970820, 18.870, 2575.0, 50.7445
25.211436580, 18.870, 2706.0, 52.0192
25.254902340, 18.870, 2638.0, 51.3615
25.298368100, 18.870, 2597.0, 50.9608
25.341833860, 18.870, 2226.0, 47.1805
25.385299620, 18.870, 2108.0, 45.9130
25.428765380, 18.870, 2038.0, 45.1442
25.472231140, 18.870, 2054.0, 45.3211
25.515696900, 18.870, 2021.0, 44.9555
25.559162660, 18.870, 1937.0, 44.0114
25.602628420, 18.870, 1785.0, 42.2493
25.646094180, 18.870, 1545.0, 39.3065
25.689559940, 18.870, 1297.0, 36.0139
25.733025700, 18.870, 1158.0, 34.0294
25.776491460, 18.870, 1118.0, 33.4365
25.819957220, 18.870, 1111.0, 33.3317
25.863422980, 18.870, 1034.0, 32.1559
25.906888740, 18.870, 1091.0, 33.0303
25.950354500, 18.870, 1131.0, 33.6303
25.993820260, 18.870, 1186.0, 34.4384
26.037286020, 18.870, 1255.0, 35.4260
26.080751780, 18.870, 1327.0, 36.4280
26.124217540, 18.870, 1452.0, 38.1051
26.167683300, 18.870, 1622.0, 40.2741
26.211149060, 18.870, 1861.0, 43.1393
26.254614820, 18.870, 2173.0, 46.6154
26.298080580, 18.870, 2784.0, 52.7636
26.341546340, 18.870, 3362.0, 57.9828
26.385012100, 18.870, 3428.0, 58.5491
26.428477860, 18.870, 3024.0, 54.9909
26.471943620, 18.870, 2547.0, 50.4678
26.515409380, 18.870, 2306.0, 48.0208
26.558875140, 18.870, 2256.0, 47.4974
26.602340900, 18.870, 2069.0, 45.4863
26.645806660, 18.870, 2026.0, 45.0111
26.689272420, 18.870, 1919.0, 43.8064
26.732738180, 18.870, 1753.0, 41.8688
26.776203940, 18.870, 1600.0, 40.0000
26.819669700, 18.870, 1434.0, 37.8682
26.863135460, 18.870, 1364.0, 36.9324
26.906601220, 18.870, 1409.0, 37.5366
26.950066980, 18.870, 1433.0, 37.8550
26.993532740, 18.870, 1561.0, 39.5095
27.036998500, 18.870, 1652.0, 40.6448
27.080464260, 18.870, 1786.0, 42.2611
27.123930020, 18.870, 1784.0, 42.2374
27.167395780, 18.870, 1781.0, 42.2019
27.210861540, 18.870, 1656.0, 40.6940
27.254327300, 18.870, 1604.0, 40.0500
27.297793060, 18.870, 1622.0, 40.2741
27.341258820, 18.870, 1739.0, 41.7013
27.384724580, 18.870, 1842.0, 42.9185
27.428190340, 18.870, 2124.0, 46.0869
27.471656100, 18.870, 2414.0, 49.1325
27.515121860, 18.870, 2817.0, 53.0754
27.558587620, 18.870, 3048.0, 55.2087
27.602053380, 18.870, 3065.0, 55.3624
27.645519140, 18.870, 2826.0, 53.1601
27.688984900, 18.870, 2658.0, 51.5558
27.732450660, 18.870, 2120.0, 46.0435
27.775916420, 18.870, 1967.0, 44.3509
27.819382180, 18.870, 1531.0, 39.1280
27.862847940, 18.870, 1430.0, 37.8153
27.906313700, 18.870, 1311.0, 36.2077
27.949779460, 18.870, 1244.0, 35.2704
27.993245220, 18.870, 1249.0, 35.3412
28.036710980, 18.870, 1289.0, 35.9026
28.080176740, 18.870, 1280.0, 35.7771
28.123642500, 18.870, 1274.0, 35.6931
28.167108260, 18.870, 1285.0, 35.8469
28.210574020, 18.870, 1296.0, 36.0000
28.254039780, 18.870, 1380.0, 37.1484
28.297505540, 18.870, 1533.0, 39.1535
28.340971300, 18.870, 1465.0, 38.2753
28.384437060, 18.870, 1434.0, 37.8682
28.427902820, 18.870, 1414.0, 37.6032
28.471368580, 18.870, 1448.0, 38.0526
28.514834340, 18.870, 1549.0, 39.3573
28.558300100, 18.870, 1625.0, 40.3113
28.601765860, 18.870, 1908.0, 43.6807
28.645231620, 18.870, 1810.0, 42.5441
28.688697380, 18.870, 1718.0, 41.4488
28.732163140, 18.870, 1506.0, 38.8072
28.775628900, 18.870, 1511.0, 38.8716
28.819094660, 18.870, 1572.0, 39.6485
28.862560420, 18.870, 1773.0, 42.1070
28.906026180, 18.870, 2161.0, 46.4866
28.949491940, 18.870, 2483.0, 49.8297
28.992957700, 18.870, 2783.0, 52.7541
29.036423460, 18.870, 3053.0, 55.2540
29.079889220, 18.870, 2824.0, 53.1413
29.123354980, 18.870, 2842.0, 53.3104
29.166820740, 18.870, 2070.0, 45.4973
29.210286500, 18.870, 1726.0, 41.5452
29.253752260, 18.870, 1411.0, 37.5633
29.297218020, 18.870, 1225.0, 35.0000
29.340683780, 18.870, 1220.0, 34.9285
29.384149540, 18.870, 1368.0, 36.9865
29.427615300, 18.870, 1336.0, 36.5513
29.471081060, 18.870, 1317.0, 36.2905
29.514546820, 18.870, 1266.0, 35.5809
29.558012580, 18.870, 1219.0, 34.9142
29.601478340, 18.870, 1091.0, 33.0303
29.644944100, 18.870, 954.0, 30.8869
29.688409860, 18.870, 982.0, 31.3369
29.731875620, 18.870, 887.0, 29.7825
29.775341380, 18.870, 910.0, 30.1662
29.818807140, 18.870, 772.0, 27.7849
29.862272900, 18.870, 857.0, 29.2746
29.905738660, 18.870, 831.0, 28.8271
29.949204420, 18.870, 840.0, 28.9828
29.992670180, 18.870, 857.0, 29.2746
30.036135940, 18.870, 862.0, 29.3598
30.079601700, 18.870, 887.0, 29.7825
30.123067460, 18.870, 887.0, 29.7825
30.166533220, 18.870, 935.0, 30.5778
30.209998980, 18.870, 1029.0, 32.0780
30.253464740, 18.870, 1044.0, 32.3110
30.296930500, 18.870, 1038.0, 32.2180
30.340396260, 18.870, 1077.0, 32.8177
30.383862020, 18.870, 1198.0, 34.6121
30.427327780, 18.870, 1233.0, 35.1141
30.470793540, 18.870, 1296.0, 36.0000
30.514259300, 18.870, 1278.0, 35.7491
30.557725060, 18.870, 1185.0, 34.4238
30.601190820, 18.870, 1233.0, 35.1141
30.644656580, 18.870, 1195.0, 34.5688
30.688122340, 18.870, 1164.0, 34.1174
30.731588100, 18.870, 1219.0, 34.9142
30.775053860, 18.870, 1173.0, 34.2491
30.818519620, 18.870, 1152.0, 33.9411
30.861985380, 18.870, 1182.0, 34.3802
30.905451140, 18.870, 1158.0, 34.0294
30.948916900, 18.870, 1316.0, 36.2767
30.992382660, 18.870, 1405.0, 37.4833
31.035848420, 18.870, 1577.0, 39.7115
31.079314180, 18.870, 1670.0, 40.8656
31.122779940, 18.870, 1631.0, 40.3856
31.166245700, 18.870, 1685.0, 41.0488
31.209711460, 18.870, 1445.0, 38.0132
31.253177220, 18.870, 1304.0, 36.1109
31.296642980, 18.870, 1160.0, 34.0588
31.340108740, 18.870, 1101.0, 33.1813
31.383574500, 18.870, 980.0, 31.3050
31.427040260, 18.870, 935.0, 30.5778
31.470506020, 18.870, 837.0, 28.9310
31.513971780, 18.870, 877.0, 29.6142
31.557437540, 18.870, 772.0, 27.7849
31.600903300, 18.870, 792.0, 28.1425
31.644369060, 18.870, 764.0, 27.6405
31.687834820, 18.870, 768.0, 27.7128
31.731300580, 18.870, 777.0, 27.8747
31.774766340, 18.870, 807.0, 28.4077
31.818232100, 18.870, 853.0, 29.2062
31.861697860, 18.870, 870.0, 29.4958
31.905163620, 18.870, 866.0, 29.4279
31.948629380, 18.870, 871.0, 29.5127
31.992095140, 18.870, 891.0, 29.8496
32.035560900, 18.870, 908.0, 30.1330
32.079026660, 18.870, 953.0, 30.8707
32.122492420, 18.870, 946.0, 30.7571
32.165958180, 18.870, 895.0, 29.9166
32.209423940, 18.870, 904.0, 30.0666
32.252889700, 18.870, 855.0, 29.2404
32.296355460, 18.870, 851.0, 29.1719
32.339821220, 18.870, 911.0, 30.1828
32.383286980, 18.870, 1066.0, 32.6497
32.426752740, 18.870, 1157.0, 34.0147
32.470218500, 18.870, 1312.0, 36.2215
32.513684260, 18.870, 1514.0, 38.9102
32.557150020, 18.870, 1595.0, 39.9375
32.600615780, 18.870, 1543.0, 39.2810
32.644081540, 18.870, 1287.0, 35.8748
32.687547300, 18.870, 1206.0, 34.7275
32.731013060, 18.870, 1000.0, 31.6228
32.774478820, 18.870, 933.0, 30.5450
32.817944580, 18.870, 932.0, 30.5287
32.861410340, 18.870, 906.0, 30.0998
32.904876100, 18.870, 1004.0, 31.6860
32.948341860, 18.870, 961.0, 31.0000
32.991807620, 18.870, 1001.0, 31.6386
33.035273380, 18.870, 988.0, 31.4325
33.078739140, 18.870, 963.0, 31.0322
33.122204900, 18.870, 1005.0, 31.7017
33.165670660, 18.870, 1036.0, 32.1870
33.209136420, 18.870, 1046.0, 32.3419
33.252602180, 18.870, 1045.0, 32.3265
33.296067940, 18.870, 1051.0, 32.4191
33.339533700, 18.870, 988.0, 31.4325
33.382999460, 18.870, 898.0, 29.9666
33.426465220, 18.870, 869.0, 29.4788
33.469930980, 18.870, 823.0, 28.6880
33.513396740, 18.870, 888.0, 29.7993
33.556862500, 18.870, 853.0, 29.2062
33.600328260, 18.870, 864.0, 29.3939
33.643794020, 18.870, 865.0, 29.4109
33.687259780, 18.870, 938.0, 30.6268
33.730725540, 18.870, 896.0, 29.9333
33.774191300, 18.870, 882.0, 29.6985
33.817657060, 18.870, 1116.0, 33.4066
33.861122820, 18.870, 1360.0, 36.8782
33.904588580, 18.870, 1557.0, 39.4588
33.948054340, 18.870, 1632.0, 40.3980
33.991520100, 18.870, 1589.0, 39.8623
34.034985860, 18.870, 1599.0, 39.9875
34.078451620, 18.870, 1331.0, 36.4829
34.121917380, 18.870, 1223.0, 34.9714
34.165383140, 18.870, 1096.0, 33.1059
34.208848900, 18.870, 974.0, 31.2090
34.252314660, 18.870, 1014.0, 31.8434
34.295780420, 18.870, 1026.0, 32.0312
34.339246180, 18.870, 1028.0, 32.0624
34.382711940, 18.870, 1113.0, 33.3617
34.426177700, 18.870, 1059.0, 32.5423
34.469643460, 18.870, 1110.0, 33.3167
34.513109220, 18.870, 1186.0, 34.4384
34.556574980, 18.870, 1217.0, 34.8855
34.600040740, 18.870, 1401.0, 37.4299
34.643506500, 18.870, 1495.0, 38.6652
34.686972260, 18.870, 1565.0, 39.5601
34.730438020, 18.870, 1640.0, 40.4969
34.773903780, 18.870, 1654.0, 40.6694
34.817369540, 18.870, 1906.0, 43.6578
34.860835300, 18.870, 2100.0, 45.8258
34.904301060, 18.870, 2049.0, 45.2659
34.947766820, 18.870, 1674.0, 40.9145
34.991232580, 18.870, 1428.0, 37.7889
35.034698340, 18.870, 1251.0, 35.3695
35.078164100, 18.870, 1254.0, 35.4119
35.121629860, 18.870, 1389.0, 37.2693
35.165095620, 18.870, 1389.0, 37.2693
35.208561380, 18.870, 1420.0, 37.6829
35.252027140, 18.870, 1401.0, 37.4299
35.295492900, 18.870, 1346.0, 36.6879
35.338958660, 18.870, 1073.0, 32.7567
35.382424420, 18.870, 1056.0, 32.4962
35.425890180, 18.870, 926.0, 30.4302
35.469355940, 18.870, 919.0, 30.3150
35.512821700, 18.870, 842.0, 29.0172
35.556287460, 18.870, 838.0, 28.9482
35.599753220, 18.870, 847.0, 29.1033
35.643218980, 18.870, 829.0, 28.7924
35.686684740, 18.870, 842.0, 29.0172
35.730150500, 18.870, 851.0, 29.1719
35.773616260, 18.870, 892.0, 29.8664
35.817082020, 18.870, 936.0, 30.5941
35.860547780, 18.870, 905.0, 30.0832
35.904013540, 18.870, 857.0, 29.2746
35.947479300, 18.870, 796.0, 28.2135
35.990945060, 18.870, 782.0, 27.9643
36.034410820, 18.870, 770.0, 27.7489
36.077876580, 18.870, 751.0, 27.4044
36.121342340, 18.870, 765.0, 27.6586
36.164808100, 18.870, 798.0, 28.2489
36.208273860, 18.870, 808.0, 28.4253
36.251739620, 18.870, 815.0, 28.5482
36.295205380, 18.870, 865.0, 29.4109
36.338671140, 18.870, 886.0, 29.7658
36.382136900, 18.870, 924.0, 30.3974
36.425602660, 18.870, 909.0, 30.1496
36.469068420, 18.870, 1043.0, 32.2955
36.512534180, 18.870, 1104.0, 33.2265
36.555999940, 18.870, 1104.0, 33.2265
36.599465700, 18.870, 1182.0, 34.3802
36.642931460, 18.870, 1132.0, 33.6452
36.686397220, 18.870, 1176.0, 34.2929
36.729862980, 18.870, 1170.0, 34.2053
36.773328740, 18.870, 1018.0, 31.9061
36.816794500, 18.870, 1034.0, 32.1559
36.860260260, 18.870, 1056.0, 32.4962
36.903726020, 18.870, 961.0, 31.0000
36.947191780, 18.870, 932.0, 30.5287
36.990657540, 18.870, 928.0, 30.4631
37.034123300, 18.870, 922.0, 30.3645
37.077589060, 18.870, 902.0, 30.0333
37.121054820, 18.870, 900.0, 30.0000
37.164520580, 18.870, 836.0, 28.9137
37.207986340, 18.870, 864.0, 29.3939
37.251452100, 18.870, 826.0, 28.7402
37.294917860, 18.870, 823.0, 28.6880
37.338383620, 18.870, 844.0, 29.0517
37.381849380, 18.870, 840.0, 28.9828
37.425315140, 18.870, 844.0, 29.0517
37.468780900, 18.870, 790.0, 28.1069
37.512246660, 18.870, 893.0, 29.8831
37.555712420, 18.870, 892.0, 29.8664
37.599178180, 18.870, 896.0, 29.9333
37.642643940, 18.870, 903.0, 30.0500
37.686109700, 18.870, 933.0, 30.5450
37.729575460, 18.870, 899.0, 29.9833
37.773041220, 18.870, 941.0, 30.6757
37.816506980, 18.870, 955.0, 30.9031
37.859972740, 18.870, 875.0, 29.5804
37.903438500, 18.870, 835.0, 28.8964
37.946904260, 18.870, 951.0, 30.8383
37.990370020, 18.870, 1049.0, 32.3883
38.033835780, 18.870, 1176.0, 34.2929
38.077301540, 18.870, 1254.0, 35.4119
38.120767300, 18.870, 1251.0, 35.3695
38.164233060, 18.870, 1178.0, 34.3220
38.207698820, 18.870, 1038.0, 32.2180
38.251164580, 18.870, 933.0, 30.5450
38.294630340, 18.870, 863.0, 29.3769
38.338096100, 18.870, 819.0, 28.6182
38.381561860, 18.870, 762.0, 27.6043
38.425027620, 18.870, 719.0, 26.8142
38.468493380, 18.870, 798.0, 28.2489
38.511959140, 18.870, 753.0, 27.4408
38.555424900, 18.870, 753.0, 27.4408
38.598890660, 18.870, 739.0, 27.1846
38.642356420, 18.870, 806.0, 28.3901
38.685822180, 18.870, 805.0, 28.3725
38.729287940, 18.870, 796.0, 28.2135
38.772753700, 18.870, 752.0, 27.4226
38.816219460, 18.870, 702.0, 26.4953
38.859685220, 18.870, 748.0, 27.3496
38.903150980, 18.870, 768.0, 27.7128
38.946616740, 18.870, 893.0, 29.8831
38.990082500, 18.870, 874.0, 29.5635
39.033548260, 18.870, 928.0, 30.4631
39.077014020, 18.870, 909.0, 30.1496
39.120479780, 18.870, 890.0, 29.8329
39.163945540, 18.870, 849.0, 29.1376
39.207411300, 18.870, 863.0, 29.3769
39.250877060, 18.870, 842.0, 29.0172
39.294342820, 18.870, 884.0, 29.7321
39.337808580, 18.870, 810.0, 28.4605
39.381274340, 18.870, 794.0, 28.1780
39.424740100, 18.870, 779.0, 27.9106
39.468205860, 18.870, 747.0, 27.3313
39.511671620, 18.870, 775.0, 27.8388
39.555137380, 18.870, 735.0, 27.1109
39.598603140, 18.870, 901.0, 30.0167
39.642068900, 18.870, 823.0, 28.6880
39.685534660, 18.870, 802.0, 28.3196
39.729000420, 18.870, 830.0, 28.8097
39.772466180, 18.870, 802.0, 28.3196
39.815931940, 18.870, 700.0, 26.4575
39.859397700, 18.870, 748.0, 27.3496
39.902863460, 18.870, 683.0, 26.1343
39.946329220, 18.870, 715.0, 26.7395
39.989794980, 18.870, 694.0, 26.3439
40.033260740, 18.870, 744.0, 27.2764
40.076726500, 18.870, 790.0, 28.1069
40.120192260, 18.870, 862.0, 29.3598
40.163658020, 18.870, 968.0, 31.1127
40.207123780, 18.870, 1051.0, 32.4191
40.250589540, 18.870, 1017.0, 31.8904
40.294055300, 18.870, 1044.0, 32.3110
40.337521060, 18.870, 1015.0, 31.8591
40.380986820, 18.870, 965.0, 31.0644
40.424452580, 18.870, 1052.0, 32.4345
40.467918340, 18.870, 1047.0, 32.3574
40.511384100, 18.870, 1153.0, 33.9559
40.554849860, 18.870, 1154.0, 33.9706
40.598315620, 18.870, 1103.0, 33.2114
40.641781380, 18.870, 1049.0, 32.3883
40.685247140, 18.870, 922.0, 30.3645
40.728712900, 18.870, 870.0, 29.4958
40.772178660, 18.870, 784.0, 28.0000
40.815644420, 18.870, 700.0, 26.4575
40.859110180, 18.870, 770.0, 27.7489
40.902575940, 18.870, 819.0, 28.6182
40.946041700, 18.870, 764.0, 27.6405
40.989507460, 18.870, 719.0, 26.8142
41.032973220, 18.870, 766.0, 27.6767
41.076438980, 18.870, 705.0, 26.5518
41.119904740, 18.870, 684.0, 26.1534
41.163370500, 18.870, 683.0, 26.1343
41.206836260, 18.870, 680.0, 26.0768
41.250302020, 18.870, 664.0, 25.7682
41.293767780, 18.870, 652.0, 25.5343
41.337233540, 18.870, 692.0, 26.3059
41.380699300, 18.870, 691.0, 26.2869
41.424165060, 18.870, 707.0, 26.5895
41.467630820, 18.870, 707.0, 26.5895
41.511096580, 18.870, 779.0, 27.9106
41.554562340, 18.870, 796.0, 28.2135
41.598028100, 18.870, 779.0, 27.9106
41.641493860, 18.870, 883.0, 29.7153
41.684959620, 18.870, 936.0, 30.5941
41.728425380, 18.870, 974.0, 31.2090
41.771891140, 18.870, 1020.0, 31.9374
41.815356900, 18.870, 925.0, 30.4138
41.858822660, 18.870, 973.0, 31.1929
41.902288420, 18.870, 876.0, 29.5973
41.945754180, 18.870, 772.0, 27.7849
41.989219940, 18.870, 753.0, 27.4408
42.032685700, 18.870, 734.0, 27.0924
42.076151460, 18.870, 669.0, 25.8650
42.119617220, 18.870, 686.0, 26.1916
42.163082980, 18.870, 730.0, 27.0185
42.206548740, 18.870, 780.0, 27.9285
42.250014500, 18.870, 763.0, 27.6225
42.293480260, 18.870, 869.0, 29.4788
42.336946020, 18.870, 873.0, 29.5466
42.380411780, 18.870, 984.0, 31.3688
42.423877540, 18.870, 1020.0, 31.9374
42.467343300, 18.870, 995.0, 31.5436
42.510809060, 18.870, 1020.0, 31.9374
42.554274820, 18.870, 1037.0, 32.2025
42.597740580, 18.870, 991.0, 31.4802
42.641206340, 18.870, 933.0, 30.5450
42.684672100, 18.870, 1023.0, 31.9844
42.728137860, 18.870, 1053.0, 32.4500
42.771603620, 18.870, 1152.0, 33.9411
42.815069380, 18.870, 1099.0, 33.1512
42.858535140, 18.870, 1046.0, 32.3419
42.902000900, 18.870, 920.0, 30.3315
42.945466660, 18.870, 863.0, 29.3769
42.988932420, 18.870, 816.0, 28.5657
43.032398180, 18.870, 798.0, 28.2489
43.075863940, 18.870, 860.0, 29.3258
43.119329700, 18.870, 889.0, 29.8161
43.162795460, 18.870, 919.0, 30.3150
43.206261220, 18.870, 963.0, 31.0322
43.249726980, 18.870, 1043.0, 32.2955
43.293192740, 18.870, 1073.0, 32.7567
43.336658500, 18.870, 992.0, 31.4960
43.380124260, 18.870, 991.0, 31.4802
43.423590020, 18.870, 922.0, 30.3645
43.467055780, 18.870, 798.0, 28.2489
43.510521540, 18.870, 781.0, 27.9464
43.553987300, 18.870, 758.0, 27.5318
43.597453060, 18.870, 759.0, 27.5500
43.640918820, 18.870, 741.0, 27.2213
43.684384580, 18.870, 818.0, 28.6007
43.727850340, 18.870, 753.0, 27.4408
43.771316100, 18.870, 790.0, 28.1069
43.814781860, 18.870, 768.0, 27.7128
43.858247620, 18.870, 719.0, 26.8142
43.901713380, 18.870, 732.0, 27.0555
43.945179140, 18.870, 617.0, 24.8395
43.988644900, 18.870, 648.0, 25.4558
44.032110660, 18.870, 671.0, 25.9037
44.075576420, 18.870, 622.0, 24.9399
44.119042180, 18.870, 719.0, 26.8142
44.162507940, 18.870, 704.0, 26.5330
44.205973700, 18.870, 744.0, 27.2764
44.249439460, 18.870, 778.0, 27.8927
44.292905220, 18.870, 759.0, 27.5500
44.336370980, 18.870, 784.0, 28.0000
44.379836740, 18.870, 775.0, 27.8388
44.423302500, 18.870, 710.0, 26.6458
44.466768260, 18.870, 629.0, 25.0799
44.510234020, 18.870, 674.0, 25.9615
44.553699780, 18.870, 645.0, 25.3969
44.597165540, 18.870, 654.0, 25.5734
44.640631300, 18.870, 607.0, 24.6374
44.684097060, 18.870, 632.0, 25.1396
44.727562820, 18.870, 707.0, 26.5895
44.771028580, 18.870, 719.0, 26.8142
44.814494340, 18.870, 747.0, 27.3313
44.857960100, 18.870, 721.0, 26.8514
44.901425860, 18.870, 767.0, 27.6948
44.944891620, 18.870, 824.0, 28.7054
44.988357380, 18.870, 994.0, 31.5278
45.031823140, 18.870, 896.0, 29.9333
45.075288900, 18.870, 917.0, 30.2820
45.118754660, 18.870, 903.0, 30.0500
45.162220420, 18.870, 833.0, 28.8617
45.205686180, 18.870, 808.0, 28.4253
45.249151940, 18.870, 795.0, 28.1957
45.292617700, 18.870, 831.0, 28.8271
45.336083460, 18.870, 827.0, 28.7576
45.379549220, 18.870, 756.0, 27.4955
45.423014980, 18.870, 715.0, 26.7395
45.466480740, 18.870, 736.0, 27.1293
45.509946500, 18.870, 680.0, 26.0768
45.553412260, 18.870, 645.0, 25.3969
45.596878020, 18.870, 649.0, 25.4755
45.640343780, 18.870, 615.0, 24.7992
45.683809540, 18.870, 648.0, 25.4558
45.727275300, 18.870, 759.0, 27.5500
45.770741060, 18.870, 724.0, 26.9072
45.814206820, 18.870, 714.0, 26.7208
45.857672580, 18.870, 777.0, 27.8747
45.901138340, 18.870, 770.0, 27.7489
45.944604100, 18.870, 688.0, 26.2298
45.988069860, 18.870, 738.0, 27.1662
46.031535620, 18.870, 729.0, 27.0000
46.075001380, 18.870, 748.0, 27.3496
46.118467140, 18.870, 715.0, 26.7395
46.161932900, 18.870, 787.0, 28.0535
46.205398660, 18.870, 822.0, 28.6705
46.248864420, 18.870, 759.0, 27.5500
46.292330180, 18.870, 761.0, 27.5862
46.335795940, 18.870, 786.0, 28.0357
46.379261700, 18.870, 818.0, 28.6007
46.422727460, 18.870, 823.0, 28.6880
46.466193220, 18.870, 747.0, 27.3313
46.509658980, 18.870, 832.0, 28.8444
46.553124740, 18.870, 790.0, 28.1069
46.596590500, 18.870, 762.0, 27.6043
46.640056260, 18.870, 817.0, 28.5832
46.683522020, 18.870, 813.0, 28.5132
46.726987780, 18.870, 815.0, 28.5482
46.770453540, 18.870, 866.0, 29.4279
46.813919300, 18.870, 741.0, 27.2213
46.857385060, 18.870, 745.0, 27.2947
46.900850820, 18.870, 740.0, 27.2029
46.944316580, 18.870, 727.0, 26.9629
46.987782340, 18.870, 670.0, 25.8844
47.031248100, 18.870, 640.0, 25.2982
47.074713860, 18.870, 691.0, 26.2869
47.118179620, 18.870, 634.0, 25.1794
47.161645380, 18.870, 636.0, 25.2190
47.205111140, 18.870, 609.0, 24.6779
47.248576900, 18.870, 644.0, 25.3772
47.292042660, 18.870, 630.0, 25.0998
47.335508420, 18.870, 598.0, 24.4540
47.378974180, 18.870, 596.0, 24.4131
47.422439940, 18.870, 626.0, 25.0200
47.465905700, 18.870, 665.0, 25.7876
47.509371460, 18.870, 646.0, 25.4165
47.552837220, 18.870, 751.0, 27.4044
47.596302980, 18.870, 764.0, 27.6405
47.639768740, 18.870, 736.0, 27.1293
47.683234500, 18.870, 708.0, 26.6083
47.726700260, 18.870, 694.0, 26.3439
47.770166020, 18.870, 635.0, 25.1992
47.813631780, 18.870, 646.0, 25.4165
47.857097540, 18.870, 646.0, 25.4165
47.900563300, 18.870, 636.0, 25.2190
47.944029060, 18.870, 647.0, 25.4362
47.987494820, 18.870, 675.0, 25.9808
48.030960580, 18.870, 662.0, 25.7294
48.074426340, 18.870, 684.0, 26.1534
48.117892100, 18.870, 663.0, 25.7488
48.161357860, 18.870, 676.0, 26.0000
48.204823620, 18.870, 651.0, 25.5147
48.248289380, 18.870, 590.0, 24.2899
48.291755140, 18.870, 632.0, 25.1396
48.335220900, 18.870, 603.0, 24.5561
48.378686660, 18.870, 605.0, 24.5967
48.422152420, 18.870, 623.0, 24.9600
48.465618180, 18.870, 608.0, 24.6577
48.509083940, 18.870, 591.0, 24.3105
48.552549700, 18.870, 599.0, 24.4745
48.596015460, 18.870, 614.0, 24.7790
48.639481220, 18.870, 594.0, 24.3721
48.682946980, 18.870, 582.0, 24.1247
48.726412740, 18.870, 567.0, 23.8118
48.769878500, 18.870, 678.0, 26.0384
48.813344260, 18.870, 684.0, 26.1534
48.856810020, 18.870, 725.0, 26.9258
48.900275780, 18.870, 759.0, 27.5500
48.943741540, 18.870, 789.0, 28.0891
48.987207300, 18.870, 724.0, 26.9072
49.030673060, 18.870, 732.0, 27.0555
49.074138820, 18.870, 702.0, 26.4953
49.117604580, 18.870, 639.0, 25.2784
49.161070340, 18.870, 695.0, 26.3629
49.204536100, 18.870, 732.0, 27.0555
49.248001860, 18.870, 839.0, 28.9655
49.291467620, 18.870, 829.0, 28.7924
49.334933380, 18.870, 812.0, 28.4956
49.378399140, 18.870, 764.0, 27.6405
49.421864900, 18.870, 765.0, 27.6586
49.465330660, 18.870, 689.0, 26.2488
49.508796420, 18.870, 666.0, 25.8070
49.552262180, 18.870, 643.0, 25.3574
49.595727940, 18.870, 626.0, 25.0200
49.639193700, 18.870, 577.0, 24.0208
49.682659460, 18.870, 631.0, 25.1197
49.726125220, 18.870, 625.0, 25.0000
49.769590980, 18.870, 555.0, 23.5584
49.813056740, 18.870, 592.0, 24.3311
49.856522500, 18.870, 658.0, 25.6515
49.899988260, 18.870, 673.0, 25.9422
49.943454020, 18.870, 646.0, 25.4165
49.986919780, 18.870, 693.0, 26.3249
50.030385540, 18.870, 669.0, 25.8650
50.073851300, 18.870, 735.0, 27.1109
50.117317060, 18.870, 672.0, 25.9230
50.160782820, 18.870, 708.0, 26.6083
50.204248580, 18.870, 655.0, 25.5930
50.247714340, 18.870, 636.0, 25.2190
50.291180100, 18.870, 629.0, 25.0799
50.334645860, 18.870, 612.0, 24.7386
50.378111620, 18.870, 627.0, 25.0400
50.421577380, 18.870, 598.0, 24.4540
50.465043140, 18.870, 605.0, 24.5967
50.508508900, 18.870, 585.0, 24.1868
50.551974660, 18.870, 622.0, 24.9399
50.595440420, 18.870, 634.0, 25.1794
50.638906180, 18.870, 590.0, 24.2899
50.682371940, 18.870, 588.0, 24.2487
50.725837700, 18.870, 579.0, 24.0624
50.769303460, 18.870, 540.0, 23.2379
50.812769220, 18.870, 556.0, 23.5797
50.856234980, 18.870, 579.0, 24.0624
50.899700740, 18.870, 578.0, 24.0416
50.943166500, 18.870, 561.0, 23.6854
50.986632260, 18.870, 516.0, 22.7156
51.030098020, 18.870, 558.0, 23.6220
51.073563780, 18.870, 557.0, 23.6008
51.117029540, 18.870, 540.0, 23.2379
51.160495300, 18.870, 497.0, 22.2935
51.203961060, 18.870, 535.0, 23.1301
51.247426820, 18.870, 523.0, 22.8692
51.290892580, 18.870, 510.0, 22.5832
51.334358340, 18.870, 512.0, 22.6274
51.377824100, 18.870, 527.0, 22.9565
51.421289860, 18.870, 529.0, 23.0000
51.464755620, 18.870, 473.0, 21.7486
51.508221380, 18.870, 515.0, 22.6936
51.551687140, 18.870, 512.0, 22.6274
51.595152900, 18.870, 530.0, 23.0217
51.638618660, 18.870, 560.0, 23.6643
51.682084420, 18.870, 550.0, 23.4521
51.725550180, 18.870, 622.0, 24.9399
51.769015940, 18.870, 546.0, 23.3666
51.812481700, 18.870, 602.0, 24.5357
51.855947460, 18.870, 588.0, 24.2487
51.899413220, 18.870, 570.0, 23.8747
51.942878980, 18.870, 611.0, 24.7184
51.986344740, 18.870, 606.0, 24.6171
52.029810500, 18.870, 626.0, 25.0200
52.073276260, 18.870, 624.0, 24.9800
52.116742020, 18.870, 638.0, 25.2587
52.160207780, 18.870, 594.0, 24.3721
52.203673540, 18.870, 612.0, 24.7386
52.247139300, 18.870, 617.0, 24.8395
52.290605060, 18.870, 594.0, 24.3721
52.334070820, 18.870, 545.0, 23.3452
52.377536580, 18.870, 528.0, 22.9783
52.421002340, 18.870, 513.0, 22.6495
52.464468100, 18.870, 522.0, 22.8473
52.507933860, 18.870, 515.0, 22.6936
52.551399620, 18.870, 547.0, 23.3880
52.594865380, 18.870, 521.0, 22.8254
52.638331140, 18.870, 526.0, 22.9347
52.681796900, 18.870, 540.0, 23.2379
52.725262660, 18.870, 550.0, 23.4521
52.768728420, 18.870, 587.0, 24.2281
52.812194180, 18.870, 579.0, 24.0624
52.855659940, 18.870, 579.0, 24.0624
52.899125700, 18.870, 594.0, 24.3721
52.942591460, 18.870, 566.0, 23.7908
52.986057220, 18.870, 596.0, 24.4131
53.029522980, 18.870, 528.0, 22.9783
53.072988740, 18.870, 528.0, 22.9783
53.116454500, 18.870, 515.0, 22.6936
53.159920260, 18.870, 537.0, 23.1733
53.203386020, 18.870, 545.0, 23.3452
53.246851780, 18.870, 526.0, 22.9347
53.290317540, 18.870, 497.0, 22.2935
53.333783300, 18.870, 480.0, 21.9089
53.377249060, 18.870, 511.0, 22.6053
53.420714820, 18.870, 495.0, 22.2486
53.464180580, 18.870, 478.0, 21.8632
53.507646340, 18.870, 513.0, 22.6495
53.551112100, 18.870, 514.0, 22.6716
53.594577860, 18.870, 493.0, 22.2036
53.638043620, 18.870, 519.0, 22.7816
53.681509380, 18.870, 485.0, 22.0227
53.724975140, 18.870, 491.0, 22.1585
53.768440900, 18.870, 471.0, 21.7025
53.811906660, 18.870, 505.0, 22.4722
53.855372420, 18.870, 468.0, 21.6333
53.898838180, 18.870, 448.0, 21.1660
53.942303940, 18.870, 470.0, 21.6795
53.985769700, 18.870, 484.0, 22.0000
54.029235460, 18.870, 473.0, 21.7486
54.072701220, 18.870, 507.0, 22.5167
54.116166980, 18.870, 545.0, 23.3452
54.159632740, 18.870, 524.0, 22.8910
54.203098500, 18.870, 466.0, 21.5870
54.246564260, 18.870, 571.0, 23.8956
54.290030020, 18.870, 525.0, 22.9129
54.333495780, 18.870, 537.0, 23.1733
54.376961540, 18.870, 502.0, 22.4054
54.420427300, 18.870, 441.0, 21.0000
54.463893060, 18.870, 480.0, 21.9089
54.507358820, 18.870, 488.0, 22.0907
54.550824580, 18.870, 510.0, 22.5832
54.594290340, 18.870, 470.0, 21.6795
54.637756100, 18.870, 449.0, 21.1896
54.681221860, 18.870, 478.0, 21.8632
54.724687620, 18.870, 460.0, 21.4476
54.768153380, 18.870, 441.0, 21.0000
54.811619140, 18.870, 488.0, 22.0907
54.855084900, 18.870, 471.0, 21.7025
54.898550660, 18.870, 461.0, 21.4709
54.942016420, 18.870, 420.0, 20.4939
54.985482180, 18.870, 505.0, 22.4722
55.028947940, 18.870, 511.0, 22.6053
55.072413700, 18.870, 510.0, 22.5832
55.115879460, 18.870, 499.0, 22.3383
55.159345220, 18.870, 465.0, 21.5639
55.202810980, 18.870, 463.0, 21.5174
55.246276740, 18.870, 499.0, 22.3383
55.289742500, 18.870, 484.0, 22.0000
55.333208260, 18.870, 492.0, 22.1811
55.376674020, 18.870, 437.0, 20.9045
55.420139780, 18.870, 478.0, 21.8632
55.463605540, 18.870, 481.0, 21.9317
55.507071300, 18.870, 427.0, 20.6640
55.550537060, 18.870, 464.0, 21.5407
55.594002820, 18.870, 434.0, 20.8327
55.637468580, 18.870, 523.0, 22.8692
55.680934340, 18.870, 436.0, 20.8806
55.724400100, 18.870, 517.0, 22.7376
55.767865860, 18.870, 469.0, 21.6564
55.811331620, 18.870, 472.0, 21.7256
55.854797380, 18.870, 466.0, 21.5870
55.898263140, 18.870, 468.0, 21.6333
55.941728900, 18.870, 477.0, 21.8403
55.985194660, 18.870, 459.0, 21.4243
56.028660420, 18.870, 465.0, 21.5639
56.072126180, 18.870, 435.0, 20.8567
56.115591940, 18.870, 448.0, 21.1660
56.159057700, 18.870, 451.0, 21.2368
56.202523460, 18.870, 443.0, 21.0476
56.245989220, 18.870, 474.0, 21.7715
56.289454980, 18.870, 415.0, 20.3715
56.332920740, 18.870, 404.0, 20.0998
56.376386500, 18.870, 407.0, 20.1742
56.419852260, 18.870, 436.0, 20.8806
56.463318020, 18.870, 474.0, 21.7715
56.506783780, 18.870, 444.0, 21.0713
56.550249540, 18.870, 426.0, 20.6398
56.593715300, 18.870, 403.0, 20.0749
56.637181060, 18.870, 434.0, 20.8327
56.680646820, 18.870, 434.0, 20.8327
56.724112580, 18.870, 425.0, 20.6155
56.767578340, 18.870, 397.0, 19.9249
56.811044100, 18.870, 470.0, 21.6795
56.854509860, 18.870, 442.0, 21.0238
56.897975620, 18.870, 414.0, 20.3470
56.941441380, 18.870, 442.0, 21.0238
56.984907140, 18.870, 415.0, 20.3715
57.028372900, 18.870, 410.0, 20.2485
57.071838660, 18.870, 438.0, 20.9284
57.115304420, 18.870, 469.0, 21.6564
57.158770180, 18.870, 423.0, 20.5670
57.202235940, 18.870, 422.0, 20.5426
57.245701700, 18.870, 440.0, 20.9762
57.289167460, 18.870, 421.0, 20.5183
57.332633220, 18.870, 409.0, 20.2237
57.376098980, 18.870, 406.0, 20.1494
57.419564740, 18.870, 421.0, 20.5183
57.463030500, 18.870, 462.0, 21.4942
57.506496260, 18.870, 424.0, 20.5913
57.549962020, 18.870, 349.0, 18.6815
57.593427780, 18.870, 378.0, 19.4422
57.636893540, 18.870, 439.0, 20.9523
57.680359300, 18.870, 359.0, 18.9473
57.723825060, 18.870, 384.0, 19.5959
57.767290820, 18.870, 352.0, 18.7617
57.810756580, 18.870, 372.0, 19.2873
57.854222340, 18.870, 383.0, 19.5704
57.897688100, 18.870, 399.0, 19.9750
57.941153860, 18.870, 416.0, 20.3961
57.984619620, 18.870, 374.0, 19.3391
58.028085380, 18.870, 399.0, 19.9750
58.071551140, 18.870, 383.0, 19.5704
58.115016900, 18.870, 402.0, 20.0499
58.158482660, 18.870, 389.0, 19.7231
58.201948420, 18.870, 381.0, 19.5192
58.245414180, 18.870, 396.0, 19.8997
58.288879940, 18.870, 375.0, 19.3649
58.332345700, 18.870, 396.0, 19.8997
58.375811460, 18.870, 406.0, 20.1494
58.419277220, 18.870, 344.0, 18.5472
58.462742980, 18.870, 409.0, 20.2237
58.506208740, 18.870, 409.0, 20.2237
58.549674500, 18.870, 456.0, 21.3542
58.593140260, 18.870, 445.0, 21.0950
58.636606020, 18.870, 436.0, 20.8806
58.680071780, 18.870, 426.0, 20.6398
58.723537540, 18.870, 457.0, 21.3776
58.767003300, 18.870, 388.0, 19.6977
58.810469060, 18.870, 421.0, 20.5183
58.853934820, 18.870, 363.0, 19.0526
58.897400580, 18.870, 402.0, 20.0499
58.940866340, 18.870, 426.0, 20.6398
58.984332100, 18.870, 356.0, 18.8680
59.027797860, 18.870, 421.0, 20.5183
59.071263620, 18.870, 351.0, 18.7350
59.114729380, 18.870, 373.0, 19.3132
59.158195140, 18.870, 384.0, 19.5959
59.201660900, 18.870, 411.0, 20.2731
59.245126660, 18.870, 371.0, 19.2614
59.288592420, 18.870, 389.0, 19.7231
59.332058180, 18.870, 385.0, 19.6214
59.375523940, 18.870, 424.0, 20.5913
59.418989700, 18.870, 408.0, 20.1990
59.462455460, 18.870, 435.0, 20.8567
59.505921220, 18.870, 423.0, 20.5670
59.549386980, 18.870, 421.0, 20.5183
59.592852740, 18.870, 404.0, 20.0998
59.636318500, 18.870, 361.0, 19.0000
59.679784260, 18.870, 365.0, 19.1050
59.723250020, 18.870, 383.0, 19.5704
59.766715780, 18.870, 382.0, 19.5448
59.810181540, 18.870, 395.0, 19.8746
59.853647300, 18.870, 363.0, 19.0526
59.897113060, 18.870, 354.0, 18.8149
59.940578820, 18.870, 366.0, 19.1311
59.984044580, 18.870, 338.0, 18.3848
59.994911020, 18.870, 334.0, 18.2757