File: XRD/2025_06_03_CBD_Sorbic_Acid_MC15.csv
[Measurement conditions]
Sample identification,2025_06_03_CBD_Sorbic_Acid_MC15
Comment - 1,"CBD - Sorbic Acid, MC 15 min, heptane, 5/14/25, JL"
Anode material,Cu
K-Alpha1 wavelength,1.5405980
K-Alpha2 wavelength,1.5444260
Ratio K-Alpha2/K-Alpha1,0.500
Divergence slit,Fixed,0.76mm
Monochromator used,NO
Generator voltage, 40
Tube current, 15
File date and time,03/Jun/2025 14:05
Unit cell,
h k l, 0 0 0
Scan axis,Gonio
Scan range,10.000000000,80.001606480
Scan step size,0.0108664
No. of points, 6442
Scan type,CONTINUOUS
Time per step,48.195
[Scan points]
Angle, TimePerStep, Intensity, ESD
10.005433220, 48.195, 6618.0, 81.3511
10.059765420, 48.195, 8663.0, 93.0752
10.114097620, 48.195, 11014.0, 104.9476
10.168429820, 48.195, 13865.0, 117.7497
10.222762020, 48.195, 16163.0, 127.1338
10.277094220, 48.195, 15803.0, 125.7100
10.331426420, 48.195, 10857.0, 104.1969
10.385758620, 48.195, 5014.0, 70.8096
10.440090820, 48.195, 2990.0, 54.6809
10.494423020, 48.195, 2697.0, 51.9326
10.548755220, 48.195, 2581.0, 50.8035
10.603087420, 48.195, 2563.0, 50.6261
10.657419620, 48.195, 2552.0, 50.5173
10.711751820, 48.195, 2622.0, 51.2055
10.766084020, 48.195, 2543.0, 50.4282
10.820416220, 48.195, 2666.0, 51.6333
10.874748420, 48.195, 2667.0, 51.6430
10.929080620, 48.195, 3016.0, 54.9181
10.983412820, 48.195, 3194.0, 56.5155
11.037745020, 48.195, 3666.0, 60.5475
11.092077220, 48.195, 4365.0, 66.0681
11.146409420, 48.195, 5279.0, 72.6567
11.200741620, 48.195, 7115.0, 84.3505
11.255073820, 48.195, 9868.0, 99.3378
11.309406020, 48.195, 13022.0, 114.1140
11.363738220, 48.195, 16152.0, 127.0905
11.418070420, 48.195, 17850.0, 133.6039
11.472402620, 48.195, 16092.0, 126.8542
11.526734820, 48.195, 10538.0, 102.6548
11.581067020, 48.195, 7845.0, 88.5720
11.635399220, 48.195, 8471.0, 92.0380
11.689731420, 48.195, 10246.0, 101.2225
11.744063620, 48.195, 11798.0, 108.6186
11.798395820, 48.195, 11746.0, 108.3790
11.852728020, 48.195, 8370.0, 91.4877
11.907060220, 48.195, 4509.0, 67.1491
11.961392420, 48.195, 3077.0, 55.4707
12.015724620, 48.195, 2702.0, 51.9808
12.070056820, 48.195, 2947.0, 54.2863
12.124389020, 48.195, 3061.0, 55.3263
12.178721220, 48.195, 3223.0, 56.7715
12.233053420, 48.195, 3529.0, 59.4054
12.287385620, 48.195, 4259.0, 65.2610
12.341717820, 48.195, 5361.0, 73.2189
12.396050020, 48.195, 7182.0, 84.7467
12.450382220, 48.195, 8727.0, 93.4184
12.504714420, 48.195, 10166.0, 100.8266
12.559046620, 48.195, 10607.0, 102.9903
12.613378820, 48.195, 8557.0, 92.5041
12.667711020, 48.195, 6362.0, 79.7621
12.722043220, 48.195, 6932.0, 83.2586
12.776375420, 48.195, 9531.0, 97.6268
12.830707620, 48.195, 12973.0, 113.8991
12.885039820, 48.195, 16884.0, 129.9384
12.939372020, 48.195, 20312.0, 142.5202
12.993704220, 48.195, 22491.0, 149.9700
13.048036420, 48.195, 19462.0, 139.5063
13.102368620, 48.195, 16253.0, 127.4873
13.156700820, 48.195, 15630.0, 125.0200
13.211033020, 48.195, 14109.0, 118.7813
13.265365220, 48.195, 9544.0, 97.6934
13.319697420, 48.195, 5169.0, 71.8958
13.374029620, 48.195, 3628.0, 60.2329
13.428361820, 48.195, 3414.0, 58.4294
13.482694020, 48.195, 3640.0, 60.3324
13.537026220, 48.195, 4105.0, 64.0703
13.591358420, 48.195, 5124.0, 71.5821
13.645690620, 48.195, 7356.0, 85.7671
13.700022820, 48.195, 9256.0, 96.2081
13.754355020, 48.195, 10911.0, 104.4557
13.808687220, 48.195, 11672.0, 108.0370
13.863019420, 48.195, 9913.0, 99.5640
13.917351620, 48.195, 5823.0, 76.3086
13.971683820, 48.195, 3251.0, 57.0175
14.026016020, 48.195, 2724.0, 52.1920
14.080348220, 48.195, 2518.0, 50.1797
14.134680420, 48.195, 2542.0, 50.4183
14.189012620, 48.195, 2484.0, 49.8397
14.243344820, 48.195, 2535.0, 50.3488
14.297677020, 48.195, 2370.0, 48.6826
14.352009220, 48.195, 2491.0, 49.9099
14.406341420, 48.195, 2497.0, 49.9700
14.460673620, 48.195, 2515.0, 50.1498
14.515005820, 48.195, 2515.0, 50.1498
14.569338020, 48.195, 2605.0, 51.0392
14.623670220, 48.195, 2667.0, 51.6430
14.678002420, 48.195, 2920.0, 54.0370
14.732334620, 48.195, 3063.0, 55.3444
14.786666820, 48.195, 3568.0, 59.7327
14.840999020, 48.195, 4372.0, 66.1211
14.895331220, 48.195, 5909.0, 76.8700
14.949663420, 48.195, 8439.0, 91.8640
15.003995620, 48.195, 10986.0, 104.8141
15.058327820, 48.195, 13343.0, 115.5119
15.112660020, 48.195, 14345.0, 119.7706
15.166992220, 48.195, 11983.0, 109.4669
15.221324420, 48.195, 7125.0, 84.4097
15.275656620, 48.195, 4463.0, 66.8057
15.329988820, 48.195, 3974.0, 63.0397
15.384321020, 48.195, 3892.0, 62.3859
15.438653220, 48.195, 3895.0, 62.4099
15.492985420, 48.195, 3105.0, 55.7225
15.547317620, 48.195, 2627.0, 51.2543
15.601649820, 48.195, 2562.0, 50.6162
15.655982020, 48.195, 2472.0, 49.7192
15.710314220, 48.195, 2500.0, 50.0000
15.764646420, 48.195, 2595.0, 50.9411
15.818978620, 48.195, 2683.0, 51.7977
15.873310820, 48.195, 2930.0, 54.1295
15.927643020, 48.195, 3223.0, 56.7715
15.981975220, 48.195, 3736.0, 61.1228
16.036307420, 48.195, 4326.0, 65.7723
16.090639620, 48.195, 4308.0, 65.6354
16.144971820, 48.195, 4219.0, 64.9538
16.199304020, 48.195, 3552.0, 59.5987
16.253636220, 48.195, 2791.0, 52.8299
16.307968420, 48.195, 2658.0, 51.5558
16.362300620, 48.195, 2750.0, 52.4404
16.416632820, 48.195, 3070.0, 55.4076
16.470965020, 48.195, 3724.0, 61.0246
16.525297220, 48.195, 4099.0, 64.0234
16.579629420, 48.195, 4707.0, 68.6076
16.633961620, 48.195, 4719.0, 68.6950
16.688293820, 48.195, 4592.0, 67.7643
16.742626020, 48.195, 3951.0, 62.8570
16.796958220, 48.195, 3467.0, 58.8812
16.851290420, 48.195, 3902.0, 62.4660
16.905622620, 48.195, 4307.0, 65.6277
16.959954820, 48.195, 4755.0, 68.9565
17.014287020, 48.195, 5370.0, 73.2803
17.068619220, 48.195, 5652.0, 75.1798
17.122951420, 48.195, 5861.0, 76.5572
17.177283620, 48.195, 7114.0, 84.3445
17.231615820, 48.195, 10627.0, 103.0873
17.285948020, 48.195, 15365.0, 123.9556
17.340280220, 48.195, 19466.0, 139.5206
17.394612420, 48.195, 22002.0, 148.3307
17.448944620, 48.195, 21401.0, 146.2908
17.503276820, 48.195, 14863.0, 121.9139
17.557609020, 48.195, 7602.0, 87.1894
17.611941220, 48.195, 4137.0, 64.3195
17.666273420, 48.195, 3321.0, 57.6281
17.720605620, 48.195, 3463.0, 58.8473
17.774937820, 48.195, 3924.0, 62.6418
17.829270020, 48.195, 4556.0, 67.4981
17.883602220, 48.195, 4855.0, 69.6778
17.937934420, 48.195, 5302.0, 72.8148
17.992266620, 48.195, 4982.0, 70.5833
18.046598820, 48.195, 4660.0, 68.2642
18.100931020, 48.195, 4392.0, 66.2722
18.155263220, 48.195, 4759.0, 68.9855
18.209595420, 48.195, 5100.0, 71.4143
18.263927620, 48.195, 5189.0, 72.0347
18.318259820, 48.195, 4730.0, 68.7750
18.372592020, 48.195, 4081.0, 63.8827
18.426924220, 48.195, 3960.0, 62.9285
18.481256420, 48.195, 4692.0, 68.4982
18.535588620, 48.195, 6489.0, 80.5543
18.589920820, 48.195, 9199.0, 95.9114
18.644253020, 48.195, 13024.0, 114.1227
18.698585220, 48.195, 17028.0, 130.4914
18.752917420, 48.195, 19280.0, 138.8524
18.807249620, 48.195, 21079.0, 145.1861
18.861581820, 48.195, 19406.0, 139.3054
18.915914020, 48.195, 15843.0, 125.8690
18.970246220, 48.195, 13577.0, 116.5204
19.024578420, 48.195, 12174.0, 110.3359
19.078910620, 48.195, 9294.0, 96.4054
19.133242820, 48.195, 7241.0, 85.0941
19.187575020, 48.195, 6330.0, 79.5613
19.241907220, 48.195, 5267.0, 72.5741
19.296239420, 48.195, 4981.0, 70.5762
19.350571620, 48.195, 5634.0, 75.0600
19.404903820, 48.195, 6630.0, 81.4248
19.459236020, 48.195, 7700.0, 87.7496
19.513568220, 48.195, 8374.0, 91.5096
19.567900420, 48.195, 8487.0, 92.1249
19.622232620, 48.195, 7229.0, 85.0235
19.676564820, 48.195, 5390.0, 73.4166
19.730897020, 48.195, 4571.0, 67.6092
19.785229220, 48.195, 4487.0, 66.9851
19.839561420, 48.195, 4499.0, 67.0746
19.893893620, 48.195, 3707.0, 60.8851
19.948225820, 48.195, 3416.0, 58.4466
20.002558020, 48.195, 3414.0, 58.4294
20.056890220, 48.195, 3416.0, 58.4466
20.111222420, 48.195, 3435.0, 58.6089
20.165554620, 48.195, 3490.0, 59.0762
20.219886820, 48.195, 3717.0, 60.9672
20.274219020, 48.195, 4402.0, 66.3476
20.328551220, 48.195, 5777.0, 76.0066
20.382883420, 48.195, 8393.0, 91.6133
20.437215620, 48.195, 11356.0, 106.5645
20.491547820, 48.195, 13995.0, 118.3005
20.545880020, 48.195, 15432.0, 124.2256
20.600212220, 48.195, 15428.0, 124.2095
20.654544420, 48.195, 11677.0, 108.0602
20.708876620, 48.195, 7510.0, 86.6603
20.763208820, 48.195, 6160.0, 78.4857
20.817541020, 48.195, 7027.0, 83.8272
20.871873220, 48.195, 7696.0, 87.7268
20.926205420, 48.195, 7759.0, 88.0852
20.980537620, 48.195, 7050.0, 83.9643
21.034869820, 48.195, 5234.0, 72.3464
21.089202020, 48.195, 3787.0, 61.5386
21.143534220, 48.195, 3528.0, 59.3970
21.197866420, 48.195, 3402.0, 58.3267
21.252198620, 48.195, 3465.0, 58.8643
21.306530820, 48.195, 3741.0, 61.1637
21.360863020, 48.195, 4037.0, 63.5374
21.415195220, 48.195, 4887.0, 69.9071
21.469527420, 48.195, 6783.0, 82.3590
21.523859620, 48.195, 10269.0, 101.3361
21.578191820, 48.195, 13522.0, 116.2841
21.632524020, 48.195, 16051.0, 126.6925
21.686856220, 48.195, 16876.0, 129.9077
21.741188420, 48.195, 14699.0, 121.2394
21.795520620, 48.195, 10249.0, 101.2373
21.849852820, 48.195, 7497.0, 86.5852
21.904185020, 48.195, 8923.0, 94.4616
21.958517220, 48.195, 13077.0, 114.3547
22.012849420, 48.195, 18792.0, 137.0839
22.067181620, 48.195, 24062.0, 155.1193
22.121513820, 48.195, 26361.0, 162.3607
22.175846020, 48.195, 25481.0, 159.6277
22.230178220, 48.195, 21461.0, 146.4957
22.284510420, 48.195, 15496.0, 124.4829
22.338842620, 48.195, 9718.0, 98.5799
22.393174820, 48.195, 7825.0, 88.4590
22.447507020, 48.195, 8707.0, 93.3113
22.501839220, 48.195, 11750.0, 108.3974
22.556171420, 48.195, 18902.0, 137.4845
22.610503620, 48.195, 29303.0, 171.1812
22.664835820, 48.195, 39617.0, 199.0402
22.719168020, 48.195, 47753.0, 218.5246
22.773500220, 48.195, 52200.0, 228.4732
22.827832420, 48.195, 46480.0, 215.5922
22.882164620, 48.195, 32758.0, 180.9917
22.936496820, 48.195, 23569.0, 153.5220
22.990829020, 48.195, 18051.0, 134.3540
23.045161220, 48.195, 12400.0, 111.3553
23.099493420, 48.195, 8596.0, 92.7146
23.153825620, 48.195, 6975.0, 83.5165
23.208157820, 48.195, 7546.0, 86.8677
23.262490020, 48.195, 9079.0, 95.2838
23.316822220, 48.195, 10509.0, 102.5134
23.371154420, 48.195, 11369.0, 106.6255
23.425486620, 48.195, 11007.0, 104.9143
23.479818820, 48.195, 9454.0, 97.2317
23.534151020, 48.195, 7814.0, 88.3968
23.588483220, 48.195, 7991.0, 89.3924
23.642815420, 48.195, 9037.0, 95.0631
23.697147620, 48.195, 9977.0, 99.8849
23.751479820, 48.195, 10314.0, 101.5579
23.805812020, 48.195, 9723.0, 98.6053
23.860144220, 48.195, 7874.0, 88.7356
23.914476420, 48.195, 6223.0, 78.8860
23.968808620, 48.195, 4829.0, 69.4910
24.023140820, 48.195, 3978.0, 63.0714
24.077473020, 48.195, 3736.0, 61.1228
24.131805220, 48.195, 3893.0, 62.3939
24.186137420, 48.195, 4354.0, 65.9848
24.240469620, 48.195, 5118.0, 71.5402
24.294801820, 48.195, 6422.0, 80.1374
24.349134020, 48.195, 7420.0, 86.1394
24.403466220, 48.195, 8089.0, 89.9389
24.457798420, 48.195, 8666.0, 93.0914
24.512130620, 48.195, 9469.0, 97.3088
24.566462820, 48.195, 12044.0, 109.7452
24.620795020, 48.195, 17201.0, 131.1526
24.675127220, 48.195, 21901.0, 147.9899
24.729459420, 48.195, 24006.0, 154.9387
24.783791620, 48.195, 22740.0, 150.7979
24.838123820, 48.195, 15807.0, 125.7259
24.892456020, 48.195, 8746.0, 93.5201
24.946788220, 48.195, 5119.0, 71.5472
25.001120420, 48.195, 4261.0, 65.2763
25.055452620, 48.195, 4432.0, 66.5733
25.109784820, 48.195, 4966.0, 70.4699
25.164117020, 48.195, 5930.0, 77.0065
25.218449220, 48.195, 6861.0, 82.8312
25.272781420, 48.195, 7062.0, 84.0357
25.327113620, 48.195, 6794.0, 82.4257
25.381445820, 48.195, 6051.0, 77.7882
25.435778020, 48.195, 5162.0, 71.8471
25.490110220, 48.195, 4585.0, 67.7126
25.544442420, 48.195, 4351.0, 65.9621
25.598774620, 48.195, 4310.0, 65.6506
25.653106820, 48.195, 4173.0, 64.5988
25.707439020, 48.195, 3765.0, 61.3596
25.761771220, 48.195, 3311.0, 57.5413
25.816103420, 48.195, 3084.0, 55.5338
25.870435620, 48.195, 3195.0, 56.5243
25.924767820, 48.195, 3060.0, 55.3173
25.979100020, 48.195, 3126.0, 55.9106
26.033432220, 48.195, 3241.0, 56.9298
26.087764420, 48.195, 3327.0, 57.6802
26.142096620, 48.195, 3631.0, 60.2578
26.196428820, 48.195, 3865.0, 62.1691
26.250761020, 48.195, 4073.0, 63.8201
26.305093220, 48.195, 4374.0, 66.1362
26.359425420, 48.195, 4819.0, 69.4190
26.413757620, 48.195, 5377.0, 73.3280
26.468089820, 48.195, 5802.0, 76.1709
26.522422020, 48.195, 5809.0, 76.2168
26.576754220, 48.195, 5641.0, 75.1066
26.631086420, 48.195, 5199.0, 72.1041
26.685418620, 48.195, 4831.0, 69.5054
26.739750820, 48.195, 4423.0, 66.5056
26.794083020, 48.195, 4014.0, 63.3561
26.848415220, 48.195, 3783.0, 61.5061
26.902747420, 48.195, 3517.0, 59.3043
26.957079620, 48.195, 3898.0, 62.4340
27.011411820, 48.195, 4383.0, 66.2042
27.065744020, 48.195, 4830.0, 69.4982
27.120076220, 48.195, 5300.0, 72.8011
27.174408420, 48.195, 5413.0, 73.5731
27.228740620, 48.195, 5386.0, 73.3894
27.283072820, 48.195, 5247.0, 72.4362
27.337405020, 48.195, 5597.0, 74.8131
27.391737220, 48.195, 6503.0, 80.6412
27.446069420, 48.195, 8207.0, 90.5925
27.500401620, 48.195, 10748.0, 103.6726
27.554733820, 48.195, 15084.0, 122.8169
27.609066020, 48.195, 19977.0, 141.3400
27.663398220, 48.195, 23875.0, 154.5154
27.717730420, 48.195, 25190.0, 158.7136
27.772062620, 48.195, 22176.0, 148.9161
27.826394820, 48.195, 14908.0, 122.0983
27.880727020, 48.195, 8321.0, 91.2195
27.935059220, 48.195, 4798.0, 69.2676
27.989391420, 48.195, 3882.0, 62.3057
28.043723620, 48.195, 3559.0, 59.6574
28.098055820, 48.195, 3611.0, 60.0916
28.152388020, 48.195, 3436.0, 58.6174
28.206720220, 48.195, 3414.0, 58.4294
28.261052420, 48.195, 3456.0, 58.7878
28.315384620, 48.195, 3522.0, 59.3464
28.369716820, 48.195, 3730.0, 61.0737
28.424049020, 48.195, 3778.0, 61.4654
28.478381220, 48.195, 3906.0, 62.4980
28.532713420, 48.195, 3990.0, 63.1664
28.587045620, 48.195, 4039.0, 63.5531
28.641377820, 48.195, 4226.0, 65.0077
28.695710020, 48.195, 4258.0, 65.2534
28.750042220, 48.195, 4383.0, 66.2042
28.804374420, 48.195, 4183.0, 64.6761
28.858706620, 48.195, 4109.0, 64.1015
28.913038820, 48.195, 4867.0, 69.7639
28.967371020, 48.195, 5943.0, 77.0909
29.021703220, 48.195, 6871.0, 82.8915
29.076035420, 48.195, 7129.0, 84.4334
29.130367620, 48.195, 6701.0, 81.8596
29.184699820, 48.195, 5553.0, 74.5185
29.239032020, 48.195, 4070.0, 63.7966
29.293364220, 48.195, 3515.0, 59.2874
29.347696420, 48.195, 3240.0, 56.9210
29.402028620, 48.195, 3364.0, 58.0000
29.456360820, 48.195, 3217.0, 56.7186
29.510693020, 48.195, 3319.0, 57.6108
29.565025220, 48.195, 3143.0, 56.0625
29.619357420, 48.195, 2947.0, 54.2863
29.673689620, 48.195, 2760.0, 52.5357
29.728021820, 48.195, 2480.0, 49.7996
29.782354020, 48.195, 2319.0, 48.1560
29.836686220, 48.195, 2303.0, 47.9896
29.891018420, 48.195, 2294.0, 47.8957
29.945350620, 48.195, 2270.0, 47.6445
29.999682820, 48.195, 2275.0, 47.6970
30.054015020, 48.195, 2232.0, 47.2440
30.108347220, 48.195, 2233.0, 47.2546
30.162679420, 48.195, 2341.0, 48.3839
30.217011620, 48.195, 2485.0, 49.8498
30.271343820, 48.195, 2568.0, 50.6754
30.325676020, 48.195, 2729.0, 52.2398
30.380008220, 48.195, 2896.0, 53.8145
30.434340420, 48.195, 2847.0, 53.3573
30.488672620, 48.195, 2795.0, 52.8678
30.543004820, 48.195, 2864.0, 53.5164
30.597337020, 48.195, 2832.0, 53.2165
30.651669220, 48.195, 2728.0, 52.2303
30.706001420, 48.195, 2831.0, 53.2071
30.760333620, 48.195, 2788.0, 52.8015
30.814665820, 48.195, 2665.0, 51.6236
30.868998020, 48.195, 2549.0, 50.4876
30.923330220, 48.195, 2609.0, 51.0784
30.977662420, 48.195, 2821.0, 53.1131
31.031994620, 48.195, 3207.0, 56.6304
31.086326820, 48.195, 3712.0, 60.9262
31.140659020, 48.195, 3709.0, 60.9016
31.194991220, 48.195, 3856.0, 62.0967
31.249323420, 48.195, 3707.0, 60.8851
31.303655620, 48.195, 3380.0, 58.1378
31.357987820, 48.195, 3224.0, 56.7803
31.412320020, 48.195, 3196.0, 56.5332
31.466652220, 48.195, 3250.0, 57.0088
31.520984420, 48.195, 3240.0, 56.9210
31.575316620, 48.195, 3145.0, 56.0803
31.629648820, 48.195, 2928.0, 54.1110
31.683981020, 48.195, 2725.0, 52.2015
31.738313220, 48.195, 2533.0, 50.3289
31.792645420, 48.195, 2729.0, 52.2398
31.846977620, 48.195, 2812.0, 53.0283
31.901309820, 48.195, 3001.0, 54.7814
31.955642020, 48.195, 3178.0, 56.3738
32.009974220, 48.195, 3529.0, 59.4054
32.064306420, 48.195, 3788.0, 61.5467
32.118638620, 48.195, 4239.0, 65.1076
32.172970820, 48.195, 4167.0, 64.5523
32.227303020, 48.195, 3973.0, 63.0317
32.281635220, 48.195, 3173.0, 56.3294
32.335967420, 48.195, 3169.0, 56.2939
32.390299620, 48.195, 3244.0, 56.9561
32.444631820, 48.195, 3697.0, 60.8030
32.498964020, 48.195, 4128.0, 64.2495
32.553296220, 48.195, 4040.0, 63.5610
32.607628420, 48.195, 3907.0, 62.5060
32.661960620, 48.195, 3528.0, 59.3970
32.716292820, 48.195, 2916.0, 54.0000
32.770625020, 48.195, 2648.0, 51.4587
32.824957220, 48.195, 2651.0, 51.4879
32.879289420, 48.195, 2703.0, 51.9904
32.933621620, 48.195, 2667.0, 51.6430
32.987953820, 48.195, 2524.0, 50.2394
33.042286020, 48.195, 2533.0, 50.3289
33.096618220, 48.195, 2548.0, 50.4777
33.150950420, 48.195, 2777.0, 52.6972
33.205282620, 48.195, 2988.0, 54.6626
33.259614820, 48.195, 3042.0, 55.1543
33.313947020, 48.195, 3085.0, 55.5428
33.368279220, 48.195, 2988.0, 54.6626
33.422611420, 48.195, 2687.0, 51.8363
33.476943620, 48.195, 2484.0, 49.8397
33.531275820, 48.195, 2387.0, 48.8569
33.585608020, 48.195, 2373.0, 48.7134
33.639940220, 48.195, 2457.0, 49.5681
33.694272420, 48.195, 2506.0, 50.0600
33.748604620, 48.195, 2544.0, 50.4381
33.802936820, 48.195, 2610.0, 51.0882
33.857269020, 48.195, 2899.0, 53.8424
33.911601220, 48.195, 3404.0, 58.3438
33.965933420, 48.195, 3551.0, 59.5903
34.020265620, 48.195, 3564.0, 59.6992
34.074597820, 48.195, 3561.0, 59.6741
34.128930020, 48.195, 2980.0, 54.5894
34.183262220, 48.195, 2707.0, 52.0288
34.237594420, 48.195, 2482.0, 49.8197
34.291926620, 48.195, 2453.0, 49.5278
34.346258820, 48.195, 2488.0, 49.8799
34.400591020, 48.195, 2575.0, 50.7445
34.454923220, 48.195, 2686.0, 51.8266
34.509255420, 48.195, 2771.0, 52.6403
34.563587620, 48.195, 2817.0, 53.0754
34.617919820, 48.195, 2969.0, 54.4885
34.672252020, 48.195, 3205.0, 56.6127
34.726584220, 48.195, 3359.0, 57.9569
34.780916420, 48.195, 3126.0, 55.9106
34.835248620, 48.195, 3025.0, 55.0000
34.889580820, 48.195, 2841.0, 53.3010
34.943913020, 48.195, 2714.0, 52.0961
34.998245220, 48.195, 2752.0, 52.4595
35.052577420, 48.195, 2776.0, 52.6878
35.106909620, 48.195, 2878.0, 53.6470
35.161241820, 48.195, 2909.0, 53.9351
35.215574020, 48.195, 2897.0, 53.8238
35.269906220, 48.195, 3005.0, 54.8179
35.324238420, 48.195, 2833.0, 53.2259
35.378570620, 48.195, 2678.0, 51.7494
35.432902820, 48.195, 2591.0, 50.9019
35.487235020, 48.195, 2699.0, 51.9519
35.541567220, 48.195, 2794.0, 52.8583
35.595899420, 48.195, 2897.0, 53.8238
35.650231620, 48.195, 3005.0, 54.8179
35.704563820, 48.195, 2858.0, 53.4603
35.758896020, 48.195, 3092.0, 55.6058
35.813228220, 48.195, 3376.0, 58.1034
35.867560420, 48.195, 3441.0, 58.6600
35.921892620, 48.195, 3622.0, 60.1831
35.976224820, 48.195, 3531.0, 59.4222
36.030557020, 48.195, 3056.0, 55.2811
36.084889220, 48.195, 2625.0, 51.2348
36.139221420, 48.195, 2288.0, 47.8330
36.193553620, 48.195, 2235.0, 47.2758
36.247885820, 48.195, 2202.0, 46.9255
36.302218020, 48.195, 2215.0, 47.0638
36.356550220, 48.195, 2349.0, 48.4665
36.410882420, 48.195, 2470.0, 49.6991
36.465214620, 48.195, 2545.0, 50.4480
36.519546820, 48.195, 2721.0, 52.1632
36.573879020, 48.195, 2797.0, 52.8867
36.628211220, 48.195, 2850.0, 53.3854
36.682543420, 48.195, 2685.0, 51.8170
36.736875620, 48.195, 2598.0, 50.9706
36.791207820, 48.195, 2674.0, 51.7107
36.845540020, 48.195, 2780.0, 52.7257
36.899872220, 48.195, 2949.0, 54.3047
36.954204420, 48.195, 3003.0, 54.7996
37.008536620, 48.195, 3042.0, 55.1543
37.062868820, 48.195, 2856.0, 53.4416
37.117201020, 48.195, 2575.0, 50.7445
37.171533220, 48.195, 2360.0, 48.5798
37.225865420, 48.195, 2255.0, 47.4868
37.280197620, 48.195, 2120.0, 46.0435
37.334529820, 48.195, 2111.0, 45.9456
37.388862020, 48.195, 2098.0, 45.8039
37.443194220, 48.195, 2118.0, 46.0217
37.497526420, 48.195, 2090.0, 45.7165
37.551858620, 48.195, 2127.0, 46.1194
37.606190820, 48.195, 2081.0, 45.6180
37.660523020, 48.195, 2041.0, 45.1774
37.714855220, 48.195, 2227.0, 47.1911
37.769187420, 48.195, 2401.0, 49.0000
37.823519620, 48.195, 2422.0, 49.2138
37.877851820, 48.195, 2507.0, 50.0700
37.932184020, 48.195, 2230.0, 47.2229
37.986516220, 48.195, 2236.0, 47.2864
38.040848420, 48.195, 2258.0, 47.5184
38.095180620, 48.195, 2330.0, 48.2701
38.149512820, 48.195, 2268.0, 47.6235
38.203845020, 48.195, 2218.0, 47.0956
38.258177220, 48.195, 2143.0, 46.2925
38.312509420, 48.195, 2073.0, 45.5302
38.366841620, 48.195, 1890.0, 43.4741
38.421173820, 48.195, 2012.0, 44.8553
38.475506020, 48.195, 1873.0, 43.2782
38.529838220, 48.195, 1998.0, 44.6990
38.584170420, 48.195, 1903.0, 43.6234
38.638502620, 48.195, 1946.0, 44.1135
38.692834820, 48.195, 1989.0, 44.5982
38.747167020, 48.195, 2128.0, 46.1303
38.801499220, 48.195, 2264.0, 47.5815
38.855831420, 48.195, 2280.0, 47.7493
38.910163620, 48.195, 2473.0, 49.7293
38.964495820, 48.195, 2431.0, 49.3052
39.018828020, 48.195, 2465.0, 49.6488
39.073160220, 48.195, 2552.0, 50.5173
39.127492420, 48.195, 2631.0, 51.2933
39.181824620, 48.195, 2868.0, 53.5537
39.236156820, 48.195, 3084.0, 55.5338
39.290489020, 48.195, 2970.0, 54.4977
39.344821220, 48.195, 3037.0, 55.1090
39.399153420, 48.195, 2826.0, 53.1601
39.453485620, 48.195, 2627.0, 51.2543
39.507817820, 48.195, 2535.0, 50.3488
39.562150020, 48.195, 2390.0, 48.8876
39.616482220, 48.195, 2441.0, 49.4065
39.670814420, 48.195, 2401.0, 49.0000
39.725146620, 48.195, 2544.0, 50.4381
39.779478820, 48.195, 3000.0, 54.7723
39.833811020, 48.195, 3394.0, 58.2580
39.888143220, 48.195, 3822.0, 61.8223
39.942475420, 48.195, 4067.0, 63.7730
39.996807620, 48.195, 4001.0, 63.2535
40.051139820, 48.195, 3480.0, 58.9915
40.105472020, 48.195, 2950.0, 54.3139
40.159804220, 48.195, 2610.0, 51.0882
40.214136420, 48.195, 2336.0, 48.3322
40.268468620, 48.195, 2409.0, 49.0816
40.322800820, 48.195, 2375.0, 48.7340
40.377133020, 48.195, 2424.0, 49.2341
40.431465220, 48.195, 2518.0, 50.1797
40.485797420, 48.195, 2576.0, 50.7543
40.540129620, 48.195, 2690.0, 51.8652
40.594461820, 48.195, 2661.0, 51.5849
40.648794020, 48.195, 2683.0, 51.7977
40.703126220, 48.195, 2745.0, 52.3927
40.757458420, 48.195, 2733.0, 52.2781
40.811790620, 48.195, 2726.0, 52.2111
40.866122820, 48.195, 2721.0, 52.1632
40.920455020, 48.195, 2514.0, 50.1398
40.974787220, 48.195, 2325.0, 48.2183
41.029119420, 48.195, 2220.0, 47.1169
41.083451620, 48.195, 2318.0, 48.1456
41.137783820, 48.195, 2377.0, 48.7545
41.192116020, 48.195, 2450.0, 49.4975
41.246448220, 48.195, 2429.0, 49.2849
41.300780420, 48.195, 2262.0, 47.5605
41.355112620, 48.195, 2068.0, 45.4753
41.409444820, 48.195, 2033.0, 45.0888
41.463777020, 48.195, 1865.0, 43.1856
41.518109220, 48.195, 1854.0, 43.0581
41.572441420, 48.195, 1882.0, 43.3820
41.626773620, 48.195, 1883.0, 43.3935
41.681105820, 48.195, 1965.0, 44.3283
41.735438020, 48.195, 2036.0, 45.1221
41.789770220, 48.195, 2128.0, 46.1303
41.844102420, 48.195, 2123.0, 46.0760
41.898434620, 48.195, 2112.0, 45.9565
41.952766820, 48.195, 1995.0, 44.6654
42.007099020, 48.195, 1867.0, 43.2088
42.061431220, 48.195, 1760.0, 41.9524
42.115763420, 48.195, 1767.0, 42.0357
42.170095620, 48.195, 1772.0, 42.0951
42.224427820, 48.195, 1814.0, 42.5911
42.278760020, 48.195, 1838.0, 42.8719
42.333092220, 48.195, 2051.0, 45.2880
42.387424420, 48.195, 2114.0, 45.9783
42.441756620, 48.195, 2259.0, 47.5289
42.496088820, 48.195, 2467.0, 49.6689
42.550421020, 48.195, 2516.0, 50.1597
42.604753220, 48.195, 2612.0, 51.1077
42.659085420, 48.195, 2366.0, 48.6415
42.713417620, 48.195, 2353.0, 48.5077
42.767749820, 48.195, 2175.0, 46.6369
42.822082020, 48.195, 2002.0, 44.7437
42.876414220, 48.195, 1942.0, 44.0681
42.930746420, 48.195, 2045.0, 45.2217
42.985078620, 48.195, 2077.0, 45.5741
43.039410820, 48.195, 2174.0, 46.6262
43.093743020, 48.195, 2367.0, 48.6518
43.148075220, 48.195, 2416.0, 49.1528
43.202407420, 48.195, 2455.0, 49.5480
43.256739620, 48.195, 2348.0, 48.4562
43.311071820, 48.195, 2285.0, 47.8017
43.365404020, 48.195, 2163.0, 46.5081
43.419736220, 48.195, 2006.0, 44.7884
43.474068420, 48.195, 1900.0, 43.5890
43.528400620, 48.195, 1829.0, 42.7668
43.582732820, 48.195, 1795.0, 42.3674
43.637065020, 48.195, 1677.0, 40.9512
43.691397220, 48.195, 1721.0, 41.4849
43.745729420, 48.195, 1681.0, 41.0000
43.800061620, 48.195, 1635.0, 40.4351
43.854393820, 48.195, 1694.0, 41.1582
43.908726020, 48.195, 1592.0, 39.8999
43.963058220, 48.195, 1475.0, 38.4057
44.017390420, 48.195, 1602.0, 40.0250
44.071722620, 48.195, 1571.0, 39.6358
44.126054820, 48.195, 1579.0, 39.7366
44.180387020, 48.195, 1691.0, 41.1218
44.234719220, 48.195, 1701.0, 41.2432
44.289051420, 48.195, 1835.0, 42.8369
44.343383620, 48.195, 1717.0, 41.4367
44.397715820, 48.195, 1691.0, 41.1218
44.452048020, 48.195, 1700.0, 41.2311
44.506380220, 48.195, 1662.0, 40.7676
44.560712420, 48.195, 1691.0, 41.1218
44.615044620, 48.195, 1696.0, 41.1825
44.669376820, 48.195, 1667.0, 40.8289
44.723709020, 48.195, 1674.0, 40.9145
44.778041220, 48.195, 1707.0, 41.3159
44.832373420, 48.195, 1720.0, 41.4729
44.886705620, 48.195, 1910.0, 43.7035
44.941037820, 48.195, 1918.0, 43.7950
44.995370020, 48.195, 2146.0, 46.3249
45.049702220, 48.195, 2256.0, 47.4974
45.104034420, 48.195, 2338.0, 48.3529
45.158366620, 48.195, 2192.0, 46.8188
45.212698820, 48.195, 2106.0, 45.8912
45.267031020, 48.195, 2035.0, 45.1110
45.321363220, 48.195, 1955.0, 44.2154
45.375695420, 48.195, 1883.0, 43.3935
45.430027620, 48.195, 1937.0, 44.0114
45.484359820, 48.195, 1857.0, 43.0929
45.538692020, 48.195, 2035.0, 45.1110
45.593024220, 48.195, 2079.0, 45.5961
45.647356420, 48.195, 2074.0, 45.5412
45.701688620, 48.195, 2126.0, 46.1086
45.756020820, 48.195, 2098.0, 45.8039
45.810353020, 48.195, 2101.0, 45.8367
45.864685220, 48.195, 2197.0, 46.8722
45.919017420, 48.195, 2468.0, 49.6790
45.973349620, 48.195, 2659.0, 51.5655
46.027681820, 48.195, 2796.0, 52.8772
46.082014020, 48.195, 2752.0, 52.4595
46.136346220, 48.195, 2667.0, 51.6430
46.190678420, 48.195, 2350.0, 48.4768
46.245010620, 48.195, 2273.0, 47.6760
46.299342820, 48.195, 2071.0, 45.5082
46.353675020, 48.195, 1983.0, 44.5309
46.408007220, 48.195, 2000.0, 44.7214
46.462339420, 48.195, 1849.0, 43.0000
46.516671620, 48.195, 1916.0, 43.7721
46.571003820, 48.195, 1959.0, 44.2606
46.625336020, 48.195, 1867.0, 43.2088
46.679668220, 48.195, 2119.0, 46.0326
46.734000420, 48.195, 2186.0, 46.7547
46.788332620, 48.195, 2270.0, 47.6445
46.842664820, 48.195, 2201.0, 46.9148
46.896997020, 48.195, 2161.0, 46.4866
46.951329220, 48.195, 1922.0, 43.8406
47.005661420, 48.195, 1783.0, 42.2256
47.059993620, 48.195, 1635.0, 40.4351
47.114325820, 48.195, 1698.0, 41.2068
47.168658020, 48.195, 1591.0, 39.8873
47.222990220, 48.195, 1650.0, 40.6202
47.277322420, 48.195, 1626.0, 40.3237
47.331654620, 48.195, 1632.0, 40.3980
47.385986820, 48.195, 1668.0, 40.8412
47.440319020, 48.195, 1887.0, 43.4396
47.494651220, 48.195, 1835.0, 42.8369
47.548983420, 48.195, 1938.0, 44.0227
47.603315620, 48.195, 1987.0, 44.5758
47.657647820, 48.195, 1866.0, 43.1972
47.711980020, 48.195, 1810.0, 42.5441
47.766312220, 48.195, 1788.0, 42.2847
47.820644420, 48.195, 1779.0, 42.1782
47.874976620, 48.195, 1808.0, 42.5206
47.929308820, 48.195, 1789.0, 42.2966
47.983641020, 48.195, 1824.0, 42.7083
48.037973220, 48.195, 1789.0, 42.2966
48.092305420, 48.195, 1931.0, 43.9431
48.146637620, 48.195, 1906.0, 43.6578
48.200969820, 48.195, 1879.0, 43.3474
48.255302020, 48.195, 1834.0, 42.8252
48.309634220, 48.195, 1820.0, 42.6615
48.363966420, 48.195, 1679.0, 40.9756
48.418298620, 48.195, 1598.0, 39.9750
48.472630820, 48.195, 1520.0, 38.9872
48.526963020, 48.195, 1529.0, 39.1024
48.581295220, 48.195, 1508.0, 38.8330
48.635627420, 48.195, 1628.0, 40.3485
48.689959620, 48.195, 1583.0, 39.7869
48.744291820, 48.195, 1438.0, 37.9210
48.798624020, 48.195, 1512.0, 38.8844
48.852956220, 48.195, 1543.0, 39.2810
48.907288420, 48.195, 1593.0, 39.9124
48.961620620, 48.195, 1619.0, 40.2368
49.015952820, 48.195, 1697.0, 41.1947
49.070285020, 48.195, 1681.0, 41.0000
49.124617220, 48.195, 1663.0, 40.7799
49.178949420, 48.195, 1742.0, 41.7373
49.233281620, 48.195, 1755.0, 41.8927
49.287613820, 48.195, 1688.0, 41.0853
49.341946020, 48.195, 1606.0, 40.0749
49.396278220, 48.195, 1663.0, 40.7799
49.450610420, 48.195, 1647.0, 40.5832
49.504942620, 48.195, 1560.0, 39.4968
49.559274820, 48.195, 1515.0, 38.9230
49.613607020, 48.195, 1509.0, 38.8458
49.667939220, 48.195, 1528.0, 39.0896
49.722271420, 48.195, 1530.0, 39.1152
49.776603620, 48.195, 1353.0, 36.7831
49.830935820, 48.195, 1451.0, 38.0920
49.885268020, 48.195, 1484.0, 38.5227
49.939600220, 48.195, 1525.0, 39.0512
49.993932420, 48.195, 1607.0, 40.0874
50.048264620, 48.195, 1595.0, 39.9375
50.102596820, 48.195, 1693.0, 41.1461
50.156929020, 48.195, 1596.0, 39.9500
50.211261220, 48.195, 1475.0, 38.4057
50.265593420, 48.195, 1534.0, 39.1663
50.319925620, 48.195, 1488.0, 38.5746
50.374257820, 48.195, 1513.0, 38.8973
50.428590020, 48.195, 1535.0, 39.1791
50.482922220, 48.195, 1499.0, 38.7169
50.537254420, 48.195, 1521.0, 39.0000
50.591586620, 48.195, 1552.0, 39.3954
50.645918820, 48.195, 1451.0, 38.0920
50.700251020, 48.195, 1531.0, 39.1280
50.754583220, 48.195, 1561.0, 39.5095
50.808915420, 48.195, 1528.0, 39.0896
50.863247620, 48.195, 1556.0, 39.4462
50.917579820, 48.195, 1545.0, 39.3065
50.971912020, 48.195, 1626.0, 40.3237
51.026244220, 48.195, 1508.0, 38.8330
51.080576420, 48.195, 1553.0, 39.4081
51.134908620, 48.195, 1499.0, 38.7169
51.189240820, 48.195, 1621.0, 40.2616
51.243573020, 48.195, 1452.0, 38.1051
51.297905220, 48.195, 1374.0, 37.0675
51.352237420, 48.195, 1418.0, 37.6563
51.406569620, 48.195, 1428.0, 37.7889
51.460901820, 48.195, 1539.0, 39.2301
51.515234020, 48.195, 1576.0, 39.6989
51.569566220, 48.195, 1614.0, 40.1746
51.623898420, 48.195, 1690.0, 41.1096
51.678230620, 48.195, 1618.0, 40.2244
51.732562820, 48.195, 1685.0, 41.0488
51.786895020, 48.195, 1578.0, 39.7240
51.841227220, 48.195, 1574.0, 39.6737
51.895559420, 48.195, 1436.0, 37.8946
51.949891620, 48.195, 1447.0, 38.0395
52.004223820, 48.195, 1523.0, 39.0256
52.058556020, 48.195, 1541.0, 39.2556
52.112888220, 48.195, 1575.0, 39.6863
52.167220420, 48.195, 1531.0, 39.1280
52.221552620, 48.195, 1435.0, 37.8814
52.275884820, 48.195, 1417.0, 37.6431
52.330217020, 48.195, 1369.0, 37.0000
52.384549220, 48.195, 1325.0, 36.4005
52.438881420, 48.195, 1370.0, 37.0135
52.493213620, 48.195, 1336.0, 36.5513
52.547545820, 48.195, 1329.0, 36.4555
52.601878020, 48.195, 1340.0, 36.6060
52.656210220, 48.195, 1368.0, 36.9865
52.710542420, 48.195, 1385.0, 37.2156
52.764874620, 48.195, 1353.0, 36.7831
52.819206820, 48.195, 1346.0, 36.6879
52.873539020, 48.195, 1392.0, 37.3095
52.927871220, 48.195, 1380.0, 37.1484
52.982203420, 48.195, 1408.0, 37.5233
53.036535620, 48.195, 1443.0, 37.9868
53.090867820, 48.195, 1328.0, 36.4417
53.145200020, 48.195, 1296.0, 36.0000
53.199532220, 48.195, 1392.0, 37.3095
53.253864420, 48.195, 1305.0, 36.1248
53.308196620, 48.195, 1326.0, 36.4143
53.362528820, 48.195, 1392.0, 37.3095
53.416861020, 48.195, 1386.0, 37.2290
53.471193220, 48.195, 1354.0, 36.7967
53.525525420, 48.195, 1425.0, 37.7492
53.579857620, 48.195, 1413.0, 37.5899
53.634189820, 48.195, 1465.0, 38.2753
53.688522020, 48.195, 1575.0, 39.6863
53.742854220, 48.195, 1692.0, 41.1339
53.797186420, 48.195, 1626.0, 40.3237
53.851518620, 48.195, 1679.0, 40.9756
53.905850820, 48.195, 1646.0, 40.5709
53.960183020, 48.195, 1519.0, 38.9744
54.014515220, 48.195, 1566.0, 39.5727
54.068847420, 48.195, 1416.0, 37.6298
54.123179620, 48.195, 1330.0, 36.4692
54.177511820, 48.195, 1312.0, 36.2215
54.231844020, 48.195, 1324.0, 36.3868
54.286176220, 48.195, 1273.0, 35.6791
54.340508420, 48.195, 1218.0, 34.8999
54.394840620, 48.195, 1236.0, 35.1568
54.449172820, 48.195, 1231.0, 35.0856
54.503505020, 48.195, 1168.0, 34.1760
54.557837220, 48.195, 1219.0, 34.9142
54.612169420, 48.195, 1230.0, 35.0714
54.666501620, 48.195, 1208.0, 34.7563
54.720833820, 48.195, 1169.0, 34.1906
54.775166020, 48.195, 1225.0, 35.0000
54.829498220, 48.195, 1179.0, 34.3366
54.883830420, 48.195, 1230.0, 35.0714
54.938162620, 48.195, 1233.0, 35.1141
54.992494820, 48.195, 1258.0, 35.4683
55.046827020, 48.195, 1182.0, 34.3802
55.101159220, 48.195, 1195.0, 34.5688
55.155491420, 48.195, 1216.0, 34.8712
55.209823620, 48.195, 1218.0, 34.8999
55.264155820, 48.195, 1263.0, 35.5387
55.318488020, 48.195, 1205.0, 34.7131
55.372820220, 48.195, 1247.0, 35.3129
55.427152420, 48.195, 1251.0, 35.3695
55.481484620, 48.195, 1199.0, 34.6266
55.535816820, 48.195, 1192.0, 34.5254
55.590149020, 48.195, 1247.0, 35.3129
55.644481220, 48.195, 1273.0, 35.6791
55.698813420, 48.195, 1242.0, 35.2420
55.753145620, 48.195, 1262.0, 35.5246
55.807477820, 48.195, 1274.0, 35.6931
55.861810020, 48.195, 1260.0, 35.4965
55.916142220, 48.195, 1376.0, 37.0945
55.970474420, 48.195, 1318.0, 36.3043
56.024806620, 48.195, 1277.0, 35.7351
56.079138820, 48.195, 1299.0, 36.0416
56.133471020, 48.195, 1250.0, 35.3553
56.187803220, 48.195, 1279.0, 35.7631
56.242135420, 48.195, 1237.0, 35.1710
56.296467620, 48.195, 1186.0, 34.4384
56.350799820, 48.195, 1239.0, 35.1994
56.405132020, 48.195, 1172.0, 34.2345
56.459464220, 48.195, 1214.0, 34.8425
56.513796420, 48.195, 1235.0, 35.1426
56.568128620, 48.195, 1168.0, 34.1760
56.622460820, 48.195, 1222.0, 34.9571
56.676793020, 48.195, 1204.0, 34.6987
56.731125220, 48.195, 1211.0, 34.7994
56.785457420, 48.195, 1295.0, 35.9861
56.839789620, 48.195, 1291.0, 35.9305
56.894121820, 48.195, 1264.0, 35.5528
56.948454020, 48.195, 1206.0, 34.7275
57.002786220, 48.195, 1236.0, 35.1568
57.057118420, 48.195, 1268.0, 35.6090
57.111450620, 48.195, 1208.0, 34.7563
57.165782820, 48.195, 1261.0, 35.5106
57.220115020, 48.195, 1299.0, 36.0416
57.274447220, 48.195, 1313.0, 36.2353
57.328779420, 48.195, 1290.0, 35.9166
57.383111620, 48.195, 1270.0, 35.6371
57.437443820, 48.195, 1204.0, 34.6987
57.491776020, 48.195, 1147.0, 33.8674
57.546108220, 48.195, 1152.0, 33.9411
57.600440420, 48.195, 1066.0, 32.6497
57.654772620, 48.195, 1046.0, 32.3419
57.709104820, 48.195, 1119.0, 33.4515
57.763437020, 48.195, 1100.0, 33.1662
57.817769220, 48.195, 1053.0, 32.4500
57.872101420, 48.195, 1138.0, 33.7343
57.926433620, 48.195, 1038.0, 32.2180
57.980765820, 48.195, 1026.0, 32.0312
58.035098020, 48.195, 1151.0, 33.9264
58.089430220, 48.195, 1083.0, 32.9090
58.143762420, 48.195, 1100.0, 33.1662
58.198094620, 48.195, 1071.0, 32.7261
58.252426820, 48.195, 1072.0, 32.7414
58.306759020, 48.195, 1061.0, 32.5730
58.361091220, 48.195, 1082.0, 32.8938
58.415423420, 48.195, 1050.0, 32.4037
58.469755620, 48.195, 1077.0, 32.8177
58.524087820, 48.195, 1043.0, 32.2955
58.578420020, 48.195, 1128.0, 33.5857
58.632752220, 48.195, 1044.0, 32.3110
58.687084420, 48.195, 1164.0, 34.1174
58.741416620, 48.195, 1206.0, 34.7275
58.795748820, 48.195, 1191.0, 34.5109
58.850081020, 48.195, 1184.0, 34.4093
58.904413220, 48.195, 1161.0, 34.0735
58.958745420, 48.195, 1149.0, 33.8969
59.013077620, 48.195, 1088.0, 32.9848
59.067409820, 48.195, 1073.0, 32.7567
59.121742020, 48.195, 1040.0, 32.2490
59.176074220, 48.195, 998.0, 31.5911
59.230406420, 48.195, 1084.0, 32.9242
59.284738620, 48.195, 1062.0, 32.5883
59.339070820, 48.195, 1083.0, 32.9090
59.393403020, 48.195, 1153.0, 33.9559
59.447735220, 48.195, 1069.0, 32.6956
59.502067420, 48.195, 1161.0, 34.0735
59.556399620, 48.195, 1131.0, 33.6303
59.610731820, 48.195, 1138.0, 33.7343
59.665064020, 48.195, 1006.0, 31.7175
59.719396220, 48.195, 1039.0, 32.2335
59.773728420, 48.195, 980.0, 31.3050
59.828060620, 48.195, 1017.0, 31.8904
59.882392820, 48.195, 1041.0, 32.2645
59.936725020, 48.195, 939.0, 30.6431
59.991057220, 48.195, 1035.0, 32.1714
60.045389420, 48.195, 908.0, 30.1330
60.099721620, 48.195, 952.0, 30.8545
60.154053820, 48.195, 993.0, 31.5119
60.208386020, 48.195, 1032.0, 32.1248
60.262718220, 48.195, 1018.0, 31.9061
60.317050420, 48.195, 1010.0, 31.7805
60.371382620, 48.195, 997.0, 31.5753
60.425714820, 48.195, 1046.0, 32.3419
60.480047020, 48.195, 1023.0, 31.9844
60.534379220, 48.195, 1016.0, 31.8748
60.588711420, 48.195, 1006.0, 31.7175
60.643043620, 48.195, 1020.0, 31.9374
60.697375820, 48.195, 1093.0, 33.0606
60.751708020, 48.195, 1111.0, 33.3317
60.806040220, 48.195, 1154.0, 33.9706
60.860372420, 48.195, 1039.0, 32.2335
60.914704620, 48.195, 1042.0, 32.2800
60.969036820, 48.195, 1048.0, 32.3728
61.023369020, 48.195, 1044.0, 32.3110
61.077701220, 48.195, 983.0, 31.3528
61.132033420, 48.195, 1060.0, 32.5576
61.186365620, 48.195, 1000.0, 31.6228
61.240697820, 48.195, 1021.0, 31.9531
61.295030020, 48.195, 1026.0, 32.0312
61.349362220, 48.195, 1043.0, 32.2955
61.403694420, 48.195, 944.0, 30.7246
61.458026620, 48.195, 999.0, 31.6070
61.512358820, 48.195, 953.0, 30.8707
61.566691020, 48.195, 1001.0, 31.6386
61.621023220, 48.195, 967.0, 31.0966
61.675355420, 48.195, 935.0, 30.5778
61.729687620, 48.195, 941.0, 30.6757
61.784019820, 48.195, 916.0, 30.2655
61.838352020, 48.195, 901.0, 30.0167
61.892684220, 48.195, 884.0, 29.7321
61.947016420, 48.195, 875.0, 29.5804
62.001348620, 48.195, 874.0, 29.5635
62.055680820, 48.195, 894.0, 29.8998
62.110013020, 48.195, 899.0, 29.9833
62.164345220, 48.195, 889.0, 29.8161
62.218677420, 48.195, 929.0, 30.4795
62.273009620, 48.195, 918.0, 30.2985
62.327341820, 48.195, 990.0, 31.4643
62.381674020, 48.195, 961.0, 31.0000
62.436006220, 48.195, 924.0, 30.3974
62.490338420, 48.195, 1011.0, 31.7962
62.544670620, 48.195, 977.0, 31.2570
62.599002820, 48.195, 1006.0, 31.7175
62.653335020, 48.195, 959.0, 30.9677
62.707667220, 48.195, 1025.0, 32.0156
62.761999420, 48.195, 963.0, 31.0322
62.816331620, 48.195, 938.0, 30.6268
62.870663820, 48.195, 998.0, 31.5911
62.924996020, 48.195, 971.0, 31.1609
62.979328220, 48.195, 909.0, 30.1496
63.033660420, 48.195, 951.0, 30.8383
63.087992620, 48.195, 926.0, 30.4302
63.142324820, 48.195, 874.0, 29.5635
63.196657020, 48.195, 897.0, 29.9500
63.250989220, 48.195, 886.0, 29.7658
63.305321420, 48.195, 891.0, 29.8496
63.359653620, 48.195, 904.0, 30.0666
63.413985820, 48.195, 917.0, 30.2820
63.468318020, 48.195, 918.0, 30.2985
63.522650220, 48.195, 909.0, 30.1496
63.576982420, 48.195, 970.0, 31.1448
63.631314620, 48.195, 916.0, 30.2655
63.685646820, 48.195, 929.0, 30.4795
63.739979020, 48.195, 862.0, 29.3598
63.794311220, 48.195, 913.0, 30.2159
63.848643420, 48.195, 809.0, 28.4429
63.902975620, 48.195, 882.0, 29.6985
63.957307820, 48.195, 912.0, 30.1993
64.011640020, 48.195, 869.0, 29.4788
64.065972220, 48.195, 884.0, 29.7321
64.120304420, 48.195, 880.0, 29.6648
64.174636620, 48.195, 875.0, 29.5804
64.228968820, 48.195, 855.0, 29.2404
64.283301020, 48.195, 866.0, 29.4279
64.337633220, 48.195, 875.0, 29.5804
64.391965420, 48.195, 866.0, 29.4279
64.446297620, 48.195, 871.0, 29.5127
64.500629820, 48.195, 876.0, 29.5973
64.554962020, 48.195, 890.0, 29.8329
64.609294220, 48.195, 847.0, 29.1033
64.663626420, 48.195, 862.0, 29.3598
64.717958620, 48.195, 843.0, 29.0345
64.772290820, 48.195, 826.0, 28.7402
64.826623020, 48.195, 748.0, 27.3496
64.880955220, 48.195, 836.0, 28.9137
64.935287420, 48.195, 883.0, 29.7153
64.989619620, 48.195, 838.0, 28.9482
65.043951820, 48.195, 923.0, 30.3809
65.098284020, 48.195, 814.0, 28.5307
65.152616220, 48.195, 856.0, 29.2575
65.206948420, 48.195, 796.0, 28.2135
65.261280620, 48.195, 870.0, 29.4958
65.315612820, 48.195, 847.0, 29.1033
65.369945020, 48.195, 847.0, 29.1033
65.424277220, 48.195, 869.0, 29.4788
65.478609420, 48.195, 820.0, 28.6356
65.532941620, 48.195, 838.0, 28.9482
65.587273820, 48.195, 894.0, 29.8998
65.641606020, 48.195, 893.0, 29.8831
65.695938220, 48.195, 903.0, 30.0500
65.750270420, 48.195, 900.0, 30.0000
65.804602620, 48.195, 885.0, 29.7489
65.858934820, 48.195, 835.0, 28.8964
65.913267020, 48.195, 887.0, 29.7825
65.967599220, 48.195, 830.0, 28.8097
66.021931420, 48.195, 851.0, 29.1719
66.076263620, 48.195, 912.0, 30.1993
66.130595820, 48.195, 880.0, 29.6648
66.184928020, 48.195, 815.0, 28.5482
66.239260220, 48.195, 853.0, 29.2062
66.293592420, 48.195, 852.0, 29.1890
66.347924620, 48.195, 836.0, 28.9137
66.402256820, 48.195, 834.0, 28.8791
66.456589020, 48.195, 847.0, 29.1033
66.510921220, 48.195, 840.0, 28.9828
66.565253420, 48.195, 809.0, 28.4429
66.619585620, 48.195, 835.0, 28.8964
66.673917820, 48.195, 766.0, 27.6767
66.728250020, 48.195, 836.0, 28.9137
66.782582220, 48.195, 827.0, 28.7576
66.836914420, 48.195, 830.0, 28.8097
66.891246620, 48.195, 818.0, 28.6007
66.945578820, 48.195, 823.0, 28.6880
66.999911020, 48.195, 806.0, 28.3901
67.054243220, 48.195, 778.0, 27.8927
67.108575420, 48.195, 821.0, 28.6531
67.162907620, 48.195, 873.0, 29.5466
67.217239820, 48.195, 786.0, 28.0357
67.271572020, 48.195, 778.0, 27.8927
67.325904220, 48.195, 801.0, 28.3019
67.380236420, 48.195, 816.0, 28.5657
67.434568620, 48.195, 811.0, 28.4781
67.488900820, 48.195, 791.0, 28.1247
67.543233020, 48.195, 745.0, 27.2947
67.597565220, 48.195, 818.0, 28.6007
67.651897420, 48.195, 805.0, 28.3725
67.706229620, 48.195, 722.0, 26.8701
67.760561820, 48.195, 791.0, 28.1247
67.814894020, 48.195, 778.0, 27.8927
67.869226220, 48.195, 778.0, 27.8927
67.923558420, 48.195, 753.0, 27.4408
67.977890620, 48.195, 797.0, 28.2312
68.032222820, 48.195, 713.0, 26.7021
68.086555020, 48.195, 853.0, 29.2062
68.140887220, 48.195, 793.0, 28.1603
68.195219420, 48.195, 778.0, 27.8927
68.249551620, 48.195, 770.0, 27.7489
68.303883820, 48.195, 782.0, 27.9643
68.358216020, 48.195, 809.0, 28.4429
68.412548220, 48.195, 785.0, 28.0179
68.466880420, 48.195, 746.0, 27.3130
68.521212620, 48.195, 819.0, 28.6182
68.575544820, 48.195, 800.0, 28.2843
68.629877020, 48.195, 810.0, 28.4605
68.684209220, 48.195, 759.0, 27.5500
68.738541420, 48.195, 746.0, 27.3130
68.792873620, 48.195, 765.0, 27.6586
68.847205820, 48.195, 782.0, 27.9643
68.901538020, 48.195, 775.0, 27.8388
68.955870220, 48.195, 794.0, 28.1780
69.010202420, 48.195, 832.0, 28.8444
69.064534620, 48.195, 788.0, 28.0713
69.118866820, 48.195, 781.0, 27.9464
69.173199020, 48.195, 808.0, 28.4253
69.227531220, 48.195, 756.0, 27.4955
69.281863420, 48.195, 757.0, 27.5136
69.336195620, 48.195, 814.0, 28.5307
69.390527820, 48.195, 778.0, 27.8927
69.444860020, 48.195, 777.0, 27.8747
69.499192220, 48.195, 838.0, 28.9482
69.553524420, 48.195, 779.0, 27.9106
69.607856620, 48.195, 791.0, 28.1247
69.662188820, 48.195, 794.0, 28.1780
69.716521020, 48.195, 807.0, 28.4077
69.770853220, 48.195, 746.0, 27.3130
69.825185420, 48.195, 771.0, 27.7669
69.879517620, 48.195, 726.0, 26.9444
69.933849820, 48.195, 743.0, 27.2580
69.988182020, 48.195, 755.0, 27.4773
70.042514220, 48.195, 762.0, 27.6043
70.096846420, 48.195, 749.0, 27.3679
70.151178620, 48.195, 724.0, 26.9072
70.205510820, 48.195, 748.0, 27.3496
70.259843020, 48.195, 751.0, 27.4044
70.314175220, 48.195, 753.0, 27.4408
70.368507420, 48.195, 742.0, 27.2397
70.422839620, 48.195, 775.0, 27.8388
70.477171820, 48.195, 783.0, 27.9821
70.531504020, 48.195, 753.0, 27.4408
70.585836220, 48.195, 717.0, 26.7769
70.640168420, 48.195, 764.0, 27.6405
70.694500620, 48.195, 796.0, 28.2135
70.748832820, 48.195, 767.0, 27.6948
70.803165020, 48.195, 762.0, 27.6043
70.857497220, 48.195, 760.0, 27.5681
70.911829420, 48.195, 753.0, 27.4408
70.966161620, 48.195, 744.0, 27.2764
71.020493820, 48.195, 741.0, 27.2213
71.074826020, 48.195, 747.0, 27.3313
71.129158220, 48.195, 762.0, 27.6043
71.183490420, 48.195, 802.0, 28.3196
71.237822620, 48.195, 755.0, 27.4773
71.292154820, 48.195, 801.0, 28.3019
71.346487020, 48.195, 755.0, 27.4773
71.400819220, 48.195, 787.0, 28.0535
71.455151420, 48.195, 819.0, 28.6182
71.509483620, 48.195, 812.0, 28.4956
71.563815820, 48.195, 762.0, 27.6043
71.618148020, 48.195, 764.0, 27.6405
71.672480220, 48.195, 726.0, 26.9444
71.726812420, 48.195, 770.0, 27.7489
71.781144620, 48.195, 747.0, 27.3313
71.835476820, 48.195, 782.0, 27.9643
71.889809020, 48.195, 754.0, 27.4591
71.944141220, 48.195, 739.0, 27.1846
71.998473420, 48.195, 736.0, 27.1293
72.052805620, 48.195, 756.0, 27.4955
72.107137820, 48.195, 766.0, 27.6767
72.161470020, 48.195, 727.0, 26.9629
72.215802220, 48.195, 725.0, 26.9258
72.270134420, 48.195, 750.0, 27.3861
72.324466620, 48.195, 766.0, 27.6767
72.378798820, 48.195, 712.0, 26.6833
72.433131020, 48.195, 786.0, 28.0357
72.487463220, 48.195, 736.0, 27.1293
72.541795420, 48.195, 761.0, 27.5862
72.596127620, 48.195, 732.0, 27.0555
72.650459820, 48.195, 806.0, 28.3901
72.704792020, 48.195, 715.0, 26.7395
72.759124220, 48.195, 735.0, 27.1109
72.813456420, 48.195, 737.0, 27.1477
72.867788620, 48.195, 697.0, 26.4008
72.922120820, 48.195, 761.0, 27.5862
72.976453020, 48.195, 758.0, 27.5318
73.030785220, 48.195, 717.0, 26.7769
73.085117420, 48.195, 791.0, 28.1247
73.139449620, 48.195, 743.0, 27.2580
73.193781820, 48.195, 758.0, 27.5318
73.248114020, 48.195, 775.0, 27.8388
73.302446220, 48.195, 780.0, 27.9285
73.356778420, 48.195, 770.0, 27.7489
73.411110620, 48.195, 809.0, 28.4429
73.465442820, 48.195, 728.0, 26.9815
73.519775020, 48.195, 763.0, 27.6225
73.574107220, 48.195, 745.0, 27.2947
73.628439420, 48.195, 741.0, 27.2213
73.682771620, 48.195, 756.0, 27.4955
73.737103820, 48.195, 714.0, 26.7208
73.791436020, 48.195, 795.0, 28.1957
73.845768220, 48.195, 702.0, 26.4953
73.900100420, 48.195, 757.0, 27.5136
73.954432620, 48.195, 736.0, 27.1293
74.008764820, 48.195, 765.0, 27.6586
74.063097020, 48.195, 769.0, 27.7308
74.117429220, 48.195, 684.0, 26.1534
74.171761420, 48.195, 734.0, 27.0924
74.226093620, 48.195, 734.0, 27.0924
74.280425820, 48.195, 689.0, 26.2488
74.334758020, 48.195, 755.0, 27.4773
74.389090220, 48.195, 746.0, 27.3130
74.443422420, 48.195, 697.0, 26.4008
74.497754620, 48.195, 765.0, 27.6586
74.552086820, 48.195, 746.0, 27.3130
74.606419020, 48.195, 743.0, 27.2580
74.660751220, 48.195, 748.0, 27.3496
74.715083420, 48.195, 762.0, 27.6043
74.769415620, 48.195, 788.0, 28.0713
74.823747820, 48.195, 728.0, 26.9815
74.878080020, 48.195, 745.0, 27.2947
74.932412220, 48.195, 767.0, 27.6948
74.986744420, 48.195, 749.0, 27.3679
75.041076620, 48.195, 733.0, 27.0740
75.095408820, 48.195, 733.0, 27.0740
75.149741020, 48.195, 714.0, 26.7208
75.204073220, 48.195, 770.0, 27.7489
75.258405420, 48.195, 740.0, 27.2029
75.312737620, 48.195, 752.0, 27.4226
75.367069820, 48.195, 774.0, 27.8209
75.421402020, 48.195, 777.0, 27.8747
75.475734220, 48.195, 678.0, 26.0384
75.530066420, 48.195, 715.0, 26.7395
75.584398620, 48.195, 749.0, 27.3679
75.638730820, 48.195, 748.0, 27.3496
75.693063020, 48.195, 744.0, 27.2764
75.747395220, 48.195, 756.0, 27.4955
75.801727420, 48.195, 765.0, 27.6586
75.856059620, 48.195, 763.0, 27.6225
75.910391820, 48.195, 738.0, 27.1662
75.964724020, 48.195, 686.0, 26.1916
76.019056220, 48.195, 787.0, 28.0535
76.073388420, 48.195, 729.0, 27.0000
76.127720620, 48.195, 770.0, 27.7489
76.182052820, 48.195, 729.0, 27.0000
76.236385020, 48.195, 779.0, 27.9106
76.290717220, 48.195, 755.0, 27.4773
76.345049420, 48.195, 730.0, 27.0185
76.399381620, 48.195, 731.0, 27.0370
76.453713820, 48.195, 729.0, 27.0000
76.508046020, 48.195, 740.0, 27.2029
76.562378220, 48.195, 811.0, 28.4781
76.616710420, 48.195, 714.0, 26.7208
76.671042620, 48.195, 773.0, 27.8029
76.725374820, 48.195, 754.0, 27.4591
76.779707020, 48.195, 754.0, 27.4591
76.834039220, 48.195, 753.0, 27.4408
76.888371420, 48.195, 753.0, 27.4408
76.942703620, 48.195, 739.0, 27.1846
76.997035820, 48.195, 788.0, 28.0713
77.051368020, 48.195, 739.0, 27.1846
77.105700220, 48.195, 727.0, 26.9629
77.160032420, 48.195, 758.0, 27.5318
77.214364620, 48.195, 781.0, 27.9464
77.268696820, 48.195, 749.0, 27.3679
77.323029020, 48.195, 770.0, 27.7489
77.377361220, 48.195, 712.0, 26.6833
77.431693420, 48.195, 729.0, 27.0000
77.486025620, 48.195, 747.0, 27.3313
77.540357820, 48.195, 755.0, 27.4773
77.594690020, 48.195, 694.0, 26.3439
77.649022220, 48.195, 704.0, 26.5330
77.703354420, 48.195, 721.0, 26.8514
77.757686620, 48.195, 719.0, 26.8142
77.812018820, 48.195, 763.0, 27.6225
77.866351020, 48.195, 738.0, 27.1662
77.920683220, 48.195, 752.0, 27.4226
77.975015420, 48.195, 729.0, 27.0000
78.029347620, 48.195, 836.0, 28.9137
78.083679820, 48.195, 761.0, 27.5862
78.138012020, 48.195, 741.0, 27.2213
78.192344220, 48.195, 721.0, 26.8514
78.246676420, 48.195, 754.0, 27.4591
78.301008620, 48.195, 743.0, 27.2580
78.355340820, 48.195, 726.0, 26.9444
78.409673020, 48.195, 757.0, 27.5136
78.464005220, 48.195, 748.0, 27.3496
78.518337420, 48.195, 730.0, 27.0185
78.572669620, 48.195, 771.0, 27.7669
78.627001820, 48.195, 792.0, 28.1425
78.681334020, 48.195, 801.0, 28.3019
78.735666220, 48.195, 837.0, 28.9310
78.789998420, 48.195, 833.0, 28.8617
78.844330620, 48.195, 755.0, 27.4773
78.898662820, 48.195, 780.0, 27.9285
78.952995020, 48.195, 753.0, 27.4408
79.007327220, 48.195, 754.0, 27.4591
79.061659420, 48.195, 719.0, 26.8142
79.115991620, 48.195, 721.0, 26.8514
79.170323820, 48.195, 756.0, 27.4955
79.224656020, 48.195, 735.0, 27.1109
79.278988220, 48.195, 728.0, 26.9815
79.333320420, 48.195, 735.0, 27.1109
79.387652620, 48.195, 703.0, 26.5141
79.441984820, 48.195, 696.0, 26.3818
79.496317020, 48.195, 772.0, 27.7849
79.550649220, 48.195, 780.0, 27.9285
79.604981420, 48.195, 716.0, 26.7582
79.659313620, 48.195, 748.0, 27.3496
79.713645820, 48.195, 754.0, 27.4591
79.767978020, 48.195, 703.0, 26.5141
79.822310220, 48.195, 738.0, 27.1662
79.876642420, 48.195, 788.0, 28.0713
79.930974620, 48.195, 742.0, 27.2397
79.985306820, 48.195, 777.0, 27.8747
79.996173260, 48.195, 751.0, 27.4044