File: XRD/2025_06_12_aNIF_DSC_3_60_22m_pXRD.csv
[Measurement conditions]
Sample identification,2025_06_12_aNIF_DSC_3_60_22m_pXRD
Comment - 1,"DSC #23 (A2 Tray), quenched glass, Nifedipine."
Anode material,Cu
K-Alpha1 wavelength,1.5405980
K-Alpha2 wavelength,1.5444260
Ratio K-Alpha2/K-Alpha1,0.500
Divergence slit,Fixed,0.76mm
Monochromator used,NO
Generator voltage, 40
Tube current, 15
File date and time,12/Jun/2025 13:55
Unit cell,
h k l, 0 0 0
Scan axis,Gonio
Scan range,2.995000000,60.000344240
Scan step size,0.0108664
No. of points, 5246
Scan type,CONTINUOUS
Time per step,58.395
[Scan points]
Angle, TimePerStep, Intensity, ESD
3.000433220, 58.395, 137375.0, 370.6413
3.043898980, 58.395, 131409.0, 362.5038
3.087364740, 58.395, 124845.0, 353.3341
3.130830500, 58.395, 119600.0, 345.8323
3.174296260, 58.395, 112387.0, 335.2417
3.217762020, 58.395, 105901.0, 325.4243
3.261227780, 58.395, 100146.0, 316.4585
3.304693540, 58.395, 94478.0, 307.3727
3.348159300, 58.395, 89441.0, 299.0669
3.391625060, 58.395, 84465.0, 290.6286
3.435090820, 58.395, 79376.0, 281.7375
3.478556580, 58.395, 74689.0, 273.2929
3.522022340, 58.395, 69899.0, 264.3842
3.565488100, 58.395, 66627.0, 258.1221
3.608953860, 58.395, 61836.0, 248.6685
3.652419620, 58.395, 57826.0, 240.4704
3.695885380, 58.395, 54551.0, 233.5616
3.739351140, 58.395, 50968.0, 225.7609
3.782816900, 58.395, 47723.0, 218.4559
3.826282660, 58.395, 44749.0, 211.5396
3.869748420, 58.395, 41443.0, 203.5755
3.913214180, 58.395, 38893.0, 197.2131
3.956679940, 58.395, 36144.0, 190.1158
4.000145700, 58.395, 33994.0, 184.3746
4.043611460, 58.395, 31360.0, 177.0875
4.087077220, 58.395, 29372.0, 171.3826
4.130542980, 58.395, 27030.0, 164.4080
4.174008740, 58.395, 24947.0, 157.9462
4.217474500, 58.395, 23270.0, 152.5451
4.260940260, 58.395, 21493.0, 146.6049
4.304406020, 58.395, 19784.0, 140.6556
4.347871780, 58.395, 18291.0, 135.2442
4.391337540, 58.395, 16875.0, 129.9038
4.434803300, 58.395, 15677.0, 125.2078
4.478269060, 58.395, 14435.0, 120.1457
4.521734820, 58.395, 13239.0, 115.0609
4.565200580, 58.395, 12153.0, 110.2406
4.608666340, 58.395, 11400.0, 106.7708
4.652132100, 58.395, 10585.0, 102.8834
4.695597860, 58.395, 9759.0, 98.7877
4.739063620, 58.395, 9336.0, 96.6230
4.782529380, 58.395, 8652.0, 93.0161
4.825995140, 58.395, 8161.0, 90.3383
4.869460900, 58.395, 7793.0, 88.2780
4.912926660, 58.395, 7460.0, 86.3713
4.956392420, 58.395, 7196.0, 84.8292
4.999858180, 58.395, 7171.0, 84.6818
5.043323940, 58.395, 7041.0, 83.9107
5.086789700, 58.395, 6891.0, 83.0120
5.130255460, 58.395, 6939.0, 83.3007
5.173721220, 58.395, 6975.0, 83.5165
5.217186980, 58.395, 6960.0, 83.4266
5.260652740, 58.395, 6833.0, 82.6620
5.304118500, 58.395, 7122.0, 84.3919
5.347584260, 58.395, 6809.0, 82.5167
5.391050020, 58.395, 6661.0, 81.6149
5.434515780, 58.395, 6355.0, 79.7183
5.477981540, 58.395, 6053.0, 77.8010
5.521447300, 58.395, 5781.0, 76.0329
5.564913060, 58.395, 5433.0, 73.7089
5.608378820, 58.395, 5097.0, 71.3933
5.651844580, 58.395, 4816.0, 69.3974
5.695310340, 58.395, 4503.0, 67.1044
5.738776100, 58.395, 4456.0, 66.7533
5.782241860, 58.395, 4263.0, 65.2917
5.825707620, 58.395, 4237.0, 65.0922
5.869173380, 58.395, 4221.0, 64.9692
5.912639140, 58.395, 4177.0, 64.6297
5.956104900, 58.395, 4016.0, 63.3719
5.999570660, 58.395, 4042.0, 63.5767
6.043036420, 58.395, 4007.0, 63.3009
6.086502180, 58.395, 3918.0, 62.5939
6.129967940, 58.395, 3859.0, 62.1208
6.173433700, 58.395, 3743.0, 61.1801
6.216899460, 58.395, 3749.0, 61.2291
6.260365220, 58.395, 3835.0, 61.9274
6.303830980, 58.395, 3705.0, 60.8687
6.347296740, 58.395, 3566.0, 59.7160
6.390762500, 58.395, 3654.0, 60.4483
6.434228260, 58.395, 3650.0, 60.4152
6.477694020, 58.395, 3537.0, 59.4727
6.521159780, 58.395, 3478.0, 58.9746
6.564625540, 58.395, 3406.0, 58.3609
6.608091300, 58.395, 3502.0, 59.1777
6.651557060, 58.395, 3400.0, 58.3095
6.695022820, 58.395, 3438.0, 58.6345
6.738488580, 58.395, 3264.0, 57.1314
6.781954340, 58.395, 3267.0, 57.1577
6.825420100, 58.395, 3295.0, 57.4021
6.868885860, 58.395, 3220.0, 56.7450
6.912351620, 58.395, 3227.0, 56.8067
6.955817380, 58.395, 3188.0, 56.4624
6.999283140, 58.395, 3320.0, 57.6194
7.042748900, 58.395, 3211.0, 56.6657
7.086214660, 58.395, 3344.0, 57.8273
7.129680420, 58.395, 3263.0, 57.1227
7.173146180, 58.395, 3368.0, 58.0345
7.216611940, 58.395, 3392.0, 58.2409
7.260077700, 58.395, 3561.0, 59.6741
7.303543460, 58.395, 3671.0, 60.5888
7.347009220, 58.395, 3832.0, 61.9032
7.390474980, 58.395, 3858.0, 62.1128
7.433940740, 58.395, 3902.0, 62.4660
7.477406500, 58.395, 4067.0, 63.7730
7.520872260, 58.395, 3864.0, 62.1611
7.564338020, 58.395, 3615.0, 60.1249
7.607803780, 58.395, 3421.0, 58.4893
7.651269540, 58.395, 3376.0, 58.1034
7.694735300, 58.395, 3225.0, 56.7891
7.738201060, 58.395, 3249.0, 57.0000
7.781666820, 58.395, 3233.0, 56.8595
7.825132580, 58.395, 3346.0, 57.8446
7.868598340, 58.395, 3249.0, 57.0000
7.912064100, 58.395, 3154.0, 56.1605
7.955529860, 58.395, 3210.0, 56.6569
7.998995620, 58.395, 3356.0, 57.9310
8.042461380, 58.395, 3340.0, 57.7927
8.085927140, 58.395, 3348.0, 57.8619
8.129392900, 58.395, 3477.0, 58.9661
8.172858660, 58.395, 3406.0, 58.3609
8.216324420, 58.395, 3396.0, 58.2752
8.259790180, 58.395, 3333.0, 57.7321
8.303255940, 58.395, 3525.0, 59.3717
8.346721700, 58.395, 3508.0, 59.2284
8.390187460, 58.395, 3551.0, 59.5903
8.433653220, 58.395, 3623.0, 60.1914
8.477118980, 58.395, 3700.0, 60.8276
8.520584740, 58.395, 3663.0, 60.5227
8.564050500, 58.395, 3650.0, 60.4152
8.607516260, 58.395, 3851.0, 62.0564
8.650982020, 58.395, 3761.0, 61.3270
8.694447780, 58.395, 3911.0, 62.5380
8.737913540, 58.395, 4050.0, 63.6396
8.781379300, 58.395, 3946.0, 62.8172
8.824845060, 58.395, 4056.0, 63.6867
8.868310820, 58.395, 4173.0, 64.5988
8.911776580, 58.395, 4215.0, 64.9230
8.955242340, 58.395, 4441.0, 66.6408
8.998708100, 58.395, 4549.0, 67.4463
9.042173860, 58.395, 4699.0, 68.5493
9.085639620, 58.395, 4778.0, 69.1231
9.129105380, 58.395, 4931.0, 70.2211
9.172571140, 58.395, 4798.0, 69.2676
9.216036900, 58.395, 4733.0, 68.7968
9.259502660, 58.395, 4775.0, 69.1014
9.302968420, 58.395, 4785.0, 69.1737
9.346434180, 58.395, 4703.0, 68.5784
9.389899940, 58.395, 4839.0, 69.5629
9.433365700, 58.395, 4822.0, 69.4406
9.476831460, 58.395, 4840.0, 69.5701
9.520297220, 58.395, 4888.0, 69.9142
9.563762980, 58.395, 4994.0, 70.6682
9.607228740, 58.395, 5046.0, 71.0352
9.650694500, 58.395, 5218.0, 72.2357
9.694160260, 58.395, 5239.0, 72.3809
9.737626020, 58.395, 5299.0, 72.7942
9.781091780, 58.395, 5487.0, 74.0743
9.824557540, 58.395, 5512.0, 74.2428
9.868023300, 58.395, 5486.0, 74.0675
9.911489060, 58.395, 5483.0, 74.0473
9.954954820, 58.395, 6082.0, 77.9872
9.998420580, 58.395, 5916.0, 76.9155
10.041886340, 58.395, 5940.0, 77.0714
10.085352100, 58.395, 6078.0, 77.9615
10.128817860, 58.395, 6257.0, 79.1012
10.172283620, 58.395, 6315.0, 79.4670
10.215749380, 58.395, 6496.0, 80.5978
10.259215140, 58.395, 6434.0, 80.2122
10.302680900, 58.395, 6620.0, 81.3634
10.346146660, 58.395, 6908.0, 83.1144
10.389612420, 58.395, 7256.0, 85.1822
10.433078180, 58.395, 7296.0, 85.4166
10.476543940, 58.395, 7609.0, 87.2296
10.520009700, 58.395, 8045.0, 89.6939
10.563475460, 58.395, 8507.0, 92.2334
10.606941220, 58.395, 8886.0, 94.2656
10.650406980, 58.395, 9415.0, 97.0309
10.693872740, 58.395, 10051.0, 100.2547
10.737338500, 58.395, 10110.0, 100.5485
10.780804260, 58.395, 10241.0, 101.1978
10.824270020, 58.395, 9882.0, 99.4082
10.867735780, 58.395, 9358.0, 96.7368
10.911201540, 58.395, 9116.0, 95.4777
10.954667300, 58.395, 8983.0, 94.7787
10.998133060, 58.395, 8875.0, 94.2072
11.041598820, 58.395, 8809.0, 93.8563
11.085064580, 58.395, 8905.0, 94.3663
11.128530340, 58.395, 8830.0, 93.9681
11.171996100, 58.395, 8801.0, 93.8136
11.215461860, 58.395, 8900.0, 94.3398
11.258927620, 58.395, 9021.0, 94.9789
11.302393380, 58.395, 9037.0, 95.0631
11.345859140, 58.395, 9037.0, 95.0631
11.389324900, 58.395, 9231.0, 96.0781
11.432790660, 58.395, 9184.0, 95.8332
11.476256420, 58.395, 9174.0, 95.7810
11.519722180, 58.395, 8894.0, 94.3080
11.563187940, 58.395, 9149.0, 95.6504
11.606653700, 58.395, 9089.0, 95.3362
11.650119460, 58.395, 9147.0, 95.6399
11.693585220, 58.395, 9234.0, 96.0937
11.737050980, 58.395, 9053.0, 95.1473
11.780516740, 58.395, 9268.0, 96.2705
11.823982500, 58.395, 9233.0, 96.0885
11.867448260, 58.395, 9194.0, 95.8853
11.910914020, 58.395, 9422.0, 97.0670
11.954379780, 58.395, 9552.0, 97.7343
11.997845540, 58.395, 9315.0, 96.5142
12.041311300, 58.395, 9439.0, 97.1545
12.084777060, 58.395, 9615.0, 98.0561
12.128242820, 58.395, 9744.0, 98.7117
12.171708580, 58.395, 9825.0, 99.1211
12.215174340, 58.395, 9918.0, 99.5892
12.258640100, 58.395, 9856.0, 99.2774
12.302105860, 58.395, 9905.0, 99.5239
12.345571620, 58.395, 9923.0, 99.6143
12.389037380, 58.395, 9578.0, 97.8673
12.432503140, 58.395, 9383.0, 96.8659
12.475968900, 58.395, 9235.0, 96.0989
12.519434660, 58.395, 9114.0, 95.4673
12.562900420, 58.395, 8955.0, 94.6309
12.606366180, 58.395, 8989.0, 94.8103
12.649831940, 58.395, 8936.0, 94.5304
12.693297700, 58.395, 9144.0, 95.6243
12.736763460, 58.395, 8921.0, 94.4510
12.780229220, 58.395, 9074.0, 95.2575
12.823694980, 58.395, 8946.0, 94.5833
12.867160740, 58.395, 8980.0, 94.7629
12.910626500, 58.395, 8644.0, 92.9731
12.954092260, 58.395, 8590.0, 92.6823
12.997558020, 58.395, 8243.0, 90.7910
13.041023780, 58.395, 8110.0, 90.0555
13.084489540, 58.395, 7990.0, 89.3868
13.127955300, 58.395, 8044.0, 89.6883
13.171421060, 58.395, 7669.0, 87.5728
13.214886820, 58.395, 7757.0, 88.0738
13.258352580, 58.395, 7546.0, 86.8677
13.301818340, 58.395, 7694.0, 87.7154
13.345284100, 58.395, 7479.0, 86.4812
13.388749860, 58.395, 7323.0, 85.5745
13.432215620, 58.395, 7270.0, 85.2643
13.475681380, 58.395, 7074.0, 84.1071
13.519147140, 58.395, 7138.0, 84.4867
13.562612900, 58.395, 7144.0, 84.5222
13.606078660, 58.395, 7104.0, 84.2852
13.649544420, 58.395, 6825.0, 82.6136
13.693010180, 58.395, 6921.0, 83.1925
13.736475940, 58.395, 6730.0, 82.0366
13.779941700, 58.395, 6675.0, 81.7007
13.823407460, 58.395, 6496.0, 80.5978
13.866873220, 58.395, 6443.0, 80.2683
13.910338980, 58.395, 6516.0, 80.7217
13.953804740, 58.395, 6502.0, 80.6350
13.997270500, 58.395, 6376.0, 79.8499
14.040736260, 58.395, 6424.0, 80.1499
14.084202020, 58.395, 6077.0, 77.9551
14.127667780, 58.395, 6257.0, 79.1012
14.171133540, 58.395, 6362.0, 79.7621
14.214599300, 58.395, 6166.0, 78.5239
14.258065060, 58.395, 5965.0, 77.2334
14.301530820, 58.395, 5914.0, 76.9025
14.344996580, 58.395, 6018.0, 77.5758
14.388462340, 58.395, 6063.0, 77.8653
14.431928100, 58.395, 5930.0, 77.0065
14.475393860, 58.395, 5875.0, 76.6485
14.518859620, 58.395, 5809.0, 76.2168
14.562325380, 58.395, 5747.0, 75.8090
14.605791140, 58.395, 5883.0, 76.7007
14.649256900, 58.395, 5815.0, 76.2561
14.692722660, 58.395, 5775.0, 75.9934
14.736188420, 58.395, 5808.0, 76.2102
14.779654180, 58.395, 5924.0, 76.9675
14.823119940, 58.395, 5772.0, 75.9737
14.866585700, 58.395, 5954.0, 77.1622
14.910051460, 58.395, 5883.0, 76.7007
14.953517220, 58.395, 5660.0, 75.2330
14.996982980, 58.395, 5680.0, 75.3658
15.040448740, 58.395, 5473.0, 73.9797
15.083914500, 58.395, 5327.0, 72.9863
15.127380260, 58.395, 5223.0, 72.2703
15.170846020, 58.395, 5213.0, 72.2011
15.214311780, 58.395, 5125.0, 71.5891
15.257777540, 58.395, 5194.0, 72.0694
15.301243300, 58.395, 5091.0, 71.3512
15.344709060, 58.395, 5096.0, 71.3863
15.388174820, 58.395, 4838.0, 69.5557
15.431640580, 58.395, 5034.0, 70.9507
15.475106340, 58.395, 5105.0, 71.4493
15.518572100, 58.395, 5093.0, 71.3653
15.562037860, 58.395, 4992.0, 70.6541
15.605503620, 58.395, 5044.0, 71.0211
15.648969380, 58.395, 4963.0, 70.4486
15.692435140, 58.395, 4875.0, 69.8212
15.735900900, 58.395, 4876.0, 69.8284
15.779366660, 58.395, 4758.0, 68.9783
15.822832420, 58.395, 4767.0, 69.0435
15.866298180, 58.395, 4864.0, 69.7424
15.909763940, 58.395, 4657.0, 68.2422
15.953229700, 58.395, 4792.0, 69.2243
15.996695460, 58.395, 4738.0, 68.8331
16.040161220, 58.395, 4806.0, 69.3253
16.083626980, 58.395, 4632.0, 68.0588
16.127092740, 58.395, 4557.0, 67.5056
16.170558500, 58.395, 4726.0, 68.7459
16.214024260, 58.395, 4589.0, 67.7422
16.257490020, 58.395, 4610.0, 67.8970
16.300955780, 58.395, 4597.0, 67.8012
16.344421540, 58.395, 4654.0, 68.2202
16.387887300, 58.395, 4756.0, 68.9638
16.431353060, 58.395, 4743.0, 68.8694
16.474818820, 58.395, 4760.0, 68.9928
16.518284580, 58.395, 4961.0, 70.4344
16.561750340, 58.395, 4863.0, 69.7352
16.605216100, 58.395, 5013.0, 70.8025
16.648681860, 58.395, 5218.0, 72.2357
16.692147620, 58.395, 5408.0, 73.5391
16.735613380, 58.395, 5649.0, 75.1598
16.779079140, 58.395, 6046.0, 77.7560
16.822544900, 58.395, 6269.0, 79.1770
16.866010660, 58.395, 6689.0, 81.7863
16.909476420, 58.395, 7254.0, 85.1704
16.952942180, 58.395, 7308.0, 85.4868
16.996407940, 58.395, 6781.0, 82.3468
17.039873700, 58.395, 6163.0, 78.5048
17.083339460, 58.395, 5536.0, 74.4043
17.126805220, 58.395, 5086.0, 71.3162
17.170270980, 58.395, 4969.0, 70.4911
17.213736740, 58.395, 4854.0, 69.6707
17.257202500, 58.395, 4968.0, 70.4840
17.300668260, 58.395, 4802.0, 69.2965
17.344134020, 58.395, 4787.0, 69.1881
17.387599780, 58.395, 4918.0, 70.1285
17.431065540, 58.395, 4948.0, 70.3420
17.474531300, 58.395, 5003.0, 70.7319
17.517997060, 58.395, 4976.0, 70.5408
17.561462820, 58.395, 5217.0, 72.2288
17.604928580, 58.395, 5013.0, 70.8025
17.648394340, 58.395, 5235.0, 72.3533
17.691860100, 58.395, 5216.0, 72.2219
17.735325860, 58.395, 5156.0, 71.8053
17.778791620, 58.395, 5142.0, 71.7077
17.822257380, 58.395, 5286.0, 72.7049
17.865723140, 58.395, 5248.0, 72.4431
17.909188900, 58.395, 5259.0, 72.5190
17.952654660, 58.395, 5248.0, 72.4431
17.996120420, 58.395, 5352.0, 73.1574
18.039586180, 58.395, 5373.0, 73.3008
18.083051940, 58.395, 5324.0, 72.9657
18.126517700, 58.395, 5614.0, 74.9266
18.169983460, 58.395, 5797.0, 76.1380
18.213449220, 58.395, 5820.0, 76.2889
18.256914980, 58.395, 6031.0, 77.6595
18.300380740, 58.395, 5809.0, 76.2168
18.343846500, 58.395, 6021.0, 77.5951
18.387312260, 58.395, 6037.0, 77.6981
18.430778020, 58.395, 5989.0, 77.3886
18.474243780, 58.395, 6125.0, 78.2624
18.517709540, 58.395, 6243.0, 79.0127
18.561175300, 58.395, 6014.0, 77.5500
18.604641060, 58.395, 5945.0, 77.1038
18.648106820, 58.395, 5911.0, 76.8830
18.691572580, 58.395, 5859.0, 76.5441
18.735038340, 58.395, 5978.0, 77.3175
18.778504100, 58.395, 6097.0, 78.0833
18.821969860, 58.395, 5988.0, 77.3822
18.865435620, 58.395, 6212.0, 78.8162
18.908901380, 58.395, 6124.0, 78.2560
18.952367140, 58.395, 6213.0, 78.8226
18.995832900, 58.395, 6462.0, 80.3866
19.039298660, 58.395, 6480.0, 80.4984
19.082764420, 58.395, 6667.0, 81.6517
19.126230180, 58.395, 6587.0, 81.1603
19.169695940, 58.395, 6650.0, 81.5475
19.213161700, 58.395, 6558.0, 80.9815
19.256627460, 58.395, 6571.0, 81.0617
19.300093220, 58.395, 6594.0, 81.2034
19.343558980, 58.395, 6898.0, 83.0542
19.387024740, 58.395, 7030.0, 83.8451
19.430490500, 58.395, 7220.0, 84.9706
19.473956260, 58.395, 7507.0, 86.6429
19.517422020, 58.395, 7567.0, 86.9885
19.560887780, 58.395, 7937.0, 89.0898
19.604353540, 58.395, 7895.0, 88.8538
19.647819300, 58.395, 7812.0, 88.3855
19.691285060, 58.395, 7857.0, 88.6397
19.734750820, 58.395, 7643.0, 87.4243
19.778216580, 58.395, 7918.0, 88.9831
19.821682340, 58.395, 8088.0, 89.9333
19.865148100, 58.395, 8239.0, 90.7689
19.908613860, 58.395, 8517.0, 92.2876
19.952079620, 58.395, 8857.0, 94.1116
19.995545380, 58.395, 9322.0, 96.5505
20.039011140, 58.395, 9369.0, 96.7936
20.082476900, 58.395, 9077.0, 95.2733
20.125942660, 58.395, 8676.0, 93.1450
20.169408420, 58.395, 8159.0, 90.3272
20.212874180, 58.395, 8065.0, 89.8053
20.256339940, 58.395, 7959.0, 89.2132
20.299805700, 58.395, 7876.0, 88.7468
20.343271460, 58.395, 7899.0, 88.8763
20.386737220, 58.395, 7855.0, 88.6284
20.430202980, 58.395, 8022.0, 89.5656
20.473668740, 58.395, 7817.0, 88.4138
20.517134500, 58.395, 7879.0, 88.7637
20.560600260, 58.395, 7982.0, 89.3420
20.604066020, 58.395, 8179.0, 90.4378
20.647531780, 58.395, 7991.0, 89.3924
20.690997540, 58.395, 8154.0, 90.2995
20.734463300, 58.395, 8261.0, 90.8900
20.777929060, 58.395, 8222.0, 90.6752
20.821394820, 58.395, 8358.0, 91.4221
20.864860580, 58.395, 8455.0, 91.9511
20.908326340, 58.395, 8633.0, 92.9139
20.951792100, 58.395, 8833.0, 93.9840
20.995257860, 58.395, 8614.0, 92.8116
21.038723620, 58.395, 8648.0, 92.9946
21.082189380, 58.395, 8712.0, 93.3381
21.125655140, 58.395, 8840.0, 94.0213
21.169120900, 58.395, 8844.0, 94.0425
21.212586660, 58.395, 8757.0, 93.5788
21.256052420, 58.395, 8764.0, 93.6162
21.299518180, 58.395, 8871.0, 94.1860
21.342983940, 58.395, 8894.0, 94.3080
21.386449700, 58.395, 9127.0, 95.5353
21.429915460, 58.395, 9225.0, 96.0469
21.473381220, 58.395, 9392.0, 96.9123
21.516846980, 58.395, 9366.0, 96.7781
21.560312740, 58.395, 9400.0, 96.9536
21.603778500, 58.395, 9595.0, 97.9541
21.647244260, 58.395, 9613.0, 98.0459
21.690710020, 58.395, 9612.0, 98.0408
21.734175780, 58.395, 9599.0, 97.9745
21.777641540, 58.395, 9528.0, 97.6115
21.821107300, 58.395, 9529.0, 97.6166
21.864573060, 58.395, 9308.0, 96.4780
21.908038820, 58.395, 9205.0, 95.9427
21.951504580, 58.395, 9147.0, 95.6399
21.994970340, 58.395, 9183.0, 95.8280
22.038436100, 58.395, 9036.0, 95.0579
22.081901860, 58.395, 8915.0, 94.4193
22.125367620, 58.395, 8980.0, 94.7629
22.168833380, 58.395, 9031.0, 95.0316
22.212299140, 58.395, 9107.0, 95.4306
22.255764900, 58.395, 9475.0, 97.3396
22.299230660, 58.395, 9354.0, 96.7161
22.342696420, 58.395, 9793.0, 98.9596
22.386162180, 58.395, 9830.0, 99.1464
22.429627940, 58.395, 10017.0, 100.0850
22.473093700, 58.395, 9905.0, 99.5239
22.516559460, 58.395, 9764.0, 98.8130
22.560025220, 58.395, 9340.0, 96.6437
22.603490980, 58.395, 9235.0, 96.0989
22.646956740, 58.395, 9094.0, 95.3625
22.690422500, 58.395, 8879.0, 94.2284
22.733888260, 58.395, 8801.0, 93.8136
22.777354020, 58.395, 8732.0, 93.4452
22.820819780, 58.395, 8622.0, 92.8547
22.864285540, 58.395, 8651.0, 93.0108
22.907751300, 58.395, 8675.0, 93.1397
22.951217060, 58.395, 8640.0, 92.9516
22.994682820, 58.395, 8652.0, 93.0161
23.038148580, 58.395, 8645.0, 92.9785
23.081614340, 58.395, 8665.0, 93.0860
23.125080100, 58.395, 8592.0, 92.6930
23.168545860, 58.395, 8817.0, 93.8989
23.212011620, 58.395, 8697.0, 93.2577
23.255477380, 58.395, 8731.0, 93.4398
23.298943140, 58.395, 8420.0, 91.7606
23.342408900, 58.395, 8397.0, 91.6351
23.385874660, 58.395, 8311.0, 91.1647
23.429340420, 58.395, 8286.0, 91.0275
23.472806180, 58.395, 8336.0, 91.3017
23.516271940, 58.395, 8235.0, 90.7469
23.559737700, 58.395, 8346.0, 91.3564
23.603203460, 58.395, 8261.0, 90.8900
23.646669220, 58.395, 8297.0, 91.0879
23.690134980, 58.395, 8386.0, 91.5751
23.733600740, 58.395, 8412.0, 91.7170
23.777066500, 58.395, 8445.0, 91.8967
23.820532260, 58.395, 8779.0, 93.6963
23.863998020, 58.395, 8916.0, 94.4246
23.907463780, 58.395, 9282.0, 96.3431
23.950929540, 58.395, 9950.0, 99.7497
23.994395300, 58.395, 10986.0, 104.8141
24.037861060, 58.395, 11995.0, 109.5217
24.081326820, 58.395, 13249.0, 115.1043
24.124792580, 58.395, 14571.0, 120.7104
24.168258340, 58.395, 16338.0, 127.8202
24.211724100, 58.395, 16782.0, 129.5454
24.255189860, 58.395, 15749.0, 125.4950
24.298655620, 58.395, 13693.0, 117.0171
24.342121380, 58.395, 11291.0, 106.2591
24.385587140, 58.395, 9370.0, 96.7988
24.429052900, 58.395, 8558.0, 92.5095
24.472518660, 58.395, 8052.0, 89.7329
24.515984420, 58.395, 7727.0, 87.9034
24.559450180, 58.395, 7720.0, 87.8635
24.602915940, 58.395, 7618.0, 87.2812
24.646381700, 58.395, 7612.0, 87.2468
24.689847460, 58.395, 7506.0, 86.6372
24.733313220, 58.395, 7672.0, 87.5900
24.776778980, 58.395, 7556.0, 86.9253
24.820244740, 58.395, 7406.0, 86.0581
24.863710500, 58.395, 7312.0, 85.5102
24.907176260, 58.395, 7152.0, 84.5695
24.950642020, 58.395, 7131.0, 84.4452
24.994107780, 58.395, 6958.0, 83.4146
25.037573540, 58.395, 6863.0, 82.8432
25.081039300, 58.395, 6910.0, 83.1264
25.124505060, 58.395, 6903.0, 83.0843
25.167970820, 58.395, 7109.0, 84.3149
25.211436580, 58.395, 6960.0, 83.4266
25.254902340, 58.395, 6978.0, 83.5344
25.298368100, 58.395, 7037.0, 83.8868
25.341833860, 58.395, 7160.0, 84.6168
25.385299620, 58.395, 7115.0, 84.3505
25.428765380, 58.395, 7015.0, 83.7556
25.472231140, 58.395, 7104.0, 84.2852
25.515696900, 58.395, 7124.0, 84.4038
25.559162660, 58.395, 7143.0, 84.5163
25.602628420, 58.395, 7176.0, 84.7113
25.646094180, 58.395, 7023.0, 83.8033
25.689559940, 58.395, 6957.0, 83.4086
25.733025700, 58.395, 6826.0, 82.6196
25.776491460, 58.395, 6864.0, 82.8493
25.819957220, 58.395, 6818.0, 82.5712
25.863422980, 58.395, 6671.0, 81.6762
25.906888740, 58.395, 6454.0, 80.3368
25.950354500, 58.395, 6432.0, 80.1998
25.993820260, 58.395, 6313.0, 79.4544
26.037286020, 58.395, 6279.0, 79.2401
26.080751780, 58.395, 6353.0, 79.7057
26.124217540, 58.395, 6459.0, 80.3679
26.167683300, 58.395, 6849.0, 82.7587
26.211149060, 58.395, 7045.0, 83.9345
26.254614820, 58.395, 6984.0, 83.5703
26.298080580, 58.395, 7022.0, 83.7974
26.341546340, 58.395, 6868.0, 82.8734
26.385012100, 58.395, 6597.0, 81.2219
26.428477860, 58.395, 6221.0, 78.8733
26.471943620, 58.395, 6124.0, 78.2560
26.515409380, 58.395, 5864.0, 76.5768
26.558875140, 58.395, 5759.0, 75.8881
26.602340900, 58.395, 5696.0, 75.4718
26.645806660, 58.395, 5569.0, 74.6257
26.689272420, 58.395, 5553.0, 74.5185
26.732738180, 58.395, 5556.0, 74.5386
26.776203940, 58.395, 5495.0, 74.1283
26.819669700, 58.395, 5452.0, 73.8377
26.863135460, 58.395, 5377.0, 73.3280
26.906601220, 58.395, 5381.0, 73.3553
26.950066980, 58.395, 5263.0, 72.5465
26.993532740, 58.395, 5211.0, 72.1873
27.036998500, 58.395, 5077.0, 71.2531
27.080464260, 58.395, 5172.0, 71.9166
27.123930020, 58.395, 5248.0, 72.4431
27.167395780, 58.395, 5089.0, 71.3372
27.210861540, 58.395, 5173.0, 71.9236
27.254327300, 58.395, 5102.0, 71.4283
27.297793060, 58.395, 5052.0, 71.0774
27.341258820, 58.395, 4757.0, 68.9710
27.384724580, 58.395, 4965.0, 70.4628
27.428190340, 58.395, 4899.0, 69.9929
27.471656100, 58.395, 4964.0, 70.4557
27.515121860, 58.395, 4845.0, 69.6060
27.558587620, 58.395, 4843.0, 69.5917
27.602053380, 58.395, 4905.0, 70.0357
27.645519140, 58.395, 4900.0, 70.0000
27.688984900, 58.395, 4800.0, 69.2820
27.732450660, 58.395, 4763.0, 69.0145
27.775916420, 58.395, 4791.0, 69.2170
27.819382180, 58.395, 4741.0, 68.8549
27.862847940, 58.395, 4654.0, 68.2202
27.906313700, 58.395, 4637.0, 68.0955
27.949779460, 58.395, 4611.0, 67.9043
27.993245220, 58.395, 4772.0, 69.0797
28.036710980, 58.395, 4690.0, 68.4836
28.080176740, 58.395, 4636.0, 68.0882
28.123642500, 58.395, 4777.0, 69.1158
28.167108260, 58.395, 4808.0, 69.3397
28.210574020, 58.395, 4759.0, 68.9855
28.254039780, 58.395, 4816.0, 69.3974
28.297505540, 58.395, 4496.0, 67.0522
28.340971300, 58.395, 4496.0, 67.0522
28.384437060, 58.395, 4478.0, 66.9179
28.427902820, 58.395, 4409.0, 66.4003
28.471368580, 58.395, 4452.0, 66.7233
28.514834340, 58.395, 4588.0, 67.7348
28.558300100, 58.395, 4413.0, 66.4304
28.601765860, 58.395, 4394.0, 66.2873
28.645231620, 58.395, 4363.0, 66.0530
28.688697380, 58.395, 4470.0, 66.8581
28.732163140, 58.395, 4418.0, 66.4680
28.775628900, 58.395, 4234.0, 65.0692
28.819094660, 58.395, 4319.0, 65.7191
28.862560420, 58.395, 4192.0, 64.7457
28.906026180, 58.395, 4205.0, 64.8460
28.949491940, 58.395, 4268.0, 65.3299
28.992957700, 58.395, 4249.0, 65.1844
29.036423460, 58.395, 4249.0, 65.1844
29.079889220, 58.395, 4125.0, 64.2262
29.123354980, 58.395, 4151.0, 64.4283
29.166820740, 58.395, 4203.0, 64.8305
29.210286500, 58.395, 4224.0, 64.9923
29.253752260, 58.395, 4099.0, 64.0234
29.297218020, 58.395, 4083.0, 63.8984
29.340683780, 58.395, 4102.0, 64.0469
29.384149540, 58.395, 4023.0, 63.4271
29.427615300, 58.395, 4074.0, 63.8279
29.471081060, 58.395, 4040.0, 63.5610
29.514546820, 58.395, 4061.0, 63.7260
29.558012580, 58.395, 4098.0, 64.0156
29.601478340, 58.395, 3972.0, 63.0238
29.644944100, 58.395, 3940.0, 62.7694
29.688409860, 58.395, 3934.0, 62.7216
29.731875620, 58.395, 3959.0, 62.9206
29.775341380, 58.395, 3883.0, 62.3137
29.818807140, 58.395, 3940.0, 62.7694
29.862272900, 58.395, 4003.0, 63.2693
29.905738660, 58.395, 3927.0, 62.6658
29.949204420, 58.395, 3887.0, 62.3458
29.992670180, 58.395, 3882.0, 62.3057
30.036135940, 58.395, 3848.0, 62.0322
30.079601700, 58.395, 3959.0, 62.9206
30.123067460, 58.395, 3897.0, 62.4260
30.166533220, 58.395, 3859.0, 62.1208
30.209998980, 58.395, 3748.0, 61.2209
30.253464740, 58.395, 3618.0, 60.1498
30.296930500, 58.395, 3679.0, 60.6548
30.340396260, 58.395, 3501.0, 59.1692
30.383862020, 58.395, 3604.0, 60.0333
30.427327780, 58.395, 3695.0, 60.7865
30.470793540, 58.395, 3551.0, 59.5903
30.514259300, 58.395, 3661.0, 60.5062
30.557725060, 58.395, 3485.0, 59.0339
30.601190820, 58.395, 3598.0, 59.9833
30.644656580, 58.395, 3548.0, 59.5651
30.688122340, 58.395, 3557.0, 59.6406
30.731588100, 58.395, 3517.0, 59.3043
30.775053860, 58.395, 3546.0, 59.5483
30.818519620, 58.395, 3516.0, 59.2959
30.861985380, 58.395, 3515.0, 59.2874
30.905451140, 58.395, 3519.0, 59.3212
30.948916900, 58.395, 3568.0, 59.7327
30.992382660, 58.395, 3513.0, 59.2706
31.035848420, 58.395, 3468.0, 58.8897
31.079314180, 58.395, 3487.0, 59.0508
31.122779940, 58.395, 3529.0, 59.4054
31.166245700, 58.395, 3452.0, 58.7537
31.209711460, 58.395, 3342.0, 57.8100
31.253177220, 58.395, 3414.0, 58.4294
31.296642980, 58.395, 3387.0, 58.1979
31.340108740, 58.395, 3396.0, 58.2752
31.383574500, 58.395, 3454.0, 58.7707
31.427040260, 58.395, 3325.0, 57.6628
31.470506020, 58.395, 3435.0, 58.6089
31.513971780, 58.395, 3275.0, 57.2276
31.557437540, 58.395, 3377.0, 58.1120
31.600903300, 58.395, 3348.0, 57.8619
31.644369060, 58.395, 3274.0, 57.2189
31.687834820, 58.395, 3241.0, 56.9298
31.731300580, 58.395, 3237.0, 56.8946
31.774766340, 58.395, 3390.0, 58.2237
31.818232100, 58.395, 3260.0, 57.0964
31.861697860, 58.395, 3357.0, 57.9396
31.905163620, 58.395, 3280.0, 57.2713
31.948629380, 58.395, 3331.0, 57.7148
31.992095140, 58.395, 3283.0, 57.2975
32.035560900, 58.395, 3177.0, 56.3649
32.079026660, 58.395, 3143.0, 56.0625
32.122492420, 58.395, 3289.0, 57.3498
32.165958180, 58.395, 3120.0, 55.8570
32.209423940, 58.395, 3229.0, 56.8243
32.252889700, 58.395, 3259.0, 57.0877
32.296355460, 58.395, 3306.0, 57.4978
32.339821220, 58.395, 3218.0, 56.7274
32.383286980, 58.395, 3299.0, 57.4369
32.426752740, 58.395, 3185.0, 56.4358
32.470218500, 58.395, 3227.0, 56.8067
32.513684260, 58.395, 3202.0, 56.5862
32.557150020, 58.395, 3159.0, 56.2050
32.600615780, 58.395, 3090.0, 55.5878
32.644081540, 58.395, 3182.0, 56.4092
32.687547300, 58.395, 3056.0, 55.2811
32.731013060, 58.395, 3170.0, 56.3028
32.774478820, 58.395, 3137.0, 56.0089
32.817944580, 58.395, 3099.0, 55.6687
32.861410340, 58.395, 3203.0, 56.5951
32.904876100, 58.395, 3045.0, 55.1815
32.948341860, 58.395, 3106.0, 55.7315
32.991807620, 58.395, 3122.0, 55.8749
33.035273380, 58.395, 3071.0, 55.4166
33.078739140, 58.395, 3207.0, 56.6304
33.122204900, 58.395, 2984.0, 54.6260
33.165670660, 58.395, 3037.0, 55.1090
33.209136420, 58.395, 3120.0, 55.8570
33.252602180, 58.395, 3030.0, 55.0454
33.296067940, 58.395, 3076.0, 55.4617
33.339533700, 58.395, 2979.0, 54.5802
33.382999460, 58.395, 3062.0, 55.3353
33.426465220, 58.395, 3012.0, 54.8817
33.469930980, 58.395, 2994.0, 54.7175
33.513396740, 58.395, 3012.0, 54.8817
33.556862500, 58.395, 2892.0, 53.7773
33.600328260, 58.395, 2966.0, 54.4610
33.643794020, 58.395, 2982.0, 54.6077
33.687259780, 58.395, 2916.0, 54.0000
33.730725540, 58.395, 2829.0, 53.1883
33.774191300, 58.395, 3040.0, 55.1362
33.817657060, 58.395, 2964.0, 54.4426
33.861122820, 58.395, 2906.0, 53.9073
33.904588580, 58.395, 2954.0, 54.3507
33.948054340, 58.395, 2994.0, 54.7175
33.991520100, 58.395, 2925.0, 54.0833
34.034985860, 58.395, 3029.0, 55.0364
34.078451620, 58.395, 2998.0, 54.7540
34.121917380, 58.395, 2969.0, 54.4885
34.165383140, 58.395, 2973.0, 54.5252
34.208848900, 58.395, 3027.0, 55.0182
34.252314660, 58.395, 2881.0, 53.6749
34.295780420, 58.395, 2991.0, 54.6900
34.339246180, 58.395, 2873.0, 53.6004
34.382711940, 58.395, 2804.0, 52.9528
34.426177700, 58.395, 2849.0, 53.3760
34.469643460, 58.395, 2793.0, 52.8488
34.513109220, 58.395, 2854.0, 53.4228
34.556574980, 58.395, 2793.0, 52.8488
34.600040740, 58.395, 2883.0, 53.6936
34.643506500, 58.395, 2845.0, 53.3385
34.686972260, 58.395, 2844.0, 53.3292
34.730438020, 58.395, 2877.0, 53.6377
34.773903780, 58.395, 2740.0, 52.3450
34.817369540, 58.395, 2817.0, 53.0754
34.860835300, 58.395, 2867.0, 53.5444
34.904301060, 58.395, 2855.0, 53.4322
34.947766820, 58.395, 2874.0, 53.6097
34.991232580, 58.395, 2807.0, 52.9811
35.034698340, 58.395, 2788.0, 52.8015
35.078164100, 58.395, 2916.0, 54.0000
35.121629860, 58.395, 2788.0, 52.8015
35.165095620, 58.395, 2906.0, 53.9073
35.208561380, 58.395, 2787.0, 52.7920
35.252027140, 58.395, 2867.0, 53.5444
35.295492900, 58.395, 2898.0, 53.8331
35.338958660, 58.395, 2881.0, 53.6749
35.382424420, 58.395, 2884.0, 53.7029
35.425890180, 58.395, 2789.0, 52.8110
35.469355940, 58.395, 2883.0, 53.6936
35.512821700, 58.395, 2902.0, 53.8702
35.556287460, 58.395, 2878.0, 53.6470
35.599753220, 58.395, 2750.0, 52.4404
35.643218980, 58.395, 2895.0, 53.8052
35.686684740, 58.395, 2861.0, 53.4883
35.730150500, 58.395, 2755.0, 52.4881
35.773616260, 58.395, 2766.0, 52.5928
35.817082020, 58.395, 2764.0, 52.5738
35.860547780, 58.395, 2769.0, 52.6213
35.904013540, 58.395, 2677.0, 51.7397
35.947479300, 58.395, 2706.0, 52.0192
35.990945060, 58.395, 2848.0, 53.3667
36.034410820, 58.395, 2761.0, 52.5452
36.077876580, 58.395, 2755.0, 52.4881
36.121342340, 58.395, 2711.0, 52.0673
36.164808100, 58.395, 2617.0, 51.1566
36.208273860, 58.395, 2656.0, 51.5364
36.251739620, 58.395, 2644.0, 51.4198
36.295205380, 58.395, 2760.0, 52.5357
36.338671140, 58.395, 2744.0, 52.3832
36.382136900, 58.395, 2710.0, 52.0577
36.425602660, 58.395, 2737.0, 52.3163
36.469068420, 58.395, 2715.0, 52.1057
36.512534180, 58.395, 2710.0, 52.0577
36.555999940, 58.395, 2764.0, 52.5738
36.599465700, 58.395, 2738.0, 52.3259
36.642931460, 58.395, 2741.0, 52.3546
36.686397220, 58.395, 2639.0, 51.3712
36.729862980, 58.395, 2767.0, 52.6023
36.773328740, 58.395, 2678.0, 51.7494
36.816794500, 58.395, 2626.0, 51.2445
36.860260260, 58.395, 2788.0, 52.8015
36.903726020, 58.395, 2772.0, 52.6498
36.947191780, 58.395, 2732.0, 52.2685
36.990657540, 58.395, 2756.0, 52.4976
37.034123300, 58.395, 2810.0, 53.0094
37.077589060, 58.395, 2647.0, 51.4490
37.121054820, 58.395, 2736.0, 52.3068
37.164520580, 58.395, 2667.0, 51.6430
37.207986340, 58.395, 2681.0, 51.7784
37.251452100, 58.395, 2648.0, 51.4587
37.294917860, 58.395, 2770.0, 52.6308
37.338383620, 58.395, 2684.0, 51.8073
37.381849380, 58.395, 2748.0, 52.4214
37.425315140, 58.395, 2681.0, 51.7784
37.468780900, 58.395, 2602.0, 51.0098
37.512246660, 58.395, 2626.0, 51.2445
37.555712420, 58.395, 2687.0, 51.8363
37.599178180, 58.395, 2617.0, 51.1566
37.642643940, 58.395, 2723.0, 52.1824
37.686109700, 58.395, 2714.0, 52.0961
37.729575460, 58.395, 2643.0, 51.4101
37.773041220, 58.395, 2564.0, 50.6360
37.816506980, 58.395, 2592.0, 50.9117
37.859972740, 58.395, 2538.0, 50.3786
37.903438500, 58.395, 2583.0, 50.8232
37.946904260, 58.395, 2612.0, 51.1077
37.990370020, 58.395, 2666.0, 51.6333
38.033835780, 58.395, 2598.0, 50.9706
38.077301540, 58.395, 2601.0, 51.0000
38.120767300, 58.395, 2570.0, 50.6952
38.164233060, 58.395, 2556.0, 50.5569
38.207698820, 58.395, 2662.0, 51.5946
38.251164580, 58.395, 2594.0, 50.9313
38.294630340, 58.395, 2632.0, 51.3030
38.338096100, 58.395, 2634.0, 51.3225
38.381561860, 58.395, 2587.0, 50.8626
38.425027620, 58.395, 2517.0, 50.1697
38.468493380, 58.395, 2627.0, 51.2543
38.511959140, 58.395, 2520.0, 50.1996
38.555424900, 58.395, 2609.0, 51.0784
38.598890660, 58.395, 2601.0, 51.0000
38.642356420, 58.395, 2651.0, 51.4879
38.685822180, 58.395, 2601.0, 51.0000
38.729287940, 58.395, 2576.0, 50.7543
38.772753700, 58.395, 2685.0, 51.8170
38.816219460, 58.395, 2628.0, 51.2640
38.859685220, 58.395, 2716.0, 52.1153
38.903150980, 58.395, 2625.0, 51.2348
38.946616740, 58.395, 2697.0, 51.9326
38.990082500, 58.395, 2692.0, 51.8845
39.033548260, 58.395, 2668.0, 51.6527
39.077014020, 58.395, 2584.0, 50.8331
39.120479780, 58.395, 2540.0, 50.3984
39.163945540, 58.395, 2489.0, 49.8899
39.207411300, 58.395, 2602.0, 51.0098
39.250877060, 58.395, 2569.0, 50.6853
39.294342820, 58.395, 2569.0, 50.6853
39.337808580, 58.395, 2554.0, 50.5371
39.381274340, 58.395, 2567.0, 50.6656
39.424740100, 58.395, 2503.0, 50.0300
39.468205860, 58.395, 2520.0, 50.1996
39.511671620, 58.395, 2548.0, 50.4777
39.555137380, 58.395, 2460.0, 49.5984
39.598603140, 58.395, 2675.0, 51.7204
39.642068900, 58.395, 2620.0, 51.1859
39.685534660, 58.395, 2623.0, 51.2152
39.729000420, 58.395, 2640.0, 51.3809
39.772466180, 58.395, 2562.0, 50.6162
39.815931940, 58.395, 2502.0, 50.0200
39.859397700, 58.395, 2562.0, 50.6162
39.902863460, 58.395, 2544.0, 50.4381
39.946329220, 58.395, 2572.0, 50.7149
39.989794980, 58.395, 2557.0, 50.5668
40.033260740, 58.395, 2567.0, 50.6656
40.076726500, 58.395, 2626.0, 51.2445
40.120192260, 58.395, 2454.0, 49.5379
40.163658020, 58.395, 2581.0, 50.8035
40.207123780, 58.395, 2576.0, 50.7543
40.250589540, 58.395, 2583.0, 50.8232
40.294055300, 58.395, 2554.0, 50.5371
40.337521060, 58.395, 2536.0, 50.3587
40.380986820, 58.395, 2506.0, 50.0600
40.424452580, 58.395, 2515.0, 50.1498
40.467918340, 58.395, 2492.0, 49.9199
40.511384100, 58.395, 2563.0, 50.6261
40.554849860, 58.395, 2499.0, 49.9900
40.598315620, 58.395, 2445.0, 49.4469
40.641781380, 58.395, 2468.0, 49.6790
40.685247140, 58.395, 2514.0, 50.1398
40.728712900, 58.395, 2461.0, 49.6085
40.772178660, 58.395, 2584.0, 50.8331
40.815644420, 58.395, 2599.0, 50.9804
40.859110180, 58.395, 2461.0, 49.6085
40.902575940, 58.395, 2469.0, 49.6890
40.946041700, 58.395, 2463.0, 49.6286
40.989507460, 58.395, 2513.0, 50.1298
41.032973220, 58.395, 2490.0, 49.8999
41.076438980, 58.395, 2486.0, 49.8598
41.119904740, 58.395, 2467.0, 49.6689
41.163370500, 58.395, 2410.0, 49.0918
41.206836260, 58.395, 2542.0, 50.4183
41.250302020, 58.395, 2495.0, 49.9500
41.293767780, 58.395, 2429.0, 49.2849
41.337233540, 58.395, 2464.0, 49.6387
41.380699300, 58.395, 2531.0, 50.3090
41.424165060, 58.395, 2490.0, 49.8999
41.467630820, 58.395, 2529.0, 50.2892
41.511096580, 58.395, 2426.0, 49.2544
41.554562340, 58.395, 2550.0, 50.4975
41.598028100, 58.395, 2451.0, 49.5076
41.641493860, 58.395, 2460.0, 49.5984
41.684959620, 58.395, 2475.0, 49.7494
41.728425380, 58.395, 2485.0, 49.8498
41.771891140, 58.395, 2524.0, 50.2394
41.815356900, 58.395, 2449.0, 49.4874
41.858822660, 58.395, 2585.0, 50.8429
41.902288420, 58.395, 2458.0, 49.5782
41.945754180, 58.395, 2584.0, 50.8331
41.989219940, 58.395, 2516.0, 50.1597
42.032685700, 58.395, 2548.0, 50.4777
42.076151460, 58.395, 2426.0, 49.2544
42.119617220, 58.395, 2537.0, 50.3686
42.163082980, 58.395, 2497.0, 49.9700
42.206548740, 58.395, 2459.0, 49.5883
42.250014500, 58.395, 2405.0, 49.0408
42.293480260, 58.395, 2525.0, 50.2494
42.336946020, 58.395, 2411.0, 49.1019
42.380411780, 58.395, 2408.0, 49.0714
42.423877540, 58.395, 2404.0, 49.0306
42.467343300, 58.395, 2372.0, 48.7032
42.510809060, 58.395, 2405.0, 49.0408
42.554274820, 58.395, 2438.0, 49.3761
42.597740580, 58.395, 2383.0, 48.8160
42.641206340, 58.395, 2433.0, 49.3254
42.684672100, 58.395, 2466.0, 49.6588
42.728137860, 58.395, 2425.0, 49.2443
42.771603620, 58.395, 2353.0, 48.5077
42.815069380, 58.395, 2360.0, 48.5798
42.858535140, 58.395, 2402.0, 49.0102
42.902000900, 58.395, 2393.0, 48.9183
42.945466660, 58.395, 2531.0, 50.3090
42.988932420, 58.395, 2322.0, 48.1871
43.032398180, 58.395, 2369.0, 48.6724
43.075863940, 58.395, 2366.0, 48.6415
43.119329700, 58.395, 2441.0, 49.4065
43.162795460, 58.395, 2433.0, 49.3254
43.206261220, 58.395, 2311.0, 48.0729
43.249726980, 58.395, 2350.0, 48.4768
43.293192740, 58.395, 2334.0, 48.3115
43.336658500, 58.395, 2444.0, 49.4368
43.380124260, 58.395, 2289.0, 47.8435
43.423590020, 58.395, 2326.0, 48.2286
43.467055780, 58.395, 2209.0, 47.0000
43.510521540, 58.395, 2251.0, 47.4447
43.553987300, 58.395, 2363.0, 48.6107
43.597453060, 58.395, 2410.0, 49.0918
43.640918820, 58.395, 2293.0, 47.8853
43.684384580, 58.395, 2193.0, 46.8295
43.727850340, 58.395, 2248.0, 47.4131
43.771316100, 58.395, 2282.0, 47.7703
43.814781860, 58.395, 2305.0, 48.0104
43.858247620, 58.395, 2320.0, 48.1664
43.901713380, 58.395, 2316.0, 48.1248
43.945179140, 58.395, 2271.0, 47.6550
43.988644900, 58.395, 2283.0, 47.7807
44.032110660, 58.395, 2314.0, 48.1041
44.075576420, 58.395, 2325.0, 48.2183
44.119042180, 58.395, 2411.0, 49.1019
44.162507940, 58.395, 2244.0, 47.3709
44.205973700, 58.395, 2284.0, 47.7912
44.249439460, 58.395, 2275.0, 47.6970
44.292905220, 58.395, 2313.0, 48.0937
44.336370980, 58.395, 2270.0, 47.6445
44.379836740, 58.395, 2280.0, 47.7493
44.423302500, 58.395, 2198.0, 46.8828
44.466768260, 58.395, 2308.0, 48.0416
44.510234020, 58.395, 2239.0, 47.3181
44.553699780, 58.395, 2322.0, 48.1871
44.597165540, 58.395, 2293.0, 47.8853
44.640631300, 58.395, 2264.0, 47.5815
44.684097060, 58.395, 2302.0, 47.9792
44.727562820, 58.395, 2281.0, 47.7598
44.771028580, 58.395, 2299.0, 47.9479
44.814494340, 58.395, 2209.0, 47.0000
44.857960100, 58.395, 2155.0, 46.4220
44.901425860, 58.395, 2232.0, 47.2440
44.944891620, 58.395, 2318.0, 48.1456
44.988357380, 58.395, 2245.0, 47.3814
45.031823140, 58.395, 2228.0, 47.2017
45.075288900, 58.395, 2238.0, 47.3075
45.118754660, 58.395, 2195.0, 46.8508
45.162220420, 58.395, 2220.0, 47.1169
45.205686180, 58.395, 2275.0, 47.6970
45.249151940, 58.395, 2213.0, 47.0425
45.292617700, 58.395, 2170.0, 46.5833
45.336083460, 58.395, 2220.0, 47.1169
45.379549220, 58.395, 2254.0, 47.4763
45.423014980, 58.395, 2181.0, 46.7012
45.466480740, 58.395, 2176.0, 46.6476
45.509946500, 58.395, 2174.0, 46.6262
45.553412260, 58.395, 2192.0, 46.8188
45.596878020, 58.395, 2122.0, 46.0652
45.640343780, 58.395, 2129.0, 46.1411
45.683809540, 58.395, 2282.0, 47.7703
45.727275300, 58.395, 2131.0, 46.1628
45.770741060, 58.395, 2095.0, 45.7712
45.814206820, 58.395, 2232.0, 47.2440
45.857672580, 58.395, 2209.0, 47.0000
45.901138340, 58.395, 2253.0, 47.4658
45.944604100, 58.395, 2171.0, 46.5940
45.988069860, 58.395, 2110.0, 45.9347
46.031535620, 58.395, 2067.0, 45.4643
46.075001380, 58.395, 2248.0, 47.4131
46.118467140, 58.395, 2188.0, 46.7761
46.161932900, 58.395, 2165.0, 46.5296
46.205398660, 58.395, 2198.0, 46.8828
46.248864420, 58.395, 2203.0, 46.9361
46.292330180, 58.395, 2154.0, 46.4112
46.335795940, 58.395, 2118.0, 46.0217
46.379261700, 58.395, 2130.0, 46.1519
46.422727460, 58.395, 2150.0, 46.3681
46.466193220, 58.395, 2017.0, 44.9110
46.509658980, 58.395, 2097.0, 45.7930
46.553124740, 58.395, 2153.0, 46.4004
46.596590500, 58.395, 2063.0, 45.4203
46.640056260, 58.395, 2035.0, 45.1110
46.683522020, 58.395, 2092.0, 45.7384
46.726987780, 58.395, 2080.0, 45.6070
46.770453540, 58.395, 2106.0, 45.8912
46.813919300, 58.395, 2066.0, 45.4533
46.857385060, 58.395, 2151.0, 46.3789
46.900850820, 58.395, 2189.0, 46.7868
46.944316580, 58.395, 2111.0, 45.9456
46.987782340, 58.395, 2236.0, 47.2864
47.031248100, 58.395, 2116.0, 46.0000
47.074713860, 58.395, 2095.0, 45.7712
47.118179620, 58.395, 2075.0, 45.5522
47.161645380, 58.395, 2163.0, 46.5081
47.205111140, 58.395, 2127.0, 46.1194
47.248576900, 58.395, 2144.0, 46.3033
47.292042660, 58.395, 2043.0, 45.1996
47.335508420, 58.395, 2074.0, 45.5412
47.378974180, 58.395, 2145.0, 46.3141
47.422439940, 58.395, 1999.0, 44.7102
47.465905700, 58.395, 2005.0, 44.7772
47.509371460, 58.395, 2113.0, 45.9674
47.552837220, 58.395, 2025.0, 45.0000
47.596302980, 58.395, 2107.0, 45.9021
47.639768740, 58.395, 2008.0, 44.8107
47.683234500, 58.395, 2015.0, 44.8888
47.726700260, 58.395, 1971.0, 44.3959
47.770166020, 58.395, 2010.0, 44.8330
47.813631780, 58.395, 1912.0, 43.7264
47.857097540, 58.395, 1941.0, 44.0568
47.900563300, 58.395, 1950.0, 44.1588
47.944029060, 58.395, 1959.0, 44.2606
47.987494820, 58.395, 1991.0, 44.6206
48.030960580, 58.395, 1967.0, 44.3509
48.074426340, 58.395, 1903.0, 43.6234
48.117892100, 58.395, 1852.0, 43.0349
48.161357860, 58.395, 1970.0, 44.3847
48.204823620, 58.395, 1885.0, 43.4166
48.248289380, 58.395, 1940.0, 44.0454
48.291755140, 58.395, 1913.0, 43.7379
48.335220900, 58.395, 1933.0, 43.9659
48.378686660, 58.395, 1913.0, 43.7379
48.422152420, 58.395, 1892.0, 43.4971
48.465618180, 58.395, 1879.0, 43.3474
48.509083940, 58.395, 1871.0, 43.2551
48.552549700, 58.395, 1842.0, 42.9185
48.596015460, 58.395, 1854.0, 43.0581
48.639481220, 58.395, 1930.0, 43.9318
48.682946980, 58.395, 1925.0, 43.8748
48.726412740, 58.395, 1895.0, 43.5316
48.769878500, 58.395, 1861.0, 43.1393
48.813344260, 58.395, 1846.0, 42.9651
48.856810020, 58.395, 1863.0, 43.1625
48.900275780, 58.395, 1805.0, 42.4853
48.943741540, 58.395, 1924.0, 43.8634
48.987207300, 58.395, 1886.0, 43.4281
49.030673060, 58.395, 1830.0, 42.7785
49.074138820, 58.395, 1825.0, 42.7200
49.117604580, 58.395, 1755.0, 41.8927
49.161070340, 58.395, 1824.0, 42.7083
49.204536100, 58.395, 1833.0, 42.8135
49.248001860, 58.395, 1851.0, 43.0232
49.291467620, 58.395, 1878.0, 43.3359
49.334933380, 58.395, 1856.0, 43.0813
49.378399140, 58.395, 1870.0, 43.2435
49.421864900, 58.395, 1840.0, 42.8952
49.465330660, 58.395, 1829.0, 42.7668
49.508796420, 58.395, 1812.0, 42.5676
49.552262180, 58.395, 1805.0, 42.4853
49.595727940, 58.395, 1793.0, 42.3438
49.639193700, 58.395, 1817.0, 42.6263
49.682659460, 58.395, 1774.0, 42.1189
49.726125220, 58.395, 1761.0, 41.9643
49.769590980, 58.395, 1776.0, 42.1426
49.813056740, 58.395, 1774.0, 42.1189
49.856522500, 58.395, 1760.0, 41.9524
49.899988260, 58.395, 1782.0, 42.2137
49.943454020, 58.395, 1733.0, 41.6293
49.986919780, 58.395, 1799.0, 42.4146
50.030385540, 58.395, 1790.0, 42.3084
50.073851300, 58.395, 1735.0, 41.6533
50.117317060, 58.395, 1690.0, 41.1096
50.160782820, 58.395, 1751.0, 41.8450
50.204248580, 58.395, 1709.0, 41.3401
50.247714340, 58.395, 1654.0, 40.6694
50.291180100, 58.395, 1742.0, 41.7373
50.334645860, 58.395, 1658.0, 40.7185
50.378111620, 58.395, 1741.0, 41.7253
50.421577380, 58.395, 1746.0, 41.7852
50.465043140, 58.395, 1694.0, 41.1582
50.508508900, 58.395, 1716.0, 41.4246
50.551974660, 58.395, 1762.0, 41.9762
50.595440420, 58.395, 1792.0, 42.3320
50.638906180, 58.395, 1685.0, 41.0488
50.682371940, 58.395, 1741.0, 41.7253
50.725837700, 58.395, 1723.0, 41.5090
50.769303460, 58.395, 1700.0, 41.2311
50.812769220, 58.395, 1607.0, 40.0874
50.856234980, 58.395, 1602.0, 40.0250
50.899700740, 58.395, 1702.0, 41.2553
50.943166500, 58.395, 1756.0, 41.9047
50.986632260, 58.395, 1701.0, 41.2432
51.030098020, 58.395, 1627.0, 40.3361
51.073563780, 58.395, 1618.0, 40.2244
51.117029540, 58.395, 1641.0, 40.5093
51.160495300, 58.395, 1693.0, 41.1461
51.203961060, 58.395, 1687.0, 41.0731
51.247426820, 58.395, 1609.0, 40.1123
51.290892580, 58.395, 1654.0, 40.6694
51.334358340, 58.395, 1634.0, 40.4228
51.377824100, 58.395, 1667.0, 40.8289
51.421289860, 58.395, 1610.0, 40.1248
51.464755620, 58.395, 1682.0, 41.0122
51.508221380, 58.395, 1637.0, 40.4599
51.551687140, 58.395, 1549.0, 39.3573
51.595152900, 58.395, 1625.0, 40.3113
51.638618660, 58.395, 1659.0, 40.7308
51.682084420, 58.395, 1596.0, 39.9500
51.725550180, 58.395, 1651.0, 40.6325
51.769015940, 58.395, 1582.0, 39.7744
51.812481700, 58.395, 1570.0, 39.6232
51.855947460, 58.395, 1608.0, 40.0999
51.899413220, 58.395, 1644.0, 40.5463
51.942878980, 58.395, 1561.0, 39.5095
51.986344740, 58.395, 1567.0, 39.5854
52.029810500, 58.395, 1618.0, 40.2244
52.073276260, 58.395, 1509.0, 38.8458
52.116742020, 58.395, 1537.0, 39.2046
52.160207780, 58.395, 1546.0, 39.3192
52.203673540, 58.395, 1546.0, 39.3192
52.247139300, 58.395, 1576.0, 39.6989
52.290605060, 58.395, 1472.0, 38.3667
52.334070820, 58.395, 1481.0, 38.4838
52.377536580, 58.395, 1474.0, 38.3927
52.421002340, 58.395, 1509.0, 38.8458
52.464468100, 58.395, 1394.0, 37.3363
52.507933860, 58.395, 1462.0, 38.2361
52.551399620, 58.395, 1491.0, 38.6135
52.594865380, 58.395, 1535.0, 39.1791
52.638331140, 58.395, 1448.0, 38.0526
52.681796900, 58.395, 1539.0, 39.2301
52.725262660, 58.395, 1439.0, 37.9342
52.768728420, 58.395, 1554.0, 39.4208
52.812194180, 58.395, 1465.0, 38.2753
52.855659940, 58.395, 1469.0, 38.3275
52.899125700, 58.395, 1393.0, 37.3229
52.942591460, 58.395, 1466.0, 38.2884
52.986057220, 58.395, 1489.0, 38.5876
53.029522980, 58.395, 1454.0, 38.1314
53.072988740, 58.395, 1514.0, 38.9102
53.116454500, 58.395, 1451.0, 38.0920
53.159920260, 58.395, 1484.0, 38.5227
53.203386020, 58.395, 1489.0, 38.5876
53.246851780, 58.395, 1433.0, 37.8550
53.290317540, 58.395, 1403.0, 37.4566
53.333783300, 58.395, 1461.0, 38.2230
53.377249060, 58.395, 1414.0, 37.6032
53.420714820, 58.395, 1422.0, 37.7094
53.464180580, 58.395, 1498.0, 38.7040
53.507646340, 58.395, 1403.0, 37.4566
53.551112100, 58.395, 1420.0, 37.6829
53.594577860, 58.395, 1408.0, 37.5233
53.638043620, 58.395, 1376.0, 37.0945
53.681509380, 58.395, 1385.0, 37.2156
53.724975140, 58.395, 1450.0, 38.0789
53.768440900, 58.395, 1374.0, 37.0675
53.811906660, 58.395, 1387.0, 37.2424
53.855372420, 58.395, 1402.0, 37.4433
53.898838180, 58.395, 1315.0, 36.2629
53.942303940, 58.395, 1460.0, 38.2099
53.985769700, 58.395, 1359.0, 36.8646
54.029235460, 58.395, 1341.0, 36.6197
54.072701220, 58.395, 1383.0, 37.1887
54.116166980, 58.395, 1306.0, 36.1386
54.159632740, 58.395, 1354.0, 36.7967
54.203098500, 58.395, 1375.0, 37.0810
54.246564260, 58.395, 1363.0, 36.9188
54.290030020, 58.395, 1376.0, 37.0945
54.333495780, 58.395, 1327.0, 36.4280
54.376961540, 58.395, 1337.0, 36.5650
54.420427300, 58.395, 1356.0, 36.8239
54.463893060, 58.395, 1304.0, 36.1109
54.507358820, 58.395, 1345.0, 36.6742
54.550824580, 58.395, 1396.0, 37.3631
54.594290340, 58.395, 1294.0, 35.9722
54.637756100, 58.395, 1333.0, 36.5103
54.681221860, 58.395, 1312.0, 36.2215
54.724687620, 58.395, 1366.0, 36.9594
54.768153380, 58.395, 1306.0, 36.1386
54.811619140, 58.395, 1348.0, 36.7151
54.855084900, 58.395, 1282.0, 35.8050
54.898550660, 58.395, 1342.0, 36.6333
54.942016420, 58.395, 1394.0, 37.3363
54.985482180, 58.395, 1312.0, 36.2215
55.028947940, 58.395, 1336.0, 36.5513
55.072413700, 58.395, 1305.0, 36.1248
55.115879460, 58.395, 1302.0, 36.0832
55.159345220, 58.395, 1365.0, 36.9459
55.202810980, 58.395, 1304.0, 36.1109
55.246276740, 58.395, 1331.0, 36.4829
55.289742500, 58.395, 1316.0, 36.2767
55.333208260, 58.395, 1300.0, 36.0555
55.376674020, 58.395, 1325.0, 36.4005
55.420139780, 58.395, 1338.0, 36.5787
55.463605540, 58.395, 1313.0, 36.2353
55.507071300, 58.395, 1293.0, 35.9583
55.550537060, 58.395, 1328.0, 36.4417
55.594002820, 58.395, 1310.0, 36.1939
55.637468580, 58.395, 1270.0, 35.6371
55.680934340, 58.395, 1343.0, 36.6470
55.724400100, 58.395, 1333.0, 36.5103
55.767865860, 58.395, 1355.0, 36.8103
55.811331620, 58.395, 1332.0, 36.4966
55.854797380, 58.395, 1310.0, 36.1939
55.898263140, 58.395, 1299.0, 36.0416
55.941728900, 58.395, 1370.0, 37.0135
55.985194660, 58.395, 1406.0, 37.4967
56.028660420, 58.395, 1316.0, 36.2767
56.072126180, 58.395, 1245.0, 35.2846
56.115591940, 58.395, 1334.0, 36.5240
56.159057700, 58.395, 1334.0, 36.5240
56.202523460, 58.395, 1348.0, 36.7151
56.245989220, 58.395, 1284.0, 35.8329
56.289454980, 58.395, 1236.0, 35.1568
56.332920740, 58.395, 1205.0, 34.7131
56.376386500, 58.395, 1246.0, 35.2987
56.419852260, 58.395, 1278.0, 35.7491
56.463318020, 58.395, 1244.0, 35.2704
56.506783780, 58.395, 1293.0, 35.9583
56.550249540, 58.395, 1180.0, 34.3511
56.593715300, 58.395, 1209.0, 34.7707
56.637181060, 58.395, 1297.0, 36.0139
56.680646820, 58.395, 1289.0, 35.9026
56.724112580, 58.395, 1197.0, 34.5977
56.767578340, 58.395, 1225.0, 35.0000
56.811044100, 58.395, 1199.0, 34.6266
56.854509860, 58.395, 1260.0, 35.4965
56.897975620, 58.395, 1221.0, 34.9428
56.941441380, 58.395, 1219.0, 34.9142
56.984907140, 58.395, 1252.0, 35.3836
57.028372900, 58.395, 1233.0, 35.1141
57.071838660, 58.395, 1226.0, 35.0143
57.115304420, 58.395, 1173.0, 34.2491
57.158770180, 58.395, 1189.0, 34.4819
57.202235940, 58.395, 1213.0, 34.8281
57.245701700, 58.395, 1241.0, 35.2278
57.289167460, 58.395, 1158.0, 34.0294
57.332633220, 58.395, 1187.0, 34.4529
57.376098980, 58.395, 1195.0, 34.5688
57.419564740, 58.395, 1209.0, 34.7707
57.463030500, 58.395, 1166.0, 34.1467
57.506496260, 58.395, 1209.0, 34.7707
57.549962020, 58.395, 1225.0, 35.0000
57.593427780, 58.395, 1178.0, 34.3220
57.636893540, 58.395, 1211.0, 34.7994
57.680359300, 58.395, 1149.0, 33.8969
57.723825060, 58.395, 1162.0, 34.0881
57.767290820, 58.395, 1181.0, 34.3657
57.810756580, 58.395, 1205.0, 34.7131
57.854222340, 58.395, 1146.0, 33.8526
57.897688100, 58.395, 1135.0, 33.6898
57.941153860, 58.395, 1203.0, 34.6843
57.984619620, 58.395, 1211.0, 34.7994
58.028085380, 58.395, 1169.0, 34.1906
58.071551140, 58.395, 1157.0, 34.0147
58.115016900, 58.395, 1175.0, 34.2783
58.158482660, 58.395, 1163.0, 34.1028
58.201948420, 58.395, 1183.0, 34.3948
58.245414180, 58.395, 1122.0, 33.4963
58.288879940, 58.395, 1201.0, 34.6554
58.332345700, 58.395, 1156.0, 34.0000
58.375811460, 58.395, 1042.0, 32.2800
58.419277220, 58.395, 1130.0, 33.6155
58.462742980, 58.395, 1158.0, 34.0294
58.506208740, 58.395, 1112.0, 33.3467
58.549674500, 58.395, 1180.0, 34.3511
58.593140260, 58.395, 1175.0, 34.2783
58.636606020, 58.395, 1145.0, 33.8378
58.680071780, 58.395, 1133.0, 33.6601
58.723537540, 58.395, 1151.0, 33.9264
58.767003300, 58.395, 1165.0, 34.1321
58.810469060, 58.395, 1126.0, 33.5559
58.853934820, 58.395, 1096.0, 33.1059
58.897400580, 58.395, 1166.0, 34.1467
58.940866340, 58.395, 1170.0, 34.2053
58.984332100, 58.395, 1152.0, 33.9411
59.027797860, 58.395, 1181.0, 34.3657
59.071263620, 58.395, 1124.0, 33.5261
59.114729380, 58.395, 1117.0, 33.4215
59.158195140, 58.395, 1139.0, 33.7491
59.201660900, 58.395, 1126.0, 33.5559
59.245126660, 58.395, 1171.0, 34.2199
59.288592420, 58.395, 1153.0, 33.9559
59.332058180, 58.395, 1082.0, 32.8938
59.375523940, 58.395, 1131.0, 33.6303
59.418989700, 58.395, 1139.0, 33.7491
59.462455460, 58.395, 1139.0, 33.7491
59.505921220, 58.395, 1114.0, 33.3766
59.549386980, 58.395, 1133.0, 33.6601
59.592852740, 58.395, 1128.0, 33.5857
59.636318500, 58.395, 1121.0, 33.4813
59.679784260, 58.395, 1178.0, 34.3220
59.723250020, 58.395, 1119.0, 33.4515
59.766715780, 58.395, 1142.0, 33.7935
59.810181540, 58.395, 1056.0, 32.4962
59.853647300, 58.395, 1129.0, 33.6006
59.897113060, 58.395, 1060.0, 32.5576
59.940578820, 58.395, 1135.0, 33.6898
59.984044580, 58.395, 1109.0, 33.3017
59.994911020, 58.395, 1098.0, 33.1361