File: XRD/2025_06_12_NaCl_3_60_8m_pXRD.csv
[Measurement conditions]
Sample identification,2025_06_12_NaCl_3_60_8m_pXRD
Comment - 1,"Salt Std"
Anode material,Cu
K-Alpha1 wavelength,1.5405980
K-Alpha2 wavelength,1.5444260
Ratio K-Alpha2/K-Alpha1,0.500
Divergence slit,Fixed,0.76mm
Monochromator used,NO
Generator voltage, 40
Tube current, 15
File date and time,12/Jun/2025 14:41
Unit cell,
h k l, 0 0 0
Scan axis,Gonio
Scan range,2.995000000,60.000344240
Scan step size,0.0108664
No. of points, 5246
Scan type,CONTINUOUS
Time per step,18.870
[Scan points]
Angle, TimePerStep, Intensity, ESD
3.000433220, 18.870, 43180.0, 207.7980
3.043898980, 18.870, 41945.0, 204.8048
3.087364740, 18.870, 39672.0, 199.1783
3.130830500, 18.870, 37825.0, 194.4865
3.174296260, 18.870, 35464.0, 188.3189
3.217762020, 18.870, 33490.0, 183.0027
3.261227780, 18.870, 31751.0, 178.1881
3.304693540, 18.870, 30239.0, 173.8936
3.348159300, 18.870, 28364.0, 168.4162
3.391625060, 18.870, 26949.0, 164.1615
3.435090820, 18.870, 25398.0, 159.3675
3.478556580, 18.870, 23769.0, 154.1720
3.522022340, 18.870, 22316.0, 149.3854
3.565488100, 18.870, 20883.0, 144.5095
3.608953860, 18.870, 19640.0, 140.1428
3.652419620, 18.870, 18359.0, 135.4954
3.695885380, 18.870, 16999.0, 130.3802
3.739351140, 18.870, 16329.0, 127.7850
3.782816900, 18.870, 15091.0, 122.8454
3.826282660, 18.870, 14250.0, 119.3734
3.869748420, 18.870, 13123.0, 114.5557
3.913214180, 18.870, 12295.0, 110.8828
3.956679940, 18.870, 11392.0, 106.7333
4.000145700, 18.870, 10671.0, 103.3005
4.043611460, 18.870, 9907.0, 99.5339
4.087077220, 18.870, 8923.0, 94.4616
4.130542980, 18.870, 8579.0, 92.6229
4.174008740, 18.870, 7897.0, 88.8651
4.217474500, 18.870, 7204.0, 84.8764
4.260940260, 18.870, 6677.0, 81.7129
4.304406020, 18.870, 6237.0, 78.9747
4.347871780, 18.870, 5549.0, 74.4916
4.391337540, 18.870, 5190.0, 72.0417
4.434803300, 18.870, 4763.0, 69.0145
4.478269060, 18.870, 4303.0, 65.5973
4.521734820, 18.870, 3996.0, 63.2139
4.565200580, 18.870, 3795.0, 61.6036
4.608666340, 18.870, 3443.0, 58.6771
4.652132100, 18.870, 3072.0, 55.4256
4.695597860, 18.870, 3043.0, 55.1634
4.739063620, 18.870, 2619.0, 51.1762
4.782529380, 18.870, 2501.0, 50.0100
4.825995140, 18.870, 2506.0, 50.0600
4.869460900, 18.870, 2256.0, 47.4974
4.912926660, 18.870, 2275.0, 47.6970
4.956392420, 18.870, 2165.0, 46.5296
4.999858180, 18.870, 2104.0, 45.8694
5.043323940, 18.870, 1974.0, 44.4297
5.086789700, 18.870, 2079.0, 45.5961
5.130255460, 18.870, 2012.0, 44.8553
5.173721220, 18.870, 1931.0, 43.9431
5.217186980, 18.870, 2103.0, 45.8585
5.260652740, 18.870, 2004.0, 44.7661
5.304118500, 18.870, 1938.0, 44.0227
5.347584260, 18.870, 1976.0, 44.4522
5.391050020, 18.870, 1854.0, 43.0581
5.434515780, 18.870, 1778.0, 42.1663
5.477981540, 18.870, 1674.0, 40.9145
5.521447300, 18.870, 1520.0, 38.9872
5.564913060, 18.870, 1382.0, 37.1753
5.608378820, 18.870, 1352.0, 36.7696
5.651844580, 18.870, 1266.0, 35.5809
5.695310340, 18.870, 1180.0, 34.3511
5.738776100, 18.870, 1126.0, 33.5559
5.782241860, 18.870, 1070.0, 32.7109
5.825707620, 18.870, 1000.0, 31.6228
5.869173380, 18.870, 981.0, 31.3209
5.912639140, 18.870, 938.0, 30.6268
5.956104900, 18.870, 930.0, 30.4959
5.999570660, 18.870, 954.0, 30.8869
6.043036420, 18.870, 965.0, 31.0644
6.086502180, 18.870, 860.0, 29.3258
6.129967940, 18.870, 894.0, 29.8998
6.173433700, 18.870, 879.0, 29.6479
6.216899460, 18.870, 827.0, 28.7576
6.260365220, 18.870, 833.0, 28.8617
6.303830980, 18.870, 794.0, 28.1780
6.347296740, 18.870, 818.0, 28.6007
6.390762500, 18.870, 821.0, 28.6531
6.434228260, 18.870, 697.0, 26.4008
6.477694020, 18.870, 814.0, 28.5307
6.521159780, 18.870, 735.0, 27.1109
6.564625540, 18.870, 704.0, 26.5330
6.608091300, 18.870, 733.0, 27.0740
6.651557060, 18.870, 778.0, 27.8927
6.695022820, 18.870, 691.0, 26.2869
6.738488580, 18.870, 715.0, 26.7395
6.781954340, 18.870, 729.0, 27.0000
6.825420100, 18.870, 638.0, 25.2587
6.868885860, 18.870, 693.0, 26.3249
6.912351620, 18.870, 712.0, 26.6833
6.955817380, 18.870, 737.0, 27.1477
6.999283140, 18.870, 680.0, 26.0768
7.042748900, 18.870, 661.0, 25.7099
7.086214660, 18.870, 726.0, 26.9444
7.129680420, 18.870, 707.0, 26.5895
7.173146180, 18.870, 708.0, 26.6083
7.216611940, 18.870, 702.0, 26.4953
7.260077700, 18.870, 682.0, 26.1151
7.303543460, 18.870, 754.0, 27.4591
7.347009220, 18.870, 726.0, 26.9444
7.390474980, 18.870, 697.0, 26.4008
7.433940740, 18.870, 716.0, 26.7582
7.477406500, 18.870, 750.0, 27.3861
7.520872260, 18.870, 760.0, 27.5681
7.564338020, 18.870, 725.0, 26.9258
7.607803780, 18.870, 778.0, 27.8927
7.651269540, 18.870, 722.0, 26.8701
7.694735300, 18.870, 777.0, 27.8747
7.738201060, 18.870, 755.0, 27.4773
7.781666820, 18.870, 828.0, 28.7750
7.825132580, 18.870, 791.0, 28.1247
7.868598340, 18.870, 817.0, 28.5832
7.912064100, 18.870, 852.0, 29.1890
7.955529860, 18.870, 884.0, 29.7321
7.998995620, 18.870, 847.0, 29.1033
8.042461380, 18.870, 821.0, 28.6531
8.085927140, 18.870, 833.0, 28.8617
8.129392900, 18.870, 890.0, 29.8329
8.172858660, 18.870, 880.0, 29.6648
8.216324420, 18.870, 920.0, 30.3315
8.259790180, 18.870, 858.0, 29.2916
8.303255940, 18.870, 957.0, 30.9354
8.346721700, 18.870, 896.0, 29.9333
8.390187460, 18.870, 945.0, 30.7409
8.433653220, 18.870, 914.0, 30.2324
8.477118980, 18.870, 860.0, 29.3258
8.520584740, 18.870, 936.0, 30.5941
8.564050500, 18.870, 914.0, 30.2324
8.607516260, 18.870, 990.0, 31.4643
8.650982020, 18.870, 1034.0, 32.1559
8.694447780, 18.870, 985.0, 31.3847
8.737913540, 18.870, 989.0, 31.4484
8.781379300, 18.870, 1045.0, 32.3265
8.824845060, 18.870, 1009.0, 31.7648
8.868310820, 18.870, 1046.0, 32.3419
8.911776580, 18.870, 1044.0, 32.3110
8.955242340, 18.870, 1023.0, 31.9844
8.998708100, 18.870, 1051.0, 32.4191
9.042173860, 18.870, 1039.0, 32.2335
9.085639620, 18.870, 1075.0, 32.7872
9.129105380, 18.870, 1098.0, 33.1361
9.172571140, 18.870, 1121.0, 33.4813
9.216036900, 18.870, 1152.0, 33.9411
9.259502660, 18.870, 1139.0, 33.7491
9.302968420, 18.870, 1127.0, 33.5708
9.346434180, 18.870, 1169.0, 34.1906
9.389899940, 18.870, 1163.0, 34.1028
9.433365700, 18.870, 1167.0, 34.1614
9.476831460, 18.870, 1138.0, 33.7343
9.520297220, 18.870, 1177.0, 34.3074
9.563762980, 18.870, 1252.0, 35.3836
9.607228740, 18.870, 1237.0, 35.1710
9.650694500, 18.870, 1250.0, 35.3553
9.694160260, 18.870, 1256.0, 35.4401
9.737626020, 18.870, 1257.0, 35.4542
9.781091780, 18.870, 1261.0, 35.5106
9.824557540, 18.870, 1193.0, 34.5398
9.868023300, 18.870, 1271.0, 35.6511
9.911489060, 18.870, 1206.0, 34.7275
9.954954820, 18.870, 1266.0, 35.5809
9.998420580, 18.870, 1255.0, 35.4260
10.041886340, 18.870, 1291.0, 35.9305
10.085352100, 18.870, 1292.0, 35.9444
10.128817860, 18.870, 1261.0, 35.5106
10.172283620, 18.870, 1285.0, 35.8469
10.215749380, 18.870, 1312.0, 36.2215
10.259215140, 18.870, 1319.0, 36.3180
10.302680900, 18.870, 1357.0, 36.8375
10.346146660, 18.870, 1323.0, 36.3731
10.389612420, 18.870, 1338.0, 36.5787
10.433078180, 18.870, 1359.0, 36.8646
10.476543940, 18.870, 1437.0, 37.9078
10.520009700, 18.870, 1369.0, 37.0000
10.563475460, 18.870, 1381.0, 37.1618
10.606941220, 18.870, 1339.0, 36.5923
10.650406980, 18.870, 1375.0, 37.0810
10.693872740, 18.870, 1441.0, 37.9605
10.737338500, 18.870, 1434.0, 37.8682
10.780804260, 18.870, 1444.0, 38.0000
10.824270020, 18.870, 1441.0, 37.9605
10.867735780, 18.870, 1385.0, 37.2156
10.911201540, 18.870, 1424.0, 37.7359
10.954667300, 18.870, 1370.0, 37.0135
10.998133060, 18.870, 1406.0, 37.4967
11.041598820, 18.870, 1513.0, 38.8973
11.085064580, 18.870, 1443.0, 37.9868
11.128530340, 18.870, 1473.0, 38.3797
11.171996100, 18.870, 1440.0, 37.9473
11.215461860, 18.870, 1471.0, 38.3536
11.258927620, 18.870, 1479.0, 38.4578
11.302393380, 18.870, 1523.0, 39.0256
11.345859140, 18.870, 1478.0, 38.4448
11.389324900, 18.870, 1484.0, 38.5227
11.432790660, 18.870, 1436.0, 37.8946
11.476256420, 18.870, 1578.0, 39.7240
11.519722180, 18.870, 1502.0, 38.7556
11.563187940, 18.870, 1600.0, 40.0000
11.606653700, 18.870, 1478.0, 38.4448
11.650119460, 18.870, 1568.0, 39.5980
11.693585220, 18.870, 1551.0, 39.3827
11.737050980, 18.870, 1566.0, 39.5727
11.780516740, 18.870, 1545.0, 39.3065
11.823982500, 18.870, 1621.0, 40.2616
11.867448260, 18.870, 1499.0, 38.7169
11.910914020, 18.870, 1554.0, 39.4208
11.954379780, 18.870, 1610.0, 40.1248
11.997845540, 18.870, 1482.0, 38.4968
12.041311300, 18.870, 1573.0, 39.6611
12.084777060, 18.870, 1630.0, 40.3733
12.128242820, 18.870, 1617.0, 40.2119
12.171708580, 18.870, 1629.0, 40.3609
12.215174340, 18.870, 1524.0, 39.0384
12.258640100, 18.870, 1570.0, 39.6232
12.302105860, 18.870, 1568.0, 39.5980
12.345571620, 18.870, 1534.0, 39.1663
12.389037380, 18.870, 1474.0, 38.3927
12.432503140, 18.870, 1594.0, 39.9249
12.475968900, 18.870, 1558.0, 39.4715
12.519434660, 18.870, 1653.0, 40.6571
12.562900420, 18.870, 1510.0, 38.8587
12.606366180, 18.870, 1548.0, 39.3446
12.649831940, 18.870, 1505.0, 38.7943
12.693297700, 18.870, 1677.0, 40.9512
12.736763460, 18.870, 1513.0, 38.8973
12.780229220, 18.870, 1533.0, 39.1535
12.823694980, 18.870, 1595.0, 39.9375
12.867160740, 18.870, 1527.0, 39.0768
12.910626500, 18.870, 1615.0, 40.1871
12.954092260, 18.870, 1549.0, 39.3573
12.997558020, 18.870, 1583.0, 39.7869
13.041023780, 18.870, 1559.0, 39.4842
13.084489540, 18.870, 1526.0, 39.0640
13.127955300, 18.870, 1594.0, 39.9249
13.171421060, 18.870, 1620.0, 40.2492
13.214886820, 18.870, 1607.0, 40.0874
13.258352580, 18.870, 1600.0, 40.0000
13.301818340, 18.870, 1570.0, 39.6232
13.345284100, 18.870, 1623.0, 40.2865
13.388749860, 18.870, 1563.0, 39.5348
13.432215620, 18.870, 1604.0, 40.0500
13.475681380, 18.870, 1592.0, 39.8999
13.519147140, 18.870, 1563.0, 39.5348
13.562612900, 18.870, 1511.0, 38.8716
13.606078660, 18.870, 1568.0, 39.5980
13.649544420, 18.870, 1576.0, 39.6989
13.693010180, 18.870, 1584.0, 39.7995
13.736475940, 18.870, 1508.0, 38.8330
13.779941700, 18.870, 1552.0, 39.3954
13.823407460, 18.870, 1579.0, 39.7366
13.866873220, 18.870, 1543.0, 39.2810
13.910338980, 18.870, 1460.0, 38.2099
13.953804740, 18.870, 1566.0, 39.5727
13.997270500, 18.870, 1572.0, 39.6485
14.040736260, 18.870, 1524.0, 39.0384
14.084202020, 18.870, 1559.0, 39.4842
14.127667780, 18.870, 1476.0, 38.4187
14.171133540, 18.870, 1519.0, 38.9744
14.214599300, 18.870, 1422.0, 37.7094
14.258065060, 18.870, 1413.0, 37.5899
14.301530820, 18.870, 1453.0, 38.1182
14.344996580, 18.870, 1432.0, 37.8418
14.388462340, 18.870, 1456.0, 38.1576
14.431928100, 18.870, 1499.0, 38.7169
14.475393860, 18.870, 1546.0, 39.3192
14.518859620, 18.870, 1452.0, 38.1051
14.562325380, 18.870, 1455.0, 38.1445
14.605791140, 18.870, 1367.0, 36.9730
14.649256900, 18.870, 1482.0, 38.4968
14.692722660, 18.870, 1405.0, 37.4833
14.736188420, 18.870, 1409.0, 37.5366
14.779654180, 18.870, 1425.0, 37.7492
14.823119940, 18.870, 1489.0, 38.5876
14.866585700, 18.870, 1437.0, 37.9078
14.910051460, 18.870, 1419.0, 37.6696
14.953517220, 18.870, 1422.0, 37.7094
14.996982980, 18.870, 1412.0, 37.5766
15.040448740, 18.870, 1448.0, 38.0526
15.083914500, 18.870, 1388.0, 37.2559
15.127380260, 18.870, 1450.0, 38.0789
15.170846020, 18.870, 1401.0, 37.4299
15.214311780, 18.870, 1315.0, 36.2629
15.257777540, 18.870, 1383.0, 37.1887
15.301243300, 18.870, 1341.0, 36.6197
15.344709060, 18.870, 1363.0, 36.9188
15.388174820, 18.870, 1379.0, 37.1349
15.431640580, 18.870, 1394.0, 37.3363
15.475106340, 18.870, 1320.0, 36.3318
15.518572100, 18.870, 1296.0, 36.0000
15.562037860, 18.870, 1334.0, 36.5240
15.605503620, 18.870, 1350.0, 36.7423
15.648969380, 18.870, 1263.0, 35.5387
15.692435140, 18.870, 1297.0, 36.0139
15.735900900, 18.870, 1202.0, 34.6699
15.779366660, 18.870, 1276.0, 35.7211
15.822832420, 18.870, 1195.0, 34.5688
15.866298180, 18.870, 1285.0, 35.8469
15.909763940, 18.870, 1217.0, 34.8855
15.953229700, 18.870, 1319.0, 36.3180
15.996695460, 18.870, 1205.0, 34.7131
16.040161220, 18.870, 1265.0, 35.5668
16.083626980, 18.870, 1278.0, 35.7491
16.127092740, 18.870, 1172.0, 34.2345
16.170558500, 18.870, 1167.0, 34.1614
16.214024260, 18.870, 1204.0, 34.6987
16.257490020, 18.870, 1228.0, 35.0428
16.300955780, 18.870, 1188.0, 34.4674
16.344421540, 18.870, 1180.0, 34.3511
16.387887300, 18.870, 1222.0, 34.9571
16.431353060, 18.870, 1116.0, 33.4066
16.474818820, 18.870, 1145.0, 33.8378
16.518284580, 18.870, 1150.0, 33.9116
16.561750340, 18.870, 1160.0, 34.0588
16.605216100, 18.870, 1179.0, 34.3366
16.648681860, 18.870, 1176.0, 34.2929
16.692147620, 18.870, 1124.0, 33.5261
16.735613380, 18.870, 1119.0, 33.4515
16.779079140, 18.870, 1062.0, 32.5883
16.822544900, 18.870, 1107.0, 33.2716
16.866010660, 18.870, 1156.0, 34.0000
16.909476420, 18.870, 1087.0, 32.9697
16.952942180, 18.870, 1092.0, 33.0454
16.996407940, 18.870, 1039.0, 32.2335
17.039873700, 18.870, 1018.0, 31.9061
17.083339460, 18.870, 1053.0, 32.4500
17.126805220, 18.870, 1045.0, 32.3265
17.170270980, 18.870, 1042.0, 32.2800
17.213736740, 18.870, 1054.0, 32.4654
17.257202500, 18.870, 1030.0, 32.0936
17.300668260, 18.870, 1024.0, 32.0000
17.344134020, 18.870, 1012.0, 31.8119
17.387599780, 18.870, 1035.0, 32.1714
17.431065540, 18.870, 956.0, 30.9192
17.474531300, 18.870, 1044.0, 32.3110
17.517997060, 18.870, 1040.0, 32.2490
17.561462820, 18.870, 983.0, 31.3528
17.604928580, 18.870, 961.0, 31.0000
17.648394340, 18.870, 904.0, 30.0666
17.691860100, 18.870, 987.0, 31.4166
17.735325860, 18.870, 992.0, 31.4960
17.778791620, 18.870, 1009.0, 31.7648
17.822257380, 18.870, 966.0, 31.0805
17.865723140, 18.870, 966.0, 31.0805
17.909188900, 18.870, 993.0, 31.5119
17.952654660, 18.870, 971.0, 31.1609
17.996120420, 18.870, 953.0, 30.8707
18.039586180, 18.870, 922.0, 30.3645
18.083051940, 18.870, 902.0, 30.0333
18.126517700, 18.870, 882.0, 29.6985
18.169983460, 18.870, 861.0, 29.3428
18.213449220, 18.870, 848.0, 29.1204
18.256914980, 18.870, 850.0, 29.1548
18.300380740, 18.870, 856.0, 29.2575
18.343846500, 18.870, 873.0, 29.5466
18.387312260, 18.870, 888.0, 29.7993
18.430778020, 18.870, 827.0, 28.7576
18.474243780, 18.870, 830.0, 28.8097
18.517709540, 18.870, 871.0, 29.5127
18.561175300, 18.870, 796.0, 28.2135
18.604641060, 18.870, 797.0, 28.2312
18.648106820, 18.870, 794.0, 28.1780
18.691572580, 18.870, 823.0, 28.6880
18.735038340, 18.870, 807.0, 28.4077
18.778504100, 18.870, 816.0, 28.5657
18.821969860, 18.870, 772.0, 27.7849
18.865435620, 18.870, 786.0, 28.0357
18.908901380, 18.870, 819.0, 28.6182
18.952367140, 18.870, 826.0, 28.7402
18.995832900, 18.870, 786.0, 28.0357
19.039298660, 18.870, 736.0, 27.1293
19.082764420, 18.870, 749.0, 27.3679
19.126230180, 18.870, 732.0, 27.0555
19.169695940, 18.870, 790.0, 28.1069
19.213161700, 18.870, 733.0, 27.0740
19.256627460, 18.870, 728.0, 26.9815
19.300093220, 18.870, 675.0, 25.9808
19.343558980, 18.870, 696.0, 26.3818
19.387024740, 18.870, 733.0, 27.0740
19.430490500, 18.870, 731.0, 27.0370
19.473956260, 18.870, 711.0, 26.6646
19.517422020, 18.870, 702.0, 26.4953
19.560887780, 18.870, 721.0, 26.8514
19.604353540, 18.870, 702.0, 26.4953
19.647819300, 18.870, 685.0, 26.1725
19.691285060, 18.870, 725.0, 26.9258
19.734750820, 18.870, 723.0, 26.8887
19.778216580, 18.870, 659.0, 25.6710
19.821682340, 18.870, 688.0, 26.2298
19.865148100, 18.870, 725.0, 26.9258
19.908613860, 18.870, 689.0, 26.2488
19.952079620, 18.870, 706.0, 26.5707
19.995545380, 18.870, 765.0, 27.6586
20.039011140, 18.870, 672.0, 25.9230
20.082476900, 18.870, 675.0, 25.9808
20.125942660, 18.870, 694.0, 26.3439
20.169408420, 18.870, 712.0, 26.6833
20.212874180, 18.870, 709.0, 26.6271
20.256339940, 18.870, 677.0, 26.0192
20.299805700, 18.870, 657.0, 25.6320
20.343271460, 18.870, 699.0, 26.4386
20.386737220, 18.870, 647.0, 25.4362
20.430202980, 18.870, 660.0, 25.6905
20.473668740, 18.870, 656.0, 25.6125
20.517134500, 18.870, 646.0, 25.4165
20.560600260, 18.870, 636.0, 25.2190
20.604066020, 18.870, 649.0, 25.4755
20.647531780, 18.870, 626.0, 25.0200
20.690997540, 18.870, 615.0, 24.7992
20.734463300, 18.870, 642.0, 25.3377
20.777929060, 18.870, 620.0, 24.8998
20.821394820, 18.870, 636.0, 25.2190
20.864860580, 18.870, 626.0, 25.0200
20.908326340, 18.870, 660.0, 25.6905
20.951792100, 18.870, 645.0, 25.3969
20.995257860, 18.870, 600.0, 24.4949
21.038723620, 18.870, 603.0, 24.5561
21.082189380, 18.870, 576.0, 24.0000
21.125655140, 18.870, 642.0, 25.3377
21.169120900, 18.870, 620.0, 24.8998
21.212586660, 18.870, 581.0, 24.1039
21.256052420, 18.870, 569.0, 23.8537
21.299518180, 18.870, 582.0, 24.1247
21.342983940, 18.870, 585.0, 24.1868
21.386449700, 18.870, 574.0, 23.9583
21.429915460, 18.870, 544.0, 23.3238
21.473381220, 18.870, 532.0, 23.0651
21.516846980, 18.870, 547.0, 23.3880
21.560312740, 18.870, 562.0, 23.7065
21.603778500, 18.870, 574.0, 23.9583
21.647244260, 18.870, 518.0, 22.7596
21.690710020, 18.870, 581.0, 24.1039
21.734175780, 18.870, 521.0, 22.8254
21.777641540, 18.870, 555.0, 23.5584
21.821107300, 18.870, 528.0, 22.9783
21.864573060, 18.870, 537.0, 23.1733
21.908038820, 18.870, 535.0, 23.1301
21.951504580, 18.870, 569.0, 23.8537
21.994970340, 18.870, 547.0, 23.3880
22.038436100, 18.870, 520.0, 22.8035
22.081901860, 18.870, 570.0, 23.8747
22.125367620, 18.870, 502.0, 22.4054
22.168833380, 18.870, 569.0, 23.8537
22.212299140, 18.870, 511.0, 22.6053
22.255764900, 18.870, 511.0, 22.6053
22.299230660, 18.870, 512.0, 22.6274
22.342696420, 18.870, 501.0, 22.3830
22.386162180, 18.870, 560.0, 23.6643
22.429627940, 18.870, 540.0, 23.2379
22.473093700, 18.870, 546.0, 23.3666
22.516559460, 18.870, 515.0, 22.6936
22.560025220, 18.870, 514.0, 22.6716
22.603490980, 18.870, 488.0, 22.0907
22.646956740, 18.870, 531.0, 23.0434
22.690422500, 18.870, 430.0, 20.7364
22.733888260, 18.870, 469.0, 21.6564
22.777354020, 18.870, 482.0, 21.9545
22.820819780, 18.870, 471.0, 21.7025
22.864285540, 18.870, 461.0, 21.4709
22.907751300, 18.870, 457.0, 21.3776
22.951217060, 18.870, 429.0, 20.7123
22.994682820, 18.870, 447.0, 21.1424
23.038148580, 18.870, 459.0, 21.4243
23.081614340, 18.870, 481.0, 21.9317
23.125080100, 18.870, 451.0, 21.2368
23.168545860, 18.870, 446.0, 21.1187
23.212011620, 18.870, 425.0, 20.6155
23.255477380, 18.870, 418.0, 20.4450
23.298943140, 18.870, 425.0, 20.6155
23.342408900, 18.870, 477.0, 21.8403
23.385874660, 18.870, 433.0, 20.8087
23.429340420, 18.870, 409.0, 20.2237
23.472806180, 18.870, 369.0, 19.2094
23.516271940, 18.870, 393.0, 19.8242
23.559737700, 18.870, 444.0, 21.0713
23.603203460, 18.870, 446.0, 21.1187
23.646669220, 18.870, 414.0, 20.3470
23.690134980, 18.870, 421.0, 20.5183
23.733600740, 18.870, 444.0, 21.0713
23.777066500, 18.870, 434.0, 20.8327
23.820532260, 18.870, 428.0, 20.6882
23.863998020, 18.870, 388.0, 19.6977
23.907463780, 18.870, 406.0, 20.1494
23.950929540, 18.870, 407.0, 20.1742
23.994395300, 18.870, 389.0, 19.7231
24.037861060, 18.870, 415.0, 20.3715
24.081326820, 18.870, 397.0, 19.9249
24.124792580, 18.870, 423.0, 20.5670
24.168258340, 18.870, 399.0, 19.9750
24.211724100, 18.870, 416.0, 20.3961
24.255189860, 18.870, 421.0, 20.5183
24.298655620, 18.870, 415.0, 20.3715
24.342121380, 18.870, 398.0, 19.9499
24.385587140, 18.870, 414.0, 20.3470
24.429052900, 18.870, 404.0, 20.0998
24.472518660, 18.870, 362.0, 19.0263
24.515984420, 18.870, 414.0, 20.3470
24.559450180, 18.870, 405.0, 20.1246
24.602915940, 18.870, 382.0, 19.5448
24.646381700, 18.870, 406.0, 20.1494
24.689847460, 18.870, 383.0, 19.5704
24.733313220, 18.870, 416.0, 20.3961
24.776778980, 18.870, 387.0, 19.6723
24.820244740, 18.870, 403.0, 20.0749
24.863710500, 18.870, 395.0, 19.8746
24.907176260, 18.870, 341.0, 18.4662
24.950642020, 18.870, 389.0, 19.7231
24.994107780, 18.870, 371.0, 19.2614
25.037573540, 18.870, 407.0, 20.1742
25.081039300, 18.870, 394.0, 19.8494
25.124505060, 18.870, 382.0, 19.5448
25.167970820, 18.870, 374.0, 19.3391
25.211436580, 18.870, 374.0, 19.3391
25.254902340, 18.870, 354.0, 18.8149
25.298368100, 18.870, 386.0, 19.6469
25.341833860, 18.870, 398.0, 19.9499
25.385299620, 18.870, 409.0, 20.2237
25.428765380, 18.870, 354.0, 18.8149
25.472231140, 18.870, 384.0, 19.5959
25.515696900, 18.870, 375.0, 19.3649
25.559162660, 18.870, 374.0, 19.3391
25.602628420, 18.870, 390.0, 19.7484
25.646094180, 18.870, 382.0, 19.5448
25.689559940, 18.870, 387.0, 19.6723
25.733025700, 18.870, 335.0, 18.3030
25.776491460, 18.870, 360.0, 18.9737
25.819957220, 18.870, 351.0, 18.7350
25.863422980, 18.870, 352.0, 18.7617
25.906888740, 18.870, 367.0, 19.1572
25.950354500, 18.870, 386.0, 19.6469
25.993820260, 18.870, 361.0, 19.0000
26.037286020, 18.870, 392.0, 19.7990
26.080751780, 18.870, 349.0, 18.6815
26.124217540, 18.870, 398.0, 19.9499
26.167683300, 18.870, 415.0, 20.3715
26.211149060, 18.870, 402.0, 20.0499
26.254614820, 18.870, 376.0, 19.3907
26.298080580, 18.870, 415.0, 20.3715
26.341546340, 18.870, 373.0, 19.3132
26.385012100, 18.870, 386.0, 19.6469
26.428477860, 18.870, 361.0, 19.0000
26.471943620, 18.870, 338.0, 18.3848
26.515409380, 18.870, 367.0, 19.1572
26.558875140, 18.870, 344.0, 18.5472
26.602340900, 18.870, 368.0, 19.1833
26.645806660, 18.870, 356.0, 18.8680
26.689272420, 18.870, 389.0, 19.7231
26.732738180, 18.870, 382.0, 19.5448
26.776203940, 18.870, 341.0, 18.4662
26.819669700, 18.870, 380.0, 19.4936
26.863135460, 18.870, 351.0, 18.7350
26.906601220, 18.870, 371.0, 19.2614
26.950066980, 18.870, 392.0, 19.7990
26.993532740, 18.870, 432.0, 20.7846
27.036998500, 18.870, 353.0, 18.7883
27.080464260, 18.870, 417.0, 20.4206
27.123930020, 18.870, 372.0, 19.2873
27.167395780, 18.870, 370.0, 19.2354
27.210861540, 18.870, 412.0, 20.2978
27.254327300, 18.870, 442.0, 21.0238
27.297793060, 18.870, 478.0, 21.8632
27.341258820, 18.870, 494.0, 22.2261
27.384724580, 18.870, 450.0, 21.2132
27.428190340, 18.870, 423.0, 20.5670
27.471656100, 18.870, 415.0, 20.3715
27.515121860, 18.870, 393.0, 19.8242
27.558587620, 18.870, 387.0, 19.6723
27.602053380, 18.870, 406.0, 20.1494
27.645519140, 18.870, 395.0, 19.8746
27.688984900, 18.870, 366.0, 19.1311
27.732450660, 18.870, 359.0, 18.9473
27.775916420, 18.870, 412.0, 20.2978
27.819382180, 18.870, 406.0, 20.1494
27.862847940, 18.870, 379.0, 19.4679
27.906313700, 18.870, 376.0, 19.3907
27.949779460, 18.870, 369.0, 19.2094
27.993245220, 18.870, 364.0, 19.0788
28.036710980, 18.870, 387.0, 19.6723
28.080176740, 18.870, 381.0, 19.5192
28.123642500, 18.870, 416.0, 20.3961
28.167108260, 18.870, 389.0, 19.7231
28.210574020, 18.870, 399.0, 19.9750
28.254039780, 18.870, 387.0, 19.6723
28.297505540, 18.870, 432.0, 20.7846
28.340971300, 18.870, 392.0, 19.7990
28.384437060, 18.870, 420.0, 20.4939
28.427902820, 18.870, 531.0, 23.0434
28.471368580, 18.870, 631.0, 25.1197
28.514834340, 18.870, 692.0, 26.3059
28.558300100, 18.870, 742.0, 27.2397
28.601765860, 18.870, 688.0, 26.2298
28.645231620, 18.870, 516.0, 22.7156
28.688697380, 18.870, 403.0, 20.0749
28.732163140, 18.870, 368.0, 19.1833
28.775628900, 18.870, 373.0, 19.3132
28.819094660, 18.870, 406.0, 20.1494
28.862560420, 18.870, 360.0, 18.9737
28.906026180, 18.870, 385.0, 19.6214
28.949491940, 18.870, 385.0, 19.6214
28.992957700, 18.870, 393.0, 19.8242
29.036423460, 18.870, 417.0, 20.4206
29.079889220, 18.870, 355.0, 18.8414
29.123354980, 18.870, 333.0, 18.2483
29.166820740, 18.870, 395.0, 19.8746
29.210286500, 18.870, 364.0, 19.0788
29.253752260, 18.870, 349.0, 18.6815
29.297218020, 18.870, 369.0, 19.2094
29.340683780, 18.870, 402.0, 20.0499
29.384149540, 18.870, 359.0, 18.9473
29.427615300, 18.870, 333.0, 18.2483
29.471081060, 18.870, 368.0, 19.1833
29.514546820, 18.870, 357.0, 18.8944
29.558012580, 18.870, 353.0, 18.7883
29.601478340, 18.870, 388.0, 19.6977
29.644944100, 18.870, 365.0, 19.1050
29.688409860, 18.870, 348.0, 18.6548
29.731875620, 18.870, 376.0, 19.3907
29.775341380, 18.870, 385.0, 19.6214
29.818807140, 18.870, 348.0, 18.6548
29.862272900, 18.870, 347.0, 18.6279
29.905738660, 18.870, 332.0, 18.2209
29.949204420, 18.870, 380.0, 19.4936
29.992670180, 18.870, 394.0, 19.8494
30.036135940, 18.870, 362.0, 19.0263
30.079601700, 18.870, 402.0, 20.0499
30.123067460, 18.870, 363.0, 19.0526
30.166533220, 18.870, 358.0, 18.9209
30.209998980, 18.870, 389.0, 19.7231
30.253464740, 18.870, 396.0, 19.8997
30.296930500, 18.870, 379.0, 19.4679
30.340396260, 18.870, 363.0, 19.0526
30.383862020, 18.870, 400.0, 20.0000
30.427327780, 18.870, 438.0, 20.9284
30.470793540, 18.870, 455.0, 21.3307
30.514259300, 18.870, 636.0, 25.2190
30.557725060, 18.870, 685.0, 26.1725
30.601190820, 18.870, 886.0, 29.7658
30.644656580, 18.870, 976.0, 31.2410
30.688122340, 18.870, 964.0, 31.0483
30.731588100, 18.870, 1039.0, 32.2335
30.775053860, 18.870, 1070.0, 32.7109
30.818519620, 18.870, 1082.0, 32.8938
30.861985380, 18.870, 1065.0, 32.6343
30.905451140, 18.870, 1029.0, 32.0780
30.948916900, 18.870, 1042.0, 32.2800
30.992382660, 18.870, 1128.0, 33.5857
31.035848420, 18.870, 1204.0, 34.6987
31.079314180, 18.870, 1232.0, 35.0999
31.122779940, 18.870, 1510.0, 38.8587
31.166245700, 18.870, 1741.0, 41.7253
31.209711460, 18.870, 2082.0, 45.6289
31.253177220, 18.870, 2416.0, 49.1528
31.296642980, 18.870, 2747.0, 52.4118
31.340108740, 18.870, 3049.0, 55.2178
31.383574500, 18.870, 3936.0, 62.7375
31.427040260, 18.870, 5318.0, 72.9246
31.470506020, 18.870, 9077.0, 95.2733
31.513971780, 18.870, 19963.0, 141.2905
31.557437540, 18.870, 42034.0, 205.0220
31.600903300, 18.870, 79967.0, 282.7844
31.644369060, 18.870, 112739.0, 335.7663
31.687834820, 18.870, 150386.0, 387.7963
31.731300580, 18.870, 135082.0, 367.5350
31.774766340, 18.870, 87998.0, 296.6446
31.818232100, 18.870, 52866.0, 229.9261
31.861697860, 18.870, 19192.0, 138.5352
31.905163620, 18.870, 9021.0, 94.9789
31.948629380, 18.870, 5065.0, 71.1688
31.992095140, 18.870, 3368.0, 58.0345
32.035560900, 18.870, 2646.0, 51.4393
32.079026660, 18.870, 2119.0, 46.0326
32.122492420, 18.870, 1697.0, 41.1947
32.165958180, 18.870, 1467.0, 38.3014
32.209423940, 18.870, 1220.0, 34.9285
32.252889700, 18.870, 1075.0, 32.7872
32.296355460, 18.870, 1038.0, 32.2180
32.339821220, 18.870, 919.0, 30.3150
32.383286980, 18.870, 884.0, 29.7321
32.426752740, 18.870, 891.0, 29.8496
32.470218500, 18.870, 824.0, 28.7054
32.513684260, 18.870, 907.0, 30.1164
32.557150020, 18.870, 798.0, 28.2489
32.600615780, 18.870, 801.0, 28.3019
32.644081540, 18.870, 820.0, 28.6356
32.687547300, 18.870, 736.0, 27.1293
32.731013060, 18.870, 739.0, 27.1846
32.774478820, 18.870, 754.0, 27.4591
32.817944580, 18.870, 721.0, 26.8514
32.861410340, 18.870, 690.0, 26.2679
32.904876100, 18.870, 684.0, 26.1534
32.948341860, 18.870, 677.0, 26.0192
32.991807620, 18.870, 713.0, 26.7021
33.035273380, 18.870, 634.0, 25.1794
33.078739140, 18.870, 639.0, 25.2784
33.122204900, 18.870, 654.0, 25.5734
33.165670660, 18.870, 631.0, 25.1197
33.209136420, 18.870, 613.0, 24.7588
33.252602180, 18.870, 607.0, 24.6374
33.296067940, 18.870, 638.0, 25.2587
33.339533700, 18.870, 562.0, 23.7065
33.382999460, 18.870, 604.0, 24.5764
33.426465220, 18.870, 552.0, 23.4947
33.469930980, 18.870, 574.0, 23.9583
33.513396740, 18.870, 552.0, 23.4947
33.556862500, 18.870, 619.0, 24.8797
33.600328260, 18.870, 569.0, 23.8537
33.643794020, 18.870, 537.0, 23.1733
33.687259780, 18.870, 537.0, 23.1733
33.730725540, 18.870, 498.0, 22.3159
33.774191300, 18.870, 511.0, 22.6053
33.817657060, 18.870, 502.0, 22.4054
33.861122820, 18.870, 504.0, 22.4499
33.904588580, 18.870, 537.0, 23.1733
33.948054340, 18.870, 544.0, 23.3238
33.991520100, 18.870, 492.0, 22.1811
34.034985860, 18.870, 545.0, 23.3452
34.078451620, 18.870, 512.0, 22.6274
34.121917380, 18.870, 506.0, 22.4944
34.165383140, 18.870, 483.0, 21.9773
34.208848900, 18.870, 548.0, 23.4094
34.252314660, 18.870, 494.0, 22.2261
34.295780420, 18.870, 483.0, 21.9773
34.339246180, 18.870, 450.0, 21.2132
34.382711940, 18.870, 457.0, 21.3776
34.426177700, 18.870, 489.0, 22.1133
34.469643460, 18.870, 506.0, 22.4944
34.513109220, 18.870, 490.0, 22.1359
34.556574980, 18.870, 519.0, 22.7816
34.600040740, 18.870, 487.0, 22.0681
34.643506500, 18.870, 519.0, 22.7816
34.686972260, 18.870, 462.0, 21.4942
34.730438020, 18.870, 487.0, 22.0681
34.773903780, 18.870, 453.0, 21.2838
34.817369540, 18.870, 454.0, 21.3073
34.860835300, 18.870, 407.0, 20.1742
34.904301060, 18.870, 430.0, 20.7364
34.947766820, 18.870, 438.0, 20.9284
34.991232580, 18.870, 416.0, 20.3961
35.034698340, 18.870, 431.0, 20.7605
35.078164100, 18.870, 404.0, 20.0998
35.121629860, 18.870, 374.0, 19.3391
35.165095620, 18.870, 369.0, 19.2094
35.208561380, 18.870, 380.0, 19.4936
35.252027140, 18.870, 421.0, 20.5183
35.295492900, 18.870, 389.0, 19.7231
35.338958660, 18.870, 397.0, 19.9249
35.382424420, 18.870, 407.0, 20.1742
35.425890180, 18.870, 387.0, 19.6723
35.469355940, 18.870, 383.0, 19.5704
35.512821700, 18.870, 405.0, 20.1246
35.556287460, 18.870, 383.0, 19.5704
35.599753220, 18.870, 351.0, 18.7350
35.643218980, 18.870, 362.0, 19.0263
35.686684740, 18.870, 345.0, 18.5742
35.730150500, 18.870, 355.0, 18.8414
35.773616260, 18.870, 342.0, 18.4932
35.817082020, 18.870, 384.0, 19.5959
35.860547780, 18.870, 374.0, 19.3391
35.904013540, 18.870, 330.0, 18.1659
35.947479300, 18.870, 368.0, 19.1833
35.990945060, 18.870, 344.0, 18.5472
36.034410820, 18.870, 350.0, 18.7083
36.077876580, 18.870, 346.0, 18.6011
36.121342340, 18.870, 375.0, 19.3649
36.164808100, 18.870, 352.0, 18.7617
36.208273860, 18.870, 318.0, 17.8326
36.251739620, 18.870, 341.0, 18.4662
36.295205380, 18.870, 326.0, 18.0555
36.338671140, 18.870, 348.0, 18.6548
36.382136900, 18.870, 364.0, 19.0788
36.425602660, 18.870, 350.0, 18.7083
36.469068420, 18.870, 367.0, 19.1572
36.512534180, 18.870, 329.0, 18.1384
36.555999940, 18.870, 306.0, 17.4929
36.599465700, 18.870, 313.0, 17.6918
36.642931460, 18.870, 286.0, 16.9115
36.686397220, 18.870, 308.0, 17.5499
36.729862980, 18.870, 335.0, 18.3030
36.773328740, 18.870, 330.0, 18.1659
36.816794500, 18.870, 317.0, 17.8045
36.860260260, 18.870, 328.0, 18.1108
36.903726020, 18.870, 293.0, 17.1172
36.947191780, 18.870, 295.0, 17.1756
36.990657540, 18.870, 321.0, 17.9165
37.034123300, 18.870, 298.0, 17.2627
37.077589060, 18.870, 317.0, 17.8045
37.121054820, 18.870, 281.0, 16.7631
37.164520580, 18.870, 277.0, 16.6433
37.207986340, 18.870, 323.0, 17.9722
37.251452100, 18.870, 316.0, 17.7764
37.294917860, 18.870, 286.0, 16.9115
37.338383620, 18.870, 291.0, 17.0587
37.381849380, 18.870, 292.0, 17.0880
37.425315140, 18.870, 308.0, 17.5499
37.468780900, 18.870, 282.0, 16.7929
37.512246660, 18.870, 300.0, 17.3205
37.555712420, 18.870, 279.0, 16.7033
37.599178180, 18.870, 286.0, 16.9115
37.642643940, 18.870, 289.0, 17.0000
37.686109700, 18.870, 261.0, 16.1555
37.729575460, 18.870, 292.0, 17.0880
37.773041220, 18.870, 274.0, 16.5529
37.816506980, 18.870, 279.0, 16.7033
37.859972740, 18.870, 266.0, 16.3095
37.903438500, 18.870, 246.0, 15.6844
37.946904260, 18.870, 243.0, 15.5885
37.990370020, 18.870, 278.0, 16.6733
38.033835780, 18.870, 270.0, 16.4317
38.077301540, 18.870, 259.0, 16.0935
38.120767300, 18.870, 280.0, 16.7332
38.164233060, 18.870, 271.0, 16.4621
38.207698820, 18.870, 249.0, 15.7797
38.251164580, 18.870, 262.0, 16.1864
38.294630340, 18.870, 256.0, 16.0000
38.338096100, 18.870, 258.0, 16.0624
38.381561860, 18.870, 271.0, 16.4621
38.425027620, 18.870, 228.0, 15.0997
38.468493380, 18.870, 243.0, 15.5885
38.511959140, 18.870, 262.0, 16.1864
38.555424900, 18.870, 251.0, 15.8430
38.598890660, 18.870, 243.0, 15.5885
38.642356420, 18.870, 230.0, 15.1658
38.685822180, 18.870, 244.0, 15.6205
38.729287940, 18.870, 201.0, 14.1774
38.772753700, 18.870, 220.0, 14.8324
38.816219460, 18.870, 260.0, 16.1245
38.859685220, 18.870, 241.0, 15.5242
38.903150980, 18.870, 233.0, 15.2643
38.946616740, 18.870, 257.0, 16.0312
38.990082500, 18.870, 219.0, 14.7986
39.033548260, 18.870, 251.0, 15.8430
39.077014020, 18.870, 260.0, 16.1245
39.120479780, 18.870, 230.0, 15.1658
39.163945540, 18.870, 245.0, 15.6525
39.207411300, 18.870, 228.0, 15.0997
39.250877060, 18.870, 233.0, 15.2643
39.294342820, 18.870, 224.0, 14.9666
39.337808580, 18.870, 241.0, 15.5242
39.381274340, 18.870, 264.0, 16.2481
39.424740100, 18.870, 210.0, 14.4914
39.468205860, 18.870, 222.0, 14.8997
39.511671620, 18.870, 257.0, 16.0312
39.555137380, 18.870, 262.0, 16.1864
39.598603140, 18.870, 257.0, 16.0312
39.642068900, 18.870, 261.0, 16.1555
39.685534660, 18.870, 200.0, 14.1421
39.729000420, 18.870, 245.0, 15.6525
39.772466180, 18.870, 206.0, 14.3527
39.815931940, 18.870, 224.0, 14.9666
39.859397700, 18.870, 236.0, 15.3623
39.902863460, 18.870, 221.0, 14.8661
39.946329220, 18.870, 225.0, 15.0000
39.989794980, 18.870, 216.0, 14.6969
40.033260740, 18.870, 209.0, 14.4568
40.076726500, 18.870, 191.0, 13.8203
40.120192260, 18.870, 204.0, 14.2829
40.163658020, 18.870, 233.0, 15.2643
40.207123780, 18.870, 235.0, 15.3297
40.250589540, 18.870, 223.0, 14.9332
40.294055300, 18.870, 211.0, 14.5258
40.337521060, 18.870, 219.0, 14.7986
40.380986820, 18.870, 212.0, 14.5602
40.424452580, 18.870, 201.0, 14.1774
40.467918340, 18.870, 203.0, 14.2478
40.511384100, 18.870, 196.0, 14.0000
40.554849860, 18.870, 196.0, 14.0000
40.598315620, 18.870, 232.0, 15.2315
40.641781380, 18.870, 230.0, 15.1658
40.685247140, 18.870, 188.0, 13.7113
40.728712900, 18.870, 193.0, 13.8924
40.772178660, 18.870, 188.0, 13.7113
40.815644420, 18.870, 218.0, 14.7648
40.859110180, 18.870, 225.0, 15.0000
40.902575940, 18.870, 188.0, 13.7113
40.946041700, 18.870, 224.0, 14.9666
40.989507460, 18.870, 177.0, 13.3041
41.032973220, 18.870, 189.0, 13.7477
41.076438980, 18.870, 210.0, 14.4914
41.119904740, 18.870, 209.0, 14.4568
41.163370500, 18.870, 185.0, 13.6015
41.206836260, 18.870, 198.0, 14.0712
41.250302020, 18.870, 202.0, 14.2127
41.293767780, 18.870, 190.0, 13.7840
41.337233540, 18.870, 191.0, 13.8203
41.380699300, 18.870, 185.0, 13.6015
41.424165060, 18.870, 173.0, 13.1529
41.467630820, 18.870, 205.0, 14.3178
41.511096580, 18.870, 208.0, 14.4222
41.554562340, 18.870, 194.0, 13.9284
41.598028100, 18.870, 203.0, 14.2478
41.641493860, 18.870, 175.0, 13.2288
41.684959620, 18.870, 209.0, 14.4568
41.728425380, 18.870, 201.0, 14.1774
41.771891140, 18.870, 189.0, 13.7477
41.815356900, 18.870, 193.0, 13.8924
41.858822660, 18.870, 170.0, 13.0384
41.902288420, 18.870, 163.0, 12.7671
41.945754180, 18.870, 205.0, 14.3178
41.989219940, 18.870, 183.0, 13.5277
42.032685700, 18.870, 199.0, 14.1067
42.076151460, 18.870, 192.0, 13.8564
42.119617220, 18.870, 202.0, 14.2127
42.163082980, 18.870, 202.0, 14.2127
42.206548740, 18.870, 210.0, 14.4914
42.250014500, 18.870, 175.0, 13.2288
42.293480260, 18.870, 147.0, 12.1244
42.336946020, 18.870, 157.0, 12.5300
42.380411780, 18.870, 192.0, 13.8564
42.423877540, 18.870, 171.0, 13.0767
42.467343300, 18.870, 187.0, 13.6748
42.510809060, 18.870, 184.0, 13.5647
42.554274820, 18.870, 178.0, 13.3417
42.597740580, 18.870, 167.0, 12.9228
42.641206340, 18.870, 175.0, 13.2288
42.684672100, 18.870, 176.0, 13.2665
42.728137860, 18.870, 193.0, 13.8924
42.771603620, 18.870, 188.0, 13.7113
42.815069380, 18.870, 149.0, 12.2066
42.858535140, 18.870, 165.0, 12.8452
42.902000900, 18.870, 178.0, 13.3417
42.945466660, 18.870, 169.0, 13.0000
42.988932420, 18.870, 184.0, 13.5647
43.032398180, 18.870, 172.0, 13.1149
43.075863940, 18.870, 181.0, 13.4536
43.119329700, 18.870, 172.0, 13.1149
43.162795460, 18.870, 154.0, 12.4097
43.206261220, 18.870, 174.0, 13.1909
43.249726980, 18.870, 191.0, 13.8203
43.293192740, 18.870, 167.0, 12.9228
43.336658500, 18.870, 168.0, 12.9615
43.380124260, 18.870, 160.0, 12.6491
43.423590020, 18.870, 168.0, 12.9615
43.467055780, 18.870, 176.0, 13.2665
43.510521540, 18.870, 176.0, 13.2665
43.553987300, 18.870, 195.0, 13.9642
43.597453060, 18.870, 165.0, 12.8452
43.640918820, 18.870, 194.0, 13.9284
43.684384580, 18.870, 217.0, 14.7309
43.727850340, 18.870, 263.0, 16.2173
43.771316100, 18.870, 243.0, 15.5885
43.814781860, 18.870, 208.0, 14.4222
43.858247620, 18.870, 215.0, 14.6629
43.901713380, 18.870, 190.0, 13.7840
43.945179140, 18.870, 182.0, 13.4907
43.988644900, 18.870, 191.0, 13.8203
44.032110660, 18.870, 175.0, 13.2288
44.075576420, 18.870, 180.0, 13.4164
44.119042180, 18.870, 204.0, 14.2829
44.162507940, 18.870, 176.0, 13.2665
44.205973700, 18.870, 176.0, 13.2665
44.249439460, 18.870, 192.0, 13.8564
44.292905220, 18.870, 179.0, 13.3791
44.336370980, 18.870, 191.0, 13.8203
44.379836740, 18.870, 169.0, 13.0000
44.423302500, 18.870, 160.0, 12.6491
44.466768260, 18.870, 158.0, 12.5698
44.510234020, 18.870, 175.0, 13.2288
44.553699780, 18.870, 164.0, 12.8062
44.597165540, 18.870, 158.0, 12.5698
44.640631300, 18.870, 186.0, 13.6382
44.684097060, 18.870, 175.0, 13.2288
44.727562820, 18.870, 173.0, 13.1529
44.771028580, 18.870, 146.0, 12.0830
44.814494340, 18.870, 182.0, 13.4907
44.857960100, 18.870, 194.0, 13.9284
44.901425860, 18.870, 162.0, 12.7279
44.944891620, 18.870, 179.0, 13.3791
44.988357380, 18.870, 196.0, 14.0000
45.031823140, 18.870, 207.0, 14.3875
45.075288900, 18.870, 212.0, 14.5602
45.118754660, 18.870, 230.0, 15.1658
45.162220420, 18.870, 296.0, 17.2047
45.205686180, 18.870, 305.0, 17.4642
45.249151940, 18.870, 424.0, 20.5913
45.292617700, 18.870, 539.0, 23.2164
45.336083460, 18.870, 1126.0, 33.5559
45.379549220, 18.870, 2095.0, 45.7712
45.423014980, 18.870, 2533.0, 50.3289
45.466480740, 18.870, 2702.0, 51.9808
45.509946500, 18.870, 3112.0, 55.7853
45.553412260, 18.870, 2339.0, 48.3632
45.596878020, 18.870, 1427.0, 37.7757
45.640343780, 18.870, 1119.0, 33.4515
45.683809540, 18.870, 613.0, 24.7588
45.727275300, 18.870, 303.0, 17.4069
45.770741060, 18.870, 259.0, 16.0935
45.814206820, 18.870, 230.0, 15.1658
45.857672580, 18.870, 191.0, 13.8203
45.901138340, 18.870, 170.0, 13.0384
45.944604100, 18.870, 194.0, 13.9284
45.988069860, 18.870, 156.0, 12.4900
46.031535620, 18.870, 176.0, 13.2665
46.075001380, 18.870, 178.0, 13.3417
46.118467140, 18.870, 140.0, 11.8322
46.161932900, 18.870, 187.0, 13.6748
46.205398660, 18.870, 163.0, 12.7671
46.248864420, 18.870, 145.0, 12.0416
46.292330180, 18.870, 153.0, 12.3693
46.335795940, 18.870, 160.0, 12.6491
46.379261700, 18.870, 172.0, 13.1149
46.422727460, 18.870, 168.0, 12.9615
46.466193220, 18.870, 152.0, 12.3288
46.509658980, 18.870, 163.0, 12.7671
46.553124740, 18.870, 137.0, 11.7047
46.596590500, 18.870, 156.0, 12.4900
46.640056260, 18.870, 153.0, 12.3693
46.683522020, 18.870, 148.0, 12.1655
46.726987780, 18.870, 155.0, 12.4499
46.770453540, 18.870, 132.0, 11.4891
46.813919300, 18.870, 151.0, 12.2882
46.857385060, 18.870, 145.0, 12.0416
46.900850820, 18.870, 157.0, 12.5300
46.944316580, 18.870, 154.0, 12.4097
46.987782340, 18.870, 150.0, 12.2474
47.031248100, 18.870, 125.0, 11.1803
47.074713860, 18.870, 152.0, 12.3288
47.118179620, 18.870, 132.0, 11.4891
47.161645380, 18.870, 154.0, 12.4097
47.205111140, 18.870, 172.0, 13.1149
47.248576900, 18.870, 154.0, 12.4097
47.292042660, 18.870, 127.0, 11.2694
47.335508420, 18.870, 152.0, 12.3288
47.378974180, 18.870, 176.0, 13.2665
47.422439940, 18.870, 136.0, 11.6619
47.465905700, 18.870, 147.0, 12.1244
47.509371460, 18.870, 149.0, 12.2066
47.552837220, 18.870, 140.0, 11.8322
47.596302980, 18.870, 141.0, 11.8743
47.639768740, 18.870, 156.0, 12.4900
47.683234500, 18.870, 127.0, 11.2694
47.726700260, 18.870, 139.0, 11.7898
47.770166020, 18.870, 148.0, 12.1655
47.813631780, 18.870, 134.0, 11.5758
47.857097540, 18.870, 134.0, 11.5758
47.900563300, 18.870, 162.0, 12.7279
47.944029060, 18.870, 147.0, 12.1244
47.987494820, 18.870, 162.0, 12.7279
48.030960580, 18.870, 127.0, 11.2694
48.074426340, 18.870, 141.0, 11.8743
48.117892100, 18.870, 136.0, 11.6619
48.161357860, 18.870, 140.0, 11.8322
48.204823620, 18.870, 148.0, 12.1655
48.248289380, 18.870, 142.0, 11.9164
48.291755140, 18.870, 161.0, 12.6886
48.335220900, 18.870, 128.0, 11.3137
48.378686660, 18.870, 160.0, 12.6491
48.422152420, 18.870, 135.0, 11.6190
48.465618180, 18.870, 136.0, 11.6619
48.509083940, 18.870, 161.0, 12.6886
48.552549700, 18.870, 152.0, 12.3288
48.596015460, 18.870, 142.0, 11.9164
48.639481220, 18.870, 115.0, 10.7238
48.682946980, 18.870, 157.0, 12.5300
48.726412740, 18.870, 141.0, 11.8743
48.769878500, 18.870, 104.0, 10.1980
48.813344260, 18.870, 126.0, 11.2250
48.856810020, 18.870, 121.0, 11.0000
48.900275780, 18.870, 130.0, 11.4018
48.943741540, 18.870, 130.0, 11.4018
48.987207300, 18.870, 146.0, 12.0830
49.030673060, 18.870, 132.0, 11.4891
49.074138820, 18.870, 149.0, 12.2066
49.117604580, 18.870, 127.0, 11.2694
49.161070340, 18.870, 121.0, 11.0000
49.204536100, 18.870, 135.0, 11.6190
49.248001860, 18.870, 134.0, 11.5758
49.291467620, 18.870, 120.0, 10.9545
49.334933380, 18.870, 139.0, 11.7898
49.378399140, 18.870, 124.0, 11.1355
49.421864900, 18.870, 131.0, 11.4455
49.465330660, 18.870, 116.0, 10.7703
49.508796420, 18.870, 119.0, 10.9087
49.552262180, 18.870, 125.0, 11.1803
49.595727940, 18.870, 141.0, 11.8743
49.639193700, 18.870, 112.0, 10.5830
49.682659460, 18.870, 116.0, 10.7703
49.726125220, 18.870, 144.0, 12.0000
49.769590980, 18.870, 138.0, 11.7473
49.813056740, 18.870, 116.0, 10.7703
49.856522500, 18.870, 112.0, 10.5830
49.899988260, 18.870, 118.0, 10.8628
49.943454020, 18.870, 123.0, 11.0905
49.986919780, 18.870, 114.0, 10.6771
50.030385540, 18.870, 119.0, 10.9087
50.073851300, 18.870, 131.0, 11.4455
50.117317060, 18.870, 131.0, 11.4455
50.160782820, 18.870, 118.0, 10.8628
50.204248580, 18.870, 112.0, 10.5830
50.247714340, 18.870, 144.0, 12.0000
50.291180100, 18.870, 103.0, 10.1489
50.334645860, 18.870, 132.0, 11.4891
50.378111620, 18.870, 134.0, 11.5758
50.421577380, 18.870, 124.0, 11.1355
50.465043140, 18.870, 108.0, 10.3923
50.508508900, 18.870, 115.0, 10.7238
50.551974660, 18.870, 118.0, 10.8628
50.595440420, 18.870, 147.0, 12.1244
50.638906180, 18.870, 106.0, 10.2956
50.682371940, 18.870, 128.0, 11.3137
50.725837700, 18.870, 149.0, 12.2066
50.769303460, 18.870, 129.0, 11.3578
50.812769220, 18.870, 95.0, 9.7468
50.856234980, 18.870, 125.0, 11.1803
50.899700740, 18.870, 116.0, 10.7703
50.943166500, 18.870, 114.0, 10.6771
50.986632260, 18.870, 109.0, 10.4403
51.030098020, 18.870, 145.0, 12.0416
51.073563780, 18.870, 104.0, 10.1980
51.117029540, 18.870, 121.0, 11.0000
51.160495300, 18.870, 123.0, 11.0905
51.203961060, 18.870, 130.0, 11.4018
51.247426820, 18.870, 124.0, 11.1355
51.290892580, 18.870, 133.0, 11.5326
51.334358340, 18.870, 129.0, 11.3578
51.377824100, 18.870, 128.0, 11.3137
51.421289860, 18.870, 140.0, 11.8322
51.464755620, 18.870, 134.0, 11.5758
51.508221380, 18.870, 99.0, 9.9499
51.551687140, 18.870, 129.0, 11.3578
51.595152900, 18.870, 147.0, 12.1244
51.638618660, 18.870, 113.0, 10.6301
51.682084420, 18.870, 135.0, 11.6190
51.725550180, 18.870, 129.0, 11.3578
51.769015940, 18.870, 123.0, 11.0905
51.812481700, 18.870, 103.0, 10.1489
51.855947460, 18.870, 104.0, 10.1980
51.899413220, 18.870, 101.0, 10.0499
51.942878980, 18.870, 93.0, 9.6437
51.986344740, 18.870, 139.0, 11.7898
52.029810500, 18.870, 95.0, 9.7468
52.073276260, 18.870, 116.0, 10.7703
52.116742020, 18.870, 115.0, 10.7238
52.160207780, 18.870, 119.0, 10.9087
52.203673540, 18.870, 124.0, 11.1355
52.247139300, 18.870, 125.0, 11.1803
52.290605060, 18.870, 145.0, 12.0416
52.334070820, 18.870, 140.0, 11.8322
52.377536580, 18.870, 134.0, 11.5758
52.421002340, 18.870, 110.0, 10.4881
52.464468100, 18.870, 127.0, 11.2694
52.507933860, 18.870, 115.0, 10.7238
52.551399620, 18.870, 126.0, 11.2250
52.594865380, 18.870, 109.0, 10.4403
52.638331140, 18.870, 128.0, 11.3137
52.681796900, 18.870, 125.0, 11.1803
52.725262660, 18.870, 124.0, 11.1355
52.768728420, 18.870, 112.0, 10.5830
52.812194180, 18.870, 109.0, 10.4403
52.855659940, 18.870, 120.0, 10.9545
52.899125700, 18.870, 125.0, 11.1803
52.942591460, 18.870, 132.0, 11.4891
52.986057220, 18.870, 119.0, 10.9087
53.029522980, 18.870, 121.0, 11.0000
53.072988740, 18.870, 115.0, 10.7238
53.116454500, 18.870, 117.0, 10.8167
53.159920260, 18.870, 105.0, 10.2470
53.203386020, 18.870, 123.0, 11.0905
53.246851780, 18.870, 123.0, 11.0905
53.290317540, 18.870, 109.0, 10.4403
53.333783300, 18.870, 125.0, 11.1803
53.377249060, 18.870, 113.0, 10.6301
53.420714820, 18.870, 123.0, 11.0905
53.464180580, 18.870, 132.0, 11.4891
53.507646340, 18.870, 122.0, 11.0454
53.551112100, 18.870, 112.0, 10.5830
53.594577860, 18.870, 119.0, 10.9087
53.638043620, 18.870, 127.0, 11.2694
53.681509380, 18.870, 147.0, 12.1244
53.724975140, 18.870, 149.0, 12.2066
53.768440900, 18.870, 178.0, 13.3417
53.811906660, 18.870, 218.0, 14.7648
53.855372420, 18.870, 273.0, 16.5227
53.898838180, 18.870, 294.0, 17.1464
53.942303940, 18.870, 233.0, 15.2643
53.985769700, 18.870, 222.0, 14.8997
54.029235460, 18.870, 184.0, 13.5647
54.072701220, 18.870, 162.0, 12.7279
54.116166980, 18.870, 120.0, 10.9545
54.159632740, 18.870, 117.0, 10.8167
54.203098500, 18.870, 131.0, 11.4455
54.246564260, 18.870, 117.0, 10.8167
54.290030020, 18.870, 87.0, 9.3274
54.333495780, 18.870, 120.0, 10.9545
54.376961540, 18.870, 108.0, 10.3923
54.420427300, 18.870, 123.0, 11.0905
54.463893060, 18.870, 78.0, 8.8318
54.507358820, 18.870, 109.0, 10.4403
54.550824580, 18.870, 112.0, 10.5830
54.594290340, 18.870, 110.0, 10.4881
54.637756100, 18.870, 107.0, 10.3441
54.681221860, 18.870, 125.0, 11.1803
54.724687620, 18.870, 115.0, 10.7238
54.768153380, 18.870, 108.0, 10.3923
54.811619140, 18.870, 101.0, 10.0499
54.855084900, 18.870, 111.0, 10.5357
54.898550660, 18.870, 129.0, 11.3578
54.942016420, 18.870, 102.0, 10.0995
54.985482180, 18.870, 108.0, 10.3923
55.028947940, 18.870, 111.0, 10.5357
55.072413700, 18.870, 125.0, 11.1803
55.115879460, 18.870, 104.0, 10.1980
55.159345220, 18.870, 91.0, 9.5394
55.202810980, 18.870, 114.0, 10.6771
55.246276740, 18.870, 124.0, 11.1355
55.289742500, 18.870, 106.0, 10.2956
55.333208260, 18.870, 121.0, 11.0000
55.376674020, 18.870, 102.0, 10.0995
55.420139780, 18.870, 107.0, 10.3441
55.463605540, 18.870, 137.0, 11.7047
55.507071300, 18.870, 96.0, 9.7980
55.550537060, 18.870, 93.0, 9.6437
55.594002820, 18.870, 104.0, 10.1980
55.637468580, 18.870, 102.0, 10.0995
55.680934340, 18.870, 118.0, 10.8628
55.724400100, 18.870, 112.0, 10.5830
55.767865860, 18.870, 101.0, 10.0499
55.811331620, 18.870, 130.0, 11.4018
55.854797380, 18.870, 120.0, 10.9545
55.898263140, 18.870, 133.0, 11.5326
55.941728900, 18.870, 145.0, 12.0416
55.985194660, 18.870, 121.0, 11.0000
56.028660420, 18.870, 134.0, 11.5758
56.072126180, 18.870, 121.0, 11.0000
56.115591940, 18.870, 137.0, 11.7047
56.159057700, 18.870, 127.0, 11.2694
56.202523460, 18.870, 131.0, 11.4455
56.245989220, 18.870, 148.0, 12.1655
56.289454980, 18.870, 190.0, 13.7840
56.332920740, 18.870, 246.0, 15.6844
56.376386500, 18.870, 429.0, 20.7123
56.419852260, 18.870, 564.0, 23.7487
56.463318020, 18.870, 423.0, 20.5670
56.506783780, 18.870, 316.0, 17.7764
56.550249540, 18.870, 382.0, 19.5448
56.593715300, 18.870, 360.0, 18.9737
56.637181060, 18.870, 181.0, 13.4536
56.680646820, 18.870, 156.0, 12.4900
56.724112580, 18.870, 170.0, 13.0384
56.767578340, 18.870, 124.0, 11.1355
56.811044100, 18.870, 114.0, 10.6771
56.854509860, 18.870, 113.0, 10.6301
56.897975620, 18.870, 122.0, 11.0454
56.941441380, 18.870, 121.0, 11.0000
56.984907140, 18.870, 123.0, 11.0905
57.028372900, 18.870, 92.0, 9.5917
57.071838660, 18.870, 113.0, 10.6301
57.115304420, 18.870, 106.0, 10.2956
57.158770180, 18.870, 107.0, 10.3441
57.202235940, 18.870, 115.0, 10.7238
57.245701700, 18.870, 105.0, 10.2470
57.289167460, 18.870, 109.0, 10.4403
57.332633220, 18.870, 99.0, 9.9499
57.376098980, 18.870, 99.0, 9.9499
57.419564740, 18.870, 96.0, 9.7980
57.463030500, 18.870, 118.0, 10.8628
57.506496260, 18.870, 106.0, 10.2956
57.549962020, 18.870, 111.0, 10.5357
57.593427780, 18.870, 111.0, 10.5357
57.636893540, 18.870, 120.0, 10.9545
57.680359300, 18.870, 92.0, 9.5917
57.723825060, 18.870, 119.0, 10.9087
57.767290820, 18.870, 114.0, 10.6771
57.810756580, 18.870, 114.0, 10.6771
57.854222340, 18.870, 104.0, 10.1980
57.897688100, 18.870, 96.0, 9.7980
57.941153860, 18.870, 109.0, 10.4403
57.984619620, 18.870, 106.0, 10.2956
58.028085380, 18.870, 117.0, 10.8167
58.071551140, 18.870, 101.0, 10.0499
58.115016900, 18.870, 100.0, 10.0000
58.158482660, 18.870, 125.0, 11.1803
58.201948420, 18.870, 109.0, 10.4403
58.245414180, 18.870, 121.0, 11.0000
58.288879940, 18.870, 107.0, 10.3441
58.332345700, 18.870, 115.0, 10.7238
58.375811460, 18.870, 97.0, 9.8489
58.419277220, 18.870, 114.0, 10.6771
58.462742980, 18.870, 106.0, 10.2956
58.506208740, 18.870, 111.0, 10.5357
58.549674500, 18.870, 127.0, 11.2694
58.593140260, 18.870, 121.0, 11.0000
58.636606020, 18.870, 111.0, 10.5357
58.680071780, 18.870, 120.0, 10.9545
58.723537540, 18.870, 117.0, 10.8167
58.767003300, 18.870, 99.0, 9.9499
58.810469060, 18.870, 119.0, 10.9087
58.853934820, 18.870, 122.0, 11.0454
58.897400580, 18.870, 117.0, 10.8167
58.940866340, 18.870, 119.0, 10.9087
58.984332100, 18.870, 118.0, 10.8628
59.027797860, 18.870, 140.0, 11.8322
59.071263620, 18.870, 162.0, 12.7279
59.114729380, 18.870, 149.0, 12.2066
59.158195140, 18.870, 135.0, 11.6190
59.201660900, 18.870, 121.0, 11.0000
59.245126660, 18.870, 102.0, 10.0995
59.288592420, 18.870, 115.0, 10.7238
59.332058180, 18.870, 109.0, 10.4403
59.375523940, 18.870, 102.0, 10.0995
59.418989700, 18.870, 119.0, 10.9087
59.462455460, 18.870, 101.0, 10.0499
59.505921220, 18.870, 109.0, 10.4403
59.549386980, 18.870, 99.0, 9.9499
59.592852740, 18.870, 120.0, 10.9545
59.636318500, 18.870, 121.0, 11.0000
59.679784260, 18.870, 112.0, 10.5830
59.723250020, 18.870, 121.0, 11.0000
59.766715780, 18.870, 124.0, 11.1355
59.810181540, 18.870, 116.0, 10.7703
59.853647300, 18.870, 100.0, 10.0000
59.897113060, 18.870, 105.0, 10.2470
59.940578820, 18.870, 97.0, 9.8489
59.984044580, 18.870, 94.0, 9.6954
59.994911020, 18.870, 110.0, 10.4881