File: XRD/2025_06_03_CBN_SA_Slurry_3_60_8min.csv
[Measurement conditions]
Sample identification,2025_06_03_CBN_SA_Slurry_3_60_8min
Comment - 1,"CBN - Sorbic Acid Cocrystal, Slurry Method, Heptane, 5/9/25, JL"
Anode material,Cu
K-Alpha1 wavelength,1.5405980
K-Alpha2 wavelength,1.5444260
Ratio K-Alpha2/K-Alpha1,0.500
Divergence slit,Fixed,0.76mm
Monochromator used,NO
Generator voltage, 40
Tube current, 15
File date and time,03/Jun/2025 15:47
Unit cell,
h k l, 0 0 0
Scan axis,Gonio
Scan range,2.995000000,60.000344240
Scan step size,0.0108664
No. of points, 5246
Scan type,CONTINUOUS
Time per step,18.870
[Scan points]
Angle, TimePerStep, Intensity, ESD
3.000433220, 18.870, 43202.0, 207.8509
3.043898980, 18.870, 41112.0, 202.7609
3.087364740, 18.870, 39355.0, 198.3809
3.130830500, 18.870, 37823.0, 194.4814
3.174296260, 18.870, 35355.0, 188.0293
3.217762020, 18.870, 33779.0, 183.7906
3.261227780, 18.870, 32033.0, 178.9777
3.304693540, 18.870, 29948.0, 173.0549
3.348159300, 18.870, 28246.0, 168.0655
3.391625060, 18.870, 26682.0, 163.3463
3.435090820, 18.870, 25000.0, 158.1139
3.478556580, 18.870, 23999.0, 154.9161
3.522022340, 18.870, 22413.0, 149.7097
3.565488100, 18.870, 21258.0, 145.8012
3.608953860, 18.870, 20092.0, 141.7463
3.652419620, 18.870, 18782.0, 137.0474
3.695885380, 18.870, 17705.0, 133.0601
3.739351140, 18.870, 16797.0, 129.6032
3.782816900, 18.870, 15739.0, 125.4552
3.826282660, 18.870, 14781.0, 121.5771
3.869748420, 18.870, 13678.0, 116.9530
3.913214180, 18.870, 13164.0, 114.7345
3.956679940, 18.870, 12214.0, 110.5170
4.000145700, 18.870, 11626.0, 107.8239
4.043611460, 18.870, 11106.0, 105.3850
4.087077220, 18.870, 10729.0, 103.5809
4.130542980, 18.870, 10425.0, 102.1029
4.174008740, 18.870, 10366.0, 101.8136
4.217474500, 18.870, 10185.0, 100.9208
4.260940260, 18.870, 10004.0, 100.0200
4.304406020, 18.870, 9800.0, 98.9949
4.347871780, 18.870, 9006.0, 94.8999
4.391337540, 18.870, 8019.0, 89.5489
4.434803300, 18.870, 7130.0, 84.4393
4.478269060, 18.870, 6333.0, 79.5801
4.521734820, 18.870, 5837.0, 76.4003
4.565200580, 18.870, 5419.0, 73.6139
4.608666340, 18.870, 5321.0, 72.9452
4.652132100, 18.870, 5413.0, 73.5731
4.695597860, 18.870, 5368.0, 73.2666
4.739063620, 18.870, 5599.0, 74.8265
4.782529380, 18.870, 5954.0, 77.1622
4.825995140, 18.870, 6341.0, 79.6304
4.869460900, 18.870, 7247.0, 85.1293
4.912926660, 18.870, 8062.0, 89.7886
4.956392420, 18.870, 9501.0, 97.4731
4.999858180, 18.870, 11258.0, 106.1037
5.043323940, 18.870, 12835.0, 113.2917
5.086789700, 18.870, 14220.0, 119.2476
5.130255460, 18.870, 14927.0, 122.1761
5.173721220, 18.870, 14855.0, 121.8811
5.217186980, 18.870, 13472.0, 116.0689
5.260652740, 18.870, 10943.0, 104.6088
5.304118500, 18.870, 8324.0, 91.2360
5.347584260, 18.870, 6420.0, 80.1249
5.391050020, 18.870, 5561.0, 74.5721
5.434515780, 18.870, 5296.0, 72.7736
5.477981540, 18.870, 5310.0, 72.8697
5.521447300, 18.870, 5413.0, 73.5731
5.564913060, 18.870, 5427.0, 73.6682
5.608378820, 18.870, 5682.0, 75.3790
5.651844580, 18.870, 5652.0, 75.1798
5.695310340, 18.870, 5464.0, 73.9189
5.738776100, 18.870, 4931.0, 70.2211
5.782241860, 18.870, 4271.0, 65.3529
5.825707620, 18.870, 3669.0, 60.5723
5.869173380, 18.870, 3103.0, 55.7046
5.912639140, 18.870, 2752.0, 52.4595
5.956104900, 18.870, 2505.0, 50.0500
5.999570660, 18.870, 2368.0, 48.6621
6.043036420, 18.870, 2328.0, 48.2494
6.086502180, 18.870, 2053.0, 45.3100
6.129967940, 18.870, 2035.0, 45.1110
6.173433700, 18.870, 1967.0, 44.3509
6.216899460, 18.870, 1898.0, 43.5660
6.260365220, 18.870, 1731.0, 41.6053
6.303830980, 18.870, 1784.0, 42.2374
6.347296740, 18.870, 1727.0, 41.5572
6.390762500, 18.870, 1614.0, 40.1746
6.434228260, 18.870, 1529.0, 39.1024
6.477694020, 18.870, 1465.0, 38.2753
6.521159780, 18.870, 1485.0, 38.5357
6.564625540, 18.870, 1382.0, 37.1753
6.608091300, 18.870, 1335.0, 36.5377
6.651557060, 18.870, 1293.0, 35.9583
6.695022820, 18.870, 1232.0, 35.0999
6.738488580, 18.870, 1260.0, 35.4965
6.781954340, 18.870, 1231.0, 35.0856
6.825420100, 18.870, 1243.0, 35.2562
6.868885860, 18.870, 1172.0, 34.2345
6.912351620, 18.870, 1207.0, 34.7419
6.955817380, 18.870, 1202.0, 34.6699
6.999283140, 18.870, 1273.0, 35.6791
7.042748900, 18.870, 1204.0, 34.6987
7.086214660, 18.870, 1165.0, 34.1321
7.129680420, 18.870, 1190.0, 34.4964
7.173146180, 18.870, 1179.0, 34.3366
7.216611940, 18.870, 1222.0, 34.9571
7.260077700, 18.870, 1254.0, 35.4119
7.303543460, 18.870, 1209.0, 34.7707
7.347009220, 18.870, 1097.0, 33.1210
7.390474980, 18.870, 1108.0, 33.2866
7.433940740, 18.870, 1043.0, 32.2955
7.477406500, 18.870, 1033.0, 32.1403
7.520872260, 18.870, 1126.0, 33.5559
7.564338020, 18.870, 1122.0, 33.4963
7.607803780, 18.870, 1183.0, 34.3948
7.651269540, 18.870, 1242.0, 35.2420
7.694735300, 18.870, 1289.0, 35.9026
7.738201060, 18.870, 1311.0, 36.2077
7.781666820, 18.870, 1393.0, 37.3229
7.825132580, 18.870, 1350.0, 36.7423
7.868598340, 18.870, 1213.0, 34.8281
7.912064100, 18.870, 1192.0, 34.5254
7.955529860, 18.870, 1063.0, 32.6037
7.998995620, 18.870, 1002.0, 31.6544
8.042461380, 18.870, 978.0, 31.2730
8.085927140, 18.870, 1032.0, 32.1248
8.129392900, 18.870, 1026.0, 32.0312
8.172858660, 18.870, 1001.0, 31.6386
8.216324420, 18.870, 1031.0, 32.1092
8.259790180, 18.870, 1007.0, 31.7333
8.303255940, 18.870, 1084.0, 32.9242
8.346721700, 18.870, 1127.0, 33.5708
8.390187460, 18.870, 1213.0, 34.8281
8.433653220, 18.870, 1231.0, 35.0856
8.477118980, 18.870, 1269.0, 35.6230
8.520584740, 18.870, 1349.0, 36.7287
8.564050500, 18.870, 1379.0, 37.1349
8.607516260, 18.870, 1270.0, 35.6371
8.650982020, 18.870, 1362.0, 36.9053
8.694447780, 18.870, 1350.0, 36.7423
8.737913540, 18.870, 1275.0, 35.7071
8.781379300, 18.870, 1305.0, 36.1248
8.824845060, 18.870, 1319.0, 36.3180
8.868310820, 18.870, 1416.0, 37.6298
8.911776580, 18.870, 1410.0, 37.5500
8.955242340, 18.870, 1469.0, 38.3275
8.998708100, 18.870, 1481.0, 38.4838
9.042173860, 18.870, 1610.0, 40.1248
9.085639620, 18.870, 1666.0, 40.8167
9.129105380, 18.870, 1711.0, 41.3642
9.172571140, 18.870, 1669.0, 40.8534
9.216036900, 18.870, 1511.0, 38.8716
9.259502660, 18.870, 1535.0, 39.1791
9.302968420, 18.870, 1350.0, 36.7423
9.346434180, 18.870, 1438.0, 37.9210
9.389899940, 18.870, 1363.0, 36.9188
9.433365700, 18.870, 1401.0, 37.4299
9.476831460, 18.870, 1404.0, 37.4700
9.520297220, 18.870, 1424.0, 37.7359
9.563762980, 18.870, 1366.0, 36.9594
9.607228740, 18.870, 1408.0, 37.5233
9.650694500, 18.870, 1316.0, 36.2767
9.694160260, 18.870, 1332.0, 36.4966
9.737626020, 18.870, 1320.0, 36.3318
9.781091780, 18.870, 1371.0, 37.0270
9.824557540, 18.870, 1593.0, 39.9124
9.868023300, 18.870, 1509.0, 38.8458
9.911489060, 18.870, 1747.0, 41.7971
9.954954820, 18.870, 1941.0, 44.0568
9.998420580, 18.870, 2128.0, 46.1303
10.041886340, 18.870, 2394.0, 48.9285
10.085352100, 18.870, 2662.0, 51.5946
10.128817860, 18.870, 2871.0, 53.5817
10.172283620, 18.870, 2900.0, 53.8516
10.215749380, 18.870, 2921.0, 54.0463
10.259215140, 18.870, 2913.0, 53.9722
10.302680900, 18.870, 2822.0, 53.1225
10.346146660, 18.870, 2501.0, 50.0100
10.389612420, 18.870, 2152.0, 46.3897
10.433078180, 18.870, 2083.0, 45.6399
10.476543940, 18.870, 2070.0, 45.4973
10.520009700, 18.870, 2171.0, 46.5940
10.563475460, 18.870, 2319.0, 48.1560
10.606941220, 18.870, 2475.0, 49.7494
10.650406980, 18.870, 2579.0, 50.7839
10.693872740, 18.870, 2580.0, 50.7937
10.737338500, 18.870, 2499.0, 49.9900
10.780804260, 18.870, 2403.0, 49.0204
10.824270020, 18.870, 2325.0, 48.2183
10.867735780, 18.870, 2196.0, 46.8615
10.911201540, 18.870, 2172.0, 46.6047
10.954667300, 18.870, 2321.0, 48.1768
10.998133060, 18.870, 2677.0, 51.7397
11.041598820, 18.870, 2911.0, 53.9537
11.085064580, 18.870, 3142.0, 56.0535
11.128530340, 18.870, 3478.0, 58.9746
11.171996100, 18.870, 3764.0, 61.3514
11.215461860, 18.870, 3962.0, 62.9444
11.258927620, 18.870, 4043.0, 63.5846
11.302393380, 18.870, 4053.0, 63.6632
11.345859140, 18.870, 4127.0, 64.2417
11.389324900, 18.870, 4006.0, 63.2930
11.432790660, 18.870, 3937.0, 62.7455
11.476256420, 18.870, 3724.0, 61.0246
11.519722180, 18.870, 3382.0, 58.1550
11.563187940, 18.870, 2883.0, 53.6936
11.606653700, 18.870, 2659.0, 51.5655
11.650119460, 18.870, 2278.0, 47.7284
11.693585220, 18.870, 2199.0, 46.8935
11.737050980, 18.870, 2075.0, 45.5522
11.780516740, 18.870, 2147.0, 46.3357
11.823982500, 18.870, 2145.0, 46.3141
11.867448260, 18.870, 1997.0, 44.6878
11.910914020, 18.870, 1898.0, 43.5660
11.954379780, 18.870, 1796.0, 42.3792
11.997845540, 18.870, 1823.0, 42.6966
12.041311300, 18.870, 1736.0, 41.6653
12.084777060, 18.870, 1840.0, 42.8952
12.128242820, 18.870, 1881.0, 43.3705
12.171708580, 18.870, 2145.0, 46.3141
12.215174340, 18.870, 2414.0, 49.1325
12.258640100, 18.870, 2819.0, 53.0943
12.302105860, 18.870, 3419.0, 58.4722
12.345571620, 18.870, 4040.0, 63.5610
12.389037380, 18.870, 4727.0, 68.7532
12.432503140, 18.870, 4914.0, 70.0999
12.475968900, 18.870, 5225.0, 72.2842
12.519434660, 18.870, 5220.0, 72.2496
12.562900420, 18.870, 4839.0, 69.5629
12.606366180, 18.870, 4221.0, 64.9692
12.649831940, 18.870, 3657.0, 60.4731
12.693297700, 18.870, 2934.0, 54.1664
12.736763460, 18.870, 2519.0, 50.1896
12.780229220, 18.870, 2371.0, 48.6929
12.823694980, 18.870, 2247.0, 47.4025
12.867160740, 18.870, 2355.0, 48.5283
12.910626500, 18.870, 2333.0, 48.3011
12.954092260, 18.870, 2082.0, 45.6289
12.997558020, 18.870, 1976.0, 44.4522
13.041023780, 18.870, 1932.0, 43.9545
13.084489540, 18.870, 1790.0, 42.3084
13.127955300, 18.870, 1569.0, 39.6106
13.171421060, 18.870, 1542.0, 39.2683
13.214886820, 18.870, 1466.0, 38.2884
13.258352580, 18.870, 1683.0, 41.0244
13.301818340, 18.870, 1689.0, 41.0974
13.345284100, 18.870, 1789.0, 42.2966
13.388749860, 18.870, 1757.0, 41.9166
13.432215620, 18.870, 1749.0, 41.8210
13.475681380, 18.870, 1740.0, 41.7133
13.519147140, 18.870, 1711.0, 41.3642
13.562612900, 18.870, 1551.0, 39.3827
13.606078660, 18.870, 1535.0, 39.1791
13.649544420, 18.870, 1536.0, 39.1918
13.693010180, 18.870, 1588.0, 39.8497
13.736475940, 18.870, 1546.0, 39.3192
13.779941700, 18.870, 1641.0, 40.5093
13.823407460, 18.870, 1629.0, 40.3609
13.866873220, 18.870, 1594.0, 39.9249
13.910338980, 18.870, 1619.0, 40.2368
13.953804740, 18.870, 1581.0, 39.7618
13.997270500, 18.870, 1558.0, 39.4715
14.040736260, 18.870, 1606.0, 40.0749
14.084202020, 18.870, 1702.0, 41.2553
14.127667780, 18.870, 1877.0, 43.3244
14.171133540, 18.870, 2169.0, 46.5725
14.214599300, 18.870, 2412.0, 49.1121
14.258065060, 18.870, 2730.0, 52.2494
14.301530820, 18.870, 3017.0, 54.9272
14.344996580, 18.870, 3290.0, 57.3585
14.388462340, 18.870, 3379.0, 58.1292
14.431928100, 18.870, 3483.0, 59.0169
14.475393860, 18.870, 3369.0, 58.0431
14.518859620, 18.870, 3259.0, 57.0877
14.562325380, 18.870, 3080.0, 55.4977
14.605791140, 18.870, 2715.0, 52.1057
14.649256900, 18.870, 2413.0, 49.1223
14.692722660, 18.870, 2214.0, 47.0532
14.736188420, 18.870, 1955.0, 44.2154
14.779654180, 18.870, 1750.0, 41.8330
14.823119940, 18.870, 1684.0, 41.0366
14.866585700, 18.870, 1621.0, 40.2616
14.910051460, 18.870, 1617.0, 40.2119
14.953517220, 18.870, 1602.0, 40.0250
14.996982980, 18.870, 1709.0, 41.3401
15.040448740, 18.870, 1768.0, 42.0476
15.083914500, 18.870, 1960.0, 44.2719
15.127380260, 18.870, 2152.0, 46.3897
15.170846020, 18.870, 2294.0, 47.8957
15.214311780, 18.870, 2391.0, 48.8979
15.257777540, 18.870, 2474.0, 49.7393
15.301243300, 18.870, 2527.0, 50.2693
15.344709060, 18.870, 2498.0, 49.9800
15.388174820, 18.870, 2314.0, 48.1041
15.431640580, 18.870, 2295.0, 47.9062
15.475106340, 18.870, 2163.0, 46.5081
15.518572100, 18.870, 2020.0, 44.9444
15.562037860, 18.870, 1841.0, 42.9069
15.605503620, 18.870, 1797.0, 42.3910
15.648969380, 18.870, 1811.0, 42.5558
15.692435140, 18.870, 1859.0, 43.1161
15.735900900, 18.870, 1995.0, 44.6654
15.779366660, 18.870, 2071.0, 45.5082
15.822832420, 18.870, 2409.0, 49.0816
15.866298180, 18.870, 2675.0, 51.7204
15.909763940, 18.870, 3050.0, 55.2268
15.953229700, 18.870, 3653.0, 60.4401
15.996695460, 18.870, 4199.0, 64.7997
16.040161220, 18.870, 5012.0, 70.7955
16.083626980, 18.870, 5388.0, 73.4030
16.127092740, 18.870, 5775.0, 75.9934
16.170558500, 18.870, 5712.0, 75.5778
16.214024260, 18.870, 5479.0, 74.0203
16.257490020, 18.870, 4882.0, 69.8713
16.300955780, 18.870, 4478.0, 66.9179
16.344421540, 18.870, 3473.0, 58.9322
16.387887300, 18.870, 2870.0, 53.5724
16.431353060, 18.870, 2485.0, 49.8498
16.474818820, 18.870, 2190.0, 46.7974
16.518284580, 18.870, 1890.0, 43.4741
16.561750340, 18.870, 1885.0, 43.4166
16.605216100, 18.870, 1785.0, 42.2493
16.648681860, 18.870, 1950.0, 44.1588
16.692147620, 18.870, 2015.0, 44.8888
16.735613380, 18.870, 2115.0, 45.9891
16.779079140, 18.870, 2352.0, 48.4974
16.822544900, 18.870, 2361.0, 48.5901
16.866010660, 18.870, 2523.0, 50.2295
16.909476420, 18.870, 2626.0, 51.2445
16.952942180, 18.870, 2650.0, 51.4782
16.996407940, 18.870, 2523.0, 50.2295
17.039873700, 18.870, 2551.0, 50.5074
17.083339460, 18.870, 2321.0, 48.1768
17.126805220, 18.870, 2113.0, 45.9674
17.170270980, 18.870, 1968.0, 44.3621
17.213736740, 18.870, 1846.0, 42.9651
17.257202500, 18.870, 1858.0, 43.1045
17.300668260, 18.870, 1821.0, 42.6732
17.344134020, 18.870, 1846.0, 42.9651
17.387599780, 18.870, 1897.0, 43.5546
17.431065540, 18.870, 1897.0, 43.5546
17.474531300, 18.870, 2075.0, 45.5522
17.517997060, 18.870, 2098.0, 45.8039
17.561462820, 18.870, 2326.0, 48.2286
17.604928580, 18.870, 2551.0, 50.5074
17.648394340, 18.870, 2715.0, 52.1057
17.691860100, 18.870, 2864.0, 53.5164
17.735325860, 18.870, 3096.0, 55.6417
17.778791620, 18.870, 3220.0, 56.7450
17.822257380, 18.870, 3453.0, 58.7622
17.865723140, 18.870, 3549.0, 59.5735
17.909188900, 18.870, 3781.0, 61.4898
17.952654660, 18.870, 4094.0, 63.9844
17.996120420, 18.870, 4425.0, 66.5207
18.039586180, 18.870, 4764.0, 69.0217
18.083051940, 18.870, 5113.0, 71.5052
18.126517700, 18.870, 5325.0, 72.9726
18.169983460, 18.870, 5527.0, 74.3438
18.213449220, 18.870, 5899.0, 76.8049
18.256914980, 18.870, 6295.0, 79.3410
18.300380740, 18.870, 6647.0, 81.5291
18.343846500, 18.870, 6729.0, 82.0305
18.387312260, 18.870, 6675.0, 81.7007
18.430778020, 18.870, 6457.0, 80.3555
18.474243780, 18.870, 6117.0, 78.2113
18.517709540, 18.870, 5429.0, 73.6817
18.561175300, 18.870, 4965.0, 70.4628
18.604641060, 18.870, 4060.0, 63.7181
18.648106820, 18.870, 3333.0, 57.7321
18.691572580, 18.870, 2877.0, 53.6377
18.735038340, 18.870, 2606.0, 51.0490
18.778504100, 18.870, 2471.0, 49.7092
18.821969860, 18.870, 2490.0, 49.8999
18.865435620, 18.870, 2565.0, 50.6458
18.908901380, 18.870, 2787.0, 52.7920
18.952367140, 18.870, 3005.0, 54.8179
18.995832900, 18.870, 3248.0, 56.9912
19.039298660, 18.870, 3466.0, 58.8727
19.082764420, 18.870, 3591.0, 59.9250
19.126230180, 18.870, 3566.0, 59.7160
19.169695940, 18.870, 3676.0, 60.6300
19.213161700, 18.870, 3623.0, 60.1914
19.256627460, 18.870, 3396.0, 58.2752
19.300093220, 18.870, 3221.0, 56.7539
19.343558980, 18.870, 3197.0, 56.5420
19.387024740, 18.870, 3034.0, 55.0818
19.430490500, 18.870, 3039.0, 55.1271
19.473956260, 18.870, 3115.0, 55.8122
19.517422020, 18.870, 3089.0, 55.5788
19.560887780, 18.870, 3100.0, 55.6776
19.604353540, 18.870, 2992.0, 54.6992
19.647819300, 18.870, 2992.0, 54.6992
19.691285060, 18.870, 2886.0, 53.7215
19.734750820, 18.870, 2990.0, 54.6809
19.778216580, 18.870, 3097.0, 55.6507
19.821682340, 18.870, 3189.0, 56.4712
19.865148100, 18.870, 3163.0, 56.2406
19.908613860, 18.870, 3172.0, 56.3205
19.952079620, 18.870, 3206.0, 56.6216
19.995545380, 18.870, 2983.0, 54.6168
20.039011140, 18.870, 2865.0, 53.5257
20.082476900, 18.870, 2781.0, 52.7352
20.125942660, 18.870, 2821.0, 53.1131
20.169408420, 18.870, 3011.0, 54.8726
20.212874180, 18.870, 3152.0, 56.1427
20.256339940, 18.870, 3575.0, 59.7913
20.299805700, 18.870, 3927.0, 62.6658
20.343271460, 18.870, 4745.0, 68.8840
20.386737220, 18.870, 5272.0, 72.6085
20.430202980, 18.870, 5619.0, 74.9600
20.473668740, 18.870, 5742.0, 75.7760
20.517134500, 18.870, 5719.0, 75.6241
20.560600260, 18.870, 5428.0, 73.6750
20.604066020, 18.870, 5095.0, 71.3793
20.647531780, 18.870, 4446.0, 66.6783
20.690997540, 18.870, 3831.0, 61.8951
20.734463300, 18.870, 3398.0, 58.2924
20.777929060, 18.870, 3102.0, 55.6956
20.821394820, 18.870, 2921.0, 54.0463
20.864860580, 18.870, 2764.0, 52.5738
20.908326340, 18.870, 2690.0, 51.8652
20.951792100, 18.870, 2624.0, 51.2250
20.995257860, 18.870, 2530.0, 50.2991
21.038723620, 18.870, 2414.0, 49.1325
21.082189380, 18.870, 2358.0, 48.5592
21.125655140, 18.870, 2257.0, 47.5079
21.169120900, 18.870, 2533.0, 50.3289
21.212586660, 18.870, 2564.0, 50.6360
21.256052420, 18.870, 2747.0, 52.4118
21.299518180, 18.870, 3148.0, 56.1070
21.342983940, 18.870, 3231.0, 56.8419
21.386449700, 18.870, 3406.0, 58.3609
21.429915460, 18.870, 3650.0, 60.4152
21.473381220, 18.870, 3858.0, 62.1128
21.516846980, 18.870, 3872.0, 62.2254
21.560312740, 18.870, 4142.0, 64.3584
21.603778500, 18.870, 4175.0, 64.6142
21.647244260, 18.870, 4309.0, 65.6430
21.690710020, 18.870, 4371.0, 66.1135
21.734175780, 18.870, 4191.0, 64.7379
21.777641540, 18.870, 4116.0, 64.1561
21.821107300, 18.870, 3928.0, 62.6738
21.864573060, 18.870, 3614.0, 60.1166
21.908038820, 18.870, 3310.0, 57.5326
21.951504580, 18.870, 3051.0, 55.2359
21.994970340, 18.870, 2902.0, 53.8702
22.038436100, 18.870, 2922.0, 54.0555
22.081901860, 18.870, 2884.0, 53.7029
22.125367620, 18.870, 2761.0, 52.5452
22.168833380, 18.870, 2716.0, 52.1153
22.212299140, 18.870, 2855.0, 53.4322
22.255764900, 18.870, 2851.0, 53.3948
22.299230660, 18.870, 3009.0, 54.8544
22.342696420, 18.870, 3079.0, 55.4887
22.386162180, 18.870, 2965.0, 54.4518
22.429627940, 18.870, 2798.0, 52.8961
22.473093700, 18.870, 2668.0, 51.6527
22.516559460, 18.870, 2452.0, 49.5177
22.560025220, 18.870, 2160.0, 46.4758
22.603490980, 18.870, 2131.0, 46.1628
22.646956740, 18.870, 2040.0, 45.1664
22.690422500, 18.870, 2003.0, 44.7549
22.733888260, 18.870, 2085.0, 45.6618
22.777354020, 18.870, 2060.0, 45.3872
22.820819780, 18.870, 2034.0, 45.0999
22.864285540, 18.870, 2047.0, 45.2438
22.907751300, 18.870, 2029.0, 45.0444
22.951217060, 18.870, 1966.0, 44.3396
22.994682820, 18.870, 1959.0, 44.2606
23.038148580, 18.870, 1962.0, 44.2945
23.081614340, 18.870, 1943.0, 44.0795
23.125080100, 18.870, 1895.0, 43.5316
23.168545860, 18.870, 1743.0, 41.7493
23.212011620, 18.870, 1690.0, 41.1096
23.255477380, 18.870, 1562.0, 39.5221
23.298943140, 18.870, 1581.0, 39.7618
23.342408900, 18.870, 1533.0, 39.1535
23.385874660, 18.870, 1548.0, 39.3446
23.429340420, 18.870, 1551.0, 39.3827
23.472806180, 18.870, 1420.0, 37.6829
23.516271940, 18.870, 1435.0, 37.8814
23.559737700, 18.870, 1542.0, 39.2683
23.603203460, 18.870, 1642.0, 40.5216
23.646669220, 18.870, 1665.0, 40.8044
23.690134980, 18.870, 1678.0, 40.9634
23.733600740, 18.870, 1640.0, 40.4969
23.777066500, 18.870, 1700.0, 41.2311
23.820532260, 18.870, 1758.0, 41.9285
23.863998020, 18.870, 1910.0, 43.7035
23.907463780, 18.870, 2044.0, 45.2106
23.950929540, 18.870, 2124.0, 46.0869
23.994395300, 18.870, 2110.0, 45.9347
24.037861060, 18.870, 2235.0, 47.2758
24.081326820, 18.870, 2295.0, 47.9062
24.124792580, 18.870, 2156.0, 46.4327
24.168258340, 18.870, 2162.0, 46.4973
24.211724100, 18.870, 1951.0, 44.1701
24.255189860, 18.870, 1911.0, 43.7150
24.298655620, 18.870, 1741.0, 41.7253
24.342121380, 18.870, 1705.0, 41.2916
24.385587140, 18.870, 1618.0, 40.2244
24.429052900, 18.870, 1679.0, 40.9756
24.472518660, 18.870, 1699.0, 41.2189
24.515984420, 18.870, 1805.0, 42.4853
24.559450180, 18.870, 1927.0, 43.8976
24.602915940, 18.870, 2036.0, 45.1221
24.646381700, 18.870, 2152.0, 46.3897
24.689847460, 18.870, 2258.0, 47.5184
24.733313220, 18.870, 2324.0, 48.2079
24.776778980, 18.870, 2303.0, 47.9896
24.820244740, 18.870, 2295.0, 47.9062
24.863710500, 18.870, 2032.0, 45.0777
24.907176260, 18.870, 1901.0, 43.6005
24.950642020, 18.870, 1722.0, 41.4970
24.994107780, 18.870, 1759.0, 41.9404
25.037573540, 18.870, 1777.0, 42.1545
25.081039300, 18.870, 1794.0, 42.3556
25.124505060, 18.870, 1857.0, 43.0929
25.167970820, 18.870, 1816.0, 42.6146
25.211436580, 18.870, 1810.0, 42.5441
25.254902340, 18.870, 1811.0, 42.5558
25.298368100, 18.870, 1687.0, 41.0731
25.341833860, 18.870, 1646.0, 40.5709
25.385299620, 18.870, 1599.0, 39.9875
25.428765380, 18.870, 1490.0, 38.6005
25.472231140, 18.870, 1620.0, 40.2492
25.515696900, 18.870, 1571.0, 39.6358
25.559162660, 18.870, 1629.0, 40.3609
25.602628420, 18.870, 1594.0, 39.9249
25.646094180, 18.870, 1596.0, 39.9500
25.689559940, 18.870, 1664.0, 40.7922
25.733025700, 18.870, 1595.0, 39.9375
25.776491460, 18.870, 1632.0, 40.3980
25.819957220, 18.870, 1520.0, 38.9872
25.863422980, 18.870, 1393.0, 37.3229
25.906888740, 18.870, 1382.0, 37.1753
25.950354500, 18.870, 1304.0, 36.1109
25.993820260, 18.870, 1299.0, 36.0416
26.037286020, 18.870, 1305.0, 36.1248
26.080751780, 18.870, 1251.0, 35.3695
26.124217540, 18.870, 1362.0, 36.9053
26.167683300, 18.870, 1338.0, 36.5787
26.211149060, 18.870, 1337.0, 36.5650
26.254614820, 18.870, 1315.0, 36.2629
26.298080580, 18.870, 1332.0, 36.4966
26.341546340, 18.870, 1332.0, 36.4966
26.385012100, 18.870, 1238.0, 35.1852
26.428477860, 18.870, 1249.0, 35.3412
26.471943620, 18.870, 1203.0, 34.6843
26.515409380, 18.870, 1127.0, 33.5708
26.558875140, 18.870, 1073.0, 32.7567
26.602340900, 18.870, 1157.0, 34.0147
26.645806660, 18.870, 1193.0, 34.5398
26.689272420, 18.870, 1207.0, 34.7419
26.732738180, 18.870, 1283.0, 35.8190
26.776203940, 18.870, 1243.0, 35.2562
26.819669700, 18.870, 1193.0, 34.5398
26.863135460, 18.870, 1359.0, 36.8646
26.906601220, 18.870, 1288.0, 35.8887
26.950066980, 18.870, 1338.0, 36.5787
26.993532740, 18.870, 1397.0, 37.3765
27.036998500, 18.870, 1438.0, 37.9210
27.080464260, 18.870, 1388.0, 37.2559
27.123930020, 18.870, 1545.0, 39.3065
27.167395780, 18.870, 1565.0, 39.5601
27.210861540, 18.870, 1487.0, 38.5616
27.254327300, 18.870, 1471.0, 38.3536
27.297793060, 18.870, 1461.0, 38.2230
27.341258820, 18.870, 1311.0, 36.2077
27.384724580, 18.870, 1235.0, 35.1426
27.428190340, 18.870, 1232.0, 35.0999
27.471656100, 18.870, 1205.0, 34.7131
27.515121860, 18.870, 1195.0, 34.5688
27.558587620, 18.870, 1257.0, 35.4542
27.602053380, 18.870, 1337.0, 36.5650
27.645519140, 18.870, 1289.0, 35.9026
27.688984900, 18.870, 1296.0, 36.0000
27.732450660, 18.870, 1210.0, 34.7851
27.775916420, 18.870, 1196.0, 34.5832
27.819382180, 18.870, 1136.0, 33.7046
27.862847940, 18.870, 1150.0, 33.9116
27.906313700, 18.870, 1062.0, 32.5883
27.949779460, 18.870, 1091.0, 33.0303
27.993245220, 18.870, 1060.0, 32.5576
28.036710980, 18.870, 1112.0, 33.3467
28.080176740, 18.870, 1096.0, 33.1059
28.123642500, 18.870, 1105.0, 33.2415
28.167108260, 18.870, 1096.0, 33.1059
28.210574020, 18.870, 1116.0, 33.4066
28.254039780, 18.870, 1107.0, 33.2716
28.297505540, 18.870, 1045.0, 32.3265
28.340971300, 18.870, 1064.0, 32.6190
28.384437060, 18.870, 1140.0, 33.7639
28.427902820, 18.870, 1122.0, 33.4963
28.471368580, 18.870, 1176.0, 34.2929
28.514834340, 18.870, 1169.0, 34.1906
28.558300100, 18.870, 1328.0, 36.4417
28.601765860, 18.870, 1245.0, 35.2846
28.645231620, 18.870, 1315.0, 36.2629
28.688697380, 18.870, 1276.0, 35.7211
28.732163140, 18.870, 1342.0, 36.6333
28.775628900, 18.870, 1332.0, 36.4966
28.819094660, 18.870, 1238.0, 35.1852
28.862560420, 18.870, 1201.0, 34.6554
28.906026180, 18.870, 1104.0, 33.2265
28.949491940, 18.870, 1142.0, 33.7935
28.992957700, 18.870, 1055.0, 32.4808
29.036423460, 18.870, 992.0, 31.4960
29.079889220, 18.870, 1069.0, 32.6956
29.123354980, 18.870, 1092.0, 33.0454
29.166820740, 18.870, 1057.0, 32.5115
29.210286500, 18.870, 1028.0, 32.0624
29.253752260, 18.870, 1052.0, 32.4345
29.297218020, 18.870, 941.0, 30.6757
29.340683780, 18.870, 966.0, 31.0805
29.384149540, 18.870, 901.0, 30.0167
29.427615300, 18.870, 887.0, 29.7825
29.471081060, 18.870, 830.0, 28.8097
29.514546820, 18.870, 849.0, 29.1376
29.558012580, 18.870, 816.0, 28.5657
29.601478340, 18.870, 843.0, 29.0345
29.644944100, 18.870, 826.0, 28.7402
29.688409860, 18.870, 910.0, 30.1662
29.731875620, 18.870, 910.0, 30.1662
29.775341380, 18.870, 918.0, 30.2985
29.818807140, 18.870, 970.0, 31.1448
29.862272900, 18.870, 997.0, 31.5753
29.905738660, 18.870, 1020.0, 31.9374
29.949204420, 18.870, 988.0, 31.4325
29.992670180, 18.870, 1028.0, 32.0624
30.036135940, 18.870, 1039.0, 32.2335
30.079601700, 18.870, 983.0, 31.3528
30.123067460, 18.870, 967.0, 31.0966
30.166533220, 18.870, 930.0, 30.4959
30.209998980, 18.870, 893.0, 29.8831
30.253464740, 18.870, 899.0, 29.9833
30.296930500, 18.870, 881.0, 29.6816
30.340396260, 18.870, 845.0, 29.0689
30.383862020, 18.870, 862.0, 29.3598
30.427327780, 18.870, 837.0, 28.9310
30.470793540, 18.870, 938.0, 30.6268
30.514259300, 18.870, 892.0, 29.8664
30.557725060, 18.870, 968.0, 31.1127
30.601190820, 18.870, 1008.0, 31.7490
30.644656580, 18.870, 937.0, 30.6105
30.688122340, 18.870, 1002.0, 31.6544
30.731588100, 18.870, 1026.0, 32.0312
30.775053860, 18.870, 1035.0, 32.1714
30.818519620, 18.870, 1099.0, 33.1512
30.861985380, 18.870, 1083.0, 32.9090
30.905451140, 18.870, 1095.0, 33.0908
30.948916900, 18.870, 1101.0, 33.1813
30.992382660, 18.870, 1016.0, 31.8748
31.035848420, 18.870, 1002.0, 31.6544
31.079314180, 18.870, 974.0, 31.2090
31.122779940, 18.870, 909.0, 30.1496
31.166245700, 18.870, 837.0, 28.9310
31.209711460, 18.870, 896.0, 29.9333
31.253177220, 18.870, 779.0, 27.9106
31.296642980, 18.870, 830.0, 28.8097
31.340108740, 18.870, 739.0, 27.1846
31.383574500, 18.870, 801.0, 28.3019
31.427040260, 18.870, 774.0, 27.8209
31.470506020, 18.870, 836.0, 28.9137
31.513971780, 18.870, 819.0, 28.6182
31.557437540, 18.870, 806.0, 28.3901
31.600903300, 18.870, 789.0, 28.0891
31.644369060, 18.870, 844.0, 29.0517
31.687834820, 18.870, 872.0, 29.5296
31.731300580, 18.870, 883.0, 29.7153
31.774766340, 18.870, 792.0, 28.1425
31.818232100, 18.870, 822.0, 28.6705
31.861697860, 18.870, 870.0, 29.4958
31.905163620, 18.870, 899.0, 29.9833
31.948629380, 18.870, 931.0, 30.5123
31.992095140, 18.870, 940.0, 30.6594
32.035560900, 18.870, 990.0, 31.4643
32.079026660, 18.870, 1017.0, 31.8904
32.122492420, 18.870, 1066.0, 32.6497
32.165958180, 18.870, 1027.0, 32.0468
32.209423940, 18.870, 982.0, 31.3369
32.252889700, 18.870, 983.0, 31.3528
32.296355460, 18.870, 948.0, 30.7896
32.339821220, 18.870, 901.0, 30.0167
32.383286980, 18.870, 930.0, 30.4959
32.426752740, 18.870, 895.0, 29.9166
32.470218500, 18.870, 814.0, 28.5307
32.513684260, 18.870, 900.0, 30.0000
32.557150020, 18.870, 931.0, 30.5123
32.600615780, 18.870, 999.0, 31.6070
32.644081540, 18.870, 957.0, 30.9354
32.687547300, 18.870, 981.0, 31.3209
32.731013060, 18.870, 1029.0, 32.0780
32.774478820, 18.870, 916.0, 30.2655
32.817944580, 18.870, 949.0, 30.8058
32.861410340, 18.870, 878.0, 29.6311
32.904876100, 18.870, 824.0, 28.7054
32.948341860, 18.870, 836.0, 28.9137
32.991807620, 18.870, 796.0, 28.2135
33.035273380, 18.870, 766.0, 27.6767
33.078739140, 18.870, 750.0, 27.3861
33.122204900, 18.870, 779.0, 27.9106
33.165670660, 18.870, 769.0, 27.7308
33.209136420, 18.870, 707.0, 26.5895
33.252602180, 18.870, 736.0, 27.1293
33.296067940, 18.870, 723.0, 26.8887
33.339533700, 18.870, 726.0, 26.9444
33.382999460, 18.870, 745.0, 27.2947
33.426465220, 18.870, 725.0, 26.9258
33.469930980, 18.870, 728.0, 26.9815
33.513396740, 18.870, 714.0, 26.7208
33.556862500, 18.870, 694.0, 26.3439
33.600328260, 18.870, 700.0, 26.4575
33.643794020, 18.870, 767.0, 27.6948
33.687259780, 18.870, 715.0, 26.7395
33.730725540, 18.870, 692.0, 26.3059
33.774191300, 18.870, 761.0, 27.5862
33.817657060, 18.870, 794.0, 28.1780
33.861122820, 18.870, 776.0, 27.8568
33.904588580, 18.870, 781.0, 27.9464
33.948054340, 18.870, 811.0, 28.4781
33.991520100, 18.870, 863.0, 29.3769
34.034985860, 18.870, 832.0, 28.8444
34.078451620, 18.870, 893.0, 29.8831
34.121917380, 18.870, 882.0, 29.6985
34.165383140, 18.870, 808.0, 28.4253
34.208848900, 18.870, 793.0, 28.1603
34.252314660, 18.870, 793.0, 28.1603
34.295780420, 18.870, 833.0, 28.8617
34.339246180, 18.870, 748.0, 27.3496
34.382711940, 18.870, 798.0, 28.2489
34.426177700, 18.870, 805.0, 28.3725
34.469643460, 18.870, 756.0, 27.4955
34.513109220, 18.870, 821.0, 28.6531
34.556574980, 18.870, 772.0, 27.7849
34.600040740, 18.870, 894.0, 29.8998
34.643506500, 18.870, 821.0, 28.6531
34.686972260, 18.870, 852.0, 29.1890
34.730438020, 18.870, 917.0, 30.2820
34.773903780, 18.870, 881.0, 29.6816
34.817369540, 18.870, 824.0, 28.7054
34.860835300, 18.870, 853.0, 29.2062
34.904301060, 18.870, 860.0, 29.3258
34.947766820, 18.870, 821.0, 28.6531
34.991232580, 18.870, 842.0, 29.0172
35.034698340, 18.870, 865.0, 29.4109
35.078164100, 18.870, 842.0, 29.0172
35.121629860, 18.870, 765.0, 27.6586
35.165095620, 18.870, 770.0, 27.7489
35.208561380, 18.870, 780.0, 27.9285
35.252027140, 18.870, 759.0, 27.5500
35.295492900, 18.870, 722.0, 26.8701
35.338958660, 18.870, 726.0, 26.9444
35.382424420, 18.870, 685.0, 26.1725
35.425890180, 18.870, 721.0, 26.8514
35.469355940, 18.870, 715.0, 26.7395
35.512821700, 18.870, 754.0, 27.4591
35.556287460, 18.870, 737.0, 27.1477
35.599753220, 18.870, 711.0, 26.6646
35.643218980, 18.870, 731.0, 27.0370
35.686684740, 18.870, 688.0, 26.2298
35.730150500, 18.870, 718.0, 26.7955
35.773616260, 18.870, 757.0, 27.5136
35.817082020, 18.870, 779.0, 27.9106
35.860547780, 18.870, 749.0, 27.3679
35.904013540, 18.870, 780.0, 27.9285
35.947479300, 18.870, 724.0, 26.9072
35.990945060, 18.870, 714.0, 26.7208
36.034410820, 18.870, 736.0, 27.1293
36.077876580, 18.870, 737.0, 27.1477
36.121342340, 18.870, 757.0, 27.5136
36.164808100, 18.870, 721.0, 26.8514
36.208273860, 18.870, 710.0, 26.6458
36.251739620, 18.870, 707.0, 26.5895
36.295205380, 18.870, 693.0, 26.3249
36.338671140, 18.870, 750.0, 27.3861
36.382136900, 18.870, 727.0, 26.9629
36.425602660, 18.870, 724.0, 26.9072
36.469068420, 18.870, 774.0, 27.8209
36.512534180, 18.870, 798.0, 28.2489
36.555999940, 18.870, 803.0, 28.3373
36.599465700, 18.870, 820.0, 28.6356
36.642931460, 18.870, 797.0, 28.2312
36.686397220, 18.870, 835.0, 28.8964
36.729862980, 18.870, 774.0, 27.8209
36.773328740, 18.870, 764.0, 27.6405
36.816794500, 18.870, 738.0, 27.1662
36.860260260, 18.870, 715.0, 26.7395
36.903726020, 18.870, 739.0, 27.1846
36.947191780, 18.870, 725.0, 26.9258
36.990657540, 18.870, 709.0, 26.6271
37.034123300, 18.870, 777.0, 27.8747
37.077589060, 18.870, 747.0, 27.3313
37.121054820, 18.870, 782.0, 27.9643
37.164520580, 18.870, 812.0, 28.4956
37.207986340, 18.870, 835.0, 28.8964
37.251452100, 18.870, 818.0, 28.6007
37.294917860, 18.870, 988.0, 31.4325
37.338383620, 18.870, 993.0, 31.5119
37.381849380, 18.870, 978.0, 31.2730
37.425315140, 18.870, 1015.0, 31.8591
37.468780900, 18.870, 1035.0, 32.1714
37.512246660, 18.870, 1026.0, 32.0312
37.555712420, 18.870, 976.0, 31.2410
37.599178180, 18.870, 943.0, 30.7083
37.642643940, 18.870, 860.0, 29.3258
37.686109700, 18.870, 878.0, 29.6311
37.729575460, 18.870, 842.0, 29.0172
37.773041220, 18.870, 801.0, 28.3019
37.816506980, 18.870, 812.0, 28.4956
37.859972740, 18.870, 804.0, 28.3549
37.903438500, 18.870, 843.0, 29.0345
37.946904260, 18.870, 830.0, 28.8097
37.990370020, 18.870, 919.0, 30.3150
38.033835780, 18.870, 815.0, 28.5482
38.077301540, 18.870, 860.0, 29.3258
38.120767300, 18.870, 882.0, 29.6985
38.164233060, 18.870, 883.0, 29.7153
38.207698820, 18.870, 909.0, 30.1496
38.251164580, 18.870, 836.0, 28.9137
38.294630340, 18.870, 905.0, 30.0832
38.338096100, 18.870, 894.0, 29.8998
38.381561860, 18.870, 824.0, 28.7054
38.425027620, 18.870, 776.0, 27.8568
38.468493380, 18.870, 841.0, 29.0000
38.511959140, 18.870, 804.0, 28.3549
38.555424900, 18.870, 740.0, 27.2029
38.598890660, 18.870, 735.0, 27.1109
38.642356420, 18.870, 764.0, 27.6405
38.685822180, 18.870, 695.0, 26.3629
38.729287940, 18.870, 751.0, 27.4044
38.772753700, 18.870, 758.0, 27.5318
38.816219460, 18.870, 745.0, 27.2947
38.859685220, 18.870, 721.0, 26.8514
38.903150980, 18.870, 715.0, 26.7395
38.946616740, 18.870, 705.0, 26.5518
38.990082500, 18.870, 740.0, 27.2029
39.033548260, 18.870, 653.0, 25.5539
39.077014020, 18.870, 659.0, 25.6710
39.120479780, 18.870, 690.0, 26.2679
39.163945540, 18.870, 658.0, 25.6515
39.207411300, 18.870, 697.0, 26.4008
39.250877060, 18.870, 655.0, 25.5930
39.294342820, 18.870, 667.0, 25.8263
39.337808580, 18.870, 709.0, 26.6271
39.381274340, 18.870, 662.0, 25.7294
39.424740100, 18.870, 688.0, 26.2298
39.468205860, 18.870, 671.0, 25.9037
39.511671620, 18.870, 679.0, 26.0576
39.555137380, 18.870, 656.0, 25.6125
39.598603140, 18.870, 747.0, 27.3313
39.642068900, 18.870, 678.0, 26.0384
39.685534660, 18.870, 741.0, 27.2213
39.729000420, 18.870, 676.0, 26.0000
39.772466180, 18.870, 730.0, 27.0185
39.815931940, 18.870, 727.0, 26.9629
39.859397700, 18.870, 665.0, 25.7876
39.902863460, 18.870, 696.0, 26.3818
39.946329220, 18.870, 717.0, 26.7769
39.989794980, 18.870, 736.0, 27.1293
40.033260740, 18.870, 696.0, 26.3818
40.076726500, 18.870, 752.0, 27.4226
40.120192260, 18.870, 726.0, 26.9444
40.163658020, 18.870, 732.0, 27.0555
40.207123780, 18.870, 685.0, 26.1725
40.250589540, 18.870, 756.0, 27.4955
40.294055300, 18.870, 721.0, 26.8514
40.337521060, 18.870, 729.0, 27.0000
40.380986820, 18.870, 728.0, 26.9815
40.424452580, 18.870, 729.0, 27.0000
40.467918340, 18.870, 713.0, 26.7021
40.511384100, 18.870, 768.0, 27.7128
40.554849860, 18.870, 732.0, 27.0555
40.598315620, 18.870, 677.0, 26.0192
40.641781380, 18.870, 710.0, 26.6458
40.685247140, 18.870, 668.0, 25.8457
40.728712900, 18.870, 713.0, 26.7021
40.772178660, 18.870, 739.0, 27.1846
40.815644420, 18.870, 741.0, 27.2213
40.859110180, 18.870, 707.0, 26.5895
40.902575940, 18.870, 733.0, 27.0740
40.946041700, 18.870, 797.0, 28.2312
40.989507460, 18.870, 730.0, 27.0185
41.032973220, 18.870, 712.0, 26.6833
41.076438980, 18.870, 735.0, 27.1109
41.119904740, 18.870, 738.0, 27.1662
41.163370500, 18.870, 688.0, 26.2298
41.206836260, 18.870, 711.0, 26.6646
41.250302020, 18.870, 690.0, 26.2679
41.293767780, 18.870, 686.0, 26.1916
41.337233540, 18.870, 728.0, 26.9815
41.380699300, 18.870, 689.0, 26.2488
41.424165060, 18.870, 721.0, 26.8514
41.467630820, 18.870, 758.0, 27.5318
41.511096580, 18.870, 677.0, 26.0192
41.554562340, 18.870, 716.0, 26.7582
41.598028100, 18.870, 761.0, 27.5862
41.641493860, 18.870, 721.0, 26.8514
41.684959620, 18.870, 765.0, 27.6586
41.728425380, 18.870, 794.0, 28.1780
41.771891140, 18.870, 758.0, 27.5318
41.815356900, 18.870, 710.0, 26.6458
41.858822660, 18.870, 788.0, 28.0713
41.902288420, 18.870, 755.0, 27.4773
41.945754180, 18.870, 690.0, 26.2679
41.989219940, 18.870, 753.0, 27.4408
42.032685700, 18.870, 744.0, 27.2764
42.076151460, 18.870, 719.0, 26.8142
42.119617220, 18.870, 726.0, 26.9444
42.163082980, 18.870, 739.0, 27.1846
42.206548740, 18.870, 741.0, 27.2213
42.250014500, 18.870, 787.0, 28.0535
42.293480260, 18.870, 796.0, 28.2135
42.336946020, 18.870, 792.0, 28.1425
42.380411780, 18.870, 781.0, 27.9464
42.423877540, 18.870, 753.0, 27.4408
42.467343300, 18.870, 749.0, 27.3679
42.510809060, 18.870, 748.0, 27.3496
42.554274820, 18.870, 732.0, 27.0555
42.597740580, 18.870, 770.0, 27.7489
42.641206340, 18.870, 715.0, 26.7395
42.684672100, 18.870, 747.0, 27.3313
42.728137860, 18.870, 718.0, 26.7955
42.771603620, 18.870, 759.0, 27.5500
42.815069380, 18.870, 707.0, 26.5895
42.858535140, 18.870, 670.0, 25.8844
42.902000900, 18.870, 740.0, 27.2029
42.945466660, 18.870, 770.0, 27.7489
42.988932420, 18.870, 720.0, 26.8328
43.032398180, 18.870, 715.0, 26.7395
43.075863940, 18.870, 733.0, 27.0740
43.119329700, 18.870, 694.0, 26.3439
43.162795460, 18.870, 712.0, 26.6833
43.206261220, 18.870, 647.0, 25.4362
43.249726980, 18.870, 624.0, 24.9800
43.293192740, 18.870, 675.0, 25.9808
43.336658500, 18.870, 666.0, 25.8070
43.380124260, 18.870, 663.0, 25.7488
43.423590020, 18.870, 641.0, 25.3180
43.467055780, 18.870, 653.0, 25.5539
43.510521540, 18.870, 663.0, 25.7488
43.553987300, 18.870, 604.0, 24.5764
43.597453060, 18.870, 648.0, 25.4558
43.640918820, 18.870, 622.0, 24.9399
43.684384580, 18.870, 601.0, 24.5153
43.727850340, 18.870, 630.0, 25.0998
43.771316100, 18.870, 597.0, 24.4336
43.814781860, 18.870, 606.0, 24.6171
43.858247620, 18.870, 637.0, 25.2389
43.901713380, 18.870, 592.0, 24.3311
43.945179140, 18.870, 653.0, 25.5539
43.988644900, 18.870, 647.0, 25.4362
44.032110660, 18.870, 554.0, 23.5372
44.075576420, 18.870, 621.0, 24.9199
44.119042180, 18.870, 629.0, 25.0799
44.162507940, 18.870, 608.0, 24.6577
44.205973700, 18.870, 654.0, 25.5734
44.249439460, 18.870, 650.0, 25.4951
44.292905220, 18.870, 661.0, 25.7099
44.336370980, 18.870, 652.0, 25.5343
44.379836740, 18.870, 625.0, 25.0000
44.423302500, 18.870, 661.0, 25.7099
44.466768260, 18.870, 632.0, 25.1396
44.510234020, 18.870, 657.0, 25.6320
44.553699780, 18.870, 638.0, 25.2587
44.597165540, 18.870, 635.0, 25.1992
44.640631300, 18.870, 651.0, 25.5147
44.684097060, 18.870, 606.0, 24.6171
44.727562820, 18.870, 595.0, 24.3926
44.771028580, 18.870, 666.0, 25.8070
44.814494340, 18.870, 616.0, 24.8193
44.857960100, 18.870, 614.0, 24.7790
44.901425860, 18.870, 648.0, 25.4558
44.944891620, 18.870, 615.0, 24.7992
44.988357380, 18.870, 660.0, 25.6905
45.031823140, 18.870, 648.0, 25.4558
45.075288900, 18.870, 575.0, 23.9792
45.118754660, 18.870, 623.0, 24.9600
45.162220420, 18.870, 576.0, 24.0000
45.205686180, 18.870, 598.0, 24.4540
45.249151940, 18.870, 562.0, 23.7065
45.292617700, 18.870, 583.0, 24.1454
45.336083460, 18.870, 623.0, 24.9600
45.379549220, 18.870, 563.0, 23.7276
45.423014980, 18.870, 563.0, 23.7276
45.466480740, 18.870, 597.0, 24.4336
45.509946500, 18.870, 590.0, 24.2899
45.553412260, 18.870, 666.0, 25.8070
45.596878020, 18.870, 622.0, 24.9399
45.640343780, 18.870, 655.0, 25.5930
45.683809540, 18.870, 631.0, 25.1197
45.727275300, 18.870, 590.0, 24.2899
45.770741060, 18.870, 577.0, 24.0208
45.814206820, 18.870, 593.0, 24.3516
45.857672580, 18.870, 600.0, 24.4949
45.901138340, 18.870, 573.0, 23.9374
45.944604100, 18.870, 632.0, 25.1396
45.988069860, 18.870, 561.0, 23.6854
46.031535620, 18.870, 603.0, 24.5561
46.075001380, 18.870, 570.0, 23.8747
46.118467140, 18.870, 592.0, 24.3311
46.161932900, 18.870, 546.0, 23.3666
46.205398660, 18.870, 555.0, 23.5584
46.248864420, 18.870, 575.0, 23.9792
46.292330180, 18.870, 557.0, 23.6008
46.335795940, 18.870, 552.0, 23.4947
46.379261700, 18.870, 585.0, 24.1868
46.422727460, 18.870, 555.0, 23.5584
46.466193220, 18.870, 561.0, 23.6854
46.509658980, 18.870, 573.0, 23.9374
46.553124740, 18.870, 550.0, 23.4521
46.596590500, 18.870, 555.0, 23.5584
46.640056260, 18.870, 520.0, 22.8035
46.683522020, 18.870, 541.0, 23.2594
46.726987780, 18.870, 583.0, 24.1454
46.770453540, 18.870, 554.0, 23.5372
46.813919300, 18.870, 542.0, 23.2809
46.857385060, 18.870, 543.0, 23.3024
46.900850820, 18.870, 590.0, 24.2899
46.944316580, 18.870, 584.0, 24.1661
46.987782340, 18.870, 542.0, 23.2809
47.031248100, 18.870, 565.0, 23.7697
47.074713860, 18.870, 581.0, 24.1039
47.118179620, 18.870, 615.0, 24.7992
47.161645380, 18.870, 553.0, 23.5160
47.205111140, 18.870, 559.0, 23.6432
47.248576900, 18.870, 551.0, 23.4734
47.292042660, 18.870, 613.0, 24.7588
47.335508420, 18.870, 538.0, 23.1948
47.378974180, 18.870, 596.0, 24.4131
47.422439940, 18.870, 555.0, 23.5584
47.465905700, 18.870, 543.0, 23.3024
47.509371460, 18.870, 542.0, 23.2809
47.552837220, 18.870, 550.0, 23.4521
47.596302980, 18.870, 549.0, 23.4307
47.639768740, 18.870, 519.0, 22.7816
47.683234500, 18.870, 534.0, 23.1084
47.726700260, 18.870, 539.0, 23.2164
47.770166020, 18.870, 531.0, 23.0434
47.813631780, 18.870, 524.0, 22.8910
47.857097540, 18.870, 507.0, 22.5167
47.900563300, 18.870, 552.0, 23.4947
47.944029060, 18.870, 501.0, 22.3830
47.987494820, 18.870, 468.0, 21.6333
48.030960580, 18.870, 516.0, 22.7156
48.074426340, 18.870, 517.0, 22.7376
48.117892100, 18.870, 486.0, 22.0454
48.161357860, 18.870, 463.0, 21.5174
48.204823620, 18.870, 518.0, 22.7596
48.248289380, 18.870, 542.0, 23.2809
48.291755140, 18.870, 502.0, 22.4054
48.335220900, 18.870, 506.0, 22.4944
48.378686660, 18.870, 541.0, 23.2594
48.422152420, 18.870, 549.0, 23.4307
48.465618180, 18.870, 518.0, 22.7596
48.509083940, 18.870, 580.0, 24.0832
48.552549700, 18.870, 515.0, 22.6936
48.596015460, 18.870, 520.0, 22.8035
48.639481220, 18.870, 507.0, 22.5167
48.682946980, 18.870, 508.0, 22.5389
48.726412740, 18.870, 485.0, 22.0227
48.769878500, 18.870, 511.0, 22.6053
48.813344260, 18.870, 519.0, 22.7816
48.856810020, 18.870, 510.0, 22.5832
48.900275780, 18.870, 488.0, 22.0907
48.943741540, 18.870, 503.0, 22.4277
48.987207300, 18.870, 532.0, 23.0651
49.030673060, 18.870, 511.0, 22.6053
49.074138820, 18.870, 516.0, 22.7156
49.117604580, 18.870, 511.0, 22.6053
49.161070340, 18.870, 511.0, 22.6053
49.204536100, 18.870, 505.0, 22.4722
49.248001860, 18.870, 533.0, 23.0868
49.291467620, 18.870, 501.0, 22.3830
49.334933380, 18.870, 508.0, 22.5389
49.378399140, 18.870, 512.0, 22.6274
49.421864900, 18.870, 473.0, 21.7486
49.465330660, 18.870, 472.0, 21.7256
49.508796420, 18.870, 466.0, 21.5870
49.552262180, 18.870, 524.0, 22.8910
49.595727940, 18.870, 473.0, 21.7486
49.639193700, 18.870, 483.0, 21.9773
49.682659460, 18.870, 504.0, 22.4499
49.726125220, 18.870, 483.0, 21.9773
49.769590980, 18.870, 498.0, 22.3159
49.813056740, 18.870, 499.0, 22.3383
49.856522500, 18.870, 485.0, 22.0227
49.899988260, 18.870, 479.0, 21.8861
49.943454020, 18.870, 457.0, 21.3776
49.986919780, 18.870, 476.0, 21.8174
50.030385540, 18.870, 486.0, 22.0454
50.073851300, 18.870, 506.0, 22.4944
50.117317060, 18.870, 508.0, 22.5389
50.160782820, 18.870, 494.0, 22.2261
50.204248580, 18.870, 523.0, 22.8692
50.247714340, 18.870, 481.0, 21.9317
50.291180100, 18.870, 453.0, 21.2838
50.334645860, 18.870, 500.0, 22.3607
50.378111620, 18.870, 465.0, 21.5639
50.421577380, 18.870, 472.0, 21.7256
50.465043140, 18.870, 502.0, 22.4054
50.508508900, 18.870, 474.0, 21.7715
50.551974660, 18.870, 475.0, 21.7945
50.595440420, 18.870, 467.0, 21.6102
50.638906180, 18.870, 447.0, 21.1424
50.682371940, 18.870, 468.0, 21.6333
50.725837700, 18.870, 497.0, 22.2935
50.769303460, 18.870, 465.0, 21.5639
50.812769220, 18.870, 478.0, 21.8632
50.856234980, 18.870, 463.0, 21.5174
50.899700740, 18.870, 488.0, 22.0907
50.943166500, 18.870, 471.0, 21.7025
50.986632260, 18.870, 496.0, 22.2711
51.030098020, 18.870, 511.0, 22.6053
51.073563780, 18.870, 549.0, 23.4307
51.117029540, 18.870, 463.0, 21.5174
51.160495300, 18.870, 486.0, 22.0454
51.203961060, 18.870, 443.0, 21.0476
51.247426820, 18.870, 454.0, 21.3073
51.290892580, 18.870, 455.0, 21.3307
51.334358340, 18.870, 469.0, 21.6564
51.377824100, 18.870, 467.0, 21.6102
51.421289860, 18.870, 444.0, 21.0713
51.464755620, 18.870, 500.0, 22.3607
51.508221380, 18.870, 491.0, 22.1585
51.551687140, 18.870, 495.0, 22.2486
51.595152900, 18.870, 499.0, 22.3383
51.638618660, 18.870, 473.0, 21.7486
51.682084420, 18.870, 473.0, 21.7486
51.725550180, 18.870, 481.0, 21.9317
51.769015940, 18.870, 449.0, 21.1896
51.812481700, 18.870, 440.0, 20.9762
51.855947460, 18.870, 490.0, 22.1359
51.899413220, 18.870, 440.0, 20.9762
51.942878980, 18.870, 435.0, 20.8567
51.986344740, 18.870, 476.0, 21.8174
52.029810500, 18.870, 461.0, 21.4709
52.073276260, 18.870, 462.0, 21.4942
52.116742020, 18.870, 431.0, 20.7605
52.160207780, 18.870, 445.0, 21.0950
52.203673540, 18.870, 423.0, 20.5670
52.247139300, 18.870, 452.0, 21.2603
52.290605060, 18.870, 415.0, 20.3715
52.334070820, 18.870, 437.0, 20.9045
52.377536580, 18.870, 430.0, 20.7364
52.421002340, 18.870, 438.0, 20.9284
52.464468100, 18.870, 437.0, 20.9045
52.507933860, 18.870, 466.0, 21.5870
52.551399620, 18.870, 443.0, 21.0476
52.594865380, 18.870, 429.0, 20.7123
52.638331140, 18.870, 438.0, 20.9284
52.681796900, 18.870, 432.0, 20.7846
52.725262660, 18.870, 442.0, 21.0238
52.768728420, 18.870, 424.0, 20.5913
52.812194180, 18.870, 454.0, 21.3073
52.855659940, 18.870, 433.0, 20.8087
52.899125700, 18.870, 456.0, 21.3542
52.942591460, 18.870, 420.0, 20.4939
52.986057220, 18.870, 432.0, 20.7846
53.029522980, 18.870, 405.0, 20.1246
53.072988740, 18.870, 448.0, 21.1660
53.116454500, 18.870, 426.0, 20.6398
53.159920260, 18.870, 438.0, 20.9284
53.203386020, 18.870, 467.0, 21.6102
53.246851780, 18.870, 459.0, 21.4243
53.290317540, 18.870, 437.0, 20.9045
53.333783300, 18.870, 400.0, 20.0000
53.377249060, 18.870, 427.0, 20.6640
53.420714820, 18.870, 428.0, 20.6882
53.464180580, 18.870, 395.0, 19.8746
53.507646340, 18.870, 405.0, 20.1246
53.551112100, 18.870, 429.0, 20.7123
53.594577860, 18.870, 410.0, 20.2485
53.638043620, 18.870, 385.0, 19.6214
53.681509380, 18.870, 413.0, 20.3224
53.724975140, 18.870, 393.0, 19.8242
53.768440900, 18.870, 408.0, 20.1990
53.811906660, 18.870, 383.0, 19.5704
53.855372420, 18.870, 404.0, 20.0998
53.898838180, 18.870, 441.0, 21.0000
53.942303940, 18.870, 445.0, 21.0950
53.985769700, 18.870, 366.0, 19.1311
54.029235460, 18.870, 435.0, 20.8567
54.072701220, 18.870, 391.0, 19.7737
54.116166980, 18.870, 423.0, 20.5670
54.159632740, 18.870, 422.0, 20.5426
54.203098500, 18.870, 415.0, 20.3715
54.246564260, 18.870, 415.0, 20.3715
54.290030020, 18.870, 412.0, 20.2978
54.333495780, 18.870, 398.0, 19.9499
54.376961540, 18.870, 461.0, 21.4709
54.420427300, 18.870, 420.0, 20.4939
54.463893060, 18.870, 484.0, 22.0000
54.507358820, 18.870, 427.0, 20.6640
54.550824580, 18.870, 401.0, 20.0250
54.594290340, 18.870, 432.0, 20.7846
54.637756100, 18.870, 401.0, 20.0250
54.681221860, 18.870, 429.0, 20.7123
54.724687620, 18.870, 409.0, 20.2237
54.768153380, 18.870, 399.0, 19.9750
54.811619140, 18.870, 359.0, 18.9473
54.855084900, 18.870, 411.0, 20.2731
54.898550660, 18.870, 403.0, 20.0749
54.942016420, 18.870, 361.0, 19.0000
54.985482180, 18.870, 431.0, 20.7605
55.028947940, 18.870, 368.0, 19.1833
55.072413700, 18.870, 373.0, 19.3132
55.115879460, 18.870, 398.0, 19.9499
55.159345220, 18.870, 401.0, 20.0250
55.202810980, 18.870, 391.0, 19.7737
55.246276740, 18.870, 388.0, 19.6977
55.289742500, 18.870, 374.0, 19.3391
55.333208260, 18.870, 380.0, 19.4936
55.376674020, 18.870, 399.0, 19.9750
55.420139780, 18.870, 399.0, 19.9750
55.463605540, 18.870, 352.0, 18.7617
55.507071300, 18.870, 391.0, 19.7737
55.550537060, 18.870, 352.0, 18.7617
55.594002820, 18.870, 381.0, 19.5192
55.637468580, 18.870, 436.0, 20.8806
55.680934340, 18.870, 435.0, 20.8567
55.724400100, 18.870, 389.0, 19.7231
55.767865860, 18.870, 352.0, 18.7617
55.811331620, 18.870, 419.0, 20.4695
55.854797380, 18.870, 398.0, 19.9499
55.898263140, 18.870, 403.0, 20.0749
55.941728900, 18.870, 411.0, 20.2731
55.985194660, 18.870, 394.0, 19.8494
56.028660420, 18.870, 447.0, 21.1424
56.072126180, 18.870, 397.0, 19.9249
56.115591940, 18.870, 399.0, 19.9750
56.159057700, 18.870, 391.0, 19.7737
56.202523460, 18.870, 413.0, 20.3224
56.245989220, 18.870, 395.0, 19.8746
56.289454980, 18.870, 364.0, 19.0788
56.332920740, 18.870, 372.0, 19.2873
56.376386500, 18.870, 379.0, 19.4679
56.419852260, 18.870, 377.0, 19.4165
56.463318020, 18.870, 358.0, 18.9209
56.506783780, 18.870, 410.0, 20.2485
56.550249540, 18.870, 397.0, 19.9249
56.593715300, 18.870, 366.0, 19.1311
56.637181060, 18.870, 364.0, 19.0788
56.680646820, 18.870, 377.0, 19.4165
56.724112580, 18.870, 376.0, 19.3907
56.767578340, 18.870, 359.0, 18.9473
56.811044100, 18.870, 363.0, 19.0526
56.854509860, 18.870, 396.0, 19.8997
56.897975620, 18.870, 366.0, 19.1311
56.941441380, 18.870, 358.0, 18.9209
56.984907140, 18.870, 336.0, 18.3303
57.028372900, 18.870, 394.0, 19.8494
57.071838660, 18.870, 331.0, 18.1934
57.115304420, 18.870, 327.0, 18.0831
57.158770180, 18.870, 339.0, 18.4120
57.202235940, 18.870, 385.0, 19.6214
57.245701700, 18.870, 359.0, 18.9473
57.289167460, 18.870, 325.0, 18.0278
57.332633220, 18.870, 339.0, 18.4120
57.376098980, 18.870, 364.0, 19.0788
57.419564740, 18.870, 321.0, 17.9165
57.463030500, 18.870, 331.0, 18.1934
57.506496260, 18.870, 352.0, 18.7617
57.549962020, 18.870, 361.0, 19.0000
57.593427780, 18.870, 355.0, 18.8414
57.636893540, 18.870, 340.0, 18.4391
57.680359300, 18.870, 334.0, 18.2757
57.723825060, 18.870, 330.0, 18.1659
57.767290820, 18.870, 301.0, 17.3494
57.810756580, 18.870, 341.0, 18.4662
57.854222340, 18.870, 345.0, 18.5742
57.897688100, 18.870, 344.0, 18.5472
57.941153860, 18.870, 347.0, 18.6279
57.984619620, 18.870, 340.0, 18.4391
58.028085380, 18.870, 315.0, 17.7482
58.071551140, 18.870, 330.0, 18.1659
58.115016900, 18.870, 353.0, 18.7883
58.158482660, 18.870, 343.0, 18.5203
58.201948420, 18.870, 322.0, 17.9444
58.245414180, 18.870, 336.0, 18.3303
58.288879940, 18.870, 341.0, 18.4662
58.332345700, 18.870, 334.0, 18.2757
58.375811460, 18.870, 334.0, 18.2757
58.419277220, 18.870, 343.0, 18.5203
58.462742980, 18.870, 287.0, 16.9411
58.506208740, 18.870, 333.0, 18.2483
58.549674500, 18.870, 354.0, 18.8149
58.593140260, 18.870, 297.0, 17.2337
58.636606020, 18.870, 340.0, 18.4391
58.680071780, 18.870, 319.0, 17.8606
58.723537540, 18.870, 348.0, 18.6548
58.767003300, 18.870, 315.0, 17.7482
58.810469060, 18.870, 332.0, 18.2209
58.853934820, 18.870, 313.0, 17.6918
58.897400580, 18.870, 312.0, 17.6635
58.940866340, 18.870, 340.0, 18.4391
58.984332100, 18.870, 357.0, 18.8944
59.027797860, 18.870, 309.0, 17.5784
59.071263620, 18.870, 301.0, 17.3494
59.114729380, 18.870, 305.0, 17.4642
59.158195140, 18.870, 312.0, 17.6635
59.201660900, 18.870, 335.0, 18.3030
59.245126660, 18.870, 335.0, 18.3030
59.288592420, 18.870, 339.0, 18.4120
59.332058180, 18.870, 311.0, 17.6352
59.375523940, 18.870, 305.0, 17.4642
59.418989700, 18.870, 302.0, 17.3781
59.462455460, 18.870, 319.0, 17.8606
59.505921220, 18.870, 328.0, 18.1108
59.549386980, 18.870, 335.0, 18.3030
59.592852740, 18.870, 336.0, 18.3303
59.636318500, 18.870, 322.0, 17.9444
59.679784260, 18.870, 303.0, 17.4069
59.723250020, 18.870, 312.0, 17.6635
59.766715780, 18.870, 300.0, 17.3205
59.810181540, 18.870, 329.0, 18.1384
59.853647300, 18.870, 302.0, 17.3781
59.897113060, 18.870, 297.0, 17.2337
59.940578820, 18.870, 259.0, 16.0935
59.984044580, 18.870, 297.0, 17.2337
59.994911020, 18.870, 308.0, 17.5499