File: XRD/2025_06_12_NIF_Xtal_DSC4_3_60_22m.csv
[Measurement conditions]
Sample identification,2025_06_12_NIF_Xtal_DSC4_3_60_22m
Comment - 1,"DSC #4 (A2 Tray), NIF crystallized at 140C in DSC."
Anode material,Cu
K-Alpha1 wavelength,1.5405980
K-Alpha2 wavelength,1.5444260
Ratio K-Alpha2/K-Alpha1,0.500
Divergence slit,Fixed,0.76mm
Monochromator used,NO
Generator voltage, 40
Tube current, 15
File date and time,12/Jun/2025 14:18
Unit cell,
h k l, 0 0 0
Scan axis,Gonio
Scan range,2.995000000,60.000344240
Scan step size,0.0108664
No. of points, 5246
Scan type,CONTINUOUS
Time per step,58.395
[Scan points]
Angle, TimePerStep, Intensity, ESD
3.000433220, 58.395, 127404.0, 356.9370
3.054765420, 58.395, 119550.0, 345.7600
3.109097620, 58.395, 113696.0, 337.1884
3.163429820, 58.395, 105556.0, 324.8938
3.217762020, 58.395, 98453.0, 313.7722
3.272094220, 58.395, 92141.0, 303.5474
3.326426420, 58.395, 85813.0, 292.9386
3.380758620, 58.395, 79692.0, 282.2977
3.435090820, 58.395, 73995.0, 272.0202
3.489423020, 58.395, 69217.0, 263.0912
3.543755220, 58.395, 64081.0, 253.1423
3.598087420, 58.395, 59215.0, 243.3413
3.652419620, 58.395, 54748.0, 233.9829
3.706751820, 58.395, 49986.0, 223.5755
3.761084020, 58.395, 46498.0, 215.6339
3.815416220, 58.395, 42147.0, 205.2973
3.869748420, 58.395, 38990.0, 197.4589
3.924080620, 58.395, 36032.0, 189.8210
3.978412820, 58.395, 32983.0, 181.6122
4.032745020, 58.395, 29946.0, 173.0491
4.087077220, 58.395, 27724.0, 166.5053
4.141409420, 58.395, 24904.0, 157.8100
4.195741620, 58.395, 22385.0, 149.6162
4.250073820, 58.395, 20544.0, 143.3318
4.304406020, 58.395, 18596.0, 136.3672
4.358738220, 58.395, 16925.0, 130.0961
4.413070420, 58.395, 15139.0, 123.0406
4.467402620, 58.395, 13706.0, 117.0726
4.521734820, 58.395, 12476.0, 111.6960
4.576067020, 58.395, 11242.0, 106.0283
4.630399220, 58.395, 10373.0, 101.8479
4.684731420, 58.395, 9300.0, 96.4365
4.739063620, 58.395, 8866.0, 94.1594
4.793395820, 58.395, 7899.0, 88.8763
4.847728020, 58.395, 7674.0, 87.6014
4.902060220, 58.395, 7174.0, 84.6995
4.956392420, 58.395, 7030.0, 83.8451
5.010724620, 58.395, 6651.0, 81.5537
5.065056820, 58.395, 6886.0, 82.9819
5.119389020, 58.395, 6771.0, 82.2861
5.173721220, 58.395, 6836.0, 82.6801
5.228053420, 58.395, 6759.0, 82.2131
5.282385620, 58.395, 7005.0, 83.6959
5.336717820, 58.395, 6572.0, 81.0679
5.391050020, 58.395, 6600.0, 81.2404
5.445382220, 58.395, 6038.0, 77.7046
5.499714420, 58.395, 5725.0, 75.6637
5.554046620, 58.395, 5174.0, 71.9305
5.608378820, 58.395, 4903.0, 70.0214
5.662711020, 58.395, 4423.0, 66.5056
5.717043220, 58.395, 4418.0, 66.4680
5.771375420, 58.395, 4166.0, 64.5446
5.825707620, 58.395, 3991.0, 63.1744
5.880039820, 58.395, 3856.0, 62.0967
5.934372020, 58.395, 3936.0, 62.7375
5.988704220, 58.395, 3775.0, 61.4410
6.043036420, 58.395, 3755.0, 61.2781
6.097368620, 58.395, 3546.0, 59.5483
6.151700820, 58.395, 3584.0, 59.8665
6.206033020, 58.395, 3492.0, 59.0931
6.260365220, 58.395, 3447.0, 58.7112
6.314697420, 58.395, 3350.0, 57.8792
6.369029620, 58.395, 3270.0, 57.1839
6.423361820, 58.395, 3047.0, 55.1996
6.477694020, 58.395, 3151.0, 56.1338
6.532026220, 58.395, 3007.0, 54.8361
6.586358420, 58.395, 3055.0, 55.2721
6.640690620, 58.395, 2949.0, 54.3047
6.695022820, 58.395, 3034.0, 55.0818
6.749355020, 58.395, 2847.0, 53.3573
6.803687220, 58.395, 2950.0, 54.3139
6.858019420, 58.395, 2671.0, 51.6817
6.912351620, 58.395, 2798.0, 52.8961
6.966683820, 58.395, 2598.0, 50.9706
7.021016020, 58.395, 2585.0, 50.8429
7.075348220, 58.395, 2466.0, 49.6588
7.129680420, 58.395, 2673.0, 51.7011
7.184012620, 58.395, 2496.0, 49.9600
7.238344820, 58.395, 2659.0, 51.5655
7.292677020, 58.395, 2605.0, 51.0392
7.347009220, 58.395, 2677.0, 51.7397
7.401341420, 58.395, 2832.0, 53.2165
7.455673620, 58.395, 2897.0, 53.8238
7.510005820, 58.395, 2948.0, 54.2955
7.564338020, 58.395, 3296.0, 57.4108
7.618670220, 58.395, 3458.0, 58.8048
7.673002420, 58.395, 3972.0, 63.0238
7.727334620, 58.395, 4437.0, 66.6108
7.781666820, 58.395, 5549.0, 74.4916
7.835999020, 58.395, 7059.0, 84.0179
7.890331220, 58.395, 9167.0, 95.7445
7.944663420, 58.395, 11149.0, 105.5888
7.998995620, 58.395, 15587.0, 124.8479
8.053327820, 58.395, 20228.0, 142.2252
8.107660020, 58.395, 20773.0, 144.1284
8.161992220, 58.395, 17902.0, 133.7984
8.216324420, 58.395, 15930.0, 126.2141
8.270656620, 58.395, 14443.0, 120.1790
8.324988820, 58.395, 9867.0, 99.3328
8.379321020, 58.395, 6962.0, 83.4386
8.433653220, 58.395, 4858.0, 69.6994
8.487985420, 58.395, 3322.0, 57.6368
8.542317620, 58.395, 3181.0, 56.4004
8.596649820, 58.395, 3192.0, 56.4978
8.650982020, 58.395, 3050.0, 55.2268
8.705314220, 58.395, 2547.0, 50.4678
8.759646420, 58.395, 2560.0, 50.5964
8.813978620, 58.395, 2444.0, 49.4368
8.868310820, 58.395, 2436.0, 49.3559
8.922643020, 58.395, 2416.0, 49.1528
8.976975220, 58.395, 2423.0, 49.2240
9.031307420, 58.395, 2376.0, 48.7442
9.085639620, 58.395, 2424.0, 49.2341
9.139971820, 58.395, 2401.0, 49.0000
9.194304020, 58.395, 2368.0, 48.6621
9.248636220, 58.395, 2430.0, 49.2950
9.302968420, 58.395, 2467.0, 49.6689
9.357300620, 58.395, 2419.0, 49.1833
9.411632820, 58.395, 2459.0, 49.5883
9.465965020, 58.395, 2445.0, 49.4469
9.520297220, 58.395, 2538.0, 50.3786
9.574629420, 58.395, 2536.0, 50.3587
9.628961620, 58.395, 2515.0, 50.1498
9.683293820, 58.395, 2583.0, 50.8232
9.737626020, 58.395, 2621.0, 51.1957
9.791958220, 58.395, 2704.0, 52.0000
9.846290420, 58.395, 2883.0, 53.6936
9.900622620, 58.395, 2973.0, 54.5252
9.954954820, 58.395, 3378.0, 58.1206
10.009287020, 58.395, 3681.0, 60.6712
10.063619220, 58.395, 4254.0, 65.2227
10.117951420, 58.395, 4960.0, 70.4273
10.172283620, 58.395, 6153.0, 78.4411
10.226615820, 58.395, 7961.0, 89.2244
10.280948020, 58.395, 11035.0, 105.0476
10.335280220, 58.395, 14167.0, 119.0252
10.389612420, 58.395, 18187.0, 134.8592
10.443944620, 58.395, 20100.0, 141.7745
10.498276820, 58.395, 18836.0, 137.2443
10.552609020, 58.395, 16633.0, 128.9690
10.606941220, 58.395, 15052.0, 122.6866
10.661273420, 58.395, 12617.0, 112.3254
10.715605620, 58.395, 10639.0, 103.1455
10.769937820, 58.395, 7104.0, 84.2852
10.824270020, 58.395, 5187.0, 72.0208
10.878602220, 58.395, 4585.0, 67.7126
10.932934420, 58.395, 3910.0, 62.5300
10.987266620, 58.395, 3351.0, 57.8878
11.041598820, 58.395, 3105.0, 55.7225
11.095931020, 58.395, 2867.0, 53.5444
11.150263220, 58.395, 3017.0, 54.9272
11.204595420, 58.395, 2986.0, 54.6443
11.258927620, 58.395, 3308.0, 57.5152
11.313259820, 58.395, 3412.0, 58.4123
11.367592020, 58.395, 4086.0, 63.9218
11.421924220, 58.395, 4590.0, 67.7495
11.476256420, 58.395, 5871.0, 76.6225
11.530588620, 58.395, 7414.0, 86.1046
11.584920820, 58.395, 11004.0, 104.9000
11.639253020, 58.395, 14997.0, 122.4622
11.693585220, 58.395, 19074.0, 138.1087
11.747917420, 58.395, 25240.0, 158.8710
11.802249620, 58.395, 33201.0, 182.2114
11.856581820, 58.395, 36434.0, 190.8769
11.910914020, 58.395, 41488.0, 203.6860
11.965246220, 58.395, 36885.0, 192.0547
12.019578420, 58.395, 31977.0, 178.8211
12.073910620, 58.395, 26461.0, 162.6684
12.128242820, 58.395, 20580.0, 143.4573
12.182575020, 58.395, 14190.0, 119.1218
12.236907220, 58.395, 8908.0, 94.3822
12.291239420, 58.395, 6742.0, 82.1097
12.345571620, 58.395, 5640.0, 75.0999
12.399903820, 58.395, 4510.0, 67.1565
12.454236020, 58.395, 4416.0, 66.4530
12.508568220, 58.395, 3844.0, 62.0000
12.562900420, 58.395, 3209.0, 56.6480
12.617232620, 58.395, 3081.0, 55.5068
12.671564820, 58.395, 3096.0, 55.6417
12.725897020, 58.395, 3084.0, 55.5338
12.780229220, 58.395, 3366.0, 58.0172
12.834561420, 58.395, 3944.0, 62.8013
12.888893620, 58.395, 4665.0, 68.3008
12.943225820, 58.395, 5318.0, 72.9246
12.997558020, 58.395, 5859.0, 76.5441
13.051890220, 58.395, 6055.0, 77.8139
13.106222420, 58.395, 5808.0, 76.2102
13.160554620, 58.395, 5160.0, 71.8331
13.214886820, 58.395, 4769.0, 69.0579
13.269219020, 58.395, 4539.0, 67.3721
13.323551220, 58.395, 4372.0, 66.1211
13.377883420, 58.395, 4086.0, 63.9218
13.432215620, 58.395, 3845.0, 62.0081
13.486547820, 58.395, 3858.0, 62.1128
13.540880020, 58.395, 3654.0, 60.4483
13.595212220, 58.395, 3301.0, 57.4543
13.649544420, 58.395, 3123.0, 55.8838
13.703876620, 58.395, 2810.0, 53.0094
13.758208820, 58.395, 2629.0, 51.2738
13.812541020, 58.395, 2604.0, 51.0294
13.866873220, 58.395, 2605.0, 51.0392
13.921205420, 58.395, 2560.0, 50.5964
13.975537620, 58.395, 2559.0, 50.5866
14.029869820, 58.395, 2502.0, 50.0200
14.084202020, 58.395, 2442.0, 49.4166
14.138534220, 58.395, 2478.0, 49.7795
14.192866420, 58.395, 2656.0, 51.5364
14.247198620, 58.395, 2636.0, 51.3420
14.301530820, 58.395, 2785.0, 52.7731
14.355863020, 58.395, 3149.0, 56.1160
14.410195220, 58.395, 3715.0, 60.9508
14.464527420, 58.395, 4263.0, 65.2917
14.518859620, 58.395, 5964.0, 77.2269
14.573191820, 58.395, 8038.0, 89.6549
14.627524020, 58.395, 10733.0, 103.6002
14.681856220, 58.395, 13409.0, 115.7972
14.736188420, 58.395, 14852.0, 121.8688
14.790520620, 58.395, 15682.0, 125.2278
14.844852820, 58.395, 14947.0, 122.2579
14.899185020, 58.395, 13347.0, 115.5292
14.953517220, 58.395, 12045.0, 109.7497
15.007849420, 58.395, 9706.0, 98.5190
15.062181620, 58.395, 6999.0, 83.6600
15.116513820, 58.395, 4495.0, 67.0448
15.170846020, 58.395, 3410.0, 58.3952
15.225178220, 58.395, 3036.0, 55.0999
15.279510420, 58.395, 3064.0, 55.3534
15.333842620, 58.395, 2699.0, 51.9519
15.388174820, 58.395, 2430.0, 49.2950
15.442507020, 58.395, 2311.0, 48.0729
15.496839220, 58.395, 2384.0, 48.8262
15.551171420, 58.395, 2404.0, 49.0306
15.605503620, 58.395, 2519.0, 50.1896
15.659835820, 58.395, 2537.0, 50.3686
15.714168020, 58.395, 2649.0, 51.4684
15.768500220, 58.395, 2906.0, 53.9073
15.822832420, 58.395, 3447.0, 58.7112
15.877164620, 58.395, 4177.0, 64.6297
15.931496820, 58.395, 5394.0, 73.4439
15.985829020, 58.395, 8132.0, 90.1776
16.040161220, 58.395, 12204.0, 110.4717
16.094493420, 58.395, 16057.0, 126.7162
16.148825620, 58.395, 19461.0, 139.5027
16.203157820, 58.395, 18601.0, 136.3855
16.257490020, 58.395, 16216.0, 127.3421
16.311822220, 58.395, 13176.0, 114.7868
16.366154420, 58.395, 11421.0, 106.8691
16.420486620, 58.395, 7710.0, 87.8066
16.474818820, 58.395, 6188.0, 78.6638
16.529151020, 58.395, 4436.0, 66.6033
16.583483220, 58.395, 3512.0, 59.2621
16.637815420, 58.395, 3304.0, 57.4804
16.692147620, 58.395, 3525.0, 59.3717
16.746479820, 58.395, 3553.0, 59.6070
16.800812020, 58.395, 3422.0, 58.4979
16.855144220, 58.395, 3795.0, 61.6036
16.909476420, 58.395, 4781.0, 69.1448
16.963808620, 58.395, 6507.0, 80.6660
17.018140820, 58.395, 8955.0, 94.6309
17.072473020, 58.395, 11199.0, 105.8253
17.126805220, 58.395, 11892.0, 109.0504
17.181137420, 58.395, 12114.0, 110.0636
17.235469620, 58.395, 11214.0, 105.8962
17.289801820, 58.395, 8972.0, 94.7206
17.344134020, 58.395, 7382.0, 85.9186
17.398466220, 58.395, 5680.0, 75.3658
17.452798420, 58.395, 4408.0, 66.3928
17.507130620, 58.395, 3466.0, 58.8727
17.561462820, 58.395, 3032.0, 55.0636
17.615795020, 58.395, 2524.0, 50.2394
17.670127220, 58.395, 2547.0, 50.4678
17.724459420, 58.395, 2457.0, 49.5681
17.778791620, 58.395, 2472.0, 49.7192
17.833123820, 58.395, 2473.0, 49.7293
17.887456020, 58.395, 2442.0, 49.4166
17.941788220, 58.395, 2392.0, 48.9081
17.996120420, 58.395, 2578.0, 50.7740
18.050452620, 58.395, 2758.0, 52.5167
18.104784820, 58.395, 3318.0, 57.6021
18.159117020, 58.395, 4308.0, 65.6354
18.213449220, 58.395, 5585.0, 74.7329
18.267781420, 58.395, 6310.0, 79.4355
18.322113620, 58.395, 6459.0, 80.3679
18.376445820, 58.395, 6117.0, 78.2113
18.430778020, 58.395, 6716.0, 81.9512
18.485110220, 58.395, 6856.0, 82.8010
18.539442420, 58.395, 5730.0, 75.6968
18.593774620, 58.395, 4832.0, 69.5126
18.648106820, 58.395, 4265.0, 65.3070
18.702439020, 58.395, 3753.0, 61.2617
18.756771220, 58.395, 3880.0, 62.2896
18.811103420, 58.395, 4818.0, 69.4118
18.865435620, 58.395, 6507.0, 80.6660
18.919767820, 58.395, 6952.0, 83.3787
18.974100020, 58.395, 7697.0, 87.7325
19.028432220, 58.395, 7802.0, 88.3289
19.082764420, 58.395, 7809.0, 88.3685
19.137096620, 58.395, 7680.0, 87.6356
19.191428820, 58.395, 7772.0, 88.1589
19.245761020, 58.395, 8052.0, 89.7329
19.300093220, 58.395, 7942.0, 89.1179
19.354425420, 58.395, 8781.0, 93.7070
19.408757620, 58.395, 11614.0, 107.7683
19.463089820, 58.395, 14432.0, 120.1333
19.517422020, 58.395, 17880.0, 133.7161
19.571754220, 58.395, 19634.0, 140.1214
19.626086420, 58.395, 23008.0, 151.6839
19.680418620, 58.395, 27845.0, 166.8682
19.734750820, 58.395, 27121.0, 164.6845
19.789083020, 58.395, 24159.0, 155.4317
19.843415220, 58.395, 24930.0, 157.8924
19.897747420, 58.395, 25960.0, 161.1211
19.952079620, 58.395, 24276.0, 155.8076
20.006411820, 58.395, 20134.0, 141.8943
20.060744020, 58.395, 15168.0, 123.1584
20.115076220, 58.395, 11072.0, 105.2236
20.169408420, 58.395, 8615.0, 92.8170
20.223740620, 58.395, 7539.0, 86.8274
20.278072820, 58.395, 6332.0, 79.5739
20.332405020, 58.395, 5527.0, 74.3438
20.386737220, 58.395, 4602.0, 67.8380
20.441069420, 58.395, 3810.0, 61.7252
20.495401620, 58.395, 3824.0, 61.8385
20.549733820, 58.395, 4072.0, 63.8122
20.604066020, 58.395, 4209.0, 64.8768
20.658398220, 58.395, 4590.0, 67.7495
20.712730420, 58.395, 5032.0, 70.9366
20.767062620, 58.395, 4541.0, 67.3869
20.821394820, 58.395, 4726.0, 68.7459
20.875727020, 58.395, 5408.0, 73.5391
20.930059220, 58.395, 5776.0, 76.0000
20.984391420, 58.395, 5506.0, 74.2024
21.038723620, 58.395, 6236.0, 78.9683
21.093055820, 58.395, 7506.0, 86.6372
21.147388020, 58.395, 7763.0, 88.1079
21.201720220, 58.395, 7455.0, 86.3423
21.256052420, 58.395, 6894.0, 83.0301
21.310384620, 58.395, 6013.0, 77.5435
21.364716820, 58.395, 6314.0, 79.4607
21.419049020, 58.395, 6451.0, 80.3181
21.473381220, 58.395, 6152.0, 78.4347
21.527713420, 58.395, 5471.0, 73.9662
21.582045620, 58.395, 5247.0, 72.4362
21.636377820, 58.395, 5300.0, 72.8011
21.690710020, 58.395, 6611.0, 81.3081
21.745042220, 58.395, 8996.0, 94.8472
21.799374420, 58.395, 11784.0, 108.5541
21.853706620, 58.395, 13275.0, 115.2172
21.908038820, 58.395, 12563.0, 112.0848
21.962371020, 58.395, 11513.0, 107.2986
22.016703220, 58.395, 11394.0, 106.7427
22.071035420, 58.395, 13633.0, 116.7604
22.125367620, 58.395, 13800.0, 117.4734
22.179699820, 58.395, 12506.0, 111.8302
22.234032020, 58.395, 12034.0, 109.6996
22.288364220, 58.395, 11537.0, 107.4104
22.342696420, 58.395, 12452.0, 111.5885
22.397028620, 58.395, 12007.0, 109.5765
22.451360820, 58.395, 11884.0, 109.0138
22.505693020, 58.395, 11599.0, 107.6987
22.560025220, 58.395, 13511.0, 116.2368
22.614357420, 58.395, 16518.0, 128.5224
22.668689620, 58.395, 17976.0, 134.0746
22.723021820, 58.395, 16752.0, 129.4295
22.777354020, 58.395, 18543.0, 136.1727
22.831686220, 58.395, 20242.0, 142.2744
22.886018420, 58.395, 19702.0, 140.3638
22.940350620, 58.395, 14310.0, 119.6244
22.994682820, 58.395, 9159.0, 95.7027
23.049015020, 58.395, 6770.0, 82.2800
23.103347220, 58.395, 5455.0, 73.8580
23.157679420, 58.395, 4587.0, 67.7274
23.212011620, 58.395, 4353.0, 65.9773
23.266343820, 58.395, 5040.0, 70.9930
23.320676020, 58.395, 4022.0, 63.4192
23.375008220, 58.395, 3244.0, 56.9561
23.429340420, 58.395, 3095.0, 55.6327
23.483672620, 58.395, 3051.0, 55.2359
23.538004820, 58.395, 3205.0, 56.6127
23.592337020, 58.395, 3384.0, 58.1722
23.646669220, 58.395, 3512.0, 59.2621
23.701001420, 58.395, 3843.0, 61.9919
23.755333620, 58.395, 3949.0, 62.8411
23.809665820, 58.395, 4109.0, 64.1015
23.863998020, 58.395, 4040.0, 63.5610
23.918330220, 58.395, 4273.0, 65.3682
23.972662420, 58.395, 5170.0, 71.9027
24.026994620, 58.395, 6035.0, 77.6853
24.081326820, 58.395, 7586.0, 87.0976
24.135659020, 58.395, 9812.0, 99.0555
24.189991220, 58.395, 11399.0, 106.7661
24.244323420, 58.395, 12155.0, 110.2497
24.298655620, 58.395, 14269.0, 119.4529
24.352987820, 58.395, 15273.0, 123.5840
24.407320020, 58.395, 14848.0, 121.8524
24.461652220, 58.395, 14799.0, 121.6511
24.515984420, 58.395, 16915.0, 130.0577
24.570316620, 58.395, 20367.0, 142.7130
24.624648820, 58.395, 23628.0, 153.7140
24.678981020, 58.395, 24179.0, 155.4960
24.733313220, 58.395, 21420.0, 146.3557
24.787645420, 58.395, 19954.0, 141.2586
24.841977620, 58.395, 22804.0, 151.0099
24.896309820, 58.395, 20220.0, 142.1970
24.950642020, 58.395, 17018.0, 130.4531
25.004974220, 58.395, 15379.0, 124.0121
25.059306420, 58.395, 13695.0, 117.0256
25.113638620, 58.395, 11744.0, 108.3697
25.167970820, 58.395, 9901.0, 99.5038
25.222303020, 58.395, 7512.0, 86.6718
25.276635220, 58.395, 6638.0, 81.4739
25.330967420, 58.395, 5796.0, 76.1315
25.385299620, 58.395, 5153.0, 71.7844
25.439631820, 58.395, 4351.0, 65.9621
25.493964020, 58.395, 4465.0, 66.8207
25.548296220, 58.395, 4914.0, 70.0999
25.602628420, 58.395, 6794.0, 82.4257
25.656960620, 58.395, 9159.0, 95.7027
25.711292820, 58.395, 12606.0, 112.2764
25.765625020, 58.395, 14566.0, 120.6897
25.819957220, 58.395, 18298.0, 135.2701
25.874289420, 58.395, 22093.0, 148.6371
25.928621620, 58.395, 19237.0, 138.6975
25.982953820, 58.395, 15085.0, 122.8210
26.037286020, 58.395, 12735.0, 112.8495
26.091618220, 58.395, 12630.0, 112.3833
26.145950420, 58.395, 12563.0, 112.0848
26.200282620, 58.395, 10708.0, 103.4795
26.254614820, 58.395, 9964.0, 99.8198
26.308947020, 58.395, 10628.0, 103.0922
26.363279220, 58.395, 11573.0, 107.5779
26.417611420, 58.395, 12273.0, 110.7836
26.471943620, 58.395, 13118.0, 114.5338
26.526275820, 58.395, 14048.0, 118.5243
26.580608020, 58.395, 13797.0, 117.4606
26.634940220, 58.395, 11444.0, 106.9766
26.689272420, 58.395, 10013.0, 100.0650
26.743604620, 58.395, 9896.0, 99.4786
26.797936820, 58.395, 11989.0, 109.4943
26.852269020, 58.395, 14471.0, 120.2955
26.906601220, 58.395, 17144.0, 130.9351
26.960933420, 58.395, 18043.0, 134.3242
27.015265620, 58.395, 18200.0, 134.9074
27.069597820, 58.395, 19344.0, 139.0827
27.123930020, 58.395, 16418.0, 128.1327
27.178262220, 58.395, 12695.0, 112.6721
27.232594420, 58.395, 10707.0, 103.4746
27.286926620, 58.395, 7161.0, 84.6227
27.341258820, 58.395, 5619.0, 74.9600
27.395591020, 58.395, 4346.0, 65.9242
27.449923220, 58.395, 3694.0, 60.7783
27.504255420, 58.395, 3642.0, 60.3490
27.558587620, 58.395, 3556.0, 59.6322
27.612919820, 58.395, 3991.0, 63.1744
27.667252020, 58.395, 4613.0, 67.9191
27.721584220, 58.395, 4776.0, 69.1086
27.775916420, 58.395, 5112.0, 71.4983
27.830248620, 58.395, 5788.0, 76.0789
27.884580820, 58.395, 6461.0, 80.3803
27.938913020, 58.395, 6437.0, 80.2309
27.993245220, 58.395, 6859.0, 82.8191
28.047577420, 58.395, 6179.0, 78.6066
28.101909620, 58.395, 5940.0, 77.0714
28.156241820, 58.395, 5298.0, 72.7874
28.210574020, 58.395, 5164.0, 71.8610
28.264906220, 58.395, 4711.0, 68.6367
28.319238420, 58.395, 4450.0, 66.7083
28.373570620, 58.395, 3994.0, 63.1981
28.427902820, 58.395, 3743.0, 61.1801
28.482235020, 58.395, 3781.0, 61.4898
28.536567220, 58.395, 4118.0, 64.1716
28.590899420, 58.395, 4147.0, 64.3972
28.645231620, 58.395, 3796.0, 61.6117
28.699563820, 58.395, 3584.0, 59.8665
28.753896020, 58.395, 3272.0, 57.2014
28.808228220, 58.395, 3079.0, 55.4887
28.862560420, 58.395, 2849.0, 53.3760
28.916892620, 58.395, 2906.0, 53.9073
28.971224820, 58.395, 3114.0, 55.8032
29.025557020, 58.395, 3295.0, 57.4021
29.079889220, 58.395, 3892.0, 62.3859
29.134221420, 58.395, 3865.0, 62.1691
29.188553620, 58.395, 3955.0, 62.8888
29.242885820, 58.395, 3557.0, 59.6406
29.297218020, 58.395, 3484.0, 59.0254
29.351550220, 58.395, 3283.0, 57.2975
29.405882420, 58.395, 3349.0, 57.8705
29.460214620, 58.395, 3764.0, 61.3514
29.514546820, 58.395, 4686.0, 68.4544
29.568879020, 58.395, 5184.0, 72.0000
29.623211220, 58.395, 5900.0, 76.8115
29.677543420, 58.395, 6135.0, 78.3262
29.731875620, 58.395, 6045.0, 77.7496
29.786207820, 58.395, 5504.0, 74.1889
29.840540020, 58.395, 5097.0, 71.3933
29.894872220, 58.395, 5092.0, 71.3583
29.949204420, 58.395, 4556.0, 67.4981
30.003536620, 58.395, 3982.0, 63.1031
30.057868820, 58.395, 3461.0, 58.8303
30.112201020, 58.395, 3187.0, 56.4535
30.166533220, 58.395, 3395.0, 58.2666
30.220865420, 58.395, 3404.0, 58.3438
30.275197620, 58.395, 3783.0, 61.5061
30.329529820, 58.395, 3674.0, 60.6135
30.383862020, 58.395, 3547.0, 59.5567
30.438194220, 58.395, 3707.0, 60.8851
30.492526420, 58.395, 3660.0, 60.4979
30.546858620, 58.395, 3502.0, 59.1777
30.601190820, 58.395, 3416.0, 58.4466
30.655523020, 58.395, 3271.0, 57.1927
30.709855220, 58.395, 3221.0, 56.7539
30.764187420, 58.395, 3176.0, 56.3560
30.818519620, 58.395, 3202.0, 56.5862
30.872851820, 58.395, 3236.0, 56.8859
30.927184020, 58.395, 3572.0, 59.7662
30.981516220, 58.395, 3763.0, 61.3433
31.035848420, 58.395, 4006.0, 63.2930
31.090180620, 58.395, 4250.0, 65.1920
31.144512820, 58.395, 4308.0, 65.6354
31.198845020, 58.395, 4309.0, 65.6430
31.253177220, 58.395, 4845.0, 69.6060
31.307509420, 58.395, 5446.0, 73.7970
31.361841620, 58.395, 5558.0, 74.5520
31.416173820, 58.395, 5986.0, 77.3692
31.470506020, 58.395, 5818.0, 76.2758
31.524838220, 58.395, 6094.0, 78.0641
31.579170420, 58.395, 6031.0, 77.6595
31.633502620, 58.395, 5782.0, 76.0395
31.687834820, 58.395, 5655.0, 75.1997
31.742167020, 58.395, 5903.0, 76.8310
31.796499220, 58.395, 5752.0, 75.8419
31.850831420, 58.395, 6018.0, 77.5758
31.905163620, 58.395, 6312.0, 79.4481
31.959495820, 58.395, 6003.0, 77.4790
32.013828020, 58.395, 6135.0, 78.3262
32.068160220, 58.395, 5705.0, 75.5315
32.122492420, 58.395, 4379.0, 66.1740
32.176824620, 58.395, 3831.0, 61.8951
32.231156820, 58.395, 4098.0, 64.0156
32.285489020, 58.395, 4265.0, 65.3070
32.339821220, 58.395, 4217.0, 64.9384
32.394153420, 58.395, 4059.0, 63.7103
32.448485620, 58.395, 3878.0, 62.2736
32.502817820, 58.395, 4082.0, 63.8905
32.557150020, 58.395, 4483.0, 66.9552
32.611482220, 58.395, 4827.0, 69.4766
32.665814420, 58.395, 5080.0, 71.2741
32.720146620, 58.395, 4847.0, 69.6204
32.774478820, 58.395, 5054.0, 71.0915
32.828811020, 58.395, 5116.0, 71.5262
32.883143220, 58.395, 5108.0, 71.4703
32.937475420, 58.395, 4955.0, 70.3918
32.991807620, 58.395, 4535.0, 67.3424
33.046139820, 58.395, 4428.0, 66.5432
33.100472020, 58.395, 4283.0, 65.4446
33.154804220, 58.395, 4187.0, 64.7070
33.209136420, 58.395, 4143.0, 64.3661
33.263468620, 58.395, 3905.0, 62.4900
33.317800820, 58.395, 3719.0, 60.9836
33.372133020, 58.395, 3603.0, 60.0250
33.426465220, 58.395, 3797.0, 61.6198
33.480797420, 58.395, 3901.0, 62.4580
33.535129620, 58.395, 3660.0, 60.4979
33.589461820, 58.395, 3207.0, 56.6304
33.643794020, 58.395, 2774.0, 52.6688
33.698126220, 58.395, 2427.0, 49.2646
33.752458420, 58.395, 2168.0, 46.5618
33.806790620, 58.395, 2066.0, 45.4533
33.861122820, 58.395, 2114.0, 45.9783
33.915455020, 58.395, 2049.0, 45.2659
33.969787220, 58.395, 1993.0, 44.6430
34.024119420, 58.395, 1961.0, 44.2832
34.078451620, 58.395, 1962.0, 44.2945
34.132783820, 58.395, 1994.0, 44.6542
34.187116020, 58.395, 2003.0, 44.7549
34.241448220, 58.395, 2059.0, 45.3762
34.295780420, 58.395, 2117.0, 46.0109
34.350112620, 58.395, 2184.0, 46.7333
34.404444820, 58.395, 2353.0, 48.5077
34.458777020, 58.395, 2385.0, 48.8365
34.513109220, 58.395, 2594.0, 50.9313
34.567441420, 58.395, 2694.0, 51.9038
34.621773620, 58.395, 2829.0, 53.1883
34.676105820, 58.395, 3039.0, 55.1271
34.730438020, 58.395, 3022.0, 54.9727
34.784770220, 58.395, 3065.0, 55.3624
34.839102420, 58.395, 2959.0, 54.3967
34.893434620, 58.395, 2745.0, 52.3927
34.947766820, 58.395, 2491.0, 49.9099
35.002099020, 58.395, 2431.0, 49.3052
35.056431220, 58.395, 2310.0, 48.0625
35.110763420, 58.395, 2277.0, 47.7179
35.165095620, 58.395, 2709.0, 52.0481
35.219427820, 58.395, 3163.0, 56.2406
35.273760020, 58.395, 3298.0, 57.4282
35.328092220, 58.395, 3348.0, 57.8619
35.382424420, 58.395, 3313.0, 57.5587
35.436756620, 58.395, 3296.0, 57.4108
35.491088820, 58.395, 3353.0, 57.9051
35.545421020, 58.395, 3479.0, 58.9830
35.599753220, 58.395, 3801.0, 61.6523
35.654085420, 58.395, 4578.0, 67.6609
35.708417620, 58.395, 4496.0, 67.0522
35.762749820, 58.395, 4308.0, 65.6354
35.817082020, 58.395, 5160.0, 71.8331
35.871414220, 58.395, 5401.0, 73.4915
35.925746420, 58.395, 5603.0, 74.8532
35.980078620, 58.395, 5151.0, 71.7705
36.034410820, 58.395, 4518.0, 67.2161
36.088743020, 58.395, 4148.0, 64.4050
36.143075220, 58.395, 3622.0, 60.1831
36.197407420, 58.395, 3799.0, 61.6360
36.251739620, 58.395, 3928.0, 62.6738
36.306071820, 58.395, 3863.0, 62.1530
36.360404020, 58.395, 3683.0, 60.6877
36.414736220, 58.395, 3346.0, 57.8446
36.469068420, 58.395, 3024.0, 54.9909
36.523400620, 58.395, 2652.0, 51.4976
36.577732820, 58.395, 2641.0, 51.3907
36.632065020, 58.395, 2449.0, 49.4874
36.686397220, 58.395, 2412.0, 49.1121
36.740729420, 58.395, 2527.0, 50.2693
36.795061620, 58.395, 2544.0, 50.4381
36.849393820, 58.395, 2640.0, 51.3809
36.903726020, 58.395, 2483.0, 49.8297
36.958058220, 58.395, 2465.0, 49.6488
37.012390420, 58.395, 2658.0, 51.5558
37.066722620, 58.395, 2679.0, 51.7591
37.121054820, 58.395, 2501.0, 50.0100
37.175387020, 58.395, 2530.0, 50.2991
37.229719220, 58.395, 2454.0, 49.5379
37.284051420, 58.395, 2515.0, 50.1498
37.338383620, 58.395, 2608.0, 51.0686
37.392715820, 58.395, 2838.0, 53.2729
37.447048020, 58.395, 2805.0, 52.9623
37.501380220, 58.395, 3430.0, 58.5662
37.555712420, 58.395, 3046.0, 55.1906
37.610044620, 58.395, 3048.0, 55.2087
37.664376820, 58.395, 2843.0, 53.3198
37.718709020, 58.395, 2862.0, 53.4977
37.773041220, 58.395, 3213.0, 56.6833
37.827373420, 58.395, 3645.0, 60.3738
37.881705620, 58.395, 4368.0, 66.0908
37.936037820, 58.395, 4442.0, 66.6483
37.990370020, 58.395, 4266.0, 65.3146
38.044702220, 58.395, 4085.0, 63.9140
38.099034420, 58.395, 3594.0, 59.9500
38.153366620, 58.395, 3510.0, 59.2453
38.207698820, 58.395, 2949.0, 54.3047
38.262031020, 58.395, 2699.0, 51.9519
38.316363220, 58.395, 2293.0, 47.8853
38.370695420, 58.395, 2295.0, 47.9062
38.425027620, 58.395, 2414.0, 49.1325
38.479359820, 58.395, 2482.0, 49.8197
38.533692020, 58.395, 2475.0, 49.7494
38.588024220, 58.395, 2963.0, 54.4334
38.642356420, 58.395, 3398.0, 58.2924
38.696688620, 58.395, 3745.0, 61.1964
38.751020820, 58.395, 4344.0, 65.9090
38.805353020, 58.395, 4577.0, 67.6535
38.859685220, 58.395, 4850.0, 69.6419
38.914017420, 58.395, 4782.0, 69.1520
38.968349620, 58.395, 4710.0, 68.6294
39.022681820, 58.395, 4294.0, 65.5286
39.077014020, 58.395, 3371.0, 58.0603
39.131346220, 58.395, 2833.0, 53.2259
39.185678420, 58.395, 2569.0, 50.6853
39.240010620, 58.395, 2763.0, 52.5642
39.294342820, 58.395, 3086.0, 55.5518
39.348675020, 58.395, 3275.0, 57.2276
39.403007220, 58.395, 3251.0, 57.0175
39.457339420, 58.395, 3430.0, 58.5662
39.511671620, 58.395, 3042.0, 55.1543
39.566003820, 58.395, 2876.0, 53.6284
39.620336020, 58.395, 2793.0, 52.8488
39.674668220, 58.395, 2654.0, 51.5170
39.729000420, 58.395, 2653.0, 51.5073
39.783332620, 58.395, 2551.0, 50.5074
39.837664820, 58.395, 2570.0, 50.6952
39.891997020, 58.395, 2512.0, 50.1199
39.946329220, 58.395, 2467.0, 49.6689
40.000661420, 58.395, 2459.0, 49.5883
40.054993620, 58.395, 2581.0, 50.8035
40.109325820, 58.395, 2776.0, 52.6878
40.163658020, 58.395, 2680.0, 51.7687
40.217990220, 58.395, 2785.0, 52.7731
40.272322420, 58.395, 2755.0, 52.4881
40.326654620, 58.395, 2839.0, 53.2823
40.380986820, 58.395, 2761.0, 52.5452
40.435319020, 58.395, 2748.0, 52.4214
40.489651220, 58.395, 2447.0, 49.4672
40.543983420, 58.395, 2453.0, 49.5278
40.598315620, 58.395, 2416.0, 49.1528
40.652647820, 58.395, 2481.0, 49.8096
40.706980020, 58.395, 2557.0, 50.5668
40.761312220, 58.395, 2820.0, 53.1037
40.815644420, 58.395, 2844.0, 53.3292
40.869976620, 58.395, 2783.0, 52.7541
40.924308820, 58.395, 2654.0, 51.5170
40.978641020, 58.395, 2426.0, 49.2544
41.032973220, 58.395, 2339.0, 48.3632
41.087305420, 58.395, 2263.0, 47.5710
41.141637620, 58.395, 2219.0, 47.1063
41.195969820, 58.395, 2132.0, 46.1736
41.250302020, 58.395, 2089.0, 45.7056
41.304634220, 58.395, 1971.0, 44.3959
41.358966420, 58.395, 1925.0, 43.8748
41.413298620, 58.395, 1914.0, 43.7493
41.467630820, 58.395, 1848.0, 42.9884
41.521963020, 58.395, 1898.0, 43.5660
41.576295220, 58.395, 1900.0, 43.5890
41.630627420, 58.395, 1949.0, 44.1475
41.684959620, 58.395, 2030.0, 45.0555
41.739291820, 58.395, 2259.0, 47.5289
41.793624020, 58.395, 2489.0, 49.8899
41.847956220, 58.395, 2634.0, 51.3225
41.902288420, 58.395, 2641.0, 51.3907
41.956620620, 58.395, 2902.0, 53.8702
42.010952820, 58.395, 3429.0, 58.5577
42.065285020, 58.395, 3574.0, 59.7829
42.119617220, 58.395, 3646.0, 60.3821
42.173949420, 58.395, 3698.0, 60.8112
42.228281620, 58.395, 3688.0, 60.7289
42.282613820, 58.395, 3901.0, 62.4580
42.336946020, 58.395, 4029.0, 63.4744
42.391278220, 58.395, 4396.0, 66.3023
42.445610420, 58.395, 3699.0, 60.8194
42.499942620, 58.395, 3435.0, 58.6089
42.554274820, 58.395, 2819.0, 53.0943
42.608607020, 58.395, 2667.0, 51.6430
42.662939220, 58.395, 2329.0, 48.2597
42.717271420, 58.395, 2397.0, 48.9592
42.771603620, 58.395, 2291.0, 47.8644
42.825935820, 58.395, 2529.0, 50.2892
42.880268020, 58.395, 2447.0, 49.4672
42.934600220, 58.395, 2599.0, 50.9804
42.988932420, 58.395, 2899.0, 53.8424
43.043264620, 58.395, 2887.0, 53.7308
43.097596820, 58.395, 2791.0, 52.8299
43.151929020, 58.395, 2743.0, 52.3737
43.206261220, 58.395, 2603.0, 51.0196
43.260593420, 58.395, 2768.0, 52.6118
43.314925620, 58.395, 2777.0, 52.6972
43.369257820, 58.395, 2848.0, 53.3667
43.423590020, 58.395, 2743.0, 52.3737
43.477922220, 58.395, 2651.0, 51.4879
43.532254420, 58.395, 2480.0, 49.7996
43.586586620, 58.395, 2536.0, 50.3587
43.640918820, 58.395, 2376.0, 48.7442
43.695251020, 58.395, 2344.0, 48.4149
43.749583220, 58.395, 2260.0, 47.5395
43.803915420, 58.395, 2171.0, 46.5940
43.858247620, 58.395, 2119.0, 46.0326
43.912579820, 58.395, 2229.0, 47.2123
43.966912020, 58.395, 2275.0, 47.6970
44.021244220, 58.395, 2453.0, 49.5278
44.075576420, 58.395, 2566.0, 50.6557
44.129908620, 58.395, 2859.0, 53.4696
44.184240820, 58.395, 3138.0, 56.0179
44.238573020, 58.395, 3544.0, 59.5315
44.292905220, 58.395, 3616.0, 60.1332
44.347237420, 58.395, 3651.0, 60.4235
44.401569620, 58.395, 3856.0, 62.0967
44.455901820, 58.395, 3473.0, 58.9322
44.510234020, 58.395, 3294.0, 57.3934
44.564566220, 58.395, 3618.0, 60.1498
44.618898420, 58.395, 3868.0, 62.1932
44.673230620, 58.395, 4256.0, 65.2380
44.727562820, 58.395, 4292.0, 65.5134
44.781895020, 58.395, 3718.0, 60.9754
44.836227220, 58.395, 3626.0, 60.2163
44.890559420, 58.395, 3498.0, 59.1439
44.944891620, 58.395, 3565.0, 59.7076
44.999223820, 58.395, 3020.0, 54.9545
45.053556020, 58.395, 2944.0, 54.2586
45.107888220, 58.395, 2574.0, 50.7346
45.162220420, 58.395, 2555.0, 50.5470
45.216552620, 58.395, 2601.0, 51.0000
45.270884820, 58.395, 2286.0, 47.8121
45.325217020, 58.395, 2373.0, 48.7134
45.379549220, 58.395, 2121.0, 46.0543
45.433881420, 58.395, 2121.0, 46.0543
45.488213620, 58.395, 1935.0, 43.9886
45.542545820, 58.395, 2037.0, 45.1331
45.596878020, 58.395, 1973.0, 44.4185
45.651210220, 58.395, 1996.0, 44.6766
45.705542420, 58.395, 1936.0, 44.0000
45.759874620, 58.395, 1983.0, 44.5309
45.814206820, 58.395, 2072.0, 45.5192
45.868539020, 58.395, 2135.0, 46.2061
45.922871220, 58.395, 2194.0, 46.8402
45.977203420, 58.395, 2288.0, 47.8330
46.031535620, 58.395, 2381.0, 48.7955
46.085867820, 58.395, 2589.0, 50.8822
46.140200020, 58.395, 2420.0, 49.1935
46.194532220, 58.395, 2404.0, 49.0306
46.248864420, 58.395, 2311.0, 48.0729
46.303196620, 58.395, 2851.0, 53.3948
46.357528820, 58.395, 2687.0, 51.8363
46.411861020, 58.395, 2619.0, 51.1762
46.466193220, 58.395, 2693.0, 51.8941
46.520525420, 58.395, 2624.0, 51.2250
46.574857620, 58.395, 2542.0, 50.4183
46.629189820, 58.395, 2210.0, 47.0106
46.683522020, 58.395, 2050.0, 45.2769
46.737854220, 58.395, 2096.0, 45.7821
46.792186420, 58.395, 1945.0, 44.1022
46.846518620, 58.395, 2150.0, 46.3681
46.900850820, 58.395, 2319.0, 48.1560
46.955183020, 58.395, 2411.0, 49.1019
47.009515220, 58.395, 2657.0, 51.5461
47.063847420, 58.395, 2887.0, 53.7308
47.118179620, 58.395, 2859.0, 53.4696
47.172511820, 58.395, 3129.0, 55.9375
47.226844020, 58.395, 3181.0, 56.4004
47.281176220, 58.395, 3114.0, 55.8032
47.335508420, 58.395, 2876.0, 53.6284
47.389840620, 58.395, 2800.0, 52.9150
47.444172820, 58.395, 2626.0, 51.2445
47.498505020, 58.395, 2526.0, 50.2593
47.552837220, 58.395, 2558.0, 50.5767
47.607169420, 58.395, 2740.0, 52.3450
47.661501620, 58.395, 2693.0, 51.8941
47.715833820, 58.395, 2698.0, 51.9423
47.770166020, 58.395, 2407.0, 49.0612
47.824498220, 58.395, 2467.0, 49.6689
47.878830420, 58.395, 2101.0, 45.8367
47.933162620, 58.395, 2046.0, 45.2327
47.987494820, 58.395, 2026.0, 45.0111
48.041827020, 58.395, 1954.0, 44.2041
48.096159220, 58.395, 1769.0, 42.0595
48.150491420, 58.395, 1942.0, 44.0681
48.204823620, 58.395, 1927.0, 43.8976
48.259155820, 58.395, 2247.0, 47.4025
48.313488020, 58.395, 2195.0, 46.8508
48.367820220, 58.395, 2360.0, 48.5798
48.422152420, 58.395, 2702.0, 51.9808
48.476484620, 58.395, 2829.0, 53.1883
48.530816820, 58.395, 2807.0, 52.9811
48.585149020, 58.395, 2744.0, 52.3832
48.639481220, 58.395, 2414.0, 49.1325
48.693813420, 58.395, 2289.0, 47.8435
48.748145620, 58.395, 2049.0, 45.2659
48.802477820, 58.395, 1887.0, 43.4396
48.856810020, 58.395, 1821.0, 42.6732
48.911142220, 58.395, 2006.0, 44.7884
48.965474420, 58.395, 2035.0, 45.1110
49.019806620, 58.395, 2254.0, 47.4763
49.074138820, 58.395, 2048.0, 45.2548
49.128471020, 58.395, 2254.0, 47.4763
49.182803220, 58.395, 2260.0, 47.5395
49.237135420, 58.395, 2200.0, 46.9042
49.291467620, 58.395, 2130.0, 46.1519
49.345799820, 58.395, 2197.0, 46.8722
49.400132020, 58.395, 2041.0, 45.1774
49.454464220, 58.395, 2119.0, 46.0326
49.508796420, 58.395, 2054.0, 45.3211
49.563128620, 58.395, 1984.0, 44.5421
49.617460820, 58.395, 1878.0, 43.3359
49.671793020, 58.395, 1829.0, 42.7668
49.726125220, 58.395, 1808.0, 42.5206
49.780457420, 58.395, 1800.0, 42.4264
49.834789620, 58.395, 1886.0, 43.4281
49.889121820, 58.395, 2047.0, 45.2438
49.943454020, 58.395, 2131.0, 46.1628
49.997786220, 58.395, 2415.0, 49.1426
50.052118420, 58.395, 2382.0, 48.8057
50.106450620, 58.395, 2405.0, 49.0408
50.160782820, 58.395, 2360.0, 48.5798
50.215115020, 58.395, 2470.0, 49.6991
50.269447220, 58.395, 2242.0, 47.3498
50.323779420, 58.395, 2119.0, 46.0326
50.378111620, 58.395, 2226.0, 47.1805
50.432443820, 58.395, 2296.0, 47.9166
50.486776020, 58.395, 2149.0, 46.3573
50.541108220, 58.395, 2126.0, 46.1086
50.595440420, 58.395, 2023.0, 44.9778
50.649772620, 58.395, 2027.0, 45.0222
50.704104820, 58.395, 1957.0, 44.2380
50.758437020, 58.395, 1920.0, 43.8178
50.812769220, 58.395, 1785.0, 42.2493
50.867101420, 58.395, 1765.0, 42.0119
50.921433620, 58.395, 1662.0, 40.7676
50.975765820, 58.395, 1745.0, 41.7732
51.030098020, 58.395, 1712.0, 41.3763
51.084430220, 58.395, 1823.0, 42.6966
51.138762420, 58.395, 1706.0, 41.3038
51.193094620, 58.395, 1700.0, 41.2311
51.247426820, 58.395, 1718.0, 41.4488
51.301759020, 58.395, 1732.0, 41.6173
51.356091220, 58.395, 1752.0, 41.8569
51.410423420, 58.395, 1684.0, 41.0366
51.464755620, 58.395, 1753.0, 41.8688
51.519087820, 58.395, 1800.0, 42.4264
51.573420020, 58.395, 1681.0, 41.0000
51.627752220, 58.395, 1775.0, 42.1307
51.682084420, 58.395, 1645.0, 40.5586
51.736416620, 58.395, 1659.0, 40.7308
51.790748820, 58.395, 1503.0, 38.7685
51.845081020, 58.395, 1627.0, 40.3361
51.899413220, 58.395, 1613.0, 40.1622
51.953745420, 58.395, 1731.0, 41.6053
52.008077620, 58.395, 1526.0, 39.0640
52.062409820, 58.395, 1625.0, 40.3113
52.116742020, 58.395, 1574.0, 39.6737
52.171074220, 58.395, 1545.0, 39.3065
52.225406420, 58.395, 1474.0, 38.3927
52.279738620, 58.395, 1467.0, 38.3014
52.334070820, 58.395, 1389.0, 37.2693
52.388403020, 58.395, 1442.0, 37.9737
52.442735220, 58.395, 1469.0, 38.3275
52.497067420, 58.395, 1507.0, 38.8201
52.551399620, 58.395, 1658.0, 40.7185
52.605731820, 58.395, 1798.0, 42.4028
52.660064020, 58.395, 1724.0, 41.5211
52.714396220, 58.395, 1780.0, 42.1900
52.768728420, 58.395, 1865.0, 43.1856
52.823060620, 58.395, 2050.0, 45.2769
52.877392820, 58.395, 2077.0, 45.5741
52.931725020, 58.395, 2035.0, 45.1110
52.986057220, 58.395, 2093.0, 45.7493
53.040389420, 58.395, 2149.0, 46.3573
53.094721620, 58.395, 1933.0, 43.9659
53.149053820, 58.395, 1937.0, 44.0114
53.203386020, 58.395, 1905.0, 43.6463
53.257718220, 58.395, 1870.0, 43.2435
53.312050420, 58.395, 1711.0, 41.3642
53.366382620, 58.395, 1781.0, 42.2019
53.420714820, 58.395, 1664.0, 40.7922
53.475047020, 58.395, 1589.0, 39.8623
53.529379220, 58.395, 1627.0, 40.3361
53.583711420, 58.395, 1688.0, 41.0853
53.638043620, 58.395, 1703.0, 41.2674
53.692375820, 58.395, 1760.0, 41.9524
53.746708020, 58.395, 1746.0, 41.7852
53.801040220, 58.395, 1748.0, 41.8091
53.855372420, 58.395, 1696.0, 41.1825
53.909704620, 58.395, 1744.0, 41.7612
53.964036820, 58.395, 1738.0, 41.6893
54.018369020, 58.395, 1767.0, 42.0357
54.072701220, 58.395, 1811.0, 42.5558
54.127033420, 58.395, 1678.0, 40.9634
54.181365620, 58.395, 1707.0, 41.3159
54.235697820, 58.395, 1698.0, 41.2068
54.290030020, 58.395, 1668.0, 40.8412
54.344362220, 58.395, 1722.0, 41.4970
54.398694420, 58.395, 1838.0, 42.8719
54.453026620, 58.395, 1866.0, 43.1972
54.507358820, 58.395, 1702.0, 41.2553
54.561691020, 58.395, 1795.0, 42.3674
54.616023220, 58.395, 1650.0, 40.6202
54.670355420, 58.395, 1616.0, 40.1995
54.724687620, 58.395, 1517.0, 38.9487
54.779019820, 58.395, 1641.0, 40.5093
54.833352020, 58.395, 1489.0, 38.5876
54.887684220, 58.395, 1462.0, 38.2361
54.942016420, 58.395, 1389.0, 37.2693
54.996348620, 58.395, 1401.0, 37.4299
55.050680820, 58.395, 1318.0, 36.3043
55.105013020, 58.395, 1378.0, 37.1214
55.159345220, 58.395, 1390.0, 37.2827
55.213677420, 58.395, 1525.0, 39.0512
55.268009620, 58.395, 1416.0, 37.6298
55.322341820, 58.395, 1459.0, 38.1969
55.376674020, 58.395, 1415.0, 37.6165
55.431006220, 58.395, 1517.0, 38.9487
55.485338420, 58.395, 1554.0, 39.4208
55.539670620, 58.395, 1697.0, 41.1947
55.594002820, 58.395, 1670.0, 40.8656
55.648335020, 58.395, 1679.0, 40.9756
55.702667220, 58.395, 1567.0, 39.5854
55.756999420, 58.395, 1645.0, 40.5586
55.811331620, 58.395, 1566.0, 39.5727
55.865663820, 58.395, 1573.0, 39.6611
55.919996020, 58.395, 1474.0, 38.3927
55.974328220, 58.395, 1469.0, 38.3275
56.028660420, 58.395, 1421.0, 37.6962
56.082992620, 58.395, 1515.0, 38.9230
56.137324820, 58.395, 1502.0, 38.7556
56.191657020, 58.395, 1480.0, 38.4708
56.245989220, 58.395, 1568.0, 39.5980
56.300321420, 58.395, 1709.0, 41.3401
56.354653620, 58.395, 1574.0, 39.6737
56.408985820, 58.395, 1623.0, 40.2865
56.463318020, 58.395, 1582.0, 39.7744
56.517650220, 58.395, 1563.0, 39.5348
56.571982420, 58.395, 1611.0, 40.1373
56.626314620, 58.395, 1575.0, 39.6863
56.680646820, 58.395, 1409.0, 37.5366
56.734979020, 58.395, 1466.0, 38.2884
56.789311220, 58.395, 1423.0, 37.7227
56.843643420, 58.395, 1373.0, 37.0540
56.897975620, 58.395, 1351.0, 36.7560
56.952307820, 58.395, 1414.0, 37.6032
57.006640020, 58.395, 1238.0, 35.1852
57.060972220, 58.395, 1339.0, 36.5923
57.115304420, 58.395, 1247.0, 35.3129
57.169636620, 58.395, 1312.0, 36.2215
57.223968820, 58.395, 1335.0, 36.5377
57.278301020, 58.395, 1417.0, 37.6431
57.332633220, 58.395, 1355.0, 36.8103
57.386965420, 58.395, 1489.0, 38.5876
57.441297620, 58.395, 1409.0, 37.5366
57.495629820, 58.395, 1497.0, 38.6911
57.549962020, 58.395, 1503.0, 38.7685
57.604294220, 58.395, 1611.0, 40.1373
57.658626420, 58.395, 1509.0, 38.8458
57.712958620, 58.395, 1505.0, 38.7943
57.767290820, 58.395, 1426.0, 37.7624
57.821623020, 58.395, 1448.0, 38.0526
57.875955220, 58.395, 1323.0, 36.3731
57.930287420, 58.395, 1464.0, 38.2623
57.984619620, 58.395, 1379.0, 37.1349
58.038951820, 58.395, 1361.0, 36.8917
58.093284020, 58.395, 1234.0, 35.1283
58.147616220, 58.395, 1301.0, 36.0694
58.201948420, 58.395, 1286.0, 35.8608
58.256280620, 58.395, 1337.0, 36.5650
58.310612820, 58.395, 1329.0, 36.4555
58.364945020, 58.395, 1347.0, 36.7015
58.419277220, 58.395, 1228.0, 35.0428
58.473609420, 58.395, 1284.0, 35.8329
58.527941620, 58.395, 1209.0, 34.7707
58.582273820, 58.395, 1209.0, 34.7707
58.636606020, 58.395, 1164.0, 34.1174
58.690938220, 58.395, 1159.0, 34.0441
58.745270420, 58.395, 1181.0, 34.3657
58.799602620, 58.395, 1181.0, 34.3657
58.853934820, 58.395, 1090.0, 33.0151
58.908267020, 58.395, 1101.0, 33.1813
58.962599220, 58.395, 1072.0, 32.7414
59.016931420, 58.395, 1145.0, 33.8378
59.071263620, 58.395, 1026.0, 32.0312
59.125595820, 58.395, 1179.0, 34.3366
59.179928020, 58.395, 1176.0, 34.2929
59.234260220, 58.395, 1163.0, 34.1028
59.288592420, 58.395, 1225.0, 35.0000
59.342924620, 58.395, 1248.0, 35.3270
59.397256820, 58.395, 1188.0, 34.4674
59.451589020, 58.395, 1192.0, 34.5254
59.505921220, 58.395, 1208.0, 34.7563
59.560253420, 58.395, 1228.0, 35.0428
59.614585620, 58.395, 1116.0, 33.4066
59.668917820, 58.395, 1220.0, 34.9285
59.723250020, 58.395, 1221.0, 34.9428
59.777582220, 58.395, 1161.0, 34.0735
59.831914420, 58.395, 1176.0, 34.2929
59.886246620, 58.395, 1178.0, 34.3220
59.940578820, 58.395, 1205.0, 34.7131
59.994911020, 58.395, 1193.0, 34.5398