File: XRD/2025_06_12_Ag_Behenate_3_60_8m_pXRD.csv
[Measurement conditions]
Sample identification,Silver_Behenate_3_60_8min_pXRD
Comment - 1,"Silver Behenate Standard."
Anode material,Cu
K-Alpha1 wavelength,1.5405980
K-Alpha2 wavelength,1.5444260
Ratio K-Alpha2/K-Alpha1,0.500
Divergence slit,Fixed,0.76mm
Monochromator used,NO
Generator voltage, 40
Tube current, 15
File date and time,12/Jun/2025 13:24
Unit cell,
h k l, 0 0 0
Scan axis,Gonio
Scan range,2.995000000,60.000344240
Scan step size,0.0108664
No. of points, 5246
Scan type,CONTINUOUS
Time per step,18.870
[Scan points]
Angle, TimePerStep, Intensity, ESD
3.000433220, 18.870, 43040.0, 207.4608
3.043898980, 18.870, 41128.0, 202.8004
3.087364740, 18.870, 39635.0, 199.0854
3.130830500, 18.870, 37433.0, 193.4761
3.174296260, 18.870, 35178.0, 187.5580
3.217762020, 18.870, 33631.0, 183.3876
3.261227780, 18.870, 31588.0, 177.7301
3.304693540, 18.870, 29853.0, 172.7802
3.348159300, 18.870, 27991.0, 167.3051
3.391625060, 18.870, 26433.0, 162.5823
3.435090820, 18.870, 24937.0, 157.9145
3.478556580, 18.870, 23438.0, 153.0947
3.522022340, 18.870, 22112.0, 148.7010
3.565488100, 18.870, 20884.0, 144.5130
3.608953860, 18.870, 19118.0, 138.2679
3.652419620, 18.870, 18291.0, 135.2442
3.695885380, 18.870, 17178.0, 131.0649
3.739351140, 18.870, 16041.0, 126.6531
3.782816900, 18.870, 14826.0, 121.7621
3.826282660, 18.870, 13771.0, 117.3499
3.869748420, 18.870, 13179.0, 114.7998
3.913214180, 18.870, 12172.0, 110.3268
3.956679940, 18.870, 11367.0, 106.6161
4.000145700, 18.870, 10565.0, 102.7862
4.043611460, 18.870, 9866.0, 99.3277
4.087077220, 18.870, 8854.0, 94.0957
4.130542980, 18.870, 8494.0, 92.1629
4.174008740, 18.870, 7906.0, 88.9157
4.217474500, 18.870, 7392.0, 85.9767
4.260940260, 18.870, 6979.0, 83.5404
4.304406020, 18.870, 6645.0, 81.5169
4.347871780, 18.870, 6050.0, 77.7817
4.391337540, 18.870, 5856.0, 76.5245
4.434803300, 18.870, 5761.0, 75.9013
4.478269060, 18.870, 5638.0, 75.0866
4.521734820, 18.870, 5494.0, 74.1215
4.565200580, 18.870, 4784.0, 69.1665
4.608666340, 18.870, 4201.0, 64.8151
4.652132100, 18.870, 3643.0, 60.3573
4.695597860, 18.870, 3229.0, 56.8243
4.739063620, 18.870, 2915.0, 53.9907
4.782529380, 18.870, 2674.0, 51.7107
4.825995140, 18.870, 2598.0, 50.9706
4.869460900, 18.870, 2361.0, 48.5901
4.912926660, 18.870, 2225.0, 47.1699
4.956392420, 18.870, 2250.0, 47.4342
4.999858180, 18.870, 2218.0, 47.0956
5.043323940, 18.870, 2166.0, 46.5403
5.086789700, 18.870, 2149.0, 46.3573
5.130255460, 18.870, 2114.0, 45.9783
5.173721220, 18.870, 2081.0, 45.6180
5.217186980, 18.870, 2125.0, 46.0977
5.260652740, 18.870, 2071.0, 45.5082
5.304118500, 18.870, 2026.0, 45.0111
5.347584260, 18.870, 2072.0, 45.5192
5.391050020, 18.870, 2116.0, 46.0000
5.434515780, 18.870, 1918.0, 43.7950
5.477981540, 18.870, 1841.0, 42.9069
5.521447300, 18.870, 1787.0, 42.2729
5.564913060, 18.870, 1580.0, 39.7492
5.608378820, 18.870, 1549.0, 39.3573
5.651844580, 18.870, 1561.0, 39.5095
5.695310340, 18.870, 1504.0, 38.7814
5.738776100, 18.870, 1536.0, 39.1918
5.782241860, 18.870, 1529.0, 39.1024
5.825707620, 18.870, 1638.0, 40.4722
5.869173380, 18.870, 1802.0, 42.4500
5.912639140, 18.870, 2028.0, 45.0333
5.956104900, 18.870, 2280.0, 47.7493
5.999570660, 18.870, 2366.0, 48.6415
6.043036420, 18.870, 2292.0, 47.8748
6.086502180, 18.870, 1717.0, 41.4367
6.129967940, 18.870, 1430.0, 37.8153
6.173433700, 18.870, 1178.0, 34.3220
6.216899460, 18.870, 992.0, 31.4960
6.260365220, 18.870, 962.0, 31.0161
6.303830980, 18.870, 866.0, 29.4279
6.347296740, 18.870, 847.0, 29.1033
6.390762500, 18.870, 882.0, 29.6985
6.434228260, 18.870, 797.0, 28.2312
6.477694020, 18.870, 782.0, 27.9643
6.521159780, 18.870, 772.0, 27.7849
6.564625540, 18.870, 731.0, 27.0370
6.608091300, 18.870, 777.0, 27.8747
6.651557060, 18.870, 718.0, 26.7955
6.695022820, 18.870, 717.0, 26.7769
6.738488580, 18.870, 674.0, 25.9615
6.781954340, 18.870, 677.0, 26.0192
6.825420100, 18.870, 652.0, 25.5343
6.868885860, 18.870, 629.0, 25.0799
6.912351620, 18.870, 649.0, 25.4755
6.955817380, 18.870, 603.0, 24.5561
6.999283140, 18.870, 674.0, 25.9615
7.042748900, 18.870, 668.0, 25.8457
7.086214660, 18.870, 667.0, 25.8263
7.129680420, 18.870, 713.0, 26.7021
7.173146180, 18.870, 743.0, 27.2580
7.216611940, 18.870, 852.0, 29.1890
7.260077700, 18.870, 844.0, 29.0517
7.303543460, 18.870, 1048.0, 32.3728
7.347009220, 18.870, 1124.0, 33.5261
7.390474980, 18.870, 1401.0, 37.4299
7.433940740, 18.870, 1640.0, 40.4969
7.477406500, 18.870, 1894.0, 43.5201
7.520872260, 18.870, 1926.0, 43.8862
7.564338020, 18.870, 1570.0, 39.6232
7.607803780, 18.870, 1127.0, 33.5708
7.651269540, 18.870, 855.0, 29.2404
7.694735300, 18.870, 627.0, 25.0400
7.738201060, 18.870, 468.0, 21.6333
7.781666820, 18.870, 462.0, 21.4942
7.825132580, 18.870, 393.0, 19.8242
7.868598340, 18.870, 391.0, 19.7737
7.912064100, 18.870, 421.0, 20.5183
7.955529860, 18.870, 374.0, 19.3391
7.998995620, 18.870, 420.0, 20.4939
8.042461380, 18.870, 354.0, 18.8149
8.085927140, 18.870, 366.0, 19.1311
8.129392900, 18.870, 335.0, 18.3030
8.172858660, 18.870, 345.0, 18.5742
8.216324420, 18.870, 305.0, 17.4642
8.259790180, 18.870, 343.0, 18.5203
8.303255940, 18.870, 357.0, 18.8944
8.346721700, 18.870, 383.0, 19.5704
8.390187460, 18.870, 353.0, 18.7883
8.433653220, 18.870, 342.0, 18.4932
8.477118980, 18.870, 334.0, 18.2757
8.520584740, 18.870, 373.0, 19.3132
8.564050500, 18.870, 415.0, 20.3715
8.607516260, 18.870, 388.0, 19.6977
8.650982020, 18.870, 403.0, 20.0749
8.694447780, 18.870, 403.0, 20.0749
8.737913540, 18.870, 435.0, 20.8567
8.781379300, 18.870, 496.0, 22.2711
8.824845060, 18.870, 558.0, 23.6220
8.868310820, 18.870, 658.0, 25.6515
8.911776580, 18.870, 776.0, 27.8568
8.955242340, 18.870, 874.0, 29.5635
8.998708100, 18.870, 942.0, 30.6920
9.042173860, 18.870, 1005.0, 31.7017
9.085639620, 18.870, 816.0, 28.5657
9.129105380, 18.870, 605.0, 24.5967
9.172571140, 18.870, 547.0, 23.3880
9.216036900, 18.870, 400.0, 20.0000
9.259502660, 18.870, 320.0, 17.8885
9.302968420, 18.870, 320.0, 17.8885
9.346434180, 18.870, 314.0, 17.7200
9.389899940, 18.870, 296.0, 17.2047
9.433365700, 18.870, 343.0, 18.5203
9.476831460, 18.870, 306.0, 17.4929
9.520297220, 18.870, 306.0, 17.4929
9.563762980, 18.870, 294.0, 17.1464
9.607228740, 18.870, 323.0, 17.9722
9.650694500, 18.870, 293.0, 17.1172
9.694160260, 18.870, 303.0, 17.4069
9.737626020, 18.870, 293.0, 17.1172
9.781091780, 18.870, 283.0, 16.8226
9.824557540, 18.870, 249.0, 15.7797
9.868023300, 18.870, 276.0, 16.6132
9.911489060, 18.870, 323.0, 17.9722
9.954954820, 18.870, 296.0, 17.2047
9.998420580, 18.870, 276.0, 16.6132
10.041886340, 18.870, 334.0, 18.2757
10.085352100, 18.870, 352.0, 18.7617
10.128817860, 18.870, 340.0, 18.4391
10.172283620, 18.870, 373.0, 19.3132
10.215749380, 18.870, 367.0, 19.1572
10.259215140, 18.870, 413.0, 20.3224
10.302680900, 18.870, 494.0, 22.2261
10.346146660, 18.870, 511.0, 22.6053
10.389612420, 18.870, 679.0, 26.0576
10.433078180, 18.870, 791.0, 28.1247
10.476543940, 18.870, 826.0, 28.7402
10.520009700, 18.870, 962.0, 31.0161
10.563475460, 18.870, 940.0, 30.6594
10.606941220, 18.870, 762.0, 27.6043
10.650406980, 18.870, 576.0, 24.0000
10.693872740, 18.870, 434.0, 20.8327
10.737338500, 18.870, 354.0, 18.8149
10.780804260, 18.870, 324.0, 18.0000
10.824270020, 18.870, 264.0, 16.2481
10.867735780, 18.870, 318.0, 17.8326
10.911201540, 18.870, 305.0, 17.4642
10.954667300, 18.870, 304.0, 17.4356
10.998133060, 18.870, 271.0, 16.4621
11.041598820, 18.870, 271.0, 16.4621
11.085064580, 18.870, 293.0, 17.1172
11.128530340, 18.870, 315.0, 17.7482
11.171996100, 18.870, 303.0, 17.4069
11.215461860, 18.870, 278.0, 16.6733
11.258927620, 18.870, 268.0, 16.3707
11.302393380, 18.870, 299.0, 17.2916
11.345859140, 18.870, 283.0, 16.8226
11.389324900, 18.870, 266.0, 16.3095
11.432790660, 18.870, 280.0, 16.7332
11.476256420, 18.870, 275.0, 16.5831
11.519722180, 18.870, 269.0, 16.4012
11.563187940, 18.870, 267.0, 16.3401
11.606653700, 18.870, 275.0, 16.5831
11.650119460, 18.870, 273.0, 16.5227
11.693585220, 18.870, 297.0, 17.2337
11.737050980, 18.870, 304.0, 17.4356
11.780516740, 18.870, 280.0, 16.7332
11.823982500, 18.870, 350.0, 18.7083
11.867448260, 18.870, 332.0, 18.2209
11.910914020, 18.870, 425.0, 20.6155
11.954379780, 18.870, 475.0, 21.7945
11.997845540, 18.870, 507.0, 22.5167
12.041311300, 18.870, 555.0, 23.5584
12.084777060, 18.870, 505.0, 22.4722
12.128242820, 18.870, 475.0, 21.7945
12.171708580, 18.870, 389.0, 19.7231
12.215174340, 18.870, 340.0, 18.4391
12.258640100, 18.870, 294.0, 17.1464
12.302105860, 18.870, 292.0, 17.0880
12.345571620, 18.870, 260.0, 16.1245
12.389037380, 18.870, 276.0, 16.6132
12.432503140, 18.870, 274.0, 16.5529
12.475968900, 18.870, 279.0, 16.7033
12.519434660, 18.870, 246.0, 15.6844
12.562900420, 18.870, 256.0, 16.0000
12.606366180, 18.870, 263.0, 16.2173
12.649831940, 18.870, 298.0, 17.2627
12.693297700, 18.870, 245.0, 15.6525
12.736763460, 18.870, 256.0, 16.0000
12.780229220, 18.870, 293.0, 17.1172
12.823694980, 18.870, 235.0, 15.3297
12.867160740, 18.870, 274.0, 16.5529
12.910626500, 18.870, 262.0, 16.1864
12.954092260, 18.870, 276.0, 16.6132
12.997558020, 18.870, 289.0, 17.0000
13.041023780, 18.870, 280.0, 16.7332
13.084489540, 18.870, 261.0, 16.1555
13.127955300, 18.870, 284.0, 16.8523
13.171421060, 18.870, 298.0, 17.2627
13.214886820, 18.870, 301.0, 17.3494
13.258352580, 18.870, 274.0, 16.5529
13.301818340, 18.870, 312.0, 17.6635
13.345284100, 18.870, 361.0, 19.0000
13.388749860, 18.870, 363.0, 19.0526
13.432215620, 18.870, 391.0, 19.7737
13.475681380, 18.870, 493.0, 22.2036
13.519147140, 18.870, 554.0, 23.5372
13.562612900, 18.870, 577.0, 24.0208
13.606078660, 18.870, 556.0, 23.5797
13.649544420, 18.870, 442.0, 21.0238
13.693010180, 18.870, 385.0, 19.6214
13.736475940, 18.870, 313.0, 17.6918
13.779941700, 18.870, 278.0, 16.6733
13.823407460, 18.870, 289.0, 17.0000
13.866873220, 18.870, 248.0, 15.7480
13.910338980, 18.870, 265.0, 16.2788
13.953804740, 18.870, 268.0, 16.3707
13.997270500, 18.870, 264.0, 16.2481
14.040736260, 18.870, 271.0, 16.4621
14.084202020, 18.870, 243.0, 15.5885
14.127667780, 18.870, 237.0, 15.3948
14.171133540, 18.870, 223.0, 14.9332
14.214599300, 18.870, 249.0, 15.7797
14.258065060, 18.870, 259.0, 16.0935
14.301530820, 18.870, 268.0, 16.3707
14.344996580, 18.870, 244.0, 15.6205
14.388462340, 18.870, 246.0, 15.6844
14.431928100, 18.870, 232.0, 15.2315
14.475393860, 18.870, 262.0, 16.1864
14.518859620, 18.870, 262.0, 16.1864
14.562325380, 18.870, 246.0, 15.6844
14.605791140, 18.870, 217.0, 14.7309
14.649256900, 18.870, 240.0, 15.4919
14.692722660, 18.870, 236.0, 15.3623
14.736188420, 18.870, 290.0, 17.0294
14.779654180, 18.870, 238.0, 15.4272
14.823119940, 18.870, 228.0, 15.0997
14.866585700, 18.870, 270.0, 16.4317
14.910051460, 18.870, 304.0, 17.4356
14.953517220, 18.870, 304.0, 17.4356
14.996982980, 18.870, 314.0, 17.7200
15.040448740, 18.870, 320.0, 17.8885
15.083914500, 18.870, 349.0, 18.6815
15.127380260, 18.870, 350.0, 18.7083
15.170846020, 18.870, 346.0, 18.6011
15.214311780, 18.870, 297.0, 17.2337
15.257777540, 18.870, 247.0, 15.7162
15.301243300, 18.870, 234.0, 15.2971
15.344709060, 18.870, 273.0, 16.5227
15.388174820, 18.870, 272.0, 16.4924
15.431640580, 18.870, 221.0, 14.8661
15.475106340, 18.870, 265.0, 16.2788
15.518572100, 18.870, 221.0, 14.8661
15.562037860, 18.870, 244.0, 15.6205
15.605503620, 18.870, 243.0, 15.5885
15.648969380, 18.870, 222.0, 14.8997
15.692435140, 18.870, 241.0, 15.5242
15.735900900, 18.870, 230.0, 15.1658
15.779366660, 18.870, 250.0, 15.8114
15.822832420, 18.870, 218.0, 14.7648
15.866298180, 18.870, 225.0, 15.0000
15.909763940, 18.870, 242.0, 15.5563
15.953229700, 18.870, 237.0, 15.3948
15.996695460, 18.870, 242.0, 15.5563
16.040161220, 18.870, 246.0, 15.6844
16.083626980, 18.870, 269.0, 16.4012
16.127092740, 18.870, 236.0, 15.3623
16.170558500, 18.870, 224.0, 14.9666
16.214024260, 18.870, 233.0, 15.2643
16.257490020, 18.870, 256.0, 16.0000
16.300955780, 18.870, 267.0, 16.3401
16.344421540, 18.870, 268.0, 16.3707
16.387887300, 18.870, 250.0, 15.8114
16.431353060, 18.870, 279.0, 16.7033
16.474818820, 18.870, 312.0, 17.6635
16.518284580, 18.870, 323.0, 17.9722
16.561750340, 18.870, 362.0, 19.0263
16.605216100, 18.870, 388.0, 19.6977
16.648681860, 18.870, 399.0, 19.9750
16.692147620, 18.870, 316.0, 17.7764
16.735613380, 18.870, 326.0, 18.0555
16.779079140, 18.870, 285.0, 16.8819
16.822544900, 18.870, 257.0, 16.0312
16.866010660, 18.870, 224.0, 14.9666
16.909476420, 18.870, 228.0, 15.0997
16.952942180, 18.870, 237.0, 15.3948
16.996407940, 18.870, 232.0, 15.2315
17.039873700, 18.870, 231.0, 15.1987
17.083339460, 18.870, 239.0, 15.4596
17.126805220, 18.870, 223.0, 14.9332
17.170270980, 18.870, 233.0, 15.2643
17.213736740, 18.870, 241.0, 15.5242
17.257202500, 18.870, 208.0, 14.4222
17.300668260, 18.870, 185.0, 13.6015
17.344134020, 18.870, 215.0, 14.6629
17.387599780, 18.870, 190.0, 13.7840
17.431065540, 18.870, 220.0, 14.8324
17.474531300, 18.870, 219.0, 14.7986
17.517997060, 18.870, 225.0, 15.0000
17.561462820, 18.870, 224.0, 14.9666
17.604928580, 18.870, 235.0, 15.3297
17.648394340, 18.870, 238.0, 15.4272
17.691860100, 18.870, 229.0, 15.1327
17.735325860, 18.870, 210.0, 14.4914
17.778791620, 18.870, 205.0, 14.3178
17.822257380, 18.870, 228.0, 15.0997
17.865723140, 18.870, 206.0, 14.3527
17.909188900, 18.870, 258.0, 16.0624
17.952654660, 18.870, 224.0, 14.9666
17.996120420, 18.870, 245.0, 15.6525
18.039586180, 18.870, 299.0, 17.2916
18.083051940, 18.870, 246.0, 15.6844
18.126517700, 18.870, 249.0, 15.7797
18.169983460, 18.870, 245.0, 15.6525
18.213449220, 18.870, 277.0, 16.6433
18.256914980, 18.870, 238.0, 15.4272
18.300380740, 18.870, 244.0, 15.6205
18.343846500, 18.870, 245.0, 15.6525
18.387312260, 18.870, 246.0, 15.6844
18.430778020, 18.870, 222.0, 14.8997
18.474243780, 18.870, 245.0, 15.6525
18.517709540, 18.870, 242.0, 15.5563
18.561175300, 18.870, 259.0, 16.0935
18.604641060, 18.870, 221.0, 14.8661
18.648106820, 18.870, 234.0, 15.2971
18.691572580, 18.870, 236.0, 15.3623
18.735038340, 18.870, 238.0, 15.4272
18.778504100, 18.870, 258.0, 16.0624
18.821969860, 18.870, 283.0, 16.8226
18.865435620, 18.870, 288.0, 16.9706
18.908901380, 18.870, 315.0, 17.7482
18.952367140, 18.870, 322.0, 17.9444
18.995832900, 18.870, 333.0, 18.2483
19.039298660, 18.870, 446.0, 21.1187
19.082764420, 18.870, 569.0, 23.8537
19.126230180, 18.870, 773.0, 27.8029
19.169695940, 18.870, 880.0, 29.6648
19.213161700, 18.870, 1028.0, 32.0624
19.256627460, 18.870, 969.0, 31.1288
19.300093220, 18.870, 967.0, 31.0966
19.343558980, 18.870, 837.0, 28.9310
19.387024740, 18.870, 962.0, 31.0161
19.430490500, 18.870, 929.0, 30.4795
19.473956260, 18.870, 935.0, 30.5778
19.517422020, 18.870, 854.0, 29.2233
19.560887780, 18.870, 654.0, 25.5734
19.604353540, 18.870, 535.0, 23.1301
19.647819300, 18.870, 465.0, 21.5639
19.691285060, 18.870, 402.0, 20.0499
19.734750820, 18.870, 375.0, 19.3649
19.778216580, 18.870, 390.0, 19.7484
19.821682340, 18.870, 335.0, 18.3030
19.865148100, 18.870, 280.0, 16.7332
19.908613860, 18.870, 288.0, 16.9706
19.952079620, 18.870, 257.0, 16.0312
19.995545380, 18.870, 299.0, 17.2916
20.039011140, 18.870, 282.0, 16.7929
20.082476900, 18.870, 282.0, 16.7929
20.125942660, 18.870, 320.0, 17.8885
20.169408420, 18.870, 248.0, 15.7480
20.212874180, 18.870, 302.0, 17.3781
20.256339940, 18.870, 304.0, 17.4356
20.299805700, 18.870, 290.0, 17.0294
20.343271460, 18.870, 295.0, 17.1756
20.386737220, 18.870, 295.0, 17.1756
20.430202980, 18.870, 246.0, 15.6844
20.473668740, 18.870, 285.0, 16.8819
20.517134500, 18.870, 280.0, 16.7332
20.560600260, 18.870, 318.0, 17.8326
20.604066020, 18.870, 315.0, 17.7482
20.647531780, 18.870, 330.0, 18.1659
20.690997540, 18.870, 327.0, 18.0831
20.734463300, 18.870, 345.0, 18.5742
20.777929060, 18.870, 273.0, 16.5227
20.821394820, 18.870, 266.0, 16.3095
20.864860580, 18.870, 259.0, 16.0935
20.908326340, 18.870, 290.0, 17.0294
20.951792100, 18.870, 262.0, 16.1864
20.995257860, 18.870, 283.0, 16.8226
21.038723620, 18.870, 273.0, 16.5227
21.082189380, 18.870, 268.0, 16.3707
21.125655140, 18.870, 294.0, 17.1464
21.169120900, 18.870, 307.0, 17.5214
21.212586660, 18.870, 295.0, 17.1756
21.256052420, 18.870, 278.0, 16.6733
21.299518180, 18.870, 287.0, 16.9411
21.342983940, 18.870, 257.0, 16.0312
21.386449700, 18.870, 289.0, 17.0000
21.429915460, 18.870, 236.0, 15.3623
21.473381220, 18.870, 286.0, 16.9115
21.516846980, 18.870, 294.0, 17.1464
21.560312740, 18.870, 261.0, 16.1555
21.603778500, 18.870, 284.0, 16.8523
21.647244260, 18.870, 276.0, 16.6132
21.690710020, 18.870, 297.0, 17.2337
21.734175780, 18.870, 311.0, 17.6352
21.777641540, 18.870, 315.0, 17.7482
21.821107300, 18.870, 344.0, 18.5472
21.864573060, 18.870, 355.0, 18.8414
21.908038820, 18.870, 339.0, 18.4120
21.951504580, 18.870, 354.0, 18.8149
21.994970340, 18.870, 334.0, 18.2757
22.038436100, 18.870, 385.0, 19.6214
22.081901860, 18.870, 401.0, 20.0250
22.125367620, 18.870, 374.0, 19.3391
22.168833380, 18.870, 385.0, 19.6214
22.212299140, 18.870, 371.0, 19.2614
22.255764900, 18.870, 403.0, 20.0749
22.299230660, 18.870, 353.0, 18.7883
22.342696420, 18.870, 327.0, 18.0831
22.386162180, 18.870, 388.0, 19.6977
22.429627940, 18.870, 355.0, 18.8414
22.473093700, 18.870, 425.0, 20.6155
22.516559460, 18.870, 416.0, 20.3961
22.560025220, 18.870, 422.0, 20.5426
22.603490980, 18.870, 491.0, 22.1585
22.646956740, 18.870, 506.0, 22.4944
22.690422500, 18.870, 508.0, 22.5389
22.733888260, 18.870, 542.0, 23.2809
22.777354020, 18.870, 568.0, 23.8328
22.820819780, 18.870, 582.0, 24.1247
22.864285540, 18.870, 656.0, 25.6125
22.907751300, 18.870, 713.0, 26.7021
22.951217060, 18.870, 784.0, 28.0000
22.994682820, 18.870, 894.0, 29.8998
23.038148580, 18.870, 1012.0, 31.8119
23.081614340, 18.870, 920.0, 30.3315
23.125080100, 18.870, 823.0, 28.6880
23.168545860, 18.870, 645.0, 25.3969
23.212011620, 18.870, 520.0, 22.8035
23.255477380, 18.870, 443.0, 21.0476
23.298943140, 18.870, 385.0, 19.6214
23.342408900, 18.870, 361.0, 19.0000
23.385874660, 18.870, 361.0, 19.0000
23.429340420, 18.870, 392.0, 19.7990
23.472806180, 18.870, 411.0, 20.2731
23.516271940, 18.870, 454.0, 21.3073
23.559737700, 18.870, 504.0, 22.4499
23.603203460, 18.870, 555.0, 23.5584
23.646669220, 18.870, 540.0, 23.2379
23.690134980, 18.870, 511.0, 22.6053
23.733600740, 18.870, 491.0, 22.1585
23.777066500, 18.870, 458.0, 21.4009
23.820532260, 18.870, 426.0, 20.6398
23.863998020, 18.870, 358.0, 18.9209
23.907463780, 18.870, 353.0, 18.7883
23.950929540, 18.870, 315.0, 17.7482
23.994395300, 18.870, 311.0, 17.6352
24.037861060, 18.870, 313.0, 17.6918
24.081326820, 18.870, 280.0, 16.7332
24.124792580, 18.870, 319.0, 17.8606
24.168258340, 18.870, 292.0, 17.0880
24.211724100, 18.870, 321.0, 17.9165
24.255189860, 18.870, 297.0, 17.2337
24.298655620, 18.870, 313.0, 17.6918
24.342121380, 18.870, 371.0, 19.2614
24.385587140, 18.870, 319.0, 17.8606
24.429052900, 18.870, 346.0, 18.6011
24.472518660, 18.870, 317.0, 17.8045
24.515984420, 18.870, 339.0, 18.4120
24.559450180, 18.870, 339.0, 18.4120
24.602915940, 18.870, 360.0, 18.9737
24.646381700, 18.870, 336.0, 18.3303
24.689847460, 18.870, 344.0, 18.5472
24.733313220, 18.870, 319.0, 17.8606
24.776778980, 18.870, 324.0, 18.0000
24.820244740, 18.870, 310.0, 17.6068
24.863710500, 18.870, 317.0, 17.8045
24.907176260, 18.870, 346.0, 18.6011
24.950642020, 18.870, 371.0, 19.2614
24.994107780, 18.870, 393.0, 19.8242
25.037573540, 18.870, 363.0, 19.0526
25.081039300, 18.870, 392.0, 19.7990
25.124505060, 18.870, 389.0, 19.7231
25.167970820, 18.870, 424.0, 20.5913
25.211436580, 18.870, 433.0, 20.8087
25.254902340, 18.870, 480.0, 21.9089
25.298368100, 18.870, 483.0, 21.9773
25.341833860, 18.870, 545.0, 23.3452
25.385299620, 18.870, 582.0, 24.1247
25.428765380, 18.870, 682.0, 26.1151
25.472231140, 18.870, 737.0, 27.1477
25.515696900, 18.870, 821.0, 28.6531
25.559162660, 18.870, 849.0, 29.1376
25.602628420, 18.870, 780.0, 27.9285
25.646094180, 18.870, 778.0, 27.8927
25.689559940, 18.870, 775.0, 27.8388
25.733025700, 18.870, 705.0, 26.5518
25.776491460, 18.870, 544.0, 23.3238
25.819957220, 18.870, 570.0, 23.8747
25.863422980, 18.870, 506.0, 22.4944
25.906888740, 18.870, 506.0, 22.4944
25.950354500, 18.870, 424.0, 20.5913
25.993820260, 18.870, 398.0, 19.9499
26.037286020, 18.870, 442.0, 21.0238
26.080751780, 18.870, 390.0, 19.7484
26.124217540, 18.870, 396.0, 19.8997
26.167683300, 18.870, 392.0, 19.7990
26.211149060, 18.870, 442.0, 21.0238
26.254614820, 18.870, 445.0, 21.0950
26.298080580, 18.870, 443.0, 21.0476
26.341546340, 18.870, 413.0, 20.3224
26.385012100, 18.870, 407.0, 20.1742
26.428477860, 18.870, 452.0, 21.2603
26.471943620, 18.870, 432.0, 20.7846
26.515409380, 18.870, 535.0, 23.1301
26.558875140, 18.870, 474.0, 21.7715
26.602340900, 18.870, 568.0, 23.8328
26.645806660, 18.870, 514.0, 22.6716
26.689272420, 18.870, 550.0, 23.4521
26.732738180, 18.870, 564.0, 23.7487
26.776203940, 18.870, 530.0, 23.0217
26.819669700, 18.870, 483.0, 21.9773
26.863135460, 18.870, 497.0, 22.2935
26.906601220, 18.870, 499.0, 22.3383
26.950066980, 18.870, 487.0, 22.0681
26.993532740, 18.870, 523.0, 22.8692
27.036998500, 18.870, 512.0, 22.6274
27.080464260, 18.870, 523.0, 22.8692
27.123930020, 18.870, 538.0, 23.1948
27.167395780, 18.870, 563.0, 23.7276
27.210861540, 18.870, 618.0, 24.8596
27.254327300, 18.870, 553.0, 23.5160
27.297793060, 18.870, 611.0, 24.7184
27.341258820, 18.870, 641.0, 25.3180
27.384724580, 18.870, 649.0, 25.4755
27.428190340, 18.870, 591.0, 24.3105
27.471656100, 18.870, 603.0, 24.5561
27.515121860, 18.870, 658.0, 25.6515
27.558587620, 18.870, 602.0, 24.5357
27.602053380, 18.870, 632.0, 25.1396
27.645519140, 18.870, 626.0, 25.0200
27.688984900, 18.870, 583.0, 24.1454
27.732450660, 18.870, 641.0, 25.3180
27.775916420, 18.870, 604.0, 24.5764
27.819382180, 18.870, 537.0, 23.1733
27.862847940, 18.870, 520.0, 22.8035
27.906313700, 18.870, 545.0, 23.3452
27.949779460, 18.870, 458.0, 21.4009
27.993245220, 18.870, 463.0, 21.5174
28.036710980, 18.870, 481.0, 21.9317
28.080176740, 18.870, 437.0, 20.9045
28.123642500, 18.870, 471.0, 21.7025
28.167108260, 18.870, 476.0, 21.8174
28.210574020, 18.870, 462.0, 21.4942
28.254039780, 18.870, 481.0, 21.9317
28.297505540, 18.870, 482.0, 21.9545
28.340971300, 18.870, 412.0, 20.2978
28.384437060, 18.870, 411.0, 20.2731
28.427902820, 18.870, 431.0, 20.7605
28.471368580, 18.870, 438.0, 20.9284
28.514834340, 18.870, 449.0, 21.1896
28.558300100, 18.870, 474.0, 21.7715
28.601765860, 18.870, 455.0, 21.3307
28.645231620, 18.870, 437.0, 20.9045
28.688697380, 18.870, 427.0, 20.6640
28.732163140, 18.870, 449.0, 21.1896
28.775628900, 18.870, 450.0, 21.2132
28.819094660, 18.870, 449.0, 21.1896
28.862560420, 18.870, 433.0, 20.8087
28.906026180, 18.870, 378.0, 19.4422
28.949491940, 18.870, 406.0, 20.1494
28.992957700, 18.870, 396.0, 19.8997
29.036423460, 18.870, 379.0, 19.4679
29.079889220, 18.870, 391.0, 19.7737
29.123354980, 18.870, 380.0, 19.4936
29.166820740, 18.870, 379.0, 19.4679
29.210286500, 18.870, 355.0, 18.8414
29.253752260, 18.870, 390.0, 19.7484
29.297218020, 18.870, 350.0, 18.7083
29.340683780, 18.870, 351.0, 18.7350
29.384149540, 18.870, 353.0, 18.7883
29.427615300, 18.870, 416.0, 20.3961
29.471081060, 18.870, 367.0, 19.1572
29.514546820, 18.870, 395.0, 19.8746
29.558012580, 18.870, 387.0, 19.6723
29.601478340, 18.870, 376.0, 19.3907
29.644944100, 18.870, 417.0, 20.4206
29.688409860, 18.870, 356.0, 18.8680
29.731875620, 18.870, 374.0, 19.3391
29.775341380, 18.870, 367.0, 19.1572
29.818807140, 18.870, 371.0, 19.2614
29.862272900, 18.870, 363.0, 19.0526
29.905738660, 18.870, 400.0, 20.0000
29.949204420, 18.870, 413.0, 20.3224
29.992670180, 18.870, 428.0, 20.6882
30.036135940, 18.870, 377.0, 19.4165
30.079601700, 18.870, 404.0, 20.0998
30.123067460, 18.870, 410.0, 20.2485
30.166533220, 18.870, 392.0, 19.7990
30.209998980, 18.870, 347.0, 18.6279
30.253464740, 18.870, 384.0, 19.5959
30.296930500, 18.870, 344.0, 18.5472
30.340396260, 18.870, 335.0, 18.3030
30.383862020, 18.870, 362.0, 19.0263
30.427327780, 18.870, 341.0, 18.4662
30.470793540, 18.870, 371.0, 19.2614
30.514259300, 18.870, 368.0, 19.1833
30.557725060, 18.870, 408.0, 20.1990
30.601190820, 18.870, 346.0, 18.6011
30.644656580, 18.870, 369.0, 19.2094
30.688122340, 18.870, 393.0, 19.8242
30.731588100, 18.870, 367.0, 19.1572
30.775053860, 18.870, 351.0, 18.7350
30.818519620, 18.870, 353.0, 18.7883
30.861985380, 18.870, 331.0, 18.1934
30.905451140, 18.870, 325.0, 18.0278
30.948916900, 18.870, 283.0, 16.8226
30.992382660, 18.870, 367.0, 19.1572
31.035848420, 18.870, 374.0, 19.3391
31.079314180, 18.870, 346.0, 18.6011
31.122779940, 18.870, 364.0, 19.0788
31.166245700, 18.870, 385.0, 19.6214
31.209711460, 18.870, 420.0, 20.4939
31.253177220, 18.870, 385.0, 19.6214
31.296642980, 18.870, 371.0, 19.2614
31.340108740, 18.870, 352.0, 18.7617
31.383574500, 18.870, 365.0, 19.1050
31.427040260, 18.870, 323.0, 17.9722
31.470506020, 18.870, 317.0, 17.8045
31.513971780, 18.870, 358.0, 18.9209
31.557437540, 18.870, 339.0, 18.4120
31.600903300, 18.870, 340.0, 18.4391
31.644369060, 18.870, 303.0, 17.4069
31.687834820, 18.870, 360.0, 18.9737
31.731300580, 18.870, 374.0, 19.3391
31.774766340, 18.870, 340.0, 18.4391
31.818232100, 18.870, 317.0, 17.8045
31.861697860, 18.870, 308.0, 17.5499
31.905163620, 18.870, 339.0, 18.4120
31.948629380, 18.870, 325.0, 18.0278
31.992095140, 18.870, 307.0, 17.5214
32.035560900, 18.870, 303.0, 17.4069
32.079026660, 18.870, 341.0, 18.4662
32.122492420, 18.870, 307.0, 17.5214
32.165958180, 18.870, 319.0, 17.8606
32.209423940, 18.870, 304.0, 17.4356
32.252889700, 18.870, 342.0, 18.4932
32.296355460, 18.870, 345.0, 18.5742
32.339821220, 18.870, 351.0, 18.7350
32.383286980, 18.870, 337.0, 18.3576
32.426752740, 18.870, 395.0, 19.8746
32.470218500, 18.870, 373.0, 19.3132
32.513684260, 18.870, 368.0, 19.1833
32.557150020, 18.870, 401.0, 20.0250
32.600615780, 18.870, 398.0, 19.9499
32.644081540, 18.870, 407.0, 20.1742
32.687547300, 18.870, 417.0, 20.4206
32.731013060, 18.870, 411.0, 20.2731
32.774478820, 18.870, 467.0, 21.6102
32.817944580, 18.870, 515.0, 22.6936
32.861410340, 18.870, 530.0, 23.0217
32.904876100, 18.870, 511.0, 22.6053
32.948341860, 18.870, 490.0, 22.1359
32.991807620, 18.870, 515.0, 22.6936
33.035273380, 18.870, 481.0, 21.9317
33.078739140, 18.870, 457.0, 21.3776
33.122204900, 18.870, 437.0, 20.9045
33.165670660, 18.870, 423.0, 20.5670
33.209136420, 18.870, 395.0, 19.8746
33.252602180, 18.870, 457.0, 21.3776
33.296067940, 18.870, 454.0, 21.3073
33.339533700, 18.870, 442.0, 21.0238
33.382999460, 18.870, 470.0, 21.6795
33.426465220, 18.870, 455.0, 21.3307
33.469930980, 18.870, 481.0, 21.9317
33.513396740, 18.870, 530.0, 23.0217
33.556862500, 18.870, 492.0, 22.1811
33.600328260, 18.870, 598.0, 24.4540
33.643794020, 18.870, 705.0, 26.5518
33.687259780, 18.870, 649.0, 25.4755
33.730725540, 18.870, 691.0, 26.2869
33.774191300, 18.870, 601.0, 24.5153
33.817657060, 18.870, 596.0, 24.4131
33.861122820, 18.870, 503.0, 22.4277
33.904588580, 18.870, 485.0, 22.0227
33.948054340, 18.870, 462.0, 21.4942
33.991520100, 18.870, 461.0, 21.4709
34.034985860, 18.870, 414.0, 20.3470
34.078451620, 18.870, 422.0, 20.5426
34.121917380, 18.870, 389.0, 19.7231
34.165383140, 18.870, 383.0, 19.5704
34.208848900, 18.870, 375.0, 19.3649
34.252314660, 18.870, 375.0, 19.3649
34.295780420, 18.870, 302.0, 17.3781
34.339246180, 18.870, 358.0, 18.9209
34.382711940, 18.870, 367.0, 19.1572
34.426177700, 18.870, 351.0, 18.7350
34.469643460, 18.870, 345.0, 18.5742
34.513109220, 18.870, 362.0, 19.0263
34.556574980, 18.870, 345.0, 18.5742
34.600040740, 18.870, 374.0, 19.3391
34.643506500, 18.870, 367.0, 19.1572
34.686972260, 18.870, 331.0, 18.1934
34.730438020, 18.870, 386.0, 19.6469
34.773903780, 18.870, 331.0, 18.1934
34.817369540, 18.870, 360.0, 18.9737
34.860835300, 18.870, 369.0, 19.2094
34.904301060, 18.870, 374.0, 19.3391
34.947766820, 18.870, 379.0, 19.4679
34.991232580, 18.870, 389.0, 19.7231
35.034698340, 18.870, 421.0, 20.5183
35.078164100, 18.870, 438.0, 20.9284
35.121629860, 18.870, 402.0, 20.0499
35.165095620, 18.870, 412.0, 20.2978
35.208561380, 18.870, 435.0, 20.8567
35.252027140, 18.870, 411.0, 20.2731
35.295492900, 18.870, 394.0, 19.8494
35.338958660, 18.870, 368.0, 19.1833
35.382424420, 18.870, 355.0, 18.8414
35.425890180, 18.870, 365.0, 19.1050
35.469355940, 18.870, 375.0, 19.3649
35.512821700, 18.870, 350.0, 18.7083
35.556287460, 18.870, 339.0, 18.4120
35.599753220, 18.870, 357.0, 18.8944
35.643218980, 18.870, 370.0, 19.2354
35.686684740, 18.870, 370.0, 19.2354
35.730150500, 18.870, 345.0, 18.5742
35.773616260, 18.870, 313.0, 17.6918
35.817082020, 18.870, 338.0, 18.3848
35.860547780, 18.870, 314.0, 17.7200
35.904013540, 18.870, 322.0, 17.9444
35.947479300, 18.870, 304.0, 17.4356
35.990945060, 18.870, 273.0, 16.5227
36.034410820, 18.870, 322.0, 17.9444
36.077876580, 18.870, 286.0, 16.9115
36.121342340, 18.870, 330.0, 18.1659
36.164808100, 18.870, 331.0, 18.1934
36.208273860, 18.870, 370.0, 19.2354
36.251739620, 18.870, 378.0, 19.4422
36.295205380, 18.870, 396.0, 19.8997
36.338671140, 18.870, 412.0, 20.2978
36.382136900, 18.870, 392.0, 19.7990
36.425602660, 18.870, 391.0, 19.7737
36.469068420, 18.870, 401.0, 20.0250
36.512534180, 18.870, 353.0, 18.7883
36.555999940, 18.870, 360.0, 18.9737
36.599465700, 18.870, 335.0, 18.3030
36.642931460, 18.870, 383.0, 19.5704
36.686397220, 18.870, 359.0, 18.9473
36.729862980, 18.870, 328.0, 18.1108
36.773328740, 18.870, 332.0, 18.2209
36.816794500, 18.870, 248.0, 15.7480
36.860260260, 18.870, 317.0, 17.8045
36.903726020, 18.870, 308.0, 17.5499
36.947191780, 18.870, 323.0, 17.9722
36.990657540, 18.870, 331.0, 18.1934
37.034123300, 18.870, 334.0, 18.2757
37.077589060, 18.870, 333.0, 18.2483
37.121054820, 18.870, 336.0, 18.3303
37.164520580, 18.870, 279.0, 16.7033
37.207986340, 18.870, 304.0, 17.4356
37.251452100, 18.870, 298.0, 17.2627
37.294917860, 18.870, 298.0, 17.2627
37.338383620, 18.870, 283.0, 16.8226
37.381849380, 18.870, 307.0, 17.5214
37.425315140, 18.870, 315.0, 17.7482
37.468780900, 18.870, 327.0, 18.0831
37.512246660, 18.870, 285.0, 16.8819
37.555712420, 18.870, 330.0, 18.1659
37.599178180, 18.870, 333.0, 18.2483
37.642643940, 18.870, 357.0, 18.8944
37.686109700, 18.870, 367.0, 19.1572
37.729575460, 18.870, 404.0, 20.0998
37.773041220, 18.870, 415.0, 20.3715
37.816506980, 18.870, 393.0, 19.8242
37.859972740, 18.870, 408.0, 20.1990
37.903438500, 18.870, 409.0, 20.2237
37.946904260, 18.870, 410.0, 20.2485
37.990370020, 18.870, 379.0, 19.4679
38.033835780, 18.870, 349.0, 18.6815
38.077301540, 18.870, 315.0, 17.7482
38.120767300, 18.870, 323.0, 17.9722
38.164233060, 18.870, 337.0, 18.3576
38.207698820, 18.870, 319.0, 17.8606
38.251164580, 18.870, 288.0, 16.9706
38.294630340, 18.870, 332.0, 18.2209
38.338096100, 18.870, 326.0, 18.0555
38.381561860, 18.870, 304.0, 17.4356
38.425027620, 18.870, 324.0, 18.0000
38.468493380, 18.870, 316.0, 17.7764
38.511959140, 18.870, 357.0, 18.8944
38.555424900, 18.870, 284.0, 16.8523
38.598890660, 18.870, 342.0, 18.4932
38.642356420, 18.870, 351.0, 18.7350
38.685822180, 18.870, 314.0, 17.7200
38.729287940, 18.870, 289.0, 17.0000
38.772753700, 18.870, 321.0, 17.9165
38.816219460, 18.870, 299.0, 17.2916
38.859685220, 18.870, 302.0, 17.3781
38.903150980, 18.870, 334.0, 18.2757
38.946616740, 18.870, 316.0, 17.7764
38.990082500, 18.870, 340.0, 18.4391
39.033548260, 18.870, 353.0, 18.7883
39.077014020, 18.870, 358.0, 18.9209
39.120479780, 18.870, 377.0, 19.4165
39.163945540, 18.870, 413.0, 20.3224
39.207411300, 18.870, 371.0, 19.2614
39.250877060, 18.870, 438.0, 20.9284
39.294342820, 18.870, 367.0, 19.1572
39.337808580, 18.870, 402.0, 20.0499
39.381274340, 18.870, 355.0, 18.8414
39.424740100, 18.870, 392.0, 19.7990
39.468205860, 18.870, 352.0, 18.7617
39.511671620, 18.870, 317.0, 17.8045
39.555137380, 18.870, 300.0, 17.3205
39.598603140, 18.870, 314.0, 17.7200
39.642068900, 18.870, 317.0, 17.8045
39.685534660, 18.870, 328.0, 18.1108
39.729000420, 18.870, 305.0, 17.4642
39.772466180, 18.870, 320.0, 17.8885
39.815931940, 18.870, 297.0, 17.2337
39.859397700, 18.870, 319.0, 17.8606
39.902863460, 18.870, 326.0, 18.0555
39.946329220, 18.870, 330.0, 18.1659
39.989794980, 18.870, 332.0, 18.2209
40.033260740, 18.870, 377.0, 19.4165
40.076726500, 18.870, 371.0, 19.2614
40.120192260, 18.870, 372.0, 19.2873
40.163658020, 18.870, 398.0, 19.9499
40.207123780, 18.870, 393.0, 19.8242
40.250589540, 18.870, 448.0, 21.1660
40.294055300, 18.870, 483.0, 21.9773
40.337521060, 18.870, 489.0, 22.1133
40.380986820, 18.870, 588.0, 24.2487
40.424452580, 18.870, 586.0, 24.2074
40.467918340, 18.870, 533.0, 23.0868
40.511384100, 18.870, 493.0, 22.2036
40.554849860, 18.870, 486.0, 22.0454
40.598315620, 18.870, 516.0, 22.7156
40.641781380, 18.870, 427.0, 20.6640
40.685247140, 18.870, 373.0, 19.3132
40.728712900, 18.870, 382.0, 19.5448
40.772178660, 18.870, 394.0, 19.8494
40.815644420, 18.870, 337.0, 18.3576
40.859110180, 18.870, 324.0, 18.0000
40.902575940, 18.870, 307.0, 17.5214
40.946041700, 18.870, 302.0, 17.3781
40.989507460, 18.870, 295.0, 17.1756
41.032973220, 18.870, 345.0, 18.5742
41.076438980, 18.870, 324.0, 18.0000
41.119904740, 18.870, 359.0, 18.9473
41.163370500, 18.870, 364.0, 19.0788
41.206836260, 18.870, 323.0, 17.9722
41.250302020, 18.870, 334.0, 18.2757
41.293767780, 18.870, 315.0, 17.7482
41.337233540, 18.870, 333.0, 18.2483
41.380699300, 18.870, 325.0, 18.0278
41.424165060, 18.870, 326.0, 18.0555
41.467630820, 18.870, 337.0, 18.3576
41.511096580, 18.870, 318.0, 17.8326
41.554562340, 18.870, 334.0, 18.2757
41.598028100, 18.870, 370.0, 19.2354
41.641493860, 18.870, 332.0, 18.2209
41.684959620, 18.870, 328.0, 18.1108
41.728425380, 18.870, 350.0, 18.7083
41.771891140, 18.870, 370.0, 19.2354
41.815356900, 18.870, 395.0, 19.8746
41.858822660, 18.870, 362.0, 19.0263
41.902288420, 18.870, 399.0, 19.9750
41.945754180, 18.870, 398.0, 19.9499
41.989219940, 18.870, 346.0, 18.6011
42.032685700, 18.870, 338.0, 18.3848
42.076151460, 18.870, 337.0, 18.3576
42.119617220, 18.870, 314.0, 17.7200
42.163082980, 18.870, 311.0, 17.6352
42.206548740, 18.870, 319.0, 17.8606
42.250014500, 18.870, 272.0, 16.4924
42.293480260, 18.870, 308.0, 17.5499
42.336946020, 18.870, 281.0, 16.7631
42.380411780, 18.870, 262.0, 16.1864
42.423877540, 18.870, 297.0, 17.2337
42.467343300, 18.870, 289.0, 17.0000
42.510809060, 18.870, 276.0, 16.6132
42.554274820, 18.870, 279.0, 16.7033
42.597740580, 18.870, 259.0, 16.0935
42.641206340, 18.870, 302.0, 17.3781
42.684672100, 18.870, 271.0, 16.4621
42.728137860, 18.870, 282.0, 16.7929
42.771603620, 18.870, 262.0, 16.1864
42.815069380, 18.870, 269.0, 16.4012
42.858535140, 18.870, 324.0, 18.0000
42.902000900, 18.870, 233.0, 15.2643
42.945466660, 18.870, 306.0, 17.4929
42.988932420, 18.870, 258.0, 16.0624
43.032398180, 18.870, 341.0, 18.4662
43.075863940, 18.870, 292.0, 17.0880
43.119329700, 18.870, 345.0, 18.5742
43.162795460, 18.870, 350.0, 18.7083
43.206261220, 18.870, 370.0, 19.2354
43.249726980, 18.870, 338.0, 18.3848
43.293192740, 18.870, 351.0, 18.7350
43.336658500, 18.870, 366.0, 19.1311
43.380124260, 18.870, 323.0, 17.9722
43.423590020, 18.870, 314.0, 17.7200
43.467055780, 18.870, 344.0, 18.5472
43.510521540, 18.870, 338.0, 18.3848
43.553987300, 18.870, 319.0, 17.8606
43.597453060, 18.870, 316.0, 17.7764
43.640918820, 18.870, 305.0, 17.4642
43.684384580, 18.870, 264.0, 16.2481
43.727850340, 18.870, 309.0, 17.5784
43.771316100, 18.870, 268.0, 16.3707
43.814781860, 18.870, 291.0, 17.0587
43.858247620, 18.870, 266.0, 16.3095
43.901713380, 18.870, 280.0, 16.7332
43.945179140, 18.870, 291.0, 17.0587
43.988644900, 18.870, 280.0, 16.7332
44.032110660, 18.870, 295.0, 17.1756
44.075576420, 18.870, 278.0, 16.6733
44.119042180, 18.870, 324.0, 18.0000
44.162507940, 18.870, 296.0, 17.2047
44.205973700, 18.870, 349.0, 18.6815
44.249439460, 18.870, 319.0, 17.8606
44.292905220, 18.870, 328.0, 18.1108
44.336370980, 18.870, 324.0, 18.0000
44.379836740, 18.870, 291.0, 17.0587
44.423302500, 18.870, 310.0, 17.6068
44.466768260, 18.870, 295.0, 17.1756
44.510234020, 18.870, 305.0, 17.4642
44.553699780, 18.870, 288.0, 16.9706
44.597165540, 18.870, 298.0, 17.2627
44.640631300, 18.870, 303.0, 17.4069
44.684097060, 18.870, 306.0, 17.4929
44.727562820, 18.870, 305.0, 17.4642
44.771028580, 18.870, 325.0, 18.0278
44.814494340, 18.870, 300.0, 17.3205
44.857960100, 18.870, 312.0, 17.6635
44.901425860, 18.870, 321.0, 17.9165
44.944891620, 18.870, 309.0, 17.5784
44.988357380, 18.870, 268.0, 16.3707
45.031823140, 18.870, 261.0, 16.1555
45.075288900, 18.870, 296.0, 17.2047
45.118754660, 18.870, 311.0, 17.6352
45.162220420, 18.870, 286.0, 16.9115
45.205686180, 18.870, 300.0, 17.3205
45.249151940, 18.870, 247.0, 15.7162
45.292617700, 18.870, 270.0, 16.4317
45.336083460, 18.870, 288.0, 16.9706
45.379549220, 18.870, 265.0, 16.2788
45.423014980, 18.870, 264.0, 16.2481
45.466480740, 18.870, 262.0, 16.1864
45.509946500, 18.870, 267.0, 16.3401
45.553412260, 18.870, 286.0, 16.9115
45.596878020, 18.870, 261.0, 16.1555
45.640343780, 18.870, 294.0, 17.1464
45.683809540, 18.870, 276.0, 16.6132
45.727275300, 18.870, 278.0, 16.6733
45.770741060, 18.870, 319.0, 17.8606
45.814206820, 18.870, 286.0, 16.9115
45.857672580, 18.870, 284.0, 16.8523
45.901138340, 18.870, 281.0, 16.7631
45.944604100, 18.870, 275.0, 16.5831
45.988069860, 18.870, 285.0, 16.8819
46.031535620, 18.870, 296.0, 17.2047
46.075001380, 18.870, 284.0, 16.8523
46.118467140, 18.870, 288.0, 16.9706
46.161932900, 18.870, 302.0, 17.3781
46.205398660, 18.870, 313.0, 17.6918
46.248864420, 18.870, 293.0, 17.1172
46.292330180, 18.870, 290.0, 17.0294
46.335795940, 18.870, 309.0, 17.5784
46.379261700, 18.870, 322.0, 17.9444
46.422727460, 18.870, 293.0, 17.1172
46.466193220, 18.870, 300.0, 17.3205
46.509658980, 18.870, 289.0, 17.0000
46.553124740, 18.870, 293.0, 17.1172
46.596590500, 18.870, 308.0, 17.5499
46.640056260, 18.870, 341.0, 18.4662
46.683522020, 18.870, 304.0, 17.4356
46.726987780, 18.870, 311.0, 17.6352
46.770453540, 18.870, 302.0, 17.3781
46.813919300, 18.870, 263.0, 16.2173
46.857385060, 18.870, 278.0, 16.6733
46.900850820, 18.870, 249.0, 15.7797
46.944316580, 18.870, 284.0, 16.8523
46.987782340, 18.870, 286.0, 16.9115
47.031248100, 18.870, 273.0, 16.5227
47.074713860, 18.870, 279.0, 16.7033
47.118179620, 18.870, 283.0, 16.8226
47.161645380, 18.870, 264.0, 16.2481
47.205111140, 18.870, 286.0, 16.9115
47.248576900, 18.870, 272.0, 16.4924
47.292042660, 18.870, 305.0, 17.4642
47.335508420, 18.870, 239.0, 15.4596
47.378974180, 18.870, 233.0, 15.2643
47.422439940, 18.870, 241.0, 15.5242
47.465905700, 18.870, 261.0, 16.1555
47.509371460, 18.870, 229.0, 15.1327
47.552837220, 18.870, 264.0, 16.2481
47.596302980, 18.870, 259.0, 16.0935
47.639768740, 18.870, 277.0, 16.6433
47.683234500, 18.870, 264.0, 16.2481
47.726700260, 18.870, 260.0, 16.1245
47.770166020, 18.870, 260.0, 16.1245
47.813631780, 18.870, 241.0, 15.5242
47.857097540, 18.870, 261.0, 16.1555
47.900563300, 18.870, 257.0, 16.0312
47.944029060, 18.870, 258.0, 16.0624
47.987494820, 18.870, 250.0, 15.8114
48.030960580, 18.870, 231.0, 15.1987
48.074426340, 18.870, 234.0, 15.2971
48.117892100, 18.870, 263.0, 16.2173
48.161357860, 18.870, 244.0, 15.6205
48.204823620, 18.870, 260.0, 16.1245
48.248289380, 18.870, 289.0, 17.0000
48.291755140, 18.870, 248.0, 15.7480
48.335220900, 18.870, 295.0, 17.1756
48.378686660, 18.870, 247.0, 15.7162
48.422152420, 18.870, 234.0, 15.2971
48.465618180, 18.870, 241.0, 15.5242
48.509083940, 18.870, 232.0, 15.2315
48.552549700, 18.870, 231.0, 15.1987
48.596015460, 18.870, 258.0, 16.0624
48.639481220, 18.870, 221.0, 14.8661
48.682946980, 18.870, 261.0, 16.1555
48.726412740, 18.870, 236.0, 15.3623
48.769878500, 18.870, 239.0, 15.4596
48.813344260, 18.870, 227.0, 15.0665
48.856810020, 18.870, 230.0, 15.1658
48.900275780, 18.870, 226.0, 15.0333
48.943741540, 18.870, 269.0, 16.4012
48.987207300, 18.870, 282.0, 16.7929
49.030673060, 18.870, 256.0, 16.0000
49.074138820, 18.870, 261.0, 16.1555
49.117604580, 18.870, 266.0, 16.3095
49.161070340, 18.870, 286.0, 16.9115
49.204536100, 18.870, 263.0, 16.2173
49.248001860, 18.870, 246.0, 15.6844
49.291467620, 18.870, 269.0, 16.4012
49.334933380, 18.870, 256.0, 16.0000
49.378399140, 18.870, 276.0, 16.6132
49.421864900, 18.870, 279.0, 16.7033
49.465330660, 18.870, 240.0, 15.4919
49.508796420, 18.870, 242.0, 15.5563
49.552262180, 18.870, 285.0, 16.8819
49.595727940, 18.870, 250.0, 15.8114
49.639193700, 18.870, 265.0, 16.2788
49.682659460, 18.870, 266.0, 16.3095
49.726125220, 18.870, 243.0, 15.5885
49.769590980, 18.870, 249.0, 15.7797
49.813056740, 18.870, 261.0, 16.1555
49.856522500, 18.870, 270.0, 16.4317
49.899988260, 18.870, 288.0, 16.9706
49.943454020, 18.870, 265.0, 16.2788
49.986919780, 18.870, 264.0, 16.2481
50.030385540, 18.870, 294.0, 17.1464
50.073851300, 18.870, 246.0, 15.6844
50.117317060, 18.870, 307.0, 17.5214
50.160782820, 18.870, 261.0, 16.1555
50.204248580, 18.870, 285.0, 16.8819
50.247714340, 18.870, 281.0, 16.7631
50.291180100, 18.870, 300.0, 17.3205
50.334645860, 18.870, 271.0, 16.4621
50.378111620, 18.870, 304.0, 17.4356
50.421577380, 18.870, 272.0, 16.4924
50.465043140, 18.870, 289.0, 17.0000
50.508508900, 18.870, 273.0, 16.5227
50.551974660, 18.870, 277.0, 16.6433
50.595440420, 18.870, 294.0, 17.1464
50.638906180, 18.870, 301.0, 17.3494
50.682371940, 18.870, 259.0, 16.0935
50.725837700, 18.870, 257.0, 16.0312
50.769303460, 18.870, 242.0, 15.5563
50.812769220, 18.870, 304.0, 17.4356
50.856234980, 18.870, 281.0, 16.7631
50.899700740, 18.870, 261.0, 16.1555
50.943166500, 18.870, 294.0, 17.1464
50.986632260, 18.870, 294.0, 17.1464
51.030098020, 18.870, 278.0, 16.6733
51.073563780, 18.870, 278.0, 16.6733
51.117029540, 18.870, 263.0, 16.2173
51.160495300, 18.870, 286.0, 16.9115
51.203961060, 18.870, 257.0, 16.0312
51.247426820, 18.870, 297.0, 17.2337
51.290892580, 18.870, 276.0, 16.6132
51.334358340, 18.870, 292.0, 17.0880
51.377824100, 18.870, 303.0, 17.4069
51.421289860, 18.870, 314.0, 17.7200
51.464755620, 18.870, 293.0, 17.1172
51.508221380, 18.870, 300.0, 17.3205
51.551687140, 18.870, 303.0, 17.4069
51.595152900, 18.870, 335.0, 18.3030
51.638618660, 18.870, 303.0, 17.4069
51.682084420, 18.870, 277.0, 16.6433
51.725550180, 18.870, 279.0, 16.7033
51.769015940, 18.870, 300.0, 17.3205
51.812481700, 18.870, 287.0, 16.9411
51.855947460, 18.870, 288.0, 16.9706
51.899413220, 18.870, 259.0, 16.0935
51.942878980, 18.870, 289.0, 17.0000
51.986344740, 18.870, 274.0, 16.5529
52.029810500, 18.870, 310.0, 17.6068
52.073276260, 18.870, 248.0, 15.7480
52.116742020, 18.870, 304.0, 17.4356
52.160207780, 18.870, 271.0, 16.4621
52.203673540, 18.870, 301.0, 17.3494
52.247139300, 18.870, 294.0, 17.1464
52.290605060, 18.870, 247.0, 15.7162
52.334070820, 18.870, 265.0, 16.2788
52.377536580, 18.870, 284.0, 16.8523
52.421002340, 18.870, 249.0, 15.7797
52.464468100, 18.870, 274.0, 16.5529
52.507933860, 18.870, 284.0, 16.8523
52.551399620, 18.870, 274.0, 16.5529
52.594865380, 18.870, 282.0, 16.7929
52.638331140, 18.870, 262.0, 16.1864
52.681796900, 18.870, 257.0, 16.0312
52.725262660, 18.870, 283.0, 16.8226
52.768728420, 18.870, 234.0, 15.2971
52.812194180, 18.870, 238.0, 15.4272
52.855659940, 18.870, 262.0, 16.1864
52.899125700, 18.870, 260.0, 16.1245
52.942591460, 18.870, 240.0, 15.4919
52.986057220, 18.870, 260.0, 16.1245
53.029522980, 18.870, 209.0, 14.4568
53.072988740, 18.870, 263.0, 16.2173
53.116454500, 18.870, 266.0, 16.3095
53.159920260, 18.870, 237.0, 15.3948
53.203386020, 18.870, 266.0, 16.3095
53.246851780, 18.870, 276.0, 16.6132
53.290317540, 18.870, 258.0, 16.0624
53.333783300, 18.870, 265.0, 16.2788
53.377249060, 18.870, 263.0, 16.2173
53.420714820, 18.870, 277.0, 16.6433
53.464180580, 18.870, 298.0, 17.2627
53.507646340, 18.870, 269.0, 16.4012
53.551112100, 18.870, 279.0, 16.7033
53.594577860, 18.870, 257.0, 16.0312
53.638043620, 18.870, 257.0, 16.0312
53.681509380, 18.870, 260.0, 16.1245
53.724975140, 18.870, 259.0, 16.0935
53.768440900, 18.870, 249.0, 15.7797
53.811906660, 18.870, 267.0, 16.3401
53.855372420, 18.870, 258.0, 16.0624
53.898838180, 18.870, 278.0, 16.6733
53.942303940, 18.870, 283.0, 16.8226
53.985769700, 18.870, 264.0, 16.2481
54.029235460, 18.870, 250.0, 15.8114
54.072701220, 18.870, 304.0, 17.4356
54.116166980, 18.870, 273.0, 16.5227
54.159632740, 18.870, 268.0, 16.3707
54.203098500, 18.870, 270.0, 16.4317
54.246564260, 18.870, 216.0, 14.6969
54.290030020, 18.870, 234.0, 15.2971
54.333495780, 18.870, 246.0, 15.6844
54.376961540, 18.870, 221.0, 14.8661
54.420427300, 18.870, 261.0, 16.1555
54.463893060, 18.870, 233.0, 15.2643
54.507358820, 18.870, 264.0, 16.2481
54.550824580, 18.870, 239.0, 15.4596
54.594290340, 18.870, 210.0, 14.4914
54.637756100, 18.870, 210.0, 14.4914
54.681221860, 18.870, 241.0, 15.5242
54.724687620, 18.870, 250.0, 15.8114
54.768153380, 18.870, 241.0, 15.5242
54.811619140, 18.870, 237.0, 15.3948
54.855084900, 18.870, 250.0, 15.8114
54.898550660, 18.870, 259.0, 16.0935
54.942016420, 18.870, 243.0, 15.5885
54.985482180, 18.870, 227.0, 15.0665
55.028947940, 18.870, 268.0, 16.3707
55.072413700, 18.870, 247.0, 15.7162
55.115879460, 18.870, 271.0, 16.4621
55.159345220, 18.870, 269.0, 16.4012
55.202810980, 18.870, 240.0, 15.4919
55.246276740, 18.870, 218.0, 14.7648
55.289742500, 18.870, 275.0, 16.5831
55.333208260, 18.870, 229.0, 15.1327
55.376674020, 18.870, 232.0, 15.2315
55.420139780, 18.870, 235.0, 15.3297
55.463605540, 18.870, 270.0, 16.4317
55.507071300, 18.870, 233.0, 15.2643
55.550537060, 18.870, 248.0, 15.7480
55.594002820, 18.870, 220.0, 14.8324
55.637468580, 18.870, 228.0, 15.0997
55.680934340, 18.870, 258.0, 16.0624
55.724400100, 18.870, 250.0, 15.8114
55.767865860, 18.870, 287.0, 16.9411
55.811331620, 18.870, 244.0, 15.6205
55.854797380, 18.870, 265.0, 16.2788
55.898263140, 18.870, 262.0, 16.1864
55.941728900, 18.870, 242.0, 15.5563
55.985194660, 18.870, 267.0, 16.3401
56.028660420, 18.870, 258.0, 16.0624
56.072126180, 18.870, 227.0, 15.0665
56.115591940, 18.870, 256.0, 16.0000
56.159057700, 18.870, 233.0, 15.2643
56.202523460, 18.870, 224.0, 14.9666
56.245989220, 18.870, 203.0, 14.2478
56.289454980, 18.870, 233.0, 15.2643
56.332920740, 18.870, 194.0, 13.9284
56.376386500, 18.870, 232.0, 15.2315
56.419852260, 18.870, 260.0, 16.1245
56.463318020, 18.870, 233.0, 15.2643
56.506783780, 18.870, 236.0, 15.3623
56.550249540, 18.870, 257.0, 16.0312
56.593715300, 18.870, 262.0, 16.1864
56.637181060, 18.870, 247.0, 15.7162
56.680646820, 18.870, 249.0, 15.7797
56.724112580, 18.870, 232.0, 15.2315
56.767578340, 18.870, 271.0, 16.4621
56.811044100, 18.870, 263.0, 16.2173
56.854509860, 18.870, 231.0, 15.1987
56.897975620, 18.870, 241.0, 15.5242
56.941441380, 18.870, 227.0, 15.0665
56.984907140, 18.870, 231.0, 15.1987
57.028372900, 18.870, 238.0, 15.4272
57.071838660, 18.870, 215.0, 14.6629
57.115304420, 18.870, 217.0, 14.7309
57.158770180, 18.870, 223.0, 14.9332
57.202235940, 18.870, 238.0, 15.4272
57.245701700, 18.870, 220.0, 14.8324
57.289167460, 18.870, 213.0, 14.5945
57.332633220, 18.870, 193.0, 13.8924
57.376098980, 18.870, 214.0, 14.6287
57.419564740, 18.870, 220.0, 14.8324
57.463030500, 18.870, 195.0, 13.9642
57.506496260, 18.870, 228.0, 15.0997
57.549962020, 18.870, 204.0, 14.2829
57.593427780, 18.870, 203.0, 14.2478
57.636893540, 18.870, 225.0, 15.0000
57.680359300, 18.870, 193.0, 13.8924
57.723825060, 18.870, 212.0, 14.5602
57.767290820, 18.870, 212.0, 14.5602
57.810756580, 18.870, 227.0, 15.0665
57.854222340, 18.870, 225.0, 15.0000
57.897688100, 18.870, 217.0, 14.7309
57.941153860, 18.870, 216.0, 14.6969
57.984619620, 18.870, 229.0, 15.1327
58.028085380, 18.870, 233.0, 15.2643
58.071551140, 18.870, 242.0, 15.5563
58.115016900, 18.870, 262.0, 16.1864
58.158482660, 18.870, 242.0, 15.5563
58.201948420, 18.870, 233.0, 15.2643
58.245414180, 18.870, 257.0, 16.0312
58.288879940, 18.870, 230.0, 15.1658
58.332345700, 18.870, 230.0, 15.1658
58.375811460, 18.870, 217.0, 14.7309
58.419277220, 18.870, 235.0, 15.3297
58.462742980, 18.870, 233.0, 15.2643
58.506208740, 18.870, 227.0, 15.0665
58.549674500, 18.870, 211.0, 14.5258
58.593140260, 18.870, 232.0, 15.2315
58.636606020, 18.870, 207.0, 14.3875
58.680071780, 18.870, 213.0, 14.5945
58.723537540, 18.870, 189.0, 13.7477
58.767003300, 18.870, 207.0, 14.3875
58.810469060, 18.870, 226.0, 15.0333
58.853934820, 18.870, 220.0, 14.8324
58.897400580, 18.870, 208.0, 14.4222
58.940866340, 18.870, 212.0, 14.5602
58.984332100, 18.870, 224.0, 14.9666
59.027797860, 18.870, 187.0, 13.6748
59.071263620, 18.870, 227.0, 15.0665
59.114729380, 18.870, 217.0, 14.7309
59.158195140, 18.870, 184.0, 13.5647
59.201660900, 18.870, 217.0, 14.7309
59.245126660, 18.870, 237.0, 15.3948
59.288592420, 18.870, 209.0, 14.4568
59.332058180, 18.870, 218.0, 14.7648
59.375523940, 18.870, 212.0, 14.5602
59.418989700, 18.870, 183.0, 13.5277
59.462455460, 18.870, 182.0, 13.4907
59.505921220, 18.870, 214.0, 14.6287
59.549386980, 18.870, 208.0, 14.4222
59.592852740, 18.870, 203.0, 14.2478
59.636318500, 18.870, 202.0, 14.2127
59.679784260, 18.870, 227.0, 15.0665
59.723250020, 18.870, 222.0, 14.8997
59.766715780, 18.870, 195.0, 13.9642
59.810181540, 18.870, 190.0, 13.7840
59.853647300, 18.870, 200.0, 14.1421
59.897113060, 18.870, 205.0, 14.3178
59.940578820, 18.870, 207.0, 14.3875
59.984044580, 18.870, 179.0, 13.3791
59.994911020, 18.870, 200.0, 14.1421