File: XRD/2025_06_12_aFEL_DSC_3_60_22m_pXRD.csv
[Measurement conditions]
Sample identification,2025_06_12_aFEL_DSC_3_60_22m_pXRD
Comment - 1,"Felodipine heated in DSC (#22, A2 Tray) to 165C.  Glassy FEL verification before Raman."
Anode material,Cu
K-Alpha1 wavelength,1.5405980
K-Alpha2 wavelength,1.5444260
Ratio K-Alpha2/K-Alpha1,0.500
Divergence slit,Fixed,0.76mm
Monochromator used,NO
Generator voltage, 40
Tube current, 15
File date and time,12/Jun/2025 13:32
Unit cell,
h k l, 0 0 0
Scan axis,Gonio
Scan range,2.995000000,60.000344240
Scan step size,0.0108664
No. of points, 5246
Scan type,CONTINUOUS
Time per step,58.395
[Scan points]
Angle, TimePerStep, Intensity, ESD
3.000433220, 58.395, 134532.0, 366.7860
3.043898980, 58.395, 127862.0, 357.5780
3.087364740, 58.395, 122442.0, 349.9171
3.130830500, 58.395, 116681.0, 341.5860
3.174296260, 58.395, 110029.0, 331.7062
3.217762020, 58.395, 103942.0, 322.4004
3.261227780, 58.395, 97460.0, 312.1858
3.304693540, 58.395, 92012.0, 303.3348
3.348159300, 58.395, 86903.0, 294.7931
3.391625060, 58.395, 82455.0, 287.1498
3.435090820, 58.395, 77504.0, 278.3954
3.478556580, 58.395, 73213.0, 270.5790
3.522022340, 58.395, 68434.0, 261.5989
3.565488100, 58.395, 64222.0, 253.4206
3.608953860, 58.395, 60668.0, 246.3087
3.652419620, 58.395, 56831.0, 238.3925
3.695885380, 58.395, 53264.0, 230.7899
3.739351140, 58.395, 49919.0, 223.4256
3.782816900, 58.395, 46563.0, 215.7846
3.826282660, 58.395, 43550.0, 208.6864
3.869748420, 58.395, 40545.0, 201.3579
3.913214180, 58.395, 37786.0, 194.3862
3.956679940, 58.395, 35065.0, 187.2565
4.000145700, 58.395, 32547.0, 180.4079
4.043611460, 58.395, 30130.0, 173.5800
4.087077220, 58.395, 27998.0, 167.3260
4.130542980, 58.395, 25629.0, 160.0906
4.174008740, 58.395, 24293.0, 155.8621
4.217474500, 58.395, 22173.0, 148.9060
4.260940260, 58.395, 20334.0, 142.5973
4.304406020, 58.395, 18839.0, 137.2552
4.347871780, 58.395, 17134.0, 130.8969
4.391337540, 58.395, 15798.0, 125.6901
4.434803300, 58.395, 14496.0, 120.3993
4.478269060, 58.395, 13420.0, 115.8447
4.521734820, 58.395, 12528.0, 111.9285
4.565200580, 58.395, 11598.0, 107.6940
4.608666340, 58.395, 10636.0, 103.1310
4.652132100, 58.395, 10077.0, 100.3843
4.695597860, 58.395, 9197.0, 95.9010
4.739063620, 58.395, 8725.0, 93.4077
4.782529380, 58.395, 8111.0, 90.0611
4.825995140, 58.395, 7549.0, 86.8850
4.869460900, 58.395, 7269.0, 85.2584
4.912926660, 58.395, 7052.0, 83.9762
4.956392420, 58.395, 6791.0, 82.4075
4.999858180, 58.395, 6685.0, 81.7618
5.043323940, 58.395, 6545.0, 80.9012
5.086789700, 58.395, 6585.0, 81.1480
5.130255460, 58.395, 6436.0, 80.2247
5.173721220, 58.395, 6428.0, 80.1748
5.217186980, 58.395, 6465.0, 80.4052
5.260652740, 58.395, 6551.0, 80.9382
5.304118500, 58.395, 6429.0, 80.1810
5.347584260, 58.395, 6279.0, 79.2401
5.391050020, 58.395, 6161.0, 78.4920
5.434515780, 58.395, 5772.0, 75.9737
5.477981540, 58.395, 5396.0, 73.4575
5.521447300, 58.395, 5242.0, 72.4017
5.564913060, 58.395, 4800.0, 69.2820
5.608378820, 58.395, 4497.0, 67.0597
5.651844580, 58.395, 4257.0, 65.2457
5.695310340, 58.395, 3984.0, 63.1189
5.738776100, 58.395, 3870.0, 62.2093
5.782241860, 58.395, 3660.0, 60.4979
5.825707620, 58.395, 3568.0, 59.7327
5.869173380, 58.395, 3555.0, 59.6238
5.912639140, 58.395, 3377.0, 58.1120
5.956104900, 58.395, 3372.0, 58.0689
5.999570660, 58.395, 3405.0, 58.3524
6.043036420, 58.395, 3216.0, 56.7098
6.086502180, 58.395, 3221.0, 56.7539
6.129967940, 58.395, 3104.0, 55.7136
6.173433700, 58.395, 3047.0, 55.1996
6.216899460, 58.395, 2898.0, 53.8331
6.260365220, 58.395, 2951.0, 54.3231
6.303830980, 58.395, 2704.0, 52.0000
6.347296740, 58.395, 2791.0, 52.8299
6.390762500, 58.395, 2655.0, 51.5267
6.434228260, 58.395, 2638.0, 51.3615
6.477694020, 58.395, 2596.0, 50.9510
6.521159780, 58.395, 2514.0, 50.1398
6.564625540, 58.395, 2549.0, 50.4876
6.608091300, 58.395, 2350.0, 48.4768
6.651557060, 58.395, 2362.0, 48.6004
6.695022820, 58.395, 2248.0, 47.4131
6.738488580, 58.395, 2254.0, 47.4763
6.781954340, 58.395, 2346.0, 48.4355
6.825420100, 58.395, 2160.0, 46.4758
6.868885860, 58.395, 2113.0, 45.9674
6.912351620, 58.395, 2023.0, 44.9778
6.955817380, 58.395, 1988.0, 44.5870
6.999283140, 58.395, 1940.0, 44.0454
7.042748900, 58.395, 1948.0, 44.1362
7.086214660, 58.395, 1973.0, 44.4185
7.129680420, 58.395, 1896.0, 43.5431
7.173146180, 58.395, 1862.0, 43.1509
7.216611940, 58.395, 1780.0, 42.1900
7.260077700, 58.395, 1812.0, 42.5676
7.303543460, 58.395, 1807.0, 42.5088
7.347009220, 58.395, 1842.0, 42.9185
7.390474980, 58.395, 1665.0, 40.8044
7.433940740, 58.395, 1709.0, 41.3401
7.477406500, 58.395, 1673.0, 40.9023
7.520872260, 58.395, 1771.0, 42.0833
7.564338020, 58.395, 1709.0, 41.3401
7.607803780, 58.395, 1701.0, 41.2432
7.651269540, 58.395, 1591.0, 39.8873
7.694735300, 58.395, 1714.0, 41.4005
7.738201060, 58.395, 1717.0, 41.4367
7.781666820, 58.395, 1644.0, 40.5463
7.825132580, 58.395, 1669.0, 40.8534
7.868598340, 58.395, 1579.0, 39.7366
7.912064100, 58.395, 1616.0, 40.1995
7.955529860, 58.395, 1640.0, 40.4969
7.998995620, 58.395, 1614.0, 40.1746
8.042461380, 58.395, 1667.0, 40.8289
8.085927140, 58.395, 1695.0, 41.1704
8.129392900, 58.395, 1628.0, 40.3485
8.172858660, 58.395, 1592.0, 39.8999
8.216324420, 58.395, 1579.0, 39.7366
8.259790180, 58.395, 1651.0, 40.6325
8.303255940, 58.395, 1660.0, 40.7431
8.346721700, 58.395, 1583.0, 39.7869
8.390187460, 58.395, 1653.0, 40.6571
8.433653220, 58.395, 1688.0, 41.0853
8.477118980, 58.395, 1686.0, 41.0609
8.520584740, 58.395, 1717.0, 41.4367
8.564050500, 58.395, 1634.0, 40.4228
8.607516260, 58.395, 1626.0, 40.3237
8.650982020, 58.395, 1700.0, 41.2311
8.694447780, 58.395, 1720.0, 41.4729
8.737913540, 58.395, 1629.0, 40.3609
8.781379300, 58.395, 1756.0, 41.9047
8.824845060, 58.395, 1703.0, 41.2674
8.868310820, 58.395, 1761.0, 41.9643
8.911776580, 58.395, 1733.0, 41.6293
8.955242340, 58.395, 1735.0, 41.6533
8.998708100, 58.395, 1830.0, 42.7785
9.042173860, 58.395, 1803.0, 42.4617
9.085639620, 58.395, 1848.0, 42.9884
9.129105380, 58.395, 1719.0, 41.4608
9.172571140, 58.395, 1833.0, 42.8135
9.216036900, 58.395, 1784.0, 42.2374
9.259502660, 58.395, 1885.0, 43.4166
9.302968420, 58.395, 1856.0, 43.0813
9.346434180, 58.395, 1953.0, 44.1928
9.389899940, 58.395, 1840.0, 42.8952
9.433365700, 58.395, 1825.0, 42.7200
9.476831460, 58.395, 2016.0, 44.8999
9.520297220, 58.395, 1984.0, 44.5421
9.563762980, 58.395, 1926.0, 43.8862
9.607228740, 58.395, 1931.0, 43.9431
9.650694500, 58.395, 2042.0, 45.1885
9.694160260, 58.395, 2005.0, 44.7772
9.737626020, 58.395, 2074.0, 45.5412
9.781091780, 58.395, 2106.0, 45.8912
9.824557540, 58.395, 2180.0, 46.6905
9.868023300, 58.395, 2161.0, 46.4866
9.911489060, 58.395, 2150.0, 46.3681
9.954954820, 58.395, 2165.0, 46.5296
9.998420580, 58.395, 2178.0, 46.6690
10.041886340, 58.395, 2213.0, 47.0425
10.085352100, 58.395, 2194.0, 46.8402
10.128817860, 58.395, 2150.0, 46.3681
10.172283620, 58.395, 2249.0, 47.4236
10.215749380, 58.395, 2243.0, 47.3603
10.259215140, 58.395, 2330.0, 48.2701
10.302680900, 58.395, 2321.0, 48.1768
10.346146660, 58.395, 2343.0, 48.4045
10.389612420, 58.395, 2341.0, 48.3839
10.433078180, 58.395, 2353.0, 48.5077
10.476543940, 58.395, 2425.0, 49.2443
10.520009700, 58.395, 2465.0, 49.6488
10.563475460, 58.395, 2473.0, 49.7293
10.606941220, 58.395, 2485.0, 49.8498
10.650406980, 58.395, 2485.0, 49.8498
10.693872740, 58.395, 2508.0, 50.0799
10.737338500, 58.395, 2548.0, 50.4777
10.780804260, 58.395, 2568.0, 50.6754
10.824270020, 58.395, 2519.0, 50.1896
10.867735780, 58.395, 2578.0, 50.7740
10.911201540, 58.395, 2537.0, 50.3686
10.954667300, 58.395, 2640.0, 51.3809
10.998133060, 58.395, 2534.0, 50.3389
11.041598820, 58.395, 2614.0, 51.1273
11.085064580, 58.395, 2535.0, 50.3488
11.128530340, 58.395, 2748.0, 52.4214
11.171996100, 58.395, 2644.0, 51.4198
11.215461860, 58.395, 2698.0, 51.9423
11.258927620, 58.395, 2742.0, 52.3641
11.302393380, 58.395, 2683.0, 51.7977
11.345859140, 58.395, 2579.0, 50.7839
11.389324900, 58.395, 2602.0, 51.0098
11.432790660, 58.395, 2719.0, 52.1440
11.476256420, 58.395, 2695.0, 51.9134
11.519722180, 58.395, 2659.0, 51.5655
11.563187940, 58.395, 2674.0, 51.7107
11.606653700, 58.395, 2652.0, 51.4976
11.650119460, 58.395, 2707.0, 52.0288
11.693585220, 58.395, 2821.0, 53.1131
11.737050980, 58.395, 2746.0, 52.4023
11.780516740, 58.395, 2752.0, 52.4595
11.823982500, 58.395, 2674.0, 51.7107
11.867448260, 58.395, 2741.0, 52.3546
11.910914020, 58.395, 2740.0, 52.3450
11.954379780, 58.395, 2679.0, 51.7591
11.997845540, 58.395, 2814.0, 53.0471
12.041311300, 58.395, 2741.0, 52.3546
12.084777060, 58.395, 2600.0, 50.9902
12.128242820, 58.395, 2759.0, 52.5262
12.171708580, 58.395, 2571.0, 50.7050
12.215174340, 58.395, 2633.0, 51.3128
12.258640100, 58.395, 2734.0, 52.2877
12.302105860, 58.395, 2619.0, 51.1762
12.345571620, 58.395, 2541.0, 50.4083
12.389037380, 58.395, 2647.0, 51.4490
12.432503140, 58.395, 2652.0, 51.4976
12.475968900, 58.395, 2500.0, 50.0000
12.519434660, 58.395, 2688.0, 51.8459
12.562900420, 58.395, 2602.0, 51.0098
12.606366180, 58.395, 2587.0, 50.8626
12.649831940, 58.395, 2550.0, 50.4975
12.693297700, 58.395, 2570.0, 50.6952
12.736763460, 58.395, 2458.0, 49.5782
12.780229220, 58.395, 2476.0, 49.7594
12.823694980, 58.395, 2485.0, 49.8498
12.867160740, 58.395, 2498.0, 49.9800
12.910626500, 58.395, 2484.0, 49.8397
12.954092260, 58.395, 2540.0, 50.3984
12.997558020, 58.395, 2468.0, 49.6790
13.041023780, 58.395, 2459.0, 49.5883
13.084489540, 58.395, 2409.0, 49.0816
13.127955300, 58.395, 2484.0, 49.8397
13.171421060, 58.395, 2358.0, 48.5592
13.214886820, 58.395, 2441.0, 49.4065
13.258352580, 58.395, 2309.0, 48.0521
13.301818340, 58.395, 2295.0, 47.9062
13.345284100, 58.395, 2289.0, 47.8435
13.388749860, 58.395, 2351.0, 48.4871
13.432215620, 58.395, 2399.0, 48.9796
13.475681380, 58.395, 2224.0, 47.1593
13.519147140, 58.395, 2312.0, 48.0833
13.562612900, 58.395, 2254.0, 47.4763
13.606078660, 58.395, 2287.0, 47.8226
13.649544420, 58.395, 2304.0, 48.0000
13.693010180, 58.395, 2302.0, 47.9792
13.736475940, 58.395, 2161.0, 46.4866
13.779941700, 58.395, 2169.0, 46.5725
13.823407460, 58.395, 2129.0, 46.1411
13.866873220, 58.395, 2172.0, 46.6047
13.910338980, 58.395, 2076.0, 45.5631
13.953804740, 58.395, 2131.0, 46.1628
13.997270500, 58.395, 2142.0, 46.2817
14.040736260, 58.395, 2137.0, 46.2277
14.084202020, 58.395, 2242.0, 47.3498
14.127667780, 58.395, 2165.0, 46.5296
14.171133540, 58.395, 2132.0, 46.1736
14.214599300, 58.395, 2083.0, 45.6399
14.258065060, 58.395, 2100.0, 45.8258
14.301530820, 58.395, 2098.0, 45.8039
14.344996580, 58.395, 2100.0, 45.8258
14.388462340, 58.395, 2094.0, 45.7602
14.431928100, 58.395, 2105.0, 45.8803
14.475393860, 58.395, 2060.0, 45.3872
14.518859620, 58.395, 2021.0, 44.9555
14.562325380, 58.395, 1967.0, 44.3509
14.605791140, 58.395, 1982.0, 44.5197
14.649256900, 58.395, 1988.0, 44.5870
14.692722660, 58.395, 2070.0, 45.4973
14.736188420, 58.395, 2087.0, 45.6837
14.779654180, 58.395, 2047.0, 45.2438
14.823119940, 58.395, 2056.0, 45.3431
14.866585700, 58.395, 2038.0, 45.1442
14.910051460, 58.395, 2047.0, 45.2438
14.953517220, 58.395, 1984.0, 44.5421
14.996982980, 58.395, 2026.0, 45.0111
15.040448740, 58.395, 1966.0, 44.3396
15.083914500, 58.395, 1985.0, 44.5533
15.127380260, 58.395, 2004.0, 44.7661
15.170846020, 58.395, 1963.0, 44.3058
15.214311780, 58.395, 1969.0, 44.3734
15.257777540, 58.395, 1978.0, 44.4747
15.301243300, 58.395, 1887.0, 43.4396
15.344709060, 58.395, 1936.0, 44.0000
15.388174820, 58.395, 1970.0, 44.3847
15.431640580, 58.395, 2037.0, 45.1331
15.475106340, 58.395, 1934.0, 43.9773
15.518572100, 58.395, 1992.0, 44.6318
15.562037860, 58.395, 1908.0, 43.6807
15.605503620, 58.395, 1926.0, 43.8862
15.648969380, 58.395, 1941.0, 44.0568
15.692435140, 58.395, 1877.0, 43.3244
15.735900900, 58.395, 2000.0, 44.7214
15.779366660, 58.395, 1944.0, 44.0908
15.822832420, 58.395, 1948.0, 44.1362
15.866298180, 58.395, 1952.0, 44.1814
15.909763940, 58.395, 1997.0, 44.6878
15.953229700, 58.395, 1891.0, 43.4856
15.996695460, 58.395, 1956.0, 44.2267
16.040161220, 58.395, 1854.0, 43.0581
16.083626980, 58.395, 1812.0, 42.5676
16.127092740, 58.395, 2015.0, 44.8888
16.170558500, 58.395, 1867.0, 43.2088
16.214024260, 58.395, 1998.0, 44.6990
16.257490020, 58.395, 1965.0, 44.3283
16.300955780, 58.395, 1965.0, 44.3283
16.344421540, 58.395, 1972.0, 44.4072
16.387887300, 58.395, 1909.0, 43.6921
16.431353060, 58.395, 1995.0, 44.6654
16.474818820, 58.395, 2014.0, 44.8776
16.518284580, 58.395, 1951.0, 44.1701
16.561750340, 58.395, 1990.0, 44.6094
16.605216100, 58.395, 2008.0, 44.8107
16.648681860, 58.395, 2042.0, 45.1885
16.692147620, 58.395, 1959.0, 44.2606
16.735613380, 58.395, 2052.0, 45.2990
16.779079140, 58.395, 2028.0, 45.0333
16.822544900, 58.395, 2039.0, 45.1553
16.866010660, 58.395, 2047.0, 45.2438
16.909476420, 58.395, 2028.0, 45.0333
16.952942180, 58.395, 2066.0, 45.4533
16.996407940, 58.395, 1964.0, 44.3170
17.039873700, 58.395, 2066.0, 45.4533
17.083339460, 58.395, 2024.0, 44.9889
17.126805220, 58.395, 2051.0, 45.2880
17.170270980, 58.395, 1989.0, 44.5982
17.213736740, 58.395, 2117.0, 46.0109
17.257202500, 58.395, 2038.0, 45.1442
17.300668260, 58.395, 2006.0, 44.7884
17.344134020, 58.395, 2144.0, 46.3033
17.387599780, 58.395, 2014.0, 44.8776
17.431065540, 58.395, 2083.0, 45.6399
17.474531300, 58.395, 2116.0, 46.0000
17.517997060, 58.395, 2095.0, 45.7712
17.561462820, 58.395, 2101.0, 45.8367
17.604928580, 58.395, 2095.0, 45.7712
17.648394340, 58.395, 2097.0, 45.7930
17.691860100, 58.395, 2157.0, 46.4435
17.735325860, 58.395, 2067.0, 45.4643
17.778791620, 58.395, 2077.0, 45.5741
17.822257380, 58.395, 2180.0, 46.6905
17.865723140, 58.395, 2134.0, 46.1952
17.909188900, 58.395, 2158.0, 46.4543
17.952654660, 58.395, 2178.0, 46.6690
17.996120420, 58.395, 2207.0, 46.9787
18.039586180, 58.395, 2186.0, 46.7547
18.083051940, 58.395, 2292.0, 47.8748
18.126517700, 58.395, 2190.0, 46.7974
18.169983460, 58.395, 2184.0, 46.7333
18.213449220, 58.395, 2153.0, 46.4004
18.256914980, 58.395, 2259.0, 47.5289
18.300380740, 58.395, 2238.0, 47.3075
18.343846500, 58.395, 2261.0, 47.5500
18.387312260, 58.395, 2291.0, 47.8644
18.430778020, 58.395, 2239.0, 47.3181
18.474243780, 58.395, 2287.0, 47.8226
18.517709540, 58.395, 2311.0, 48.0729
18.561175300, 58.395, 2313.0, 48.0937
18.604641060, 58.395, 2324.0, 48.2079
18.648106820, 58.395, 2287.0, 47.8226
18.691572580, 58.395, 2313.0, 48.0937
18.735038340, 58.395, 2344.0, 48.4149
18.778504100, 58.395, 2365.0, 48.6313
18.821969860, 58.395, 2330.0, 48.2701
18.865435620, 58.395, 2379.0, 48.7750
18.908901380, 58.395, 2364.0, 48.6210
18.952367140, 58.395, 2388.0, 48.8672
18.995832900, 58.395, 2444.0, 49.4368
19.039298660, 58.395, 2350.0, 48.4768
19.082764420, 58.395, 2385.0, 48.8365
19.126230180, 58.395, 2534.0, 50.3389
19.169695940, 58.395, 2465.0, 49.6488
19.213161700, 58.395, 2477.0, 49.7695
19.256627460, 58.395, 2501.0, 50.0100
19.300093220, 58.395, 2428.0, 49.2747
19.343558980, 58.395, 2420.0, 49.1935
19.387024740, 58.395, 2473.0, 49.7293
19.430490500, 58.395, 2518.0, 50.1797
19.473956260, 58.395, 2477.0, 49.7695
19.517422020, 58.395, 2552.0, 50.5173
19.560887780, 58.395, 2482.0, 49.8197
19.604353540, 58.395, 2436.0, 49.3559
19.647819300, 58.395, 2662.0, 51.5946
19.691285060, 58.395, 2518.0, 50.1797
19.734750820, 58.395, 2519.0, 50.1896
19.778216580, 58.395, 2628.0, 51.2640
19.821682340, 58.395, 2659.0, 51.5655
19.865148100, 58.395, 2536.0, 50.3587
19.908613860, 58.395, 2546.0, 50.4579
19.952079620, 58.395, 2602.0, 51.0098
19.995545380, 58.395, 2536.0, 50.3587
20.039011140, 58.395, 2731.0, 52.2590
20.082476900, 58.395, 2689.0, 51.8556
20.125942660, 58.395, 2646.0, 51.4393
20.169408420, 58.395, 2598.0, 50.9706
20.212874180, 58.395, 2712.0, 52.0769
20.256339940, 58.395, 2657.0, 51.5461
20.299805700, 58.395, 2697.0, 51.9326
20.343271460, 58.395, 2607.0, 51.0588
20.386737220, 58.395, 2698.0, 51.9423
20.430202980, 58.395, 2744.0, 52.3832
20.473668740, 58.395, 2787.0, 52.7920
20.517134500, 58.395, 2660.0, 51.5752
20.560600260, 58.395, 2698.0, 51.9423
20.604066020, 58.395, 2729.0, 52.2398
20.647531780, 58.395, 2783.0, 52.7541
20.690997540, 58.395, 2757.0, 52.5071
20.734463300, 58.395, 2717.0, 52.1249
20.777929060, 58.395, 2769.0, 52.6213
20.821394820, 58.395, 2741.0, 52.3546
20.864860580, 58.395, 2865.0, 53.5257
20.908326340, 58.395, 2795.0, 52.8678
20.951792100, 58.395, 2761.0, 52.5452
20.995257860, 58.395, 2792.0, 52.8394
21.038723620, 58.395, 2864.0, 53.5164
21.082189380, 58.395, 2777.0, 52.6972
21.125655140, 58.395, 2791.0, 52.8299
21.169120900, 58.395, 2946.0, 54.2771
21.212586660, 58.395, 2828.0, 53.1789
21.256052420, 58.395, 2894.0, 53.7959
21.299518180, 58.395, 2795.0, 52.8678
21.342983940, 58.395, 2786.0, 52.7826
21.386449700, 58.395, 2814.0, 53.0471
21.429915460, 58.395, 2781.0, 52.7352
21.473381220, 58.395, 2798.0, 52.8961
21.516846980, 58.395, 2857.0, 53.4509
21.560312740, 58.395, 2822.0, 53.1225
21.603778500, 58.395, 2828.0, 53.1789
21.647244260, 58.395, 2880.0, 53.6656
21.690710020, 58.395, 2874.0, 53.6097
21.734175780, 58.395, 2912.0, 53.9630
21.777641540, 58.395, 2949.0, 54.3047
21.821107300, 58.395, 2894.0, 53.7959
21.864573060, 58.395, 2941.0, 54.2310
21.908038820, 58.395, 2881.0, 53.6749
21.951504580, 58.395, 2808.0, 52.9906
21.994970340, 58.395, 2895.0, 53.8052
22.038436100, 58.395, 2867.0, 53.5444
22.081901860, 58.395, 2976.0, 54.5527
22.125367620, 58.395, 2853.0, 53.4135
22.168833380, 58.395, 3001.0, 54.7814
22.212299140, 58.395, 2887.0, 53.7308
22.255764900, 58.395, 2901.0, 53.8609
22.299230660, 58.395, 2914.0, 53.9815
22.342696420, 58.395, 2903.0, 53.8795
22.386162180, 58.395, 2855.0, 53.4322
22.429627940, 58.395, 2924.0, 54.0740
22.473093700, 58.395, 2926.0, 54.0925
22.516559460, 58.395, 2815.0, 53.0566
22.560025220, 58.395, 3000.0, 54.7723
22.603490980, 58.395, 2935.0, 54.1756
22.646956740, 58.395, 2946.0, 54.2771
22.690422500, 58.395, 2849.0, 53.3760
22.733888260, 58.395, 2928.0, 54.1110
22.777354020, 58.395, 2936.0, 54.1849
22.820819780, 58.395, 2950.0, 54.3139
22.864285540, 58.395, 2789.0, 52.8110
22.907751300, 58.395, 2902.0, 53.8702
22.951217060, 58.395, 2885.0, 53.7122
22.994682820, 58.395, 2913.0, 53.9722
23.038148580, 58.395, 2971.0, 54.5069
23.081614340, 58.395, 2901.0, 53.8609
23.125080100, 58.395, 2821.0, 53.1131
23.168545860, 58.395, 2933.0, 54.1572
23.212011620, 58.395, 2951.0, 54.3231
23.255477380, 58.395, 2858.0, 53.4603
23.298943140, 58.395, 2830.0, 53.1977
23.342408900, 58.395, 2906.0, 53.9073
23.385874660, 58.395, 2816.0, 53.0660
23.429340420, 58.395, 2938.0, 54.2033
23.472806180, 58.395, 2914.0, 53.9815
23.516271940, 58.395, 2828.0, 53.1789
23.559737700, 58.395, 2846.0, 53.3479
23.603203460, 58.395, 2860.0, 53.4790
23.646669220, 58.395, 2850.0, 53.3854
23.690134980, 58.395, 2844.0, 53.3292
23.733600740, 58.395, 2815.0, 53.0566
23.777066500, 58.395, 2857.0, 53.4509
23.820532260, 58.395, 2782.0, 52.7447
23.863998020, 58.395, 2752.0, 52.4595
23.907463780, 58.395, 2797.0, 52.8867
23.950929540, 58.395, 2858.0, 53.4603
23.994395300, 58.395, 2690.0, 51.8652
24.037861060, 58.395, 2815.0, 53.0566
24.081326820, 58.395, 2818.0, 53.0848
24.124792580, 58.395, 2922.0, 54.0555
24.168258340, 58.395, 2784.0, 52.7636
24.211724100, 58.395, 2713.0, 52.0865
24.255189860, 58.395, 2775.0, 52.6783
24.298655620, 58.395, 2795.0, 52.8678
24.342121380, 58.395, 2722.0, 52.1728
24.385587140, 58.395, 2817.0, 53.0754
24.429052900, 58.395, 2827.0, 53.1695
24.472518660, 58.395, 2700.0, 51.9615
24.515984420, 58.395, 2763.0, 52.5642
24.559450180, 58.395, 2671.0, 51.6817
24.602915940, 58.395, 2685.0, 51.8170
24.646381700, 58.395, 2711.0, 52.0673
24.689847460, 58.395, 2714.0, 52.0961
24.733313220, 58.395, 2759.0, 52.5262
24.776778980, 58.395, 2718.0, 52.1344
24.820244740, 58.395, 2627.0, 51.2543
24.863710500, 58.395, 2650.0, 51.4782
24.907176260, 58.395, 2617.0, 51.1566
24.950642020, 58.395, 2712.0, 52.0769
24.994107780, 58.395, 2659.0, 51.5655
25.037573540, 58.395, 2666.0, 51.6333
25.081039300, 58.395, 2629.0, 51.2738
25.124505060, 58.395, 2640.0, 51.3809
25.167970820, 58.395, 2663.0, 51.6043
25.211436580, 58.395, 2642.0, 51.4004
25.254902340, 58.395, 2683.0, 51.7977
25.298368100, 58.395, 2546.0, 50.4579
25.341833860, 58.395, 2536.0, 50.3587
25.385299620, 58.395, 2593.0, 50.9215
25.428765380, 58.395, 2660.0, 51.5752
25.472231140, 58.395, 2641.0, 51.3907
25.515696900, 58.395, 2427.0, 49.2646
25.559162660, 58.395, 2528.0, 50.2792
25.602628420, 58.395, 2515.0, 50.1498
25.646094180, 58.395, 2453.0, 49.5278
25.689559940, 58.395, 2524.0, 50.2394
25.733025700, 58.395, 2490.0, 49.8999
25.776491460, 58.395, 2431.0, 49.3052
25.819957220, 58.395, 2431.0, 49.3052
25.863422980, 58.395, 2510.0, 50.0999
25.906888740, 58.395, 2455.0, 49.5480
25.950354500, 58.395, 2473.0, 49.7293
25.993820260, 58.395, 2399.0, 48.9796
26.037286020, 58.395, 2350.0, 48.4768
26.080751780, 58.395, 2396.0, 48.9490
26.124217540, 58.395, 2404.0, 49.0306
26.167683300, 58.395, 2441.0, 49.4065
26.211149060, 58.395, 2353.0, 48.5077
26.254614820, 58.395, 2489.0, 49.8899
26.298080580, 58.395, 2350.0, 48.4768
26.341546340, 58.395, 2341.0, 48.3839
26.385012100, 58.395, 2318.0, 48.1456
26.428477860, 58.395, 2228.0, 47.2017
26.471943620, 58.395, 2293.0, 47.8853
26.515409380, 58.395, 2301.0, 47.9687
26.558875140, 58.395, 2316.0, 48.1248
26.602340900, 58.395, 2272.0, 47.6655
26.645806660, 58.395, 2252.0, 47.4552
26.689272420, 58.395, 2291.0, 47.8644
26.732738180, 58.395, 2287.0, 47.8226
26.776203940, 58.395, 2306.0, 48.0208
26.819669700, 58.395, 2279.0, 47.7389
26.863135460, 58.395, 2206.0, 46.9681
26.906601220, 58.395, 2246.0, 47.3920
26.950066980, 58.395, 2156.0, 46.4327
26.993532740, 58.395, 2317.0, 48.1352
27.036998500, 58.395, 2195.0, 46.8508
27.080464260, 58.395, 2205.0, 46.9574
27.123930020, 58.395, 2143.0, 46.2925
27.167395780, 58.395, 2149.0, 46.3573
27.210861540, 58.395, 2135.0, 46.2061
27.254327300, 58.395, 2221.0, 47.1275
27.297793060, 58.395, 2083.0, 45.6399
27.341258820, 58.395, 2131.0, 46.1628
27.384724580, 58.395, 2159.0, 46.4650
27.428190340, 58.395, 2129.0, 46.1411
27.471656100, 58.395, 2078.0, 45.5851
27.515121860, 58.395, 2110.0, 45.9347
27.558587620, 58.395, 2104.0, 45.8694
27.602053380, 58.395, 2126.0, 46.1086
27.645519140, 58.395, 1983.0, 44.5309
27.688984900, 58.395, 2053.0, 45.3100
27.732450660, 58.395, 2069.0, 45.4863
27.775916420, 58.395, 2032.0, 45.0777
27.819382180, 58.395, 2102.0, 45.8476
27.862847940, 58.395, 1984.0, 44.5421
27.906313700, 58.395, 1989.0, 44.5982
27.949779460, 58.395, 2049.0, 45.2659
27.993245220, 58.395, 2047.0, 45.2438
28.036710980, 58.395, 2002.0, 44.7437
28.080176740, 58.395, 2017.0, 44.9110
28.123642500, 58.395, 2060.0, 45.3872
28.167108260, 58.395, 2053.0, 45.3100
28.210574020, 58.395, 1922.0, 43.8406
28.254039780, 58.395, 2084.0, 45.6508
28.297505540, 58.395, 2017.0, 44.9110
28.340971300, 58.395, 1923.0, 43.8520
28.384437060, 58.395, 1981.0, 44.5084
28.427902820, 58.395, 1920.0, 43.8178
28.471368580, 58.395, 1888.0, 43.4511
28.514834340, 58.395, 1867.0, 43.2088
28.558300100, 58.395, 2007.0, 44.7996
28.601765860, 58.395, 1918.0, 43.7950
28.645231620, 58.395, 1926.0, 43.8862
28.688697380, 58.395, 1854.0, 43.0581
28.732163140, 58.395, 1901.0, 43.6005
28.775628900, 58.395, 1900.0, 43.5890
28.819094660, 58.395, 1858.0, 43.1045
28.862560420, 58.395, 1878.0, 43.3359
28.906026180, 58.395, 1914.0, 43.7493
28.949491940, 58.395, 1816.0, 42.6146
28.992957700, 58.395, 1787.0, 42.2729
29.036423460, 58.395, 1834.0, 42.8252
29.079889220, 58.395, 1949.0, 44.1475
29.123354980, 58.395, 1922.0, 43.8406
29.166820740, 58.395, 1900.0, 43.5890
29.210286500, 58.395, 1828.0, 42.7551
29.253752260, 58.395, 1788.0, 42.2847
29.297218020, 58.395, 1828.0, 42.7551
29.340683780, 58.395, 1827.0, 42.7434
29.384149540, 58.395, 1747.0, 41.7971
29.427615300, 58.395, 1851.0, 43.0232
29.471081060, 58.395, 1771.0, 42.0833
29.514546820, 58.395, 1790.0, 42.3084
29.558012580, 58.395, 1765.0, 42.0119
29.601478340, 58.395, 1796.0, 42.3792
29.644944100, 58.395, 1791.0, 42.3202
29.688409860, 58.395, 1689.0, 41.0974
29.731875620, 58.395, 1790.0, 42.3084
29.775341380, 58.395, 1789.0, 42.2966
29.818807140, 58.395, 1814.0, 42.5911
29.862272900, 58.395, 1690.0, 41.1096
29.905738660, 58.395, 1701.0, 41.2432
29.949204420, 58.395, 1651.0, 40.6325
29.992670180, 58.395, 1810.0, 42.5441
30.036135940, 58.395, 1708.0, 41.3280
30.079601700, 58.395, 1740.0, 41.7133
30.123067460, 58.395, 1761.0, 41.9643
30.166533220, 58.395, 1703.0, 41.2674
30.209998980, 58.395, 1761.0, 41.9643
30.253464740, 58.395, 1716.0, 41.4246
30.296930500, 58.395, 1760.0, 41.9524
30.340396260, 58.395, 1792.0, 42.3320
30.383862020, 58.395, 1692.0, 41.1339
30.427327780, 58.395, 1693.0, 41.1461
30.470793540, 58.395, 1593.0, 39.9124
30.514259300, 58.395, 1622.0, 40.2741
30.557725060, 58.395, 1594.0, 39.9249
30.601190820, 58.395, 1592.0, 39.8999
30.644656580, 58.395, 1654.0, 40.6694
30.688122340, 58.395, 1677.0, 40.9512
30.731588100, 58.395, 1679.0, 40.9756
30.775053860, 58.395, 1565.0, 39.5601
30.818519620, 58.395, 1680.0, 40.9878
30.861985380, 58.395, 1645.0, 40.5586
30.905451140, 58.395, 1660.0, 40.7431
30.948916900, 58.395, 1642.0, 40.5216
30.992382660, 58.395, 1599.0, 39.9875
31.035848420, 58.395, 1666.0, 40.8167
31.079314180, 58.395, 1620.0, 40.2492
31.122779940, 58.395, 1538.0, 39.2173
31.166245700, 58.395, 1672.0, 40.8901
31.209711460, 58.395, 1657.0, 40.7063
31.253177220, 58.395, 1610.0, 40.1248
31.296642980, 58.395, 1571.0, 39.6358
31.340108740, 58.395, 1627.0, 40.3361
31.383574500, 58.395, 1527.0, 39.0768
31.427040260, 58.395, 1550.0, 39.3700
31.470506020, 58.395, 1630.0, 40.3733
31.513971780, 58.395, 1588.0, 39.8497
31.557437540, 58.395, 1557.0, 39.4588
31.600903300, 58.395, 1517.0, 38.9487
31.644369060, 58.395, 1470.0, 38.3406
31.687834820, 58.395, 1582.0, 39.7744
31.731300580, 58.395, 1483.0, 38.5097
31.774766340, 58.395, 1565.0, 39.5601
31.818232100, 58.395, 1526.0, 39.0640
31.861697860, 58.395, 1542.0, 39.2683
31.905163620, 58.395, 1525.0, 39.0512
31.948629380, 58.395, 1562.0, 39.5221
31.992095140, 58.395, 1562.0, 39.5221
32.035560900, 58.395, 1562.0, 39.5221
32.079026660, 58.395, 1550.0, 39.3700
32.122492420, 58.395, 1456.0, 38.1576
32.165958180, 58.395, 1536.0, 39.1918
32.209423940, 58.395, 1578.0, 39.7240
32.252889700, 58.395, 1557.0, 39.4588
32.296355460, 58.395, 1431.0, 37.8286
32.339821220, 58.395, 1498.0, 38.7040
32.383286980, 58.395, 1516.0, 38.9358
32.426752740, 58.395, 1469.0, 38.3275
32.470218500, 58.395, 1511.0, 38.8716
32.513684260, 58.395, 1545.0, 39.3065
32.557150020, 58.395, 1480.0, 38.4708
32.600615780, 58.395, 1477.0, 38.4318
32.644081540, 58.395, 1465.0, 38.2753
32.687547300, 58.395, 1501.0, 38.7427
32.731013060, 58.395, 1493.0, 38.6394
32.774478820, 58.395, 1465.0, 38.2753
32.817944580, 58.395, 1468.0, 38.3145
32.861410340, 58.395, 1406.0, 37.4967
32.904876100, 58.395, 1369.0, 37.0000
32.948341860, 58.395, 1378.0, 37.1214
32.991807620, 58.395, 1408.0, 37.5233
33.035273380, 58.395, 1434.0, 37.8682
33.078739140, 58.395, 1416.0, 37.6298
33.122204900, 58.395, 1445.0, 38.0132
33.165670660, 58.395, 1386.0, 37.2290
33.209136420, 58.395, 1513.0, 38.8973
33.252602180, 58.395, 1450.0, 38.0789
33.296067940, 58.395, 1473.0, 38.3797
33.339533700, 58.395, 1436.0, 37.8946
33.382999460, 58.395, 1377.0, 37.1080
33.426465220, 58.395, 1372.0, 37.0405
33.469930980, 58.395, 1431.0, 37.8286
33.513396740, 58.395, 1372.0, 37.0405
33.556862500, 58.395, 1428.0, 37.7889
33.600328260, 58.395, 1397.0, 37.3765
33.643794020, 58.395, 1365.0, 36.9459
33.687259780, 58.395, 1350.0, 36.7423
33.730725540, 58.395, 1413.0, 37.5899
33.774191300, 58.395, 1402.0, 37.4433
33.817657060, 58.395, 1322.0, 36.3593
33.861122820, 58.395, 1372.0, 37.0405
33.904588580, 58.395, 1447.0, 38.0395
33.948054340, 58.395, 1440.0, 37.9473
33.991520100, 58.395, 1418.0, 37.6563
34.034985860, 58.395, 1367.0, 36.9730
34.078451620, 58.395, 1354.0, 36.7967
34.121917380, 58.395, 1369.0, 37.0000
34.165383140, 58.395, 1363.0, 36.9188
34.208848900, 58.395, 1281.0, 35.7911
34.252314660, 58.395, 1399.0, 37.4032
34.295780420, 58.395, 1384.0, 37.2022
34.339246180, 58.395, 1332.0, 36.4966
34.382711940, 58.395, 1329.0, 36.4555
34.426177700, 58.395, 1346.0, 36.6879
34.469643460, 58.395, 1336.0, 36.5513
34.513109220, 58.395, 1332.0, 36.4966
34.556574980, 58.395, 1336.0, 36.5513
34.600040740, 58.395, 1361.0, 36.8917
34.643506500, 58.395, 1366.0, 36.9594
34.686972260, 58.395, 1293.0, 35.9583
34.730438020, 58.395, 1326.0, 36.4143
34.773903780, 58.395, 1327.0, 36.4280
34.817369540, 58.395, 1385.0, 37.2156
34.860835300, 58.395, 1262.0, 35.5246
34.904301060, 58.395, 1301.0, 36.0694
34.947766820, 58.395, 1402.0, 37.4433
34.991232580, 58.395, 1353.0, 36.7831
35.034698340, 58.395, 1381.0, 37.1618
35.078164100, 58.395, 1241.0, 35.2278
35.121629860, 58.395, 1288.0, 35.8887
35.165095620, 58.395, 1286.0, 35.8608
35.208561380, 58.395, 1318.0, 36.3043
35.252027140, 58.395, 1300.0, 36.0555
35.295492900, 58.395, 1355.0, 36.8103
35.338958660, 58.395, 1300.0, 36.0555
35.382424420, 58.395, 1302.0, 36.0832
35.425890180, 58.395, 1297.0, 36.0139
35.469355940, 58.395, 1308.0, 36.1663
35.512821700, 58.395, 1331.0, 36.4829
35.556287460, 58.395, 1272.0, 35.6651
35.599753220, 58.395, 1278.0, 35.7491
35.643218980, 58.395, 1359.0, 36.8646
35.686684740, 58.395, 1313.0, 36.2353
35.730150500, 58.395, 1281.0, 35.7911
35.773616260, 58.395, 1378.0, 37.1214
35.817082020, 58.395, 1295.0, 35.9861
35.860547780, 58.395, 1258.0, 35.4683
35.904013540, 58.395, 1290.0, 35.9166
35.947479300, 58.395, 1267.0, 35.5949
35.990945060, 58.395, 1290.0, 35.9166
36.034410820, 58.395, 1299.0, 36.0416
36.077876580, 58.395, 1268.0, 35.6090
36.121342340, 58.395, 1222.0, 34.9571
36.164808100, 58.395, 1325.0, 36.4005
36.208273860, 58.395, 1315.0, 36.2629
36.251739620, 58.395, 1288.0, 35.8887
36.295205380, 58.395, 1214.0, 34.8425
36.338671140, 58.395, 1252.0, 35.3836
36.382136900, 58.395, 1320.0, 36.3318
36.425602660, 58.395, 1311.0, 36.2077
36.469068420, 58.395, 1309.0, 36.1801
36.512534180, 58.395, 1331.0, 36.4829
36.555999940, 58.395, 1261.0, 35.5106
36.599465700, 58.395, 1276.0, 35.7211
36.642931460, 58.395, 1266.0, 35.5809
36.686397220, 58.395, 1291.0, 35.9305
36.729862980, 58.395, 1263.0, 35.5387
36.773328740, 58.395, 1182.0, 34.3802
36.816794500, 58.395, 1316.0, 36.2767
36.860260260, 58.395, 1253.0, 35.3977
36.903726020, 58.395, 1208.0, 34.7563
36.947191780, 58.395, 1277.0, 35.7351
36.990657540, 58.395, 1244.0, 35.2704
37.034123300, 58.395, 1299.0, 36.0416
37.077589060, 58.395, 1254.0, 35.4119
37.121054820, 58.395, 1260.0, 35.4965
37.164520580, 58.395, 1247.0, 35.3129
37.207986340, 58.395, 1309.0, 36.1801
37.251452100, 58.395, 1242.0, 35.2420
37.294917860, 58.395, 1222.0, 34.9571
37.338383620, 58.395, 1309.0, 36.1801
37.381849380, 58.395, 1256.0, 35.4401
37.425315140, 58.395, 1183.0, 34.3948
37.468780900, 58.395, 1244.0, 35.2704
37.512246660, 58.395, 1259.0, 35.4824
37.555712420, 58.395, 1317.0, 36.2905
37.599178180, 58.395, 1228.0, 35.0428
37.642643940, 58.395, 1208.0, 34.7563
37.686109700, 58.395, 1231.0, 35.0856
37.729575460, 58.395, 1246.0, 35.2987
37.773041220, 58.395, 1216.0, 34.8712
37.816506980, 58.395, 1229.0, 35.0571
37.859972740, 58.395, 1277.0, 35.7351
37.903438500, 58.395, 1226.0, 35.0143
37.946904260, 58.395, 1231.0, 35.0856
37.990370020, 58.395, 1191.0, 34.5109
38.033835780, 58.395, 1197.0, 34.5977
38.077301540, 58.395, 1266.0, 35.5809
38.120767300, 58.395, 1244.0, 35.2704
38.164233060, 58.395, 1190.0, 34.4964
38.207698820, 58.395, 1236.0, 35.1568
38.251164580, 58.395, 1161.0, 34.0735
38.294630340, 58.395, 1325.0, 36.4005
38.338096100, 58.395, 1236.0, 35.1568
38.381561860, 58.395, 1182.0, 34.3802
38.425027620, 58.395, 1299.0, 36.0416
38.468493380, 58.395, 1195.0, 34.5688
38.511959140, 58.395, 1220.0, 34.9285
38.555424900, 58.395, 1167.0, 34.1614
38.598890660, 58.395, 1235.0, 35.1426
38.642356420, 58.395, 1208.0, 34.7563
38.685822180, 58.395, 1112.0, 33.3467
38.729287940, 58.395, 1210.0, 34.7851
38.772753700, 58.395, 1241.0, 35.2278
38.816219460, 58.395, 1259.0, 35.4824
38.859685220, 58.395, 1208.0, 34.7563
38.903150980, 58.395, 1093.0, 33.0606
38.946616740, 58.395, 1215.0, 34.8569
38.990082500, 58.395, 1208.0, 34.7563
39.033548260, 58.395, 1133.0, 33.6601
39.077014020, 58.395, 1228.0, 35.0428
39.120479780, 58.395, 1204.0, 34.6987
39.163945540, 58.395, 1211.0, 34.7994
39.207411300, 58.395, 1140.0, 33.7639
39.250877060, 58.395, 1171.0, 34.2199
39.294342820, 58.395, 1239.0, 35.1994
39.337808580, 58.395, 1191.0, 34.5109
39.381274340, 58.395, 1143.0, 33.8083
39.424740100, 58.395, 1182.0, 34.3802
39.468205860, 58.395, 1139.0, 33.7491
39.511671620, 58.395, 1196.0, 34.5832
39.555137380, 58.395, 1130.0, 33.6155
39.598603140, 58.395, 1107.0, 33.2716
39.642068900, 58.395, 1186.0, 34.4384
39.685534660, 58.395, 1174.0, 34.2637
39.729000420, 58.395, 1213.0, 34.8281
39.772466180, 58.395, 1120.0, 33.4664
39.815931940, 58.395, 1252.0, 35.3836
39.859397700, 58.395, 1171.0, 34.2199
39.902863460, 58.395, 1168.0, 34.1760
39.946329220, 58.395, 1167.0, 34.1614
39.989794980, 58.395, 1129.0, 33.6006
40.033260740, 58.395, 1199.0, 34.6266
40.076726500, 58.395, 1159.0, 34.0441
40.120192260, 58.395, 1191.0, 34.5109
40.163658020, 58.395, 1184.0, 34.4093
40.207123780, 58.395, 1149.0, 33.8969
40.250589540, 58.395, 1164.0, 34.1174
40.294055300, 58.395, 1128.0, 33.5857
40.337521060, 58.395, 1197.0, 34.5977
40.380986820, 58.395, 1084.0, 32.9242
40.424452580, 58.395, 1200.0, 34.6410
40.467918340, 58.395, 1144.0, 33.8231
40.511384100, 58.395, 1160.0, 34.0588
40.554849860, 58.395, 1149.0, 33.8969
40.598315620, 58.395, 1175.0, 34.2783
40.641781380, 58.395, 1177.0, 34.3074
40.685247140, 58.395, 1228.0, 35.0428
40.728712900, 58.395, 1115.0, 33.3916
40.772178660, 58.395, 1096.0, 33.1059
40.815644420, 58.395, 1119.0, 33.4515
40.859110180, 58.395, 1121.0, 33.4813
40.902575940, 58.395, 1182.0, 34.3802
40.946041700, 58.395, 1103.0, 33.2114
40.989507460, 58.395, 1108.0, 33.2866
41.032973220, 58.395, 1153.0, 33.9559
41.076438980, 58.395, 1127.0, 33.5708
41.119904740, 58.395, 1105.0, 33.2415
41.163370500, 58.395, 1105.0, 33.2415
41.206836260, 58.395, 1140.0, 33.7639
41.250302020, 58.395, 1121.0, 33.4813
41.293767780, 58.395, 1114.0, 33.3766
41.337233540, 58.395, 1121.0, 33.4813
41.380699300, 58.395, 1104.0, 33.2265
41.424165060, 58.395, 1031.0, 32.1092
41.467630820, 58.395, 1106.0, 33.2566
41.511096580, 58.395, 1051.0, 32.4191
41.554562340, 58.395, 1123.0, 33.5112
41.598028100, 58.395, 1118.0, 33.4365
41.641493860, 58.395, 1119.0, 33.4515
41.684959620, 58.395, 1097.0, 33.1210
41.728425380, 58.395, 1121.0, 33.4813
41.771891140, 58.395, 1116.0, 33.4066
41.815356900, 58.395, 1104.0, 33.2265
41.858822660, 58.395, 1135.0, 33.6898
41.902288420, 58.395, 1079.0, 32.8481
41.945754180, 58.395, 1102.0, 33.1964
41.989219940, 58.395, 1129.0, 33.6006
42.032685700, 58.395, 1164.0, 34.1174
42.076151460, 58.395, 1054.0, 32.4654
42.119617220, 58.395, 1021.0, 31.9531
42.163082980, 58.395, 1105.0, 33.2415
42.206548740, 58.395, 1102.0, 33.1964
42.250014500, 58.395, 1103.0, 33.2114
42.293480260, 58.395, 1176.0, 34.2929
42.336946020, 58.395, 1096.0, 33.1059
42.380411780, 58.395, 1081.0, 32.8786
42.423877540, 58.395, 1094.0, 33.0757
42.467343300, 58.395, 1111.0, 33.3317
42.510809060, 58.395, 1065.0, 32.6343
42.554274820, 58.395, 1105.0, 33.2415
42.597740580, 58.395, 1143.0, 33.8083
42.641206340, 58.395, 1029.0, 32.0780
42.684672100, 58.395, 1086.0, 32.9545
42.728137860, 58.395, 1086.0, 32.9545
42.771603620, 58.395, 1054.0, 32.4654
42.815069380, 58.395, 1058.0, 32.5269
42.858535140, 58.395, 1061.0, 32.5730
42.902000900, 58.395, 1106.0, 33.2566
42.945466660, 58.395, 1089.0, 33.0000
42.988932420, 58.395, 1093.0, 33.0606
43.032398180, 58.395, 1048.0, 32.3728
43.075863940, 58.395, 1061.0, 32.5730
43.119329700, 58.395, 1063.0, 32.6037
43.162795460, 58.395, 1098.0, 33.1361
43.206261220, 58.395, 1044.0, 32.3110
43.249726980, 58.395, 1100.0, 33.1662
43.293192740, 58.395, 1085.0, 32.9393
43.336658500, 58.395, 1085.0, 32.9393
43.380124260, 58.395, 1000.0, 31.6228
43.423590020, 58.395, 1097.0, 33.1210
43.467055780, 58.395, 1022.0, 31.9687
43.510521540, 58.395, 1018.0, 31.9061
43.553987300, 58.395, 1107.0, 33.2716
43.597453060, 58.395, 999.0, 31.6070
43.640918820, 58.395, 1063.0, 32.6037
43.684384580, 58.395, 1024.0, 32.0000
43.727850340, 58.395, 1090.0, 33.0151
43.771316100, 58.395, 1072.0, 32.7414
43.814781860, 58.395, 1030.0, 32.0936
43.858247620, 58.395, 1052.0, 32.4345
43.901713380, 58.395, 1054.0, 32.4654
43.945179140, 58.395, 1072.0, 32.7414
43.988644900, 58.395, 1026.0, 32.0312
44.032110660, 58.395, 997.0, 31.5753
44.075576420, 58.395, 1094.0, 33.0757
44.119042180, 58.395, 1050.0, 32.4037
44.162507940, 58.395, 1085.0, 32.9393
44.205973700, 58.395, 1013.0, 31.8277
44.249439460, 58.395, 1094.0, 33.0757
44.292905220, 58.395, 1057.0, 32.5115
44.336370980, 58.395, 999.0, 31.6070
44.379836740, 58.395, 1027.0, 32.0468
44.423302500, 58.395, 1035.0, 32.1714
44.466768260, 58.395, 1001.0, 31.6386
44.510234020, 58.395, 1087.0, 32.9697
44.553699780, 58.395, 1057.0, 32.5115
44.597165540, 58.395, 1058.0, 32.5269
44.640631300, 58.395, 1024.0, 32.0000
44.684097060, 58.395, 1038.0, 32.2180
44.727562820, 58.395, 978.0, 31.2730
44.771028580, 58.395, 967.0, 31.0966
44.814494340, 58.395, 1007.0, 31.7333
44.857960100, 58.395, 1034.0, 32.1559
44.901425860, 58.395, 998.0, 31.5911
44.944891620, 58.395, 1021.0, 31.9531
44.988357380, 58.395, 1007.0, 31.7333
45.031823140, 58.395, 1042.0, 32.2800
45.075288900, 58.395, 965.0, 31.0644
45.118754660, 58.395, 1029.0, 32.0780
45.162220420, 58.395, 977.0, 31.2570
45.205686180, 58.395, 1046.0, 32.3419
45.249151940, 58.395, 1038.0, 32.2180
45.292617700, 58.395, 979.0, 31.2890
45.336083460, 58.395, 1041.0, 32.2645
45.379549220, 58.395, 1043.0, 32.2955
45.423014980, 58.395, 976.0, 31.2410
45.466480740, 58.395, 985.0, 31.3847
45.509946500, 58.395, 969.0, 31.1288
45.553412260, 58.395, 1012.0, 31.8119
45.596878020, 58.395, 960.0, 30.9839
45.640343780, 58.395, 1045.0, 32.3265
45.683809540, 58.395, 1029.0, 32.0780
45.727275300, 58.395, 1020.0, 31.9374
45.770741060, 58.395, 1016.0, 31.8748
45.814206820, 58.395, 1038.0, 32.2180
45.857672580, 58.395, 995.0, 31.5436
45.901138340, 58.395, 1003.0, 31.6702
45.944604100, 58.395, 1011.0, 31.7962
45.988069860, 58.395, 907.0, 30.1164
46.031535620, 58.395, 1025.0, 32.0156
46.075001380, 58.395, 926.0, 30.4302
46.118467140, 58.395, 1035.0, 32.1714
46.161932900, 58.395, 964.0, 31.0483
46.205398660, 58.395, 981.0, 31.3209
46.248864420, 58.395, 958.0, 30.9516
46.292330180, 58.395, 945.0, 30.7409
46.335795940, 58.395, 964.0, 31.0483
46.379261700, 58.395, 1014.0, 31.8434
46.422727460, 58.395, 1003.0, 31.6702
46.466193220, 58.395, 941.0, 30.6757
46.509658980, 58.395, 997.0, 31.5753
46.553124740, 58.395, 1008.0, 31.7490
46.596590500, 58.395, 1013.0, 31.8277
46.640056260, 58.395, 969.0, 31.1288
46.683522020, 58.395, 939.0, 30.6431
46.726987780, 58.395, 976.0, 31.2410
46.770453540, 58.395, 973.0, 31.1929
46.813919300, 58.395, 1025.0, 32.0156
46.857385060, 58.395, 1004.0, 31.6860
46.900850820, 58.395, 959.0, 30.9677
46.944316580, 58.395, 993.0, 31.5119
46.987782340, 58.395, 1016.0, 31.8748
47.031248100, 58.395, 994.0, 31.5278
47.074713860, 58.395, 1046.0, 32.3419
47.118179620, 58.395, 957.0, 30.9354
47.161645380, 58.395, 1012.0, 31.8119
47.205111140, 58.395, 1005.0, 31.7017
47.248576900, 58.395, 1004.0, 31.6860
47.292042660, 58.395, 1008.0, 31.7490
47.335508420, 58.395, 1017.0, 31.8904
47.378974180, 58.395, 1019.0, 31.9218
47.422439940, 58.395, 959.0, 30.9677
47.465905700, 58.395, 978.0, 31.2730
47.509371460, 58.395, 980.0, 31.3050
47.552837220, 58.395, 948.0, 30.7896
47.596302980, 58.395, 965.0, 31.0644
47.639768740, 58.395, 983.0, 31.3528
47.683234500, 58.395, 949.0, 30.8058
47.726700260, 58.395, 980.0, 31.3050
47.770166020, 58.395, 999.0, 31.6070
47.813631780, 58.395, 911.0, 30.1828
47.857097540, 58.395, 947.0, 30.7734
47.900563300, 58.395, 907.0, 30.1164
47.944029060, 58.395, 919.0, 30.3150
47.987494820, 58.395, 970.0, 31.1448
48.030960580, 58.395, 960.0, 30.9839
48.074426340, 58.395, 927.0, 30.4467
48.117892100, 58.395, 996.0, 31.5595
48.161357860, 58.395, 971.0, 31.1609
48.204823620, 58.395, 939.0, 30.6431
48.248289380, 58.395, 953.0, 30.8707
48.291755140, 58.395, 954.0, 30.8869
48.335220900, 58.395, 995.0, 31.5436
48.378686660, 58.395, 944.0, 30.7246
48.422152420, 58.395, 972.0, 31.1769
48.465618180, 58.395, 932.0, 30.5287
48.509083940, 58.395, 1005.0, 31.7017
48.552549700, 58.395, 911.0, 30.1828
48.596015460, 58.395, 856.0, 29.2575
48.639481220, 58.395, 917.0, 30.2820
48.682946980, 58.395, 1029.0, 32.0780
48.726412740, 58.395, 927.0, 30.4467
48.769878500, 58.395, 931.0, 30.5123
48.813344260, 58.395, 962.0, 31.0161
48.856810020, 58.395, 962.0, 31.0161
48.900275780, 58.395, 968.0, 31.1127
48.943741540, 58.395, 935.0, 30.5778
48.987207300, 58.395, 911.0, 30.1828
49.030673060, 58.395, 932.0, 30.5287
49.074138820, 58.395, 923.0, 30.3809
49.117604580, 58.395, 982.0, 31.3369
49.161070340, 58.395, 921.0, 30.3480
49.204536100, 58.395, 888.0, 29.7993
49.248001860, 58.395, 946.0, 30.7571
49.291467620, 58.395, 872.0, 29.5296
49.334933380, 58.395, 905.0, 30.0832
49.378399140, 58.395, 948.0, 30.7896
49.421864900, 58.395, 928.0, 30.4631
49.465330660, 58.395, 950.0, 30.8221
49.508796420, 58.395, 936.0, 30.5941
49.552262180, 58.395, 866.0, 29.4279
49.595727940, 58.395, 887.0, 29.7825
49.639193700, 58.395, 950.0, 30.8221
49.682659460, 58.395, 917.0, 30.2820
49.726125220, 58.395, 862.0, 29.3598
49.769590980, 58.395, 835.0, 28.8964
49.813056740, 58.395, 968.0, 31.1127
49.856522500, 58.395, 921.0, 30.3480
49.899988260, 58.395, 920.0, 30.3315
49.943454020, 58.395, 889.0, 29.8161
49.986919780, 58.395, 897.0, 29.9500
50.030385540, 58.395, 871.0, 29.5127
50.073851300, 58.395, 890.0, 29.8329
50.117317060, 58.395, 926.0, 30.4302
50.160782820, 58.395, 928.0, 30.4631
50.204248580, 58.395, 916.0, 30.2655
50.247714340, 58.395, 935.0, 30.5778
50.291180100, 58.395, 905.0, 30.0832
50.334645860, 58.395, 903.0, 30.0500
50.378111620, 58.395, 866.0, 29.4279
50.421577380, 58.395, 909.0, 30.1496
50.465043140, 58.395, 881.0, 29.6816
50.508508900, 58.395, 909.0, 30.1496
50.551974660, 58.395, 902.0, 30.0333
50.595440420, 58.395, 844.0, 29.0517
50.638906180, 58.395, 878.0, 29.6311
50.682371940, 58.395, 917.0, 30.2820
50.725837700, 58.395, 850.0, 29.1548
50.769303460, 58.395, 879.0, 29.6479
50.812769220, 58.395, 900.0, 30.0000
50.856234980, 58.395, 817.0, 28.5832
50.899700740, 58.395, 948.0, 30.7896
50.943166500, 58.395, 863.0, 29.3769
50.986632260, 58.395, 888.0, 29.7993
51.030098020, 58.395, 888.0, 29.7993
51.073563780, 58.395, 876.0, 29.5973
51.117029540, 58.395, 866.0, 29.4279
51.160495300, 58.395, 857.0, 29.2746
51.203961060, 58.395, 835.0, 28.8964
51.247426820, 58.395, 887.0, 29.7825
51.290892580, 58.395, 857.0, 29.2746
51.334358340, 58.395, 840.0, 28.9828
51.377824100, 58.395, 855.0, 29.2404
51.421289860, 58.395, 860.0, 29.3258
51.464755620, 58.395, 876.0, 29.5973
51.508221380, 58.395, 843.0, 29.0345
51.551687140, 58.395, 878.0, 29.6311
51.595152900, 58.395, 832.0, 28.8444
51.638618660, 58.395, 873.0, 29.5466
51.682084420, 58.395, 867.0, 29.4449
51.725550180, 58.395, 873.0, 29.5466
51.769015940, 58.395, 829.0, 28.7924
51.812481700, 58.395, 817.0, 28.5832
51.855947460, 58.395, 816.0, 28.5657
51.899413220, 58.395, 869.0, 29.4788
51.942878980, 58.395, 849.0, 29.1376
51.986344740, 58.395, 799.0, 28.2666
52.029810500, 58.395, 823.0, 28.6880
52.073276260, 58.395, 756.0, 27.4955
52.116742020, 58.395, 815.0, 28.5482
52.160207780, 58.395, 787.0, 28.0535
52.203673540, 58.395, 816.0, 28.5657
52.247139300, 58.395, 821.0, 28.6531
52.290605060, 58.395, 752.0, 27.4226
52.334070820, 58.395, 812.0, 28.4956
52.377536580, 58.395, 817.0, 28.5832
52.421002340, 58.395, 866.0, 29.4279
52.464468100, 58.395, 744.0, 27.2764
52.507933860, 58.395, 770.0, 27.7489
52.551399620, 58.395, 788.0, 28.0713
52.594865380, 58.395, 789.0, 28.0891
52.638331140, 58.395, 825.0, 28.7228
52.681796900, 58.395, 737.0, 27.1477
52.725262660, 58.395, 774.0, 27.8209
52.768728420, 58.395, 829.0, 28.7924
52.812194180, 58.395, 779.0, 27.9106
52.855659940, 58.395, 800.0, 28.2843
52.899125700, 58.395, 789.0, 28.0891
52.942591460, 58.395, 798.0, 28.2489
52.986057220, 58.395, 760.0, 27.5681
53.029522980, 58.395, 789.0, 28.0891
53.072988740, 58.395, 777.0, 27.8747
53.116454500, 58.395, 801.0, 28.3019
53.159920260, 58.395, 805.0, 28.3725
53.203386020, 58.395, 775.0, 27.8388
53.246851780, 58.395, 769.0, 27.7308
53.290317540, 58.395, 715.0, 26.7395
53.333783300, 58.395, 792.0, 28.1425
53.377249060, 58.395, 780.0, 27.9285
53.420714820, 58.395, 718.0, 26.7955
53.464180580, 58.395, 728.0, 26.9815
53.507646340, 58.395, 781.0, 27.9464
53.551112100, 58.395, 789.0, 28.0891
53.594577860, 58.395, 773.0, 27.8029
53.638043620, 58.395, 801.0, 28.3019
53.681509380, 58.395, 825.0, 28.7228
53.724975140, 58.395, 870.0, 29.4958
53.768440900, 58.395, 770.0, 27.7489
53.811906660, 58.395, 814.0, 28.5307
53.855372420, 58.395, 792.0, 28.1425
53.898838180, 58.395, 771.0, 27.7669
53.942303940, 58.395, 794.0, 28.1780
53.985769700, 58.395, 719.0, 26.8142
54.029235460, 58.395, 757.0, 27.5136
54.072701220, 58.395, 753.0, 27.4408
54.116166980, 58.395, 722.0, 26.8701
54.159632740, 58.395, 682.0, 26.1151
54.203098500, 58.395, 764.0, 27.6405
54.246564260, 58.395, 798.0, 28.2489
54.290030020, 58.395, 763.0, 27.6225
54.333495780, 58.395, 713.0, 26.7021
54.376961540, 58.395, 763.0, 27.6225
54.420427300, 58.395, 740.0, 27.2029
54.463893060, 58.395, 731.0, 27.0370
54.507358820, 58.395, 725.0, 26.9258
54.550824580, 58.395, 728.0, 26.9815
54.594290340, 58.395, 693.0, 26.3249
54.637756100, 58.395, 697.0, 26.4008
54.681221860, 58.395, 728.0, 26.9815
54.724687620, 58.395, 675.0, 25.9808
54.768153380, 58.395, 755.0, 27.4773
54.811619140, 58.395, 695.0, 26.3629
54.855084900, 58.395, 742.0, 27.2397
54.898550660, 58.395, 723.0, 26.8887
54.942016420, 58.395, 688.0, 26.2298
54.985482180, 58.395, 700.0, 26.4575
55.028947940, 58.395, 706.0, 26.5707
55.072413700, 58.395, 711.0, 26.6646
55.115879460, 58.395, 714.0, 26.7208
55.159345220, 58.395, 704.0, 26.5330
55.202810980, 58.395, 703.0, 26.5141
55.246276740, 58.395, 716.0, 26.7582
55.289742500, 58.395, 680.0, 26.0768
55.333208260, 58.395, 698.0, 26.4197
55.376674020, 58.395, 744.0, 27.2764
55.420139780, 58.395, 747.0, 27.3313
55.463605540, 58.395, 682.0, 26.1151
55.507071300, 58.395, 711.0, 26.6646
55.550537060, 58.395, 659.0, 25.6710
55.594002820, 58.395, 694.0, 26.3439
55.637468580, 58.395, 731.0, 27.0370
55.680934340, 58.395, 740.0, 27.2029
55.724400100, 58.395, 677.0, 26.0192
55.767865860, 58.395, 689.0, 26.2488
55.811331620, 58.395, 725.0, 26.9258
55.854797380, 58.395, 759.0, 27.5500
55.898263140, 58.395, 733.0, 27.0740
55.941728900, 58.395, 778.0, 27.8927
55.985194660, 58.395, 684.0, 26.1534
56.028660420, 58.395, 724.0, 26.9072
56.072126180, 58.395, 682.0, 26.1151
56.115591940, 58.395, 640.0, 25.2982
56.159057700, 58.395, 652.0, 25.5343
56.202523460, 58.395, 669.0, 25.8650
56.245989220, 58.395, 692.0, 26.3059
56.289454980, 58.395, 729.0, 27.0000
56.332920740, 58.395, 692.0, 26.3059
56.376386500, 58.395, 671.0, 25.9037
56.419852260, 58.395, 706.0, 26.5707
56.463318020, 58.395, 682.0, 26.1151
56.506783780, 58.395, 637.0, 25.2389
56.550249540, 58.395, 692.0, 26.3059
56.593715300, 58.395, 667.0, 25.8263
56.637181060, 58.395, 692.0, 26.3059
56.680646820, 58.395, 645.0, 25.3969
56.724112580, 58.395, 651.0, 25.5147
56.767578340, 58.395, 637.0, 25.2389
56.811044100, 58.395, 648.0, 25.4558
56.854509860, 58.395, 633.0, 25.1595
56.897975620, 58.395, 623.0, 24.9600
56.941441380, 58.395, 671.0, 25.9037
56.984907140, 58.395, 708.0, 26.6083
57.028372900, 58.395, 704.0, 26.5330
57.071838660, 58.395, 700.0, 26.4575
57.115304420, 58.395, 670.0, 25.8844
57.158770180, 58.395, 672.0, 25.9230
57.202235940, 58.395, 668.0, 25.8457
57.245701700, 58.395, 632.0, 25.1396
57.289167460, 58.395, 658.0, 25.6515
57.332633220, 58.395, 657.0, 25.6320
57.376098980, 58.395, 647.0, 25.4362
57.419564740, 58.395, 577.0, 24.0208
57.463030500, 58.395, 616.0, 24.8193
57.506496260, 58.395, 643.0, 25.3574
57.549962020, 58.395, 618.0, 24.8596
57.593427780, 58.395, 662.0, 25.7294
57.636893540, 58.395, 640.0, 25.2982
57.680359300, 58.395, 645.0, 25.3969
57.723825060, 58.395, 609.0, 24.6779
57.767290820, 58.395, 662.0, 25.7294
57.810756580, 58.395, 632.0, 25.1396
57.854222340, 58.395, 649.0, 25.4755
57.897688100, 58.395, 625.0, 25.0000
57.941153860, 58.395, 638.0, 25.2587
57.984619620, 58.395, 648.0, 25.4558
58.028085380, 58.395, 633.0, 25.1595
58.071551140, 58.395, 655.0, 25.5930
58.115016900, 58.395, 601.0, 24.5153
58.158482660, 58.395, 628.0, 25.0599
58.201948420, 58.395, 581.0, 24.1039
58.245414180, 58.395, 631.0, 25.1197
58.288879940, 58.395, 627.0, 25.0400
58.332345700, 58.395, 660.0, 25.6905
58.375811460, 58.395, 617.0, 24.8395
58.419277220, 58.395, 617.0, 24.8395
58.462742980, 58.395, 581.0, 24.1039
58.506208740, 58.395, 626.0, 25.0200
58.549674500, 58.395, 629.0, 25.0799
58.593140260, 58.395, 624.0, 24.9800
58.636606020, 58.395, 665.0, 25.7876
58.680071780, 58.395, 642.0, 25.3377
58.723537540, 58.395, 617.0, 24.8395
58.767003300, 58.395, 686.0, 26.1916
58.810469060, 58.395, 612.0, 24.7386
58.853934820, 58.395, 630.0, 25.0998
58.897400580, 58.395, 610.0, 24.6982
58.940866340, 58.395, 656.0, 25.6125
58.984332100, 58.395, 629.0, 25.0799
59.027797860, 58.395, 626.0, 25.0200
59.071263620, 58.395, 654.0, 25.5734
59.114729380, 58.395, 630.0, 25.0998
59.158195140, 58.395, 608.0, 24.6577
59.201660900, 58.395, 633.0, 25.1595
59.245126660, 58.395, 615.0, 24.7992
59.288592420, 58.395, 582.0, 24.1247
59.332058180, 58.395, 590.0, 24.2899
59.375523940, 58.395, 638.0, 25.2587
59.418989700, 58.395, 654.0, 25.5734
59.462455460, 58.395, 619.0, 24.8797
59.505921220, 58.395, 618.0, 24.8596
59.549386980, 58.395, 622.0, 24.9399
59.592852740, 58.395, 606.0, 24.6171
59.636318500, 58.395, 603.0, 24.5561
59.679784260, 58.395, 619.0, 24.8797
59.723250020, 58.395, 580.0, 24.0832
59.766715780, 58.395, 582.0, 24.1247
59.810181540, 58.395, 592.0, 24.3311
59.853647300, 58.395, 605.0, 24.5967
59.897113060, 58.395, 622.0, 24.9399
59.940578820, 58.395, 552.0, 23.4947
59.984044580, 58.395, 587.0, 24.2281
59.994911020, 58.395, 607.0, 24.6374