File: XRD/2025_06_03_CBD_SA_Slurry_3_60_8min.csv
[Measurement conditions]
Sample identification,2025_06_03_CBD_SA_Slurry_3_60_8min
Comment - 1,"CBD - Sorbic Acid Cocrystal, Slurry Method, 5/9/25, JL."
Anode material,Cu
K-Alpha1 wavelength,1.5405980
K-Alpha2 wavelength,1.5444260
Ratio K-Alpha2/K-Alpha1,0.500
Divergence slit,Fixed,0.76mm
Monochromator used,NO
Generator voltage, 40
Tube current, 15
File date and time,03/Jun/2025 15:30
Unit cell,
h k l, 0 0 0
Scan axis,Gonio
Scan range,2.995000000,60.000344240
Scan step size,0.0108664
No. of points, 5246
Scan type,CONTINUOUS
Time per step,18.870
[Scan points]
Angle, TimePerStep, Intensity, ESD
3.000433220, 18.870, 44515.0, 210.9858
3.043898980, 18.870, 42502.0, 206.1601
3.087364740, 18.870, 40728.0, 201.8118
3.130830500, 18.870, 38161.0, 195.3484
3.174296260, 18.870, 36476.0, 190.9869
3.217762020, 18.870, 34314.0, 185.2404
3.261227780, 18.870, 32428.0, 180.0778
3.304693540, 18.870, 30621.0, 174.9886
3.348159300, 18.870, 28793.0, 169.6850
3.391625060, 18.870, 27370.0, 165.4388
3.435090820, 18.870, 25872.0, 160.8478
3.478556580, 18.870, 24440.0, 156.3330
3.522022340, 18.870, 23014.0, 151.7037
3.565488100, 18.870, 21642.0, 147.1122
3.608953860, 18.870, 20310.0, 142.5132
3.652419620, 18.870, 19103.0, 138.2136
3.695885380, 18.870, 17812.0, 133.4616
3.739351140, 18.870, 16877.0, 129.9115
3.782816900, 18.870, 15494.0, 124.4749
3.826282660, 18.870, 14670.0, 121.1198
3.869748420, 18.870, 13710.0, 117.0897
3.913214180, 18.870, 12601.0, 112.2542
3.956679940, 18.870, 11805.0, 108.6508
4.000145700, 18.870, 11043.0, 105.0857
4.043611460, 18.870, 10057.0, 100.2846
4.087077220, 18.870, 9469.0, 97.3088
4.130542980, 18.870, 8738.0, 93.4773
4.174008740, 18.870, 8130.0, 90.1665
4.217474500, 18.870, 7587.0, 87.1034
4.260940260, 18.870, 6932.0, 83.2586
4.304406020, 18.870, 6582.0, 81.1295
4.347871780, 18.870, 5848.0, 76.4722
4.391337540, 18.870, 5446.0, 73.7970
4.434803300, 18.870, 5062.0, 71.1477
4.478269060, 18.870, 4766.0, 69.0362
4.521734820, 18.870, 4248.0, 65.1767
4.565200580, 18.870, 3913.0, 62.5540
4.608666340, 18.870, 3747.0, 61.2127
4.652132100, 18.870, 3497.0, 59.1354
4.695597860, 18.870, 3283.0, 57.2975
4.739063620, 18.870, 3143.0, 56.0625
4.782529380, 18.870, 2937.0, 54.1941
4.825995140, 18.870, 2911.0, 53.9537
4.869460900, 18.870, 2942.0, 54.2402
4.912926660, 18.870, 2988.0, 54.6626
4.956392420, 18.870, 2964.0, 54.4426
4.999858180, 18.870, 2903.0, 53.8795
5.043323940, 18.870, 3307.0, 57.5065
5.086789700, 18.870, 3582.0, 59.8498
5.130255460, 18.870, 3956.0, 62.8967
5.173721220, 18.870, 4466.0, 66.8281
5.217186980, 18.870, 4460.0, 66.7832
5.260652740, 18.870, 4106.0, 64.0781
5.304118500, 18.870, 3314.0, 57.5674
5.347584260, 18.870, 2839.0, 53.2823
5.391050020, 18.870, 2802.0, 52.9339
5.434515780, 18.870, 2790.0, 52.8205
5.477981540, 18.870, 2879.0, 53.6563
5.521447300, 18.870, 3123.0, 55.8838
5.564913060, 18.870, 3419.0, 58.4722
5.608378820, 18.870, 3633.0, 60.2744
5.651844580, 18.870, 4010.0, 63.3246
5.695310340, 18.870, 4600.0, 67.8233
5.738776100, 18.870, 4469.0, 66.8506
5.782241860, 18.870, 3927.0, 62.6658
5.825707620, 18.870, 3007.0, 54.8361
5.869173380, 18.870, 2229.0, 47.2123
5.912639140, 18.870, 1670.0, 40.8656
5.956104900, 18.870, 1560.0, 39.4968
5.999570660, 18.870, 1435.0, 37.8814
6.043036420, 18.870, 1340.0, 36.6060
6.086502180, 18.870, 1240.0, 35.2136
6.129967940, 18.870, 1154.0, 33.9706
6.173433700, 18.870, 1214.0, 34.8425
6.216899460, 18.870, 1168.0, 34.1760
6.260365220, 18.870, 1058.0, 32.5269
6.303830980, 18.870, 1015.0, 31.8591
6.347296740, 18.870, 1075.0, 32.7872
6.390762500, 18.870, 974.0, 31.2090
6.434228260, 18.870, 949.0, 30.8058
6.477694020, 18.870, 944.0, 30.7246
6.521159780, 18.870, 919.0, 30.3150
6.564625540, 18.870, 902.0, 30.0333
6.608091300, 18.870, 826.0, 28.7402
6.651557060, 18.870, 787.0, 28.0535
6.695022820, 18.870, 839.0, 28.9655
6.738488580, 18.870, 797.0, 28.2312
6.781954340, 18.870, 780.0, 27.9285
6.825420100, 18.870, 795.0, 28.1957
6.868885860, 18.870, 799.0, 28.2666
6.912351620, 18.870, 761.0, 27.5862
6.955817380, 18.870, 667.0, 25.8263
6.999283140, 18.870, 729.0, 27.0000
7.042748900, 18.870, 703.0, 26.5141
7.086214660, 18.870, 719.0, 26.8142
7.129680420, 18.870, 658.0, 25.6515
7.173146180, 18.870, 685.0, 26.1725
7.216611940, 18.870, 686.0, 26.1916
7.260077700, 18.870, 665.0, 25.7876
7.303543460, 18.870, 646.0, 25.4165
7.347009220, 18.870, 638.0, 25.2587
7.390474980, 18.870, 612.0, 24.7386
7.433940740, 18.870, 606.0, 24.6171
7.477406500, 18.870, 654.0, 25.5734
7.520872260, 18.870, 568.0, 23.8328
7.564338020, 18.870, 570.0, 23.8747
7.607803780, 18.870, 558.0, 23.6220
7.651269540, 18.870, 495.0, 22.2486
7.694735300, 18.870, 525.0, 22.9129
7.738201060, 18.870, 547.0, 23.3880
7.781666820, 18.870, 562.0, 23.7065
7.825132580, 18.870, 550.0, 23.4521
7.868598340, 18.870, 524.0, 22.8910
7.912064100, 18.870, 532.0, 23.0651
7.955529860, 18.870, 547.0, 23.3880
7.998995620, 18.870, 532.0, 23.0651
8.042461380, 18.870, 531.0, 23.0434
8.085927140, 18.870, 520.0, 22.8035
8.129392900, 18.870, 546.0, 23.3666
8.172858660, 18.870, 539.0, 23.2164
8.216324420, 18.870, 546.0, 23.3666
8.259790180, 18.870, 485.0, 22.0227
8.303255940, 18.870, 519.0, 22.7816
8.346721700, 18.870, 539.0, 23.2164
8.390187460, 18.870, 524.0, 22.8910
8.433653220, 18.870, 514.0, 22.6716
8.477118980, 18.870, 523.0, 22.8692
8.520584740, 18.870, 499.0, 22.3383
8.564050500, 18.870, 558.0, 23.6220
8.607516260, 18.870, 523.0, 22.8692
8.650982020, 18.870, 583.0, 24.1454
8.694447780, 18.870, 617.0, 24.8395
8.737913540, 18.870, 614.0, 24.7790
8.781379300, 18.870, 624.0, 24.9800
8.824845060, 18.870, 709.0, 26.6271
8.868310820, 18.870, 688.0, 26.2298
8.911776580, 18.870, 730.0, 27.0185
8.955242340, 18.870, 825.0, 28.7228
8.998708100, 18.870, 916.0, 30.2655
9.042173860, 18.870, 984.0, 31.3688
9.085639620, 18.870, 1146.0, 33.8526
9.129105380, 18.870, 1250.0, 35.3553
9.172571140, 18.870, 1559.0, 39.4842
9.216036900, 18.870, 1803.0, 42.4617
9.259502660, 18.870, 1919.0, 43.8064
9.302968420, 18.870, 2195.0, 46.8508
9.346434180, 18.870, 2294.0, 47.8957
9.389899940, 18.870, 2084.0, 45.6508
9.433365700, 18.870, 1799.0, 42.4146
9.476831460, 18.870, 1406.0, 37.4967
9.520297220, 18.870, 1026.0, 32.0312
9.563762980, 18.870, 912.0, 30.1993
9.607228740, 18.870, 768.0, 27.7128
9.650694500, 18.870, 697.0, 26.4008
9.694160260, 18.870, 651.0, 25.5147
9.737626020, 18.870, 617.0, 24.8395
9.781091780, 18.870, 598.0, 24.4540
9.824557540, 18.870, 568.0, 23.8328
9.868023300, 18.870, 646.0, 25.4165
9.911489060, 18.870, 614.0, 24.7790
9.954954820, 18.870, 678.0, 26.0384
9.998420580, 18.870, 669.0, 25.8650
10.041886340, 18.870, 712.0, 26.6833
10.085352100, 18.870, 734.0, 27.0924
10.128817860, 18.870, 775.0, 27.8388
10.172283620, 18.870, 812.0, 28.4956
10.215749380, 18.870, 928.0, 30.4631
10.259215140, 18.870, 943.0, 30.7083
10.302680900, 18.870, 1073.0, 32.7567
10.346146660, 18.870, 1205.0, 34.7131
10.389612420, 18.870, 1323.0, 36.3731
10.433078180, 18.870, 1419.0, 37.6696
10.476543940, 18.870, 1618.0, 40.2244
10.520009700, 18.870, 1777.0, 42.1545
10.563475460, 18.870, 1778.0, 42.1663
10.606941220, 18.870, 1684.0, 41.0366
10.650406980, 18.870, 1485.0, 38.5357
10.693872740, 18.870, 1201.0, 34.6554
10.737338500, 18.870, 1070.0, 32.7109
10.780804260, 18.870, 978.0, 31.2730
10.824270020, 18.870, 1100.0, 33.1662
10.867735780, 18.870, 1150.0, 33.9116
10.911201540, 18.870, 1318.0, 36.3043
10.954667300, 18.870, 1506.0, 38.8072
10.998133060, 18.870, 1697.0, 41.1947
11.041598820, 18.870, 1826.0, 42.7317
11.085064580, 18.870, 1990.0, 44.6094
11.128530340, 18.870, 1947.0, 44.1248
11.171996100, 18.870, 2102.0, 45.8476
11.215461860, 18.870, 2174.0, 46.6262
11.258927620, 18.870, 2536.0, 50.3587
11.302393380, 18.870, 2825.0, 53.1507
11.345859140, 18.870, 3040.0, 55.1362
11.389324900, 18.870, 3158.0, 56.1961
11.432790660, 18.870, 3086.0, 55.5518
11.476256420, 18.870, 2870.0, 53.5724
11.519722180, 18.870, 2881.0, 53.6749
11.563187940, 18.870, 2748.0, 52.4214
11.606653700, 18.870, 2749.0, 52.4309
11.650119460, 18.870, 2556.0, 50.5569
11.693585220, 18.870, 2316.0, 48.1248
11.737050980, 18.870, 1860.0, 43.1277
11.780516740, 18.870, 1474.0, 38.3927
11.823982500, 18.870, 1112.0, 33.3467
11.867448260, 18.870, 1076.0, 32.8024
11.910914020, 18.870, 977.0, 31.2570
11.954379780, 18.870, 1012.0, 31.8119
11.997845540, 18.870, 1141.0, 33.7787
12.041311300, 18.870, 1314.0, 36.2491
12.084777060, 18.870, 1598.0, 39.9750
12.128242820, 18.870, 1807.0, 42.5088
12.171708580, 18.870, 1950.0, 44.1588
12.215174340, 18.870, 2048.0, 45.2548
12.258640100, 18.870, 1939.0, 44.0341
12.302105860, 18.870, 1825.0, 42.7200
12.345571620, 18.870, 1509.0, 38.8458
12.389037380, 18.870, 1203.0, 34.6843
12.432503140, 18.870, 1048.0, 32.3728
12.475968900, 18.870, 1087.0, 32.9697
12.519434660, 18.870, 1045.0, 32.3265
12.562900420, 18.870, 1013.0, 31.8277
12.606366180, 18.870, 1031.0, 32.1092
12.649831940, 18.870, 922.0, 30.3645
12.693297700, 18.870, 850.0, 29.1548
12.736763460, 18.870, 828.0, 28.7750
12.780229220, 18.870, 852.0, 29.1890
12.823694980, 18.870, 846.0, 29.0861
12.867160740, 18.870, 902.0, 30.0333
12.910626500, 18.870, 883.0, 29.7153
12.954092260, 18.870, 856.0, 29.2575
12.997558020, 18.870, 801.0, 28.3019
13.041023780, 18.870, 760.0, 27.5681
13.084489540, 18.870, 645.0, 25.3969
13.127955300, 18.870, 634.0, 25.1794
13.171421060, 18.870, 634.0, 25.1794
13.214886820, 18.870, 635.0, 25.1992
13.258352580, 18.870, 594.0, 24.3721
13.301818340, 18.870, 613.0, 24.7588
13.345284100, 18.870, 655.0, 25.5930
13.388749860, 18.870, 662.0, 25.7294
13.432215620, 18.870, 650.0, 25.4951
13.475681380, 18.870, 684.0, 26.1534
13.519147140, 18.870, 714.0, 26.7208
13.562612900, 18.870, 689.0, 26.2488
13.606078660, 18.870, 709.0, 26.6271
13.649544420, 18.870, 659.0, 25.6710
13.693010180, 18.870, 613.0, 24.7588
13.736475940, 18.870, 585.0, 24.1868
13.779941700, 18.870, 578.0, 24.0416
13.823407460, 18.870, 572.0, 23.9165
13.866873220, 18.870, 558.0, 23.6220
13.910338980, 18.870, 561.0, 23.6854
13.953804740, 18.870, 595.0, 24.3926
13.997270500, 18.870, 597.0, 24.4336
14.040736260, 18.870, 570.0, 23.8747
14.084202020, 18.870, 626.0, 25.0200
14.127667780, 18.870, 690.0, 26.2679
14.171133540, 18.870, 601.0, 24.5153
14.214599300, 18.870, 658.0, 25.6515
14.258065060, 18.870, 707.0, 26.5895
14.301530820, 18.870, 759.0, 27.5500
14.344996580, 18.870, 832.0, 28.8444
14.388462340, 18.870, 911.0, 30.1828
14.431928100, 18.870, 999.0, 31.6070
14.475393860, 18.870, 1122.0, 33.4963
14.518859620, 18.870, 1342.0, 36.6333
14.562325380, 18.870, 1418.0, 37.6563
14.605791140, 18.870, 1424.0, 37.7359
14.649256900, 18.870, 1498.0, 38.7040
14.692722660, 18.870, 1573.0, 39.6611
14.736188420, 18.870, 1449.0, 38.0657
14.779654180, 18.870, 1332.0, 36.4966
14.823119940, 18.870, 1089.0, 33.0000
14.866585700, 18.870, 971.0, 31.1609
14.910051460, 18.870, 969.0, 31.1288
14.953517220, 18.870, 1012.0, 31.8119
14.996982980, 18.870, 1257.0, 35.4542
15.040448740, 18.870, 1477.0, 38.4318
15.083914500, 18.870, 1583.0, 39.7869
15.127380260, 18.870, 1856.0, 43.0813
15.170846020, 18.870, 1858.0, 43.1045
15.214311780, 18.870, 2043.0, 45.1996
15.257777540, 18.870, 2112.0, 45.9565
15.301243300, 18.870, 2115.0, 45.9891
15.344709060, 18.870, 1999.0, 44.7102
15.388174820, 18.870, 2086.0, 45.6727
15.431640580, 18.870, 2298.0, 47.9375
15.475106340, 18.870, 2865.0, 53.5257
15.518572100, 18.870, 3668.0, 60.5640
15.562037860, 18.870, 4311.0, 65.6582
15.605503620, 18.870, 5190.0, 72.0417
15.648969380, 18.870, 5576.0, 74.6726
15.692435140, 18.870, 5915.0, 76.9090
15.735900900, 18.870, 5608.0, 74.8866
15.779366660, 18.870, 4811.0, 69.3614
15.822832420, 18.870, 3636.0, 60.2993
15.866298180, 18.870, 2485.0, 49.8498
15.909763940, 18.870, 1745.0, 41.7732
15.953229700, 18.870, 1444.0, 38.0000
15.996695460, 18.870, 1380.0, 37.1484
16.040161220, 18.870, 1486.0, 38.5487
16.083626980, 18.870, 1724.0, 41.5211
16.127092740, 18.870, 2016.0, 44.8999
16.170558500, 18.870, 2354.0, 48.5180
16.214024260, 18.870, 2614.0, 51.1273
16.257490020, 18.870, 2832.0, 53.2165
16.300955780, 18.870, 2908.0, 53.9259
16.344421540, 18.870, 2947.0, 54.2863
16.387887300, 18.870, 2796.0, 52.8772
16.431353060, 18.870, 2619.0, 51.1762
16.474818820, 18.870, 2492.0, 49.9199
16.518284580, 18.870, 2371.0, 48.6929
16.561750340, 18.870, 2271.0, 47.6550
16.605216100, 18.870, 2150.0, 46.3681
16.648681860, 18.870, 1972.0, 44.4072
16.692147620, 18.870, 1827.0, 42.7434
16.735613380, 18.870, 1657.0, 40.7063
16.779079140, 18.870, 1437.0, 37.9078
16.822544900, 18.870, 1355.0, 36.8103
16.866010660, 18.870, 1312.0, 36.2215
16.909476420, 18.870, 1260.0, 35.4965
16.952942180, 18.870, 1389.0, 37.2693
16.996407940, 18.870, 1595.0, 39.9375
17.039873700, 18.870, 1801.0, 42.4382
17.083339460, 18.870, 2102.0, 45.8476
17.126805220, 18.870, 2351.0, 48.4871
17.170270980, 18.870, 2771.0, 52.6403
17.213736740, 18.870, 2952.0, 54.3323
17.257202500, 18.870, 3064.0, 55.3534
17.300668260, 18.870, 3127.0, 55.9196
17.344134020, 18.870, 2952.0, 54.3323
17.387599780, 18.870, 2666.0, 51.6333
17.431065540, 18.870, 2263.0, 47.5710
17.474531300, 18.870, 1907.0, 43.6692
17.517997060, 18.870, 1458.0, 38.1838
17.561462820, 18.870, 1240.0, 35.2136
17.604928580, 18.870, 1176.0, 34.2929
17.648394340, 18.870, 1030.0, 32.0936
17.691860100, 18.870, 981.0, 31.3209
17.735325860, 18.870, 1035.0, 32.1714
17.778791620, 18.870, 1033.0, 32.1403
17.822257380, 18.870, 1016.0, 31.8748
17.865723140, 18.870, 1032.0, 32.1248
17.909188900, 18.870, 1030.0, 32.0936
17.952654660, 18.870, 1094.0, 33.0757
17.996120420, 18.870, 1038.0, 32.2180
18.039586180, 18.870, 1047.0, 32.3574
18.083051940, 18.870, 1149.0, 33.8969
18.126517700, 18.870, 1367.0, 36.9730
18.169983460, 18.870, 1466.0, 38.2884
18.213449220, 18.870, 1743.0, 41.7493
18.256914980, 18.870, 2075.0, 45.5522
18.300380740, 18.870, 2478.0, 49.7795
18.343846500, 18.870, 2895.0, 53.8052
18.387312260, 18.870, 3382.0, 58.1550
18.430778020, 18.870, 3928.0, 62.6738
18.474243780, 18.870, 4333.0, 65.8255
18.517709540, 18.870, 5127.0, 71.6031
18.561175300, 18.870, 5587.0, 74.7462
18.604641060, 18.870, 5898.0, 76.7984
18.648106820, 18.870, 6044.0, 77.7432
18.691572580, 18.870, 5926.0, 76.9805
18.735038340, 18.870, 5347.0, 73.1232
18.778504100, 18.870, 4770.0, 69.0652
18.821969860, 18.870, 3982.0, 63.1031
18.865435620, 18.870, 3344.0, 57.8273
18.908901380, 18.870, 3054.0, 55.2630
18.952367140, 18.870, 2958.0, 54.3875
18.995832900, 18.870, 3133.0, 55.9732
19.039298660, 18.870, 3275.0, 57.2276
19.082764420, 18.870, 3621.0, 60.1747
19.126230180, 18.870, 3795.0, 61.6036
19.169695940, 18.870, 3641.0, 60.3407
19.213161700, 18.870, 3543.0, 59.5231
19.256627460, 18.870, 3556.0, 59.6322
19.300093220, 18.870, 3395.0, 58.2666
19.343558980, 18.870, 3150.0, 56.1249
19.387024740, 18.870, 2868.0, 53.5537
19.430490500, 18.870, 2560.0, 50.5964
19.473956260, 18.870, 1975.0, 44.4410
19.517422020, 18.870, 1665.0, 40.8044
19.560887780, 18.870, 1372.0, 37.0405
19.604353540, 18.870, 1274.0, 35.6931
19.647819300, 18.870, 1219.0, 34.9142
19.691285060, 18.870, 1166.0, 34.1467
19.734750820, 18.870, 1245.0, 35.2846
19.778216580, 18.870, 1282.0, 35.8050
19.821682340, 18.870, 1471.0, 38.3536
19.865148100, 18.870, 1544.0, 39.2938
19.908613860, 18.870, 1462.0, 38.2361
19.952079620, 18.870, 1455.0, 38.1445
19.995545380, 18.870, 1374.0, 37.0675
20.039011140, 18.870, 1312.0, 36.2215
20.082476900, 18.870, 1298.0, 36.0278
20.125942660, 18.870, 1266.0, 35.5809
20.169408420, 18.870, 1303.0, 36.0971
20.212874180, 18.870, 1375.0, 37.0810
20.256339940, 18.870, 1480.0, 38.4708
20.299805700, 18.870, 1621.0, 40.2616
20.343271460, 18.870, 1737.0, 41.6773
20.386737220, 18.870, 1931.0, 43.9431
20.430202980, 18.870, 2241.0, 47.3392
20.473668740, 18.870, 2576.0, 50.7543
20.517134500, 18.870, 3327.0, 57.6802
20.560600260, 18.870, 3654.0, 60.4483
20.604066020, 18.870, 4109.0, 64.1015
20.647531780, 18.870, 4288.0, 65.4828
20.690997540, 18.870, 4442.0, 66.6483
20.734463300, 18.870, 4375.0, 66.1438
20.777929060, 18.870, 4129.0, 64.2573
20.821394820, 18.870, 4045.0, 63.6003
20.864860580, 18.870, 4315.0, 65.6887
20.908326340, 18.870, 5022.0, 70.8661
20.951792100, 18.870, 5920.0, 76.9415
20.995257860, 18.870, 6850.0, 82.7647
21.038723620, 18.870, 7579.0, 87.0575
21.082189380, 18.870, 7691.0, 87.6983
21.125655140, 18.870, 7566.0, 86.9828
21.169120900, 18.870, 6866.0, 82.8613
21.212586660, 18.870, 5679.0, 75.3591
21.256052420, 18.870, 4435.0, 66.5958
21.299518180, 18.870, 3392.0, 58.2409
21.342983940, 18.870, 2556.0, 50.5569
21.386449700, 18.870, 2138.0, 46.2385
21.429915460, 18.870, 1729.0, 41.5812
21.473381220, 18.870, 1519.0, 38.9744
21.516846980, 18.870, 1303.0, 36.0971
21.560312740, 18.870, 1281.0, 35.7911
21.603778500, 18.870, 1129.0, 33.6006
21.647244260, 18.870, 1115.0, 33.3916
21.690710020, 18.870, 1123.0, 33.5112
21.734175780, 18.870, 1064.0, 32.6190
21.777641540, 18.870, 1089.0, 33.0000
21.821107300, 18.870, 1101.0, 33.1813
21.864573060, 18.870, 1135.0, 33.6898
21.908038820, 18.870, 1240.0, 35.2136
21.951504580, 18.870, 1393.0, 37.3229
21.994970340, 18.870, 1483.0, 38.5097
22.038436100, 18.870, 1628.0, 40.3485
22.081901860, 18.870, 1763.0, 41.9881
22.125367620, 18.870, 1824.0, 42.7083
22.168833380, 18.870, 1821.0, 42.6732
22.212299140, 18.870, 1656.0, 40.6940
22.255764900, 18.870, 1532.0, 39.1408
22.299230660, 18.870, 1454.0, 38.1314
22.342696420, 18.870, 1221.0, 34.9428
22.386162180, 18.870, 1184.0, 34.4093
22.429627940, 18.870, 1105.0, 33.2415
22.473093700, 18.870, 1144.0, 33.8231
22.516559460, 18.870, 1211.0, 34.7994
22.560025220, 18.870, 1174.0, 34.2637
22.603490980, 18.870, 1123.0, 33.5112
22.646956740, 18.870, 1186.0, 34.4384
22.690422500, 18.870, 1191.0, 34.5109
22.733888260, 18.870, 1304.0, 36.1109
22.777354020, 18.870, 1441.0, 37.9605
22.820819780, 18.870, 1454.0, 38.1314
22.864285540, 18.870, 1717.0, 41.4367
22.907751300, 18.870, 1814.0, 42.5911
22.951217060, 18.870, 1867.0, 43.2088
22.994682820, 18.870, 1870.0, 43.2435
23.038148580, 18.870, 1635.0, 40.4351
23.081614340, 18.870, 1524.0, 39.0384
23.125080100, 18.870, 1464.0, 38.2623
23.168545860, 18.870, 1436.0, 37.8946
23.212011620, 18.870, 1409.0, 37.5366
23.255477380, 18.870, 1404.0, 37.4700
23.298943140, 18.870, 1463.0, 38.2492
23.342408900, 18.870, 1500.0, 38.7298
23.385874660, 18.870, 1685.0, 41.0488
23.429340420, 18.870, 1640.0, 40.4969
23.472806180, 18.870, 1763.0, 41.9881
23.516271940, 18.870, 1705.0, 41.2916
23.559737700, 18.870, 1648.0, 40.5956
23.603203460, 18.870, 1531.0, 39.1280
23.646669220, 18.870, 1322.0, 36.3593
23.690134980, 18.870, 1210.0, 34.7851
23.733600740, 18.870, 1071.0, 32.7261
23.777066500, 18.870, 994.0, 31.5278
23.820532260, 18.870, 943.0, 30.7083
23.863998020, 18.870, 884.0, 29.7321
23.907463780, 18.870, 911.0, 30.1828
23.950929540, 18.870, 954.0, 30.8869
23.994395300, 18.870, 962.0, 31.0161
24.037861060, 18.870, 1094.0, 33.0757
24.081326820, 18.870, 1303.0, 36.0971
24.124792580, 18.870, 1490.0, 38.6005
24.168258340, 18.870, 1755.0, 41.8927
24.211724100, 18.870, 1938.0, 44.0227
24.255189860, 18.870, 2143.0, 46.2925
24.298655620, 18.870, 2210.0, 47.0106
24.342121380, 18.870, 2101.0, 45.8367
24.385587140, 18.870, 1872.0, 43.2666
24.429052900, 18.870, 1655.0, 40.6817
24.472518660, 18.870, 1312.0, 36.2215
24.515984420, 18.870, 1225.0, 35.0000
24.559450180, 18.870, 1064.0, 32.6190
24.602915940, 18.870, 1016.0, 31.8748
24.646381700, 18.870, 956.0, 30.9192
24.689847460, 18.870, 949.0, 30.8058
24.733313220, 18.870, 866.0, 29.4279
24.776778980, 18.870, 790.0, 28.1069
24.820244740, 18.870, 785.0, 28.0179
24.863710500, 18.870, 655.0, 25.5930
24.907176260, 18.870, 692.0, 26.3059
24.950642020, 18.870, 684.0, 26.1534
24.994107780, 18.870, 719.0, 26.8142
25.037573540, 18.870, 670.0, 25.8844
25.081039300, 18.870, 710.0, 26.6458
25.124505060, 18.870, 755.0, 27.4773
25.167970820, 18.870, 869.0, 29.4788
25.211436580, 18.870, 850.0, 29.1548
25.254902340, 18.870, 870.0, 29.4958
25.298368100, 18.870, 869.0, 29.4788
25.341833860, 18.870, 880.0, 29.6648
25.385299620, 18.870, 939.0, 30.6431
25.428765380, 18.870, 940.0, 30.6594
25.472231140, 18.870, 895.0, 29.9166
25.515696900, 18.870, 1034.0, 32.1559
25.559162660, 18.870, 1014.0, 31.8434
25.602628420, 18.870, 1074.0, 32.7719
25.646094180, 18.870, 1244.0, 35.2704
25.689559940, 18.870, 1230.0, 35.0714
25.733025700, 18.870, 1341.0, 36.6197
25.776491460, 18.870, 1346.0, 36.6879
25.819957220, 18.870, 1487.0, 38.5616
25.863422980, 18.870, 1469.0, 38.3275
25.906888740, 18.870, 1441.0, 37.9605
25.950354500, 18.870, 1443.0, 37.9868
25.993820260, 18.870, 1516.0, 38.9358
26.037286020, 18.870, 1597.0, 39.9625
26.080751780, 18.870, 1622.0, 40.2741
26.124217540, 18.870, 1659.0, 40.7308
26.167683300, 18.870, 1749.0, 41.8210
26.211149060, 18.870, 1832.0, 42.8019
26.254614820, 18.870, 1778.0, 42.1663
26.298080580, 18.870, 1746.0, 41.7852
26.341546340, 18.870, 1563.0, 39.5348
26.385012100, 18.870, 1482.0, 38.4968
26.428477860, 18.870, 1264.0, 35.5528
26.471943620, 18.870, 1122.0, 33.4963
26.515409380, 18.870, 968.0, 31.1127
26.558875140, 18.870, 959.0, 30.9677
26.602340900, 18.870, 813.0, 28.5132
26.645806660, 18.870, 758.0, 27.5318
26.689272420, 18.870, 735.0, 27.1109
26.732738180, 18.870, 666.0, 25.8070
26.776203940, 18.870, 690.0, 26.2679
26.819669700, 18.870, 640.0, 25.2982
26.863135460, 18.870, 676.0, 26.0000
26.906601220, 18.870, 681.0, 26.0960
26.950066980, 18.870, 684.0, 26.1534
26.993532740, 18.870, 611.0, 24.7184
27.036998500, 18.870, 637.0, 25.2389
27.080464260, 18.870, 673.0, 25.9422
27.123930020, 18.870, 684.0, 26.1534
27.167395780, 18.870, 777.0, 27.8747
27.210861540, 18.870, 759.0, 27.5500
27.254327300, 18.870, 887.0, 29.7825
27.297793060, 18.870, 906.0, 30.0998
27.341258820, 18.870, 965.0, 31.0644
27.384724580, 18.870, 944.0, 30.7246
27.428190340, 18.870, 969.0, 31.1288
27.471656100, 18.870, 874.0, 29.5635
27.515121860, 18.870, 752.0, 27.4226
27.558587620, 18.870, 753.0, 27.4408
27.602053380, 18.870, 769.0, 27.7308
27.645519140, 18.870, 777.0, 27.8747
27.688984900, 18.870, 814.0, 28.5307
27.732450660, 18.870, 831.0, 28.8271
27.775916420, 18.870, 943.0, 30.7083
27.819382180, 18.870, 926.0, 30.4302
27.862847940, 18.870, 1102.0, 33.1964
27.906313700, 18.870, 956.0, 30.9192
27.949779460, 18.870, 1021.0, 31.9531
27.993245220, 18.870, 1020.0, 31.9374
28.036710980, 18.870, 970.0, 31.1448
28.080176740, 18.870, 932.0, 30.5287
28.123642500, 18.870, 987.0, 31.4166
28.167108260, 18.870, 985.0, 31.3847
28.210574020, 18.870, 1045.0, 32.3265
28.254039780, 18.870, 998.0, 31.5911
28.297505540, 18.870, 1104.0, 33.2265
28.340971300, 18.870, 1095.0, 33.0908
28.384437060, 18.870, 1178.0, 34.3220
28.427902820, 18.870, 1175.0, 34.2783
28.471368580, 18.870, 1270.0, 35.6371
28.514834340, 18.870, 1183.0, 34.3948
28.558300100, 18.870, 1089.0, 33.0000
28.601765860, 18.870, 1040.0, 32.2490
28.645231620, 18.870, 984.0, 31.3688
28.688697380, 18.870, 854.0, 29.2233
28.732163140, 18.870, 916.0, 30.2655
28.775628900, 18.870, 994.0, 31.5278
28.819094660, 18.870, 974.0, 31.2090
28.862560420, 18.870, 1031.0, 32.1092
28.906026180, 18.870, 998.0, 31.5911
28.949491940, 18.870, 1097.0, 33.1210
28.992957700, 18.870, 1049.0, 32.3883
29.036423460, 18.870, 1048.0, 32.3728
29.079889220, 18.870, 1001.0, 31.6386
29.123354980, 18.870, 914.0, 30.2324
29.166820740, 18.870, 812.0, 28.4956
29.210286500, 18.870, 850.0, 29.1548
29.253752260, 18.870, 794.0, 28.1780
29.297218020, 18.870, 814.0, 28.5307
29.340683780, 18.870, 731.0, 27.0370
29.384149540, 18.870, 738.0, 27.1662
29.427615300, 18.870, 678.0, 26.0384
29.471081060, 18.870, 614.0, 24.7790
29.514546820, 18.870, 620.0, 24.8998
29.558012580, 18.870, 658.0, 25.6515
29.601478340, 18.870, 627.0, 25.0400
29.644944100, 18.870, 686.0, 26.1916
29.688409860, 18.870, 696.0, 26.3818
29.731875620, 18.870, 666.0, 25.8070
29.775341380, 18.870, 747.0, 27.3313
29.818807140, 18.870, 723.0, 26.8887
29.862272900, 18.870, 732.0, 27.0555
29.905738660, 18.870, 725.0, 26.9258
29.949204420, 18.870, 746.0, 27.3130
29.992670180, 18.870, 706.0, 26.5707
30.036135940, 18.870, 733.0, 27.0740
30.079601700, 18.870, 743.0, 27.2580
30.123067460, 18.870, 789.0, 28.0891
30.166533220, 18.870, 814.0, 28.5307
30.209998980, 18.870, 795.0, 28.1957
30.253464740, 18.870, 784.0, 28.0000
30.296930500, 18.870, 697.0, 26.4008
30.340396260, 18.870, 714.0, 26.7208
30.383862020, 18.870, 674.0, 25.9615
30.427327780, 18.870, 677.0, 26.0192
30.470793540, 18.870, 642.0, 25.3377
30.514259300, 18.870, 711.0, 26.6646
30.557725060, 18.870, 715.0, 26.7395
30.601190820, 18.870, 732.0, 27.0555
30.644656580, 18.870, 679.0, 26.0576
30.688122340, 18.870, 776.0, 27.8568
30.731588100, 18.870, 788.0, 28.0713
30.775053860, 18.870, 808.0, 28.4253
30.818519620, 18.870, 852.0, 29.1890
30.861985380, 18.870, 793.0, 28.1603
30.905451140, 18.870, 826.0, 28.7402
30.948916900, 18.870, 681.0, 26.0960
30.992382660, 18.870, 812.0, 28.4956
31.035848420, 18.870, 792.0, 28.1425
31.079314180, 18.870, 737.0, 27.1477
31.122779940, 18.870, 786.0, 28.0357
31.166245700, 18.870, 865.0, 29.4109
31.209711460, 18.870, 895.0, 29.9166
31.253177220, 18.870, 897.0, 29.9500
31.296642980, 18.870, 1027.0, 32.0468
31.340108740, 18.870, 1007.0, 31.7333
31.383574500, 18.870, 1007.0, 31.7333
31.427040260, 18.870, 938.0, 30.6268
31.470506020, 18.870, 876.0, 29.5973
31.513971780, 18.870, 883.0, 29.7153
31.557437540, 18.870, 823.0, 28.6880
31.600903300, 18.870, 871.0, 29.5127
31.644369060, 18.870, 825.0, 28.7228
31.687834820, 18.870, 903.0, 30.0500
31.731300580, 18.870, 863.0, 29.3769
31.774766340, 18.870, 899.0, 29.9833
31.818232100, 18.870, 953.0, 30.8707
31.861697860, 18.870, 1018.0, 31.9061
31.905163620, 18.870, 984.0, 31.3688
31.948629380, 18.870, 1019.0, 31.9218
31.992095140, 18.870, 1044.0, 32.3110
32.035560900, 18.870, 994.0, 31.5278
32.079026660, 18.870, 953.0, 30.8707
32.122492420, 18.870, 885.0, 29.7489
32.165958180, 18.870, 784.0, 28.0000
32.209423940, 18.870, 716.0, 26.7582
32.252889700, 18.870, 650.0, 25.4951
32.296355460, 18.870, 644.0, 25.3772
32.339821220, 18.870, 644.0, 25.3772
32.383286980, 18.870, 608.0, 24.6577
32.426752740, 18.870, 583.0, 24.1454
32.470218500, 18.870, 580.0, 24.0832
32.513684260, 18.870, 556.0, 23.5797
32.557150020, 18.870, 561.0, 23.6854
32.600615780, 18.870, 560.0, 23.6643
32.644081540, 18.870, 583.0, 24.1454
32.687547300, 18.870, 554.0, 23.5372
32.731013060, 18.870, 585.0, 24.1868
32.774478820, 18.870, 600.0, 24.4949
32.817944580, 18.870, 652.0, 25.5343
32.861410340, 18.870, 703.0, 26.5141
32.904876100, 18.870, 747.0, 27.3313
32.948341860, 18.870, 760.0, 27.5681
32.991807620, 18.870, 810.0, 28.4605
33.035273380, 18.870, 922.0, 30.3645
33.078739140, 18.870, 929.0, 30.4795
33.122204900, 18.870, 909.0, 30.1496
33.165670660, 18.870, 909.0, 30.1496
33.209136420, 18.870, 920.0, 30.3315
33.252602180, 18.870, 788.0, 28.0713
33.296067940, 18.870, 814.0, 28.5307
33.339533700, 18.870, 727.0, 26.9629
33.382999460, 18.870, 842.0, 29.0172
33.426465220, 18.870, 841.0, 29.0000
33.469930980, 18.870, 858.0, 29.2916
33.513396740, 18.870, 905.0, 30.0832
33.556862500, 18.870, 876.0, 29.5973
33.600328260, 18.870, 879.0, 29.6479
33.643794020, 18.870, 847.0, 29.1033
33.687259780, 18.870, 820.0, 28.6356
33.730725540, 18.870, 790.0, 28.1069
33.774191300, 18.870, 775.0, 27.8388
33.817657060, 18.870, 674.0, 25.9615
33.861122820, 18.870, 683.0, 26.1343
33.904588580, 18.870, 660.0, 25.6905
33.948054340, 18.870, 630.0, 25.0998
33.991520100, 18.870, 625.0, 25.0000
34.034985860, 18.870, 582.0, 24.1247
34.078451620, 18.870, 580.0, 24.0832
34.121917380, 18.870, 565.0, 23.7697
34.165383140, 18.870, 633.0, 25.1595
34.208848900, 18.870, 587.0, 24.2281
34.252314660, 18.870, 610.0, 24.6982
34.295780420, 18.870, 631.0, 25.1197
34.339246180, 18.870, 560.0, 23.6643
34.382711940, 18.870, 652.0, 25.5343
34.426177700, 18.870, 592.0, 24.3311
34.469643460, 18.870, 634.0, 25.1794
34.513109220, 18.870, 571.0, 23.8956
34.556574980, 18.870, 528.0, 22.9783
34.600040740, 18.870, 545.0, 23.3452
34.643506500, 18.870, 538.0, 23.1948
34.686972260, 18.870, 547.0, 23.3880
34.730438020, 18.870, 557.0, 23.6008
34.773903780, 18.870, 506.0, 22.4944
34.817369540, 18.870, 511.0, 22.6053
34.860835300, 18.870, 539.0, 23.2164
34.904301060, 18.870, 523.0, 22.8692
34.947766820, 18.870, 527.0, 22.9565
34.991232580, 18.870, 512.0, 22.6274
35.034698340, 18.870, 507.0, 22.5167
35.078164100, 18.870, 505.0, 22.4722
35.121629860, 18.870, 528.0, 22.9783
35.165095620, 18.870, 534.0, 23.1084
35.208561380, 18.870, 515.0, 22.6936
35.252027140, 18.870, 566.0, 23.7908
35.295492900, 18.870, 573.0, 23.9374
35.338958660, 18.870, 571.0, 23.8956
35.382424420, 18.870, 655.0, 25.5930
35.425890180, 18.870, 619.0, 24.8797
35.469355940, 18.870, 608.0, 24.6577
35.512821700, 18.870, 664.0, 25.7682
35.556287460, 18.870, 598.0, 24.4540
35.599753220, 18.870, 630.0, 25.0998
35.643218980, 18.870, 531.0, 23.0434
35.686684740, 18.870, 588.0, 24.2487
35.730150500, 18.870, 526.0, 22.9347
35.773616260, 18.870, 472.0, 21.7256
35.817082020, 18.870, 463.0, 21.5174
35.860547780, 18.870, 483.0, 21.9773
35.904013540, 18.870, 483.0, 21.9773
35.947479300, 18.870, 457.0, 21.3776
35.990945060, 18.870, 452.0, 21.2603
36.034410820, 18.870, 494.0, 22.2261
36.077876580, 18.870, 490.0, 22.1359
36.121342340, 18.870, 521.0, 22.8254
36.164808100, 18.870, 501.0, 22.3830
36.208273860, 18.870, 509.0, 22.5610
36.251739620, 18.870, 545.0, 23.3452
36.295205380, 18.870, 555.0, 23.5584
36.338671140, 18.870, 581.0, 24.1039
36.382136900, 18.870, 554.0, 23.5372
36.425602660, 18.870, 579.0, 24.0624
36.469068420, 18.870, 574.0, 23.9583
36.512534180, 18.870, 606.0, 24.6171
36.555999940, 18.870, 636.0, 25.2190
36.599465700, 18.870, 661.0, 25.7099
36.642931460, 18.870, 670.0, 25.8844
36.686397220, 18.870, 705.0, 26.5518
36.729862980, 18.870, 634.0, 25.1794
36.773328740, 18.870, 641.0, 25.3180
36.816794500, 18.870, 639.0, 25.2784
36.860260260, 18.870, 627.0, 25.0400
36.903726020, 18.870, 631.0, 25.1197
36.947191780, 18.870, 560.0, 23.6643
36.990657540, 18.870, 639.0, 25.2784
37.034123300, 18.870, 711.0, 26.6646
37.077589060, 18.870, 635.0, 25.1992
37.121054820, 18.870, 654.0, 25.5734
37.164520580, 18.870, 633.0, 25.1595
37.207986340, 18.870, 582.0, 24.1247
37.251452100, 18.870, 560.0, 23.6643
37.294917860, 18.870, 601.0, 24.5153
37.338383620, 18.870, 577.0, 24.0208
37.381849380, 18.870, 609.0, 24.6779
37.425315140, 18.870, 585.0, 24.1868
37.468780900, 18.870, 560.0, 23.6643
37.512246660, 18.870, 591.0, 24.3105
37.555712420, 18.870, 551.0, 23.4734
37.599178180, 18.870, 585.0, 24.1868
37.642643940, 18.870, 538.0, 23.1948
37.686109700, 18.870, 558.0, 23.6220
37.729575460, 18.870, 622.0, 24.9399
37.773041220, 18.870, 546.0, 23.3666
37.816506980, 18.870, 547.0, 23.3880
37.859972740, 18.870, 594.0, 24.3721
37.903438500, 18.870, 609.0, 24.6779
37.946904260, 18.870, 621.0, 24.9199
37.990370020, 18.870, 639.0, 25.2784
38.033835780, 18.870, 700.0, 26.4575
38.077301540, 18.870, 622.0, 24.9399
38.120767300, 18.870, 667.0, 25.8263
38.164233060, 18.870, 686.0, 26.1916
38.207698820, 18.870, 676.0, 26.0000
38.251164580, 18.870, 727.0, 26.9629
38.294630340, 18.870, 657.0, 25.6320
38.338096100, 18.870, 673.0, 25.9422
38.381561860, 18.870, 608.0, 24.6577
38.425027620, 18.870, 620.0, 24.8998
38.468493380, 18.870, 583.0, 24.1454
38.511959140, 18.870, 583.0, 24.1454
38.555424900, 18.870, 551.0, 23.4734
38.598890660, 18.870, 551.0, 23.4734
38.642356420, 18.870, 540.0, 23.2379
38.685822180, 18.870, 583.0, 24.1454
38.729287940, 18.870, 555.0, 23.5584
38.772753700, 18.870, 602.0, 24.5357
38.816219460, 18.870, 628.0, 25.0599
38.859685220, 18.870, 647.0, 25.4362
38.903150980, 18.870, 652.0, 25.5343
38.946616740, 18.870, 612.0, 24.7386
38.990082500, 18.870, 622.0, 24.9399
39.033548260, 18.870, 598.0, 24.4540
39.077014020, 18.870, 577.0, 24.0208
39.120479780, 18.870, 583.0, 24.1454
39.163945540, 18.870, 592.0, 24.3311
39.207411300, 18.870, 550.0, 23.4521
39.250877060, 18.870, 540.0, 23.2379
39.294342820, 18.870, 548.0, 23.4094
39.337808580, 18.870, 555.0, 23.5584
39.381274340, 18.870, 495.0, 22.2486
39.424740100, 18.870, 527.0, 22.9565
39.468205860, 18.870, 564.0, 23.7487
39.511671620, 18.870, 519.0, 22.7816
39.555137380, 18.870, 556.0, 23.5797
39.598603140, 18.870, 602.0, 24.5357
39.642068900, 18.870, 574.0, 23.9583
39.685534660, 18.870, 492.0, 22.1811
39.729000420, 18.870, 502.0, 22.4054
39.772466180, 18.870, 502.0, 22.4054
39.815931940, 18.870, 507.0, 22.5167
39.859397700, 18.870, 464.0, 21.5407
39.902863460, 18.870, 515.0, 22.6936
39.946329220, 18.870, 450.0, 21.2132
39.989794980, 18.870, 525.0, 22.9129
40.033260740, 18.870, 495.0, 22.2486
40.076726500, 18.870, 538.0, 23.1948
40.120192260, 18.870, 537.0, 23.1733
40.163658020, 18.870, 517.0, 22.7376
40.207123780, 18.870, 545.0, 23.3452
40.250589540, 18.870, 548.0, 23.4094
40.294055300, 18.870, 508.0, 22.5389
40.337521060, 18.870, 473.0, 21.7486
40.380986820, 18.870, 509.0, 22.5610
40.424452580, 18.870, 500.0, 22.3607
40.467918340, 18.870, 515.0, 22.6936
40.511384100, 18.870, 465.0, 21.5639
40.554849860, 18.870, 480.0, 21.9089
40.598315620, 18.870, 497.0, 22.2935
40.641781380, 18.870, 479.0, 21.8861
40.685247140, 18.870, 436.0, 20.8806
40.728712900, 18.870, 430.0, 20.7364
40.772178660, 18.870, 478.0, 21.8632
40.815644420, 18.870, 466.0, 21.5870
40.859110180, 18.870, 451.0, 21.2368
40.902575940, 18.870, 494.0, 22.2261
40.946041700, 18.870, 437.0, 20.9045
40.989507460, 18.870, 420.0, 20.4939
41.032973220, 18.870, 419.0, 20.4695
41.076438980, 18.870, 495.0, 22.2486
41.119904740, 18.870, 466.0, 21.5870
41.163370500, 18.870, 473.0, 21.7486
41.206836260, 18.870, 500.0, 22.3607
41.250302020, 18.870, 462.0, 21.4942
41.293767780, 18.870, 511.0, 22.6053
41.337233540, 18.870, 536.0, 23.1517
41.380699300, 18.870, 528.0, 22.9783
41.424165060, 18.870, 494.0, 22.2261
41.467630820, 18.870, 577.0, 24.0208
41.511096580, 18.870, 535.0, 23.1301
41.554562340, 18.870, 554.0, 23.5372
41.598028100, 18.870, 534.0, 23.1084
41.641493860, 18.870, 544.0, 23.3238
41.684959620, 18.870, 535.0, 23.1301
41.728425380, 18.870, 533.0, 23.0868
41.771891140, 18.870, 515.0, 22.6936
41.815356900, 18.870, 548.0, 23.4094
41.858822660, 18.870, 490.0, 22.1359
41.902288420, 18.870, 497.0, 22.2935
41.945754180, 18.870, 496.0, 22.2711
41.989219940, 18.870, 459.0, 21.4243
42.032685700, 18.870, 494.0, 22.2261
42.076151460, 18.870, 491.0, 22.1585
42.119617220, 18.870, 492.0, 22.1811
42.163082980, 18.870, 466.0, 21.5870
42.206548740, 18.870, 484.0, 22.0000
42.250014500, 18.870, 473.0, 21.7486
42.293480260, 18.870, 476.0, 21.8174
42.336946020, 18.870, 482.0, 21.9545
42.380411780, 18.870, 481.0, 21.9317
42.423877540, 18.870, 448.0, 21.1660
42.467343300, 18.870, 448.0, 21.1660
42.510809060, 18.870, 471.0, 21.7025
42.554274820, 18.870, 457.0, 21.3776
42.597740580, 18.870, 442.0, 21.0238
42.641206340, 18.870, 427.0, 20.6640
42.684672100, 18.870, 445.0, 21.0950
42.728137860, 18.870, 422.0, 20.5426
42.771603620, 18.870, 430.0, 20.7364
42.815069380, 18.870, 441.0, 21.0000
42.858535140, 18.870, 456.0, 21.3542
42.902000900, 18.870, 425.0, 20.6155
42.945466660, 18.870, 443.0, 21.0476
42.988932420, 18.870, 431.0, 20.7605
43.032398180, 18.870, 477.0, 21.8403
43.075863940, 18.870, 494.0, 22.2261
43.119329700, 18.870, 437.0, 20.9045
43.162795460, 18.870, 446.0, 21.1187
43.206261220, 18.870, 486.0, 22.0454
43.249726980, 18.870, 526.0, 22.9347
43.293192740, 18.870, 496.0, 22.2711
43.336658500, 18.870, 516.0, 22.7156
43.380124260, 18.870, 451.0, 21.2368
43.423590020, 18.870, 517.0, 22.7376
43.467055780, 18.870, 502.0, 22.4054
43.510521540, 18.870, 503.0, 22.4277
43.553987300, 18.870, 510.0, 22.5832
43.597453060, 18.870, 479.0, 21.8861
43.640918820, 18.870, 526.0, 22.9347
43.684384580, 18.870, 500.0, 22.3607
43.727850340, 18.870, 533.0, 23.0868
43.771316100, 18.870, 441.0, 21.0000
43.814781860, 18.870, 457.0, 21.3776
43.858247620, 18.870, 483.0, 21.9773
43.901713380, 18.870, 455.0, 21.3307
43.945179140, 18.870, 447.0, 21.1424
43.988644900, 18.870, 473.0, 21.7486
44.032110660, 18.870, 517.0, 22.7376
44.075576420, 18.870, 479.0, 21.8861
44.119042180, 18.870, 456.0, 21.3542
44.162507940, 18.870, 479.0, 21.8861
44.205973700, 18.870, 470.0, 21.6795
44.249439460, 18.870, 465.0, 21.5639
44.292905220, 18.870, 515.0, 22.6936
44.336370980, 18.870, 500.0, 22.3607
44.379836740, 18.870, 492.0, 22.1811
44.423302500, 18.870, 451.0, 21.2368
44.466768260, 18.870, 475.0, 21.7945
44.510234020, 18.870, 500.0, 22.3607
44.553699780, 18.870, 409.0, 20.2237
44.597165540, 18.870, 411.0, 20.2731
44.640631300, 18.870, 403.0, 20.0749
44.684097060, 18.870, 434.0, 20.8327
44.727562820, 18.870, 395.0, 19.8746
44.771028580, 18.870, 421.0, 20.5183
44.814494340, 18.870, 407.0, 20.1742
44.857960100, 18.870, 370.0, 19.2354
44.901425860, 18.870, 364.0, 19.0788
44.944891620, 18.870, 402.0, 20.0499
44.988357380, 18.870, 394.0, 19.8494
45.031823140, 18.870, 406.0, 20.1494
45.075288900, 18.870, 374.0, 19.3391
45.118754660, 18.870, 400.0, 20.0000
45.162220420, 18.870, 374.0, 19.3391
45.205686180, 18.870, 405.0, 20.1246
45.249151940, 18.870, 406.0, 20.1494
45.292617700, 18.870, 436.0, 20.8806
45.336083460, 18.870, 421.0, 20.5183
45.379549220, 18.870, 432.0, 20.7846
45.423014980, 18.870, 392.0, 19.7990
45.466480740, 18.870, 403.0, 20.0749
45.509946500, 18.870, 406.0, 20.1494
45.553412260, 18.870, 429.0, 20.7123
45.596878020, 18.870, 417.0, 20.4206
45.640343780, 18.870, 402.0, 20.0499
45.683809540, 18.870, 374.0, 19.3391
45.727275300, 18.870, 366.0, 19.1311
45.770741060, 18.870, 380.0, 19.4936
45.814206820, 18.870, 387.0, 19.6723
45.857672580, 18.870, 417.0, 20.4206
45.901138340, 18.870, 376.0, 19.3907
45.944604100, 18.870, 399.0, 19.9750
45.988069860, 18.870, 413.0, 20.3224
46.031535620, 18.870, 396.0, 19.8997
46.075001380, 18.870, 394.0, 19.8494
46.118467140, 18.870, 367.0, 19.1572
46.161932900, 18.870, 389.0, 19.7231
46.205398660, 18.870, 421.0, 20.5183
46.248864420, 18.870, 434.0, 20.8327
46.292330180, 18.870, 434.0, 20.8327
46.335795940, 18.870, 402.0, 20.0499
46.379261700, 18.870, 412.0, 20.2978
46.422727460, 18.870, 432.0, 20.7846
46.466193220, 18.870, 445.0, 21.0950
46.509658980, 18.870, 388.0, 19.6977
46.553124740, 18.870, 391.0, 19.7737
46.596590500, 18.870, 412.0, 20.2978
46.640056260, 18.870, 401.0, 20.0250
46.683522020, 18.870, 401.0, 20.0250
46.726987780, 18.870, 396.0, 19.8997
46.770453540, 18.870, 368.0, 19.1833
46.813919300, 18.870, 378.0, 19.4422
46.857385060, 18.870, 423.0, 20.5670
46.900850820, 18.870, 400.0, 20.0000
46.944316580, 18.870, 438.0, 20.9284
46.987782340, 18.870, 431.0, 20.7605
47.031248100, 18.870, 443.0, 21.0476
47.074713860, 18.870, 396.0, 19.8997
47.118179620, 18.870, 452.0, 21.2603
47.161645380, 18.870, 473.0, 21.7486
47.205111140, 18.870, 415.0, 20.3715
47.248576900, 18.870, 410.0, 20.2485
47.292042660, 18.870, 413.0, 20.3224
47.335508420, 18.870, 374.0, 19.3391
47.378974180, 18.870, 406.0, 20.1494
47.422439940, 18.870, 419.0, 20.4695
47.465905700, 18.870, 374.0, 19.3391
47.509371460, 18.870, 425.0, 20.6155
47.552837220, 18.870, 380.0, 19.4936
47.596302980, 18.870, 410.0, 20.2485
47.639768740, 18.870, 353.0, 18.7883
47.683234500, 18.870, 371.0, 19.2614
47.726700260, 18.870, 374.0, 19.3391
47.770166020, 18.870, 394.0, 19.8494
47.813631780, 18.870, 368.0, 19.1833
47.857097540, 18.870, 374.0, 19.3391
47.900563300, 18.870, 374.0, 19.3391
47.944029060, 18.870, 378.0, 19.4422
47.987494820, 18.870, 416.0, 20.3961
48.030960580, 18.870, 374.0, 19.3391
48.074426340, 18.870, 379.0, 19.4679
48.117892100, 18.870, 398.0, 19.9499
48.161357860, 18.870, 399.0, 19.9750
48.204823620, 18.870, 356.0, 18.8680
48.248289380, 18.870, 395.0, 19.8746
48.291755140, 18.870, 386.0, 19.6469
48.335220900, 18.870, 431.0, 20.7605
48.378686660, 18.870, 386.0, 19.6469
48.422152420, 18.870, 375.0, 19.3649
48.465618180, 18.870, 394.0, 19.8494
48.509083940, 18.870, 424.0, 20.5913
48.552549700, 18.870, 391.0, 19.7737
48.596015460, 18.870, 411.0, 20.2731
48.639481220, 18.870, 403.0, 20.0749
48.682946980, 18.870, 399.0, 19.9750
48.726412740, 18.870, 389.0, 19.7231
48.769878500, 18.870, 395.0, 19.8746
48.813344260, 18.870, 428.0, 20.6882
48.856810020, 18.870, 391.0, 19.7737
48.900275780, 18.870, 389.0, 19.7231
48.943741540, 18.870, 397.0, 19.9249
48.987207300, 18.870, 403.0, 20.0749
49.030673060, 18.870, 416.0, 20.3961
49.074138820, 18.870, 365.0, 19.1050
49.117604580, 18.870, 360.0, 18.9737
49.161070340, 18.870, 412.0, 20.2978
49.204536100, 18.870, 356.0, 18.8680
49.248001860, 18.870, 373.0, 19.3132
49.291467620, 18.870, 353.0, 18.7883
49.334933380, 18.870, 407.0, 20.1742
49.378399140, 18.870, 379.0, 19.4679
49.421864900, 18.870, 359.0, 18.9473
49.465330660, 18.870, 397.0, 19.9249
49.508796420, 18.870, 383.0, 19.5704
49.552262180, 18.870, 363.0, 19.0526
49.595727940, 18.870, 351.0, 18.7350
49.639193700, 18.870, 374.0, 19.3391
49.682659460, 18.870, 411.0, 20.2731
49.726125220, 18.870, 381.0, 19.5192
49.769590980, 18.870, 368.0, 19.1833
49.813056740, 18.870, 375.0, 19.3649
49.856522500, 18.870, 376.0, 19.3907
49.899988260, 18.870, 391.0, 19.7737
49.943454020, 18.870, 386.0, 19.6469
49.986919780, 18.870, 438.0, 20.9284
50.030385540, 18.870, 361.0, 19.0000
50.073851300, 18.870, 391.0, 19.7737
50.117317060, 18.870, 401.0, 20.0250
50.160782820, 18.870, 408.0, 20.1990
50.204248580, 18.870, 424.0, 20.5913
50.247714340, 18.870, 318.0, 17.8326
50.291180100, 18.870, 369.0, 19.2094
50.334645860, 18.870, 375.0, 19.3649
50.378111620, 18.870, 391.0, 19.7737
50.421577380, 18.870, 398.0, 19.9499
50.465043140, 18.870, 371.0, 19.2614
50.508508900, 18.870, 331.0, 18.1934
50.551974660, 18.870, 388.0, 19.6977
50.595440420, 18.870, 378.0, 19.4422
50.638906180, 18.870, 386.0, 19.6469
50.682371940, 18.870, 330.0, 18.1659
50.725837700, 18.870, 334.0, 18.2757
50.769303460, 18.870, 359.0, 18.9473
50.812769220, 18.870, 321.0, 17.9165
50.856234980, 18.870, 335.0, 18.3030
50.899700740, 18.870, 363.0, 19.0526
50.943166500, 18.870, 306.0, 17.4929
50.986632260, 18.870, 342.0, 18.4932
51.030098020, 18.870, 364.0, 19.0788
51.073563780, 18.870, 348.0, 18.6548
51.117029540, 18.870, 353.0, 18.7883
51.160495300, 18.870, 341.0, 18.4662
51.203961060, 18.870, 386.0, 19.6469
51.247426820, 18.870, 348.0, 18.6548
51.290892580, 18.870, 348.0, 18.6548
51.334358340, 18.870, 341.0, 18.4662
51.377824100, 18.870, 335.0, 18.3030
51.421289860, 18.870, 339.0, 18.4120
51.464755620, 18.870, 340.0, 18.4391
51.508221380, 18.870, 317.0, 17.8045
51.551687140, 18.870, 339.0, 18.4120
51.595152900, 18.870, 359.0, 18.9473
51.638618660, 18.870, 312.0, 17.6635
51.682084420, 18.870, 360.0, 18.9737
51.725550180, 18.870, 325.0, 18.0278
51.769015940, 18.870, 340.0, 18.4391
51.812481700, 18.870, 310.0, 17.6068
51.855947460, 18.870, 291.0, 17.0587
51.899413220, 18.870, 334.0, 18.2757
51.942878980, 18.870, 294.0, 17.1464
51.986344740, 18.870, 337.0, 18.3576
52.029810500, 18.870, 332.0, 18.2209
52.073276260, 18.870, 355.0, 18.8414
52.116742020, 18.870, 330.0, 18.1659
52.160207780, 18.870, 318.0, 17.8326
52.203673540, 18.870, 315.0, 17.7482
52.247139300, 18.870, 325.0, 18.0278
52.290605060, 18.870, 382.0, 19.5448
52.334070820, 18.870, 330.0, 18.1659
52.377536580, 18.870, 316.0, 17.7764
52.421002340, 18.870, 336.0, 18.3303
52.464468100, 18.870, 349.0, 18.6815
52.507933860, 18.870, 334.0, 18.2757
52.551399620, 18.870, 345.0, 18.5742
52.594865380, 18.870, 319.0, 17.8606
52.638331140, 18.870, 297.0, 17.2337
52.681796900, 18.870, 314.0, 17.7200
52.725262660, 18.870, 312.0, 17.6635
52.768728420, 18.870, 303.0, 17.4069
52.812194180, 18.870, 352.0, 18.7617
52.855659940, 18.870, 342.0, 18.4932
52.899125700, 18.870, 347.0, 18.6279
52.942591460, 18.870, 324.0, 18.0000
52.986057220, 18.870, 333.0, 18.2483
53.029522980, 18.870, 323.0, 17.9722
53.072988740, 18.870, 336.0, 18.3303
53.116454500, 18.870, 351.0, 18.7350
53.159920260, 18.870, 248.0, 15.7480
53.203386020, 18.870, 319.0, 17.8606
53.246851780, 18.870, 328.0, 18.1108
53.290317540, 18.870, 326.0, 18.0555
53.333783300, 18.870, 325.0, 18.0278
53.377249060, 18.870, 352.0, 18.7617
53.420714820, 18.870, 339.0, 18.4120
53.464180580, 18.870, 350.0, 18.7083
53.507646340, 18.870, 345.0, 18.5742
53.551112100, 18.870, 318.0, 17.8326
53.594577860, 18.870, 336.0, 18.3303
53.638043620, 18.870, 322.0, 17.9444
53.681509380, 18.870, 309.0, 17.5784
53.724975140, 18.870, 359.0, 18.9473
53.768440900, 18.870, 312.0, 17.6635
53.811906660, 18.870, 356.0, 18.8680
53.855372420, 18.870, 309.0, 17.5784
53.898838180, 18.870, 351.0, 18.7350
53.942303940, 18.870, 337.0, 18.3576
53.985769700, 18.870, 314.0, 17.7200
54.029235460, 18.870, 317.0, 17.8045
54.072701220, 18.870, 331.0, 18.1934
54.116166980, 18.870, 295.0, 17.1756
54.159632740, 18.870, 325.0, 18.0278
54.203098500, 18.870, 344.0, 18.5472
54.246564260, 18.870, 322.0, 17.9444
54.290030020, 18.870, 315.0, 17.7482
54.333495780, 18.870, 289.0, 17.0000
54.376961540, 18.870, 352.0, 18.7617
54.420427300, 18.870, 324.0, 18.0000
54.463893060, 18.870, 332.0, 18.2209
54.507358820, 18.870, 330.0, 18.1659
54.550824580, 18.870, 340.0, 18.4391
54.594290340, 18.870, 290.0, 17.0294
54.637756100, 18.870, 311.0, 17.6352
54.681221860, 18.870, 306.0, 17.4929
54.724687620, 18.870, 281.0, 16.7631
54.768153380, 18.870, 276.0, 16.6132
54.811619140, 18.870, 307.0, 17.5214
54.855084900, 18.870, 289.0, 17.0000
54.898550660, 18.870, 274.0, 16.5529
54.942016420, 18.870, 290.0, 17.0294
54.985482180, 18.870, 313.0, 17.6918
55.028947940, 18.870, 276.0, 16.6132
55.072413700, 18.870, 306.0, 17.4929
55.115879460, 18.870, 289.0, 17.0000
55.159345220, 18.870, 290.0, 17.0294
55.202810980, 18.870, 298.0, 17.2627
55.246276740, 18.870, 279.0, 16.7033
55.289742500, 18.870, 286.0, 16.9115
55.333208260, 18.870, 317.0, 17.8045
55.376674020, 18.870, 313.0, 17.6918
55.420139780, 18.870, 283.0, 16.8226
55.463605540, 18.870, 315.0, 17.7482
55.507071300, 18.870, 318.0, 17.8326
55.550537060, 18.870, 299.0, 17.2916
55.594002820, 18.870, 328.0, 18.1108
55.637468580, 18.870, 338.0, 18.3848
55.680934340, 18.870, 324.0, 18.0000
55.724400100, 18.870, 302.0, 17.3781
55.767865860, 18.870, 305.0, 17.4642
55.811331620, 18.870, 342.0, 18.4932
55.854797380, 18.870, 337.0, 18.3576
55.898263140, 18.870, 364.0, 19.0788
55.941728900, 18.870, 332.0, 18.2209
55.985194660, 18.870, 304.0, 17.4356
56.028660420, 18.870, 293.0, 17.1172
56.072126180, 18.870, 347.0, 18.6279
56.115591940, 18.870, 366.0, 19.1311
56.159057700, 18.870, 299.0, 17.2916
56.202523460, 18.870, 308.0, 17.5499
56.245989220, 18.870, 248.0, 15.7480
56.289454980, 18.870, 300.0, 17.3205
56.332920740, 18.870, 274.0, 16.5529
56.376386500, 18.870, 317.0, 17.8045
56.419852260, 18.870, 319.0, 17.8606
56.463318020, 18.870, 293.0, 17.1172
56.506783780, 18.870, 265.0, 16.2788
56.550249540, 18.870, 267.0, 16.3401
56.593715300, 18.870, 280.0, 16.7332
56.637181060, 18.870, 310.0, 17.6068
56.680646820, 18.870, 275.0, 16.5831
56.724112580, 18.870, 288.0, 16.9706
56.767578340, 18.870, 241.0, 15.5242
56.811044100, 18.870, 281.0, 16.7631
56.854509860, 18.870, 307.0, 17.5214
56.897975620, 18.870, 303.0, 17.4069
56.941441380, 18.870, 280.0, 16.7332
56.984907140, 18.870, 262.0, 16.1864
57.028372900, 18.870, 273.0, 16.5227
57.071838660, 18.870, 296.0, 17.2047
57.115304420, 18.870, 260.0, 16.1245
57.158770180, 18.870, 256.0, 16.0000
57.202235940, 18.870, 250.0, 15.8114
57.245701700, 18.870, 282.0, 16.7929
57.289167460, 18.870, 246.0, 15.6844
57.332633220, 18.870, 276.0, 16.6132
57.376098980, 18.870, 273.0, 16.5227
57.419564740, 18.870, 236.0, 15.3623
57.463030500, 18.870, 230.0, 15.1658
57.506496260, 18.870, 309.0, 17.5784
57.549962020, 18.870, 236.0, 15.3623
57.593427780, 18.870, 257.0, 16.0312
57.636893540, 18.870, 240.0, 15.4919
57.680359300, 18.870, 298.0, 17.2627
57.723825060, 18.870, 248.0, 15.7480
57.767290820, 18.870, 281.0, 16.7631
57.810756580, 18.870, 275.0, 16.5831
57.854222340, 18.870, 264.0, 16.2481
57.897688100, 18.870, 265.0, 16.2788
57.941153860, 18.870, 243.0, 15.5885
57.984619620, 18.870, 270.0, 16.4317
58.028085380, 18.870, 269.0, 16.4012
58.071551140, 18.870, 267.0, 16.3401
58.115016900, 18.870, 264.0, 16.2481
58.158482660, 18.870, 249.0, 15.7797
58.201948420, 18.870, 268.0, 16.3707
58.245414180, 18.870, 284.0, 16.8523
58.288879940, 18.870, 283.0, 16.8226
58.332345700, 18.870, 240.0, 15.4919
58.375811460, 18.870, 232.0, 15.2315
58.419277220, 18.870, 280.0, 16.7332
58.462742980, 18.870, 270.0, 16.4317
58.506208740, 18.870, 245.0, 15.6525
58.549674500, 18.870, 263.0, 16.2173
58.593140260, 18.870, 231.0, 15.1987
58.636606020, 18.870, 247.0, 15.7162
58.680071780, 18.870, 229.0, 15.1327
58.723537540, 18.870, 269.0, 16.4012
58.767003300, 18.870, 267.0, 16.3401
58.810469060, 18.870, 251.0, 15.8430
58.853934820, 18.870, 271.0, 16.4621
58.897400580, 18.870, 237.0, 15.3948
58.940866340, 18.870, 269.0, 16.4012
58.984332100, 18.870, 292.0, 17.0880
59.027797860, 18.870, 243.0, 15.5885
59.071263620, 18.870, 265.0, 16.2788
59.114729380, 18.870, 287.0, 16.9411
59.158195140, 18.870, 259.0, 16.0935
59.201660900, 18.870, 238.0, 15.4272
59.245126660, 18.870, 259.0, 16.0935
59.288592420, 18.870, 230.0, 15.1658
59.332058180, 18.870, 217.0, 14.7309
59.375523940, 18.870, 249.0, 15.7797
59.418989700, 18.870, 228.0, 15.0997
59.462455460, 18.870, 233.0, 15.2643
59.505921220, 18.870, 226.0, 15.0333
59.549386980, 18.870, 219.0, 14.7986
59.592852740, 18.870, 229.0, 15.1327
59.636318500, 18.870, 250.0, 15.8114
59.679784260, 18.870, 230.0, 15.1658
59.723250020, 18.870, 263.0, 16.2173
59.766715780, 18.870, 257.0, 16.0312
59.810181540, 18.870, 234.0, 15.2971
59.853647300, 18.870, 250.0, 15.8114
59.897113060, 18.870, 231.0, 15.1987
59.940578820, 18.870, 205.0, 14.3178
59.984044580, 18.870, 219.0, 14.7986
59.994911020, 18.870, 262.0, 16.1864