File: XRD/2025_06_03_Sorbic_Acid_3_60_8min.csv
[Measurement conditions]
Sample identification,2025_06_03_Sorbic_Acid_3_60_8min
Comment - 1,"Sorbic Acid Standard"
Anode material,Cu
K-Alpha1 wavelength,1.5405980
K-Alpha2 wavelength,1.5444260
Ratio K-Alpha2/K-Alpha1,0.500
Divergence slit,Fixed,0.76mm
Monochromator used,NO
Generator voltage, 40
Tube current, 15
File date and time,03/Jun/2025 15:22
Unit cell,
h k l, 0 0 0
Scan axis,Gonio
Scan range,2.995000000,60.000344240
Scan step size,0.0108664
No. of points, 5246
Scan type,CONTINUOUS
Time per step,18.870
[Scan points]
Angle, TimePerStep, Intensity, ESD
3.000433220, 18.870, 43466.0, 208.4850
3.043898980, 18.870, 41335.0, 203.3101
3.087364740, 18.870, 39310.0, 198.2675
3.130830500, 18.870, 37624.0, 193.9691
3.174296260, 18.870, 35240.0, 187.7232
3.217762020, 18.870, 33410.0, 182.7840
3.261227780, 18.870, 31364.0, 177.0988
3.304693540, 18.870, 30007.0, 173.2253
3.348159300, 18.870, 28049.0, 167.4784
3.391625060, 18.870, 26703.0, 163.4105
3.435090820, 18.870, 24883.0, 157.7435
3.478556580, 18.870, 23552.0, 153.4666
3.522022340, 18.870, 22188.0, 148.9564
3.565488100, 18.870, 21008.0, 144.9414
3.608953860, 18.870, 19845.0, 140.8723
3.652419620, 18.870, 18352.0, 135.4696
3.695885380, 18.870, 17381.0, 131.8370
3.739351140, 18.870, 16186.0, 127.2242
3.782816900, 18.870, 15047.0, 122.6662
3.826282660, 18.870, 14198.0, 119.1554
3.869748420, 18.870, 13256.0, 115.1347
3.913214180, 18.870, 12206.0, 110.4808
3.956679940, 18.870, 11279.0, 106.2026
4.000145700, 18.870, 10666.0, 103.2763
4.043611460, 18.870, 9969.0, 99.8449
4.087077220, 18.870, 8851.0, 94.0798
4.130542980, 18.870, 8594.0, 92.7038
4.174008740, 18.870, 7910.0, 88.9382
4.217474500, 18.870, 7142.0, 84.5104
4.260940260, 18.870, 6605.0, 81.2712
4.304406020, 18.870, 6363.0, 79.7684
4.347871780, 18.870, 5717.0, 75.6108
4.391337540, 18.870, 5398.0, 73.4711
4.434803300, 18.870, 4710.0, 68.6294
4.478269060, 18.870, 4542.0, 67.3944
4.521734820, 18.870, 4108.0, 64.0937
4.565200580, 18.870, 3862.0, 62.1450
4.608666340, 18.870, 3581.0, 59.8415
4.652132100, 18.870, 3248.0, 56.9912
4.695597860, 18.870, 3061.0, 55.3263
4.739063620, 18.870, 2811.0, 53.0189
4.782529380, 18.870, 2631.0, 51.2933
4.825995140, 18.870, 2583.0, 50.8232
4.869460900, 18.870, 2513.0, 50.1298
4.912926660, 18.870, 2307.0, 48.0312
4.956392420, 18.870, 2289.0, 47.8435
4.999858180, 18.870, 2297.0, 47.9270
5.043323940, 18.870, 2248.0, 47.4131
5.086789700, 18.870, 2242.0, 47.3498
5.130255460, 18.870, 2236.0, 47.2864
5.173721220, 18.870, 2279.0, 47.7389
5.217186980, 18.870, 2264.0, 47.5815
5.260652740, 18.870, 2269.0, 47.6340
5.304118500, 18.870, 2292.0, 47.8748
5.347584260, 18.870, 2250.0, 47.4342
5.391050020, 18.870, 2174.0, 46.6262
5.434515780, 18.870, 2036.0, 45.1221
5.477981540, 18.870, 1955.0, 44.2154
5.521447300, 18.870, 1795.0, 42.3674
5.564913060, 18.870, 1817.0, 42.6263
5.608378820, 18.870, 1682.0, 41.0122
5.651844580, 18.870, 1575.0, 39.6863
5.695310340, 18.870, 1491.0, 38.6135
5.738776100, 18.870, 1510.0, 38.8587
5.782241860, 18.870, 1455.0, 38.1445
5.825707620, 18.870, 1431.0, 37.8286
5.869173380, 18.870, 1425.0, 37.7492
5.912639140, 18.870, 1346.0, 36.6879
5.956104900, 18.870, 1372.0, 37.0405
5.999570660, 18.870, 1313.0, 36.2353
6.043036420, 18.870, 1280.0, 35.7771
6.086502180, 18.870, 1271.0, 35.6511
6.129967940, 18.870, 1277.0, 35.7351
6.173433700, 18.870, 1296.0, 36.0000
6.216899460, 18.870, 1270.0, 35.6371
6.260365220, 18.870, 1244.0, 35.2704
6.303830980, 18.870, 1179.0, 34.3366
6.347296740, 18.870, 1178.0, 34.3220
6.390762500, 18.870, 1183.0, 34.3948
6.434228260, 18.870, 1185.0, 34.4238
6.477694020, 18.870, 1164.0, 34.1174
6.521159780, 18.870, 1142.0, 33.7935
6.564625540, 18.870, 1103.0, 33.2114
6.608091300, 18.870, 1128.0, 33.5857
6.651557060, 18.870, 1101.0, 33.1813
6.695022820, 18.870, 1131.0, 33.6303
6.738488580, 18.870, 1072.0, 32.7414
6.781954340, 18.870, 1041.0, 32.2645
6.825420100, 18.870, 1017.0, 31.8904
6.868885860, 18.870, 1063.0, 32.6037
6.912351620, 18.870, 1015.0, 31.8591
6.955817380, 18.870, 1019.0, 31.9218
6.999283140, 18.870, 1031.0, 32.1092
7.042748900, 18.870, 1018.0, 31.9061
7.086214660, 18.870, 992.0, 31.4960
7.129680420, 18.870, 957.0, 30.9354
7.173146180, 18.870, 979.0, 31.2890
7.216611940, 18.870, 1002.0, 31.6544
7.260077700, 18.870, 1034.0, 32.1559
7.303543460, 18.870, 984.0, 31.3688
7.347009220, 18.870, 992.0, 31.4960
7.390474980, 18.870, 989.0, 31.4484
7.433940740, 18.870, 904.0, 30.0666
7.477406500, 18.870, 985.0, 31.3847
7.520872260, 18.870, 976.0, 31.2410
7.564338020, 18.870, 954.0, 30.8869
7.607803780, 18.870, 931.0, 30.5123
7.651269540, 18.870, 935.0, 30.5778
7.694735300, 18.870, 986.0, 31.4006
7.738201060, 18.870, 981.0, 31.3209
7.781666820, 18.870, 947.0, 30.7734
7.825132580, 18.870, 925.0, 30.4138
7.868598340, 18.870, 1010.0, 31.7805
7.912064100, 18.870, 987.0, 31.4166
7.955529860, 18.870, 985.0, 31.3847
7.998995620, 18.870, 982.0, 31.3369
8.042461380, 18.870, 987.0, 31.4166
8.085927140, 18.870, 945.0, 30.7409
8.129392900, 18.870, 1035.0, 32.1714
8.172858660, 18.870, 959.0, 30.9677
8.216324420, 18.870, 963.0, 31.0322
8.259790180, 18.870, 982.0, 31.3369
8.303255940, 18.870, 921.0, 30.3480
8.346721700, 18.870, 982.0, 31.3369
8.390187460, 18.870, 902.0, 30.0333
8.433653220, 18.870, 943.0, 30.7083
8.477118980, 18.870, 973.0, 31.1929
8.520584740, 18.870, 1001.0, 31.6386
8.564050500, 18.870, 949.0, 30.8058
8.607516260, 18.870, 983.0, 31.3528
8.650982020, 18.870, 992.0, 31.4960
8.694447780, 18.870, 949.0, 30.8058
8.737913540, 18.870, 1017.0, 31.8904
8.781379300, 18.870, 1046.0, 32.3419
8.824845060, 18.870, 1062.0, 32.5883
8.868310820, 18.870, 1030.0, 32.0936
8.911776580, 18.870, 1073.0, 32.7567
8.955242340, 18.870, 1110.0, 33.3167
8.998708100, 18.870, 1069.0, 32.6956
9.042173860, 18.870, 1093.0, 33.0606
9.085639620, 18.870, 1172.0, 34.2345
9.129105380, 18.870, 1186.0, 34.4384
9.172571140, 18.870, 1073.0, 32.7567
9.216036900, 18.870, 1099.0, 33.1512
9.259502660, 18.870, 1090.0, 33.0151
9.302968420, 18.870, 1093.0, 33.0606
9.346434180, 18.870, 1046.0, 32.3419
9.389899940, 18.870, 1008.0, 31.7490
9.433365700, 18.870, 1012.0, 31.8119
9.476831460, 18.870, 1071.0, 32.7261
9.520297220, 18.870, 1016.0, 31.8748
9.563762980, 18.870, 1055.0, 32.4808
9.607228740, 18.870, 1111.0, 33.3317
9.650694500, 18.870, 1073.0, 32.7567
9.694160260, 18.870, 1114.0, 33.3766
9.737626020, 18.870, 1060.0, 32.5576
9.781091780, 18.870, 1067.0, 32.6650
9.824557540, 18.870, 1049.0, 32.3883
9.868023300, 18.870, 1039.0, 32.2335
9.911489060, 18.870, 1065.0, 32.6343
9.954954820, 18.870, 1068.0, 32.6803
9.998420580, 18.870, 1104.0, 33.2265
10.041886340, 18.870, 1067.0, 32.6650
10.085352100, 18.870, 1122.0, 33.4963
10.128817860, 18.870, 1086.0, 32.9545
10.172283620, 18.870, 1141.0, 33.7787
10.215749380, 18.870, 1124.0, 33.5261
10.259215140, 18.870, 1126.0, 33.5559
10.302680900, 18.870, 1132.0, 33.6452
10.346146660, 18.870, 1149.0, 33.8969
10.389612420, 18.870, 1121.0, 33.4813
10.433078180, 18.870, 1181.0, 34.3657
10.476543940, 18.870, 1212.0, 34.8138
10.520009700, 18.870, 1151.0, 33.9264
10.563475460, 18.870, 1134.0, 33.6749
10.606941220, 18.870, 1138.0, 33.7343
10.650406980, 18.870, 1122.0, 33.4963
10.693872740, 18.870, 1220.0, 34.9285
10.737338500, 18.870, 1186.0, 34.4384
10.780804260, 18.870, 1297.0, 36.0139
10.824270020, 18.870, 1345.0, 36.6742
10.867735780, 18.870, 1557.0, 39.4588
10.911201540, 18.870, 1733.0, 41.6293
10.954667300, 18.870, 2054.0, 45.3211
10.998133060, 18.870, 2337.0, 48.3425
11.041598820, 18.870, 2831.0, 53.2071
11.085064580, 18.870, 3558.0, 59.6490
11.128530340, 18.870, 4666.0, 68.3081
11.171996100, 18.870, 7117.0, 84.3623
11.215461860, 18.870, 13192.0, 114.8564
11.258927620, 18.870, 20696.0, 143.8610
11.302393380, 18.870, 26287.0, 162.1327
11.345859140, 18.870, 30810.0, 175.5278
11.389324900, 18.870, 35594.0, 188.6637
11.432790660, 18.870, 43693.0, 209.0287
11.476256420, 18.870, 47450.0, 217.8302
11.519722180, 18.870, 41483.0, 203.6738
11.563187940, 18.870, 28282.0, 168.1725
11.606653700, 18.870, 17685.0, 132.9850
11.650119460, 18.870, 12078.0, 109.9000
11.693585220, 18.870, 9970.0, 99.8499
11.737050980, 18.870, 7788.0, 88.2496
11.780516740, 18.870, 4039.0, 63.5531
11.823982500, 18.870, 2492.0, 49.9199
11.867448260, 18.870, 2096.0, 45.7821
11.910914020, 18.870, 1768.0, 42.0476
11.954379780, 18.870, 1695.0, 41.1704
11.997845540, 18.870, 1600.0, 40.0000
12.041311300, 18.870, 1637.0, 40.4599
12.084777060, 18.870, 1542.0, 39.2683
12.128242820, 18.870, 1536.0, 39.1918
12.171708580, 18.870, 1550.0, 39.3700
12.215174340, 18.870, 1519.0, 38.9744
12.258640100, 18.870, 1546.0, 39.3192
12.302105860, 18.870, 1515.0, 38.9230
12.345571620, 18.870, 1500.0, 38.7298
12.389037380, 18.870, 1437.0, 37.9078
12.432503140, 18.870, 1541.0, 39.2556
12.475968900, 18.870, 1636.0, 40.4475
12.519434660, 18.870, 1665.0, 40.8044
12.562900420, 18.870, 1854.0, 43.0581
12.606366180, 18.870, 1993.0, 44.6430
12.649831940, 18.870, 2315.0, 48.1144
12.693297700, 18.870, 2551.0, 50.5074
12.736763460, 18.870, 3015.0, 54.9090
12.780229220, 18.870, 3676.0, 60.6300
12.823694980, 18.870, 4763.0, 69.0145
12.867160740, 18.870, 5914.0, 76.9025
12.910626500, 18.870, 6292.0, 79.3221
12.954092260, 18.870, 6525.0, 80.7775
12.997558020, 18.870, 7199.0, 84.8469
13.041023780, 18.870, 9457.0, 97.2471
13.084489540, 18.870, 12536.0, 111.9643
13.127955300, 18.870, 13431.0, 115.8922
13.171421060, 18.870, 10312.0, 101.5480
13.214886820, 18.870, 4298.0, 65.5591
13.258352580, 18.870, 1866.0, 43.1972
13.301818340, 18.870, 1657.0, 40.7063
13.345284100, 18.870, 1475.0, 38.4057
13.388749860, 18.870, 1409.0, 37.5366
13.432215620, 18.870, 1411.0, 37.5633
13.475681380, 18.870, 1375.0, 37.0810
13.519147140, 18.870, 1291.0, 35.9305
13.562612900, 18.870, 1247.0, 35.3129
13.606078660, 18.870, 1225.0, 35.0000
13.649544420, 18.870, 1265.0, 35.5668
13.693010180, 18.870, 1164.0, 34.1174
13.736475940, 18.870, 1240.0, 35.2136
13.779941700, 18.870, 1187.0, 34.4529
13.823407460, 18.870, 1188.0, 34.4674
13.866873220, 18.870, 1246.0, 35.2987
13.910338980, 18.870, 1133.0, 33.6601
13.953804740, 18.870, 1188.0, 34.4674
13.997270500, 18.870, 1177.0, 34.3074
14.040736260, 18.870, 1179.0, 34.3366
14.084202020, 18.870, 1126.0, 33.5559
14.127667780, 18.870, 1118.0, 33.4365
14.171133540, 18.870, 1138.0, 33.7343
14.214599300, 18.870, 1128.0, 33.5857
14.258065060, 18.870, 1113.0, 33.3617
14.301530820, 18.870, 1137.0, 33.7194
14.344996580, 18.870, 1130.0, 33.6155
14.388462340, 18.870, 1165.0, 34.1321
14.431928100, 18.870, 1098.0, 33.1361
14.475393860, 18.870, 1112.0, 33.3467
14.518859620, 18.870, 1088.0, 32.9848
14.562325380, 18.870, 1089.0, 33.0000
14.605791140, 18.870, 1105.0, 33.2415
14.649256900, 18.870, 1103.0, 33.2114
14.692722660, 18.870, 1048.0, 32.3728
14.736188420, 18.870, 1079.0, 32.8481
14.779654180, 18.870, 1154.0, 33.9706
14.823119940, 18.870, 1020.0, 31.9374
14.866585700, 18.870, 1044.0, 32.3110
14.910051460, 18.870, 1079.0, 32.8481
14.953517220, 18.870, 1026.0, 32.0312
14.996982980, 18.870, 979.0, 31.2890
15.040448740, 18.870, 1044.0, 32.3110
15.083914500, 18.870, 1079.0, 32.8481
15.127380260, 18.870, 1063.0, 32.6037
15.170846020, 18.870, 1058.0, 32.5269
15.214311780, 18.870, 1041.0, 32.2645
15.257777540, 18.870, 1030.0, 32.0936
15.301243300, 18.870, 1017.0, 31.8904
15.344709060, 18.870, 949.0, 30.8058
15.388174820, 18.870, 1019.0, 31.9218
15.431640580, 18.870, 971.0, 31.1609
15.475106340, 18.870, 1010.0, 31.7805
15.518572100, 18.870, 1038.0, 32.2180
15.562037860, 18.870, 965.0, 31.0644
15.605503620, 18.870, 1066.0, 32.6497
15.648969380, 18.870, 1110.0, 33.3167
15.692435140, 18.870, 1037.0, 32.2025
15.735900900, 18.870, 1073.0, 32.7567
15.779366660, 18.870, 1161.0, 34.0735
15.822832420, 18.870, 1141.0, 33.7787
15.866298180, 18.870, 1287.0, 35.8748
15.909763940, 18.870, 1525.0, 39.0512
15.953229700, 18.870, 1614.0, 40.1746
15.996695460, 18.870, 1752.0, 41.8569
16.040161220, 18.870, 1929.0, 43.9204
16.083626980, 18.870, 2183.0, 46.7226
16.127092740, 18.870, 2509.0, 50.0899
16.170558500, 18.870, 2515.0, 50.1498
16.214024260, 18.870, 1976.0, 44.4522
16.257490020, 18.870, 1679.0, 40.9756
16.300955780, 18.870, 1484.0, 38.5227
16.344421540, 18.870, 1298.0, 36.0278
16.387887300, 18.870, 1110.0, 33.3167
16.431353060, 18.870, 984.0, 31.3688
16.474818820, 18.870, 909.0, 30.1496
16.518284580, 18.870, 954.0, 30.8869
16.561750340, 18.870, 926.0, 30.4302
16.605216100, 18.870, 956.0, 30.9192
16.648681860, 18.870, 962.0, 31.0161
16.692147620, 18.870, 890.0, 29.8329
16.735613380, 18.870, 938.0, 30.6268
16.779079140, 18.870, 928.0, 30.4631
16.822544900, 18.870, 940.0, 30.6594
16.866010660, 18.870, 899.0, 29.9833
16.909476420, 18.870, 890.0, 29.8329
16.952942180, 18.870, 943.0, 30.7083
16.996407940, 18.870, 922.0, 30.3645
17.039873700, 18.870, 909.0, 30.1496
17.083339460, 18.870, 898.0, 29.9666
17.126805220, 18.870, 913.0, 30.2159
17.170270980, 18.870, 849.0, 29.1376
17.213736740, 18.870, 938.0, 30.6268
17.257202500, 18.870, 885.0, 29.7489
17.300668260, 18.870, 817.0, 28.5832
17.344134020, 18.870, 863.0, 29.3769
17.387599780, 18.870, 922.0, 30.3645
17.431065540, 18.870, 931.0, 30.5123
17.474531300, 18.870, 848.0, 29.1204
17.517997060, 18.870, 842.0, 29.0172
17.561462820, 18.870, 866.0, 29.4279
17.604928580, 18.870, 904.0, 30.0666
17.648394340, 18.870, 881.0, 29.6816
17.691860100, 18.870, 929.0, 30.4795
17.735325860, 18.870, 943.0, 30.7083
17.778791620, 18.870, 946.0, 30.7571
17.822257380, 18.870, 937.0, 30.6105
17.865723140, 18.870, 963.0, 31.0322
17.909188900, 18.870, 961.0, 31.0000
17.952654660, 18.870, 1023.0, 31.9844
17.996120420, 18.870, 1181.0, 34.3657
18.039586180, 18.870, 1375.0, 37.0810
18.083051940, 18.870, 1521.0, 39.0000
18.126517700, 18.870, 1600.0, 40.0000
18.169983460, 18.870, 1537.0, 39.2046
18.213449220, 18.870, 1405.0, 37.4833
18.256914980, 18.870, 1302.0, 36.0832
18.300380740, 18.870, 1509.0, 38.8458
18.343846500, 18.870, 1724.0, 41.5211
18.387312260, 18.870, 1767.0, 42.0357
18.430778020, 18.870, 1729.0, 41.5812
18.474243780, 18.870, 1467.0, 38.3014
18.517709540, 18.870, 1134.0, 33.6749
18.561175300, 18.870, 988.0, 31.4325
18.604641060, 18.870, 966.0, 31.0805
18.648106820, 18.870, 956.0, 30.9192
18.691572580, 18.870, 985.0, 31.3847
18.735038340, 18.870, 962.0, 31.0161
18.778504100, 18.870, 918.0, 30.2985
18.821969860, 18.870, 941.0, 30.6757
18.865435620, 18.870, 901.0, 30.0167
18.908901380, 18.870, 935.0, 30.5778
18.952367140, 18.870, 1009.0, 31.7648
18.995832900, 18.870, 989.0, 31.4484
19.039298660, 18.870, 1032.0, 32.1248
19.082764420, 18.870, 1018.0, 31.9061
19.126230180, 18.870, 1159.0, 34.0441
19.169695940, 18.870, 1103.0, 33.2114
19.213161700, 18.870, 1235.0, 35.1426
19.256627460, 18.870, 1266.0, 35.5809
19.300093220, 18.870, 1366.0, 36.9594
19.343558980, 18.870, 1403.0, 37.4566
19.387024740, 18.870, 1524.0, 39.0384
19.430490500, 18.870, 1432.0, 37.8418
19.473956260, 18.870, 1350.0, 36.7423
19.517422020, 18.870, 1498.0, 38.7040
19.560887780, 18.870, 1323.0, 36.3731
19.604353540, 18.870, 1131.0, 33.6303
19.647819300, 18.870, 1029.0, 32.0780
19.691285060, 18.870, 950.0, 30.8221
19.734750820, 18.870, 918.0, 30.2985
19.778216580, 18.870, 1013.0, 31.8277
19.821682340, 18.870, 930.0, 30.4959
19.865148100, 18.870, 1002.0, 31.6544
19.908613860, 18.870, 996.0, 31.5595
19.952079620, 18.870, 1008.0, 31.7490
19.995545380, 18.870, 986.0, 31.4006
20.039011140, 18.870, 1014.0, 31.8434
20.082476900, 18.870, 1004.0, 31.6860
20.125942660, 18.870, 1029.0, 32.0780
20.169408420, 18.870, 939.0, 30.6431
20.212874180, 18.870, 1006.0, 31.7175
20.256339940, 18.870, 1061.0, 32.5730
20.299805700, 18.870, 999.0, 31.6070
20.343271460, 18.870, 1099.0, 33.1512
20.386737220, 18.870, 1092.0, 33.0454
20.430202980, 18.870, 1090.0, 33.0151
20.473668740, 18.870, 1234.0, 35.1283
20.517134500, 18.870, 1236.0, 35.1568
20.560600260, 18.870, 1240.0, 35.2136
20.604066020, 18.870, 1281.0, 35.7911
20.647531780, 18.870, 1232.0, 35.0999
20.690997540, 18.870, 1204.0, 34.6987
20.734463300, 18.870, 1197.0, 34.5977
20.777929060, 18.870, 1161.0, 34.0735
20.821394820, 18.870, 1236.0, 35.1568
20.864860580, 18.870, 1137.0, 33.7194
20.908326340, 18.870, 1117.0, 33.4215
20.951792100, 18.870, 1137.0, 33.7194
20.995257860, 18.870, 1109.0, 33.3017
21.038723620, 18.870, 1135.0, 33.6898
21.082189380, 18.870, 1071.0, 32.7261
21.125655140, 18.870, 1131.0, 33.6303
21.169120900, 18.870, 1114.0, 33.3766
21.212586660, 18.870, 1100.0, 33.1662
21.256052420, 18.870, 1135.0, 33.6898
21.299518180, 18.870, 1134.0, 33.6749
21.342983940, 18.870, 1094.0, 33.0757
21.386449700, 18.870, 1196.0, 34.5832
21.429915460, 18.870, 1150.0, 33.9116
21.473381220, 18.870, 1188.0, 34.4674
21.516846980, 18.870, 1203.0, 34.6843
21.560312740, 18.870, 1254.0, 35.4119
21.603778500, 18.870, 1190.0, 34.4964
21.647244260, 18.870, 1310.0, 36.1939
21.690710020, 18.870, 1229.0, 35.0571
21.734175780, 18.870, 1204.0, 34.6987
21.777641540, 18.870, 1415.0, 37.6165
21.821107300, 18.870, 1371.0, 37.0270
21.864573060, 18.870, 1328.0, 36.4417
21.908038820, 18.870, 1448.0, 38.0526
21.951504580, 18.870, 1521.0, 39.0000
21.994970340, 18.870, 1704.0, 41.2795
22.038436100, 18.870, 1764.0, 42.0000
22.081901860, 18.870, 1988.0, 44.5870
22.125367620, 18.870, 2212.0, 47.0319
22.168833380, 18.870, 2302.0, 47.9792
22.212299140, 18.870, 2579.0, 50.7839
22.255764900, 18.870, 3065.0, 55.3624
22.299230660, 18.870, 3468.0, 58.8897
22.342696420, 18.870, 3893.0, 62.3939
22.386162180, 18.870, 4296.0, 65.5439
22.429627940, 18.870, 5343.0, 73.0958
22.473093700, 18.870, 6702.0, 81.8657
22.516559460, 18.870, 9635.0, 98.1580
22.560025220, 18.870, 14762.0, 121.4990
22.603490980, 18.870, 21613.0, 147.0136
22.646956740, 18.870, 32091.0, 179.1396
22.690422500, 18.870, 43770.0, 209.2128
22.733888260, 18.870, 57008.0, 238.7635
22.777354020, 18.870, 78831.0, 280.7686
22.820819780, 18.870, 90876.0, 301.4565
22.864285540, 18.870, 88312.0, 297.1734
22.907751300, 18.870, 76698.0, 276.9440
22.951217060, 18.870, 73856.0, 271.7646
22.994682820, 18.870, 75649.0, 275.0436
23.038148580, 18.870, 68094.0, 260.9483
23.081614340, 18.870, 51466.0, 226.8612
23.125080100, 18.870, 37398.0, 193.3856
23.168545860, 18.870, 26366.0, 162.3761
23.212011620, 18.870, 17017.0, 130.4492
23.255477380, 18.870, 9580.0, 97.8775
23.298943140, 18.870, 6951.0, 83.3727
23.342408900, 18.870, 6225.0, 78.8987
23.385874660, 18.870, 6623.0, 81.3818
23.429340420, 18.870, 8056.0, 89.7552
23.472806180, 18.870, 9878.0, 99.3881
23.516271940, 18.870, 9994.0, 99.9700
23.559737700, 18.870, 8785.0, 93.7283
23.603203460, 18.870, 7795.0, 88.2893
23.646669220, 18.870, 7233.0, 85.0470
23.690134980, 18.870, 6571.0, 81.0617
23.733600740, 18.870, 6138.0, 78.3454
23.777066500, 18.870, 5785.0, 76.0592
23.820532260, 18.870, 5278.0, 72.6498
23.863998020, 18.870, 4452.0, 66.7233
23.907463780, 18.870, 3476.0, 58.9576
23.950929540, 18.870, 2881.0, 53.6749
23.994395300, 18.870, 2412.0, 49.1121
24.037861060, 18.870, 2303.0, 47.9896
24.081326820, 18.870, 2262.0, 47.5605
24.124792580, 18.870, 2142.0, 46.2817
24.168258340, 18.870, 2291.0, 47.8644
24.211724100, 18.870, 2192.0, 46.8188
24.255189860, 18.870, 2203.0, 46.9361
24.298655620, 18.870, 2377.0, 48.7545
24.342121380, 18.870, 2362.0, 48.6004
24.385587140, 18.870, 2578.0, 50.7740
24.429052900, 18.870, 2722.0, 52.1728
24.472518660, 18.870, 3426.0, 58.5320
24.515984420, 18.870, 4661.0, 68.2715
24.559450180, 18.870, 7027.0, 83.8272
24.602915940, 18.870, 10948.0, 104.6327
24.646381700, 18.870, 15048.0, 122.6703
24.689847460, 18.870, 20642.0, 143.6732
24.733313220, 18.870, 25023.0, 158.1866
24.776778980, 18.870, 26388.0, 162.4438
24.820244740, 18.870, 24079.0, 155.1741
24.863710500, 18.870, 19543.0, 139.7963
24.907176260, 18.870, 13979.0, 118.2328
24.950642020, 18.870, 11369.0, 106.6255
24.994107780, 18.870, 9100.0, 95.3939
25.037573540, 18.870, 7623.0, 87.3098
25.081039300, 18.870, 5358.0, 73.1984
25.124505060, 18.870, 3606.0, 60.0500
25.167970820, 18.870, 2547.0, 50.4678
25.211436580, 18.870, 2225.0, 47.1699
25.254902340, 18.870, 2089.0, 45.7056
25.298368100, 18.870, 1877.0, 43.3244
25.341833860, 18.870, 1851.0, 43.0232
25.385299620, 18.870, 1774.0, 42.1189
25.428765380, 18.870, 1759.0, 41.9404
25.472231140, 18.870, 1653.0, 40.6571
25.515696900, 18.870, 1723.0, 41.5090
25.559162660, 18.870, 1629.0, 40.3609
25.602628420, 18.870, 1704.0, 41.2795
25.646094180, 18.870, 1775.0, 42.1307
25.689559940, 18.870, 1708.0, 41.3280
25.733025700, 18.870, 1786.0, 42.2611
25.776491460, 18.870, 1697.0, 41.1947
25.819957220, 18.870, 1685.0, 41.0488
25.863422980, 18.870, 1669.0, 40.8534
25.906888740, 18.870, 1742.0, 41.7373
25.950354500, 18.870, 1880.0, 43.3590
25.993820260, 18.870, 1867.0, 43.2088
26.037286020, 18.870, 1878.0, 43.3359
26.080751780, 18.870, 1767.0, 42.0357
26.124217540, 18.870, 1696.0, 41.1825
26.167683300, 18.870, 1705.0, 41.2916
26.211149060, 18.870, 1683.0, 41.0244
26.254614820, 18.870, 1649.0, 40.6079
26.298080580, 18.870, 1681.0, 41.0000
26.341546340, 18.870, 1823.0, 42.6966
26.385012100, 18.870, 1897.0, 43.5546
26.428477860, 18.870, 2127.0, 46.1194
26.471943620, 18.870, 2247.0, 47.4025
26.515409380, 18.870, 2563.0, 50.6261
26.558875140, 18.870, 2725.0, 52.2015
26.602340900, 18.870, 2714.0, 52.0961
26.645806660, 18.870, 2535.0, 50.3488
26.689272420, 18.870, 2183.0, 46.7226
26.732738180, 18.870, 1700.0, 41.2311
26.776203940, 18.870, 1625.0, 40.3113
26.819669700, 18.870, 1517.0, 38.9487
26.863135460, 18.870, 1598.0, 39.9750
26.906601220, 18.870, 1648.0, 40.5956
26.950066980, 18.870, 1612.0, 40.1497
26.993532740, 18.870, 1642.0, 40.5216
27.036998500, 18.870, 1648.0, 40.5956
27.080464260, 18.870, 1827.0, 42.7434
27.123930020, 18.870, 1862.0, 43.1509
27.167395780, 18.870, 1962.0, 44.2945
27.210861540, 18.870, 2098.0, 45.8039
27.254327300, 18.870, 2320.0, 48.1664
27.297793060, 18.870, 2563.0, 50.6261
27.341258820, 18.870, 2513.0, 50.1298
27.384724580, 18.870, 2716.0, 52.1153
27.428190340, 18.870, 2943.0, 54.2494
27.471656100, 18.870, 3522.0, 59.3464
27.515121860, 18.870, 4531.0, 67.3127
27.558587620, 18.870, 7358.0, 85.7788
27.602053380, 18.870, 10203.0, 101.0099
27.645519140, 18.870, 14365.0, 119.8541
27.688984900, 18.870, 18693.0, 136.7223
27.732450660, 18.870, 23935.0, 154.7094
27.775916420, 18.870, 29945.0, 173.0462
27.819382180, 18.870, 28503.0, 168.8283
27.862847940, 18.870, 22404.0, 149.6797
27.906313700, 18.870, 16241.0, 127.4402
27.949779460, 18.870, 12748.0, 112.9070
27.993245220, 18.870, 9570.0, 97.8264
28.036710980, 18.870, 6914.0, 83.1505
28.080176740, 18.870, 4558.0, 67.5130
28.123642500, 18.870, 3098.0, 55.6597
28.167108260, 18.870, 2181.0, 46.7012
28.210574020, 18.870, 1926.0, 43.8862
28.254039780, 18.870, 1796.0, 42.3792
28.297505540, 18.870, 1589.0, 39.8623
28.340971300, 18.870, 1585.0, 39.8121
28.384437060, 18.870, 1463.0, 38.2492
28.427902820, 18.870, 1564.0, 39.5474
28.471368580, 18.870, 1425.0, 37.7492
28.514834340, 18.870, 1358.0, 36.8511
28.558300100, 18.870, 1375.0, 37.0810
28.601765860, 18.870, 1423.0, 37.7227
28.645231620, 18.870, 1424.0, 37.7359
28.688697380, 18.870, 1367.0, 36.9730
28.732163140, 18.870, 1339.0, 36.5923
28.775628900, 18.870, 1310.0, 36.1939
28.819094660, 18.870, 1300.0, 36.0555
28.862560420, 18.870, 1256.0, 35.4401
28.906026180, 18.870, 1285.0, 35.8469
28.949491940, 18.870, 1285.0, 35.8469
28.992957700, 18.870, 1248.0, 35.3270
29.036423460, 18.870, 1311.0, 36.2077
29.079889220, 18.870, 1270.0, 35.6371
29.123354980, 18.870, 1206.0, 34.7275
29.166820740, 18.870, 1271.0, 35.6511
29.210286500, 18.870, 1215.0, 34.8569
29.253752260, 18.870, 1160.0, 34.0588
29.297218020, 18.870, 1259.0, 35.4824
29.340683780, 18.870, 1189.0, 34.4819
29.384149540, 18.870, 1249.0, 35.3412
29.427615300, 18.870, 1196.0, 34.5832
29.471081060, 18.870, 1316.0, 36.2767
29.514546820, 18.870, 1252.0, 35.3836
29.558012580, 18.870, 1437.0, 37.9078
29.601478340, 18.870, 1538.0, 39.2173
29.644944100, 18.870, 1657.0, 40.7063
29.688409860, 18.870, 1834.0, 42.8252
29.731875620, 18.870, 1759.0, 41.9404
29.775341380, 18.870, 1584.0, 39.7995
29.818807140, 18.870, 1427.0, 37.7757
29.862272900, 18.870, 1248.0, 35.3270
29.905738660, 18.870, 1168.0, 34.1760
29.949204420, 18.870, 1094.0, 33.0757
29.992670180, 18.870, 1116.0, 33.4066
30.036135940, 18.870, 1078.0, 32.8329
30.079601700, 18.870, 1076.0, 32.8024
30.123067460, 18.870, 1061.0, 32.5730
30.166533220, 18.870, 1061.0, 32.5730
30.209998980, 18.870, 1060.0, 32.5576
30.253464740, 18.870, 1062.0, 32.5883
30.296930500, 18.870, 1016.0, 31.8748
30.340396260, 18.870, 1068.0, 32.6803
30.383862020, 18.870, 1010.0, 31.7805
30.427327780, 18.870, 1019.0, 31.9218
30.470793540, 18.870, 1067.0, 32.6650
30.514259300, 18.870, 1058.0, 32.5269
30.557725060, 18.870, 1007.0, 31.7333
30.601190820, 18.870, 1037.0, 32.2025
30.644656580, 18.870, 1018.0, 31.9061
30.688122340, 18.870, 1068.0, 32.6803
30.731588100, 18.870, 988.0, 31.4325
30.775053860, 18.870, 988.0, 31.4325
30.818519620, 18.870, 1048.0, 32.3728
30.861985380, 18.870, 975.0, 31.2250
30.905451140, 18.870, 965.0, 31.0644
30.948916900, 18.870, 960.0, 30.9839
30.992382660, 18.870, 995.0, 31.5436
31.035848420, 18.870, 1013.0, 31.8277
31.079314180, 18.870, 1012.0, 31.8119
31.122779940, 18.870, 1037.0, 32.2025
31.166245700, 18.870, 998.0, 31.5911
31.209711460, 18.870, 1076.0, 32.8024
31.253177220, 18.870, 1053.0, 32.4500
31.296642980, 18.870, 1124.0, 33.5261
31.340108740, 18.870, 1262.0, 35.5246
31.383574500, 18.870, 1550.0, 39.3700
31.427040260, 18.870, 1887.0, 43.4396
31.470506020, 18.870, 2223.0, 47.1487
31.513971780, 18.870, 2442.0, 49.4166
31.557437540, 18.870, 2765.0, 52.5833
31.600903300, 18.870, 2848.0, 53.3667
31.644369060, 18.870, 2460.0, 49.5984
31.687834820, 18.870, 2262.0, 47.5605
31.731300580, 18.870, 2156.0, 46.4327
31.774766340, 18.870, 2053.0, 45.3100
31.818232100, 18.870, 1970.0, 44.3847
31.861697860, 18.870, 1836.0, 42.8486
31.905163620, 18.870, 1684.0, 41.0366
31.948629380, 18.870, 1654.0, 40.6694
31.992095140, 18.870, 1733.0, 41.6293
32.035560900, 18.870, 1871.0, 43.2551
32.079026660, 18.870, 2272.0, 47.6655
32.122492420, 18.870, 2361.0, 48.5901
32.165958180, 18.870, 2742.0, 52.3641
32.209423940, 18.870, 3188.0, 56.4624
32.252889700, 18.870, 3717.0, 60.9672
32.296355460, 18.870, 3679.0, 60.6548
32.339821220, 18.870, 3245.0, 56.9649
32.383286980, 18.870, 2981.0, 54.5985
32.426752740, 18.870, 2400.0, 48.9898
32.470218500, 18.870, 2304.0, 48.0000
32.513684260, 18.870, 2144.0, 46.3033
32.557150020, 18.870, 2213.0, 47.0425
32.600615780, 18.870, 2174.0, 46.6262
32.644081540, 18.870, 1964.0, 44.3170
32.687547300, 18.870, 1915.0, 43.7607
32.731013060, 18.870, 1776.0, 42.1426
32.774478820, 18.870, 1489.0, 38.5876
32.817944580, 18.870, 1431.0, 37.8286
32.861410340, 18.870, 1228.0, 35.0428
32.904876100, 18.870, 1244.0, 35.2704
32.948341860, 18.870, 1324.0, 36.3868
32.991807620, 18.870, 1276.0, 35.7211
33.035273380, 18.870, 1257.0, 35.4542
33.078739140, 18.870, 1185.0, 34.4238
33.122204900, 18.870, 1137.0, 33.7194
33.165670660, 18.870, 1171.0, 34.2199
33.209136420, 18.870, 1229.0, 35.0571
33.252602180, 18.870, 1249.0, 35.3412
33.296067940, 18.870, 1198.0, 34.6121
33.339533700, 18.870, 1191.0, 34.5109
33.382999460, 18.870, 1100.0, 33.1662
33.426465220, 18.870, 1037.0, 32.2025
33.469930980, 18.870, 1071.0, 32.7261
33.513396740, 18.870, 978.0, 31.2730
33.556862500, 18.870, 996.0, 31.5595
33.600328260, 18.870, 913.0, 30.2159
33.643794020, 18.870, 1012.0, 31.8119
33.687259780, 18.870, 1127.0, 33.5708
33.730725540, 18.870, 1288.0, 35.8887
33.774191300, 18.870, 1251.0, 35.3695
33.817657060, 18.870, 1355.0, 36.8103
33.861122820, 18.870, 1307.0, 36.1525
33.904588580, 18.870, 1365.0, 36.9459
33.948054340, 18.870, 1254.0, 35.4119
33.991520100, 18.870, 1242.0, 35.2420
34.034985860, 18.870, 1208.0, 34.7563
34.078451620, 18.870, 1185.0, 34.4238
34.121917380, 18.870, 1071.0, 32.7261
34.165383140, 18.870, 1054.0, 32.4654
34.208848900, 18.870, 1002.0, 31.6544
34.252314660, 18.870, 866.0, 29.4279
34.295780420, 18.870, 863.0, 29.3769
34.339246180, 18.870, 860.0, 29.3258
34.382711940, 18.870, 798.0, 28.2489
34.426177700, 18.870, 824.0, 28.7054
34.469643460, 18.870, 841.0, 29.0000
34.513109220, 18.870, 893.0, 29.8831
34.556574980, 18.870, 863.0, 29.3769
34.600040740, 18.870, 928.0, 30.4631
34.643506500, 18.870, 1039.0, 32.2335
34.686972260, 18.870, 913.0, 30.2159
34.730438020, 18.870, 923.0, 30.3809
34.773903780, 18.870, 923.0, 30.3809
34.817369540, 18.870, 877.0, 29.6142
34.860835300, 18.870, 867.0, 29.4449
34.904301060, 18.870, 852.0, 29.1890
34.947766820, 18.870, 826.0, 28.7402
34.991232580, 18.870, 853.0, 29.2062
35.034698340, 18.870, 810.0, 28.4605
35.078164100, 18.870, 833.0, 28.8617
35.121629860, 18.870, 844.0, 29.0517
35.165095620, 18.870, 886.0, 29.7658
35.208561380, 18.870, 857.0, 29.2746
35.252027140, 18.870, 863.0, 29.3769
35.295492900, 18.870, 884.0, 29.7321
35.338958660, 18.870, 852.0, 29.1890
35.382424420, 18.870, 960.0, 30.9839
35.425890180, 18.870, 1126.0, 33.5559
35.469355940, 18.870, 1307.0, 36.1525
35.512821700, 18.870, 1541.0, 39.2556
35.556287460, 18.870, 1791.0, 42.3202
35.599753220, 18.870, 1982.0, 44.5197
35.643218980, 18.870, 1970.0, 44.3847
35.686684740, 18.870, 1914.0, 43.7493
35.730150500, 18.870, 2056.0, 45.3431
35.773616260, 18.870, 2618.0, 51.1664
35.817082020, 18.870, 3146.0, 56.0892
35.860547780, 18.870, 3587.0, 59.8916
35.904013540, 18.870, 4423.0, 66.5056
35.947479300, 18.870, 5089.0, 71.3372
35.990945060, 18.870, 4948.0, 70.3420
36.034410820, 18.870, 4258.0, 65.2534
36.077876580, 18.870, 3237.0, 56.8946
36.121342340, 18.870, 2386.0, 48.8467
36.164808100, 18.870, 1648.0, 40.5956
36.208273860, 18.870, 1380.0, 37.1484
36.251739620, 18.870, 1236.0, 35.1568
36.295205380, 18.870, 1070.0, 32.7109
36.338671140, 18.870, 1031.0, 32.1092
36.382136900, 18.870, 959.0, 30.9677
36.425602660, 18.870, 956.0, 30.9192
36.469068420, 18.870, 922.0, 30.3645
36.512534180, 18.870, 937.0, 30.6105
36.555999940, 18.870, 939.0, 30.6431
36.599465700, 18.870, 954.0, 30.8869
36.642931460, 18.870, 994.0, 31.5278
36.686397220, 18.870, 1027.0, 32.0468
36.729862980, 18.870, 1022.0, 31.9687
36.773328740, 18.870, 1089.0, 33.0000
36.816794500, 18.870, 1214.0, 34.8425
36.860260260, 18.870, 1313.0, 36.2353
36.903726020, 18.870, 1474.0, 38.3927
36.947191780, 18.870, 1357.0, 36.8375
36.990657540, 18.870, 1237.0, 35.1710
37.034123300, 18.870, 1162.0, 34.0881
37.077589060, 18.870, 1113.0, 33.3617
37.121054820, 18.870, 1182.0, 34.3802
37.164520580, 18.870, 1117.0, 33.4215
37.207986340, 18.870, 1015.0, 31.8591
37.251452100, 18.870, 1057.0, 32.5115
37.294917860, 18.870, 902.0, 30.0333
37.338383620, 18.870, 864.0, 29.3939
37.381849380, 18.870, 838.0, 28.9482
37.425315140, 18.870, 805.0, 28.3725
37.468780900, 18.870, 872.0, 29.5296
37.512246660, 18.870, 826.0, 28.7402
37.555712420, 18.870, 869.0, 29.4788
37.599178180, 18.870, 880.0, 29.6648
37.642643940, 18.870, 886.0, 29.7658
37.686109700, 18.870, 833.0, 28.8617
37.729575460, 18.870, 813.0, 28.5132
37.773041220, 18.870, 873.0, 29.5466
37.816506980, 18.870, 891.0, 29.8496
37.859972740, 18.870, 832.0, 28.8444
37.903438500, 18.870, 860.0, 29.3258
37.946904260, 18.870, 832.0, 28.8444
37.990370020, 18.870, 793.0, 28.1603
38.033835780, 18.870, 816.0, 28.5657
38.077301540, 18.870, 790.0, 28.1069
38.120767300, 18.870, 842.0, 29.0172
38.164233060, 18.870, 819.0, 28.6182
38.207698820, 18.870, 819.0, 28.6182
38.251164580, 18.870, 838.0, 28.9482
38.294630340, 18.870, 877.0, 29.6142
38.338096100, 18.870, 798.0, 28.2489
38.381561860, 18.870, 835.0, 28.8964
38.425027620, 18.870, 841.0, 29.0000
38.468493380, 18.870, 787.0, 28.0535
38.511959140, 18.870, 854.0, 29.2233
38.555424900, 18.870, 856.0, 29.2575
38.598890660, 18.870, 860.0, 29.3258
38.642356420, 18.870, 853.0, 29.2062
38.685822180, 18.870, 905.0, 30.0832
38.729287940, 18.870, 894.0, 29.8998
38.772753700, 18.870, 1004.0, 31.6860
38.816219460, 18.870, 1018.0, 31.9061
38.859685220, 18.870, 1014.0, 31.8434
38.903150980, 18.870, 1019.0, 31.9218
38.946616740, 18.870, 1044.0, 32.3110
38.990082500, 18.870, 1110.0, 33.3167
39.033548260, 18.870, 1196.0, 34.5832
39.077014020, 18.870, 1192.0, 34.5254
39.120479780, 18.870, 1374.0, 37.0675
39.163945540, 18.870, 1329.0, 36.4555
39.207411300, 18.870, 1403.0, 37.4566
39.250877060, 18.870, 1455.0, 38.1445
39.294342820, 18.870, 1648.0, 40.5956
39.337808580, 18.870, 2031.0, 45.0666
39.381274340, 18.870, 2158.0, 46.4543
39.424740100, 18.870, 2043.0, 45.1996
39.468205860, 18.870, 1898.0, 43.5660
39.511671620, 18.870, 1650.0, 40.6202
39.555137380, 18.870, 1484.0, 38.5227
39.598603140, 18.870, 1276.0, 35.7211
39.642068900, 18.870, 1407.0, 37.5100
39.685534660, 18.870, 1600.0, 40.0000
39.729000420, 18.870, 1924.0, 43.8634
39.772466180, 18.870, 2135.0, 46.2061
39.815931940, 18.870, 2197.0, 46.8722
39.859397700, 18.870, 2309.0, 48.0521
39.902863460, 18.870, 2613.0, 51.1175
39.946329220, 18.870, 2827.0, 53.1695
39.989794980, 18.870, 3606.0, 60.0500
40.033260740, 18.870, 3890.0, 62.3699
40.076726500, 18.870, 3448.0, 58.7197
40.120192260, 18.870, 2711.0, 52.0673
40.163658020, 18.870, 2137.0, 46.2277
40.207123780, 18.870, 1562.0, 39.5221
40.250589540, 18.870, 1124.0, 33.5261
40.294055300, 18.870, 1126.0, 33.5559
40.337521060, 18.870, 1064.0, 32.6190
40.380986820, 18.870, 1034.0, 32.1559
40.424452580, 18.870, 970.0, 31.1448
40.467918340, 18.870, 907.0, 30.1164
40.511384100, 18.870, 873.0, 29.5466
40.554849860, 18.870, 893.0, 29.8831
40.598315620, 18.870, 847.0, 29.1033
40.641781380, 18.870, 938.0, 30.6268
40.685247140, 18.870, 1040.0, 32.2490
40.728712900, 18.870, 1108.0, 33.2866
40.772178660, 18.870, 1104.0, 33.2265
40.815644420, 18.870, 1184.0, 34.4093
40.859110180, 18.870, 1287.0, 35.8748
40.902575940, 18.870, 1300.0, 36.0555
40.946041700, 18.870, 1231.0, 35.0856
40.989507460, 18.870, 1190.0, 34.4964
41.032973220, 18.870, 1240.0, 35.2136
41.076438980, 18.870, 1313.0, 36.2353
41.119904740, 18.870, 1359.0, 36.8646
41.163370500, 18.870, 1343.0, 36.6470
41.206836260, 18.870, 1367.0, 36.9730
41.250302020, 18.870, 1425.0, 37.7492
41.293767780, 18.870, 1490.0, 38.6005
41.337233540, 18.870, 1572.0, 39.6485
41.380699300, 18.870, 1454.0, 38.1314
41.424165060, 18.870, 1414.0, 37.6032
41.467630820, 18.870, 1298.0, 36.0278
41.511096580, 18.870, 1253.0, 35.3977
41.554562340, 18.870, 1122.0, 33.4963
41.598028100, 18.870, 922.0, 30.3645
41.641493860, 18.870, 923.0, 30.3809
41.684959620, 18.870, 878.0, 29.6311
41.728425380, 18.870, 839.0, 28.9655
41.771891140, 18.870, 789.0, 28.0891
41.815356900, 18.870, 813.0, 28.5132
41.858822660, 18.870, 765.0, 27.6586
41.902288420, 18.870, 723.0, 26.8887
41.945754180, 18.870, 763.0, 27.6225
41.989219940, 18.870, 772.0, 27.7849
42.032685700, 18.870, 741.0, 27.2213
42.076151460, 18.870, 819.0, 28.6182
42.119617220, 18.870, 777.0, 27.8747
42.163082980, 18.870, 720.0, 26.8328
42.206548740, 18.870, 733.0, 27.0740
42.250014500, 18.870, 731.0, 27.0370
42.293480260, 18.870, 757.0, 27.5136
42.336946020, 18.870, 728.0, 26.9815
42.380411780, 18.870, 775.0, 27.8388
42.423877540, 18.870, 764.0, 27.6405
42.467343300, 18.870, 784.0, 28.0000
42.510809060, 18.870, 845.0, 29.0689
42.554274820, 18.870, 988.0, 31.4325
42.597740580, 18.870, 989.0, 31.4484
42.641206340, 18.870, 978.0, 31.2730
42.684672100, 18.870, 1033.0, 32.1403
42.728137860, 18.870, 926.0, 30.4302
42.771603620, 18.870, 848.0, 29.1204
42.815069380, 18.870, 865.0, 29.4109
42.858535140, 18.870, 867.0, 29.4449
42.902000900, 18.870, 866.0, 29.4279
42.945466660, 18.870, 875.0, 29.5804
42.988932420, 18.870, 924.0, 30.3974
43.032398180, 18.870, 1047.0, 32.3574
43.075863940, 18.870, 1168.0, 34.1760
43.119329700, 18.870, 1194.0, 34.5543
43.162795460, 18.870, 1273.0, 35.6791
43.206261220, 18.870, 1101.0, 33.1813
43.249726980, 18.870, 1140.0, 33.7639
43.293192740, 18.870, 946.0, 30.7571
43.336658500, 18.870, 893.0, 29.8831
43.380124260, 18.870, 816.0, 28.5657
43.423590020, 18.870, 808.0, 28.4253
43.467055780, 18.870, 758.0, 27.5318
43.510521540, 18.870, 744.0, 27.2764
43.553987300, 18.870, 721.0, 26.8514
43.597453060, 18.870, 753.0, 27.4408
43.640918820, 18.870, 721.0, 26.8514
43.684384580, 18.870, 723.0, 26.8887
43.727850340, 18.870, 655.0, 25.5930
43.771316100, 18.870, 724.0, 26.9072
43.814781860, 18.870, 698.0, 26.4197
43.858247620, 18.870, 757.0, 27.5136
43.901713380, 18.870, 726.0, 26.9444
43.945179140, 18.870, 716.0, 26.7582
43.988644900, 18.870, 670.0, 25.8844
44.032110660, 18.870, 744.0, 27.2764
44.075576420, 18.870, 691.0, 26.2869
44.119042180, 18.870, 717.0, 26.7769
44.162507940, 18.870, 759.0, 27.5500
44.205973700, 18.870, 721.0, 26.8514
44.249439460, 18.870, 741.0, 27.2213
44.292905220, 18.870, 719.0, 26.8142
44.336370980, 18.870, 653.0, 25.5539
44.379836740, 18.870, 668.0, 25.8457
44.423302500, 18.870, 722.0, 26.8701
44.466768260, 18.870, 697.0, 26.4008
44.510234020, 18.870, 697.0, 26.4008
44.553699780, 18.870, 767.0, 27.6948
44.597165540, 18.870, 807.0, 28.4077
44.640631300, 18.870, 778.0, 27.8927
44.684097060, 18.870, 808.0, 28.4253
44.727562820, 18.870, 787.0, 28.0535
44.771028580, 18.870, 813.0, 28.5132
44.814494340, 18.870, 836.0, 28.9137
44.857960100, 18.870, 835.0, 28.8964
44.901425860, 18.870, 854.0, 29.2233
44.944891620, 18.870, 873.0, 29.5466
44.988357380, 18.870, 940.0, 30.6594
45.031823140, 18.870, 1038.0, 32.2180
45.075288900, 18.870, 1031.0, 32.1092
45.118754660, 18.870, 1147.0, 33.8674
45.162220420, 18.870, 1348.0, 36.7151
45.205686180, 18.870, 1178.0, 34.3220
45.249151940, 18.870, 1216.0, 34.8712
45.292617700, 18.870, 1322.0, 36.3593
45.336083460, 18.870, 1267.0, 35.5949
45.379549220, 18.870, 1146.0, 33.8526
45.423014980, 18.870, 1144.0, 33.8231
45.466480740, 18.870, 1206.0, 34.7275
45.509946500, 18.870, 1395.0, 37.3497
45.553412260, 18.870, 1772.0, 42.0951
45.596878020, 18.870, 1776.0, 42.1426
45.640343780, 18.870, 1705.0, 41.2916
45.683809540, 18.870, 1690.0, 41.1096
45.727275300, 18.870, 1528.0, 39.0896
45.770741060, 18.870, 1381.0, 37.1618
45.814206820, 18.870, 1419.0, 37.6696
45.857672580, 18.870, 1983.0, 44.5309
45.901138340, 18.870, 2419.0, 49.1833
45.944604100, 18.870, 2745.0, 52.3927
45.988069860, 18.870, 2816.0, 53.0660
46.031535620, 18.870, 2473.0, 49.7293
46.075001380, 18.870, 2490.0, 49.8999
46.118467140, 18.870, 2178.0, 46.6690
46.161932900, 18.870, 1650.0, 40.6202
46.205398660, 18.870, 1560.0, 39.4968
46.248864420, 18.870, 1610.0, 40.1248
46.292330180, 18.870, 1474.0, 38.3927
46.335795940, 18.870, 1224.0, 34.9857
46.379261700, 18.870, 1111.0, 33.3317
46.422727460, 18.870, 991.0, 31.4802
46.466193220, 18.870, 936.0, 30.5941
46.509658980, 18.870, 898.0, 29.9666
46.553124740, 18.870, 826.0, 28.7402
46.596590500, 18.870, 855.0, 29.2404
46.640056260, 18.870, 951.0, 30.8383
46.683522020, 18.870, 1180.0, 34.3511
46.726987780, 18.870, 1555.0, 39.4335
46.770453540, 18.870, 1731.0, 41.6053
46.813919300, 18.870, 1723.0, 41.5090
46.857385060, 18.870, 1692.0, 41.1339
46.900850820, 18.870, 1788.0, 42.2847
46.944316580, 18.870, 1537.0, 39.2046
46.987782340, 18.870, 1373.0, 37.0540
47.031248100, 18.870, 1375.0, 37.0810
47.074713860, 18.870, 1162.0, 34.0881
47.118179620, 18.870, 1054.0, 32.4654
47.161645380, 18.870, 936.0, 30.5941
47.205111140, 18.870, 809.0, 28.4429
47.248576900, 18.870, 868.0, 29.4618
47.292042660, 18.870, 759.0, 27.5500
47.335508420, 18.870, 760.0, 27.5681
47.378974180, 18.870, 795.0, 28.1957
47.422439940, 18.870, 866.0, 29.4279
47.465905700, 18.870, 949.0, 30.8058
47.509371460, 18.870, 936.0, 30.5941
47.552837220, 18.870, 887.0, 29.7825
47.596302980, 18.870, 930.0, 30.4959
47.639768740, 18.870, 882.0, 29.6985
47.683234500, 18.870, 887.0, 29.7825
47.726700260, 18.870, 867.0, 29.4449
47.770166020, 18.870, 912.0, 30.1993
47.813631780, 18.870, 962.0, 31.0161
47.857097540, 18.870, 900.0, 30.0000
47.900563300, 18.870, 931.0, 30.5123
47.944029060, 18.870, 899.0, 29.9833
47.987494820, 18.870, 924.0, 30.3974
48.030960580, 18.870, 988.0, 31.4325
48.074426340, 18.870, 910.0, 30.1662
48.117892100, 18.870, 865.0, 29.4109
48.161357860, 18.870, 948.0, 30.7896
48.204823620, 18.870, 864.0, 29.3939
48.248289380, 18.870, 915.0, 30.2490
48.291755140, 18.870, 1000.0, 31.6228
48.335220900, 18.870, 1063.0, 32.6037
48.378686660, 18.870, 1008.0, 31.7490
48.422152420, 18.870, 928.0, 30.4631
48.465618180, 18.870, 910.0, 30.1662
48.509083940, 18.870, 927.0, 30.4467
48.552549700, 18.870, 857.0, 29.2746
48.596015460, 18.870, 802.0, 28.3196
48.639481220, 18.870, 780.0, 27.9285
48.682946980, 18.870, 767.0, 27.6948
48.726412740, 18.870, 727.0, 26.9629
48.769878500, 18.870, 712.0, 26.6833
48.813344260, 18.870, 722.0, 26.8701
48.856810020, 18.870, 700.0, 26.4575
48.900275780, 18.870, 729.0, 27.0000
48.943741540, 18.870, 676.0, 26.0000
48.987207300, 18.870, 680.0, 26.0768
49.030673060, 18.870, 718.0, 26.7955
49.074138820, 18.870, 761.0, 27.5862
49.117604580, 18.870, 799.0, 28.2666
49.161070340, 18.870, 739.0, 27.1846
49.204536100, 18.870, 802.0, 28.3196
49.248001860, 18.870, 714.0, 26.7208
49.291467620, 18.870, 699.0, 26.4386
49.334933380, 18.870, 707.0, 26.5895
49.378399140, 18.870, 662.0, 25.7294
49.421864900, 18.870, 697.0, 26.4008
49.465330660, 18.870, 671.0, 25.9037
49.508796420, 18.870, 621.0, 24.9199
49.552262180, 18.870, 626.0, 25.0200
49.595727940, 18.870, 666.0, 25.8070
49.639193700, 18.870, 658.0, 25.6515
49.682659460, 18.870, 669.0, 25.8650
49.726125220, 18.870, 609.0, 24.6779
49.769590980, 18.870, 667.0, 25.8263
49.813056740, 18.870, 638.0, 25.2587
49.856522500, 18.870, 667.0, 25.8263
49.899988260, 18.870, 644.0, 25.3772
49.943454020, 18.870, 645.0, 25.3969
49.986919780, 18.870, 609.0, 24.6779
50.030385540, 18.870, 648.0, 25.4558
50.073851300, 18.870, 670.0, 25.8844
50.117317060, 18.870, 664.0, 25.7682
50.160782820, 18.870, 635.0, 25.1992
50.204248580, 18.870, 669.0, 25.8650
50.247714340, 18.870, 661.0, 25.7099
50.291180100, 18.870, 646.0, 25.4165
50.334645860, 18.870, 627.0, 25.0400
50.378111620, 18.870, 621.0, 24.9199
50.421577380, 18.870, 618.0, 24.8596
50.465043140, 18.870, 611.0, 24.7184
50.508508900, 18.870, 564.0, 23.7487
50.551974660, 18.870, 626.0, 25.0200
50.595440420, 18.870, 607.0, 24.6374
50.638906180, 18.870, 667.0, 25.8263
50.682371940, 18.870, 649.0, 25.4755
50.725837700, 18.870, 662.0, 25.7294
50.769303460, 18.870, 705.0, 26.5518
50.812769220, 18.870, 746.0, 27.3130
50.856234980, 18.870, 751.0, 27.4044
50.899700740, 18.870, 751.0, 27.4044
50.943166500, 18.870, 770.0, 27.7489
50.986632260, 18.870, 678.0, 26.0384
51.030098020, 18.870, 670.0, 25.8844
51.073563780, 18.870, 688.0, 26.2298
51.117029540, 18.870, 669.0, 25.8650
51.160495300, 18.870, 656.0, 25.6125
51.203961060, 18.870, 696.0, 26.3818
51.247426820, 18.870, 704.0, 26.5330
51.290892580, 18.870, 684.0, 26.1534
51.334358340, 18.870, 671.0, 25.9037
51.377824100, 18.870, 676.0, 26.0000
51.421289860, 18.870, 670.0, 25.8844
51.464755620, 18.870, 722.0, 26.8701
51.508221380, 18.870, 757.0, 27.5136
51.551687140, 18.870, 755.0, 27.4773
51.595152900, 18.870, 832.0, 28.8444
51.638618660, 18.870, 784.0, 28.0000
51.682084420, 18.870, 754.0, 27.4591
51.725550180, 18.870, 753.0, 27.4408
51.769015940, 18.870, 752.0, 27.4226
51.812481700, 18.870, 760.0, 27.5681
51.855947460, 18.870, 748.0, 27.3496
51.899413220, 18.870, 667.0, 25.8263
51.942878980, 18.870, 671.0, 25.9037
51.986344740, 18.870, 639.0, 25.2784
52.029810500, 18.870, 610.0, 24.6982
52.073276260, 18.870, 595.0, 24.3926
52.116742020, 18.870, 588.0, 24.2487
52.160207780, 18.870, 585.0, 24.1868
52.203673540, 18.870, 598.0, 24.4540
52.247139300, 18.870, 632.0, 25.1396
52.290605060, 18.870, 599.0, 24.4745
52.334070820, 18.870, 567.0, 23.8118
52.377536580, 18.870, 593.0, 24.3516
52.421002340, 18.870, 590.0, 24.2899
52.464468100, 18.870, 603.0, 24.5561
52.507933860, 18.870, 583.0, 24.1454
52.551399620, 18.870, 608.0, 24.6577
52.594865380, 18.870, 603.0, 24.5561
52.638331140, 18.870, 616.0, 24.8193
52.681796900, 18.870, 637.0, 25.2389
52.725262660, 18.870, 656.0, 25.6125
52.768728420, 18.870, 652.0, 25.5343
52.812194180, 18.870, 615.0, 24.7992
52.855659940, 18.870, 616.0, 24.8193
52.899125700, 18.870, 607.0, 24.6374
52.942591460, 18.870, 631.0, 25.1197
52.986057220, 18.870, 613.0, 24.7588
53.029522980, 18.870, 646.0, 25.4165
53.072988740, 18.870, 619.0, 24.8797
53.116454500, 18.870, 627.0, 25.0400
53.159920260, 18.870, 677.0, 26.0192
53.203386020, 18.870, 646.0, 25.4165
53.246851780, 18.870, 651.0, 25.5147
53.290317540, 18.870, 660.0, 25.6905
53.333783300, 18.870, 603.0, 24.5561
53.377249060, 18.870, 664.0, 25.7682
53.420714820, 18.870, 705.0, 26.5518
53.464180580, 18.870, 740.0, 27.2029
53.507646340, 18.870, 704.0, 26.5330
53.551112100, 18.870, 765.0, 27.6586
53.594577860, 18.870, 859.0, 29.3087
53.638043620, 18.870, 919.0, 30.3150
53.681509380, 18.870, 896.0, 29.9333
53.724975140, 18.870, 1032.0, 32.1248
53.768440900, 18.870, 1130.0, 33.6155
53.811906660, 18.870, 929.0, 30.4795
53.855372420, 18.870, 1005.0, 31.7017
53.898838180, 18.870, 1077.0, 32.8177
53.942303940, 18.870, 1098.0, 33.1361
53.985769700, 18.870, 1139.0, 33.7491
54.029235460, 18.870, 1016.0, 31.8748
54.072701220, 18.870, 984.0, 31.3688
54.116166980, 18.870, 896.0, 29.9333
54.159632740, 18.870, 757.0, 27.5136
54.203098500, 18.870, 752.0, 27.4226
54.246564260, 18.870, 670.0, 25.8844
54.290030020, 18.870, 622.0, 24.9399
54.333495780, 18.870, 677.0, 26.0192
54.376961540, 18.870, 645.0, 25.3969
54.420427300, 18.870, 582.0, 24.1247
54.463893060, 18.870, 614.0, 24.7790
54.507358820, 18.870, 575.0, 23.9792
54.550824580, 18.870, 602.0, 24.5357
54.594290340, 18.870, 639.0, 25.2784
54.637756100, 18.870, 626.0, 25.0200
54.681221860, 18.870, 673.0, 25.9422
54.724687620, 18.870, 586.0, 24.2074
54.768153380, 18.870, 608.0, 24.6577
54.811619140, 18.870, 617.0, 24.8395
54.855084900, 18.870, 569.0, 23.8537
54.898550660, 18.870, 586.0, 24.2074
54.942016420, 18.870, 590.0, 24.2899
54.985482180, 18.870, 590.0, 24.2899
55.028947940, 18.870, 547.0, 23.3880
55.072413700, 18.870, 551.0, 23.4734
55.115879460, 18.870, 541.0, 23.2594
55.159345220, 18.870, 562.0, 23.7065
55.202810980, 18.870, 515.0, 22.6936
55.246276740, 18.870, 572.0, 23.9165
55.289742500, 18.870, 569.0, 23.8537
55.333208260, 18.870, 579.0, 24.0624
55.376674020, 18.870, 584.0, 24.1661
55.420139780, 18.870, 584.0, 24.1661
55.463605540, 18.870, 591.0, 24.3105
55.507071300, 18.870, 565.0, 23.7697
55.550537060, 18.870, 582.0, 24.1247
55.594002820, 18.870, 552.0, 23.4947
55.637468580, 18.870, 548.0, 23.4094
55.680934340, 18.870, 574.0, 23.9583
55.724400100, 18.870, 531.0, 23.0434
55.767865860, 18.870, 588.0, 24.2487
55.811331620, 18.870, 570.0, 23.8747
55.854797380, 18.870, 590.0, 24.2899
55.898263140, 18.870, 620.0, 24.8998
55.941728900, 18.870, 587.0, 24.2281
55.985194660, 18.870, 618.0, 24.8596
56.028660420, 18.870, 605.0, 24.5967
56.072126180, 18.870, 676.0, 26.0000
56.115591940, 18.870, 654.0, 25.5734
56.159057700, 18.870, 603.0, 24.5561
56.202523460, 18.870, 703.0, 26.5141
56.245989220, 18.870, 602.0, 24.5357
56.289454980, 18.870, 653.0, 25.5539
56.332920740, 18.870, 594.0, 24.3721
56.376386500, 18.870, 617.0, 24.8395
56.419852260, 18.870, 617.0, 24.8395
56.463318020, 18.870, 620.0, 24.8998
56.506783780, 18.870, 560.0, 23.6643
56.550249540, 18.870, 599.0, 24.4745
56.593715300, 18.870, 648.0, 25.4558
56.637181060, 18.870, 658.0, 25.6515
56.680646820, 18.870, 625.0, 25.0000
56.724112580, 18.870, 691.0, 26.2869
56.767578340, 18.870, 694.0, 26.3439
56.811044100, 18.870, 667.0, 25.8263
56.854509860, 18.870, 799.0, 28.2666
56.897975620, 18.870, 947.0, 30.7734
56.941441380, 18.870, 958.0, 30.9516
56.984907140, 18.870, 983.0, 31.3528
57.028372900, 18.870, 1004.0, 31.6860
57.071838660, 18.870, 962.0, 31.0161
57.115304420, 18.870, 930.0, 30.4959
57.158770180, 18.870, 868.0, 29.4618
57.202235940, 18.870, 788.0, 28.0713
57.245701700, 18.870, 869.0, 29.4788
57.289167460, 18.870, 894.0, 29.8998
57.332633220, 18.870, 953.0, 30.8707
57.376098980, 18.870, 852.0, 29.1890
57.419564740, 18.870, 784.0, 28.0000
57.463030500, 18.870, 808.0, 28.4253
57.506496260, 18.870, 773.0, 27.8029
57.549962020, 18.870, 709.0, 26.6271
57.593427780, 18.870, 653.0, 25.5539
57.636893540, 18.870, 634.0, 25.1794
57.680359300, 18.870, 621.0, 24.9199
57.723825060, 18.870, 536.0, 23.1517
57.767290820, 18.870, 597.0, 24.4336
57.810756580, 18.870, 634.0, 25.1794
57.854222340, 18.870, 585.0, 24.1868
57.897688100, 18.870, 593.0, 24.3516
57.941153860, 18.870, 592.0, 24.3311
57.984619620, 18.870, 565.0, 23.7697
58.028085380, 18.870, 580.0, 24.0832
58.071551140, 18.870, 604.0, 24.5764
58.115016900, 18.870, 639.0, 25.2784
58.158482660, 18.870, 676.0, 26.0000
58.201948420, 18.870, 674.0, 25.9615
58.245414180, 18.870, 650.0, 25.4951
58.288879940, 18.870, 628.0, 25.0599
58.332345700, 18.870, 657.0, 25.6320
58.375811460, 18.870, 611.0, 24.7184
58.419277220, 18.870, 668.0, 25.8457
58.462742980, 18.870, 619.0, 24.8797
58.506208740, 18.870, 617.0, 24.8395
58.549674500, 18.870, 565.0, 23.7697
58.593140260, 18.870, 586.0, 24.2074
58.636606020, 18.870, 592.0, 24.3311
58.680071780, 18.870, 566.0, 23.7908
58.723537540, 18.870, 561.0, 23.6854
58.767003300, 18.870, 640.0, 25.2982
58.810469060, 18.870, 610.0, 24.6982
58.853934820, 18.870, 592.0, 24.3311
58.897400580, 18.870, 676.0, 26.0000
58.940866340, 18.870, 643.0, 25.3574
58.984332100, 18.870, 567.0, 23.8118
59.027797860, 18.870, 589.0, 24.2693
59.071263620, 18.870, 591.0, 24.3105
59.114729380, 18.870, 595.0, 24.3926
59.158195140, 18.870, 568.0, 23.8328
59.201660900, 18.870, 592.0, 24.3311
59.245126660, 18.870, 581.0, 24.1039
59.288592420, 18.870, 555.0, 23.5584
59.332058180, 18.870, 640.0, 25.2982
59.375523940, 18.870, 582.0, 24.1247
59.418989700, 18.870, 758.0, 27.5318
59.462455460, 18.870, 946.0, 30.7571
59.505921220, 18.870, 1152.0, 33.9411
59.549386980, 18.870, 1176.0, 34.2929
59.592852740, 18.870, 1136.0, 33.7046
59.636318500, 18.870, 1205.0, 34.7131
59.679784260, 18.870, 1170.0, 34.2053
59.723250020, 18.870, 1083.0, 32.9090
59.766715780, 18.870, 837.0, 28.9310
59.810181540, 18.870, 764.0, 27.6405
59.853647300, 18.870, 759.0, 27.5500
59.897113060, 18.870, 647.0, 25.4362
59.940578820, 18.870, 594.0, 24.3721
59.984044580, 18.870, 565.0, 23.7697
59.994911020, 18.870, 535.0, 23.1301