File: XRD/2025_06_03_CBD_SA_MC15_3_60_8min.csv
[Measurement conditions]
Sample identification,2025_06_03_CBD_SA_MC15_3_60_8min
Comment - 1,"CBD - Sorbic Acid, MC 15 min, heptane, 5/14/25, JL"
Anode material,Cu
K-Alpha1 wavelength,1.5405980
K-Alpha2 wavelength,1.5444260
Ratio K-Alpha2/K-Alpha1,0.500
Divergence slit,Fixed,0.76mm
Monochromator used,NO
Generator voltage, 40
Tube current, 15
File date and time,03/Jun/2025 15:38
Unit cell,
h k l, 0 0 0
Scan axis,Gonio
Scan range,2.995000000,60.000344240
Scan step size,0.0108664
No. of points, 5246
Scan type,CONTINUOUS
Time per step,18.870
[Scan points]
Angle, TimePerStep, Intensity, ESD
3.000433220, 18.870, 43436.0, 208.4131
3.043898980, 18.870, 41460.0, 203.6173
3.087364740, 18.870, 39557.0, 198.8894
3.130830500, 18.870, 37127.0, 192.6837
3.174296260, 18.870, 35090.0, 187.3233
3.217762020, 18.870, 33716.0, 183.6192
3.261227780, 18.870, 31842.0, 178.4433
3.304693540, 18.870, 30246.0, 173.9138
3.348159300, 18.870, 28539.0, 168.9349
3.391625060, 18.870, 26633.0, 163.1962
3.435090820, 18.870, 25132.0, 158.5308
3.478556580, 18.870, 23565.0, 153.5090
3.522022340, 18.870, 22358.0, 149.5259
3.565488100, 18.870, 21153.0, 145.4407
3.608953860, 18.870, 19554.0, 139.8356
3.652419620, 18.870, 18316.0, 135.3366
3.695885380, 18.870, 17149.0, 130.9542
3.739351140, 18.870, 16194.0, 127.2556
3.782816900, 18.870, 15053.0, 122.6907
3.826282660, 18.870, 14023.0, 118.4187
3.869748420, 18.870, 13211.0, 114.9391
3.913214180, 18.870, 12573.0, 112.1294
3.956679940, 18.870, 11391.0, 106.7286
4.000145700, 18.870, 10591.0, 102.9126
4.043611460, 18.870, 10004.0, 100.0200
4.087077220, 18.870, 9023.0, 94.9895
4.130542980, 18.870, 8619.0, 92.8386
4.174008740, 18.870, 7812.0, 88.3855
4.217474500, 18.870, 7261.0, 85.2115
4.260940260, 18.870, 6973.0, 83.5045
4.304406020, 18.870, 6264.0, 79.1454
4.347871780, 18.870, 5696.0, 75.4718
4.391337540, 18.870, 5301.0, 72.8080
4.434803300, 18.870, 4930.0, 70.2140
4.478269060, 18.870, 4470.0, 66.8581
4.521734820, 18.870, 4246.0, 65.1613
4.565200580, 18.870, 3896.0, 62.4179
4.608666340, 18.870, 3523.0, 59.3549
4.652132100, 18.870, 3320.0, 57.6194
4.695597860, 18.870, 3172.0, 56.3205
4.739063620, 18.870, 2958.0, 54.3875
4.782529380, 18.870, 2772.0, 52.6498
4.825995140, 18.870, 2693.0, 51.8941
4.869460900, 18.870, 2612.0, 51.1077
4.912926660, 18.870, 2500.0, 50.0000
4.956392420, 18.870, 2536.0, 50.3587
4.999858180, 18.870, 2421.0, 49.2037
5.043323940, 18.870, 2485.0, 49.8498
5.086789700, 18.870, 2491.0, 49.9099
5.130255460, 18.870, 2574.0, 50.7346
5.173721220, 18.870, 2436.0, 49.3559
5.217186980, 18.870, 2444.0, 49.4368
5.260652740, 18.870, 2372.0, 48.7032
5.304118500, 18.870, 2233.0, 47.2546
5.347584260, 18.870, 2178.0, 46.6690
5.391050020, 18.870, 2182.0, 46.7119
5.434515780, 18.870, 2022.0, 44.9667
5.477981540, 18.870, 1985.0, 44.5533
5.521447300, 18.870, 1831.0, 42.7902
5.564913060, 18.870, 1787.0, 42.2729
5.608378820, 18.870, 1615.0, 40.1871
5.651844580, 18.870, 1591.0, 39.8873
5.695310340, 18.870, 1556.0, 39.4462
5.738776100, 18.870, 1446.0, 38.0263
5.782241860, 18.870, 1450.0, 38.0789
5.825707620, 18.870, 1376.0, 37.0945
5.869173380, 18.870, 1347.0, 36.7015
5.912639140, 18.870, 1290.0, 35.9166
5.956104900, 18.870, 1282.0, 35.8050
5.999570660, 18.870, 1224.0, 34.9857
6.043036420, 18.870, 1219.0, 34.9142
6.086502180, 18.870, 1255.0, 35.4260
6.129967940, 18.870, 1161.0, 34.0735
6.173433700, 18.870, 1194.0, 34.5543
6.216899460, 18.870, 1227.0, 35.0286
6.260365220, 18.870, 1194.0, 34.5543
6.303830980, 18.870, 1115.0, 33.3916
6.347296740, 18.870, 1119.0, 33.4515
6.390762500, 18.870, 1093.0, 33.0606
6.434228260, 18.870, 1146.0, 33.8526
6.477694020, 18.870, 1115.0, 33.3916
6.521159780, 18.870, 1045.0, 32.3265
6.564625540, 18.870, 1070.0, 32.7109
6.608091300, 18.870, 1059.0, 32.5423
6.651557060, 18.870, 1014.0, 31.8434
6.695022820, 18.870, 996.0, 31.5595
6.738488580, 18.870, 1038.0, 32.2180
6.781954340, 18.870, 916.0, 30.2655
6.825420100, 18.870, 955.0, 30.9031
6.868885860, 18.870, 957.0, 30.9354
6.912351620, 18.870, 932.0, 30.5287
6.955817380, 18.870, 944.0, 30.7246
6.999283140, 18.870, 871.0, 29.5127
7.042748900, 18.870, 884.0, 29.7321
7.086214660, 18.870, 925.0, 30.4138
7.129680420, 18.870, 870.0, 29.4958
7.173146180, 18.870, 856.0, 29.2575
7.216611940, 18.870, 885.0, 29.7489
7.260077700, 18.870, 835.0, 28.8964
7.303543460, 18.870, 830.0, 28.8097
7.347009220, 18.870, 822.0, 28.6705
7.390474980, 18.870, 790.0, 28.1069
7.433940740, 18.870, 878.0, 29.6311
7.477406500, 18.870, 821.0, 28.6531
7.520872260, 18.870, 835.0, 28.8964
7.564338020, 18.870, 799.0, 28.2666
7.607803780, 18.870, 863.0, 29.3769
7.651269540, 18.870, 800.0, 28.2843
7.694735300, 18.870, 825.0, 28.7228
7.738201060, 18.870, 786.0, 28.0357
7.781666820, 18.870, 832.0, 28.8444
7.825132580, 18.870, 811.0, 28.4781
7.868598340, 18.870, 810.0, 28.4605
7.912064100, 18.870, 769.0, 27.7308
7.955529860, 18.870, 829.0, 28.7924
7.998995620, 18.870, 853.0, 29.2062
8.042461380, 18.870, 878.0, 29.6311
8.085927140, 18.870, 868.0, 29.4618
8.129392900, 18.870, 894.0, 29.8998
8.172858660, 18.870, 999.0, 31.6070
8.216324420, 18.870, 1056.0, 32.4962
8.259790180, 18.870, 1116.0, 33.4066
8.303255940, 18.870, 1183.0, 34.3948
8.346721700, 18.870, 1172.0, 34.2345
8.390187460, 18.870, 1106.0, 33.2566
8.433653220, 18.870, 994.0, 31.5278
8.477118980, 18.870, 900.0, 30.0000
8.520584740, 18.870, 831.0, 28.8271
8.564050500, 18.870, 764.0, 27.6405
8.607516260, 18.870, 789.0, 28.0891
8.650982020, 18.870, 904.0, 30.0666
8.694447780, 18.870, 924.0, 30.3974
8.737913540, 18.870, 879.0, 29.6479
8.781379300, 18.870, 905.0, 30.0832
8.824845060, 18.870, 906.0, 30.0998
8.868310820, 18.870, 898.0, 29.9666
8.911776580, 18.870, 990.0, 31.4643
8.955242340, 18.870, 1097.0, 33.1210
8.998708100, 18.870, 1158.0, 34.0294
9.042173860, 18.870, 1309.0, 36.1801
9.085639620, 18.870, 1419.0, 37.6696
9.129105380, 18.870, 1639.0, 40.4846
9.172571140, 18.870, 1881.0, 43.3705
9.216036900, 18.870, 2312.0, 48.0833
9.259502660, 18.870, 2952.0, 54.3323
9.302968420, 18.870, 3399.0, 58.3009
9.346434180, 18.870, 3991.0, 63.1744
9.389899940, 18.870, 4480.0, 66.9328
9.433365700, 18.870, 4542.0, 67.3944
9.476831460, 18.870, 4515.0, 67.1937
9.520297220, 18.870, 4716.0, 68.6731
9.563762980, 18.870, 5953.0, 77.1557
9.607228740, 18.870, 7910.0, 88.9382
9.650694500, 18.870, 9944.0, 99.7196
9.694160260, 18.870, 11932.0, 109.2337
9.737626020, 18.870, 13520.0, 116.2755
9.781091780, 18.870, 13325.0, 115.4340
9.824557540, 18.870, 10542.0, 102.6742
9.868023300, 18.870, 5979.0, 77.3240
9.911489060, 18.870, 2928.0, 54.1110
9.954954820, 18.870, 2376.0, 48.7442
9.998420580, 18.870, 2584.0, 50.8331
10.041886340, 18.870, 3189.0, 56.4712
10.085352100, 18.870, 3888.0, 62.3538
10.128817860, 18.870, 4597.0, 67.8012
10.172283620, 18.870, 5463.0, 73.9121
10.215749380, 18.870, 6081.0, 77.9808
10.259215140, 18.870, 6362.0, 79.7621
10.302680900, 18.870, 5314.0, 72.8972
10.346146660, 18.870, 3627.0, 60.2246
10.389612420, 18.870, 1854.0, 43.0581
10.433078180, 18.870, 1279.0, 35.7631
10.476543940, 18.870, 1150.0, 33.9116
10.520009700, 18.870, 1044.0, 32.3110
10.563475460, 18.870, 996.0, 31.5595
10.606941220, 18.870, 1051.0, 32.4191
10.650406980, 18.870, 996.0, 31.5595
10.693872740, 18.870, 998.0, 31.5911
10.737338500, 18.870, 989.0, 31.4484
10.780804260, 18.870, 1032.0, 32.1248
10.824270020, 18.870, 1010.0, 31.7805
10.867735780, 18.870, 1081.0, 32.8786
10.911201540, 18.870, 1153.0, 33.9559
10.954667300, 18.870, 1212.0, 34.8138
10.998133060, 18.870, 1304.0, 36.1109
11.041598820, 18.870, 1450.0, 38.0789
11.085064580, 18.870, 1631.0, 40.3856
11.128530340, 18.870, 1961.0, 44.2832
11.171996100, 18.870, 2285.0, 47.8017
11.215461860, 18.870, 3099.0, 55.6687
11.258927620, 18.870, 4068.0, 63.7809
11.302393380, 18.870, 4941.0, 70.2922
11.345859140, 18.870, 5845.0, 76.4526
11.389324900, 18.870, 6586.0, 81.1542
11.432790660, 18.870, 6971.0, 83.4925
11.476256420, 18.870, 6215.0, 78.8353
11.519722180, 18.870, 4366.0, 66.0757
11.563187940, 18.870, 3199.0, 56.5597
11.606653700, 18.870, 3025.0, 55.0000
11.650119460, 18.870, 3485.0, 59.0339
11.693585220, 18.870, 3966.0, 62.9762
11.737050980, 18.870, 4569.0, 67.5944
11.780516740, 18.870, 4568.0, 67.5870
11.823982500, 18.870, 4096.0, 64.0000
11.867448260, 18.870, 2858.0, 53.4603
11.910914020, 18.870, 1648.0, 40.5956
11.954379780, 18.870, 1258.0, 35.4683
11.997845540, 18.870, 1084.0, 32.9242
12.041311300, 18.870, 1029.0, 32.0780
12.084777060, 18.870, 1129.0, 33.6006
12.128242820, 18.870, 1161.0, 34.0735
12.171708580, 18.870, 1259.0, 35.4824
12.215174340, 18.870, 1326.0, 36.4143
12.258640100, 18.870, 1448.0, 38.0526
12.302105860, 18.870, 1744.0, 41.7612
12.345571620, 18.870, 2170.0, 46.5833
12.389037380, 18.870, 2713.0, 52.0865
12.432503140, 18.870, 3162.0, 56.2317
12.475968900, 18.870, 3641.0, 60.3407
12.519434660, 18.870, 4122.0, 64.2028
12.562900420, 18.870, 3975.0, 63.0476
12.606366180, 18.870, 3475.0, 58.9491
12.649831940, 18.870, 2697.0, 51.9326
12.693297700, 18.870, 2504.0, 50.0400
12.736763460, 18.870, 2817.0, 53.0754
12.780229220, 18.870, 3725.0, 61.0328
12.823694980, 18.870, 4895.0, 69.9643
12.867160740, 18.870, 6095.0, 78.0705
12.910626500, 18.870, 7066.0, 84.0595
12.954092260, 18.870, 8142.0, 90.2330
12.997558020, 18.870, 8758.0, 93.5842
13.041023780, 18.870, 8023.0, 89.5712
13.084489540, 18.870, 6660.0, 81.6088
13.127955300, 18.870, 6089.0, 78.0320
13.171421060, 18.870, 5914.0, 76.9025
13.214886820, 18.870, 5414.0, 73.5799
13.258352580, 18.870, 3939.0, 62.7615
13.301818340, 18.870, 2564.0, 50.6360
13.345284100, 18.870, 1647.0, 40.5832
13.388749860, 18.870, 1425.0, 37.7492
13.432215620, 18.870, 1358.0, 36.8511
13.475681380, 18.870, 1410.0, 37.5500
13.519147140, 18.870, 1481.0, 38.4838
13.562612900, 18.870, 1773.0, 42.1070
13.606078660, 18.870, 2272.0, 47.6655
13.649544420, 18.870, 2778.0, 52.7067
13.693010180, 18.870, 3425.0, 58.5235
13.736475940, 18.870, 3963.0, 62.9524
13.779941700, 18.870, 4530.0, 67.3053
13.823407460, 18.870, 4489.0, 67.0000
13.866873220, 18.870, 3798.0, 61.6279
13.910338980, 18.870, 2559.0, 50.5866
13.953804740, 18.870, 1549.0, 39.3573
13.997270500, 18.870, 1167.0, 34.1614
14.040736260, 18.870, 1047.0, 32.3574
14.084202020, 18.870, 997.0, 31.5753
14.127667780, 18.870, 912.0, 30.1993
14.171133540, 18.870, 1012.0, 31.8119
14.214599300, 18.870, 973.0, 31.1929
14.258065060, 18.870, 888.0, 29.7993
14.301530820, 18.870, 963.0, 31.0322
14.344996580, 18.870, 915.0, 30.2490
14.388462340, 18.870, 896.0, 29.9333
14.431928100, 18.870, 951.0, 30.8383
14.475393860, 18.870, 994.0, 31.5278
14.518859620, 18.870, 1010.0, 31.7805
14.562325380, 18.870, 997.0, 31.5753
14.605791140, 18.870, 1019.0, 31.9218
14.649256900, 18.870, 1112.0, 33.3467
14.692722660, 18.870, 1153.0, 33.9559
14.736188420, 18.870, 1229.0, 35.0571
14.779654180, 18.870, 1292.0, 35.9444
14.823119940, 18.870, 1494.0, 38.6523
14.866585700, 18.870, 1897.0, 43.5546
14.910051460, 18.870, 2502.0, 50.0200
14.953517220, 18.870, 3321.0, 57.6281
14.996982980, 18.870, 4271.0, 65.3529
15.040448740, 18.870, 4876.0, 69.8284
15.083914500, 18.870, 5344.0, 73.1027
15.127380260, 18.870, 5381.0, 73.3553
15.170846020, 18.870, 4724.0, 68.7314
15.214311780, 18.870, 3222.0, 56.7627
15.257777540, 18.870, 1990.0, 44.6094
15.301243300, 18.870, 1559.0, 39.4842
15.344709060, 18.870, 1579.0, 39.7366
15.388174820, 18.870, 1504.0, 38.7814
15.431640580, 18.870, 1466.0, 38.2884
15.475106340, 18.870, 1390.0, 37.2827
15.518572100, 18.870, 1156.0, 34.0000
15.562037860, 18.870, 1071.0, 32.7261
15.605503620, 18.870, 1007.0, 31.7333
15.648969380, 18.870, 948.0, 30.7896
15.692435140, 18.870, 922.0, 30.3645
15.735900900, 18.870, 993.0, 31.5119
15.779366660, 18.870, 1023.0, 31.9844
15.822832420, 18.870, 1112.0, 33.3467
15.866298180, 18.870, 1163.0, 34.1028
15.909763940, 18.870, 1155.0, 33.9853
15.953229700, 18.870, 1383.0, 37.1887
15.996695460, 18.870, 1582.0, 39.7744
16.040161220, 18.870, 1603.0, 40.0375
16.083626980, 18.870, 1767.0, 42.0357
16.127092740, 18.870, 1677.0, 40.9512
16.170558500, 18.870, 1659.0, 40.7308
16.214024260, 18.870, 1387.0, 37.2424
16.257490020, 18.870, 1075.0, 32.7872
16.300955780, 18.870, 1028.0, 32.0624
16.344421540, 18.870, 1017.0, 31.8904
16.387887300, 18.870, 1126.0, 33.5559
16.431353060, 18.870, 1176.0, 34.2929
16.474818820, 18.870, 1389.0, 37.2693
16.518284580, 18.870, 1597.0, 39.9625
16.561750340, 18.870, 1777.0, 42.1545
16.605216100, 18.870, 1882.0, 43.3820
16.648681860, 18.870, 1792.0, 42.3320
16.692147620, 18.870, 1853.0, 43.0465
16.735613380, 18.870, 1598.0, 39.9750
16.779079140, 18.870, 1370.0, 37.0135
16.822544900, 18.870, 1288.0, 35.8887
16.866010660, 18.870, 1511.0, 38.8716
16.909476420, 18.870, 1686.0, 41.0609
16.952942180, 18.870, 1850.0, 43.0116
16.996407940, 18.870, 2041.0, 45.1774
17.039873700, 18.870, 2119.0, 46.0326
17.083339460, 18.870, 2218.0, 47.0956
17.126805220, 18.870, 2295.0, 47.9062
17.170270980, 18.870, 2659.0, 51.5655
17.213736740, 18.870, 3657.0, 60.4731
17.257202500, 18.870, 4967.0, 70.4769
17.300668260, 18.870, 6171.0, 78.5557
17.344134020, 18.870, 7455.0, 86.3423
17.387599780, 18.870, 8393.0, 91.6133
17.431065540, 18.870, 8495.0, 92.1683
17.474531300, 18.870, 7405.0, 86.0523
17.517997060, 18.870, 5111.0, 71.4913
17.561462820, 18.870, 2921.0, 54.0463
17.604928580, 18.870, 1797.0, 42.3910
17.648394340, 18.870, 1363.0, 36.9188
17.691860100, 18.870, 1284.0, 35.8329
17.735325860, 18.870, 1374.0, 37.0675
17.778791620, 18.870, 1531.0, 39.1280
17.822257380, 18.870, 1645.0, 40.5586
17.865723140, 18.870, 1733.0, 41.6293
17.909188900, 18.870, 1866.0, 43.1972
17.952654660, 18.870, 2142.0, 46.2817
17.996120420, 18.870, 1975.0, 44.4410
18.039586180, 18.870, 1880.0, 43.3590
18.083051940, 18.870, 1725.0, 41.5331
18.126517700, 18.870, 1735.0, 41.6533
18.169983460, 18.870, 1818.0, 42.6380
18.213449220, 18.870, 2001.0, 44.7325
18.256914980, 18.870, 2062.0, 45.4093
18.300380740, 18.870, 1894.0, 43.5201
18.343846500, 18.870, 1770.0, 42.0714
18.387312260, 18.870, 1549.0, 39.3573
18.430778020, 18.870, 1605.0, 40.0625
18.474243780, 18.870, 1764.0, 42.0000
18.517709540, 18.870, 2312.0, 48.0833
18.561175300, 18.870, 2858.0, 53.4603
18.604641060, 18.870, 3843.0, 61.9919
18.648106820, 18.870, 5040.0, 70.9930
18.691572580, 18.870, 6248.0, 79.0443
18.735038340, 18.870, 7111.0, 84.3267
18.778504100, 18.870, 7891.0, 88.8313
18.821969860, 18.870, 8224.0, 90.6863
18.865435620, 18.870, 7704.0, 87.7724
18.908901380, 18.870, 6564.0, 81.0185
18.952367140, 18.870, 5455.0, 73.8580
18.995832900, 18.870, 5099.0, 71.4073
19.039298660, 18.870, 4478.0, 66.9179
19.082764420, 18.870, 3646.0, 60.3821
19.126230180, 18.870, 2905.0, 53.8981
19.169695940, 18.870, 2638.0, 51.3615
19.213161700, 18.870, 2268.0, 47.6235
19.256627460, 18.870, 1973.0, 44.4185
19.300093220, 18.870, 1943.0, 44.0795
19.343558980, 18.870, 2147.0, 46.3357
19.387024740, 18.870, 2440.0, 49.3964
19.430490500, 18.870, 2773.0, 52.6593
19.473956260, 18.870, 3011.0, 54.8726
19.517422020, 18.870, 3092.0, 55.6058
19.560887780, 18.870, 3107.0, 55.7405
19.604353540, 18.870, 3088.0, 55.5698
19.647819300, 18.870, 2568.0, 50.6754
19.691285060, 18.870, 2028.0, 45.0333
19.734750820, 18.870, 1821.0, 42.6732
19.778216580, 18.870, 1701.0, 41.2432
19.821682340, 18.870, 1743.0, 41.7493
19.865148100, 18.870, 1597.0, 39.9625
19.908613860, 18.870, 1494.0, 38.6523
19.952079620, 18.870, 1339.0, 36.5923
19.995545380, 18.870, 1302.0, 36.0832
20.039011140, 18.870, 1401.0, 37.4299
20.082476900, 18.870, 1337.0, 36.5650
20.125942660, 18.870, 1410.0, 37.5500
20.169408420, 18.870, 1342.0, 36.6333
20.212874180, 18.870, 1415.0, 37.6165
20.256339940, 18.870, 1635.0, 40.4351
20.299805700, 18.870, 1901.0, 43.6005
20.343271460, 18.870, 2411.0, 49.1019
20.386737220, 18.870, 3236.0, 56.8859
20.430202980, 18.870, 4099.0, 64.0234
20.473668740, 18.870, 5001.0, 70.7177
20.517134500, 18.870, 5544.0, 74.4580
20.560600260, 18.870, 6112.0, 78.1793
20.604066020, 18.870, 5914.0, 76.9025
20.647531780, 18.870, 4972.0, 70.5124
20.690997540, 18.870, 3633.0, 60.2744
20.734463300, 18.870, 2593.0, 50.9215
20.777929060, 18.870, 2463.0, 49.6286
20.821394820, 18.870, 2649.0, 51.4684
20.864860580, 18.870, 2931.0, 54.1387
20.908326340, 18.870, 3025.0, 55.0000
20.951792100, 18.870, 2985.0, 54.6352
20.995257860, 18.870, 2671.0, 51.6817
21.038723620, 18.870, 2107.0, 45.9021
21.082189380, 18.870, 1599.0, 39.9875
21.125655140, 18.870, 1376.0, 37.0945
21.169120900, 18.870, 1276.0, 35.7211
21.212586660, 18.870, 1356.0, 36.8239
21.256052420, 18.870, 1329.0, 36.4555
21.299518180, 18.870, 1392.0, 37.3095
21.342983940, 18.870, 1676.0, 40.9390
21.386449700, 18.870, 1725.0, 41.5331
21.429915460, 18.870, 2035.0, 45.1110
21.473381220, 18.870, 2730.0, 52.2494
21.516846980, 18.870, 3769.0, 61.3922
21.560312740, 18.870, 4670.0, 68.3374
21.603778500, 18.870, 5644.0, 75.1266
21.647244260, 18.870, 6087.0, 78.0192
21.690710020, 18.870, 6454.0, 80.3368
21.734175780, 18.870, 6161.0, 78.4920
21.777641540, 18.870, 4876.0, 69.8284
21.821107300, 18.870, 3468.0, 58.8897
21.864573060, 18.870, 2863.0, 53.5070
21.908038820, 18.870, 3529.0, 59.4054
21.951504580, 18.870, 4630.0, 68.0441
21.994970340, 18.870, 6302.0, 79.3851
22.038436100, 18.870, 7862.0, 88.6679
22.081901860, 18.870, 9406.0, 96.9845
22.125367620, 18.870, 10181.0, 100.9009
22.168833380, 18.870, 10018.0, 100.0900
22.212299140, 18.870, 9127.0, 95.5353
22.255764900, 18.870, 7854.0, 88.6228
22.299230660, 18.870, 5835.0, 76.3872
22.342696420, 18.870, 4050.0, 63.6396
22.386162180, 18.870, 3142.0, 56.0535
22.429627940, 18.870, 3103.0, 55.7046
22.473093700, 18.870, 3881.0, 62.2977
22.516559460, 18.870, 4973.0, 70.5195
22.560025220, 18.870, 7625.0, 87.3212
22.603490980, 18.870, 10590.0, 102.9077
22.646956740, 18.870, 13907.0, 117.9279
22.690422500, 18.870, 16653.0, 129.0465
22.733888260, 18.870, 18604.0, 136.3965
22.777354020, 18.870, 20413.0, 142.8741
22.820819780, 18.870, 19588.0, 139.9571
22.864285540, 18.870, 15658.0, 125.1319
22.907751300, 18.870, 11493.0, 107.2054
22.951217060, 18.870, 9101.0, 95.3992
22.994682820, 18.870, 7303.0, 85.4576
23.038148580, 18.870, 5587.0, 74.7462
23.081614340, 18.870, 3945.0, 62.8092
23.125080100, 18.870, 3019.0, 54.9454
23.168545860, 18.870, 2735.0, 52.2972
23.212011620, 18.870, 2835.0, 53.2447
23.255477380, 18.870, 3322.0, 57.6368
23.298943140, 18.870, 3743.0, 61.1801
23.342408900, 18.870, 4148.0, 64.4050
23.385874660, 18.870, 4361.0, 66.0379
23.429340420, 18.870, 4161.0, 64.5058
23.472806180, 18.870, 3989.0, 63.1585
23.516271940, 18.870, 3363.0, 57.9914
23.559737700, 18.870, 3130.0, 55.9464
23.603203460, 18.870, 3177.0, 56.3649
23.646669220, 18.870, 3410.0, 58.3952
23.690134980, 18.870, 3707.0, 60.8851
23.733600740, 18.870, 4072.0, 63.8122
23.777066500, 18.870, 4060.0, 63.7181
23.820532260, 18.870, 3599.0, 59.9917
23.863998020, 18.870, 3193.0, 56.5066
23.907463780, 18.870, 2668.0, 51.6527
23.950929540, 18.870, 2168.0, 46.5618
23.994395300, 18.870, 1822.0, 42.6849
24.037861060, 18.870, 1602.0, 40.0250
24.081326820, 18.870, 1544.0, 39.2938
24.124792580, 18.870, 1510.0, 38.8587
24.168258340, 18.870, 1629.0, 40.3609
24.211724100, 18.870, 1835.0, 42.8369
24.255189860, 18.870, 2208.0, 46.9894
24.298655620, 18.870, 2456.0, 49.5580
24.342121380, 18.870, 2683.0, 51.7977
24.385587140, 18.870, 3075.0, 55.4527
24.429052900, 18.870, 3229.0, 56.8243
24.472518660, 18.870, 3469.0, 58.8982
24.515984420, 18.870, 3601.0, 60.0083
24.559450180, 18.870, 4202.0, 64.8228
24.602915940, 18.870, 5761.0, 75.9013
24.646381700, 18.870, 7116.0, 84.3564
24.689847460, 18.870, 8389.0, 91.5915
24.733313220, 18.870, 8897.0, 94.3239
24.776778980, 18.870, 9038.0, 95.0684
24.820244740, 18.870, 7560.0, 86.9483
24.863710500, 18.870, 5461.0, 73.8986
24.907176260, 18.870, 3253.0, 57.0351
24.950642020, 18.870, 2124.0, 46.0869
24.994107780, 18.870, 1720.0, 41.4729
25.037573540, 18.870, 1711.0, 41.3642
25.081039300, 18.870, 1777.0, 42.1545
25.124505060, 18.870, 2056.0, 45.3431
25.167970820, 18.870, 2234.0, 47.2652
25.211436580, 18.870, 2537.0, 50.3686
25.254902340, 18.870, 2755.0, 52.4881
25.298368100, 18.870, 2645.0, 51.4296
25.341833860, 18.870, 2584.0, 50.8331
25.385299620, 18.870, 2325.0, 48.2183
25.428765380, 18.870, 2179.0, 46.6798
25.472231140, 18.870, 1955.0, 44.2154
25.515696900, 18.870, 1734.0, 41.6413
25.559162660, 18.870, 1730.0, 41.5933
25.602628420, 18.870, 1619.0, 40.2368
25.646094180, 18.870, 1767.0, 42.0357
25.689559940, 18.870, 1556.0, 39.4462
25.733025700, 18.870, 1390.0, 37.2827
25.776491460, 18.870, 1272.0, 35.6651
25.819957220, 18.870, 1249.0, 35.3412
25.863422980, 18.870, 1303.0, 36.0971
25.906888740, 18.870, 1270.0, 35.6371
25.950354500, 18.870, 1246.0, 35.2987
25.993820260, 18.870, 1221.0, 34.9428
26.037286020, 18.870, 1337.0, 36.5650
26.080751780, 18.870, 1290.0, 35.9166
26.124217540, 18.870, 1278.0, 35.7491
26.167683300, 18.870, 1412.0, 37.5766
26.211149060, 18.870, 1515.0, 38.9230
26.254614820, 18.870, 1611.0, 40.1373
26.298080580, 18.870, 1670.0, 40.8656
26.341546340, 18.870, 1863.0, 43.1625
26.385012100, 18.870, 1972.0, 44.4072
26.428477860, 18.870, 2162.0, 46.4973
26.471943620, 18.870, 2243.0, 47.3603
26.515409380, 18.870, 2266.0, 47.6025
26.558875140, 18.870, 2251.0, 47.4447
26.602340900, 18.870, 2198.0, 46.8828
26.645806660, 18.870, 2016.0, 44.8999
26.689272420, 18.870, 1918.0, 43.7950
26.732738180, 18.870, 1758.0, 41.9285
26.776203940, 18.870, 1591.0, 39.8873
26.819669700, 18.870, 1592.0, 39.8999
26.863135460, 18.870, 1492.0, 38.6264
26.906601220, 18.870, 1400.0, 37.4166
26.950066980, 18.870, 1498.0, 38.7040
26.993532740, 18.870, 1557.0, 39.4588
27.036998500, 18.870, 1866.0, 43.1972
27.080464260, 18.870, 1958.0, 44.2493
27.123930020, 18.870, 2057.0, 45.3542
27.167395780, 18.870, 2163.0, 46.5081
27.210861540, 18.870, 2083.0, 45.6399
27.254327300, 18.870, 2063.0, 45.4203
27.297793060, 18.870, 2011.0, 44.8442
27.341258820, 18.870, 2162.0, 46.4973
27.384724580, 18.870, 2480.0, 49.7996
27.428190340, 18.870, 2889.0, 53.7494
27.471656100, 18.870, 3418.0, 58.4637
27.515121860, 18.870, 4325.0, 65.7647
27.558587620, 18.870, 5810.0, 76.2234
27.602053380, 18.870, 7311.0, 85.5044
27.645519140, 18.870, 8492.0, 92.1520
27.688984900, 18.870, 9248.0, 96.1665
27.732450660, 18.870, 9760.0, 98.7927
27.775916420, 18.870, 8889.0, 94.2815
27.819382180, 18.870, 6935.0, 83.2766
27.862847940, 18.870, 4790.0, 69.2098
27.906313700, 18.870, 2884.0, 53.7029
27.949779460, 18.870, 2007.0, 44.7996
27.993245220, 18.870, 1542.0, 39.2683
28.036710980, 18.870, 1457.0, 38.1707
28.080176740, 18.870, 1382.0, 37.1753
28.123642500, 18.870, 1429.0, 37.8021
28.167108260, 18.870, 1433.0, 37.8550
28.210574020, 18.870, 1413.0, 37.5899
28.254039780, 18.870, 1346.0, 36.6879
28.297505540, 18.870, 1399.0, 37.4032
28.340971300, 18.870, 1451.0, 38.0920
28.384437060, 18.870, 1509.0, 38.8458
28.427902820, 18.870, 1467.0, 38.3014
28.471368580, 18.870, 1516.0, 38.9358
28.514834340, 18.870, 1561.0, 39.5095
28.558300100, 18.870, 1674.0, 40.9145
28.601765860, 18.870, 1568.0, 39.5980
28.645231620, 18.870, 1657.0, 40.7063
28.688697380, 18.870, 1657.0, 40.7063
28.732163140, 18.870, 1800.0, 42.4264
28.775628900, 18.870, 1669.0, 40.8534
28.819094660, 18.870, 1580.0, 39.7492
28.862560420, 18.870, 1584.0, 39.7995
28.906026180, 18.870, 1787.0, 42.2729
28.949491940, 18.870, 2045.0, 45.2217
28.992957700, 18.870, 2372.0, 48.7032
29.036423460, 18.870, 2698.0, 51.9423
29.079889220, 18.870, 2854.0, 53.4228
29.123354980, 18.870, 2848.0, 53.3667
29.166820740, 18.870, 2423.0, 49.2240
29.210286500, 18.870, 2081.0, 45.6180
29.253752260, 18.870, 1655.0, 40.6817
29.297218020, 18.870, 1433.0, 37.8550
29.340683780, 18.870, 1277.0, 35.7351
29.384149540, 18.870, 1344.0, 36.6606
29.427615300, 18.870, 1381.0, 37.1618
29.471081060, 18.870, 1373.0, 37.0540
29.514546820, 18.870, 1299.0, 36.0416
29.558012580, 18.870, 1278.0, 35.7491
29.601478340, 18.870, 1263.0, 35.5387
29.644944100, 18.870, 1159.0, 34.0441
29.688409860, 18.870, 1137.0, 33.7194
29.731875620, 18.870, 990.0, 31.4643
29.775341380, 18.870, 940.0, 30.6594
29.818807140, 18.870, 869.0, 29.4788
29.862272900, 18.870, 975.0, 31.2250
29.905738660, 18.870, 896.0, 29.9333
29.949204420, 18.870, 900.0, 30.0000
29.992670180, 18.870, 877.0, 29.6142
30.036135940, 18.870, 849.0, 29.1376
30.079601700, 18.870, 894.0, 29.8998
30.123067460, 18.870, 879.0, 29.6479
30.166533220, 18.870, 893.0, 29.8831
30.209998980, 18.870, 929.0, 30.4795
30.253464740, 18.870, 1042.0, 32.2800
30.296930500, 18.870, 1038.0, 32.2180
30.340396260, 18.870, 1092.0, 33.0454
30.383862020, 18.870, 1131.0, 33.6303
30.427327780, 18.870, 1119.0, 33.4515
30.470793540, 18.870, 1054.0, 32.4654
30.514259300, 18.870, 1162.0, 34.0881
30.557725060, 18.870, 1105.0, 33.2415
30.601190820, 18.870, 1149.0, 33.8969
30.644656580, 18.870, 1112.0, 33.3467
30.688122340, 18.870, 1070.0, 32.7109
30.731588100, 18.870, 1094.0, 33.0757
30.775053860, 18.870, 1136.0, 33.7046
30.818519620, 18.870, 1002.0, 31.6544
30.861985380, 18.870, 1075.0, 32.7872
30.905451140, 18.870, 1034.0, 32.1559
30.948916900, 18.870, 1037.0, 32.2025
30.992382660, 18.870, 1155.0, 33.9853
31.035848420, 18.870, 1229.0, 35.0571
31.079314180, 18.870, 1418.0, 37.6563
31.122779940, 18.870, 1459.0, 38.1969
31.166245700, 18.870, 1482.0, 38.4968
31.209711460, 18.870, 1576.0, 39.6989
31.253177220, 18.870, 1459.0, 38.1969
31.296642980, 18.870, 1389.0, 37.2693
31.340108740, 18.870, 1252.0, 35.3836
31.383574500, 18.870, 1263.0, 35.5387
31.427040260, 18.870, 1291.0, 35.9305
31.470506020, 18.870, 1267.0, 35.5949
31.513971780, 18.870, 1166.0, 34.1467
31.557437540, 18.870, 1274.0, 35.6931
31.600903300, 18.870, 1238.0, 35.1852
31.644369060, 18.870, 1186.0, 34.4384
31.687834820, 18.870, 1127.0, 33.5708
31.731300580, 18.870, 1053.0, 32.4500
31.774766340, 18.870, 1079.0, 32.8481
31.818232100, 18.870, 1119.0, 33.4515
31.861697860, 18.870, 1125.0, 33.5410
31.905163620, 18.870, 1179.0, 34.3366
31.948629380, 18.870, 1257.0, 35.4542
31.992095140, 18.870, 1335.0, 36.5377
32.035560900, 18.870, 1483.0, 38.5097
32.079026660, 18.870, 1506.0, 38.8072
32.122492420, 18.870, 1600.0, 40.0000
32.165958180, 18.870, 1582.0, 39.7744
32.209423940, 18.870, 1621.0, 40.2616
32.252889700, 18.870, 1577.0, 39.7115
32.296355460, 18.870, 1314.0, 36.2491
32.339821220, 18.870, 1279.0, 35.7631
32.383286980, 18.870, 1285.0, 35.8469
32.426752740, 18.870, 1334.0, 36.5240
32.470218500, 18.870, 1482.0, 38.4968
32.513684260, 18.870, 1628.0, 40.3485
32.557150020, 18.870, 1578.0, 39.7240
32.600615780, 18.870, 1585.0, 39.8121
32.644081540, 18.870, 1481.0, 38.4838
32.687547300, 18.870, 1308.0, 36.1663
32.731013060, 18.870, 1175.0, 34.2783
32.774478820, 18.870, 1133.0, 33.6601
32.817944580, 18.870, 1080.0, 32.8634
32.861410340, 18.870, 1037.0, 32.2025
32.904876100, 18.870, 1034.0, 32.1559
32.948341860, 18.870, 1081.0, 32.8786
32.991807620, 18.870, 1048.0, 32.3728
33.035273380, 18.870, 971.0, 31.1609
33.078739140, 18.870, 1058.0, 32.5269
33.122204900, 18.870, 1027.0, 32.0468
33.165670660, 18.870, 1142.0, 33.7935
33.209136420, 18.870, 1078.0, 32.8329
33.252602180, 18.870, 1167.0, 34.1614
33.296067940, 18.870, 1265.0, 35.5668
33.339533700, 18.870, 1224.0, 34.9857
33.382999460, 18.870, 1189.0, 34.4819
33.426465220, 18.870, 1080.0, 32.8634
33.469930980, 18.870, 1073.0, 32.7567
33.513396740, 18.870, 954.0, 30.8869
33.556862500, 18.870, 971.0, 31.1609
33.600328260, 18.870, 943.0, 30.7083
33.643794020, 18.870, 947.0, 30.7734
33.687259780, 18.870, 1005.0, 31.7017
33.730725540, 18.870, 958.0, 30.9516
33.774191300, 18.870, 1029.0, 32.0780
33.817657060, 18.870, 1053.0, 32.4500
33.861122820, 18.870, 1229.0, 35.0571
33.904588580, 18.870, 1271.0, 35.6511
33.948054340, 18.870, 1338.0, 36.5787
33.991520100, 18.870, 1431.0, 37.8286
34.034985860, 18.870, 1431.0, 37.8286
34.078451620, 18.870, 1436.0, 37.8946
34.121917380, 18.870, 1322.0, 36.3593
34.165383140, 18.870, 1161.0, 34.0735
34.208848900, 18.870, 1077.0, 32.8177
34.252314660, 18.870, 1033.0, 32.1403
34.295780420, 18.870, 1020.0, 31.9374
34.339246180, 18.870, 1026.0, 32.0312
34.382711940, 18.870, 1029.0, 32.0780
34.426177700, 18.870, 1035.0, 32.1714
34.469643460, 18.870, 1127.0, 33.5708
34.513109220, 18.870, 1122.0, 33.4963
34.556574980, 18.870, 1108.0, 33.2866
34.600040740, 18.870, 1181.0, 34.3657
34.643506500, 18.870, 1210.0, 34.7851
34.686972260, 18.870, 1302.0, 36.0832
34.730438020, 18.870, 1311.0, 36.2077
34.773903780, 18.870, 1253.0, 35.3977
34.817369540, 18.870, 1244.0, 35.2704
34.860835300, 18.870, 1157.0, 34.0147
34.904301060, 18.870, 1152.0, 33.9411
34.947766820, 18.870, 1099.0, 33.1512
34.991232580, 18.870, 1105.0, 33.2415
35.034698340, 18.870, 1106.0, 33.2566
35.078164100, 18.870, 1093.0, 33.0606
35.121629860, 18.870, 1127.0, 33.5708
35.165095620, 18.870, 1121.0, 33.4813
35.208561380, 18.870, 1139.0, 33.7491
35.252027140, 18.870, 1150.0, 33.9116
35.295492900, 18.870, 1201.0, 34.6554
35.338958660, 18.870, 1111.0, 33.3317
35.382424420, 18.870, 1042.0, 32.2800
35.425890180, 18.870, 1081.0, 32.8786
35.469355940, 18.870, 1041.0, 32.2645
35.512821700, 18.870, 1101.0, 33.1813
35.556287460, 18.870, 1113.0, 33.3617
35.599753220, 18.870, 1105.0, 33.2415
35.643218980, 18.870, 1186.0, 34.4384
35.686684740, 18.870, 1143.0, 33.8083
35.730150500, 18.870, 1223.0, 34.9714
35.773616260, 18.870, 1272.0, 35.6651
35.817082020, 18.870, 1301.0, 36.0694
35.860547780, 18.870, 1351.0, 36.7560
35.904013540, 18.870, 1447.0, 38.0395
35.947479300, 18.870, 1485.0, 38.5357
35.990945060, 18.870, 1340.0, 36.6060
36.034410820, 18.870, 1296.0, 36.0000
36.077876580, 18.870, 1054.0, 32.4654
36.121342340, 18.870, 965.0, 31.0644
36.164808100, 18.870, 933.0, 30.5450
36.208273860, 18.870, 890.0, 29.8329
36.251739620, 18.870, 850.0, 29.1548
36.295205380, 18.870, 885.0, 29.7489
36.338671140, 18.870, 931.0, 30.5123
36.382136900, 18.870, 979.0, 31.2890
36.425602660, 18.870, 1017.0, 31.8904
36.469068420, 18.870, 1024.0, 32.0000
36.512534180, 18.870, 1152.0, 33.9411
36.555999940, 18.870, 1205.0, 34.7131
36.599465700, 18.870, 1160.0, 34.0588
36.642931460, 18.870, 1111.0, 33.3317
36.686397220, 18.870, 1113.0, 33.3617
36.729862980, 18.870, 1120.0, 33.4664
36.773328740, 18.870, 1057.0, 32.5115
36.816794500, 18.870, 1059.0, 32.5423
36.860260260, 18.870, 1184.0, 34.4093
36.903726020, 18.870, 1093.0, 33.0606
36.947191780, 18.870, 1166.0, 34.1467
36.990657540, 18.870, 1188.0, 34.4674
37.034123300, 18.870, 1121.0, 33.4813
37.077589060, 18.870, 1099.0, 33.1512
37.121054820, 18.870, 1021.0, 31.9531
37.164520580, 18.870, 966.0, 31.0805
37.207986340, 18.870, 865.0, 29.4109
37.251452100, 18.870, 865.0, 29.4109
37.294917860, 18.870, 845.0, 29.0689
37.338383620, 18.870, 836.0, 28.9137
37.381849380, 18.870, 800.0, 28.2843
37.425315140, 18.870, 814.0, 28.5307
37.468780900, 18.870, 817.0, 28.5832
37.512246660, 18.870, 814.0, 28.5307
37.555712420, 18.870, 821.0, 28.6531
37.599178180, 18.870, 817.0, 28.5832
37.642643940, 18.870, 881.0, 29.6816
37.686109700, 18.870, 911.0, 30.1828
37.729575460, 18.870, 925.0, 30.4138
37.773041220, 18.870, 917.0, 30.2820
37.816506980, 18.870, 921.0, 30.3480
37.859972740, 18.870, 967.0, 31.0966
37.903438500, 18.870, 923.0, 30.3809
37.946904260, 18.870, 901.0, 30.0167
37.990370020, 18.870, 860.0, 29.3258
38.033835780, 18.870, 925.0, 30.4138
38.077301540, 18.870, 862.0, 29.3598
38.120767300, 18.870, 901.0, 30.0167
38.164233060, 18.870, 868.0, 29.4618
38.207698820, 18.870, 897.0, 29.9500
38.251164580, 18.870, 872.0, 29.5296
38.294630340, 18.870, 869.0, 29.4788
38.338096100, 18.870, 820.0, 28.6356
38.381561860, 18.870, 752.0, 27.4226
38.425027620, 18.870, 796.0, 28.2135
38.468493380, 18.870, 749.0, 27.3679
38.511959140, 18.870, 767.0, 27.6948
38.555424900, 18.870, 783.0, 27.9821
38.598890660, 18.870, 743.0, 27.2580
38.642356420, 18.870, 815.0, 28.5482
38.685822180, 18.870, 820.0, 28.6356
38.729287940, 18.870, 814.0, 28.5307
38.772753700, 18.870, 847.0, 29.1033
38.816219460, 18.870, 908.0, 30.1330
38.859685220, 18.870, 961.0, 31.0000
38.903150980, 18.870, 960.0, 30.9839
38.946616740, 18.870, 975.0, 31.2250
38.990082500, 18.870, 963.0, 31.0322
39.033548260, 18.870, 998.0, 31.5911
39.077014020, 18.870, 997.0, 31.5753
39.120479780, 18.870, 1056.0, 32.4962
39.163945540, 18.870, 1105.0, 33.2415
39.207411300, 18.870, 1201.0, 34.6554
39.250877060, 18.870, 1175.0, 34.2783
39.294342820, 18.870, 1174.0, 34.2637
39.337808580, 18.870, 1202.0, 34.6699
39.381274340, 18.870, 1192.0, 34.5254
39.424740100, 18.870, 1121.0, 33.4813
39.468205860, 18.870, 1060.0, 32.5576
39.511671620, 18.870, 1007.0, 31.7333
39.555137380, 18.870, 940.0, 30.6594
39.598603140, 18.870, 899.0, 29.9833
39.642068900, 18.870, 997.0, 31.5753
39.685534660, 18.870, 945.0, 30.7409
39.729000420, 18.870, 996.0, 31.5595
39.772466180, 18.870, 1138.0, 33.7343
39.815931940, 18.870, 1285.0, 35.8469
39.859397700, 18.870, 1426.0, 37.7624
39.902863460, 18.870, 1494.0, 38.6523
39.946329220, 18.870, 1641.0, 40.5093
39.989794980, 18.870, 1659.0, 40.7308
40.033260740, 18.870, 1381.0, 37.1618
40.076726500, 18.870, 1306.0, 36.1386
40.120192260, 18.870, 1127.0, 33.5708
40.163658020, 18.870, 1008.0, 31.7490
40.207123780, 18.870, 920.0, 30.3315
40.250589540, 18.870, 910.0, 30.1662
40.294055300, 18.870, 942.0, 30.6920
40.337521060, 18.870, 976.0, 31.2410
40.380986820, 18.870, 914.0, 30.2324
40.424452580, 18.870, 974.0, 31.2090
40.467918340, 18.870, 1018.0, 31.9061
40.511384100, 18.870, 1041.0, 32.2645
40.554849860, 18.870, 989.0, 31.4484
40.598315620, 18.870, 1048.0, 32.3728
40.641781380, 18.870, 1030.0, 32.0936
40.685247140, 18.870, 1100.0, 33.1662
40.728712900, 18.870, 1075.0, 32.7872
40.772178660, 18.870, 1165.0, 34.1321
40.815644420, 18.870, 1092.0, 33.0454
40.859110180, 18.870, 1065.0, 32.6343
40.902575940, 18.870, 1053.0, 32.4500
40.946041700, 18.870, 990.0, 31.4643
40.989507460, 18.870, 903.0, 30.0500
41.032973220, 18.870, 900.0, 30.0000
41.076438980, 18.870, 877.0, 29.6142
41.119904740, 18.870, 910.0, 30.1662
41.163370500, 18.870, 981.0, 31.3209
41.206836260, 18.870, 1054.0, 32.4654
41.250302020, 18.870, 981.0, 31.3209
41.293767780, 18.870, 894.0, 29.8998
41.337233540, 18.870, 871.0, 29.5127
41.380699300, 18.870, 870.0, 29.4958
41.424165060, 18.870, 773.0, 27.8029
41.467630820, 18.870, 713.0, 26.7021
41.511096580, 18.870, 757.0, 27.5136
41.554562340, 18.870, 785.0, 28.0179
41.598028100, 18.870, 744.0, 27.2764
41.641493860, 18.870, 781.0, 27.9464
41.684959620, 18.870, 786.0, 28.0357
41.728425380, 18.870, 810.0, 28.4605
41.771891140, 18.870, 848.0, 29.1204
41.815356900, 18.870, 832.0, 28.8444
41.858822660, 18.870, 889.0, 29.8161
41.902288420, 18.870, 823.0, 28.6880
41.945754180, 18.870, 790.0, 28.1069
41.989219940, 18.870, 796.0, 28.2135
42.032685700, 18.870, 721.0, 26.8514
42.076151460, 18.870, 707.0, 26.5895
42.119617220, 18.870, 733.0, 27.0740
42.163082980, 18.870, 693.0, 26.3249
42.206548740, 18.870, 766.0, 27.6767
42.250014500, 18.870, 739.0, 27.1846
42.293480260, 18.870, 757.0, 27.5136
42.336946020, 18.870, 794.0, 28.1780
42.380411780, 18.870, 843.0, 29.0345
42.423877540, 18.870, 866.0, 29.4279
42.467343300, 18.870, 918.0, 30.2985
42.510809060, 18.870, 976.0, 31.2410
42.554274820, 18.870, 980.0, 31.3050
42.597740580, 18.870, 1054.0, 32.4654
42.641206340, 18.870, 1033.0, 32.1403
42.684672100, 18.870, 945.0, 30.7409
42.728137860, 18.870, 899.0, 29.9833
42.771603620, 18.870, 901.0, 30.0167
42.815069380, 18.870, 848.0, 29.1204
42.858535140, 18.870, 809.0, 28.4429
42.902000900, 18.870, 817.0, 28.5832
42.945466660, 18.870, 771.0, 27.7669
42.988932420, 18.870, 821.0, 28.6531
43.032398180, 18.870, 890.0, 29.8329
43.075863940, 18.870, 905.0, 30.0832
43.119329700, 18.870, 968.0, 31.1127
43.162795460, 18.870, 970.0, 31.1448
43.206261220, 18.870, 987.0, 31.4166
43.249726980, 18.870, 920.0, 30.3315
43.293192740, 18.870, 952.0, 30.8545
43.336658500, 18.870, 899.0, 29.9833
43.380124260, 18.870, 834.0, 28.8791
43.423590020, 18.870, 806.0, 28.3901
43.467055780, 18.870, 753.0, 27.4408
43.510521540, 18.870, 780.0, 27.9285
43.553987300, 18.870, 812.0, 28.4956
43.597453060, 18.870, 729.0, 27.0000
43.640918820, 18.870, 683.0, 26.1343
43.684384580, 18.870, 690.0, 26.2679
43.727850340, 18.870, 622.0, 24.9399
43.771316100, 18.870, 672.0, 25.9230
43.814781860, 18.870, 629.0, 25.0799
43.858247620, 18.870, 666.0, 25.8070
43.901713380, 18.870, 655.0, 25.5930
43.945179140, 18.870, 647.0, 25.4362
43.988644900, 18.870, 612.0, 24.7386
44.032110660, 18.870, 634.0, 25.1794
44.075576420, 18.870, 627.0, 25.0400
44.119042180, 18.870, 615.0, 24.7992
44.162507940, 18.870, 672.0, 25.9230
44.205973700, 18.870, 682.0, 26.1151
44.249439460, 18.870, 666.0, 25.8070
44.292905220, 18.870, 672.0, 25.9230
44.336370980, 18.870, 645.0, 25.3969
44.379836740, 18.870, 669.0, 25.8650
44.423302500, 18.870, 667.0, 25.8263
44.466768260, 18.870, 717.0, 26.7769
44.510234020, 18.870, 612.0, 24.7386
44.553699780, 18.870, 649.0, 25.4755
44.597165540, 18.870, 616.0, 24.8193
44.640631300, 18.870, 653.0, 25.5539
44.684097060, 18.870, 673.0, 25.9422
44.727562820, 18.870, 651.0, 25.5147
44.771028580, 18.870, 689.0, 26.2488
44.814494340, 18.870, 657.0, 25.6320
44.857960100, 18.870, 695.0, 26.3629
44.901425860, 18.870, 708.0, 26.6083
44.944891620, 18.870, 777.0, 27.8747
44.988357380, 18.870, 826.0, 28.7402
45.031823140, 18.870, 828.0, 28.7750
45.075288900, 18.870, 886.0, 29.7658
45.118754660, 18.870, 885.0, 29.7489
45.162220420, 18.870, 911.0, 30.1828
45.205686180, 18.870, 837.0, 28.9310
45.249151940, 18.870, 863.0, 29.3769
45.292617700, 18.870, 813.0, 28.5132
45.336083460, 18.870, 755.0, 27.4773
45.379549220, 18.870, 743.0, 27.2580
45.423014980, 18.870, 809.0, 28.4429
45.466480740, 18.870, 848.0, 29.1204
45.509946500, 18.870, 687.0, 26.2107
45.553412260, 18.870, 849.0, 29.1376
45.596878020, 18.870, 772.0, 27.7849
45.640343780, 18.870, 831.0, 28.8271
45.683809540, 18.870, 802.0, 28.3196
45.727275300, 18.870, 834.0, 28.8791
45.770741060, 18.870, 831.0, 28.8271
45.814206820, 18.870, 789.0, 28.0891
45.857672580, 18.870, 938.0, 30.6268
45.901138340, 18.870, 937.0, 30.6105
45.944604100, 18.870, 958.0, 30.9516
45.988069860, 18.870, 1065.0, 32.6343
46.031535620, 18.870, 1138.0, 33.7343
46.075001380, 18.870, 1052.0, 32.4345
46.118467140, 18.870, 1024.0, 32.0000
46.161932900, 18.870, 1010.0, 31.7805
46.205398660, 18.870, 981.0, 31.3209
46.248864420, 18.870, 929.0, 30.4795
46.292330180, 18.870, 843.0, 29.0345
46.335795940, 18.870, 801.0, 28.3019
46.379261700, 18.870, 779.0, 27.9106
46.422727460, 18.870, 761.0, 27.5862
46.466193220, 18.870, 733.0, 27.0740
46.509658980, 18.870, 755.0, 27.4773
46.553124740, 18.870, 745.0, 27.2947
46.596590500, 18.870, 771.0, 27.7669
46.640056260, 18.870, 717.0, 26.7769
46.683522020, 18.870, 817.0, 28.5832
46.726987780, 18.870, 869.0, 29.4788
46.770453540, 18.870, 864.0, 29.3939
46.813919300, 18.870, 902.0, 30.0333
46.857385060, 18.870, 951.0, 30.8383
46.900850820, 18.870, 886.0, 29.7658
46.944316580, 18.870, 845.0, 29.0689
46.987782340, 18.870, 785.0, 28.0179
47.031248100, 18.870, 660.0, 25.6905
47.074713860, 18.870, 688.0, 26.2298
47.118179620, 18.870, 673.0, 25.9422
47.161645380, 18.870, 724.0, 26.9072
47.205111140, 18.870, 615.0, 24.7992
47.248576900, 18.870, 645.0, 25.3969
47.292042660, 18.870, 624.0, 24.9800
47.335508420, 18.870, 635.0, 25.1992
47.378974180, 18.870, 686.0, 26.1916
47.422439940, 18.870, 692.0, 26.3059
47.465905700, 18.870, 768.0, 27.7128
47.509371460, 18.870, 794.0, 28.1780
47.552837220, 18.870, 761.0, 27.5862
47.596302980, 18.870, 782.0, 27.9643
47.639768740, 18.870, 690.0, 26.2679
47.683234500, 18.870, 717.0, 26.7769
47.726700260, 18.870, 693.0, 26.3249
47.770166020, 18.870, 755.0, 27.4773
47.813631780, 18.870, 705.0, 26.5518
47.857097540, 18.870, 710.0, 26.6458
47.900563300, 18.870, 731.0, 27.0370
47.944029060, 18.870, 759.0, 27.5500
47.987494820, 18.870, 737.0, 27.1477
48.030960580, 18.870, 747.0, 27.3313
48.074426340, 18.870, 729.0, 27.0000
48.117892100, 18.870, 706.0, 26.5707
48.161357860, 18.870, 758.0, 27.5318
48.204823620, 18.870, 728.0, 26.9815
48.248289380, 18.870, 701.0, 26.4764
48.291755140, 18.870, 741.0, 27.2213
48.335220900, 18.870, 748.0, 27.3496
48.378686660, 18.870, 721.0, 26.8514
48.422152420, 18.870, 701.0, 26.4764
48.465618180, 18.870, 685.0, 26.1725
48.509083940, 18.870, 668.0, 25.8457
48.552549700, 18.870, 646.0, 25.4165
48.596015460, 18.870, 613.0, 24.7588
48.639481220, 18.870, 602.0, 24.5357
48.682946980, 18.870, 627.0, 25.0400
48.726412740, 18.870, 612.0, 24.7386
48.769878500, 18.870, 632.0, 25.1396
48.813344260, 18.870, 653.0, 25.5539
48.856810020, 18.870, 560.0, 23.6643
48.900275780, 18.870, 626.0, 25.0200
48.943741540, 18.870, 629.0, 25.0799
48.987207300, 18.870, 654.0, 25.5734
49.030673060, 18.870, 664.0, 25.7682
49.074138820, 18.870, 670.0, 25.8844
49.117604580, 18.870, 698.0, 26.4197
49.161070340, 18.870, 687.0, 26.2107
49.204536100, 18.870, 648.0, 25.4558
49.248001860, 18.870, 705.0, 26.5518
49.291467620, 18.870, 691.0, 26.2869
49.334933380, 18.870, 638.0, 25.2587
49.378399140, 18.870, 651.0, 25.5147
49.421864900, 18.870, 638.0, 25.2587
49.465330660, 18.870, 616.0, 24.8193
49.508796420, 18.870, 626.0, 25.0200
49.552262180, 18.870, 630.0, 25.0998
49.595727940, 18.870, 615.0, 24.7992
49.639193700, 18.870, 641.0, 25.3180
49.682659460, 18.870, 627.0, 25.0400
49.726125220, 18.870, 571.0, 23.8956
49.769590980, 18.870, 590.0, 24.2899
49.813056740, 18.870, 566.0, 23.7908
49.856522500, 18.870, 573.0, 23.9374
49.899988260, 18.870, 614.0, 24.7790
49.943454020, 18.870, 620.0, 24.8998
49.986919780, 18.870, 608.0, 24.6577
50.030385540, 18.870, 648.0, 25.4558
50.073851300, 18.870, 642.0, 25.3377
50.117317060, 18.870, 659.0, 25.6710
50.160782820, 18.870, 636.0, 25.2190
50.204248580, 18.870, 650.0, 25.4951
50.247714340, 18.870, 556.0, 23.5797
50.291180100, 18.870, 584.0, 24.1661
50.334645860, 18.870, 633.0, 25.1595
50.378111620, 18.870, 603.0, 24.5561
50.421577380, 18.870, 621.0, 24.9199
50.465043140, 18.870, 563.0, 23.7276
50.508508900, 18.870, 649.0, 25.4755
50.551974660, 18.870, 600.0, 24.4949
50.595440420, 18.870, 592.0, 24.3311
50.638906180, 18.870, 593.0, 24.3516
50.682371940, 18.870, 595.0, 24.3926
50.725837700, 18.870, 651.0, 25.5147
50.769303460, 18.870, 622.0, 24.9399
50.812769220, 18.870, 623.0, 24.9600
50.856234980, 18.870, 585.0, 24.1868
50.899700740, 18.870, 627.0, 25.0400
50.943166500, 18.870, 582.0, 24.1247
50.986632260, 18.870, 541.0, 23.2594
51.030098020, 18.870, 610.0, 24.6982
51.073563780, 18.870, 614.0, 24.7790
51.117029540, 18.870, 624.0, 24.9800
51.160495300, 18.870, 626.0, 25.0200
51.203961060, 18.870, 541.0, 23.2594
51.247426820, 18.870, 569.0, 23.8537
51.290892580, 18.870, 609.0, 24.6779
51.334358340, 18.870, 560.0, 23.6643
51.377824100, 18.870, 552.0, 23.4947
51.421289860, 18.870, 541.0, 23.2594
51.464755620, 18.870, 551.0, 23.4734
51.508221380, 18.870, 603.0, 24.5561
51.551687140, 18.870, 652.0, 25.5343
51.595152900, 18.870, 658.0, 25.6515
51.638618660, 18.870, 608.0, 24.6577
51.682084420, 18.870, 625.0, 25.0000
51.725550180, 18.870, 647.0, 25.4362
51.769015940, 18.870, 642.0, 25.3377
51.812481700, 18.870, 609.0, 24.6779
51.855947460, 18.870, 587.0, 24.2281
51.899413220, 18.870, 582.0, 24.1247
51.942878980, 18.870, 582.0, 24.1247
51.986344740, 18.870, 587.0, 24.2281
52.029810500, 18.870, 614.0, 24.7790
52.073276260, 18.870, 577.0, 24.0208
52.116742020, 18.870, 625.0, 25.0000
52.160207780, 18.870, 590.0, 24.2899
52.203673540, 18.870, 600.0, 24.4949
52.247139300, 18.870, 569.0, 23.8537
52.290605060, 18.870, 595.0, 24.3926
52.334070820, 18.870, 612.0, 24.7386
52.377536580, 18.870, 569.0, 23.8537
52.421002340, 18.870, 531.0, 23.0434
52.464468100, 18.870, 588.0, 24.2487
52.507933860, 18.870, 521.0, 22.8254
52.551399620, 18.870, 527.0, 22.9565
52.594865380, 18.870, 559.0, 23.6432
52.638331140, 18.870, 541.0, 23.2594
52.681796900, 18.870, 546.0, 23.3666
52.725262660, 18.870, 532.0, 23.0651
52.768728420, 18.870, 557.0, 23.6008
52.812194180, 18.870, 571.0, 23.8956
52.855659940, 18.870, 567.0, 23.8118
52.899125700, 18.870, 532.0, 23.0651
52.942591460, 18.870, 531.0, 23.0434
52.986057220, 18.870, 588.0, 24.2487
53.029522980, 18.870, 581.0, 24.1039
53.072988740, 18.870, 535.0, 23.1301
53.116454500, 18.870, 529.0, 23.0000
53.159920260, 18.870, 523.0, 22.8692
53.203386020, 18.870, 529.0, 23.0000
53.246851780, 18.870, 463.0, 21.5174
53.290317540, 18.870, 488.0, 22.0907
53.333783300, 18.870, 563.0, 23.7276
53.377249060, 18.870, 536.0, 23.1517
53.420714820, 18.870, 583.0, 24.1454
53.464180580, 18.870, 545.0, 23.3452
53.507646340, 18.870, 546.0, 23.3666
53.551112100, 18.870, 593.0, 24.3516
53.594577860, 18.870, 573.0, 23.9374
53.638043620, 18.870, 586.0, 24.2074
53.681509380, 18.870, 634.0, 25.1794
53.724975140, 18.870, 665.0, 25.7876
53.768440900, 18.870, 641.0, 25.3180
53.811906660, 18.870, 639.0, 25.2784
53.855372420, 18.870, 653.0, 25.5539
53.898838180, 18.870, 669.0, 25.8650
53.942303940, 18.870, 637.0, 25.2389
53.985769700, 18.870, 557.0, 23.6008
54.029235460, 18.870, 578.0, 24.0416
54.072701220, 18.870, 547.0, 23.3880
54.116166980, 18.870, 528.0, 22.9783
54.159632740, 18.870, 523.0, 22.8692
54.203098500, 18.870, 517.0, 22.7376
54.246564260, 18.870, 547.0, 23.3880
54.290030020, 18.870, 508.0, 22.5389
54.333495780, 18.870, 519.0, 22.7816
54.376961540, 18.870, 517.0, 22.7376
54.420427300, 18.870, 519.0, 22.7816
54.463893060, 18.870, 482.0, 21.9545
54.507358820, 18.870, 487.0, 22.0681
54.550824580, 18.870, 493.0, 22.2036
54.594290340, 18.870, 481.0, 21.9317
54.637756100, 18.870, 483.0, 21.9773
54.681221860, 18.870, 506.0, 22.4944
54.724687620, 18.870, 512.0, 22.6274
54.768153380, 18.870, 542.0, 23.2809
54.811619140, 18.870, 464.0, 21.5407
54.855084900, 18.870, 477.0, 21.8403
54.898550660, 18.870, 517.0, 22.7376
54.942016420, 18.870, 459.0, 21.4243
54.985482180, 18.870, 504.0, 22.4499
55.028947940, 18.870, 478.0, 21.8632
55.072413700, 18.870, 518.0, 22.7596
55.115879460, 18.870, 511.0, 22.6053
55.159345220, 18.870, 545.0, 23.3452
55.202810980, 18.870, 504.0, 22.4499
55.246276740, 18.870, 497.0, 22.2935
55.289742500, 18.870, 493.0, 22.2036
55.333208260, 18.870, 493.0, 22.2036
55.376674020, 18.870, 475.0, 21.7945
55.420139780, 18.870, 495.0, 22.2486
55.463605540, 18.870, 503.0, 22.4277
55.507071300, 18.870, 533.0, 23.0868
55.550537060, 18.870, 511.0, 22.6053
55.594002820, 18.870, 479.0, 21.8861
55.637468580, 18.870, 521.0, 22.8254
55.680934340, 18.870, 484.0, 22.0000
55.724400100, 18.870, 501.0, 22.3830
55.767865860, 18.870, 536.0, 23.1517
55.811331620, 18.870, 499.0, 22.3383
55.854797380, 18.870, 539.0, 23.2164
55.898263140, 18.870, 551.0, 23.4734
55.941728900, 18.870, 527.0, 22.9565
55.985194660, 18.870, 505.0, 22.4722
56.028660420, 18.870, 521.0, 22.8254
56.072126180, 18.870, 537.0, 23.1733
56.115591940, 18.870, 476.0, 21.8174
56.159057700, 18.870, 498.0, 22.3159
56.202523460, 18.870, 493.0, 22.2036
56.245989220, 18.870, 495.0, 22.2486
56.289454980, 18.870, 478.0, 21.8632
56.332920740, 18.870, 474.0, 21.7715
56.376386500, 18.870, 491.0, 22.1585
56.419852260, 18.870, 511.0, 22.6053
56.463318020, 18.870, 479.0, 21.8861
56.506783780, 18.870, 520.0, 22.8035
56.550249540, 18.870, 463.0, 21.5174
56.593715300, 18.870, 450.0, 21.2132
56.637181060, 18.870, 491.0, 22.1585
56.680646820, 18.870, 479.0, 21.8861
56.724112580, 18.870, 516.0, 22.7156
56.767578340, 18.870, 508.0, 22.5389
56.811044100, 18.870, 490.0, 22.1359
56.854509860, 18.870, 543.0, 23.3024
56.897975620, 18.870, 518.0, 22.7596
56.941441380, 18.870, 503.0, 22.4277
56.984907140, 18.870, 482.0, 21.9545
57.028372900, 18.870, 481.0, 21.9317
57.071838660, 18.870, 500.0, 22.3607
57.115304420, 18.870, 503.0, 22.4277
57.158770180, 18.870, 501.0, 22.3830
57.202235940, 18.870, 537.0, 23.1733
57.245701700, 18.870, 498.0, 22.3159
57.289167460, 18.870, 522.0, 22.8473
57.332633220, 18.870, 498.0, 22.3159
57.376098980, 18.870, 496.0, 22.2711
57.419564740, 18.870, 521.0, 22.8254
57.463030500, 18.870, 495.0, 22.2486
57.506496260, 18.870, 432.0, 20.7846
57.549962020, 18.870, 504.0, 22.4499
57.593427780, 18.870, 451.0, 21.2368
57.636893540, 18.870, 424.0, 20.5913
57.680359300, 18.870, 440.0, 20.9762
57.723825060, 18.870, 430.0, 20.7364
57.767290820, 18.870, 429.0, 20.7123
57.810756580, 18.870, 382.0, 19.5448
57.854222340, 18.870, 385.0, 19.6214
57.897688100, 18.870, 440.0, 20.9762
57.941153860, 18.870, 454.0, 21.3073
57.984619620, 18.870, 388.0, 19.6977
58.028085380, 18.870, 426.0, 20.6398
58.071551140, 18.870, 413.0, 20.3224
58.115016900, 18.870, 396.0, 19.8997
58.158482660, 18.870, 417.0, 20.4206
58.201948420, 18.870, 462.0, 21.4942
58.245414180, 18.870, 453.0, 21.2838
58.288879940, 18.870, 437.0, 20.9045
58.332345700, 18.870, 409.0, 20.2237
58.375811460, 18.870, 414.0, 20.3470
58.419277220, 18.870, 446.0, 21.1187
58.462742980, 18.870, 413.0, 20.3224
58.506208740, 18.870, 413.0, 20.3224
58.549674500, 18.870, 429.0, 20.7123
58.593140260, 18.870, 401.0, 20.0250
58.636606020, 18.870, 452.0, 21.2603
58.680071780, 18.870, 440.0, 20.9762
58.723537540, 18.870, 457.0, 21.3776
58.767003300, 18.870, 451.0, 21.2368
58.810469060, 18.870, 481.0, 21.9317
58.853934820, 18.870, 509.0, 22.5610
58.897400580, 18.870, 481.0, 21.9317
58.940866340, 18.870, 464.0, 21.5407
58.984332100, 18.870, 437.0, 20.9045
59.027797860, 18.870, 453.0, 21.2838
59.071263620, 18.870, 397.0, 19.9249
59.114729380, 18.870, 447.0, 21.1424
59.158195140, 18.870, 388.0, 19.6977
59.201660900, 18.870, 395.0, 19.8746
59.245126660, 18.870, 430.0, 20.7364
59.288592420, 18.870, 432.0, 20.7846
59.332058180, 18.870, 398.0, 19.9499
59.375523940, 18.870, 462.0, 21.4942
59.418989700, 18.870, 428.0, 20.6882
59.462455460, 18.870, 448.0, 21.1660
59.505921220, 18.870, 470.0, 21.6795
59.549386980, 18.870, 507.0, 22.5167
59.592852740, 18.870, 450.0, 21.2132
59.636318500, 18.870, 459.0, 21.4243
59.679784260, 18.870, 438.0, 20.9284
59.723250020, 18.870, 425.0, 20.6155
59.766715780, 18.870, 440.0, 20.9762
59.810181540, 18.870, 402.0, 20.0499
59.853647300, 18.870, 408.0, 20.1990
59.897113060, 18.870, 386.0, 19.6469
59.940578820, 18.870, 388.0, 19.6977
59.984044580, 18.870, 392.0, 19.7990
59.994911020, 18.870, 445.0, 21.0950