File: XRD/2025_06_03_CBD_10_80_50s.csv
[Measurement conditions]
Sample identification,2025_06_03_CBD_10_80_50s
Comment - 1,"Crystalline CBD Standard"
Anode material,Cu
K-Alpha1 wavelength,1.5405980
K-Alpha2 wavelength,1.5444260
Ratio K-Alpha2/K-Alpha1,0.500
Divergence slit,Fixed,0.76mm
Monochromator used,NO
Generator voltage, 40
Tube current, 15
File date and time,03/Jun/2025 12:56
Unit cell,
h k l, 0 0 0
Scan axis,Gonio
Scan range,10.000000000,80.001606480
Scan step size,0.0108664
No. of points, 6442
Scan type,CONTINUOUS
Time per step,48.195
[Scan points]
Angle, TimePerStep, Intensity, ESD
10.005433220, 48.195, 16658.0, 129.0659
10.059765420, 48.195, 26440.0, 162.6038
10.114097620, 48.195, 40232.0, 200.5792
10.168429820, 48.195, 53938.0, 232.2456
10.222762020, 48.195, 57658.0, 240.1208
10.277094220, 48.195, 49855.0, 223.2823
10.331426420, 48.195, 29272.0, 171.0906
10.385758620, 48.195, 14195.0, 119.1428
10.440090820, 48.195, 6885.0, 82.9759
10.494423020, 48.195, 4278.0, 65.4064
10.548755220, 48.195, 3886.0, 62.3378
10.603087420, 48.195, 3605.0, 60.0417
10.657419620, 48.195, 3386.0, 58.1893
10.711751820, 48.195, 3303.0, 57.4717
10.766084020, 48.195, 3128.0, 55.9285
10.820416220, 48.195, 3111.0, 55.7763
10.874748420, 48.195, 2970.0, 54.4977
10.929080620, 48.195, 3139.0, 56.0268
10.983412820, 48.195, 2892.0, 53.7773
11.037745020, 48.195, 3034.0, 55.0818
11.092077220, 48.195, 3131.0, 55.9553
11.146409420, 48.195, 3069.0, 55.3986
11.200741620, 48.195, 3139.0, 56.0268
11.255073820, 48.195, 3257.0, 57.0701
11.309406020, 48.195, 3657.0, 60.4731
11.363738220, 48.195, 3815.0, 61.7657
11.418070420, 48.195, 4321.0, 65.7343
11.472402620, 48.195, 4795.0, 69.2459
11.526734820, 48.195, 6198.0, 78.7274
11.581067020, 48.195, 9010.0, 94.9210
11.635399220, 48.195, 13796.0, 117.4564
11.689731420, 48.195, 18511.0, 136.0551
11.744063620, 48.195, 17882.0, 133.7236
11.798395820, 48.195, 12760.0, 112.9602
11.852728020, 48.195, 7241.0, 85.0941
11.907060220, 48.195, 4127.0, 64.2417
11.961392420, 48.195, 3547.0, 59.5567
12.015724620, 48.195, 3369.0, 58.0431
12.070056820, 48.195, 3331.0, 57.7148
12.124389020, 48.195, 3480.0, 58.9915
12.178721220, 48.195, 3737.0, 61.1310
12.233053420, 48.195, 4304.0, 65.6049
12.287385620, 48.195, 5438.0, 73.7428
12.341717820, 48.195, 7310.0, 85.4985
12.396050020, 48.195, 8740.0, 93.4880
12.450382220, 48.195, 9455.0, 97.2368
12.504714420, 48.195, 10174.0, 100.8662
12.559046620, 48.195, 9746.0, 98.7218
12.613378820, 48.195, 7131.0, 84.4452
12.667711020, 48.195, 4514.0, 67.1863
12.722043220, 48.195, 4199.0, 64.7997
12.776375420, 48.195, 4499.0, 67.0746
12.830707620, 48.195, 5471.0, 73.9662
12.885039820, 48.195, 6952.0, 83.3787
12.939372020, 48.195, 9881.0, 99.4032
12.993704220, 48.195, 14745.0, 121.4290
13.048036420, 48.195, 20281.0, 142.4114
13.102368620, 48.195, 25394.0, 159.3549
13.156700820, 48.195, 25143.0, 158.5654
13.211033020, 48.195, 18758.0, 136.9598
13.265365220, 48.195, 10472.0, 102.3328
13.319697420, 48.195, 5725.0, 75.6637
13.374029620, 48.195, 4123.0, 64.2106
13.428361820, 48.195, 4295.0, 65.5362
13.482694020, 48.195, 4696.0, 68.5274
13.537026220, 48.195, 5749.0, 75.8222
13.591358420, 48.195, 7654.0, 87.4871
13.645690620, 48.195, 11132.0, 105.5083
13.700022820, 48.195, 13739.0, 117.2135
13.754355020, 48.195, 14771.0, 121.5360
13.808687220, 48.195, 13902.0, 117.9067
13.863019420, 48.195, 9506.0, 97.4987
13.917351620, 48.195, 5095.0, 71.3793
13.971683820, 48.195, 3306.0, 57.4978
14.026016020, 48.195, 2891.0, 53.7680
14.080348220, 48.195, 2725.0, 52.2015
14.134680420, 48.195, 2701.0, 51.9711
14.189012620, 48.195, 2651.0, 51.4879
14.243344820, 48.195, 2582.0, 50.8134
14.297677020, 48.195, 2520.0, 50.1996
14.352009220, 48.195, 2486.0, 49.8598
14.406341420, 48.195, 2630.0, 51.2835
14.460673620, 48.195, 2523.0, 50.2295
14.515005820, 48.195, 2652.0, 51.4976
14.569338020, 48.195, 2866.0, 53.5350
14.623670220, 48.195, 3116.0, 55.8211
14.678002420, 48.195, 3420.0, 58.4808
14.732334620, 48.195, 3760.0, 61.3188
14.786666820, 48.195, 4414.0, 66.4379
14.840999020, 48.195, 5932.0, 77.0195
14.895331220, 48.195, 9210.0, 95.9687
14.949663420, 48.195, 13860.0, 117.7285
15.003995620, 48.195, 18476.0, 135.9265
15.058327820, 48.195, 23305.0, 152.6598
15.112660020, 48.195, 28469.0, 168.7276
15.166992220, 48.195, 23960.0, 154.7902
15.221324420, 48.195, 12965.0, 113.8640
15.275656620, 48.195, 8885.0, 94.2603
15.329988820, 48.195, 9107.0, 95.4306
15.384321020, 48.195, 8852.0, 94.0851
15.438653220, 48.195, 7005.0, 83.6959
15.492985420, 48.195, 4772.0, 69.0797
15.547317620, 48.195, 3458.0, 58.8048
15.601649820, 48.195, 2904.0, 53.8888
15.655982020, 48.195, 2695.0, 51.9134
15.710314220, 48.195, 2838.0, 53.2729
15.764646420, 48.195, 2782.0, 52.7447
15.818978620, 48.195, 2757.0, 52.5071
15.873310820, 48.195, 2872.0, 53.5910
15.927643020, 48.195, 3273.0, 57.2101
15.981975220, 48.195, 3611.0, 60.0916
16.036307420, 48.195, 4073.0, 63.8201
16.090639620, 48.195, 4345.0, 65.9166
16.144971820, 48.195, 3755.0, 61.2781
16.199304020, 48.195, 3219.0, 56.7362
16.253636220, 48.195, 2941.0, 54.2310
16.307968420, 48.195, 2948.0, 54.2955
16.362300620, 48.195, 3222.0, 56.7627
16.416632820, 48.195, 3563.0, 59.6909
16.470965020, 48.195, 4276.0, 65.3911
16.525297220, 48.195, 4728.0, 68.7605
16.579629420, 48.195, 4959.0, 70.4202
16.633961620, 48.195, 4828.0, 69.4838
16.688293820, 48.195, 4652.0, 68.2056
16.742626020, 48.195, 4339.0, 65.8711
16.796958220, 48.195, 4502.0, 67.0969
16.851290420, 48.195, 5433.0, 73.7089
16.905622620, 48.195, 6193.0, 78.6956
16.959954820, 48.195, 7079.0, 84.1368
17.014287020, 48.195, 7144.0, 84.5222
17.068619220, 48.195, 7831.0, 88.4929
17.122951420, 48.195, 9300.0, 96.4365
17.177283620, 48.195, 13530.0, 116.3185
17.231615820, 48.195, 21928.0, 148.0811
17.285948020, 48.195, 37887.0, 194.6458
17.340280220, 48.195, 55567.0, 235.7265
17.394612420, 48.195, 61923.0, 248.8433
17.448944620, 48.195, 43511.0, 208.5929
17.503276820, 48.195, 19164.0, 138.4341
17.557609020, 48.195, 8613.0, 92.8062
17.611941220, 48.195, 5762.0, 75.9078
17.666273420, 48.195, 4852.0, 69.6563
17.720605620, 48.195, 5065.0, 71.1688
17.774937820, 48.195, 5656.0, 75.2064
17.829270020, 48.195, 6889.0, 83.0000
17.883602220, 48.195, 9994.0, 99.9700
17.937934420, 48.195, 14843.0, 121.8319
17.992266620, 48.195, 12980.0, 113.9298
18.046598820, 48.195, 6142.0, 78.3709
18.100931020, 48.195, 4068.0, 63.7809
18.155263220, 48.195, 3861.0, 62.1369
18.209595420, 48.195, 4017.0, 63.3798
18.263927620, 48.195, 4192.0, 64.7457
18.318259820, 48.195, 4300.0, 65.5744
18.372592020, 48.195, 4821.0, 69.4334
18.426924220, 48.195, 5783.0, 76.0460
18.481256420, 48.195, 7680.0, 87.6356
18.535588620, 48.195, 11622.0, 107.8054
18.589920820, 48.195, 18642.0, 136.5357
18.644253020, 48.195, 30215.0, 173.8246
18.698585220, 48.195, 43842.0, 209.3848
18.752917420, 48.195, 55880.0, 236.3895
18.807249620, 48.195, 57278.0, 239.3282
18.861581820, 48.195, 44470.0, 210.8791
18.915914020, 48.195, 29665.0, 172.2353
18.970246220, 48.195, 24026.0, 155.0032
19.024578420, 48.195, 17598.0, 132.6575
19.078910620, 48.195, 11197.0, 105.8159
19.133242820, 48.195, 7922.0, 89.0056
19.187575020, 48.195, 6727.0, 82.0183
19.241907220, 48.195, 5877.0, 76.6616
19.296239420, 48.195, 5989.0, 77.3886
19.350571620, 48.195, 7505.0, 86.6314
19.404903820, 48.195, 10330.0, 101.6366
19.459236020, 48.195, 12772.0, 113.0133
19.513568220, 48.195, 13368.0, 115.6201
19.567900420, 48.195, 10808.0, 103.9615
19.622232620, 48.195, 7710.0, 87.8066
19.676564820, 48.195, 5899.0, 76.8049
19.730897020, 48.195, 5346.0, 73.1163
19.785229220, 48.195, 5166.0, 71.8749
19.839561420, 48.195, 5159.0, 71.8262
19.893893620, 48.195, 4620.0, 67.9706
19.948225820, 48.195, 4322.0, 65.7419
20.002558020, 48.195, 4253.0, 65.2150
20.056890220, 48.195, 4293.0, 65.5210
20.111222420, 48.195, 4534.0, 67.3350
20.165554620, 48.195, 4863.0, 69.7352
20.219886820, 48.195, 5917.0, 76.9220
20.274219020, 48.195, 8067.0, 89.8165
20.328551220, 48.195, 12521.0, 111.8973
20.382883420, 48.195, 20525.0, 143.2655
20.437215620, 48.195, 28969.0, 170.2028
20.491547820, 48.195, 31913.0, 178.6421
20.545880020, 48.195, 31367.0, 177.1073
20.600212220, 48.195, 24872.0, 157.7086
20.654544420, 48.195, 15256.0, 123.5152
20.708876620, 48.195, 9862.0, 99.3076
20.763208820, 48.195, 9261.0, 96.2341
20.817541020, 48.195, 9871.0, 99.3529
20.871873220, 48.195, 9667.0, 98.3209
20.926205420, 48.195, 8607.0, 92.7739
20.980537620, 48.195, 7043.0, 83.9226
21.034869820, 48.195, 5277.0, 72.6430
21.089202020, 48.195, 4260.0, 65.2687
21.143534220, 48.195, 4207.0, 64.8614
21.197866420, 48.195, 4277.0, 65.3988
21.252198620, 48.195, 4539.0, 67.3721
21.306530820, 48.195, 4809.0, 69.3470
21.360863020, 48.195, 5677.0, 75.3459
21.415195220, 48.195, 7705.0, 87.7781
21.469527420, 48.195, 11274.0, 106.1791
21.523859620, 48.195, 16098.0, 126.8779
21.578191820, 48.195, 23278.0, 152.5713
21.632524020, 48.195, 26618.0, 163.1502
21.686856220, 48.195, 24676.0, 157.0860
21.741188420, 48.195, 19036.0, 137.9710
21.795520620, 48.195, 12055.0, 109.7953
21.849852820, 48.195, 10627.0, 103.0873
21.904185020, 48.195, 14772.0, 121.5401
21.958517220, 48.195, 24046.0, 155.0677
22.012849420, 48.195, 40320.0, 200.7984
22.067181620, 48.195, 53909.0, 232.1831
22.121513820, 48.195, 62400.0, 249.7999
22.175846020, 48.195, 57518.0, 239.8291
22.230178220, 48.195, 51482.0, 226.8965
22.284510420, 48.195, 31135.0, 176.4511
22.338842620, 48.195, 12456.0, 111.6065
22.393174820, 48.195, 7027.0, 83.8272
22.447507020, 48.195, 7735.0, 87.9488
22.501839220, 48.195, 11017.0, 104.9619
22.556171420, 48.195, 15891.0, 126.0595
22.610503620, 48.195, 19011.0, 137.8804
22.664835820, 48.195, 21808.0, 147.6753
22.719168020, 48.195, 21364.0, 146.1643
22.773500220, 48.195, 16787.0, 129.5647
22.827832420, 48.195, 10952.0, 104.6518
22.882164620, 48.195, 8050.0, 89.7218
22.936496820, 48.195, 7538.0, 86.8217
22.990829020, 48.195, 7329.0, 85.6096
23.045161220, 48.195, 6745.0, 82.1279
23.099493420, 48.195, 5980.0, 77.3305
23.153825620, 48.195, 5049.0, 71.0563
23.208157820, 48.195, 4741.0, 68.8549
23.262490020, 48.195, 4603.0, 67.8454
23.316822220, 48.195, 4563.0, 67.5500
23.371154420, 48.195, 4500.0, 67.0820
23.425486620, 48.195, 4635.0, 68.0808
23.479818820, 48.195, 5718.0, 75.6175
23.534151020, 48.195, 7815.0, 88.4025
23.588483220, 48.195, 9573.0, 97.8417
23.642815420, 48.195, 10255.0, 101.2670
23.697147620, 48.195, 10109.0, 100.5435
23.751479820, 48.195, 10603.0, 102.9709
23.805812020, 48.195, 10049.0, 100.2447
23.860144220, 48.195, 7997.0, 89.4259
23.914476420, 48.195, 6367.0, 79.7935
23.968808620, 48.195, 5122.0, 71.5681
24.023140820, 48.195, 4278.0, 65.4064
24.077473020, 48.195, 4071.0, 63.8044
24.131805220, 48.195, 4313.0, 65.6734
24.186137420, 48.195, 5307.0, 72.8492
24.240469620, 48.195, 6663.0, 81.6272
24.294801820, 48.195, 7939.0, 89.1011
24.349134020, 48.195, 8489.0, 92.1358
24.403466220, 48.195, 9025.0, 95.0000
24.457798420, 48.195, 9035.0, 95.0526
24.512130620, 48.195, 6968.0, 83.4745
24.566462820, 48.195, 5567.0, 74.6123
24.620795020, 48.195, 5499.0, 74.1552
24.675127220, 48.195, 5779.0, 76.0197
24.729459420, 48.195, 5739.0, 75.7562
24.783791620, 48.195, 4997.0, 70.6895
24.838123820, 48.195, 4131.0, 64.2729
24.892456020, 48.195, 3755.0, 61.2781
24.946788220, 48.195, 3677.0, 60.6383
25.001120420, 48.195, 4079.0, 63.8670
25.055452620, 48.195, 4904.0, 70.0286
25.109784820, 48.195, 6113.0, 78.1857
25.164117020, 48.195, 7467.0, 86.4118
25.218449220, 48.195, 8058.0, 89.7664
25.272781420, 48.195, 8223.0, 90.6808
25.327113620, 48.195, 7363.0, 85.8079
25.381445820, 48.195, 6401.0, 80.0062
25.435778020, 48.195, 5814.0, 76.2496
25.490110220, 48.195, 5817.0, 76.2693
25.544442420, 48.195, 5806.0, 76.1971
25.598774620, 48.195, 4912.0, 70.0857
25.653106820, 48.195, 4161.0, 64.5058
25.707439020, 48.195, 3651.0, 60.4235
25.761771220, 48.195, 3322.0, 57.6368
25.816103420, 48.195, 3179.0, 56.3826
25.870435620, 48.195, 3187.0, 56.4535
25.924767820, 48.195, 3212.0, 56.6745
25.979100020, 48.195, 3251.0, 57.0175
26.033432220, 48.195, 3625.0, 60.2080
26.087764420, 48.195, 4266.0, 65.3146
26.142096620, 48.195, 5192.0, 72.0555
26.196428820, 48.195, 6368.0, 79.7997
26.250761020, 48.195, 7247.0, 85.1293
26.305093220, 48.195, 7846.0, 88.5776
26.359425420, 48.195, 8473.0, 92.0489
26.413757620, 48.195, 8176.0, 90.4212
26.468089820, 48.195, 7117.0, 84.3623
26.522422020, 48.195, 6587.0, 81.1603
26.576754220, 48.195, 6337.0, 79.6053
26.631086420, 48.195, 5676.0, 75.3392
26.685418620, 48.195, 5183.0, 71.9931
26.739750820, 48.195, 4797.0, 69.2604
26.794083020, 48.195, 4333.0, 65.8255
26.848415220, 48.195, 3937.0, 62.7455
26.902747420, 48.195, 4070.0, 63.7966
26.957079620, 48.195, 4697.0, 68.5347
27.011411820, 48.195, 4836.0, 69.5414
27.065744020, 48.195, 5147.0, 71.7426
27.120076220, 48.195, 5478.0, 74.0135
27.174408420, 48.195, 5339.0, 73.0685
27.228740620, 48.195, 4782.0, 69.1520
27.283072820, 48.195, 4785.0, 69.1737
27.337405020, 48.195, 5029.0, 70.9154
27.391737220, 48.195, 5449.0, 73.8173
27.446069420, 48.195, 6343.0, 79.6430
27.500401620, 48.195, 8105.0, 90.0278
27.554733820, 48.195, 8747.0, 93.5254
27.609066020, 48.195, 8362.0, 91.4440
27.663398220, 48.195, 8140.0, 90.2219
27.717730420, 48.195, 7662.0, 87.5329
27.772062620, 48.195, 6013.0, 77.5435
27.826394820, 48.195, 4675.0, 68.3740
27.880727020, 48.195, 3904.0, 62.4820
27.935059220, 48.195, 3616.0, 60.1332
27.989391420, 48.195, 3462.0, 58.8388
28.043723620, 48.195, 3570.0, 59.7495
28.098055820, 48.195, 3570.0, 59.7495
28.152388020, 48.195, 3578.0, 59.8164
28.206720220, 48.195, 3643.0, 60.3573
28.261052420, 48.195, 3877.0, 62.2656
28.315384620, 48.195, 4085.0, 63.9140
28.369716820, 48.195, 4017.0, 63.3798
28.424049020, 48.195, 4239.0, 65.1076
28.478381220, 48.195, 4394.0, 66.2873
28.532713420, 48.195, 4469.0, 66.8506
28.587045620, 48.195, 4806.0, 69.3253
28.641377820, 48.195, 5167.0, 71.8818
28.695710020, 48.195, 4738.0, 68.8331
28.750042220, 48.195, 4450.0, 66.7083
28.804374420, 48.195, 4534.0, 67.3350
28.858706620, 48.195, 5220.0, 72.2496
28.913038820, 48.195, 6603.0, 81.2588
28.967371020, 48.195, 7394.0, 85.9884
29.021703220, 48.195, 8412.0, 91.7170
29.076035420, 48.195, 8494.0, 92.1629
29.130367620, 48.195, 7865.0, 88.6848
29.184699820, 48.195, 6137.0, 78.3390
29.239032020, 48.195, 4653.0, 68.2129
29.293364220, 48.195, 3755.0, 61.2781
29.347696420, 48.195, 3621.0, 60.1747
29.402028620, 48.195, 3770.0, 61.4003
29.456360820, 48.195, 3577.0, 59.8080
29.510693020, 48.195, 3613.0, 60.1082
29.565025220, 48.195, 3324.0, 57.6541
29.619357420, 48.195, 2930.0, 54.1295
29.673689620, 48.195, 2629.0, 51.2738
29.728021820, 48.195, 2572.0, 50.7149
29.782354020, 48.195, 2325.0, 48.2183
29.836686220, 48.195, 2418.0, 49.1732
29.891018420, 48.195, 2434.0, 49.3356
29.945350620, 48.195, 2338.0, 48.3529
29.999682820, 48.195, 2316.0, 48.1248
30.054015020, 48.195, 2487.0, 49.8698
30.108347220, 48.195, 2448.0, 49.4773
30.162679420, 48.195, 2564.0, 50.6360
30.217011620, 48.195, 2751.0, 52.4500
30.271343820, 48.195, 2956.0, 54.3691
30.325676020, 48.195, 3066.0, 55.3715
30.380008220, 48.195, 3407.0, 58.3695
30.434340420, 48.195, 3553.0, 59.6070
30.488672620, 48.195, 3694.0, 60.7783
30.543004820, 48.195, 3622.0, 60.1831
30.597337020, 48.195, 3623.0, 60.1914
30.651669220, 48.195, 3597.0, 59.9750
30.706001420, 48.195, 3546.0, 59.5483
30.760333620, 48.195, 3511.0, 59.2537
30.814665820, 48.195, 3190.0, 56.4801
30.868998020, 48.195, 3086.0, 55.5518
30.923330220, 48.195, 3211.0, 56.6657
30.977662420, 48.195, 3603.0, 60.0250
31.031994620, 48.195, 4085.0, 63.9140
31.086326820, 48.195, 4346.0, 65.9242
31.140659020, 48.195, 4478.0, 66.9179
31.194991220, 48.195, 4344.0, 65.9090
31.249323420, 48.195, 3999.0, 63.2376
31.303655620, 48.195, 3500.0, 59.1608
31.357987820, 48.195, 3019.0, 54.9454
31.412320020, 48.195, 2688.0, 51.8459
31.466652220, 48.195, 2411.0, 49.1019
31.520984420, 48.195, 2231.0, 47.2335
31.575316620, 48.195, 2233.0, 47.2546
31.629648820, 48.195, 2270.0, 47.6445
31.683981020, 48.195, 2228.0, 47.2017
31.738313220, 48.195, 2201.0, 46.9148
31.792645420, 48.195, 2209.0, 47.0000
31.846977620, 48.195, 2339.0, 48.3632
31.901309820, 48.195, 2442.0, 49.4166
31.955642020, 48.195, 2647.0, 51.4490
32.009974220, 48.195, 2631.0, 51.2933
32.064306420, 48.195, 2652.0, 51.4976
32.118638620, 48.195, 2694.0, 51.9038
32.172970820, 48.195, 2579.0, 50.7839
32.227303020, 48.195, 2481.0, 49.8096
32.281635220, 48.195, 2506.0, 50.0600
32.335967420, 48.195, 2690.0, 51.8652
32.390299620, 48.195, 2845.0, 53.3385
32.444631820, 48.195, 3286.0, 57.3236
32.498964020, 48.195, 3867.0, 62.1852
32.553296220, 48.195, 4027.0, 63.4586
32.607628420, 48.195, 3534.0, 59.4475
32.661960620, 48.195, 3188.0, 56.4624
32.716292820, 48.195, 2842.0, 53.3104
32.770625020, 48.195, 2611.0, 51.0979
32.824957220, 48.195, 2669.0, 51.6624
32.879289420, 48.195, 2834.0, 53.2353
32.933621620, 48.195, 2847.0, 53.3573
32.987953820, 48.195, 2776.0, 52.6878
33.042286020, 48.195, 2688.0, 51.8459
33.096618220, 48.195, 2839.0, 53.2823
33.150950420, 48.195, 2808.0, 52.9906
33.205282620, 48.195, 2889.0, 53.7494
33.259614820, 48.195, 2991.0, 54.6900
33.313947020, 48.195, 2935.0, 54.1756
33.368279220, 48.195, 2647.0, 51.4490
33.422611420, 48.195, 2573.0, 50.7247
33.476943620, 48.195, 2438.0, 49.3761
33.531275820, 48.195, 2461.0, 49.6085
33.585608020, 48.195, 2520.0, 50.1996
33.639940220, 48.195, 2524.0, 50.2394
33.694272420, 48.195, 2545.0, 50.4480
33.748604620, 48.195, 2692.0, 51.8845
33.802936820, 48.195, 2978.0, 54.5711
33.857269020, 48.195, 3934.0, 62.7216
33.911601220, 48.195, 4577.0, 67.6535
33.965933420, 48.195, 4825.0, 69.4622
34.020265620, 48.195, 4857.0, 69.6922
34.074597820, 48.195, 4260.0, 65.2687
34.128930020, 48.195, 3461.0, 58.8303
34.183262220, 48.195, 3078.0, 55.4797
34.237594420, 48.195, 2891.0, 53.7680
34.291926620, 48.195, 2935.0, 54.1756
34.346258820, 48.195, 3008.0, 54.8452
34.400591020, 48.195, 2976.0, 54.5527
34.454923220, 48.195, 3109.0, 55.7584
34.509255420, 48.195, 3373.0, 58.0775
34.563587620, 48.195, 3586.0, 59.8832
34.617919820, 48.195, 4331.0, 65.8103
34.672252020, 48.195, 4798.0, 69.2676
34.726584220, 48.195, 5386.0, 73.3894
34.780916420, 48.195, 5410.0, 73.5527
34.835248620, 48.195, 6066.0, 77.8845
34.889580820, 48.195, 5414.0, 73.5799
34.943913020, 48.195, 4626.0, 68.0147
34.998245220, 48.195, 3900.0, 62.4500
35.052577420, 48.195, 3634.0, 60.2827
35.106909620, 48.195, 3901.0, 62.4580
35.161241820, 48.195, 4138.0, 64.3273
35.215574020, 48.195, 4081.0, 63.8827
35.269906220, 48.195, 4228.0, 65.0231
35.324238420, 48.195, 3562.0, 59.6825
35.378570620, 48.195, 3093.0, 55.6147
35.432902820, 48.195, 2758.0, 52.5167
35.487235020, 48.195, 2706.0, 52.0192
35.541567220, 48.195, 2674.0, 51.7107
35.595899420, 48.195, 2535.0, 50.3488
35.650231620, 48.195, 2500.0, 50.0000
35.704563820, 48.195, 2385.0, 48.8365
35.758896020, 48.195, 2469.0, 49.6890
35.813228220, 48.195, 2502.0, 50.0200
35.867560420, 48.195, 2498.0, 49.9800
35.921892620, 48.195, 2413.0, 49.1223
35.976224820, 48.195, 2233.0, 47.2546
36.030557020, 48.195, 2222.0, 47.1381
36.084889220, 48.195, 2165.0, 46.5296
36.139221420, 48.195, 2158.0, 46.4543
36.193553620, 48.195, 2272.0, 47.6655
36.247885820, 48.195, 2262.0, 47.5605
36.302218020, 48.195, 2467.0, 49.6689
36.356550220, 48.195, 2578.0, 50.7740
36.410882420, 48.195, 2700.0, 51.9615
36.465214620, 48.195, 2898.0, 53.8331
36.519546820, 48.195, 3231.0, 56.8419
36.573879020, 48.195, 3287.0, 57.3324
36.628211220, 48.195, 3060.0, 55.3173
36.682543420, 48.195, 2883.0, 53.6936
36.736875620, 48.195, 2793.0, 52.8488
36.791207820, 48.195, 2751.0, 52.4500
36.845540020, 48.195, 3103.0, 55.7046
36.899872220, 48.195, 2935.0, 54.1756
36.954204420, 48.195, 2988.0, 54.6626
37.008536620, 48.195, 2935.0, 54.1756
37.062868820, 48.195, 2771.0, 52.6403
37.117201020, 48.195, 2711.0, 52.0673
37.171533220, 48.195, 2628.0, 51.2640
37.225865420, 48.195, 2547.0, 50.4678
37.280197620, 48.195, 2463.0, 49.6286
37.334529820, 48.195, 2366.0, 48.6415
37.388862020, 48.195, 2516.0, 50.1597
37.443194220, 48.195, 2441.0, 49.4065
37.497526420, 48.195, 2415.0, 49.1426
37.551858620, 48.195, 2333.0, 48.3011
37.606190820, 48.195, 2516.0, 50.1597
37.660523020, 48.195, 2619.0, 51.1762
37.714855220, 48.195, 2659.0, 51.5655
37.769187420, 48.195, 2733.0, 52.2781
37.823519620, 48.195, 2692.0, 51.8845
37.877851820, 48.195, 2752.0, 52.4595
37.932184020, 48.195, 2735.0, 52.2972
37.986516220, 48.195, 2996.0, 54.7357
38.040848420, 48.195, 3309.0, 57.5239
38.095180620, 48.195, 3325.0, 57.6628
38.149512820, 48.195, 3173.0, 56.3294
38.203845020, 48.195, 2849.0, 53.3760
38.258177220, 48.195, 2441.0, 49.4065
38.312509420, 48.195, 2308.0, 48.0416
38.366841620, 48.195, 2233.0, 47.2546
38.421173820, 48.195, 2262.0, 47.5605
38.475506020, 48.195, 2276.0, 47.7074
38.529838220, 48.195, 2160.0, 46.4758
38.584170420, 48.195, 2233.0, 47.2546
38.638502620, 48.195, 2107.0, 45.9021
38.692834820, 48.195, 2076.0, 45.5631
38.747167020, 48.195, 2164.0, 46.5188
38.801499220, 48.195, 2172.0, 46.6047
38.855831420, 48.195, 2184.0, 46.7333
38.910163620, 48.195, 2193.0, 46.8295
38.964495820, 48.195, 2451.0, 49.5076
39.018828020, 48.195, 2451.0, 49.5076
39.073160220, 48.195, 2401.0, 49.0000
39.127492420, 48.195, 2404.0, 49.0306
39.181824620, 48.195, 2384.0, 48.8262
39.236156820, 48.195, 2448.0, 49.4773
39.290489020, 48.195, 2715.0, 52.1057
39.344821220, 48.195, 2470.0, 49.6991
39.399153420, 48.195, 2418.0, 49.1732
39.453485620, 48.195, 2291.0, 47.8644
39.507817820, 48.195, 2134.0, 46.1952
39.562150020, 48.195, 2218.0, 47.0956
39.616482220, 48.195, 2312.0, 48.0833
39.670814420, 48.195, 2299.0, 47.9479
39.725146620, 48.195, 2202.0, 46.9255
39.779478820, 48.195, 2201.0, 46.9148
39.833811020, 48.195, 1996.0, 44.6766
39.888143220, 48.195, 1972.0, 44.4072
39.942475420, 48.195, 1869.0, 43.2319
39.996807620, 48.195, 2130.0, 46.1519
40.051139820, 48.195, 2213.0, 47.0425
40.105472020, 48.195, 2482.0, 49.8197
40.159804220, 48.195, 2666.0, 51.6333
40.214136420, 48.195, 2954.0, 54.3507
40.268468620, 48.195, 3101.0, 55.6866
40.322800820, 48.195, 2952.0, 54.3323
40.377133020, 48.195, 2848.0, 53.3667
40.431465220, 48.195, 2982.0, 54.6077
40.485797420, 48.195, 3113.0, 55.7943
40.540129620, 48.195, 2874.0, 53.6097
40.594461820, 48.195, 2797.0, 52.8867
40.648794020, 48.195, 2537.0, 50.3686
40.703126220, 48.195, 2254.0, 47.4763
40.757458420, 48.195, 2171.0, 46.5940
40.811790620, 48.195, 2114.0, 45.9783
40.866122820, 48.195, 2141.0, 46.2709
40.920455020, 48.195, 2230.0, 47.2229
40.974787220, 48.195, 2143.0, 46.2925
41.029119420, 48.195, 1951.0, 44.1701
41.083451620, 48.195, 1942.0, 44.0681
41.137783820, 48.195, 1967.0, 44.3509
41.192116020, 48.195, 1915.0, 43.7607
41.246448220, 48.195, 1918.0, 43.7950
41.300780420, 48.195, 1888.0, 43.4511
41.355112620, 48.195, 1952.0, 44.1814
41.409444820, 48.195, 1921.0, 43.8292
41.463777020, 48.195, 2059.0, 45.3762
41.518109220, 48.195, 2117.0, 46.0109
41.572441420, 48.195, 2107.0, 45.9021
41.626773620, 48.195, 2302.0, 47.9792
41.681105820, 48.195, 2577.0, 50.7642
41.735438020, 48.195, 2722.0, 52.1728
41.789770220, 48.195, 2820.0, 53.1037
41.844102420, 48.195, 2646.0, 51.4393
41.898434620, 48.195, 2458.0, 49.5782
41.952766820, 48.195, 2251.0, 47.4447
42.007099020, 48.195, 1995.0, 44.6654
42.061431220, 48.195, 1981.0, 44.5084
42.115763420, 48.195, 2009.0, 44.8219
42.170095620, 48.195, 2087.0, 45.6837
42.224427820, 48.195, 2065.0, 45.4423
42.278760020, 48.195, 2261.0, 47.5500
42.333092220, 48.195, 2461.0, 49.6085
42.387424420, 48.195, 2636.0, 51.3420
42.441756620, 48.195, 2839.0, 53.2823
42.496088820, 48.195, 2900.0, 53.8516
42.550421020, 48.195, 2872.0, 53.5910
42.604753220, 48.195, 2856.0, 53.4416
42.659085420, 48.195, 2790.0, 52.8205
42.713417620, 48.195, 2685.0, 51.8170
42.767749820, 48.195, 2628.0, 51.2640
42.822082020, 48.195, 2446.0, 49.4571
42.876414220, 48.195, 2384.0, 48.8262
42.930746420, 48.195, 2196.0, 46.8615
42.985078620, 48.195, 2174.0, 46.6262
43.039410820, 48.195, 2180.0, 46.6905
43.093743020, 48.195, 2432.0, 49.3153
43.148075220, 48.195, 2565.0, 50.6458
43.202407420, 48.195, 2644.0, 51.4198
43.256739620, 48.195, 2760.0, 52.5357
43.311071820, 48.195, 2601.0, 51.0000
43.365404020, 48.195, 2666.0, 51.6333
43.419736220, 48.195, 2452.0, 49.5177
43.474068420, 48.195, 2451.0, 49.5076
43.528400620, 48.195, 2297.0, 47.9270
43.582732820, 48.195, 2102.0, 45.8476
43.637065020, 48.195, 2056.0, 45.3431
43.691397220, 48.195, 2133.0, 46.1844
43.745729420, 48.195, 2061.0, 45.3982
43.800061620, 48.195, 1965.0, 44.3283
43.854393820, 48.195, 1831.0, 42.7902
43.908726020, 48.195, 1806.0, 42.4971
43.963058220, 48.195, 1819.0, 42.6497
44.017390420, 48.195, 1713.0, 41.3884
44.071722620, 48.195, 1823.0, 42.6966
44.126054820, 48.195, 1859.0, 43.1161
44.180387020, 48.195, 1963.0, 44.3058
44.234719220, 48.195, 1952.0, 44.1814
44.289051420, 48.195, 2055.0, 45.3321
44.343383620, 48.195, 2046.0, 45.2327
44.397715820, 48.195, 1926.0, 43.8862
44.452048020, 48.195, 1844.0, 42.9418
44.506380220, 48.195, 1832.0, 42.8019
44.560712420, 48.195, 1881.0, 43.3705
44.615044620, 48.195, 1792.0, 42.3320
44.669376820, 48.195, 1864.0, 43.1741
44.723709020, 48.195, 1854.0, 43.0581
44.778041220, 48.195, 1884.0, 43.4051
44.832373420, 48.195, 2004.0, 44.7661
44.886705620, 48.195, 2074.0, 45.5412
44.941037820, 48.195, 2290.0, 47.8539
44.995370020, 48.195, 2476.0, 49.7594
45.049702220, 48.195, 2488.0, 49.8799
45.104034420, 48.195, 2424.0, 49.2341
45.158366620, 48.195, 2195.0, 46.8508
45.212698820, 48.195, 2201.0, 46.9148
45.267031020, 48.195, 2258.0, 47.5184
45.321363220, 48.195, 2179.0, 46.6798
45.375695420, 48.195, 2196.0, 46.8615
45.430027620, 48.195, 2014.0, 44.8776
45.484359820, 48.195, 2024.0, 44.9889
45.538692020, 48.195, 1896.0, 43.5431
45.593024220, 48.195, 1852.0, 43.0349
45.647356420, 48.195, 1896.0, 43.5431
45.701688620, 48.195, 2085.0, 45.6618
45.756020820, 48.195, 2095.0, 45.7712
45.810353020, 48.195, 2055.0, 45.3321
45.864685220, 48.195, 2077.0, 45.5741
45.919017420, 48.195, 2150.0, 46.3681
45.973349620, 48.195, 2124.0, 46.0869
46.027681820, 48.195, 2100.0, 45.8258
46.082014020, 48.195, 2217.0, 47.0850
46.136346220, 48.195, 2086.0, 45.6727
46.190678420, 48.195, 2033.0, 45.0888
46.245010620, 48.195, 2105.0, 45.8803
46.299342820, 48.195, 2034.0, 45.0999
46.353675020, 48.195, 2185.0, 46.7440
46.408007220, 48.195, 2056.0, 45.3431
46.462339420, 48.195, 2171.0, 46.5940
46.516671620, 48.195, 2064.0, 45.4313
46.571003820, 48.195, 2173.0, 46.6154
46.625336020, 48.195, 2264.0, 47.5815
46.679668220, 48.195, 2278.0, 47.7284
46.734000420, 48.195, 2352.0, 48.4974
46.788332620, 48.195, 2327.0, 48.2390
46.842664820, 48.195, 2177.0, 46.6583
46.896997020, 48.195, 2038.0, 45.1442
46.951329220, 48.195, 1909.0, 43.6921
47.005661420, 48.195, 1913.0, 43.7379
47.059993620, 48.195, 1923.0, 43.8520
47.114325820, 48.195, 1788.0, 42.2847
47.168658020, 48.195, 1800.0, 42.4264
47.222990220, 48.195, 1820.0, 42.6615
47.277322420, 48.195, 1742.0, 41.7373
47.331654620, 48.195, 1785.0, 42.2493
47.385986820, 48.195, 1784.0, 42.2374
47.440319020, 48.195, 1861.0, 43.1393
47.494651220, 48.195, 2052.0, 45.2990
47.548983420, 48.195, 2350.0, 48.4768
47.603315620, 48.195, 2347.0, 48.4458
47.657647820, 48.195, 2304.0, 48.0000
47.711980020, 48.195, 2054.0, 45.3211
47.766312220, 48.195, 1904.0, 43.6348
47.820644420, 48.195, 1828.0, 42.7551
47.874976620, 48.195, 1798.0, 42.4028
47.929308820, 48.195, 1802.0, 42.4500
47.983641020, 48.195, 1853.0, 43.0465
48.037973220, 48.195, 1758.0, 41.9285
48.092305420, 48.195, 1851.0, 43.0232
48.146637620, 48.195, 1836.0, 42.8486
48.200969820, 48.195, 1789.0, 42.2966
48.255302020, 48.195, 1727.0, 41.5572
48.309634220, 48.195, 1692.0, 41.1339
48.363966420, 48.195, 1725.0, 41.5331
48.418298620, 48.195, 1663.0, 40.7799
48.472630820, 48.195, 1653.0, 40.6571
48.526963020, 48.195, 1535.0, 39.1791
48.581295220, 48.195, 1621.0, 40.2616
48.635627420, 48.195, 1575.0, 39.6863
48.689959620, 48.195, 1612.0, 40.1497
48.744291820, 48.195, 1676.0, 40.9390
48.798624020, 48.195, 1782.0, 42.2137
48.852956220, 48.195, 1779.0, 42.1782
48.907288420, 48.195, 1876.0, 43.3128
48.961620620, 48.195, 1794.0, 42.3556
49.015952820, 48.195, 1893.0, 43.5086
49.070285020, 48.195, 1820.0, 42.6615
49.124617220, 48.195, 1912.0, 43.7264
49.178949420, 48.195, 1942.0, 44.0681
49.233281620, 48.195, 2072.0, 45.5192
49.287613820, 48.195, 2217.0, 47.0850
49.341946020, 48.195, 2204.0, 46.9468
49.396278220, 48.195, 1990.0, 44.6094
49.450610420, 48.195, 1952.0, 44.1814
49.504942620, 48.195, 1788.0, 42.2847
49.559274820, 48.195, 1758.0, 41.9285
49.613607020, 48.195, 1735.0, 41.6533
49.667939220, 48.195, 1672.0, 40.8901
49.722271420, 48.195, 1652.0, 40.6448
49.776603620, 48.195, 1564.0, 39.5474
49.830935820, 48.195, 1656.0, 40.6940
49.885268020, 48.195, 1752.0, 41.8569
49.939600220, 48.195, 1827.0, 42.7434
49.993932420, 48.195, 1862.0, 43.1509
50.048264620, 48.195, 1980.0, 44.4972
50.102596820, 48.195, 2000.0, 44.7214
50.156929020, 48.195, 1900.0, 43.5890
50.211261220, 48.195, 1861.0, 43.1393
50.265593420, 48.195, 1713.0, 41.3884
50.319925620, 48.195, 1702.0, 41.2553
50.374257820, 48.195, 1738.0, 41.6893
50.428590020, 48.195, 1796.0, 42.3792
50.482922220, 48.195, 1735.0, 41.6533
50.537254420, 48.195, 1717.0, 41.4367
50.591586620, 48.195, 1663.0, 40.7799
50.645918820, 48.195, 1722.0, 41.4970
50.700251020, 48.195, 1636.0, 40.4475
50.754583220, 48.195, 1613.0, 40.1622
50.808915420, 48.195, 1586.0, 39.8246
50.863247620, 48.195, 1590.0, 39.8748
50.917579820, 48.195, 1502.0, 38.7556
50.971912020, 48.195, 1504.0, 38.7814
51.026244220, 48.195, 1491.0, 38.6135
51.080576420, 48.195, 1507.0, 38.8201
51.134908620, 48.195, 1475.0, 38.4057
51.189240820, 48.195, 1423.0, 37.7227
51.243573020, 48.195, 1424.0, 37.7359
51.297905220, 48.195, 1417.0, 37.6431
51.352237420, 48.195, 1420.0, 37.6829
51.406569620, 48.195, 1483.0, 38.5097
51.460901820, 48.195, 1487.0, 38.5616
51.515234020, 48.195, 1494.0, 38.6523
51.569566220, 48.195, 1513.0, 38.8973
51.623898420, 48.195, 1512.0, 38.8844
51.678230620, 48.195, 1655.0, 40.6817
51.732562820, 48.195, 1705.0, 41.2916
51.786895020, 48.195, 1672.0, 40.8901
51.841227220, 48.195, 1813.0, 42.5793
51.895559420, 48.195, 1677.0, 40.9512
51.949891620, 48.195, 1669.0, 40.8534
52.004223820, 48.195, 1786.0, 42.2611
52.058556020, 48.195, 1809.0, 42.5323
52.112888220, 48.195, 1816.0, 42.6146
52.167220420, 48.195, 1821.0, 42.6732
52.221552620, 48.195, 1633.0, 40.4104
52.275884820, 48.195, 1558.0, 39.4715
52.330217020, 48.195, 1545.0, 39.3065
52.384549220, 48.195, 1522.0, 39.0128
52.438881420, 48.195, 1484.0, 38.5227
52.493213620, 48.195, 1467.0, 38.3014
52.547545820, 48.195, 1488.0, 38.5746
52.601878020, 48.195, 1477.0, 38.4318
52.656210220, 48.195, 1533.0, 39.1535
52.710542420, 48.195, 1570.0, 39.6232
52.764874620, 48.195, 1538.0, 39.2173
52.819206820, 48.195, 1578.0, 39.7240
52.873539020, 48.195, 1615.0, 40.1871
52.927871220, 48.195, 1576.0, 39.6989
52.982203420, 48.195, 1570.0, 39.6232
53.036535620, 48.195, 1520.0, 38.9872
53.090867820, 48.195, 1387.0, 37.2424
53.145200020, 48.195, 1352.0, 36.7696
53.199532220, 48.195, 1335.0, 36.5377
53.253864420, 48.195, 1373.0, 37.0540
53.308196620, 48.195, 1363.0, 36.9188
53.362528820, 48.195, 1416.0, 37.6298
53.416861020, 48.195, 1391.0, 37.2961
53.471193220, 48.195, 1412.0, 37.5766
53.525525420, 48.195, 1415.0, 37.6165
53.579857620, 48.195, 1381.0, 37.1618
53.634189820, 48.195, 1452.0, 38.1051
53.688522020, 48.195, 1449.0, 38.0657
53.742854220, 48.195, 1366.0, 36.9594
53.797186420, 48.195, 1370.0, 37.0135
53.851518620, 48.195, 1358.0, 36.8511
53.905850820, 48.195, 1327.0, 36.4280
53.960183020, 48.195, 1301.0, 36.0694
54.014515220, 48.195, 1299.0, 36.0416
54.068847420, 48.195, 1465.0, 38.2753
54.123179620, 48.195, 1412.0, 37.5766
54.177511820, 48.195, 1472.0, 38.3667
54.231844020, 48.195, 1450.0, 38.0789
54.286176220, 48.195, 1447.0, 38.0395
54.340508420, 48.195, 1361.0, 36.8917
54.394840620, 48.195, 1328.0, 36.4417
54.449172820, 48.195, 1350.0, 36.7423
54.503505020, 48.195, 1299.0, 36.0416
54.557837220, 48.195, 1348.0, 36.7151
54.612169420, 48.195, 1288.0, 35.8887
54.666501620, 48.195, 1353.0, 36.7831
54.720833820, 48.195, 1319.0, 36.3180
54.775166020, 48.195, 1317.0, 36.2905
54.829498220, 48.195, 1310.0, 36.1939
54.883830420, 48.195, 1407.0, 37.5100
54.938162620, 48.195, 1397.0, 37.3765
54.992494820, 48.195, 1417.0, 37.6431
55.046827020, 48.195, 1448.0, 38.0526
55.101159220, 48.195, 1341.0, 36.6197
55.155491420, 48.195, 1249.0, 35.3412
55.209823620, 48.195, 1360.0, 36.8782
55.264155820, 48.195, 1268.0, 35.6090
55.318488020, 48.195, 1357.0, 36.8375
55.372820220, 48.195, 1263.0, 35.5387
55.427152420, 48.195, 1339.0, 36.5923
55.481484620, 48.195, 1319.0, 36.3180
55.535816820, 48.195, 1327.0, 36.4280
55.590149020, 48.195, 1341.0, 36.6197
55.644481220, 48.195, 1393.0, 37.3229
55.698813420, 48.195, 1314.0, 36.2491
55.753145620, 48.195, 1396.0, 37.3631
55.807477820, 48.195, 1411.0, 37.5633
55.861810020, 48.195, 1400.0, 37.4166
55.916142220, 48.195, 1279.0, 35.7631
55.970474420, 48.195, 1310.0, 36.1939
56.024806620, 48.195, 1341.0, 36.6197
56.079138820, 48.195, 1261.0, 35.5106
56.133471020, 48.195, 1243.0, 35.2562
56.187803220, 48.195, 1243.0, 35.2562
56.242135420, 48.195, 1211.0, 34.7994
56.296467620, 48.195, 1241.0, 35.2278
56.350799820, 48.195, 1171.0, 34.2199
56.405132020, 48.195, 1196.0, 34.5832
56.459464220, 48.195, 1204.0, 34.6987
56.513796420, 48.195, 1129.0, 33.6006
56.568128620, 48.195, 1190.0, 34.4964
56.622460820, 48.195, 1194.0, 34.5543
56.676793020, 48.195, 1174.0, 34.2637
56.731125220, 48.195, 1124.0, 33.5261
56.785457420, 48.195, 1206.0, 34.7275
56.839789620, 48.195, 1122.0, 33.4963
56.894121820, 48.195, 1111.0, 33.3317
56.948454020, 48.195, 1259.0, 35.4824
57.002786220, 48.195, 1262.0, 35.5246
57.057118420, 48.195, 1268.0, 35.6090
57.111450620, 48.195, 1251.0, 35.3695
57.165782820, 48.195, 1175.0, 34.2783
57.220115020, 48.195, 1186.0, 34.4384
57.274447220, 48.195, 1206.0, 34.7275
57.328779420, 48.195, 1185.0, 34.4238
57.383111620, 48.195, 1202.0, 34.6699
57.437443820, 48.195, 1154.0, 33.9706
57.491776020, 48.195, 1135.0, 33.6898
57.546108220, 48.195, 1180.0, 34.3511
57.600440420, 48.195, 1134.0, 33.6749
57.654772620, 48.195, 1057.0, 32.5115
57.709104820, 48.195, 1092.0, 33.0454
57.763437020, 48.195, 1116.0, 33.4066
57.817769220, 48.195, 1044.0, 32.3110
57.872101420, 48.195, 1074.0, 32.7719
57.926433620, 48.195, 1093.0, 33.0606
57.980765820, 48.195, 1112.0, 33.3467
58.035098020, 48.195, 1103.0, 33.2114
58.089430220, 48.195, 1196.0, 34.5832
58.143762420, 48.195, 1108.0, 33.2866
58.198094620, 48.195, 1124.0, 33.5261
58.252426820, 48.195, 1135.0, 33.6898
58.306759020, 48.195, 1141.0, 33.7787
58.361091220, 48.195, 1100.0, 33.1662
58.415423420, 48.195, 1132.0, 33.6452
58.469755620, 48.195, 1071.0, 32.7261
58.524087820, 48.195, 1114.0, 33.3766
58.578420020, 48.195, 1205.0, 34.7131
58.632752220, 48.195, 1228.0, 35.0428
58.687084420, 48.195, 1223.0, 34.9714
58.741416620, 48.195, 1149.0, 33.8969
58.795748820, 48.195, 1170.0, 34.2053
58.850081020, 48.195, 1116.0, 33.4066
58.904413220, 48.195, 1139.0, 33.7491
58.958745420, 48.195, 1119.0, 33.4515
59.013077620, 48.195, 1097.0, 33.1210
59.067409820, 48.195, 1036.0, 32.1870
59.121742020, 48.195, 1196.0, 34.5832
59.176074220, 48.195, 1017.0, 31.8904
59.230406420, 48.195, 1139.0, 33.7491
59.284738620, 48.195, 1101.0, 33.1813
59.339070820, 48.195, 1107.0, 33.2716
59.393403020, 48.195, 1211.0, 34.7994
59.447735220, 48.195, 1119.0, 33.4515
59.502067420, 48.195, 1101.0, 33.1813
59.556399620, 48.195, 1081.0, 32.8786
59.610731820, 48.195, 1093.0, 33.0606
59.665064020, 48.195, 1034.0, 32.1559
59.719396220, 48.195, 1149.0, 33.8969
59.773728420, 48.195, 1074.0, 32.7719
59.828060620, 48.195, 1050.0, 32.4037
59.882392820, 48.195, 1108.0, 33.2866
59.936725020, 48.195, 1080.0, 32.8634
59.991057220, 48.195, 980.0, 31.3050
60.045389420, 48.195, 1005.0, 31.7017
60.099721620, 48.195, 957.0, 30.9354
60.154053820, 48.195, 1005.0, 31.7017
60.208386020, 48.195, 972.0, 31.1769
60.262718220, 48.195, 1026.0, 32.0312
60.317050420, 48.195, 994.0, 31.5278
60.371382620, 48.195, 977.0, 31.2570
60.425714820, 48.195, 1016.0, 31.8748
60.480047020, 48.195, 1102.0, 33.1964
60.534379220, 48.195, 1035.0, 32.1714
60.588711420, 48.195, 1004.0, 31.6860
60.643043620, 48.195, 1017.0, 31.8904
60.697375820, 48.195, 1016.0, 31.8748
60.751708020, 48.195, 1060.0, 32.5576
60.806040220, 48.195, 1012.0, 31.8119
60.860372420, 48.195, 993.0, 31.5119
60.914704620, 48.195, 1040.0, 32.2490
60.969036820, 48.195, 1136.0, 33.7046
61.023369020, 48.195, 1023.0, 31.9844
61.077701220, 48.195, 1062.0, 32.5883
61.132033420, 48.195, 1073.0, 32.7567
61.186365620, 48.195, 1073.0, 32.7567
61.240697820, 48.195, 1067.0, 32.6650
61.295030020, 48.195, 1041.0, 32.2645
61.349362220, 48.195, 1040.0, 32.2490
61.403694420, 48.195, 1013.0, 31.8277
61.458026620, 48.195, 1065.0, 32.6343
61.512358820, 48.195, 964.0, 31.0483
61.566691020, 48.195, 1121.0, 33.4813
61.621023220, 48.195, 1055.0, 32.4808
61.675355420, 48.195, 968.0, 31.1127
61.729687620, 48.195, 1073.0, 32.7567
61.784019820, 48.195, 970.0, 31.1448
61.838352020, 48.195, 944.0, 30.7246
61.892684220, 48.195, 1020.0, 31.9374
61.947016420, 48.195, 962.0, 31.0161
62.001348620, 48.195, 987.0, 31.4166
62.055680820, 48.195, 950.0, 30.8221
62.110013020, 48.195, 960.0, 30.9839
62.164345220, 48.195, 972.0, 31.1769
62.218677420, 48.195, 961.0, 31.0000
62.273009620, 48.195, 1016.0, 31.8748
62.327341820, 48.195, 1049.0, 32.3883
62.381674020, 48.195, 1036.0, 32.1870
62.436006220, 48.195, 1000.0, 31.6228
62.490338420, 48.195, 1050.0, 32.4037
62.544670620, 48.195, 1006.0, 31.7175
62.599002820, 48.195, 974.0, 31.2090
62.653335020, 48.195, 1008.0, 31.7490
62.707667220, 48.195, 939.0, 30.6431
62.761999420, 48.195, 962.0, 31.0161
62.816331620, 48.195, 1015.0, 31.8591
62.870663820, 48.195, 1068.0, 32.6803
62.924996020, 48.195, 955.0, 30.9031
62.979328220, 48.195, 964.0, 31.0483
63.033660420, 48.195, 947.0, 30.7734
63.087992620, 48.195, 975.0, 31.2250
63.142324820, 48.195, 970.0, 31.1448
63.196657020, 48.195, 1015.0, 31.8591
63.250989220, 48.195, 952.0, 30.8545
63.305321420, 48.195, 944.0, 30.7246
63.359653620, 48.195, 948.0, 30.7896
63.413985820, 48.195, 978.0, 31.2730
63.468318020, 48.195, 965.0, 31.0644
63.522650220, 48.195, 965.0, 31.0644
63.576982420, 48.195, 957.0, 30.9354
63.631314620, 48.195, 984.0, 31.3688
63.685646820, 48.195, 956.0, 30.9192
63.739979020, 48.195, 1009.0, 31.7648
63.794311220, 48.195, 938.0, 30.6268
63.848643420, 48.195, 956.0, 30.9192
63.902975620, 48.195, 963.0, 31.0322
63.957307820, 48.195, 918.0, 30.2985
64.011640020, 48.195, 932.0, 30.5287
64.065972220, 48.195, 919.0, 30.3150
64.120304420, 48.195, 932.0, 30.5287
64.174636620, 48.195, 974.0, 31.2090
64.228968820, 48.195, 918.0, 30.2985
64.283301020, 48.195, 915.0, 30.2490
64.337633220, 48.195, 887.0, 29.7825
64.391965420, 48.195, 921.0, 30.3480
64.446297620, 48.195, 945.0, 30.7409
64.500629820, 48.195, 864.0, 29.3939
64.554962020, 48.195, 925.0, 30.4138
64.609294220, 48.195, 924.0, 30.3974
64.663626420, 48.195, 914.0, 30.2324
64.717958620, 48.195, 889.0, 29.8161
64.772290820, 48.195, 889.0, 29.8161
64.826623020, 48.195, 876.0, 29.5973
64.880955220, 48.195, 937.0, 30.6105
64.935287420, 48.195, 882.0, 29.6985
64.989619620, 48.195, 882.0, 29.6985
65.043951820, 48.195, 903.0, 30.0500
65.098284020, 48.195, 914.0, 30.2324
65.152616220, 48.195, 883.0, 29.7153
65.206948420, 48.195, 908.0, 30.1330
65.261280620, 48.195, 937.0, 30.6105
65.315612820, 48.195, 908.0, 30.1330
65.369945020, 48.195, 933.0, 30.5450
65.424277220, 48.195, 940.0, 30.6594
65.478609420, 48.195, 925.0, 30.4138
65.532941620, 48.195, 872.0, 29.5296
65.587273820, 48.195, 898.0, 29.9666
65.641606020, 48.195, 909.0, 30.1496
65.695938220, 48.195, 890.0, 29.8329
65.750270420, 48.195, 928.0, 30.4631
65.804602620, 48.195, 837.0, 28.9310
65.858934820, 48.195, 914.0, 30.2324
65.913267020, 48.195, 891.0, 29.8496
65.967599220, 48.195, 869.0, 29.4788
66.021931420, 48.195, 896.0, 29.9333
66.076263620, 48.195, 884.0, 29.7321
66.130595820, 48.195, 814.0, 28.5307
66.184928020, 48.195, 885.0, 29.7489
66.239260220, 48.195, 951.0, 30.8383
66.293592420, 48.195, 825.0, 28.7228
66.347924620, 48.195, 849.0, 29.1376
66.402256820, 48.195, 854.0, 29.2233
66.456589020, 48.195, 893.0, 29.8831
66.510921220, 48.195, 875.0, 29.5804
66.565253420, 48.195, 908.0, 30.1330
66.619585620, 48.195, 917.0, 30.2820
66.673917820, 48.195, 859.0, 29.3087
66.728250020, 48.195, 866.0, 29.4279
66.782582220, 48.195, 900.0, 30.0000
66.836914420, 48.195, 872.0, 29.5296
66.891246620, 48.195, 946.0, 30.7571
66.945578820, 48.195, 974.0, 31.2090
66.999911020, 48.195, 883.0, 29.7153
67.054243220, 48.195, 910.0, 30.1662
67.108575420, 48.195, 954.0, 30.8869
67.162907620, 48.195, 878.0, 29.6311
67.217239820, 48.195, 888.0, 29.7993
67.271572020, 48.195, 859.0, 29.3087
67.325904220, 48.195, 905.0, 30.0832
67.380236420, 48.195, 853.0, 29.2062
67.434568620, 48.195, 867.0, 29.4449
67.488900820, 48.195, 912.0, 30.1993
67.543233020, 48.195, 833.0, 28.8617
67.597565220, 48.195, 852.0, 29.1890
67.651897420, 48.195, 894.0, 29.8998
67.706229620, 48.195, 874.0, 29.5635
67.760561820, 48.195, 870.0, 29.4958
67.814894020, 48.195, 847.0, 29.1033
67.869226220, 48.195, 796.0, 28.2135
67.923558420, 48.195, 880.0, 29.6648
67.977890620, 48.195, 900.0, 30.0000
68.032222820, 48.195, 899.0, 29.9833
68.086555020, 48.195, 872.0, 29.5296
68.140887220, 48.195, 883.0, 29.7153
68.195219420, 48.195, 900.0, 30.0000
68.249551620, 48.195, 886.0, 29.7658
68.303883820, 48.195, 875.0, 29.5804
68.358216020, 48.195, 860.0, 29.3258
68.412548220, 48.195, 806.0, 28.3901
68.466880420, 48.195, 850.0, 29.1548
68.521212620, 48.195, 839.0, 28.9655
68.575544820, 48.195, 901.0, 30.0167
68.629877020, 48.195, 813.0, 28.5132
68.684209220, 48.195, 826.0, 28.7402
68.738541420, 48.195, 890.0, 29.8329
68.792873620, 48.195, 889.0, 29.8161
68.847205820, 48.195, 883.0, 29.7153
68.901538020, 48.195, 880.0, 29.6648
68.955870220, 48.195, 844.0, 29.0517
69.010202420, 48.195, 851.0, 29.1719
69.064534620, 48.195, 862.0, 29.3598
69.118866820, 48.195, 901.0, 30.0167
69.173199020, 48.195, 877.0, 29.6142
69.227531220, 48.195, 817.0, 28.5832
69.281863420, 48.195, 837.0, 28.9310
69.336195620, 48.195, 829.0, 28.7924
69.390527820, 48.195, 854.0, 29.2233
69.444860020, 48.195, 832.0, 28.8444
69.499192220, 48.195, 851.0, 29.1719
69.553524420, 48.195, 808.0, 28.4253
69.607856620, 48.195, 784.0, 28.0000
69.662188820, 48.195, 807.0, 28.4077
69.716521020, 48.195, 826.0, 28.7402
69.770853220, 48.195, 861.0, 29.3428
69.825185420, 48.195, 843.0, 29.0345
69.879517620, 48.195, 814.0, 28.5307
69.933849820, 48.195, 871.0, 29.5127
69.988182020, 48.195, 847.0, 29.1033
70.042514220, 48.195, 880.0, 29.6648
70.096846420, 48.195, 878.0, 29.6311
70.151178620, 48.195, 818.0, 28.6007
70.205510820, 48.195, 796.0, 28.2135
70.259843020, 48.195, 767.0, 27.6948
70.314175220, 48.195, 888.0, 29.7993
70.368507420, 48.195, 873.0, 29.5466
70.422839620, 48.195, 850.0, 29.1548
70.477171820, 48.195, 896.0, 29.9333
70.531504020, 48.195, 784.0, 28.0000
70.585836220, 48.195, 823.0, 28.6880
70.640168420, 48.195, 837.0, 28.9310
70.694500620, 48.195, 811.0, 28.4781
70.748832820, 48.195, 808.0, 28.4253
70.803165020, 48.195, 847.0, 29.1033
70.857497220, 48.195, 840.0, 28.9828
70.911829420, 48.195, 847.0, 29.1033
70.966161620, 48.195, 854.0, 29.2233
71.020493820, 48.195, 876.0, 29.5973
71.074826020, 48.195, 843.0, 29.0345
71.129158220, 48.195, 875.0, 29.5804
71.183490420, 48.195, 741.0, 27.2213
71.237822620, 48.195, 780.0, 27.9285
71.292154820, 48.195, 842.0, 29.0172
71.346487020, 48.195, 837.0, 28.9310
71.400819220, 48.195, 772.0, 27.7849
71.455151420, 48.195, 836.0, 28.9137
71.509483620, 48.195, 807.0, 28.4077
71.563815820, 48.195, 792.0, 28.1425
71.618148020, 48.195, 850.0, 29.1548
71.672480220, 48.195, 784.0, 28.0000
71.726812420, 48.195, 832.0, 28.8444
71.781144620, 48.195, 813.0, 28.5132
71.835476820, 48.195, 827.0, 28.7576
71.889809020, 48.195, 766.0, 27.6767
71.944141220, 48.195, 791.0, 28.1247
71.998473420, 48.195, 814.0, 28.5307
72.052805620, 48.195, 845.0, 29.0689
72.107137820, 48.195, 873.0, 29.5466
72.161470020, 48.195, 806.0, 28.3901
72.215802220, 48.195, 872.0, 29.5296
72.270134420, 48.195, 858.0, 29.2916
72.324466620, 48.195, 850.0, 29.1548
72.378798820, 48.195, 872.0, 29.5296
72.433131020, 48.195, 809.0, 28.4429
72.487463220, 48.195, 812.0, 28.4956
72.541795420, 48.195, 849.0, 29.1376
72.596127620, 48.195, 879.0, 29.6479
72.650459820, 48.195, 811.0, 28.4781
72.704792020, 48.195, 815.0, 28.5482
72.759124220, 48.195, 772.0, 27.7849
72.813456420, 48.195, 866.0, 29.4279
72.867788620, 48.195, 914.0, 30.2324
72.922120820, 48.195, 845.0, 29.0689
72.976453020, 48.195, 817.0, 28.5832
73.030785220, 48.195, 814.0, 28.5307
73.085117420, 48.195, 832.0, 28.8444
73.139449620, 48.195, 806.0, 28.3901
73.193781820, 48.195, 845.0, 29.0689
73.248114020, 48.195, 846.0, 29.0861
73.302446220, 48.195, 848.0, 29.1204
73.356778420, 48.195, 887.0, 29.7825
73.411110620, 48.195, 898.0, 29.9666
73.465442820, 48.195, 901.0, 30.0167
73.519775020, 48.195, 843.0, 29.0345
73.574107220, 48.195, 821.0, 28.6531
73.628439420, 48.195, 900.0, 30.0000
73.682771620, 48.195, 818.0, 28.6007
73.737103820, 48.195, 805.0, 28.3725
73.791436020, 48.195, 813.0, 28.5132
73.845768220, 48.195, 861.0, 29.3428
73.900100420, 48.195, 761.0, 27.5862
73.954432620, 48.195, 871.0, 29.5127
74.008764820, 48.195, 820.0, 28.6356
74.063097020, 48.195, 790.0, 28.1069
74.117429220, 48.195, 826.0, 28.7402
74.171761420, 48.195, 789.0, 28.0891
74.226093620, 48.195, 793.0, 28.1603
74.280425820, 48.195, 826.0, 28.7402
74.334758020, 48.195, 786.0, 28.0357
74.389090220, 48.195, 825.0, 28.7228
74.443422420, 48.195, 824.0, 28.7054
74.497754620, 48.195, 829.0, 28.7924
74.552086820, 48.195, 816.0, 28.5657
74.606419020, 48.195, 779.0, 27.9106
74.660751220, 48.195, 776.0, 27.8568
74.715083420, 48.195, 803.0, 28.3373
74.769415620, 48.195, 783.0, 27.9821
74.823747820, 48.195, 792.0, 28.1425
74.878080020, 48.195, 818.0, 28.6007
74.932412220, 48.195, 747.0, 27.3313
74.986744420, 48.195, 804.0, 28.3549
75.041076620, 48.195, 804.0, 28.3549
75.095408820, 48.195, 825.0, 28.7228
75.149741020, 48.195, 794.0, 28.1780
75.204073220, 48.195, 804.0, 28.3549
75.258405420, 48.195, 799.0, 28.2666
75.312737620, 48.195, 857.0, 29.2746
75.367069820, 48.195, 838.0, 28.9482
75.421402020, 48.195, 804.0, 28.3549
75.475734220, 48.195, 820.0, 28.6356
75.530066420, 48.195, 852.0, 29.1890
75.584398620, 48.195, 806.0, 28.3901
75.638730820, 48.195, 780.0, 27.9285
75.693063020, 48.195, 795.0, 28.1957
75.747395220, 48.195, 785.0, 28.0179
75.801727420, 48.195, 801.0, 28.3019
75.856059620, 48.195, 827.0, 28.7576
75.910391820, 48.195, 806.0, 28.3901
75.964724020, 48.195, 827.0, 28.7576
76.019056220, 48.195, 806.0, 28.3901
76.073388420, 48.195, 831.0, 28.8271
76.127720620, 48.195, 781.0, 27.9464
76.182052820, 48.195, 777.0, 27.8747
76.236385020, 48.195, 839.0, 28.9655
76.290717220, 48.195, 812.0, 28.4956
76.345049420, 48.195, 768.0, 27.7128
76.399381620, 48.195, 811.0, 28.4781
76.453713820, 48.195, 810.0, 28.4605
76.508046020, 48.195, 807.0, 28.4077
76.562378220, 48.195, 782.0, 27.9643
76.616710420, 48.195, 800.0, 28.2843
76.671042620, 48.195, 835.0, 28.8964
76.725374820, 48.195, 796.0, 28.2135
76.779707020, 48.195, 812.0, 28.4956
76.834039220, 48.195, 786.0, 28.0357
76.888371420, 48.195, 824.0, 28.7054
76.942703620, 48.195, 858.0, 29.2916
76.997035820, 48.195, 805.0, 28.3725
77.051368020, 48.195, 809.0, 28.4429
77.105700220, 48.195, 838.0, 28.9482
77.160032420, 48.195, 896.0, 29.9333
77.214364620, 48.195, 830.0, 28.8097
77.268696820, 48.195, 846.0, 29.0861
77.323029020, 48.195, 863.0, 29.3769
77.377361220, 48.195, 854.0, 29.2233
77.431693420, 48.195, 818.0, 28.6007
77.486025620, 48.195, 802.0, 28.3196
77.540357820, 48.195, 831.0, 28.8271
77.594690020, 48.195, 795.0, 28.1957
77.649022220, 48.195, 855.0, 29.2404
77.703354420, 48.195, 763.0, 27.6225
77.757686620, 48.195, 848.0, 29.1204
77.812018820, 48.195, 790.0, 28.1069
77.866351020, 48.195, 828.0, 28.7750
77.920683220, 48.195, 808.0, 28.4253
77.975015420, 48.195, 824.0, 28.7054
78.029347620, 48.195, 850.0, 29.1548
78.083679820, 48.195, 812.0, 28.4956
78.138012020, 48.195, 798.0, 28.2489
78.192344220, 48.195, 835.0, 28.8964
78.246676420, 48.195, 887.0, 29.7825
78.301008620, 48.195, 776.0, 27.8568
78.355340820, 48.195, 775.0, 27.8388
78.409673020, 48.195, 797.0, 28.2312
78.464005220, 48.195, 791.0, 28.1247
78.518337420, 48.195, 819.0, 28.6182
78.572669620, 48.195, 800.0, 28.2843
78.627001820, 48.195, 769.0, 27.7308
78.681334020, 48.195, 804.0, 28.3549
78.735666220, 48.195, 813.0, 28.5132
78.789998420, 48.195, 772.0, 27.7849
78.844330620, 48.195, 792.0, 28.1425
78.898662820, 48.195, 740.0, 27.2029
78.952995020, 48.195, 832.0, 28.8444
79.007327220, 48.195, 802.0, 28.3196
79.061659420, 48.195, 807.0, 28.4077
79.115991620, 48.195, 793.0, 28.1603
79.170323820, 48.195, 798.0, 28.2489
79.224656020, 48.195, 806.0, 28.3901
79.278988220, 48.195, 819.0, 28.6182
79.333320420, 48.195, 783.0, 27.9821
79.387652620, 48.195, 853.0, 29.2062
79.441984820, 48.195, 765.0, 27.6586
79.496317020, 48.195, 788.0, 28.0713
79.550649220, 48.195, 808.0, 28.4253
79.604981420, 48.195, 834.0, 28.8791
79.659313620, 48.195, 853.0, 29.2062
79.713645820, 48.195, 869.0, 29.4788
79.767978020, 48.195, 843.0, 29.0345
79.822310220, 48.195, 802.0, 28.3196
79.876642420, 48.195, 790.0, 28.1069
79.930974620, 48.195, 862.0, 29.3598
79.985306820, 48.195, 768.0, 27.7128
79.996173260, 48.195, 829.0, 28.7924