File: XRD/2025_06_03_CBD_Sorbic_Acid_Slurry.csv
[Measurement conditions]
Sample identification,2025_06_03_CBD_Sorbic_Acid_Slurry
Comment - 1,"CBD - Sorbic Acid Cocrystal, Slurry Method, 5/9/25, JL."
Anode material,Cu
K-Alpha1 wavelength,1.5405980
K-Alpha2 wavelength,1.5444260
Ratio K-Alpha2/K-Alpha1,0.500
Divergence slit,Fixed,0.76mm
Monochromator used,NO
Generator voltage, 40
Tube current, 15
File date and time,03/Jun/2025 13:42
Unit cell,
h k l, 0 0 0
Scan axis,Gonio
Scan range,10.000000000,80.001606480
Scan step size,0.0108664
No. of points, 6442
Scan type,CONTINUOUS
Time per step,48.195
[Scan points]
Angle, TimePerStep, Intensity, ESD
10.005433220, 48.195, 1697.0, 41.1947
10.059765420, 48.195, 1770.0, 42.0714
10.114097620, 48.195, 1953.0, 44.1928
10.168429820, 48.195, 2053.0, 45.3100
10.222762020, 48.195, 2258.0, 47.5184
10.277094220, 48.195, 2601.0, 51.0000
10.331426420, 48.195, 2826.0, 53.1601
10.385758620, 48.195, 3153.0, 56.1516
10.440090820, 48.195, 3684.0, 60.6960
10.494423020, 48.195, 4137.0, 64.3195
10.548755220, 48.195, 4265.0, 65.3070
10.603087420, 48.195, 4039.0, 63.5531
10.657419620, 48.195, 3527.0, 59.3886
10.711751820, 48.195, 2914.0, 53.9815
10.766084020, 48.195, 2525.0, 50.2494
10.820416220, 48.195, 2650.0, 51.4782
10.874748420, 48.195, 3086.0, 55.5518
10.929080620, 48.195, 3511.0, 59.2537
10.983412820, 48.195, 4063.0, 63.7417
11.037745020, 48.195, 4750.0, 68.9202
11.092077220, 48.195, 5107.0, 71.4633
11.146409420, 48.195, 5159.0, 71.8262
11.200741620, 48.195, 5478.0, 74.0135
11.255073820, 48.195, 6314.0, 79.4607
11.309406020, 48.195, 6963.0, 83.4446
11.363738220, 48.195, 7629.0, 87.3441
11.418070420, 48.195, 7638.0, 87.3957
11.472402620, 48.195, 7237.0, 85.0706
11.526734820, 48.195, 6859.0, 82.8191
11.581067020, 48.195, 6790.0, 82.4015
11.635399220, 48.195, 6486.0, 80.5357
11.689731420, 48.195, 5512.0, 74.2428
11.744063620, 48.195, 4320.0, 65.7267
11.798395820, 48.195, 3157.0, 56.1872
11.852728020, 48.195, 2465.0, 49.6488
11.907060220, 48.195, 2470.0, 49.6991
11.961392420, 48.195, 2726.0, 52.2111
12.015724620, 48.195, 3144.0, 56.0714
12.070056820, 48.195, 3733.0, 61.0983
12.124389020, 48.195, 4397.0, 66.3099
12.178721220, 48.195, 5040.0, 70.9930
12.233053420, 48.195, 5229.0, 72.3118
12.287385620, 48.195, 4680.0, 68.4105
12.341717820, 48.195, 3737.0, 61.1310
12.396050020, 48.195, 3049.0, 55.2178
12.450382220, 48.195, 2717.0, 52.1249
12.504714420, 48.195, 2630.0, 51.2835
12.559046620, 48.195, 2632.0, 51.3030
12.613378820, 48.195, 2431.0, 49.3052
12.667711020, 48.195, 2296.0, 47.9166
12.722043220, 48.195, 2081.0, 45.6180
12.776375420, 48.195, 2054.0, 45.3211
12.830707620, 48.195, 2147.0, 46.3357
12.885039820, 48.195, 2151.0, 46.3789
12.939372020, 48.195, 2067.0, 45.4643
12.993704220, 48.195, 1996.0, 44.6766
13.048036420, 48.195, 1817.0, 42.6263
13.102368620, 48.195, 1604.0, 40.0500
13.156700820, 48.195, 1659.0, 40.7308
13.211033020, 48.195, 1564.0, 39.5474
13.265365220, 48.195, 1562.0, 39.5221
13.319697420, 48.195, 1655.0, 40.6817
13.374029620, 48.195, 1672.0, 40.8901
13.428361820, 48.195, 1651.0, 40.6325
13.482694020, 48.195, 1743.0, 41.7493
13.537026220, 48.195, 1739.0, 41.7013
13.591358420, 48.195, 1741.0, 41.7253
13.645690620, 48.195, 1762.0, 41.9762
13.700022820, 48.195, 1527.0, 39.0768
13.754355020, 48.195, 1537.0, 39.2046
13.808687220, 48.195, 1345.0, 36.6742
13.863019420, 48.195, 1411.0, 37.5633
13.917351620, 48.195, 1442.0, 37.9737
13.971683820, 48.195, 1412.0, 37.5766
14.026016020, 48.195, 1479.0, 38.4578
14.080348220, 48.195, 1527.0, 39.0768
14.134680420, 48.195, 1637.0, 40.4599
14.189012620, 48.195, 1732.0, 41.6173
14.243344820, 48.195, 1800.0, 42.4264
14.297677020, 48.195, 1922.0, 43.8406
14.352009220, 48.195, 2053.0, 45.3100
14.406341420, 48.195, 2398.0, 48.9694
14.460673620, 48.195, 2783.0, 52.7541
14.515005820, 48.195, 3118.0, 55.8391
14.569338020, 48.195, 3403.0, 58.3352
14.623670220, 48.195, 3675.0, 60.6218
14.678002420, 48.195, 3689.0, 60.7371
14.732334620, 48.195, 3453.0, 58.7622
14.786666820, 48.195, 2941.0, 54.2310
14.840999020, 48.195, 2523.0, 50.2295
14.895331220, 48.195, 2369.0, 48.6724
14.949663420, 48.195, 2560.0, 50.5964
15.003995620, 48.195, 3109.0, 55.7584
15.058327820, 48.195, 3752.0, 61.2536
15.112660020, 48.195, 4530.0, 67.3053
15.166992220, 48.195, 4857.0, 69.6922
15.221324420, 48.195, 5193.0, 72.0625
15.275656620, 48.195, 5067.0, 71.1829
15.329988820, 48.195, 4896.0, 69.9714
15.384321020, 48.195, 5066.0, 71.1758
15.438653220, 48.195, 5910.0, 76.8765
15.492985420, 48.195, 7755.0, 88.0625
15.547317620, 48.195, 10154.0, 100.7671
15.601649820, 48.195, 12271.0, 110.7745
15.655982020, 48.195, 13405.0, 115.7800
15.710314220, 48.195, 12999.0, 114.0132
15.764646420, 48.195, 10991.0, 104.8380
15.818978620, 48.195, 8167.0, 90.3715
15.873310820, 48.195, 5331.0, 73.0137
15.927643020, 48.195, 3734.0, 61.1065
15.981975220, 48.195, 3458.0, 58.8048
16.036307420, 48.195, 3748.0, 61.2209
16.090639620, 48.195, 4520.0, 67.2309
16.144971820, 48.195, 5588.0, 74.7529
16.199304020, 48.195, 6411.0, 80.0687
16.253636220, 48.195, 6999.0, 83.6600
16.307968420, 48.195, 7209.0, 84.9058
16.362300620, 48.195, 7029.0, 83.8391
16.416632820, 48.195, 6404.0, 80.0250
16.470965020, 48.195, 5803.0, 76.1774
16.525297220, 48.195, 5517.0, 74.2765
16.579629420, 48.195, 5091.0, 71.3512
16.633961620, 48.195, 4803.0, 69.3037
16.688293820, 48.195, 4117.0, 64.1639
16.742626020, 48.195, 3681.0, 60.6712
16.796958220, 48.195, 3301.0, 57.4543
16.851290420, 48.195, 3116.0, 55.8211
16.905622620, 48.195, 3247.0, 56.9825
16.959954820, 48.195, 3478.0, 58.9746
17.014287020, 48.195, 4143.0, 64.3661
17.068619220, 48.195, 5083.0, 71.2952
17.122951420, 48.195, 5894.0, 76.7724
17.177283620, 48.195, 6911.0, 83.1324
17.231615820, 48.195, 7338.0, 85.6621
17.285948020, 48.195, 7213.0, 84.9294
17.340280220, 48.195, 6817.0, 82.5651
17.394612420, 48.195, 5883.0, 76.7007
17.448944620, 48.195, 4810.0, 69.3542
17.503276820, 48.195, 3640.0, 60.3324
17.557609020, 48.195, 2957.0, 54.3783
17.611941220, 48.195, 2589.0, 50.8822
17.666273420, 48.195, 2402.0, 49.0102
17.720605620, 48.195, 2389.0, 48.8774
17.774937820, 48.195, 2446.0, 49.4571
17.829270020, 48.195, 2422.0, 49.2138
17.883602220, 48.195, 2618.0, 51.1664
17.937934420, 48.195, 2705.0, 52.0096
17.992266620, 48.195, 2797.0, 52.8867
18.046598820, 48.195, 2759.0, 52.5262
18.100931020, 48.195, 2996.0, 54.7357
18.155263220, 48.195, 3589.0, 59.9083
18.209595420, 48.195, 4362.0, 66.0454
18.263927620, 48.195, 5419.0, 73.6139
18.318259820, 48.195, 6701.0, 81.8596
18.372592020, 48.195, 8155.0, 90.3050
18.426924220, 48.195, 9750.0, 98.7421
18.481256420, 48.195, 11360.0, 106.5833
18.535588620, 48.195, 13105.0, 114.4771
18.589920820, 48.195, 14394.0, 119.9750
18.644253020, 48.195, 14136.0, 118.8949
18.698585220, 48.195, 12955.0, 113.8200
18.752917420, 48.195, 11457.0, 107.0374
18.807249620, 48.195, 9221.0, 96.0260
18.861581820, 48.195, 7636.0, 87.3842
18.915914020, 48.195, 7101.0, 84.2674
18.970246220, 48.195, 7381.0, 85.9127
19.024578420, 48.195, 8073.0, 89.8499
19.078910620, 48.195, 8674.0, 93.1343
19.133242820, 48.195, 9099.0, 95.3887
19.187575020, 48.195, 9122.0, 95.5092
19.241907220, 48.195, 8602.0, 92.7470
19.296239420, 48.195, 8149.0, 90.2718
19.350571620, 48.195, 7443.0, 86.2728
19.404903820, 48.195, 6324.0, 79.5236
19.459236020, 48.195, 4975.0, 70.5337
19.513568220, 48.195, 3995.0, 63.2060
19.567900420, 48.195, 3234.0, 56.8683
19.622232620, 48.195, 2980.0, 54.5894
19.676564820, 48.195, 2922.0, 54.0555
19.730897020, 48.195, 3075.0, 55.4527
19.785229220, 48.195, 3326.0, 57.6715
19.839561420, 48.195, 3597.0, 59.9750
19.893893620, 48.195, 3661.0, 60.5062
19.948225820, 48.195, 3684.0, 60.6960
20.002558020, 48.195, 3418.0, 58.4637
20.056890220, 48.195, 3090.0, 55.5878
20.111222420, 48.195, 2936.0, 54.1849
20.165554620, 48.195, 3175.0, 56.3471
20.219886820, 48.195, 3370.0, 58.0517
20.274219020, 48.195, 3777.0, 61.4573
20.328551220, 48.195, 4095.0, 63.9922
20.382883420, 48.195, 4544.0, 67.4092
20.437215620, 48.195, 5711.0, 75.5712
20.491547820, 48.195, 7007.0, 83.7078
20.545880020, 48.195, 8455.0, 91.9511
20.600212220, 48.195, 9214.0, 95.9896
20.654544420, 48.195, 10035.0, 100.1748
20.708876620, 48.195, 9870.0, 99.3479
20.763208820, 48.195, 9392.0, 96.9123
20.817541020, 48.195, 9410.0, 97.0052
20.871873220, 48.195, 10756.0, 103.7111
20.926205420, 48.195, 13077.0, 114.3547
20.980537620, 48.195, 15272.0, 123.5799
21.034869820, 48.195, 17028.0, 130.4914
21.089202020, 48.195, 17216.0, 131.2098
21.143534220, 48.195, 15659.0, 125.1359
21.197866420, 48.195, 12850.0, 113.3578
21.252198620, 48.195, 9459.0, 97.2574
21.306530820, 48.195, 6927.0, 83.2286
21.360863020, 48.195, 5085.0, 71.3092
21.415195220, 48.195, 4087.0, 63.9296
21.469527420, 48.195, 3459.0, 58.8133
21.523859620, 48.195, 3112.0, 55.7853
21.578191820, 48.195, 2856.0, 53.4416
21.632524020, 48.195, 2668.0, 51.6527
21.686856220, 48.195, 2558.0, 50.5767
21.741188420, 48.195, 2477.0, 49.7695
21.795520620, 48.195, 2510.0, 50.0999
21.849852820, 48.195, 2680.0, 51.7687
21.904185020, 48.195, 2873.0, 53.6004
21.958517220, 48.195, 3206.0, 56.6216
22.012849420, 48.195, 3653.0, 60.4401
22.067181620, 48.195, 3966.0, 62.9762
22.121513820, 48.195, 4051.0, 63.6475
22.175846020, 48.195, 3766.0, 61.3677
22.230178220, 48.195, 3609.0, 60.0750
22.284510420, 48.195, 3207.0, 56.6304
22.338842620, 48.195, 2923.0, 54.0648
22.393174820, 48.195, 2691.0, 51.8748
22.447507020, 48.195, 2801.0, 52.9245
22.501839220, 48.195, 2792.0, 52.8394
22.556171420, 48.195, 2796.0, 52.8772
22.610503620, 48.195, 2731.0, 52.2590
22.664835820, 48.195, 2760.0, 52.5357
22.719168020, 48.195, 3111.0, 55.7763
22.773500220, 48.195, 3389.0, 58.2151
22.827832420, 48.195, 3993.0, 63.1902
22.882164620, 48.195, 4233.0, 65.0615
22.936496820, 48.195, 4563.0, 67.5500
22.990829020, 48.195, 4453.0, 66.7308
23.045161220, 48.195, 4109.0, 64.1015
23.099493420, 48.195, 3517.0, 59.3043
23.153825620, 48.195, 3325.0, 57.6628
23.208157820, 48.195, 3289.0, 57.3498
23.262490020, 48.195, 3466.0, 58.8727
23.316822220, 48.195, 3618.0, 60.1498
23.371154420, 48.195, 3837.0, 61.9435
23.425486620, 48.195, 3957.0, 62.9047
23.479818820, 48.195, 3919.0, 62.6019
23.534151020, 48.195, 3869.0, 62.2013
23.588483220, 48.195, 3445.0, 58.6941
23.642815420, 48.195, 3111.0, 55.7763
23.697147620, 48.195, 2659.0, 51.5655
23.751479820, 48.195, 2488.0, 49.8799
23.805812020, 48.195, 2275.0, 47.6970
23.860144220, 48.195, 2197.0, 46.8722
23.914476420, 48.195, 2152.0, 46.3897
23.968808620, 48.195, 2327.0, 48.2390
24.023140820, 48.195, 2644.0, 51.4198
24.077473020, 48.195, 3076.0, 55.4617
24.131805220, 48.195, 3849.0, 62.0403
24.186137420, 48.195, 4579.0, 67.6683
24.240469620, 48.195, 5031.0, 70.9295
24.294801820, 48.195, 5175.0, 71.9375
24.349134020, 48.195, 4985.0, 70.6045
24.403466220, 48.195, 4074.0, 63.8279
24.457798420, 48.195, 3201.0, 56.5774
24.512130620, 48.195, 2818.0, 53.0848
24.566462820, 48.195, 2454.0, 49.5379
24.620795020, 48.195, 2478.0, 49.7795
24.675127220, 48.195, 2156.0, 46.4327
24.729459420, 48.195, 1998.0, 44.6990
24.783791620, 48.195, 1798.0, 42.4028
24.838123820, 48.195, 1699.0, 41.2189
24.892456020, 48.195, 1613.0, 40.1622
24.946788220, 48.195, 1624.0, 40.2989
25.001120420, 48.195, 1596.0, 39.9500
25.055452620, 48.195, 1734.0, 41.6413
25.109784820, 48.195, 1851.0, 43.0232
25.164117020, 48.195, 2006.0, 44.7884
25.218449220, 48.195, 2059.0, 45.3762
25.272781420, 48.195, 2279.0, 47.7389
25.327113620, 48.195, 2152.0, 46.3897
25.381445820, 48.195, 2320.0, 48.1664
25.435778020, 48.195, 2241.0, 47.3392
25.490110220, 48.195, 2216.0, 47.0744
25.544442420, 48.195, 2422.0, 49.2138
25.598774620, 48.195, 2671.0, 51.6817
25.653106820, 48.195, 3029.0, 55.0364
25.707439020, 48.195, 3200.0, 56.5685
25.761771220, 48.195, 3378.0, 58.1206
25.816103420, 48.195, 3489.0, 59.0678
25.870435620, 48.195, 3620.0, 60.1664
25.924767820, 48.195, 3759.0, 61.3107
25.979100020, 48.195, 3606.0, 60.0500
26.033432220, 48.195, 3815.0, 61.7657
26.087764420, 48.195, 3946.0, 62.8172
26.142096620, 48.195, 4084.0, 63.9062
26.196428820, 48.195, 4053.0, 63.6632
26.250761020, 48.195, 3961.0, 62.9365
26.305093220, 48.195, 3877.0, 62.2656
26.359425420, 48.195, 3275.0, 57.2276
26.413757620, 48.195, 2893.0, 53.7866
26.468089820, 48.195, 2489.0, 49.8899
26.522422020, 48.195, 2265.0, 47.5920
26.576754220, 48.195, 1987.0, 44.5758
26.631086420, 48.195, 1648.0, 40.5956
26.685418620, 48.195, 1594.0, 39.9249
26.739750820, 48.195, 1655.0, 40.6817
26.794083020, 48.195, 1615.0, 40.1871
26.848415220, 48.195, 1551.0, 39.3827
26.902747420, 48.195, 1554.0, 39.4208
26.957079620, 48.195, 1575.0, 39.6863
27.011411820, 48.195, 1573.0, 39.6611
27.065744020, 48.195, 1617.0, 40.2119
27.120076220, 48.195, 1700.0, 41.2311
27.174408420, 48.195, 1825.0, 42.7200
27.228740620, 48.195, 2092.0, 45.7384
27.283072820, 48.195, 2239.0, 47.3181
27.337405020, 48.195, 2367.0, 48.6518
27.391737220, 48.195, 2280.0, 47.7493
27.446069420, 48.195, 2212.0, 47.0319
27.500401620, 48.195, 2055.0, 45.3321
27.554733820, 48.195, 1850.0, 43.0116
27.609066020, 48.195, 1799.0, 42.4146
27.663398220, 48.195, 1959.0, 44.2606
27.717730420, 48.195, 2000.0, 44.7214
27.772062620, 48.195, 2173.0, 46.6154
27.826394820, 48.195, 2314.0, 48.1041
27.880727020, 48.195, 2313.0, 48.0937
27.935059220, 48.195, 2311.0, 48.0729
27.989391420, 48.195, 2340.0, 48.3735
28.043723620, 48.195, 2136.0, 46.2169
28.098055820, 48.195, 2306.0, 48.0208
28.152388020, 48.195, 2370.0, 48.6826
28.206720220, 48.195, 2409.0, 49.0816
28.261052420, 48.195, 2465.0, 49.6488
28.315384620, 48.195, 2696.0, 51.9230
28.369716820, 48.195, 2838.0, 53.2729
28.424049020, 48.195, 2811.0, 53.0189
28.478381220, 48.195, 2700.0, 51.9615
28.532713420, 48.195, 2780.0, 52.7257
28.587045620, 48.195, 2361.0, 48.5901
28.641377820, 48.195, 2196.0, 46.8615
28.695710020, 48.195, 1994.0, 44.6542
28.750042220, 48.195, 2139.0, 46.2493
28.804374420, 48.195, 2332.0, 48.2908
28.858706620, 48.195, 2428.0, 49.2747
28.913038820, 48.195, 2494.0, 49.9400
28.967371020, 48.195, 2470.0, 49.6991
29.021703220, 48.195, 2415.0, 49.1426
29.076035420, 48.195, 2258.0, 47.5184
29.130367620, 48.195, 2137.0, 46.2277
29.184699820, 48.195, 2107.0, 45.9021
29.239032020, 48.195, 1974.0, 44.4297
29.293364220, 48.195, 1908.0, 43.6807
29.347696420, 48.195, 1792.0, 42.3320
29.402028620, 48.195, 1599.0, 39.9875
29.456360820, 48.195, 1434.0, 37.8682
29.510693020, 48.195, 1443.0, 37.9868
29.565025220, 48.195, 1464.0, 38.2623
29.619357420, 48.195, 1569.0, 39.6106
29.673689620, 48.195, 1551.0, 39.3827
29.728021820, 48.195, 1726.0, 41.5452
29.782354020, 48.195, 1805.0, 42.4853
29.836686220, 48.195, 1602.0, 40.0250
29.891018420, 48.195, 1655.0, 40.6817
29.945350620, 48.195, 1648.0, 40.5956
29.999682820, 48.195, 1651.0, 40.6325
30.054015020, 48.195, 1793.0, 42.3438
30.108347220, 48.195, 1835.0, 42.8369
30.162679420, 48.195, 1867.0, 43.2088
30.217011620, 48.195, 1780.0, 42.1900
30.271343820, 48.195, 1750.0, 41.8330
30.325676020, 48.195, 1696.0, 41.1825
30.380008220, 48.195, 1649.0, 40.6079
30.434340420, 48.195, 1651.0, 40.6325
30.488672620, 48.195, 1563.0, 39.5348
30.543004820, 48.195, 1582.0, 39.7744
30.597337020, 48.195, 1658.0, 40.7185
30.651669220, 48.195, 1728.0, 41.5692
30.706001420, 48.195, 1832.0, 42.8019
30.760333620, 48.195, 1948.0, 44.1362
30.814665820, 48.195, 1883.0, 43.3935
30.868998020, 48.195, 1843.0, 42.9302
30.923330220, 48.195, 1794.0, 42.3556
30.977662420, 48.195, 1769.0, 42.0595
31.031994620, 48.195, 1733.0, 41.6293
31.086326820, 48.195, 1771.0, 42.0833
31.140659020, 48.195, 1909.0, 43.6921
31.194991220, 48.195, 2085.0, 45.6618
31.249323420, 48.195, 2282.0, 47.7703
31.303655620, 48.195, 2344.0, 48.4149
31.357987820, 48.195, 2329.0, 48.2597
31.412320020, 48.195, 2124.0, 46.0869
31.466652220, 48.195, 2058.0, 45.3652
31.520984420, 48.195, 1994.0, 44.6542
31.575316620, 48.195, 1926.0, 43.8862
31.629648820, 48.195, 1818.0, 42.6380
31.683981020, 48.195, 2069.0, 45.4863
31.738313220, 48.195, 2093.0, 45.7493
31.792645420, 48.195, 2142.0, 46.2817
31.846977620, 48.195, 2294.0, 47.8957
31.901309820, 48.195, 2287.0, 47.8226
31.955642020, 48.195, 2323.0, 48.1975
32.009974220, 48.195, 2317.0, 48.1352
32.064306420, 48.195, 2183.0, 46.7226
32.118638620, 48.195, 1962.0, 44.2945
32.172970820, 48.195, 1778.0, 42.1663
32.227303020, 48.195, 1578.0, 39.7240
32.281635220, 48.195, 1491.0, 38.6135
32.335967420, 48.195, 1425.0, 37.7492
32.390299620, 48.195, 1335.0, 36.5377
32.444631820, 48.195, 1433.0, 37.8550
32.498964020, 48.195, 1408.0, 37.5233
32.553296220, 48.195, 1300.0, 36.0555
32.607628420, 48.195, 1349.0, 36.7287
32.661960620, 48.195, 1386.0, 37.2290
32.716292820, 48.195, 1367.0, 36.9730
32.770625020, 48.195, 1526.0, 39.0640
32.824957220, 48.195, 1571.0, 39.6358
32.879289420, 48.195, 1721.0, 41.4849
32.933621620, 48.195, 1907.0, 43.6692
32.987953820, 48.195, 1973.0, 44.4185
33.042286020, 48.195, 2098.0, 45.8039
33.096618220, 48.195, 2148.0, 46.3465
33.150950420, 48.195, 2014.0, 44.8776
33.205282620, 48.195, 1992.0, 44.6318
33.259614820, 48.195, 1887.0, 43.4396
33.313947020, 48.195, 1829.0, 42.7668
33.368279220, 48.195, 1786.0, 42.2611
33.422611420, 48.195, 1980.0, 44.4972
33.476943620, 48.195, 1996.0, 44.6766
33.531275820, 48.195, 1990.0, 44.6094
33.585608020, 48.195, 2040.0, 45.1664
33.639940220, 48.195, 1872.0, 43.2666
33.694272420, 48.195, 1864.0, 43.1741
33.748604620, 48.195, 1813.0, 42.5793
33.802936820, 48.195, 1721.0, 41.4849
33.857269020, 48.195, 1561.0, 39.5095
33.911601220, 48.195, 1488.0, 38.5746
33.965933420, 48.195, 1425.0, 37.7492
34.020265620, 48.195, 1384.0, 37.2022
34.074597820, 48.195, 1349.0, 36.7287
34.128930020, 48.195, 1300.0, 36.0555
34.183262220, 48.195, 1446.0, 38.0263
34.237594420, 48.195, 1356.0, 36.8239
34.291926620, 48.195, 1443.0, 37.9868
34.346258820, 48.195, 1465.0, 38.2753
34.400591020, 48.195, 1436.0, 37.8946
34.454923220, 48.195, 1264.0, 35.5528
34.509255420, 48.195, 1344.0, 36.6606
34.563587620, 48.195, 1280.0, 35.7771
34.617919820, 48.195, 1332.0, 36.4966
34.672252020, 48.195, 1328.0, 36.4417
34.726584220, 48.195, 1244.0, 35.2704
34.780916420, 48.195, 1230.0, 35.0714
34.835248620, 48.195, 1244.0, 35.2704
34.889580820, 48.195, 1231.0, 35.0856
34.943913020, 48.195, 1243.0, 35.2562
34.998245220, 48.195, 1237.0, 35.1710
35.052577420, 48.195, 1261.0, 35.5106
35.106909620, 48.195, 1264.0, 35.5528
35.161241820, 48.195, 1297.0, 36.0139
35.215574020, 48.195, 1315.0, 36.2629
35.269906220, 48.195, 1397.0, 37.3765
35.324238420, 48.195, 1403.0, 37.4566
35.378570620, 48.195, 1535.0, 39.1791
35.432902820, 48.195, 1542.0, 39.2683
35.487235020, 48.195, 1535.0, 39.1791
35.541567220, 48.195, 1434.0, 37.8682
35.595899420, 48.195, 1433.0, 37.8550
35.650231620, 48.195, 1327.0, 36.4280
35.704563820, 48.195, 1228.0, 35.0428
35.758896020, 48.195, 1211.0, 34.7994
35.813228220, 48.195, 1188.0, 34.4674
35.867560420, 48.195, 1154.0, 33.9706
35.921892620, 48.195, 1174.0, 34.2637
35.976224820, 48.195, 1089.0, 33.0000
36.030557020, 48.195, 1110.0, 33.3167
36.084889220, 48.195, 1116.0, 33.4066
36.139221420, 48.195, 1256.0, 35.4401
36.193553620, 48.195, 1230.0, 35.0714
36.247885820, 48.195, 1278.0, 35.7491
36.302218020, 48.195, 1327.0, 36.4280
36.356550220, 48.195, 1317.0, 36.2905
36.410882420, 48.195, 1404.0, 37.4700
36.465214620, 48.195, 1406.0, 37.4967
36.519546820, 48.195, 1434.0, 37.8682
36.573879020, 48.195, 1515.0, 38.9230
36.628211220, 48.195, 1594.0, 39.9249
36.682543420, 48.195, 1548.0, 39.3446
36.736875620, 48.195, 1555.0, 39.4335
36.791207820, 48.195, 1555.0, 39.4335
36.845540020, 48.195, 1540.0, 39.2428
36.899872220, 48.195, 1563.0, 39.5348
36.954204420, 48.195, 1573.0, 39.6611
37.008536620, 48.195, 1566.0, 39.5727
37.062868820, 48.195, 1559.0, 39.4842
37.117201020, 48.195, 1488.0, 38.5746
37.171533220, 48.195, 1418.0, 37.6563
37.225865420, 48.195, 1384.0, 37.2022
37.280197620, 48.195, 1452.0, 38.1051
37.334529820, 48.195, 1281.0, 35.7911
37.388862020, 48.195, 1339.0, 36.5923
37.443194220, 48.195, 1318.0, 36.3043
37.497526420, 48.195, 1349.0, 36.7287
37.551858620, 48.195, 1389.0, 37.2693
37.606190820, 48.195, 1309.0, 36.1801
37.660523020, 48.195, 1330.0, 36.4692
37.714855220, 48.195, 1335.0, 36.5377
37.769187420, 48.195, 1263.0, 35.5387
37.823519620, 48.195, 1358.0, 36.8511
37.877851820, 48.195, 1345.0, 36.6742
37.932184020, 48.195, 1393.0, 37.3229
37.986516220, 48.195, 1427.0, 37.7757
38.040848420, 48.195, 1568.0, 39.5980
38.095180620, 48.195, 1539.0, 39.2301
38.149512820, 48.195, 1557.0, 39.4588
38.203845020, 48.195, 1627.0, 40.3361
38.258177220, 48.195, 1561.0, 39.5095
38.312509420, 48.195, 1553.0, 39.4081
38.366841620, 48.195, 1440.0, 37.9473
38.421173820, 48.195, 1430.0, 37.8153
38.475506020, 48.195, 1299.0, 36.0416
38.529838220, 48.195, 1367.0, 36.9730
38.584170420, 48.195, 1317.0, 36.2905
38.638502620, 48.195, 1369.0, 37.0000
38.692834820, 48.195, 1404.0, 37.4700
38.747167020, 48.195, 1432.0, 37.8418
38.801499220, 48.195, 1437.0, 37.9078
38.855831420, 48.195, 1440.0, 37.9473
38.910163620, 48.195, 1417.0, 37.6431
38.964495820, 48.195, 1465.0, 38.2753
39.018828020, 48.195, 1503.0, 38.7685
39.073160220, 48.195, 1386.0, 37.2290
39.127492420, 48.195, 1369.0, 37.0000
39.181824620, 48.195, 1378.0, 37.1214
39.236156820, 48.195, 1268.0, 35.6090
39.290489020, 48.195, 1293.0, 35.9583
39.344821220, 48.195, 1251.0, 35.3695
39.399153420, 48.195, 1246.0, 35.2987
39.453485620, 48.195, 1194.0, 34.5543
39.507817820, 48.195, 1252.0, 35.3836
39.562150020, 48.195, 1252.0, 35.3836
39.616482220, 48.195, 1350.0, 36.7423
39.670814420, 48.195, 1183.0, 34.3948
39.725146620, 48.195, 1225.0, 35.0000
39.779478820, 48.195, 1156.0, 34.0000
39.833811020, 48.195, 1154.0, 33.9706
39.888143220, 48.195, 1119.0, 33.4515
39.942475420, 48.195, 1188.0, 34.4674
39.996807620, 48.195, 1179.0, 34.3366
40.051139820, 48.195, 1264.0, 35.5528
40.105472020, 48.195, 1252.0, 35.3836
40.159804220, 48.195, 1263.0, 35.5387
40.214136420, 48.195, 1289.0, 35.9026
40.268468620, 48.195, 1299.0, 36.0416
40.322800820, 48.195, 1192.0, 34.5254
40.377133020, 48.195, 1183.0, 34.3948
40.431465220, 48.195, 1120.0, 33.4664
40.485797420, 48.195, 1088.0, 32.9848
40.540129620, 48.195, 1164.0, 34.1174
40.594461820, 48.195, 1164.0, 34.1174
40.648794020, 48.195, 1053.0, 32.4500
40.703126220, 48.195, 1189.0, 34.4819
40.757458420, 48.195, 1141.0, 33.7787
40.811790620, 48.195, 1071.0, 32.7261
40.866122820, 48.195, 1105.0, 33.2415
40.920455020, 48.195, 1067.0, 32.6650
40.974787220, 48.195, 1071.0, 32.7261
41.029119420, 48.195, 1049.0, 32.3883
41.083451620, 48.195, 1087.0, 32.9697
41.137783820, 48.195, 1078.0, 32.8329
41.192116020, 48.195, 1119.0, 33.4515
41.246448220, 48.195, 1099.0, 33.1512
41.300780420, 48.195, 1180.0, 34.3511
41.355112620, 48.195, 1146.0, 33.8526
41.409444820, 48.195, 1304.0, 36.1109
41.463777020, 48.195, 1278.0, 35.7491
41.518109220, 48.195, 1209.0, 34.7707
41.572441420, 48.195, 1200.0, 34.6410
41.626773620, 48.195, 1306.0, 36.1386
41.681105820, 48.195, 1300.0, 36.0555
41.735438020, 48.195, 1207.0, 34.7419
41.789770220, 48.195, 1229.0, 35.0571
41.844102420, 48.195, 1185.0, 34.4238
41.898434620, 48.195, 1190.0, 34.4964
41.952766820, 48.195, 1128.0, 33.5857
42.007099020, 48.195, 1184.0, 34.4093
42.061431220, 48.195, 1147.0, 33.8674
42.115763420, 48.195, 1146.0, 33.8526
42.170095620, 48.195, 1126.0, 33.5559
42.224427820, 48.195, 1085.0, 32.9393
42.278760020, 48.195, 1063.0, 32.6037
42.333092220, 48.195, 1121.0, 33.4813
42.387424420, 48.195, 1022.0, 31.9687
42.441756620, 48.195, 1057.0, 32.5115
42.496088820, 48.195, 1088.0, 32.9848
42.550421020, 48.195, 961.0, 31.0000
42.604753220, 48.195, 985.0, 31.3847
42.659085420, 48.195, 1098.0, 33.1361
42.713417620, 48.195, 979.0, 31.2890
42.767749820, 48.195, 1102.0, 33.1964
42.822082020, 48.195, 1116.0, 33.4066
42.876414220, 48.195, 1159.0, 34.0441
42.930746420, 48.195, 1122.0, 33.4963
42.985078620, 48.195, 1094.0, 33.0757
43.039410820, 48.195, 1060.0, 32.5576
43.093743020, 48.195, 1070.0, 32.7109
43.148075220, 48.195, 1097.0, 33.1210
43.202407420, 48.195, 1167.0, 34.1614
43.256739620, 48.195, 1135.0, 33.6898
43.311071820, 48.195, 1138.0, 33.7343
43.365404020, 48.195, 1117.0, 33.4215
43.419736220, 48.195, 1160.0, 34.0588
43.474068420, 48.195, 1120.0, 33.4664
43.528400620, 48.195, 1234.0, 35.1283
43.582732820, 48.195, 1157.0, 34.0147
43.637065020, 48.195, 1134.0, 33.6749
43.691397220, 48.195, 1121.0, 33.4813
43.745729420, 48.195, 1046.0, 32.3419
43.800061620, 48.195, 1112.0, 33.3467
43.854393820, 48.195, 1125.0, 33.5410
43.908726020, 48.195, 1100.0, 33.1662
43.963058220, 48.195, 1052.0, 32.4345
44.017390420, 48.195, 1076.0, 32.8024
44.071722620, 48.195, 1033.0, 32.1403
44.126054820, 48.195, 1146.0, 33.8526
44.180387020, 48.195, 1163.0, 34.1028
44.234719220, 48.195, 1164.0, 34.1174
44.289051420, 48.195, 1205.0, 34.7131
44.343383620, 48.195, 1176.0, 34.2929
44.397715820, 48.195, 1111.0, 33.3317
44.452048020, 48.195, 1039.0, 32.2335
44.506380220, 48.195, 1104.0, 33.2265
44.560712420, 48.195, 1050.0, 32.4037
44.615044620, 48.195, 954.0, 30.8869
44.669376820, 48.195, 982.0, 31.3369
44.723709020, 48.195, 951.0, 30.8383
44.778041220, 48.195, 991.0, 31.4802
44.832373420, 48.195, 836.0, 28.9137
44.886705620, 48.195, 910.0, 30.1662
44.941037820, 48.195, 847.0, 29.1033
44.995370020, 48.195, 951.0, 30.8383
45.049702220, 48.195, 941.0, 30.6757
45.104034420, 48.195, 1002.0, 31.6544
45.158366620, 48.195, 952.0, 30.8545
45.212698820, 48.195, 962.0, 31.0161
45.267031020, 48.195, 1023.0, 31.9844
45.321363220, 48.195, 966.0, 31.0805
45.375695420, 48.195, 1014.0, 31.8434
45.430027620, 48.195, 993.0, 31.5119
45.484359820, 48.195, 980.0, 31.3050
45.538692020, 48.195, 929.0, 30.4795
45.593024220, 48.195, 973.0, 31.1929
45.647356420, 48.195, 943.0, 30.7083
45.701688620, 48.195, 957.0, 30.9354
45.756020820, 48.195, 932.0, 30.5287
45.810353020, 48.195, 894.0, 29.8998
45.864685220, 48.195, 869.0, 29.4788
45.919017420, 48.195, 897.0, 29.9500
45.973349620, 48.195, 925.0, 30.4138
46.027681820, 48.195, 907.0, 30.1164
46.082014020, 48.195, 954.0, 30.8869
46.136346220, 48.195, 954.0, 30.8869
46.190678420, 48.195, 991.0, 31.4802
46.245010620, 48.195, 980.0, 31.3050
46.299342820, 48.195, 991.0, 31.4802
46.353675020, 48.195, 1026.0, 32.0312
46.408007220, 48.195, 1035.0, 32.1714
46.462339420, 48.195, 998.0, 31.5911
46.516671620, 48.195, 957.0, 30.9354
46.571003820, 48.195, 1000.0, 31.6228
46.625336020, 48.195, 902.0, 30.0333
46.679668220, 48.195, 926.0, 30.4302
46.734000420, 48.195, 950.0, 30.8221
46.788332620, 48.195, 982.0, 31.3369
46.842664820, 48.195, 896.0, 29.9333
46.896997020, 48.195, 952.0, 30.8545
46.951329220, 48.195, 1074.0, 32.7719
47.005661420, 48.195, 1046.0, 32.3419
47.059993620, 48.195, 1005.0, 31.7017
47.114325820, 48.195, 1075.0, 32.7872
47.168658020, 48.195, 1121.0, 33.4813
47.222990220, 48.195, 1070.0, 32.7109
47.277322420, 48.195, 1044.0, 32.3110
47.331654620, 48.195, 1061.0, 32.5730
47.385986820, 48.195, 973.0, 31.1929
47.440319020, 48.195, 930.0, 30.4959
47.494651220, 48.195, 979.0, 31.2890
47.548983420, 48.195, 973.0, 31.1929
47.603315620, 48.195, 934.0, 30.5614
47.657647820, 48.195, 887.0, 29.7825
47.711980020, 48.195, 918.0, 30.2985
47.766312220, 48.195, 888.0, 29.7993
47.820644420, 48.195, 879.0, 29.6479
47.874976620, 48.195, 928.0, 30.4631
47.929308820, 48.195, 970.0, 31.1448
47.983641020, 48.195, 949.0, 30.8058
48.037973220, 48.195, 912.0, 30.1993
48.092305420, 48.195, 921.0, 30.3480
48.146637620, 48.195, 936.0, 30.5941
48.200969820, 48.195, 950.0, 30.8221
48.255302020, 48.195, 899.0, 29.9833
48.309634220, 48.195, 999.0, 31.6070
48.363966420, 48.195, 947.0, 30.7734
48.418298620, 48.195, 924.0, 30.3974
48.472630820, 48.195, 954.0, 30.8869
48.526963020, 48.195, 929.0, 30.4795
48.581295220, 48.195, 1050.0, 32.4037
48.635627420, 48.195, 940.0, 30.6594
48.689959620, 48.195, 988.0, 31.4325
48.744291820, 48.195, 898.0, 29.9666
48.798624020, 48.195, 877.0, 29.6142
48.852956220, 48.195, 1003.0, 31.6702
48.907288420, 48.195, 910.0, 30.1662
48.961620620, 48.195, 969.0, 31.1288
49.015952820, 48.195, 934.0, 30.5614
49.070285020, 48.195, 947.0, 30.7734
49.124617220, 48.195, 925.0, 30.4138
49.178949420, 48.195, 883.0, 29.7153
49.233281620, 48.195, 920.0, 30.3315
49.287613820, 48.195, 875.0, 29.5804
49.341946020, 48.195, 863.0, 29.3769
49.396278220, 48.195, 901.0, 30.0167
49.450610420, 48.195, 874.0, 29.5635
49.504942620, 48.195, 884.0, 29.7321
49.559274820, 48.195, 899.0, 29.9833
49.613607020, 48.195, 927.0, 30.4467
49.667939220, 48.195, 959.0, 30.9677
49.722271420, 48.195, 896.0, 29.9333
49.776603620, 48.195, 870.0, 29.4958
49.830935820, 48.195, 945.0, 30.7409
49.885268020, 48.195, 956.0, 30.9192
49.939600220, 48.195, 1022.0, 31.9687
49.993932420, 48.195, 940.0, 30.6594
50.048264620, 48.195, 946.0, 30.7571
50.102596820, 48.195, 967.0, 31.0966
50.156929020, 48.195, 904.0, 30.0666
50.211261220, 48.195, 939.0, 30.6431
50.265593420, 48.195, 900.0, 30.0000
50.319925620, 48.195, 822.0, 28.6705
50.374257820, 48.195, 879.0, 29.6479
50.428590020, 48.195, 873.0, 29.5466
50.482922220, 48.195, 853.0, 29.2062
50.537254420, 48.195, 891.0, 29.8496
50.591586620, 48.195, 823.0, 28.6880
50.645918820, 48.195, 866.0, 29.4279
50.700251020, 48.195, 831.0, 28.8271
50.754583220, 48.195, 913.0, 30.2159
50.808915420, 48.195, 882.0, 29.6985
50.863247620, 48.195, 884.0, 29.7321
50.917579820, 48.195, 867.0, 29.4449
50.971912020, 48.195, 835.0, 28.8964
51.026244220, 48.195, 807.0, 28.4077
51.080576420, 48.195, 830.0, 28.8097
51.134908620, 48.195, 871.0, 29.5127
51.189240820, 48.195, 799.0, 28.2666
51.243573020, 48.195, 813.0, 28.5132
51.297905220, 48.195, 829.0, 28.7924
51.352237420, 48.195, 742.0, 27.2397
51.406569620, 48.195, 845.0, 29.0689
51.460901820, 48.195, 807.0, 28.4077
51.515234020, 48.195, 815.0, 28.5482
51.569566220, 48.195, 814.0, 28.5307
51.623898420, 48.195, 835.0, 28.8964
51.678230620, 48.195, 786.0, 28.0357
51.732562820, 48.195, 785.0, 28.0179
51.786895020, 48.195, 773.0, 27.8029
51.841227220, 48.195, 765.0, 27.6586
51.895559420, 48.195, 843.0, 29.0345
51.949891620, 48.195, 784.0, 28.0000
52.004223820, 48.195, 788.0, 28.0713
52.058556020, 48.195, 781.0, 27.9464
52.112888220, 48.195, 771.0, 27.7669
52.167220420, 48.195, 747.0, 27.3313
52.221552620, 48.195, 775.0, 27.8388
52.275884820, 48.195, 800.0, 28.2843
52.330217020, 48.195, 808.0, 28.4253
52.384549220, 48.195, 738.0, 27.1662
52.438881420, 48.195, 727.0, 26.9629
52.493213620, 48.195, 774.0, 27.8209
52.547545820, 48.195, 816.0, 28.5657
52.601878020, 48.195, 822.0, 28.6705
52.656210220, 48.195, 825.0, 28.7228
52.710542420, 48.195, 788.0, 28.0713
52.764874620, 48.195, 809.0, 28.4429
52.819206820, 48.195, 831.0, 28.8271
52.873539020, 48.195, 794.0, 28.1780
52.927871220, 48.195, 821.0, 28.6531
52.982203420, 48.195, 817.0, 28.5832
53.036535620, 48.195, 802.0, 28.3196
53.090867820, 48.195, 755.0, 27.4773
53.145200020, 48.195, 770.0, 27.7489
53.199532220, 48.195, 736.0, 27.1293
53.253864420, 48.195, 774.0, 27.8209
53.308196620, 48.195, 753.0, 27.4408
53.362528820, 48.195, 807.0, 28.4077
53.416861020, 48.195, 771.0, 27.7669
53.471193220, 48.195, 823.0, 28.6880
53.525525420, 48.195, 823.0, 28.6880
53.579857620, 48.195, 822.0, 28.6705
53.634189820, 48.195, 795.0, 28.1957
53.688522020, 48.195, 835.0, 28.8964
53.742854220, 48.195, 801.0, 28.3019
53.797186420, 48.195, 783.0, 27.9821
53.851518620, 48.195, 771.0, 27.7669
53.905850820, 48.195, 798.0, 28.2489
53.960183020, 48.195, 761.0, 27.5862
54.014515220, 48.195, 760.0, 27.5681
54.068847420, 48.195, 758.0, 27.5318
54.123179620, 48.195, 770.0, 27.7489
54.177511820, 48.195, 780.0, 27.9285
54.231844020, 48.195, 767.0, 27.6948
54.286176220, 48.195, 742.0, 27.2397
54.340508420, 48.195, 748.0, 27.3496
54.394840620, 48.195, 772.0, 27.7849
54.449172820, 48.195, 732.0, 27.0555
54.503505020, 48.195, 725.0, 26.9258
54.557837220, 48.195, 748.0, 27.3496
54.612169420, 48.195, 730.0, 27.0185
54.666501620, 48.195, 706.0, 26.5707
54.720833820, 48.195, 719.0, 26.8142
54.775166020, 48.195, 750.0, 27.3861
54.829498220, 48.195, 716.0, 26.7582
54.883830420, 48.195, 699.0, 26.4386
54.938162620, 48.195, 671.0, 25.9037
54.992494820, 48.195, 692.0, 26.3059
55.046827020, 48.195, 726.0, 26.9444
55.101159220, 48.195, 679.0, 26.0576
55.155491420, 48.195, 698.0, 26.4197
55.209823620, 48.195, 701.0, 26.4764
55.264155820, 48.195, 643.0, 25.3574
55.318488020, 48.195, 702.0, 26.4953
55.372820220, 48.195, 687.0, 26.2107
55.427152420, 48.195, 759.0, 27.5500
55.481484620, 48.195, 716.0, 26.7582
55.535816820, 48.195, 730.0, 27.0185
55.590149020, 48.195, 792.0, 28.1425
55.644481220, 48.195, 751.0, 27.4044
55.698813420, 48.195, 731.0, 27.0370
55.753145620, 48.195, 858.0, 29.2916
55.807477820, 48.195, 906.0, 30.0998
55.861810020, 48.195, 858.0, 29.2916
55.916142220, 48.195, 834.0, 28.8791
55.970474420, 48.195, 832.0, 28.8444
56.024806620, 48.195, 805.0, 28.3725
56.079138820, 48.195, 759.0, 27.5500
56.133471020, 48.195, 777.0, 27.8747
56.187803220, 48.195, 716.0, 26.7582
56.242135420, 48.195, 734.0, 27.0924
56.296467620, 48.195, 740.0, 27.2029
56.350799820, 48.195, 702.0, 26.4953
56.405132020, 48.195, 744.0, 27.2764
56.459464220, 48.195, 699.0, 26.4386
56.513796420, 48.195, 708.0, 26.6083
56.568128620, 48.195, 728.0, 26.9815
56.622460820, 48.195, 725.0, 26.9258
56.676793020, 48.195, 636.0, 25.2190
56.731125220, 48.195, 744.0, 27.2764
56.785457420, 48.195, 673.0, 25.9422
56.839789620, 48.195, 675.0, 25.9808
56.894121820, 48.195, 647.0, 25.4362
56.948454020, 48.195, 663.0, 25.7488
57.002786220, 48.195, 662.0, 25.7294
57.057118420, 48.195, 658.0, 25.6515
57.111450620, 48.195, 667.0, 25.8263
57.165782820, 48.195, 658.0, 25.6515
57.220115020, 48.195, 638.0, 25.2587
57.274447220, 48.195, 619.0, 24.8797
57.328779420, 48.195, 649.0, 25.4755
57.383111620, 48.195, 652.0, 25.5343
57.437443820, 48.195, 643.0, 25.3574
57.491776020, 48.195, 602.0, 24.5357
57.546108220, 48.195, 682.0, 26.1151
57.600440420, 48.195, 647.0, 25.4362
57.654772620, 48.195, 635.0, 25.1992
57.709104820, 48.195, 570.0, 23.8747
57.763437020, 48.195, 674.0, 25.9615
57.817769220, 48.195, 648.0, 25.4558
57.872101420, 48.195, 657.0, 25.6320
57.926433620, 48.195, 650.0, 25.4951
57.980765820, 48.195, 668.0, 25.8457
58.035098020, 48.195, 674.0, 25.9615
58.089430220, 48.195, 582.0, 24.1247
58.143762420, 48.195, 630.0, 25.0998
58.198094620, 48.195, 613.0, 24.7588
58.252426820, 48.195, 690.0, 26.2679
58.306759020, 48.195, 598.0, 24.4540
58.361091220, 48.195, 606.0, 24.6171
58.415423420, 48.195, 596.0, 24.4131
58.469755620, 48.195, 677.0, 26.0192
58.524087820, 48.195, 662.0, 25.7294
58.578420020, 48.195, 635.0, 25.1992
58.632752220, 48.195, 618.0, 24.8596
58.687084420, 48.195, 592.0, 24.3311
58.741416620, 48.195, 556.0, 23.5797
58.795748820, 48.195, 641.0, 25.3180
58.850081020, 48.195, 652.0, 25.5343
58.904413220, 48.195, 644.0, 25.3772
58.958745420, 48.195, 551.0, 23.4734
59.013077620, 48.195, 631.0, 25.1197
59.067409820, 48.195, 594.0, 24.3721
59.121742020, 48.195, 659.0, 25.6710
59.176074220, 48.195, 611.0, 24.7184
59.230406420, 48.195, 559.0, 23.6432
59.284738620, 48.195, 608.0, 24.6577
59.339070820, 48.195, 555.0, 23.5584
59.393403020, 48.195, 615.0, 24.7992
59.447735220, 48.195, 593.0, 24.3516
59.502067420, 48.195, 555.0, 23.5584
59.556399620, 48.195, 573.0, 23.9374
59.610731820, 48.195, 534.0, 23.1084
59.665064020, 48.195, 565.0, 23.7697
59.719396220, 48.195, 573.0, 23.9374
59.773728420, 48.195, 566.0, 23.7908
59.828060620, 48.195, 560.0, 23.6643
59.882392820, 48.195, 544.0, 23.3238
59.936725020, 48.195, 585.0, 24.1868
59.991057220, 48.195, 585.0, 24.1868
60.045389420, 48.195, 543.0, 23.3024
60.099721620, 48.195, 533.0, 23.0868
60.154053820, 48.195, 585.0, 24.1868
60.208386020, 48.195, 542.0, 23.2809
60.262718220, 48.195, 625.0, 25.0000
60.317050420, 48.195, 542.0, 23.2809
60.371382620, 48.195, 544.0, 23.3238
60.425714820, 48.195, 554.0, 23.5372
60.480047020, 48.195, 523.0, 22.8692
60.534379220, 48.195, 584.0, 24.1661
60.588711420, 48.195, 578.0, 24.0416
60.643043620, 48.195, 552.0, 23.4947
60.697375820, 48.195, 542.0, 23.2809
60.751708020, 48.195, 534.0, 23.1084
60.806040220, 48.195, 544.0, 23.3238
60.860372420, 48.195, 539.0, 23.2164
60.914704620, 48.195, 530.0, 23.0217
60.969036820, 48.195, 558.0, 23.6220
61.023369020, 48.195, 526.0, 22.9347
61.077701220, 48.195, 552.0, 23.4947
61.132033420, 48.195, 584.0, 24.1661
61.186365620, 48.195, 544.0, 23.3238
61.240697820, 48.195, 569.0, 23.8537
61.295030020, 48.195, 545.0, 23.3452
61.349362220, 48.195, 558.0, 23.6220
61.403694420, 48.195, 530.0, 23.0217
61.458026620, 48.195, 517.0, 22.7376
61.512358820, 48.195, 569.0, 23.8537
61.566691020, 48.195, 548.0, 23.4094
61.621023220, 48.195, 555.0, 23.5584
61.675355420, 48.195, 551.0, 23.4734
61.729687620, 48.195, 537.0, 23.1733
61.784019820, 48.195, 523.0, 22.8692
61.838352020, 48.195, 516.0, 22.7156
61.892684220, 48.195, 533.0, 23.0868
61.947016420, 48.195, 527.0, 22.9565
62.001348620, 48.195, 525.0, 22.9129
62.055680820, 48.195, 523.0, 22.8692
62.110013020, 48.195, 558.0, 23.6220
62.164345220, 48.195, 514.0, 22.6716
62.218677420, 48.195, 527.0, 22.9565
62.273009620, 48.195, 566.0, 23.7908
62.327341820, 48.195, 486.0, 22.0454
62.381674020, 48.195, 485.0, 22.0227
62.436006220, 48.195, 560.0, 23.6643
62.490338420, 48.195, 540.0, 23.2379
62.544670620, 48.195, 545.0, 23.3452
62.599002820, 48.195, 525.0, 22.9129
62.653335020, 48.195, 517.0, 22.7376
62.707667220, 48.195, 525.0, 22.9129
62.761999420, 48.195, 463.0, 21.5174
62.816331620, 48.195, 513.0, 22.6495
62.870663820, 48.195, 522.0, 22.8473
62.924996020, 48.195, 543.0, 23.3024
62.979328220, 48.195, 541.0, 23.2594
63.033660420, 48.195, 506.0, 22.4944
63.087992620, 48.195, 535.0, 23.1301
63.142324820, 48.195, 539.0, 23.2164
63.196657020, 48.195, 488.0, 22.0907
63.250989220, 48.195, 504.0, 22.4499
63.305321420, 48.195, 484.0, 22.0000
63.359653620, 48.195, 540.0, 23.2379
63.413985820, 48.195, 527.0, 22.9565
63.468318020, 48.195, 466.0, 21.5870
63.522650220, 48.195, 497.0, 22.2935
63.576982420, 48.195, 521.0, 22.8254
63.631314620, 48.195, 501.0, 22.3830
63.685646820, 48.195, 486.0, 22.0454
63.739979020, 48.195, 506.0, 22.4944
63.794311220, 48.195, 465.0, 21.5639
63.848643420, 48.195, 520.0, 22.8035
63.902975620, 48.195, 514.0, 22.6716
63.957307820, 48.195, 501.0, 22.3830
64.011640020, 48.195, 504.0, 22.4499
64.065972220, 48.195, 520.0, 22.8035
64.120304420, 48.195, 485.0, 22.0227
64.174636620, 48.195, 521.0, 22.8254
64.228968820, 48.195, 491.0, 22.1585
64.283301020, 48.195, 504.0, 22.4499
64.337633220, 48.195, 513.0, 22.6495
64.391965420, 48.195, 461.0, 21.4709
64.446297620, 48.195, 470.0, 21.6795
64.500629820, 48.195, 488.0, 22.0907
64.554962020, 48.195, 499.0, 22.3383
64.609294220, 48.195, 505.0, 22.4722
64.663626420, 48.195, 467.0, 21.6102
64.717958620, 48.195, 527.0, 22.9565
64.772290820, 48.195, 511.0, 22.6053
64.826623020, 48.195, 458.0, 21.4009
64.880955220, 48.195, 447.0, 21.1424
64.935287420, 48.195, 447.0, 21.1424
64.989619620, 48.195, 491.0, 22.1585
65.043951820, 48.195, 478.0, 21.8632
65.098284020, 48.195, 494.0, 22.2261
65.152616220, 48.195, 503.0, 22.4277
65.206948420, 48.195, 511.0, 22.6053
65.261280620, 48.195, 500.0, 22.3607
65.315612820, 48.195, 523.0, 22.8692
65.369945020, 48.195, 484.0, 22.0000
65.424277220, 48.195, 488.0, 22.0907
65.478609420, 48.195, 479.0, 21.8861
65.532941620, 48.195, 465.0, 21.5639
65.587273820, 48.195, 524.0, 22.8910
65.641606020, 48.195, 491.0, 22.1585
65.695938220, 48.195, 494.0, 22.2261
65.750270420, 48.195, 476.0, 21.8174
65.804602620, 48.195, 486.0, 22.0454
65.858934820, 48.195, 473.0, 21.7486
65.913267020, 48.195, 458.0, 21.4009
65.967599220, 48.195, 446.0, 21.1187
66.021931420, 48.195, 507.0, 22.5167
66.076263620, 48.195, 473.0, 21.7486
66.130595820, 48.195, 515.0, 22.6936
66.184928020, 48.195, 459.0, 21.4243
66.239260220, 48.195, 465.0, 21.5639
66.293592420, 48.195, 462.0, 21.4942
66.347924620, 48.195, 487.0, 22.0681
66.402256820, 48.195, 503.0, 22.4277
66.456589020, 48.195, 511.0, 22.6053
66.510921220, 48.195, 559.0, 23.6432
66.565253420, 48.195, 461.0, 21.4709
66.619585620, 48.195, 475.0, 21.7945
66.673917820, 48.195, 516.0, 22.7156
66.728250020, 48.195, 476.0, 21.8174
66.782582220, 48.195, 461.0, 21.4709
66.836914420, 48.195, 494.0, 22.2261
66.891246620, 48.195, 473.0, 21.7486
66.945578820, 48.195, 481.0, 21.9317
66.999911020, 48.195, 472.0, 21.7256
67.054243220, 48.195, 446.0, 21.1187
67.108575420, 48.195, 442.0, 21.0238
67.162907620, 48.195, 492.0, 22.1811
67.217239820, 48.195, 449.0, 21.1896
67.271572020, 48.195, 472.0, 21.7256
67.325904220, 48.195, 470.0, 21.6795
67.380236420, 48.195, 443.0, 21.0476
67.434568620, 48.195, 459.0, 21.4243
67.488900820, 48.195, 508.0, 22.5389
67.543233020, 48.195, 455.0, 21.3307
67.597565220, 48.195, 456.0, 21.3542
67.651897420, 48.195, 467.0, 21.6102
67.706229620, 48.195, 461.0, 21.4709
67.760561820, 48.195, 453.0, 21.2838
67.814894020, 48.195, 472.0, 21.7256
67.869226220, 48.195, 492.0, 22.1811
67.923558420, 48.195, 461.0, 21.4709
67.977890620, 48.195, 463.0, 21.5174
68.032222820, 48.195, 448.0, 21.1660
68.086555020, 48.195, 470.0, 21.6795
68.140887220, 48.195, 469.0, 21.6564
68.195219420, 48.195, 441.0, 21.0000
68.249551620, 48.195, 416.0, 20.3961
68.303883820, 48.195, 427.0, 20.6640
68.358216020, 48.195, 415.0, 20.3715
68.412548220, 48.195, 429.0, 20.7123
68.466880420, 48.195, 444.0, 21.0713
68.521212620, 48.195, 499.0, 22.3383
68.575544820, 48.195, 456.0, 21.3542
68.629877020, 48.195, 480.0, 21.9089
68.684209220, 48.195, 435.0, 20.8567
68.738541420, 48.195, 480.0, 21.9089
68.792873620, 48.195, 450.0, 21.2132
68.847205820, 48.195, 487.0, 22.0681
68.901538020, 48.195, 418.0, 20.4450
68.955870220, 48.195, 437.0, 20.9045
69.010202420, 48.195, 497.0, 22.2935
69.064534620, 48.195, 470.0, 21.6795
69.118866820, 48.195, 458.0, 21.4009
69.173199020, 48.195, 458.0, 21.4009
69.227531220, 48.195, 440.0, 20.9762
69.281863420, 48.195, 454.0, 21.3073
69.336195620, 48.195, 440.0, 20.9762
69.390527820, 48.195, 445.0, 21.0950
69.444860020, 48.195, 395.0, 19.8746
69.499192220, 48.195, 475.0, 21.7945
69.553524420, 48.195, 431.0, 20.7605
69.607856620, 48.195, 433.0, 20.8087
69.662188820, 48.195, 443.0, 21.0476
69.716521020, 48.195, 467.0, 21.6102
69.770853220, 48.195, 444.0, 21.0713
69.825185420, 48.195, 495.0, 22.2486
69.879517620, 48.195, 447.0, 21.1424
69.933849820, 48.195, 450.0, 21.2132
69.988182020, 48.195, 416.0, 20.3961
70.042514220, 48.195, 440.0, 20.9762
70.096846420, 48.195, 448.0, 21.1660
70.151178620, 48.195, 456.0, 21.3542
70.205510820, 48.195, 441.0, 21.0000
70.259843020, 48.195, 458.0, 21.4009
70.314175220, 48.195, 433.0, 20.8087
70.368507420, 48.195, 449.0, 21.1896
70.422839620, 48.195, 474.0, 21.7715
70.477171820, 48.195, 460.0, 21.4476
70.531504020, 48.195, 401.0, 20.0250
70.585836220, 48.195, 433.0, 20.8087
70.640168420, 48.195, 488.0, 22.0907
70.694500620, 48.195, 456.0, 21.3542
70.748832820, 48.195, 456.0, 21.3542
70.803165020, 48.195, 450.0, 21.2132
70.857497220, 48.195, 445.0, 21.0950
70.911829420, 48.195, 434.0, 20.8327
70.966161620, 48.195, 451.0, 21.2368
71.020493820, 48.195, 432.0, 20.7846
71.074826020, 48.195, 447.0, 21.1424
71.129158220, 48.195, 402.0, 20.0499
71.183490420, 48.195, 444.0, 21.0713
71.237822620, 48.195, 467.0, 21.6102
71.292154820, 48.195, 450.0, 21.2132
71.346487020, 48.195, 423.0, 20.5670
71.400819220, 48.195, 441.0, 21.0000
71.455151420, 48.195, 507.0, 22.5167
71.509483620, 48.195, 424.0, 20.5913
71.563815820, 48.195, 451.0, 21.2368
71.618148020, 48.195, 432.0, 20.7846
71.672480220, 48.195, 436.0, 20.8806
71.726812420, 48.195, 401.0, 20.0250
71.781144620, 48.195, 470.0, 21.6795
71.835476820, 48.195, 427.0, 20.6640
71.889809020, 48.195, 398.0, 19.9499
71.944141220, 48.195, 432.0, 20.7846
71.998473420, 48.195, 427.0, 20.6640
72.052805620, 48.195, 412.0, 20.2978
72.107137820, 48.195, 462.0, 21.4942
72.161470020, 48.195, 427.0, 20.6640
72.215802220, 48.195, 430.0, 20.7364
72.270134420, 48.195, 427.0, 20.6640
72.324466620, 48.195, 462.0, 21.4942
72.378798820, 48.195, 464.0, 21.5407
72.433131020, 48.195, 426.0, 20.6398
72.487463220, 48.195, 431.0, 20.7605
72.541795420, 48.195, 456.0, 21.3542
72.596127620, 48.195, 445.0, 21.0950
72.650459820, 48.195, 417.0, 20.4206
72.704792020, 48.195, 444.0, 21.0713
72.759124220, 48.195, 458.0, 21.4009
72.813456420, 48.195, 444.0, 21.0713
72.867788620, 48.195, 434.0, 20.8327
72.922120820, 48.195, 427.0, 20.6640
72.976453020, 48.195, 468.0, 21.6333
73.030785220, 48.195, 437.0, 20.9045
73.085117420, 48.195, 457.0, 21.3776
73.139449620, 48.195, 409.0, 20.2237
73.193781820, 48.195, 423.0, 20.5670
73.248114020, 48.195, 440.0, 20.9762
73.302446220, 48.195, 468.0, 21.6333
73.356778420, 48.195, 457.0, 21.3776
73.411110620, 48.195, 465.0, 21.5639
73.465442820, 48.195, 427.0, 20.6640
73.519775020, 48.195, 451.0, 21.2368
73.574107220, 48.195, 437.0, 20.9045
73.628439420, 48.195, 449.0, 21.1896
73.682771620, 48.195, 427.0, 20.6640
73.737103820, 48.195, 448.0, 21.1660
73.791436020, 48.195, 413.0, 20.3224
73.845768220, 48.195, 440.0, 20.9762
73.900100420, 48.195, 469.0, 21.6564
73.954432620, 48.195, 420.0, 20.4939
74.008764820, 48.195, 450.0, 21.2132
74.063097020, 48.195, 435.0, 20.8567
74.117429220, 48.195, 416.0, 20.3961
74.171761420, 48.195, 463.0, 21.5174
74.226093620, 48.195, 462.0, 21.4942
74.280425820, 48.195, 391.0, 19.7737
74.334758020, 48.195, 472.0, 21.7256
74.389090220, 48.195, 462.0, 21.4942
74.443422420, 48.195, 444.0, 21.0713
74.497754620, 48.195, 432.0, 20.7846
74.552086820, 48.195, 442.0, 21.0238
74.606419020, 48.195, 454.0, 21.3073
74.660751220, 48.195, 437.0, 20.9045
74.715083420, 48.195, 464.0, 21.5407
74.769415620, 48.195, 463.0, 21.5174
74.823747820, 48.195, 451.0, 21.2368
74.878080020, 48.195, 425.0, 20.6155
74.932412220, 48.195, 431.0, 20.7605
74.986744420, 48.195, 444.0, 21.0713
75.041076620, 48.195, 422.0, 20.5426
75.095408820, 48.195, 483.0, 21.9773
75.149741020, 48.195, 428.0, 20.6882
75.204073220, 48.195, 466.0, 21.5870
75.258405420, 48.195, 414.0, 20.3470
75.312737620, 48.195, 418.0, 20.4450
75.367069820, 48.195, 478.0, 21.8632
75.421402020, 48.195, 414.0, 20.3470
75.475734220, 48.195, 448.0, 21.1660
75.530066420, 48.195, 455.0, 21.3307
75.584398620, 48.195, 407.0, 20.1742
75.638730820, 48.195, 398.0, 19.9499
75.693063020, 48.195, 428.0, 20.6882
75.747395220, 48.195, 438.0, 20.9284
75.801727420, 48.195, 456.0, 21.3542
75.856059620, 48.195, 455.0, 21.3307
75.910391820, 48.195, 458.0, 21.4009
75.964724020, 48.195, 445.0, 21.0950
76.019056220, 48.195, 419.0, 20.4695
76.073388420, 48.195, 439.0, 20.9523
76.127720620, 48.195, 439.0, 20.9523
76.182052820, 48.195, 491.0, 22.1585
76.236385020, 48.195, 428.0, 20.6882
76.290717220, 48.195, 467.0, 21.6102
76.345049420, 48.195, 474.0, 21.7715
76.399381620, 48.195, 460.0, 21.4476
76.453713820, 48.195, 458.0, 21.4009
76.508046020, 48.195, 456.0, 21.3542
76.562378220, 48.195, 493.0, 22.2036
76.616710420, 48.195, 423.0, 20.5670
76.671042620, 48.195, 450.0, 21.2132
76.725374820, 48.195, 453.0, 21.2838
76.779707020, 48.195, 421.0, 20.5183
76.834039220, 48.195, 428.0, 20.6882
76.888371420, 48.195, 454.0, 21.3073
76.942703620, 48.195, 477.0, 21.8403
76.997035820, 48.195, 447.0, 21.1424
77.051368020, 48.195, 399.0, 19.9750
77.105700220, 48.195, 443.0, 21.0476
77.160032420, 48.195, 428.0, 20.6882
77.214364620, 48.195, 423.0, 20.5670
77.268696820, 48.195, 453.0, 21.2838
77.323029020, 48.195, 440.0, 20.9762
77.377361220, 48.195, 407.0, 20.1742
77.431693420, 48.195, 459.0, 21.4243
77.486025620, 48.195, 469.0, 21.6564
77.540357820, 48.195, 404.0, 20.0998
77.594690020, 48.195, 432.0, 20.7846
77.649022220, 48.195, 429.0, 20.7123
77.703354420, 48.195, 449.0, 21.1896
77.757686620, 48.195, 445.0, 21.0950
77.812018820, 48.195, 434.0, 20.8327
77.866351020, 48.195, 380.0, 19.4936
77.920683220, 48.195, 451.0, 21.2368
77.975015420, 48.195, 435.0, 20.8567
78.029347620, 48.195, 420.0, 20.4939
78.083679820, 48.195, 454.0, 21.3073
78.138012020, 48.195, 412.0, 20.2978
78.192344220, 48.195, 454.0, 21.3073
78.246676420, 48.195, 415.0, 20.3715
78.301008620, 48.195, 432.0, 20.7846
78.355340820, 48.195, 472.0, 21.7256
78.409673020, 48.195, 413.0, 20.3224
78.464005220, 48.195, 407.0, 20.1742
78.518337420, 48.195, 428.0, 20.6882
78.572669620, 48.195, 439.0, 20.9523
78.627001820, 48.195, 459.0, 21.4243
78.681334020, 48.195, 437.0, 20.9045
78.735666220, 48.195, 434.0, 20.8327
78.789998420, 48.195, 440.0, 20.9762
78.844330620, 48.195, 437.0, 20.9045
78.898662820, 48.195, 452.0, 21.2603
78.952995020, 48.195, 468.0, 21.6333
79.007327220, 48.195, 407.0, 20.1742
79.061659420, 48.195, 454.0, 21.3073
79.115991620, 48.195, 427.0, 20.6640
79.170323820, 48.195, 400.0, 20.0000
79.224656020, 48.195, 421.0, 20.5183
79.278988220, 48.195, 446.0, 21.1187
79.333320420, 48.195, 413.0, 20.3224
79.387652620, 48.195, 455.0, 21.3307
79.441984820, 48.195, 431.0, 20.7605
79.496317020, 48.195, 468.0, 21.6333
79.550649220, 48.195, 452.0, 21.2603
79.604981420, 48.195, 450.0, 21.2132
79.659313620, 48.195, 415.0, 20.3715
79.713645820, 48.195, 432.0, 20.7846
79.767978020, 48.195, 442.0, 21.0238
79.822310220, 48.195, 422.0, 20.5426
79.876642420, 48.195, 431.0, 20.7605
79.930974620, 48.195, 425.0, 20.6155
79.985306820, 48.195, 440.0, 20.9762
79.996173260, 48.195, 398.0, 19.9499