File: XRD/2025_06_03_THC_Sorbic_Acid_MC15.csv
[Measurement conditions]
Sample identification,2025_06_03_THC_Sorbic_Acid_MC15
Comment - 1,"THC - Sorbic Acid, MC 15 min, Heptane, Yellowish viscous (like honey)."
Anode material,Cu
K-Alpha1 wavelength,1.5405980
K-Alpha2 wavelength,1.5444260
Ratio K-Alpha2/K-Alpha1,0.500
Divergence slit,Fixed,0.76mm
Monochromator used,NO
Generator voltage, 40
Tube current, 15
File date and time,03/Jun/2025 14:51
Unit cell,
h k l, 0 0 0
Scan axis,Gonio
Scan range,10.000000000,80.001606480
Scan step size,0.0108664
No. of points, 6442
Scan type,CONTINUOUS
Time per step,48.195
[Scan points]
Angle, TimePerStep, Intensity, ESD
10.005433220, 48.195, 3616.0, 60.1332
10.059765420, 48.195, 3729.0, 61.0655
10.114097620, 48.195, 3700.0, 60.8276
10.168429820, 48.195, 3728.0, 61.0574
10.222762020, 48.195, 3606.0, 60.0500
10.277094220, 48.195, 3658.0, 60.4814
10.331426420, 48.195, 3680.0, 60.6630
10.385758620, 48.195, 3596.0, 59.9667
10.440090820, 48.195, 3781.0, 61.4898
10.494423020, 48.195, 3751.0, 61.2454
10.548755220, 48.195, 3786.0, 61.5305
10.603087420, 48.195, 3696.0, 60.7947
10.657419620, 48.195, 3984.0, 63.1189
10.711751820, 48.195, 3917.0, 62.5859
10.766084020, 48.195, 4085.0, 63.9140
10.820416220, 48.195, 4307.0, 65.6277
10.874748420, 48.195, 4531.0, 67.3127
10.929080620, 48.195, 4948.0, 70.3420
10.983412820, 48.195, 5424.0, 73.6478
11.037745020, 48.195, 6411.0, 80.0687
11.092077220, 48.195, 7711.0, 87.8123
11.146409420, 48.195, 10860.0, 104.2113
11.200741620, 48.195, 16957.0, 130.2190
11.255073820, 48.195, 22100.0, 148.6607
11.309406020, 48.195, 17990.0, 134.1268
11.363738220, 48.195, 10614.0, 103.0243
11.418070420, 48.195, 8786.0, 93.7337
11.472402620, 48.195, 7249.0, 85.1411
11.526734820, 48.195, 5215.0, 72.2150
11.581067020, 48.195, 4436.0, 66.6033
11.635399220, 48.195, 4220.0, 64.9615
11.689731420, 48.195, 4244.0, 65.1460
11.744063620, 48.195, 4178.0, 64.6375
11.798395820, 48.195, 4330.0, 65.8027
11.852728020, 48.195, 4339.0, 65.8711
11.907060220, 48.195, 4337.0, 65.8559
11.961392420, 48.195, 4203.0, 64.8305
12.015724620, 48.195, 4352.0, 65.9697
12.070056820, 48.195, 4429.0, 66.5507
12.124389020, 48.195, 4404.0, 66.3626
12.178721220, 48.195, 4492.0, 67.0224
12.233053420, 48.195, 4529.0, 67.2978
12.287385620, 48.195, 4541.0, 67.3869
12.341717820, 48.195, 4711.0, 68.6367
12.396050020, 48.195, 4994.0, 70.6682
12.450382220, 48.195, 5355.0, 73.1779
12.504714420, 48.195, 5734.0, 75.7232
12.559046620, 48.195, 6396.0, 79.9750
12.613378820, 48.195, 7714.0, 87.8294
12.667711020, 48.195, 10362.0, 101.7939
12.722043220, 48.195, 15791.0, 125.6622
12.776375420, 48.195, 19952.0, 141.2515
12.830707620, 48.195, 16820.0, 129.6919
12.885039820, 48.195, 10072.0, 100.3594
12.939372020, 48.195, 7856.0, 88.6341
12.993704220, 48.195, 6921.0, 83.1925
13.048036420, 48.195, 5741.0, 75.7694
13.102368620, 48.195, 5007.0, 70.7602
13.156700820, 48.195, 4893.0, 69.9500
13.211033020, 48.195, 4786.0, 69.1809
13.265365220, 48.195, 4840.0, 69.5701
13.319697420, 48.195, 4851.0, 69.6491
13.374029620, 48.195, 4862.0, 69.7280
13.428361820, 48.195, 4883.0, 69.8785
13.482694020, 48.195, 4887.0, 69.9071
13.537026220, 48.195, 5079.0, 71.2671
13.591358420, 48.195, 5017.0, 70.8308
13.645690620, 48.195, 4963.0, 70.4486
13.700022820, 48.195, 4974.0, 70.5266
13.754355020, 48.195, 5086.0, 71.3162
13.808687220, 48.195, 5084.0, 71.3022
13.863019420, 48.195, 5064.0, 71.1618
13.917351620, 48.195, 5028.0, 70.9084
13.971683820, 48.195, 5026.0, 70.8943
14.026016020, 48.195, 4993.0, 70.6612
14.080348220, 48.195, 5006.0, 70.7531
14.134680420, 48.195, 5026.0, 70.8943
14.189012620, 48.195, 5211.0, 72.1873
14.243344820, 48.195, 5018.0, 70.8378
14.297677020, 48.195, 5130.0, 71.6240
14.352009220, 48.195, 5002.0, 70.7248
14.406341420, 48.195, 5096.0, 71.3863
14.460673620, 48.195, 5017.0, 70.8308
14.515005820, 48.195, 5218.0, 72.2357
14.569338020, 48.195, 5197.0, 72.0902
14.623670220, 48.195, 5226.0, 72.2911
14.678002420, 48.195, 5286.0, 72.7049
14.732334620, 48.195, 5147.0, 71.7426
14.786666820, 48.195, 5225.0, 72.2842
14.840999020, 48.195, 5133.0, 71.6450
14.895331220, 48.195, 5292.0, 72.7461
14.949663420, 48.195, 5270.0, 72.5948
15.003995620, 48.195, 5333.0, 73.0274
15.058327820, 48.195, 5152.0, 71.7774
15.112660020, 48.195, 5229.0, 72.3118
15.166992220, 48.195, 5279.0, 72.6567
15.221324420, 48.195, 5375.0, 73.3144
15.275656620, 48.195, 5438.0, 73.7428
15.329988820, 48.195, 5329.0, 73.0000
15.384321020, 48.195, 5495.0, 74.1283
15.438653220, 48.195, 5492.0, 74.1080
15.492985420, 48.195, 5327.0, 72.9863
15.547317620, 48.195, 5655.0, 75.1997
15.601649820, 48.195, 5567.0, 74.6123
15.655982020, 48.195, 5686.0, 75.4056
15.710314220, 48.195, 5695.0, 75.4652
15.764646420, 48.195, 5893.0, 76.7659
15.818978620, 48.195, 6048.0, 77.7689
15.873310820, 48.195, 6623.0, 81.3818
15.927643020, 48.195, 6717.0, 81.9573
15.981975220, 48.195, 6241.0, 79.0000
16.036307420, 48.195, 5935.0, 77.0390
16.090639620, 48.195, 5743.0, 75.7826
16.144971820, 48.195, 5753.0, 75.8485
16.199304020, 48.195, 5817.0, 76.2693
16.253636220, 48.195, 5757.0, 75.8749
16.307968420, 48.195, 5799.0, 76.1512
16.362300620, 48.195, 5867.0, 76.5963
16.416632820, 48.195, 5848.0, 76.4722
16.470965020, 48.195, 5995.0, 77.4274
16.525297220, 48.195, 5977.0, 77.3111
16.579629420, 48.195, 5969.0, 77.2593
16.633961620, 48.195, 5934.0, 77.0325
16.688293820, 48.195, 5934.0, 77.0325
16.742626020, 48.195, 6032.0, 77.6660
16.796958220, 48.195, 6134.0, 78.3199
16.851290420, 48.195, 6174.0, 78.5748
16.905622620, 48.195, 6295.0, 79.3410
16.959954820, 48.195, 6282.0, 79.2591
17.014287020, 48.195, 6191.0, 78.6829
17.068619220, 48.195, 6412.0, 80.0750
17.122951420, 48.195, 6296.0, 79.3473
17.177283620, 48.195, 6352.0, 79.6994
17.231615820, 48.195, 6346.0, 79.6618
17.285948020, 48.195, 6471.0, 80.4425
17.340280220, 48.195, 6562.0, 81.0062
17.394612420, 48.195, 6578.0, 81.1049
17.448944620, 48.195, 6570.0, 81.0555
17.503276820, 48.195, 6603.0, 81.2588
17.557609020, 48.195, 6726.0, 82.0122
17.611941220, 48.195, 6817.0, 82.5651
17.666273420, 48.195, 6761.0, 82.2253
17.720605620, 48.195, 6787.0, 82.3833
17.774937820, 48.195, 6946.0, 83.3427
17.829270020, 48.195, 7220.0, 84.9706
17.883602220, 48.195, 7207.0, 84.8941
17.937934420, 48.195, 7800.0, 88.3176
17.992266620, 48.195, 8446.0, 91.9021
18.046598820, 48.195, 9127.0, 95.5353
18.100931020, 48.195, 9291.0, 96.3898
18.155263220, 48.195, 8471.0, 92.0380
18.209595420, 48.195, 7741.0, 87.9830
18.263927620, 48.195, 7581.0, 87.0689
18.318259820, 48.195, 7336.0, 85.6505
18.372592020, 48.195, 7308.0, 85.4868
18.426924220, 48.195, 7451.0, 86.3192
18.481256420, 48.195, 7371.0, 85.8545
18.535588620, 48.195, 7471.0, 86.4349
18.589920820, 48.195, 7491.0, 86.5506
18.644253020, 48.195, 7532.0, 86.7871
18.698585220, 48.195, 7726.0, 87.8977
18.752917420, 48.195, 7531.0, 86.7813
18.807249620, 48.195, 7804.0, 88.3403
18.861581820, 48.195, 7697.0, 87.7325
18.915914020, 48.195, 7784.0, 88.2270
18.970246220, 48.195, 7922.0, 89.0056
19.024578420, 48.195, 8009.0, 89.4930
19.078910620, 48.195, 8468.0, 92.0217
19.133242820, 48.195, 8811.0, 93.8669
19.187575020, 48.195, 8689.0, 93.2148
19.241907220, 48.195, 8248.0, 90.8185
19.296239420, 48.195, 7942.0, 89.1179
19.350571620, 48.195, 7861.0, 88.6623
19.404903820, 48.195, 7926.0, 89.0281
19.459236020, 48.195, 7969.0, 89.2693
19.513568220, 48.195, 7840.0, 88.5438
19.567900420, 48.195, 7843.0, 88.5607
19.622232620, 48.195, 7852.0, 88.6115
19.676564820, 48.195, 7763.0, 88.1079
19.730897020, 48.195, 7959.0, 89.2132
19.785229220, 48.195, 7827.0, 88.4703
19.839561420, 48.195, 7819.0, 88.4251
19.893893620, 48.195, 7856.0, 88.6341
19.948225820, 48.195, 7767.0, 88.1306
20.002558020, 48.195, 7781.0, 88.2100
20.056890220, 48.195, 7635.0, 87.3785
20.111222420, 48.195, 7679.0, 87.6299
20.165554620, 48.195, 7657.0, 87.5043
20.219886820, 48.195, 7626.0, 87.3270
20.274219020, 48.195, 7592.0, 87.1321
20.328551220, 48.195, 7757.0, 88.0738
20.382883420, 48.195, 7543.0, 86.8504
20.437215620, 48.195, 7458.0, 86.3597
20.491547820, 48.195, 7361.0, 85.7963
20.545880020, 48.195, 7419.0, 86.1336
20.600212220, 48.195, 7444.0, 86.2786
20.654544420, 48.195, 7187.0, 84.7762
20.708876620, 48.195, 7184.0, 84.7585
20.763208820, 48.195, 7262.0, 85.2174
20.817541020, 48.195, 7182.0, 84.7467
20.871873220, 48.195, 7140.0, 84.4985
20.926205420, 48.195, 7011.0, 83.7317
20.980537620, 48.195, 6979.0, 83.5404
21.034869820, 48.195, 6932.0, 83.2586
21.089202020, 48.195, 6854.0, 82.7889
21.143534220, 48.195, 6763.0, 82.2375
21.197866420, 48.195, 6835.0, 82.6741
21.252198620, 48.195, 6721.0, 81.9817
21.306530820, 48.195, 6608.0, 81.2896
21.360863020, 48.195, 6553.0, 80.9506
21.415195220, 48.195, 6633.0, 81.4432
21.469527420, 48.195, 6523.0, 80.7651
21.523859620, 48.195, 6483.0, 80.5171
21.578191820, 48.195, 6464.0, 80.3990
21.632524020, 48.195, 6288.0, 79.2969
21.686856220, 48.195, 6237.0, 78.9747
21.741188420, 48.195, 6286.0, 79.2843
21.795520620, 48.195, 6378.0, 79.8624
21.849852820, 48.195, 6506.0, 80.6598
21.904185020, 48.195, 6248.0, 79.0443
21.958517220, 48.195, 6416.0, 80.0999
22.012849420, 48.195, 6282.0, 79.2591
22.067181620, 48.195, 6585.0, 81.1480
22.121513820, 48.195, 6842.0, 82.7164
22.175846020, 48.195, 6777.0, 82.3225
22.230178220, 48.195, 7284.0, 85.3464
22.284510420, 48.195, 7594.0, 87.1436
22.338842620, 48.195, 8414.0, 91.7279
22.393174820, 48.195, 10581.0, 102.8640
22.447507020, 48.195, 16096.0, 126.8700
22.501839220, 48.195, 29451.0, 171.6129
22.556171420, 48.195, 48756.0, 220.8076
22.610503620, 48.195, 52419.0, 228.9520
22.664835820, 48.195, 37969.0, 194.8564
22.719168020, 48.195, 28577.0, 169.0473
22.773500220, 48.195, 26562.0, 162.9785
22.827832420, 48.195, 20235.0, 142.2498
22.882164620, 48.195, 12521.0, 111.8973
22.936496820, 48.195, 8284.0, 91.0165
22.990829020, 48.195, 6881.0, 82.9518
23.045161220, 48.195, 6201.0, 78.7464
23.099493420, 48.195, 6166.0, 78.5239
23.153825620, 48.195, 6798.0, 82.4500
23.208157820, 48.195, 7380.0, 85.9069
23.262490020, 48.195, 7128.0, 84.4275
23.316822220, 48.195, 6334.0, 79.5864
23.371154420, 48.195, 5977.0, 77.3111
23.425486620, 48.195, 6189.0, 78.6702
23.479818820, 48.195, 5793.0, 76.1118
23.534151020, 48.195, 5312.0, 72.8835
23.588483220, 48.195, 4937.0, 70.2638
23.642815420, 48.195, 4933.0, 70.2353
23.697147620, 48.195, 4769.0, 69.0579
23.751479820, 48.195, 4774.0, 69.0941
23.805812020, 48.195, 4595.0, 67.7864
23.860144220, 48.195, 4548.0, 67.4389
23.914476420, 48.195, 4573.0, 67.6240
23.968808620, 48.195, 4438.0, 66.6183
24.023140820, 48.195, 4523.0, 67.2533
24.077473020, 48.195, 4404.0, 66.3626
24.131805220, 48.195, 4395.0, 66.2948
24.186137420, 48.195, 4370.0, 66.1060
24.240469620, 48.195, 4490.0, 67.0075
24.294801820, 48.195, 4395.0, 66.2948
24.349134020, 48.195, 4619.0, 67.9632
24.403466220, 48.195, 5083.0, 71.2952
24.457798420, 48.195, 6362.0, 79.7621
24.512130620, 48.195, 8838.0, 94.0106
24.566462820, 48.195, 11146.0, 105.5746
24.620795020, 48.195, 10066.0, 100.3295
24.675127220, 48.195, 7352.0, 85.7438
24.729459420, 48.195, 5300.0, 72.8011
24.783791620, 48.195, 4654.0, 68.2202
24.838123820, 48.195, 4213.0, 64.9076
24.892456020, 48.195, 4021.0, 63.4114
24.946788220, 48.195, 4049.0, 63.6318
25.001120420, 48.195, 3753.0, 61.2617
25.055452620, 48.195, 3677.0, 60.6383
25.109784820, 48.195, 3757.0, 61.2944
25.164117020, 48.195, 3630.0, 60.2495
25.218449220, 48.195, 3516.0, 59.2959
25.272781420, 48.195, 3640.0, 60.3324
25.327113620, 48.195, 3588.0, 59.8999
25.381445820, 48.195, 3667.0, 60.5558
25.435778020, 48.195, 3562.0, 59.6825
25.490110220, 48.195, 3508.0, 59.2284
25.544442420, 48.195, 3587.0, 59.8916
25.598774620, 48.195, 3392.0, 58.2409
25.653106820, 48.195, 3496.0, 59.1270
25.707439020, 48.195, 3405.0, 58.3524
25.761771220, 48.195, 3487.0, 59.0508
25.816103420, 48.195, 3546.0, 59.5483
25.870435620, 48.195, 3435.0, 58.6089
25.924767820, 48.195, 3326.0, 57.6715
25.979100020, 48.195, 3391.0, 58.2323
26.033432220, 48.195, 3259.0, 57.0877
26.087764420, 48.195, 3264.0, 57.1314
26.142096620, 48.195, 3390.0, 58.2237
26.196428820, 48.195, 3312.0, 57.5500
26.250761020, 48.195, 3516.0, 59.2959
26.305093220, 48.195, 3857.0, 62.1048
26.359425420, 48.195, 4116.0, 64.1561
26.413757620, 48.195, 3948.0, 62.8331
26.468089820, 48.195, 3512.0, 59.2621
26.522422020, 48.195, 3363.0, 57.9914
26.576754220, 48.195, 3224.0, 56.7803
26.631086420, 48.195, 3158.0, 56.1961
26.685418620, 48.195, 3057.0, 55.2901
26.739750820, 48.195, 3172.0, 56.3205
26.794083020, 48.195, 3176.0, 56.3560
26.848415220, 48.195, 3149.0, 56.1160
26.902747420, 48.195, 3028.0, 55.0273
26.957079620, 48.195, 3117.0, 55.8301
27.011411820, 48.195, 3191.0, 56.4889
27.065744020, 48.195, 3356.0, 57.9310
27.120076220, 48.195, 3279.0, 57.2626
27.174408420, 48.195, 3348.0, 57.8619
27.228740620, 48.195, 3694.0, 60.7783
27.283072820, 48.195, 4485.0, 66.9701
27.337405020, 48.195, 5364.0, 73.2393
27.391737220, 48.195, 5812.0, 76.2365
27.446069420, 48.195, 6737.0, 82.0792
27.500401620, 48.195, 9772.0, 98.8534
27.554733820, 48.195, 11552.0, 107.4802
27.609066020, 48.195, 10074.0, 100.3693
27.663398220, 48.195, 6622.0, 81.3757
27.717730420, 48.195, 4434.0, 66.5883
27.772062620, 48.195, 3514.0, 59.2790
27.826394820, 48.195, 3168.0, 56.2850
27.880727020, 48.195, 3017.0, 54.9272
27.935059220, 48.195, 2877.0, 53.6377
27.989391420, 48.195, 2778.0, 52.7067
28.043723620, 48.195, 2797.0, 52.8867
28.098055820, 48.195, 2777.0, 52.6972
28.152388020, 48.195, 2861.0, 53.4883
28.206720220, 48.195, 2707.0, 52.0288
28.261052420, 48.195, 2889.0, 53.7494
28.315384620, 48.195, 2725.0, 52.2015
28.369716820, 48.195, 2703.0, 51.9904
28.424049020, 48.195, 2560.0, 50.5964
28.478381220, 48.195, 2728.0, 52.2303
28.532713420, 48.195, 2580.0, 50.7937
28.587045620, 48.195, 2610.0, 51.0882
28.641377820, 48.195, 2587.0, 50.8626
28.695710020, 48.195, 2677.0, 51.7397
28.750042220, 48.195, 2575.0, 50.7445
28.804374420, 48.195, 2496.0, 49.9600
28.858706620, 48.195, 2530.0, 50.2991
28.913038820, 48.195, 2541.0, 50.4083
28.967371020, 48.195, 2434.0, 49.3356
29.021703220, 48.195, 2480.0, 49.7996
29.076035420, 48.195, 2465.0, 49.6488
29.130367620, 48.195, 2485.0, 49.8498
29.184699820, 48.195, 2543.0, 50.4282
29.239032020, 48.195, 2445.0, 49.4469
29.293364220, 48.195, 2513.0, 50.1298
29.347696420, 48.195, 2542.0, 50.4183
29.402028620, 48.195, 2578.0, 50.7740
29.456360820, 48.195, 2578.0, 50.7740
29.510693020, 48.195, 2424.0, 49.2341
29.565025220, 48.195, 2263.0, 47.5710
29.619357420, 48.195, 2350.0, 48.4768
29.673689620, 48.195, 2339.0, 48.3632
29.728021820, 48.195, 2251.0, 47.4447
29.782354020, 48.195, 2419.0, 49.1833
29.836686220, 48.195, 2288.0, 47.8330
29.891018420, 48.195, 2339.0, 48.3632
29.945350620, 48.195, 2310.0, 48.0625
29.999682820, 48.195, 2299.0, 47.9479
30.054015020, 48.195, 2239.0, 47.3181
30.108347220, 48.195, 2224.0, 47.1593
30.162679420, 48.195, 2292.0, 47.8748
30.217011620, 48.195, 2254.0, 47.4763
30.271343820, 48.195, 2290.0, 47.8539
30.325676020, 48.195, 2267.0, 47.6130
30.380008220, 48.195, 2112.0, 45.9565
30.434340420, 48.195, 2249.0, 47.4236
30.488672620, 48.195, 2283.0, 47.7807
30.543004820, 48.195, 2263.0, 47.5710
30.597337020, 48.195, 2259.0, 47.5289
30.651669220, 48.195, 2171.0, 46.5940
30.706001420, 48.195, 2207.0, 46.9787
30.760333620, 48.195, 2192.0, 46.8188
30.814665820, 48.195, 2073.0, 45.5302
30.868998020, 48.195, 2158.0, 46.4543
30.923330220, 48.195, 2164.0, 46.5188
30.977662420, 48.195, 2128.0, 46.1303
31.031994620, 48.195, 2152.0, 46.3897
31.086326820, 48.195, 2257.0, 47.5079
31.140659020, 48.195, 2223.0, 47.1487
31.194991220, 48.195, 2179.0, 46.6798
31.249323420, 48.195, 2218.0, 47.0956
31.303655620, 48.195, 2672.0, 51.6914
31.357987820, 48.195, 2647.0, 51.4490
31.412320020, 48.195, 2635.0, 51.3323
31.466652220, 48.195, 2430.0, 49.2950
31.520984420, 48.195, 2240.0, 47.3286
31.575316620, 48.195, 2229.0, 47.2123
31.629648820, 48.195, 2547.0, 50.4678
31.683981020, 48.195, 2639.0, 51.3712
31.738313220, 48.195, 2794.0, 52.8583
31.792645420, 48.195, 2509.0, 50.0899
31.846977620, 48.195, 2546.0, 50.4579
31.901309820, 48.195, 2801.0, 52.9245
31.955642020, 48.195, 3516.0, 59.2959
32.009974220, 48.195, 3664.0, 60.5310
32.064306420, 48.195, 3272.0, 57.2014
32.118638620, 48.195, 2804.0, 52.9528
32.172970820, 48.195, 2362.0, 48.6004
32.227303020, 48.195, 2423.0, 49.2240
32.281635220, 48.195, 2930.0, 54.1295
32.335967420, 48.195, 3488.0, 59.0593
32.390299620, 48.195, 3402.0, 58.3267
32.444631820, 48.195, 2934.0, 54.1664
32.498964020, 48.195, 2447.0, 49.4672
32.553296220, 48.195, 2249.0, 47.4236
32.607628420, 48.195, 2204.0, 46.9468
32.661960620, 48.195, 2055.0, 45.3321
32.716292820, 48.195, 2188.0, 46.7761
32.770625020, 48.195, 2095.0, 45.7712
32.824957220, 48.195, 2146.0, 46.3249
32.879289420, 48.195, 2047.0, 45.2438
32.933621620, 48.195, 2118.0, 46.0217
32.987953820, 48.195, 2016.0, 44.8999
33.042286020, 48.195, 2009.0, 44.8219
33.096618220, 48.195, 2074.0, 45.5412
33.150950420, 48.195, 2223.0, 47.1487
33.205282620, 48.195, 2140.0, 46.2601
33.259614820, 48.195, 2053.0, 45.3100
33.313947020, 48.195, 1971.0, 44.3959
33.368279220, 48.195, 1951.0, 44.1701
33.422611420, 48.195, 1926.0, 43.8862
33.476943620, 48.195, 1989.0, 44.5982
33.531275820, 48.195, 2035.0, 45.1110
33.585608020, 48.195, 2055.0, 45.3321
33.639940220, 48.195, 2210.0, 47.0106
33.694272420, 48.195, 2419.0, 49.1833
33.748604620, 48.195, 2389.0, 48.8774
33.802936820, 48.195, 2225.0, 47.1699
33.857269020, 48.195, 1995.0, 44.6654
33.911601220, 48.195, 1913.0, 43.7379
33.965933420, 48.195, 1885.0, 43.4166
34.020265620, 48.195, 1874.0, 43.2897
34.074597820, 48.195, 1898.0, 43.5660
34.128930020, 48.195, 1913.0, 43.7379
34.183262220, 48.195, 1940.0, 44.0454
34.237594420, 48.195, 1778.0, 42.1663
34.291926620, 48.195, 1896.0, 43.5431
34.346258820, 48.195, 1932.0, 43.9545
34.400591020, 48.195, 1842.0, 42.9185
34.454923220, 48.195, 1877.0, 43.3244
34.509255420, 48.195, 1935.0, 43.9886
34.563587620, 48.195, 1887.0, 43.4396
34.617919820, 48.195, 1844.0, 42.9418
34.672252020, 48.195, 1854.0, 43.0581
34.726584220, 48.195, 1852.0, 43.0349
34.780916420, 48.195, 1828.0, 42.7551
34.835248620, 48.195, 1863.0, 43.1625
34.889580820, 48.195, 1924.0, 43.8634
34.943913020, 48.195, 1831.0, 42.7902
34.998245220, 48.195, 1857.0, 43.0929
35.052577420, 48.195, 1984.0, 44.5421
35.106909620, 48.195, 1912.0, 43.7264
35.161241820, 48.195, 1934.0, 43.9773
35.215574020, 48.195, 1825.0, 42.7200
35.269906220, 48.195, 1933.0, 43.9659
35.324238420, 48.195, 2113.0, 45.9674
35.378570620, 48.195, 2466.0, 49.6588
35.432902820, 48.195, 2711.0, 52.0673
35.487235020, 48.195, 2627.0, 51.2543
35.541567220, 48.195, 2399.0, 48.9796
35.595899420, 48.195, 2265.0, 47.5920
35.650231620, 48.195, 2271.0, 47.6550
35.704563820, 48.195, 2578.0, 50.7740
35.758896020, 48.195, 2840.0, 53.2917
35.813228220, 48.195, 2662.0, 51.5946
35.867560420, 48.195, 2431.0, 49.3052
35.921892620, 48.195, 2131.0, 46.1628
35.976224820, 48.195, 2055.0, 45.3321
36.030557020, 48.195, 1947.0, 44.1248
36.084889220, 48.195, 1888.0, 43.4511
36.139221420, 48.195, 1938.0, 44.0227
36.193553620, 48.195, 1926.0, 43.8862
36.247885820, 48.195, 2038.0, 45.1442
36.302218020, 48.195, 1986.0, 44.5646
36.356550220, 48.195, 1980.0, 44.4972
36.410882420, 48.195, 1992.0, 44.6318
36.465214620, 48.195, 1919.0, 43.8064
36.519546820, 48.195, 2008.0, 44.8107
36.573879020, 48.195, 1905.0, 43.6463
36.628211220, 48.195, 1974.0, 44.4297
36.682543420, 48.195, 2016.0, 44.8999
36.736875620, 48.195, 2333.0, 48.3011
36.791207820, 48.195, 2591.0, 50.9019
36.845540020, 48.195, 2570.0, 50.6952
36.899872220, 48.195, 2390.0, 48.8876
36.954204420, 48.195, 2016.0, 44.8999
37.008536620, 48.195, 1942.0, 44.0681
37.062868820, 48.195, 1991.0, 44.6206
37.117201020, 48.195, 1855.0, 43.0697
37.171533220, 48.195, 1933.0, 43.9659
37.225865420, 48.195, 1848.0, 42.9884
37.280197620, 48.195, 1849.0, 43.0000
37.334529820, 48.195, 1943.0, 44.0795
37.388862020, 48.195, 1832.0, 42.8019
37.443194220, 48.195, 1866.0, 43.1972
37.497526420, 48.195, 1846.0, 42.9651
37.551858620, 48.195, 1889.0, 43.4626
37.606190820, 48.195, 1957.0, 44.2380
37.660523020, 48.195, 1942.0, 44.0681
37.714855220, 48.195, 1908.0, 43.6807
37.769187420, 48.195, 1936.0, 44.0000
37.823519620, 48.195, 1926.0, 43.8862
37.877851820, 48.195, 1917.0, 43.7836
37.932184020, 48.195, 1857.0, 43.0929
37.986516220, 48.195, 1896.0, 43.5431
38.040848420, 48.195, 1969.0, 44.3734
38.095180620, 48.195, 1897.0, 43.5546
38.149512820, 48.195, 1896.0, 43.5431
38.203845020, 48.195, 1878.0, 43.3359
38.258177220, 48.195, 1821.0, 42.6732
38.312509420, 48.195, 1873.0, 43.2782
38.366841620, 48.195, 1876.0, 43.3128
38.421173820, 48.195, 1918.0, 43.7950
38.475506020, 48.195, 1952.0, 44.1814
38.529838220, 48.195, 1922.0, 43.8406
38.584170420, 48.195, 1983.0, 44.5309
38.638502620, 48.195, 2056.0, 45.3431
38.692834820, 48.195, 2191.0, 46.8081
38.747167020, 48.195, 2263.0, 47.5710
38.801499220, 48.195, 2260.0, 47.5395
38.855831420, 48.195, 2161.0, 46.4866
38.910163620, 48.195, 2179.0, 46.6798
38.964495820, 48.195, 2363.0, 48.6107
39.018828020, 48.195, 2568.0, 50.6754
39.073160220, 48.195, 2703.0, 51.9904
39.127492420, 48.195, 2695.0, 51.9134
39.181824620, 48.195, 2564.0, 50.6360
39.236156820, 48.195, 2355.0, 48.5283
39.290489020, 48.195, 2384.0, 48.8262
39.344821220, 48.195, 2469.0, 49.6890
39.399153420, 48.195, 2570.0, 50.6952
39.453485620, 48.195, 2372.0, 48.7032
39.507817820, 48.195, 2309.0, 48.0521
39.562150020, 48.195, 2234.0, 47.2652
39.616482220, 48.195, 2201.0, 46.9148
39.670814420, 48.195, 2625.0, 51.2348
39.725146620, 48.195, 3778.0, 61.4654
39.779478820, 48.195, 4468.0, 66.8431
39.833811020, 48.195, 4219.0, 64.9538
39.888143220, 48.195, 3564.0, 59.6992
39.942475420, 48.195, 2960.0, 54.4059
39.996807620, 48.195, 2345.0, 48.4252
40.051139820, 48.195, 2091.0, 45.7275
40.105472020, 48.195, 2041.0, 45.1774
40.159804220, 48.195, 1956.0, 44.2267
40.214136420, 48.195, 1993.0, 44.6430
40.268468620, 48.195, 1943.0, 44.0795
40.322800820, 48.195, 1955.0, 44.2154
40.377133020, 48.195, 1928.0, 43.9090
40.431465220, 48.195, 2007.0, 44.7996
40.485797420, 48.195, 1915.0, 43.7607
40.540129620, 48.195, 2206.0, 46.9681
40.594461820, 48.195, 2283.0, 47.7807
40.648794020, 48.195, 2494.0, 49.9400
40.703126220, 48.195, 2516.0, 50.1597
40.757458420, 48.195, 2260.0, 47.5395
40.811790620, 48.195, 2215.0, 47.0638
40.866122820, 48.195, 2081.0, 45.6180
40.920455020, 48.195, 2133.0, 46.1844
40.974787220, 48.195, 2322.0, 48.1871
41.029119420, 48.195, 2497.0, 49.9700
41.083451620, 48.195, 2493.0, 49.9300
41.137783820, 48.195, 2431.0, 49.3052
41.192116020, 48.195, 2259.0, 47.5289
41.246448220, 48.195, 2133.0, 46.1844
41.300780420, 48.195, 1954.0, 44.2041
41.355112620, 48.195, 1927.0, 43.8976
41.409444820, 48.195, 1869.0, 43.2319
41.463777020, 48.195, 1972.0, 44.4072
41.518109220, 48.195, 1857.0, 43.0929
41.572441420, 48.195, 1863.0, 43.1625
41.626773620, 48.195, 1901.0, 43.6005
41.681105820, 48.195, 1875.0, 43.3013
41.735438020, 48.195, 1872.0, 43.2666
41.789770220, 48.195, 1897.0, 43.5546
41.844102420, 48.195, 1856.0, 43.0813
41.898434620, 48.195, 1887.0, 43.4396
41.952766820, 48.195, 1890.0, 43.4741
42.007099020, 48.195, 1958.0, 44.2493
42.061431220, 48.195, 1895.0, 43.5316
42.115763420, 48.195, 1828.0, 42.7551
42.170095620, 48.195, 1879.0, 43.3474
42.224427820, 48.195, 1863.0, 43.1625
42.278760020, 48.195, 1864.0, 43.1741
42.333092220, 48.195, 1883.0, 43.3935
42.387424420, 48.195, 1993.0, 44.6430
42.441756620, 48.195, 2024.0, 44.9889
42.496088820, 48.195, 1892.0, 43.4971
42.550421020, 48.195, 1990.0, 44.6094
42.604753220, 48.195, 1936.0, 44.0000
42.659085420, 48.195, 1832.0, 42.8019
42.713417620, 48.195, 1929.0, 43.9204
42.767749820, 48.195, 1976.0, 44.4522
42.822082020, 48.195, 1868.0, 43.2204
42.876414220, 48.195, 2082.0, 45.6289
42.930746420, 48.195, 2133.0, 46.1844
42.985078620, 48.195, 2095.0, 45.7712
43.039410820, 48.195, 1980.0, 44.4972
43.093743020, 48.195, 1877.0, 43.3244
43.148075220, 48.195, 1833.0, 42.8135
43.202407420, 48.195, 1787.0, 42.2729
43.256739620, 48.195, 1765.0, 42.0119
43.311071820, 48.195, 1744.0, 41.7612
43.365404020, 48.195, 1803.0, 42.4617
43.419736220, 48.195, 1816.0, 42.6146
43.474068420, 48.195, 1755.0, 41.8927
43.528400620, 48.195, 1780.0, 42.1900
43.582732820, 48.195, 1777.0, 42.1545
43.637065020, 48.195, 1726.0, 41.5452
43.691397220, 48.195, 1774.0, 42.1189
43.745729420, 48.195, 1737.0, 41.6773
43.800061620, 48.195, 1720.0, 41.4729
43.854393820, 48.195, 1713.0, 41.3884
43.908726020, 48.195, 1748.0, 41.8091
43.963058220, 48.195, 1692.0, 41.1339
44.017390420, 48.195, 1771.0, 42.0833
44.071722620, 48.195, 1659.0, 40.7308
44.126054820, 48.195, 1794.0, 42.3556
44.180387020, 48.195, 1749.0, 41.8210
44.234719220, 48.195, 1745.0, 41.7732
44.289051420, 48.195, 1755.0, 41.8927
44.343383620, 48.195, 1810.0, 42.5441
44.397715820, 48.195, 1765.0, 42.0119
44.452048020, 48.195, 1789.0, 42.2966
44.506380220, 48.195, 1746.0, 41.7852
44.560712420, 48.195, 1744.0, 41.7612
44.615044620, 48.195, 1670.0, 40.8656
44.669376820, 48.195, 1687.0, 41.0731
44.723709020, 48.195, 1666.0, 40.8167
44.778041220, 48.195, 1707.0, 41.3159
44.832373420, 48.195, 1677.0, 40.9512
44.886705620, 48.195, 1797.0, 42.3910
44.941037820, 48.195, 1763.0, 41.9881
44.995370020, 48.195, 1713.0, 41.3884
45.049702220, 48.195, 1813.0, 42.5793
45.104034420, 48.195, 1792.0, 42.3320
45.158366620, 48.195, 1738.0, 41.6893
45.212698820, 48.195, 1632.0, 40.3980
45.267031020, 48.195, 1732.0, 41.6173
45.321363220, 48.195, 1826.0, 42.7317
45.375695420, 48.195, 1878.0, 43.3359
45.430027620, 48.195, 2166.0, 46.5403
45.484359820, 48.195, 2330.0, 48.2701
45.538692020, 48.195, 2181.0, 46.7012
45.593024220, 48.195, 2122.0, 46.0652
45.647356420, 48.195, 1902.0, 43.6119
45.701688620, 48.195, 1889.0, 43.4626
45.756020820, 48.195, 1822.0, 42.6849
45.810353020, 48.195, 2049.0, 45.2659
45.864685220, 48.195, 2287.0, 47.8226
45.919017420, 48.195, 2314.0, 48.1041
45.973349620, 48.195, 2205.0, 46.9574
46.027681820, 48.195, 2003.0, 44.7549
46.082014020, 48.195, 1902.0, 43.6119
46.136346220, 48.195, 1767.0, 42.0357
46.190678420, 48.195, 1635.0, 40.4351
46.245010620, 48.195, 1632.0, 40.3980
46.299342820, 48.195, 1685.0, 41.0488
46.353675020, 48.195, 1582.0, 39.7744
46.408007220, 48.195, 1531.0, 39.1280
46.462339420, 48.195, 1657.0, 40.7063
46.516671620, 48.195, 1615.0, 40.1871
46.571003820, 48.195, 1649.0, 40.6079
46.625336020, 48.195, 1778.0, 42.1663
46.679668220, 48.195, 1846.0, 42.9651
46.734000420, 48.195, 1844.0, 42.9418
46.788332620, 48.195, 1794.0, 42.3556
46.842664820, 48.195, 1622.0, 40.2741
46.896997020, 48.195, 1629.0, 40.3609
46.951329220, 48.195, 1597.0, 39.9625
47.005661420, 48.195, 1563.0, 39.5348
47.059993620, 48.195, 1562.0, 39.5221
47.114325820, 48.195, 1576.0, 39.6989
47.168658020, 48.195, 1474.0, 38.3927
47.222990220, 48.195, 1673.0, 40.9023
47.277322420, 48.195, 1801.0, 42.4382
47.331654620, 48.195, 1898.0, 43.5660
47.385986820, 48.195, 1866.0, 43.1972
47.440319020, 48.195, 1762.0, 41.9762
47.494651220, 48.195, 1814.0, 42.5911
47.548983420, 48.195, 1649.0, 40.6079
47.603315620, 48.195, 1624.0, 40.2989
47.657647820, 48.195, 1617.0, 40.2119
47.711980020, 48.195, 1584.0, 39.7995
47.766312220, 48.195, 1515.0, 38.9230
47.820644420, 48.195, 1527.0, 39.0768
47.874976620, 48.195, 1638.0, 40.4722
47.929308820, 48.195, 1565.0, 39.5601
47.983641020, 48.195, 1509.0, 38.8458
48.037973220, 48.195, 1646.0, 40.5709
48.092305420, 48.195, 1629.0, 40.3609
48.146637620, 48.195, 1642.0, 40.5216
48.200969820, 48.195, 1596.0, 39.9500
48.255302020, 48.195, 1548.0, 39.3446
48.309634220, 48.195, 1501.0, 38.7427
48.363966420, 48.195, 1431.0, 37.8286
48.418298620, 48.195, 1452.0, 38.1051
48.472630820, 48.195, 1365.0, 36.9459
48.526963020, 48.195, 1367.0, 36.9730
48.581295220, 48.195, 1405.0, 37.4833
48.635627420, 48.195, 1402.0, 37.4433
48.689959620, 48.195, 1397.0, 37.3765
48.744291820, 48.195, 1442.0, 37.9737
48.798624020, 48.195, 1406.0, 37.4967
48.852956220, 48.195, 1402.0, 37.4433
48.907288420, 48.195, 1465.0, 38.2753
48.961620620, 48.195, 1429.0, 37.8021
49.015952820, 48.195, 1422.0, 37.7094
49.070285020, 48.195, 1428.0, 37.7889
49.124617220, 48.195, 1411.0, 37.5633
49.178949420, 48.195, 1391.0, 37.2961
49.233281620, 48.195, 1376.0, 37.0945
49.287613820, 48.195, 1370.0, 37.0135
49.341946020, 48.195, 1290.0, 35.9166
49.396278220, 48.195, 1410.0, 37.5500
49.450610420, 48.195, 1294.0, 35.9722
49.504942620, 48.195, 1311.0, 36.2077
49.559274820, 48.195, 1269.0, 35.6230
49.613607020, 48.195, 1297.0, 36.0139
49.667939220, 48.195, 1351.0, 36.7560
49.722271420, 48.195, 1322.0, 36.3593
49.776603620, 48.195, 1363.0, 36.9188
49.830935820, 48.195, 1332.0, 36.4966
49.885268020, 48.195, 1266.0, 35.5809
49.939600220, 48.195, 1325.0, 36.4005
49.993932420, 48.195, 1297.0, 36.0139
50.048264620, 48.195, 1295.0, 35.9861
50.102596820, 48.195, 1291.0, 35.9305
50.156929020, 48.195, 1317.0, 36.2905
50.211261220, 48.195, 1334.0, 36.5240
50.265593420, 48.195, 1324.0, 36.3868
50.319925620, 48.195, 1305.0, 36.1248
50.374257820, 48.195, 1344.0, 36.6606
50.428590020, 48.195, 1284.0, 35.8329
50.482922220, 48.195, 1262.0, 35.5246
50.537254420, 48.195, 1283.0, 35.8190
50.591586620, 48.195, 1267.0, 35.5949
50.645918820, 48.195, 1373.0, 37.0540
50.700251020, 48.195, 1334.0, 36.5240
50.754583220, 48.195, 1277.0, 35.7351
50.808915420, 48.195, 1314.0, 36.2491
50.863247620, 48.195, 1288.0, 35.8887
50.917579820, 48.195, 1326.0, 36.4143
50.971912020, 48.195, 1397.0, 37.3765
51.026244220, 48.195, 1424.0, 37.7359
51.080576420, 48.195, 1337.0, 36.5650
51.134908620, 48.195, 1340.0, 36.6060
51.189240820, 48.195, 1340.0, 36.6060
51.243573020, 48.195, 1227.0, 35.0286
51.297905220, 48.195, 1310.0, 36.1939
51.352237420, 48.195, 1372.0, 37.0405
51.406569620, 48.195, 1367.0, 36.9730
51.460901820, 48.195, 1419.0, 37.6696
51.515234020, 48.195, 1344.0, 36.6606
51.569566220, 48.195, 1392.0, 37.3095
51.623898420, 48.195, 1373.0, 37.0540
51.678230620, 48.195, 1295.0, 35.9861
51.732562820, 48.195, 1216.0, 34.8712
51.786895020, 48.195, 1212.0, 34.8138
51.841227220, 48.195, 1203.0, 34.6843
51.895559420, 48.195, 1204.0, 34.6987
51.949891620, 48.195, 1235.0, 35.1426
52.004223820, 48.195, 1189.0, 34.4819
52.058556020, 48.195, 1178.0, 34.3220
52.112888220, 48.195, 1215.0, 34.8569
52.167220420, 48.195, 1166.0, 34.1467
52.221552620, 48.195, 1214.0, 34.8425
52.275884820, 48.195, 1222.0, 34.9571
52.330217020, 48.195, 1154.0, 33.9706
52.384549220, 48.195, 1132.0, 33.6452
52.438881420, 48.195, 1251.0, 35.3695
52.493213620, 48.195, 1215.0, 34.8569
52.547545820, 48.195, 1176.0, 34.2929
52.601878020, 48.195, 1198.0, 34.6121
52.656210220, 48.195, 1156.0, 34.0000
52.710542420, 48.195, 1157.0, 34.0147
52.764874620, 48.195, 1218.0, 34.8999
52.819206820, 48.195, 1212.0, 34.8138
52.873539020, 48.195, 1196.0, 34.5832
52.927871220, 48.195, 1219.0, 34.9142
52.982203420, 48.195, 1141.0, 33.7787
53.036535620, 48.195, 1190.0, 34.4964
53.090867820, 48.195, 1159.0, 34.0441
53.145200020, 48.195, 1090.0, 33.0151
53.199532220, 48.195, 1116.0, 33.4066
53.253864420, 48.195, 1197.0, 34.5977
53.308196620, 48.195, 1105.0, 33.2415
53.362528820, 48.195, 1116.0, 33.4066
53.416861020, 48.195, 1173.0, 34.2491
53.471193220, 48.195, 1209.0, 34.7707
53.525525420, 48.195, 1226.0, 35.0143
53.579857620, 48.195, 1254.0, 35.4119
53.634189820, 48.195, 1295.0, 35.9861
53.688522020, 48.195, 1418.0, 37.6563
53.742854220, 48.195, 1270.0, 35.6371
53.797186420, 48.195, 1345.0, 36.6742
53.851518620, 48.195, 1293.0, 35.9583
53.905850820, 48.195, 1170.0, 34.2053
53.960183020, 48.195, 1158.0, 34.0294
54.014515220, 48.195, 1080.0, 32.8634
54.068847420, 48.195, 1101.0, 33.1813
54.123179620, 48.195, 1127.0, 33.5708
54.177511820, 48.195, 1109.0, 33.3017
54.231844020, 48.195, 1096.0, 33.1059
54.286176220, 48.195, 1037.0, 32.2025
54.340508420, 48.195, 1039.0, 32.2335
54.394840620, 48.195, 1039.0, 32.2335
54.449172820, 48.195, 1067.0, 32.6650
54.503505020, 48.195, 1135.0, 33.6898
54.557837220, 48.195, 1050.0, 32.4037
54.612169420, 48.195, 1034.0, 32.1559
54.666501620, 48.195, 1051.0, 32.4191
54.720833820, 48.195, 1081.0, 32.8786
54.775166020, 48.195, 1036.0, 32.1870
54.829498220, 48.195, 1016.0, 31.8748
54.883830420, 48.195, 1067.0, 32.6650
54.938162620, 48.195, 1041.0, 32.2645
54.992494820, 48.195, 1068.0, 32.6803
55.046827020, 48.195, 957.0, 30.9354
55.101159220, 48.195, 998.0, 31.5911
55.155491420, 48.195, 1028.0, 32.0624
55.209823620, 48.195, 1090.0, 33.0151
55.264155820, 48.195, 1046.0, 32.3419
55.318488020, 48.195, 1053.0, 32.4500
55.372820220, 48.195, 1091.0, 33.0303
55.427152420, 48.195, 1059.0, 32.5423
55.481484620, 48.195, 1048.0, 32.3728
55.535816820, 48.195, 1079.0, 32.8481
55.590149020, 48.195, 1011.0, 31.7962
55.644481220, 48.195, 1000.0, 31.6228
55.698813420, 48.195, 1158.0, 34.0294
55.753145620, 48.195, 1097.0, 33.1210
55.807477820, 48.195, 1154.0, 33.9706
55.861810020, 48.195, 1197.0, 34.5977
55.916142220, 48.195, 1135.0, 33.6898
55.970474420, 48.195, 1079.0, 32.8481
56.024806620, 48.195, 1115.0, 33.3916
56.079138820, 48.195, 1038.0, 32.2180
56.133471020, 48.195, 1061.0, 32.5730
56.187803220, 48.195, 1063.0, 32.6037
56.242135420, 48.195, 1049.0, 32.3883
56.296467620, 48.195, 1025.0, 32.0156
56.350799820, 48.195, 1083.0, 32.9090
56.405132020, 48.195, 1130.0, 33.6155
56.459464220, 48.195, 1018.0, 31.9061
56.513796420, 48.195, 1071.0, 32.7261
56.568128620, 48.195, 1024.0, 32.0000
56.622460820, 48.195, 1116.0, 33.4066
56.676793020, 48.195, 1150.0, 33.9116
56.731125220, 48.195, 1162.0, 34.0881
56.785457420, 48.195, 1064.0, 32.6190
56.839789620, 48.195, 1056.0, 32.4962
56.894121820, 48.195, 1080.0, 32.8634
56.948454020, 48.195, 998.0, 31.5911
57.002786220, 48.195, 976.0, 31.2410
57.057118420, 48.195, 1041.0, 32.2645
57.111450620, 48.195, 1082.0, 32.8938
57.165782820, 48.195, 1097.0, 33.1210
57.220115020, 48.195, 1043.0, 32.2955
57.274447220, 48.195, 1060.0, 32.5576
57.328779420, 48.195, 1016.0, 31.8748
57.383111620, 48.195, 980.0, 31.3050
57.437443820, 48.195, 983.0, 31.3528
57.491776020, 48.195, 961.0, 31.0000
57.546108220, 48.195, 896.0, 29.9333
57.600440420, 48.195, 954.0, 30.8869
57.654772620, 48.195, 886.0, 29.7658
57.709104820, 48.195, 932.0, 30.5287
57.763437020, 48.195, 955.0, 30.9031
57.817769220, 48.195, 976.0, 31.2410
57.872101420, 48.195, 893.0, 29.8831
57.926433620, 48.195, 971.0, 31.1609
57.980765820, 48.195, 972.0, 31.1769
58.035098020, 48.195, 1013.0, 31.8277
58.089430220, 48.195, 931.0, 30.5123
58.143762420, 48.195, 919.0, 30.3150
58.198094620, 48.195, 964.0, 31.0483
58.252426820, 48.195, 959.0, 30.9677
58.306759020, 48.195, 941.0, 30.6757
58.361091220, 48.195, 917.0, 30.2820
58.415423420, 48.195, 941.0, 30.6757
58.469755620, 48.195, 849.0, 29.1376
58.524087820, 48.195, 918.0, 30.2985
58.578420020, 48.195, 905.0, 30.0832
58.632752220, 48.195, 879.0, 29.6479
58.687084420, 48.195, 944.0, 30.7246
58.741416620, 48.195, 931.0, 30.5123
58.795748820, 48.195, 896.0, 29.9333
58.850081020, 48.195, 939.0, 30.6431
58.904413220, 48.195, 881.0, 29.6816
58.958745420, 48.195, 915.0, 30.2490
59.013077620, 48.195, 921.0, 30.3480
59.067409820, 48.195, 924.0, 30.3974
59.121742020, 48.195, 888.0, 29.7993
59.176074220, 48.195, 925.0, 30.4138
59.230406420, 48.195, 967.0, 31.0966
59.284738620, 48.195, 983.0, 31.3528
59.339070820, 48.195, 1075.0, 32.7872
59.393403020, 48.195, 1079.0, 32.8481
59.447735220, 48.195, 1087.0, 32.9697
59.502067420, 48.195, 1009.0, 31.7648
59.556399620, 48.195, 990.0, 31.4643
59.610731820, 48.195, 963.0, 31.0322
59.665064020, 48.195, 888.0, 29.7993
59.719396220, 48.195, 874.0, 29.5635
59.773728420, 48.195, 836.0, 28.9137
59.828060620, 48.195, 829.0, 28.7924
59.882392820, 48.195, 858.0, 29.2916
59.936725020, 48.195, 867.0, 29.4449
59.991057220, 48.195, 878.0, 29.6311
60.045389420, 48.195, 882.0, 29.6985
60.099721620, 48.195, 947.0, 30.7734
60.154053820, 48.195, 889.0, 29.8161
60.208386020, 48.195, 931.0, 30.5123
60.262718220, 48.195, 925.0, 30.4138
60.317050420, 48.195, 864.0, 29.3939
60.371382620, 48.195, 867.0, 29.4449
60.425714820, 48.195, 860.0, 29.3258
60.480047020, 48.195, 904.0, 30.0666
60.534379220, 48.195, 984.0, 31.3688
60.588711420, 48.195, 995.0, 31.5436
60.643043620, 48.195, 975.0, 31.2250
60.697375820, 48.195, 936.0, 30.5941
60.751708020, 48.195, 1018.0, 31.9061
60.806040220, 48.195, 943.0, 30.7083
60.860372420, 48.195, 843.0, 29.0345
60.914704620, 48.195, 865.0, 29.4109
60.969036820, 48.195, 879.0, 29.6479
61.023369020, 48.195, 889.0, 29.8161
61.077701220, 48.195, 853.0, 29.2062
61.132033420, 48.195, 834.0, 28.8791
61.186365620, 48.195, 894.0, 29.8998
61.240697820, 48.195, 770.0, 27.7489
61.295030020, 48.195, 825.0, 28.7228
61.349362220, 48.195, 858.0, 29.2916
61.403694420, 48.195, 784.0, 28.0000
61.458026620, 48.195, 806.0, 28.3901
61.512358820, 48.195, 755.0, 27.4773
61.566691020, 48.195, 824.0, 28.7054
61.621023220, 48.195, 825.0, 28.7228
61.675355420, 48.195, 825.0, 28.7228
61.729687620, 48.195, 790.0, 28.1069
61.784019820, 48.195, 800.0, 28.2843
61.838352020, 48.195, 832.0, 28.8444
61.892684220, 48.195, 786.0, 28.0357
61.947016420, 48.195, 812.0, 28.4956
62.001348620, 48.195, 784.0, 28.0000
62.055680820, 48.195, 752.0, 27.4226
62.110013020, 48.195, 780.0, 27.9285
62.164345220, 48.195, 831.0, 28.8271
62.218677420, 48.195, 843.0, 29.0345
62.273009620, 48.195, 819.0, 28.6182
62.327341820, 48.195, 838.0, 28.9482
62.381674020, 48.195, 812.0, 28.4956
62.436006220, 48.195, 812.0, 28.4956
62.490338420, 48.195, 827.0, 28.7576
62.544670620, 48.195, 839.0, 28.9655
62.599002820, 48.195, 793.0, 28.1603
62.653335020, 48.195, 858.0, 29.2916
62.707667220, 48.195, 844.0, 29.0517
62.761999420, 48.195, 800.0, 28.2843
62.816331620, 48.195, 849.0, 29.1376
62.870663820, 48.195, 836.0, 28.9137
62.924996020, 48.195, 788.0, 28.0713
62.979328220, 48.195, 793.0, 28.1603
63.033660420, 48.195, 801.0, 28.3019
63.087992620, 48.195, 793.0, 28.1603
63.142324820, 48.195, 789.0, 28.0891
63.196657020, 48.195, 829.0, 28.7924
63.250989220, 48.195, 772.0, 27.7849
63.305321420, 48.195, 814.0, 28.5307
63.359653620, 48.195, 790.0, 28.1069
63.413985820, 48.195, 843.0, 29.0345
63.468318020, 48.195, 789.0, 28.0891
63.522650220, 48.195, 839.0, 28.9655
63.576982420, 48.195, 785.0, 28.0179
63.631314620, 48.195, 713.0, 26.7021
63.685646820, 48.195, 795.0, 28.1957
63.739979020, 48.195, 752.0, 27.4226
63.794311220, 48.195, 778.0, 27.8927
63.848643420, 48.195, 849.0, 29.1376
63.902975620, 48.195, 760.0, 27.5681
63.957307820, 48.195, 764.0, 27.6405
64.011640020, 48.195, 768.0, 27.7128
64.065972220, 48.195, 754.0, 27.4591
64.120304420, 48.195, 817.0, 28.5832
64.174636620, 48.195, 776.0, 27.8568
64.228968820, 48.195, 725.0, 26.9258
64.283301020, 48.195, 770.0, 27.7489
64.337633220, 48.195, 772.0, 27.7849
64.391965420, 48.195, 749.0, 27.3679
64.446297620, 48.195, 734.0, 27.0924
64.500629820, 48.195, 680.0, 26.0768
64.554962020, 48.195, 751.0, 27.4044
64.609294220, 48.195, 741.0, 27.2213
64.663626420, 48.195, 776.0, 27.8568
64.717958620, 48.195, 733.0, 27.0740
64.772290820, 48.195, 718.0, 26.7955
64.826623020, 48.195, 755.0, 27.4773
64.880955220, 48.195, 755.0, 27.4773
64.935287420, 48.195, 800.0, 28.2843
64.989619620, 48.195, 758.0, 27.5318
65.043951820, 48.195, 787.0, 28.0535
65.098284020, 48.195, 733.0, 27.0740
65.152616220, 48.195, 726.0, 26.9444
65.206948420, 48.195, 721.0, 26.8514
65.261280620, 48.195, 723.0, 26.8887
65.315612820, 48.195, 759.0, 27.5500
65.369945020, 48.195, 756.0, 27.4955
65.424277220, 48.195, 719.0, 26.8142
65.478609420, 48.195, 792.0, 28.1425
65.532941620, 48.195, 747.0, 27.3313
65.587273820, 48.195, 729.0, 27.0000
65.641606020, 48.195, 746.0, 27.3130
65.695938220, 48.195, 735.0, 27.1109
65.750270420, 48.195, 735.0, 27.1109
65.804602620, 48.195, 736.0, 27.1293
65.858934820, 48.195, 773.0, 27.8029
65.913267020, 48.195, 738.0, 27.1662
65.967599220, 48.195, 768.0, 27.7128
66.021931420, 48.195, 743.0, 27.2580
66.076263620, 48.195, 787.0, 28.0535
66.130595820, 48.195, 713.0, 26.7021
66.184928020, 48.195, 743.0, 27.2580
66.239260220, 48.195, 752.0, 27.4226
66.293592420, 48.195, 768.0, 27.7128
66.347924620, 48.195, 758.0, 27.5318
66.402256820, 48.195, 773.0, 27.8029
66.456589020, 48.195, 669.0, 25.8650
66.510921220, 48.195, 758.0, 27.5318
66.565253420, 48.195, 778.0, 27.8927
66.619585620, 48.195, 721.0, 26.8514
66.673917820, 48.195, 709.0, 26.6271
66.728250020, 48.195, 712.0, 26.6833
66.782582220, 48.195, 729.0, 27.0000
66.836914420, 48.195, 715.0, 26.7395
66.891246620, 48.195, 790.0, 28.1069
66.945578820, 48.195, 728.0, 26.9815
66.999911020, 48.195, 744.0, 27.2764
67.054243220, 48.195, 651.0, 25.5147
67.108575420, 48.195, 712.0, 26.6833
67.162907620, 48.195, 728.0, 26.9815
67.217239820, 48.195, 711.0, 26.6646
67.271572020, 48.195, 716.0, 26.7582
67.325904220, 48.195, 722.0, 26.8701
67.380236420, 48.195, 746.0, 27.3130
67.434568620, 48.195, 744.0, 27.2764
67.488900820, 48.195, 653.0, 25.5539
67.543233020, 48.195, 669.0, 25.8650
67.597565220, 48.195, 657.0, 25.6320
67.651897420, 48.195, 677.0, 26.0192
67.706229620, 48.195, 703.0, 26.5141
67.760561820, 48.195, 704.0, 26.5330
67.814894020, 48.195, 693.0, 26.3249
67.869226220, 48.195, 711.0, 26.6646
67.923558420, 48.195, 717.0, 26.7769
67.977890620, 48.195, 721.0, 26.8514
68.032222820, 48.195, 708.0, 26.6083
68.086555020, 48.195, 742.0, 27.2397
68.140887220, 48.195, 660.0, 25.6905
68.195219420, 48.195, 682.0, 26.1151
68.249551620, 48.195, 710.0, 26.6458
68.303883820, 48.195, 712.0, 26.6833
68.358216020, 48.195, 653.0, 25.5539
68.412548220, 48.195, 681.0, 26.0960
68.466880420, 48.195, 636.0, 25.2190
68.521212620, 48.195, 741.0, 27.2213
68.575544820, 48.195, 713.0, 26.7021
68.629877020, 48.195, 704.0, 26.5330
68.684209220, 48.195, 698.0, 26.4197
68.738541420, 48.195, 687.0, 26.2107
68.792873620, 48.195, 729.0, 27.0000
68.847205820, 48.195, 757.0, 27.5136
68.901538020, 48.195, 681.0, 26.0960
68.955870220, 48.195, 742.0, 27.2397
69.010202420, 48.195, 707.0, 26.5895
69.064534620, 48.195, 713.0, 26.7021
69.118866820, 48.195, 731.0, 27.0370
69.173199020, 48.195, 680.0, 26.0768
69.227531220, 48.195, 664.0, 25.7682
69.281863420, 48.195, 690.0, 26.2679
69.336195620, 48.195, 710.0, 26.6458
69.390527820, 48.195, 677.0, 26.0192
69.444860020, 48.195, 731.0, 27.0370
69.499192220, 48.195, 699.0, 26.4386
69.553524420, 48.195, 631.0, 25.1197
69.607856620, 48.195, 724.0, 26.9072
69.662188820, 48.195, 647.0, 25.4362
69.716521020, 48.195, 729.0, 27.0000
69.770853220, 48.195, 679.0, 26.0576
69.825185420, 48.195, 688.0, 26.2298
69.879517620, 48.195, 687.0, 26.2107
69.933849820, 48.195, 644.0, 25.3772
69.988182020, 48.195, 670.0, 25.8844
70.042514220, 48.195, 696.0, 26.3818
70.096846420, 48.195, 675.0, 25.9808
70.151178620, 48.195, 716.0, 26.7582
70.205510820, 48.195, 664.0, 25.7682
70.259843020, 48.195, 726.0, 26.9444
70.314175220, 48.195, 669.0, 25.8650
70.368507420, 48.195, 674.0, 25.9615
70.422839620, 48.195, 671.0, 25.9037
70.477171820, 48.195, 670.0, 25.8844
70.531504020, 48.195, 639.0, 25.2784
70.585836220, 48.195, 679.0, 26.0576
70.640168420, 48.195, 691.0, 26.2869
70.694500620, 48.195, 718.0, 26.7955
70.748832820, 48.195, 673.0, 25.9422
70.803165020, 48.195, 679.0, 26.0576
70.857497220, 48.195, 674.0, 25.9615
70.911829420, 48.195, 698.0, 26.4197
70.966161620, 48.195, 713.0, 26.7021
71.020493820, 48.195, 699.0, 26.4386
71.074826020, 48.195, 698.0, 26.4197
71.129158220, 48.195, 718.0, 26.7955
71.183490420, 48.195, 662.0, 25.7294
71.237822620, 48.195, 744.0, 27.2764
71.292154820, 48.195, 741.0, 27.2213
71.346487020, 48.195, 711.0, 26.6646
71.400819220, 48.195, 696.0, 26.3818
71.455151420, 48.195, 682.0, 26.1151
71.509483620, 48.195, 674.0, 25.9615
71.563815820, 48.195, 696.0, 26.3818
71.618148020, 48.195, 719.0, 26.8142
71.672480220, 48.195, 680.0, 26.0768
71.726812420, 48.195, 697.0, 26.4008
71.781144620, 48.195, 674.0, 25.9615
71.835476820, 48.195, 655.0, 25.5930
71.889809020, 48.195, 655.0, 25.5930
71.944141220, 48.195, 665.0, 25.7876
71.998473420, 48.195, 675.0, 25.9808
72.052805620, 48.195, 658.0, 25.6515
72.107137820, 48.195, 677.0, 26.0192
72.161470020, 48.195, 653.0, 25.5539
72.215802220, 48.195, 717.0, 26.7769
72.270134420, 48.195, 694.0, 26.3439
72.324466620, 48.195, 694.0, 26.3439
72.378798820, 48.195, 694.0, 26.3439
72.433131020, 48.195, 624.0, 24.9800
72.487463220, 48.195, 698.0, 26.4197
72.541795420, 48.195, 658.0, 25.6515
72.596127620, 48.195, 656.0, 25.6125
72.650459820, 48.195, 724.0, 26.9072
72.704792020, 48.195, 646.0, 25.4165
72.759124220, 48.195, 650.0, 25.4951
72.813456420, 48.195, 642.0, 25.3377
72.867788620, 48.195, 658.0, 25.6515
72.922120820, 48.195, 702.0, 26.4953
72.976453020, 48.195, 678.0, 26.0384
73.030785220, 48.195, 635.0, 25.1992
73.085117420, 48.195, 662.0, 25.7294
73.139449620, 48.195, 699.0, 26.4386
73.193781820, 48.195, 693.0, 26.3249
73.248114020, 48.195, 652.0, 25.5343
73.302446220, 48.195, 619.0, 24.8797
73.356778420, 48.195, 654.0, 25.5734
73.411110620, 48.195, 659.0, 25.6710
73.465442820, 48.195, 681.0, 26.0960
73.519775020, 48.195, 678.0, 26.0384
73.574107220, 48.195, 673.0, 25.9422
73.628439420, 48.195, 702.0, 26.4953
73.682771620, 48.195, 656.0, 25.6125
73.737103820, 48.195, 646.0, 25.4165
73.791436020, 48.195, 672.0, 25.9230
73.845768220, 48.195, 657.0, 25.6320
73.900100420, 48.195, 650.0, 25.4951
73.954432620, 48.195, 706.0, 26.5707
74.008764820, 48.195, 669.0, 25.8650
74.063097020, 48.195, 662.0, 25.7294
74.117429220, 48.195, 627.0, 25.0400
74.171761420, 48.195, 653.0, 25.5539
74.226093620, 48.195, 744.0, 27.2764
74.280425820, 48.195, 623.0, 24.9600
74.334758020, 48.195, 666.0, 25.8070
74.389090220, 48.195, 696.0, 26.3818
74.443422420, 48.195, 688.0, 26.2298
74.497754620, 48.195, 701.0, 26.4764
74.552086820, 48.195, 697.0, 26.4008
74.606419020, 48.195, 667.0, 25.8263
74.660751220, 48.195, 664.0, 25.7682
74.715083420, 48.195, 665.0, 25.7876
74.769415620, 48.195, 671.0, 25.9037
74.823747820, 48.195, 692.0, 26.3059
74.878080020, 48.195, 651.0, 25.5147
74.932412220, 48.195, 676.0, 26.0000
74.986744420, 48.195, 701.0, 26.4764
75.041076620, 48.195, 689.0, 26.2488
75.095408820, 48.195, 744.0, 27.2764
75.149741020, 48.195, 700.0, 26.4575
75.204073220, 48.195, 707.0, 26.5895
75.258405420, 48.195, 694.0, 26.3439
75.312737620, 48.195, 735.0, 27.1109
75.367069820, 48.195, 682.0, 26.1151
75.421402020, 48.195, 694.0, 26.3439
75.475734220, 48.195, 681.0, 26.0960
75.530066420, 48.195, 683.0, 26.1343
75.584398620, 48.195, 675.0, 25.9808
75.638730820, 48.195, 701.0, 26.4764
75.693063020, 48.195, 704.0, 26.5330
75.747395220, 48.195, 715.0, 26.7395
75.801727420, 48.195, 647.0, 25.4362
75.856059620, 48.195, 662.0, 25.7294
75.910391820, 48.195, 672.0, 25.9230
75.964724020, 48.195, 695.0, 26.3629
76.019056220, 48.195, 735.0, 27.1109
76.073388420, 48.195, 674.0, 25.9615
76.127720620, 48.195, 681.0, 26.0960
76.182052820, 48.195, 684.0, 26.1534
76.236385020, 48.195, 642.0, 25.3377
76.290717220, 48.195, 685.0, 26.1725
76.345049420, 48.195, 661.0, 25.7099
76.399381620, 48.195, 711.0, 26.6646
76.453713820, 48.195, 667.0, 25.8263
76.508046020, 48.195, 679.0, 26.0576
76.562378220, 48.195, 693.0, 26.3249
76.616710420, 48.195, 687.0, 26.2107
76.671042620, 48.195, 689.0, 26.2488
76.725374820, 48.195, 800.0, 28.2843
76.779707020, 48.195, 746.0, 27.3130
76.834039220, 48.195, 702.0, 26.4953
76.888371420, 48.195, 665.0, 25.7876
76.942703620, 48.195, 679.0, 26.0576
76.997035820, 48.195, 716.0, 26.7582
77.051368020, 48.195, 686.0, 26.1916
77.105700220, 48.195, 674.0, 25.9615
77.160032420, 48.195, 693.0, 26.3249
77.214364620, 48.195, 662.0, 25.7294
77.268696820, 48.195, 651.0, 25.5147
77.323029020, 48.195, 695.0, 26.3629
77.377361220, 48.195, 680.0, 26.0768
77.431693420, 48.195, 624.0, 24.9800
77.486025620, 48.195, 686.0, 26.1916
77.540357820, 48.195, 651.0, 25.5147
77.594690020, 48.195, 660.0, 25.6905
77.649022220, 48.195, 687.0, 26.2107
77.703354420, 48.195, 690.0, 26.2679
77.757686620, 48.195, 687.0, 26.2107
77.812018820, 48.195, 692.0, 26.3059
77.866351020, 48.195, 697.0, 26.4008
77.920683220, 48.195, 673.0, 25.9422
77.975015420, 48.195, 682.0, 26.1151
78.029347620, 48.195, 665.0, 25.7876
78.083679820, 48.195, 654.0, 25.5734
78.138012020, 48.195, 694.0, 26.3439
78.192344220, 48.195, 726.0, 26.9444
78.246676420, 48.195, 653.0, 25.5539
78.301008620, 48.195, 688.0, 26.2298
78.355340820, 48.195, 702.0, 26.4953
78.409673020, 48.195, 708.0, 26.6083
78.464005220, 48.195, 700.0, 26.4575
78.518337420, 48.195, 710.0, 26.6458
78.572669620, 48.195, 741.0, 27.2213
78.627001820, 48.195, 749.0, 27.3679
78.681334020, 48.195, 730.0, 27.0185
78.735666220, 48.195, 733.0, 27.0740
78.789998420, 48.195, 749.0, 27.3679
78.844330620, 48.195, 759.0, 27.5500
78.898662820, 48.195, 777.0, 27.8747
78.952995020, 48.195, 650.0, 25.4951
79.007327220, 48.195, 715.0, 26.7395
79.061659420, 48.195, 685.0, 26.1725
79.115991620, 48.195, 709.0, 26.6271
79.170323820, 48.195, 661.0, 25.7099
79.224656020, 48.195, 701.0, 26.4764
79.278988220, 48.195, 672.0, 25.9230
79.333320420, 48.195, 664.0, 25.7682
79.387652620, 48.195, 720.0, 26.8328
79.441984820, 48.195, 706.0, 26.5707
79.496317020, 48.195, 684.0, 26.1534
79.550649220, 48.195, 654.0, 25.5734
79.604981420, 48.195, 677.0, 26.0192
79.659313620, 48.195, 656.0, 25.6125
79.713645820, 48.195, 709.0, 26.6271
79.767978020, 48.195, 675.0, 25.9808
79.822310220, 48.195, 650.0, 25.4951
79.876642420, 48.195, 711.0, 26.6646
79.930974620, 48.195, 682.0, 26.1151
79.985306820, 48.195, 648.0, 25.4558
79.996173260, 48.195, 668.0, 25.8457