File: XRD/2025_06_03_Ag_Behenate_3_60_8min.csv
[Measurement conditions]
Sample identification,2025_06_03_Ag_Behenate_3_60_8min
Comment - 1,"Silver Behenate Standard"
Anode material,Cu
K-Alpha1 wavelength,1.5405980
K-Alpha2 wavelength,1.5444260
Ratio K-Alpha2/K-Alpha1,0.500
Divergence slit,Fixed,0.76mm
Monochromator used,NO
Generator voltage, 40
Tube current, 15
File date and time,03/Jun/2025 16:03
Unit cell,
h k l, 0 0 0
Scan axis,Gonio
Scan range,2.995000000,60.000344240
Scan step size,0.0108664
No. of points, 5246
Scan type,CONTINUOUS
Time per step,18.870
[Scan points]
Angle, TimePerStep, Intensity, ESD
3.000433220, 18.870, 44111.0, 210.0262
3.043898980, 18.870, 42637.0, 206.4873
3.087364740, 18.870, 40569.0, 201.4175
3.130830500, 18.870, 38323.0, 195.7626
3.174296260, 18.870, 36158.0, 190.1526
3.217762020, 18.870, 33812.0, 183.8804
3.261227780, 18.870, 32059.0, 179.0503
3.304693540, 18.870, 29839.0, 172.7397
3.348159300, 18.870, 28337.0, 168.3360
3.391625060, 18.870, 26697.0, 163.3922
3.435090820, 18.870, 25355.0, 159.2325
3.478556580, 18.870, 23222.0, 152.3877
3.522022340, 18.870, 22316.0, 149.3854
3.565488100, 18.870, 20818.0, 144.2844
3.608953860, 18.870, 19780.0, 140.6414
3.652419620, 18.870, 18700.0, 136.7479
3.695885380, 18.870, 17074.0, 130.6675
3.739351140, 18.870, 16082.0, 126.8148
3.782816900, 18.870, 15024.0, 122.5724
3.826282660, 18.870, 14047.0, 118.5200
3.869748420, 18.870, 13286.0, 115.2649
3.913214180, 18.870, 12383.0, 111.2789
3.956679940, 18.870, 11627.0, 107.8286
4.000145700, 18.870, 10952.0, 104.6518
4.043611460, 18.870, 10220.0, 101.0940
4.087077220, 18.870, 9687.0, 98.4226
4.130542980, 18.870, 9061.0, 95.1893
4.174008740, 18.870, 8758.0, 93.5842
4.217474500, 18.870, 8287.0, 91.0330
4.260940260, 18.870, 7887.0, 88.8088
4.304406020, 18.870, 7789.0, 88.2553
4.347871780, 18.870, 7659.0, 87.5157
4.391337540, 18.870, 8184.0, 90.4655
4.434803300, 18.870, 9516.0, 97.5500
4.478269060, 18.870, 11138.0, 105.5367
4.521734820, 18.870, 11550.0, 107.4709
4.565200580, 18.870, 8312.0, 91.1702
4.608666340, 18.870, 5605.0, 74.8665
4.652132100, 18.870, 4441.0, 66.6408
4.695597860, 18.870, 3642.0, 60.3490
4.739063620, 18.870, 3316.0, 57.5847
4.782529380, 18.870, 2906.0, 53.9073
4.825995140, 18.870, 2619.0, 51.1762
4.869460900, 18.870, 2533.0, 50.3289
4.912926660, 18.870, 2399.0, 48.9796
4.956392420, 18.870, 2378.0, 48.7647
4.999858180, 18.870, 2215.0, 47.0638
5.043323940, 18.870, 2230.0, 47.2229
5.086789700, 18.870, 2227.0, 47.1911
5.130255460, 18.870, 2295.0, 47.9062
5.173721220, 18.870, 2158.0, 46.4543
5.217186980, 18.870, 2224.0, 47.1593
5.260652740, 18.870, 2141.0, 46.2709
5.304118500, 18.870, 2255.0, 47.4868
5.347584260, 18.870, 2198.0, 46.8828
5.391050020, 18.870, 2215.0, 47.0638
5.434515780, 18.870, 2121.0, 46.0543
5.477981540, 18.870, 2036.0, 45.1221
5.521447300, 18.870, 1989.0, 44.5982
5.564913060, 18.870, 1909.0, 43.6921
5.608378820, 18.870, 1964.0, 44.3170
5.651844580, 18.870, 1971.0, 44.3959
5.695310340, 18.870, 2006.0, 44.7884
5.738776100, 18.870, 2249.0, 47.4236
5.782241860, 18.870, 2441.0, 49.4065
5.825707620, 18.870, 2841.0, 53.3010
5.869173380, 18.870, 3440.0, 58.6515
5.912639140, 18.870, 4591.0, 67.7569
5.956104900, 18.870, 6356.0, 79.7245
5.999570660, 18.870, 8321.0, 91.2195
6.043036420, 18.870, 8455.0, 91.9511
6.086502180, 18.870, 5211.0, 72.1873
6.129967940, 18.870, 2907.0, 53.9166
6.173433700, 18.870, 2080.0, 45.6070
6.216899460, 18.870, 1584.0, 39.7995
6.260365220, 18.870, 1342.0, 36.6333
6.303830980, 18.870, 1224.0, 34.9857
6.347296740, 18.870, 1133.0, 33.6601
6.390762500, 18.870, 1063.0, 32.6037
6.434228260, 18.870, 1023.0, 31.9844
6.477694020, 18.870, 986.0, 31.4006
6.521159780, 18.870, 945.0, 30.7409
6.564625540, 18.870, 926.0, 30.4302
6.608091300, 18.870, 918.0, 30.2985
6.651557060, 18.870, 893.0, 29.8831
6.695022820, 18.870, 876.0, 29.5973
6.738488580, 18.870, 823.0, 28.6880
6.781954340, 18.870, 859.0, 29.3087
6.825420100, 18.870, 843.0, 29.0345
6.868885860, 18.870, 884.0, 29.7321
6.912351620, 18.870, 856.0, 29.2575
6.955817380, 18.870, 920.0, 30.3315
6.999283140, 18.870, 890.0, 29.8329
7.042748900, 18.870, 1072.0, 32.7414
7.086214660, 18.870, 1064.0, 32.6190
7.129680420, 18.870, 1226.0, 35.0143
7.173146180, 18.870, 1295.0, 35.9861
7.216611940, 18.870, 1520.0, 38.9872
7.260077700, 18.870, 1811.0, 42.5558
7.303543460, 18.870, 2146.0, 46.3249
7.347009220, 18.870, 2620.0, 51.1859
7.390474980, 18.870, 3452.0, 58.7537
7.433940740, 18.870, 5069.0, 71.1969
7.477406500, 18.870, 6899.0, 83.0602
7.520872260, 18.870, 9097.0, 95.3782
7.564338020, 18.870, 8569.0, 92.5689
7.607803780, 18.870, 5041.0, 71.0000
7.651269540, 18.870, 2754.0, 52.4786
7.694735300, 18.870, 1633.0, 40.4104
7.738201060, 18.870, 1176.0, 34.2929
7.781666820, 18.870, 840.0, 28.9828
7.825132580, 18.870, 834.0, 28.8791
7.868598340, 18.870, 734.0, 27.0924
7.912064100, 18.870, 662.0, 25.7294
7.955529860, 18.870, 656.0, 25.6125
7.998995620, 18.870, 640.0, 25.2982
8.042461380, 18.870, 615.0, 24.7992
8.085927140, 18.870, 597.0, 24.4336
8.129392900, 18.870, 607.0, 24.6374
8.172858660, 18.870, 637.0, 25.2389
8.216324420, 18.870, 562.0, 23.7065
8.259790180, 18.870, 587.0, 24.2281
8.303255940, 18.870, 557.0, 23.6008
8.346721700, 18.870, 576.0, 24.0000
8.390187460, 18.870, 565.0, 23.7697
8.433653220, 18.870, 598.0, 24.4540
8.477118980, 18.870, 573.0, 23.9374
8.520584740, 18.870, 558.0, 23.6220
8.564050500, 18.870, 673.0, 25.9422
8.607516260, 18.870, 697.0, 26.4008
8.650982020, 18.870, 688.0, 26.2298
8.694447780, 18.870, 817.0, 28.5832
8.737913540, 18.870, 894.0, 29.8998
8.781379300, 18.870, 1017.0, 31.8904
8.824845060, 18.870, 1211.0, 34.7994
8.868310820, 18.870, 1484.0, 38.5227
8.911776580, 18.870, 1907.0, 43.6692
8.955242340, 18.870, 2539.0, 50.3885
8.998708100, 18.870, 3410.0, 58.3952
9.042173860, 18.870, 4509.0, 67.1491
9.085639620, 18.870, 4147.0, 64.3972
9.129105380, 18.870, 2492.0, 49.9199
9.172571140, 18.870, 1518.0, 38.9615
9.216036900, 18.870, 936.0, 30.5941
9.259502660, 18.870, 766.0, 27.6767
9.302968420, 18.870, 691.0, 26.2869
9.346434180, 18.870, 639.0, 25.2784
9.389899940, 18.870, 583.0, 24.1454
9.433365700, 18.870, 624.0, 24.9800
9.476831460, 18.870, 521.0, 22.8254
9.520297220, 18.870, 513.0, 22.6495
9.563762980, 18.870, 531.0, 23.0434
9.607228740, 18.870, 502.0, 22.4054
9.650694500, 18.870, 499.0, 22.3383
9.694160260, 18.870, 491.0, 22.1585
9.737626020, 18.870, 478.0, 21.8632
9.781091780, 18.870, 543.0, 23.3024
9.824557540, 18.870, 497.0, 22.2935
9.868023300, 18.870, 499.0, 22.3383
9.911489060, 18.870, 515.0, 22.6936
9.954954820, 18.870, 519.0, 22.7816
9.998420580, 18.870, 554.0, 23.5372
10.041886340, 18.870, 573.0, 23.9374
10.085352100, 18.870, 592.0, 24.3311
10.128817860, 18.870, 699.0, 26.4386
10.172283620, 18.870, 702.0, 26.4953
10.215749380, 18.870, 758.0, 27.5318
10.259215140, 18.870, 855.0, 29.2404
10.302680900, 18.870, 998.0, 31.5911
10.346146660, 18.870, 1153.0, 33.9559
10.389612420, 18.870, 1550.0, 39.3700
10.433078180, 18.870, 1996.0, 44.6766
10.476543940, 18.870, 2698.0, 51.9423
10.520009700, 18.870, 3610.0, 60.0833
10.563475460, 18.870, 4697.0, 68.5347
10.606941220, 18.870, 3821.0, 61.8142
10.650406980, 18.870, 2332.0, 48.2908
10.693872740, 18.870, 1347.0, 36.7015
10.737338500, 18.870, 888.0, 29.7993
10.780804260, 18.870, 666.0, 25.8070
10.824270020, 18.870, 557.0, 23.6008
10.867735780, 18.870, 549.0, 23.4307
10.911201540, 18.870, 524.0, 22.8910
10.954667300, 18.870, 548.0, 23.4094
10.998133060, 18.870, 520.0, 22.8035
11.041598820, 18.870, 471.0, 21.7025
11.085064580, 18.870, 488.0, 22.0907
11.128530340, 18.870, 446.0, 21.1187
11.171996100, 18.870, 469.0, 21.6564
11.215461860, 18.870, 438.0, 20.9284
11.258927620, 18.870, 417.0, 20.4206
11.302393380, 18.870, 454.0, 21.3073
11.345859140, 18.870, 449.0, 21.1896
11.389324900, 18.870, 449.0, 21.1896
11.432790660, 18.870, 425.0, 20.6155
11.476256420, 18.870, 456.0, 21.3542
11.519722180, 18.870, 483.0, 21.9773
11.563187940, 18.870, 499.0, 22.3383
11.606653700, 18.870, 489.0, 22.1133
11.650119460, 18.870, 563.0, 23.7276
11.693585220, 18.870, 519.0, 22.7816
11.737050980, 18.870, 528.0, 22.9783
11.780516740, 18.870, 583.0, 24.1454
11.823982500, 18.870, 630.0, 25.0998
11.867448260, 18.870, 735.0, 27.1109
11.910914020, 18.870, 825.0, 28.7228
11.954379780, 18.870, 1038.0, 32.2180
11.997845540, 18.870, 1307.0, 36.1525
12.041311300, 18.870, 1717.0, 41.4367
12.084777060, 18.870, 1887.0, 43.4396
12.128242820, 18.870, 1691.0, 41.1218
12.171708580, 18.870, 1093.0, 33.0606
12.215174340, 18.870, 747.0, 27.3313
12.258640100, 18.870, 549.0, 23.4307
12.302105860, 18.870, 513.0, 22.6495
12.345571620, 18.870, 506.0, 22.4944
12.389037380, 18.870, 478.0, 21.8632
12.432503140, 18.870, 486.0, 22.0454
12.475968900, 18.870, 412.0, 20.2978
12.519434660, 18.870, 456.0, 21.3542
12.562900420, 18.870, 429.0, 20.7123
12.606366180, 18.870, 405.0, 20.1246
12.649831940, 18.870, 459.0, 21.4243
12.693297700, 18.870, 426.0, 20.6398
12.736763460, 18.870, 409.0, 20.2237
12.780229220, 18.870, 439.0, 20.9523
12.823694980, 18.870, 402.0, 20.0499
12.867160740, 18.870, 405.0, 20.1246
12.910626500, 18.870, 432.0, 20.7846
12.954092260, 18.870, 433.0, 20.8087
12.997558020, 18.870, 466.0, 21.5870
13.041023780, 18.870, 463.0, 21.5174
13.084489540, 18.870, 485.0, 22.0227
13.127955300, 18.870, 495.0, 22.2486
13.171421060, 18.870, 488.0, 22.0907
13.214886820, 18.870, 446.0, 21.1187
13.258352580, 18.870, 510.0, 22.5832
13.301818340, 18.870, 572.0, 23.9165
13.345284100, 18.870, 582.0, 24.1247
13.388749860, 18.870, 666.0, 25.8070
13.432215620, 18.870, 824.0, 28.7054
13.475681380, 18.870, 1014.0, 31.8434
13.519147140, 18.870, 1373.0, 37.0540
13.562612900, 18.870, 1700.0, 41.2311
13.606078660, 18.870, 1955.0, 44.2154
13.649544420, 18.870, 1704.0, 41.2795
13.693010180, 18.870, 1130.0, 33.6155
13.736475940, 18.870, 751.0, 27.4044
13.779941700, 18.870, 602.0, 24.5357
13.823407460, 18.870, 481.0, 21.9317
13.866873220, 18.870, 469.0, 21.6564
13.910338980, 18.870, 417.0, 20.4206
13.953804740, 18.870, 432.0, 20.7846
13.997270500, 18.870, 402.0, 20.0499
14.040736260, 18.870, 414.0, 20.3470
14.084202020, 18.870, 396.0, 19.8997
14.127667780, 18.870, 421.0, 20.5183
14.171133540, 18.870, 389.0, 19.7231
14.214599300, 18.870, 380.0, 19.4936
14.258065060, 18.870, 417.0, 20.4206
14.301530820, 18.870, 373.0, 19.3132
14.344996580, 18.870, 377.0, 19.4165
14.388462340, 18.870, 387.0, 19.6723
14.431928100, 18.870, 383.0, 19.5704
14.475393860, 18.870, 409.0, 20.2237
14.518859620, 18.870, 374.0, 19.3391
14.562325380, 18.870, 361.0, 19.0000
14.605791140, 18.870, 390.0, 19.7484
14.649256900, 18.870, 402.0, 20.0499
14.692722660, 18.870, 395.0, 19.8746
14.736188420, 18.870, 409.0, 20.2237
14.779654180, 18.870, 448.0, 21.1660
14.823119940, 18.870, 432.0, 20.7846
14.866585700, 18.870, 431.0, 20.7605
14.910051460, 18.870, 478.0, 21.8632
14.953517220, 18.870, 589.0, 24.2693
14.996982980, 18.870, 580.0, 24.0832
15.040448740, 18.870, 669.0, 25.8650
15.083914500, 18.870, 710.0, 26.6458
15.127380260, 18.870, 837.0, 28.9310
15.170846020, 18.870, 780.0, 27.9285
15.214311780, 18.870, 622.0, 24.9399
15.257777540, 18.870, 489.0, 22.1133
15.301243300, 18.870, 437.0, 20.9045
15.344709060, 18.870, 417.0, 20.4206
15.388174820, 18.870, 376.0, 19.3907
15.431640580, 18.870, 373.0, 19.3132
15.475106340, 18.870, 396.0, 19.8997
15.518572100, 18.870, 428.0, 20.6882
15.562037860, 18.870, 379.0, 19.4679
15.605503620, 18.870, 383.0, 19.5704
15.648969380, 18.870, 370.0, 19.2354
15.692435140, 18.870, 392.0, 19.7990
15.735900900, 18.870, 344.0, 18.5472
15.779366660, 18.870, 366.0, 19.1311
15.822832420, 18.870, 376.0, 19.3907
15.866298180, 18.870, 401.0, 20.0250
15.909763940, 18.870, 365.0, 19.1050
15.953229700, 18.870, 400.0, 20.0000
15.996695460, 18.870, 359.0, 18.9473
16.040161220, 18.870, 374.0, 19.3391
16.083626980, 18.870, 384.0, 19.5959
16.127092740, 18.870, 388.0, 19.6977
16.170558500, 18.870, 408.0, 20.1990
16.214024260, 18.870, 339.0, 18.4120
16.257490020, 18.870, 404.0, 20.0998
16.300955780, 18.870, 402.0, 20.0499
16.344421540, 18.870, 394.0, 19.8494
16.387887300, 18.870, 397.0, 19.9249
16.431353060, 18.870, 482.0, 21.9545
16.474818820, 18.870, 483.0, 21.9773
16.518284580, 18.870, 563.0, 23.7276
16.561750340, 18.870, 691.0, 26.2869
16.605216100, 18.870, 769.0, 27.7308
16.648681860, 18.870, 905.0, 30.0832
16.692147620, 18.870, 816.0, 28.5657
16.735613380, 18.870, 671.0, 25.9037
16.779079140, 18.870, 487.0, 22.0681
16.822544900, 18.870, 420.0, 20.4939
16.866010660, 18.870, 395.0, 19.8746
16.909476420, 18.870, 414.0, 20.3470
16.952942180, 18.870, 397.0, 19.9249
16.996407940, 18.870, 340.0, 18.4391
17.039873700, 18.870, 367.0, 19.1572
17.083339460, 18.870, 382.0, 19.5448
17.126805220, 18.870, 339.0, 18.4120
17.170270980, 18.870, 367.0, 19.1572
17.213736740, 18.870, 379.0, 19.4679
17.257202500, 18.870, 366.0, 19.1311
17.300668260, 18.870, 345.0, 18.5742
17.344134020, 18.870, 393.0, 19.8242
17.387599780, 18.870, 383.0, 19.5704
17.431065540, 18.870, 383.0, 19.5704
17.474531300, 18.870, 341.0, 18.4662
17.517997060, 18.870, 329.0, 18.1384
17.561462820, 18.870, 360.0, 18.9737
17.604928580, 18.870, 318.0, 17.8326
17.648394340, 18.870, 381.0, 19.5192
17.691860100, 18.870, 347.0, 18.6279
17.735325860, 18.870, 385.0, 19.6214
17.778791620, 18.870, 380.0, 19.4936
17.822257380, 18.870, 351.0, 18.7350
17.865723140, 18.870, 370.0, 19.2354
17.909188900, 18.870, 400.0, 20.0000
17.952654660, 18.870, 335.0, 18.3030
17.996120420, 18.870, 407.0, 20.1742
18.039586180, 18.870, 386.0, 19.6469
18.083051940, 18.870, 435.0, 20.8567
18.126517700, 18.870, 439.0, 20.9523
18.169983460, 18.870, 418.0, 20.4450
18.213449220, 18.870, 453.0, 21.2838
18.256914980, 18.870, 480.0, 21.9089
18.300380740, 18.870, 404.0, 20.0998
18.343846500, 18.870, 403.0, 20.0749
18.387312260, 18.870, 360.0, 18.9737
18.430778020, 18.870, 330.0, 18.1659
18.474243780, 18.870, 371.0, 19.2614
18.517709540, 18.870, 403.0, 20.0749
18.561175300, 18.870, 388.0, 19.6977
18.604641060, 18.870, 392.0, 19.7990
18.648106820, 18.870, 342.0, 18.4932
18.691572580, 18.870, 414.0, 20.3470
18.735038340, 18.870, 425.0, 20.6155
18.778504100, 18.870, 409.0, 20.2237
18.821969860, 18.870, 428.0, 20.6882
18.865435620, 18.870, 492.0, 22.1811
18.908901380, 18.870, 506.0, 22.4944
18.952367140, 18.870, 581.0, 24.1039
18.995832900, 18.870, 670.0, 25.8844
19.039298660, 18.870, 805.0, 28.3725
19.082764420, 18.870, 998.0, 31.5911
19.126230180, 18.870, 1286.0, 35.8608
19.169695940, 18.870, 1730.0, 41.5933
19.213161700, 18.870, 1855.0, 43.0697
19.256627460, 18.870, 2121.0, 46.0543
19.300093220, 18.870, 2009.0, 44.8219
19.343558980, 18.870, 1835.0, 42.8369
19.387024740, 18.870, 1721.0, 41.4849
19.430490500, 18.870, 1764.0, 42.0000
19.473956260, 18.870, 1836.0, 42.8486
19.517422020, 18.870, 1706.0, 41.3038
19.560887780, 18.870, 1400.0, 37.4166
19.604353540, 18.870, 1155.0, 33.9853
19.647819300, 18.870, 916.0, 30.2655
19.691285060, 18.870, 799.0, 28.2666
19.734750820, 18.870, 755.0, 27.4773
19.778216580, 18.870, 680.0, 26.0768
19.821682340, 18.870, 518.0, 22.7596
19.865148100, 18.870, 484.0, 22.0000
19.908613860, 18.870, 444.0, 21.0713
19.952079620, 18.870, 458.0, 21.4009
19.995545380, 18.870, 466.0, 21.5870
20.039011140, 18.870, 487.0, 22.0681
20.082476900, 18.870, 459.0, 21.4243
20.125942660, 18.870, 493.0, 22.2036
20.169408420, 18.870, 519.0, 22.7816
20.212874180, 18.870, 504.0, 22.4499
20.256339940, 18.870, 494.0, 22.2261
20.299805700, 18.870, 487.0, 22.0681
20.343271460, 18.870, 490.0, 22.1359
20.386737220, 18.870, 455.0, 21.3307
20.430202980, 18.870, 442.0, 21.0238
20.473668740, 18.870, 428.0, 20.6882
20.517134500, 18.870, 460.0, 21.4476
20.560600260, 18.870, 465.0, 21.5639
20.604066020, 18.870, 541.0, 23.2594
20.647531780, 18.870, 543.0, 23.3024
20.690997540, 18.870, 530.0, 23.0217
20.734463300, 18.870, 517.0, 22.7376
20.777929060, 18.870, 466.0, 21.5870
20.821394820, 18.870, 450.0, 21.2132
20.864860580, 18.870, 373.0, 19.3132
20.908326340, 18.870, 410.0, 20.2485
20.951792100, 18.870, 416.0, 20.3961
20.995257860, 18.870, 436.0, 20.8806
21.038723620, 18.870, 425.0, 20.6155
21.082189380, 18.870, 429.0, 20.7123
21.125655140, 18.870, 439.0, 20.9523
21.169120900, 18.870, 489.0, 22.1133
21.212586660, 18.870, 469.0, 21.6564
21.256052420, 18.870, 485.0, 22.0227
21.299518180, 18.870, 422.0, 20.5426
21.342983940, 18.870, 451.0, 21.2368
21.386449700, 18.870, 484.0, 22.0000
21.429915460, 18.870, 439.0, 20.9523
21.473381220, 18.870, 403.0, 20.0749
21.516846980, 18.870, 441.0, 21.0000
21.560312740, 18.870, 448.0, 21.1660
21.603778500, 18.870, 453.0, 21.2838
21.647244260, 18.870, 470.0, 21.6795
21.690710020, 18.870, 504.0, 22.4499
21.734175780, 18.870, 493.0, 22.2036
21.777641540, 18.870, 525.0, 22.9129
21.821107300, 18.870, 535.0, 23.1301
21.864573060, 18.870, 565.0, 23.7697
21.908038820, 18.870, 626.0, 25.0200
21.951504580, 18.870, 602.0, 24.5357
21.994970340, 18.870, 615.0, 24.7992
22.038436100, 18.870, 633.0, 25.1595
22.081901860, 18.870, 673.0, 25.9422
22.125367620, 18.870, 580.0, 24.0832
22.168833380, 18.870, 640.0, 25.2982
22.212299140, 18.870, 633.0, 25.1595
22.255764900, 18.870, 653.0, 25.5539
22.299230660, 18.870, 695.0, 26.3629
22.342696420, 18.870, 618.0, 24.8596
22.386162180, 18.870, 556.0, 23.5797
22.429627940, 18.870, 562.0, 23.7065
22.473093700, 18.870, 663.0, 25.7488
22.516559460, 18.870, 680.0, 26.0768
22.560025220, 18.870, 829.0, 28.7924
22.603490980, 18.870, 883.0, 29.7153
22.646956740, 18.870, 942.0, 30.6920
22.690422500, 18.870, 1071.0, 32.7261
22.733888260, 18.870, 1130.0, 33.6155
22.777354020, 18.870, 1082.0, 32.8938
22.820819780, 18.870, 1148.0, 33.8821
22.864285540, 18.870, 1227.0, 35.0286
22.907751300, 18.870, 1460.0, 38.2099
22.951217060, 18.870, 1710.0, 41.3521
22.994682820, 18.870, 1866.0, 43.1972
23.038148580, 18.870, 2026.0, 45.0111
23.081614340, 18.870, 1980.0, 44.4972
23.125080100, 18.870, 1515.0, 38.9230
23.168545860, 18.870, 1201.0, 34.6554
23.212011620, 18.870, 893.0, 29.8831
23.255477380, 18.870, 742.0, 27.2397
23.298943140, 18.870, 653.0, 25.5539
23.342408900, 18.870, 612.0, 24.7386
23.385874660, 18.870, 669.0, 25.8650
23.429340420, 18.870, 673.0, 25.9422
23.472806180, 18.870, 737.0, 27.1477
23.516271940, 18.870, 839.0, 28.9655
23.559737700, 18.870, 970.0, 31.1448
23.603203460, 18.870, 939.0, 30.6431
23.646669220, 18.870, 969.0, 31.1288
23.690134980, 18.870, 933.0, 30.5450
23.733600740, 18.870, 910.0, 30.1662
23.777066500, 18.870, 839.0, 28.9655
23.820532260, 18.870, 695.0, 26.3629
23.863998020, 18.870, 646.0, 25.4165
23.907463780, 18.870, 572.0, 23.9165
23.950929540, 18.870, 542.0, 23.2809
23.994395300, 18.870, 483.0, 21.9773
24.037861060, 18.870, 516.0, 22.7156
24.081326820, 18.870, 480.0, 21.9089
24.124792580, 18.870, 461.0, 21.4709
24.168258340, 18.870, 487.0, 22.0681
24.211724100, 18.870, 513.0, 22.6495
24.255189860, 18.870, 502.0, 22.4054
24.298655620, 18.870, 529.0, 23.0000
24.342121380, 18.870, 519.0, 22.7816
24.385587140, 18.870, 577.0, 24.0208
24.429052900, 18.870, 545.0, 23.3452
24.472518660, 18.870, 602.0, 24.5357
24.515984420, 18.870, 604.0, 24.5764
24.559450180, 18.870, 633.0, 25.1595
24.602915940, 18.870, 594.0, 24.3721
24.646381700, 18.870, 570.0, 23.8747
24.689847460, 18.870, 534.0, 23.1084
24.733313220, 18.870, 469.0, 21.6564
24.776778980, 18.870, 530.0, 23.0217
24.820244740, 18.870, 549.0, 23.4307
24.863710500, 18.870, 569.0, 23.8537
24.907176260, 18.870, 597.0, 24.4336
24.950642020, 18.870, 641.0, 25.3180
24.994107780, 18.870, 612.0, 24.7386
25.037573540, 18.870, 665.0, 25.7876
25.081039300, 18.870, 675.0, 25.9808
25.124505060, 18.870, 658.0, 25.6515
25.167970820, 18.870, 753.0, 27.4408
25.211436580, 18.870, 747.0, 27.3313
25.254902340, 18.870, 847.0, 29.1033
25.298368100, 18.870, 856.0, 29.2575
25.341833860, 18.870, 1008.0, 31.7490
25.385299620, 18.870, 1054.0, 32.4654
25.428765380, 18.870, 1226.0, 35.0143
25.472231140, 18.870, 1405.0, 37.4833
25.515696900, 18.870, 1476.0, 38.4187
25.559162660, 18.870, 1594.0, 39.9249
25.602628420, 18.870, 1579.0, 39.7366
25.646094180, 18.870, 1515.0, 38.9230
25.689559940, 18.870, 1418.0, 37.6563
25.733025700, 18.870, 1258.0, 35.4683
25.776491460, 18.870, 1154.0, 33.9706
25.819957220, 18.870, 1088.0, 32.9848
25.863422980, 18.870, 930.0, 30.4959
25.906888740, 18.870, 843.0, 29.0345
25.950354500, 18.870, 793.0, 28.1603
25.993820260, 18.870, 776.0, 27.8568
26.037286020, 18.870, 724.0, 26.9072
26.080751780, 18.870, 711.0, 26.6646
26.124217540, 18.870, 744.0, 27.2764
26.167683300, 18.870, 737.0, 27.1477
26.211149060, 18.870, 761.0, 27.5862
26.254614820, 18.870, 737.0, 27.1477
26.298080580, 18.870, 777.0, 27.8747
26.341546340, 18.870, 757.0, 27.5136
26.385012100, 18.870, 745.0, 27.2947
26.428477860, 18.870, 803.0, 28.3373
26.471943620, 18.870, 857.0, 29.2746
26.515409380, 18.870, 902.0, 30.0333
26.558875140, 18.870, 871.0, 29.5127
26.602340900, 18.870, 1003.0, 31.6702
26.645806660, 18.870, 956.0, 30.9192
26.689272420, 18.870, 980.0, 31.3050
26.732738180, 18.870, 967.0, 31.0966
26.776203940, 18.870, 936.0, 30.5941
26.819669700, 18.870, 929.0, 30.4795
26.863135460, 18.870, 915.0, 30.2490
26.906601220, 18.870, 890.0, 29.8329
26.950066980, 18.870, 941.0, 30.6757
26.993532740, 18.870, 900.0, 30.0000
27.036998500, 18.870, 919.0, 30.3150
27.080464260, 18.870, 1031.0, 32.1092
27.123930020, 18.870, 1016.0, 31.8748
27.167395780, 18.870, 1088.0, 32.9848
27.210861540, 18.870, 1091.0, 33.0303
27.254327300, 18.870, 1212.0, 34.8138
27.297793060, 18.870, 1065.0, 32.6343
27.341258820, 18.870, 1180.0, 34.3511
27.384724580, 18.870, 1085.0, 32.9393
27.428190340, 18.870, 1096.0, 33.1059
27.471656100, 18.870, 1113.0, 33.3617
27.515121860, 18.870, 1156.0, 34.0000
27.558587620, 18.870, 1198.0, 34.6121
27.602053380, 18.870, 1190.0, 34.4964
27.645519140, 18.870, 1167.0, 34.1614
27.688984900, 18.870, 1196.0, 34.5832
27.732450660, 18.870, 1159.0, 34.0441
27.775916420, 18.870, 1060.0, 32.5576
27.819382180, 18.870, 1050.0, 32.4037
27.862847940, 18.870, 927.0, 30.4467
27.906313700, 18.870, 921.0, 30.3480
27.949779460, 18.870, 872.0, 29.5296
27.993245220, 18.870, 858.0, 29.2916
28.036710980, 18.870, 796.0, 28.2135
28.080176740, 18.870, 770.0, 27.7489
28.123642500, 18.870, 743.0, 27.2580
28.167108260, 18.870, 705.0, 26.5518
28.210574020, 18.870, 709.0, 26.6271
28.254039780, 18.870, 715.0, 26.7395
28.297505540, 18.870, 741.0, 27.2213
28.340971300, 18.870, 715.0, 26.7395
28.384437060, 18.870, 716.0, 26.7582
28.427902820, 18.870, 721.0, 26.8514
28.471368580, 18.870, 735.0, 27.1109
28.514834340, 18.870, 770.0, 27.7489
28.558300100, 18.870, 846.0, 29.0861
28.601765860, 18.870, 796.0, 28.2135
28.645231620, 18.870, 788.0, 28.0713
28.688697380, 18.870, 801.0, 28.3019
28.732163140, 18.870, 796.0, 28.2135
28.775628900, 18.870, 809.0, 28.4429
28.819094660, 18.870, 789.0, 28.0891
28.862560420, 18.870, 777.0, 27.8747
28.906026180, 18.870, 750.0, 27.3861
28.949491940, 18.870, 709.0, 26.6271
28.992957700, 18.870, 689.0, 26.2488
29.036423460, 18.870, 690.0, 26.2679
29.079889220, 18.870, 601.0, 24.5153
29.123354980, 18.870, 678.0, 26.0384
29.166820740, 18.870, 607.0, 24.6374
29.210286500, 18.870, 644.0, 25.3772
29.253752260, 18.870, 638.0, 25.2587
29.297218020, 18.870, 632.0, 25.1396
29.340683780, 18.870, 618.0, 24.8596
29.384149540, 18.870, 653.0, 25.5539
29.427615300, 18.870, 641.0, 25.3180
29.471081060, 18.870, 652.0, 25.5343
29.514546820, 18.870, 725.0, 26.9258
29.558012580, 18.870, 715.0, 26.7395
29.601478340, 18.870, 716.0, 26.7582
29.644944100, 18.870, 620.0, 24.8998
29.688409860, 18.870, 656.0, 25.6125
29.731875620, 18.870, 608.0, 24.6577
29.775341380, 18.870, 672.0, 25.9230
29.818807140, 18.870, 652.0, 25.5343
29.862272900, 18.870, 690.0, 26.2679
29.905738660, 18.870, 710.0, 26.6458
29.949204420, 18.870, 733.0, 27.0740
29.992670180, 18.870, 727.0, 26.9629
30.036135940, 18.870, 761.0, 27.5862
30.079601700, 18.870, 737.0, 27.1477
30.123067460, 18.870, 657.0, 25.6320
30.166533220, 18.870, 707.0, 26.5895
30.209998980, 18.870, 620.0, 24.8998
30.253464740, 18.870, 623.0, 24.9600
30.296930500, 18.870, 619.0, 24.8797
30.340396260, 18.870, 621.0, 24.9199
30.383862020, 18.870, 552.0, 23.4947
30.427327780, 18.870, 591.0, 24.3105
30.470793540, 18.870, 537.0, 23.1733
30.514259300, 18.870, 589.0, 24.2693
30.557725060, 18.870, 669.0, 25.8650
30.601190820, 18.870, 656.0, 25.6125
30.644656580, 18.870, 685.0, 26.1725
30.688122340, 18.870, 665.0, 25.7876
30.731588100, 18.870, 584.0, 24.1661
30.775053860, 18.870, 570.0, 23.8747
30.818519620, 18.870, 593.0, 24.3516
30.861985380, 18.870, 596.0, 24.4131
30.905451140, 18.870, 526.0, 22.9347
30.948916900, 18.870, 551.0, 23.4734
30.992382660, 18.870, 603.0, 24.5561
31.035848420, 18.870, 603.0, 24.5561
31.079314180, 18.870, 658.0, 25.6515
31.122779940, 18.870, 607.0, 24.6374
31.166245700, 18.870, 676.0, 26.0000
31.209711460, 18.870, 660.0, 25.6905
31.253177220, 18.870, 642.0, 25.3377
31.296642980, 18.870, 657.0, 25.6320
31.340108740, 18.870, 608.0, 24.6577
31.383574500, 18.870, 582.0, 24.1247
31.427040260, 18.870, 597.0, 24.4336
31.470506020, 18.870, 549.0, 23.4307
31.513971780, 18.870, 547.0, 23.3880
31.557437540, 18.870, 495.0, 22.2486
31.600903300, 18.870, 529.0, 23.0000
31.644369060, 18.870, 561.0, 23.6854
31.687834820, 18.870, 619.0, 24.8797
31.731300580, 18.870, 568.0, 23.8328
31.774766340, 18.870, 614.0, 24.7790
31.818232100, 18.870, 608.0, 24.6577
31.861697860, 18.870, 568.0, 23.8328
31.905163620, 18.870, 578.0, 24.0416
31.948629380, 18.870, 516.0, 22.7156
31.992095140, 18.870, 589.0, 24.2693
32.035560900, 18.870, 545.0, 23.3452
32.079026660, 18.870, 525.0, 22.9129
32.122492420, 18.870, 532.0, 23.0651
32.165958180, 18.870, 592.0, 24.3311
32.209423940, 18.870, 592.0, 24.3311
32.252889700, 18.870, 617.0, 24.8395
32.296355460, 18.870, 584.0, 24.1661
32.339821220, 18.870, 639.0, 25.2784
32.383286980, 18.870, 686.0, 26.1916
32.426752740, 18.870, 665.0, 25.7876
32.470218500, 18.870, 723.0, 26.8887
32.513684260, 18.870, 744.0, 27.2764
32.557150020, 18.870, 736.0, 27.1293
32.600615780, 18.870, 724.0, 26.9072
32.644081540, 18.870, 795.0, 28.1957
32.687547300, 18.870, 803.0, 28.3373
32.731013060, 18.870, 844.0, 29.0517
32.774478820, 18.870, 910.0, 30.1662
32.817944580, 18.870, 960.0, 30.9839
32.861410340, 18.870, 912.0, 30.1993
32.904876100, 18.870, 963.0, 31.0322
32.948341860, 18.870, 894.0, 29.8998
32.991807620, 18.870, 930.0, 30.4959
33.035273380, 18.870, 906.0, 30.0998
33.078739140, 18.870, 872.0, 29.5296
33.122204900, 18.870, 838.0, 28.9482
33.165670660, 18.870, 858.0, 29.2916
33.209136420, 18.870, 813.0, 28.5132
33.252602180, 18.870, 801.0, 28.3019
33.296067940, 18.870, 802.0, 28.3196
33.339533700, 18.870, 823.0, 28.6880
33.382999460, 18.870, 860.0, 29.3258
33.426465220, 18.870, 923.0, 30.3809
33.469930980, 18.870, 926.0, 30.4302
33.513396740, 18.870, 947.0, 30.7734
33.556862500, 18.870, 1028.0, 32.0624
33.600328260, 18.870, 1108.0, 33.2866
33.643794020, 18.870, 1210.0, 34.7851
33.687259780, 18.870, 1331.0, 36.4829
33.730725540, 18.870, 1261.0, 35.5106
33.774191300, 18.870, 1180.0, 34.3511
33.817657060, 18.870, 1052.0, 32.4345
33.861122820, 18.870, 946.0, 30.7571
33.904588580, 18.870, 843.0, 29.0345
33.948054340, 18.870, 760.0, 27.5681
33.991520100, 18.870, 725.0, 26.9258
34.034985860, 18.870, 737.0, 27.1477
34.078451620, 18.870, 725.0, 26.9258
34.121917380, 18.870, 670.0, 25.8844
34.165383140, 18.870, 645.0, 25.3969
34.208848900, 18.870, 665.0, 25.7876
34.252314660, 18.870, 596.0, 24.4131
34.295780420, 18.870, 636.0, 25.2190
34.339246180, 18.870, 564.0, 23.7487
34.382711940, 18.870, 595.0, 24.3926
34.426177700, 18.870, 551.0, 23.4734
34.469643460, 18.870, 540.0, 23.2379
34.513109220, 18.870, 651.0, 25.5147
34.556574980, 18.870, 629.0, 25.0799
34.600040740, 18.870, 620.0, 24.8998
34.643506500, 18.870, 609.0, 24.6779
34.686972260, 18.870, 570.0, 23.8747
34.730438020, 18.870, 607.0, 24.6374
34.773903780, 18.870, 606.0, 24.6171
34.817369540, 18.870, 631.0, 25.1197
34.860835300, 18.870, 629.0, 25.0799
34.904301060, 18.870, 644.0, 25.3772
34.947766820, 18.870, 700.0, 26.4575
34.991232580, 18.870, 766.0, 27.6767
35.034698340, 18.870, 744.0, 27.2764
35.078164100, 18.870, 830.0, 28.8097
35.121629860, 18.870, 830.0, 28.8097
35.165095620, 18.870, 737.0, 27.1477
35.208561380, 18.870, 759.0, 27.5500
35.252027140, 18.870, 784.0, 28.0000
35.295492900, 18.870, 710.0, 26.6458
35.338958660, 18.870, 700.0, 26.4575
35.382424420, 18.870, 635.0, 25.1992
35.425890180, 18.870, 616.0, 24.8193
35.469355940, 18.870, 589.0, 24.2693
35.512821700, 18.870, 599.0, 24.4745
35.556287460, 18.870, 610.0, 24.6982
35.599753220, 18.870, 635.0, 25.1992
35.643218980, 18.870, 623.0, 24.9600
35.686684740, 18.870, 609.0, 24.6779
35.730150500, 18.870, 592.0, 24.3311
35.773616260, 18.870, 552.0, 23.4947
35.817082020, 18.870, 525.0, 22.9129
35.860547780, 18.870, 526.0, 22.9347
35.904013540, 18.870, 485.0, 22.0227
35.947479300, 18.870, 535.0, 23.1301
35.990945060, 18.870, 584.0, 24.1661
36.034410820, 18.870, 504.0, 22.4499
36.077876580, 18.870, 536.0, 23.1517
36.121342340, 18.870, 554.0, 23.5372
36.164808100, 18.870, 590.0, 24.2899
36.208273860, 18.870, 617.0, 24.8395
36.251739620, 18.870, 631.0, 25.1197
36.295205380, 18.870, 737.0, 27.1477
36.338671140, 18.870, 746.0, 27.3130
36.382136900, 18.870, 730.0, 27.0185
36.425602660, 18.870, 742.0, 27.2397
36.469068420, 18.870, 729.0, 27.0000
36.512534180, 18.870, 718.0, 26.7955
36.555999940, 18.870, 674.0, 25.9615
36.599465700, 18.870, 680.0, 26.0768
36.642931460, 18.870, 638.0, 25.2587
36.686397220, 18.870, 664.0, 25.7682
36.729862980, 18.870, 605.0, 24.5967
36.773328740, 18.870, 583.0, 24.1454
36.816794500, 18.870, 558.0, 23.6220
36.860260260, 18.870, 563.0, 23.7276
36.903726020, 18.870, 598.0, 24.4540
36.947191780, 18.870, 552.0, 23.4947
36.990657540, 18.870, 526.0, 22.9347
37.034123300, 18.870, 574.0, 23.9583
37.077589060, 18.870, 531.0, 23.0434
37.121054820, 18.870, 515.0, 22.6936
37.164520580, 18.870, 529.0, 23.0000
37.207986340, 18.870, 530.0, 23.0217
37.251452100, 18.870, 527.0, 22.9565
37.294917860, 18.870, 522.0, 22.8473
37.338383620, 18.870, 485.0, 22.0227
37.381849380, 18.870, 479.0, 21.8861
37.425315140, 18.870, 498.0, 22.3159
37.468780900, 18.870, 533.0, 23.0868
37.512246660, 18.870, 590.0, 24.2899
37.555712420, 18.870, 611.0, 24.7184
37.599178180, 18.870, 621.0, 24.9199
37.642643940, 18.870, 650.0, 25.4951
37.686109700, 18.870, 680.0, 26.0768
37.729575460, 18.870, 755.0, 27.4773
37.773041220, 18.870, 750.0, 27.3861
37.816506980, 18.870, 745.0, 27.2947
37.859972740, 18.870, 799.0, 28.2666
37.903438500, 18.870, 768.0, 27.7128
37.946904260, 18.870, 710.0, 26.6458
37.990370020, 18.870, 728.0, 26.9815
38.033835780, 18.870, 643.0, 25.3574
38.077301540, 18.870, 559.0, 23.6432
38.120767300, 18.870, 516.0, 22.7156
38.164233060, 18.870, 534.0, 23.1084
38.207698820, 18.870, 524.0, 22.8910
38.251164580, 18.870, 490.0, 22.1359
38.294630340, 18.870, 503.0, 22.4277
38.338096100, 18.870, 511.0, 22.6053
38.381561860, 18.870, 614.0, 24.7790
38.425027620, 18.870, 578.0, 24.0416
38.468493380, 18.870, 522.0, 22.8473
38.511959140, 18.870, 575.0, 23.9792
38.555424900, 18.870, 541.0, 23.2594
38.598890660, 18.870, 560.0, 23.6643
38.642356420, 18.870, 550.0, 23.4521
38.685822180, 18.870, 546.0, 23.3666
38.729287940, 18.870, 511.0, 22.6053
38.772753700, 18.870, 484.0, 22.0000
38.816219460, 18.870, 521.0, 22.8254
38.859685220, 18.870, 558.0, 23.6220
38.903150980, 18.870, 544.0, 23.3238
38.946616740, 18.870, 489.0, 22.1133
38.990082500, 18.870, 589.0, 24.2693
39.033548260, 18.870, 645.0, 25.3969
39.077014020, 18.870, 661.0, 25.7099
39.120479780, 18.870, 718.0, 26.7955
39.163945540, 18.870, 750.0, 27.3861
39.207411300, 18.870, 780.0, 27.9285
39.250877060, 18.870, 732.0, 27.0555
39.294342820, 18.870, 745.0, 27.2947
39.337808580, 18.870, 773.0, 27.8029
39.381274340, 18.870, 659.0, 25.6710
39.424740100, 18.870, 628.0, 25.0599
39.468205860, 18.870, 627.0, 25.0400
39.511671620, 18.870, 633.0, 25.1595
39.555137380, 18.870, 588.0, 24.2487
39.598603140, 18.870, 590.0, 24.2899
39.642068900, 18.870, 573.0, 23.9374
39.685534660, 18.870, 535.0, 23.1301
39.729000420, 18.870, 568.0, 23.8328
39.772466180, 18.870, 573.0, 23.9374
39.815931940, 18.870, 581.0, 24.1039
39.859397700, 18.870, 524.0, 22.8910
39.902863460, 18.870, 543.0, 23.3024
39.946329220, 18.870, 578.0, 24.0416
39.989794980, 18.870, 625.0, 25.0000
40.033260740, 18.870, 621.0, 24.9199
40.076726500, 18.870, 694.0, 26.3439
40.120192260, 18.870, 725.0, 26.9258
40.163658020, 18.870, 813.0, 28.5132
40.207123780, 18.870, 820.0, 28.6356
40.250589540, 18.870, 919.0, 30.3150
40.294055300, 18.870, 972.0, 31.1769
40.337521060, 18.870, 1044.0, 32.3110
40.380986820, 18.870, 1115.0, 33.3916
40.424452580, 18.870, 1159.0, 34.0441
40.467918340, 18.870, 1142.0, 33.7935
40.511384100, 18.870, 1010.0, 31.7805
40.554849860, 18.870, 1006.0, 31.7175
40.598315620, 18.870, 936.0, 30.5941
40.641781380, 18.870, 861.0, 29.3428
40.685247140, 18.870, 822.0, 28.6705
40.728712900, 18.870, 742.0, 27.2397
40.772178660, 18.870, 715.0, 26.7395
40.815644420, 18.870, 605.0, 24.5967
40.859110180, 18.870, 614.0, 24.7790
40.902575940, 18.870, 600.0, 24.4949
40.946041700, 18.870, 616.0, 24.8193
40.989507460, 18.870, 564.0, 23.7487
41.032973220, 18.870, 500.0, 22.3607
41.076438980, 18.870, 592.0, 24.3311
41.119904740, 18.870, 593.0, 24.3516
41.163370500, 18.870, 603.0, 24.5561
41.206836260, 18.870, 570.0, 23.8747
41.250302020, 18.870, 589.0, 24.2693
41.293767780, 18.870, 585.0, 24.1868
41.337233540, 18.870, 548.0, 23.4094
41.380699300, 18.870, 564.0, 23.7487
41.424165060, 18.870, 581.0, 24.1039
41.467630820, 18.870, 558.0, 23.6220
41.511096580, 18.870, 564.0, 23.7487
41.554562340, 18.870, 612.0, 24.7386
41.598028100, 18.870, 629.0, 25.0799
41.641493860, 18.870, 619.0, 24.8797
41.684959620, 18.870, 647.0, 25.4362
41.728425380, 18.870, 676.0, 26.0000
41.771891140, 18.870, 689.0, 26.2488
41.815356900, 18.870, 686.0, 26.1916
41.858822660, 18.870, 667.0, 25.8263
41.902288420, 18.870, 683.0, 26.1343
41.945754180, 18.870, 668.0, 25.8457
41.989219940, 18.870, 634.0, 25.1794
42.032685700, 18.870, 592.0, 24.3311
42.076151460, 18.870, 604.0, 24.5764
42.119617220, 18.870, 627.0, 25.0400
42.163082980, 18.870, 588.0, 24.2487
42.206548740, 18.870, 537.0, 23.1733
42.250014500, 18.870, 531.0, 23.0434
42.293480260, 18.870, 483.0, 21.9773
42.336946020, 18.870, 440.0, 20.9762
42.380411780, 18.870, 497.0, 22.2935
42.423877540, 18.870, 488.0, 22.0907
42.467343300, 18.870, 479.0, 21.8861
42.510809060, 18.870, 431.0, 20.7605
42.554274820, 18.870, 455.0, 21.3307
42.597740580, 18.870, 458.0, 21.4009
42.641206340, 18.870, 487.0, 22.0681
42.684672100, 18.870, 462.0, 21.4942
42.728137860, 18.870, 503.0, 22.4277
42.771603620, 18.870, 483.0, 21.9773
42.815069380, 18.870, 491.0, 22.1585
42.858535140, 18.870, 487.0, 22.0681
42.902000900, 18.870, 466.0, 21.5870
42.945466660, 18.870, 491.0, 22.1585
42.988932420, 18.870, 508.0, 22.5389
43.032398180, 18.870, 556.0, 23.5797
43.075863940, 18.870, 573.0, 23.9374
43.119329700, 18.870, 548.0, 23.4094
43.162795460, 18.870, 598.0, 24.4540
43.206261220, 18.870, 639.0, 25.2784
43.249726980, 18.870, 642.0, 25.3377
43.293192740, 18.870, 697.0, 26.4008
43.336658500, 18.870, 704.0, 26.5330
43.380124260, 18.870, 670.0, 25.8844
43.423590020, 18.870, 592.0, 24.3311
43.467055780, 18.870, 597.0, 24.4336
43.510521540, 18.870, 572.0, 23.9165
43.553987300, 18.870, 562.0, 23.7065
43.597453060, 18.870, 506.0, 22.4944
43.640918820, 18.870, 557.0, 23.6008
43.684384580, 18.870, 545.0, 23.3452
43.727850340, 18.870, 491.0, 22.1585
43.771316100, 18.870, 507.0, 22.5167
43.814781860, 18.870, 477.0, 21.8403
43.858247620, 18.870, 481.0, 21.9317
43.901713380, 18.870, 487.0, 22.0681
43.945179140, 18.870, 459.0, 21.4243
43.988644900, 18.870, 511.0, 22.6053
44.032110660, 18.870, 527.0, 22.9565
44.075576420, 18.870, 496.0, 22.2711
44.119042180, 18.870, 528.0, 22.9783
44.162507940, 18.870, 522.0, 22.8473
44.205973700, 18.870, 544.0, 23.3238
44.249439460, 18.870, 538.0, 23.1948
44.292905220, 18.870, 539.0, 23.2164
44.336370980, 18.870, 596.0, 24.4131
44.379836740, 18.870, 544.0, 23.3238
44.423302500, 18.870, 556.0, 23.5797
44.466768260, 18.870, 532.0, 23.0651
44.510234020, 18.870, 536.0, 23.1517
44.553699780, 18.870, 518.0, 22.7596
44.597165540, 18.870, 523.0, 22.8692
44.640631300, 18.870, 512.0, 22.6274
44.684097060, 18.870, 526.0, 22.9347
44.727562820, 18.870, 520.0, 22.8035
44.771028580, 18.870, 501.0, 22.3830
44.814494340, 18.870, 491.0, 22.1585
44.857960100, 18.870, 523.0, 22.8692
44.901425860, 18.870, 536.0, 23.1517
44.944891620, 18.870, 553.0, 23.5160
44.988357380, 18.870, 559.0, 23.6432
45.031823140, 18.870, 543.0, 23.3024
45.075288900, 18.870, 512.0, 22.6274
45.118754660, 18.870, 482.0, 21.9545
45.162220420, 18.870, 443.0, 21.0476
45.205686180, 18.870, 430.0, 20.7364
45.249151940, 18.870, 460.0, 21.4476
45.292617700, 18.870, 462.0, 21.4942
45.336083460, 18.870, 475.0, 21.7945
45.379549220, 18.870, 478.0, 21.8632
45.423014980, 18.870, 444.0, 21.0713
45.466480740, 18.870, 469.0, 21.6564
45.509946500, 18.870, 444.0, 21.0713
45.553412260, 18.870, 452.0, 21.2603
45.596878020, 18.870, 446.0, 21.1187
45.640343780, 18.870, 449.0, 21.1896
45.683809540, 18.870, 451.0, 21.2368
45.727275300, 18.870, 477.0, 21.8403
45.770741060, 18.870, 426.0, 20.6398
45.814206820, 18.870, 481.0, 21.9317
45.857672580, 18.870, 476.0, 21.8174
45.901138340, 18.870, 460.0, 21.4476
45.944604100, 18.870, 468.0, 21.6333
45.988069860, 18.870, 511.0, 22.6053
46.031535620, 18.870, 491.0, 22.1585
46.075001380, 18.870, 477.0, 21.8403
46.118467140, 18.870, 550.0, 23.4521
46.161932900, 18.870, 469.0, 21.6564
46.205398660, 18.870, 550.0, 23.4521
46.248864420, 18.870, 482.0, 21.9545
46.292330180, 18.870, 503.0, 22.4277
46.335795940, 18.870, 500.0, 22.3607
46.379261700, 18.870, 472.0, 21.7256
46.422727460, 18.870, 516.0, 22.7156
46.466193220, 18.870, 550.0, 23.4521
46.509658980, 18.870, 511.0, 22.6053
46.553124740, 18.870, 550.0, 23.4521
46.596590500, 18.870, 538.0, 23.1948
46.640056260, 18.870, 520.0, 22.8035
46.683522020, 18.870, 504.0, 22.4499
46.726987780, 18.870, 466.0, 21.5870
46.770453540, 18.870, 457.0, 21.3776
46.813919300, 18.870, 428.0, 20.6882
46.857385060, 18.870, 437.0, 20.9045
46.900850820, 18.870, 411.0, 20.2731
46.944316580, 18.870, 423.0, 20.5670
46.987782340, 18.870, 419.0, 20.4695
47.031248100, 18.870, 401.0, 20.0250
47.074713860, 18.870, 390.0, 19.7484
47.118179620, 18.870, 390.0, 19.7484
47.161645380, 18.870, 398.0, 19.9499
47.205111140, 18.870, 406.0, 20.1494
47.248576900, 18.870, 370.0, 19.2354
47.292042660, 18.870, 425.0, 20.6155
47.335508420, 18.870, 415.0, 20.3715
47.378974180, 18.870, 449.0, 21.1896
47.422439940, 18.870, 424.0, 20.5913
47.465905700, 18.870, 424.0, 20.5913
47.509371460, 18.870, 456.0, 21.3542
47.552837220, 18.870, 451.0, 21.2368
47.596302980, 18.870, 411.0, 20.2731
47.639768740, 18.870, 438.0, 20.9284
47.683234500, 18.870, 455.0, 21.3307
47.726700260, 18.870, 438.0, 20.9284
47.770166020, 18.870, 481.0, 21.9317
47.813631780, 18.870, 435.0, 20.8567
47.857097540, 18.870, 433.0, 20.8087
47.900563300, 18.870, 450.0, 21.2132
47.944029060, 18.870, 432.0, 20.7846
47.987494820, 18.870, 440.0, 20.9762
48.030960580, 18.870, 437.0, 20.9045
48.074426340, 18.870, 454.0, 21.3073
48.117892100, 18.870, 418.0, 20.4450
48.161357860, 18.870, 440.0, 20.9762
48.204823620, 18.870, 455.0, 21.3307
48.248289380, 18.870, 439.0, 20.9523
48.291755140, 18.870, 455.0, 21.3307
48.335220900, 18.870, 430.0, 20.7364
48.378686660, 18.870, 413.0, 20.3224
48.422152420, 18.870, 414.0, 20.3470
48.465618180, 18.870, 410.0, 20.2485
48.509083940, 18.870, 372.0, 19.2873
48.552549700, 18.870, 389.0, 19.7231
48.596015460, 18.870, 381.0, 19.5192
48.639481220, 18.870, 410.0, 20.2485
48.682946980, 18.870, 403.0, 20.0749
48.726412740, 18.870, 413.0, 20.3224
48.769878500, 18.870, 391.0, 19.7737
48.813344260, 18.870, 394.0, 19.8494
48.856810020, 18.870, 429.0, 20.7123
48.900275780, 18.870, 424.0, 20.5913
48.943741540, 18.870, 453.0, 21.2838
48.987207300, 18.870, 428.0, 20.6882
49.030673060, 18.870, 392.0, 19.7990
49.074138820, 18.870, 392.0, 19.7990
49.117604580, 18.870, 419.0, 20.4695
49.161070340, 18.870, 410.0, 20.2485
49.204536100, 18.870, 431.0, 20.7605
49.248001860, 18.870, 451.0, 21.2368
49.291467620, 18.870, 448.0, 21.1660
49.334933380, 18.870, 432.0, 20.7846
49.378399140, 18.870, 417.0, 20.4206
49.421864900, 18.870, 415.0, 20.3715
49.465330660, 18.870, 387.0, 19.6723
49.508796420, 18.870, 408.0, 20.1990
49.552262180, 18.870, 401.0, 20.0250
49.595727940, 18.870, 395.0, 19.8746
49.639193700, 18.870, 425.0, 20.6155
49.682659460, 18.870, 417.0, 20.4206
49.726125220, 18.870, 440.0, 20.9762
49.769590980, 18.870, 406.0, 20.1494
49.813056740, 18.870, 468.0, 21.6333
49.856522500, 18.870, 428.0, 20.6882
49.899988260, 18.870, 497.0, 22.2935
49.943454020, 18.870, 476.0, 21.8174
49.986919780, 18.870, 445.0, 21.0950
50.030385540, 18.870, 442.0, 21.0238
50.073851300, 18.870, 435.0, 20.8567
50.117317060, 18.870, 464.0, 21.5407
50.160782820, 18.870, 440.0, 20.9762
50.204248580, 18.870, 447.0, 21.1424
50.247714340, 18.870, 431.0, 20.7605
50.291180100, 18.870, 420.0, 20.4939
50.334645860, 18.870, 434.0, 20.8327
50.378111620, 18.870, 466.0, 21.5870
50.421577380, 18.870, 449.0, 21.1896
50.465043140, 18.870, 459.0, 21.4243
50.508508900, 18.870, 439.0, 20.9523
50.551974660, 18.870, 444.0, 21.0713
50.595440420, 18.870, 488.0, 22.0907
50.638906180, 18.870, 455.0, 21.3307
50.682371940, 18.870, 445.0, 21.0950
50.725837700, 18.870, 438.0, 20.9284
50.769303460, 18.870, 473.0, 21.7486
50.812769220, 18.870, 485.0, 22.0227
50.856234980, 18.870, 421.0, 20.5183
50.899700740, 18.870, 439.0, 20.9523
50.943166500, 18.870, 458.0, 21.4009
50.986632260, 18.870, 462.0, 21.4942
51.030098020, 18.870, 445.0, 21.0950
51.073563780, 18.870, 444.0, 21.0713
51.117029540, 18.870, 458.0, 21.4009
51.160495300, 18.870, 501.0, 22.3830
51.203961060, 18.870, 472.0, 21.7256
51.247426820, 18.870, 504.0, 22.4499
51.290892580, 18.870, 494.0, 22.2261
51.334358340, 18.870, 521.0, 22.8254
51.377824100, 18.870, 500.0, 22.3607
51.421289860, 18.870, 492.0, 22.1811
51.464755620, 18.870, 534.0, 23.1084
51.508221380, 18.870, 503.0, 22.4277
51.551687140, 18.870, 554.0, 23.5372
51.595152900, 18.870, 523.0, 22.8692
51.638618660, 18.870, 477.0, 21.8403
51.682084420, 18.870, 499.0, 22.3383
51.725550180, 18.870, 493.0, 22.2036
51.769015940, 18.870, 469.0, 21.6564
51.812481700, 18.870, 486.0, 22.0454
51.855947460, 18.870, 491.0, 22.1585
51.899413220, 18.870, 461.0, 21.4709
51.942878980, 18.870, 455.0, 21.3307
51.986344740, 18.870, 451.0, 21.2368
52.029810500, 18.870, 466.0, 21.5870
52.073276260, 18.870, 465.0, 21.5639
52.116742020, 18.870, 497.0, 22.2935
52.160207780, 18.870, 471.0, 21.7025
52.203673540, 18.870, 452.0, 21.2603
52.247139300, 18.870, 500.0, 22.3607
52.290605060, 18.870, 462.0, 21.4942
52.334070820, 18.870, 479.0, 21.8861
52.377536580, 18.870, 444.0, 21.0713
52.421002340, 18.870, 441.0, 21.0000
52.464468100, 18.870, 490.0, 22.1359
52.507933860, 18.870, 443.0, 21.0476
52.551399620, 18.870, 459.0, 21.4243
52.594865380, 18.870, 476.0, 21.8174
52.638331140, 18.870, 475.0, 21.7945
52.681796900, 18.870, 454.0, 21.3073
52.725262660, 18.870, 421.0, 20.5183
52.768728420, 18.870, 460.0, 21.4476
52.812194180, 18.870, 436.0, 20.8806
52.855659940, 18.870, 421.0, 20.5183
52.899125700, 18.870, 402.0, 20.0499
52.942591460, 18.870, 411.0, 20.2731
52.986057220, 18.870, 438.0, 20.9284
53.029522980, 18.870, 412.0, 20.2978
53.072988740, 18.870, 477.0, 21.8403
53.116454500, 18.870, 441.0, 21.0000
53.159920260, 18.870, 429.0, 20.7123
53.203386020, 18.870, 451.0, 21.2368
53.246851780, 18.870, 450.0, 21.2132
53.290317540, 18.870, 454.0, 21.3073
53.333783300, 18.870, 482.0, 21.9545
53.377249060, 18.870, 478.0, 21.8632
53.420714820, 18.870, 451.0, 21.2368
53.464180580, 18.870, 429.0, 20.7123
53.507646340, 18.870, 401.0, 20.0250
53.551112100, 18.870, 460.0, 21.4476
53.594577860, 18.870, 424.0, 20.5913
53.638043620, 18.870, 472.0, 21.7256
53.681509380, 18.870, 446.0, 21.1187
53.724975140, 18.870, 456.0, 21.3542
53.768440900, 18.870, 399.0, 19.9750
53.811906660, 18.870, 492.0, 22.1811
53.855372420, 18.870, 431.0, 20.7605
53.898838180, 18.870, 398.0, 19.9499
53.942303940, 18.870, 421.0, 20.5183
53.985769700, 18.870, 422.0, 20.5426
54.029235460, 18.870, 417.0, 20.4206
54.072701220, 18.870, 434.0, 20.8327
54.116166980, 18.870, 439.0, 20.9523
54.159632740, 18.870, 396.0, 19.8997
54.203098500, 18.870, 430.0, 20.7364
54.246564260, 18.870, 416.0, 20.3961
54.290030020, 18.870, 401.0, 20.0250
54.333495780, 18.870, 398.0, 19.9499
54.376961540, 18.870, 385.0, 19.6214
54.420427300, 18.870, 418.0, 20.4450
54.463893060, 18.870, 385.0, 19.6214
54.507358820, 18.870, 456.0, 21.3542
54.550824580, 18.870, 407.0, 20.1742
54.594290340, 18.870, 393.0, 19.8242
54.637756100, 18.870, 406.0, 20.1494
54.681221860, 18.870, 392.0, 19.7990
54.724687620, 18.870, 365.0, 19.1050
54.768153380, 18.870, 428.0, 20.6882
54.811619140, 18.870, 434.0, 20.8327
54.855084900, 18.870, 406.0, 20.1494
54.898550660, 18.870, 437.0, 20.9045
54.942016420, 18.870, 390.0, 19.7484
54.985482180, 18.870, 417.0, 20.4206
55.028947940, 18.870, 439.0, 20.9523
55.072413700, 18.870, 409.0, 20.2237
55.115879460, 18.870, 403.0, 20.0749
55.159345220, 18.870, 406.0, 20.1494
55.202810980, 18.870, 389.0, 19.7231
55.246276740, 18.870, 390.0, 19.7484
55.289742500, 18.870, 391.0, 19.7737
55.333208260, 18.870, 380.0, 19.4936
55.376674020, 18.870, 370.0, 19.2354
55.420139780, 18.870, 397.0, 19.9249
55.463605540, 18.870, 426.0, 20.6398
55.507071300, 18.870, 391.0, 19.7737
55.550537060, 18.870, 412.0, 20.2978
55.594002820, 18.870, 388.0, 19.6977
55.637468580, 18.870, 358.0, 18.9209
55.680934340, 18.870, 406.0, 20.1494
55.724400100, 18.870, 380.0, 19.4936
55.767865860, 18.870, 462.0, 21.4942
55.811331620, 18.870, 404.0, 20.0998
55.854797380, 18.870, 391.0, 19.7737
55.898263140, 18.870, 363.0, 19.0526
55.941728900, 18.870, 379.0, 19.4679
55.985194660, 18.870, 391.0, 19.7737
56.028660420, 18.870, 396.0, 19.8997
56.072126180, 18.870, 397.0, 19.9249
56.115591940, 18.870, 404.0, 20.0998
56.159057700, 18.870, 378.0, 19.4422
56.202523460, 18.870, 331.0, 18.1934
56.245989220, 18.870, 365.0, 19.1050
56.289454980, 18.870, 417.0, 20.4206
56.332920740, 18.870, 376.0, 19.3907
56.376386500, 18.870, 412.0, 20.2978
56.419852260, 18.870, 386.0, 19.6469
56.463318020, 18.870, 401.0, 20.0250
56.506783780, 18.870, 400.0, 20.0000
56.550249540, 18.870, 436.0, 20.8806
56.593715300, 18.870, 409.0, 20.2237
56.637181060, 18.870, 426.0, 20.6398
56.680646820, 18.870, 449.0, 21.1896
56.724112580, 18.870, 441.0, 21.0000
56.767578340, 18.870, 431.0, 20.7605
56.811044100, 18.870, 423.0, 20.5670
56.854509860, 18.870, 443.0, 21.0476
56.897975620, 18.870, 381.0, 19.5192
56.941441380, 18.870, 374.0, 19.3391
56.984907140, 18.870, 440.0, 20.9762
57.028372900, 18.870, 345.0, 18.5742
57.071838660, 18.870, 399.0, 19.9750
57.115304420, 18.870, 420.0, 20.4939
57.158770180, 18.870, 390.0, 19.7484
57.202235940, 18.870, 315.0, 17.7482
57.245701700, 18.870, 336.0, 18.3303
57.289167460, 18.870, 371.0, 19.2614
57.332633220, 18.870, 380.0, 19.4936
57.376098980, 18.870, 343.0, 18.5203
57.419564740, 18.870, 376.0, 19.3907
57.463030500, 18.870, 354.0, 18.8149
57.506496260, 18.870, 369.0, 19.2094
57.549962020, 18.870, 392.0, 19.7990
57.593427780, 18.870, 397.0, 19.9249
57.636893540, 18.870, 393.0, 19.8242
57.680359300, 18.870, 378.0, 19.4422
57.723825060, 18.870, 345.0, 18.5742
57.767290820, 18.870, 371.0, 19.2614
57.810756580, 18.870, 350.0, 18.7083
57.854222340, 18.870, 367.0, 19.1572
57.897688100, 18.870, 367.0, 19.1572
57.941153860, 18.870, 398.0, 19.9499
57.984619620, 18.870, 410.0, 20.2485
58.028085380, 18.870, 378.0, 19.4422
58.071551140, 18.870, 427.0, 20.6640
58.115016900, 18.870, 402.0, 20.0499
58.158482660, 18.870, 431.0, 20.7605
58.201948420, 18.870, 432.0, 20.7846
58.245414180, 18.870, 396.0, 19.8997
58.288879940, 18.870, 467.0, 21.6102
58.332345700, 18.870, 424.0, 20.5913
58.375811460, 18.870, 420.0, 20.4939
58.419277220, 18.870, 390.0, 19.7484
58.462742980, 18.870, 394.0, 19.8494
58.506208740, 18.870, 367.0, 19.1572
58.549674500, 18.870, 365.0, 19.1050
58.593140260, 18.870, 367.0, 19.1572
58.636606020, 18.870, 343.0, 18.5203
58.680071780, 18.870, 368.0, 19.1833
58.723537540, 18.870, 368.0, 19.1833
58.767003300, 18.870, 360.0, 18.9737
58.810469060, 18.870, 382.0, 19.5448
58.853934820, 18.870, 361.0, 19.0000
58.897400580, 18.870, 389.0, 19.7231
58.940866340, 18.870, 408.0, 20.1990
58.984332100, 18.870, 394.0, 19.8494
59.027797860, 18.870, 363.0, 19.0526
59.071263620, 18.870, 373.0, 19.3132
59.114729380, 18.870, 369.0, 19.2094
59.158195140, 18.870, 382.0, 19.5448
59.201660900, 18.870, 362.0, 19.0263
59.245126660, 18.870, 359.0, 18.9473
59.288592420, 18.870, 339.0, 18.4120
59.332058180, 18.870, 311.0, 17.6352
59.375523940, 18.870, 328.0, 18.1108
59.418989700, 18.870, 342.0, 18.4932
59.462455460, 18.870, 345.0, 18.5742
59.505921220, 18.870, 320.0, 17.8885
59.549386980, 18.870, 368.0, 19.1833
59.592852740, 18.870, 311.0, 17.6352
59.636318500, 18.870, 371.0, 19.2614
59.679784260, 18.870, 355.0, 18.8414
59.723250020, 18.870, 312.0, 17.6635
59.766715780, 18.870, 338.0, 18.3848
59.810181540, 18.870, 350.0, 18.7083
59.853647300, 18.870, 400.0, 20.0000
59.897113060, 18.870, 357.0, 18.8944
59.940578820, 18.870, 360.0, 18.9737
59.984044580, 18.870, 357.0, 18.8944
59.994911020, 18.870, 351.0, 18.7350