File: XRD/2025_06_03_Sorbic_Acid_10_80_50s.csv
[Measurement conditions]
Sample identification,2025_06_03_Sorbic_Acid_10_80_50s
Comment - 1,"Sorbic Acid Standard"
Anode material,Cu
K-Alpha1 wavelength,1.5405980
K-Alpha2 wavelength,1.5444260
Ratio K-Alpha2/K-Alpha1,0.500
Divergence slit,Fixed,0.76mm
Monochromator used,NO
Generator voltage, 40
Tube current, 15
File date and time,03/Jun/2025 13:19
Unit cell,
h k l, 0 0 0
Scan axis,Gonio
Scan range,10.000000000,80.001606480
Scan step size,0.0108664
No. of points, 6442
Scan type,CONTINUOUS
Time per step,48.195
[Scan points]
Angle, TimePerStep, Intensity, ESD
10.005433220, 48.195, 2760.0, 52.5357
10.059765420, 48.195, 2728.0, 52.2303
10.114097620, 48.195, 2776.0, 52.6878
10.168429820, 48.195, 2970.0, 54.4977
10.222762020, 48.195, 2962.0, 54.4243
10.277094220, 48.195, 2920.0, 54.0370
10.331426420, 48.195, 2900.0, 53.8516
10.385758620, 48.195, 3023.0, 54.9818
10.440090820, 48.195, 2959.0, 54.3967
10.494423020, 48.195, 2821.0, 53.1131
10.548755220, 48.195, 2932.0, 54.1479
10.603087420, 48.195, 2883.0, 53.6936
10.657419620, 48.195, 2909.0, 53.9351
10.711751820, 48.195, 3106.0, 55.7315
10.766084020, 48.195, 3212.0, 56.6745
10.820416220, 48.195, 3398.0, 58.2924
10.874748420, 48.195, 3916.0, 62.5780
10.929080620, 48.195, 4472.0, 66.8730
10.983412820, 48.195, 5564.0, 74.5922
11.037745020, 48.195, 6841.0, 82.7103
11.092077220, 48.195, 8946.0, 94.5833
11.146409420, 48.195, 13325.0, 115.4340
11.200741620, 48.195, 25767.0, 160.5210
11.255073820, 48.195, 46653.0, 215.9931
11.309406020, 48.195, 60113.0, 245.1795
11.363738220, 48.195, 71299.0, 267.0187
11.418070420, 48.195, 95633.0, 309.2459
11.472402620, 48.195, 111980.0, 334.6341
11.526734820, 48.195, 94291.0, 307.0684
11.581067020, 48.195, 57779.0, 240.3726
11.635399220, 48.195, 32601.0, 180.5575
11.689731420, 48.195, 21012.0, 144.9552
11.744063620, 48.195, 13585.0, 116.5547
11.798395820, 48.195, 6866.0, 82.8613
11.852728020, 48.195, 5152.0, 71.7774
11.907060220, 48.195, 4558.0, 67.5130
11.961392420, 48.195, 4365.0, 66.0681
12.015724620, 48.195, 4001.0, 63.2535
12.070056820, 48.195, 3933.0, 62.7136
12.124389020, 48.195, 3790.0, 61.5630
12.178721220, 48.195, 3705.0, 60.8687
12.233053420, 48.195, 3685.0, 60.7042
12.287385620, 48.195, 3685.0, 60.7042
12.341717820, 48.195, 3779.0, 61.4736
12.396050020, 48.195, 3775.0, 61.4410
12.450382220, 48.195, 3833.0, 61.9112
12.504714420, 48.195, 4189.0, 64.7225
12.559046620, 48.195, 4557.0, 67.5056
12.613378820, 48.195, 5036.0, 70.9648
12.667711020, 48.195, 5983.0, 77.3499
12.722043220, 48.195, 7478.0, 86.4754
12.776375420, 48.195, 10264.0, 101.3114
12.830707620, 48.195, 15066.0, 122.7436
12.885039820, 48.195, 18939.0, 137.6190
12.939372020, 48.195, 21203.0, 145.6125
12.993704220, 48.195, 24204.0, 155.5763
13.048036420, 48.195, 31525.0, 177.5528
13.102368620, 48.195, 36770.0, 191.7551
13.156700820, 48.195, 26434.0, 162.5854
13.211033020, 48.195, 12710.0, 112.7386
13.265365220, 48.195, 5901.0, 76.8180
13.319697420, 48.195, 4315.0, 65.6887
13.374029620, 48.195, 3734.0, 61.1065
13.428361820, 48.195, 3505.0, 59.2030
13.482694020, 48.195, 3397.0, 58.2838
13.537026220, 48.195, 3295.0, 57.4021
13.591358420, 48.195, 3143.0, 56.0625
13.645690620, 48.195, 3077.0, 55.4707
13.700022820, 48.195, 3097.0, 55.6507
13.754355020, 48.195, 3102.0, 55.6956
13.808687220, 48.195, 3070.0, 55.4076
13.863019420, 48.195, 3118.0, 55.8391
13.917351620, 48.195, 3050.0, 55.2268
13.971683820, 48.195, 3039.0, 55.1271
14.026016020, 48.195, 2896.0, 53.8145
14.080348220, 48.195, 2928.0, 54.1110
14.134680420, 48.195, 2861.0, 53.4883
14.189012620, 48.195, 2905.0, 53.8981
14.243344820, 48.195, 2958.0, 54.3875
14.297677020, 48.195, 2908.0, 53.9259
14.352009220, 48.195, 2829.0, 53.1883
14.406341420, 48.195, 2892.0, 53.7773
14.460673620, 48.195, 2942.0, 54.2402
14.515005820, 48.195, 2852.0, 53.4041
14.569338020, 48.195, 2806.0, 52.9717
14.623670220, 48.195, 2768.0, 52.6118
14.678002420, 48.195, 2707.0, 52.0288
14.732334620, 48.195, 2743.0, 52.3737
14.786666820, 48.195, 2610.0, 51.0882
14.840999020, 48.195, 2720.0, 52.1536
14.895331220, 48.195, 2707.0, 52.0288
14.949663420, 48.195, 2573.0, 50.7247
15.003995620, 48.195, 2645.0, 51.4296
15.058327820, 48.195, 2636.0, 51.3420
15.112660020, 48.195, 2706.0, 52.0192
15.166992220, 48.195, 2637.0, 51.3517
15.221324420, 48.195, 2571.0, 50.7050
15.275656620, 48.195, 2611.0, 51.0979
15.329988820, 48.195, 2613.0, 51.1175
15.384321020, 48.195, 2579.0, 50.7839
15.438653220, 48.195, 2491.0, 49.9099
15.492985420, 48.195, 2532.0, 50.3190
15.547317620, 48.195, 2664.0, 51.6140
15.601649820, 48.195, 2629.0, 51.2738
15.655982020, 48.195, 2587.0, 50.8626
15.710314220, 48.195, 2754.0, 52.4786
15.764646420, 48.195, 2684.0, 51.8073
15.818978620, 48.195, 2891.0, 53.7680
15.873310820, 48.195, 3294.0, 57.3934
15.927643020, 48.195, 3618.0, 60.1498
15.981975220, 48.195, 4271.0, 65.3529
16.036307420, 48.195, 4565.0, 67.5648
16.090639620, 48.195, 4949.0, 70.3491
16.144971820, 48.195, 6147.0, 78.4028
16.199304020, 48.195, 6673.0, 81.6884
16.253636220, 48.195, 5595.0, 74.7997
16.307968420, 48.195, 4080.0, 63.8749
16.362300620, 48.195, 3070.0, 55.4076
16.416632820, 48.195, 2654.0, 51.5170
16.470965020, 48.195, 2565.0, 50.6458
16.525297220, 48.195, 2421.0, 49.2037
16.579629420, 48.195, 2393.0, 48.9183
16.633961620, 48.195, 2282.0, 47.7703
16.688293820, 48.195, 2266.0, 47.6025
16.742626020, 48.195, 2348.0, 48.4562
16.796958220, 48.195, 2316.0, 48.1248
16.851290420, 48.195, 2323.0, 48.1975
16.905622620, 48.195, 2252.0, 47.4552
16.959954820, 48.195, 2347.0, 48.4458
17.014287020, 48.195, 2320.0, 48.1664
17.068619220, 48.195, 2249.0, 47.4236
17.122951420, 48.195, 2430.0, 49.2950
17.177283620, 48.195, 2286.0, 47.8121
17.231615820, 48.195, 2272.0, 47.6655
17.285948020, 48.195, 2333.0, 48.3011
17.340280220, 48.195, 2230.0, 47.2229
17.394612420, 48.195, 2313.0, 48.0937
17.448944620, 48.195, 2266.0, 47.6025
17.503276820, 48.195, 2371.0, 48.6929
17.557609020, 48.195, 2234.0, 47.2652
17.611941220, 48.195, 2362.0, 48.6004
17.666273420, 48.195, 2349.0, 48.4665
17.720605620, 48.195, 2389.0, 48.8774
17.774937820, 48.195, 2326.0, 48.2286
17.829270020, 48.195, 2348.0, 48.4562
17.883602220, 48.195, 2417.0, 49.1630
17.937934420, 48.195, 2538.0, 50.3786
17.992266620, 48.195, 2912.0, 53.9630
18.046598820, 48.195, 3305.0, 57.4891
18.100931020, 48.195, 4096.0, 64.0000
18.155263220, 48.195, 4460.0, 66.7832
18.209595420, 48.195, 4680.0, 68.4105
18.263927620, 48.195, 4835.0, 69.5342
18.318259820, 48.195, 4870.0, 69.7854
18.372592020, 48.195, 4139.0, 64.3351
18.426924220, 48.195, 3157.0, 56.1872
18.481256420, 48.195, 2704.0, 52.0000
18.535588620, 48.195, 2431.0, 49.3052
18.589920820, 48.195, 2475.0, 49.7494
18.644253020, 48.195, 2415.0, 49.1426
18.698585220, 48.195, 2440.0, 49.3964
18.752917420, 48.195, 2350.0, 48.4768
18.807249620, 48.195, 2448.0, 49.4773
18.861581820, 48.195, 2413.0, 49.1223
18.915914020, 48.195, 2472.0, 49.7192
18.970246220, 48.195, 2454.0, 49.5379
19.024578420, 48.195, 2460.0, 49.5984
19.078910620, 48.195, 2572.0, 50.7149
19.133242820, 48.195, 2710.0, 52.0577
19.187575020, 48.195, 3204.0, 56.6039
19.241907220, 48.195, 3496.0, 59.1270
19.296239420, 48.195, 3918.0, 62.5939
19.350571620, 48.195, 4105.0, 64.0703
19.404903820, 48.195, 4070.0, 63.7966
19.459236020, 48.195, 4047.0, 63.6160
19.513568220, 48.195, 4136.0, 64.3117
19.567900420, 48.195, 3664.0, 60.5310
19.622232620, 48.195, 2838.0, 53.2729
19.676564820, 48.195, 2621.0, 51.1957
19.730897020, 48.195, 2438.0, 49.3761
19.785229220, 48.195, 2532.0, 50.3190
19.839561420, 48.195, 2673.0, 51.7011
19.893893620, 48.195, 2517.0, 50.1697
19.948225820, 48.195, 2471.0, 49.7092
20.002558020, 48.195, 2427.0, 49.2646
20.056890220, 48.195, 2542.0, 50.4183
20.111222420, 48.195, 2496.0, 49.9600
20.165554620, 48.195, 2491.0, 49.9099
20.219886820, 48.195, 2636.0, 51.3420
20.274219020, 48.195, 2608.0, 51.0686
20.328551220, 48.195, 2639.0, 51.3712
20.382883420, 48.195, 2820.0, 53.1037
20.437215620, 48.195, 2784.0, 52.7636
20.491547820, 48.195, 2876.0, 53.6284
20.545880020, 48.195, 2963.0, 54.4334
20.600212220, 48.195, 3084.0, 55.5338
20.654544420, 48.195, 3072.0, 55.4256
20.708876620, 48.195, 2994.0, 54.7175
20.763208820, 48.195, 3041.0, 55.1453
20.817541020, 48.195, 2896.0, 53.8145
20.871873220, 48.195, 2904.0, 53.8888
20.926205420, 48.195, 2838.0, 53.2729
20.980537620, 48.195, 2790.0, 52.8205
21.034869820, 48.195, 2769.0, 52.6213
21.089202020, 48.195, 2892.0, 53.7773
21.143534220, 48.195, 2850.0, 53.3854
21.197866420, 48.195, 2872.0, 53.5910
21.252198620, 48.195, 2928.0, 54.1110
21.306530820, 48.195, 2821.0, 53.1131
21.360863020, 48.195, 2949.0, 54.3047
21.415195220, 48.195, 2875.0, 53.6190
21.469527420, 48.195, 3047.0, 55.1996
21.523859620, 48.195, 3015.0, 54.9090
21.578191820, 48.195, 2975.0, 54.5436
21.632524020, 48.195, 3088.0, 55.5698
21.686856220, 48.195, 3148.0, 56.1070
21.741188420, 48.195, 3105.0, 55.7225
21.795520620, 48.195, 3346.0, 57.8446
21.849852820, 48.195, 3419.0, 58.4722
21.904185020, 48.195, 3502.0, 59.1777
21.958517220, 48.195, 3796.0, 61.6117
22.012849420, 48.195, 4134.0, 64.2962
22.067181620, 48.195, 4568.0, 67.5870
22.121513820, 48.195, 4947.0, 70.3349
22.175846020, 48.195, 5587.0, 74.7462
22.230178220, 48.195, 6718.0, 81.9634
22.284510420, 48.195, 8363.0, 91.4494
22.338842620, 48.195, 10149.0, 100.7422
22.393174820, 48.195, 11606.0, 107.7311
22.447507020, 48.195, 13406.0, 115.7843
22.501839220, 48.195, 18012.0, 134.2088
22.556171420, 48.195, 31614.0, 177.8033
22.610503620, 48.195, 50801.0, 225.3908
22.664835820, 48.195, 67603.0, 260.0058
22.719168020, 48.195, 96955.0, 311.3760
22.773500220, 48.195, 144666.0, 380.3498
22.827832420, 48.195, 174930.0, 418.2463
22.882164620, 48.195, 165934.0, 407.3500
22.936496820, 48.195, 160075.0, 400.0937
22.990829020, 48.195, 178596.0, 422.6062
23.045161220, 48.195, 155772.0, 394.6796
23.099493420, 48.195, 106467.0, 326.2928
23.153825620, 48.195, 68536.0, 261.7938
23.208157820, 48.195, 38750.0, 196.8502
23.262490020, 48.195, 22987.0, 151.6146
23.316822220, 48.195, 17922.0, 133.8731
23.371154420, 48.195, 18393.0, 135.6208
23.425486620, 48.195, 19625.0, 140.0893
23.479818820, 48.195, 20022.0, 141.4991
23.534151020, 48.195, 16456.0, 128.2809
23.588483220, 48.195, 12219.0, 110.5396
23.642815420, 48.195, 9592.0, 97.9388
23.697147620, 48.195, 8782.0, 93.7123
23.751479820, 48.195, 8766.0, 93.6269
23.805812020, 48.195, 8433.0, 91.8314
23.860144220, 48.195, 7065.0, 84.0536
23.914476420, 48.195, 6059.0, 77.8396
23.968808620, 48.195, 5297.0, 72.7805
24.023140820, 48.195, 5369.0, 73.2735
24.077473020, 48.195, 5466.0, 73.9324
24.131805220, 48.195, 5339.0, 73.0685
24.186137420, 48.195, 5362.0, 73.2257
24.240469620, 48.195, 5587.0, 74.7462
24.294801820, 48.195, 5602.0, 74.8465
24.349134020, 48.195, 5944.0, 77.0973
24.403466220, 48.195, 6662.0, 81.6211
24.457798420, 48.195, 8079.0, 89.8833
24.512130620, 48.195, 11779.0, 108.5311
24.566462820, 48.195, 22044.0, 148.4722
24.620795020, 48.195, 35292.0, 187.8617
24.675127220, 48.195, 46960.0, 216.7026
24.729459420, 48.195, 58069.0, 240.9751
24.783791620, 48.195, 65548.0, 256.0234
24.838123820, 48.195, 60720.0, 246.4143
24.892456020, 48.195, 51407.0, 226.7311
24.946788220, 48.195, 35737.0, 189.0423
25.001120420, 48.195, 20271.0, 142.3763
25.055452620, 48.195, 10839.0, 104.1105
25.109784820, 48.195, 6984.0, 83.5703
25.164117020, 48.195, 5583.0, 74.7195
25.218449220, 48.195, 5275.0, 72.6292
25.272781420, 48.195, 4805.0, 69.3181
25.327113620, 48.195, 4732.0, 68.7895
25.381445820, 48.195, 4397.0, 66.3099
25.435778020, 48.195, 4312.0, 65.6658
25.490110220, 48.195, 4230.0, 65.0385
25.544442420, 48.195, 4368.0, 66.0908
25.598774620, 48.195, 4173.0, 64.5988
25.653106820, 48.195, 4135.0, 64.3040
25.707439020, 48.195, 4306.0, 65.6201
25.761771220, 48.195, 4200.0, 64.8074
25.816103420, 48.195, 4267.0, 65.3223
25.870435620, 48.195, 4272.0, 65.3605
25.924767820, 48.195, 4391.0, 66.2646
25.979100020, 48.195, 4476.0, 66.9029
26.033432220, 48.195, 4640.0, 68.1175
26.087764420, 48.195, 4914.0, 70.0999
26.142096620, 48.195, 4681.0, 68.4178
26.196428820, 48.195, 4400.0, 66.3325
26.250761020, 48.195, 4106.0, 64.0781
26.305093220, 48.195, 4223.0, 64.9846
26.359425420, 48.195, 4996.0, 70.6824
26.413757620, 48.195, 6017.0, 77.5693
26.468089820, 48.195, 6357.0, 79.7308
26.522422020, 48.195, 6214.0, 78.8289
26.576754220, 48.195, 5846.0, 76.4591
26.631086420, 48.195, 5438.0, 73.7428
26.685418620, 48.195, 5625.0, 75.0000
26.739750820, 48.195, 5431.0, 73.6953
26.794083020, 48.195, 4995.0, 70.6753
26.848415220, 48.195, 4199.0, 64.7997
26.902747420, 48.195, 4164.0, 64.5291
26.957079620, 48.195, 3954.0, 62.8808
27.011411820, 48.195, 4206.0, 64.8537
27.065744020, 48.195, 4390.0, 66.2571
27.120076220, 48.195, 4667.0, 68.3154
27.174408420, 48.195, 5032.0, 70.9366
27.228740620, 48.195, 5225.0, 72.2842
27.283072820, 48.195, 5815.0, 76.2561
27.337405020, 48.195, 6950.0, 83.3667
27.391737220, 48.195, 8123.0, 90.1277
27.446069420, 48.195, 8960.0, 94.6573
27.500401620, 48.195, 11315.0, 106.3720
27.554733820, 48.195, 17391.0, 131.8749
27.609066020, 48.195, 25278.0, 158.9906
27.663398220, 48.195, 31648.0, 177.8988
27.717730420, 48.195, 33899.0, 184.1168
27.772062620, 48.195, 36400.0, 190.7878
27.826394820, 48.195, 38602.0, 196.4739
27.880727020, 48.195, 46871.0, 216.4971
27.935059220, 48.195, 45108.0, 212.3864
27.989391420, 48.195, 36825.0, 191.8984
28.043723620, 48.195, 19666.0, 140.2355
28.098055820, 48.195, 9102.0, 95.4044
28.152388020, 48.195, 5601.0, 74.8398
28.206720220, 48.195, 4795.0, 69.2459
28.261052420, 48.195, 4245.0, 65.1537
28.315384620, 48.195, 4116.0, 64.1561
28.369716820, 48.195, 3763.0, 61.3433
28.424049020, 48.195, 3699.0, 60.8194
28.478381220, 48.195, 3537.0, 59.4727
28.532713420, 48.195, 3480.0, 58.9915
28.587045620, 48.195, 3451.0, 58.7452
28.641377820, 48.195, 3410.0, 58.3952
28.695710020, 48.195, 3242.0, 56.9386
28.750042220, 48.195, 3334.0, 57.7408
28.804374420, 48.195, 3299.0, 57.4369
28.858706620, 48.195, 3213.0, 56.6833
28.913038820, 48.195, 3204.0, 56.6039
28.967371020, 48.195, 3119.0, 55.8480
29.021703220, 48.195, 3127.0, 55.9196
29.076035420, 48.195, 3156.0, 56.1783
29.130367620, 48.195, 3018.0, 54.9363
29.184699820, 48.195, 2987.0, 54.6535
29.239032020, 48.195, 3006.0, 54.8270
29.293364220, 48.195, 3061.0, 55.3263
29.347696420, 48.195, 2952.0, 54.3323
29.402028620, 48.195, 3238.0, 56.9034
29.456360820, 48.195, 3307.0, 57.5065
29.510693020, 48.195, 3416.0, 58.4466
29.565025220, 48.195, 3478.0, 58.9746
29.619357420, 48.195, 3572.0, 59.7662
29.673689620, 48.195, 3481.0, 59.0000
29.728021820, 48.195, 3373.0, 58.0775
29.782354020, 48.195, 3220.0, 56.7450
29.836686220, 48.195, 3269.0, 57.1752
29.891018420, 48.195, 2921.0, 54.0463
29.945350620, 48.195, 2800.0, 52.9150
29.999682820, 48.195, 2800.0, 52.9150
30.054015020, 48.195, 2751.0, 52.4500
30.108347220, 48.195, 2629.0, 51.2738
30.162679420, 48.195, 2708.0, 52.0384
30.217011620, 48.195, 2511.0, 50.1099
30.271343820, 48.195, 2603.0, 51.0196
30.325676020, 48.195, 2726.0, 52.2111
30.380008220, 48.195, 2621.0, 51.1957
30.434340420, 48.195, 2613.0, 51.1175
30.488672620, 48.195, 2550.0, 50.4975
30.543004820, 48.195, 2582.0, 50.8134
30.597337020, 48.195, 2543.0, 50.4282
30.651669220, 48.195, 2557.0, 50.5668
30.706001420, 48.195, 2469.0, 49.6890
30.760333620, 48.195, 2596.0, 50.9510
30.814665820, 48.195, 2571.0, 50.7050
30.868998020, 48.195, 2508.0, 50.0799
30.923330220, 48.195, 2481.0, 49.8096
30.977662420, 48.195, 2566.0, 50.6557
31.031994620, 48.195, 2571.0, 50.7050
31.086326820, 48.195, 2513.0, 50.1298
31.140659020, 48.195, 2576.0, 50.7543
31.194991220, 48.195, 2637.0, 51.3517
31.249323420, 48.195, 2701.0, 51.9711
31.303655620, 48.195, 2917.0, 54.0093
31.357987820, 48.195, 3349.0, 57.8705
31.412320020, 48.195, 3560.0, 59.6657
31.466652220, 48.195, 4071.0, 63.8044
31.520984420, 48.195, 5152.0, 71.7774
31.575316620, 48.195, 5859.0, 76.5441
31.629648820, 48.195, 6912.0, 83.1384
31.683981020, 48.195, 6882.0, 82.9578
31.738313220, 48.195, 6189.0, 78.6702
31.792645420, 48.195, 5089.0, 71.3372
31.846977620, 48.195, 4470.0, 66.8581
31.901309820, 48.195, 4204.0, 64.8383
31.955642020, 48.195, 4342.0, 65.8939
32.009974220, 48.195, 5057.0, 71.1126
32.064306420, 48.195, 5663.0, 75.2529
32.118638620, 48.195, 5682.0, 75.3790
32.172970820, 48.195, 6131.0, 78.3007
32.227303020, 48.195, 7375.0, 85.8778
32.281635220, 48.195, 8320.0, 91.2140
32.335967420, 48.195, 9845.0, 99.2220
32.390299620, 48.195, 11576.0, 107.5918
32.444631820, 48.195, 10182.0, 100.9059
32.498964020, 48.195, 8027.0, 89.5935
32.553296220, 48.195, 8330.0, 91.2688
32.607628420, 48.195, 9852.0, 99.2572
32.661960620, 48.195, 10173.0, 100.8613
32.716292820, 48.195, 7591.0, 87.1263
32.770625020, 48.195, 5281.0, 72.6705
32.824957220, 48.195, 3936.0, 62.7375
32.879289420, 48.195, 3396.0, 58.2752
32.933621620, 48.195, 3434.0, 58.6003
32.987953820, 48.195, 3682.0, 60.6795
33.042286020, 48.195, 3585.0, 59.8749
33.096618220, 48.195, 3448.0, 58.7197
33.150950420, 48.195, 3275.0, 57.2276
33.205282620, 48.195, 3287.0, 57.3324
33.259614820, 48.195, 3537.0, 59.4727
33.313947020, 48.195, 3477.0, 58.9661
33.368279220, 48.195, 3572.0, 59.7662
33.422611420, 48.195, 3924.0, 62.6418
33.476943620, 48.195, 3475.0, 58.9491
33.531275820, 48.195, 3130.0, 55.9464
33.585608020, 48.195, 2620.0, 51.1859
33.639940220, 48.195, 2680.0, 51.7687
33.694272420, 48.195, 2786.0, 52.7826
33.748604620, 48.195, 2929.0, 54.1202
33.802936820, 48.195, 2880.0, 53.6656
33.857269020, 48.195, 2990.0, 54.6809
33.911601220, 48.195, 2999.0, 54.7631
33.965933420, 48.195, 2848.0, 53.3667
34.020265620, 48.195, 3009.0, 54.8544
34.074597820, 48.195, 3140.0, 56.0357
34.128930020, 48.195, 3328.0, 57.6888
34.183262220, 48.195, 2876.0, 53.6284
34.237594420, 48.195, 2558.0, 50.5767
34.291926620, 48.195, 2284.0, 47.7912
34.346258820, 48.195, 2241.0, 47.3392
34.400591020, 48.195, 2258.0, 47.5184
34.454923220, 48.195, 2183.0, 46.7226
34.509255420, 48.195, 2118.0, 46.0217
34.563587620, 48.195, 2247.0, 47.4025
34.617919820, 48.195, 2324.0, 48.2079
34.672252020, 48.195, 2236.0, 47.2864
34.726584220, 48.195, 2272.0, 47.6655
34.780916420, 48.195, 2288.0, 47.8330
34.835248620, 48.195, 2237.0, 47.2969
34.889580820, 48.195, 2208.0, 46.9894
34.943913020, 48.195, 2132.0, 46.1736
34.998245220, 48.195, 2208.0, 46.9894
35.052577420, 48.195, 2047.0, 45.2438
35.106909620, 48.195, 2261.0, 47.5500
35.161241820, 48.195, 2165.0, 46.5296
35.215574020, 48.195, 2222.0, 47.1381
35.269906220, 48.195, 2154.0, 46.4112
35.324238420, 48.195, 2317.0, 48.1352
35.378570620, 48.195, 2437.0, 49.3660
35.432902820, 48.195, 2716.0, 52.1153
35.487235020, 48.195, 2934.0, 54.1664
35.541567220, 48.195, 3258.0, 57.0789
35.595899420, 48.195, 3775.0, 61.4410
35.650231620, 48.195, 4869.0, 69.7782
35.704563820, 48.195, 5704.0, 75.5248
35.758896020, 48.195, 6799.0, 82.4560
35.813228220, 48.195, 7411.0, 86.0872
35.867560420, 48.195, 7194.0, 84.8175
35.921892620, 48.195, 7971.0, 89.2805
35.976224820, 48.195, 7561.0, 86.9540
36.030557020, 48.195, 6620.0, 81.3634
36.084889220, 48.195, 5539.0, 74.4245
36.139221420, 48.195, 4903.0, 70.0214
36.193553620, 48.195, 4048.0, 63.6239
36.247885820, 48.195, 3554.0, 59.6154
36.302218020, 48.195, 2981.0, 54.5985
36.356550220, 48.195, 2635.0, 51.3323
36.410882420, 48.195, 2558.0, 50.5767
36.465214620, 48.195, 2412.0, 49.1121
36.519546820, 48.195, 2517.0, 50.1697
36.573879020, 48.195, 2700.0, 51.9615
36.628211220, 48.195, 2795.0, 52.8678
36.682543420, 48.195, 2749.0, 52.4309
36.736875620, 48.195, 2838.0, 53.2729
36.791207820, 48.195, 3013.0, 54.8908
36.845540020, 48.195, 3432.0, 58.5833
36.899872220, 48.195, 3216.0, 56.7098
36.954204420, 48.195, 3139.0, 56.0268
37.008536620, 48.195, 3078.0, 55.4797
37.062868820, 48.195, 2935.0, 54.1756
37.117201020, 48.195, 2761.0, 52.5452
37.171533220, 48.195, 2490.0, 49.8999
37.225865420, 48.195, 2290.0, 47.8539
37.280197620, 48.195, 2186.0, 46.7547
37.334529820, 48.195, 2067.0, 45.4643
37.388862020, 48.195, 2133.0, 46.1844
37.443194220, 48.195, 2023.0, 44.9778
37.497526420, 48.195, 2187.0, 46.7654
37.551858620, 48.195, 2107.0, 45.9021
37.606190820, 48.195, 2204.0, 46.9468
37.660523020, 48.195, 2210.0, 47.0106
37.714855220, 48.195, 2095.0, 45.7712
37.769187420, 48.195, 2129.0, 46.1411
37.823519620, 48.195, 2105.0, 45.8803
37.877851820, 48.195, 2202.0, 46.9255
37.932184020, 48.195, 2168.0, 46.5618
37.986516220, 48.195, 2045.0, 45.2217
38.040848420, 48.195, 2164.0, 46.5188
38.095180620, 48.195, 2086.0, 45.6727
38.149512820, 48.195, 2112.0, 45.9565
38.203845020, 48.195, 2143.0, 46.2925
38.258177220, 48.195, 2074.0, 45.5412
38.312509420, 48.195, 2005.0, 44.7772
38.366841620, 48.195, 2129.0, 46.1411
38.421173820, 48.195, 2164.0, 46.5188
38.475506020, 48.195, 2136.0, 46.2169
38.529838220, 48.195, 2184.0, 46.7333
38.584170420, 48.195, 2134.0, 46.1952
38.638502620, 48.195, 2137.0, 46.2277
38.692834820, 48.195, 2202.0, 46.9255
38.747167020, 48.195, 2267.0, 47.6130
38.801499220, 48.195, 2270.0, 47.6445
38.855831420, 48.195, 2411.0, 49.1019
38.910163620, 48.195, 2595.0, 50.9411
38.964495820, 48.195, 2658.0, 51.5558
39.018828020, 48.195, 2732.0, 52.2685
39.073160220, 48.195, 3064.0, 55.3534
39.127492420, 48.195, 3465.0, 58.8643
39.181824620, 48.195, 3749.0, 61.2291
39.236156820, 48.195, 4052.0, 63.6553
39.290489020, 48.195, 4500.0, 67.0820
39.344821220, 48.195, 5849.0, 76.4788
39.399153420, 48.195, 6040.0, 77.7174
39.453485620, 48.195, 5590.0, 74.7663
39.507817820, 48.195, 4458.0, 66.7683
39.562150020, 48.195, 3492.0, 59.0931
39.616482220, 48.195, 3186.0, 56.4447
39.670814420, 48.195, 3382.0, 58.1550
39.725146620, 48.195, 3603.0, 60.0250
39.779478820, 48.195, 4947.0, 70.3349
39.833811020, 48.195, 6026.0, 77.6273
39.888143220, 48.195, 8033.0, 89.6270
39.942475420, 48.195, 7722.0, 87.8749
39.996807620, 48.195, 8398.0, 91.6406
40.051139820, 48.195, 8119.0, 90.1055
40.105472020, 48.195, 7344.0, 85.6971
40.159804220, 48.195, 5375.0, 73.3144
40.214136420, 48.195, 4296.0, 65.5439
40.268468620, 48.195, 3407.0, 58.3695
40.322800820, 48.195, 2984.0, 54.6260
40.377133020, 48.195, 2659.0, 51.5655
40.431465220, 48.195, 2573.0, 50.7247
40.485797420, 48.195, 2287.0, 47.8226
40.540129620, 48.195, 2289.0, 47.8435
40.594461820, 48.195, 2531.0, 50.3090
40.648794020, 48.195, 2694.0, 51.9038
40.703126220, 48.195, 3530.0, 59.4138
40.757458420, 48.195, 4192.0, 64.7457
40.811790620, 48.195, 4769.0, 69.0579
40.866122820, 48.195, 5369.0, 73.2735
40.920455020, 48.195, 4830.0, 69.4982
40.974787220, 48.195, 4312.0, 65.6658
41.029119420, 48.195, 3900.0, 62.4500
41.083451620, 48.195, 3534.0, 59.4475
41.137783820, 48.195, 3266.0, 57.1489
41.192116020, 48.195, 3351.0, 57.8878
41.246448220, 48.195, 3238.0, 56.9034
41.300780420, 48.195, 3555.0, 59.6238
41.355112620, 48.195, 4190.0, 64.7302
41.409444820, 48.195, 4413.0, 66.4304
41.463777020, 48.195, 3941.0, 62.7774
41.518109220, 48.195, 3633.0, 60.2744
41.572441420, 48.195, 2902.0, 53.8702
41.626773620, 48.195, 2553.0, 50.5272
41.681105820, 48.195, 2282.0, 47.7703
41.735438020, 48.195, 2231.0, 47.2335
41.789770220, 48.195, 1997.0, 44.6878
41.844102420, 48.195, 2098.0, 45.8039
41.898434620, 48.195, 2062.0, 45.4093
41.952766820, 48.195, 2174.0, 46.6262
42.007099020, 48.195, 2119.0, 46.0326
42.061431220, 48.195, 2048.0, 45.2548
42.115763420, 48.195, 2033.0, 45.0888
42.170095620, 48.195, 2037.0, 45.1331
42.224427820, 48.195, 2035.0, 45.1110
42.278760020, 48.195, 2025.0, 45.0000
42.333092220, 48.195, 2052.0, 45.2990
42.387424420, 48.195, 1983.0, 44.5309
42.441756620, 48.195, 2086.0, 45.6727
42.496088820, 48.195, 2106.0, 45.8912
42.550421020, 48.195, 2175.0, 46.6369
42.604753220, 48.195, 2478.0, 49.7795
42.659085420, 48.195, 2737.0, 52.3163
42.713417620, 48.195, 3140.0, 56.0357
42.767749820, 48.195, 3792.0, 61.5792
42.822082020, 48.195, 4318.0, 65.7115
42.876414220, 48.195, 4351.0, 65.9621
42.930746420, 48.195, 4444.0, 66.6633
42.985078620, 48.195, 4245.0, 65.1537
43.039410820, 48.195, 3808.0, 61.7090
43.093743020, 48.195, 3388.0, 58.2065
43.148075220, 48.195, 2921.0, 54.0463
43.202407420, 48.195, 2640.0, 51.3809
43.256739620, 48.195, 2429.0, 49.2849
43.311071820, 48.195, 2206.0, 46.9681
43.365404020, 48.195, 2030.0, 45.0555
43.419736220, 48.195, 1956.0, 44.2267
43.474068420, 48.195, 1893.0, 43.5086
43.528400620, 48.195, 1936.0, 44.0000
43.582732820, 48.195, 1898.0, 43.5660
43.637065020, 48.195, 1880.0, 43.3590
43.691397220, 48.195, 1939.0, 44.0341
43.745729420, 48.195, 1954.0, 44.2041
43.800061620, 48.195, 1916.0, 43.7721
43.854393820, 48.195, 1932.0, 43.9545
43.908726020, 48.195, 1917.0, 43.7836
43.963058220, 48.195, 1975.0, 44.4410
44.017390420, 48.195, 1864.0, 43.1741
44.071722620, 48.195, 1783.0, 42.2256
44.126054820, 48.195, 1847.0, 42.9767
44.180387020, 48.195, 1881.0, 43.3705
44.234719220, 48.195, 1908.0, 43.6807
44.289051420, 48.195, 1781.0, 42.2019
44.343383620, 48.195, 1833.0, 42.8135
44.397715820, 48.195, 1850.0, 43.0116
44.452048020, 48.195, 1877.0, 43.3244
44.506380220, 48.195, 1929.0, 43.9204
44.560712420, 48.195, 1992.0, 44.6318
44.615044620, 48.195, 1963.0, 44.3058
44.669376820, 48.195, 1994.0, 44.6542
44.723709020, 48.195, 1943.0, 44.0795
44.778041220, 48.195, 1994.0, 44.6542
44.832373420, 48.195, 1988.0, 44.5870
44.886705620, 48.195, 2041.0, 45.1774
44.941037820, 48.195, 2455.0, 49.5480
44.995370020, 48.195, 2586.0, 50.8527
45.049702220, 48.195, 2572.0, 50.7149
45.104034420, 48.195, 2764.0, 52.5738
45.158366620, 48.195, 3017.0, 54.9272
45.212698820, 48.195, 3227.0, 56.8067
45.267031020, 48.195, 3159.0, 56.2050
45.321363220, 48.195, 3234.0, 56.8683
45.375695420, 48.195, 2768.0, 52.6118
45.430027620, 48.195, 2800.0, 52.9150
45.484359820, 48.195, 3023.0, 54.9818
45.538692020, 48.195, 3219.0, 56.7362
45.593024220, 48.195, 3236.0, 56.8859
45.647356420, 48.195, 3600.0, 60.0000
45.701688620, 48.195, 3414.0, 58.4294
45.756020820, 48.195, 3404.0, 58.3438
45.810353020, 48.195, 3644.0, 60.3656
45.864685220, 48.195, 5701.0, 75.5050
45.919017420, 48.195, 6976.0, 83.5225
45.973349620, 48.195, 7157.0, 84.5991
46.027681820, 48.195, 7184.0, 84.7585
46.082014020, 48.195, 6605.0, 81.2712
46.136346220, 48.195, 5879.0, 76.6746
46.190678420, 48.195, 5011.0, 70.7884
46.245010620, 48.195, 4162.0, 64.5136
46.299342820, 48.195, 3493.0, 59.1016
46.353675020, 48.195, 2975.0, 54.5436
46.408007220, 48.195, 2692.0, 51.8845
46.462339420, 48.195, 2397.0, 48.9592
46.516671620, 48.195, 2427.0, 49.2646
46.571003820, 48.195, 2321.0, 48.1768
46.625336020, 48.195, 2696.0, 51.9230
46.679668220, 48.195, 3197.0, 56.5420
46.734000420, 48.195, 3725.0, 61.0328
46.788332620, 48.195, 3691.0, 60.7536
46.842664820, 48.195, 3559.0, 59.6574
46.896997020, 48.195, 3560.0, 59.6657
46.951329220, 48.195, 3217.0, 56.7186
47.005661420, 48.195, 3298.0, 57.4282
47.059993620, 48.195, 3277.0, 57.2451
47.114325820, 48.195, 2843.0, 53.3198
47.168658020, 48.195, 2592.0, 50.9117
47.222990220, 48.195, 2370.0, 48.6826
47.277322420, 48.195, 2175.0, 46.6369
47.331654620, 48.195, 2083.0, 45.6399
47.385986820, 48.195, 2368.0, 48.6621
47.440319020, 48.195, 2496.0, 49.9600
47.494651220, 48.195, 2939.0, 54.2125
47.548983420, 48.195, 3718.0, 60.9754
47.603315620, 48.195, 4181.0, 64.6607
47.657647820, 48.195, 4311.0, 65.6582
47.711980020, 48.195, 3798.0, 61.6279
47.766312220, 48.195, 3261.0, 57.1052
47.820644420, 48.195, 2874.0, 53.6097
47.874976620, 48.195, 2527.0, 50.2693
47.929308820, 48.195, 2526.0, 50.2593
47.983641020, 48.195, 2663.0, 51.6043
48.037973220, 48.195, 2417.0, 49.1630
48.092305420, 48.195, 2358.0, 48.5592
48.146637620, 48.195, 2413.0, 49.1223
48.200969820, 48.195, 2223.0, 47.1487
48.255302020, 48.195, 2291.0, 47.8644
48.309634220, 48.195, 2172.0, 46.6047
48.363966420, 48.195, 2210.0, 47.0106
48.418298620, 48.195, 2139.0, 46.2493
48.472630820, 48.195, 2167.0, 46.5510
48.526963020, 48.195, 1996.0, 44.6766
48.581295220, 48.195, 1945.0, 44.1022
48.635627420, 48.195, 1808.0, 42.5206
48.689959620, 48.195, 1825.0, 42.7200
48.744291820, 48.195, 1846.0, 42.9651
48.798624020, 48.195, 1850.0, 43.0116
48.852956220, 48.195, 1782.0, 42.2137
48.907288420, 48.195, 1831.0, 42.7902
48.961620620, 48.195, 1888.0, 43.4511
49.015952820, 48.195, 1909.0, 43.6921
49.070285020, 48.195, 1895.0, 43.5316
49.124617220, 48.195, 1972.0, 44.4072
49.178949420, 48.195, 1817.0, 42.6263
49.233281620, 48.195, 1939.0, 44.0341
49.287613820, 48.195, 2032.0, 45.0777
49.341946020, 48.195, 2031.0, 45.0666
49.396278220, 48.195, 1989.0, 44.5982
49.450610420, 48.195, 1886.0, 43.4281
49.504942620, 48.195, 1764.0, 42.0000
49.559274820, 48.195, 1807.0, 42.5088
49.613607020, 48.195, 1865.0, 43.1856
49.667939220, 48.195, 1810.0, 42.5441
49.722271420, 48.195, 1889.0, 43.4626
49.776603620, 48.195, 1970.0, 44.3847
49.830935820, 48.195, 1858.0, 43.1045
49.885268020, 48.195, 1981.0, 44.5084
49.939600220, 48.195, 1954.0, 44.2041
49.993932420, 48.195, 1937.0, 44.0114
50.048264620, 48.195, 1889.0, 43.4626
50.102596820, 48.195, 1885.0, 43.4166
50.156929020, 48.195, 1769.0, 42.0595
50.211261220, 48.195, 1917.0, 43.7836
50.265593420, 48.195, 1717.0, 41.4367
50.319925620, 48.195, 1686.0, 41.0609
50.374257820, 48.195, 1688.0, 41.0853
50.428590020, 48.195, 1666.0, 40.8167
50.482922220, 48.195, 1627.0, 40.3361
50.537254420, 48.195, 1652.0, 40.6448
50.591586620, 48.195, 1591.0, 39.8873
50.645918820, 48.195, 1778.0, 42.1663
50.700251020, 48.195, 1741.0, 41.7253
50.754583220, 48.195, 1744.0, 41.7612
50.808915420, 48.195, 1859.0, 43.1161
50.863247620, 48.195, 1929.0, 43.9204
50.917579820, 48.195, 1923.0, 43.8520
50.971912020, 48.195, 1936.0, 44.0000
51.026244220, 48.195, 1912.0, 43.7264
51.080576420, 48.195, 1894.0, 43.5201
51.134908620, 48.195, 1949.0, 44.1475
51.189240820, 48.195, 1981.0, 44.5084
51.243573020, 48.195, 2244.0, 47.3709
51.297905220, 48.195, 2414.0, 49.1325
51.352237420, 48.195, 2204.0, 46.9468
51.406569620, 48.195, 2117.0, 46.0109
51.460901820, 48.195, 2036.0, 45.1221
51.515234020, 48.195, 1911.0, 43.7150
51.569566220, 48.195, 1822.0, 42.6849
51.623898420, 48.195, 2038.0, 45.1442
51.678230620, 48.195, 2112.0, 45.9565
51.732562820, 48.195, 2299.0, 47.9479
51.786895020, 48.195, 2350.0, 48.4768
51.841227220, 48.195, 2257.0, 47.5079
51.895559420, 48.195, 2042.0, 45.1885
51.949891620, 48.195, 1896.0, 43.5431
52.004223820, 48.195, 1709.0, 41.3401
52.058556020, 48.195, 1633.0, 40.4104
52.112888220, 48.195, 1734.0, 41.6413
52.167220420, 48.195, 1630.0, 40.3733
52.221552620, 48.195, 1742.0, 41.7373
52.275884820, 48.195, 1599.0, 39.9875
52.330217020, 48.195, 1577.0, 39.7115
52.384549220, 48.195, 1623.0, 40.2865
52.438881420, 48.195, 1660.0, 40.7431
52.493213620, 48.195, 1616.0, 40.1995
52.547545820, 48.195, 1596.0, 39.9500
52.601878020, 48.195, 1623.0, 40.2865
52.656210220, 48.195, 1600.0, 40.0000
52.710542420, 48.195, 1591.0, 39.8873
52.764874620, 48.195, 1654.0, 40.6694
52.819206820, 48.195, 1744.0, 41.7612
52.873539020, 48.195, 1741.0, 41.7253
52.927871220, 48.195, 1828.0, 42.7551
52.982203420, 48.195, 1705.0, 41.2916
53.036535620, 48.195, 1845.0, 42.9535
53.090867820, 48.195, 1710.0, 41.3521
53.145200020, 48.195, 1754.0, 41.8808
53.199532220, 48.195, 1828.0, 42.7551
53.253864420, 48.195, 1823.0, 42.6966
53.308196620, 48.195, 1805.0, 42.4853
53.362528820, 48.195, 1893.0, 43.5086
53.416861020, 48.195, 1878.0, 43.3359
53.471193220, 48.195, 1942.0, 44.0681
53.525525420, 48.195, 1926.0, 43.8862
53.579857620, 48.195, 1974.0, 44.4297
53.634189820, 48.195, 2101.0, 45.8367
53.688522020, 48.195, 2088.0, 45.6946
53.742854220, 48.195, 2622.0, 51.2055
53.797186420, 48.195, 2534.0, 50.3389
53.851518620, 48.195, 2790.0, 52.8205
53.905850820, 48.195, 3146.0, 56.0892
53.960183020, 48.195, 3184.0, 56.4269
54.014515220, 48.195, 2904.0, 53.8888
54.068847420, 48.195, 2808.0, 52.9906
54.123179620, 48.195, 2552.0, 50.5173
54.177511820, 48.195, 2178.0, 46.6690
54.231844020, 48.195, 1933.0, 43.9659
54.286176220, 48.195, 1877.0, 43.3244
54.340508420, 48.195, 1729.0, 41.5812
54.394840620, 48.195, 1652.0, 40.6448
54.449172820, 48.195, 1562.0, 39.5221
54.503505020, 48.195, 1641.0, 40.5093
54.557837220, 48.195, 1625.0, 40.3113
54.612169420, 48.195, 1675.0, 40.9268
54.666501620, 48.195, 1696.0, 41.1825
54.720833820, 48.195, 1610.0, 40.1248
54.775166020, 48.195, 1623.0, 40.2865
54.829498220, 48.195, 1620.0, 40.2492
54.883830420, 48.195, 1500.0, 38.7298
54.938162620, 48.195, 1587.0, 39.8372
54.992494820, 48.195, 1510.0, 38.8587
55.046827020, 48.195, 1517.0, 38.9487
55.101159220, 48.195, 1539.0, 39.2301
55.155491420, 48.195, 1504.0, 38.7814
55.209823620, 48.195, 1499.0, 38.7169
55.264155820, 48.195, 1506.0, 38.8072
55.318488020, 48.195, 1469.0, 38.3275
55.372820220, 48.195, 1455.0, 38.1445
55.427152420, 48.195, 1522.0, 39.0128
55.481484620, 48.195, 1469.0, 38.3275
55.535816820, 48.195, 1535.0, 39.1791
55.590149020, 48.195, 1501.0, 38.7427
55.644481220, 48.195, 1449.0, 38.0657
55.698813420, 48.195, 1539.0, 39.2301
55.753145620, 48.195, 1505.0, 38.7943
55.807477820, 48.195, 1629.0, 40.3609
55.861810020, 48.195, 1684.0, 41.0366
55.916142220, 48.195, 1690.0, 41.1096
55.970474420, 48.195, 1767.0, 42.0357
56.024806620, 48.195, 1811.0, 42.5558
56.079138820, 48.195, 1688.0, 41.0853
56.133471020, 48.195, 1685.0, 41.0488
56.187803220, 48.195, 1732.0, 41.6173
56.242135420, 48.195, 1762.0, 41.9762
56.296467620, 48.195, 1670.0, 40.8656
56.350799820, 48.195, 1637.0, 40.4599
56.405132020, 48.195, 1683.0, 41.0244
56.459464220, 48.195, 1633.0, 40.4104
56.513796420, 48.195, 1695.0, 41.1704
56.568128620, 48.195, 1664.0, 40.7922
56.622460820, 48.195, 1653.0, 40.6571
56.676793020, 48.195, 1675.0, 40.9268
56.731125220, 48.195, 1677.0, 40.9512
56.785457420, 48.195, 1714.0, 41.4005
56.839789620, 48.195, 1745.0, 41.7732
56.894121820, 48.195, 1792.0, 42.3320
56.948454020, 48.195, 1761.0, 41.9643
57.002786220, 48.195, 1900.0, 43.5890
57.057118420, 48.195, 2062.0, 45.4093
57.111450620, 48.195, 1942.0, 44.0681
57.165782820, 48.195, 2040.0, 45.1664
57.220115020, 48.195, 2006.0, 44.7884
57.274447220, 48.195, 1875.0, 43.3013
57.328779420, 48.195, 2002.0, 44.7437
57.383111620, 48.195, 1993.0, 44.6430
57.437443820, 48.195, 1901.0, 43.6005
57.491776020, 48.195, 1928.0, 43.9090
57.546108220, 48.195, 1879.0, 43.3474
57.600440420, 48.195, 1661.0, 40.7554
57.654772620, 48.195, 1561.0, 39.5095
57.709104820, 48.195, 1531.0, 39.1280
57.763437020, 48.195, 1499.0, 38.7169
57.817769220, 48.195, 1486.0, 38.5487
57.872101420, 48.195, 1490.0, 38.6005
57.926433620, 48.195, 1534.0, 39.1663
57.980765820, 48.195, 1556.0, 39.4462
58.035098020, 48.195, 1557.0, 39.4588
58.089430220, 48.195, 1546.0, 39.3192
58.143762420, 48.195, 1494.0, 38.6523
58.198094620, 48.195, 1622.0, 40.2741
58.252426820, 48.195, 1592.0, 39.8999
58.306759020, 48.195, 1598.0, 39.9750
58.361091220, 48.195, 1553.0, 39.4081
58.415423420, 48.195, 1534.0, 39.1663
58.469755620, 48.195, 1563.0, 39.5348
58.524087820, 48.195, 1563.0, 39.5348
58.578420020, 48.195, 1538.0, 39.2173
58.632752220, 48.195, 1560.0, 39.4968
58.687084420, 48.195, 1492.0, 38.6264
58.741416620, 48.195, 1624.0, 40.2989
58.795748820, 48.195, 1491.0, 38.6135
58.850081020, 48.195, 1484.0, 38.5227
58.904413220, 48.195, 1402.0, 37.4433
58.958745420, 48.195, 1429.0, 37.8021
59.013077620, 48.195, 1445.0, 38.0132
59.067409820, 48.195, 1421.0, 37.6962
59.121742020, 48.195, 1438.0, 37.9210
59.176074220, 48.195, 1399.0, 37.4032
59.230406420, 48.195, 1365.0, 36.9459
59.284738620, 48.195, 1425.0, 37.7492
59.339070820, 48.195, 1464.0, 38.2623
59.393403020, 48.195, 1747.0, 41.7971
59.447735220, 48.195, 1958.0, 44.2493
59.502067420, 48.195, 2207.0, 46.9787
59.556399620, 48.195, 2169.0, 46.5725
59.610731820, 48.195, 2206.0, 46.9681
59.665064020, 48.195, 2258.0, 47.5184
59.719396220, 48.195, 2151.0, 46.3789
59.773728420, 48.195, 1919.0, 43.8064
59.828060620, 48.195, 1816.0, 42.6146
59.882392820, 48.195, 1711.0, 41.3642
59.936725020, 48.195, 1568.0, 39.5980
59.991057220, 48.195, 1473.0, 38.3797
60.045389420, 48.195, 1451.0, 38.0920
60.099721620, 48.195, 1478.0, 38.4448
60.154053820, 48.195, 1502.0, 38.7556
60.208386020, 48.195, 1369.0, 37.0000
60.262718220, 48.195, 1462.0, 38.2361
60.317050420, 48.195, 1495.0, 38.6652
60.371382620, 48.195, 1457.0, 38.1707
60.425714820, 48.195, 1474.0, 38.3927
60.480047020, 48.195, 1562.0, 39.5221
60.534379220, 48.195, 1657.0, 40.7063
60.588711420, 48.195, 1835.0, 42.8369
60.643043620, 48.195, 1796.0, 42.3792
60.697375820, 48.195, 2007.0, 44.7996
60.751708020, 48.195, 1904.0, 43.6348
60.806040220, 48.195, 1906.0, 43.6578
60.860372420, 48.195, 1843.0, 42.9302
60.914704620, 48.195, 1832.0, 42.8019
60.969036820, 48.195, 1777.0, 42.1545
61.023369020, 48.195, 1624.0, 40.2989
61.077701220, 48.195, 1584.0, 39.7995
61.132033420, 48.195, 1572.0, 39.6485
61.186365620, 48.195, 1588.0, 39.8497
61.240697820, 48.195, 1497.0, 38.6911
61.295030020, 48.195, 1430.0, 37.8153
61.349362220, 48.195, 1442.0, 37.9737
61.403694420, 48.195, 1450.0, 38.0789
61.458026620, 48.195, 1315.0, 36.2629
61.512358820, 48.195, 1319.0, 36.3180
61.566691020, 48.195, 1377.0, 37.1080
61.621023220, 48.195, 1224.0, 34.9857
61.675355420, 48.195, 1290.0, 35.9166
61.729687620, 48.195, 1261.0, 35.5106
61.784019820, 48.195, 1310.0, 36.1939
61.838352020, 48.195, 1161.0, 34.0735
61.892684220, 48.195, 1326.0, 36.4143
61.947016420, 48.195, 1257.0, 35.4542
62.001348620, 48.195, 1278.0, 35.7491
62.055680820, 48.195, 1231.0, 35.0856
62.110013020, 48.195, 1239.0, 35.1994
62.164345220, 48.195, 1249.0, 35.3412
62.218677420, 48.195, 1193.0, 34.5398
62.273009620, 48.195, 1248.0, 35.3270
62.327341820, 48.195, 1218.0, 34.8999
62.381674020, 48.195, 1245.0, 35.2846
62.436006220, 48.195, 1273.0, 35.6791
62.490338420, 48.195, 1306.0, 36.1386
62.544670620, 48.195, 1313.0, 36.2353
62.599002820, 48.195, 1362.0, 36.9053
62.653335020, 48.195, 1380.0, 37.1484
62.707667220, 48.195, 1395.0, 37.3497
62.761999420, 48.195, 1369.0, 37.0000
62.816331620, 48.195, 1416.0, 37.6298
62.870663820, 48.195, 1424.0, 37.7359
62.924996020, 48.195, 1475.0, 38.4057
62.979328220, 48.195, 1454.0, 38.1314
63.033660420, 48.195, 1394.0, 37.3363
63.087992620, 48.195, 1389.0, 37.2693
63.142324820, 48.195, 1323.0, 36.3731
63.196657020, 48.195, 1249.0, 35.3412
63.250989220, 48.195, 1276.0, 35.7211
63.305321420, 48.195, 1247.0, 35.3129
63.359653620, 48.195, 1329.0, 36.4555
63.413985820, 48.195, 1228.0, 35.0428
63.468318020, 48.195, 1272.0, 35.6651
63.522650220, 48.195, 1316.0, 36.2767
63.576982420, 48.195, 1277.0, 35.7351
63.631314620, 48.195, 1287.0, 35.8748
63.685646820, 48.195, 1284.0, 35.8329
63.739979020, 48.195, 1274.0, 35.6931
63.794311220, 48.195, 1227.0, 35.0286
63.848643420, 48.195, 1173.0, 34.2491
63.902975620, 48.195, 1164.0, 34.1174
63.957307820, 48.195, 1168.0, 34.1760
64.011640020, 48.195, 1167.0, 34.1614
64.065972220, 48.195, 1058.0, 32.5269
64.120304420, 48.195, 1141.0, 33.7787
64.174636620, 48.195, 1135.0, 33.6898
64.228968820, 48.195, 1135.0, 33.6898
64.283301020, 48.195, 1111.0, 33.3317
64.337633220, 48.195, 1143.0, 33.8083
64.391965420, 48.195, 1129.0, 33.6006
64.446297620, 48.195, 1166.0, 34.1467
64.500629820, 48.195, 1108.0, 33.2866
64.554962020, 48.195, 1137.0, 33.7194
64.609294220, 48.195, 1204.0, 34.6987
64.663626420, 48.195, 1129.0, 33.6006
64.717958620, 48.195, 1155.0, 33.9853
64.772290820, 48.195, 1086.0, 32.9545
64.826623020, 48.195, 1141.0, 33.7787
64.880955220, 48.195, 1174.0, 34.2637
64.935287420, 48.195, 1125.0, 33.5410
64.989619620, 48.195, 1168.0, 34.1760
65.043951820, 48.195, 1137.0, 33.7194
65.098284020, 48.195, 1169.0, 34.1906
65.152616220, 48.195, 1142.0, 33.7935
65.206948420, 48.195, 1234.0, 35.1283
65.261280620, 48.195, 1164.0, 34.1174
65.315612820, 48.195, 1076.0, 32.8024
65.369945020, 48.195, 1104.0, 33.2265
65.424277220, 48.195, 1142.0, 33.7935
65.478609420, 48.195, 1227.0, 35.0286
65.532941620, 48.195, 1301.0, 36.0694
65.587273820, 48.195, 1362.0, 36.9053
65.641606020, 48.195, 1302.0, 36.0832
65.695938220, 48.195, 1322.0, 36.3593
65.750270420, 48.195, 1300.0, 36.0555
65.804602620, 48.195, 1256.0, 35.4401
65.858934820, 48.195, 1255.0, 35.4260
65.913267020, 48.195, 1151.0, 33.9264
65.967599220, 48.195, 1244.0, 35.2704
66.021931420, 48.195, 1174.0, 34.2637
66.076263620, 48.195, 1177.0, 34.3074
66.130595820, 48.195, 1254.0, 35.4119
66.184928020, 48.195, 1188.0, 34.4674
66.239260220, 48.195, 1171.0, 34.2199
66.293592420, 48.195, 1145.0, 33.8378
66.347924620, 48.195, 1104.0, 33.2265
66.402256820, 48.195, 1087.0, 32.9697
66.456589020, 48.195, 1119.0, 33.4515
66.510921220, 48.195, 1090.0, 33.0151
66.565253420, 48.195, 1052.0, 32.4345
66.619585620, 48.195, 1068.0, 32.6803
66.673917820, 48.195, 1147.0, 33.8674
66.728250020, 48.195, 1134.0, 33.6749
66.782582220, 48.195, 1028.0, 32.0624
66.836914420, 48.195, 1159.0, 34.0441
66.891246620, 48.195, 1199.0, 34.6266
66.945578820, 48.195, 1158.0, 34.0294
66.999911020, 48.195, 1192.0, 34.5254
67.054243220, 48.195, 1118.0, 33.4365
67.108575420, 48.195, 1128.0, 33.5857
67.162907620, 48.195, 1096.0, 33.1059
67.217239820, 48.195, 1127.0, 33.5708
67.271572020, 48.195, 1106.0, 33.2566
67.325904220, 48.195, 1119.0, 33.4515
67.380236420, 48.195, 1147.0, 33.8674
67.434568620, 48.195, 1097.0, 33.1210
67.488900820, 48.195, 1226.0, 35.0143
67.543233020, 48.195, 1139.0, 33.7491
67.597565220, 48.195, 1112.0, 33.3467
67.651897420, 48.195, 1032.0, 32.1248
67.706229620, 48.195, 1105.0, 33.2415
67.760561820, 48.195, 1066.0, 32.6497
67.814894020, 48.195, 1022.0, 31.9687
67.869226220, 48.195, 1030.0, 32.0936
67.923558420, 48.195, 994.0, 31.5278
67.977890620, 48.195, 1100.0, 33.1662
68.032222820, 48.195, 1079.0, 32.8481
68.086555020, 48.195, 1129.0, 33.6006
68.140887220, 48.195, 1133.0, 33.6601
68.195219420, 48.195, 1126.0, 33.5559
68.249551620, 48.195, 1166.0, 34.1467
68.303883820, 48.195, 1123.0, 33.5112
68.358216020, 48.195, 1118.0, 33.4365
68.412548220, 48.195, 1098.0, 33.1361
68.466880420, 48.195, 1133.0, 33.6601
68.521212620, 48.195, 1018.0, 31.9061
68.575544820, 48.195, 1062.0, 32.5883
68.629877020, 48.195, 1060.0, 32.5576
68.684209220, 48.195, 1032.0, 32.1248
68.738541420, 48.195, 1008.0, 31.7490
68.792873620, 48.195, 1052.0, 32.4345
68.847205820, 48.195, 1065.0, 32.6343
68.901538020, 48.195, 1097.0, 33.1210
68.955870220, 48.195, 1039.0, 32.2335
69.010202420, 48.195, 1048.0, 32.3728
69.064534620, 48.195, 1082.0, 32.8938
69.118866820, 48.195, 1158.0, 34.0294
69.173199020, 48.195, 1144.0, 33.8231
69.227531220, 48.195, 1080.0, 32.8634
69.281863420, 48.195, 1066.0, 32.6497
69.336195620, 48.195, 1097.0, 33.1210
69.390527820, 48.195, 1018.0, 31.9061
69.444860020, 48.195, 1059.0, 32.5423
69.499192220, 48.195, 1014.0, 31.8434
69.553524420, 48.195, 1039.0, 32.2335
69.607856620, 48.195, 1020.0, 31.9374
69.662188820, 48.195, 1060.0, 32.5576
69.716521020, 48.195, 1074.0, 32.7719
69.770853220, 48.195, 1052.0, 32.4345
69.825185420, 48.195, 1027.0, 32.0468
69.879517620, 48.195, 1044.0, 32.3110
69.933849820, 48.195, 960.0, 30.9839
69.988182020, 48.195, 1024.0, 32.0000
70.042514220, 48.195, 985.0, 31.3847
70.096846420, 48.195, 975.0, 31.2250
70.151178620, 48.195, 972.0, 31.1769
70.205510820, 48.195, 1017.0, 31.8904
70.259843020, 48.195, 1008.0, 31.7490
70.314175220, 48.195, 940.0, 30.6594
70.368507420, 48.195, 988.0, 31.4325
70.422839620, 48.195, 1014.0, 31.8434
70.477171820, 48.195, 1071.0, 32.7261
70.531504020, 48.195, 1021.0, 31.9531
70.585836220, 48.195, 972.0, 31.1769
70.640168420, 48.195, 1006.0, 31.7175
70.694500620, 48.195, 1073.0, 32.7567
70.748832820, 48.195, 983.0, 31.3528
70.803165020, 48.195, 1003.0, 31.6702
70.857497220, 48.195, 977.0, 31.2570
70.911829420, 48.195, 1036.0, 32.1870
70.966161620, 48.195, 976.0, 31.2410
71.020493820, 48.195, 979.0, 31.2890
71.074826020, 48.195, 1079.0, 32.8481
71.129158220, 48.195, 1044.0, 32.3110
71.183490420, 48.195, 1074.0, 32.7719
71.237822620, 48.195, 1129.0, 33.6006
71.292154820, 48.195, 1145.0, 33.8378
71.346487020, 48.195, 1142.0, 33.7935
71.400819220, 48.195, 1170.0, 34.2053
71.455151420, 48.195, 1168.0, 34.1760
71.509483620, 48.195, 1231.0, 35.0856
71.563815820, 48.195, 1132.0, 33.6452
71.618148020, 48.195, 1138.0, 33.7343
71.672480220, 48.195, 1132.0, 33.6452
71.726812420, 48.195, 1069.0, 32.6956
71.781144620, 48.195, 1097.0, 33.1210
71.835476820, 48.195, 979.0, 31.2890
71.889809020, 48.195, 1010.0, 31.7805
71.944141220, 48.195, 1044.0, 32.3110
71.998473420, 48.195, 1006.0, 31.7175
72.052805620, 48.195, 974.0, 31.2090
72.107137820, 48.195, 978.0, 31.2730
72.161470020, 48.195, 1003.0, 31.6702
72.215802220, 48.195, 999.0, 31.6070
72.270134420, 48.195, 950.0, 30.8221
72.324466620, 48.195, 1034.0, 32.1559
72.378798820, 48.195, 915.0, 30.2490
72.433131020, 48.195, 922.0, 30.3645
72.487463220, 48.195, 978.0, 31.2730
72.541795420, 48.195, 929.0, 30.4795
72.596127620, 48.195, 934.0, 30.5614
72.650459820, 48.195, 990.0, 31.4643
72.704792020, 48.195, 913.0, 30.2159
72.759124220, 48.195, 945.0, 30.7409
72.813456420, 48.195, 938.0, 30.6268
72.867788620, 48.195, 977.0, 31.2570
72.922120820, 48.195, 978.0, 31.2730
72.976453020, 48.195, 937.0, 30.6105
73.030785220, 48.195, 971.0, 31.1609
73.085117420, 48.195, 1063.0, 32.6037
73.139449620, 48.195, 1057.0, 32.5115
73.193781820, 48.195, 1025.0, 32.0156
73.248114020, 48.195, 1023.0, 31.9844
73.302446220, 48.195, 1037.0, 32.2025
73.356778420, 48.195, 1046.0, 32.3419
73.411110620, 48.195, 987.0, 31.4166
73.465442820, 48.195, 962.0, 31.0161
73.519775020, 48.195, 1029.0, 32.0780
73.574107220, 48.195, 924.0, 30.3974
73.628439420, 48.195, 923.0, 30.3809
73.682771620, 48.195, 905.0, 30.0832
73.737103820, 48.195, 914.0, 30.2324
73.791436020, 48.195, 942.0, 30.6920
73.845768220, 48.195, 948.0, 30.7896
73.900100420, 48.195, 934.0, 30.5614
73.954432620, 48.195, 959.0, 30.9677
74.008764820, 48.195, 924.0, 30.3974
74.063097020, 48.195, 933.0, 30.5450
74.117429220, 48.195, 863.0, 29.3769
74.171761420, 48.195, 919.0, 30.3150
74.226093620, 48.195, 933.0, 30.5450
74.280425820, 48.195, 944.0, 30.7246
74.334758020, 48.195, 938.0, 30.6268
74.389090220, 48.195, 982.0, 31.3369
74.443422420, 48.195, 1021.0, 31.9531
74.497754620, 48.195, 978.0, 31.2730
74.552086820, 48.195, 967.0, 31.0966
74.606419020, 48.195, 1035.0, 32.1714
74.660751220, 48.195, 1008.0, 31.7490
74.715083420, 48.195, 1046.0, 32.3419
74.769415620, 48.195, 1053.0, 32.4500
74.823747820, 48.195, 1019.0, 31.9218
74.878080020, 48.195, 980.0, 31.3050
74.932412220, 48.195, 983.0, 31.3528
74.986744420, 48.195, 910.0, 30.1662
75.041076620, 48.195, 979.0, 31.2890
75.095408820, 48.195, 977.0, 31.2570
75.149741020, 48.195, 944.0, 30.7246
75.204073220, 48.195, 909.0, 30.1496
75.258405420, 48.195, 935.0, 30.5778
75.312737620, 48.195, 961.0, 31.0000
75.367069820, 48.195, 1029.0, 32.0780
75.421402020, 48.195, 917.0, 30.2820
75.475734220, 48.195, 984.0, 31.3688
75.530066420, 48.195, 882.0, 29.6985
75.584398620, 48.195, 947.0, 30.7734
75.638730820, 48.195, 917.0, 30.2820
75.693063020, 48.195, 971.0, 31.1609
75.747395220, 48.195, 996.0, 31.5595
75.801727420, 48.195, 966.0, 31.0805
75.856059620, 48.195, 1004.0, 31.6860
75.910391820, 48.195, 962.0, 31.0161
75.964724020, 48.195, 940.0, 30.6594
76.019056220, 48.195, 993.0, 31.5119
76.073388420, 48.195, 947.0, 30.7734
76.127720620, 48.195, 986.0, 31.4006
76.182052820, 48.195, 1038.0, 32.2180
76.236385020, 48.195, 982.0, 31.3369
76.290717220, 48.195, 979.0, 31.2890
76.345049420, 48.195, 967.0, 31.0966
76.399381620, 48.195, 965.0, 31.0644
76.453713820, 48.195, 922.0, 30.3645
76.508046020, 48.195, 996.0, 31.5595
76.562378220, 48.195, 958.0, 30.9516
76.616710420, 48.195, 1023.0, 31.9844
76.671042620, 48.195, 969.0, 31.1288
76.725374820, 48.195, 921.0, 30.3480
76.779707020, 48.195, 927.0, 30.4467
76.834039220, 48.195, 982.0, 31.3369
76.888371420, 48.195, 1008.0, 31.7490
76.942703620, 48.195, 990.0, 31.4643
76.997035820, 48.195, 1032.0, 32.1248
77.051368020, 48.195, 976.0, 31.2410
77.105700220, 48.195, 999.0, 31.6070
77.160032420, 48.195, 972.0, 31.1769
77.214364620, 48.195, 998.0, 31.5911
77.268696820, 48.195, 953.0, 30.8707
77.323029020, 48.195, 968.0, 31.1127
77.377361220, 48.195, 931.0, 30.5123
77.431693420, 48.195, 935.0, 30.5778
77.486025620, 48.195, 930.0, 30.4959
77.540357820, 48.195, 1004.0, 31.6860
77.594690020, 48.195, 940.0, 30.6594
77.649022220, 48.195, 936.0, 30.5941
77.703354420, 48.195, 941.0, 30.6757
77.757686620, 48.195, 979.0, 31.2890
77.812018820, 48.195, 921.0, 30.3480
77.866351020, 48.195, 942.0, 30.6920
77.920683220, 48.195, 1006.0, 31.7175
77.975015420, 48.195, 1003.0, 31.6702
78.029347620, 48.195, 1067.0, 32.6650
78.083679820, 48.195, 1181.0, 34.3657
78.138012020, 48.195, 1173.0, 34.2491
78.192344220, 48.195, 1098.0, 33.1361
78.246676420, 48.195, 1022.0, 31.9687
78.301008620, 48.195, 1061.0, 32.5730
78.355340820, 48.195, 1035.0, 32.1714
78.409673020, 48.195, 1116.0, 33.4066
78.464005220, 48.195, 1033.0, 32.1403
78.518337420, 48.195, 1028.0, 32.0624
78.572669620, 48.195, 1052.0, 32.4345
78.627001820, 48.195, 1219.0, 34.9142
78.681334020, 48.195, 1286.0, 35.8608
78.735666220, 48.195, 1216.0, 34.8712
78.789998420, 48.195, 1100.0, 33.1662
78.844330620, 48.195, 1184.0, 34.4093
78.898662820, 48.195, 1183.0, 34.3948
78.952995020, 48.195, 1093.0, 33.0606
79.007327220, 48.195, 1054.0, 32.4654
79.061659420, 48.195, 1047.0, 32.3574
79.115991620, 48.195, 991.0, 31.4802
79.170323820, 48.195, 997.0, 31.5753
79.224656020, 48.195, 935.0, 30.5778
79.278988220, 48.195, 941.0, 30.6757
79.333320420, 48.195, 1018.0, 31.9061
79.387652620, 48.195, 941.0, 30.6757
79.441984820, 48.195, 972.0, 31.1769
79.496317020, 48.195, 934.0, 30.5614
79.550649220, 48.195, 1017.0, 31.8904
79.604981420, 48.195, 929.0, 30.4795
79.659313620, 48.195, 976.0, 31.2410
79.713645820, 48.195, 964.0, 31.0483
79.767978020, 48.195, 1004.0, 31.6860
79.822310220, 48.195, 950.0, 30.8221
79.876642420, 48.195, 960.0, 30.9839
79.930974620, 48.195, 1002.0, 31.6544
79.985306820, 48.195, 959.0, 30.9677
79.996173260, 48.195, 1052.0, 32.4345