File: XRD/2025_06_03_CBN_3_60_8min.csv
[Measurement conditions]
Sample identification,2025_06_03_CBN_3_60_8min
Comment - 1,"Recrystallized CBN"
Anode material,Cu
K-Alpha1 wavelength,1.5405980
K-Alpha2 wavelength,1.5444260
Ratio K-Alpha2/K-Alpha1,0.500
Divergence slit,Fixed,0.76mm
Monochromator used,NO
Generator voltage, 40
Tube current, 15
File date and time,03/Jun/2025 16:11
Unit cell,
h k l, 0 0 0
Scan axis,Gonio
Scan range,2.995000000,60.000344240
Scan step size,0.0108664
No. of points, 5246
Scan type,CONTINUOUS
Time per step,18.870
[Scan points]
Angle, TimePerStep, Intensity, ESD
3.000433220, 18.870, 43532.0, 208.6432
3.043898980, 18.870, 41193.0, 202.9606
3.087364740, 18.870, 39576.0, 198.9372
3.130830500, 18.870, 37475.0, 193.5846
3.174296260, 18.870, 35420.0, 188.2020
3.217762020, 18.870, 33548.0, 183.1611
3.261227780, 18.870, 31759.0, 178.2105
3.304693540, 18.870, 30074.0, 173.4186
3.348159300, 18.870, 28396.0, 168.5111
3.391625060, 18.870, 26560.0, 162.9724
3.435090820, 18.870, 24994.0, 158.0949
3.478556580, 18.870, 23669.0, 153.8473
3.522022340, 18.870, 22265.0, 149.2146
3.565488100, 18.870, 20820.0, 144.2914
3.608953860, 18.870, 19817.0, 140.7729
3.652419620, 18.870, 18584.0, 136.3231
3.695885380, 18.870, 17454.0, 132.1136
3.739351140, 18.870, 16271.0, 127.5578
3.782816900, 18.870, 15015.0, 122.5357
3.826282660, 18.870, 14239.0, 119.3273
3.869748420, 18.870, 13175.0, 114.7824
3.913214180, 18.870, 12311.0, 110.9549
3.956679940, 18.870, 11641.0, 107.8935
4.000145700, 18.870, 10673.0, 103.3102
4.043611460, 18.870, 9985.0, 99.9250
4.087077220, 18.870, 9148.0, 95.6452
4.130542980, 18.870, 8496.0, 92.1737
4.174008740, 18.870, 7971.0, 89.2805
4.217474500, 18.870, 7402.0, 86.0349
4.260940260, 18.870, 6885.0, 82.9759
4.304406020, 18.870, 6319.0, 79.4921
4.347871780, 18.870, 5791.0, 76.0986
4.391337540, 18.870, 5586.0, 74.7395
4.434803300, 18.870, 4943.0, 70.3065
4.478269060, 18.870, 4643.0, 68.1396
4.521734820, 18.870, 4209.0, 64.8768
4.565200580, 18.870, 3931.0, 62.6977
4.608666340, 18.870, 3622.0, 60.1831
4.652132100, 18.870, 3343.0, 57.8187
4.695597860, 18.870, 3201.0, 56.5774
4.739063620, 18.870, 3012.0, 54.8817
4.782529380, 18.870, 2857.0, 53.4509
4.825995140, 18.870, 2839.0, 53.2823
4.869460900, 18.870, 2712.0, 52.0769
4.912926660, 18.870, 2702.0, 51.9808
4.956392420, 18.870, 2715.0, 52.1057
4.999858180, 18.870, 2638.0, 51.3615
5.043323940, 18.870, 2680.0, 51.7687
5.086789700, 18.870, 2627.0, 51.2543
5.130255460, 18.870, 2688.0, 51.8459
5.173721220, 18.870, 2918.0, 54.0185
5.217186980, 18.870, 3170.0, 56.3028
5.260652740, 18.870, 3288.0, 57.3411
5.304118500, 18.870, 3452.0, 58.7537
5.347584260, 18.870, 3903.0, 62.4740
5.391050020, 18.870, 4516.0, 67.2012
5.434515780, 18.870, 4926.0, 70.1855
5.477981540, 18.870, 5784.0, 76.0526
5.521447300, 18.870, 6896.0, 83.0422
5.564913060, 18.870, 8446.0, 91.9021
5.608378820, 18.870, 10772.0, 103.7882
5.651844580, 18.870, 14857.0, 121.8893
5.695310340, 18.870, 21561.0, 146.8366
5.738776100, 18.870, 33226.0, 182.2800
5.782241860, 18.870, 46342.0, 215.2719
5.825707620, 18.870, 57260.0, 239.2906
5.869173380, 18.870, 66350.0, 257.5849
5.912639140, 18.870, 80770.0, 284.2006
5.956104900, 18.870, 115872.0, 340.3998
5.999570660, 18.870, 140618.0, 374.9907
6.043036420, 18.870, 105026.0, 324.0772
6.086502180, 18.870, 53526.0, 231.3569
6.129967940, 18.870, 13392.0, 115.7238
6.173433700, 18.870, 8167.0, 90.3715
6.216899460, 18.870, 5295.0, 72.7668
6.260365220, 18.870, 4573.0, 67.6240
6.303830980, 18.870, 4215.0, 64.9230
6.347296740, 18.870, 3673.0, 60.6053
6.390762500, 18.870, 3232.0, 56.8507
6.434228260, 18.870, 2906.0, 53.9073
6.477694020, 18.870, 2618.0, 51.1664
6.521159780, 18.870, 2469.0, 49.6890
6.564625540, 18.870, 2272.0, 47.6655
6.608091300, 18.870, 2263.0, 47.5710
6.651557060, 18.870, 2154.0, 46.4112
6.695022820, 18.870, 2067.0, 45.4643
6.738488580, 18.870, 2060.0, 45.3872
6.781954340, 18.870, 1977.0, 44.4635
6.825420100, 18.870, 1894.0, 43.5201
6.868885860, 18.870, 1844.0, 42.9418
6.912351620, 18.870, 1813.0, 42.5793
6.955817380, 18.870, 1752.0, 41.8569
6.999283140, 18.870, 1689.0, 41.0974
7.042748900, 18.870, 1681.0, 41.0000
7.086214660, 18.870, 1505.0, 38.7943
7.129680420, 18.870, 1481.0, 38.4838
7.173146180, 18.870, 1418.0, 37.6563
7.216611940, 18.870, 1465.0, 38.2753
7.260077700, 18.870, 1320.0, 36.3318
7.303543460, 18.870, 1349.0, 36.7287
7.347009220, 18.870, 1334.0, 36.5240
7.390474980, 18.870, 1290.0, 35.9166
7.433940740, 18.870, 1301.0, 36.0694
7.477406500, 18.870, 1283.0, 35.8190
7.520872260, 18.870, 1214.0, 34.8425
7.564338020, 18.870, 1144.0, 33.8231
7.607803780, 18.870, 1259.0, 35.4824
7.651269540, 18.870, 1195.0, 34.5688
7.694735300, 18.870, 1124.0, 33.5261
7.738201060, 18.870, 1038.0, 32.2180
7.781666820, 18.870, 1058.0, 32.5269
7.825132580, 18.870, 1052.0, 32.4345
7.868598340, 18.870, 1054.0, 32.4654
7.912064100, 18.870, 976.0, 31.2410
7.955529860, 18.870, 1047.0, 32.3574
7.998995620, 18.870, 969.0, 31.1288
8.042461380, 18.870, 1105.0, 33.2415
8.085927140, 18.870, 1001.0, 31.6386
8.129392900, 18.870, 1041.0, 32.2645
8.172858660, 18.870, 1019.0, 31.9218
8.216324420, 18.870, 973.0, 31.1929
8.259790180, 18.870, 910.0, 30.1662
8.303255940, 18.870, 852.0, 29.1890
8.346721700, 18.870, 852.0, 29.1890
8.390187460, 18.870, 774.0, 27.8209
8.433653220, 18.870, 857.0, 29.2746
8.477118980, 18.870, 781.0, 27.9464
8.520584740, 18.870, 810.0, 28.4605
8.564050500, 18.870, 792.0, 28.1425
8.607516260, 18.870, 762.0, 27.6043
8.650982020, 18.870, 739.0, 27.1846
8.694447780, 18.870, 761.0, 27.5862
8.737913540, 18.870, 750.0, 27.3861
8.781379300, 18.870, 713.0, 26.7021
8.824845060, 18.870, 780.0, 27.9285
8.868310820, 18.870, 751.0, 27.4044
8.911776580, 18.870, 768.0, 27.7128
8.955242340, 18.870, 747.0, 27.3313
8.998708100, 18.870, 801.0, 28.3019
9.042173860, 18.870, 747.0, 27.3313
9.085639620, 18.870, 745.0, 27.2947
9.129105380, 18.870, 785.0, 28.0179
9.172571140, 18.870, 824.0, 28.7054
9.216036900, 18.870, 842.0, 29.0172
9.259502660, 18.870, 867.0, 29.4449
9.302968420, 18.870, 914.0, 30.2324
9.346434180, 18.870, 923.0, 30.3809
9.389899940, 18.870, 1005.0, 31.7017
9.433365700, 18.870, 1105.0, 33.2415
9.476831460, 18.870, 1238.0, 35.1852
9.520297220, 18.870, 1364.0, 36.9324
9.563762980, 18.870, 1456.0, 38.1576
9.607228740, 18.870, 1684.0, 41.0366
9.650694500, 18.870, 2009.0, 44.8219
9.694160260, 18.870, 2632.0, 51.3030
9.737626020, 18.870, 3383.0, 58.1636
9.781091780, 18.870, 4168.0, 64.5600
9.824557540, 18.870, 4699.0, 68.5493
9.868023300, 18.870, 4928.0, 70.1997
9.911489060, 18.870, 4608.0, 67.8823
9.954954820, 18.870, 4005.0, 63.2851
9.998420580, 18.870, 3119.0, 55.8480
10.041886340, 18.870, 2440.0, 49.3964
10.085352100, 18.870, 1945.0, 44.1022
10.128817860, 18.870, 1607.0, 40.0874
10.172283620, 18.870, 1415.0, 37.6165
10.215749380, 18.870, 1425.0, 37.7492
10.259215140, 18.870, 1372.0, 37.0405
10.302680900, 18.870, 1366.0, 36.9594
10.346146660, 18.870, 1221.0, 34.9428
10.389612420, 18.870, 1137.0, 33.7194
10.433078180, 18.870, 919.0, 30.3150
10.476543940, 18.870, 911.0, 30.1828
10.520009700, 18.870, 882.0, 29.6985
10.563475460, 18.870, 877.0, 29.6142
10.606941220, 18.870, 857.0, 29.2746
10.650406980, 18.870, 817.0, 28.5832
10.693872740, 18.870, 821.0, 28.6531
10.737338500, 18.870, 820.0, 28.6356
10.780804260, 18.870, 818.0, 28.6007
10.824270020, 18.870, 822.0, 28.6705
10.867735780, 18.870, 829.0, 28.7924
10.911201540, 18.870, 859.0, 29.3087
10.954667300, 18.870, 842.0, 29.0172
10.998133060, 18.870, 899.0, 29.9833
11.041598820, 18.870, 1017.0, 31.8904
11.085064580, 18.870, 1061.0, 32.5730
11.128530340, 18.870, 1220.0, 34.9285
11.171996100, 18.870, 1419.0, 37.6696
11.215461860, 18.870, 1789.0, 42.2966
11.258927620, 18.870, 2270.0, 47.6445
11.302393380, 18.870, 2622.0, 51.2055
11.345859140, 18.870, 2842.0, 53.3104
11.389324900, 18.870, 2806.0, 52.9717
11.432790660, 18.870, 2893.0, 53.7866
11.476256420, 18.870, 2939.0, 54.2125
11.519722180, 18.870, 3291.0, 57.3672
11.563187940, 18.870, 4623.0, 67.9926
11.606653700, 18.870, 7333.0, 85.6329
11.650119460, 18.870, 9720.0, 98.5901
11.693585220, 18.870, 10531.0, 102.6207
11.737050980, 18.870, 10827.0, 104.0529
11.780516740, 18.870, 10534.0, 102.6353
11.823982500, 18.870, 12175.0, 110.3404
11.867448260, 18.870, 17581.0, 132.5934
11.910914020, 18.870, 21059.0, 145.1172
11.954379780, 18.870, 14511.0, 120.4616
11.997845540, 18.870, 8369.0, 91.4822
12.041311300, 18.870, 2627.0, 51.2543
12.084777060, 18.870, 1580.0, 39.7492
12.128242820, 18.870, 1262.0, 35.5246
12.171708580, 18.870, 1244.0, 35.2704
12.215174340, 18.870, 1102.0, 33.1964
12.258640100, 18.870, 1109.0, 33.3017
12.302105860, 18.870, 1058.0, 32.5269
12.345571620, 18.870, 1024.0, 32.0000
12.389037380, 18.870, 1082.0, 32.8938
12.432503140, 18.870, 1147.0, 33.8674
12.475968900, 18.870, 1179.0, 34.3366
12.519434660, 18.870, 1339.0, 36.5923
12.562900420, 18.870, 1579.0, 39.7366
12.606366180, 18.870, 1799.0, 42.4146
12.649831940, 18.870, 2180.0, 46.6905
12.693297700, 18.870, 2451.0, 49.5076
12.736763460, 18.870, 2759.0, 52.5262
12.780229220, 18.870, 2882.0, 53.6843
12.823694980, 18.870, 2921.0, 54.0463
12.867160740, 18.870, 2720.0, 52.1536
12.910626500, 18.870, 2165.0, 46.5296
12.954092260, 18.870, 1617.0, 40.2119
12.997558020, 18.870, 1408.0, 37.5233
13.041023780, 18.870, 1377.0, 37.1080
13.084489540, 18.870, 1405.0, 37.4833
13.127955300, 18.870, 1497.0, 38.6911
13.171421060, 18.870, 1498.0, 38.7040
13.214886820, 18.870, 1664.0, 40.7922
13.258352580, 18.870, 1672.0, 40.8901
13.301818340, 18.870, 1608.0, 40.0999
13.345284100, 18.870, 1451.0, 38.0920
13.388749860, 18.870, 1326.0, 36.4143
13.432215620, 18.870, 1129.0, 33.6006
13.475681380, 18.870, 1069.0, 32.6956
13.519147140, 18.870, 909.0, 30.1496
13.562612900, 18.870, 871.0, 29.5127
13.606078660, 18.870, 972.0, 31.1769
13.649544420, 18.870, 1061.0, 32.5730
13.693010180, 18.870, 992.0, 31.4960
13.736475940, 18.870, 1043.0, 32.2955
13.779941700, 18.870, 1158.0, 34.0294
13.823407460, 18.870, 1357.0, 36.8375
13.866873220, 18.870, 1517.0, 38.9487
13.910338980, 18.870, 1957.0, 44.2380
13.953804740, 18.870, 2384.0, 48.8262
13.997270500, 18.870, 3043.0, 55.1634
14.040736260, 18.870, 3520.0, 59.3296
14.084202020, 18.870, 3784.0, 61.5142
14.127667780, 18.870, 3583.0, 59.8582
14.171133540, 18.870, 3105.0, 55.7225
14.214599300, 18.870, 2802.0, 52.9339
14.258065060, 18.870, 2413.0, 49.1223
14.301530820, 18.870, 1984.0, 44.5421
14.344996580, 18.870, 1904.0, 43.6348
14.388462340, 18.870, 2492.0, 49.9199
14.431928100, 18.870, 3517.0, 59.3043
14.475393860, 18.870, 4879.0, 69.8498
14.518859620, 18.870, 6257.0, 79.1012
14.562325380, 18.870, 7467.0, 86.4118
14.605791140, 18.870, 7761.0, 88.0965
14.649256900, 18.870, 7287.0, 85.3639
14.692722660, 18.870, 6406.0, 80.0375
14.736188420, 18.870, 5432.0, 73.7021
14.779654180, 18.870, 4083.0, 63.8984
14.823119940, 18.870, 2758.0, 52.5167
14.866585700, 18.870, 1834.0, 42.8252
14.910051460, 18.870, 1329.0, 36.4555
14.953517220, 18.870, 1274.0, 35.6931
14.996982980, 18.870, 1253.0, 35.3977
15.040448740, 18.870, 1137.0, 33.7194
15.083914500, 18.870, 1219.0, 34.9142
15.127380260, 18.870, 1264.0, 35.5528
15.170846020, 18.870, 1343.0, 36.6470
15.214311780, 18.870, 1542.0, 39.2683
15.257777540, 18.870, 1653.0, 40.6571
15.301243300, 18.870, 1867.0, 43.2088
15.344709060, 18.870, 1764.0, 42.0000
15.388174820, 18.870, 1645.0, 40.5586
15.431640580, 18.870, 1485.0, 38.5357
15.475106340, 18.870, 1285.0, 35.8469
15.518572100, 18.870, 1210.0, 34.7851
15.562037860, 18.870, 1107.0, 33.2716
15.605503620, 18.870, 1226.0, 35.0143
15.648969380, 18.870, 1289.0, 35.9026
15.692435140, 18.870, 1371.0, 37.0270
15.735900900, 18.870, 1464.0, 38.2623
15.779366660, 18.870, 1423.0, 37.7227
15.822832420, 18.870, 1338.0, 36.5787
15.866298180, 18.870, 1300.0, 36.0555
15.909763940, 18.870, 1177.0, 34.3074
15.953229700, 18.870, 1027.0, 32.0468
15.996695460, 18.870, 1045.0, 32.3265
16.040161220, 18.870, 1028.0, 32.0624
16.083626980, 18.870, 1081.0, 32.8786
16.127092740, 18.870, 1104.0, 33.2265
16.170558500, 18.870, 1096.0, 33.1059
16.214024260, 18.870, 1254.0, 35.4119
16.257490020, 18.870, 1374.0, 37.0675
16.300955780, 18.870, 1523.0, 39.0256
16.344421540, 18.870, 1773.0, 42.1070
16.387887300, 18.870, 2008.0, 44.8107
16.431353060, 18.870, 2028.0, 45.0333
16.474818820, 18.870, 1902.0, 43.6119
16.518284580, 18.870, 1561.0, 39.5095
16.561750340, 18.870, 1334.0, 36.5240
16.605216100, 18.870, 1220.0, 34.9285
16.648681860, 18.870, 1160.0, 34.0588
16.692147620, 18.870, 1199.0, 34.6266
16.735613380, 18.870, 1284.0, 35.8329
16.779079140, 18.870, 1427.0, 37.7757
16.822544900, 18.870, 1664.0, 40.7922
16.866010660, 18.870, 1812.0, 42.5676
16.909476420, 18.870, 1835.0, 42.8369
16.952942180, 18.870, 1738.0, 41.6893
16.996407940, 18.870, 1621.0, 40.2616
17.039873700, 18.870, 1507.0, 38.8201
17.083339460, 18.870, 1500.0, 38.7298
17.126805220, 18.870, 1379.0, 37.1349
17.170270980, 18.870, 1391.0, 37.2961
17.213736740, 18.870, 1412.0, 37.5766
17.257202500, 18.870, 1330.0, 36.4692
17.300668260, 18.870, 1290.0, 35.9166
17.344134020, 18.870, 1272.0, 35.6651
17.387599780, 18.870, 1271.0, 35.6511
17.431065540, 18.870, 1464.0, 38.2623
17.474531300, 18.870, 1813.0, 42.5793
17.517997060, 18.870, 2466.0, 49.6588
17.561462820, 18.870, 3685.0, 60.7042
17.604928580, 18.870, 4660.0, 68.2642
17.648394340, 18.870, 4867.0, 69.7639
17.691860100, 18.870, 4755.0, 68.9565
17.735325860, 18.870, 4486.0, 66.9776
17.778791620, 18.870, 5049.0, 71.0563
17.822257380, 18.870, 7376.0, 85.8836
17.865723140, 18.870, 8689.0, 93.2148
17.909188900, 18.870, 6215.0, 78.8353
17.952654660, 18.870, 3611.0, 60.0916
17.996120420, 18.870, 2081.0, 45.6180
18.039586180, 18.870, 1780.0, 42.1900
18.083051940, 18.870, 1939.0, 44.0341
18.126517700, 18.870, 2362.0, 48.6004
18.169983460, 18.870, 3122.0, 55.8749
18.213449220, 18.870, 4670.0, 68.3374
18.256914980, 18.870, 7049.0, 83.9583
18.300380740, 18.870, 8912.0, 94.4034
18.343846500, 18.870, 9880.0, 99.3982
18.387312260, 18.870, 10235.0, 101.1682
18.430778020, 18.870, 10227.0, 101.1286
18.474243780, 18.870, 9572.0, 97.8366
18.517709540, 18.870, 8602.0, 92.7470
18.561175300, 18.870, 7814.0, 88.3968
18.604641060, 18.870, 6694.0, 81.8169
18.648106820, 18.870, 7146.0, 84.5340
18.691572580, 18.870, 9115.0, 95.4725
18.735038340, 18.870, 11123.0, 105.4656
18.778504100, 18.870, 11756.0, 108.4251
18.821969860, 18.870, 11847.0, 108.8439
18.865435620, 18.870, 10857.0, 104.1969
18.908901380, 18.870, 8567.0, 92.5581
18.952367140, 18.870, 5548.0, 74.4849
18.995832900, 18.870, 3545.0, 59.5399
19.039298660, 18.870, 2517.0, 50.1697
19.082764420, 18.870, 1903.0, 43.6234
19.126230180, 18.870, 1817.0, 42.6263
19.169695940, 18.870, 1774.0, 42.1189
19.213161700, 18.870, 1770.0, 42.0714
19.256627460, 18.870, 1685.0, 41.0488
19.300093220, 18.870, 1580.0, 39.7492
19.343558980, 18.870, 1541.0, 39.2556
19.387024740, 18.870, 1554.0, 39.4208
19.430490500, 18.870, 1486.0, 38.5487
19.473956260, 18.870, 1441.0, 37.9605
19.517422020, 18.870, 1395.0, 37.3497
19.560887780, 18.870, 1506.0, 38.8072
19.604353540, 18.870, 1694.0, 41.1582
19.647819300, 18.870, 1924.0, 43.8634
19.691285060, 18.870, 2362.0, 48.6004
19.734750820, 18.870, 2498.0, 49.9800
19.778216580, 18.870, 2489.0, 49.8899
19.821682340, 18.870, 2232.0, 47.2440
19.865148100, 18.870, 2059.0, 45.3762
19.908613860, 18.870, 1908.0, 43.6807
19.952079620, 18.870, 1831.0, 42.7902
19.995545380, 18.870, 1930.0, 43.9318
20.039011140, 18.870, 2249.0, 47.4236
20.082476900, 18.870, 2431.0, 49.3052
20.125942660, 18.870, 2341.0, 48.3839
20.169408420, 18.870, 2341.0, 48.3839
20.212874180, 18.870, 2258.0, 47.5184
20.256339940, 18.870, 1933.0, 43.9659
20.299805700, 18.870, 1830.0, 42.7785
20.343271460, 18.870, 1787.0, 42.2729
20.386737220, 18.870, 2077.0, 45.5741
20.430202980, 18.870, 2354.0, 48.5180
20.473668740, 18.870, 2848.0, 53.3667
20.517134500, 18.870, 3408.0, 58.3781
20.560600260, 18.870, 4077.0, 63.8514
20.604066020, 18.870, 4035.0, 63.5216
20.647531780, 18.870, 3858.0, 62.1128
20.690997540, 18.870, 4028.0, 63.4665
20.734463300, 18.870, 3826.0, 61.8547
20.777929060, 18.870, 3697.0, 60.8030
20.821394820, 18.870, 3750.0, 61.2372
20.864860580, 18.870, 4594.0, 67.7791
20.908326340, 18.870, 6382.0, 79.8874
20.951792100, 18.870, 8004.0, 89.4651
20.995257860, 18.870, 9036.0, 95.0579
21.038723620, 18.870, 9368.0, 96.7884
21.082189380, 18.870, 8743.0, 93.5040
21.125655140, 18.870, 7735.0, 87.9488
21.169120900, 18.870, 5792.0, 76.1052
21.212586660, 18.870, 4089.0, 63.9453
21.256052420, 18.870, 2777.0, 52.6972
21.299518180, 18.870, 2151.0, 46.3789
21.342983940, 18.870, 1757.0, 41.9166
21.386449700, 18.870, 1688.0, 41.0853
21.429915460, 18.870, 1686.0, 41.0609
21.473381220, 18.870, 1963.0, 44.3058
21.516846980, 18.870, 2171.0, 46.5940
21.560312740, 18.870, 2199.0, 46.8935
21.603778500, 18.870, 2113.0, 45.9674
21.647244260, 18.870, 1931.0, 43.9431
21.690710020, 18.870, 1775.0, 42.1307
21.734175780, 18.870, 1518.0, 38.9615
21.777641540, 18.870, 1406.0, 37.4967
21.821107300, 18.870, 1321.0, 36.3456
21.864573060, 18.870, 1234.0, 35.1283
21.908038820, 18.870, 1263.0, 35.5387
21.951504580, 18.870, 1267.0, 35.5949
21.994970340, 18.870, 1286.0, 35.8608
22.038436100, 18.870, 1351.0, 36.7560
22.081901860, 18.870, 1331.0, 36.4829
22.125367620, 18.870, 1461.0, 38.2230
22.168833380, 18.870, 1402.0, 37.4433
22.212299140, 18.870, 1329.0, 36.4555
22.255764900, 18.870, 1298.0, 36.0278
22.299230660, 18.870, 1271.0, 35.6511
22.342696420, 18.870, 1248.0, 35.3270
22.386162180, 18.870, 1213.0, 34.8281
22.429627940, 18.870, 1303.0, 36.0971
22.473093700, 18.870, 1529.0, 39.1024
22.516559460, 18.870, 1706.0, 41.3038
22.560025220, 18.870, 1921.0, 43.8292
22.603490980, 18.870, 2158.0, 46.4543
22.646956740, 18.870, 2311.0, 48.0729
22.690422500, 18.870, 2151.0, 46.3789
22.733888260, 18.870, 2062.0, 45.4093
22.777354020, 18.870, 1941.0, 44.0568
22.820819780, 18.870, 1843.0, 42.9302
22.864285540, 18.870, 1817.0, 42.6263
22.907751300, 18.870, 1927.0, 43.8976
22.951217060, 18.870, 2138.0, 46.2385
22.994682820, 18.870, 2360.0, 48.5798
23.038148580, 18.870, 2414.0, 49.1325
23.081614340, 18.870, 2551.0, 50.5074
23.125080100, 18.870, 2534.0, 50.3389
23.168545860, 18.870, 2710.0, 52.0577
23.212011620, 18.870, 2913.0, 53.9722
23.255477380, 18.870, 3269.0, 57.1752
23.298943140, 18.870, 3738.0, 61.1392
23.342408900, 18.870, 4259.0, 65.2610
23.385874660, 18.870, 4733.0, 68.7968
23.429340420, 18.870, 5284.0, 72.6911
23.472806180, 18.870, 6429.0, 80.1810
23.516271940, 18.870, 9464.0, 97.2831
23.559737700, 18.870, 14399.0, 119.9958
23.603203460, 18.870, 18661.0, 136.6053
23.646669220, 18.870, 20906.0, 144.5891
23.690134980, 18.870, 19105.0, 138.2208
23.733600740, 18.870, 17049.0, 130.5718
23.777066500, 18.870, 21001.0, 144.9172
23.820532260, 18.870, 31675.0, 177.9747
23.863998020, 18.870, 32417.0, 180.0472
23.907463780, 18.870, 22657.0, 150.5224
23.950929540, 18.870, 10816.0, 104.0000
23.994395300, 18.870, 5341.0, 73.0821
24.037861060, 18.870, 2917.0, 54.0093
24.081326820, 18.870, 2479.0, 49.7896
24.124792580, 18.870, 2282.0, 47.7703
24.168258340, 18.870, 2077.0, 45.5741
24.211724100, 18.870, 2113.0, 45.9674
24.255189860, 18.870, 1929.0, 43.9204
24.298655620, 18.870, 1884.0, 43.4051
24.342121380, 18.870, 1734.0, 41.6413
24.385587140, 18.870, 1567.0, 39.5854
24.429052900, 18.870, 1402.0, 37.4433
24.472518660, 18.870, 1325.0, 36.4005
24.515984420, 18.870, 1373.0, 37.0540
24.559450180, 18.870, 1419.0, 37.6696
24.602915940, 18.870, 1523.0, 39.0256
24.646381700, 18.870, 1678.0, 40.9634
24.689847460, 18.870, 1862.0, 43.1509
24.733313220, 18.870, 1839.0, 42.8836
24.776778980, 18.870, 1776.0, 42.1426
24.820244740, 18.870, 1654.0, 40.6694
24.863710500, 18.870, 1775.0, 42.1307
24.907176260, 18.870, 1695.0, 41.1704
24.950642020, 18.870, 1520.0, 38.9872
24.994107780, 18.870, 1288.0, 35.8887
25.037573540, 18.870, 1084.0, 32.9242
25.081039300, 18.870, 1121.0, 33.4813
25.124505060, 18.870, 1044.0, 32.3110
25.167970820, 18.870, 1042.0, 32.2800
25.211436580, 18.870, 1112.0, 33.3467
25.254902340, 18.870, 1028.0, 32.0624
25.298368100, 18.870, 1091.0, 33.0303
25.341833860, 18.870, 1180.0, 34.3511
25.385299620, 18.870, 1318.0, 36.3043
25.428765380, 18.870, 1445.0, 38.0132
25.472231140, 18.870, 1760.0, 41.9524
25.515696900, 18.870, 1796.0, 42.3792
25.559162660, 18.870, 1879.0, 43.3474
25.602628420, 18.870, 1871.0, 43.2551
25.646094180, 18.870, 1798.0, 42.4028
25.689559940, 18.870, 1652.0, 40.6448
25.733025700, 18.870, 1419.0, 37.6696
25.776491460, 18.870, 1367.0, 36.9730
25.819957220, 18.870, 1252.0, 35.3836
25.863422980, 18.870, 1072.0, 32.7414
25.906888740, 18.870, 1044.0, 32.3110
25.950354500, 18.870, 957.0, 30.9354
25.993820260, 18.870, 901.0, 30.0167
26.037286020, 18.870, 913.0, 30.2159
26.080751780, 18.870, 964.0, 31.0483
26.124217540, 18.870, 926.0, 30.4302
26.167683300, 18.870, 928.0, 30.4631
26.211149060, 18.870, 973.0, 31.1929
26.254614820, 18.870, 914.0, 30.2324
26.298080580, 18.870, 933.0, 30.5450
26.341546340, 18.870, 1001.0, 31.6386
26.385012100, 18.870, 929.0, 30.4795
26.428477860, 18.870, 1032.0, 32.1248
26.471943620, 18.870, 1074.0, 32.7719
26.515409380, 18.870, 1070.0, 32.7109
26.558875140, 18.870, 1055.0, 32.4808
26.602340900, 18.870, 1051.0, 32.4191
26.645806660, 18.870, 1014.0, 31.8434
26.689272420, 18.870, 1021.0, 31.9531
26.732738180, 18.870, 1127.0, 33.5708
26.776203940, 18.870, 1185.0, 34.4238
26.819669700, 18.870, 1100.0, 33.1662
26.863135460, 18.870, 1199.0, 34.6266
26.906601220, 18.870, 1129.0, 33.6006
26.950066980, 18.870, 1127.0, 33.5708
26.993532740, 18.870, 1176.0, 34.2929
27.036998500, 18.870, 1090.0, 33.0151
27.080464260, 18.870, 1151.0, 33.9264
27.123930020, 18.870, 976.0, 31.2410
27.167395780, 18.870, 1033.0, 32.1403
27.210861540, 18.870, 1100.0, 33.1662
27.254327300, 18.870, 992.0, 31.4960
27.297793060, 18.870, 970.0, 31.1448
27.341258820, 18.870, 918.0, 30.2985
27.384724580, 18.870, 859.0, 29.3087
27.428190340, 18.870, 849.0, 29.1376
27.471656100, 18.870, 836.0, 28.9137
27.515121860, 18.870, 856.0, 29.2575
27.558587620, 18.870, 887.0, 29.7825
27.602053380, 18.870, 933.0, 30.5450
27.645519140, 18.870, 1083.0, 32.9090
27.688984900, 18.870, 1299.0, 36.0416
27.732450660, 18.870, 1574.0, 39.6737
27.775916420, 18.870, 1774.0, 42.1189
27.819382180, 18.870, 1996.0, 44.6766
27.862847940, 18.870, 2054.0, 45.3211
27.906313700, 18.870, 1839.0, 42.8836
27.949779460, 18.870, 1671.0, 40.8779
27.993245220, 18.870, 1377.0, 37.1080
28.036710980, 18.870, 1162.0, 34.0881
28.080176740, 18.870, 1213.0, 34.8281
28.123642500, 18.870, 1084.0, 32.9242
28.167108260, 18.870, 1096.0, 33.1059
28.210574020, 18.870, 1047.0, 32.3574
28.254039780, 18.870, 1076.0, 32.8024
28.297505540, 18.870, 1016.0, 31.8748
28.340971300, 18.870, 1066.0, 32.6497
28.384437060, 18.870, 978.0, 31.2730
28.427902820, 18.870, 950.0, 30.8221
28.471368580, 18.870, 940.0, 30.6594
28.514834340, 18.870, 897.0, 29.9500
28.558300100, 18.870, 864.0, 29.3939
28.601765860, 18.870, 854.0, 29.2233
28.645231620, 18.870, 793.0, 28.1603
28.688697380, 18.870, 821.0, 28.6531
28.732163140, 18.870, 825.0, 28.7228
28.775628900, 18.870, 820.0, 28.6356
28.819094660, 18.870, 830.0, 28.8097
28.862560420, 18.870, 910.0, 30.1662
28.906026180, 18.870, 1011.0, 31.7962
28.949491940, 18.870, 1239.0, 35.1994
28.992957700, 18.870, 1373.0, 37.0540
29.036423460, 18.870, 1409.0, 37.5366
29.079889220, 18.870, 1468.0, 38.3145
29.123354980, 18.870, 1383.0, 37.1887
29.166820740, 18.870, 1175.0, 34.2783
29.210286500, 18.870, 1091.0, 33.0303
29.253752260, 18.870, 942.0, 30.6920
29.297218020, 18.870, 900.0, 30.0000
29.340683780, 18.870, 846.0, 29.0861
29.384149540, 18.870, 900.0, 30.0000
29.427615300, 18.870, 976.0, 31.2410
29.471081060, 18.870, 1028.0, 32.0624
29.514546820, 18.870, 1139.0, 33.7491
29.558012580, 18.870, 1383.0, 37.1887
29.601478340, 18.870, 2092.0, 45.7384
29.644944100, 18.870, 2665.0, 51.6236
29.688409860, 18.870, 3146.0, 56.0892
29.731875620, 18.870, 3140.0, 56.0357
29.775341380, 18.870, 2624.0, 51.2250
29.818807140, 18.870, 2964.0, 54.4426
29.862272900, 18.870, 4093.0, 63.9766
29.905738660, 18.870, 4898.0, 69.9857
29.949204420, 18.870, 3961.0, 62.9365
29.992670180, 18.870, 3161.0, 56.2228
30.036135940, 18.870, 1650.0, 40.6202
30.079601700, 18.870, 1204.0, 34.6987
30.123067460, 18.870, 1008.0, 31.7490
30.166533220, 18.870, 937.0, 30.6105
30.209998980, 18.870, 949.0, 30.8058
30.253464740, 18.870, 913.0, 30.2159
30.296930500, 18.870, 868.0, 29.4618
30.340396260, 18.870, 876.0, 29.5973
30.383862020, 18.870, 894.0, 29.8998
30.427327780, 18.870, 870.0, 29.4958
30.470793540, 18.870, 811.0, 28.4781
30.514259300, 18.870, 882.0, 29.6985
30.557725060, 18.870, 811.0, 28.4781
30.601190820, 18.870, 868.0, 29.4618
30.644656580, 18.870, 892.0, 29.8664
30.688122340, 18.870, 871.0, 29.5127
30.731588100, 18.870, 830.0, 28.8097
30.775053860, 18.870, 927.0, 30.4467
30.818519620, 18.870, 949.0, 30.8058
30.861985380, 18.870, 936.0, 30.5941
30.905451140, 18.870, 904.0, 30.0666
30.948916900, 18.870, 924.0, 30.3974
30.992382660, 18.870, 927.0, 30.4467
31.035848420, 18.870, 895.0, 29.9166
31.079314180, 18.870, 963.0, 31.0322
31.122779940, 18.870, 991.0, 31.4802
31.166245700, 18.870, 1068.0, 32.6803
31.209711460, 18.870, 1164.0, 34.1174
31.253177220, 18.870, 1128.0, 33.5857
31.296642980, 18.870, 1132.0, 33.6452
31.340108740, 18.870, 1108.0, 33.2866
31.383574500, 18.870, 1073.0, 32.7567
31.427040260, 18.870, 1006.0, 31.7175
31.470506020, 18.870, 980.0, 31.3050
31.513971780, 18.870, 837.0, 28.9310
31.557437540, 18.870, 834.0, 28.8791
31.600903300, 18.870, 789.0, 28.0891
31.644369060, 18.870, 841.0, 29.0000
31.687834820, 18.870, 873.0, 29.5466
31.731300580, 18.870, 875.0, 29.5804
31.774766340, 18.870, 963.0, 31.0322
31.818232100, 18.870, 952.0, 30.8545
31.861697860, 18.870, 909.0, 30.1496
31.905163620, 18.870, 892.0, 29.8664
31.948629380, 18.870, 803.0, 28.3373
31.992095140, 18.870, 784.0, 28.0000
32.035560900, 18.870, 755.0, 27.4773
32.079026660, 18.870, 738.0, 27.1662
32.122492420, 18.870, 719.0, 26.8142
32.165958180, 18.870, 724.0, 26.9072
32.209423940, 18.870, 776.0, 27.8568
32.252889700, 18.870, 717.0, 26.7769
32.296355460, 18.870, 755.0, 27.4773
32.339821220, 18.870, 753.0, 27.4408
32.383286980, 18.870, 673.0, 25.9422
32.426752740, 18.870, 779.0, 27.9106
32.470218500, 18.870, 736.0, 27.1293
32.513684260, 18.870, 686.0, 26.1916
32.557150020, 18.870, 662.0, 25.7294
32.600615780, 18.870, 645.0, 25.3969
32.644081540, 18.870, 707.0, 26.5895
32.687547300, 18.870, 705.0, 26.5518
32.731013060, 18.870, 684.0, 26.1534
32.774478820, 18.870, 654.0, 25.5734
32.817944580, 18.870, 698.0, 26.4197
32.861410340, 18.870, 618.0, 24.8596
32.904876100, 18.870, 627.0, 25.0400
32.948341860, 18.870, 642.0, 25.3377
32.991807620, 18.870, 597.0, 24.4336
33.035273380, 18.870, 606.0, 24.6171
33.078739140, 18.870, 631.0, 25.1197
33.122204900, 18.870, 686.0, 26.1916
33.165670660, 18.870, 783.0, 27.9821
33.209136420, 18.870, 759.0, 27.5500
33.252602180, 18.870, 784.0, 28.0000
33.296067940, 18.870, 838.0, 28.9482
33.339533700, 18.870, 885.0, 29.7489
33.382999460, 18.870, 843.0, 29.0345
33.426465220, 18.870, 877.0, 29.6142
33.469930980, 18.870, 867.0, 29.4449
33.513396740, 18.870, 725.0, 26.9258
33.556862500, 18.870, 667.0, 25.8263
33.600328260, 18.870, 654.0, 25.5734
33.643794020, 18.870, 650.0, 25.4951
33.687259780, 18.870, 646.0, 25.4165
33.730725540, 18.870, 656.0, 25.6125
33.774191300, 18.870, 634.0, 25.1794
33.817657060, 18.870, 687.0, 26.2107
33.861122820, 18.870, 678.0, 26.0384
33.904588580, 18.870, 650.0, 25.4951
33.948054340, 18.870, 659.0, 25.6710
33.991520100, 18.870, 579.0, 24.0624
34.034985860, 18.870, 573.0, 23.9374
34.078451620, 18.870, 559.0, 23.6432
34.121917380, 18.870, 566.0, 23.7908
34.165383140, 18.870, 596.0, 24.4131
34.208848900, 18.870, 574.0, 23.9583
34.252314660, 18.870, 603.0, 24.5561
34.295780420, 18.870, 581.0, 24.1039
34.339246180, 18.870, 582.0, 24.1247
34.382711940, 18.870, 629.0, 25.0799
34.426177700, 18.870, 662.0, 25.7294
34.469643460, 18.870, 651.0, 25.5147
34.513109220, 18.870, 700.0, 26.4575
34.556574980, 18.870, 728.0, 26.9815
34.600040740, 18.870, 736.0, 27.1293
34.643506500, 18.870, 835.0, 28.8964
34.686972260, 18.870, 834.0, 28.8791
34.730438020, 18.870, 917.0, 30.2820
34.773903780, 18.870, 932.0, 30.5287
34.817369540, 18.870, 898.0, 29.9666
34.860835300, 18.870, 775.0, 27.8388
34.904301060, 18.870, 678.0, 26.0384
34.947766820, 18.870, 749.0, 27.3679
34.991232580, 18.870, 700.0, 26.4575
35.034698340, 18.870, 639.0, 25.2784
35.078164100, 18.870, 717.0, 26.7769
35.121629860, 18.870, 724.0, 26.9072
35.165095620, 18.870, 665.0, 25.7876
35.208561380, 18.870, 687.0, 26.2107
35.252027140, 18.870, 632.0, 25.1396
35.295492900, 18.870, 716.0, 26.7582
35.338958660, 18.870, 669.0, 25.8650
35.382424420, 18.870, 703.0, 26.5141
35.425890180, 18.870, 762.0, 27.6043
35.469355940, 18.870, 668.0, 25.8457
35.512821700, 18.870, 748.0, 27.3496
35.556287460, 18.870, 661.0, 25.7099
35.599753220, 18.870, 734.0, 27.0924
35.643218980, 18.870, 828.0, 28.7750
35.686684740, 18.870, 896.0, 29.9333
35.730150500, 18.870, 1168.0, 34.1760
35.773616260, 18.870, 1669.0, 40.8534
35.817082020, 18.870, 2037.0, 45.1331
35.860547780, 18.870, 2217.0, 47.0850
35.904013540, 18.870, 2009.0, 44.8219
35.947479300, 18.870, 1894.0, 43.5201
35.990945060, 18.870, 2443.0, 49.4267
36.034410820, 18.870, 3103.0, 55.7046
36.077876580, 18.870, 2767.0, 52.6023
36.121342340, 18.870, 2466.0, 49.6588
36.164808100, 18.870, 1794.0, 42.3556
36.208273860, 18.870, 1211.0, 34.7994
36.251739620, 18.870, 999.0, 31.6070
36.295205380, 18.870, 800.0, 28.2843
36.338671140, 18.870, 888.0, 29.7993
36.382136900, 18.870, 807.0, 28.4077
36.425602660, 18.870, 884.0, 29.7321
36.469068420, 18.870, 895.0, 29.9166
36.512534180, 18.870, 876.0, 29.5973
36.555999940, 18.870, 839.0, 28.9655
36.599465700, 18.870, 794.0, 28.1780
36.642931460, 18.870, 812.0, 28.4956
36.686397220, 18.870, 792.0, 28.1425
36.729862980, 18.870, 779.0, 27.9106
36.773328740, 18.870, 746.0, 27.3130
36.816794500, 18.870, 745.0, 27.2947
36.860260260, 18.870, 635.0, 25.1992
36.903726020, 18.870, 701.0, 26.4764
36.947191780, 18.870, 648.0, 25.4558
36.990657540, 18.870, 667.0, 25.8263
37.034123300, 18.870, 720.0, 26.8328
37.077589060, 18.870, 730.0, 27.0185
37.121054820, 18.870, 775.0, 27.8388
37.164520580, 18.870, 861.0, 29.3428
37.207986340, 18.870, 847.0, 29.1033
37.251452100, 18.870, 843.0, 29.0345
37.294917860, 18.870, 852.0, 29.1890
37.338383620, 18.870, 877.0, 29.6142
37.381849380, 18.870, 866.0, 29.4279
37.425315140, 18.870, 837.0, 28.9310
37.468780900, 18.870, 847.0, 29.1033
37.512246660, 18.870, 787.0, 28.0535
37.555712420, 18.870, 757.0, 27.5136
37.599178180, 18.870, 701.0, 26.4764
37.642643940, 18.870, 754.0, 27.4591
37.686109700, 18.870, 720.0, 26.8328
37.729575460, 18.870, 676.0, 26.0000
37.773041220, 18.870, 619.0, 24.8797
37.816506980, 18.870, 651.0, 25.5147
37.859972740, 18.870, 677.0, 26.0192
37.903438500, 18.870, 692.0, 26.3059
37.946904260, 18.870, 655.0, 25.5930
37.990370020, 18.870, 712.0, 26.6833
38.033835780, 18.870, 701.0, 26.4764
38.077301540, 18.870, 704.0, 26.5330
38.120767300, 18.870, 734.0, 27.0924
38.164233060, 18.870, 708.0, 26.6083
38.207698820, 18.870, 687.0, 26.2107
38.251164580, 18.870, 738.0, 27.1662
38.294630340, 18.870, 759.0, 27.5500
38.338096100, 18.870, 672.0, 25.9230
38.381561860, 18.870, 667.0, 25.8263
38.425027620, 18.870, 685.0, 26.1725
38.468493380, 18.870, 717.0, 26.7769
38.511959140, 18.870, 707.0, 26.5895
38.555424900, 18.870, 740.0, 27.2029
38.598890660, 18.870, 636.0, 25.2190
38.642356420, 18.870, 681.0, 26.0960
38.685822180, 18.870, 700.0, 26.4575
38.729287940, 18.870, 728.0, 26.9815
38.772753700, 18.870, 693.0, 26.3249
38.816219460, 18.870, 794.0, 28.1780
38.859685220, 18.870, 881.0, 29.6816
38.903150980, 18.870, 1050.0, 32.4037
38.946616740, 18.870, 1192.0, 34.5254
38.990082500, 18.870, 1288.0, 35.8887
39.033548260, 18.870, 1388.0, 37.2559
39.077014020, 18.870, 1465.0, 38.2753
39.120479780, 18.870, 1255.0, 35.4260
39.163945540, 18.870, 1227.0, 35.0286
39.207411300, 18.870, 1058.0, 32.5269
39.250877060, 18.870, 926.0, 30.4302
39.294342820, 18.870, 861.0, 29.3428
39.337808580, 18.870, 776.0, 27.8568
39.381274340, 18.870, 640.0, 25.2982
39.424740100, 18.870, 706.0, 26.5707
39.468205860, 18.870, 628.0, 25.0599
39.511671620, 18.870, 668.0, 25.8457
39.555137380, 18.870, 657.0, 25.6320
39.598603140, 18.870, 665.0, 25.7876
39.642068900, 18.870, 705.0, 26.5518
39.685534660, 18.870, 667.0, 25.8263
39.729000420, 18.870, 762.0, 27.6043
39.772466180, 18.870, 706.0, 26.5707
39.815931940, 18.870, 740.0, 27.2029
39.859397700, 18.870, 785.0, 28.0179
39.902863460, 18.870, 747.0, 27.3313
39.946329220, 18.870, 807.0, 28.4077
39.989794980, 18.870, 722.0, 26.8701
40.033260740, 18.870, 679.0, 26.0576
40.076726500, 18.870, 728.0, 26.9815
40.120192260, 18.870, 696.0, 26.3818
40.163658020, 18.870, 648.0, 25.4558
40.207123780, 18.870, 696.0, 26.3818
40.250589540, 18.870, 626.0, 25.0200
40.294055300, 18.870, 582.0, 24.1247
40.337521060, 18.870, 653.0, 25.5539
40.380986820, 18.870, 694.0, 26.3439
40.424452580, 18.870, 672.0, 25.9230
40.467918340, 18.870, 684.0, 26.1534
40.511384100, 18.870, 707.0, 26.5895
40.554849860, 18.870, 715.0, 26.7395
40.598315620, 18.870, 793.0, 28.1603
40.641781380, 18.870, 770.0, 27.7489
40.685247140, 18.870, 916.0, 30.2655
40.728712900, 18.870, 838.0, 28.9482
40.772178660, 18.870, 777.0, 27.8747
40.815644420, 18.870, 781.0, 27.9464
40.859110180, 18.870, 734.0, 27.0924
40.902575940, 18.870, 719.0, 26.8142
40.946041700, 18.870, 625.0, 25.0000
40.989507460, 18.870, 662.0, 25.7294
41.032973220, 18.870, 682.0, 26.1151
41.076438980, 18.870, 689.0, 26.2488
41.119904740, 18.870, 657.0, 25.6320
41.163370500, 18.870, 654.0, 25.5734
41.206836260, 18.870, 694.0, 26.3439
41.250302020, 18.870, 641.0, 25.3180
41.293767780, 18.870, 656.0, 25.6125
41.337233540, 18.870, 682.0, 26.1151
41.380699300, 18.870, 638.0, 25.2587
41.424165060, 18.870, 749.0, 27.3679
41.467630820, 18.870, 741.0, 27.2213
41.511096580, 18.870, 700.0, 26.4575
41.554562340, 18.870, 786.0, 28.0357
41.598028100, 18.870, 792.0, 28.1425
41.641493860, 18.870, 811.0, 28.4781
41.684959620, 18.870, 841.0, 29.0000
41.728425380, 18.870, 764.0, 27.6405
41.771891140, 18.870, 732.0, 27.0555
41.815356900, 18.870, 794.0, 28.1780
41.858822660, 18.870, 769.0, 27.7308
41.902288420, 18.870, 773.0, 27.8029
41.945754180, 18.870, 766.0, 27.6767
41.989219940, 18.870, 743.0, 27.2580
42.032685700, 18.870, 739.0, 27.1846
42.076151460, 18.870, 763.0, 27.6225
42.119617220, 18.870, 734.0, 27.0924
42.163082980, 18.870, 631.0, 25.1197
42.206548740, 18.870, 720.0, 26.8328
42.250014500, 18.870, 694.0, 26.3439
42.293480260, 18.870, 662.0, 25.7294
42.336946020, 18.870, 705.0, 26.5518
42.380411780, 18.870, 705.0, 26.5518
42.423877540, 18.870, 706.0, 26.5707
42.467343300, 18.870, 752.0, 27.4226
42.510809060, 18.870, 826.0, 28.7402
42.554274820, 18.870, 1024.0, 32.0000
42.597740580, 18.870, 1054.0, 32.4654
42.641206340, 18.870, 1091.0, 33.0303
42.684672100, 18.870, 1074.0, 32.7719
42.728137860, 18.870, 1114.0, 33.3766
42.771603620, 18.870, 1091.0, 33.0303
42.815069380, 18.870, 1108.0, 33.2866
42.858535140, 18.870, 1012.0, 31.8119
42.902000900, 18.870, 899.0, 29.9833
42.945466660, 18.870, 839.0, 28.9655
42.988932420, 18.870, 820.0, 28.6356
43.032398180, 18.870, 801.0, 28.3019
43.075863940, 18.870, 775.0, 27.8388
43.119329700, 18.870, 789.0, 28.0891
43.162795460, 18.870, 831.0, 28.8271
43.206261220, 18.870, 815.0, 28.5482
43.249726980, 18.870, 808.0, 28.4253
43.293192740, 18.870, 918.0, 30.2985
43.336658500, 18.870, 989.0, 31.4484
43.380124260, 18.870, 1031.0, 32.1092
43.423590020, 18.870, 1077.0, 32.8177
43.467055780, 18.870, 1099.0, 33.1512
43.510521540, 18.870, 1077.0, 32.8177
43.553987300, 18.870, 1085.0, 32.9393
43.597453060, 18.870, 1098.0, 33.1361
43.640918820, 18.870, 1033.0, 32.1403
43.684384580, 18.870, 913.0, 30.2159
43.727850340, 18.870, 971.0, 31.1609
43.771316100, 18.870, 884.0, 29.7321
43.814781860, 18.870, 852.0, 29.1890
43.858247620, 18.870, 836.0, 28.9137
43.901713380, 18.870, 807.0, 28.4077
43.945179140, 18.870, 813.0, 28.5132
43.988644900, 18.870, 908.0, 30.1330
44.032110660, 18.870, 879.0, 29.6479
44.075576420, 18.870, 962.0, 31.0161
44.119042180, 18.870, 1028.0, 32.0624
44.162507940, 18.870, 1214.0, 34.8425
44.205973700, 18.870, 1192.0, 34.5254
44.249439460, 18.870, 1253.0, 35.3977
44.292905220, 18.870, 1195.0, 34.5688
44.336370980, 18.870, 1171.0, 34.2199
44.379836740, 18.870, 1170.0, 34.2053
44.423302500, 18.870, 995.0, 31.5436
44.466768260, 18.870, 940.0, 30.6594
44.510234020, 18.870, 763.0, 27.6225
44.553699780, 18.870, 745.0, 27.2947
44.597165540, 18.870, 720.0, 26.8328
44.640631300, 18.870, 670.0, 25.8844
44.684097060, 18.870, 685.0, 26.1725
44.727562820, 18.870, 751.0, 27.4044
44.771028580, 18.870, 663.0, 25.7488
44.814494340, 18.870, 666.0, 25.8070
44.857960100, 18.870, 679.0, 26.0576
44.901425860, 18.870, 644.0, 25.3772
44.944891620, 18.870, 668.0, 25.8457
44.988357380, 18.870, 659.0, 25.6710
45.031823140, 18.870, 596.0, 24.4131
45.075288900, 18.870, 642.0, 25.3377
45.118754660, 18.870, 639.0, 25.2784
45.162220420, 18.870, 635.0, 25.1992
45.205686180, 18.870, 613.0, 24.7588
45.249151940, 18.870, 581.0, 24.1039
45.292617700, 18.870, 626.0, 25.0200
45.336083460, 18.870, 648.0, 25.4558
45.379549220, 18.870, 632.0, 25.1396
45.423014980, 18.870, 611.0, 24.7184
45.466480740, 18.870, 620.0, 24.8998
45.509946500, 18.870, 596.0, 24.4131
45.553412260, 18.870, 618.0, 24.8596
45.596878020, 18.870, 600.0, 24.4949
45.640343780, 18.870, 556.0, 23.5797
45.683809540, 18.870, 619.0, 24.8797
45.727275300, 18.870, 565.0, 23.7697
45.770741060, 18.870, 665.0, 25.7876
45.814206820, 18.870, 617.0, 24.8395
45.857672580, 18.870, 591.0, 24.3105
45.901138340, 18.870, 590.0, 24.2899
45.944604100, 18.870, 597.0, 24.4336
45.988069860, 18.870, 577.0, 24.0208
46.031535620, 18.870, 624.0, 24.9800
46.075001380, 18.870, 598.0, 24.4540
46.118467140, 18.870, 574.0, 23.9583
46.161932900, 18.870, 588.0, 24.2487
46.205398660, 18.870, 592.0, 24.3311
46.248864420, 18.870, 634.0, 25.1794
46.292330180, 18.870, 616.0, 24.8193
46.335795940, 18.870, 624.0, 24.9800
46.379261700, 18.870, 553.0, 23.5160
46.422727460, 18.870, 609.0, 24.6779
46.466193220, 18.870, 568.0, 23.8328
46.509658980, 18.870, 635.0, 25.1992
46.553124740, 18.870, 646.0, 25.4165
46.596590500, 18.870, 661.0, 25.7099
46.640056260, 18.870, 620.0, 24.8998
46.683522020, 18.870, 648.0, 25.4558
46.726987780, 18.870, 605.0, 24.5967
46.770453540, 18.870, 681.0, 26.0960
46.813919300, 18.870, 660.0, 25.6905
46.857385060, 18.870, 690.0, 26.2679
46.900850820, 18.870, 688.0, 26.2298
46.944316580, 18.870, 700.0, 26.4575
46.987782340, 18.870, 690.0, 26.2679
47.031248100, 18.870, 655.0, 25.5930
47.074713860, 18.870, 680.0, 26.0768
47.118179620, 18.870, 660.0, 25.6905
47.161645380, 18.870, 597.0, 24.4336
47.205111140, 18.870, 619.0, 24.8797
47.248576900, 18.870, 589.0, 24.2693
47.292042660, 18.870, 638.0, 25.2587
47.335508420, 18.870, 642.0, 25.3377
47.378974180, 18.870, 591.0, 24.3105
47.422439940, 18.870, 598.0, 24.4540
47.465905700, 18.870, 600.0, 24.4949
47.509371460, 18.870, 629.0, 25.0799
47.552837220, 18.870, 652.0, 25.5343
47.596302980, 18.870, 587.0, 24.2281
47.639768740, 18.870, 693.0, 26.3249
47.683234500, 18.870, 638.0, 25.2587
47.726700260, 18.870, 648.0, 25.4558
47.770166020, 18.870, 630.0, 25.0998
47.813631780, 18.870, 690.0, 26.2679
47.857097540, 18.870, 641.0, 25.3180
47.900563300, 18.870, 577.0, 24.0208
47.944029060, 18.870, 599.0, 24.4745
47.987494820, 18.870, 583.0, 24.1454
48.030960580, 18.870, 550.0, 23.4521
48.074426340, 18.870, 561.0, 23.6854
48.117892100, 18.870, 558.0, 23.6220
48.161357860, 18.870, 585.0, 24.1868
48.204823620, 18.870, 622.0, 24.9399
48.248289380, 18.870, 590.0, 24.2899
48.291755140, 18.870, 615.0, 24.7992
48.335220900, 18.870, 648.0, 25.4558
48.378686660, 18.870, 711.0, 26.6646
48.422152420, 18.870, 721.0, 26.8514
48.465618180, 18.870, 708.0, 26.6083
48.509083940, 18.870, 752.0, 27.4226
48.552549700, 18.870, 751.0, 27.4044
48.596015460, 18.870, 775.0, 27.8388
48.639481220, 18.870, 908.0, 30.1330
48.682946980, 18.870, 996.0, 31.5595
48.726412740, 18.870, 944.0, 30.7246
48.769878500, 18.870, 807.0, 28.4077
48.813344260, 18.870, 898.0, 29.9666
48.856810020, 18.870, 871.0, 29.5127
48.900275780, 18.870, 821.0, 28.6531
48.943741540, 18.870, 747.0, 27.3313
48.987207300, 18.870, 729.0, 27.0000
49.030673060, 18.870, 627.0, 25.0400
49.074138820, 18.870, 663.0, 25.7488
49.117604580, 18.870, 593.0, 24.3516
49.161070340, 18.870, 606.0, 24.6171
49.204536100, 18.870, 615.0, 24.7992
49.248001860, 18.870, 609.0, 24.6779
49.291467620, 18.870, 595.0, 24.3926
49.334933380, 18.870, 569.0, 23.8537
49.378399140, 18.870, 619.0, 24.8797
49.421864900, 18.870, 633.0, 25.1595
49.465330660, 18.870, 702.0, 26.4953
49.508796420, 18.870, 783.0, 27.9821
49.552262180, 18.870, 975.0, 31.2250
49.595727940, 18.870, 1069.0, 32.6956
49.639193700, 18.870, 1034.0, 32.1559
49.682659460, 18.870, 1075.0, 32.7872
49.726125220, 18.870, 1008.0, 31.7490
49.769590980, 18.870, 993.0, 31.5119
49.813056740, 18.870, 893.0, 29.8831
49.856522500, 18.870, 789.0, 28.0891
49.899988260, 18.870, 736.0, 27.1293
49.943454020, 18.870, 665.0, 25.7876
49.986919780, 18.870, 664.0, 25.7682
50.030385540, 18.870, 590.0, 24.2899
50.073851300, 18.870, 561.0, 23.6854
50.117317060, 18.870, 584.0, 24.1661
50.160782820, 18.870, 584.0, 24.1661
50.204248580, 18.870, 580.0, 24.0832
50.247714340, 18.870, 590.0, 24.2899
50.291180100, 18.870, 608.0, 24.6577
50.334645860, 18.870, 623.0, 24.9600
50.378111620, 18.870, 654.0, 25.5734
50.421577380, 18.870, 654.0, 25.5734
50.465043140, 18.870, 681.0, 26.0960
50.508508900, 18.870, 608.0, 24.6577
50.551974660, 18.870, 636.0, 25.2190
50.595440420, 18.870, 630.0, 25.0998
50.638906180, 18.870, 632.0, 25.1396
50.682371940, 18.870, 581.0, 24.1039
50.725837700, 18.870, 525.0, 22.9129
50.769303460, 18.870, 535.0, 23.1301
50.812769220, 18.870, 568.0, 23.8328
50.856234980, 18.870, 585.0, 24.1868
50.899700740, 18.870, 600.0, 24.4949
50.943166500, 18.870, 561.0, 23.6854
50.986632260, 18.870, 569.0, 23.8537
51.030098020, 18.870, 553.0, 23.5160
51.073563780, 18.870, 579.0, 24.0624
51.117029540, 18.870, 563.0, 23.7276
51.160495300, 18.870, 530.0, 23.0217
51.203961060, 18.870, 528.0, 22.9783
51.247426820, 18.870, 559.0, 23.6432
51.290892580, 18.870, 524.0, 22.8910
51.334358340, 18.870, 548.0, 23.4094
51.377824100, 18.870, 551.0, 23.4734
51.421289860, 18.870, 529.0, 23.0000
51.464755620, 18.870, 531.0, 23.0434
51.508221380, 18.870, 493.0, 22.2036
51.551687140, 18.870, 530.0, 23.0217
51.595152900, 18.870, 511.0, 22.6053
51.638618660, 18.870, 533.0, 23.0868
51.682084420, 18.870, 506.0, 22.4944
51.725550180, 18.870, 515.0, 22.6936
51.769015940, 18.870, 561.0, 23.6854
51.812481700, 18.870, 535.0, 23.1301
51.855947460, 18.870, 518.0, 22.7596
51.899413220, 18.870, 553.0, 23.5160
51.942878980, 18.870, 472.0, 21.7256
51.986344740, 18.870, 579.0, 24.0624
52.029810500, 18.870, 557.0, 23.6008
52.073276260, 18.870, 550.0, 23.4521
52.116742020, 18.870, 505.0, 22.4722
52.160207780, 18.870, 570.0, 23.8747
52.203673540, 18.870, 582.0, 24.1247
52.247139300, 18.870, 530.0, 23.0217
52.290605060, 18.870, 589.0, 24.2693
52.334070820, 18.870, 587.0, 24.2281
52.377536580, 18.870, 557.0, 23.6008
52.421002340, 18.870, 563.0, 23.7276
52.464468100, 18.870, 526.0, 22.9347
52.507933860, 18.870, 487.0, 22.0681
52.551399620, 18.870, 513.0, 22.6495
52.594865380, 18.870, 486.0, 22.0454
52.638331140, 18.870, 497.0, 22.2935
52.681796900, 18.870, 469.0, 21.6564
52.725262660, 18.870, 505.0, 22.4722
52.768728420, 18.870, 487.0, 22.0681
52.812194180, 18.870, 495.0, 22.2486
52.855659940, 18.870, 465.0, 21.5639
52.899125700, 18.870, 476.0, 21.8174
52.942591460, 18.870, 474.0, 21.7715
52.986057220, 18.870, 471.0, 21.7025
53.029522980, 18.870, 473.0, 21.7486
53.072988740, 18.870, 479.0, 21.8861
53.116454500, 18.870, 470.0, 21.6795
53.159920260, 18.870, 425.0, 20.6155
53.203386020, 18.870, 473.0, 21.7486
53.246851780, 18.870, 511.0, 22.6053
53.290317540, 18.870, 444.0, 21.0713
53.333783300, 18.870, 475.0, 21.7945
53.377249060, 18.870, 488.0, 22.0907
53.420714820, 18.870, 496.0, 22.2711
53.464180580, 18.870, 468.0, 21.6333
53.507646340, 18.870, 457.0, 21.3776
53.551112100, 18.870, 492.0, 22.1811
53.594577860, 18.870, 483.0, 21.9773
53.638043620, 18.870, 452.0, 21.2603
53.681509380, 18.870, 463.0, 21.5174
53.724975140, 18.870, 484.0, 22.0000
53.768440900, 18.870, 472.0, 21.7256
53.811906660, 18.870, 495.0, 22.2486
53.855372420, 18.870, 472.0, 21.7256
53.898838180, 18.870, 452.0, 21.2603
53.942303940, 18.870, 441.0, 21.0000
53.985769700, 18.870, 480.0, 21.9089
54.029235460, 18.870, 449.0, 21.1896
54.072701220, 18.870, 480.0, 21.9089
54.116166980, 18.870, 445.0, 21.0950
54.159632740, 18.870, 485.0, 22.0227
54.203098500, 18.870, 468.0, 21.6333
54.246564260, 18.870, 482.0, 21.9545
54.290030020, 18.870, 447.0, 21.1424
54.333495780, 18.870, 457.0, 21.3776
54.376961540, 18.870, 434.0, 20.8327
54.420427300, 18.870, 449.0, 21.1896
54.463893060, 18.870, 427.0, 20.6640
54.507358820, 18.870, 416.0, 20.3961
54.550824580, 18.870, 472.0, 21.7256
54.594290340, 18.870, 483.0, 21.9773
54.637756100, 18.870, 408.0, 20.1990
54.681221860, 18.870, 455.0, 21.3307
54.724687620, 18.870, 449.0, 21.1896
54.768153380, 18.870, 456.0, 21.3542
54.811619140, 18.870, 462.0, 21.4942
54.855084900, 18.870, 488.0, 22.0907
54.898550660, 18.870, 492.0, 22.1811
54.942016420, 18.870, 461.0, 21.4709
54.985482180, 18.870, 499.0, 22.3383
55.028947940, 18.870, 542.0, 23.2809
55.072413700, 18.870, 517.0, 22.7376
55.115879460, 18.870, 505.0, 22.4722
55.159345220, 18.870, 596.0, 24.4131
55.202810980, 18.870, 678.0, 26.0384
55.246276740, 18.870, 767.0, 27.6948
55.289742500, 18.870, 699.0, 26.4386
55.333208260, 18.870, 706.0, 26.5707
55.376674020, 18.870, 797.0, 28.2312
55.420139780, 18.870, 789.0, 28.0891
55.463605540, 18.870, 811.0, 28.4781
55.507071300, 18.870, 715.0, 26.7395
55.550537060, 18.870, 621.0, 24.9199
55.594002820, 18.870, 633.0, 25.1595
55.637468580, 18.870, 616.0, 24.8193
55.680934340, 18.870, 570.0, 23.8747
55.724400100, 18.870, 508.0, 22.5389
55.767865860, 18.870, 443.0, 21.0476
55.811331620, 18.870, 472.0, 21.7256
55.854797380, 18.870, 501.0, 22.3830
55.898263140, 18.870, 510.0, 22.5832
55.941728900, 18.870, 471.0, 21.7025
55.985194660, 18.870, 466.0, 21.5870
56.028660420, 18.870, 494.0, 22.2261
56.072126180, 18.870, 479.0, 21.8861
56.115591940, 18.870, 482.0, 21.9545
56.159057700, 18.870, 495.0, 22.2486
56.202523460, 18.870, 523.0, 22.8692
56.245989220, 18.870, 540.0, 23.2379
56.289454980, 18.870, 508.0, 22.5389
56.332920740, 18.870, 471.0, 21.7025
56.376386500, 18.870, 502.0, 22.4054
56.419852260, 18.870, 511.0, 22.6053
56.463318020, 18.870, 483.0, 21.9773
56.506783780, 18.870, 501.0, 22.3830
56.550249540, 18.870, 449.0, 21.1896
56.593715300, 18.870, 443.0, 21.0476
56.637181060, 18.870, 435.0, 20.8567
56.680646820, 18.870, 437.0, 20.9045
56.724112580, 18.870, 421.0, 20.5183
56.767578340, 18.870, 412.0, 20.2978
56.811044100, 18.870, 387.0, 19.6723
56.854509860, 18.870, 383.0, 19.5704
56.897975620, 18.870, 414.0, 20.3470
56.941441380, 18.870, 442.0, 21.0238
56.984907140, 18.870, 403.0, 20.0749
57.028372900, 18.870, 419.0, 20.4695
57.071838660, 18.870, 398.0, 19.9499
57.115304420, 18.870, 443.0, 21.0476
57.158770180, 18.870, 398.0, 19.9499
57.202235940, 18.870, 408.0, 20.1990
57.245701700, 18.870, 454.0, 21.3073
57.289167460, 18.870, 432.0, 20.7846
57.332633220, 18.870, 422.0, 20.5426
57.376098980, 18.870, 435.0, 20.8567
57.419564740, 18.870, 421.0, 20.5183
57.463030500, 18.870, 417.0, 20.4206
57.506496260, 18.870, 412.0, 20.2978
57.549962020, 18.870, 421.0, 20.5183
57.593427780, 18.870, 382.0, 19.5448
57.636893540, 18.870, 358.0, 18.9209
57.680359300, 18.870, 405.0, 20.1246
57.723825060, 18.870, 406.0, 20.1494
57.767290820, 18.870, 412.0, 20.2978
57.810756580, 18.870, 421.0, 20.5183
57.854222340, 18.870, 398.0, 19.9499
57.897688100, 18.870, 419.0, 20.4695
57.941153860, 18.870, 445.0, 21.0950
57.984619620, 18.870, 418.0, 20.4450
58.028085380, 18.870, 400.0, 20.0000
58.071551140, 18.870, 401.0, 20.0250
58.115016900, 18.870, 412.0, 20.2978
58.158482660, 18.870, 444.0, 21.0713
58.201948420, 18.870, 434.0, 20.8327
58.245414180, 18.870, 456.0, 21.3542
58.288879940, 18.870, 393.0, 19.8242
58.332345700, 18.870, 397.0, 19.9249
58.375811460, 18.870, 397.0, 19.9249
58.419277220, 18.870, 399.0, 19.9750
58.462742980, 18.870, 438.0, 20.9284
58.506208740, 18.870, 417.0, 20.4206
58.549674500, 18.870, 389.0, 19.7231
58.593140260, 18.870, 417.0, 20.4206
58.636606020, 18.870, 393.0, 19.8242
58.680071780, 18.870, 422.0, 20.5426
58.723537540, 18.870, 362.0, 19.0263
58.767003300, 18.870, 372.0, 19.2873
58.810469060, 18.870, 361.0, 19.0000
58.853934820, 18.870, 418.0, 20.4450
58.897400580, 18.870, 378.0, 19.4422
58.940866340, 18.870, 361.0, 19.0000
58.984332100, 18.870, 356.0, 18.8680
59.027797860, 18.870, 383.0, 19.5704
59.071263620, 18.870, 379.0, 19.4679
59.114729380, 18.870, 382.0, 19.5448
59.158195140, 18.870, 380.0, 19.4936
59.201660900, 18.870, 334.0, 18.2757
59.245126660, 18.870, 362.0, 19.0263
59.288592420, 18.870, 370.0, 19.2354
59.332058180, 18.870, 406.0, 20.1494
59.375523940, 18.870, 405.0, 20.1246
59.418989700, 18.870, 392.0, 19.7990
59.462455460, 18.870, 401.0, 20.0250
59.505921220, 18.870, 336.0, 18.3303
59.549386980, 18.870, 366.0, 19.1311
59.592852740, 18.870, 366.0, 19.1311
59.636318500, 18.870, 385.0, 19.6214
59.679784260, 18.870, 411.0, 20.2731
59.723250020, 18.870, 392.0, 19.7990
59.766715780, 18.870, 395.0, 19.8746
59.810181540, 18.870, 383.0, 19.5704
59.853647300, 18.870, 409.0, 20.2237
59.897113060, 18.870, 411.0, 20.2731
59.940578820, 18.870, 385.0, 19.6214
59.984044580, 18.870, 388.0, 19.6977
59.994911020, 18.870, 379.0, 19.4679