File: XRD/2025_06_03_CBN_Sorbic_Acid_Slurry.csv
[Measurement conditions]
Sample identification,2025_06_03_CBN_Sorbic_Acid_Slurry
Comment - 1,"CBN - Sorbic Acid Cocrystal, Slurry Method, Heptane, 5/9/25, JL"
Anode material,Cu
K-Alpha1 wavelength,1.5405980
K-Alpha2 wavelength,1.5444260
Ratio K-Alpha2/K-Alpha1,0.500
Divergence slit,Fixed,0.76mm
Monochromator used,NO
Generator voltage, 40
Tube current, 15
File date and time,03/Jun/2025 14:28
Unit cell,
h k l, 0 0 0
Scan axis,Gonio
Scan range,10.000000000,80.001606480
Scan step size,0.0108664
No. of points, 6442
Scan type,CONTINUOUS
Time per step,48.195
[Scan points]
Angle, TimePerStep, Intensity, ESD
10.005433220, 48.195, 5465.0, 73.9256
10.059765420, 48.195, 6366.0, 79.7872
10.114097620, 48.195, 7044.0, 83.9285
10.168429820, 48.195, 7537.0, 86.8159
10.222762020, 48.195, 7723.0, 87.8806
10.277094220, 48.195, 7176.0, 84.7113
10.331426420, 48.195, 6553.0, 80.9506
10.385758620, 48.195, 5550.0, 74.4983
10.440090820, 48.195, 5235.0, 72.3533
10.494423020, 48.195, 5189.0, 72.0347
10.548755220, 48.195, 5759.0, 75.8881
10.603087420, 48.195, 5961.0, 77.2075
10.657419620, 48.195, 6489.0, 80.5543
10.711751820, 48.195, 6604.0, 81.2650
10.766084020, 48.195, 6235.0, 78.9620
10.820416220, 48.195, 5590.0, 74.7663
10.874748420, 48.195, 5387.0, 73.3962
10.929080620, 48.195, 5763.0, 75.9144
10.983412820, 48.195, 6499.0, 80.6164
11.037745020, 48.195, 7185.0, 84.7644
11.092077220, 48.195, 8272.0, 90.9505
11.146409420, 48.195, 9024.0, 94.9947
11.200741620, 48.195, 9471.0, 97.3191
11.255073820, 48.195, 10134.0, 100.6678
11.309406020, 48.195, 10128.0, 100.6380
11.363738220, 48.195, 10510.0, 102.5183
11.418070420, 48.195, 10047.0, 100.2347
11.472402620, 48.195, 9519.0, 97.5654
11.526734820, 48.195, 8401.0, 91.6570
11.581067020, 48.195, 6893.0, 83.0241
11.635399220, 48.195, 5784.0, 76.0526
11.689731420, 48.195, 5367.0, 73.2598
11.744063620, 48.195, 5192.0, 72.0555
11.798395820, 48.195, 5204.0, 72.1388
11.852728020, 48.195, 5154.0, 71.7914
11.907060220, 48.195, 4832.0, 69.5126
11.961392420, 48.195, 4598.0, 67.8086
12.015724620, 48.195, 4467.0, 66.8356
12.070056820, 48.195, 4599.0, 67.8159
12.124389020, 48.195, 4856.0, 69.6850
12.178721220, 48.195, 5740.0, 75.7628
12.233053420, 48.195, 6768.0, 82.2679
12.287385620, 48.195, 8447.0, 91.9076
12.341717820, 48.195, 10452.0, 102.2350
12.396050020, 48.195, 12197.0, 110.4400
12.450382220, 48.195, 13341.0, 115.5032
12.504714420, 48.195, 13733.0, 117.1879
12.559046620, 48.195, 12778.0, 113.0398
12.613378820, 48.195, 10819.0, 104.0144
12.667711020, 48.195, 8206.0, 90.5870
12.722043220, 48.195, 6533.0, 80.8270
12.776375420, 48.195, 5959.0, 77.1946
12.830707620, 48.195, 5577.0, 74.6793
12.885039820, 48.195, 5632.0, 75.0467
12.939372020, 48.195, 5663.0, 75.2529
12.993704220, 48.195, 5136.0, 71.6659
13.048036420, 48.195, 4641.0, 68.1249
13.102368620, 48.195, 4066.0, 63.7652
13.156700820, 48.195, 3944.0, 62.8013
13.211033020, 48.195, 3887.0, 62.3458
13.265365220, 48.195, 4122.0, 64.2028
13.319697420, 48.195, 4369.0, 66.0984
13.374029620, 48.195, 4619.0, 67.9632
13.428361820, 48.195, 4478.0, 66.9179
13.482694020, 48.195, 4344.0, 65.9090
13.537026220, 48.195, 3968.0, 62.9921
13.591358420, 48.195, 3715.0, 60.9508
13.645690620, 48.195, 3824.0, 61.8385
13.700022820, 48.195, 3976.0, 63.0555
13.754355020, 48.195, 4171.0, 64.5833
13.808687220, 48.195, 4185.0, 64.6916
13.863019420, 48.195, 4018.0, 63.3877
13.917351620, 48.195, 3987.0, 63.1427
13.971683820, 48.195, 3882.0, 62.3057
14.026016020, 48.195, 3917.0, 62.5859
14.080348220, 48.195, 4319.0, 65.7191
14.134680420, 48.195, 4761.0, 69.0000
14.189012620, 48.195, 5645.0, 75.1332
14.243344820, 48.195, 6471.0, 80.4425
14.297677020, 48.195, 7686.0, 87.6698
14.352009220, 48.195, 8427.0, 91.7987
14.406341420, 48.195, 9047.0, 95.1157
14.460673620, 48.195, 9271.0, 96.2860
14.515005820, 48.195, 8820.0, 93.9149
14.569338020, 48.195, 7686.0, 87.6698
14.623670220, 48.195, 6538.0, 80.8579
14.678002420, 48.195, 5459.0, 73.8850
14.732334620, 48.195, 4757.0, 68.9710
14.786666820, 48.195, 4324.0, 65.7571
14.840999020, 48.195, 4235.0, 65.0769
14.895331220, 48.195, 3948.0, 62.8331
14.949663420, 48.195, 3906.0, 62.4980
15.003995620, 48.195, 4196.0, 64.7765
15.058327820, 48.195, 4591.0, 67.7569
15.112660020, 48.195, 5071.0, 71.2110
15.166992220, 48.195, 5712.0, 75.5778
15.221324420, 48.195, 6084.0, 78.0000
15.275656620, 48.195, 6321.0, 79.5047
15.329988820, 48.195, 6412.0, 80.0750
15.384321020, 48.195, 6111.0, 78.1729
15.438653220, 48.195, 5556.0, 74.5386
15.492985420, 48.195, 5141.0, 71.7008
15.547317620, 48.195, 4739.0, 68.8404
15.601649820, 48.195, 4636.0, 68.0882
15.655982020, 48.195, 4553.0, 67.4759
15.710314220, 48.195, 4872.0, 69.7997
15.764646420, 48.195, 5097.0, 71.3933
15.818978620, 48.195, 5827.0, 76.3348
15.873310820, 48.195, 6798.0, 82.4500
15.927643020, 48.195, 8377.0, 91.5260
15.981975220, 48.195, 10590.0, 102.9077
16.036307420, 48.195, 12697.0, 112.6810
16.090639620, 48.195, 14300.0, 119.5826
16.144971820, 48.195, 15077.0, 122.7884
16.199304020, 48.195, 14604.0, 120.8470
16.253636220, 48.195, 13215.0, 114.9565
16.307968420, 48.195, 10555.0, 102.7375
16.362300620, 48.195, 8184.0, 90.4655
16.416632820, 48.195, 6402.0, 80.0125
16.470965020, 48.195, 5297.0, 72.7805
16.525297220, 48.195, 4970.0, 70.4982
16.579629420, 48.195, 4654.0, 68.2202
16.633961620, 48.195, 4602.0, 67.8380
16.688293820, 48.195, 5018.0, 70.8378
16.742626020, 48.195, 5402.0, 73.4983
16.796958220, 48.195, 6024.0, 77.6144
16.851290420, 48.195, 6386.0, 79.9125
16.905622620, 48.195, 6573.0, 81.0740
16.959954820, 48.195, 6653.0, 81.5659
17.014287020, 48.195, 6267.0, 79.1644
17.068619220, 48.195, 5673.0, 75.3193
17.122951420, 48.195, 5096.0, 71.3863
17.177283620, 48.195, 4829.0, 69.4910
17.231615820, 48.195, 4635.0, 68.0808
17.285948020, 48.195, 4576.0, 67.6461
17.340280220, 48.195, 4401.0, 66.3400
17.394612420, 48.195, 4766.0, 69.0362
17.448944620, 48.195, 4730.0, 68.7750
17.503276820, 48.195, 5320.0, 72.9383
17.557609020, 48.195, 5770.0, 75.9605
17.611941220, 48.195, 6646.0, 81.5230
17.666273420, 48.195, 7336.0, 85.6505
17.720605620, 48.195, 7845.0, 88.5720
17.774937820, 48.195, 8183.0, 90.4599
17.829270020, 48.195, 8704.0, 93.2952
17.883602220, 48.195, 9372.0, 96.8091
17.937934420, 48.195, 10064.0, 100.3195
17.992266620, 48.195, 11257.0, 106.0990
18.046598820, 48.195, 12026.0, 109.6631
18.100931020, 48.195, 12618.0, 112.3299
18.155263220, 48.195, 13432.0, 115.8965
18.209595420, 48.195, 14208.0, 119.1973
18.263927620, 48.195, 15526.0, 124.6034
18.318259820, 48.195, 16690.0, 129.1898
18.372592020, 48.195, 16962.0, 130.2382
18.426924220, 48.195, 16691.0, 129.1937
18.481256420, 48.195, 15395.0, 124.0766
18.535588620, 48.195, 13782.0, 117.3968
18.589920820, 48.195, 11281.0, 106.2121
18.644253020, 48.195, 8879.0, 94.2284
18.698585220, 48.195, 7164.0, 84.6404
18.752917420, 48.195, 6398.0, 79.9875
18.807249620, 48.195, 6159.0, 78.4793
18.861581820, 48.195, 6585.0, 81.1480
18.915914020, 48.195, 7210.0, 84.9117
18.970246220, 48.195, 7884.0, 88.7919
19.024578420, 48.195, 8422.0, 91.7715
19.078910620, 48.195, 9226.0, 96.0521
19.133242820, 48.195, 9261.0, 96.2341
19.187575020, 48.195, 9105.0, 95.4201
19.241907220, 48.195, 8847.0, 94.0585
19.296239420, 48.195, 8235.0, 90.7469
19.350571620, 48.195, 7752.0, 88.0454
19.404903820, 48.195, 7543.0, 86.8504
19.459236020, 48.195, 7393.0, 85.9826
19.513568220, 48.195, 7565.0, 86.9770
19.567900420, 48.195, 7312.0, 85.5102
19.622232620, 48.195, 7103.0, 84.2793
19.676564820, 48.195, 6917.0, 83.1685
19.730897020, 48.195, 7226.0, 85.0059
19.785229220, 48.195, 7703.0, 87.7667
19.839561420, 48.195, 7900.0, 88.8819
19.893893620, 48.195, 8067.0, 89.8165
19.948225820, 48.195, 7846.0, 88.5776
20.002558020, 48.195, 7318.0, 85.5453
20.056890220, 48.195, 6938.0, 83.2947
20.111222420, 48.195, 7111.0, 84.3267
20.165554620, 48.195, 7360.0, 85.7904
20.219886820, 48.195, 8211.0, 90.6146
20.274219020, 48.195, 9622.0, 98.0918
20.328551220, 48.195, 11584.0, 107.6290
20.382883420, 48.195, 13485.0, 116.1249
20.437215620, 48.195, 15011.0, 122.5194
20.491547820, 48.195, 15384.0, 124.0323
20.545880020, 48.195, 14785.0, 121.5936
20.600212220, 48.195, 13165.0, 114.7388
20.654544420, 48.195, 10968.0, 104.7282
20.708876620, 48.195, 9136.0, 95.5824
20.763208820, 48.195, 8011.0, 89.5042
20.817541020, 48.195, 7301.0, 85.4459
20.871873220, 48.195, 6805.0, 82.4924
20.926205420, 48.195, 6532.0, 80.8208
20.980537620, 48.195, 6256.0, 79.0949
21.034869820, 48.195, 5885.0, 76.7138
21.089202020, 48.195, 5791.0, 76.0986
21.143534220, 48.195, 5973.0, 77.2852
21.197866420, 48.195, 6433.0, 80.2060
21.252198620, 48.195, 6946.0, 83.3427
21.306530820, 48.195, 7459.0, 86.3655
21.360863020, 48.195, 8199.0, 90.5483
21.415195220, 48.195, 8810.0, 93.8616
21.469527420, 48.195, 9095.0, 95.3677
21.523859620, 48.195, 9814.0, 99.0656
21.578191820, 48.195, 10157.0, 100.7819
21.632524020, 48.195, 10734.0, 103.6050
21.686856220, 48.195, 11060.0, 105.1665
21.741188420, 48.195, 10720.0, 103.5374
21.795520620, 48.195, 10140.0, 100.6976
21.849852820, 48.195, 9178.0, 95.8019
21.904185020, 48.195, 8409.0, 91.7006
21.958517220, 48.195, 7732.0, 87.9318
22.012849420, 48.195, 7155.0, 84.5872
22.067181620, 48.195, 7136.0, 84.4748
22.121513820, 48.195, 7007.0, 83.7078
22.175846020, 48.195, 7129.0, 84.4334
22.230178220, 48.195, 7458.0, 86.3597
22.284510420, 48.195, 7794.0, 88.2836
22.338842620, 48.195, 7984.0, 89.3532
22.393174820, 48.195, 7793.0, 88.2780
22.447507020, 48.195, 7149.0, 84.5518
22.501839220, 48.195, 6445.0, 80.2808
22.556171420, 48.195, 5571.0, 74.6391
22.610503620, 48.195, 5176.0, 71.9444
22.664835820, 48.195, 4929.0, 70.2068
22.719168020, 48.195, 4998.0, 70.6965
22.773500220, 48.195, 5120.0, 71.5542
22.827832420, 48.195, 5082.0, 71.2881
22.882164620, 48.195, 5151.0, 71.7705
22.936496820, 48.195, 5174.0, 71.9305
22.990829020, 48.195, 5096.0, 71.3863
23.045161220, 48.195, 4893.0, 69.9500
23.099493420, 48.195, 4727.0, 68.7532
23.153825620, 48.195, 4427.0, 66.5357
23.208157820, 48.195, 4310.0, 65.6506
23.262490020, 48.195, 3956.0, 62.8967
23.316822220, 48.195, 3862.0, 62.1450
23.371154420, 48.195, 3731.0, 61.0819
23.425486620, 48.195, 3765.0, 61.3596
23.479818820, 48.195, 3661.0, 60.5062
23.534151020, 48.195, 3686.0, 60.7124
23.588483220, 48.195, 3727.0, 61.0492
23.642815420, 48.195, 3897.0, 62.4260
23.697147620, 48.195, 4249.0, 65.1844
23.751479820, 48.195, 4253.0, 65.2150
23.805812020, 48.195, 4622.0, 67.9853
23.860144220, 48.195, 4784.0, 69.1665
23.914476420, 48.195, 5137.0, 71.6729
23.968808620, 48.195, 5575.0, 74.6659
24.023140820, 48.195, 5779.0, 76.0197
24.077473020, 48.195, 5938.0, 77.0584
24.131805220, 48.195, 5851.0, 76.4918
24.186137420, 48.195, 5238.0, 72.3740
24.240469620, 48.195, 4759.0, 68.9855
24.294801820, 48.195, 4236.0, 65.0846
24.349134020, 48.195, 4112.0, 64.1249
24.403466220, 48.195, 4038.0, 63.5453
24.457798420, 48.195, 4216.0, 64.9307
24.512130620, 48.195, 4553.0, 67.4759
24.566462820, 48.195, 4856.0, 69.6850
24.620795020, 48.195, 5221.0, 72.2565
24.675127220, 48.195, 5575.0, 74.6659
24.729459420, 48.195, 5543.0, 74.4513
24.783791620, 48.195, 5324.0, 72.9657
24.838123820, 48.195, 4963.0, 70.4486
24.892456020, 48.195, 4743.0, 68.8694
24.946788220, 48.195, 4377.0, 66.1589
25.001120420, 48.195, 4370.0, 66.1060
25.055452620, 48.195, 4618.0, 67.9559
25.109784820, 48.195, 4766.0, 69.0362
25.164117020, 48.195, 4903.0, 70.0214
25.218449220, 48.195, 4807.0, 69.3325
25.272781420, 48.195, 4630.0, 68.0441
25.327113620, 48.195, 4336.0, 65.8483
25.381445820, 48.195, 4154.0, 64.4515
25.435778020, 48.195, 3972.0, 63.0238
25.490110220, 48.195, 3984.0, 63.1189
25.544442420, 48.195, 3977.0, 63.0635
25.598774620, 48.195, 4083.0, 63.8984
25.653106820, 48.195, 4052.0, 63.6553
25.707439020, 48.195, 4088.0, 63.9375
25.761771220, 48.195, 3979.0, 63.0793
25.816103420, 48.195, 3743.0, 61.1801
25.870435620, 48.195, 3549.0, 59.5735
25.924767820, 48.195, 3401.0, 58.3181
25.979100020, 48.195, 3062.0, 55.3353
26.033432220, 48.195, 3149.0, 56.1160
26.087764420, 48.195, 3247.0, 56.9825
26.142096620, 48.195, 3320.0, 57.6194
26.196428820, 48.195, 3317.0, 57.5934
26.250761020, 48.195, 3410.0, 58.3952
26.305093220, 48.195, 3298.0, 57.4282
26.359425420, 48.195, 3143.0, 56.0625
26.413757620, 48.195, 2889.0, 53.7494
26.468089820, 48.195, 3000.0, 54.7723
26.522422020, 48.195, 2814.0, 53.0471
26.576754220, 48.195, 2910.0, 53.9444
26.631086420, 48.195, 2898.0, 53.8331
26.685418620, 48.195, 3061.0, 55.3263
26.739750820, 48.195, 3059.0, 55.3082
26.794083020, 48.195, 3146.0, 56.0892
26.848415220, 48.195, 3135.0, 55.9911
26.902747420, 48.195, 3224.0, 56.7803
26.957079620, 48.195, 3225.0, 56.7891
27.011411820, 48.195, 3407.0, 58.3695
27.065744020, 48.195, 3726.0, 61.0410
27.120076220, 48.195, 3857.0, 62.1048
27.174408420, 48.195, 3869.0, 62.2013
27.228740620, 48.195, 3744.0, 61.1882
27.283072820, 48.195, 3692.0, 60.7618
27.337405020, 48.195, 3388.0, 58.2065
27.391737220, 48.195, 3286.0, 57.3236
27.446069420, 48.195, 3220.0, 56.7450
27.500401620, 48.195, 3087.0, 55.5608
27.554733820, 48.195, 3163.0, 56.2406
27.609066020, 48.195, 3303.0, 57.4717
27.663398220, 48.195, 3176.0, 56.3560
27.717730420, 48.195, 3138.0, 56.0179
27.772062620, 48.195, 3059.0, 55.3082
27.826394820, 48.195, 2893.0, 53.7866
27.880727020, 48.195, 2775.0, 52.6783
27.935059220, 48.195, 2647.0, 51.4490
27.989391420, 48.195, 2693.0, 51.8941
28.043723620, 48.195, 2675.0, 51.7204
28.098055820, 48.195, 2702.0, 51.9808
28.152388020, 48.195, 2771.0, 52.6403
28.206720220, 48.195, 2803.0, 52.9434
28.261052420, 48.195, 2853.0, 53.4135
28.315384620, 48.195, 2774.0, 52.6688
28.369716820, 48.195, 2739.0, 52.3355
28.424049020, 48.195, 2915.0, 53.9907
28.478381220, 48.195, 2989.0, 54.6717
28.532713420, 48.195, 3060.0, 55.3173
28.587045620, 48.195, 3284.0, 57.3062
28.641377820, 48.195, 3318.0, 57.6021
28.695710020, 48.195, 3419.0, 58.4722
28.750042220, 48.195, 3285.0, 57.3149
28.804374420, 48.195, 3127.0, 55.9196
28.858706620, 48.195, 2834.0, 53.2353
28.913038820, 48.195, 2700.0, 51.9615
28.967371020, 48.195, 2635.0, 51.3323
29.021703220, 48.195, 2590.0, 50.8920
29.076035420, 48.195, 2624.0, 51.2250
29.130367620, 48.195, 2653.0, 51.5073
29.184699820, 48.195, 2523.0, 50.2295
29.239032020, 48.195, 2444.0, 49.4368
29.293364220, 48.195, 2322.0, 48.1871
29.347696420, 48.195, 2275.0, 47.6970
29.402028620, 48.195, 2162.0, 46.4973
29.456360820, 48.195, 2023.0, 44.9778
29.510693020, 48.195, 2124.0, 46.0869
29.565025220, 48.195, 2116.0, 46.0000
29.619357420, 48.195, 2077.0, 45.5741
29.673689620, 48.195, 2249.0, 47.4236
29.728021820, 48.195, 2233.0, 47.2546
29.782354020, 48.195, 2374.0, 48.7237
29.836686220, 48.195, 2474.0, 49.7393
29.891018420, 48.195, 2400.0, 48.9898
29.945350620, 48.195, 2552.0, 50.5173
29.999682820, 48.195, 2621.0, 51.1957
30.054015020, 48.195, 2564.0, 50.6360
30.108347220, 48.195, 2414.0, 49.1325
30.162679420, 48.195, 2318.0, 48.1456
30.217011620, 48.195, 2257.0, 47.5079
30.271343820, 48.195, 2045.0, 45.2217
30.325676020, 48.195, 2143.0, 46.2925
30.380008220, 48.195, 2090.0, 45.7165
30.434340420, 48.195, 2115.0, 45.9891
30.488672620, 48.195, 2305.0, 48.0104
30.543004820, 48.195, 2450.0, 49.4975
30.597337020, 48.195, 2390.0, 48.8876
30.651669220, 48.195, 2367.0, 48.6518
30.706001420, 48.195, 2355.0, 48.5283
30.760333620, 48.195, 2494.0, 49.9400
30.814665820, 48.195, 2702.0, 51.9808
30.868998020, 48.195, 2865.0, 53.5257
30.923330220, 48.195, 2815.0, 53.0566
30.977662420, 48.195, 2710.0, 52.0577
31.031994620, 48.195, 2575.0, 50.7445
31.086326820, 48.195, 2396.0, 48.9490
31.140659020, 48.195, 2185.0, 46.7440
31.194991220, 48.195, 2043.0, 45.1996
31.249323420, 48.195, 2027.0, 45.0222
31.303655620, 48.195, 1979.0, 44.4860
31.357987820, 48.195, 2035.0, 45.1110
31.412320020, 48.195, 2042.0, 45.1885
31.466652220, 48.195, 2055.0, 45.3321
31.520984420, 48.195, 1985.0, 44.5533
31.575316620, 48.195, 1982.0, 44.5197
31.629648820, 48.195, 2004.0, 44.7661
31.683981020, 48.195, 2116.0, 46.0000
31.738313220, 48.195, 2053.0, 45.3100
31.792645420, 48.195, 2102.0, 45.8476
31.846977620, 48.195, 2160.0, 46.4758
31.901309820, 48.195, 2248.0, 47.4131
31.955642020, 48.195, 2226.0, 47.1805
32.009974220, 48.195, 2384.0, 48.8262
32.064306420, 48.195, 2521.0, 50.2096
32.118638620, 48.195, 2621.0, 51.1957
32.172970820, 48.195, 2493.0, 49.9300
32.227303020, 48.195, 2320.0, 48.1664
32.281635220, 48.195, 2206.0, 46.9681
32.335967420, 48.195, 2273.0, 47.6760
32.390299620, 48.195, 2167.0, 46.5510
32.444631820, 48.195, 2200.0, 46.9042
32.498964020, 48.195, 2241.0, 47.3392
32.553296220, 48.195, 2361.0, 48.5901
32.607628420, 48.195, 2535.0, 50.3488
32.661960620, 48.195, 2488.0, 49.8799
32.716292820, 48.195, 2351.0, 48.4871
32.770625020, 48.195, 2356.0, 48.5386
32.824957220, 48.195, 2178.0, 46.6690
32.879289420, 48.195, 2056.0, 45.3431
32.933621620, 48.195, 2022.0, 44.9667
32.987953820, 48.195, 2024.0, 44.9889
33.042286020, 48.195, 1989.0, 44.5982
33.096618220, 48.195, 1940.0, 44.0454
33.150950420, 48.195, 1934.0, 43.9773
33.205282620, 48.195, 1877.0, 43.3244
33.259614820, 48.195, 1851.0, 43.0232
33.313947020, 48.195, 1825.0, 42.7200
33.368279220, 48.195, 1758.0, 41.9285
33.422611420, 48.195, 1819.0, 42.6497
33.476943620, 48.195, 1774.0, 42.1189
33.531275820, 48.195, 1760.0, 41.9524
33.585608020, 48.195, 1734.0, 41.6413
33.639940220, 48.195, 1779.0, 42.1782
33.694272420, 48.195, 1877.0, 43.3244
33.748604620, 48.195, 1936.0, 44.0000
33.802936820, 48.195, 1820.0, 42.6615
33.857269020, 48.195, 1874.0, 43.2897
33.911601220, 48.195, 2040.0, 45.1664
33.965933420, 48.195, 2024.0, 44.9889
34.020265620, 48.195, 2054.0, 45.3211
34.074597820, 48.195, 2096.0, 45.7821
34.128930020, 48.195, 2052.0, 45.2990
34.183262220, 48.195, 2019.0, 44.9333
34.237594420, 48.195, 2060.0, 45.3872
34.291926620, 48.195, 1956.0, 44.2267
34.346258820, 48.195, 2113.0, 45.9674
34.400591020, 48.195, 1923.0, 43.8520
34.454923220, 48.195, 1944.0, 44.0908
34.509255420, 48.195, 1993.0, 44.6430
34.563587620, 48.195, 2055.0, 45.3321
34.617919820, 48.195, 2102.0, 45.8476
34.672252020, 48.195, 2221.0, 47.1275
34.726584220, 48.195, 2017.0, 44.9110
34.780916420, 48.195, 2227.0, 47.1911
34.835248620, 48.195, 2076.0, 45.5631
34.889580820, 48.195, 2131.0, 46.1628
34.943913020, 48.195, 2089.0, 45.7056
34.998245220, 48.195, 1958.0, 44.2493
35.052577420, 48.195, 2086.0, 45.6727
35.106909620, 48.195, 1974.0, 44.4297
35.161241820, 48.195, 1958.0, 44.2493
35.215574020, 48.195, 1906.0, 43.6578
35.269906220, 48.195, 1753.0, 41.8688
35.324238420, 48.195, 1796.0, 42.3792
35.378570620, 48.195, 1796.0, 42.3792
35.432902820, 48.195, 1730.0, 41.5933
35.487235020, 48.195, 1763.0, 41.9881
35.541567220, 48.195, 1767.0, 42.0357
35.595899420, 48.195, 1811.0, 42.5558
35.650231620, 48.195, 1720.0, 41.4729
35.704563820, 48.195, 1790.0, 42.3084
35.758896020, 48.195, 1874.0, 43.2897
35.813228220, 48.195, 1812.0, 42.5676
35.867560420, 48.195, 1826.0, 42.7317
35.921892620, 48.195, 1727.0, 41.5572
35.976224820, 48.195, 1854.0, 43.0581
36.030557020, 48.195, 1748.0, 41.8091
36.084889220, 48.195, 1793.0, 42.3438
36.139221420, 48.195, 1785.0, 42.2493
36.193553620, 48.195, 1815.0, 42.6028
36.247885820, 48.195, 1731.0, 41.6053
36.302218020, 48.195, 1875.0, 43.3013
36.356550220, 48.195, 1901.0, 43.6005
36.410882420, 48.195, 1980.0, 44.4972
36.465214620, 48.195, 1921.0, 43.8292
36.519546820, 48.195, 2011.0, 44.8442
36.573879020, 48.195, 1918.0, 43.7950
36.628211220, 48.195, 1976.0, 44.4522
36.682543420, 48.195, 1910.0, 43.7035
36.736875620, 48.195, 1914.0, 43.7493
36.791207820, 48.195, 1898.0, 43.5660
36.845540020, 48.195, 1786.0, 42.2611
36.899872220, 48.195, 1903.0, 43.6234
36.954204420, 48.195, 1841.0, 42.9069
37.008536620, 48.195, 1827.0, 42.7434
37.062868820, 48.195, 1893.0, 43.5086
37.117201020, 48.195, 1969.0, 44.3734
37.171533220, 48.195, 2101.0, 45.8367
37.225865420, 48.195, 2159.0, 46.4650
37.280197620, 48.195, 2415.0, 49.1426
37.334529820, 48.195, 2585.0, 50.8429
37.388862020, 48.195, 2648.0, 51.4587
37.443194220, 48.195, 2678.0, 51.7494
37.497526420, 48.195, 2606.0, 51.0490
37.551858620, 48.195, 2389.0, 48.8774
37.606190820, 48.195, 2339.0, 48.3632
37.660523020, 48.195, 2196.0, 46.8615
37.714855220, 48.195, 2036.0, 45.1221
37.769187420, 48.195, 2128.0, 46.1303
37.823519620, 48.195, 2102.0, 45.8476
37.877851820, 48.195, 2052.0, 45.2990
37.932184020, 48.195, 2062.0, 45.4093
37.986516220, 48.195, 2078.0, 45.5851
38.040848420, 48.195, 2252.0, 47.4552
38.095180620, 48.195, 2292.0, 47.8748
38.149512820, 48.195, 2341.0, 48.3839
38.203845020, 48.195, 2260.0, 47.5395
38.258177220, 48.195, 2199.0, 46.8935
38.312509420, 48.195, 2151.0, 46.3789
38.366841620, 48.195, 2051.0, 45.2880
38.421173820, 48.195, 1938.0, 44.0227
38.475506020, 48.195, 1931.0, 43.9431
38.529838220, 48.195, 2002.0, 44.7437
38.584170420, 48.195, 1857.0, 43.0929
38.638502620, 48.195, 1783.0, 42.2256
38.692834820, 48.195, 1834.0, 42.8252
38.747167020, 48.195, 1819.0, 42.6497
38.801499220, 48.195, 1764.0, 42.0000
38.855831420, 48.195, 1720.0, 41.4729
38.910163620, 48.195, 1709.0, 41.3401
38.964495820, 48.195, 1729.0, 41.5812
39.018828020, 48.195, 1737.0, 41.6773
39.073160220, 48.195, 1691.0, 41.1218
39.127492420, 48.195, 1728.0, 41.5692
39.181824620, 48.195, 1661.0, 40.7554
39.236156820, 48.195, 1682.0, 41.0122
39.290489020, 48.195, 1615.0, 40.1871
39.344821220, 48.195, 1651.0, 40.6325
39.399153420, 48.195, 1672.0, 40.8901
39.453485620, 48.195, 1629.0, 40.3609
39.507817820, 48.195, 1586.0, 39.8246
39.562150020, 48.195, 1766.0, 42.0238
39.616482220, 48.195, 1730.0, 41.5933
39.670814420, 48.195, 1860.0, 43.1277
39.725146620, 48.195, 1803.0, 42.4617
39.779478820, 48.195, 1709.0, 41.3401
39.833811020, 48.195, 1747.0, 41.7971
39.888143220, 48.195, 1662.0, 40.7676
39.942475420, 48.195, 1800.0, 42.4264
39.996807620, 48.195, 1765.0, 42.0119
40.051139820, 48.195, 1664.0, 40.7922
40.105472020, 48.195, 1791.0, 42.3202
40.159804220, 48.195, 1818.0, 42.6380
40.214136420, 48.195, 1767.0, 42.0357
40.268468620, 48.195, 1835.0, 42.8369
40.322800820, 48.195, 1842.0, 42.9185
40.377133020, 48.195, 1784.0, 42.2374
40.431465220, 48.195, 1707.0, 41.3159
40.485797420, 48.195, 1814.0, 42.5911
40.540129620, 48.195, 1802.0, 42.4500
40.594461820, 48.195, 1836.0, 42.8486
40.648794020, 48.195, 1832.0, 42.8019
40.703126220, 48.195, 1783.0, 42.2256
40.757458420, 48.195, 1787.0, 42.2729
40.811790620, 48.195, 1745.0, 41.7732
40.866122820, 48.195, 1729.0, 41.5812
40.920455020, 48.195, 1790.0, 42.3084
40.974787220, 48.195, 1796.0, 42.3792
41.029119420, 48.195, 1777.0, 42.1545
41.083451620, 48.195, 1841.0, 42.9069
41.137783820, 48.195, 1706.0, 41.3038
41.192116020, 48.195, 1716.0, 41.4246
41.246448220, 48.195, 1774.0, 42.1189
41.300780420, 48.195, 1664.0, 40.7922
41.355112620, 48.195, 1725.0, 41.5331
41.409444820, 48.195, 1692.0, 41.1339
41.463777020, 48.195, 1816.0, 42.6146
41.518109220, 48.195, 1825.0, 42.7200
41.572441420, 48.195, 1820.0, 42.6615
41.626773620, 48.195, 1866.0, 43.1972
41.681105820, 48.195, 1925.0, 43.8748
41.735438020, 48.195, 1900.0, 43.5890
41.789770220, 48.195, 1835.0, 42.8369
41.844102420, 48.195, 1866.0, 43.1972
41.898434620, 48.195, 1795.0, 42.3674
41.952766820, 48.195, 1774.0, 42.1189
42.007099020, 48.195, 1732.0, 41.6173
42.061431220, 48.195, 1816.0, 42.6146
42.115763420, 48.195, 1801.0, 42.4382
42.170095620, 48.195, 1853.0, 43.0465
42.224427820, 48.195, 1955.0, 44.2154
42.278760020, 48.195, 1909.0, 43.6921
42.333092220, 48.195, 1942.0, 44.0681
42.387424420, 48.195, 1928.0, 43.9090
42.441756620, 48.195, 1942.0, 44.0681
42.496088820, 48.195, 1943.0, 44.0795
42.550421020, 48.195, 1903.0, 43.6234
42.604753220, 48.195, 1833.0, 42.8135
42.659085420, 48.195, 1819.0, 42.6497
42.713417620, 48.195, 1862.0, 43.1509
42.767749820, 48.195, 1821.0, 42.6732
42.822082020, 48.195, 1803.0, 42.4617
42.876414220, 48.195, 1787.0, 42.2729
42.930746420, 48.195, 1758.0, 41.9285
42.985078620, 48.195, 1758.0, 41.9285
43.039410820, 48.195, 1803.0, 42.4617
43.093743020, 48.195, 1684.0, 41.0366
43.148075220, 48.195, 1670.0, 40.8656
43.202407420, 48.195, 1626.0, 40.3237
43.256739620, 48.195, 1556.0, 39.4462
43.311071820, 48.195, 1537.0, 39.2046
43.365404020, 48.195, 1568.0, 39.5980
43.419736220, 48.195, 1508.0, 38.8330
43.474068420, 48.195, 1569.0, 39.6106
43.528400620, 48.195, 1502.0, 38.7556
43.582732820, 48.195, 1539.0, 39.2301
43.637065020, 48.195, 1533.0, 39.1535
43.691397220, 48.195, 1538.0, 39.2173
43.745729420, 48.195, 1452.0, 38.1051
43.800061620, 48.195, 1521.0, 39.0000
43.854393820, 48.195, 1610.0, 40.1248
43.908726020, 48.195, 1564.0, 39.5474
43.963058220, 48.195, 1525.0, 39.0512
44.017390420, 48.195, 1496.0, 38.6782
44.071722620, 48.195, 1568.0, 39.5980
44.126054820, 48.195, 1579.0, 39.7366
44.180387020, 48.195, 1603.0, 40.0375
44.234719220, 48.195, 1509.0, 38.8458
44.289051420, 48.195, 1527.0, 39.0768
44.343383620, 48.195, 1689.0, 41.0974
44.397715820, 48.195, 1600.0, 40.0000
44.452048020, 48.195, 1580.0, 39.7492
44.506380220, 48.195, 1552.0, 39.3954
44.560712420, 48.195, 1531.0, 39.1280
44.615044620, 48.195, 1582.0, 39.7744
44.669376820, 48.195, 1584.0, 39.7995
44.723709020, 48.195, 1581.0, 39.7618
44.778041220, 48.195, 1552.0, 39.3954
44.832373420, 48.195, 1528.0, 39.0896
44.886705620, 48.195, 1555.0, 39.4335
44.941037820, 48.195, 1577.0, 39.7115
44.995370020, 48.195, 1569.0, 39.6106
45.049702220, 48.195, 1507.0, 38.8201
45.104034420, 48.195, 1443.0, 37.9868
45.158366620, 48.195, 1484.0, 38.5227
45.212698820, 48.195, 1460.0, 38.2099
45.267031020, 48.195, 1442.0, 37.9737
45.321363220, 48.195, 1475.0, 38.4057
45.375695420, 48.195, 1502.0, 38.7556
45.430027620, 48.195, 1454.0, 38.1314
45.484359820, 48.195, 1498.0, 38.7040
45.538692020, 48.195, 1580.0, 39.7492
45.593024220, 48.195, 1578.0, 39.7240
45.647356420, 48.195, 1504.0, 38.7814
45.701688620, 48.195, 1462.0, 38.2361
45.756020820, 48.195, 1469.0, 38.3275
45.810353020, 48.195, 1444.0, 38.0000
45.864685220, 48.195, 1403.0, 37.4566
45.919017420, 48.195, 1509.0, 38.8458
45.973349620, 48.195, 1388.0, 37.2559
46.027681820, 48.195, 1398.0, 37.3898
46.082014020, 48.195, 1381.0, 37.1618
46.136346220, 48.195, 1384.0, 37.2022
46.190678420, 48.195, 1413.0, 37.5899
46.245010620, 48.195, 1339.0, 36.5923
46.299342820, 48.195, 1428.0, 37.7889
46.353675020, 48.195, 1406.0, 37.4967
46.408007220, 48.195, 1495.0, 38.6652
46.462339420, 48.195, 1388.0, 37.2559
46.516671620, 48.195, 1390.0, 37.2827
46.571003820, 48.195, 1441.0, 37.9605
46.625336020, 48.195, 1436.0, 37.8946
46.679668220, 48.195, 1386.0, 37.2290
46.734000420, 48.195, 1383.0, 37.1887
46.788332620, 48.195, 1452.0, 38.1051
46.842664820, 48.195, 1367.0, 36.9730
46.896997020, 48.195, 1397.0, 37.3765
46.951329220, 48.195, 1384.0, 37.2022
47.005661420, 48.195, 1411.0, 37.5633
47.059993620, 48.195, 1464.0, 38.2623
47.114325820, 48.195, 1452.0, 38.1051
47.168658020, 48.195, 1402.0, 37.4433
47.222990220, 48.195, 1401.0, 37.4299
47.277322420, 48.195, 1430.0, 37.8153
47.331654620, 48.195, 1411.0, 37.5633
47.385986820, 48.195, 1361.0, 36.8917
47.440319020, 48.195, 1305.0, 36.1248
47.494651220, 48.195, 1362.0, 36.9053
47.548983420, 48.195, 1482.0, 38.4968
47.603315620, 48.195, 1343.0, 36.6470
47.657647820, 48.195, 1333.0, 36.5103
47.711980020, 48.195, 1340.0, 36.6060
47.766312220, 48.195, 1307.0, 36.1525
47.820644420, 48.195, 1335.0, 36.5377
47.874976620, 48.195, 1277.0, 35.7351
47.929308820, 48.195, 1290.0, 35.9166
47.983641020, 48.195, 1312.0, 36.2215
48.037973220, 48.195, 1254.0, 35.4119
48.092305420, 48.195, 1302.0, 36.0832
48.146637620, 48.195, 1315.0, 36.2629
48.200969820, 48.195, 1239.0, 35.1994
48.255302020, 48.195, 1352.0, 36.7696
48.309634220, 48.195, 1310.0, 36.1939
48.363966420, 48.195, 1297.0, 36.0139
48.418298620, 48.195, 1308.0, 36.1663
48.472630820, 48.195, 1270.0, 35.6371
48.526963020, 48.195, 1255.0, 35.4260
48.581295220, 48.195, 1321.0, 36.3456
48.635627420, 48.195, 1244.0, 35.2704
48.689959620, 48.195, 1189.0, 34.4819
48.744291820, 48.195, 1256.0, 35.4401
48.798624020, 48.195, 1196.0, 34.5832
48.852956220, 48.195, 1243.0, 35.2562
48.907288420, 48.195, 1333.0, 36.5103
48.961620620, 48.195, 1231.0, 35.0856
49.015952820, 48.195, 1221.0, 34.9428
49.070285020, 48.195, 1333.0, 36.5103
49.124617220, 48.195, 1335.0, 36.5377
49.178949420, 48.195, 1215.0, 34.8569
49.233281620, 48.195, 1323.0, 36.3731
49.287613820, 48.195, 1293.0, 35.9583
49.341946020, 48.195, 1204.0, 34.6987
49.396278220, 48.195, 1313.0, 36.2353
49.450610420, 48.195, 1167.0, 34.1614
49.504942620, 48.195, 1268.0, 35.6090
49.559274820, 48.195, 1218.0, 34.8999
49.613607020, 48.195, 1216.0, 34.8712
49.667939220, 48.195, 1266.0, 35.5809
49.722271420, 48.195, 1230.0, 35.0714
49.776603620, 48.195, 1303.0, 36.0971
49.830935820, 48.195, 1157.0, 34.0147
49.885268020, 48.195, 1226.0, 35.0143
49.939600220, 48.195, 1215.0, 34.8569
49.993932420, 48.195, 1296.0, 36.0000
50.048264620, 48.195, 1176.0, 34.2929
50.102596820, 48.195, 1210.0, 34.7851
50.156929020, 48.195, 1232.0, 35.0999
50.211261220, 48.195, 1188.0, 34.4674
50.265593420, 48.195, 1214.0, 34.8425
50.319925620, 48.195, 1192.0, 34.5254
50.374257820, 48.195, 1222.0, 34.9571
50.428590020, 48.195, 1204.0, 34.6987
50.482922220, 48.195, 1205.0, 34.7131
50.537254420, 48.195, 1137.0, 33.7194
50.591586620, 48.195, 1216.0, 34.8712
50.645918820, 48.195, 1220.0, 34.9285
50.700251020, 48.195, 1150.0, 33.9116
50.754583220, 48.195, 1235.0, 35.1426
50.808915420, 48.195, 1166.0, 34.1467
50.863247620, 48.195, 1212.0, 34.8138
50.917579820, 48.195, 1207.0, 34.7419
50.971912020, 48.195, 1208.0, 34.7563
51.026244220, 48.195, 1263.0, 35.5387
51.080576420, 48.195, 1176.0, 34.2929
51.134908620, 48.195, 1226.0, 35.0143
51.189240820, 48.195, 1169.0, 34.1906
51.243573020, 48.195, 1172.0, 34.2345
51.297905220, 48.195, 1158.0, 34.0294
51.352237420, 48.195, 1165.0, 34.1321
51.406569620, 48.195, 1198.0, 34.6121
51.460901820, 48.195, 1151.0, 33.9264
51.515234020, 48.195, 1156.0, 34.0000
51.569566220, 48.195, 1178.0, 34.3220
51.623898420, 48.195, 1239.0, 35.1994
51.678230620, 48.195, 1145.0, 33.8378
51.732562820, 48.195, 1233.0, 35.1141
51.786895020, 48.195, 1130.0, 33.6155
51.841227220, 48.195, 1157.0, 34.0147
51.895559420, 48.195, 1103.0, 33.2114
51.949891620, 48.195, 1109.0, 33.3017
52.004223820, 48.195, 1126.0, 33.5559
52.058556020, 48.195, 1074.0, 32.7719
52.112888220, 48.195, 1079.0, 32.8481
52.167220420, 48.195, 1122.0, 33.4963
52.221552620, 48.195, 1140.0, 33.7639
52.275884820, 48.195, 1103.0, 33.2114
52.330217020, 48.195, 1131.0, 33.6303
52.384549220, 48.195, 1144.0, 33.8231
52.438881420, 48.195, 1153.0, 33.9559
52.493213620, 48.195, 1176.0, 34.2929
52.547545820, 48.195, 1127.0, 33.5708
52.601878020, 48.195, 1187.0, 34.4529
52.656210220, 48.195, 1120.0, 33.4664
52.710542420, 48.195, 1135.0, 33.6898
52.764874620, 48.195, 1142.0, 33.7935
52.819206820, 48.195, 1081.0, 32.8786
52.873539020, 48.195, 1152.0, 33.9411
52.927871220, 48.195, 1080.0, 32.8634
52.982203420, 48.195, 1092.0, 33.0454
53.036535620, 48.195, 1057.0, 32.5115
53.090867820, 48.195, 1106.0, 33.2566
53.145200020, 48.195, 1106.0, 33.2566
53.199532220, 48.195, 1099.0, 33.1512
53.253864420, 48.195, 1060.0, 32.5576
53.308196620, 48.195, 1048.0, 32.3728
53.362528820, 48.195, 1057.0, 32.5115
53.416861020, 48.195, 1036.0, 32.1870
53.471193220, 48.195, 996.0, 31.5595
53.525525420, 48.195, 1021.0, 31.9531
53.579857620, 48.195, 1039.0, 32.2335
53.634189820, 48.195, 996.0, 31.5595
53.688522020, 48.195, 981.0, 31.3209
53.742854220, 48.195, 1087.0, 32.9697
53.797186420, 48.195, 1059.0, 32.5423
53.851518620, 48.195, 995.0, 31.5436
53.905850820, 48.195, 993.0, 31.5119
53.960183020, 48.195, 1053.0, 32.4500
54.014515220, 48.195, 990.0, 31.4643
54.068847420, 48.195, 991.0, 31.4802
54.123179620, 48.195, 1010.0, 31.7805
54.177511820, 48.195, 1000.0, 31.6228
54.231844020, 48.195, 1020.0, 31.9374
54.286176220, 48.195, 1027.0, 32.0468
54.340508420, 48.195, 1018.0, 31.9061
54.394840620, 48.195, 986.0, 31.4006
54.449172820, 48.195, 1058.0, 32.5269
54.503505020, 48.195, 1075.0, 32.7872
54.557837220, 48.195, 1070.0, 32.7109
54.612169420, 48.195, 1066.0, 32.6497
54.666501620, 48.195, 1038.0, 32.2180
54.720833820, 48.195, 1071.0, 32.7261
54.775166020, 48.195, 993.0, 31.5119
54.829498220, 48.195, 1057.0, 32.5115
54.883830420, 48.195, 991.0, 31.4802
54.938162620, 48.195, 976.0, 31.2410
54.992494820, 48.195, 992.0, 31.4960
55.046827020, 48.195, 964.0, 31.0483
55.101159220, 48.195, 954.0, 30.8869
55.155491420, 48.195, 923.0, 30.3809
55.209823620, 48.195, 900.0, 30.0000
55.264155820, 48.195, 956.0, 30.9192
55.318488020, 48.195, 945.0, 30.7409
55.372820220, 48.195, 967.0, 31.0966
55.427152420, 48.195, 945.0, 30.7409
55.481484620, 48.195, 904.0, 30.0666
55.535816820, 48.195, 932.0, 30.5287
55.590149020, 48.195, 958.0, 30.9516
55.644481220, 48.195, 948.0, 30.7896
55.698813420, 48.195, 1032.0, 32.1248
55.753145620, 48.195, 1007.0, 31.7333
55.807477820, 48.195, 1024.0, 32.0000
55.861810020, 48.195, 976.0, 31.2410
55.916142220, 48.195, 1033.0, 32.1403
55.970474420, 48.195, 1029.0, 32.0780
56.024806620, 48.195, 1020.0, 31.9374
56.079138820, 48.195, 1001.0, 31.6386
56.133471020, 48.195, 981.0, 31.3209
56.187803220, 48.195, 951.0, 30.8383
56.242135420, 48.195, 970.0, 31.1448
56.296467620, 48.195, 969.0, 31.1288
56.350799820, 48.195, 873.0, 29.5466
56.405132020, 48.195, 945.0, 30.7409
56.459464220, 48.195, 906.0, 30.0998
56.513796420, 48.195, 859.0, 29.3087
56.568128620, 48.195, 930.0, 30.4959
56.622460820, 48.195, 966.0, 31.0805
56.676793020, 48.195, 998.0, 31.5911
56.731125220, 48.195, 940.0, 30.6594
56.785457420, 48.195, 881.0, 29.6816
56.839789620, 48.195, 882.0, 29.6985
56.894121820, 48.195, 893.0, 29.8831
56.948454020, 48.195, 881.0, 29.6816
57.002786220, 48.195, 839.0, 28.9655
57.057118420, 48.195, 901.0, 30.0167
57.111450620, 48.195, 853.0, 29.2062
57.165782820, 48.195, 876.0, 29.5973
57.220115020, 48.195, 824.0, 28.7054
57.274447220, 48.195, 846.0, 29.0861
57.328779420, 48.195, 809.0, 28.4429
57.383111620, 48.195, 879.0, 29.6479
57.437443820, 48.195, 908.0, 30.1330
57.491776020, 48.195, 862.0, 29.3598
57.546108220, 48.195, 882.0, 29.6985
57.600440420, 48.195, 869.0, 29.4788
57.654772620, 48.195, 864.0, 29.3939
57.709104820, 48.195, 831.0, 28.8271
57.763437020, 48.195, 904.0, 30.0666
57.817769220, 48.195, 847.0, 29.1033
57.872101420, 48.195, 848.0, 29.1204
57.926433620, 48.195, 860.0, 29.3258
57.980765820, 48.195, 821.0, 28.6531
58.035098020, 48.195, 862.0, 29.3598
58.089430220, 48.195, 846.0, 29.0861
58.143762420, 48.195, 815.0, 28.5482
58.198094620, 48.195, 834.0, 28.8791
58.252426820, 48.195, 852.0, 29.1890
58.306759020, 48.195, 828.0, 28.7750
58.361091220, 48.195, 821.0, 28.6531
58.415423420, 48.195, 834.0, 28.8791
58.469755620, 48.195, 821.0, 28.6531
58.524087820, 48.195, 784.0, 28.0000
58.578420020, 48.195, 858.0, 29.2916
58.632752220, 48.195, 888.0, 29.7993
58.687084420, 48.195, 849.0, 29.1376
58.741416620, 48.195, 782.0, 27.9643
58.795748820, 48.195, 814.0, 28.5307
58.850081020, 48.195, 796.0, 28.2135
58.904413220, 48.195, 804.0, 28.3549
58.958745420, 48.195, 784.0, 28.0000
59.013077620, 48.195, 786.0, 28.0357
59.067409820, 48.195, 836.0, 28.9137
59.121742020, 48.195, 784.0, 28.0000
59.176074220, 48.195, 829.0, 28.7924
59.230406420, 48.195, 812.0, 28.4956
59.284738620, 48.195, 844.0, 29.0517
59.339070820, 48.195, 803.0, 28.3373
59.393403020, 48.195, 806.0, 28.3901
59.447735220, 48.195, 798.0, 28.2489
59.502067420, 48.195, 816.0, 28.5657
59.556399620, 48.195, 741.0, 27.2213
59.610731820, 48.195, 754.0, 27.4591
59.665064020, 48.195, 751.0, 27.4044
59.719396220, 48.195, 792.0, 28.1425
59.773728420, 48.195, 767.0, 27.6948
59.828060620, 48.195, 773.0, 27.8029
59.882392820, 48.195, 811.0, 28.4781
59.936725020, 48.195, 766.0, 27.6767
59.991057220, 48.195, 779.0, 27.9106
60.045389420, 48.195, 770.0, 27.7489
60.099721620, 48.195, 768.0, 27.7128
60.154053820, 48.195, 778.0, 27.8927
60.208386020, 48.195, 843.0, 29.0345
60.262718220, 48.195, 719.0, 26.8142
60.317050420, 48.195, 722.0, 26.8701
60.371382620, 48.195, 790.0, 28.1069
60.425714820, 48.195, 700.0, 26.4575
60.480047020, 48.195, 765.0, 27.6586
60.534379220, 48.195, 792.0, 28.1425
60.588711420, 48.195, 721.0, 26.8514
60.643043620, 48.195, 755.0, 27.4773
60.697375820, 48.195, 746.0, 27.3130
60.751708020, 48.195, 733.0, 27.0740
60.806040220, 48.195, 798.0, 28.2489
60.860372420, 48.195, 781.0, 27.9464
60.914704620, 48.195, 772.0, 27.7849
60.969036820, 48.195, 786.0, 28.0357
61.023369020, 48.195, 746.0, 27.3130
61.077701220, 48.195, 800.0, 28.2843
61.132033420, 48.195, 736.0, 27.1293
61.186365620, 48.195, 738.0, 27.1662
61.240697820, 48.195, 723.0, 26.8887
61.295030020, 48.195, 741.0, 27.2213
61.349362220, 48.195, 706.0, 26.5707
61.403694420, 48.195, 714.0, 26.7208
61.458026620, 48.195, 707.0, 26.5895
61.512358820, 48.195, 756.0, 27.4955
61.566691020, 48.195, 746.0, 27.3130
61.621023220, 48.195, 718.0, 26.7955
61.675355420, 48.195, 709.0, 26.6271
61.729687620, 48.195, 735.0, 27.1109
61.784019820, 48.195, 705.0, 26.5518
61.838352020, 48.195, 648.0, 25.4558
61.892684220, 48.195, 754.0, 27.4591
61.947016420, 48.195, 655.0, 25.5930
62.001348620, 48.195, 763.0, 27.6225
62.055680820, 48.195, 676.0, 26.0000
62.110013020, 48.195, 750.0, 27.3861
62.164345220, 48.195, 773.0, 27.8029
62.218677420, 48.195, 713.0, 26.7021
62.273009620, 48.195, 694.0, 26.3439
62.327341820, 48.195, 694.0, 26.3439
62.381674020, 48.195, 714.0, 26.7208
62.436006220, 48.195, 669.0, 25.8650
62.490338420, 48.195, 768.0, 27.7128
62.544670620, 48.195, 669.0, 25.8650
62.599002820, 48.195, 721.0, 26.8514
62.653335020, 48.195, 728.0, 26.9815
62.707667220, 48.195, 702.0, 26.4953
62.761999420, 48.195, 699.0, 26.4386
62.816331620, 48.195, 707.0, 26.5895
62.870663820, 48.195, 689.0, 26.2488
62.924996020, 48.195, 692.0, 26.3059
62.979328220, 48.195, 719.0, 26.8142
63.033660420, 48.195, 689.0, 26.2488
63.087992620, 48.195, 724.0, 26.9072
63.142324820, 48.195, 652.0, 25.5343
63.196657020, 48.195, 716.0, 26.7582
63.250989220, 48.195, 668.0, 25.8457
63.305321420, 48.195, 719.0, 26.8142
63.359653620, 48.195, 691.0, 26.2869
63.413985820, 48.195, 674.0, 25.9615
63.468318020, 48.195, 676.0, 26.0000
63.522650220, 48.195, 677.0, 26.0192
63.576982420, 48.195, 621.0, 24.9199
63.631314620, 48.195, 681.0, 26.0960
63.685646820, 48.195, 634.0, 25.1794
63.739979020, 48.195, 646.0, 25.4165
63.794311220, 48.195, 668.0, 25.8457
63.848643420, 48.195, 702.0, 26.4953
63.902975620, 48.195, 685.0, 26.1725
63.957307820, 48.195, 725.0, 26.9258
64.011640020, 48.195, 668.0, 25.8457
64.065972220, 48.195, 651.0, 25.5147
64.120304420, 48.195, 708.0, 26.6083
64.174636620, 48.195, 643.0, 25.3574
64.228968820, 48.195, 709.0, 26.6271
64.283301020, 48.195, 643.0, 25.3574
64.337633220, 48.195, 616.0, 24.8193
64.391965420, 48.195, 641.0, 25.3180
64.446297620, 48.195, 653.0, 25.5539
64.500629820, 48.195, 662.0, 25.7294
64.554962020, 48.195, 688.0, 26.2298
64.609294220, 48.195, 635.0, 25.1992
64.663626420, 48.195, 668.0, 25.8457
64.717958620, 48.195, 650.0, 25.4951
64.772290820, 48.195, 657.0, 25.6320
64.826623020, 48.195, 683.0, 26.1343
64.880955220, 48.195, 663.0, 25.7488
64.935287420, 48.195, 692.0, 26.3059
64.989619620, 48.195, 665.0, 25.7876
65.043951820, 48.195, 657.0, 25.6320
65.098284020, 48.195, 596.0, 24.4131
65.152616220, 48.195, 638.0, 25.2587
65.206948420, 48.195, 670.0, 25.8844
65.261280620, 48.195, 656.0, 25.6125
65.315612820, 48.195, 674.0, 25.9615
65.369945020, 48.195, 631.0, 25.1197
65.424277220, 48.195, 612.0, 24.7386
65.478609420, 48.195, 644.0, 25.3772
65.532941620, 48.195, 647.0, 25.4362
65.587273820, 48.195, 655.0, 25.5930
65.641606020, 48.195, 592.0, 24.3311
65.695938220, 48.195, 611.0, 24.7184
65.750270420, 48.195, 637.0, 25.2389
65.804602620, 48.195, 639.0, 25.2784
65.858934820, 48.195, 611.0, 24.7184
65.913267020, 48.195, 620.0, 24.8998
65.967599220, 48.195, 607.0, 24.6374
66.021931420, 48.195, 611.0, 24.7184
66.076263620, 48.195, 617.0, 24.8395
66.130595820, 48.195, 615.0, 24.7992
66.184928020, 48.195, 640.0, 25.2982
66.239260220, 48.195, 582.0, 24.1247
66.293592420, 48.195, 619.0, 24.8797
66.347924620, 48.195, 610.0, 24.6982
66.402256820, 48.195, 612.0, 24.7386
66.456589020, 48.195, 603.0, 24.5561
66.510921220, 48.195, 603.0, 24.5561
66.565253420, 48.195, 593.0, 24.3516
66.619585620, 48.195, 618.0, 24.8596
66.673917820, 48.195, 620.0, 24.8998
66.728250020, 48.195, 594.0, 24.3721
66.782582220, 48.195, 539.0, 23.2164
66.836914420, 48.195, 613.0, 24.7588
66.891246620, 48.195, 611.0, 24.7184
66.945578820, 48.195, 601.0, 24.5153
66.999911020, 48.195, 595.0, 24.3926
67.054243220, 48.195, 635.0, 25.1992
67.108575420, 48.195, 611.0, 24.7184
67.162907620, 48.195, 595.0, 24.3926
67.217239820, 48.195, 612.0, 24.7386
67.271572020, 48.195, 616.0, 24.8193
67.325904220, 48.195, 565.0, 23.7697
67.380236420, 48.195, 649.0, 25.4755
67.434568620, 48.195, 644.0, 25.3772
67.488900820, 48.195, 635.0, 25.1992
67.543233020, 48.195, 604.0, 24.5764
67.597565220, 48.195, 592.0, 24.3311
67.651897420, 48.195, 616.0, 24.8193
67.706229620, 48.195, 570.0, 23.8747
67.760561820, 48.195, 606.0, 24.6171
67.814894020, 48.195, 557.0, 23.6008
67.869226220, 48.195, 596.0, 24.4131
67.923558420, 48.195, 613.0, 24.7588
67.977890620, 48.195, 572.0, 23.9165
68.032222820, 48.195, 566.0, 23.7908
68.086555020, 48.195, 623.0, 24.9600
68.140887220, 48.195, 596.0, 24.4131
68.195219420, 48.195, 637.0, 25.2389
68.249551620, 48.195, 634.0, 25.1794
68.303883820, 48.195, 590.0, 24.2899
68.358216020, 48.195, 619.0, 24.8797
68.412548220, 48.195, 587.0, 24.2281
68.466880420, 48.195, 584.0, 24.1661
68.521212620, 48.195, 596.0, 24.4131
68.575544820, 48.195, 616.0, 24.8193
68.629877020, 48.195, 593.0, 24.3516
68.684209220, 48.195, 562.0, 23.7065
68.738541420, 48.195, 563.0, 23.7276
68.792873620, 48.195, 624.0, 24.9800
68.847205820, 48.195, 632.0, 25.1396
68.901538020, 48.195, 623.0, 24.9600
68.955870220, 48.195, 622.0, 24.9399
69.010202420, 48.195, 628.0, 25.0599
69.064534620, 48.195, 565.0, 23.7697
69.118866820, 48.195, 624.0, 24.9800
69.173199020, 48.195, 650.0, 25.4951
69.227531220, 48.195, 543.0, 23.3024
69.281863420, 48.195, 585.0, 24.1868
69.336195620, 48.195, 609.0, 24.6779
69.390527820, 48.195, 594.0, 24.3721
69.444860020, 48.195, 575.0, 23.9792
69.499192220, 48.195, 586.0, 24.2074
69.553524420, 48.195, 604.0, 24.5764
69.607856620, 48.195, 612.0, 24.7386
69.662188820, 48.195, 573.0, 23.9374
69.716521020, 48.195, 623.0, 24.9600
69.770853220, 48.195, 582.0, 24.1247
69.825185420, 48.195, 605.0, 24.5967
69.879517620, 48.195, 630.0, 25.0998
69.933849820, 48.195, 617.0, 24.8395
69.988182020, 48.195, 626.0, 25.0200
70.042514220, 48.195, 595.0, 24.3926
70.096846420, 48.195, 566.0, 23.7908
70.151178620, 48.195, 608.0, 24.6577
70.205510820, 48.195, 578.0, 24.0416
70.259843020, 48.195, 588.0, 24.2487
70.314175220, 48.195, 595.0, 24.3926
70.368507420, 48.195, 585.0, 24.1868
70.422839620, 48.195, 575.0, 23.9792
70.477171820, 48.195, 612.0, 24.7386
70.531504020, 48.195, 592.0, 24.3311
70.585836220, 48.195, 591.0, 24.3105
70.640168420, 48.195, 603.0, 24.5561
70.694500620, 48.195, 608.0, 24.6577
70.748832820, 48.195, 589.0, 24.2693
70.803165020, 48.195, 643.0, 25.3574
70.857497220, 48.195, 539.0, 23.2164
70.911829420, 48.195, 628.0, 25.0599
70.966161620, 48.195, 585.0, 24.1868
71.020493820, 48.195, 651.0, 25.5147
71.074826020, 48.195, 518.0, 22.7596
71.129158220, 48.195, 567.0, 23.8118
71.183490420, 48.195, 573.0, 23.9374
71.237822620, 48.195, 598.0, 24.4540
71.292154820, 48.195, 610.0, 24.6982
71.346487020, 48.195, 592.0, 24.3311
71.400819220, 48.195, 603.0, 24.5561
71.455151420, 48.195, 589.0, 24.2693
71.509483620, 48.195, 568.0, 23.8328
71.563815820, 48.195, 548.0, 23.4094
71.618148020, 48.195, 594.0, 24.3721
71.672480220, 48.195, 592.0, 24.3311
71.726812420, 48.195, 566.0, 23.7908
71.781144620, 48.195, 587.0, 24.2281
71.835476820, 48.195, 588.0, 24.2487
71.889809020, 48.195, 598.0, 24.4540
71.944141220, 48.195, 595.0, 24.3926
71.998473420, 48.195, 621.0, 24.9199
72.052805620, 48.195, 590.0, 24.2899
72.107137820, 48.195, 658.0, 25.6515
72.161470020, 48.195, 639.0, 25.2784
72.215802220, 48.195, 623.0, 24.9600
72.270134420, 48.195, 629.0, 25.0799
72.324466620, 48.195, 548.0, 23.4094
72.378798820, 48.195, 635.0, 25.1992
72.433131020, 48.195, 569.0, 23.8537
72.487463220, 48.195, 589.0, 24.2693
72.541795420, 48.195, 574.0, 23.9583
72.596127620, 48.195, 538.0, 23.1948
72.650459820, 48.195, 565.0, 23.7697
72.704792020, 48.195, 573.0, 23.9374
72.759124220, 48.195, 571.0, 23.8956
72.813456420, 48.195, 549.0, 23.4307
72.867788620, 48.195, 567.0, 23.8118
72.922120820, 48.195, 595.0, 24.3926
72.976453020, 48.195, 628.0, 25.0599
73.030785220, 48.195, 617.0, 24.8395
73.085117420, 48.195, 604.0, 24.5764
73.139449620, 48.195, 567.0, 23.8118
73.193781820, 48.195, 608.0, 24.6577
73.248114020, 48.195, 565.0, 23.7697
73.302446220, 48.195, 581.0, 24.1039
73.356778420, 48.195, 591.0, 24.3105
73.411110620, 48.195, 588.0, 24.2487
73.465442820, 48.195, 586.0, 24.2074
73.519775020, 48.195, 621.0, 24.9199
73.574107220, 48.195, 597.0, 24.4336
73.628439420, 48.195, 600.0, 24.4949
73.682771620, 48.195, 602.0, 24.5357
73.737103820, 48.195, 561.0, 23.6854
73.791436020, 48.195, 626.0, 25.0200
73.845768220, 48.195, 591.0, 24.3105
73.900100420, 48.195, 618.0, 24.8596
73.954432620, 48.195, 610.0, 24.6982
74.008764820, 48.195, 594.0, 24.3721
74.063097020, 48.195, 557.0, 23.6008
74.117429220, 48.195, 639.0, 25.2784
74.171761420, 48.195, 549.0, 23.4307
74.226093620, 48.195, 623.0, 24.9600
74.280425820, 48.195, 635.0, 25.1992
74.334758020, 48.195, 546.0, 23.3666
74.389090220, 48.195, 634.0, 25.1794
74.443422420, 48.195, 583.0, 24.1454
74.497754620, 48.195, 580.0, 24.0832
74.552086820, 48.195, 593.0, 24.3516
74.606419020, 48.195, 585.0, 24.1868
74.660751220, 48.195, 576.0, 24.0000
74.715083420, 48.195, 550.0, 23.4521
74.769415620, 48.195, 547.0, 23.3880
74.823747820, 48.195, 575.0, 23.9792
74.878080020, 48.195, 585.0, 24.1868
74.932412220, 48.195, 527.0, 22.9565
74.986744420, 48.195, 608.0, 24.6577
75.041076620, 48.195, 581.0, 24.1039
75.095408820, 48.195, 581.0, 24.1039
75.149741020, 48.195, 588.0, 24.2487
75.204073220, 48.195, 602.0, 24.5357
75.258405420, 48.195, 561.0, 23.6854
75.312737620, 48.195, 632.0, 25.1396
75.367069820, 48.195, 625.0, 25.0000
75.421402020, 48.195, 604.0, 24.5764
75.475734220, 48.195, 573.0, 23.9374
75.530066420, 48.195, 605.0, 24.5967
75.584398620, 48.195, 638.0, 25.2587
75.638730820, 48.195, 627.0, 25.0400
75.693063020, 48.195, 615.0, 24.7992
75.747395220, 48.195, 632.0, 25.1396
75.801727420, 48.195, 604.0, 24.5764
75.856059620, 48.195, 631.0, 25.1197
75.910391820, 48.195, 625.0, 25.0000
75.964724020, 48.195, 618.0, 24.8596
76.019056220, 48.195, 582.0, 24.1247
76.073388420, 48.195, 588.0, 24.2487
76.127720620, 48.195, 631.0, 25.1197
76.182052820, 48.195, 623.0, 24.9600
76.236385020, 48.195, 632.0, 25.1396
76.290717220, 48.195, 595.0, 24.3926
76.345049420, 48.195, 608.0, 24.6577
76.399381620, 48.195, 594.0, 24.3721
76.453713820, 48.195, 606.0, 24.6171
76.508046020, 48.195, 569.0, 23.8537
76.562378220, 48.195, 642.0, 25.3377
76.616710420, 48.195, 608.0, 24.6577
76.671042620, 48.195, 616.0, 24.8193
76.725374820, 48.195, 617.0, 24.8395
76.779707020, 48.195, 607.0, 24.6374
76.834039220, 48.195, 647.0, 25.4362
76.888371420, 48.195, 530.0, 23.0217
76.942703620, 48.195, 597.0, 24.4336
76.997035820, 48.195, 559.0, 23.6432
77.051368020, 48.195, 591.0, 24.3105
77.105700220, 48.195, 555.0, 23.5584
77.160032420, 48.195, 628.0, 25.0599
77.214364620, 48.195, 590.0, 24.2899
77.268696820, 48.195, 619.0, 24.8797
77.323029020, 48.195, 535.0, 23.1301
77.377361220, 48.195, 597.0, 24.4336
77.431693420, 48.195, 582.0, 24.1247
77.486025620, 48.195, 555.0, 23.5584
77.540357820, 48.195, 598.0, 24.4540
77.594690020, 48.195, 588.0, 24.2487
77.649022220, 48.195, 589.0, 24.2693
77.703354420, 48.195, 573.0, 23.9374
77.757686620, 48.195, 607.0, 24.6374
77.812018820, 48.195, 587.0, 24.2281
77.866351020, 48.195, 597.0, 24.4336
77.920683220, 48.195, 618.0, 24.8596
77.975015420, 48.195, 554.0, 23.5372
78.029347620, 48.195, 592.0, 24.3311
78.083679820, 48.195, 591.0, 24.3105
78.138012020, 48.195, 560.0, 23.6643
78.192344220, 48.195, 586.0, 24.2074
78.246676420, 48.195, 638.0, 25.2587
78.301008620, 48.195, 601.0, 24.5153
78.355340820, 48.195, 555.0, 23.5584
78.409673020, 48.195, 608.0, 24.6577
78.464005220, 48.195, 581.0, 24.1039
78.518337420, 48.195, 612.0, 24.7386
78.572669620, 48.195, 578.0, 24.0416
78.627001820, 48.195, 611.0, 24.7184
78.681334020, 48.195, 600.0, 24.4949
78.735666220, 48.195, 610.0, 24.6982
78.789998420, 48.195, 596.0, 24.4131
78.844330620, 48.195, 624.0, 24.9800
78.898662820, 48.195, 574.0, 23.9583
78.952995020, 48.195, 591.0, 24.3105
79.007327220, 48.195, 559.0, 23.6432
79.061659420, 48.195, 607.0, 24.6374
79.115991620, 48.195, 584.0, 24.1661
79.170323820, 48.195, 617.0, 24.8395
79.224656020, 48.195, 587.0, 24.2281
79.278988220, 48.195, 588.0, 24.2487
79.333320420, 48.195, 590.0, 24.2899
79.387652620, 48.195, 589.0, 24.2693
79.441984820, 48.195, 602.0, 24.5357
79.496317020, 48.195, 649.0, 25.4755
79.550649220, 48.195, 573.0, 23.9374
79.604981420, 48.195, 585.0, 24.1868
79.659313620, 48.195, 646.0, 25.4165
79.713645820, 48.195, 576.0, 24.0000
79.767978020, 48.195, 629.0, 25.0799
79.822310220, 48.195, 623.0, 24.9600
79.876642420, 48.195, 596.0, 24.4131
79.930974620, 48.195, 661.0, 25.7099
79.985306820, 48.195, 611.0, 24.7184
79.996173260, 48.195, 539.0, 23.2164