File: XRD/2025_06_03_CeO2_3_60_8min.csv
[Measurement conditions]
Sample identification,2025_06_03_CeO2_3_60_8min
Comment - 1,"CeO2 Standard"
Anode material,Cu
K-Alpha1 wavelength,1.5405980
K-Alpha2 wavelength,1.5444260
Ratio K-Alpha2/K-Alpha1,0.500
Divergence slit,Fixed,0.76mm
Monochromator used,NO
Generator voltage, 40
Tube current, 15
File date and time,03/Jun/2025 15:55
Unit cell,
h k l, 0 0 0
Scan axis,Gonio
Scan range,2.995000000,60.000344240
Scan step size,0.0108664
No. of points, 5246
Scan type,CONTINUOUS
Time per step,18.870
[Scan points]
Angle, TimePerStep, Intensity, ESD
3.000433220, 18.870, 43202.0, 207.8509
3.043898980, 18.870, 41514.0, 203.7498
3.087364740, 18.870, 39583.0, 198.9548
3.130830500, 18.870, 37539.0, 193.7498
3.174296260, 18.870, 35108.0, 187.3713
3.217762020, 18.870, 33261.0, 182.3760
3.261227780, 18.870, 31873.0, 178.5301
3.304693540, 18.870, 29490.0, 171.7265
3.348159300, 18.870, 27802.0, 166.7393
3.391625060, 18.870, 26600.0, 163.0951
3.435090820, 18.870, 24876.0, 157.7213
3.478556580, 18.870, 23531.0, 153.3982
3.522022340, 18.870, 22164.0, 148.8758
3.565488100, 18.870, 20593.0, 143.5026
3.608953860, 18.870, 19302.0, 138.9316
3.652419620, 18.870, 18385.0, 135.5913
3.695885380, 18.870, 17180.0, 131.0725
3.739351140, 18.870, 16067.0, 126.7557
3.782816900, 18.870, 15172.0, 123.1747
3.826282660, 18.870, 14079.0, 118.6550
3.869748420, 18.870, 13153.0, 114.6865
3.913214180, 18.870, 12026.0, 109.6631
3.956679940, 18.870, 11297.0, 106.2873
4.000145700, 18.870, 10488.0, 102.4109
4.043611460, 18.870, 9796.0, 98.9747
4.087077220, 18.870, 8929.0, 94.4934
4.130542980, 18.870, 8294.0, 91.0714
4.174008740, 18.870, 7656.0, 87.4986
4.217474500, 18.870, 7196.0, 84.8292
4.260940260, 18.870, 6610.0, 81.3019
4.304406020, 18.870, 5859.0, 76.5441
4.347871780, 18.870, 5633.0, 75.0533
4.391337540, 18.870, 5019.0, 70.8449
4.434803300, 18.870, 4694.0, 68.5128
4.478269060, 18.870, 4265.0, 65.3070
4.521734820, 18.870, 3931.0, 62.6977
4.565200580, 18.870, 3682.0, 60.6795
4.608666340, 18.870, 3254.0, 57.0438
4.652132100, 18.870, 3114.0, 55.8032
4.695597860, 18.870, 2823.0, 53.1319
4.739063620, 18.870, 2580.0, 50.7937
4.782529380, 18.870, 2442.0, 49.4166
4.825995140, 18.870, 2279.0, 47.7389
4.869460900, 18.870, 2214.0, 47.0532
4.912926660, 18.870, 2164.0, 46.5188
4.956392420, 18.870, 2131.0, 46.1628
4.999858180, 18.870, 1927.0, 43.8976
5.043323940, 18.870, 1976.0, 44.4522
5.086789700, 18.870, 1927.0, 43.8976
5.130255460, 18.870, 1956.0, 44.2267
5.173721220, 18.870, 1896.0, 43.5431
5.217186980, 18.870, 1909.0, 43.6921
5.260652740, 18.870, 1876.0, 43.3128
5.304118500, 18.870, 1917.0, 43.7836
5.347584260, 18.870, 1877.0, 43.3244
5.391050020, 18.870, 1793.0, 42.3438
5.434515780, 18.870, 1742.0, 41.7373
5.477981540, 18.870, 1566.0, 39.5727
5.521447300, 18.870, 1458.0, 38.1838
5.564913060, 18.870, 1442.0, 37.9737
5.608378820, 18.870, 1296.0, 36.0000
5.651844580, 18.870, 1118.0, 33.4365
5.695310340, 18.870, 1137.0, 33.7194
5.738776100, 18.870, 1026.0, 32.0312
5.782241860, 18.870, 1031.0, 32.1092
5.825707620, 18.870, 963.0, 31.0322
5.869173380, 18.870, 964.0, 31.0483
5.912639140, 18.870, 950.0, 30.8221
5.956104900, 18.870, 955.0, 30.9031
5.999570660, 18.870, 898.0, 29.9666
6.043036420, 18.870, 899.0, 29.9833
6.086502180, 18.870, 788.0, 28.0713
6.129967940, 18.870, 827.0, 28.7576
6.173433700, 18.870, 775.0, 27.8388
6.216899460, 18.870, 822.0, 28.6705
6.260365220, 18.870, 756.0, 27.4955
6.303830980, 18.870, 707.0, 26.5895
6.347296740, 18.870, 723.0, 26.8887
6.390762500, 18.870, 686.0, 26.1916
6.434228260, 18.870, 674.0, 25.9615
6.477694020, 18.870, 639.0, 25.2784
6.521159780, 18.870, 675.0, 25.9808
6.564625540, 18.870, 624.0, 24.9800
6.608091300, 18.870, 618.0, 24.8596
6.651557060, 18.870, 663.0, 25.7488
6.695022820, 18.870, 623.0, 24.9600
6.738488580, 18.870, 564.0, 23.7487
6.781954340, 18.870, 532.0, 23.0651
6.825420100, 18.870, 499.0, 22.3383
6.868885860, 18.870, 525.0, 22.9129
6.912351620, 18.870, 515.0, 22.6936
6.955817380, 18.870, 465.0, 21.5639
6.999283140, 18.870, 429.0, 20.7123
7.042748900, 18.870, 487.0, 22.0681
7.086214660, 18.870, 459.0, 21.4243
7.129680420, 18.870, 482.0, 21.9545
7.173146180, 18.870, 463.0, 21.5174
7.216611940, 18.870, 392.0, 19.7990
7.260077700, 18.870, 466.0, 21.5870
7.303543460, 18.870, 390.0, 19.7484
7.347009220, 18.870, 412.0, 20.2978
7.390474980, 18.870, 437.0, 20.9045
7.433940740, 18.870, 390.0, 19.7484
7.477406500, 18.870, 399.0, 19.9750
7.520872260, 18.870, 407.0, 20.1742
7.564338020, 18.870, 382.0, 19.5448
7.607803780, 18.870, 372.0, 19.2873
7.651269540, 18.870, 377.0, 19.4165
7.694735300, 18.870, 373.0, 19.3132
7.738201060, 18.870, 351.0, 18.7350
7.781666820, 18.870, 345.0, 18.5742
7.825132580, 18.870, 350.0, 18.7083
7.868598340, 18.870, 311.0, 17.6352
7.912064100, 18.870, 369.0, 19.2094
7.955529860, 18.870, 362.0, 19.0263
7.998995620, 18.870, 377.0, 19.4165
8.042461380, 18.870, 337.0, 18.3576
8.085927140, 18.870, 342.0, 18.4932
8.129392900, 18.870, 368.0, 19.1833
8.172858660, 18.870, 334.0, 18.2757
8.216324420, 18.870, 385.0, 19.6214
8.259790180, 18.870, 318.0, 17.8326
8.303255940, 18.870, 312.0, 17.6635
8.346721700, 18.870, 383.0, 19.5704
8.390187460, 18.870, 340.0, 18.4391
8.433653220, 18.870, 303.0, 17.4069
8.477118980, 18.870, 353.0, 18.7883
8.520584740, 18.870, 295.0, 17.1756
8.564050500, 18.870, 335.0, 18.3030
8.607516260, 18.870, 301.0, 17.3494
8.650982020, 18.870, 320.0, 17.8885
8.694447780, 18.870, 319.0, 17.8606
8.737913540, 18.870, 292.0, 17.0880
8.781379300, 18.870, 329.0, 18.1384
8.824845060, 18.870, 297.0, 17.2337
8.868310820, 18.870, 314.0, 17.7200
8.911776580, 18.870, 309.0, 17.5784
8.955242340, 18.870, 326.0, 18.0555
8.998708100, 18.870, 349.0, 18.6815
9.042173860, 18.870, 327.0, 18.0831
9.085639620, 18.870, 310.0, 17.6068
9.129105380, 18.870, 333.0, 18.2483
9.172571140, 18.870, 280.0, 16.7332
9.216036900, 18.870, 313.0, 17.6918
9.259502660, 18.870, 296.0, 17.2047
9.302968420, 18.870, 307.0, 17.5214
9.346434180, 18.870, 295.0, 17.1756
9.389899940, 18.870, 296.0, 17.2047
9.433365700, 18.870, 315.0, 17.7482
9.476831460, 18.870, 342.0, 18.4932
9.520297220, 18.870, 282.0, 16.7929
9.563762980, 18.870, 371.0, 19.2614
9.607228740, 18.870, 298.0, 17.2627
9.650694500, 18.870, 301.0, 17.3494
9.694160260, 18.870, 329.0, 18.1384
9.737626020, 18.870, 335.0, 18.3030
9.781091780, 18.870, 313.0, 17.6918
9.824557540, 18.870, 309.0, 17.5784
9.868023300, 18.870, 356.0, 18.8680
9.911489060, 18.870, 285.0, 16.8819
9.954954820, 18.870, 344.0, 18.5472
9.998420580, 18.870, 343.0, 18.5203
10.041886340, 18.870, 350.0, 18.7083
10.085352100, 18.870, 326.0, 18.0555
10.128817860, 18.870, 320.0, 17.8885
10.172283620, 18.870, 346.0, 18.6011
10.215749380, 18.870, 325.0, 18.0278
10.259215140, 18.870, 316.0, 17.7764
10.302680900, 18.870, 323.0, 17.9722
10.346146660, 18.870, 298.0, 17.2627
10.389612420, 18.870, 330.0, 18.1659
10.433078180, 18.870, 338.0, 18.3848
10.476543940, 18.870, 332.0, 18.2209
10.520009700, 18.870, 339.0, 18.4120
10.563475460, 18.870, 301.0, 17.3494
10.606941220, 18.870, 329.0, 18.1384
10.650406980, 18.870, 339.0, 18.4120
10.693872740, 18.870, 301.0, 17.3494
10.737338500, 18.870, 319.0, 17.8606
10.780804260, 18.870, 332.0, 18.2209
10.824270020, 18.870, 297.0, 17.2337
10.867735780, 18.870, 319.0, 17.8606
10.911201540, 18.870, 307.0, 17.5214
10.954667300, 18.870, 345.0, 18.5742
10.998133060, 18.870, 323.0, 17.9722
11.041598820, 18.870, 340.0, 18.4391
11.085064580, 18.870, 328.0, 18.1108
11.128530340, 18.870, 293.0, 17.1172
11.171996100, 18.870, 319.0, 17.8606
11.215461860, 18.870, 301.0, 17.3494
11.258927620, 18.870, 342.0, 18.4932
11.302393380, 18.870, 315.0, 17.7482
11.345859140, 18.870, 335.0, 18.3030
11.389324900, 18.870, 320.0, 17.8885
11.432790660, 18.870, 352.0, 18.7617
11.476256420, 18.870, 343.0, 18.5203
11.519722180, 18.870, 329.0, 18.1384
11.563187940, 18.870, 340.0, 18.4391
11.606653700, 18.870, 328.0, 18.1108
11.650119460, 18.870, 344.0, 18.5472
11.693585220, 18.870, 343.0, 18.5203
11.737050980, 18.870, 333.0, 18.2483
11.780516740, 18.870, 351.0, 18.7350
11.823982500, 18.870, 375.0, 19.3649
11.867448260, 18.870, 383.0, 19.5704
11.910914020, 18.870, 300.0, 17.3205
11.954379780, 18.870, 329.0, 18.1384
11.997845540, 18.870, 318.0, 17.8326
12.041311300, 18.870, 341.0, 18.4662
12.084777060, 18.870, 299.0, 17.2916
12.128242820, 18.870, 363.0, 19.0526
12.171708580, 18.870, 319.0, 17.8606
12.215174340, 18.870, 376.0, 19.3907
12.258640100, 18.870, 306.0, 17.4929
12.302105860, 18.870, 379.0, 19.4679
12.345571620, 18.870, 324.0, 18.0000
12.389037380, 18.870, 332.0, 18.2209
12.432503140, 18.870, 332.0, 18.2209
12.475968900, 18.870, 334.0, 18.2757
12.519434660, 18.870, 336.0, 18.3303
12.562900420, 18.870, 333.0, 18.2483
12.606366180, 18.870, 338.0, 18.3848
12.649831940, 18.870, 324.0, 18.0000
12.693297700, 18.870, 333.0, 18.2483
12.736763460, 18.870, 326.0, 18.0555
12.780229220, 18.870, 320.0, 17.8885
12.823694980, 18.870, 338.0, 18.3848
12.867160740, 18.870, 315.0, 17.7482
12.910626500, 18.870, 355.0, 18.8414
12.954092260, 18.870, 323.0, 17.9722
12.997558020, 18.870, 335.0, 18.3030
13.041023780, 18.870, 318.0, 17.8326
13.084489540, 18.870, 325.0, 18.0278
13.127955300, 18.870, 341.0, 18.4662
13.171421060, 18.870, 307.0, 17.5214
13.214886820, 18.870, 317.0, 17.8045
13.258352580, 18.870, 350.0, 18.7083
13.301818340, 18.870, 343.0, 18.5203
13.345284100, 18.870, 329.0, 18.1384
13.388749860, 18.870, 325.0, 18.0278
13.432215620, 18.870, 376.0, 19.3907
13.475681380, 18.870, 328.0, 18.1108
13.519147140, 18.870, 327.0, 18.0831
13.562612900, 18.870, 305.0, 17.4642
13.606078660, 18.870, 352.0, 18.7617
13.649544420, 18.870, 356.0, 18.8680
13.693010180, 18.870, 335.0, 18.3030
13.736475940, 18.870, 384.0, 19.5959
13.779941700, 18.870, 349.0, 18.6815
13.823407460, 18.870, 304.0, 17.4356
13.866873220, 18.870, 343.0, 18.5203
13.910338980, 18.870, 336.0, 18.3303
13.953804740, 18.870, 304.0, 17.4356
13.997270500, 18.870, 344.0, 18.5472
14.040736260, 18.870, 359.0, 18.9473
14.084202020, 18.870, 347.0, 18.6279
14.127667780, 18.870, 311.0, 17.6352
14.171133540, 18.870, 307.0, 17.5214
14.214599300, 18.870, 315.0, 17.7482
14.258065060, 18.870, 358.0, 18.9209
14.301530820, 18.870, 327.0, 18.0831
14.344996580, 18.870, 319.0, 17.8606
14.388462340, 18.870, 315.0, 17.7482
14.431928100, 18.870, 311.0, 17.6352
14.475393860, 18.870, 342.0, 18.4932
14.518859620, 18.870, 321.0, 17.9165
14.562325380, 18.870, 320.0, 17.8885
14.605791140, 18.870, 331.0, 18.1934
14.649256900, 18.870, 321.0, 17.9165
14.692722660, 18.870, 315.0, 17.7482
14.736188420, 18.870, 324.0, 18.0000
14.779654180, 18.870, 329.0, 18.1384
14.823119940, 18.870, 336.0, 18.3303
14.866585700, 18.870, 333.0, 18.2483
14.910051460, 18.870, 342.0, 18.4932
14.953517220, 18.870, 320.0, 17.8885
14.996982980, 18.870, 343.0, 18.5203
15.040448740, 18.870, 320.0, 17.8885
15.083914500, 18.870, 304.0, 17.4356
15.127380260, 18.870, 324.0, 18.0000
15.170846020, 18.870, 315.0, 17.7482
15.214311780, 18.870, 315.0, 17.7482
15.257777540, 18.870, 334.0, 18.2757
15.301243300, 18.870, 310.0, 17.6068
15.344709060, 18.870, 334.0, 18.2757
15.388174820, 18.870, 292.0, 17.0880
15.431640580, 18.870, 308.0, 17.5499
15.475106340, 18.870, 304.0, 17.4356
15.518572100, 18.870, 331.0, 18.1934
15.562037860, 18.870, 347.0, 18.6279
15.605503620, 18.870, 299.0, 17.2916
15.648969380, 18.870, 304.0, 17.4356
15.692435140, 18.870, 324.0, 18.0000
15.735900900, 18.870, 301.0, 17.3494
15.779366660, 18.870, 319.0, 17.8606
15.822832420, 18.870, 334.0, 18.2757
15.866298180, 18.870, 323.0, 17.9722
15.909763940, 18.870, 312.0, 17.6635
15.953229700, 18.870, 311.0, 17.6352
15.996695460, 18.870, 299.0, 17.2916
16.040161220, 18.870, 304.0, 17.4356
16.083626980, 18.870, 323.0, 17.9722
16.127092740, 18.870, 310.0, 17.6068
16.170558500, 18.870, 301.0, 17.3494
16.214024260, 18.870, 310.0, 17.6068
16.257490020, 18.870, 306.0, 17.4929
16.300955780, 18.870, 344.0, 18.5472
16.344421540, 18.870, 321.0, 17.9165
16.387887300, 18.870, 329.0, 18.1384
16.431353060, 18.870, 353.0, 18.7883
16.474818820, 18.870, 330.0, 18.1659
16.518284580, 18.870, 322.0, 17.9444
16.561750340, 18.870, 319.0, 17.8606
16.605216100, 18.870, 322.0, 17.9444
16.648681860, 18.870, 308.0, 17.5499
16.692147620, 18.870, 345.0, 18.5742
16.735613380, 18.870, 325.0, 18.0278
16.779079140, 18.870, 313.0, 17.6918
16.822544900, 18.870, 339.0, 18.4120
16.866010660, 18.870, 267.0, 16.3401
16.909476420, 18.870, 319.0, 17.8606
16.952942180, 18.870, 316.0, 17.7764
16.996407940, 18.870, 338.0, 18.3848
17.039873700, 18.870, 299.0, 17.2916
17.083339460, 18.870, 312.0, 17.6635
17.126805220, 18.870, 328.0, 18.1108
17.170270980, 18.870, 297.0, 17.2337
17.213736740, 18.870, 299.0, 17.2916
17.257202500, 18.870, 326.0, 18.0555
17.300668260, 18.870, 279.0, 16.7033
17.344134020, 18.870, 330.0, 18.1659
17.387599780, 18.870, 336.0, 18.3303
17.431065540, 18.870, 317.0, 17.8045
17.474531300, 18.870, 318.0, 17.8326
17.517997060, 18.870, 282.0, 16.7929
17.561462820, 18.870, 318.0, 17.8326
17.604928580, 18.870, 337.0, 18.3576
17.648394340, 18.870, 293.0, 17.1172
17.691860100, 18.870, 319.0, 17.8606
17.735325860, 18.870, 293.0, 17.1172
17.778791620, 18.870, 334.0, 18.2757
17.822257380, 18.870, 314.0, 17.7200
17.865723140, 18.870, 271.0, 16.4621
17.909188900, 18.870, 318.0, 17.8326
17.952654660, 18.870, 314.0, 17.7200
17.996120420, 18.870, 318.0, 17.8326
18.039586180, 18.870, 304.0, 17.4356
18.083051940, 18.870, 279.0, 16.7033
18.126517700, 18.870, 315.0, 17.7482
18.169983460, 18.870, 322.0, 17.9444
18.213449220, 18.870, 331.0, 18.1934
18.256914980, 18.870, 307.0, 17.5214
18.300380740, 18.870, 301.0, 17.3494
18.343846500, 18.870, 280.0, 16.7332
18.387312260, 18.870, 285.0, 16.8819
18.430778020, 18.870, 320.0, 17.8885
18.474243780, 18.870, 322.0, 17.9444
18.517709540, 18.870, 298.0, 17.2627
18.561175300, 18.870, 318.0, 17.8326
18.604641060, 18.870, 344.0, 18.5472
18.648106820, 18.870, 302.0, 17.3781
18.691572580, 18.870, 312.0, 17.6635
18.735038340, 18.870, 317.0, 17.8045
18.778504100, 18.870, 305.0, 17.4642
18.821969860, 18.870, 301.0, 17.3494
18.865435620, 18.870, 314.0, 17.7200
18.908901380, 18.870, 294.0, 17.1464
18.952367140, 18.870, 305.0, 17.4642
18.995832900, 18.870, 284.0, 16.8523
19.039298660, 18.870, 326.0, 18.0555
19.082764420, 18.870, 317.0, 17.8045
19.126230180, 18.870, 279.0, 16.7033
19.169695940, 18.870, 298.0, 17.2627
19.213161700, 18.870, 291.0, 17.0587
19.256627460, 18.870, 305.0, 17.4642
19.300093220, 18.870, 328.0, 18.1108
19.343558980, 18.870, 292.0, 17.0880
19.387024740, 18.870, 297.0, 17.2337
19.430490500, 18.870, 315.0, 17.7482
19.473956260, 18.870, 323.0, 17.9722
19.517422020, 18.870, 274.0, 16.5529
19.560887780, 18.870, 330.0, 18.1659
19.604353540, 18.870, 271.0, 16.4621
19.647819300, 18.870, 284.0, 16.8523
19.691285060, 18.870, 324.0, 18.0000
19.734750820, 18.870, 298.0, 17.2627
19.778216580, 18.870, 310.0, 17.6068
19.821682340, 18.870, 279.0, 16.7033
19.865148100, 18.870, 276.0, 16.6132
19.908613860, 18.870, 303.0, 17.4069
19.952079620, 18.870, 306.0, 17.4929
19.995545380, 18.870, 270.0, 16.4317
20.039011140, 18.870, 278.0, 16.6733
20.082476900, 18.870, 291.0, 17.0587
20.125942660, 18.870, 307.0, 17.5214
20.169408420, 18.870, 277.0, 16.6433
20.212874180, 18.870, 296.0, 17.2047
20.256339940, 18.870, 307.0, 17.5214
20.299805700, 18.870, 312.0, 17.6635
20.343271460, 18.870, 333.0, 18.2483
20.386737220, 18.870, 292.0, 17.0880
20.430202980, 18.870, 288.0, 16.9706
20.473668740, 18.870, 319.0, 17.8606
20.517134500, 18.870, 303.0, 17.4069
20.560600260, 18.870, 305.0, 17.4642
20.604066020, 18.870, 341.0, 18.4662
20.647531780, 18.870, 286.0, 16.9115
20.690997540, 18.870, 302.0, 17.3781
20.734463300, 18.870, 274.0, 16.5529
20.777929060, 18.870, 282.0, 16.7929
20.821394820, 18.870, 280.0, 16.7332
20.864860580, 18.870, 282.0, 16.7929
20.908326340, 18.870, 277.0, 16.6433
20.951792100, 18.870, 271.0, 16.4621
20.995257860, 18.870, 299.0, 17.2916
21.038723620, 18.870, 294.0, 17.1464
21.082189380, 18.870, 321.0, 17.9165
21.125655140, 18.870, 269.0, 16.4012
21.169120900, 18.870, 302.0, 17.3781
21.212586660, 18.870, 288.0, 16.9706
21.256052420, 18.870, 318.0, 17.8326
21.299518180, 18.870, 279.0, 16.7033
21.342983940, 18.870, 250.0, 15.8114
21.386449700, 18.870, 312.0, 17.6635
21.429915460, 18.870, 303.0, 17.4069
21.473381220, 18.870, 296.0, 17.2047
21.516846980, 18.870, 268.0, 16.3707
21.560312740, 18.870, 281.0, 16.7631
21.603778500, 18.870, 265.0, 16.2788
21.647244260, 18.870, 276.0, 16.6132
21.690710020, 18.870, 295.0, 17.1756
21.734175780, 18.870, 303.0, 17.4069
21.777641540, 18.870, 283.0, 16.8226
21.821107300, 18.870, 326.0, 18.0555
21.864573060, 18.870, 278.0, 16.6733
21.908038820, 18.870, 270.0, 16.4317
21.951504580, 18.870, 314.0, 17.7200
21.994970340, 18.870, 282.0, 16.7929
22.038436100, 18.870, 273.0, 16.5227
22.081901860, 18.870, 301.0, 17.3494
22.125367620, 18.870, 274.0, 16.5529
22.168833380, 18.870, 284.0, 16.8523
22.212299140, 18.870, 304.0, 17.4356
22.255764900, 18.870, 291.0, 17.0587
22.299230660, 18.870, 313.0, 17.6918
22.342696420, 18.870, 292.0, 17.0880
22.386162180, 18.870, 282.0, 16.7929
22.429627940, 18.870, 313.0, 17.6918
22.473093700, 18.870, 279.0, 16.7033
22.516559460, 18.870, 292.0, 17.0880
22.560025220, 18.870, 278.0, 16.6733
22.603490980, 18.870, 324.0, 18.0000
22.646956740, 18.870, 280.0, 16.7332
22.690422500, 18.870, 308.0, 17.5499
22.733888260, 18.870, 306.0, 17.4929
22.777354020, 18.870, 257.0, 16.0312
22.820819780, 18.870, 279.0, 16.7033
22.864285540, 18.870, 285.0, 16.8819
22.907751300, 18.870, 293.0, 17.1172
22.951217060, 18.870, 298.0, 17.2627
22.994682820, 18.870, 286.0, 16.9115
23.038148580, 18.870, 311.0, 17.6352
23.081614340, 18.870, 281.0, 16.7631
23.125080100, 18.870, 279.0, 16.7033
23.168545860, 18.870, 273.0, 16.5227
23.212011620, 18.870, 280.0, 16.7332
23.255477380, 18.870, 274.0, 16.5529
23.298943140, 18.870, 317.0, 17.8045
23.342408900, 18.870, 274.0, 16.5529
23.385874660, 18.870, 361.0, 19.0000
23.429340420, 18.870, 291.0, 17.0587
23.472806180, 18.870, 303.0, 17.4069
23.516271940, 18.870, 301.0, 17.3494
23.559737700, 18.870, 274.0, 16.5529
23.603203460, 18.870, 259.0, 16.0935
23.646669220, 18.870, 289.0, 17.0000
23.690134980, 18.870, 294.0, 17.1464
23.733600740, 18.870, 285.0, 16.8819
23.777066500, 18.870, 288.0, 16.9706
23.820532260, 18.870, 286.0, 16.9115
23.863998020, 18.870, 313.0, 17.6918
23.907463780, 18.870, 296.0, 17.2047
23.950929540, 18.870, 282.0, 16.7929
23.994395300, 18.870, 282.0, 16.7929
24.037861060, 18.870, 274.0, 16.5529
24.081326820, 18.870, 281.0, 16.7631
24.124792580, 18.870, 247.0, 15.7162
24.168258340, 18.870, 299.0, 17.2916
24.211724100, 18.870, 269.0, 16.4012
24.255189860, 18.870, 271.0, 16.4621
24.298655620, 18.870, 267.0, 16.3401
24.342121380, 18.870, 264.0, 16.2481
24.385587140, 18.870, 271.0, 16.4621
24.429052900, 18.870, 260.0, 16.1245
24.472518660, 18.870, 277.0, 16.6433
24.515984420, 18.870, 287.0, 16.9411
24.559450180, 18.870, 227.0, 15.0665
24.602915940, 18.870, 291.0, 17.0587
24.646381700, 18.870, 235.0, 15.3297
24.689847460, 18.870, 290.0, 17.0294
24.733313220, 18.870, 266.0, 16.3095
24.776778980, 18.870, 261.0, 16.1555
24.820244740, 18.870, 269.0, 16.4012
24.863710500, 18.870, 265.0, 16.2788
24.907176260, 18.870, 272.0, 16.4924
24.950642020, 18.870, 264.0, 16.2481
24.994107780, 18.870, 281.0, 16.7631
25.037573540, 18.870, 303.0, 17.4069
25.081039300, 18.870, 232.0, 15.2315
25.124505060, 18.870, 275.0, 16.5831
25.167970820, 18.870, 276.0, 16.6132
25.211436580, 18.870, 272.0, 16.4924
25.254902340, 18.870, 287.0, 16.9411
25.298368100, 18.870, 261.0, 16.1555
25.341833860, 18.870, 287.0, 16.9411
25.385299620, 18.870, 282.0, 16.7929
25.428765380, 18.870, 294.0, 17.1464
25.472231140, 18.870, 262.0, 16.1864
25.515696900, 18.870, 295.0, 17.1756
25.559162660, 18.870, 285.0, 16.8819
25.602628420, 18.870, 259.0, 16.0935
25.646094180, 18.870, 290.0, 17.0294
25.689559940, 18.870, 298.0, 17.2627
25.733025700, 18.870, 320.0, 17.8885
25.776491460, 18.870, 304.0, 17.4356
25.819957220, 18.870, 330.0, 18.1659
25.863422980, 18.870, 326.0, 18.0555
25.906888740, 18.870, 306.0, 17.4929
25.950354500, 18.870, 236.0, 15.3623
25.993820260, 18.870, 314.0, 17.7200
26.037286020, 18.870, 276.0, 16.6132
26.080751780, 18.870, 248.0, 15.7480
26.124217540, 18.870, 282.0, 16.7929
26.167683300, 18.870, 259.0, 16.0935
26.211149060, 18.870, 265.0, 16.2788
26.254614820, 18.870, 277.0, 16.6433
26.298080580, 18.870, 247.0, 15.7162
26.341546340, 18.870, 304.0, 17.4356
26.385012100, 18.870, 296.0, 17.2047
26.428477860, 18.870, 305.0, 17.4642
26.471943620, 18.870, 308.0, 17.5499
26.515409380, 18.870, 263.0, 16.2173
26.558875140, 18.870, 261.0, 16.1555
26.602340900, 18.870, 268.0, 16.3707
26.645806660, 18.870, 303.0, 17.4069
26.689272420, 18.870, 275.0, 16.5831
26.732738180, 18.870, 270.0, 16.4317
26.776203940, 18.870, 277.0, 16.6433
26.819669700, 18.870, 261.0, 16.1555
26.863135460, 18.870, 263.0, 16.2173
26.906601220, 18.870, 269.0, 16.4012
26.950066980, 18.870, 280.0, 16.7332
26.993532740, 18.870, 268.0, 16.3707
27.036998500, 18.870, 259.0, 16.0935
27.080464260, 18.870, 279.0, 16.7033
27.123930020, 18.870, 278.0, 16.6733
27.167395780, 18.870, 272.0, 16.4924
27.210861540, 18.870, 299.0, 17.2916
27.254327300, 18.870, 282.0, 16.7929
27.297793060, 18.870, 284.0, 16.8523
27.341258820, 18.870, 264.0, 16.2481
27.384724580, 18.870, 284.0, 16.8523
27.428190340, 18.870, 283.0, 16.8226
27.471656100, 18.870, 267.0, 16.3401
27.515121860, 18.870, 285.0, 16.8819
27.558587620, 18.870, 263.0, 16.2173
27.602053380, 18.870, 326.0, 18.0555
27.645519140, 18.870, 338.0, 18.3848
27.688984900, 18.870, 349.0, 18.6815
27.732450660, 18.870, 365.0, 19.1050
27.775916420, 18.870, 367.0, 19.1572
27.819382180, 18.870, 356.0, 18.8680
27.862847940, 18.870, 359.0, 18.9473
27.906313700, 18.870, 323.0, 17.9722
27.949779460, 18.870, 385.0, 19.6214
27.993245220, 18.870, 402.0, 20.0499
28.036710980, 18.870, 387.0, 19.6723
28.080176740, 18.870, 469.0, 21.6564
28.123642500, 18.870, 503.0, 22.4277
28.167108260, 18.870, 516.0, 22.7156
28.210574020, 18.870, 565.0, 23.7697
28.254039780, 18.870, 630.0, 25.0998
28.297505540, 18.870, 677.0, 26.0192
28.340971300, 18.870, 858.0, 29.2916
28.384437060, 18.870, 1162.0, 34.0881
28.427902820, 18.870, 1679.0, 40.9756
28.471368580, 18.870, 3062.0, 55.3353
28.514834340, 18.870, 5256.0, 72.4983
28.558300100, 18.870, 10220.0, 101.0940
28.601765860, 18.870, 16997.0, 130.3725
28.645231620, 18.870, 17038.0, 130.5297
28.688697380, 18.870, 11840.0, 108.8118
28.732163140, 18.870, 6363.0, 79.7684
28.775628900, 18.870, 2367.0, 48.6518
28.819094660, 18.870, 1366.0, 36.9594
28.862560420, 18.870, 934.0, 30.5614
28.906026180, 18.870, 817.0, 28.5832
28.949491940, 18.870, 653.0, 25.5539
28.992957700, 18.870, 578.0, 24.0416
29.036423460, 18.870, 515.0, 22.6936
29.079889220, 18.870, 459.0, 21.4243
29.123354980, 18.870, 416.0, 20.3961
29.166820740, 18.870, 394.0, 19.8494
29.210286500, 18.870, 424.0, 20.5913
29.253752260, 18.870, 361.0, 19.0000
29.297218020, 18.870, 339.0, 18.4120
29.340683780, 18.870, 330.0, 18.1659
29.384149540, 18.870, 315.0, 17.7482
29.427615300, 18.870, 309.0, 17.5784
29.471081060, 18.870, 314.0, 17.7200
29.514546820, 18.870, 305.0, 17.4642
29.558012580, 18.870, 306.0, 17.4929
29.601478340, 18.870, 339.0, 18.4120
29.644944100, 18.870, 356.0, 18.8680
29.688409860, 18.870, 281.0, 16.7631
29.731875620, 18.870, 316.0, 17.7764
29.775341380, 18.870, 315.0, 17.7482
29.818807140, 18.870, 280.0, 16.7332
29.862272900, 18.870, 311.0, 17.6352
29.905738660, 18.870, 308.0, 17.5499
29.949204420, 18.870, 320.0, 17.8885
29.992670180, 18.870, 295.0, 17.1756
30.036135940, 18.870, 311.0, 17.6352
30.079601700, 18.870, 284.0, 16.8523
30.123067460, 18.870, 280.0, 16.7332
30.166533220, 18.870, 278.0, 16.6733
30.209998980, 18.870, 310.0, 17.6068
30.253464740, 18.870, 297.0, 17.2337
30.296930500, 18.870, 304.0, 17.4356
30.340396260, 18.870, 296.0, 17.2047
30.383862020, 18.870, 300.0, 17.3205
30.427327780, 18.870, 298.0, 17.2627
30.470793540, 18.870, 261.0, 16.1555
30.514259300, 18.870, 307.0, 17.5214
30.557725060, 18.870, 259.0, 16.0935
30.601190820, 18.870, 271.0, 16.4621
30.644656580, 18.870, 272.0, 16.4924
30.688122340, 18.870, 267.0, 16.3401
30.731588100, 18.870, 266.0, 16.3095
30.775053860, 18.870, 258.0, 16.0624
30.818519620, 18.870, 258.0, 16.0624
30.861985380, 18.870, 264.0, 16.2481
30.905451140, 18.870, 295.0, 17.1756
30.948916900, 18.870, 293.0, 17.1172
30.992382660, 18.870, 240.0, 15.4919
31.035848420, 18.870, 279.0, 16.7033
31.079314180, 18.870, 265.0, 16.2788
31.122779940, 18.870, 288.0, 16.9706
31.166245700, 18.870, 279.0, 16.7033
31.209711460, 18.870, 300.0, 17.3205
31.253177220, 18.870, 282.0, 16.7929
31.296642980, 18.870, 279.0, 16.7033
31.340108740, 18.870, 274.0, 16.5529
31.383574500, 18.870, 260.0, 16.1245
31.427040260, 18.870, 246.0, 15.6844
31.470506020, 18.870, 251.0, 15.8430
31.513971780, 18.870, 267.0, 16.3401
31.557437540, 18.870, 272.0, 16.4924
31.600903300, 18.870, 257.0, 16.0312
31.644369060, 18.870, 259.0, 16.0935
31.687834820, 18.870, 269.0, 16.4012
31.731300580, 18.870, 262.0, 16.1864
31.774766340, 18.870, 266.0, 16.3095
31.818232100, 18.870, 244.0, 15.6205
31.861697860, 18.870, 259.0, 16.0935
31.905163620, 18.870, 229.0, 15.1327
31.948629380, 18.870, 267.0, 16.3401
31.992095140, 18.870, 302.0, 17.3781
32.035560900, 18.870, 303.0, 17.4069
32.079026660, 18.870, 293.0, 17.1172
32.122492420, 18.870, 267.0, 16.3401
32.165958180, 18.870, 261.0, 16.1555
32.209423940, 18.870, 275.0, 16.5831
32.252889700, 18.870, 262.0, 16.1864
32.296355460, 18.870, 273.0, 16.5227
32.339821220, 18.870, 268.0, 16.3707
32.383286980, 18.870, 248.0, 15.7480
32.426752740, 18.870, 278.0, 16.6733
32.470218500, 18.870, 284.0, 16.8523
32.513684260, 18.870, 250.0, 15.8114
32.557150020, 18.870, 279.0, 16.7033
32.600615780, 18.870, 315.0, 17.7482
32.644081540, 18.870, 274.0, 16.5529
32.687547300, 18.870, 312.0, 17.6635
32.731013060, 18.870, 292.0, 17.0880
32.774478820, 18.870, 339.0, 18.4120
32.817944580, 18.870, 360.0, 18.9737
32.861410340, 18.870, 387.0, 19.6723
32.904876100, 18.870, 443.0, 21.0476
32.948341860, 18.870, 573.0, 23.9374
32.991807620, 18.870, 796.0, 28.2135
33.035273380, 18.870, 1279.0, 35.7631
33.078739140, 18.870, 2453.0, 49.5278
33.122204900, 18.870, 4432.0, 66.5733
33.165670660, 18.870, 5287.0, 72.7118
33.209136420, 18.870, 4026.0, 63.4508
33.252602180, 18.870, 2776.0, 52.6878
33.296067940, 18.870, 1307.0, 36.1525
33.339533700, 18.870, 695.0, 26.3629
33.382999460, 18.870, 440.0, 20.9762
33.426465220, 18.870, 444.0, 21.0713
33.469930980, 18.870, 365.0, 19.1050
33.513396740, 18.870, 352.0, 18.7617
33.556862500, 18.870, 295.0, 17.1756
33.600328260, 18.870, 281.0, 16.7631
33.643794020, 18.870, 278.0, 16.6733
33.687259780, 18.870, 269.0, 16.4012
33.730725540, 18.870, 268.0, 16.3707
33.774191300, 18.870, 246.0, 15.6844
33.817657060, 18.870, 257.0, 16.0312
33.861122820, 18.870, 279.0, 16.7033
33.904588580, 18.870, 261.0, 16.1555
33.948054340, 18.870, 271.0, 16.4621
33.991520100, 18.870, 239.0, 15.4596
34.034985860, 18.870, 232.0, 15.2315
34.078451620, 18.870, 280.0, 16.7332
34.121917380, 18.870, 236.0, 15.3623
34.165383140, 18.870, 271.0, 16.4621
34.208848900, 18.870, 221.0, 14.8661
34.252314660, 18.870, 230.0, 15.1658
34.295780420, 18.870, 262.0, 16.1864
34.339246180, 18.870, 241.0, 15.5242
34.382711940, 18.870, 243.0, 15.5885
34.426177700, 18.870, 273.0, 16.5227
34.469643460, 18.870, 219.0, 14.7986
34.513109220, 18.870, 265.0, 16.2788
34.556574980, 18.870, 278.0, 16.6733
34.600040740, 18.870, 217.0, 14.7309
34.643506500, 18.870, 224.0, 14.9666
34.686972260, 18.870, 249.0, 15.7797
34.730438020, 18.870, 236.0, 15.3623
34.773903780, 18.870, 233.0, 15.2643
34.817369540, 18.870, 276.0, 16.6132
34.860835300, 18.870, 215.0, 14.6629
34.904301060, 18.870, 234.0, 15.2971
34.947766820, 18.870, 208.0, 14.4222
34.991232580, 18.870, 244.0, 15.6205
35.034698340, 18.870, 230.0, 15.1658
35.078164100, 18.870, 230.0, 15.1658
35.121629860, 18.870, 228.0, 15.0997
35.165095620, 18.870, 228.0, 15.0997
35.208561380, 18.870, 230.0, 15.1658
35.252027140, 18.870, 218.0, 14.7648
35.295492900, 18.870, 242.0, 15.5563
35.338958660, 18.870, 218.0, 14.7648
35.382424420, 18.870, 227.0, 15.0665
35.425890180, 18.870, 216.0, 14.6969
35.469355940, 18.870, 206.0, 14.3527
35.512821700, 18.870, 217.0, 14.7309
35.556287460, 18.870, 203.0, 14.2478
35.599753220, 18.870, 229.0, 15.1327
35.643218980, 18.870, 248.0, 15.7480
35.686684740, 18.870, 249.0, 15.7797
35.730150500, 18.870, 214.0, 14.6287
35.773616260, 18.870, 219.0, 14.7986
35.817082020, 18.870, 239.0, 15.4596
35.860547780, 18.870, 233.0, 15.2643
35.904013540, 18.870, 208.0, 14.4222
35.947479300, 18.870, 219.0, 14.7986
35.990945060, 18.870, 228.0, 15.0997
36.034410820, 18.870, 236.0, 15.3623
36.077876580, 18.870, 229.0, 15.1327
36.121342340, 18.870, 222.0, 14.8997
36.164808100, 18.870, 233.0, 15.2643
36.208273860, 18.870, 235.0, 15.3297
36.251739620, 18.870, 206.0, 14.3527
36.295205380, 18.870, 207.0, 14.3875
36.338671140, 18.870, 221.0, 14.8661
36.382136900, 18.870, 232.0, 15.2315
36.425602660, 18.870, 193.0, 13.8924
36.469068420, 18.870, 204.0, 14.2829
36.512534180, 18.870, 221.0, 14.8661
36.555999940, 18.870, 244.0, 15.6205
36.599465700, 18.870, 212.0, 14.5602
36.642931460, 18.870, 222.0, 14.8997
36.686397220, 18.870, 228.0, 15.0997
36.729862980, 18.870, 235.0, 15.3297
36.773328740, 18.870, 211.0, 14.5258
36.816794500, 18.870, 235.0, 15.3297
36.860260260, 18.870, 210.0, 14.4914
36.903726020, 18.870, 221.0, 14.8661
36.947191780, 18.870, 201.0, 14.1774
36.990657540, 18.870, 198.0, 14.0712
37.034123300, 18.870, 215.0, 14.6629
37.077589060, 18.870, 211.0, 14.5258
37.121054820, 18.870, 247.0, 15.7162
37.164520580, 18.870, 197.0, 14.0357
37.207986340, 18.870, 216.0, 14.6969
37.251452100, 18.870, 222.0, 14.8997
37.294917860, 18.870, 204.0, 14.2829
37.338383620, 18.870, 205.0, 14.3178
37.381849380, 18.870, 220.0, 14.8324
37.425315140, 18.870, 189.0, 13.7477
37.468780900, 18.870, 207.0, 14.3875
37.512246660, 18.870, 217.0, 14.7309
37.555712420, 18.870, 208.0, 14.4222
37.599178180, 18.870, 213.0, 14.5945
37.642643940, 18.870, 199.0, 14.1067
37.686109700, 18.870, 205.0, 14.3178
37.729575460, 18.870, 220.0, 14.8324
37.773041220, 18.870, 202.0, 14.2127
37.816506980, 18.870, 216.0, 14.6969
37.859972740, 18.870, 195.0, 13.9642
37.903438500, 18.870, 206.0, 14.3527
37.946904260, 18.870, 202.0, 14.2127
37.990370020, 18.870, 188.0, 13.7113
38.033835780, 18.870, 217.0, 14.7309
38.077301540, 18.870, 180.0, 13.4164
38.120767300, 18.870, 193.0, 13.8924
38.164233060, 18.870, 214.0, 14.6287
38.207698820, 18.870, 216.0, 14.6969
38.251164580, 18.870, 231.0, 15.1987
38.294630340, 18.870, 226.0, 15.0333
38.338096100, 18.870, 193.0, 13.8924
38.381561860, 18.870, 232.0, 15.2315
38.425027620, 18.870, 216.0, 14.6969
38.468493380, 18.870, 218.0, 14.7648
38.511959140, 18.870, 192.0, 13.8564
38.555424900, 18.870, 205.0, 14.3178
38.598890660, 18.870, 225.0, 15.0000
38.642356420, 18.870, 202.0, 14.2127
38.685822180, 18.870, 218.0, 14.7648
38.729287940, 18.870, 205.0, 14.3178
38.772753700, 18.870, 188.0, 13.7113
38.816219460, 18.870, 212.0, 14.5602
38.859685220, 18.870, 229.0, 15.1327
38.903150980, 18.870, 203.0, 14.2478
38.946616740, 18.870, 217.0, 14.7309
38.990082500, 18.870, 220.0, 14.8324
39.033548260, 18.870, 199.0, 14.1067
39.077014020, 18.870, 179.0, 13.3791
39.120479780, 18.870, 203.0, 14.2478
39.163945540, 18.870, 205.0, 14.3178
39.207411300, 18.870, 207.0, 14.3875
39.250877060, 18.870, 210.0, 14.4914
39.294342820, 18.870, 230.0, 15.1658
39.337808580, 18.870, 243.0, 15.5885
39.381274340, 18.870, 236.0, 15.3623
39.424740100, 18.870, 225.0, 15.0000
39.468205860, 18.870, 215.0, 14.6629
39.511671620, 18.870, 224.0, 14.9666
39.555137380, 18.870, 177.0, 13.3041
39.598603140, 18.870, 194.0, 13.9284
39.642068900, 18.870, 189.0, 13.7477
39.685534660, 18.870, 225.0, 15.0000
39.729000420, 18.870, 200.0, 14.1421
39.772466180, 18.870, 189.0, 13.7477
39.815931940, 18.870, 187.0, 13.6748
39.859397700, 18.870, 195.0, 13.9642
39.902863460, 18.870, 200.0, 14.1421
39.946329220, 18.870, 204.0, 14.2829
39.989794980, 18.870, 165.0, 12.8452
40.033260740, 18.870, 208.0, 14.4222
40.076726500, 18.870, 197.0, 14.0357
40.120192260, 18.870, 190.0, 13.7840
40.163658020, 18.870, 190.0, 13.7840
40.207123780, 18.870, 195.0, 13.9642
40.250589540, 18.870, 215.0, 14.6629
40.294055300, 18.870, 208.0, 14.4222
40.337521060, 18.870, 199.0, 14.1067
40.380986820, 18.870, 202.0, 14.2127
40.424452580, 18.870, 211.0, 14.5258
40.467918340, 18.870, 186.0, 13.6382
40.511384100, 18.870, 199.0, 14.1067
40.554849860, 18.870, 217.0, 14.7309
40.598315620, 18.870, 192.0, 13.8564
40.641781380, 18.870, 193.0, 13.8924
40.685247140, 18.870, 224.0, 14.9666
40.728712900, 18.870, 210.0, 14.4914
40.772178660, 18.870, 176.0, 13.2665
40.815644420, 18.870, 172.0, 13.1149
40.859110180, 18.870, 218.0, 14.7648
40.902575940, 18.870, 186.0, 13.6382
40.946041700, 18.870, 202.0, 14.2127
40.989507460, 18.870, 213.0, 14.5945
41.032973220, 18.870, 210.0, 14.4914
41.076438980, 18.870, 211.0, 14.5258
41.119904740, 18.870, 168.0, 12.9615
41.163370500, 18.870, 187.0, 13.6748
41.206836260, 18.870, 192.0, 13.8564
41.250302020, 18.870, 210.0, 14.4914
41.293767780, 18.870, 168.0, 12.9615
41.337233540, 18.870, 174.0, 13.1909
41.380699300, 18.870, 204.0, 14.2829
41.424165060, 18.870, 198.0, 14.0712
41.467630820, 18.870, 180.0, 13.4164
41.511096580, 18.870, 197.0, 14.0357
41.554562340, 18.870, 206.0, 14.3527
41.598028100, 18.870, 192.0, 13.8564
41.641493860, 18.870, 191.0, 13.8203
41.684959620, 18.870, 194.0, 13.9284
41.728425380, 18.870, 219.0, 14.7986
41.771891140, 18.870, 170.0, 13.0384
41.815356900, 18.870, 198.0, 14.0712
41.858822660, 18.870, 197.0, 14.0357
41.902288420, 18.870, 216.0, 14.6969
41.945754180, 18.870, 198.0, 14.0712
41.989219940, 18.870, 209.0, 14.4568
42.032685700, 18.870, 172.0, 13.1149
42.076151460, 18.870, 213.0, 14.5945
42.119617220, 18.870, 198.0, 14.0712
42.163082980, 18.870, 201.0, 14.1774
42.206548740, 18.870, 212.0, 14.5602
42.250014500, 18.870, 182.0, 13.4907
42.293480260, 18.870, 212.0, 14.5602
42.336946020, 18.870, 183.0, 13.5277
42.380411780, 18.870, 193.0, 13.8924
42.423877540, 18.870, 179.0, 13.3791
42.467343300, 18.870, 194.0, 13.9284
42.510809060, 18.870, 194.0, 13.9284
42.554274820, 18.870, 210.0, 14.4914
42.597740580, 18.870, 177.0, 13.3041
42.641206340, 18.870, 212.0, 14.5602
42.684672100, 18.870, 213.0, 14.5945
42.728137860, 18.870, 201.0, 14.1774
42.771603620, 18.870, 216.0, 14.6969
42.815069380, 18.870, 204.0, 14.2829
42.858535140, 18.870, 204.0, 14.2829
42.902000900, 18.870, 177.0, 13.3041
42.945466660, 18.870, 213.0, 14.5945
42.988932420, 18.870, 178.0, 13.3417
43.032398180, 18.870, 177.0, 13.3041
43.075863940, 18.870, 211.0, 14.5258
43.119329700, 18.870, 165.0, 12.8452
43.162795460, 18.870, 175.0, 13.2288
43.206261220, 18.870, 201.0, 14.1774
43.249726980, 18.870, 200.0, 14.1421
43.293192740, 18.870, 183.0, 13.5277
43.336658500, 18.870, 183.0, 13.5277
43.380124260, 18.870, 177.0, 13.3041
43.423590020, 18.870, 189.0, 13.7477
43.467055780, 18.870, 206.0, 14.3527
43.510521540, 18.870, 193.0, 13.8924
43.553987300, 18.870, 182.0, 13.4907
43.597453060, 18.870, 198.0, 14.0712
43.640918820, 18.870, 203.0, 14.2478
43.684384580, 18.870, 199.0, 14.1067
43.727850340, 18.870, 178.0, 13.3417
43.771316100, 18.870, 175.0, 13.2288
43.814781860, 18.870, 176.0, 13.2665
43.858247620, 18.870, 212.0, 14.5602
43.901713380, 18.870, 167.0, 12.9228
43.945179140, 18.870, 196.0, 14.0000
43.988644900, 18.870, 206.0, 14.3527
44.032110660, 18.870, 181.0, 13.4536
44.075576420, 18.870, 200.0, 14.1421
44.119042180, 18.870, 184.0, 13.5647
44.162507940, 18.870, 192.0, 13.8564
44.205973700, 18.870, 211.0, 14.5258
44.249439460, 18.870, 204.0, 14.2829
44.292905220, 18.870, 190.0, 13.7840
44.336370980, 18.870, 201.0, 14.1774
44.379836740, 18.870, 194.0, 13.9284
44.423302500, 18.870, 183.0, 13.5277
44.466768260, 18.870, 179.0, 13.3791
44.510234020, 18.870, 176.0, 13.2665
44.553699780, 18.870, 172.0, 13.1149
44.597165540, 18.870, 192.0, 13.8564
44.640631300, 18.870, 194.0, 13.9284
44.684097060, 18.870, 187.0, 13.6748
44.727562820, 18.870, 194.0, 13.9284
44.771028580, 18.870, 194.0, 13.9284
44.814494340, 18.870, 171.0, 13.0767
44.857960100, 18.870, 179.0, 13.3791
44.901425860, 18.870, 214.0, 14.6287
44.944891620, 18.870, 189.0, 13.7477
44.988357380, 18.870, 185.0, 13.6015
45.031823140, 18.870, 190.0, 13.7840
45.075288900, 18.870, 162.0, 12.7279
45.118754660, 18.870, 208.0, 14.4222
45.162220420, 18.870, 193.0, 13.8924
45.205686180, 18.870, 216.0, 14.6969
45.249151940, 18.870, 169.0, 13.0000
45.292617700, 18.870, 146.0, 12.0830
45.336083460, 18.870, 180.0, 13.4164
45.379549220, 18.870, 174.0, 13.1909
45.423014980, 18.870, 203.0, 14.2478
45.466480740, 18.870, 160.0, 12.6491
45.509946500, 18.870, 173.0, 13.1529
45.553412260, 18.870, 186.0, 13.6382
45.596878020, 18.870, 208.0, 14.4222
45.640343780, 18.870, 191.0, 13.8203
45.683809540, 18.870, 200.0, 14.1421
45.727275300, 18.870, 167.0, 12.9228
45.770741060, 18.870, 207.0, 14.3875
45.814206820, 18.870, 207.0, 14.3875
45.857672580, 18.870, 222.0, 14.8997
45.901138340, 18.870, 202.0, 14.2127
45.944604100, 18.870, 212.0, 14.5602
45.988069860, 18.870, 228.0, 15.0997
46.031535620, 18.870, 219.0, 14.7986
46.075001380, 18.870, 220.0, 14.8324
46.118467140, 18.870, 238.0, 15.4272
46.161932900, 18.870, 201.0, 14.1774
46.205398660, 18.870, 223.0, 14.9332
46.248864420, 18.870, 202.0, 14.2127
46.292330180, 18.870, 204.0, 14.2829
46.335795940, 18.870, 185.0, 13.6015
46.379261700, 18.870, 204.0, 14.2829
46.422727460, 18.870, 218.0, 14.7648
46.466193220, 18.870, 229.0, 15.1327
46.509658980, 18.870, 200.0, 14.1421
46.553124740, 18.870, 234.0, 15.2971
46.596590500, 18.870, 223.0, 14.9332
46.640056260, 18.870, 233.0, 15.2643
46.683522020, 18.870, 209.0, 14.4568
46.726987780, 18.870, 223.0, 14.9332
46.770453540, 18.870, 250.0, 15.8114
46.813919300, 18.870, 227.0, 15.0665
46.857385060, 18.870, 233.0, 15.2643
46.900850820, 18.870, 240.0, 15.4919
46.944316580, 18.870, 279.0, 16.7033
46.987782340, 18.870, 274.0, 16.5529
47.031248100, 18.870, 299.0, 17.2916
47.074713860, 18.870, 315.0, 17.7482
47.118179620, 18.870, 318.0, 17.8326
47.161645380, 18.870, 385.0, 19.6214
47.205111140, 18.870, 419.0, 20.4695
47.248576900, 18.870, 485.0, 22.0227
47.292042660, 18.870, 617.0, 24.8395
47.335508420, 18.870, 774.0, 27.8209
47.378974180, 18.870, 1045.0, 32.3265
47.422439940, 18.870, 1687.0, 41.0731
47.465905700, 18.870, 3627.0, 60.2246
47.509371460, 18.870, 7434.0, 86.2206
47.552837220, 18.870, 10056.0, 100.2796
47.596302980, 18.870, 6564.0, 81.0185
47.639768740, 18.870, 5528.0, 74.3505
47.683234500, 18.870, 5246.0, 72.4293
47.726700260, 18.870, 2754.0, 52.4786
47.770166020, 18.870, 1335.0, 36.5377
47.813631780, 18.870, 773.0, 27.8029
47.857097540, 18.870, 599.0, 24.4745
47.900563300, 18.870, 480.0, 21.9089
47.944029060, 18.870, 421.0, 20.5183
47.987494820, 18.870, 371.0, 19.2614
48.030960580, 18.870, 331.0, 18.1934
48.074426340, 18.870, 302.0, 17.3781
48.117892100, 18.870, 273.0, 16.5227
48.161357860, 18.870, 283.0, 16.8226
48.204823620, 18.870, 248.0, 15.7480
48.248289380, 18.870, 249.0, 15.7797
48.291755140, 18.870, 233.0, 15.2643
48.335220900, 18.870, 234.0, 15.2971
48.378686660, 18.870, 227.0, 15.0665
48.422152420, 18.870, 238.0, 15.4272
48.465618180, 18.870, 220.0, 14.8324
48.509083940, 18.870, 210.0, 14.4914
48.552549700, 18.870, 224.0, 14.9666
48.596015460, 18.870, 201.0, 14.1774
48.639481220, 18.870, 211.0, 14.5258
48.682946980, 18.870, 216.0, 14.6969
48.726412740, 18.870, 209.0, 14.4568
48.769878500, 18.870, 228.0, 15.0997
48.813344260, 18.870, 198.0, 14.0712
48.856810020, 18.870, 218.0, 14.7648
48.900275780, 18.870, 198.0, 14.0712
48.943741540, 18.870, 210.0, 14.4914
48.987207300, 18.870, 209.0, 14.4568
49.030673060, 18.870, 222.0, 14.8997
49.074138820, 18.870, 210.0, 14.4914
49.117604580, 18.870, 206.0, 14.3527
49.161070340, 18.870, 200.0, 14.1421
49.204536100, 18.870, 169.0, 13.0000
49.248001860, 18.870, 217.0, 14.7309
49.291467620, 18.870, 226.0, 15.0333
49.334933380, 18.870, 204.0, 14.2829
49.378399140, 18.870, 181.0, 13.4536
49.421864900, 18.870, 225.0, 15.0000
49.465330660, 18.870, 194.0, 13.9284
49.508796420, 18.870, 195.0, 13.9642
49.552262180, 18.870, 221.0, 14.8661
49.595727940, 18.870, 192.0, 13.8564
49.639193700, 18.870, 206.0, 14.3527
49.682659460, 18.870, 232.0, 15.2315
49.726125220, 18.870, 183.0, 13.5277
49.769590980, 18.870, 205.0, 14.3178
49.813056740, 18.870, 208.0, 14.4222
49.856522500, 18.870, 183.0, 13.5277
49.899988260, 18.870, 222.0, 14.8997
49.943454020, 18.870, 208.0, 14.4222
49.986919780, 18.870, 208.0, 14.4222
50.030385540, 18.870, 183.0, 13.5277
50.073851300, 18.870, 218.0, 14.7648
50.117317060, 18.870, 193.0, 13.8924
50.160782820, 18.870, 211.0, 14.5258
50.204248580, 18.870, 216.0, 14.6969
50.247714340, 18.870, 190.0, 13.7840
50.291180100, 18.870, 182.0, 13.4907
50.334645860, 18.870, 209.0, 14.4568
50.378111620, 18.870, 195.0, 13.9642
50.421577380, 18.870, 196.0, 14.0000
50.465043140, 18.870, 193.0, 13.8924
50.508508900, 18.870, 232.0, 15.2315
50.551974660, 18.870, 243.0, 15.5885
50.595440420, 18.870, 211.0, 14.5258
50.638906180, 18.870, 223.0, 14.9332
50.682371940, 18.870, 213.0, 14.5945
50.725837700, 18.870, 186.0, 13.6382
50.769303460, 18.870, 192.0, 13.8564
50.812769220, 18.870, 169.0, 13.0000
50.856234980, 18.870, 204.0, 14.2829
50.899700740, 18.870, 169.0, 13.0000
50.943166500, 18.870, 212.0, 14.5602
50.986632260, 18.870, 190.0, 13.7840
51.030098020, 18.870, 197.0, 14.0357
51.073563780, 18.870, 187.0, 13.6748
51.117029540, 18.870, 209.0, 14.4568
51.160495300, 18.870, 179.0, 13.3791
51.203961060, 18.870, 166.0, 12.8841
51.247426820, 18.870, 197.0, 14.0357
51.290892580, 18.870, 177.0, 13.3041
51.334358340, 18.870, 206.0, 14.3527
51.377824100, 18.870, 173.0, 13.1529
51.421289860, 18.870, 184.0, 13.5647
51.464755620, 18.870, 183.0, 13.5277
51.508221380, 18.870, 200.0, 14.1421
51.551687140, 18.870, 178.0, 13.3417
51.595152900, 18.870, 134.0, 11.5758
51.638618660, 18.870, 204.0, 14.2829
51.682084420, 18.870, 212.0, 14.5602
51.725550180, 18.870, 166.0, 12.8841
51.769015940, 18.870, 184.0, 13.5647
51.812481700, 18.870, 167.0, 12.9228
51.855947460, 18.870, 198.0, 14.0712
51.899413220, 18.870, 216.0, 14.6969
51.942878980, 18.870, 185.0, 13.6015
51.986344740, 18.870, 195.0, 13.9642
52.029810500, 18.870, 174.0, 13.1909
52.073276260, 18.870, 188.0, 13.7113
52.116742020, 18.870, 190.0, 13.7840
52.160207780, 18.870, 192.0, 13.8564
52.203673540, 18.870, 187.0, 13.6748
52.247139300, 18.870, 163.0, 12.7671
52.290605060, 18.870, 186.0, 13.6382
52.334070820, 18.870, 188.0, 13.7113
52.377536580, 18.870, 213.0, 14.5945
52.421002340, 18.870, 203.0, 14.2478
52.464468100, 18.870, 183.0, 13.5277
52.507933860, 18.870, 194.0, 13.9284
52.551399620, 18.870, 192.0, 13.8564
52.594865380, 18.870, 188.0, 13.7113
52.638331140, 18.870, 187.0, 13.6748
52.681796900, 18.870, 165.0, 12.8452
52.725262660, 18.870, 182.0, 13.4907
52.768728420, 18.870, 220.0, 14.8324
52.812194180, 18.870, 190.0, 13.7840
52.855659940, 18.870, 188.0, 13.7113
52.899125700, 18.870, 169.0, 13.0000
52.942591460, 18.870, 170.0, 13.0384
52.986057220, 18.870, 171.0, 13.0767
53.029522980, 18.870, 160.0, 12.6491
53.072988740, 18.870, 187.0, 13.6748
53.116454500, 18.870, 177.0, 13.3041
53.159920260, 18.870, 183.0, 13.5277
53.203386020, 18.870, 171.0, 13.0767
53.246851780, 18.870, 166.0, 12.8841
53.290317540, 18.870, 164.0, 12.8062
53.333783300, 18.870, 173.0, 13.1529
53.377249060, 18.870, 171.0, 13.0767
53.420714820, 18.870, 178.0, 13.3417
53.464180580, 18.870, 165.0, 12.8452
53.507646340, 18.870, 175.0, 13.2288
53.551112100, 18.870, 197.0, 14.0357
53.594577860, 18.870, 181.0, 13.4536
53.638043620, 18.870, 184.0, 13.5647
53.681509380, 18.870, 190.0, 13.7840
53.724975140, 18.870, 161.0, 12.6886
53.768440900, 18.870, 186.0, 13.6382
53.811906660, 18.870, 176.0, 13.2665
53.855372420, 18.870, 190.0, 13.7840
53.898838180, 18.870, 173.0, 13.1529
53.942303940, 18.870, 176.0, 13.2665
53.985769700, 18.870, 180.0, 13.4164
54.029235460, 18.870, 182.0, 13.4907
54.072701220, 18.870, 169.0, 13.0000
54.116166980, 18.870, 183.0, 13.5277
54.159632740, 18.870, 187.0, 13.6748
54.203098500, 18.870, 159.0, 12.6095
54.246564260, 18.870, 189.0, 13.7477
54.290030020, 18.870, 196.0, 14.0000
54.333495780, 18.870, 205.0, 14.3178
54.376961540, 18.870, 177.0, 13.3041
54.420427300, 18.870, 182.0, 13.4907
54.463893060, 18.870, 177.0, 13.3041
54.507358820, 18.870, 178.0, 13.3417
54.550824580, 18.870, 203.0, 14.2478
54.594290340, 18.870, 213.0, 14.5945
54.637756100, 18.870, 202.0, 14.2127
54.681221860, 18.870, 172.0, 13.1149
54.724687620, 18.870, 186.0, 13.6382
54.768153380, 18.870, 214.0, 14.6287
54.811619140, 18.870, 190.0, 13.7840
54.855084900, 18.870, 197.0, 14.0357
54.898550660, 18.870, 211.0, 14.5258
54.942016420, 18.870, 178.0, 13.3417
54.985482180, 18.870, 224.0, 14.9666
55.028947940, 18.870, 220.0, 14.8324
55.072413700, 18.870, 187.0, 13.6748
55.115879460, 18.870, 211.0, 14.5258
55.159345220, 18.870, 197.0, 14.0357
55.202810980, 18.870, 205.0, 14.3178
55.246276740, 18.870, 193.0, 13.8924
55.289742500, 18.870, 227.0, 15.0665
55.333208260, 18.870, 188.0, 13.7113
55.376674020, 18.870, 209.0, 14.4568
55.420139780, 18.870, 228.0, 15.0997
55.463605540, 18.870, 215.0, 14.6629
55.507071300, 18.870, 257.0, 16.0312
55.550537060, 18.870, 191.0, 13.8203
55.594002820, 18.870, 223.0, 14.9332
55.637468580, 18.870, 211.0, 14.5258
55.680934340, 18.870, 215.0, 14.6629
55.724400100, 18.870, 217.0, 14.7309
55.767865860, 18.870, 250.0, 15.8114
55.811331620, 18.870, 229.0, 15.1327
55.854797380, 18.870, 232.0, 15.2315
55.898263140, 18.870, 259.0, 16.0935
55.941728900, 18.870, 301.0, 17.3494
55.985194660, 18.870, 292.0, 17.0880
56.028660420, 18.870, 341.0, 18.4662
56.072126180, 18.870, 383.0, 19.5704
56.115591940, 18.870, 468.0, 21.6333
56.159057700, 18.870, 540.0, 23.2379
56.202523460, 18.870, 680.0, 26.0768
56.245989220, 18.870, 934.0, 30.5614
56.289454980, 18.870, 1589.0, 39.8623
56.332920740, 18.870, 3473.0, 58.9322
56.376386500, 18.870, 6812.0, 82.5348
56.419852260, 18.870, 7241.0, 85.0941
56.463318020, 18.870, 4112.0, 64.1249
56.506783780, 18.870, 3430.0, 58.5662
56.550249540, 18.870, 4312.0, 65.6658
56.593715300, 18.870, 2925.0, 54.0833
56.637181060, 18.870, 1288.0, 35.8887
56.680646820, 18.870, 758.0, 27.5318
56.724112580, 18.870, 588.0, 24.2487
56.767578340, 18.870, 459.0, 21.4243
56.811044100, 18.870, 369.0, 19.2094
56.854509860, 18.870, 295.0, 17.1756
56.897975620, 18.870, 302.0, 17.3781
56.941441380, 18.870, 267.0, 16.3401
56.984907140, 18.870, 210.0, 14.4914
57.028372900, 18.870, 217.0, 14.7309
57.071838660, 18.870, 228.0, 15.0997
57.115304420, 18.870, 273.0, 16.5227
57.158770180, 18.870, 212.0, 14.5602
57.202235940, 18.870, 206.0, 14.3527
57.245701700, 18.870, 217.0, 14.7309
57.289167460, 18.870, 212.0, 14.5602
57.332633220, 18.870, 208.0, 14.4222
57.376098980, 18.870, 185.0, 13.6015
57.419564740, 18.870, 193.0, 13.8924
57.463030500, 18.870, 191.0, 13.8203
57.506496260, 18.870, 206.0, 14.3527
57.549962020, 18.870, 193.0, 13.8924
57.593427780, 18.870, 185.0, 13.6015
57.636893540, 18.870, 173.0, 13.1529
57.680359300, 18.870, 185.0, 13.6015
57.723825060, 18.870, 185.0, 13.6015
57.767290820, 18.870, 188.0, 13.7113
57.810756580, 18.870, 182.0, 13.4907
57.854222340, 18.870, 175.0, 13.2288
57.897688100, 18.870, 203.0, 14.2478
57.941153860, 18.870, 171.0, 13.0767
57.984619620, 18.870, 180.0, 13.4164
58.028085380, 18.870, 179.0, 13.3791
58.071551140, 18.870, 199.0, 14.1067
58.115016900, 18.870, 180.0, 13.4164
58.158482660, 18.870, 210.0, 14.4914
58.201948420, 18.870, 160.0, 12.6491
58.245414180, 18.870, 193.0, 13.8924
58.288879940, 18.870, 186.0, 13.6382
58.332345700, 18.870, 194.0, 13.9284
58.375811460, 18.870, 189.0, 13.7477
58.419277220, 18.870, 196.0, 14.0000
58.462742980, 18.870, 179.0, 13.3791
58.506208740, 18.870, 180.0, 13.4164
58.549674500, 18.870, 164.0, 12.8062
58.593140260, 18.870, 185.0, 13.6015
58.636606020, 18.870, 157.0, 12.5300
58.680071780, 18.870, 194.0, 13.9284
58.723537540, 18.870, 196.0, 14.0000
58.767003300, 18.870, 224.0, 14.9666
58.810469060, 18.870, 222.0, 14.8997
58.853934820, 18.870, 233.0, 15.2643
58.897400580, 18.870, 259.0, 16.0935
58.940866340, 18.870, 275.0, 16.5831
58.984332100, 18.870, 313.0, 17.6918
59.027797860, 18.870, 429.0, 20.7123
59.071263620, 18.870, 734.0, 27.0924
59.114729380, 18.870, 1261.0, 35.5106
59.158195140, 18.870, 1544.0, 39.2938
59.201660900, 18.870, 961.0, 31.0000
59.245126660, 18.870, 733.0, 27.0740
59.288592420, 18.870, 911.0, 30.1828
59.332058180, 18.870, 803.0, 28.3373
59.375523940, 18.870, 480.0, 21.9089
59.418989700, 18.870, 341.0, 18.4662
59.462455460, 18.870, 259.0, 16.0935
59.505921220, 18.870, 232.0, 15.2315
59.549386980, 18.870, 219.0, 14.7986
59.592852740, 18.870, 194.0, 13.9284
59.636318500, 18.870, 210.0, 14.4914
59.679784260, 18.870, 198.0, 14.0712
59.723250020, 18.870, 202.0, 14.2127
59.766715780, 18.870, 199.0, 14.1067
59.810181540, 18.870, 174.0, 13.1909
59.853647300, 18.870, 171.0, 13.0767
59.897113060, 18.870, 163.0, 12.7671
59.940578820, 18.870, 182.0, 13.4907
59.984044580, 18.870, 200.0, 14.1421
59.994911020, 18.870, 172.0, 13.1149