File: TGA/2023_07_10_alumel_calib_1cpm.txt
CLOSED
Version	0.4
Run	867
Instrument	2950 TGA       V5.4A
Module	TGA 1000 øC
Sample	2023_07_10_alumel_calib_1cpm
Size	23.4220	mg
Method	50C to 300C 1CPM
Operator	SBK
Comment	2023_07_10_alumel_calib_1cpm
Xcomment	Pan: Platinum           Gas1: Nitrogen  40          Gas2: Nitrogen  40
Text	2023_07_10_alumel_calib_1cpm
Text	Calibration with alumel and magnet
Kcell	1.00000
TempCal	0	pts
Thresholds	0.050	0.0000
Controls	Gas 1  Event Off  Sampling 2.0 sec/pt
Nsig	3
Sig1	Time (min)
Sig2	Temperature (øC)
Sig3	Weight (mg)
Date	10-Jul-23
Time	16:26
File	C:\TA\Data\TGA\Skyler\2023_07_10_alumel_calib_1cpm.001
OrgFile	C:\TA\Data\TGA\Skyler\2023_07_10_alumel_calib_1cpm.001
StartOfData
0.0000000	50.10813	23.41093
0.1678333	50.14975	23.41100
0.3361667	50.23002	23.41094
0.5045000	50.34634	23.41095
0.6728332	50.48808	23.41091
0.8411668	50.64210	23.41079
1.009500	50.80418	23.41086
1.177834	50.96662	23.41072
1.346167	51.13658	23.41062
1.514500	51.30774	23.41040
1.682833	51.47566	23.41049
1.851166	51.63620	23.41039
2.019667	51.79980	23.41032
2.188000	51.96146	23.41020
2.356000	52.12847	23.41018
2.522833	52.29546	23.41012
2.689500	52.46246	23.40994
2.856167	52.62971	23.40997
3.022833	52.80161	23.40990
3.189667	52.97282	23.40966
3.356333	53.14014	23.40972
3.523000	53.30478	23.40968
3.689667	53.47439	23.40951
3.856333	53.64055	23.40935
4.023000	53.80651	23.40930
4.189500	53.97506	23.40924
4.356333	54.14282	23.40924
4.523000	54.30645	23.40911
4.689667	54.46968	23.40927
4.856000	54.63308	23.40911
5.022833	54.79752	23.40910
5.189500	54.96270	23.40905
5.356168	55.12334	23.40889
5.522832	55.28918	23.40885
5.689500	55.45800	23.40884
5.858000	55.62486	23.40865
6.026332	55.79401	23.40848
6.194668	55.96695	23.40836
6.362832	56.13508	23.40836
6.531168	56.30141	23.40829
6.699500	56.47006	23.40820
6.867832	56.63908	23.40818
7.036166	56.81368	23.40813
7.204500	56.98394	23.40806
7.372832	57.15186	23.40800
7.541168	57.31716	23.40794
7.709668	57.48284	23.40776
7.877832	57.65611	23.40774
8.046166	57.82952	23.40771
8.212832	57.99415	23.40745
8.379666	58.16104	23.40762
8.546166	58.32411	23.40752
8.712832	58.48844	23.40744
8.879501	58.65090	23.40742
9.046166	58.81562	23.40738
9.213000	58.98321	23.40742
9.379334	59.14985	23.40742
9.546166	59.31350	23.40728
9.712832	59.48160	23.40726
9.879501	59.65176	23.40730
10.04617	59.81946	23.40712
10.21283	59.98688	23.40720
10.37967	60.15166	23.40710
10.54633	60.32400	23.40718
10.71300	60.49625	23.40694
10.87950	60.66650	23.40684
11.04616	60.83466	23.40679
11.21283	61.00050	23.40680
11.38050	61.16717	23.40675
11.54867	61.33334	23.40659
11.71700	61.49678	23.40660
11.88533	61.65890	23.40654
12.05367	61.82632	23.40657
12.22200	61.99480	23.40646
12.39033	62.15292	23.40637
12.55784	62.31108	23.40652
12.72467	62.48116	23.40642
12.89133	62.64665	23.40620
13.05800	62.81440	23.40626
13.22467	62.97916	23.40629
13.39133	63.14836	23.40605
13.55800	63.32480	23.40604
13.72450	63.50043	23.40604
13.89117	63.67016	23.40582
14.05784	63.83925	23.40595
14.22434	64.01176	23.40602
14.39133	64.17818	23.40585
14.55800	64.33824	23.40566
14.72467	64.50402	23.40586
14.89133	64.66957	23.40570
15.05800	64.83382	23.40561
15.22467	65.00292	23.40565
15.39133	65.16576	23.40551
15.55784	65.33270	23.40552
15.72450	65.49853	23.40544
15.89284	65.66814	23.40547
16.06117	65.83432	23.40531
16.22950	66.00410	23.40537
16.39784	66.17720	23.40538
16.56600	66.34564	23.40530
16.73300	66.51640	23.40518
16.89966	66.68580	23.40515
17.06616	66.85160	23.40492
17.23284	67.01778	23.40503
17.39950	67.18592	23.40492
17.56616	67.34956	23.40496
17.73284	67.51419	23.40488
17.89950	67.67599	23.40474
18.06616	67.84486	23.40466
18.23266	68.01204	23.40450
18.39966	68.17708	23.40448
18.56633	68.34884	23.40442
18.73284	68.51781	23.40437
18.89950	68.68218	23.40438
19.06600	68.85030	23.40442
19.23300	69.01704	23.40425
19.39950	69.18720	23.40416
19.56616	69.34928	23.40414
19.73284	69.51238	23.40406
19.90117	69.67766	23.40412
20.06966	69.83884	23.40406
20.23800	70.00506	23.40392
20.40600	70.17543	23.40396
20.57283	70.33461	23.40384
20.73950	70.49641	23.40394
20.90617	70.66634	23.40383
21.07283	70.83901	23.40391
21.23950	71.00663	23.40383
21.40617	71.17744	23.40391
21.57283	71.34765	23.40386
21.73950	71.51163	23.40386
21.90617	71.68418	23.40366
22.07283	71.85411	23.40364
22.23950	72.02516	23.40366
22.40633	72.18597	23.40356
22.57300	72.35541	23.40365
22.73934	72.52524	23.40352
22.90617	72.68552	23.40350
23.07283	72.85208	23.40348
23.23950	73.01997	23.40343
23.40617	73.18322	23.40348
23.57266	73.35274	23.40337
23.74133	73.51306	23.40328
23.90966	73.68246	23.40326
24.07800	73.85338	23.40322
24.24617	74.02561	23.40314
24.41450	74.18594	23.40310
24.58284	74.35101	23.40301
24.75117	74.52462	23.40297
24.91950	74.69901	23.40302
25.08617	74.86926	23.40286
25.25266	75.03759	23.40288
25.41934	75.19718	23.40282
25.58617	75.35768	23.40291
25.75283	75.52655	23.40271
25.91950	75.69134	23.40270
26.08617	75.86140	23.40267
26.25283	76.02971	23.40269
26.41950	76.19829	23.40267
26.58617	76.36478	23.40255
26.75283	76.53047	23.40248
26.91950	76.69715	23.40256
27.08600	76.86897	23.40256
27.25300	77.03874	23.40253
27.41966	77.20654	23.40240
27.58617	77.36982	23.40242
27.75283	77.53795	23.40236
27.91950	77.70230	23.40230
28.08617	77.86581	23.40220
28.25300	78.03299	23.40227
28.41966	78.19870	23.40219
28.58633	78.36921	23.40216
28.75300	78.53432	23.40222
28.91966	78.70269	23.40215
29.08633	78.86485	23.40196
29.25300	79.03338	23.40198
29.41966	79.20202	23.40191
29.58617	79.37056	23.40180
29.75283	79.53954	23.40194
29.91950	79.70650	23.40171
30.08600	79.87010	23.40185
30.25300	80.03728	23.40180
30.41950	80.19724	23.40172
30.58617	80.36669	23.40159
30.75283	80.53778	23.40160
30.91966	80.70359	23.40152
31.08633	80.86706	23.40160
31.25300	81.03280	23.40149
31.42050	81.19589	23.40144
31.58883	81.35872	23.40138
31.75716	81.52353	23.40134
31.92550	81.68980	23.40140
32.09384	81.86206	23.40125
32.26216	82.03259	23.40109
32.43050	82.20410	23.40116
32.59867	82.37310	23.40125
32.76700	82.54259	23.40128
32.93533	82.71640	23.40124
33.10367	82.88611	23.40118
33.27217	83.05890	23.40085
33.44050	83.23006	23.40108
33.60867	83.39728	23.40108
33.77700	83.56316	23.40087
33.94533	83.72902	23.40076
34.11383	83.89551	23.40087
34.28200	84.06328	23.40093
34.45033	84.23000	23.40094
34.61783	84.40014	23.40084
34.78433	84.56553	23.40076
34.95100	84.73061	23.40062
35.11800	84.89664	23.40091
35.28467	85.06085	23.40063
35.45133	85.22845	23.40053
35.61783	85.39425	23.40045
35.78450	85.56059	23.40061
35.95117	85.72653	23.40045
36.11783	85.89328	23.40042
36.28450	86.06129	23.40040
36.45117	86.22531	23.40049
36.61783	86.39344	23.40033
36.78467	86.55939	23.40025
36.95133	86.72401	23.40029
37.11800	86.89266	23.40026
37.28450	87.06024	23.40018
37.45117	87.22799	23.40018
37.61783	87.39247	23.40012
37.78450	87.55132	23.40016
37.95284	87.71809	23.40012
38.12134	87.88788	23.40021
38.28967	88.05928	23.40011
38.45783	88.23100	23.40014
38.62617	88.40072	23.40001
38.79450	88.57050	23.40000
38.96283	88.73916	23.39990
39.13117	88.90722	23.40001
39.29950	89.07569	23.39986
39.46784	89.24303	23.39970
39.63617	89.41176	23.39974
39.80450	89.57853	23.39972
39.97283	89.74816	23.39975
40.14117	89.91949	23.39970
40.30950	90.08159	23.39964
40.47783	90.24781	23.39946
40.64617	90.41680	23.39950
40.81450	90.58711	23.39960
40.98283	90.75812	23.39950
41.14950	90.92431	23.39936
41.31617	91.09015	23.39930
41.48283	91.25496	23.39930
41.64950	91.42157	23.39925
41.81617	91.58621	23.39932
41.98283	91.75039	23.39927
42.14950	91.91759	23.39925
42.31617	92.08157	23.39926
42.48283	92.24659	23.39913
42.64966	92.41554	23.39910
42.81633	92.58194	23.39900
42.98300	92.75129	23.39902
43.14950	92.92126	23.39910
43.31617	93.08705	23.39896
43.48283	93.25882	23.39908
43.64950	93.42689	23.39894
43.81633	93.59085	23.39906
43.98283	93.75803	23.39892
44.14950	93.92400	23.39882
44.31783	94.09843	23.39883
44.48617	94.26609	23.39878
44.65450	94.43301	23.39888
44.82117	94.59797	23.39877
44.98766	94.76353	23.39870
45.15467	94.92806	23.39862
45.32133	95.09131	23.39860
45.48800	95.25055	23.39853
45.65434	95.41680	23.39856
45.82133	95.58976	23.39860
45.98800	95.75984	23.39848
46.15467	95.92988	23.39844
46.32117	96.10018	23.39846
46.48784	96.26641	23.39836
46.65450	96.43064	23.39836
46.82117	96.59686	23.39829
46.98784	96.76219	23.39819
47.15450	96.92535	23.39827
47.32117	97.09078	23.39822
47.48784	97.25722	23.39819
47.65450	97.42391	23.39824
47.82117	97.59074	23.39814
47.98934	97.76024	23.39806
48.15800	97.93165	23.39805
48.32633	98.09903	23.39808
48.49467	98.26382	23.39805
48.66300	98.43256	23.39798
48.83133	98.60294	23.39796
48.99967	98.76947	23.39801
49.16800	98.93597	23.39801
49.33633	99.10462	23.39810
49.50467	99.27570	23.39797
49.67300	99.44659	23.39797
49.84117	99.61197	23.39782
50.00967	99.77874	23.39784
50.17800	99.94981	23.39776
50.34633	100.1169	23.39787
50.51467	100.2857	23.39777
50.68283	100.4576	23.39771
50.85117	100.6275	23.39782
51.01950	100.7970	23.39766
51.18783	100.9653	23.39746
51.35616	101.1335	23.39762
51.52450	101.3021	23.39742
51.69283	101.4681	23.39754
51.86284	101.6357	23.39750
52.02950	101.8028	23.39760
52.19617	101.9706	23.39742
52.36284	102.1346	23.39726
52.52950	102.3019	23.39731
52.69617	102.4678	23.39723
52.86284	102.6343	23.39729
53.02950	102.7989	23.39722
53.19634	102.9678	23.39742
53.36300	103.1347	23.39715
53.52967	103.3002	23.39708
53.69634	103.4674	23.39709
53.86300	103.6362	23.39696
54.02950	103.8017	23.39692
54.19617	103.9698	23.39673
54.36300	104.1339	23.39688
54.52967	104.3026	23.39680
54.69634	104.4710	23.39684
54.86300	104.6381	23.39692
55.02950	104.8071	23.39680
55.19617	104.9730	23.39670
55.36450	105.1417	23.39674
55.53116	105.3084	23.39661
55.69783	105.4739	23.39662
55.86450	105.6430	23.39665
56.03116	105.8072	23.39656
56.19783	105.9731	23.39636
56.36433	106.1420	23.39635
56.53134	106.3074	23.39650
56.69800	106.4732	23.39644
56.86433	106.6382	23.39638
57.03116	106.8028	23.39637
57.19783	106.9716	23.39634
57.36450	107.1378	23.39624
57.53116	107.3053	23.39619
57.69783	107.4721	23.39610
57.86450	107.6385	23.39602
58.03116	107.8028	23.39621
58.19783	107.9700	23.39608
58.36450	108.1360	23.39604
58.53116	108.3026	23.39595
58.69783	108.4715	23.39598
58.86533	108.6393	23.39590
59.03367	108.8085	23.39582
59.20200	108.9730	23.39577
59.37034	109.1383	23.39586
59.53882	109.3061	23.39584
59.70717	109.4733	23.39586
59.87550	109.6450	23.39570
60.04384	109.8141	23.39574
60.21216	109.9831	23.39582
60.38050	110.1498	23.39575
60.54883	110.3134	23.39568
60.71717	110.4842	23.39566
60.88516	110.6543	23.39575
61.05266	110.8264	23.39567
61.21950	110.9934	23.39556
61.38616	111.1597	23.39553
61.55283	111.3267	23.39557
61.71950	111.4925	23.39546
61.88616	111.6646	23.39533
62.05283	111.8333	23.39542
62.21950	111.9975	23.39540
62.38616	112.1633	23.39537
62.55283	112.3297	23.39538
62.71950	112.4952	23.39538
62.88616	112.6624	23.39521
63.05283	112.8278	23.39530
63.21950	112.9916	23.39522
63.38616	113.1577	23.39523
63.55300	113.3233	23.39525
63.71950	113.4904	23.39520
63.88616	113.6548	23.39503
64.05300	113.8222	23.39512
64.21967	113.9922	23.39503
64.38632	114.1569	23.39488
64.55434	114.3240	23.39480
64.72100	114.4914	23.39492
64.88766	114.6611	23.39501
65.05450	114.8256	23.39498
65.22117	114.9896	23.39481
65.38783	115.1547	23.39498
65.55434	115.3225	23.39482
65.72134	115.4881	23.39475
65.88800	115.6587	23.39465
66.05450	115.8274	23.39450
66.22116	115.9993	23.39467
66.38800	116.1654	23.39464
66.55466	116.3301	23.39468
66.72134	116.4980	23.39453
66.88800	116.6614	23.39444
67.05466	116.8287	23.39448
67.22134	116.9970	23.39441
67.38766	117.1580	23.39433
67.55450	117.3259	23.39442
67.72116	117.4924	23.39432
67.88950	117.6564	23.39427
68.05782	117.8211	23.39422
68.22632	117.9913	23.39425
68.39434	118.1594	23.39412
68.56284	118.3251	23.39413
68.73116	118.4939	23.39406
68.89950	118.6627	23.39412
69.06616	118.8296	23.39403
69.23284	118.9972	23.39405
69.39950	119.1655	23.39392
69.56616	119.3344	23.39400
69.73284	119.5046	23.39391
69.89966	119.6746	23.39398
70.06634	119.8441	23.39380
70.23300	120.0116	23.39392
70.39966	120.1829	23.39380
70.56634	120.3486	23.39373
70.73300	120.5120	23.39367
70.89950	120.6774	23.39386
71.06616	120.8429	23.39371
71.23284	121.0057	23.39360
71.39966	121.1671	23.39353
71.56616	121.3328	23.39359
71.73284	121.4969	23.39355
71.89950	121.6611	23.39358
72.06616	121.8304	23.39352
72.23450	121.9958	23.39346
72.40282	122.1704	23.39354
72.57116	122.3418	23.39350
72.73950	122.5125	23.39331
72.90800	122.6814	23.39334
73.07616	122.8464	23.39320
73.24450	123.0123	23.39328
73.41300	123.1780	23.39326
73.58134	123.3473	23.39314
73.74966	123.5106	23.39328
73.91800	123.6758	23.39314
74.08634	123.8466	23.39316
74.25468	124.0157	23.39297
74.42300	124.1864	23.39301
74.59134	124.3557	23.39292
74.75968	124.5268	23.39283
74.92800	124.6989	23.39294
75.09616	124.8711	23.39285
75.26450	125.0364	23.39279
75.43282	125.1954	23.39270
75.60132	125.3407	23.39261
75.76968	125.4879	23.39256
75.93784	125.6469	23.39255
76.10616	125.8058	23.39251
76.27432	125.9525	23.39237
76.44300	126.1094	23.39237
76.61118	126.2754	23.39235
76.77950	126.4456	23.39234
76.94800	126.6211	23.39234
77.11616	126.8021	23.39228
77.28450	126.9821	23.39229
77.45282	127.1628	23.39222
77.62100	127.3412	23.39216
77.78968	127.5204	23.39210
77.95782	127.7000	23.39196
78.12616	127.8790	23.39205
78.29468	128.0554	23.39187
78.46282	128.2288	23.39179
78.63116	128.4002	23.39172
78.79950	128.5670	23.39184
78.96800	128.7363	23.39178
79.13618	128.9035	23.39174
79.30450	129.0703	23.39170
79.47266	129.2416	23.39180
79.64134	129.4099	23.39176
79.80950	129.5803	23.39170
79.97784	129.7486	23.39165
80.14434	129.9157	23.39162
80.31134	130.0833	23.39156
80.47784	130.2493	23.39158
80.64450	130.4146	23.39148
80.81116	130.5812	23.39156
80.97784	130.7476	23.39152
81.14434	130.9136	23.39151
81.31134	131.0784	23.39133
81.47800	131.2461	23.39131
81.64468	131.4125	23.39127
81.81134	131.5813	23.39125
81.97800	131.7504	23.39119
82.14468	131.9155	23.39096
82.31134	132.0814	23.39101
82.47800	132.2447	23.39095
82.64468	132.4088	23.39102
82.81134	132.5778	23.39106
82.97784	132.7459	23.39096
83.14450	132.9120	23.39111
83.31282	133.0825	23.39104
83.48100	133.2512	23.39108
83.64950	133.4202	23.39101
83.81782	133.5892	23.39106
83.98449	133.7559	23.39087
84.15134	133.9226	23.39072
84.31782	134.0898	23.39070
84.48449	134.2546	23.39073
84.65134	134.4182	23.39076
84.81782	134.5835	23.39068
84.98434	134.7520	23.39061
85.15118	134.9180	23.39060
85.31782	135.0839	23.39058
85.48434	135.2514	23.39050
85.65134	135.4191	23.39044
85.81782	135.5851	23.39035
85.98449	135.7518	23.39042
86.15134	135.9172	23.39017
86.31800	136.0862	23.39042
86.48449	136.2504	23.39033
86.65118	136.4194	23.39014
86.81782	136.5879	23.39016
86.98449	136.7569	23.39008
87.15266	136.9246	23.39008
87.32134	137.0917	23.39006
87.48882	137.2567	23.39003
87.65699	137.4249	23.39006
87.82450	137.5922	23.38998
87.99100	137.7586	23.38990
88.15766	137.9258	23.39002
88.32434	138.0942	23.38983
88.49100	138.2615	23.38980
88.65766	138.4289	23.38987
88.82468	138.5945	23.38980
88.99132	138.7616	23.38986
89.15800	138.9276	23.38970
89.32450	139.0926	23.38966
89.49116	139.2583	23.38962
89.65782	139.4246	23.38951
89.82450	139.5914	23.38960
89.99116	139.7578	23.38952
90.15782	139.9277	23.38955
90.32450	140.0926	23.38958
90.49132	140.2581	23.38955
90.65800	140.4246	23.38947
90.82468	140.5901	23.38946
90.99100	140.7562	23.38938
91.15949	140.9270	23.38947
91.32950	141.0998	23.38928
91.49618	141.2655	23.38910
91.66449	141.4344	23.38918
91.83282	141.6019	23.38908
92.00116	141.7698	23.38903
92.16950	141.9399	23.38900
92.33782	142.1092	23.38910
92.50616	142.2795	23.38900
92.67450	142.4476	23.38901
92.84282	142.6149	23.38890
93.01118	142.7832	23.38890
93.17950	142.9516	23.38881
93.34782	143.1181	23.38880
93.51618	143.2838	23.38882
93.68468	143.4498	23.38872
93.85300	143.6192	23.38864
94.02132	143.7882	23.38854
94.18934	143.9573	23.38870
94.35616	144.1238	23.38853
94.52282	144.2923	23.38851
94.68950	144.4590	23.38848
94.85632	144.6254	23.38845
95.02301	144.7926	23.38843
95.18950	144.9579	23.38824
95.35616	145.1225	23.38816
95.52282	145.2878	23.38822
95.68968	145.4538	23.38812
95.85632	145.6214	23.38808
96.02266	145.7883	23.38802
96.18950	145.9572	23.38809
96.35616	146.1263	23.38801
96.52282	146.2933	23.38796
96.68950	146.4574	23.38788
96.85616	146.6233	23.38773
97.02282	146.7953	23.38782
97.18950	146.9602	23.38763
97.35616	147.1266	23.38763
97.52450	147.2949	23.38766
97.69282	147.4624	23.38767
97.86118	147.6292	23.38759
98.02950	147.7994	23.38750
98.19782	147.9676	23.38744
98.36616	148.1346	23.38736
98.53449	148.3023	23.38734
98.70282	148.4682	23.38738
98.87118	148.6378	23.38729
99.03782	148.8048	23.38723
99.20450	148.9712	23.38723
99.37118	149.1405	23.38725
99.53782	149.3053	23.38720
99.70450	149.4749	23.38712
99.87118	149.6440	23.38712
100.0378	149.8105	23.38703
100.2045	149.9746	23.38690
100.3712	150.1399	23.38676
100.5380	150.3039	23.38684
100.7047	150.4696	23.38672
100.8710	150.6367	23.38670
101.0378	150.8051	23.38670
101.2045	150.9729	23.38660
101.3712	151.1386	23.38648
101.5378	151.3051	23.38626
101.7045	151.4746	23.38640
101.8712	151.6412	23.38619
102.0378	151.8072	23.38617
102.2062	151.9763	23.38625
102.3747	152.1433	23.38607
102.5430	152.3117	23.38611
102.7128	152.4803	23.38609
102.8795	152.6457	23.38590
103.0480	152.8159	23.38574
103.2163	152.9820	23.38565
103.3845	153.1500	23.38560
103.5528	153.3186	23.38548
103.7212	153.4879	23.38544
103.8895	153.6567	23.38526
104.0580	153.8252	23.38508
104.2263	153.9952	23.38508
104.3947	154.1626	23.38486
104.5630	154.3285	23.38472
104.7310	154.4974	23.38462
104.8995	154.6656	23.38426
105.0678	154.8351	23.38404
105.2362	155.0058	23.38370
105.4045	155.1768	23.38342
105.5730	155.3452	23.38302
105.7413	155.5128	23.38258
105.9093	155.6812	23.38200
106.0778	155.8467	23.38138
106.2462	156.0155	23.38064
106.4128	156.1834	23.37984
106.5795	156.3495	23.37874
106.7462	156.5159	23.37761
106.9130	156.6822	23.37640
107.0795	156.8502	23.37502
107.2462	157.0136	23.37332
107.4128	157.1832	23.37168
107.5795	157.3511	23.36963
107.7462	157.5166	23.36751
107.9128	157.6837	23.36533
108.0797	157.8505	23.36277
108.2463	158.0167	23.36043
108.4130	158.1841	23.35784
108.5793	158.3475	23.35510
108.7462	158.5125	23.35249
108.9128	158.6768	23.34953
109.0795	158.8469	23.34652
109.2462	159.0143	23.34359
109.4128	159.1794	23.34073
109.5812	159.3476	23.33772
109.7496	159.5144	23.33463
109.9180	159.6842	23.33171
110.0843	159.8527	23.32864
110.2512	160.0182	23.32581
110.4178	160.1834	23.32312
110.5845	160.3486	23.32023
110.7512	160.5176	23.31736
110.9180	160.6863	23.31492
111.0847	160.8531	23.31221
111.2510	161.0196	23.30966
111.4178	161.1870	23.30724
111.5845	161.3557	23.30492
111.7512	161.5212	23.30271
111.9178	161.6872	23.30040
112.0845	161.8522	23.29826
112.2512	162.0166	23.29635
112.4180	162.1819	23.29440
112.5843	162.3489	23.29230
112.7512	162.5170	23.29055
112.9178	162.6852	23.28876
113.0845	162.8525	23.28698
113.2520	163.0205	23.28526
113.4203	163.1883	23.28377
113.5888	163.3555	23.28220
113.7572	163.5250	23.28060
113.9255	163.6947	23.27926
114.0938	163.8614	23.27799
114.2622	164.0299	23.27665
114.4302	164.1963	23.27539
114.5986	164.3647	23.27414
114.7670	164.5325	23.27302
114.9355	164.7031	23.27183
115.1035	164.8724	23.27082
115.2712	165.0394	23.26968
115.4378	165.2056	23.26875
115.6045	165.3706	23.26773
115.7712	165.5370	23.26692
115.9380	165.7025	23.26596
116.1047	165.8684	23.26504
116.2713	166.0359	23.26422
116.4377	166.2037	23.26350
116.6045	166.3723	23.26271
116.7712	166.5377	23.26192
116.9378	166.7060	23.26130
117.1045	166.8761	23.26074
117.2712	167.0417	23.26000
117.4378	167.2056	23.25940
117.6045	167.3707	23.25860
117.7712	167.5390	23.25823
117.9378	167.7073	23.25780
118.1045	167.8724	23.25711
118.2712	168.0429	23.25682
118.4378	168.2077	23.25620
118.6062	168.3778	23.25569
118.7743	168.5434	23.25538
118.9427	168.7125	23.25491
119.1130	168.8820	23.25441
119.2793	169.0476	23.25410
119.4477	169.2172	23.25369
119.6143	169.3827	23.25323
119.7810	169.5480	23.25282
119.9477	169.7168	23.25255
120.1143	169.8842	23.25215
120.2810	170.0514	23.25189
120.4477	170.2164	23.25146
120.6145	170.3828	23.25108
120.7812	170.5489	23.25088
120.9478	170.7139	23.25046
121.1145	170.8769	23.25004
121.2812	171.0454	23.24988
121.4478	171.2122	23.24968
121.6145	171.3782	23.24939
121.7813	171.5473	23.24913
121.9480	171.7168	23.24894
122.1143	171.8867	23.24874
122.2812	172.0512	23.24843
122.4478	172.2158	23.24813
122.6145	172.3874	23.24800
122.7830	172.5584	23.24779
122.9512	172.7216	23.24752
123.1195	172.8886	23.24723
123.2878	173.0532	23.24700
123.4563	173.2204	23.24695
123.6245	173.3862	23.24675
123.7928	173.5575	23.24660
123.9610	173.7259	23.24642
124.1278	173.8935	23.24630
124.2947	174.0588	23.24608
124.4612	174.2234	23.24584
124.6278	174.3903	23.24570
124.7947	174.5570	23.24550
124.9612	174.7249	23.24539
125.1278	174.8947	23.24523
125.2947	175.0623	23.24513
125.4612	175.2306	23.24504
125.6278	175.3972	23.24470
125.7947	175.5658	23.24478
125.9612	175.7308	23.24462
126.1280	175.8950	23.24446
126.2945	176.0625	23.24435
126.4613	176.2291	23.24423
126.6278	176.3963	23.24416
126.7945	176.5641	23.24402
126.9613	176.7284	23.24389
127.1278	176.8933	23.24378
127.2963	177.0624	23.24366
127.4645	177.2316	23.24355
127.6330	177.3998	23.24340
127.7995	177.5673	23.24326
127.9662	177.7363	23.24320
128.1327	177.9020	23.24300
128.2995	178.0691	23.24292
128.4663	178.2350	23.24282
128.6328	178.3993	23.24245
128.7997	178.5652	23.24244
128.9662	178.7341	23.24254
129.1328	178.9012	23.24242
129.2997	179.0694	23.24234
129.4662	179.2350	23.24216
129.6330	179.4013	23.24202
129.7993	179.5678	23.24204
129.9662	179.7325	23.24194
130.1330	179.9004	23.24184
130.2995	180.0676	23.24177
130.4663	180.2367	23.24176
130.6328	180.4024	23.24162
130.8013	180.5689	23.24157
130.9678	180.7363	23.24144
131.1345	180.9029	23.24147
131.3013	181.0684	23.24130
131.4678	181.2360	23.24134
131.6345	181.4030	23.24131
131.8013	181.5680	23.24126
131.9678	181.7332	23.24130
132.1345	181.8994	23.24127
132.3013	182.0672	23.24126
132.4678	182.2327	23.24112
132.6347	182.3965	23.24116
132.8010	182.5634	23.24115
132.9678	182.7303	23.24105
133.1347	182.8971	23.24108
133.3012	183.0655	23.24102
133.4678	183.2342	23.24096
133.6345	183.4017	23.24088
133.8013	183.5679	23.24076
133.9677	183.7351	23.24082
134.1345	183.9026	23.24078
134.3012	184.0680	23.24064
134.4680	184.2358	23.24060
134.6344	184.4022	23.24065
134.8012	184.5688	23.24067
134.9680	184.7333	23.24056
135.1344	184.8986	23.24043
135.3012	185.0658	23.24042
135.4678	185.2331	23.24030
135.6347	185.3995	23.24035
135.8012	185.5637	23.24026
135.9678	185.7341	23.24030
136.1347	185.9008	23.24016
136.3010	186.0672	23.24024
136.4677	186.2330	23.24010
136.6345	186.4014	23.24014
136.8012	186.5704	23.24014
136.9678	186.7386	23.24008
137.1345	186.9035	23.24008
137.3013	187.0708	23.24000
137.4695	187.2397	23.24010
137.6378	187.4059	23.24004
137.8062	187.5732	23.23977
137.9745	187.7410	23.23972
138.1428	187.9101	23.23981
138.3114	188.0762	23.23970
138.4797	188.2448	23.23978
138.6478	188.4142	23.23978
138.8145	188.5811	23.23974
138.9812	188.7467	23.23966
139.1478	188.9151	23.23969
139.3147	189.0817	23.23982
139.4810	189.2497	23.23969
139.6478	189.4148	23.23957
139.8145	189.5805	23.23952
139.9812	189.7452	23.23953
140.1480	189.9133	23.23948
140.3147	190.0791	23.23949
140.4810	190.2484	23.23958
140.6476	190.4170	23.23946
140.8144	190.5822	23.23946
140.9814	190.7502	23.23948
141.1480	190.9173	23.23965
141.3147	191.0814	23.23955
141.4814	191.2484	23.23961
141.6478	191.4134	23.23949
141.8145	191.5776	23.23949
141.9828	191.7476	23.23940
142.1514	191.9215	23.23936
142.3194	192.0894	23.23930
142.4862	192.2576	23.23941
142.6528	192.4219	23.23924
142.8195	192.5881	23.23928
142.9862	192.7538	23.23927
143.1528	192.9198	23.23914
143.3195	193.0853	23.23920
143.4860	193.2516	23.23916
143.6530	193.4178	23.23914
143.8195	193.5851	23.23908
143.9862	193.7512	23.23916
144.1528	193.9211	23.23918
144.3197	194.0892	23.23918
144.4862	194.2550	23.23908
144.6528	194.4218	23.23914
144.8195	194.5890	23.23914
144.9862	194.7558	23.23911
145.1528	194.9214	23.23904
145.3194	195.0878	23.23898
145.4863	195.2552	23.23898
145.6530	195.4206	23.23900
145.8212	195.5887	23.23903
145.9895	195.7552	23.23898
146.1578	195.9250	23.23908
146.3245	196.0890	23.23899
146.4913	196.2581	23.23900
146.6578	196.4240	23.23892
146.8245	196.5918	23.23902
146.9912	196.7575	23.23895
147.1578	196.9231	23.23898
147.3244	197.0885	23.23892
147.4910	197.2560	23.23890
147.6580	197.4227	23.23885
147.8246	197.5878	23.23887
147.9913	197.7551	23.23888
148.1580	197.9245	23.23894
148.3246	198.0920	23.23890
148.4913	198.2605	23.23886
148.6578	198.4248	23.23889
148.8245	198.5928	23.23890
148.9912	198.7601	23.23890
149.1578	198.9267	23.23904
149.3245	199.0914	23.23903
149.4928	199.2599	23.23886
149.6628	199.4303	23.23877
149.8295	199.5980	23.23888
149.9964	199.7660	23.23894
150.1630	199.9324	23.23890
150.3295	200.0986	23.23883
150.4962	200.2636	23.23892
150.6628	200.4296	23.23892
150.8295	200.5950	23.23889
150.9960	200.7605	23.23880
151.1630	200.9272	23.23897
151.3297	201.0934	23.23884
151.4964	201.2592	23.23879
151.6627	201.4267	23.23882
151.8294	201.5957	23.23870
151.9964	201.7626	23.23873
152.1628	201.9287	23.23862
152.3295	202.0966	23.23863
152.4962	202.2628	23.23857
152.6628	202.4288	23.23858
152.8295	202.5956	23.23860
152.9962	202.7644	23.23864
153.1628	202.9312	23.23863
153.3302	203.0987	23.23869
153.4988	203.2694	23.23865
153.6670	203.4368	23.23874
153.8353	203.6042	23.23868
154.0036	203.7726	23.23872
154.1720	203.9394	23.23868
154.3403	204.1066	23.23866
154.5087	204.2712	23.23868
154.6772	204.4364	23.23851
154.8455	204.6064	23.23846
155.0138	204.7751	23.23862
155.1820	204.9445	23.23849
155.3503	205.1159	23.23854
155.5186	205.2844	23.23850
155.6862	205.4559	23.23860
155.8528	205.6227	23.23850
156.0195	205.7888	23.23841
156.1860	205.9558	23.23840
156.3526	206.1222	23.23848
156.5197	206.2902	23.23838
156.6864	206.4520	23.23828
156.8528	206.6176	23.23826
157.0195	206.7832	23.23833
157.1862	206.9505	23.23854
157.3526	207.1172	23.23850
157.5197	207.2835	23.23842
157.6864	207.4514	23.23848
157.8528	207.6208	23.23840
158.0195	207.7872	23.23851
158.1862	207.9542	23.23846
158.3526	208.1216	23.23861
158.5197	208.2894	23.23867
158.6862	208.4541	23.23858
158.8528	208.6180	23.23851
159.0212	208.7884	23.23858
159.1895	208.9556	23.23862
159.3578	209.1225	23.23853
159.5260	209.2902	23.23848
159.6930	209.4578	23.23823
159.8597	209.6256	23.23839
160.0262	209.7934	23.23845
160.1928	209.9584	23.23848
160.3595	210.1240	23.23853
160.5262	210.2880	23.23848
160.6928	210.4584	23.23844
160.8597	210.6278	23.23842
161.0264	210.7952	23.23852
161.1928	210.9644	23.23851
161.3595	211.1284	23.23834
161.5262	211.2945	23.23852
161.6928	211.4619	23.23850
161.8593	211.6267	23.23852
162.0264	211.7909	23.23828
162.1928	211.9572	23.23818
162.3595	212.1260	23.23840
162.5262	212.2919	23.23837
162.6927	212.4590	23.23827
162.8630	212.6299	23.23845
163.0297	212.7938	23.23826
163.1980	212.9624	23.23830
163.3662	213.1303	23.23832
163.5345	213.3010	23.23834
163.7028	213.4673	23.23825
163.8710	213.6366	23.23838
164.0397	213.8040	23.23832
164.2080	213.9716	23.23830
164.3763	214.1394	23.23830
164.5447	214.3095	23.23825
164.7130	214.4774	23.23838
164.8813	214.6483	23.23847
165.0495	214.8172	23.23842
165.2178	214.9832	23.23830
165.3862	215.1514	23.23832
165.5528	215.3177	23.23837
165.7195	215.4828	23.23838
165.8862	215.6486	23.23838
166.0527	215.8205	23.23829
166.2197	215.9893	23.23831
166.3864	216.1564	23.23830
166.5530	216.3219	23.23830
166.7194	216.4870	23.23829
166.8864	216.6531	23.23829
167.0530	216.8192	23.23835
167.2197	216.9838	23.23828
167.3864	217.1512	23.23850
167.5528	217.3196	23.23834
167.7195	217.4890	23.23820
167.8862	217.6546	23.23816
168.0528	217.8208	23.23821
168.2195	217.9863	23.23818
168.3862	218.1540	23.23824
168.5528	218.3195	23.23826
168.7195	218.4858	23.23826
168.8862	218.6493	23.23826
169.0528	218.8168	23.23830
169.2195	218.9842	23.23825
169.3862	219.1496	23.23838
169.5528	219.3172	23.23834
169.7195	219.4832	23.23831
169.8862	219.6540	23.23841
170.0528	219.8206	23.23843
170.2195	219.9850	23.23835
170.3862	220.1523	23.23842
170.5530	220.3192	23.23838
170.7194	220.4844	23.23834
170.8862	220.6485	23.23840
171.0528	220.8153	23.23842
171.2195	220.9834	23.23852
171.3862	221.1478	23.23856
171.5528	221.3150	23.23853
171.7195	221.4786	23.23834
171.8878	221.6490	23.23844
172.0562	221.8188	23.23834
172.2247	221.9896	23.23840
172.3930	222.1602	23.23830
172.5612	222.3277	23.23823
172.7295	222.4963	23.23820
172.8978	222.6634	23.23820
173.0662	222.8335	23.23831
173.2345	223.0029	23.23825
173.4028	223.1705	23.23822
173.5712	223.3365	23.23815
173.7395	223.5044	23.23818
173.9078	223.6730	23.23830
174.0745	223.8418	23.23822
174.2412	224.0094	23.23834
174.4078	224.1749	23.23826
174.5744	224.3434	23.23826
174.7413	224.5121	23.23833
174.9080	224.6777	23.23831
175.0745	224.8429	23.23830
175.2412	225.0084	23.23822
175.4078	225.1727	23.23814
175.5745	225.3384	23.23825
175.7412	225.5032	23.23824
175.9080	225.6726	23.23819
176.0746	225.8385	23.23809
176.2412	226.0054	23.23814
176.4078	226.1701	23.23808
176.5745	226.3362	23.23818
176.7410	226.5054	23.23818
176.9080	226.6744	23.23824
177.0745	226.8418	23.23814
177.2420	227.0097	23.23825
177.4103	227.1797	23.23833
177.5787	227.3492	23.23838
177.7472	227.5179	23.23834
177.9153	227.6859	23.23833
178.0837	227.8535	23.23826
178.2520	228.0205	23.23833
178.4203	228.1877	23.23819
178.5888	228.3548	23.23808
178.7570	228.5223	23.23820
178.9254	228.6912	23.23825
179.0926	228.8590	23.23833
179.2597	229.0247	23.23828
179.4262	229.1916	23.23826
179.5928	229.3620	23.23839
179.7595	229.5278	23.23838
179.9263	229.6914	23.23828
180.0928	229.8572	23.23842
180.2595	230.0253	23.23844
180.4260	230.1934	23.23854
180.5930	230.3584	23.23847
180.7595	230.5240	23.23839
180.9262	230.6908	23.23848
181.0926	230.8554	23.23848
181.2597	231.0214	23.23850
181.4263	231.1880	23.23854
181.5928	231.3548	23.23845
181.7595	231.5240	23.23840
181.9262	231.6904	23.23852
182.0930	231.8571	23.23859
182.2597	232.0244	23.23856
182.4278	232.1920	23.23852
182.5962	232.3590	23.23840
182.7645	232.5284	23.23832
182.9310	232.6967	23.23838
183.0980	232.8626	23.23844
183.2647	233.0291	23.23832
183.4313	233.1955	23.23820
183.5980	233.3639	23.23842
183.7645	233.5324	23.23831
183.9312	233.7011	23.23840
184.0977	233.8682	23.23836
184.2647	234.0326	23.23838
184.4313	234.1972	23.23831
184.5980	234.3628	23.23832
184.7647	234.5301	23.23840
184.9312	234.6977	23.23842
185.0978	234.8654	23.23840
185.2645	235.0306	23.23850
185.4312	235.1967	23.23852
185.5978	235.3616	23.23854
185.7645	235.5285	23.23865
185.9312	235.6954	23.23852
186.0995	235.8657	23.23865
186.2663	236.0326	23.23861
186.4328	236.1984	23.23855
186.5995	236.3648	23.23859
186.7662	236.5320	23.23854
186.9328	236.6974	23.23858
187.0994	236.8644	23.23857
187.2663	237.0335	23.23877
187.4330	237.1996	23.23873
187.5995	237.3672	23.23864
187.7662	237.5330	23.23864
187.9330	237.6994	23.23862
188.0995	237.8650	23.23856
188.2662	238.0326	23.23862
188.4328	238.1969	23.23856
188.5995	238.3642	23.23867
188.7660	238.5310	23.23865
188.9330	238.7010	23.23863
189.0995	238.8675	23.23871
189.2662	239.0347	23.23870
189.4344	239.2047	23.23864
189.6030	239.3702	23.23872
189.7712	239.5388	23.23872
189.9395	239.7054	23.23858
190.1076	239.8738	23.23858
190.2764	240.0429	23.23868
190.4445	240.2102	23.23867
190.6128	240.3768	23.23853
190.7812	240.5446	23.23855
190.9480	240.7125	23.23860
191.1145	240.8805	23.23870
191.2812	241.0477	23.23866
191.4478	241.2126	23.23863
191.6145	241.3784	23.23862
191.7813	241.5478	23.23866
191.9478	241.7141	23.23861
192.1145	241.8822	23.23858
192.2810	242.0460	23.23850
192.4480	242.2121	23.23851
192.6145	242.3810	23.23857
192.7812	242.5476	23.23854
192.9480	242.7160	23.23858
193.1145	242.8820	23.23861
193.2812	243.0505	23.23861
193.4478	243.2156	23.23858
193.6147	243.3825	23.23853
193.7813	243.5482	23.23860
193.9478	243.7134	23.23866
194.1145	243.8782	23.23863
194.2828	244.0466	23.23858
194.4496	244.2141	23.23864
194.6162	244.3818	23.23864
194.7828	244.5496	23.23858
194.9495	244.7172	23.23869
195.1163	244.8840	23.23868
195.2828	245.0480	23.23867
195.4495	245.2150	23.23852
195.6160	245.3801	23.23851
195.7830	245.5506	23.23858
195.9495	245.7164	23.23872
196.1162	245.8822	23.23870
196.2828	246.0462	23.23876
196.4494	246.2122	23.23870
196.6160	246.3778	23.23873
196.7830	246.5446	23.23888
196.9496	246.7105	23.23873
197.1162	246.8781	23.23886
197.2828	247.0489	23.23885
197.4495	247.2150	23.23893
197.6170	247.3825	23.23901
197.7844	247.5502	23.23886
197.9514	247.7162	23.23895
198.1180	247.8838	23.23895
198.2845	248.0509	23.23889
198.4512	248.2178	23.23888
198.6178	248.3832	23.23884
198.7845	248.5496	23.23895
198.9512	248.7159	23.23885
199.1178	248.8832	23.23887
199.2844	249.0505	23.23891
199.4510	249.2166	23.23892
199.6176	249.3825	23.23896
199.7845	249.5506	23.23896
199.9512	249.7171	23.23889
200.1178	249.8814	23.23881
200.2845	250.0487	23.23879
200.4512	250.2166	23.23892
200.6178	250.3833	23.23881
200.7845	250.5520	23.23888
200.9512	250.7223	23.23878
201.1195	250.8919	23.23864
201.2878	251.0578	23.23870
201.4545	251.2220	23.23874
201.6212	251.3865	23.23874
201.7878	251.5514	23.23870
201.9544	251.7206	23.23876
202.1210	251.8872	23.23878
202.2878	252.0534	23.23870
202.4545	252.2199	23.23882
202.6212	252.3853	23.23878
202.7878	252.5524	23.23886
202.9544	252.7196	23.23877
203.1210	252.8889	23.23890
203.2880	253.0557	23.23890
203.4547	253.2228	23.23898
203.6213	253.3894	23.23899
203.7878	253.5556	23.23902
203.9545	253.7220	23.23892
204.1210	253.8876	23.23890
204.2880	254.0548	23.23894
204.4547	254.2225	23.23890
204.6230	254.3886	23.23899
204.7913	254.5564	23.23895
204.9597	254.7250	23.23902
205.1280	254.8932	23.23903
205.2962	255.0608	23.23907
205.4646	255.2301	23.23898
205.6330	255.3997	23.23894
205.8012	255.5692	23.23892
205.9695	255.7353	23.23883
206.1378	255.9042	23.23889
206.3062	256.0748	23.23892
206.4745	256.2426	23.23894
206.6430	256.4092	23.23886
206.8113	256.5770	23.23877
206.9794	256.7446	23.23884
207.1478	256.9123	23.23888
207.3162	257.0809	23.23899
207.4845	257.2504	23.23910
207.6528	257.4196	23.23905
207.8213	257.5880	23.23910
207.9897	257.7554	23.23904
208.1576	257.9223	23.23908
208.3260	258.0921	23.23903
208.4960	258.2622	23.23906
208.6628	258.4282	23.23898
208.8312	258.5984	23.23906
208.9995	258.7677	23.23900
209.1662	258.9348	23.23905
209.3328	259.0998	23.23905
209.4996	259.2655	23.23895
209.6663	259.4332	23.23897
209.8330	259.5983	23.23903
209.9996	259.7668	23.23904
210.1660	259.9339	23.23922
210.3328	260.0985	23.23907
210.4995	260.2669	23.23912
210.6662	260.4298	23.23908
210.8328	260.5976	23.23904
210.9995	260.7671	23.23910
211.1662	260.9336	23.23906
211.3328	261.1002	23.23892
211.4995	261.2668	23.23886
211.6662	261.4328	23.23885
211.8328	261.6004	23.23898
211.9995	261.7684	23.23898
212.1662	261.9356	23.23904
212.3347	262.1032	23.23890
212.5030	262.2687	23.23884
212.6713	262.4351	23.23879
212.8396	262.6025	23.23881
213.0080	262.7710	23.23881
213.1746	262.9380	23.23881
213.3413	263.1054	23.23878
213.5080	263.2744	23.23884
213.6746	263.4422	23.23893
213.8413	263.6100	23.23899
214.0078	263.7768	23.23909
214.1745	263.9426	23.23916
214.3412	264.1057	23.23915
214.5078	264.2730	23.23913
214.6745	264.4382	23.23903
214.8412	264.6060	23.23906
215.0078	264.7748	23.23923
215.1745	264.9410	23.23922
215.3412	265.1045	23.23910
215.5078	265.2694	23.23922
215.6745	265.4372	23.23934
215.8412	265.6036	23.23920
216.0078	265.7700	23.23922
216.1745	265.9386	23.23935
216.3412	266.1065	23.23944
216.5078	266.2738	23.23946
216.6745	266.4436	23.23942
216.8412	266.6107	23.23942
217.0076	266.7782	23.23946
217.1745	266.9408	23.23938
217.3412	267.1068	23.23939
217.5078	267.2730	23.23942
217.6745	267.4394	23.23948
217.8412	267.6058	23.23933
218.0078	267.7743	23.23947
218.1745	267.9401	23.23947
218.3412	268.1052	23.23945
218.5078	268.2735	23.23950
218.6745	268.4425	23.23960
218.8412	268.6088	23.23956
219.0078	268.7757	23.23962
219.1745	268.9403	23.23956
219.3410	269.1060	23.23956
219.5076	269.2730	23.23953
219.6744	269.4411	23.23964
219.8410	269.6091	23.23956
220.0080	269.7750	23.23960
220.1746	269.9404	23.23952
220.3413	270.1066	23.23953
220.5080	270.2764	23.23956
220.6745	270.4422	23.23958
220.8412	270.6084	23.23967
221.0078	270.7752	23.23958
221.1745	270.9424	23.23972
221.3412	271.1091	23.23952
221.5078	271.2764	23.23959
221.6744	271.4403	23.23958
221.8413	271.6041	23.23950
222.0080	271.7724	23.23950
222.1746	271.9414	23.23960
222.3412	272.1103	23.23956
222.5078	272.2759	23.23949
222.6745	272.4429	23.23949
222.8428	272.6096	23.23942
223.0127	272.7790	23.23946
223.1797	272.9464	23.23948
223.3478	273.1148	23.23940
223.5162	273.2808	23.23927
223.6845	273.4494	23.23930
223.8528	273.6168	23.23938
224.0212	273.7856	23.23940
224.1895	273.9538	23.23948
224.3578	274.1219	23.23948
224.5262	274.2904	23.23930
224.6945	274.4569	23.23934
224.8628	274.6264	23.23932
225.0313	274.7971	23.23938
225.1995	274.9672	23.23948
225.3678	275.1363	23.23952
225.5362	275.3053	23.23940
225.7043	275.4724	23.23944
225.8730	275.6386	23.23944
226.0413	275.8058	23.23950
226.2095	275.9742	23.23947
226.3778	276.1431	23.23948
226.5462	276.3110	23.23946
226.7145	276.4797	23.23944
226.8813	276.6487	23.23956
227.0480	276.8160	23.23955
227.2146	276.9812	23.23955
227.3812	277.1490	23.23950
227.5478	277.3145	23.23940
227.7145	277.4812	23.23944
227.8810	277.6490	23.23950
228.0480	277.8146	23.23952
228.2146	277.9815	23.23956
228.3812	278.1484	23.23947
228.5478	278.3142	23.23946
228.7145	278.4821	23.23949
228.8813	278.6493	23.23940
229.0480	278.8140	23.23941
229.2145	278.9801	23.23934
229.3812	279.1479	23.23952
229.5478	279.3155	23.23956
229.7146	279.4828	23.23961
229.8813	279.6492	23.23967
230.0495	279.8167	23.23966
230.2178	279.9840	23.23970
230.3862	280.1516	23.23976
230.5545	280.3178	23.23967
230.7228	280.4844	23.23961
230.8913	280.6535	23.23970
231.0597	280.8228	23.23968
231.2280	280.9930	23.23969
231.3963	281.1622	23.23976
231.5645	281.3305	23.23966
231.7328	281.4964	23.23959
231.9012	281.6655	23.23952
232.0677	281.8337	23.23949
232.2347	282.0008	23.23959
232.4012	282.1658	23.23952
232.5678	282.3344	23.23962
232.7345	282.5003	23.23973
232.9014	282.6670	23.23963
233.0678	282.8344	23.23964
233.2345	283.0014	23.23952
233.4010	283.1678	23.23956
233.5680	283.3336	23.23947
233.7345	283.5019	23.23957
233.9012	283.6684	23.23950
234.0678	283.8349	23.23964
234.2344	283.9996	23.23952
234.4014	284.1659	23.23952
234.5678	284.3310	23.23946
234.7345	284.4990	23.23937
234.9014	284.6654	23.23955
235.0678	284.8318	23.23946
235.2345	285.0001	23.23942
235.4014	285.1678	23.23955
235.5678	285.3360	23.23955
235.7345	285.5002	23.23961
235.9014	285.6682	23.23975
236.0680	285.8352	23.23975
236.2345	286.0018	23.23973
236.4010	286.1687	23.23972
236.5678	286.3344	23.23984
236.7345	286.5004	23.23986
236.9010	286.6678	23.23976
237.0678	286.8345	23.23981
237.2345	287.0010	23.23970
237.4010	287.1682	23.23972
237.5680	287.3330	23.23966
237.7345	287.5014	23.23990
237.9012	287.6671	23.23978
238.0677	287.8344	23.23976
238.2347	288.0020	23.23984
238.4028	288.1687	23.23982
238.5710	288.3355	23.23976
238.7395	288.5055	23.23980
238.9078	288.6756	23.23969
239.0760	288.8436	23.23980
239.2445	289.0110	23.23966
239.4128	289.1784	23.23974
239.5793	289.3448	23.23986
239.7462	289.5117	23.23978
239.9128	289.6777	23.23977
240.0793	289.8442	23.23972
240.2462	290.0097	23.23956
240.4128	290.1780	23.23978
240.5793	290.3448	23.23976
240.7463	290.5104	23.23969
240.9128	290.6790	23.23976
241.0795	290.8458	23.23980
241.2463	291.0137	23.23986
241.4130	291.1786	23.23982
241.5795	291.3438	23.23986
241.7462	291.5091	23.23980
241.9130	291.6774	23.23992
242.0795	291.8450	23.24002
242.2462	292.0112	23.24002
242.4128	292.1795	23.23998
242.5797	292.3452	23.23992
242.7472	292.5107	23.23985
242.9153	292.6791	23.23992
243.0826	292.8472	23.24002
243.2496	293.0146	23.23994
243.4162	293.1815	23.23994
243.5828	293.3490	23.24003
243.7496	293.5177	23.23998
243.9162	293.6834	23.24000
244.0828	293.8490	23.23999
244.2493	294.0164	23.23999
244.4163	294.1805	23.23990
244.5828	294.3484	23.23984
244.7495	294.5154	23.23998
244.9160	294.6832	23.23986
245.0830	294.8491	23.23997
245.2495	295.0147	23.23992
245.4162	295.1816	23.24002
245.5830	295.3496	23.23992
245.7495	295.5141	23.23982
245.9162	295.6806	23.23963
246.0826	295.8470	23.23990
246.2496	296.0138	23.23978
246.4178	296.1824	23.23988
246.5862	296.3504	23.23980
246.7544	296.5200	23.23982
246.9230	296.6904	23.23994
247.0912	296.8581	23.23994
247.2594	297.0276	23.23999
247.4297	297.1966	23.24000
247.5962	297.3631	23.24005
247.7645	297.5310	23.24009
247.9330	297.6996	23.24000
248.1012	297.8676	23.24013
248.2710	298.0381	23.24013
248.4378	298.2046	23.24015
248.6062	298.3714	23.24002
248.7744	298.5403	23.24006
248.9428	298.7070	23.24017
249.1112	298.8758	23.24021
249.2793	299.0441	23.24009
249.4480	299.2128	23.24019
249.6163	299.3797	23.24019
249.7845	299.5478	23.24021
249.9528	299.7197	23.24024