File: TGA/2023_07_13_CBD_powder_1cpm.txt
CLOSED
Version	0.4
Run	875
Instrument	2950 TGA       V5.4A
Module	TGA 1000 øC
Sample	2023_07_13_CBD_powder_1cpm
Size	12.3330	mg
Method	50C to 300C at 1 cpm
Operator	SBK
Comment	2023_07_13_CBD_powder_1cpm
Xcomment	Pan: Platinum           Gas1: Nitrogen  40          Gas2: Nitrogen  40
Text	2023_07_13_CBD_powder_1cpm
Text	Third run with CBD powder after new calib
Kcell	1.00000
TempCal	2	pts	156.68	152.50,	376.53	354.00
Thresholds	0.050	0.0000
Controls	Gas 1  Event Off  Sampling 2.0 sec/pt
Nsig	3
Sig1	Time (min)
Sig2	Temperature (øC)
Sig3	Weight (mg)
Date	13-Jul-23
Time	10:44
File	C:\TA\Data\TGA\Skyler\2023_07_13_CBD_powder_1cpm.001
OrgFile	C:\TA\Data\TGA\Skyler\2023_07_13_CBD_powder_1cpm.001
StartOfData
0.0000000	50.08414	12.32346
0.1661667	50.12328	12.32340
0.3326666	50.21332	12.32338
0.4993334	50.33787	12.32344
0.6660000	50.47502	12.32342
0.8328334	50.62847	12.32334
0.9995000	50.79102	12.32322
1.166000	50.95246	12.32308
1.334334	51.11670	12.32294
1.502500	51.28408	12.32292
1.671000	51.45478	12.32294
1.841000	51.62352	12.32281
2.009167	51.79200	12.32272
2.176167	51.95728	12.32264
2.342666	52.12360	12.32264
2.509334	52.28682	12.32262
2.676167	52.44879	12.32249
2.842666	52.61878	12.32244
3.009334	52.78098	12.32248
3.175833	52.94180	12.32235
3.342666	53.11156	12.32234
3.509334	53.27792	12.32234
3.675833	53.44392	12.32227
3.842833	53.60770	12.32216
4.009500	53.77171	12.32214
4.176000	53.94509	12.32210
4.342666	54.10996	12.32208
4.509333	54.27410	12.32201
4.676166	54.44120	12.32200
4.842666	54.60636	12.32196
5.009333	54.76959	12.32193
5.176000	54.92644	12.32198
5.342666	55.09045	12.32187
5.509332	55.25981	12.32193
5.675832	55.42922	12.32193
5.842834	55.59565	12.32177
6.009500	55.76295	12.32166
6.176166	55.92951	12.32172
6.342834	56.09861	12.32160
6.509332	56.27059	12.32156
6.676000	56.44310	12.32155
6.842666	56.61030	12.32137
7.009168	56.77717	12.32132
7.177832	56.94900	12.32143
7.347668	57.11916	12.32138
7.516000	57.28691	12.32133
7.684500	57.45496	12.32131
7.852668	57.61952	12.32128
8.022668	57.78725	12.32111
8.191000	57.95498	12.32119
8.359332	58.12170	12.32114
8.527668	58.28904	12.32107
8.696168	58.46524	12.32105
8.866168	58.63491	12.32105
9.034332	58.79932	12.32096
9.202668	58.96115	12.32093
9.372666	59.12963	12.32087
9.541000	59.29158	12.32075
9.707666	59.46487	12.32068
9.874168	59.63629	12.32078
10.04117	59.80097	12.32062
10.20767	59.96258	12.32051
10.37433	60.12636	12.32050
10.54084	60.30145	12.32053
10.70783	60.47502	12.32043
10.87450	60.64310	12.32027
11.04100	60.81606	12.32040
11.20766	60.97955	12.32047
11.37434	61.14090	12.32038
11.54117	61.30750	12.32033
11.70783	61.48023	12.32024
11.87450	61.64346	12.32023
12.04100	61.80484	12.32016
12.20766	61.96703	12.32010
12.37600	62.12930	12.31985
12.54450	62.29918	12.31972
12.71434	62.46916	12.31969
12.88266	62.64626	12.31978
13.05100	62.81314	12.31958
13.21950	62.97578	12.31956
13.38934	63.14611	12.31946
13.55766	63.31306	12.31944
13.72600	63.48270	12.31953
13.89450	63.65408	12.31934
14.06284	63.82612	12.31931
14.23283	63.99540	12.31918
14.40100	64.16182	12.31907
14.56934	64.33342	12.31903
14.73767	64.50250	12.31900
14.90750	64.67193	12.31888
15.07617	64.83967	12.31875
15.24434	65.01050	12.31877
15.41434	65.17965	12.31870
15.58266	65.35208	12.31868
15.75083	65.51620	12.31869
15.91950	65.68438	12.31860
16.08950	65.85612	12.31860
16.25767	66.02318	12.31837
16.42600	66.19138	12.31819
16.59434	66.36366	12.31804
16.76434	66.53181	12.31786
16.93266	66.70069	12.31746
17.09934	66.86772	12.31706
17.26617	67.03624	12.31681
17.43266	67.20043	12.31655
17.59934	67.36772	12.31636
17.76600	67.53022	12.31626
17.93266	67.69600	12.31612
18.09917	67.85850	12.31590
18.26617	68.02190	12.31590
18.43266	68.19125	12.31579
18.59934	68.36158	12.31569
18.76600	68.52886	12.31569
18.93266	68.70085	12.31579
19.09934	68.86860	12.31580
19.26617	69.03653	12.31563
19.43266	69.20512	12.31557
19.59934	69.37796	12.31554
19.76684	69.54425	12.31542
19.93500	69.71432	12.31536
20.10450	69.88256	12.31526
20.27367	70.05060	12.31527
20.44184	70.21466	12.31528
20.61016	70.37975	12.31524
20.77934	70.53665	12.31516
20.94850	70.70193	12.31517
21.11684	70.86594	12.31511
21.28516	71.03391	12.31505
21.45434	71.20868	12.31498
21.62433	71.38243	12.31512
21.79266	71.55741	12.31505
21.95917	71.73052	12.31496
22.12583	71.89306	12.31500
22.29283	72.05962	12.31502
22.45950	72.22375	12.31512
22.62600	72.39087	12.31494
22.79266	72.56100	12.31487
22.95934	72.73219	12.31488
23.12583	72.89395	12.31476
23.29283	73.05493	12.31474
23.45950	73.21812	12.31466
23.62600	73.37842	12.31460
23.79266	73.54292	12.31460
23.95934	73.71412	12.31456
24.12600	73.87794	12.31454
24.29266	74.03951	12.31444
24.45950	74.21454	12.31434
24.62783	74.39288	12.31423
24.79766	74.56343	12.31422
24.96600	74.73912	12.31419
25.13433	74.90612	12.31416
25.30266	75.07384	12.31416
25.47117	75.24381	12.31402
25.64117	75.40813	12.31399
25.80950	75.57100	12.31404
25.97783	75.74394	12.31403
26.14767	75.91362	12.31398
26.31600	76.08581	12.31394
26.48433	76.24910	12.31384
26.65266	76.42316	12.31379
26.82100	76.58991	12.31369
26.99083	76.76147	12.31364
27.15950	76.92832	12.31361
27.32783	77.09172	12.31348
27.49783	77.26024	12.31344
27.66616	77.43005	12.31340
27.83433	77.60068	12.31350
28.00266	77.76695	12.31343
28.17283	77.93160	12.31337
28.34117	78.09843	12.31336
28.50950	78.26712	12.31336
28.67766	78.43776	12.31329
28.84766	78.61656	12.31320
29.01600	78.78964	12.31317
29.18433	78.94926	12.31304
29.35266	79.11734	12.31296
29.51934	79.29040	12.31292
29.68600	79.45488	12.31289
29.85266	79.60932	12.31281
30.01934	79.78016	12.31264
30.18617	79.94814	12.31272
30.35283	80.11380	12.31266
30.51934	80.27670	12.31268
30.68600	80.44485	12.31258
30.85266	80.62196	12.31264
31.01934	80.79256	12.31252
31.18600	80.95700	12.31249
31.35266	81.12488	12.31240
31.51917	81.29442	12.31238
31.68617	81.46172	12.31227
31.85283	81.62782	12.31228
32.01916	81.79682	12.31224
32.18916	81.96297	12.31216
32.35750	82.12397	12.31204
32.52583	82.29574	12.31207
32.69450	82.46402	12.31201
32.86284	82.63116	12.31196
33.03266	82.80426	12.31202
33.20100	82.97179	12.31199
33.36934	83.13964	12.31197
33.53600	83.30856	12.31206
33.70284	83.47626	12.31198
33.86950	83.63722	12.31194
34.03600	83.80256	12.31191
34.20266	83.96616	12.31184
34.36934	84.12961	12.31177
34.53600	84.29609	12.31164
34.70284	84.46636	12.31165
34.86934	84.63501	12.31146
35.03600	84.80512	12.31156
35.20266	84.96844	12.31133
35.36934	85.13538	12.31129
35.53617	85.30111	12.31131
35.70284	85.46678	12.31126
35.86950	85.63432	12.31110
36.03933	85.80450	12.31122
36.20767	85.96892	12.31106
36.37600	86.13582	12.31102
36.54434	86.30571	12.31100
36.71266	86.47866	12.31095
36.88283	86.64543	12.31093
37.05117	86.81134	12.31097
37.21933	86.98231	12.31086
37.38766	87.15184	12.31073
37.55416	87.32120	12.31064
37.72117	87.48848	12.31055
37.88766	87.65431	12.31046
38.05433	87.82266	12.31033
38.22100	87.98934	12.31031
38.38766	88.15430	12.31019
38.55450	88.31489	12.31017
38.72117	88.48140	12.31008
38.88750	88.64603	12.31016
39.05433	88.81266	12.31019
39.22100	88.98174	12.31010
39.38766	89.15118	12.31008
39.55433	89.31844	12.30995
39.72100	89.48687	12.30999
39.88766	89.65356	12.30984
40.05433	89.81965	12.30986
40.22434	89.99011	12.30988
40.39266	90.15571	12.30986
40.56100	90.32024	12.30966
40.73100	90.48938	12.30968
40.89934	90.65078	12.30968
41.06766	90.82120	12.30954
41.23617	90.99451	12.30945
41.40450	91.16524	12.30927
41.57450	91.33196	12.30932
41.74083	91.49784	12.30915
41.90766	91.66541	12.30898
42.07416	91.83592	12.30900
42.24117	92.00225	12.30894
42.40766	92.17101	12.30885
42.57434	92.33992	12.30879
42.74100	92.50701	12.30871
42.90766	92.67011	12.30858
43.07434	92.83226	12.30851
43.24100	92.99874	12.30850
43.40750	93.16711	12.30850
43.57450	93.33361	12.30843
43.74117	93.50309	12.30831
43.90766	93.67405	12.30820
44.07434	93.84542	12.30818
44.24100	94.01001	12.30803
44.40850	94.17041	12.30799
44.57683	94.33910	12.30795
44.74434	94.50731	12.30787
44.91083	94.67303	12.30770
45.07750	94.84155	12.30773
45.24450	95.01156	12.30761
45.41100	95.17976	12.30758
45.57766	95.34364	12.30741
45.74450	95.50892	12.30730
45.91117	95.67406	12.30704
46.07766	95.83974	12.30698
46.24434	96.00328	12.30699
46.41100	96.16891	12.30687
46.57784	96.33566	12.30671
46.74450	96.50074	12.30665
46.91117	96.66674	12.30663
47.07784	96.83559	12.30645
47.24434	97.00414	12.30638
47.41100	97.16972	12.30618
47.57766	97.33872	12.30628
47.74417	97.50457	12.30605
47.91083	97.67134	12.30602
48.07784	97.83712	12.30596
48.24434	98.00311	12.30567
48.41100	98.16764	12.30555
48.57750	98.33420	12.30557
48.74450	98.50019	12.30540
48.91117	98.66996	12.30524
49.07784	98.84113	12.30514
49.24450	99.00688	12.30526
49.41117	99.17469	12.30502
49.57766	99.33984	12.30486
49.74434	99.50481	12.30485
49.91100	99.67012	12.30471
50.07766	99.83199	12.30460
50.24766	100.0024	12.30457
50.41600	100.1730	12.30443
50.58433	100.3405	12.30428
50.75266	100.5133	12.30416
50.92100	100.6815	12.30403
51.09083	100.8539	12.30388
51.25950	101.0231	12.30376
51.42783	101.1902	12.30334
51.59766	101.3605	12.30312
51.76600	101.5280	12.30303
51.93433	101.6934	12.30290
52.10266	101.8552	12.30267
52.27266	102.0242	12.30262
52.44100	102.1954	12.30254
52.60933	102.3674	12.30232
52.77582	102.5367	12.30211
52.94283	102.7042	12.30192
53.10950	102.8696	12.30175
53.27617	103.0356	12.30164
53.44283	103.2061	12.30143
53.60950	103.3731	12.30130
53.77617	103.5426	12.30117
53.94266	103.7144	12.30104
54.10933	103.8816	12.30091
54.27600	104.0452	12.30072
54.44266	104.2102	12.30052
54.60950	104.3746	12.30032
54.77617	104.5376	12.30020
54.94283	104.7018	12.30006
55.10933	104.8700	12.29979
55.27600	105.0365	12.29958
55.44266	105.2029	12.29950
55.60933	105.3654	12.29929
55.77600	105.5346	12.29906
55.94283	105.7027	12.29896
56.10950	105.8698	12.29863
56.27600	106.0409	12.29846
56.44266	106.2080	12.29824
56.60933	106.3755	12.29804
56.77600	106.5376	12.29791
56.94266	106.7050	12.29754
57.10950	106.8714	12.29735
57.27582	107.0366	12.29716
57.44266	107.2034	12.29703
57.60933	107.3697	12.29679
57.77600	107.5353	12.29651
57.94433	107.7037	12.29617
58.11433	107.8720	12.29592
58.28266	108.0388	12.29564
58.45100	108.2102	12.29545
58.61934	108.3808	12.29528
58.78933	108.5476	12.29497
58.95766	108.7202	12.29472
59.12600	108.8884	12.29449
59.29434	109.0578	12.29418
59.46266	109.2273	12.29401
59.63266	109.3957	12.29367
59.79918	109.5620	12.29334
59.96600	109.7270	12.29298
60.13266	109.8951	12.29285
60.29932	110.0621	12.29260
60.46600	110.2300	12.29230
60.63266	110.3943	12.29198
60.79932	110.5621	12.29166
60.96600	110.7291	12.29133
61.13266	110.8974	12.29111
61.29932	111.0642	12.29076
61.46600	111.2250	12.29057
61.63266	111.3936	12.29036
61.79932	111.5629	12.29017
61.96600	111.7306	12.28978
62.13266	111.8967	12.28936
62.29932	112.0636	12.28905
62.46684	112.2222	12.28877
62.63516	112.3914	12.28829
62.80450	112.5631	12.28791
62.97368	112.7344	12.28772
63.14184	112.9039	12.28734
63.30933	113.0714	12.28698
63.47600	113.2385	12.28656
63.64266	113.4014	12.28620
63.80933	113.5665	12.28585
63.97617	113.7323	12.28547
64.14282	113.8985	12.28506
64.30918	114.0633	12.28458
64.47600	114.2319	12.28423
64.64268	114.4008	12.28384
64.80933	114.5662	12.28344
64.97600	114.7334	12.28312
65.14268	114.8992	12.28264
65.30918	115.0674	12.28220
65.47600	115.2346	12.28173
65.64268	115.3996	12.28125
65.80932	115.5681	12.28090
65.97600	115.7356	12.28046
66.14268	115.9030	12.28016
66.30932	116.0753	12.27962
66.47600	116.2423	12.27919
66.64268	116.4084	12.27878
66.80932	116.5753	12.27831
66.97600	116.7414	12.27792
67.14268	116.9068	12.27741
67.30932	117.0723	12.27699
67.47600	117.2391	12.27642
67.64282	117.4042	12.27599
67.80950	117.5685	12.27552
67.97600	117.7354	12.27494
68.14268	117.8986	12.27432
68.30932	118.0647	12.27380
68.47784	118.2325	12.27329
68.64616	118.4006	12.27284
68.81600	118.5730	12.27216
68.98434	118.7415	12.27157
69.15266	118.9066	12.27107
69.32266	119.0760	12.27050
69.49100	119.2437	12.26980
69.65932	119.4135	12.26931
69.82766	119.5824	12.26880
69.99766	119.7536	12.26805
70.16600	119.9288	12.26754
70.33434	120.0992	12.26686
70.50268	120.2648	12.26632
70.67266	120.4377	12.26577
70.84100	120.5871	12.26513
71.00932	120.7553	12.26445
71.17782	120.9314	12.26390
71.34616	121.1054	12.26326
71.51582	121.2778	12.26246
71.68250	121.4448	12.26177
71.84950	121.6129	12.26102
72.01616	121.7824	12.26039
72.18250	121.9505	12.25974
72.34918	122.1199	12.25901
72.51582	122.2898	12.25836
72.68250	122.4627	12.25767
72.84918	122.6275	12.25701
73.01582	122.7942	12.25625
73.18250	122.9627	12.25544
73.34934	123.1225	12.25469
73.51600	123.2882	12.25384
73.68266	123.4506	12.25305
73.84934	123.6126	12.25225
74.01600	123.7727	12.25138
74.18432	123.9390	12.25063
74.35266	124.1042	12.24997
74.52266	124.2737	12.24903
74.69100	124.4414	12.24825
74.85934	124.6112	12.24734
75.02782	124.7835	12.24642
75.19782	124.9559	12.24556
75.36582	125.1214	12.24460
75.53266	125.2885	12.24369
75.69934	125.4579	12.24272
75.86600	125.6308	12.24189
76.03266	125.7986	12.24079
76.19934	125.9630	12.23974
76.36600	126.1280	12.23889
76.53266	126.2952	12.23797
76.69934	126.4602	12.23698
76.86582	126.6243	12.23581
77.03284	126.7932	12.23494
77.19950	126.9506	12.23384
77.36616	127.1155	12.23285
77.53266	127.2817	12.23184
77.69934	127.4252	12.23084
77.86600	127.5653	12.22989
78.03266	127.7182	12.22886
78.20100	127.8790	12.22784
78.36932	128.0508	12.22678
78.53766	128.2254	12.22569
78.70766	128.4208	12.22449
78.87434	128.6279	12.22341
79.04100	128.8236	12.22229
79.20766	129.0096	12.22100
79.37434	129.1841	12.21979
79.54100	129.3534	12.21856
79.70766	129.5196	12.21735
79.87434	129.6782	12.21603
80.04100	129.8359	12.21490
80.20766	129.9975	12.21369
80.37434	130.1588	12.21234
80.54100	130.3175	12.21113
80.70782	130.4776	12.20978
80.87450	130.6299	12.20852
81.04116	130.7724	12.20706
81.20782	130.8883	12.20568
81.37450	131.0092	12.20433
81.54166	131.1483	12.20288
81.71016	131.3071	12.20160
81.87768	131.4766	12.20019
82.04434	131.6571	12.19888
82.21100	131.8429	12.19738
82.37768	132.0294	12.19591
82.54434	132.2204	12.19446
82.71100	132.4056	12.19299
82.87768	132.5878	12.19145
83.04434	132.7661	12.19004
83.21118	132.9414	12.18851
83.37782	133.1159	12.18708
83.54450	133.2879	12.18535
83.71118	133.4588	12.18371
83.87768	133.6295	12.18217
84.04434	133.8021	12.18062
84.21100	133.9736	12.17896
84.37768	134.1414	12.17722
84.54450	134.3100	12.17551
84.71450	134.4795	12.17376
84.88250	134.6463	12.17190
85.04932	134.8086	12.17006
85.21601	134.9731	12.16844
85.38266	135.1398	12.16673
85.54932	135.3027	12.16486
85.71616	135.4657	12.16306
85.88282	135.6385	12.16128
86.04932	135.8061	12.15948
86.21601	135.9708	12.15749
86.38266	136.1372	12.15559
86.54932	136.3056	12.15364
86.71616	136.4743	12.15165
86.88282	136.6409	12.14974
87.04916	136.8069	12.14770
87.21601	136.9708	12.14557
87.38266	137.1388	12.14365
87.54932	137.3059	12.14157
87.71782	137.4743	12.13943
87.88600	137.6399	12.13732
88.05434	137.8064	12.13523
88.22450	137.9751	12.13282
88.39282	138.1478	12.13068
88.56084	138.3166	12.12843
88.72766	138.4816	12.12603
88.89434	138.6478	12.12393
89.06100	138.8158	12.12158
89.22784	138.9839	12.11931
89.39450	139.1531	12.11706
89.56100	139.3230	12.11461
89.72766	139.4905	12.11222
89.89434	139.6558	12.10988
90.06100	139.8226	12.10732
90.22766	139.9881	12.10484
90.39450	140.1545	12.10233
90.56084	140.3192	12.09975
90.72766	140.4844	12.09714
90.89434	140.6489	12.09461
91.06100	140.8163	12.09211
91.22766	140.9843	12.08930
91.39766	141.1531	12.08654
91.56601	141.3217	12.08384
91.73449	141.4899	12.08101
91.90282	141.6580	12.07819
92.07082	141.8269	12.07543
92.24082	141.9981	12.07259
92.40934	142.1663	12.06974
92.57600	142.3319	12.06676
92.74266	142.4988	12.06378
92.90934	142.6648	12.06075
93.07600	142.8333	12.05781
93.24266	142.9986	12.05475
93.40934	143.1643	12.05169
93.57600	143.3319	12.04860
93.74266	143.4992	12.04558
93.90934	143.6654	12.04240
94.07600	143.8333	12.03920
94.24266	143.9984	12.03596
94.40934	144.1652	12.03268
94.57616	144.3308	12.02949
94.74282	144.4989	12.02614
94.90949	144.6650	12.02277
95.07782	144.8357	12.01935
95.24618	145.0054	12.01580
95.41618	145.1754	12.01221
95.58450	145.3442	12.00875
95.75268	145.5131	12.00524
95.92266	145.6824	12.00137
96.09101	145.8502	11.99772
96.25934	146.0168	11.99416
96.42766	146.1811	11.99034
96.59766	146.3505	11.98647
96.76618	146.5209	11.98261
96.93450	146.6894	11.97874
97.10250	146.8569	11.97486
97.27101	147.0258	11.97082
97.44101	147.1964	11.96661
97.60934	147.3646	11.96265
97.77766	147.5359	11.95860
97.94766	147.7042	11.95429
98.11616	147.8701	11.95023
98.28418	148.0386	11.94598
98.45250	148.2073	11.94176
98.61932	148.3748	11.93752
98.78601	148.5421	11.93334
98.95266	148.7086	11.92881
99.11932	148.8704	11.92437
99.28601	149.0356	11.92007
99.45282	149.2014	11.91561
99.61916	149.3732	11.91096
99.78601	149.5396	11.90637
99.95266	149.7075	11.90179
100.1193	149.8748	11.89703
100.2862	150.0414	11.89231
100.4528	150.2092	11.88762
100.6195	150.3771	11.88274
100.7858	150.5423	11.87781
100.9525	150.7089	11.87288
101.1192	150.8735	11.86782
101.2870	151.0404	11.86267
101.4562	151.2089	11.85769
101.6253	151.3806	11.85226
101.7937	151.5504	11.84698
101.9628	151.7224	11.84170
102.1320	151.8894	11.83617
102.3003	152.0575	11.83088
102.4687	152.2275	11.82549
102.6370	152.3961	11.81993
102.8062	152.5622	11.81436
102.9752	152.7286	11.80855
103.1435	152.8954	11.80288
103.3127	153.0680	11.79699
103.4818	153.2370	11.79104
103.6502	153.4073	11.78521
103.8185	153.5754	11.77934
103.9867	153.7471	11.77335
104.1562	153.9137	11.76710
104.3253	154.0800	11.76096
104.4935	154.2475	11.75479
104.6610	154.4129	11.74843
104.8277	154.5804	11.74218
104.9942	154.7484	11.73596
105.1612	154.9122	11.72951
105.3276	155.0786	11.72301
105.4943	155.2469	11.71648
105.6610	155.4144	11.70996
105.8276	155.5816	11.70338
105.9943	155.7476	11.69660
106.1610	155.9166	11.68978
106.3276	156.0856	11.68290
106.4942	156.2512	11.67602
106.6612	156.4178	11.66904
106.8278	156.5865	11.66199
106.9945	156.7537	11.65473
107.1610	156.9180	11.64730
107.3276	157.0840	11.64021
107.4977	157.2540	11.63232
107.6660	157.4217	11.62515
107.8343	157.5893	11.61757
108.0025	157.7579	11.61006
108.1695	157.9228	11.60237
108.3362	158.0899	11.59450
108.5027	158.2566	11.58666
108.6693	158.4246	11.57875
108.8360	158.5907	11.57071
109.0027	158.7571	11.56272
109.1693	158.9218	11.55460
109.3360	159.0872	11.54620
109.5027	159.2552	11.53785
109.6693	159.4231	11.52953
109.8362	159.5905	11.52099
110.0028	159.7549	11.51244
110.1692	159.9216	11.50391
110.3360	160.0900	11.49513
110.5027	160.2587	11.48625
110.6692	160.4248	11.47725
110.8358	160.5899	11.46816
111.0025	160.7602	11.45912
111.1692	160.9294	11.44991
111.3360	161.0945	11.44073
111.5027	161.2620	11.43138
111.6693	161.4298	11.42193
111.8360	161.5976	11.41243
112.0027	161.7635	11.40275
112.1693	161.9281	11.39284
112.3358	162.0904	11.38320
112.5028	162.2597	11.37316
112.6695	162.4226	11.36292
112.8362	162.5895	11.35271
113.0028	162.7556	11.34264
113.1693	162.9213	11.33226
113.3393	163.0921	11.32142
113.5077	163.2653	11.31088
113.6760	163.4317	11.30024
113.8443	163.6008	11.28944
114.0127	163.7670	11.27860
114.1827	163.9364	11.26705
114.3510	164.1044	11.25596
114.5193	164.2753	11.24494
114.6895	164.4489	11.23312
114.8578	164.6162	11.22169
115.0262	164.7817	11.21029
115.1945	164.9473	11.19850
115.3643	165.1205	11.18626
115.5327	165.2888	11.17442
115.7010	165.4561	11.16243
115.8693	165.6225	11.15038
116.0395	165.7919	11.13765
116.2078	165.9607	11.12526
116.3758	166.1252	11.11281
116.5442	166.2942	11.10031
116.7145	166.4664	11.08709
116.8828	166.6344	11.07441
117.0512	166.8033	11.06149
117.2195	166.9720	11.04857
117.3878	167.1414	11.03542
117.5575	167.3122	11.02148
117.7260	167.4824	11.00805
117.8927	167.6494	10.99447
118.0593	167.8158	10.98078
118.2260	167.9800	10.96703
118.3927	168.1442	10.95291
118.5595	168.3108	10.93896
118.7262	168.4780	10.92478
118.8925	168.6465	10.91066
119.0593	168.8128	10.89605
119.2260	168.9805	10.88147
119.3927	169.1484	10.86680
119.5593	169.3161	10.85187
119.7260	169.4826	10.83686
119.8927	169.6480	10.82174
120.0593	169.8120	10.80644
120.2260	169.9804	10.79104
120.3945	170.1489	10.77553
120.5645	170.3210	10.75883
120.7327	170.4878	10.74297
120.9010	170.6546	10.72694
121.0695	170.8197	10.71070
121.2395	170.9909	10.69358
121.4075	171.1583	10.67707
121.5760	171.3288	10.66032
121.7427	171.4970	10.64356
121.9093	171.6650	10.62661
122.0760	171.8341	10.60969
122.2427	171.9983	10.59246
122.4093	172.1655	10.57502
122.5762	172.3295	10.55746
122.7428	172.4987	10.53971
122.9095	172.6659	10.52189
123.0758	172.8326	10.50376
123.2427	172.9980	10.48556
123.4093	173.1662	10.46714
123.5760	173.3334	10.44861
123.7427	173.4988	10.42998
123.9093	173.6641	10.41091
124.0760	173.8324	10.39188
124.2435	173.9982	10.37265
124.4117	174.1669	10.35331
124.5812	174.3361	10.33330
124.7502	174.5025	10.31300
124.9185	174.6700	10.29302
125.0868	174.8357	10.27285
125.2560	175.0043	10.25195
125.4252	175.1746	10.23093
125.5935	175.3457	10.21034
125.7618	175.5155	10.18953
125.9310	175.6864	10.16795
126.1002	175.8550	10.14623
126.2685	176.0242	10.12474
126.4368	176.1950	10.10313
126.6060	176.3639	10.08084
126.7752	176.5339	10.05833
126.9435	176.7001	10.03600
127.1118	176.8658	10.01350
127.2810	177.0339	9.990426
127.4493	177.2032	9.967156
127.6160	177.3706	9.944126
127.7827	177.5374	9.920861
127.9495	177.7017	9.897403
128.1162	177.8675	9.873718
128.2828	178.0345	9.849915
128.4495	178.2041	9.825916
128.6162	178.3736	9.801670
128.7828	178.5405	9.777254
128.9492	178.7069	9.752472
129.1160	178.8727	9.727528
129.2827	179.0384	9.702437
129.4493	179.2057	9.677047
129.6160	179.3703	9.651584
129.7827	179.5365	9.625868
129.9493	179.7025	9.599876
130.1177	179.8684	9.573694
130.2862	180.0355	9.547256
130.4562	180.2081	9.519184
130.6242	180.3779	9.492299
130.7910	180.5450	9.465091
130.9577	180.7134	9.437819
131.1243	180.8801	9.410266
131.2910	181.0405	9.382599
131.4577	181.2079	9.354611
131.6243	181.3755	9.326522
131.7912	181.5450	9.298056
131.9578	181.7123	9.269395
132.1243	181.8786	9.240522
132.2910	182.0462	9.211493
132.4577	182.2141	9.182331
132.6243	182.3812	9.152908
132.7912	182.5481	9.123351
132.9578	182.7141	9.093406
133.1242	182.8794	9.063322
133.2908	183.0448	9.032968
133.4592	183.2126	9.002426
133.6277	183.3784	8.971675
133.7960	183.5477	8.940876
133.9660	183.7190	8.908082
134.1345	183.8901	8.876563
134.3028	184.0577	8.844658
134.4728	184.2309	8.811166
134.6408	184.3974	8.778830
134.8093	184.5638	8.746362
134.9776	184.7313	8.713392
135.1476	184.8992	8.678791
135.3162	185.0666	8.645632
135.4845	185.2333	8.612082
135.6528	185.4012	8.578234
135.8228	185.5729	8.542559
135.9912	185.7427	8.508081
136.1595	185.9116	8.473345
136.3258	186.0772	8.438284
136.4925	186.2460	8.403197
136.6592	186.4109	8.367720
136.8258	186.5786	8.331887
136.9925	186.7437	8.295703
137.1592	186.9091	8.259369
137.3260	187.0756	8.222694
137.4927	187.2422	8.185611
137.6593	187.4087	8.148320
137.8260	187.5759	8.110916
137.9928	187.7438	8.072936
138.1595	187.9106	8.034778
138.3262	188.0767	7.996191
138.4925	188.2439	7.957482
138.6593	188.4128	7.918501
138.8276	188.5839	7.879282
138.9960	188.7523	7.839441
139.1660	188.9239	7.797730
139.3325	189.0904	7.757388
139.4995	189.2546	7.716895
139.6662	189.4180	7.676134
139.8327	189.5825	7.634986
139.9993	189.7510	7.593472
140.1660	189.9184	7.551894
140.3327	190.0875	7.509754
140.4992	190.2526	7.467449
140.6662	190.4206	7.424799
140.8328	190.5880	7.382140
140.9995	190.7530	7.338836
141.1662	190.9162	7.295359
141.3328	191.0844	7.251821
141.4995	191.2503	7.207525
141.6662	191.4159	7.162976
141.8325	191.5825	7.118188
142.0008	191.7517	7.073134
142.1692	191.9190	7.027595
142.3360	192.0842	6.981706
142.5027	192.2552	6.935626
142.6693	192.4238	6.889200
142.8360	192.5909	6.842034
143.0027	192.7574	6.795276
143.1693	192.9233	6.747724
143.3360	193.0895	6.700020
143.5027	193.2562	6.651864
143.6693	193.4224	6.603506
143.8360	193.5883	6.554457
144.0027	193.7564	6.505562
144.1693	193.9217	6.455993
144.3360	194.0840	6.406283
144.5027	194.2524	6.356088
144.6695	194.4225	6.305558
144.8358	194.5902	6.254670
145.0035	194.7595	6.203623
145.1727	194.9284	6.150750
145.3418	195.0984	6.097348
145.5102	195.2633	6.045006
145.6785	195.4298	5.992239
145.8478	195.5975	5.938007
146.0170	195.7686	5.883248
146.1853	195.9412	5.829545
146.3536	196.1105	5.774006
146.5228	196.2762	5.719704
146.6918	196.4418	5.663663
146.8602	196.6100	5.608618
147.0293	196.7800	5.551825
147.1987	196.9488	5.494488
147.3667	197.1167	5.438432
147.5352	197.2836	5.381855
147.7044	197.4514	5.323519
147.8737	197.6188	5.264729
148.0410	197.7875	5.207094
148.2077	197.9543	5.149096
148.3743	198.1225	5.090996
148.5410	198.2893	5.032326
148.7078	198.4540	4.973272
148.8745	198.6205	4.913756
149.0408	198.7892	4.854180
149.2075	198.9626	4.794109
149.3742	199.1338	4.733708
149.5408	199.3002	4.672840
149.7077	199.4666	4.611610
149.8743	199.6318	4.550163
150.0410	199.7944	4.488456
150.2077	199.9569	4.426143
150.3745	200.1242	4.363656
150.5412	200.2900	4.300732
150.7075	200.4558	4.237418
150.8743	200.6246	4.173848
151.0410	200.7933	4.110006
151.2077	200.9592	4.045483
151.3743	201.1252	3.980873
151.5412	201.2910	3.916016
151.7075	201.4590	3.850742
151.8743	201.6266	3.785007
152.0410	201.7946	3.719226
152.2077	201.9590	3.653094
152.3745	202.1265	3.586498
152.5412	202.2935	3.519567
152.7077	202.4571	3.452346
152.8743	202.6237	3.384976
153.0410	202.7894	3.317390
153.2078	202.9594	3.249399
153.3745	203.1256	3.181094
153.5425	203.2936	3.112588
153.7110	203.4617	3.043661
153.8794	203.6320	2.974646
154.0493	203.8026	2.901985
154.2177	203.9704	2.832565
154.3862	204.1379	2.762542
154.5545	204.3048	2.692448
154.7242	204.4736	2.618540
154.8927	204.6430	2.547838
155.0610	204.8111	2.476860
155.2294	204.9828	2.405774
155.3960	205.1478	2.334212
155.5627	205.3168	2.262862
155.7294	205.4838	2.190899
155.8960	205.6494	2.118770
156.0628	205.8133	2.046412
156.2295	205.9811	1.974020
156.3962	206.1469	1.901162
156.5628	206.3161	1.828125
156.7295	206.4836	1.754902
156.8962	206.6516	1.681230
157.0628	206.8186	1.607649
157.2292	206.9814	1.533775
157.3960	207.1451	1.459690
157.5627	207.3090	1.385578
157.7294	207.4735	1.311139
157.8960	207.6435	1.236615
158.0660	207.8138	1.158337
158.2343	207.9838	1.083836
158.4010	208.1513	1.009294
158.5677	208.3174	0.9346688
158.7343	208.4830	0.8602149
158.9010	208.6513	0.7855466
159.0677	208.8179	0.7108020
159.2343	208.9858	0.6364326
159.4010	209.1516	0.5626470
159.5677	209.3176	0.4897295
159.7343	209.4828	0.4200117
159.9010	209.6526	0.3554316
160.0677	209.8195	0.2953362
160.2345	209.9878	0.2410326
160.4008	210.1535	0.1902992
160.5677	210.3198	0.1436556
160.7343	210.4826	0.1021720
160.9026	210.6573	0.06595266
161.0726	210.8261	0.03395041
161.2410	210.9954	.009711258
161.4093	211.1631	-3.8583E-3
161.5776	211.3313	-6.5498E-3
161.7477	211.5030	-7.0688E-3
161.9160	211.6714	-7.3812E-3
162.0844	211.8400	-7.6161E-3
162.2527	212.0055	-7.7539E-3
162.4212	212.1730	-8.0043E-3
162.5912	212.3405	-8.3801E-3
162.7592	212.5089	-8.4946E-3
162.9277	212.6826	-8.5098E-3
163.0960	212.8518	-8.6551E-3
163.2627	213.0159	-8.9014E-3
163.4292	213.1826	-8.9876E-3
163.5962	213.3488	-9.0795E-3
163.7628	213.5158	-9.2274E-3
163.9294	213.6820	-9.3003E-3
164.0960	213.8508	-9.4786E-3
164.2627	214.0138	-9.8021E-3
164.4294	214.1808	-9.6610E-3
164.5960	214.3492	-9.7599E-3
164.7627	214.5160	-9.9027E-3
164.9294	214.6820	-9.9355E-3
165.0960	214.8445	-.01000726
165.2627	215.0088	-.01023122
165.4294	215.1742	-.01022683
165.5960	215.3444	-.01016673
165.7635	215.5119	-.01031396
165.9320	215.6784	-.01037709
166.1002	215.8475	-.01061982
166.2685	216.0210	-.01050219
166.4377	216.1900	-.01054314
166.6068	216.3570	-.01058678
166.7752	216.5258	-.01069839
166.9435	216.6920	-.01070306
167.1127	216.8585	-.01084661
167.2818	217.0306	-.01085395
167.4502	217.2038	-.01110831
167.6176	217.3724	-.01120583
167.7842	217.5404	-.01103462
167.9508	217.7074	-.01112461
168.1175	217.8702	-.01142969
168.2845	218.0374	-.01146678
168.4512	218.2055	-.01140336
168.6176	218.3698	-.01166895
168.7844	218.5348	-.01143037
168.9510	218.7006	-.01162142
169.1176	218.8656	-.01179338
169.2844	219.0334	-.01189428
169.4510	219.1992	-.01200792
169.6176	219.3634	-.01205899
169.7844	219.5298	-.01210621
169.9508	219.6974	-.01215790
170.1178	219.8657	-.01230755
170.2845	220.0324	-.01221474
170.4525	220.2034	-.01231380
170.6208	220.3730	-.01213147
170.7878	220.5386	-.01260151
170.9544	220.7032	-.01268045
171.1210	220.8741	-.01269967
171.2877	221.0391	-.01278947
171.4544	221.2066	-.01272275
171.6210	221.3720	-.01287455
171.7878	221.5367	-.01291072
171.9545	221.7021	-.01293580
172.1212	221.8672	-.01293416
172.2877	222.0334	-.01310347
172.4544	222.2022	-.01303445
172.6212	222.3695	-.01324416
172.7878	222.5401	-.01311318
172.9545	222.7094	-.01324688
173.1212	222.8741	-.01322851
173.2895	223.0409	-.01331940
173.4576	223.2090	-.01333694
173.6260	223.3781	-.01336489
173.7943	223.5453	-.01349574
173.9644	223.7145	-.01351256
174.1326	223.8809	-.01377636
174.3010	224.0488	-.01371570
174.4694	224.2163	-.01379259
174.6394	224.3857	-.01386687
174.8076	224.5542	-.01400402
174.9762	224.7260	-.01404343
175.1445	224.8954	-.01416381
175.3128	225.0613	-.01432298
175.4828	225.2308	-.01419572
175.6512	225.4010	-.01431596
175.8195	225.5681	-.01442790
175.9878	225.7356	-.01443672
176.1576	225.9087	-.01454180
176.3260	226.0776	-.01455070
176.4944	226.2444	-.01453881
176.6627	226.4128	-.01460062
176.8326	226.5810	-.01463830
177.0010	226.7483	-.01480328
177.1693	226.9146	-.01488661
177.3394	227.0832	-.01503372
177.5076	227.2514	-.01499119
177.6760	227.4211	-.01504194
177.8444	227.5947	-.01509784
178.0145	227.7635	-.01528860
178.1828	227.9292	-.01515118
178.3512	228.0989	-.01525035
178.5195	228.2687	-.01521488
178.6875	228.4369	-.01516467
178.8576	228.6067	-.01527952
179.0260	228.7752	-.01536458
179.1927	228.9412	-.01542458
179.3592	229.1074	-.01544642
179.5262	229.2722	-.01552555
179.6927	229.4390	-.01587809
179.8594	229.6086	-.01567693
180.0260	229.7755	-.01581658
180.1927	229.9433	-.01584519
180.3595	230.1077	-.01597009
180.5262	230.2742	-.01599679
180.6928	230.4464	-.01614382
180.8594	230.6125	-.01608935
181.0260	230.7784	-.01609079
181.1927	230.9428	-.01609438
181.3594	231.1082	-.01629236
181.5260	231.2767	-.01623748
181.6944	231.4451	-.01613305
181.8644	231.6161	-.01636356
182.0326	231.7826	-.01639426
182.2010	231.9497	-.01661565
182.3694	232.1150	-.01662485
182.5377	232.2847	-.01667670
182.7076	232.4559	-.01663630
182.8758	232.6246	-.01674181
183.0442	232.7957	-.01677162
183.2128	232.9648	-.01683165
183.3826	233.1356	-.01683292
183.5510	233.3014	-.01694114
183.7194	233.4690	-.01687895
183.8877	233.6374	-.01695875
184.0576	233.8063	-.01691193
184.2244	233.9764	-.01723874
184.3912	234.1436	-.01712545
184.5578	234.3120	-.01697379
184.7244	234.4768	-.01708000
184.8910	234.6444	-.01701182
185.0576	234.8078	-.01708539
185.2242	234.9734	-.01734985
185.3912	235.1411	-.01729074
185.5576	235.3083	-.01731847
185.7244	235.4740	-.01733957
185.8910	235.6410	-.01738791
186.0576	235.8036	-.01749127
186.2244	235.9707	-.01733081
186.3910	236.1394	-.01733436
186.5576	236.3052	-.01729356
186.7260	236.4753	-.01738914
186.8944	236.6450	-.01734648
187.0644	236.8142	-.01748180
187.2326	236.9818	-.01753410
187.4010	237.1517	-.01763477
187.5694	237.3208	-.01752153
187.7394	237.4920	-.01757065
187.9076	237.6601	-.01758701
188.0760	237.8273	-.01767354
188.2445	237.9944	-.01757995
188.4145	238.1629	-.01775393
188.5828	238.3294	-.01779281
188.7512	238.4981	-.01780268
188.9192	238.6643	-.01778169
189.0876	238.8352	-.01775881
189.2576	239.0069	-.01777166
189.4260	239.1759	-.01783211
189.5944	239.3442	-.01778482
189.7644	239.5162	-.01788361
189.9326	239.6878	-.01804035
190.1010	239.8553	-.01790213
190.2694	240.0225	-.01799044
190.4394	240.1930	-.01808694
190.6078	240.3590	-.01806873
190.7762	240.5274	-.01814870
190.9445	240.6936	-.01827547
191.1145	240.8652	-.01810614
191.2826	241.0324	-.01810590
191.4510	241.2010	-.01809600
191.6194	241.3684	-.01823034
191.7894	241.5415	-.01817432
191.9576	241.7094	-.01819819
192.1260	241.8758	-.01830700
192.2943	242.0436	-.01815077
192.4644	242.2119	-.01824184
192.6328	242.3814	-.01822190
192.8012	242.5502	-.01824942
192.9692	242.7180	-.01818531
193.1360	242.8847	-.01818732
193.3027	243.0500	-.01816062
193.4694	243.2152	-.01819645
193.6362	243.3848	-.01810441
193.8028	243.5492	-.01814673
193.9695	243.7168	-.01812020
194.1358	243.8844	-.01798450
194.3027	244.0523	-.01811884
194.4694	244.2172	-.01821922
194.6360	244.3854	-.01813634
194.8027	244.5525	-.01823058
194.9692	244.7166	-.01815828
195.1360	244.8806	-.01820862
195.3027	245.0500	-.01813758
195.4694	245.2158	-.01812121
195.6360	245.3846	-.01822628
195.8025	245.5524	-.01833526
195.9695	245.7222	-.01836059
196.1362	245.8893	-.01830511
196.3028	246.0552	-.01834056
196.4695	246.2214	-.01840205
196.6362	246.3884	-.01845866
196.8025	246.5537	-.01832596
196.9692	246.7180	-.01839378
197.1360	246.8850	-.01834875
197.3027	247.0503	-.01842761
197.4694	247.2184	-.01831505
197.6360	247.3857	-.01832180
197.8027	247.5526	-.01827409
197.9694	247.7179	-.01827408
198.1360	247.8830	-.01827940
198.3028	248.0487	-.01841775
198.4695	248.2160	-.01832807
198.6378	248.3842	-.01845848
198.8075	248.5530	-.01842388
198.9760	248.7252	-.01836253
199.1444	248.8953	-.01831302
199.3110	249.0620	-.01828622
199.4776	249.2294	-.01841240
199.6444	249.3939	-.01845680
199.8112	249.5608	-.01843866
199.9775	249.7282	-.01832968
200.1444	249.8938	-.01830506
200.3110	250.0589	-.01834260
200.4778	250.2245	-.01845712
200.6444	250.3953	-.01820175
200.8110	250.5598	-.01814661
200.9778	250.7278	-.01830100
201.1444	250.8956	-.01812986
201.3110	251.0606	-.01846485
201.4778	251.2265	-.01861807
201.6444	251.3921	-.01833428
201.8110	251.5586	-.01832960
201.9812	251.7290	-.01859335
202.1494	251.8969	-.01848128
202.3177	252.0648	-.01862973
202.4862	252.2352	-.01836305
202.6543	252.4008	-.01860132
202.8244	252.5707	-.01839356
202.9926	252.7412	-.01851092
203.1608	252.9092	-.01849547
203.3294	253.0803	-.01853030
203.4994	253.2494	-.01856380
203.6678	253.4176	-.01845940
203.8344	253.5830	-.01861309
204.0010	253.7484	-.01858244
204.1676	253.9164	-.01852441
204.3345	254.0837	-.01851307
204.5010	254.2514	-.01848010
204.6676	254.4169	-.01849066
204.8345	254.5840	-.01851755
205.0010	254.7504	-.01848372
205.1677	254.9167	-.01857579
205.3345	255.0842	-.01847514
205.5008	255.2512	-.01842769
205.6677	255.4184	-.01839080
205.8344	255.5833	-.01835469
206.0012	255.7496	-.01830792
206.1677	255.9162	-.01833754
206.3360	256.0856	-.01826623
206.5062	256.2551	-.01832452
206.6742	256.4266	-.01835945
206.8410	256.5935	-.01835134
207.0076	256.7594	-.01852827
207.1745	256.9266	-.01845539
207.3410	257.0933	-.01838846
207.5076	257.2575	-.01862406
207.6745	257.4244	-.01854753
207.8410	257.5898	-.01846336
208.0076	257.7564	-.01834275
208.1745	257.9214	-.01842414
208.3408	258.0918	-.01828761
208.5076	258.2570	-.01850492
208.6745	258.4246	-.01826233
208.8408	258.5888	-.01847371
209.0076	258.7569	-.01839882
209.1744	258.9223	-.01845122
209.3428	259.0919	-.01847794
209.5110	259.2589	-.01853220
209.6810	259.4314	-.01849751
209.8478	259.5953	-.01853092
210.0144	259.7626	-.01849156
210.1810	259.9292	-.01866114
210.3478	260.0990	-.01843597
210.5142	260.2672	-.01853132
210.6810	260.4333	-.01851312
210.8477	260.5984	-.01856647
211.0145	260.7646	-.01849104
211.1808	260.9304	-.01845846
211.3477	261.0958	-.01842245
211.5144	261.2623	-.01839596
211.6812	261.4263	-.01854284
211.8478	261.5947	-.01845978
212.0142	261.7629	-.01842917
212.1810	261.9301	-.01841505
212.3485	262.0967	-.01850554
212.5168	262.2680	-.01852185
212.6852	262.4375	-.01845911
212.8544	262.6063	-.01842163
213.0235	262.7752	-.01841870
213.1920	262.9430	-.01848860
213.3603	263.1113	-.01857925
213.5295	263.2828	-.01847108
213.6987	263.4507	-.01851648
213.8670	263.6190	-.01837612
214.0354	263.7850	-.01852673
214.2025	263.9506	-.01854721
214.3695	264.1186	-.01861902
214.5362	264.2840	-.01854593
214.7028	264.4496	-.01854597
214.8695	264.6161	-.01853588
215.0362	264.7840	-.01848062
215.2028	264.9520	-.01855622
215.3695	265.1210	-.01839151
215.5362	265.2871	-.01841587
215.7026	265.4541	-.01846709
215.8694	265.6194	-.01851254
216.0360	265.7858	-.01844471
216.2025	265.9526	-.01870670
216.3695	266.1214	-.01846445
216.5360	266.2886	-.01850757
216.7026	266.4542	-.01856544
216.8694	266.6225	-.01839410
217.0394	266.7910	-.01845482
217.2078	266.9606	-.01826416
217.3762	267.1251	-.01832407
217.5444	267.2936	-.01828519
217.7144	267.4641	-.01822927
217.8825	267.6316	-.01842905
218.0512	267.8010	-.01832807
218.2195	267.9691	-.01855651
218.3894	268.1393	-.01840204
218.5576	268.3074	-.01846606
218.7258	268.4756	-.01862604
218.8945	268.6438	-.01834172
219.0628	268.8100	-.01841962
219.2326	268.9797	-.01847295
219.4010	269.1485	-.01842023
219.5694	269.3175	-.01847220
219.7358	269.4867	-.01845011
219.9028	269.6525	-.01839995
220.0695	269.8190	-.01852272
220.2360	269.9860	-.01834475
220.4026	270.1514	-.01852673
220.5692	270.3190	-.01845660
220.7362	270.4876	-.01841727
220.9026	270.6538	-.01840405
221.0694	270.8198	-.01829683
221.2360	270.9850	-.01840637
221.4026	271.1516	-.01849810
221.5694	271.3198	-.01847766
221.7358	271.4857	-.01851372
221.9028	271.6516	-.01843728
222.0695	271.8185	-.01852538
222.2378	271.9869	-.01835498
222.4078	272.1558	-.01832128
222.5760	272.3248	-.01833025
222.7444	272.4912	-.01857405
222.9144	272.6619	-.01845967
223.0826	272.8352	-.01846699
223.2512	273.0044	-.01842464
223.4195	273.1704	-.01851738
223.5894	273.3404	-.01856289
223.7576	273.5075	-.01831808
223.9260	273.6764	-.01838562
224.0944	273.8456	-.01830532
224.2627	274.0133	-.01840680
224.4325	274.1832	-.01821745
224.6012	274.3504	-.01826836
224.7694	274.5185	-.01821375
224.9394	274.6877	-.01824908
225.1076	274.8547	-.01829184
225.2760	275.0209	-.01820873
225.4444	275.1910	-.01812426
225.6127	275.3648	-.01804820
225.7825	275.5369	-.01807126
225.9512	275.7028	-.01819501
226.1195	275.8694	-.01816198
226.2894	276.0384	-.01812509
226.4576	276.2049	-.01820764
226.6258	276.3750	-.01801753
226.7945	276.5402	-.01817021
226.9644	276.7134	-.01835161
227.1326	276.8812	-.01817746
227.3010	277.0498	-.01833708
227.4694	277.2178	-.01828369
227.6378	277.3842	-.01841482
227.8078	277.5556	-.01835954
227.9762	277.7246	-.01825602
228.1445	277.8934	-.01828364
228.3144	278.0625	-.01830256
228.4826	278.2327	-.01825612
228.6510	278.4010	-.01828114
228.8194	278.5700	-.01823639
228.9877	278.7410	-.01830098
229.1576	278.9101	-.01837036
229.3243	279.0780	-.01826925
229.4910	279.2420	-.01814508
229.6576	279.4058	-.01825182
229.8242	279.5722	-.01838491
229.9912	279.7378	-.01832987
230.1578	279.9028	-.01838524
230.3242	280.0697	-.01832726
230.4910	280.2358	-.01827431
230.6576	280.4015	-.01840514
230.8243	280.5709	-.01819315
230.9910	280.7385	-.01827420
231.1576	280.9074	-.01815895
231.3243	281.0752	-.01814317
231.4910	281.2386	-.01835474
231.6576	281.4080	-.01817323
231.8243	281.5724	-.01816631
231.9910	281.7409	-.01815594
232.1576	281.9042	-.01818990
232.3242	282.0724	-.01809931
232.4908	282.2379	-.01819054
232.6575	282.4050	-.01813131
232.8243	282.5718	-.01812813
232.9910	282.7408	-.01803473
233.1576	282.9064	-.01811558
233.3245	283.0746	-.01815758
233.4912	283.2418	-.01825108
233.6576	283.4073	-.01817222
233.8243	283.5753	-.01816485
233.9910	283.7394	-.01823368
234.1576	283.9076	-.01827881
234.3243	284.0765	-.01824653
234.4926	284.2440	-.01828019
234.6608	284.4110	-.01822438
234.8310	284.5812	-.01820122
234.9993	284.7466	-.01822901
235.1677	284.9159	-.01826077
235.3362	285.0828	-.01819178
235.5062	285.2530	-.01821705
235.6745	285.4232	-.01822264
235.8428	285.5917	-.01842159
236.0112	285.7608	-.01821759
236.1794	285.9290	-.01817362
236.3460	286.0940	-.01835117
236.5127	286.2612	-.01819862
236.6794	286.4290	-.01824944
236.8460	286.5952	-.01812622
237.0125	286.7646	-.01819697
237.1792	286.9298	-.01825371
237.3462	287.0966	-.01791944
237.5128	287.2620	-.01806010
237.6795	287.4275	-.01808780
237.8460	287.5936	-.01812662
238.0127	287.7611	-.01826897
238.1795	287.9296	-.01804624
238.3462	288.0954	-.01819550
238.5128	288.2615	-.01818438
238.6795	288.4263	-.01814045
238.8462	288.5956	-.01806541
239.0145	288.7643	-.01814731
239.1837	288.9344	-.01808878
239.3520	289.1012	-.01796927
239.5210	289.2713	-.01783315
239.6902	289.4417	-.01792617
239.8585	289.6110	-.01799548
240.0268	289.7787	-.01811555
240.1958	289.9504	-.01810426
240.3653	290.1178	-.01804738
240.5335	290.2864	-.01790401
240.7018	290.4524	-.01806186
240.8700	290.6200	-.01792610
241.0375	290.7878	-.01806250
241.2042	290.9530	-.01800671
241.3712	291.1204	-.01802096
241.5378	291.2839	-.01799352
241.7045	291.4490	-.01804771
241.8712	291.6186	-.01805693
242.0377	291.7886	-.01789111
242.2043	291.9553	-.01797730
242.3710	292.1241	-.01800615
242.5377	292.2919	-.01788620
242.7043	292.4550	-.01801573
242.8708	292.6218	-.01808287
243.0378	292.7928	-.01798401
243.2045	292.9578	-.01791918
243.3710	293.1252	-.01802428
243.5377	293.2906	-.01804116
243.7042	293.4590	-.01778312
243.8743	293.6232	-.01801591
244.0427	293.7930	-.01796982
244.2110	293.9604	-.01799713
244.3808	294.1305	-.01800567
244.5495	294.2969	-.01788760
244.7177	294.4636	-.01802048
244.8860	294.6297	-.01797073
245.0544	294.8003	-.01802975
245.2212	294.9680	-.01794230
245.3877	295.1391	-.01789293
245.5542	295.3078	-.01771156
245.7212	295.4736	-.01772849
245.8877	295.6392	-.01772716
246.0544	295.8070	-.01779621
246.2212	295.9727	-.01770372
246.3878	296.1368	-.01793193
246.5544	296.3032	-.01782514
246.7210	296.4714	-.01779180
246.8878	296.6382	-.01757973
247.0544	296.8062	-.01760864
247.2210	296.9707	-.01772106
247.3878	297.1367	-.01780197
247.5545	297.3037	-.01783794
247.7227	297.4722	-.01777390
247.8910	297.6386	-.01785580
248.0595	297.8078	-.01781195
248.2278	297.9756	-.01775342
248.3976	298.1476	-.01774380
248.5660	298.3154	-.01779041
248.7326	298.4842	-.01758530
248.8995	298.6482	-.01772965
249.0660	298.8135	-.01780113
249.2326	298.9802	-.01778775
249.3994	299.1461	-.01772049
249.5662	299.3144	-.01749634
249.7326	299.4790	-.01759514
249.8994	299.6463	-.01780077
249.9660	299.7114	-.01768018