File: TGA/2023_07_10_Ni_calibration_1cpm.txt
CLOSED
Version	0.4
Run	866
Instrument	2950 TGA       V5.4A
Module	TGA 1000 øC
Sample	2023_07_10_Ni_calibration_1cpm
Size	14.9670	mg
Method	250C to 400C 1 cpm
Operator	SBK
Comment	2023_07_10_Ni_calibration_1cpm
Xcomment	Pan: Platinum           Gas1: Nitrogen  40          Gas2: Nitrogen  40
Text	2023_07_10_Ni_calibration_1cpm
Text	Calibration with nickel foam and magnet
Kcell	1.00000
TempCal	2	pts	158.19	152.50,	363.28	354.00
Thresholds	0.050	0.0000
Controls	Gas 1  Event Off  Sampling 2.0 sec/pt
Nsig	3
Sig1	Time (min)
Sig2	Temperature (øC)
Sig3	Weight (mg)
Date	10-Jul-23
Time	10:49
File	C:\TA\Data\TGA\Skyler\2023_07_10_Ni_calibration_1cpm.001
OrgFile	C:\TA\Data\TGA\Skyler\2023_07_10_Ni_calibration_1cpm.001
StartOfData
0.0000000	250.0392	15.01818
0.1010000	250.0780	15.01802
0.2010000	250.1425	15.01784
0.3026666	250.2180	15.01769
0.4035000	250.3010	15.01751
0.5043333	250.3874	15.01750
0.6076668	250.4803	15.01732
0.7076668	250.5735	15.01721
0.8093334	250.6738	15.01719
0.9101666	250.7694	15.01697
1.010833	250.8688	15.01677
1.112500	250.9700	15.01672
1.212834	251.0685	15.01664
1.316167	251.1713	15.01649
1.417000	251.2705	15.01639
1.517833	251.3722	15.01624
1.619500	251.4746	15.01609
1.719333	251.5740	15.01593
1.822666	251.6768	15.01604
1.923500	251.7808	15.01584
2.024333	251.8822	15.01555
2.126000	251.9834	15.01548
2.226000	252.0808	15.01534
2.327667	252.1815	15.01518
2.429334	252.2830	15.01499
2.531000	252.3840	15.01485
2.632666	252.4858	15.01479
2.732666	252.5830	15.01470
2.834334	252.6840	15.01464
2.935166	252.7834	15.01444
3.036000	252.8847	15.01430
3.139334	252.9858	15.01433
3.239334	253.0824	15.01410
3.341000	253.1830	15.01394
3.441833	253.2842	15.01390
3.542666	253.3829	15.01374
3.644333	253.4865	15.01368
3.744166	253.5858	15.01344
3.846167	253.6905	15.01334
3.947833	253.7908	15.01322
4.049500	253.8919	15.01300
4.151166	253.9935	15.01289
4.251167	254.0923	15.01278
4.352833	254.1930	15.01267
4.454334	254.2956	15.01252
4.556000	254.3965	15.01234
4.657666	254.4984	15.01226
4.757666	254.5972	15.01202
4.859500	254.6978	15.01207
4.960333	254.8012	15.01189
5.061000	254.9031	15.01186
5.164334	255.0061	15.01163
5.264334	255.1055	15.01173
5.365832	255.2055	15.01153
5.467000	255.3060	15.01134
5.567666	255.4052	15.01130
5.669334	255.5051	15.01113
5.769334	255.6082	15.01104
5.871000	255.7073	15.01087
5.972832	255.8080	15.01075
6.074500	255.9080	15.01059
6.176000	256.0096	15.01049
6.276000	256.1090	15.01024
6.377666	256.2108	15.01020
6.478332	256.3106	15.01003
6.579500	256.4118	15.00995
6.682666	256.5134	15.00991
6.782666	256.6134	15.00981
6.882666	256.7148	15.00969
6.982500	256.8142	15.00961
7.082832	256.9148	15.00938
7.182832	257.0158	15.00928
7.282666	257.1150	15.00916
7.382666	257.2148	15.00901
7.482666	257.3152	15.00889
7.582666	257.4156	15.00889
7.682832	257.5172	15.00872
7.782832	257.6168	15.00842
7.882666	257.7165	15.00839
7.982666	257.8148	15.00822
8.082666	257.9153	15.00808
8.182666	258.0140	15.00813
8.282500	258.1150	15.00796
8.382834	258.2150	15.00786
8.482832	258.3140	15.00773
8.582666	258.4143	15.00766
8.682668	258.5146	15.00751
8.782666	258.6118	15.00739
8.882668	258.7116	15.00721
8.982668	258.8098	15.00706
9.082666	258.9099	15.00697
9.182668	259.0098	15.00684
9.282666	259.1103	15.00676
9.384334	259.2127	15.00659
9.484168	259.3123	15.00644
9.586166	259.4139	15.00631
9.687834	259.5190	15.00627
9.789501	259.6190	15.00604
9.891000	259.7195	15.00591
9.991000	259.8190	15.00582
10.09267	259.9206	15.00565
10.19350	260.0218	15.00549
10.29433	260.1196	15.00542
10.39600	260.2248	15.00564
10.49600	260.3244	15.00524
10.59934	260.4274	15.00500
10.70016	260.5295	15.00494
10.80100	260.6280	15.00482
10.90267	260.7297	15.00474
11.00266	260.8283	15.00464
11.10600	260.9315	15.00438
11.20684	261.0342	15.00439
11.30767	261.1336	15.00426
11.40934	261.2358	15.00412
11.50934	261.3348	15.00407
11.61100	261.4366	15.00402
11.71266	261.5402	15.00397
11.81433	261.6408	15.00383
11.91600	261.7461	15.00371
12.01600	261.8466	15.00360
12.11766	261.9480	15.00344
12.21834	262.0485	15.00334
12.31950	262.1491	15.00319
12.42116	262.2524	15.00322
12.52117	262.3523	15.00302
12.62434	262.4539	15.00288
12.72516	262.5534	15.00272
12.82600	262.6542	15.00260
12.92767	262.7572	15.00258
13.02783	262.8577	15.00240
13.13116	262.9622	15.00232
13.23184	263.0617	15.00219
13.33266	263.1616	15.00211
13.43433	263.2639	15.00199
13.53450	263.3613	15.00180
13.63617	263.4644	15.00182
13.73767	263.5642	15.00163
13.83934	263.6647	15.00158
13.94100	263.7656	15.00146
14.04100	263.8674	15.00146
14.14250	263.9680	15.00136
14.24366	264.0694	15.00126
14.34450	264.1685	15.00111
14.44783	264.2759	15.00119
14.54767	264.3754	15.00118
14.64934	264.4750	15.00104
14.75016	264.5786	15.00072
14.85100	264.6783	15.00081
14.95266	264.7792	15.00068
15.05267	264.8780	15.00058
15.15434	264.9785	15.00058
15.25434	265.0811	15.00038
15.35434	265.1798	15.00062
15.45434	265.2830	15.00023
15.55417	265.3746	15.00060
15.65450	265.4770	15.00013
15.75450	265.5796	15.00016
15.85434	265.6799	15.00009
15.95434	265.7802	14.99999
16.05434	265.8796	14.99996
16.15434	265.9784	14.99990
16.25417	266.0782	14.99981
16.35450	266.1795	14.99979
16.45450	266.2793	14.99971
16.55434	266.3794	14.99966
16.65434	266.4817	14.99954
16.75434	266.5798	14.99960
16.85434	266.6816	14.99966
16.95416	266.7846	14.99962
17.05450	266.8832	14.99944
17.15450	266.9826	14.99941
17.25450	267.0770	14.99932
17.35450	267.1876	14.99956
17.45434	267.2812	14.99935
17.55434	267.3814	14.99920
17.65434	267.4822	14.99909
17.75434	267.5825	14.99902
17.85600	267.6848	14.99914
17.95684	267.7844	14.99912
18.05766	267.8851	14.99908
18.15916	267.9859	14.99897
18.25917	268.0860	14.99896
18.36084	268.1882	14.99896
18.46200	268.2879	14.99885
18.56284	268.3894	14.99895
18.66600	268.4908	14.99881
18.76600	268.5900	14.99869
18.86766	268.6938	14.99881
18.96850	268.7975	14.99872
19.06934	268.9004	14.99862
19.16916	268.9996	14.99858
19.26950	269.1004	14.99860
19.36950	269.1998	14.99854
19.46950	269.2983	14.99856
19.56934	269.3982	14.99846
19.66934	269.4983	14.99847
19.76934	269.5982	14.99828
19.86934	269.6980	14.99829
19.96934	269.7984	14.99830
20.06934	269.8982	14.99821
20.16950	269.9970	14.99823
20.26950	270.0974	14.99824
20.36934	270.1970	14.99814
20.46934	270.2953	14.99823
20.56934	270.3940	14.99804
20.66934	270.4960	14.99801
20.76934	270.5942	14.99806
20.86917	270.6937	14.99800
20.96950	270.7938	14.99790
21.06950	270.8937	14.99790
21.16934	270.9940	14.99789
21.26934	271.0952	14.99781
21.36934	271.1928	14.99794
21.46934	271.2956	14.99793
21.56917	271.3920	14.99770
21.66950	271.4950	14.99762
21.76950	271.5935	14.99774
21.87266	271.6962	14.99765
21.97266	271.7954	14.99767
22.07434	271.8991	14.99772
22.17500	271.9990	14.99793
22.27617	272.1043	14.99764
22.37766	272.2041	14.99758
22.47766	272.3045	14.99760
22.57934	272.4065	14.99760
22.68083	272.5088	14.99755
22.78284	272.6099	14.99758
22.88450	272.7121	14.99755
22.98433	272.8115	14.99757
23.08600	272.9126	14.99760
23.18683	273.0128	14.99757
23.28750	273.1138	14.99754
23.39117	273.2164	14.99753
23.49100	273.3186	14.99756
23.59266	273.4187	14.99762
23.69266	273.5190	14.99759
23.79266	273.6154	14.99746
23.89266	273.7165	14.99746
23.99250	273.8167	14.99756
24.09283	273.9163	14.99754
24.19283	274.0172	14.99760
24.29283	274.1170	14.99755
24.39266	274.2166	14.99761
24.49266	274.3164	14.99770
24.59266	274.4168	14.99759
24.69266	274.5182	14.99768
24.79266	274.6180	14.99745
24.89284	274.7183	14.99753
24.99284	274.8188	14.99752
25.09266	274.9191	14.99754
25.19266	275.0194	14.99754
25.29266	275.1186	14.99752
25.39266	275.2192	14.99752
25.49266	275.3185	14.99749
25.59250	275.4190	14.99742
25.69284	275.5203	14.99753
25.79284	275.6190	14.99746
25.89266	275.7206	14.99755
25.99266	275.8199	14.99748
26.09266	275.9205	14.99740
26.19250	276.0204	14.99741
26.29450	276.1215	14.99732
26.39600	276.2238	14.99751
26.49767	276.3244	14.99748
26.59933	276.4252	14.99747
26.69934	276.5246	14.99750
26.80083	276.6279	14.99755
26.90200	276.7298	14.99757
27.00266	276.8289	14.99756
27.10600	276.9328	14.99742
27.20600	277.0308	14.99756
27.30766	277.1326	14.99751
27.40833	277.2320	14.99746
27.50950	277.3336	14.99748
27.61100	277.4358	14.99744
27.71100	277.5354	14.99750
27.81434	277.6387	14.99757
27.91516	277.7384	14.99755
28.01583	277.8390	14.99743
28.11784	277.9421	14.99744
28.21766	278.0419	14.99736
28.31934	278.1468	14.99764
28.42100	278.2478	14.99761
28.52267	278.3472	14.99748
28.62417	278.4492	14.99757
28.72450	278.5509	14.99753
28.82617	278.6493	14.99760
28.92684	278.7494	14.99749
29.02766	278.8532	14.99768
29.13100	278.9552	14.99788
29.23100	279.0543	14.99785
29.33266	279.1560	14.99777
29.43367	279.2574	14.99768
29.53450	279.3572	14.99772
29.63617	279.4593	14.99771
29.73617	279.5594	14.99763
29.83933	279.6621	14.99768
29.94016	279.7641	14.99776
30.04100	279.8658	14.99770
30.14266	279.9678	14.99778
30.24266	280.0650	14.99777
30.34416	280.1688	14.99781
30.44534	280.2700	14.99770
30.54617	280.3700	14.99764
30.64934	280.4744	14.99784
30.74933	280.5746	14.99772
30.85100	280.6762	14.99775
30.95100	280.7770	14.99788
31.05100	280.8765	14.99794
31.15100	280.9760	14.99800
31.25083	281.0740	14.99795
31.35117	281.1764	14.99797
31.45117	281.2772	14.99804
31.55100	281.3772	14.99806
31.65100	281.4766	14.99808
31.75100	281.5752	14.99800
31.85100	281.6746	14.99806
31.95100	281.7752	14.99805
32.05100	281.8764	14.99808
32.15100	281.9784	14.99822
32.25083	282.0778	14.99819
32.35117	282.1750	14.99834
32.45117	282.2752	14.99827
32.55117	282.3755	14.99831
32.65100	282.4741	14.99834
32.75100	282.5722	14.99825
32.85100	282.6717	14.99826
32.95100	282.7702	14.99834
33.05100	282.8713	14.99826
33.15100	282.9712	14.99852
33.25100	283.0722	14.99828
33.35083	283.1730	14.99828
33.45083	283.2720	14.99825
33.55250	283.3738	14.99839
33.65250	283.4749	14.99824
33.75250	283.5735	14.99832
33.85250	283.6741	14.99844
33.95284	283.7758	14.99840
34.05283	283.8770	14.99842
34.15283	283.9765	14.99841
34.25284	284.0785	14.99844
34.35283	284.1795	14.99842
34.45284	284.2776	14.99834
34.55283	284.3799	14.99860
34.65283	284.4787	14.99860
34.75284	284.5786	14.99858
34.85283	284.6791	14.99870
34.95250	284.7800	14.99865
35.05250	284.8809	14.99864
35.15250	284.9810	14.99876
35.25266	285.0798	14.99868
35.35266	285.1775	14.99868
35.45266	285.2772	14.99873
35.55266	285.3779	14.99885
35.65266	285.4750	14.99886
35.75266	285.5747	14.99891
35.85266	285.6762	14.99878
35.95266	285.7755	14.99887
36.05266	285.8768	14.99893
36.15266	285.9772	14.99896
36.25266	286.0764	14.99890
36.35350	286.1788	14.99898
36.45433	286.2789	14.99910
36.55766	286.3840	14.99906
36.65766	286.4852	14.99918
36.75934	286.5870	14.99940
36.86000	286.6886	14.99920
36.96084	286.7884	14.99930
37.06100	286.8872	14.99926
37.16100	286.9859	14.99924
37.26100	287.0857	14.99931
37.36100	287.1855	14.99934
37.46100	287.2856	14.99924
37.56100	287.3866	14.99922
37.66100	287.4849	14.99927
37.76100	287.5882	14.99944
37.86100	287.6875	14.99934
37.96100	287.7848	14.99930
38.06100	287.8883	14.99948
38.16100	287.9860	14.99957
38.26100	288.0844	14.99950
38.36100	288.1842	14.99944
38.46100	288.2798	14.99944
38.56100	288.3824	14.99962
38.66100	288.4828	14.99965
38.76117	288.5832	14.99987
38.86117	288.6822	14.99971
38.96117	288.7825	14.99974
39.06116	288.8834	14.99970
39.16117	288.9834	14.99974
39.26084	289.0852	14.99990
39.36100	289.1841	14.99975
39.46100	289.2848	14.99997
39.56100	289.3855	14.99990
39.66100	289.4850	14.99994
39.76266	289.5880	15.00001
39.86267	289.6885	15.00001
39.96600	289.7920	15.00012
40.06683	289.8933	15.00008
40.16766	289.9941	15.00010
40.26750	290.0944	15.00013
40.36783	290.1954	15.00010
40.46784	290.2954	15.00016
40.56766	290.3944	15.00016
40.66766	290.4948	15.00019
40.76766	290.5950	15.00028
40.86767	290.6918	15.00023
40.96766	290.7935	15.00046
41.06766	290.8928	15.00040
41.16766	290.9916	15.00049
41.26766	291.0920	15.00050
41.36750	291.1922	15.00060
41.46750	291.2919	15.00067
41.56783	291.3919	15.00074
41.66783	291.4924	15.00076
41.76783	291.5926	15.00086
41.86783	291.6928	15.00087
41.96783	291.7925	15.00093
42.06783	291.8930	15.00094
42.16783	291.9942	15.00100
42.26783	292.0949	15.00112
42.36783	292.1920	15.00110
42.46766	292.2938	15.00122
42.56766	292.3948	15.00115
42.66766	292.4932	15.00125
42.76850	292.5957	15.00137
42.86934	292.6992	15.00148
42.97100	292.7991	15.00146
43.07100	292.9019	15.00144
43.17100	292.9981	15.00162
43.27100	293.0980	15.00156
43.37100	293.1959	15.00161
43.47100	293.2964	15.00174
43.57100	293.3947	15.00168
43.67100	293.4944	15.00186
43.77100	293.5928	15.00178
43.87100	293.6922	15.00176
43.97100	293.7924	15.00180
44.07100	293.8914	15.00171
44.17100	293.9920	15.00189
44.27100	294.0940	15.00202
44.37100	294.1912	15.00182
44.47100	294.2930	15.00213
44.57100	294.3938	15.00220
44.67084	294.4944	15.00219
44.77083	294.5966	15.00216
44.87117	294.6965	15.00212
44.97117	294.7982	15.00226
45.07100	294.8973	15.00230
45.17100	294.9976	15.00236
45.27100	295.0966	15.00233
45.37084	295.1956	15.00226
45.47117	295.2954	15.00240
45.57117	295.3966	15.00255
45.67117	295.4961	15.00247
45.77100	295.5956	15.00247
45.87433	295.7006	15.00266
45.97516	295.8008	15.00255
46.07600	295.8994	15.00250
46.17600	296.0015	15.00260
46.27584	296.1007	15.00260
46.37583	296.2006	15.00279
46.47617	296.3008	15.00287
46.57617	296.3996	15.00279
46.67617	296.4996	15.00263
46.77600	296.5984	15.00287
46.87600	296.6997	15.00306
46.97600	296.8018	15.00312
47.07600	296.9013	15.00320
47.17600	297.0015	15.00316
47.27600	297.1015	15.00317
47.37583	297.2014	15.00314
47.47584	297.2998	15.00332
47.57617	297.4000	15.00329
47.67617	297.5011	15.00341
47.77600	297.6034	15.00358
47.87600	297.7020	15.00352
47.97600	297.8035	15.00355
48.07600	297.9000	15.00339
48.17600	298.0008	15.00374
48.27600	298.1007	15.00361
48.37600	298.2016	15.00375
48.47584	298.3036	15.00373
48.57617	298.4039	15.00387
48.67700	298.5041	15.00383
48.77766	298.6035	15.00383
48.88100	298.7087	15.00390
48.98100	298.8076	15.00405
49.08267	298.9082	15.00422
49.18350	299.0083	15.00424
49.28433	299.1082	15.00418
49.38584	299.2093	15.00428
49.48617	299.3091	15.00429
49.58933	299.4144	15.00446
49.69016	299.5142	15.00440
49.79100	299.6145	15.00462
49.89266	299.7162	15.00468
49.99250	299.8170	15.00466
50.09450	299.9192	15.00467
50.19617	300.0189	15.00468
50.29766	300.1201	15.00467
50.39934	300.2228	15.00467
50.49933	300.3208	15.00471
50.60100	300.4238	15.00479
50.70183	300.5254	15.00480
50.80266	300.6269	15.00484
50.90283	300.7280	15.00483
51.00284	300.8285	15.00492
51.10266	300.9268	15.00496
51.20266	301.0286	15.00503
51.30266	301.1272	15.00513
51.40250	301.2280	15.00525
51.50283	301.3284	15.00529
51.60283	301.4278	15.00545
51.70266	301.5276	15.00550
51.80266	301.6252	15.00554
51.90266	301.7266	15.00551
52.00266	301.8256	15.00550
52.10266	301.9263	15.00561
52.20250	302.0265	15.00561
52.30283	302.1268	15.00572
52.40283	302.2278	15.00577
52.50283	302.3284	15.00591
52.60266	302.4289	15.00596
52.70266	302.5282	15.00598
52.80266	302.6286	15.00602
52.90266	302.7294	15.00604
53.00266	302.8280	15.00610
53.10250	302.9282	15.00619
53.20283	303.0266	15.00640
53.30266	303.1292	15.00646
53.40266	303.2266	15.00630
53.50266	303.3310	15.00631
53.60600	303.4291	15.00650
53.70600	303.5314	15.00644
53.80766	303.6316	15.00649
53.90850	303.7362	15.00672
54.00933	303.8376	15.00687
54.11100	303.9366	15.00701
54.21100	304.0360	15.00684
54.31084	304.1368	15.00699
54.41118	304.2361	15.00707
54.51116	304.3372	15.00716
54.61118	304.4367	15.00726
54.71118	304.5370	15.00725
54.81116	304.6387	15.00750
54.91118	304.7360	15.00746
55.01116	304.8329	15.00735
55.11118	304.9348	15.00739
55.21118	305.0325	15.00746
55.31116	305.1338	15.00766
55.41118	305.2332	15.00768
55.51116	305.3335	15.00771
55.61118	305.4340	15.00762
55.71118	305.5366	15.00781
55.81116	305.6360	15.00783
55.91118	305.7364	15.00791
56.01116	305.8358	15.00791
56.11100	305.9360	15.00792
56.21100	306.0351	15.00799
56.31100	306.1338	15.00810
56.41100	306.2340	15.00807
56.51100	306.3352	15.00808
56.61100	306.4346	15.00821
56.71100	306.5353	15.00813
56.81100	306.6348	15.00821
56.91100	306.7348	15.00826
57.01433	306.8388	15.00834
57.11600	306.9410	15.00847
57.21766	307.0438	15.00852
57.31766	307.1428	15.00860
57.41768	307.2420	15.00869
57.51934	307.3469	15.00878
57.61934	307.4442	15.00870
57.71934	307.5435	15.00890
57.81933	307.6447	15.00889
57.91934	307.7426	15.00887
58.01934	307.8428	15.00892
58.11934	307.9418	15.00894
58.21934	308.0403	15.00899
58.31933	308.1408	15.00903
58.41934	308.2400	15.00906
58.51934	308.3413	15.00915
58.61934	308.4425	15.00937
58.71934	308.5446	15.00940
58.81933	308.6432	15.00935
58.91934	308.7438	15.00937
59.01916	308.8462	15.00955
59.11916	308.9452	15.00964
59.21916	309.0457	15.00972
59.31916	309.1453	15.00982
59.41916	309.2447	15.00980
59.51916	309.3432	15.00974
59.61916	309.4434	15.00986
59.71916	309.5435	15.00990
59.81916	309.6422	15.01003
59.91916	309.7455	15.01014
60.01916	309.8461	15.01028
60.11934	309.9454	15.01038
60.21934	310.0452	15.01023
60.32016	310.1459	15.01039
60.42100	310.2465	15.01042
60.52434	310.3501	15.01075
60.62434	310.4497	15.01061
60.72600	310.5510	15.01082
60.82700	310.6508	15.01078
60.92783	310.7533	15.01099
61.03116	310.8574	15.01099
61.13118	310.9569	15.01106
61.23250	311.0550	15.01084
61.33332	311.1546	15.01098
61.43433	311.2575	15.01110
61.53600	311.3584	15.01118
61.63600	311.4596	15.01124
61.73766	311.5610	15.01126
61.83933	311.6635	15.01139
61.94100	311.7635	15.01139
62.04283	311.8647	15.01149
62.14283	311.9657	15.01154
62.24450	312.0678	15.01161
62.34533	312.1674	15.01167
62.44584	312.2691	15.01180
62.54932	312.3726	15.01184
62.64934	312.4722	15.01184
62.74934	312.5730	15.01185
62.84934	312.6704	15.01182
62.94934	312.7744	15.01190
63.04950	312.8716	15.01203
63.14916	312.9711	15.01208
63.24934	313.0720	15.01205
63.34934	313.1738	15.01230
63.44934	313.2766	15.01223
63.54950	313.3754	15.01231
63.64950	313.4785	15.01211
63.74934	313.5754	15.01276
63.84934	313.6680	15.01250
63.94934	313.7765	15.01292
64.04932	313.8738	15.01261
64.14950	313.9744	15.01267
64.24950	314.0730	15.01271
64.34918	314.1736	15.01274
64.44934	314.2728	15.01278
64.54932	314.3732	15.01279
64.64932	314.4736	15.01289
64.74934	314.5738	15.01298
64.84950	314.6742	15.01298
64.94950	314.7752	15.01317
65.04916	314.8754	15.01317
65.14932	314.9731	15.01320
65.25100	315.0783	15.01326
65.35100	315.1768	15.01354
65.45266	315.2794	15.01342
65.55434	315.3809	15.01339
65.65616	315.4818	15.01348
65.75784	315.5836	15.01359
65.85784	315.6834	15.01381
65.95918	315.7838	15.01383
66.06000	315.8834	15.01389
66.16100	315.9850	15.01407
66.26100	316.0878	15.01399
66.36100	316.1860	15.01399
66.46100	316.2843	15.01409
66.56100	316.3832	15.01413
66.66116	316.4808	15.01413
66.76084	316.5830	15.01414
66.86100	316.6848	15.01433
66.96100	316.7838	15.01436
67.06100	316.8825	15.01439
67.16116	316.9834	15.01464
67.26118	317.0847	15.01471
67.36100	317.1845	15.01475
67.46100	317.2840	15.01473
67.56100	317.3840	15.01484
67.66100	317.4820	15.01487
67.76118	317.5834	15.01508
67.86084	317.6828	15.01496
67.96100	317.7827	15.01506
68.06100	317.8830	15.01515
68.16100	317.9839	15.01516
68.26118	318.0833	15.01527
68.36084	318.1855	15.01528
68.46100	318.2842	15.01540
68.56100	318.3843	15.01548
68.66100	318.4837	15.01548
68.76100	318.5850	15.01552
68.86118	318.6844	15.01566
68.96250	318.7870	15.01569
69.06268	318.8856	15.01577
69.16600	318.9882	15.01580
69.26684	319.0895	15.01584
69.36782	319.1908	15.01592
69.46918	319.2930	15.01598
69.56934	319.3968	15.01599
69.66934	319.4953	15.01613
69.76934	319.5954	15.01626
69.86932	319.6972	15.01646
69.96950	319.7962	15.01644
70.06950	319.8965	15.01639
70.16950	319.9982	15.01656
70.26950	320.0972	15.01664
70.36916	320.1990	15.01673
70.46918	320.2992	15.01680
70.56934	320.3988	15.01683
70.66934	320.4976	15.01684
70.76934	320.5987	15.01692
70.86932	320.6965	15.01701
70.96932	320.7968	15.01700
71.06934	320.8961	15.01700
71.16934	320.9965	15.01715
71.26934	321.0966	15.01716
71.36950	321.1969	15.01726
71.46950	321.2947	15.01726
71.56950	321.3960	15.01736
71.66950	321.4950	15.01737
71.76950	321.5964	15.01741
71.86950	321.6938	15.01736
71.96950	321.7948	15.01749
72.06950	321.8940	15.01760
72.16916	321.9933	15.01766
72.26916	322.0944	15.01777
72.37084	322.1966	15.01782
72.47250	322.2975	15.01780
72.57434	322.3985	15.01785
72.67600	322.5007	15.01784
72.77600	322.6012	15.01801
72.87768	322.7009	15.01789
72.97850	322.8028	15.01803
73.07934	322.9046	15.01808
73.17934	323.0038	15.01814
73.27934	323.1035	15.01820
73.37934	323.2040	15.01823
73.47934	323.3040	15.01832
73.57934	323.4038	15.01838
73.67934	323.5037	15.01848
73.77934	323.6058	15.01843
73.87934	323.7044	15.01862
73.97934	323.8029	15.01869
74.07934	323.9034	15.01862
74.17934	324.0040	15.01876
74.27950	324.1039	15.01878
74.37950	324.2039	15.01874
74.47950	324.3030	15.01884
74.57950	324.4018	15.01892
74.67950	324.5022	15.01902
74.77950	324.6026	15.01906
74.87950	324.7037	15.01900
74.97950	324.8050	15.01918
75.07950	324.9052	15.01924
75.17950	325.0052	15.01925
75.27950	325.1059	15.01934
75.37950	325.2045	15.01944
75.47950	325.3045	15.01946
75.57950	325.4048	15.01954
75.67950	325.5037	15.01970
75.77918	325.6042	15.01971
75.88250	325.7080	15.01997
75.98266	325.8094	15.01998
76.08434	325.9106	15.02009
76.18516	326.0146	15.02007
76.28600	326.1104	15.02011
76.38934	326.2144	15.02011
76.48950	326.3120	15.02015
76.59116	326.4120	15.02015
76.69082	326.5127	15.02016
76.79100	326.6108	15.02030
76.89100	326.7125	15.02036
76.99100	326.8115	15.02029
77.09116	326.9121	15.02045
77.19082	327.0115	15.02035
77.29100	327.1114	15.02047
77.39100	327.2135	15.02048
77.49100	327.3140	15.02066
77.59116	327.4131	15.02078
77.69116	327.5113	15.02058
77.79082	327.6116	15.02066
77.89100	327.7131	15.02087
77.99100	327.8141	15.02096
78.09100	327.9148	15.02090
78.19100	328.0141	15.02106
78.29116	328.1165	15.02129
78.39116	328.2183	15.02119
78.49116	328.3160	15.02124
78.59116	328.4182	15.02120
78.69082	328.5175	15.02125
78.79100	328.6150	15.02126
78.89100	328.7153	15.02133
78.99100	328.8155	15.02139
79.09100	328.9158	15.02143
79.19100	329.0143	15.02142
79.29266	329.1154	15.02154
79.39368	329.2174	15.02186
79.49450	329.3215	15.02207
79.59582	329.4235	15.02172
79.69600	329.5227	15.02181
79.79932	329.6244	15.02191
79.89932	329.7234	15.02200
79.99934	329.8235	15.02197
80.09934	329.9228	15.02211
80.19934	330.0228	15.02194
80.29932	330.1237	15.02225
80.39950	330.2252	15.02227
80.49950	330.3222	15.02224
80.59950	330.4244	15.02219
80.69916	330.5239	15.02238
80.79932	330.6205	15.02237
80.89932	330.7230	15.02232
80.99934	330.8208	15.02241
81.09934	330.9230	15.02245
81.19934	331.0234	15.02244
81.29932	331.1233	15.02260
81.39950	331.2222	15.02262
81.49950	331.3295	15.02314
81.59918	331.4306	15.02310
81.69934	331.5327	15.02287
81.79932	331.6297	15.02277
81.89932	331.7283	15.02276
81.99934	331.8262	15.02289
82.09934	331.9247	15.02306
82.19934	332.0260	15.02323
82.29950	332.1304	15.02332
82.39950	332.2292	15.02325
82.50082	332.3269	15.02328
82.60184	332.4277	15.02334
82.70266	332.5281	15.02341
82.80266	332.6280	15.02339
82.90266	332.7251	15.02327
83.00268	332.8245	15.02342
83.10266	332.9246	15.02354
83.20266	333.0224	15.02353
83.30266	333.1228	15.02360
83.40282	333.2248	15.02361
83.50250	333.3225	15.02368
83.60266	333.4216	15.02378
83.70266	333.5256	15.02379
83.80266	333.6246	15.02391
83.90266	333.7263	15.02400
84.00268	333.8241	15.02391
84.10284	333.9269	15.02401
84.20282	334.0269	15.02391
84.30250	334.1270	15.02398
84.40266	334.2250	15.02397
84.50268	334.3259	15.02401
84.60266	334.4250	15.02410
84.70266	334.5288	15.02455
84.80266	334.6322	15.02474
84.90266	334.7310	15.02439
85.00282	334.8291	15.02448
85.10284	334.9290	15.02448
85.20282	335.0270	15.02455
85.30250	335.1280	15.02452
85.40250	335.2275	15.02445
85.50268	335.3276	15.02454
85.60266	335.4269	15.02463
85.70266	335.5275	15.02468
85.80266	335.6270	15.02473
85.90266	335.7265	15.02473
86.00268	335.8272	15.02480
86.10266	335.9265	15.02492
86.20282	336.0258	15.02486
86.30282	336.1263	15.02490
86.40282	336.2264	15.02490
86.50282	336.3258	15.02497
86.60284	336.4264	15.02502
86.70282	336.5272	15.02514
86.80282	336.6266	15.02521
86.90282	336.7278	15.02508
87.00268	336.8294	15.02514
87.10266	336.9292	15.02519
87.20266	337.0304	15.02522
87.30266	337.1281	15.02535
87.40282	337.2277	15.02524
87.50282	337.3286	15.02516
87.60284	337.4285	15.02509
87.70266	337.5275	15.02510
87.80266	337.6272	15.02525
87.90266	337.7288	15.02521
88.00434	337.8328	15.02540
88.10601	337.9331	15.02534
88.20766	338.0325	15.02526
88.30782	338.1328	15.02530
88.40949	338.2359	15.02529
88.51032	338.3362	15.02530
88.61118	338.4370	15.02522
88.71282	338.5400	15.02540
88.81250	338.6365	15.02546
88.91582	338.7395	15.02538
89.01668	338.8405	15.02549
89.11750	338.9422	15.02550
89.21918	339.0450	15.02549
89.31916	339.1444	15.02554
89.42100	339.2459	15.02558
89.52101	339.3456	15.02567
89.62101	339.4456	15.02576
89.72101	339.5462	15.02587
89.82100	339.6470	15.02588
89.92100	339.7467	15.02581
90.02084	339.8450	15.02583
90.12084	339.9478	15.02594
90.22082	340.0478	15.02588
90.32082	340.1455	15.02590
90.42082	340.2456	15.02584
90.52084	340.3464	15.02598
90.62084	340.4450	15.02608
90.72101	340.5448	15.02597
90.82100	340.6443	15.02597
90.92100	340.7430	15.02616
91.02101	340.8435	15.02609
91.12101	340.9436	15.02608
91.22101	341.0437	15.02612
91.32100	341.1445	15.02614
91.42118	341.2434	15.02599
91.52118	341.3455	15.02626
91.62118	341.4430	15.02622
91.72082	341.5426	15.02614
91.82082	341.6434	15.02618
91.92100	341.7448	15.02628
92.02101	341.8458	15.02627
92.12101	341.9462	15.02635
92.22266	342.0478	15.02632
92.32434	342.1502	15.02642
92.42618	342.2498	15.02635
92.52618	342.3509	15.02635
92.62750	342.4534	15.02638
92.72766	342.5550	15.02633
92.82766	342.6548	15.02646
92.92766	342.7535	15.02632
93.02766	342.8528	15.02637
93.12782	342.9534	15.02643
93.22784	343.0542	15.02634
93.32750	343.1558	15.02642
93.42766	343.2539	15.02643
93.52766	343.3532	15.02654
93.62768	343.4511	15.02647
93.72766	343.5533	15.02676
93.82782	343.6528	15.02664
93.92750	343.7517	15.02653
94.02766	343.8525	15.02661
94.12768	343.9516	15.02636
94.22766	344.0531	15.02647
94.32766	344.1503	15.02650
94.42782	344.2517	15.02642
94.52782	344.3533	15.02664
94.62750	344.4544	15.02665
94.72766	344.5544	15.02655
94.82766	344.6515	15.02651
94.92766	344.7529	15.02662
95.02782	344.8532	15.02635
95.12782	344.9534	15.02668
95.22766	345.0519	15.02664
95.32766	345.1521	15.02660
95.42934	345.2524	15.02655
95.53100	345.3549	15.02672
95.63282	345.4589	15.02648
95.73250	345.5580	15.02645
95.83434	345.6600	15.02645
95.93516	345.7591	15.02641
96.03601	345.8616	15.02662
96.13950	345.9642	15.02657
96.23918	346.0634	15.02651
96.34101	346.1640	15.02638
96.44184	346.2654	15.02632
96.54266	346.3660	15.02639
96.64434	346.4690	15.02640
96.74450	346.5672	15.02612
96.84782	346.6714	15.02616
96.94850	346.7732	15.02626
97.04932	346.8740	15.02625
97.15100	346.9770	15.02639
97.25100	347.0766	15.02628
97.35284	347.1760	15.02619
97.45450	347.2794	15.02624
97.55600	347.3800	15.02625
97.65766	347.4806	15.02621
97.75766	347.5808	15.02614
97.85934	347.6833	15.02621
97.96016	347.7832	15.02623
98.06116	347.8864	15.02625
98.16282	347.9899	15.02626
98.26250	348.0901	15.02602
98.36600	348.1931	15.02600
98.46684	348.2918	15.02595
98.56766	348.3919	15.02586
98.66950	348.4963	15.02602
98.76950	348.5966	15.02606
98.87084	348.6965	15.02600
98.97101	348.7959	15.02594
99.07100	348.8980	15.02585
99.17100	348.9975	15.02580
99.27101	349.0934	15.02570
99.37118	349.1972	15.02568
99.47118	349.2945	15.02559
99.57118	349.3950	15.02561
99.67082	349.4950	15.02550
99.77084	349.5916	15.02528
99.87101	349.6943	15.02535
99.97101	349.7946	15.02528
100.0710	349.8971	15.02522
100.1710	349.9948	15.02506
100.2710	350.0938	15.02498
100.3710	350.1949	15.02496
100.4710	350.2946	15.02480
100.5710	350.3963	15.02478
100.6710	350.4963	15.02484
100.7710	350.5960	15.02468
100.8710	350.6954	15.02462
100.9710	350.7978	15.02459
101.0710	350.8985	15.02452
101.1710	350.9998	15.02465
101.2710	351.0994	15.02446
101.3710	351.1989	15.02436
101.4710	351.3000	15.02438
101.5727	351.4015	15.02437
101.6735	351.5011	15.02431
101.7743	351.6014	15.02408
101.8760	351.7016	15.02394
101.9760	351.8016	15.02396
102.0777	351.9026	15.02372
102.1793	352.0026	15.02359
102.2812	352.1038	15.02349
102.3828	352.2053	15.02342
102.4825	352.3054	15.02342
102.5843	352.4060	15.02332
102.6852	352.5078	15.02316
102.7860	352.6079	15.02319
102.8893	352.7134	15.02334
102.9893	352.8138	15.02306
103.0910	352.9170	15.02286
103.1918	353.0172	15.02276
103.2927	353.1168	15.02247
103.3943	353.2208	15.02263
103.4943	353.3181	15.02250
103.5978	353.4225	15.02235
103.6987	353.5238	15.02222
103.7993	353.6256	15.02230
103.9010	353.7280	15.02215
104.0010	353.8270	15.02205
104.1027	353.9283	15.02186
104.2045	354.0300	15.02185
104.3062	354.1320	15.02162
104.4078	354.2316	15.02137
104.5075	354.3334	15.02133
104.6077	354.4322	15.02111
104.7077	354.5334	15.02120
104.8077	354.6315	15.02090
104.9077	354.7320	15.02075
105.0077	354.8303	15.02053
105.1078	354.9307	15.02051
105.2078	355.0332	15.02029
105.3078	355.1308	15.01998
105.4078	355.2315	15.01999
105.5078	355.3325	15.01985
105.6078	355.4350	15.01968
105.7075	355.5332	15.01956
105.8075	355.6338	15.01952
105.9077	355.7359	15.01931
106.0077	355.8350	15.01919
106.1077	355.9336	15.01901
106.2077	356.0320	15.01880
106.3077	356.1324	15.01869
106.4077	356.2305	15.01840
106.5077	356.3312	15.01825
106.6077	356.4332	15.01809
106.7077	356.5350	15.01810
106.8077	356.6390	15.01800
106.9077	356.7341	15.01739
107.0077	356.8346	15.01734
107.1093	356.9354	15.01719
107.2093	357.0350	15.01689
107.3110	357.1356	15.01671
107.4127	357.2346	15.01646
107.5145	357.3374	15.01649
107.6162	357.4428	15.01639
107.7162	357.5472	15.01626
107.8177	357.6476	15.01584
107.9187	357.7456	15.01563
108.0195	357.8472	15.01544
108.1212	357.9465	15.01504
108.2212	358.0442	15.01483
108.3245	358.1472	15.01457
108.4250	358.2478	15.01426
108.5258	358.3472	15.01396
108.6277	358.4519	15.01402
108.7277	358.5515	15.01366
108.8276	358.6521	15.01342
108.9276	358.7515	15.01299
109.0276	358.8529	15.01320
109.1275	358.9520	15.01256
109.2275	359.0536	15.01218
109.3278	359.1578	15.01205
109.4278	359.2562	15.01177
109.5278	359.3563	15.01165
109.6278	359.4551	15.01114
109.7278	359.5561	15.01072
109.8278	359.6569	15.01069
109.9278	359.7556	15.01057
110.0276	359.8517	15.00988
110.1277	359.9540	15.00956
110.2277	360.0540	15.00924
110.3276	360.1535	15.00889
110.4276	360.2536	15.00864
110.5276	360.3538	15.00834
110.6277	360.4530	15.00804
110.7275	360.5541	15.00768
110.8275	360.6533	15.00720
110.9278	360.7522	15.00666
111.0278	360.8548	15.00659
111.1278	360.9544	15.00634
111.2278	361.0550	15.00578
111.3276	361.1532	15.00540
111.4276	361.2510	15.00497
111.5310	361.3559	15.00462
111.6318	361.4553	15.00409
111.7327	361.5558	15.00370
111.8343	361.6571	15.00330
111.9343	361.7574	15.00281
112.0360	361.8591	15.00234
112.1377	361.9600	15.00184
112.2393	362.0619	15.00138
112.3427	362.1637	15.00076
112.4427	362.2683	15.00044
112.5427	362.3674	14.99994
112.6434	362.4675	14.99940
112.7443	362.5706	14.99891
112.8443	362.6660	14.99806
112.9443	362.7722	14.99829
113.0443	362.8678	14.99736
113.1443	362.9693	14.99694
113.2443	363.0703	14.99644
113.3443	363.1677	14.99583
113.4443	363.2726	14.99523
113.5443	363.3688	14.99468
113.6443	363.4660	14.99382
113.7443	363.5698	14.99368
113.8443	363.6686	14.99262
113.9443	363.7675	14.99186
114.0443	363.8684	14.99118
114.1443	363.9690	14.99061
114.2443	364.0702	14.98995
114.3443	364.1688	14.98907
114.4443	364.2684	14.98841
114.5443	364.3684	14.98770
114.6443	364.4678	14.98679
114.7445	364.5691	14.98610
114.8442	364.6678	14.98535
114.9443	364.7684	14.98446
115.0443	364.8695	14.98351
115.1443	364.9710	14.98302
115.2442	365.0724	14.98207
115.3453	365.1720	14.98103
115.4462	365.2749	14.98014
115.5495	365.3773	14.97921
115.6495	365.4749	14.97834
115.7512	365.5758	14.97748
115.8520	365.6771	14.97638
115.9528	365.7802	14.97538
116.0545	365.8791	14.97436
116.1545	365.9806	14.97341
116.2578	366.0851	14.97221
116.3585	366.1853	14.97102
116.4593	366.2844	14.96992
116.5610	366.3858	14.96878
116.6610	366.4868	14.96766
116.7645	366.5908	14.96630
116.8653	366.6887	14.96502
116.9662	366.7915	14.96396
117.0675	366.8900	14.96257
117.1677	366.9903	14.96124
117.2693	367.0924	14.95988
117.3702	367.1937	14.95834
117.4710	367.2936	14.95718
117.5743	367.3983	14.95536
117.6743	367.4985	14.95368
117.7760	367.5990	14.95210
117.8770	367.6997	14.95052
117.9778	367.8032	14.94869
118.0795	367.9054	14.94703
118.1795	368.0046	14.94536
118.2825	368.1083	14.94328
118.3835	368.2079	14.94152
118.4843	368.3076	14.93958
118.5860	368.4085	14.93750
118.6860	368.5078	14.93534
118.7893	368.6120	14.93298
118.8902	368.7148	14.93075
118.9912	368.8141	14.92831
119.0928	368.9167	14.92594
119.1925	369.0158	14.92329
119.2927	369.1156	14.92033
119.3927	369.2172	14.91765
119.4927	369.3176	14.91467
119.5927	369.4177	14.91170
119.6927	369.5170	14.90819
119.7928	369.6169	14.90458
119.8928	369.7178	14.90082
119.9925	369.8158	14.89664
120.0927	369.9160	14.89225
120.1927	370.0170	14.88757
120.2927	370.1185	14.88249
120.3927	370.2196	14.87702
120.4927	370.3216	14.87106
120.5927	370.4222	14.86486
120.6927	370.5221	14.85795
120.7927	370.6240	14.85089
120.8927	370.7229	14.84315
120.9927	370.8230	14.83497
121.0928	370.9226	14.82653
121.1928	371.0222	14.81798
121.2928	371.1190	14.80845
121.3925	371.2208	14.79867
121.4927	371.3172	14.78824
121.5927	371.4167	14.77732
121.6927	371.5147	14.76578
121.7927	371.6164	14.75378
121.8927	371.7176	14.74157
121.9942	371.8198	14.72947
122.0962	371.9219	14.71692
122.1978	372.0239	14.70428
122.2993	372.1265	14.69210
122.3993	372.2258	14.68021
122.5010	372.3261	14.66836
122.6018	372.4278	14.65641
122.7026	372.5313	14.64444
122.8043	372.6325	14.63249
122.9042	372.7318	14.62011
123.0078	372.8355	14.60688
123.1087	372.9358	14.59481
123.2093	373.0362	14.58241
123.3110	373.1370	14.57024
123.4110	373.2372	14.55808
123.5143	373.3396	14.54506
123.6152	373.4386	14.53293
123.7160	373.5392	14.52072
123.8177	373.6421	14.50854
123.9177	373.7402	14.49625
124.0193	373.8422	14.48371
124.1202	373.9434	14.47119
124.2210	374.0458	14.45907
124.3242	374.1498	14.44646
124.4242	374.2508	14.43515
124.5242	374.3502	14.42430
124.6242	374.4498	14.41426
124.7242	374.5481	14.40498
124.8243	374.6470	14.39635
124.9243	374.7490	14.38840
125.0243	374.8458	14.38152
125.1243	374.9463	14.37528
125.2243	375.0464	14.36983
125.3245	375.1459	14.36495
125.4245	375.2463	14.36082
125.5245	375.3460	14.35772
125.6242	375.4483	14.35486
125.7242	375.5485	14.35242
125.8243	375.6503	14.35051
125.9243	375.7480	14.34852
126.0243	375.8515	14.34682
126.1243	375.9500	14.34548
126.2243	376.0514	14.34410
126.3243	376.1525	14.34290
126.4243	376.2530	14.34199
126.5243	376.3510	14.34092
126.6245	376.4510	14.34010
126.7245	376.5495	14.33928
126.8242	376.6490	14.33852
126.9243	376.7495	14.33799
127.0243	376.8494	14.33730
127.1243	376.9510	14.33672
127.2260	377.0528	14.33620
127.3268	377.1534	14.33570
127.4276	377.2561	14.33520
127.5292	377.3563	14.33469
127.6292	377.4534	14.33421
127.7293	377.5525	14.33383
127.8293	377.6512	14.33340
127.9293	377.7519	14.33297
128.0293	377.8513	14.33263
128.1293	377.9512	14.33232
128.2294	378.0509	14.33194
128.3295	378.1506	14.33168
128.4295	378.2518	14.33145
128.5295	378.3531	14.33113
128.6292	378.4560	14.33064
128.7294	378.5576	14.33061
128.8293	378.6566	14.33024
128.9293	378.7566	14.33000
129.0293	378.8564	14.32982
129.1293	378.9580	14.32964
129.2294	379.0565	14.32928
129.3293	379.1568	14.32898
129.4293	379.2552	14.32899
129.5293	379.3569	14.32876
129.6295	379.4548	14.32872
129.7295	379.5542	14.32841
129.8292	379.6513	14.32825
129.9293	379.7528	14.32803
130.0293	379.8520	14.32781
130.1293	379.9530	14.32776
130.2310	380.0520	14.32740
130.3310	380.1534	14.32746
130.4328	380.2538	14.32722
130.5337	380.3570	14.32713
130.6345	380.4555	14.32692
130.7362	380.5603	14.32670
130.8358	380.6588	14.32658
130.9377	380.7613	14.32656
131.0393	380.8627	14.32638
131.1410	380.9639	14.32610
131.2427	381.0658	14.32603
131.3428	381.1675	14.32593
131.4445	381.2683	14.32580
131.5442	381.3720	14.32594
131.6444	381.4724	14.32554
131.7444	381.5732	14.32549
131.8444	381.6750	14.32548
131.9442	381.7758	14.32533
132.0442	381.8750	14.32507
132.1442	381.9739	14.32515
132.2444	382.0725	14.32512
132.3444	382.1709	14.32506
132.4444	382.2692	14.32484
132.5443	382.3684	14.32485
132.6444	382.4698	14.32473
132.7444	382.5690	14.32468
132.8444	382.6728	14.32482
132.9444	382.7706	14.32470
133.0445	382.8709	14.32464
133.1445	382.9696	14.32454
133.2442	383.0700	14.32451
133.3444	383.1663	14.32427
133.4444	383.2688	14.32422
133.5443	383.3687	14.32424
133.6444	383.4688	14.32417
133.7444	383.5696	14.32410
133.8444	383.6694	14.32402
133.9444	383.7695	14.32393
134.0445	383.8679	14.32388
134.1462	383.9716	14.32390
134.2477	384.0752	14.32399
134.3494	384.1720	14.32381
134.4510	384.2744	14.32388
134.5510	384.3727	14.32388
134.6526	384.4738	14.32365
134.7545	384.5748	14.32367
134.8562	384.6781	14.32354
134.9575	384.7796	14.32359
135.0577	384.8811	14.32342
135.1593	384.9812	14.32319
135.2602	385.0822	14.32314
135.3612	385.1855	14.32334
135.4642	385.2888	14.32311
135.5642	385.3868	14.32294
135.6660	385.4926	14.32314
135.7668	385.5916	14.32311
135.8677	385.6940	14.32290
135.9694	385.7963	14.32298
136.0694	385.8958	14.32296
136.1727	385.9995	14.32286
136.2737	386.1002	14.32294
136.3745	386.1998	14.32280
136.4758	386.3020	14.32288
136.5760	386.4011	14.32284
136.6777	386.5018	14.32264
136.7785	386.6085	14.32275
136.8794	386.7072	14.32277
136.9827	386.8088	14.32270
137.0827	386.9104	14.32266
137.1843	387.0132	14.32273
137.2852	387.1141	14.32269
137.3862	387.2152	14.32266
137.4895	387.3186	14.32265
137.5895	387.4170	14.32257
137.6908	387.5170	14.32253
137.7908	387.6180	14.32251
137.8908	387.7170	14.32241
137.9908	387.8200	14.32239
138.0908	387.9184	14.32236
138.1908	388.0192	14.32248
138.2908	388.1184	14.32255
138.3908	388.2178	14.32250
138.4908	388.3178	14.32250
138.5908	388.4161	14.32238
138.6910	388.5161	14.32216
138.7910	388.6163	14.32238
138.8910	388.7160	14.32251
138.9910	388.8152	14.32234
139.0910	388.9149	14.32222
139.1910	389.0156	14.32229
139.2910	389.1150	14.32234
139.3910	389.2140	14.32220
139.4910	389.3144	14.32223
139.5910	389.4148	14.32223
139.6910	389.5163	14.32230
139.7912	389.6167	14.32198
139.8912	389.7169	14.32230
139.9912	389.8172	14.32224
140.0912	389.9156	14.32210
140.1908	390.0159	14.32199
140.2908	390.1155	14.32204
140.3910	390.2164	14.32211
140.4910	390.3132	14.32190
140.5910	390.4154	14.32180
140.6910	390.5140	14.32176
140.7910	390.6125	14.32169
140.8912	390.7165	14.32190
140.9912	390.8168	14.32175
141.0912	390.9180	14.32188
141.1912	391.0160	14.32184
141.2912	391.1140	14.32183
141.3908	391.2150	14.32165
141.4908	391.3158	14.32178
141.5910	391.4142	14.32172
141.6910	391.5174	14.32184
141.7910	391.6174	14.32189
141.8910	391.7165	14.32178
141.9910	391.8166	14.32170
142.0910	391.9170	14.32158
142.1910	392.0178	14.32168
142.2910	392.1160	14.32156
142.3910	392.2175	14.32158
142.4910	392.3178	14.32173
142.5910	392.4190	14.32164
142.6910	392.5175	14.32158
142.7910	392.6204	14.32161
142.8912	392.7180	14.32146
142.9912	392.8189	14.32150
143.0912	392.9178	14.32166
143.1908	393.0164	14.32148
143.2910	393.1149	14.32144
143.3910	393.2128	14.32192
143.4910	393.3160	14.32154
143.5910	393.4166	14.32145
143.6910	393.5173	14.32157
143.7910	393.6163	14.32151
143.8910	393.7150	14.32138
143.9910	393.8160	14.32147
144.0910	393.9152	14.32144
144.1910	394.0152	14.32140
144.2912	394.1176	14.32142
144.3912	394.2170	14.32146
144.4908	394.3158	14.32138
144.5908	394.4192	14.32169
144.6908	394.5160	14.32155
144.7908	394.6160	14.32141
144.8908	394.7159	14.32124
144.9908	394.8176	14.32148
145.0908	394.9167	14.32129
145.1908	395.0191	14.32137
145.2908	395.1197	14.32125
145.3908	395.2178	14.32122
145.4908	395.3202	14.32121
145.5910	395.4174	14.32124
145.6910	395.5166	14.32126
145.7910	395.6162	14.32125
145.8918	395.7156	14.32132
145.9927	395.8152	14.32117
146.0945	395.9184	14.32126
146.1942	396.0183	14.32109
146.2960	396.1217	14.32134
146.3960	396.2213	14.32134
146.4960	396.3207	14.32116
146.5960	396.4202	14.32116
146.6960	396.5192	14.32113
146.7962	396.6213	14.32103
146.8962	396.7206	14.32111
146.9958	396.8209	14.32110
147.0958	396.9209	14.32109
147.1958	397.0198	14.32113
147.2960	397.1206	14.32107
147.3960	397.2235	14.32110
147.4958	397.3238	14.32096
147.5958	397.4237	14.32093
147.6960	397.5228	14.32091
147.7960	397.6223	14.32088
147.8960	397.7215	14.32083
147.9960	397.8202	14.32111
148.0960	397.9228	14.32109
148.1960	398.0206	14.32106
148.2960	398.1220	14.32103
148.3960	398.2230	14.32106
148.4962	398.3232	14.32110
148.5962	398.4210	14.32096
148.6958	398.5221	14.32085
148.7958	398.6216	14.32083
148.8960	398.7222	14.32091
148.9977	398.8246	14.32104
149.0985	398.9252	14.32103
149.1994	399.0244	14.32097
149.3010	399.1280	14.32102
149.4010	399.2318	14.32106
149.5027	399.3306	14.32102
149.6035	399.4317	14.32096
149.7042	399.5328	14.32100
149.8078	399.6361	14.32106
149.9078	399.7339	14.32097
149.9420	399.7680	14.32096