File: TGA/2023_07_11_CuSO4_5Hydrate_1cpm.txt
CLOSED
Version	0.4
Run	871
Instrument	2950 TGA       V5.4A
Module	TGA 1000 øC
Sample	2023_07_11_CuSO4_5Hydrate_1cpm
Size	47.0300	mg
Method	25C to 350C at 1 cpm
Operator	SBK
Comment	2023_07_11_CuSO4_5Hydrate_1cpm
Xcomment	Pan: Platinum           Gas1: Nitrogen  40          Gas2: Nitrogen  40
Text	2023_07_11_CuSO4_5Hydrate_1cpm
Text	Standard for calibration confirmation
Kcell	1.00000
TempCal	2	pts	156.68	152.50,	376.53	354.00
Thresholds	0.050	0.0000
Controls	Gas 1  Event Off  Sampling 2.0 sec/pt
Nsig	3
Sig1	Time (min)
Sig2	Temperature (øC)
Sig3	Weight (mg)
Date	11-Jul-23
Time	17:14
File	C:\TA\Data\TGA\Skyler\2023_07_11_CuSO4_5Hydrate_1cpm.001
OrgFile	C:\TA\Data\TGA\Skyler\2023_07_11_CuSO4_5Hydrate_1cpm.001
StartOfData
0.0000000	25.10737	46.91738
0.2326667	25.23578	46.89990
0.4661667	25.41881	46.88422
0.6991668	25.63134	46.86961
0.9326668	25.85463	46.85591
1.167834	26.08210	46.84374
1.406000	26.31875	46.83192
1.641000	26.55010	46.82101
1.876834	26.78344	46.81081
2.114500	27.02468	46.80106
2.349333	27.25864	46.79236
2.586000	27.49742	46.78415
2.822833	27.73210	46.77596
3.058500	27.96360	46.76851
3.294500	28.20008	46.76132
3.530834	28.43967	46.75457
3.767666	28.67649	46.74828
4.002666	28.91270	46.74250
4.240334	29.15289	46.73676
4.474333	29.38620	46.73139
4.707666	29.62070	46.72635
4.941166	29.85190	46.72164
5.174334	30.08450	46.71744
5.407666	30.31715	46.71350
5.641000	30.55054	46.70978
5.874500	30.78466	46.70611
6.107666	31.01626	46.70224
6.341000	31.24646	46.69885
6.574500	31.48530	46.69544
6.807500	31.71760	46.69274
7.042666	31.95398	46.68992
7.277000	32.18800	46.68736
7.514500	32.42528	46.68433
7.747668	32.66030	46.68124
7.981000	32.89209	46.67856
8.214500	33.12497	46.67602
8.447501	33.35648	46.67358
8.681000	33.59304	46.67124
8.914501	33.82538	46.66880
9.147668	34.05650	46.66646
9.381000	34.28906	46.66433
9.614501	34.52206	46.66172
9.847832	34.75883	46.65824
10.08100	34.99164	46.65498
10.31683	35.22720	46.65180
10.55266	35.45984	46.64828
10.78950	35.70365	46.64444
11.02600	35.93560	46.64042
11.26100	36.17504	46.63628
11.49867	36.40330	46.63118
11.73450	36.63960	46.62553
11.96950	36.87578	46.61806
12.20584	37.10741	46.60766
12.43933	37.34125	46.59504
12.67267	37.57672	46.57898
12.90617	37.80734	46.56003
13.13934	38.04004	46.53888
13.37267	38.27354	46.51596
13.60617	38.50384	46.49150
13.83916	38.73706	46.46620
14.07267	38.96845	46.44010
14.30600	39.20318	46.41388
14.53934	39.44056	46.38711
14.77434	39.67790	46.35930
15.00950	39.91280	46.33086
15.24750	40.14716	46.30020
15.48267	40.38018	46.26974
15.71850	40.61370	46.23896
15.95616	40.84700	46.20602
16.19084	41.08066	46.17354
16.42434	41.31511	46.13992
16.65784	41.55102	46.10552
16.89117	41.78085	46.07030
17.12433	42.01236	46.03438
17.35784	42.24772	45.99774
17.59100	42.48134	45.96018
17.82450	42.71562	45.92190
18.05766	42.94898	45.88296
18.29100	43.18536	45.84294
18.52417	43.42024	45.80190
18.75767	43.65424	45.76020
18.99284	43.89160	45.71770
19.22767	44.12485	45.67398
19.46617	44.35990	45.62808
19.70100	44.59408	45.58290
19.93784	44.82753	45.53627
20.17434	45.06403	45.48867
20.40950	45.29959	45.44114
20.64266	45.53034	45.39266
20.87617	45.76184	45.34381
21.10933	45.99568	45.29381
21.34266	46.22526	45.24342
21.57583	46.45988	45.19214
21.80934	46.69858	45.13988
22.04283	46.93220	45.08712
22.27583	47.16624	45.03340
22.50933	47.39962	44.97890
22.74284	47.62802	44.92415
22.97600	47.86394	44.86824
23.21100	48.09898	44.81197
23.44750	48.33398	44.75300
23.68100	48.56756	44.69522
23.91450	48.80384	44.63716
24.14766	49.04129	44.57790
24.38100	49.27211	44.51818
24.61450	49.50492	44.45764
24.84750	49.73500	44.39674
25.08100	49.96881	44.33540
25.31434	50.20212	44.27352
25.54766	50.43399	44.21106
25.78100	50.66826	44.14817
26.01533	50.89936	44.08467
26.25100	51.13817	44.02106
26.48600	51.37610	43.95669
26.72433	51.61450	43.88969
26.95933	51.84438	43.82475
27.19600	52.07466	43.75829
27.43266	52.30744	43.69168
27.66766	52.54985	43.62594
27.90600	52.79374	43.55746
28.14100	53.03163	43.49130
28.37433	53.26930	43.42484
28.60766	53.49879	43.35837
28.84100	53.73199	43.29198
29.07417	53.96200	43.22574
29.30766	54.19300	43.15938
29.54100	54.42805	43.09309
29.77417	54.66216	43.02694
30.00766	54.90391	42.96072
30.24117	55.13740	42.89472
30.47433	55.36855	42.82876
30.70766	55.60186	42.76310
30.94266	55.83494	42.69809
31.17783	56.07462	42.63344
31.41516	56.31076	42.56654
31.65100	56.54916	42.50279
31.88600	56.78444	42.43934
32.11934	57.01687	42.37680
32.35283	57.24741	42.31474
32.58600	57.48166	42.25326
32.81933	57.71524	42.19253
33.05283	57.95230	42.13263
33.28600	58.18480	42.07370
33.51933	58.41384	42.01531
33.75284	58.64724	41.95781
33.98617	58.88324	41.90131
34.21933	59.11045	41.84574
34.45266	59.33911	41.79115
34.68950	59.57859	41.73562
34.92433	59.80924	41.68274
35.16100	60.04450	41.63094
35.39783	60.28758	41.57822
35.63250	60.52234	41.52812
35.86600	60.75636	41.47924
36.09950	60.98968	41.43116
36.33250	61.22372	41.38414
36.56600	61.46230	41.33824
36.79950	61.69490	41.29326
37.03250	61.92883	41.24931
37.26600	62.16220	41.20652
37.49950	62.39460	41.16450
37.73284	62.62934	41.12364
37.96617	62.86620	41.08365
38.19950	63.09965	41.04478
38.43433	63.33713	41.00691
38.67100	63.56750	40.96954
38.90784	63.80933	40.93341
39.14266	64.04127	40.89939
39.37766	64.27740	40.86630
39.61117	64.51368	40.83440
39.84433	64.74838	40.80341
40.07766	64.97637	40.77350
40.31116	65.20582	40.74440
40.54434	65.44572	40.71633
40.77766	65.67830	40.68876
41.01100	65.90772	40.66250
41.24450	66.14522	40.63711
41.47783	66.37382	40.61274
41.71100	66.60470	40.58891
41.94433	66.84108	40.56620
42.17783	67.08178	40.54396
42.41100	67.31324	40.52252
42.64433	67.53614	40.50156
42.87766	67.76774	40.48132
43.11117	68.00450	40.46158
43.34433	68.24101	40.44266
43.57766	68.48087	40.42412
43.81100	68.70776	40.40637
44.04434	68.94282	40.38933
44.27766	69.17284	40.37322
44.51084	69.40540	40.35788
44.74617	69.63712	40.34317
44.98266	69.88160	40.32904
45.21766	70.11718	40.31619
45.45084	70.34622	40.30406
45.68450	70.57789	40.29261
45.91783	70.79931	40.28183
46.15117	71.03326	40.27168
46.38434	71.26830	40.26230
46.61767	71.50445	40.25356
46.85100	71.74586	40.24525
47.08450	71.97861	40.23776
47.31783	72.21143	40.23108
47.55117	72.44540	40.22484
47.78516	72.66872	40.21878
48.02266	72.91189	40.21302
48.25766	73.15112	40.20747
48.49267	73.39790	40.20216
48.72600	73.63072	40.19686
48.95950	73.86268	40.19172
49.19283	74.09294	40.18666
49.42617	74.32592	40.18147
49.65950	74.56536	40.17642
49.89283	74.80030	40.17153
50.12600	75.02906	40.16638
50.35933	75.26222	40.16128
50.59283	75.49243	40.15613
50.82617	75.71221	40.15089
51.06116	75.94675	40.14557
51.29766	76.19038	40.14034
51.53450	76.42872	40.13506
51.76950	76.66558	40.12972
52.00666	76.90302	40.12385
52.24267	77.13989	40.11818
52.47750	77.37822	40.11260
52.71118	77.61422	40.10669
52.94433	77.84794	40.10082
53.17766	78.08220	40.09482
53.41100	78.31201	40.08865
53.64450	78.54778	40.08244
53.87783	78.77741	40.07598
54.11100	79.00805	40.06960
54.34434	79.23378	40.06270
54.57766	79.46656	40.05594
54.81100	79.70197	40.04907
55.04450	79.93550	40.04198
55.28116	80.17124	40.03441
55.51416	80.40601	40.02706
55.74766	80.64125	40.01937
55.98116	80.87674	40.01140
56.21433	81.10814	40.00324
56.44766	81.34360	39.99492
56.68116	81.57556	39.98620
56.91433	81.80762	39.97720
57.14766	82.04306	39.96793
57.38118	82.27437	39.95808
57.61433	82.50740	39.94800
57.84766	82.73426	39.93698
58.08367	82.97408	39.92559
58.31766	83.20966	39.91305
58.55117	83.44516	39.89944
58.78433	83.67869	39.88438
59.01783	83.91225	39.86730
59.25100	84.14649	39.84803
59.48433	84.38056	39.82636
59.71783	84.61244	39.80262
59.95100	84.84272	39.77733
60.18433	85.07806	39.75137
60.41750	85.30750	39.72490
60.65100	85.54007	39.69803
60.88616	85.77684	39.67021
61.11934	86.00888	39.64104
61.35283	86.24792	39.61014
61.58600	86.48001	39.57655
61.81950	86.71109	39.53960
62.05266	86.94218	39.49813
62.28600	87.17155	39.45108
62.51950	87.40566	39.39710
62.75266	87.63956	39.33467
62.98618	87.87589	39.26335
63.21934	88.10881	39.18193
63.45250	88.34191	39.09052
63.68934	88.58019	38.98489
63.92432	88.81306	38.87259
64.16033	89.04944	38.75094
64.39434	89.28253	38.62040
64.62750	89.51584	38.48137
64.86100	89.75100	38.33461
65.09433	89.98160	38.18050
65.32783	90.21368	38.02010
65.56100	90.45056	37.85407
65.79434	90.68632	37.68272
66.02782	90.91838	37.50725
66.26100	91.15516	37.32826
66.49416	91.38837	37.14650
66.72766	91.62159	36.96314
66.96100	91.85701	36.77874
67.19868	92.09147	36.58844
67.43432	92.32813	36.40576
67.66950	92.56076	36.22591
67.90766	92.80009	36.04338
68.14282	93.03309	35.87297
68.37934	93.27311	35.70572
68.61616	93.51388	35.54691
68.84934	93.75126	35.40030
69.08282	93.98256	35.26470
69.31600	94.21655	35.14075
69.54916	94.44574	35.02940
69.78266	94.68088	34.93080
70.01600	94.91175	34.84465
70.24950	95.14241	34.77083
70.48266	95.37148	34.70795
70.71616	95.60656	34.65539
70.94934	95.83641	34.61206
71.18250	96.07153	34.57672
71.41600	96.30847	34.54800
71.64932	96.54126	34.52478
71.88284	96.77468	34.50702
72.11600	97.00446	34.49295
72.34934	97.23863	34.48201
72.58282	97.46968	34.47338
72.81600	97.70725	34.46614
73.04932	97.94109	34.45992
73.28250	98.17578	34.45472
73.51616	98.40618	34.45040
73.74934	98.63861	34.44669
73.98434	98.87731	34.44329
74.21950	99.11484	34.44022
74.45684	99.35101	34.43761
74.69250	99.58891	34.43537
74.92782	99.82325	34.43300
75.16432	100.0565	34.43106
75.39750	100.2899	34.42920
75.63100	100.5231	34.42752
75.86432	100.7542	34.42575
76.09750	100.9883	34.42429
76.33100	101.2237	34.42287
76.56432	101.4572	34.42139
76.79766	101.6914	34.42019
77.03082	101.9235	34.41887
77.26434	102.1558	34.41753
77.49782	102.3880	34.41634
77.73266	102.6261	34.41528
77.96766	102.8609	34.41420
78.20618	103.0992	34.41311
78.44100	103.3345	34.41195
78.67682	103.5717	34.41091
78.91418	103.8103	34.40986
79.14766	104.0424	34.40901
79.38100	104.2776	34.40818
79.61416	104.5144	34.40719
79.84750	104.7458	34.40630
80.08084	104.9804	34.40530
80.31450	105.2109	34.40442
80.54784	105.4422	34.40342
80.78116	105.6728	34.40255
81.01450	105.9012	34.40167
81.24782	106.1362	34.40078
81.48116	106.3662	34.39998
81.71700	106.5977	34.39912
81.95282	106.8331	34.39822
82.18950	107.0788	34.39740
82.42618	107.3205	34.39645
82.66116	107.5591	34.39570
82.89850	107.7947	34.39481
83.13450	108.0225	34.39392
83.36950	108.2614	34.39314
83.60766	108.5020	34.39239
83.84266	108.7339	34.39153
84.07934	108.9724	34.39058
84.31582	109.2093	34.38978
84.55084	109.4464	34.38910
84.78418	109.6780	34.38838
85.01782	109.9088	34.38777
85.25116	110.1410	34.38692
85.48434	110.3766	34.38636
85.71766	110.6108	34.38540
85.95100	110.8469	34.38464
86.18434	111.0804	34.38372
86.41782	111.3116	34.38319
86.65118	111.5391	34.38250
86.88434	111.7752	34.38181
87.11766	112.0042	34.38098
87.35116	112.2357	34.38003
87.58450	112.4687	34.37932
87.81782	112.7062	34.37857
88.05100	112.9426	34.37787
88.28434	113.1749	34.37717
88.51750	113.4051	34.37636
88.75116	113.6366	34.37560
88.98434	113.8676	34.37476
89.21766	114.0976	34.37396
89.45100	114.3368	34.37322
89.68418	114.5758	34.37269
89.91950	114.8099	34.37172
90.15699	115.0332	34.37095
90.39282	115.2690	34.37039
90.62768	115.5141	34.36961
90.86600	115.7613	34.36872
91.10100	115.9991	34.36794
91.33768	116.2392	34.36715
91.57434	116.4732	34.36630
91.80950	116.7042	34.36553
92.04766	116.9368	34.36479
92.28266	117.1703	34.36412
92.51766	117.4029	34.36332
92.75100	117.6406	34.36267
92.98434	117.8797	34.36210
93.21750	118.1122	34.36106
93.45084	118.3432	34.36032
93.68434	118.5699	34.35970
93.91766	118.8031	34.35875
94.15100	119.0500	34.35822
94.38434	119.2746	34.35748
94.61766	119.5079	34.35670
94.85116	119.7417	34.35594
95.08618	119.9774	34.35525
95.32282	120.2097	34.35430
95.55851	120.4432	34.35368
95.79434	120.6797	34.35285
96.03100	120.9142	34.35203
96.26766	121.1544	34.35126
96.50268	121.3901	34.35042
96.74032	121.6327	34.34960
96.97616	121.8687	34.34893
97.21100	122.1023	34.34824
97.44934	122.3363	34.34750
97.68450	122.5658	34.34668
97.91916	122.8031	34.34584
98.15266	123.0377	34.34511
98.38600	123.2672	34.34436
98.61932	123.4991	34.34363
98.85266	123.7336	34.34274
99.08618	123.9706	34.34192
99.31916	124.2055	34.34118
99.55266	124.4316	34.34044
99.78601	124.6297	34.33963
100.0195	124.8280	34.33895
100.2527	125.0230	34.33836
100.4862	125.2427	34.33764
100.7225	125.4888	34.33684
100.9585	125.7423	34.33607
101.1945	125.9998	34.33542
101.4308	126.2584	34.33462
101.6643	126.5114	34.33405
101.8977	126.7597	34.33312
102.1310	127.0047	34.33222
102.3643	127.2447	34.33160
102.5977	127.4844	34.33076
102.8310	127.7198	34.33002
103.0645	127.9522	34.32921
103.2978	128.1877	34.32848
103.5310	128.4204	34.32775
103.7643	128.6515	34.32695
103.9985	128.8830	34.32612
104.2343	129.1199	34.32536
104.4693	129.3574	34.32454
104.7077	129.5948	34.32372
104.9427	129.8292	34.32296
105.1793	130.0676	34.32204
105.4158	130.3037	34.32134
105.6508	130.5367	34.32060
105.8858	130.7724	34.31986
106.1193	131.0081	34.31894
106.3525	131.2424	34.31815
106.5862	131.4749	34.31726
106.8192	131.7089	34.31656
107.0526	131.9395	34.31588
107.2860	132.1734	34.31504
107.5193	132.4079	34.31437
107.7525	132.6409	34.31347
107.9862	132.8726	34.31270
108.2195	133.1065	34.31187
108.4525	133.3417	34.31111
108.6893	133.5747	34.31025
108.9260	133.8096	34.30944
109.1612	134.0444	34.30862
109.3985	134.2884	34.30772
109.6343	134.5270	34.30711
109.8693	134.7614	34.30619
110.1077	134.9947	34.30538
110.3428	135.2261	34.30449
110.5775	135.4633	34.30372
110.8110	135.6997	34.30286
111.0443	135.9339	34.30219
111.2776	136.1662	34.30130
111.5110	136.3993	34.30056
111.7443	136.6344	34.29961
111.9778	136.8678	34.29878
112.2110	137.1008	34.29814
112.4443	137.3354	34.29730
112.6778	137.5633	34.29656
112.9108	137.7970	34.29578
113.1443	138.0312	34.29497
113.3810	138.2676	34.29410
113.6170	138.5018	34.29318
113.8525	138.7364	34.29231
114.0893	138.9726	34.29139
114.3227	139.2082	34.29053
114.5562	139.4442	34.28975
114.7895	139.6774	34.28898
115.0227	139.9104	34.28805
115.2560	140.1435	34.28730
115.4895	140.3795	34.28635
115.7227	140.6140	34.28557
115.9560	140.8434	34.28479
116.1893	141.0760	34.28388
116.4228	141.3075	34.28294
116.6568	141.5430	34.28228
116.8927	141.7794	34.28122
117.1278	142.0172	34.28042
117.3643	142.2536	34.27948
117.5977	142.4856	34.27861
117.8310	142.7154	34.27766
118.0643	142.9507	34.27683
118.2978	143.1805	34.27588
118.5310	143.4208	34.27510
118.7643	143.6580	34.27422
118.9978	143.8906	34.27331
119.2310	144.1222	34.27246
119.4643	144.3536	34.27159
119.6975	144.5842	34.27067
119.9327	144.8178	34.27003
120.1678	145.0528	34.26910
120.4010	145.2870	34.26824
120.6345	145.5212	34.26722
120.8677	145.7564	34.26633
121.1010	145.9901	34.26543
121.3345	146.2217	34.26447
121.5677	146.4555	34.26356
121.8010	146.6904	34.26258
122.0345	146.9224	34.26170
122.2677	147.1558	34.26059
122.5010	147.3909	34.25977
122.7354	147.6232	34.25882
122.9727	147.8570	34.25796
123.2077	148.0942	34.25700
123.4445	148.3392	34.25614
123.6812	148.5724	34.25508
123.9168	148.8045	34.25433
124.1526	149.0366	34.25325
124.3893	149.2751	34.25238
124.6262	149.5136	34.25152
124.8610	149.7478	34.25050
125.0985	149.9842	34.24939
125.3343	150.2201	34.24857
125.5693	150.4590	34.24750
125.8078	150.6966	34.24652
126.0428	150.9306	34.24553
126.2775	151.1665	34.24450
126.5110	151.3986	34.24358
126.7443	151.6307	34.24254
126.9777	151.8613	34.24148
127.2112	152.0952	34.24042
127.4443	152.3311	34.23940
127.6776	152.5653	34.23842
127.9110	152.7990	34.23740
128.1443	153.0309	34.23641
128.3777	153.2643	34.23530
128.6110	153.4980	34.23434
128.8445	153.7320	34.23329
129.0808	153.9681	34.23213
129.3143	154.1996	34.23109
129.5477	154.4333	34.23008
129.7810	154.6679	34.22898
130.0143	154.9026	34.22806
130.2477	155.1352	34.22694
130.4812	155.3682	34.22576
130.7144	155.6003	34.22467
130.9476	155.8324	34.22361
131.1810	156.0675	34.22269
131.4144	156.2978	34.22157
131.6478	156.5285	34.22042
131.8845	156.7654	34.21924
132.1195	157.0019	34.21808
132.3566	157.2429	34.21696
132.5927	157.4802	34.21578
132.8276	157.7152	34.21455
133.0660	157.9534	34.21334
133.3010	158.1900	34.21231
133.5377	158.4239	34.21110
133.7744	158.6613	34.20989
134.0094	158.8962	34.20864
134.2477	159.1341	34.20735
134.4827	159.3690	34.20607
134.7187	159.6049	34.20502
134.9562	159.8395	34.20380
135.1912	160.0782	34.20268
135.4275	160.3176	34.20132
135.6644	160.5563	34.20034
135.9002	160.7902	34.19912
136.1360	161.0231	34.19775
136.3727	161.2576	34.19636
136.6093	161.4908	34.19514
136.8445	161.7262	34.19376
137.0820	161.9625	34.19247
137.3178	162.1979	34.19112
137.5508	162.4365	34.18978
137.7843	162.6716	34.18848
138.0177	162.9079	34.18717
138.2510	163.1420	34.18578
138.4843	163.3734	34.18439
138.7178	163.6041	34.18307
138.9512	163.8395	34.18181
139.1845	164.0719	34.18039
139.4175	164.3028	34.17900
139.6510	164.5366	34.17750
139.8844	164.7729	34.17620
140.1210	165.0075	34.17474
140.3578	165.2426	34.17334
140.5925	165.4752	34.17219
140.8310	165.7121	34.17063
141.0660	165.9511	34.16912
141.3018	166.1872	34.16754
141.5394	166.4246	34.16600
141.7744	166.6609	34.16446
142.0110	166.8959	34.16296
142.2444	167.1316	34.16152
142.4776	167.3643	34.16000
142.7110	167.5972	34.15836
142.9442	167.8294	34.15690
143.1777	168.0618	34.15533
143.4110	168.2957	34.15364
143.6445	168.5315	34.15215
143.8778	168.7644	34.15046
144.1112	168.9954	34.14899
144.3442	169.2281	34.14732
144.5776	169.4611	34.14559
144.8110	169.6914	34.14374
145.0493	169.9294	34.14196
145.2825	170.1647	34.14032
145.5162	170.3980	34.13872
145.7492	170.6323	34.13678
145.9827	170.8678	34.13504
146.2160	171.1026	34.13330
146.4494	171.3334	34.13134
146.6827	171.5688	34.12943
146.9160	171.8020	34.12760
147.1494	172.0346	34.12567
147.3827	172.2670	34.12367
147.6160	172.5009	34.12170
147.8495	172.7332	34.11969
148.0862	172.9690	34.11766
148.3225	173.2072	34.11558
148.5560	173.4418	34.11346
148.7894	173.6778	34.11130
149.0226	173.9111	34.10905
149.2560	174.1446	34.10687
149.4894	174.3790	34.10468
149.7227	174.6112	34.10233
149.9560	174.8411	34.09972
150.1895	175.0729	34.09729
150.4228	175.3088	34.09473
150.6562	175.5397	34.09208
150.8892	175.7689	34.08939
151.1260	176.0070	34.08655
151.3610	176.2412	34.08366
151.5985	176.4792	34.08074
151.8344	176.7194	34.07774
152.0695	176.9568	34.07471
152.3078	177.1955	34.07136
152.5428	177.4310	34.06798
152.7792	177.6639	34.06436
153.0160	177.8973	34.06071
153.2493	178.1288	34.05689
153.4827	178.3630	34.05292
153.7160	178.5993	34.04893
153.9494	178.8334	34.04463
154.1827	179.0684	34.04019
154.4162	179.2990	34.03562
154.6495	179.5379	34.03072
154.8828	179.7682	34.02556
155.1162	179.9998	34.02020
155.3495	180.2348	34.01472
155.5828	180.4672	34.00893
155.8186	180.7019	34.00278
156.0558	180.9394	33.99628
156.2910	181.1742	33.98964
156.5244	181.4074	33.98300
156.7577	181.6397	33.97575
156.9908	181.8744	33.96836
157.2242	182.1071	33.96074
157.4578	182.3445	33.95278
157.6912	182.5769	33.94464
157.9245	182.8097	33.93612
158.1577	183.0430	33.92742
158.3910	183.2761	33.91826
158.6243	183.5091	33.90885
158.8575	183.7417	33.89905
159.0912	183.9758	33.88916
159.3244	184.2101	33.87884
159.5577	184.4430	33.86848
159.7910	184.6725	33.85759
160.0242	184.9060	33.84652
160.2578	185.1403	33.83521
160.4910	185.3738	33.82366
160.7244	185.6075	33.81188
160.9575	185.8429	33.79982
161.1912	186.0764	33.78752
161.4260	186.3123	33.77510
161.6610	186.5463	33.76224
161.8942	186.7789	33.74924
162.1277	187.0112	33.73597
162.3610	187.2451	33.72244
162.5944	187.4791	33.70886
162.8278	187.7104	33.69524
163.0610	187.9430	33.68119
163.2943	188.1787	33.66700
163.5276	188.4112	33.65242
163.7608	188.6471	33.63811
163.9945	188.8818	33.62324
164.2276	189.1123	33.60818
164.4644	189.3481	33.59268
164.6995	189.5837	33.57751
164.9352	189.8183	33.56206
165.1693	190.0528	33.54650
165.4025	190.2868	33.53084
165.6362	190.5192	33.51502
165.8694	190.7506	33.49910
166.1026	190.9842	33.48313
166.3362	191.2188	33.46680
166.5694	191.4530	33.45048
166.8027	191.6845	33.43408
167.0360	191.9189	33.41757
167.2695	192.1506	33.40098
167.5027	192.3818	33.38422
167.7360	192.6155	33.36734
167.9727	192.8568	33.34990
168.2062	193.0908	33.33290
168.4394	193.3238	33.31598
168.6727	193.5576	33.29878
168.9058	193.7923	33.28146
169.1395	194.0260	33.26394
169.3727	194.2561	33.24640
169.6060	194.4854	33.22866
169.8395	194.7190	33.21079
170.0726	194.9558	33.19324
170.3060	195.1928	33.17544
170.5412	195.4239	33.15738
170.7760	195.6572	33.13940
171.0127	195.8934	33.12094
171.2495	196.1305	33.10261
171.4844	196.3665	33.08418
171.7227	196.6057	33.06535
171.9558	196.8362	33.04710
172.1895	197.0712	33.02873
172.4227	197.3075	33.01042
172.6558	197.5404	32.99175
172.8895	197.7769	32.97323
173.1227	198.0086	32.95450
173.3560	198.2418	32.93608
173.5892	198.4738	32.91726
173.8228	198.7064	32.89866
174.0560	198.9361	32.88011
174.2894	199.1707	32.86133
174.5245	199.4050	32.84231
174.7610	199.6428	32.82354
174.9975	199.8793	32.80391
175.2335	200.1176	32.78510
175.4692	200.3540	32.76611
175.7060	200.5912	32.74636
175.9427	200.8304	32.72746
176.1762	201.0614	32.70859
176.4094	201.2910	32.68963
176.6425	201.5259	32.67052
176.8760	201.7579	32.65167
177.1094	201.9913	32.63258
177.3428	202.2234	32.61356
177.5760	202.4554	32.59461
177.8095	202.6889	32.57545
178.0426	202.9213	32.55656
178.2760	203.1558	32.53750
178.5095	203.3909	32.51858
178.7426	203.6263	32.49971
178.9812	203.8657	32.47998
179.2160	204.0993	32.46090
179.4518	204.3331	32.44188
179.6895	204.5694	32.42200
179.9244	204.8084	32.40304
180.1612	205.0491	32.38411
180.3976	205.2841	32.36430
180.6335	205.5156	32.34530
180.8692	205.7512	32.32625
181.1060	205.9858	32.30662
181.3426	206.2211	32.28762
181.5760	206.4536	32.26853
181.8095	206.6885	32.24972
182.0426	206.9235	32.23090
182.2762	207.1565	32.21202
182.5094	207.3903	32.19329
182.7426	207.6248	32.17438
182.9760	207.8603	32.15574
183.2094	208.0927	32.13696
183.4428	208.3268	32.11844
183.6760	208.5591	32.09984
183.9094	208.7890	32.08122
184.1445	209.0259	32.06270
184.3826	209.2652	32.04371
184.6176	209.5001	32.02537
184.8544	209.7370	32.00670
185.0910	209.9703	31.98823
185.3245	210.2042	31.97008
185.5576	210.4374	31.95182
185.7910	210.6733	31.93377
186.0245	210.9070	31.91584
186.2576	211.1418	31.89803
186.4908	211.3768	31.88014
186.7244	211.6087	31.86250
186.9576	211.8406	31.84494
187.1912	212.0725	31.82739
187.4244	212.3013	31.81000
187.6576	212.5356	31.79290
187.8920	212.7691	31.77582
188.1277	213.0090	31.75879
188.3644	213.2447	31.74117
188.6012	213.4806	31.72433
188.8360	213.7134	31.70765
189.0735	213.9493	31.69047
189.3092	214.1894	31.67424
189.5445	214.4260	31.65790
189.7826	214.6652	31.64124
190.0177	214.8982	31.62528
190.2527	215.1337	31.60948
190.4858	215.3694	31.59383
190.7195	215.6011	31.57846
190.9526	215.8376	31.56326
191.1860	216.0685	31.54822
191.4193	216.3012	31.53335
191.6528	216.5376	31.51859
191.8860	216.7718	31.50403
192.1192	217.0013	31.48940
192.3528	217.2355	31.47539
192.5860	217.4676	31.46150
192.8192	217.7002	31.44776
193.0560	217.9365	31.43374
193.2908	218.1738	31.42060
193.5244	218.4035	31.40745
193.7576	218.6411	31.39459
193.9912	218.8720	31.38200
194.2244	219.1040	31.36963
194.4575	219.3379	31.35746
194.6912	219.5717	31.34558
194.9244	219.8068	31.33399
195.1575	220.0374	31.32254
195.3910	220.2710	31.31139
195.6244	220.5034	31.30029
195.8595	220.7373	31.28956
196.0944	220.9722	31.27910
196.3316	221.2063	31.26850
196.5677	221.4476	31.25844
196.8025	221.6870	31.24878
197.0412	221.9256	31.23894
197.2760	222.1587	31.22950
197.5095	222.3916	31.22050
197.7426	222.6257	31.21159
197.9760	222.8576	31.20300
198.2092	223.0908	31.19466
198.4427	223.3232	31.18654
198.6760	223.5530	31.17863
198.9094	223.7851	31.17088
199.1425	224.0198	31.16334
199.3762	224.2553	31.15600
199.6094	224.4902	31.14905
199.8426	224.7253	31.14214
200.0760	224.9582	31.13566
200.3095	225.1917	31.12928
200.5426	225.4250	31.12290
200.7760	225.6585	31.11700
201.0094	225.8904	31.11120
201.2428	226.1237	31.10551
201.4760	226.3568	31.09990
201.7094	226.5898	31.09472
201.9427	226.8224	31.08972
202.1758	227.0584	31.08468
202.4103	227.2916	31.07986
202.6478	227.5296	31.07498
202.8826	227.7666	31.07046
203.1194	228.0035	31.06609
203.3560	228.2386	31.06173
203.5920	228.4744	31.05785
203.8278	228.7097	31.05390
204.0645	228.9457	31.04991
204.3010	229.1814	31.04624
204.5360	229.4162	31.04280
204.7735	229.6538	31.03926
205.0094	229.8895	31.03580
205.2444	230.1242	31.03260
205.4825	230.3628	31.02941
205.7160	230.5958	31.02650
205.9493	230.8320	31.02356
206.1825	231.0627	31.02062
206.4162	231.2968	31.01805
206.6495	231.5310	31.01548
206.8828	231.7646	31.01286
207.1160	231.9973	31.01042
207.3494	232.2282	31.00808
207.5826	232.4621	31.00588
207.8160	232.6966	31.00368
208.0494	232.9316	31.00155
208.2826	233.1646	30.99937
208.5177	233.3997	30.99729
208.7510	233.6328	30.99536
208.9844	233.8647	30.99354
209.2178	234.0977	30.99180
209.4510	234.3302	30.99002
209.6844	234.5629	30.98826
209.9178	234.7966	30.98666
210.1508	235.0292	30.98518
210.3844	235.2625	30.98342
210.6176	235.4964	30.98209
210.8512	235.7290	30.98071
211.0842	235.9610	30.97916
211.3194	236.1969	30.97792
211.5527	236.4323	30.97646
211.7860	236.6660	30.97506
212.0195	236.8994	30.97380
212.2528	237.1331	30.97258
212.4862	237.3675	30.97137
212.7194	237.6000	30.97028
212.9526	237.8318	30.96919
213.1860	238.0650	30.96814
213.4194	238.2998	30.96704
213.6526	238.5348	30.96594
213.8862	238.7667	30.96482
214.1194	238.9992	30.96387
214.3526	239.2342	30.96282
214.5862	239.4652	30.96190
214.8194	239.6972	30.96077
215.0527	239.9311	30.95990
215.2860	240.1640	30.95893
215.5192	240.3973	30.95796
215.7526	240.6321	30.95721
215.9862	240.8663	30.95638
216.2194	241.1013	30.95561
216.4526	241.3335	30.95485
216.6862	241.5670	30.95418
216.9235	241.8034	30.95332
217.1594	242.0423	30.95269
217.3944	242.2764	30.95180
217.6328	242.5150	30.95113
217.8676	242.7480	30.95043
218.1045	242.9855	30.94970
218.3394	243.2201	30.94911
218.5728	243.4502	30.94846
218.8060	243.6825	30.94779
219.0392	243.9174	30.94709
219.2726	244.1492	30.94645
219.5058	244.3853	30.94590
219.7394	244.6194	30.94522
219.9725	244.8523	30.94468
220.2060	245.0841	30.94395
220.4392	245.3174	30.94336
220.6726	245.5541	30.94280
220.9078	245.7881	30.94228
221.1435	246.0252	30.94170
221.3810	246.2642	30.94110
221.6158	246.4981	30.94068
221.8494	246.7319	30.94016
222.0826	246.9637	30.93966
222.3158	247.1948	30.93906
222.5494	247.4262	30.93871
222.7828	247.6588	30.93811
223.0160	247.8933	30.93774
223.2493	248.1290	30.93717
223.4826	248.3648	30.93671
223.7158	248.6001	30.93635
223.9493	248.8328	30.93574
224.1835	249.0669	30.93538
224.4195	249.3050	30.93494
224.6558	249.5416	30.93461
224.8894	249.7736	30.93418
225.1226	250.0060	30.93367
225.3562	250.2393	30.93319
225.5892	250.4705	30.93269
225.8226	250.7010	30.93228
226.0560	250.9324	30.93174
226.2895	251.1675	30.93128
226.5226	251.4024	30.93096
226.7560	251.6360	30.93052
226.9894	251.8714	30.93016
227.2235	252.1062	30.92967
227.4595	252.3420	30.92934
227.6945	252.5758	30.92888
227.9325	252.8142	30.92874
228.1675	253.0472	30.92825
228.4045	253.2856	30.92795
228.6412	253.5236	30.92752
228.8758	253.7568	30.92718
229.1144	253.9951	30.92680
229.3494	254.2281	30.92650
229.5844	254.4605	30.92610
229.8177	254.6958	30.92590
230.0510	254.9318	30.92551
230.2844	255.1668	30.92525
230.5178	255.4009	30.92490
230.7512	255.6331	30.92438
230.9845	255.8644	30.92407
231.2178	256.0983	30.92379
231.4512	256.3310	30.92337
231.6845	256.5655	30.92312
231.9178	256.7977	30.92264
232.1528	257.0318	30.92230
232.3895	257.2702	30.92203
232.6250	257.5058	30.92168
232.8612	257.7408	30.92148
233.0978	257.9759	30.92100
233.3342	258.2136	30.92086
233.5694	258.4473	30.92044
233.8068	258.6858	30.92002
234.0425	258.9238	30.91980
234.2778	259.1602	30.91959
234.5160	259.3984	30.91922
234.7512	259.6321	30.91906
234.9878	259.8682	30.91866
235.2245	260.1035	30.91841
235.4594	260.3399	30.91810
235.6976	260.5806	30.91766
235.9326	260.8153	30.91742
236.1685	261.0503	30.91722
236.4060	261.2865	30.91691
236.6408	261.5204	30.91654
236.8778	261.7566	30.91648
237.1145	261.9940	30.91608
237.3503	262.2280	30.91565
237.5860	262.4666	30.91541
237.8226	262.7031	30.91496
238.0594	262.9396	30.91458
238.2945	263.1750	30.91433
238.5318	263.4124	30.91426
238.7675	263.6487	30.91388
239.0026	263.8836	30.91373
239.2410	264.1227	30.91346
239.4745	264.3552	30.91304
239.7076	264.5877	30.91292
239.9410	264.8200	30.91254
240.1745	265.0559	30.91229
240.4076	265.2891	30.91211
240.6410	265.5215	30.91185
240.8745	265.7544	30.91166
241.1076	265.9886	30.91144
241.3410	266.2212	30.91125
241.5742	266.4547	30.91076
241.8078	266.6872	30.91054
242.0427	266.9234	30.91038
242.2810	267.1618	30.90996
242.5158	267.3964	30.90982
242.7520	267.6335	30.90950
242.9894	267.8692	30.90925
243.2244	268.1056	30.90913
243.4578	268.3378	30.90865
243.6910	268.5706	30.90835
243.9244	268.8046	30.90814
244.1576	269.0388	30.90785
244.3908	269.2702	30.90755
244.6245	269.5032	30.90747
244.8578	269.7346	30.90728
245.0912	269.9680	30.90702
245.3243	270.2028	30.90675
245.5576	270.4376	30.90650
245.7918	270.6715	30.90633
246.0276	270.9041	30.90605
246.2644	271.1423	30.90579
246.5010	271.3796	30.90558
246.7344	271.6139	30.90532
246.9677	271.8468	30.90523
247.2010	272.0818	30.90501
247.4344	272.3138	30.90472
247.6677	272.5480	30.90445
247.9010	272.7806	30.90432
248.1344	273.0122	30.90402
248.3676	273.2464	30.90390
248.6010	273.4801	30.90369
248.8344	273.7136	30.90348
249.0677	273.9490	30.90324
249.3027	274.1832	30.90304
249.5408	274.4214	30.90300
249.7745	274.6533	30.90248
250.0075	274.8876	30.90235
250.2408	275.1218	30.90194
250.4742	275.3573	30.90166
250.7075	275.5892	30.90154
250.9412	275.8268	30.90135
251.1744	276.0564	30.90115
251.4076	276.2894	30.90100
251.6410	276.5208	30.90050
251.8742	276.7552	30.90051
252.1078	276.9904	30.90027
252.3410	277.2236	30.90018
252.5776	277.4584	30.89992
252.8144	277.6926	30.89966
253.0494	277.9280	30.89946
253.2826	278.1636	30.89931
253.5158	278.3965	30.89916
253.7495	278.6279	30.89890
253.9828	278.8632	30.89884
254.2162	279.0955	30.89865
254.4493	279.3290	30.89841
254.6826	279.5644	30.89829
254.9160	279.7959	30.89804
255.1494	280.0302	30.89789
255.3828	280.2630	30.89757
255.6178	280.4960	30.89741
255.8528	280.7308	30.89726
256.0903	280.9668	30.89700
256.3262	281.2018	30.89682
256.5612	281.4384	30.89657
256.7995	281.6794	30.89637
257.0345	281.9154	30.89624
257.2710	282.1515	30.89605
257.5078	282.3879	30.89594
257.7428	282.6227	30.89575
257.9810	282.8638	30.89551
258.2160	283.0986	30.89539
258.4520	283.3320	30.89518
258.6895	283.5670	30.89487
258.9245	283.8032	30.89458
259.1608	284.0390	30.89441
259.3975	284.2774	30.89411
259.6333	284.5167	30.89395
259.8695	284.7535	30.89382
260.1060	284.9884	30.89354
260.3426	285.2249	30.89343
260.5776	285.4586	30.89328
260.8152	285.6950	30.89312
261.0512	285.9320	30.89290
261.2860	286.1690	30.89276
261.5243	286.4059	30.89256
261.7594	286.6422	30.89240
261.9960	286.8773	30.89215
262.2326	287.1150	30.89211
262.4676	287.3486	30.89191
262.7060	287.5855	30.89156
262.9410	287.8202	30.89146
263.1768	288.0563	30.89130
263.4144	288.2949	30.89101
263.6493	288.5280	30.89094
263.8860	288.7660	30.89060
264.1227	289.0030	30.89035
264.3585	289.2389	30.89016
264.5944	289.4738	30.89005
264.8310	289.7100	30.88988
265.0676	289.9481	30.88958
265.3027	290.1829	30.88952
265.5402	290.4197	30.88944
265.7760	290.6558	30.88919
266.0110	290.8894	30.88894
266.2445	291.1232	30.88882
266.4778	291.3565	30.88876
266.7110	291.5900	30.88844
266.9444	291.8235	30.88814
267.1777	292.0590	30.88816
267.4112	292.2948	30.88805
267.6444	292.5284	30.88789
267.8776	292.7602	30.88766
268.1108	292.9939	30.88740
268.3445	293.2248	30.88711
268.5776	293.4586	30.88700
268.8142	293.6944	30.88690
269.0494	293.9312	30.88657
269.2860	294.1682	30.88649
269.5225	294.4040	30.88620
269.7585	294.6411	30.88622
269.9944	294.8726	30.88596
270.2310	295.1090	30.88575
270.4658	295.3441	30.88538
270.6995	295.5780	30.88548
270.9326	295.8100	30.88522
271.1660	296.0453	30.88498
271.3993	296.2803	30.88480
271.6328	296.5117	30.88467
271.8660	296.7463	30.88440
272.0994	296.9802	30.88440
272.3326	297.2124	30.88412
272.5662	297.4477	30.88375
272.7994	297.6828	30.88378
273.0326	297.9137	30.88339
273.2678	298.1502	30.88320
273.5060	298.3875	30.88291
273.7410	298.6214	30.88274
273.9770	298.8551	30.88257
274.2144	299.0923	30.88239
274.4476	299.3276	30.88220
274.6812	299.5622	30.88210
274.9145	299.7938	30.88194
275.1477	300.0266	30.88164
275.3810	300.2620	30.88144
275.6143	300.4946	30.88105
275.8476	300.7280	30.88094
276.0810	300.9604	30.88072
276.3144	301.1943	30.88073
276.5476	301.4262	30.88038
276.7810	301.6597	30.88021
277.0168	301.8947	30.87990
277.2526	302.1330	30.87976
277.4893	302.3716	30.87963
277.7260	302.6091	30.87938
277.9610	302.8433	30.87928
278.1985	303.0798	30.87908
278.4345	303.3163	30.87888
278.6694	303.5523	30.87864
278.9076	303.7892	30.87844
279.1425	304.0237	30.87815
279.3762	304.2566	30.87789
279.6094	304.4908	30.87778
279.8426	304.7238	30.87759
280.0760	304.9579	30.87734
280.3094	305.1914	30.87709
280.5425	305.4238	30.87680
280.7762	305.6576	30.87660
281.0094	305.8915	30.87645
281.2427	306.1243	30.87611
281.4760	306.3578	30.87596
281.7092	306.5907	30.87585
281.9428	306.8242	30.87559
282.1760	307.0575	30.87544
282.4092	307.2900	30.87505
282.6427	307.5226	30.87482
282.8760	307.7574	30.87456
283.1094	307.9898	30.87433
283.3425	308.2226	30.87419
283.5760	308.4558	30.87396
283.8094	308.6918	30.87364
284.0428	308.9240	30.87334
284.2760	309.1567	30.87300
284.5110	309.3908	30.87285
284.7477	309.6292	30.87257
284.9845	309.8659	30.87235
285.2195	310.0999	30.87217
285.4568	310.3390	30.87201
285.6926	310.5744	30.87163
285.9258	310.8088	30.87144
286.1595	311.0415	30.87108
286.3928	311.2722	30.87088
286.6258	311.5032	30.87060
286.8595	311.7383	30.87040
287.0926	311.9715	30.87028
287.3260	312.2060	30.86986
287.5594	312.4369	30.86960
287.7927	312.6712	30.86922
288.0262	312.9055	30.86912
288.2594	313.1416	30.86883
288.4960	313.3780	30.86862
288.7326	313.6136	30.86828
288.9676	313.8478	30.86813
289.2026	314.0828	30.86792
289.4358	314.3184	30.86765
289.6695	314.5530	30.86742
289.9027	314.7853	30.86694
290.1360	315.0177	30.86663
290.3694	315.2534	30.86629
290.6025	315.4848	30.86616
290.8362	315.7159	30.86586
291.0695	315.9508	30.86558
291.3028	316.1902	30.86534
291.5360	316.4178	30.86512
291.7694	316.6500	30.86474
292.0060	316.8851	30.86432
292.2425	317.1210	30.86407
292.4778	317.3559	30.86390
292.7152	317.5928	30.86362
292.9510	317.8309	30.86318
293.1860	318.0672	30.86298
293.4244	318.3050	30.86252
293.6594	318.5396	30.86221
293.8960	318.7724	30.86178
294.1328	319.0122	30.86146
294.3678	319.2498	30.86135
294.6062	319.4881	30.86100
294.8412	319.7243	30.86080
295.0770	319.9588	30.86049
295.3144	320.1944	30.86006
295.5494	320.4299	30.85982
295.7860	320.6691	30.85962
296.0227	320.9061	30.85928
296.2587	321.1421	30.85904
296.4944	321.3794	30.85869
296.7310	321.6156	30.85852
296.9676	321.8527	30.85822
297.2025	322.0846	30.85783
297.4362	322.3172	30.85744
297.6695	322.5480	30.85710
297.9028	322.7814	30.85679
298.1360	323.0159	30.85650
298.3694	323.2521	30.85615
298.6028	323.4857	30.85588
298.8360	323.7187	30.85560
299.0694	323.9487	30.85522
299.3027	324.1826	30.85496
299.5360	324.4170	30.85459
299.7694	324.6509	30.85416
300.0060	324.8879	30.85395
300.2410	325.1232	30.85352
300.4766	325.3580	30.85324
300.7142	325.5954	30.85290
300.9495	325.8310	30.85274
301.1862	326.0674	30.85237
301.4228	326.3038	30.85201
301.6587	326.5396	30.85160
301.8944	326.7762	30.85112
302.1310	327.0146	30.85070
302.3660	327.2522	30.85043
302.5995	327.4852	30.85014
302.8328	327.7168	30.84967
303.0660	327.9506	30.84937
303.2994	328.1819	30.84885
303.5326	328.4168	30.84863
303.7658	328.6496	30.84815
303.9995	328.8817	30.84785
304.2326	329.1146	30.84749
304.4660	329.3478	30.84718
304.6994	329.5813	30.84670
304.9344	329.8166	30.84635
305.1694	330.0522	30.84602
305.4078	330.2900	30.84573
305.6427	330.5241	30.84536
305.8794	330.7614	30.84509
306.1160	330.9972	30.84463
306.3510	331.2318	30.84428
306.5845	331.4662	30.84406
306.8176	331.6984	30.84362
307.0510	331.9328	30.84336
307.2844	332.1650	30.84298
307.5178	332.3984	30.84258
307.7512	332.6320	30.84208
307.9844	332.8675	30.84181
308.2176	333.1006	30.84160
308.4512	333.3334	30.84106
308.6845	333.5654	30.84078
308.9185	333.7980	30.84038
309.1560	334.0348	30.83996
309.3908	334.2711	30.83968
309.6276	334.5086	30.83914
309.8643	334.7456	30.83888
310.0994	334.9798	30.83860
310.3326	335.2107	30.83820
310.5660	335.4444	30.83780
310.7992	335.6778	30.83738
311.0328	335.9156	30.83716
311.2660	336.1475	30.83689
311.4993	336.3832	30.83644
311.7326	336.6176	30.83604
311.9662	336.8492	30.83560
312.1994	337.0801	30.83516
312.4326	337.3141	30.83492
312.6678	337.5506	30.83450
312.9027	337.7830	30.83422
313.1402	338.0219	30.83382
313.3760	338.2590	30.83352
313.6095	338.4916	30.83318
313.8426	338.7252	30.83277
314.0760	338.9573	30.83240
314.3095	339.1917	30.83218
314.5427	339.4239	30.83180
314.7758	339.6578	30.83138
315.0095	339.8916	30.83116
315.2427	340.1257	30.83075
315.4760	340.3588	30.83040
315.7095	340.5928	30.83018
315.9426	340.8265	30.82988
316.1777	341.0609	30.82943
316.4112	341.2924	30.82909
316.6444	341.5244	30.82878
316.8776	341.7576	30.82840
317.1110	341.9925	30.82818
317.3444	342.2257	30.82771
317.5775	342.4588	30.82746
317.8110	342.6924	30.82722
318.0444	342.9273	30.82672
318.2778	343.1621	30.82640
318.5110	343.3928	30.82596
318.7444	343.6272	30.82564
318.9812	343.8656	30.82537
319.2168	344.1016	30.82504
319.4512	344.3362	30.82472
319.6844	344.5686	30.82441
319.9178	344.8012	30.82415
320.1510	345.0352	30.82365
320.3845	345.2674	30.82344
320.6177	345.4984	30.82302
320.8510	345.7314	30.82264
321.0845	345.9668	30.82238
321.3176	346.1992	30.82194
321.5510	346.4302	30.82158
321.7842	346.6649	30.82122
322.0195	346.9019	30.82092
322.2568	347.1391	30.82054
322.4925	347.3753	30.82013
322.7276	347.6091	30.81972
322.9660	347.8505	30.81956
323.2010	348.0856	30.81920
323.4345	348.3178	30.81894
323.6677	348.5505	30.81859
323.9010	348.7842	30.81831
324.1344	349.0176	30.81792
324.3677	349.2521	30.81771
324.6008	349.4850	30.81728
324.8345	349.7186	30.81709
324.9676	349.8505	30.81680