File: TGA/2023_07_17_CBN_powder_1cpm.txt
CLOSED
Version	0.4
Run	877
Instrument	2950 TGA       V5.4A
Module	TGA 1000 øC
Sample	2023_07_17_CBN_powder_1cpm
Size	5.94700	mg
Method	25C to 350C at 1 cpm
Operator	SBK
Comment	2023_07_17_CBN_powder_1cpm
Xcomment	Pan: Platinum           Gas1: Nitrogen  40          Gas2: Nitrogen  40
Text	2023_07_17_CBN_powder_1cpm
Text	Crystalline CBN powder
Kcell	1.00000
TempCal	2	pts	156.68	152.50,	376.53	354.00
Thresholds	0.050	0.0000
Controls	Gas 1  Event Off  Sampling 2.0 sec/pt
Nsig	3
Sig1	Time (min)
Sig2	Temperature (øC)
Sig3	Weight (mg)
Date	17-Jul-23
Time	10:37
File	C:\TA\Data\TGA\Skyler\2023_07_17_CBN_powder_1cpm.001
OrgFile	C:\TA\Data\TGA\Skyler\2023_07_17_CBN_powder_1cpm.001
StartOfData
0.0000000	25.12236	5.943640
0.1660000	25.21216	5.943648
0.3326666	25.34502	5.943796
0.4993334	25.48665	5.943742
0.6660000	25.64346	5.942938
0.8326668	25.80020	5.942882
0.9993332	25.96604	5.942707
1.166000	26.13308	5.942672
1.332500	26.29610	5.942469
1.501167	26.46345	5.942334
1.669500	26.62890	5.942299
1.839334	26.79889	5.942211
2.007666	26.96481	5.942135
2.176000	27.13750	5.942078
2.344334	27.30646	5.941972
2.514333	27.47680	5.941812
2.682666	27.64372	5.941765
2.851000	27.81090	5.941680
3.019333	27.97914	5.941580
3.189334	28.14974	5.941468
3.357500	28.31988	5.941399
3.526166	28.48710	5.941264
3.694500	28.65484	5.941130
3.864334	28.82776	5.940952
4.032666	28.99221	5.940862
4.201000	29.16368	5.941040
4.369333	29.33333	5.940916
4.539500	29.49922	5.940805
4.707833	29.66545	5.940579
4.876167	29.83510	5.940548
5.044334	30.00185	5.940453
5.214334	30.17486	5.940382
5.381000	30.33866	5.940293
5.547666	30.50766	5.940190
5.714334	30.67589	5.940202
5.881000	30.84275	5.940142
6.047832	31.00827	5.940069
6.214500	31.17322	5.939986
6.381166	31.34055	5.939934
6.547668	31.51067	5.939910
6.714334	31.67219	5.939789
6.881000	31.84160	5.939724
7.047668	32.00841	5.939712
7.214166	32.17454	5.939639
7.381166	32.33740	5.939482
7.547832	32.50821	5.939413
7.714500	32.67695	5.939292
7.882500	32.84703	5.939137
8.051166	33.01511	5.939052
8.219500	33.17854	5.939055
8.389500	33.34950	5.938962
8.557500	33.51728	5.938940
8.725832	33.67310	5.938824
8.894166	33.84850	5.938848
9.060832	34.01766	5.938692
9.227500	34.18920	5.938542
9.394332	34.35850	5.938480
9.561000	34.52611	5.938502
9.727668	34.69146	5.938477
9.894332	34.85055	5.938486
10.06100	35.00782	5.938432
10.22767	35.17510	5.938309
10.39433	35.34565	5.938206
10.56100	35.51572	5.938136
10.72767	35.68167	5.938050
10.89434	35.85330	5.938183
11.06100	36.01351	5.937991
11.22783	36.17501	5.937900
11.39450	36.34459	5.937996
11.56117	36.51162	5.937958
11.73100	36.68502	5.937890
11.89934	36.85368	5.937821
12.06766	37.02168	5.937818
12.23617	37.19232	5.937744
12.40617	37.36189	5.937661
12.57450	37.52950	5.937578
12.74283	37.70074	5.937554
12.91117	37.86715	5.937455
13.08084	38.03613	5.937348
13.24934	38.20259	5.937353
13.41766	38.36604	5.937326
13.58617	38.53550	5.937234
13.75600	38.70550	5.937229
13.92434	38.87564	5.937316
14.09266	39.04672	5.937149
14.26100	39.21637	5.937130
14.43100	39.38259	5.937041
14.59934	39.54900	5.937063
14.76766	39.71477	5.936940
14.93617	39.87863	5.936920
15.10617	40.04968	5.936798
15.27450	40.21991	5.936791
15.44283	40.38975	5.936740
15.61084	40.55580	5.936672
15.78100	40.72409	5.936668
15.94934	40.89150	5.936570
16.11766	41.06270	5.936563
16.28600	41.23066	5.936435
16.45617	41.40076	5.936445
16.62450	41.57076	5.936428
16.79284	41.74290	5.936335
16.96100	41.91248	5.936310
17.13100	42.08032	5.936191
17.29934	42.25067	5.936120
17.46766	42.41956	5.936104
17.63600	42.58646	5.936024
17.80600	42.75608	5.936024
17.97434	42.91750	5.935940
18.14266	43.07696	5.935974
18.31100	43.24789	5.935846
18.48100	43.41713	5.935955
18.64950	43.58738	5.935932
18.81784	43.75894	5.935855
18.98584	43.92926	5.935807
19.15266	44.09326	5.935816
19.31934	44.25680	5.935637
19.48600	44.42354	5.935560
19.65266	44.59322	5.935589
19.81934	44.75736	5.935550
19.98600	44.92618	5.935425
20.15284	45.08994	5.935446
20.31934	45.25379	5.935367
20.48600	45.42031	5.935413
20.65266	45.58770	5.935351
20.81950	45.75744	5.935392
20.98584	45.92064	5.935305
21.15266	46.08623	5.935188
21.31934	46.25410	5.935320
21.48617	46.42028	5.935215
21.65266	46.58618	5.935093
21.82100	46.75752	5.935082
21.99016	46.92868	5.935046
22.15867	47.09422	5.934922
22.32684	47.26060	5.934856
22.49600	47.42858	5.934988
22.66533	47.59672	5.934954
22.83250	47.76450	5.935038
22.99933	47.92945	5.934802
23.16600	48.10544	5.934922
23.33266	48.27468	5.934891
23.49933	48.44087	5.934805
23.66617	48.60770	5.934805
23.83250	48.77338	5.934617
23.99933	48.94138	5.934539
24.16600	49.10822	5.934579
24.33266	49.27507	5.934473
24.49933	49.43958	5.934420
24.66617	49.60680	5.934372
24.83284	49.77564	5.934519
24.99950	49.94440	5.934340
25.16583	50.11006	5.934309
25.33250	50.27574	5.934318
25.49933	50.44328	5.934224
25.66600	50.60316	5.934197
25.83266	50.77024	5.934230
25.99933	50.93705	5.934168
26.16616	51.10538	5.934151
26.33284	51.26968	5.934118
26.49933	51.43597	5.934070
26.66600	51.60676	5.934040
26.83266	51.77700	5.934088
26.99933	51.94188	5.934088
27.16616	52.11231	5.933988
27.33284	52.27667	5.933774
27.49917	52.44260	5.933850
27.66600	52.60702	5.933728
27.83266	52.77328	5.933752
27.99933	52.93699	5.933816
28.16600	53.10318	5.933752
28.33450	53.27143	5.933738
28.50283	53.44253	5.933664
28.67266	53.61094	5.933601
28.84100	53.78082	5.933525
29.00933	53.94487	5.933412
29.17750	54.11928	5.933403
29.34766	54.29518	5.933356
29.51600	54.46368	5.933271
29.68433	54.63202	5.933240
29.85100	54.79925	5.933164
30.01784	54.96472	5.933270
30.18433	55.12906	5.933212
30.35100	55.29580	5.933188
30.51766	55.46108	5.933086
30.68417	55.62760	5.933145
30.85117	55.79474	5.932962
31.01766	55.96394	5.933032
31.18433	56.13109	5.932982
31.35117	56.29771	5.932879
31.51784	56.46809	5.932832
31.68433	56.63464	5.932744
31.85100	56.80045	5.932898
32.01750	56.96620	5.932748
32.18450	57.13052	5.932700
32.35266	57.29421	5.932666
32.52267	57.46334	5.932608
32.68934	57.63086	5.932537
32.85600	57.79430	5.932602
33.02250	57.95900	5.932568
33.18950	58.12086	5.932470
33.35617	58.28960	5.932438
33.52267	58.46100	5.932473
33.68933	58.63032	5.932578
33.85600	58.79150	5.932560
34.02250	58.95644	5.932488
34.18950	59.12618	5.932450
34.35600	59.29370	5.932385
34.52267	59.45852	5.932319
34.68933	59.62486	5.932288
34.85600	59.79710	5.932238
35.02267	59.96350	5.932216
35.19100	60.13357	5.932282
35.35766	60.30213	5.932161
35.52417	60.47110	5.932152
35.69116	60.64304	5.932192
35.85784	60.81314	5.932076
36.02450	60.97554	5.931944
36.19116	61.13978	5.932148
36.35766	61.30702	5.932070
36.52434	61.46802	5.932070
36.69100	61.63367	5.932100
36.85784	61.79896	5.932100
37.02450	61.96734	5.931959
37.19116	62.14282	5.931914
37.35750	62.31196	5.931934
37.52434	62.47937	5.931921
37.69100	62.64145	5.931863
37.85784	62.80557	5.931728
38.02500	62.97230	5.931719
38.19350	63.14041	5.931635
38.36267	63.31182	5.931610
38.53200	63.47808	5.931576
38.70016	63.64870	5.931444
38.86850	63.82036	5.931506
39.03784	63.98890	5.931552
39.20683	64.15935	5.931513
39.37517	64.32373	5.931593
39.54367	64.49158	5.931450
39.71266	64.65832	5.931562
39.88183	64.82626	5.931446
40.05017	64.99340	5.931284
40.21866	65.16224	5.931339
40.38766	65.33324	5.931343
40.55684	65.50361	5.931116
40.72534	65.67270	5.931126
40.89366	65.84238	5.931106
41.06266	66.01368	5.931051
41.23184	66.18305	5.931072
41.40033	66.35112	5.931074
41.56850	66.51243	5.931106
41.73784	66.67622	5.931066
41.90683	66.84109	5.930935
42.07533	67.00736	5.930922
42.24267	67.17618	5.930985
42.40933	67.34576	5.931000
42.57617	67.51366	5.930862
42.74267	67.68280	5.930761
42.90933	67.85834	5.930759
43.07600	68.03238	5.930768
43.24283	68.20400	5.930781
43.40933	68.37403	5.930774
43.57617	68.53843	5.930778
43.74267	68.70154	5.930760
43.90950	68.86161	5.930789
44.07600	69.02628	5.930709
44.24267	69.18692	5.930679
44.40917	69.35026	5.930676
44.57600	69.51319	5.930620
44.74283	69.68294	5.930761
44.90933	69.85474	5.930874
45.07617	70.02047	5.930856
45.24267	70.18756	5.930708
45.40933	70.35497	5.930581
45.57617	70.52413	5.930559
45.74250	70.69007	5.930558
45.90933	70.85986	5.930551
46.07600	71.03128	5.930400
46.24283	71.19844	5.930430
46.40917	71.36353	5.930414
46.57600	71.52659	5.930300
46.74267	71.69272	5.930376
46.90933	71.85961	5.930350
47.07617	72.02378	5.930300
47.24283	72.19074	5.930191
47.40933	72.35699	5.930006
47.57600	72.52253	5.929949
47.74267	72.69038	5.929906
47.90950	72.85712	5.929885
48.07600	73.02247	5.929798
48.24267	73.19122	5.929730
48.40933	73.35749	5.929586
48.57600	73.52187	5.929581
48.74283	73.69081	5.929527
48.90933	73.85356	5.929529
49.07600	74.01812	5.929394
49.24283	74.18626	5.929352
49.40933	74.35308	5.929234
49.57600	74.52069	5.929008
49.74267	74.68997	5.929020
49.91117	74.85828	5.928957
50.08100	75.02901	5.928692
50.24933	75.19756	5.928623
50.41766	75.36656	5.928428
50.58617	75.53480	5.928284
50.75583	75.70394	5.928100
50.92433	75.87106	5.928032
51.09266	76.03716	5.927950
51.26116	76.20505	5.927788
51.42766	76.37092	5.927801
51.59434	76.53637	5.927630
51.76100	76.69986	5.927535
51.92766	76.86643	5.927541
52.09434	77.03684	5.927385
52.26100	77.20610	5.927236
52.42750	77.37488	5.927332
52.59416	77.54071	5.927264
52.76100	77.70520	5.927211
52.92766	77.87161	5.927047
53.09434	78.03990	5.927150
53.26100	78.20482	5.927184
53.42750	78.37166	5.927106
53.59416	78.54031	5.926928
53.76084	78.70810	5.926874
53.92766	78.87511	5.926844
54.09434	79.03862	5.926781
54.26100	79.20235	5.926742
54.42766	79.36653	5.926636
54.59434	79.53345	5.926722
54.76084	79.70130	5.926682
54.92750	79.86716	5.926605
55.09450	80.03455	5.926552
55.26116	80.20145	5.926528
55.42766	80.36882	5.926528
55.59434	80.53534	5.926504
55.76100	80.70438	5.926422
55.92766	80.87026	5.926479
56.09450	81.03599	5.926522
56.26116	81.20274	5.926380
56.42766	81.37222	5.926494
56.59434	81.53969	5.926632
56.76100	81.70398	5.926445
56.92783	81.86958	5.926609
57.09434	82.03531	5.926518
57.26100	82.20196	5.926468
57.42750	82.37055	5.926630
57.59450	82.53606	5.926568
57.76116	82.70200	5.926524
57.92766	82.86724	5.926452
58.09434	83.03402	5.926582
58.26100	83.20064	5.926456
58.42766	83.36701	5.926625
58.59416	83.53394	5.926474
58.76116	83.70144	5.926526
58.92766	83.86903	5.926500
59.09434	84.03838	5.926399
59.26100	84.20352	5.926371
59.42750	84.36774	5.926318
59.59783	84.53876	5.926260
59.76600	84.70769	5.926242
59.93433	84.87544	5.926120
60.10250	85.04369	5.926189
60.27283	85.21340	5.926136
60.44100	85.38001	5.926063
60.60933	85.54851	5.926024
60.77766	85.70829	5.926033
60.94766	85.87342	5.926120
61.11600	86.04819	5.926112
61.28433	86.22148	5.925851
61.45117	86.39118	5.926171
61.61783	86.56424	5.926198
61.78450	86.73078	5.926154
61.95100	86.89765	5.926078
62.11768	87.06424	5.926088
62.28418	87.23285	5.926020
62.45117	87.39965	5.925943
62.61768	87.56466	5.926049
62.78433	87.73170	5.925876
62.95100	87.89469	5.925808
63.11768	88.05891	5.925871
63.28450	88.22486	5.925808
63.45100	88.39095	5.925776
63.61768	88.56106	5.925828
63.78433	88.72931	5.925787
63.95100	88.89680	5.925590
64.11768	89.06426	5.925725
64.28450	89.22736	5.925581
64.45117	89.39118	5.925507
64.61768	89.55725	5.925480
64.78433	89.72259	5.925354
64.95100	89.88881	5.925393
65.11768	90.05769	5.925386
65.28433	90.22359	5.925246
65.45100	90.39043	5.925351
65.61768	90.56157	5.925337
65.78432	90.72839	5.925380
65.95100	90.89451	5.925466
66.11750	91.06093	5.925389
66.28418	91.22766	5.925408
66.45250	91.39871	5.925373
66.62282	91.56741	5.925428
66.79116	91.73066	5.925220
66.95950	91.89861	5.925426
67.12768	92.06796	5.925437
67.29766	92.23725	5.925310
67.46600	92.40585	5.925364
67.63432	92.57805	5.925266
67.80266	92.74859	5.925061
67.97266	92.91970	5.925118
68.14100	93.08905	5.925018
68.30950	93.25369	5.924900
68.47784	93.41882	5.924880
68.64434	93.58306	5.924911
68.81100	93.74887	5.924871
68.97750	93.91320	5.924966
69.14450	94.08147	5.924888
69.31116	94.24742	5.924832
69.47766	94.41634	5.924840
69.64434	94.58505	5.924675
69.81116	94.75278	5.924695
69.97784	94.91574	5.924652
70.14434	95.08515	5.924678
70.31100	95.25472	5.924543
70.47766	95.42018	5.924526
70.64434	95.58585	5.924536
70.81116	95.75566	5.924421
70.97784	95.92314	5.924420
71.14450	96.09251	5.924454
71.31450	96.26075	5.924348
71.48284	96.42799	5.924294
71.64918	96.59336	5.924324
71.81582	96.75788	5.924275
71.98266	96.92401	5.924256
72.14932	97.08949	5.924226
72.31600	97.25571	5.924234
72.48266	97.42247	5.924060
72.64950	97.58881	5.924230
72.81582	97.75662	5.924066
72.98266	97.92428	5.924096
73.14932	98.09072	5.923951
73.31600	98.25922	5.924040
73.48284	98.42624	5.923962
73.64918	98.59166	5.923926
73.81600	98.75912	5.923872
73.98266	98.92642	5.923666
74.14932	99.09230	5.923732
74.31684	99.25976	5.923642
74.48516	99.42837	5.923508
74.65434	99.59804	5.923344
74.82334	99.76890	5.923418
74.99168	99.93790	5.923472
75.16016	100.1059	5.923418
75.32950	100.2746	5.923278
75.49866	100.4418	5.923222
75.66700	100.6105	5.923322
75.83532	100.7785	5.923262
76.00434	100.9464	5.923096
76.17350	101.1139	5.923030
76.34200	101.2831	5.923072
76.51000	101.4503	5.923038
76.67934	101.6186	5.922928
76.84850	101.7893	5.922982
77.01700	101.9588	5.922886
77.18432	102.1233	5.922790
77.35100	102.2891	5.922904
77.51768	102.4574	5.922717
77.68450	102.6245	5.922542
77.85100	102.7927	5.922584
78.01768	102.9607	5.922420
78.18450	103.1262	5.922468
78.35082	103.2953	5.922592
78.51768	103.4632	5.922472
78.68432	103.6299	5.922543
78.85082	103.7954	5.922470
79.01768	103.9629	5.922394
79.18432	104.1282	5.922268
79.35116	104.2962	5.922130
79.51768	104.4601	5.921976
79.68432	104.6289	5.921926
79.85284	104.7942	5.921745
80.02266	104.9627	5.921717
80.19100	105.1310	5.921734
80.35934	105.3006	5.921560
80.52766	105.4702	5.921502
80.69750	105.6393	5.921560
80.86600	105.8068	5.921543
81.03450	105.9741	5.921429
81.20100	106.1377	5.921293
81.36782	106.3042	5.921129
81.53432	106.4697	5.921168
81.70116	106.6368	5.921100
81.86768	106.8062	5.921089
82.03450	106.9733	5.920984
82.20100	107.1420	5.920798
82.36782	107.3114	5.920776
82.53434	107.4784	5.920726
82.70116	107.6467	5.920527
82.86766	107.8131	5.920527
83.03434	107.9809	5.920461
83.20116	108.1441	5.920530
83.36766	108.3104	5.920344
83.53450	108.4730	5.920194
83.70100	108.6406	5.920142
83.86950	108.8070	5.920048
84.03601	108.9739	5.920062
84.20266	109.1405	5.920101
84.36932	109.3059	5.919798
84.53616	109.4726	5.919754
84.70250	109.6374	5.919618
84.86932	109.8041	5.919570
85.03601	109.9717	5.919460
85.20250	110.1356	5.919282
85.36932	110.3042	5.919260
85.53582	110.4714	5.919129
85.70266	110.6391	5.918992
85.86916	110.8080	5.918918
86.03601	110.9736	5.918648
86.20282	111.1402	5.918618
86.36932	111.3074	5.918479
86.53616	111.4764	5.918356
86.70584	111.6458	5.918291
86.87434	111.8128	5.918184
87.04266	111.9788	5.918109
87.21118	112.1490	5.917910
87.38116	112.3209	5.917820
87.54932	112.4865	5.917864
87.71601	112.6520	5.917681
87.88266	112.8187	5.917528
88.04932	112.9859	5.917356
88.21601	113.1566	5.917404
88.38266	113.3257	5.917252
88.54932	113.4932	5.917150
88.71601	113.6606	5.916948
88.88266	113.8256	5.916729
89.04932	113.9888	5.916606
89.21601	114.1532	5.916493
89.38266	114.3125	5.916316
89.54932	114.4834	5.916255
89.71616	114.6538	5.916098
89.88282	114.8196	5.915899
90.04950	114.9886	5.915730
90.21601	115.1599	5.915635
90.38434	115.3316	5.915498
90.55266	115.5014	5.915398
90.72266	115.6664	5.915100
90.89100	115.8296	5.914988
91.05934	115.9930	5.914707
91.22582	116.1601	5.914630
91.39250	116.3275	5.914453
91.55950	116.4951	5.914360
91.72616	116.6676	5.914136
91.89282	116.8324	5.914081
92.05950	116.9979	5.913748
92.22616	117.1626	5.913530
92.39282	117.3275	5.913589
92.55950	117.4884	5.913192
92.72616	117.6526	5.913254
92.89282	117.8178	5.912968
93.05950	117.9825	5.912729
93.22582	118.1473	5.912497
93.39250	118.3133	5.912328
93.55934	118.4758	5.912182
93.72600	118.6447	5.911892
93.89266	118.8214	5.911816
94.05918	118.9971	5.911687
94.22616	119.1726	5.911558
94.39282	119.3481	5.911236
94.55950	119.5137	5.911041
94.72582	119.6830	5.910871
94.89266	119.8491	5.910722
95.05934	120.0106	5.910519
95.22600	120.1736	5.910382
95.39266	120.3395	5.910020
95.55934	120.5067	5.909846
95.72582	120.6710	5.909690
95.89282	120.8338	5.909384
96.05950	120.9945	5.909301
96.22616	121.1506	5.908894
96.39250	121.2957	5.908782
96.56100	121.4370	5.908542
96.73101	121.5745	5.908180
96.89932	121.7210	5.907974
97.06766	121.8824	5.907792
97.23600	122.0534	5.907461
97.40616	122.2328	5.907152
97.57450	122.4164	5.906890
97.74250	122.6013	5.906626
97.91101	122.7842	5.906242
98.07766	122.9660	5.906024
98.24432	123.1440	5.905768
98.41116	123.3204	5.905462
98.57782	123.4942	5.905130
98.74432	123.6660	5.904901
98.91101	123.8380	5.904531
99.07766	124.0080	5.904210
99.24432	124.1803	5.904066
99.41116	124.3494	5.903722
99.57782	124.5161	5.903284
99.74432	124.6840	5.903012
99.91101	124.8488	5.902590
100.0778	125.0149	5.902300
100.2445	125.1822	5.902010
100.4112	125.3489	5.901770
100.5778	125.5143	5.901486
100.7478	125.6845	5.901216
100.9162	125.8542	5.900764
101.0842	126.0234	5.900416
101.2510	126.1911	5.900085
101.4177	126.3576	5.899672
101.5843	126.5287	5.899288
101.7512	126.6941	5.898856
101.9175	126.8600	5.898338
102.0842	127.0261	5.898281
102.2512	127.1888	5.897787
102.4178	127.3534	5.897356
102.5842	127.5194	5.897036
102.7510	127.6852	5.896646
102.9177	127.8514	5.896232
103.0843	128.0187	5.895864
103.2510	128.1826	5.895480
103.4177	128.3492	5.895113
103.5845	128.5163	5.894574
103.7525	128.6856	5.894287
103.9193	128.8549	5.893862
104.0860	129.0227	5.893468
104.2527	129.1946	5.893066
104.4193	129.3604	5.892597
104.5860	129.5256	5.892093
104.7527	129.6935	5.891754
104.9193	129.8598	5.891118
105.0862	130.0254	5.890648
105.2525	130.1927	5.890244
105.4193	130.3648	5.889715
105.5860	130.5330	5.889129
105.7527	130.7018	5.888845
105.9193	130.8635	5.888172
106.0862	131.0271	5.887810
106.2528	131.1934	5.887207
106.4193	131.3613	5.886672
106.5893	131.5306	5.886199
106.7577	131.6941	5.885713
106.9260	131.8594	5.885211
107.0943	132.0251	5.884674
107.2643	132.1938	5.884120
107.4327	132.3617	5.883390
107.6010	132.5323	5.882842
107.7693	132.7005	5.882265
107.9395	132.8742	5.881714
108.1078	133.0470	5.881170
108.2743	133.2143	5.880558
108.4410	133.3842	5.879969
108.6077	133.5492	5.879378
108.7743	133.7179	5.878640
108.9410	133.8840	5.878116
109.1078	134.0502	5.877439
109.2743	134.2148	5.876820
109.4410	134.3805	5.876189
109.6077	134.5439	5.875374
109.7743	134.7113	5.874859
109.9410	134.8779	5.874178
110.1077	135.0427	5.873480
110.2743	135.2089	5.872780
110.4412	135.3793	5.872158
110.6075	135.5456	5.871350
110.7743	135.7125	5.870770
110.9418	135.8781	5.869934
111.1102	136.0478	5.869305
111.2793	136.2177	5.868506
111.4487	136.3861	5.867782
111.6168	136.5532	5.867058
111.7852	136.7209	5.866400
111.9543	136.8901	5.865620
112.1235	137.0613	5.864868
112.2918	137.2275	5.863954
112.4602	137.3974	5.863150
112.6295	137.5656	5.862324
112.7975	137.7335	5.861380
112.9643	137.9023	5.860750
113.1310	138.0681	5.859922
113.2977	138.2314	5.858907
113.4643	138.3990	5.858033
113.6312	138.5677	5.857266
113.7978	138.7374	5.856430
113.9645	138.9036	5.855457
114.1312	139.0691	5.854516
114.2975	139.2351	5.853675
114.4643	139.4026	5.852829
114.6310	139.5693	5.851807
114.7977	139.7356	5.850921
114.9643	139.9006	5.850063
115.1310	140.0666	5.848996
115.2977	140.2350	5.848048
115.4662	140.4022	5.847006
115.6345	140.5732	5.846054
115.8026	140.7406	5.845020
115.9727	140.9105	5.843990
116.1410	141.0773	5.842951
116.3093	141.2436	5.841855
116.4777	141.4119	5.840771
116.6477	141.5832	5.839834
116.8160	141.7535	5.838640
116.9843	141.9196	5.837481
117.1510	142.0865	5.836455
117.3177	142.2566	5.835415
117.4843	142.4253	5.834378
117.6512	142.5913	5.833040
117.8178	142.7580	5.831880
117.9842	142.9247	5.830700
118.1508	143.0923	5.829621
118.3177	143.2595	5.828430
118.4843	143.4279	5.827200
118.6510	143.5928	5.825909
118.8177	143.7580	5.824792
118.9845	143.9213	5.823429
119.1512	144.0863	5.822248
119.3175	144.2536	5.820963
119.4843	144.4197	5.819604
119.6526	144.5911	5.818389
119.8228	144.7600	5.817084
119.9908	144.9249	5.815557
120.1593	145.0928	5.814260
120.3276	145.2618	5.812856
120.4977	145.4362	5.811217
120.6662	145.6064	5.810016
120.8342	145.7747	5.808520
121.0027	145.9426	5.807151
121.1727	146.1115	5.805620
121.3410	146.2789	5.804107
121.5093	146.4474	5.802626
121.6778	146.6160	5.801070
121.8475	146.7852	5.799534
122.0143	146.9518	5.797949
122.1810	147.1181	5.796461
122.3477	147.2842	5.795000
122.5143	147.4511	5.793289
122.6812	147.6189	5.791844
122.8478	147.7858	5.790270
123.0142	147.9547	5.788604
123.1812	148.1206	5.786950
123.3478	148.2847	5.785198
123.5142	148.4501	5.783391
123.6810	148.6163	5.781780
123.8477	148.7874	5.780117
124.0143	148.9511	5.778164
124.1810	149.1166	5.776269
124.3478	149.2825	5.774476
124.5162	149.4544	5.772895
124.6845	149.6215	5.771015
124.8528	149.7893	5.769209
125.0225	149.9599	5.767330
125.1910	150.1274	5.765344
125.3593	150.2979	5.763462
125.5276	150.4668	5.761590
125.6977	150.6364	5.759467
125.8660	150.8050	5.757361
126.0345	150.9741	5.755458
126.2028	151.1394	5.753378
126.3728	151.3089	5.751244
126.5412	151.4754	5.749202
126.7095	151.6428	5.747071
126.8778	151.8119	5.744950
127.0475	151.9843	5.742687
127.2162	152.1522	5.740632
127.3845	152.3203	5.738331
127.5528	152.4885	5.736176
127.7228	152.6570	5.733822
127.8912	152.8270	5.731670
128.0595	152.9993	5.729282
128.2278	153.1682	5.726929
128.3976	153.3354	5.724524
128.5662	153.5041	5.722217
128.7345	153.6721	5.719742
128.9028	153.8418	5.717414
129.0726	154.0112	5.714886
129.2410	154.1776	5.712376
129.4093	154.3460	5.709926
129.5776	154.5127	5.707226
129.7442	154.6786	5.704707
129.9112	154.8445	5.702154
130.0778	155.0097	5.699590
130.2443	155.1786	5.697043
130.4110	155.3471	5.694416
130.5776	155.5148	5.691629
130.7443	155.6813	5.688992
130.9110	155.8476	5.686305
131.0776	156.0098	5.683664
131.2445	156.1786	5.680791
131.4112	156.3452	5.677954
131.5776	156.5131	5.675187
131.7444	156.6769	5.672262
131.9110	156.8458	5.669426
132.0776	157.0121	5.666392
132.2444	157.1797	5.663521
132.4144	157.3503	5.660285
132.5827	157.5174	5.657288
132.7508	157.6831	5.654084
132.9178	157.8529	5.650951
133.0845	158.0214	5.647851
133.2512	158.1897	5.644685
133.4178	158.3568	5.641479
133.5845	158.5238	5.638339
133.7512	158.6895	5.635068
133.9178	158.8554	5.631874
134.0845	159.0223	5.628574
134.2512	159.1876	5.625202
134.4175	159.3554	5.621850
134.5844	159.5213	5.618408
134.7512	159.6874	5.614875
134.9175	159.8523	5.611446
135.0844	160.0166	5.607842
135.2510	160.1833	5.604128
135.4185	160.3508	5.600481
135.5876	160.5206	5.596799
135.7570	160.6892	5.592875
135.9254	160.8582	5.589120
136.0935	161.0259	5.585324
136.2610	161.1949	5.581494
136.4277	161.3622	5.577650
136.5944	161.5274	5.573665
136.7612	161.6947	5.569844
136.9278	161.8619	5.565874
137.0945	162.0273	5.561890
137.2612	162.1922	5.557806
137.4277	162.3595	5.553852
137.5944	162.5267	5.549670
137.7610	162.6955	5.545369
137.9278	162.8624	5.541260
138.0942	163.0286	5.537020
138.2610	163.1958	5.532654
138.4277	163.3628	5.528220
138.5945	163.5325	5.523829
138.7610	163.6986	5.519368
138.9277	163.8642	5.514864
139.0977	164.0334	5.510063
139.2662	164.2015	5.505500
139.4343	164.3698	5.501071
139.6026	164.5375	5.496389
139.7726	164.7076	5.491384
139.9412	164.8762	5.486609
140.1093	165.0452	5.481738
140.2760	165.2151	5.476840
140.4427	165.3844	5.472003
140.6095	165.5518	5.466968
140.7758	165.7169	5.461744
140.9427	165.8833	5.456707
141.1093	166.0474	5.451666
141.2760	166.2117	5.446461
141.4428	166.3772	5.441155
141.6095	166.5450	5.435812
141.7762	166.7138	5.430561
141.9428	166.8836	5.425222
142.1092	167.0499	5.419829
142.2760	167.2145	5.414275
142.4427	167.3814	5.408771
142.6093	167.5478	5.403180
142.7776	167.7139	5.397459
142.9478	167.8885	5.391551
143.1162	168.0552	5.385750
143.2845	168.2242	5.379910
143.4508	168.3874	5.373966
143.6178	168.5523	5.368159
143.7845	168.7172	5.362040
143.9512	168.8846	5.356060
144.1178	169.0487	5.349920
144.2845	169.2175	5.343613
144.4512	169.3836	5.337452
144.6177	169.5480	5.331059
144.7843	169.7151	5.324626
144.9510	169.8809	5.318310
145.1177	170.0499	5.311903
145.2843	170.2171	5.305295
145.4510	170.3836	5.298635
145.6177	170.5522	5.291973
145.7843	170.7204	5.285266
145.9512	170.8871	5.278454
146.1195	171.0548	5.271651
146.2894	171.2236	5.264349
146.4577	171.3914	5.257188
146.6260	171.5596	5.250187
146.7943	171.7279	5.243075
146.9608	171.8953	5.235881
147.1278	172.0601	5.228519
147.2945	172.2250	5.221128
147.4610	172.3919	5.213741
147.6277	172.5574	5.206175
147.7943	172.7256	5.198545
147.9610	172.8928	5.190840
148.1277	173.0597	5.183038
148.2943	173.2256	5.175269
148.4610	173.3918	5.167347
148.6277	173.5596	5.159434
148.7942	173.7262	5.151371
148.9612	173.8943	5.143310
149.1277	174.0629	5.135078
149.2943	174.2291	5.126683
149.4610	174.3961	5.118362
149.6310	174.5679	5.109590
149.7993	174.7357	5.101039
149.9678	174.9029	5.092422
150.1360	175.0714	5.083768
150.3060	175.2414	5.074533
150.4745	175.4059	5.065678
150.6428	175.5711	5.056820
150.8112	175.7409	5.047922
150.9812	175.9143	5.038396
151.1494	176.0845	5.029203
151.3177	176.2528	5.019967
151.4860	176.4205	5.010540
151.6560	176.5945	5.000766
151.8245	176.7638	4.991122
151.9928	176.9338	4.981388
152.1612	177.1053	4.971970
152.3312	177.2725	4.961489
152.4992	177.4383	4.951648
152.6677	177.6078	4.941955
152.8344	177.7716	4.931859
153.0010	177.9370	4.921820
153.1678	178.1028	4.911589
153.3344	178.2674	4.901243
153.5010	178.4367	4.891130
153.6677	178.6040	4.880661
153.8344	178.7695	4.870092
154.0012	178.9388	4.859620
154.1675	179.1061	4.849010
154.3344	179.2708	4.838179
154.5010	179.4381	4.827433
154.6678	179.6020	4.816560
154.8345	179.7683	4.805623
155.0010	179.9336	4.794617
155.1677	180.1016	4.783622
155.3353	180.2710	4.772461
155.5044	180.4384	4.760946
155.6735	180.6059	4.749369
155.8420	180.7721	4.737974
156.0092	180.9379	4.726678
156.1760	181.1012	4.715263
156.3427	181.2694	4.703930
156.5094	181.4380	4.692169
156.6762	181.6065	4.680616
156.8428	181.7729	4.668913
157.0095	181.9415	4.657261
157.1762	182.1136	4.645670
157.3428	182.2778	4.633835
157.5095	182.4432	4.622183
157.6760	182.6098	4.610254
157.8427	182.7754	4.598754
158.0094	182.9442	4.587056
158.1760	183.1113	4.575540
158.3427	183.2772	4.563896
158.5094	183.4442	4.552254
158.6760	183.6099	4.540502
158.8444	183.7764	4.528516
159.0144	183.9446	4.515850
159.1827	184.1120	4.503832
159.3510	184.2821	4.491676
159.5194	184.4497	4.479394
159.6894	184.6193	4.466097
159.8577	184.7881	4.453720
160.0260	184.9558	4.441210
160.1944	185.1259	4.428460
160.3644	185.2958	4.414922
160.5327	185.4644	4.401903
160.7010	185.6318	4.388774
160.8694	185.8014	4.375479
161.0394	185.9704	4.361534
161.2078	186.1376	4.348050
161.3762	186.3063	4.334322
161.5442	186.4759	4.320526
161.7144	186.6464	4.305893
161.8827	186.8156	4.291957
162.0510	186.9855	4.277832
162.2195	187.1549	4.263568
162.3895	187.3255	4.248462
162.5575	187.4947	4.233954
162.7260	187.6619	4.219394
162.8944	187.8312	4.204517
163.0642	188.0002	4.188809
163.2325	188.1706	4.173760
163.4008	188.3408	4.158672
163.5692	188.5071	4.143326
163.7394	188.6786	4.127197
163.9076	188.8472	4.111624
164.0760	189.0140	4.096037
164.2444	189.1821	4.079997
164.4144	189.3513	4.063347
164.5828	189.5190	4.047268
164.7508	189.6856	4.030890
164.9193	189.8536	4.014417
165.0894	190.0260	3.997116
165.2578	190.1965	3.980508
165.4244	190.3587	3.963526
165.5910	190.5252	3.946594
165.7578	190.6922	3.929430
165.9244	190.8584	3.912165
166.0910	191.0256	3.894717
166.2576	191.1940	3.877285
166.4245	191.3595	3.859433
166.5908	191.5258	3.841483
166.7576	191.6922	3.823621
166.9244	191.8586	3.805375
167.0910	192.0220	3.786914
167.2576	192.1903	3.768649
167.4245	192.3559	3.750148
167.5910	192.5238	3.731311
167.7578	192.6904	3.712372
167.9258	192.8591	3.693320
168.0944	193.0262	3.674015
168.2645	193.1976	3.653664
168.4326	193.3640	3.634070
168.6010	193.5330	3.614244
168.7695	193.7012	3.594328
168.9360	193.8676	3.574378
169.1026	194.0316	3.554162
169.2692	194.1970	3.533774
169.4360	194.3628	3.513241
169.6026	194.5282	3.492613
169.7692	194.6984	3.471716
169.9360	194.8658	3.450634
170.1026	195.0339	3.429318
170.2694	195.1992	3.407942
170.4360	195.3657	3.386504
170.6025	195.5340	3.364690
170.7694	195.7025	3.342670
170.9362	195.8704	3.320580
171.1026	196.0398	3.298147
171.2694	196.2074	3.275748
171.4360	196.3731	3.253128
171.6060	196.5414	3.229240
171.7742	196.7070	3.206180
171.9427	196.8744	3.182963
172.1110	197.0442	3.159632
172.2812	197.2138	3.134842
172.4476	197.3795	3.111050
172.6144	197.5448	3.087044
172.7812	197.7112	3.062948
172.9476	197.8754	3.038658
173.1144	198.0430	3.014156
173.2812	198.2106	2.989338
173.4475	198.3790	2.964364
173.6144	198.5487	2.939196
173.7812	198.7152	2.913864
173.9476	198.8825	2.888234
174.1144	199.0483	2.862572
174.2808	199.2146	2.836548
174.4476	199.3805	2.810594
174.6144	199.5484	2.784390
174.7812	199.7145	2.757785
174.9494	199.8845	2.731113
175.1160	200.0486	2.704141
175.2826	200.2147	2.677094
175.4495	200.3823	2.649854
175.6162	200.5501	2.622369
175.7826	200.7138	2.594685
175.9494	200.8807	2.566774
176.1162	201.0464	2.538720
176.2826	201.2146	2.510555
176.4495	201.3776	2.481912
176.6160	201.5458	2.453377
176.7828	201.7124	2.424590
176.9494	201.8794	2.395517
177.1160	202.0471	2.366309
177.2828	202.2168	2.336934
177.4494	202.3841	2.307058
177.6168	202.5498	2.277094
177.7853	202.7184	2.246983
177.9544	202.8848	2.215758
178.1235	203.0568	2.184505
178.2920	203.2259	2.153764
178.4602	203.3930	2.122859
178.6294	203.5631	2.090792
178.7986	203.7332	2.058393
178.9668	203.9000	2.026611
179.1353	204.0684	1.994699
179.3044	204.2355	1.961717
179.4736	204.4096	1.928595
179.6416	204.5738	1.895687
179.8102	204.7403	1.862726
179.9794	204.9096	1.828866
180.1487	205.0821	1.794743
180.3168	205.2547	1.761107
180.4852	205.4181	1.727272
180.6545	205.5862	1.692584
180.8226	205.7540	1.657461
180.9894	205.9219	1.622968
181.1562	206.0874	1.588210
181.3226	206.2524	1.553383
181.4894	206.4153	1.517980
181.6562	206.5846	1.482820
181.8226	206.7534	1.447291
181.9894	206.9198	1.411298
182.1562	207.0861	1.375346
182.3226	207.2537	1.339018
182.4895	207.4197	1.302429
182.6560	207.5865	1.265618
182.8226	207.7558	1.228425
182.9892	207.9217	1.191265
183.1560	208.0886	1.153948
183.3225	208.2574	1.116128
183.4910	208.4256	1.078193
183.6595	208.5942	1.040130
183.8276	208.7617	1.001865
183.9977	208.9303	0.9614918
184.1662	209.0957	0.9226210
184.3344	209.2656	0.8837775
184.5028	209.4350	0.8448518
184.6727	209.6034	0.8033320
184.8394	209.7700	0.7636460
185.0058	209.9379	0.7239401
185.1727	210.1048	0.6839600
185.3395	210.2688	0.6439157
185.5060	210.4366	0.6037784
185.6728	210.6017	0.5632984
185.8394	210.7684	0.5229602
186.0062	210.9350	0.4824719
186.1727	211.1014	0.4418344
186.3395	211.2687	0.4013313
186.5060	211.4362	0.3611908
186.6728	211.6037	0.3214337
186.8394	211.7690	0.2830330
187.0062	211.9364	0.2477706
187.1727	212.1033	0.2147516
187.3394	212.2688	0.1838565
187.5058	212.4350	0.1552042
187.6727	212.6003	0.1281382
187.8395	212.7678	0.1027508
188.0060	212.9373	0.07845016
188.1728	213.1069	0.05607212
188.3392	213.2744	0.03540088
188.5060	213.4400	0.01649335
188.6728	213.6059	3.68066E-4
188.8395	213.7719	-.01118530
189.0058	213.9358	-.01522465
189.1727	214.1023	-.01616493
189.3394	214.2688	-.01658656
189.5060	214.4350	-.01672688
189.6728	214.5990	-.01670763
189.8412	214.7699	-.01680626
190.0092	214.9414	-.01702621
190.1777	215.1114	-.01698741
190.3477	215.2805	-.01694739
190.5160	215.4490	-.01704455
190.6844	215.6169	-.01712666
190.8528	215.7854	-.01723129
191.0194	215.9526	-.01724769
191.1860	216.1176	-.01737434
191.3526	216.2859	-.01742879
191.5195	216.4508	-.01749025
191.6862	216.6210	-.01740416
191.8528	216.7879	-.01752192
192.0194	216.9562	-.01757978
192.1860	217.1210	-.01760230
192.3526	217.2860	-.01767114
192.5194	217.4515	-.01764710
192.6860	217.6194	-.01773821
192.8526	217.7880	-.01771482
193.0194	217.9513	-.01792692
193.1860	218.1175	-.01791163
193.3526	218.2832	-.01811448
193.5194	218.4499	-.01807790
193.6894	218.6210	-.01824918
193.8578	218.7894	-.01812628
194.0262	218.9588	-.01821752
194.1945	219.1273	-.01825737
194.3645	219.2969	-.01812883
194.5328	219.4652	-.01818124
194.7012	219.6335	-.01805406
194.8695	219.8027	-.01815138
195.0395	219.9700	-.01815422
195.2076	220.1365	-.01824738
195.3760	220.3072	-.01819414
195.5426	220.4754	-.01828619
195.7095	220.6414	-.01822821
195.8760	220.8098	-.01826102
196.0426	220.9746	-.01829412
196.2094	221.1426	-.01823593
196.3762	221.3094	-.01824008
196.5426	221.4748	-.01824212
196.7094	221.6400	-.01844642
196.8762	221.8070	-.01849306
197.0426	221.9738	-.01849246
197.2094	222.1406	-.01859952
197.3762	222.3060	-.01848477
197.5426	222.4748	-.01849110
197.7094	222.6409	-.01855127
197.8762	222.8058	-.01861681
198.0435	222.9732	-.01869188
198.2126	223.1434	-.01871758
198.3820	223.3121	-.01883823
198.5502	223.4801	-.01885452
198.7185	223.6497	-.01876323
198.8875	223.8180	-.01875203
199.0570	223.9879	-.01876455
199.2252	224.1552	-.01886055
199.3927	224.3225	-.01876496
199.5592	224.4903	-.01881683
199.7262	224.6530	-.01893509
199.8927	224.8222	-.01891604
200.0594	224.9893	-.01897460
200.2258	225.1558	-.01895081
200.3928	225.3232	-.01891782
200.5594	225.4880	-.01904901
200.7260	225.6544	-.01912472
200.8928	225.8206	-.01899239
201.0594	225.9900	-.01892352
201.2260	226.1577	-.01882834
201.3927	226.3230	-.01891654
201.5595	226.4883	-.01897389
201.7262	226.6557	-.01895413
201.8927	226.8232	-.01899684
202.0610	226.9903	-.01897881
202.2310	227.1589	-.01904516
202.3994	227.3268	-.01908257
202.5675	227.4960	-.01903022
202.7362	227.6649	-.01893022
202.9060	227.8339	-.01918391
203.0744	228.0034	-.01899322
203.2425	228.1713	-.01918130
203.4112	228.3415	-.01912814
203.5812	228.5110	-.01918998
203.7494	228.6795	-.01924463
203.9176	228.8482	-.01928976
204.0860	229.0160	-.01925752
204.2560	229.1868	-.01929709
204.4244	229.3572	-.01921814
204.5908	229.5238	-.01927121
204.7578	229.6893	-.01929565
204.9245	229.8567	-.01931238
205.0910	230.0230	-.01925562
205.2576	230.1880	-.01929890
205.4244	230.3568	-.01934971
205.5910	230.5217	-.01924097
205.7576	230.6866	-.01937769
205.9242	230.8545	-.01940394
206.0912	231.0231	-.01935501
206.2576	231.1896	-.01940262
206.4244	231.3544	-.01939209
206.5908	231.5227	-.01949126
206.7578	231.6896	-.01952130
206.9244	231.8555	-.01951933
207.0927	232.0256	-.01934439
207.2592	232.1923	-.01934486
207.4262	232.3590	-.01939961
207.5928	232.5242	-.01954696
207.7594	232.6896	-.01955583
207.9260	232.8539	-.01950574
208.0927	233.0196	-.01953546
208.2594	233.1882	-.01950920
208.4258	233.3563	-.01949725
208.5925	233.5233	-.01946159
208.7594	233.6892	-.01957356
208.9260	233.8574	-.01936400
209.0927	234.0224	-.01945568
209.2594	234.1886	-.01942613
209.4260	234.3546	-.01967260
209.5927	234.5215	-.01942119
209.7610	234.6880	-.01950489
209.9310	234.8590	-.01953654
210.0994	235.0274	-.01969483
210.2678	235.1970	-.01941800
210.4362	235.3646	-.01954173
210.6058	235.5360	-.01939446
210.7744	235.7035	-.01955188
210.9427	235.8708	-.01949686
211.1110	236.0387	-.01951105
211.2810	236.2102	-.01960299
211.4493	236.3807	-.01955496
211.6178	236.5478	-.01946235
211.7862	236.7174	-.01952773
211.9525	236.8814	-.01949119
212.1194	237.0492	-.01937045
212.2860	237.2184	-.01944398
212.4526	237.3846	-.01934196
212.6194	237.5520	-.01940043
212.7860	237.7172	-.01938528
212.9526	237.8839	-.01934190
213.1195	238.0511	-.01933515
213.2862	238.2158	-.01936456
213.4528	238.3818	-.01946089
213.6194	238.5485	-.01954688
213.7860	238.7164	-.01945788
213.9526	238.8822	-.01952983
214.1194	239.0472	-.01949908
214.2860	239.2141	-.01964447
214.4526	239.3835	-.01939658
214.6228	239.5532	-.01942400
214.7912	239.7222	-.01938943
214.9594	239.8897	-.01955710
215.1276	240.0605	-.01930810
215.2978	240.2267	-.01965829
215.4658	240.3932	-.01943873
215.6326	240.5590	-.01955227
215.7994	240.7281	-.01950644
215.9662	240.8960	-.01946257
216.1325	241.0620	-.01956925
216.2994	241.2281	-.01950862
216.4660	241.3951	-.01953227
216.6328	241.5627	-.01963932
216.7994	241.7302	-.01961887
216.9660	241.8985	-.01973952
217.1326	242.0644	-.01954501
217.2994	242.2289	-.01960802
217.4660	242.3968	-.01943041
217.6328	242.5633	-.01963318
217.7992	242.7285	-.01968127
217.9660	242.8952	-.01962709
218.1326	243.0625	-.01945456
218.2994	243.2290	-.01965587
218.4662	243.3962	-.01940955
218.6328	243.5634	-.01944939
218.7992	243.7274	-.01961523
218.9660	243.8940	-.01970939
219.1326	244.0624	-.01970285
219.2994	244.2294	-.01960710
219.4660	244.3970	-.01964679
219.6326	244.5648	-.01950835
219.7994	244.7310	-.01942532
219.9662	244.8983	-.01945848
220.1328	245.0665	-.01961835
220.2995	245.2314	-.01970291
220.4662	245.3962	-.01959828
220.6326	245.5614	-.01975192
220.7994	245.7280	-.01977985
220.9677	245.8949	-.01989773
221.1360	246.0644	-.01966499
221.3060	246.2361	-.01972521
221.4744	246.4052	-.01964414
221.6427	246.5710	-.01977326
221.8110	246.7412	-.01976186
221.9810	246.9130	-.01975508
222.1495	247.0836	-.01960864
222.3178	247.2539	-.01939452
222.4862	247.4184	-.01960024
222.6558	247.5861	-.01950833
222.8226	247.7508	-.01953091
222.9894	247.9160	-.01950687
223.1560	248.0816	-.01946213
223.3226	248.2486	-.01926569
223.4895	248.4156	-.01944181
223.6562	248.5847	-.01936054
223.8228	248.7518	-.01929045
223.9892	248.9183	-.01947092
224.1560	249.0847	-.01943565
224.3226	249.2525	-.01957652
224.4894	249.4170	-.01949044
224.6560	249.5862	-.01938414
224.8226	249.7528	-.01929722
224.9894	249.9203	-.01938250
225.1560	250.0865	-.01947719
225.3245	250.2566	-.01911032
225.4926	250.4222	-.01928934
225.6610	250.5903	-.01928009
225.8312	250.7614	-.01910741
225.9995	250.9300	-.01922885
226.1678	251.0990	-.01903273
226.3358	251.2660	-.01902426
226.5058	251.4364	-.01911966
226.6742	251.6037	-.01915741
226.8408	251.7686	-.01926503
227.0078	251.9376	-.01920768
227.1745	252.1035	-.01919974
227.3412	252.2719	-.01907749
227.5078	252.4383	-.01903152
227.6745	252.6047	-.01911254
227.8408	252.7738	-.01925777
228.0075	252.9419	-.01887010
228.1745	253.1103	-.01912718
228.3412	253.2738	-.01892021
228.5078	253.4397	-.01899904
228.6745	253.6049	-.01884653
228.8412	253.7713	-.01889087
229.0076	253.9404	-.01884532
229.1744	254.1040	-.01893707
229.3427	254.2751	-.01889261
229.5110	254.4418	-.01917700
229.6810	254.6114	-.01916204
229.8495	254.7786	-.01897190
230.0178	254.9458	-.01909024
230.1862	255.1152	-.01889167
230.3562	255.2816	-.01907472
230.5245	255.4533	-.01880236
230.6928	255.6210	-.01885198
230.8612	255.7888	-.01877106
231.0312	255.9581	-.01897713
231.1995	256.1277	-.01887819
231.3678	256.2984	-.01874045
231.5362	256.4658	-.01893234
231.7062	256.6379	-.01892008
231.8745	256.8061	-.01883415
232.0428	256.9748	-.01875623
232.2112	257.1412	-.01886316
232.3812	257.3097	-.01882485
232.5495	257.4784	-.01887445
232.7177	257.6479	-.01884018
232.8860	257.8178	-.01884150
233.0560	257.9875	-.01884450
233.2244	258.1556	-.01877730
233.3927	258.3239	-.01873689
233.5610	258.4922	-.01874829
233.7310	258.6600	-.01882212
233.8994	258.8291	-.01876440
234.0677	258.9975	-.01879539
234.2360	259.1644	-.01879945
234.4060	259.3366	-.01859232
234.5743	259.5065	-.01865854
234.7425	259.6747	-.01864357
234.9112	259.8438	-.01868596
235.0812	260.0130	-.01867293
235.2493	260.1799	-.01867889
235.4177	260.3482	-.01879736
235.5860	260.5181	-.01866579
235.7560	260.6863	-.01885290
235.9245	260.8540	-.01882709
236.0927	261.0220	-.01877470
236.2610	261.1897	-.01898493
236.4308	261.3582	-.01875472
236.5995	261.5281	-.01877692
236.7678	261.6970	-.01885030
236.9362	261.8662	-.01877284
237.1062	262.0348	-.01889404
237.2744	262.2060	-.01889427
237.4427	262.3748	-.01891130
237.6110	262.5459	-.01876616
237.7810	262.7123	-.01879326
237.9493	262.8800	-.01879485
238.1176	263.0506	-.01846977
238.2860	263.2190	-.01847345
238.4560	263.3859	-.01844452
238.6226	263.5527	-.01865468
238.7894	263.7198	-.01853634
238.9558	263.8869	-.01851004
239.1225	264.0531	-.01864288
239.2895	264.2183	-.01869081
239.4562	264.3844	-.01877522
239.6228	264.5508	-.01871696
239.7895	264.7178	-.01869469
239.9562	264.8846	-.01868292
240.1228	265.0504	-.01864360
240.2892	265.2194	-.01878456
240.4560	265.3860	-.01870991
240.6226	265.5536	-.01867888
240.7894	265.7197	-.01877330
240.9560	265.8868	-.01886970
241.1243	266.0560	-.01878147
241.2927	266.2232	-.01875477