File: TGA/2023_07_12_CuSO4_5Hydrate_10cpm.txt
CLOSED
Version	0.4
Run	872
Instrument	2950 TGA       V5.4A
Module	TGA 1000 øC
Sample	2023_07_12_CuSO4_5Hydrate_10cpm
Size	35.7980	mg
Method	25C to 350C at 10 cpm
Operator	SBK
Comment	2023_07_12_CuSO4_5Hydrate_10cpm
Xcomment	Pan: Platinum           Gas1: Nitrogen  40          Gas2: Nitrogen  40
Text	2023_07_12_CuSO4_5Hydrate_10cpm
Text	Standard for calibration confirmation
Kcell	1.00000
TempCal	2	pts	156.68	152.50,	376.53	354.00
Thresholds	0.050	0.0000
Controls	Gas 1  Event Off  Sampling 2.0 sec/pt
Nsig	3
Sig1	Time (min)
Sig2	Temperature (øC)
Sig3	Weight (mg)
Date	12-Jul-23
Time	10:37
File	C:\TA\Data\TGA\Skyler\2023_07_12_CuSO4_5Hydrate_10cpm.001
OrgFile	C:\TA\Data\TGA\Skyler\2023_07_12_CuSO4_5Hydrate_10cpm.001
StartOfData
0.0000000	25.12250	35.62010
0.03416667	25.14346	35.61811
0.06916666	25.23426	35.61601
0.1025000	25.36266	35.61417
0.1358334	25.51455	35.61240
0.1691667	25.68429	35.61070
0.2025000	25.86790	35.60900
0.2358334	26.06516	35.60728
0.2691667	26.27732	35.60553
0.3025000	26.50115	35.60372
0.3358333	26.73740	35.60190
0.3700000	26.98851	35.60000
0.4041666	27.25183	35.59804
0.4375000	27.51777	35.59614
0.4708334	27.79140	35.59414
0.5041666	28.07228	35.59212
0.5383334	28.36684	35.59009
0.5725000	28.66846	35.58784
0.6058334	28.96938	35.58563
0.6391666	29.27298	35.58332
0.6725000	29.58222	35.58103
0.7066666	29.90232	35.57863
0.7408334	30.22522	35.57623
0.7741666	30.54414	35.57382
0.8075000	30.86532	35.57134
0.8408332	31.18891	35.56881
0.8758332	31.52790	35.56583
0.9108334	31.86654	35.56276
0.9441666	32.18834	35.55989
0.9775001	32.51360	35.55699
1.010833	32.84187	35.55414
1.045000	33.17662	35.55117
1.079166	33.51476	35.54816
1.112500	33.84348	35.54517
1.145666	34.17416	35.54201
1.179000	34.50534	35.53880
1.213167	34.84517	35.53557
1.247334	35.18510	35.53226
1.280667	35.51786	35.52894
1.314000	35.85181	35.52548
1.347334	36.18521	35.52197
1.381500	36.52500	35.51840
1.415666	36.86540	35.51475
1.449000	37.19739	35.51092
1.482333	37.53011	35.50696
1.515667	37.86326	35.50306
1.550666	38.21281	35.49844
1.585666	38.56235	35.49365
1.619000	38.89372	35.48930
1.652334	39.22604	35.48482
1.685666	39.55822	35.48013
1.719834	39.89402	35.47539
1.754000	40.22808	35.47052
1.787167	40.55593	35.46548
1.820500	40.88414	35.46028
1.853833	41.21444	35.45502
1.887166	41.54368	35.44956
1.920500	41.87252	35.44394
1.953833	42.20127	35.43827
1.987166	42.52908	35.43247
2.020833	42.86034	35.42654
2.055000	43.19777	35.42043
2.089166	43.53441	35.41416
2.122500	43.86172	35.40774
2.155833	44.18962	35.40106
2.189166	44.51932	35.39425
2.223334	44.85610	35.38723
2.257500	45.19320	35.37997
2.290833	45.52334	35.37245
2.324167	45.85288	35.36478
2.357500	46.18424	35.35696
2.392500	46.53012	35.34788
2.427500	46.87639	35.33855
2.460834	47.20540	35.33008
2.494166	47.53270	35.32146
2.527500	47.85860	35.31247
2.561666	48.19336	35.30324
2.595833	48.52728	35.29374
2.628833	48.85340	35.28397
2.662167	49.18210	35.27405
2.695666	49.51066	35.26389
2.729834	49.84786	35.25348
2.764000	50.18640	35.24280
2.797333	50.51480	35.23186
2.830667	50.84562	35.22064
2.864000	51.17488	35.20918
2.898166	51.51344	35.19746
2.932333	51.85087	35.18559
2.965667	52.18139	35.17338
2.999000	52.51168	35.16100
3.032334	52.84292	35.14824
3.067334	53.19062	35.13355
3.102334	53.53816	35.11859
3.135666	53.86922	35.10508
3.169000	54.20107	35.09124
3.202333	54.53174	35.07700
3.236500	54.87082	35.06250
3.270666	55.20943	35.04778
3.304000	55.53662	35.03271
3.337334	55.86546	35.01735
3.370667	56.19518	35.00175
3.405000	56.53420	34.98588
3.439166	56.87437	34.96961
3.472500	57.20596	34.95315
3.505834	57.53891	34.93640
3.539166	57.87353	34.91930
3.573334	58.21562	34.90189
3.607500	58.55645	34.88418
3.640500	58.88638	34.86619
3.673834	59.21802	34.84786
3.707334	59.55258	34.82928
3.742334	59.90430	34.80787
3.777333	60.25586	34.78602
3.810666	60.59021	34.76636
3.844000	60.92508	34.74636
3.877334	61.26000	34.72590
3.911500	61.60500	34.70521
3.945666	61.94848	34.68419
3.979000	62.28408	34.66290
4.012334	62.61870	34.64124
4.045666	62.95102	34.61929
4.079000	63.28236	34.59701
4.112167	63.61358	34.57430
4.145500	63.94532	34.55128
4.178834	64.27784	34.52800
4.212167	64.61206	34.50444
4.246666	64.95393	34.48051
4.280834	65.29736	34.45631
4.314166	65.62988	34.43179
4.347500	65.96337	34.40693
4.380833	66.29614	34.38176
4.415000	66.63760	34.35639
4.449167	66.97810	34.33074
4.482500	67.31006	34.30474
4.515833	67.63941	34.27852
4.549167	67.97020	34.25198
4.584167	68.31687	34.22179
4.619167	68.66451	34.19124
4.652500	68.99650	34.16382
4.685834	69.32945	34.13615
4.719166	69.66518	34.10810
4.753333	70.00938	34.07975
4.787500	70.35174	34.05112
4.820833	70.68269	34.02226
4.854166	71.01441	33.99300
4.887500	71.34956	33.96350
4.921667	71.69124	33.93380
4.955834	72.03242	33.90380
4.989166	72.36515	33.87346
5.022500	72.69855	33.84281
5.055834	73.03089	33.81184
5.090000	73.37349	33.78063
5.124166	73.71604	33.74922
5.157500	74.05054	33.71755
5.190833	74.38434	33.68566
5.224167	74.71801	33.65350
5.259168	75.06888	33.61703
5.294166	75.42036	33.58031
5.327500	75.75547	33.54732
5.360832	76.08966	33.51412
5.394166	76.42538	33.48078
5.428332	76.76895	33.44713
5.462500	77.11144	33.41334
5.495834	77.44640	33.37937
5.529168	77.77778	33.34520
5.562500	78.10913	33.31075
5.596668	78.44869	33.27611
5.630832	78.79116	33.24126
5.664166	79.12718	33.20626
5.697500	79.46046	33.17114
5.730834	79.79374	33.13578
5.765000	80.13660	33.10034
5.799168	80.47728	33.06475
5.832500	80.80792	33.02886
5.865832	81.13600	32.99285
5.899166	81.46168	32.95678
5.934000	81.80060	32.91614
5.969166	82.13716	32.87537
6.002500	82.45930	32.83910
6.035832	82.78137	32.80283
6.069166	83.10272	32.76662
6.103332	83.43364	32.73045
6.137500	83.76634	32.69428
6.170832	84.09006	32.65809
6.204168	84.41413	32.62200
6.237500	84.73887	32.58596
6.271668	85.07028	32.54986
6.305834	85.40282	32.51383
6.339168	85.72730	32.47794
6.372168	86.05197	32.44209
6.405500	86.37742	32.40632
6.439668	86.71405	32.37075
6.473834	87.05243	32.33539
6.507334	87.38406	32.30020
6.540666	87.71582	32.26524
6.574000	88.04864	32.23042
6.609000	88.39853	32.19156
6.644000	88.74816	32.15290
6.677332	89.08379	32.11862
6.710666	89.41882	32.08450
6.744000	89.75368	32.05056
6.778168	90.09799	32.01666
6.812332	90.44184	31.98294
6.845666	90.77724	31.94932
6.879000	91.11446	31.91572
6.912334	91.45098	31.88232
6.945666	91.78874	31.84912
6.979000	92.12449	31.81600
7.012334	92.45918	31.78296
7.045666	92.79634	31.75010
7.079000	93.13149	31.71734
7.113166	93.47499	31.68477
7.147332	93.82004	31.65222
7.180666	94.15676	31.61974
7.214000	94.49449	31.58736
7.247334	94.83101	31.55524
7.281500	95.17678	31.52319
7.315668	95.52219	31.49118
7.349000	95.85961	31.45922
7.382168	96.19637	31.42733
7.415500	96.53290	31.39553
7.450500	96.88754	31.35988
7.485500	97.24322	31.32433
7.518832	97.57976	31.29280
7.552168	97.91774	31.26125
7.585500	98.25524	31.22961
7.619666	98.59976	31.19783
7.653832	98.94506	31.16592
7.687168	99.27982	31.13375
7.720500	99.61386	31.10144
7.753832	99.94634	31.06890
7.787168	100.2816	31.03613
7.820500	100.6173	31.00315
7.853832	100.9526	30.97009
7.887168	101.2878	30.93678
7.920666	101.6238	30.90327
7.954000	101.9607	30.86958
7.987334	102.2965	30.83568
8.020668	102.6305	30.80166
8.054000	102.9667	30.76754
8.087334	103.3031	30.73328
8.120666	103.6393	30.69882
8.154000	103.9759	30.66432
8.187332	104.3109	30.62981
8.220666	104.6467	30.59514
8.254000	104.9823	30.56062
8.287334	105.3192	30.52602
8.320666	105.6542	30.49142
8.354000	105.9905	30.45668
8.387332	106.3242	30.42191
8.420666	106.6572	30.38719
8.453999	106.9895	30.35250
8.487334	107.3225	30.31787
8.520668	107.6552	30.28320
8.554000	107.9871	30.24855
8.587334	108.3217	30.21394
8.620666	108.6561	30.17928
8.654000	108.9899	30.14452
8.687332	109.3247	30.10972
8.720666	109.6584	30.07474
8.753999	109.9929	30.03970
8.787334	110.3287	30.00450
8.820666	110.6630	29.96916
8.854000	110.9971	29.93346
8.887332	111.3322	29.89730
8.920666	111.6678	29.86074
8.953999	112.0017	29.82362
8.987334	112.3360	29.78582
9.020668	112.6706	29.74721
9.054000	113.0036	29.70782
9.087334	113.3364	29.66752
9.120666	113.6686	29.62654
9.154000	113.9990	29.58467
9.187332	114.3288	29.54185
9.220666	114.6611	29.49814
9.253999	114.9927	29.45348
9.287334	115.3247	29.40784
9.320666	115.6564	29.36124
9.354000	115.9883	29.31370
9.387332	116.3199	29.26537
9.420666	116.6509	29.21619
9.453999	116.9837	29.16625
9.487334	117.3172	29.11565
9.520668	117.6506	29.06418
9.554000	117.9837	29.01180
9.587334	118.3178	28.95863
9.620666	118.6517	28.90486
9.654000	118.9843	28.85045
9.687332	119.3191	28.79563
9.720666	119.6526	28.74038
9.753999	119.9883	28.68472
9.787334	120.3205	28.62875
9.820666	120.6519	28.57241
9.854000	120.9860	28.51586
9.887332	121.3188	28.45920
9.920666	121.6542	28.40243
9.953999	121.9899	28.34559
9.987334	122.3238	28.28872
10.02067	122.6603	28.23206
10.05400	122.9948	28.17552
10.08733	123.3304	28.11904
10.12067	123.6670	28.06292
10.15400	124.0030	28.00707
10.18733	124.3384	27.95141
10.22067	124.6745	27.89620
10.25400	125.0096	27.84141
10.28733	125.3476	27.78691
10.32067	125.6814	27.73278
10.35400	126.0172	27.67932
10.38733	126.3535	27.62659
10.42067	126.6877	27.57448
10.45400	127.0244	27.52295
10.48734	127.3578	27.47184
10.52067	127.6913	27.42152
10.55400	128.0248	27.37236
10.58734	128.3585	27.32427
10.62066	128.6938	27.27700
10.65484	129.0390	27.23065
10.68900	129.3822	27.18538
10.72233	129.7180	27.14136
10.75566	130.0521	27.09856
10.78900	130.3881	27.05686
10.82316	130.7327	27.01638
10.85734	131.0766	26.97700
10.89066	131.4119	26.93873
10.92400	131.7478	26.90137
10.95734	132.0817	26.86490
10.99233	132.4343	26.82508
11.02733	132.7869	26.78656
11.06067	133.1212	26.75330
11.09400	133.4549	26.72094
11.12734	133.7899	26.68950
11.16150	134.1302	26.65913
11.19566	134.4698	26.62972
11.22900	134.8019	26.60118
11.26233	135.1339	26.57346
11.29566	135.4666	26.54649
11.32983	135.8074	26.52008
11.36400	136.1484	26.49422
11.39733	136.4811	26.46905
11.43066	136.8125	26.44445
11.46400	137.1439	26.42045
11.49734	137.4775	26.39736
11.53066	137.8088	26.37497
11.56400	138.1401	26.35337
11.59733	138.4729	26.33258
11.63066	138.8042	26.31268
11.66400	139.1378	26.29375
11.69734	139.4699	26.27593
11.73066	139.8001	26.25923
11.76400	140.1319	26.24365
11.79734	140.4647	26.22916
11.83066	140.7953	26.21565
11.86400	141.1262	26.20304
11.89733	141.4572	26.19118
11.93066	141.7886	26.17990
11.96400	142.1218	26.16926
11.99734	142.4542	26.15940
12.03066	142.7865	26.15022
12.06400	143.1190	26.14173
12.09733	143.4527	26.13391
12.13066	143.7861	26.12669
12.16400	144.1196	26.12018
12.19734	144.4512	26.11416
12.23066	144.7832	26.10849
12.26400	145.1166	26.10296
12.29734	145.4489	26.09778
12.33066	145.7809	26.09322
12.36400	146.1127	26.08911
12.39733	146.4456	26.08559
12.43066	146.7780	26.08258
12.46400	147.1108	26.07991
12.49734	147.4424	26.07763
12.53066	147.7708	26.07567
12.56417	148.1012	26.07385
12.59750	148.4325	26.07218
12.63084	148.7645	26.07072
12.66416	149.0961	26.06927
12.69750	149.4272	26.06790
12.73084	149.7592	26.06656
12.76417	150.0926	26.06528
12.79750	150.4255	26.06408
12.83084	150.7590	26.06294
12.86416	151.0906	26.06184
12.89750	151.4234	26.06078
12.93084	151.7566	26.05981
12.96416	152.0890	26.05878
12.99750	152.4220	26.05773
13.03084	152.7548	26.05676
13.06416	153.0880	26.05590
13.09750	153.4214	26.05497
13.13050	153.7516	26.05405
13.16383	154.0844	26.05308
13.19717	154.4162	26.05219
13.23050	154.7486	26.05136
13.26383	155.0820	26.05046
13.29717	155.4150	26.04964
13.33066	155.7478	26.04882
13.36400	156.0765	26.04799
13.39733	156.4055	26.04711
13.43066	156.7356	26.04619
13.46400	157.0660	26.04539
13.49733	157.3976	26.04469
13.53066	157.7299	26.04388
13.56400	158.0628	26.04299
13.59733	158.3958	26.04216
13.63066	158.7292	26.04141
13.66400	159.0630	26.04061
13.69733	159.3963	26.03973
13.73066	159.7310	26.03892
13.76400	160.0649	26.03811
13.79734	160.3980	26.03733
13.83066	160.7296	26.03657
13.86400	161.0615	26.03575
13.89733	161.3946	26.03496
13.93066	161.7277	26.03413
13.96400	162.0612	26.03338
13.99750	162.3951	26.03256
14.03084	162.7287	26.03180
14.06416	163.0612	26.03104
14.09750	163.3954	26.03022
14.13084	163.7296	26.02938
14.16383	164.0636	26.02860
14.19800	164.4044	26.02777
14.23216	164.7478	26.02692
14.26567	165.0826	26.02615
14.29900	165.4169	26.02532
14.33234	165.7478	26.02449
14.36734	166.0928	26.02356
14.40233	166.4392	26.02268
14.43567	166.7688	26.02191
14.46900	167.1004	26.02103
14.50233	167.4315	26.02023
14.53650	167.7713	26.01939
14.57066	168.1121	26.01856
14.60400	168.4457	26.01774
14.63733	168.7786	26.01692
14.67066	169.1126	26.01617
14.70400	169.4466	26.01526
14.73734	169.7817	26.01439
14.77066	170.1173	26.01354
14.80400	170.4506	26.01268
14.83750	170.7850	26.01178
14.87167	171.1269	26.01084
14.90584	171.4694	26.00995
14.93916	171.8032	26.00912
14.97250	172.1373	26.00814
15.00584	172.4728	26.00728
15.03883	172.8044	26.00641
15.07217	173.1378	26.00552
15.10566	173.4709	26.00459
15.13900	173.8032	26.00367
15.17234	174.1390	26.00282
15.20566	174.4719	26.00185
15.23900	174.8048	26.00085
15.27233	175.1387	25.99989
15.30566	175.4689	25.99900
15.33900	175.7972	25.99801
15.37233	176.1269	25.99703
15.40566	176.4591	25.99602
15.43900	176.7922	25.99514
15.47233	177.1239	25.99425
15.50566	177.4575	25.99336
15.53900	177.7902	25.99234
15.57233	178.1244	25.99128
15.60584	178.4581	25.99030
15.63916	178.7931	25.98933
15.67250	179.1277	25.98837
15.70584	179.4616	25.98735
15.73916	179.7948	25.98633
15.77250	180.1276	25.98538
15.80550	180.4602	25.98430
15.83883	180.7924	25.98327
15.87217	181.1256	25.98214
15.90550	181.4599	25.98100
15.93900	181.7949	25.98004
15.97233	182.1286	25.97907
16.00566	182.4636	25.97798
16.03900	182.7972	25.97682
16.07233	183.1325	25.97580
16.10566	183.4676	25.97468
16.13900	183.8023	25.97358
16.17233	184.1372	25.97244
16.20566	184.4719	25.97123
16.23900	184.8048	25.97006
16.27233	185.1351	25.96888
16.30566	185.4654	25.96780
16.33900	185.7941	25.96660
16.37233	186.1235	25.96534
16.40566	186.4552	25.96411
16.43900	186.7880	25.96291
16.47234	187.1211	25.96156
16.50566	187.4535	25.96018
16.53900	187.7872	25.95898
16.57233	188.1204	25.95762
16.60566	188.4558	25.95624
16.63900	188.7905	25.95494
16.67250	189.1245	25.95360
16.70584	189.4589	25.95225
16.73916	189.7925	25.95089
16.77250	190.1272	25.94950
16.80584	190.4615	25.94808
16.83916	190.7970	25.94668
16.87250	191.1306	25.94518
16.90584	191.4645	25.94365
16.93916	191.7975	25.94216
16.97216	192.1277	25.94068
17.00550	192.4598	25.93912
17.03883	192.7944	25.93755
17.07216	193.1285	25.93598
17.10566	193.4633	25.93430
17.13900	193.7978	25.93260
17.17233	194.1292	25.93097
17.20566	194.4584	25.92932
17.23900	194.7883	25.92760
17.27233	195.1194	25.92590
17.30566	195.4523	25.92414
17.33900	195.7860	25.92234
17.37233	196.1188	25.92053
17.40566	196.4516	25.91869
17.43900	196.7854	25.91692
17.47234	197.1195	25.91508
17.50566	197.4512	25.91316
17.53900	197.7846	25.91126
17.57233	198.1175	25.90934
17.60566	198.4504	25.90738
17.63900	198.7836	25.90534
17.67233	199.1184	25.90328
17.70566	199.4521	25.90124
17.73900	199.7856	25.89908
17.77233	200.1206	25.89704
17.80566	200.4545	25.89486
17.83900	200.7889	25.89266
17.87233	201.1227	25.89040
17.90566	201.4562	25.88812
17.93900	201.7902	25.88581
17.97234	202.1256	25.88336
18.00566	202.4577	25.88093
18.03900	202.7935	25.87842
18.07316	203.1351	25.87592
18.10750	203.4732	25.87336
18.14083	203.8032	25.87072
18.17416	204.1353	25.86805
18.20750	204.4669	25.86528
18.24250	204.8162	25.86205
18.27750	205.1664	25.85878
18.31084	205.4989	25.85581
18.34384	205.8323	25.85272
18.37716	206.1649	25.84961
18.41133	206.5061	25.84634
18.44550	206.8491	25.84298
18.47884	207.1839	25.83951
18.51217	207.5180	25.83590
18.54566	207.8513	25.83212
18.57900	208.1858	25.82826
18.61234	208.5201	25.82427
18.64566	208.8541	25.82013
18.67900	209.1846	25.81573
18.71234	209.5179	25.81110
18.74566	209.8506	25.80644
18.77900	210.1829	25.80153
18.81234	210.5167	25.79630
18.84566	210.8501	25.79094
18.87900	211.1839	25.78535
18.91233	211.5180	25.77955
18.94566	211.8511	25.77348
18.97900	212.1844	25.76714
19.01233	212.5139	25.76052
19.04566	212.8455	25.75366
19.07900	213.1774	25.74652
19.11234	213.5102	25.73912
19.14566	213.8431	25.73140
19.17900	214.1768	25.72358
19.21234	214.5088	25.71531
19.24566	214.8414	25.70675
19.27900	215.1736	25.69787
19.31234	215.5066	25.68870
19.34566	215.8392	25.67932
19.37900	216.1718	25.66952
19.41233	216.5060	25.65957
19.44566	216.8388	25.64933
19.47900	217.1734	25.63878
19.51250	217.5065	25.62801
19.54584	217.8400	25.61697
19.57916	218.1746	25.60565
19.61250	218.5095	25.59403
19.64584	218.8445	25.58216
19.67917	219.1796	25.56999
19.71250	219.5156	25.55760
19.74583	219.8502	25.54489
19.77917	220.1828	25.53199
19.81250	220.5138	25.51884
19.84583	220.8468	25.50545
19.87917	221.1786	25.49194
19.91250	221.5092	25.47812
19.94583	221.8403	25.46402
19.97916	222.1730	25.44978
20.01250	222.5054	25.43525
20.04584	222.8379	25.42057
20.07916	223.1707	25.40568
20.11250	223.5046	25.39063
20.14584	223.8375	25.37534
20.17917	224.1705	25.35972
20.21250	224.5045	25.34388
20.24583	224.8391	25.32802
20.27917	225.1726	25.31194
20.31250	225.5052	25.29562
20.34583	225.8396	25.27910
20.37917	226.1733	25.26240
20.41250	226.5058	25.24546
20.44566	226.8391	25.22842
20.47900	227.1725	25.21126
20.51233	227.5071	25.19390
20.54566	227.8413	25.17635
20.57900	228.1762	25.15861
20.61234	228.5100	25.14082
20.64566	228.8428	25.12281
20.67900	229.1770	25.10453
20.71234	229.5120	25.08624
20.74566	229.8462	25.06791
20.77900	230.1790	25.04932
20.81234	230.5133	25.03060
20.84566	230.8468	25.01187
20.87900	231.1791	24.99289
20.91233	231.5105	24.97374
20.94566	231.8451	24.95455
20.97900	232.1764	24.93522
21.01233	232.5096	24.91576
21.04566	232.8433	24.89626
21.07900	233.1764	24.87665
21.11234	233.5088	24.85687
21.14566	233.8422	24.83705
21.17900	234.1764	24.81718
21.21234	234.5092	24.79716
21.24566	234.8444	24.77705
21.27983	235.1867	24.75710
21.31400	235.5284	24.73684
21.34734	235.8632	24.71646
21.38066	236.1963	24.69615
21.41400	236.5275	24.67575
21.44816	236.8690	24.65531
21.48234	237.2090	24.63487
21.51583	237.5418	24.61433
21.54916	237.8758	24.59378
21.58250	238.2077	24.57316
21.61750	238.5588	24.54996
21.65250	238.9088	24.52672
21.68584	239.2414	24.50595
21.71916	239.5748	24.48528
21.75234	239.9094	24.46468
21.78650	240.2505	24.44404
21.82066	240.5926	24.42333
21.85400	240.9260	24.40275
21.88733	241.2590	24.38198
21.92066	241.5931	24.36138
21.95484	241.9354	24.34084
21.98900	242.2761	24.32031
22.02234	242.6098	24.29982
22.05566	242.9424	24.27941
22.08900	243.2764	24.25905
22.12316	243.6179	24.23880
22.15734	243.9596	24.21855
22.19066	244.2944	24.19844
22.22400	244.6272	24.17847
22.25734	244.9619	24.15844
22.29234	245.3126	24.13603
22.32734	245.6627	24.11386
22.36066	245.9972	24.09428
22.39400	246.3312	24.07478
22.42734	246.6654	24.05548
22.46150	247.0072	24.03628
22.49566	247.3490	24.01724
22.52900	247.6820	23.99835
22.56234	248.0140	23.97955
22.59566	248.3473	23.96096
22.62984	248.6904	23.94267
22.66400	249.0292	23.92453
22.69734	249.3641	23.90640
22.73066	249.6969	23.88858
22.76400	250.0325	23.87106
22.79816	250.3760	23.85383
22.83234	250.7179	23.83675
22.86567	251.0520	23.81982
22.89900	251.3847	23.80314
22.93234	251.7176	23.78672
22.96733	252.0679	23.76855
23.00234	252.4175	23.75081
23.03566	252.7499	23.73532
23.06900	253.0822	23.72023
23.10234	253.4143	23.70543
23.13650	253.7560	23.69080
23.17066	254.0992	23.67658
23.20400	254.4314	23.66262
23.23734	254.7648	23.64896
23.27066	255.0976	23.63576
23.30483	255.4397	23.62285
23.33900	255.7815	23.61037
23.37234	256.1155	23.59806
23.40566	256.4504	23.58628
23.43900	256.7845	23.57484
23.47316	257.1264	23.56372
23.50734	257.4695	23.55297
23.54066	257.8021	23.54266
23.57400	258.1338	23.53267
23.60734	258.4670	23.52310
23.64234	258.8151	23.51282
23.67734	259.1648	23.50300
23.71066	259.4986	23.49470
23.74400	259.8316	23.48677
23.77734	260.1647	23.47914
23.81150	260.5064	23.47194
23.84566	260.8488	23.46511
23.87900	261.1829	23.45866
23.91233	261.5155	23.45250
23.94566	261.8492	23.44676
23.97984	262.1906	23.44124
24.01400	262.5328	23.43597
24.04734	262.8668	23.43115
24.08066	263.2000	23.42661
24.11400	263.5332	23.42234
24.14816	263.8750	23.41832
24.18234	264.2160	23.41458
24.21566	264.5490	23.41108
24.24900	264.8830	23.40778
24.28234	265.2166	23.40476
24.31734	265.5674	23.40160
24.35234	265.9172	23.39864
24.38566	266.2510	23.39616
24.41900	266.5836	23.39379
24.45234	266.9172	23.39170
24.48650	267.2586	23.38980
24.52066	267.5998	23.38782
24.55400	267.9354	23.38613
24.58734	268.2681	23.38462
24.62066	268.5987	23.38302
24.65483	268.9402	23.38156
24.68900	269.2798	23.38030
24.72234	269.6100	23.37888
24.75566	269.9442	23.37750
24.78917	270.2771	23.37654
24.82334	270.6174	23.37551
24.85750	270.9573	23.37447
24.89083	271.2923	23.37345
24.92416	271.6245	23.37260
24.95750	271.9580	23.37180
24.99250	272.3086	23.37096
25.02750	272.6584	23.37019
25.06084	272.9911	23.36936
25.09416	273.3246	23.36862
25.12750	273.6582	23.36795
25.16167	274.0006	23.36744
25.19583	274.3408	23.36678
25.22916	274.6752	23.36612
25.26250	275.0098	23.36556
25.29584	275.3438	23.36504
25.33000	275.6856	23.36449
25.36416	276.0276	23.36395
25.39750	276.3599	23.36334
25.43083	276.6945	23.36282
25.46416	277.0278	23.36240
25.49834	277.3700	23.36201
25.53234	277.7119	23.36155
25.56566	278.0454	23.36106
25.59900	278.3785	23.36065
25.63234	278.7113	23.36023
25.66734	279.0610	23.35973
25.70234	279.4102	23.35930
25.73566	279.7428	23.35900
25.76900	280.0760	23.35866
25.80234	280.4087	23.35830
25.83650	280.7501	23.35792
25.87066	281.0928	23.35760
25.90400	281.4258	23.35731
25.93734	281.7587	23.35700
25.97066	282.0918	23.35660
26.00484	282.4344	23.35634
26.03900	282.7774	23.35605
26.07234	283.1135	23.35574
26.10566	283.4490	23.35545
26.13900	283.7843	23.35516
26.17316	284.1264	23.35484
26.20734	284.4686	23.35453
26.24067	284.8024	23.35423
26.27400	285.1355	23.35388
26.30734	285.4687	23.35359
26.34234	285.8198	23.35333
26.37733	286.1699	23.35305
26.41067	286.5033	23.35280
26.44400	286.8370	23.35254
26.47733	287.1704	23.35230
26.51150	287.5129	23.35208
26.54566	287.8546	23.35186
26.57900	288.1863	23.35166
26.61233	288.5203	23.35139
26.64566	288.8543	23.35115
26.67984	289.1961	23.35092
26.71400	289.5359	23.35070
26.74734	289.8672	23.35050
26.78066	290.2004	23.35020
26.81400	290.5325	23.34990
26.84817	290.8758	23.34968
26.88234	291.2170	23.34946
26.91567	291.5494	23.34926
26.94900	291.8855	23.34906
26.98234	292.2215	23.34886
27.01734	292.5716	23.34860
27.05234	292.9232	23.34833
27.08566	293.2567	23.34814
27.11900	293.5910	23.34791
27.15234	293.9236	23.34766
27.18650	294.2668	23.34752
27.22066	294.6083	23.34741
27.25400	294.9400	23.34721
27.28733	295.2735	23.34696
27.32066	295.6064	23.34670
27.35383	295.9395	23.34650
27.38717	296.2726	23.34646
27.42050	296.6050	23.34635
27.45383	296.9381	23.34611
27.48750	297.2723	23.34588
27.52084	297.6066	23.34567
27.55416	297.9390	23.34541
27.58750	298.2707	23.34510
27.62083	298.6022	23.34488
27.65417	298.9364	23.34468
27.68750	299.2706	23.34454
27.72083	299.6053	23.34454
27.75417	299.9363	23.34444
27.78750	300.2688	23.34411
27.82084	300.6026	23.34382
27.85400	300.9387	23.34361
27.88733	301.2736	23.34340
27.92066	301.6079	23.34320
27.95400	301.9418	23.34304
27.98733	302.2761	23.34287
28.02066	302.6098	23.34268
28.05400	302.9434	23.34244
28.08734	303.2764	23.34223
28.12066	303.6096	23.34202
28.15400	303.9428	23.34184
28.18734	304.2764	23.34165
28.22066	304.6100	23.34151
28.25400	304.9430	23.34138
28.28733	305.2750	23.34118
28.32066	305.6096	23.34093
28.35400	305.9406	23.34080
28.38733	306.2738	23.34056
28.42066	306.6072	23.34050
28.45400	306.9381	23.34036
28.48733	307.2709	23.34016
28.52066	307.6044	23.33990
28.55400	307.9370	23.33975
28.58734	308.2682	23.33957
28.62066	308.6020	23.33936
28.65400	308.9318	23.33902
28.68734	309.2658	23.33875
28.72066	309.6002	23.33878
28.75400	309.9365	23.33857
28.78733	310.2734	23.33841
28.82066	310.6098	23.33830
28.85400	310.9448	23.33819
28.88733	311.2766	23.33802
28.92066	311.6093	23.33781
28.95400	311.9425	23.33756
28.98733	312.2770	23.33740
29.02066	312.6097	23.33728
29.05400	312.9435	23.33712
29.08734	313.2753	23.33696
29.12066	313.6117	23.33670
29.15417	313.9420	23.33655
29.18750	314.2765	23.33637
29.22083	314.6102	23.33626
29.25417	314.9428	23.33605
29.28750	315.2770	23.33580
29.32084	315.6089	23.33576
29.35416	315.9418	23.33553
29.38750	316.2751	23.33534
29.42084	316.6080	23.33515
29.45416	316.9408	23.33498
29.48750	317.2737	23.33478
29.52084	317.6044	23.33455
29.55416	317.9404	23.33430
29.58750	318.2712	23.33426
29.62083	318.6041	23.33407
29.65417	318.9402	23.33386
29.68750	319.2776	23.33379
29.72083	319.6131	23.33359
29.75417	319.9490	23.33338
29.78750	320.2848	23.33314
29.82084	320.6198	23.33300
29.85416	320.9543	23.33285
29.88750	321.2877	23.33272
29.92084	321.6206	23.33258
29.95416	321.9528	23.33236
29.98733	322.2863	23.33217
30.02084	322.6195	23.33200
30.05500	322.9605	23.33182
30.08916	323.3031	23.33170
30.12250	323.6340	23.33154
30.15584	323.9706	23.33128
30.18916	324.3038	23.33125
30.22334	324.6451	23.33113
30.25750	324.9860	23.33098
30.29083	325.3190	23.33083
30.32417	325.6532	23.33076
30.35750	325.9860	23.33068
30.39250	326.3347	23.33045
30.42750	326.6836	23.33016
30.46084	327.0170	23.32997
30.49417	327.3492	23.32976
30.52750	327.6806	23.32960
30.56167	328.0212	23.32947
30.59583	328.3613	23.32926
30.62917	328.7014	23.32899
30.66250	329.0383	23.32890
30.69584	329.3733	23.32874
30.73000	329.7162	23.32860
30.76416	330.0570	23.32850
30.79750	330.3906	23.32825
30.83084	330.7237	23.32802
30.86400	331.0570	23.32780
30.89834	331.3994	23.32770
30.93250	331.7406	23.32751
30.96583	332.0732	23.32734
30.99917	332.4061	23.32718
31.03250	332.7393	23.32690
31.06750	333.0881	23.32672
31.10250	333.4368	23.32652
31.13584	333.7681	23.32633
31.16916	334.1019	23.32608
31.20250	334.4345	23.32592
31.23667	334.7766	23.32578
31.27084	335.1172	23.32561
31.30416	335.4519	23.32540
31.33750	335.7841	23.32530
31.37083	336.1168	23.32509
31.40500	336.4572	23.32486
31.43883	336.7988	23.32473
31.47216	337.1295	23.32457
31.50550	337.4637	23.32436
31.53883	337.7968	23.32414
31.57300	338.1455	23.32393
31.60734	338.4914	23.32370
31.64067	338.8278	23.32344
31.67400	339.1620	23.32327
31.70734	339.4948	23.32306
31.74234	339.8452	23.32280
31.77734	340.1958	23.32260
31.81066	340.5310	23.32242
31.84400	340.8630	23.32230
31.87733	341.1964	23.32206
31.91150	341.5364	23.32184
31.94566	341.8806	23.32163
31.97900	342.2119	23.32142
32.01233	342.5458	23.32119
32.04566	342.8787	23.32099
32.07900	343.2122	23.32078
32.11234	343.5453	23.32057
32.14566	343.8795	23.32037
32.17900	344.2117	23.32019
32.21234	344.5439	23.32000
32.24650	344.8840	23.31978
32.28066	345.2256	23.31958
32.31400	345.5591	23.31941
32.34734	345.8920	23.31916
32.38066	346.2241	23.31893
32.41483	346.5650	23.31874
32.44900	346.9071	23.31856
32.48234	347.2390	23.31834