File: TGA/2023_07_11_Ni_calib_1cpm.txt
CLOSED
Version	0.4
Run	869
Instrument	2950 TGA       V5.4A
Module	TGA 1000 øC
Sample	2023_07_11_Ni_calib_1cpm
Size	14.4900	mg
Method	270C to 400C 1CPM
Operator	SBK
Comment	2023_07_11_Ni_calib_1cpm
Xcomment	Pan: Platinum           Gas1: Nitrogen  40          Gas2: Nitrogen  40
Text	2023_07_11_Ni_calib_1cpm
Text	Calibration with nickel foam and magnet
Kcell	1.00000
TempCal	0	pts
Thresholds	0.050	0.0000
Controls	Gas 1  Event Off  Sampling 2.0 sec/pt
Nsig	3
Sig1	Time (min)
Sig2	Temperature (øC)
Sig3	Weight (mg)
Date	11-Jul-23
Time	10:42
File	C:\TA\Data\TGA\Skyler\2023_07_11_Ni_calib_1cpm.002
OrgFile	C:\TA\Data\TGA\Skyler\2023_07_11_Ni_calib_1cpm.002
StartOfData
0.0000000	269.9831	14.53189
0.1028333	270.0300	14.53198
0.2028334	270.0950	14.53174
0.3045000	270.1687	14.53152
0.4053333	270.2510	14.53156
0.5061666	270.3375	14.53141
0.6078332	270.4274	14.53147
0.7078332	270.5200	14.53118
0.8111668	270.6150	14.53093
0.9120000	270.7106	14.53075
1.012833	270.8070	14.53082
1.114667	270.9046	14.53051
1.214667	271.0010	14.53028
1.316000	271.0964	14.53000
1.417666	271.1934	14.52984
1.519334	271.2924	14.52964
1.621000	271.3902	14.52951
1.721167	271.4878	14.52945
1.821167	271.5840	14.52928
1.921000	271.6823	14.52906
2.021000	271.7774	14.52894
2.121000	271.8770	14.52871
2.221000	271.9726	14.52872
2.321000	272.0737	14.52848
2.421000	272.1719	14.52845
2.521167	272.2702	14.52816
2.621167	272.3688	14.52786
2.721167	272.4670	14.52780
2.821167	272.5679	14.52755
2.921167	272.6657	14.52739
3.021167	272.7657	14.52734
3.121167	272.8684	14.52720
3.221000	272.9685	14.52699
3.321000	273.0679	14.52677
3.421333	273.1686	14.52658
3.521333	273.2683	14.52645
3.621333	273.3667	14.52640
3.721333	273.4659	14.52600
3.821333	273.5645	14.52582
3.921333	273.6611	14.52566
4.021333	273.7629	14.52535
4.121334	273.8628	14.52530
4.221334	273.9634	14.52524
4.321334	274.0634	14.52500
4.421334	274.1644	14.52469
4.523000	274.2660	14.52453
4.623833	274.3670	14.52433
4.724667	274.4681	14.52414
4.827667	274.5708	14.52398
4.927666	274.6731	14.52373
5.029500	274.7741	14.52350
5.130333	274.8733	14.52335
5.231167	274.9764	14.52324
5.332832	275.0772	14.52313
5.432832	275.1773	14.52284
5.536168	275.2808	14.52281
5.637168	275.3820	14.52251
5.738000	275.4836	14.52228
5.839334	275.5829	14.52188
5.939500	275.6831	14.52187
6.041168	275.7850	14.52166
6.142000	275.8851	14.52145
6.242832	275.9878	14.52139
6.346166	276.0904	14.52112
6.446166	276.1932	14.52099
6.548000	276.2934	14.52088
6.647666	276.3927	14.52059
6.747832	276.4910	14.52040
6.847832	276.5894	14.52002
6.947832	276.6912	14.51978
7.047832	276.7890	14.51958
7.147832	276.8888	14.51950
7.248000	276.9907	14.51949
7.347668	277.0895	14.51906
7.447832	277.1924	14.51903
7.547832	277.2944	14.51901
7.647832	277.3916	14.51856
7.747832	277.4932	14.51843
7.848000	277.5924	14.51804
7.947832	277.6933	14.51783
8.047832	277.7926	14.51766
8.147832	277.8928	14.51746
8.247832	277.9923	14.51719
8.348000	278.0928	14.51708
8.447668	278.1918	14.51686
8.547832	278.2910	14.51672
8.647832	278.3914	14.51656
8.747832	278.4929	14.51656
8.847832	278.5935	14.51599
8.947999	278.6930	14.51583
9.047668	278.7931	14.51568
9.147832	278.8945	14.51539
9.247832	278.9938	14.51514
9.348666	279.0913	14.51502
9.449500	279.1950	14.51480
9.553000	279.2963	14.51434
9.652668	279.3966	14.51426
9.754501	279.4985	14.51395
9.855332	279.5982	14.51384
9.956166	279.7015	14.51366
10.05783	279.8040	14.51363
10.15783	279.9024	14.51331
10.26133	280.0068	14.51312
10.36183	280.1090	14.51296
10.46283	280.2082	14.51282
10.56450	280.3110	14.51258
10.66450	280.4124	14.51221
10.76634	280.5125	14.51212
10.86800	280.6142	14.51192
10.96950	280.7150	14.51164
11.07117	280.8164	14.51148
11.17116	280.9148	14.51126
11.27283	281.0190	14.51125
11.37383	281.1208	14.51087
11.47434	281.2217	14.51068
11.57783	281.3269	14.51047
11.67783	281.4264	14.51027
11.77967	281.5266	14.51006
11.88050	281.6275	14.51000
11.98117	281.7280	14.50970
12.08283	281.8294	14.50957
12.18284	281.9289	14.50928
12.28633	282.0313	14.50895
12.38717	282.1330	14.50872
12.48783	282.2348	14.50852
12.58783	282.3346	14.50854
12.68784	282.4367	14.50841
12.78800	282.5364	14.50798
12.88800	282.6356	14.50778
12.98767	282.7348	14.50764
13.08783	282.8350	14.50738
13.18784	282.9342	14.50729
13.28783	283.0333	14.50712
13.38784	283.1332	14.50689
13.48800	283.2320	14.50662
13.58766	283.3314	14.50640
13.68784	283.4317	14.50624
13.78783	283.5315	14.50603
13.88784	283.6304	14.50571
13.98800	283.7321	14.50555
14.08766	283.8320	14.50549
14.18784	283.9314	14.50510
14.28783	284.0326	14.50514
14.38784	284.1315	14.50493
14.48800	284.2311	14.50459
14.58766	284.3306	14.50432
14.68784	284.4332	14.50445
14.78783	284.5332	14.50430
14.88784	284.6346	14.50387
14.98800	284.7373	14.50378
15.08766	284.8354	14.50351
15.18784	284.9359	14.50328
15.28950	285.0370	14.50314
15.38950	285.1368	14.50300
15.49133	285.2395	14.50282
15.59300	285.3422	14.50273
15.69450	285.4455	14.50236
15.79617	285.5448	14.50221
15.89617	285.6447	14.50194
15.99783	285.7454	14.50175
16.09883	285.8454	14.50148
16.19934	285.9459	14.50124
16.30283	286.0492	14.50106
16.40284	286.1496	14.50091
16.50450	286.2510	14.50064
16.60534	286.3524	14.50045
16.70633	286.4514	14.50009
16.80800	286.5525	14.49971
16.90767	286.6534	14.49957
17.01117	286.7588	14.49928
17.11200	286.8580	14.49911
17.21283	286.9588	14.49896
17.31450	287.0628	14.49891
17.41450	287.1628	14.49869
17.51633	287.2670	14.49857
17.61800	287.3686	14.49824
17.71966	287.4697	14.49822
17.82100	287.5722	14.49772
17.92100	287.6696	14.49763
18.02284	287.7722	14.49723
18.12367	287.8736	14.49695
18.22450	287.9740	14.49660
18.32784	288.0752	14.49651
18.42800	288.1790	14.49566
18.52966	288.2726	14.49255
18.62934	288.3682	14.49214
18.72950	288.4739	14.49235
18.82950	288.5701	14.49179
18.92950	288.6728	14.49176
19.02950	288.7724	14.49144
19.12967	288.8722	14.49118
19.22966	288.9748	14.49132
19.32934	289.0750	14.49093
19.42950	289.1768	14.49075
19.52950	289.2740	14.49035
19.62950	289.3756	14.49022
19.72950	289.4755	14.49012
19.82950	289.5778	14.49004
19.92950	289.6756	14.48953
20.02950	289.7779	14.48928
20.12950	289.8786	14.48923
20.22950	289.9782	14.48889
20.32966	290.0772	14.48873
20.42966	290.1768	14.48851
20.52966	290.2774	14.48814
20.62934	290.3766	14.48795
20.72950	290.4780	14.48802
20.82950	290.5779	14.48772
20.92950	290.6785	14.48745
21.02950	290.7779	14.48728
21.12950	290.8750	14.48706
21.22950	290.9772	14.48686
21.33034	291.0780	14.48658
21.43117	291.1792	14.48646
21.53117	291.2780	14.48624
21.63117	291.3781	14.48586
21.73117	291.4772	14.48586
21.83117	291.5756	14.48562
21.93117	291.6765	14.48545
22.03117	291.7755	14.48510
22.13117	291.8766	14.48488
22.23133	291.9768	14.48478
22.33133	292.0738	14.48442
22.43133	292.1768	14.48420
22.53133	292.2765	14.48406
22.63133	292.3776	14.48378
22.73133	292.4776	14.48372
22.83100	292.5768	14.48345
22.93100	292.6766	14.48312
23.03100	292.7781	14.48303
23.13117	292.8777	14.48273
23.23117	292.9788	14.48250
23.33117	293.0800	14.48229
23.43117	293.1796	14.48217
23.53117	293.2802	14.48192
23.63117	293.3794	14.48175
23.73117	293.4791	14.48137
23.83117	293.5788	14.48145
23.93100	293.6795	14.48120
24.03100	293.7801	14.48074
24.13100	293.8804	14.48048
24.23100	293.9808	14.48036
24.33117	294.0788	14.47999
24.43117	294.1761	14.47970
24.53117	294.2765	14.47951
24.63117	294.3752	14.47936
24.73117	294.4758	14.47925
24.83117	294.5770	14.47902
24.93117	294.6760	14.47886
25.03117	294.7760	14.47858
25.13117	294.8774	14.47829
25.23117	294.9775	14.47813
25.33117	295.0778	14.47776
25.43117	295.1763	14.47756
25.53117	295.2780	14.47737
25.63117	295.3785	14.47716
25.73117	295.4780	14.47701
25.83117	295.5777	14.47688
25.93116	295.6798	14.47690
26.03116	295.7794	14.47642
26.13117	295.8787	14.47622
26.23117	295.9775	14.47600
26.33117	296.0766	14.47574
26.43116	296.1760	14.47549
26.53116	296.2762	14.47522
26.63117	296.3780	14.47512
26.73117	296.4780	14.47490
26.83117	296.5766	14.47461
26.93284	296.6780	14.47441
27.03284	296.7781	14.47415
27.13617	296.8824	14.47399
27.23700	296.9832	14.47380
27.33783	297.0850	14.47377
27.43950	297.1870	14.47347
27.53950	297.2854	14.47328
27.64117	297.3864	14.47296
27.74284	297.4868	14.47286
27.84434	297.5910	14.47263
27.94600	297.6924	14.47244
28.04600	297.7932	14.47201
28.14600	297.8924	14.47206
28.24600	297.9944	14.47179
28.34600	298.0940	14.47146
28.44600	298.1948	14.47151
28.54600	298.2964	14.47114
28.64600	298.3955	14.47075
28.74600	298.4958	14.47079
28.84600	298.5940	14.47059
28.94633	298.6944	14.47042
29.04633	298.7936	14.47013
29.14634	298.8932	14.46994
29.24617	298.9924	14.46976
29.34617	299.0912	14.46951
29.44617	299.1909	14.46941
29.54617	299.2893	14.46921
29.64617	299.3893	14.46890
29.74617	299.4890	14.46870
29.84617	299.5902	14.46827
29.94633	299.6912	14.46811
30.04633	299.7916	14.46797
30.14617	299.8932	14.46779
30.24617	299.9922	14.46742
30.34617	300.0920	14.46719
30.44617	300.1899	14.46691
30.54617	300.2955	14.46709
30.64600	300.3964	14.46659
30.74634	300.4947	14.46654
30.84800	300.5950	14.46622
30.94867	300.6950	14.46584
31.04950	300.7985	14.46566
31.15284	300.8985	14.46550
31.25283	300.9982	14.46532
31.35450	301.1013	14.46511
31.45516	301.2022	14.46500
31.55633	301.3066	14.46491
31.65800	301.4068	14.46438
31.75784	301.5052	14.46404
31.86117	301.6074	14.46365
31.96117	301.7069	14.46350
32.06116	301.8059	14.46324
32.16117	301.9067	14.46298
32.26100	302.0064	14.46286
32.36133	302.1075	14.46272
32.46133	302.2076	14.46243
32.56133	302.3094	14.46252
32.66117	302.4109	14.46202
32.76117	302.5096	14.46186
32.86117	302.6091	14.46159
32.96117	302.7094	14.46149
33.06133	302.8070	14.46106
33.16133	302.9074	14.46079
33.26117	303.0042	14.46057
33.36117	303.1041	14.46029
33.46117	303.2045	14.46010
33.56116	303.3062	14.45995
33.66133	303.4068	14.45976
33.76133	303.5085	14.45961
33.86117	303.6069	14.45922
33.96117	303.7076	14.45907
34.06116	303.8084	14.45889
34.16117	303.9094	14.45861
34.26117	304.0080	14.45843
34.36117	304.1087	14.45796
34.46100	304.2079	14.45785
34.56100	304.3082	14.45752
34.66184	304.4080	14.45751
34.76300	304.5108	14.45739
34.86467	304.6116	14.45692
34.96467	304.7107	14.45656
35.06633	304.8125	14.45640
35.16783	304.9128	14.45601
35.26950	305.0154	14.45581
35.37117	305.1160	14.45555
35.47117	305.2165	14.45536
35.57100	305.3174	14.45521
35.67133	305.4164	14.45487
35.77133	305.5152	14.45454
35.87117	305.6160	14.45421
35.97117	305.7165	14.45398
36.07117	305.8159	14.45392
36.17117	305.9180	14.45365
36.27117	306.0164	14.45352
36.37117	306.1154	14.45324
36.47117	306.2154	14.45309
36.57117	306.3161	14.45291
36.67117	306.4166	14.45266
36.77117	306.5167	14.45239
36.87117	306.6181	14.45218
36.97100	306.7180	14.45196
37.07100	306.8183	14.45186
37.17133	306.9180	14.45144
37.27133	307.0182	14.45126
37.37117	307.1180	14.45105
37.47117	307.2178	14.45080
37.57117	307.3180	14.45060
37.67117	307.4185	14.45036
37.77117	307.5178	14.45014
37.87117	307.6162	14.44993
37.97117	307.7165	14.44980
38.07117	307.8171	14.44951
38.17100	307.9164	14.44922
38.27133	308.0168	14.44907
38.37134	308.1162	14.44890
38.47133	308.2168	14.44880
38.57117	308.3172	14.44856
38.67117	308.4171	14.44830
38.77117	308.5158	14.44808
38.87117	308.6166	14.44784
38.97117	308.7168	14.44756
39.07117	308.8178	14.44731
39.17117	308.9173	14.44713
39.27100	309.0183	14.44696
39.37134	309.1190	14.44669
39.47133	309.2186	14.44660
39.57134	309.3196	14.44638
39.67133	309.4180	14.44622
39.77117	309.5184	14.44601
39.87117	309.6182	14.44569
39.97117	309.7195	14.44558
40.07117	309.8200	14.44542
40.17117	309.9223	14.44516
40.27117	310.0192	14.44492
40.37117	310.1175	14.44464
40.47117	310.2166	14.44458
40.57117	310.3165	14.44434
40.67117	310.4172	14.44423
40.77117	310.5174	14.44383
40.87100	310.6158	14.44352
40.97100	310.7140	14.44313
41.07133	310.8148	14.44292
41.17133	310.9155	14.44263
41.27133	311.0139	14.44241
41.37133	311.1148	14.44220
41.47133	311.2134	14.44216
41.57133	311.3125	14.44184
41.67133	311.4137	14.44177
41.77100	311.5160	14.44144
41.87133	311.6138	14.44128
41.97133	311.7148	14.44110
42.07133	311.8160	14.44104
42.17133	311.9180	14.44095
42.27133	312.0183	14.44047
42.37117	312.1189	14.44026
42.47117	312.2185	14.44019
42.57117	312.3186	14.44020
42.67117	312.4194	14.44012
42.77117	312.5200	14.43995
42.87117	312.6192	14.43970
42.97117	312.7189	14.43975
43.07117	312.8180	14.43965
43.17117	312.9181	14.43925
43.27117	313.0173	14.43914
43.37117	313.1182	14.43900
43.47117	313.2182	14.43890
43.57117	313.3193	14.43910
43.67283	313.4206	14.43880
43.77383	313.5218	14.43864
43.87467	313.6208	14.43830
43.97800	313.7203	14.43802
44.07800	313.8245	14.43806
44.17967	313.9222	14.43772
44.28050	314.0240	14.43766
44.38133	314.1238	14.43739
44.48283	314.2262	14.43717
44.58283	314.3271	14.43700
44.68616	314.4320	14.43676
44.78700	314.5332	14.43664
44.88783	314.6360	14.43644
44.98950	314.7378	14.43639
45.08933	314.8388	14.43610
45.19100	314.9393	14.43594
45.29300	315.0425	14.43592
45.39467	315.1444	14.43590
45.49633	315.2470	14.43582
45.59633	315.3470	14.43566
45.69783	315.4465	14.43518
45.79867	315.5466	14.43499
45.89950	315.6473	14.43500
45.99950	315.7486	14.43498
46.09950	315.8459	14.43478
46.19950	315.9463	14.43464
46.29950	316.0446	14.43433
46.39950	316.1415	14.43396
46.49950	316.2436	14.43389
46.59950	316.3440	14.43365
46.69950	316.4455	14.43357
46.79933	316.5459	14.43366
46.89934	316.6446	14.43339
46.99967	316.7450	14.43309
47.09967	316.8450	14.43310
47.19966	316.9422	14.43259
47.29950	317.0475	14.43292
47.39950	317.1441	14.43258
47.49950	317.2436	14.43222
47.59950	317.3436	14.43213
47.69950	317.4482	14.43244
47.79950	317.5450	14.43199
47.89950	317.6440	14.43185
47.99950	317.7438	14.43169
48.09950	317.8445	14.43134
48.19950	317.9458	14.43131
48.29933	318.0455	14.43086
48.39966	318.1471	14.43112
48.49967	318.2470	14.43072
48.59950	318.3461	14.43050
48.70284	318.4485	14.43030
48.80283	318.5495	14.43026
48.90450	318.6503	14.43019
49.00533	318.7518	14.42988
49.10617	318.8524	14.42979
49.20783	318.9536	14.42947
49.30783	319.0549	14.42931
49.41117	319.1584	14.42930
49.51200	319.2575	14.42898
49.61266	319.3596	14.42892
49.71266	319.4602	14.42881
49.81300	319.5603	14.42860
49.91300	319.6605	14.42841
50.01300	319.7600	14.42823
50.11300	319.8610	14.42812
50.21283	319.9606	14.42782
50.31283	320.0591	14.42749
50.41284	320.1594	14.42729
50.51283	320.2604	14.42721
50.61284	320.3572	14.42706
50.71266	320.4611	14.42694
50.81266	320.5602	14.42679
50.91300	320.6609	14.42674
51.01300	320.7612	14.42666
51.11300	320.8608	14.42644
51.21300	320.9606	14.42618
51.31300	321.0596	14.42589
51.41300	321.1608	14.42572
51.51283	321.2614	14.42561
51.61284	321.3585	14.42548
51.71284	321.4568	14.42524
51.81300	321.5576	14.42512
51.91300	321.6580	14.42494
52.01300	321.7572	14.42457
52.11300	321.8573	14.42440
52.21300	321.9598	14.42423
52.31300	322.0593	14.42411
52.41467	322.1611	14.42398
52.51467	322.2605	14.42372
52.61633	322.3608	14.42348
52.71800	322.4612	14.42327
52.81967	322.5632	14.42302
52.92133	322.6624	14.42284
53.02100	322.7646	14.42274
53.12266	322.8669	14.42250
53.22350	322.9678	14.42237
53.32434	323.0692	14.42223
53.42432	323.1715	14.42210
53.52466	323.2726	14.42192
53.62467	323.3722	14.42179
53.72450	323.4717	14.42151
53.82450	323.5724	14.42124
53.92450	323.6721	14.42095
54.02450	323.7694	14.42084
54.12450	323.8707	14.42075
54.22450	323.9706	14.42062
54.32450	324.0716	14.42036
54.42450	324.1716	14.42018
54.52450	324.2718	14.41992
54.62450	324.3734	14.41981
54.72450	324.4717	14.41974
54.82450	324.5706	14.41962
54.92450	324.6719	14.41943
55.02450	324.7714	14.41911
55.12450	324.8694	14.41897
55.22466	324.9686	14.41868
55.32466	325.0700	14.41864
55.42450	325.1703	14.41849
55.52450	325.2690	14.41831
55.62450	325.3670	14.41798
55.72450	325.4694	14.41772
55.82450	325.5680	14.41755
55.92450	325.6692	14.41758
56.02450	325.7680	14.41718
56.12800	325.8736	14.41704
56.22800	325.9748	14.41688
56.32934	326.0772	14.41663
56.42950	326.1777	14.41665
56.52950	326.2799	14.41628
56.62950	326.3790	14.41632
56.72950	326.4794	14.41600
56.82966	326.5753	14.41570
56.92967	326.6757	14.41554
57.02934	326.7776	14.41545
57.12950	326.8761	14.41529
57.22950	326.9759	14.41521
57.32950	327.0763	14.41514
57.42950	327.1770	14.41511
57.52967	327.2777	14.41470
57.62966	327.3778	14.41456
57.72967	327.4765	14.41439
57.82950	327.5750	14.41416
57.92950	327.6754	14.41392
58.02950	327.7750	14.41373
58.12950	327.8750	14.41351
58.22950	327.9748	14.41329
58.32966	328.0761	14.41315
58.42967	328.1748	14.41301
58.52934	328.2740	14.41288
58.62950	328.3750	14.41254
58.72950	328.4749	14.41224
58.82950	328.5752	14.41233
58.92950	328.6756	14.41219
59.02950	328.7757	14.41178
59.13033	328.8754	14.41166
59.23116	328.9744	14.41147
59.33300	329.0795	14.41142
59.43300	329.1788	14.41116
59.53633	329.2815	14.41098
59.63700	329.3832	14.41080
59.73784	329.4844	14.41080
59.83950	329.5858	14.41044
59.93950	329.6859	14.41022
60.04133	329.7865	14.41016
60.14300	329.8883	14.40987
60.24467	329.9883	14.40965
60.34600	330.0894	14.40937
60.44617	330.1908	14.40924
60.54783	330.2929	14.40910
60.64868	330.3935	14.40894
60.74950	330.4953	14.40857
60.85283	330.5997	14.40844
60.95300	330.6968	14.40814
61.05434	330.8015	14.40820
61.15533	330.9004	14.40795
61.25618	331.0012	14.40775
61.35784	331.1030	14.40759
61.45783	331.2044	14.40742
61.56133	331.3078	14.40696
61.66184	331.4094	14.40683
61.76283	331.5080	14.40662
61.86450	331.6113	14.40639
61.96450	331.7108	14.40621
62.06633	331.8115	14.40601
62.16768	331.9126	14.40579
62.26950	332.0160	14.40558
62.37117	332.1186	14.40530
62.47117	332.2186	14.40510
62.57300	332.3206	14.40490
62.67350	332.4206	14.40484
62.77450	332.5208	14.40458
62.87783	332.6238	14.40433
62.97800	332.7210	14.40394
63.07966	332.8247	14.40404
63.17950	332.9250	14.40376
63.27950	333.0269	14.40354
63.37950	333.1248	14.40326
63.47967	333.2254	14.40304
63.57966	333.3260	14.40282
63.67950	333.4256	14.40252
63.77950	333.5264	14.40243
63.87950	333.6244	14.40199
63.97950	333.7246	14.40184
64.07966	333.8253	14.40170
64.17934	333.9258	14.40148
64.27950	334.0252	14.40144
64.37950	334.1252	14.40112
64.47950	334.2261	14.40077
64.57966	334.3263	14.40084
64.67934	334.4248	14.40056
64.77950	334.5250	14.40037
64.87950	334.6248	14.39992
64.97967	334.7256	14.39971
65.07966	334.8263	14.39960
65.17950	334.9262	14.39933
65.27950	335.0266	14.39912
65.37950	335.1279	14.39904
65.47950	335.2301	14.39913
65.57950	335.3295	14.39854
65.67966	335.4262	14.39818
65.77966	335.5267	14.39797
65.88032	335.6258	14.39771
65.98116	335.7264	14.39751
66.08282	335.8276	14.39730
66.18282	335.9272	14.39711
66.28632	336.0300	14.39683
66.38718	336.1304	14.39661
66.48782	336.2316	14.39621
66.58950	336.3334	14.39613
66.68950	336.4348	14.39584
66.79134	336.5341	14.39552
66.89300	336.6365	14.39531
66.99450	336.7378	14.39495
67.09616	336.8414	14.39482
67.19616	336.9424	14.39470
67.29784	337.0460	14.39447
67.39868	337.1462	14.39428
67.49966	337.2480	14.39407
67.60266	337.3516	14.39386
67.70282	337.4511	14.39353
67.80450	337.5522	14.39306
67.90532	337.6528	14.39270
68.00634	337.7525	14.39238
68.10766	337.8550	14.39214
68.20782	337.9544	14.39216
68.30950	338.0564	14.39219
68.41132	338.1606	14.39171
68.51266	338.2591	14.39156
68.61450	338.3608	14.39151
68.71450	338.4620	14.39056
68.81634	338.5597	14.39019
68.91766	338.6603	14.38996
69.01950	338.7624	14.38948
69.12116	338.8637	14.38932
69.22134	338.9658	14.38906
69.32266	339.0668	14.38872
69.42284	339.1660	14.38841
69.52282	339.2653	14.38830
69.62300	339.3662	14.38805
69.72282	339.4654	14.38792
69.82282	339.5663	14.38737
69.92300	339.6682	14.38741
70.02282	339.7682	14.38671
70.12282	339.8692	14.38651
70.22282	339.9671	14.38599
70.32300	340.0689	14.38564
70.42300	340.1700	14.38569
70.52300	340.2705	14.38528
70.62266	340.3709	14.38499
70.72282	340.4684	14.38452
70.82282	340.5690	14.38428
70.92284	340.6694	14.38411
71.02282	340.7699	14.38384
71.12282	340.8679	14.38351
71.22282	340.9720	14.38333
71.32300	341.0697	14.38313
71.42300	341.1717	14.38284
71.52300	341.2720	14.38251
71.62266	341.3715	14.38217
71.72282	341.4708	14.38180
71.82282	341.5700	14.38141
71.92284	341.6703	14.38139
72.02282	341.7688	14.38102
72.12384	341.8691	14.38076
72.22468	341.9706	14.38060
72.32800	342.0747	14.38024
72.42800	342.1756	14.37974
72.52934	342.2761	14.37947
72.62950	342.3776	14.37931
72.72950	342.4765	14.37882
72.82950	342.5769	14.37841
72.92950	342.6764	14.37822
73.02966	342.7778	14.37792
73.12968	342.8774	14.37756
73.22968	342.9775	14.37718
73.32934	343.0758	14.36842
73.42934	343.1758	14.36594
73.52950	343.2764	14.36558
73.62950	343.3757	14.36543
73.72950	343.4762	14.36518
73.82950	343.5750	14.36489
73.92950	343.6736	14.36466
74.02950	343.7742	14.36436
74.12950	343.8740	14.36397
74.22950	343.9724	14.36365
74.32950	344.0729	14.36343
74.42950	344.1748	14.36321
74.52950	344.2742	14.36277
74.62950	344.3740	14.36260
74.72950	344.4761	14.36255
74.82950	344.5756	14.36189
74.92950	344.6744	14.36172
75.02950	344.7744	14.36144
75.12950	344.8742	14.36123
75.22968	344.9753	14.36086
75.33050	345.0766	14.36100
75.43134	345.1778	14.36147
75.53300	345.2824	14.36120
75.63284	345.3815	14.36080
75.73618	345.4852	14.36040
75.83700	345.5877	14.35986
75.93784	345.6882	14.35947
76.03950	345.7865	14.35903
76.13950	345.8876	14.35889
76.24116	345.9908	14.35855
76.34282	346.0922	14.35745
76.44450	346.1945	14.35210
76.54616	346.2957	14.35154
76.64616	346.3960	14.35121
76.74782	346.4948	14.35087
76.84866	346.5957	14.35060
76.94950	346.6950	14.35017
77.05282	346.7966	14.35010
77.15282	346.8975	14.34975
77.25450	347.0000	14.34945
77.35532	347.1000	14.34902
77.45600	347.2012	14.34866
77.55766	347.3041	14.34842
77.65784	347.4030	14.34818
77.76118	347.5062	14.34792
77.86200	347.6078	14.34738
77.96268	347.7102	14.34722
78.06432	347.8125	14.34694
78.16468	347.9134	14.34659
78.26634	348.0152	14.34646
78.36782	348.1169	14.34620
78.46950	348.2198	14.34598
78.57116	348.3232	14.34602
78.67116	348.4224	14.34556
78.77282	348.5244	14.34520
78.87366	348.6232	14.34496
78.97450	348.7242	14.34458
79.07616	348.8248	14.34436
79.17618	348.9231	14.34400
79.27950	349.0274	14.34365
79.38016	349.1266	14.34349
79.48100	349.2267	14.34314
79.58300	349.3284	14.34280
79.68300	349.4280	14.34239
79.78632	349.5318	14.34199
79.88700	349.6328	14.34176
79.98782	349.7328	14.34136
80.08950	349.8316	14.34076
80.18950	349.9346	14.34085
80.29116	350.0322	14.34036
80.39282	350.1376	14.34009
80.49432	350.2382	14.33969
80.59600	350.3395	14.33934
80.69634	350.4429	14.33911
80.79800	350.5430	14.33881
80.89884	350.6450	14.33840
80.99966	350.7458	14.33806
81.10300	350.8481	14.33766
81.20300	350.9487	14.33736
81.30466	351.0509	14.33709
81.40550	351.1509	14.33682
81.50634	351.2522	14.33656
81.60800	351.3535	14.33618
81.70800	351.4529	14.33589
81.81134	351.5548	14.33557
81.91218	351.6578	14.33530
82.01300	351.7582	14.33484
82.11468	351.8608	14.33457
82.21468	351.9631	14.33428
82.31618	352.0644	14.33392
82.41782	352.1618	14.33344
82.51950	352.2658	14.33317
82.62118	352.3692	14.33294
82.72118	352.4684	14.33274
82.82282	352.5684	14.33237
82.92368	352.6659	14.33198
83.02450	352.7668	14.33164
83.12782	352.8712	14.33125
83.22784	352.9729	14.33090
83.32950	353.0750	14.33057
83.43032	353.1766	14.33025
83.53116	353.2767	14.32988
83.63282	353.3782	14.32918
83.73282	353.4788	14.32899
83.83618	353.5848	14.32875
83.93700	353.6844	14.32806
84.03782	353.7860	14.32793
84.13950	353.8863	14.32755
84.23950	353.9871	14.32719
84.34116	354.0940	14.32690
84.44282	354.1906	14.32652
84.54450	354.2939	14.32612
84.64618	354.3946	14.32578
84.74618	354.4942	14.32531
84.84618	354.5944	14.32517
84.94618	354.6914	14.32476
85.04600	354.7903	14.32446
85.14601	354.8911	14.32407
85.24632	354.9910	14.32394
85.34634	355.0913	14.32343
85.44634	355.1906	14.32294
85.54632	355.2900	14.32272
85.64601	355.3903	14.32223
85.74618	355.4902	14.32178
85.84618	355.5912	14.32163
85.94618	355.6924	14.32111
86.04618	355.7908	14.32056
86.14618	355.8920	14.32033
86.24618	355.9900	14.31981
86.34618	356.0930	14.31948
86.44618	356.1912	14.31920
86.54632	356.2908	14.31876
86.64632	356.3909	14.31832
86.74632	356.4925	14.31810
86.84634	356.5906	14.31752
86.94600	356.6910	14.31727
87.04600	356.7912	14.31677
87.14618	356.8885	14.31627
87.24618	356.9887	14.31588
87.34618	357.0896	14.31546
87.44618	357.1888	14.31519
87.54784	357.2920	14.31470
87.64868	357.3922	14.31419
87.74950	357.4932	14.31392
87.85300	357.5955	14.31339
87.95301	357.6970	14.31310
88.05468	357.7991	14.31239
88.15516	357.9028	14.31233
88.25600	358.0042	14.31161
88.35766	358.1066	14.31122
88.45782	358.2060	14.31090
88.56116	358.3093	14.31038
88.66200	358.4105	14.30995
88.76282	358.5125	14.30952
88.86450	358.6109	14.30878
88.96450	358.7113	14.30852
89.06632	358.8105	14.30813
89.16800	358.9133	14.30762
89.26968	359.0155	14.30723
89.37132	359.1203	14.30694
89.47134	359.2192	14.30631
89.57266	359.3210	14.30597
89.67350	359.4210	14.30547
89.77432	359.5235	14.30487
89.87768	359.6248	14.30432
89.97766	359.7248	14.30391
90.07934	359.8268	14.30342
90.18016	359.9265	14.30295
90.28100	360.0281	14.30244
90.38100	360.1285	14.30196
90.48101	360.2297	14.30164
90.58118	360.3269	14.30110
90.68116	360.4268	14.30066
90.78116	360.5266	14.30034
90.88116	360.6274	14.29974
90.98116	360.7256	14.29912
91.08118	360.8252	14.29866
91.18116	360.9262	14.29840
91.28116	361.0265	14.29774
91.38116	361.1264	14.29721
91.48101	361.2259	14.29678
91.58100	361.3269	14.29622
91.68100	361.4244	14.29562
91.78100	361.5268	14.29532
91.88116	361.6254	14.29474
91.98116	361.7265	14.29428
92.08118	361.8261	14.29372
92.18116	361.9270	14.29334
92.28116	362.0278	14.29284
92.38116	362.1250	14.29211
92.48116	362.2259	14.29153
92.58118	362.3258	14.29105
92.68116	362.4268	14.29060
92.78134	362.5276	14.29012
92.88134	362.6309	14.28953
92.98116	362.7288	14.28893
93.08282	362.8307	14.28840
93.18282	362.9302	14.28788
93.28616	363.0332	14.28703
93.38700	363.1348	14.28659
93.48782	363.2356	14.28599
93.58950	363.3384	14.28562
93.68950	363.4373	14.28508
93.78949	363.5392	14.28444
93.88950	363.6385	14.28391
93.98950	363.7384	14.28333
94.08950	363.8396	14.28274
94.18950	363.9398	14.28205
94.28949	364.0414	14.28172
94.38950	364.1392	14.28108
94.48934	364.2392	14.28039
94.58934	364.3369	14.27964
94.68968	364.4384	14.27921
94.78968	364.5391	14.27848
94.88966	364.6386	14.27779
94.98968	364.7390	14.27713
95.08968	364.8392	14.27656
95.18950	364.9394	14.27594
95.28949	365.0376	14.27533
95.38950	365.1392	14.27479
95.48950	365.2378	14.27411
95.58950	365.3375	14.27349
95.68950	365.4362	14.27275
95.78949	365.5369	14.27212
95.88950	365.6363	14.27150
95.98950	365.7357	14.27075
96.08950	365.8352	14.27005
96.18950	365.9367	14.26944
96.28949	366.0366	14.26876
96.38950	366.1354	14.26843
96.49116	366.2369	14.26768
96.59282	366.3358	14.26675
96.69449	366.4385	14.26597
96.79618	366.5381	14.26548
96.89618	366.6393	14.26472
96.99601	366.7394	14.26393
97.09601	366.8386	14.26320
97.19634	366.9368	14.26230
97.29632	367.0449	14.26220
97.39632	367.1424	14.26112
97.49632	367.2478	14.26056
97.59634	367.3420	14.25973
97.69634	367.4424	14.25893
97.79618	367.5415	14.25806
97.89618	367.6411	14.25718
97.99618	367.7410	14.25623
98.09618	367.8413	14.25572
98.19618	367.9394	14.25476
98.29618	368.0450	14.25413
98.39601	368.1429	14.25325
98.49601	368.2410	14.25230
98.59634	368.3440	14.25147
98.69634	368.4434	14.25078
98.79632	368.5408	14.24983
98.89632	368.6416	14.24905
98.99618	368.7439	14.24836
99.09618	368.8430	14.24744
99.19618	368.9413	14.24646
99.29618	369.0416	14.24554
99.39618	369.1403	14.24472
99.49618	369.2418	14.24386
99.59618	369.3418	14.24302
99.69766	369.4450	14.24224
99.79884	369.5467	14.24127
99.89968	369.6467	14.24040
100.0028	369.7505	14.23944
100.1028	369.8492	14.23846
100.2045	369.9510	14.23736
100.3045	370.0513	14.23630
100.4043	370.1511	14.23521
100.5047	370.2526	14.23416
100.6047	370.3479	14.23292
100.7047	370.4511	14.23212
100.8045	370.5511	14.23125
100.9045	370.6508	14.22999
101.0045	370.7522	14.22896
101.1045	370.8530	14.22797
101.2045	370.9491	14.22684
101.3045	371.0511	14.22582
101.4045	371.1502	14.22481
101.5045	371.2478	14.22377
101.6045	371.3511	14.22272
101.7045	371.4502	14.22156
101.8045	371.5500	14.22045
101.9045	371.6518	14.21946
102.0045	371.7502	14.21826
102.1045	371.8507	14.21717
102.2045	371.9518	14.21604
102.3045	372.0500	14.21480
102.4045	372.1485	14.21362
102.5045	372.2507	14.21241
102.6045	372.3506	14.21133
102.7045	372.4496	14.21003
102.8045	372.5472	14.20869
102.9045	372.6478	14.20754
103.0053	372.7484	14.20620
103.1062	372.8516	14.20507
103.2078	372.9518	14.20374
103.3078	373.0520	14.20222
103.4112	373.1562	14.20083
103.5122	373.2568	14.19929
103.6130	373.3590	14.19787
103.7147	373.4616	14.19642
103.8147	373.5600	14.19511
103.9163	373.6626	14.19364
104.0180	373.7645	14.19206
104.1197	373.8676	14.19049
104.2213	373.9668	14.18787
104.3213	374.0680	14.18423
104.4230	374.1694	14.18257
104.5238	374.2710	14.18095
104.6247	374.3744	14.17912
104.7280	374.4758	14.17763
104.8280	374.5775	14.17622
104.9297	374.6776	14.17429
105.0305	374.7784	14.17249
105.1312	374.8808	14.17077
105.2328	374.9818	14.16909
105.3328	375.0796	14.16717
105.4362	375.1824	14.16516
105.5370	375.2821	14.16316
105.6378	375.3840	14.16130
105.7395	375.4858	14.15924
105.8395	375.5872	14.15702
105.9412	375.6894	14.15484
106.0428	375.7917	14.15262
106.1445	375.8931	14.15039
106.2462	375.9952	14.14829
106.3462	376.0939	14.14600
106.4478	376.1943	14.14366
106.5487	376.2937	14.14137
106.6495	376.3950	14.13876
106.7528	376.4994	14.13620
106.8528	376.5996	14.13372
106.9545	376.7019	14.13120
107.0553	376.8024	14.12848
107.1562	376.9024	14.12578
107.2578	377.0028	14.12304
107.3578	377.1017	14.12011
107.4612	377.2047	14.11692
107.5620	377.3046	14.11398
107.6628	377.4051	14.11097
107.7645	377.5089	14.10762
107.8645	377.6084	14.10408
107.9662	377.7090	14.10050
108.0662	377.8098	14.09680
108.1662	377.9117	14.09297
108.2660	378.0136	14.08866
108.3660	378.1150	14.06507
108.4663	378.2146	14.05795
108.5663	378.3131	14.05268
108.6663	378.4137	14.04688
108.7663	378.5142	14.04092
108.8662	378.6143	14.03404
108.9662	378.7145	14.02679
109.0662	378.8128	14.01909
109.1662	378.9118	14.01098
109.2662	379.0131	14.00198
109.3660	379.1111	13.99286
109.4663	379.2126	13.98322
109.5663	379.3118	13.97327
109.6662	379.4122	13.96300
109.7662	379.5122	13.95252
109.8662	379.6125	13.94192
109.9660	379.7116	13.93128
110.0663	379.8116	13.92038
110.1663	379.9116	13.90966
110.2662	380.0099	13.89927
110.3662	380.1105	13.88925
110.4662	380.2100	13.87905
110.5662	380.3098	13.86914
110.6662	380.4115	13.85950
110.7678	380.5126	13.84972
110.8693	380.6147	13.83982
110.9697	380.7148	13.83042
111.0697	380.8121	13.82110
111.1712	380.9163	13.81212
111.2720	381.0178	13.80342
111.3728	381.1195	13.79460
111.4745	381.2203	13.78536
111.5745	381.3195	13.77615
111.6776	381.4266	13.76643
111.7785	381.5250	13.75792
111.8797	381.6274	13.74945
111.9812	381.7287	13.74081
112.0812	381.8286	13.73242
112.1828	381.9300	13.72410
112.2845	382.0317	13.71528
112.3862	382.1344	13.70695
112.4876	382.2337	13.69848
112.5877	382.3341	13.68989
112.6897	382.4356	13.68142
112.7905	382.5367	13.67278
112.8913	382.6372	13.66458
112.9945	382.7397	13.65583
113.0945	382.8378	13.64763
113.1962	382.9407	13.63931
113.2970	383.0395	13.63119
113.3978	383.1435	13.62342
113.4995	383.2433	13.61564
113.5996	383.3422	13.60789
113.7030	383.4464	13.59962
113.8038	383.5463	13.59236
113.9047	383.6488	13.58536
114.0063	383.7495	13.57878
114.1063	383.8490	13.57266
114.2080	383.9518	13.56688
114.3097	384.0536	13.56132
114.4110	384.1556	13.55609
114.5128	384.2569	13.55159
114.6128	384.3570	13.54726
114.7145	384.4590	13.54328
114.8153	384.5606	13.53956
114.9162	384.6622	13.53635
115.0178	384.7650	13.53315
115.1178	384.8644	13.53041
115.2212	384.9690	13.52764
115.3218	385.0684	13.52521
115.4230	385.1736	13.52320
115.5247	385.2738	13.52128
115.6246	385.3713	13.51950
115.7277	385.4756	13.51793
115.8287	385.5747	13.51642
115.9295	385.6750	13.51507
116.0312	385.7730	13.51402
116.1312	385.8743	13.51308
116.2328	385.9756	13.51238
116.3347	386.0774	13.51134
116.4363	386.1789	13.51050
116.5380	386.2830	13.50994
116.6377	386.3841	13.50940
116.7395	386.4844	13.50876
116.8403	386.5878	13.50835
116.9412	386.6878	13.50789
117.0428	386.7909	13.50734
117.1428	386.8912	13.50688
117.2462	386.9954	13.50638
117.3470	387.0956	13.50603
117.4478	387.1956	13.50554
117.5495	387.2986	13.50522
117.6497	387.3985	13.50492
117.7530	387.4992	13.50456
117.8538	387.6010	13.50433
117.9543	387.7010	13.50428
118.0543	387.7986	13.50395
118.1547	387.9006	13.50361
118.2547	388.0015	13.50347
118.3547	388.1003	13.50315
118.4543	388.2004	13.50295
118.5543	388.3016	13.50276
118.6545	388.3992	13.50247
118.7545	388.5010	13.50242
118.8545	388.5984	13.50212
118.9545	388.6981	13.50183
119.0545	388.7965	13.50171
119.1547	388.9009	13.50164
119.2547	389.0027	13.50129
119.3547	389.1039	13.50138
119.4543	389.2026	13.50116
119.5543	389.3012	13.50092
119.6545	389.4010	13.50085
119.7545	389.4974	13.50061
119.8545	389.6010	13.50060
119.9545	389.7002	13.50055
120.0545	389.7998	13.50038
120.1547	389.9023	13.50018
120.2547	390.0030	13.50002
120.3547	390.1028	13.49988
120.4543	390.2014	13.49996
120.5543	390.3015	13.49973
120.6545	390.4010	13.49960
120.7562	390.5035	13.49950
120.8562	390.6011	13.49944
120.9578	390.7041	13.49913
121.0597	390.8032	13.49913
121.1613	390.9072	13.49918
121.2627	391.0062	13.49887
121.3628	391.1094	13.49892
121.4628	391.2093	13.49901
121.5628	391.3088	13.49892
121.6628	391.4080	13.49884
121.7630	391.5085	13.49872
121.8630	391.6092	13.49883
121.9630	391.7100	13.49854
122.0630	391.8120	13.49858
122.1630	391.9100	13.49847
122.2630	392.0106	13.49843
122.3626	392.1094	13.49827
122.4627	392.2122	13.49846
122.5628	392.3125	13.49834
122.6628	392.4123	13.49826
122.7628	392.5134	13.49818
122.8628	392.6130	13.49816
122.9628	392.7112	13.49806
123.0628	392.8126	13.49811
123.1628	392.9105	13.49806
123.2628	393.0110	13.49802
123.3630	393.1100	13.49792
123.4630	393.2091	13.49783
123.5627	393.3081	13.49775
123.6627	393.4072	13.49775
123.7628	393.5075	13.49778
123.8628	393.6067	13.49770
123.9628	393.7075	13.49759
124.0628	393.8068	13.49750
124.1645	393.9080	13.49741
124.2653	394.0088	13.49735
124.3663	394.1095	13.49731
124.4697	394.2136	13.49739
124.5695	394.3134	13.49731
124.6712	394.4164	13.49724
124.7720	394.5170	13.49724
124.8728	394.6182	13.49724
124.9746	394.7212	13.49738
125.0743	394.8200	13.49713
125.1778	394.9248	13.49714
125.2787	395.0250	13.49710
125.3795	395.1253	13.49705
125.4813	395.2254	13.49697
125.5812	395.3248	13.49684
125.6828	395.4270	13.49682
125.7845	395.5294	13.49682
125.8863	395.6310	13.49689
125.9876	395.7321	13.49684
126.0878	395.8342	13.49684
126.1895	395.9348	13.49697
126.2905	396.0370	13.49692
126.3910	396.1375	13.49692
126.4912	396.2380	13.49680
126.5912	396.3377	13.49675
126.6913	396.4362	13.49674
126.7912	396.5357	13.49664
126.8912	396.6362	13.49668
126.9912	396.7390	13.49662
127.0913	396.8386	13.49669
127.1910	396.9378	13.49655
127.2912	397.0380	13.49645
127.3912	397.1400	13.49644
127.4912	397.2400	13.49649
127.5912	397.3390	13.49644
127.6913	397.4397	13.49643
127.7913	397.5379	13.49624
127.8910	397.6375	13.49618
127.9912	397.7385	13.49622
128.0912	397.8394	13.49623
128.1912	397.9402	13.49618
128.2913	398.0398	13.49611
128.3910	398.1400	13.49612
128.4912	398.2406	13.49602
128.5912	398.3389	13.49602
128.6912	398.4395	13.49604
128.7913	398.5389	13.49617
128.8912	398.6390	13.49621
128.9912	398.7371	13.49611
129.0912	398.8365	13.49597
129.1947	398.9394	13.49591
129.2945	399.0400	13.49587
129.3962	399.1436	13.49595
129.4970	399.2448	13.49589
129.5980	399.3448	13.49593
129.6995	399.4458	13.49595
129.7995	399.5454	13.49595
129.9028	399.6490	13.49576
129.9362	399.6824	13.49585