File: TGA/2023_07_12_CBD_powder_1cpm_2.txt
CLOSED
Version	0.4
Run	874
Instrument	2950 TGA       V5.4A
Module	TGA 1000 øC
Sample	2023_07_12_CBD_powder_1cpm_2
Size	11.4910	mg
Method	25C to 300C at 1 cpm
Operator	SBK
Comment	2023_07_12_CBD_powder_1cpm_2
Xcomment	Pan: Platinum           Gas1: Nitrogen  40          Gas2: Nitrogen  40
Text	2023_07_12_CBD_powder_1cpm_2
Text	Second run with CBD powder after new calib
Kcell	1.00000
TempCal	2	pts	156.68	152.50,	376.53	354.00
Thresholds	0.050	0.0000
Controls	Gas 1  Event Off  Sampling 2.0 sec/pt
Nsig	3
Sig1	Time (min)
Sig2	Temperature (øC)
Sig3	Weight (mg)
Date	12-Jul-23
Time	17:23
File	C:\TA\Data\TGA\Skyler\2023_07_12_CBD_powder_1cpm_2.001
OrgFile	C:\TA\Data\TGA\Skyler\2023_07_12_CBD_powder_1cpm_2.001
StartOfData
0.0000000	25.16592	11.48849
0.1995000	25.25388	11.48845
0.3996667	25.39577	11.48846
0.5996666	25.56676	11.48837
0.7995000	25.74895	11.48806
0.9995000	25.93946	11.48807
1.199666	26.13421	11.48789
1.399500	26.33435	11.48772
1.599500	26.53182	11.48764
1.799334	26.73072	11.48740
2.000500	26.93230	11.48734
2.202834	27.13452	11.48719
2.406166	27.33525	11.48711
2.607834	27.53799	11.48703
2.809500	27.73796	11.48682
3.011167	27.94309	11.48668
3.211167	28.13885	11.48654
3.411334	28.34002	11.48636
3.611334	28.53758	11.48639
3.811334	28.74197	11.48621
4.011166	28.94317	11.48618
4.211166	29.14372	11.48610
4.411166	29.34441	11.48602
4.611000	29.54385	11.48576
4.811333	29.74487	11.48577
5.011166	29.94560	11.48560
5.211167	30.14132	11.48555
5.411168	30.34373	11.48542
5.611166	30.54314	11.48535
5.814500	30.74507	11.48527
6.016332	30.94512	11.48530
6.218834	31.14825	11.48525
6.422832	31.35305	11.48506
6.624500	31.55213	11.48515
6.826166	31.75537	11.48505
7.027832	31.95474	11.48488
7.232168	32.16081	11.48471
7.434668	32.36697	11.48450
7.636166	32.56988	11.48458
7.839500	32.77050	11.48444
8.041168	32.97518	11.48422
8.242668	33.17820	11.48415
8.443000	33.37806	11.48411
8.642834	33.57748	11.48398
8.842834	33.77630	11.48392
9.042832	33.97665	11.48385
9.242668	34.17507	11.48378
9.443000	34.36986	11.48375
9.642834	34.57065	11.48366
9.842834	34.77293	11.48350
10.04283	34.96752	11.48337
10.24283	35.16854	11.48331
10.44283	35.37317	11.48319
10.64266	35.57415	11.48310
10.84266	35.77528	11.48310
11.04450	35.97409	11.48304
11.24434	36.16988	11.48293
11.44467	36.36806	11.48294
11.64467	36.56543	11.48280
11.84467	36.76852	11.48286
12.04467	36.97120	11.48266
12.24450	37.17068	11.48266
12.44450	37.36436	11.48268
12.64450	37.56730	11.48259
12.84450	37.76408	11.48236
13.04450	37.95975	11.48232
13.24450	38.16226	11.48225
13.44467	38.36438	11.48219
13.64467	38.56534	11.48206
13.84783	38.77125	11.48193
14.04950	38.97406	11.48199
14.25116	39.17298	11.48189
14.45283	39.37509	11.48186
14.65267	39.57684	11.48182
14.85300	39.77312	11.48168
15.05300	39.97492	11.48175
15.25283	40.17466	11.48160
15.45283	40.37495	11.48159
15.65283	40.57233	11.48145
15.85267	40.77256	11.48140
16.05300	40.97231	11.48127
16.25300	41.17291	11.48120
16.45284	41.37416	11.48106
16.65284	41.57378	11.48100
16.85267	41.77234	11.48110
17.05300	41.96972	11.48110
17.25616	42.16992	11.48111
17.45784	42.37187	11.48097
17.65950	42.57611	11.48100
17.86117	42.77954	11.48072
18.06117	42.98138	11.48079
18.26117	43.18201	11.48079
18.46117	43.38158	11.48082
18.66117	43.58430	11.48065
18.86117	43.77924	11.48053
19.06100	43.97598	11.48031
19.26134	44.17736	11.48049
19.46117	44.37685	11.48038
19.66117	44.57290	11.48027
19.86117	44.77224	11.48024
20.06117	44.97010	11.48014
20.26117	45.17556	11.48009
20.46117	45.37828	11.48009
20.66117	45.58111	11.47991
20.86100	45.78054	11.47990
21.06133	45.97838	11.47986
21.26133	46.18148	11.47987
21.46117	46.38262	11.47981
21.66117	46.57728	11.47973
21.86117	46.77558	11.47955
22.06117	46.97519	11.47954
22.26117	47.16980	11.47945
22.46133	47.37242	11.47949
22.66117	47.57190	11.47940
22.86117	47.77109	11.47933
23.06100	47.96806	11.47934
23.26300	48.16623	11.47935
23.46617	48.36813	11.47931
23.66783	48.57244	11.47937
23.86950	48.77178	11.47923
24.07283	48.97235	11.47909
24.27533	49.17648	11.47914
24.47783	49.37722	11.47905
24.67784	49.58271	11.47896
24.87783	49.79033	11.47879
25.07784	49.99300	11.47886
25.27784	50.19216	11.47880
25.47800	50.40020	11.47892
25.67800	50.59994	11.47876
25.87783	50.79250	11.47877
26.07783	50.99102	11.47867
26.27784	51.18472	11.47858
26.47800	51.37913	11.47853
26.67783	51.57910	11.47847
26.87783	51.78052	11.47839
27.07783	51.98078	11.47838
27.27784	52.18025	11.47830
27.48216	52.39272	11.47830
27.68467	52.59821	11.47830
27.88633	52.80218	11.47825
28.08967	53.00630	11.47818
28.29133	53.21390	11.47822
28.49383	53.42004	11.47827
28.69800	53.62394	11.47824
28.89934	53.81762	11.47823
29.09950	54.01465	11.47812
29.29950	54.21282	11.47809
29.49950	54.40938	11.47790
29.69950	54.60439	11.47793
29.89966	54.80245	11.47795
30.09967	54.99788	11.47792
30.29967	55.20282	11.47786
30.49950	55.40949	11.47788
30.69950	55.60966	11.47778
30.89950	55.80880	11.47774
31.09950	56.01018	11.47767
31.29950	56.21006	11.47759
31.49950	56.41170	11.47757
31.70033	56.61410	11.47757
31.90284	56.80990	11.47749
32.10617	57.00354	11.47745
32.30784	57.20010	11.47733
32.50967	57.40500	11.47727
32.71266	57.61479	11.47734
32.91617	57.82694	11.47720
33.11616	58.03048	11.47714
33.31616	58.23408	11.47708
33.51617	58.43376	11.47704
33.71617	58.63256	11.47710
33.91617	58.83190	11.47720
34.11616	59.03871	11.47712
34.31616	59.23750	11.47698
34.51617	59.43918	11.47700
34.71617	59.63271	11.47692
34.91617	59.83322	11.47672
35.11633	60.03126	11.47673
35.31633	60.23548	11.47675
35.51600	60.43412	11.47660
35.71617	60.63350	11.47663
35.91617	60.83387	11.47662
36.11616	61.03718	11.47650
36.31616	61.23750	11.47649
36.51617	61.42864	11.47633
36.71617	61.62558	11.47642
36.91600	61.83094	11.47632
37.11633	62.02842	11.47626
37.31633	62.22426	11.47624
37.51633	62.42976	11.47616
37.71633	62.63244	11.47607
37.91633	62.82952	11.47599
38.11700	63.03024	11.47590
38.31950	63.22793	11.47594
38.52283	63.43484	11.47589
38.72450	63.63226	11.47574
38.92617	63.83686	11.47573
39.12950	64.04336	11.47570
39.33283	64.24055	11.47586
39.53433	64.44059	11.47584
39.73633	64.64488	11.47591
39.93933	64.84796	11.47591
40.14183	65.05434	11.47593
40.34450	65.25264	11.47600
40.54450	65.44793	11.47610
40.74450	65.65406	11.47618
40.94450	65.85129	11.47639
41.14467	66.05042	11.47634
41.34467	66.25428	11.47609
41.54434	66.45860	11.47593
41.74450	66.66515	11.47580
41.94450	66.86682	11.47581
42.14450	67.06568	11.47575
42.34467	67.26662	11.47574
42.54467	67.46894	11.47575
42.74467	67.66718	11.47564
42.94467	67.86248	11.47564
43.14450	68.05938	11.47556
43.34867	68.26211	11.47546
43.55117	68.46054	11.47542
43.75284	68.66207	11.47543
43.95616	68.86812	11.47534
44.15766	69.07090	11.47532
44.36016	69.27388	11.47522
44.56100	69.47412	11.47525
44.76117	69.67202	11.47520
44.96117	69.87743	11.47527
45.16117	70.07718	11.47526
45.36117	70.27585	11.47524
45.56116	70.47820	11.47512
45.76117	70.67996	11.47514
45.96117	70.87725	11.47500
46.16117	71.07969	11.47482
46.36117	71.28192	11.47482
46.56116	71.47889	11.47473
46.76117	71.67951	11.47474
46.96117	71.87916	11.47472
47.16117	72.07595	11.47462
47.36450	72.27796	11.47451
47.56700	72.48124	11.47448
47.76950	72.67603	11.47441
47.97283	72.87750	11.47445
48.17450	73.08047	11.47441
48.37634	73.28804	11.47426
48.57934	73.48968	11.47421
48.78283	73.69488	11.47411
48.98283	73.89204	11.47411
49.18283	74.09907	11.47405
49.38283	74.30069	11.47402
49.58300	74.49543	11.47404
49.78283	74.69201	11.47387
49.98283	74.89150	11.47389
50.18300	75.09049	11.47382
50.38266	75.29687	11.47385
50.58283	75.49389	11.47392
50.78283	75.69416	11.47375
50.98266	75.90156	11.47371
51.18283	76.10389	11.47369
51.38283	76.30089	11.47352
51.58450	76.50466	11.47353
51.78800	76.69562	11.47353
51.98950	76.89104	11.47339
52.18950	77.09036	11.47329
52.38967	77.29932	11.47336
52.58950	77.50988	11.47334
52.78950	77.71172	11.47331
52.98967	77.91212	11.47314
53.18950	78.11506	11.47309
53.38950	78.31554	11.47304
53.58950	78.51557	11.47315
53.78967	78.71501	11.47311
53.98950	78.90514	11.47280
54.18950	79.10180	11.47291
54.38967	79.29360	11.47289
54.59133	79.50186	11.47269
54.79283	79.70766	11.47276
54.99617	79.90374	11.47268
55.19966	80.11284	11.47258
55.39950	80.31410	11.47266
55.59950	80.51975	11.47240
55.79950	80.70776	11.47248
55.99967	80.91109	11.47244
56.19966	81.11391	11.47252
56.39950	81.31176	11.47233
56.59950	81.51036	11.47236
56.79950	81.72253	11.47225
56.99950	81.92488	11.47222
57.19966	82.12919	11.47213
57.39966	82.32535	11.47196
57.59934	82.52508	11.47197
57.79950	82.71972	11.47194
57.99950	82.91381	11.47186
58.20217	83.11118	11.47186
58.40634	83.32518	11.47173
58.60800	83.52545	11.47165
58.80933	83.72500	11.47164
59.01116	83.93006	11.47157
59.21533	84.13849	11.47147
59.41783	84.33863	11.47141
59.61967	84.53681	11.47132
59.82283	84.73960	11.47142
60.02450	84.93470	11.47132
60.22700	85.14156	11.47124
60.43132	85.34429	11.47115
60.63300	85.55051	11.47114
60.83450	85.74980	11.47098
61.03618	85.95207	11.47096
61.24033	86.16153	11.47085
61.44283	86.35938	11.47092
61.64450	86.56218	11.47101
61.84800	86.76379	11.47098
62.04967	86.97047	11.47087
62.25100	87.17005	11.47084
62.45117	87.36526	11.47075
62.65117	87.55753	11.47059
62.85117	87.75438	11.47058
63.05117	87.96259	11.47051
63.25134	88.16196	11.47044
63.45100	88.37211	11.47040
63.65117	88.57294	11.47031
63.85117	88.77285	11.47017
64.05118	88.97149	11.47014
64.25134	89.16894	11.47012
64.45132	89.37431	11.46994
64.65100	89.57544	11.46991
64.85117	89.77188	11.46985
65.05283	89.96803	11.46986
65.25616	90.16897	11.46970
65.45883	90.37108	11.46959
65.66132	90.57342	11.46953
65.86432	90.78722	11.46955
66.06616	90.99018	11.46939
66.26782	91.18898	11.46931
66.46782	91.39281	11.46929
66.66782	91.59212	11.46913
66.86782	91.79129	11.46907
67.06782	91.97828	11.46903
67.26782	92.17601	11.46897
67.46782	92.38269	11.46885
67.66800	92.58211	11.46884
67.86768	92.78312	11.46879
68.06782	92.98363	11.46863
68.26782	93.18361	11.46856
68.46800	93.38042	11.46844
68.66800	93.58422	11.46834
68.86950	93.79514	11.46810
69.07282	93.99975	11.46806
69.27450	94.20434	11.46803
69.47616	94.40418	11.46783
69.67950	94.60316	11.46777
69.88300	94.81209	11.46757
70.08466	95.01508	11.46740
70.28600	95.20489	11.46727
70.48950	95.41075	11.46717
70.69200	95.61464	11.46710
70.89468	95.81866	11.46702
71.09800	96.02180	11.46684
71.29932	96.22250	11.46670
71.49950	96.41656	11.46650
71.69950	96.61747	11.46655
71.89950	96.81610	11.46633
72.09968	97.01509	11.46613
72.29968	97.21608	11.46600
72.49934	97.41778	11.46586
72.69934	97.61218	11.46584
72.89950	97.81374	11.46594
73.09950	98.01718	11.46590
73.29950	98.21955	11.46566
73.49950	98.41793	11.46557
73.69950	98.61574	11.46537
73.89950	98.81359	11.46523
74.10132	99.01218	11.46498
74.30266	99.21371	11.46484
74.50282	99.41418	11.46477
74.70282	99.61636	11.46462
74.90300	99.81587	11.46443
75.10284	100.0154	11.46431
75.30282	100.2157	11.46420
75.50300	100.4139	11.46396
75.70282	100.6142	11.46375
75.90282	100.8143	11.46356
76.10300	101.0143	11.46339
76.30266	101.2131	11.46316
76.50282	101.4132	11.46296
76.70282	101.6154	11.46286
76.90282	101.8151	11.46263
77.10450	102.0194	11.46256
77.30800	102.2223	11.46232
77.50932	102.4232	11.46220
77.71118	102.6247	11.46194
77.91450	102.8302	11.46174
78.11700	103.0307	11.46156
78.31968	103.2330	11.46126
78.52300	103.4349	11.46126
78.72434	103.6359	11.46094
78.92450	103.8386	11.46086
79.12450	104.0393	11.46067
79.32450	104.2388	11.46047
79.52450	104.4380	11.46025
79.72450	104.6343	11.45997
79.92450	104.8326	11.45973
80.12450	105.0350	11.45945
80.32450	105.2386	11.45926
80.52450	105.4400	11.45904
80.72450	105.6396	11.45870
80.92450	105.8374	11.45844
81.12466	106.0340	11.45826
81.32450	106.2313	11.45789
81.52618	106.4337	11.45768
81.72784	106.6419	11.45737
81.93134	106.8475	11.45702
82.13300	107.0484	11.45680
82.33550	107.2532	11.45649
82.53968	107.4582	11.45630
82.74132	107.6599	11.45597
82.94266	107.8593	11.45567
83.14282	108.0582	11.45541
83.34282	108.2582	11.45493
83.54282	108.4545	11.45461
83.74282	108.6537	11.45444
83.94282	108.8500	11.45413
84.14282	109.0510	11.45392
84.34301	109.2544	11.45360
84.54300	109.4534	11.45327
84.74282	109.6537	11.45300
84.94282	109.8570	11.45266
85.14282	110.0594	11.45231
85.34301	110.2562	11.45192
85.54300	110.4531	11.45144
85.74450	110.6524	11.45115
85.94782	110.8545	11.45077
86.14950	111.0562	11.45048
86.35132	111.2608	11.45012
86.55434	111.4674	11.44971
86.75782	111.6720	11.44915
86.95782	111.8706	11.44890
87.15782	112.0711	11.44852
87.35782	112.2709	11.44806
87.55782	112.4718	11.44762
87.75782	112.6665	11.44717
87.95782	112.8678	11.44670
88.15800	113.0699	11.44626
88.35782	113.2735	11.44593
88.55782	113.4728	11.44537
88.75782	113.6698	11.44495
88.95782	113.8689	11.44456
89.15782	114.0706	11.44396
89.35800	114.2699	11.44350
89.55800	114.4673	11.44311
89.76032	114.6719	11.44272
89.96450	114.8764	11.44216
90.16449	115.0773	11.44170
90.36434	115.2810	11.44120
90.56434	115.4796	11.44064
90.76450	115.6792	11.43996
90.96434	115.8788	11.43931
91.16468	116.0779	11.43878
91.36450	116.2779	11.43831
91.56450	116.4791	11.43775
91.76450	116.6783	11.43722
91.96468	116.8787	11.43660
92.16449	117.0772	11.43605
92.36450	117.2775	11.43542
92.56450	117.4785	11.43478
92.76632	117.6817	11.43416
92.96866	117.8832	11.43359
93.17284	118.0864	11.43296
93.37468	118.2884	11.43230
93.57616	118.4877	11.43161
93.77782	118.6885	11.43101
93.97784	118.8902	11.43033
94.17801	119.0910	11.42971
94.37782	119.2908	11.42897
94.57782	119.4900	11.42830
94.77766	119.6906	11.42750
94.97800	119.8888	11.42684
95.17782	120.0916	11.42626
95.37782	120.2916	11.42554
95.57801	120.4934	11.42478
95.77782	120.6926	11.42396
95.97784	120.8922	11.42323
96.17782	121.0925	11.42247
96.37800	121.2934	11.42164
96.58118	121.4951	11.42072
96.78266	121.6959	11.41992
96.98468	121.8980	11.41910
97.18782	122.0997	11.41830
97.39100	122.3034	11.41727
97.59301	122.5050	11.41642
97.79450	122.7072	11.41552
97.99450	122.9062	11.41453
98.19449	123.1113	11.41367
98.39434	123.3097	11.41278
98.59468	123.5105	11.41184
98.79468	123.7054	11.41084
98.99450	123.9030	11.40988
99.19449	124.1018	11.40874
99.39434	124.3024	11.40784
99.59468	124.5060	11.40694
99.79450	124.7072	11.40583
99.99450	124.9072	11.40472
100.1943	125.1082	11.40367
100.3947	125.3063	11.40266
100.5978	125.5082	11.40164
100.7995	125.7078	11.40063
101.0012	125.9109	11.39942
101.2027	126.1174	11.39832
101.4072	126.3206	11.39715
101.6097	126.5226	11.39584
101.8112	126.7248	11.39471
102.0145	126.9281	11.39336
102.2162	127.1273	11.39208
102.4187	127.3334	11.39095
102.6228	127.5349	11.38953
102.8245	127.7310	11.38837
103.0262	127.9300	11.38707
103.2278	128.1319	11.38568
103.4322	128.3381	11.38420
103.6347	128.5462	11.38291
103.8363	128.7495	11.38158
104.0397	128.9537	11.38016
104.2413	129.1510	11.37866
104.4435	129.3505	11.37725
104.6477	129.5566	11.37566
104.8495	129.7612	11.37432
105.0495	129.9598	11.37276
105.2495	130.1619	11.37132
105.4495	130.3665	11.36981
105.6495	130.5672	11.36832
105.8495	130.7644	11.36676
106.0495	130.9619	11.36516
106.2495	131.1595	11.36356
106.4495	131.3622	11.36199
106.6495	131.5610	11.36025
106.8495	131.7502	11.35854
107.0495	131.9542	11.35690
107.2495	132.1606	11.35524
107.4495	132.3634	11.35330
107.6503	132.5641	11.35143
107.8528	132.7677	11.34976
108.0562	132.9697	11.34767
108.2578	133.1715	11.34582
108.4578	133.3719	11.34386
108.6578	133.5722	11.34212
108.8578	133.7727	11.34013
109.0578	133.9677	11.33820
109.2578	134.1626	11.33624
109.4578	134.3592	11.33428
109.6578	134.5596	11.33215
109.8578	134.7487	11.33023
110.0578	134.8862	11.32798
110.2580	135.0251	11.32598
110.4580	135.1940	11.32381
110.6578	135.3844	11.32160
110.8588	135.5936	11.31942
111.0613	135.8168	11.31721
111.2646	136.0483	11.31480
111.4663	136.2806	11.31251
111.6680	136.5058	11.31023
111.8713	136.7271	11.30777
112.0745	136.9467	11.30539
112.2762	137.1601	11.30304
112.4778	137.3710	11.30044
112.6812	137.5819	11.29778
112.8837	137.7930	11.29530
113.0862	138.0008	11.29269
113.2895	138.2044	11.28998
113.4895	138.4009	11.28726
113.6895	138.5988	11.28456
113.8895	138.8031	11.28188
114.0893	139.0029	11.27918
114.2896	139.1997	11.27640
114.4895	139.3975	11.27349
114.6895	139.5996	11.27057
114.8895	139.8016	11.26769
115.0895	140.0055	11.26476
115.2895	140.2016	11.26183
115.4895	140.3990	11.25882
115.6893	140.5956	11.25572
115.8896	140.7958	11.25257
116.0922	140.9972	11.24954
116.2947	141.1995	11.24633
116.4978	141.4032	11.24308
116.6995	141.6088	11.23969
116.9012	141.8112	11.23644
117.1045	142.0121	11.23303
117.3078	142.2116	11.22956
117.5093	142.4210	11.22614
117.7113	142.6229	11.22273
117.9146	142.8253	11.21914
118.1170	143.0286	11.21553
118.3195	143.2288	11.21186
118.5228	143.4333	11.20804
118.7243	143.6342	11.20431
118.9263	143.8338	11.20047
119.1297	144.0356	11.19672
119.3328	144.2408	11.19266
119.5345	144.4434	11.18880
119.7362	144.6441	11.18494
119.9395	144.8451	11.18080
120.1410	145.0475	11.17671
120.3413	145.2501	11.17265
120.5413	145.4478	11.16848
120.7412	145.6464	11.16431
120.9412	145.8466	11.15998
121.1412	146.0471	11.15562
121.3412	146.2496	11.15124
121.5412	146.4494	11.14678
121.7410	146.6505	11.14240
121.9413	146.8522	11.13787
122.1413	147.0514	11.13325
122.3412	147.2517	11.12853
122.5412	147.4478	11.12366
122.7412	147.6493	11.11901
122.9428	147.8485	11.11427
123.1447	148.0510	11.10948
123.3488	148.2575	11.10423
123.5512	148.4599	11.09921
123.7528	148.6629	11.09406
123.9530	148.8639	11.08896
124.1530	149.0609	11.08370
124.3528	149.2609	11.07841
124.5528	149.4612	11.07316
124.7528	149.6614	11.06776
124.9526	149.8600	11.06206
125.1530	150.0598	11.05663
125.3528	150.2592	11.05101
125.5528	150.4556	11.04518
125.7528	150.6557	11.03949
125.9526	150.8575	11.03350
126.1530	151.0588	11.02771
126.3530	151.2598	11.02163
126.5545	151.4628	11.01544
126.7578	151.6668	11.00925
126.9595	151.8691	11.00290
127.1595	152.0706	10.99671
127.3597	152.2684	10.99034
127.5597	152.4688	10.98389
127.7597	152.6663	10.97738
127.9597	152.8660	10.97064
128.1595	153.0687	10.96407
128.3595	153.2686	10.95738
128.5595	153.4649	10.95049
128.7595	153.6674	10.94345
128.9595	153.8681	10.93654
129.1595	154.0685	10.92943
129.3595	154.2651	10.92227
129.5595	154.4670	10.91501
129.7593	154.6683	10.90766
129.9597	154.8691	10.90015
130.1597	155.0686	10.89257
130.3597	155.2672	10.88487
130.5595	155.4678	10.87723
130.7595	155.6670	10.86945
130.9595	155.8672	10.86154
131.1593	156.0652	10.85343
131.3593	156.2675	10.84550
131.5597	156.4677	10.83728
131.7597	156.6670	10.82902
131.9597	156.8673	10.82057
132.1613	157.0688	10.81205
132.3645	157.2724	10.80302
132.5662	157.4735	10.79430
132.7678	157.6755	10.78548
132.9713	157.8778	10.77638
133.1747	158.0823	10.76723
133.3762	158.2854	10.75812
133.5780	158.4870	10.74886
133.7813	158.6907	10.73899
133.9835	158.8900	10.72968
134.1860	159.0920	10.72008
134.3896	159.2957	10.70993
134.5913	159.4984	10.70008
134.7930	159.6994	10.69011
134.9964	159.9042	10.67975
135.1995	160.1107	10.66929
135.4012	160.3102	10.65908
135.6030	160.5094	10.64852
135.8062	160.7131	10.63766
136.0087	160.9164	10.62697
136.2112	161.1188	10.61630
136.4112	161.3164	10.60530
136.6112	161.5159	10.59422
136.8110	161.7143	10.58296
137.0114	161.9158	10.57175
137.2112	162.1157	10.56026
137.4112	162.3173	10.54862
137.6112	162.5174	10.53699
137.8112	162.7163	10.52510
138.0112	162.9144	10.51295
138.2110	163.1142	10.50084
138.4110	163.3150	10.48871
138.6113	163.5166	10.47620
138.8112	163.7170	10.46361
139.0112	163.9183	10.45089
139.2145	164.1231	10.43748
139.4147	164.3233	10.42443
139.6145	164.5240	10.41134
139.8145	164.7236	10.39816
140.0145	164.9228	10.38458
140.2146	165.1211	10.37099
140.4145	165.3200	10.35725
140.6145	165.5252	10.34336
140.8145	165.7241	10.32928
141.0144	165.9199	10.31501
141.2145	166.1199	10.30061
141.4145	166.3182	10.28598
141.6145	166.5190	10.27118
141.8163	166.7201	10.25621
142.0178	166.9217	10.24109
142.2195	167.1242	10.22584
142.4228	167.3323	10.20988
142.6228	167.5300	10.19430
142.8228	167.7283	10.17850
143.0230	167.9289	10.16250
143.2228	168.1273	10.14640
143.4228	168.3279	10.13006
143.6227	168.5261	10.11340
143.8230	168.7252	10.09678
144.0228	168.9236	10.08000
144.2228	169.1218	10.06280
144.4228	169.3240	10.04546
144.6228	169.5247	10.02804
144.8226	169.7259	10.01039
145.0247	169.9294	9.992459
145.2262	170.1297	9.974499
145.4278	170.3331	9.956330
145.6277	170.5342	9.937762
145.8278	170.7359	9.919191
146.0278	170.9351	9.900269
146.2278	171.1368	9.881069
146.4277	171.3392	9.861691
146.6280	171.5375	9.842108
146.8278	171.7354	9.822532
147.0276	171.9359	9.802551
147.2278	172.1344	9.782410
147.4278	172.3366	9.761954
147.6280	172.5333	9.741304
147.8280	172.7330	9.720572
148.0278	172.9316	9.699500
148.2276	173.1334	9.678269
148.4280	173.3314	9.656742
148.6278	173.5323	9.635156
148.8278	173.7336	9.613219
149.0280	173.9332	9.591161
149.2278	174.1335	9.568818
149.4277	174.3327	9.546140
149.6278	174.5338	9.523314
149.8278	174.7346	9.500201
150.0278	174.9351	9.476840
150.2278	175.1340	9.453207
150.4280	175.3321	9.429334
150.6280	175.5312	9.405175
150.8278	175.7310	9.380844
151.0320	175.9353	9.355235
151.2345	176.1398	9.330391
151.4364	176.3435	9.305180
151.6395	176.5447	9.278657
151.8412	176.7470	9.252994
152.0437	176.9500	9.226913
152.2444	177.1505	9.200601
152.4447	177.3496	9.174066
152.6445	177.5487	9.147324
152.8445	177.7489	9.120184
153.0445	177.9504	9.092887
153.2446	178.1497	9.065226
153.4447	178.3500	9.037207
153.6445	178.5509	9.009069
153.8445	178.7495	8.980564
154.0445	178.9490	8.951681
154.2444	179.1500	8.922742
154.4447	179.3500	8.893261
154.6447	179.5500	8.863639
154.8445	179.7500	8.833728
155.0478	179.9530	8.802064
155.2504	180.1529	8.771418
155.4528	180.3552	8.740451
155.6560	180.5592	8.707837
155.8577	180.7609	8.676239
156.0577	180.9625	8.644351
156.2580	181.1627	8.612141
156.4580	181.3611	8.579640
156.6580	181.5635	8.546837
156.8580	181.7632	8.513504
157.0578	181.9661	8.480014
157.2578	182.1656	8.446100
157.4578	182.3652	8.411842
157.6578	182.5647	8.377254
157.8578	182.7638	8.342270
158.0578	182.9617	8.306984
158.2578	183.1606	8.271516
158.4578	183.3591	8.235658
158.6595	183.5618	8.199246
158.8612	183.7632	8.162566
159.0645	183.9660	8.124098
159.2662	184.1686	8.086691
159.4687	184.3749	8.049035
159.6693	184.5770	8.010856
159.8695	184.7764	7.972410
160.0695	184.9730	7.933524
160.2695	185.1722	7.894251
160.4697	185.3735	7.854516
160.6697	185.5733	7.814510
160.8696	185.7727	7.774158
161.0697	185.9724	7.733434
161.2697	186.1725	7.692138
161.4695	186.3718	7.650440
161.6695	186.5732	7.608462
161.8695	186.7734	7.566071
162.0695	186.9760	7.523145
162.2697	187.1761	7.479930
162.4730	187.3808	7.434475
162.6755	187.5829	7.390359
162.8780	187.7847	7.345859
163.0812	187.9863	7.298881
163.2830	188.1879	7.253562
163.4847	188.3885	7.207803
163.6880	188.5898	7.160719
163.8910	188.7926	7.112966
164.0930	188.9939	7.065997
164.2943	189.1965	7.018422
164.4977	189.4034	6.968430
164.7003	189.6045	6.920051
164.9028	189.8074	6.871280
165.1062	190.0110	6.819946
165.3078	190.2122	6.770139
165.5095	190.4131	6.719910
165.7095	190.6124	6.669270
165.9095	190.8126	6.618250
166.1095	191.0140	6.566662
166.3095	191.2144	6.514651
166.5095	191.4152	6.462129
166.7095	191.6125	6.409311
166.9095	191.8120	6.356071
167.1095	192.0131	6.302456
167.3094	192.2146	6.248482
167.5094	192.4134	6.193894
167.7094	192.6152	6.139041
167.9094	192.8167	6.083760
168.1113	193.0192	6.028074
168.3145	193.2233	5.969734
168.5162	193.4246	5.913183
168.7178	193.6244	5.856150
168.9193	193.8240	5.798790
169.1196	194.0230	5.741000
169.3195	194.2216	5.682734
169.5195	194.4193	5.623906
169.7195	194.6175	5.564430
169.9195	194.8197	5.504778
170.1194	195.0211	5.444574
170.3197	195.2229	5.383907
170.5195	195.4236	5.322598
170.7197	195.6232	5.260870
170.9197	195.8230	5.198587
171.1196	196.0231	5.135829
171.3195	196.2241	5.072701
171.5195	196.4220	5.008947
171.7228	196.6259	4.942047
171.9244	196.8292	4.877306
172.1272	197.0325	4.812232
172.3313	197.2357	4.743678
172.5330	197.4340	4.677498
172.7345	197.6366	4.610787
172.9362	197.8391	4.543687
173.1403	198.0433	4.473318
173.3428	198.2488	4.405086
173.5445	198.4513	4.336256
173.7478	198.6530	4.264114
173.9494	198.8550	4.194438
174.1522	199.0560	4.124369
174.3562	199.2601	4.050842
174.5578	199.4629	3.979780
174.7578	199.6626	3.908398
174.9576	199.8630	3.836507
175.1580	200.0633	3.764127
175.3578	200.2628	3.691275
175.5578	200.4614	3.618124
175.7578	200.6582	3.544274
175.9578	200.8586	3.470111
176.1578	201.0562	3.395410
176.3578	201.2570	3.320407
176.5578	201.4591	3.244953
176.7576	201.6594	3.168918
176.9580	201.8621	3.092590
177.1578	202.0631	3.015899
177.3603	202.2633	2.938366
177.5645	202.4685	2.857553
177.7663	202.6714	2.779532
177.9680	202.8729	2.701108
178.1695	203.0720	2.622295
178.3737	203.2738	2.539708
178.5762	203.4754	2.460168
178.7778	203.6814	2.380176
178.9812	203.8842	2.296297
179.1826	204.0872	2.215492
179.3826	204.2880	2.134411
179.5826	204.4878	2.052854
179.7830	204.6881	1.971002
179.9830	204.8870	1.888702
180.1828	205.0870	1.806320
180.3828	205.2846	1.723489
180.5828	205.4871	1.640355
180.7828	205.6878	1.556854
180.9828	205.8872	1.473205
181.1828	206.0863	1.389058
181.3826	206.2834	1.304721
181.5830	206.4830	1.220149
181.7847	206.6871	1.135323
181.9863	206.8900	1.050194
182.1895	207.0927	0.9613800
182.3912	207.2953	0.8757907
182.5937	207.5004	0.7900988
182.7977	207.7016	0.7010245
182.9996	207.9020	0.6157700
183.2014	208.1016	0.5309841
183.4028	208.3069	0.4474831
183.6070	208.5112	0.3646955
183.8095	208.7093	0.2936171
184.0112	208.9107	0.2302530
184.2145	209.1161	0.1715414
184.4163	209.3173	0.1217776
184.6188	209.5257	0.07899711
184.8228	209.7297	0.04043782
185.0245	209.9278	0.01129532
185.2262	210.1267	-5.2864E-3
185.4262	210.3260	-6.9338E-3
185.6260	210.5320	-7.3672E-3
185.8264	210.7318	-7.5353E-3
186.0262	210.9294	-7.6953E-3
186.2262	211.1274	-7.9668E-3
186.4262	211.3285	-8.1387E-3
186.6260	211.5270	-8.3476E-3
186.8260	211.7264	-8.5129E-3
187.0264	211.9288	-8.5915E-3
187.2263	212.1263	-8.6681E-3
187.4262	212.3235	-8.8448E-3
187.6262	212.5222	-9.0634E-3
187.8270	212.7254	-9.2043E-3
188.0312	212.9292	-9.3622E-3
188.2328	213.1345	-9.4089E-3
188.4328	213.3369	-9.5212E-3
188.6328	213.5371	-9.5479E-3
188.8326	213.7328	-9.7179E-3
189.0326	213.9275	-9.8063E-3
189.2330	214.1309	-9.8587E-3
189.4330	214.3306	-9.9825E-3
189.6328	214.5332	-9.9867E-3
189.8328	214.7343	-9.9575E-3
190.0328	214.9359	-.01007277
190.2328	215.1374	-.01020101
190.4326	215.3370	-.01028344
190.6326	215.5375	-.01044089
190.8328	215.7364	-.01044066
191.0344	215.9387	-.01056009
191.2347	216.1387	-.01078442
191.4347	216.3368	-.01074505
191.6347	216.5350	-.01075776
191.8347	216.7333	-.01085822
192.0347	216.9340	-.01097146
192.2345	217.1353	-.01104867
192.4345	217.3364	-.01108573
192.6345	217.5376	-.01117311
192.8345	217.7386	-.01124474
193.0345	217.9368	-.01131742
193.2345	218.1352	-.01143327
193.4345	218.3344	-.01156411
193.6345	218.5373	-.01160753
193.8345	218.7371	-.01170373
194.0345	218.9384	-.01171800
194.2345	219.1363	-.01174266
194.4345	219.3366	-.01176188
194.6345	219.5345	-.01184188
194.8347	219.7359	-.01194778
195.0347	219.9364	-.01205510
195.2345	220.1339	-.01213903
195.4345	220.3330	-.01216885
195.6345	220.5346	-.01227402
195.8344	220.7355	-.01234535
196.0347	220.9371	-.01239542
196.2347	221.1371	-.01242607
196.4353	221.3380	-.01249598
196.6395	221.5419	-.01264906
196.8412	221.7433	-.01260549
197.0410	221.9431	-.01272225
197.2413	222.1429	-.01272361
197.4412	222.3430	-.01280426
197.6412	222.5425	-.01281267
197.8410	222.7438	-.01295141
198.0413	222.9436	-.01310664
198.2412	223.1440	-.01315171
198.4412	223.3420	-.01328599
198.6412	223.5413	-.01334113
198.8412	223.7408	-.01335661
199.0410	223.9407	-.01348750
199.2413	224.1404	-.01354658
199.4412	224.3396	-.01357771
199.6437	224.5423	-.01362741
199.8478	224.7475	-.01378424
200.0478	224.9487	-.01371617
200.2477	225.1504	-.01374944
200.4480	225.3484	-.01390657
200.6478	225.5466	-.01405953
200.8478	225.7459	-.01404368
201.0478	225.9483	-.01401496
201.2478	226.1506	-.01408483
201.4478	226.3496	-.01422684
201.6476	226.5495	-.01420689
201.8477	226.7494	-.01418598
202.0477	226.9494	-.01430426
202.2480	227.1500	-.01434970
202.4480	227.3507	-.01441151
202.6497	227.5520	-.01433406
202.8522	227.7528	-.01443238
203.0563	227.9591	-.01451979
203.2580	228.1588	-.01454891
203.4597	228.3594	-.01460464
203.6613	228.5605	-.01461449
203.8652	228.7625	-.01482190
204.0678	228.9692	-.01489349
204.2695	229.1705	-.01498549
204.4728	229.3756	-.01492339
204.6745	229.5755	-.01495126
204.8770	229.7788	-.01503228
205.0812	229.9810	-.01511656
205.2830	230.1841	-.01508549
205.4845	230.3856	-.01511028
205.6862	230.5908	-.01512012
205.8903	230.7943	-.01513266
206.0928	230.9966	-.01517110
206.2944	231.1950	-.01523316
206.4980	231.3949	-.01536222
206.6996	231.6010	-.01531552
206.9022	231.8055	-.01539406
207.1064	232.0102	-.01542332
207.3078	232.2110	-.01547354
207.5095	232.4151	-.01547261
207.7112	232.6172	-.01547558
207.9155	232.8152	-.01557880
208.1176	233.0158	-.01562412
208.3195	233.2164	-.01580039
208.5228	233.4228	-.01578007
208.7245	233.6232	-.01583610
208.9270	233.8240	-.01577970
209.1313	234.0275	-.01586228
209.3326	234.2316	-.01585549
209.5328	234.4326	-.01590936
209.7328	234.6352	-.01582563
209.9328	234.8350	-.01586953
210.1330	235.0355	-.01592245
210.3330	235.2387	-.01593862
210.5330	235.4384	-.01600383
210.7328	235.6360	-.01598501
210.9328	235.8348	-.01595973
211.1330	236.0325	-.01617333
211.3328	236.2336	-.01613248
211.5330	236.4298	-.01625370
211.7328	236.6306	-.01617322
211.9345	236.8347	-.01610760
212.1353	237.0352	-.01606690
212.3396	237.2412	-.01611224
212.5410	237.4420	-.01610624
212.7428	237.6424	-.01619096
212.9445	237.8468	-.01619623
213.1488	238.0502	-.01622872
213.3514	238.2525	-.01623056
213.5530	238.4543	-.01635195
213.7562	238.6592	-.01635178
213.9578	238.8587	-.01632473
214.1604	239.0624	-.01634266
214.3647	239.2664	-.01640906
214.5663	239.4684	-.01644727
214.7680	239.6699	-.01645572
214.9694	239.8713	-.01646494
215.1736	240.0774	-.01642117
215.3762	240.2799	-.01637167
215.5778	240.4810	-.01640436
215.7812	240.6832	-.01633868
215.9830	240.8860	-.01633758
216.1855	241.0874	-.01637591
216.3862	241.2879	-.01643718
216.5862	241.4874	-.01636944
216.7863	241.6867	-.01645683
216.9860	241.8872	-.01643675
217.1862	242.0856	-.01650230
217.3863	242.2871	-.01647580
217.5863	242.4857	-.01647998
217.7862	242.6856	-.01649554
217.9862	242.8864	-.01647991
218.1862	243.0889	-.01647988
218.3863	243.2900	-.01645428
218.5860	243.4900	-.01647921
218.7862	243.6904	-.01647264
218.9862	243.8898	-.01654289
219.1897	244.0926	-.01644688
219.3922	244.2905	-.01650138
219.5944	244.4930	-.01644805
219.7945	244.6927	-.01644862
219.9945	244.8911	-.01659482
220.1945	245.0940	-.01662510
220.3947	245.2938	-.01655884
220.5947	245.4946	-.01652469
220.7945	245.6969	-.01661742
220.9945	245.8988	-.01660056
221.1945	246.0994	-.01648569
221.3944	246.2983	-.01656937
221.5945	246.4967	-.01654874
221.7945	246.6972	-.01655419
221.9946	246.8946	-.01650408
222.1945	247.0930	-.01649836
222.3945	247.2916	-.01650909
222.5988	247.4985	-.01643998
222.7994	247.7008	-.01640262
222.9995	247.8996	-.01642538
223.1995	248.0986	-.01638738
223.3997	248.2994	-.01649010
223.5995	248.5036	-.01656970
223.7995	248.7044	-.01653349
223.9996	248.9011	-.01668384
224.1993	249.1004	-.01663113
224.3995	249.3010	-.01664171
224.5995	249.5030	-.01672289
224.7996	249.7030	-.01661736
224.9993	249.9011	-.01658301
225.1995	250.1033	-.01642877
225.3995	250.3038	-.01658220
225.6010	250.5011	-.01662532
225.8045	250.7044	-.01678084
226.0080	250.9084	-.01662961
226.2095	251.1103	-.01658804
226.4112	251.3117	-.01652209
226.6147	251.5175	-.01658962
226.8162	251.7179	-.01655692
227.0162	251.9187	-.01653223
227.2163	252.1170	-.01656007
227.4162	252.3163	-.01662627
227.6162	252.5165	-.01658791
227.8160	252.7149	-.01666501
228.0162	252.9159	-.01665720
228.2163	253.1162	-.01657894
228.4162	253.3180	-.01650165
228.6162	253.5156	-.01662112
228.8163	253.7148	-.01660316
229.0160	253.9162	-.01654717
229.2162	254.1186	-.01647052
229.4178	254.3228	-.01647695
229.6196	254.5246	-.01637951
229.8230	254.7297	-.01629637
230.0254	254.9319	-.01640165
230.2278	255.1333	-.01651455
230.4314	255.3318	-.01652450
230.6330	255.5319	-.01653377
230.8347	255.7330	-.01651044
231.0362	255.9352	-.01648058
231.2362	256.1358	-.01653902
231.4362	256.3356	-.01646446
231.6362	256.5352	-.01646016
231.8362	256.7355	-.01649428
232.0362	256.9352	-.01651958
232.2363	257.1342	-.01661932
232.4363	257.3350	-.01660858
232.6363	257.5372	-.01657002
232.8360	257.7370	-.01662849
233.0360	257.9370	-.01656713
233.2360	258.1374	-.01654117
233.4363	258.3378	-.01646967
233.6363	258.5380	-.01651573
233.8396	258.7412	-.01656108
234.0413	258.9432	-.01659794
234.2438	259.1444	-.01658206
234.4480	259.3484	-.01642117
234.6495	259.5526	-.01654658
234.8512	259.7540	-.01658327
235.0528	259.9574	-.01645942
235.2570	260.1608	-.01649210
235.4595	260.3631	-.01645651
235.6595	260.5620	-.01659142
235.8594	260.7611	-.01674796
236.0597	260.9613	-.01645923
236.2597	261.1611	-.01646898
236.4595	261.3583	-.01652958
236.6595	261.5592	-.01652771
236.8595	261.7592	-.01648164
237.0595	261.9601	-.01637653
237.2597	262.1604	-.01644719
237.4597	262.3603	-.01651397
237.6595	262.5609	-.01645156
237.8595	262.7614	-.01643974
238.0595	262.9590	-.01651729
238.2594	263.1596	-.01648800
238.4597	263.3596	-.01652064
238.6595	263.5580	-.01651476
238.8595	263.7601	-.01651577
239.0597	263.9608	-.01649647
239.2595	264.1619	-.01638098
239.4595	264.3628	-.01638859
239.6597	264.5617	-.01625941
239.8595	264.7627	-.01633236
240.0595	264.9622	-.01620845
240.2597	265.1623	-.01626979
240.4595	265.3618	-.01635545
240.6604	265.5617	-.01632833
240.8647	265.7660	-.01637243
241.0662	265.9676	-.01638530
241.2680	266.1691	-.01630223
241.4695	266.3684	-.01633102
241.6735	266.5725	-.01639521
241.8762	266.7786	-.01635529
242.0778	266.9801	-.01631926
242.2812	267.1846	-.01635763
242.4828	267.3852	-.01616556
242.6855	267.5882	-.01623563
242.8862	267.7872	-.01633858
243.0863	267.9856	-.01625192
243.2862	268.1852	-.01620871
243.4863	268.3870	-.01616059
243.6862	268.5878	-.01624939
243.8862	268.7874	-.01614167
244.0862	268.9867	-.01609413
244.2862	269.1875	-.01615535
244.4862	269.3875	-.01602318
244.6862	269.5881	-.01610419
244.8863	269.7867	-.01600219
245.0862	269.9845	-.01610127
245.2863	270.1860	-.01605475
245.4862	270.3858	-.01604401
245.6863	270.5867	-.01602020
245.8862	270.7874	-.01609452
246.0863	270.9865	-.01607289
246.2862	271.1888	-.01604477
246.4863	271.3913	-.01606989
246.6862	271.5891	-.01608580
246.8863	271.7876	-.01618008
247.0862	271.9878	-.01615144
247.2863	272.1887	-.01612044
247.4862	272.3856	-.01610021
247.6863	272.5847	-.01608242
247.8862	272.7846	-.01595816
248.0863	272.9849	-.01597337
248.2895	273.1880	-.01589764
248.4910	273.3900	-.01588267
248.6928	273.5902	-.01584285
248.8945	273.7915	-.01592956
249.0988	273.9966	-.01592981
249.3012	274.2014	-.01591520
249.5030	274.4038	-.01599861
249.7062	274.6082	-.01589694
249.9080	274.8099	-.01586857
250.1103	275.0110	-.01599058
250.3147	275.2154	-.01593556
250.5162	275.4178	-.01595486
250.7177	275.6182	-.01588204
250.9195	275.8218	-.01597066
251.1226	276.0238	-.01589619
251.3228	276.2241	-.01594366
251.5230	276.4256	-.01591154
251.7228	276.6262	-.01585479
251.9230	276.8264	-.01580559
252.1228	277.0254	-.01589949
252.3228	277.2245	-.01587462
252.5226	277.4252	-.01603566
252.7228	277.6239	-.01588284
252.9230	277.8236	-.01579549
253.1228	278.0230	-.01581444
253.3230	278.2236	-.01589275
253.5228	278.4240	-.01582948
253.7245	278.6256	-.01583408
253.9260	278.8269	-.01579958
254.1278	279.0289	-.01574621
254.3322	279.2330	-.01574242
254.5345	279.4352	-.01575441
254.7363	279.6376	-.01578383
254.9395	279.8401	-.01589858
255.1397	280.0410	-.01586090
255.3395	280.2418	-.01578367
255.5395	280.4410	-.01581573
255.7395	280.6402	-.01586403
255.9395	280.8410	-.01582166
256.1395	281.0408	-.01577862
256.3395	281.2404	-.01578980
256.5395	281.4401	-.01573113
256.7395	281.6402	-.01574485
256.9395	281.8413	-.01576131
257.1397	282.0440	-.01563664
257.3395	282.2437	-.01572516
257.5405	282.4444	-.01572911
257.7428	282.6456	-.01577799
257.9447	282.8466	-.01579642
258.1478	283.0486	-.01597312
258.3496	283.2510	-.01589056
258.5520	283.4529	-.01581773
258.7526	283.6533	-.01575448
258.9528	283.8529	-.01576832
259.1528	284.0535	-.01585493
259.3530	284.2539	-.01569225
259.5528	284.4524	-.01561881
259.7530	284.6534	-.01565272
259.9528	284.8529	-.01563972
260.1530	285.0535	-.01562656
260.3528	285.2514	-.01579409
260.5527	285.4544	-.01565218
260.7530	285.6531	-.01576552
260.9528	285.8537	-.01564973
261.1527	286.0539	-.01584454
261.3530	286.2538	-.01579938
261.5562	286.4560	-.01568800
261.7587	286.6584	-.01574426
261.9610	286.8618	-.01567027
262.1646	287.0637	-.01557031
262.3662	287.2675	-.01554551
262.5678	287.4687	-.01560511
262.7680	287.6697	-.01559672
262.9678	287.8696	-.01566239
263.1678	288.0688	-.01567091
263.3678	288.2685	-.01553668
263.5680	288.4668	-.01554045
263.7678	288.6684	-.01569557
263.9678	288.8681	-.01557831
264.1678	289.0666	-.01560274
264.3680	289.2654	-.01559064
264.5678	289.4640	-.01560966
264.7678	289.6639	-.01560308
264.9676	289.8658	-.01547847
265.1697	290.0686	-.01549512
265.3728	290.2724	-.01551834
265.5728	290.4750	-.01553749
265.7730	290.6726	-.01545124
265.9728	290.8738	-.01549623
266.1728	291.0731	-.01555312
266.3730	291.2740	-.01550057
266.5728	291.4739	-.01552918
266.7730	291.6750	-.01541723
266.9728	291.8739	-.01548062
267.1728	292.0744	-.01540330
267.3730	292.2758	-.01554914
267.5728	292.4742	-.01547642
267.7728	292.6722	-.01553449
267.9728	292.8738	-.01545548
268.1755	293.0753	-.01544542
268.3778	293.2761	-.01546774
268.5813	293.4782	-.01545373
268.7812	293.6769	-.01552668
268.9812	293.8768	-.01548770
269.1814	294.0760	-.01561365
269.3812	294.2758	-.01560593
269.5812	294.4778	-.01553079
269.7812	294.6802	-.01556948
269.9812	294.8800	-.01548754
270.1810	295.0797	-.01555681
270.3814	295.2808	-.01550951
270.5813	295.4826	-.01544752
270.7812	295.6820	-.01533342
270.9812	295.8834	-.01525618
271.1814	296.0826	-.01538316
271.3837	296.2846	-.01532633
271.5862	296.4862	-.01545506
271.7896	296.6898	-.01548825
271.9912	296.8934	-.01549298
272.1930	297.0964	-.01557000
272.3945	297.2981	-.01538736
272.5947	297.4988	-.01528664
272.7945	297.6994	-.01545172
272.9945	297.8975	-.01539600
273.1947	298.0972	-.01545919
273.3946	298.2982	-.01541705
273.5945	298.5006	-.01527053
273.7945	298.6988	-.01528670
273.9945	298.8990	-.01524246
274.1945	299.0990	-.01524885
274.3945	299.2968	-.01530690
274.5947	299.4966	-.01537770
274.7945	299.6954	-.01530820
274.9612	299.8620	-.01519021