File: TGA/2023_07_11_alumel_calib_1cpm.txt
CLOSED
Version	0.4
Run	870
Instrument	2950 TGA       V5.4A
Module	TGA 1000 øC
Sample	2023_07_11_alumel_calib_1cpm
Size	59.7340	mg
Method	50C to 300C at 1 cpm
Operator	SBK
Comment	2023_07_11_alumel_calib_1cpm
Xcomment	Pan: Platinum           Gas1: Nitrogen  40          Gas2: Nitrogen  40
Text	2023_07_11_alumel_calib_1cpm
Text	Calibration with alumel wire and magnet
Kcell	1.00000
TempCal	2	pts	156.68	152.50,	376.53	354.00
Thresholds	0.050	0.0000
Controls	Gas 1  Event Off  Sampling 2.0 sec/pt
Nsig	3
Sig1	Time (min)
Sig2	Temperature (øC)
Sig3	Weight (mg)
Date	11-Jul-23
Time	14:21
File	C:\TA\Data\TGA\Skyler\2023_07_11_alumel_calib_1cpm.001
OrgFile	C:\TA\Data\TGA\Skyler\2023_07_11_alumel_calib_1cpm.001
StartOfData
0.0000000	50.08008	59.73291
0.09933334	50.09665	59.73342
0.1993334	50.13346	59.73362
0.2991667	50.18600	59.73370
0.3991667	50.24922	59.73386
0.4991667	50.32553	59.73379
0.5991668	50.40434	59.73377
0.6991668	50.48989	59.73390
0.7991668	50.58048	59.73386
0.8991668	50.67224	59.73371
0.9991668	50.76964	59.73380
1.099500	50.86728	59.73387
1.199500	50.96637	59.73382
1.299500	51.06384	59.73383
1.399500	51.16347	59.73394
1.499500	51.26362	59.73388
1.599334	51.36478	59.73380
1.701000	51.46516	59.73389
1.802666	51.56869	59.73389
1.904334	51.67024	59.73389
2.006000	51.76894	59.73384
2.106000	51.86418	59.73391
2.207666	51.96381	59.73390
2.308500	52.06143	59.73394
2.409333	52.15969	59.73388
2.512834	52.25933	59.73394
2.612833	52.35670	59.73398
2.714500	52.45691	59.73395
2.815333	52.55962	59.73416
2.916167	52.66132	59.73393
3.017833	52.76470	59.73396
3.117833	52.86724	59.73399
3.221000	52.97260	59.73408
3.321834	53.07504	59.73418
3.422666	53.17840	59.73422
3.524333	53.28004	59.73416
3.624333	53.37502	59.73416
3.726000	53.47127	59.73421
3.827667	53.57160	59.73426
3.929334	53.67344	59.73426
4.029333	53.77491	59.73420
4.129334	53.87672	59.73428
4.229334	53.97860	59.73430
4.329334	54.07870	59.73438
4.429333	54.17822	59.73438
4.529333	54.27690	59.73435
4.629334	54.37769	59.73448
4.729334	54.47654	59.73441
4.829500	54.57660	59.73440
4.929500	54.67800	59.73437
5.029500	54.77744	59.73447
5.129500	54.87681	59.73437
5.229500	54.97379	59.73460
5.329500	55.07317	59.73442
5.429500	55.17416	59.73432
5.529500	55.27666	59.73442
5.629500	55.37776	59.73447
5.729500	55.47900	59.73452
5.829500	55.58072	59.73448
5.929500	55.68159	59.73450
6.029500	55.78108	59.73455
6.129500	55.88196	59.73457
6.229500	55.98303	59.73461
6.329500	56.08236	59.73462
6.429500	56.18135	59.73461
6.529166	56.27876	59.73465
6.629166	56.37757	59.73476
6.729334	56.48026	59.73479
6.829334	56.57945	59.73482
6.929334	56.68025	59.73480
7.029334	56.78282	59.73482
7.129334	56.87960	59.73490
7.229334	56.98081	59.73493
7.329334	57.07864	59.73496
7.429334	57.17470	59.73494
7.529334	57.27489	59.73501
7.629334	57.37295	59.73514
7.729334	57.46994	59.73496
7.829334	57.57039	59.73508
7.929334	57.67280	59.73506
8.029166	57.77266	59.73509
8.129500	57.87718	59.73511
8.229500	57.97350	59.73508
8.329500	58.07214	59.73510
8.429500	58.17240	59.73521
8.529500	58.27008	59.73524
8.629501	58.36970	59.73528
8.729500	58.47220	59.73521
8.829500	58.57266	59.73534
8.929500	58.67370	59.73551
9.029500	58.77624	59.73546
9.129501	58.87570	59.73540
9.229500	58.97428	59.73542
9.329334	59.07226	59.73545
9.431000	59.16991	59.73536
9.531000	59.26407	59.73540
9.632668	59.36672	59.73537
9.733499	59.46996	59.73574
9.834334	59.56952	59.73552
9.937668	59.67351	59.73564
10.03767	59.77780	59.73559
10.13933	59.88172	59.73565
10.24017	59.98007	59.73556
10.34100	60.08324	59.73562
10.44267	60.18720	59.73559
10.54266	60.28770	59.73576
10.64600	60.39318	59.73582
10.74684	60.49402	59.73566
10.84767	60.59340	59.73557
10.94934	60.69546	59.73565
11.04934	60.79539	59.73562
11.15100	60.89868	59.73575
11.25266	60.99796	59.73569
11.35433	61.10056	59.73585
11.45600	61.20447	59.73568
11.55600	61.30440	59.73586
11.65766	61.40892	59.73585
11.75850	61.51224	59.73589
11.85934	61.61224	59.73590
11.95934	61.71474	59.73590
12.05934	61.81684	59.73606
12.15934	61.91507	59.73593
12.25934	62.01215	59.73596
12.35934	62.11280	59.73610
12.45934	62.21187	59.73606
12.55934	62.31330	59.73598
12.65934	62.41141	59.73601
12.75934	62.51129	59.73605
12.85950	62.61060	59.73616
12.95950	62.71268	59.73614
13.05950	62.81360	59.73620
13.15950	62.91474	59.73629
13.25950	63.01574	59.73616
13.35950	63.11684	59.73601
13.45950	63.21690	59.73603
13.55933	63.31586	59.73616
13.65934	63.41613	59.73632
13.75934	63.51530	59.73622
13.85933	63.61462	59.73629
13.95934	63.71492	59.73623
14.05933	63.81613	59.73645
14.15934	63.91548	59.73638
14.25917	64.01370	59.73641
14.35950	64.11410	59.73646
14.45950	64.21296	59.73638
14.55950	64.31232	59.73637
14.65950	64.41479	59.73656
14.75950	64.51480	59.73646
14.86283	64.61720	59.73650
14.96367	64.71954	59.73658
15.06450	64.82028	59.73676
15.16600	64.92125	59.73668
15.26600	65.01732	59.73668
15.36766	65.11716	59.73682
15.46934	65.21921	59.73674
15.57100	65.32272	59.73670
15.67283	65.42364	59.73699
15.77283	65.52042	59.73668
15.87450	65.62509	59.73680
15.97516	65.72766	59.73688
16.07600	65.82644	59.73676
16.17934	65.93171	59.73694
16.27934	66.03374	59.73676
16.38100	66.13710	59.73678
16.48184	66.24072	59.73688
16.58266	66.34390	59.73661
16.68434	66.44308	59.73706
16.78434	66.53919	59.73710
16.88766	66.64069	59.73711
16.98850	66.74189	59.73705
17.08933	66.84118	59.73704
17.19100	66.94256	59.73704
17.29100	67.04116	59.73720
17.39266	67.14244	59.73708
17.49434	67.24221	59.73738
17.59600	67.34048	59.73730
17.69766	67.43878	59.73720
17.79767	67.53894	59.73728
17.89950	67.64292	59.73716
18.00034	67.74219	59.73736
18.10116	67.84534	59.73736
18.20434	67.95171	59.73738
18.30434	68.05372	59.73753
18.40600	68.16080	59.73734
18.50684	68.26209	59.73719
18.60766	68.36218	59.73752
18.70934	68.46250	59.73750
18.80934	68.56208	59.73754
18.91250	68.66310	59.73782
19.01283	68.76287	59.73772
19.11283	68.86291	59.73778
19.21433	68.96540	59.73779
19.31433	69.06606	59.73782
19.41600	69.16593	59.73782
19.51684	69.26504	59.73777
19.61766	69.36468	59.73789
19.72100	69.46518	59.73792
19.82083	69.56556	59.73803
19.92117	69.66597	59.73797
20.02200	69.76732	59.73800
20.12267	69.86725	59.73789
20.22434	69.96930	59.73793
20.32434	70.06884	59.73805
20.42600	70.17082	59.73818
20.52600	70.27197	59.73832
20.62600	70.37346	59.73820
20.72600	70.47085	59.73993
20.82583	70.56578	59.74366
20.92617	70.66524	59.74443
21.02617	70.76403	59.74450
21.12617	70.86780	59.74459
21.22600	70.96887	59.74458
21.32600	71.07110	59.74476
21.42600	71.17116	59.74463
21.52600	71.26936	59.74503
21.62600	71.37109	59.74520
21.72583	71.47382	59.74522
21.82617	71.57141	59.74528
21.92617	71.67309	59.74550
22.02600	71.77539	59.74516
22.12600	71.87622	59.74512
22.22600	71.97648	59.74505
22.32600	72.07651	59.74496
22.42600	72.17694	59.74520
22.52600	72.27750	59.74515
22.62600	72.38006	59.74507
22.72600	72.48034	59.74511
22.82600	72.57866	59.74524
22.92600	72.67805	59.74530
23.02600	72.77498	59.74514
23.12600	72.87218	59.74521
23.22766	72.97530	59.74511
23.32934	73.07860	59.74533
23.43100	73.18108	59.74532
23.53100	73.28006	59.74526
23.63267	73.38164	59.74543
23.73350	73.48316	59.74531
23.83434	73.58478	59.74546
23.93766	73.68610	59.74553
24.03766	73.78684	59.74556
24.13950	73.88925	59.74550
24.24034	73.98638	59.74560
24.34117	74.08651	59.74568
24.44283	74.19053	59.74592
24.54266	74.28865	59.74570
24.64600	74.39324	59.74551
24.74684	74.49500	59.74547
24.84766	74.59672	59.74580
24.94934	74.69756	59.74574
25.04934	74.79646	59.74570
25.14950	74.89688	59.74575
25.24950	74.99642	59.74596
25.34950	75.09720	59.74600
25.44934	75.19550	59.74580
25.54934	75.29514	59.74594
25.64934	75.39466	59.74605
25.74933	75.49462	59.74608
25.84933	75.59112	59.74621
25.94934	75.69264	59.74623
26.04934	75.79556	59.74623
26.14934	75.89394	59.74626
26.24933	75.99187	59.74631
26.34950	76.08940	59.74632
26.44950	76.19001	59.74645
26.54950	76.29001	59.74633
26.64917	76.38965	59.74638
26.74917	76.49160	59.74651
26.84933	76.59097	59.74663
26.94934	76.69045	59.74651
27.04934	76.79024	59.74668
27.14934	76.89384	59.74652
27.24933	76.99580	59.74662
27.34933	77.09264	59.74672
27.44934	77.19231	59.74680
27.54934	77.29234	59.74660
27.64934	77.39269	59.74662
27.74933	77.49413	59.74678
27.85100	77.59310	59.74684
27.95266	77.69462	59.74695
28.05434	77.79745	59.74674
28.15600	77.90105	59.74694
28.25600	78.00271	59.74690
28.35766	78.10420	59.74722
28.45850	78.20690	59.74746
28.55933	78.30718	59.74728
28.66266	78.41032	59.74730
28.76267	78.50953	59.74750
28.86267	78.60847	59.74752
28.96267	78.70810	59.74765
29.06266	78.80813	59.74761
29.16266	78.90882	59.74762
29.26250	79.00811	59.74788
29.36283	79.10979	59.74763
29.46283	79.20997	59.74781
29.56283	79.31030	59.74792
29.66284	79.40779	59.74778
29.76283	79.50774	59.74778
29.86283	79.60861	59.74780
29.96283	79.70974	59.74788
30.06283	79.80665	59.74778
30.16284	79.90647	59.74778
30.26283	80.00600	59.74795
30.36250	80.10679	59.74807
30.46250	80.20666	59.74800
30.56266	80.30406	59.74818
30.66266	80.40400	59.74809
30.76267	80.50414	59.74809
30.86267	80.60553	59.74820
30.96267	80.70441	59.74832
31.06266	80.80542	59.74832
31.16266	80.90601	59.74832
31.26267	81.00796	59.74822
31.36267	81.10730	59.74850
31.46267	81.20778	59.74878
31.56266	81.30682	59.74872
31.66350	81.40812	59.74892
31.76434	81.50796	59.74893
31.86600	81.60858	59.74900
31.96617	81.71142	59.74895
32.06784	81.81387	59.74894
32.16950	81.91425	59.74887
32.27117	82.01670	59.74871
32.37283	82.12004	59.74890
32.47250	82.21996	59.74910
32.57250	82.31934	59.74916
32.67250	82.42028	59.74912
32.77283	82.51926	59.74928
32.87283	82.62047	59.74922
32.97283	82.72210	59.74910
33.07283	82.81965	59.74940
33.17283	82.91705	59.74942
33.27283	83.01694	59.74944
33.37250	83.11387	59.74932
33.47267	83.21625	59.74886
33.57266	83.31994	59.74924
33.67267	83.41969	59.74946
33.77267	83.52132	59.74939
33.87266	83.61720	59.74963
33.97267	83.71722	59.74974
34.07266	83.81736	59.74966
34.17267	83.91661	59.74980
34.27267	84.01519	59.74975
34.37266	84.11414	59.74981
34.47267	84.21407	59.74984
34.57266	84.31168	59.74988
34.67267	84.41055	59.74992
34.77283	84.51632	59.74976
34.87283	84.61680	59.75015
34.97250	84.71493	59.75000
35.07266	84.81578	59.75022
35.17267	84.91699	59.75020
35.27434	85.01691	59.75029
35.37517	85.11718	59.75020
35.47617	85.21819	59.75027
35.57950	85.32122	59.75036
35.67933	85.41937	59.75057
35.78100	85.51906	59.75051
35.88183	85.61864	59.75063
35.98266	85.71900	59.75058
36.08433	85.82004	59.75079
36.18433	85.92124	59.75088
36.28766	86.02387	59.75089
36.38867	86.12403	59.75086
36.48950	86.22672	59.75090
36.59117	86.33097	59.75092
36.69083	86.43231	59.75095
36.79266	86.53332	59.75094
36.89433	86.63499	59.75107
36.99600	86.73689	59.75100
37.09600	86.83863	59.75108
37.19617	86.93785	59.75118
37.29783	87.04181	59.75130
37.39750	87.14304	59.75125
37.49766	87.24212	59.75147
37.59767	87.34394	59.75144
37.69766	87.44562	59.75148
37.79767	87.54616	59.75151
37.89783	87.64618	59.75152
37.99750	87.74594	59.75164
38.09767	87.84539	59.75163
38.19766	87.94543	59.75160
38.29783	88.04788	59.75158
38.39783	88.14828	59.75176
38.49750	88.24762	59.75175
38.59767	88.34566	59.75179
38.69766	88.44489	59.75175
38.79767	88.54453	59.75180
38.89767	88.64303	59.75190
38.99783	88.74330	59.75188
39.09783	88.84234	59.75214
39.19766	88.94245	59.75213
39.29767	89.04064	59.75226
39.39767	89.14063	59.75229
39.49766	89.24035	59.75222
39.59767	89.33819	59.75227
39.69766	89.43843	59.75230
39.79767	89.53931	59.75234
39.89783	89.64000	59.75248
39.99783	89.73965	59.75242
40.09867	89.84126	59.75242
40.19950	89.94218	59.75255
40.30084	90.04389	59.75250
40.40083	90.14312	59.75260
40.50433	90.24874	59.75268
40.60516	90.34912	59.75266
40.70600	90.44905	59.75272
40.80600	90.54742	59.75289
40.90600	90.64576	59.75278
41.00766	90.74688	59.75284
41.10867	90.84812	59.75307
41.20950	90.94980	59.75302
41.31283	91.05556	59.75305
41.41250	91.15520	59.75317
41.51433	91.25772	59.75315
41.61434	91.35675	59.75334
41.71433	91.45790	59.75340
41.81434	91.55834	59.75322
41.91434	91.65864	59.75335
42.01433	91.75881	59.75337
42.11434	91.85675	59.75343
42.21450	91.95719	59.75352
42.31416	92.05525	59.75352
42.41434	92.15547	59.75360
42.51433	92.25519	59.75354
42.61434	92.35434	59.75356
42.71433	92.45444	59.75368
42.81450	92.55391	59.75385
42.91450	92.65465	59.75390
43.01416	92.75352	59.75400
43.11434	92.85399	59.75398
43.21433	92.95342	59.75404
43.31434	93.05228	59.75428
43.41434	93.15358	59.75422
43.51433	93.25432	59.75446
43.61450	93.35131	59.75420
43.71450	93.45165	59.75443
43.81450	93.55372	59.75445
43.91450	93.65288	59.75447
44.01416	93.75206	59.75440
44.11434	93.85398	59.75444
44.21433	93.95624	59.75465
44.31516	94.05642	59.75470
44.41600	94.15675	59.75459
44.51783	94.25937	59.75474
44.61783	94.35932	59.75494
44.72083	94.46218	59.75495
44.82100	94.56225	59.75488
44.92100	94.66084	59.75489
45.02100	94.76259	59.75502
45.12100	94.86203	59.75500
45.22117	94.96181	59.75504
45.32084	95.06219	59.75514
45.42100	95.16095	59.75522
45.52100	95.26031	59.75530
45.62100	95.36191	59.75518
45.72117	95.46119	59.75530
45.82117	95.56149	59.75528
45.92100	95.66356	59.75532
46.02100	95.76578	59.75542
46.12100	95.86571	59.75535
46.22100	95.96695	59.75550
46.32100	96.06788	59.75558
46.42100	96.16624	59.75564
46.52100	96.26649	59.75570
46.62100	96.36825	59.75570
46.72100	96.46922	59.75579
46.82100	96.56743	59.75590
46.92117	96.66699	59.75581
47.02083	96.76780	59.75587
47.12100	96.86909	59.75591
47.22100	96.96769	59.75598
47.32117	97.06522	59.75609
47.42084	97.16550	59.75611
47.52183	97.26887	59.75620
47.62266	97.36809	59.75625
47.72434	97.46711	59.75636
47.82450	97.56781	59.75630
47.92584	97.66814	59.75640
48.02766	97.76957	59.75649
48.12934	97.87170	59.75649
48.23100	97.97503	59.75669
48.33100	98.07555	59.75686
48.43100	98.17369	59.75688
48.53200	98.27676	59.75698
48.63250	98.37755	59.75698
48.73266	98.47618	59.75708
48.83267	98.57670	59.75710
48.93266	98.67676	59.75720
49.03266	98.77618	59.75736
49.13283	98.87641	59.75729
49.23283	98.97780	59.75730
49.33250	99.07801	59.75742
49.43266	99.17632	59.75752
49.53266	99.27858	59.75758
49.63266	99.38047	59.75751
49.73266	99.48261	59.75752
49.83283	99.58209	59.75762
49.93283	99.68207	59.75761
50.03250	99.78026	59.75762
50.13266	99.88069	59.75764
50.23266	99.97866	59.75756
50.33267	100.0803	59.75772
50.43266	100.1780	59.75770
50.53266	100.2787	59.75774
50.63283	100.3784	59.75789
50.73283	100.4771	59.75787
50.83283	100.5768	59.75793
50.93266	100.6772	59.75793
51.03266	100.7780	59.75808
51.13266	100.8760	59.75810
51.23266	100.9754	59.75816
51.33266	101.0753	59.75818
51.43266	101.1743	59.75816
51.53266	101.2724	59.75824
51.63283	101.3736	59.75840
51.73367	101.4761	59.75839
51.83450	101.5785	59.75851
51.93783	101.6820	59.75850
52.03784	101.7801	59.75859
52.13916	101.8820	59.75868
52.24000	101.9855	59.75874
52.34083	102.0882	59.75886
52.44100	102.1890	59.75891
52.54100	102.2871	59.75894
52.64100	102.3865	59.75904
52.74100	102.4858	59.75912
52.84100	102.5854	59.75945
52.94100	102.6859	59.75934
53.04100	102.7861	59.75928
53.14100	102.8862	59.75926
53.24100	102.9837	59.75924
53.34082	103.0834	59.75944
53.44082	103.1817	59.75963
53.54082	103.2812	59.75970
53.64117	103.3817	59.75976
53.74116	103.4823	59.75970
53.84117	103.5843	59.75987
53.94100	103.6830	59.75999
54.04100	103.7832	59.75984
54.14100	103.8832	59.75996
54.24100	103.9848	59.76000
54.34100	104.0864	59.76020
54.44100	104.1881	59.76021
54.54117	104.2898	59.76025
54.64117	104.3907	59.76030
54.74100	104.4887	59.76035
54.84100	104.5877	59.76040
54.94100	104.6877	59.76046
55.04082	104.7894	59.76040
55.14117	104.8892	59.76057
55.24116	104.9896	59.76063
55.34266	105.0898	59.76068
55.44433	105.1928	59.76064
55.54600	105.2941	59.76060
55.64766	105.3919	59.76074
55.74766	105.4885	59.76093
55.84934	105.5879	59.76109
55.95033	105.6896	59.76120
56.05117	105.7902	59.76122
56.15434	105.8946	59.76129
56.25434	105.9945	59.76124
56.35600	106.0969	59.76134
56.45684	106.1979	59.76130
56.55766	106.2980	59.76135
56.65766	106.4015	59.76140
56.75766	106.5019	59.76142
56.85750	106.6016	59.76148
56.95750	106.7002	59.76160
57.05784	106.8000	59.76156
57.15783	106.8990	59.76157
57.25783	106.9992	59.76168
57.35784	107.0988	59.76186
57.45783	107.2015	59.76187
57.55784	107.3010	59.76188
57.65783	107.3991	59.76191
57.75766	107.5002	59.76204
57.85766	107.5985	59.76210
57.95766	107.6990	59.76213
58.05766	107.7976	59.76211
58.15766	107.8997	59.76256
58.25750	107.9981	59.76226
58.35784	108.0998	59.76234
58.45783	108.1992	59.76238
58.55784	108.3003	59.76254
58.65783	108.4009	59.76265
58.75783	108.5020	59.76266
58.85784	108.6017	59.76266
58.95783	108.7022	59.76275
59.05784	108.7989	59.76270
59.15783	108.8980	59.76279
59.25783	108.9983	59.76276
59.35950	109.0986	59.76282
59.45950	109.1962	59.76285
59.56250	109.2942	59.76310
59.66334	109.3951	59.76319
59.76433	109.4973	59.76320
59.86600	109.6019	59.76330
59.96600	109.7028	59.76336
60.06766	109.8054	59.76326
60.16934	109.9086	59.76338
60.27100	110.0129	59.76346
60.37266	110.1156	59.76365
60.47266	110.2171	59.76352
60.57266	110.3179	59.76359
60.67350	110.4183	59.76371
60.77434	110.5200	59.76382
60.87600	110.6194	59.76387
60.97584	110.7185	59.76395
61.07582	110.8177	59.76400
61.17584	110.9166	59.76397
61.27582	111.0134	59.76409
61.37582	111.1105	59.76414
61.47600	111.2102	59.76420
61.57600	111.3084	59.76431
61.67600	111.4089	59.76433
61.77600	111.5093	59.76430
61.87600	111.6105	59.76435
61.97600	111.7107	59.76452
62.07600	111.8099	59.76466
62.17600	111.9106	59.76472
62.27600	112.0137	59.76495
62.37600	112.1129	59.76487
62.47600	112.2133	59.76500
62.57600	112.3130	59.76516
62.67600	112.4120	59.76514
62.77600	112.5135	59.76513
62.87600	112.6150	59.76536
62.97617	112.7161	59.76540
63.07617	112.8177	59.76539
63.17584	112.9191	59.76545
63.27600	113.0183	59.76557
63.37600	113.1174	59.76552
63.47600	113.2193	59.76575
63.57600	113.3193	59.76581
63.67600	113.4185	59.76584
63.77617	113.5170	59.76608
63.87617	113.6182	59.76620
63.97584	113.7181	59.76612
64.07600	113.8171	59.76612
64.17600	113.9172	59.76614
64.27934	114.0202	59.76632
64.38016	114.1196	59.76632
64.48100	114.2210	59.76642
64.58100	114.3247	59.76645
64.68100	114.4287	59.76657
64.78266	114.5309	59.76661
64.88350	114.6294	59.76652
64.98434	114.7289	59.76666
65.08768	114.8287	59.76678
65.18768	114.9269	59.76695
65.28933	115.0271	59.76718
65.39016	115.1260	59.76714
65.49116	115.2256	59.76718
65.59282	115.3299	59.76732
65.69282	115.4296	59.76724
65.79582	115.5336	59.76736
65.89668	115.6335	59.76742
65.99766	115.7343	59.76747
66.09934	115.8368	59.76747
66.19934	115.9376	59.76752
66.30100	116.0382	59.76749
66.40266	116.1404	59.76759
66.50434	116.2404	59.76768
66.60616	116.3402	59.76774
66.70618	116.4404	59.76774
66.80782	116.5430	59.76783
66.90866	116.6461	59.76789
67.00916	116.7481	59.76810
67.11266	116.8530	59.76824
67.21268	116.9511	59.76812
67.31432	117.0498	59.76824
67.41516	117.1534	59.76843
67.51600	117.2540	59.76840
67.61782	117.3546	59.76826
67.71782	117.4519	59.76856
67.82116	117.5551	59.76861
67.92168	117.6591	59.76871
68.02266	117.7603	59.76886
68.12434	117.8640	59.76879
68.22434	117.9678	59.76907
68.32600	118.0700	59.76897
68.42766	118.1708	59.76909
68.52934	118.2706	59.76918
68.63116	118.3708	59.76915
68.73116	118.4690	59.76918
68.83282	118.5696	59.76909
68.93334	118.6677	59.76912
69.03432	118.7660	59.76958
69.13766	118.8708	59.76960
69.23766	118.9720	59.76976
69.33932	119.0745	59.76977
69.44018	119.1760	59.76970
69.54100	119.2786	59.76985
69.64268	119.3805	59.76995
69.74268	119.4800	59.77002
69.84600	119.5834	59.77010
69.94682	119.6850	59.77012
70.04766	119.7863	59.77027
70.14932	119.8866	59.77036
70.24934	119.9848	59.77050
70.35100	120.0864	59.77050
70.45266	120.1855	59.77036
70.55434	120.2816	59.77010
70.65600	120.3804	59.77066
70.75600	120.4812	59.77079
70.85766	120.5838	59.77089
70.95850	120.6864	59.77089
71.05932	120.7869	59.77094
71.16266	120.8899	59.77100
71.26266	120.9875	59.77110
71.36432	121.0893	59.77089
71.46432	121.1846	59.77056
71.56432	121.2733	59.77031
71.66616	121.3626	59.77033
71.76616	121.4511	59.77038
71.86782	121.5384	59.77021
71.96918	121.6297	59.77028
72.07082	121.7226	59.77037
72.17266	121.8201	59.77038
72.27266	121.9174	59.77028
72.37434	122.0190	59.77027
72.47516	122.1219	59.77037
72.57600	122.2259	59.77053
72.67934	122.3359	59.77053
72.77934	122.4413	59.77062
72.88100	122.5496	59.77063
72.98100	122.6551	59.77087
73.08100	122.7597	59.77078
73.18266	122.8682	59.77088
73.28266	122.9754	59.77093
73.38432	123.0842	59.77094
73.48600	123.1900	59.77112
73.58768	123.2970	59.77107
73.68950	123.4023	59.77114
73.78950	123.5050	59.77134
73.89116	123.6098	59.77132
73.99200	123.7137	59.77138
74.09250	123.8172	59.77143
74.19600	123.9216	59.77150
74.29600	124.0248	59.77162
74.39766	124.1293	59.77160
74.49766	124.2307	59.77190
74.59766	124.3304	59.77188
74.69934	124.4347	59.77200
74.79932	124.5367	59.77209
74.90118	124.6392	59.77196
75.00282	124.7412	59.77205
75.10450	124.8408	59.77210
75.20584	124.9440	59.77224
75.30600	125.0426	59.77239
75.40766	125.1442	59.77245
75.50850	125.2459	59.77257
75.60934	125.3466	59.77262
75.71268	125.4507	59.77280
75.81268	125.5508	59.77278
75.91450	125.6520	59.77293
76.01532	125.7544	59.77296
76.11616	125.8576	59.77292
76.21782	125.9582	59.77301
76.31750	126.0573	59.77324
76.41766	126.1567	59.77338
76.51768	126.2582	59.77344
76.61768	126.3580	59.77338
76.71766	126.4584	59.77348
76.81766	126.5590	59.77356
76.91766	126.6591	59.77363
77.01782	126.7597	59.77365
77.11782	126.8579	59.77376
77.21750	126.9587	59.77385
77.31766	127.0584	59.77395
77.41766	127.1570	59.77408
77.51768	127.2560	59.77421
77.61782	127.3570	59.77428
77.71782	127.4542	59.77428
77.81750	127.5543	59.77443
77.91766	127.6546	59.77434
78.01768	127.7552	59.77440
78.11768	127.8535	59.77473
78.21766	127.9544	59.77479
78.31766	128.0598	59.77485
78.41782	128.1587	59.77493
78.51750	128.2582	59.77502
78.61768	128.3583	59.77519
78.71766	128.4594	59.77522
78.81766	128.5593	59.77524
78.91782	128.6577	59.77526
79.01768	128.7577	59.77554
79.12100	128.8593	59.77554
79.22182	128.9607	59.77560
79.32282	129.0630	59.77575
79.42284	129.1657	59.77566
79.52266	129.2666	59.77585
79.62434	129.3665	59.77590
79.72516	129.4674	59.77593
79.82600	129.5673	59.77610
79.92950	129.6669	59.77613
80.02950	129.7672	59.77636
80.13100	129.8694	59.77646
80.23184	129.9701	59.77638
80.33266	130.0703	59.77645
80.43432	130.1708	59.77662
80.53432	130.2700	59.77666
80.63782	130.3763	59.77683
80.73750	130.4773	59.77692
80.83768	130.5776	59.77696
80.93768	130.6785	59.77708
81.03766	130.7792	59.77709
81.13782	130.8832	59.77694
81.23782	130.9848	59.77703
81.33782	131.0832	59.77710
81.43784	131.1807	59.77702
81.53750	131.2788	59.77716
81.63766	131.3800	59.77738
81.73766	131.4767	59.77738
81.83768	131.5741	59.77744
81.93768	131.6723	59.77750
82.03766	131.7744	59.77773
82.13766	131.8727	59.77760
82.23782	131.9724	59.77764
82.33782	132.0726	59.77780
82.43782	132.1754	59.77793
82.53750	132.2744	59.77801
82.63766	132.3755	59.77814
82.73766	132.4778	59.77828
82.83768	132.5800	59.77824
82.93768	132.6804	59.77834
83.03766	132.7784	59.77840
83.13766	132.8788	59.77850
83.23766	132.9808	59.77866
83.33950	133.0816	59.77877
83.44032	133.1825	59.77872
83.54082	133.2837	59.77888
83.64266	133.3840	59.77906
83.74266	133.4823	59.77918
83.84600	133.5834	59.77921
83.94684	133.6836	59.77930
84.04766	133.7853	59.77943
84.14932	133.8872	59.77942
84.24950	133.9876	59.77955
84.35116	134.0896	59.77969
84.45282	134.1927	59.77974
84.55418	134.2941	59.77979
84.65600	134.3988	59.77999
84.75600	134.4975	59.78005
84.85766	134.5991	59.78043
84.95851	134.6950	59.78031
85.05950	134.7954	59.78032
85.16282	134.8993	59.78050
85.26282	134.9989	59.78054
85.36418	135.1011	59.78066
85.46516	135.2005	59.78075
85.56601	135.3044	59.78097
85.66766	135.4065	59.78092
85.76766	135.5080	59.78101
85.87084	135.6125	59.78115
85.97168	135.7148	59.78124
86.07282	135.8162	59.78140
86.17284	135.9156	59.78144
86.27282	136.0159	59.78165
86.37450	136.1153	59.78169
86.47532	136.2150	59.78184
86.57600	136.3154	59.78184
86.67934	136.4212	59.78201
86.77934	136.5203	59.78222
86.88116	136.6217	59.78226
86.98200	136.7227	59.78231
87.08282	136.8238	59.78234
87.18450	136.9225	59.78250
87.28449	137.0249	59.78246
87.38782	137.1256	59.78262
87.48750	137.2258	59.78279
87.58750	137.3250	59.78295
87.68782	137.4260	59.78308
87.78782	137.5277	59.78316
87.88766	137.6286	59.78326
87.98766	137.7290	59.78338
88.08768	137.8294	59.78356
88.18768	137.9290	59.78359
88.28766	138.0288	59.78379
88.38782	138.1282	59.78382
88.48782	138.2284	59.78386
88.58782	138.3278	59.78396
88.68750	138.4284	59.78411
88.78750	138.5301	59.78410
88.88750	138.6302	59.78426
88.98782	138.7307	59.78428
89.08782	138.8285	59.78441
89.18768	138.9283	59.78441
89.28766	139.0262	59.78450
89.38766	139.1270	59.78476
89.48766	139.2269	59.78501
89.58782	139.3279	59.78492
89.68782	139.4276	59.78516
89.78782	139.5267	59.78526
89.88782	139.6256	59.78535
89.98766	139.7223	59.78535
90.08950	139.8248	59.78546
90.19018	139.9238	59.78554
90.29101	140.0262	59.78574
90.39266	140.1305	59.78580
90.49266	140.2313	59.78590
90.59601	140.3369	59.78598
90.69684	140.4388	59.78606
90.79750	140.5396	59.78622
90.89950	140.6413	59.78626
90.99950	140.7426	59.78641
91.10116	140.8430	59.78649
91.20266	140.9444	59.78660
91.30434	141.0464	59.78676
91.40600	141.1465	59.78680
91.50600	141.2454	59.78684
91.60766	141.3454	59.78707
91.70851	141.4453	59.78712
91.80934	141.5467	59.78726
91.90918	141.6472	59.78734
92.00949	141.7463	59.78747
92.10949	141.8475	59.78754
92.20950	141.9440	59.78769
92.30934	142.0454	59.78776
92.40934	142.1449	59.78774
92.50934	142.2450	59.78789
92.60934	142.3454	59.78804
92.70934	142.4461	59.78803
92.80934	142.5478	59.78820
92.90934	142.6470	59.78845
93.00916	142.7478	59.78850
93.10949	142.8482	59.78868
93.20950	142.9488	59.78870
93.30950	143.0495	59.78868
93.40949	143.1491	59.78890
93.50916	143.2491	59.78900
93.60934	143.3514	59.78910
93.70934	143.4512	59.78918
93.80934	143.5514	59.78943
93.90934	143.6493	59.78934
94.00934	143.7483	59.78960
94.10934	143.8475	59.78955
94.20934	143.9468	59.78969
94.30934	144.0462	59.78975
94.40934	144.1474	59.78969
94.50934	144.2463	59.78979
94.61282	144.3507	59.78984
94.71282	144.4505	59.79000
94.81450	144.5525	59.79006
94.91534	144.6527	59.79014
95.01582	144.7530	59.79019
95.11766	144.8546	59.79026
95.21766	144.9538	59.79058
95.32100	145.0572	59.79062
95.42184	145.1583	59.79079
95.52266	145.2598	59.79082
95.62282	145.3602	59.79082
95.72282	145.4619	59.79094
95.82416	145.5653	59.79124
95.92516	145.6680	59.79112
96.02600	145.7688	59.79106
96.12934	145.8726	59.79130
96.22934	145.9722	59.79140
96.33100	146.0730	59.79150
96.43100	146.1739	59.79170
96.53100	146.2739	59.79160
96.63266	146.3756	59.79164
96.73266	146.4734	59.79172
96.83434	146.5739	59.79184
96.93600	146.6748	59.79180
97.03766	146.7776	59.79194
97.13934	146.8789	59.79188
97.23934	146.9794	59.79203
97.34101	147.0802	59.79202
97.44184	147.1825	59.79211
97.54282	147.2836	59.79210
97.64618	147.3871	59.79224
97.74618	147.4878	59.79222
97.84750	147.5909	59.79229
97.94766	147.6893	59.79241
98.04766	147.7876	59.79248
98.14766	147.8875	59.79258
98.24766	147.9867	59.79255
98.34766	148.0860	59.79256
98.44782	148.1845	59.79262
98.54784	148.2843	59.79275
98.64750	148.3808	59.79272
98.74766	148.4815	59.79282
98.84766	148.5825	59.79275
98.94766	148.6829	59.79272
99.04766	148.7834	59.79268
99.14766	148.8821	59.79254
99.24766	148.9834	59.79280
99.34766	149.0841	59.79281
99.44766	149.1852	59.79273
99.54766	149.2850	59.79270
99.64782	149.3836	59.79265
99.74782	149.4862	59.79266
99.84782	149.5877	59.79248
99.94750	149.6872	59.79246
100.0477	149.7886	59.79236
100.1477	149.8879	59.79209
100.2477	149.9898	59.79188
100.3477	150.0889	59.79182
100.4477	150.1895	59.79187
100.5478	150.2874	59.79180
100.6487	150.3860	59.79160
100.7495	150.4876	59.79136
100.8512	150.5900	59.79118
100.9510	150.6914	59.79099
101.0543	150.7969	59.79075
101.1552	150.8974	59.79047
101.2560	150.9968	59.79005
101.3577	151.0974	59.78955
101.4577	151.1989	59.78916
101.5593	151.3017	59.78894
101.6610	151.4044	59.78862
101.7625	151.5070	59.78793
101.8645	151.6069	59.78728
101.9645	151.7054	59.78670
102.0645	151.8020	59.78597
102.1653	151.9018	59.78510
102.2662	152.0038	59.78472
102.3677	152.1028	59.78360
102.4677	152.2040	59.78270
102.5710	152.3099	59.78164
102.6718	152.4087	59.78024
102.7727	152.5114	59.77900
102.8743	152.6121	59.77744
102.9742	152.7116	59.77618
103.0745	152.8138	59.77454
103.1745	152.9126	59.77269
103.2745	153.0118	59.77080
103.3743	153.1118	59.76856
103.4743	153.2126	59.76644
103.5743	153.3107	59.76409
103.6743	153.4092	59.76144
103.7743	153.5086	59.75886
103.8743	153.6083	59.75598
103.9743	153.7102	59.75292
104.0743	153.8098	59.74959
104.1743	153.9094	59.74639
104.2742	154.0093	59.74292
104.3742	154.1116	59.73924
104.4745	154.2127	59.73562
104.5745	154.3144	59.73174
104.6743	154.4150	59.72778
104.7743	154.5162	59.72382
104.8743	154.6168	59.71975
104.9743	154.7165	59.71571
105.0745	154.8152	59.71148
105.1745	154.9175	59.70737
105.2743	155.0161	59.70318
105.3743	155.1159	59.69911
105.4743	155.2153	59.69459
105.5743	155.3133	59.69048
105.6743	155.4157	59.68596
105.7760	155.5174	59.68132
105.8777	155.6191	59.67695
105.9793	155.7195	59.67240
106.0810	155.8200	59.66820
106.1810	155.9179	59.66396
106.2808	156.0184	59.65972
106.3808	156.1176	59.65545
106.4812	156.2181	59.65118
106.5812	156.3175	59.64682
106.6812	156.4157	59.64238
106.7812	156.5162	59.63818
106.8812	156.6144	59.63404
106.9812	156.7120	59.62995
107.0812	156.8135	59.62593
107.1812	156.9150	59.62194
107.2812	157.0164	59.61788
107.3812	157.1179	59.61407
107.4812	157.2169	59.61025
107.5812	157.3172	59.60650
107.6812	157.4183	59.60271
107.7810	157.5198	59.59931
107.8810	157.6188	59.59578
107.9810	157.7202	59.59230
108.0810	157.8216	59.58898
108.1810	157.9218	59.58562
108.2810	158.0201	59.58227
108.3810	158.1192	59.57902
108.4810	158.2185	59.57593
108.5810	158.3183	59.57290
108.6810	158.4184	59.56988
108.7810	158.5150	59.56692
108.8810	158.6158	59.56416
108.9810	158.7169	59.56130
109.0818	158.8200	59.55860
109.1827	158.9261	59.55591
109.2843	159.0239	59.55305
109.3843	159.1279	59.55066
109.4876	159.2275	59.54778
109.5885	159.3264	59.54536
109.6893	159.4271	59.54300
109.7893	159.5268	59.54065
109.8892	159.6267	59.53813
109.9908	159.7281	59.53578
110.0908	159.8269	59.53343
110.1912	159.9277	59.53112
110.2912	160.0274	59.52908
110.3912	160.1277	59.52693
110.4912	160.2299	59.52505
110.5912	160.3306	59.52316
110.6912	160.4318	59.52121
110.7912	160.5336	59.51941
110.8912	160.6331	59.51777
110.9908	160.7335	59.51598
111.0908	160.8294	59.51434
111.1908	160.9290	59.51266
111.2908	161.0274	59.51102
111.3908	161.1265	59.50948
111.4910	161.2244	59.50788
111.5910	161.3232	59.50628
111.6910	161.4231	59.50489
111.7910	161.5232	59.50354
111.8910	161.6226	59.50205
111.9912	161.7241	59.50074
112.0912	161.8233	59.49948
112.1912	161.9252	59.49809
112.2912	162.0245	59.49678
112.3912	162.1261	59.49551
112.4908	162.2231	59.49425
112.5908	162.3250	59.49307
112.6910	162.4248	59.49179
112.7910	162.5256	59.49066
112.8910	162.6278	59.48954
112.9927	162.7302	59.48854
113.0927	162.8306	59.48760
113.1960	162.9347	59.48644
113.2968	163.0359	59.48546
113.3977	163.1341	59.48430
113.4995	163.2346	59.48370
113.5995	163.3389	59.48262
113.6992	163.4398	59.48168
113.7993	163.5406	59.48061
113.8993	163.6414	59.47982
113.9993	163.7396	59.47900
114.0993	163.8357	59.47822
114.1993	163.9368	59.47754
114.2993	164.0374	59.47656
114.3993	164.1365	59.47580
114.4993	164.2356	59.47510
114.5995	164.3371	59.47437
114.6995	164.4382	59.47368
114.7995	164.5376	59.47295
114.8992	164.6373	59.47226
114.9993	164.7374	59.47164
115.0993	164.8373	59.47096
115.1993	164.9342	59.47022
115.2993	165.0334	59.46972
115.3993	165.1322	59.46910
115.4993	165.2316	59.46843
115.5993	165.3321	59.46775
115.6993	165.4331	59.46701
115.7993	165.5346	59.46641
115.8993	165.6351	59.46586
115.9993	165.7353	59.46534
116.0993	165.8340	59.46468
116.1993	165.9363	59.46429
116.2993	166.0370	59.46370
116.4012	166.1394	59.46321
116.5028	166.2417	59.46293
116.6042	166.3432	59.46206
116.7060	166.4455	59.46169
116.8060	166.5453	59.46138
116.9077	166.6463	59.46090
117.0085	166.7465	59.46042
117.1093	166.8450	59.45996
117.2127	166.9470	59.45952
117.3127	167.0460	59.45907
117.4145	167.1484	59.45878
117.5153	167.2490	59.45832
117.6162	167.3486	59.45776
117.7175	167.4491	59.45745
117.8175	167.5481	59.45702
117.9208	167.6530	59.45672
118.0218	167.7523	59.45630
118.1227	167.8560	59.45618
118.2227	167.9574	59.45564
118.3227	168.0589	59.45531
118.4243	168.1617	59.45474
118.5252	168.2642	59.45456
118.6260	168.3638	59.45440
118.7293	168.4681	59.45391
118.8293	168.5695	59.45355
118.9310	168.6704	59.45330
119.0310	168.7697	59.45293
119.1312	168.8682	59.45261
119.2328	168.9692	59.45232
119.3328	169.0707	59.45210
119.4345	169.1702	59.45195
119.5342	169.2714	59.45149
119.6343	169.3704	59.45136
119.7343	169.4736	59.45126
119.8343	169.5712	59.45088
119.9343	169.6722	59.45057
120.0345	169.7720	59.45032
120.1345	169.8731	59.45004
120.2345	169.9732	59.44990
120.3342	170.0708	59.44944
120.4343	170.1708	59.44937
120.5343	170.2693	59.44904
120.6343	170.3703	59.44886
120.7343	170.4691	59.44859
120.8343	170.5673	59.44842
120.9343	170.6678	59.44816
121.0345	170.7691	59.44780
121.1345	170.8694	59.44790
121.2345	170.9689	59.44753
121.3345	171.0701	59.44705
121.4342	171.1692	59.44679
121.5343	171.2703	59.44665
121.6343	171.3721	59.44653
121.7343	171.4724	59.44638
121.8343	171.5743	59.44604
121.9343	171.6735	59.44590
122.0343	171.7730	59.44574
122.1345	171.8740	59.44554
122.2345	171.9732	59.44545
122.3342	172.0722	59.44516
122.4377	172.1750	59.44495
122.5377	172.2750	59.44462
122.6393	172.3762	59.44444
122.7402	172.4780	59.44432
122.8410	172.5791	59.44421
122.9428	172.6788	59.44386
123.0428	172.7805	59.44421
123.1427	172.8805	59.44380
123.2427	172.9791	59.44360
123.3427	173.0791	59.44321
123.4428	173.1797	59.44335
123.5425	173.2780	59.44314
123.6427	173.3771	59.44280
123.7427	173.4792	59.44270
123.8427	173.5808	59.44259
123.9427	173.6800	59.44258
124.0428	173.7784	59.44234
124.1425	173.8789	59.44219
124.2427	173.9788	59.44218
124.3427	174.0770	59.44180
124.4427	174.1761	59.44170
124.5428	174.2758	59.44165
124.6425	174.3764	59.44142
124.7427	174.4774	59.44135
124.8427	174.5778	59.44113
124.9427	174.6799	59.44112
125.0428	174.7814	59.44100
125.1428	174.8797	59.44090
125.2425	174.9787	59.44071
125.3427	175.0797	59.44071
125.4427	175.1785	59.44068
125.5427	175.2776	59.44050
125.6427	175.3755	59.44038
125.7428	175.4770	59.44021
125.8425	175.5777	59.44023
125.9427	175.6784	59.43995
126.0427	175.7797	59.44000
126.1460	175.8805	59.43976
126.2462	175.9788	59.43966
126.3478	176.0796	59.43948
126.4485	176.1788	59.43943
126.5493	176.2822	59.43932
126.6510	176.3845	59.43918
126.7512	176.4823	59.43898
126.8542	176.5885	59.43908
126.9552	176.6892	59.43907
127.0560	176.7914	59.43892
127.1577	176.8915	59.43894
127.2577	176.9925	59.43903
127.3595	177.0966	59.43874
127.4592	177.2004	59.43867
127.5593	177.2994	59.43882
127.6593	177.3986	59.43856
127.7593	177.4996	59.43848
127.8595	177.5997	59.43830
127.9595	177.6998	59.43805
128.0592	177.7972	59.43793
128.1593	177.8949	59.43800
128.2593	177.9944	59.43789
128.3593	178.0972	59.43814
128.4595	178.1942	59.43792
128.5595	178.2951	59.43785
128.6592	178.3939	59.43778
128.7593	178.4942	59.43766
128.8593	178.5952	59.43768
128.9593	178.6932	59.43753
129.0593	178.7925	59.43750
129.1593	178.8937	59.43757
129.2595	178.9916	59.43740
129.3592	179.0897	59.43720
129.4593	179.1930	59.43732
129.5593	179.2938	59.43711
129.6593	179.3942	59.43707
129.7593	179.4956	59.43707
129.8593	179.5964	59.43696
129.9595	179.6961	59.43680
130.0595	179.7961	59.43672
130.1592	179.8985	59.43682
130.2593	179.9966	59.43671
130.3627	180.0995	59.43674
130.4626	180.2001	59.43662
130.5643	180.3016	59.43647