File: TGA/2023_07_14_CBD_powder_1cpm.txt
CLOSED
Version	0.4
Run	876
Instrument	2950 TGA       V5.4A
Module	TGA 1000 øC
Sample	2023_07_14_CBD_powder_1cpm
Size	6.33600	mg
Method	25C to 300C at 1 cpm
Operator	SBK
Comment	2023_07_14_CBD_powder_1cpm
Xcomment	Pan: Platinum           Gas1: Nitrogen  40          Gas2: Nitrogen  40
Text	2023_07_14_CBD_powder_1cpm
Text	Fourth run with CBD powder after new calib
Kcell	1.00000
TempCal	2	pts	156.68	152.50,	376.53	354.00
Thresholds	0.050	0.0000
Controls	Gas 1  Event Off  Sampling 2.0 sec/pt
Nsig	3
Sig1	Time (min)
Sig2	Temperature (øC)
Sig3	Weight (mg)
Date	14-Jul-23
Time	15:24
File	C:\TA\Data\TGA\Skyler\2023_07_14_CBD_powder_1cpm.001
OrgFile	C:\TA\Data\TGA\Skyler\2023_07_14_CBD_powder_1cpm.001
StartOfData
0.0000000	25.12003	6.333536
0.1995000	25.23720	6.333535
0.3996667	25.40434	6.333410
0.5993334	25.58452	6.333408
0.7995000	25.77754	6.333248
0.9995000	25.97242	6.333101
1.199500	26.16826	6.332944
1.399500	26.36556	6.332828
1.599667	26.56612	6.332758
1.801000	26.77041	6.332676
2.004500	26.97045	6.332473
2.206167	27.17088	6.332341
2.407833	27.37261	6.332340
2.612000	27.57508	6.332192
2.814667	27.78110	6.332075
3.016333	27.98270	6.332075
3.216167	28.17754	6.331969
3.416167	28.37970	6.331900
3.616167	28.57987	6.331829
3.816167	28.77662	6.331792
4.016333	28.97748	6.331620
4.216166	29.17974	6.331549
4.416166	29.38080	6.331368
4.616166	29.58134	6.331190
4.816166	29.78100	6.331187
5.016166	29.98187	6.331040
5.216334	30.18213	6.331010
5.416332	30.37974	6.330916
5.616000	30.58085	6.330886
5.817000	30.78131	6.330812
6.021168	30.98636	6.330679
6.222832	31.18616	6.330669
6.424668	31.38628	6.330526
6.627666	31.59039	6.330518
6.829500	31.78860	6.330456
7.029500	31.99162	6.330340
7.229500	32.19340	6.330176
7.429500	32.38931	6.330020
7.629500	32.59148	6.329956
7.829500	32.79712	6.330052
8.029500	32.99338	6.329936
8.229500	33.19454	6.329829
8.429500	33.39628	6.329734
8.629501	33.59470	6.329634
8.829500	33.79398	6.329464
9.029500	33.98789	6.329488
9.229500	34.18564	6.329413
9.429500	34.38435	6.329247
9.631332	34.58802	6.329273
9.833000	34.79314	6.329128
10.03700	35.00019	6.329314
10.23950	35.20005	6.329023
10.44117	35.40368	6.328950
10.64266	35.60170	6.328782
10.84600	35.80444	6.328857
11.04883	36.00267	6.328651
11.25133	36.20568	6.328668
11.45450	36.40844	6.328742
11.65617	36.60980	6.328669
11.85783	36.80620	6.328564
12.06117	37.01708	6.328486
12.26467	37.21906	6.328332
12.46633	37.42456	6.328388
12.66950	37.62773	6.328270
12.87117	37.83035	6.328132
13.07117	38.03210	6.328022
13.27117	38.22861	6.327965
13.47117	38.42779	6.327948
13.67100	38.62767	6.327830
13.87133	38.82293	6.327717
14.07133	39.02332	6.327695
14.27133	39.21862	6.327536
14.47133	39.42030	6.327676
14.67100	39.62198	6.327541
14.87133	39.81453	6.327554
15.07133	40.01846	6.327609
15.27100	40.22334	6.327420
15.47100	40.41728	6.327453
15.67283	40.61969	6.327352
15.87450	40.82278	6.327332
16.07783	41.03223	6.327280
16.28033	41.23293	6.327006
16.48300	41.43588	6.327011
16.68434	41.63848	6.327057
16.88783	41.84108	6.326838
17.08783	42.04145	6.326872
17.28784	42.24036	6.326730
17.48783	42.44373	6.326708
17.68784	42.64277	6.326680
17.88783	42.84332	6.326578
18.08783	43.04059	6.326586
18.28784	43.23597	6.326678
18.48783	43.44000	6.326443
18.68784	43.64348	6.326426
18.88800	43.83638	6.326352
19.08800	44.03561	6.326151
19.28766	44.23426	6.326176
19.48783	44.43772	6.326126
19.68950	44.63876	6.326181
19.89117	44.83976	6.326161
20.09450	45.04257	6.326161
20.29617	45.23853	6.326151
20.49883	45.44540	6.326094
20.70266	45.65176	6.326084
20.90450	45.85392	6.326014
21.10450	46.05172	6.325926
21.30450	46.24560	6.325902
21.50450	46.44313	6.325822
21.70450	46.64668	6.325578
21.90450	46.85475	6.325480
22.10450	47.05352	6.325704
22.30450	47.25110	6.325508
22.50467	47.44971	6.325523
22.70434	47.64769	6.325497
22.90450	47.84201	6.325498
23.10450	48.03891	6.325398
23.30450	48.23438	6.325440
23.50450	48.43520	6.325349
23.70534	48.64000	6.325254
23.90800	48.84480	6.325266
24.10966	49.04775	6.325112
24.31284	49.24844	6.325096
24.51450	49.45450	6.325190
24.71783	49.66116	6.324970
24.92117	49.86713	6.324925
25.12283	50.06802	6.324890
25.32283	50.26247	6.324768
25.52283	50.46545	6.324887
25.72300	50.66455	6.324684
25.92266	50.85682	6.324816
26.12283	51.05652	6.324812
26.32300	51.25869	6.324722
26.52283	51.46316	6.324714
26.72283	51.67530	6.324670
26.92300	51.88363	6.324570
27.12300	52.07816	6.324516
27.32283	52.27434	6.324413
27.52283	52.47317	6.324368
27.72283	52.67179	6.324431
27.92533	52.87984	6.324500
28.12950	53.07814	6.324400
28.33117	53.27881	6.324372
28.53284	53.48012	6.324324
28.73467	53.68916	6.324192
28.93883	53.88956	6.324215
29.14133	54.09101	6.324217
29.34450	54.29294	6.324201
29.54617	54.49010	6.324122
29.74783	54.68299	6.324090
29.95033	54.88458	6.324014
30.15434	55.09354	6.323980
30.35633	55.29570	6.323933
30.55800	55.49272	6.323936
30.75967	55.69887	6.323824
30.96383	55.90118	6.323868
31.16616	56.10457	6.323790
31.36784	56.30488	6.323746
31.57133	56.50770	6.323840
31.77283	56.71144	6.323871
31.97534	56.91730	6.323806
32.17967	57.12429	6.323710
32.38117	57.32608	6.323671
32.58100	57.52799	6.323582
32.78116	57.72778	6.323522
32.98117	57.92488	6.323368
33.18133	58.12665	6.323271
33.38117	58.33022	6.323296
33.58116	58.53002	6.323367
33.78116	58.73155	6.323324
33.98117	58.93389	6.323108
34.18100	59.13458	6.323092
34.38117	59.33034	6.323094
34.58100	59.52600	6.323011
34.78116	59.72451	6.323134
34.98100	59.92859	6.323019
35.18450	60.13244	6.322990
35.38766	60.33605	6.322934
35.58950	60.54184	6.322991
35.79117	60.74348	6.322844
35.99283	60.94292	6.322760
36.19700	61.14627	6.322828
36.39966	61.33470	6.322755
36.60283	61.53074	6.322730
36.80450	61.73632	6.322654
37.00600	61.93580	6.322628
37.20883	62.14363	6.322680
37.41284	62.34545	6.322637
37.61450	62.54739	6.322443
37.81616	62.75130	6.322359
38.01950	62.95254	6.322391
38.22283	63.16101	6.322208
38.42450	63.37296	6.322143
38.62617	63.57047	6.322012
38.82966	63.77180	6.321979
39.03134	63.97610	6.321874
39.23450	64.18232	6.321844
39.43783	64.38071	6.321748
39.63967	64.58940	6.321660
39.84133	64.79472	6.321619
40.04450	65.00113	6.321358
40.24700	65.20160	6.321511
40.44950	65.41008	6.321256
40.65100	65.61220	6.321130
40.85450	65.81561	6.321060
41.05617	66.01301	6.320736
41.25617	66.21308	6.320682
41.45633	66.40482	6.320269
41.65616	66.60232	6.319986
41.85617	66.80293	6.319780
42.05600	67.00920	6.319668
42.25633	67.20814	6.319514
42.45616	67.41186	6.319416
42.65616	67.61108	6.319464
42.85634	67.80134	6.319482
43.05617	68.00176	6.319386
43.25617	68.20610	6.319458
43.45616	68.38836	6.319500
43.65783	68.58479	6.319370
43.85950	68.78810	6.319278
44.05950	69.00294	6.319306
44.25934	69.21401	6.319220
44.45967	69.41209	6.319249
44.65967	69.60984	6.319190
44.85966	69.80782	6.319146
45.05966	70.00585	6.319143
45.25950	70.20651	6.319106
45.45950	70.41204	6.319066
45.65950	70.61743	6.318902
45.85933	70.82040	6.318993
46.05933	71.01136	6.318824
46.25950	71.21404	6.318870
46.45950	71.40418	6.318898
46.66117	71.59782	6.318894
46.86450	71.79390	6.318770
47.06617	71.99960	6.318696
47.26950	72.19736	6.318688
47.47133	72.40078	6.318764
47.67383	72.61316	6.318632
47.87800	72.82324	6.318744
48.07967	73.02891	6.318684
48.28134	73.23205	6.318750
48.48300	73.43387	6.318720
48.68717	73.63834	6.318537
48.88933	73.83872	6.318578
49.09117	74.03668	6.318481
49.29283	74.23561	6.318406
49.49617	74.44084	6.318458
49.69883	74.64175	6.318393
49.90133	74.85372	6.318349
50.10100	75.05790	6.318276
50.30117	75.25449	6.318352
50.50117	75.46089	6.318134
50.70117	75.66192	6.318190
50.90117	75.85686	6.318106
51.10117	76.04688	6.318098
51.30134	76.24456	6.317955
51.50134	76.45540	6.317988
51.70133	76.66072	6.317997
51.90100	76.85074	6.317936
52.10133	77.04906	6.317925
52.30134	77.25434	6.317947
52.50134	77.44780	6.317896
52.70300	77.65772	6.317807
52.90550	77.86438	6.317794
53.10784	78.06000	6.317730
53.31116	78.26236	6.317730
53.51300	78.46510	6.317722
53.71467	78.66958	6.317680
53.91717	78.87080	6.317801
54.12117	79.07864	6.317765
54.32283	79.28134	6.317702
54.52450	79.48569	6.317608
54.72617	79.68479	6.317698
54.93050	79.88148	6.317612
55.13266	80.08103	6.317540
55.33433	80.28960	6.317395
55.53450	80.49016	6.317230
55.73450	80.69392	6.317285
55.93433	80.89210	6.317260
56.13467	81.09712	6.317190
56.33467	81.29082	6.317158
56.53467	81.48720	6.317136
56.73467	81.67640	6.317074
56.93467	81.87903	6.316916
57.13467	82.07955	6.316932
57.33467	82.28257	6.316878
57.53450	82.48499	6.316772
57.73450	82.68898	6.316820
57.93450	82.88722	6.316765
58.13716	83.08594	6.316670
58.33967	83.28644	6.316630
58.54133	83.49000	6.316670
58.74268	83.69628	6.316533
58.94600	83.90274	6.316445
59.14868	84.10828	6.316320
59.35283	84.30515	6.316368
59.55467	84.49860	6.316361
59.75618	84.70038	6.316387
59.95783	84.89941	6.316378
60.16200	85.10425	6.316394
60.36467	85.30701	6.316310
60.56600	85.51597	6.316282
60.76783	85.71910	6.316088
60.97133	85.92251	6.316028
61.17350	86.12468	6.315955
61.37617	86.32676	6.316012
61.57966	86.52794	6.315840
61.78100	86.73349	6.315766
61.98284	86.93741	6.315826
62.18717	87.14364	6.315862
62.38950	87.34338	6.315530
62.59117	87.54163	6.315586
62.79467	87.74460	6.315620
62.99617	87.94203	6.315485
63.19617	88.14043	6.315504
63.39633	88.34019	6.315451
63.59600	88.53907	6.315338
63.79617	88.74353	6.315392
63.99617	88.94438	6.315222
64.19634	89.14678	6.315220
64.39617	89.34720	6.315144
64.59617	89.54738	6.315192
64.79633	89.74728	6.315082
64.99600	89.94506	6.315113
65.19617	90.14520	6.314986
65.39633	90.34422	6.314991
65.59616	90.54360	6.314926
65.79784	90.74551	6.314812
65.99966	90.94746	6.314678
66.20100	91.15101	6.314630
66.40532	91.35222	6.314500
66.60800	91.55447	6.314401
66.80766	91.74731	6.314335
67.00784	91.94735	6.314300
67.20800	92.14944	6.314304
67.40766	92.35074	6.314161
67.60784	92.55360	6.314169
67.80782	92.75469	6.314011
68.00800	92.95590	6.313826
68.20800	93.15697	6.313706
68.40766	93.35512	6.313660
68.60784	93.55488	6.313648
68.80782	93.75244	6.313474
69.00784	93.95226	6.313470
69.20782	94.15162	6.313442
69.40800	94.34938	6.313370
69.61134	94.55475	6.313190
69.81468	94.76481	6.313215
70.01616	94.96631	6.313048
70.21950	95.16932	6.313105
70.42116	95.36812	6.312920
70.62366	95.57209	6.312980
70.82782	95.77555	6.312730
71.02950	95.97880	6.312656
71.23116	96.17758	6.312672
71.43282	96.38026	6.312478
71.63450	96.58039	6.312346
71.83450	96.78015	6.312193
72.03450	96.97680	6.312145
72.23450	97.17628	6.312030
72.43450	97.37753	6.312005
72.63450	97.57476	6.311921
72.83450	97.77960	6.311786
73.03450	97.98398	6.311693
73.23450	98.18266	6.311592
73.43450	98.37818	6.311474
73.63450	98.57769	6.311209
73.83450	98.77616	6.311094
74.03432	98.97736	6.310924
74.23634	99.18061	6.310895
74.43784	99.38068	6.310741
74.63950	99.57961	6.310615
74.84282	99.78632	6.310455
75.04616	99.99174	6.310165
75.24782	100.1962	6.310112
75.44968	100.3984	6.309944
75.65100	100.5988	6.309954
75.85450	100.7994	6.309742
76.05450	100.9951	6.309736
76.25450	101.1943	6.309624
76.45450	101.3934	6.309500
76.65466	101.5953	6.309312
76.85434	101.7969	6.309130
77.05450	101.9982	6.308940
77.25450	102.2002	6.308731
77.45434	102.4035	6.308581
77.65434	102.6030	6.308330
77.85468	102.8019	6.308172
78.05434	103.0008	6.308059
78.25450	103.1977	6.307755
78.45450	103.3974	6.307644
78.65616	103.5990	6.307531
78.85784	103.7999	6.307396
79.06216	104.0073	6.307068
79.26434	104.2084	6.306840
79.46450	104.4093	6.306700
79.66450	104.6131	6.306445
79.86450	104.8128	6.306268
80.06450	105.0110	6.306043
80.26466	105.2129	6.305954
80.46432	105.4103	6.305729
80.66450	105.6112	6.305378
80.86450	105.8103	6.305256
81.06450	106.0087	6.305000
81.26450	106.2106	6.304809
81.46450	106.4024	6.304489
81.66450	106.5995	6.304313
81.86450	106.8032	6.304115
82.06468	107.0100	6.303867
82.26718	107.2161	6.303647
82.47100	107.4196	6.303445
82.67284	107.6197	6.303432
82.87450	107.8216	6.302918
83.07800	108.0234	6.302552
83.28050	108.2258	6.302257
83.48282	108.4325	6.302121
83.68450	108.6336	6.301874
83.88782	108.8330	6.301543
84.08968	109.0344	6.301326
84.29200	109.2381	6.301100
84.49618	109.4405	6.300569
84.69782	109.6419	6.300440
84.89950	109.8442	6.300097
85.10266	110.0486	6.299718
85.30532	110.2501	6.299399
85.50800	110.4521	6.299276
85.70966	110.6547	6.298786
85.91266	110.8577	6.298481
86.11450	111.0598	6.298120
86.31700	111.2621	6.297812
86.52118	111.4652	6.297401
86.72282	111.6682	6.297174
86.92450	111.8721	6.296782
87.12800	112.0754	6.296530
87.33016	112.2766	6.296099
87.53282	112.4770	6.295628
87.73634	112.6820	6.295248
87.93768	112.8867	6.294928
88.13782	113.0847	6.294575
88.33782	113.2811	6.294280
88.53766	113.4812	6.293756
88.73782	113.6823	6.293118
88.93800	113.8820	6.292784
89.13782	114.0816	6.292379
89.33782	114.2803	6.291934
89.53800	114.4807	6.291580
89.73766	114.6756	6.291074
89.93782	114.8775	6.290644
90.13782	115.0808	6.290166
90.33800	115.2801	6.289682
90.53800	115.4785	6.289316
90.73950	115.6798	6.288801
90.94118	115.8807	6.288332
91.14468	116.0860	6.287815
91.34618	116.2866	6.287280
91.54618	116.4920	6.286786
91.74632	116.6923	6.286291
91.94618	116.8918	6.285750
92.14618	117.0906	6.285210
92.34601	117.2894	6.284710
92.54618	117.4891	6.284113
92.74632	117.6902	6.283611
92.94618	117.8895	6.283106
93.14618	118.0926	6.282649
93.34618	118.2924	6.282040
93.54632	118.4899	6.281555
93.74618	118.6884	6.280753
93.94618	118.8867	6.280300
94.14801	119.0884	6.279582
94.34782	119.2899	6.279118
94.54784	119.4898	6.278570
94.74766	119.6859	6.277786
94.94782	119.8871	6.277218
95.14801	120.0872	6.276515
95.34782	120.2860	6.275850
95.54784	120.4852	6.275061
95.74800	120.6846	6.274467
95.94782	120.8885	6.273819
96.14782	121.0891	6.273026
96.34782	121.2933	6.272302
96.54784	121.4926	6.271602
96.74800	121.6909	6.270898
96.94868	121.8895	6.270104
97.15134	122.0893	6.269347
97.35116	122.2904	6.268501
97.55132	122.4923	6.267818
97.75116	122.6902	6.266916
97.95116	122.8884	6.266066
98.15100	123.0934	6.265283
98.35116	123.2898	6.264453
98.55132	123.4837	6.263639
98.75116	123.6851	6.262870
98.95116	123.8899	6.261929
99.15100	124.0907	6.261044
99.35116	124.2967	6.260220
99.55118	124.4992	6.259152
99.75134	124.6976	6.258338
99.95282	124.8937	6.257321
100.1553	125.0878	6.256330
100.3578	125.2874	6.255408
100.5613	125.4860	6.254472
100.7630	125.6632	6.253396
100.9643	125.8467	6.252356
101.1662	126.0405	6.251322
101.3662	126.2398	6.250288
101.5662	126.4225	6.249156
101.7663	126.6084	6.248144
101.9660	126.8037	6.247052
102.1662	127.0072	6.245865
102.3662	127.2162	6.244850
102.5662	127.4311	6.243750
102.7662	127.6466	6.242671
102.9660	127.8626	6.241663
103.1660	128.0733	6.240360
103.3660	128.2823	6.239222
103.5662	128.4880	6.237904
103.7662	128.6940	6.236670
103.9678	128.8928	6.235576
104.1712	129.0996	6.234245
104.3737	129.3107	6.232877
104.5762	129.5208	6.231634
104.7762	129.7224	6.230240
104.9762	129.9247	6.229004
105.1762	130.1277	6.227533
105.3762	130.3296	6.226136
105.5762	130.5257	6.224650
105.7762	130.7186	6.223336
105.9762	130.9143	6.221806
106.1762	131.1127	6.220350
106.3762	131.3134	6.218876
106.5762	131.5144	6.217474
106.7762	131.7136	6.215831
106.9762	131.9140	6.214300
107.1762	132.1140	6.212652
107.3778	132.3149	6.211031
107.5803	132.5166	6.209365
107.7828	132.7255	6.207770
107.9862	132.9324	6.206152
108.1878	133.1366	6.204449
108.3896	133.3371	6.202770
108.5930	133.5353	6.201084
108.7962	133.7389	6.199428
108.9978	133.9395	6.197735
109.1995	134.1374	6.195928
109.4030	134.3397	6.194182
109.6055	134.5398	6.192476
109.8080	134.7437	6.190640
110.0097	134.9480	6.188774
110.2127	135.1533	6.187016
110.4127	135.3573	6.185162
110.6128	135.5564	6.183335
110.8128	135.7555	6.181389
111.0128	135.9538	6.179325
111.2128	136.1518	6.177486
111.4128	136.3523	6.175530
111.6128	136.5537	6.173670
111.8128	136.7521	6.171742
112.0128	136.9521	6.169558
112.2128	137.1528	6.167480
112.4130	137.3508	6.165451
112.6130	137.5542	6.163394
112.8130	137.7592	6.161234
113.0146	137.9608	6.159180
113.2143	138.1586	6.156880
113.4145	138.3564	6.154738
113.6145	138.5542	6.152379
113.8145	138.7538	6.150220
114.0145	138.9516	6.147913
114.2147	139.1530	6.145540
114.4146	139.3550	6.143258
114.6143	139.5540	6.140842
114.8145	139.7534	6.138438
115.0145	139.9544	6.135976
115.2145	140.1569	6.133616
115.4145	140.3583	6.130994
115.6145	140.5550	6.128418
115.8145	140.7559	6.125874
116.0172	140.9579	6.123168
116.2210	141.1624	6.120330
116.4228	141.3624	6.117754
116.6228	141.5631	6.114724
116.8228	141.7673	6.112118
117.0228	141.9678	6.109394
117.2228	142.1664	6.106666
117.4228	142.3650	6.103699
117.6228	142.5658	6.100706
117.8228	142.7688	6.097982
118.0228	142.9651	6.094895
118.2230	143.1646	6.091882
118.4230	143.3631	6.088831
118.6228	143.5621	6.085726
118.8228	143.7654	6.082540
119.0228	143.9671	6.079426
119.2236	144.1644	6.076213
119.4280	144.3666	6.072792
119.6297	144.5700	6.069601
119.8312	144.7714	6.066239
120.0328	144.9749	6.062808
120.2362	145.1769	6.059394
120.4395	145.3778	6.055877
120.6412	145.5758	6.052516
120.8428	145.7794	6.048851
121.0462	145.9846	6.045124
121.2462	146.1864	6.041431
121.4462	146.3879	6.037645
121.6462	146.5900	6.034063
121.8462	146.7887	6.030094
122.0462	146.9866	6.026212
122.2462	147.1898	6.022334
122.4462	147.3902	6.018462
122.6462	147.5890	6.014462
122.8462	147.7874	6.010463
123.0462	147.9851	6.006390
123.2462	148.1862	6.002261
123.4462	148.3844	5.997825
123.6480	148.5836	5.993613
123.8496	148.7879	5.989510
124.0510	148.9899	5.985123
124.2510	149.1885	5.980734
124.4512	149.3892	5.976292
124.6512	149.5898	5.971807
124.8512	149.7910	5.967245
125.0512	149.9919	5.962755
125.2512	150.1919	5.957957
125.4512	150.3914	5.953281
125.6512	150.5914	5.948578
125.8512	150.7910	5.943714
126.0512	150.9930	5.938914
126.2512	151.1913	5.933886
126.4510	151.3925	5.928850
126.6510	151.5927	5.923690
126.8547	151.7943	5.918339
127.0562	151.9961	5.913116
127.2578	152.1981	5.907706
127.4612	152.4016	5.902111
127.6637	152.6048	5.896740
127.8645	152.8059	5.891162
128.0645	153.0070	5.885652
128.2645	153.2063	5.880124
128.4645	153.4053	5.874504
128.6645	153.6054	5.868760
128.8645	153.8049	5.862930
129.0645	154.0050	5.856838
129.2645	154.2011	5.851181
129.4645	154.3993	5.844882
129.6645	154.6002	5.838808
129.8645	154.8013	5.832590
130.0645	155.0041	5.826424
130.2645	155.2057	5.820069
130.4645	155.4059	5.813770
130.6645	155.6078	5.807300
130.8645	155.8079	5.800850
131.0645	156.0089	5.794201
131.2645	156.2067	5.787500
131.4645	156.4070	5.780787
131.6645	156.6030	5.773910
131.8645	156.7987	5.767138
132.0645	157.0012	5.760120
132.2645	157.2023	5.752958
132.4645	157.4052	5.745788
132.6645	157.6089	5.738379
132.8647	157.8085	5.731012
133.0672	158.0087	5.723446
133.2710	158.2100	5.715803
133.4728	158.4108	5.708268
133.6745	158.6123	5.700611
133.8778	158.8223	5.692621
134.0805	159.0208	5.684840
134.2827	159.2237	5.676812
134.4845	159.4235	5.668989
134.6878	159.6290	5.660469
134.8896	159.8293	5.652224
135.0930	160.0292	5.643724
135.2962	160.2332	5.635227
135.4978	160.4358	5.626780
135.6995	160.6348	5.618064
135.9030	160.8402	5.609068
136.1052	161.0424	5.600074
136.3078	161.2443	5.591457
136.5095	161.4476	5.582393
136.7128	161.6520	5.572959
136.9147	161.8569	5.563695
137.1168	162.0580	5.554278
137.3212	162.2601	5.544450
137.5228	162.4587	5.534856
137.7245	162.6648	5.525171
137.9280	162.8718	5.515064
138.1305	163.0743	5.505164
138.3327	163.2778	5.495110
138.5327	163.4771	5.484820
138.7328	163.6764	5.474549
138.9328	163.8761	5.464212
139.1328	164.0760	5.453808
139.3328	164.2727	5.443234
139.5328	164.4705	5.432669
139.7328	164.6680	5.421819
139.9328	164.8664	5.410979
140.1330	165.0685	5.399859
140.3330	165.2664	5.388456
140.5327	165.4664	5.377256
140.7327	165.6661	5.365742
140.9327	165.8676	5.354105
141.1347	166.0705	5.342373
141.3385	166.2742	5.330081
141.5412	166.4760	5.318061
141.7428	166.6788	5.305862
141.9462	166.8818	5.293051
142.1480	167.0850	5.280618
142.3505	167.2879	5.267887
142.5545	167.4918	5.254916
142.7562	167.6956	5.241934
142.9578	167.8946	5.229062
143.1595	168.0962	5.215958
143.3635	168.3051	5.202094
143.5662	168.5077	5.188624
143.7662	168.7062	5.174918
143.9662	168.9059	5.160942
144.1663	169.1030	5.147009
144.3660	169.3044	5.132850
144.5662	169.5041	5.118734
144.7662	169.7059	5.104500
144.9663	169.9040	5.089930
145.1663	170.1054	5.075386
145.3662	170.3047	5.060635
145.5662	170.5054	5.045713
145.7662	170.7060	5.030469
145.9662	170.9050	5.015463
146.1662	171.1042	4.999912
146.3662	171.3052	4.984324
146.5703	171.5115	4.967888
146.7728	171.7135	4.952017
146.9745	171.9161	4.935864
147.1778	172.1194	4.918884
147.3795	172.3204	4.902459
147.5820	172.5202	4.885833
147.7863	172.7234	4.868298
147.9877	172.9246	4.851256
148.1878	173.1280	4.834116
148.3878	173.3261	4.816817
148.5878	173.5240	4.799400
148.7878	173.7208	4.781742
148.9878	173.9228	4.763712
149.1880	174.1250	4.745663
149.3880	174.3263	4.727402
149.5880	174.5263	4.708964
149.7877	174.7293	4.690361
149.9878	174.9289	4.671350
150.1878	175.1282	4.652224
150.3878	175.3308	4.633026
150.5878	175.5284	4.613692
150.7887	175.7261	4.593876
150.9912	175.9294	4.574222
151.1928	176.1311	4.554250
151.3962	176.3344	4.532965
151.5978	176.5349	4.512588
151.8004	176.7373	4.491940
152.0045	176.9409	4.470156
152.2045	177.1396	4.449112
152.4045	177.3400	4.427812
152.6045	177.5408	4.406384
152.8045	177.7406	4.384585
153.0045	177.9392	4.362596
153.2045	178.1390	4.340230
153.4045	178.3385	4.317891
153.6045	178.5377	4.295239
153.8047	178.7405	4.272387
154.0044	178.9412	4.249344
154.2045	179.1415	4.226002
154.4045	179.3447	4.202378
154.6045	179.5446	4.178364
154.8045	179.7484	4.154482
155.0045	179.9474	4.130156
155.2045	180.1464	4.105606
155.4045	180.3433	4.080793
155.6047	180.5412	4.055672
155.8044	180.7399	4.030462
156.0045	180.9423	4.004889
156.2045	181.1420	3.979117
156.4045	181.3414	3.953221
156.6047	181.5415	3.926778
156.8047	181.7421	3.900198
157.0044	181.9420	3.873394
157.2044	182.1403	3.846072
157.4062	182.3451	3.818982
157.6078	182.5457	3.791280
157.8112	182.7490	3.762200
158.0130	182.9501	3.734012
158.2155	183.1507	3.705493
158.4178	183.3541	3.676800
158.6212	183.5566	3.646496
158.8228	183.7575	3.617386
159.0247	183.9589	3.587933
159.2278	184.1663	3.557394
159.4312	184.3723	3.526784
159.6330	184.5731	3.496458
159.8345	184.7700	3.465805
160.0378	184.9745	3.433535
160.2403	185.1801	3.402301
160.4447	185.3830	3.369422
160.6462	185.5823	3.337450
160.8478	185.7829	3.305365
161.0497	185.9894	3.272642
161.2535	186.1912	3.238459
161.4562	186.3964	3.205340
161.6580	186.5950	3.172096
161.8593	186.7928	3.138394
162.0628	186.9962	3.103038
162.2653	187.1979	3.068708
162.4697	187.4006	3.032582
162.6712	187.6015	2.997760
162.8728	187.8042	2.962604
163.0743	188.0070	2.927012
163.2745	188.2091	2.891230
163.4747	188.4097	2.855065
163.6745	188.6108	2.818688
163.8745	188.8108	2.781955
164.0745	189.0103	2.745016
164.2745	189.2114	2.707817
164.4747	189.4115	2.670240
164.6745	189.6128	2.632474
164.8746	189.8116	2.594184
165.0744	190.0120	2.555641
165.2745	190.2104	2.516792
165.4747	190.4105	2.477766
165.6744	190.6099	2.438318
165.8762	190.8129	2.398548
166.0797	191.0174	2.356866
166.2812	191.2175	2.316449
166.4838	191.4200	2.274953
166.6845	191.6206	2.234707
166.8845	191.8201	2.193405
167.0844	192.0204	2.151870
167.2845	192.2213	2.109927
167.4847	192.4206	2.067666
167.6845	192.6203	2.024954
167.8845	192.8182	1.982152
168.0844	193.0191	1.938946
168.2845	193.2200	1.895487
168.4847	193.4220	1.851814
168.6845	193.6238	1.807744
168.8845	193.8216	1.763312
169.0844	194.0202	1.718603
169.2845	194.2193	1.673709
169.4878	194.4227	1.626488
169.6895	194.6251	1.580805
169.8895	194.8282	1.535034
170.0897	195.0276	1.488689
170.2895	195.2277	1.442220
170.4895	195.4253	1.395404
170.6894	195.6249	1.348498
170.8895	195.8232	1.301059
171.0897	196.0234	1.253487
171.2895	196.2236	1.205484
171.4897	196.4245	1.157351
171.6895	196.6283	1.108928
171.8895	196.8301	1.060291
172.0894	197.0313	1.011467
172.2912	197.2334	0.9621957
172.4946	197.4325	0.9108312
172.6962	197.6337	0.8613366
172.8987	197.8349	0.8114795
173.1013	198.0354	0.7605650
173.3012	198.2338	0.7114770
173.5012	198.4359	0.6612049
173.7014	198.6363	0.6107615
173.9012	198.8362	0.5602672
174.1012	199.0366	0.5099760
174.3013	199.2358	0.4602667
174.5012	199.4387	0.4107722
174.7012	199.6402	0.3627500
174.9014	199.8363	0.3177812
175.1010	200.0366	0.2760687
175.3012	200.2340	0.2370465
175.5010	200.4341	0.2013428
175.7012	200.6386	0.1682364
175.9030	200.8432	0.1358888
176.1053	201.0422	0.1071534
176.3078	201.2423	0.08079688
176.5095	201.4444	0.05637281
176.7128	201.6478	0.03319989
176.9145	201.8519	0.01358101
177.1172	202.0542	-3.2556E-3
177.3177	202.2564	-.01475209
177.5178	202.4582	-.01716364
177.7178	202.6586	-.01752037
177.9176	202.8556	-.01785085
178.1178	203.0535	-.01780886
178.3180	203.2520	-.01778423
178.5178	203.4509	-.01788655
178.7178	203.6516	-.01808431
178.9178	203.8524	-.01813343
179.1180	204.0536	-.01821026
179.3180	204.2552	-.01817316
179.5178	204.4524	-.01830586
179.7178	204.6538	-.01830448
179.9178	204.8545	-.01833760
180.1212	205.0552	-.01834750
180.3237	205.2562	-.01845225
180.5278	205.4625	-.01848528
180.7297	205.6654	-.01845619
180.9312	205.8672	-.01849870
181.1328	206.0687	-.01857223
181.3368	206.2736	-.01877271
181.5395	206.4774	-.01877922
181.7412	206.6800	-.01889479
181.9447	206.8805	-.01870583
182.1460	207.0828	-.01862498
182.3486	207.2839	-.01871392
182.5528	207.4871	-.01877001
182.7547	207.6926	-.01873992
182.9562	207.8926	-.01891165
183.1578	208.0928	-.01889618
183.3622	208.2958	-.01887670
183.5645	208.4987	-.01902954
183.7663	208.7000	-.01902925
183.9676	208.8989	-.01904468
184.1712	209.1044	-.01904684
184.3712	209.3110	-.01901810
184.5713	209.5088	-.01903424
184.7712	209.7044	-.01907988
184.9712	209.9016	-.01908855
185.1710	210.1024	-.01917711
185.3712	210.3074	-.01912805
185.5713	210.5096	-.01908287
185.7712	210.7070	-.01913431
185.9713	210.9074	-.01924676
186.1712	211.1064	-.01934373
186.3712	211.3046	-.01935994
186.5712	211.5015	-.01939356
186.7728	211.7045	-.01940149
186.9747	211.9046	-.01943625
187.1745	212.1050	-.01942924
187.3745	212.3056	-.01932649
187.5745	212.5062	-.01938023
187.7745	212.7103	-.01936772
187.9744	212.9116	-.01946624
188.1745	213.1123	-.01944390
188.3746	213.3128	-.01937290
188.5745	213.5136	-.01941865
188.7747	213.7132	-.01947138
188.9745	213.9130	-.01955931
189.1747	214.1083	-.01950561
189.3745	214.3074	-.01937148
189.5746	214.5060	-.01938125
189.7762	214.7084	-.01939117
189.9797	214.9119	-.01943084
190.1812	215.1117	-.01968393
190.3830	215.3161	-.01967121
190.5845	215.5180	-.01977295
190.7888	215.7240	-.01976243
190.9912	215.9252	-.01992278
191.1947	216.1305	-.01995635
191.3962	216.3325	-.01983777
191.5980	216.5334	-.01991386
191.7978	216.7326	-.01990084
191.9980	216.9321	-.01988994
192.1978	217.1314	-.01990226
192.3980	217.3322	-.01983691
192.5978	217.5310	-.01998375
192.7980	217.7324	-.01999306
192.9978	217.9326	-.01993419
193.1978	218.1332	-.01992854
193.3976	218.3329	-.01998340
193.5978	218.5353	-.02013318
193.7977	218.7328	-.02010014
193.9978	218.9342	-.02012752
194.1996	219.1330	-.02027551
194.3995	219.3334	-.02020150
194.5995	219.5339	-.02021919
194.7994	219.7332	-.02026072
194.9995	219.9334	-.02013186
195.1996	220.1312	-.02032041
195.3995	220.3317	-.02029077
195.5997	220.5316	-.02023055
195.7995	220.7316	-.02020242
195.9995	220.9333	-.02023654
196.1996	221.1332	-.02024677
196.3995	221.3336	-.02040108
196.5997	221.5314	-.02039020
196.7995	221.7334	-.02026282
196.9995	221.9342	-.02041829
197.2035	222.1375	-.02038500
197.4062	222.3417	-.02042226
197.6078	222.5439	-.02043502
197.8095	222.7427	-.02048128
198.0127	222.9488	-.02056172
198.2153	223.1495	-.02047871
198.4176	223.3505	-.02056575
198.6212	223.5520	-.02062582
198.8226	223.7551	-.02057351
199.0228	223.9580	-.02061033
199.2227	224.1603	-.02057399
199.4228	224.3601	-.02063434
199.6227	224.5589	-.02059685
199.8228	224.7586	-.02062710
200.0230	224.9561	-.02070553
200.2228	225.1540	-.02075026
200.4228	225.3526	-.02077005
200.6227	225.5534	-.02072601
200.8228	225.7549	-.02065839
201.0230	225.9550	-.02059475
201.2228	226.1532	-.02056595
201.4236	226.3554	-.02066231
201.6244	226.5566	-.02074776
201.8245	226.7576	-.02068642
202.0247	226.9575	-.02077111
202.2245	227.1583	-.02080718
202.4245	227.3591	-.02076934
202.6244	227.5570	-.02071715
202.8245	227.7572	-.02075417
203.0247	227.9610	-.02068301
203.2245	228.1606	-.02067307
203.4245	228.3586	-.02087610
203.6244	228.5574	-.02094934
203.8245	228.7582	-.02070000
204.0247	228.9605	-.02088959
204.2245	229.1580	-.02075424
204.4262	229.3575	-.02092232
204.6305	229.5632	-.02089481
204.8328	229.7665	-.02087214
205.0363	229.9726	-.02077275
205.2378	230.1725	-.02084227
205.4395	230.3732	-.02074704
205.6430	230.5768	-.02077623
205.8462	230.7794	-.02078564
206.0478	230.9792	-.02084627
206.2496	231.1790	-.02085749
206.4512	231.3794	-.02093090
206.6512	231.5755	-.02094124
206.8514	231.7660	-.02107999
207.0512	231.9613	-.02106550
207.2512	232.1633	-.02102444
207.4514	232.3658	-.02102419
207.6514	232.5674	-.02110470
207.8512	232.7681	-.02107352
208.0512	232.9695	-.02107754
208.2513	233.1720	-.02118514
208.4512	233.3758	-.02106176
208.6512	233.5781	-.02102026
208.8514	233.7792	-.02106556
209.0527	233.9828	-.02115303
209.2545	234.1873	-.02102656
209.4562	234.3892	-.02101980
209.6580	234.5918	-.02114530
209.8610	234.7934	-.02105747
210.0645	235.0000	-.02105725
210.2662	235.2012	-.02105230
210.4695	235.4058	-.02103462
210.6712	235.6075	-.02088967
210.8737	235.8076	-.02094849
211.0778	236.0133	-.02086809
211.2797	236.2136	-.02110911
211.4810	236.4145	-.02103884
211.6812	236.6148	-.02098802
211.8812	236.8154	-.02081047
212.0812	237.0150	-.02085543
212.2812	237.2153	-.02104170
212.4812	237.4138	-.02073918
212.6812	237.6094	-.02100780
212.8812	237.8117	-.02098587
213.0812	238.0148	-.02095252
213.2813	238.2151	-.02091041
213.4812	238.4167	-.02106730
213.6812	238.6152	-.02109580
213.8813	238.8176	-.02079016
214.0813	239.0166	-.02094556
214.2830	239.2172	-.02093664
214.4847	239.4175	-.02100646
214.6877	239.6202	-.02094438
214.8895	239.8207	-.02099188
215.0895	240.0219	-.02083880
215.2895	240.2228	-.02085789
215.4895	240.4223	-.02105908
215.6895	240.6242	-.02097631
215.8895	240.8240	-.02092645
216.0895	241.0236	-.02097596
216.2895	241.2227	-.02090152
216.4895	241.4245	-.02099532
216.6895	241.6260	-.02101139
216.8895	241.8257	-.02103125
217.0895	242.0228	-.02114383
217.2895	242.2222	-.02106006
217.4895	242.4218	-.02114540
217.6912	242.6213	-.02120768
217.8947	242.8256	-.02107413
218.0963	243.0296	-.02101540
218.2988	243.2305	-.02106085
218.5013	243.4352	-.02099117
218.7047	243.6392	-.02103152
218.9062	243.8430	-.02085088
219.1078	244.0430	-.02075356
219.3120	244.2456	-.02070451
219.5145	244.4454	-.02090148
219.7162	244.6452	-.02101177
219.9195	244.8503	-.02090690
220.1212	245.0542	-.02081776
220.3235	245.2584	-.02094769
220.5264	245.4620	-.02086533
220.7295	245.6638	-.02107758
220.9312	245.8656	-.02099901
221.1328	246.0680	-.02098782
221.3344	246.2707	-.02085925
221.5347	246.4723	-.02096144
221.7347	246.6716	-.02088476
221.9345	246.8728	-.02070271
222.1345	247.0711	-.02088270
222.3345	247.2679	-.02091200
222.5345	247.4652	-.02089768
222.7344	247.6648	-.02094619
222.9347	247.8650	-.02095197
223.1347	248.0656	-.02092307
223.3345	248.2673	-.02084365
223.5345	248.4653	-.02098950
223.7345	248.6668	-.02088234
223.9362	248.8680	-.02095157
224.1378	249.0712	-.02094980
224.3395	249.2742	-.02085245
224.5428	249.4769	-.02095424
224.7462	249.6813	-.02095787
224.9476	249.8826	-.02073738
225.1497	250.0832	-.02089613
225.3528	250.2865	-.02086145
225.5553	250.4884	-.02105180
225.7578	250.6923	-.02102932
225.9595	250.8952	-.02096627
226.1628	251.0951	-.02102506
226.3644	251.2966	-.02097072
226.5670	251.4975	-.02105345
226.7710	251.7038	-.02085607
226.9727	251.9056	-.02084531
227.1746	252.1078	-.02080311
227.3763	252.3112	-.02082873
227.5804	252.5174	-.02088660
227.7828	252.7200	-.02091386
227.9862	252.9244	-.02092276
228.1878	253.1215	-.02108670
228.3895	253.3219	-.02104235
228.5920	253.5247	-.02102905
228.7927	253.7264	-.02105242
228.9930	253.9284	-.02100014
229.1928	254.1275	-.02077701
229.3928	254.3276	-.02065730
229.5928	254.5249	-.02077519
229.7928	254.7246	-.02074821
229.9928	254.9237	-.02061800
230.1928	255.1233	-.02059509
230.3928	255.3251	-.02062276
230.5927	255.5248	-.02062842
230.7930	255.7256	-.02072311
230.9930	255.9244	-.02078599
231.1927	256.1260	-.02060469
231.3927	256.3282	-.02068214
231.5928	256.5294	-.02075525
231.7928	256.7264	-.02073754
231.9928	256.9242	-.02080200
232.1928	257.1264	-.02081289
232.3928	257.3268	-.02071886
232.5928	257.5256	-.02080755
232.7928	257.7293	-.02076603
232.9928	257.9300	-.02074896
233.1928	258.1283	-.02092949
233.3928	258.3274	-.02064701
233.5928	258.5228	-.02092755
233.7928	258.7238	-.02073623
233.9937	258.9232	-.02075058
234.1962	259.1273	-.02081172
234.3978	259.3310	-.02079851
234.5995	259.5336	-.02071227
234.8012	259.7326	-.02072213
235.0052	259.9387	-.02052625
235.2080	260.1438	-.02053789
235.4112	260.3465	-.02054439
235.6128	260.5455	-.02046203
235.8145	260.7480	-.02054006
236.0170	260.9496	-.02054713
236.2213	261.1538	-.02054231
236.4230	261.3549	-.02064605
236.6246	261.5558	-.02062805
236.8278	261.7614	-.02061378
237.0303	261.9636	-.02064068
237.2328	262.1670	-.02063803
237.4347	262.3690	-.02057530
237.6380	262.5693	-.02062549
237.8395	262.7719	-.02069260
238.0420	262.9764	-.02072748
238.2426	263.1780	-.02061888
238.4430	263.3776	-.02064898
238.6428	263.5788	-.02065214
238.8428	263.7798	-.02062441
239.0428	263.9787	-.02060658
239.2430	264.1765	-.02062328
239.4430	264.3752	-.02070436
239.6428	264.5750	-.02051215
239.8428	264.7778	-.02053847
240.0427	264.9768	-.02048732
240.2430	265.1754	-.02067335
240.4428	265.3768	-.02062047
240.6428	265.5787	-.02057268
240.8427	265.7779	-.02050076
241.0463	265.9781	-.02059542
241.2487	266.1798	-.02073844
241.4495	266.3829	-.02062617
241.6495	266.5854	-.02050803
241.8496	266.7828	-.02054541
242.0495	266.9822	-.02057466
242.2495	267.1828	-.02053423
242.4496	267.3810	-.02063619
242.6495	267.5842	-.02070001
242.8495	267.7825	-.02076365
243.0495	267.9846	-.02054988
243.2493	268.1847	-.02060626
243.4496	268.3844	-.02068116
243.6495	268.5849	-.02053799
243.8495	268.7824	-.02039556
244.0496	268.9826	-.02040644
244.2513	269.1818	-.02038403
244.4554	269.3860	-.02033840
244.6562	269.5860	-.02033265
244.8564	269.7874	-.02045755
245.0562	269.9879	-.02047694
245.2562	270.1885	-.02038676
245.4562	270.3898	-.02024237
245.6563	270.5896	-.02033818
245.8564	270.7902	-.02032942
246.0562	270.9900	-.02033095
246.2562	271.1887	-.02033961
246.4562	271.3902	-.02019653
246.6563	271.5900	-.02016969
246.8562	271.7880	-.02019663
247.0562	271.9881	-.02030021
247.2578	272.1903	-.02025961
247.4576	272.3902	-.02032326
247.6580	272.5909	-.02026758
247.8578	272.7922	-.02022020
248.0578	272.9918	-.02030651
248.2576	273.1910	-.02023470
248.4580	273.3920	-.02026184
248.6578	273.5903	-.02020724
248.8578	273.7928	-.02022749
249.0578	273.9954	-.02006960
249.2576	274.1922	-.02012610
249.4580	274.3926	-.02029165
249.6580	274.5928	-.02006876
249.8595	274.7946	-.02010231
250.0628	274.9969	-.02015724
250.2628	275.1956	-.02030519
250.4628	275.3957	-.02023237
250.6627	275.5959	-.02016511
250.8630	275.7966	-.02000819
251.0630	275.9956	-.02000688
251.2630	276.1940	-.01994518
251.4630	276.3925	-.02005616
251.6630	276.5947	-.01984895
251.8630	276.7934	-.02001878
252.0630	276.9935	-.02002704
252.2628	277.1942	-.02001812
252.4628	277.3954	-.01998079
252.6628	277.5965	-.01995387
252.8644	277.7967	-.01988510
253.0672	278.0028	-.01974156
253.2713	278.2046	-.01978129
253.4730	278.4055	-.01994583
253.6745	278.6084	-.01978760
253.8778	278.8104	-.01996403
254.0804	279.0122	-.01982923
254.2812	279.2136	-.01986093
254.4810	279.4117	-.01987774
254.6814	279.6132	-.01980638
254.8813	279.8130	-.01989700
255.0812	280.0142	-.01985651
255.2812	280.2132	-.01981649
255.4812	280.4150	-.01951997
255.6812	280.6146	-.01976708
255.8813	280.8134	-.01996861
256.0813	281.0138	-.01999402
256.2812	281.2134	-.01999043
256.4812	281.4132	-.02007015
256.6812	281.6145	-.01988230
256.8814	281.8159	-.01982092
257.0828	282.0163	-.01987253
257.2870	282.2219	-.01986156
257.4893	282.4246	-.01974114
257.6912	282.6244	-.01986150
257.8945	282.8286	-.01989348
258.0960	283.0299	-.01978235
258.2988	283.2324	-.01981439
258.5028	283.4365	-.01985906
258.7044	283.6370	-.01985086
258.9062	283.8400	-.01990405
259.1078	284.0428	-.01976775
259.3120	284.2444	-.01992680
259.5147	284.4455	-.01991598
259.7163	284.6485	-.01990832
259.9195	284.8518	-.01980592
260.1211	285.0532	-.01984665
260.3226	285.2562	-.01978603
260.5230	285.4564	-.01981234
260.7228	285.6609	-.01987987
260.9228	285.8598	-.01986424
261.1230	286.0606	-.01984210
261.3228	286.2583	-.01981454
261.5227	286.4560	-.01988306
261.7230	286.6558	-.01978086
261.9228	286.8535	-.01976980
262.1227	287.0517	-.01988641
262.3230	287.2520	-.01985239
262.5228	287.4543	-.01992949
262.7228	287.6574	-.01992835
262.9246	287.8582	-.02007293
263.1278	288.0618	-.02006521
263.3295	288.2623	-.01989442
263.5320	288.4650	-.02004696
263.7346	288.6703	-.01981271
263.9378	288.8735	-.01973756
264.1395	289.0744	-.01972677
264.3410	289.2742	-.01980101
264.5413	289.4741	-.01977614
264.7412	289.6734	-.01963496
264.9412	289.8726	-.01968306
265.1412	290.0711	-.01961572
265.3412	290.2716	-.01949919
265.5413	290.4720	-.01957928
265.7413	290.6728	-.01956497
265.9412	290.8723	-.01966512
266.1412	291.0740	-.01965716
266.3410	291.2737	-.01979491
266.5413	291.4750	-.01978755
266.7412	291.6777	-.01977428
266.9412	291.8773	-.01965271
267.1445	292.0778	-.01965528
267.3462	292.2768	-.01974865
267.5476	292.4792	-.01978850
267.7477	292.6798	-.01974025
267.9480	292.8800	-.01973916
268.1480	293.0810	-.01965269
268.3480	293.2818	-.01951658
268.5478	293.4793	-.01967022
268.7478	293.6809	-.01965981
268.9478	293.8789	-.01974562
269.1478	294.0830	-.01959163
269.3478	294.2812	-.01968179
269.5478	294.4824	-.01971249
269.7477	294.6822	-.01971588
269.9480	294.8834	-.01961943
270.1496	295.0830	-.01957530
270.3528	295.2880	-.01953567
270.5545	295.4911	-.01947366
270.7562	295.6910	-.01945684
270.9562	295.8904	-.01942639
271.1562	296.0892	-.01954034
271.3562	296.2879	-.01956948
271.5562	296.4913	-.01950254
271.7562	296.6900	-.01942148
271.9560	296.8894	-.01933984
272.1560	297.0899	-.01939589
272.3563	297.2899	-.01947720
272.5562	297.4910	-.01958082
272.7562	297.6914	-.01944687
272.9562	297.8890	-.01945809
273.1562	298.0870	-.01938573
273.3578	298.2900	-.01919402
273.5595	298.4901	-.01933605
273.7627	298.6938	-.01940395
273.9646	298.8972	-.01940160
274.1680	299.1020	-.01947477
274.3711	299.3056	-.01934636
274.5728	299.5075	-.01946031
274.7745	299.7058	-.01943720
274.9778	299.9100	-.01932905