File: TGA/2023_07_12_CBD_powder_1cpm.txt
CLOSED
Version	0.4
Run	873
Instrument	2950 TGA       V5.4A
Module	TGA 1000 øC
Sample	2023_07_12_CBD_powder_1cpm
Size	6.56300	mg
Method	50C to 300C at 1 cpm
Operator	SBK
Comment	2023_07_12_CBD_powder_1cpm
Xcomment	Pan: Platinum           Gas1: Nitrogen  40          Gas2: Nitrogen  40
Text	2023_07_12_CBD_powder_1cpm
Text	First run with CBD powder after new calib
Kcell	1.00000
TempCal	2	pts	156.68	152.50,	376.53	354.00
Thresholds	0.050	0.0000
Controls	Gas 1  Event Off  Sampling 2.0 sec/pt
Nsig	3
Sig1	Time (min)
Sig2	Temperature (øC)
Sig3	Weight (mg)
Date	12-Jul-23
Time	11:54
File	C:\TA\Data\TGA\Skyler\2023_07_12_CBD_powder_1cpm.001
OrgFile	C:\TA\Data\TGA\Skyler\2023_07_12_CBD_powder_1cpm.001
StartOfData
0.0000000	50.09705	6.554302
0.1328334	50.12196	6.554221
0.2661666	50.18122	6.554238
0.3995000	50.25868	6.554272
0.5325000	50.35131	6.554181
0.6658334	50.45870	6.554125
0.7995000	50.57460	6.553909
0.9328332	50.69766	6.553816
1.066167	50.82791	6.553701
1.199500	50.96119	6.553658
1.332833	51.09368	6.553549
1.466166	51.23410	6.553565
1.599500	51.37016	6.553521
1.732834	51.50609	6.553558
1.866167	51.64044	6.553490
1.999500	51.77176	6.553435
2.132666	51.90429	6.553387
2.266000	52.03306	6.553181
2.399333	52.16266	6.553193
2.532667	52.29394	6.553196
2.667833	52.42846	6.553110
2.800833	52.56250	6.553172
2.935166	52.69458	6.553108
3.069333	52.82642	6.553021
3.204334	52.95908	6.552936
3.341000	53.09611	6.552981
3.476000	53.22558	6.552954
3.609334	53.35084	6.552898
3.742666	53.48069	6.552851
3.877667	53.61662	6.552859
4.012666	53.75088	6.552731
4.147666	53.88384	6.552705
4.282666	54.01996	6.552638
4.417666	54.15678	6.552650
4.552666	54.29260	6.552608
4.686000	54.42412	6.552612
4.819166	54.55997	6.552735
4.952500	54.70126	6.552700
5.085834	54.84140	6.552630
5.219334	54.97870	6.552580
5.352666	55.10918	6.552495
5.486000	55.24537	6.552432
5.619334	55.37950	6.552350
5.752500	55.51232	6.552280
5.886166	55.64399	6.552282
6.019500	55.77276	6.552231
6.152832	55.90193	6.552228
6.286168	56.03324	6.552192
6.419500	56.16416	6.552208
6.552832	56.29632	6.552210
6.686000	56.42992	6.552136
6.819334	56.56222	6.552121
6.952666	56.69738	6.552030
7.086168	56.83068	6.551982
7.219500	56.96460	6.552014
7.352832	57.09832	6.552100
7.485832	57.23157	6.551962
7.619166	57.36526	6.551865
7.752500	57.50139	6.551698
7.885832	57.63637	6.551780
8.021000	57.77240	6.551750
8.155166	57.90700	6.551772
8.289334	58.03943	6.551650
8.426000	58.17747	6.551718
8.561000	58.31694	6.551614
8.696000	58.45222	6.551563
8.830168	58.59020	6.551618
8.964334	58.72366	6.551520
9.101000	58.86184	6.551424
9.234332	58.99488	6.551421
9.369332	59.12463	6.551438
9.503668	59.25844	6.551492
9.637832	59.38626	6.551314
9.772500	59.51422	6.551279
9.906000	59.64838	6.551287
10.03933	59.78198	6.551230
10.17267	59.91700	6.551274
10.30600	60.05276	6.551135
10.43933	60.18764	6.551120
10.57267	60.32264	6.551010
10.70600	60.45611	6.551099
10.83934	60.58709	6.551100
10.97267	60.71826	6.551002
11.10617	60.84894	6.550910
11.23950	60.97882	6.550850
11.37250	61.11093	6.550874
11.50600	61.24885	6.550850
11.63934	61.38616	6.550793
11.77267	61.52314	6.550719
11.90600	61.65547	6.550610
12.03950	61.79132	6.550582
12.17250	61.91992	6.550528
12.30600	62.05548	6.550420
12.43933	62.18994	6.550390
12.57434	62.32320	6.550248
12.70783	62.45370	6.550332
12.84100	62.58882	6.550176
12.97767	62.72989	6.550138
13.11100	62.86429	6.550043
13.24617	63.00108	6.550059
13.38033	63.13449	6.550041
13.51434	63.27182	6.550048
13.65100	63.40964	6.550146
13.78600	63.54589	6.549804
13.91934	63.67793	6.549878
14.05367	63.80718	6.549762
14.18784	63.94101	6.549714
14.32250	64.07978	6.549844
14.45934	64.22172	6.549745
14.59266	64.34961	6.549759
14.72684	64.47716	6.549630
14.86117	64.61284	6.549576
14.99583	64.74746	6.549643
15.12934	64.87562	6.549459
15.26266	65.01238	6.549511
15.39600	65.15110	6.549387
15.52934	65.28863	6.549160
15.66283	65.42208	6.549198
15.79617	65.55224	6.549293
15.92917	65.68634	6.549176
16.06266	65.82366	6.549084
16.19600	65.96366	6.548873
16.32934	66.09856	6.548778
16.46267	66.23166	6.548562
16.59600	66.36543	6.548243
16.72950	66.49757	6.548125
16.86283	66.62992	6.547982
16.99600	66.76012	6.548054
17.12934	66.88999	6.547962
17.26266	67.02388	6.547866
17.39600	67.16049	6.547852
17.52934	67.29587	6.547770
17.66266	67.43184	6.547744
17.79600	67.56320	6.547739
17.92934	67.68968	6.547605
18.06266	67.81766	6.547669
18.19934	67.95514	6.547635
18.33450	68.08766	6.547566
18.46784	68.21814	6.547520
18.60167	68.35304	6.547504
18.73584	68.48844	6.547568
18.87117	68.62819	6.547410
19.00616	68.77016	6.547342
19.14250	68.90925	6.547234
19.27683	69.04538	6.547174
19.41100	69.17760	6.547045
19.54434	69.30854	6.547053
19.67934	69.44090	6.547082
19.81600	69.57703	6.547070
19.95016	69.71088	6.546961
20.08434	69.84694	6.546858
20.21934	69.97816	6.546832
20.35267	70.11036	6.546765
20.48600	70.24110	6.546713
20.61934	70.37536	6.546720
20.75266	70.50640	6.546734
20.88600	70.63824	6.546650
21.01934	70.75950	6.546536
21.15284	70.88906	6.546636
21.28617	71.02050	6.546670
21.41950	71.15118	6.546686
21.55284	71.28801	6.546726
21.68617	71.42282	6.546601
21.81950	71.56312	6.546496
21.95250	71.69960	6.546503
22.08600	71.83512	6.546630
22.21934	71.97438	6.546487
22.35266	72.10501	6.546430
22.48600	72.23929	6.546240
22.61934	72.36931	6.546430
22.75266	72.51030	6.546339
22.88600	72.64650	6.546306
23.01934	72.77944	6.546332
23.15266	72.91206	6.546203
23.28600	73.04000	6.546265
23.42100	73.17326	6.546190
23.55766	73.31482	6.546256
23.69266	73.44839	6.546094
23.82684	73.58080	6.546086
23.96100	73.71700	6.546039
24.09600	73.84766	6.546088
24.23266	73.98258	6.546168
24.36766	74.11426	6.546042
24.50100	74.24585	6.546118
24.63433	74.38555	6.546106
24.76934	74.52229	6.546023
24.90434	74.66114	6.545989
25.03766	74.80020	6.545880
25.17100	74.94011	6.545828
25.30417	75.07413	6.545862
25.43784	75.20911	6.545836
25.57117	75.34234	6.545821
25.70434	75.47571	6.545746
25.83767	75.61094	6.545882
25.97100	75.74568	6.545730
26.10434	75.87197	6.545661
26.23767	76.00611	6.545620
26.37100	76.14062	6.545624
26.50434	76.27241	6.545625
26.63767	76.40700	6.545513
26.77117	76.54111	6.545581
26.90434	76.67637	6.545632
27.03766	76.80626	6.545584
27.17100	76.93594	6.545526
27.30434	77.06712	6.545440
27.43766	77.19384	6.545536
27.57084	77.32030	6.545605
27.70450	77.45262	6.545569
27.83783	77.58622	6.545532
27.97117	77.72226	6.545482
28.10416	77.84588	6.545430
28.23916	77.97962	6.545406
28.37417	78.12168	6.545180
28.50950	78.25904	6.545244
28.64284	78.39544	6.545264
28.77784	78.53169	6.545196
28.91266	78.67251	6.545022
29.04766	78.80976	6.545016
29.18266	78.94410	6.545059
29.31766	79.07993	6.544961
29.45283	79.21684	6.545080
29.58783	79.35030	6.545049
29.72266	79.48725	6.544772
29.85766	79.62422	6.544891
29.99266	79.75649	6.544819
30.12600	79.88812	6.544683
30.25933	80.01934	6.544698
30.39266	80.15005	6.544644
30.52583	80.28250	6.544576
30.65950	80.41722	6.544624
30.79284	80.54809	6.544440
30.92600	80.68356	6.544530
31.05933	80.81806	6.544504
31.19266	80.94420	6.544412
31.32600	81.07836	6.544574
31.45933	81.21340	6.544522
31.59266	81.34578	6.544602
31.72583	81.47844	6.544526
31.85917	81.61293	6.544510
31.99250	81.74905	6.544609
32.12617	81.88003	6.544414
32.25950	82.01336	6.544421
32.39284	82.14676	6.544450
32.52600	82.27944	6.544301
32.65933	82.41569	6.544439
32.79266	82.54796	6.544196
32.92600	82.68236	6.544062
33.05933	82.81282	6.544109
33.19284	82.94395	6.544223
33.32784	83.07886	6.544128
33.46250	83.21415	6.544195
33.59600	83.34695	6.543990
33.72917	83.47806	6.543972
33.86250	83.61234	6.543844
33.99617	83.74742	6.543904
34.12950	83.88134	6.543758
34.26283	84.01663	6.543806
34.39617	84.15051	6.543713
34.52950	84.28342	6.543722
34.66284	84.41584	6.543687
34.79617	84.54871	6.543652
34.92950	84.68574	6.543640
35.06283	84.81728	6.543586
35.19617	84.95106	6.543474
35.32916	85.08247	6.543352
35.46250	85.21476	6.543348
35.59583	85.34592	6.543326
35.72917	85.47574	6.543274
35.86250	85.61061	6.543200
35.99584	85.74672	6.543088
36.12933	85.87799	6.543218
36.26266	86.01139	6.543242
36.39600	86.14424	6.543152
36.53100	86.28087	6.543175
36.66766	86.41789	6.543140
36.80100	86.55224	6.543135
36.93433	86.68598	6.543037
37.06766	86.82144	6.543056
37.20100	86.95508	6.542940
37.33433	87.09009	6.542998
37.46766	87.22313	6.542870
37.60100	87.35629	6.542891
37.73433	87.48884	6.542859
37.86767	87.62270	6.542906
38.00100	87.75542	6.542874
38.13434	87.88734	6.542812
38.26766	88.02238	6.543015
38.40100	88.15649	6.542868
38.53433	88.28999	6.542872
38.66766	88.42164	6.542810
38.80100	88.55236	6.542646
38.93433	88.68549	6.542598
39.06766	88.81874	6.542770
39.20117	88.95169	6.542728
39.33417	89.08459	6.542524
39.46766	89.21588	6.542500
39.60100	89.34950	6.542288
39.73433	89.48225	6.542457
39.86767	89.61686	6.542299
40.00183	89.75056	6.542226
40.13617	89.88466	6.542163
40.27117	90.01864	6.542070
40.40584	90.15592	6.542032
40.53933	90.29093	6.542050
40.67267	90.42442	6.542046
40.80600	90.55914	6.542004
40.93933	90.69126	6.541842
41.07266	90.82399	6.541835
41.20600	90.95834	6.541830
41.33933	91.08866	6.541654
41.47283	91.22319	6.541512
41.60617	91.35801	6.541488
41.73916	91.49312	6.541418
41.87266	91.62705	6.541314
42.00600	91.75926	6.541285
42.13933	91.89129	6.541312
42.27266	92.02168	6.541210
42.40616	92.15309	6.541127
42.53916	92.28876	6.541080
42.67250	92.42195	6.540992
42.80600	92.55680	6.540934
42.93934	92.68938	6.540884
43.07266	92.82141	6.540832
43.20600	92.95469	6.540640
43.33950	93.08741	6.540805
43.47283	93.21991	6.540882
43.60783	93.35608	6.540652
43.74117	93.49265	6.540671
43.87533	93.62592	6.540630
44.00950	93.75660	6.540574
44.14450	93.89078	6.540510
44.27934	94.02644	6.540471
44.41434	94.16412	6.540404
44.54933	94.30411	6.540342
44.68433	94.44151	6.540246
44.81783	94.57511	6.540280
44.95284	94.70914	6.540246
45.08766	94.84259	6.540040
45.22183	94.97284	6.540030
45.35600	95.10566	6.540034
45.49283	95.24539	6.539880
45.62617	95.37778	6.539732
45.76117	95.51231	6.539606
45.89533	95.64545	6.539600
46.02950	95.77666	6.539527
46.16450	95.90850	6.539380
46.29916	96.03992	6.539316
46.43584	96.17578	6.539236
46.56917	96.30922	6.539075
46.70266	96.44166	6.539043
46.83600	96.57661	6.538843
46.96933	96.71059	6.538794
47.10266	96.84825	6.538629
47.23600	96.98613	6.538526
47.36934	97.12201	6.538537
47.50266	97.25414	6.538481
47.63617	97.38459	6.538364
47.76950	97.51762	6.538300
47.90283	97.65118	6.538306
48.03583	97.78676	6.538129
48.16934	97.92331	6.538076
48.30266	98.05464	6.538004
48.43600	98.18625	6.537869
48.56933	98.31942	6.537859
48.70284	98.45211	6.537812
48.83584	98.58559	6.537841
48.96933	98.71863	6.537676
49.10266	98.85082	6.537588
49.23600	98.98687	6.537646
49.36934	99.11828	6.537590
49.50284	99.25362	6.537426
49.63584	99.38694	6.537314
49.76933	99.52031	6.537210
49.90266	99.65214	6.537246
50.03766	99.78819	6.537129
50.17283	99.92103	6.536976
50.30783	100.0574	6.536996
50.44083	100.1912	6.536746
50.57434	100.3272	6.536700
50.70767	100.4604	6.536660
50.84100	100.5935	6.536512
50.97434	100.7281	6.536444
51.10766	100.8652	6.536389
51.24100	100.9999	6.536296
51.37434	101.1313	6.536120
51.50766	101.2647	6.535958
51.64100	101.3969	6.535902
51.77434	101.5305	6.535800
51.90766	101.6639	6.535575
52.04100	101.7997	6.535562
52.17433	101.9336	6.535344
52.30766	102.0651	6.535250
52.44117	102.1981	6.535147
52.57450	102.3340	6.535168
52.70750	102.4640	6.534942
52.84100	102.5979	6.534834
52.97434	102.7326	6.534745
53.10766	102.8648	6.534563
53.24268	103.0003	6.534599
53.37617	103.1325	6.534371
53.51116	103.2680	6.534207
53.64500	103.4021	6.534234
53.77934	103.5356	6.534089
53.91250	103.6663	6.533876
54.04600	103.7980	6.533689
54.17934	103.9334	6.533609
54.31268	104.0663	6.533479
54.44600	104.1992	6.533272
54.57934	104.3327	6.533124
54.71266	104.4659	6.533202
54.84600	104.5998	6.533054
54.97934	104.7352	6.532940
55.11266	104.8688	6.532840
55.24600	105.0005	6.532836
55.37934	105.1317	6.532480
55.51283	105.2633	6.532358
55.64617	105.3966	6.532169
55.77934	105.5312	6.532032
55.91266	105.6664	6.531838
56.04582	105.8002	6.531836
56.17950	105.9323	6.531347
56.31283	106.0646	6.531428
56.44617	106.1952	6.531024
56.58116	106.3309	6.530924
56.71617	106.4631	6.530761
56.84918	106.5966	6.530561
56.98250	106.7321	6.530303
57.11582	106.8669	6.530255
57.24918	107.0038	6.530132
57.38250	107.1370	6.529792
57.51582	107.2676	6.529706
57.64950	107.3989	6.529404
57.78283	107.5288	6.529109
57.91617	107.6598	6.529000
58.04950	107.7942	6.528724
58.18284	107.9271	6.528410
58.31617	108.0623	6.528358
58.44950	108.2011	6.528015
58.58266	108.3366	6.527965
58.71600	108.4734	6.527930
58.84934	108.6039	6.527686
58.98266	108.7350	6.527478
59.11600	108.8654	6.527305
59.24934	108.9952	6.527014
59.38266	109.1305	6.526819
59.51582	109.2679	6.526606
59.64950	109.4016	6.526400
59.78450	109.5354	6.526258
59.91950	109.6694	6.526059
60.05350	109.8031	6.525910
60.18768	109.9356	6.525642
60.32434	110.0751	6.525482
60.45933	110.2134	6.525210
60.59266	110.3480	6.525125
60.72683	110.4832	6.524951
60.86100	110.6169	6.524762
60.99600	110.7527	6.524512
61.13266	110.8890	6.524218
61.26766	111.0207	6.524020
61.40100	111.1540	6.523726
61.53433	111.2809	6.523554
61.66934	111.4144	6.523268
61.80266	111.5472	6.522984
61.93600	111.6807	6.522744
62.06950	111.8145	6.522474
62.20283	111.9475	6.522339
62.33600	112.0796	6.522046
62.46934	112.2143	6.521626
62.60266	112.3462	6.521682
62.73600	112.4747	6.521250
62.86934	112.6144	6.520974
63.00266	112.7518	6.520637
63.13600	112.8894	6.520413
63.26934	113.0241	6.520126
63.40266	113.1602	6.519888
63.53618	113.2925	6.519607
63.66950	113.4257	6.519250
63.80283	113.5584	6.518962
63.93616	113.6929	6.518655
64.06934	113.8233	6.518354
64.20266	113.9521	6.518116
64.33600	114.0808	6.518025
64.46933	114.2129	6.517652
64.60266	114.3450	6.517241
64.73600	114.4772	6.516946
64.86933	114.6120	6.516662
65.00250	114.7460	6.516230
65.13783	114.8805	6.515972
65.27283	115.0177	6.515582
65.40766	115.1523	6.515335
65.54266	115.2930	6.515004
65.67766	115.4282	6.514670
65.81268	115.5623	6.514336
65.94682	115.6938	6.513948
66.08118	115.8240	6.513616
66.21616	115.9591	6.513305
66.35116	116.0938	6.513007
66.48600	116.2290	6.512812
66.62016	116.3663	6.512458
66.75434	116.5038	6.512018
66.89100	116.6415	6.511650
67.02600	116.7773	6.511374
67.15932	116.9108	6.511035
67.29350	117.0452	6.510548
67.42766	117.1778	6.510266
67.56284	117.3059	6.509663
67.69782	117.4391	6.509443
67.83282	117.5706	6.509024
67.96700	117.7042	6.508715
68.10082	117.8400	6.508334
68.23584	117.9766	6.507995
68.37100	118.1166	6.507537
68.50600	118.2471	6.507011
68.64100	118.3814	6.506568
68.77600	118.5135	6.506182
68.90932	118.6527	6.505831
69.04434	118.7938	6.505366
69.17934	118.9302	6.504882
69.31350	119.0586	6.504403
69.44782	119.1953	6.504082
69.58450	119.3334	6.503539
69.71782	119.4664	6.503087
69.85082	119.5991	6.502722
69.98434	119.7337	6.502353
70.11768	119.8628	6.501903
70.25100	119.9931	6.501311
70.38432	120.1282	6.500968
70.51768	120.2575	6.500510
70.65100	120.3759	6.499829
70.78432	120.4916	6.499549
70.91766	120.6031	6.499084
71.05118	120.7103	6.498691
71.18450	120.8213	6.498226
71.31766	120.9413	6.497500
71.45100	121.0728	6.497332
71.58434	121.2070	6.496771
71.71766	121.3483	6.496384
71.85100	121.4917	6.495747
71.98450	121.6363	6.495390
72.11750	121.7794	6.494885
72.25100	121.9236	6.494230
72.38432	122.0666	6.493689
72.51768	122.2124	6.493161
72.65100	122.3580	6.492595
72.78600	122.5020	6.492000
72.92116	122.6460	6.491639
73.05782	122.7887	6.490958
73.19200	122.9275	6.490368
73.32616	123.0656	6.489816
73.46100	123.2024	6.489135
73.59432	123.3366	6.488500
73.72766	123.4728	6.487974
73.86100	123.6060	6.487375
73.99432	123.7413	6.486757
74.12782	123.8764	6.486120
74.26084	124.0099	6.485546
74.39434	124.1418	6.484834
74.52766	124.2760	6.484312
74.66100	124.4075	6.483608
74.79450	124.5426	6.483056
74.92750	124.6768	6.482340
75.06100	124.8123	6.481680
75.19434	124.9442	6.481238
75.32766	125.0770	6.480515
75.46100	125.2109	6.479807
75.59450	125.3414	6.479031
75.72766	125.4742	6.478360
75.86100	125.6088	6.477698
75.99432	125.7434	6.476960
76.12768	125.8784	6.476324
76.26100	126.0146	6.475676
76.39434	126.1509	6.474930
76.52766	126.2829	6.474160
76.66116	126.4143	6.473340
76.79450	126.5453	6.472599
76.92918	126.6782	6.471844
77.06332	126.8115	6.471230
77.19766	126.9456	6.470588
77.33100	127.0796	6.469610
77.46432	127.2129	6.469043
77.59766	127.3468	6.468028
77.73084	127.4826	6.467386
77.86432	127.6170	6.466440
77.99766	127.7499	6.465624
78.13116	127.8822	6.464930
78.26450	128.0149	6.464097
78.39766	128.1461	6.463098
78.53100	128.2777	6.462305
78.66432	128.4151	6.461566
78.79766	128.5466	6.460678
78.93116	128.6778	6.459863
79.06450	128.8091	6.459072
79.19766	128.9402	6.458130
79.33100	129.0730	6.457205
79.46432	129.2094	6.456306
79.59782	129.3401	6.455394
79.73084	129.4773	6.454556
79.86432	129.6096	6.453730
79.99766	129.7447	6.452759
80.13432	129.8793	6.451810
80.26782	130.0126	6.450790
80.40100	130.1454	6.449896
80.53600	130.2779	6.448926
80.67100	130.4147	6.447947
80.80600	130.5516	6.446957
80.94100	130.6860	6.446028
81.07600	130.8218	6.445066
81.20934	130.9549	6.444060
81.34450	131.0920	6.442963
81.47950	131.2269	6.442188
81.61334	131.3588	6.441044
81.74766	131.4925	6.440109
81.88432	131.6290	6.439026
82.01766	131.7637	6.437945
82.15282	131.8993	6.436799
82.28668	132.0338	6.435810
82.42100	132.1681	6.434757
82.55434	132.3048	6.433814
82.68768	132.4394	6.432795
82.82100	132.5731	6.431695
82.95450	132.7039	6.430394
83.08768	132.8364	6.429403
83.22100	132.9703	6.428360
83.35434	133.1021	6.427032
83.48782	133.2367	6.425968
83.62084	133.3686	6.424907
83.75434	133.5008	6.423604
83.88766	133.6366	6.422479
84.02101	133.7721	6.421412
84.15434	133.9029	6.420154
84.28782	134.0371	6.419026
84.42118	134.1673	6.417736
84.55450	134.2996	6.416618
84.68782	134.4306	6.415289
84.82082	134.5647	6.414076
84.95434	134.6978	6.412680
85.08768	134.8319	6.411390
85.22101	134.9667	6.410031
85.35434	135.0991	6.408892
85.48782	135.2339	6.407617
85.62118	135.3656	6.406352
85.75616	135.4997	6.405200
85.89282	135.6365	6.403599
86.02618	135.7714	6.402265
86.16032	135.9060	6.400967
86.29450	136.0416	6.399722
86.42950	136.1779	6.398396
86.56450	136.3112	6.396919
86.69950	136.4459	6.395356
86.83250	136.5785	6.394039
86.96601	136.7137	6.392720
87.09934	136.8466	6.391384
87.23266	136.9798	6.389982
87.36600	137.1115	6.388491
87.49950	137.2458	6.386974
87.63282	137.3778	6.385532
87.76600	137.5069	6.383948
87.89932	137.6426	6.382498
88.03266	137.7747	6.380865
88.16618	137.9080	6.379372
88.29916	138.0425	6.377938
88.43266	138.1766	6.376494
88.56601	138.3104	6.374880
88.69950	138.4456	6.373280
88.83250	138.5812	6.371728
88.96601	138.7157	6.370200
89.09934	138.8490	6.368496
89.23250	138.9813	6.366840
89.36600	139.1150	6.365185
89.49934	139.2490	6.363635
89.63250	139.3821	6.361894
89.76600	139.5146	6.360352
89.90118	139.6491	6.358643
90.03500	139.7820	6.356863
90.16934	139.9151	6.355208
90.30266	140.0470	6.353454
90.43782	140.1810	6.351712
90.57266	140.3153	6.349853
90.70766	140.4501	6.348160
90.84266	140.5868	6.346202
90.97616	140.7226	6.344366
91.11118	140.8570	6.342546
91.24618	140.9936	6.340723
91.38000	141.1265	6.338872
91.51434	141.2695	6.336938
91.65100	141.4192	6.334989
91.78434	141.4926	6.333036
91.91950	141.5879	6.331074
92.05366	141.6999	6.329196
92.18782	141.8208	6.327354
92.32250	141.9518	6.325270
92.45934	142.0915	6.323214
92.59432	142.2351	6.321158
92.72851	142.3820	6.319265
92.86266	142.5332	6.317245
92.99934	142.6844	6.314992
93.13434	142.8308	6.313091
93.26766	142.9723	6.310812
93.40200	143.1117	6.308726
93.53616	143.2555	6.306542
93.67082	143.3958	6.304380
93.80584	143.5339	6.302282
93.94118	143.6721	6.300034
94.07450	143.8077	6.297785
94.20750	143.9438	6.295566
94.34101	144.0805	6.293332
94.47434	144.2158	6.291039
94.60766	144.3518	6.288774
94.74116	144.4839	6.286492
94.87418	144.6162	6.284115
95.00766	144.7499	6.281802
95.14100	144.8811	6.279380
95.27432	145.0134	6.276844
95.40766	145.1476	6.274432
95.54101	145.2771	6.272030
95.67450	145.4091	6.269545
95.80782	145.5438	6.267068
95.94101	145.6764	6.264508
96.07434	145.8074	6.261945
96.20766	145.9381	6.259475
96.34116	146.0961	6.256916
96.47450	146.2729	6.254254
96.60750	146.4372	6.251520
96.74100	146.5923	6.249010
96.87434	146.7388	6.246278
97.00934	146.8781	6.243526
97.14450	147.0119	6.240795
97.27750	147.1392	6.237920
97.41101	147.2626	6.235059
97.54434	147.3829	6.232231
97.67766	147.5044	6.229348
97.81100	147.6269	6.226570
97.94449	147.7491	6.223644
98.07766	147.8722	6.220618
98.21100	147.9966	6.217810
98.34432	148.1194	6.214792
98.47784	148.2463	6.211926
98.61082	148.3724	6.208963
98.74432	148.5016	6.205903
98.87768	148.6328	6.202918
99.01100	148.7619	6.199849
99.14450	148.8936	6.196760
99.27750	149.0271	6.193574
99.41101	149.1574	6.190466
99.54434	149.2901	6.187359
99.67782	149.4241	6.184053
99.81084	149.5561	6.180722
99.94434	149.6902	6.177407
100.0777	149.8262	6.173995
100.2110	149.9584	6.170760
100.3445	150.0924	6.167362
100.4787	150.2247	6.163900
100.6128	150.3606	6.160407
100.7475	150.4944	6.156830
100.8843	150.6308	6.153362
101.0193	150.7659	6.149761
101.1527	150.9004	6.145996
101.2860	151.0341	6.142490
101.4210	151.1699	6.138840
101.5577	151.3049	6.134994
101.6927	151.4403	6.131350
101.8268	151.5748	6.127630
101.9610	151.7084	6.123970
102.0960	151.8420	6.120118
102.2293	151.9754	6.116250
102.3627	152.1086	6.112316
102.4960	152.2416	6.108481
102.6293	152.3740	6.104566
102.7627	152.5070	6.100784
102.8960	152.6392	6.096746
103.0292	152.7730	6.092830
103.1625	152.9041	6.088672
103.2960	153.0391	6.084536
103.4293	153.1712	6.080313
103.5627	153.3066	6.076382
103.6960	153.4389	6.072136
103.8293	153.5746	6.068042
103.9627	153.7108	6.063790
104.0960	153.8438	6.059592
104.2293	153.9739	6.055228
104.3627	154.1093	6.050913
104.4960	154.2412	6.046590
104.6293	154.3750	6.042129
104.7627	154.5075	6.037706
104.8960	154.6390	6.033248
105.0293	154.7722	6.028650
105.1627	154.9054	6.024140
105.2977	155.0421	6.019514
105.4343	155.1810	6.014596
105.5693	155.3191	6.009879
105.7026	155.4545	6.005088
105.8358	155.5865	6.000262
105.9695	155.7208	5.995484
106.1028	155.8519	5.990605
106.2360	155.9850	5.985683
106.3693	156.1186	5.980680
106.5027	156.2492	5.975776
106.6360	156.3822	5.970757
106.7693	156.5148	5.965670
106.9025	156.6471	5.960449
107.0362	156.7813	5.955204
107.1695	156.9148	5.950000
107.3026	157.0496	5.944824
107.4360	157.1832	5.939587
107.5693	157.3163	5.934207
107.7025	157.4478	5.928870
107.8362	157.5808	5.923461
107.9695	157.7145	5.917974
108.1028	157.8471	5.912507
108.2360	157.9800	5.906868
108.3693	158.1146	5.901373
108.5027	158.2492	5.895762
108.6360	158.3838	5.890154
108.7693	158.5176	5.884566
108.9026	158.6514	5.878650
109.0358	158.7844	5.872784
109.1695	158.9166	5.866954
109.3028	159.0482	5.861132
109.4362	159.1800	5.855121
109.5693	159.3146	5.849324
109.7026	159.4487	5.843115
109.8360	159.5803	5.837005
109.9693	159.7148	5.830824
110.1027	159.8474	5.824386
110.2360	159.9799	5.818355
110.3693	160.1143	5.812024
110.5025	160.2461	5.805740
110.6362	160.3794	5.799408
110.7693	160.5124	5.793002
110.9026	160.6475	5.786429
111.0360	160.7808	5.780011
111.1693	160.9151	5.773340
111.3025	161.0497	5.766812
111.4362	161.1818	5.760002
111.5695	161.3170	5.753294
111.7026	161.4502	5.746399
111.8377	161.5845	5.739612
111.9743	161.7207	5.732212
112.1077	161.8546	5.725199
112.2410	161.9880	5.718272
112.3742	162.1238	5.711203
112.5075	162.2570	5.704060
112.6412	162.3884	5.696887
112.7745	162.5185	5.689482
112.9077	162.6528	5.682245
113.0410	162.7864	5.674884
113.1743	162.9200	5.667524
113.3077	163.0535	5.660010
113.4410	163.1863	5.652343
113.5743	163.3205	5.644812
113.7077	163.4549	5.637293
113.8410	163.5874	5.629658
113.9743	163.7199	5.621839
114.1077	163.8519	5.614087
114.2410	163.9841	5.606204
114.3743	164.1189	5.598248
114.5077	164.2507	5.590174
114.6410	164.3859	5.582207
114.7743	164.5194	5.574076
114.9077	164.6520	5.565922
115.0427	164.7878	5.557871
115.1776	164.9234	5.549607
115.3118	165.0558	5.541180
115.4460	165.1909	5.532830
115.5827	165.3275	5.523796
115.7177	165.4634	5.515356
115.8512	165.5963	5.506514
115.9845	165.7306	5.498101
116.1177	165.8614	5.489520
116.2510	165.9930	5.480710
116.3843	166.1266	5.471826
116.5177	166.2598	5.462950
116.6510	166.3951	5.453967
116.7842	166.5297	5.444834
116.9178	166.6637	5.435678
117.0510	166.7963	5.426464
117.1843	166.9289	5.417218
117.3177	167.0604	5.407890
117.4510	167.1956	5.398465
117.5843	167.3290	5.388969
117.7177	167.4624	5.379585
117.8508	167.5967	5.369880
117.9845	167.7303	5.360190
118.1177	167.8636	5.350420
118.2510	167.9971	5.340626
118.3843	168.1294	5.330753
118.5177	168.2618	5.320776
118.6510	168.3931	5.310828
118.7843	168.5250	5.300620
118.9175	168.6578	5.290368
119.0512	168.7926	5.280118
119.1845	168.9259	5.269802
119.3178	169.0614	5.259484
119.4512	169.1942	5.248954
119.5845	169.3306	5.238438
119.7175	169.4632	5.227850
119.8510	169.5974	5.217170
119.9843	169.7295	5.206371
120.1177	169.8639	5.195545
120.2510	169.9958	5.184612
120.3843	170.1285	5.173660
120.5177	170.2609	5.162668
120.6510	170.3934	5.151656
120.7843	170.5245	5.140459
120.9177	170.6582	5.129206
121.0510	170.7936	5.117950
121.1843	170.9266	5.106594
121.3178	171.0608	5.095123
121.4512	171.1926	5.083560
121.5845	171.3267	5.072063
121.7178	171.4589	5.060449
121.8512	171.5925	5.048724
121.9862	171.7297	5.037094
122.1208	171.8642	5.025180
122.2560	172.0022	5.013000
122.3910	172.1390	5.000484
122.5260	172.2742	4.988388
122.6593	172.4084	4.976056
122.7945	172.5444	4.963900
122.9295	172.6788	4.951516
123.0625	172.8116	4.939030
123.1960	172.9438	4.926694
123.3293	173.0764	4.913996
123.4627	173.2094	4.901496
123.5960	173.3411	4.888847
123.7293	173.4720	4.876068
123.8625	173.6062	4.863258
123.9958	173.7412	4.850275
124.1295	173.8771	4.837282
124.2628	174.0094	4.824104
124.3962	174.1414	4.811004
124.5293	174.2746	4.797728
124.6627	174.4077	4.784328
124.7960	174.5416	4.770890
124.9293	174.6752	4.757277
125.0627	174.8081	4.743710
125.1958	174.9389	4.729979
125.3295	175.0711	4.716296
125.4628	175.2004	4.702440
125.5960	175.3290	4.688590
125.7293	175.4622	4.674718
125.8626	175.5978	4.660647
125.9993	175.7348	4.645480
126.1343	175.8727	4.631296
126.2685	176.0094	4.616930
126.4026	176.1470	4.602560
126.5360	176.2794	4.587993
126.6693	176.4125	4.573316
126.8026	176.5473	4.558702
126.9360	176.6811	4.543964
127.0693	176.8139	4.529103
127.2026	176.9452	4.514131
127.3360	177.0785	4.499103
127.4693	177.2109	4.483914
127.6027	177.3476	4.468716
127.7360	177.4822	4.453302
127.8693	177.6183	4.437874
128.0025	177.7527	4.422351
128.1362	177.8869	4.406544
128.2695	178.0220	4.390957
128.4028	178.1534	4.374989
128.5360	178.2866	4.359010
128.6693	178.4192	4.342926
128.8027	178.5503	4.326838
128.9360	178.6819	4.310412
129.0692	178.8134	4.293979
129.2028	178.9480	4.277670
129.3362	179.0780	4.261090
129.4702	179.2130	4.244464
129.6044	179.3479	4.227660
129.7410	179.4840	4.209615
129.8760	179.6195	4.192705
130.0093	179.7516	4.175586
130.1427	179.8856	4.158474
130.2760	180.0201	4.141232
130.4093	180.1529	4.123750
130.5427	180.2880	4.106133
130.6760	180.4214	4.088547
130.8093	180.5538	4.070855
130.9427	180.6874	4.052885
131.0758	180.8180	4.034922
131.2095	180.9494	4.016687
131.3428	181.0820	3.998448
131.4760	181.2174	3.980106
131.6093	181.3514	3.961629
131.7427	181.4848	3.943008
131.8760	181.6199	3.924374
132.0092	181.7535	3.905685
132.1425	181.8874	3.886719
132.2762	182.0234	3.867564
132.4095	182.1568	3.848388
132.5427	182.2911	3.829112
132.6760	182.4230	3.809454
132.8093	182.5534	3.790334
132.9442	182.6862	3.770604
133.0795	182.8218	3.750910
133.2162	182.9602	3.729797
133.3502	183.0953	3.709756
133.4843	183.2280	3.689473
133.6194	183.3626	3.669413
133.7544	183.4989	3.648944
133.8895	183.6342	3.628434
134.0245	183.7694	3.607063
134.1593	183.9044	3.585617
134.2927	184.0388	3.564676
134.4277	184.1731	3.543830
134.5627	184.3084	3.522675
134.6968	184.4414	3.501433
134.8310	184.5759	3.480083
134.9675	184.7117	3.457318
135.1025	184.8449	3.435715
135.2362	184.9789	3.413989
135.3703	185.1123	3.392198
135.5045	185.2463	3.370249
135.6410	185.3828	3.346746
135.7760	185.5174	3.324457
135.9093	185.6496	3.302167
136.0435	185.7838	3.279618
136.1775	185.9187	3.256952
136.3112	186.0538	3.234030
136.4445	186.1887	3.211158
136.5776	186.3237	3.188140
136.7110	186.4565	3.165040
136.8444	186.5901	3.141846
136.9776	186.7215	3.118470
137.1110	186.8546	3.094881
137.2442	186.9879	3.071218
137.3778	187.1217	3.047404
137.5112	187.2556	3.023428
137.6445	187.3884	2.999490
137.7778	187.5198	2.975156
137.9112	187.6536	2.950850
138.0445	187.7869	2.926330
138.1778	187.9195	2.901692
138.3112	188.0514	2.876870
138.4445	188.1834	2.852043
138.5775	188.3190	2.827003
138.7108	188.4581	2.801966
138.8444	188.5939	2.776652
138.9776	188.7252	2.751096
139.1110	188.8570	2.725519
139.2452	188.9892	2.699819
139.3795	189.1217	2.674021
139.5160	189.2587	2.646444
139.6510	189.3947	2.620343
139.7843	189.5284	2.594074
139.9184	189.6634	2.567715
140.0528	189.7976	2.541133
140.1878	189.9309	2.514524
140.3245	190.0686	2.486280
140.4578	190.2020	2.459314
140.5925	190.3337	2.432398
140.7276	190.4682	2.405373
140.8610	190.6009	2.378058
140.9960	190.7374	2.350762
141.1327	190.8733	2.321636
141.2668	191.0069	2.293977
141.4010	191.1429	2.266469
141.5345	191.2761	2.238586
141.6695	191.4114	2.210634
141.8045	191.5460	2.182499
141.9386	191.6810	2.154400
142.0726	191.8178	2.126216
142.2060	191.9516	2.097916
142.3394	192.0841	2.069395
142.4727	192.2176	2.040845
142.6062	192.3499	2.012169
142.7392	192.4834	1.983291
142.8725	192.6168	1.954439
143.0060	192.7484	1.925373
143.1394	192.8832	1.896195
143.2726	193.0151	1.867056
143.4060	193.1467	1.837692
143.5395	193.2794	1.808206
143.6728	193.4139	1.778706
143.8062	193.5466	1.749077
143.9395	193.6791	1.719436
144.0726	193.8128	1.689442
144.2060	193.9490	1.659488
144.3394	194.0825	1.629339
144.4727	194.2170	1.599413
144.6060	194.3501	1.569115
144.7394	194.4847	1.538900
144.8743	194.6204	1.506738
145.0094	194.7560	1.476297
145.1427	194.8862	1.445707
145.2760	195.0188	1.415370
145.4110	195.1534	1.384638
145.5462	195.2888	1.353908
145.6828	195.4233	1.321273
145.8170	195.5578	1.290440
145.9512	195.6932	1.259657
146.0845	195.8276	1.228776
146.2195	195.9615	1.197813
146.3545	196.0954	1.166957
146.4885	196.2306	1.135818
146.6227	196.3632	1.104660
146.7594	196.5022	1.071741
146.8928	196.6358	1.040686
147.0275	196.7710	1.009618
147.1610	196.9040	0.9784179
147.2943	197.0358	0.9472103
147.4277	197.1712	0.9163618
147.5610	197.3015	0.8851882
147.6945	197.4344	0.8541095
147.8278	197.5680	0.8229637
147.9612	197.7011	0.7918281
148.0945	197.8366	0.7608655
148.2278	197.9687	0.7295857
148.3608	198.1022	0.6986808
148.4944	198.2365	0.6677362
148.6277	198.3691	0.6368844
148.7610	198.5000	0.6061020
148.8944	198.6333	0.5754239
149.0278	198.7668	0.5448492
149.1610	198.8982	0.5144562
149.2943	199.0338	0.4841653
149.4277	199.1667	0.4540734
149.5612	199.3006	0.4241496
149.6944	199.4347	0.3944242
149.8276	199.5708	0.3649722
149.9610	199.7053	0.3360006
150.0945	199.8382	0.3073628
150.2292	199.9713	0.2796438
150.3635	200.1056	0.2528027
150.4977	200.2408	0.2274318
150.6345	200.3768	0.2026035
150.7694	200.5107	0.1808725
150.9026	200.6444	0.1605875
151.0370	200.7796	0.1413245
151.1708	200.9120	0.1229746
151.3060	201.0443	0.1054193
151.4427	201.1816	0.08782806
151.5762	201.3133	0.07219040
151.7103	201.4504	0.05743318
151.8442	201.5856	0.04378538
151.9776	201.7207	0.03145202
152.1110	201.8522	0.02058681
152.2445	201.9870	0.01144323
152.3775	202.1208	.003900848
152.5110	202.2521	-1.4808E-3
152.6444	202.3844	-3.9835E-3
152.7776	202.5171	-4.3742E-3
152.9112	202.6500	-4.5578E-3
153.0442	202.7861	-4.6739E-3
153.1777	202.9199	-4.8331E-3
153.3110	203.0530	-4.8187E-3
153.4444	203.1846	-4.9225E-3
153.5776	203.3191	-5.0056E-3
153.7110	203.4524	-5.0964E-3
153.8445	203.5862	-5.0830E-3
153.9778	203.7191	-5.2809E-3
154.1108	203.8533	-5.0909E-3
154.2444	203.9859	-5.3240E-3
154.3777	204.1189	-5.3782E-3
154.5110	204.2516	-5.3432E-3
154.6444	204.3851	-5.3845E-3
154.7793	204.5194	-5.5088E-3
154.9137	204.6550	-5.3921E-3
155.0478	204.7902	-5.5642E-3
155.1825	204.9233	-5.7298E-3
155.3194	205.0597	-5.7466E-3
155.4526	205.1919	-5.9482E-3
155.5868	205.3294	-5.8085E-3
155.7210	205.4641	-5.7825E-3
155.8578	205.6016	-5.7327E-3
155.9928	205.7349	-5.9906E-3
156.1278	205.8711	-6.0003E-3
156.2618	206.0042	-5.9018E-3
156.3960	206.1399	-6.0958E-3
156.5293	206.2716	-6.1867E-3
156.6627	206.4043	-6.2527E-3
156.7960	206.5362	-6.1881E-3
156.9295	206.6726	-6.2443E-3
157.0628	206.8050	-6.4098E-3
157.1962	206.9387	-6.3822E-3
157.3292	207.0714	-6.2859E-3
157.4625	207.2051	-6.3487E-3
157.5958	207.3391	-6.5570E-3
157.7292	207.4722	-6.5364E-3
157.8625	207.6056	-6.5420E-3
157.9960	207.7365	-6.6598E-3
158.1294	207.8709	-6.6674E-3
158.2627	208.0057	-6.5250E-3
158.3960	208.1395	-6.6322E-3
158.5293	208.2740	-6.6375E-3
158.6627	208.4071	-6.6498E-3
158.7960	208.5402	-6.7493E-3
158.9294	208.6734	-6.7920E-3
159.0627	208.8045	-6.6923E-3
159.1960	208.9380	-6.7574E-3
159.3294	209.0696	-6.7143E-3
159.4637	209.2040	-6.6775E-3
159.5978	209.3396	-6.7800E-3
159.7328	209.4753	-6.8595E-3
159.8678	209.6112	-6.8008E-3
160.0028	209.7458	-6.7565E-3
160.1358	209.8776	-6.8614E-3
160.2692	210.0111	-6.6186E-3
160.4026	210.1482	-6.5461E-3
160.5360	210.2868	-6.6055E-3
160.6693	210.4238	-6.6117E-3
160.8027	210.5583	-6.7107E-3
160.9360	210.6938	-6.7625E-3
161.0694	210.8298	-6.6514E-3
161.2026	210.9670	-6.7034E-3
161.3360	211.1003	-6.7120E-3
161.4694	211.2344	-6.6123E-3
161.6026	211.3650	-6.7170E-3
161.7360	211.4959	-6.6421E-3
161.8694	211.6253	-6.6337E-3
162.0027	211.7559	-6.6995E-3
162.1360	211.8872	-6.6231E-3
162.2694	212.0203	-6.7074E-3
162.4026	212.1498	-6.6854E-3
162.5360	212.2803	-6.7504E-3
162.6693	212.4105	-6.6987E-3
162.8025	212.5425	-6.7120E-3
162.9358	212.6760	-6.6978E-3
163.0695	212.8086	-6.8865E-3
163.2028	212.9432	-6.7288E-3
163.3362	213.0748	-6.8001E-3
163.4695	213.2098	-6.7405E-3
163.6028	213.3448	-6.8093E-3
163.7360	213.4787	-6.6806E-3
163.8694	213.6118	-6.8356E-3
164.0027	213.7457	-6.8497E-3
164.1362	213.8769	-6.9747E-3
164.2695	214.0115	-6.9722E-3
164.4028	214.1448	-6.9683E-3
164.5362	214.2781	-6.9702E-3
164.6695	214.4126	-7.0445E-3
164.8028	214.5462	-7.0985E-3
164.9362	214.6807	-7.0370E-3
165.0695	214.8134	-7.0989E-3
165.2025	214.9423	-7.0450E-3
165.3360	215.0733	-7.2109E-3
165.4694	215.2064	-7.1516E-3
165.6026	215.3396	-7.1734E-3
165.7360	215.4736	-7.1828E-3
165.8702	215.6064	-7.2613E-3
166.0044	215.7409	-7.4163E-3
166.1395	215.8794	-7.3379E-3
166.2762	216.0156	-7.2717E-3
166.4108	216.1510	-7.2051E-3
166.5442	216.2890	-7.3694E-3
166.6778	216.4268	-7.3797E-3
166.8112	216.5627	-7.3539E-3
166.9444	216.6932	-7.5394E-3
167.0776	216.8239	-7.5139E-3
167.2110	216.9570	-7.5560E-3
167.3444	217.0890	-7.5752E-3
167.4775	217.2215	-7.7041E-3
167.6108	217.3570	-7.6335E-3
167.7442	217.4880	-7.6596E-3
167.8777	217.6188	-7.6858E-3
168.0110	217.7521	-7.7783E-3
168.1444	217.8836	-7.7199E-3
168.2776	218.0160	-7.7320E-3
168.4110	218.1474	-7.8477E-3
168.5443	218.2833	-7.7754E-3
168.6777	218.4180	-7.8111E-3
168.8110	218.5524	-7.7298E-3
168.9444	218.6848	-7.8104E-3
169.0776	218.8195	-7.9413E-3
169.2110	218.9537	-7.8869E-3
169.3460	219.0872	-7.8455E-3
169.4826	219.2222	-7.7920E-3
169.6176	219.3562	-7.9133E-3
169.7518	219.4931	-7.8783E-3
169.8860	219.6281	-7.8877E-3
170.0194	219.7628	-7.8296E-3
170.1542	219.8983	-7.8048E-3
170.2895	220.0308	-7.7992E-3
170.4245	220.1660	-7.7600E-3
170.5595	220.3007	-7.7046E-3
170.6927	220.4341	-7.7525E-3
170.8276	220.5684	-7.6505E-3
170.9626	220.7027	-7.8472E-3
171.0977	220.8371	-7.7397E-3
171.2326	220.9724	-7.8082E-3
171.3694	221.1080	-7.8324E-3
171.5027	221.2386	-7.7653E-3
171.6377	221.3740	-7.8567E-3
171.7710	221.5071	-7.8485E-3
171.9043	221.6428	-7.8785E-3
172.0377	221.7738	-7.8767E-3
172.1708	221.9090	-7.8490E-3
172.3042	222.0430	-7.7091E-3
172.4375	222.1776	-7.7573E-3
172.5710	222.3112	-7.8095E-3
172.7044	222.4457	-7.6648E-3
172.8376	222.5779	-7.7690E-3
172.9710	222.7121	-7.6890E-3
173.1044	222.8448	-7.7645E-3
173.2375	222.9761	-7.8347E-3
173.3712	223.1112	-7.9193E-3
173.5045	223.2427	-7.7691E-3
173.6378	223.3764	-7.8582E-3
173.7712	223.5107	-7.8132E-3
173.9045	223.6450	-7.9141E-3
174.0378	223.7773	-7.9908E-3
174.1712	223.9127	-7.8495E-3
174.3045	224.0469	-7.9607E-3
174.4378	224.1806	-7.9213E-3
174.5708	224.3113	-7.9345E-3
174.7042	224.4452	-7.8911E-3
174.8394	224.5776	-7.9277E-3
174.9742	224.7122	-7.9052E-3
175.1092	224.8464	-7.9732E-3
175.2442	224.9826	-7.8677E-3
175.3775	225.1148	-7.9407E-3
175.5128	225.2500	-8.0708E-3
175.6470	225.3837	-8.0596E-3
175.7810	225.5182	-8.0353E-3
175.9176	225.6546	-8.0192E-3
176.0510	225.7874	-8.1102E-3
176.1860	225.9246	-8.0885E-3
176.3202	226.0608	-7.9741E-3
176.4544	226.1958	-8.0911E-3
176.5910	226.3332	-8.1247E-3
176.7260	226.4672	-8.1103E-3
176.8610	226.6039	-8.0893E-3
176.9944	226.7366	-8.0936E-3
177.1277	226.8704	-8.1161E-3
177.2610	227.0025	-8.1324E-3
177.3944	227.1342	-8.0968E-3
177.5276	227.2661	-8.0814E-3
177.6610	227.3984	-8.0924E-3
177.7943	227.5337	-8.0760E-3
177.9277	227.6669	-8.0280E-3
178.0608	227.7992	-8.1306E-3
178.1942	227.9348	-8.0607E-3
178.3278	228.0710	-8.2056E-3
178.4612	228.2036	-8.1801E-3
178.5945	228.3366	-8.2226E-3
178.7278	228.4718	-8.1947E-3
178.8610	228.6056	-8.3467E-3
178.9944	228.7373	-8.2624E-3
179.1277	228.8724	-8.1776E-3
179.2610	229.0039	-8.3123E-3
179.3944	229.1389	-8.1528E-3
179.5276	229.2688	-8.2999E-3
179.6610	229.3997	-8.3787E-3
179.7942	229.5323	-8.3992E-3
179.9275	229.6662	-8.1987E-3
180.0608	229.8000	-8.2812E-3
180.1944	229.9318	-8.3259E-3
180.3276	230.0658	-8.3311E-3
180.4610	230.1992	-8.4063E-3
180.5944	230.3344	-8.4376E-3
180.7276	230.4670	-8.5182E-3
180.8610	230.6006	-8.5534E-3
180.9944	230.7346	-8.6914E-3
181.1277	230.8732	-8.6955E-3
181.2610	231.0071	-8.6909E-3
181.3944	231.1396	-8.5761E-3
181.5276	231.2710	-8.5328E-3
181.6610	231.4047	-8.5440E-3
181.7945	231.5381	-8.5462E-3
181.9278	231.6710	-8.5502E-3
182.0612	231.8033	-8.4798E-3
182.1945	231.9337	-8.4251E-3
182.3275	232.0661	-8.4929E-3
182.4608	232.2000	-8.4384E-3
182.5942	232.3336	-8.4755E-3
182.7275	232.4664	-8.5481E-3
182.8612	232.5987	-8.5214E-3
182.9945	232.7306	-8.4493E-3
183.1295	232.8644	-8.4410E-3
183.2645	232.9994	-8.4909E-3
183.3995	233.1372	-8.4535E-3
183.5345	233.2756	-8.3773E-3
183.6693	233.4112	-8.4235E-3
183.8044	233.5464	-8.4128E-3
183.9410	233.6847	-8.1927E-3
184.0753	233.8161	-8.3953E-3
184.2095	233.9495	-8.3629E-3
184.3445	234.0846	-8.3396E-3
184.4795	234.2228	-8.3962E-3
184.6162	234.3574	-8.3490E-3
184.7504	234.4917	-8.3271E-3
184.8844	234.6237	-8.2430E-3
185.0178	234.7552	-8.2660E-3
185.1528	234.8895	-8.4131E-3
185.2878	235.0259	-8.2577E-3
185.4220	235.1600	-8.2598E-3
185.5562	235.2930	-8.3909E-3
185.6928	235.4309	-8.3633E-3
185.8278	235.5660	-8.3230E-3
185.9628	235.7008	-8.3846E-3
186.0968	235.8352	-8.3875E-3
186.2310	235.9686	-8.4346E-3
186.3676	236.1051	-8.4372E-3
186.5027	236.2393	-8.4558E-3
186.6377	236.3731	-8.4538E-3
186.7726	236.5078	-8.5166E-3
186.9076	236.6440	-8.4567E-3
187.0426	236.7806	-8.3729E-3
187.1760	236.9160	-8.4121E-3
187.3110	237.0524	-8.5704E-3
187.4452	237.1871	-8.4148E-3
187.5794	237.3210	-8.4692E-3
187.7142	237.4582	-8.4418E-3
187.8495	237.5922	-8.5867E-3
187.9845	237.7277	-8.3448E-3
188.1185	237.8611	-8.4138E-3
188.2527	237.9933	-8.4619E-3
188.3877	238.1277	-8.4250E-3
188.5244	238.2632	-8.4470E-3
188.6594	238.3989	-8.4484E-3
188.7934	238.5342	-8.4712E-3
188.9278	238.6690	-8.5456E-3
189.0612	238.8016	-8.5269E-3
189.1960	238.9344	-8.6583E-3
189.3326	239.0722	-8.5695E-3
189.4668	239.2076	-8.5566E-3
189.6010	239.3435	-8.4201E-3
189.7344	239.4766	-8.5469E-3
189.8694	239.6112	-8.4598E-3
190.0044	239.7452	-8.4962E-3
190.1394	239.8778	-8.6368E-3
190.2744	240.0135	-8.4528E-3
190.4094	240.1492	-8.5153E-3
190.5426	240.2828	-8.5626E-3
190.6777	240.4180	-8.6536E-3
190.8118	240.5513	-8.4842E-3
190.9460	240.6867	-8.5148E-3
191.0810	240.8216	-8.4994E-3
191.2176	240.9579	-8.4696E-3
191.3526	241.0916	-8.5224E-3
191.4860	241.2230	-8.5802E-3
191.6194	241.3574	-8.7281E-3
191.7525	241.4904	-8.6804E-3
191.8862	241.6242	-8.6850E-3
192.0195	241.7582	-8.7846E-3
192.1526	241.8934	-8.5530E-3
192.2860	242.0256	-8.5959E-3
192.4193	242.1582	-8.6899E-3
192.5527	242.2922	-8.7455E-3
192.6860	242.4260	-8.6740E-3
192.8194	242.5606	-8.6316E-3
192.9526	242.6946	-8.6817E-3
193.0860	242.8272	-8.7921E-3
193.2194	242.9606	-8.7574E-3
193.3526	243.0920	-8.7831E-3
193.4860	243.2251	-8.6527E-3
193.6194	243.3586	-8.6620E-3
193.7527	243.4916	-8.5212E-3
193.8860	243.6239	-8.6945E-3
194.0194	243.7562	-8.6591E-3
194.1526	243.8880	-8.6196E-3
194.2860	244.0235	-8.4407E-3
194.4193	244.1599	-8.3779E-3
194.5527	244.2944	-8.4119E-3
194.6868	244.4276	-8.3885E-3
194.8210	244.5634	-8.4841E-3
194.9560	244.7013	-8.4425E-3
195.0894	244.8344	-8.3613E-3
195.2227	244.9655	-8.5065E-3
195.3560	245.0989	-8.4796E-3
195.4894	245.2303	-8.5538E-3
195.6227	245.3650	-8.5656E-3
195.7560	245.4966	-8.4750E-3
195.8894	245.6312	-8.4571E-3
196.0226	245.7635	-8.5977E-3
196.1560	245.8966	-8.6064E-3
196.2894	246.0304	-8.5540E-3
196.4225	246.1630	-8.4775E-3
196.5562	246.2955	-8.5163E-3
196.6895	246.4283	-8.4606E-3
196.8228	246.5610	-8.3792E-3
196.9558	246.6941	-8.3779E-3
197.0894	246.8282	-8.4588E-3
197.2227	246.9634	-8.4831E-3
197.3560	247.0962	-8.4910E-3
197.4895	247.2278	-8.5612E-3
197.6228	247.3612	-8.5414E-3
197.7562	247.4962	-8.4947E-3
197.8895	247.6303	-8.4135E-3
198.0228	247.7602	-8.6297E-3
198.1594	247.8972	-8.4946E-3
198.2943	248.0340	-8.4569E-3