File: DSC/Olivia/2025_08_02_1CBN_3PVP_MeOH_MC_n60C_130C_10Cmin_x3.csv
Filename,2025_08_02_1CBN_3PVP_MeOH_MC_n60C_130C_10Cmin_x3
Instrument name,DSC2A-00468 (192.168.1.100)
Operator,Yarger
rundate,8/2/2025
Sample name,2025_08_02_1CBN_3PVP_MeOH_MC_n60C_130C_10Cmin_x3
proceduresegments,Data Off ; Equilibrate -60.00 °C; Data On ; Ramp 10.00 °C/min to 130.00 °C; Data Off ; Isothermal 2.0 min; Data On ; Ramp 10.00 °C/min to -60.00 °C; Data Off ; Isothermal 2.0 min; Data On ; Ramp 10.00 °C/min to 130.00 °C; Data Off ; Isothermal 2.0 min; Data On ; Ramp 10.00 °C/min to -60.00 °C; Data Off ; Isothermal 2.0 min; Data On ; Ramp 10.00 °C/min to 130.00 °C
[File Parameters]
Run date,8/2/2025 1:25:07 AM
Trios version,5.1.1.46572
Original File Name,
Current File Name,D:\DSC2500\Gibbons\2025_08_02_1CBN_3PVP_MeOH_MC_n60C_130C_10Cmin_x3.tri
[Procedure]
Procedure Name,CBNPVP_n60C_130C_10Cmin_x3
Sample Name,2025_08_02_1CBN_3PVP_MeOH_MC_n60C_130C_10Cmin_x3
Sample Mass,4.69 mg
Reference Sample Mass,0 mg
Pan Mass,32.76 mg
Pan Number,49
Reference Pan Mass,32.73 mg
Reference Pan Number,46
Pan Type,Aluminum
Comments,Thermal support Al pans/lids. DSC_Samples_A2_Tray_July2025 google sheet.
Project Name,Pharma - Cocrystals
Operator,Yarger
Test,Custom
Unload Max Temperature,30
Unload Min Temperature,30
Load Max Temperature,30
Load Min Temperature,30
Stop on Gas Flow Error,Yes
[Signal List]
Signal #1,Time (min)
Signal #2,Temperature (°C)
Signal #3,Heat Flow (mW)
Signal #4,Delta T (µV)
Signal #5,Delta Tzero (µV)
Signal #6,Tzero Temperature (°C)
Signal #7,Cell Purge (mL/min)
Signal #8,Heater Temp (°C)
Signal #9,Power Delivered (W)
Signal #10,Reference Junction Temperature (°C)
Signal #11,Flange Temperature (°C)
Signal #12,Heat Flow Phase (rad)
Signal #13,Total Heat Capacity (J/°C)
Signal #14,Heat Capacity (J/°C)
[Configuration]
Company Name,ASU
Instrument Name,DSC2A-00468
Instrument Type,DSC2500
Serial Number,DSC2A-00468
IP,192.168.1.100
Location of Instrument,MRRC
DisplayType,Unknown
Sample Interval ,0.1 s/pt
Selected Heat Flow,T4P
Exotherm Direction,Down
Cell Serial,DRC2-00792
Lid Type,Standard
Cooler,RCS 90
Leave Cooler on at End of Sequence,On
Gas 2,Nitrogen
Gas Selected,Channel 1
Flow Rate,50 mL/min
Secondary Purge,On
Licensed Heat Flow,Heat Flow T4P
Modulation Licensed,Yes
[Versions]
Common IDD Version,1
Cortex Version,VER 2.10.2.31
Driver,5.0.0.6
GDM Version,1.0.3.3
TouchscreenVersion,1.0.0.16145
FEP Version,1.2.1.21
FEP Bootloader,2.0.0.5
AutoSampler Version,2.1.1.26
Auto Sampler Bootloader,2.0.0.5
FCM Version,1.1.0.3
FCM Bootloader,2.0.0.5
[Experiment Logs]
Experiment Log Entry # 1,Data On set to 0
Experiment Log Entry # 3,Equilibrate Segment -60 (C) Started
Experiment Log Entry # 5,Air Cool is off.
Experiment Log Entry # 7,Data On set to 1
Experiment Log Entry # 9,Ramp Segment 10 C/min to 130 Started
Experiment Log Entry # 11,Data On set to 0
Experiment Log Entry # 13,Isothermal Segment 2 min started
Experiment Log Entry # 15,Data On set to 1
Experiment Log Entry # 17,Ramp Segment 10 C/min to -60 Started
Experiment Log Entry # 19,Data On set to 0
Experiment Log Entry # 21,Isothermal Segment 2 min started
Experiment Log Entry # 23,Data On set to 1
Experiment Log Entry # 25,Ramp Segment 10 C/min to 130 Started
Experiment Log Entry # 27,Data On set to 0
Experiment Log Entry # 29,Isothermal Segment 2 min started
Experiment Log Entry # 31,Data On set to 1
Experiment Log Entry # 33,Ramp Segment 10 C/min to -60 Started
Experiment Log Entry # 35,Data On set to 0
Experiment Log Entry # 37,Isothermal Segment 2 min started
Experiment Log Entry # 39,Data On set to 1
Experiment Log Entry # 41,Ramp Segment 10 C/min to 130 Started
[Method Log]
Method Log Entry # 1,Data Off
Method Log Entry # 2,Equilibrate -60 °C
Method Log Entry # 3,Data On
Method Log Entry # 4,(Ramp 109881) Ramp 10 °C/minute to 130 °C
Method Log Entry # 5,Data Off
Method Log Entry # 6,Isothermal 2 minutes
Method Log Entry # 7,Data On
Method Log Entry # 8,(Ramp 109885) Ramp 10 °C/minute to -60 °C
Method Log Entry # 9,Data Off
Method Log Entry # 10,Isothermal 2 minutes
Method Log Entry # 11,Data On
Method Log Entry # 12,(Ramp 109889) Ramp 10 °C/minute to 130 °C
Method Log Entry # 13,Data Off
Method Log Entry # 14,Isothermal 2 minutes
Method Log Entry # 15,Data On
Method Log Entry # 16,(Ramp 109893) Ramp 10 °C/minute to -60 °C
Method Log Entry # 17,Data Off
Method Log Entry # 18,Isothermal 2 minutes
Method Log Entry # 19,Data On
Method Log Entry # 20,(Ramp 109897) Ramp 10 °C/minute to 130 °C
Cell Serial,DRC2-00792
[T1 Calibration]
Slope,-0.008529666
Offset,9.636258
Initial Temperature,98.23
GUID,f8bfdadc-4977-4fdf-ba6d-0ba9134940c3
[TZero Calibration]
Date Applied,11/29/2022 4:06:13 PM
Description,From -89.059 °C to 396.009 °C at 20.000°C/min
Gas Type,Nitrogen
Pan Type,None
Source Files 1,C:\Users\yargerlab\Desktop\DSC Data\General\TZero_calibration_11_29_22_2nd(2).tri
Source Files 2,C:\Users\yargerlab\Desktop\DSC Data\General\TZero_calibration_11_29_22_2nd(3).tri
Delta T Offset,13.05235
Delta T Slope,-0.007271007
Delta T0 Offset,-13.69128
Delta T0 Slope,0.06063341
[Temperature Calibration]
Date Applied,11/29/2022 7:12:28 PM
Description,From 106.590 °C to 186.590 °C at 10.000°C/min
Gas Type,Nitrogen
Pan Type,Tzero Aluminum Hermetic
Source Files 1,C:\Users\yargerlab\Desktop\DSC Data\General\Indium(6).tri
Measured 1,157.391
Known 1,156.598
[Cell Constant Calibration]
Date Applied,11/29/2022 7:12:29 PM
Description,From 106.590 °C to 186.590 °C at 10.000°C/min
Gas Type,Nitrogen
Pan Type,Tzero Aluminum Hermetic
Source Files 1,C:\Users\yargerlab\Desktop\DSC Data\General\Indium(6).tri
T4P KCell,1.006051
Onset Slope,63.26126 mW/°C
[Direct Cp Calibration]
Date Applied,11/30/2022 11:04:51 AM
Description,From -79.983 °C to 298.409 °C at 10.000°C/min
Gas Type,Nitrogen
Pan Type,Tzero Aluminum Hermetic
Source Files 1,C:\Users\yargerlab\Desktop\DSC Data\General\Sapphire_Heat_Capacity_11_30_22.tri
[Rev Cp Calibration]
Date Applied,11/30/2022 1:58:51 PM
Description,From -79.996 °C to 292.812 °C at 3.000°C/min
Gas Type,Nitrogen
Pan Type,Tzero Aluminum Hermetic
Source Files 1,C:\Users\yargerlab\Desktop\DSC Data\General\Sapphire_MDSC_Calibration_11_30_22.tri
[step]
Ramp 10.00 °C/min to 130.00 °C
Time,Temperature,Heat Flow (Normalized)
min,°C,W/g
0.00,-59.81,-0.060
0.01,-59.81,-0.057
0.03,-59.82,-0.054
0.04,-59.81,-0.052
0.05,-59.80,-0.053
0.07,-59.78,-0.058
0.08,-59.75,-0.077
0.09,-59.71,-0.089
0.11,-59.65,-0.098
0.12,-59.57,-0.103
0.13,-59.49,-0.102
0.15,-59.40,-0.098
0.16,-59.30,-0.090
0.17,-59.20,-0.066
0.19,-59.09,-0.048
0.20,-58.97,-0.028
0.21,-58.86,-0.010
0.23,-58.74,0.009
0.24,-58.62,0.025
0.25,-58.49,0.042
0.27,-58.37,0.056
0.28,-58.25,0.067
0.29,-58.12,0.078
0.31,-58.00,0.088
0.32,-57.87,0.096
0.33,-57.74,0.104
0.35,-57.62,0.108
0.36,-57.49,0.114
0.37,-57.36,0.118
0.39,-57.24,0.122
0.40,-57.11,0.126
0.41,-56.98,0.128
0.43,-56.85,0.132
0.44,-56.72,0.133
0.45,-56.59,0.135
0.47,-56.46,0.138
0.48,-56.33,0.139
0.49,-56.20,0.140
0.51,-56.07,0.141
0.52,-55.94,0.143
0.53,-55.81,0.144
0.55,-55.68,0.145
0.56,-55.55,0.145
0.57,-55.42,0.146
0.59,-55.29,0.147
0.60,-55.16,0.147
0.61,-55.03,0.148
0.63,-54.90,0.148
0.64,-54.77,0.148
0.65,-54.63,0.149
0.67,-54.50,0.149
0.68,-54.37,0.149
0.69,-54.24,0.149
0.71,-54.11,0.150
0.72,-53.97,0.151
0.73,-53.84,0.151
0.75,-53.71,0.151
0.76,-53.58,0.152
0.77,-53.45,0.152
0.79,-53.32,0.152
0.80,-53.18,0.153
0.81,-53.05,0.153
0.83,-52.92,0.153
0.84,-52.79,0.154
0.85,-52.65,0.154
0.87,-52.52,0.154
0.88,-52.39,0.155
0.89,-52.26,0.155
0.91,-52.12,0.155
0.92,-51.99,0.155
0.93,-51.86,0.156
0.95,-51.73,0.156
0.96,-51.60,0.156
0.97,-51.46,0.157
0.99,-51.33,0.157
1.00,-51.20,0.157
1.01,-51.07,0.157
1.03,-50.93,0.158
1.04,-50.80,0.158
1.05,-50.67,0.158
1.07,-50.53,0.158
1.08,-50.40,0.158
1.09,-50.27,0.159
1.11,-50.14,0.159
1.12,-50.00,0.159
1.13,-49.87,0.159
1.15,-49.74,0.160
1.16,-49.61,0.160
1.17,-49.47,0.160
1.19,-49.34,0.160
1.20,-49.20,0.160
1.21,-49.07,0.161
1.23,-48.94,0.161
1.24,-48.81,0.161
1.25,-48.67,0.161
1.27,-48.54,0.161
1.28,-48.41,0.161
1.29,-48.27,0.162
1.31,-48.14,0.162
1.32,-48.01,0.162
1.33,-47.87,0.162
1.35,-47.74,0.162
1.36,-47.61,0.162
1.37,-47.47,0.163
1.39,-47.34,0.163
1.40,-47.21,0.163
1.41,-47.07,0.163
1.43,-46.94,0.163
1.44,-46.81,0.163
1.45,-46.68,0.163
1.47,-46.54,0.163
1.48,-46.41,0.163
1.49,-46.27,0.164
1.51,-46.14,0.164
1.52,-46.01,0.164
1.53,-45.88,0.164
1.55,-45.74,0.164
1.56,-45.61,0.164
1.57,-45.48,0.164
1.59,-45.34,0.164
1.60,-45.21,0.164
1.61,-45.08,0.164
1.63,-44.94,0.164
1.64,-44.81,0.165
1.65,-44.68,0.165
1.67,-44.54,0.165
1.68,-44.41,0.165
1.69,-44.28,0.165
1.71,-44.14,0.165
1.72,-44.01,0.165
1.73,-43.88,0.165
1.75,-43.74,0.165
1.76,-43.61,0.165
1.77,-43.48,0.165
1.79,-43.34,0.166
1.80,-43.21,0.166
1.81,-43.07,0.166
1.83,-42.94,0.166
1.84,-42.81,0.166
1.85,-42.67,0.166
1.87,-42.54,0.166
1.88,-42.41,0.166
1.89,-42.27,0.166
1.91,-42.14,0.166
1.92,-42.01,0.166
1.93,-41.87,0.166
1.95,-41.74,0.166
1.96,-41.61,0.166
1.97,-41.47,0.167
1.99,-41.34,0.167
2.00,-41.21,0.167
2.01,-41.07,0.167
2.03,-40.94,0.167
2.04,-40.80,0.167
2.05,-40.67,0.167
2.07,-40.54,0.167
2.08,-40.41,0.167
2.09,-40.27,0.167
2.11,-40.14,0.167
2.12,-40.01,0.167
2.13,-39.87,0.167
2.15,-39.74,0.167
2.16,-39.61,0.167
2.17,-39.47,0.167
2.19,-39.34,0.167
2.20,-39.20,0.168
2.21,-39.07,0.168
2.23,-38.94,0.168
2.24,-38.80,0.168
2.25,-38.67,0.168
2.27,-38.54,0.168
2.28,-38.40,0.168
2.29,-38.27,0.168
2.31,-38.14,0.168
2.32,-38.00,0.168
2.33,-37.87,0.168
2.35,-37.74,0.168
2.36,-37.60,0.168
2.37,-37.47,0.168
2.39,-37.33,0.168
2.40,-37.20,0.168
2.41,-37.07,0.168
2.43,-36.93,0.168
2.44,-36.80,0.168
2.45,-36.67,0.168
2.47,-36.53,0.168
2.48,-36.40,0.169
2.49,-36.27,0.169
2.51,-36.13,0.169
2.52,-36.00,0.169
2.53,-35.86,0.169
2.55,-35.73,0.169
2.56,-35.60,0.169
2.57,-35.46,0.169
2.59,-35.33,0.169
2.60,-35.20,0.169
2.61,-35.06,0.169
2.63,-34.93,0.169
2.64,-34.80,0.169
2.65,-34.66,0.169
2.67,-34.53,0.169
2.68,-34.40,0.169
2.69,-34.26,0.169
2.71,-34.13,0.169
2.72,-34.00,0.169
2.73,-33.86,0.169
2.75,-33.73,0.169
2.76,-33.60,0.169
2.77,-33.46,0.169
2.79,-33.33,0.170
2.80,-33.20,0.169
2.81,-33.06,0.170
2.83,-32.93,0.170
2.84,-32.80,0.170
2.85,-32.66,0.170
2.87,-32.53,0.170
2.88,-32.40,0.170
2.89,-32.26,0.170
2.91,-32.13,0.170
2.92,-31.99,0.170
2.93,-31.86,0.170
2.95,-31.73,0.170
2.96,-31.60,0.170
2.97,-31.46,0.170
2.99,-31.33,0.170
3.00,-31.19,0.170
3.01,-31.06,0.170
3.03,-30.93,0.170
3.04,-30.80,0.170
3.05,-30.66,0.170
3.07,-30.53,0.170
3.08,-30.39,0.170
3.09,-30.26,0.170
3.11,-30.13,0.170
3.12,-29.99,0.170
3.13,-29.86,0.170
3.15,-29.73,0.170
3.16,-29.59,0.171
3.17,-29.46,0.171
3.19,-29.33,0.171
3.20,-29.19,0.171
3.21,-29.06,0.171
3.23,-28.92,0.171
3.24,-28.79,0.171
3.25,-28.66,0.171
3.27,-28.52,0.171
3.28,-28.39,0.171
3.29,-28.25,0.171
3.31,-28.12,0.171
3.32,-27.99,0.171
3.33,-27.85,0.171
3.35,-27.72,0.171
3.36,-27.59,0.172
3.37,-27.45,0.172
3.39,-27.32,0.172
3.40,-27.19,0.172
3.41,-27.06,0.172
3.43,-26.92,0.172
3.44,-26.79,0.172
3.45,-26.65,0.172
3.47,-26.52,0.172
3.48,-26.39,0.172
3.49,-26.25,0.172
3.51,-26.12,0.172
3.52,-25.99,0.172
3.53,-25.85,0.172
3.55,-25.72,0.172
3.56,-25.59,0.172
3.57,-25.45,0.172
3.59,-25.32,0.172
3.60,-25.19,0.172
3.61,-25.05,0.172
3.63,-24.92,0.172
3.64,-24.79,0.172
3.65,-24.65,0.173
3.67,-24.52,0.173
3.68,-24.39,0.173
3.69,-24.25,0.173
3.71,-24.12,0.173
3.72,-23.98,0.173
3.73,-23.85,0.173
3.75,-23.72,0.173
3.76,-23.58,0.173
3.77,-23.45,0.173
3.79,-23.32,0.173
3.80,-23.18,0.173
3.81,-23.05,0.173
3.83,-22.92,0.173
3.84,-22.78,0.173
3.85,-22.65,0.173
3.87,-22.52,0.173
3.88,-22.38,0.173
3.89,-22.25,0.174
3.91,-22.12,0.174
3.92,-21.98,0.174
3.93,-21.85,0.174
3.95,-21.72,0.174
3.96,-21.58,0.174
3.97,-21.45,0.174
3.99,-21.32,0.174
4.00,-21.18,0.174
4.01,-21.05,0.174
4.03,-20.91,0.174
4.04,-20.78,0.174
4.05,-20.65,0.174
4.07,-20.51,0.174
4.08,-20.38,0.174
4.09,-20.25,0.175
4.11,-20.11,0.175
4.12,-19.98,0.175
4.13,-19.85,0.175
4.15,-19.71,0.175
4.16,-19.58,0.175
4.17,-19.45,0.175
4.19,-19.31,0.175
4.20,-19.18,0.175
4.21,-19.05,0.175
4.23,-18.91,0.175
4.24,-18.78,0.175
4.25,-18.65,0.175
4.27,-18.51,0.175
4.28,-18.38,0.175
4.29,-18.25,0.175
4.31,-18.11,0.175
4.32,-17.98,0.176
4.33,-17.84,0.176
4.35,-17.71,0.176
4.36,-17.58,0.176
4.37,-17.44,0.176
4.39,-17.31,0.176
4.40,-17.18,0.176
4.41,-17.04,0.176
4.43,-16.91,0.176
4.44,-16.78,0.176
4.45,-16.64,0.176
4.47,-16.51,0.176
4.48,-16.38,0.176
4.49,-16.24,0.176
4.51,-16.11,0.176
4.52,-15.98,0.177
4.53,-15.84,0.177
4.55,-15.71,0.177
4.56,-15.58,0.177
4.57,-15.44,0.177
4.59,-15.31,0.177
4.60,-15.18,0.177
4.61,-15.04,0.177
4.63,-14.91,0.177
4.64,-14.78,0.177
4.65,-14.64,0.177
4.67,-14.51,0.177
4.68,-14.38,0.177
4.69,-14.24,0.177
4.71,-14.11,0.178
4.72,-13.97,0.178
4.73,-13.84,0.178
4.75,-13.71,0.178
4.76,-13.57,0.178
4.77,-13.44,0.178
4.79,-13.31,0.178
4.80,-13.17,0.178
4.81,-13.04,0.178
4.83,-12.91,0.178
4.84,-12.77,0.178
4.85,-12.64,0.178
4.87,-12.50,0.178
4.88,-12.37,0.179
4.89,-12.24,0.179
4.91,-12.11,0.179
4.92,-11.97,0.179
4.93,-11.84,0.179
4.95,-11.70,0.179
4.96,-11.57,0.179
4.97,-11.44,0.179
4.99,-11.31,0.179
5.00,-11.17,0.179
5.01,-11.04,0.179
5.03,-10.90,0.179
5.04,-10.77,0.179
5.05,-10.64,0.180
5.07,-10.50,0.180
5.08,-10.37,0.180
5.09,-10.24,0.180
5.11,-10.10,0.180
5.12,-9.97,0.180
5.13,-9.84,0.180
5.15,-9.70,0.180
5.16,-9.57,0.180
5.17,-9.44,0.180
5.19,-9.30,0.180
5.20,-9.17,0.180
5.21,-9.03,0.180
5.23,-8.90,0.180
5.24,-8.77,0.181
5.25,-8.64,0.181
5.27,-8.50,0.181
5.28,-8.37,0.181
5.29,-8.23,0.181
5.31,-8.10,0.181
5.32,-7.97,0.181
5.33,-7.83,0.181
5.35,-7.70,0.181
5.36,-7.57,0.181
5.37,-7.43,0.181
5.39,-7.30,0.181
5.40,-7.17,0.182
5.41,-7.03,0.182
5.43,-6.90,0.182
5.44,-6.77,0.182
5.45,-6.63,0.182
5.47,-6.50,0.182
5.48,-6.37,0.182
5.49,-6.23,0.182
5.51,-6.10,0.182
5.52,-5.97,0.182
5.53,-5.83,0.182
5.55,-5.70,0.183
5.56,-5.57,0.183
5.57,-5.43,0.183
5.59,-5.30,0.183
5.60,-5.17,0.183
5.61,-5.03,0.183
5.63,-4.90,0.183
5.64,-4.76,0.183
5.65,-4.63,0.183
5.67,-4.50,0.183
5.68,-4.37,0.183
5.69,-4.23,0.184
5.71,-4.10,0.184
5.72,-3.96,0.184
5.73,-3.83,0.184
5.75,-3.70,0.184
5.76,-3.56,0.184
5.77,-3.43,0.184
5.79,-3.30,0.184
5.80,-3.16,0.184
5.81,-3.03,0.184
5.83,-2.90,0.185
5.84,-2.76,0.185
5.85,-2.63,0.185
5.87,-2.50,0.185
5.88,-2.36,0.185
5.89,-2.23,0.185
5.91,-2.09,0.185
5.92,-1.96,0.185
5.93,-1.83,0.185
5.95,-1.70,0.185
5.96,-1.56,0.185
5.97,-1.43,0.186
5.99,-1.29,0.186
6.00,-1.16,0.186
6.01,-1.03,0.186
6.03,-0.90,0.186
6.04,-0.76,0.186
6.05,-0.63,0.186
6.07,-0.50,0.186
6.08,-0.36,0.186
6.09,-0.23,0.187
6.11,-0.10,0.187
6.12,0.04,0.187
6.13,0.17,0.187
6.15,0.31,0.187
6.16,0.44,0.187
6.17,0.57,0.187
6.19,0.71,0.187
6.20,0.84,0.187
6.21,0.97,0.187
6.23,1.11,0.188
6.24,1.24,0.188
6.25,1.37,0.188
6.27,1.51,0.188
6.28,1.64,0.188
6.29,1.77,0.188
6.31,1.91,0.188
6.32,2.04,0.188
6.33,2.17,0.188
6.35,2.31,0.189
6.36,2.44,0.189
6.37,2.57,0.189
6.39,2.70,0.189
6.40,2.84,0.189
6.41,2.97,0.189
6.43,3.11,0.189
6.44,3.24,0.189
6.45,3.37,0.189
6.47,3.51,0.189
6.48,3.64,0.189
6.49,3.77,0.189
6.51,3.91,0.189
6.52,4.04,0.190
6.53,4.17,0.190
6.55,4.31,0.190
6.56,4.44,0.190
6.57,4.57,0.190
6.59,4.71,0.190
6.60,4.84,0.190
6.61,4.97,0.191
6.63,5.11,0.191
6.64,5.24,0.191
6.65,5.38,0.191
6.67,5.51,0.191
6.68,5.64,0.191
6.69,5.78,0.191
6.71,5.91,0.191
6.72,6.04,0.192
6.73,6.18,0.192
6.75,6.31,0.192
6.76,6.44,0.192
6.77,6.58,0.192
6.79,6.71,0.192
6.80,6.84,0.192
6.81,6.98,0.192
6.83,7.11,0.193
6.84,7.24,0.193
6.85,7.38,0.193
6.87,7.51,0.193
6.88,7.64,0.193
6.89,7.78,0.193
6.91,7.91,0.193
6.92,8.05,0.194
6.93,8.18,0.194
6.95,8.31,0.194
6.96,8.44,0.194
6.97,8.58,0.194
6.99,8.71,0.194
7.00,8.85,0.194
7.01,8.98,0.195
7.03,9.11,0.195
7.04,9.25,0.195
7.05,9.38,0.195
7.07,9.51,0.195
7.08,9.65,0.195
7.09,9.78,0.195
7.11,9.91,0.195
7.12,10.05,0.196
7.13,10.18,0.196
7.15,10.31,0.196
7.16,10.45,0.196
7.17,10.58,0.196
7.19,10.71,0.196
7.20,10.85,0.196
7.21,10.98,0.196
7.23,11.11,0.197
7.24,11.25,0.197
7.25,11.38,0.197
7.27,11.52,0.197
7.28,11.65,0.197
7.29,11.78,0.197
7.31,11.92,0.197
7.32,12.05,0.198
7.33,12.18,0.198
7.35,12.32,0.198
7.36,12.45,0.198
7.37,12.58,0.198
7.39,12.72,0.198
7.40,12.85,0.199
7.41,12.98,0.199
7.43,13.12,0.199
7.44,13.25,0.199
7.45,13.38,0.199
7.47,13.52,0.199
7.48,13.65,0.199
7.49,13.78,0.200
7.51,13.92,0.200
7.52,14.05,0.200
7.53,14.19,0.200
7.55,14.32,0.200
7.56,14.45,0.200
7.57,14.59,0.201
7.59,14.72,0.201
7.60,14.85,0.201
7.61,14.98,0.201
7.63,15.12,0.201
7.64,15.25,0.201
7.65,15.38,0.201
7.67,15.52,0.202
7.68,15.65,0.202
7.69,15.79,0.202
7.71,15.92,0.202
7.72,16.05,0.202
7.73,16.19,0.202
7.75,16.32,0.203
7.76,16.45,0.203
7.77,16.59,0.203
7.79,16.72,0.203
7.80,16.85,0.203
7.81,16.99,0.203
7.83,17.12,0.204
7.84,17.25,0.204
7.85,17.39,0.204
7.87,17.52,0.204
7.88,17.65,0.204
7.89,17.79,0.204
7.91,17.92,0.204
7.92,18.05,0.205
7.93,18.19,0.205
7.95,18.32,0.205
7.96,18.45,0.205
7.97,18.59,0.205
7.99,18.72,0.206
8.00,18.85,0.206
8.01,18.99,0.206
8.03,19.12,0.206
8.04,19.26,0.206
8.05,19.39,0.206
8.07,19.52,0.207
8.08,19.66,0.207
8.09,19.79,0.207
8.11,19.92,0.207
8.12,20.06,0.207
8.13,20.19,0.207
8.15,20.32,0.208
8.16,20.45,0.208
8.17,20.59,0.208
8.19,20.72,0.208
8.20,20.86,0.208
8.21,20.99,0.209
8.23,21.12,0.209
8.24,21.26,0.209
8.25,21.39,0.209
8.27,21.52,0.209
8.28,21.66,0.210
8.29,21.79,0.210
8.31,21.92,0.210
8.32,22.06,0.210
8.33,22.19,0.210
8.35,22.33,0.210
8.36,22.46,0.211
8.37,22.59,0.211
8.39,22.73,0.211
8.40,22.86,0.211
8.41,22.99,0.212
8.43,23.13,0.212
8.44,23.26,0.212
8.45,23.39,0.212
8.47,23.52,0.212
8.48,23.66,0.213
8.49,23.79,0.213
8.51,23.93,0.213
8.52,24.06,0.213
8.53,24.19,0.213
8.55,24.33,0.214
8.56,24.46,0.214
8.57,24.59,0.214
8.59,24.73,0.214
8.60,24.86,0.214
8.61,24.99,0.215
8.63,25.13,0.215
8.64,25.26,0.215
8.65,25.39,0.215
8.67,25.53,0.216
8.68,25.66,0.216
8.69,25.79,0.216
8.71,25.93,0.216
8.72,26.06,0.216
8.73,26.19,0.217
8.75,26.33,0.217
8.76,26.46,0.217
8.77,26.59,0.218
8.79,26.73,0.218
8.80,26.86,0.218
8.81,26.99,0.218
8.83,27.13,0.218
8.84,27.26,0.219
8.85,27.39,0.219
8.87,27.53,0.219
8.88,27.66,0.219
8.89,27.80,0.220
8.91,27.93,0.220
8.92,28.06,0.220
8.93,28.19,0.220
8.95,28.33,0.221
8.96,28.46,0.221
8.97,28.60,0.221
8.99,28.73,0.221
9.00,28.86,0.222
9.01,29.00,0.222
9.03,29.13,0.222
9.04,29.26,0.222
9.05,29.39,0.223
9.07,29.53,0.223
9.08,29.66,0.223
9.09,29.80,0.223
9.11,29.93,0.224
9.12,30.06,0.224
9.13,30.20,0.224
9.15,30.33,0.225
9.16,30.46,0.225
9.17,30.60,0.225
9.19,30.73,0.225
9.20,30.86,0.226
9.21,31.00,0.226
9.23,31.13,0.226
9.24,31.26,0.226
9.25,31.40,0.227
9.27,31.53,0.227
9.28,31.66,0.227
9.29,31.80,0.228
9.31,31.93,0.228
9.32,32.06,0.228
9.33,32.20,0.229
9.35,32.33,0.229
9.36,32.46,0.229
9.37,32.60,0.230
9.39,32.73,0.230
9.40,32.86,0.230
9.41,33.00,0.230
9.43,33.13,0.231
9.44,33.26,0.231
9.45,33.40,0.231
9.47,33.53,0.232
9.48,33.66,0.232
9.49,33.80,0.232
9.51,33.93,0.233
9.52,34.07,0.233
9.53,34.20,0.233
9.55,34.33,0.233
9.56,34.47,0.234
9.57,34.60,0.234
9.59,34.74,0.235
9.60,34.87,0.235
9.61,35.00,0.236
9.63,35.14,0.236
9.64,35.27,0.237
9.65,35.40,0.237
9.67,35.54,0.238
9.68,35.67,0.238
9.69,35.80,0.238
9.71,35.94,0.238
9.72,36.07,0.239
9.73,36.20,0.239
9.75,36.34,0.239
9.76,36.47,0.240
9.77,36.60,0.240
9.79,36.74,0.240
9.80,36.87,0.241
9.81,37.00,0.241
9.83,37.14,0.241
9.84,37.27,0.242
9.85,37.40,0.242
9.87,37.54,0.242
9.88,37.67,0.243
9.89,37.80,0.243
9.91,37.94,0.244
9.92,38.07,0.244
9.93,38.20,0.244
9.95,38.34,0.245
9.96,38.47,0.245
9.97,38.60,0.246
9.99,38.73,0.246
10.00,38.87,0.246
10.01,39.00,0.247
10.03,39.14,0.247
10.04,39.27,0.248
10.05,39.40,0.248
10.07,39.54,0.248
10.08,39.67,0.249
10.09,39.80,0.249
10.11,39.93,0.250
10.12,40.07,0.250
10.13,40.20,0.251
10.15,40.33,0.251
10.16,40.47,0.252
10.17,40.60,0.252
10.19,40.73,0.252
10.20,40.87,0.253
10.21,41.00,0.253
10.23,41.13,0.254
10.24,41.27,0.254
10.25,41.40,0.255
10.27,41.53,0.255
10.28,41.67,0.256
10.29,41.80,0.256
10.31,41.93,0.257
10.32,42.07,0.257
10.33,42.20,0.258
10.35,42.33,0.258
10.36,42.47,0.259
10.37,42.60,0.260
10.39,42.73,0.261
10.40,42.87,0.261
10.41,43.00,0.262
10.43,43.13,0.263
10.44,43.26,0.263
10.45,43.40,0.264
10.47,43.53,0.264
10.48,43.66,0.265
10.49,43.80,0.266
10.51,43.93,0.266
10.52,44.07,0.267
10.53,44.20,0.268
10.55,44.33,0.269
10.56,44.46,0.270
10.57,44.60,0.270
10.59,44.73,0.271
10.60,44.86,0.272
10.61,45.00,0.273
10.63,45.13,0.273
10.64,45.26,0.274
10.65,45.40,0.276
10.67,45.53,0.277
10.68,45.66,0.277
10.69,45.80,0.278
10.71,45.93,0.279
10.72,46.06,0.281
10.73,46.20,0.282
10.75,46.33,0.283
10.76,46.46,0.283
10.77,46.59,0.284
10.79,46.73,0.285
10.80,46.86,0.286
10.81,46.99,0.286
10.83,47.13,0.287
10.84,47.26,0.288
10.85,47.39,0.289
10.87,47.53,0.291
10.88,47.66,0.292
10.89,47.80,0.294
10.91,47.93,0.297
10.92,48.06,0.298
10.93,48.19,0.299
10.95,48.33,0.300
10.96,48.46,0.302
10.97,48.59,0.303
10.99,48.73,0.305
11.00,48.86,0.306
11.01,48.99,0.307
11.03,49.12,0.310
11.04,49.26,0.311
11.05,49.39,0.313
11.07,49.53,0.314
11.08,49.66,0.316
11.09,49.79,0.317
11.11,49.92,0.319
11.12,50.06,0.320
11.13,50.19,0.321
11.15,50.32,0.323
11.16,50.46,0.325
11.17,50.59,0.327
11.19,50.72,0.329
11.20,50.86,0.331
11.21,50.99,0.333
11.23,51.12,0.335
11.24,51.25,0.337
11.25,51.39,0.339
11.27,51.52,0.341
11.28,51.65,0.342
11.29,51.78,0.345
11.31,51.92,0.347
11.32,52.05,0.348
11.33,52.18,0.350
11.35,52.32,0.352
11.36,52.45,0.355
11.37,52.58,0.357
11.39,52.71,0.359
11.40,52.85,0.362
11.41,52.98,0.364
11.43,53.11,0.368
11.44,53.24,0.369
11.45,53.38,0.371
11.47,53.51,0.372
11.48,53.64,0.376
11.49,53.78,0.377
11.51,53.91,0.380
11.52,54.04,0.382
11.53,54.17,0.385
11.55,54.31,0.387
11.56,54.44,0.389
11.57,54.57,0.392
11.59,54.71,0.395
11.60,54.84,0.397
11.61,54.97,0.399
11.63,55.10,0.402
11.64,55.24,0.404
11.65,55.37,0.407
11.67,55.50,0.409
11.68,55.64,0.411
11.69,55.77,0.413
11.71,55.90,0.416
11.72,56.04,0.419
11.73,56.17,0.421
11.75,56.30,0.423
11.76,56.43,0.425
11.77,56.57,0.428
11.79,56.70,0.429
11.80,56.83,0.432
11.81,56.96,0.433
11.83,57.10,0.435
11.84,57.23,0.437
11.85,57.36,0.438
11.87,57.49,0.441
11.88,57.63,0.442
11.89,57.76,0.444
11.91,57.89,0.445
11.92,58.03,0.447
11.93,58.16,0.449
11.95,58.29,0.450
11.96,58.42,0.452
11.97,58.56,0.453
11.99,58.69,0.455
12.00,58.82,0.456
12.01,58.96,0.457
12.03,59.09,0.457
12.04,59.22,0.458
12.05,59.36,0.458
12.07,59.49,0.459
12.08,59.62,0.459
12.09,59.76,0.460
12.11,59.89,0.460
12.12,60.02,0.460
12.13,60.16,0.460
12.15,60.29,0.461
12.16,60.42,0.461
12.17,60.56,0.461
12.19,60.69,0.461
12.20,60.83,0.461
12.21,60.96,0.462
12.23,61.09,0.462
12.24,61.23,0.462
12.25,61.36,0.462
12.27,61.49,0.461
12.28,61.63,0.460
12.29,61.76,0.460
12.31,61.89,0.459
12.32,62.03,0.458
12.33,62.16,0.458
12.35,62.30,0.456
12.36,62.43,0.454
12.37,62.56,0.453
12.39,62.70,0.451
12.40,62.83,0.450
12.41,62.97,0.448
12.43,63.10,0.446
12.44,63.23,0.445
12.45,63.37,0.443
12.47,63.50,0.441
12.48,63.64,0.440
12.49,63.77,0.438
12.51,63.90,0.438
12.52,64.04,0.437
12.53,64.17,0.436
12.55,64.31,0.435
12.56,64.44,0.435
12.57,64.57,0.433
12.59,64.71,0.432
12.60,64.84,0.432
12.61,64.98,0.431
12.63,65.11,0.431
12.64,65.24,0.430
12.65,65.38,0.430
12.67,65.51,0.430
12.68,65.64,0.429
12.69,65.78,0.429
12.71,65.91,0.429
12.72,66.04,0.429
12.73,66.18,0.428
12.75,66.31,0.428
12.76,66.44,0.428
12.77,66.58,0.428
12.79,66.71,0.428
12.80,66.84,0.428
12.81,66.98,0.428
12.83,67.11,0.428
12.84,67.25,0.428
12.85,67.38,0.428
12.87,67.51,0.428
12.88,67.65,0.428
12.89,67.78,0.428
12.91,67.91,0.428
12.92,68.05,0.429
12.93,68.18,0.429
12.95,68.31,0.429
12.96,68.45,0.429
12.97,68.58,0.430
12.99,68.71,0.430
13.00,68.84,0.431
13.01,68.98,0.431
13.03,69.11,0.432
13.04,69.24,0.432
13.05,69.38,0.433
13.07,69.51,0.433
13.08,69.64,0.434
13.09,69.78,0.434
13.11,69.91,0.435
13.12,70.04,0.437
13.13,70.18,0.437
13.15,70.31,0.438
13.16,70.44,0.439
13.17,70.58,0.440
13.19,70.71,0.441
13.20,70.84,0.442
13.21,70.98,0.443
13.23,71.11,0.443
13.24,71.24,0.444
13.25,71.38,0.445
13.27,71.51,0.446
13.28,71.64,0.448
13.29,71.77,0.448
13.31,71.91,0.449
13.32,72.04,0.450
13.33,72.17,0.451
13.35,72.31,0.452
13.36,72.44,0.453
13.37,72.57,0.454
13.39,72.71,0.455
13.40,72.84,0.456
13.41,72.97,0.457
13.43,73.11,0.458
13.44,73.24,0.459
13.45,73.37,0.460
13.47,73.51,0.461
13.48,73.64,0.462
13.49,73.77,0.463
13.51,73.91,0.464
13.52,74.04,0.466
13.53,74.17,0.467
13.55,74.30,0.468
13.56,74.44,0.469
13.57,74.57,0.470
13.59,74.70,0.471
13.60,74.84,0.472
13.61,74.97,0.473
13.63,75.10,0.474
13.64,75.24,0.475
13.65,75.37,0.476
13.67,75.50,0.477
13.68,75.64,0.477
13.69,75.77,0.479
13.71,75.90,0.480
13.72,76.04,0.481
13.73,76.17,0.483
13.75,76.30,0.484
13.76,76.44,0.485
13.77,76.57,0.486
13.79,76.70,0.488
13.80,76.83,0.488
13.81,76.97,0.489
13.83,77.10,0.490
13.84,77.23,0.490
13.85,77.37,0.492
13.87,77.50,0.493
13.88,77.63,0.495
13.89,77.77,0.496
13.91,77.90,0.498
13.92,78.03,0.499
13.93,78.17,0.500
13.95,78.30,0.501
13.96,78.43,0.502
13.97,78.56,0.503
13.99,78.70,0.504
14.00,78.83,0.505
14.01,78.97,0.506
14.03,79.10,0.508
14.04,79.23,0.510
14.05,79.36,0.511
14.07,79.50,0.512
14.08,79.63,0.513
14.09,79.76,0.514
14.11,79.90,0.515
14.12,80.03,0.516
14.13,80.16,0.517
14.15,80.30,0.518
14.16,80.43,0.519
14.17,80.56,0.520
14.19,80.70,0.521
14.20,80.83,0.523
14.21,80.96,0.524
14.23,81.09,0.526
14.24,81.23,0.526
14.25,81.36,0.528
14.27,81.49,0.530
14.28,81.63,0.531
14.29,81.76,0.532
14.31,81.89,0.533
14.32,82.03,0.534
14.33,82.16,0.534
14.35,82.29,0.535
14.36,82.43,0.536
14.37,82.56,0.538
14.39,82.69,0.540
14.40,82.83,0.541
14.41,82.96,0.543
14.43,83.09,0.545
14.44,83.23,0.547
14.45,83.36,0.547
14.47,83.49,0.548
14.48,83.63,0.550
14.49,83.76,0.550
14.51,83.89,0.552
14.52,84.02,0.553
14.53,84.16,0.554
14.55,84.29,0.555
14.56,84.42,0.556
14.57,84.56,0.557
14.59,84.69,0.558
14.60,84.82,0.560
14.61,84.96,0.561
14.63,85.09,0.562
14.64,85.22,0.564
14.65,85.35,0.565
14.67,85.49,0.566
14.68,85.62,0.567
14.69,85.75,0.568
14.71,85.89,0.569
14.72,86.02,0.570
14.73,86.15,0.572
14.75,86.28,0.572
14.76,86.42,0.574
14.77,86.55,0.575
14.79,86.69,0.576
14.80,86.82,0.578
14.81,86.95,0.580
14.83,87.09,0.581
14.84,87.22,0.583
14.85,87.35,0.585
14.87,87.49,0.586
14.88,87.62,0.587
14.89,87.75,0.588
14.91,87.89,0.589
14.92,88.02,0.590
14.93,88.15,0.592
14.95,88.28,0.593
14.96,88.42,0.594
14.97,88.55,0.595
14.99,88.68,0.596
15.00,88.82,0.596
15.01,88.95,0.598
15.03,89.08,0.599
15.04,89.21,0.600
15.05,89.35,0.601
15.07,89.48,0.602
15.08,89.61,0.604
15.09,89.75,0.606
15.11,89.88,0.606
15.12,90.01,0.607
15.13,90.15,0.609
15.15,90.28,0.610
15.16,90.41,0.611
15.17,90.55,0.612
15.19,90.68,0.614
15.20,90.81,0.615
15.21,90.95,0.616
15.23,91.08,0.619
15.24,91.21,0.619
15.25,91.34,0.620
15.27,91.48,0.622
15.28,91.61,0.623
15.29,91.74,0.624
15.31,91.88,0.624
15.32,92.01,0.625
15.33,92.15,0.626
15.35,92.28,0.627
15.36,92.41,0.628
15.37,92.54,0.630
15.39,92.68,0.631
15.40,92.81,0.632
15.41,92.94,0.634
15.43,93.08,0.635
15.44,93.21,0.635
15.45,93.34,0.636
15.47,93.47,0.637
15.48,93.61,0.637
15.49,93.74,0.638
15.51,93.87,0.639
15.52,94.01,0.640
15.53,94.14,0.641
15.55,94.27,0.643
15.56,94.41,0.643
15.57,94.54,0.644
15.59,94.67,0.645
15.60,94.81,0.645
15.61,94.94,0.646
15.63,95.07,0.647
15.64,95.21,0.649
15.65,95.34,0.650
15.67,95.47,0.651
15.68,95.61,0.652
15.69,95.74,0.653
15.71,95.87,0.653
15.72,96.01,0.654
15.73,96.14,0.654
15.75,96.27,0.655
15.76,96.41,0.655
15.77,96.54,0.656
15.79,96.67,0.657
15.80,96.81,0.658
15.81,96.94,0.659
15.83,97.07,0.660
15.84,97.21,0.661
15.85,97.34,0.661
15.87,97.47,0.662
15.88,97.61,0.662
15.89,97.74,0.663
15.91,97.87,0.663
15.92,98.01,0.664
15.93,98.14,0.664
15.95,98.27,0.665
15.96,98.40,0.666
15.97,98.54,0.667
15.99,98.67,0.667
16.00,98.80,0.667
16.01,98.94,0.668
16.03,99.07,0.669
16.04,99.21,0.669
16.05,99.34,0.669
16.07,99.47,0.670
16.08,99.61,0.670
16.09,99.74,0.671
16.11,99.87,0.671
16.12,100.00,0.672
16.13,100.14,0.672
16.15,100.27,0.672
16.16,100.40,0.673
16.17,100.54,0.673
16.19,100.67,0.674
16.20,100.80,0.674
16.21,100.94,0.674
16.23,101.07,0.675
16.24,101.20,0.675
16.25,101.34,0.675
16.27,101.47,0.676
16.28,101.61,0.676
16.29,101.74,0.676
16.31,101.87,0.677
16.32,102.01,0.677
16.33,102.14,0.677
16.35,102.27,0.677
16.36,102.41,0.678
16.37,102.54,0.678
16.39,102.67,0.678
16.40,102.81,0.679
16.41,102.94,0.679
16.43,103.07,0.679
16.44,103.21,0.679
16.45,103.34,0.679
16.47,103.48,0.679
16.48,103.61,0.680
16.49,103.74,0.680
16.51,103.88,0.680
16.52,104.01,0.680
16.53,104.14,0.680
16.55,104.28,0.680
16.56,104.41,0.680
16.57,104.54,0.680
16.59,104.68,0.680
16.60,104.81,0.680
16.61,104.94,0.680
16.63,105.08,0.680
16.64,105.21,0.680
16.65,105.34,0.680
16.67,105.48,0.680
16.68,105.61,0.680
16.69,105.74,0.680
16.71,105.88,0.680
16.72,106.01,0.679
16.73,106.15,0.679
16.75,106.28,0.679
16.76,106.41,0.679
16.77,106.55,0.679
16.79,106.68,0.679
16.80,106.82,0.678
16.81,106.95,0.678
16.83,107.08,0.678
16.84,107.22,0.678
16.85,107.35,0.677
16.87,107.48,0.677
16.88,107.62,0.676
16.89,107.75,0.676
16.91,107.88,0.676
16.92,108.02,0.675
16.93,108.15,0.675
16.95,108.29,0.674
16.96,108.42,0.674
16.97,108.55,0.674
16.99,108.69,0.673
17.00,108.82,0.673
17.01,108.95,0.672
17.03,109.09,0.671
17.04,109.22,0.670
17.05,109.35,0.668
17.07,109.49,0.668
17.08,109.62,0.667
17.09,109.76,0.666
17.11,109.89,0.666
17.12,110.02,0.665
17.13,110.16,0.664
17.15,110.29,0.664
17.16,110.42,0.663
17.17,110.56,0.662
17.19,110.69,0.662
17.20,110.83,0.661
17.21,110.96,0.660
17.23,111.09,0.659
17.24,111.22,0.658
17.25,111.36,0.656
17.27,111.49,0.653
17.28,111.63,0.653
17.29,111.76,0.652
17.31,111.89,0.651
17.32,112.03,0.650
17.33,112.16,0.650
17.35,112.30,0.648
17.36,112.43,0.647
17.37,112.56,0.646
17.39,112.70,0.646
17.40,112.83,0.645
17.41,112.97,0.644
17.43,113.10,0.643
17.44,113.23,0.641
17.45,113.37,0.640
17.47,113.50,0.639
17.48,113.63,0.639
17.49,113.77,0.638
17.51,113.90,0.637
17.52,114.04,0.636
17.53,114.17,0.635
17.55,114.30,0.633
17.56,114.44,0.632
17.57,114.57,0.631
17.59,114.70,0.629
17.60,114.84,0.628
17.61,114.97,0.627
17.63,115.11,0.625
17.64,115.24,0.624
17.65,115.37,0.622
17.67,115.51,0.621
17.68,115.64,0.619
17.69,115.77,0.619
17.71,115.91,0.618
17.72,116.04,0.616
17.73,116.18,0.615
17.75,116.31,0.614
17.76,116.44,0.613
17.77,116.58,0.611
17.79,116.71,0.610
17.80,116.84,0.608
17.81,116.98,0.608
17.83,117.11,0.607
17.84,117.25,0.606
17.85,117.38,0.605
17.87,117.51,0.603
17.88,117.65,0.601
17.89,117.78,0.600
17.91,117.92,0.599
17.92,118.05,0.598
17.93,118.19,0.596
17.95,118.32,0.595
17.96,118.45,0.594
17.97,118.59,0.593
17.99,118.72,0.592
18.00,118.85,0.591
18.01,118.99,0.589
18.03,119.12,0.587
18.04,119.25,0.587
18.05,119.39,0.585
18.07,119.52,0.584
18.08,119.65,0.582
18.09,119.79,0.581
18.11,119.92,0.579
18.12,120.06,0.578
18.13,120.19,0.576
18.15,120.32,0.575
18.16,120.46,0.573
18.17,120.59,0.572
18.19,120.73,0.571
18.20,120.86,0.570
18.21,120.99,0.568
18.23,121.13,0.567
18.24,121.26,0.566
18.25,121.39,0.565
18.27,121.53,0.564
18.28,121.66,0.563
18.29,121.80,0.561
18.31,121.93,0.560
18.32,122.07,0.559
18.33,122.20,0.557
18.35,122.33,0.556
18.36,122.47,0.555
18.37,122.60,0.553
18.39,122.74,0.552
18.40,122.87,0.551
18.41,123.00,0.550
18.43,123.14,0.549
18.44,123.27,0.548
18.45,123.41,0.547
18.47,123.54,0.545
18.48,123.67,0.544
18.49,123.81,0.542
18.51,123.94,0.540
18.52,124.07,0.539
18.53,124.21,0.538
18.55,124.34,0.535
18.56,124.47,0.534
18.57,124.61,0.533
18.59,124.74,0.531
18.60,124.88,0.530
18.61,125.01,0.528
18.63,125.14,0.527
18.64,125.28,0.526
18.65,125.41,0.525
18.67,125.55,0.524
18.68,125.68,0.523
18.69,125.81,0.522
18.71,125.95,0.520
18.72,126.08,0.520
18.73,126.21,0.518
18.75,126.35,0.517
18.76,126.48,0.515
18.77,126.62,0.514
18.79,126.75,0.513
18.80,126.88,0.511
18.81,127.02,0.509
18.83,127.15,0.508
18.84,127.28,0.506
18.85,127.42,0.505
18.87,127.55,0.504
18.88,127.69,0.503
18.89,127.82,0.502
18.91,127.95,0.500
18.92,128.09,0.499
18.93,128.22,0.497
18.95,128.36,
18.96,128.49,
18.97,128.62,
18.99,,
18.99,,

[step]
Ramp 10.00 °C/min to -60.00 °C
Time,Temperature,Heat Flow (Normalized)
min,°C,W/g
20.99,130.13,0.031
21.01,130.13,0.030
21.02,130.13,0.030
21.03,130.12,0.030
21.05,130.11,0.030
21.06,130.09,0.045
21.07,130.05,0.059
21.09,130.00,0.066
21.10,129.94,0.065
21.11,129.86,0.056
21.13,129.77,0.018
21.14,129.67,-0.016
21.15,129.57,-0.055
21.17,129.46,-0.090
21.18,129.35,-0.122
21.19,129.23,-0.149
21.21,129.12,-0.171
21.22,129.00,-0.191
21.23,128.88,-0.204
21.25,128.76,-0.216
21.26,128.63,-0.229
21.27,128.51,-0.236
21.29,128.38,-0.246
21.30,128.26,-0.254
21.31,128.13,-0.259
21.33,128.00,-0.266
21.34,127.87,-0.271
21.35,127.74,-0.274
21.37,127.61,-0.280
21.38,127.48,-0.281
21.39,127.35,-0.284
21.41,127.22,-0.287
21.42,127.09,-0.290
21.43,126.96,-0.291
21.45,126.83,-0.292
21.46,126.70,-0.293
21.47,126.57,-0.295
21.49,126.43,-0.296
21.50,126.30,-0.297
21.51,126.17,-0.298
21.53,126.04,-0.298
21.54,125.91,-0.299
21.55,125.78,-0.300
21.57,125.64,-0.301
21.58,125.51,-0.301
21.59,125.38,-0.302
21.61,125.25,-0.302
21.62,125.11,-0.303
21.63,124.98,-0.303
21.65,124.85,-0.303
21.66,124.72,-0.303
21.67,124.59,-0.304
21.69,124.45,-0.304
21.70,124.32,-0.304
21.71,124.19,-0.305
21.73,124.06,-0.305
21.74,123.92,-0.305
21.75,123.79,-0.306
21.77,123.66,-0.306
21.78,123.52,-0.307
21.79,123.39,-0.307
21.81,123.26,-0.307
21.82,123.13,-0.308
21.83,122.99,-0.308
21.85,122.86,-0.308
21.86,122.73,-0.308
21.87,122.60,-0.309
21.89,122.46,-0.309
21.90,122.33,-0.309
21.91,122.20,-0.310
21.93,122.06,-0.310
21.94,121.93,-0.310
21.95,121.80,-0.310
21.97,121.67,-0.311
21.98,121.53,-0.311
21.99,121.40,-0.311
22.01,121.27,-0.312
22.02,121.13,-0.312
22.03,121.00,-0.312
22.05,120.87,-0.312
22.06,120.74,-0.313
22.07,120.60,-0.313
22.09,120.47,-0.313
22.10,120.34,-0.313
22.11,120.20,-0.313
22.13,120.07,-0.314
22.14,119.94,-0.314
22.15,119.80,-0.314
22.17,119.67,-0.314
22.18,119.54,-0.315
22.19,119.41,-0.315
22.21,119.27,-0.315
22.22,119.14,-0.315
22.23,119.01,-0.315
22.25,118.87,-0.316
22.26,118.74,-0.316
22.27,118.61,-0.316
22.29,118.47,-0.316
22.30,118.34,-0.316
22.31,118.21,-0.316
22.33,118.07,-0.317
22.34,117.94,-0.317
22.35,117.81,-0.317
22.37,117.68,-0.317
22.38,117.54,-0.317
22.39,117.41,-0.317
22.41,117.28,-0.317
22.42,117.14,-0.318
22.43,117.01,-0.318
22.45,116.88,-0.318
22.46,116.74,-0.318
22.47,116.61,-0.318
22.49,116.48,-0.318
22.50,116.34,-0.318
22.51,116.21,-0.319
22.53,116.08,-0.319
22.54,115.94,-0.319
22.55,115.81,-0.319
22.57,115.68,-0.319
22.58,115.54,-0.319
22.59,115.41,-0.319
22.61,115.28,-0.319
22.62,115.15,-0.319
22.63,115.01,-0.320
22.65,114.88,-0.320
22.66,114.75,-0.320
22.67,114.61,-0.320
22.69,114.48,-0.320
22.70,114.35,-0.320
22.71,114.21,-0.320
22.73,114.08,-0.320
22.74,113.95,-0.320
22.75,113.81,-0.320
22.77,113.68,-0.320
22.78,113.55,-0.320
22.79,113.41,-0.320
22.81,113.28,-0.321
22.82,113.15,-0.321
22.83,113.02,-0.321
22.85,112.88,-0.321
22.86,112.75,-0.321
22.87,112.62,-0.321
22.89,112.48,-0.321
22.90,112.35,-0.321
22.91,112.22,-0.321
22.93,112.08,-0.321
22.94,111.95,-0.321
22.95,111.82,-0.321
22.97,111.68,-0.321
22.98,111.55,-0.321
22.99,111.42,-0.321
23.01,111.28,-0.322
23.02,111.15,-0.322
23.03,111.02,-0.322
23.05,110.88,-0.322
23.06,110.75,-0.322
23.07,110.62,-0.322
23.09,110.48,-0.322
23.10,110.35,-0.322
23.11,110.22,-0.322
23.13,110.08,-0.322
23.14,109.95,-0.322
23.15,109.82,-0.322
23.17,109.68,-0.322
23.18,109.55,-0.322
23.19,109.42,-0.322
23.21,109.28,-0.322
23.22,109.15,-0.322
23.23,109.02,-0.322
23.25,108.88,-0.322
23.26,108.75,-0.322
23.27,108.62,-0.322
23.29,108.48,-0.322
23.30,108.35,-0.322
23.31,108.22,-0.322
23.33,108.08,-0.322
23.34,107.95,-0.322
23.35,107.82,-0.322
23.37,107.68,-0.322
23.38,107.55,-0.322
23.39,107.42,-0.322
23.41,107.28,-0.322
23.42,107.15,-0.322
23.43,107.02,-0.322
23.45,106.88,-0.322
23.46,106.75,-0.322
23.47,106.62,-0.322
23.49,106.48,-0.322
23.50,106.35,-0.322
23.51,106.22,-0.322
23.53,106.08,-0.322
23.54,105.95,-0.322
23.55,105.82,-0.322
23.57,105.69,-0.322
23.58,105.55,-0.322
23.59,105.42,-0.322
23.61,105.28,-0.322
23.62,105.15,-0.322
23.63,105.02,-0.322
23.65,104.88,-0.322
23.66,104.75,-0.322
23.67,104.62,-0.321
23.69,104.49,-0.321
23.70,104.35,-0.321
23.71,104.22,-0.321
23.73,104.09,-0.321
23.74,103.95,-0.321
23.75,103.82,-0.321
23.77,103.69,-0.321
23.78,103.55,-0.321
23.79,103.42,-0.321
23.81,103.29,-0.321
23.82,103.15,-0.320
23.83,103.02,-0.320
23.85,102.89,-0.320
23.86,102.75,-0.320
23.87,102.62,-0.320
23.89,102.49,-0.320
23.90,102.35,-0.320
23.91,102.22,-0.320
23.93,102.09,-0.320
23.94,101.95,-0.320
23.95,101.82,-0.319
23.97,101.69,-0.319
23.98,101.55,-0.319
23.99,101.42,-0.319
24.01,101.29,-0.319
24.02,101.15,-0.319
24.03,101.02,-0.319
24.05,100.89,-0.319
24.06,100.75,-0.319
24.07,100.62,-0.318
24.09,100.49,-0.318
24.10,100.35,-0.318
24.11,100.22,-0.318
24.13,100.09,-0.318
24.14,99.95,-0.318
24.15,99.82,-0.318
24.17,99.69,-0.317
24.18,99.55,-0.317
24.19,99.42,-0.317
24.21,99.29,-0.317
24.22,99.15,-0.317
24.23,99.02,-0.317
24.25,98.89,-0.317
24.26,98.75,-0.316
24.27,98.62,-0.316
24.29,98.49,-0.316
24.30,98.35,-0.316
24.31,98.22,-0.316
24.33,98.09,-0.315
24.34,97.95,-0.315
24.35,97.82,-0.315
24.37,97.69,-0.315
24.38,97.55,-0.315
24.39,97.42,-0.314
24.41,97.29,-0.314
24.42,97.15,-0.314
24.43,97.02,-0.314
24.45,96.89,-0.314
24.46,96.75,-0.314
24.47,96.62,-0.313
24.49,96.49,-0.313
24.50,96.35,-0.313
24.51,96.22,-0.313
24.53,96.09,-0.312
24.54,95.95,-0.312
24.55,95.82,-0.312
24.57,95.69,-0.312
24.58,95.55,-0.312
24.59,95.42,-0.311
24.61,95.29,-0.311
24.62,95.15,-0.311
24.63,95.02,-0.311
24.65,94.89,-0.311
24.66,94.75,-0.310
24.67,94.62,-0.310
24.69,94.49,-0.310
24.70,94.35,-0.309
24.71,94.22,-0.309
24.73,94.09,-0.309
24.74,93.95,-0.309
24.75,93.82,-0.309
24.77,93.69,-0.309
24.78,93.55,-0.308
24.79,93.42,-0.308
24.81,93.28,-0.308
24.82,93.15,-0.308
24.83,93.02,-0.307
24.85,92.89,-0.307
24.86,92.75,-0.307
24.87,92.62,-0.307
24.89,92.49,-0.306
24.90,92.35,-0.306
24.91,92.22,-0.306
24.93,92.09,-0.306
24.94,91.95,-0.306
24.95,91.82,-0.305
24.97,91.69,-0.305
24.98,91.55,-0.305
24.99,91.42,-0.305
25.01,91.29,-0.304
25.02,91.15,-0.304
25.03,91.02,-0.304
25.05,90.88,-0.304
25.06,90.75,-0.303
25.07,90.62,-0.303
25.09,90.49,-0.303
25.10,90.35,-0.303
25.11,90.22,-0.302
25.13,90.08,-0.302
25.14,89.95,-0.302
25.15,89.82,-0.302
25.17,89.69,-0.301
25.18,89.55,-0.301
25.19,89.42,-0.301
25.21,89.29,-0.301
25.22,89.15,-0.300
25.23,89.02,-0.300
25.25,88.89,-0.300
25.26,88.75,-0.300
25.27,88.62,-0.299
25.29,88.48,-0.299
25.30,88.35,-0.299
25.31,88.22,-0.298
25.33,88.09,-0.298
25.34,87.95,-0.298
25.35,87.82,-0.298
25.37,87.68,-0.297
25.38,87.55,-0.297
25.39,87.42,-0.297
25.41,87.28,-0.296
25.42,87.15,-0.296
25.43,87.02,-0.296
25.45,86.88,-0.296
25.46,86.75,-0.295
25.47,86.62,-0.295
25.49,86.48,-0.295
25.50,86.35,-0.295
25.51,86.22,-0.294
25.53,86.08,-0.294
25.54,85.95,-0.294
25.55,85.82,-0.293
25.57,85.68,-0.293
25.58,85.55,-0.293
25.59,85.42,-0.293
25.61,85.28,-0.292
25.62,85.15,-0.292
25.63,85.02,-0.292
25.65,84.89,-0.292
25.66,84.75,-0.292
25.67,84.62,-0.291
25.69,84.48,-0.291
25.70,84.35,-0.291
25.71,84.22,-0.291
25.73,84.08,-0.290
25.74,83.95,-0.290
25.75,83.82,-0.290
25.77,83.68,-0.290
25.78,83.55,-0.289
25.79,83.42,-0.289
25.81,83.29,-0.289
25.82,83.15,-0.289
25.83,83.02,-0.289
25.85,82.88,-0.288
25.86,82.75,-0.288
25.87,82.62,-0.288
25.89,82.48,-0.288
25.90,82.35,-0.287
25.91,82.22,-0.287
25.93,82.08,-0.287
25.94,81.95,-0.287
25.95,81.82,-0.287
25.97,81.68,-0.287
25.98,81.55,-0.286
25.99,81.42,-0.286
26.01,81.28,-0.286
26.02,81.15,-0.285
26.03,81.02,-0.285
26.05,80.88,-0.285
26.06,80.75,-0.285
26.07,80.62,-0.285
26.09,80.48,-0.285
26.10,80.35,-0.284
26.11,80.22,-0.284
26.13,80.08,-0.284
26.14,79.95,-0.284
26.15,79.82,-0.283
26.17,79.68,-0.283
26.18,79.55,-0.283
26.19,79.42,-0.283
26.21,79.28,-0.283
26.22,79.15,-0.282
26.23,79.02,-0.282
26.25,78.88,-0.282
26.26,78.75,-0.282
26.27,78.62,-0.282
26.29,78.48,-0.281
26.30,78.35,-0.281
26.31,78.22,-0.281
26.33,78.08,-0.281
26.34,77.95,-0.281
26.35,77.82,-0.280
26.37,77.68,-0.280
26.38,77.55,-0.280
26.39,77.42,-0.280
26.41,77.28,-0.279
26.42,77.15,-0.279
26.43,77.02,-0.279
26.45,76.88,-0.279
26.46,76.75,-0.279
26.47,76.62,-0.278
26.49,76.48,-0.278
26.50,76.35,-0.278
26.51,76.22,-0.277
26.53,76.08,-0.277
26.54,75.95,-0.277
26.55,75.82,-0.277
26.57,75.68,-0.276
26.58,75.55,-0.276
26.59,75.42,-0.276
26.61,75.28,-0.276
26.62,75.15,-0.276
26.63,75.02,-0.275
[...]
88.49,-16.38,0.146
88.50,-16.25,0.146
88.51,-16.12,0.146
88.53,-15.98,0.146
88.54,-15.85,0.146
88.55,-15.72,0.146
88.57,-15.58,0.146
88.58,-15.45,0.146
88.60,-15.32,0.146
88.61,-15.18,0.146
88.62,-15.05,0.146
88.64,-14.92,0.146
88.65,-14.78,0.146
88.66,-14.65,0.146
88.68,-14.52,0.146
88.69,-14.38,0.146
88.70,-14.25,0.146
88.71,-14.12,0.147
88.73,-13.98,0.147
88.74,-13.85,0.147
88.75,-13.72,0.147
88.77,-13.58,0.147
88.78,-13.45,0.147
88.80,-13.32,0.147
88.81,-13.18,0.147
88.82,-13.05,0.147
88.84,-12.92,0.147
88.85,-12.78,0.147
88.86,-12.65,0.147
88.88,-12.51,0.147
88.89,-12.38,0.147
88.90,-12.25,0.147
88.91,-12.11,0.147
88.93,-11.98,0.147
88.94,-11.85,0.147
88.95,-11.71,0.147
88.97,-11.58,0.147
88.98,-11.45,0.147
89.00,-11.31,0.147
89.01,-11.18,0.147
89.02,-11.05,0.147
89.04,-10.91,0.147
89.05,-10.78,0.148
89.06,-10.64,0.148
89.08,-10.51,0.148
89.09,-10.38,0.148
89.10,-10.24,0.148
89.11,-10.11,0.148
89.13,-9.98,0.148
89.14,-9.84,0.148
89.15,-9.71,0.148
89.17,-9.58,0.148
89.18,-9.44,0.148
89.20,-9.31,0.148
89.21,-9.18,0.148
89.22,-9.04,0.148
89.24,-8.91,0.148
89.25,-8.78,0.148
89.26,-8.64,0.148
89.28,-8.51,0.148
89.29,-8.38,0.148
89.30,-8.24,0.148
89.31,-8.11,0.148
89.33,-7.98,0.149
89.34,-7.84,0.149
89.35,-7.71,0.149
89.37,-7.58,0.149
89.38,-7.44,0.149
89.40,-7.31,0.149
89.41,-7.18,0.149
89.42,-7.04,0.149
89.44,-6.91,0.149
89.45,-6.77,0.149
89.46,-6.64,0.149
89.48,-6.51,0.149
89.49,-6.37,0.149
89.50,-6.24,0.149
89.51,-6.11,0.149
89.53,-5.97,0.149
89.54,-5.84,0.149
89.55,-5.71,0.149
89.57,-5.57,0.149
89.58,-5.44,0.149
89.60,-5.30,0.149
89.61,-5.17,0.149
89.62,-5.04,0.149
89.64,-4.91,0.150
89.65,-4.77,0.150
89.66,-4.64,0.150
89.68,-4.50,0.150
89.69,-4.37,0.150
89.70,-4.24,0.150
89.71,-4.10,0.150
89.73,-3.97,0.150
89.74,-3.84,0.150
89.75,-3.70,0.150
89.77,-3.57,0.150
89.78,-3.44,0.150
89.80,-3.30,0.150
89.81,-3.17,0.150
89.82,-3.04,0.150
89.84,-2.90,0.150
89.85,-2.77,0.150
89.86,-2.64,0.150
89.88,-2.50,0.150
89.89,-2.37,0.150
89.90,-2.24,0.150
89.91,-2.10,0.150
89.93,-1.97,0.151
89.94,-1.83,0.151
89.95,-1.70,0.151
89.97,-1.57,0.151
89.98,-1.43,0.151
90.00,-1.30,0.151
90.01,-1.17,0.151
90.02,-1.04,0.151
90.04,-0.90,0.151
90.05,-0.77,0.151
90.06,-0.63,0.151
90.08,-0.50,0.151
90.09,-0.37,0.151
90.10,-0.23,0.151
90.11,-0.10,0.151
90.13,0.03,0.151
90.14,0.17,0.151
90.15,0.30,0.151
90.17,0.43,0.151
90.18,0.57,0.152
90.20,0.70,0.152
90.21,0.83,0.152
90.22,0.97,0.152
90.24,1.10,0.152
90.25,1.23,0.152
90.26,1.37,0.152
90.28,1.50,0.152
90.29,1.63,0.152
90.30,1.77,0.152
90.31,1.90,0.152
90.33,2.03,0.152
90.34,2.17,0.152
90.35,2.30,0.152
90.37,2.44,0.152
90.38,2.57,0.152
90.40,2.70,0.152
90.41,2.84,0.153
90.42,2.97,0.153
90.44,3.10,0.153
90.45,3.24,0.153
90.46,3.37,0.153
90.48,3.50,0.153
90.49,3.64,0.153
90.50,3.77,0.153
90.51,3.90,0.153
90.53,4.04,0.153
90.54,4.17,0.153
90.55,4.30,0.153
90.57,4.44,0.153
90.58,4.57,0.153
90.60,4.70,0.153
90.61,4.84,0.153
90.62,4.97,0.153
90.64,5.10,0.153
90.65,5.24,0.153
90.66,5.37,0.154
90.68,5.51,0.154
90.69,5.64,0.154
90.70,5.77,0.154
90.71,5.91,0.154
90.73,6.04,0.154
90.74,6.17,0.154
90.75,6.31,0.154
90.77,6.44,0.154
90.78,6.57,0.154
90.80,6.71,0.154
90.81,6.84,0.154
90.82,6.97,0.154
90.84,7.11,0.154
90.85,7.24,0.154
90.86,7.37,0.154
90.88,7.51,0.154
90.89,7.64,0.155
90.90,7.78,0.155
90.91,7.91,0.155
90.93,8.04,0.155
90.94,8.18,0.155
90.95,8.31,0.155
90.97,8.44,0.155
90.98,8.58,0.155
91.00,8.71,0.155
91.01,8.84,0.155
91.02,8.98,0.155
91.04,9.11,0.155
91.05,9.24,0.155
91.06,9.38,0.155
91.08,9.51,0.155
91.09,9.65,0.155
91.10,9.78,0.156
91.11,9.91,0.156
91.13,10.04,0.156
91.14,10.18,0.156
91.15,10.31,0.156
91.17,10.45,0.156
91.18,10.58,0.156
91.20,10.71,0.156
91.21,10.85,0.156
91.22,10.98,0.156
91.24,11.11,0.156
91.25,11.25,0.156
91.26,11.38,0.156
91.28,11.51,0.156
91.29,11.65,0.156
91.30,11.78,0.156
91.31,11.91,0.157
91.33,12.05,0.157
91.34,12.18,0.157
91.35,12.32,0.157
91.37,12.45,0.157
91.38,12.58,0.157
91.40,12.72,0.157
91.41,12.85,0.157
91.42,12.98,0.157
91.44,13.12,0.157
91.45,13.25,0.157
91.46,13.38,0.157
91.48,13.52,0.157
91.49,13.65,0.158
91.50,13.78,0.158
91.51,13.92,0.158
91.53,14.05,0.158
91.54,14.18,0.158
91.55,14.32,0.158
91.57,14.45,0.158
91.58,14.59,0.158
91.60,14.72,0.158
91.61,14.85,0.158
91.62,14.98,0.158
91.64,15.12,0.158
91.65,15.25,0.158
91.66,15.38,0.158
91.68,15.52,0.158
91.69,15.65,0.158
91.70,15.78,0.158
91.71,15.92,0.158
91.73,16.05,0.158
91.74,16.18,0.158
91.75,16.32,0.159
91.77,16.45,0.159
91.78,16.58,0.159
91.80,16.72,0.159
91.81,16.85,0.159
91.82,16.99,0.159
91.84,17.12,0.159
91.85,17.25,0.159
91.86,17.39,0.159
91.88,17.52,0.159
91.89,17.65,0.159
91.90,17.79,0.159
91.91,17.92,0.159
91.93,18.05,0.159
91.94,18.19,0.159
91.95,18.32,0.160
91.97,18.45,0.160
91.98,18.59,0.160
92.00,18.72,0.160
92.01,18.85,0.160
92.02,18.99,0.160
92.04,19.12,0.160
92.05,19.25,0.160
92.06,19.39,0.160
92.08,19.52,0.160
92.09,19.65,0.160
92.10,19.79,0.160
92.11,19.92,0.160
92.13,20.05,0.160
92.14,20.19,0.160
92.15,20.32,0.160
92.17,20.45,0.160
92.18,20.59,0.161
92.20,20.72,0.161
92.21,20.85,0.161
92.22,20.99,0.161
92.24,21.12,0.161
92.25,21.25,0.161
92.26,21.39,0.161
92.28,21.52,0.161
92.29,21.66,0.161
92.30,21.79,0.161
92.31,21.92,0.161
92.33,22.05,0.161
92.34,22.19,0.162
92.35,22.32,0.162
92.37,22.45,0.162
92.38,22.59,0.162
92.40,22.72,0.162
92.41,22.85,0.162
92.42,22.99,0.162
92.44,23.12,0.162
92.45,23.26,0.162
92.46,23.39,0.162
92.48,23.52,0.162
92.49,23.66,0.162
92.50,23.79,0.162
92.51,23.92,0.162
92.53,24.06,0.162
92.54,24.19,0.163
92.55,24.32,0.163
92.57,24.46,0.163
92.58,24.59,0.163
92.60,24.72,0.163
92.61,24.86,0.163
92.62,24.99,0.163
92.64,25.12,0.163
92.65,25.26,0.163
92.66,25.39,0.163
92.68,25.52,0.163
92.69,25.66,0.163
92.70,25.79,0.164
92.71,25.92,0.164
92.73,26.06,0.164
92.74,26.19,0.164
92.75,26.33,0.164
92.77,26.46,0.164
92.78,26.59,0.164
92.80,26.72,0.164
92.81,26.86,0.164
92.82,26.99,0.164
92.84,27.13,0.164
92.85,27.26,0.165
92.86,27.39,0.165
92.88,27.53,0.165
92.89,27.66,0.165
92.90,27.79,0.165
92.91,27.93,0.165
92.93,28.06,0.165
92.94,28.19,0.165
92.95,28.33,0.165
92.97,28.46,0.165
92.98,28.60,0.165
93.00,28.73,0.165
93.01,28.86,0.165
93.02,29.00,0.165
93.04,29.13,0.166
93.05,29.26,0.166
93.06,29.40,0.166
93.08,29.53,0.166
93.09,29.66,0.166
93.10,29.80,0.166
93.11,29.93,0.166
93.13,30.06,0.166
93.14,30.20,0.166
93.15,30.33,0.166
93.17,30.46,0.166
93.18,30.60,0.166
93.20,30.73,0.166
93.21,30.87,0.166
93.22,31.00,0.166
93.24,31.13,0.166
93.25,31.26,0.167
93.26,31.40,0.167
93.28,31.53,0.167
93.29,31.67,0.167
93.30,31.80,0.167
93.31,31.93,0.167
93.33,32.07,0.167
93.34,32.20,0.167
93.35,32.33,0.167
93.37,32.47,0.167
93.38,32.60,0.167
93.40,32.73,0.167
93.41,32.87,0.167
93.42,33.00,0.167
93.44,33.13,0.167
93.45,33.27,0.168
93.46,33.40,0.168
93.48,33.53,0.168
93.49,33.67,0.168
93.50,33.80,0.168
93.51,33.93,0.168
93.53,34.07,0.168
93.54,34.20,0.168
93.55,34.33,0.168
93.57,34.47,0.168
93.58,34.60,0.168
93.60,34.73,0.168
93.61,34.87,0.168
93.62,35.00,0.169
93.64,35.14,0.169
93.65,35.27,0.169
93.66,35.40,0.169
93.68,35.53,0.169
93.69,35.67,0.169
93.70,35.80,0.169
93.71,35.94,0.169
93.73,36.07,0.169
93.74,36.20,0.169
93.75,36.34,0.169
93.77,36.47,0.169
93.78,36.60,0.169
93.80,36.74,0.170
93.81,36.87,0.170
93.82,37.00,0.170
93.84,37.14,0.170
93.85,37.27,0.170
93.86,37.40,0.170
93.88,37.54,0.170
93.89,37.67,0.170
93.90,37.80,0.170
93.91,37.94,0.170
93.93,38.07,0.170
93.94,38.21,0.170
93.95,38.34,0.170
93.97,38.47,0.170
93.98,38.61,0.171
94.00,38.74,0.171
94.01,38.87,0.171
94.02,39.01,0.171
94.04,39.14,0.171
94.05,39.27,0.171
94.06,39.41,0.171
94.08,39.54,0.171
94.09,39.67,0.171
94.10,39.81,0.171
94.11,39.94,0.171
94.13,40.07,0.171
94.14,40.21,0.172
94.15,40.34,0.172
94.17,40.47,0.172
94.18,40.61,0.172
94.20,40.74,0.172
94.21,40.87,0.172
94.22,41.01,0.172
94.24,41.14,0.172
94.25,41.28,0.172
94.26,41.41,0.172
94.28,41.54,0.172
94.29,41.67,0.172
94.30,41.81,0.173
94.31,41.94,0.173
94.33,42.08,0.173
94.34,42.21,0.173
94.35,42.34,0.173
94.37,42.48,0.173
94.38,42.61,0.173
94.40,42.74,0.173
94.41,42.88,0.173
94.42,43.01,0.173
94.44,43.14,0.173
94.45,43.28,0.173
94.46,43.41,0.173
94.48,43.54,0.174
94.49,43.68,0.174
94.50,43.81,0.174
94.51,43.94,0.174
94.53,44.08,0.174
94.54,44.21,0.174
94.55,44.34,0.174
94.57,44.48,0.174
94.58,44.61,0.174
94.60,44.74,0.174
94.61,44.88,0.174
94.62,45.01,0.174
94.64,45.14,0.174
94.65,45.28,0.175
94.66,45.41,0.175
94.68,45.55,0.175
94.69,45.68,0.175
94.70,45.81,0.175
94.71,45.95,0.175
94.73,46.08,0.175
94.74,46.21,0.175
94.75,46.35,0.175
94.77,46.48,0.175
94.78,46.61,0.175
94.80,46.74,0.175
94.81,46.88,0.176
94.82,47.01,0.176
94.84,47.15,0.176
94.85,47.28,0.176
94.86,47.41,0.176
94.88,47.55,0.176
94.89,47.68,0.176
94.90,47.82,0.176
94.91,47.95,0.176
94.93,48.08,0.176
94.94,48.21,0.176
94.95,48.35,0.176
94.97,48.48,0.176
94.98,48.61,0.177
95.00,48.75,0.177
95.01,48.88,0.177
95.02,49.02,0.177
95.04,49.15,0.177
95.05,49.28,0.177
95.06,49.42,0.177
95.08,49.55,0.177
95.09,49.68,0.177
95.10,49.82,0.177
95.11,49.95,0.177
95.13,50.08,0.177
95.14,50.22,0.178
95.15,50.35,0.178
95.17,50.48,0.178
95.18,50.62,0.178
95.20,50.75,0.178
95.21,50.88,0.178
95.22,51.02,0.178
95.24,51.15,0.178
95.25,51.28,0.178
95.26,51.42,0.178
95.28,51.55,0.178
95.29,51.68,0.178
95.30,51.82,0.179
95.31,51.95,0.179
95.33,52.08,0.179
95.34,52.22,0.179
95.35,52.35,0.179
95.37,52.48,0.179
95.38,52.62,0.179
95.40,52.75,0.179
95.41,52.88,0.179
95.42,53.02,0.179
95.44,53.15,0.179
95.45,53.28,0.179
95.46,53.42,0.179
95.48,53.55,0.180
95.49,53.69,0.180
95.50,53.82,0.180
95.51,53.95,0.180
95.53,54.09,0.180
95.54,54.22,0.180
95.55,54.35,0.180
95.57,54.49,0.180
95.58,54.62,0.180
95.60,54.75,0.180
95.61,54.89,0.180
95.62,55.02,0.180
95.64,55.15,0.181
95.65,55.29,0.181
95.66,55.42,0.181
95.68,55.55,0.181
95.69,55.69,0.181
95.70,55.82,0.181
95.71,55.95,0.181
95.73,56.09,0.181
95.74,56.22,0.181
95.75,56.36,0.181
95.77,56.49,0.181
95.78,56.62,0.182
95.80,56.76,0.182
95.81,56.89,0.182
95.82,57.02,0.182
95.84,57.15,0.182
95.85,57.29,0.182
95.86,57.42,0.182
95.88,57.56,0.182
95.89,57.69,0.182
95.90,57.82,0.182
95.91,57.96,0.182
95.93,58.09,0.182
95.94,58.22,0.182
95.95,58.36,0.182
95.97,58.49,0.183
95.98,58.62,0.183
96.00,58.76,0.183
96.01,58.89,0.183
96.02,59.02,0.183
96.04,59.16,0.183
96.05,59.29,0.183
96.06,59.43,0.183
96.08,59.56,0.183
96.09,59.69,0.183
96.10,59.82,0.183
96.11,59.96,0.184
96.13,60.09,0.184
96.14,60.23,0.184
96.15,60.36,0.184
96.17,60.49,0.184
96.18,60.63,0.184
96.20,60.76,0.184
96.21,60.89,0.184
96.22,61.03,0.184
96.24,61.16,0.184
96.25,61.30,0.184
96.26,61.43,0.184
96.28,61.56,0.184
96.29,61.70,0.185
96.30,61.83,0.185
96.31,61.97,0.185
96.33,62.10,0.185
96.34,62.23,0.185
96.35,62.37,0.185
96.37,62.50,0.185
96.38,62.63,0.186
96.40,62.77,0.186
96.41,62.90,0.186
96.42,63.03,0.186
96.44,63.17,0.186
96.45,63.30,0.186
96.46,63.43,0.186
96.48,63.56,0.186
96.49,63.70,0.186
96.50,63.83,0.186
96.51,63.96,0.186
96.53,64.10,0.186
96.54,64.23,0.186
96.55,64.36,0.186
96.57,64.50,0.186
96.58,64.63,0.186
96.60,64.76,0.187
96.61,64.90,0.187
96.62,65.03,0.187
96.64,65.16,0.187
96.65,65.30,0.187
96.66,65.43,0.187
96.68,65.56,0.187
96.69,65.70,0.187
96.70,65.83,0.187
96.71,65.96,0.187
96.73,66.10,0.187
96.74,66.23,0.187
96.75,66.36,0.187
96.77,66.50,0.187
96.78,66.63,0.188
96.80,66.76,0.188
96.81,66.90,0.188
96.82,67.03,0.188
96.84,67.17,0.188
96.85,67.30,0.188
96.86,67.43,0.188
96.88,67.57,0.188
96.89,67.70,0.188
96.90,67.83,0.188
96.91,67.97,0.188
96.93,68.10,0.189
96.94,68.23,0.189
96.95,68.37,0.189
96.97,68.50,0.189
96.98,68.63,0.189
97.00,68.77,0.189
97.01,68.90,0.189
97.02,69.03,0.189
97.04,69.17,0.189
97.05,69.30,0.189
97.06,69.43,0.190
97.08,69.57,0.190
97.09,69.70,0.190
97.10,69.83,0.190
97.11,69.97,0.190
97.13,70.10,0.190
97.14,70.24,0.190
97.15,70.37,0.190
97.17,70.50,0.190
97.18,70.64,0.190
97.20,70.77,0.191
97.21,70.90,0.191
97.22,71.04,0.191
97.24,71.17,0.191
97.25,71.30,0.191
97.26,71.44,0.191
97.28,71.57,0.191
97.29,71.70,0.191
97.30,71.84,0.191
97.31,71.97,0.192
97.33,72.11,0.192
97.34,72.24,0.192
97.35,72.37,0.192
97.37,72.51,0.192
97.38,72.64,0.192
97.40,72.77,0.192
97.41,72.91,0.192
97.42,73.04,0.192
97.44,73.17,0.193
97.45,73.31,0.193
97.46,73.44,0.193
97.48,73.57,0.193
97.49,73.70,0.193
97.50,73.84,0.193
97.51,73.97,0.193
97.53,74.11,0.193
97.54,74.24,0.193
97.55,74.37,0.193
97.57,74.51,0.193
97.58,74.64,0.194
97.60,74.77,0.194
97.61,74.91,0.194
97.62,75.04,0.194
97.64,75.17,0.194
97.65,75.31,0.194
97.66,75.44,0.194
97.68,75.57,0.194
97.69,75.71,0.195
97.70,75.84,0.195
97.71,75.97,0.195
97.73,76.11,0.195
97.74,76.24,0.195
97.75,76.37,0.195
97.77,76.51,0.195
97.78,76.64,0.195
97.80,76.77,0.195
97.81,76.91,0.196
97.82,77.04,0.196
97.84,77.17,0.196
97.85,77.31,0.196
97.86,77.44,0.196
97.88,77.57,0.196
97.89,77.71,0.196
97.90,77.84,0.196
97.91,77.97,0.197
97.93,78.11,0.197
97.94,78.24,0.197
97.95,78.37,0.197
97.97,78.51,0.197
97.98,78.64,0.197
98.00,78.77,0.197
98.01,78.91,0.197
98.02,79.04,0.198
98.04,79.17,0.198
98.05,79.31,0.198
98.06,79.44,0.198
98.08,79.57,0.198
98.09,79.71,0.198
98.10,79.84,0.198
98.11,79.97,0.198
98.13,80.11,0.199
98.14,80.24,0.199
98.15,80.38,0.199
98.17,80.51,0.199
98.18,80.64,0.199
98.20,80.78,0.199
98.21,80.91,0.199
98.22,81.04,0.199
98.24,81.18,0.200
98.25,81.31,0.200
98.26,81.44,0.200
98.28,81.58,0.200
98.29,81.71,0.200
98.30,81.84,0.200
98.31,81.98,0.200
98.33,82.11,0.200
98.34,82.24,0.201
98.35,82.38,0.201
98.37,82.51,0.201
98.38,82.64,0.201
98.40,82.78,0.201
98.41,82.91,0.201
98.42,83.04,0.201
98.44,83.18,0.201
98.45,83.31,0.202
98.46,83.44,0.202
98.48,83.58,0.202
98.49,83.71,0.202
98.50,83.84,0.202
98.51,83.98,0.202
98.53,84.11,0.202
98.54,84.24,0.203
98.55,84.38,0.203
98.57,84.51,0.203
98.58,84.64,0.203
98.60,84.78,0.203
98.61,84.91,0.203
98.62,85.04,0.204
98.64,85.18,0.204
98.65,85.31,0.204
98.66,85.44,0.204
98.68,85.58,0.204
98.69,85.71,0.204
98.70,85.84,0.205
98.71,85.98,0.205
98.73,86.11,0.205
98.74,86.24,0.205
98.75,86.38,0.205
98.77,86.51,0.206
98.78,86.64,0.206
98.80,86.78,0.206
98.81,86.91,0.206
98.82,87.05,0.206
98.84,87.18,0.206
98.85,87.31,0.207
98.86,87.45,0.207
98.88,87.58,0.207
98.89,87.71,0.207
98.90,87.85,0.208
98.91,87.98,0.208
98.93,88.11,0.208
98.94,88.25,0.208
98.95,88.38,0.208
98.97,88.51,0.209
98.98,88.65,0.209
99.00,88.78,0.209
99.01,88.91,0.209
99.02,89.05,0.209
99.04,89.18,0.210
99.05,89.31,0.210
99.06,89.45,0.210
99.08,89.58,0.210
99.09,89.71,0.211
99.10,89.85,0.211
99.11,89.98,0.211
99.13,90.11,0.211
99.14,90.25,0.211
99.15,90.38,0.212
99.17,90.52,0.212
99.18,90.65,0.212
99.20,90.78,0.212
99.21,90.91,0.213
99.22,91.05,0.213
99.24,91.18,0.213
99.25,91.32,0.214
99.26,91.45,0.214
99.28,91.58,0.214
99.29,91.72,0.214
99.30,91.85,0.215
99.31,91.98,0.215
99.33,92.12,0.215
99.34,92.25,0.215
99.35,92.38,0.216
99.37,92.51,0.216
99.38,92.65,0.216
99.40,92.78,0.216
99.41,92.92,0.217
99.42,93.05,0.217
99.44,93.18,0.217
99.45,93.32,0.218
99.46,93.45,0.218
99.48,93.58,0.218
99.49,93.72,0.219
99.50,93.85,0.219
99.51,93.98,0.219
99.53,94.12,0.220
99.54,94.25,0.220
99.55,94.38,0.220
99.57,94.52,0.221
99.58,94.65,0.221
99.60,94.78,0.221
99.61,94.92,0.221
99.62,95.05,0.222
99.64,95.18,0.222
99.65,95.32,0.222
99.66,95.45,0.223
99.68,95.58,0.223
99.69,95.71,0.223
99.70,95.85,0.224
99.71,95.98,0.224
99.73,96.11,0.224
99.74,96.25,0.225
99.75,96.38,0.225
99.77,96.52,0.226
99.78,96.65,0.226
99.80,96.78,0.226
99.81,96.92,0.227
99.82,97.05,0.227
99.84,97.18,0.228
99.85,97.32,0.228
99.86,97.45,0.229
99.88,97.58,0.229
99.89,97.72,0.230
99.90,97.85,0.230
99.91,97.98,0.230
99.93,98.12,0.231
99.94,98.25,0.231
99.95,98.38,0.232
99.97,98.52,0.232
99.98,98.65,0.233
100.00,98.78,0.233
100.01,98.91,0.234
100.02,99.05,0.234
100.04,99.18,0.234
100.05,99.31,0.235
100.06,99.45,0.235
100.08,99.58,0.236
100.09,99.71,0.236
100.10,99.85,0.237
100.11,99.98,0.237
100.13,100.12,0.237
100.14,100.25,0.238
100.15,100.38,0.239
100.17,100.51,0.239
100.18,100.65,0.240
100.20,100.78,0.240
100.21,100.91,0.241
100.22,101.05,0.241
100.24,101.18,0.242
100.25,101.31,0.243
100.26,101.45,0.243
100.28,101.58,0.243
100.29,101.71,0.244
100.30,101.85,0.244
100.31,101.98,0.245
100.33,102.11,0.245
100.34,102.25,0.246
100.35,102.38,0.246
100.37,102.51,0.247
100.38,102.65,0.247
100.40,102.78,0.248
100.41,102.91,0.248
100.42,103.05,0.249
100.44,103.18,0.249
100.45,103.31,0.250
100.46,103.45,0.250
100.48,103.58,0.251
100.49,103.71,0.251
100.50,103.85,0.252
100.51,103.98,0.252
100.53,104.12,0.253
100.54,104.25,0.253
100.55,104.38,0.254
100.57,104.51,0.254
100.58,104.65,0.254
100.60,104.78,0.255
100.61,104.91,0.255
100.62,105.05,0.256
100.64,105.18,0.256
100.65,105.31,0.256
100.66,105.45,0.257
100.68,105.58,0.257
100.69,105.71,0.258
100.70,105.85,0.258
100.71,105.98,0.258
100.73,106.11,0.259
100.74,106.25,0.259
100.75,106.38,0.259
100.77,106.52,0.260
100.78,106.65,0.260
100.80,106.78,0.261
100.81,106.92,0.261
100.82,107.05,0.261
100.84,107.18,0.262
100.85,107.32,0.262
100.86,107.45,0.262
100.88,107.58,0.263
100.89,107.71,0.263
100.90,107.85,0.263
100.91,107.98,0.263
100.93,108.12,0.264
100.94,108.25,0.264
100.95,108.38,0.264
100.97,108.52,0.264
100.98,108.65,0.264
101.00,108.78,0.265
101.01,108.92,0.265
101.02,109.05,0.265
101.04,109.18,0.265
101.05,109.32,0.265
101.06,109.45,0.266
101.08,109.58,0.266
101.09,109.72,0.266
101.10,109.85,0.266
101.11,109.98,0.266
101.13,110.12,0.267
101.14,110.25,0.267
101.15,110.38,0.267
101.17,110.52,0.267
101.18,110.65,0.267
101.20,110.78,0.267
101.21,110.92,0.267
101.22,111.05,0.267
101.24,111.18,0.267
101.25,111.32,0.267
101.26,111.45,0.267
101.28,111.58,0.267
101.29,111.72,0.267
101.30,111.85,0.267
101.31,111.99,0.268
101.33,112.12,0.268
101.34,112.25,0.268
101.35,112.39,0.268
101.37,112.52,0.268
101.38,112.65,0.268
101.40,112.79,0.268
101.41,112.92,0.268
101.42,113.05,0.268
101.44,113.19,0.268
101.45,113.32,0.268
101.46,113.45,0.268
101.48,113.59,0.268
101.49,113.72,0.268
101.50,113.85,0.268
101.51,113.99,0.268
101.53,114.12,0.268
101.54,114.26,0.268
101.55,114.39,0.268
101.57,114.52,0.268
101.58,114.66,0.268
101.60,114.79,0.268
101.61,114.92,0.268
101.62,115.06,0.268
101.64,115.19,0.268
101.65,115.32,0.268
101.66,115.45,0.268
101.68,115.59,0.268
101.69,115.72,0.268
101.70,115.86,0.268
101.71,115.99,0.268
101.73,116.12,0.268
101.74,116.26,0.268
101.75,116.39,0.268
101.77,116.52,0.268
101.78,116.66,0.268
101.80,116.79,0.268
101.81,116.92,0.268
101.82,117.06,0.268
101.84,117.19,0.268
101.85,117.32,0.268
101.86,117.46,0.268
101.88,117.59,0.268
101.89,117.72,0.268
101.90,117.86,0.268
101.91,117.99,0.268
101.93,118.12,0.268
101.94,118.26,0.268
101.95,118.39,0.268
101.97,118.52,0.268
101.98,118.66,0.268
102.00,118.79,0.268
102.01,118.92,0.268
102.02,119.06,0.268
102.04,119.19,0.268
102.05,119.32,0.268
102.06,119.46,0.268
102.08,119.59,0.268
102.09,119.73,0.268
102.10,119.86,0.268
102.11,119.99,0.268
102.13,120.13,0.268
102.14,120.26,0.268
102.15,120.39,0.268
102.17,120.53,0.268
102.18,120.66,0.268
102.20,120.79,0.268
102.21,120.93,0.268
102.22,121.06,0.268
102.24,121.19,0.268
102.25,121.33,0.268
102.26,121.46,0.268
102.28,121.60,0.269
102.29,121.73,0.269
102.30,121.86,0.269
102.31,121.99,0.269
102.33,122.13,0.269
102.34,122.26,0.269
102.35,122.40,0.269
102.37,122.53,0.269
102.38,122.66,0.269
102.40,122.80,0.269
102.41,122.93,0.269
102.42,123.06,0.269
102.44,123.19,0.269
102.45,123.33,0.269
102.46,123.46,0.269
102.48,123.60,0.269
102.49,123.73,0.269
102.50,123.86,0.269
102.51,124.00,0.269
102.53,124.13,0.269
102.54,124.26,0.269
102.55,124.40,0.269
102.57,124.53,0.269
102.58,124.66,0.269
102.60,124.80,0.269
102.61,124.93,0.270
102.62,125.06,0.270
102.64,125.20,0.270
102.65,125.33,0.270
102.66,125.46,0.270
102.68,125.60,0.270
102.69,125.73,0.270
102.70,125.87,0.270
102.71,126.00,0.270
102.73,126.13,0.270
102.74,126.27,0.270
102.75,126.40,0.270
102.77,126.53,0.270
102.78,126.67,0.270
102.80,126.80,0.270
102.81,126.93,0.270
102.82,127.07,0.270
102.84,127.20,0.271
102.85,127.33,0.271
102.86,127.47,0.271
102.88,127.60,0.271
102.89,127.73,0.271
102.90,127.87,0.271
102.91,128.00,0.271
102.93,128.13,0.271
102.94,128.27,
102.95,128.40,
102.97,128.53,
102.98,128.67,
102.99,,