File: DSC/Olivia/2025_08_09_PVP40_n60C_230C_10Cmin_x3.csv
Filename,2025_08_09_PVP40_n60C_230C_10Cmin_x3
Instrument name,DSC2A-00468 (192.168.1.100)
Operator,Yarger
rundate,8/9/2025
Sample name,2025_08_09_PVP40_n60C_230C_10Cmin_x3
proceduresegments,Data Off ; Equilibrate -60.00 °C; Data On ; Ramp 10.00 °C/min to 230.00 °C; Data Off ; Isothermal 2.0 min; Data On ; Ramp 10.00 °C/min to -60.00 °C; Data Off ; Isothermal 2.0 min; Data On ; Ramp 10.00 °C/min to 230.00 °C; Data Off ; Isothermal 2.0 min; Data On ; Ramp 10.00 °C/min to -60.00 °C; Data Off ; Isothermal 2.0 min; Data On ; Ramp 10.00 °C/min to 230.00 °C
[File Parameters]
Run date,8/9/2025 10:08:06 AM
Trios version,5.1.1.46572
Original File Name,
Current File Name,D:\DSC2500\JYarger\2025_08_09_PVP40_n60C_230C_10Cmin_x3.tri
[Procedure]
Procedure Name,PVP40_TS_Pans_n60C_230C_10Cmin_x3
Sample Name,2025_08_09_PVP40_n60C_230C_10Cmin_x3
Sample Mass,4.56 mg
Reference Sample Mass,0 mg
Pan Mass,32.46 mg
Pan Number,41
Reference Pan Mass,32.52 mg
Reference Pan Number,37
Pan Type,Aluminum
Comments,Thermal support Al pans/lids. DSC_Samples_A2_Tray_July2025 google sheet.
Project Name,Pharma
Operator,Yarger
Test,Custom
Unload Max Temperature,30
Unload Min Temperature,30
Load Max Temperature,30
Load Min Temperature,30
Stop on Gas Flow Error,Yes
[Signal List]
Signal #1,Time (min)
Signal #2,Temperature (°C)
Signal #3,Heat Flow (mW)
Signal #4,Delta T (µV)
Signal #5,Delta Tzero (µV)
Signal #6,Tzero Temperature (°C)
Signal #7,Cell Purge (mL/min)
Signal #8,Heater Temp (°C)
Signal #9,Power Delivered (W)
Signal #10,Reference Junction Temperature (°C)
Signal #11,Flange Temperature (°C)
Signal #12,Heat Flow Phase (rad)
Signal #13,Total Heat Capacity (J/°C)
Signal #14,Heat Capacity (J/°C)
[Configuration]
Company Name,ASU
Instrument Name,DSC2A-00468
Instrument Type,DSC2500
Serial Number,DSC2A-00468
IP,192.168.1.100
Location of Instrument,MRRC
DisplayType,Unknown
Sample Interval ,0.1 s/pt
Selected Heat Flow,T4P
Exotherm Direction,Down
Cell Serial,DRC2-00792
Lid Type,Standard
Cooler,RCS 90
Leave Cooler on at End of Sequence,On
Gas 2,Nitrogen
Gas Selected,Channel 1
Flow Rate,50 mL/min
Secondary Purge,On
Licensed Heat Flow,Heat Flow T4P
Modulation Licensed,Yes
[Versions]
Common IDD Version,1
Cortex Version,VER 2.10.2.31
Driver,5.0.0.6
GDM Version,1.0.3.3
TouchscreenVersion,1.0.0.16145
FEP Version,1.2.1.21
FEP Bootloader,2.0.0.5
AutoSampler Version,2.1.1.26
Auto Sampler Bootloader,2.0.0.5
FCM Version,1.1.0.3
FCM Bootloader,2.0.0.5
[Experiment Logs]
Experiment Log Entry # 1,Data On set to 0
Experiment Log Entry # 3,Equilibrate Segment -60 (C) Started
Experiment Log Entry # 5,Data On set to 1
Experiment Log Entry # 7,Ramp Segment 10 C/min to 230 Started
Experiment Log Entry # 9,Data On set to 0
Experiment Log Entry # 11,Isothermal Segment 2 min started
Experiment Log Entry # 13,Data On set to 1
Experiment Log Entry # 15,Ramp Segment 10 C/min to -60 Started
Experiment Log Entry # 17,Data On set to 0
Experiment Log Entry # 19,Isothermal Segment 2 min started
Experiment Log Entry # 21,Data On set to 1
Experiment Log Entry # 23,Ramp Segment 10 C/min to 230 Started
Experiment Log Entry # 25,Data On set to 0
Experiment Log Entry # 27,Isothermal Segment 2 min started
Experiment Log Entry # 29,Data On set to 1
Experiment Log Entry # 31,Ramp Segment 10 C/min to -60 Started
Experiment Log Entry # 33,Data On set to 0
Experiment Log Entry # 35,Isothermal Segment 2 min started
Experiment Log Entry # 37,Data On set to 1
Experiment Log Entry # 39,Ramp Segment 10 C/min to 230 Started
Experiment Log Entry # 41,Auto sampler has detected that FEP has gone offline
[Method Log]
Method Log Entry # 1,Data Off
Method Log Entry # 2,Equilibrate -60 °C
Method Log Entry # 3,Data On
Method Log Entry # 4,(Ramp 630796) Ramp 10 °C/minute to 230 °C
Method Log Entry # 5,Data Off
Method Log Entry # 6,Isothermal 2 minutes
Method Log Entry # 7,Data On
Method Log Entry # 8,(Ramp 630800) Ramp 10 °C/minute to -60 °C
Method Log Entry # 9,Data Off
Method Log Entry # 10,Isothermal 2 minutes
Method Log Entry # 11,Data On
Method Log Entry # 12,(Ramp 630804) Ramp 10 °C/minute to 230 °C
Method Log Entry # 13,Data Off
Method Log Entry # 14,Isothermal 2 minutes
Method Log Entry # 15,Data On
Method Log Entry # 16,(Ramp 630808) Ramp 10 °C/minute to -60 °C
Method Log Entry # 17,Data Off
Method Log Entry # 18,Isothermal 2 minutes
Method Log Entry # 19,Data On
Method Log Entry # 20,(Ramp 630812) Ramp 10 °C/minute to 230 °C
Cell Serial,DRC2-00792
[T1 Calibration]
Slope,-0.008529666
Offset,9.636258
Initial Temperature,98.23
GUID,f8bfdadc-4977-4fdf-ba6d-0ba9134940c3
[TZero Calibration]
Date Applied,11/29/2022 4:06:13 PM
Description,From -89.059 °C to 396.009 °C at 20.000°C/min
Gas Type,Nitrogen
Pan Type,None
Source Files 1,C:\Users\yargerlab\Desktop\DSC Data\General\TZero_calibration_11_29_22_2nd(2).tri
Source Files 2,C:\Users\yargerlab\Desktop\DSC Data\General\TZero_calibration_11_29_22_2nd(3).tri
Delta T Offset,13.05235
Delta T Slope,-0.007271007
Delta T0 Offset,-13.69128
Delta T0 Slope,0.06063341
[Temperature Calibration]
Date Applied,11/29/2022 7:12:28 PM
Description,From 106.590 °C to 186.590 °C at 10.000°C/min
Gas Type,Nitrogen
Pan Type,Tzero Aluminum Hermetic
Source Files 1,C:\Users\yargerlab\Desktop\DSC Data\General\Indium(6).tri
Measured 1,157.391
Known 1,156.598
[Cell Constant Calibration]
Date Applied,11/29/2022 7:12:29 PM
Description,From 106.590 °C to 186.590 °C at 10.000°C/min
Gas Type,Nitrogen
Pan Type,Tzero Aluminum Hermetic
Source Files 1,C:\Users\yargerlab\Desktop\DSC Data\General\Indium(6).tri
T4P KCell,1.006051
Onset Slope,63.26126 mW/°C
[Direct Cp Calibration]
Date Applied,11/30/2022 11:04:51 AM
Description,From -79.983 °C to 298.409 °C at 10.000°C/min
Gas Type,Nitrogen
Pan Type,Tzero Aluminum Hermetic
Source Files 1,C:\Users\yargerlab\Desktop\DSC Data\General\Sapphire_Heat_Capacity_11_30_22.tri
[Rev Cp Calibration]
Date Applied,11/30/2022 1:58:51 PM
Description,From -79.996 °C to 292.812 °C at 3.000°C/min
Gas Type,Nitrogen
Pan Type,Tzero Aluminum Hermetic
Source Files 1,C:\Users\yargerlab\Desktop\DSC Data\General\Sapphire_MDSC_Calibration_11_30_22.tri
[step]
Ramp 10.00 °C/min to 230.00 °C
Time,Temperature,Heat Flow (Normalized)
min,°C,W/g
0.00,-59.80,-0.061
0.02,-59.81,-0.058
0.04,-59.81,-0.053
0.06,-59.79,-0.053
0.08,-59.75,-0.053
0.10,-59.68,-0.049
0.12,-59.59,-0.025
0.14,-59.47,0.002
0.16,-59.33,0.038
0.18,-59.17,0.073
0.20,-59.00,0.106
0.22,-58.83,0.135
0.24,-58.65,0.157
0.26,-58.46,0.178
0.28,-58.27,0.193
0.30,-58.08,0.205
0.32,-57.89,0.214
0.34,-57.70,0.220
0.36,-57.51,0.226
0.38,-57.31,0.230
0.40,-57.12,0.233
0.42,-56.93,0.236
0.44,-56.73,0.238
0.46,-56.54,0.240
0.48,-56.34,0.241
0.50,-56.15,0.243
0.52,-55.95,0.243
0.54,-55.75,0.244
0.56,-55.56,0.245
0.58,-55.36,0.246
0.60,-55.17,0.246
0.62,-54.97,0.247
0.64,-54.78,0.247
0.66,-54.58,0.247
0.68,-54.38,0.248
0.70,-54.19,0.248
0.72,-53.99,0.249
0.74,-53.79,0.249
0.76,-53.59,0.250
0.78,-53.39,0.251
0.80,-53.20,0.252
0.82,-53.00,0.252
0.84,-52.80,0.253
0.86,-52.60,0.254
0.88,-52.40,0.254
0.90,-52.20,0.255
0.92,-52.00,0.255
0.94,-51.80,0.256
0.96,-51.61,0.256
0.98,-51.41,0.257
1.00,-51.21,0.257
1.02,-51.01,0.258
1.04,-50.81,0.258
1.06,-50.61,0.258
1.08,-50.41,0.259
1.10,-50.21,0.259
1.12,-50.01,0.260
1.14,-49.81,0.260
1.16,-49.61,0.260
1.18,-49.41,0.261
1.20,-49.21,0.261
1.22,-49.01,0.261
1.24,-48.81,0.262
1.26,-48.61,0.262
1.28,-48.41,0.262
1.30,-48.21,0.263
1.32,-48.01,0.263
1.34,-47.81,0.263
1.36,-47.62,0.263
1.38,-47.41,0.264
1.40,-47.21,0.264
1.42,-47.01,0.264
1.44,-46.82,0.264
1.46,-46.61,0.265
1.48,-46.42,0.265
1.50,-46.22,0.265
1.52,-46.01,0.265
1.54,-45.82,0.266
1.56,-45.62,0.266
1.58,-45.41,0.266
1.60,-45.21,0.266
1.62,-45.01,0.266
1.64,-44.81,0.267
1.66,-44.61,0.267
1.68,-44.41,0.267
1.70,-44.21,0.267
1.72,-44.01,0.267
1.74,-43.81,0.268
1.76,-43.61,0.268
1.78,-43.41,0.268
1.80,-43.21,0.268
1.82,-43.01,0.268
1.84,-42.81,0.268
1.86,-42.61,0.269
1.88,-42.41,0.269
1.90,-42.21,0.269
1.92,-42.01,0.269
1.94,-41.81,0.269
1.96,-41.61,0.269
1.98,-41.41,0.269
2.00,-41.21,0.270
2.02,-41.01,0.270
2.04,-40.81,0.270
2.06,-40.61,0.270
2.08,-40.41,0.270
2.10,-40.21,0.270
2.12,-40.01,0.270
2.14,-39.81,0.271
2.16,-39.61,0.271
2.18,-39.41,0.271
2.20,-39.21,0.271
2.22,-39.01,0.271
2.24,-38.81,0.271
2.26,-38.61,0.271
2.28,-38.41,0.271
2.30,-38.21,0.271
2.32,-38.01,0.272
2.34,-37.81,0.272
2.36,-37.61,0.272
2.38,-37.41,0.272
2.40,-37.21,0.272
2.42,-37.01,0.272
2.44,-36.81,0.272
2.46,-36.61,0.272
2.48,-36.41,0.273
2.50,-36.21,0.273
2.52,-36.01,0.273
2.54,-35.81,0.273
2.56,-35.61,0.273
2.58,-35.41,0.273
2.60,-35.20,0.273
2.62,-35.01,0.273
2.64,-34.80,0.273
2.66,-34.60,0.274
2.68,-34.40,0.274
2.70,-34.20,0.274
2.72,-34.00,0.274
2.74,-33.80,0.274
2.76,-33.60,0.274
2.78,-33.40,0.274
2.80,-33.20,0.274
2.82,-33.00,0.275
2.84,-32.80,0.275
2.86,-32.60,0.275
2.88,-32.40,0.275
2.90,-32.20,0.275
2.92,-32.00,0.275
2.94,-31.80,0.275
2.96,-31.60,0.276
2.98,-31.40,0.276
3.00,-31.20,0.276
3.02,-31.00,0.276
3.04,-30.80,0.276
3.06,-30.60,0.276
3.08,-30.40,0.276
3.10,-30.20,0.277
3.12,-30.00,0.277
3.14,-29.80,0.277
3.16,-29.60,0.277
3.18,-29.40,0.277
3.20,-29.20,0.277
3.22,-29.00,0.277
3.24,-28.80,0.277
3.26,-28.60,0.278
3.28,-28.40,0.278
3.30,-28.20,0.278
3.32,-28.00,0.278
3.34,-27.80,0.278
3.36,-27.60,0.278
3.38,-27.40,0.279
3.40,-27.20,0.279
3.42,-26.99,0.279
3.44,-26.80,0.279
3.46,-26.59,0.279
3.48,-26.39,0.279
3.50,-26.19,0.280
3.52,-25.99,0.280
3.54,-25.79,0.280
3.56,-25.59,0.280
3.58,-25.39,0.281
3.60,-25.19,0.281
3.62,-24.98,0.281
3.64,-24.78,0.281
3.66,-24.58,0.281
3.68,-24.38,0.281
3.70,-24.19,0.282
3.72,-23.98,0.282
3.74,-23.79,0.282
3.76,-23.59,0.282
3.78,-23.39,0.282
3.80,-23.19,0.282
3.82,-22.99,0.282
3.84,-22.79,0.282
3.86,-22.59,0.282
3.88,-22.39,0.282
3.90,-22.19,0.283
3.92,-21.99,0.283
3.94,-21.79,0.283
3.96,-21.59,0.283
3.98,-21.39,0.283
4.00,-21.19,0.283
4.02,-20.99,0.283
4.04,-20.79,0.284
4.06,-20.59,0.284
4.08,-20.38,0.284
4.10,-20.19,0.284
4.12,-19.98,0.284
4.14,-19.79,0.285
4.16,-19.58,0.285
4.18,-19.38,0.285
4.20,-19.19,0.285
4.22,-18.98,0.285
4.24,-18.79,0.285
4.26,-18.58,0.286
4.28,-18.38,0.286
4.30,-18.18,0.286
4.32,-17.98,0.286
4.34,-17.78,0.286
4.36,-17.58,0.287
4.38,-17.38,0.287
4.40,-17.18,0.287
4.42,-16.98,0.287
4.44,-16.78,0.287
4.46,-16.58,0.287
4.48,-16.38,0.288
4.50,-16.18,0.288
4.52,-15.98,0.288
4.54,-15.78,0.288
4.56,-15.58,0.288
4.58,-15.38,0.289
4.60,-15.18,0.289
4.62,-14.98,0.289
4.64,-14.78,0.289
4.66,-14.58,0.289
4.68,-14.38,0.289
4.70,-14.18,0.290
4.72,-13.98,0.290
4.74,-13.78,0.290
4.76,-13.58,0.290
4.78,-13.38,0.290
4.80,-13.18,0.291
4.82,-12.98,0.291
4.84,-12.78,0.291
4.86,-12.58,0.291
4.88,-12.38,0.291
4.90,-12.18,0.292
4.92,-11.98,0.292
4.94,-11.78,0.292
4.96,-11.58,0.292
4.98,-11.38,0.293
5.00,-11.18,0.293
5.02,-10.98,0.293
5.04,-10.78,0.293
5.06,-10.58,0.293
5.08,-10.38,0.294
5.10,-10.18,0.294
5.12,-9.98,0.294
5.14,-9.78,0.294
5.16,-9.58,0.295
5.18,-9.38,0.295
5.20,-9.18,0.295
5.22,-8.98,0.295
5.24,-8.78,0.296
5.26,-8.58,0.296
5.28,-8.38,0.296
5.30,-8.18,0.296
5.32,-7.98,0.296
5.34,-7.78,0.297
5.36,-7.58,0.297
5.38,-7.38,0.297
5.40,-7.18,0.297
5.42,-6.98,0.298
5.44,-6.78,0.298
5.46,-6.58,0.298
5.48,-6.38,0.298
5.50,-6.18,0.299
5.52,-5.98,0.299
5.54,-5.78,0.299
5.56,-5.57,0.299
5.58,-5.37,0.300
5.60,-5.17,0.300
5.62,-4.97,0.300
5.64,-4.77,0.300
5.66,-4.57,0.301
5.68,-4.37,0.301
5.70,-4.17,0.301
5.72,-3.97,0.301
5.74,-3.77,0.302
5.76,-3.57,0.302
5.78,-3.37,0.302
5.80,-3.17,0.302
5.82,-2.97,0.303
5.84,-2.77,0.303
5.86,-2.57,0.303
5.88,-2.37,0.304
5.90,-2.17,0.304
5.92,-1.97,0.304
5.94,-1.77,0.304
5.96,-1.57,0.305
5.98,-1.37,0.305
6.00,-1.17,0.305
6.02,-0.97,0.305
6.04,-0.77,0.306
6.06,-0.57,0.306
6.08,-0.37,0.306
6.10,-0.17,0.306
6.12,0.03,0.307
6.14,0.23,0.307
6.16,0.43,0.307
6.18,0.63,0.308
6.20,0.83,0.308
6.22,1.03,0.308
6.24,1.23,0.308
6.26,1.43,0.309
6.28,1.63,0.309
6.30,1.83,0.309
6.32,2.03,0.310
6.34,2.23,0.310
6.36,2.43,0.310
6.38,2.63,0.311
6.40,2.83,0.311
6.42,3.03,0.311
6.44,3.23,0.311
6.46,3.43,0.312
6.48,3.63,0.312
6.50,3.83,0.312
6.52,4.04,0.313
6.54,4.24,0.313
6.56,4.44,0.313
6.58,4.64,0.314
6.60,4.84,0.314
6.62,5.04,0.314
6.64,5.23,0.315
6.66,5.44,0.315
6.68,5.64,0.315
6.70,5.84,0.316
6.72,6.04,0.316
6.74,6.24,0.316
6.76,6.44,0.317
6.78,6.64,0.317
6.80,6.84,0.317
6.82,7.04,0.318
6.84,7.24,0.318
6.86,7.44,0.318
6.88,7.64,0.319
6.90,7.84,0.319
6.92,8.04,0.319
6.94,8.24,0.320
6.96,8.44,0.320
6.98,8.64,0.321
7.00,8.84,0.321
7.02,9.04,0.321
7.04,9.24,0.322
7.06,9.44,0.322
7.08,9.64,0.322
7.10,9.84,0.323
7.12,10.04,0.323
7.14,10.24,0.324
7.16,10.44,0.324
7.18,10.64,0.324
7.20,10.84,0.325
7.22,11.04,0.325
7.24,11.24,0.326
7.26,11.44,0.326
7.28,11.64,0.326
7.30,11.84,0.327
7.32,12.04,0.327
7.34,12.24,0.328
7.36,12.44,0.328
7.38,12.64,0.329
7.40,12.84,0.329
7.42,13.04,0.329
7.44,13.24,0.330
7.46,13.44,0.330
7.48,13.64,0.331
7.50,13.84,0.331
7.52,14.04,0.332
7.54,14.24,0.332
7.56,14.44,0.333
7.58,14.64,0.333
7.60,14.84,0.334
7.62,15.04,0.334
7.64,15.24,0.334
7.66,15.44,0.335
7.68,15.64,0.335
7.70,15.84,0.336
7.72,16.04,0.336
7.74,16.24,0.337
7.76,16.44,0.337
7.78,16.64,0.338
7.80,16.84,0.338
7.82,17.04,0.339
7.84,17.24,0.339
7.86,17.44,0.340
7.88,17.64,0.340
7.90,17.84,0.341
7.92,18.04,0.341
7.94,18.24,0.342
7.96,18.44,0.342
7.98,18.64,0.343
8.00,18.84,0.343
8.02,19.04,0.344
8.04,19.24,0.344
8.06,19.44,0.345
8.08,19.64,0.345
8.10,19.84,0.346
8.12,20.04,0.346
8.14,20.24,0.347
8.16,20.44,0.348
8.18,20.64,0.348
8.20,20.84,0.349
8.22,21.04,0.349
8.24,21.24,0.350
8.26,21.44,0.351
8.28,21.64,0.351
8.30,21.84,0.352
8.32,22.04,0.352
8.34,22.24,0.353
8.36,22.44,0.354
8.38,22.64,0.354
8.40,22.84,0.355
8.42,23.04,0.355
8.44,23.24,0.356
8.46,23.44,0.357
8.48,23.64,0.357
8.50,23.84,0.358
8.52,24.04,0.359
8.54,24.24,0.359
8.56,24.44,0.360
8.58,24.64,0.361
8.60,24.84,0.362
8.62,25.04,0.362
8.64,25.24,0.363
8.66,25.44,0.364
8.68,25.64,0.364
8.70,25.84,0.365
8.72,26.04,0.366
8.74,26.24,0.367
8.76,26.44,0.368
8.78,26.64,0.368
8.80,26.84,0.369
8.82,27.04,0.370
8.84,27.24,0.371
8.86,27.44,0.371
8.88,27.64,0.373
8.90,27.84,0.373
8.92,28.04,0.374
8.94,28.24,0.375
8.96,28.44,0.376
8.98,28.64,0.377
9.00,28.84,0.377
9.02,29.04,0.378
9.04,29.24,0.379
9.06,29.44,0.380
9.08,29.64,0.381
9.10,29.84,0.382
9.12,30.04,0.382
9.14,30.24,0.383
9.16,30.44,0.384
9.18,30.64,0.385
9.20,30.84,0.386
9.22,31.04,0.387
9.24,31.24,0.388
9.26,31.44,0.389
9.28,31.64,0.390
9.30,31.84,0.391
9.32,32.04,0.392
9.34,32.24,0.392
9.36,32.44,0.393
9.38,32.64,0.395
9.40,32.84,0.396
9.42,33.04,0.397
9.44,33.24,0.398
9.46,33.44,0.399
9.48,33.64,0.400
9.50,33.84,0.401
9.52,34.04,0.402
9.54,34.24,0.403
9.56,34.44,0.404
9.58,34.64,0.406
9.60,34.84,0.407
9.62,35.04,0.408
9.64,35.24,0.409
9.66,35.44,0.410
9.68,35.64,0.411
9.70,35.84,0.412
9.72,36.04,0.414
9.74,36.24,0.415
9.76,36.44,0.417
9.78,36.64,0.418
9.80,36.84,0.419
9.82,37.04,0.420
9.84,37.24,0.422
9.86,37.44,0.423
9.88,37.64,0.424
9.90,37.84,0.425
9.92,38.04,0.427
9.94,38.24,0.428
9.96,38.44,0.430
9.98,38.64,0.432
10.00,38.84,0.433
10.02,39.04,0.434
10.04,39.24,0.436
10.06,39.44,0.438
10.08,39.64,0.440
10.10,39.84,0.441
10.12,40.04,0.443
10.14,40.24,0.444
10.16,40.44,0.446
10.18,40.64,0.448
10.20,40.84,0.450
10.22,41.04,0.452
10.24,41.24,0.453
10.26,41.44,0.455
10.28,41.64,0.457
10.30,41.84,0.459
10.32,42.04,0.461
10.34,42.23,0.463
10.36,42.43,0.465
10.38,42.63,0.467
10.40,42.83,0.468
10.42,43.03,0.471
10.44,43.23,0.472
10.46,43.43,0.475
10.48,43.63,0.478
10.50,43.83,0.479
10.52,44.03,0.483
10.54,44.23,0.485
10.56,44.43,0.487
10.58,44.63,0.489
10.60,44.83,0.492
10.62,45.03,0.494
10.64,45.23,0.496
10.66,45.43,0.498
10.68,45.63,0.500
10.70,45.83,0.503
10.72,46.03,0.506
10.74,46.23,0.508
10.76,46.43,0.511
10.78,46.63,0.514
10.80,46.82,0.517
10.82,47.02,0.519
10.84,47.22,0.522
10.86,47.42,0.524
10.88,47.62,0.528
10.90,47.82,0.531
10.92,48.02,0.534
10.94,48.22,0.537
10.96,48.42,0.540
10.98,48.62,0.543
11.00,48.82,0.545
11.02,49.02,0.548
11.04,49.22,0.551
11.06,49.42,0.555
11.08,49.61,0.558
11.10,49.81,0.560
11.12,50.01,0.564
11.14,50.21,0.566
11.16,50.41,0.569
11.18,50.61,0.572
11.20,50.81,0.574
11.22,51.01,0.577
11.24,51.21,0.580
11.26,51.41,0.582
11.28,51.61,0.585
11.30,51.81,0.587
11.32,52.01,0.589
11.34,52.21,0.591
11.36,52.41,0.593
11.38,52.61,0.595
11.40,52.81,0.596
11.42,53.01,0.597
11.44,53.21,0.598
11.46,53.41,0.599
11.48,53.61,0.600
11.50,53.81,0.601
11.52,54.01,0.602
11.54,54.21,0.603
11.56,54.41,0.603
11.58,54.61,0.604
11.60,54.80,0.605
11.62,55.01,0.605
11.64,55.21,0.606
11.66,55.40,0.607
11.68,55.60,0.607
11.70,55.80,0.608
11.72,56.01,0.609
11.74,56.21,0.610
11.76,56.41,0.611
11.78,56.61,0.612
11.80,56.81,0.614
11.82,57.01,0.616
11.84,57.21,0.617
11.86,57.41,0.618
11.88,57.61,0.621
11.90,57.80,0.623
11.92,58.00,0.626
11.94,58.20,0.628
11.96,58.40,0.631
11.98,58.60,0.634
12.00,58.80,0.637
12.02,59.00,0.641
12.04,59.20,0.644
12.06,59.40,0.647
12.08,59.60,0.650
12.10,59.80,0.653
12.12,60.00,0.656
12.14,60.20,0.659
12.16,60.40,0.664
12.18,60.60,0.667
12.20,60.80,0.672
12.22,61.00,0.675
12.24,61.19,0.679
12.26,61.39,0.682
12.28,61.59,0.687
12.30,61.79,0.690
12.32,61.99,0.694
12.34,62.19,0.697
12.36,62.39,0.702
12.38,62.59,0.706
12.40,62.79,0.711
12.42,62.99,0.714
12.44,63.18,0.718
12.46,63.38,0.722
12.48,63.58,0.726
12.50,63.78,0.730
12.52,63.98,0.735
12.54,64.18,0.738
12.56,64.38,0.741
12.58,64.58,0.747
12.60,64.78,0.750
12.62,64.98,0.753
12.64,65.18,0.759
12.66,65.38,0.762
12.68,65.57,0.765
12.70,65.77,0.770
12.72,65.97,0.773
12.74,66.17,0.777
12.76,66.37,0.781
12.78,66.57,0.785
12.80,66.77,0.789
12.82,66.97,0.793
12.84,67.17,0.796
12.86,67.36,0.800
12.88,67.57,0.804
12.90,67.76,0.807
12.92,67.96,0.811
12.94,68.16,0.816
12.96,68.36,0.819
12.98,68.56,0.823
13.00,68.76,0.827
13.02,68.96,0.831
13.04,69.16,0.834
13.06,69.36,0.838
13.08,69.56,0.842
13.10,69.76,0.847
13.12,69.95,0.851
13.14,70.15,0.854
13.16,70.35,0.859
13.18,70.55,0.862
13.20,70.75,0.866
13.22,70.95,0.870
13.24,71.15,0.873
13.26,71.35,0.878
13.28,71.55,0.882
13.30,71.74,0.886
13.32,71.94,0.891
13.34,72.14,0.895
13.36,72.34,0.899
13.38,72.54,0.904
13.40,72.74,0.907
13.42,72.94,0.912
13.44,73.14,0.917
13.46,73.34,0.921
13.48,73.54,0.925
13.50,73.74,0.930
13.52,73.94,0.933
13.54,74.14,0.938
13.56,74.33,0.943
13.58,74.53,0.947
13.60,74.73,0.951
13.62,74.93,0.957
13.64,75.13,0.960
13.66,75.33,0.965
13.68,75.53,0.969
13.70,75.73,0.975
13.72,75.92,0.980
13.74,76.12,0.984
13.76,76.32,0.988
13.78,76.52,0.994
13.80,76.72,0.999
13.82,76.92,1.004
13.84,77.12,1.008
13.86,77.32,1.013
13.88,77.51,1.018
13.90,77.71,1.024
13.92,77.91,1.029
13.94,78.11,1.035
13.96,78.31,1.039
13.98,78.51,1.044
14.00,78.71,1.049
14.02,78.91,1.054
14.04,79.11,1.058
14.06,79.30,1.065
14.08,79.50,1.069
14.10,79.70,1.074
14.12,79.90,1.080
14.14,80.10,1.085
14.16,80.30,1.091
14.18,80.50,1.096
14.20,80.70,1.102
14.22,80.89,1.107
14.24,81.09,1.112
14.26,81.29,1.118
14.28,81.49,1.124
14.30,81.69,1.129
14.32,81.89,1.135
14.34,82.09,1.141
14.36,82.29,1.146
14.38,82.48,1.152
14.40,82.68,1.158
14.42,82.88,1.164
14.44,83.08,1.169
14.46,83.28,1.174
14.48,83.48,1.182
14.50,83.68,1.187
14.52,83.87,1.193
14.54,84.07,1.198
14.56,84.27,1.204
14.58,84.47,1.209
14.60,84.67,1.215
14.62,84.87,1.222
14.64,85.07,1.226
14.66,85.26,1.233
14.68,85.46,1.240
14.70,85.66,1.245
14.72,85.86,1.252
14.74,86.06,1.257
14.76,86.26,1.263
14.78,86.45,1.270
14.80,86.65,1.275
14.82,86.85,1.281
14.84,87.05,1.287
14.86,87.25,1.293
14.88,87.45,1.299
14.90,87.64,1.305
14.92,87.84,1.311
14.94,88.04,1.318
14.96,88.24,1.325
14.98,88.44,1.332
15.00,88.64,1.338
15.02,88.83,1.344
15.04,89.03,1.350
15.06,89.23,1.357
15.08,89.43,1.364
15.10,89.63,1.370
15.12,89.83,1.377
15.14,90.03,1.384
15.16,90.22,1.390
15.18,90.42,1.396
15.20,90.62,1.403
15.22,90.82,1.408
15.24,91.02,1.415
15.26,91.22,1.421
15.28,91.42,1.428
15.30,91.61,1.433
15.32,91.81,1.438
15.34,92.01,1.446
15.36,92.21,1.451
15.38,92.41,1.456
15.40,92.61,1.462
15.42,92.80,1.469
15.44,93.00,1.476
15.46,93.20,1.481
15.48,93.40,1.487
15.50,93.60,1.493
15.52,93.80,1.499
15.54,94.00,1.506
15.56,94.20,1.510
15.58,94.40,1.516
15.60,94.59,1.521
15.62,94.79,1.527
15.64,94.99,1.532
15.66,95.19,1.538
15.68,95.39,1.543
15.70,95.59,1.548
15.72,95.79,1.554
15.74,95.98,1.559
15.76,96.18,1.565
15.78,96.38,1.569
15.80,96.58,1.575
15.82,96.78,1.579
15.84,96.98,1.584
15.86,97.18,1.588
15.88,97.38,1.593
15.90,97.58,1.599
15.92,97.77,1.603
15.94,97.97,1.607
15.96,98.17,1.612
15.98,98.37,1.616
16.00,98.57,1.620
16.02,98.77,1.623
16.04,98.97,1.626
16.06,99.17,1.629
16.08,99.37,1.634
16.10,99.57,1.637
16.12,99.77,1.640
16.14,99.96,1.644
16.16,100.16,1.647
16.18,100.36,1.650
16.20,100.56,1.654
16.22,100.76,1.656
16.24,100.96,1.659
16.26,101.16,1.661
16.28,101.36,1.664
16.30,101.56,1.666
16.32,101.76,1.669
16.34,101.96,1.670
16.36,102.16,1.671
16.38,102.36,1.673
16.40,102.56,1.673
16.42,102.76,1.675
16.44,102.96,1.676
16.46,103.16,1.677
16.48,103.36,1.678
16.50,103.56,1.679
16.52,103.76,1.680
16.54,103.96,1.680
16.56,104.16,1.681
16.58,104.36,1.681
16.60,104.56,1.682
16.62,104.76,1.682
16.64,104.96,1.682
16.66,105.16,1.682
16.68,105.36,1.682
16.70,105.56,1.682
16.72,105.76,1.682
16.74,105.96,1.682
16.76,106.16,1.681
16.78,106.37,1.680
16.80,106.57,1.679
16.82,106.77,1.677
16.84,106.97,1.675
16.86,107.17,1.672
16.88,107.37,1.669
16.90,107.57,1.665
16.92,107.77,1.661
16.94,107.97,1.657
16.96,108.17,1.652
16.98,108.37,1.648
17.00,108.58,1.644
17.02,108.78,1.639
17.04,108.98,1.635
17.06,109.18,1.631
17.08,109.38,1.626
17.10,109.58,1.621
17.12,109.79,1.615
17.14,109.99,1.611
17.16,110.19,1.604
17.18,110.39,1.599
17.20,110.59,1.592
17.22,110.80,1.587
17.24,111.00,1.581
17.26,111.20,1.574
17.28,111.40,1.567
17.30,111.60,1.561
17.32,111.80,1.554
17.34,112.01,1.547
17.36,112.21,1.540
17.38,112.41,1.534
17.40,112.61,1.526
17.42,112.82,1.519
17.44,113.02,1.512
17.46,113.22,1.504
17.48,113.42,1.498
17.50,113.63,1.490
17.52,113.83,1.482
17.54,114.03,1.475
17.56,114.23,1.467
17.58,114.44,1.459
17.60,114.64,1.451
17.62,114.84,1.443
17.64,115.04,1.436
17.66,115.25,1.428
17.68,115.45,1.418
17.70,115.65,1.410
17.72,115.85,1.402
17.74,116.06,1.394
17.76,116.26,1.384
17.78,116.46,1.377
17.80,116.66,1.368
17.82,116.87,1.360
17.84,117.07,1.351
17.86,117.27,1.342
17.88,117.47,1.334
17.90,117.68,1.325
17.92,117.88,1.316
17.94,118.08,1.308
17.96,118.28,1.300
17.98,118.49,1.292
18.00,118.69,1.283
18.02,118.89,1.275
18.04,119.09,1.266
18.06,119.30,1.258
18.08,119.50,1.251
18.10,119.70,1.243
18.12,119.90,1.234
18.14,120.11,1.225
18.16,120.31,1.218
18.18,120.51,1.211
18.20,120.71,1.202
18.22,120.92,1.194
18.24,121.12,1.187
18.26,121.32,1.176
18.28,121.52,1.170
18.30,121.73,1.161
18.32,121.93,1.154
18.34,122.13,1.144
18.36,122.33,1.136
18.38,122.54,1.129
18.40,122.74,1.120
18.42,122.94,1.113
18.44,123.14,1.105
18.46,123.35,1.096
18.48,123.55,1.090
18.50,123.75,1.082
18.52,123.95,1.074
18.54,124.16,1.066
18.56,124.36,1.059
18.58,124.56,1.051
18.60,124.76,1.045
18.62,124.97,1.036
18.64,125.17,1.028
18.66,125.37,1.022
18.68,125.57,1.013
18.70,125.78,1.006
18.72,125.98,0.999
18.74,126.18,0.991
18.76,126.38,0.985
18.78,126.58,0.976
18.80,126.79,0.971
18.82,126.99,0.962
18.84,127.19,0.957
18.86,127.39,0.949
18.88,127.59,0.943
18.90,127.80,0.936
18.92,128.00,0.929
18.94,128.20,0.923
18.96,128.40,0.916
18.98,128.61,0.909
19.00,128.81,0.903
19.02,129.01,0.896
19.04,129.21,0.890
19.06,129.41,0.883
19.08,129.61,0.875
19.10,129.82,0.870
19.12,130.02,0.863
19.14,130.22,0.857
19.16,130.42,0.851
19.18,130.62,0.844
19.20,130.83,0.839
19.22,131.03,0.832
19.24,131.23,0.826
19.26,131.43,0.821
19.28,131.63,0.815
19.30,131.83,0.809
19.32,132.04,0.802
19.34,132.24,0.797
19.36,132.44,0.791
19.38,132.64,0.785
19.40,132.85,0.780
19.42,133.05,0.775
19.44,133.25,0.769
19.46,133.45,0.763
19.48,133.65,0.758
19.50,133.85,0.752
19.52,134.06,0.746
19.54,134.26,0.741
19.56,134.46,0.735
19.58,134.66,0.731
19.60,134.86,0.725
19.62,135.07,0.721
19.64,135.27,0.714
19.66,135.47,0.709
19.68,135.67,0.703
19.70,135.87,0.699
19.72,136.07,0.693
19.74,136.27,0.688
19.76,136.47,0.683
19.78,136.68,0.679
19.80,136.88,0.674
19.82,137.08,0.669
19.84,137.28,0.664
19.86,137.48,0.660
19.88,137.68,0.655
19.90,137.89,0.650
19.92,138.09,0.646
19.94,138.29,0.640
19.96,138.49,0.636
19.98,138.69,0.632
20.00,138.89,0.628
20.02,139.10,0.623
20.04,139.30,0.619
20.06,139.50,0.615
20.08,139.70,0.610
20.10,139.90,0.606
20.12,140.10,0.601
20.14,140.30,0.597
20.16,140.50,0.592
20.18,140.71,0.588
20.20,140.91,0.584
20.22,141.11,0.581
20.24,141.31,0.578
20.26,141.51,0.572
20.28,141.71,0.568
20.30,141.91,0.565
20.32,142.11,0.561
20.34,142.31,0.556
20.36,142.52,0.553
20.38,142.72,0.549
20.40,142.92,0.546
20.42,143.12,0.542
20.44,143.32,0.538
20.46,143.52,0.535
20.48,143.72,0.531
20.50,143.92,0.528
20.52,144.12,0.524
20.54,144.33,0.520
20.56,144.53,0.518
20.58,144.73,0.514
20.60,144.93,0.510
20.62,145.13,0.508
20.64,145.33,0.504
20.66,145.53,0.501
20.68,145.74,0.498
20.70,145.94,0.495
20.72,146.14,0.492
20.74,146.34,0.488
20.76,146.54,0.484
20.78,146.74,0.481
20.80,146.94,0.478
20.82,147.14,0.476
20.84,147.34,0.473
20.86,147.54,0.470
20.88,147.74,0.467
20.90,147.95,0.464
20.92,148.15,0.462
20.94,148.35,0.459
20.96,148.55,0.456
20.98,148.75,0.454
21.00,148.95,0.451
21.02,149.15,0.449
21.04,149.35,0.446
21.06,149.55,0.443
21.08,149.75,0.441
21.10,149.95,0.437
21.12,150.16,0.436
21.14,150.36,0.433
21.16,150.56,0.432
21.18,150.76,0.430
21.20,150.96,0.427
21.22,151.16,0.425
21.24,151.36,0.422
21.26,151.56,0.420
21.28,151.76,0.418
21.30,151.96,0.415
21.32,152.16,0.413
21.34,152.37,0.411
21.36,152.57,0.409
21.38,152.77,0.407
21.40,152.97,0.405
21.42,153.17,0.404
21.44,153.37,0.401
21.46,153.57,0.399
21.48,153.77,0.397
21.50,153.97,0.396
21.52,154.17,0.394
21.54,154.37,0.393
21.56,154.58,0.391
21.58,154.78,0.390
21.60,154.98,0.389
21.62,155.18,0.386
21.64,155.38,0.384
21.66,155.58,0.383
21.68,155.78,0.381
21.70,155.98,0.379
21.72,156.18,0.378
21.74,156.38,0.376
21.76,156.58,0.375
21.78,156.78,0.374
21.80,156.98,0.373
21.82,157.18,0.371
21.84,157.38,0.370
21.86,157.58,0.369
21.88,157.78,0.367
21.90,157.98,0.366
21.92,158.18,0.365
21.94,158.38,0.364
21.96,158.58,0.362
21.98,158.79,0.362
22.00,158.98,0.360
22.02,159.19,0.360
22.04,159.39,0.359
22.06,159.59,0.358
22.08,159.79,0.357
22.10,159.99,0.356
22.12,160.19,0.356
22.14,160.39,0.355
22.16,160.59,0.354
22.18,160.79,0.353
22.20,160.99,0.352
22.22,161.19,0.351
22.24,161.39,0.351
22.26,161.59,0.350
22.28,161.79,0.349
22.30,161.99,0.348
22.32,162.19,0.348
22.34,162.39,0.347
22.36,162.59,0.347
22.38,162.79,0.346
22.40,162.99,0.345
22.42,163.19,0.345
22.44,163.39,0.344
22.46,163.59,0.344
22.48,163.79,0.343
22.50,163.99,0.343
22.52,164.19,0.342
22.54,164.39,0.342
22.56,164.60,0.342
22.58,164.80,0.342
22.60,165.00,0.341
22.62,165.20,0.341
22.64,165.40,0.341
22.66,165.60,0.340
22.68,165.80,0.339
22.70,166.00,0.339
22.72,166.20,0.338
22.74,166.40,0.338
22.76,166.60,0.337
22.78,166.80,0.337
22.80,167.00,0.336
22.82,167.20,0.336
22.84,167.40,0.336
22.86,167.60,0.335
22.88,167.80,0.335
22.90,168.00,0.335
22.92,168.20,0.334
22.94,168.40,0.334
22.96,168.60,0.334
22.98,168.80,0.334
23.00,169.00,0.334
23.02,169.20,0.334
23.04,169.40,0.333
23.06,169.60,0.333
23.08,169.80,0.334
23.10,170.00,0.334
23.12,170.20,0.334
23.14,170.40,0.334
23.16,170.60,0.334
23.18,170.80,0.335
23.20,171.00,0.335
23.22,171.20,0.335
23.24,171.40,0.336
23.26,171.60,0.336
23.28,171.80,0.337
23.30,172.00,0.337
23.32,172.20,0.338
23.34,172.40,0.338
23.36,172.60,0.339
23.38,172.80,0.340
23.40,173.00,0.341
23.42,173.20,0.342
23.44,173.40,0.342
23.46,173.60,0.343
23.48,173.80,0.344
23.50,174.00,0.345
23.52,174.20,0.346
23.54,174.40,0.347
23.56,174.60,0.348
23.58,174.80,0.350
23.60,175.00,0.352
23.62,175.20,0.353
23.64,175.40,0.355
23.66,175.60,0.356
23.68,175.80,0.358
23.70,176.00,0.359
23.72,176.20,0.361
23.74,176.40,0.363
23.76,176.60,0.365
23.78,176.80,0.367
23.80,177.00,0.368
23.82,177.20,0.368
23.84,177.40,0.369
23.86,177.60,0.370
23.88,177.80,0.371
23.90,178.00,0.372
23.92,178.20,0.372
23.94,178.40,0.373
23.96,178.59,0.374
23.98,178.80,0.374
24.00,178.99,0.375
24.02,179.20,0.375
24.04,179.40,0.376
24.06,179.60,0.376
24.08,179.80,0.376
24.10,180.00,0.377
24.12,180.20,0.377
24.14,180.40,0.377
24.16,180.60,0.377
24.18,180.80,0.377
24.20,181.00,0.376
24.22,181.20,0.376
24.24,181.40,0.376
24.26,181.60,0.376
24.28,181.80,0.375
24.30,182.00,0.375
24.32,182.20,0.374
24.34,182.40,0.374
24.36,182.60,0.373
24.38,182.80,0.373
24.40,183.00,0.372
24.42,183.20,0.372
24.44,183.40,0.371
24.46,183.60,0.371
24.48,183.80,0.370
24.50,184.00,0.370
24.52,184.20,0.369
24.54,184.40,0.369
24.56,184.60,0.369
24.58,184.80,0.369
24.60,185.00,0.368
24.62,185.20,0.368
24.64,185.41,0.368
24.66,185.60,0.368
24.68,185.80,0.367
24.70,186.00,0.367
24.72,186.20,0.367
24.74,186.41,0.367
24.76,186.61,0.367
24.78,186.81,0.367
24.80,187.01,0.367
24.82,187.21,0.367
24.84,187.41,0.367
24.86,187.61,0.366
24.88,187.81,0.366
24.90,188.01,0.366
24.92,188.21,0.366
24.94,188.41,0.366
24.96,188.61,0.366
24.98,188.81,0.366
25.00,189.01,0.366
25.02,189.21,0.366
25.04,189.41,0.366
25.06,189.61,0.366
25.08,189.81,0.366
25.10,190.01,0.366
25.12,190.21,0.366
25.14,190.41,0.366
25.16,190.61,0.366
25.18,190.81,0.367
25.20,191.01,0.367
25.22,191.21,0.367
25.24,191.41,0.367
25.26,191.61,0.367
25.28,191.81,0.367
25.30,192.01,0.367
25.32,192.21,0.367
25.34,192.41,0.367
25.36,192.61,0.367
25.38,192.81,0.368
25.40,193.01,0.368
25.42,193.21,0.368
25.44,193.41,0.368
25.46,193.61,0.368
25.48,193.81,0.368
25.50,194.01,0.368
25.52,194.21,0.368
25.54,194.41,0.368
25.56,194.61,0.368
25.58,194.81,0.369
25.60,195.01,0.369
25.62,195.21,0.369
25.64,195.41,0.369
25.66,195.61,0.369
25.68,195.81,0.369
25.70,196.01,0.369
25.72,196.21,0.369
25.74,196.41,0.369
25.76,196.61,0.369
25.78,196.81,0.369
25.80,197.01,0.369
25.82,197.21,0.369
25.84,197.41,0.370
25.86,197.61,0.370
25.88,197.81,0.370
25.90,198.01,0.370
25.92,198.21,0.370
25.94,198.41,0.370
25.96,198.61,0.370
25.98,198.81,0.370
26.00,199.01,0.370
26.02,199.21,0.371
26.04,199.41,0.371
26.06,199.61,0.371
26.08,199.81,0.371
26.10,200.01,0.371
26.12,200.21,0.371
26.14,200.41,0.371
26.16,200.61,0.371
26.18,200.81,0.372
26.20,201.01,0.372
26.22,201.21,0.372
26.24,201.41,0.372
26.26,201.61,0.372
26.28,201.81,0.372
26.30,202.01,0.372
26.32,202.21,0.372
26.34,202.42,0.372
26.36,202.62,0.372
26.38,202.82,0.373
26.40,203.02,0.373
26.42,203.22,0.373
26.44,203.42,0.373
26.46,203.62,0.373
26.48,203.82,0.373
26.50,204.02,0.373
26.52,204.22,0.373
26.54,204.42,0.373
26.56,204.62,0.373
26.58,204.82,0.374
26.60,205.02,0.374
26.62,205.22,0.374
26.64,205.42,0.374
26.66,205.62,0.374
26.68,205.82,0.374
26.70,206.02,0.374
26.72,206.22,0.374
26.74,206.42,0.374
26.76,206.62,0.374
26.78,206.82,0.374
26.80,207.02,0.374
26.82,207.22,0.374
26.84,207.42,0.374
26.86,207.62,0.375
26.88,207.82,0.375
26.90,208.02,0.375
26.92,208.22,0.375
26.94,208.42,0.375
26.96,208.62,0.375
26.98,208.82,0.375
27.00,209.02,0.375
27.02,209.22,0.375
27.04,209.42,0.376
27.06,209.62,0.376
27.08,209.82,0.376
27.10,210.02,0.376
27.12,210.22,0.376
27.14,210.42,0.376
27.16,210.62,0.376
27.18,210.82,0.376
27.20,211.02,0.376
27.22,211.22,0.376
27.24,211.42,0.376
27.26,211.62,0.376
27.28,211.82,0.376
27.30,212.02,0.377
27.32,212.22,0.377
27.34,212.42,0.377
27.36,212.62,0.377
27.38,212.82,0.377
27.40,213.02,0.377
27.42,213.22,0.377
27.44,213.42,0.377
27.46,213.62,0.378
27.48,213.82,0.378
27.50,214.02,0.378
27.52,214.22,0.378
27.54,214.42,0.378
27.56,214.62,0.378
27.58,214.82,0.378
27.60,215.02,0.378
27.62,215.22,0.379
27.64,215.42,0.379
27.66,215.62,0.379
27.68,215.82,0.379
27.70,216.02,0.379
27.72,216.22,0.379
27.74,216.42,0.379
27.76,216.62,0.379
27.78,216.82,0.379
27.80,217.02,0.379
27.82,217.22,0.379
27.84,217.42,0.379
27.86,217.62,0.379
27.88,217.82,0.379
27.90,218.02,0.379
27.92,218.22,0.380
27.94,218.42,0.380
27.96,218.63,0.380
27.98,218.83,0.380
28.00,219.03,0.380
28.02,219.23,0.380
28.04,219.43,0.380
28.06,219.63,0.381
28.08,219.83,0.381
28.10,220.03,0.381
28.12,220.23,0.381
28.14,220.43,0.381
28.16,220.63,0.381
28.18,220.83,0.381
28.20,221.03,0.381
28.22,221.23,0.381
28.24,221.43,0.381
28.26,221.63,0.381
28.28,221.83,0.381
28.30,222.03,0.381
28.32,222.23,0.382
28.34,222.43,0.382
28.36,222.63,0.382
28.38,222.83,0.382
28.40,223.03,0.382
28.42,223.23,0.382
28.44,223.43,0.382
28.46,223.63,0.382
28.48,223.83,0.382
28.50,224.03,0.382
28.52,224.23,0.382
28.54,224.43,0.382
28.56,224.63,0.383
28.58,224.83,0.383
28.60,225.03,0.383
28.62,225.23,0.383
28.64,225.43,0.383
28.66,225.63,0.383
28.68,225.83,0.383
28.70,226.03,0.383
28.72,226.23,0.383
28.74,226.43,0.383
28.76,226.63,0.383
28.78,226.83,0.383
28.80,227.03,0.383
28.82,227.23,0.383
28.84,227.43,0.383
28.86,227.63,0.384
28.88,227.83,0.384
28.90,228.03,0.384
28.92,228.23,0.384
28.94,228.43,
28.96,228.63,
28.98,228.83,
28.99,,

[step]
Ramp 10.00 °C/min to -60.00 °C
Time,Temperature,Heat Flow (Normalized)
min,°C,W/g
30.99,230.16,-0.034
31.01,230.16,-0.034
31.03,230.16,-0.034
31.05,230.14,-0.033
31.07,230.11,-0.035
31.09,230.04,-0.069
31.11,229.95,-0.119
31.13,229.82,-0.182
31.15,229.68,-0.244
31.17,229.52,-0.301
31.19,229.34,-0.343
31.21,229.16,-0.376
31.23,228.97,-0.399
31.25,228.78,-0.412
31.27,228.59,-0.422
31.29,228.39,-0.429
31.31,228.20,-0.433
31.33,228.00,-0.436
31.35,227.81,-0.438
31.37,227.61,-0.440
31.39,227.41,-0.441
31.41,227.21,-0.442
31.43,227.02,-0.443
31.45,226.82,-0.444
31.47,226.62,-0.444
31.49,226.42,-0.445
31.51,226.22,-0.445
31.53,226.02,-0.445
31.55,225.83,-0.446
31.57,225.63,-0.446
31.59,225.43,-0.446
31.61,225.23,-0.446
31.63,225.03,-0.447
31.65,224.83,-0.447
31.67,224.63,-0.447
31.69,224.44,-0.447
31.71,224.24,-0.448
31.73,224.04,-0.448
31.75,223.84,-0.448
31.77,223.64,-0.448
31.79,223.44,-0.448
31.81,223.24,-0.448
31.83,223.05,-0.448
31.85,222.85,-0.448
31.87,222.65,-0.448
31.89,222.45,-0.448
31.91,222.25,-0.449
31.93,222.05,-0.449
31.95,221.85,-0.449
31.97,221.65,-0.449
31.99,221.45,-0.449
32.01,221.25,-0.449
32.03,221.05,-0.449
32.05,220.85,-0.449
32.07,220.65,-0.449
32.09,220.46,-0.449
32.11,220.26,-0.449
32.13,220.06,-0.449
32.15,219.86,-0.449
32.17,219.66,-0.449
32.19,219.46,-0.449
32.21,219.26,-0.449
32.23,219.06,-0.449
32.25,218.86,-0.449
32.27,218.66,-0.449
32.29,218.46,-0.449
32.31,218.26,-0.449
32.33,218.06,-0.449
32.35,217.86,-0.449
32.37,217.66,-0.449
32.39,217.46,-0.448
32.41,217.26,-0.448
32.43,217.06,-0.448
32.45,216.86,-0.448
32.47,216.66,-0.448
32.49,216.47,-0.448
32.51,216.27,-0.448
32.53,216.07,-0.448
32.55,215.87,-0.448
32.57,215.67,-0.448
32.59,215.47,-0.448
32.61,215.27,-0.448
32.63,215.07,-0.448
32.65,214.87,-0.448
32.67,214.67,-0.448
32.69,214.47,-0.448
32.71,214.27,-0.448
32.73,214.07,-0.448
32.75,213.87,-0.448
32.77,213.67,-0.447
32.79,213.47,-0.447
32.81,213.27,-0.447
32.83,213.07,-0.447
32.85,212.87,-0.447
32.87,212.67,-0.447
32.89,212.47,-0.447
32.91,212.27,-0.447
32.93,212.07,-0.447
32.95,211.87,-0.447
32.97,211.67,-0.446
32.99,211.47,-0.446
33.01,211.27,-0.446
33.03,211.07,-0.446
33.05,210.87,-0.446
33.07,210.67,-0.446
33.09,210.47,-0.446
33.11,210.27,-0.446
33.13,210.07,-0.446
33.15,209.87,-0.446
33.17,209.67,-0.446
33.19,209.47,-0.446
33.21,209.27,-0.445
33.23,209.07,-0.445
33.25,208.87,-0.445
33.27,208.67,-0.445
33.29,208.47,-0.445
33.31,208.27,-0.445
33.33,208.07,-0.445
33.35,207.87,-0.445
33.37,207.67,-0.444
33.39,207.47,-0.444
33.41,207.27,-0.444
33.43,207.07,-0.444
33.45,206.87,-0.444
33.47,206.67,-0.444
33.49,206.47,-0.444
33.51,206.27,-0.444
33.53,206.07,-0.444
33.55,205.87,-0.444
33.57,205.67,-0.444
33.59,205.47,-0.444
33.61,205.27,-0.443
33.63,205.07,-0.443
33.65,204.87,-0.443
33.67,204.67,-0.443
33.69,204.47,-0.443
33.71,204.27,-0.443
33.73,204.07,-0.443
33.75,203.87,-0.443
33.77,203.67,-0.443
33.79,203.48,-0.443
33.81,203.28,-0.443
33.83,203.07,-0.442
33.85,202.87,-0.442
33.87,202.68,-0.442
33.89,202.47,-0.442
33.91,202.28,-0.442
33.93,202.07,-0.442
33.95,201.88,-0.442
33.97,201.67,-0.442
33.99,201.48,-0.442
34.01,201.28,-0.442
34.03,201.08,-0.442
34.05,200.88,-0.442
34.07,200.68,-0.441
34.09,200.47,-0.441
34.11,200.28,-0.441
34.13,200.08,-0.441
34.15,199.87,-0.441
34.17,199.67,-0.441
34.19,199.47,-0.441
34.21,199.28,-0.441
34.23,199.08,-0.441
34.25,198.88,-0.441
34.27,198.68,-0.441
34.29,198.48,-0.440
34.31,198.28,-0.440
34.33,198.08,-0.440
34.35,197.88,-0.440
34.37,197.68,-0.440
34.39,197.48,-0.440
34.41,197.28,-0.440
34.43,197.08,-0.440
34.45,196.88,-0.440
34.47,196.68,-0.440
34.49,196.48,-0.440
34.51,196.28,-0.440
34.53,196.08,-0.440
34.55,195.88,-0.439
34.57,195.68,-0.439
34.59,195.48,-0.439
34.61,195.28,-0.439
34.63,195.08,-0.439
34.65,194.88,-0.439
34.67,194.68,-0.439
34.69,194.48,-0.439
34.71,194.28,-0.439
34.73,194.08,-0.439
34.75,193.88,-0.439
34.77,193.68,-0.439
34.79,193.48,-0.439
34.81,193.28,-0.439
34.83,193.08,-0.438
34.85,192.88,-0.438
34.87,192.68,-0.438
34.89,192.48,-0.438
34.91,192.28,-0.438
34.93,192.08,-0.438
34.95,191.88,-0.438
34.97,191.68,-0.438
34.99,191.48,-0.438
35.01,191.28,-0.438
35.03,191.08,-0.437
35.05,190.88,-0.437
35.07,190.68,-0.437
35.09,190.48,-0.437
35.11,190.28,-0.437
35.13,190.08,-0.437
35.15,189.88,-0.437
35.17,189.68,-0.437
35.19,189.48,-0.437
35.21,189.28,-0.437
35.23,189.08,-0.436
35.25,188.88,-0.436
35.27,188.68,-0.436
35.29,188.48,-0.436
35.31,188.28,-0.436
35.33,188.08,-0.436
35.35,187.88,-0.436
35.37,187.68,-0.436
35.39,187.48,-0.436
35.41,187.28,-0.436
35.43,187.08,-0.436
35.45,186.88,-0.436
35.47,186.68,-0.436
35.49,186.48,-0.435
35.51,186.28,-0.435
35.53,186.08,-0.435
35.55,185.88,-0.435
35.57,185.68,-0.435
35.59,185.48,-0.435
35.61,185.28,-0.435
35.63,185.08,-0.435
35.65,184.88,-0.435
35.67,184.68,-0.435
35.69,184.48,-0.434
35.71,184.28,-0.434
35.73,184.08,-0.434
35.75,183.88,-0.434
35.77,183.68,-0.434
35.79,183.48,-0.434
35.81,183.28,-0.434
35.83,183.08,-0.434
35.85,182.88,-0.434
35.87,182.68,-0.433
35.89,182.48,-0.433
35.91,182.28,-0.433
35.93,182.08,-0.433
35.95,181.88,-0.433
35.97,181.68,-0.433
35.99,181.48,-0.432
36.01,181.28,-0.432
36.03,181.08,-0.432
36.05,180.88,-0.432
36.07,180.68,-0.432
36.09,180.48,-0.432
36.11,180.28,-0.432
36.13,180.08,-0.431
36.15,179.88,-0.431
36.17,179.68,-0.431
36.19,179.48,-0.431
36.21,179.28,-0.431
36.23,179.08,-0.431
36.25,178.88,-0.430
36.27,178.68,-0.430
36.29,178.48,-0.430
36.31,178.28,-0.429
36.33,178.08,-0.429
36.35,177.88,-0.429
36.37,177.68,-0.429
36.39,177.48,-0.429
36.41,177.28,-0.428
36.43,177.08,-0.428
36.45,176.88,-0.428
36.47,176.68,-0.427
36.49,176.48,-0.427
36.51,176.28,-0.427
36.53,176.08,-0.426
36.55,175.88,-0.426
36.57,175.68,-0.426
36.59,175.48,-0.426
36.61,175.28,-0.425
36.63,175.08,-0.425
36.65,174.88,-0.424
36.67,174.68,-0.424
36.69,174.48,-0.424
36.71,174.28,-0.423
36.73,174.08,-0.423
36.75,173.88,-0.422
36.77,173.68,-0.422
36.79,173.48,-0.421
36.81,173.28,-0.421
36.83,173.08,-0.421
36.85,172.88,-0.420
36.87,172.68,-0.419
36.89,172.48,-0.419
36.91,172.28,-0.418
36.93,172.08,-0.418
36.95,171.88,-0.418
36.97,171.68,-0.417
36.99,171.48,-0.417
37.01,171.28,-0.416
37.03,171.08,-0.416
37.05,170.88,-0.415
37.07,170.68,-0.415
37.09,170.48,-0.414
37.11,170.28,-0.414
37.13,170.08,-0.413
37.15,169.88,-0.412
37.17,169.68,-0.412
37.19,169.48,-0.411
37.21,169.28,-0.411
37.23,169.08,-0.410
37.25,168.88,-0.410
37.27,168.68,-0.409
37.29,168.48,-0.409
37.31,168.28,-0.408
37.33,168.08,-0.408
37.35,167.88,-0.407
37.37,167.68,-0.407
37.39,167.48,-0.406
37.41,167.28,-0.406
37.43,167.08,-0.405
37.45,166.88,-0.405
37.47,166.68,-0.404
37.49,166.48,-0.404
37.51,166.28,-0.403
37.53,166.08,-0.403
37.55,165.88,-0.402
37.57,165.68,-0.402
37.59,165.48,-0.401
37.61,165.28,-0.401
37.63,165.08,-0.400
37.65,164.88,-0.400
37.67,164.68,-0.400
37.69,164.48,-0.399
37.71,164.28,-0.399
37.73,164.08,-0.398
37.75,163.88,-0.398
37.77,163.68,-0.397
37.79,163.48,-0.397
37.81,163.28,-0.397
37.83,163.08,-0.396
37.85,162.88,-0.396
37.87,162.68,-0.395
37.89,162.48,-0.395
37.91,162.28,-0.395
37.93,162.08,-0.394
37.95,161.88,-0.394
37.97,161.68,-0.393
37.99,161.48,-0.393
38.01,161.28,-0.393
38.03,161.08,-0.392
38.05,160.88,-0.392
38.07,160.68,-0.392
38.09,160.48,-0.391
38.11,160.28,-0.391
38.13,160.08,-0.390
38.15,159.88,-0.390
38.17,159.68,-0.390
38.19,159.48,-0.389
38.21,159.28,-0.389
38.23,159.08,-0.389
[...]
132.63,25.13,0.227
132.65,25.33,0.228
132.67,25.53,0.228
132.69,25.73,0.228
132.71,25.93,0.228
132.73,26.13,0.228
132.75,26.33,0.228
132.77,26.53,0.228
132.79,26.73,0.228
132.81,26.93,0.228
132.83,27.13,0.228
132.85,27.33,0.229
132.87,27.53,0.229
132.89,27.73,0.229
132.91,27.93,0.229
132.93,28.13,0.229
132.95,28.33,0.229
132.97,28.53,0.229
132.99,28.73,0.229
133.01,28.93,0.230
133.03,29.13,0.230
133.05,29.33,0.230
133.07,29.53,0.230
133.09,29.74,0.230
133.11,29.94,0.230
133.13,30.14,0.230
133.15,30.34,0.230
133.17,30.53,0.230
133.19,30.74,0.231
133.21,30.94,0.231
133.23,31.14,0.231
133.25,31.34,0.231
133.27,31.54,0.231
133.29,31.74,0.231
133.31,31.94,0.231
133.33,32.14,0.231
133.35,32.34,0.231
133.37,32.54,0.231
133.39,32.74,0.231
133.41,32.94,0.232
133.43,33.14,0.232
133.45,33.34,0.232
133.47,33.54,0.232
133.49,33.74,0.232
133.51,33.94,0.232
133.53,34.14,0.232
133.55,34.34,0.232
133.57,34.54,0.233
133.59,34.74,0.233
133.61,34.94,0.233
133.63,35.14,0.233
133.65,35.34,0.233
133.67,35.54,0.233
133.69,35.74,0.233
133.71,35.94,0.233
133.73,36.14,0.233
133.75,36.34,0.233
133.77,36.54,0.234
133.79,36.74,0.234
133.81,36.94,0.234
133.83,37.14,0.234
133.85,37.34,0.234
133.87,37.54,0.234
133.89,37.74,0.234
133.91,37.94,0.234
133.93,38.14,0.234
133.95,38.34,0.234
133.97,38.54,0.235
133.99,38.74,0.235
134.01,38.94,0.235
134.03,39.14,0.235
134.05,39.34,0.235
134.07,39.54,0.235
134.09,39.74,0.235
134.11,39.95,0.235
134.13,40.14,0.235
134.15,40.34,0.235
134.17,40.55,0.236
134.19,40.75,0.236
134.21,40.95,0.236
134.23,41.15,0.236
134.25,41.35,0.236
134.27,41.55,0.236
134.29,41.75,0.236
134.31,41.95,0.236
134.33,42.15,0.236
134.35,42.35,0.237
134.37,42.55,0.237
134.39,42.75,0.237
134.41,42.95,0.237
134.43,43.15,0.237
134.45,43.35,0.237
134.47,43.55,0.237
134.49,43.75,0.237
134.51,43.95,0.237
134.53,44.15,0.238
134.55,44.35,0.238
134.57,44.55,0.238
134.59,44.75,0.238
134.61,44.95,0.238
134.63,45.15,0.238
134.65,45.35,0.238
134.67,45.55,0.238
134.69,45.75,0.238
134.71,45.95,0.239
134.73,46.15,0.239
134.75,46.35,0.239
134.77,46.55,0.239
134.79,46.75,0.239
134.81,46.95,0.239
134.83,47.15,0.239
134.85,47.35,0.240
134.87,47.55,0.240
134.89,47.75,0.240
134.91,47.95,0.240
134.93,48.15,0.240
134.95,48.35,0.240
134.97,48.55,0.240
134.99,48.75,0.240
135.01,48.95,0.240
135.03,49.15,0.240
135.05,49.35,0.241
135.07,49.55,0.241
135.09,49.75,0.241
135.11,49.96,0.241
135.13,50.16,0.241
135.15,50.36,0.241
135.17,50.56,0.241
135.19,50.76,0.241
135.21,50.96,0.242
135.23,51.16,0.242
135.25,51.36,0.242
135.27,51.56,0.242
135.29,51.76,0.242
135.31,51.96,0.242
135.33,52.16,0.242
135.35,52.36,0.242
135.37,52.56,0.242
135.39,52.76,0.242
135.41,52.96,0.242
135.43,53.16,0.243
135.45,53.36,0.243
135.47,53.56,0.243
135.49,53.76,0.243
135.51,53.96,0.243
135.53,54.16,0.243
135.55,54.36,0.243
135.57,54.56,0.243
135.59,54.76,0.243
135.61,54.96,0.244
135.63,55.16,0.244
135.65,55.36,0.244
135.67,55.56,0.244
135.69,55.76,0.244
135.71,55.96,0.244
135.73,56.16,0.244
135.75,56.36,0.244
135.77,56.56,0.244
135.79,56.76,0.245
135.81,56.96,0.245
135.83,57.16,0.245
135.85,57.36,0.245
135.87,57.56,0.245
135.89,57.76,0.245
135.91,57.96,0.245
135.93,58.16,0.245
135.95,58.36,0.245
135.97,58.56,0.246
135.99,58.76,0.246
136.01,58.96,0.246
136.03,59.16,0.246
136.05,59.36,0.246
136.07,59.57,0.246
136.09,59.76,0.246
136.11,59.96,0.246
136.13,60.17,0.246
136.15,60.37,0.247
136.17,60.57,0.247
136.19,60.77,0.247
136.21,60.97,0.247
136.23,61.17,0.247
136.25,61.37,0.247
136.27,61.57,0.247
136.29,61.76,0.247
136.31,61.97,0.247
136.33,62.17,0.248
136.35,62.37,0.248
136.37,62.57,0.248
136.39,62.77,0.248
136.41,62.97,0.248
136.43,63.17,0.248
136.45,63.37,0.248
136.47,63.57,0.248
136.49,63.77,0.248
136.51,63.97,0.249
136.53,64.17,0.249
136.55,64.37,0.249
136.57,64.57,0.249
136.59,64.77,0.249
136.61,64.97,0.249
136.63,65.17,0.249
136.65,65.37,0.249
136.67,65.57,0.249
136.69,65.77,0.250
136.71,65.97,0.250
136.73,66.17,0.250
136.75,66.37,0.250
136.77,66.57,0.250
136.79,66.77,0.250
136.81,66.97,0.250
136.83,67.17,0.250
136.85,67.37,0.251
136.87,67.57,0.251
136.89,67.77,0.251
136.91,67.97,0.251
136.93,68.17,0.251
136.95,68.37,0.251
136.97,68.57,0.251
136.99,68.77,0.251
137.01,68.97,0.251
137.03,69.17,0.252
137.05,69.37,0.252
137.07,69.57,0.252
137.09,69.77,0.252
137.11,69.97,0.252
137.13,70.17,0.252
137.15,70.37,0.252
137.17,70.57,0.252
137.19,70.77,0.252
137.21,70.97,0.253
137.23,71.17,0.253
137.25,71.37,0.253
137.27,71.57,0.253
137.29,71.78,0.253
137.31,71.98,0.253
137.33,72.18,0.253
137.35,72.38,0.253
137.37,72.58,0.254
137.39,72.78,0.254
137.41,72.98,0.254
137.43,73.18,0.254
137.45,73.38,0.254
137.47,73.58,0.254
137.49,73.78,0.254
137.51,73.98,0.254
137.53,74.18,0.254
137.55,74.38,0.255
137.57,74.58,0.255
137.59,74.78,0.255
137.61,74.98,0.255
137.63,75.18,0.255
137.65,75.38,0.255
137.67,75.58,0.255
137.69,75.78,0.255
137.71,75.98,0.255
137.73,76.18,0.256
137.75,76.38,0.256
137.77,76.58,0.256
137.79,76.78,0.256
137.81,76.98,0.256
137.83,77.18,0.256
137.85,77.38,0.256
137.87,77.58,0.256
137.89,77.78,0.256
137.91,77.98,0.256
137.93,78.18,0.257
137.95,78.38,0.257
137.97,78.58,0.257
137.99,78.78,0.257
138.01,78.98,0.257
138.03,79.18,0.257
138.05,79.38,0.257
138.07,79.58,0.257
138.09,79.78,0.258
138.11,79.98,0.258
138.13,80.18,0.258
138.15,80.38,0.258
138.17,80.58,0.258
138.19,80.78,0.258
138.21,80.98,0.258
138.23,81.18,0.258
138.25,81.38,0.258
138.27,81.58,0.259
138.29,81.78,0.259
138.31,81.98,0.259
138.33,82.18,0.259
138.35,82.38,0.259
138.37,82.58,0.259
138.39,82.78,0.259
138.41,82.98,0.259
138.43,83.18,0.259
138.45,83.38,0.259
138.47,83.58,0.259
138.49,83.79,0.260
138.51,83.99,0.260
138.53,84.19,0.260
138.55,84.39,0.260
138.57,84.59,0.260
138.59,84.79,0.260
138.61,84.99,0.260
138.63,85.19,0.260
138.65,85.39,0.260
138.67,85.59,0.261
138.69,85.79,0.261
138.71,85.99,0.261
138.73,86.19,0.261
138.75,86.39,0.261
138.77,86.59,0.261
138.79,86.79,0.261
138.81,86.99,0.261
138.83,87.19,0.261
138.85,87.39,0.261
138.87,87.59,0.262
138.89,87.79,0.262
138.91,87.99,0.262
138.93,88.19,0.262
138.95,88.39,0.262
138.97,88.59,0.262
138.99,88.79,0.262
139.01,88.99,0.262
139.03,89.19,0.263
139.05,89.39,0.263
139.07,89.59,0.263
139.09,89.79,0.263
139.11,89.99,0.263
139.13,90.19,0.263
139.15,90.39,0.263
139.17,90.59,0.264
139.19,90.79,0.264
139.21,90.99,0.264
139.23,91.19,0.264
139.25,91.39,0.264
139.27,91.59,0.264
139.29,91.79,0.264
139.31,91.99,0.264
139.33,92.19,0.265
139.35,92.39,0.265
139.37,92.59,0.265
139.39,92.79,0.265
139.41,92.99,0.265
139.43,93.19,0.265
139.45,93.39,0.265
139.47,93.59,0.266
139.49,93.79,0.266
139.51,93.99,0.266
139.53,94.19,0.266
139.55,94.39,0.266
139.57,94.59,0.266
139.59,94.79,0.266
139.61,94.99,0.266
139.63,95.19,0.266
139.65,95.39,0.267
139.67,95.59,0.267
139.69,95.79,0.267
139.71,95.99,0.267
139.73,96.20,0.267
139.75,96.40,0.267
139.77,96.60,0.267
139.79,96.80,0.267
139.81,97.00,0.268
139.83,97.20,0.268
139.85,97.40,0.268
139.87,97.60,0.268
139.89,97.80,0.268
139.91,98.00,0.268
139.93,98.20,0.268
139.95,98.40,0.268
139.97,98.60,0.269
139.99,98.80,0.269
140.01,99.00,0.269
140.03,99.20,0.269
140.05,99.40,0.269
140.07,99.60,0.269
140.09,99.80,0.269
140.11,100.00,0.269
140.13,100.20,0.270
140.15,100.40,0.270
140.17,100.60,0.270
140.19,100.80,0.270
140.21,101.00,0.270
140.23,101.20,0.270
140.25,101.40,0.270
140.27,101.60,0.270
140.29,101.80,0.270
140.31,102.00,0.271
140.33,102.20,0.271
140.35,102.40,0.271
140.37,102.60,0.271
140.39,102.80,0.271
140.41,103.00,0.271
140.43,103.20,0.271
140.45,103.40,0.271
140.47,103.60,0.272
140.49,103.80,0.272
140.51,104.00,0.272
140.53,104.20,0.272
140.55,104.40,0.272
140.57,104.60,0.272
140.59,104.80,0.272
140.61,105.00,0.272
140.63,105.20,0.272
140.65,105.40,0.273
140.67,105.60,0.273
140.69,105.81,0.273
140.71,106.00,0.273
140.73,106.20,0.273
140.75,106.40,0.273
140.77,106.60,0.273
140.79,106.80,0.273
140.81,107.00,0.273
140.83,107.20,0.274
140.85,107.40,0.274
140.87,107.60,0.274
140.89,107.81,0.274
140.91,108.01,0.274
140.93,108.21,0.274
140.95,108.41,0.274
140.97,108.61,0.274
140.99,108.81,0.275
141.01,109.01,0.275
141.03,109.21,0.275
141.05,109.41,0.275
141.07,109.61,0.275
141.09,109.81,0.275
141.11,110.01,0.275
141.13,110.21,0.276
141.15,110.41,0.276
141.17,110.61,0.276
141.19,110.81,0.276
141.21,111.01,0.276
141.23,111.21,0.276
141.25,111.41,0.276
141.27,111.61,0.276
141.29,111.81,0.276
141.31,112.01,0.277
141.33,112.21,0.277
141.35,112.41,0.277
141.37,112.61,0.277
141.39,112.81,0.277
141.41,113.01,0.277
141.43,113.21,0.277
141.45,113.41,0.277
141.47,113.61,0.277
141.49,113.81,0.278
141.51,114.01,0.278
141.53,114.21,0.278
141.55,114.41,0.278
141.57,114.61,0.278
141.59,114.81,0.278
141.61,115.01,0.278
141.63,115.21,0.278
141.65,115.41,0.278
141.67,115.61,0.279
141.69,115.81,0.279
141.71,116.01,0.279
141.73,116.21,0.279
141.75,116.41,0.279
141.77,116.61,0.279
141.79,116.81,0.279
141.81,117.01,0.279
141.83,117.21,0.279
141.85,117.41,0.279
141.87,117.61,0.280
141.89,117.81,0.280
141.91,118.01,0.280
141.93,118.21,0.280
141.95,118.41,0.280
141.97,118.61,0.280
141.99,118.81,0.280
142.01,119.01,0.281
142.03,119.21,0.281
142.05,119.41,0.281
142.07,119.61,0.281
142.09,119.81,0.281
142.11,120.01,0.281
142.13,120.21,0.281
142.15,120.41,0.281
142.17,120.61,0.282
142.19,120.82,0.282
142.21,121.01,0.282
142.23,121.21,0.282
142.25,121.41,0.282
142.27,121.61,0.282
142.29,121.82,0.282
142.31,122.02,0.282
142.33,122.22,0.282
142.35,122.42,0.283
142.37,122.62,0.283
142.39,122.82,0.283
142.41,123.02,0.283
142.43,123.22,0.283
142.45,123.42,0.283
142.47,123.62,0.283
142.49,123.82,0.284
142.51,124.02,0.284
142.53,124.22,0.284
142.55,124.42,0.284
142.57,124.62,0.284
142.59,124.82,0.284
142.61,125.02,0.284
142.63,125.22,0.284
142.65,125.42,0.284
142.67,125.62,0.285
142.69,125.82,0.285
142.71,126.02,0.285
142.73,126.22,0.285
142.75,126.42,0.285
142.77,126.62,0.285
142.79,126.82,0.285
142.81,127.02,0.285
142.83,127.22,0.286
142.85,127.42,0.286
142.87,127.62,0.286
142.89,127.82,0.286
142.91,128.02,0.286
142.93,128.22,0.286
142.95,128.42,0.286
142.97,128.62,0.286
142.99,128.82,0.286
143.01,129.02,0.287
143.03,129.22,0.287
143.05,129.42,0.287
143.07,129.62,0.287
143.09,129.82,0.287
143.11,130.02,0.287
143.13,130.22,0.287
143.15,130.42,0.287
143.17,130.62,0.288
143.19,130.82,0.288
143.21,131.02,0.288
143.23,131.22,0.288
143.25,131.42,0.288
143.27,131.62,0.288
143.29,131.82,0.288
143.31,132.02,0.288
143.33,132.22,0.288
143.35,132.42,0.289
143.37,132.62,0.289
143.39,132.82,0.289
143.41,133.02,0.289
143.43,133.22,0.289
143.45,133.42,0.289
143.47,133.62,0.289
143.49,133.82,0.289
143.51,134.02,0.289
143.53,134.22,0.290
143.55,134.42,0.290
143.57,134.62,0.290
143.59,134.82,0.290
143.61,135.02,0.290
143.63,135.22,0.290
143.65,135.42,0.290
143.67,135.62,0.290
143.69,135.82,0.291
143.71,136.02,0.291
143.73,136.23,0.291
143.75,136.43,0.291
143.77,136.63,0.291
143.79,136.83,0.291
143.81,137.03,0.291
143.83,137.22,0.291
143.85,137.43,0.292
143.87,137.63,0.292
143.89,137.83,0.292
143.91,138.03,0.292
143.93,138.22,0.292
143.95,138.43,0.292
143.97,138.63,0.292
143.99,138.83,0.292
144.01,139.03,0.292
144.03,139.23,0.292
144.05,139.43,0.293
144.07,139.63,0.293
144.09,139.83,0.293
144.11,140.03,0.293
144.13,140.23,0.293
144.15,140.43,0.293
144.17,140.63,0.293
144.19,140.83,0.293
144.21,141.03,0.294
144.23,141.23,0.294
144.25,141.43,0.294
144.27,141.63,0.294
144.29,141.83,0.294
144.31,142.03,0.294
144.33,142.23,0.294
144.35,142.43,0.294
144.37,142.63,0.295
144.39,142.83,0.295
144.41,143.03,0.295
144.43,143.23,0.295
144.45,143.43,0.295
144.47,143.63,0.295
144.49,143.83,0.295
144.51,144.03,0.296
144.53,144.23,0.296
144.55,144.43,0.296
144.57,144.63,0.296
144.59,144.83,0.296
144.61,145.03,0.296
144.63,145.23,0.296
144.65,145.43,0.296
144.67,145.63,0.296
144.69,145.83,0.297
144.71,146.03,0.297
144.73,146.23,0.297
144.75,146.43,0.297
144.77,146.63,0.297
144.79,146.83,0.297
144.81,147.03,0.297
144.83,147.23,0.297
144.85,147.43,0.297
144.87,147.63,0.298
144.89,147.83,0.298
144.91,148.03,0.298
144.93,148.23,0.298
144.95,148.43,0.298
144.97,148.63,0.298
144.99,148.83,0.298
145.01,149.03,0.299
145.03,149.23,0.299
145.05,149.43,0.299
145.07,149.63,0.299
145.09,149.83,0.299
145.11,150.03,0.299
145.13,150.23,0.300
145.15,150.43,0.300
145.17,150.63,0.300
145.19,150.83,0.300
145.21,151.03,0.300
145.23,151.23,0.300
145.25,151.43,0.300
145.27,151.63,0.300
145.29,151.83,0.301
145.31,152.03,0.301
145.33,152.23,0.301
145.35,152.43,0.301
145.37,152.63,0.301
145.39,152.83,0.301
145.41,153.04,0.301
145.43,153.24,0.301
145.45,153.44,0.302
145.47,153.64,0.302
145.49,153.84,0.302
145.51,154.04,0.302
145.53,154.24,0.302
145.55,154.44,0.303
145.57,154.64,0.303
145.59,154.84,0.303
145.61,155.04,0.303
145.63,155.24,0.303
145.65,155.44,0.303
145.67,155.64,0.303
145.69,155.84,0.303
145.71,156.04,0.304
145.73,156.24,0.304
145.75,156.44,0.304
145.77,156.64,0.304
145.79,156.84,0.304
145.81,157.04,0.304
145.83,157.24,0.304
145.85,157.44,0.305
145.87,157.64,0.305
145.89,157.84,0.305
145.91,158.04,0.305
145.93,158.24,0.305
145.95,158.44,0.306
145.97,158.64,0.306
145.99,158.84,0.306
146.01,159.04,0.306
146.03,159.24,0.306
146.05,159.44,0.306
146.07,159.64,0.307
146.09,159.84,0.307
146.11,160.04,0.307
146.13,160.24,0.307
146.15,160.44,0.307
146.17,160.64,0.308
146.19,160.84,0.308
146.21,161.04,0.308
146.23,161.24,0.308
146.25,161.44,0.308
146.27,161.64,0.309
146.29,161.84,0.309
146.31,162.04,0.309
146.33,162.24,0.309
146.35,162.44,0.309
146.37,162.64,0.310
146.39,162.84,0.310
146.41,163.04,0.310
146.43,163.24,0.311
146.45,163.44,0.311
146.47,163.64,0.311
146.49,163.84,0.311
146.51,164.04,0.311
146.53,164.24,0.311
146.55,164.44,0.312
146.57,164.64,0.312
146.59,164.84,0.312
146.61,165.04,0.312
146.63,165.25,0.313
146.65,165.45,0.313
146.67,165.65,0.313
146.69,165.85,0.314
146.71,166.05,0.314
146.73,166.25,0.314
146.75,166.45,0.315
146.77,166.65,0.315
146.79,166.85,0.315
146.81,167.05,0.316
146.83,167.25,0.316
146.85,167.45,0.316
146.87,167.65,0.317
146.89,167.85,0.317
146.91,168.05,0.317
146.93,168.25,0.318
146.95,168.45,0.318
146.97,168.65,0.319
146.99,168.84,0.319
147.01,169.04,0.319
147.03,169.24,0.320
147.05,169.44,0.320
147.07,169.64,0.320
147.09,169.84,0.321
147.11,170.04,0.322
147.13,170.24,0.322
147.15,170.45,0.323
147.17,170.64,0.323
147.19,170.84,0.324
147.21,171.04,0.324
147.23,171.24,0.325
147.25,171.45,0.326
147.27,171.64,0.326
147.29,171.84,0.327
147.31,172.04,0.327
147.33,172.24,0.328
147.35,172.44,0.329
147.37,172.64,0.330
147.39,172.84,0.331
147.41,173.04,0.332
147.43,173.24,0.332
147.45,173.44,0.333
147.47,173.64,0.334
147.49,173.84,0.335
147.51,174.04,0.336
147.53,174.24,0.337
147.55,174.44,0.338
147.57,174.64,0.340
147.59,174.84,0.342
147.61,175.04,0.342
147.63,175.24,0.344
147.65,175.44,0.345
147.67,175.64,0.348
147.69,175.84,0.349
147.71,176.04,0.351
147.73,176.24,0.352
147.75,176.44,0.354
147.77,176.64,0.356
147.79,176.84,0.357
147.81,177.04,0.358
147.83,177.25,0.360
147.85,177.45,0.363
147.87,177.65,0.366
147.89,177.85,0.368
147.91,178.05,0.369
147.93,178.25,0.370
147.95,178.45,0.370
147.97,178.65,0.371
147.99,178.85,0.371
148.01,179.05,0.371
148.03,179.25,0.371
148.05,179.45,0.372
148.07,179.65,0.372
148.09,179.85,0.372
148.11,180.05,0.372
148.13,180.25,0.372
148.15,180.45,0.372
148.17,180.65,0.372
148.19,180.85,0.372
148.21,181.05,0.372
148.23,181.25,0.371
148.25,181.45,0.371
148.27,181.65,0.371
148.29,181.85,0.371
148.31,182.05,0.370
148.33,182.25,0.370
148.35,182.45,0.370
148.37,182.65,0.369
148.39,182.85,0.369
148.41,183.05,0.369
148.43,183.25,0.368
148.45,183.45,0.368
148.47,183.65,0.368
148.49,183.85,0.367
148.51,184.05,0.367
148.53,184.25,0.367
148.55,184.45,0.367
148.57,184.65,0.367
148.59,184.85,0.366
148.61,185.05,0.366
148.63,185.25,0.366
148.65,185.45,0.366
148.67,185.65,0.366
148.69,185.85,0.365
148.71,186.05,0.365
148.73,186.25,0.365
148.75,186.45,0.365
148.77,186.65,0.365
148.79,186.85,0.365
148.81,187.05,0.365
148.83,187.25,0.365
148.85,187.45,0.364
148.87,187.65,0.364
148.89,187.85,0.364
148.91,188.05,0.364
148.93,188.25,0.364
148.95,188.45,0.364
148.97,188.65,0.364
148.99,188.85,0.364
149.01,189.05,0.364
149.03,189.25,0.364
149.05,189.45,0.364
149.07,189.65,0.364
149.09,189.85,0.364
149.11,190.05,0.364
149.13,190.25,0.365
149.15,190.45,0.365
149.17,190.65,0.365
149.19,190.85,0.365
149.21,191.05,0.365
149.23,191.25,0.365
149.25,191.45,0.365
149.27,191.65,0.365
149.29,191.85,0.365
149.31,192.05,0.365
149.33,192.25,0.365
149.35,192.45,0.366
149.37,192.65,0.366
149.39,192.85,0.366
149.41,193.05,0.366
149.43,193.25,0.366
149.45,193.45,0.366
149.47,193.65,0.366
149.49,193.85,0.366
149.51,194.05,0.366
149.53,194.25,0.366
149.55,194.45,0.366
149.57,194.65,0.366
149.59,194.85,0.367
149.61,195.05,0.367
149.63,195.25,0.367
149.65,195.45,0.367
149.67,195.65,0.367
149.69,195.85,0.367
149.71,196.05,0.367
149.73,196.25,0.367
149.75,196.45,0.367
149.77,196.65,0.368
149.79,196.85,0.368
149.81,197.05,0.368
149.83,197.25,0.368
149.85,197.45,0.368
149.87,197.65,0.368
149.89,197.85,0.368
149.91,198.05,0.368
149.93,198.25,0.368
149.95,198.46,0.368
149.97,198.66,0.369
149.99,198.86,0.369
150.01,199.06,0.369
150.03,199.26,0.369
150.05,199.46,0.369
150.07,199.66,0.369
150.09,199.86,0.369
150.11,200.06,0.369
150.13,200.26,0.370
150.15,200.46,0.370
150.17,200.66,0.370
150.19,200.86,0.370
150.21,201.06,0.370
150.23,201.26,0.370
150.25,201.46,0.370
150.27,201.66,0.370
150.29,201.86,0.370
150.31,202.06,0.370
150.33,202.26,0.370
150.35,202.46,0.371
150.37,202.66,0.371
150.39,202.86,0.371
150.41,203.06,0.371
150.43,203.26,0.371
150.45,203.46,0.371
150.47,203.66,0.371
150.49,203.86,0.371
150.51,204.06,0.372
150.53,204.26,0.372
150.55,204.46,0.372
150.57,204.66,0.372
150.59,204.86,0.372
150.61,205.06,0.372
150.63,205.26,0.372
150.65,205.46,0.372
150.67,205.66,0.372
150.69,205.86,0.372
150.71,206.06,0.372
150.73,206.26,0.372
150.75,206.46,0.372
150.77,206.66,0.372
150.79,206.86,0.372
150.81,207.06,0.372
150.83,207.26,0.372
150.85,207.46,0.373
150.87,207.66,0.373
150.89,207.86,0.373
150.91,208.06,0.373
150.93,208.26,0.373
150.95,208.46,0.373
150.97,208.66,0.373
150.99,208.86,0.373
151.01,209.06,0.373
151.03,209.26,0.373
151.05,209.46,0.373
151.07,209.66,0.374
151.09,209.86,0.374
151.11,210.06,0.374
151.13,210.26,0.374
151.15,210.46,0.374
151.17,210.66,0.374
151.19,210.86,0.374
151.21,211.06,0.374
151.23,211.26,0.374
151.25,211.46,0.375
151.27,211.66,0.375
151.29,211.86,0.375
151.31,212.06,0.375
151.33,212.26,0.375
151.35,212.46,0.375
151.37,212.66,0.375
151.39,212.86,0.375
151.41,213.06,0.375
151.43,213.26,0.375
151.45,213.46,0.375
151.47,213.66,0.375
151.49,213.86,0.375
151.51,214.06,0.375
151.53,214.26,0.375
151.55,214.46,0.376
151.57,214.67,0.376
151.59,214.86,0.376
151.61,215.06,0.376
151.63,215.27,0.376
151.65,215.47,0.376
151.67,215.67,0.376
151.69,215.87,0.376
151.71,216.07,0.377
151.73,216.27,0.377
151.75,216.47,0.377
151.77,216.67,0.377
151.79,216.87,0.377
151.81,217.07,0.377
151.83,217.27,0.377
151.85,217.47,0.377
151.87,217.67,0.377
151.89,217.87,0.377
151.91,218.07,0.377
151.93,218.27,0.377
151.95,218.47,0.377
151.97,218.67,0.378
151.99,218.87,0.378
152.01,219.07,0.378
152.03,219.27,0.378
152.05,219.47,0.378
152.07,219.67,0.378
152.09,219.87,0.378
152.11,220.07,0.378
152.13,220.27,0.378
152.15,220.47,0.378
152.17,220.67,0.378
152.19,220.87,0.378
152.21,221.07,0.379
152.23,221.27,0.379
152.25,221.47,0.379
152.27,221.67,0.379
152.29,221.87,0.379
152.31,222.07,0.379
152.33,222.27,0.379
152.35,222.47,0.379
152.37,222.67,0.379
152.39,222.87,0.379
152.41,223.07,0.379
152.43,223.27,0.380
152.45,223.47,0.380
152.47,223.67,0.380
152.49,223.87,0.380
152.51,224.07,0.380
152.53,224.27,0.380
152.55,224.47,0.380
152.57,224.67,0.380
152.59,224.87,0.380
152.61,225.07,0.380
152.63,225.27,0.381
152.65,225.47,0.381
152.67,225.67,0.381
152.69,225.87,0.381
152.71,226.07,0.381
152.73,226.27,0.381
152.75,226.47,0.381
152.77,226.67,0.381
152.79,226.87,0.381
152.81,227.07,0.381
152.83,227.27,0.381
152.85,227.47,0.381
152.87,227.67,0.381
152.89,227.87,0.381
152.91,228.07,0.381
152.93,228.27,0.382
152.95,228.47,
152.97,228.67,
152.99,,