File: DSC/Olivia/2025_08_01_CBN_n60C_110C_10Cmin_x3.csv
Filename,2025_08_01_CBN_n60C_110C_10Cmin_x3
Instrument name,DSC2A-00468 (192.168.1.100)
Operator,Yarger
rundate,8/1/2025
Sample name,2025_08_01_CBN_n60C_110C_10Cmin_x3
proceduresegments,Data Off ; Equilibrate -60.00 °C; Data On ; Ramp 10.00 °C/min to 110.00 °C; Data Off ; Isothermal 2.0 min; Data On ; Ramp 10.00 °C/min to -60.00 °C; Data Off ; Isothermal 2.0 min; Data On ; Ramp 10.00 °C/min to 110.00 °C; Data Off ; Isothermal 2.0 min; Data On ; Ramp 10.00 °C/min to -60.00 °C; Data Off ; Isothermal 2.0 min; Data On ; Ramp 10.00 °C/min to 30.00 °C
[File Parameters]
Run date,8/1/2025 5:03:11 PM
Trios version,5.1.1.46572
Original File Name,
Current File Name,D:\DSC2500\Gibbons\2025_08_01_CBN_n60C_110C_10Cmin_x3.tri
[Procedure]
Procedure Name,CBN_n60C_110C_10Cmin_x3
Sample Name,2025_08_01_CBN_n60C_110C_10Cmin_x3
Sample Mass,4.84 mg
Reference Sample Mass,0 mg
Pan Mass,32.51 mg
Pan Number,43
Reference Pan Mass,32.52 mg
Reference Pan Number,37
Pan Type,Aluminum
Comments,Thermal support Al pans/lids. DSC_Samples_A2_Tray_July2025 google sheet.
Project Name,Pharma - Cocrystals
Operator,Yarger
Test,Custom
Unload Max Temperature,30
Unload Min Temperature,30
Load Max Temperature,30
Load Min Temperature,30
Stop on Gas Flow Error,Yes
[Signal List]
Signal #1,Time (min)
Signal #2,Temperature (°C)
Signal #3,Heat Flow (mW)
Signal #4,Delta T (µV)
Signal #5,Delta Tzero (µV)
Signal #6,Tzero Temperature (°C)
Signal #7,Cell Purge (mL/min)
Signal #8,Heater Temp (°C)
Signal #9,Power Delivered (W)
Signal #10,Reference Junction Temperature (°C)
Signal #11,Flange Temperature (°C)
Signal #12,Heat Flow Phase (rad)
Signal #13,Total Heat Capacity (J/°C)
Signal #14,Heat Capacity (J/°C)
[Configuration]
Company Name,ASU
Instrument Name,DSC2A-00468
Instrument Type,DSC2500
Serial Number,DSC2A-00468
IP,192.168.1.100
Location of Instrument,MRRC
DisplayType,Unknown
Sample Interval ,0.1 s/pt
Selected Heat Flow,T4P
Exotherm Direction,Down
Cell Serial,DRC2-00792
Lid Type,Standard
Cooler,RCS 90
Leave Cooler on at End of Sequence,On
Gas 2,Nitrogen
Gas Selected,Channel 1
Flow Rate,50 mL/min
Secondary Purge,On
Licensed Heat Flow,Heat Flow T4P
Modulation Licensed,Yes
[Versions]
Common IDD Version,1
Cortex Version,VER 2.10.2.31
Driver,5.0.0.6
GDM Version,1.0.3.3
TouchscreenVersion,1.0.0.16145
FEP Version,1.2.1.21
FEP Bootloader,2.0.0.5
AutoSampler Version,2.1.1.26
Auto Sampler Bootloader,2.0.0.5
FCM Version,1.1.0.3
FCM Bootloader,2.0.0.5
[Experiment Logs]
Experiment Log Entry # 1,Air Cool is off.
Experiment Log Entry # 3,Data On set to 0
Experiment Log Entry # 5,Equilibrate Segment -60 (C) Started
Experiment Log Entry # 7,Data On set to 1
Experiment Log Entry # 9,Ramp Segment 10 C/min to 110 Started
Experiment Log Entry # 11,Data On set to 0
Experiment Log Entry # 13,Isothermal Segment 2 min started
Experiment Log Entry # 15,Data On set to 1
Experiment Log Entry # 17,Ramp Segment 10 C/min to -60 Started
Experiment Log Entry # 19,Data On set to 0
Experiment Log Entry # 21,Isothermal Segment 2 min started
Experiment Log Entry # 23,Data On set to 1
Experiment Log Entry # 25,Ramp Segment 10 C/min to 110 Started
Experiment Log Entry # 27,Data On set to 0
Experiment Log Entry # 29,Isothermal Segment 2 min started
Experiment Log Entry # 31,Data On set to 1
Experiment Log Entry # 33,Ramp Segment 10 C/min to -60 Started
Experiment Log Entry # 35,Data On set to 0
Experiment Log Entry # 37,Isothermal Segment 2 min started
Experiment Log Entry # 39,Data On set to 1
Experiment Log Entry # 41,Ramp Segment 10 C/min to 30 Started
[Method Log]
Method Log Entry # 1,Data Off
Method Log Entry # 2,Equilibrate -60 °C
Method Log Entry # 3,Data On
Method Log Entry # 4,(Ramp 1089) Ramp 10 °C/minute to 110 °C
Method Log Entry # 5,Data Off
Method Log Entry # 6,Isothermal 2 minutes
Method Log Entry # 7,Data On
Method Log Entry # 8,(Ramp 1093) Ramp 10 °C/minute to -60 °C
Method Log Entry # 9,Data Off
Method Log Entry # 10,Isothermal 2 minutes
Method Log Entry # 11,Data On
Method Log Entry # 12,(Ramp 1097) Ramp 10 °C/minute to 110 °C
Method Log Entry # 13,Data Off
Method Log Entry # 14,Isothermal 2 minutes
Method Log Entry # 15,Data On
Method Log Entry # 16,(Ramp 1101) Ramp 10 °C/minute to -60 °C
Method Log Entry # 17,Data Off
Method Log Entry # 18,Isothermal 2 minutes
Method Log Entry # 19,Data On
Method Log Entry # 20,(Ramp 1105) Ramp 10 °C/minute to 30 °C
Cell Serial,DRC2-00792
[T1 Calibration]
Slope,-0.008529666
Offset,9.636258
Initial Temperature,98.23
GUID,f8bfdadc-4977-4fdf-ba6d-0ba9134940c3
[TZero Calibration]
Date Applied,11/29/2022 4:06:13 PM
Description,From -89.059 °C to 396.009 °C at 20.000°C/min
Gas Type,Nitrogen
Pan Type,None
Source Files 1,C:\Users\yargerlab\Desktop\DSC Data\General\TZero_calibration_11_29_22_2nd(2).tri
Source Files 2,C:\Users\yargerlab\Desktop\DSC Data\General\TZero_calibration_11_29_22_2nd(3).tri
Delta T Offset,13.05235
Delta T Slope,-0.007271007
Delta T0 Offset,-13.69128
Delta T0 Slope,0.06063341
[Temperature Calibration]
Date Applied,11/29/2022 7:12:28 PM
Description,From 106.590 °C to 186.590 °C at 10.000°C/min
Gas Type,Nitrogen
Pan Type,Tzero Aluminum Hermetic
Source Files 1,C:\Users\yargerlab\Desktop\DSC Data\General\Indium(6).tri
Measured 1,157.391
Known 1,156.598
[Cell Constant Calibration]
Date Applied,11/29/2022 7:12:29 PM
Description,From 106.590 °C to 186.590 °C at 10.000°C/min
Gas Type,Nitrogen
Pan Type,Tzero Aluminum Hermetic
Source Files 1,C:\Users\yargerlab\Desktop\DSC Data\General\Indium(6).tri
T4P KCell,1.006051
Onset Slope,63.26126 mW/°C
[Direct Cp Calibration]
Date Applied,11/30/2022 11:04:51 AM
Description,From -79.983 °C to 298.409 °C at 10.000°C/min
Gas Type,Nitrogen
Pan Type,Tzero Aluminum Hermetic
Source Files 1,C:\Users\yargerlab\Desktop\DSC Data\General\Sapphire_Heat_Capacity_11_30_22.tri
[Rev Cp Calibration]
Date Applied,11/30/2022 1:58:51 PM
Description,From -79.996 °C to 292.812 °C at 3.000°C/min
Gas Type,Nitrogen
Pan Type,Tzero Aluminum Hermetic
Source Files 1,C:\Users\yargerlab\Desktop\DSC Data\General\Sapphire_MDSC_Calibration_11_30_22.tri
[step]
Ramp 10.00 °C/min to 110.00 °C
Time,Temperature,Heat Flow (Normalized)
min,°C,W/g
0.00,-59.82,-0.055
0.01,-59.82,-0.053
0.02,-59.82,-0.050
0.03,-59.82,-0.048
0.05,-59.82,-0.047
0.06,-59.81,-0.047
0.07,-59.79,-0.048
0.08,-59.77,-0.049
0.09,-59.73,-0.050
0.11,-59.68,-0.050
0.12,-59.63,-0.044
0.13,-59.56,-0.030
0.14,-59.49,-0.014
0.15,-59.41,0.000
0.16,-59.33,0.018
0.18,-59.24,0.037
0.19,-59.14,0.053
0.20,-59.04,0.071
0.21,-58.94,0.086
0.22,-58.84,0.101
0.23,-58.74,0.114
0.24,-58.63,0.126
0.26,-58.52,0.136
0.27,-58.41,0.145
0.28,-58.30,0.152
0.29,-58.19,0.160
0.30,-58.08,0.165
0.31,-57.97,0.170
0.33,-57.86,0.175
0.34,-57.75,0.177
0.35,-57.64,0.180
0.36,-57.52,0.183
0.37,-57.41,0.186
0.39,-57.30,0.188
0.40,-57.18,0.189
0.41,-57.07,0.191
0.42,-56.96,0.192
0.43,-56.84,0.193
0.44,-56.73,0.194
0.45,-56.62,0.195
0.47,-56.50,0.196
0.48,-56.39,0.197
0.49,-56.27,0.197
0.50,-56.16,0.198
0.51,-56.04,0.198
0.53,-55.93,0.199
0.54,-55.82,0.199
0.55,-55.70,0.200
0.56,-55.59,0.200
0.57,-55.47,0.200
0.58,-55.36,0.201
0.60,-55.24,0.201
0.61,-55.13,0.201
0.62,-55.01,0.202
0.63,-54.90,0.202
0.64,-54.78,0.202
0.65,-54.67,0.203
0.67,-54.55,0.203
0.68,-54.44,0.203
0.69,-54.32,0.204
0.70,-54.21,0.204
0.71,-54.09,0.204
0.72,-53.98,0.205
0.73,-53.86,0.205
0.75,-53.75,0.205
0.76,-53.63,0.205
0.77,-53.51,0.206
0.78,-53.40,0.206
0.79,-53.28,0.206
0.80,-53.17,0.206
0.82,-53.05,0.207
0.83,-52.94,0.207
0.84,-52.82,0.207
0.85,-52.71,0.208
0.86,-52.59,0.208
0.88,-52.47,0.208
0.89,-52.36,0.208
0.90,-52.24,0.209
0.91,-52.13,0.209
0.92,-52.01,0.209
0.93,-51.89,0.209
0.95,-51.78,0.210
0.96,-51.66,0.210
0.97,-51.55,0.210
0.98,-51.43,0.210
0.99,-51.31,0.210
1.00,-51.20,0.211
1.02,-51.08,0.211
1.03,-50.97,0.211
1.04,-50.85,0.211
1.05,-50.74,0.212
1.06,-50.62,0.212
1.07,-50.50,0.212
1.08,-50.39,0.212
1.10,-50.27,0.212
1.11,-50.16,0.212
1.12,-50.04,0.213
1.13,-49.92,0.213
1.14,-49.81,0.213
1.16,-49.69,0.213
1.17,-49.58,0.213
1.18,-49.46,0.213
1.19,-49.35,0.213
1.20,-49.23,0.213
1.21,-49.11,0.213
1.23,-49.00,0.214
1.24,-48.88,0.214
1.25,-48.76,0.214
1.26,-48.65,0.214
1.27,-48.53,0.214
1.28,-48.41,0.214
1.29,-48.30,0.215
1.31,-48.18,0.215
1.32,-48.06,0.215
1.33,-47.95,0.215
1.34,-47.83,0.215
1.35,-47.72,0.215
1.37,-47.60,0.215
1.38,-47.48,0.216
1.39,-47.37,0.216
1.40,-47.25,0.216
1.41,-47.13,0.216
1.42,-47.01,0.216
1.43,-46.90,0.216
1.45,-46.78,0.216
1.46,-46.67,0.217
1.47,-46.55,0.217
1.48,-46.43,0.217
1.49,-46.31,0.217
1.51,-46.20,0.217
1.52,-46.08,0.217
1.53,-45.97,0.217
1.54,-45.85,0.217
1.55,-45.73,0.218
1.56,-45.61,0.218
1.58,-45.50,0.218
1.59,-45.38,0.218
1.60,-45.26,0.218
1.61,-45.15,0.218
1.62,-45.03,0.218
1.63,-44.91,0.218
1.64,-44.80,0.218
1.66,-44.68,0.218
1.67,-44.56,0.219
1.68,-44.45,0.219
1.69,-44.33,0.219
1.70,-44.21,0.219
1.72,-44.10,0.219
1.73,-43.98,0.219
1.74,-43.86,0.219
1.75,-43.75,0.219
1.76,-43.63,0.219
1.77,-43.51,0.219
1.78,-43.40,0.219
1.80,-43.28,0.219
1.81,-43.16,0.219
1.82,-43.05,0.220
1.83,-42.93,0.220
1.84,-42.81,0.220
1.86,-42.69,0.220
1.87,-42.58,0.220
1.88,-42.46,0.220
1.89,-42.35,0.220
1.90,-42.23,0.220
1.91,-42.11,0.220
1.93,-42.00,0.220
1.94,-41.88,0.220
1.95,-41.76,0.220
1.96,-41.65,0.220
1.97,-41.53,0.220
1.98,-41.41,0.220
1.99,-41.29,0.220
2.01,-41.18,0.220
2.02,-41.06,0.221
2.03,-40.94,0.221
2.04,-40.83,0.221
2.05,-40.71,0.221
2.07,-40.59,0.221
2.08,-40.48,0.221
2.09,-40.36,0.221
2.10,-40.24,0.221
2.11,-40.13,0.221
2.12,-40.01,0.221
2.14,-39.89,0.221
2.15,-39.78,0.221
2.16,-39.66,0.221
2.17,-39.54,0.221
2.18,-39.43,0.221
2.19,-39.31,0.221
2.21,-39.19,0.221
2.22,-39.08,0.222
2.23,-38.96,0.222
2.24,-38.84,0.222
2.25,-38.73,0.222
2.26,-38.61,0.222
2.28,-38.49,0.222
2.29,-38.37,0.222
2.30,-38.26,0.222
2.31,-38.14,0.222
2.32,-38.02,0.222
2.33,-37.91,0.222
2.34,-37.79,0.222
2.36,-37.67,0.222
2.37,-37.56,0.222
2.38,-37.44,0.222
2.39,-37.32,0.222
2.40,-37.21,0.222
2.41,-37.09,0.222
2.43,-36.97,0.223
2.44,-36.85,0.223
2.45,-36.74,0.223
2.46,-36.62,0.223
2.47,-36.50,0.223
2.49,-36.39,0.223
2.50,-36.27,0.223
2.51,-36.15,0.223
2.52,-36.04,0.223
2.53,-35.92,0.223
2.54,-35.80,0.223
2.56,-35.69,0.223
2.57,-35.57,0.223
2.58,-35.45,0.223
2.59,-35.34,0.223
2.60,-35.22,0.223
2.61,-35.10,0.223
2.63,-34.98,0.223
2.64,-34.87,0.223
2.65,-34.75,0.223
2.66,-34.64,0.223
2.67,-34.52,0.223
2.68,-34.40,0.223
2.69,-34.28,0.223
2.71,-34.17,0.224
2.72,-34.05,0.224
2.73,-33.93,0.224
2.74,-33.82,0.224
2.75,-33.70,0.224
2.76,-33.58,0.224
2.78,-33.47,0.224
2.79,-33.35,0.224
2.80,-33.23,0.224
2.81,-33.12,0.224
2.82,-33.00,0.224
2.84,-32.88,0.224
2.85,-32.77,0.224
2.86,-32.65,0.224
2.87,-32.53,0.224
2.88,-32.42,0.224
2.89,-32.30,0.224
2.91,-32.18,0.224
2.92,-32.06,0.224
2.93,-31.95,0.225
2.94,-31.83,0.225
2.95,-31.71,0.225
2.96,-31.60,0.225
2.98,-31.48,0.225
2.99,-31.36,0.225
3.00,-31.25,0.225
3.01,-31.13,0.225
3.02,-31.01,0.225
3.03,-30.90,0.225
3.04,-30.78,0.225
3.06,-30.66,0.225
3.07,-30.55,0.225
3.08,-30.43,0.225
3.09,-30.31,0.225
3.10,-30.20,0.225
3.11,-30.08,0.225
3.13,-29.96,0.225
3.14,-29.84,0.225
3.15,-29.73,0.225
3.16,-29.61,0.226
3.17,-29.50,0.226
3.19,-29.38,0.226
3.20,-29.26,0.226
3.21,-29.14,0.226
3.22,-29.03,0.226
3.23,-28.91,0.226
3.24,-28.79,0.226
3.26,-28.68,0.226
3.27,-28.56,0.226
3.28,-28.44,0.226
3.29,-28.33,0.226
3.30,-28.21,0.226
3.31,-28.09,0.226
3.33,-27.97,0.226
3.34,-27.86,0.226
3.35,-27.74,0.227
3.36,-27.62,0.227
3.37,-27.51,0.227
3.38,-27.39,0.227
3.39,-27.27,0.227
3.41,-27.16,0.227
3.42,-27.04,0.227
3.43,-26.92,0.227
3.44,-26.80,0.227
3.45,-26.69,0.227
3.46,-26.57,0.227
3.48,-26.45,0.228
3.49,-26.34,0.228
3.50,-26.22,0.228
3.51,-26.10,0.228
3.52,-25.99,0.228
3.54,-25.87,0.228
3.55,-25.75,0.228
3.56,-25.64,0.228
3.57,-25.52,0.228
3.58,-25.40,0.228
3.59,-25.29,0.228
3.61,-25.17,0.228
3.62,-25.05,0.228
3.63,-24.94,0.228
3.64,-24.82,0.228
3.65,-24.70,0.228
3.66,-24.59,0.228
3.68,-24.47,0.228
3.69,-24.35,0.228
3.70,-24.24,0.228
3.71,-24.12,0.228
3.72,-24.00,0.229
3.73,-23.89,0.229
3.74,-23.77,0.229
3.76,-23.65,0.229
3.77,-23.53,0.229
3.78,-23.42,0.229
3.79,-23.30,0.229
3.80,-23.19,0.229
3.81,-23.07,0.229
3.83,-22.95,0.229
3.84,-22.84,0.229
3.85,-22.72,0.229
3.86,-22.60,0.229
3.87,-22.49,0.229
3.89,-22.37,0.229
3.90,-22.25,0.229
3.91,-22.13,0.229
3.92,-22.02,0.229
3.93,-21.90,0.230
3.94,-21.78,0.230
3.96,-21.67,0.230
3.97,-21.55,0.230
3.98,-21.43,0.230
3.99,-21.32,0.230
4.00,-21.20,0.230
4.01,-21.08,0.230
4.03,-20.97,0.230
4.04,-20.85,0.230
4.05,-20.73,0.230
4.06,-20.62,0.230
4.07,-20.50,0.230
4.08,-20.38,0.230
4.09,-20.27,0.231
4.11,-20.15,0.231
4.12,-20.03,0.231
4.13,-19.92,0.231
4.14,-19.80,0.231
4.15,-19.68,0.231
4.16,-19.57,0.231
4.18,-19.45,0.231
4.19,-19.33,0.231
4.20,-19.22,0.231
4.21,-19.10,0.231
4.22,-18.98,0.231
4.24,-18.87,0.231
4.25,-18.75,0.231
4.26,-18.63,0.231
4.27,-18.51,0.231
4.28,-18.40,0.231
4.29,-18.28,0.232
4.30,-18.16,0.232
4.32,-18.05,0.232
4.33,-17.93,0.232
4.34,-17.81,0.232
4.35,-17.70,0.232
4.36,-17.58,0.232
4.38,-17.47,0.232
4.39,-17.35,0.232
4.40,-17.23,0.232
4.41,-17.11,0.232
4.42,-17.00,0.232
4.43,-16.88,0.233
4.45,-16.76,0.233
4.46,-16.65,0.233
4.47,-16.53,0.233
4.48,-16.41,0.233
4.49,-16.30,0.233
4.50,-16.18,0.233
4.51,-16.06,0.233
4.53,-15.95,0.233
4.54,-15.83,0.233
4.55,-15.71,0.233
4.56,-15.60,0.233
4.57,-15.48,0.233
4.59,-15.36,0.233
4.60,-15.24,0.234
4.61,-15.13,0.234
4.62,-15.01,0.234
4.63,-14.90,0.234
4.64,-14.78,0.234
4.65,-14.66,0.234
4.67,-14.54,0.234
4.68,-14.43,0.234
4.69,-14.31,0.234
4.70,-14.20,0.234
4.71,-14.08,0.234
4.73,-13.96,0.234
4.74,-13.84,0.234
4.75,-13.73,0.234
4.76,-13.61,0.235
4.77,-13.49,0.235
4.78,-13.38,0.235
4.80,-13.26,0.235
4.81,-13.14,0.235
4.82,-13.03,0.235
4.83,-12.91,0.235
4.84,-12.79,0.235
4.85,-12.68,0.235
4.86,-12.56,0.235
4.88,-12.44,0.235
4.89,-12.32,0.235
4.90,-12.21,0.236
4.91,-12.09,0.236
4.92,-11.98,0.236
4.94,-11.86,0.236
4.95,-11.74,0.236
4.96,-11.62,0.236
4.97,-11.51,0.236
4.98,-11.39,0.236
4.99,-11.27,0.236
5.00,-11.16,0.236
5.02,-11.04,0.236
5.03,-10.92,0.236
5.04,-10.81,0.237
5.05,-10.69,0.237
5.06,-10.57,0.237
5.08,-10.46,0.237
5.09,-10.34,0.237
5.10,-10.22,0.237
5.11,-10.11,0.237
5.12,-9.99,0.237
5.13,-9.87,0.237
5.15,-9.76,0.237
5.16,-9.64,0.237
5.17,-9.52,0.237
5.18,-9.41,0.237
5.19,-9.29,0.237
5.20,-9.17,0.238
5.21,-9.06,0.238
5.23,-8.94,0.238
5.24,-8.82,0.238
5.25,-8.71,0.238
5.26,-8.59,0.238
5.27,-8.47,0.238
5.29,-8.36,0.238
5.30,-8.24,0.238
5.31,-8.12,0.238
5.32,-8.01,0.238
5.33,-7.89,0.238
5.34,-7.77,0.239
5.35,-7.65,0.239
5.37,-7.54,0.239
5.38,-7.42,0.239
5.39,-7.30,0.239
5.40,-7.19,0.239
5.41,-7.07,0.239
5.43,-6.95,0.239
5.44,-6.84,0.239
5.45,-6.72,0.239
5.46,-6.60,0.239
5.47,-6.49,0.239
5.48,-6.37,0.240
5.50,-6.25,0.240
5.51,-6.14,0.240
5.52,-6.02,0.240
5.53,-5.90,0.240
5.54,-5.79,0.240
5.55,-5.67,0.240
5.56,-5.55,0.240
5.58,-5.44,0.240
5.59,-5.32,0.240
5.60,-5.20,0.240
5.61,-5.09,0.240
5.62,-4.97,0.241
5.64,-4.85,0.241
5.65,-4.73,0.241
5.66,-4.62,0.241
5.67,-4.50,0.241
5.68,-4.38,0.241
5.69,-4.27,0.241
5.70,-4.15,0.241
5.72,-4.03,0.241
5.73,-3.92,0.241
5.74,-3.80,0.241
5.75,-3.68,0.242
5.76,-3.57,0.242
5.78,-3.45,0.242
5.79,-3.33,0.242
5.80,-3.22,0.242
5.81,-3.10,0.242
5.82,-2.98,0.242
5.83,-2.87,0.242
5.85,-2.75,0.242
5.86,-2.63,0.242
5.87,-2.51,0.242
5.88,-2.40,0.242
5.89,-2.28,0.243
5.90,-2.16,0.243
5.91,-2.05,0.243
5.93,-1.93,0.243
5.94,-1.81,0.243
5.95,-1.70,0.243
5.96,-1.58,0.243
5.97,-1.46,0.243
5.99,-1.35,0.243
6.00,-1.23,0.244
6.01,-1.11,0.244
6.02,-1.00,0.244
6.03,-0.88,0.244
6.04,-0.76,0.244
6.05,-0.65,0.244
6.07,-0.53,0.244
6.08,-0.41,0.244
6.09,-0.30,0.244
6.10,-0.18,0.244
6.11,-0.06,0.244
6.13,0.05,0.244
6.14,0.17,0.244
6.15,0.29,0.244
6.16,0.40,0.245
6.17,0.52,0.245
6.18,0.64,0.245
6.20,0.75,0.245
6.21,0.87,0.245
6.22,0.99,0.245
6.23,1.10,0.245
6.24,1.22,0.245
6.25,1.34,0.245
6.26,1.46,0.245
6.28,1.57,0.245
6.29,1.69,0.245
6.30,1.81,0.246
6.31,1.92,0.246
6.32,2.04,0.246
6.34,2.16,0.246
6.35,2.27,0.246
6.36,2.39,0.246
6.37,2.51,0.246
6.38,2.62,0.246
6.39,2.74,0.246
6.40,2.86,0.246
6.42,2.97,0.246
6.43,3.09,0.247
6.44,3.21,0.247
6.45,3.32,0.247
6.46,3.44,0.247
6.48,3.56,0.247
6.49,3.68,0.247
6.50,3.79,0.247
6.51,3.91,0.247
6.52,4.02,0.247
6.53,4.14,0.247
6.55,4.26,0.247
6.56,4.37,0.247
6.57,4.49,0.248
6.58,4.61,0.248
6.59,4.73,0.248
6.60,4.84,0.248
6.61,4.96,0.248
6.63,5.08,0.248
6.64,5.19,0.248
6.65,5.31,0.248
6.66,5.43,0.248
6.67,5.54,0.248
6.69,5.66,0.248
6.70,5.78,0.248
6.71,5.89,0.249
6.72,6.01,0.249
6.73,6.13,0.249
6.74,6.24,0.249
6.75,6.36,0.249
6.77,6.48,0.249
6.78,6.59,0.249
6.79,6.71,0.249
6.80,6.83,0.249
6.81,6.94,0.249
6.83,7.06,0.249
6.84,7.18,0.249
6.85,7.29,0.250
6.86,7.41,0.250
6.87,7.53,0.250
6.88,7.64,0.250
6.90,7.76,0.250
6.91,7.88,0.250
6.92,8.00,0.250
6.93,8.11,0.250
6.94,8.23,0.250
6.95,8.35,0.251
6.96,8.46,0.251
6.98,8.58,0.251
6.99,8.70,0.251
7.00,8.81,0.251
7.01,8.93,0.251
7.02,9.05,0.251
7.04,9.16,0.251
7.05,9.28,0.251
7.06,9.40,0.251
7.07,9.51,0.252
7.08,9.63,0.252
7.09,9.75,0.252
7.10,9.86,0.252
7.12,9.98,0.252
7.13,10.10,0.252
7.14,10.21,0.252
7.15,10.33,0.252
7.16,10.45,0.252
7.18,10.56,0.252
7.19,10.68,0.253
7.20,10.80,0.253
7.21,10.92,0.253
7.22,11.03,0.253
7.23,11.15,0.253
7.25,11.27,0.253
7.26,11.38,0.253
7.27,11.50,0.253
7.28,11.62,0.253
7.29,11.73,0.253
7.30,11.85,0.253
7.31,11.97,0.254
7.33,12.08,0.254
7.34,12.20,0.254
7.35,12.32,0.254
7.36,12.43,0.254
7.37,12.55,0.254
7.39,12.67,0.254
7.40,12.78,0.254
7.41,12.90,0.254
7.42,13.02,0.254
7.43,13.13,0.255
7.44,13.25,0.255
7.45,13.37,0.255
7.47,13.48,0.255
7.48,13.60,0.255
7.49,13.72,0.255
7.50,13.83,0.255
7.51,13.95,0.255
7.53,14.07,0.255
7.54,14.18,0.255
7.55,14.30,0.256
7.56,14.42,0.256
7.57,14.53,0.256
7.58,14.65,0.256
7.60,14.77,0.256
7.61,14.89,0.256
7.62,15.00,0.256
7.63,15.12,0.256
7.64,15.24,0.256
7.65,15.35,0.256
7.66,15.47,0.257
7.68,15.59,0.257
7.69,15.70,0.257
7.70,15.82,0.257
7.71,15.94,0.257
7.72,16.05,0.257
7.74,16.17,0.257
7.75,16.29,0.257
7.76,16.40,0.257
7.77,16.52,0.258
7.78,16.64,0.258
7.79,16.75,0.258
7.80,16.87,0.258
7.82,16.99,0.258
7.83,17.11,0.258
7.84,17.22,0.258
7.85,17.34,0.258
7.86,17.46,0.258
7.88,17.57,0.258
7.89,17.69,0.258
7.90,17.81,0.259
7.91,17.92,0.259
7.92,18.04,0.259
7.93,18.16,0.259
7.95,18.27,0.259
7.96,18.39,0.259
7.97,18.51,0.259
7.98,18.62,0.259
7.99,18.74,0.259
8.00,18.85,0.259
8.01,18.97,0.260
8.03,19.09,0.260
8.04,19.21,0.260
8.05,19.32,0.260
8.06,19.44,0.260
8.07,19.56,0.260
8.09,19.67,0.260
8.10,19.79,0.260
8.11,19.91,0.260
8.12,20.02,0.260
8.13,20.14,0.260
8.14,20.26,0.261
8.15,20.37,0.261
8.17,20.49,0.261
8.18,20.61,0.261
8.19,20.72,0.261
8.20,20.84,0.261
8.21,20.96,0.261
8.23,21.07,0.261
8.24,21.19,0.261
8.25,21.31,0.261
8.26,21.42,0.262
8.27,21.54,0.262
8.28,21.66,0.262
8.30,21.77,0.262
8.31,21.89,0.262
8.32,22.01,0.262
8.33,22.12,0.262
8.34,22.24,0.262
8.35,22.36,0.262
8.36,22.47,0.262
8.38,22.59,0.263
8.39,22.71,0.263
8.40,22.82,0.263
8.41,22.94,0.263
8.42,23.06,0.263
8.44,23.17,0.263
8.45,23.29,0.263
8.46,23.41,0.263
8.47,23.52,0.263
8.48,23.64,0.263
8.49,23.76,0.264
8.50,23.88,0.264
8.52,23.99,0.264
8.53,24.11,0.264
8.54,24.23,0.264
8.55,24.34,0.264
8.56,24.46,0.264
8.58,24.58,0.264
8.59,24.69,0.264
8.60,24.81,0.264
8.61,24.93,0.265
8.62,25.04,0.265
8.63,25.16,0.265
8.65,25.28,0.265
8.66,25.39,0.265
8.67,25.51,0.265
8.68,25.63,0.265
8.69,25.74,0.265
8.70,25.86,0.265
8.72,25.98,0.266
8.73,26.09,0.266
8.74,26.21,0.266
8.75,26.33,0.266
8.76,26.44,0.266
8.77,26.56,0.266
8.78,26.68,0.266
8.80,26.79,0.266
8.81,26.91,0.266
8.82,27.03,0.266
8.83,27.14,0.267
8.84,27.26,0.267
8.85,27.38,0.267
8.87,27.49,0.267
8.88,27.61,0.267
8.89,27.73,0.267
8.90,27.85,0.267
8.91,27.96,0.267
8.93,28.08,0.268
8.94,28.20,0.268
8.95,28.31,0.268
8.96,28.43,0.268
8.97,28.55,0.268
8.98,28.66,0.268
9.00,28.78,0.268
9.01,28.90,0.268
9.02,29.01,0.268
9.03,29.13,0.268
9.04,29.25,0.268
9.05,29.36,0.269
9.07,29.48,0.269
9.08,29.60,0.269
9.09,29.71,0.269
9.10,29.83,0.269
9.11,29.95,0.269
9.12,30.07,0.269
9.13,30.18,0.269
9.15,30.30,0.269
9.16,30.42,0.270
9.17,30.53,0.270
9.18,30.65,0.270
9.19,30.77,0.270
9.20,30.88,0.270
9.22,31.00,0.270
9.23,31.12,0.270
9.24,31.23,0.270
9.25,31.35,0.270
9.26,31.47,0.270
9.28,31.58,0.271
9.29,31.70,0.271
9.30,31.82,0.271
9.31,31.93,0.271
9.32,32.05,0.271
9.33,32.17,0.271
9.35,32.28,0.271
9.36,32.40,0.271
9.37,32.52,0.271
9.38,32.63,0.271
9.39,32.75,0.271
9.40,32.87,0.271
9.42,32.98,0.272
9.43,33.10,0.272
9.44,33.22,0.272
9.45,33.33,0.272
9.46,33.45,0.272
9.47,33.57,0.272
9.48,33.68,0.272
9.50,33.80,0.272
9.51,33.92,0.272
9.52,34.03,0.272
9.53,34.15,0.272
9.54,34.27,0.273
9.55,34.38,0.273
9.57,34.50,0.273
9.58,34.62,0.273
9.59,34.74,0.273
9.60,34.85,0.273
9.61,34.97,0.273
9.63,35.09,0.273
9.64,35.20,0.273
9.65,35.32,0.274
9.66,35.44,0.274
9.67,35.55,0.274
9.68,35.67,0.274
9.70,35.79,0.274
9.71,35.90,0.274
9.72,36.02,0.274
9.73,36.14,0.274
9.74,36.26,0.274
9.75,36.37,0.275
9.77,36.49,0.275
9.78,36.61,0.275
9.79,36.72,0.275
9.80,36.84,0.275
9.81,36.96,0.275
9.82,37.07,0.275
9.83,37.19,0.275
9.85,37.31,0.275
9.86,37.42,0.275
9.87,37.54,0.276
9.88,37.66,0.276
9.89,37.77,0.276
9.90,37.89,0.276
9.92,38.01,0.276
9.93,38.12,0.276
9.94,38.24,0.276
9.95,38.36,0.276
9.96,38.47,0.276
9.98,38.59,0.276
9.99,38.71,0.276
10.00,38.82,0.277
10.01,38.94,0.277
10.02,39.06,0.277
10.03,39.17,0.277
10.05,39.29,0.277
10.06,39.41,0.277
10.07,39.52,0.277
10.08,39.64,0.277
10.09,39.76,0.277
10.10,39.88,0.277
10.12,39.99,0.278
10.13,40.11,0.278
10.14,40.23,0.278
10.15,40.34,0.278
10.16,40.46,0.278
10.17,40.57,0.278
10.18,40.69,0.278
10.20,40.81,0.278
10.21,40.92,0.278
10.22,41.04,0.278
10.23,41.16,0.278
10.24,41.28,0.279
10.25,41.39,0.279
10.27,41.51,0.279
10.28,41.63,0.279
10.29,41.74,0.279
10.30,41.86,0.279
10.31,41.98,0.279
10.33,42.09,0.279
10.34,42.21,0.279
10.35,42.33,0.280
10.36,42.44,0.280
10.37,42.56,0.280
10.38,42.68,0.280
10.40,42.79,0.280
10.41,42.91,0.280
10.42,43.03,0.280
10.43,43.14,0.280
10.44,43.26,0.280
10.45,43.38,0.280
10.47,43.50,0.280
10.48,43.61,0.281
10.49,43.73,0.281
10.50,43.85,0.281
10.51,43.96,0.281
10.52,44.08,0.281
10.53,44.20,0.281
10.55,44.31,0.281
10.56,44.43,0.281
10.57,44.55,0.281
10.58,44.66,0.281
10.59,44.78,0.282
10.60,44.90,0.282
10.62,45.01,0.282
10.63,45.13,0.282
10.64,45.25,0.282
10.65,45.36,0.282
10.66,45.48,0.282
10.68,45.60,0.282
10.69,45.71,0.282
10.70,45.83,0.282
10.71,45.95,0.283
10.72,46.06,0.283
10.73,46.18,0.283
10.75,46.30,0.283
10.76,46.41,0.283
10.77,46.53,0.283
10.78,46.65,0.283
10.79,46.76,0.283
10.80,46.88,0.283
10.82,47.00,0.283
10.83,47.11,0.284
10.84,47.23,0.284
10.85,47.35,0.284
10.86,47.47,0.284
10.87,47.58,0.284
10.88,47.70,0.284
10.90,47.82,0.284
10.91,47.93,0.284
10.92,48.05,0.284
10.93,48.17,0.285
10.94,48.28,0.285
10.95,48.40,0.285
10.97,48.52,0.285
10.98,48.63,0.285
10.99,48.75,0.285
11.00,48.87,0.285
11.01,48.98,0.285
11.03,49.10,0.285
11.04,49.22,0.285
11.05,49.33,0.285
11.06,49.45,0.286
11.07,49.57,0.286
11.08,49.68,0.286
11.10,49.80,0.286
11.11,49.92,0.286
11.12,50.03,0.286
11.13,50.15,0.286
11.14,50.27,0.286
11.15,50.38,0.286
11.17,50.50,0.286
11.18,50.62,0.286
11.19,50.73,0.287
11.20,50.85,0.287
11.21,50.97,0.287
11.22,51.09,0.287
11.23,51.20,0.287
11.25,51.32,0.287
11.26,51.44,0.287
11.27,51.55,0.287
11.28,51.67,0.287
11.29,51.79,0.287
11.30,51.90,0.288
11.32,52.02,0.288
11.33,52.14,0.288
11.34,52.25,0.288
11.35,52.37,0.288
11.36,52.49,0.288
11.38,52.61,0.288
11.39,52.73,0.288
11.40,52.84,0.288
11.41,52.96,0.289
11.42,53.08,0.289
11.43,53.20,0.289
11.45,53.31,0.289
11.46,53.43,0.289
11.47,53.55,0.290
11.48,53.66,0.290
11.49,53.78,0.290
11.50,53.90,0.290
11.52,54.01,0.290
11.53,54.13,0.290
11.54,54.24,0.290
11.55,54.36,0.290
11.56,54.48,0.290
11.57,54.60,0.290
11.58,54.71,0.290
11.60,54.83,0.290
11.61,54.94,0.291
11.62,55.06,0.291
11.63,55.18,0.291
11.64,55.29,0.291
11.65,55.41,0.291
11.67,55.53,0.291
11.68,55.64,0.291
11.69,55.76,0.291
11.70,55.88,0.291
11.71,55.99,0.291
11.73,56.11,0.291
11.74,56.23,0.291
11.75,56.34,0.291
11.76,56.46,0.291
11.77,56.58,0.292
11.78,56.69,0.292
11.80,56.81,0.292
11.81,56.93,0.292
11.82,57.04,0.292
11.83,57.16,0.292
11.84,57.28,0.292
11.85,57.39,0.292
11.87,57.51,0.292
11.88,57.63,0.292
11.89,57.74,0.292
11.90,57.86,0.293
11.91,57.98,0.293
11.92,58.09,0.293
11.93,58.21,0.293
11.95,58.33,0.293
11.96,58.44,0.293
11.97,58.56,0.293
11.98,58.68,0.293
11.99,58.79,0.293
12.00,58.91,0.294
12.02,59.03,0.294
12.03,59.15,0.294
12.04,59.26,0.294
12.05,59.38,0.294
12.06,59.49,0.294
12.08,59.61,0.294
12.09,59.73,0.294
12.10,59.84,0.294
12.11,59.96,0.295
12.12,60.08,0.295
12.13,60.19,0.295
12.15,60.31,0.295
12.16,60.43,0.295
12.17,60.54,0.295
12.18,60.66,0.295
12.19,60.78,0.295
12.20,60.89,0.296
12.22,61.01,0.296
12.23,61.13,0.296
12.24,61.24,0.296
12.25,61.36,0.296
12.26,61.48,0.296
12.27,61.59,0.296
12.28,61.71,0.296
12.30,61.83,0.297
12.31,61.94,0.297
12.32,62.06,0.297
12.33,62.18,0.297
12.34,62.30,0.297
12.35,62.41,0.297
12.37,62.53,0.298
12.38,62.65,0.298
12.39,62.76,0.298
12.40,62.88,0.298
12.41,62.99,0.298
12.43,63.11,0.298
12.44,63.23,0.299
12.45,63.35,0.299
12.46,63.46,0.299
12.47,63.58,0.299
12.48,63.70,0.299
12.50,63.81,0.300
12.51,63.93,0.300
12.52,64.05,0.300
12.53,64.16,0.300
12.54,64.28,0.300
12.55,64.40,0.300
12.57,64.51,0.301
12.58,64.63,0.301
12.59,64.75,0.301
12.60,64.86,0.301
12.61,64.98,0.302
12.62,65.10,0.302
12.63,65.21,0.302
12.65,65.33,0.302
12.66,65.45,0.303
12.67,65.56,0.303
12.68,65.68,0.303
12.69,65.80,0.303
12.70,65.91,0.304
12.72,66.03,0.304
12.73,66.15,0.304
12.74,66.26,0.304
12.75,66.38,0.305
12.76,66.50,0.305
12.78,66.61,0.305
12.79,66.73,0.305
12.80,66.85,0.306
12.81,66.96,0.306
12.82,67.08,0.306
12.83,67.20,0.307
12.85,67.31,0.307
12.86,67.43,0.307
12.87,67.55,0.308
12.88,67.66,0.308
12.89,67.78,0.309
12.90,67.90,0.309
12.92,68.01,0.310
12.93,68.13,0.310
12.94,68.25,0.311
12.95,68.36,0.311
12.96,68.48,0.312
12.97,68.59,0.313
12.98,68.71,0.313
13.00,68.83,0.314
13.01,68.94,0.315
13.02,69.06,0.316
13.03,69.18,0.317
13.04,69.29,0.319
13.05,69.41,0.320
13.07,69.53,0.322
13.08,69.64,0.323
13.09,69.76,0.324
13.10,69.88,0.326
13.11,69.99,0.328
13.13,70.11,0.330
13.14,70.23,0.332
13.15,70.34,0.334
13.16,70.46,0.337
13.17,70.58,0.338
13.18,70.69,0.341
13.20,70.81,0.343
13.21,70.92,0.346
13.22,71.04,0.350
13.23,71.16,0.353
13.24,71.27,0.355
13.25,71.39,0.358
13.27,71.50,0.362
13.28,71.62,0.366
13.29,71.74,0.371
13.30,71.85,0.375
13.31,71.97,0.380
13.32,72.08,0.386
13.33,72.20,0.392
13.35,72.31,0.399
13.36,72.43,0.406
13.37,72.54,0.413
13.38,72.66,0.422
13.39,72.77,0.431
13.40,72.89,0.442
13.42,73.00,0.454
13.43,73.11,0.467
13.44,73.23,0.481
13.45,73.34,0.499
13.46,73.45,0.518
13.48,73.56,0.540
13.49,73.67,0.566
13.50,73.78,0.594
13.51,73.89,0.627
13.52,74.00,0.665
13.53,74.11,0.707
13.55,74.22,0.758
13.56,74.32,0.817
13.57,74.42,0.884
13.58,74.52,0.960
13.59,74.62,1.047
13.60,74.71,1.147
13.62,74.81,1.256
13.63,74.89,1.377
13.64,74.98,1.501
13.65,75.06,1.641
13.66,75.14,1.779
13.67,75.22,1.926
13.68,75.30,2.076
13.70,75.37,2.227
13.71,75.44,2.381
13.72,75.52,2.535
13.73,75.59,2.682
13.74,75.66,2.828
13.75,75.73,2.968
13.77,75.80,3.104
13.78,75.87,3.232
13.79,75.95,3.349
13.80,76.03,3.451
13.81,76.11,3.535
13.83,76.19,3.599
13.84,76.28,3.639
13.85,76.37,3.660
13.86,76.47,3.659
13.87,76.58,3.644
13.88,76.69,3.614
13.90,76.80,3.567
13.91,76.92,3.504
13.92,77.05,3.427
13.93,77.18,3.332
13.94,77.32,3.220
13.95,77.46,3.096
13.97,77.60,2.956
13.98,77.75,2.806
13.99,77.91,2.646
14.00,78.06,2.478
14.01,78.23,2.305
14.02,78.39,2.130
14.03,78.56,1.953
14.05,78.72,1.786
14.06,78.89,1.626
14.07,79.06,1.473
14.08,79.22,1.331
14.09,79.39,1.205
14.10,79.55,1.090
14.12,79.71,0.993
14.13,79.86,0.905
14.14,80.01,0.835
14.15,80.16,0.766
14.16,80.30,0.705
14.18,80.45,0.653
14.19,80.58,0.611
14.20,80.72,0.575
14.21,80.86,0.543
14.22,80.99,0.518
14.23,81.12,0.496
14.25,81.24,0.477
14.26,81.37,0.461
14.27,81.50,0.448
14.28,81.62,0.436
14.29,81.74,0.425
14.30,81.87,0.417
14.32,81.99,0.410
14.33,82.11,0.403
14.34,82.23,0.397
14.35,82.35,0.394
14.36,82.47,0.389
14.37,82.59,0.385
14.38,82.70,0.382
14.40,82.82,0.380
14.41,82.94,0.377
14.42,83.06,0.376
14.43,83.18,0.375
14.44,83.29,0.374
14.45,83.41,0.373
14.47,83.53,0.372
14.48,83.65,0.371
14.49,83.76,0.370
14.50,83.88,0.370
14.51,84.00,0.369
14.53,84.12,0.369
14.54,84.23,0.369
14.55,84.35,0.368
14.56,84.47,0.368
14.57,84.58,0.368
14.58,84.70,0.368
14.60,84.82,0.367
14.61,84.94,0.367
14.62,85.05,0.367
14.63,85.17,0.367
14.64,85.29,0.367
14.65,85.40,0.367
14.67,85.52,0.366
14.68,85.64,0.366
14.69,85.75,0.366
14.70,85.87,0.366
14.71,85.99,0.366
14.72,86.10,0.366
14.73,86.22,0.366
14.75,86.34,0.366
14.76,86.45,0.365
14.77,86.57,0.365
14.78,86.69,0.365
14.79,86.80,0.365
14.80,86.92,0.365
14.82,87.04,0.365
14.83,87.15,0.365
14.84,87.27,0.365
14.85,87.39,0.365
14.86,87.50,0.365
14.88,87.62,0.365
14.89,87.74,0.365
14.90,87.85,0.365
14.91,87.97,0.365
14.92,88.09,0.365
14.93,88.20,0.365
14.95,88.32,0.365
14.96,88.44,0.364
14.97,88.55,0.364
14.98,88.67,0.364
14.99,88.79,0.364
15.00,88.90,0.364
15.02,89.02,0.365
15.03,89.14,0.365
15.04,89.25,0.365
15.05,89.37,0.364
15.06,89.49,0.365
15.07,89.60,0.365
15.08,89.72,0.365
15.10,89.84,0.365
15.11,89.95,0.365
15.12,90.07,0.365
15.13,90.19,0.365
15.14,90.31,0.365
15.15,90.42,0.365
15.17,90.54,0.365
15.18,90.66,0.365
15.19,90.77,0.365
15.20,90.89,0.365
15.21,91.01,0.365
15.23,91.12,0.365
15.24,91.24,0.365
15.25,91.36,0.365
15.26,91.47,0.365
15.27,91.59,0.365
15.28,91.71,0.365
15.30,91.82,0.365
15.31,91.94,0.365
15.32,92.06,0.365
15.33,92.17,0.365
15.34,92.29,0.366
15.35,92.41,0.366
15.37,92.52,0.366
15.38,92.64,0.366
15.39,92.76,0.366
15.40,92.87,0.366
15.41,92.99,0.366
15.42,93.11,0.366
15.43,93.23,0.366
15.45,93.34,0.366
15.46,93.46,0.366
15.47,93.57,0.366
15.48,93.69,0.366
15.49,93.81,0.366
15.50,93.92,0.366
15.52,94.04,0.366
15.53,94.16,0.366
15.54,94.28,0.366
15.55,94.39,0.366
15.56,94.51,0.367
15.58,94.63,0.367
15.59,94.74,0.367
15.60,94.86,0.367
15.61,94.98,0.367
15.62,95.09,0.367
15.63,95.21,0.367
15.65,95.33,0.367
15.66,95.44,0.367
15.67,95.56,0.367
15.68,95.68,0.367
15.69,95.79,0.367
15.70,95.91,0.367
15.72,96.03,0.367
15.73,96.14,0.367
15.74,96.26,0.367
15.75,96.38,0.367
15.76,96.49,0.367
15.77,96.61,0.367
15.78,96.73,0.367
15.80,96.84,0.368
15.81,96.96,0.368
15.82,97.08,0.368
15.83,97.19,0.368
15.84,97.31,0.368
15.85,97.43,0.368
15.87,97.54,0.368
15.88,97.66,0.368
15.89,97.78,0.368
15.90,97.89,0.368
15.91,98.01,0.368
15.93,98.13,0.368
15.94,98.24,0.368
15.95,98.36,0.368
15.96,98.48,0.368
15.97,98.60,0.368
15.98,98.71,0.369
16.00,98.83,0.369
16.01,98.95,0.369
16.02,99.06,0.369
16.03,99.18,0.369
16.04,99.30,0.369
16.05,99.41,0.369
16.07,99.53,0.369
16.08,99.65,0.369
16.09,99.76,0.369
16.10,99.88,0.369
16.11,100.00,0.369
16.12,100.11,0.369
16.13,100.23,0.369
16.15,100.35,0.369
16.16,100.46,0.369
16.17,100.58,0.369
16.18,100.70,0.369
16.19,100.81,0.369
16.20,100.93,0.370
16.22,101.05,0.370
16.23,101.16,0.370
16.24,101.28,0.370
16.25,101.40,0.370
16.26,101.51,0.370
16.28,101.63,0.370
16.29,101.75,0.370
16.30,101.86,0.370
16.31,101.98,0.370
16.32,102.10,0.370
16.33,102.21,0.370
16.35,102.33,0.370
16.36,102.45,0.370
16.37,102.56,0.370
16.38,102.68,0.370
16.39,102.80,0.370
16.40,102.91,0.371
16.42,103.03,0.371
16.43,103.15,0.371
16.44,103.26,0.371
16.45,103.38,0.371
16.46,103.50,0.371
16.47,103.62,0.371
16.48,103.73,0.371
16.50,103.85,0.371
16.51,103.96,0.371
16.52,104.08,0.371
16.53,104.20,0.371
16.54,104.32,0.371
16.55,104.43,0.371
16.57,104.55,0.372
16.58,104.67,0.372
16.59,104.78,0.372
16.60,104.90,0.372
16.61,105.02,0.372
16.63,105.13,0.372
16.64,105.25,0.372
16.65,105.37,0.372
16.66,105.48,0.372
16.67,105.60,0.372
16.68,105.72,0.372
16.70,105.83,0.372
16.71,105.95,0.372
16.72,106.07,0.372
16.73,106.18,0.373
16.74,106.30,0.373
16.75,106.42,0.373
16.77,106.54,0.373
16.78,106.65,0.373
16.79,106.77,0.373
16.80,106.89,0.399
16.81,107.00,0.394
16.82,107.12,0.391
16.83,107.23,0.390
16.85,107.35,0.389
16.86,107.47,0.388
16.87,107.58,0.387
16.88,107.70,0.387
16.89,107.82,0.386
16.90,107.93,0.386
16.92,108.05,0.385
16.93,108.17,0.385
16.94,108.29,
16.95,108.40,
16.96,108.52,
16.98,108.64,
16.99,,
16.99,,

[step]
Ramp 10.00 °C/min to -60.00 °C
Time,Temperature,Heat Flow (Normalized)
min,°C,W/g
18.99,110.14,-0.028
19.01,110.14,-0.028
19.02,110.14,-0.028
19.03,110.13,-0.028
19.04,110.12,-0.028
19.05,110.11,-0.028
19.07,110.09,-0.027
19.08,110.06,-0.028
19.09,110.02,-0.044
19.10,109.97,-0.068
19.11,109.90,-0.099
19.12,109.83,-0.133
19.13,109.75,-0.171
19.15,109.67,-0.207
19.16,109.58,-0.239
19.17,109.48,-0.269
19.18,109.38,-0.293
19.19,109.29,-0.313
19.21,109.18,-0.327
19.22,109.08,-0.342
19.23,108.98,-0.352
19.24,108.87,-0.362
19.25,108.76,-0.370
19.26,108.65,-0.377
19.28,108.54,-0.384
19.29,108.43,-0.390
19.30,108.32,-0.396
19.31,108.21,-0.399
19.32,108.10,-0.404
19.33,107.99,-0.407
19.34,107.87,-0.410
19.36,107.76,-0.413
19.37,107.64,-0.415
19.38,107.53,-0.417
19.39,107.42,-0.417
19.40,107.30,-0.418
19.42,107.19,-0.420
19.43,107.07,-0.421
19.44,106.96,-0.422
19.45,106.84,-0.423
19.46,106.73,-0.423
19.47,106.61,-0.424
19.48,106.50,-0.424
19.50,106.38,-0.425
19.51,106.27,-0.425
19.52,106.15,-0.426
19.53,106.03,-0.426
19.54,105.92,-0.427
19.56,105.80,-0.427
19.57,105.69,-0.427
19.58,105.57,-0.427
19.59,105.46,-0.428
19.60,105.34,-0.428
19.61,105.22,-0.428
19.63,105.11,-0.428
19.64,104.99,-0.428
19.65,104.88,-0.429
19.66,104.76,-0.429
19.67,104.65,-0.429
19.68,104.53,-0.429
19.69,104.41,-0.429
19.71,104.30,-0.430
19.72,104.18,-0.430
19.73,104.06,-0.430
19.74,103.95,-0.430
19.75,103.83,-0.430
19.77,103.72,-0.430
19.78,103.60,-0.431
19.79,103.48,-0.431
19.80,103.37,-0.431
19.81,103.25,-0.431
19.82,103.14,-0.431
19.83,103.02,-0.431
19.85,102.90,-0.431
19.86,102.79,-0.431
19.87,102.67,-0.431
19.88,102.56,-0.432
19.89,102.44,-0.432
19.91,102.32,-0.432
19.92,102.21,-0.432
19.93,102.09,-0.432
19.94,101.97,-0.432
19.95,101.86,-0.432
19.96,101.74,-0.432
19.98,101.63,-0.432
19.99,101.51,-0.432
20.00,101.39,-0.432
20.01,101.28,-0.432
20.02,101.16,-0.433
20.03,101.04,-0.433
20.04,100.93,-0.433
20.06,100.81,-0.433
20.07,100.69,-0.433
20.08,100.58,-0.433
20.09,100.46,-0.433
20.10,100.35,-0.433
20.12,100.23,-0.433
20.13,100.11,-0.433
20.14,100.00,-0.433
20.15,99.88,-0.433
20.16,99.76,-0.433
20.17,99.65,-0.433
20.18,99.53,-0.433
20.20,99.42,-0.433
20.21,99.30,-0.433
20.22,99.18,-0.433
20.23,99.07,-0.433
20.24,98.95,-0.433
20.26,98.83,-0.433
20.27,98.72,-0.433
20.28,98.60,-0.433
20.29,98.48,-0.433
20.30,98.37,-0.433
20.31,98.25,-0.433
20.33,98.13,-0.433
20.34,98.02,-0.433
20.35,97.90,-0.433
20.36,97.78,-0.433
20.37,97.67,-0.433
20.38,97.55,-0.433
20.39,97.43,-0.433
20.41,97.32,-0.433
20.42,97.20,-0.433
20.43,97.08,-0.433
20.44,96.97,-0.433
20.45,96.85,-0.433
20.47,96.74,-0.433
20.48,96.62,-0.433
20.49,96.50,-0.433
20.50,96.39,-0.433
20.51,96.27,-0.433
20.52,96.15,-0.433
20.53,96.04,-0.433
20.55,95.92,-0.433
20.56,95.80,-0.432
20.57,95.69,-0.432
20.58,95.57,-0.432
20.59,95.45,-0.432
20.61,95.34,-0.432
20.62,95.22,-0.432
20.63,95.10,-0.432
20.64,94.99,-0.432
20.65,94.87,-0.432
20.66,94.75,-0.432
20.68,94.64,-0.432
20.69,94.52,-0.432
20.70,94.40,-0.432
20.71,94.29,-0.432
20.72,94.17,-0.432
20.73,94.05,-0.432
20.74,93.94,-0.432
20.76,93.82,-0.432
20.77,93.70,-0.432
20.78,93.59,-0.432
20.79,93.47,-0.432
20.80,93.36,-0.432
20.82,93.24,-0.431
20.83,93.12,-0.431
20.84,93.01,-0.431
20.85,92.89,-0.431
20.86,92.77,-0.431
20.87,92.65,-0.431
20.88,92.54,-0.431
20.90,92.42,-0.431
20.91,92.31,-0.431
20.92,92.19,-0.431
20.93,92.07,-0.431
20.94,91.95,-0.431
20.96,91.84,-0.431
20.97,91.72,-0.431
20.98,91.61,-0.431
20.99,91.49,-0.430
21.00,91.37,-0.430
21.01,91.26,-0.430
21.03,91.14,-0.430
21.04,91.02,-0.430
21.05,90.91,-0.430
21.06,90.79,-0.430
21.07,90.67,-0.430
21.08,90.56,-0.430
21.09,90.44,-0.430
21.11,90.32,-0.430
21.12,90.21,-0.430
21.13,90.09,-0.430
21.14,89.97,-0.430
21.15,89.86,-0.430
21.17,89.74,-0.430
21.18,89.62,-0.429
21.19,89.51,-0.429
21.20,89.39,-0.429
21.21,89.27,-0.429
21.22,89.16,-0.429
21.23,89.04,-0.429
21.25,88.92,-0.429
21.26,88.81,-0.429
21.27,88.69,-0.429
21.28,88.57,-0.429
21.29,88.46,-0.429
21.31,88.34,-0.429
21.32,88.22,-0.429
21.33,88.11,-0.429
21.34,87.99,-0.428
21.35,87.87,-0.428
21.36,87.76,-0.428
21.38,87.64,-0.428
21.39,87.52,-0.428
21.40,87.41,-0.428
21.41,87.29,-0.428
21.42,87.17,-0.428
21.43,87.06,-0.428
21.44,86.94,-0.428
21.46,86.82,-0.428
21.47,86.71,-0.428
21.48,86.59,-0.428
21.49,86.47,-0.428
21.50,86.36,-0.427
21.52,86.24,-0.427
21.53,86.12,-0.427
21.54,86.01,-0.427
21.55,85.89,-0.427
21.56,85.77,-0.427
21.57,85.66,-0.427
21.58,85.54,-0.427
21.60,85.42,-0.427
21.61,85.31,-0.427
21.62,85.19,-0.427
21.63,85.08,-0.427
21.64,84.96,-0.427
21.66,84.84,-0.427
21.67,84.73,-0.427
21.68,84.61,-0.427
21.69,84.49,-0.427
21.70,84.38,-0.427
21.71,84.26,-0.427
21.73,84.14,-0.426
21.74,84.03,-0.426
21.75,83.91,-0.426
21.76,83.79,-0.426
21.77,83.68,-0.426
21.78,83.56,-0.426
21.79,83.44,-0.426
21.81,83.33,-0.426
21.82,83.21,-0.426
21.83,83.09,-0.426
21.84,82.98,-0.426
21.85,82.86,-0.426
21.87,82.74,-0.426
21.88,82.63,-0.426
21.89,82.51,-0.426
21.90,82.39,-0.426
21.91,82.28,-0.426
21.92,82.16,-0.426
21.93,82.04,-0.426
21.95,81.92,-0.426
21.96,81.81,-0.426
21.97,81.69,-0.426
21.98,81.57,-0.426
21.99,81.46,-0.426
22.01,81.34,-0.426
22.02,81.22,-0.426
22.03,81.11,-0.426
22.04,80.99,-0.426
22.05,80.87,-0.426
22.06,80.76,-0.426
22.08,80.64,-0.426
22.09,80.52,-0.426
22.10,80.41,-0.426
22.11,80.29,-0.426
22.12,80.18,-0.426
22.13,80.06,-0.426
22.14,79.94,-0.426
22.16,79.83,-0.426
22.17,79.71,-0.426
22.18,79.59,-0.425
22.19,79.48,-0.425
22.20,79.36,-0.425
22.22,79.24,-0.425
22.23,79.13,-0.425
22.24,79.01,-0.425
22.25,78.90,-0.425
22.26,78.78,-0.425
22.27,78.66,-0.425
22.28,78.55,-0.425
22.30,78.43,-0.425
22.31,78.31,-0.425
22.32,78.20,-0.425
22.33,78.08,-0.425
22.34,77.96,-0.425
22.36,77.84,-0.425
22.37,77.73,-0.425
22.38,77.61,-0.425
22.39,77.49,-0.425
22.40,77.38,-0.425
22.41,77.26,-0.425
22.43,77.14,-0.425
22.44,77.03,-0.425
22.45,76.91,-0.425
22.46,76.79,-0.424
22.47,76.68,-0.424
22.48,76.56,-0.424
22.49,76.44,-0.424
22.51,76.33,-0.424
22.52,76.21,-0.424
22.53,76.09,-0.424
22.54,75.98,-0.424
22.55,75.86,-0.424
22.57,75.74,-0.424
22.58,75.63,-0.424
22.59,75.51,-0.424
22.60,75.39,-0.424
22.61,75.28,-0.424
22.62,75.16,-0.424
22.63,75.05,-0.424
22.65,74.93,-0.424
22.66,74.81,-0.424
22.67,74.69,-0.423
22.68,74.58,-0.423
22.69,74.46,-0.423
22.71,74.34,-0.423
22.72,74.23,-0.423
22.73,74.11,-0.423
22.74,74.00,-0.423
22.75,73.88,-0.423
22.76,73.76,-0.423
22.78,73.65,-0.423
22.79,73.53,-0.423
22.80,73.41,-0.423
22.81,73.30,-0.423
22.82,73.18,-0.423
22.83,73.06,-0.423
22.84,72.95,-0.423
22.86,72.83,-0.423
22.87,72.71,-0.423
22.88,72.59,-0.423
22.89,72.48,-0.423
22.90,72.36,-0.422
22.92,72.24,-0.422
22.93,72.13,-0.422
22.94,72.01,-0.422
22.95,71.90,-0.422
22.96,71.78,-0.422
22.97,71.66,-0.422
22.98,71.54,-0.422
23.00,71.43,-0.422
23.01,71.31,-0.422
23.02,71.20,-0.422
23.03,71.08,-0.422
23.04,70.96,-0.422
23.06,70.85,-0.422
23.07,70.73,-0.422
23.08,70.61,-0.421
23.09,70.50,-0.421
23.10,70.38,-0.421
23.11,70.26,-0.421
23.13,70.15,-0.421
23.14,70.03,-0.421
23.15,69.91,-0.421
23.16,69.80,-0.421
23.17,69.68,-0.421
23.18,69.56,-0.421
23.19,69.45,-0.421
23.21,69.33,-0.421
23.22,69.21,-0.421
23.23,69.10,-0.421
23.24,68.98,-0.421
23.25,68.86,-0.421
23.27,68.75,-0.421
23.28,68.63,-0.421
23.29,68.51,-0.420
23.30,68.40,-0.420
23.31,68.28,-0.420
23.32,68.16,-0.420
23.33,68.05,-0.420
23.35,67.93,-0.420
23.36,67.81,-0.420
23.37,67.70,-0.420
23.38,67.58,-0.420
23.39,67.47,-0.420
23.41,67.35,-0.420
23.42,67.23,-0.420
23.43,67.11,-0.420
23.44,67.00,-0.420
23.45,66.88,-0.420
23.46,66.76,-0.420
23.48,66.65,-0.420
23.49,66.53,-0.420
23.50,66.42,-0.419
23.51,66.30,-0.419
23.52,66.18,-0.419
23.53,66.07,-0.419
23.54,65.95,-0.419
23.56,65.83,-0.419
23.57,65.72,-0.419
23.58,65.60,-0.419
23.59,65.48,-0.419
23.60,65.37,-0.419
23.62,65.25,-0.419
23.63,65.13,-0.419
23.64,65.02,-0.419
23.65,64.90,-0.419
23.66,64.78,-0.419
23.67,64.67,-0.419
23.68,64.55,-0.419
23.70,64.43,-0.419
23.71,64.32,-0.418
23.72,64.20,-0.418
23.73,64.08,-0.418
23.74,63.97,-0.418
23.76,63.85,-0.418
23.77,63.73,-0.418
23.78,63.62,-0.418
23.79,63.50,-0.418
23.80,63.38,-0.418
23.81,63.27,-0.418
23.83,63.15,-0.418
[...]
77.71,-44.18,0.225
77.72,-44.11,0.225
77.73,-44.04,0.225
77.74,-43.97,0.225
77.74,-43.91,0.225
77.75,-43.84,0.225
77.75,-43.78,0.225
77.76,-43.71,0.225
77.77,-43.64,0.225
77.78,-43.57,0.225
77.78,-43.51,0.225
77.79,-43.44,0.225
77.80,-43.38,0.225
77.80,-43.31,0.225
77.81,-43.24,0.225
77.81,-43.18,0.225
77.82,-43.11,0.225
77.83,-43.04,0.226
77.84,-42.98,0.226
77.84,-42.91,0.226
77.85,-42.84,0.226
77.85,-42.78,0.226
77.86,-42.71,0.226
77.87,-42.64,0.226
77.88,-42.58,0.226
77.88,-42.51,0.226
77.89,-42.44,0.226
77.90,-42.37,0.226
77.90,-42.31,0.226
77.91,-42.24,0.226
77.91,-42.17,0.226
77.92,-42.11,0.226
77.93,-42.04,0.226
77.94,-41.97,0.226
77.94,-41.91,0.226
77.95,-41.84,0.226
77.95,-41.77,0.226
77.96,-41.71,0.226
77.97,-41.64,0.226
77.98,-41.57,0.226
77.98,-41.51,0.226
77.99,-41.44,0.226
78.00,-41.37,0.227
78.00,-41.31,0.227
78.01,-41.24,0.227
78.01,-41.17,0.227
78.02,-41.11,0.227
78.03,-41.04,0.227
78.04,-40.97,0.227
78.04,-40.91,0.227
78.05,-40.84,0.227
78.05,-40.77,0.227
78.06,-40.71,0.227
78.07,-40.64,0.227
78.08,-40.57,0.227
78.08,-40.51,0.227
78.09,-40.44,0.227
78.10,-40.37,0.227
78.10,-40.31,0.227
78.11,-40.24,0.227
78.11,-40.17,0.227
78.12,-40.11,0.227
78.13,-40.04,0.227
78.14,-39.97,0.227
78.14,-39.91,0.227
78.15,-39.84,0.227
78.15,-39.77,0.227
78.16,-39.70,0.228
78.17,-39.64,0.228
78.18,-39.57,0.228
78.18,-39.50,0.228
78.19,-39.44,0.228
78.20,-39.37,0.228
78.20,-39.30,0.228
78.21,-39.23,0.228
78.21,-39.17,0.228
78.22,-39.10,0.228
78.23,-39.04,0.228
78.24,-38.97,0.228
78.24,-38.90,0.228
78.25,-38.83,0.228
78.25,-38.77,0.228
78.26,-38.70,0.228
78.27,-38.63,0.228
78.28,-38.57,0.228
78.28,-38.50,0.228
78.29,-38.43,0.228
78.30,-38.37,0.228
78.30,-38.30,0.229
78.31,-38.23,0.229
78.31,-38.17,0.229
78.32,-38.10,0.229
78.33,-38.03,0.229
78.34,-37.97,0.229
78.34,-37.90,0.229
78.35,-37.83,0.229
78.35,-37.77,0.229
78.36,-37.70,0.229
78.37,-37.63,0.229
78.38,-37.57,0.229
78.38,-37.50,0.229
78.39,-37.43,0.229
78.40,-37.37,0.229
78.40,-37.30,0.229
78.41,-37.23,0.229
78.41,-37.17,0.229
78.42,-37.10,0.229
78.43,-37.03,0.229
78.44,-36.97,0.229
78.44,-36.90,0.229
78.45,-36.83,0.229
78.45,-36.76,0.229
78.46,-36.70,0.229
78.47,-36.63,0.229
78.48,-36.57,0.229
78.48,-36.50,0.229
78.49,-36.43,0.229
78.50,-36.36,0.229
78.50,-36.30,0.229
78.51,-36.23,0.229
78.51,-36.16,0.229
78.52,-36.10,0.229
78.53,-36.03,0.229
78.54,-35.97,0.229
78.54,-35.90,0.229
78.55,-35.83,0.229
78.55,-35.77,0.229
78.56,-35.70,0.229
78.57,-35.63,0.229
78.58,-35.57,0.229
78.58,-35.50,0.229
78.59,-35.43,0.229
78.60,-35.37,0.230
78.60,-35.30,0.230
78.61,-35.23,0.230
78.61,-35.17,0.230
78.62,-35.10,0.230
78.63,-35.03,0.230
78.64,-34.96,0.230
78.64,-34.90,0.230
78.65,-34.83,0.230
78.65,-34.76,0.230
78.66,-34.70,0.230
78.67,-34.63,0.230
78.68,-34.56,0.230
78.68,-34.50,0.230
78.69,-34.43,0.230
78.70,-34.36,0.230
78.70,-34.30,0.230
78.71,-34.23,0.230
78.71,-34.16,0.230
78.72,-34.10,0.230
78.73,-34.03,0.230
78.74,-33.96,0.230
78.74,-33.90,0.230
78.75,-33.83,0.230
78.75,-33.76,0.230
78.76,-33.70,0.230
78.77,-33.63,0.230
78.78,-33.56,0.230
78.78,-33.50,0.230
78.79,-33.43,0.230
78.80,-33.36,0.230
78.80,-33.30,0.231
78.81,-33.23,0.231
78.81,-33.16,0.231
78.82,-33.10,0.231
78.83,-33.03,0.231
78.84,-32.96,0.231
78.84,-32.90,0.231
78.85,-32.83,0.231
78.85,-32.76,0.231
78.86,-32.70,0.231
78.87,-32.63,0.231
78.88,-32.56,0.231
78.88,-32.50,0.231
78.89,-32.43,0.231
78.90,-32.36,0.231
78.90,-32.29,0.231
78.91,-32.23,0.231
78.91,-32.16,0.231
78.92,-32.09,0.231
78.93,-32.03,0.231
78.94,-31.96,0.231
78.94,-31.89,0.231
78.95,-31.83,0.231
78.95,-31.76,0.231
78.96,-31.69,0.231
78.97,-31.63,0.231
78.98,-31.56,0.231
78.98,-31.49,0.231
78.99,-31.43,0.231
79.00,-31.36,0.231
79.00,-31.29,0.231
79.01,-31.23,0.231
79.01,-31.16,0.231
79.02,-31.09,0.231
79.03,-31.03,0.232
79.04,-30.96,0.232
79.04,-30.89,0.232
79.05,-30.83,0.232
79.05,-30.76,0.232
79.06,-30.69,0.232
79.07,-30.63,0.232
79.08,-30.56,0.232
79.08,-30.49,0.232
79.09,-30.43,0.232
79.10,-30.36,0.232
79.10,-30.29,0.232
79.11,-30.23,0.232
79.11,-30.16,0.232
79.12,-30.09,0.232
79.13,-30.03,0.232
79.14,-29.96,0.232
79.14,-29.89,0.232
79.15,-29.83,0.232
79.15,-29.76,0.232
79.16,-29.69,0.232
79.17,-29.63,0.232
79.18,-29.56,0.232
79.18,-29.49,0.232
79.19,-29.43,0.232
79.20,-29.36,0.232
79.20,-29.29,0.232
79.21,-29.23,0.232
79.21,-29.16,0.233
79.22,-29.09,0.233
79.23,-29.03,0.233
79.24,-28.96,0.233
79.24,-28.89,0.233
79.25,-28.82,0.233
79.25,-28.76,0.233
79.26,-28.69,0.233
79.27,-28.63,0.233
79.28,-28.56,0.233
79.28,-28.49,0.233
79.29,-28.43,0.233
79.30,-28.36,0.233
79.30,-28.29,0.233
79.31,-28.22,0.233
79.31,-28.16,0.233
79.32,-28.09,0.233
79.33,-28.02,0.233
79.34,-27.96,0.233
79.34,-27.89,0.233
79.35,-27.82,0.233
79.35,-27.76,0.233
79.36,-27.69,0.233
79.37,-27.62,0.233
79.38,-27.56,0.233
79.38,-27.49,0.233
79.39,-27.42,0.233
79.40,-27.36,0.233
79.40,-27.29,0.233
79.41,-27.22,0.234
79.41,-27.16,0.234
79.42,-27.09,0.234
79.43,-27.02,0.234
79.44,-26.96,0.234
79.44,-26.89,0.234
79.45,-26.82,0.234
79.45,-26.75,0.234
79.46,-26.69,0.234
79.47,-26.62,0.234
79.48,-26.56,0.234
79.48,-26.49,0.234
79.49,-26.42,0.234
79.50,-26.35,0.234
79.50,-26.29,0.234
79.51,-26.22,0.234
79.51,-26.15,0.234
79.52,-26.09,0.234
79.53,-26.02,0.234
79.54,-25.95,0.234
79.54,-25.89,0.234
79.55,-25.82,0.234
79.55,-25.75,0.234
79.56,-25.69,0.234
79.57,-25.62,0.234
79.58,-25.55,0.234
79.58,-25.49,0.234
79.59,-25.42,0.234
79.60,-25.35,0.235
79.60,-25.29,0.235
79.61,-25.22,0.235
79.61,-25.15,0.235
79.62,-25.09,0.235
79.63,-25.02,0.235
79.64,-24.95,0.235
79.64,-24.89,0.235
79.65,-24.82,0.235
79.65,-24.75,0.235
79.66,-24.69,0.235
79.67,-24.62,0.235
79.68,-24.55,0.235
79.68,-24.49,0.235
79.69,-24.42,0.235
79.70,-24.35,0.235
79.70,-24.29,0.235
79.71,-24.22,0.235
79.71,-24.15,0.235
79.72,-24.08,0.235
79.73,-24.02,0.235
79.74,-23.95,0.235
79.74,-23.89,0.235
79.75,-23.82,0.235
79.75,-23.75,0.236
79.76,-23.68,0.236
79.77,-23.62,0.236
79.78,-23.55,0.236
79.78,-23.49,0.236
79.79,-23.42,0.236
79.80,-23.35,0.236
79.80,-23.28,0.236
79.81,-23.22,0.236
79.81,-23.15,0.236
79.82,-23.08,0.236
79.83,-23.02,0.236
79.84,-22.95,0.236
79.84,-22.88,0.236
79.85,-22.82,0.236
79.85,-22.75,0.236
79.86,-22.68,0.236
79.87,-22.62,0.236
79.88,-22.55,0.236
79.88,-22.48,0.236
79.89,-22.42,0.236
79.90,-22.35,0.236
79.90,-22.29,0.236
79.91,-22.22,0.236
79.91,-22.15,0.236
79.92,-22.08,0.237
79.93,-22.02,0.237
79.94,-21.95,0.237
79.94,-21.88,0.237
79.95,-21.82,0.237
79.95,-21.75,0.237
79.96,-21.68,0.237
79.97,-21.62,0.237
79.98,-21.55,0.237
79.98,-21.48,0.237
79.99,-21.42,0.237
80.00,-21.35,0.237
80.00,-21.28,0.237
80.01,-21.22,0.237
80.01,-21.15,0.237
80.02,-21.08,0.237
80.03,-21.01,0.237
80.04,-20.95,0.237
80.04,-20.88,0.237
80.05,-20.81,0.237
80.05,-20.75,0.237
80.06,-20.68,0.237
80.07,-20.61,0.238
80.08,-20.55,0.238
80.08,-20.48,0.238
80.09,-20.41,0.238
80.10,-20.35,0.238
80.10,-20.28,0.238
80.11,-20.21,0.238
80.11,-20.15,0.238
80.12,-20.08,0.238
80.13,-20.01,0.238
80.14,-19.95,0.238
80.14,-19.88,0.238
80.15,-19.81,0.238
80.15,-19.75,0.238
80.16,-19.68,0.238
80.17,-19.61,0.238
80.18,-19.55,0.238
80.18,-19.48,0.238
80.19,-19.41,0.238
80.20,-19.35,0.238
80.20,-19.28,0.238
80.21,-19.21,0.238
80.21,-19.15,0.238
80.22,-19.08,0.238
80.23,-19.01,0.239
80.24,-18.95,0.239
80.24,-18.88,0.239
80.25,-18.81,0.239
80.25,-18.75,0.239
80.26,-18.68,0.239
80.27,-18.61,0.239
80.28,-18.55,0.239
80.28,-18.48,0.239
80.29,-18.41,0.239
80.30,-18.34,0.239
80.30,-18.28,0.239
80.31,-18.21,0.239
80.31,-18.15,0.239
80.32,-18.08,0.239
80.33,-18.01,0.239
80.34,-17.95,0.239
80.34,-17.88,0.239
80.35,-17.81,0.239
80.35,-17.75,0.239
80.36,-17.68,0.239
80.37,-17.61,0.239
80.38,-17.55,0.239
80.38,-17.48,0.239
80.39,-17.41,0.240
80.40,-17.35,0.240
80.40,-17.28,0.240
80.41,-17.21,0.240
80.41,-17.15,0.240
80.42,-17.08,0.240
80.43,-17.01,0.240
80.44,-16.94,0.240
80.44,-16.88,0.240
80.45,-16.81,0.240
80.45,-16.75,0.240
80.46,-16.68,0.240
80.47,-16.61,0.240
80.48,-16.54,0.240
80.48,-16.48,0.240
80.49,-16.41,0.240
80.50,-16.34,0.240
80.50,-16.28,0.240
80.51,-16.21,0.240
80.51,-16.14,0.240
80.52,-16.08,0.241
80.53,-16.01,0.241
80.54,-15.94,0.241
80.54,-15.88,0.241
80.55,-15.81,0.241
80.55,-15.74,0.241
80.56,-15.68,0.241
80.57,-15.61,0.241
80.58,-15.54,0.241
80.58,-15.48,0.241
80.59,-15.41,0.241
80.60,-15.34,0.241
80.60,-15.28,0.241
80.61,-15.21,0.241
80.61,-15.14,0.241
80.62,-15.08,0.241
80.63,-15.01,0.241
80.64,-14.94,0.241
80.64,-14.88,0.241
80.65,-14.81,0.241
80.65,-14.74,0.241
80.66,-14.68,0.242
80.67,-14.61,0.242
80.68,-14.54,0.242
80.68,-14.48,0.242
80.69,-14.41,0.242
80.70,-14.34,0.242
80.70,-14.28,0.242
80.71,-14.21,0.242
80.71,-14.14,0.242
80.72,-14.08,0.242
80.73,-14.01,0.242
80.74,-13.94,0.242
80.74,-13.87,0.242
80.75,-13.81,0.242
80.75,-13.74,0.242
80.76,-13.67,0.242
80.77,-13.61,0.242
80.78,-13.54,0.243
80.78,-13.48,0.243
80.79,-13.41,0.243
80.80,-13.34,0.243
80.80,-13.28,0.243
80.81,-13.21,0.243
80.81,-13.14,0.243
80.82,-13.07,0.243
80.83,-13.01,0.243
80.84,-12.94,0.243
80.84,-12.87,0.243
80.85,-12.81,0.243
80.85,-12.74,0.243
80.86,-12.67,0.243
80.87,-12.61,0.243
80.88,-12.54,0.243
80.88,-12.47,0.244
80.89,-12.41,0.244
80.90,-12.34,0.244
80.90,-12.27,0.244
80.91,-12.21,0.244
80.91,-12.14,0.244
80.92,-12.07,0.244
80.93,-12.01,0.244
80.94,-11.94,0.244
80.94,-11.87,0.244
80.95,-11.81,0.244
80.95,-11.74,0.244
80.96,-11.67,0.244
80.97,-11.61,0.244
80.98,-11.54,0.244
80.98,-11.47,0.245
80.99,-11.41,0.245
81.00,-11.34,0.245
81.00,-11.27,0.245
81.01,-11.21,0.245
81.01,-11.14,0.245
81.02,-11.07,0.245
81.03,-11.01,0.245
81.04,-10.94,0.245
81.04,-10.87,0.245
81.05,-10.81,0.245
81.05,-10.74,0.245
81.06,-10.67,0.246
81.07,-10.61,0.246
81.08,-10.54,0.246
81.08,-10.47,0.246
81.09,-10.40,0.246
81.10,-10.34,0.246
81.10,-10.27,0.246
81.11,-10.20,0.246
81.11,-10.14,0.246
81.12,-10.07,0.246
81.13,-10.00,0.246
81.14,-9.94,0.246
81.14,-9.87,0.247
81.15,-9.81,0.247
81.15,-9.74,0.247
81.16,-9.67,0.247
81.17,-9.60,0.247
81.18,-9.54,0.247
81.18,-9.47,0.247
81.19,-9.41,0.247
81.20,-9.34,0.247
81.20,-9.27,0.247
81.21,-9.20,0.247
81.21,-9.14,0.248
81.22,-9.07,0.248
81.23,-9.00,0.248
81.24,-8.94,0.248
81.24,-8.87,0.248
81.25,-8.80,0.248
81.25,-8.74,0.248
81.26,-8.67,0.248
81.27,-8.60,0.248
81.28,-8.54,0.249
81.28,-8.47,0.249
81.29,-8.41,0.249
81.30,-8.34,0.249
81.30,-8.27,0.249
81.31,-8.20,0.249
81.31,-8.14,0.249
81.32,-8.07,0.249
81.33,-8.00,0.250
81.34,-7.94,0.250
81.34,-7.87,0.250
81.35,-7.81,0.250
81.35,-7.74,0.250
81.36,-7.67,0.250
81.37,-7.60,0.250
81.38,-7.54,0.251
81.38,-7.47,0.251
81.39,-7.40,0.251
81.40,-7.34,0.251
81.40,-7.27,0.251
81.41,-7.20,0.251
81.41,-7.13,0.251
81.42,-7.07,0.252
81.43,-7.00,0.252
81.44,-6.93,0.252
81.44,-6.87,0.252
81.45,-6.80,0.253
81.45,-6.73,0.253
81.46,-6.67,0.253
81.47,-6.60,0.254
81.48,-6.53,0.254
81.48,-6.46,0.254
81.49,-6.40,0.254
81.50,-6.33,0.254
81.50,-6.26,0.255
81.51,-6.20,0.255
81.51,-6.13,0.255
81.52,-6.07,0.255
81.53,-6.00,0.255
81.54,-5.93,0.255
81.54,-5.87,0.256
81.55,-5.80,0.256
81.55,-5.73,0.256
81.56,-5.66,0.256
81.57,-5.60,0.256
81.58,-5.53,0.256
81.58,-5.46,0.257
81.59,-5.40,0.257
81.60,-5.33,0.257
81.60,-5.27,0.258
81.61,-5.20,0.258
81.61,-5.13,0.258
81.62,-5.07,0.258
81.63,-5.00,0.258
81.64,-4.93,0.259
81.64,-4.87,0.259
81.65,-4.80,0.259
81.65,-4.73,0.260
81.66,-4.67,0.260
81.67,-4.60,0.260
81.68,-4.54,0.260
81.68,-4.47,0.261
81.69,-4.40,0.261
81.70,-4.33,0.262
81.70,-4.27,0.262
81.71,-4.20,0.262
81.71,-4.13,0.263
81.72,-4.07,0.263
81.73,-4.00,0.264
81.74,-3.93,0.265
81.74,-3.87,0.266
81.75,-3.80,0.266
81.75,-3.73,0.267
81.76,-3.67,0.268
81.77,-3.60,0.268
81.78,-3.54,0.268
81.78,-3.47,0.269
81.79,-3.40,0.270
81.80,-3.34,0.270
81.80,-3.27,0.270
81.81,-3.20,0.271
81.81,-3.14,0.272
81.82,-3.07,0.273
81.83,-3.00,0.273
81.84,-2.94,0.274
81.84,-2.87,0.274
81.85,-2.80,0.275
81.85,-2.74,0.276
81.86,-2.67,0.277
81.87,-2.60,0.277
81.88,-2.54,0.278
81.88,-2.47,0.279
81.89,-2.41,0.281
81.90,-2.34,0.282
81.90,-2.27,0.282
81.91,-2.21,0.283
81.91,-2.14,0.285
81.92,-2.07,0.286
81.93,-2.01,0.287
81.94,-1.94,0.287
81.94,-1.87,0.288
81.95,-1.81,0.290
81.95,-1.74,0.292
81.96,-1.67,0.293
81.97,-1.61,0.293
81.98,-1.54,0.294
81.98,-1.47,0.294
81.99,-1.41,0.296
82.00,-1.34,0.298
82.00,-1.28,0.299
82.01,-1.21,0.300
82.01,-1.14,0.301
82.02,-1.08,0.301
82.03,-1.01,0.302
82.04,-0.94,0.303
82.04,-0.88,0.304
82.05,-0.81,0.306
82.05,-0.74,0.307
82.06,-0.68,0.308
82.07,-0.61,0.309
82.08,-0.55,0.311
82.08,-0.48,0.312
82.09,-0.41,0.313
82.10,-0.35,0.315
82.10,-0.28,0.316
82.11,-0.22,0.317
82.11,-0.15,0.318
82.12,-0.08,0.320
82.13,-0.02,0.322
82.14,0.05,0.323
82.14,0.12,0.324
82.15,0.18,0.325
82.15,0.25,0.327
82.16,0.31,0.329
82.17,0.38,0.330
82.18,0.45,0.331
82.18,0.51,0.332
82.19,0.58,0.333
82.20,0.65,0.335
82.20,0.71,0.337
82.21,0.78,0.338
82.21,0.85,0.339
82.22,0.91,0.341
82.23,0.98,0.343
82.24,1.04,0.344
82.24,1.11,0.345
82.25,1.18,0.346
82.25,1.24,0.348
82.26,1.31,0.350
82.27,1.38,0.351
82.28,1.44,0.352
82.28,1.51,0.353
82.29,1.58,0.353
82.30,1.64,0.354
82.30,1.71,0.355
82.31,1.77,0.357
82.31,1.84,0.358
82.32,1.91,0.358
82.33,1.97,0.359
82.34,2.04,0.359
82.34,2.11,0.360
82.35,2.17,0.360
82.35,2.24,0.361
82.36,2.31,0.361
82.37,2.37,0.362
82.38,2.44,0.362
82.38,2.51,0.362
82.39,2.57,0.363
82.40,2.64,0.363
82.40,2.71,0.363
82.41,2.77,0.363
82.41,2.84,0.364
82.42,2.91,0.364
82.43,2.97,0.364
82.44,3.04,0.364
82.44,3.11,0.364
82.45,3.17,0.364
82.45,3.24,0.364
82.46,3.30,0.364
82.47,3.37,0.364
82.48,3.44,0.363
82.48,3.51,0.363
82.49,3.57,0.363
82.50,3.64,0.362
82.50,3.71,0.362
82.51,3.77,0.361
82.51,3.84,0.361
82.52,3.91,0.359
82.53,3.98,0.358
82.54,4.04,0.357
82.54,4.11,0.357
82.55,4.18,0.356
82.55,4.24,0.354
82.56,4.31,0.354
82.57,4.38,0.353
82.58,4.45,0.352
82.58,4.51,0.351
82.59,4.58,0.350
82.60,4.65,0.349
82.60,4.71,0.348
82.61,4.78,0.348
82.61,4.85,0.347
82.62,4.91,0.346
82.63,4.98,0.345
82.64,5.05,0.345
82.64,5.12,0.344
82.65,5.18,0.344
82.65,5.25,0.344
82.66,5.32,0.343
82.67,5.38,0.343
82.68,5.45,0.342
82.68,5.52,0.342
82.69,5.58,0.342
82.70,5.65,0.342
82.70,5.72,0.341
82.71,5.79,0.341
82.71,5.85,0.341
82.72,5.92,0.340
82.73,5.99,0.340
82.74,6.05,0.340
82.74,6.12,0.340
82.75,6.19,0.340
82.75,6.25,0.340
82.76,6.32,0.340
82.77,6.39,0.339
82.78,6.45,0.339
82.78,6.52,0.339
82.79,6.59,0.339
82.80,6.65,0.339
82.80,6.72,0.339
82.81,6.79,0.339
82.81,6.85,0.338
82.82,6.92,0.338
82.83,6.99,0.338
82.84,7.05,0.338
82.84,7.12,0.338
82.85,7.19,0.338
82.85,7.25,0.338
82.86,7.32,0.338
82.87,7.39,0.337
82.88,7.46,0.337
82.88,7.52,0.337
82.89,7.59,0.337
82.90,7.66,0.337
82.90,7.72,0.337
82.91,7.79,0.337
82.91,7.86,0.337
82.92,7.92,0.337
82.93,7.99,0.337
82.94,8.06,0.336
82.94,8.12,0.336
82.95,8.19,0.336
82.95,8.26,0.336
82.96,8.32,0.336
82.97,8.39,0.336
82.98,8.46,0.336
82.98,8.52,0.336
82.99,8.59,0.336
83.00,8.66,0.336
83.00,8.72,0.336
83.01,8.79,0.336
83.01,8.86,0.336
83.02,8.92,0.336
83.03,8.99,0.335
83.04,9.06,0.335
83.04,9.13,0.335
83.05,9.19,0.335
83.05,9.26,0.335
83.06,9.33,0.335
83.07,9.39,0.335
83.08,9.46,0.335
83.08,9.52,0.335
83.09,9.59,0.335
83.10,9.66,0.335
83.10,9.73,0.335
83.11,9.79,0.335
83.11,9.86,0.335
83.12,9.93,0.335
83.13,9.99,0.335
83.14,10.06,0.335
83.14,10.13,0.335
83.15,10.19,0.335
83.15,10.26,0.335
83.16,10.33,0.335
83.17,10.39,0.335
83.18,10.46,0.335
83.18,10.53,0.335
83.19,10.59,0.335
83.20,10.66,0.335
83.20,10.73,0.335
83.21,10.79,0.335
83.21,10.86,0.335
83.22,10.93,0.335
83.23,10.99,0.335
83.24,11.06,0.335
83.24,11.13,0.335
83.25,11.19,0.335
83.25,11.26,0.335
83.26,11.33,0.335
83.27,11.39,0.335
83.28,11.46,0.335
83.28,11.53,0.335
83.29,11.59,0.335
83.30,11.66,0.335
83.30,11.73,0.335
83.31,11.79,0.335
83.31,11.86,0.335
83.32,11.93,0.335
83.33,11.99,0.335
83.34,12.06,0.335
83.34,12.13,0.335
83.35,12.19,0.335
83.35,12.26,0.335
83.36,12.33,0.335
83.37,12.39,0.335
83.38,12.46,0.335
83.38,12.53,0.335
83.39,12.59,0.335
83.40,12.66,0.335
83.40,12.73,0.335
83.41,12.80,0.335
83.41,12.86,0.335
83.42,12.93,0.335
83.43,13.00,0.335
83.44,13.06,0.335
83.44,13.13,0.335
83.45,13.20,0.335
83.45,13.26,0.335
83.46,13.33,0.335
83.47,13.40,0.335
83.48,13.46,0.335
83.48,13.53,0.335
83.49,13.60,0.335
83.50,13.66,0.335
83.50,13.73,0.335
83.51,13.80,0.335
83.51,13.86,0.335
83.52,13.93,0.335
83.53,14.00,0.335
83.54,14.06,0.335
83.54,14.13,0.335
83.55,14.20,0.335
83.55,14.26,0.335
83.56,14.33,0.335
83.57,14.40,0.335
83.58,14.46,0.335
83.58,14.53,0.335
83.59,14.60,0.335
83.60,14.66,0.335
83.60,14.73,0.335
83.61,14.80,0.335
83.61,14.86,0.335
83.62,14.93,0.336
83.63,15.00,0.336
83.64,15.06,0.336
83.64,15.13,0.336
83.65,15.20,0.336
83.65,15.26,0.336
83.66,15.33,0.336
83.67,15.40,0.336
83.68,15.46,0.336
83.68,15.53,0.336
83.69,15.60,0.336
83.70,15.66,0.336
83.70,15.73,0.336
83.71,15.80,0.336
83.71,15.86,0.336
83.72,15.93,0.336
83.73,16.00,0.336
83.74,16.07,0.336
83.74,16.13,0.336
83.75,16.20,0.336
83.75,16.27,0.336
83.76,16.33,0.336
83.77,16.40,0.336
83.78,16.47,0.336
83.78,16.53,0.336
83.79,16.60,0.336
83.80,16.67,0.336
83.80,16.73,0.337
83.81,16.80,0.337
83.81,16.86,0.337
83.82,16.93,0.337
83.83,17.00,0.337
83.84,17.07,0.337
83.84,17.13,0.337
83.85,17.20,0.337
83.85,17.27,0.337
83.86,17.33,0.337
83.87,17.40,0.337
83.88,17.47,0.337
83.88,17.53,0.337
83.89,17.60,0.337
83.90,17.67,0.337
83.90,17.73,0.337
83.91,17.80,0.337
83.91,17.87,0.337
83.92,17.93,0.337
83.93,18.00,0.337
83.94,18.07,0.337
83.94,18.13,0.337
83.95,18.20,0.337
83.95,18.27,0.337
83.96,18.33,0.337
83.97,18.40,0.337
83.98,18.47,0.337
83.98,18.53,0.337
83.99,18.60,0.337
84.00,18.67,0.338
84.00,18.73,0.338
84.01,18.80,0.338
84.01,18.87,0.338
84.02,18.93,0.338
84.03,19.00,0.338
84.04,19.07,0.338
84.04,19.13,0.338
84.05,19.20,0.338
84.05,19.27,0.338
84.06,19.33,0.338
84.07,19.40,0.338
84.08,19.47,0.338
84.08,19.53,0.338
84.09,19.60,0.338
84.10,19.67,0.338
84.10,19.73,0.338
84.11,19.80,0.338
84.11,19.87,0.338
84.12,19.93,0.338
84.13,20.00,0.338
84.14,20.07,0.338
84.14,20.14,0.338
84.15,20.20,0.338
84.15,20.27,0.338
84.16,20.33,0.338
84.17,20.40,0.338
84.18,20.47,0.339
84.18,20.53,0.339
84.19,20.60,0.339
84.20,20.67,0.339
84.20,20.73,0.339
84.21,20.80,0.339
84.21,20.87,0.339
84.22,20.94,0.339
84.23,21.00,0.339
84.24,21.07,0.339
84.24,21.14,0.339
84.25,21.20,0.339
84.25,21.27,0.339
84.26,21.34,0.339
84.27,21.40,0.339
84.28,21.47,0.339
84.28,21.54,0.339
84.29,21.60,0.339
84.30,21.67,0.339
84.30,21.74,0.339
84.31,21.80,0.339
84.31,21.87,0.339
84.32,21.94,0.339
84.33,22.00,0.339
84.34,22.07,0.339
84.34,22.13,0.340
84.35,22.20,0.340
84.35,22.27,0.340
84.36,22.34,0.340
84.37,22.40,0.340
84.38,22.47,0.340
84.38,22.54,0.340
84.39,22.60,0.340
84.40,22.67,0.340
84.40,22.74,0.340
84.41,22.80,0.340
84.41,22.87,0.340
84.42,22.94,0.340
84.43,23.00,0.340
84.44,23.07,0.340
84.44,23.14,0.340
84.45,23.20,0.340
84.45,23.27,0.340
84.46,23.34,0.340
84.47,23.40,0.340
84.48,23.47,0.340
84.48,23.54,0.340
84.49,23.60,0.341
84.50,23.67,0.341
84.50,23.74,0.341
84.51,23.80,0.341
84.51,23.87,0.341
84.52,23.94,0.341
84.53,24.00,0.341
84.54,24.07,0.341
84.54,24.14,0.341
84.55,24.20,0.341
84.55,24.27,0.341
84.56,24.34,0.341
84.57,24.40,0.341
84.58,24.47,0.341
84.58,24.54,0.341
84.59,24.61,0.341
84.60,24.67,0.341
84.60,24.74,0.341
84.61,24.80,0.341
84.61,24.87,0.341
84.62,24.94,0.341
84.63,25.01,0.342
84.64,25.07,0.342
84.64,25.14,0.342
84.65,25.21,0.342
84.65,25.27,0.342
84.66,25.34,0.342
84.67,25.41,0.342
84.68,25.47,0.342
84.68,25.54,0.342
84.69,25.61,0.342
84.70,25.67,0.342
84.70,25.74,0.342
84.71,25.81,0.342
84.71,25.87,0.342
84.72,25.94,0.342
84.73,26.01,0.342
84.74,26.07,0.342
84.74,26.14,0.342
84.75,26.21,0.342
84.75,26.27,0.342
84.76,26.34,0.342
84.77,26.41,0.342
84.78,26.47,0.343
84.78,26.54,0.343
84.79,26.61,0.343
84.80,26.68,0.343
84.80,26.74,0.343
84.81,26.81,0.343
84.81,26.88,0.343
84.82,26.94,0.343
84.83,27.01,0.343
84.84,27.07,0.343
84.84,27.14,0.343
84.85,27.21,0.343
84.85,27.28,0.343
84.86,27.34,0.343
84.87,27.41,0.343
84.88,27.48,0.343
84.88,27.54,0.343
84.89,27.61,0.343
84.90,27.67,0.343
84.90,27.74,0.343
84.91,27.81,0.343
84.91,27.88,0.343
84.92,27.94,0.343
84.93,28.01,0.344
84.94,28.08,0.344
84.94,28.14,
84.95,28.21,
84.95,28.28,
84.96,28.34,
84.97,28.41,
84.98,28.48,
84.98,28.54,
84.99,,
84.99,,