File: DSC/Olivia/2025_08_10_PVP90_TS_n60C_250C_10Cmin_x3.csv
Filename,2025_08_10_PVP90_TS_n60C_250C_10Cmin_x3
Instrument name,DSC2A-00468 (192.168.1.100)
Operator,Yarger
rundate,8/10/2025
Sample name,2025_08_10_PVP90_TS_n60C_250C_10Cmin_x3
proceduresegments,Data Off ; Equilibrate -60.00 °C; Data On ; Ramp 10.00 °C/min to 250.00 °C; Data Off ; Isothermal 2.0 min; Data On ; Ramp 10.00 °C/min to -60.00 °C; Data Off ; Isothermal 2.0 min; Data On ; Ramp 10.00 °C/min to 250.00 °C; Data Off ; Isothermal 2.0 min; Data On ; Ramp 10.00 °C/min to -60.00 °C; Data Off ; Isothermal 2.0 min; Data On ; Ramp 10.00 °C/min to 250.00 °C
[File Parameters]
Run date,8/10/2025 10:56:55 AM
Trios version,5.1.1.46572
Original File Name,
Current File Name,D:\DSC2500\JYarger\2025_08_10_PVP90_TS_n60C_250C_10Cmin_x3.tri
[Procedure]
Procedure Name,PVP90_TS_n60C_250C_10Cmin_x3
Sample Name,2025_08_10_PVP90_TS_n60C_250C_10Cmin_x3
Sample Mass,32.38 mg
Reference Sample Mass,0 mg
Pan Mass,4.42 mg
Pan Number,8
Reference Pan Mass,32.42 mg
Reference Pan Number,10
Pan Type,Aluminum
Comments,Thermal support Al pans/lids. DSC_Samples_A2_Tray_August2025 google sheet.
Project Name,Pharma
Operator,Yarger
Test,Custom
Unload Max Temperature,30
Unload Min Temperature,30
Load Max Temperature,30
Load Min Temperature,30
Stop on Gas Flow Error,Yes
[Signal List]
Signal #1,Time (min)
Signal #2,Temperature (°C)
Signal #3,Heat Flow (mW)
Signal #4,Delta T (µV)
Signal #5,Delta Tzero (µV)
Signal #6,Tzero Temperature (°C)
Signal #7,Cell Purge (mL/min)
Signal #8,Heater Temp (°C)
Signal #9,Power Delivered (W)
Signal #10,Reference Junction Temperature (°C)
Signal #11,Flange Temperature (°C)
Signal #12,Heat Flow Phase (rad)
Signal #13,Total Heat Capacity (J/°C)
Signal #14,Heat Capacity (J/°C)
[Configuration]
Company Name,ASU
Instrument Name,DSC2A-00468
Instrument Type,DSC2500
Serial Number,DSC2A-00468
IP,192.168.1.100
Location of Instrument,MRRC
DisplayType,Unknown
Sample Interval ,0.1 s/pt
Selected Heat Flow,T4P
Exotherm Direction,Down
Cell Serial,DRC2-00792
Lid Type,Standard
Cooler,RCS 90
Leave Cooler on at End of Sequence,On
Gas 2,Nitrogen
Gas Selected,Channel 1
Flow Rate,50 mL/min
Secondary Purge,On
Licensed Heat Flow,Heat Flow T4P
Modulation Licensed,Yes
[Versions]
Common IDD Version,1
Cortex Version,VER 2.10.2.31
Driver,5.0.0.6
GDM Version,1.0.3.3
TouchscreenVersion,1.0.0.16145
FEP Version,1.2.1.21
FEP Bootloader,2.0.0.5
AutoSampler Version,2.1.1.26
Auto Sampler Bootloader,2.0.0.5
FCM Version,1.1.0.3
FCM Bootloader,2.0.0.5
[Experiment Logs]
Experiment Log Entry # 1,Data On set to 0
Experiment Log Entry # 3,Equilibrate Segment -60 (C) Started
Experiment Log Entry # 5,Data On set to 1
Experiment Log Entry # 7,Ramp Segment 10 C/min to 250 Started
Experiment Log Entry # 9,Data On set to 0
Experiment Log Entry # 11,Isothermal Segment 2 min started
Experiment Log Entry # 13,Data On set to 1
Experiment Log Entry # 15,Ramp Segment 10 C/min to -60 Started
Experiment Log Entry # 17,Data On set to 0
Experiment Log Entry # 19,Isothermal Segment 2 min started
Experiment Log Entry # 21,Data On set to 1
Experiment Log Entry # 23,Ramp Segment 10 C/min to 250 Started
Experiment Log Entry # 25,Data On set to 0
Experiment Log Entry # 27,Isothermal Segment 2 min started
Experiment Log Entry # 29,Data On set to 1
Experiment Log Entry # 31,Ramp Segment 10 C/min to -60 Started
Experiment Log Entry # 33,Data On set to 0
Experiment Log Entry # 35,Isothermal Segment 2 min started
Experiment Log Entry # 37,Data On set to 1
Experiment Log Entry # 39,Ramp Segment 10 C/min to 250 Started
[Method Log]
Method Log Entry # 1,Data Off
Method Log Entry # 2,Equilibrate -60 °C
Method Log Entry # 3,Data On
Method Log Entry # 4,(Ramp 932853) Ramp 10 °C/minute to 250 °C
Method Log Entry # 5,Data Off
Method Log Entry # 6,Isothermal 2 minutes
Method Log Entry # 7,Data On
Method Log Entry # 8,(Ramp 932857) Ramp 10 °C/minute to -60 °C
Method Log Entry # 9,Data Off
Method Log Entry # 10,Isothermal 2 minutes
Method Log Entry # 11,Data On
Method Log Entry # 12,(Ramp 932861) Ramp 10 °C/minute to 250 °C
Method Log Entry # 13,Data Off
Method Log Entry # 14,Isothermal 2 minutes
Method Log Entry # 15,Data On
Method Log Entry # 16,(Ramp 932865) Ramp 10 °C/minute to -60 °C
Method Log Entry # 17,Data Off
Method Log Entry # 18,Isothermal 2 minutes
Method Log Entry # 19,Data On
Method Log Entry # 20,(Ramp 932869) Ramp 10 °C/minute to 250 °C
Cell Serial,DRC2-00792
[T1 Calibration]
Slope,-0.008529666
Offset,9.636258
Initial Temperature,98.23
GUID,f8bfdadc-4977-4fdf-ba6d-0ba9134940c3
[TZero Calibration]
Date Applied,11/29/2022 4:06:13 PM
Description,From -89.059 °C to 396.009 °C at 20.000°C/min
Gas Type,Nitrogen
Pan Type,None
Source Files 1,C:\Users\yargerlab\Desktop\DSC Data\General\TZero_calibration_11_29_22_2nd(2).tri
Source Files 2,C:\Users\yargerlab\Desktop\DSC Data\General\TZero_calibration_11_29_22_2nd(3).tri
Delta T Offset,13.05235
Delta T Slope,-0.007271007
Delta T0 Offset,-13.69128
Delta T0 Slope,0.06063341
[Temperature Calibration]
Date Applied,11/29/2022 7:12:28 PM
Description,From 106.590 °C to 186.590 °C at 10.000°C/min
Gas Type,Nitrogen
Pan Type,Tzero Aluminum Hermetic
Source Files 1,C:\Users\yargerlab\Desktop\DSC Data\General\Indium(6).tri
Measured 1,157.391
Known 1,156.598
[Cell Constant Calibration]
Date Applied,11/29/2022 7:12:29 PM
Description,From 106.590 °C to 186.590 °C at 10.000°C/min
Gas Type,Nitrogen
Pan Type,Tzero Aluminum Hermetic
Source Files 1,C:\Users\yargerlab\Desktop\DSC Data\General\Indium(6).tri
T4P KCell,1.006051
Onset Slope,63.26126 mW/°C
[Direct Cp Calibration]
Date Applied,11/30/2022 11:04:51 AM
Description,From -79.983 °C to 298.409 °C at 10.000°C/min
Gas Type,Nitrogen
Pan Type,Tzero Aluminum Hermetic
Source Files 1,C:\Users\yargerlab\Desktop\DSC Data\General\Sapphire_Heat_Capacity_11_30_22.tri
[Rev Cp Calibration]
Date Applied,11/30/2022 1:58:51 PM
Description,From -79.996 °C to 292.812 °C at 3.000°C/min
Gas Type,Nitrogen
Pan Type,Tzero Aluminum Hermetic
Source Files 1,C:\Users\yargerlab\Desktop\DSC Data\General\Sapphire_MDSC_Calibration_11_30_22.tri
[step]
Ramp 10.00 °C/min to 250.00 °C
Time,Temperature,Heat Flow (Normalized)
min,°C,W/g
0.00,-59.81,-0.007
0.02,-59.81,-0.007
0.04,-59.81,-0.007
0.07,-59.79,-0.007
0.09,-59.73,-0.007
0.11,-59.65,-0.007
0.13,-59.53,-0.005
0.15,-59.39,0.000
0.17,-59.22,0.004
0.19,-59.04,0.009
0.22,-58.85,0.013
0.24,-58.65,0.017
0.26,-58.46,0.020
0.28,-58.25,0.022
0.30,-58.05,0.024
0.33,-57.84,0.026
0.35,-57.63,0.027
0.37,-57.42,0.027
0.39,-57.21,0.028
0.41,-57.00,0.028
0.43,-56.79,0.029
0.45,-56.58,0.029
0.48,-56.37,0.029
0.50,-56.16,0.029
0.52,-55.94,0.029
0.54,-55.73,0.030
0.56,-55.52,0.030
0.58,-55.31,0.030
0.61,-55.09,0.030
0.63,-54.88,0.030
0.65,-54.66,0.030
0.67,-54.45,0.030
0.69,-54.24,0.030
0.72,-54.02,0.030
0.74,-53.81,0.030
0.76,-53.59,0.030
0.78,-53.38,0.030
0.80,-53.16,0.030
0.82,-52.95,0.031
0.85,-52.73,0.031
0.87,-52.52,0.031
0.89,-52.31,0.031
0.91,-52.09,0.031
0.93,-51.88,0.031
0.95,-51.66,0.031
0.98,-51.44,0.031
1.00,-51.23,0.031
1.02,-51.01,0.031
1.04,-50.80,0.031
1.06,-50.58,0.031
1.08,-50.37,0.031
1.11,-50.15,0.031
1.13,-49.93,0.031
1.15,-49.72,0.031
1.17,-49.50,0.031
1.19,-49.29,0.032
1.21,-49.07,0.032
1.23,-48.85,0.032
1.26,-48.64,0.032
1.28,-48.42,0.032
1.30,-48.20,0.032
1.32,-47.99,0.032
1.34,-47.77,0.032
1.37,-47.56,0.032
1.39,-47.34,0.032
1.41,-47.12,0.032
1.43,-46.91,0.032
1.45,-46.69,0.032
1.47,-46.47,0.032
1.49,-46.26,0.032
1.52,-46.04,0.032
1.54,-45.82,0.032
1.56,-45.61,0.032
1.58,-45.39,0.032
1.60,-45.17,0.032
1.63,-44.96,0.032
1.65,-44.74,0.032
1.67,-44.52,0.032
1.69,-44.31,0.032
1.71,-44.09,0.032
1.73,-43.87,0.032
1.76,-43.66,0.032
1.78,-43.44,0.032
1.80,-43.22,0.032
1.82,-43.01,0.032
1.84,-42.79,0.032
1.86,-42.57,0.032
1.88,-42.35,0.032
1.91,-42.14,0.032
1.93,-41.92,0.032
1.95,-41.70,0.033
1.97,-41.49,0.033
1.99,-41.27,0.033
2.02,-41.06,0.033
2.04,-40.84,0.033
2.06,-40.62,0.033
2.08,-40.40,0.033
2.10,-40.19,0.033
2.12,-39.97,0.033
2.14,-39.75,0.033
2.17,-39.54,0.033
2.19,-39.32,0.033
2.21,-39.10,0.033
2.23,-38.89,0.033
2.25,-38.67,0.033
2.28,-38.45,0.033
2.30,-38.24,0.033
2.32,-38.02,0.033
2.34,-37.80,0.033
2.36,-37.58,0.033
2.38,-37.37,0.033
2.41,-37.15,0.033
2.43,-36.93,0.033
2.45,-36.72,0.033
2.47,-36.50,0.033
2.49,-36.28,0.033
2.51,-36.07,0.033
2.54,-35.85,0.033
2.56,-35.63,0.033
2.58,-35.41,0.033
2.60,-35.20,0.033
2.62,-34.98,0.033
2.64,-34.76,0.033
2.66,-34.55,0.033
2.69,-34.33,0.033
2.71,-34.11,0.033
2.73,-33.90,0.033
2.75,-33.68,0.033
2.77,-33.46,0.033
2.79,-33.25,0.033
2.82,-33.03,0.033
2.84,-32.81,0.033
2.86,-32.59,0.033
2.88,-32.38,0.033
2.90,-32.16,0.033
2.93,-31.94,0.033
2.95,-31.73,0.033
2.97,-31.51,0.033
2.99,-31.29,0.033
3.01,-31.08,0.033
3.03,-30.86,0.033
3.06,-30.64,0.033
3.08,-30.42,0.033
3.10,-30.21,0.033
3.12,-29.99,0.033
3.14,-29.77,0.033
3.16,-29.56,0.033
3.19,-29.34,0.034
3.21,-29.12,0.034
3.23,-28.91,0.034
3.25,-28.69,0.034
3.27,-28.47,0.034
3.29,-28.26,0.034
3.31,-28.04,0.034
3.34,-27.82,0.034
3.36,-27.61,0.034
3.38,-27.39,0.034
3.40,-27.17,0.034
3.42,-26.95,0.034
3.44,-26.74,0.034
3.47,-26.52,0.034
3.49,-26.30,0.034
3.51,-26.09,0.034
3.53,-25.87,0.034
3.55,-25.65,0.034
3.58,-25.44,0.034
3.60,-25.22,0.034
3.62,-25.00,0.034
3.64,-24.79,0.034
3.66,-24.57,0.034
3.68,-24.35,0.034
3.71,-24.13,0.034
3.73,-23.92,0.034
3.75,-23.70,0.034
3.77,-23.48,0.034
3.79,-23.27,0.034
3.81,-23.05,0.034
3.84,-22.83,0.034
3.86,-22.62,0.034
3.88,-22.40,0.034
3.90,-22.18,0.034
3.92,-21.97,0.034
3.94,-21.75,0.034
3.96,-21.53,0.034
3.99,-21.31,0.034
4.01,-21.10,0.034
4.03,-20.88,0.034
4.05,-20.66,0.034
4.07,-20.45,0.034
4.09,-20.23,0.034
4.12,-20.01,0.034
4.14,-19.80,0.035
4.16,-19.58,0.035
4.18,-19.36,0.035
4.20,-19.15,0.035
4.23,-18.93,0.035
4.25,-18.71,0.035
4.27,-18.50,0.035
4.29,-18.28,0.035
4.31,-18.06,0.035
4.33,-17.84,0.035
4.35,-17.63,0.035
4.38,-17.41,0.035
4.40,-17.19,0.035
4.42,-16.98,0.035
4.44,-16.76,0.035
4.46,-16.54,0.035
4.49,-16.33,0.035
4.51,-16.11,0.035
4.53,-15.89,0.035
4.55,-15.68,0.035
4.57,-15.46,0.035
4.59,-15.24,0.035
4.61,-15.02,0.035
4.64,-14.81,0.035
4.66,-14.59,0.035
4.68,-14.37,0.035
4.70,-14.16,0.035
4.72,-13.94,0.035
4.75,-13.73,0.035
4.77,-13.51,0.035
4.79,-13.29,0.035
4.81,-13.07,0.035
4.83,-12.86,0.035
4.85,-12.64,0.035
4.88,-12.42,0.035
4.90,-12.21,0.035
4.92,-11.99,0.035
4.94,-11.77,0.035
4.96,-11.56,0.035
4.98,-11.34,0.036
5.00,-11.12,0.036
5.03,-10.91,0.036
5.05,-10.69,0.036
5.07,-10.47,0.036
5.09,-10.25,0.036
5.11,-10.04,0.036
5.14,-9.82,0.036
5.16,-9.60,0.036
5.18,-9.39,0.036
5.20,-9.17,0.036
5.22,-8.95,0.036
5.24,-8.74,0.036
5.26,-8.52,0.036
5.29,-8.30,0.036
5.31,-8.09,0.036
5.33,-7.87,0.036
5.35,-7.65,0.036
5.37,-7.44,0.036
5.40,-7.22,0.036
5.42,-7.00,0.036
5.44,-6.78,0.036
5.46,-6.57,0.036
5.48,-6.35,0.036
5.50,-6.13,0.036
5.53,-5.92,0.036
5.55,-5.70,0.036
5.57,-5.48,0.036
5.59,-5.27,0.036
5.61,-5.05,0.036
5.63,-4.83,0.036
5.65,-4.62,0.037
5.68,-4.40,0.037
5.70,-4.18,0.037
5.72,-3.97,0.037
5.74,-3.75,0.037
5.76,-3.53,0.037
5.79,-3.31,0.037
5.81,-3.10,0.037
5.83,-2.88,0.037
5.85,-2.66,0.037
5.87,-2.45,0.037
5.89,-2.23,0.037
5.91,-2.01,0.037
5.94,-1.80,0.037
5.96,-1.58,0.037
5.98,-1.36,0.037
6.00,-1.15,0.037
6.02,-0.93,0.037
6.05,-0.71,0.037
6.07,-0.50,0.037
6.09,-0.28,0.037
6.11,-0.06,0.037
6.13,0.16,0.037
6.15,0.37,0.037
6.18,0.59,0.037
6.20,0.81,0.037
6.22,1.02,0.037
6.24,1.24,0.038
6.26,1.46,0.038
6.28,1.67,0.038
6.30,1.89,0.038
6.33,2.11,0.038
6.35,2.33,0.038
6.37,2.54,0.038
6.39,2.76,0.038
6.41,2.97,0.038
6.44,3.19,0.038
6.46,3.41,0.038
6.48,3.63,0.038
6.50,3.84,0.038
6.52,4.06,0.038
6.54,4.28,0.038
6.56,4.49,0.038
6.59,4.71,0.038
6.61,4.93,0.038
6.63,5.14,0.038
6.65,5.36,0.038
6.67,5.58,0.038
6.70,5.79,0.038
6.72,6.01,0.038
6.74,6.23,0.038
6.76,6.45,0.039
6.78,6.66,0.039
6.80,6.88,0.039
6.83,7.09,0.039
6.85,7.31,0.039
6.87,7.53,0.039
6.89,7.75,0.039
6.91,7.96,0.039
6.93,8.18,0.039
6.95,8.40,0.039
6.98,8.61,0.039
7.00,8.83,0.039
7.02,9.05,0.039
7.04,9.26,0.039
7.06,9.48,0.039
7.09,9.70,0.039
7.11,9.92,0.039
7.13,10.13,0.039
7.15,10.35,0.039
7.17,10.57,0.039
7.19,10.78,0.039
7.21,11.00,0.040
7.24,11.22,0.040
7.26,11.43,0.040
7.28,11.65,0.040
7.30,11.87,0.040
7.32,12.08,0.040
7.35,12.30,0.040
7.37,12.52,0.040
7.39,12.73,0.040
7.41,12.95,0.040
7.43,13.17,0.040
7.45,13.38,0.040
7.48,13.60,0.040
7.50,13.82,0.040
7.52,14.03,0.040
7.54,14.25,0.040
7.56,14.47,0.040
7.58,14.68,0.040
7.60,14.90,0.040
7.63,15.12,0.041
7.65,15.33,0.041
7.67,15.55,0.041
7.69,15.77,0.041
7.71,15.98,0.041
7.74,16.20,0.041
7.76,16.42,0.041
7.78,16.63,0.041
7.80,16.85,0.041
7.82,17.07,0.041
7.84,17.28,0.041
7.86,17.50,0.041
7.89,17.72,0.041
7.91,17.93,0.041
7.93,18.15,0.041
7.95,18.37,0.041
7.97,18.58,0.041
8.00,18.80,0.042
8.02,19.02,0.042
8.04,19.23,0.042
8.06,19.45,0.042
8.08,19.67,0.042
8.10,19.88,0.042
8.13,20.10,0.042
8.15,20.32,0.042
8.17,20.53,0.042
8.19,20.75,0.042
8.21,20.97,0.042
8.23,21.18,0.042
8.25,21.40,0.042
8.28,21.62,0.042
8.30,21.84,0.043
8.32,22.05,0.043
8.34,22.27,0.043
8.36,22.48,0.043
8.39,22.70,0.043
8.41,22.92,0.043
8.43,23.14,0.043
8.45,23.35,0.043
8.47,23.57,0.043
8.49,23.79,0.043
8.51,24.00,0.043
8.54,24.22,0.043
8.56,24.44,0.043
8.58,24.65,0.044
8.60,24.87,0.044
8.62,25.09,0.044
8.65,25.30,0.044
8.67,25.52,0.044
8.69,25.74,0.044
8.71,25.95,0.044
8.73,26.17,0.044
8.75,26.39,0.044
8.78,26.60,0.044
8.80,26.82,0.044
8.82,27.04,0.044
8.84,27.25,0.044
8.86,27.47,0.045
8.88,27.69,0.045
8.90,27.91,0.045
8.93,28.12,0.045
8.95,28.34,0.045
8.97,28.55,0.045
8.99,28.77,0.045
9.01,28.99,0.045
9.03,29.20,0.045
9.06,29.42,0.045
9.08,29.64,0.046
9.10,29.86,0.046
9.12,30.07,0.046
9.14,30.29,0.046
9.17,30.51,0.046
9.19,30.72,0.046
9.21,30.94,0.046
9.23,31.16,0.046
9.25,31.37,0.046
9.27,31.59,0.046
9.30,31.81,0.047
9.32,32.02,0.047
9.34,32.24,0.047
9.36,32.46,0.047
9.38,32.67,0.047
9.40,32.89,0.047
9.43,33.11,0.047
9.45,33.32,0.047
9.47,33.54,0.047
9.49,33.76,0.048
9.51,33.97,0.048
9.53,34.19,0.048
9.55,34.41,0.048
9.58,34.62,0.048
9.60,34.84,0.048
9.62,35.06,0.048
9.64,35.27,0.048
9.66,35.49,0.049
9.68,35.70,0.049
9.71,35.92,0.049
9.73,36.14,0.049
9.75,36.36,0.049
9.77,36.57,0.049
9.79,36.79,0.049
9.82,37.01,0.050
9.84,37.22,0.050
9.86,37.44,0.050
9.88,37.65,0.050
9.90,37.87,0.050
9.92,38.09,0.051
9.95,38.31,0.051
9.97,38.52,0.051
9.99,38.74,0.051
10.01,38.95,0.051
10.03,39.17,0.052
10.05,39.39,0.052
10.08,39.60,0.052
10.10,39.82,0.052
10.12,40.04,0.052
10.14,40.25,0.053
10.16,40.47,0.053
10.18,40.69,0.053
10.20,40.90,0.053
10.23,41.12,0.054
10.25,41.33,0.054
10.27,41.55,0.054
10.29,41.77,0.054
10.31,41.98,0.055
10.33,42.20,0.055
10.36,42.42,0.055
10.38,42.63,0.056
10.40,42.85,0.056
10.42,43.07,0.056
10.44,43.28,0.057
10.47,43.50,0.057
10.49,43.71,0.057
10.51,43.93,0.058
10.53,44.15,0.058
10.55,44.36,0.058
10.57,44.58,0.059
10.60,44.79,0.059
10.62,45.01,0.060
10.64,45.23,0.060
10.66,45.44,0.060
10.68,45.66,0.061
10.70,45.88,0.061
10.73,46.09,0.061
10.75,46.31,0.062
10.77,46.53,0.062
10.79,46.74,0.062
10.81,46.96,0.062
10.83,47.17,0.062
10.85,47.39,0.063
10.88,47.61,0.063
10.90,47.82,0.063
10.92,48.04,0.063
10.94,48.26,0.063
10.96,48.47,0.063
10.98,48.69,0.063
11.01,48.91,0.063
11.03,49.12,0.063
11.05,49.34,0.063
11.07,49.56,0.063
11.09,49.78,0.063
11.12,49.99,0.063
11.14,50.21,0.063
11.16,50.43,0.063
11.18,50.65,0.063
11.20,50.86,0.063
11.22,51.08,0.063
11.25,51.30,0.063
11.27,51.52,0.063
11.29,51.73,0.063
11.31,51.95,0.062
11.33,52.17,0.062
11.35,52.38,0.062
11.38,52.60,0.062
11.40,52.82,0.062
11.42,53.03,0.062
11.44,53.25,0.062
11.46,53.47,0.062
11.48,53.68,0.062
11.50,53.90,0.062
11.53,54.12,0.062
11.55,54.33,0.063
11.57,54.55,0.063
11.59,54.76,0.063
11.61,54.98,0.063
11.63,55.20,0.064
11.66,55.41,0.064
11.68,55.63,0.064
11.70,55.85,0.064
11.72,56.06,0.065
11.74,56.28,0.065
11.77,56.49,0.065
11.79,56.71,0.066
11.81,56.93,0.066
11.83,57.14,0.066
11.85,57.36,0.067
11.87,57.58,0.067
11.90,57.79,0.067
11.92,58.01,0.068
11.94,58.23,0.068
11.96,58.44,0.069
11.98,58.66,0.069
12.00,58.87,0.069
12.03,59.09,0.070
12.05,59.31,0.070
12.07,59.52,0.070
12.09,59.74,0.071
12.11,59.95,0.071
12.13,60.17,0.072
12.15,60.39,0.072
12.18,60.60,0.073
12.20,60.82,0.073
12.22,61.04,0.074
12.24,61.25,0.074
12.26,61.47,0.075
12.28,61.68,0.075
12.31,61.90,0.075
12.33,62.11,0.076
12.35,62.33,0.076
12.37,62.55,0.077
12.39,62.76,0.077
12.42,62.98,0.078
12.44,63.19,0.079
12.46,63.41,0.079
12.48,63.63,0.080
12.50,63.84,0.080
12.52,64.06,0.081
12.55,64.27,0.081
12.57,64.49,0.082
12.59,64.70,0.082
12.61,64.92,0.083
12.63,65.14,0.083
12.65,65.35,0.084
12.68,65.57,0.084
12.70,65.78,0.085
12.72,66.00,0.085
12.74,66.22,0.086
12.76,66.43,0.086
12.78,66.65,0.087
12.80,66.86,0.087
12.83,67.08,0.088
12.85,67.30,0.088
12.87,67.51,0.088
12.89,67.73,0.089
12.91,67.94,0.089
12.93,68.16,0.090
12.96,68.38,0.090
12.98,68.59,0.091
13.00,68.81,0.091
13.02,69.02,0.091
13.04,69.24,0.092
13.07,69.46,0.092
13.09,69.67,0.092
13.11,69.89,0.093
13.13,70.10,0.093
13.15,70.32,0.094
13.17,70.54,0.094
13.20,70.75,0.095
13.22,70.97,0.095
13.24,71.18,0.096
13.26,71.40,0.096
13.28,71.62,0.096
13.30,71.83,0.097
13.33,72.05,0.097
13.35,72.26,0.098
13.37,72.48,0.098
13.39,72.70,0.099
13.41,72.91,0.099
13.43,73.13,0.099
13.45,73.34,0.100
13.48,73.56,0.100
13.50,73.77,0.101
13.52,73.99,0.101
13.54,74.21,0.102
13.56,74.42,0.102
13.58,74.64,0.103
13.61,74.85,0.103
13.63,75.07,0.104
13.65,75.29,0.104
13.67,75.50,0.105
13.69,75.72,0.105
13.72,75.93,0.106
13.74,76.15,0.106
13.76,76.36,0.107
13.78,76.58,0.107
13.80,76.80,0.108
13.82,77.01,0.108
13.85,77.23,0.109
13.87,77.45,0.109
13.89,77.66,0.110
13.91,77.88,0.111
13.93,78.09,0.111
13.95,78.31,0.112
13.98,78.52,0.112
14.00,78.74,0.113
14.02,78.95,0.113
14.04,79.17,0.114
14.06,79.39,0.114
14.08,79.60,0.115
14.10,79.82,0.116
14.13,80.03,0.116
14.15,80.25,0.117
14.17,80.47,0.117
14.19,80.68,0.118
14.21,80.90,0.119
14.23,81.11,0.119
14.26,81.33,0.120
14.28,81.54,0.120
14.30,81.76,0.121
14.32,81.97,0.122
14.34,82.19,0.122
14.37,82.41,0.123
14.39,82.62,0.124
14.41,82.84,0.124
14.43,83.05,0.125
14.45,83.27,0.126
14.47,83.49,0.126
14.50,83.70,0.127
14.52,83.92,0.128
14.54,84.13,0.128
14.56,84.35,0.129
14.58,84.56,0.130
14.60,84.78,0.130
14.63,84.99,0.131
14.65,85.21,0.132
14.67,85.42,0.133
14.69,85.64,0.133
14.71,85.85,0.134
14.73,86.07,0.135
14.75,86.28,0.135
14.78,86.50,0.136
14.80,86.72,0.137
14.82,86.93,0.138
14.84,87.15,0.139
14.86,87.36,0.139
14.88,87.58,0.140
14.91,87.79,0.141
14.93,88.01,0.142
14.95,88.22,0.143
14.97,88.44,0.143
14.99,88.65,0.144
15.02,88.87,0.145
15.04,89.08,0.146
15.06,89.30,0.147
15.08,89.51,0.148
15.10,89.73,0.149
15.12,89.94,0.150
15.15,90.16,0.151
15.17,90.37,0.151
15.19,90.59,0.152
15.21,90.80,0.153
15.23,91.02,0.154
15.25,91.23,0.155
15.28,91.45,0.156
15.30,91.67,0.157
15.32,91.88,0.158
15.34,92.10,0.159
15.36,92.31,0.160
15.38,92.53,0.161
15.40,92.74,0.161
15.43,92.96,0.163
15.45,93.17,0.164
15.47,93.39,0.165
15.49,93.60,0.166
15.51,93.82,0.167
15.53,94.03,0.168
15.56,94.25,0.168
15.58,94.46,0.170
15.60,94.68,0.170
15.62,94.89,0.172
15.64,95.11,0.172
15.67,95.32,0.173
15.69,95.54,0.174
15.71,95.75,0.175
15.73,95.97,0.176
15.75,96.18,0.177
15.77,96.40,0.179
15.80,96.61,0.179
15.82,96.82,0.180
15.84,97.04,0.182
15.86,97.26,0.183
15.88,97.47,0.184
15.90,97.69,0.185
15.93,97.90,0.186
15.95,98.12,0.187
15.97,98.33,0.188
15.99,98.54,0.189
16.01,98.76,0.190
16.03,98.97,0.191
16.05,99.19,0.192
16.08,99.40,0.193
16.10,99.62,0.194
16.12,99.83,0.196
16.14,100.05,0.197
16.16,100.26,0.198
16.18,100.48,0.199
16.21,100.69,0.200
16.23,100.91,0.201
16.25,101.12,0.202
16.27,101.34,0.203
16.29,101.55,0.204
16.32,101.76,0.205
16.34,101.98,0.206
16.36,102.20,0.207
16.38,102.41,0.208
16.40,102.63,0.209
16.42,102.84,0.210
16.45,103.05,0.211
16.47,103.27,0.212
16.49,103.49,0.213
16.51,103.70,0.214
16.53,103.91,0.215
16.55,104.13,0.216
16.58,104.35,0.217
16.60,104.56,0.218
16.62,104.78,0.219
16.64,104.99,0.220
16.66,105.21,0.221
16.68,105.42,0.221
16.70,105.64,0.222
16.73,105.85,0.223
16.75,106.07,0.224
16.77,106.28,0.225
16.79,106.50,0.225
16.81,106.71,0.226
16.83,106.93,0.227
16.86,107.14,0.227
16.88,107.36,0.228
16.90,107.57,0.229
16.92,107.79,0.229
16.94,108.01,0.230
16.97,108.22,0.231
16.99,108.44,0.231
17.01,108.65,0.232
17.03,108.87,0.232
17.05,109.08,0.233
17.07,109.30,0.233
17.09,109.52,0.234
17.12,109.73,0.234
17.14,109.95,0.234
17.16,110.17,0.235
17.18,110.38,0.235
17.20,110.60,0.235
17.23,110.81,0.235
17.25,111.03,0.236
17.27,111.25,0.236
17.29,111.46,0.236
17.31,111.68,0.236
17.33,111.90,0.236
17.36,112.12,0.236
17.38,112.33,0.236
17.40,112.55,0.236
17.42,112.77,0.236
17.44,112.98,0.236
17.46,113.20,0.236
17.48,113.42,0.236
17.51,113.64,0.236
17.53,113.85,0.236
17.55,114.07,0.236
17.57,114.29,0.236
17.59,114.50,0.236
17.62,114.72,0.235
17.64,114.94,0.234
17.66,115.16,0.234
17.68,115.38,0.233
17.70,115.59,0.233
17.72,115.81,0.232
17.74,116.03,0.231
17.77,116.25,0.231
17.79,116.47,0.230
17.81,116.68,0.229
17.83,116.90,0.228
17.85,117.12,0.227
17.88,117.34,0.226
17.90,117.56,0.226
17.92,117.78,0.225
17.94,118.00,0.224
17.96,118.22,0.223
17.98,118.44,0.221
18.01,118.65,0.220
18.03,118.87,0.219
18.05,119.09,0.218
18.07,119.31,0.217
18.09,119.53,0.216
18.11,119.75,0.214
18.13,119.97,0.213
18.16,120.19,0.212
18.18,120.41,0.211
18.20,120.63,0.209
18.22,120.85,0.208
18.24,121.07,0.206
18.27,121.29,0.205
18.29,121.51,0.204
18.31,121.73,0.202
18.33,121.95,0.201
18.35,122.16,0.200
18.37,122.39,0.198
18.39,122.61,0.197
18.42,122.82,0.195
18.44,123.04,0.194
18.46,123.26,0.192
18.48,123.48,0.191
18.50,123.70,0.189
18.53,123.92,0.188
18.55,124.14,0.186
18.57,124.36,0.185
18.59,124.58,0.183
18.61,124.80,0.182
18.63,125.02,0.180
18.66,125.24,0.179
18.68,125.46,0.178
18.70,125.68,0.176
18.72,125.90,0.175
18.74,126.12,0.173
18.76,126.34,0.172
18.78,126.56,0.171
18.81,126.78,0.169
18.83,127.00,0.168
18.85,127.22,0.167
18.87,127.44,0.165
18.89,127.66,0.164
18.92,127.88,0.162
18.94,128.10,0.161
18.96,128.32,0.160
18.98,128.54,0.158
19.00,128.76,0.157
19.02,128.98,0.156
19.04,129.20,0.154
19.07,129.42,0.153
19.09,129.64,0.152
19.11,129.85,0.151
19.13,130.08,0.149
19.15,130.29,0.148
19.18,130.51,0.147
19.20,130.73,0.146
19.22,130.95,0.145
19.24,131.17,0.143
19.26,131.39,0.142
19.28,131.61,0.141
19.31,131.83,0.140
19.33,132.05,0.139
19.35,132.27,0.138
19.37,132.49,0.136
19.39,132.71,0.135
19.41,132.93,0.134
19.43,133.15,0.133
19.46,133.37,0.132
19.48,133.58,0.131
19.50,133.80,0.130
19.52,134.02,0.129
19.54,134.24,0.128
19.57,134.46,0.127
19.59,134.68,0.126
19.61,134.90,0.125
19.63,135.12,0.124
19.65,135.33,0.123
19.67,135.55,0.122
19.69,135.77,0.121
19.72,135.99,0.120
19.74,136.21,0.119
19.76,136.43,0.118
19.78,136.65,0.117
19.80,136.87,0.116
19.83,137.09,0.115
19.85,137.30,0.114
19.87,137.52,0.113
19.89,137.74,0.112
19.91,137.96,0.111
19.93,138.18,0.111
19.96,138.40,0.110
19.98,138.61,0.109
20.00,138.83,0.108
20.02,139.05,0.107
20.04,139.27,0.106
20.06,139.49,0.105
20.08,139.71,0.105
20.11,139.93,0.104
20.13,140.14,0.103
20.15,140.36,0.102
20.17,140.58,0.101
20.19,140.80,0.101
20.22,141.02,0.100
20.24,141.24,0.099
20.26,141.45,0.098
20.28,141.67,0.098
20.30,141.89,0.097
20.32,142.11,0.096
20.34,142.33,0.095
20.37,142.55,0.095
20.39,142.76,0.094
20.41,142.98,0.093
20.43,143.20,0.092
20.45,143.42,0.092
20.48,143.64,0.091
20.50,143.85,0.090
20.52,144.07,0.090
20.54,144.29,0.089
20.56,144.51,0.088
20.58,144.73,0.088
20.61,144.95,0.087
20.63,145.17,0.086
20.65,145.38,0.086
20.67,145.60,0.085
20.69,145.82,0.084
20.71,146.04,0.084
20.73,146.26,0.083
20.76,146.47,0.082
20.78,146.69,0.082
20.80,146.91,0.081
20.82,147.13,0.081
20.84,147.35,0.080
20.87,147.56,0.079
20.89,147.78,0.079
20.91,148.00,0.078
20.93,148.22,0.078
20.95,148.43,0.077
20.97,148.65,0.076
20.99,148.87,0.076
21.02,149.09,0.076
21.04,149.31,0.075
21.06,149.53,0.074
21.08,149.74,0.074
21.10,149.96,0.073
21.13,150.18,0.073
21.15,150.40,0.072
21.17,150.61,0.072
21.19,150.83,0.071
21.21,151.05,0.071
21.23,151.27,0.070
21.26,151.49,0.070
21.28,151.70,0.069
21.30,151.92,0.069
21.32,152.14,0.068
21.34,152.36,0.068
21.36,152.57,0.067
21.38,152.79,0.067
21.41,153.01,0.067
21.43,153.23,0.066
21.45,153.45,0.066
21.47,153.66,0.065
21.49,153.88,0.065
21.52,154.10,0.064
21.54,154.32,0.064
21.56,154.53,0.063
21.58,154.75,0.063
21.60,154.97,0.063
21.62,155.19,0.062
21.64,155.40,0.062
21.67,155.62,0.062
21.69,155.84,0.061
21.71,156.06,0.061
21.73,156.27,0.061
21.75,156.49,0.060
21.78,156.71,0.060
21.80,156.93,0.059
21.82,157.15,0.059
21.84,157.36,0.059
21.86,157.58,0.059
21.88,157.80,0.058
21.91,158.01,0.058
21.93,158.23,0.057
21.95,158.45,0.057
21.97,158.67,0.057
21.99,158.89,0.056
22.01,159.10,0.056
22.03,159.32,0.056
22.06,159.54,0.056
22.08,159.76,0.055
22.10,159.97,0.055
22.12,160.19,0.055
22.14,160.41,0.054
22.17,160.62,0.054
22.19,160.84,0.054
22.21,161.06,0.054
22.23,161.28,0.053
22.25,161.49,0.053
22.27,161.71,0.053
22.29,161.93,0.053
22.32,162.14,0.052
22.34,162.36,0.052
22.36,162.58,0.052
22.38,162.80,0.052
22.40,163.01,0.051
22.43,163.23,0.051
22.45,163.45,0.051
22.47,163.67,0.051
22.49,163.88,0.051
22.51,164.10,0.051
22.53,164.32,0.050
22.56,164.54,0.050
22.58,164.76,0.050
22.60,164.97,0.050
22.62,165.19,0.050
22.64,165.41,0.049
22.66,165.62,0.049
22.68,165.84,0.049
22.71,166.06,0.049
22.73,166.27,0.048
22.75,166.49,0.048
22.77,166.71,0.048
22.79,166.93,0.048
22.82,167.14,0.048
22.84,167.36,0.048
22.86,167.58,0.048
22.88,167.79,0.047
22.90,168.01,0.047
22.92,168.23,0.047
22.94,168.45,0.047
22.97,168.66,0.047
22.99,168.88,0.047
23.01,169.10,0.047
23.03,169.31,0.046
23.05,169.53,0.046
23.08,169.75,0.046
23.10,169.96,0.046
23.12,170.18,0.046
23.14,170.40,0.046
23.16,170.62,0.046
23.18,170.83,0.046
23.21,171.05,0.046
23.23,171.27,0.045
23.25,171.48,0.045
23.27,171.70,0.045
23.29,171.92,0.045
23.31,172.14,0.045
23.33,172.35,0.045
23.36,172.57,0.045
23.38,172.79,0.045
23.40,173.00,0.045
23.42,173.22,0.045
23.44,173.44,0.045
23.47,173.65,0.045
23.49,173.87,0.045
23.51,174.09,0.044
23.53,174.30,0.044
23.55,174.52,0.044
23.57,174.74,0.044
23.59,174.96,0.044
23.62,175.17,0.044
23.64,175.39,0.044
23.66,175.61,0.044
23.68,175.83,0.044
23.70,176.04,0.044
23.73,176.26,0.044
23.75,176.48,0.044
23.77,176.70,0.044
23.79,176.91,0.044
23.81,177.13,0.044
23.83,177.35,0.044
23.86,177.57,0.044
23.88,177.78,0.044
23.90,178.00,0.044
23.92,178.21,0.044
23.94,178.43,0.044
23.96,178.65,0.044
23.98,178.86,0.044
24.01,179.08,0.044
24.03,179.30,0.044
24.05,179.51,0.044
24.07,179.73,0.045
24.09,179.94,0.045
24.12,180.16,0.045
24.14,180.38,0.045
24.16,180.59,0.045
24.18,180.81,0.045
24.20,181.03,0.045
24.22,181.24,0.046
24.24,181.46,0.046
24.27,181.67,0.046
24.29,181.89,0.046
24.31,182.11,0.046
24.33,182.32,0.047
24.35,182.54,0.047
24.38,182.75,0.047
24.40,182.97,0.047
24.42,183.19,0.048
24.44,183.40,0.048
24.46,183.62,0.048
24.48,183.84,0.048
24.51,184.05,0.048
24.53,184.27,0.048
24.55,184.49,0.048
24.57,184.70,0.049
24.59,184.92,0.049
24.61,185.14,0.049
24.63,185.35,0.049
24.66,185.57,0.049
24.68,185.79,0.049
24.70,186.01,0.048
24.72,186.22,0.048
24.74,186.44,0.048
24.77,186.66,0.048
24.79,186.87,0.048
24.81,187.09,0.048
24.83,187.31,0.047
24.85,187.53,0.047
24.87,187.74,0.047
24.89,187.96,0.047
24.92,188.18,0.047
24.94,188.39,0.047
24.96,188.61,0.047
24.98,188.83,0.047
25.00,189.05,0.047
25.03,189.26,0.047
25.05,189.48,0.047
25.07,189.70,0.046
25.09,189.91,0.046
25.11,190.13,0.046
25.13,190.35,0.046
25.16,190.56,0.046
25.18,190.78,0.046
25.20,191.00,0.046
25.22,191.21,0.046
25.24,191.43,0.046
25.26,191.65,0.046
25.28,191.86,0.046
25.31,192.08,0.046
25.33,192.30,0.046
25.35,192.51,0.046
25.37,192.73,0.046
25.39,192.95,0.046
25.42,193.17,0.046
25.44,193.38,0.046
25.46,193.60,0.046
25.48,193.82,0.046
25.50,194.03,0.046
25.52,194.25,0.046
25.54,194.47,0.046
25.57,194.68,0.046
25.59,194.90,0.046
25.61,195.12,0.046
25.63,195.33,0.046
25.65,195.55,0.046
25.68,195.77,0.046
25.70,195.99,0.046
25.72,196.20,0.046
25.74,196.42,0.046
25.76,196.64,0.046
25.78,196.85,0.046
25.81,197.07,0.046
25.83,197.29,0.046
25.85,197.50,0.046
25.87,197.72,0.046
25.89,197.94,0.046
25.91,198.15,0.046
25.93,198.37,0.046
25.96,198.59,0.046
25.98,198.80,0.046
26.00,199.02,0.046
26.02,199.24,0.046
26.04,199.45,0.046
26.07,199.67,0.046
26.09,199.89,0.046
26.11,200.10,0.046
26.13,200.32,0.046
26.15,200.54,0.046
26.17,200.75,0.046
26.19,200.97,0.046
26.22,201.19,0.046
26.24,201.40,0.046
26.26,201.62,0.046
26.28,201.84,0.046
26.30,202.05,0.046
26.33,202.27,0.046
26.35,202.49,0.046
26.37,202.71,0.046
26.39,202.92,0.046
26.41,203.14,0.046
26.43,203.36,0.046
26.46,203.57,0.046
26.48,203.79,0.046
26.50,204.01,0.046
26.52,204.22,0.046
26.54,204.44,0.046
26.56,204.66,0.046
26.58,204.87,0.046
26.61,205.09,0.046
26.63,205.31,0.046
26.65,205.52,0.046
26.67,205.74,0.046
26.69,205.96,0.046
26.72,206.18,0.046
26.74,206.39,0.046
26.76,206.61,0.046
26.78,206.83,0.046
26.80,207.04,0.046
26.82,207.26,0.046
26.84,207.47,0.046
26.87,207.69,0.046
26.89,207.91,0.046
26.91,208.13,0.046
26.93,208.34,0.046
26.95,208.56,0.046
26.98,208.77,0.046
27.00,208.99,0.046
27.02,209.21,0.046
27.04,209.43,0.046
27.06,209.64,0.046
27.08,209.86,0.046
27.11,210.08,0.046
27.13,210.30,0.046
27.15,210.51,0.046
27.17,210.73,0.046
27.19,210.95,0.046
27.21,211.16,0.046
27.23,211.38,0.046
27.26,211.60,0.046
27.28,211.81,0.046
27.30,212.03,0.046
27.32,212.25,0.046
27.34,212.46,0.046
27.37,212.68,0.046
27.39,212.89,0.046
27.41,213.11,0.046
27.43,213.33,0.046
27.45,213.54,0.046
27.47,213.76,0.046
27.49,213.98,0.046
27.52,214.20,0.046
27.54,214.41,0.046
27.56,214.63,0.046
27.58,214.85,0.046
27.60,215.06,0.046
27.63,215.28,0.046
27.65,215.50,0.047
27.67,215.72,0.047
27.69,215.93,0.047
27.71,216.15,0.047
27.73,216.36,0.047
27.76,216.58,0.047
27.78,216.80,0.047
27.80,217.01,0.047
27.82,217.23,0.047
27.84,217.45,0.047
27.86,217.66,0.047
27.88,217.88,0.047
27.91,218.10,0.047
27.93,218.32,0.047
27.95,218.53,0.047
27.97,218.75,0.047
27.99,218.96,0.047
28.02,219.18,0.047
28.04,219.40,0.047
28.06,219.61,0.047
28.08,219.83,0.047
28.10,220.05,0.047
28.12,220.26,0.047
28.14,220.48,0.047
28.17,220.70,0.047
28.19,220.92,0.047
28.21,221.13,0.047
28.23,221.35,0.047
28.25,221.57,0.047
28.28,221.78,0.047
28.30,222.00,0.047
28.32,222.22,0.047
28.34,222.43,0.047
28.36,222.65,0.047
28.38,222.87,0.047
28.41,223.08,0.047
28.43,223.30,0.047
28.45,223.52,0.047
28.47,223.73,0.047
28.49,223.95,0.047
28.51,224.17,0.047
28.53,224.39,0.047
28.56,224.60,0.047
28.58,224.82,0.047
28.60,225.04,0.047
28.62,225.25,0.047
28.64,225.47,0.047
28.67,225.68,0.047
28.69,225.90,0.047
28.71,226.12,0.047
28.73,226.34,0.047
28.75,226.55,0.047
28.77,226.77,0.047
28.79,226.99,0.047
28.82,227.20,0.047
28.84,227.42,0.047
28.86,227.64,0.047
28.88,227.85,0.047
28.90,228.07,0.047
28.93,228.29,0.047
28.95,228.50,0.047
28.97,228.72,0.047
28.99,228.94,0.047
29.01,229.15,0.047
29.03,229.37,0.047
29.06,229.59,0.047
29.08,229.81,0.047
29.10,230.02,0.047
29.12,230.24,0.047
29.14,230.46,0.047
29.16,230.67,0.047
29.18,230.89,0.047
29.21,231.11,0.047
29.23,231.32,0.047
29.25,231.54,0.047
29.27,231.76,0.047
29.29,231.97,0.047
29.32,232.19,0.048
29.34,232.41,0.048
29.36,232.62,0.048
29.38,232.84,0.048
29.40,233.06,0.048
29.42,233.27,0.048
29.44,233.49,0.048
29.47,233.71,0.048
29.49,233.92,0.048
29.51,234.14,0.048
29.53,234.36,0.048
29.55,234.57,0.048
29.58,234.79,0.048
29.60,235.01,0.048
29.62,235.22,0.048
29.64,235.44,0.048
29.66,235.66,0.048
29.68,235.87,0.048
29.71,236.09,0.048
29.73,236.31,0.048
29.75,236.52,0.048
29.77,236.74,0.048
29.79,236.96,0.048
29.81,237.17,0.048
29.83,237.39,0.048
29.86,237.61,0.048
29.88,237.83,0.048
29.90,238.04,0.048
29.92,238.26,0.048
29.94,238.48,0.048
29.97,238.69,0.048
29.99,238.91,0.048
30.01,239.13,0.048
30.03,239.34,0.048
30.05,239.56,0.048
30.07,239.78,0.048
30.09,239.99,0.048
30.12,240.21,0.048
30.14,240.43,0.048
30.16,240.64,0.048
30.18,240.86,0.048
30.20,241.08,0.048
30.23,241.29,0.048
30.25,241.51,0.048
30.27,241.73,0.048
30.29,241.94,0.048
30.31,242.16,0.048
30.33,242.38,0.048
30.36,242.59,0.048
30.38,242.81,0.048
30.40,243.03,0.048
30.42,243.24,0.048
30.44,243.46,0.048
30.46,243.68,0.048
30.48,243.90,0.048
30.51,244.11,0.048
30.53,244.33,0.048
30.55,244.55,0.048
30.57,244.76,0.048
30.59,244.98,0.048
30.62,245.20,0.048
30.64,245.41,0.048
30.66,245.63,0.048
30.68,245.85,0.048
30.70,246.06,0.048
30.72,246.28,0.048
30.74,246.50,0.049
30.77,246.71,0.049
30.79,246.93,0.049
30.81,247.15,0.049
30.83,247.36,0.049
30.85,247.58,0.049
30.88,247.80,0.049
30.90,248.01,0.049
30.92,248.23,0.049
30.94,248.45,
30.96,248.66,
30.98,248.88,
30.99,,

[step]
Ramp 10.00 °C/min to -60.00 °C
Time,Temperature,Heat Flow (Normalized)
min,°C,W/g
32.99,250.17,-0.006
33.02,250.17,-0.006
33.04,250.16,-0.006
33.06,250.14,-0.006
33.08,250.09,-0.007
33.10,250.00,-0.013
33.12,249.89,-0.021
33.14,249.74,-0.030
33.17,249.57,-0.039
33.19,249.38,-0.045
33.21,249.19,-0.050
33.23,248.98,-0.053
33.25,248.78,-0.055
33.28,248.57,-0.057
33.30,248.35,-0.057
33.32,248.14,-0.058
33.34,247.93,-0.058
33.36,247.71,-0.059
33.38,247.50,-0.059
33.41,247.28,-0.059
33.43,247.07,-0.059
33.45,246.86,-0.059
33.47,246.64,-0.059
33.49,246.43,-0.059
33.51,246.21,-0.059
33.53,246.00,-0.059
33.56,245.78,-0.059
33.58,245.56,-0.059
33.60,245.35,-0.059
33.62,245.14,-0.059
33.64,244.92,-0.059
33.67,244.70,-0.059
33.69,244.49,-0.059
33.71,244.28,-0.059
33.73,244.06,-0.059
33.75,243.84,-0.060
33.77,243.63,-0.060
33.79,243.41,-0.060
33.82,243.20,-0.060
33.84,242.98,-0.060
33.86,242.77,-0.060
33.88,242.55,-0.060
33.90,242.33,-0.060
33.93,242.12,-0.060
33.95,241.90,-0.060
33.97,241.69,-0.060
33.99,241.47,-0.060
34.01,241.25,-0.060
34.03,241.04,-0.060
34.06,240.82,-0.060
34.08,240.61,-0.060
34.10,240.39,-0.060
34.12,240.18,-0.060
34.14,239.96,-0.060
34.16,239.74,-0.060
34.19,239.53,-0.060
34.21,239.31,-0.060
34.23,239.10,-0.060
34.25,238.88,-0.059
34.27,238.66,-0.059
34.29,238.45,-0.059
34.31,238.23,-0.059
34.34,238.02,-0.059
34.36,237.80,-0.059
34.38,237.58,-0.059
34.40,237.37,-0.059
34.42,237.15,-0.059
34.44,236.93,-0.059
34.47,236.72,-0.059
34.49,236.50,-0.059
34.51,236.28,-0.059
34.53,236.07,-0.059
34.55,235.85,-0.059
34.58,235.63,-0.059
34.60,235.42,-0.059
34.62,235.20,-0.059
34.64,234.99,-0.059
34.66,234.77,-0.059
34.68,234.55,-0.059
34.71,234.34,-0.059
34.73,234.12,-0.059
34.75,233.90,-0.059
34.77,233.69,-0.059
34.79,233.47,-0.059
34.81,233.25,-0.059
34.84,233.04,-0.059
34.86,232.82,-0.059
34.88,232.61,-0.059
34.90,232.39,-0.059
34.92,232.17,-0.059
34.94,231.96,-0.059
34.96,231.74,-0.059
34.99,231.52,-0.059
35.01,231.31,-0.059
35.03,231.09,-0.059
35.05,230.87,-0.059
35.07,230.66,-0.059
35.09,230.44,-0.059
35.12,230.23,-0.059
35.14,230.01,-0.059
35.16,229.79,-0.059
35.18,229.58,-0.059
35.20,229.36,-0.059
35.23,229.14,-0.059
35.25,228.93,-0.059
35.27,228.71,-0.059
35.29,228.49,-0.059
35.31,228.28,-0.059
35.33,228.06,-0.059
35.36,227.84,-0.059
35.38,227.63,-0.059
35.40,227.41,-0.059
35.42,227.19,-0.059
35.44,226.98,-0.059
35.46,226.76,-0.059
35.49,226.54,-0.059
35.51,226.33,-0.059
35.53,226.11,-0.059
35.55,225.89,-0.059
35.57,225.68,-0.059
35.59,225.46,-0.059
35.61,225.24,-0.059
35.64,225.03,-0.059
35.66,224.81,-0.059
35.68,224.59,-0.059
35.70,224.38,-0.059
35.72,224.16,-0.059
35.74,223.95,-0.059
35.77,223.73,-0.059
35.79,223.51,-0.059
35.81,223.30,-0.059
35.83,223.08,-0.059
35.85,222.86,-0.058
35.88,222.65,-0.058
35.90,222.43,-0.058
35.92,222.21,-0.058
35.94,222.00,-0.058
35.96,221.78,-0.058
35.98,221.56,-0.058
36.01,221.35,-0.058
36.03,221.13,-0.058
36.05,220.91,-0.058
36.07,220.70,-0.058
36.09,220.48,-0.058
36.11,220.26,-0.058
36.14,220.05,-0.058
36.16,219.83,-0.058
36.18,219.62,-0.058
36.20,219.40,-0.058
36.22,219.18,-0.058
36.24,218.97,-0.058
36.26,218.75,-0.058
36.29,218.53,-0.058
36.31,218.32,-0.058
36.33,218.10,-0.058
36.35,217.88,-0.058
36.37,217.66,-0.058
36.39,217.45,-0.058
36.42,217.23,-0.058
36.44,217.01,-0.058
36.46,216.80,-0.058
36.48,216.58,-0.058
36.50,216.37,-0.058
36.53,216.15,-0.058
36.55,215.93,-0.058
36.57,215.72,-0.058
36.59,215.50,-0.058
36.61,215.28,-0.058
36.63,215.07,-0.058
36.66,214.85,-0.058
36.68,214.63,-0.058
36.70,214.42,-0.058
36.72,214.20,-0.058
36.74,213.98,-0.058
36.76,213.77,-0.058
36.79,213.55,-0.058
36.81,213.33,-0.058
36.83,213.11,-0.058
36.85,212.90,-0.058
36.87,212.68,-0.058
36.89,212.47,-0.058
36.91,212.25,-0.058
36.94,212.03,-0.058
36.96,211.82,-0.058
36.98,211.60,-0.058
37.00,211.38,-0.058
37.02,211.17,-0.058
37.04,210.95,-0.058
37.07,210.73,-0.058
37.09,210.52,-0.058
37.11,210.30,-0.058
37.13,210.08,-0.058
37.15,209.87,-0.058
37.18,209.65,-0.058
37.20,209.43,-0.058
37.22,209.22,-0.058
37.24,209.00,-0.058
37.26,208.79,-0.058
37.28,208.57,-0.058
37.31,208.35,-0.058
37.33,208.13,-0.058
37.35,207.92,-0.058
37.37,207.70,-0.058
37.39,207.48,-0.058
37.41,207.27,-0.058
37.44,207.05,-0.057
37.46,206.84,-0.057
37.48,206.62,-0.057
37.50,206.40,-0.057
37.52,206.18,-0.057
37.54,205.97,-0.057
37.56,205.75,-0.057
37.59,205.54,-0.057
37.61,205.32,-0.057
37.63,205.10,-0.057
37.65,204.89,-0.057
37.67,204.67,-0.057
37.69,204.45,-0.057
37.72,204.24,-0.057
37.74,204.02,-0.057
37.76,203.80,-0.057
37.78,203.59,-0.057
37.80,203.37,-0.057
37.83,203.15,-0.057
37.85,202.94,-0.057
37.87,202.72,-0.057
37.89,202.50,-0.057
37.91,202.29,-0.057
37.93,202.07,-0.057
37.96,201.85,-0.057
37.98,201.64,-0.057
38.00,201.42,-0.057
38.02,201.20,-0.057
38.04,200.99,-0.057
38.06,200.77,-0.057
38.09,200.55,-0.057
38.11,200.34,-0.057
38.13,200.12,-0.057
38.15,199.90,-0.057
38.17,199.69,-0.057
38.19,199.47,-0.057
38.21,199.25,-0.057
38.24,199.04,-0.057
38.26,198.82,-0.057
38.28,198.61,-0.057
38.30,198.39,-0.057
38.32,198.17,-0.057
38.34,197.96,-0.057
38.37,197.74,-0.057
38.39,197.52,-0.057
38.41,197.31,-0.057
38.43,197.09,-0.057
38.45,196.87,-0.057
38.48,196.66,-0.057
38.50,196.44,-0.057
38.52,196.22,-0.057
38.54,196.01,-0.057
38.56,195.79,-0.057
38.58,195.57,-0.057
38.61,195.36,-0.057
38.63,195.14,-0.057
38.65,194.92,-0.057
38.67,194.71,-0.057
38.69,194.49,-0.057
38.71,194.27,-0.057
38.74,194.06,-0.057
38.76,193.84,-0.057
38.78,193.62,-0.057
38.80,193.41,-0.057
38.82,193.19,-0.057
38.84,192.97,-0.057
38.86,192.76,-0.057
38.89,192.54,-0.057
38.91,192.32,-0.057
38.93,192.11,-0.057
38.95,191.89,-0.057
38.97,191.67,-0.057
38.99,191.46,-0.057
39.02,191.24,-0.057
39.04,191.02,-0.057
39.06,190.81,-0.057
39.08,190.59,-0.057
39.10,190.37,-0.057
39.13,190.16,-0.057
39.15,189.94,-0.057
39.17,189.72,-0.057
39.19,189.51,-0.056
39.21,189.29,-0.056
39.23,189.08,-0.056
39.26,188.86,-0.056
39.28,188.64,-0.056
39.30,188.43,-0.056
39.32,188.21,-0.056
39.34,187.99,-0.056
39.36,187.77,-0.056
39.39,187.56,-0.056
39.41,187.34,-0.056
39.43,187.12,-0.056
39.45,186.91,-0.056
39.47,186.69,-0.056
39.49,186.47,-0.056
39.51,186.26,-0.056
39.54,186.04,-0.056
39.56,185.83,-0.056
39.58,185.61,-0.056
39.60,185.39,-0.056
39.62,185.18,-0.056
39.64,184.96,-0.056
39.67,184.74,-0.056
39.69,184.53,-0.056
39.71,184.31,-0.056
39.73,184.09,-0.056
39.75,183.88,-0.056
39.78,183.66,-0.056
39.80,183.44,-0.056
39.82,183.23,-0.056
39.84,183.01,-0.056
39.86,182.79,-0.056
39.88,182.58,-0.056
39.91,182.36,-0.056
39.93,182.14,-0.056
39.95,181.93,-0.056
39.97,181.71,-0.055
39.99,181.49,-0.055
40.01,181.28,-0.055
40.04,181.06,-0.055
40.06,180.84,-0.055
40.08,180.63,-0.055
40.10,180.41,-0.055
40.12,180.19,-0.055
40.14,179.97,-0.055
40.16,179.76,-0.055
40.19,179.54,-0.055
40.21,179.33,-0.055
40.23,179.11,-0.055
40.25,178.89,-0.055
40.27,178.68,-0.055
40.29,178.46,-0.055
40.32,178.24,-0.054
40.34,178.02,-0.054
40.36,177.81,-0.054
40.38,177.59,-0.054
40.40,177.37,-0.054
40.43,177.16,-0.054
40.45,176.94,-0.054
40.47,176.72,-0.054
40.49,176.50,-0.054
40.51,176.29,-0.054
40.53,176.07,-0.054
40.56,175.85,-0.054
40.58,175.64,-0.053
40.60,175.42,-0.053
40.62,175.20,-0.053
40.64,174.99,-0.053
40.66,174.77,-0.053
40.69,174.55,-0.053
40.71,174.34,-0.053
40.73,174.12,-0.053
40.75,173.90,-0.053
40.77,173.69,-0.053
40.79,173.47,-0.053
40.81,173.25,-0.053
40.84,173.04,-0.052
40.86,172.82,-0.052
40.88,172.60,-0.052
40.90,172.39,-0.052
40.92,172.17,-0.052
40.94,171.95,-0.052
40.97,171.74,-0.052
40.99,171.52,-0.052
41.01,171.31,-0.052
41.03,171.09,-0.052
41.05,170.87,-0.052
41.08,170.65,-0.052
41.10,170.44,-0.052
41.12,170.22,-0.052
41.14,170.00,-0.051
41.16,169.79,-0.051
41.18,169.57,-0.051
41.21,169.35,-0.051
41.23,169.14,-0.051
[...]
140.98,28.67,0.027
141.01,28.88,0.027
141.03,29.10,0.027
141.05,29.32,0.028
141.07,29.53,0.028
141.09,29.75,0.028
141.12,29.97,0.028
141.14,30.18,0.028
141.16,30.40,0.028
141.18,30.62,0.028
141.20,30.83,0.028
141.22,31.05,0.028
141.25,31.27,0.028
141.27,31.49,0.028
141.29,31.70,0.028
141.31,31.92,0.028
141.33,32.14,0.028
141.35,32.35,0.028
141.38,32.57,0.028
141.40,32.79,0.028
141.42,33.00,0.028
141.44,33.22,0.028
141.46,33.44,0.028
141.48,33.65,0.028
141.50,33.87,0.028
141.53,34.09,0.028
141.55,34.30,0.028
141.57,34.52,0.028
141.59,34.74,0.028
141.61,34.96,0.028
141.63,35.17,0.028
141.66,35.39,0.028
141.68,35.60,0.028
141.70,35.82,0.028
141.72,36.04,0.028
141.74,36.26,0.028
141.77,36.47,0.028
141.79,36.69,0.028
141.81,36.91,0.028
141.83,37.13,0.028
141.85,37.34,0.028
141.87,37.56,0.028
141.90,37.77,0.028
141.92,37.99,0.028
141.94,38.21,0.028
141.96,38.43,0.028
141.98,38.64,0.028
142.00,38.86,0.028
142.03,39.08,0.028
142.05,39.29,0.028
142.07,39.51,0.028
142.09,39.73,0.028
142.11,39.94,0.028
142.13,40.16,0.028
142.15,40.38,0.028
142.18,40.59,0.028
142.20,40.81,0.028
142.22,41.03,0.028
142.24,41.25,0.028
142.26,41.46,0.028
142.28,41.68,0.028
142.31,41.90,0.029
142.33,42.11,0.029
142.35,42.33,0.029
142.37,42.55,0.029
142.39,42.76,0.029
142.42,42.98,0.029
142.44,43.20,0.029
142.46,43.41,0.029
142.48,43.63,0.029
142.50,43.85,0.029
142.52,44.06,0.029
142.55,44.28,0.029
142.57,44.50,0.029
142.59,44.71,0.029
142.61,44.93,0.029
142.63,45.15,0.029
142.65,45.37,0.029
142.68,45.58,0.029
142.70,45.80,0.029
142.72,46.02,0.029
142.74,46.23,0.029
142.76,46.45,0.029
142.78,46.67,0.029
142.80,46.88,0.029
142.83,47.10,0.029
142.85,47.32,0.029
142.87,47.54,0.029
142.89,47.75,0.029
142.91,47.97,0.029
142.93,48.19,0.029
142.96,48.40,0.029
142.98,48.62,0.029
143.00,48.84,0.029
143.02,49.05,0.029
143.04,49.27,0.029
143.07,49.49,0.029
143.09,49.70,0.029
143.11,49.92,0.029
143.13,50.14,0.029
143.15,50.35,0.029
143.17,50.57,0.029
143.20,50.79,0.029
143.22,51.00,0.029
143.24,51.22,0.029
143.26,51.44,0.029
143.28,51.65,0.029
143.30,51.87,0.029
143.33,52.09,0.029
143.35,52.31,0.029
143.37,52.52,0.029
143.39,52.74,0.029
143.41,52.96,0.029
143.43,53.17,0.029
143.45,53.39,0.029
143.48,53.61,0.029
143.50,53.82,0.029
143.52,54.04,0.029
143.54,54.26,0.029
143.56,54.47,0.029
143.58,54.69,0.029
143.61,54.91,0.030
143.63,55.13,0.030
143.65,55.34,0.030
143.67,55.56,0.030
143.69,55.78,0.030
143.72,55.99,0.030
143.74,56.21,0.030
143.76,56.43,0.030
143.78,56.64,0.030
143.80,56.86,0.030
143.82,57.08,0.030
143.85,57.29,0.030
143.87,57.51,0.030
143.89,57.73,0.030
143.91,57.94,0.030
143.93,58.16,0.030
143.95,58.38,0.030
143.98,58.60,0.030
144.00,58.81,0.030
144.02,59.03,0.030
144.04,59.25,0.030
144.06,59.46,0.030
144.08,59.68,0.030
144.10,59.90,0.030
144.13,60.11,0.030
144.15,60.33,0.030
144.17,60.55,0.030
144.19,60.76,0.030
144.21,60.98,0.030
144.23,61.20,0.030
144.26,61.41,0.030
144.28,61.63,0.030
144.30,61.85,0.030
144.32,62.06,0.030
144.34,62.28,0.030
144.37,62.50,0.030
144.39,62.72,0.030
144.41,62.93,0.030
144.43,63.15,0.030
144.45,63.37,0.030
144.47,63.58,0.030
144.50,63.80,0.030
144.52,64.02,0.030
144.54,64.23,0.030
144.56,64.45,0.030
144.58,64.67,0.030
144.60,64.89,0.030
144.63,65.10,0.030
144.65,65.32,0.030
144.67,65.54,0.030
144.69,65.75,0.030
144.71,65.97,0.030
144.73,66.19,0.030
144.75,66.40,0.030
144.78,66.62,0.030
144.80,66.84,0.030
144.82,67.05,0.030
144.84,67.27,0.030
144.86,67.49,0.030
144.88,67.70,0.030
144.91,67.92,0.030
144.93,68.14,0.031
144.95,68.36,0.031
144.97,68.57,0.031
144.99,68.79,0.031
145.02,69.01,0.031
145.04,69.22,0.031
145.06,69.44,0.031
145.08,69.66,0.031
145.10,69.87,0.031
145.12,70.09,0.031
145.15,70.31,0.031
145.17,70.52,0.031
145.19,70.74,0.031
145.21,70.96,0.031
145.23,71.17,0.031
145.25,71.39,0.031
145.28,71.61,0.031
145.30,71.82,0.031
145.32,72.04,0.031
145.34,72.26,0.031
145.36,72.47,0.031
145.38,72.69,0.031
145.40,72.91,0.031
145.43,73.12,0.031
145.45,73.34,0.031
145.47,73.56,0.031
145.49,73.77,0.031
145.51,73.99,0.031
145.53,74.21,0.031
145.56,74.43,0.031
145.58,74.64,0.031
145.60,74.86,0.031
145.62,75.08,0.031
145.64,75.29,0.031
145.67,75.51,0.031
145.69,75.73,0.031
145.71,75.94,0.031
145.73,76.16,0.031
145.75,76.38,0.031
145.77,76.60,0.031
145.80,76.81,0.031
145.82,77.03,0.031
145.84,77.24,0.031
145.86,77.46,0.031
145.88,77.68,0.031
145.90,77.89,0.031
145.93,78.11,0.031
145.95,78.33,0.031
145.97,78.55,0.031
145.99,78.76,0.031
146.01,78.98,0.031
146.03,79.20,0.031
146.05,79.41,0.031
146.08,79.63,0.031
146.10,79.85,0.031
146.12,80.06,0.031
146.14,80.28,0.031
146.16,80.50,0.031
146.18,80.71,0.031
146.21,80.93,0.031
146.23,81.15,0.032
146.25,81.37,0.032
146.27,81.58,0.032
146.29,81.80,0.032
146.32,82.02,0.032
146.34,82.23,0.032
146.36,82.45,0.032
146.38,82.67,0.032
146.40,82.88,0.032
146.42,83.10,0.032
146.45,83.32,0.032
146.47,83.53,0.032
146.49,83.75,0.032
146.51,83.97,0.032
146.53,84.18,0.032
146.55,84.40,0.032
146.58,84.62,0.032
146.60,84.83,0.032
146.62,85.05,0.032
146.64,85.27,0.032
146.66,85.49,0.032
146.68,85.70,0.032
146.70,85.92,0.032
146.73,86.14,0.032
146.75,86.35,0.032
146.77,86.57,0.032
146.79,86.79,0.032
146.81,87.00,0.032
146.83,87.22,0.032
146.86,87.44,0.032
146.88,87.65,0.032
146.90,87.87,0.032
146.92,88.09,0.032
146.94,88.30,0.032
146.97,88.52,0.032
146.99,88.74,0.032
147.01,88.95,0.032
147.03,89.17,0.032
147.05,89.39,0.032
147.07,89.60,0.032
147.10,89.82,0.032
147.12,90.04,0.032
147.14,90.25,0.032
147.16,90.47,0.032
147.18,90.69,0.032
147.20,90.91,0.032
147.23,91.12,0.032
147.25,91.34,0.032
147.27,91.56,0.032
147.29,91.77,0.032
147.31,91.99,0.032
147.33,92.21,0.032
147.35,92.42,0.032
147.38,92.64,0.032
147.40,92.86,0.032
147.42,93.07,0.032
147.44,93.29,0.032
147.46,93.51,0.032
147.48,93.72,0.033
147.51,93.94,0.033
147.53,94.16,0.033
147.55,94.37,0.033
147.57,94.59,0.033
147.59,94.81,0.033
147.62,95.03,0.033
147.64,95.24,0.033
147.66,95.46,0.033
147.68,95.68,0.033
147.70,95.89,0.033
147.72,96.11,0.033
147.75,96.33,0.033
147.77,96.54,0.033
147.79,96.76,0.033
147.81,96.98,0.033
147.83,97.20,0.033
147.85,97.41,0.033
147.88,97.63,0.033
147.90,97.85,0.033
147.92,98.06,0.033
147.94,98.28,0.033
147.96,98.50,0.033
147.98,98.71,0.033
148.00,98.93,0.033
148.03,99.15,0.033
148.05,99.36,0.033
148.07,99.58,0.033
148.09,99.80,0.033
148.11,100.01,0.033
148.13,100.23,0.033
148.16,100.45,0.033
148.18,100.66,0.033
148.20,100.88,0.033
148.22,101.10,0.033
148.24,101.31,0.033
148.27,101.53,0.033
148.29,101.75,0.033
148.31,101.96,0.033
148.33,102.18,0.033
148.35,102.40,0.033
148.37,102.62,0.033
148.40,102.83,0.033
148.42,103.05,0.033
148.44,103.27,0.033
148.46,103.48,0.033
148.48,103.70,0.033
148.50,103.92,0.033
148.53,104.13,0.033
148.55,104.35,0.033
148.57,104.57,0.033
148.59,104.78,0.033
148.61,105.00,0.033
148.63,105.22,0.033
148.65,105.43,0.033
148.68,105.65,0.033
148.70,105.87,0.033
148.72,106.08,0.033
148.74,106.30,0.034
148.76,106.52,0.034
148.78,106.74,0.034
148.81,106.95,0.034
148.83,107.17,0.034
148.85,107.39,0.034
148.87,107.60,0.034
148.89,107.82,0.034
148.92,108.03,0.034
148.94,108.25,0.034
148.96,108.47,0.034
148.98,108.69,0.034
149.00,108.90,0.034
149.02,109.12,0.034
149.05,109.34,0.034
149.07,109.55,0.034
149.09,109.77,0.034
149.11,109.99,0.034
149.13,110.20,0.034
149.15,110.42,0.034
149.18,110.64,0.034
149.20,110.85,0.034
149.22,111.07,0.034
149.24,111.29,0.034
149.26,111.50,0.034
149.28,111.72,0.034
149.30,111.94,0.034
149.33,112.15,0.034
149.35,112.37,0.034
149.37,112.59,0.034
149.39,112.80,0.034
149.41,113.02,0.034
149.43,113.24,0.034
149.46,113.45,0.034
149.48,113.67,0.034
149.50,113.89,0.034
149.52,114.11,0.034
149.54,114.32,0.034
149.57,114.54,0.034
149.59,114.76,0.034
149.61,114.97,0.034
149.63,115.19,0.034
149.65,115.41,0.034
149.67,115.62,0.034
149.70,115.84,0.034
149.72,116.06,0.034
149.74,116.28,0.034
149.76,116.49,0.034
149.78,116.71,0.034
149.80,116.93,0.034
149.83,117.14,0.034
149.85,117.36,0.034
149.87,117.58,0.034
149.89,117.79,0.034
149.91,118.01,0.034
149.93,118.23,0.034
149.95,118.44,0.034
149.98,118.66,0.035
150.00,118.88,0.035
150.02,119.09,0.035
150.04,119.31,0.035
150.06,119.53,0.035
150.08,119.74,0.035
150.11,119.96,0.035
150.13,120.18,0.035
150.15,120.40,0.035
150.17,120.61,0.035
150.19,120.83,0.035
150.22,121.05,0.035
150.24,121.26,0.035
150.26,121.48,0.035
150.28,121.70,0.035
150.30,121.91,0.035
150.32,122.13,0.035
150.35,122.35,0.035
150.37,122.56,0.035
150.39,122.78,0.035
150.41,123.00,0.035
150.43,123.21,0.035
150.45,123.43,0.035
150.48,123.65,0.035
150.50,123.86,0.035
150.52,124.08,0.035
150.54,124.30,0.035
150.56,124.51,0.035
150.58,124.73,0.035
150.60,124.95,0.035
150.63,125.16,0.035
150.65,125.38,0.035
150.67,125.60,0.035
150.69,125.82,0.035
150.71,126.03,0.035
150.73,126.25,0.035
150.76,126.47,0.035
150.78,126.68,0.035
150.80,126.90,0.035
150.82,127.12,0.035
150.84,127.33,0.035
150.87,127.55,0.035
150.89,127.77,0.035
150.91,127.98,0.035
150.93,128.20,0.035
150.95,128.42,0.035
150.97,128.64,0.035
151.00,128.85,0.035
151.02,129.07,0.035
151.04,129.29,0.035
151.06,129.50,0.035
151.08,129.72,0.035
151.10,129.94,0.035
151.13,130.15,0.035
151.15,130.37,0.035
151.17,130.59,0.035
151.19,130.80,0.035
151.21,131.02,0.035
151.23,131.24,0.035
151.25,131.45,0.035
151.28,131.67,0.035
151.30,131.89,0.036
151.32,132.10,0.036
151.34,132.32,0.036
151.36,132.54,0.036
151.38,132.76,0.036
151.41,132.98,0.036
151.43,133.19,0.036
151.45,133.41,0.036
151.47,133.63,0.036
151.49,133.84,0.036
151.52,134.06,0.036
151.54,134.28,0.036
151.56,134.49,0.036
151.58,134.71,0.036
151.60,134.93,0.036
151.62,135.14,0.036
151.65,135.36,0.036
151.67,135.57,0.036
151.69,135.79,0.036
151.71,136.01,0.036
151.73,136.23,0.036
151.75,136.44,0.036
151.78,136.66,0.036
151.80,136.88,0.036
151.82,137.10,0.036
151.84,137.31,0.036
151.86,137.53,0.036
151.88,137.75,0.036
151.90,137.96,0.036
151.93,138.18,0.036
151.95,138.39,0.036
151.97,138.61,0.036
151.99,138.83,0.036
152.01,139.05,0.036
152.03,139.26,0.036
152.06,139.48,0.036
152.08,139.69,0.036
152.10,139.91,0.036
152.12,140.13,0.036
152.14,140.35,0.036
152.17,140.56,0.036
152.19,140.78,0.036
152.21,141.00,0.036
152.23,141.21,0.036
152.25,141.43,0.036
152.27,141.65,0.036
152.30,141.86,0.036
152.32,142.08,0.036
152.34,142.30,0.036
152.36,142.51,0.036
152.38,142.73,0.036
152.40,142.95,0.036
152.43,143.16,0.036
152.45,143.38,0.036
152.47,143.60,0.036
152.49,143.81,0.036
152.51,144.03,0.036
152.53,144.25,0.036
152.55,144.46,0.036
152.58,144.68,0.037
152.60,144.90,0.037
152.62,145.11,0.037
152.64,145.33,0.037
152.66,145.55,0.037
152.68,145.77,0.037
152.71,145.98,0.037
152.73,146.20,0.037
152.75,146.41,0.037
152.77,146.63,0.037
152.79,146.85,0.037
152.82,147.07,0.037
152.84,147.28,0.037
152.86,147.50,0.037
152.88,147.72,0.037
152.90,147.93,0.037
152.92,148.15,0.037
152.95,148.37,0.037
152.97,148.58,0.037
152.99,148.80,0.037
153.01,149.01,0.037
153.03,149.23,0.037
153.05,149.45,0.037
153.08,149.67,0.037
153.10,149.88,0.037
153.12,150.10,0.037
153.14,150.32,0.037
153.16,150.53,0.037
153.18,150.75,0.037
153.20,150.97,0.037
153.23,151.18,0.037
153.25,151.40,0.037
153.27,151.62,0.037
153.29,151.83,0.037
153.31,152.05,0.037
153.33,152.27,0.037
153.36,152.48,0.037
153.38,152.70,0.037
153.40,152.92,0.037
153.42,153.14,0.037
153.44,153.35,0.037
153.47,153.57,0.037
153.49,153.78,0.037
153.51,154.00,0.037
153.53,154.22,0.037
153.55,154.43,0.037
153.57,154.65,0.037
153.60,154.87,0.037
153.62,155.09,0.037
153.64,155.30,0.037
153.66,155.52,0.037
153.68,155.74,0.037
153.70,155.95,0.037
153.73,156.17,0.038
153.75,156.39,0.038
153.77,156.60,0.038
153.79,156.82,0.038
153.81,157.04,0.038
153.83,157.26,0.038
153.85,157.47,0.038
153.88,157.69,0.038
153.90,157.91,0.038
153.92,158.12,0.038
153.94,158.34,0.038
153.96,158.56,0.038
153.98,158.77,0.038
154.01,158.99,0.038
154.03,159.21,0.038
154.05,159.42,0.038
154.07,159.64,0.038
154.09,159.85,0.038
154.12,160.07,0.038
154.14,160.29,0.038
154.16,160.51,0.038
154.18,160.72,0.038
154.20,160.94,0.038
154.22,161.16,0.038
154.25,161.37,0.038
154.27,161.59,0.038
154.29,161.81,0.038
154.31,162.02,0.038
154.33,162.24,0.038
154.35,162.46,0.038
154.38,162.67,0.038
154.40,162.89,0.038
154.42,163.11,0.038
154.44,163.32,0.038
154.46,163.54,0.038
154.48,163.76,0.038
154.50,163.98,0.038
154.53,164.19,0.038
154.55,164.41,0.038
154.57,164.63,0.038
154.59,164.84,0.038
154.61,165.06,0.038
154.63,165.28,0.038
154.66,165.49,0.038
154.68,165.71,0.038
154.70,165.93,0.039
154.72,166.14,0.039
154.74,166.36,0.039
154.77,166.58,0.039
154.79,166.79,0.039
154.81,167.01,0.039
154.83,167.23,0.039
154.85,167.44,0.039
154.87,167.66,0.039
154.90,167.88,0.039
154.92,168.09,0.039
154.94,168.31,0.039
154.96,168.53,0.039
154.98,168.75,0.039
155.00,168.96,0.039
155.03,169.18,0.039
155.05,169.40,0.039
155.07,169.61,0.039
155.09,169.83,0.039
155.11,170.05,0.039
155.13,170.26,0.039
155.15,170.48,0.039
155.18,170.69,0.039
155.20,170.91,0.039
155.22,171.13,0.039
155.24,171.35,0.039
155.26,171.56,0.039
155.28,171.78,0.039
155.31,172.00,0.040
155.33,172.21,0.040
155.35,172.43,0.040
155.37,172.65,0.040
155.39,172.86,0.040
155.42,173.08,0.040
155.44,173.30,0.040
155.46,173.51,0.040
155.48,173.73,0.040
155.50,173.95,0.040
155.52,174.16,0.040
155.55,174.38,0.040
155.57,174.60,0.040
155.59,174.81,0.040
155.61,175.03,0.040
155.63,175.25,0.040
155.65,175.46,0.040
155.68,175.68,0.040
155.70,175.90,0.041
155.72,176.11,0.041
155.74,176.33,0.041
155.76,176.54,0.041
155.78,176.76,0.041
155.80,176.98,0.041
155.83,177.19,0.041
155.85,177.41,0.041
155.87,177.63,0.041
155.89,177.84,0.041
155.91,178.06,0.041
155.93,178.28,0.042
155.96,178.50,0.042
155.98,178.71,0.042
156.00,178.93,0.042
156.02,179.15,0.042
156.04,179.36,0.042
156.07,179.58,0.042
156.09,179.80,0.043
156.11,180.01,0.043
156.13,180.23,0.043
156.15,180.44,0.043
156.17,180.66,0.043
156.20,180.88,0.044
156.22,181.09,0.044
156.24,181.31,0.044
156.26,181.53,0.044
156.28,181.74,0.045
156.30,181.96,0.045
156.33,182.18,0.045
156.35,182.39,0.046
156.37,182.61,0.046
156.39,182.83,0.046
156.41,183.04,0.046
156.43,183.26,0.046
156.45,183.48,0.046
156.48,183.69,0.047
156.50,183.91,0.047
156.52,184.12,0.047
156.54,184.34,0.047
156.56,184.56,0.047
156.58,184.77,0.047
156.61,184.99,0.047
156.63,185.21,0.047
156.65,185.42,0.047
156.67,185.64,0.047
156.69,185.86,0.047
156.72,186.07,0.047
156.74,186.29,0.047
156.76,186.51,0.047
156.78,186.73,0.047
156.80,186.95,0.047
156.82,187.16,0.047
156.85,187.38,0.047
156.87,187.60,0.047
156.89,187.81,0.047
156.91,188.03,0.047
156.93,188.25,0.047
156.95,188.46,0.047
156.98,188.68,0.047
157.00,188.90,0.047
157.02,189.11,0.047
157.04,189.33,0.047
157.06,189.55,0.047
157.08,189.76,0.047
157.10,189.98,0.047
157.13,190.20,0.047
157.15,190.41,0.047
157.17,190.63,0.047
157.19,190.85,0.046
157.21,191.07,0.046
157.23,191.28,0.046
157.26,191.50,0.046
157.28,191.72,0.046
157.30,191.93,0.046
157.32,192.15,0.046
157.34,192.37,0.046
157.37,192.59,0.046
157.39,192.80,0.046
157.41,193.02,0.046
157.43,193.23,0.046
157.45,193.45,0.046
157.47,193.67,0.046
157.50,193.89,0.046
157.52,194.10,0.046
157.54,194.32,0.046
157.56,194.54,0.046
157.58,194.75,0.046
157.60,194.97,0.046
157.63,195.19,0.046
157.65,195.40,0.046
157.67,195.62,0.046
157.69,195.84,0.046
157.71,196.05,0.046
157.73,196.27,0.046
157.75,196.49,0.046
157.78,196.70,0.046
157.80,196.92,0.046
157.82,197.14,0.046
157.84,197.35,0.046
157.86,197.57,0.046
157.88,197.79,0.046
157.91,198.00,0.046
157.93,198.22,0.046
157.95,198.44,0.046
157.97,198.65,0.046
157.99,198.87,0.046
158.02,199.09,0.046
158.04,199.30,0.046
158.06,199.52,0.046
158.08,199.74,0.046
158.10,199.96,0.046
158.12,200.17,0.046
158.15,200.39,0.047
158.17,200.61,0.047
158.19,200.82,0.047
158.21,201.04,0.047
158.23,201.26,0.047
158.25,201.47,0.047
158.28,201.69,0.047
158.30,201.91,0.047
158.32,202.12,0.047
158.34,202.34,0.047
158.36,202.56,0.047
158.38,202.77,0.047
158.40,202.99,0.047
158.43,203.21,0.047
158.45,203.42,0.047
158.47,203.64,0.047
158.49,203.86,0.047
158.51,204.07,0.047
158.53,204.29,0.047
158.56,204.51,0.047
158.58,204.72,0.047
158.60,204.94,0.047
158.62,205.16,0.047
158.64,205.38,0.047
158.67,205.59,0.047
158.69,205.81,0.047
158.71,206.03,0.047
158.73,206.24,0.047
158.75,206.46,0.047
158.77,206.68,0.047
158.80,206.89,0.047
158.82,207.11,0.047
158.84,207.33,0.047
158.86,207.54,0.047
158.88,207.76,0.047
158.90,207.98,0.047
158.93,208.19,0.047
158.95,208.41,0.047
158.97,208.63,0.047
158.99,208.85,0.047
159.01,209.06,0.047
159.03,209.28,0.047
159.05,209.50,0.047
159.08,209.71,0.047
159.10,209.93,0.047
159.12,210.14,0.047
159.14,210.36,0.047
159.16,210.58,0.047
159.18,210.79,0.047
159.21,211.01,0.047
159.23,211.23,0.047
159.25,211.45,0.047
159.27,211.66,0.047
159.29,211.88,0.047
159.32,212.10,0.047
159.34,212.31,0.047
159.36,212.53,0.047
159.38,212.75,0.047
159.40,212.96,0.047
159.42,213.18,0.047
159.45,213.40,0.047
159.47,213.61,0.047
159.49,213.83,0.047
159.51,214.05,0.047
159.53,214.26,0.047
159.55,214.48,0.047
159.58,214.70,0.047
159.60,214.91,0.047
159.62,215.13,0.047
159.64,215.35,0.047
159.66,215.56,0.047
159.68,215.78,0.047
159.70,216.00,0.047
159.73,216.21,0.047
159.75,216.43,0.047
159.77,216.65,0.047
159.79,216.87,0.047
159.81,217.08,0.047
159.83,217.30,0.047
159.86,217.52,0.047
159.88,217.73,0.047
159.90,217.95,0.047
159.92,218.17,0.048
159.94,218.38,0.048
159.97,218.60,0.048
159.99,218.82,0.048
160.01,219.03,0.048
160.03,219.25,0.048
160.05,219.47,0.048
160.07,219.68,0.048
160.10,219.90,0.048
160.12,220.11,0.048
160.14,220.33,0.048
160.16,220.55,0.048
160.18,220.77,0.048
160.20,220.98,0.048
160.23,221.20,0.048
160.25,221.42,0.048
160.27,221.63,0.048
160.29,221.85,0.048
160.31,222.07,0.048
160.33,222.28,0.048
160.35,222.50,0.048
160.38,222.72,0.048
160.40,222.93,0.048
160.42,223.15,0.048
160.44,223.37,0.048
160.46,223.59,0.048
160.48,223.80,0.048
160.51,224.02,0.048
160.53,224.24,0.048
160.55,224.45,0.048
160.57,224.67,0.048
160.59,224.89,0.048
160.62,225.10,0.048
160.64,225.32,0.048
160.66,225.54,0.048
160.68,225.75,0.048
160.70,225.97,0.048
160.72,226.19,0.048
160.75,226.40,0.048
160.77,226.62,0.048
160.79,226.84,0.048
160.81,227.06,0.048
160.83,227.27,0.048
160.85,227.49,0.048
160.88,227.71,0.048
160.90,227.92,0.048
160.92,228.14,0.048
160.94,228.36,0.048
160.96,228.57,0.048
160.98,228.79,0.048
161.00,229.01,0.048
161.03,229.22,0.048
161.05,229.44,0.048
161.07,229.66,0.048
161.09,229.87,0.048
161.11,230.09,0.048
161.13,230.31,0.048
161.16,230.52,0.048
161.18,230.74,0.048
161.20,230.96,0.048
161.22,231.17,0.048
161.24,231.39,0.048
161.27,231.61,0.048
161.29,231.82,0.048
161.31,232.04,0.048
161.33,232.26,0.048
161.35,232.47,0.048
161.37,232.69,0.048
161.40,232.91,0.048
161.42,233.13,0.048
161.44,233.34,0.048
161.46,233.56,0.048
161.48,233.77,0.048
161.50,233.99,0.048
161.53,234.21,0.048
161.55,234.42,0.048
161.57,234.64,0.048
161.59,234.86,0.048
161.61,235.07,0.048
161.63,235.29,0.048
161.65,235.51,0.048
161.68,235.73,0.048
161.70,235.94,0.048
161.72,236.16,0.048
161.74,236.38,0.048
161.76,236.59,0.048
161.78,236.81,0.048
161.81,237.03,0.048
161.83,237.24,0.048
161.85,237.46,0.048
161.87,237.68,0.048
161.89,237.89,0.048
161.92,238.11,0.049
161.94,238.33,0.049
161.96,238.54,0.049
161.98,238.76,0.049
162.00,238.98,0.049
162.02,239.19,0.049
162.05,239.41,0.049
162.07,239.63,0.049
162.09,239.84,0.049
162.11,240.06,0.049
162.13,240.28,0.049
162.15,240.50,0.049
162.18,240.71,0.049
162.20,240.93,0.049
162.22,241.14,0.049
162.24,241.36,0.049
162.26,241.58,0.049
162.28,241.80,0.049
162.30,242.01,0.049
162.33,242.23,0.049
162.35,242.45,0.049
162.37,242.66,0.049
162.39,242.88,0.049
162.41,243.10,0.049
162.43,243.31,0.049
162.46,243.53,0.049
162.48,243.75,0.049
162.50,243.96,0.049
162.52,244.18,0.049
162.54,244.40,0.049
162.57,244.61,0.049
162.59,244.83,0.049
162.61,245.05,0.049
162.63,245.26,0.049
162.65,245.48,0.049
162.67,245.70,0.049
162.70,245.91,0.049
162.72,246.13,0.049
162.74,246.35,0.049
162.76,246.56,0.049
162.78,246.78,0.049
162.80,247.00,0.049
162.83,247.21,0.049
162.85,247.43,0.049
162.87,247.65,0.049
162.89,247.87,0.049
162.91,248.08,0.049
162.93,248.30,0.049
162.95,248.51,
162.98,248.73,
162.99,,