File: DSC/Olivia/2025_08_09_Empty_TS_Pans_n60C_250C_10Cmin_x3.csv
Filename,2025_08_09_Empty_TS_Pans_n60C_250C_10Cmin_x3
Instrument name,DSC2A-00468 (192.168.1.100)
Operator,Yarger
rundate,8/9/2025
Sample name,2025_08_09_Empty_TS_Pans_n60C_250C_10Cmin_x3
proceduresegments,Data Off ; Equilibrate -60.00 °C; Data On ; Ramp 10.00 °C/min to 250.00 °C; Data Off ; Isothermal 2.0 min; Data On ; Ramp 10.00 °C/min to -60.00 °C; Data Off ; Isothermal 2.0 min; Data On ; Ramp 10.00 °C/min to 250.00 °C; Data Off ; Isothermal 2.0 min; Data On ; Ramp 10.00 °C/min to -60.00 °C; Data Off ; Isothermal 2.0 min; Data On ; Ramp 10.00 °C/min to 250.00 °C
[File Parameters]
Run date,8/9/2025 12:51:39 PM
Trios version,5.1.1.46572
Original File Name,
Current File Name,D:\DSC2500\JYarger\2025_08_09_Empty_TS_Pans_n60C_250C_10Cmin_x3.tri
[Procedure]
Procedure Name,Empty_TS_n60C_250C_10Cmin_x3
Sample Name,2025_08_09_Empty_TS_Pans_n60C_250C_10Cmin_x3
Sample Mass,32.37 mg
Reference Sample Mass,0 mg
Pan Mass,0 mg
Pan Number,5
Reference Pan Mass,32.42 mg
Reference Pan Number,10
Pan Type,Aluminum
Comments,Thermal support Al pans/lids. DSC_Samples_A2_Tray_August2025 google sheet.
Project Name,Pharma
Operator,Yarger
Test,Custom
Unload Max Temperature,30
Unload Min Temperature,30
Load Max Temperature,30
Load Min Temperature,30
Stop on Gas Flow Error,Yes
[Signal List]
Signal #1,Time (min)
Signal #2,Temperature (°C)
Signal #3,Heat Flow (mW)
Signal #4,Delta T (µV)
Signal #5,Delta Tzero (µV)
Signal #6,Tzero Temperature (°C)
Signal #7,Cell Purge (mL/min)
Signal #8,Heater Temp (°C)
Signal #9,Power Delivered (W)
Signal #10,Reference Junction Temperature (°C)
Signal #11,Flange Temperature (°C)
Signal #12,Heat Flow Phase (rad)
Signal #13,Total Heat Capacity (J/°C)
Signal #14,Heat Capacity (J/°C)
[Configuration]
Company Name,ASU
Instrument Name,DSC2A-00468
Instrument Type,DSC2500
Serial Number,DSC2A-00468
IP,192.168.1.100
Location of Instrument,MRRC
DisplayType,Unknown
Sample Interval ,0.1 s/pt
Selected Heat Flow,T4P
Exotherm Direction,Down
Cell Serial,DRC2-00792
Lid Type,Standard
Cooler,RCS 90
Leave Cooler on at End of Sequence,On
Gas 2,Nitrogen
Gas Selected,Channel 1
Flow Rate,50 mL/min
Secondary Purge,On
Licensed Heat Flow,Heat Flow T4P
Modulation Licensed,Yes
[Versions]
Common IDD Version,1
Cortex Version,VER 2.10.2.31
Driver,5.0.0.6
GDM Version,1.0.3.3
TouchscreenVersion,1.0.0.16145
FEP Version,1.2.1.21
FEP Bootloader,2.0.0.5
AutoSampler Version,2.1.1.26
Auto Sampler Bootloader,2.0.0.5
FCM Version,1.1.0.3
FCM Bootloader,2.0.0.5
[Experiment Logs]
Experiment Log Entry # 1,Air Cool is off.
Experiment Log Entry # 3,Data On set to 0
Experiment Log Entry # 5,Equilibrate Segment -60 (C) Started
Experiment Log Entry # 7,Data On set to 1
Experiment Log Entry # 9,Ramp Segment 10 C/min to 250 Started
Experiment Log Entry # 11,Data On set to 0
Experiment Log Entry # 13,Isothermal Segment 2 min started
Experiment Log Entry # 15,Data On set to 1
Experiment Log Entry # 17,Ramp Segment 10 C/min to -60 Started
Experiment Log Entry # 19,Data On set to 0
Experiment Log Entry # 21,Isothermal Segment 2 min started
Experiment Log Entry # 23,Data On set to 1
Experiment Log Entry # 25,Ramp Segment 10 C/min to 250 Started
Experiment Log Entry # 27,Data On set to 0
Experiment Log Entry # 29,Isothermal Segment 2 min started
Experiment Log Entry # 31,Data On set to 1
Experiment Log Entry # 33,Ramp Segment 10 C/min to -60 Started
Experiment Log Entry # 35,Data On set to 0
Experiment Log Entry # 37,Isothermal Segment 2 min started
Experiment Log Entry # 39,Data On set to 1
Experiment Log Entry # 41,Ramp Segment 10 C/min to 250 Started
[Method Log]
Method Log Entry # 1,Data Off
Method Log Entry # 2,Equilibrate -60 °C
Method Log Entry # 3,Data On
Method Log Entry # 4,(Ramp 666097) Ramp 10 °C/minute to 250 °C
Method Log Entry # 5,Data Off
Method Log Entry # 6,Isothermal 2 minutes
Method Log Entry # 7,Data On
Method Log Entry # 8,(Ramp 666101) Ramp 10 °C/minute to -60 °C
Method Log Entry # 9,Data Off
Method Log Entry # 10,Isothermal 2 minutes
Method Log Entry # 11,Data On
Method Log Entry # 12,(Ramp 666105) Ramp 10 °C/minute to 250 °C
Method Log Entry # 13,Data Off
Method Log Entry # 14,Isothermal 2 minutes
Method Log Entry # 15,Data On
Method Log Entry # 16,(Ramp 666109) Ramp 10 °C/minute to -60 °C
Method Log Entry # 17,Data Off
Method Log Entry # 18,Isothermal 2 minutes
Method Log Entry # 19,Data On
Method Log Entry # 20,(Ramp 666113) Ramp 10 °C/minute to 250 °C
Cell Serial,DRC2-00792
[T1 Calibration]
Slope,-0.008529666
Offset,9.636258
Initial Temperature,98.23
GUID,f8bfdadc-4977-4fdf-ba6d-0ba9134940c3
[TZero Calibration]
Date Applied,11/29/2022 4:06:13 PM
Description,From -89.059 °C to 396.009 °C at 20.000°C/min
Gas Type,Nitrogen
Pan Type,None
Source Files 1,C:\Users\yargerlab\Desktop\DSC Data\General\TZero_calibration_11_29_22_2nd(2).tri
Source Files 2,C:\Users\yargerlab\Desktop\DSC Data\General\TZero_calibration_11_29_22_2nd(3).tri
Delta T Offset,13.05235
Delta T Slope,-0.007271007
Delta T0 Offset,-13.69128
Delta T0 Slope,0.06063341
[Temperature Calibration]
Date Applied,11/29/2022 7:12:28 PM
Description,From 106.590 °C to 186.590 °C at 10.000°C/min
Gas Type,Nitrogen
Pan Type,Tzero Aluminum Hermetic
Source Files 1,C:\Users\yargerlab\Desktop\DSC Data\General\Indium(6).tri
Measured 1,157.391
Known 1,156.598
[Cell Constant Calibration]
Date Applied,11/29/2022 7:12:29 PM
Description,From 106.590 °C to 186.590 °C at 10.000°C/min
Gas Type,Nitrogen
Pan Type,Tzero Aluminum Hermetic
Source Files 1,C:\Users\yargerlab\Desktop\DSC Data\General\Indium(6).tri
T4P KCell,1.006051
Onset Slope,63.26126 mW/°C
[Direct Cp Calibration]
Date Applied,11/30/2022 11:04:51 AM
Description,From -79.983 °C to 298.409 °C at 10.000°C/min
Gas Type,Nitrogen
Pan Type,Tzero Aluminum Hermetic
Source Files 1,C:\Users\yargerlab\Desktop\DSC Data\General\Sapphire_Heat_Capacity_11_30_22.tri
[Rev Cp Calibration]
Date Applied,11/30/2022 1:58:51 PM
Description,From -79.996 °C to 292.812 °C at 3.000°C/min
Gas Type,Nitrogen
Pan Type,Tzero Aluminum Hermetic
Source Files 1,C:\Users\yargerlab\Desktop\DSC Data\General\Sapphire_MDSC_Calibration_11_30_22.tri
[step]
Ramp 10.00 °C/min to 250.00 °C
Time,Temperature,Heat Flow (Normalized)
min,°C,W/g
0.00,-59.82,-0.003
0.02,-59.82,-0.003
0.04,-59.82,-0.003
0.07,-59.79,0.000
0.09,-59.74,0.003
0.11,-59.66,0.006
0.13,-59.54,0.008
0.15,-59.39,0.010
0.17,-59.21,0.010
0.19,-59.03,0.010
0.22,-58.83,0.010
0.24,-58.62,0.009
0.26,-58.42,0.009
0.28,-58.21,0.009
0.30,-57.99,0.009
0.33,-57.78,0.008
0.35,-57.57,0.008
0.37,-57.36,0.008
0.39,-57.15,0.008
0.41,-56.93,0.008
0.43,-56.72,0.008
0.45,-56.51,0.008
0.48,-56.30,0.008
0.50,-56.08,0.008
0.52,-55.87,0.008
0.54,-55.66,0.008
0.56,-55.44,0.008
0.58,-55.23,0.008
0.61,-55.02,0.008
0.63,-54.80,0.008
0.65,-54.59,0.008
0.67,-54.37,0.008
0.69,-54.16,0.008
0.72,-53.95,0.008
0.74,-53.73,0.008
0.76,-53.52,0.008
0.78,-53.30,0.008
0.80,-53.09,0.008
0.82,-52.87,0.008
0.85,-52.66,0.008
0.87,-52.44,0.008
0.89,-52.23,0.008
0.91,-52.01,0.008
0.93,-51.80,0.008
0.95,-51.58,0.008
0.98,-51.36,0.008
1.00,-51.15,0.008
1.02,-50.93,0.008
1.04,-50.72,0.008
1.06,-50.50,0.008
1.08,-50.29,0.008
1.11,-50.07,0.008
1.13,-49.85,0.008
1.15,-49.64,0.008
1.17,-49.42,0.008
1.19,-49.21,0.008
1.21,-48.99,0.008
1.23,-48.77,0.008
1.26,-48.56,0.008
1.28,-48.34,0.008
1.30,-48.13,0.008
1.32,-47.91,0.008
1.34,-47.69,0.008
1.37,-47.48,0.008
1.39,-47.26,0.008
1.41,-47.04,0.008
1.43,-46.83,0.008
1.45,-46.61,0.008
1.47,-46.39,0.008
1.49,-46.18,0.008
1.52,-45.96,0.008
1.54,-45.74,0.008
1.56,-45.53,0.008
1.58,-45.31,0.008
1.60,-45.09,0.008
1.63,-44.88,0.008
1.65,-44.66,0.008
1.67,-44.44,0.008
1.69,-44.23,0.008
1.71,-44.01,0.008
1.73,-43.79,0.008
1.76,-43.57,0.008
1.78,-43.36,0.008
1.80,-43.14,0.008
1.82,-42.92,0.008
1.84,-42.71,0.008
1.86,-42.49,0.008
1.88,-42.27,0.008
1.91,-42.06,0.008
1.93,-41.84,0.008
1.95,-41.62,0.008
1.97,-41.41,0.008
1.99,-41.19,0.008
2.02,-40.97,0.008
2.04,-40.76,0.008
2.06,-40.54,0.008
2.08,-40.32,0.008
2.10,-40.11,0.008
2.12,-39.89,0.008
2.14,-39.67,0.008
2.17,-39.45,0.008
2.19,-39.24,0.008
2.21,-39.02,0.008
2.23,-38.80,0.008
2.25,-38.59,0.008
2.28,-38.37,0.008
2.30,-38.15,0.008
2.32,-37.93,0.008
2.34,-37.72,0.008
2.36,-37.50,0.008
2.38,-37.28,0.008
2.41,-37.07,0.008
2.43,-36.85,0.008
2.45,-36.64,0.008
2.47,-36.42,0.008
2.49,-36.20,0.008
2.51,-35.98,0.008
2.54,-35.77,0.008
2.56,-35.55,0.008
2.58,-35.33,0.008
2.60,-35.11,0.008
2.62,-34.90,0.008
2.64,-34.68,0.008
2.66,-34.47,0.008
2.69,-34.25,0.008
2.71,-34.03,0.008
2.73,-33.81,0.008
2.75,-33.60,0.008
2.77,-33.38,0.008
2.79,-33.16,0.008
2.82,-32.95,0.008
2.84,-32.73,0.008
2.86,-32.51,0.008
2.88,-32.29,0.008
2.90,-32.08,0.008
2.93,-31.86,0.008
2.95,-31.64,0.008
2.97,-31.43,0.008
2.99,-31.21,0.008
3.01,-30.99,0.008
3.03,-30.77,0.008
3.06,-30.56,0.008
3.08,-30.34,0.008
3.10,-30.12,0.008
3.12,-29.91,0.008
3.14,-29.69,0.008
3.16,-29.47,0.008
3.19,-29.26,0.008
3.21,-29.04,0.008
3.23,-28.82,0.008
3.25,-28.61,0.008
3.27,-28.39,0.008
3.29,-28.17,0.008
3.31,-27.96,0.008
3.34,-27.74,0.008
3.36,-27.52,0.008
3.38,-27.30,0.008
3.40,-27.09,0.008
3.42,-26.87,0.008
3.44,-26.65,0.008
3.47,-26.44,0.007
3.49,-26.22,0.007
3.51,-26.00,0.007
3.53,-25.78,0.007
3.55,-25.57,0.007
3.58,-25.35,0.007
3.60,-25.13,0.007
3.62,-24.92,0.007
3.64,-24.70,0.007
3.66,-24.48,0.007
3.68,-24.27,0.007
3.71,-24.05,0.007
3.73,-23.83,0.007
3.75,-23.62,0.007
3.77,-23.40,0.007
3.79,-23.18,0.007
3.81,-22.96,0.007
3.84,-22.75,0.007
3.86,-22.53,0.007
3.88,-22.31,0.007
3.90,-22.10,0.007
3.92,-21.88,0.007
3.94,-21.66,0.007
3.96,-21.45,0.007
3.99,-21.23,0.007
4.01,-21.01,0.007
4.03,-20.79,0.007
4.05,-20.58,0.007
4.07,-20.36,0.007
4.09,-20.14,0.007
4.12,-19.93,0.007
4.14,-19.71,0.007
4.16,-19.49,0.007
4.18,-19.28,0.007
4.20,-19.06,0.007
4.23,-18.84,0.007
4.25,-18.63,0.007
4.27,-18.41,0.007
4.29,-18.19,0.007
4.31,-17.97,0.007
4.33,-17.76,0.007
4.35,-17.54,0.007
4.38,-17.32,0.007
4.40,-17.11,0.007
4.42,-16.89,0.007
4.44,-16.67,0.007
4.46,-16.46,0.007
4.49,-16.24,0.007
4.51,-16.02,0.007
4.53,-15.81,0.007
4.55,-15.59,0.007
4.57,-15.37,0.007
4.59,-15.15,0.007
4.61,-14.94,0.007
4.64,-14.72,0.007
4.66,-14.50,0.007
4.68,-14.29,0.007
4.70,-14.07,0.007
4.72,-13.85,0.007
4.75,-13.63,0.007
4.77,-13.42,0.007
4.79,-13.20,0.007
4.81,-12.99,0.007
4.83,-12.77,0.007
4.85,-12.55,0.007
4.88,-12.33,0.007
4.90,-12.12,0.007
4.92,-11.90,0.007
4.94,-11.68,0.007
4.96,-11.47,0.007
4.98,-11.25,0.007
5.00,-11.03,0.007
5.03,-10.82,0.007
5.05,-10.60,0.007
5.07,-10.38,0.007
5.09,-10.16,0.007
5.11,-9.95,0.007
5.14,-9.73,0.007
5.16,-9.51,0.007
5.18,-9.30,0.007
5.20,-9.08,0.007
5.22,-8.86,0.007
5.24,-8.65,0.007
5.26,-8.43,0.007
5.29,-8.21,0.007
5.31,-8.00,0.007
5.33,-7.78,0.007
5.35,-7.56,0.007
5.37,-7.35,0.007
5.40,-7.13,0.007
5.42,-6.91,0.007
5.44,-6.69,0.007
5.46,-6.48,0.007
5.48,-6.26,0.007
5.50,-6.04,0.007
5.53,-5.83,0.007
5.55,-5.61,0.007
5.57,-5.39,0.007
5.59,-5.17,0.007
5.61,-4.96,0.007
5.63,-4.74,0.007
5.65,-4.52,0.007
5.68,-4.31,0.007
5.70,-4.09,0.007
5.72,-3.87,0.007
5.74,-3.66,0.007
5.76,-3.44,0.007
5.79,-3.22,0.007
5.81,-3.01,0.007
5.83,-2.79,0.007
5.85,-2.57,0.007
5.87,-2.36,0.007
5.89,-2.14,0.007
5.91,-1.92,0.007
5.94,-1.70,0.007
5.96,-1.49,0.007
5.98,-1.27,0.007
6.00,-1.05,0.007
6.02,-0.84,0.007
6.05,-0.62,0.007
6.07,-0.40,0.007
6.09,-0.19,0.007
6.11,0.03,0.007
6.13,0.25,0.007
6.15,0.47,0.007
6.18,0.68,0.007
6.20,0.90,0.007
6.22,1.12,0.007
6.24,1.33,0.007
6.26,1.55,0.007
6.28,1.77,0.007
6.30,1.98,0.007
6.33,2.20,0.007
6.35,2.42,0.007
6.37,2.64,0.007
6.39,2.85,0.007
6.41,3.07,0.007
6.44,3.28,0.007
6.46,3.50,0.007
6.48,3.72,0.007
6.50,3.94,0.007
6.52,4.15,0.007
6.54,4.37,0.007
6.56,4.59,0.007
6.59,4.80,0.007
6.61,5.02,0.007
6.63,5.24,0.007
6.65,5.45,0.007
6.67,5.67,0.007
6.70,5.89,0.007
6.72,6.11,0.007
6.74,6.32,0.007
6.76,6.54,0.006
6.78,6.76,0.006
6.80,6.97,0.006
6.83,7.19,0.006
6.85,7.41,0.006
6.87,7.62,0.006
6.89,7.84,0.006
6.91,8.06,0.006
6.93,8.27,0.006
6.95,8.49,0.006
6.98,8.71,0.006
7.00,8.92,0.006
7.02,9.14,0.006
7.04,9.36,0.006
7.06,9.58,0.006
7.09,9.79,0.006
7.11,10.01,0.006
7.13,10.23,0.006
7.15,10.45,0.006
7.17,10.66,0.006
7.19,10.88,0.006
7.21,11.09,0.006
7.24,11.31,0.006
7.26,11.53,0.006
7.28,11.75,0.006
7.30,11.96,0.006
7.32,12.18,0.006
7.35,12.40,0.006
7.37,12.61,0.006
7.39,12.83,0.006
7.41,13.05,0.006
7.43,13.26,0.006
7.45,13.48,0.006
7.48,13.70,0.006
7.50,13.91,0.006
7.52,14.13,0.006
7.54,14.35,0.006
7.56,14.56,0.006
7.58,14.78,0.006
7.60,15.00,0.006
7.63,15.22,0.006
7.65,15.43,0.006
7.67,15.65,0.006
7.69,15.87,0.006
7.71,16.08,0.006
7.74,16.30,0.006
7.76,16.52,0.006
7.78,16.74,0.006
7.80,16.95,0.006
7.82,17.17,0.006
7.84,17.39,0.006
7.86,17.60,0.006
7.89,17.82,0.006
7.91,18.04,0.006
7.93,18.25,0.006
7.95,18.47,0.006
7.97,18.69,0.006
8.00,18.90,0.006
8.02,19.12,0.006
8.04,19.34,0.006
8.06,19.55,0.006
8.08,19.77,0.006
8.10,19.99,0.006
8.13,20.20,0.006
8.15,20.42,0.006
8.17,20.64,0.006
8.19,20.85,0.006
8.21,21.07,0.006
8.23,21.29,0.006
8.25,21.50,0.006
8.28,21.72,0.006
8.30,21.94,0.006
8.32,22.15,0.006
8.34,22.37,0.006
8.36,22.59,0.006
8.39,22.81,0.006
8.41,23.02,0.006
8.43,23.24,0.006
8.45,23.46,0.006
8.47,23.67,0.006
8.49,23.89,0.006
8.51,24.11,0.006
8.54,24.32,0.006
8.56,24.54,0.006
8.58,24.76,0.006
8.60,24.97,0.006
8.62,25.19,0.006
8.65,25.41,0.006
8.67,25.63,0.006
8.69,25.84,0.006
8.71,26.06,0.006
8.73,26.28,0.006
8.75,26.49,0.006
8.78,26.71,0.006
8.80,26.93,0.006
8.82,27.14,0.006
8.84,27.36,0.006
8.86,27.58,0.006
8.88,27.80,0.006
8.90,28.01,0.006
8.93,28.23,0.006
8.95,28.45,0.006
8.97,28.66,0.006
8.99,28.88,0.006
9.01,29.10,0.006
9.03,29.31,0.006
9.06,29.53,0.006
9.08,29.75,0.006
9.10,29.96,0.006
9.12,30.18,0.006
9.14,30.40,0.006
9.17,30.62,0.006
9.19,30.83,0.006
9.21,31.05,0.006
9.23,31.27,0.006
9.25,31.48,0.006
9.27,31.70,0.006
9.30,31.92,0.006
9.32,32.13,0.006
9.34,32.35,0.006
9.36,32.57,0.006
9.38,32.78,0.006
9.40,33.00,0.006
9.43,33.22,0.006
9.45,33.43,0.006
9.47,33.65,0.006
9.49,33.87,0.006
9.51,34.09,0.006
9.53,34.30,0.006
9.55,34.52,0.006
9.58,34.74,0.006
9.60,34.95,0.006
9.62,35.17,0.006
9.64,35.39,0.006
9.66,35.60,0.006
9.68,35.82,0.006
9.71,36.04,0.006
9.73,36.25,0.006
9.75,36.47,0.006
9.77,36.69,0.006
9.79,36.91,0.006
9.82,37.12,0.006
9.84,37.34,0.006
9.86,37.56,0.006
9.88,37.77,0.006
9.90,37.99,0.006
9.92,38.21,0.006
9.95,38.42,0.006
9.97,38.64,0.006
9.99,38.86,0.006
10.01,39.07,0.006
10.03,39.29,0.006
10.05,39.51,0.006
10.08,39.72,0.006
10.10,39.94,0.006
10.12,40.16,0.006
10.14,40.37,0.006
10.16,40.59,0.006
10.18,40.81,0.006
10.20,41.03,0.006
10.23,41.24,0.006
10.25,41.46,0.006
10.27,41.68,0.006
10.29,41.89,0.006
10.31,42.11,0.006
10.33,42.33,0.006
10.36,42.55,0.006
10.38,42.76,0.006
10.40,42.98,0.006
10.42,43.20,0.006
10.44,43.41,0.006
10.47,43.63,0.006
10.49,43.85,0.006
10.51,44.06,0.006
10.53,44.28,0.006
10.55,44.50,0.006
10.57,44.71,0.006
10.60,44.93,0.006
10.62,45.15,0.006
10.64,45.36,0.006
10.66,45.58,0.006
10.68,45.80,0.006
10.70,46.01,0.006
10.73,46.23,0.006
10.75,46.45,0.006
10.77,46.67,0.006
10.79,46.88,0.006
10.81,47.10,0.006
10.83,47.31,0.006
10.85,47.53,0.006
10.88,47.75,0.006
10.90,47.97,0.006
10.92,48.18,0.006
10.94,48.40,0.006
10.96,48.62,0.006
10.98,48.83,0.006
11.01,49.05,0.006
11.03,49.27,0.006
11.05,49.48,0.006
11.07,49.70,0.006
11.09,49.92,0.006
11.12,50.14,0.006
11.14,50.35,0.006
11.16,50.57,0.006
11.18,50.79,0.006
11.20,51.00,0.006
11.22,51.22,0.006
11.25,51.44,0.006
11.27,51.65,0.006
11.29,51.87,0.006
11.31,52.09,0.006
11.33,52.30,0.006
11.35,52.52,0.006
11.38,52.74,0.006
11.40,52.95,0.006
11.42,53.17,0.006
11.44,53.39,0.006
11.46,53.60,0.006
11.48,53.82,0.006
11.50,54.04,0.006
11.53,54.25,0.006
11.55,54.47,0.006
11.57,54.69,0.006
11.59,54.90,0.006
11.61,55.12,0.006
11.63,55.34,0.006
11.66,55.56,0.006
11.68,55.77,0.006
11.70,55.99,0.006
11.72,56.21,0.006
11.74,56.43,0.006
11.77,56.65,0.006
11.79,56.86,0.006
11.81,57.08,0.006
11.83,57.30,0.006
11.85,57.51,0.006
11.87,57.73,0.006
11.90,57.95,0.006
11.92,58.16,0.006
11.94,58.38,0.006
11.96,58.60,0.006
11.98,58.81,0.006
12.00,59.03,0.006
12.03,59.25,0.006
12.05,59.46,0.006
12.07,59.68,0.006
12.09,59.90,0.006
12.11,60.11,0.006
12.13,60.33,0.006
12.15,60.55,0.006
12.18,60.77,0.006
12.20,60.98,0.006
12.22,61.20,0.006
12.24,61.42,0.006
12.26,61.63,0.006
12.28,61.85,0.006
12.31,62.07,0.006
12.33,62.28,0.006
12.35,62.50,0.006
12.37,62.72,0.006
12.39,62.93,0.006
12.42,63.15,0.006
12.44,63.37,0.006
12.46,63.58,0.006
12.48,63.80,0.006
12.50,64.02,0.006
12.52,64.23,0.006
12.55,64.45,0.006
12.57,64.67,0.006
12.59,64.88,0.006
12.61,65.10,0.006
12.63,65.32,0.006
12.65,65.54,0.006
12.68,65.75,0.006
12.70,65.97,0.006
12.72,66.19,0.006
12.74,66.40,0.006
12.76,66.62,0.006
12.78,66.84,0.006
12.80,67.05,0.006
12.83,67.27,0.006
12.85,67.49,0.006
12.87,67.71,0.006
12.89,67.92,0.006
12.91,68.14,0.006
12.93,68.36,0.006
12.96,68.57,0.006
12.98,68.79,0.006
13.00,69.01,0.006
13.02,69.22,0.006
13.04,69.44,0.006
13.07,69.65,0.006
13.09,69.87,0.006
13.11,70.09,0.006
13.13,70.31,0.006
13.15,70.52,0.006
13.17,70.74,0.006
13.20,70.96,0.006
13.22,71.17,0.006
13.24,71.39,0.006
13.26,71.61,0.006
13.28,71.83,0.006
13.30,72.04,0.006
13.33,72.26,0.006
13.35,72.48,0.006
13.37,72.69,0.006
13.39,72.91,0.006
13.41,73.13,0.006
13.43,73.34,0.006
13.45,73.56,0.006
13.48,73.78,0.006
13.50,74.00,0.006
13.52,74.21,0.006
13.54,74.43,0.006
13.56,74.65,0.006
13.58,74.86,0.006
13.61,75.08,0.006
13.63,75.30,0.006
13.65,75.52,0.006
13.67,75.73,0.006
13.69,75.95,0.006
13.72,76.16,0.006
13.74,76.38,0.006
13.76,76.60,0.006
13.78,76.81,0.006
13.80,77.03,0.006
13.82,77.25,0.006
13.85,77.46,0.006
13.87,77.68,0.006
13.89,77.90,0.006
13.91,78.11,0.006
13.93,78.33,0.006
13.95,78.55,0.006
13.98,78.76,0.006
14.00,78.98,0.006
14.02,79.20,0.006
14.04,79.41,0.006
14.06,79.63,0.006
14.08,79.85,0.006
14.10,80.07,0.006
14.13,80.28,0.006
14.15,80.50,0.006
14.17,80.72,0.006
14.19,80.93,0.006
14.21,81.15,0.006
14.23,81.37,0.006
14.26,81.58,0.006
14.28,81.80,0.006
14.30,82.02,0.006
14.32,82.23,0.006
14.34,82.45,0.006
14.37,82.67,0.006
14.39,82.88,0.006
14.41,83.10,0.006
14.43,83.32,0.006
14.45,83.54,0.006
14.47,83.75,0.006
14.50,83.97,0.006
14.52,84.19,0.006
14.54,84.40,0.006
14.56,84.62,0.006
14.58,84.84,0.006
14.60,85.06,0.006
14.63,85.27,0.006
14.65,85.49,0.006
14.67,85.70,0.006
14.69,85.92,0.006
14.71,86.14,0.006
14.73,86.35,0.006
14.75,86.57,0.006
14.78,86.79,0.006
14.80,87.01,0.006
14.82,87.22,0.006
14.84,87.44,0.006
14.86,87.66,0.006
14.88,87.87,0.006
14.91,88.09,0.006
14.93,88.31,0.006
14.95,88.52,0.006
14.97,88.74,0.006
14.99,88.96,0.006
15.02,89.17,0.006
15.04,89.39,0.006
15.06,89.61,0.006
15.08,89.83,0.006
15.10,90.04,0.006
15.12,90.26,0.006
15.15,90.48,0.006
15.17,90.69,0.006
15.19,90.91,0.006
15.21,91.13,0.006
15.23,91.34,0.006
15.25,91.56,0.006
15.28,91.78,0.006
15.30,91.99,0.006
15.32,92.21,0.006
15.34,92.43,0.006
15.36,92.64,0.006
15.38,92.86,0.006
15.40,93.08,0.006
15.43,93.29,0.006
15.45,93.51,0.006
15.47,93.73,0.006
15.49,93.94,0.006
15.51,94.16,0.006
15.53,94.38,0.006
15.56,94.59,0.006
15.58,94.81,0.006
15.60,95.03,0.006
15.62,95.25,0.006
15.64,95.46,0.006
15.67,95.68,0.006
15.69,95.90,0.006
15.71,96.11,0.006
15.73,96.33,0.006
15.75,96.55,0.006
15.77,96.76,0.006
15.80,96.98,0.006
15.82,97.20,0.006
15.84,97.41,0.006
15.86,97.63,0.006
15.88,97.85,0.006
15.90,98.06,0.006
15.93,98.28,0.006
15.95,98.50,0.006
15.97,98.71,0.006
15.99,98.93,0.006
16.01,99.15,0.006
16.03,99.37,0.006
16.05,99.58,0.006
16.08,99.80,0.006
16.10,100.02,0.006
16.12,100.23,0.006
16.14,100.45,0.006
16.16,100.67,0.006
16.18,100.88,0.006
16.21,101.10,0.006
16.23,101.32,0.006
16.25,101.54,0.006
16.27,101.75,0.006
16.29,101.97,0.006
16.32,102.19,0.006
16.34,102.40,0.006
16.36,102.62,0.006
16.38,102.84,0.006
16.40,103.06,0.006
16.42,103.27,0.006
16.45,103.49,0.006
16.47,103.71,0.006
16.49,103.92,0.006
16.51,104.14,0.006
16.53,104.36,0.006
16.55,104.57,0.006
16.58,104.79,0.006
16.60,105.01,0.006
16.62,105.22,0.006
16.64,105.44,0.006
16.66,105.66,0.006
16.68,105.87,0.006
16.70,106.09,0.006
16.73,106.31,0.006
16.75,106.52,0.006
16.77,106.74,0.006
16.79,106.96,0.006
16.81,107.17,0.006
16.83,107.39,0.006
16.86,107.61,0.006
16.88,107.82,0.006
16.90,108.04,0.006
16.92,108.26,0.006
16.94,108.48,0.006
16.97,108.69,0.006
16.99,108.91,0.006
17.01,109.13,0.006
17.03,109.34,0.006
17.05,109.56,0.006
17.07,109.77,0.006
17.09,109.99,0.006
17.12,110.21,0.006
17.14,110.43,0.006
17.16,110.64,0.006
17.18,110.86,0.006
17.20,111.08,0.006
17.23,111.29,0.006
17.25,111.51,0.006
17.27,111.72,0.006
17.29,111.94,0.006
17.31,112.16,0.006
17.33,112.37,0.006
17.36,112.59,0.006
17.38,112.81,0.006
17.40,113.03,0.006
17.42,113.24,0.006
17.44,113.46,0.006
17.46,113.67,0.006
17.48,113.89,0.006
17.51,114.11,0.006
17.53,114.33,0.006
17.55,114.54,0.006
17.57,114.76,0.006
17.59,114.98,0.006
17.62,115.19,0.006
17.64,115.41,0.006
17.66,115.63,0.006
17.68,115.84,0.006
17.70,116.06,0.006
17.72,116.28,0.006
17.74,116.49,0.006
17.77,116.71,0.006
17.79,116.93,0.006
17.81,117.15,0.006
17.83,117.36,0.006
17.85,117.58,0.006
17.88,117.80,0.006
17.90,118.01,0.006
17.92,118.23,0.006
17.94,118.45,0.006
17.96,118.67,0.006
17.98,118.88,0.006
18.01,119.10,0.006
18.03,119.31,0.006
18.05,119.53,0.006
18.07,119.75,0.006
18.09,119.97,0.006
18.11,120.18,0.006
18.13,120.40,0.006
18.16,120.62,0.006
18.18,120.83,0.006
18.20,121.05,0.006
18.22,121.27,0.006
18.24,121.48,0.006
18.27,121.70,0.006
18.29,121.92,0.006
18.31,122.13,0.006
18.33,122.35,0.006
18.35,122.57,0.006
18.37,122.79,0.006
18.39,123.00,0.006
18.42,123.22,0.006
18.44,123.44,0.006
18.46,123.65,0.006
18.48,123.87,0.006
18.50,124.09,0.006
18.53,124.30,0.006
18.55,124.52,0.006
18.57,124.74,0.006
18.59,124.96,0.006
18.61,125.17,0.006
18.63,125.39,0.006
18.66,125.61,0.006
18.68,125.82,0.006
18.70,126.04,0.006
18.72,126.26,0.006
18.74,126.47,0.006
18.76,126.69,0.006
18.78,126.91,0.006
18.81,127.12,0.006
18.83,127.34,0.006
18.85,127.56,0.006
18.87,127.77,0.006
18.89,127.99,0.006
18.92,128.21,0.006
18.94,128.42,0.006
18.96,128.64,0.006
18.98,128.86,0.006
19.00,129.08,0.006
19.02,129.29,0.006
19.04,129.51,0.006
19.07,129.72,0.006
19.09,129.94,0.006
19.11,130.16,0.006
19.13,130.38,0.006
19.15,130.59,0.006
19.18,130.81,0.006
19.20,131.02,0.006
19.22,131.24,0.006
19.24,131.46,0.006
19.26,131.68,0.007
19.28,131.89,0.007
19.31,132.11,0.007
19.33,132.33,0.007
19.35,132.54,0.007
19.37,132.76,0.007
19.39,132.98,0.007
19.41,133.19,0.007
19.43,133.41,0.007
19.46,133.63,0.007
19.48,133.85,0.007
19.50,134.06,0.007
19.52,134.28,0.007
19.54,134.50,0.007
19.57,134.71,0.007
19.59,134.93,0.007
19.61,135.15,0.007
19.63,135.36,0.007
19.65,135.58,0.007
19.67,135.79,0.007
19.69,136.01,0.007
19.72,136.23,0.007
19.74,136.45,0.007
19.76,136.66,0.007
19.78,136.88,0.007
19.80,137.10,0.007
19.83,137.31,0.007
19.85,137.53,0.007
19.87,137.75,0.007
19.89,137.96,0.007
19.91,138.18,0.007
19.93,138.40,0.007
19.96,138.61,0.007
19.98,138.83,0.007
20.00,139.05,0.007
20.02,139.26,0.007
20.04,139.48,0.007
20.06,139.70,0.007
20.08,139.92,0.007
20.11,140.13,0.007
20.13,140.35,0.007
20.15,140.57,0.007
20.17,140.79,0.007
20.19,141.00,0.007
20.22,141.22,0.007
20.24,141.44,0.007
20.26,141.65,0.007
20.28,141.87,0.007
20.30,142.09,0.007
20.32,142.30,0.007
20.34,142.52,0.007
20.37,142.74,0.007
20.39,142.95,0.007
20.41,143.17,0.007
20.43,143.39,0.007
20.45,143.61,0.007
20.48,143.82,0.007
20.50,144.04,0.007
20.52,144.25,0.007
20.54,144.47,0.007
20.56,144.69,0.007
20.58,144.90,0.007
20.61,145.12,0.007
20.63,145.34,0.007
20.65,145.55,0.007
20.67,145.77,0.007
20.69,145.99,0.007
20.71,146.21,0.007
20.73,146.42,0.007
20.76,146.64,0.007
20.78,146.85,0.007
20.80,147.07,0.007
20.82,147.29,0.007
20.84,147.50,0.007
20.87,147.72,0.007
20.89,147.94,0.007
20.91,148.16,0.007
20.93,148.37,0.007
20.95,148.59,0.007
20.97,148.80,0.007
20.99,149.02,0.007
21.02,149.24,0.007
21.04,149.45,0.007
21.06,149.67,0.007
21.08,149.89,0.007
21.10,150.10,0.007
21.13,150.32,0.007
21.15,150.54,0.007
21.17,150.76,0.007
21.19,150.97,0.007
21.21,151.19,0.007
21.23,151.41,0.007
21.26,151.62,0.007
21.28,151.84,0.007
21.30,152.06,0.007
21.32,152.27,0.007
21.34,152.49,0.007
21.36,152.71,0.007
21.38,152.92,0.007
21.41,153.14,0.007
21.43,153.36,0.007
21.45,153.57,0.007
21.47,153.79,0.007
21.49,154.01,0.007
21.52,154.22,0.007
21.54,154.44,0.007
21.56,154.66,0.007
21.58,154.88,0.007
21.60,155.09,0.007
21.62,155.31,0.007
21.64,155.53,0.007
21.67,155.74,0.007
21.69,155.96,0.007
21.71,156.18,0.007
21.73,156.39,0.007
21.75,156.61,0.007
21.78,156.83,0.007
21.80,157.04,0.007
21.82,157.26,0.007
21.84,157.48,0.007
21.86,157.69,0.007
21.88,157.91,0.007
21.91,158.13,0.007
21.93,158.35,0.007
21.95,158.56,0.007
21.97,158.78,0.007
21.99,159.00,0.007
22.01,159.21,0.007
22.03,159.43,0.007
22.06,159.65,0.007
22.08,159.86,0.007
22.10,160.08,0.007
22.12,160.30,0.007
22.14,160.52,0.007
22.17,160.73,0.007
22.19,160.95,0.007
22.21,161.17,0.007
22.23,161.38,0.007
22.25,161.60,0.007
22.27,161.81,0.007
22.29,162.03,0.007
22.32,162.25,0.007
22.34,162.46,0.007
22.36,162.68,0.007
22.38,162.90,0.007
22.40,163.11,0.007
22.43,163.33,0.007
22.45,163.55,0.007
22.47,163.76,0.007
22.49,163.98,0.007
22.51,164.20,0.007
22.53,164.41,0.007
22.56,164.63,0.007
22.58,164.85,0.007
22.60,165.07,0.007
22.62,165.28,0.007
22.64,165.50,0.007
22.66,165.72,0.007
22.68,165.93,0.007
22.71,166.15,0.007
22.73,166.37,0.007
22.75,166.59,0.007
22.77,166.80,0.007
22.79,167.02,0.007
22.82,167.24,0.007
22.84,167.45,0.007
22.86,167.67,0.007
22.88,167.89,0.007
22.90,168.10,0.007
22.92,168.32,0.007
22.94,168.54,0.007
22.97,168.75,0.007
22.99,168.97,0.007
23.01,169.19,0.007
23.03,169.40,0.007
23.05,169.62,0.007
23.08,169.84,0.007
23.10,170.05,0.007
23.12,170.27,0.007
23.14,170.49,0.007
23.16,170.70,0.007
23.18,170.92,0.007
23.21,171.14,0.007
23.23,171.35,0.007
23.25,171.57,0.007
23.27,171.79,0.007
23.29,172.00,0.007
23.31,172.22,0.007
23.33,172.44,0.007
23.36,172.66,0.007
23.38,172.87,0.007
23.40,173.09,0.007
23.42,173.31,0.007
23.44,173.52,0.007
23.47,173.74,0.007
23.49,173.95,0.007
23.51,174.17,0.007
23.53,174.39,0.007
23.55,174.61,0.007
23.57,174.82,0.007
23.59,175.04,0.007
23.62,175.26,0.007
23.64,175.47,0.007
23.66,175.69,0.007
23.68,175.91,0.007
23.70,176.12,0.007
23.73,176.34,0.007
23.75,176.56,0.007
23.77,176.77,0.007
23.79,176.99,0.007
23.81,177.21,0.007
23.83,177.42,0.007
23.86,177.64,0.007
23.88,177.86,0.007
23.90,178.07,0.007
23.92,178.29,0.007
23.94,178.51,0.007
23.96,178.73,0.007
23.98,178.94,0.007
24.01,179.16,0.007
24.03,179.38,0.007
24.05,179.59,0.007
24.07,179.81,0.007
24.09,180.03,0.007
24.12,180.24,0.007
24.14,180.46,0.007
24.16,180.68,0.007
24.18,180.90,0.007
24.20,181.11,0.007
24.22,181.33,0.007
24.24,181.55,0.007
24.27,181.76,0.007
24.29,181.98,0.007
24.31,182.19,0.007
24.33,182.41,0.007
24.35,182.63,0.008
24.38,182.84,0.008
24.40,183.06,0.008
24.42,183.28,0.008
24.44,183.50,0.008
24.46,183.71,0.008
24.48,183.93,0.008
24.51,184.15,0.008
24.53,184.37,0.008
24.55,184.58,0.008
24.57,184.80,0.008
24.59,185.01,0.008
24.61,185.23,0.008
24.63,185.45,0.008
24.66,185.66,0.008
24.68,185.88,0.008
24.70,186.10,0.008
24.72,186.31,0.008
24.74,186.53,0.008
24.77,186.75,0.008
24.79,186.96,0.008
24.81,187.18,0.008
24.83,187.40,0.008
24.85,187.61,0.008
24.87,187.83,0.008
24.89,188.05,0.008
24.92,188.27,0.008
24.94,188.48,0.008
24.96,188.70,0.008
24.98,188.92,0.008
25.00,189.13,0.008
25.03,189.35,0.008
25.05,189.56,0.008
25.07,189.78,0.008
25.09,190.00,0.008
25.11,190.22,0.008
25.13,190.43,0.008
25.16,190.65,0.008
25.18,190.87,0.008
25.20,191.08,0.008
25.22,191.30,0.008
25.24,191.52,0.008
25.26,191.73,0.008
25.28,191.95,0.008
25.31,192.17,0.008
25.33,192.38,0.008
25.35,192.60,0.008
25.37,192.82,0.008
25.39,193.03,0.008
25.42,193.25,0.008
25.44,193.47,0.008
25.46,193.69,0.008
25.48,193.90,0.008
25.50,194.12,0.008
25.52,194.34,0.008
25.54,194.55,0.008
25.57,194.77,0.008
25.59,194.99,0.008
25.61,195.20,0.008
25.63,195.42,0.008
25.65,195.64,0.008
25.68,195.85,0.008
25.70,196.07,0.008
25.72,196.29,0.008
25.74,196.50,0.008
25.76,196.72,0.008
25.78,196.94,0.008
25.81,197.16,0.008
25.83,197.37,0.008
25.85,197.59,0.008
25.87,197.80,0.008
25.89,198.02,0.008
25.91,198.24,0.008
25.93,198.45,0.008
25.96,198.67,0.008
25.98,198.89,0.008
26.00,199.11,0.008
26.02,199.32,0.008
26.04,199.54,0.008
26.07,199.76,0.008
26.09,199.97,0.008
26.11,200.19,0.008
26.13,200.41,0.008
26.15,200.62,0.008
26.17,200.84,0.008
26.19,201.06,0.008
26.22,201.27,0.008
26.24,201.49,0.008
26.26,201.71,0.008
26.28,201.92,0.008
26.30,202.14,0.008
26.33,202.36,0.008
26.35,202.58,0.008
26.37,202.79,0.008
26.39,203.01,0.008
26.41,203.23,0.008
26.43,203.44,0.008
26.46,203.66,0.008
26.48,203.88,0.008
26.50,204.09,0.008
26.52,204.31,0.008
26.54,204.53,0.008
26.56,204.74,0.008
26.58,204.96,0.008
26.61,205.18,0.008
26.63,205.39,0.008
26.65,205.61,0.008
26.67,205.83,0.008
26.69,206.05,0.008
26.72,206.26,0.008
26.74,206.48,0.008
26.76,206.70,0.008
26.78,206.91,0.008
26.80,207.13,0.008
26.82,207.34,0.008
26.84,207.56,0.008
26.87,207.78,0.008
26.89,207.99,0.008
26.91,208.21,0.008
26.93,208.43,0.008
26.95,208.65,0.008
26.98,208.86,0.008
27.00,209.08,0.008
27.02,209.30,0.008
27.04,209.51,0.008
27.06,209.73,0.008
27.08,209.95,0.008
27.11,210.16,0.008
27.13,210.38,0.008
27.15,210.60,0.008
27.17,210.81,0.008
27.19,211.03,0.008
27.21,211.25,0.008
27.23,211.46,0.008
27.26,211.68,0.008
27.28,211.90,0.008
27.30,212.11,0.008
27.32,212.33,0.008
27.34,212.55,0.008
27.37,212.77,0.008
27.39,212.98,0.008
27.41,213.20,0.008
27.43,213.42,0.008
27.45,213.63,0.008
27.47,213.85,0.008
27.49,214.06,0.008
27.52,214.28,0.008
27.54,214.50,0.008
27.56,214.71,0.008
27.58,214.93,0.008
27.60,215.15,0.008
27.63,215.36,0.008
27.65,215.58,0.008
27.67,215.80,0.008
27.69,216.01,0.008
27.71,216.23,0.008
27.73,216.45,0.008
27.76,216.67,0.008
27.78,216.88,0.008
27.80,217.10,0.008
27.82,217.32,0.008
27.84,217.53,0.008
27.86,217.75,0.008
27.88,217.97,0.008
27.91,218.18,0.008
27.93,218.40,0.008
27.95,218.62,0.008
27.97,218.84,0.008
27.99,219.05,0.008
28.02,219.27,0.008
28.04,219.49,0.008
28.06,219.70,0.008
28.08,219.92,0.008
28.10,220.13,0.008
28.12,220.35,0.008
28.14,220.57,0.008
28.17,220.78,0.008
28.19,221.00,0.008
28.21,221.22,0.008
28.23,221.44,0.008
28.25,221.65,0.008
28.28,221.87,0.008
28.30,222.09,0.008
28.32,222.30,0.008
28.34,222.52,0.008
28.36,222.74,0.008
28.38,222.95,0.008
28.41,223.17,0.008
28.43,223.39,0.008
28.45,223.60,0.008
28.47,223.82,0.008
28.49,224.04,0.008
28.51,224.25,0.008
28.53,224.47,0.008
28.56,224.69,0.008
28.58,224.90,0.008
28.60,225.12,0.008
28.62,225.34,0.008
28.64,225.55,0.008
28.67,225.77,0.008
28.69,225.99,0.008
28.71,226.20,0.008
28.73,226.42,0.008
28.75,226.64,0.008
28.77,226.85,0.008
28.79,227.07,0.008
28.82,227.29,0.008
28.84,227.50,0.008
28.86,227.72,0.008
28.88,227.94,0.008
28.90,228.16,0.008
28.93,228.37,0.008
28.95,228.59,0.008
28.97,228.81,0.008
28.99,229.02,0.008
29.01,229.24,0.008
29.03,229.46,0.008
29.06,229.67,0.008
29.08,229.89,0.008
29.10,230.11,0.008
29.12,230.32,0.008
29.14,230.54,0.008
29.16,230.76,0.008
29.18,230.97,0.008
29.21,231.19,0.008
29.23,231.41,0.008
29.25,231.62,0.008
29.27,231.84,0.008
29.29,232.06,0.008
29.32,232.28,0.008
29.34,232.49,0.008
29.36,232.71,0.008
29.38,232.93,0.008
29.40,233.14,0.008
29.42,233.36,0.008
29.44,233.57,0.008
29.47,233.79,0.008
29.49,234.01,0.008
29.51,234.23,0.008
29.53,234.44,0.008
29.55,234.66,0.008
29.58,234.88,0.008
29.60,235.09,0.008
29.62,235.31,0.008
29.64,235.53,0.008
29.66,235.74,0.008
29.68,235.96,0.008
29.71,236.18,0.008
29.73,236.39,0.008
29.75,236.61,0.008
29.77,236.83,0.008
29.79,237.04,0.008
29.81,237.26,0.008
29.83,237.48,0.008
29.86,237.69,0.008
29.88,237.91,0.008
29.90,238.13,0.008
29.92,238.34,0.008
29.94,238.56,0.008
29.97,238.78,0.008
29.99,238.99,0.008
30.01,239.21,0.008
30.03,239.43,0.008
30.05,239.64,0.008
30.07,239.86,0.008
30.09,240.08,0.008
30.12,240.30,0.008
30.14,240.51,0.008
30.16,240.73,0.008
30.18,240.95,0.008
30.20,241.16,0.008
30.23,241.38,0.008
30.25,241.60,0.008
30.27,241.81,0.008
30.29,242.03,0.008
30.31,242.25,0.008
30.33,242.46,0.008
30.36,242.68,0.008
30.38,242.90,0.008
30.40,243.11,0.008
30.42,243.33,0.008
30.44,243.55,0.009
30.46,243.76,0.009
30.48,243.98,0.009
30.51,244.20,0.009
30.53,244.41,0.008
30.55,244.63,0.009
30.57,244.85,0.009
30.59,245.06,0.009
30.62,245.28,0.009
30.64,245.50,0.009
30.66,245.71,0.009
30.68,245.93,0.009
30.70,246.15,0.009
30.72,246.37,0.009
30.74,246.58,0.009
30.77,246.80,0.009
30.79,247.02,0.009
30.81,247.23,0.009
30.83,247.45,0.009
30.85,247.67,0.009
30.88,247.88,0.009
30.90,248.10,0.009
30.92,248.32,0.009
30.94,248.53,
30.96,248.75,
30.98,248.97,
30.99,,

[step]
Ramp 10.00 °C/min to -60.00 °C
Time,Temperature,Heat Flow (Normalized)
min,°C,W/g
32.99,250.16,-0.005
33.02,250.16,-0.005
33.04,250.16,-0.005
33.06,250.13,-0.009
33.08,250.09,-0.012
33.10,250.00,-0.016
33.12,249.87,-0.018
33.14,249.72,-0.019
33.17,249.54,-0.019
33.19,249.34,-0.019
33.21,249.13,-0.018
33.23,248.92,-0.018
33.25,248.71,-0.018
33.28,248.49,-0.018
33.30,248.28,-0.018
33.32,248.06,-0.018
33.34,247.85,-0.018
33.36,247.63,-0.018
33.38,247.42,-0.018
33.41,247.20,-0.018
33.43,246.99,-0.018
33.45,246.77,-0.018
33.47,246.56,-0.018
33.49,246.34,-0.018
33.51,246.13,-0.018
33.53,245.91,-0.018
33.56,245.70,-0.018
33.58,245.48,-0.018
33.60,245.27,-0.018
33.62,245.05,-0.018
33.64,244.84,-0.018
33.67,244.62,-0.018
33.69,244.41,-0.018
33.71,244.19,-0.018
33.73,243.98,-0.018
33.75,243.76,-0.018
33.77,243.55,-0.018
33.79,243.33,-0.018
33.82,243.12,-0.018
33.84,242.90,-0.018
33.86,242.68,-0.018
33.88,242.47,-0.018
33.90,242.25,-0.018
33.93,242.04,-0.018
33.95,241.82,-0.018
33.97,241.60,-0.018
33.99,241.39,-0.018
34.01,241.17,-0.018
34.03,240.96,-0.018
34.06,240.74,-0.018
34.08,240.53,-0.018
34.10,240.31,-0.018
34.12,240.09,-0.018
34.14,239.88,-0.018
34.16,239.66,-0.018
34.19,239.44,-0.018
34.21,239.23,-0.018
34.23,239.01,-0.018
34.25,238.80,-0.018
34.27,238.58,-0.018
34.29,238.36,-0.018
34.31,238.15,-0.018
34.34,237.93,-0.018
34.36,237.72,-0.018
34.38,237.50,-0.018
34.40,237.28,-0.018
34.42,237.07,-0.018
34.44,236.85,-0.018
34.47,236.63,-0.018
34.49,236.42,-0.018
34.51,236.20,-0.018
34.53,235.99,-0.018
34.55,235.77,-0.018
34.58,235.55,-0.018
34.60,235.34,-0.018
34.62,235.12,-0.018
34.64,234.91,-0.018
34.66,234.69,-0.018
34.68,234.47,-0.018
34.71,234.26,-0.018
34.73,234.04,-0.018
34.75,233.82,-0.018
34.77,233.61,-0.018
34.79,233.39,-0.018
34.81,233.17,-0.018
34.84,232.96,-0.018
34.86,232.74,-0.018
34.88,232.52,-0.018
34.90,232.31,-0.018
34.92,232.09,-0.018
34.94,231.88,-0.017
34.96,231.66,-0.017
34.99,231.44,-0.017
35.01,231.23,-0.017
35.03,231.01,-0.017
35.05,230.79,-0.017
35.07,230.58,-0.017
35.09,230.36,-0.017
35.12,230.14,-0.017
35.14,229.93,-0.017
35.16,229.71,-0.017
35.18,229.49,-0.017
35.20,229.28,-0.017
35.23,229.06,-0.017
35.25,228.84,-0.017
35.27,228.63,-0.017
35.29,228.41,-0.017
35.31,228.19,-0.017
35.33,227.98,-0.017
35.36,227.76,-0.017
35.38,227.54,-0.017
35.40,227.33,-0.017
35.42,227.11,-0.017
35.44,226.89,-0.017
35.46,226.68,-0.017
35.49,226.46,-0.017
35.51,226.25,-0.017
35.53,226.03,-0.017
35.55,225.81,-0.017
35.57,225.59,-0.017
35.59,225.38,-0.017
35.61,225.16,-0.017
35.64,224.94,-0.017
35.66,224.73,-0.017
35.68,224.51,-0.017
35.70,224.29,-0.017
35.72,224.08,-0.017
35.74,223.86,-0.017
35.77,223.65,-0.017
35.79,223.43,-0.017
35.81,223.21,-0.017
35.83,223.00,-0.017
35.85,222.78,-0.017
35.88,222.56,-0.017
35.90,222.35,-0.017
35.92,222.13,-0.017
35.94,221.91,-0.017
35.96,221.70,-0.017
35.98,221.48,-0.017
36.01,221.26,-0.017
36.03,221.05,-0.017
36.05,220.83,-0.017
36.07,220.61,-0.017
36.09,220.40,-0.017
36.11,220.18,-0.017
36.14,219.96,-0.017
36.16,219.75,-0.017
36.18,219.53,-0.017
36.20,219.31,-0.017
36.22,219.10,-0.017
36.24,218.88,-0.017
36.26,218.67,-0.017
36.29,218.45,-0.017
36.31,218.23,-0.017
36.33,218.02,-0.017
36.35,217.80,-0.017
36.37,217.58,-0.017
36.39,217.37,-0.017
36.42,217.15,-0.017
36.44,216.93,-0.017
36.46,216.72,-0.017
36.48,216.50,-0.017
36.50,216.28,-0.017
36.53,216.07,-0.017
36.55,215.85,-0.017
36.57,215.63,-0.017
36.59,215.42,-0.017
36.61,215.20,-0.017
36.63,214.98,-0.017
36.66,214.77,-0.017
36.68,214.55,-0.017
36.70,214.33,-0.017
36.72,214.12,-0.017
36.74,213.90,-0.017
36.76,213.68,-0.017
36.79,213.47,-0.017
36.81,213.25,-0.017
36.83,213.04,-0.017
36.85,212.82,-0.017
36.87,212.60,-0.017
36.89,212.38,-0.017
36.91,212.17,-0.017
36.94,211.95,-0.017
36.96,211.73,-0.017
36.98,211.52,-0.017
37.00,211.30,-0.017
37.02,211.08,-0.017
37.04,210.87,-0.017
37.07,210.65,-0.017
37.09,210.43,-0.017
37.11,210.22,-0.017
37.13,210.00,-0.017
37.15,209.78,-0.017
37.18,209.57,-0.017
37.20,209.35,-0.017
37.22,209.14,-0.017
37.24,208.92,-0.017
37.26,208.70,-0.017
37.28,208.49,-0.017
37.31,208.27,-0.017
37.33,208.05,-0.017
37.35,207.84,-0.017
37.37,207.62,-0.017
37.39,207.40,-0.017
37.41,207.19,-0.017
37.44,206.97,-0.017
37.46,206.75,-0.017
37.48,206.54,-0.017
37.50,206.32,-0.017
37.52,206.10,-0.017
37.54,205.89,-0.017
37.56,205.67,-0.017
37.59,205.45,-0.017
37.61,205.24,-0.017
37.63,205.02,-0.017
37.65,204.80,-0.017
37.67,204.59,-0.017
37.69,204.37,-0.017
37.72,204.15,-0.017
37.74,203.94,-0.017
37.76,203.72,-0.017
37.78,203.50,-0.017
37.80,203.29,-0.017
37.83,203.07,-0.017
37.85,202.85,-0.017
37.87,202.64,-0.017
37.89,202.42,-0.017
37.91,202.20,-0.017
37.93,201.99,-0.017
37.96,201.77,-0.017
37.98,201.55,-0.017
38.00,201.34,-0.017
38.02,201.12,-0.017
38.04,200.90,-0.017
38.06,200.69,-0.017
38.09,200.47,-0.017
38.11,200.26,-0.017
38.13,200.04,-0.017
38.15,199.82,-0.017
38.17,199.61,-0.017
38.19,199.39,-0.017
38.21,199.17,-0.017
38.24,198.96,-0.017
38.26,198.74,-0.017
38.28,198.52,-0.017
38.30,198.31,-0.017
38.32,198.09,-0.017
38.34,197.87,-0.017
38.37,197.65,-0.017
38.39,197.44,-0.017
38.41,197.22,-0.017
38.43,197.00,-0.017
38.45,196.79,-0.017
38.48,196.57,-0.017
38.50,196.36,-0.017
38.52,196.14,-0.017
38.54,195.92,-0.017
38.56,195.71,-0.017
38.58,195.49,-0.017
38.61,195.27,-0.017
38.63,195.06,-0.017
38.65,194.84,-0.017
38.67,194.62,-0.017
38.69,194.41,-0.017
38.71,194.19,-0.017
38.74,193.97,-0.017
38.76,193.76,-0.017
38.78,193.54,-0.017
38.80,193.32,-0.017
38.82,193.11,-0.017
38.84,192.89,-0.017
38.86,192.67,-0.017
38.89,192.46,-0.017
38.91,192.24,-0.017
38.93,192.02,-0.017
38.95,191.81,-0.017
38.97,191.59,-0.017
38.99,191.37,-0.017
39.02,191.16,-0.017
39.04,190.94,-0.017
39.06,190.73,-0.017
39.08,190.51,-0.017
39.10,190.29,-0.017
39.13,190.07,-0.017
39.15,189.86,-0.017
39.17,189.64,-0.017
39.19,189.42,-0.017
39.21,189.21,-0.017
39.23,188.99,-0.017
39.26,188.78,-0.017
39.28,188.56,-0.017
39.30,188.34,-0.017
39.32,188.13,-0.017
39.34,187.91,-0.017
39.36,187.69,-0.017
39.39,187.47,-0.017
39.41,187.26,-0.017
39.43,187.04,-0.017
39.45,186.82,-0.017
39.47,186.61,-0.017
39.49,186.39,-0.017
39.51,186.18,-0.017
39.54,185.96,-0.017
39.56,185.74,-0.017
39.58,185.53,-0.017
39.60,185.31,-0.017
39.62,185.09,-0.017
39.64,184.88,-0.017
39.67,184.66,-0.017
39.69,184.44,-0.017
39.71,184.22,-0.017
39.73,184.01,-0.017
39.75,183.79,-0.017
39.78,183.58,-0.017
39.80,183.36,-0.017
39.82,183.14,-0.017
39.84,182.93,-0.017
39.86,182.71,-0.017
39.88,182.49,-0.017
39.91,182.28,-0.017
39.93,182.06,-0.017
39.95,181.84,-0.017
39.97,181.63,-0.017
39.99,181.41,-0.017
40.01,181.19,-0.017
40.04,180.98,-0.017
40.06,180.76,-0.017
40.08,180.54,-0.017
40.10,180.33,-0.017
40.12,180.11,-0.017
40.14,179.89,-0.017
40.16,179.68,-0.017
40.19,179.46,-0.017
40.21,179.24,-0.017
40.23,179.03,-0.017
40.25,178.81,-0.017
40.27,178.59,-0.017
40.29,178.38,-0.017
40.32,178.16,-0.017
40.34,177.94,-0.017
40.36,177.73,-0.017
40.38,177.51,-0.017
40.40,177.29,-0.017
40.43,177.08,-0.017
40.45,176.86,-0.017
40.47,176.65,-0.017
40.49,176.43,-0.017
40.51,176.21,-0.017
40.53,175.99,-0.017
40.56,175.78,-0.017
40.58,175.56,-0.017
40.60,175.35,-0.017
40.62,175.13,-0.017
40.64,174.91,-0.017
40.66,174.70,-0.017
40.69,174.48,-0.017
40.71,174.26,-0.017
40.73,174.04,-0.017
40.75,173.83,-0.017
40.77,173.61,-0.017
40.79,173.40,-0.017
40.81,173.18,-0.017
40.84,172.96,-0.017
40.86,172.75,-0.017
40.88,172.53,-0.017
40.90,172.31,-0.017
40.92,172.10,-0.017
40.94,171.88,-0.017
40.97,171.66,-0.017
40.99,171.45,-0.017
41.01,171.23,-0.017
41.03,171.01,-0.017
41.05,170.80,-0.017
41.08,170.58,-0.017
41.10,170.36,-0.017
41.12,170.15,-0.017
41.14,169.93,-0.017
41.16,169.71,-0.017
[...]
140.99,28.73,0.006
141.01,28.95,0.006
141.03,29.17,0.006
141.05,29.38,0.006
141.07,29.60,0.006
141.10,29.82,0.006
141.12,30.03,0.006
141.14,30.25,0.006
141.16,30.47,0.006
141.18,30.68,0.006
141.20,30.90,0.006
141.23,31.12,0.006
141.25,31.33,0.006
141.27,31.55,0.006
141.29,31.77,0.006
141.31,31.98,0.006
141.33,32.20,0.006
141.35,32.42,0.006
141.38,32.63,0.006
141.40,32.85,0.006
141.42,33.07,0.006
141.44,33.29,0.006
141.46,33.50,0.006
141.48,33.72,0.006
141.51,33.94,0.006
141.53,34.15,0.006
141.55,34.37,0.006
141.57,34.59,0.006
141.59,34.80,0.006
141.62,35.02,0.006
141.64,35.24,0.006
141.66,35.45,0.006
141.68,35.67,0.006
141.70,35.89,0.006
141.72,36.11,0.006
141.75,36.32,0.006
141.77,36.54,0.006
141.79,36.76,0.006
141.81,36.97,0.006
141.83,37.19,0.006
141.85,37.41,0.006
141.88,37.62,0.006
141.90,37.84,0.006
141.92,38.06,0.006
141.94,38.28,0.006
141.96,38.49,0.006
141.98,38.71,0.006
142.00,38.93,0.006
142.03,39.14,0.006
142.05,39.36,0.006
142.07,39.58,0.006
142.09,39.79,0.006
142.11,40.01,0.006
142.13,40.23,0.006
142.16,40.44,0.006
142.18,40.66,0.006
142.20,40.88,0.006
142.22,41.09,0.006
142.24,41.31,0.006
142.27,41.53,0.006
142.29,41.75,0.006
142.31,41.96,0.006
142.33,42.18,0.006
142.35,42.40,0.006
142.37,42.61,0.006
142.40,42.83,0.006
142.42,43.05,0.006
142.44,43.26,0.006
142.46,43.48,0.006
142.48,43.70,0.006
142.50,43.91,0.006
142.53,44.13,0.006
142.55,44.35,0.006
142.57,44.57,0.006
142.59,44.78,0.006
142.61,45.00,0.006
142.63,45.22,0.006
142.65,45.43,0.006
142.68,45.65,0.006
142.70,45.87,0.006
142.72,46.08,0.006
142.74,46.30,0.006
142.76,46.52,0.006
142.78,46.73,0.006
142.81,46.95,0.006
142.83,47.17,0.006
142.85,47.38,0.006
142.87,47.60,0.006
142.89,47.82,0.006
142.92,48.04,0.006
142.94,48.25,0.006
142.96,48.47,0.006
142.98,48.68,0.006
143.00,48.90,0.006
143.02,49.12,0.006
143.05,49.34,0.006
143.07,49.55,0.006
143.09,49.77,0.006
143.11,49.99,0.006
143.13,50.20,0.006
143.15,50.42,0.006
143.18,50.64,0.006
143.20,50.85,0.006
143.22,51.07,0.006
143.24,51.29,0.006
143.26,51.50,0.006
143.28,51.72,0.006
143.30,51.94,0.006
143.33,52.16,0.006
143.35,52.37,0.006
143.37,52.59,0.006
143.39,52.81,0.006
143.41,53.02,0.006
143.43,53.24,0.006
143.46,53.46,0.006
143.48,53.67,0.006
143.50,53.89,0.006
143.52,54.11,0.006
143.54,54.33,0.006
143.57,54.54,0.006
143.59,54.76,0.006
143.61,54.98,0.006
143.63,55.19,0.006
143.65,55.41,0.006
143.67,55.63,0.006
143.70,55.84,0.006
143.72,56.06,0.006
143.74,56.28,0.006
143.76,56.49,0.006
143.78,56.71,0.006
143.80,56.93,0.006
143.83,57.14,0.006
143.85,57.36,0.006
143.87,57.58,0.006
143.89,57.80,0.006
143.91,58.01,0.006
143.93,58.23,0.006
143.95,58.45,0.006
143.98,58.66,0.006
144.00,58.88,0.006
144.02,59.10,0.006
144.04,59.31,0.006
144.06,59.53,0.006
144.08,59.75,0.006
144.11,59.96,0.006
144.13,60.18,0.006
144.15,60.40,0.006
144.17,60.61,0.006
144.19,60.83,0.006
144.22,61.05,0.006
144.24,61.27,0.006
144.26,61.48,0.006
144.28,61.70,0.006
144.30,61.92,0.006
144.32,62.13,0.006
144.35,62.35,0.006
144.37,62.57,0.006
144.39,62.78,0.006
144.41,63.00,0.006
144.43,63.22,0.006
144.45,63.44,0.006
144.48,63.65,0.006
144.50,63.87,0.006
144.52,64.09,0.006
144.54,64.30,0.006
144.56,64.52,0.006
144.58,64.74,0.006
144.60,64.95,0.006
144.63,65.17,0.006
144.65,65.39,0.006
144.67,65.60,0.006
144.69,65.82,0.006
144.71,66.04,0.006
144.73,66.25,0.006
144.76,66.47,0.006
144.78,66.69,0.006
144.80,66.91,0.006
144.82,67.12,0.006
144.84,67.34,0.006
144.87,67.56,0.006
144.89,67.77,0.006
144.91,67.99,0.006
144.93,68.21,0.006
144.95,68.42,0.006
144.97,68.64,0.006
145.00,68.86,0.006
145.02,69.07,0.006
145.04,69.29,0.006
145.06,69.51,0.006
145.08,69.73,0.006
145.10,69.94,0.006
145.13,70.16,0.006
145.15,70.38,0.006
145.17,70.59,0.006
145.19,70.81,0.006
145.21,71.03,0.006
145.23,71.24,0.006
145.25,71.46,0.006
145.28,71.68,0.006
145.30,71.89,0.006
145.32,72.11,0.006
145.34,72.33,0.006
145.36,72.55,0.006
145.38,72.76,0.006
145.41,72.98,0.006
145.43,73.20,0.006
145.45,73.41,0.006
145.47,73.63,0.006
145.49,73.85,0.006
145.52,74.06,0.006
145.54,74.28,0.006
145.56,74.50,0.006
145.58,74.71,0.006
145.60,74.93,0.006
145.62,75.15,0.006
145.65,75.36,0.006
145.67,75.58,0.006
145.69,75.80,0.006
145.71,76.01,0.006
145.73,76.23,0.006
145.75,76.45,0.006
145.78,76.66,0.006
145.80,76.88,0.006
145.82,77.10,0.006
145.84,77.32,0.006
145.86,77.53,0.006
145.88,77.75,0.006
145.90,77.97,0.006
145.93,78.18,0.006
145.95,78.40,0.006
145.97,78.62,0.006
145.99,78.83,0.006
146.01,79.05,0.006
146.03,79.27,0.006
146.06,79.48,0.006
146.08,79.70,0.006
146.10,79.92,0.006
146.12,80.13,0.006
146.14,80.35,0.006
146.17,80.57,0.006
146.19,80.78,0.006
146.21,81.00,0.006
146.23,81.22,0.006
146.25,81.44,0.006
146.27,81.65,0.006
146.30,81.87,0.006
146.32,82.09,0.006
146.34,82.30,0.006
146.36,82.52,0.006
146.38,82.74,0.006
146.40,82.95,0.006
146.43,83.17,0.006
146.45,83.39,0.006
146.47,83.60,0.006
146.49,83.82,0.006
146.51,84.04,0.006
146.53,84.25,0.006
146.55,84.47,0.006
146.58,84.69,0.006
146.60,84.90,0.006
146.62,85.12,0.006
146.64,85.34,0.006
146.66,85.55,0.006
146.68,85.77,0.006
146.71,85.99,0.006
146.73,86.20,0.006
146.75,86.42,0.006
146.77,86.64,0.006
146.79,86.86,0.006
146.82,87.07,0.006
146.84,87.29,0.006
146.86,87.51,0.006
146.88,87.72,0.006
146.90,87.94,0.006
146.92,88.16,0.006
146.95,88.37,0.006
146.97,88.59,0.006
146.99,88.81,0.006
147.01,89.03,0.006
147.03,89.24,0.006
147.05,89.46,0.006
147.08,89.68,0.006
147.10,89.90,0.006
147.12,90.12,0.006
147.14,90.33,0.006
147.16,90.55,0.006
147.18,90.77,0.006
147.20,90.98,0.006
147.23,91.20,0.006
147.25,91.42,0.006
147.27,91.63,0.006
147.29,91.85,0.006
147.31,92.07,0.006
147.33,92.28,0.006
147.36,92.50,0.006
147.38,92.71,0.006
147.40,92.93,0.006
147.42,93.15,0.006
147.44,93.36,0.006
147.47,93.58,0.006
147.49,93.80,0.006
147.51,94.01,0.006
147.53,94.23,0.006
147.55,94.45,0.006
147.57,94.66,0.006
147.60,94.88,0.006
147.62,95.10,0.006
147.64,95.32,0.006
147.66,95.53,0.006
147.68,95.75,0.006
147.70,95.97,0.006
147.73,96.18,0.006
147.75,96.40,0.006
147.77,96.62,0.006
147.79,96.83,0.006
147.81,97.05,0.006
147.83,97.27,0.006
147.85,97.48,0.006
147.88,97.70,0.006
147.90,97.92,0.006
147.92,98.13,0.006
147.94,98.35,0.006
147.96,98.57,0.006
147.98,98.78,0.006
148.01,99.00,0.006
148.03,99.22,0.006
148.05,99.43,0.006
148.07,99.65,0.006
148.09,99.87,0.006
148.12,100.09,0.006
148.14,100.30,0.006
148.16,100.52,0.006
148.18,100.74,0.006
148.20,100.95,0.006
148.22,101.17,0.006
148.25,101.39,0.006
148.27,101.60,0.006
148.29,101.82,0.006
148.31,102.04,0.006
148.33,102.26,0.006
148.35,102.47,0.006
148.38,102.69,0.006
148.40,102.90,0.006
148.42,103.12,0.006
148.44,103.34,0.006
148.46,103.55,0.006
148.48,103.77,0.006
148.50,103.99,0.006
148.53,104.20,0.006
148.55,104.42,0.006
148.57,104.64,0.006
148.59,104.85,0.006
148.61,105.07,0.006
148.63,105.29,0.006
148.66,105.51,0.006
148.68,105.72,0.006
148.70,105.94,0.006
148.72,106.16,0.006
148.74,106.37,0.006
148.77,106.59,0.006
148.79,106.81,0.006
148.81,107.02,0.006
148.83,107.24,0.006
148.85,107.46,0.006
148.87,107.68,0.006
148.90,107.89,0.006
148.92,108.11,0.006
148.94,108.33,0.006
148.96,108.54,0.006
148.98,108.76,0.006
149.00,108.98,0.006
149.03,109.19,0.006
149.05,109.41,0.006
149.07,109.63,0.006
149.09,109.84,0.006
149.11,110.06,0.006
149.13,110.28,0.006
149.15,110.49,0.006
149.18,110.71,0.006
149.20,110.92,0.006
149.22,111.14,0.006
149.24,111.36,0.006
149.26,111.58,0.006
149.28,111.79,0.006
149.31,112.01,0.006
149.33,112.23,0.006
149.35,112.44,0.006
149.37,112.66,0.006
149.39,112.88,0.006
149.42,113.10,0.006
149.44,113.31,0.006
149.46,113.53,0.006
149.48,113.75,0.006
149.50,113.96,0.006
149.52,114.18,0.006
149.55,114.40,0.006
149.57,114.61,0.006
149.59,114.83,0.006
149.61,115.04,0.006
149.63,115.26,0.006
149.65,115.48,0.006
149.68,115.70,0.006
149.70,115.91,0.006
149.72,116.13,0.006
149.74,116.35,0.006
149.76,116.56,0.006
149.78,116.78,0.006
149.80,117.00,0.006
149.83,117.21,0.006
149.85,117.43,0.006
149.87,117.65,0.007
149.89,117.87,0.006
149.91,118.08,0.007
149.93,118.30,0.007
149.96,118.52,0.007
149.98,118.73,0.007
150.00,118.95,0.007
150.02,119.17,0.007
150.04,119.38,0.007
150.07,119.60,0.007
150.09,119.82,0.007
150.11,120.04,0.007
150.13,120.25,0.007
150.15,120.47,0.007
150.17,120.68,0.007
150.20,120.90,0.007
150.22,121.12,0.007
150.24,121.34,0.007
150.26,121.55,0.007
150.28,121.77,0.007
150.30,121.98,0.007
150.33,122.20,0.007
150.35,122.42,0.007
150.37,122.64,0.007
150.39,122.85,0.007
150.41,123.07,0.007
150.43,123.29,0.007
150.45,123.50,0.007
150.48,123.72,0.007
150.50,123.94,0.007
150.52,124.15,0.007
150.54,124.37,0.007
150.56,124.59,0.007
150.58,124.80,0.007
150.61,125.02,0.007
150.63,125.24,0.007
150.65,125.45,0.007
150.67,125.67,0.007
150.69,125.89,0.007
150.72,126.10,0.007
150.74,126.32,0.007
150.76,126.54,0.007
150.78,126.76,0.007
150.80,126.97,0.007
150.82,127.19,0.007
150.85,127.41,0.007
150.87,127.62,0.007
150.89,127.84,0.007
150.91,128.06,0.007
150.93,128.27,0.007
150.95,128.49,0.007
150.98,128.71,0.007
151.00,128.92,0.007
151.02,129.14,0.007
151.04,129.36,0.007
151.06,129.57,0.007
151.08,129.79,0.007
151.10,130.01,0.007
151.13,130.23,0.007
151.15,130.44,0.007
151.17,130.66,0.007
151.19,130.88,0.007
151.21,131.09,0.007
151.23,131.31,0.007
151.26,131.53,0.007
151.28,131.74,0.007
151.30,131.96,0.007
151.32,132.18,0.007
151.34,132.40,0.007
151.37,132.61,0.007
151.39,132.83,0.007
151.41,133.05,0.007
151.43,133.26,0.007
151.45,133.48,0.007
151.47,133.70,0.007
151.50,133.92,0.007
151.52,134.13,0.007
151.54,134.35,0.007
151.56,134.57,0.007
151.58,134.78,0.007
151.60,135.00,0.007
151.63,135.21,0.007
151.65,135.43,0.007
151.67,135.65,0.007
151.69,135.86,0.007
151.71,136.08,0.007
151.73,136.30,0.007
151.75,136.51,0.007
151.78,136.73,0.007
151.80,136.95,0.007
151.82,137.17,0.007
151.84,137.38,0.007
151.86,137.60,0.007
151.88,137.82,0.007
151.91,138.03,0.007
151.93,138.25,0.007
151.95,138.47,0.007
151.97,138.69,0.007
151.99,138.90,0.007
152.02,139.12,0.007
152.04,139.34,0.007
152.06,139.55,0.007
152.08,139.77,0.007
152.10,139.99,0.007
152.12,140.20,0.007
152.15,140.42,0.007
152.17,140.64,0.007
152.19,140.85,0.007
152.21,141.07,0.007
152.23,141.29,0.007
152.25,141.50,0.007
152.28,141.72,0.007
152.30,141.94,0.007
152.32,142.15,0.007
152.34,142.37,0.007
152.36,142.59,0.007
152.38,142.80,0.007
152.40,143.02,0.007
152.43,143.24,0.007
152.45,143.45,0.007
152.47,143.67,0.007
152.49,143.89,0.007
152.51,144.10,0.007
152.53,144.32,0.007
152.56,144.54,0.007
152.58,144.75,0.007
152.60,144.97,0.007
152.62,145.19,0.007
152.64,145.41,0.007
152.67,145.62,0.007
152.69,145.84,0.007
152.71,146.06,0.007
152.73,146.27,0.007
152.75,146.49,0.007
152.77,146.71,0.007
152.80,146.92,0.007
152.82,147.14,0.007
152.84,147.36,0.007
152.86,147.57,0.007
152.88,147.79,0.007
152.90,148.01,0.007
152.93,148.22,0.007
152.95,148.44,0.007
152.97,148.66,0.007
152.99,148.88,0.007
153.01,149.09,0.007
153.03,149.31,0.007
153.05,149.52,0.007
153.08,149.74,0.007
153.10,149.96,0.007
153.12,150.17,0.007
153.14,150.39,0.007
153.16,150.61,0.007
153.18,150.82,0.007
153.21,151.04,0.007
153.23,151.26,0.007
153.25,151.48,0.007
153.27,151.69,0.007
153.29,151.91,0.007
153.32,152.13,0.007
153.34,152.34,0.007
153.36,152.56,0.007
153.38,152.78,0.007
153.40,152.99,0.007
153.42,153.21,0.007
153.45,153.43,0.007
153.47,153.64,0.007
153.49,153.86,0.007
153.51,154.08,0.007
153.53,154.29,0.007
153.55,154.51,0.007
153.58,154.73,0.007
153.60,154.94,0.007
153.62,155.16,0.007
153.64,155.38,0.007
153.66,155.59,0.007
153.68,155.81,0.007
153.70,156.03,0.007
153.73,156.25,0.007
153.75,156.46,0.007
153.77,156.68,0.007
153.79,156.89,0.007
153.81,157.11,0.007
153.83,157.33,0.007
153.86,157.55,0.007
153.88,157.76,0.007
153.90,157.98,0.007
153.92,158.20,0.007
153.94,158.42,0.007
153.97,158.63,0.007
153.99,158.85,0.007
154.01,159.07,0.007
154.03,159.28,0.007
154.05,159.50,0.007
154.07,159.72,0.007
154.10,159.93,0.007
154.12,160.15,0.007
154.14,160.37,0.007
154.16,160.58,0.007
154.18,160.80,0.007
154.20,161.02,0.007
154.23,161.23,0.007
154.25,161.45,0.007
154.27,161.67,0.007
154.29,161.88,0.007
154.31,162.10,0.007
154.33,162.31,0.007
154.35,162.53,0.007
154.38,162.75,0.007
154.40,162.96,0.007
154.42,163.18,0.007
154.44,163.40,0.007
154.46,163.61,0.007
154.48,163.83,0.007
154.51,164.05,0.007
154.53,164.27,0.007
154.55,164.48,0.007
154.57,164.70,0.007
154.59,164.92,0.007
154.62,165.14,0.007
154.64,165.35,0.007
154.66,165.57,0.007
154.68,165.79,0.007
154.70,166.01,0.007
154.72,166.22,0.007
154.75,166.44,0.007
154.77,166.65,0.007
154.79,166.87,0.007
154.81,167.09,0.007
154.83,167.30,0.007
154.85,167.52,0.007
154.88,167.73,0.007
154.90,167.95,0.007
154.92,168.17,0.007
154.94,168.39,0.007
154.96,168.60,0.007
154.98,168.82,0.007
155.00,169.04,0.007
155.03,169.25,0.007
155.05,169.47,0.007
155.07,169.69,0.007
155.09,169.90,0.007
155.11,170.12,0.007
155.13,170.34,0.007
155.16,170.55,0.007
155.18,170.77,0.007
155.20,170.99,0.007
155.22,171.20,0.007
155.24,171.42,0.007
155.27,171.64,0.007
155.29,171.86,0.007
155.31,172.07,0.007
155.33,172.29,0.007
155.35,172.51,0.007
155.37,172.72,0.007
155.40,172.94,0.007
155.42,173.16,0.007
155.44,173.38,0.007
155.46,173.59,0.007
155.48,173.81,0.007
155.50,174.02,0.007
155.53,174.24,0.007
155.55,174.46,0.007
155.57,174.68,0.007
155.59,174.89,0.007
155.61,175.11,0.007
155.63,175.33,0.007
155.65,175.54,0.007
155.68,175.76,0.007
155.70,175.98,0.007
155.72,176.19,0.007
155.74,176.41,0.007
155.76,176.63,0.007
155.78,176.84,0.007
155.81,177.06,0.007
155.83,177.28,0.007
155.85,177.49,0.007
155.87,177.71,0.007
155.89,177.93,0.007
155.92,178.14,0.007
155.94,178.36,0.007
155.96,178.58,0.007
155.98,178.79,0.007
156.00,179.01,0.007
156.02,179.23,0.007
156.05,179.44,0.007
156.07,179.66,0.007
156.09,179.88,0.007
156.11,180.09,0.007
156.13,180.31,0.007
156.15,180.53,0.007
156.18,180.74,0.007
156.20,180.96,0.007
156.22,181.18,0.007
156.24,181.40,0.007
156.26,181.61,0.007
156.28,181.83,0.007
156.30,182.04,0.007
156.33,182.26,0.007
156.35,182.48,0.007
156.37,182.69,0.007
156.39,182.91,0.007
156.41,183.13,0.007
156.43,183.35,0.007
156.46,183.56,0.007
156.48,183.78,0.007
156.50,184.00,0.007
156.52,184.21,0.007
156.54,184.43,0.007
156.57,184.65,0.007
156.59,184.86,0.007
156.61,185.08,0.007
156.63,185.30,0.007
156.65,185.51,0.007
156.67,185.73,0.007
156.70,185.95,0.007
156.72,186.17,0.007
156.74,186.38,0.007
156.76,186.60,0.007
156.78,186.82,0.007
156.80,187.03,0.007
156.83,187.25,0.007
156.85,187.47,0.007
156.87,187.68,0.007
156.89,187.90,0.007
156.91,188.12,0.007
156.93,188.33,0.007
156.95,188.55,0.007
156.98,188.77,0.007
157.00,188.98,0.007
157.02,189.20,0.007
157.04,189.42,0.007
157.06,189.63,0.007
157.08,189.85,0.007
157.11,190.07,0.007
157.13,190.28,0.007
157.15,190.50,0.007
157.17,190.72,0.007
157.19,190.93,0.007
157.22,191.15,0.007
157.24,191.37,0.007
157.26,191.58,0.007
157.28,191.80,0.007
157.30,192.02,0.007
157.32,192.24,0.007
157.35,192.45,0.007
157.37,192.67,0.007
157.39,192.89,0.007
157.41,193.10,0.007
157.43,193.32,0.007
157.45,193.54,0.007
157.48,193.75,0.007
157.50,193.97,0.007
157.52,194.19,0.007
157.54,194.40,0.007
157.56,194.62,0.007
157.58,194.84,0.007
157.60,195.05,0.007
157.63,195.27,0.007
157.65,195.49,0.007
157.67,195.70,0.007
157.69,195.92,0.007
157.71,196.14,0.007
157.73,196.35,0.007
157.76,196.57,0.007
157.78,196.79,0.007
157.80,197.00,0.007
157.82,197.22,0.007
157.84,197.44,0.007
157.87,197.65,0.007
157.89,197.87,0.007
157.91,198.09,0.007
157.93,198.31,0.007
157.95,198.52,0.007
157.97,198.74,0.007
158.00,198.96,0.007
158.02,199.17,0.007
158.04,199.39,0.007
158.06,199.61,0.007
158.08,199.83,0.007
158.10,200.04,0.007
158.13,200.26,0.007
158.15,200.47,0.007
158.17,200.69,0.007
158.19,200.91,0.007
158.21,201.13,0.007
158.23,201.34,0.007
158.25,201.56,0.007
158.28,201.78,0.007
158.30,201.99,0.007
158.32,202.21,0.007
158.34,202.43,0.007
158.36,202.64,0.007
158.38,202.86,0.007
158.41,203.08,0.007
158.43,203.29,0.007
158.45,203.51,0.007
158.47,203.73,0.007
158.49,203.95,0.007
158.52,204.16,0.007
158.54,204.38,0.007
158.56,204.60,0.007
158.58,204.81,0.007
158.60,205.03,0.007
158.62,205.24,0.007
158.65,205.46,0.007
158.67,205.68,0.007
158.69,205.89,0.007
158.71,206.11,0.007
158.73,206.33,0.007
158.75,206.54,0.007
158.78,206.76,0.007
158.80,206.98,0.007
158.82,207.19,0.007
158.84,207.41,0.007
158.86,207.63,0.007
158.88,207.84,0.007
158.90,208.06,0.007
158.93,208.28,0.007
158.95,208.50,0.007
158.97,208.71,0.007
158.99,208.93,0.007
159.01,209.15,0.007
159.03,209.36,0.007
159.06,209.58,0.007
159.08,209.80,0.007
159.10,210.01,0.007
159.12,210.23,0.007
159.14,210.45,0.007
159.17,210.66,0.007
159.19,210.88,0.007
159.21,211.10,0.007
159.23,211.31,0.007
159.25,211.53,0.007
159.27,211.75,0.007
159.30,211.96,0.007
159.32,212.18,0.007
159.34,212.40,0.007
159.36,212.61,0.007
159.38,212.83,0.007
159.40,213.05,0.007
159.43,213.27,0.007
159.45,213.48,0.007
159.47,213.70,0.007
159.49,213.92,0.007
159.51,214.13,0.007
159.53,214.35,0.007
159.55,214.57,0.007
159.58,214.78,0.007
159.60,215.00,0.007
159.62,215.22,0.007
159.64,215.43,0.007
159.66,215.65,0.007
159.68,215.87,0.007
159.71,216.08,0.007
159.73,216.30,0.007
159.75,216.52,0.007
159.77,216.73,0.007
159.79,216.95,0.007
159.82,217.17,0.007
159.84,217.38,0.007
159.86,217.60,0.007
159.88,217.82,0.007
159.90,218.03,0.007
159.92,218.25,0.007
159.95,218.47,0.007
159.97,218.69,0.008
159.99,218.90,0.008
160.01,219.12,0.008
160.03,219.34,0.008
160.05,219.55,0.008
160.08,219.77,0.008
160.10,219.98,0.008
160.12,220.20,0.008
160.14,220.42,0.008
160.16,220.63,0.008
160.18,220.85,0.008
160.20,221.07,0.008
160.23,221.29,0.008
160.25,221.50,0.008
160.27,221.72,0.008
160.29,221.94,0.008
160.31,222.15,0.008
160.33,222.37,0.008
160.36,222.59,0.008
160.38,222.80,0.008
160.40,223.02,0.008
160.42,223.24,0.008
160.44,223.45,0.008
160.47,223.67,0.008
160.49,223.89,0.008
160.51,224.10,0.008
160.53,224.32,0.008
160.55,224.54,0.008
160.57,224.75,0.008
160.60,224.97,0.008
160.62,225.19,0.008
160.64,225.41,0.008
160.66,225.62,0.008
160.68,225.84,0.008
160.70,226.06,0.008
160.73,226.27,0.008
160.75,226.49,0.008
160.77,226.71,0.008
160.79,226.92,0.008
160.81,227.14,0.008
160.83,227.36,0.008
160.85,227.57,0.008
160.88,227.79,0.008
160.90,228.01,0.008
160.92,228.22,0.008
160.94,228.44,0.008
160.96,228.66,0.008
160.98,228.87,0.008
161.01,229.09,0.008
161.03,229.31,0.008
161.05,229.52,0.008
161.07,229.74,0.008
161.09,229.96,0.008
161.12,230.17,0.008
161.14,230.39,0.008
161.16,230.61,0.008
161.18,230.83,0.008
161.20,231.04,0.008
161.22,231.26,0.008
161.25,231.48,0.008
161.27,231.69,0.008
161.29,231.91,0.008
161.31,232.13,0.008
161.33,232.34,0.008
161.35,232.56,0.008
161.38,232.78,0.008
161.40,232.99,0.008
161.42,233.21,0.008
161.44,233.43,0.008
161.46,233.64,0.008
161.48,233.86,0.008
161.50,234.08,0.008
161.53,234.29,0.008
161.55,234.51,0.008
161.57,234.73,0.008
161.59,234.94,0.008
161.61,235.16,0.008
161.63,235.38,0.008
161.66,235.59,0.008
161.68,235.81,0.008
161.70,236.03,0.008
161.72,236.24,0.008
161.74,236.46,0.008
161.77,236.68,0.008
161.79,236.89,0.008
161.81,237.11,0.008
161.83,237.33,0.008
161.85,237.55,0.008
161.87,237.76,0.008
161.90,237.98,0.008
161.92,238.20,0.008
161.94,238.41,0.008
161.96,238.63,0.008
161.98,238.85,0.008
162.00,239.06,0.008
162.03,239.28,0.008
162.05,239.50,0.008
162.07,239.71,0.008
162.09,239.93,0.008
162.11,240.15,0.008
162.13,240.36,0.008
162.15,240.58,0.008
162.18,240.80,0.008
162.20,241.01,0.008
162.22,241.23,0.008
162.24,241.45,0.008
162.26,241.66,0.008
162.28,241.88,0.008
162.31,242.10,0.008
162.33,242.31,0.008
162.35,242.53,0.008
162.37,242.75,0.008
162.39,242.96,0.008
162.42,243.18,0.008
162.44,243.40,0.008
162.46,243.61,0.008
162.48,243.83,0.008
162.50,244.05,0.008
162.52,244.27,0.008
162.55,244.48,0.008
162.57,244.70,0.008
162.59,244.92,0.008
162.61,245.13,0.008
162.63,245.35,0.008
162.65,245.57,0.008
162.68,245.78,0.008
162.70,246.00,0.008
162.72,246.22,0.008
162.74,246.43,0.008
162.76,246.65,0.008
162.78,246.87,0.008
162.80,247.08,0.008
162.83,247.30,0.008
162.85,247.52,0.008
162.87,247.73,0.008
162.89,247.95,0.008
162.91,248.17,0.008
162.93,248.38,0.008
162.96,248.60,
162.98,248.82,
162.99,,