File: DSC/Olivia/2025_08_09_1CBN_3PVP29_MP_n60C_200C_10Cmin_x3.csv
Filename,2025_08_09_1CBN_3PVP29_MP_n60C_200C_10Cmin_x3
Instrument name,DSC2A-00468 (192.168.1.100)
Operator,Yarger
rundate,8/10/2025
Sample name,2025_08_09_1CBN_3PVP29_MP_n60C_200C_10Cmin_x3
proceduresegments,Data Off ; Equilibrate -60.00 °C; Data On ; Ramp 10.00 °C/min to 200.00 °C; Data Off ; Isothermal 2.0 min; Data On ; Ramp 10.00 °C/min to -60.00 °C; Data Off ; Isothermal 2.0 min; Data On ; Ramp 10.00 °C/min to 200.00 °C; Data Off ; Isothermal 2.0 min; Data On ; Ramp 10.00 °C/min to -60.00 °C; Data Off ; Isothermal 2.0 min; Data On ; Ramp 10.00 °C/min to 200.00 °C
[File Parameters]
Run date,8/10/2025 3:06:49 AM
Trios version,5.1.1.46572
Original File Name,
Current File Name,D:\DSC2500\JYarger\2025_08_09_1CBN_3PVP29_MP_n60C_200C_10Cmin_x3.tri
[Procedure]
Procedure Name,CBN_PVP_TS_n60C_200C_10Cmin_x3
Sample Name,2025_08_09_1CBN_3PVP29_MP_n60C_200C_10Cmin_x3
Sample Mass,32.64 mg
Reference Sample Mass,0 mg
Pan Mass,8.05 mg
Pan Number,14
Reference Pan Mass,32.42 mg
Reference Pan Number,10
Pan Type,Aluminum
Comments,Thermal support Al pans/lids. DSC_Samples_A2_Tray_August2025 google sheet.
Project Name,Pharma
Operator,Yarger
Test,Custom
Unload Max Temperature,30
Unload Min Temperature,30
Load Max Temperature,30
Load Min Temperature,30
Stop on Gas Flow Error,Yes
[Signal List]
Signal #1,Time (min)
Signal #2,Temperature (°C)
Signal #3,Heat Flow (mW)
Signal #4,Delta T (µV)
Signal #5,Delta Tzero (µV)
Signal #6,Tzero Temperature (°C)
Signal #7,Cell Purge (mL/min)
Signal #8,Heater Temp (°C)
Signal #9,Power Delivered (W)
Signal #10,Reference Junction Temperature (°C)
Signal #11,Flange Temperature (°C)
Signal #12,Heat Flow Phase (rad)
Signal #13,Total Heat Capacity (J/°C)
Signal #14,Heat Capacity (J/°C)
[Configuration]
Company Name,ASU
Instrument Name,DSC2A-00468
Instrument Type,DSC2500
Serial Number,DSC2A-00468
IP,192.168.1.100
Location of Instrument,MRRC
DisplayType,Unknown
Sample Interval ,0.1 s/pt
Selected Heat Flow,T4P
Exotherm Direction,Down
Cell Serial,DRC2-00792
Lid Type,Standard
Cooler,RCS 90
Leave Cooler on at End of Sequence,On
Gas 2,Nitrogen
Gas Selected,Channel 1
Flow Rate,50 mL/min
Secondary Purge,On
Licensed Heat Flow,Heat Flow T4P
Modulation Licensed,Yes
[Versions]
Common IDD Version,1
Cortex Version,VER 2.10.2.31
Driver,5.0.0.6
GDM Version,1.0.3.3
TouchscreenVersion,1.0.0.16145
FEP Version,1.2.1.21
FEP Bootloader,2.0.0.5
AutoSampler Version,2.1.1.26
Auto Sampler Bootloader,2.0.0.5
FCM Version,1.1.0.3
FCM Bootloader,2.0.0.5
[Experiment Logs]
Experiment Log Entry # 1,Data On set to 0
Experiment Log Entry # 3,Equilibrate Segment -60 (C) Started
Experiment Log Entry # 5,Air Cool is off.
Experiment Log Entry # 7,Data On set to 1
Experiment Log Entry # 9,Ramp Segment 10 C/min to 200 Started
Experiment Log Entry # 11,Data On set to 0
Experiment Log Entry # 13,Isothermal Segment 2 min started
Experiment Log Entry # 15,Data On set to 1
Experiment Log Entry # 17,Ramp Segment 10 C/min to -60 Started
Experiment Log Entry # 19,Data On set to 0
Experiment Log Entry # 21,Isothermal Segment 2 min started
Experiment Log Entry # 23,Data On set to 1
Experiment Log Entry # 25,Ramp Segment 10 C/min to 200 Started
Experiment Log Entry # 27,Data On set to 0
Experiment Log Entry # 29,Isothermal Segment 2 min started
Experiment Log Entry # 31,Data On set to 1
Experiment Log Entry # 33,Ramp Segment 10 C/min to -60 Started
Experiment Log Entry # 35,Data On set to 0
Experiment Log Entry # 37,Isothermal Segment 2 min started
Experiment Log Entry # 39,Data On set to 1
Experiment Log Entry # 41,Ramp Segment 10 C/min to 200 Started
[Method Log]
Method Log Entry # 1,Data Off
Method Log Entry # 2,Equilibrate -60 °C
Method Log Entry # 3,Data On
Method Log Entry # 4,(Ramp 831514) Ramp 10 °C/minute to 200 °C
Method Log Entry # 5,Data Off
Method Log Entry # 6,Isothermal 2 minutes
Method Log Entry # 7,Data On
Method Log Entry # 8,(Ramp 831518) Ramp 10 °C/minute to -60 °C
Method Log Entry # 9,Data Off
Method Log Entry # 10,Isothermal 2 minutes
Method Log Entry # 11,Data On
Method Log Entry # 12,(Ramp 831522) Ramp 10 °C/minute to 200 °C
Method Log Entry # 13,Data Off
Method Log Entry # 14,Isothermal 2 minutes
Method Log Entry # 15,Data On
Method Log Entry # 16,(Ramp 831526) Ramp 10 °C/minute to -60 °C
Method Log Entry # 17,Data Off
Method Log Entry # 18,Isothermal 2 minutes
Method Log Entry # 19,Data On
Method Log Entry # 20,(Ramp 831530) Ramp 10 °C/minute to 200 °C
Cell Serial,DRC2-00792
[T1 Calibration]
Slope,-0.008529666
Offset,9.636258
Initial Temperature,98.23
GUID,f8bfdadc-4977-4fdf-ba6d-0ba9134940c3
[TZero Calibration]
Date Applied,11/29/2022 4:06:13 PM
Description,From -89.059 °C to 396.009 °C at 20.000°C/min
Gas Type,Nitrogen
Pan Type,None
Source Files 1,C:\Users\yargerlab\Desktop\DSC Data\General\TZero_calibration_11_29_22_2nd(2).tri
Source Files 2,C:\Users\yargerlab\Desktop\DSC Data\General\TZero_calibration_11_29_22_2nd(3).tri
Delta T Offset,13.05235
Delta T Slope,-0.007271007
Delta T0 Offset,-13.69128
Delta T0 Slope,0.06063341
[Temperature Calibration]
Date Applied,11/29/2022 7:12:28 PM
Description,From 106.590 °C to 186.590 °C at 10.000°C/min
Gas Type,Nitrogen
Pan Type,Tzero Aluminum Hermetic
Source Files 1,C:\Users\yargerlab\Desktop\DSC Data\General\Indium(6).tri
Measured 1,157.391
Known 1,156.598
[Cell Constant Calibration]
Date Applied,11/29/2022 7:12:29 PM
Description,From 106.590 °C to 186.590 °C at 10.000°C/min
Gas Type,Nitrogen
Pan Type,Tzero Aluminum Hermetic
Source Files 1,C:\Users\yargerlab\Desktop\DSC Data\General\Indium(6).tri
T4P KCell,1.006051
Onset Slope,63.26126 mW/°C
[Direct Cp Calibration]
Date Applied,11/30/2022 11:04:51 AM
Description,From -79.983 °C to 298.409 °C at 10.000°C/min
Gas Type,Nitrogen
Pan Type,Tzero Aluminum Hermetic
Source Files 1,C:\Users\yargerlab\Desktop\DSC Data\General\Sapphire_Heat_Capacity_11_30_22.tri
[Rev Cp Calibration]
Date Applied,11/30/2022 1:58:51 PM
Description,From -79.996 °C to 292.812 °C at 3.000°C/min
Gas Type,Nitrogen
Pan Type,Tzero Aluminum Hermetic
Source Files 1,C:\Users\yargerlab\Desktop\DSC Data\General\Sapphire_MDSC_Calibration_11_30_22.tri
[step]
Ramp 10.00 °C/min to 200.00 °C
Time,Temperature,Heat Flow (Normalized)
min,°C,W/g
0.00,-59.80,-0.009
0.02,-59.80,-0.008
0.04,-59.81,-0.008
0.05,-59.80,-0.007
0.07,-59.77,-0.006
0.09,-59.72,-0.004
0.11,-59.65,0.000
0.13,-59.55,0.004
0.15,-59.44,0.010
0.16,-59.31,0.015
0.18,-59.17,0.021
0.20,-59.02,0.025
0.22,-58.86,0.029
0.24,-58.69,0.033
0.26,-58.53,0.036
0.28,-58.36,0.038
0.29,-58.18,0.040
0.31,-58.01,0.041
0.33,-57.84,0.042
0.35,-57.66,0.043
0.37,-57.48,0.044
0.39,-57.31,0.045
0.40,-57.13,0.045
0.42,-56.95,0.045
0.44,-56.77,0.046
0.46,-56.59,0.046
0.48,-56.42,0.046
0.50,-56.24,0.046
0.51,-56.06,0.047
0.53,-55.88,0.047
0.55,-55.70,0.047
0.57,-55.52,0.047
0.59,-55.33,0.047
0.60,-55.16,0.047
0.62,-54.97,0.047
0.64,-54.79,0.047
0.66,-54.61,0.047
0.68,-54.43,0.047
0.70,-54.25,0.048
0.72,-54.07,0.048
0.73,-53.89,0.048
0.75,-53.71,0.048
0.77,-53.52,0.048
0.79,-53.34,0.048
0.81,-53.16,0.048
0.83,-52.98,0.048
0.84,-52.80,0.048
0.86,-52.62,0.048
0.88,-52.44,0.048
0.90,-52.25,0.048
0.92,-52.07,0.048
0.93,-51.89,0.048
0.95,-51.71,0.049
0.97,-51.52,0.049
0.99,-51.34,0.049
1.01,-51.16,0.049
1.03,-50.98,0.049
1.05,-50.80,0.049
1.06,-50.61,0.049
1.08,-50.43,0.049
1.10,-50.25,0.049
1.12,-50.06,0.049
1.14,-49.88,0.049
1.16,-49.70,0.049
1.17,-49.52,0.049
1.19,-49.33,0.049
1.21,-49.15,0.049
1.23,-48.97,0.049
1.25,-48.79,0.049
1.27,-48.60,0.049
1.28,-48.42,0.049
1.30,-48.24,0.050
1.32,-48.05,0.050
1.34,-47.87,0.050
1.36,-47.69,0.050
1.38,-47.51,0.050
1.39,-47.32,0.050
1.41,-47.14,0.050
1.43,-46.95,0.050
1.45,-46.77,0.050
1.47,-46.59,0.050
1.48,-46.41,0.050
1.50,-46.22,0.050
1.52,-46.04,0.050
1.54,-45.86,0.050
1.56,-45.67,0.050
1.58,-45.49,0.050
1.59,-45.31,0.050
1.61,-45.12,0.050
1.63,-44.94,0.050
1.65,-44.76,0.050
1.67,-44.57,0.050
1.69,-44.39,0.050
1.71,-44.21,0.050
1.72,-44.02,0.050
1.74,-43.84,0.051
1.76,-43.66,0.051
1.78,-43.47,0.051
1.80,-43.29,0.051
1.82,-43.11,0.051
1.83,-42.92,0.051
1.85,-42.74,0.051
1.87,-42.56,0.051
1.89,-42.37,0.051
1.91,-42.19,0.051
1.93,-42.01,0.051
1.94,-41.82,0.051
1.96,-41.64,0.051
1.98,-41.46,0.051
2.00,-41.27,0.051
2.02,-41.09,0.051
2.03,-40.91,0.051
2.05,-40.72,0.051
2.07,-40.54,0.051
2.09,-40.36,0.051
2.11,-40.17,0.051
2.13,-39.99,0.051
2.14,-39.81,0.051
2.16,-39.62,0.051
2.18,-39.44,0.051
2.20,-39.26,0.051
2.22,-39.07,0.051
2.24,-38.89,0.051
2.26,-38.70,0.051
2.27,-38.52,0.051
2.29,-38.34,0.051
2.31,-38.15,0.052
2.33,-37.97,0.052
2.35,-37.79,0.052
2.36,-37.60,0.052
2.38,-37.42,0.052
2.40,-37.23,0.052
2.42,-37.05,0.052
2.44,-36.87,0.052
2.46,-36.68,0.052
2.48,-36.50,0.052
2.49,-36.32,0.052
2.51,-36.13,0.052
2.53,-35.95,0.052
2.55,-35.77,0.052
2.57,-35.58,0.052
2.59,-35.40,0.052
2.60,-35.21,0.052
2.62,-35.03,0.052
2.64,-34.85,0.052
2.66,-34.66,0.052
2.68,-34.48,0.052
2.69,-34.30,0.052
2.71,-34.11,0.052
2.73,-33.93,0.052
2.75,-33.75,0.052
2.77,-33.56,0.052
2.79,-33.38,0.052
2.81,-33.20,0.052
2.82,-33.01,0.052
2.84,-32.83,0.053
2.86,-32.65,0.053
2.88,-32.46,0.053
2.90,-32.28,0.053
2.91,-32.10,0.053
2.93,-31.92,0.053
2.95,-31.73,0.053
2.97,-31.55,0.053
2.99,-31.36,0.053
3.01,-31.18,0.053
3.03,-31.00,0.053
3.04,-30.81,0.053
3.06,-30.63,0.053
3.08,-30.45,0.053
3.10,-30.26,0.053
3.12,-30.08,0.053
3.14,-29.89,0.053
3.15,-29.71,0.053
3.17,-29.53,0.053
3.19,-29.34,0.053
3.21,-29.16,0.053
3.23,-28.97,0.053
3.24,-28.79,0.053
3.26,-28.61,0.053
3.28,-28.42,0.053
3.30,-28.24,0.053
3.32,-28.06,0.053
3.34,-27.87,0.053
3.36,-27.69,0.053
3.37,-27.51,0.053
3.39,-27.32,0.053
3.41,-27.14,0.054
3.43,-26.96,0.054
3.45,-26.77,0.054
3.46,-26.59,0.054
3.48,-26.40,0.054
3.50,-26.22,0.054
3.52,-26.04,0.054
3.54,-25.85,0.054
3.56,-25.67,0.054
3.58,-25.49,0.054
3.59,-25.30,0.054
3.61,-25.12,0.054
3.63,-24.94,0.054
3.65,-24.75,0.054
3.67,-24.57,0.054
3.69,-24.39,0.054
3.70,-24.20,0.054
3.72,-24.02,0.054
3.74,-23.84,0.054
3.76,-23.65,0.054
3.78,-23.47,0.054
3.79,-23.29,0.054
3.81,-23.10,0.054
3.83,-22.92,0.054
3.85,-22.73,0.054
3.87,-22.55,0.054
3.89,-22.37,0.054
3.91,-22.18,0.054
3.92,-22.00,0.054
3.94,-21.82,0.055
3.96,-21.63,0.055
3.98,-21.45,0.055
4.00,-21.27,0.055
4.01,-21.08,0.055
4.03,-20.90,0.055
4.05,-20.72,0.055
4.07,-20.53,0.055
4.09,-20.35,0.055
4.11,-20.17,0.055
4.13,-19.98,0.055
4.14,-19.80,0.055
4.16,-19.62,0.055
4.18,-19.43,0.055
4.20,-19.25,0.055
4.22,-19.07,0.055
4.24,-18.88,0.055
4.25,-18.70,0.055
4.27,-18.51,0.055
4.29,-18.33,0.055
4.31,-18.15,0.055
4.33,-17.96,0.055
4.35,-17.78,0.055
4.36,-17.60,0.055
4.38,-17.41,0.055
4.40,-17.23,0.056
4.42,-17.05,0.056
4.44,-16.86,0.056
4.45,-16.68,0.056
4.47,-16.50,0.056
4.49,-16.31,0.056
4.51,-16.13,0.056
4.53,-15.95,0.056
4.55,-15.76,0.056
4.56,-15.58,0.056
4.58,-15.40,0.056
4.60,-15.21,0.056
4.62,-15.03,0.056
4.64,-14.85,0.056
4.66,-14.66,0.056
4.68,-14.48,0.056
4.69,-14.30,0.056
4.71,-14.11,0.056
4.73,-13.93,0.056
4.75,-13.75,0.056
4.77,-13.56,0.056
4.79,-13.38,0.056
4.80,-13.19,0.056
4.82,-13.01,0.056
4.84,-12.83,0.057
4.86,-12.64,0.057
4.88,-12.46,0.057
4.90,-12.28,0.057
4.91,-12.09,0.057
4.93,-11.91,0.057
4.95,-11.73,0.057
4.97,-11.54,0.057
4.99,-11.36,0.057
5.00,-11.18,0.057
5.02,-10.99,0.057
5.04,-10.81,0.057
5.06,-10.63,0.057
5.08,-10.44,0.057
5.10,-10.26,0.057
5.11,-10.08,0.057
5.13,-9.89,0.057
5.15,-9.71,0.057
5.17,-9.53,0.057
5.19,-9.34,0.057
5.21,-9.16,0.057
5.23,-8.98,0.057
5.24,-8.79,0.057
5.26,-8.61,0.058
5.28,-8.43,0.058
5.30,-8.24,0.058
5.32,-8.06,0.058
5.34,-7.87,0.058
5.35,-7.69,0.058
5.37,-7.51,0.058
5.39,-7.32,0.058
5.41,-7.14,0.058
5.43,-6.96,0.058
5.45,-6.77,0.058
5.46,-6.59,0.058
5.48,-6.41,0.058
5.50,-6.22,0.058
5.52,-6.04,0.058
5.54,-5.86,0.058
5.55,-5.67,0.058
5.57,-5.49,0.058
5.59,-5.31,0.058
5.61,-5.12,0.058
5.63,-4.94,0.058
5.65,-4.76,0.059
5.66,-4.57,0.059
5.68,-4.39,0.059
5.70,-4.21,0.059
5.72,-4.02,0.059
5.74,-3.84,0.059
5.76,-3.66,0.059
5.78,-3.47,0.059
5.79,-3.29,0.059
5.81,-3.10,0.059
5.83,-2.92,0.059
5.85,-2.74,0.059
5.87,-2.55,0.059
5.89,-2.37,0.059
5.90,-2.19,0.059
5.92,-2.00,0.059
5.94,-1.82,0.059
5.96,-1.63,0.059
5.98,-1.45,0.059
6.00,-1.27,0.059
6.01,-1.09,0.060
6.03,-0.90,0.060
6.05,-0.72,0.060
6.07,-0.53,0.060
6.09,-0.35,0.060
6.10,-0.17,0.060
6.12,0.02,0.060
6.14,0.20,0.060
6.16,0.39,0.060
6.18,0.57,0.060
6.20,0.75,0.060
6.21,0.93,0.060
6.23,1.12,0.060
6.25,1.30,0.060
6.27,1.49,0.060
6.29,1.67,0.060
6.31,1.85,0.060
6.33,2.03,0.060
6.34,2.22,0.060
6.36,2.40,0.060
6.38,2.59,0.061
6.40,2.77,0.061
6.42,2.95,0.061
6.44,3.14,0.061
6.45,3.32,0.061
6.47,3.50,0.061
6.49,3.69,0.061
6.51,3.87,0.061
6.53,4.05,0.061
6.55,4.24,0.061
6.56,4.42,0.061
6.58,4.60,0.061
6.60,4.79,0.061
6.62,4.97,0.061
6.64,5.15,0.061
6.65,5.34,0.061
6.67,5.52,0.061
6.69,5.70,0.061
6.71,5.89,0.061
6.73,6.07,0.062
6.75,6.25,0.062
6.76,6.44,0.062
6.78,6.62,0.062
6.80,6.80,0.062
6.82,6.99,0.062
6.84,7.17,0.062
6.86,7.35,0.062
6.88,7.54,0.062
6.89,7.72,0.062
6.91,7.90,0.062
6.93,8.09,0.062
6.95,8.27,0.062
6.97,8.45,0.062
6.99,8.64,0.062
7.00,8.82,0.062
7.02,9.00,0.063
7.04,9.19,0.063
7.06,9.37,0.063
7.08,9.56,0.063
7.10,9.74,0.063
7.11,9.92,0.063
7.13,10.11,0.063
7.15,10.29,0.063
7.17,10.47,0.063
7.19,10.66,0.063
7.20,10.84,0.063
7.22,11.02,0.063
7.24,11.21,0.063
7.26,11.39,0.063
7.28,11.57,0.063
7.30,11.76,0.063
7.31,11.94,0.063
7.33,12.12,0.064
7.35,12.31,0.064
7.37,12.49,0.064
7.39,12.67,0.064
7.41,12.86,0.064
7.43,13.04,0.064
7.44,13.23,0.064
7.46,13.41,0.064
7.48,13.59,0.064
7.50,13.78,0.064
7.52,13.96,0.064
7.54,14.14,0.064
7.55,14.33,0.064
7.57,14.51,0.064
7.59,14.69,0.064
7.61,14.88,0.065
7.63,15.06,0.065
7.65,15.24,0.065
7.66,15.43,0.065
7.68,15.61,0.065
7.70,15.79,0.065
7.72,15.97,0.065
7.74,16.16,0.065
7.75,16.34,0.065
7.77,16.53,0.065
7.79,16.71,0.065
7.81,16.89,0.065
7.83,17.08,0.065
7.85,17.26,0.065
7.86,17.44,0.065
7.88,17.63,0.065
7.90,17.81,0.066
7.92,17.99,0.066
7.94,18.18,0.066
7.96,18.36,0.066
7.98,18.54,0.066
7.99,18.73,0.066
8.01,18.91,0.066
8.03,19.09,0.066
8.05,19.28,0.066
8.07,19.46,0.066
8.09,19.64,0.066
8.10,19.83,0.066
8.12,20.01,0.066
8.14,20.19,0.067
8.16,20.38,0.067
8.18,20.56,0.067
8.20,20.74,0.067
8.21,20.93,0.067
8.23,21.11,0.067
8.25,21.29,0.067
8.27,21.47,0.067
8.29,21.66,0.067
8.30,21.84,0.067
8.32,22.03,0.067
8.34,22.21,0.067
8.36,22.39,0.067
8.38,22.58,0.068
8.40,22.76,0.068
8.41,22.94,0.068
8.43,23.13,0.068
8.45,23.31,0.068
8.47,23.49,0.068
8.49,23.68,0.068
8.51,23.86,0.068
8.53,24.04,0.068
8.54,24.23,0.068
8.56,24.41,0.068
8.58,24.59,0.068
8.60,24.78,0.069
8.62,24.96,0.069
8.63,25.14,0.069
8.65,25.33,0.069
8.67,25.51,0.069
8.69,25.69,0.069
8.71,25.88,0.069
8.73,26.06,0.069
8.75,26.24,0.069
8.76,26.43,0.069
8.78,26.61,0.069
8.80,26.79,0.070
8.82,26.98,0.070
8.84,27.16,0.070
8.85,27.35,0.070
8.87,27.53,0.070
8.89,27.71,0.070
8.91,27.90,0.070
8.93,28.08,0.070
8.95,28.26,0.070
8.97,28.44,0.070
8.98,28.63,0.071
9.00,28.81,0.071
9.02,28.99,0.071
9.04,29.18,0.071
9.06,29.36,0.071
9.08,29.54,0.071
9.09,29.73,0.071
9.11,29.91,0.071
9.13,30.09,0.071
9.15,30.28,0.071
9.17,30.46,0.072
9.18,30.65,0.072
9.20,30.83,0.072
9.22,31.01,0.072
9.24,31.19,0.072
9.26,31.38,0.072
9.28,31.56,0.072
9.30,31.75,0.072
9.31,31.93,0.073
9.33,32.11,0.073
9.35,32.30,0.073
9.37,32.48,0.073
9.39,32.66,0.073
9.40,32.84,0.073
9.42,33.03,0.073
9.44,33.21,0.073
9.46,33.40,0.073
9.48,33.58,0.074
9.50,33.76,0.074
9.52,33.95,0.074
9.53,34.13,0.074
9.55,34.31,0.074
9.57,34.49,0.074
9.59,34.68,0.074
9.61,34.86,0.075
9.63,35.04,0.075
9.64,35.23,0.075
9.66,35.41,0.075
9.68,35.59,0.075
9.70,35.78,0.075
9.72,35.96,0.075
9.73,36.14,0.076
9.75,36.33,0.076
9.77,36.51,0.076
9.79,36.69,0.076
9.81,36.88,0.076
9.83,37.06,0.077
9.85,37.24,0.077
9.86,37.43,0.077
9.88,37.61,0.077
9.90,37.79,0.077
9.92,37.97,0.078
9.94,38.16,0.078
9.95,38.34,0.078
9.97,38.52,0.078
9.99,38.71,0.078
10.01,38.89,0.079
10.03,39.07,0.079
10.05,39.26,0.079
10.07,39.44,0.079
10.08,39.62,0.080
10.10,39.81,0.080
10.12,39.99,0.080
10.14,40.17,0.080
10.16,40.36,0.081
10.18,40.54,0.081
10.19,40.72,0.081
10.21,40.90,0.081
10.23,41.09,0.082
10.25,41.27,0.082
10.27,41.45,0.082
10.28,41.64,0.083
10.30,41.82,0.083
10.32,42.00,0.083
10.34,42.19,0.084
10.36,42.37,0.084
10.38,42.55,0.084
10.40,42.73,0.085
10.41,42.92,0.085
10.43,43.10,0.086
10.45,43.28,0.086
10.47,43.47,0.086
10.49,43.65,0.087
10.50,43.83,0.087
10.52,44.01,0.088
10.54,44.20,0.088
10.56,44.38,0.088
10.58,44.56,0.089
10.60,44.74,0.089
10.62,44.93,0.090
10.63,45.11,0.090
10.65,45.29,0.091
10.67,45.47,0.091
10.69,45.66,0.092
10.71,45.84,0.092
10.73,46.02,0.092
10.74,46.21,0.093
10.76,46.39,0.093
10.78,46.57,0.093
10.80,46.75,0.094
10.82,46.94,0.094
10.83,47.12,0.094
10.85,47.30,0.094
10.87,47.48,0.095
10.89,47.67,0.095
10.91,47.85,0.095
10.93,48.03,0.095
10.95,48.22,0.095
10.96,48.40,0.095
10.98,48.58,0.095
11.00,48.77,0.096
11.02,48.95,0.096
11.04,49.13,0.096
11.05,49.32,0.096
11.07,49.50,0.096
11.09,49.68,0.096
11.11,49.87,0.096
11.13,50.05,0.096
11.15,50.23,0.096
11.17,50.42,0.096
11.18,50.60,0.096
11.20,50.79,0.096
11.22,50.97,0.096
11.24,51.15,0.096
11.26,51.34,0.096
11.28,51.52,0.096
11.29,51.70,0.096
11.31,51.89,0.096
11.33,52.07,0.097
11.35,52.25,0.097
11.37,52.44,0.097
11.38,52.62,0.097
11.40,52.80,0.097
11.42,52.99,0.097
11.44,53.17,0.097
11.46,53.35,0.097
11.48,53.54,0.097
11.50,53.72,0.097
11.51,53.90,0.098
11.53,54.09,0.098
11.55,54.27,0.098
11.57,54.45,0.098
11.59,54.63,0.099
11.60,54.82,0.099
11.62,55.00,0.099
11.64,55.19,0.100
11.66,55.37,0.100
11.68,55.55,0.101
11.70,55.73,0.101
11.72,55.92,0.102
11.73,56.10,0.102
11.75,56.28,0.103
11.77,56.46,0.103
11.79,56.65,0.104
11.81,56.83,0.104
11.83,57.01,0.105
11.84,57.19,0.105
11.86,57.38,0.106
11.88,57.56,0.106
11.90,57.74,0.107
11.92,57.92,0.108
11.93,58.10,0.108
11.95,58.29,0.109
11.97,58.47,0.109
11.99,58.65,0.110
12.01,58.83,0.110
12.03,59.02,0.111
12.05,59.20,0.112
12.06,59.38,0.112
12.08,59.56,0.113
12.10,59.75,0.114
12.12,59.93,0.114
12.14,60.11,0.115
12.15,60.29,0.116
12.17,60.48,0.116
12.19,60.66,0.117
12.21,60.84,0.118
12.23,61.02,0.118
12.25,61.20,0.119
12.27,61.39,0.120
12.28,61.57,0.121
12.30,61.75,0.122
12.32,61.93,0.122
12.34,62.11,0.123
12.36,62.29,0.124
12.38,62.48,0.125
12.39,62.66,0.126
12.41,62.84,0.127
12.43,63.02,0.128
12.45,63.20,0.129
12.47,63.38,0.130
12.48,63.57,0.131
12.50,63.75,0.132
12.52,63.93,0.133
12.54,64.11,0.134
12.56,64.29,0.135
12.58,64.47,0.137
12.60,64.65,0.138
12.61,64.84,0.139
12.63,65.02,0.140
12.65,65.20,0.142
12.67,65.38,0.143
12.69,65.56,0.145
12.70,65.74,0.146
12.72,65.92,0.147
12.74,66.10,0.149
12.76,66.28,0.150
12.78,66.46,0.152
12.80,66.64,0.154
12.82,66.82,0.155
12.83,67.00,0.157
12.85,67.18,0.158
12.87,67.36,0.160
12.89,67.54,0.161
12.91,67.72,0.163
12.93,67.90,0.165
12.94,68.08,0.166
12.96,68.26,0.168
12.98,68.44,0.169
13.00,68.62,0.171
13.02,68.80,0.172
13.03,68.99,0.174
13.05,69.16,0.175
13.07,69.34,0.177
13.09,69.53,0.178
13.11,69.71,0.179
13.13,69.89,0.180
13.15,70.07,0.181
13.16,70.25,0.181
13.18,70.43,0.182
13.20,70.61,0.182
13.22,70.80,0.182
13.24,70.98,0.182
13.25,71.17,0.182
13.27,71.35,0.180
13.29,71.54,0.178
13.31,71.72,0.176
13.33,71.91,0.173
13.35,72.10,0.171
13.37,72.28,0.167
13.38,72.47,0.163
13.40,72.67,0.159
13.42,72.86,0.155
13.44,73.05,0.150
13.46,73.24,0.146
13.48,73.44,0.141
13.49,73.63,0.137
13.51,73.82,0.133
13.53,74.01,0.130
13.55,74.20,0.126
13.57,74.40,0.123
13.58,74.59,0.121
13.60,74.78,0.118
13.62,74.96,0.116
13.64,75.15,0.114
13.66,75.34,0.112
13.68,75.53,0.111
13.70,75.72,0.110
13.71,75.90,0.109
13.73,76.09,0.109
13.75,76.27,0.109
13.77,76.46,0.108
13.79,76.64,0.109
13.80,76.83,0.109
13.82,77.01,0.109
13.84,77.20,0.110
13.86,77.38,0.110
13.88,77.56,0.110
13.90,77.74,0.111
13.92,77.92,0.111
13.93,78.11,0.112
13.95,78.29,0.112
13.97,78.47,0.113
13.99,78.65,0.114
14.01,78.84,0.115
14.03,79.02,0.115
14.04,79.20,0.116
14.06,79.38,0.116
14.08,79.56,0.117
14.10,79.75,0.118
14.12,79.93,0.118
14.13,80.11,0.119
14.15,80.29,0.119
14.17,80.48,0.120
14.19,80.66,0.120
14.21,80.84,0.121
14.23,81.02,0.122
14.25,81.21,0.122
14.26,81.39,0.123
14.28,81.57,0.123
14.30,81.75,0.124
14.32,81.93,0.125
14.34,82.12,0.125
14.35,82.30,0.126
14.37,82.48,0.127
14.39,82.66,0.127
14.41,82.85,0.128
14.43,83.03,0.128
14.45,83.21,0.129
14.47,83.39,0.130
14.48,83.57,0.130
14.50,83.76,0.131
14.52,83.94,0.131
14.54,84.12,0.132
14.56,84.30,0.132
14.58,84.49,0.133
14.59,84.67,0.134
14.61,84.85,0.134
14.63,85.03,0.135
14.65,85.22,0.135
14.67,85.40,0.136
14.68,85.58,0.137
14.70,85.76,0.137
14.72,85.95,0.138
14.74,86.13,0.139
14.76,86.31,0.139
14.78,86.49,0.140
14.80,86.67,0.140
14.81,86.86,0.141
14.83,87.04,0.142
14.85,87.22,0.142
14.87,87.40,0.143
14.89,87.58,0.144
14.90,87.77,0.144
14.92,87.95,0.145
14.94,88.13,0.145
14.96,88.31,0.146
14.98,88.50,0.146
15.00,88.68,0.147
15.02,88.86,0.147
15.03,89.04,0.148
15.05,89.23,0.148
15.07,89.41,0.149
15.09,89.59,0.149
15.11,89.78,0.150
15.13,89.96,0.150
15.14,90.14,0.151
15.16,90.32,0.151
15.18,90.51,0.152
15.20,90.69,0.153
15.22,90.87,0.154
15.23,91.05,0.154
15.25,91.23,0.155
15.27,91.42,0.155
15.29,91.60,0.156
15.31,91.78,0.157
15.33,91.96,0.157
15.35,92.14,0.158
15.36,92.33,0.158
15.38,92.51,0.159
15.40,92.69,0.160
15.42,92.88,0.160
15.44,93.06,0.161
15.45,93.24,0.162
15.47,93.42,0.162
15.49,93.60,0.163
15.51,93.79,0.164
15.53,93.97,0.164
15.55,94.15,0.165
15.57,94.33,0.165
15.58,94.52,0.166
15.60,94.70,0.167
15.62,94.88,0.167
15.64,95.06,0.168
15.66,95.24,0.168
15.68,95.43,0.169
15.69,95.61,0.170
15.71,95.79,0.170
15.73,95.97,0.171
15.75,96.16,0.171
15.77,96.34,0.172
15.78,96.52,0.172
15.80,96.70,0.173
15.82,96.89,0.174
15.84,97.07,0.174
15.86,97.25,0.175
15.88,97.43,0.176
15.90,97.62,0.176
15.91,97.80,0.177
15.93,97.98,0.177
15.95,98.16,0.178
15.97,98.34,0.178
15.99,98.53,0.179
16.00,98.71,0.180
16.02,98.89,0.180
16.04,99.07,0.181
16.06,99.25,0.181
16.08,99.44,0.182
16.10,99.62,0.183
16.12,99.80,0.183
16.13,99.99,0.184
16.15,100.17,0.184
16.17,100.35,0.185
16.19,100.53,0.185
16.21,100.71,0.186
16.23,100.90,0.187
16.24,101.08,0.187
16.26,101.26,0.188
16.28,101.45,0.188
16.30,101.63,0.188
16.32,101.81,0.189
16.33,101.99,0.189
16.35,102.18,0.190
16.37,102.36,0.190
16.39,102.54,0.190
16.41,102.73,0.190
16.43,102.91,0.190
16.45,103.09,0.190
16.46,103.27,0.191
16.48,103.46,0.191
16.50,103.64,0.191
16.52,103.82,0.191
16.54,104.01,0.192
16.55,104.19,0.192
16.57,104.37,0.192
16.59,104.55,0.192
16.61,104.74,0.192
16.63,104.92,0.193
16.65,105.10,0.193
16.67,105.29,0.193
16.68,105.47,0.193
16.70,105.65,0.193
16.72,105.84,0.193
16.74,106.02,0.193
16.76,106.21,0.193
16.78,106.39,0.193
16.79,106.57,0.193
16.81,106.76,0.192
16.83,106.94,0.192
16.85,107.13,0.192
16.87,107.31,0.191
16.88,107.50,0.190
16.90,107.68,0.189
16.92,107.87,0.188
16.94,108.05,0.187
16.96,108.24,0.186
16.98,108.42,0.184
17.00,108.61,0.182
17.01,108.80,0.181
17.03,108.98,0.179
17.05,109.17,0.178
17.07,109.35,0.176
17.09,109.54,0.175
17.11,109.73,0.174
17.12,109.91,0.172
17.14,110.10,0.171
17.16,110.29,0.169
17.18,110.47,0.168
17.20,110.66,0.166
17.22,110.85,0.164
17.23,111.04,0.162
17.25,111.22,0.160
17.27,111.41,0.157
17.29,111.60,0.155
17.31,111.79,0.153
17.33,111.97,0.151
17.34,112.16,0.148
17.36,112.35,0.146
17.38,112.54,0.143
17.40,112.73,0.141
17.42,112.92,0.138
17.43,113.11,0.136
17.45,113.29,0.134
17.47,113.48,0.131
17.49,113.67,0.130
17.51,113.86,0.128
17.53,114.04,0.126
17.54,114.23,0.124
17.56,114.42,0.122
17.58,114.61,0.121
17.60,114.79,0.119
17.62,114.98,0.118
17.64,115.17,0.117
17.66,115.35,0.115
17.67,115.54,0.114
17.69,115.73,0.112
17.71,115.91,0.111
17.73,116.10,0.110
17.75,116.28,0.110
17.77,116.47,0.109
17.78,116.66,0.109
17.80,116.84,0.108
17.82,117.02,0.107
17.84,117.21,0.107
17.86,117.39,0.106
17.88,117.58,0.106
17.89,117.76,0.105
17.91,117.95,0.105
17.93,118.13,0.104
17.95,118.32,0.104
17.97,118.50,0.103
17.98,118.69,0.103
18.00,118.87,0.102
18.02,119.05,0.102
18.04,119.24,0.102
18.06,119.42,0.101
18.08,119.61,0.101
18.09,119.79,0.101
18.11,119.98,0.100
18.13,120.16,0.100
18.15,120.34,0.100
18.17,120.53,0.100
18.19,120.71,0.099
18.21,120.90,0.099
18.22,121.08,0.099
18.24,121.27,0.099
18.26,121.45,0.098
18.28,121.63,0.098
18.30,121.82,0.098
18.32,122.00,0.098
18.33,122.19,0.098
18.35,122.37,0.098
18.37,122.55,0.098
18.39,122.74,0.098
18.41,122.92,0.097
18.43,123.10,0.097
18.44,123.29,0.097
18.46,123.47,0.097
18.48,123.66,0.097
18.50,123.84,0.097
18.52,124.02,0.097
18.53,124.21,0.097
18.55,124.39,0.101
18.57,124.55,0.129
18.59,124.73,0.110
18.61,124.92,0.105
18.63,125.10,0.103
18.64,125.29,0.102
18.66,125.48,0.101
18.68,125.66,0.100
18.70,125.85,0.100
18.72,126.01,0.143
18.74,126.18,0.117
18.76,126.37,0.111
18.77,126.54,0.254
18.79,125.53,1.946
18.81,124.97,1.549
18.83,124.96,1.303
18.85,125.14,1.164
18.87,125.40,1.069
18.88,125.70,0.992
18.90,126.01,0.927
18.92,126.31,0.868
18.94,126.61,0.812
18.96,126.91,0.764
18.98,127.20,0.720
18.99,127.48,0.679
19.01,127.75,0.641
19.03,128.01,0.609
19.05,128.27,0.577
19.07,128.52,0.549
19.08,128.76,0.523
19.10,129.00,0.499
19.12,129.24,0.478
19.14,129.47,0.458
19.16,129.70,0.440
19.18,129.92,0.424
19.19,130.14,0.409
19.21,130.35,0.397
19.23,130.57,0.385
19.25,130.78,0.374
19.27,130.98,0.364
19.29,131.19,0.354
19.31,131.39,0.345
19.32,131.60,0.336
19.34,131.80,0.328
19.36,132.00,0.320
19.38,132.20,0.313
19.40,132.40,0.306
19.42,132.59,0.300
19.43,132.79,0.294
19.45,132.99,0.292
19.47,133.18,0.288
19.49,133.37,0.282
19.51,133.56,0.277
19.53,133.76,0.272
19.54,133.95,0.267
19.56,134.14,0.263
19.58,134.34,0.258
19.60,134.53,0.254
19.62,134.72,0.249
19.63,134.91,0.245
19.65,135.11,0.241
19.67,135.30,0.237
19.69,135.49,0.232
19.71,135.68,0.228
19.73,135.88,0.224
19.74,136.07,0.221
19.76,136.26,0.218
19.78,136.45,0.215
19.80,136.63,0.212
19.82,136.82,0.211
19.84,137.01,0.208
19.86,137.20,0.206
19.87,137.39,0.204
19.89,137.58,0.201
19.91,137.76,0.199
19.93,137.95,0.197
19.95,138.14,0.194
19.97,138.33,0.191
19.98,138.52,0.189
20.00,138.70,0.186
20.02,138.89,0.184
20.04,139.08,0.182
20.06,139.27,0.180
20.08,139.46,0.178
20.09,139.64,0.177
20.11,139.83,0.175
20.13,140.02,0.173
20.15,140.20,0.171
20.17,140.39,0.169
20.18,140.58,0.168
20.20,140.77,0.166
20.22,140.95,0.164
20.24,141.14,0.162
20.26,141.33,0.160
20.28,141.51,0.158
20.29,141.70,0.156
20.31,141.89,0.154
20.33,142.08,0.152
20.35,142.26,0.150
20.37,142.45,0.149
20.39,142.64,0.147
20.41,142.82,0.146
20.42,143.01,0.144
20.44,143.20,0.143
20.46,143.38,0.140
20.48,143.57,0.138
20.50,143.76,0.137
20.52,143.95,0.135
20.53,144.13,0.134
20.55,144.32,0.132
20.57,144.51,0.132
20.59,144.69,0.131
20.61,144.88,0.130
20.63,145.06,0.129
20.64,145.25,0.129
20.66,145.43,0.128
20.68,145.62,0.128
20.70,145.80,0.127
20.72,145.99,0.126
20.73,146.17,0.126
20.75,146.36,0.125
20.77,146.54,0.125
20.79,146.73,0.124
20.81,146.91,0.124
20.83,147.09,0.123
20.84,147.28,0.123
20.86,147.46,0.123
20.88,147.65,0.122
20.90,147.83,0.122
20.92,148.01,0.122
20.94,148.20,0.121
20.96,148.38,0.121
20.97,148.57,0.120
20.99,148.75,0.120
21.01,148.94,0.120
21.03,149.12,0.120
21.05,149.31,0.119
21.07,149.49,0.119
21.08,149.67,0.119
21.10,149.86,0.119
21.12,150.04,0.119
21.14,150.23,0.118
21.16,150.41,0.118
21.18,150.59,0.118
21.19,150.78,0.118
21.21,150.96,0.117
21.23,151.15,0.117
21.25,151.33,0.117
21.27,151.51,0.117
21.28,151.70,0.117
21.30,151.88,0.116
21.32,152.06,0.116
21.34,152.25,0.116
21.36,152.43,0.115
21.38,152.62,0.115
21.39,152.80,0.115
21.41,152.98,0.114
21.43,153.17,0.114
21.45,153.35,0.114
21.47,153.54,0.114
21.49,153.72,0.114
21.51,153.90,0.114
21.52,154.09,0.113
21.54,154.27,0.113
21.56,154.46,0.113
21.58,154.64,0.112
21.60,154.82,0.112
21.62,155.01,0.112
21.63,155.19,0.112
21.65,155.38,0.111
21.67,155.56,0.111
21.69,155.74,0.110
21.71,155.93,0.110
21.73,156.11,0.109
21.74,156.30,0.109
21.76,156.48,0.109
21.78,156.67,0.109
21.80,156.85,0.109
21.82,157.03,0.109
21.83,157.22,0.109
21.85,157.40,0.108
21.87,157.58,0.108
21.89,157.77,0.108
21.91,157.95,0.108
21.93,158.14,0.108
21.94,158.32,0.107
21.96,158.50,0.107
21.98,158.69,0.107
22.00,158.87,0.107
22.02,159.06,0.107
22.04,159.24,0.107
22.06,159.42,0.107
22.07,159.61,0.107
22.09,159.79,0.107
22.11,159.97,0.106
22.13,160.16,0.106
22.15,160.34,0.106
22.17,160.52,0.107
22.18,160.71,0.108
22.20,160.89,0.107
22.22,161.07,0.107
22.24,161.26,0.107
22.26,161.44,0.107
22.28,161.62,0.107
22.29,161.81,0.107
22.31,161.99,0.107
22.33,162.18,0.107
22.35,162.36,0.107
22.37,162.54,0.107
22.38,162.73,0.106
22.40,162.91,0.106
22.42,163.09,0.106
22.44,163.28,0.106
22.46,163.46,0.106
22.48,163.65,0.106
22.49,163.83,0.106
22.51,164.01,0.106
22.53,164.20,0.105
22.55,164.38,0.105
22.57,164.56,0.105
22.59,164.75,0.105
22.61,164.93,0.105
22.62,165.12,0.105
22.64,165.30,0.105
22.66,165.48,0.105
22.68,165.67,0.105
22.70,165.85,0.104
22.72,166.03,0.104
22.73,166.22,0.104
22.75,166.40,0.104
22.77,166.59,0.104
22.79,166.77,0.104
22.81,166.95,0.104
22.83,167.14,0.104
22.84,167.32,0.104
22.86,167.50,0.103
22.88,167.69,0.103
22.90,167.87,0.103
22.92,168.06,0.103
22.93,168.24,0.103
22.95,168.42,0.103
22.97,168.61,0.103
22.99,168.79,0.103
23.01,168.97,0.103
23.03,169.16,0.102
23.04,169.34,0.102
23.06,169.52,0.102
23.08,169.71,0.102
23.10,169.89,0.102
23.12,170.08,0.102
23.14,170.26,0.102
23.16,170.44,0.102
23.17,170.63,0.102
23.19,170.81,0.102
23.21,171.00,0.102
23.23,171.18,0.102
23.25,171.36,0.101
23.27,171.55,0.101
23.28,171.73,0.101
23.30,171.91,0.101
23.32,172.10,0.101
23.34,172.28,0.101
23.36,172.46,0.101
23.38,172.65,0.101
23.39,172.83,0.101
23.41,173.01,0.101
23.43,173.20,0.101
23.45,173.38,0.101
23.47,173.56,0.100
23.48,173.75,0.100
23.50,173.93,0.100
23.52,174.12,0.100
23.54,174.30,0.100
23.56,174.48,0.100
23.58,174.67,0.100
23.59,174.85,0.100
23.61,175.03,0.100
23.63,175.22,0.100
23.65,175.40,0.100
23.67,175.58,0.100
23.69,175.77,0.100
23.71,175.95,0.100
23.72,176.14,0.099
23.74,176.32,0.099
23.76,176.50,0.099
23.78,176.69,0.099
23.80,176.87,0.099
23.82,177.05,0.099
23.83,177.24,0.099
23.85,177.42,0.099
23.87,177.60,0.099
23.89,177.79,0.099
23.91,177.97,0.099
23.93,178.16,0.099
23.94,178.34,0.099
23.96,178.52,0.099
23.98,178.71,0.099
24.00,178.89,0.099
24.02,179.07,0.099
24.03,179.26,0.098
24.05,179.44,0.098
24.07,179.62,0.098
24.09,179.81,0.098
24.11,179.99,0.098
24.13,180.17,0.098
24.14,180.36,0.098
24.16,180.54,0.098
24.18,180.72,0.098
24.20,180.91,0.098
24.22,181.09,0.098
24.24,181.27,0.098
24.26,181.46,0.098
24.27,181.64,0.098
24.29,181.83,0.098
24.31,182.01,0.098
24.33,182.20,0.098
24.35,182.38,0.098
24.37,182.56,0.098
24.38,182.74,0.098
24.40,182.93,0.098
24.42,183.11,0.098
24.44,183.30,0.097
24.46,183.48,0.097
24.48,183.66,0.097
24.49,183.85,0.097
24.51,184.03,0.097
24.53,184.21,0.097
24.55,184.40,0.097
24.57,184.58,0.097
24.58,184.76,0.097
24.60,184.95,0.097
24.62,185.13,0.097
24.64,185.32,0.097
24.66,185.50,0.097
24.68,185.68,0.097
24.69,185.87,0.097
24.71,186.05,0.097
24.73,186.23,0.097
24.75,186.42,0.097
24.77,186.60,0.097
24.79,186.78,0.097
24.81,186.97,0.097
24.82,187.15,0.097
24.84,187.33,0.097
24.86,187.52,0.097
24.88,187.70,0.097
24.90,187.88,0.097
24.92,188.07,0.097
24.93,188.25,0.097
24.95,188.43,0.097
24.97,188.62,0.096
24.99,188.80,0.096
25.01,188.99,0.096
25.03,189.17,0.096
25.04,189.35,0.096
25.06,189.54,0.096
25.08,189.72,0.096
25.10,189.90,0.096
25.12,190.09,0.096
25.13,190.27,0.096
25.15,190.45,0.096
25.17,190.64,0.096
25.19,190.82,0.096
25.21,191.01,0.096
25.23,191.19,0.096
25.24,191.37,0.096
25.26,191.56,0.096
25.28,191.74,0.096
25.30,191.92,0.096
25.32,192.11,0.096
25.34,192.29,0.096
25.36,192.47,0.096
25.37,192.66,0.096
25.39,192.84,0.096
25.41,193.03,0.096
25.43,193.21,0.096
25.45,193.39,0.096
25.47,193.57,0.096
25.48,193.76,0.096
25.50,193.94,0.096
25.52,194.12,0.096
25.54,194.31,0.096
25.56,194.49,0.096
25.58,194.67,0.096
25.59,194.86,0.096
25.61,195.04,0.096
25.63,195.22,0.096
25.65,195.41,0.096
25.67,195.59,0.096
25.68,195.78,0.096
25.70,195.96,0.095
25.72,196.14,0.095
25.74,196.33,0.095
25.76,196.51,0.095
25.78,196.69,0.095
25.79,196.88,0.095
25.81,197.06,0.095
25.83,197.25,0.095
25.85,197.43,0.095
25.87,197.61,0.095
25.89,197.80,0.095
25.91,197.98,0.095
25.92,198.16,0.095
25.94,198.35,
25.96,198.53,
25.98,198.71,
25.99,,

[step]
Ramp 10.00 °C/min to -60.00 °C
Time,Temperature,Heat Flow (Normalized)
min,°C,W/g
27.99,200.15,0.003
28.01,200.15,0.003
28.03,200.14,0.003
28.05,200.13,0.003
28.07,200.11,0.002
28.08,200.06,-0.003
28.10,199.99,-0.010
28.12,199.89,-0.020
28.14,199.77,-0.031
28.16,199.64,-0.042
28.18,199.49,-0.051
28.19,199.34,-0.059
28.21,199.18,-0.065
28.23,199.01,-0.069
28.25,198.84,-0.072
28.27,198.67,-0.075
28.29,198.50,-0.077
28.31,198.32,-0.078
28.32,198.15,-0.079
28.34,197.97,-0.080
28.36,197.79,-0.081
28.38,197.61,-0.082
28.40,197.43,-0.083
28.42,197.25,-0.083
28.43,197.07,-0.083
28.45,196.89,-0.084
28.47,196.71,-0.084
28.49,196.53,-0.084
28.51,196.35,-0.084
28.53,196.16,-0.085
28.54,195.98,-0.085
28.56,195.80,-0.085
28.58,195.62,-0.085
28.60,195.44,-0.085
28.62,195.26,-0.085
28.63,195.07,-0.085
28.65,194.89,-0.085
28.67,194.71,-0.085
28.69,194.53,-0.085
28.71,194.35,-0.085
28.73,194.16,-0.086
28.74,193.98,-0.086
28.76,193.80,-0.086
28.78,193.62,-0.086
28.80,193.43,-0.086
28.82,193.25,-0.086
28.84,193.07,-0.086
28.86,192.89,-0.086
28.87,192.70,-0.086
28.89,192.52,-0.086
28.91,192.34,-0.086
28.93,192.16,-0.086
28.95,191.98,-0.086
28.97,191.79,-0.086
28.98,191.61,-0.086
29.00,191.43,-0.086
29.02,191.25,-0.086
29.04,191.06,-0.086
29.06,190.88,-0.087
29.08,190.70,-0.087
29.09,190.51,-0.087
29.11,190.33,-0.087
29.13,190.15,-0.087
29.15,189.97,-0.087
29.17,189.78,-0.087
29.18,189.60,-0.087
29.20,189.42,-0.087
29.22,189.23,-0.087
29.24,189.05,-0.087
29.26,188.87,-0.087
29.28,188.69,-0.087
29.29,188.50,-0.087
29.31,188.32,-0.087
29.33,188.14,-0.087
29.35,187.96,-0.087
29.37,187.77,-0.087
29.39,187.59,-0.087
29.41,187.41,-0.087
29.42,187.22,-0.087
29.44,187.04,-0.087
29.46,186.86,-0.087
29.48,186.67,-0.087
29.50,186.49,-0.087
29.52,186.31,-0.087
29.53,186.13,-0.087
29.55,185.94,-0.087
29.57,185.76,-0.087
29.59,185.58,-0.087
29.61,185.39,-0.087
29.63,185.21,-0.087
29.64,185.03,-0.087
29.66,184.84,-0.087
29.68,184.66,-0.087
29.70,184.48,-0.087
29.72,184.29,-0.087
29.73,184.11,-0.087
29.75,183.93,-0.087
29.77,183.75,-0.087
29.79,183.56,-0.087
29.81,183.38,-0.087
29.83,183.20,-0.087
29.84,183.01,-0.087
29.86,182.83,-0.087
29.88,182.65,-0.087
29.90,182.46,-0.087
29.92,182.28,-0.087
29.94,182.10,-0.087
29.96,181.91,-0.087
29.97,181.73,-0.087
29.99,181.55,-0.087
30.01,181.36,-0.087
30.03,181.18,-0.087
30.05,181.00,-0.087
30.07,180.81,-0.087
30.08,180.63,-0.087
30.10,180.45,-0.087
30.12,180.26,-0.087
30.14,180.08,-0.087
30.16,179.90,-0.087
30.18,179.72,-0.087
30.19,179.53,-0.087
30.21,179.35,-0.087
30.23,179.17,-0.087
30.25,178.98,-0.087
30.27,178.80,-0.087
30.28,178.62,-0.087
30.30,178.43,-0.087
30.32,178.25,-0.087
30.34,178.07,-0.087
30.36,177.88,-0.087
30.38,177.70,-0.087
30.39,177.52,-0.087
30.41,177.33,-0.087
30.43,177.15,-0.087
30.45,176.97,-0.087
30.47,176.78,-0.087
30.49,176.60,-0.087
30.51,176.42,-0.087
30.52,176.23,-0.087
30.54,176.05,-0.087
30.56,175.87,-0.087
30.58,175.68,-0.087
30.60,175.50,-0.087
30.62,175.32,-0.087
30.63,175.13,-0.087
30.65,174.95,-0.087
30.67,174.77,-0.087
30.69,174.58,-0.087
30.71,174.40,-0.087
30.73,174.22,-0.087
30.74,174.03,-0.087
30.76,173.85,-0.087
30.78,173.67,-0.087
30.80,173.48,-0.087
30.82,173.30,-0.087
30.83,173.12,-0.087
30.85,172.93,-0.087
30.87,172.75,-0.087
30.89,172.57,-0.087
30.91,172.38,-0.087
30.93,172.20,-0.087
30.94,172.02,-0.087
30.96,171.83,-0.087
30.98,171.65,-0.087
31.00,171.47,-0.087
31.02,171.28,-0.087
31.04,171.10,-0.087
31.06,170.92,-0.087
31.07,170.74,-0.087
31.09,170.55,-0.087
31.11,170.37,-0.087
31.13,170.19,-0.087
31.15,170.00,-0.087
31.17,169.82,-0.087
31.18,169.64,-0.087
31.20,169.45,-0.087
31.22,169.27,-0.087
31.24,169.09,-0.087
31.26,168.90,-0.087
31.28,168.72,-0.087
31.29,168.54,-0.087
31.31,168.35,-0.087
31.33,168.17,-0.087
31.35,167.99,-0.087
31.37,167.80,-0.087
31.38,167.62,-0.087
31.40,167.44,-0.087
31.42,167.25,-0.087
31.44,167.07,-0.087
31.46,166.89,-0.087
31.48,166.70,-0.087
31.49,166.52,-0.087
31.51,166.34,-0.087
31.53,166.15,-0.087
31.55,165.97,-0.087
31.57,165.79,-0.087
31.59,165.60,-0.087
31.61,165.42,-0.087
31.62,165.24,-0.087
31.64,165.06,-0.087
31.66,164.87,-0.087
31.68,164.69,-0.087
31.70,164.51,-0.087
31.72,164.32,-0.087
31.73,164.14,-0.087
31.75,163.95,-0.087
31.77,163.77,-0.087
31.79,163.59,-0.087
31.81,163.40,-0.087
31.83,163.22,-0.087
31.84,163.04,-0.087
31.86,162.86,-0.087
31.88,162.67,-0.087
31.90,162.49,-0.087
31.92,162.31,-0.087
31.93,162.12,-0.087
31.95,161.94,-0.087
31.97,161.76,-0.087
31.99,161.57,-0.087
32.01,161.39,-0.087
32.03,161.21,-0.087
32.04,161.02,-0.087
32.06,160.84,-0.087
32.08,160.66,-0.087
32.10,160.47,-0.087
32.12,160.29,-0.087
32.14,160.11,-0.087
32.16,159.92,-0.087
32.17,159.74,-0.087
32.19,159.56,-0.087
32.21,159.37,-0.087
32.23,159.19,-0.087
32.25,159.01,-0.087
32.27,158.82,-0.087
32.28,158.64,-0.087
32.30,158.46,-0.087
32.32,158.27,-0.087
32.34,158.09,-0.087
32.36,157.91,-0.087
32.38,157.72,-0.086
32.39,157.54,-0.086
32.41,157.36,-0.086
32.43,157.17,-0.086
32.45,156.99,-0.086
32.47,156.81,-0.086
32.48,156.62,-0.086
32.50,156.44,-0.086
32.52,156.26,-0.086
32.54,156.07,-0.086
32.56,155.89,-0.086
32.58,155.71,-0.086
32.59,155.52,-0.086
32.61,155.34,-0.086
32.63,155.16,-0.086
32.65,154.97,-0.086
32.67,154.79,-0.086
32.69,154.61,-0.086
32.71,154.42,-0.086
32.72,154.24,-0.086
32.74,154.06,-0.086
32.76,153.87,-0.086
32.78,153.69,-0.086
32.80,153.51,-0.086
32.82,153.33,-0.086
32.83,153.14,-0.086
32.85,152.96,-0.086
32.87,152.78,-0.086
32.89,152.59,-0.086
32.91,152.41,-0.086
32.93,152.23,-0.086
32.94,152.04,-0.086
32.96,151.86,-0.086
32.98,151.68,-0.086
33.00,151.49,-0.086
33.02,151.31,-0.086
33.03,151.13,-0.086
33.05,150.94,-0.086
33.07,150.76,-0.086
33.09,150.58,-0.086
33.11,150.39,-0.086
33.13,150.21,-0.086
33.14,150.03,-0.086
33.16,149.84,-0.086
33.18,149.66,-0.086
33.20,149.48,-0.086
33.22,149.29,-0.086
33.24,149.11,-0.086
33.26,148.93,-0.086
33.27,148.74,-0.086
33.29,148.56,-0.086
33.31,148.38,-0.086
33.33,148.19,-0.086
33.35,148.01,-0.086
33.37,147.83,-0.086
33.38,147.64,-0.086
33.40,147.46,-0.086
33.42,147.28,-0.086
33.44,147.09,-0.086
33.46,146.91,-0.086
33.48,146.73,-0.086
33.49,146.54,-0.086
33.51,146.36,-0.086
33.53,146.18,-0.086
33.55,145.99,-0.086
33.57,145.81,-0.086
33.58,145.63,-0.086
33.60,145.44,-0.086
33.62,145.26,-0.086
33.64,145.08,-0.086
33.66,144.89,-0.086
33.68,144.71,-0.086
33.69,144.53,-0.086
33.71,144.35,-0.086
33.73,144.16,-0.085
33.75,143.98,-0.085
33.77,143.80,-0.085
33.79,143.61,-0.085
33.81,143.43,-0.085
33.82,143.25,-0.085
33.84,143.06,-0.085
33.86,142.88,-0.085
33.88,142.69,-0.085
33.90,142.51,-0.085
33.92,142.33,-0.085
33.93,142.14,-0.085
33.95,141.96,-0.085
33.97,141.78,-0.085
33.99,141.60,-0.085
34.01,141.41,-0.085
34.03,141.23,-0.085
34.04,141.05,-0.085
34.06,140.86,-0.085
34.08,140.68,-0.085
34.10,140.50,-0.085
34.12,140.31,-0.085
34.14,140.13,-0.085
34.15,139.95,-0.085
34.17,139.76,-0.085
34.19,139.58,-0.085
34.21,139.40,-0.085
34.23,139.21,-0.085
34.24,139.03,-0.085
34.26,138.85,-0.085
34.28,138.66,-0.085
34.30,138.48,-0.085
34.32,138.30,-0.085
34.34,138.11,-0.085
34.36,137.93,-0.085
34.37,137.75,-0.085
34.39,137.56,-0.085
34.41,137.38,-0.085
34.43,137.20,-0.085
34.45,137.01,-0.085
34.46,136.83,-0.085
34.48,136.65,-0.085
34.50,136.46,-0.085
34.52,136.28,-0.085
34.54,136.10,-0.085
34.56,135.91,-0.085
34.58,135.73,-0.085
34.59,135.55,-0.085
34.61,135.36,-0.085
34.63,135.18,-0.085
34.65,135.00,-0.085
34.67,134.81,-0.085
34.69,134.63,-0.085
34.70,134.45,-0.085
34.72,134.26,-0.085
34.74,134.08,-0.085
34.76,133.90,-0.085
34.78,133.71,-0.085
34.79,133.53,-0.085
34.81,133.35,-0.085
34.83,133.16,-0.085
34.85,132.98,-0.085
34.87,132.80,-0.085
34.89,132.61,-0.085
34.91,132.43,-0.084
34.92,132.25,-0.084
34.94,132.06,-0.084
34.96,131.88,-0.084
34.98,131.70,-0.084
35.00,131.51,-0.084
35.01,131.33,-0.084
35.03,131.15,-0.084
35.05,130.96,-0.084
35.07,130.78,-0.084
35.09,130.60,-0.084
35.11,130.42,-0.084
35.13,130.23,-0.084
35.14,130.05,-0.084
35.16,129.87,-0.084
35.18,129.68,-0.084
35.20,129.50,-0.084
35.22,129.32,-0.084
35.24,129.13,-0.084
35.25,128.95,-0.084
35.27,128.77,-0.084
35.29,128.58,-0.084
[...]
119.22,10.91,0.048
119.24,11.10,0.048
119.25,11.28,0.048
119.27,11.46,0.048
119.29,11.65,0.048
119.31,11.83,0.048
119.33,12.01,0.048
119.35,12.20,0.048
119.36,12.38,0.048
119.38,12.56,0.048
119.40,12.75,0.048
119.42,12.93,0.048
119.44,13.11,0.048
119.46,13.30,0.048
119.48,13.48,0.048
119.49,13.66,0.048
119.51,13.85,0.048
119.53,14.03,0.048
119.55,14.21,0.048
119.57,14.40,0.048
119.59,14.58,0.048
119.60,14.77,0.048
119.62,14.95,0.048
119.64,15.13,0.048
119.66,15.32,0.048
119.68,15.50,0.048
119.70,15.68,0.048
119.71,15.87,0.048
119.73,16.05,0.048
119.75,16.23,0.048
119.77,16.42,0.048
119.79,16.60,0.048
119.80,16.78,0.048
119.82,16.97,0.048
119.84,17.15,0.048
119.86,17.33,0.048
119.88,17.52,0.048
119.90,17.70,0.049
119.91,17.88,0.049
119.93,18.07,0.049
119.95,18.25,0.049
119.97,18.43,0.049
119.99,18.62,0.049
120.01,18.80,0.049
120.03,18.98,0.049
120.04,19.17,0.049
120.06,19.35,0.049
120.08,19.53,0.049
120.10,19.72,0.049
120.12,19.90,0.049
120.14,20.08,0.049
120.15,20.27,0.049
120.17,20.45,0.049
120.19,20.63,0.049
120.21,20.82,0.049
120.23,21.00,0.049
120.25,21.19,0.049
120.26,21.37,0.049
120.28,21.55,0.049
120.30,21.74,0.049
120.32,21.92,0.049
120.34,22.10,0.049
120.35,22.29,0.049
120.37,22.47,0.049
120.39,22.65,0.049
120.41,22.84,0.049
120.43,23.02,0.049
120.45,23.20,0.049
120.46,23.39,0.049
120.48,23.57,0.050
120.50,23.75,0.050
120.52,23.94,0.050
120.54,24.12,0.050
120.56,24.30,0.050
120.58,24.49,0.050
120.59,24.67,0.050
120.61,24.85,0.050
120.63,25.04,0.050
120.65,25.22,0.050
120.67,25.41,0.050
120.69,25.59,0.050
120.70,25.77,0.050
120.72,25.96,0.050
120.74,26.14,0.050
120.76,26.32,0.050
120.78,26.51,0.050
120.80,26.69,0.050
120.81,26.87,0.050
120.83,27.06,0.050
120.85,27.24,0.050
120.87,27.43,0.050
120.89,27.61,0.050
120.90,27.79,0.050
120.92,27.98,0.050
120.94,28.16,0.050
120.96,28.34,0.050
120.98,28.53,0.050
121.00,28.71,0.050
121.01,28.89,0.050
121.03,29.08,0.050
121.05,29.26,0.051
121.07,29.44,0.051
121.09,29.63,0.051
121.11,29.81,0.051
121.13,29.99,0.051
121.14,30.18,0.051
121.16,30.36,0.051
121.18,30.54,0.051
121.20,30.73,0.051
121.22,30.91,0.051
121.24,31.10,0.051
121.25,31.28,0.051
121.27,31.46,0.051
121.29,31.65,0.051
121.31,31.83,0.051
121.33,32.01,0.051
121.35,32.20,0.051
121.36,32.38,0.051
121.38,32.56,0.051
121.40,32.75,0.051
121.42,32.93,0.051
121.44,33.12,0.051
121.45,33.30,0.051
121.47,33.48,0.051
121.49,33.67,0.051
121.51,33.85,0.051
121.53,34.03,0.051
121.55,34.21,0.051
121.56,34.40,0.051
121.58,34.58,0.051
121.60,34.77,0.051
121.62,34.95,0.051
121.64,35.13,0.051
121.66,35.32,0.052
121.68,35.50,0.052
121.69,35.68,0.052
121.71,35.87,0.052
121.73,36.05,0.052
121.75,36.23,0.052
121.77,36.42,0.052
121.79,36.60,0.052
121.80,36.78,0.052
121.82,36.97,0.052
121.84,37.15,0.052
121.86,37.33,0.052
121.88,37.52,0.052
121.90,37.70,0.052
121.91,37.89,0.052
121.93,38.07,0.052
121.95,38.25,0.052
121.97,38.44,0.052
121.99,38.62,0.052
122.00,38.80,0.052
122.02,38.99,0.052
122.04,39.17,0.052
122.06,39.35,0.052
122.08,39.54,0.052
122.10,39.72,0.052
122.11,39.90,0.052
122.13,40.09,0.052
122.15,40.27,0.052
122.17,40.45,0.052
122.19,40.64,0.052
122.21,40.82,0.052
122.23,41.00,0.052
122.24,41.19,0.052
122.26,41.37,0.053
122.28,41.55,0.053
122.30,41.74,0.053
122.32,41.92,0.053
122.34,42.11,0.053
122.35,42.29,0.053
122.37,42.47,0.053
122.39,42.66,0.053
122.41,42.84,0.053
122.43,43.02,0.053
122.45,43.21,0.053
122.46,43.39,0.053
122.48,43.57,0.053
122.50,43.76,0.053
122.52,43.94,0.053
122.54,44.12,0.053
122.55,44.31,0.053
122.57,44.49,0.053
122.59,44.67,0.053
122.61,44.86,0.053
122.63,45.04,0.053
122.65,45.22,0.053
122.66,45.41,0.053
122.68,45.59,0.053
122.70,45.77,0.053
122.72,45.96,0.053
122.74,46.14,0.053
122.76,46.32,0.053
122.78,46.51,0.053
122.79,46.69,0.053
122.81,46.88,0.053
122.83,47.06,0.054
122.85,47.24,0.054
122.87,47.43,0.054
122.89,47.61,0.054
122.90,47.79,0.054
122.92,47.98,0.054
122.94,48.16,0.054
122.96,48.34,0.054
122.98,48.53,0.054
123.00,48.71,0.054
123.01,48.89,0.054
123.03,49.08,0.054
123.05,49.26,0.054
123.07,49.45,0.054
123.09,49.63,0.054
123.10,49.81,0.054
123.12,50.00,0.054
123.14,50.18,0.054
123.16,50.36,0.054
123.18,50.55,0.054
123.20,50.73,0.054
123.21,50.91,0.054
123.23,51.10,0.054
123.25,51.28,0.054
123.27,51.46,0.054
123.29,51.65,0.054
123.31,51.83,0.054
123.33,52.01,0.054
123.34,52.20,0.054
123.36,52.38,0.054
123.38,52.56,0.055
123.40,52.75,0.055
123.42,52.93,0.055
123.44,53.12,0.055
123.45,53.30,0.055
123.47,53.48,0.055
123.49,53.67,0.055
123.51,53.85,0.055
123.53,54.03,0.055
123.55,54.22,0.055
123.56,54.40,0.055
123.58,54.58,0.055
123.60,54.77,0.055
123.62,54.95,0.055
123.64,55.13,0.055
123.65,55.32,0.055
123.67,55.50,0.055
123.69,55.68,0.055
123.71,55.87,0.055
123.73,56.05,0.055
123.75,56.23,0.055
123.76,56.42,0.055
123.78,56.60,0.055
123.80,56.78,0.055
123.82,56.97,0.055
123.84,57.15,0.055
123.86,57.34,0.055
123.88,57.52,0.055
123.89,57.70,0.055
123.91,57.89,0.055
123.93,58.07,0.055
123.95,58.25,0.055
123.97,58.44,0.056
123.99,58.62,0.056
124.00,58.80,0.056
124.02,58.99,0.056
124.04,59.17,0.056
124.06,59.35,0.056
124.08,59.54,0.056
124.10,59.72,0.056
124.11,59.90,0.056
124.13,60.09,0.056
124.15,60.27,0.056
124.17,60.45,0.056
124.19,60.64,0.056
124.20,60.82,0.056
124.22,61.00,0.056
124.24,61.19,0.056
124.26,61.37,0.056
124.28,61.56,0.056
124.30,61.74,0.056
124.31,61.92,0.056
124.33,62.11,0.056
124.35,62.29,0.056
124.37,62.47,0.056
124.39,62.66,0.056
124.41,62.84,0.056
124.43,63.02,0.056
124.44,63.21,0.056
124.46,63.39,0.056
124.48,63.57,0.056
124.50,63.76,0.057
124.52,63.94,0.057
124.54,64.12,0.057
124.55,64.31,0.057
124.57,64.49,0.057
124.59,64.67,0.057
124.61,64.86,0.057
124.63,65.04,0.057
124.65,65.23,0.057
124.66,65.41,0.057
124.68,65.59,0.057
124.70,65.77,0.057
124.72,65.96,0.057
124.74,66.14,0.057
124.75,66.33,0.057
124.77,66.51,0.057
124.79,66.69,0.057
124.81,66.88,0.057
124.83,67.06,0.057
124.85,67.24,0.057
124.86,67.43,0.057
124.88,67.61,0.057
124.90,67.79,0.057
124.92,67.98,0.057
124.94,68.16,0.057
124.96,68.34,0.057
124.98,68.53,0.057
124.99,68.71,0.057
125.01,68.89,0.057
125.03,69.08,0.058
125.05,69.26,0.058
125.07,69.44,0.058
125.09,69.63,0.058
125.10,69.81,0.058
125.12,69.99,0.058
125.14,70.18,0.058
125.16,70.36,0.058
125.18,70.55,0.058
125.20,70.73,0.058
125.21,70.91,0.058
125.23,71.10,0.058
125.25,71.28,0.058
125.27,71.46,0.058
125.29,71.65,0.058
125.30,71.83,0.058
125.32,72.01,0.058
125.34,72.20,0.058
125.36,72.38,0.058
125.38,72.56,0.058
125.40,72.75,0.058
125.41,72.93,0.058
125.43,73.11,0.058
125.45,73.30,0.058
125.47,73.48,0.058
125.49,73.66,0.058
125.51,73.85,0.059
125.53,74.03,0.059
125.54,74.21,0.059
125.56,74.40,0.059
125.58,74.58,0.059
125.60,74.76,0.059
125.62,74.95,0.059
125.64,75.13,0.059
125.65,75.32,0.059
125.67,75.50,0.059
125.69,75.68,0.059
125.71,75.86,0.059
125.73,76.05,0.059
125.75,76.23,0.059
125.76,76.41,0.059
125.78,76.60,0.059
125.80,76.78,0.059
125.82,76.97,0.059
125.84,77.15,0.059
125.85,77.33,0.059
125.87,77.51,0.059
125.89,77.70,0.059
125.91,77.88,0.059
125.93,78.07,0.060
125.95,78.25,0.060
125.96,78.43,0.060
125.98,78.61,0.060
126.00,78.80,0.060
126.02,78.98,0.060
126.04,79.17,0.060
126.06,79.35,0.060
126.08,79.53,0.060
126.09,79.72,0.060
126.11,79.90,0.060
126.13,80.08,0.060
126.15,80.27,0.060
126.17,80.45,0.060
126.19,80.63,0.060
126.20,80.82,0.060
126.22,81.00,0.060
126.24,81.18,0.060
126.26,81.37,0.060
126.28,81.55,0.060
126.30,81.73,0.060
126.31,81.92,0.060
126.33,82.10,0.061
126.35,82.28,0.061
126.37,82.47,0.061
126.39,82.65,0.061
126.40,82.83,0.061
126.42,83.02,0.061
126.44,83.20,0.061
126.46,83.39,0.061
126.48,83.57,0.061
126.50,83.75,0.061
126.51,83.94,0.061
126.53,84.12,0.061
126.55,84.30,0.061
126.57,84.49,0.061
126.59,84.67,0.061
126.61,84.85,0.061
126.63,85.04,0.061
126.64,85.22,0.061
126.66,85.40,0.061
126.68,85.59,0.061
126.70,85.77,0.062
126.72,85.95,0.062
126.74,86.14,0.062
126.75,86.32,0.062
126.77,86.50,0.062
126.79,86.69,0.062
126.81,86.87,0.062
126.83,87.05,0.062
126.85,87.24,0.062
126.86,87.42,0.062
126.88,87.60,0.062
126.90,87.79,0.062
126.92,87.97,0.062
126.94,88.15,0.062
126.95,88.34,0.062
126.97,88.52,0.062
126.99,88.70,0.063
127.01,88.89,0.063
127.03,89.07,0.063
127.05,89.25,0.063
127.06,89.44,0.063
127.08,89.62,0.063
127.10,89.80,0.063
127.12,89.99,0.063
127.14,90.17,0.063
127.16,90.35,0.063
127.18,90.54,0.063
127.19,90.72,0.063
127.21,90.90,0.063
127.23,91.09,0.064
127.25,91.27,0.064
127.27,91.45,0.064
127.29,91.64,0.064
127.30,91.82,0.064
127.32,92.00,0.064
127.34,92.19,0.064
127.36,92.37,0.064
127.38,92.55,0.064
127.40,92.74,0.064
127.41,92.92,0.064
127.43,93.10,0.065
127.45,93.29,0.065
127.47,93.47,0.065
127.49,93.65,0.065
127.50,93.84,0.065
127.52,94.02,0.065
127.54,94.20,0.065
127.56,94.39,0.065
127.58,94.57,0.065
127.60,94.75,0.065
127.61,94.94,0.066
127.63,95.12,0.066
127.65,95.30,0.066
127.67,95.49,0.066
127.69,95.67,0.066
127.71,95.85,0.066
127.73,96.04,0.066
127.74,96.22,0.066
127.76,96.40,0.067
127.78,96.59,0.067
127.80,96.77,0.067
127.82,96.95,0.067
127.84,97.14,0.067
127.85,97.32,0.067
127.87,97.50,0.067
127.89,97.69,0.068
127.91,97.87,0.068
127.93,98.05,0.068
127.95,98.24,0.068
127.96,98.42,0.068
127.98,98.60,0.068
128.00,98.79,0.068
128.02,98.97,0.069
128.04,99.15,0.069
128.05,99.34,0.069
128.07,99.52,0.069
128.09,99.70,0.069
128.11,99.88,0.069
128.13,100.07,0.069
128.15,100.25,0.070
128.16,100.43,0.070
128.18,100.62,0.070
128.20,100.80,0.070
128.22,100.98,0.070
128.24,101.17,0.070
128.26,101.35,0.070
128.28,101.53,0.071
128.29,101.72,0.071
128.31,101.90,0.071
128.33,102.08,0.071
128.35,102.27,0.071
128.37,102.45,0.071
128.39,102.63,0.071
128.40,102.81,0.071
128.42,103.00,0.072
128.44,103.18,0.072
128.46,103.36,0.072
128.48,103.55,0.072
128.50,103.73,0.072
128.51,103.91,0.072
128.53,104.10,0.072
128.55,104.28,0.072
128.57,104.46,0.073
128.59,104.65,0.073
128.60,104.83,0.073
128.62,105.01,0.073
128.64,105.20,0.073
128.66,105.38,0.073
128.68,105.57,0.073
128.70,105.75,0.073
128.71,105.93,0.074
128.73,106.12,0.074
128.75,106.30,0.074
128.77,106.48,0.074
128.79,106.67,0.074
128.81,106.85,0.074
128.83,107.03,0.074
128.84,107.22,0.074
128.86,107.40,0.074
128.88,107.58,0.074
128.90,107.77,0.075
128.92,107.95,0.075
128.94,108.13,0.075
128.95,108.31,0.075
128.97,108.50,0.075
128.99,108.68,0.075
129.01,108.86,0.075
129.03,109.05,0.075
129.05,109.23,0.075
129.06,109.42,0.075
129.08,109.60,0.075
129.10,109.78,0.075
129.12,109.97,0.076
129.14,110.15,0.076
129.15,110.33,0.076
129.17,110.51,0.076
129.19,110.70,0.076
129.21,110.88,0.076
129.23,111.07,0.076
129.25,111.25,0.076
129.26,111.43,0.076
129.28,111.62,0.076
129.30,111.80,0.076
129.32,111.98,0.076
129.34,112.17,0.076
129.36,112.35,0.076
129.38,112.53,0.076
129.39,112.72,0.076
129.41,112.90,0.076
129.43,113.08,0.077
129.45,113.27,0.077
129.47,113.45,0.077
129.49,113.63,0.077
129.50,113.82,0.077
129.52,114.00,0.077
129.54,114.18,0.077
129.56,114.37,0.077
129.58,114.55,0.077
129.60,114.73,0.077
129.61,114.92,0.077
129.63,115.10,0.077
129.65,115.28,0.077
129.67,115.47,0.077
129.69,115.65,0.077
129.70,115.83,0.077
129.72,116.02,0.077
129.74,116.20,0.077
129.76,116.39,0.077
129.78,116.57,0.077
129.80,116.75,0.077
129.81,116.94,0.077
129.83,117.12,0.077
129.85,117.30,0.077
129.87,117.49,0.077
129.89,117.67,0.077
129.91,117.85,0.077
129.93,118.04,0.077
129.94,118.22,0.077
129.96,118.40,0.077
129.98,118.59,0.077
130.00,118.77,0.077
130.02,118.96,0.078
130.04,119.14,0.078
130.05,119.32,0.078
130.07,119.51,0.078
130.09,119.69,0.078
130.11,119.87,0.078
130.13,120.06,0.078
130.15,120.24,0.078
130.16,120.42,0.078
130.18,120.61,0.078
130.20,120.79,0.078
130.22,120.97,0.078
130.24,121.16,0.078
130.25,121.34,0.078
130.27,121.52,0.078
130.29,121.71,0.078
130.31,121.89,0.078
130.33,122.07,0.078
130.35,122.26,0.078
130.36,122.44,0.078
130.38,122.63,0.078
130.40,122.81,0.078
130.42,122.99,0.078
130.44,123.17,0.078
130.46,123.36,0.078
130.48,123.54,0.078
130.49,123.73,0.078
130.51,123.91,0.078
130.53,124.09,0.078
130.55,124.27,0.078
130.57,124.46,0.078
130.59,124.64,0.078
130.60,124.83,0.078
130.62,125.01,0.078
130.64,125.19,0.078
130.66,125.38,0.078
130.68,125.56,0.078
130.70,125.74,0.078
130.71,125.93,0.078
130.73,126.11,0.078
130.75,126.29,0.078
130.77,126.48,0.078
130.79,126.66,0.079
130.80,126.84,0.079
130.82,127.03,0.079
130.84,127.21,0.079
130.86,127.39,0.079
130.88,127.58,0.079
130.90,127.76,0.079
130.91,127.95,0.079
130.93,128.13,0.079
130.95,128.31,0.079
130.97,128.50,0.079
130.99,128.68,0.079
131.01,128.86,0.079
131.03,129.05,0.079
131.04,129.23,0.079
131.06,129.41,0.079
131.08,129.60,0.079
131.10,129.78,0.079
131.12,129.97,0.079
131.14,130.15,0.079
131.15,130.33,0.079
131.17,130.52,0.079
131.19,130.70,0.079
131.21,130.88,0.079
131.23,131.07,0.079
131.25,131.25,0.079
131.26,131.43,0.079
131.28,131.62,0.079
131.30,131.80,0.079
131.32,131.98,0.079
131.34,132.17,0.079
131.35,132.35,0.079
131.37,132.54,0.079
131.39,132.72,0.079
131.41,132.90,0.079
131.43,133.09,0.079
131.45,133.27,0.079
131.46,133.45,0.080
131.48,133.64,0.080
131.50,133.82,0.080
131.52,134.00,0.080
131.54,134.19,0.080
131.56,134.37,0.080
131.58,134.55,0.080
131.59,134.74,0.080
131.61,134.92,0.080
131.63,135.10,0.080
131.65,135.29,0.080
131.67,135.47,0.080
131.69,135.65,0.080
131.70,135.84,0.080
131.72,136.02,0.080
131.74,136.20,0.080
131.76,136.39,0.080
131.78,136.57,0.080
131.80,136.75,0.080
131.81,136.94,0.080
131.83,137.12,0.080
131.85,137.31,0.080
131.87,137.49,0.080
131.89,137.67,0.080
131.90,137.86,0.080
131.92,138.04,0.080
131.94,138.22,0.080
131.96,138.40,0.080
131.98,138.59,0.080
132.00,138.77,0.080
132.01,138.95,0.080
132.03,139.14,0.080
132.05,139.32,0.080
132.07,139.51,0.080
132.09,139.69,0.080
132.11,139.87,0.080
132.13,140.06,0.080
132.14,140.24,0.080
132.16,140.42,0.080
132.18,140.61,0.080
132.20,140.79,0.081
132.22,140.97,0.081
132.24,141.16,0.081
132.25,141.34,0.081
132.27,141.52,0.081
132.29,141.71,0.081
132.31,141.89,0.081
132.33,142.07,0.081
132.35,142.26,0.081
132.36,142.44,0.081
132.38,142.62,0.081
132.40,142.81,0.081
132.42,142.99,0.081
132.44,143.17,0.081
132.45,143.36,0.081
132.47,143.54,0.081
132.49,143.72,0.081
132.51,143.91,0.081
132.53,144.09,0.081
132.55,144.27,0.081
132.56,144.46,0.081
132.58,144.64,0.081
132.60,144.82,0.081
132.62,145.01,0.081
132.64,145.19,0.081
132.66,145.38,0.081
132.68,145.56,0.081
132.69,145.74,0.081
132.71,145.93,0.081
132.73,146.11,0.081
132.75,146.29,0.081
132.77,146.48,0.081
132.79,146.66,0.081
132.80,146.84,0.081
132.82,147.03,0.081
132.84,147.21,0.081
132.86,147.39,0.081
132.88,147.58,0.082
132.90,147.76,0.082
132.91,147.95,0.082
132.93,148.13,0.082
132.95,148.31,0.082
132.97,148.49,0.082
132.99,148.68,0.082
133.00,148.86,0.082
133.02,149.04,0.082
133.04,149.23,0.082
133.06,149.41,0.082
133.08,149.59,0.082
133.10,149.78,0.082
133.11,149.96,0.082
133.13,150.14,0.082
133.15,150.33,0.082
133.17,150.51,0.082
133.19,150.69,0.082
133.21,150.88,0.082
133.23,151.06,0.082
133.24,151.24,0.082
133.26,151.43,0.082
133.28,151.61,0.082
133.30,151.79,0.082
133.32,151.98,0.082
133.34,152.16,0.082
133.35,152.34,0.082
133.37,152.53,0.082
133.39,152.71,0.082
133.41,152.90,0.082
133.43,153.08,0.082
133.45,153.26,0.082
133.46,153.45,0.082
133.48,153.63,0.082
133.50,153.81,0.083
133.52,154.00,0.083
133.54,154.18,0.083
133.55,154.36,0.083
133.57,154.55,0.083
133.59,154.73,0.083
133.61,154.91,0.083
133.63,155.10,0.083
133.65,155.28,0.083
133.66,155.46,0.083
133.68,155.65,0.083
133.70,155.83,0.083
133.72,156.01,0.083
133.74,156.20,0.083
133.76,156.38,0.083
133.78,156.57,0.083
133.79,156.75,0.083
133.81,156.93,0.083
133.83,157.12,0.083
133.85,157.30,0.083
133.87,157.48,0.083
133.89,157.67,0.083
133.90,157.85,0.083
133.92,158.03,0.083
133.94,158.22,0.083
133.96,158.40,0.083
133.98,158.58,0.083
134.00,158.77,0.083
134.01,158.95,0.083
134.03,159.13,0.083
134.05,159.32,0.083
134.07,159.50,0.083
134.09,159.69,0.083
134.10,159.87,0.083
134.12,160.05,0.083
134.14,160.23,0.083
134.16,160.42,0.083
134.18,160.60,0.083
134.20,160.78,0.083
134.21,160.97,0.083
134.23,161.15,0.083
134.25,161.33,0.083
134.27,161.52,0.084
134.29,161.70,0.084
134.31,161.88,0.084
134.33,162.07,0.084
134.34,162.25,0.084
134.36,162.43,0.084
134.38,162.62,0.084
134.40,162.80,0.084
134.42,162.98,0.084
134.44,163.17,0.084
134.45,163.35,0.084
134.47,163.54,0.084
134.49,163.72,0.084
134.51,163.90,0.084
134.53,164.09,0.084
134.55,164.27,0.084
134.56,164.45,0.084
134.58,164.64,0.084
134.60,164.82,0.084
134.62,165.00,0.084
134.64,165.19,0.084
134.65,165.37,0.084
134.67,165.55,0.084
134.69,165.74,0.084
134.71,165.92,0.084
134.73,166.10,0.084
134.75,166.29,0.084
134.76,166.47,0.084
134.78,166.66,0.084
134.80,166.84,0.084
134.82,167.02,0.085
134.84,167.21,0.085
134.86,167.39,0.085
134.88,167.57,0.085
134.89,167.76,0.085
134.91,167.94,0.085
134.93,168.12,0.085
134.95,168.31,0.085
134.97,168.49,0.085
134.99,168.67,0.085
135.00,168.86,0.085
135.02,169.04,0.085
135.04,169.22,0.085
135.06,169.41,0.085
135.08,169.59,0.085
135.10,169.77,0.085
135.11,169.96,0.085
135.13,170.14,0.085
135.15,170.32,0.085
135.17,170.51,0.085
135.19,170.69,0.085
135.20,170.87,0.085
135.22,171.06,0.085
135.24,171.24,0.085
135.26,171.42,0.085
135.28,171.61,0.085
135.30,171.79,0.085
135.31,171.97,0.085
135.33,172.16,0.085
135.35,172.34,0.085
135.37,172.52,0.086
135.39,172.71,0.086
135.41,172.89,0.086
135.43,173.08,0.086
135.44,173.26,0.086
135.46,173.44,0.086
135.48,173.62,0.086
135.50,173.81,0.086
135.52,173.99,0.086
135.54,174.18,0.086
135.55,174.36,0.086
135.57,174.54,0.086
135.59,174.73,0.086
135.61,174.91,0.086
135.63,175.09,0.086
135.65,175.28,0.086
135.66,175.46,0.086
135.68,175.64,0.086
135.70,175.83,0.086
135.72,176.01,0.086
135.74,176.19,0.086
135.75,176.38,0.086
135.77,176.56,0.086
135.79,176.74,0.086
135.81,176.93,0.086
135.83,177.11,0.086
135.85,177.29,0.086
135.86,177.48,0.086
135.88,177.66,0.087
135.90,177.84,0.087
135.92,178.03,0.087
135.94,178.21,0.087
135.96,178.39,0.087
135.98,178.58,0.087
135.99,178.76,0.087
136.01,178.94,0.087
136.03,179.13,0.087
136.05,179.31,0.087
136.07,179.50,0.087
136.09,179.68,0.087
136.10,179.86,0.087
136.12,180.04,0.087
136.14,180.23,0.087
136.16,180.41,0.087
136.18,180.60,0.087
136.20,180.78,0.087
136.21,180.96,0.087
136.23,181.14,0.087
136.25,181.33,0.087
136.27,181.51,0.087
136.29,181.70,0.087
136.30,181.88,0.087
136.32,182.06,0.088
136.34,182.25,0.088
136.36,182.43,0.088
136.38,182.61,0.088
136.40,182.80,0.088
136.41,182.98,0.088
136.43,183.16,0.088
136.45,183.35,0.088
136.47,183.53,0.088
136.49,183.71,0.088
136.51,183.90,0.088
136.53,184.08,0.088
136.54,184.26,0.088
136.56,184.45,0.088
136.58,184.63,0.088
136.60,184.81,0.088
136.62,185.00,0.088
136.63,185.18,0.088
136.65,185.36,0.088
136.67,185.55,0.088
136.69,185.73,0.088
136.71,185.91,0.088
136.73,186.10,0.088
136.75,186.28,0.088
136.76,186.46,0.088
136.78,186.65,0.088
136.80,186.83,0.089
136.82,187.02,0.089
136.84,187.20,0.089
136.85,187.38,0.089
136.87,187.57,0.089
136.89,187.75,0.089
136.91,187.93,0.089
136.93,188.12,0.089
136.95,188.30,0.089
136.97,188.48,0.089
136.98,188.67,0.089
137.00,188.85,0.089
137.02,189.03,0.089
137.04,189.22,0.089
137.06,189.40,0.089
137.08,189.58,0.089
137.09,189.77,0.089
137.11,189.95,0.089
137.13,190.14,0.089
137.15,190.32,0.089
137.17,190.50,0.089
137.18,190.68,0.089
137.20,190.87,0.089
137.22,191.05,0.089
137.24,191.23,0.089
137.26,191.42,0.090
137.28,191.60,0.090
137.30,191.78,0.090
137.31,191.97,0.090
137.33,192.15,0.090
137.35,192.33,0.090
137.37,192.52,0.090
137.39,192.70,0.090
137.40,192.88,0.090
137.42,193.07,0.090
137.44,193.25,0.090
137.46,193.43,0.090
137.48,193.62,0.090
137.50,193.80,0.090
137.52,193.99,0.090
137.53,194.17,0.090
137.55,194.35,0.090
137.57,194.54,0.090
137.59,194.72,0.090
137.61,194.90,0.090
137.63,195.09,0.090
137.64,195.27,0.090
137.66,195.45,0.091
137.68,195.63,0.091
137.70,195.82,0.091
137.72,196.00,0.091
137.73,196.19,0.091
137.75,196.37,0.091
137.77,196.55,0.091
137.79,196.74,0.091
137.81,196.92,0.091
137.83,197.10,0.091
137.85,197.29,0.091
137.86,197.47,0.091
137.88,197.65,0.091
137.90,197.84,0.091
137.92,198.02,0.091
137.94,198.21,
137.95,198.39,
137.97,198.57,
137.99,,
137.99,,