File: DSC/Olivia/2025_07_20_Al_PanLid_TS_Baseline_n60C_300C_10Cmin_x3.csv
Filename,2025_07_20_Al_PanLid_TS_Baseline_n60C_300C_10Cmin_x3
Instrument name,DSC2A-00468 (192.168.1.100)
Operator,Yarger
rundate,7/20/2025
Sample name,2025_07_20_Al_PanLid_TS_Baseline_n60C_300C_10Cmin_x3
proceduresegments,Data Off ; Equilibrate -60.00 °C; Data On ; Ramp 10.00 °C/min to 300.00 °C; Data Off ; Isothermal 2.0 min; Data On ; Ramp 10.00 °C/min to -60.00 °C; Data Off ; Isothermal 2.0 min; Data On ; Ramp 10.00 °C/min to 300.00 °C; Data Off ; Isothermal 2.0 min; Data On ; Ramp 10.00 °C/min to -60.00 °C; Data Off ; Isothermal 2.0 min; Data On ; Ramp 10.00 °C/min to 300.00 °C
[File Parameters]
Run date,7/20/2025 6:21:09 PM
Trios version,5.1.1.46572
Original File Name,
Current File Name,D:\DSC2500\Gibbons\2025_07_20_Al_PanLid_TS_Baseline_n60C_300C_10Cmin_x3.tri
[Procedure]
Procedure Name,DSC_TS_Al_Pans_n60C_300C_10Cmin_x3
Sample Name,2025_07_20_Al_PanLid_TS_Baseline_n60C_300C_10Cmin_x3
Sample Mass,0 mg
Reference Sample Mass,0 mg
Pan Mass,32.69 mg
Pan Number,38
Reference Pan Mass,32.52 mg
Reference Pan Number,37
Pan Type,Aluminum
Comments,Baseline with two empty thermal support Al pans/lids. DSC_Samples_A2_Tray_July2025 google sheet.
Project Name,Pharma - Cocrystals
Operator,Yarger
Test,Custom
Unload Max Temperature,30
Unload Min Temperature,30
Load Max Temperature,30
Load Min Temperature,30
Stop on Gas Flow Error,Yes
[Signal List]
Signal #1,Time (min)
Signal #2,Temperature (°C)
Signal #3,Heat Flow (mW)
Signal #4,Delta T (µV)
Signal #5,Delta Tzero (µV)
Signal #6,Tzero Temperature (°C)
Signal #7,Cell Purge (mL/min)
Signal #8,Heater Temp (°C)
Signal #9,Power Delivered (W)
Signal #10,Reference Junction Temperature (°C)
Signal #11,Flange Temperature (°C)
Signal #12,Heat Flow Phase (rad)
Signal #13,Total Heat Capacity (J/°C)
Signal #14,Heat Capacity (J/°C)
[Configuration]
Company Name,ASU
Instrument Name,DSC2A-00468
Instrument Type,DSC2500
Serial Number,DSC2A-00468
IP,192.168.1.100
Location of Instrument,MRRC
DisplayType,Unknown
Sample Interval ,0.1 s/pt
Selected Heat Flow,T4P
Exotherm Direction,Down
Cell Serial,DRC2-00792
Lid Type,Standard
Cooler,RCS 90
Leave Cooler on at End of Sequence,On
Gas 2,Nitrogen
Gas Selected,Channel 1
Flow Rate,50 mL/min
Secondary Purge,On
Licensed Heat Flow,Heat Flow T4P
Modulation Licensed,Yes
[Versions]
Common IDD Version,1
Cortex Version,VER 2.10.2.31
Driver,5.0.0.6
GDM Version,1.0.3.3
TouchscreenVersion,1.0.0.16145
FEP Version,1.2.1.21
FEP Bootloader,2.0.0.5
AutoSampler Version,2.1.1.26
Auto Sampler Bootloader,2.0.0.5
FCM Version,1.1.0.3
FCM Bootloader,2.0.0.5
[Experiment Logs]
Experiment Log Entry # 1,Air Cool is off.
Experiment Log Entry # 3,Data On set to 0
Experiment Log Entry # 5,Equilibrate Segment -60 (C) Started
Experiment Log Entry # 7,Data On set to 1
Experiment Log Entry # 9,Ramp Segment 10 C/min to 300 Started
Experiment Log Entry # 11,Data On set to 0
Experiment Log Entry # 13,Isothermal Segment 2 min started
Experiment Log Entry # 15,Data On set to 1
Experiment Log Entry # 17,Ramp Segment 10 C/min to -60 Started
Experiment Log Entry # 19,Data On set to 0
Experiment Log Entry # 21,Isothermal Segment 2 min started
Experiment Log Entry # 23,Data On set to 1
Experiment Log Entry # 25,Ramp Segment 10 C/min to 300 Started
Experiment Log Entry # 27,Data On set to 0
Experiment Log Entry # 29,Isothermal Segment 2 min started
Experiment Log Entry # 31,Data On set to 1
Experiment Log Entry # 33,Ramp Segment 10 C/min to -60 Started
Experiment Log Entry # 35,Data On set to 0
Experiment Log Entry # 37,Isothermal Segment 2 min started
Experiment Log Entry # 39,Data On set to 1
Experiment Log Entry # 41,Ramp Segment 10 C/min to 300 Started
[Method Log]
Method Log Entry # 1,Data Off
Method Log Entry # 2,Equilibrate -60 °C
Method Log Entry # 3,Data On
Method Log Entry # 4,(Ramp 1345) Ramp 10 °C/minute to 300 °C
Method Log Entry # 5,Data Off
Method Log Entry # 6,Isothermal 2 minutes
Method Log Entry # 7,Data On
Method Log Entry # 8,(Ramp 1349) Ramp 10 °C/minute to -60 °C
Method Log Entry # 9,Data Off
Method Log Entry # 10,Isothermal 2 minutes
Method Log Entry # 11,Data On
Method Log Entry # 12,(Ramp 1353) Ramp 10 °C/minute to 300 °C
Method Log Entry # 13,Data Off
Method Log Entry # 14,Isothermal 2 minutes
Method Log Entry # 15,Data On
Method Log Entry # 16,(Ramp 1357) Ramp 10 °C/minute to -60 °C
Method Log Entry # 17,Data Off
Method Log Entry # 18,Isothermal 2 minutes
Method Log Entry # 19,Data On
Method Log Entry # 20,(Ramp 1361) Ramp 10 °C/minute to 300 °C
Cell Serial,DRC2-00792
[T1 Calibration]
Slope,-0.008529666
Offset,9.636258
Initial Temperature,98.23
GUID,f8bfdadc-4977-4fdf-ba6d-0ba9134940c3
[TZero Calibration]
Date Applied,11/29/2022 4:06:13 PM
Description,From -89.059 °C to 396.009 °C at 20.000°C/min
Gas Type,Nitrogen
Pan Type,None
Source Files 1,C:\Users\yargerlab\Desktop\DSC Data\General\TZero_calibration_11_29_22_2nd(2).tri
Source Files 2,C:\Users\yargerlab\Desktop\DSC Data\General\TZero_calibration_11_29_22_2nd(3).tri
Delta T Offset,13.05235
Delta T Slope,-0.007271007
Delta T0 Offset,-13.69128
Delta T0 Slope,0.06063341
[Temperature Calibration]
Date Applied,11/29/2022 7:12:28 PM
Description,From 106.590 °C to 186.590 °C at 10.000°C/min
Gas Type,Nitrogen
Pan Type,Tzero Aluminum Hermetic
Source Files 1,C:\Users\yargerlab\Desktop\DSC Data\General\Indium(6).tri
Measured 1,157.391
Known 1,156.598
[Cell Constant Calibration]
Date Applied,11/29/2022 7:12:29 PM
Description,From 106.590 °C to 186.590 °C at 10.000°C/min
Gas Type,Nitrogen
Pan Type,Tzero Aluminum Hermetic
Source Files 1,C:\Users\yargerlab\Desktop\DSC Data\General\Indium(6).tri
T4P KCell,1.006051
Onset Slope,63.26126 mW/°C
[Direct Cp Calibration]
Date Applied,11/30/2022 11:04:51 AM
Description,From -79.983 °C to 298.409 °C at 10.000°C/min
Gas Type,Nitrogen
Pan Type,Tzero Aluminum Hermetic
Source Files 1,C:\Users\yargerlab\Desktop\DSC Data\General\Sapphire_Heat_Capacity_11_30_22.tri
[Rev Cp Calibration]
Date Applied,11/30/2022 1:58:51 PM
Description,From -79.996 °C to 292.812 °C at 3.000°C/min
Gas Type,Nitrogen
Pan Type,Tzero Aluminum Hermetic
Source Files 1,C:\Users\yargerlab\Desktop\DSC Data\General\Sapphire_MDSC_Calibration_11_30_22.tri
[step]
Ramp 10.00 °C/min to 300.00 °C
Time,Temperature,Heat Flow (Normalized)
min,°C,W/g
0.00,-59.82,
0.03,-59.82,
0.05,-59.82,
0.08,-59.78,
0.10,-59.69,
0.13,-59.56,
0.15,-59.40,
0.18,-59.20,
0.20,-58.98,
0.23,-58.75,
0.25,-58.52,
0.28,-58.28,
0.30,-58.04,
0.33,-57.79,
0.35,-57.55,
0.38,-57.31,
0.40,-57.06,
0.43,-56.82,
0.45,-56.57,
0.48,-56.33,
0.50,-56.08,
0.53,-55.84,
0.55,-55.59,
0.58,-55.35,
0.60,-55.10,
0.63,-54.85,
0.65,-54.61,
0.68,-54.36,
0.70,-54.11,
0.73,-53.86,
0.75,-53.62,
0.78,-53.37,
0.80,-53.12,
0.83,-52.87,
0.85,-52.63,
0.88,-52.38,
0.90,-52.13,
0.93,-51.88,
0.95,-51.63,
0.98,-51.38,
1.00,-51.14,
1.03,-50.89,
1.05,-50.64,
1.08,-50.39,
1.10,-50.14,
1.13,-49.89,
1.15,-49.64,
1.18,-49.39,
1.20,-49.14,
1.23,-48.89,
1.25,-48.64,
1.28,-48.40,
1.30,-48.15,
1.33,-47.90,
1.35,-47.65,
1.38,-47.40,
1.40,-47.15,
1.43,-46.90,
1.45,-46.65,
1.48,-46.40,
1.50,-46.15,
1.53,-45.90,
1.55,-45.65,
1.58,-45.40,
1.60,-45.15,
1.63,-44.90,
1.65,-44.65,
1.68,-44.40,
1.70,-44.15,
1.73,-43.90,
1.75,-43.65,
1.78,-43.40,
1.80,-43.15,
1.83,-42.90,
1.85,-42.65,
1.88,-42.40,
1.90,-42.15,
1.93,-41.89,
1.95,-41.65,
1.98,-41.39,
2.00,-41.14,
2.03,-40.89,
2.05,-40.64,
2.08,-40.39,
2.10,-40.14,
2.13,-39.89,
2.15,-39.64,
2.18,-39.39,
2.20,-39.14,
2.23,-38.89,
2.25,-38.64,
2.28,-38.39,
2.30,-38.14,
2.33,-37.89,
2.35,-37.64,
2.38,-37.39,
2.40,-37.14,
2.43,-36.89,
2.45,-36.64,
2.48,-36.39,
2.50,-36.14,
2.53,-35.88,
2.55,-35.64,
2.58,-35.39,
2.60,-35.14,
2.63,-34.88,
2.65,-34.63,
2.68,-34.38,
2.70,-34.13,
2.73,-33.88,
2.75,-33.63,
2.78,-33.38,
2.80,-33.13,
2.83,-32.88,
2.85,-32.63,
2.88,-32.38,
2.90,-32.13,
2.93,-31.88,
2.95,-31.63,
2.98,-31.38,
3.00,-31.13,
3.03,-30.88,
3.05,-30.63,
3.08,-30.38,
3.10,-30.12,
3.13,-29.87,
3.15,-29.62,
3.18,-29.37,
3.20,-29.12,
3.23,-28.87,
3.25,-28.62,
3.28,-28.37,
3.30,-28.12,
3.33,-27.87,
3.35,-27.62,
3.38,-27.37,
3.40,-27.12,
3.43,-26.87,
3.45,-26.62,
3.48,-26.37,
3.50,-26.12,
3.53,-25.87,
3.55,-25.62,
3.58,-25.37,
3.60,-25.12,
3.63,-24.87,
3.65,-24.62,
3.68,-24.37,
3.70,-24.12,
3.73,-23.87,
3.75,-23.62,
3.78,-23.37,
3.80,-23.12,
3.83,-22.87,
3.85,-22.62,
3.88,-22.37,
3.90,-22.12,
3.93,-21.87,
3.95,-21.61,
3.98,-21.36,
4.00,-21.11,
4.03,-20.86,
4.05,-20.61,
4.08,-20.36,
4.10,-20.11,
4.13,-19.86,
4.15,-19.61,
4.18,-19.36,
4.20,-19.11,
4.23,-18.86,
4.25,-18.61,
4.28,-18.36,
4.30,-18.11,
4.33,-17.86,
4.35,-17.61,
4.38,-17.36,
4.40,-17.11,
4.43,-16.86,
4.45,-16.61,
4.48,-16.36,
4.50,-16.11,
4.53,-15.86,
4.55,-15.61,
4.58,-15.36,
4.60,-15.11,
4.63,-14.86,
4.65,-14.61,
4.68,-14.36,
4.70,-14.11,
4.73,-13.86,
4.75,-13.61,
4.78,-13.35,
4.80,-13.10,
4.83,-12.85,
4.85,-12.60,
4.88,-12.35,
4.90,-12.10,
4.93,-11.85,
4.95,-11.60,
4.98,-11.35,
5.00,-11.10,
5.03,-10.85,
5.05,-10.60,
5.08,-10.35,
5.10,-10.10,
5.13,-9.85,
5.15,-9.60,
5.18,-9.35,
5.20,-9.10,
5.23,-8.85,
5.25,-8.60,
5.28,-8.35,
5.30,-8.10,
5.33,-7.85,
5.35,-7.60,
5.38,-7.35,
5.40,-7.10,
5.43,-6.85,
5.45,-6.60,
5.48,-6.35,
5.50,-6.10,
5.53,-5.85,
5.55,-5.59,
5.58,-5.34,
5.60,-5.10,
5.63,-4.84,
5.65,-4.60,
5.68,-4.34,
5.70,-4.09,
5.73,-3.84,
5.75,-3.59,
5.78,-3.34,
5.80,-3.09,
5.83,-2.84,
5.85,-2.59,
5.88,-2.34,
5.90,-2.09,
5.93,-1.84,
5.95,-1.59,
5.98,-1.34,
6.00,-1.09,
6.03,-0.84,
6.05,-0.59,
6.08,-0.34,
6.10,-0.09,
6.13,0.16,
6.15,0.41,
6.18,0.66,
6.20,0.91,
6.23,1.16,
6.25,1.41,
6.28,1.66,
6.30,1.91,
6.33,2.16,
6.35,2.41,
6.38,2.67,
6.40,2.91,
6.43,3.16,
6.45,3.42,
6.48,3.67,
6.50,3.92,
6.53,4.17,
6.55,4.42,
6.58,4.67,
6.60,4.92,
6.63,5.17,
6.65,5.42,
6.68,5.67,
6.70,5.92,
6.73,6.17,
6.75,6.42,
6.78,6.67,
6.80,6.92,
6.83,7.17,
6.85,7.42,
6.88,7.67,
6.90,7.92,
6.93,8.17,
6.95,8.42,
6.98,8.67,
7.00,8.92,
7.03,9.17,
7.05,9.42,
7.08,9.67,
7.10,9.93,
7.13,10.17,
7.15,10.42,
7.18,10.68,
7.20,10.93,
7.23,11.18,
7.25,11.43,
7.28,11.68,
7.30,11.93,
7.33,12.18,
7.35,12.43,
7.38,12.68,
7.40,12.93,
7.43,13.18,
7.45,13.43,
7.48,13.68,
7.50,13.93,
7.53,14.18,
7.55,14.43,
7.58,14.68,
7.60,14.93,
7.63,15.18,
7.65,15.43,
7.68,15.68,
7.70,15.93,
7.73,16.18,
7.75,16.43,
7.78,16.68,
7.80,16.93,
7.83,17.18,
7.85,17.43,
7.88,17.68,
7.90,17.93,
7.93,18.19,
7.95,18.44,
7.98,18.69,
8.00,18.93,
8.03,19.19,
8.05,19.43,
8.08,19.69,
8.10,19.93,
8.13,20.19,
8.15,20.44,
8.18,20.69,
8.20,20.94,
8.23,21.19,
8.25,21.44,
8.28,21.69,
8.30,21.94,
8.33,22.19,
8.35,22.44,
8.38,22.69,
8.40,22.94,
8.43,23.19,
8.45,23.44,
8.48,23.69,
8.50,23.94,
8.53,24.19,
8.55,24.44,
8.58,24.69,
8.60,24.94,
8.63,25.19,
8.65,25.44,
8.68,25.69,
8.70,25.94,
8.73,26.19,
8.75,26.44,
8.78,26.69,
8.80,26.94,
8.83,27.19,
8.85,27.44,
8.88,27.69,
8.90,27.94,
8.93,28.19,
8.95,28.44,
8.98,28.69,
9.00,28.94,
9.03,29.19,
9.05,29.44,
9.08,29.69,
9.10,29.94,
9.13,30.19,
9.15,30.45,
9.18,30.69,
9.20,30.95,
9.23,31.20,
9.25,31.45,
9.28,31.70,
9.30,31.95,
9.33,32.20,
9.35,32.45,
9.38,32.70,
9.40,32.95,
9.43,33.20,
9.45,33.45,
9.48,33.70,
9.50,33.95,
9.53,34.20,
9.55,34.45,
9.58,34.70,
9.60,34.95,
9.63,35.20,
9.65,35.45,
9.68,35.70,
9.70,35.95,
9.73,36.20,
9.75,36.45,
9.78,36.70,
9.80,36.95,
9.83,37.20,
9.85,37.45,
9.88,37.70,
9.90,37.95,
9.93,38.20,
9.95,38.45,
9.98,38.70,
10.00,38.95,
10.03,39.20,
10.05,39.46,
10.08,39.71,
10.10,39.96,
10.13,40.21,
10.15,40.46,
10.18,40.71,
10.20,40.96,
10.23,41.21,
10.25,41.46,
10.28,41.71,
10.30,41.96,
10.33,42.21,
10.35,42.46,
10.38,42.71,
10.40,42.96,
10.43,43.21,
10.45,43.46,
10.48,43.71,
10.50,43.96,
10.53,44.21,
10.55,44.46,
10.58,44.71,
10.60,44.96,
10.63,45.21,
10.65,45.46,
10.68,45.71,
10.70,45.96,
10.73,46.21,
10.75,46.46,
10.78,46.71,
10.80,46.96,
10.83,47.21,
10.85,47.47,
10.88,47.72,
10.90,47.97,
10.93,48.22,
10.95,48.47,
10.98,48.71,
11.00,48.97,
11.03,49.22,
11.05,49.47,
11.08,49.72,
11.10,49.97,
11.13,50.22,
11.15,50.47,
11.18,50.72,
11.20,50.97,
11.23,51.22,
11.25,51.47,
11.28,51.72,
11.30,51.97,
11.33,52.22,
11.35,52.47,
11.38,52.72,
11.40,52.97,
11.43,53.22,
11.45,53.47,
11.48,53.72,
11.50,53.97,
11.53,54.22,
11.55,54.47,
11.58,54.72,
11.60,54.97,
11.63,55.22,
11.65,55.47,
11.68,55.72,
11.70,55.97,
11.73,56.22,
11.75,56.47,
11.78,56.72,
11.80,56.97,
11.83,57.22,
11.85,57.48,
11.88,57.72,
11.90,57.98,
11.93,58.22,
11.95,58.48,
11.98,58.73,
12.00,58.98,
12.03,59.23,
12.05,59.48,
12.08,59.73,
12.10,59.98,
12.13,60.23,
12.15,60.48,
12.18,60.73,
12.20,60.98,
12.23,61.23,
12.25,61.48,
12.28,61.73,
12.30,61.98,
12.33,62.23,
12.35,62.48,
12.38,62.73,
12.40,62.98,
12.43,63.23,
12.45,63.48,
12.48,63.73,
12.50,63.98,
12.53,64.23,
12.55,64.48,
12.58,64.73,
12.60,64.98,
12.63,65.23,
12.65,65.48,
12.68,65.73,
12.70,65.98,
12.73,66.23,
12.75,66.48,
12.78,66.73,
12.80,66.98,
12.83,67.23,
12.85,67.48,
12.88,67.73,
12.90,67.98,
12.93,68.24,
12.95,68.49,
12.98,68.74,
13.00,68.99,
13.03,69.24,
13.05,69.49,
13.08,69.74,
13.10,69.99,
13.13,70.24,
13.15,70.49,
13.18,70.74,
13.20,70.99,
13.23,71.24,
13.25,71.49,
13.28,71.74,
13.30,71.99,
13.33,72.24,
13.35,72.49,
13.38,72.74,
13.40,72.99,
13.43,73.24,
13.45,73.49,
13.48,73.74,
13.50,73.99,
13.53,74.24,
13.55,74.49,
13.58,74.74,
13.60,74.99,
13.63,75.24,
13.65,75.49,
13.68,75.74,
13.70,75.99,
13.73,76.24,
13.75,76.49,
13.78,76.74,
13.80,76.99,
13.83,77.24,
13.85,77.49,
13.88,77.74,
13.90,77.99,
13.93,78.24,
13.95,78.49,
13.98,78.74,
14.00,78.99,
14.03,79.24,
14.05,79.49,
14.08,79.74,
14.10,79.99,
14.13,80.25,
14.15,80.49,
14.18,80.75,
14.20,81.00,
14.23,81.25,
14.25,81.50,
14.28,81.75,
14.30,82.00,
14.33,82.25,
14.35,82.50,
14.38,82.75,
14.40,83.00,
14.43,83.25,
14.45,83.50,
14.48,83.75,
14.50,84.00,
14.53,84.25,
14.55,84.50,
14.58,84.75,
14.60,85.00,
14.63,85.25,
14.65,85.50,
14.68,85.75,
14.70,86.00,
14.73,86.25,
14.75,86.50,
14.78,86.75,
14.80,87.00,
14.83,87.25,
14.85,87.50,
14.88,87.75,
14.90,88.00,
14.93,88.25,
14.95,88.50,
14.98,88.75,
15.00,89.00,
15.03,89.25,
15.05,89.50,
15.08,89.76,
15.10,90.00,
15.13,90.26,
15.15,90.51,
15.18,90.76,
15.20,91.01,
15.23,91.26,
15.25,91.51,
15.28,91.76,
15.30,92.01,
15.33,92.26,
15.35,92.51,
15.38,92.76,
15.40,93.01,
15.43,93.26,
15.45,93.51,
15.48,93.76,
15.50,94.01,
15.53,94.26,
15.55,94.51,
15.58,94.76,
15.60,95.01,
15.63,95.26,
15.65,95.51,
15.68,95.76,
15.70,96.01,
15.73,96.26,
15.75,96.51,
15.78,96.76,
15.80,97.01,
15.83,97.26,
15.85,97.51,
15.88,97.76,
15.90,98.01,
15.93,98.26,
15.95,98.51,
15.98,98.76,
16.00,99.01,
16.03,99.26,
16.05,99.52,
16.08,99.77,
16.10,100.01,
16.13,100.26,
16.15,100.51,
16.18,100.76,
16.20,101.01,
16.23,101.26,
16.25,101.51,
16.28,101.77,
16.30,102.02,
16.33,102.27,
16.35,102.52,
16.38,102.76,
16.40,103.02,
16.43,103.27,
16.45,103.52,
16.48,103.77,
16.50,104.02,
16.53,104.27,
16.55,104.52,
16.58,104.77,
16.60,105.02,
16.63,105.27,
16.65,105.52,
16.68,105.77,
16.70,106.02,
16.73,106.27,
16.75,106.52,
16.78,106.77,
16.80,107.02,
16.83,107.27,
16.85,107.52,
16.88,107.77,
16.90,108.02,
16.93,108.27,
16.95,108.52,
16.98,108.77,
17.00,109.02,
17.03,109.27,
17.05,109.52,
17.08,109.77,
17.10,110.02,
17.13,110.27,
17.15,110.52,
17.18,110.77,
17.20,111.02,
17.23,111.27,
17.25,111.52,
17.28,111.77,
17.30,112.02,
17.33,112.27,
17.35,112.52,
17.38,112.77,
17.40,113.02,
17.43,113.27,
17.45,113.52,
17.48,113.77,
17.50,114.02,
17.53,114.28,
17.55,114.52,
17.58,114.78,
17.60,115.03,
17.63,115.28,
17.65,115.53,
17.68,115.78,
17.70,116.03,
17.73,116.28,
17.75,116.53,
17.78,116.78,
17.80,117.03,
17.83,117.28,
17.85,117.53,
17.88,117.78,
17.90,118.03,
17.93,118.28,
17.95,118.53,
17.98,118.78,
18.00,119.03,
18.03,119.28,
18.05,119.53,
18.08,119.78,
18.10,120.03,
18.13,120.28,
18.15,120.53,
18.18,120.78,
18.20,121.03,
18.23,121.28,
18.25,121.53,
18.28,121.78,
18.30,122.03,
18.33,122.28,
18.35,122.53,
18.38,122.78,
18.40,123.03,
18.43,123.28,
18.45,123.53,
18.48,123.78,
18.50,124.03,
18.53,124.28,
18.55,124.53,
18.58,124.78,
18.60,125.03,
18.63,125.28,
18.65,125.53,
18.68,125.78,
18.70,126.03,
18.73,126.28,
18.75,126.54,
18.78,126.78,
18.80,127.03,
18.83,127.29,
18.85,127.53,
18.88,127.79,
18.90,128.03,
18.93,128.29,
18.95,128.54,
18.98,128.80,
19.00,129.05,
19.03,129.30,
19.05,129.55,
19.08,129.80,
19.10,130.05,
19.13,130.30,
19.15,130.55,
19.18,130.80,
19.20,131.05,
19.23,131.30,
19.25,131.55,
19.28,131.80,
19.30,132.05,
19.33,132.30,
19.35,132.55,
19.38,132.79,
19.40,133.04,
19.43,133.30,
19.45,133.55,
19.48,133.79,
19.50,134.04,
19.53,134.29,
19.55,134.54,
19.58,134.79,
19.60,135.05,
19.63,135.30,
19.65,135.54,
19.68,135.80,
19.70,136.04,
19.73,136.30,
19.75,136.54,
19.78,136.79,
19.80,137.04,
19.83,137.29,
19.85,137.54,
19.88,137.79,
19.90,138.04,
19.93,138.29,
19.95,138.54,
19.98,138.79,
20.00,139.04,
20.03,139.29,
20.05,139.54,
20.08,139.80,
20.10,140.05,
20.13,140.30,
20.15,140.55,
20.18,140.80,
20.20,141.05,
20.23,141.30,
20.25,141.55,
20.28,141.80,
20.30,142.05,
20.33,142.30,
20.35,142.55,
20.38,142.80,
20.40,143.05,
20.43,143.30,
20.45,143.55,
20.48,143.80,
20.50,144.05,
20.53,144.30,
20.55,144.55,
20.58,144.80,
20.60,145.05,
20.63,145.30,
20.65,145.55,
20.68,145.80,
20.70,146.05,
20.73,146.30,
20.75,146.55,
20.78,146.80,
20.80,147.05,
20.83,147.30,
20.85,147.55,
20.88,147.80,
20.90,148.05,
20.93,148.30,
20.95,148.55,
20.98,148.80,
21.00,149.05,
21.03,149.30,
21.05,149.55,
21.08,149.80,
21.10,150.05,
21.13,150.30,
21.15,150.55,
21.18,150.80,
21.20,151.05,
21.23,151.30,
21.25,151.55,
21.28,151.80,
21.30,152.05,
21.33,152.30,
21.35,152.55,
21.38,152.80,
21.40,153.05,
21.43,153.31,
21.45,153.56,
21.48,153.81,
21.50,154.06,
21.53,154.31,
21.55,154.56,
21.58,154.81,
21.60,155.06,
21.63,155.31,
21.65,155.56,
21.68,155.81,
21.70,156.06,
21.73,156.31,
21.75,156.56,
21.78,156.81,
21.80,157.06,
21.83,157.31,
21.85,157.56,
21.88,157.81,
21.90,158.06,
21.93,158.31,
21.95,158.56,
21.98,158.81,
22.00,159.06,
22.03,159.31,
22.05,159.56,
22.08,159.81,
22.10,160.06,
22.13,160.31,
22.15,160.56,
22.18,160.81,
22.20,161.06,
22.23,161.31,
22.25,161.56,
22.28,161.81,
22.30,162.06,
22.33,162.31,
22.35,162.56,
22.38,162.81,
22.40,163.06,
22.43,163.31,
22.45,163.57,
22.48,163.81,
22.50,164.07,
22.53,164.31,
22.55,164.56,
22.58,164.81,
22.60,165.07,
22.63,165.31,
22.65,165.57,
22.68,165.82,
22.70,166.07,
22.73,166.32,
22.75,166.57,
22.78,166.82,
22.80,167.07,
22.83,167.31,
22.85,167.57,
22.88,167.82,
22.90,168.07,
22.93,168.32,
22.95,168.57,
22.98,168.82,
23.00,169.07,
23.03,169.32,
23.05,169.57,
23.08,169.82,
23.10,170.07,
23.13,170.32,
23.15,170.57,
23.18,170.82,
23.20,171.07,
23.23,171.32,
23.25,171.57,
23.28,171.82,
23.30,172.07,
23.33,172.32,
23.35,172.57,
23.38,172.82,
23.40,173.07,
23.43,173.32,
23.45,173.57,
23.48,173.82,
23.50,174.07,
23.53,174.32,
23.55,174.57,
23.58,174.82,
23.60,175.07,
23.63,175.32,
23.65,175.57,
23.68,175.82,
23.70,176.07,
23.73,176.32,
23.75,176.57,
23.78,176.82,
23.80,177.07,
23.83,177.33,
23.85,177.57,
23.88,177.82,
23.90,178.07,
23.93,178.32,
23.95,178.57,
23.98,178.82,
24.00,179.07,
24.03,179.32,
24.05,179.57,
24.08,179.82,
24.10,180.07,
24.13,180.32,
24.15,180.57,
24.18,180.82,
24.20,181.07,
24.23,181.32,
24.25,181.57,
24.28,181.82,
24.30,182.07,
24.33,182.32,
24.35,182.58,
24.38,182.82,
24.40,183.08,
24.43,183.33,
24.45,183.58,
24.48,183.83,
24.50,184.08,
24.53,184.32,
24.55,184.58,
24.58,184.83,
24.60,185.08,
24.63,185.33,
24.65,185.58,
24.68,185.83,
24.70,186.08,
24.73,186.33,
24.75,186.58,
24.78,186.83,
24.80,187.08,
24.83,187.33,
24.85,187.58,
24.88,187.83,
24.90,188.08,
24.93,188.33,
24.95,188.58,
24.98,188.83,
25.00,189.08,
25.03,189.33,
25.05,189.58,
25.08,189.83,
25.10,190.08,
25.13,190.33,
25.15,190.58,
25.18,190.83,
25.20,191.08,
25.23,191.33,
25.25,191.58,
25.28,191.83,
25.30,192.08,
25.33,192.33,
25.35,192.58,
25.38,192.83,
25.40,193.08,
25.43,193.33,
25.45,193.58,
25.48,193.83,
25.50,194.08,
25.53,194.33,
25.55,194.58,
25.58,194.83,
25.60,195.08,
25.63,195.33,
25.65,195.58,
25.68,195.83,
25.70,196.08,
25.73,196.33,
25.75,196.58,
25.78,196.83,
25.80,197.08,
25.83,197.33,
25.85,197.58,
25.88,197.83,
25.90,198.08,
25.93,198.33,
25.95,198.58,
25.98,198.83,
26.00,199.08,
26.03,199.33,
26.05,199.58,
26.08,199.83,
26.10,200.08,
26.13,200.34,
26.15,200.59,
26.18,200.84,
26.20,201.09,
26.23,201.34,
26.25,201.59,
26.28,201.84,
26.30,202.09,
26.33,202.34,
26.35,202.59,
26.38,202.83,
26.40,203.08,
26.43,203.34,
26.45,203.59,
26.48,203.84,
26.50,204.09,
26.53,204.34,
26.55,204.59,
26.58,204.84,
26.60,205.09,
26.63,205.34,
26.65,205.59,
26.68,205.84,
26.70,206.09,
26.73,206.34,
26.75,206.59,
26.78,206.84,
26.80,207.09,
26.83,207.34,
26.85,207.59,
26.88,207.84,
26.90,208.09,
26.93,208.34,
26.95,208.59,
26.98,208.84,
27.00,209.09,
27.03,209.34,
27.05,209.59,
27.08,209.84,
27.10,210.09,
27.13,210.34,
27.15,210.59,
27.18,210.84,
27.20,211.09,
27.23,211.34,
27.25,211.59,
27.28,211.84,
27.30,212.09,
27.33,212.34,
27.35,212.59,
27.38,212.84,
27.40,213.09,
27.43,213.34,
27.45,213.59,
27.48,213.84,
27.50,214.10,
27.53,214.35,
27.55,214.60,
27.58,214.85,
27.60,215.10,
27.63,215.35,
27.65,215.60,
27.68,215.85,
27.70,216.10,
27.73,216.35,
27.75,216.60,
27.78,216.85,
27.80,217.10,
27.83,217.35,
27.85,217.60,
27.88,217.85,
27.90,218.10,
27.93,218.35,
27.95,218.60,
27.98,218.85,
28.00,219.10,
28.03,219.35,
28.05,219.60,
28.08,219.85,
28.10,220.10,
28.13,220.35,
28.15,220.60,
28.18,220.85,
28.20,221.10,
28.23,221.35,
28.25,221.60,
28.28,221.85,
28.30,222.10,
28.33,222.35,
28.35,222.60,
28.38,222.85,
28.40,223.10,
28.43,223.35,
28.45,223.60,
28.48,223.85,
28.50,224.10,
28.53,224.35,
28.55,224.60,
28.58,224.85,
28.60,225.10,
28.63,225.35,
28.65,225.60,
28.68,225.85,
28.70,226.10,
28.73,226.35,
28.75,226.60,
28.78,226.85,
28.80,227.10,
28.83,227.35,
28.85,227.60,
28.88,227.85,
28.90,228.10,
28.93,228.35,
28.95,228.60,
28.98,228.85,
29.00,229.10,
29.03,229.35,
29.05,229.60,
29.08,229.85,
29.10,230.10,
29.13,230.35,
29.15,230.60,
29.18,230.86,
29.20,231.10,
29.23,231.36,
29.25,231.61,
29.28,231.86,
29.30,232.11,
29.33,232.35,
29.35,232.61,
29.38,232.86,
29.40,233.11,
29.43,233.36,
29.45,233.61,
29.48,233.86,
29.50,234.11,
29.53,234.35,
29.55,234.60,
29.58,234.86,
29.60,235.11,
29.63,235.36,
29.65,235.61,
29.68,235.86,
29.70,236.11,
29.73,236.36,
29.75,236.61,
29.78,236.86,
29.80,237.11,
29.83,237.36,
29.85,237.61,
29.88,237.86,
29.90,238.11,
29.93,238.36,
29.95,238.61,
29.98,238.86,
30.00,239.11,
30.03,239.36,
30.05,239.61,
30.08,239.86,
30.10,240.11,
30.13,240.36,
30.15,240.61,
30.18,240.86,
30.20,241.11,
30.23,241.36,
30.25,241.61,
30.28,241.86,
30.30,242.11,
30.33,242.36,
30.35,242.61,
30.38,242.86,
30.40,243.11,
30.43,243.36,
30.45,243.61,
30.48,243.86,
30.50,244.11,
30.53,244.36,
30.55,244.61,
30.58,244.86,
30.60,245.11,
30.63,245.36,
30.65,245.61,
30.68,245.86,
30.70,246.11,
30.73,246.36,
30.75,246.61,
30.78,246.86,
30.80,247.11,
30.83,247.36,
30.85,247.61,
30.88,247.86,
30.90,248.11,
30.93,248.36,
30.95,248.61,
30.98,248.86,
31.00,249.11,
31.03,249.36,
31.05,249.61,
31.08,249.87,
31.10,250.11,
31.13,250.37,
31.15,250.62,
31.18,250.87,
31.20,251.12,
31.23,251.37,
31.25,251.62,
31.28,251.87,
31.30,252.12,
31.33,252.37,
31.35,252.62,
31.38,252.87,
31.40,253.12,
31.43,253.37,
31.45,253.62,
31.48,253.87,
31.50,254.12,
31.53,254.37,
31.55,254.62,
31.58,254.87,
31.60,255.12,
31.63,255.37,
31.65,255.62,
31.68,255.87,
31.70,256.12,
31.73,256.37,
31.75,256.62,
31.78,256.87,
31.80,257.12,
31.83,257.37,
31.85,257.62,
31.88,257.87,
31.90,258.12,
31.93,258.37,
31.95,258.62,
31.98,258.87,
32.00,259.12,
32.03,259.37,
32.05,259.62,
32.08,259.87,
32.10,260.12,
32.13,260.37,
32.15,260.62,
32.18,260.87,
32.20,261.12,
32.23,261.37,
32.25,261.62,
32.28,261.87,
32.30,262.12,
32.33,262.37,
32.35,262.62,
32.38,262.87,
32.40,263.12,
32.43,263.37,
32.45,263.62,
32.48,263.87,
32.50,264.12,
32.53,264.37,
32.55,264.62,
32.58,264.87,
32.60,265.12,
32.63,265.37,
32.65,265.62,
32.68,265.87,
32.70,266.12,
32.73,266.37,
32.75,266.62,
32.78,266.87,
32.80,267.12,
32.83,267.37,
32.85,267.62,
32.88,267.87,
32.90,268.12,
32.93,268.37,
32.95,268.62,
32.98,268.87,
33.00,269.12,
33.03,269.37,
33.05,269.62,
33.08,269.87,
33.10,270.12,
33.13,270.37,
33.15,270.62,
33.18,270.87,
33.20,271.12,
33.23,271.37,
33.25,271.62,
33.28,271.87,
33.30,272.12,
33.33,272.37,
33.35,272.62,
33.38,272.87,
33.40,273.12,
33.43,273.37,
33.45,273.62,
33.48,273.87,
33.50,274.12,
33.53,274.37,
33.55,274.62,
33.58,274.87,
33.60,275.12,
33.63,275.37,
33.65,275.63,
33.68,275.88,
33.70,276.12,
33.73,276.37,
33.75,276.63,
33.78,276.87,
33.80,277.12,
33.83,277.38,
33.85,277.62,
33.88,277.87,
33.90,278.12,
33.93,278.37,
33.95,278.62,
33.98,278.88,
34.00,279.13,
34.03,279.38,
34.05,279.63,
34.08,279.88,
34.10,280.13,
34.13,280.38,
34.15,280.63,
34.18,280.88,
34.20,281.13,
34.23,281.38,
34.25,281.63,
34.28,281.88,
34.30,282.13,
34.33,282.38,
34.35,282.63,
34.38,282.88,
34.40,283.13,
34.43,283.38,
34.45,283.63,
34.48,283.88,
34.50,284.13,
34.53,284.38,
34.55,284.63,
34.58,284.88,
34.60,285.13,
34.63,285.38,
34.65,285.63,
34.68,285.88,
34.70,286.13,
34.73,286.38,
34.75,286.63,
34.78,286.88,
34.80,287.13,
34.83,287.38,
34.85,287.63,
34.88,287.88,
34.90,288.13,
34.93,288.38,
34.95,288.63,
34.98,288.88,
35.00,289.13,
35.03,289.38,
35.05,289.63,
35.08,289.88,
35.10,290.13,
35.13,290.38,
35.15,290.63,
35.18,290.88,
35.20,291.13,
35.23,291.38,
35.25,291.63,
35.28,291.88,
35.30,292.13,
35.33,292.38,
35.35,292.63,
35.38,292.88,
35.40,293.13,
35.43,293.38,
35.45,293.63,
35.48,293.88,
35.50,294.13,
35.53,294.38,
35.55,294.63,
35.58,294.88,
35.60,295.13,
35.63,295.38,
35.65,295.63,
35.68,295.88,
35.70,296.13,
35.73,296.38,
35.75,296.63,
35.78,296.88,
35.80,297.13,
35.83,297.38,
35.85,297.63,
35.88,297.88,
35.90,298.13,
35.93,298.38,
35.95,298.63,
35.98,298.88,
35.99,,

[step]
Ramp 10.00 °C/min to -60.00 °C
Time,Temperature,Heat Flow (Normalized)
min,°C,W/g
37.99,300.16,
38.02,300.16,
38.04,300.14,
38.07,300.10,
38.09,300.02,
38.12,299.88,
38.14,299.70,
38.17,299.48,
38.19,299.25,
38.22,299.01,
38.24,298.76,
38.27,298.52,
38.29,298.27,
38.32,298.02,
38.34,297.77,
38.37,297.53,
38.39,297.28,
38.42,297.03,
38.44,296.78,
38.47,296.53,
38.49,296.29,
38.52,296.04,
38.54,295.79,
38.57,295.54,
38.59,295.29,
38.62,295.04,
38.64,294.79,
38.67,294.55,
38.69,294.30,
38.72,294.05,
38.74,293.80,
38.77,293.55,
38.79,293.30,
38.82,293.05,
38.84,292.81,
38.87,292.56,
38.89,292.31,
38.92,292.06,
38.94,291.81,
38.97,291.56,
38.99,291.31,
39.02,291.06,
39.04,290.82,
39.07,290.57,
39.09,290.32,
39.12,290.07,
39.14,289.82,
39.17,289.57,
39.19,289.32,
39.22,289.07,
39.24,288.82,
39.27,288.57,
39.29,288.32,
39.32,288.07,
39.34,287.83,
39.37,287.58,
39.39,287.33,
39.42,287.08,
39.44,286.83,
39.47,286.58,
39.49,286.33,
39.52,286.08,
39.54,285.83,
39.57,285.58,
39.59,285.33,
39.62,285.08,
39.64,284.83,
39.67,284.58,
39.69,284.33,
39.72,284.08,
39.74,283.84,
39.77,283.59,
39.79,283.34,
39.82,283.09,
39.84,282.84,
39.87,282.59,
39.89,282.34,
39.92,282.09,
39.94,281.84,
39.97,281.59,
39.99,281.34,
40.02,281.09,
40.04,280.84,
40.07,280.59,
40.09,280.34,
40.12,280.09,
40.14,279.84,
40.17,279.59,
40.19,279.34,
40.22,279.09,
40.24,278.84,
40.27,278.59,
40.29,278.34,
40.32,278.09,
40.34,277.84,
40.37,277.59,
40.39,277.34,
40.42,277.09,
40.44,276.84,
40.47,276.59,
40.49,276.34,
40.52,276.09,
40.54,275.84,
40.57,275.59,
40.59,275.34,
40.62,275.09,
40.64,274.84,
40.67,274.59,
40.69,274.34,
40.72,274.09,
40.74,273.84,
40.77,273.59,
40.79,273.34,
40.82,273.09,
40.84,272.84,
40.87,272.59,
40.89,272.34,
40.92,272.09,
40.94,271.84,
40.97,271.59,
40.99,271.34,
41.02,271.09,
41.04,270.84,
41.07,270.59,
41.09,270.35,
41.12,270.09,
41.14,269.85,
41.17,269.59,
41.19,269.35,
41.22,269.10,
41.24,268.85,
41.27,268.60,
41.29,268.35,
41.32,268.10,
41.34,267.85,
41.37,267.60,
41.39,267.35,
41.42,267.10,
41.44,266.85,
41.47,266.60,
41.49,266.35,
41.52,266.10,
41.54,265.85,
41.57,265.60,
41.59,265.35,
41.62,265.10,
41.64,264.85,
41.67,264.60,
41.69,264.35,
41.72,264.10,
41.74,263.85,
41.77,263.60,
41.79,263.35,
41.82,263.10,
41.84,262.85,
41.87,262.60,
41.89,262.35,
41.92,262.10,
41.94,261.85,
41.97,261.60,
41.99,261.35,
42.02,261.10,
42.04,260.85,
42.07,260.60,
42.09,260.35,
42.12,260.10,
42.14,259.85,
42.17,259.60,
42.19,259.35,
42.22,259.10,
42.24,258.85,
42.27,258.60,
42.29,258.35,
42.32,258.10,
42.34,257.85,
42.37,257.60,
42.39,257.35,
42.42,257.10,
42.44,256.85,
42.47,256.60,
42.49,256.35,
42.52,256.11,
42.54,255.86,
42.57,255.61,
42.59,255.36,
42.62,255.10,
42.64,254.85,
42.67,254.61,
42.69,254.36,
42.72,254.11,
42.74,253.86,
42.77,253.61,
42.79,253.36,
42.82,253.11,
42.84,252.86,
42.87,252.61,
42.89,252.36,
42.92,252.11,
42.94,251.86,
42.97,251.61,
42.99,251.36,
43.02,251.11,
43.04,250.86,
43.07,250.61,
43.09,250.36,
43.12,250.11,
43.14,249.86,
43.17,249.61,
43.19,249.36,
43.22,249.11,
43.24,248.86,
43.27,248.61,
43.29,248.36,
43.32,248.11,
43.34,247.86,
43.37,247.61,
43.39,247.36,
43.42,247.11,
43.44,246.86,
43.47,246.61,
43.49,246.36,
43.52,246.11,
43.54,245.86,
43.57,245.61,
43.59,245.36,
43.62,245.11,
43.64,244.86,
43.67,244.61,
43.69,244.36,
43.72,244.11,
43.74,243.86,
43.77,243.61,
43.79,243.36,
43.82,243.11,
43.84,242.86,
43.87,242.61,
43.89,242.36,
43.92,242.11,
43.94,241.86,
43.97,241.61,
43.99,241.36,
44.02,241.11,
44.04,240.86,
44.07,240.61,
44.09,240.36,
44.12,240.11,
44.14,239.86,
44.17,239.62,
44.19,239.36,
44.22,239.11,
44.24,238.86,
44.27,238.61,
44.29,238.36,
44.32,238.11,
44.34,237.86,
44.37,237.61,
44.39,237.36,
44.42,237.11,
44.44,236.86,
44.47,236.61,
44.49,236.36,
44.52,236.11,
44.54,235.87,
44.57,235.62,
44.59,235.37,
44.62,235.12,
44.64,234.87,
44.67,234.62,
44.69,234.37,
44.72,234.12,
44.74,233.87,
44.77,233.62,
44.79,233.37,
44.82,233.12,
44.84,232.87,
44.87,232.62,
44.89,232.37,
44.92,232.12,
44.94,231.87,
44.97,231.62,
44.99,231.37,
45.02,231.12,
45.04,230.87,
45.07,230.62,
45.09,230.37,
45.12,230.12,
45.14,229.87,
45.17,229.62,
45.19,229.37,
45.22,229.12,
45.24,228.87,
45.27,228.62,
45.29,228.37,
45.32,228.12,
45.34,227.87,
45.37,227.62,
45.39,227.37,
45.42,227.12,
45.44,226.87,
45.47,226.62,
45.49,226.37,
45.52,226.12,
45.54,225.87,
45.57,225.62,
45.59,225.37,
45.62,225.12,
45.64,224.87,
45.67,224.62,
45.69,224.37,
45.72,224.12,
45.74,223.87,
45.77,223.62,
45.79,223.37,
45.82,223.12,
45.84,222.87,
45.87,222.62,
45.89,222.37,
45.92,222.12,
45.94,221.87,
45.97,221.62,
45.99,221.37,
46.02,221.12,
46.04,220.87,
46.07,220.62,
46.09,220.37,
46.12,220.12,
46.14,219.87,
46.17,219.63,
46.19,219.38,
46.22,219.13,
46.24,218.87,
46.27,218.62,
46.29,218.37,
46.32,218.12,
46.34,217.87,
46.37,217.62,
46.39,217.37,
46.42,217.12,
46.44,216.87,
46.47,216.62,
46.49,216.37,
46.52,216.12,
46.54,215.87,
46.57,215.62,
46.59,215.37,
46.62,215.12,
46.64,214.87,
46.67,214.62,
46.69,214.38,
46.72,214.13,
46.74,213.88,
46.77,213.62,
46.79,213.37,
46.82,213.12,
46.84,212.87,
46.87,212.62,
46.89,212.37,
46.92,212.13,
46.94,211.88,
46.97,211.63,
46.99,211.38,
47.02,211.13,
47.04,210.88,
47.07,210.63,
47.09,210.38,
47.12,210.13,
47.14,209.88,
47.17,209.63,
47.19,209.38,
47.22,209.13,
47.24,208.88,
47.27,208.63,
47.29,208.38,
47.32,208.13,
47.34,207.88,
47.37,207.63,
47.39,207.38,
47.42,207.13,
47.44,206.88,
47.47,206.63,
47.49,206.38,
47.52,206.13,
47.54,205.88,
47.57,205.63,
47.59,205.38,
47.62,205.13,
47.64,204.88,
47.67,204.63,
47.69,204.38,
47.72,204.13,
47.74,203.88,
47.77,203.63,
47.79,203.38,
47.82,203.13,
47.84,202.88,
47.87,202.63,
47.89,202.38,
47.92,202.13,
47.94,201.88,
47.97,201.63,
47.99,201.38,
48.02,201.13,
48.04,200.88,
48.07,200.63,
48.09,200.38,
48.12,200.13,
48.14,199.88,
48.17,199.63,
48.19,199.38,
48.22,199.13,
48.24,198.88,
48.27,198.63,
48.29,198.38,
48.32,198.13,
48.34,197.88,
48.37,197.63,
48.39,197.38,
48.42,197.13,
48.44,196.88,
48.47,196.63,
48.49,196.38,
48.52,196.13,
48.54,195.88,
48.57,195.63,
48.59,195.38,
48.62,195.13,
48.64,194.88,
48.67,194.63,
48.69,194.38,
48.72,194.13,
48.74,193.88,
48.77,193.63,
48.79,193.38,
48.82,193.13,
48.84,192.88,
48.87,192.63,
48.89,192.38,
48.92,192.13,
48.94,191.88,
48.97,191.63,
48.99,191.38,
49.02,191.13,
49.04,190.88,
49.07,190.63,
49.09,190.38,
49.12,190.13,
49.14,189.88,
49.17,189.63,
49.19,189.38,
49.22,189.13,
49.24,188.88,
49.27,188.63,
49.29,188.38,
49.32,188.13,
49.34,187.88,
49.37,187.63,
49.39,187.38,
49.42,187.13,
49.44,186.88,
49.47,186.63,
49.49,186.38,
49.52,186.13,
49.54,185.88,
49.57,185.63,
49.59,185.38,
49.62,185.13,
49.64,184.88,
49.67,184.63,
49.69,184.38,
49.72,184.13,
49.74,183.88,
49.77,183.63,
49.79,183.38,
49.82,183.13,
49.84,182.89,
49.87,182.63,
49.89,182.39,
49.92,182.13,
49.94,181.88,
49.97,181.64,
49.99,181.38,
50.02,181.13,
50.04,180.88,
50.07,180.63,
50.09,180.39,
50.12,180.13,
50.14,179.88,
50.17,179.63,
50.19,179.39,
50.22,179.13,
50.24,178.88,
50.27,178.63,
50.29,178.38,
50.32,178.13,
50.34,177.88,
50.37,177.64,
50.39,177.39,
50.42,177.13,
50.44,176.89,
50.47,176.64,
50.49,176.39,
50.52,176.14,
50.54,175.89,
50.57,175.64,
50.59,175.39,
50.62,175.14,
50.64,174.89,
50.67,174.64,
50.69,174.39,
50.72,174.14,
50.74,173.89,
50.77,173.64,
50.79,173.39,
50.82,173.14,
50.84,172.89,
50.87,172.64,
50.89,172.39,
50.92,172.14,
50.94,171.89,
50.97,171.64,
50.99,171.39,
51.02,171.14,
51.04,170.89,
51.07,170.64,
51.09,170.39,
51.12,170.14,
51.14,169.89,
51.17,169.64,
51.19,169.39,
51.22,169.14,
51.24,168.89,
51.27,168.64,
51.29,168.39,
51.32,168.14,
51.34,167.89,
51.37,167.64,
51.39,167.39,
51.42,167.14,
51.44,166.89,
51.47,166.64,
51.49,166.39,
51.52,166.14,
51.54,165.89,
51.57,165.64,
51.59,165.39,
51.62,165.14,
51.64,164.89,
51.67,164.64,
51.69,164.39,
51.72,164.14,
51.74,163.89,
51.77,163.64,
51.79,163.39,
51.82,163.14,
51.84,162.89,
51.87,162.64,
51.89,162.39,
51.92,162.14,
51.94,161.89,
51.97,161.64,
51.99,161.39,
52.02,161.14,
52.04,160.89,
52.07,160.64,
52.09,160.39,
52.12,160.14,
52.14,159.89,
52.17,159.64,
52.19,159.39,
52.22,159.14,
52.24,158.89,
52.27,158.64,
52.29,158.39,
52.32,158.14,
52.34,157.89,
52.37,157.64,
52.39,157.39,
52.42,157.14,
52.44,156.89,
52.47,156.64,
52.49,156.39,
52.52,156.14,
52.54,155.89,
52.57,155.64,
52.59,155.39,
52.62,155.14,
52.64,154.89,
52.67,154.64,
52.69,154.39,
52.72,154.14,
52.74,153.89,
52.77,153.64,
52.79,153.39,
52.82,153.14,
52.84,152.89,
52.87,152.64,
52.89,152.39,
52.92,152.14,
52.94,151.89,
52.97,151.64,
52.99,151.39,
53.02,151.14,
53.04,150.89,
53.07,150.64,
53.09,150.39,
53.12,150.14,
53.14,149.89,
53.17,149.64,
53.19,149.39,
53.22,149.14,
53.24,148.89,
53.27,148.64,
53.29,148.39,
53.32,148.14,
53.34,147.89,
53.37,147.64,
53.39,147.39,
53.42,147.14,
53.44,146.89,
53.47,146.64,
53.49,146.39,
53.52,146.15,
53.54,145.89,
53.57,145.64,
53.59,145.40,
53.62,145.14,
53.64,144.89,
53.67,144.65,
53.69,144.39,
53.72,144.14,
53.74,143.89,
53.77,143.64,
53.79,143.40,
53.82,143.14,
53.84,142.89,
53.87,142.64,
53.89,142.39,
53.92,142.14,
53.94,141.89,
53.97,141.64,
53.99,141.39,
54.02,141.14,
54.04,140.89,
54.07,140.64,
54.09,140.39,
54.12,140.14,
54.14,139.89,
54.17,139.64,
54.19,139.39,
54.22,139.15,
54.24,138.89,
54.27,138.65,
54.29,138.40,
54.32,138.15,
54.34,137.90,
54.37,137.65,
54.39,137.40,
54.42,137.15,
54.44,136.90,
54.47,136.65,
54.49,136.40,
54.52,136.15,
54.54,135.90,
54.57,135.65,
54.59,135.40,
54.62,135.15,
54.64,134.90,
54.67,134.65,
54.69,134.40,
54.72,134.15,
54.74,133.90,
54.77,133.65,
54.79,133.40,
54.82,133.15,
54.84,132.90,
54.87,132.65,
54.89,132.40,
54.92,132.15,
54.94,131.90,
54.97,131.65,
54.99,131.40,
55.02,131.15,
55.04,130.90,
55.07,130.65,
55.09,130.40,
55.12,130.15,
55.14,129.90,
55.17,129.65,
55.19,129.40,
55.22,129.15,
55.24,128.90,
55.27,128.65,
55.29,128.40,
55.32,128.15,
55.34,127.90,
55.37,127.65,
55.39,127.40,
55.42,127.15,
55.44,126.90,
55.47,126.65,
55.49,126.40,
55.52,126.15,
55.54,125.90,
55.57,125.65,
55.59,125.40,
55.62,125.15,
55.64,124.90,
55.67,124.65,
55.69,124.40,
55.72,124.15,
55.74,123.90,
55.77,123.65,
55.79,123.40,
55.82,123.15,
55.84,122.90,
55.87,122.65,
55.89,122.40,
55.92,122.15,
55.94,121.90,
55.97,121.65,
55.99,121.40,
56.02,121.15,
56.04,120.90,
56.07,120.65,
56.09,120.40,
56.12,120.15,
56.14,119.90,
56.17,119.65,
56.19,119.40,
56.22,119.15,
56.24,118.90,
56.27,118.65,
56.29,118.40,
56.32,118.15,
56.34,117.90,
56.37,117.65,
56.39,117.40,
56.42,117.15,
56.44,116.90,
56.47,116.65,
56.49,116.40,
56.52,116.15,
56.54,115.90,
56.57,115.65,
56.59,115.40,
56.62,115.15,
56.64,114.90,
56.67,114.65,
56.69,114.40,
56.72,114.15,
56.74,113.90,
56.77,113.65,
56.79,113.40,
56.82,113.15,
56.84,112.90,
56.87,112.65,
56.89,112.40,
56.92,112.15,
56.94,111.90,
56.97,111.65,
56.99,111.40,
57.02,111.15,
57.04,110.90,
57.07,110.65,
57.09,110.40,
57.12,110.15,
57.14,109.90,
57.17,109.65,
57.19,109.40,
57.22,109.15,
57.24,108.90,
57.27,108.65,
57.29,108.40,
57.32,108.15,
57.34,107.90,
57.37,107.65,
57.39,107.40,
57.42,107.15,
57.44,106.90,
57.47,106.65,
57.49,106.40,
57.52,106.15,
57.54,105.90,
57.57,105.65,
57.59,105.40,
57.62,105.15,
57.64,104.90,
57.67,104.65,
57.69,104.40,
57.72,104.15,
57.74,103.90,
57.77,103.65,
57.79,103.40,
57.82,103.15,
57.84,102.90,
57.87,102.65,
57.89,102.40,
57.92,102.15,
57.94,101.90,
57.97,101.65,
57.99,101.40,
58.02,101.15,
58.04,100.90,
58.07,100.65,
58.09,100.40,
58.12,100.15,
58.14,99.90,
58.17,99.65,
58.19,99.40,
58.22,99.15,
58.24,98.90,
58.27,98.65,
58.29,98.40,
58.32,98.15,
58.34,97.91,
58.37,97.66,
58.39,97.40,
58.42,97.15,
58.44,96.90,
58.47,96.66,
58.49,96.40,
58.52,96.16,
58.54,95.91,
58.57,95.66,
58.59,95.41,
58.62,95.16,
58.64,94.91,
58.67,94.66,
58.69,94.41,
58.72,94.16,
58.74,93.91,
58.77,93.66,
58.79,93.41,
58.82,93.16,
58.84,92.91,
58.87,92.66,
58.89,92.41,
58.92,92.16,
58.94,91.91,
58.97,91.66,
58.99,91.41,
59.02,91.16,
59.04,90.91,
59.07,90.66,
59.09,90.41,
59.12,90.16,
59.14,89.91,
59.17,89.66,
59.19,89.41,
59.22,89.16,
59.24,88.91,
59.27,88.66,
59.29,88.41,
59.32,88.16,
59.34,87.91,
59.37,87.66,
59.39,87.41,
59.42,87.16,
59.44,86.91,
59.47,86.66,
59.49,86.41,
59.52,86.16,
59.54,85.91,
59.57,85.66,
59.59,85.41,
59.62,85.16,
59.64,84.91,
59.67,84.66,
59.69,84.41,
59.72,84.16,
59.74,83.91,
59.77,83.66,
59.79,83.41,
59.82,83.16,
59.84,82.91,
59.87,82.66,
59.89,82.41,
59.92,82.16,
59.94,81.91,
59.97,81.66,
59.99,81.41,
60.02,81.16,
60.04,80.91,
60.07,80.66,
60.09,80.41,
60.12,80.16,
60.14,79.91,
60.17,79.66,
60.19,79.41,
60.22,79.16,
60.24,78.91,
60.27,78.66,
60.29,78.41,
60.32,78.16,
60.34,77.91,
60.37,77.66,
60.39,77.41,
60.42,77.16,
60.44,76.91,
60.47,76.66,
60.49,76.41,
60.52,76.16,
60.54,75.91,
60.57,75.66,
60.59,75.41,
60.62,75.16,
60.64,74.91,
60.67,74.66,
60.69,74.41,
60.72,74.16,
60.74,73.91,
60.77,73.66,
60.79,73.41,
60.82,73.16,
60.84,72.91,
60.87,72.66,
60.89,72.41,
60.92,72.16,
60.94,71.91,
60.97,71.66,
60.99,71.41,
61.02,71.16,
61.04,70.91,
61.07,70.66,
61.09,70.41,
61.12,70.16,
61.14,69.91,
61.17,69.66,
61.19,69.41,
61.22,69.16,
61.24,68.91,
61.27,68.66,
61.29,68.41,
61.32,68.16,
61.34,67.91,
61.37,67.66,
61.39,67.41,
61.42,67.16,
61.44,66.91,
61.47,66.66,
61.49,66.41,
61.52,66.16,
61.54,65.91,
61.57,65.66,
61.59,65.41,
61.62,65.16,
61.64,64.91,
61.67,64.66,
61.69,64.41,
61.72,64.16,
61.74,63.91,
61.77,63.66,
61.79,63.41,
61.82,63.16,
61.84,62.91,
61.87,62.66,
61.89,62.41,
61.92,62.16,
61.94,61.91,
61.97,61.66,
61.99,61.41,
62.02,61.16,
62.04,60.91,
62.07,60.66,
62.09,60.41,
62.12,60.16,
62.14,59.92,
62.17,59.67,
62.19,59.42,
62.22,59.17,
62.24,58.92,
62.27,58.67,
62.29,58.42,
62.32,58.17,
62.34,57.92,
62.37,57.67,
62.39,57.42,
62.42,57.17,
62.44,56.92,
62.47,56.67,
62.49,56.41,
62.52,56.17,
62.54,55.92,
62.57,55.67,
62.59,55.42,
62.62,55.17,
62.64,54.92,
62.67,54.67,
62.69,54.42,
62.72,54.17,
62.74,53.92,
62.77,53.67,
62.79,53.42,
62.82,53.17,
62.84,52.92,
62.87,52.67,
62.89,52.42,
62.92,52.17,
62.94,51.92,
62.97,51.67,
62.99,51.42,
63.02,51.17,
63.04,50.91,
63.07,50.66,
63.09,50.41,
63.12,50.16,
63.14,49.91,
63.17,49.66,
63.19,49.42,
63.22,49.17,
63.24,48.91,
63.27,48.67,
63.29,48.42,
63.32,48.17,
63.34,47.92,
63.37,47.67,
63.39,47.42,
63.42,47.17,
63.44,46.92,
63.47,46.67,
63.49,46.42,
63.52,46.17,
63.54,45.92,
63.57,45.67,
63.59,45.42,
63.62,45.17,
63.64,44.92,
63.67,44.67,
63.69,44.42,
63.72,44.17,
63.74,43.92,
63.77,43.67,
63.79,43.42,
63.82,43.17,
63.84,42.92,
63.87,42.67,
63.89,42.42,
63.92,42.17,
63.94,41.92,
63.97,41.67,
63.99,41.42,
64.02,41.17,
64.04,40.92,
64.07,40.67,
[...]
164.00,58.84,,0.009
164.02,59.09,,0.009
164.05,59.34,,0.009
164.07,59.59,,0.009
164.10,59.84,,0.009
164.12,60.09,,0.009
164.15,60.34,,0.009
164.17,60.59,,0.009
164.20,60.84,,0.009
164.22,61.09,,0.009
164.25,61.34,,0.009
164.27,61.59,,0.009
164.30,61.84,,0.009
164.32,62.09,,0.009
164.35,62.34,,0.009
164.37,62.59,,0.009
164.40,62.84,,0.009
164.42,63.09,,0.008
164.45,63.34,,0.008
164.47,63.59,,0.008
164.50,63.84,,0.008
164.52,64.09,,0.008
164.55,64.34,,0.008
164.57,64.60,,0.008
164.60,64.84,,0.008
164.62,65.10,,0.008
164.65,65.35,,0.008
164.67,65.60,,0.007
164.70,65.85,,0.007
164.72,66.10,,0.007
164.75,66.35,,0.007
164.77,66.60,,0.007
164.80,66.85,,0.007
164.82,67.10,,0.007
164.85,67.35,,0.007
164.87,67.60,,0.008
164.90,67.85,,0.008
164.92,68.10,,0.008
164.95,68.35,,0.008
164.97,68.60,,0.008
165.00,68.85,,0.008
165.02,69.10,,0.008
165.05,69.35,,0.008
165.07,69.60,,0.007
165.10,69.85,,0.007
165.12,70.10,,0.007
165.15,70.35,,0.007
165.17,70.60,,0.007
165.20,70.85,,0.007
165.22,71.10,,0.007
165.25,71.35,,0.007
165.27,71.60,,0.007
165.30,71.85,,0.007
165.32,72.10,,0.007
165.35,72.35,,0.007
165.37,72.60,,0.007
165.40,72.85,,0.007
165.42,73.10,,0.007
165.45,73.35,,0.007
165.47,73.60,,0.007
165.50,73.85,,0.007
165.52,74.10,,0.007
165.55,74.35,,0.007
165.57,74.60,,0.007
165.60,74.86,,0.007
165.62,75.11,,0.007
165.65,75.36,,0.007
165.67,75.61,,0.007
165.70,75.86,,0.007
165.72,76.11,,0.007
165.75,76.36,,0.007
165.77,76.61,,0.007
165.80,76.86,,0.006
165.82,77.11,,0.006
165.85,77.36,,0.007
165.87,77.61,,0.006
165.90,77.86,,0.007
165.92,78.11,,0.007
165.95,78.36,,0.006
165.97,78.61,,0.006
166.00,78.86,,0.006
166.02,79.11,,0.006
166.05,79.36,,0.006
166.07,79.61,,0.006
166.10,79.86,,0.006
166.12,80.11,,0.006
166.15,80.36,,0.006
166.17,80.61,,0.006
166.20,80.86,,0.006
166.22,81.11,,0.006
166.25,81.36,,0.006
166.27,81.61,,0.006
166.30,81.86,,0.006
166.32,82.11,,0.006
166.35,82.36,,0.006
166.37,82.61,,0.006
166.40,82.86,,0.006
166.42,83.11,,0.006
166.45,83.36,,0.005
166.47,83.62,,0.005
166.50,83.87,,0.005
166.52,84.12,,0.005
166.55,84.37,,0.005
166.57,84.62,,0.005
166.60,84.87,,0.005
166.62,85.12,,0.004
166.65,85.37,,0.004
166.67,85.62,,0.004
166.70,85.87,,0.004
166.72,86.12,,0.004
166.75,86.37,,0.004
166.77,86.62,,0.004
166.80,86.87,,0.003
166.82,87.12,,0.003
166.85,87.37,,0.003
166.87,87.62,,0.003
166.90,87.87,,0.003
166.92,88.12,,0.003
166.95,88.37,,0.003
166.97,88.62,,0.003
167.00,88.87,,0.003
167.02,89.12,,0.003
167.05,89.37,,0.003
167.07,89.62,,0.003
167.10,89.87,,0.003
167.12,90.12,,0.003
167.15,90.37,,0.003
167.17,90.62,,0.004
167.20,90.87,,0.004
167.22,91.12,,0.004
167.25,91.37,,0.004
167.27,91.62,,0.004
167.30,91.87,,0.004
167.32,92.12,,0.004
167.35,92.37,,0.004
167.37,92.62,,0.004
167.40,92.87,,0.004
167.42,93.12,,0.004
167.45,93.37,,0.004
167.47,93.62,,0.004
167.50,93.87,,0.004
167.52,94.12,,0.004
167.55,94.37,,0.004
167.57,94.62,,0.004
167.60,94.87,,0.004
167.62,95.12,,0.004
167.65,95.37,,0.004
167.67,95.62,,0.004
167.70,95.88,,0.004
167.72,96.12,,0.004
167.75,96.38,,0.004
167.77,96.63,,0.004
167.80,96.88,,0.004
167.82,97.13,,0.004
167.85,97.38,,0.004
167.87,97.63,,0.004
167.90,97.88,,0.004
167.92,98.13,,0.003
167.95,98.38,,0.003
167.97,98.63,,0.003
168.00,98.88,,0.003
168.02,99.13,,0.004
168.05,99.38,,0.003
168.07,99.63,,0.004
168.10,99.88,,0.004
168.12,100.13,,0.004
168.15,100.38,,0.004
168.17,100.63,,0.004
168.20,100.88,,0.004
168.22,101.13,,0.004
168.25,101.38,,0.004
168.27,101.63,,0.004
168.30,101.88,,0.004
168.32,102.13,,0.004
168.35,102.38,,0.004
168.37,102.63,,0.004
168.40,102.88,,0.004
168.42,103.13,,0.004
168.45,103.38,,0.004
168.47,103.63,,0.004
168.50,103.88,,0.004
168.52,104.13,,0.004
168.55,104.38,,0.004
168.57,104.63,,0.004
168.60,104.88,,0.004
168.62,105.13,,0.004
168.65,105.38,,0.004
168.67,105.63,,0.004
168.70,105.88,,0.004
168.72,106.13,,0.004
168.75,106.38,,0.004
168.77,106.64,,0.004
168.80,106.89,,0.004
168.82,107.14,,0.004
168.85,107.39,,0.004
168.87,107.64,,0.004
168.90,107.89,,0.004
168.92,108.14,,0.004
168.95,108.39,,0.003
168.97,108.64,,0.004
169.00,108.89,,0.003
169.02,109.14,,0.003
169.05,109.39,,0.003
169.07,109.64,,0.003
169.10,109.89,,0.003
169.12,110.14,,0.003
169.15,110.39,,0.003
169.17,110.64,,0.003
169.20,110.89,,0.003
169.22,111.14,,0.003
169.25,111.39,,0.003
169.27,111.64,,0.003
169.30,111.89,,0.002
169.32,112.14,,0.002
169.35,112.39,,0.003
169.37,112.64,,0.003
169.40,112.89,,0.002
169.42,113.14,,0.002
169.45,113.39,,0.002
169.47,113.64,,0.002
169.50,113.89,,0.002
169.52,114.14,,0.002
169.55,114.39,,0.002
169.57,114.64,,0.002
169.60,114.89,,0.002
169.62,115.14,,0.003
169.65,115.39,,0.003
169.67,115.64,,0.002
169.70,115.89,,0.002
169.72,116.14,,0.002
169.75,116.39,,0.002
169.77,116.64,,0.002
169.80,116.89,,0.002
169.82,117.14,,0.002
169.85,117.39,,0.003
169.87,117.64,,0.002
169.90,117.89,,0.002
169.92,118.14,,0.002
169.95,118.39,,0.002
169.97,118.64,,0.002
170.00,118.89,,0.002
170.02,119.14,,0.002
170.05,119.39,,0.003
170.07,119.64,,0.003
170.10,119.89,,0.003
170.12,120.14,,0.003
170.15,120.39,,0.002
170.17,120.64,,0.002
170.20,120.89,,0.003
170.22,121.15,,0.003
170.25,121.40,,0.003
170.27,121.65,,0.003
170.30,121.90,,0.003
170.32,122.15,,0.003
170.35,122.40,,0.003
170.37,122.65,,0.003
170.40,122.90,,0.003
170.42,123.15,,0.002
170.45,123.40,,0.002
170.47,123.65,,0.002
170.50,123.90,,0.003
170.52,124.15,,0.002
170.55,124.40,,0.002
170.57,124.65,,0.002
170.60,124.90,,0.002
170.62,125.15,,0.002
170.65,125.40,,0.003
170.67,125.65,,0.003
170.70,125.90,,0.003
170.72,126.15,,0.003
170.75,126.40,,0.003
170.77,126.65,,0.003
170.80,126.90,,0.003
170.82,127.15,,0.003
170.85,127.40,,0.003
170.87,127.65,,0.002
170.90,127.90,,0.002
170.92,128.15,,0.002
170.95,128.40,,0.002
170.97,128.65,,0.002
171.00,128.90,,0.002
171.02,129.15,,0.002
171.05,129.40,,0.002
171.07,129.65,,0.002
171.10,129.90,,0.002
171.12,130.15,,0.002
171.15,130.40,,0.002
171.17,130.65,,0.002
171.20,130.90,,0.002
171.22,131.15,,0.002
171.25,131.40,,0.002
171.27,131.65,,0.002
171.30,131.90,,0.002
171.32,132.15,,0.002
171.35,132.40,,0.002
171.37,132.65,,0.003
171.40,132.90,,0.003
171.42,133.15,,0.003
171.45,133.41,,0.003
171.47,133.65,,0.003
171.50,133.91,,0.003
171.52,134.16,,0.003
171.55,134.41,,0.003
171.57,134.66,,0.003
171.60,134.91,,0.004
171.62,135.16,,0.003
171.65,135.41,,0.004
171.67,135.66,,0.004
171.70,135.91,,0.004
171.72,136.16,,0.004
171.75,136.41,,0.004
171.77,136.66,,0.003
171.80,136.91,,0.003
171.82,137.16,,0.003
171.85,137.41,,0.003
171.87,137.66,,0.003
171.90,137.91,,0.003
171.92,138.16,,0.003
171.95,138.41,,0.003
171.97,138.66,,0.003
172.00,138.91,,0.003
172.02,139.16,,0.003
172.05,139.41,,0.003
172.07,139.66,,0.003
172.10,139.91,,0.003
172.12,140.16,,0.003
172.15,140.41,,0.003
172.17,140.66,,0.003
172.20,140.91,,0.003
172.22,141.16,,0.003
172.25,141.41,,0.003
172.27,141.66,,0.003
172.30,141.91,,0.003
172.32,142.16,,0.003
172.35,142.41,,0.003
172.37,142.66,,0.003
172.40,142.91,,0.003
172.42,143.16,,0.003
172.45,143.41,,0.003
172.47,143.66,,0.003
172.50,143.91,,0.003
172.52,144.16,,0.003
172.55,144.41,,0.003
172.57,144.66,,0.003
172.60,144.91,,0.003
172.62,145.16,,0.003
172.65,145.42,,0.003
172.67,145.67,,0.003
172.70,145.92,,0.003
172.72,146.17,,0.002
172.75,146.42,,0.002
172.77,146.67,,0.002
172.80,146.91,,0.002
172.82,147.17,,0.002
172.85,147.42,,0.002
172.87,147.67,,0.002
172.90,147.91,,0.002
172.92,148.17,,0.002
172.95,148.41,,0.002
172.97,148.67,,0.002
173.00,148.92,,0.002
173.02,149.17,,0.002
173.05,149.42,,0.003
173.07,149.67,,0.003
173.10,149.92,,0.003
173.12,150.17,,0.003
173.15,150.42,,0.003
173.17,150.67,,0.003
173.20,150.92,,0.003
173.22,151.17,,0.003
173.25,151.42,,0.003
173.27,151.67,,0.003
173.30,151.92,,0.002
173.32,152.17,,0.002
173.35,152.42,,0.002
173.37,152.67,,0.002
173.40,152.92,,0.002
173.42,153.17,,0.002
173.45,153.42,,0.002
173.47,153.67,,0.003
173.50,153.92,,0.003
173.52,154.17,,0.003
173.55,154.42,,0.003
173.57,154.67,,0.003
173.60,154.92,,0.003
173.62,155.17,,0.003
173.65,155.42,,0.003
173.67,155.67,,0.003
173.70,155.92,,0.003
173.72,156.17,,0.003
173.75,156.42,,0.003
173.77,156.67,,0.003
173.80,156.92,,0.003
173.82,157.17,,0.003
173.85,157.42,,0.003
173.87,157.67,,0.002
173.90,157.92,,0.002
173.92,158.17,,0.002
173.95,158.42,,0.002
173.97,158.67,,0.002
174.00,158.92,,0.002
174.02,159.17,,0.002
174.05,159.42,,0.002
174.07,159.67,,0.002
174.10,159.92,,0.002
174.12,160.17,,0.002
174.15,160.43,,0.002
174.17,160.68,,0.002
174.20,160.93,,0.002
174.22,161.18,,0.002
174.25,161.43,,0.002
174.27,161.68,,0.002
174.30,161.93,,0.002
174.32,162.18,,0.002
174.35,162.43,,0.002
174.37,162.68,,0.002
174.40,162.93,,0.001
174.42,163.18,,0.001
174.45,163.43,,0.001
174.47,163.68,,0.001
174.50,163.93,,0.002
174.52,164.18,,0.002
174.55,164.43,,0.002
174.57,164.68,,0.001
174.60,164.93,,0.001
174.62,165.18,,0.001
174.65,165.43,,0.001
174.67,165.68,,0.001
174.70,165.93,,0.001
174.72,166.18,,0.001
174.75,166.43,,0.001
174.77,166.68,,0.001
174.80,166.93,,0.001
174.82,167.18,,0.001
174.85,167.43,,0.001
174.87,167.68,,0.001
174.90,167.93,,0.001
174.92,168.18,,0.001
174.95,168.43,,0.001
174.97,168.68,,0.001
175.00,168.93,,0.002
175.02,169.18,,0.002
175.05,169.43,,0.002
175.07,169.68,,0.002
175.10,169.93,,0.002
175.12,170.18,,0.002
175.15,170.43,,0.002
175.17,170.68,,0.002
175.20,170.93,,0.002
175.22,171.18,,0.002
175.25,171.43,,0.002
175.27,171.68,,0.002
175.30,171.93,,0.003
175.32,172.18,,0.003
175.35,172.43,,0.003
175.37,172.68,,0.003
175.40,172.93,,0.003
175.42,173.18,,0.003
175.45,173.43,,0.003
175.47,173.68,,0.003
175.50,173.93,,0.003
175.52,174.18,,0.003
175.55,174.43,,0.003
175.57,174.68,,0.003
175.60,174.93,,0.002
175.62,175.18,,0.002
175.65,175.44,,0.002
175.67,175.69,,0.002
175.70,175.94,,0.002
175.72,176.19,,0.002
175.75,176.44,,0.002
175.77,176.69,,0.002
175.80,176.94,,0.002
175.82,177.19,,0.002
175.85,177.44,,0.002
175.87,177.69,,0.002
175.90,177.94,,0.002
175.92,178.19,,0.002
175.95,178.44,,0.002
175.97,178.69,,0.002
176.00,178.94,,0.002
176.02,179.19,,0.002
176.05,179.44,,0.002
176.07,179.69,,0.002
176.10,179.94,,0.002
176.12,180.19,,0.002
176.15,180.44,,0.001
176.17,180.69,,0.001
176.20,180.94,,0.001
176.22,181.19,,0.001
176.25,181.44,,0.001
176.27,181.69,,0.001
176.30,181.94,,0.001
176.32,182.19,,0.001
176.35,182.44,,0.001
176.37,182.69,,0.001
176.40,182.94,,0.001
176.42,183.19,,0.002
176.45,183.44,,0.002
176.47,183.69,,0.002
176.50,183.94,,0.002
176.52,184.19,,0.002
176.55,184.44,,0.002
176.57,184.69,,0.002
176.60,184.94,,0.003
176.62,185.19,,0.003
176.65,185.44,,0.003
176.67,185.69,,0.003
176.70,185.94,,0.003
176.72,186.19,,0.003
176.75,186.44,,0.004
176.77,186.69,,0.004
176.80,186.94,,0.004
176.82,187.19,,0.004
176.85,187.44,,0.004
176.87,187.69,,0.004
176.90,187.94,,0.004
176.92,188.19,,0.004
176.95,188.44,,0.004
176.97,188.69,,0.004
177.00,188.94,,0.004
177.02,189.19,,0.004
177.05,189.44,,0.004
177.07,189.69,,0.005
177.10,189.95,,0.004
177.12,190.20,,0.004
177.15,190.44,,0.005
177.17,190.69,,0.004
177.20,190.95,,0.004
177.22,191.20,,0.004
177.25,191.45,,0.004
177.27,191.70,,0.004
177.30,191.95,,0.004
177.32,192.20,,0.004
177.35,192.45,,0.004
177.37,192.70,,0.004
177.40,192.95,,0.004
177.42,193.20,,0.004
177.45,193.45,,0.004
177.47,193.70,,0.004
177.50,193.95,,0.004
177.52,194.20,,0.005
177.55,194.45,,0.005
177.57,194.70,,0.005
177.60,194.95,,0.005
177.62,195.20,,0.006
177.65,195.45,,0.006
177.67,195.70,,0.006
177.70,195.95,,0.006
177.72,196.20,,0.006
177.75,196.45,,0.006
177.77,196.70,,0.006
177.80,196.95,,0.006
177.82,197.20,,0.006
177.85,197.45,,0.007
177.87,197.70,,0.007
177.90,197.95,,0.007
177.92,198.20,,0.007
177.95,198.45,,0.007
177.97,198.70,,0.007
178.00,198.95,,0.008
178.02,199.20,,0.008
178.05,199.45,,0.008
178.07,199.70,,0.008
178.10,199.95,,0.008
178.12,200.20,,0.008
178.15,200.45,,0.009
178.17,200.70,,0.009
178.20,200.95,,0.009
178.22,201.20,,0.009
178.25,201.45,,0.009
178.27,201.70,,0.009
178.30,201.95,,0.010
178.32,202.20,,0.009
178.35,202.45,,0.010
178.37,202.70,,0.010
178.40,202.95,,0.009
178.42,203.20,,0.009
178.45,203.45,,0.009
178.47,203.70,,0.009
178.50,203.95,,0.009
178.52,204.20,,0.009
178.55,204.45,,0.009
178.57,204.70,,0.009
178.60,204.95,,0.009
178.62,205.20,,0.010
178.65,205.46,,0.010
178.67,205.71,,0.010
178.70,205.96,,0.010
178.72,206.21,,0.009
178.75,206.46,,0.009
178.77,206.71,,0.009
178.80,206.96,,0.009
178.82,207.21,,0.009
178.85,207.46,,0.008
178.87,207.71,,0.008
178.90,207.96,,0.008
178.92,208.21,,0.008
178.95,208.46,,0.008
178.97,208.71,,0.008
179.00,208.96,,0.008
179.02,209.21,,0.008
179.05,209.46,,0.008
179.07,209.71,,0.008
179.10,209.96,,0.008
179.12,210.21,,0.008
179.15,210.46,,0.008
179.17,210.70,,0.008
179.20,210.96,,0.008
179.22,211.21,,0.008
179.25,211.46,,0.008
179.27,211.71,,0.008
179.30,211.96,,0.008
179.32,212.21,,0.009
179.35,212.46,,0.009
179.37,212.71,,0.009
179.40,212.96,,0.009
179.42,213.21,,0.009
179.45,213.46,,0.009
179.47,213.71,,0.009
179.50,213.96,,0.010
179.52,214.21,,0.010
179.55,214.46,,0.010
179.57,214.71,,0.010
179.60,214.96,,0.010
179.62,215.21,,0.010
179.65,215.46,,0.010
179.67,215.71,,0.010
179.70,215.96,,0.010
179.72,216.21,,0.010
179.75,216.46,,0.010
179.77,216.71,,0.010
179.80,216.96,,0.011
179.82,217.21,,0.011
179.85,217.46,,0.011
179.87,217.71,,0.011
179.90,217.96,,0.011
179.92,218.21,,0.012
179.95,218.46,,0.012
179.97,218.71,,0.012
180.00,218.96,,0.012
180.02,219.21,,0.012
180.05,219.46,,0.012
180.07,219.71,,0.012
180.10,219.96,,0.012
180.12,220.21,,0.012
180.15,220.46,,0.012
180.17,220.71,,0.012
180.20,220.96,,0.013
180.22,221.21,,0.013
180.25,221.46,,0.013
180.27,221.71,,0.013
180.30,221.97,,0.013
180.32,222.21,,0.013
180.35,222.46,,0.013
180.37,222.71,,0.014
180.40,222.96,,0.014
180.42,223.21,,0.014
180.45,223.46,,0.014
180.47,223.71,,0.014
180.50,223.96,,0.014
180.52,224.22,,0.015
180.55,224.46,,0.015
180.57,224.72,,0.015
180.60,224.97,,0.015
180.62,225.22,,0.015
180.65,225.47,,0.015
180.67,225.72,,0.015
180.70,225.97,,0.015
180.72,226.22,,0.015
180.75,226.47,,0.015
180.77,226.72,,0.015
180.80,226.97,,0.015
180.82,227.22,,0.015
180.85,227.47,,0.015
180.87,227.72,,0.015
180.90,227.97,,0.015
180.92,228.22,,0.016
180.95,228.47,,0.015
180.97,228.72,,0.015
181.00,228.97,,0.015
181.02,229.22,,0.016
181.05,229.47,,0.016
181.07,229.72,,0.016
181.10,229.97,,0.016
181.12,230.22,,0.016
181.15,230.47,,0.016
181.17,230.72,,0.016
181.20,230.97,,0.016
181.22,231.22,,0.016
181.25,231.47,,0.016
181.27,231.72,,0.017
181.30,231.97,,0.017
181.32,232.22,,0.016
181.35,232.47,,0.016
181.37,232.72,,0.016
181.40,232.97,,0.016
181.42,233.22,,0.016
181.45,233.47,,0.016
181.47,233.72,,0.016
181.50,233.97,,0.016
181.52,234.22,,0.016
181.55,234.47,,0.016
181.57,234.72,,0.016
181.60,234.97,,0.016
181.62,235.22,,0.016
181.65,235.47,,0.016
181.67,235.72,,0.016
181.70,235.97,,0.016
181.72,236.22,,0.016
181.75,236.47,,0.016
181.77,236.72,,0.016
181.80,236.97,,0.016
181.82,237.22,,0.016
181.85,237.47,,0.016
181.87,237.72,,0.016
181.90,237.97,,0.016
181.92,238.22,,0.016
181.95,238.47,,0.016
181.97,238.72,,0.016
182.00,238.97,,0.015
182.02,239.22,,0.016
182.05,239.47,,0.016
182.07,239.72,,0.016
182.10,239.97,,0.016
182.12,240.22,,0.016
182.15,240.47,,0.016
182.17,240.72,,0.016
182.20,240.97,,0.016
182.22,241.22,,0.016
182.25,241.48,,0.016
182.27,241.73,,0.016
182.30,241.98,,0.017
182.32,242.22,,0.017
182.35,242.48,,0.017
182.37,242.73,,0.017
182.40,242.98,,0.017
182.42,243.23,,0.017
182.45,243.48,,0.017
182.47,243.73,,0.017
182.50,243.98,,0.017
182.52,244.23,,0.017
182.55,244.48,,0.017
182.57,244.73,,0.017
182.60,244.98,,0.017
182.62,245.23,,0.017
182.65,245.48,,0.017
182.67,245.73,,0.016
182.70,245.98,,0.016
182.72,246.23,,0.016
182.75,246.48,,0.016
182.77,246.73,,0.017
182.80,246.98,,0.017
182.82,247.23,,0.017
182.85,247.48,,0.017
182.87,247.73,,0.017
182.90,247.98,,0.017
182.92,248.23,,0.017
182.95,248.48,,0.018
182.97,248.73,,0.018
183.00,248.98,,0.018
183.02,249.23,,0.017
183.05,249.48,,0.017
183.07,249.73,,0.017
183.10,249.98,,0.018
183.12,250.23,,0.017
183.15,250.48,,0.018
183.17,250.73,,0.018
183.20,250.98,,0.018
183.22,251.23,,0.018
183.25,251.48,,0.017
183.27,251.73,,0.017
183.30,251.98,,0.018
183.32,252.23,,0.018
183.35,252.48,,0.018
183.37,252.73,,0.018
183.40,252.98,,0.018
183.42,253.23,,0.018
183.45,253.48,,0.018
183.47,253.73,,0.018
183.50,253.98,,0.018
183.52,254.23,,0.018
183.55,254.48,,0.018
183.57,254.73,,0.018
183.60,254.98,,0.018
183.62,255.23,,0.018
183.65,255.48,,0.018
183.67,255.73,,0.018
183.70,255.98,,0.018
183.72,256.23,,0.018
183.75,256.48,,0.018
183.77,256.73,,0.018
183.80,256.98,,0.018
183.82,257.23,,0.019
183.85,257.48,,0.019
183.87,257.73,,0.019
183.90,257.98,,0.019
183.92,258.23,,0.019
183.95,258.48,,0.018
183.97,258.73,,0.019
184.00,258.98,,0.019
184.02,259.23,,0.019
184.05,259.48,,0.019
184.07,259.73,,0.019
184.10,259.98,,0.019
184.12,260.23,,0.019
184.15,260.48,,0.019
184.17,260.73,,0.019
184.20,260.98,,0.019
184.22,261.23,,0.019
184.25,261.48,,0.019
184.27,261.73,,0.019
184.30,261.98,,0.019
184.32,262.23,,0.019
184.35,262.49,,0.019
184.37,262.74,,0.019
184.40,262.98,,0.019
184.42,263.24,,0.019
184.45,263.49,,0.019
184.47,263.73,,0.019
184.50,263.98,,0.019
184.52,264.23,,0.019
184.55,264.48,,0.019
184.57,264.74,,0.020
184.60,264.99,,0.020
184.62,265.24,,0.020
184.65,265.49,,0.020
184.67,265.74,,0.021
184.70,265.99,,0.021
184.72,266.24,,0.021
184.75,266.49,,0.020
184.77,266.74,,0.021
184.80,266.99,,0.021
184.82,267.24,,0.020
184.85,267.49,,0.020
184.87,267.74,,0.020
184.90,267.99,,0.020
184.92,268.24,,0.020
184.95,268.49,,0.020
184.97,268.74,,0.019
185.00,268.99,,0.019
185.02,269.24,,0.019
185.05,269.49,,0.019
185.07,269.74,,0.019
185.10,269.99,,0.019
185.12,270.24,,0.019
185.15,270.49,,0.019
185.17,270.74,,0.019
185.20,270.99,,0.019
185.22,271.24,,0.019
185.25,271.49,,0.020
185.27,271.74,,0.020
185.30,271.99,,0.020
185.32,272.24,,0.020
185.35,272.49,,0.020
185.37,272.74,,0.020
185.40,272.99,,0.020
185.42,273.24,,0.020
185.45,273.49,,0.020
185.47,273.74,,0.020
185.50,273.99,,0.020
185.52,274.24,,0.020
185.55,274.49,,0.020
185.57,274.74,,0.020
185.60,274.99,,0.020
185.62,275.24,,0.020
185.65,275.49,,0.020
185.67,275.74,,0.020
185.70,275.99,,0.020
185.72,276.24,,0.020
185.75,276.49,,0.020
185.77,276.74,,0.020
185.80,276.99,,0.020
185.82,277.24,,0.020
185.85,277.49,,0.020
185.87,277.74,,0.020
185.90,277.99,,0.020
185.92,278.24,,0.020
185.95,278.49,,0.020
185.97,278.74,,0.020
186.00,278.99,,0.020
186.02,279.24,,0.020
186.05,279.49,,0.020
186.07,279.74,,0.020
186.10,279.99,,0.020
186.12,280.24,,0.020
186.15,280.49,,0.020
186.17,280.74,,0.020
186.20,280.99,,0.020
186.22,281.24,,0.020
186.25,281.49,,0.020
186.27,281.74,,0.021
186.30,281.99,,0.021
186.32,282.24,,0.021
186.35,282.49,,0.021
186.37,282.74,,0.021
186.40,282.99,,0.021
186.42,283.24,,0.021
186.45,283.49,,0.021
186.47,283.74,,0.021
186.50,283.99,,0.022
186.52,284.24,,0.021
186.55,284.49,,0.022
186.57,284.74,,0.022
186.60,284.99,,0.022
186.62,285.24,,0.022
186.65,285.49,,0.022
186.67,285.74,,0.022
186.70,285.99,,0.022
186.72,286.25,,0.022
186.75,286.50,,0.021
186.77,286.75,,0.021
186.80,287.00,,0.021
186.82,287.24,,0.021
186.85,287.49,,0.021
186.87,287.74,,0.021
186.90,287.99,,0.022
186.92,288.25,,0.022
186.95,288.49,,0.022
186.97,288.75,,0.022
187.00,289.00,,0.022
187.02,289.25,,0.022
187.05,289.50,,0.022
187.07,289.75,,0.022
187.10,289.99,,0.022
187.12,290.24,,0.022
187.15,290.50,,0.022
187.17,290.75,,0.022
187.20,291.00,,0.022
187.22,291.25,,0.022
187.25,291.50,,0.022
187.27,291.75,,0.022
187.30,292.00,,0.021
187.32,292.25,,0.021
187.35,292.50,,0.021
187.37,292.75,,0.021
187.40,293.00,,0.021
187.42,293.25,,0.021
187.45,293.50,,0.021
187.47,293.75,,0.021
187.50,294.00,,0.021
187.52,294.25,,0.021
187.55,294.50,,0.021
187.57,294.75,,0.020
187.60,295.00,,0.021
187.62,295.25,,0.020
187.65,295.50,,0.020
187.67,295.75,,0.020
187.70,296.00,,0.020
187.72,296.25,,0.020
187.75,296.50,,0.020
187.77,296.75,,0.021
187.80,297.00,,0.020
187.82,297.25,,0.020
187.85,297.50,,0.020
187.87,297.75,,0.020
187.90,298.00,,0.020
187.92,298.25,,0.021
187.95,298.50,,
187.97,298.75,,
187.99,,,