File: DSC/Olivia/2025_08_01_Indium_n60C_200C_10Cmin_x3.csv
Filename,2025_08_01_Indium_n60C_200C_10Cmin_x3
Instrument name,DSC2A-00468 (192.168.1.100)
Operator,Yarger
rundate,8/1/2025
Sample name,2025_08_01_Indium_n60C_200C_10Cmin_x3
proceduresegments,Data Off ; Equilibrate -60.00 °C; Data On ; Ramp 10.00 °C/min to 200.00 °C; Data Off ; Isothermal 2.0 min; Data On ; Ramp 10.00 °C/min to -60.00 °C; Data Off ; Isothermal 2.0 min; Data On ; Ramp 10.00 °C/min to 200.00 °C; Data Off ; Isothermal 2.0 min; Data On ; Ramp 10.00 °C/min to -60.00 °C; Data Off ; Isothermal 2.0 min; Data On ; Ramp 10.00 °C/min to 200.00 °C
[File Parameters]
Run date,8/1/2025 9:03:24 PM
Trios version,5.1.1.46572
Original File Name,
Current File Name,D:\DSC2500\Gibbons\2025_08_01_Indium_n60C_200C_10Cmin_x3.tri
[Procedure]
Procedure Name,Indium_n60C_200C_10Cmin_x3
Sample Name,2025_08_01_Indium_n60C_200C_10Cmin_x3
Sample Mass,8.83 mg
Reference Sample Mass,0 mg
Pan Mass,33 mg
Pan Number,45
Reference Pan Mass,32.52 mg
Reference Pan Number,37
Pan Type,Aluminum
Comments,Thermal support Al pans/lids. DSC_Samples_A2_Tray_July2025 google sheet.
Project Name,Pharma - Cocrystals
Operator,Yarger
Test,Custom
Unload Max Temperature,30
Unload Min Temperature,30
Load Max Temperature,30
Load Min Temperature,30
Stop on Gas Flow Error,Yes
[Signal List]
Signal #1,Time (min)
Signal #2,Temperature (°C)
Signal #3,Heat Flow (mW)
Signal #4,Delta T (µV)
Signal #5,Delta Tzero (µV)
Signal #6,Tzero Temperature (°C)
Signal #7,Cell Purge (mL/min)
Signal #8,Heater Temp (°C)
Signal #9,Power Delivered (W)
Signal #10,Reference Junction Temperature (°C)
Signal #11,Flange Temperature (°C)
Signal #12,Heat Flow Phase (rad)
Signal #13,Total Heat Capacity (J/°C)
Signal #14,Heat Capacity (J/°C)
[Configuration]
Company Name,ASU
Instrument Name,DSC2A-00468
Instrument Type,DSC2500
Serial Number,DSC2A-00468
IP,192.168.1.100
Location of Instrument,MRRC
DisplayType,Unknown
Sample Interval ,0.1 s/pt
Selected Heat Flow,T4P
Exotherm Direction,Down
Cell Serial,DRC2-00792
Lid Type,Standard
Cooler,RCS 90
Leave Cooler on at End of Sequence,On
Gas 2,Nitrogen
Gas Selected,Channel 1
Flow Rate,50 mL/min
Secondary Purge,On
Licensed Heat Flow,Heat Flow T4P
Modulation Licensed,Yes
[Versions]
Common IDD Version,1
Cortex Version,VER 2.10.2.31
Driver,5.0.0.6
GDM Version,1.0.3.3
TouchscreenVersion,1.0.0.16145
FEP Version,1.2.1.21
FEP Bootloader,2.0.0.5
AutoSampler Version,2.1.1.26
Auto Sampler Bootloader,2.0.0.5
FCM Version,1.1.0.3
FCM Bootloader,2.0.0.5
[Experiment Logs]
Experiment Log Entry # 2,Data On set to 0
Experiment Log Entry # 4,Equilibrate Segment -60 (C) Started
Experiment Log Entry # 6,Air Cool is off.
Experiment Log Entry # 8,Data On set to 1
Experiment Log Entry # 10,Ramp Segment 10 C/min to 200 Started
Experiment Log Entry # 12,Auto sampler has detected that FCM has gone offline
Experiment Log Entry # 14,Data On set to 0
Experiment Log Entry # 16,Isothermal Segment 2 min started
Experiment Log Entry # 18,Data On set to 1
Experiment Log Entry # 20,Ramp Segment 10 C/min to -60 Started
Experiment Log Entry # 22,Data On set to 0
Experiment Log Entry # 24,Isothermal Segment 2 min started
Experiment Log Entry # 26,Data On set to 1
Experiment Log Entry # 28,Ramp Segment 10 C/min to 200 Started
Experiment Log Entry # 30,Data On set to 0
Experiment Log Entry # 32,Isothermal Segment 2 min started
Experiment Log Entry # 34,Data On set to 1
Experiment Log Entry # 36,Ramp Segment 10 C/min to -60 Started
Experiment Log Entry # 38,Data On set to 0
Experiment Log Entry # 40,Isothermal Segment 2 min started
Experiment Log Entry # 42,Data On set to 1
Experiment Log Entry # 44,Ramp Segment 10 C/min to 200 Started
[Method Log]
Method Log Entry # 1,Data Off
Method Log Entry # 2,Equilibrate -60 °C
Method Log Entry # 3,Data On
Method Log Entry # 4,(Ramp 52955) Ramp 10 °C/minute to 200 °C
Method Log Entry # 5,Data Off
Method Log Entry # 6,Isothermal 2 minutes
Method Log Entry # 7,Data On
Method Log Entry # 8,(Ramp 52959) Ramp 10 °C/minute to -60 °C
Method Log Entry # 9,Data Off
Method Log Entry # 10,Isothermal 2 minutes
Method Log Entry # 11,Data On
Method Log Entry # 12,(Ramp 52963) Ramp 10 °C/minute to 200 °C
Method Log Entry # 13,Data Off
Method Log Entry # 14,Isothermal 2 minutes
Method Log Entry # 15,Data On
Method Log Entry # 16,(Ramp 52967) Ramp 10 °C/minute to -60 °C
Method Log Entry # 17,Data Off
Method Log Entry # 18,Isothermal 2 minutes
Method Log Entry # 19,Data On
Method Log Entry # 20,(Ramp 52971) Ramp 10 °C/minute to 200 °C
Cell Serial,DRC2-00792
[T1 Calibration]
Slope,-0.008529666
Offset,9.636258
Initial Temperature,98.23
GUID,f8bfdadc-4977-4fdf-ba6d-0ba9134940c3
[TZero Calibration]
Date Applied,11/29/2022 4:06:13 PM
Description,From -89.059 °C to 396.009 °C at 20.000°C/min
Gas Type,Nitrogen
Pan Type,None
Source Files 1,C:\Users\yargerlab\Desktop\DSC Data\General\TZero_calibration_11_29_22_2nd(2).tri
Source Files 2,C:\Users\yargerlab\Desktop\DSC Data\General\TZero_calibration_11_29_22_2nd(3).tri
Delta T Offset,13.05235
Delta T Slope,-0.007271007
Delta T0 Offset,-13.69128
Delta T0 Slope,0.06063341
[Temperature Calibration]
Date Applied,11/29/2022 7:12:28 PM
Description,From 106.590 °C to 186.590 °C at 10.000°C/min
Gas Type,Nitrogen
Pan Type,Tzero Aluminum Hermetic
Source Files 1,C:\Users\yargerlab\Desktop\DSC Data\General\Indium(6).tri
Measured 1,157.391
Known 1,156.598
[Cell Constant Calibration]
Date Applied,11/29/2022 7:12:29 PM
Description,From 106.590 °C to 186.590 °C at 10.000°C/min
Gas Type,Nitrogen
Pan Type,Tzero Aluminum Hermetic
Source Files 1,C:\Users\yargerlab\Desktop\DSC Data\General\Indium(6).tri
T4P KCell,1.006051
Onset Slope,63.26126 mW/°C
[Direct Cp Calibration]
Date Applied,11/30/2022 11:04:51 AM
Description,From -79.983 °C to 298.409 °C at 10.000°C/min
Gas Type,Nitrogen
Pan Type,Tzero Aluminum Hermetic
Source Files 1,C:\Users\yargerlab\Desktop\DSC Data\General\Sapphire_Heat_Capacity_11_30_22.tri
[Rev Cp Calibration]
Date Applied,11/30/2022 1:58:51 PM
Description,From -79.996 °C to 292.812 °C at 3.000°C/min
Gas Type,Nitrogen
Pan Type,Tzero Aluminum Hermetic
Source Files 1,C:\Users\yargerlab\Desktop\DSC Data\General\Sapphire_MDSC_Calibration_11_30_22.tri
[step]
Ramp 10.00 °C/min to 200.00 °C
Time,Temperature,Heat Flow (Normalized)
min,°C,W/g
0.00,-59.81,-0.021
0.02,-59.82,-0.020
0.04,-59.82,-0.018
0.05,-59.81,-0.019
0.07,-59.78,-0.033
0.09,-59.72,-0.044
0.11,-59.64,-0.052
0.13,-59.53,-0.055
0.15,-59.41,-0.052
0.16,-59.27,-0.047
0.18,-59.11,-0.034
0.20,-58.96,-0.024
0.22,-58.79,-0.013
0.24,-58.62,-0.004
0.26,-58.45,0.005
0.28,-58.28,0.011
0.29,-58.10,0.017
0.31,-57.93,0.020
0.33,-57.75,0.023
0.35,-57.57,0.026
0.37,-57.40,0.028
0.39,-57.22,0.030
0.40,-57.04,0.030
0.42,-56.86,0.031
0.44,-56.68,0.032
0.46,-56.50,0.032
0.48,-56.33,0.033
0.50,-56.15,0.033
0.51,-55.97,0.033
0.53,-55.79,0.033
0.55,-55.61,0.034
0.57,-55.43,0.034
0.59,-55.25,0.034
0.60,-55.07,0.034
0.62,-54.88,0.034
0.64,-54.70,0.035
0.66,-54.52,0.035
0.68,-54.34,0.035
0.70,-54.16,0.035
0.72,-53.98,0.035
0.73,-53.80,0.035
0.75,-53.62,0.036
0.77,-53.44,0.036
0.79,-53.25,0.036
0.81,-53.07,0.036
0.83,-52.89,0.036
0.84,-52.71,0.036
0.86,-52.53,0.036
0.88,-52.34,0.036
0.90,-52.16,0.037
0.92,-51.98,0.037
0.93,-51.80,0.037
0.95,-51.62,0.037
0.97,-51.43,0.037
0.99,-51.25,0.037
1.01,-51.07,0.037
1.03,-50.89,0.037
1.05,-50.70,0.037
1.06,-50.52,0.037
1.08,-50.34,0.037
1.10,-50.16,0.037
1.12,-49.97,0.037
1.14,-49.79,0.037
1.16,-49.61,0.037
1.17,-49.43,0.038
1.19,-49.24,0.038
1.21,-49.06,0.038
1.23,-48.88,0.038
1.25,-48.69,0.038
1.27,-48.51,0.038
1.28,-48.33,0.038
1.30,-48.15,0.038
1.32,-47.96,0.038
1.34,-47.78,0.038
1.36,-47.60,0.038
1.38,-47.41,0.038
1.39,-47.23,0.038
1.41,-47.05,0.038
1.43,-46.86,0.038
1.45,-46.68,0.038
1.47,-46.49,0.038
1.48,-46.31,0.038
1.50,-46.13,0.038
1.52,-45.95,0.038
1.54,-45.76,0.038
1.56,-45.58,0.038
1.58,-45.40,0.038
1.59,-45.21,0.038
1.61,-45.03,0.038
1.63,-44.85,0.038
1.65,-44.66,0.038
1.67,-44.48,0.038
1.69,-44.30,0.038
1.71,-44.11,0.038
1.72,-43.93,0.038
1.74,-43.75,0.037
1.76,-43.56,0.037
1.78,-43.38,0.037
1.80,-43.20,0.037
1.82,-43.01,0.037
1.83,-42.83,0.037
1.85,-42.64,0.037
1.87,-42.46,0.037
1.89,-42.28,0.037
1.91,-42.09,0.037
1.93,-41.91,0.037
1.94,-41.73,0.037
1.96,-41.54,0.037
1.98,-41.36,0.037
2.00,-41.18,0.037
2.02,-40.99,0.037
2.03,-40.81,0.037
2.05,-40.63,0.037
2.07,-40.44,0.037
2.09,-40.26,0.037
2.11,-40.08,0.037
2.13,-39.89,0.037
2.14,-39.71,0.037
2.16,-39.52,0.037
2.18,-39.34,0.037
2.20,-39.16,0.037
2.22,-38.97,0.037
2.24,-38.79,0.037
2.26,-38.61,0.037
2.27,-38.42,0.037
2.29,-38.24,0.037
2.31,-38.06,0.037
2.33,-37.87,0.037
2.35,-37.69,0.036
2.36,-37.51,0.036
2.38,-37.32,0.036
2.40,-37.14,0.036
2.42,-36.95,0.036
2.44,-36.77,0.036
2.46,-36.59,0.036
2.48,-36.40,0.036
2.49,-36.22,0.036
2.51,-36.03,0.036
2.53,-35.85,0.036
2.55,-35.67,0.036
2.57,-35.49,0.036
2.59,-35.30,0.036
2.60,-35.12,0.036
2.62,-34.93,0.036
2.64,-34.75,0.036
2.66,-34.57,0.036
2.68,-34.38,0.036
2.69,-34.20,0.036
2.71,-34.01,0.036
2.73,-33.83,0.036
2.75,-33.65,0.036
2.77,-33.47,0.036
2.79,-33.28,0.035
2.81,-33.10,0.035
2.82,-32.92,0.035
2.84,-32.73,0.035
2.86,-32.55,0.035
2.88,-32.36,0.035
2.90,-32.18,0.035
2.91,-32.00,0.035
2.93,-31.81,0.035
2.95,-31.63,0.035
2.97,-31.45,0.035
2.99,-31.26,0.035
3.01,-31.08,0.035
3.03,-30.90,0.035
3.04,-30.71,0.035
3.06,-30.53,0.035
3.08,-30.35,0.035
3.10,-30.16,0.035
3.12,-29.98,0.035
3.14,-29.80,0.035
3.15,-29.61,0.035
3.17,-29.43,0.035
3.19,-29.24,0.035
3.21,-29.06,0.035
3.23,-28.88,0.035
3.24,-28.69,0.034
3.26,-28.51,0.034
3.28,-28.33,0.034
3.30,-28.14,0.034
3.32,-27.96,0.034
3.34,-27.77,0.034
3.36,-27.59,0.034
3.37,-27.41,0.034
3.39,-27.22,0.034
3.41,-27.04,0.034
3.43,-26.86,0.034
3.45,-26.67,0.034
3.46,-26.49,0.034
3.48,-26.30,0.034
3.50,-26.12,0.034
3.52,-25.94,0.034
3.54,-25.75,0.034
3.56,-25.57,0.034
3.58,-25.38,0.034
3.59,-25.20,0.034
3.61,-25.02,0.034
3.63,-24.83,0.034
3.65,-24.65,0.034
3.67,-24.47,0.034
3.69,-24.28,0.034
3.70,-24.10,0.034
3.72,-23.92,0.034
3.74,-23.73,0.034
3.76,-23.55,0.034
3.78,-23.37,0.034
3.79,-23.18,0.034
3.81,-23.00,0.034
3.83,-22.82,0.034
3.85,-22.63,0.034
3.87,-22.45,0.034
3.89,-22.26,0.034
3.91,-22.08,0.033
3.92,-21.90,0.033
3.94,-21.71,0.033
3.96,-21.53,0.033
3.98,-21.35,0.033
4.00,-21.16,0.033
4.01,-20.98,0.033
4.03,-20.80,0.033
4.05,-20.61,0.033
4.07,-20.43,0.033
4.09,-20.25,0.033
4.11,-20.06,0.033
4.13,-19.88,0.033
4.14,-19.70,0.033
4.16,-19.51,0.033
4.18,-19.33,0.033
4.20,-19.14,0.033
4.22,-18.96,0.033
4.24,-18.78,0.033
4.25,-18.59,0.033
4.27,-18.41,0.033
4.29,-18.23,0.033
4.31,-18.04,0.033
4.33,-17.86,0.033
4.35,-17.68,0.033
4.36,-17.49,0.033
4.38,-17.31,0.033
4.40,-17.13,0.033
4.42,-16.94,0.033
4.44,-16.76,0.033
4.45,-16.57,0.033
4.47,-16.39,0.033
4.49,-16.21,0.033
4.51,-16.02,0.033
4.53,-15.84,0.033
4.55,-15.66,0.032
4.56,-15.47,0.032
4.58,-15.29,0.032
4.60,-15.11,0.032
4.62,-14.92,0.032
4.64,-14.74,0.032
4.66,-14.56,0.032
4.68,-14.37,0.032
4.69,-14.19,0.032
4.71,-14.00,0.032
4.73,-13.82,0.032
4.75,-13.64,0.032
4.77,-13.45,0.032
4.79,-13.27,0.032
4.80,-13.09,0.032
4.82,-12.90,0.032
4.84,-12.72,0.032
4.86,-12.54,0.032
4.88,-12.35,0.032
4.90,-12.17,0.032
4.91,-11.99,0.032
4.93,-11.80,0.032
4.95,-11.62,0.032
4.97,-11.44,0.032
4.99,-11.25,0.032
5.00,-11.07,0.032
5.02,-10.88,0.032
5.04,-10.70,0.032
5.06,-10.52,0.032
5.08,-10.33,0.032
5.10,-10.15,0.032
5.11,-9.97,0.032
5.13,-9.78,0.032
5.15,-9.60,0.032
5.17,-9.42,0.032
5.19,-9.23,0.032
5.21,-9.05,0.032
5.23,-8.87,0.032
5.24,-8.68,0.032
5.26,-8.50,0.032
5.28,-8.32,0.032
5.30,-8.13,0.032
5.32,-7.95,0.032
5.34,-7.77,0.031
5.35,-7.58,0.031
5.37,-7.40,0.031
5.39,-7.21,0.031
5.41,-7.03,0.031
5.43,-6.85,0.031
5.45,-6.66,0.031
5.46,-6.48,0.031
5.48,-6.30,0.031
5.50,-6.11,0.031
5.52,-5.93,0.031
5.54,-5.75,0.031
5.55,-5.56,0.031
5.57,-5.38,0.031
5.59,-5.20,0.031
5.61,-5.01,0.031
5.63,-4.83,0.031
5.65,-4.64,0.031
5.66,-4.46,0.031
5.68,-4.28,0.031
5.70,-4.09,0.031
5.72,-3.91,0.031
5.74,-3.73,0.031
5.76,-3.54,0.031
5.78,-3.36,0.031
5.79,-3.17,0.031
5.81,-2.99,0.031
5.83,-2.81,0.031
5.85,-2.62,0.031
5.87,-2.44,0.031
5.89,-2.26,0.031
5.90,-2.07,0.031
5.92,-1.89,0.031
5.94,-1.71,0.031
5.96,-1.52,0.031
5.98,-1.34,0.031
6.00,-1.16,0.031
6.01,-0.97,0.031
6.03,-0.79,0.031
6.05,-0.61,0.031
6.07,-0.42,0.031
6.09,-0.24,0.031
6.10,-0.06,0.031
6.12,0.13,0.031
6.14,0.31,0.031
6.16,0.50,0.031
6.18,0.68,0.031
6.20,0.87,0.031
6.21,1.05,0.031
6.23,1.23,0.031
6.25,1.41,0.031
6.27,1.60,0.031
6.29,1.78,0.031
6.31,1.97,0.031
6.33,2.15,0.031
6.34,2.33,0.031
6.36,2.52,0.031
6.38,2.70,0.031
6.40,2.88,0.031
6.42,3.07,0.031
6.44,3.25,0.030
6.45,3.43,0.030
6.47,3.62,0.030
6.49,3.80,0.030
6.51,3.98,0.030
6.53,4.17,0.030
6.55,4.35,0.030
6.56,4.53,0.030
6.58,4.72,0.030
6.60,4.90,0.030
6.62,5.08,0.030
6.64,5.27,0.030
6.65,5.45,0.030
6.67,5.64,0.030
6.69,5.82,0.030
6.71,6.00,0.030
6.73,6.19,0.030
6.75,6.37,0.030
6.76,6.55,0.030
6.78,6.74,0.030
6.80,6.92,0.030
6.82,7.10,0.030
6.84,7.29,0.030
6.86,7.47,0.030
6.88,7.66,0.030
6.89,7.84,0.030
6.91,8.02,0.030
6.93,8.21,0.030
6.95,8.39,0.030
6.97,8.57,0.030
6.99,8.76,0.030
7.00,8.94,0.030
7.02,9.13,0.030
7.04,9.31,0.030
7.06,9.49,0.030
7.08,9.67,0.030
7.10,9.86,0.030
7.11,10.04,0.030
7.13,10.22,0.030
7.15,10.41,0.030
7.17,10.59,0.030
7.19,10.78,0.030
7.20,10.96,0.030
7.22,11.14,0.030
7.24,11.33,0.030
7.26,11.51,0.030
7.28,11.69,0.030
7.30,11.88,0.030
7.31,12.06,0.030
7.33,12.24,0.030
7.35,12.43,0.030
7.37,12.61,0.030
7.39,12.79,0.030
7.41,12.98,0.030
7.43,13.16,0.030
7.44,13.35,0.030
7.46,13.53,0.030
7.48,13.71,0.030
7.50,13.90,0.030
7.52,14.08,0.030
7.54,14.26,0.030
7.55,14.45,0.030
7.57,14.63,0.030
7.59,14.81,0.030
7.61,15.00,0.030
7.63,15.18,0.030
7.65,15.37,0.030
7.66,15.55,0.030
7.68,15.73,0.030
7.70,15.92,0.030
7.72,16.10,0.030
7.74,16.28,0.030
7.75,16.47,0.030
7.77,16.65,0.030
7.79,16.83,0.030
7.81,17.02,0.030
7.83,17.20,0.030
7.85,17.38,0.029
7.86,17.57,0.029
7.88,17.75,0.029
7.90,17.93,0.029
7.92,18.12,0.029
7.94,18.30,0.029
7.96,18.49,0.030
7.98,18.67,0.030
7.99,18.85,0.030
8.01,19.04,0.029
8.03,19.22,0.029
8.05,19.40,0.029
8.07,19.58,0.029
8.09,19.77,0.029
8.10,19.95,0.029
8.12,20.13,0.029
8.14,20.32,0.029
8.16,20.50,0.029
8.18,20.69,0.029
8.20,20.87,0.029
8.21,21.05,0.029
8.23,21.24,0.029
8.25,21.42,0.029
8.27,21.60,0.029
8.29,21.79,0.029
8.30,21.97,0.029
8.32,22.15,0.029
8.34,22.34,0.029
8.36,22.52,0.029
8.38,22.71,0.029
8.40,22.89,0.029
8.41,23.07,0.029
8.43,23.26,0.029
8.45,23.44,0.029
8.47,23.62,0.029
8.49,23.81,0.029
8.51,23.99,0.029
8.53,24.17,0.029
8.54,24.36,0.029
8.56,24.54,0.029
8.58,24.73,0.029
8.60,24.91,0.029
8.62,25.09,0.029
8.63,25.28,0.029
8.65,25.46,0.029
8.67,25.64,0.029
8.69,25.83,0.029
8.71,26.01,0.029
8.73,26.19,0.029
8.75,26.37,0.029
8.76,26.56,0.029
8.78,26.74,0.029
8.80,26.93,0.029
8.82,27.11,0.029
8.84,27.29,0.029
8.85,27.48,0.029
8.87,27.66,0.029
8.89,27.84,0.029
8.91,28.03,0.029
8.93,28.21,0.029
8.95,28.39,0.029
8.97,28.58,0.029
8.98,28.76,0.029
9.00,28.95,0.029
9.02,29.13,0.029
9.04,29.31,0.029
9.06,29.49,0.029
9.08,29.68,0.029
9.09,29.86,0.029
9.11,30.05,0.029
9.13,30.23,0.029
9.15,30.41,0.029
9.17,30.60,0.029
9.18,30.78,0.029
9.20,30.96,0.029
9.22,31.15,0.029
9.24,31.33,0.029
9.26,31.51,0.029
9.28,31.70,0.029
9.30,31.88,0.029
9.31,32.07,0.029
9.33,32.25,0.029
9.35,32.43,0.029
9.37,32.62,0.029
9.39,32.80,0.029
9.40,32.98,0.029
9.42,33.16,0.029
9.44,33.35,0.029
9.46,33.53,0.029
9.48,33.72,0.029
9.50,33.90,0.029
9.52,34.08,0.029
9.53,34.27,0.029
9.55,34.45,0.029
9.57,34.63,0.029
9.59,34.82,0.029
9.61,35.00,0.029
9.63,35.18,0.029
9.64,35.37,0.029
9.66,35.55,0.029
9.68,35.73,0.029
9.70,35.92,0.029
9.72,36.10,0.029
9.73,36.29,0.029
9.75,36.47,0.029
9.77,36.65,0.029
9.79,36.84,0.029
9.81,37.02,0.029
9.83,37.20,0.029
9.85,37.39,0.028
9.86,37.57,0.028
9.88,37.75,0.028
9.90,37.94,0.028
9.92,38.12,0.028
9.94,38.31,0.028
9.95,38.49,0.028
9.97,38.67,0.028
9.99,38.86,0.028
10.01,39.04,0.028
10.03,39.22,0.028
10.05,39.41,0.028
10.07,39.59,0.028
10.08,39.78,0.028
10.10,39.96,0.028
10.12,40.14,0.028
10.14,40.32,0.028
10.16,40.51,0.028
10.18,40.69,0.028
10.19,40.87,0.028
10.21,41.06,0.028
10.23,41.24,0.028
10.25,41.43,0.028
10.27,41.61,0.028
10.28,41.79,0.028
10.30,41.98,0.028
10.32,42.16,0.028
10.34,42.34,0.028
10.36,42.53,0.028
10.38,42.71,0.028
10.40,42.89,0.028
10.41,43.08,0.028
10.43,43.26,0.028
10.45,43.44,0.028
10.47,43.63,0.028
10.49,43.81,0.028
10.50,43.99,0.028
10.52,44.18,0.028
10.54,44.36,0.028
10.56,44.55,0.028
10.58,44.73,0.028
10.60,44.91,0.028
10.62,45.10,0.028
10.63,45.28,0.028
10.65,45.46,0.028
10.67,45.65,0.028
10.69,45.83,0.028
10.71,46.01,0.028
10.73,46.20,0.028
10.74,46.38,0.028
10.76,46.57,0.028
10.78,46.75,0.028
10.80,46.93,0.028
10.82,47.11,0.028
10.83,47.30,0.028
10.85,47.48,0.028
10.87,47.67,0.028
10.89,47.85,0.028
10.91,48.03,0.028
10.93,48.22,0.028
10.95,48.40,0.028
10.96,48.58,0.028
10.98,48.77,0.028
11.00,48.95,0.028
11.02,49.13,0.028
11.04,49.32,0.028
11.05,49.50,0.028
11.07,49.69,0.028
11.09,49.87,0.028
11.11,50.05,0.028
11.13,50.24,0.028
11.15,50.42,0.028
11.17,50.60,0.028
11.18,50.79,0.028
11.20,50.97,0.028
11.22,51.15,0.028
11.24,51.34,0.028
11.26,51.52,0.028
11.28,51.70,0.028
11.29,51.89,0.028
11.31,52.07,0.028
11.33,52.25,0.028
11.35,52.44,0.028
11.37,52.62,0.028
11.38,52.80,0.028
11.40,52.99,0.028
11.42,53.17,0.028
11.44,53.36,0.028
11.46,53.54,0.028
11.48,53.72,0.028
11.50,53.91,0.028
11.51,54.09,0.028
11.53,54.27,0.028
11.55,54.46,0.028
11.57,54.64,0.028
11.59,54.82,0.028
11.60,55.01,0.028
11.62,55.19,0.028
11.64,55.37,0.028
11.66,55.56,0.028
11.68,55.74,0.028
11.70,55.93,0.028
11.72,56.11,0.028
11.73,56.29,0.028
11.75,56.48,0.028
11.77,56.66,0.028
11.79,56.84,0.028
11.81,57.03,0.028
11.83,57.21,0.028
11.84,57.39,0.028
11.86,57.58,0.028
11.88,57.76,0.028
11.90,57.94,0.028
11.92,58.13,0.028
11.93,58.31,0.028
11.95,58.49,0.028
11.97,58.68,0.028
11.99,58.86,0.028
12.01,59.05,0.028
12.03,59.23,0.028
12.05,59.41,0.028
12.06,59.60,0.028
12.08,59.78,0.028
12.10,59.96,0.028
12.12,60.15,0.028
12.14,60.33,0.028
12.15,60.51,0.028
12.17,60.70,0.028
12.19,60.88,0.028
12.21,61.06,0.028
12.23,61.25,0.028
12.25,61.43,0.028
12.27,61.61,0.028
12.28,61.80,0.028
12.30,61.98,0.028
12.32,62.16,0.028
12.34,62.35,0.028
12.36,62.53,0.028
12.38,62.71,0.028
12.39,62.90,0.028
12.41,63.08,0.028
12.43,63.26,0.028
12.45,63.45,0.028
12.47,63.63,0.028
12.48,63.82,0.028
12.50,64.00,0.028
12.52,64.18,0.028
12.54,64.37,0.028
12.56,64.55,0.028
12.58,64.73,0.028
12.60,64.92,0.028
12.61,65.10,0.028
12.63,65.29,0.028
12.65,65.47,0.028
12.67,65.65,0.028
12.69,65.83,0.028
12.70,66.02,0.028
12.72,66.20,0.028
12.74,66.39,0.028
12.76,66.57,0.028
12.78,66.75,0.028
12.80,66.94,0.028
12.82,67.12,0.028
12.83,67.30,0.028
12.85,67.49,0.028
12.87,67.67,0.028
12.89,67.85,0.028
12.91,68.04,0.028
12.93,68.22,0.028
12.94,68.41,0.028
12.96,68.59,0.028
12.98,68.77,0.028
13.00,68.96,0.028
13.02,69.14,0.028
13.03,69.32,0.028
13.05,69.51,0.028
13.07,69.69,0.028
13.09,69.87,0.028
13.11,70.06,0.028
13.13,70.24,0.028
13.15,70.43,0.028
13.16,70.61,0.028
13.18,70.79,0.028
13.20,70.98,0.028
13.22,71.16,0.028
13.24,71.34,0.028
13.25,71.53,0.028
13.27,71.71,0.028
13.29,71.89,0.028
13.31,72.08,0.028
13.33,72.26,0.028
13.35,72.45,0.028
13.37,72.63,0.028
13.38,72.81,0.028
13.40,72.99,0.028
13.42,73.18,0.028
13.44,73.36,0.028
13.46,73.54,0.028
13.48,73.73,0.028
13.49,73.91,0.028
13.51,74.10,0.028
13.53,74.28,0.028
13.55,74.46,0.028
13.57,74.65,0.028
13.58,74.83,0.028
13.60,75.01,0.028
13.62,75.20,0.028
13.64,75.38,0.028
13.66,75.56,0.028
13.68,75.75,0.028
13.70,75.93,0.028
13.71,76.11,0.028
13.73,76.30,0.028
13.75,76.48,0.028
13.77,76.66,0.028
13.79,76.85,0.028
13.80,77.03,0.028
13.82,77.21,0.028
13.84,77.40,0.028
13.86,77.58,0.028
13.88,77.76,0.028
13.90,77.95,0.028
13.92,78.13,0.028
13.93,78.31,0.028
13.95,78.50,0.028
13.97,78.68,0.028
13.99,78.87,0.028
14.01,79.05,0.028
14.03,79.23,0.028
14.04,79.41,0.028
14.06,79.60,0.028
14.08,79.78,0.028
14.10,79.97,0.028
14.12,80.15,0.028
14.13,80.33,0.028
14.15,80.52,0.028
14.17,80.70,0.028
14.19,80.88,0.028
14.21,81.07,0.028
14.23,81.25,0.028
14.25,81.43,0.028
14.26,81.61,0.028
14.28,81.80,0.028
14.30,81.98,0.028
14.32,82.17,0.028
14.34,82.35,0.028
14.35,82.53,0.028
14.37,82.72,0.028
14.39,82.90,0.028
14.41,83.09,0.028
14.43,83.27,0.028
14.45,83.45,0.028
14.47,83.64,0.028
14.48,83.82,0.028
14.50,84.00,0.028
14.52,84.19,0.028
14.54,84.37,0.028
14.56,84.55,0.028
14.58,84.74,0.028
14.59,84.92,0.028
14.61,85.11,0.028
14.63,85.29,0.028
14.65,85.47,0.028
14.67,85.66,0.028
14.68,85.84,0.028
14.70,86.02,0.028
14.72,86.21,0.028
14.74,86.39,0.028
14.76,86.57,0.028
14.78,86.76,0.028
14.80,86.94,0.028
14.81,87.12,0.028
14.83,87.31,0.028
14.85,87.49,0.028
14.87,87.68,0.028
14.89,87.86,0.028
14.90,88.04,0.028
14.92,88.22,0.028
14.94,88.41,0.028
14.96,88.59,0.028
14.98,88.78,0.028
15.00,88.96,0.028
15.02,89.14,0.028
15.03,89.33,0.028
15.05,89.51,0.028
15.07,89.69,0.028
15.09,89.88,0.028
15.11,90.06,0.028
15.13,90.24,0.028
15.14,90.42,0.028
15.16,90.61,0.028
15.18,90.79,0.028
15.20,90.98,0.028
15.22,91.16,0.028
15.23,91.34,0.028
15.25,91.53,0.028
15.27,91.71,0.028
15.29,91.89,0.028
15.31,92.08,0.028
15.33,92.26,0.028
15.35,92.44,0.028
15.36,92.63,0.028
15.38,92.81,0.028
15.40,92.99,0.028
15.42,93.18,0.028
15.44,93.36,0.028
15.45,93.54,0.028
15.47,93.73,0.028
15.49,93.91,0.028
15.51,94.09,0.028
15.53,94.28,0.028
15.55,94.46,0.028
15.57,94.65,0.028
15.58,94.83,0.028
15.60,95.01,0.028
15.62,95.20,0.028
15.64,95.38,0.028
15.66,95.56,0.028
15.68,95.75,0.028
15.69,95.93,0.028
15.71,96.11,0.028
15.73,96.30,0.028
15.75,96.48,0.028
15.77,96.66,0.028
15.78,96.85,0.028
15.80,97.03,0.028
15.82,97.22,0.028
15.84,97.40,0.028
15.86,97.58,0.028
15.88,97.77,0.028
15.90,97.95,0.028
15.91,98.13,0.028
15.93,98.31,0.028
15.95,98.50,0.028
15.97,98.68,0.028
15.99,98.87,0.028
16.00,99.05,0.028
16.02,99.23,0.028
16.04,99.42,0.028
16.06,99.60,0.028
16.08,99.78,0.028
16.10,99.97,0.028
16.12,100.15,0.028
16.13,100.33,0.028
16.15,100.52,0.028
16.17,100.70,0.028
16.19,100.88,0.028
16.21,101.07,0.028
16.23,101.25,0.028
16.24,101.43,0.028
16.26,101.62,0.028
16.28,101.80,0.028
16.30,101.99,0.028
16.32,102.17,0.028
16.33,102.35,0.028
16.35,102.54,0.028
16.37,102.72,0.028
16.39,102.90,0.028
16.41,103.09,0.028
16.43,103.27,0.028
16.45,103.45,0.028
16.46,103.64,0.028
16.48,103.82,0.028
16.50,104.00,0.028
16.52,104.19,0.028
16.54,104.37,0.028
16.55,104.55,0.028
16.57,104.74,0.028
16.59,104.92,0.028
16.61,105.10,0.028
16.63,105.29,0.028
16.65,105.47,0.028
16.67,105.65,0.028
16.68,105.84,0.028
16.70,106.02,0.028
16.72,106.21,0.028
16.74,106.39,0.028
16.76,106.57,0.028
16.78,106.76,0.028
16.79,106.94,0.028
16.81,107.12,0.028
16.83,107.31,0.028
16.85,107.49,0.028
16.87,107.67,0.028
16.88,107.86,0.028
16.90,108.04,0.028
16.92,108.22,0.028
16.94,108.41,0.028
16.96,108.59,0.028
16.98,108.78,0.028
17.00,108.96,0.028
17.01,109.14,0.028
17.03,109.33,0.028
17.05,109.51,0.028
17.07,109.69,0.028
17.09,109.88,0.028
17.11,110.06,0.029
17.12,110.24,0.029
17.14,110.43,0.029
17.16,110.61,0.028
17.18,110.79,0.029
17.20,110.98,0.029
17.22,111.16,0.029
17.23,111.34,0.029
17.25,111.53,0.029
17.27,111.71,0.029
17.29,111.89,0.029
17.31,112.08,0.029
17.33,112.26,0.029
17.34,112.44,0.029
17.36,112.63,0.029
17.38,112.81,0.029
17.40,112.99,0.029
17.42,113.18,0.029
17.43,113.36,0.029
17.45,113.55,0.029
17.47,113.73,0.029
17.49,113.91,0.029
17.51,114.10,0.029
17.53,114.28,0.029
17.54,114.46,0.029
17.56,114.65,0.029
17.58,114.83,0.029
17.60,115.01,0.029
17.62,115.20,0.029
17.64,115.38,0.029
17.66,115.56,0.029
17.67,115.75,0.029
17.69,115.93,0.029
17.71,116.11,0.029
17.73,116.30,0.029
17.75,116.48,0.029
17.77,116.66,0.029
17.78,116.85,0.029
17.80,117.03,0.029
17.82,117.22,0.029
17.84,117.40,0.029
17.86,117.58,0.029
17.88,117.77,0.029
17.89,117.95,0.029
17.91,118.13,0.029
17.93,118.32,0.029
17.95,118.50,0.029
17.97,118.68,0.029
17.98,118.87,0.029
18.00,119.05,0.029
18.02,119.23,0.029
18.04,119.42,0.029
18.06,119.60,0.029
18.08,119.78,0.029
18.09,119.97,0.029
18.11,120.15,0.029
18.13,120.33,0.029
18.15,120.52,0.029
18.17,120.70,0.029
18.19,120.88,0.029
18.21,121.07,0.029
18.22,121.25,0.029
18.24,121.43,0.029
18.26,121.62,0.029
18.28,121.80,0.029
18.30,121.98,0.029
18.32,122.17,0.029
18.33,122.35,0.029
18.35,122.54,0.029
18.37,122.72,0.029
18.39,122.90,0.029
18.41,123.09,0.029
18.43,123.27,0.029
18.44,123.45,0.029
18.46,123.64,0.029
18.48,123.82,0.029
18.50,124.00,0.029
18.52,124.19,0.029
18.53,124.37,0.029
18.55,124.55,0.029
18.57,124.74,0.029
18.59,124.92,0.029
18.61,125.10,0.029
18.63,125.29,0.029
18.64,125.47,0.029
18.66,125.65,0.029
18.68,125.84,0.029
18.70,126.02,0.029
18.72,126.20,0.029
18.74,126.39,0.029
18.76,126.57,0.029
18.77,126.76,0.029
18.79,126.94,0.029
18.81,127.12,0.029
18.83,127.31,0.029
18.85,127.49,0.029
18.87,127.67,0.029
18.88,127.86,0.029
18.90,128.04,0.029
18.92,128.22,0.029
18.94,128.41,0.029
18.96,128.59,0.029
18.98,128.77,0.029
18.99,128.96,0.029
19.01,129.14,0.029
19.03,129.32,0.029
19.05,129.51,0.029
19.07,129.69,0.029
19.08,129.87,0.029
19.10,130.06,0.029
19.12,130.24,0.029
19.14,130.43,0.029
19.16,130.61,0.029
19.18,130.79,0.029
19.19,130.98,0.029
19.21,131.16,0.029
19.23,131.34,0.029
19.25,131.53,0.029
19.27,131.71,0.029
19.29,131.89,0.029
19.31,132.08,0.029
19.32,132.26,0.029
19.34,132.44,0.029
19.36,132.63,0.029
19.38,132.81,0.029
19.40,132.99,0.029
19.42,133.18,0.029
19.43,133.36,0.029
19.45,133.54,0.029
19.47,133.73,0.029
19.49,133.91,0.029
19.51,134.10,0.029
19.53,134.28,0.029
19.54,134.46,0.029
19.56,134.65,0.029
19.58,134.83,0.029
19.60,135.01,0.029
19.62,135.20,0.029
19.63,135.38,0.029
19.65,135.56,0.029
19.67,135.75,0.029
19.69,135.93,0.029
19.71,136.11,0.029
19.73,136.30,0.029
19.74,136.48,0.029
19.76,136.66,0.029
19.78,136.85,0.029
19.80,137.03,0.029
19.82,137.22,0.029
19.84,137.40,0.029
19.86,137.58,0.029
19.87,137.76,0.029
19.89,137.95,0.029
19.91,138.13,0.029
19.93,138.32,0.029
19.95,138.50,0.029
19.97,138.68,0.029
19.98,138.87,0.029
20.00,139.05,0.029
20.02,139.23,0.029
20.04,139.42,0.029
20.06,139.60,0.029
20.08,139.78,0.029
20.09,139.97,0.029
20.11,140.15,0.029
20.13,140.33,0.029
20.15,140.52,0.029
20.17,140.70,0.029
20.18,140.88,0.029
20.20,141.07,0.029
20.22,141.25,0.029
20.24,141.43,0.029
20.26,141.62,0.029
20.28,141.80,0.029
20.29,141.98,0.029
20.31,142.17,0.029
20.33,142.35,0.029
20.35,142.53,0.029
20.37,142.72,0.029
20.39,142.90,0.029
20.41,143.08,0.029
20.42,143.27,0.029
20.44,143.45,0.029
20.46,143.63,0.029
20.48,143.82,0.029
20.50,144.00,0.029
20.52,144.18,0.029
20.53,144.37,0.029
20.55,144.55,0.029
20.57,144.74,0.029
20.59,144.92,0.029
20.61,145.10,0.029
20.63,145.29,0.029
20.64,145.47,0.029
20.66,145.65,0.029
20.68,145.84,0.029
20.70,146.02,0.029
20.72,146.20,0.029
20.73,146.39,0.029
20.75,146.57,0.029
20.77,146.75,0.029
20.79,146.94,0.029
20.81,147.12,0.029
20.83,147.31,0.029
20.84,147.49,0.029
20.86,147.67,0.030
20.88,147.86,0.030
20.90,148.04,0.030
20.92,148.22,0.030
20.94,148.41,0.030
20.96,148.59,0.030
20.97,148.77,0.030
20.99,148.96,0.030
21.01,149.14,0.030
21.03,149.32,0.030
21.05,149.51,0.030
21.07,149.69,0.030
21.08,149.87,0.030
21.10,150.06,0.030
21.12,150.24,0.030
21.14,150.42,0.030
21.16,150.61,0.030
21.18,150.79,0.030
21.19,150.97,0.030
21.21,151.15,0.030
21.23,151.34,0.030
21.25,151.52,0.030
21.27,151.70,0.030
21.28,151.89,0.030
21.30,152.07,0.030
21.32,152.26,0.030
21.34,152.44,0.030
21.36,152.62,0.030
21.38,152.81,0.030
21.39,152.99,0.030
21.41,153.17,0.030
21.43,153.36,0.030
21.45,153.54,0.030
21.47,153.73,0.030
21.49,153.91,0.030
21.51,154.09,0.030
21.52,154.28,0.030
21.54,154.46,0.030
21.56,154.64,0.030
21.58,154.83,0.030
21.60,155.01,0.030
21.62,155.19,0.030
21.63,155.37,0.030
21.65,155.56,0.030
21.67,155.74,0.030
21.69,155.93,0.030
21.71,156.11,0.030
21.73,156.29,0.030
21.74,156.48,0.031
21.76,156.66,0.036
21.78,156.83,0.170
21.80,156.93,0.521
21.82,157.02,0.765
21.83,157.09,0.982
21.85,157.17,1.193
21.87,157.24,1.402
21.89,157.32,1.610
21.91,157.40,1.815
21.93,157.48,2.015
21.94,157.56,2.199
21.96,157.65,2.372
21.98,157.74,2.537
22.00,157.84,2.622
22.02,158.06,1.798
22.04,158.49,0.999
22.06,158.90,0.702
22.07,159.25,0.525
22.09,159.57,0.401
22.11,159.85,0.309
22.13,160.11,0.240
22.15,160.35,0.188
22.17,160.57,0.148
22.18,160.79,0.119
22.20,161.00,0.095
22.22,161.20,0.079
22.24,161.39,0.066
22.26,161.59,0.056
22.28,161.78,0.049
22.29,161.97,0.044
22.31,162.15,0.039
22.33,162.34,0.037
22.35,162.53,0.034
22.37,162.71,0.032
22.38,162.90,0.032
22.40,163.08,0.031
22.42,163.27,0.030
22.44,163.45,0.030
22.46,163.63,0.029
22.48,163.82,0.029
22.49,164.00,0.029
22.51,164.18,0.029
22.53,164.37,0.029
22.55,164.55,0.028
22.57,164.73,0.028
22.59,164.92,0.028
22.61,165.10,0.028
22.62,165.28,0.028
22.64,165.47,0.028
22.66,165.65,0.028
22.68,165.83,0.028
22.70,166.02,0.028
22.72,166.20,0.028
22.73,166.39,0.028
22.75,166.57,0.028
22.77,166.75,0.028
22.79,166.94,0.028
22.81,167.12,0.028
22.83,167.30,0.028
22.84,167.49,0.028
22.86,167.67,0.028
22.88,167.85,0.028
22.90,168.04,0.028
22.92,168.22,0.028
22.93,168.40,0.028
22.95,168.59,0.028
22.97,168.77,0.028
22.99,168.95,0.027
23.01,169.14,0.027
23.03,169.32,0.027
23.04,169.50,0.027
23.06,169.69,0.027
23.08,169.87,0.027
23.10,170.06,0.027
23.12,170.24,0.027
23.14,170.42,0.027
23.16,170.61,0.027
23.17,170.79,0.027
23.19,170.97,0.027
23.21,171.16,0.027
23.23,171.34,0.027
23.25,171.52,0.027
23.27,171.71,0.027
23.28,171.89,0.027
23.30,172.07,0.027
23.32,172.26,0.027
23.34,172.44,0.027
23.36,172.62,0.027
23.38,172.81,0.027
23.39,172.99,0.027
23.41,173.17,0.027
23.43,173.36,0.027
23.45,173.54,0.027
23.47,173.72,0.027
23.48,173.91,0.027
23.50,174.09,0.027
23.52,174.28,0.027
23.54,174.46,0.027
23.56,174.64,0.027
23.58,174.83,0.027
23.59,175.01,0.027
23.61,175.19,0.027
23.63,175.38,0.027
23.65,175.56,0.027
23.67,175.75,0.027
23.69,175.93,0.027
23.71,176.11,0.027
23.72,176.30,0.027
23.74,176.48,0.027
23.76,176.66,0.027
23.78,176.85,0.027
23.80,177.03,0.027
23.82,177.21,0.027
23.83,177.40,0.027
23.85,177.58,0.027
23.87,177.76,0.027
23.89,177.95,0.027
23.91,178.13,0.027
23.93,178.31,0.027
23.94,178.50,0.027
23.96,178.68,0.027
23.98,178.86,0.027
24.00,179.05,0.027
24.02,179.23,0.027
24.03,179.41,0.027
24.05,179.60,0.027
24.07,179.78,0.027
24.09,179.96,0.027
24.11,180.15,0.027
24.13,180.33,0.027
24.14,180.51,0.027
24.16,180.70,0.027
24.18,180.88,0.027
24.20,181.06,0.027
24.22,181.25,0.027
24.24,181.43,0.027
24.26,181.61,0.027
24.27,181.80,0.027
24.29,181.98,0.027
24.31,182.16,0.027
24.33,182.35,0.027
24.35,182.53,0.027
24.37,182.71,0.027
24.38,182.90,0.027
24.40,183.08,0.027
24.42,183.27,0.027
24.44,183.45,0.027
24.46,183.63,0.027
24.48,183.82,0.027
24.49,184.00,0.027
24.51,184.18,0.027
24.53,184.37,0.027
24.55,184.55,0.027
24.57,184.73,0.027
24.58,184.91,0.027
24.60,185.10,0.027
24.62,185.28,0.027
24.64,185.47,0.027
24.66,185.65,0.027
24.68,185.83,0.027
24.69,186.02,0.027
24.71,186.20,0.027
24.73,186.39,0.027
24.75,186.57,0.027
24.77,186.75,0.027
24.79,186.93,0.027
24.81,187.12,0.027
24.82,187.30,0.027
24.84,187.49,0.027
24.86,187.67,0.027
24.88,187.85,0.027
24.90,188.03,0.027
24.92,188.22,0.027
24.93,188.40,0.027
24.95,188.58,0.027
24.97,188.77,0.027
24.99,188.95,0.027
25.01,189.14,0.027
25.03,189.32,0.027
25.04,189.50,0.027
25.06,189.69,0.027
25.08,189.87,0.027
25.10,190.05,0.027
25.12,190.24,0.027
25.13,190.42,0.027
25.15,190.60,0.027
25.17,190.79,0.027
25.19,190.97,0.027
25.21,191.15,0.027
25.23,191.34,0.027
25.24,191.52,0.027
25.26,191.70,0.027
25.28,191.89,0.027
25.30,192.07,0.027
25.32,192.25,0.027
25.34,192.44,0.027
25.36,192.62,0.027
25.37,192.81,0.027
25.39,192.99,0.027
25.41,193.17,0.027
25.43,193.35,0.027
25.45,193.54,0.027
25.47,193.72,0.027
25.48,193.90,0.027
25.50,194.09,0.027
25.52,194.27,0.027
25.54,194.45,0.027
25.56,194.64,0.027
25.58,194.82,0.027
25.59,195.01,0.027
25.61,195.19,0.027
25.63,195.37,0.027
25.65,195.56,0.027
25.67,195.74,0.027
25.68,195.92,0.027
25.70,196.11,0.027
25.72,196.29,0.027
25.74,196.47,0.027
25.76,196.66,0.027
25.78,196.84,0.027
25.79,197.02,0.027
25.81,197.21,0.027
25.83,197.39,0.027
25.85,197.57,0.027
25.87,197.76,0.027
25.89,197.94,0.027
25.91,198.12,0.027
25.92,198.31,0.027
25.94,198.49,
25.96,198.67,
25.98,198.86,
25.99,,

[step]
Ramp 10.00 °C/min to -60.00 °C
Time,Temperature,Heat Flow (Normalized)
min,°C,W/g
27.99,200.16,-0.020
28.01,200.16,-0.020
28.03,200.16,-0.019
28.05,200.14,-0.015
28.07,200.11,-0.002
28.08,200.06,0.008
28.10,199.98,0.014
28.12,199.87,0.011
28.14,199.74,0.004
28.16,199.59,-0.012
28.18,199.44,-0.025
28.19,199.27,-0.037
28.21,199.10,-0.044
28.23,198.93,-0.052
28.25,198.75,-0.056
28.27,198.57,-0.058
28.29,198.39,-0.059
28.31,198.21,-0.061
28.32,198.04,-0.062
28.34,197.85,-0.062
28.36,197.67,-0.063
28.38,197.49,-0.063
28.40,197.31,-0.063
28.42,197.13,-0.064
28.43,196.95,-0.064
28.45,196.77,-0.064
28.47,196.58,-0.064
28.49,196.40,-0.065
28.51,196.22,-0.065
28.53,196.04,-0.065
28.54,195.86,-0.065
28.56,195.68,-0.065
28.58,195.49,-0.065
28.60,195.31,-0.065
28.62,195.13,-0.065
28.63,194.95,-0.065
28.65,194.77,-0.065
28.67,194.58,-0.065
28.69,194.40,-0.065
28.71,194.22,-0.066
28.73,194.04,-0.066
28.74,193.85,-0.066
28.76,193.67,-0.066
28.78,193.49,-0.066
28.80,193.31,-0.066
28.82,193.12,-0.066
28.84,192.94,-0.066
28.86,192.76,-0.066
28.87,192.58,-0.066
28.89,192.40,-0.066
28.91,192.21,-0.066
28.93,192.03,-0.066
28.95,191.85,-0.066
28.97,191.66,-0.066
28.98,191.48,-0.066
29.00,191.30,-0.066
29.02,191.12,-0.066
29.04,190.93,-0.066
29.06,190.75,-0.066
29.08,190.57,-0.066
29.09,190.39,-0.066
29.11,190.20,-0.066
29.13,190.02,-0.066
29.15,189.84,-0.066
29.17,189.65,-0.066
29.18,189.47,-0.066
29.20,189.29,-0.066
29.22,189.10,-0.066
29.24,188.92,-0.066
29.26,188.74,-0.066
29.28,188.56,-0.066
29.29,188.37,-0.066
29.31,188.19,-0.066
29.33,188.01,-0.066
29.35,187.82,-0.065
29.37,187.64,-0.065
29.39,187.46,-0.065
29.41,187.27,-0.065
29.42,187.09,-0.065
29.44,186.91,-0.065
29.46,186.73,-0.065
29.48,186.54,-0.065
29.50,186.36,-0.065
29.52,186.18,-0.065
29.53,185.99,-0.065
29.55,185.81,-0.065
29.57,185.63,-0.065
29.59,185.44,-0.065
29.61,185.26,-0.065
29.63,185.08,-0.065
29.64,184.89,-0.065
29.66,184.71,-0.065
29.68,184.53,-0.065
29.70,184.34,-0.065
29.72,184.16,-0.065
29.73,183.98,-0.065
29.75,183.79,-0.065
29.77,183.61,-0.065
29.79,183.43,-0.065
29.81,183.24,-0.065
29.83,183.06,-0.065
29.84,182.88,-0.065
29.86,182.70,-0.065
29.88,182.51,-0.065
29.90,182.33,-0.065
29.92,182.15,-0.065
29.94,181.96,-0.064
29.96,181.78,-0.064
29.97,181.60,-0.064
29.99,181.41,-0.064
30.01,181.23,-0.064
30.03,181.05,-0.064
30.05,180.87,-0.064
30.07,180.68,-0.064
30.08,180.50,-0.064
30.10,180.31,-0.064
30.12,180.13,-0.064
30.14,179.95,-0.064
30.16,179.76,-0.064
30.18,179.58,-0.064
30.19,179.40,-0.064
30.21,179.22,-0.064
30.23,179.03,-0.064
30.25,178.85,-0.064
30.27,178.66,-0.064
30.28,178.48,-0.064
30.30,178.30,-0.064
30.32,178.12,-0.064
30.34,177.93,-0.064
30.36,177.75,-0.064
30.38,177.57,-0.064
30.39,177.38,-0.064
30.41,177.20,-0.064
30.43,177.02,-0.064
30.45,176.83,-0.064
30.47,176.65,-0.064
30.49,176.47,-0.064
30.51,176.28,-0.064
30.52,176.10,-0.064
30.54,175.92,-0.063
30.56,175.73,-0.063
30.58,175.55,-0.063
30.60,175.37,-0.063
30.62,175.18,-0.063
30.63,175.00,-0.063
30.65,174.82,-0.063
30.67,174.63,-0.063
30.69,174.45,-0.063
30.71,174.27,-0.063
30.73,174.09,-0.063
30.74,173.90,-0.063
30.76,173.72,-0.063
30.78,173.53,-0.063
30.80,173.35,-0.063
30.82,173.17,-0.063
30.83,172.98,-0.063
30.85,172.80,-0.063
30.87,172.62,-0.063
30.89,172.43,-0.063
30.91,172.25,-0.063
30.93,172.07,-0.063
30.94,171.88,-0.063
30.96,171.70,-0.063
30.98,171.52,-0.063
31.00,171.33,-0.063
31.02,171.15,-0.063
31.04,170.97,-0.063
31.06,170.78,-0.063
31.07,170.60,-0.063
31.09,170.42,-0.063
31.11,170.23,-0.063
31.13,170.05,-0.063
31.15,169.87,-0.063
31.17,169.69,-0.063
31.18,169.50,-0.063
31.20,169.32,-0.063
31.22,169.14,-0.063
31.24,168.95,-0.063
31.26,168.77,-0.063
31.28,168.59,-0.063
31.29,168.40,-0.063
31.31,168.22,-0.063
31.33,168.03,-0.063
31.35,167.85,-0.063
31.37,167.67,-0.063
31.38,167.48,-0.063
31.40,167.30,-0.063
31.42,167.12,-0.063
31.44,166.93,-0.063
31.46,166.75,-0.063
31.48,166.57,-0.063
31.49,166.38,-0.063
31.51,166.20,-0.063
31.53,166.02,-0.062
31.55,165.84,-0.062
31.57,165.65,-0.062
31.59,165.47,-0.062
31.61,165.29,-0.062
31.62,165.10,-0.062
31.64,164.92,-0.062
31.66,164.74,-0.062
31.68,164.55,-0.062
31.70,164.37,-0.062
31.72,164.19,-0.062
31.73,164.00,-0.062
31.75,163.82,-0.062
31.77,163.64,-0.062
31.79,163.45,-0.062
31.81,163.27,-0.062
31.83,163.09,-0.062
31.84,162.90,-0.062
31.86,162.72,-0.062
31.88,162.54,-0.062
31.90,162.35,-0.062
31.92,162.17,-0.062
31.93,161.99,-0.062
31.95,161.80,-0.062
31.97,161.62,-0.062
31.99,161.44,-0.062
32.01,161.25,-0.062
32.03,161.07,-0.062
32.04,160.89,-0.062
32.06,160.71,-0.062
32.08,160.52,-0.062
32.10,160.34,-0.062
32.12,160.15,-0.062
32.14,159.97,-0.062
32.16,159.79,-0.062
32.17,159.60,-0.062
32.19,159.42,-0.062
32.21,159.24,-0.062
32.23,159.05,-0.062
32.25,158.87,-0.062
32.27,158.69,-0.062
32.28,158.50,-0.062
32.30,158.32,-0.062
32.32,158.14,-0.062
32.34,157.95,-0.062
32.36,157.77,-0.062
32.38,157.59,-0.062
32.39,157.40,-0.062
32.41,157.22,-0.062
32.43,157.04,-0.062
32.45,156.85,-0.062
32.47,156.67,-0.062
32.48,156.49,-0.062
32.50,156.30,-0.062
32.52,156.12,-0.062
32.54,155.94,-0.062
32.56,155.75,-0.062
32.58,155.57,-0.062
32.59,155.39,-0.062
32.61,155.20,-0.062
32.63,155.02,-0.062
32.65,154.84,-0.062
32.67,154.65,-0.062
32.69,154.72,-4.781
32.71,155.29,-3.976
32.72,155.33,-3.324
32.74,155.28,-3.321
32.76,155.20,-3.443
32.78,155.10,-3.359
32.80,154.85,-1.744
32.82,154.35,-0.682
32.83,153.88,-0.432
32.85,153.48,-0.325
32.87,153.14,-0.259
32.89,152.83,-0.211
32.91,152.55,-0.175
32.93,152.30,-0.148
32.94,152.07,-0.127
32.96,151.84,-0.110
32.98,151.63,-0.098
33.00,151.43,-0.089
33.02,151.23,-0.082
33.03,151.03,-0.077
33.05,150.84,-0.073
33.07,150.65,-0.071
33.09,150.46,-0.068
33.11,150.27,-0.067
33.13,150.08,-0.066
33.14,149.90,-0.065
33.16,149.71,-0.065
33.18,149.53,-0.064
33.20,149.34,-0.064
33.22,149.16,-0.063
33.24,148.98,-0.063
33.26,148.79,-0.063
33.27,148.61,-0.062
33.29,148.43,-0.062
33.31,148.24,-0.062
33.33,148.06,-0.062
33.35,147.87,-0.062
33.37,147.69,-0.062
33.38,147.51,-0.062
33.40,147.32,-0.062
33.42,147.14,-0.062
33.44,146.96,-0.062
33.46,146.77,-0.062
33.48,146.59,-0.062
33.49,146.41,-0.062
33.51,146.22,-0.062
33.53,146.04,-0.062
33.55,145.86,-0.062
33.57,145.68,-0.062
33.58,145.49,-0.062
33.60,145.31,-0.062
33.62,145.13,-0.062
33.64,144.94,-0.062
33.66,144.76,-0.061
33.68,144.57,-0.061
33.69,144.39,-0.061
33.71,144.21,-0.061
33.73,144.02,-0.061
33.75,143.84,-0.061
33.77,143.66,-0.061
33.79,143.47,-0.061
33.81,143.29,-0.061
33.82,143.11,-0.061
33.84,142.93,-0.061
33.86,142.74,-0.061
33.88,142.56,-0.061
33.90,142.38,-0.061
33.92,142.19,-0.061
33.93,142.01,-0.061
33.95,141.83,-0.061
33.97,141.64,-0.061
33.99,141.46,-0.061
34.01,141.28,-0.061
34.03,141.09,-0.061
34.04,140.91,-0.061
34.06,140.72,-0.061
34.08,140.54,-0.061
34.10,140.36,-0.061
34.12,140.18,-0.061
34.14,139.99,-0.061
34.15,139.81,-0.061
34.17,139.63,-0.061
34.19,139.44,-0.061
34.21,139.26,-0.061
34.23,139.08,-0.061
34.24,138.89,-0.061
34.26,138.71,-0.061
34.28,138.53,-0.061
34.30,138.34,-0.061
34.32,138.16,-0.061
34.34,137.98,-0.061
34.36,137.79,-0.061
34.37,137.61,-0.061
34.39,137.43,-0.061
34.41,137.24,-0.061
34.43,137.06,-0.061
34.45,136.88,-0.061
34.46,136.69,-0.060
34.48,136.51,-0.060
34.50,136.33,-0.060
34.52,136.14,-0.060
34.54,135.96,-0.060
34.56,135.78,-0.060
34.58,135.59,-0.060
34.59,135.41,-0.060
34.61,135.23,-0.060
34.63,135.04,-0.060
34.65,134.86,-0.060
34.67,134.68,-0.060
34.69,134.49,-0.060
34.70,134.31,-0.060
34.72,134.13,-0.060
34.74,133.95,-0.060
34.76,133.76,-0.060
34.78,133.58,-0.060
34.79,133.39,-0.060
34.81,133.21,-0.060
34.83,133.03,-0.060
34.85,132.84,-0.060
34.87,132.66,-0.060
34.89,132.48,-0.060
34.91,132.29,-0.060
34.92,132.11,-0.060
34.94,131.93,-0.060
34.96,131.74,-0.060
34.98,131.56,-0.060
35.00,131.38,-0.060
35.01,131.19,-0.060
35.03,131.01,-0.060
35.05,130.83,-0.060
35.07,130.64,-0.060
35.09,130.46,-0.060
35.11,130.28,-0.060
35.13,130.10,-0.060
35.14,129.91,-0.060
35.16,129.73,-0.060
35.18,129.55,-0.060
35.20,129.36,-0.060
35.22,129.18,-0.060
35.24,128.99,-0.060
[...]
119.22,10.99,0.028
119.24,11.17,0.028
119.25,11.36,0.028
119.27,11.54,0.028
119.29,11.72,0.028
119.31,11.91,0.028
119.33,12.09,0.028
119.35,12.27,0.027
119.36,12.46,0.027
119.38,12.64,0.027
119.40,12.82,0.027
119.42,13.01,0.027
119.44,13.19,0.027
119.46,13.37,0.027
119.48,13.56,0.027
119.49,13.74,0.027
119.51,13.93,0.027
119.53,14.11,0.027
119.55,14.29,0.027
119.57,14.48,0.027
119.59,14.66,0.027
119.60,14.84,0.027
119.62,15.03,0.027
119.64,15.21,0.027
119.66,15.39,0.027
119.68,15.58,0.027
119.70,15.76,0.027
119.71,15.94,0.027
119.73,16.13,0.027
119.75,16.31,0.027
119.77,16.49,0.027
119.79,16.68,0.027
119.80,16.86,0.027
119.82,17.04,0.027
119.84,17.23,0.027
119.86,17.41,0.027
119.88,17.59,0.027
119.90,17.78,0.027
119.91,17.96,0.027
119.93,18.15,0.027
119.95,18.33,0.027
119.97,18.51,0.027
119.99,18.70,0.027
120.01,18.88,0.027
120.03,19.06,0.027
120.04,19.25,0.027
120.06,19.43,0.027
120.08,19.61,0.027
120.10,19.80,0.027
120.12,19.98,0.027
120.14,20.16,0.027
120.15,20.35,0.027
120.17,20.53,0.027
120.19,20.71,0.027
120.21,20.90,0.027
120.23,21.08,0.027
120.25,21.26,0.027
120.26,21.45,0.027
120.28,21.63,0.027
120.30,21.81,0.027
120.32,22.00,0.027
120.34,22.18,0.027
120.35,22.37,0.027
120.37,22.55,0.027
120.39,22.73,0.027
120.41,22.92,0.027
120.43,23.10,0.027
120.45,23.28,0.027
120.46,23.47,0.027
120.48,23.65,0.027
120.50,23.83,0.027
120.52,24.02,0.027
120.54,24.20,0.027
120.56,24.38,0.027
120.58,24.57,0.027
120.59,24.75,0.027
120.61,24.93,0.027
120.63,25.12,0.027
120.65,25.30,0.027
120.67,25.49,0.027
120.69,25.67,0.027
120.70,25.85,0.027
120.72,26.04,0.027
120.74,26.22,0.027
120.76,26.40,0.027
120.78,26.59,0.027
120.80,26.77,0.027
120.81,26.95,0.027
120.83,27.14,0.027
120.85,27.32,0.027
120.87,27.50,0.027
120.89,27.69,0.027
120.90,27.87,0.027
120.92,28.05,0.027
120.94,28.24,0.027
120.96,28.42,0.027
120.98,28.61,0.027
121.00,28.79,0.027
121.01,28.97,0.027
121.03,29.16,0.027
121.05,29.34,0.027
121.07,29.52,0.027
121.09,29.71,0.027
121.11,29.89,0.027
121.13,30.07,0.027
121.14,30.26,0.027
121.16,30.44,0.027
121.18,30.63,0.027
121.20,30.81,0.027
121.22,30.99,0.027
121.24,31.18,0.027
121.25,31.36,0.027
121.27,31.54,0.027
121.29,31.73,0.027
121.31,31.91,0.027
121.33,32.09,0.027
121.35,32.28,0.027
121.36,32.46,0.027
121.38,32.65,0.027
121.40,32.83,0.027
121.42,33.01,0.027
121.44,33.19,0.027
121.45,33.38,0.027
121.47,33.56,0.027
121.49,33.75,0.027
121.51,33.93,0.027
121.53,34.11,0.027
121.55,34.30,0.027
121.56,34.48,0.027
121.58,34.66,0.027
121.60,34.85,0.027
121.62,35.03,0.026
121.64,35.21,0.026
121.66,35.40,0.026
121.68,35.58,0.026
121.69,35.76,0.026
121.71,35.95,0.026
121.73,36.13,0.026
121.75,36.32,0.026
121.77,36.50,0.026
121.79,36.68,0.026
121.80,36.87,0.026
121.82,37.05,0.026
121.84,37.23,0.026
121.86,37.42,0.026
121.88,37.60,0.026
121.90,37.78,0.026
121.91,37.97,0.026
121.93,38.15,0.026
121.95,38.33,0.026
121.97,38.52,0.026
121.99,38.70,0.026
122.00,38.89,0.026
122.02,39.07,0.026
122.04,39.25,0.026
122.06,39.44,0.026
122.08,39.62,0.026
122.10,39.80,0.026
122.11,39.99,0.026
122.13,40.17,0.026
122.15,40.35,0.026
122.17,40.54,0.026
122.19,40.72,0.026
122.21,40.90,0.026
122.23,41.09,0.026
122.24,41.27,0.026
122.26,41.46,0.026
122.28,41.64,0.026
122.30,41.82,0.026
122.32,42.00,0.026
122.34,42.19,0.026
122.35,42.37,0.026
122.37,42.56,0.026
122.39,42.74,0.026
122.41,42.92,0.026
122.43,43.11,0.026
122.45,43.29,0.026
122.46,43.47,0.026
122.48,43.66,0.026
122.50,43.84,0.026
122.52,44.02,0.026
122.54,44.21,0.026
122.55,44.39,0.026
122.57,44.58,0.026
122.59,44.76,0.026
122.61,44.94,0.026
122.63,45.13,0.026
122.65,45.31,0.026
122.66,45.49,0.026
122.68,45.68,0.026
122.70,45.86,0.026
122.72,46.04,0.026
122.74,46.23,0.026
122.76,46.41,0.026
122.78,46.59,0.026
122.79,46.78,0.026
122.81,46.96,0.026
122.83,47.14,0.026
122.85,47.33,0.026
122.87,47.51,0.026
122.89,47.69,0.026
122.90,47.88,0.026
122.92,48.06,0.026
122.94,48.24,0.026
122.96,48.43,0.026
122.98,48.61,0.026
123.00,48.79,0.026
123.01,48.98,0.026
123.03,49.16,0.026
123.05,49.35,0.026
123.07,49.53,0.026
123.09,49.71,0.026
123.10,49.90,0.026
123.12,50.08,0.026
123.14,50.26,0.026
123.16,50.45,0.026
123.18,50.63,0.026
123.20,50.81,0.026
123.21,51.00,0.026
123.23,51.18,0.026
123.25,51.37,0.026
123.27,51.55,0.026
123.29,51.73,0.026
123.31,51.92,0.026
123.33,52.10,0.026
123.34,52.28,0.026
123.36,52.47,0.026
123.38,52.65,0.026
123.40,52.83,0.026
123.42,53.02,0.026
123.44,53.20,0.026
123.45,53.38,0.026
123.47,53.57,0.026
123.49,53.75,0.026
123.51,53.93,0.026
123.53,54.12,0.026
123.55,54.30,0.026
123.56,54.49,0.026
123.58,54.67,0.026
123.60,54.85,0.026
123.62,55.04,0.026
123.64,55.22,0.026
123.65,55.40,0.026
123.67,55.59,0.026
123.69,55.77,0.026
123.71,55.95,0.026
123.73,56.14,0.026
123.75,56.32,0.026
123.76,56.50,0.026
123.78,56.69,0.026
123.80,56.87,0.026
123.82,57.05,0.026
123.84,57.24,0.026
123.86,57.42,0.026
123.88,57.61,0.026
123.89,57.79,0.026
123.91,57.97,0.026
123.93,58.16,0.026
123.95,58.34,0.026
123.97,58.52,0.026
123.99,58.71,0.026
124.00,58.89,0.026
124.02,59.07,0.026
124.04,59.26,0.026
124.06,59.44,0.026
124.08,59.62,0.026
124.10,59.81,0.026
124.11,59.99,0.026
124.13,60.17,0.026
124.15,60.36,0.026
124.17,60.54,0.026
124.19,60.73,0.026
124.20,60.91,0.026
124.22,61.09,0.026
124.24,61.28,0.026
124.26,61.46,0.026
124.28,61.64,0.026
124.30,61.83,0.026
124.31,62.01,0.026
124.33,62.19,0.026
124.35,62.38,0.026
124.37,62.56,0.026
124.39,62.74,0.026
124.41,62.93,0.026
124.43,63.11,0.026
124.44,63.29,0.026
124.46,63.48,0.026
124.48,63.66,0.026
124.50,63.84,0.026
124.52,64.03,0.026
124.54,64.21,0.026
124.55,64.39,0.026
124.57,64.58,0.026
124.59,64.76,0.026
124.61,64.95,0.026
124.63,65.13,0.026
124.65,65.31,0.026
124.66,65.50,0.026
124.68,65.68,0.026
124.70,65.86,0.026
124.72,66.05,0.026
124.74,66.23,0.026
124.75,66.41,0.026
124.77,66.60,0.026
124.79,66.78,0.026
124.81,66.96,0.026
124.83,67.15,0.026
124.85,67.33,0.026
124.86,67.52,0.026
124.88,67.70,0.026
124.90,67.88,0.026
124.92,68.07,0.026
124.94,68.25,0.026
124.96,68.43,0.026
124.98,68.62,0.026
124.99,68.80,0.026
125.01,68.98,0.026
125.03,69.17,0.026
125.05,69.35,0.026
125.07,69.54,0.026
125.09,69.72,0.026
125.10,69.90,0.026
125.12,70.09,0.026
125.14,70.27,0.026
125.16,70.45,0.026
125.18,70.64,0.026
125.20,70.82,0.026
125.21,71.00,0.026
125.23,71.19,0.026
125.25,71.37,0.026
125.27,71.56,0.026
125.29,71.74,0.026
125.30,71.92,0.026
125.32,72.11,0.026
125.34,72.29,0.026
125.36,72.47,0.026
125.38,72.66,0.026
125.40,72.84,0.026
125.41,73.03,0.026
125.43,73.21,0.026
125.45,73.40,0.026
125.47,73.58,0.026
125.49,73.77,0.026
125.51,73.95,0.026
125.53,74.13,0.026
125.54,74.32,0.026
125.56,74.50,0.026
125.58,74.68,0.026
125.60,74.86,0.026
125.62,75.05,0.026
125.64,75.23,0.026
125.65,75.41,0.026
125.67,75.60,0.026
125.69,75.78,0.026
125.71,75.96,0.026
125.73,76.14,0.026
125.75,76.32,0.026
125.76,76.51,0.026
125.78,76.69,0.026
125.80,76.87,0.026
125.82,77.06,0.026
125.84,77.24,0.026
125.85,77.42,0.026
125.87,77.61,0.026
125.89,77.79,0.026
125.91,77.97,0.026
125.93,78.16,0.026
125.95,78.34,0.026
125.96,78.52,0.026
125.98,78.71,0.026
126.00,78.89,0.026
126.02,79.08,0.026
126.04,79.26,0.026
126.06,79.44,0.026
126.08,79.63,0.026
126.09,79.81,0.026
126.11,80.00,0.026
126.13,80.18,0.026
126.15,80.37,0.026
126.17,80.55,0.026
126.19,80.73,0.026
126.20,80.92,0.026
126.22,81.10,0.026
126.24,81.28,0.026
126.26,81.47,0.026
126.28,81.65,0.026
126.30,81.83,0.026
126.31,82.02,0.026
126.33,82.20,0.026
126.35,82.38,0.026
126.37,82.57,0.026
126.39,82.75,0.026
126.40,82.93,0.026
126.42,83.12,0.026
126.44,83.30,0.026
126.46,83.48,0.026
126.48,83.67,0.026
126.50,83.85,0.026
126.51,84.03,0.026
126.53,84.22,0.026
126.55,84.40,0.026
126.57,84.58,0.026
126.59,84.77,0.026
126.61,84.95,0.026
126.63,85.13,0.026
126.64,85.32,0.026
126.66,85.50,0.026
126.68,85.68,0.026
126.70,85.87,0.026
126.72,86.05,0.026
126.74,86.23,0.026
126.75,86.42,0.026
126.77,86.60,0.026
126.79,86.78,0.026
126.81,86.97,0.026
126.83,87.15,0.026
126.85,87.33,0.026
126.86,87.52,0.026
126.88,87.70,0.026
126.90,87.89,0.026
126.92,88.07,0.026
126.94,88.25,0.026
126.95,88.44,0.026
126.97,88.62,0.026
126.99,88.80,0.026
127.01,88.99,0.026
127.03,89.17,0.026
127.05,89.35,0.026
127.06,89.54,0.026
127.08,89.72,0.026
127.10,89.91,0.026
127.12,90.09,0.026
127.14,90.27,0.026
127.16,90.45,0.026
127.18,90.64,0.026
127.19,90.82,0.026
127.21,91.00,0.026
127.23,91.19,0.026
127.25,91.37,0.026
127.27,91.55,0.026
127.29,91.74,0.026
127.30,91.92,0.026
127.32,92.10,0.026
127.34,92.29,0.026
127.36,92.47,0.026
127.38,92.66,0.026
127.40,92.84,0.026
127.41,93.02,0.026
127.43,93.21,0.026
127.45,93.39,0.026
127.47,93.57,0.026
127.49,93.76,0.026
127.50,93.94,0.026
127.52,94.12,0.026
127.54,94.31,0.026
127.56,94.49,0.026
127.58,94.67,0.026
127.60,94.86,0.026
127.61,95.04,0.026
127.63,95.22,0.026
127.65,95.41,0.026
127.67,95.59,0.026
127.69,95.78,0.026
127.71,95.96,0.026
127.73,96.14,0.026
127.74,96.33,0.026
127.76,96.51,0.026
127.78,96.69,0.026
127.80,96.88,0.026
127.82,97.06,0.026
127.84,97.24,0.026
127.85,97.43,0.026
127.87,97.61,0.026
127.89,97.79,0.026
127.91,97.98,0.026
127.93,98.16,0.026
127.95,98.34,0.026
127.96,98.53,0.026
127.98,98.71,0.026
128.00,98.89,0.026
128.02,99.08,0.026
128.04,99.26,0.026
128.05,99.44,0.026
128.07,99.63,0.026
128.09,99.81,0.026
128.11,100.00,0.026
128.13,100.18,0.026
128.15,100.36,0.026
128.16,100.55,0.026
128.18,100.73,0.026
128.20,100.91,0.026
128.22,101.09,0.026
128.24,101.28,0.026
128.26,101.46,0.026
128.28,101.65,0.026
128.29,101.83,0.026
128.31,102.01,0.026
128.33,102.20,0.026
128.35,102.38,0.026
128.37,102.57,0.026
128.39,102.75,0.026
128.40,102.93,0.026
128.42,103.12,0.026
128.44,103.30,0.026
128.46,103.48,0.026
128.48,103.67,0.026
128.50,103.85,0.026
128.51,104.03,0.026
128.53,104.22,0.026
128.55,104.40,0.026
128.57,104.58,0.026
128.59,104.77,0.026
128.60,104.95,0.026
128.62,105.13,0.026
128.64,105.32,0.026
128.66,105.50,0.026
128.68,105.68,0.026
128.70,105.87,0.026
128.71,106.05,0.026
128.73,106.24,0.026
128.75,106.42,0.026
128.77,106.60,0.026
128.79,106.78,0.026
128.81,106.97,0.026
128.83,107.15,0.026
128.84,107.33,0.026
128.86,107.52,0.026
128.88,107.70,0.026
128.90,107.88,0.026
128.92,108.07,0.026
128.94,108.25,0.026
128.95,108.44,0.026
128.97,108.62,0.026
128.99,108.80,0.026
129.01,108.99,0.026
129.03,109.17,0.026
129.05,109.35,0.026
129.06,109.54,0.026
129.08,109.72,0.026
129.10,109.90,0.026
129.12,110.09,0.026
129.14,110.27,0.026
129.15,110.45,0.026
129.17,110.64,0.027
129.19,110.82,0.027
129.21,111.00,0.027
129.23,111.19,0.027
129.25,111.37,0.027
129.26,111.56,0.027
129.28,111.74,0.027
129.30,111.92,0.027
129.32,112.11,0.027
129.34,112.29,0.026
129.36,112.47,0.027
129.38,112.66,0.027
129.39,112.84,0.027
129.41,113.02,0.027
129.43,113.21,0.027
129.45,113.39,0.027
129.47,113.57,0.027
129.49,113.76,0.027
129.50,113.94,0.027
129.52,114.12,0.027
129.54,114.31,0.027
129.56,114.49,0.027
129.58,114.67,0.027
129.60,114.86,0.027
129.61,115.04,0.027
129.63,115.22,0.027
129.65,115.41,0.027
129.67,115.59,0.027
129.69,115.77,0.027
129.70,115.96,0.027
129.72,116.14,0.027
129.74,116.32,0.027
129.76,116.51,0.027
129.78,116.69,0.027
129.80,116.87,0.027
129.81,117.06,0.027
129.83,117.24,0.027
129.85,117.43,0.027
129.87,117.61,0.027
129.89,117.79,0.027
129.91,117.98,0.027
129.93,118.16,0.027
129.94,118.34,0.027
129.96,118.53,0.027
129.98,118.71,0.027
130.00,118.89,0.027
130.02,119.08,0.027
130.04,119.26,0.027
130.05,119.44,0.027
130.07,119.63,0.027
130.09,119.81,0.027
130.11,119.99,0.027
130.13,120.18,0.027
130.15,120.36,0.027
130.16,120.54,0.027
130.18,120.73,0.027
130.20,120.91,0.027
130.22,121.10,0.027
130.24,121.28,0.027
130.25,121.46,0.027
130.27,121.65,0.027
130.29,121.83,0.027
130.31,122.01,0.027
130.33,122.20,0.027
130.35,122.38,0.027
130.36,122.56,0.027
130.38,122.75,0.027
130.40,122.93,0.027
130.42,123.11,0.027
130.44,123.30,0.027
130.46,123.48,0.027
130.48,123.66,0.027
130.49,123.85,0.027
130.51,124.03,0.027
130.53,124.21,0.027
130.55,124.40,0.027
130.57,124.58,0.027
130.59,124.77,0.027
130.60,124.95,0.027
130.62,125.13,0.027
130.64,125.32,0.027
130.66,125.50,0.027
130.68,125.68,0.027
130.70,125.87,0.027
130.71,126.05,0.027
130.73,126.23,0.027
130.75,126.42,0.027
130.77,126.60,0.027
130.79,126.78,0.027
130.80,126.97,0.027
130.82,127.15,0.027
130.84,127.33,0.027
130.86,127.52,0.027
130.88,127.70,0.027
130.90,127.89,0.027
130.91,128.07,0.027
130.93,128.25,0.027
130.95,128.44,0.027
130.97,128.62,0.027
130.99,128.80,0.027
131.01,128.99,0.027
131.03,129.17,0.027
131.04,129.36,0.027
131.06,129.54,0.027
131.08,129.72,0.027
131.10,129.90,0.027
131.12,130.09,0.027
131.14,130.27,0.027
131.15,130.45,0.027
131.17,130.64,0.027
131.19,130.82,0.027
131.21,131.00,0.027
131.23,131.19,0.027
131.25,131.37,0.027
131.26,131.55,0.027
131.28,131.74,0.027
131.30,131.92,0.027
131.32,132.10,0.027
131.34,132.29,0.027
131.35,132.47,0.027
131.37,132.65,0.027
131.39,132.84,0.027
131.41,133.02,0.027
131.43,133.20,0.027
131.45,133.39,0.027
131.46,133.57,0.027
131.48,133.76,0.027
131.50,133.94,0.027
131.52,134.12,0.027
131.54,134.31,0.027
131.56,134.49,0.027
131.58,134.68,0.027
131.59,134.86,0.027
131.61,135.04,0.027
131.63,135.23,0.027
131.65,135.41,0.027
131.67,135.59,0.027
131.69,135.78,0.027
131.70,135.96,0.027
131.72,136.14,0.027
131.74,136.33,0.027
131.76,136.51,0.027
131.78,136.69,0.027
131.80,136.88,0.027
131.81,137.06,0.027
131.83,137.24,0.027
131.85,137.43,0.027
131.87,137.61,0.027
131.89,137.79,0.027
131.90,137.98,0.027
131.92,138.16,0.027
131.94,138.35,0.027
131.96,138.53,0.027
131.98,138.71,0.027
132.00,138.90,0.027
132.01,139.08,0.027
132.03,139.26,0.027
132.05,139.45,0.027
132.07,139.63,0.027
132.09,139.81,0.027
132.11,140.00,0.027
132.13,140.18,0.027
132.14,140.36,0.027
132.16,140.55,0.027
132.18,140.73,0.027
132.20,140.91,0.027
132.22,141.10,0.027
132.24,141.28,0.027
132.25,141.47,0.027
132.27,141.65,0.027
132.29,141.83,0.027
132.31,142.02,0.027
132.33,142.20,0.027
132.35,142.38,0.027
132.36,142.57,0.027
132.38,142.75,0.027
132.40,142.93,0.027
132.42,143.12,0.027
132.44,143.30,0.028
132.45,143.48,0.028
132.47,143.67,0.028
132.49,143.85,0.028
132.51,144.03,0.028
132.53,144.22,0.028
132.55,144.40,0.027
132.56,144.58,0.027
132.58,144.77,0.028
132.60,144.95,0.028
132.62,145.13,0.028
132.64,145.32,0.028
132.66,145.50,0.028
132.68,145.68,0.028
132.69,145.87,0.028
132.71,146.05,0.028
132.73,146.23,0.028
132.75,146.42,0.028
132.77,146.60,0.028
132.79,146.78,0.028
132.80,146.97,0.028
132.82,147.15,0.028
132.84,147.33,0.028
132.86,147.52,0.028
132.88,147.70,0.028
132.90,147.88,0.028
132.91,148.07,0.028
132.93,148.25,0.028
132.95,148.43,0.028
132.97,148.62,0.028
132.99,148.80,0.028
133.00,148.98,0.028
133.02,149.17,0.028
133.04,149.35,0.028
133.06,149.53,0.028
133.08,149.72,0.028
133.10,149.90,0.028
133.11,150.08,0.028
133.13,150.27,0.028
133.15,150.45,0.028
133.17,150.64,0.028
133.19,150.82,0.028
133.21,151.00,0.028
133.23,151.19,0.028
133.24,151.37,0.028
133.26,151.55,0.028
133.28,151.74,0.028
133.30,151.92,0.028
133.32,152.10,0.028
133.34,152.29,0.028
133.35,152.47,0.028
133.37,152.65,0.028
133.39,152.84,0.028
133.41,153.02,0.028
133.43,153.20,0.028
133.45,153.39,0.028
133.46,153.57,0.028
133.48,153.76,0.028
133.50,153.94,0.028
133.52,154.12,0.028
133.54,154.31,0.028
133.55,154.49,0.028
133.57,154.67,0.028
133.59,154.85,0.028
133.61,155.04,0.028
133.63,155.22,0.028
133.65,155.40,0.028
133.66,155.59,0.028
133.68,155.77,0.028
133.70,155.96,0.028
133.72,156.14,0.028
133.74,156.32,0.029
133.76,156.50,0.029
133.78,156.69,0.042
133.79,156.84,0.262
133.81,156.94,0.581
133.83,157.02,0.816
133.85,157.10,1.033
133.87,157.17,1.244
133.89,157.25,1.454
133.90,157.32,1.661
133.92,157.40,1.865
133.94,157.48,2.060
133.96,157.56,2.238
133.98,157.65,2.415
134.00,157.74,2.574
134.01,157.85,2.597
134.03,158.14,1.497
134.05,158.58,0.902
134.07,158.97,0.647
134.09,159.32,0.487
134.10,159.62,0.374
134.12,159.90,0.288
134.14,160.15,0.224
134.16,160.39,0.175
134.18,160.61,0.139
134.20,160.82,0.111
134.21,161.03,0.090
134.23,161.23,0.074
134.25,161.42,0.062
134.27,161.62,0.054
134.29,161.81,0.048
134.31,162.00,0.042
134.33,162.18,0.039
134.34,162.37,0.036
134.36,162.56,0.034
134.38,162.74,0.033
134.40,162.92,0.032
134.42,163.11,0.031
134.44,163.29,0.031
134.45,163.48,0.030
134.47,163.66,0.030
134.49,163.84,0.029
134.51,164.03,0.029
134.53,164.21,0.029
134.55,164.40,0.029
134.56,164.58,0.029
134.58,164.76,0.029
134.60,164.95,0.029
134.62,165.13,0.028
134.64,165.31,0.028
134.65,165.50,0.028
134.67,165.68,0.028
134.69,165.86,0.028
134.71,166.05,0.028
134.73,166.23,0.028
134.75,166.41,0.028
134.76,166.60,0.028
134.78,166.78,0.028
134.80,166.96,0.028
134.82,167.15,0.028
134.84,167.33,0.028
134.86,167.51,0.028
134.88,167.70,0.028
134.89,167.88,0.028
134.91,168.07,0.028
134.93,168.25,0.028
134.95,168.43,0.028
134.97,168.62,0.028
134.99,168.80,0.028
135.00,168.98,0.028
135.02,169.17,0.028
135.04,169.35,0.028
135.06,169.53,0.028
135.08,169.72,0.028
135.10,169.90,0.028
135.11,170.08,0.028
135.13,170.27,0.028
135.15,170.45,0.028
135.17,170.63,0.028
135.19,170.82,0.028
135.20,171.00,0.028
135.22,171.19,0.028
135.24,171.37,0.028
135.26,171.55,0.028
135.28,171.74,0.028
135.30,171.92,0.028
135.31,172.10,0.028
135.33,172.29,0.028
135.35,172.47,0.028
135.37,172.65,0.028
135.39,172.84,0.028
135.41,173.02,0.028
135.43,173.20,0.028
135.44,173.39,0.028
135.46,173.57,0.028
135.48,173.75,0.028
135.50,173.94,0.028
135.52,174.12,0.028
135.54,174.30,0.028
135.55,174.49,0.028
135.57,174.67,0.028
135.59,174.85,0.028
135.61,175.04,0.028
135.63,175.22,0.028
135.65,175.40,0.028
135.66,175.59,0.028
135.68,175.77,0.028
135.70,175.95,0.028
135.72,176.14,0.028
135.74,176.32,0.028
135.75,176.50,0.028
135.77,176.69,0.028
135.79,176.87,0.028
135.81,177.06,0.028
135.83,177.24,0.028
135.85,177.42,0.028
135.86,177.61,0.028
135.88,177.79,0.028
135.90,177.97,0.028
135.92,178.16,0.028
135.94,178.34,0.028
135.96,178.52,0.028
135.98,178.70,0.028
135.99,178.89,0.028
136.01,179.07,0.028
136.03,179.26,0.028
136.05,179.44,0.028
136.07,179.62,0.028
136.09,179.81,0.028
136.10,179.99,0.028
136.12,180.17,0.028
136.14,180.35,0.028
136.16,180.54,0.028
136.18,180.72,0.028
136.20,180.91,0.028
136.21,181.09,0.028
136.23,181.27,0.028
136.25,181.46,0.028
136.27,181.64,0.028
136.29,181.82,0.028
136.30,182.01,0.028
136.32,182.19,0.028
136.34,182.37,0.028
136.36,182.56,0.028
136.38,182.74,0.028
136.40,182.93,0.028
136.41,183.11,0.028
136.43,183.29,0.028
136.45,183.48,0.028
136.47,183.66,0.028
136.49,183.84,0.028
136.51,184.03,0.028
136.53,184.21,0.028
136.54,184.39,0.028
136.56,184.58,0.028
136.58,184.76,0.028
136.60,184.94,0.028
136.62,185.13,0.028
136.63,185.31,0.028
136.65,185.49,0.028
136.67,185.68,0.028
136.69,185.86,0.028
136.71,186.04,0.028
136.73,186.23,0.028
136.75,186.41,0.028
136.76,186.60,0.028
136.78,186.78,0.028
136.80,186.96,0.028
136.82,187.15,0.028
136.84,187.33,0.028
136.85,187.51,0.028
136.87,187.70,0.028
136.89,187.88,0.028
136.91,188.06,0.028
136.93,188.25,0.028
136.95,188.43,0.028
136.97,188.61,0.028
136.98,188.80,0.028
137.00,188.98,0.028
137.02,189.16,0.028
137.04,189.35,0.028
137.06,189.53,0.028
137.08,189.71,0.028
137.09,189.90,0.028
137.11,190.08,0.028
137.13,190.26,0.028
137.15,190.45,0.028
137.17,190.63,0.028
137.18,190.81,0.028
137.20,191.00,0.028
137.22,191.18,0.028
137.24,191.36,0.028
137.26,191.55,0.028
137.28,191.73,0.028
137.30,191.91,0.028
137.31,192.10,0.028
137.33,192.28,0.028
137.35,192.46,0.028
137.37,192.65,0.028
137.39,192.83,0.028
137.40,193.02,0.028
137.42,193.20,0.028
137.44,193.38,0.028
137.46,193.57,0.028
137.48,193.75,0.028
137.50,193.93,0.028
137.52,194.12,0.028
137.53,194.30,0.028
137.55,194.48,0.028
137.57,194.67,0.028
137.59,194.85,0.028
137.61,195.03,0.028
137.63,195.22,0.028
137.64,195.40,0.028
137.66,195.58,0.028
137.68,195.77,0.028
137.70,195.95,0.028
137.72,196.13,0.028
137.73,196.32,0.028
137.75,196.50,0.028
137.77,196.68,0.028
137.79,196.87,0.028
137.81,197.05,0.028
137.83,197.23,0.028
137.85,197.42,0.028
137.86,197.60,0.028
137.88,197.79,0.028
137.90,197.97,0.028
137.92,198.15,0.028
137.94,198.34,
137.95,198.52,
137.97,198.70,
137.99,,
137.99,,