File: DSC/Olivia/2025_08_10_1CBN_3PVP90_MeOH_ASD_n60C_250C_10Cmin_x3.csv
Filename,2025_08_10_1CBN_3PVP90_MeOH_ASD_n60C_250C_10Cmin_x3
Instrument name,DSC2A-00468 (192.168.1.100)
Operator,Yarger
rundate,8/10/2025
Sample name,2025_08_10_1CBN_3PVP90_MeOH_ASD_n60C_250C_10Cmin_x3
proceduresegments,Data Off ; Equilibrate -60.00 °C; Data On ; Ramp 10.00 °C/min to 250.00 °C; Data Off ; Isothermal 2.0 min; Data On ; Ramp 10.00 °C/min to -60.00 °C; Data Off ; Isothermal 2.0 min; Data On ; Ramp 10.00 °C/min to 250.00 °C; Data Off ; Isothermal 2.0 min; Data On ; Ramp 10.00 °C/min to -60.00 °C; Data Off ; Isothermal 2.0 min; Data On ; Ramp 10.00 °C/min to 250.00 °C
[File Parameters]
Run date,8/10/2025 7:17:58 PM
Trios version,5.1.1.46572
Original File Name,
Current File Name,D:\DSC2500\JYarger\2025_08_10_1CBN_3PVP90_MeOH_ASD_n60C_250C_10Cmin_x3.tri
[Procedure]
Procedure Name,TS_n60C_250C_10Cmin_x3
Sample Name,2025_08_10_1CBN_3PVP90_MeOH_ASD_n60C_250C_10Cmin_x3
Sample Mass,32.36 mg
Reference Sample Mass,0 mg
Pan Mass,2.94 mg
Pan Number,17
Reference Pan Mass,32.42 mg
Reference Pan Number,10
Pan Type,Aluminum
Comments,Thermal support Al pans/lids. DSC_Samples_A2_Tray_August2025 google sheet.
Project Name,Pharma
Operator,Yarger
Test,Custom
Unload Max Temperature,30
Unload Min Temperature,30
Load Max Temperature,30
Load Min Temperature,30
Stop on Gas Flow Error,Yes
[Signal List]
Signal #1,Time (min)
Signal #2,Temperature (°C)
Signal #3,Heat Flow (mW)
Signal #4,Delta T (µV)
Signal #5,Delta Tzero (µV)
Signal #6,Tzero Temperature (°C)
Signal #7,Cell Purge (mL/min)
Signal #8,Heater Temp (°C)
Signal #9,Power Delivered (W)
Signal #10,Reference Junction Temperature (°C)
Signal #11,Flange Temperature (°C)
Signal #12,Heat Flow Phase (rad)
Signal #13,Total Heat Capacity (J/°C)
Signal #14,Heat Capacity (J/°C)
[Configuration]
Company Name,ASU
Instrument Name,DSC2A-00468
Instrument Type,DSC2500
Serial Number,DSC2A-00468
IP,192.168.1.100
Location of Instrument,MRRC
DisplayType,Unknown
Sample Interval ,0.1 s/pt
Selected Heat Flow,T4P
Exotherm Direction,Down
Cell Serial,DRC2-00792
Lid Type,Standard
Cooler,RCS 90
Leave Cooler on at End of Sequence,On
Gas 2,Nitrogen
Gas Selected,Channel 1
Flow Rate,50 mL/min
Secondary Purge,On
Licensed Heat Flow,Heat Flow T4P
Modulation Licensed,Yes
[Versions]
Common IDD Version,1
Cortex Version,VER 2.10.2.31
Driver,5.0.0.6
GDM Version,1.0.3.3
TouchscreenVersion,1.0.0.16145
FEP Version,1.2.1.21
FEP Bootloader,2.0.0.5
AutoSampler Version,2.1.1.26
Auto Sampler Bootloader,2.0.0.5
FCM Version,1.1.0.3
FCM Bootloader,2.0.0.5
[Experiment Logs]
Experiment Log Entry # 1,Data On set to 0
Experiment Log Entry # 3,Equilibrate Segment -60 (C) Started
Experiment Log Entry # 5,Data On set to 1
Experiment Log Entry # 7,Ramp Segment 10 C/min to 250 Started
Experiment Log Entry # 9,Data On set to 0
Experiment Log Entry # 11,Isothermal Segment 2 min started
Experiment Log Entry # 13,Data On set to 1
Experiment Log Entry # 15,Ramp Segment 10 C/min to -60 Started
Experiment Log Entry # 17,Data On set to 0
Experiment Log Entry # 19,Isothermal Segment 2 min started
Experiment Log Entry # 21,Data On set to 1
Experiment Log Entry # 23,Ramp Segment 10 C/min to 250 Started
Experiment Log Entry # 25,Data On set to 0
Experiment Log Entry # 27,Isothermal Segment 2 min started
Experiment Log Entry # 29,Data On set to 1
Experiment Log Entry # 31,Ramp Segment 10 C/min to -60 Started
Experiment Log Entry # 33,Data On set to 0
Experiment Log Entry # 35,Isothermal Segment 2 min started
Experiment Log Entry # 37,Data On set to 1
Experiment Log Entry # 39,Ramp Segment 10 C/min to 250 Started
[Method Log]
Method Log Entry # 1,Data Off
Method Log Entry # 2,Equilibrate -60 °C
Method Log Entry # 3,Data On
Method Log Entry # 4,(Ramp 1040148) Ramp 10 °C/minute to 250 °C
Method Log Entry # 5,Data Off
Method Log Entry # 6,Isothermal 2 minutes
Method Log Entry # 7,Data On
Method Log Entry # 8,(Ramp 1040152) Ramp 10 °C/minute to -60 °C
Method Log Entry # 9,Data Off
Method Log Entry # 10,Isothermal 2 minutes
Method Log Entry # 11,Data On
Method Log Entry # 12,(Ramp 1040156) Ramp 10 °C/minute to 250 °C
Method Log Entry # 13,Data Off
Method Log Entry # 14,Isothermal 2 minutes
Method Log Entry # 15,Data On
Method Log Entry # 16,(Ramp 1040160) Ramp 10 °C/minute to -60 °C
Method Log Entry # 17,Data Off
Method Log Entry # 18,Isothermal 2 minutes
Method Log Entry # 19,Data On
Method Log Entry # 20,(Ramp 1040164) Ramp 10 °C/minute to 250 °C
Cell Serial,DRC2-00792
[T1 Calibration]
Slope,-0.008529666
Offset,9.636258
Initial Temperature,98.23
GUID,f8bfdadc-4977-4fdf-ba6d-0ba9134940c3
[TZero Calibration]
Date Applied,11/29/2022 4:06:13 PM
Description,From -89.059 °C to 396.009 °C at 20.000°C/min
Gas Type,Nitrogen
Pan Type,None
Source Files 1,C:\Users\yargerlab\Desktop\DSC Data\General\TZero_calibration_11_29_22_2nd(2).tri
Source Files 2,C:\Users\yargerlab\Desktop\DSC Data\General\TZero_calibration_11_29_22_2nd(3).tri
Delta T Offset,13.05235
Delta T Slope,-0.007271007
Delta T0 Offset,-13.69128
Delta T0 Slope,0.06063341
[Temperature Calibration]
Date Applied,11/29/2022 7:12:28 PM
Description,From 106.590 °C to 186.590 °C at 10.000°C/min
Gas Type,Nitrogen
Pan Type,Tzero Aluminum Hermetic
Source Files 1,C:\Users\yargerlab\Desktop\DSC Data\General\Indium(6).tri
Measured 1,157.391
Known 1,156.598
[Cell Constant Calibration]
Date Applied,11/29/2022 7:12:29 PM
Description,From 106.590 °C to 186.590 °C at 10.000°C/min
Gas Type,Nitrogen
Pan Type,Tzero Aluminum Hermetic
Source Files 1,C:\Users\yargerlab\Desktop\DSC Data\General\Indium(6).tri
T4P KCell,1.006051
Onset Slope,63.26126 mW/°C
[Direct Cp Calibration]
Date Applied,11/30/2022 11:04:51 AM
Description,From -79.983 °C to 298.409 °C at 10.000°C/min
Gas Type,Nitrogen
Pan Type,Tzero Aluminum Hermetic
Source Files 1,C:\Users\yargerlab\Desktop\DSC Data\General\Sapphire_Heat_Capacity_11_30_22.tri
[Rev Cp Calibration]
Date Applied,11/30/2022 1:58:51 PM
Description,From -79.996 °C to 292.812 °C at 3.000°C/min
Gas Type,Nitrogen
Pan Type,Tzero Aluminum Hermetic
Source Files 1,C:\Users\yargerlab\Desktop\DSC Data\General\Sapphire_MDSC_Calibration_11_30_22.tri
[step]
Ramp 10.00 °C/min to 250.00 °C
Time,Temperature,Heat Flow (Normalized)
min,°C,W/g
0.00,-59.81,-0.006
0.02,-59.82,-0.006
0.04,-59.81,-0.005
0.07,-59.79,-0.005
0.09,-59.74,-0.006
0.11,-59.65,-0.006
0.13,-59.53,-0.006
0.15,-59.38,-0.003
0.17,-59.22,0.001
0.19,-59.03,0.004
0.22,-58.84,0.007
0.24,-58.64,0.010
0.26,-58.44,0.012
0.28,-58.23,0.014
0.30,-58.03,0.015
0.33,-57.82,0.016
0.35,-57.61,0.016
0.37,-57.40,0.017
0.39,-57.19,0.017
0.41,-56.98,0.017
0.43,-56.76,0.017
0.45,-56.55,0.017
0.48,-56.34,0.018
0.50,-56.13,0.018
0.52,-55.92,0.018
0.54,-55.70,0.018
0.56,-55.49,0.018
0.58,-55.28,0.018
0.61,-55.06,0.018
0.63,-54.85,0.018
0.65,-54.63,0.018
0.67,-54.42,0.018
0.69,-54.21,0.018
0.72,-53.99,0.018
0.74,-53.78,0.018
0.76,-53.56,0.018
0.78,-53.35,0.019
0.80,-53.13,0.019
0.82,-52.92,0.019
0.85,-52.70,0.019
0.87,-52.49,0.019
0.89,-52.28,0.019
0.91,-52.06,0.019
0.93,-51.84,0.019
0.95,-51.63,0.019
0.98,-51.41,0.019
1.00,-51.20,0.019
1.02,-50.98,0.019
1.04,-50.77,0.019
1.06,-50.55,0.019
1.08,-50.33,0.019
1.11,-50.12,0.019
1.13,-49.90,0.019
1.15,-49.69,0.019
1.17,-49.47,0.019
1.19,-49.25,0.019
1.21,-49.04,0.019
1.23,-48.82,0.019
1.26,-48.61,0.019
1.28,-48.39,0.019
1.30,-48.17,0.019
1.32,-47.96,0.019
1.34,-47.74,0.019
1.37,-47.52,0.019
1.39,-47.31,0.019
1.41,-47.09,0.019
1.43,-46.88,0.019
1.45,-46.66,0.019
1.47,-46.44,0.019
1.49,-46.22,0.019
1.52,-46.01,0.019
1.54,-45.79,0.020
1.56,-45.58,0.020
1.58,-45.36,0.020
1.60,-45.14,0.020
1.63,-44.92,0.020
1.65,-44.71,0.020
1.67,-44.49,0.020
1.69,-44.28,0.020
1.71,-44.06,0.020
1.73,-43.84,0.020
1.76,-43.62,0.020
1.78,-43.41,0.020
1.80,-43.19,0.020
1.82,-42.98,0.020
1.84,-42.76,0.020
1.86,-42.54,0.020
1.88,-42.32,0.020
1.91,-42.11,0.020
1.93,-41.89,0.020
1.95,-41.67,0.020
1.97,-41.46,0.020
1.99,-41.24,0.020
2.02,-41.02,0.020
2.04,-40.81,0.020
2.06,-40.59,0.020
2.08,-40.37,0.020
2.10,-40.16,0.020
2.12,-39.94,0.020
2.14,-39.72,0.020
2.17,-39.50,0.020
2.19,-39.29,0.020
2.21,-39.07,0.020
2.23,-38.85,0.020
2.25,-38.64,0.020
2.28,-38.42,0.020
2.30,-38.20,0.020
2.32,-37.98,0.020
2.34,-37.77,0.020
2.36,-37.55,0.020
2.38,-37.33,0.020
2.41,-37.12,0.020
2.43,-36.90,0.020
2.45,-36.68,0.020
2.47,-36.47,0.020
2.49,-36.25,0.020
2.51,-36.03,0.020
2.54,-35.81,0.020
2.56,-35.60,0.020
2.58,-35.38,0.020
2.60,-35.17,0.020
2.62,-34.95,0.020
2.64,-34.73,0.020
2.66,-34.51,0.020
2.69,-34.30,0.020
2.71,-34.08,0.020
2.73,-33.86,0.020
2.75,-33.65,0.020
2.77,-33.43,0.020
2.79,-33.21,0.020
2.82,-32.99,0.020
2.84,-32.78,0.020
2.86,-32.56,0.020
2.88,-32.34,0.020
2.90,-32.13,0.020
2.93,-31.91,0.020
2.95,-31.69,0.020
2.97,-31.48,0.020
2.99,-31.26,0.020
3.01,-31.04,0.020
3.03,-30.83,0.020
3.06,-30.61,0.020
3.08,-30.39,0.020
3.10,-30.17,0.020
3.12,-29.96,0.020
3.14,-29.74,0.020
3.16,-29.52,0.020
3.19,-29.31,0.020
3.21,-29.09,0.020
3.23,-28.87,0.020
3.25,-28.65,0.020
3.27,-28.44,0.020
3.29,-28.22,0.020
3.31,-28.01,0.020
3.34,-27.79,0.020
3.36,-27.57,0.020
3.38,-27.35,0.020
3.40,-27.14,0.020
3.42,-26.92,0.020
3.44,-26.70,0.020
3.47,-26.48,0.020
3.49,-26.27,0.020
3.51,-26.05,0.020
3.53,-25.84,0.020
3.55,-25.62,0.020
3.58,-25.40,0.020
3.60,-25.19,0.020
3.62,-24.97,0.020
3.64,-24.75,0.020
3.66,-24.54,0.020
3.68,-24.32,0.020
3.71,-24.10,0.020
3.73,-23.88,0.020
3.75,-23.67,0.020
3.77,-23.45,0.020
3.79,-23.23,0.020
3.81,-23.02,0.020
3.84,-22.80,0.020
3.86,-22.58,0.020
3.88,-22.37,0.020
3.90,-22.15,0.020
3.92,-21.93,0.020
3.94,-21.72,0.020
3.96,-21.50,0.020
3.99,-21.28,0.020
4.01,-21.06,0.020
4.03,-20.85,0.020
4.05,-20.63,0.020
4.07,-20.41,0.020
4.09,-20.20,0.020
4.12,-19.98,0.020
4.14,-19.76,0.020
4.16,-19.54,0.020
4.18,-19.33,0.020
4.20,-19.11,0.020
4.23,-18.89,0.020
4.25,-18.68,0.020
4.27,-18.46,0.020
4.29,-18.24,0.020
4.31,-18.03,0.020
4.33,-17.81,0.020
4.35,-17.59,0.020
4.38,-17.38,0.020
4.40,-17.16,0.020
4.42,-16.94,0.020
4.44,-16.73,0.020
4.46,-16.51,0.020
4.49,-16.29,0.020
4.51,-16.08,0.020
4.53,-15.86,0.020
4.55,-15.64,0.020
4.57,-15.42,0.020
4.59,-15.21,0.020
4.61,-14.99,0.020
4.64,-14.77,0.020
4.66,-14.56,0.020
4.68,-14.34,0.020
4.70,-14.12,0.020
4.72,-13.91,0.020
4.75,-13.69,0.020
4.77,-13.47,0.020
4.79,-13.25,0.020
4.81,-13.04,0.020
4.83,-12.82,0.020
4.85,-12.60,0.020
4.88,-12.39,0.020
4.90,-12.17,0.020
4.92,-11.95,0.020
4.94,-11.74,0.020
4.96,-11.52,0.020
4.98,-11.30,0.020
5.00,-11.09,0.020
5.03,-10.87,0.020
5.05,-10.65,0.020
5.07,-10.44,0.020
5.09,-10.22,0.020
5.11,-10.00,0.020
5.14,-9.78,0.020
5.16,-9.57,0.020
5.18,-9.35,0.020
5.20,-9.13,0.020
5.22,-8.92,0.020
5.24,-8.70,0.020
5.26,-8.48,0.020
5.29,-8.27,0.020
5.31,-8.05,0.020
5.33,-7.83,0.020
5.35,-7.61,0.020
5.37,-7.40,0.020
5.40,-7.18,0.020
5.42,-6.96,0.020
5.44,-6.75,0.020
5.46,-6.53,0.021
5.48,-6.31,0.021
5.50,-6.10,0.021
5.53,-5.88,0.021
5.55,-5.66,0.021
5.57,-5.45,0.021
5.59,-5.23,0.021
5.61,-5.01,0.021
5.63,-4.80,0.021
5.65,-4.58,0.021
5.68,-4.36,0.021
5.70,-4.15,0.021
5.72,-3.93,0.021
5.74,-3.71,0.021
5.76,-3.49,0.021
5.79,-3.28,0.021
5.81,-3.06,0.021
5.83,-2.84,0.021
5.85,-2.63,0.021
5.87,-2.41,0.021
5.89,-2.19,0.021
5.91,-1.98,0.021
5.94,-1.76,0.021
5.96,-1.54,0.021
5.98,-1.32,0.021
6.00,-1.11,0.021
6.02,-0.89,0.021
6.05,-0.68,0.021
6.07,-0.46,0.021
6.09,-0.24,0.021
6.11,-0.02,0.021
6.13,0.19,0.021
6.15,0.41,0.021
6.18,0.63,0.021
6.20,0.84,0.021
6.22,1.06,0.021
6.24,1.28,0.021
6.26,1.50,0.021
6.28,1.71,0.021
6.30,1.93,0.021
6.33,2.14,0.021
6.35,2.36,0.021
6.37,2.58,0.021
6.39,2.80,0.021
6.41,3.01,0.021
6.44,3.23,0.021
6.46,3.45,0.021
6.48,3.66,0.021
6.50,3.88,0.021
6.52,4.10,0.021
6.54,4.31,0.021
6.56,4.53,0.021
6.59,4.75,0.021
6.61,4.96,0.021
6.63,5.18,0.021
6.65,5.40,0.021
6.67,5.62,0.021
6.70,5.83,0.021
6.72,6.05,0.021
6.74,6.27,0.021
6.76,6.48,0.021
6.78,6.70,0.021
6.80,6.92,0.021
6.83,7.13,0.021
6.85,7.35,0.022
6.87,7.57,0.022
6.89,7.79,0.022
6.91,8.00,0.022
6.93,8.22,0.022
6.95,8.44,0.022
6.98,8.65,0.022
7.00,8.87,0.022
7.02,9.09,0.022
7.04,9.30,0.022
7.06,9.52,0.022
7.09,9.74,0.022
7.11,9.95,0.022
7.13,10.17,0.022
7.15,10.39,0.022
7.17,10.60,0.022
7.19,10.82,0.022
7.21,11.04,0.022
7.24,11.25,0.022
7.26,11.47,0.022
7.28,11.69,0.022
7.30,11.91,0.022
7.32,12.12,0.022
7.35,12.34,0.022
7.37,12.56,0.022
7.39,12.77,0.022
7.41,12.99,0.022
7.43,13.21,0.022
7.45,13.42,0.022
7.48,13.64,0.022
7.50,13.86,0.022
7.52,14.07,0.022
7.54,14.29,0.022
7.56,14.51,0.022
7.58,14.72,0.022
7.60,14.94,0.022
7.63,15.16,0.022
7.65,15.37,0.022
7.67,15.59,0.022
7.69,15.81,0.022
7.71,16.02,0.022
7.74,16.24,0.022
7.76,16.46,0.023
7.78,16.67,0.023
7.80,16.89,0.023
7.82,17.11,0.023
7.84,17.32,0.023
7.86,17.54,0.023
7.89,17.76,0.023
7.91,17.97,0.023
7.93,18.19,0.023
7.95,18.41,0.023
7.97,18.62,0.023
8.00,18.84,0.023
8.02,19.06,0.023
8.04,19.28,0.023
8.06,19.49,0.023
8.08,19.71,0.023
8.10,19.93,0.023
8.13,20.14,0.023
8.15,20.36,0.023
8.17,20.58,0.023
8.19,20.79,0.023
8.21,21.01,0.023
8.23,21.23,0.023
8.25,21.44,0.023
8.28,21.66,0.023
8.30,21.88,0.023
8.32,22.10,0.023
8.34,22.31,0.023
8.36,22.53,0.023
8.39,22.75,0.023
8.41,22.96,0.023
8.43,23.18,0.024
8.45,23.40,0.024
8.47,23.61,0.024
8.49,23.83,0.024
8.51,24.05,0.024
8.54,24.26,0.024
8.56,24.48,0.024
8.58,24.70,0.024
8.60,24.91,0.024
8.62,25.13,0.024
8.65,25.35,0.024
8.67,25.57,0.024
8.69,25.78,0.024
8.71,26.00,0.024
8.73,26.22,0.024
8.75,26.43,0.024
8.78,26.65,0.024
8.80,26.87,0.024
8.82,27.08,0.024
8.84,27.30,0.024
8.86,27.52,0.024
8.88,27.73,0.024
8.90,27.95,0.024
8.93,28.17,0.024
8.95,28.38,0.025
8.97,28.60,0.025
8.99,28.82,0.025
9.01,29.03,0.025
9.03,29.25,0.025
9.06,29.47,0.025
9.08,29.68,0.025
9.10,29.90,0.025
9.12,30.12,0.025
9.14,30.34,0.025
9.17,30.55,0.025
9.19,30.77,0.025
9.21,30.98,0.025
9.23,31.20,0.025
9.25,31.42,0.025
9.27,31.64,0.025
9.30,31.85,0.025
9.32,32.07,0.025
9.34,32.29,0.025
9.36,32.50,0.025
9.38,32.72,0.026
9.40,32.94,0.026
9.43,33.15,0.026
9.45,33.37,0.026
9.47,33.59,0.026
9.49,33.80,0.026
9.51,34.02,0.026
9.53,34.24,0.026
9.55,34.45,0.026
9.58,34.67,0.026
9.60,34.89,0.026
9.62,35.10,0.026
9.64,35.32,0.026
9.66,35.54,0.026
9.68,35.76,0.026
9.71,35.97,0.026
9.73,36.19,0.026
9.75,36.40,0.027
9.77,36.62,0.027
9.79,36.84,0.027
9.82,37.06,0.027
9.84,37.27,0.027
9.86,37.49,0.027
9.88,37.71,0.027
9.90,37.92,0.027
9.92,38.14,0.027
9.95,38.36,0.027
9.97,38.57,0.027
9.99,38.79,0.027
10.01,39.01,0.027
10.03,39.22,0.027
10.05,39.44,0.028
10.08,39.66,0.028
10.10,39.87,0.028
10.12,40.09,0.028
10.14,40.31,0.028
10.16,40.52,0.028
10.18,40.74,0.028
10.20,40.96,0.028
10.23,41.17,0.028
10.25,41.39,0.028
10.27,41.61,0.028
10.29,41.82,0.028
10.31,42.04,0.028
10.33,42.26,0.029
10.36,42.47,0.029
10.38,42.69,0.029
10.40,42.91,0.029
10.42,43.12,0.029
10.44,43.34,0.029
10.47,43.56,0.029
10.49,43.77,0.029
10.51,43.99,0.029
10.53,44.21,0.029
10.55,44.42,0.030
10.57,44.64,0.030
10.60,44.86,0.030
10.62,45.07,0.030
10.64,45.29,0.030
10.66,45.51,0.030
10.68,45.72,0.030
10.70,45.94,0.030
10.73,46.16,0.030
10.75,46.37,0.030
10.77,46.59,0.031
10.79,46.81,0.031
10.81,47.02,0.031
10.83,47.24,0.031
10.85,47.46,0.031
10.88,47.67,0.031
10.90,47.89,0.031
10.92,48.11,0.031
10.94,48.32,0.032
10.96,48.54,0.032
10.98,48.76,0.032
11.01,48.97,0.032
11.03,49.19,0.032
11.05,49.41,0.032
11.07,49.62,0.032
11.09,49.84,0.033
11.12,50.06,0.033
11.14,50.27,0.033
11.16,50.49,0.033
11.18,50.71,0.033
11.20,50.92,0.033
11.22,51.14,0.033
11.25,51.36,0.034
11.27,51.57,0.034
11.29,51.79,0.034
11.31,52.01,0.034
11.33,52.22,0.034
11.35,52.44,0.035
11.38,52.66,0.035
11.40,52.87,0.035
11.42,53.09,0.035
11.44,53.30,0.035
11.46,53.52,0.035
11.48,53.74,0.036
11.50,53.96,0.036
11.53,54.17,0.036
11.55,54.39,0.036
11.57,54.60,0.036
11.59,54.82,0.037
11.61,55.04,0.037
11.63,55.25,0.037
11.66,55.47,0.037
11.68,55.69,0.038
11.70,55.90,0.038
11.72,56.12,0.038
11.74,56.34,0.038
11.77,56.55,0.038
11.79,56.77,0.039
11.81,56.98,0.039
11.83,57.20,0.039
11.85,57.42,0.039
11.87,57.63,0.040
11.90,57.85,0.040
11.92,58.07,0.040
11.94,58.28,0.040
11.96,58.50,0.040
11.98,58.72,0.041
12.00,58.93,0.041
12.03,59.15,0.041
12.05,59.37,0.041
12.07,59.58,0.041
12.09,59.80,0.042
12.11,60.01,0.042
12.13,60.23,0.042
12.15,60.45,0.042
12.18,60.66,0.042
12.20,60.88,0.043
12.22,61.10,0.043
12.24,61.31,0.043
12.26,61.53,0.043
12.28,61.75,0.043
12.31,61.96,0.044
12.33,62.18,0.044
12.35,62.40,0.044
12.37,62.61,0.044
12.39,62.83,0.044
12.42,63.05,0.045
12.44,63.26,0.045
12.46,63.48,0.045
12.48,63.70,0.045
12.50,63.91,0.045
12.52,64.13,0.046
12.55,64.34,0.046
12.57,64.56,0.046
12.59,64.78,0.046
12.61,65.00,0.047
12.63,65.21,0.047
12.65,65.43,0.047
12.68,65.64,0.048
12.70,65.86,0.048
12.72,66.08,0.048
12.74,66.29,0.048
12.76,66.51,0.049
12.78,66.73,0.049
12.80,66.94,0.049
12.83,67.16,0.050
12.85,67.37,0.050
12.87,67.59,0.050
12.89,67.81,0.051
12.91,68.02,0.051
12.93,68.24,0.051
12.96,68.46,0.052
12.98,68.67,0.052
13.00,68.89,0.052
13.02,69.10,0.053
13.04,69.32,0.053
13.07,69.54,0.053
13.09,69.75,0.053
13.11,69.97,0.054
13.13,70.19,0.054
13.15,70.40,0.054
13.17,70.62,0.055
13.20,70.83,0.055
13.22,71.05,0.055
13.24,71.27,0.055
13.26,71.48,0.055
13.28,71.70,0.056
13.30,71.92,0.056
13.33,72.13,0.056
13.35,72.35,0.056
13.37,72.57,0.057
13.39,72.78,0.057
13.41,73.00,0.057
13.43,73.21,0.057
13.45,73.43,0.057
13.48,73.65,0.058
13.50,73.86,0.058
13.52,74.08,0.058
13.54,74.30,0.058
13.56,74.51,0.059
13.58,74.73,0.059
13.61,74.95,0.059
13.63,75.16,0.059
13.65,75.38,0.060
13.67,75.59,0.060
13.69,75.81,0.060
13.72,76.03,0.060
13.74,76.24,0.060
13.76,76.46,0.061
13.78,76.68,0.061
13.80,76.89,0.061
13.82,77.11,0.061
13.85,77.33,0.062
13.87,77.54,0.062
13.89,77.76,0.062
13.91,77.97,0.062
13.93,78.19,0.063
13.95,78.41,0.063
13.98,78.62,0.063
14.00,78.84,0.063
14.02,79.06,0.064
14.04,79.27,0.064
14.06,79.49,0.064
14.08,79.71,0.064
14.10,79.92,0.065
14.13,80.14,0.065
14.15,80.36,0.065
14.17,80.57,0.065
14.19,80.79,0.066
14.21,81.00,0.066
14.23,81.22,0.066
14.26,81.44,0.066
14.28,81.65,0.067
14.30,81.87,0.067
14.32,82.09,0.067
14.34,82.30,0.067
14.37,82.52,0.068
14.39,82.74,0.068
14.41,82.95,0.068
14.43,83.17,0.068
14.45,83.39,0.069
14.47,83.60,0.069
14.50,83.82,0.069
14.52,84.03,0.070
14.54,84.25,0.070
14.56,84.47,0.070
14.58,84.68,0.070
14.60,84.90,0.070
14.63,85.12,0.071
14.65,85.33,0.071
14.67,85.55,0.071
14.69,85.76,0.072
14.71,85.98,0.072
14.73,86.20,0.072
14.75,86.41,0.072
14.78,86.63,0.073
14.80,86.85,0.073
14.82,87.06,0.073
14.84,87.28,0.073
14.86,87.50,0.074
14.88,87.71,0.074
14.91,87.93,0.074
14.93,88.14,0.074
14.95,88.36,0.075
14.97,88.58,0.075
14.99,88.80,0.075
15.02,89.01,0.075
15.04,89.23,0.076
15.06,89.44,0.076
15.08,89.66,0.076
15.10,89.88,0.077
15.12,90.09,0.077
15.15,90.31,0.077
15.17,90.52,0.077
15.19,90.74,0.077
15.21,90.96,0.078
15.23,91.17,0.078
15.25,91.39,0.078
15.28,91.61,0.078
15.30,91.82,0.079
15.32,92.04,0.079
15.34,92.26,0.079
15.36,92.47,0.079
15.38,92.69,0.079
15.40,92.90,0.080
15.43,93.12,0.080
15.45,93.34,0.080
15.47,93.55,0.080
15.49,93.77,0.081
15.51,93.99,0.081
15.53,94.20,0.081
15.56,94.42,0.081
15.58,94.64,0.081
15.60,94.85,0.082
15.62,95.07,0.082
15.64,95.29,0.082
15.67,95.50,0.082
15.69,95.72,0.082
15.71,95.93,0.082
15.73,96.15,0.083
15.75,96.37,0.083
15.77,96.58,0.083
15.80,96.80,0.083
15.82,97.02,0.083
15.84,97.23,0.083
15.86,97.45,0.083
15.88,97.67,0.084
15.90,97.88,0.084
15.93,98.10,0.084
15.95,98.32,0.084
15.97,98.54,0.084
15.99,98.75,0.084
16.01,98.97,0.084
16.03,99.18,0.084
16.05,99.40,0.084
16.08,99.62,0.085
16.10,99.84,0.085
16.12,100.05,0.085
16.14,100.27,0.085
16.16,100.49,0.085
16.18,100.70,0.085
16.21,100.92,0.085
16.23,101.13,0.085
16.25,101.35,0.085
16.27,101.57,0.085
16.29,101.79,0.085
16.32,102.00,0.086
16.34,102.22,0.086
16.36,102.44,0.086
16.38,102.65,0.086
16.40,102.87,0.086
16.42,103.09,0.086
16.45,103.30,0.086
16.47,103.52,0.086
16.49,103.74,0.086
16.51,103.95,0.086
16.53,104.17,0.086
16.55,104.39,0.086
16.58,104.60,0.086
16.60,104.82,0.086
16.62,105.04,0.086
16.64,105.26,0.086
16.66,105.47,0.086
16.68,105.69,0.086
16.70,105.91,0.086
16.73,106.12,0.086
16.75,106.34,0.086
16.77,106.56,0.086
16.79,106.78,0.086
16.81,106.99,0.085
16.83,107.21,0.085
16.86,107.43,0.085
16.88,107.64,0.085
16.90,107.86,0.085
16.92,108.08,0.085
16.94,108.30,0.085
16.97,108.51,0.085
16.99,108.73,0.085
17.01,108.95,0.084
17.03,109.17,0.084
17.05,109.38,0.084
17.07,109.60,0.084
17.09,109.82,0.084
17.12,110.04,0.083
17.14,110.25,0.083
17.16,110.47,0.083
17.18,110.69,0.083
17.20,110.91,0.082
17.23,111.12,0.082
17.25,111.34,0.082
17.27,111.56,0.082
17.29,111.78,0.081
17.31,111.99,0.081
17.33,112.21,0.081
17.36,112.43,0.080
17.38,112.65,0.080
17.40,112.86,0.080
17.42,113.08,0.079
17.44,113.30,0.079
17.46,113.51,0.079
17.48,113.73,0.079
17.51,113.95,0.078
17.53,114.17,0.078
17.55,114.39,0.078
17.57,114.60,0.077
17.59,114.82,0.077
17.62,115.04,0.076
17.64,115.26,0.076
17.66,115.47,0.076
17.68,115.69,0.075
17.70,115.91,0.075
17.72,116.13,0.075
17.74,116.34,0.074
17.77,116.56,0.074
17.79,116.78,0.074
17.81,116.99,0.073
17.83,117.21,0.073
17.85,117.43,0.073
17.88,117.65,0.072
17.90,117.86,0.072
17.92,118.08,0.071
17.94,118.30,0.071
17.96,118.52,0.071
17.98,118.74,0.070
18.01,118.95,0.070
18.03,119.17,0.070
18.05,119.39,0.069
18.07,119.61,0.069
18.09,119.82,0.069
18.11,120.04,0.068
18.13,120.26,0.068
18.16,120.48,0.067
18.18,120.69,0.067
18.20,120.91,0.067
18.22,121.13,0.066
18.24,121.35,0.066
18.27,121.56,0.066
18.29,121.78,0.065
18.31,122.00,0.065
18.33,122.22,0.064
18.35,122.43,0.064
18.37,122.65,0.064
18.39,122.87,0.063
18.42,123.09,0.063
18.44,123.31,0.063
18.46,123.52,0.062
18.48,123.74,0.062
18.50,123.96,0.061
18.53,124.18,0.061
18.55,124.39,0.061
18.57,124.61,0.060
18.59,124.83,0.060
18.61,125.05,0.060
18.63,125.27,0.059
18.66,125.48,0.059
18.68,125.70,0.059
18.70,125.92,0.058
18.72,126.14,0.058
18.74,126.35,0.057
18.76,126.57,0.057
18.78,126.79,0.057
18.81,127.01,0.056
18.83,127.22,0.056
18.85,127.44,0.056
18.87,127.66,0.055
18.89,127.88,0.055
18.92,128.09,0.055
18.94,128.31,0.054
18.96,128.53,0.054
18.98,128.75,0.054
19.00,128.96,0.053
19.02,129.18,0.053
19.04,129.40,0.053
19.07,129.62,0.052
19.09,129.83,0.052
19.11,130.05,0.052
19.13,130.27,0.051
19.15,130.49,0.051
19.18,130.71,0.051
19.20,130.92,0.050
19.22,131.14,0.050
19.24,131.36,0.050
19.26,131.57,0.049
19.28,131.79,0.049
19.31,132.01,0.049
19.33,132.23,0.048
19.35,132.45,0.048
19.37,132.66,0.048
19.39,132.88,0.048
19.41,133.10,0.047
19.43,133.32,0.047
19.46,133.53,0.047
19.48,133.75,0.047
19.50,133.97,0.046
19.52,134.19,0.046
19.54,134.40,0.046
19.57,134.62,0.045
19.59,134.84,0.045
19.61,135.06,0.045
19.63,135.27,0.045
19.65,135.49,0.044
19.67,135.71,0.044
19.69,135.92,0.044
19.72,136.14,0.044
19.74,136.36,0.043
19.76,136.58,0.043
19.78,136.79,0.043
19.80,137.01,0.043
19.83,137.23,0.042
19.85,137.45,0.042
19.87,137.66,0.042
19.89,137.88,0.042
19.91,138.10,0.042
19.93,138.32,0.041
19.96,138.53,0.041
19.98,138.75,0.041
20.00,138.97,0.041
20.02,139.18,0.040
20.04,139.40,0.040
20.06,139.62,0.040
20.08,139.83,0.040
20.11,140.05,0.039
20.13,140.27,0.039
20.15,140.49,0.039
20.17,140.70,0.039
20.19,140.92,0.039
20.22,141.14,0.039
20.24,141.35,0.038
20.26,141.57,0.038
20.28,141.79,0.038
20.30,142.01,0.038
20.32,142.22,0.038
20.34,142.44,0.038
20.37,142.66,0.037
20.39,142.88,0.037
20.41,143.09,0.037
20.43,143.31,0.037
20.45,143.53,0.037
20.48,143.74,0.036
20.50,143.96,0.036
20.52,144.18,0.036
20.54,144.40,0.036
20.56,144.61,0.036
20.58,144.83,0.036
20.61,145.05,0.036
20.63,145.27,0.035
20.65,145.48,0.035
20.67,145.70,0.035
20.69,145.92,0.035
20.71,146.13,0.035
20.73,146.35,0.035
20.76,146.57,0.034
20.78,146.79,0.034
20.80,147.00,0.034
20.82,147.22,0.034
20.84,147.44,0.034
20.87,147.65,0.034
20.89,147.87,0.034
20.91,148.09,0.033
20.93,148.30,0.033
20.95,148.52,0.033
20.97,148.74,0.033
20.99,148.95,0.033
21.02,149.17,0.033
21.04,149.39,0.033
21.06,149.60,0.033
21.08,149.82,0.032
21.10,150.04,0.032
21.13,150.26,0.032
21.15,150.47,0.032
21.17,150.69,0.032
21.19,150.91,0.032
21.21,151.13,0.032
21.23,151.34,0.032
21.26,151.56,0.032
21.28,151.78,0.031
21.30,151.99,0.031
21.32,152.21,0.031
21.34,152.43,0.031
21.36,152.64,0.031
21.38,152.86,0.031
21.41,153.08,0.031
21.43,153.30,0.031
21.45,153.51,0.031
21.47,153.73,0.030
21.49,153.95,0.030
21.52,154.16,0.030
21.54,154.38,0.030
21.56,154.60,0.030
21.58,154.81,0.030
21.60,155.03,0.030
21.62,155.25,0.030
21.64,155.46,0.030
21.67,155.68,0.030
21.69,155.90,0.029
21.71,156.12,0.029
21.73,156.33,0.029
21.75,156.55,0.029
21.78,156.77,0.029
21.80,156.98,0.029
21.82,157.20,0.029
21.84,157.42,0.029
21.86,157.64,0.029
21.88,157.85,0.029
21.91,158.07,0.029
21.93,158.29,0.029
21.95,158.50,0.028
21.97,158.72,0.028
21.99,158.94,0.028
22.01,159.15,0.028
22.03,159.37,0.028
22.06,159.59,0.028
22.08,159.81,0.028
22.10,160.02,0.028
22.12,160.24,0.028
22.14,160.46,0.028
22.17,160.67,0.028
22.19,160.89,0.028
22.21,161.11,0.028
22.23,161.32,0.028
22.25,161.54,0.028
22.27,161.76,0.028
22.29,161.97,0.027
22.32,162.19,0.027
22.34,162.41,0.027
22.36,162.62,0.027
22.38,162.84,0.027
22.40,163.06,0.027
22.43,163.27,0.027
22.45,163.49,0.027
22.47,163.71,0.027
22.49,163.93,0.027
22.51,164.14,0.027
22.53,164.36,0.027
22.56,164.58,0.027
22.58,164.79,0.027
22.60,165.01,0.027
22.62,165.23,0.027
22.64,165.44,0.027
22.66,165.66,0.027
22.68,165.88,0.027
22.71,166.09,0.027
22.73,166.31,0.027
22.75,166.53,0.027
22.77,166.75,0.027
22.79,166.96,0.027
22.82,167.18,0.027
22.84,167.40,0.027
22.86,167.61,0.027
22.88,167.83,0.027
22.90,168.05,0.027
22.92,168.27,0.027
22.94,168.48,0.027
22.97,168.70,0.027
22.99,168.92,0.027
23.01,169.13,0.027
23.03,169.35,0.027
23.05,169.57,0.027
23.08,169.78,0.027
23.10,170.00,0.027
23.12,170.21,0.027
23.14,170.43,0.026
23.16,170.65,0.026
23.18,170.87,0.026
23.21,171.08,0.026
23.23,171.30,0.026
23.25,171.52,0.026
23.27,171.73,0.026
23.29,171.95,0.026
23.31,172.17,0.026
23.33,172.38,0.026
23.36,172.60,0.026
23.38,172.82,0.026
23.40,173.03,0.026
23.42,173.25,0.026
23.44,173.47,0.026
23.47,173.68,0.026
23.49,173.90,0.026
23.51,174.12,0.026
23.53,174.33,0.027
23.55,174.55,0.027
23.57,174.77,0.027
23.59,174.98,0.027
23.62,175.20,0.027
23.64,175.42,0.027
23.66,175.64,0.027
23.68,175.85,0.027
23.70,176.07,0.027
23.73,176.28,0.027
23.75,176.50,0.027
23.77,176.72,0.027
23.79,176.94,0.027
23.81,177.15,0.027
23.83,177.37,0.027
23.86,177.59,0.027
23.88,177.80,0.027
23.90,178.02,0.027
23.92,178.24,0.027
23.94,178.45,0.027
23.96,178.67,0.027
23.98,178.89,0.027
24.01,179.10,0.027
24.03,179.32,0.027
24.05,179.54,0.027
24.07,179.75,0.027
24.09,179.97,0.027
24.12,180.19,0.027
24.14,180.40,0.027
24.16,180.62,0.027
24.18,180.84,0.027
24.20,181.05,0.027
24.22,181.27,0.027
24.24,181.49,0.027
24.27,181.70,0.027
24.29,181.92,0.027
24.31,182.14,0.027
24.33,182.36,0.027
24.35,182.57,0.027
24.38,182.79,0.027
24.40,183.01,0.027
24.42,183.22,0.027
24.44,183.44,0.027
24.46,183.66,0.027
24.48,183.87,0.027
24.51,184.09,0.027
24.53,184.31,0.027
24.55,184.52,0.027
24.57,184.74,0.027
24.59,184.96,0.027
24.61,185.17,0.028
24.63,185.39,0.028
24.66,185.61,0.028
24.68,185.83,0.028
24.70,186.04,0.028
24.72,186.26,0.028
24.74,186.48,0.028
24.77,186.69,0.028
24.79,186.91,0.028
24.81,187.13,0.028
24.83,187.34,0.028
24.85,187.56,0.028
24.87,187.78,0.028
24.89,187.99,0.028
24.92,188.21,0.028
24.94,188.43,0.028
24.96,188.64,0.028
24.98,188.86,0.028
25.00,189.08,0.028
25.03,189.29,0.028
25.05,189.51,0.028
25.07,189.73,0.028
25.09,189.94,0.028
25.11,190.16,0.028
25.13,190.38,0.028
25.16,190.59,0.028
25.18,190.81,0.028
25.20,191.03,0.028
25.22,191.24,0.028
25.24,191.46,0.028
25.26,191.68,0.028
25.28,191.89,0.028
25.31,192.11,0.028
25.33,192.33,0.028
25.35,192.55,0.028
25.37,192.76,0.028
25.39,192.98,0.028
25.42,193.20,0.028
25.44,193.41,0.028
25.46,193.63,0.028
25.48,193.85,0.028
25.50,194.06,0.028
25.52,194.28,0.028
25.54,194.50,0.028
25.57,194.71,0.028
25.59,194.93,0.028
25.61,195.15,0.029
25.63,195.36,0.029
25.65,195.58,0.029
25.68,195.80,0.029
25.70,196.01,0.029
25.72,196.23,0.029
25.74,196.45,0.029
25.76,196.66,0.029
25.78,196.88,0.029
25.81,197.10,0.029
25.83,197.32,0.029
25.85,197.53,0.029
25.87,197.75,0.029
25.89,197.97,0.029
25.91,198.18,0.029
25.93,198.40,0.029
25.96,198.62,0.029
25.98,198.83,0.029
26.00,199.05,0.029
26.02,199.27,0.029
26.04,199.48,0.029
26.07,199.70,0.029
26.09,199.92,0.029
26.11,200.13,0.029
26.13,200.35,0.029
26.15,200.57,0.029
26.17,200.78,0.029
26.19,201.00,0.029
26.22,201.22,0.029
26.24,201.43,0.029
26.26,201.65,0.029
26.28,201.87,0.029
26.30,202.09,0.029
26.33,202.30,0.029
26.35,202.52,0.029
26.37,202.74,0.029
26.39,202.95,0.029
26.41,203.17,0.029
26.43,203.39,0.029
26.46,203.60,0.029
26.48,203.82,0.029
26.50,204.03,0.029
26.52,204.25,0.029
26.54,204.47,0.029
26.56,204.68,0.029
26.58,204.90,0.029
26.61,205.12,0.029
26.63,205.34,0.029
26.65,205.55,0.029
26.67,205.77,0.029
26.69,205.99,0.029
26.72,206.20,0.029
26.74,206.42,0.029
26.76,206.64,0.029
26.78,206.85,0.029
26.80,207.07,0.029
26.82,207.29,0.029
26.84,207.50,0.029
26.87,207.72,0.029
26.89,207.94,0.029
26.91,208.15,0.029
26.93,208.37,0.029
26.95,208.59,0.029
26.98,208.80,0.029
27.00,209.02,0.029
27.02,209.24,0.029
27.04,209.45,0.029
27.06,209.67,0.029
27.08,209.89,0.029
27.11,210.10,0.029
27.13,210.32,0.029
27.15,210.54,0.029
27.17,210.75,0.029
27.19,210.97,0.029
27.21,211.19,0.029
27.23,211.41,0.029
27.26,211.62,0.029
27.28,211.84,0.029
27.30,212.06,0.029
27.32,212.27,0.029
27.34,212.49,0.029
27.37,212.71,0.029
27.39,212.92,0.029
27.41,213.14,0.029
27.43,213.36,0.029
27.45,213.57,0.029
27.47,213.79,0.029
27.49,214.01,0.029
27.52,214.22,0.029
27.54,214.44,0.030
27.56,214.66,0.030
27.58,214.87,0.030
27.60,215.09,0.030
27.63,215.31,0.030
27.65,215.52,0.030
27.67,215.74,0.030
27.69,215.96,0.030
27.71,216.17,0.030
27.73,216.39,0.030
27.76,216.61,0.030
27.78,216.82,0.030
27.80,217.04,0.030
27.82,217.26,0.030
27.84,217.48,0.030
27.86,217.69,0.030
27.88,217.91,0.030
27.91,218.13,0.030
27.93,218.34,0.030
27.95,218.56,0.030
27.97,218.78,0.030
27.99,218.99,0.030
28.02,219.21,0.030
28.04,219.43,0.030
28.06,219.64,0.030
28.08,219.86,0.030
28.10,220.08,0.030
28.12,220.30,0.030
28.14,220.51,0.030
28.17,220.73,0.030
28.19,220.95,0.030
28.21,221.16,0.030
28.23,221.38,0.030
28.25,221.60,0.030
28.28,221.81,0.030
28.30,222.03,0.030
28.32,222.25,0.030
28.34,222.46,0.030
28.36,222.68,0.030
28.38,222.90,0.030
28.41,223.11,0.030
28.43,223.33,0.030
28.45,223.55,0.030
28.47,223.76,0.030
28.49,223.98,0.030
28.51,224.20,0.030
28.53,224.41,0.030
28.56,224.63,0.030
28.58,224.85,0.030
28.60,225.06,0.030
28.62,225.28,0.030
28.64,225.50,0.030
28.67,225.71,0.030
28.69,225.93,0.030
28.71,226.15,0.030
28.73,226.36,0.030
28.75,226.58,0.030
28.77,226.80,0.030
28.79,227.01,0.030
28.82,227.23,0.030
28.84,227.45,0.030
28.86,227.66,0.030
28.88,227.88,0.030
28.90,228.10,0.030
28.93,228.32,0.030
28.95,228.53,0.030
28.97,228.75,0.030
28.99,228.97,0.030
29.01,229.18,0.030
29.03,229.40,0.030
29.06,229.62,0.030
29.08,229.83,0.030
29.10,230.05,0.030
29.12,230.27,0.030
29.14,230.48,0.030
29.16,230.70,0.030
29.18,230.92,0.030
29.21,231.13,0.030
29.23,231.35,0.030
29.25,231.57,0.030
29.27,231.78,0.030
29.29,232.00,0.030
29.32,232.22,0.030
29.34,232.43,0.030
29.36,232.65,0.030
29.38,232.87,0.030
29.40,233.09,0.030
29.42,233.30,0.030
29.44,233.52,0.030
29.47,233.74,0.030
29.49,233.95,0.030
29.51,234.17,0.030
29.53,234.38,0.030
29.55,234.60,0.030
29.58,234.82,0.030
29.60,235.03,0.030
29.62,235.25,0.030
29.64,235.47,0.030
29.66,235.69,0.030
29.68,235.90,0.030
29.71,236.12,0.031
29.73,236.34,0.031
29.75,236.55,0.031
29.77,236.77,0.031
29.79,236.99,0.031
29.81,237.20,0.031
29.83,237.42,0.031
29.86,237.64,0.031
29.88,237.85,0.031
29.90,238.07,0.031
29.92,238.29,0.031
29.94,238.50,0.031
29.97,238.72,0.031
29.99,238.94,0.031
30.01,239.15,0.031
30.03,239.37,0.031
30.05,239.59,0.031
30.07,239.80,0.031
30.09,240.02,0.031
30.12,240.24,0.031
30.14,240.45,0.031
30.16,240.67,0.031
30.18,240.89,0.031
30.20,241.10,0.031
30.23,241.32,0.031
30.25,241.54,0.031
30.27,241.76,0.031
30.29,241.97,0.031
30.31,242.19,0.031
30.33,242.41,0.031
30.36,242.62,0.031
30.38,242.84,0.031
30.40,243.06,0.031
30.42,243.27,0.031
30.44,243.49,0.031
30.46,243.71,0.031
30.48,243.92,0.031
30.51,244.14,0.031
30.53,244.36,0.031
30.55,244.57,0.031
30.57,244.79,0.031
30.59,245.01,0.031
30.62,245.22,0.031
30.64,245.44,0.031
30.66,245.66,0.031
30.68,245.87,0.031
30.70,246.09,0.031
30.72,246.31,0.031
30.74,246.52,0.031
30.77,246.74,0.031
30.79,246.96,0.031
30.81,247.17,0.031
30.83,247.39,0.031
30.85,247.61,0.031
30.88,247.83,0.031
30.90,248.04,0.031
30.92,248.26,0.031
30.94,248.48,
30.96,248.69,
30.98,248.91,
30.99,,

[step]
Ramp 10.00 °C/min to -60.00 °C
Time,Temperature,Heat Flow (Normalized)
min,°C,W/g
32.99,250.17,-0.006
33.02,250.17,-0.006
33.04,250.16,-0.006
33.06,250.14,-0.006
33.08,250.09,-0.006
33.10,250.00,-0.009
33.12,249.88,-0.015
33.14,249.73,-0.021
33.17,249.56,-0.027
33.19,249.37,-0.032
33.21,249.17,-0.036
33.23,248.97,-0.039
33.25,248.76,-0.040
33.28,248.55,-0.041
33.30,248.33,-0.042
33.32,248.12,-0.042
33.34,247.91,-0.042
33.36,247.69,-0.042
33.38,247.48,-0.042
33.41,247.26,-0.042
33.43,247.05,-0.042
33.45,246.83,-0.042
33.47,246.62,-0.042
33.49,246.40,-0.043
33.51,246.19,-0.043
33.53,245.97,-0.043
33.56,245.76,-0.043
33.58,245.54,-0.043
33.60,245.33,-0.043
33.62,245.11,-0.043
33.64,244.90,-0.043
33.67,244.68,-0.043
33.69,244.47,-0.043
33.71,244.25,-0.043
33.73,244.04,-0.043
33.75,243.82,-0.043
33.77,243.61,-0.043
33.79,243.39,-0.043
33.82,243.17,-0.043
33.84,242.96,-0.043
33.86,242.74,-0.043
33.88,242.53,-0.043
33.90,242.31,-0.043
33.93,242.10,-0.043
33.95,241.88,-0.043
33.97,241.67,-0.043
33.99,241.45,-0.043
34.01,241.24,-0.043
34.03,241.02,-0.043
34.06,240.80,-0.043
34.08,240.59,-0.043
34.10,240.37,-0.043
34.12,240.15,-0.043
34.14,239.94,-0.043
34.16,239.72,-0.043
34.19,239.51,-0.043
34.21,239.29,-0.043
34.23,239.08,-0.043
34.25,238.86,-0.043
34.27,238.64,-0.043
34.29,238.43,-0.043
34.31,238.21,-0.043
34.34,237.99,-0.043
34.36,237.78,-0.043
34.38,237.56,-0.043
34.40,237.34,-0.043
34.42,237.13,-0.043
34.44,236.91,-0.043
34.47,236.70,-0.043
34.49,236.48,-0.043
34.51,236.26,-0.043
34.53,236.05,-0.043
34.55,235.83,-0.043
34.58,235.62,-0.043
34.60,235.40,-0.043
34.62,235.18,-0.043
34.64,234.97,-0.043
34.66,234.75,-0.043
34.68,234.53,-0.043
34.71,234.32,-0.043
34.73,234.10,-0.043
34.75,233.88,-0.043
34.77,233.67,-0.043
34.79,233.45,-0.043
34.81,233.23,-0.042
34.84,233.02,-0.042
34.86,232.80,-0.042
34.88,232.59,-0.042
34.90,232.37,-0.042
34.92,232.15,-0.042
34.94,231.94,-0.042
34.96,231.72,-0.042
34.99,231.50,-0.042
35.01,231.29,-0.042
35.03,231.07,-0.042
35.05,230.85,-0.042
35.07,230.64,-0.042
35.09,230.42,-0.042
35.12,230.20,-0.042
35.14,229.99,-0.042
35.16,229.77,-0.042
35.18,229.55,-0.042
35.20,229.34,-0.042
35.23,229.12,-0.042
35.25,228.91,-0.042
35.27,228.69,-0.042
35.29,228.47,-0.042
35.31,228.26,-0.042
35.33,228.04,-0.042
35.36,227.82,-0.042
35.38,227.61,-0.042
35.40,227.39,-0.042
35.42,227.17,-0.042
35.44,226.96,-0.042
35.46,226.74,-0.042
35.49,226.52,-0.042
35.51,226.31,-0.042
35.53,226.09,-0.042
35.55,225.87,-0.042
35.57,225.66,-0.042
35.59,225.44,-0.042
35.61,225.22,-0.042
35.64,225.01,-0.042
35.66,224.79,-0.042
35.68,224.57,-0.042
35.70,224.36,-0.042
35.72,224.14,-0.042
35.74,223.92,-0.042
35.77,223.71,-0.042
35.79,223.49,-0.042
35.81,223.27,-0.042
35.83,223.06,-0.042
35.85,222.84,-0.042
35.88,222.62,-0.042
35.90,222.41,-0.042
35.92,222.19,-0.042
35.94,221.98,-0.042
35.96,221.76,-0.042
35.98,221.54,-0.042
36.01,221.33,-0.042
36.03,221.11,-0.042
36.05,220.89,-0.042
36.07,220.68,-0.042
36.09,220.46,-0.042
36.11,220.24,-0.042
36.14,220.03,-0.042
36.16,219.81,-0.042
36.18,219.59,-0.042
36.20,219.38,-0.042
36.22,219.16,-0.042
36.24,218.94,-0.042
36.26,218.73,-0.042
36.29,218.51,-0.042
36.31,218.30,-0.042
36.33,218.08,-0.042
36.35,217.86,-0.042
36.37,217.64,-0.042
36.39,217.43,-0.042
36.42,217.21,-0.042
36.44,216.99,-0.042
36.46,216.78,-0.042
36.48,216.56,-0.042
36.50,216.34,-0.042
36.53,216.13,-0.042
36.55,215.91,-0.042
36.57,215.69,-0.042
36.59,215.48,-0.042
36.61,215.26,-0.042
36.63,215.05,-0.042
36.66,214.83,-0.042
36.68,214.61,-0.041
36.70,214.40,-0.041
36.72,214.18,-0.041
36.74,213.96,-0.041
36.76,213.75,-0.041
36.79,213.53,-0.041
36.81,213.31,-0.041
36.83,213.10,-0.041
36.85,212.88,-0.041
36.87,212.66,-0.041
36.89,212.45,-0.041
36.91,212.23,-0.041
36.94,212.01,-0.041
36.96,211.80,-0.041
36.98,211.58,-0.041
37.00,211.36,-0.041
37.02,211.15,-0.041
37.04,210.93,-0.041
37.07,210.71,-0.041
37.09,210.50,-0.041
37.11,210.28,-0.041
37.13,210.06,-0.041
37.15,209.85,-0.041
37.18,209.63,-0.041
37.20,209.41,-0.041
37.22,209.20,-0.041
37.24,208.98,-0.041
37.26,208.76,-0.041
37.28,208.55,-0.041
37.31,208.33,-0.041
37.33,208.11,-0.041
37.35,207.90,-0.041
37.37,207.68,-0.041
37.39,207.46,-0.041
37.41,207.25,-0.041
37.44,207.03,-0.041
37.46,206.81,-0.041
37.48,206.60,-0.041
37.50,206.38,-0.041
37.52,206.16,-0.041
37.54,205.95,-0.041
37.56,205.73,-0.041
37.59,205.51,-0.041
37.61,205.30,-0.041
37.63,205.08,-0.041
37.65,204.86,-0.041
37.67,204.65,-0.041
37.69,204.43,-0.041
37.72,204.22,-0.041
37.74,204.00,-0.041
37.76,203.78,-0.041
37.78,203.57,-0.041
37.80,203.35,-0.041
37.83,203.13,-0.041
37.85,202.92,-0.041
37.87,202.70,-0.041
37.89,202.48,-0.041
37.91,202.27,-0.041
37.93,202.05,-0.041
37.96,201.83,-0.041
37.98,201.62,-0.041
38.00,201.40,-0.041
38.02,201.18,-0.041
38.04,200.97,-0.041
38.06,200.75,-0.041
38.09,200.53,-0.041
38.11,200.32,-0.041
38.13,200.10,-0.041
38.15,199.88,-0.041
38.17,199.67,-0.041
38.19,199.45,-0.041
38.21,199.23,-0.041
38.24,199.02,-0.041
38.26,198.80,-0.041
38.28,198.59,-0.041
38.30,198.37,-0.041
38.32,198.15,-0.041
38.34,197.93,-0.041
38.37,197.72,-0.041
38.39,197.50,-0.041
38.41,197.28,-0.041
38.43,197.07,-0.041
38.45,196.85,-0.041
38.48,196.63,-0.041
38.50,196.42,-0.041
38.52,196.20,-0.041
38.54,195.98,-0.041
38.56,195.77,-0.041
38.58,195.55,-0.041
38.61,195.34,-0.041
38.63,195.12,-0.041
38.65,194.90,-0.041
38.67,194.69,-0.041
38.69,194.47,-0.041
38.71,194.25,-0.041
38.74,194.04,-0.041
38.76,193.82,-0.041
38.78,193.60,-0.041
38.80,193.39,-0.041
38.82,193.17,-0.041
38.84,192.95,-0.041
38.86,192.74,-0.041
38.89,192.52,-0.041
38.91,192.30,-0.041
38.93,192.08,-0.041
38.95,191.87,-0.041
38.97,191.65,-0.041
38.99,191.44,-0.041
39.02,191.22,-0.040
39.04,191.00,-0.040
39.06,190.79,-0.040
39.08,190.57,-0.040
39.10,190.35,-0.040
39.13,190.14,-0.040
39.15,189.92,-0.040
39.17,189.70,-0.040
39.19,189.49,-0.040
39.21,189.27,-0.040
39.23,189.05,-0.040
39.26,188.84,-0.040
39.28,188.62,-0.040
39.30,188.40,-0.040
39.32,188.19,-0.040
39.34,187.97,-0.040
39.36,187.75,-0.040
39.39,187.54,-0.040
39.41,187.32,-0.040
39.43,187.10,-0.040
39.45,186.89,-0.040
39.47,186.67,-0.040
39.49,186.46,-0.040
39.51,186.24,-0.040
39.54,186.02,-0.040
39.56,185.81,-0.040
39.58,185.59,-0.040
39.60,185.37,-0.040
39.62,185.16,-0.040
39.64,184.94,-0.040
39.67,184.72,-0.040
39.69,184.51,-0.040
39.71,184.29,-0.040
39.73,184.07,-0.040
39.75,183.85,-0.040
39.78,183.64,-0.040
39.80,183.42,-0.040
39.82,183.20,-0.040
39.84,182.99,-0.040
39.86,182.77,-0.040
39.88,182.56,-0.040
39.91,182.34,-0.040
39.93,182.12,-0.040
39.95,181.91,-0.040
39.97,181.69,-0.040
39.99,181.47,-0.040
40.01,181.26,-0.040
40.04,181.04,-0.040
40.06,180.82,-0.040
40.08,180.61,-0.040
40.10,180.39,-0.040
40.12,180.17,-0.040
40.14,179.96,-0.040
40.16,179.74,-0.040
40.19,179.52,-0.040
40.21,179.31,-0.040
40.23,179.09,-0.040
40.25,178.87,-0.040
40.27,178.66,-0.040
40.29,178.44,-0.040
40.32,178.22,-0.040
40.34,178.01,-0.040
40.36,177.79,-0.040
40.38,177.57,-0.040
40.40,177.36,-0.040
40.43,177.14,-0.040
40.45,176.92,-0.040
40.47,176.71,-0.040
40.49,176.49,-0.040
40.51,176.27,-0.040
40.53,176.06,-0.040
40.56,175.84,-0.040
40.58,175.62,-0.040
40.60,175.41,-0.040
40.62,175.19,-0.040
40.64,174.97,-0.040
40.66,174.76,-0.040
40.69,174.54,-0.040
40.71,174.33,-0.040
40.73,174.11,-0.040
40.75,173.89,-0.040
40.77,173.67,-0.040
40.79,173.46,-0.040
40.81,173.24,-0.040
40.84,173.03,-0.040
40.86,172.81,-0.040
40.88,172.59,-0.040
40.90,172.38,-0.040
40.92,172.16,-0.040
40.94,171.94,-0.040
40.97,171.73,-0.040
40.99,171.51,-0.040
41.01,171.29,-0.040
41.03,171.07,-0.040
41.05,170.86,-0.040
41.08,170.64,-0.040
41.10,170.43,-0.040
41.12,170.21,-0.040
41.14,169.99,-0.040
41.16,169.77,-0.040
[...]
140.99,28.68,0.018
141.01,28.90,0.018
141.03,29.12,0.018
141.05,29.33,0.018
141.08,29.55,0.018
141.10,29.77,0.018
141.12,29.98,0.018
141.14,30.20,0.018
141.16,30.42,0.018
141.18,30.63,0.018
141.20,30.85,0.018
141.23,31.07,0.018
141.25,31.29,0.018
141.27,31.50,0.018
141.29,31.72,0.018
141.31,31.94,0.018
141.33,32.15,0.018
141.36,32.37,0.018
141.38,32.59,0.018
141.40,32.80,0.018
141.42,33.02,0.018
141.44,33.24,0.018
141.47,33.45,0.018
141.49,33.67,0.018
141.51,33.89,0.018
141.53,34.10,0.018
141.55,34.32,0.018
141.57,34.54,0.018
141.60,34.75,0.018
141.62,34.97,0.018
141.64,35.19,0.018
141.66,35.41,0.018
141.68,35.62,0.018
141.70,35.84,0.018
141.73,36.06,0.018
141.75,36.27,0.018
141.77,36.49,0.018
141.79,36.71,0.018
141.81,36.92,0.018
141.83,37.14,0.018
141.85,37.36,0.018
141.88,37.57,0.018
141.90,37.79,0.018
141.92,38.01,0.018
141.94,38.23,0.018
141.96,38.44,0.018
141.98,38.66,0.018
142.01,38.88,0.018
142.03,39.09,0.018
142.05,39.31,0.018
142.07,39.53,0.018
142.09,39.74,0.018
142.12,39.96,0.018
142.14,40.18,0.018
142.16,40.39,0.018
142.18,40.61,0.018
142.20,40.83,0.018
142.22,41.04,0.018
142.25,41.26,0.018
142.27,41.48,0.018
142.29,41.70,0.018
142.31,41.91,0.018
142.33,42.13,0.018
142.35,42.35,0.018
142.38,42.56,0.018
142.40,42.78,0.018
142.42,43.00,0.018
142.44,43.21,0.018
142.46,43.43,0.018
142.48,43.65,0.018
142.50,43.87,0.018
142.53,44.08,0.018
142.55,44.30,0.018
142.57,44.51,0.018
142.59,44.73,0.018
142.61,44.95,0.018
142.63,45.17,0.018
142.66,45.38,0.018
142.68,45.60,0.018
142.70,45.82,0.018
142.72,46.03,0.018
142.74,46.25,0.018
142.77,46.47,0.018
142.79,46.68,0.018
142.81,46.90,0.018
142.83,47.12,0.018
142.85,47.34,0.018
142.87,47.55,0.018
142.90,47.77,0.018
142.92,47.99,0.018
142.94,48.20,0.018
142.96,48.42,0.018
142.98,48.63,0.018
143.00,48.85,0.018
143.03,49.07,0.018
143.05,49.29,0.018
143.07,49.50,0.019
143.09,49.72,0.019
143.11,49.94,0.019
143.13,50.15,0.019
143.15,50.37,0.019
143.18,50.59,0.019
143.20,50.81,0.019
143.22,51.02,0.019
143.24,51.24,0.019
143.26,51.46,0.019
143.28,51.67,0.019
143.31,51.89,0.019
143.33,52.11,0.019
143.35,52.32,0.019
143.37,52.54,0.019
143.39,52.76,0.019
143.42,52.97,0.019
143.44,53.19,0.019
143.46,53.41,0.019
143.48,53.62,0.019
143.50,53.84,0.019
143.52,54.06,0.019
143.55,54.27,0.019
143.57,54.49,0.019
143.59,54.71,0.019
143.61,54.93,0.019
143.63,55.14,0.019
143.65,55.36,0.019
143.68,55.58,0.019
143.70,55.79,0.019
143.72,56.01,0.019
143.74,56.23,0.019
143.76,56.44,0.019
143.78,56.66,0.019
143.80,56.88,0.019
143.83,57.09,0.019
143.85,57.31,0.019
143.87,57.53,0.019
143.89,57.74,0.019
143.91,57.96,0.019
143.93,58.18,0.019
143.96,58.40,0.019
143.98,58.61,0.019
144.00,58.83,0.019
144.02,59.05,0.019
144.04,59.26,0.019
144.07,59.48,0.019
144.09,59.70,0.019
144.11,59.91,0.019
144.13,60.13,0.019
144.15,60.35,0.019
144.17,60.56,0.019
144.20,60.78,0.019
144.22,61.00,0.019
144.24,61.22,0.019
144.26,61.43,0.019
144.28,61.65,0.019
144.30,61.87,0.019
144.33,62.08,0.019
144.35,62.30,0.019
144.37,62.52,0.019
144.39,62.73,0.019
144.41,62.95,0.019
144.43,63.17,0.019
144.45,63.38,0.019
144.48,63.60,0.019
144.50,63.82,0.019
144.52,64.04,0.019
144.54,64.25,0.019
144.56,64.47,0.019
144.58,64.69,0.019
144.61,64.90,0.019
144.63,65.12,0.019
144.65,65.34,0.019
144.67,65.55,0.019
144.69,65.77,0.019
144.72,65.99,0.019
144.74,66.20,0.019
144.76,66.42,0.019
144.78,66.64,0.019
144.80,66.86,0.019
144.82,67.07,0.019
144.85,67.29,0.019
144.87,67.51,0.019
144.89,67.72,0.019
144.91,67.94,0.019
144.93,68.16,0.019
144.95,68.37,0.019
144.98,68.59,0.019
145.00,68.81,0.019
145.02,69.02,0.019
145.04,69.24,0.019
145.06,69.46,0.019
145.08,69.67,0.019
145.10,69.89,0.019
145.13,70.11,0.019
145.15,70.32,0.019
145.17,70.54,0.020
145.19,70.76,0.020
145.21,70.97,0.020
145.23,71.19,0.020
145.26,71.41,0.020
145.28,71.63,0.020
145.30,71.84,0.020
145.32,72.06,0.020
145.34,72.28,0.020
145.37,72.49,0.020
145.39,72.71,0.020
145.41,72.93,0.020
145.43,73.14,0.020
145.45,73.36,0.020
145.47,73.58,0.020
145.50,73.80,0.020
145.52,74.01,0.020
145.54,74.23,0.020
145.56,74.45,0.020
145.58,74.66,0.020
145.60,74.88,0.020
145.63,75.10,0.020
145.65,75.31,0.020
145.67,75.53,0.020
145.69,75.75,0.020
145.71,75.96,0.020
145.73,76.18,0.020
145.75,76.40,0.020
145.78,76.61,0.020
145.80,76.83,0.020
145.82,77.05,0.020
145.84,77.26,0.020
145.86,77.48,0.020
145.88,77.70,0.020
145.91,77.91,0.020
145.93,78.13,0.020
145.95,78.35,0.020
145.97,78.56,0.020
145.99,78.78,0.020
146.02,79.00,0.020
146.04,79.21,0.020
146.06,79.43,0.020
146.08,79.65,0.020
146.10,79.87,0.020
146.12,80.08,0.020
146.15,80.30,0.020
146.17,80.52,0.020
146.19,80.73,0.020
146.21,80.95,0.020
146.23,81.17,0.020
146.25,81.38,0.020
146.28,81.60,0.020
146.30,81.82,0.020
146.32,82.03,0.020
146.34,82.25,0.020
146.36,82.47,0.020
146.38,82.68,0.020
146.40,82.90,0.020
146.43,83.12,0.020
146.45,83.33,0.020
146.47,83.55,0.020
146.49,83.77,0.020
146.51,83.98,0.020
146.53,84.20,0.020
146.56,84.42,0.020
146.58,84.64,0.020
146.60,84.85,0.020
146.62,85.07,0.020
146.64,85.29,0.020
146.67,85.50,0.020
146.69,85.72,0.020
146.71,85.94,0.020
146.73,86.15,0.020
146.75,86.37,0.020
146.77,86.59,0.020
146.80,86.81,0.020
146.82,87.02,0.020
146.84,87.24,0.020
146.86,87.46,0.020
146.88,87.67,0.020
146.90,87.89,0.020
146.93,88.11,0.020
146.95,88.32,0.020
146.97,88.54,0.020
146.99,88.76,0.020
147.01,88.97,0.020
147.03,89.19,0.020
147.05,89.41,0.020
147.08,89.62,0.020
147.10,89.84,0.020
147.12,90.06,0.020
147.14,90.27,0.021
147.16,90.49,0.021
147.18,90.71,0.021
147.21,90.93,0.021
147.23,91.14,0.021
147.25,91.36,0.021
147.27,91.58,0.021
147.29,91.79,0.021
147.32,92.01,0.021
147.34,92.23,0.021
147.36,92.44,0.021
147.38,92.66,0.021
147.40,92.88,0.021
147.42,93.09,0.021
147.45,93.31,0.021
147.47,93.53,0.021
147.49,93.74,0.021
147.51,93.96,0.021
147.53,94.18,0.021
147.55,94.39,0.021
147.58,94.61,0.021
147.60,94.83,0.021
147.62,95.04,0.021
147.64,95.26,0.021
147.66,95.48,0.021
147.68,95.70,0.021
147.70,95.91,0.021
147.73,96.13,0.021
147.75,96.35,0.021
147.77,96.56,0.021
147.79,96.78,0.021
147.81,97.00,0.021
147.83,97.21,0.021
147.86,97.43,0.021
147.88,97.65,0.021
147.90,97.86,0.021
147.92,98.08,0.021
147.94,98.30,0.021
147.97,98.51,0.021
147.99,98.73,0.021
148.01,98.95,0.021
148.03,99.16,0.021
148.05,99.38,0.021
148.07,99.60,0.021
148.10,99.82,0.021
148.12,100.03,0.021
148.14,100.25,0.021
148.16,100.46,0.021
148.18,100.68,0.021
148.20,100.90,0.021
148.23,101.12,0.021
148.25,101.33,0.021
148.27,101.55,0.021
148.29,101.77,0.021
148.31,101.98,0.021
148.33,102.20,0.021
148.35,102.42,0.021
148.38,102.63,0.021
148.40,102.85,0.021
148.42,103.07,0.021
148.44,103.28,0.021
148.46,103.50,0.021
148.48,103.72,0.021
148.51,103.94,0.021
148.53,104.15,0.021
148.55,104.37,0.021
148.57,104.59,0.021
148.59,104.80,0.021
148.62,105.02,0.021
148.64,105.24,0.021
148.66,105.45,0.021
148.68,105.67,0.022
148.70,105.89,0.022
148.72,106.10,0.022
148.75,106.32,0.022
148.77,106.54,0.022
148.79,106.75,0.022
148.81,106.97,0.022
148.83,107.19,0.022
148.85,107.41,0.022
148.88,107.62,0.022
148.90,107.84,0.022
148.92,108.05,0.022
148.94,108.27,0.022
148.96,108.49,0.022
148.98,108.70,0.022
149.00,108.92,0.022
149.03,109.14,0.022
149.05,109.36,0.022
149.07,109.57,0.022
149.09,109.79,0.022
149.11,110.01,0.022
149.13,110.22,0.022
149.16,110.44,0.022
149.18,110.66,0.022
149.20,110.87,0.022
149.22,111.09,0.022
149.24,111.31,0.022
149.27,111.52,0.022
149.29,111.74,0.022
149.31,111.96,0.022
149.33,112.17,0.022
149.35,112.39,0.022
149.37,112.61,0.022
149.40,112.82,0.022
149.42,113.04,0.022
149.44,113.26,0.022
149.46,113.48,0.022
149.48,113.69,0.022
149.50,113.91,0.022
149.53,114.13,0.022
149.55,114.34,0.022
149.57,114.56,0.022
149.59,114.78,0.022
149.61,114.99,0.022
149.63,115.21,0.022
149.65,115.43,0.022
149.68,115.64,0.022
149.70,115.86,0.022
149.72,116.08,0.022
149.74,116.29,0.022
149.76,116.51,0.022
149.78,116.73,0.022
149.81,116.94,0.022
149.83,117.16,0.022
149.85,117.38,0.022
149.87,117.59,0.022
149.89,117.81,0.023
149.92,118.03,0.023
149.94,118.24,0.023
149.96,118.46,0.023
149.98,118.68,0.023
150.00,118.89,0.023
150.02,119.11,0.023
150.05,119.33,0.023
150.07,119.54,0.023
150.09,119.76,0.023
150.11,119.98,0.023
150.13,120.19,0.023
150.15,120.41,0.023
150.18,120.63,0.023
150.20,120.85,0.023
150.22,121.06,0.023
150.24,121.28,0.023
150.26,121.50,0.023
150.28,121.71,0.023
150.30,121.93,0.023
150.33,122.15,0.023
150.35,122.36,0.023
150.37,122.58,0.023
150.39,122.80,0.023
150.41,123.01,0.023
150.43,123.23,0.023
150.46,123.45,0.023
150.48,123.66,0.023
150.50,123.88,0.023
150.52,124.10,0.023
150.54,124.31,0.023
150.57,124.53,0.024
150.59,124.75,0.024
150.61,124.96,0.024
150.63,125.18,0.024
150.65,125.40,0.024
150.67,125.61,0.024
150.70,125.83,0.024
150.72,126.05,0.024
150.74,126.26,0.024
150.76,126.48,0.024
150.78,126.70,0.024
150.80,126.91,0.024
150.83,127.13,0.024
150.85,127.35,0.024
150.87,127.57,0.024
150.89,127.78,0.024
150.91,128.00,0.024
150.93,128.22,0.024
150.95,128.43,0.024
150.98,128.65,0.025
151.00,128.87,0.025
151.02,129.08,0.025
151.04,129.30,0.025
151.06,129.52,0.025
151.08,129.73,0.025
151.11,129.95,0.025
151.13,130.16,0.025
151.15,130.38,0.025
151.17,130.60,0.025
151.19,130.82,0.025
151.22,131.03,0.025
151.24,131.25,0.025
151.26,131.47,0.026
151.28,131.68,0.026
151.30,131.90,0.026
151.32,132.12,0.026
151.35,132.33,0.026
151.37,132.55,0.026
151.39,132.77,0.026
151.41,132.98,0.026
151.43,133.20,0.026
151.45,133.42,0.026
151.48,133.63,0.027
151.50,133.85,0.027
151.52,134.07,0.027
151.54,134.29,0.027
151.56,134.50,0.027
151.58,134.72,0.027
151.60,134.93,0.027
151.63,135.15,0.027
151.65,135.37,0.027
151.67,135.58,0.027
151.69,135.80,0.027
151.71,136.02,0.027
151.73,136.24,0.027
151.76,136.45,0.027
151.78,136.67,0.028
151.80,136.89,0.028
151.82,137.10,0.028
151.84,137.32,0.028
151.87,137.54,0.028
151.89,137.75,0.028
151.91,137.97,0.028
151.93,138.19,0.028
151.95,138.40,0.028
151.97,138.62,0.028
152.00,138.84,0.028
152.02,139.05,0.028
152.04,139.27,0.028
152.06,139.49,0.028
152.08,139.71,0.028
152.10,139.92,0.028
152.13,140.14,0.028
152.15,140.36,0.028
152.17,140.57,0.028
152.19,140.79,0.028
152.21,141.01,0.028
152.23,141.22,0.028
152.25,141.44,0.028
152.28,141.66,0.028
152.30,141.87,0.028
152.32,142.09,0.028
152.34,142.31,0.028
152.36,142.53,0.028
152.38,142.74,0.028
152.41,142.96,0.028
152.43,143.17,0.028
152.45,143.39,0.028
152.47,143.61,0.028
152.49,143.83,0.028
152.52,144.04,0.028
152.54,144.26,0.028
152.56,144.48,0.028
152.58,144.69,0.028
152.60,144.91,0.028
152.62,145.13,0.028
152.65,145.34,0.028
152.67,145.56,0.028
152.69,145.78,0.028
152.71,145.99,0.028
152.73,146.21,0.028
152.75,146.43,0.028
152.78,146.64,0.028
152.80,146.86,0.028
152.82,147.08,0.028
152.84,147.29,0.028
152.86,147.51,0.028
152.88,147.73,0.028
152.90,147.94,0.028
152.93,148.16,0.028
152.95,148.38,0.028
152.97,148.59,0.028
152.99,148.81,0.028
153.01,149.03,0.028
153.03,149.24,0.028
153.06,149.46,0.028
153.08,149.68,0.028
153.10,149.90,0.028
153.12,150.11,0.028
153.14,150.33,0.028
153.17,150.55,0.028
153.19,150.76,0.028
153.21,150.98,0.028
153.23,151.20,0.028
153.25,151.41,0.028
153.27,151.63,0.028
153.30,151.85,0.028
153.32,152.07,0.028
153.34,152.28,0.028
153.36,152.50,0.028
153.38,152.72,0.028
153.40,152.93,0.028
153.43,153.15,0.028
153.45,153.37,0.028
153.47,153.58,0.028
153.49,153.80,0.028
153.51,154.02,0.028
153.53,154.23,0.028
153.55,154.45,0.028
153.58,154.66,0.028
153.60,154.88,0.028
153.62,155.10,0.028
153.64,155.32,0.028
153.66,155.53,0.028
153.68,155.75,0.028
153.71,155.97,0.028
153.73,156.18,0.028
153.75,156.40,0.028
153.77,156.62,0.028
153.79,156.83,0.028
153.82,157.05,0.028
153.84,157.27,0.028
153.86,157.48,0.028
153.88,157.70,0.028
153.90,157.92,0.028
153.92,158.13,0.028
153.95,158.35,0.028
153.97,158.57,0.028
153.99,158.78,0.028
154.01,159.00,0.028
154.03,159.22,0.028
154.05,159.43,0.028
154.08,159.65,0.028
154.10,159.87,0.028
154.12,160.09,0.028
154.14,160.30,0.028
154.16,160.52,0.028
154.18,160.74,0.028
154.20,160.95,0.028
154.23,161.17,0.028
154.25,161.39,0.028
154.27,161.60,0.028
154.29,161.82,0.028
154.31,162.04,0.028
154.33,162.25,0.028
154.36,162.47,0.028
154.38,162.69,0.028
154.40,162.90,0.028
154.42,163.12,0.028
154.44,163.34,0.028
154.47,163.55,0.029
154.49,163.77,0.029
154.51,163.99,0.029
154.53,164.20,0.029
154.55,164.42,0.029
154.57,164.64,0.029
154.60,164.85,0.029
154.62,165.07,0.029
154.64,165.29,0.029
154.66,165.51,0.029
154.68,165.72,0.029
154.70,165.94,0.029
154.73,166.16,0.029
154.75,166.37,0.029
154.77,166.59,0.029
154.79,166.81,0.029
154.81,167.02,0.029
154.83,167.24,0.029
154.85,167.46,0.029
154.88,167.67,0.029
154.90,167.89,0.029
154.92,168.11,0.029
154.94,168.33,0.029
154.96,168.54,0.029
154.98,168.76,0.029
155.01,168.98,0.029
155.03,169.19,0.029
155.05,169.41,0.029
155.07,169.63,0.029
155.09,169.84,0.029
155.12,170.06,0.029
155.14,170.28,0.029
155.16,170.49,0.029
155.18,170.71,0.029
155.20,170.93,0.029
155.22,171.14,0.029
155.25,171.36,0.029
155.27,171.58,0.029
155.29,171.79,0.029
155.31,172.01,0.029
155.33,172.23,0.029
155.35,172.45,0.029
155.38,172.66,0.029
155.40,172.88,0.029
155.42,173.10,0.029
155.44,173.31,0.029
155.46,173.53,0.029
155.48,173.74,0.029
155.50,173.96,0.029
155.53,174.18,0.029
155.55,174.40,0.029
155.57,174.61,0.029
155.59,174.83,0.029
155.61,175.05,0.029
155.63,175.26,0.029
155.66,175.48,0.029
155.68,175.70,0.029
155.70,175.91,0.029
155.72,176.13,0.029
155.74,176.35,0.029
155.77,176.56,0.029
155.79,176.78,0.029
155.81,177.00,0.029
155.83,177.21,0.029
155.85,177.43,0.029
155.87,177.65,0.029
155.90,177.86,0.029
155.92,178.08,0.029
155.94,178.30,0.029
155.96,178.51,0.029
155.98,178.73,0.029
156.00,178.95,0.029
156.03,179.17,0.029
156.05,179.38,0.029
156.07,179.60,0.029
156.09,179.82,0.029
156.11,180.03,0.029
156.13,180.25,0.029
156.15,180.47,0.029
156.18,180.68,0.029
156.20,180.90,0.029
156.22,181.12,0.029
156.24,181.33,0.029
156.26,181.55,0.029
156.28,181.77,0.029
156.31,181.98,0.029
156.33,182.20,0.029
156.35,182.42,0.029
156.37,182.63,0.029
156.39,182.85,0.029
156.42,183.07,0.029
156.44,183.29,0.029
156.46,183.50,0.029
156.48,183.72,0.029
156.50,183.94,0.029
156.52,184.15,0.029
156.55,184.37,0.029
156.57,184.58,0.029
156.59,184.80,0.029
156.61,185.02,0.029
156.63,185.24,0.029
156.65,185.45,0.029
156.68,185.67,0.029
156.70,185.89,0.029
156.72,186.10,0.029
156.74,186.32,0.029
156.76,186.54,0.029
156.78,186.75,0.029
156.80,186.97,0.029
156.83,187.19,0.029
156.85,187.40,0.029
156.87,187.62,0.029
156.89,187.84,0.029
156.91,188.06,0.029
156.93,188.27,0.029
156.96,188.49,0.029
156.98,188.70,0.029
157.00,188.92,0.029
157.02,189.14,0.029
157.04,189.35,0.029
157.07,189.57,0.029
157.09,189.79,0.029
157.11,190.01,0.030
157.13,190.22,0.030
157.15,190.44,0.030
157.17,190.66,0.030
157.20,190.87,0.030
157.22,191.09,0.030
157.24,191.31,0.030
157.26,191.52,0.030
157.28,191.74,0.030
157.30,191.96,0.030
157.33,192.17,0.030
157.35,192.39,0.030
157.37,192.61,0.030
157.39,192.82,0.030
157.41,193.04,0.030
157.43,193.26,0.030
157.45,193.47,0.030
157.48,193.69,0.030
157.50,193.91,0.030
157.52,194.13,0.030
157.54,194.34,0.030
157.56,194.56,0.030
157.58,194.78,0.030
157.61,194.99,0.030
157.63,195.21,0.030
157.65,195.43,0.030
157.67,195.64,0.030
157.69,195.86,0.030
157.72,196.08,0.030
157.74,196.29,0.030
157.76,196.51,0.030
157.78,196.73,0.030
157.80,196.94,0.030
157.82,197.16,0.030
157.85,197.38,0.030
157.87,197.59,0.030
157.89,197.81,0.030
157.91,198.03,0.030
157.93,198.25,0.030
157.95,198.46,0.030
157.98,198.68,0.030
158.00,198.90,0.030
158.02,199.11,0.030
158.04,199.33,0.030
158.06,199.55,0.030
158.08,199.76,0.030
158.10,199.98,0.030
158.13,200.20,0.030
158.15,200.41,0.030
158.17,200.63,0.030
158.19,200.85,0.030
158.21,201.06,0.030
158.23,201.28,0.030
158.26,201.50,0.030
158.28,201.72,0.030
158.30,201.93,0.030
158.32,202.15,0.030
158.34,202.36,0.030
158.37,202.58,0.030
158.39,202.80,0.030
158.41,203.01,0.030
158.43,203.23,0.030
158.45,203.45,0.030
158.47,203.66,0.030
158.50,203.88,0.030
158.52,204.10,0.030
158.54,204.32,0.030
158.56,204.53,0.030
158.58,204.75,0.030
158.60,204.97,0.030
158.63,205.18,0.030
158.65,205.40,0.030
158.67,205.61,0.030
158.69,205.83,0.030
158.71,206.05,0.030
158.73,206.27,0.030
158.75,206.48,0.030
158.78,206.70,0.030
158.80,206.92,0.030
158.82,207.13,0.030
158.84,207.35,0.030
158.86,207.57,0.030
158.88,207.78,0.030
158.91,208.00,0.030
158.93,208.22,0.030
158.95,208.43,0.030
158.97,208.65,0.030
158.99,208.87,0.030
159.02,209.08,0.030
159.04,209.30,0.030
159.06,209.52,0.030
159.08,209.73,0.030
159.10,209.95,0.030
159.12,210.17,0.030
159.15,210.38,0.030
159.17,210.60,0.030
159.19,210.82,0.030
159.21,211.03,0.030
159.23,211.25,0.030
159.25,211.47,0.030
159.28,211.68,0.030
159.30,211.90,0.030
159.32,212.12,0.030
159.34,212.34,0.030
159.36,212.55,0.030
159.38,212.77,0.030
159.40,212.99,0.030
159.43,213.20,0.030
159.45,213.42,0.030
159.47,213.64,0.030
159.49,213.86,0.030
159.51,214.07,0.030
159.53,214.29,0.030
159.56,214.50,0.030
159.58,214.72,0.030
159.60,214.94,0.031
159.62,215.15,0.031
159.64,215.37,0.031
159.67,215.59,0.031
159.69,215.80,0.031
159.71,216.02,0.031
159.73,216.24,0.031
159.75,216.46,0.031
159.77,216.67,0.031
159.80,216.89,0.031
159.82,217.11,0.031
159.84,217.32,0.031
159.86,217.54,0.031
159.88,217.76,0.031
159.90,217.97,0.031
159.93,218.19,0.031
159.95,218.41,0.031
159.97,218.62,0.031
159.99,218.84,0.031
160.01,219.06,0.031
160.03,219.27,0.031
160.05,219.49,0.031
160.08,219.71,0.031
160.10,219.92,0.031
160.12,220.14,0.031
160.14,220.36,0.031
160.16,220.57,0.031
160.18,220.79,0.031
160.21,221.01,0.031
160.23,221.22,0.031
160.25,221.44,0.031
160.27,221.66,0.031
160.29,221.87,0.031
160.32,222.09,0.031
160.34,222.31,0.031
160.36,222.52,0.031
160.38,222.74,0.031
160.40,222.96,0.031
160.42,223.18,0.031
160.45,223.39,0.031
160.47,223.61,0.031
160.49,223.83,0.031
160.51,224.04,0.031
160.53,224.26,0.031
160.55,224.48,0.031
160.58,224.70,0.031
160.60,224.91,0.031
160.62,225.13,0.031
160.64,225.34,0.031
160.66,225.56,0.031
160.68,225.78,0.031
160.70,225.99,0.031
160.73,226.21,0.031
160.75,226.43,0.031
160.77,226.64,0.031
160.79,226.86,0.031
160.81,227.08,0.031
160.83,227.29,0.031
160.86,227.51,0.031
160.88,227.73,0.031
160.90,227.95,0.031
160.92,228.16,0.031
160.94,228.38,0.031
160.97,228.60,0.031
160.99,228.81,0.031
161.01,229.03,0.031
161.03,229.25,0.031
161.05,229.46,0.031
161.07,229.68,0.031
161.10,229.90,0.031
161.12,230.11,0.031
161.14,230.33,0.031
161.16,230.55,0.031
161.18,230.76,0.031
161.20,230.98,0.031
161.23,231.19,0.031
161.25,231.41,0.031
161.27,231.63,0.031
161.29,231.85,0.031
161.31,232.06,0.031
161.33,232.28,0.031
161.35,232.50,0.031
161.38,232.72,0.031
161.40,232.93,0.031
161.42,233.15,0.031
161.44,233.37,0.031
161.46,233.58,0.031
161.48,233.80,0.031
161.51,234.01,0.031
161.53,234.23,0.031
161.55,234.45,0.031
161.57,234.67,0.031
161.59,234.88,0.031
161.62,235.10,0.031
161.64,235.32,0.031
161.66,235.53,0.031
161.68,235.75,0.031
161.70,235.97,0.031
161.72,236.18,0.031
161.75,236.40,0.031
161.77,236.62,0.031
161.79,236.83,0.031
161.81,237.05,0.031
161.83,237.27,0.031
161.85,237.48,0.031
161.88,237.70,0.031
161.90,237.92,0.031
161.92,238.13,0.031
161.94,238.35,0.031
161.96,238.57,0.031
161.98,238.79,0.031
162.00,239.00,0.031
162.03,239.22,0.031
162.05,239.44,0.031
162.07,239.65,0.031
162.09,239.87,0.031
162.11,240.09,0.031
162.13,240.30,0.031
162.16,240.52,0.031
162.18,240.73,0.031
162.20,240.95,0.031
162.22,241.17,0.031
162.24,241.39,0.031
162.27,241.60,0.031
162.29,241.82,0.031
162.31,242.04,0.032
162.33,242.25,0.032
162.35,242.47,0.032
162.37,242.69,0.032
162.40,242.90,0.032
162.42,243.12,0.032
162.44,243.34,0.032
162.46,243.55,0.032
162.48,243.77,0.032
162.50,243.99,0.032
162.53,244.20,0.032
162.55,244.42,0.032
162.57,244.64,0.032
162.59,244.85,0.032
162.61,245.07,0.032
162.63,245.29,0.032
162.65,245.51,0.032
162.68,245.72,0.032
162.70,245.94,0.032
162.72,246.15,0.032
162.74,246.37,0.032
162.76,246.59,0.032
162.78,246.81,0.032
162.81,247.02,0.032
162.83,247.24,0.032
162.85,247.46,0.032
162.87,247.67,0.032
162.89,247.89,0.032
162.92,248.11,0.032
162.94,248.32,0.032
162.96,248.54,
162.98,248.76,
163.00,,