File: DSC/Olivia/2025_07_20_PVP40_10Cmin_x3.csv
Filename,2025_07_20_PVP40_10Cmin_x3
Instrument name,DSC2A-00468 (192.168.1.100)
Operator,Yarger
rundate,7/20/2025
Sample name,2025_07_20_PVP40_10Cmin_x3
proceduresegments,Data Off ; Equilibrate -60.00 °C; Data On ; Ramp 10.00 °C/min to 230.00 °C; Data Off ; Isothermal 2.0 min; Data On ; Ramp 10.00 °C/min to -60.00 °C; Data Off ; Isothermal 2.0 min; Data On ; Ramp 10.00 °C/min to 230.00 °C; Data Off ; Isothermal 2.0 min; Data On ; Ramp 10.00 °C/min to -60.00 °C; Data Off ; Isothermal 2.0 min; Data On ; Ramp 10.00 °C/min to 230.00 °C
[File Parameters]
Run date,7/20/2025 10:45:57 PM
Trios version,5.1.1.46572
Original File Name,
Current File Name,D:\DSC2500\Gibbons\2025_07_20_PVP40_10Cmin_x3.tri
[Procedure]
Procedure Name,PVP_n60C_230C_10Cmin_x3
Sample Name,2025_07_20_PVP40_10Cmin_x3
Sample Mass,8.08 mg
Reference Sample Mass,0 mg
Pan Mass,32.43 mg
Pan Number,40
Reference Pan Mass,32.52 mg
Reference Pan Number,37
Pan Type,Aluminum
Comments,Thermal support Al pans/lids. DSC_Samples_A2_Tray_July2025 google sheet.
Project Name,Pharma - Cocrystals
Operator,Yarger
Test,Custom
Unload Max Temperature,30
Unload Min Temperature,30
Load Max Temperature,30
Load Min Temperature,30
Stop on Gas Flow Error,Yes
[Signal List]
Signal #1,Time (min)
Signal #2,Temperature (°C)
Signal #3,Heat Flow (mW)
Signal #4,Delta T (µV)
Signal #5,Delta Tzero (µV)
Signal #6,Tzero Temperature (°C)
Signal #7,Cell Purge (mL/min)
Signal #8,Heater Temp (°C)
Signal #9,Power Delivered (W)
Signal #10,Reference Junction Temperature (°C)
Signal #11,Flange Temperature (°C)
Signal #12,Heat Flow Phase (rad)
Signal #13,Total Heat Capacity (J/°C)
Signal #14,Heat Capacity (J/°C)
[Configuration]
Company Name,ASU
Instrument Name,DSC2A-00468
Instrument Type,DSC2500
Serial Number,DSC2A-00468
IP,192.168.1.100
Location of Instrument,MRRC
DisplayType,Unknown
Sample Interval ,0.1 s/pt
Selected Heat Flow,T4P
Exotherm Direction,Down
Cell Serial,DRC2-00792
Lid Type,Standard
Cooler,RCS 90
Leave Cooler on at End of Sequence,On
Gas 2,Nitrogen
Gas Selected,Channel 1
Flow Rate,50 mL/min
Secondary Purge,On
Licensed Heat Flow,Heat Flow T4P
Modulation Licensed,Yes
[Versions]
Common IDD Version,1
Cortex Version,VER 2.10.2.31
Driver,5.0.0.6
GDM Version,1.0.3.3
TouchscreenVersion,1.0.0.16145
FEP Version,1.2.1.21
FEP Bootloader,2.0.0.5
AutoSampler Version,2.1.1.26
Auto Sampler Bootloader,2.0.0.5
FCM Version,1.1.0.3
FCM Bootloader,2.0.0.5
[Experiment Logs]
Experiment Log Entry # 1,Data On set to 0
Experiment Log Entry # 3,Equilibrate Segment -60 (C) Started
Experiment Log Entry # 5,Air Cool is off.
Experiment Log Entry # 7,Data On set to 1
Experiment Log Entry # 9,Ramp Segment 10 C/min to 230 Started
Experiment Log Entry # 11,Data On set to 0
Experiment Log Entry # 13,Isothermal Segment 2 min started
Experiment Log Entry # 15,Data On set to 1
Experiment Log Entry # 17,Ramp Segment 10 C/min to -60 Started
Experiment Log Entry # 19,Data On set to 0
Experiment Log Entry # 21,Isothermal Segment 2 min started
Experiment Log Entry # 23,Data On set to 1
Experiment Log Entry # 25,Ramp Segment 10 C/min to 230 Started
Experiment Log Entry # 27,Data On set to 0
Experiment Log Entry # 29,Isothermal Segment 2 min started
Experiment Log Entry # 31,Data On set to 1
Experiment Log Entry # 33,Ramp Segment 10 C/min to -60 Started
Experiment Log Entry # 35,Data On set to 0
Experiment Log Entry # 37,Isothermal Segment 2 min started
Experiment Log Entry # 39,Data On set to 1
Experiment Log Entry # 41,Ramp Segment 10 C/min to 230 Started
[Method Log]
Method Log Entry # 1,Data Off
Method Log Entry # 2,Equilibrate -60 °C
Method Log Entry # 3,Data On
Method Log Entry # 4,(Ramp 58963) Ramp 10 °C/minute to 230 °C
Method Log Entry # 5,Data Off
Method Log Entry # 6,Isothermal 2 minutes
Method Log Entry # 7,Data On
Method Log Entry # 8,(Ramp 58967) Ramp 10 °C/minute to -60 °C
Method Log Entry # 9,Data Off
Method Log Entry # 10,Isothermal 2 minutes
Method Log Entry # 11,Data On
Method Log Entry # 12,(Ramp 58971) Ramp 10 °C/minute to 230 °C
Method Log Entry # 13,Data Off
Method Log Entry # 14,Isothermal 2 minutes
Method Log Entry # 15,Data On
Method Log Entry # 16,(Ramp 58975) Ramp 10 °C/minute to -60 °C
Method Log Entry # 17,Data Off
Method Log Entry # 18,Isothermal 2 minutes
Method Log Entry # 19,Data On
Method Log Entry # 20,(Ramp 58979) Ramp 10 °C/minute to 230 °C
Cell Serial,DRC2-00792
[T1 Calibration]
Slope,-0.008529666
Offset,9.636258
Initial Temperature,98.23
GUID,f8bfdadc-4977-4fdf-ba6d-0ba9134940c3
[TZero Calibration]
Date Applied,11/29/2022 4:06:13 PM
Description,From -89.059 °C to 396.009 °C at 20.000°C/min
Gas Type,Nitrogen
Pan Type,None
Source Files 1,C:\Users\yargerlab\Desktop\DSC Data\General\TZero_calibration_11_29_22_2nd(2).tri
Source Files 2,C:\Users\yargerlab\Desktop\DSC Data\General\TZero_calibration_11_29_22_2nd(3).tri
Delta T Offset,13.05235
Delta T Slope,-0.007271007
Delta T0 Offset,-13.69128
Delta T0 Slope,0.06063341
[Temperature Calibration]
Date Applied,11/29/2022 7:12:28 PM
Description,From 106.590 °C to 186.590 °C at 10.000°C/min
Gas Type,Nitrogen
Pan Type,Tzero Aluminum Hermetic
Source Files 1,C:\Users\yargerlab\Desktop\DSC Data\General\Indium(6).tri
Measured 1,157.391
Known 1,156.598
[Cell Constant Calibration]
Date Applied,11/29/2022 7:12:29 PM
Description,From 106.590 °C to 186.590 °C at 10.000°C/min
Gas Type,Nitrogen
Pan Type,Tzero Aluminum Hermetic
Source Files 1,C:\Users\yargerlab\Desktop\DSC Data\General\Indium(6).tri
T4P KCell,1.006051
Onset Slope,63.26126 mW/°C
[Direct Cp Calibration]
Date Applied,11/30/2022 11:04:51 AM
Description,From -79.983 °C to 298.409 °C at 10.000°C/min
Gas Type,Nitrogen
Pan Type,Tzero Aluminum Hermetic
Source Files 1,C:\Users\yargerlab\Desktop\DSC Data\General\Sapphire_Heat_Capacity_11_30_22.tri
[Rev Cp Calibration]
Date Applied,11/30/2022 1:58:51 PM
Description,From -79.996 °C to 292.812 °C at 3.000°C/min
Gas Type,Nitrogen
Pan Type,Tzero Aluminum Hermetic
Source Files 1,C:\Users\yargerlab\Desktop\DSC Data\General\Sapphire_MDSC_Calibration_11_30_22.tri
[step]
Ramp 10.00 °C/min to 230.00 °C
Time,Temperature,Heat Flow (Normalized)
min,°C,W/g
0.00,-59.79,-0.043
0.02,-59.80,-0.041
0.04,-59.80,-0.037
0.06,-59.79,-0.034
0.08,-59.75,-0.027
0.10,-59.69,-0.015
0.12,-59.60,0.003
0.14,-59.48,0.024
0.16,-59.35,0.050
0.18,-59.19,0.074
0.20,-59.03,0.096
0.22,-58.86,0.115
0.24,-58.68,0.130
0.26,-58.50,0.143
0.28,-58.31,0.152
0.30,-58.12,0.160
0.32,-57.93,0.165
0.34,-57.74,0.169
0.36,-57.55,0.174
0.38,-57.36,0.176
0.40,-57.16,0.179
0.42,-56.97,0.180
0.44,-56.77,0.182
0.46,-56.58,0.184
0.48,-56.38,0.185
0.50,-56.19,0.186
0.52,-55.99,0.187
0.54,-55.80,0.187
0.56,-55.60,0.188
0.58,-55.40,0.189
0.60,-55.21,0.189
0.62,-55.01,0.190
0.64,-54.81,0.191
0.66,-54.62,0.191
0.68,-54.42,0.191
0.70,-54.22,0.192
0.72,-54.02,0.192
0.74,-53.83,0.193
0.76,-53.63,0.193
0.78,-53.43,0.194
0.80,-53.23,0.194
0.82,-53.03,0.194
0.84,-52.83,0.195
0.86,-52.64,0.195
0.88,-52.44,0.196
0.90,-52.24,0.196
0.92,-52.04,0.196
0.94,-51.84,0.196
0.96,-51.64,0.197
0.98,-51.44,0.197
1.00,-51.25,0.198
1.02,-51.05,0.198
1.04,-50.85,0.198
1.06,-50.65,0.199
1.08,-50.45,0.199
1.10,-50.25,0.199
1.12,-50.05,0.199
1.14,-49.85,0.200
1.16,-49.65,0.200
1.18,-49.46,0.200
1.20,-49.26,0.201
1.22,-49.06,0.201
1.24,-48.86,0.201
1.26,-48.66,0.201
1.28,-48.46,0.202
1.30,-48.26,0.202
1.32,-48.06,0.202
1.34,-47.86,0.202
1.36,-47.66,0.203
1.38,-47.46,0.203
1.40,-47.26,0.203
1.42,-47.06,0.203
1.44,-46.86,0.203
1.46,-46.66,0.204
1.48,-46.46,0.204
1.50,-46.26,0.204
1.52,-46.06,0.204
1.54,-45.86,0.205
1.56,-45.66,0.205
1.58,-45.46,0.205
1.60,-45.26,0.205
1.62,-45.06,0.205
1.64,-44.86,0.206
1.66,-44.66,0.206
1.68,-44.46,0.206
1.70,-44.26,0.206
1.72,-44.06,0.206
1.74,-43.86,0.206
1.76,-43.66,0.207
1.78,-43.46,0.207
1.80,-43.26,0.207
1.82,-43.06,0.207
1.84,-42.86,0.207
1.86,-42.66,0.207
1.88,-42.46,0.208
1.90,-42.26,0.208
1.92,-42.06,0.208
1.94,-41.86,0.208
1.96,-41.66,0.208
1.98,-41.46,0.208
2.00,-41.26,0.208
2.02,-41.06,0.209
2.04,-40.86,0.209
2.06,-40.66,0.209
2.08,-40.46,0.209
2.10,-40.26,0.209
2.12,-40.06,0.209
2.14,-39.86,0.209
2.16,-39.66,0.210
2.18,-39.46,0.210
2.20,-39.26,0.210
2.22,-39.06,0.210
2.24,-38.86,0.210
2.26,-38.66,0.210
2.28,-38.46,0.210
2.30,-38.26,0.211
2.32,-38.06,0.211
2.34,-37.86,0.211
2.36,-37.66,0.211
2.38,-37.46,0.211
2.40,-37.26,0.211
2.42,-37.05,0.211
2.44,-36.86,0.212
2.46,-36.65,0.212
2.48,-36.45,0.212
2.50,-36.25,0.212
2.52,-36.05,0.212
2.54,-35.85,0.212
2.56,-35.65,0.212
2.58,-35.45,0.213
2.60,-35.25,0.213
2.62,-35.05,0.213
2.64,-34.85,0.213
2.66,-34.65,0.213
2.68,-34.45,0.213
2.70,-34.25,0.213
2.72,-34.05,0.214
2.74,-33.85,0.214
2.76,-33.65,0.214
2.78,-33.45,0.214
2.80,-33.25,0.214
2.82,-33.05,0.214
2.84,-32.85,0.214
2.86,-32.65,0.214
2.88,-32.45,0.215
2.90,-32.25,0.215
2.92,-32.05,0.215
2.94,-31.85,0.215
2.96,-31.65,0.215
2.98,-31.45,0.215
3.00,-31.25,0.215
3.02,-31.05,0.216
3.04,-30.85,0.216
3.06,-30.65,0.216
3.08,-30.45,0.216
3.10,-30.25,0.216
3.12,-30.05,0.216
3.14,-29.85,0.216
3.16,-29.65,0.216
3.18,-29.45,0.217
3.20,-29.24,0.217
3.22,-29.04,0.217
3.24,-28.85,0.217
3.26,-28.64,0.217
3.28,-28.45,0.217
3.30,-28.24,0.217
3.32,-28.04,0.218
3.34,-27.85,0.218
3.36,-27.65,0.218
3.38,-27.44,0.218
3.40,-27.25,0.218
3.42,-27.05,0.218
3.44,-26.85,0.218
3.46,-26.65,0.219
3.48,-26.44,0.219
3.50,-26.24,0.219
3.52,-26.04,0.219
3.54,-25.84,0.219
3.56,-25.64,0.219
3.58,-25.44,0.220
3.60,-25.24,0.220
3.62,-25.04,0.220
3.64,-24.84,0.220
3.66,-24.64,0.220
3.68,-24.44,0.220
3.70,-24.24,0.221
3.72,-24.04,0.221
3.74,-23.84,0.221
3.76,-23.64,0.221
3.78,-23.44,0.221
3.80,-23.24,0.221
3.82,-23.04,0.222
3.84,-22.84,0.222
3.86,-22.64,0.222
3.88,-22.44,0.222
3.90,-22.24,0.222
3.92,-22.04,0.222
3.94,-21.84,0.223
3.96,-21.64,0.223
3.98,-21.44,0.223
4.00,-21.24,0.223
4.02,-21.04,0.223
4.04,-20.84,0.223
4.06,-20.64,0.224
4.08,-20.44,0.224
4.10,-20.24,0.224
4.12,-20.04,0.224
4.14,-19.84,0.224
4.16,-19.64,0.224
4.18,-19.44,0.224
4.20,-19.24,0.225
4.22,-19.04,0.225
4.24,-18.84,0.225
4.26,-18.64,0.225
4.28,-18.44,0.225
4.30,-18.24,0.225
4.32,-18.04,0.226
4.34,-17.83,0.226
4.36,-17.64,0.226
4.38,-17.44,0.226
4.40,-17.24,0.226
4.42,-17.03,0.226
4.44,-16.84,0.227
4.46,-16.64,0.227
4.48,-16.43,0.227
4.50,-16.23,0.227
4.52,-16.03,0.227
4.54,-15.83,0.227
4.56,-15.63,0.228
4.58,-15.43,0.228
4.60,-15.23,0.228
4.62,-15.03,0.228
4.64,-14.83,0.228
4.66,-14.63,0.229
4.68,-14.43,0.229
4.70,-14.23,0.229
4.72,-14.03,0.229
4.74,-13.83,0.229
4.76,-13.63,0.229
4.78,-13.43,0.230
4.80,-13.23,0.230
4.82,-13.03,0.230
4.84,-12.83,0.230
4.86,-12.63,0.230
4.88,-12.43,0.231
4.90,-12.23,0.231
4.92,-12.03,0.231
4.94,-11.83,0.231
4.96,-11.63,0.231
4.98,-11.43,0.232
5.00,-11.23,0.232
5.02,-11.03,0.232
5.04,-10.83,0.232
5.06,-10.63,0.232
5.08,-10.43,0.233
5.10,-10.23,0.233
5.12,-10.03,0.233
5.14,-9.83,0.233
5.16,-9.63,0.233
5.18,-9.43,0.234
5.20,-9.23,0.234
5.22,-9.03,0.234
5.24,-8.83,0.234
5.26,-8.63,0.234
5.28,-8.43,0.235
5.30,-8.23,0.235
5.32,-8.03,0.235
5.34,-7.83,0.235
5.36,-7.63,0.235
5.38,-7.43,0.236
5.40,-7.23,0.236
5.42,-7.03,0.236
5.44,-6.83,0.236
5.46,-6.63,0.236
5.48,-6.43,0.237
5.50,-6.23,0.237
5.52,-6.03,0.237
5.54,-5.83,0.237
5.56,-5.63,0.238
5.58,-5.43,0.238
5.60,-5.23,0.238
5.62,-5.03,0.238
5.64,-4.83,0.238
5.66,-4.63,0.239
5.68,-4.43,0.239
5.70,-4.23,0.239
5.72,-4.03,0.239
5.74,-3.83,0.240
5.76,-3.63,0.240
5.78,-3.43,0.240
5.80,-3.23,0.240
5.82,-3.02,0.241
5.84,-2.83,0.241
5.86,-2.62,0.241
5.88,-2.42,0.241
5.90,-2.22,0.241
5.92,-2.02,0.242
5.94,-1.82,0.242
5.96,-1.62,0.242
5.98,-1.42,0.242
6.00,-1.22,0.242
6.02,-1.02,0.243
6.04,-0.82,0.243
6.06,-0.62,0.243
6.08,-0.42,0.243
6.10,-0.22,0.244
6.12,-0.02,0.244
6.14,0.17,0.244
6.16,0.38,0.244
6.18,0.58,0.244
6.20,0.78,0.245
6.22,0.98,0.245
6.24,1.18,0.245
6.26,1.38,0.246
6.28,1.58,0.246
6.30,1.78,0.246
6.32,1.98,0.246
6.34,2.18,0.247
6.36,2.38,0.247
6.38,2.58,0.247
6.40,2.78,0.247
6.42,2.98,0.248
6.44,3.18,0.248
6.46,3.38,0.248
6.48,3.58,0.248
6.50,3.78,0.249
6.52,3.98,0.249
6.54,4.18,0.249
6.56,4.38,0.249
6.58,4.58,0.250
6.60,4.78,0.250
6.62,4.98,0.250
6.64,5.18,0.250
6.66,5.38,0.251
6.68,5.58,0.251
6.70,5.78,0.251
6.72,5.98,0.252
6.74,6.18,0.252
6.76,6.38,0.252
6.78,6.58,0.252
6.80,6.78,0.253
6.82,6.98,0.253
6.84,7.18,0.253
6.86,7.38,0.253
6.88,7.58,0.254
6.90,7.78,0.254
6.92,7.98,0.254
6.94,8.18,0.255
6.96,8.38,0.255
6.98,8.58,0.255
7.00,8.78,0.256
7.02,8.98,0.256
7.04,9.18,0.256
7.06,9.38,0.257
7.08,9.58,0.257
7.10,9.78,0.257
7.12,9.98,0.258
7.14,10.18,0.258
7.16,10.38,0.258
7.18,10.58,0.258
7.20,10.78,0.259
7.22,10.99,0.259
7.24,11.18,0.259
7.26,11.38,0.260
7.28,11.58,0.260
7.30,11.78,0.260
7.32,11.98,0.261
7.34,12.18,0.261
7.36,12.38,0.261
7.38,12.58,0.262
7.40,12.78,0.262
7.42,12.98,0.262
7.44,13.18,0.263
7.46,13.39,0.263
7.48,13.59,0.263
7.50,13.78,0.264
7.52,13.98,0.264
7.54,14.19,0.264
7.56,14.39,0.265
7.58,14.59,0.265
7.60,14.79,0.265
7.62,14.99,0.266
7.64,15.19,0.266
7.66,15.39,0.267
7.68,15.59,0.267
7.70,15.79,0.267
7.72,15.99,0.268
7.74,16.19,0.268
7.76,16.39,0.268
7.78,16.59,0.269
7.80,16.79,0.269
7.82,16.99,0.269
7.84,17.19,0.270
7.86,17.39,0.270
7.88,17.59,0.271
7.90,17.79,0.271
7.92,17.99,0.271
7.94,18.19,0.272
7.96,18.39,0.272
7.98,18.59,0.272
8.00,18.79,0.273
8.02,18.99,0.273
8.04,19.19,0.274
8.06,19.39,0.274
8.08,19.59,0.275
8.10,19.79,0.275
8.12,19.99,0.275
8.14,20.19,0.276
8.16,20.39,0.276
8.18,20.59,0.277
8.20,20.78,0.277
8.22,20.99,0.278
8.24,21.18,0.278
8.26,21.38,0.279
8.28,21.58,0.279
8.30,21.79,0.280
8.32,21.99,0.280
8.34,22.19,0.281
8.36,22.39,0.281
8.38,22.58,0.281
8.40,22.78,0.282
8.42,22.98,0.282
8.44,23.18,0.283
8.46,23.38,0.284
8.48,23.58,0.284
8.50,23.78,0.285
8.52,23.98,0.285
8.54,24.18,0.286
8.56,24.38,0.286
8.58,24.58,0.287
8.60,24.78,0.287
8.62,24.98,0.288
8.64,25.18,0.289
8.66,25.38,0.289
8.68,25.58,0.290
8.70,25.78,0.290
8.72,25.98,0.291
8.74,26.18,0.292
8.76,26.38,0.293
8.78,26.58,0.293
8.80,26.78,0.294
8.82,26.98,0.295
8.84,27.18,0.295
8.86,27.38,0.296
8.88,27.58,0.296
8.90,27.78,0.297
8.92,27.98,0.297
8.94,28.18,0.298
8.96,28.38,0.299
8.98,28.58,0.300
9.00,28.78,0.300
9.02,28.98,0.301
9.04,29.18,0.302
9.06,29.38,0.302
9.08,29.58,0.303
9.10,29.78,0.303
9.12,29.98,0.304
9.14,30.18,0.305
9.16,30.38,0.306
9.18,30.58,0.306
9.20,30.78,0.307
9.22,30.98,0.308
9.24,31.18,0.309
9.26,31.38,0.309
9.28,31.58,0.310
9.30,31.78,0.311
9.32,31.98,0.312
9.34,32.18,0.312
9.36,32.38,0.313
9.38,32.58,0.314
9.40,32.78,0.315
9.42,32.98,0.315
9.44,33.18,0.316
9.46,33.38,0.317
9.48,33.58,0.318
9.50,33.78,0.319
9.52,33.98,0.320
9.54,34.18,0.321
9.56,34.38,0.322
9.58,34.58,0.322
9.60,34.78,0.323
9.62,34.98,0.325
9.64,35.18,0.325
9.66,35.38,0.327
9.68,35.58,0.328
9.70,35.78,0.328
9.72,35.98,0.329
9.74,36.18,0.330
9.76,36.38,0.331
9.78,36.58,0.332
9.80,36.78,0.333
9.82,36.98,0.334
9.84,37.18,0.335
9.86,37.37,0.336
9.88,37.58,0.337
9.90,37.78,0.338
9.92,37.97,0.339
9.94,38.17,0.340
9.96,38.37,0.341
9.98,38.57,0.342
10.00,38.77,0.343
10.02,38.97,0.344
10.04,39.17,0.345
10.06,39.37,0.346
10.08,39.57,0.347
10.10,39.77,0.349
10.12,39.97,0.350
10.14,40.17,0.351
10.16,40.37,0.352
10.18,40.57,0.353
10.20,40.77,0.354
10.22,40.97,0.355
10.24,41.17,0.356
10.26,41.37,0.357
10.28,41.57,0.358
10.30,41.77,0.359
10.32,41.97,0.360
10.34,42.17,0.361
10.36,42.37,0.362
10.38,42.57,0.364
10.40,42.77,0.365
10.42,42.97,0.366
10.44,43.17,0.366
10.46,43.37,0.367
10.48,43.57,0.368
10.50,43.77,0.369
10.52,43.97,0.370
10.54,44.17,0.370
10.56,44.37,0.372
10.58,44.57,0.373
10.60,44.77,0.374
10.62,44.97,0.375
10.64,45.16,0.375
10.66,45.37,0.376
10.68,45.57,0.377
10.70,45.76,0.378
10.72,45.97,0.379
10.74,46.16,0.380
10.76,46.36,0.381
10.78,46.56,0.382
10.80,46.76,0.382
10.82,46.96,0.383
10.84,47.16,0.384
10.86,47.36,0.385
10.88,47.56,0.386
10.90,47.76,0.387
10.92,47.96,0.388
10.94,48.16,0.388
10.96,48.36,0.389
10.98,48.56,0.390
11.00,48.76,0.391
11.02,48.96,0.392
11.04,49.16,0.393
11.06,49.36,0.394
11.08,49.56,0.395
11.10,49.76,0.396
11.12,49.96,0.397
11.14,50.16,0.398
11.16,50.36,0.399
11.18,50.56,0.400
11.20,50.76,0.401
11.22,50.96,0.402
11.24,51.16,0.403
11.26,51.36,0.404
11.28,51.56,0.405
11.30,51.76,0.406
11.32,51.96,0.407
11.34,52.16,0.408
11.36,52.36,0.410
11.38,52.56,0.411
11.40,52.76,0.412
11.42,52.96,0.413
11.44,53.15,0.415
11.46,53.36,0.416
11.48,53.55,0.417
11.50,53.75,0.418
11.52,53.95,0.420
11.54,54.15,0.421
11.56,54.35,0.422
11.58,54.55,0.423
11.60,54.75,0.424
11.62,54.95,0.426
11.64,55.15,0.427
11.66,55.35,0.429
11.68,55.55,0.430
11.70,55.75,0.431
11.72,55.95,0.433
11.74,56.15,0.435
11.76,56.35,0.436
11.78,56.55,0.438
11.80,56.75,0.439
11.82,56.95,0.441
11.84,57.15,0.442
11.86,57.35,0.444
11.88,57.55,0.445
11.90,57.75,0.447
11.92,57.94,0.448
11.94,58.15,0.449
11.96,58.34,0.451
11.98,58.54,0.452
12.00,58.74,0.454
12.02,58.94,0.456
12.04,59.14,0.458
12.06,59.34,0.460
12.08,59.54,0.461
12.10,59.74,0.462
12.12,59.94,0.465
12.14,60.14,0.466
12.16,60.34,0.468
12.18,60.54,0.470
12.20,60.74,0.472
12.22,60.94,0.474
12.24,61.14,0.475
12.26,61.34,0.477
12.28,61.54,0.479
12.30,61.73,0.480
12.32,61.93,0.482
12.34,62.13,0.484
12.36,62.33,0.486
12.38,62.53,0.488
12.40,62.73,0.490
12.42,62.93,0.492
12.44,63.13,0.494
12.46,63.33,0.496
12.48,63.53,0.498
12.50,63.73,0.500
12.52,63.93,0.502
12.54,64.13,0.504
12.56,64.33,0.506
12.58,64.52,0.508
12.60,64.72,0.510
12.62,64.92,0.512
12.64,65.12,0.514
12.66,65.32,0.516
12.68,65.52,0.518
12.70,65.72,0.520
12.72,65.92,0.522
12.74,66.12,0.525
12.76,66.32,0.527
12.78,66.51,0.529
12.80,66.71,0.532
12.82,66.91,0.533
12.84,67.11,0.536
12.86,67.31,0.538
12.88,67.51,0.541
12.90,67.71,0.543
12.92,67.91,0.545
12.94,68.11,0.547
12.96,68.31,0.550
12.98,68.50,0.552
13.00,68.70,0.554
13.02,68.90,0.557
13.04,69.10,0.560
13.06,69.30,0.562
13.08,69.50,0.564
13.10,69.70,0.567
13.12,69.90,0.569
13.14,70.10,0.572
13.16,70.30,0.574
13.18,70.49,0.577
13.20,70.69,0.579
13.22,70.89,0.581
13.24,71.09,0.584
13.26,71.29,0.587
13.28,71.49,0.590
13.30,71.69,0.593
13.32,71.89,0.595
13.34,72.09,0.598
13.36,72.28,0.601
13.38,72.48,0.603
13.40,72.68,0.606
13.42,72.88,0.609
13.44,73.08,0.611
13.46,73.28,0.614
13.48,73.48,0.617
13.50,73.68,0.620
13.52,73.88,0.623
13.54,74.08,0.625
13.56,74.27,0.628
13.58,74.47,0.631
13.60,74.67,0.634
13.62,74.87,0.637
13.64,75.07,0.640
13.66,75.27,0.643
13.68,75.47,0.645
13.70,75.66,0.649
13.72,75.86,0.652
13.74,76.06,0.654
13.76,76.26,0.658
13.78,76.46,0.661
13.80,76.66,0.664
13.82,76.86,0.667
13.84,77.06,0.670
13.86,77.26,0.673
13.88,77.45,0.676
13.90,77.65,0.679
13.92,77.85,0.683
13.94,78.05,0.685
13.96,78.25,0.689
13.98,78.45,0.692
14.00,78.64,0.695
14.02,78.84,0.698
14.04,79.04,0.702
14.06,79.24,0.705
14.08,79.44,0.708
14.10,79.64,0.711
14.12,79.84,0.714
14.14,80.03,0.718
14.16,80.23,0.721
14.18,80.43,0.724
14.20,80.63,0.728
14.22,80.83,0.731
14.24,81.03,0.734
14.26,81.23,0.737
14.28,81.42,0.740
14.30,81.62,0.744
14.32,81.82,0.748
14.34,82.02,0.751
14.36,82.22,0.755
14.38,82.42,0.758
14.40,82.62,0.761
14.42,82.81,0.765
14.44,83.01,0.768
14.46,83.21,0.772
14.48,83.41,0.776
14.50,83.61,0.779
14.52,83.81,0.783
14.54,84.01,0.786
14.56,84.20,0.790
14.58,84.40,0.793
14.60,84.60,0.796
14.62,84.80,0.800
14.64,85.00,0.803
14.66,85.20,0.807
14.68,85.39,0.811
14.70,85.59,0.814
14.72,85.79,0.818
14.74,85.99,0.822
14.76,86.19,0.825
14.78,86.39,0.829
14.80,86.58,0.832
14.82,86.78,0.836
14.84,86.98,0.840
14.86,87.18,0.843
14.88,87.38,0.847
14.90,87.58,0.850
14.92,87.78,0.854
14.94,87.98,0.857
14.96,88.17,0.861
14.98,88.37,0.865
15.00,88.57,0.868
15.02,88.77,0.871
15.04,88.97,0.875
15.06,89.17,0.880
15.08,89.36,0.882
15.10,89.56,0.886
15.12,89.76,0.890
15.14,89.96,0.894
15.16,90.16,0.897
15.18,90.36,0.900
15.20,90.55,0.904
15.22,90.75,0.908
15.24,90.95,0.912
15.26,91.15,0.915
15.28,91.35,0.919
15.30,91.55,0.922
15.32,91.75,0.926
15.34,91.94,0.929
15.36,92.14,0.932
15.38,92.34,0.936
15.40,92.54,0.939
15.42,92.74,0.942
15.44,92.94,0.946
15.46,93.14,0.950
15.48,93.34,0.953
15.50,93.53,0.957
15.52,93.73,0.959
15.54,93.93,0.963
15.56,94.13,0.966
15.58,94.33,0.970
15.60,94.53,0.973
15.62,94.73,0.976
15.64,94.92,0.979
15.66,95.12,0.982
15.68,95.32,0.985
15.70,95.52,0.989
15.72,95.72,0.991
15.74,95.92,0.994
15.76,96.12,0.997
15.78,96.31,1.000
15.80,96.51,1.003
15.82,96.71,1.006
15.84,96.91,1.009
15.86,97.11,1.012
15.88,97.31,1.015
15.90,97.51,1.017
15.92,97.71,1.020
15.94,97.91,1.023
15.96,98.10,1.026
15.98,98.30,1.028
16.00,98.50,1.031
16.02,98.70,1.033
16.04,98.90,1.035
16.06,99.10,1.037
16.08,99.30,1.040
16.10,99.50,1.043
16.12,99.70,1.045
16.14,99.89,1.047
16.16,100.09,1.049
16.18,100.29,1.051
16.20,100.49,1.053
16.22,100.69,1.055
16.24,100.89,1.057
16.26,101.09,1.059
16.28,101.29,1.060
16.30,101.49,1.062
16.32,101.69,1.064
16.34,101.89,1.065
16.36,102.09,1.066
16.38,102.29,1.068
16.40,102.49,1.070
16.42,102.69,1.071
16.44,102.89,1.072
16.46,103.09,1.073
16.48,103.29,1.074
16.50,103.48,1.076
16.52,103.68,1.076
16.54,103.89,1.078
16.56,104.09,1.078
16.58,104.29,1.079
16.60,104.49,1.079
16.62,104.69,1.080
16.64,104.88,1.081
16.66,105.09,1.081
16.68,105.29,1.081
16.70,105.49,1.081
16.72,105.69,1.082
16.74,105.89,1.082
16.76,106.09,1.082
16.78,106.29,1.082
16.80,106.48,1.083
16.82,106.69,1.083
16.84,106.89,1.083
16.86,107.09,1.082
16.88,107.29,1.082
16.90,107.49,1.082
16.92,107.69,1.082
16.94,107.89,1.082
16.96,108.09,1.082
16.98,108.29,1.082
17.00,108.49,1.081
17.02,108.69,1.081
17.04,108.89,1.080
17.06,109.10,1.079
17.08,109.30,1.078
17.10,109.50,1.077
17.12,109.70,1.075
17.14,109.90,1.073
17.16,110.10,1.071
17.18,110.30,1.069
17.20,110.50,1.066
17.22,110.70,1.065
17.24,110.90,1.062
17.26,111.10,1.060
17.28,111.31,1.058
17.30,111.51,1.055
17.32,111.71,1.054
17.34,111.91,1.051
17.36,112.11,1.049
17.38,112.31,1.046
17.40,112.51,1.043
17.42,112.71,1.041
17.44,112.92,1.038
17.46,113.12,1.035
17.48,113.32,1.032
17.50,113.52,1.029
17.52,113.72,1.026
17.54,113.92,1.023
17.56,114.12,1.020
17.58,114.33,1.016
17.60,114.53,1.014
17.62,114.73,1.010
17.64,114.93,1.007
17.66,115.13,1.004
17.68,115.34,1.000
17.70,115.54,0.996
17.72,115.74,0.993
17.74,115.94,0.989
17.76,116.15,0.985
17.78,116.35,0.981
17.80,116.55,0.978
17.82,116.75,0.974
17.84,116.96,0.970
17.86,117.16,0.966
17.88,117.36,0.962
17.90,117.56,0.957
17.92,117.76,0.953
17.94,117.97,0.949
17.96,118.17,0.945
17.98,118.37,0.940
18.00,118.57,0.936
18.02,118.78,0.932
18.04,118.98,0.928
18.06,119.18,0.924
18.08,119.38,0.919
18.10,119.59,0.915
18.12,119.79,0.910
18.14,119.99,0.906
18.16,120.19,0.902
18.18,120.40,0.897
18.20,120.60,0.893
18.22,120.80,0.888
18.24,121.00,0.884
18.26,121.21,0.878
18.28,121.41,0.874
18.30,121.61,0.869
18.32,121.81,0.865
18.34,122.02,0.860
18.36,122.22,0.856
18.38,122.42,0.851
18.40,122.62,0.847
18.42,122.83,0.842
18.44,123.03,0.837
18.46,123.23,0.833
18.48,123.43,0.828
18.50,123.64,0.823
18.52,123.84,0.818
18.54,124.04,0.814
18.56,124.24,0.810
18.58,124.45,0.805
18.60,124.65,0.800
18.62,124.85,0.796
18.64,125.05,0.791
18.66,125.26,0.785
18.68,125.46,0.781
18.70,125.66,0.776
18.72,125.87,0.772
18.74,126.07,0.767
18.76,126.27,0.761
18.78,126.47,0.757
18.80,126.68,0.752
18.82,126.88,0.748
18.84,127.08,0.743
18.86,127.29,0.738
18.88,127.49,0.734
18.90,127.69,0.729
18.92,127.89,0.725
18.94,128.10,0.720
18.96,128.30,0.716
18.98,128.50,0.711
19.00,128.70,0.706
19.02,128.91,0.701
19.04,129.11,0.697
19.06,129.31,0.693
19.08,129.51,0.688
19.10,129.72,0.683
19.12,129.92,0.679
19.14,130.12,0.675
19.16,130.32,0.670
19.18,130.53,0.666
19.20,130.73,0.662
19.22,130.93,0.657
19.24,131.13,0.653
19.26,131.33,0.648
19.28,131.54,0.643
19.30,131.74,0.639
19.32,131.94,0.635
19.34,132.15,0.631
19.36,132.35,0.626
19.38,132.55,0.622
19.40,132.75,0.618
19.42,132.95,0.614
19.44,133.16,0.610
19.46,133.36,0.606
19.48,133.56,0.601
19.50,133.76,0.597
19.52,133.97,0.593
19.54,134.17,0.589
19.56,134.37,0.584
19.58,134.57,0.580
19.60,134.77,0.576
19.62,134.97,0.573
19.64,135.18,0.568
19.66,135.38,0.565
19.68,135.58,0.561
19.70,135.78,0.557
19.72,135.98,0.554
19.74,136.19,0.549
19.76,136.39,0.546
19.78,136.59,0.542
19.80,136.79,0.538
19.82,136.99,0.534
19.84,137.20,0.530
19.86,137.40,0.527
19.88,137.60,0.523
19.90,137.80,0.520
19.92,138.00,0.516
19.94,138.21,0.513
19.96,138.41,0.510
19.98,138.61,0.506
20.00,138.81,0.502
20.02,139.01,0.499
20.04,139.22,0.496
20.06,139.42,0.492
20.08,139.62,0.489
20.10,139.82,0.486
20.12,140.02,0.483
20.14,140.22,0.479
20.16,140.43,0.476
20.18,140.63,0.473
20.20,140.83,0.470
20.22,141.03,0.467
20.24,141.23,0.464
20.26,141.44,0.460
20.28,141.64,0.458
20.30,141.84,0.454
20.32,142.04,0.452
20.34,142.24,0.449
20.36,142.44,0.446
20.38,142.64,0.443
20.40,142.85,0.441
20.42,143.05,0.438
20.44,143.25,0.435
20.46,143.45,0.433
20.48,143.65,0.430
20.50,143.85,0.426
20.52,144.06,0.424
20.54,144.26,0.422
20.56,144.46,0.419
20.58,144.66,0.417
20.60,144.86,0.415
20.62,145.06,0.413
20.64,145.26,0.410
20.66,145.47,0.408
20.68,145.67,0.405
20.70,145.87,0.403
20.72,146.07,0.401
20.74,146.27,0.399
20.76,146.47,0.396
20.78,146.67,0.394
20.80,146.87,0.392
20.82,147.08,0.390
20.84,147.28,0.389
20.86,147.48,0.387
20.88,147.68,0.385
20.90,147.88,0.384
20.92,148.08,0.382
20.94,148.28,0.380
20.96,148.48,0.378
20.98,148.69,0.376
21.00,148.89,0.375
21.02,149.09,0.373
21.04,149.29,0.371
21.06,149.49,0.369
21.08,149.69,0.368
21.10,149.89,0.367
21.12,150.09,0.366
21.14,150.29,0.364
21.16,150.49,0.363
21.18,150.69,0.362
21.20,150.89,0.361
21.22,151.09,0.359
21.24,151.29,0.359
21.26,151.50,0.358
21.28,151.70,0.357
21.30,151.90,0.356
21.32,152.10,0.355
21.34,152.30,0.355
21.36,152.50,0.354
21.38,152.70,0.353
21.40,152.90,0.353
21.42,153.10,0.352
21.44,153.30,0.352
21.46,153.50,0.351
21.48,153.70,0.351
21.50,153.91,0.350
21.52,154.11,0.350
21.54,154.31,0.349
21.56,154.51,0.349
21.58,154.71,0.349
21.60,154.91,0.348
21.62,155.11,0.348
21.64,155.31,0.347
21.66,155.51,0.347
21.68,155.71,0.347
21.70,155.91,0.347
21.72,156.11,0.346
21.74,156.31,0.346
21.76,156.51,0.346
21.78,156.71,0.346
21.80,156.91,0.346
21.82,157.11,0.346
21.84,157.31,0.346
21.86,157.51,0.346
21.88,157.71,0.346
21.90,157.91,0.346
21.92,158.11,0.346
21.94,158.31,0.346
21.96,158.51,0.347
21.98,158.71,0.347
22.00,158.91,0.347
22.02,159.11,0.347
22.04,159.31,0.348
22.06,159.51,0.348
22.08,159.71,0.349
22.10,159.91,0.349
22.12,160.11,0.350
22.14,160.30,0.350
22.16,160.51,0.351
22.18,160.71,0.351
22.20,160.91,0.351
22.22,161.11,0.352
22.24,161.31,0.352
22.26,161.51,0.353
22.28,161.71,0.353
22.30,161.91,0.353
22.32,162.11,0.354
22.34,162.31,0.354
22.36,162.51,0.354
22.38,162.71,0.354
22.40,162.91,0.354
22.42,163.11,0.354
22.44,163.31,0.355
22.46,163.51,0.355
22.48,163.71,0.355
22.50,163.91,0.355
22.52,164.11,0.355
22.54,164.31,0.354
22.56,164.51,0.354
22.58,164.71,0.353
22.60,164.91,0.353
22.62,165.11,0.353
22.64,165.31,0.352
22.66,165.51,0.352
22.68,165.71,0.352
22.70,165.91,0.351
22.72,166.11,0.351
22.74,166.31,0.350
22.76,166.51,0.350
22.78,166.71,0.350
22.80,166.91,0.349
22.82,167.11,0.349
22.84,167.32,0.348
22.86,167.52,0.348
22.88,167.72,0.348
22.90,167.92,0.347
22.92,168.12,0.347
22.94,168.32,0.347
22.96,168.52,0.347
22.98,168.72,0.346
23.00,168.92,0.346
23.02,169.12,0.346
23.04,169.32,0.346
23.06,169.52,0.345
23.08,169.72,0.345
23.10,169.92,0.345
23.12,170.12,0.345
23.14,170.32,0.344
23.16,170.52,0.344
23.18,170.72,0.344
23.20,170.92,0.344
23.22,171.12,0.344
23.24,171.32,0.344
23.26,171.52,0.344
23.28,171.72,0.344
23.30,171.92,0.344
23.32,172.12,0.344
23.34,172.32,0.344
23.36,172.52,0.344
23.38,172.72,0.344
23.40,172.92,0.344
23.42,173.12,0.344
23.44,173.32,0.344
23.46,173.52,0.344
23.48,173.72,0.344
23.50,173.92,0.344
23.52,174.12,0.344
23.54,174.32,0.344
23.56,174.52,0.344
23.58,174.72,0.344
23.60,174.92,0.344
23.62,175.12,0.344
23.64,175.32,0.344
23.66,175.52,0.344
23.68,175.72,0.344
23.70,175.92,0.345
23.72,176.12,0.345
23.74,176.32,0.345
23.76,176.52,0.345
23.78,176.72,0.345
23.80,176.93,0.345
23.82,177.12,0.345
23.84,177.32,0.345
23.86,177.53,0.345
23.88,177.72,0.346
23.90,177.92,0.346
23.92,178.12,0.346
23.94,178.32,0.346
23.96,178.52,0.346
23.98,178.72,0.346
24.00,178.92,0.346
24.02,179.12,0.346
24.04,179.32,0.346
24.06,179.52,0.347
24.08,179.72,0.347
24.10,179.92,0.347
24.12,180.12,0.347
24.14,180.33,0.347
24.16,180.53,0.347
24.18,180.73,0.347
24.20,180.93,0.348
24.22,181.13,0.348
24.24,181.33,0.348
24.26,181.53,0.348
24.28,181.73,0.348
24.30,181.93,0.349
24.32,182.13,0.349
24.34,182.33,0.349
24.36,182.53,0.349
24.38,182.73,0.349
24.40,182.93,0.349
24.42,183.13,0.349
24.44,183.33,0.350
24.46,183.53,0.350
24.48,183.73,0.350
24.50,183.93,0.350
24.52,184.13,0.350
24.54,184.33,0.351
24.56,184.53,0.351
24.58,184.73,0.351
24.60,184.93,0.351
24.62,185.13,0.351
24.64,185.33,0.351
24.66,185.53,0.352
24.68,185.73,0.352
24.70,185.93,0.352
24.72,186.13,0.352
24.74,186.33,0.352
24.76,186.53,0.353
24.78,186.73,0.353
24.80,186.93,0.353
24.82,187.13,0.353
24.84,187.33,0.353
24.86,187.53,0.354
24.88,187.73,0.354
24.90,187.93,0.354
24.92,188.13,0.354
24.94,188.33,0.354
24.96,188.53,0.354
24.98,188.73,0.355
25.00,188.93,0.355
25.02,189.13,0.355
25.04,189.33,0.355
25.06,189.53,0.355
25.08,189.73,0.356
25.10,189.93,0.356
25.12,190.13,0.356
25.14,190.33,0.356
25.16,190.53,0.357
25.18,190.73,0.357
25.20,190.93,0.357
25.22,191.13,0.358
25.24,191.33,0.358
25.26,191.53,0.358
25.28,191.73,0.358
25.30,191.93,0.358
25.32,192.13,0.359
25.34,192.33,0.359
25.36,192.53,0.359
25.38,192.73,0.359
25.40,192.93,0.360
25.42,193.13,0.360
25.44,193.33,0.360
25.46,193.53,0.360
25.48,193.73,0.361
25.50,193.93,0.361
25.52,194.13,0.361
25.54,194.33,0.362
25.56,194.53,0.362
25.58,194.73,0.362
25.60,194.93,0.362
25.62,195.13,0.363
25.64,195.33,0.363
25.66,195.53,0.363
25.68,195.73,0.363
25.70,195.93,0.364
25.72,196.13,0.364
25.74,196.33,0.364
25.76,196.53,0.365
25.78,196.73,0.365
25.80,196.93,0.365
25.82,197.13,0.365
25.84,197.33,0.366
25.86,197.53,0.366
25.88,197.73,0.366
25.90,197.93,0.367
25.92,198.13,0.367
25.94,198.33,0.367
25.96,198.53,0.367
25.98,198.73,0.368
26.00,198.93,0.368
26.02,199.13,0.368
26.04,199.33,0.368
26.06,199.53,0.369
26.08,199.73,0.369
26.10,199.93,0.369
26.12,200.13,0.370
26.14,200.33,0.370
26.16,200.53,0.370
26.18,200.73,0.370
26.20,200.93,0.371
26.22,201.13,0.371
26.24,201.33,0.371
26.26,201.53,0.372
26.28,201.73,0.372
26.30,201.93,0.372
26.32,202.13,0.372
26.34,202.33,0.373
26.36,202.53,0.373
26.38,202.73,0.373
26.40,202.93,0.373
26.42,203.13,0.374
26.44,203.33,0.374
26.46,203.53,0.374
26.48,203.73,0.374
26.50,203.93,0.375
26.52,204.13,0.375
26.54,204.33,0.375
26.56,204.54,0.375
26.58,204.73,0.376
26.60,204.94,0.376
26.62,205.14,0.376
26.64,205.34,0.376
26.66,205.54,0.376
26.68,205.74,0.377
26.70,205.94,0.377
26.72,206.14,0.377
26.74,206.34,0.377
26.76,206.54,0.377
26.78,206.74,0.378
26.80,206.94,0.378
26.82,207.14,0.378
26.84,207.34,0.378
26.86,207.54,0.378
26.88,207.74,0.378
26.90,207.94,0.379
26.92,208.14,0.379
26.94,208.34,0.379
26.96,208.54,0.379
26.98,208.74,0.379
27.00,208.94,0.380
27.02,209.14,0.380
27.04,209.34,0.380
27.06,209.53,0.380
27.08,209.74,0.380
27.10,209.94,0.380
27.12,210.14,0.381
27.14,210.34,0.381
27.16,210.54,0.381
27.18,210.74,0.381
27.20,210.94,0.381
27.22,211.14,0.381
27.24,211.34,0.382
27.26,211.54,0.382
27.28,211.74,0.382
27.30,211.94,0.382
27.32,212.14,0.382
27.34,212.34,0.382
27.36,212.54,0.383
27.38,212.74,0.383
27.40,212.94,0.383
27.42,213.14,0.383
27.44,213.34,0.383
27.46,213.54,0.383
27.48,213.74,0.384
27.50,213.94,0.384
27.52,214.14,0.384
27.54,214.34,0.384
27.56,214.54,0.384
27.58,214.74,0.384
27.60,214.94,0.385
27.62,215.14,0.385
27.64,215.34,0.385
27.66,215.54,0.385
27.68,215.74,0.385
27.70,215.94,0.385
27.72,216.14,0.385
27.74,216.34,0.385
27.76,216.54,0.386
27.78,216.74,0.386
27.80,216.94,0.386
27.82,217.14,0.386
27.84,217.34,0.386
27.86,217.54,0.386
27.88,217.74,0.387
27.90,217.94,0.387
27.92,218.14,0.387
27.94,218.34,0.387
27.96,218.54,0.387
27.98,218.74,0.387
28.00,218.94,0.387
28.02,219.14,0.387
28.04,219.34,0.387
28.06,219.54,0.387
28.08,219.74,0.388
28.10,219.94,0.388
28.12,220.14,0.388
28.14,220.34,0.388
28.16,220.54,0.388
28.18,220.74,0.388
28.20,220.94,0.388
28.22,221.14,0.388
28.24,221.34,0.389
28.26,221.54,0.389
28.28,221.74,0.389
28.30,221.94,0.389
28.32,222.14,0.389
28.34,222.34,0.389
28.36,222.54,0.389
28.38,222.74,0.389
28.40,222.94,0.389
28.42,223.14,0.389
28.44,223.34,0.389
28.46,223.54,0.389
28.48,223.74,0.389
28.50,223.94,0.389
28.52,224.14,0.390
28.54,224.34,0.390
28.56,224.54,0.390
28.58,224.74,0.390
28.60,224.94,0.390
28.62,225.14,0.390
28.64,225.34,0.390
28.66,225.54,0.390
28.68,225.75,0.391
28.70,225.95,0.391
28.72,226.15,0.391
28.74,226.34,0.391
28.76,226.55,0.391
28.78,226.74,0.391
28.80,226.94,0.391
28.82,227.15,0.391
28.84,227.35,0.391
28.86,227.55,0.391
28.88,227.75,0.391
28.90,227.95,0.391
28.92,228.15,0.391
28.94,228.35,
28.96,228.55,
28.98,228.75,
28.99,,

[step]
Ramp 10.00 °C/min to -60.00 °C
Time,Temperature,Heat Flow (Normalized)
min,°C,W/g
30.99,230.16,-0.002
31.01,230.15,-0.002
31.03,230.15,-0.003
31.05,230.13,-0.004
31.07,230.10,-0.021
31.09,230.04,-0.049
31.11,229.95,-0.091
31.13,229.83,-0.142
31.15,229.69,-0.193
31.17,229.54,-0.239
31.19,229.37,-0.276
31.21,229.19,-0.303
31.23,229.01,-0.324
31.25,228.82,-0.338
31.27,228.63,-0.347
31.29,228.44,-0.355
31.31,228.25,-0.361
31.33,228.06,-0.365
31.35,227.86,-0.369
31.37,227.67,-0.370
31.39,227.47,-0.373
31.41,227.27,-0.374
31.43,227.08,-0.375
31.45,226.88,-0.376
31.47,226.68,-0.377
31.49,226.48,-0.377
31.51,226.29,-0.378
31.53,226.09,-0.379
31.55,225.89,-0.379
31.57,225.69,-0.379
31.59,225.49,-0.379
31.61,225.29,-0.380
31.63,225.09,-0.380
31.65,224.90,-0.380
31.67,224.70,-0.380
31.69,224.50,-0.381
31.71,224.30,-0.381
31.73,224.10,-0.381
31.75,223.90,-0.381
31.77,223.70,-0.381
31.79,223.51,-0.381
31.81,223.31,-0.381
31.83,223.11,-0.382
31.85,222.91,-0.382
31.87,222.71,-0.382
31.89,222.51,-0.382
31.91,222.31,-0.382
31.93,222.11,-0.382
31.95,221.91,-0.383
31.97,221.71,-0.383
31.99,221.51,-0.383
32.01,221.32,-0.383
32.03,221.12,-0.383
32.05,220.92,-0.383
32.07,220.72,-0.383
32.09,220.52,-0.383
32.11,220.32,-0.383
32.13,220.12,-0.383
32.15,219.92,-0.383
32.17,219.72,-0.383
32.19,219.52,-0.383
32.21,219.32,-0.383
32.23,219.12,-0.383
32.25,218.92,-0.383
32.27,218.72,-0.384
32.29,218.52,-0.384
32.31,218.32,-0.384
32.33,218.12,-0.384
32.35,217.93,-0.384
32.37,217.73,-0.383
32.39,217.53,-0.383
32.41,217.33,-0.383
32.43,217.13,-0.383
32.45,216.93,-0.383
32.47,216.73,-0.383
32.49,216.53,-0.383
32.51,216.33,-0.383
32.53,216.13,-0.383
32.55,215.93,-0.383
32.57,215.73,-0.383
32.59,215.53,-0.383
32.61,215.33,-0.383
32.63,215.13,-0.384
32.65,214.93,-0.383
32.67,214.73,-0.383
32.69,214.53,-0.383
32.71,214.33,-0.383
32.73,214.13,-0.383
32.75,213.93,-0.383
32.77,213.73,-0.383
32.79,213.53,-0.383
32.81,213.33,-0.383
32.83,213.13,-0.383
32.85,212.93,-0.383
32.87,212.73,-0.383
32.89,212.53,-0.383
32.91,212.33,-0.383
32.93,212.14,-0.383
32.95,211.94,-0.383
32.97,211.74,-0.383
32.99,211.54,-0.383
33.01,211.34,-0.383
33.03,211.14,-0.383
33.05,210.94,-0.383
33.07,210.74,-0.383
33.09,210.54,-0.383
33.11,210.34,-0.382
33.13,210.14,-0.382
33.15,209.94,-0.382
33.17,209.74,-0.382
33.19,209.54,-0.382
33.21,209.34,-0.382
33.23,209.14,-0.382
33.25,208.94,-0.382
33.27,208.74,-0.382
33.29,208.54,-0.382
33.31,208.34,-0.382
33.33,208.14,-0.382
33.35,207.94,-0.382
33.37,207.74,-0.382
33.39,207.54,-0.382
33.41,207.34,-0.382
33.43,207.14,-0.382
33.45,206.94,-0.382
33.47,206.74,-0.381
33.49,206.54,-0.381
33.51,206.34,-0.381
33.53,206.14,-0.381
33.55,205.94,-0.381
33.57,205.74,-0.381
33.59,205.54,-0.381
33.61,205.34,-0.381
33.63,205.14,-0.381
33.65,204.94,-0.381
33.67,204.74,-0.381
33.69,204.54,-0.381
33.71,204.34,-0.381
33.73,204.14,-0.381
33.75,203.94,-0.381
33.77,203.74,-0.381
33.79,203.54,-0.380
33.81,203.34,-0.380
33.83,203.14,-0.380
33.85,202.94,-0.380
33.87,202.74,-0.380
33.89,202.54,-0.380
33.91,202.34,-0.380
33.93,202.14,-0.380
33.95,201.94,-0.380
33.97,201.74,-0.380
33.99,201.54,-0.380
34.01,201.34,-0.380
34.03,201.14,-0.380
34.05,200.94,-0.379
34.07,200.74,-0.379
34.09,200.54,-0.379
34.11,200.34,-0.379
34.13,200.14,-0.379
34.15,199.94,-0.379
34.17,199.74,-0.379
34.19,199.54,-0.379
34.21,199.34,-0.379
34.23,199.14,-0.379
34.25,198.94,-0.379
34.27,198.74,-0.379
34.29,198.54,-0.379
34.31,198.34,-0.379
34.33,198.14,-0.379
34.35,197.94,-0.379
34.37,197.74,-0.379
34.39,197.54,-0.379
34.41,197.34,-0.379
34.43,197.14,-0.378
34.45,196.94,-0.378
34.47,196.74,-0.378
34.49,196.54,-0.378
34.51,196.34,-0.378
34.53,196.14,-0.378
34.55,195.94,-0.378
34.57,195.74,-0.378
34.59,195.54,-0.378
34.61,195.34,-0.378
34.63,195.14,-0.378
34.65,194.94,-0.378
34.67,194.74,-0.378
34.69,194.54,-0.378
34.71,194.34,-0.378
34.73,194.14,-0.378
34.75,193.94,-0.377
34.77,193.74,-0.377
34.79,193.54,-0.377
34.81,193.34,-0.377
34.83,193.14,-0.377
34.85,192.94,-0.377
34.87,192.74,-0.377
34.89,192.54,-0.377
34.91,192.34,-0.377
34.93,192.14,-0.377
34.95,191.94,-0.377
34.97,191.75,-0.377
34.99,191.55,-0.377
35.01,191.35,-0.377
35.03,191.14,-0.377
35.05,190.94,-0.376
35.07,190.75,-0.376
35.09,190.55,-0.376
35.11,190.34,-0.376
35.13,190.15,-0.376
35.15,189.95,-0.376
35.17,189.75,-0.376
35.19,189.55,-0.376
35.21,189.34,-0.376
35.23,189.15,-0.376
35.25,188.95,-0.376
35.27,188.75,-0.376
35.29,188.55,-0.376
35.31,188.35,-0.375
35.33,188.15,-0.375
35.35,187.95,-0.375
35.37,187.75,-0.375
35.39,187.55,-0.375
35.41,187.35,-0.375
35.43,187.15,-0.375
35.45,186.95,-0.375
35.47,186.75,-0.375
35.49,186.55,-0.375
35.51,186.35,-0.375
35.53,186.15,-0.375
35.55,185.95,-0.375
35.57,185.75,-0.375
35.59,185.55,-0.374
35.61,185.35,-0.374
35.63,185.15,-0.374
35.65,184.95,-0.374
35.67,184.75,-0.374
35.69,184.55,-0.374
35.71,184.35,-0.374
35.73,184.15,-0.374
35.75,183.95,-0.374
35.77,183.75,-0.374
35.79,183.55,-0.374
35.81,183.35,-0.374
35.83,183.15,-0.374
35.85,182.95,-0.373
35.87,182.75,-0.373
35.89,182.55,-0.373
35.91,182.35,-0.373
35.93,182.15,-0.373
35.95,181.95,-0.373
35.97,181.75,-0.373
35.99,181.55,-0.373
36.01,181.35,-0.373
36.03,181.15,-0.373
36.05,180.95,-0.373
36.07,180.75,-0.372
36.09,180.55,-0.372
36.11,180.35,-0.372
36.13,180.15,-0.372
36.15,179.95,-0.372
36.17,179.75,-0.372
36.19,179.55,-0.372
36.21,179.35,-0.372
36.23,179.15,-0.372
36.25,178.95,-0.372
36.27,178.75,-0.371
36.29,178.55,-0.371
36.31,178.35,-0.371
36.33,178.15,-0.371
36.35,177.95,-0.371
36.37,177.75,-0.371
36.39,177.55,-0.371
36.41,177.35,-0.371
36.43,177.15,-0.371
36.45,176.95,-0.371
36.47,176.75,-0.370
36.49,176.55,-0.370
36.51,176.35,-0.370
36.53,176.15,-0.370
36.55,175.95,-0.370
36.57,175.75,-0.370
36.59,175.55,-0.370
36.61,175.35,-0.370
36.63,175.15,-0.369
36.65,174.95,-0.369
36.67,174.75,-0.369
36.69,174.55,-0.369
36.71,174.35,-0.369
36.73,174.15,-0.369
36.75,173.95,-0.369
36.77,173.75,-0.368
36.79,173.55,-0.368
36.81,173.35,-0.368
36.83,173.15,-0.368
36.85,172.95,-0.368
36.87,172.75,-0.367
36.89,172.55,-0.367
36.91,172.35,-0.367
36.93,172.15,-0.367
36.95,171.95,-0.366
36.97,171.75,-0.366
36.99,171.55,-0.366
37.01,171.35,-0.365
37.03,171.15,-0.365
37.05,170.95,-0.365
37.07,170.75,-0.365
37.09,170.55,-0.364
37.11,170.35,-0.364
37.13,170.15,-0.364
37.15,169.95,-0.363
37.17,169.75,-0.363
37.19,169.55,-0.363
37.21,169.35,-0.362
37.23,169.15,-0.362
37.25,168.95,-0.362
37.27,168.75,-0.361
37.29,168.55,-0.361
37.31,168.35,-0.361
37.33,168.15,-0.360
37.35,167.95,-0.360
37.37,167.75,-0.359
37.39,167.55,-0.359
37.41,167.35,-0.358
37.43,167.15,-0.358
37.45,166.95,-0.357
37.47,166.75,-0.356
37.49,166.55,-0.356
37.51,166.35,-0.356
37.53,166.15,-0.355
37.55,165.95,-0.355
37.57,165.75,-0.354
37.59,165.55,-0.354
37.61,165.35,-0.353
37.63,165.15,-0.353
37.65,164.95,-0.352
37.67,164.75,-0.352
37.69,164.55,-0.351
37.71,164.35,-0.350
37.73,164.15,-0.350
37.75,163.95,-0.349
37.77,163.75,-0.348
37.79,163.55,-0.348
37.81,163.35,-0.348
37.83,163.15,-0.347
37.85,162.95,-0.347
37.87,162.75,-0.346
37.89,162.55,-0.345
37.91,162.34,-0.345
37.93,162.15,-0.345
37.95,161.94,-0.344
37.97,161.74,-0.344
37.99,161.54,-0.343
38.01,161.34,-0.343
38.03,161.14,-0.343
38.05,160.94,-0.342
38.07,160.74,-0.342
38.09,160.54,-0.341
38.11,160.34,-0.341
38.13,160.14,-0.340
38.15,159.94,-0.340
38.17,159.74,-0.339
38.19,159.54,-0.339
38.21,159.34,-0.338
38.23,159.14,-0.338
38.25,158.94,-0.337
38.27,158.74,-0.337
38.29,158.54,-0.337
38.31,158.34,-0.336
[...]
132.64,25.08,0.193
132.65,25.28,0.193
132.68,25.48,0.193
132.70,25.68,0.193
132.71,25.88,0.193
132.74,26.08,0.193
132.75,26.28,0.193
132.78,26.48,0.193
132.80,26.68,0.194
132.81,26.88,0.194
132.84,27.08,0.194
132.85,27.28,0.194
132.88,27.48,0.194
132.90,27.68,0.194
132.91,27.88,0.194
132.94,28.08,0.195
132.95,28.28,0.195
132.98,28.48,0.195
133.00,28.68,0.195
133.01,28.89,0.195
133.04,29.08,0.195
133.05,29.29,0.195
133.08,29.49,0.195
133.10,29.69,0.195
133.11,29.89,0.196
133.14,30.09,0.196
133.15,30.29,0.196
133.18,30.49,0.196
133.20,30.69,0.196
133.21,30.89,0.196
133.24,31.09,0.196
133.25,31.29,0.196
133.28,31.49,0.197
133.30,31.69,0.197
133.31,31.89,0.197
133.34,32.09,0.197
133.35,32.29,0.197
133.38,32.49,0.197
133.40,32.69,0.197
133.41,32.89,0.198
133.44,33.09,0.198
133.45,33.29,0.198
133.48,33.49,0.198
133.50,33.69,0.198
133.51,33.89,0.198
133.54,34.09,0.198
133.55,34.29,0.198
133.58,34.49,0.198
133.60,34.69,0.199
133.61,34.89,0.199
133.64,35.09,0.199
133.65,35.29,0.199
133.68,35.49,0.199
133.70,35.69,0.199
133.71,35.89,0.199
133.74,36.09,0.199
133.75,36.29,0.200
133.78,36.49,0.200
133.80,36.69,0.200
133.81,36.89,0.200
133.84,37.09,0.200
133.85,37.29,0.200
133.88,37.49,0.200
133.90,37.69,0.200
133.91,37.89,0.200
133.94,38.09,0.201
133.95,38.29,0.201
133.98,38.49,0.201
134.00,38.69,0.201
134.01,38.90,0.201
134.04,39.09,0.201
134.05,39.29,0.201
134.08,39.49,0.201
134.10,39.69,0.202
134.11,39.90,0.202
134.14,40.10,0.202
134.15,40.30,0.202
134.18,40.50,0.202
134.20,40.70,0.202
134.21,40.90,0.202
134.24,41.10,0.202
134.25,41.30,0.203
134.28,41.50,0.203
134.30,41.70,0.203
134.31,41.90,0.203
134.34,42.10,0.203
134.35,42.30,0.203
134.38,42.50,0.203
134.40,42.70,0.203
134.41,42.90,0.204
134.44,43.10,0.204
134.45,43.30,0.204
134.48,43.50,0.204
134.50,43.70,0.204
134.51,43.90,0.204
134.54,44.10,0.204
134.55,44.30,0.204
134.58,44.50,0.205
134.60,44.70,0.205
134.61,44.90,0.205
134.64,45.10,0.205
134.65,45.30,0.205
134.68,45.50,0.205
134.70,45.70,0.205
134.71,45.90,0.206
134.74,46.10,0.206
134.75,46.30,0.206
134.78,46.50,0.206
134.80,46.70,0.206
134.81,46.90,0.206
134.84,47.10,0.206
134.85,47.30,0.206
134.88,47.50,0.207
134.90,47.70,0.207
134.91,47.90,0.207
134.94,48.10,0.207
134.95,48.30,0.207
134.98,48.50,0.207
135.00,48.70,0.207
135.01,48.90,0.208
135.04,49.10,0.208
135.05,49.30,0.208
135.08,49.50,0.208
135.10,49.70,0.208
135.11,49.90,0.208
135.14,50.10,0.208
135.15,50.30,0.208
135.18,50.50,0.209
135.20,50.71,0.209
135.21,50.91,0.209
135.24,51.11,0.209
135.25,51.31,0.209
135.28,51.51,0.209
135.30,51.71,0.209
135.31,51.91,0.209
135.34,52.11,0.210
135.35,52.31,0.210
135.38,52.51,0.210
135.40,52.71,0.210
135.41,52.91,0.210
135.44,53.11,0.210
135.45,53.31,0.210
135.48,53.51,0.211
135.50,53.71,0.211
135.51,53.91,0.211
135.54,54.11,0.211
135.55,54.31,0.211
135.58,54.51,0.211
135.60,54.71,0.211
135.61,54.91,0.211
135.64,55.11,0.212
135.65,55.31,0.212
135.68,55.51,0.212
135.70,55.71,0.212
135.71,55.91,0.212
135.74,56.11,0.212
135.75,56.31,0.212
135.78,56.51,0.212
135.80,56.71,0.213
135.81,56.91,0.213
135.84,57.11,0.213
135.85,57.31,0.213
135.88,57.51,0.213
135.90,57.71,0.213
135.91,57.91,0.213
135.94,58.11,0.213
135.95,58.31,0.214
135.98,58.51,0.214
136.00,58.71,0.214
136.01,58.91,0.214
136.04,59.11,0.214
136.05,59.31,0.214
136.08,59.51,0.214
136.10,59.71,0.214
136.11,59.91,0.215
136.14,60.11,0.215
136.15,60.31,0.215
136.18,60.51,0.215
136.20,60.71,0.215
136.21,60.91,0.215
136.24,61.11,0.215
136.25,61.31,0.215
136.28,61.51,0.216
136.30,61.71,0.216
136.31,61.91,0.216
136.34,62.11,0.216
136.35,62.31,0.216
136.38,62.51,0.216
136.40,62.71,0.216
136.41,62.92,0.216
136.44,63.11,0.217
136.45,63.32,0.217
136.48,63.52,0.217
136.50,63.72,0.217
136.51,63.92,0.217
136.53,64.12,0.217
136.55,64.32,0.217
136.58,64.52,0.218
136.60,64.72,0.218
136.62,64.92,0.218
136.63,65.12,0.218
136.65,65.32,0.218
136.68,65.52,0.218
136.70,65.72,0.218
136.72,65.92,0.219
136.73,66.12,0.219
136.75,66.32,0.219
136.78,66.52,0.219
136.80,66.72,0.219
136.82,66.92,0.219
136.83,67.12,0.219
136.85,67.32,0.219
136.88,67.52,0.219
136.90,67.72,0.220
136.92,67.92,0.220
136.93,68.12,0.220
136.95,68.32,0.220
136.98,68.52,0.220
137.00,68.72,0.220
137.02,68.92,0.220
137.03,69.12,0.220
137.05,69.32,0.221
137.08,69.52,0.221
137.10,69.72,0.221
137.12,69.92,0.221
137.13,70.12,0.221
137.15,70.32,0.221
137.18,70.52,0.221
137.20,70.72,0.221
137.22,70.92,0.222
137.23,71.12,0.222
137.25,71.32,0.222
137.28,71.52,0.222
137.30,71.72,0.222
137.32,71.92,0.222
137.33,72.12,0.222
137.35,72.32,0.222
137.38,72.52,0.223
137.40,72.72,0.223
137.42,72.92,0.223
137.43,73.12,0.223
137.45,73.32,0.223
137.48,73.52,0.223
137.50,73.72,0.223
137.52,73.92,0.223
137.53,74.12,0.224
137.55,74.32,0.224
137.58,74.52,0.224
137.60,74.72,0.224
137.62,74.92,0.224
137.63,75.13,0.224
137.65,75.33,0.224
137.68,75.53,0.225
137.70,75.72,0.225
137.72,75.93,0.225
137.73,76.13,0.225
137.75,76.33,0.225
137.78,76.53,0.225
137.80,76.73,0.225
137.82,76.93,0.225
137.83,77.13,0.226
137.85,77.33,0.226
137.88,77.53,0.226
137.90,77.73,0.226
137.92,77.93,0.226
137.93,78.13,0.226
137.95,78.33,0.226
137.98,78.53,0.227
138.00,78.73,0.227
138.02,78.93,0.227
138.03,79.13,0.227
138.05,79.33,0.227
138.08,79.53,0.227
138.10,79.73,0.227
138.12,79.93,0.227
138.13,80.13,0.227
138.15,80.33,0.228
138.18,80.53,0.228
138.20,80.73,0.228
138.22,80.93,0.228
138.23,81.13,0.228
138.25,81.33,0.228
138.28,81.53,0.228
138.30,81.73,0.229
138.32,81.93,0.229
138.33,82.13,0.229
138.35,82.33,0.229
138.38,82.53,0.229
138.40,82.73,0.229
138.42,82.93,0.229
138.43,83.13,0.229
138.45,83.33,0.230
138.48,83.53,0.230
138.50,83.73,0.230
138.52,83.93,0.230
138.53,84.13,0.230
138.55,84.33,0.230
138.58,84.53,0.230
138.60,84.73,0.230
138.62,84.93,0.230
138.63,85.13,0.231
138.65,85.33,0.231
138.68,85.53,0.231
138.70,85.73,0.231
138.72,85.93,0.231
138.73,86.13,0.231
138.75,86.33,0.231
138.78,86.53,0.231
138.80,86.73,0.231
138.82,86.93,0.232
138.83,87.13,0.232
138.85,87.33,0.232
138.88,87.53,0.232
138.90,87.73,0.232
138.92,87.94,0.232
138.93,88.14,0.232
138.95,88.33,0.233
138.98,88.54,0.233
139.00,88.73,0.233
139.02,88.93,0.233
139.03,89.14,0.233
139.05,89.34,0.233
139.08,89.53,0.233
139.10,89.74,0.233
139.12,89.94,0.234
139.13,90.14,0.234
139.15,90.34,0.234
139.18,90.54,0.234
139.20,90.74,0.234
139.22,90.94,0.234
139.23,91.14,0.234
139.25,91.34,0.235
139.28,91.54,0.235
139.30,91.74,0.235
139.32,91.94,0.235
139.33,92.14,0.235
139.35,92.34,0.235
139.38,92.54,0.235
139.40,92.74,0.236
139.42,92.94,0.236
139.43,93.14,0.236
139.45,93.34,0.236
139.48,93.54,0.236
139.50,93.74,0.236
139.52,93.94,0.236
139.53,94.14,0.237
139.55,94.34,0.237
139.58,94.54,0.237
139.60,94.74,0.237
139.62,94.94,0.237
139.63,95.14,0.237
139.65,95.34,0.237
139.68,95.54,0.237
139.70,95.74,0.238
139.72,95.94,0.238
139.73,96.14,0.238
139.75,96.34,0.238
139.78,96.54,0.238
139.80,96.74,0.238
139.82,96.94,0.238
139.83,97.14,0.239
139.85,97.34,0.239
139.88,97.54,0.239
139.90,97.74,0.239
139.92,97.94,0.239
139.93,98.14,0.239
139.95,98.34,0.239
139.98,98.54,0.239
140.00,98.74,0.240
140.02,98.94,0.240
140.03,99.14,0.240
140.05,99.34,0.240
140.08,99.54,0.240
140.10,99.74,0.240
140.12,99.94,0.240
140.13,100.14,0.240
140.15,100.34,0.241
140.18,100.54,0.241
140.20,100.74,0.241
140.22,100.94,0.241
140.23,101.14,0.241
140.25,101.34,0.241
140.28,101.54,0.241
140.30,101.74,0.242
140.32,101.94,0.242
140.33,102.14,0.242
140.35,102.34,0.242
140.38,102.54,0.242
140.40,102.74,0.242
140.42,102.94,0.242
140.43,103.14,0.242
140.45,103.35,0.243
140.48,103.55,0.243
140.50,103.75,0.243
140.52,103.95,0.243
140.53,104.15,0.243
140.55,104.35,0.243
140.58,104.55,0.243
140.60,104.75,0.244
140.62,104.95,0.244
140.63,105.15,0.244
140.65,105.35,0.244
140.68,105.55,0.244
140.70,105.75,0.244
140.72,105.95,0.244
140.73,106.15,0.244
140.75,106.35,0.245
140.78,106.55,0.245
140.80,106.75,0.245
140.82,106.95,0.245
140.83,107.15,0.245
140.85,107.35,0.245
140.88,107.55,0.245
140.90,107.75,0.245
140.92,107.95,0.245
140.93,108.15,0.246
140.95,108.35,0.246
140.98,108.55,0.246
141.00,108.75,0.246
141.02,108.95,0.246
141.03,109.15,0.246
141.05,109.35,0.246
141.08,109.55,0.247
141.10,109.75,0.247
141.12,109.95,0.247
141.13,110.15,0.247
141.15,110.35,0.247
141.18,110.55,0.247
141.20,110.75,0.247
141.22,110.95,0.247
141.23,111.15,0.248
141.25,111.35,0.248
141.28,111.55,0.248
141.30,111.75,0.248
141.32,111.95,0.248
141.33,112.15,0.248
141.35,112.35,0.248
141.38,112.55,0.248
141.40,112.75,0.249
141.42,112.95,0.249
141.43,113.15,0.249
141.45,113.35,0.249
141.48,113.55,0.249
141.50,113.75,0.249
141.52,113.95,0.249
141.53,114.15,0.250
141.55,114.35,0.250
141.58,114.55,0.250
141.60,114.75,0.250
141.62,114.95,0.250
141.63,115.15,0.250
141.65,115.35,0.250
141.68,115.55,0.251
141.70,115.75,0.251
141.72,115.95,0.251
141.73,116.15,0.251
141.75,116.35,0.251
141.78,116.55,0.251
141.80,116.75,0.251
141.82,116.95,0.251
141.83,117.15,0.252
141.85,117.35,0.252
141.88,117.55,0.252
141.90,117.76,0.252
141.92,117.95,0.252
141.93,118.15,0.252
141.95,118.35,0.252
141.98,118.55,0.252
142.00,118.75,0.253
142.02,118.96,0.253
142.03,119.16,0.253
142.05,119.36,0.253
142.08,119.55,0.253
142.10,119.76,0.253
142.12,119.96,0.253
142.13,120.16,0.253
142.15,120.36,0.254
142.18,120.56,0.254
142.20,120.76,0.254
142.22,120.96,0.254
142.23,121.16,0.254
142.25,121.36,0.254
142.28,121.56,0.254
142.30,121.76,0.254
142.32,121.96,0.255
142.33,122.16,0.255
142.35,122.36,0.255
142.38,122.56,0.255
142.40,122.76,0.255
142.42,122.96,0.255
142.43,123.16,0.255
142.45,123.36,0.255
142.48,123.56,0.256
142.50,123.76,0.256
142.52,123.96,0.256
142.53,124.16,0.256
142.55,124.36,0.256
142.58,124.56,0.256
142.60,124.76,0.256
142.62,124.96,0.257
142.63,125.16,0.257
142.65,125.36,0.257
142.68,125.56,0.257
142.70,125.76,0.257
142.72,125.96,0.257
142.73,126.16,0.257
142.75,126.36,0.257
142.78,126.56,0.258
142.80,126.76,0.258
142.82,126.96,0.258
142.83,127.16,0.258
142.85,127.36,0.258
142.88,127.56,0.258
142.90,127.76,0.258
142.92,127.96,0.258
142.93,128.16,0.259
142.95,128.36,0.259
142.98,128.56,0.259
143.00,128.76,0.259
143.02,128.96,0.259
143.03,129.16,0.259
143.05,129.36,0.259
143.08,129.56,0.260
143.10,129.76,0.260
143.12,129.96,0.260
143.13,130.16,0.260
143.15,130.36,0.260
143.18,130.56,0.260
143.20,130.76,0.260
143.22,130.97,0.261
143.23,131.16,0.261
143.25,131.36,0.261
143.28,131.56,0.261
143.30,131.76,0.261
143.32,131.96,0.261
143.33,132.16,0.261
143.35,132.36,0.261
143.38,132.56,0.262
143.40,132.77,0.262
143.42,132.97,0.262
143.43,133.17,0.262
143.45,133.37,0.262
143.48,133.57,0.262
143.50,133.77,0.263
143.52,133.97,0.263
143.53,134.17,0.263
143.55,134.37,0.263
143.58,134.57,0.263
143.60,134.77,0.263
143.62,134.97,0.263
143.63,135.17,0.264
143.65,135.37,0.264
143.68,135.57,0.264
143.70,135.77,0.264
143.72,135.97,0.264
143.73,136.17,0.264
143.75,136.37,0.264
143.78,136.57,0.265
143.80,136.77,0.265
143.82,136.97,0.265
143.83,137.17,0.265
143.85,137.37,0.265
143.88,137.57,0.265
143.90,137.77,0.265
143.92,137.97,0.265
143.93,138.17,0.266
143.95,138.37,0.266
143.98,138.57,0.266
144.00,138.77,0.266
144.02,138.97,0.266
144.03,139.17,0.266
144.05,139.37,0.266
144.08,139.57,0.266
144.10,139.77,0.267
144.12,139.97,0.267
144.13,140.17,0.267
144.15,140.37,0.267
144.18,140.57,0.267
144.20,140.77,0.267
144.22,140.97,0.267
144.23,141.17,0.267
144.25,141.37,0.267
144.28,141.57,0.268
144.30,141.77,0.268
144.32,141.97,0.268
144.33,142.17,0.268
144.35,142.37,0.268
144.38,142.57,0.268
144.40,142.77,0.269
144.42,142.97,0.269
144.43,143.17,0.269
144.45,143.37,0.269
144.48,143.57,0.269
144.50,143.77,0.269
144.52,143.97,0.269
144.53,144.17,0.270
144.55,144.37,0.270
144.58,144.57,0.270
144.60,144.77,0.270
144.62,144.97,0.270
144.63,145.17,0.270
144.65,145.37,0.270
144.68,145.57,0.271
144.70,145.77,0.271
144.72,145.97,0.271
144.73,146.17,0.271
144.75,146.37,0.271
144.78,146.57,0.271
144.80,146.77,0.272
144.82,146.97,0.272
144.83,147.17,0.272
144.85,147.37,0.272
144.88,147.58,0.272
144.90,147.78,0.272
144.92,147.98,0.273
144.93,148.18,0.273
144.95,148.37,0.273
144.98,148.58,0.273
145.00,148.78,0.273
145.02,148.97,0.273
145.03,149.17,0.274
145.05,149.38,0.274
145.08,149.58,0.274
145.10,149.77,0.274
145.12,149.98,0.274
145.13,150.17,0.274
145.15,150.37,0.275
145.18,150.57,0.275
145.20,150.77,0.275
145.22,150.97,0.275
145.23,151.17,0.275
145.25,151.37,0.275
145.28,151.57,0.276
145.30,151.77,0.276
145.32,151.97,0.276
145.33,152.18,0.276
145.35,152.37,0.276
145.38,152.58,0.277
145.40,152.77,0.277
145.42,152.98,0.277
145.43,153.18,0.277
145.45,153.38,0.277
145.48,153.58,0.278
145.50,153.78,0.278
145.52,153.98,0.278
145.53,154.18,0.278
145.55,154.38,0.278
145.58,154.58,0.279
145.60,154.78,0.279
145.62,154.98,0.279
145.63,155.18,0.279
145.65,155.38,0.280
145.68,155.58,0.280
145.70,155.78,0.280
145.72,155.98,0.280
145.73,156.18,0.280
145.75,156.38,0.281
145.78,156.58,0.281
145.80,156.78,0.281
145.82,156.98,0.281
145.83,157.18,0.282
145.85,157.38,0.282
145.88,157.58,0.282
145.90,157.78,0.282
145.92,157.98,0.283
145.93,158.18,0.283
145.95,158.38,0.283
145.98,158.58,0.283
146.00,158.78,0.284
146.02,158.98,0.284
146.03,159.18,0.284
146.05,159.38,0.285
146.08,159.58,0.285
146.10,159.78,0.285
146.12,159.98,0.285
146.13,160.18,0.286
146.15,160.38,0.286
146.18,160.58,0.286
146.20,160.78,0.287
146.22,160.98,0.287
146.23,161.18,0.288
146.25,161.38,0.288
146.28,161.58,0.288
146.30,161.78,0.289
146.32,161.98,0.289
146.33,162.18,0.290
146.35,162.38,0.290
146.38,162.58,0.291
146.40,162.78,0.291
146.42,162.98,0.292
146.43,163.18,0.292
146.45,163.38,0.293
146.48,163.58,0.293
146.50,163.78,0.294
146.52,163.98,0.294
146.53,164.18,0.295
146.55,164.38,0.296
146.58,164.58,0.296
146.60,164.78,0.296
146.62,164.98,0.297
146.63,165.18,0.298
146.65,165.38,0.299
146.68,165.58,0.300
146.70,165.78,0.301
146.72,165.97,0.301
146.73,166.17,0.302
146.75,166.37,0.303
146.78,166.57,0.304
146.80,166.77,0.305
146.82,166.97,0.307
146.83,167.17,0.308
146.85,167.37,0.310
146.88,167.57,0.311
146.90,167.77,0.313
146.92,167.97,0.314
146.93,168.17,0.314
146.95,168.37,0.315
146.98,168.57,0.316
147.00,168.77,0.317
147.02,168.97,0.318
147.03,169.17,0.319
147.05,169.37,0.320
147.08,169.57,0.321
147.10,169.77,0.322
147.12,169.97,0.323
147.13,170.17,0.325
147.15,170.37,0.326
147.18,170.57,0.327
147.20,170.77,0.328
147.22,170.97,0.330
147.23,171.17,0.330
147.25,171.37,0.331
147.28,171.57,0.332
147.30,171.77,0.332
147.32,171.97,0.333
147.33,172.17,0.333
147.35,172.37,0.334
147.38,172.57,0.334
147.40,172.77,0.335
147.42,172.97,0.335
147.43,173.17,0.336
147.45,173.37,0.336
147.48,173.57,0.336
147.50,173.77,0.337
147.52,173.97,0.337
147.53,174.17,0.337
147.55,174.37,0.338
147.58,174.57,0.338
147.60,174.77,0.338
147.62,174.97,0.338
147.63,175.17,0.338
147.65,175.37,0.339
147.68,175.57,0.339
147.70,175.77,0.339
147.72,175.97,0.339
147.73,176.17,0.339
147.75,176.37,0.339
147.78,176.57,0.339
147.80,176.77,0.339
147.82,176.97,0.339
147.83,177.17,0.339
147.85,177.37,0.339
147.88,177.57,0.339
147.90,177.77,0.339
147.92,177.97,0.339
147.93,178.17,0.339
147.95,178.37,0.339
147.98,178.57,0.339
148.00,178.77,0.339
148.02,178.97,0.339
148.03,179.17,0.339
148.05,179.37,0.339
148.08,179.57,0.339
148.10,179.77,0.338
148.12,179.97,0.338
148.13,180.17,0.338
148.15,180.37,0.338
148.18,180.57,0.338
148.20,180.77,0.338
148.22,180.97,0.338
148.23,181.17,0.338
148.25,181.37,0.338
148.28,181.57,0.338
148.30,181.77,0.338
148.32,181.97,0.338
148.33,182.17,0.338
148.35,182.37,0.338
148.38,182.57,0.338
148.40,182.77,0.338
148.42,182.97,0.338
148.43,183.17,0.338
148.45,183.37,0.338
148.48,183.57,0.338
148.50,183.78,0.338
148.52,183.98,0.338
148.53,184.18,0.338
148.55,184.38,0.338
148.58,184.57,0.338
148.60,184.77,0.338
148.62,184.97,0.338
148.63,185.17,0.338
148.65,185.38,0.338
148.68,185.58,0.338
148.70,185.78,0.338
148.72,185.98,0.338
148.73,186.18,0.338
148.75,186.38,0.338
148.78,186.58,0.338
148.80,186.78,0.338
148.82,186.98,0.338
148.83,187.18,0.338
148.85,187.38,0.338
148.88,187.58,0.339
148.90,187.78,0.339
148.92,187.98,0.339
148.93,188.18,0.339
148.95,188.38,0.339
148.98,188.58,0.339
149.00,188.78,0.339
149.02,188.98,0.339
149.03,189.18,0.339
149.05,189.38,0.339
149.08,189.58,0.339
149.10,189.78,0.339
149.12,189.98,0.339
149.13,190.18,0.339
149.15,190.38,0.339
149.18,190.58,0.340
149.20,190.78,0.340
149.22,190.98,0.340
149.23,191.18,0.340
149.25,191.38,0.340
149.28,191.58,0.340
149.30,191.78,0.340
149.32,191.98,0.340
149.33,192.18,0.340
149.35,192.38,0.340
149.38,192.58,0.340
149.40,192.78,0.341
149.42,192.98,0.341
149.43,193.18,0.341
149.45,193.38,0.341
149.48,193.58,0.341
149.50,193.78,0.341
149.52,193.98,0.341
149.53,194.18,0.341
149.55,194.38,0.341
149.58,194.58,0.342
149.60,194.78,0.342
149.62,194.98,0.342
149.63,195.18,0.342
149.65,195.38,0.342
149.68,195.58,0.342
149.70,195.78,0.342
149.72,195.98,0.342
149.73,196.18,0.342
149.75,196.38,0.343
149.78,196.58,0.343
149.80,196.78,0.343
149.82,196.98,0.343
149.83,197.18,0.343
149.85,197.38,0.343
149.88,197.58,0.343
149.90,197.78,0.343
149.92,197.98,0.343
149.93,198.18,0.343
149.95,198.38,0.344
149.98,198.58,0.344
150.00,198.79,0.344
150.02,198.99,0.344
150.03,199.19,0.344
150.05,199.39,0.344
150.08,199.59,0.344
150.10,199.79,0.344
150.12,199.99,0.344
150.13,200.19,0.344
150.15,200.39,0.345
150.18,200.59,0.345
150.20,200.79,0.345
150.22,200.99,0.345
150.23,201.19,0.345
150.25,201.39,0.345
150.28,201.59,0.345
150.30,201.79,0.345
150.32,201.99,0.345
150.33,202.19,0.345
150.35,202.39,0.346
150.38,202.59,0.346
150.40,202.79,0.346
150.42,202.99,0.346
150.43,203.19,0.346
150.45,203.39,0.346
150.48,203.59,0.346
150.50,203.79,0.346
150.52,203.99,0.346
150.53,204.19,0.346
150.55,204.39,0.346
150.58,204.59,0.347
150.60,204.79,0.347
150.62,204.99,0.347
150.63,205.19,0.347
150.65,205.39,0.347
150.68,205.59,0.347
150.70,205.79,0.347
150.72,205.99,0.347
150.73,206.19,0.347
150.75,206.39,0.347
150.78,206.59,0.348
150.80,206.79,0.348
150.82,206.99,0.348
150.83,207.19,0.348
150.85,207.39,0.348
150.88,207.59,0.348
150.90,207.79,0.348
150.92,207.99,0.348
150.93,208.19,0.348
150.95,208.39,0.348
150.98,208.59,0.349
151.00,208.79,0.349
151.02,208.99,0.349
151.03,209.19,0.349
151.05,209.39,0.349
151.08,209.59,0.349
151.10,209.79,0.349
151.12,209.99,0.349
151.13,210.19,0.349
151.15,210.39,0.350
151.18,210.59,0.350
151.20,210.79,0.350
151.22,210.99,0.350
151.23,211.19,0.350
151.25,211.39,0.350
151.28,211.59,0.350
151.30,211.79,0.350
151.32,211.99,0.350
151.33,212.19,0.351
151.35,212.39,0.351
151.38,212.59,0.351
151.40,212.79,0.351
151.42,212.99,0.351
151.43,213.19,0.351
151.45,213.39,0.351
151.48,213.59,0.351
151.50,213.79,0.351
151.52,213.99,0.351
151.53,214.19,0.351
151.55,214.39,0.352
151.58,214.59,0.352
151.60,214.79,0.352
151.62,214.99,0.352
151.63,215.20,0.352
151.65,215.39,0.352
151.68,215.59,0.352
151.70,215.80,0.352
151.72,215.99,0.352
151.73,216.19,0.353
151.75,216.39,0.353
151.78,216.59,0.353
151.80,216.79,0.353
151.82,217.00,0.353
151.83,217.20,0.353
151.85,217.40,0.353
151.88,217.59,0.353
151.90,217.79,0.353
151.92,218.00,0.353
151.93,218.19,0.354
151.95,218.39,0.354
151.98,218.59,0.354
152.00,218.80,0.354
152.02,218.99,0.354
152.03,219.20,0.354
152.05,219.40,0.354
152.08,219.60,0.354
152.10,219.80,0.354
152.12,220.00,0.355
152.13,220.20,0.355
152.15,220.40,0.355
152.18,220.60,0.355
152.20,220.80,0.355
152.22,221.00,0.355
152.23,221.20,0.355
152.25,221.40,0.356
152.28,221.60,0.356
152.30,221.80,0.356
152.32,222.00,0.356
152.33,222.20,0.356
152.35,222.40,0.356
152.38,222.60,0.356
152.40,222.80,0.356
152.42,223.00,0.356
152.43,223.20,0.356
152.45,223.40,0.356
152.48,223.60,0.357
152.50,223.80,0.357
152.52,224.00,0.357
152.53,224.20,0.357
152.55,224.40,0.357
152.58,224.60,0.357
152.60,224.80,0.357
152.62,225.00,0.357
152.63,225.20,0.358
152.65,225.40,0.358
152.68,225.60,0.358
152.70,225.80,0.358
152.72,226.00,0.358
152.73,226.20,0.358
152.75,226.40,0.358
152.78,226.60,0.358
152.80,226.80,0.358
152.82,227.00,0.359
152.83,227.20,0.359
152.85,227.40,0.359
152.88,227.60,0.359
152.90,227.80,0.359
152.92,228.00,0.359
152.93,228.20,0.359
152.95,228.40,
152.98,228.60,
152.99,,