File: DSC/Olivia/2025_08_09_Sapphire_TS_n60C_250C_10Cmin_x3.csv
Filename,2025_08_09_Sapphire_TS_n60C_250C_10Cmin_x3
Instrument name,DSC2A-00468 (192.168.1.100)
Operator,Yarger
rundate,8/10/2025
Sample name,2025_08_09_Sapphire_TS_n60C_250C_10Cmin_x3
proceduresegments,Data Off ; Equilibrate -60.00 °C; Data On ; Ramp 10.00 °C/min to 250.00 °C; Data Off ; Isothermal 2.0 min; Data On ; Ramp 10.00 °C/min to -60.00 °C; Data Off ; Isothermal 2.0 min; Data On ; Ramp 10.00 °C/min to 250.00 °C; Data Off ; Isothermal 2.0 min; Data On ; Ramp 10.00 °C/min to -60.00 °C; Data Off ; Isothermal 2.0 min; Data On ; Ramp 10.00 °C/min to 250.00 °C
[File Parameters]
Run date,8/10/2025 8:03:08 AM
Trios version,5.1.1.46572
Original File Name,
Current File Name,D:\DSC2500\JYarger\2025_08_09_Sapphire_TS_n60C_250C_10Cmin_x3.tri
[Procedure]
Procedure Name,Sapphire_TS_n60C_250C_10Cmin_x3
Sample Name,2025_08_09_Sapphire_TS_n60C_250C_10Cmin_x3
Sample Mass,32.9 mg
Reference Sample Mass,0 mg
Pan Mass,5.38 mg
Pan Number,6
Reference Pan Mass,32.42 mg
Reference Pan Number,10
Pan Type,Aluminum
Comments,Thermal support Al pans/lids. DSC_Samples_A2_Tray_August2025 google sheet.
Project Name,Pharma
Operator,Yarger
Test,Custom
Unload Max Temperature,30
Unload Min Temperature,30
Load Max Temperature,30
Load Min Temperature,30
Stop on Gas Flow Error,Yes
[Signal List]
Signal #1,Time (min)
Signal #2,Temperature (°C)
Signal #3,Heat Flow (mW)
Signal #4,Delta T (µV)
Signal #5,Delta Tzero (µV)
Signal #6,Tzero Temperature (°C)
Signal #7,Cell Purge (mL/min)
Signal #8,Heater Temp (°C)
Signal #9,Power Delivered (W)
Signal #10,Reference Junction Temperature (°C)
Signal #11,Flange Temperature (°C)
Signal #12,Heat Flow Phase (rad)
Signal #13,Total Heat Capacity (J/°C)
Signal #14,Heat Capacity (J/°C)
[Configuration]
Company Name,ASU
Instrument Name,DSC2A-00468
Instrument Type,DSC2500
Serial Number,DSC2A-00468
IP,192.168.1.100
Location of Instrument,MRRC
DisplayType,Unknown
Sample Interval ,0.1 s/pt
Selected Heat Flow,T4P
Exotherm Direction,Down
Cell Serial,DRC2-00792
Lid Type,Standard
Cooler,RCS 90
Leave Cooler on at End of Sequence,On
Gas 2,Nitrogen
Gas Selected,Channel 1
Flow Rate,50 mL/min
Secondary Purge,On
Licensed Heat Flow,Heat Flow T4P
Modulation Licensed,Yes
[Versions]
Common IDD Version,1
Cortex Version,VER 2.10.2.31
Driver,5.0.0.6
GDM Version,1.0.3.3
TouchscreenVersion,1.0.0.16145
FEP Version,1.2.1.21
FEP Bootloader,2.0.0.5
AutoSampler Version,2.1.1.26
Auto Sampler Bootloader,2.0.0.5
FCM Version,1.1.0.3
FCM Bootloader,2.0.0.5
[Experiment Logs]
Experiment Log Entry # 1,Data On set to 0
Experiment Log Entry # 3,Equilibrate Segment -60 (C) Started
Experiment Log Entry # 5,Air Cool is off.
Experiment Log Entry # 7,Data On set to 1
Experiment Log Entry # 9,Ramp Segment 10 C/min to 250 Started
Experiment Log Entry # 11,Data On set to 0
Experiment Log Entry # 13,Isothermal Segment 2 min started
Experiment Log Entry # 15,Data On set to 1
Experiment Log Entry # 17,Ramp Segment 10 C/min to -60 Started
Experiment Log Entry # 19,Data On set to 0
Experiment Log Entry # 21,Isothermal Segment 2 min started
Experiment Log Entry # 23,Data On set to 1
Experiment Log Entry # 25,Ramp Segment 10 C/min to 250 Started
Experiment Log Entry # 27,Data On set to 0
Experiment Log Entry # 29,Isothermal Segment 2 min started
Experiment Log Entry # 31,Data On set to 1
Experiment Log Entry # 33,Ramp Segment 10 C/min to -60 Started
Experiment Log Entry # 35,Data On set to 0
Experiment Log Entry # 37,Isothermal Segment 2 min started
Experiment Log Entry # 39,Data On set to 1
Experiment Log Entry # 41,Ramp Segment 10 C/min to 250 Started
[Method Log]
Method Log Entry # 1,Data Off
Method Log Entry # 2,Equilibrate -60 °C
Method Log Entry # 3,Data On
Method Log Entry # 4,(Ramp 895412) Ramp 10 °C/minute to 250 °C
Method Log Entry # 5,Data Off
Method Log Entry # 6,Isothermal 2 minutes
Method Log Entry # 7,Data On
Method Log Entry # 8,(Ramp 895416) Ramp 10 °C/minute to -60 °C
Method Log Entry # 9,Data Off
Method Log Entry # 10,Isothermal 2 minutes
Method Log Entry # 11,Data On
Method Log Entry # 12,(Ramp 895420) Ramp 10 °C/minute to 250 °C
Method Log Entry # 13,Data Off
Method Log Entry # 14,Isothermal 2 minutes
Method Log Entry # 15,Data On
Method Log Entry # 16,(Ramp 895424) Ramp 10 °C/minute to -60 °C
Method Log Entry # 17,Data Off
Method Log Entry # 18,Isothermal 2 minutes
Method Log Entry # 19,Data On
Method Log Entry # 20,(Ramp 895428) Ramp 10 °C/minute to 250 °C
Cell Serial,DRC2-00792
[T1 Calibration]
Slope,-0.008529666
Offset,9.636258
Initial Temperature,98.23
GUID,f8bfdadc-4977-4fdf-ba6d-0ba9134940c3
[TZero Calibration]
Date Applied,11/29/2022 4:06:13 PM
Description,From -89.059 °C to 396.009 °C at 20.000°C/min
Gas Type,Nitrogen
Pan Type,None
Source Files 1,C:\Users\yargerlab\Desktop\DSC Data\General\TZero_calibration_11_29_22_2nd(2).tri
Source Files 2,C:\Users\yargerlab\Desktop\DSC Data\General\TZero_calibration_11_29_22_2nd(3).tri
Delta T Offset,13.05235
Delta T Slope,-0.007271007
Delta T0 Offset,-13.69128
Delta T0 Slope,0.06063341
[Temperature Calibration]
Date Applied,11/29/2022 7:12:28 PM
Description,From 106.590 °C to 186.590 °C at 10.000°C/min
Gas Type,Nitrogen
Pan Type,Tzero Aluminum Hermetic
Source Files 1,C:\Users\yargerlab\Desktop\DSC Data\General\Indium(6).tri
Measured 1,157.391
Known 1,156.598
[Cell Constant Calibration]
Date Applied,11/29/2022 7:12:29 PM
Description,From 106.590 °C to 186.590 °C at 10.000°C/min
Gas Type,Nitrogen
Pan Type,Tzero Aluminum Hermetic
Source Files 1,C:\Users\yargerlab\Desktop\DSC Data\General\Indium(6).tri
T4P KCell,1.006051
Onset Slope,63.26126 mW/°C
[Direct Cp Calibration]
Date Applied,11/30/2022 11:04:51 AM
Description,From -79.983 °C to 298.409 °C at 10.000°C/min
Gas Type,Nitrogen
Pan Type,Tzero Aluminum Hermetic
Source Files 1,C:\Users\yargerlab\Desktop\DSC Data\General\Sapphire_Heat_Capacity_11_30_22.tri
[Rev Cp Calibration]
Date Applied,11/30/2022 1:58:51 PM
Description,From -79.996 °C to 292.812 °C at 3.000°C/min
Gas Type,Nitrogen
Pan Type,Tzero Aluminum Hermetic
Source Files 1,C:\Users\yargerlab\Desktop\DSC Data\General\Sapphire_MDSC_Calibration_11_30_22.tri
[step]
Ramp 10.00 °C/min to 250.00 °C
Time,Temperature,Heat Flow (Normalized)
min,°C,W/g
0.00,-59.81,-0.006
0.02,-59.81,-0.006
0.04,-59.81,-0.006
0.07,-59.79,-0.006
0.09,-59.73,-0.010
0.11,-59.64,-0.011
0.13,-59.52,-0.011
0.15,-59.37,-0.010
0.17,-59.20,-0.006
0.19,-59.02,-0.002
0.22,-58.82,0.002
0.24,-58.63,0.005
0.26,-58.43,0.008
0.28,-58.22,0.010
0.30,-58.01,0.011
0.33,-57.81,0.013
0.35,-57.60,0.013
0.37,-57.39,0.014
0.39,-57.18,0.014
0.41,-56.97,0.015
0.43,-56.76,0.015
0.45,-56.55,0.015
0.48,-56.33,0.015
0.50,-56.12,0.015
0.52,-55.91,0.016
0.54,-55.70,0.016
0.56,-55.48,0.016
0.58,-55.27,0.016
0.61,-55.06,0.016
0.63,-54.84,0.016
0.65,-54.63,0.016
0.67,-54.41,0.016
0.69,-54.20,0.016
0.72,-53.99,0.016
0.74,-53.77,0.016
0.76,-53.56,0.016
0.78,-53.34,0.016
0.80,-53.13,0.016
0.82,-52.91,0.017
0.85,-52.70,0.017
0.87,-52.48,0.017
0.89,-52.27,0.017
0.91,-52.05,0.017
0.93,-51.84,0.017
0.95,-51.62,0.017
0.98,-51.41,0.017
1.00,-51.19,0.017
1.02,-50.98,0.017
1.04,-50.76,0.017
1.06,-50.54,0.017
1.08,-50.33,0.017
1.11,-50.11,0.017
1.13,-49.89,0.017
1.15,-49.68,0.017
1.17,-49.46,0.017
1.19,-49.25,0.017
1.21,-49.03,0.017
1.23,-48.81,0.017
1.26,-48.60,0.017
1.28,-48.38,0.017
1.30,-48.17,0.017
1.32,-47.95,0.017
1.34,-47.73,0.017
1.37,-47.52,0.017
1.39,-47.30,0.017
1.41,-47.09,0.017
1.43,-46.87,0.017
1.45,-46.65,0.017
1.47,-46.43,0.017
1.49,-46.22,0.017
1.52,-46.00,0.017
1.54,-45.79,0.017
1.56,-45.57,0.017
1.58,-45.35,0.017
1.60,-45.13,0.017
1.63,-44.92,0.017
1.65,-44.70,0.017
1.67,-44.48,0.017
1.69,-44.27,0.017
1.71,-44.05,0.017
1.73,-43.83,0.017
1.76,-43.62,0.017
1.78,-43.40,0.018
1.80,-43.18,0.018
1.82,-42.97,0.018
1.84,-42.75,0.018
1.86,-42.53,0.018
1.88,-42.31,0.018
1.91,-42.10,0.018
1.93,-41.88,0.018
1.95,-41.67,0.018
1.97,-41.45,0.018
1.99,-41.23,0.018
2.02,-41.02,0.018
2.04,-40.80,0.018
2.06,-40.58,0.018
2.08,-40.36,0.018
2.10,-40.15,0.018
2.12,-39.93,0.018
2.14,-39.71,0.018
2.17,-39.50,0.018
2.19,-39.28,0.018
2.21,-39.06,0.018
2.23,-38.85,0.018
2.25,-38.63,0.018
2.28,-38.41,0.018
2.30,-38.20,0.018
2.32,-37.98,0.018
2.34,-37.76,0.018
2.36,-37.54,0.018
2.38,-37.33,0.018
2.41,-37.11,0.018
2.43,-36.89,0.018
2.45,-36.68,0.018
2.47,-36.46,0.018
2.49,-36.24,0.018
2.51,-36.02,0.018
2.54,-35.81,0.018
2.56,-35.59,0.018
2.58,-35.37,0.018
2.60,-35.16,0.018
2.62,-34.94,0.018
2.64,-34.72,0.018
2.66,-34.51,0.018
2.69,-34.29,0.018
2.71,-34.07,0.018
2.73,-33.85,0.018
2.75,-33.64,0.018
2.77,-33.42,0.018
2.79,-33.20,0.018
2.82,-32.99,0.018
2.84,-32.77,0.018
2.86,-32.55,0.018
2.88,-32.34,0.018
2.90,-32.12,0.018
2.93,-31.90,0.018
2.95,-31.69,0.018
2.97,-31.47,0.018
2.99,-31.25,0.018
3.01,-31.03,0.018
3.03,-30.82,0.018
3.06,-30.60,0.018
3.08,-30.38,0.018
3.10,-30.17,0.018
3.12,-29.95,0.018
3.14,-29.73,0.018
3.16,-29.52,0.018
3.19,-29.30,0.018
3.21,-29.08,0.018
3.23,-28.87,0.018
3.25,-28.65,0.018
3.27,-28.43,0.018
3.29,-28.21,0.018
3.31,-28.00,0.018
3.34,-27.78,0.018
3.36,-27.56,0.018
3.38,-27.35,0.018
3.40,-27.13,0.018
3.42,-26.91,0.018
3.44,-26.70,0.018
3.47,-26.48,0.018
3.49,-26.26,0.018
3.51,-26.05,0.018
3.53,-25.83,0.018
3.55,-25.61,0.018
3.58,-25.39,0.018
3.60,-25.18,0.018
3.62,-24.96,0.018
3.64,-24.74,0.018
3.66,-24.53,0.018
3.68,-24.31,0.018
3.71,-24.09,0.018
3.73,-23.88,0.018
3.75,-23.66,0.018
3.77,-23.44,0.018
3.79,-23.22,0.018
3.81,-23.01,0.018
3.84,-22.79,0.018
3.86,-22.57,0.018
3.88,-22.36,0.018
3.90,-22.14,0.018
3.92,-21.92,0.018
3.94,-21.71,0.018
3.96,-21.49,0.018
3.99,-21.27,0.018
4.01,-21.05,0.018
4.03,-20.84,0.018
4.05,-20.62,0.018
4.07,-20.40,0.018
4.09,-20.19,0.018
4.12,-19.97,0.018
4.14,-19.75,0.018
4.16,-19.54,0.018
4.18,-19.32,0.018
4.20,-19.10,0.018
4.23,-18.89,0.018
4.25,-18.67,0.018
4.27,-18.45,0.018
4.29,-18.23,0.018
4.31,-18.02,0.018
4.33,-17.80,0.018
4.35,-17.59,0.018
4.38,-17.37,0.018
4.40,-17.15,0.018
4.42,-16.93,0.018
4.44,-16.72,0.018
4.46,-16.50,0.018
4.49,-16.28,0.018
4.51,-16.07,0.018
4.53,-15.85,0.018
4.55,-15.63,0.018
4.57,-15.42,0.018
4.59,-15.20,0.018
4.61,-14.98,0.018
4.64,-14.77,0.018
4.66,-14.55,0.018
4.68,-14.33,0.018
4.70,-14.11,0.018
4.72,-13.90,0.018
4.75,-13.68,0.018
4.77,-13.46,0.018
4.79,-13.25,0.018
4.81,-13.03,0.018
4.83,-12.81,0.018
4.85,-12.60,0.018
4.88,-12.38,0.018
4.90,-12.16,0.018
4.92,-11.95,0.018
4.94,-11.73,0.018
4.96,-11.51,0.018
4.98,-11.30,0.018
5.00,-11.08,0.018
5.03,-10.86,0.018
5.05,-10.64,0.018
5.07,-10.43,0.018
5.09,-10.21,0.018
5.11,-9.99,0.018
5.14,-9.78,0.018
5.16,-9.56,0.018
5.18,-9.34,0.018
5.20,-9.12,0.018
5.22,-8.91,0.018
5.24,-8.69,0.018
5.26,-8.47,0.018
5.29,-8.26,0.018
5.31,-8.04,0.018
5.33,-7.82,0.018
5.35,-7.61,0.018
5.37,-7.39,0.018
5.40,-7.17,0.018
5.42,-6.96,0.018
5.44,-6.74,0.018
5.46,-6.52,0.018
5.48,-6.30,0.018
5.50,-6.09,0.018
5.53,-5.87,0.018
5.55,-5.65,0.018
5.57,-5.44,0.018
5.59,-5.22,0.018
5.61,-5.01,0.018
5.63,-4.79,0.018
5.65,-4.57,0.018
5.68,-4.35,0.018
5.70,-4.14,0.018
5.72,-3.92,0.018
5.74,-3.70,0.018
5.76,-3.49,0.018
5.79,-3.27,0.018
5.81,-3.05,0.018
5.83,-2.83,0.018
5.85,-2.62,0.018
5.87,-2.40,0.018
5.89,-2.18,0.018
5.91,-1.97,0.018
5.94,-1.75,0.018
5.96,-1.53,0.018
5.98,-1.32,0.018
6.00,-1.10,0.018
6.02,-0.88,0.018
6.05,-0.66,0.018
6.07,-0.45,0.018
6.09,-0.23,0.018
6.11,-0.01,0.018
6.13,0.20,0.018
6.15,0.42,0.018
6.18,0.64,0.018
6.20,0.85,0.018
6.22,1.07,0.018
6.24,1.29,0.018
6.26,1.50,0.018
6.28,1.72,0.018
6.30,1.94,0.018
6.33,2.16,0.018
6.35,2.37,0.018
6.37,2.59,0.018
6.39,2.81,0.018
6.41,3.02,0.018
6.44,3.24,0.018
6.46,3.46,0.018
6.48,3.67,0.019
6.50,3.89,0.019
6.52,4.11,0.019
6.54,4.32,0.019
6.56,4.54,0.019
6.59,4.76,0.019
6.61,4.98,0.019
6.63,5.19,0.019
6.65,5.41,0.019
6.67,5.63,0.019
6.70,5.84,0.019
6.72,6.06,0.019
6.74,6.28,0.019
6.76,6.49,0.019
6.78,6.71,0.019
6.80,6.93,0.019
6.83,7.14,0.019
6.85,7.36,0.019
6.87,7.58,0.019
6.89,7.79,0.019
6.91,8.01,0.019
6.93,8.23,0.019
6.95,8.44,0.019
6.98,8.66,0.019
7.00,8.88,0.019
7.02,9.10,0.019
7.04,9.31,0.019
7.06,9.53,0.019
7.09,9.75,0.019
7.11,9.96,0.019
7.13,10.18,0.019
7.15,10.40,0.019
7.17,10.61,0.019
7.19,10.83,0.019
7.21,11.05,0.019
7.24,11.27,0.019
7.26,11.48,0.019
7.28,11.70,0.019
7.30,11.92,0.019
7.32,12.13,0.019
7.35,12.35,0.019
7.37,12.57,0.019
7.39,12.78,0.019
7.41,13.00,0.019
7.43,13.22,0.019
7.45,13.43,0.019
7.48,13.65,0.019
7.50,13.87,0.019
7.52,14.08,0.019
7.54,14.30,0.019
7.56,14.52,0.019
7.58,14.73,0.019
7.60,14.95,0.019
7.63,15.17,0.019
7.65,15.39,0.019
7.67,15.60,0.019
7.69,15.82,0.019
7.71,16.04,0.019
7.74,16.25,0.019
7.76,16.47,0.019
7.78,16.69,0.019
7.80,16.90,0.019
7.82,17.12,0.019
7.84,17.34,0.019
7.86,17.55,0.019
7.89,17.77,0.019
7.91,17.99,0.019
7.93,18.21,0.019
7.95,18.42,0.019
7.97,18.64,0.019
8.00,18.86,0.019
8.02,19.07,0.019
8.04,19.29,0.019
8.06,19.51,0.019
8.08,19.72,0.019
8.10,19.94,0.019
8.13,20.16,0.019
8.15,20.37,0.019
8.17,20.59,0.019
8.19,20.81,0.019
8.21,21.03,0.019
8.23,21.24,0.019
8.25,21.46,0.019
8.28,21.67,0.019
8.30,21.89,0.019
8.32,22.11,0.019
8.34,22.33,0.019
8.36,22.54,0.019
8.39,22.76,0.019
8.41,22.97,0.019
8.43,23.19,0.019
8.45,23.41,0.019
8.47,23.63,0.019
8.49,23.85,0.019
8.51,24.06,0.019
8.54,24.28,0.019
8.56,24.50,0.019
8.58,24.71,0.019
8.60,24.93,0.019
8.62,25.15,0.019
8.65,25.36,0.019
8.67,25.58,0.019
8.69,25.80,0.019
8.71,26.01,0.019
8.73,26.23,0.019
8.75,26.45,0.019
8.78,26.66,0.019
8.80,26.88,0.019
8.82,27.10,0.019
8.84,27.32,0.019
8.86,27.53,0.019
8.88,27.75,0.019
8.90,27.97,0.019
8.93,28.18,0.019
8.95,28.40,0.019
8.97,28.62,0.020
8.99,28.83,0.020
9.01,29.05,0.020
9.03,29.27,0.020
9.06,29.48,0.020
9.08,29.70,0.020
9.10,29.92,0.020
9.12,30.13,0.020
9.14,30.35,0.020
9.17,30.57,0.020
9.19,30.79,0.020
9.21,31.00,0.020
9.23,31.22,0.020
9.25,31.44,0.020
9.27,31.65,0.020
9.30,31.87,0.020
9.32,32.09,0.020
9.34,32.30,0.020
9.36,32.52,0.020
9.38,32.74,0.020
9.40,32.95,0.020
9.43,33.17,0.020
9.45,33.39,0.020
9.47,33.60,0.020
9.49,33.82,0.020
9.51,34.04,0.020
9.53,34.26,0.020
9.55,34.47,0.020
9.58,34.69,0.020
9.60,34.91,0.020
9.62,35.12,0.020
9.64,35.34,0.020
9.66,35.56,0.020
9.68,35.77,0.020
9.71,35.99,0.020
9.73,36.21,0.020
9.75,36.42,0.020
9.77,36.64,0.020
9.79,36.86,0.020
9.82,37.08,0.020
9.84,37.29,0.020
9.86,37.51,0.020
9.88,37.72,0.020
9.90,37.94,0.020
9.92,38.16,0.020
9.95,38.38,0.020
9.97,38.59,0.020
9.99,38.81,0.020
10.01,39.03,0.020
10.03,39.24,0.020
10.05,39.46,0.020
10.08,39.68,0.020
10.10,39.89,0.020
10.12,40.11,0.020
10.14,40.33,0.020
10.16,40.55,0.020
10.18,40.76,0.020
10.20,40.98,0.020
10.23,41.20,0.020
10.25,41.41,0.020
10.27,41.63,0.020
10.29,41.85,0.020
10.31,42.06,0.020
10.33,42.28,0.020
10.36,42.50,0.020
10.38,42.71,0.020
10.40,42.93,0.020
10.42,43.15,0.020
10.44,43.37,0.020
10.47,43.58,0.020
10.49,43.80,0.020
10.51,44.02,0.020
10.53,44.23,0.020
10.55,44.45,0.020
10.57,44.67,0.020
10.60,44.88,0.020
10.62,45.10,0.020
10.64,45.32,0.020
10.66,45.53,0.020
10.68,45.75,0.020
10.70,45.97,0.020
10.73,46.18,0.020
10.75,46.40,0.020
10.77,46.62,0.020
10.79,46.83,0.020
10.81,47.05,0.020
10.83,47.27,0.020
10.85,47.49,0.020
10.88,47.70,0.020
10.90,47.92,0.020
10.92,48.14,0.020
10.94,48.35,0.020
10.96,48.57,0.020
10.98,48.79,0.020
11.01,49.00,0.020
11.03,49.22,0.020
11.05,49.44,0.020
11.07,49.65,0.020
11.09,49.87,0.020
11.12,50.09,0.020
11.14,50.31,0.020
11.16,50.52,0.020
11.18,50.74,0.020
11.20,50.96,0.020
11.22,51.17,0.020
11.25,51.39,0.020
11.27,51.61,0.020
11.29,51.82,0.020
11.31,52.04,0.020
11.33,52.26,0.020
11.35,52.47,0.020
11.38,52.69,0.020
11.40,52.91,0.020
11.42,53.13,0.020
11.44,53.34,0.020
11.46,53.56,0.020
11.48,53.78,0.020
11.50,53.99,0.020
11.53,54.21,0.020
11.55,54.43,0.020
11.57,54.64,0.020
11.59,54.86,0.020
11.61,55.08,0.020
11.63,55.29,0.020
11.66,55.51,0.020
11.68,55.73,0.020
11.70,55.94,0.020
11.72,56.16,0.021
11.74,56.38,0.021
11.77,56.59,0.021
11.79,56.81,0.021
11.81,57.03,0.021
11.83,57.24,0.021
11.85,57.46,0.021
11.87,57.68,0.021
11.90,57.90,0.021
11.92,58.11,0.021
11.94,58.33,0.021
11.96,58.55,0.021
11.98,58.76,0.021
12.00,58.98,0.021
12.03,59.20,0.021
12.05,59.42,0.021
12.07,59.63,0.021
12.09,59.85,0.021
12.11,60.07,0.021
12.13,60.28,0.021
12.15,60.50,0.021
12.18,60.72,0.021
12.20,60.93,0.021
12.22,61.15,0.021
12.24,61.37,0.021
12.26,61.58,0.021
12.28,61.80,0.021
12.31,62.02,0.021
12.33,62.23,0.021
12.35,62.45,0.021
12.37,62.67,0.021
12.39,62.89,0.021
12.42,63.10,0.021
12.44,63.32,0.021
12.46,63.54,0.021
12.48,63.75,0.021
12.50,63.97,0.021
12.52,64.19,0.021
12.55,64.40,0.021
12.57,64.62,0.021
12.59,64.84,0.021
12.61,65.05,0.021
12.63,65.27,0.021
12.65,65.49,0.021
12.68,65.71,0.021
12.70,65.92,0.021
12.72,66.14,0.021
12.74,66.36,0.021
12.76,66.57,0.021
12.78,66.79,0.021
12.80,67.01,0.021
12.83,67.22,0.021
12.85,67.44,0.021
12.87,67.66,0.021
12.89,67.87,0.021
12.91,68.09,0.021
12.93,68.31,0.021
12.96,68.52,0.021
12.98,68.74,0.021
13.00,68.96,0.021
13.02,69.17,0.021
13.04,69.39,0.021
13.07,69.61,0.021
13.09,69.82,0.021
13.11,70.04,0.021
13.13,70.26,0.021
13.15,70.48,0.021
13.17,70.69,0.021
13.20,70.91,0.021
13.22,71.13,0.021
13.24,71.34,0.021
13.26,71.56,0.021
13.28,71.78,0.021
13.30,71.99,0.021
13.33,72.21,0.021
13.35,72.43,0.021
13.37,72.64,0.021
13.39,72.86,0.021
13.41,73.08,0.021
13.43,73.29,0.021
13.45,73.51,0.021
13.48,73.73,0.021
13.50,73.94,0.021
13.52,74.16,0.021
13.54,74.38,0.021
13.56,74.59,0.021
13.58,74.81,0.021
13.61,75.03,0.021
13.63,75.24,0.021
13.65,75.46,0.021
13.67,75.68,0.021
13.69,75.89,0.021
13.72,76.11,0.021
13.74,76.33,0.021
13.76,76.54,0.021
13.78,76.76,0.021
13.80,76.98,0.021
13.82,77.20,0.021
13.85,77.41,0.021
13.87,77.63,0.021
13.89,77.85,0.021
13.91,78.06,0.021
13.93,78.28,0.021
13.95,78.50,0.021
13.98,78.71,0.021
14.00,78.93,0.021
14.02,79.15,0.021
14.04,79.36,0.021
14.06,79.58,0.021
14.08,79.80,0.021
14.10,80.01,0.021
14.13,80.23,0.021
14.15,80.45,0.021
14.17,80.67,0.021
14.19,80.88,0.021
14.21,81.10,0.021
14.23,81.32,0.021
14.26,81.53,0.021
14.28,81.75,0.021
14.30,81.97,0.021
14.32,82.19,0.021
14.34,82.40,0.021
14.37,82.62,0.021
14.39,82.84,0.021
14.41,83.05,0.021
14.43,83.27,0.021
14.45,83.49,0.022
14.47,83.70,0.022
14.50,83.92,0.022
14.52,84.14,0.022
14.54,84.35,0.022
14.56,84.57,0.022
14.58,84.79,0.022
14.60,85.00,0.022
14.63,85.22,0.022
14.65,85.44,0.022
14.67,85.65,0.022
14.69,85.87,0.022
14.71,86.09,0.022
14.73,86.31,0.022
14.75,86.52,0.022
14.78,86.74,0.022
14.80,86.96,0.022
14.82,87.17,0.022
14.84,87.39,0.022
14.86,87.61,0.022
14.88,87.82,0.022
14.91,88.04,0.022
14.93,88.26,0.022
14.95,88.48,0.022
14.97,88.69,0.022
14.99,88.91,0.022
15.02,89.13,0.022
15.04,89.34,0.022
15.06,89.56,0.022
15.08,89.78,0.022
15.10,89.99,0.022
15.12,90.21,0.022
15.15,90.43,0.022
15.17,90.64,0.022
15.19,90.86,0.022
15.21,91.08,0.022
15.23,91.29,0.022
15.25,91.51,0.022
15.28,91.73,0.022
15.30,91.94,0.022
15.32,92.16,0.022
15.34,92.38,0.022
15.36,92.59,0.022
15.38,92.81,0.022
15.40,93.03,0.022
15.43,93.24,0.022
15.45,93.46,0.022
15.47,93.68,0.022
15.49,93.90,0.022
15.51,94.11,0.022
15.53,94.33,0.022
15.56,94.55,0.022
15.58,94.76,0.022
15.60,94.98,0.022
15.62,95.20,0.022
15.64,95.41,0.022
15.67,95.63,0.022
15.69,95.85,0.022
15.71,96.06,0.022
15.73,96.28,0.022
15.75,96.50,0.022
15.77,96.71,0.022
15.80,96.93,0.022
15.82,97.15,0.022
15.84,97.36,0.022
15.86,97.58,0.022
15.88,97.80,0.022
15.90,98.01,0.022
15.93,98.23,0.022
15.95,98.45,0.022
15.97,98.67,0.022
15.99,98.88,0.022
16.01,99.10,0.022
16.03,99.32,0.022
16.05,99.53,0.022
16.08,99.75,0.022
16.10,99.97,0.022
16.12,100.18,0.022
16.14,100.40,0.022
16.16,100.62,0.022
16.18,100.83,0.022
16.21,101.05,0.022
16.23,101.27,0.022
16.25,101.48,0.022
16.27,101.70,0.022
16.29,101.92,0.022
16.32,102.13,0.022
16.34,102.35,0.022
16.36,102.57,0.022
16.38,102.78,0.022
16.40,103.00,0.022
16.42,103.22,0.022
16.45,103.44,0.022
16.47,103.65,0.022
16.49,103.87,0.022
16.51,104.09,0.022
16.53,104.30,0.022
16.55,104.52,0.022
16.58,104.74,0.022
16.60,104.95,0.022
16.62,105.17,0.022
16.64,105.39,0.022
16.66,105.61,0.022
16.68,105.82,0.022
16.70,106.04,0.022
16.73,106.25,0.022
16.75,106.47,0.022
16.77,106.69,0.022
16.79,106.91,0.022
16.81,107.12,0.022
16.83,107.34,0.022
16.86,107.56,0.022
16.88,107.77,0.022
16.90,107.99,0.022
16.92,108.21,0.022
16.94,108.42,0.022
16.97,108.64,0.022
16.99,108.86,0.023
17.01,109.07,0.023
17.03,109.29,0.023
17.05,109.51,0.023
17.07,109.72,0.023
17.09,109.94,0.023
17.12,110.16,0.023
17.14,110.38,0.023
17.16,110.59,0.023
17.18,110.81,0.023
17.20,111.02,0.023
17.23,111.24,0.023
17.25,111.46,0.023
17.27,111.67,0.023
17.29,111.89,0.023
17.31,112.11,0.023
17.33,112.32,0.023
17.36,112.54,0.023
17.38,112.76,0.023
17.40,112.98,0.023
17.42,113.19,0.023
17.44,113.41,0.023
17.46,113.63,0.023
17.48,113.84,0.023
17.51,114.06,0.023
17.53,114.28,0.023
17.55,114.49,0.024
17.57,114.71,0.024
17.59,114.93,0.024
17.62,115.14,0.024
17.64,115.36,0.024
17.66,115.58,0.024
17.68,115.79,0.024
17.70,116.01,0.024
17.72,116.23,0.024
17.74,116.44,0.024
17.77,116.66,0.025
17.79,116.88,0.025
17.81,117.09,0.025
17.83,117.31,0.025
17.85,117.53,0.025
17.88,117.74,0.025
17.90,117.96,0.026
17.92,118.18,0.026
17.94,118.39,0.026
17.96,118.61,0.026
17.98,118.83,0.027
18.01,119.04,0.027
18.03,119.26,0.027
18.05,119.48,0.027
18.07,119.69,0.027
18.09,119.91,0.028
18.11,120.12,0.028
18.13,120.34,0.028
18.16,120.56,0.028
18.18,120.78,0.028
18.20,120.99,0.028
18.22,121.21,0.028
18.24,121.43,0.028
18.27,121.64,0.028
18.29,121.86,0.028
18.31,122.08,0.028
18.33,122.29,0.028
18.35,122.51,0.028
18.37,122.73,0.028
18.39,122.94,0.028
18.42,123.16,0.028
18.44,123.38,0.028
18.46,123.59,0.028
18.48,123.81,0.028
18.50,124.03,0.028
18.53,124.25,0.028
18.55,124.46,0.028
18.57,124.68,0.028
18.59,124.89,0.028
18.61,125.11,0.028
18.63,125.33,0.028
18.66,125.55,0.028
18.68,125.76,0.028
18.70,125.98,0.028
18.72,126.20,0.028
18.74,126.41,0.028
18.76,126.63,0.028
18.78,126.85,0.028
18.81,127.07,0.028
18.83,127.28,0.028
18.85,127.50,0.028
18.87,127.71,0.028
18.89,127.93,0.028
18.92,128.15,0.028
18.94,128.37,0.028
18.96,128.58,0.028
18.98,128.80,0.028
19.00,129.02,0.028
19.02,129.23,0.028
19.04,129.45,0.028
19.07,129.67,0.028
19.09,129.89,0.028
19.11,130.10,0.028
19.13,130.32,0.028
19.15,130.54,0.028
19.18,130.75,0.028
19.20,130.97,0.028
19.22,131.19,0.028
19.24,131.40,0.028
19.26,131.62,0.028
19.28,131.84,0.028
19.31,132.05,0.028
19.33,132.27,0.028
19.35,132.49,0.028
19.37,132.70,0.028
19.39,132.92,0.028
19.41,133.14,0.029
19.43,133.36,0.029
19.46,133.57,0.029
19.48,133.79,0.029
19.50,134.00,0.029
19.52,134.22,0.029
19.54,134.44,0.029
19.57,134.65,0.029
19.59,134.87,0.029
19.61,135.09,0.029
19.63,135.30,0.029
19.65,135.52,0.029
19.67,135.74,0.029
19.69,135.95,0.029
19.72,136.17,0.029
19.74,136.39,0.029
19.76,136.61,0.029
19.78,136.82,0.029
19.80,137.04,0.029
19.83,137.26,0.029
19.85,137.47,0.029
19.87,137.69,0.029
19.89,137.91,0.029
19.91,138.12,0.029
19.93,138.34,0.029
19.96,138.56,0.029
19.98,138.77,0.029
20.00,138.99,0.029
20.02,139.21,0.029
20.04,139.42,0.029
20.06,139.64,0.029
20.08,139.86,0.029
20.11,140.07,0.029
20.13,140.29,0.029
20.15,140.51,0.029
20.17,140.72,0.029
20.19,140.94,0.029
20.22,141.16,0.029
20.24,141.37,0.029
20.26,141.59,0.029
20.28,141.81,0.029
20.30,142.02,0.029
20.32,142.24,0.029
20.34,142.46,0.029
20.37,142.68,0.029
20.39,142.89,0.029
20.41,143.11,0.029
20.43,143.33,0.029
20.45,143.54,0.029
20.48,143.76,0.029
20.50,143.98,0.029
20.52,144.19,0.029
20.54,144.41,0.029
20.56,144.63,0.029
20.58,144.84,0.029
20.61,145.06,0.029
20.63,145.28,0.029
20.65,145.49,0.029
20.67,145.71,0.029
20.69,145.93,0.029
20.71,146.15,0.029
20.73,146.36,0.029
20.76,146.58,0.029
20.78,146.80,0.029
20.80,147.01,0.029
20.82,147.23,0.029
20.84,147.45,0.029
20.87,147.66,0.029
20.89,147.88,0.029
20.91,148.09,0.029
20.93,148.31,0.029
20.95,148.53,0.029
20.97,148.74,0.029
20.99,148.96,0.029
21.02,149.18,0.029
21.04,149.40,0.029
21.06,149.61,0.029
21.08,149.83,0.029
21.10,150.05,0.029
21.13,150.26,0.029
21.15,150.48,0.029
21.17,150.70,0.029
21.19,150.91,0.029
21.21,151.13,0.029
21.23,151.35,0.029
21.26,151.57,0.029
21.28,151.78,0.029
21.30,152.00,0.029
21.32,152.21,0.029
21.34,152.43,0.029
21.36,152.65,0.029
21.38,152.86,0.029
21.41,153.08,0.029
21.43,153.30,0.029
21.45,153.52,0.029
21.47,153.73,0.029
21.49,153.95,0.029
21.52,154.17,0.029
21.54,154.38,0.029
21.56,154.60,0.029
21.58,154.82,0.029
21.60,155.03,0.029
21.62,155.25,0.029
21.64,155.47,0.029
21.67,155.69,0.029
21.69,155.90,0.029
21.71,156.12,0.029
21.73,156.33,0.029
21.75,156.55,0.029
21.78,156.77,0.029
21.80,156.99,0.029
21.82,157.20,0.029
21.84,157.42,0.029
21.86,157.64,0.029
21.88,157.85,0.029
21.91,158.07,0.029
21.93,158.29,0.029
21.95,158.50,0.029
21.97,158.72,0.029
21.99,158.94,0.029
22.01,159.15,0.029
22.03,159.37,0.029
22.06,159.59,0.029
22.08,159.80,0.029
22.10,160.02,0.029
22.12,160.24,0.029
22.14,160.45,0.029
22.17,160.67,0.029
22.19,160.89,0.029
22.21,161.11,0.029
22.23,161.32,0.029
22.25,161.54,0.029
22.27,161.76,0.029
22.29,161.97,0.029
22.32,162.19,0.029
22.34,162.41,0.029
22.36,162.62,0.029
22.38,162.84,0.029
22.40,163.06,0.029
22.43,163.27,0.029
22.45,163.49,0.029
22.47,163.71,0.030
22.49,163.92,0.030
22.51,164.14,0.030
22.53,164.36,0.030
22.56,164.58,0.030
22.58,164.79,0.030
22.60,165.01,0.030
22.62,165.23,0.030
22.64,165.44,0.030
22.66,165.66,0.030
22.68,165.88,0.030
22.71,166.09,0.030
22.73,166.31,0.030
22.75,166.53,0.030
22.77,166.75,0.030
22.79,166.97,0.030
22.82,167.18,0.030
22.84,167.40,0.030
22.86,167.62,0.030
22.88,167.84,0.030
22.90,168.05,0.030
22.92,168.27,0.030
22.94,168.49,0.030
22.97,168.70,0.030
22.99,168.92,0.030
23.01,169.13,0.030
23.03,169.35,0.030
23.05,169.57,0.030
23.08,169.78,0.030
23.10,170.00,0.030
23.12,170.22,0.030
23.14,170.43,0.030
23.16,170.65,0.030
23.18,170.86,0.030
23.21,171.08,0.030
23.23,171.30,0.030
23.25,171.51,0.030
23.27,171.73,0.030
23.29,171.95,0.030
23.31,172.16,0.030
23.33,172.38,0.030
23.36,172.60,0.030
23.38,172.82,0.030
23.40,173.03,0.030
23.42,173.25,0.030
23.44,173.47,0.030
23.47,173.68,0.030
23.49,173.90,0.030
23.51,174.11,0.030
23.53,174.33,0.030
23.55,174.55,0.030
23.57,174.77,0.030
23.59,174.98,0.030
23.62,175.20,0.030
23.64,175.42,0.030
23.66,175.63,0.030
23.68,175.85,0.030
23.70,176.07,0.030
23.73,176.28,0.030
23.75,176.50,0.030
23.77,176.72,0.030
23.79,176.93,0.030
23.81,177.15,0.030
23.83,177.37,0.030
23.86,177.58,0.030
23.88,177.80,0.030
23.90,178.02,0.030
23.92,178.23,0.030
23.94,178.45,0.030
23.96,178.67,0.030
23.98,178.89,0.030
24.01,179.10,0.030
24.03,179.32,0.030
24.05,179.54,0.030
24.07,179.75,0.030
24.09,179.97,0.030
24.12,180.19,0.030
24.14,180.40,0.030
24.16,180.62,0.030
24.18,180.84,0.030
24.20,181.05,0.030
24.22,181.27,0.030
24.24,181.49,0.030
24.27,181.70,0.030
24.29,181.92,0.030
24.31,182.14,0.030
24.33,182.35,0.030
24.35,182.57,0.030
24.38,182.79,0.030
24.40,183.00,0.030
24.42,183.22,0.030
24.44,183.44,0.030
24.46,183.65,0.030
24.48,183.87,0.030
24.51,184.09,0.030
24.53,184.30,0.030
24.55,184.52,0.030
24.57,184.74,0.030
24.59,184.95,0.030
24.61,185.17,0.030
24.63,185.39,0.030
24.66,185.61,0.030
24.68,185.82,0.030
24.70,186.04,0.030
24.72,186.26,0.030
24.74,186.47,0.030
24.77,186.69,0.030
24.79,186.91,0.030
24.81,187.12,0.030
24.83,187.34,0.030
24.85,187.56,0.030
24.87,187.77,0.030
24.89,187.99,0.030
24.92,188.21,0.030
24.94,188.42,0.030
24.96,188.64,0.030
24.98,188.86,0.030
25.00,189.08,0.030
25.03,189.29,0.030
25.05,189.51,0.030
25.07,189.73,0.030
25.09,189.94,0.030
25.11,190.16,0.030
25.13,190.38,0.030
25.16,190.59,0.030
25.18,190.81,0.030
25.20,191.03,0.030
25.22,191.24,0.030
25.24,191.46,0.030
25.26,191.68,0.030
25.28,191.89,0.030
25.31,192.11,0.030
25.33,192.33,0.030
25.35,192.55,0.030
25.37,192.76,0.030
25.39,192.98,0.030
25.42,193.19,0.030
25.44,193.41,0.030
25.46,193.63,0.030
25.48,193.85,0.030
25.50,194.06,0.030
25.52,194.28,0.030
25.54,194.50,0.030
25.57,194.71,0.030
25.59,194.93,0.030
25.61,195.15,0.030
25.63,195.36,0.030
25.65,195.58,0.030
25.68,195.80,0.030
25.70,196.02,0.030
25.72,196.23,0.030
25.74,196.45,0.030
25.76,196.66,0.030
25.78,196.88,0.030
25.81,197.10,0.030
25.83,197.31,0.030
25.85,197.53,0.030
25.87,197.75,0.030
25.89,197.97,0.030
25.91,198.18,0.030
25.93,198.40,0.030
25.96,198.62,0.030
25.98,198.83,0.030
26.00,199.05,0.030
26.02,199.27,0.030
26.04,199.48,0.030
26.07,199.70,0.030
26.09,199.92,0.030
26.11,200.13,0.030
26.13,200.35,0.030
26.15,200.57,0.030
26.17,200.78,0.030
26.19,201.00,0.030
26.22,201.22,0.030
26.24,201.43,0.030
26.26,201.65,0.030
26.28,201.87,0.030
26.30,202.08,0.030
26.33,202.30,0.030
26.35,202.52,0.030
26.37,202.74,0.030
26.39,202.95,0.030
26.41,203.17,0.030
26.43,203.39,0.030
26.46,203.60,0.030
26.48,203.82,0.030
26.50,204.04,0.030
26.52,204.25,0.030
26.54,204.47,0.030
26.56,204.69,0.030
26.58,204.90,0.030
26.61,205.12,0.030
26.63,205.34,0.030
26.65,205.55,0.030
26.67,205.77,0.030
26.69,205.99,0.030
26.72,206.20,0.030
26.74,206.42,0.030
26.76,206.64,0.030
26.78,206.85,0.031
26.80,207.07,0.031
26.82,207.29,0.031
26.84,207.50,0.031
26.87,207.72,0.031
26.89,207.94,0.031
26.91,208.15,0.031
26.93,208.37,0.031
26.95,208.59,0.031
26.98,208.81,0.031
27.00,209.02,0.031
27.02,209.24,0.031
27.04,209.46,0.031
27.06,209.67,0.031
27.08,209.89,0.031
27.11,210.11,0.031
27.13,210.32,0.031
27.15,210.54,0.031
27.17,210.76,0.031
27.19,210.97,0.031
27.21,211.19,0.031
27.23,211.41,0.031
27.26,211.62,0.031
27.28,211.84,0.031
27.30,212.06,0.031
27.32,212.27,0.031
27.34,212.49,0.031
27.37,212.71,0.031
27.39,212.93,0.031
27.41,213.14,0.031
27.43,213.36,0.031
27.45,213.58,0.031
27.47,213.79,0.031
27.49,214.01,0.031
27.52,214.22,0.031
27.54,214.44,0.031
27.56,214.66,0.031
27.58,214.87,0.031
27.60,215.09,0.031
27.63,215.31,0.031
27.65,215.53,0.031
27.67,215.74,0.031
27.69,215.96,0.031
27.71,216.17,0.031
27.73,216.39,0.031
27.76,216.61,0.031
27.78,216.83,0.031
27.80,217.04,0.031
27.82,217.26,0.031
27.84,217.48,0.031
27.86,217.69,0.031
27.88,217.91,0.031
27.91,218.13,0.031
27.93,218.34,0.031
27.95,218.56,0.031
27.97,218.78,0.031
27.99,218.99,0.031
28.02,219.21,0.031
28.04,219.43,0.031
28.06,219.64,0.031
28.08,219.86,0.031
28.10,220.08,0.031
28.12,220.29,0.031
28.14,220.51,0.031
28.17,220.73,0.031
28.19,220.95,0.031
28.21,221.16,0.031
28.23,221.38,0.031
28.25,221.60,0.031
28.28,221.81,0.031
28.30,222.03,0.031
28.32,222.25,0.031
28.34,222.46,0.031
28.36,222.68,0.031
28.38,222.90,0.031
28.41,223.11,0.031
28.43,223.33,0.031
28.45,223.55,0.031
28.47,223.76,0.031
28.49,223.98,0.031
28.51,224.20,0.031
28.53,224.41,0.031
28.56,224.63,0.031
28.58,224.85,0.031
28.60,225.06,0.031
28.62,225.28,0.031
28.64,225.50,0.031
28.67,225.72,0.031
28.69,225.93,0.031
28.71,226.15,0.031
28.73,226.37,0.031
28.75,226.58,0.031
28.77,226.80,0.031
28.79,227.02,0.031
28.82,227.23,0.031
28.84,227.45,0.031
28.86,227.67,0.031
28.88,227.88,0.031
28.90,228.10,0.031
28.93,228.32,0.031
28.95,228.53,0.031
28.97,228.75,0.031
28.99,228.97,0.031
29.01,229.19,0.031
29.03,229.40,0.031
29.06,229.62,0.031
29.08,229.84,0.031
29.10,230.05,0.031
29.12,230.27,0.031
29.14,230.49,0.031
29.16,230.70,0.031
29.18,230.92,0.031
29.21,231.14,0.031
29.23,231.35,0.031
29.25,231.57,0.031
29.27,231.79,0.031
29.29,232.00,0.031
29.32,232.22,0.031
29.34,232.44,0.031
29.36,232.65,0.031
29.38,232.87,0.031
29.40,233.09,0.031
29.42,233.30,0.031
29.44,233.52,0.031
29.47,233.74,0.031
29.49,233.95,0.031
29.51,234.17,0.031
29.53,234.39,0.031
29.55,234.61,0.031
29.58,234.82,0.031
29.60,235.04,0.031
29.62,235.26,0.031
29.64,235.47,0.031
29.66,235.69,0.031
29.68,235.91,0.031
29.71,236.12,0.031
29.73,236.34,0.031
29.75,236.55,0.031
29.77,236.77,0.031
29.79,236.99,0.031
29.81,237.21,0.031
29.83,237.42,0.031
29.86,237.64,0.031
29.88,237.86,0.031
29.90,238.07,0.031
29.92,238.29,0.031
29.94,238.51,0.031
29.97,238.72,0.031
29.99,238.94,0.031
30.01,239.16,0.031
30.03,239.37,0.031
30.05,239.59,0.031
30.07,239.81,0.031
30.09,240.02,0.031
30.12,240.24,0.031
30.14,240.46,0.031
30.16,240.67,0.031
30.18,240.89,0.031
30.20,241.11,0.031
30.23,241.32,0.031
30.25,241.54,0.031
30.27,241.76,0.031
30.29,241.97,0.031
30.31,242.19,0.031
30.33,242.41,0.031
30.36,242.63,0.031
30.38,242.84,0.031
30.40,243.06,0.031
30.42,243.27,0.031
30.44,243.49,0.031
30.46,243.71,0.031
30.48,243.93,0.031
30.51,244.14,0.031
30.53,244.36,0.031
30.55,244.58,0.031
30.57,244.79,0.031
30.59,245.01,0.031
30.62,245.23,0.031
30.64,245.44,0.031
30.66,245.66,0.031
30.68,245.88,0.031
30.70,246.09,0.031
30.72,246.31,0.031
30.74,246.53,0.031
30.77,246.74,0.031
30.79,246.96,0.031
30.81,247.18,0.031
30.83,247.39,0.031
30.85,247.61,0.031
30.88,247.83,0.031
30.90,248.04,0.031
30.92,248.26,0.031
30.94,248.48,
30.96,248.70,
30.98,248.91,
30.99,,

[step]
Ramp 10.00 °C/min to -60.00 °C
Time,Temperature,Heat Flow (Normalized)
min,°C,W/g
32.99,250.17,-0.006
33.02,250.17,-0.006
33.04,250.16,-0.006
33.06,250.14,-0.005
33.08,250.09,-0.005
33.10,250.00,-0.008
33.12,249.88,-0.013
33.14,249.73,-0.020
33.17,249.55,-0.026
33.19,249.37,-0.031
33.21,249.17,-0.035
33.23,248.96,-0.038
33.25,248.75,-0.040
33.28,248.54,-0.040
33.30,248.33,-0.041
33.32,248.12,-0.041
33.34,247.90,-0.042
33.36,247.69,-0.042
33.38,247.47,-0.042
33.41,247.26,-0.042
33.43,247.04,-0.042
33.45,246.83,-0.042
33.47,246.61,-0.042
33.49,246.40,-0.042
33.51,246.18,-0.042
33.53,245.97,-0.042
33.56,245.75,-0.042
33.58,245.54,-0.042
33.60,245.32,-0.042
33.62,245.11,-0.042
33.64,244.89,-0.042
33.67,244.68,-0.042
33.69,244.46,-0.042
33.71,244.25,-0.042
33.73,244.03,-0.042
33.75,243.82,-0.042
33.77,243.60,-0.042
33.79,243.39,-0.043
33.82,243.17,-0.043
33.84,242.95,-0.043
33.86,242.74,-0.043
33.88,242.52,-0.043
33.90,242.31,-0.043
33.93,242.09,-0.043
33.95,241.87,-0.043
33.97,241.66,-0.043
33.99,241.44,-0.043
34.01,241.23,-0.043
34.03,241.01,-0.043
34.06,240.80,-0.043
34.08,240.58,-0.043
34.10,240.36,-0.043
34.12,240.15,-0.043
34.14,239.93,-0.043
34.16,239.72,-0.042
34.19,239.50,-0.042
34.21,239.29,-0.042
34.23,239.07,-0.042
34.25,238.85,-0.042
34.27,238.64,-0.042
34.29,238.42,-0.042
34.31,238.20,-0.042
34.34,237.99,-0.042
34.36,237.77,-0.042
34.38,237.56,-0.042
34.40,237.34,-0.042
34.42,237.12,-0.042
34.44,236.91,-0.042
34.47,236.69,-0.042
34.49,236.47,-0.042
34.51,236.26,-0.042
34.53,236.04,-0.042
34.55,235.83,-0.042
34.58,235.61,-0.042
34.60,235.39,-0.042
34.62,235.18,-0.042
34.64,234.96,-0.042
34.66,234.74,-0.042
34.68,234.53,-0.042
34.71,234.31,-0.042
34.73,234.09,-0.042
34.75,233.88,-0.042
34.77,233.66,-0.042
34.79,233.44,-0.042
34.81,233.23,-0.042
34.84,233.01,-0.042
34.86,232.80,-0.042
34.88,232.58,-0.042
34.90,232.36,-0.042
34.92,232.15,-0.042
34.94,231.93,-0.042
34.96,231.71,-0.042
34.99,231.50,-0.042
35.01,231.28,-0.042
35.03,231.06,-0.042
35.05,230.85,-0.042
35.07,230.63,-0.042
35.09,230.41,-0.042
35.12,230.20,-0.042
35.14,229.98,-0.042
35.16,229.77,-0.042
35.18,229.55,-0.042
35.20,229.33,-0.042
35.23,229.12,-0.042
35.25,228.90,-0.042
35.27,228.68,-0.042
35.29,228.47,-0.042
35.31,228.25,-0.042
35.33,228.03,-0.042
35.36,227.82,-0.042
35.38,227.60,-0.042
35.40,227.38,-0.042
35.42,227.17,-0.042
35.44,226.95,-0.042
35.46,226.73,-0.042
35.49,226.52,-0.042
35.51,226.30,-0.042
35.53,226.08,-0.042
35.55,225.87,-0.042
35.57,225.65,-0.042
35.59,225.43,-0.042
35.61,225.22,-0.042
35.64,225.00,-0.042
35.66,224.78,-0.042
35.68,224.57,-0.042
35.70,224.35,-0.042
35.72,224.13,-0.042
35.74,223.92,-0.042
35.77,223.70,-0.042
35.79,223.49,-0.042
35.81,223.27,-0.042
35.83,223.05,-0.042
35.85,222.84,-0.042
35.88,222.62,-0.042
35.90,222.40,-0.042
35.92,222.19,-0.042
35.94,221.97,-0.042
35.96,221.75,-0.042
35.98,221.54,-0.042
36.01,221.32,-0.042
36.03,221.10,-0.042
36.05,220.89,-0.042
36.07,220.67,-0.042
36.09,220.46,-0.042
36.11,220.24,-0.042
36.14,220.02,-0.042
36.16,219.80,-0.042
36.18,219.59,-0.042
36.20,219.37,-0.042
36.22,219.16,-0.042
36.24,218.94,-0.042
36.26,218.72,-0.042
36.29,218.50,-0.042
36.31,218.29,-0.042
36.33,218.07,-0.042
36.35,217.86,-0.042
36.37,217.64,-0.042
36.39,217.42,-0.042
36.42,217.21,-0.042
36.44,216.99,-0.042
36.46,216.77,-0.042
36.48,216.56,-0.042
36.50,216.34,-0.042
36.53,216.12,-0.042
36.55,215.91,-0.042
36.57,215.69,-0.042
36.59,215.47,-0.042
36.61,215.26,-0.042
36.63,215.04,-0.042
36.66,214.82,-0.042
36.68,214.61,-0.042
36.70,214.39,-0.042
36.72,214.17,-0.042
36.74,213.96,-0.042
36.76,213.74,-0.042
36.79,213.52,-0.042
36.81,213.31,-0.042
36.83,213.09,-0.042
36.85,212.87,-0.042
36.87,212.66,-0.042
36.89,212.44,-0.042
36.91,212.22,-0.042
36.94,212.01,-0.042
36.96,211.79,-0.042
36.98,211.57,-0.042
37.00,211.36,-0.042
37.02,211.14,-0.042
37.04,210.92,-0.041
37.07,210.71,-0.042
37.09,210.49,-0.041
37.11,210.27,-0.041
37.13,210.06,-0.041
37.15,209.84,-0.041
37.18,209.63,-0.041
37.20,209.41,-0.041
37.22,209.19,-0.041
37.24,208.97,-0.041
37.26,208.76,-0.041
37.28,208.54,-0.041
37.31,208.33,-0.041
37.33,208.11,-0.041
37.35,207.89,-0.041
37.37,207.68,-0.041
37.39,207.46,-0.041
37.41,207.24,-0.041
37.44,207.03,-0.041
37.46,206.81,-0.041
37.48,206.59,-0.041
37.50,206.38,-0.041
37.52,206.16,-0.041
37.54,205.94,-0.041
37.56,205.73,-0.041
37.59,205.51,-0.041
37.61,205.29,-0.041
37.63,205.08,-0.041
37.65,204.86,-0.041
37.67,204.64,-0.041
37.69,204.43,-0.041
37.72,204.21,-0.041
37.74,203.99,-0.041
37.76,203.78,-0.041
37.78,203.56,-0.041
37.80,203.34,-0.041
37.83,203.13,-0.041
37.85,202.91,-0.041
37.87,202.70,-0.041
37.89,202.48,-0.041
37.91,202.26,-0.041
37.93,202.05,-0.041
37.96,201.83,-0.041
37.98,201.61,-0.041
38.00,201.39,-0.041
38.02,201.18,-0.041
38.04,200.96,-0.041
38.06,200.74,-0.041
38.09,200.53,-0.041
38.11,200.31,-0.041
38.13,200.10,-0.041
38.15,199.88,-0.041
38.17,199.66,-0.041
38.19,199.45,-0.041
38.21,199.23,-0.041
38.24,199.01,-0.041
38.26,198.80,-0.041
38.28,198.58,-0.041
38.30,198.36,-0.041
38.32,198.15,-0.041
38.34,197.93,-0.041
38.37,197.71,-0.041
38.39,197.50,-0.041
38.41,197.28,-0.041
38.43,197.06,-0.041
38.45,196.85,-0.041
38.48,196.63,-0.041
38.50,196.41,-0.041
38.52,196.20,-0.041
38.54,195.98,-0.041
38.56,195.76,-0.041
38.58,195.55,-0.041
38.61,195.33,-0.041
38.63,195.11,-0.041
38.65,194.90,-0.041
38.67,194.68,-0.041
38.69,194.46,-0.041
38.71,194.25,-0.041
38.74,194.03,-0.041
38.76,193.81,-0.041
38.78,193.60,-0.041
38.80,193.38,-0.041
38.82,193.16,-0.041
38.84,192.95,-0.041
38.86,192.73,-0.041
38.89,192.51,-0.041
38.91,192.30,-0.041
38.93,192.08,-0.041
38.95,191.86,-0.041
38.97,191.65,-0.041
38.99,191.43,-0.041
39.02,191.22,-0.041
39.04,191.00,-0.041
39.06,190.78,-0.041
39.08,190.57,-0.041
39.10,190.35,-0.041
39.13,190.13,-0.041
39.15,189.92,-0.041
39.17,189.70,-0.041
39.19,189.48,-0.041
39.21,189.27,-0.041
39.23,189.05,-0.041
39.26,188.83,-0.041
39.28,188.62,-0.041
39.30,188.40,-0.041
39.32,188.18,-0.041
39.34,187.97,-0.041
39.36,187.75,-0.041
39.39,187.53,-0.041
39.41,187.32,-0.041
39.43,187.10,-0.041
39.45,186.88,-0.041
39.47,186.67,-0.041
39.49,186.45,-0.041
39.51,186.23,-0.041
39.54,186.02,-0.041
39.56,185.80,-0.041
39.58,185.58,-0.041
39.60,185.37,-0.041
39.62,185.15,-0.041
39.64,184.93,-0.041
39.67,184.72,-0.041
39.69,184.50,-0.041
39.71,184.28,-0.041
39.73,184.06,-0.041
39.75,183.85,-0.041
39.78,183.63,-0.041
39.80,183.41,-0.041
39.82,183.20,-0.041
39.84,182.98,-0.041
39.86,182.76,-0.041
39.88,182.55,-0.041
39.91,182.33,-0.041
39.93,182.11,-0.041
39.95,181.90,-0.041
39.97,181.68,-0.041
39.99,181.47,-0.041
40.01,181.25,-0.041
40.04,181.03,-0.041
40.06,180.82,-0.041
40.08,180.60,-0.041
40.10,180.38,-0.041
40.12,180.17,-0.041
40.14,179.95,-0.041
40.16,179.73,-0.041
40.19,179.52,-0.041
40.21,179.30,-0.041
40.23,179.08,-0.041
40.25,178.87,-0.041
40.27,178.65,-0.041
40.29,178.43,-0.041
40.32,178.22,-0.041
40.34,178.00,-0.041
40.36,177.79,-0.041
40.38,177.57,-0.041
40.40,177.35,-0.041
40.43,177.14,-0.041
40.45,176.92,-0.041
40.47,176.70,-0.041
40.49,176.49,-0.041
40.51,176.27,-0.041
40.53,176.05,-0.041
40.56,175.84,-0.041
40.58,175.62,-0.041
40.60,175.40,-0.041
40.62,175.19,-0.041
40.64,174.97,-0.041
40.66,174.75,-0.041
40.69,174.54,-0.041
40.71,174.32,-0.041
40.73,174.10,-0.041
40.75,173.89,-0.040
40.77,173.67,-0.040
40.79,173.45,-0.040
40.81,173.24,-0.040
40.84,173.02,-0.040
40.86,172.80,-0.040
40.88,172.59,-0.040
40.90,172.37,-0.040
40.92,172.15,-0.040
40.94,171.94,-0.040
40.97,171.72,-0.040
40.99,171.50,-0.040
41.01,171.29,-0.040
41.03,171.07,-0.040
41.05,170.86,-0.040
41.08,170.64,-0.040
41.10,170.42,-0.040
41.12,170.20,-0.040
41.14,169.99,-0.040
41.16,169.77,-0.040
[...]
140.98,28.67,0.025
141.01,28.88,0.025
141.03,29.10,0.025
141.05,29.32,0.025
141.07,29.53,0.025
141.09,29.75,0.025
141.12,29.97,0.025
141.14,30.18,0.025
141.16,30.40,0.025
141.18,30.62,0.025
141.20,30.84,0.025
141.22,31.05,0.025
141.25,31.27,0.025
141.27,31.49,0.025
141.29,31.70,0.025
141.31,31.92,0.025
141.33,32.14,0.025
141.35,32.35,0.025
141.38,32.57,0.025
141.40,32.79,0.025
141.42,33.01,0.025
141.44,33.22,0.025
141.46,33.44,0.025
141.48,33.66,0.025
141.50,33.87,0.025
141.53,34.09,0.025
141.55,34.31,0.025
141.57,34.53,0.025
141.59,34.74,0.025
141.61,34.96,0.025
141.63,35.17,0.025
141.66,35.39,0.025
141.68,35.61,0.025
141.70,35.82,0.025
141.72,36.04,0.025
141.74,36.26,0.025
141.77,36.48,0.025
141.79,36.69,0.025
141.81,36.91,0.025
141.83,37.13,0.025
141.85,37.34,0.025
141.87,37.56,0.025
141.90,37.78,0.025
141.92,38.00,0.025
141.94,38.21,0.025
141.96,38.43,0.025
141.98,38.65,0.025
142.00,38.86,0.025
142.03,39.08,0.025
142.05,39.30,0.025
142.07,39.51,0.025
142.09,39.73,0.025
142.11,39.95,0.025
142.13,40.16,0.025
142.15,40.38,0.025
142.18,40.60,0.025
142.20,40.82,0.025
142.22,41.03,0.025
142.24,41.25,0.025
142.26,41.46,0.025
142.28,41.68,0.025
142.31,41.90,0.025
142.33,42.11,0.025
142.35,42.33,0.026
142.37,42.55,0.026
142.39,42.77,0.026
142.42,42.98,0.026
142.44,43.20,0.026
142.46,43.42,0.026
142.48,43.63,0.026
142.50,43.85,0.026
142.52,44.07,0.026
142.55,44.28,0.026
142.57,44.50,0.026
142.59,44.72,0.026
142.61,44.94,0.026
142.63,45.15,0.026
142.65,45.37,0.026
142.68,45.59,0.026
142.70,45.80,0.026
142.72,46.02,0.026
142.74,46.24,0.026
142.76,46.45,0.026
142.78,46.67,0.026
142.80,46.89,0.026
142.83,47.11,0.026
142.85,47.32,0.026
142.87,47.54,0.026
142.89,47.76,0.026
142.91,47.97,0.026
142.93,48.19,0.026
142.96,48.41,0.026
142.98,48.62,0.026
143.00,48.84,0.026
143.02,49.06,0.026
143.04,49.27,0.026
143.07,49.49,0.026
143.09,49.71,0.026
143.11,49.92,0.026
143.13,50.14,0.026
143.15,50.36,0.026
143.17,50.57,0.026
143.20,50.79,0.026
143.22,51.01,0.026
143.24,51.22,0.026
143.26,51.44,0.026
143.28,51.66,0.026
143.30,51.88,0.026
143.33,52.09,0.026
143.35,52.31,0.026
143.37,52.53,0.026
143.39,52.74,0.026
143.41,52.96,0.026
143.43,53.18,0.026
143.45,53.39,0.026
143.48,53.61,0.026
143.50,53.83,0.026
143.52,54.05,0.026
143.54,54.26,0.026
143.56,54.48,0.026
143.58,54.70,0.026
143.61,54.91,0.026
143.63,55.13,0.026
143.65,55.35,0.026
143.67,55.56,0.026
143.69,55.78,0.026
143.72,56.00,0.026
143.74,56.21,0.026
143.76,56.43,0.026
143.78,56.65,0.026
143.80,56.86,0.026
143.82,57.08,0.026
143.85,57.30,0.026
143.87,57.51,0.026
143.89,57.73,0.026
143.91,57.95,0.026
143.93,58.17,0.026
143.95,58.38,0.026
143.98,58.60,0.026
144.00,58.82,0.026
144.02,59.03,0.026
144.04,59.25,0.026
144.06,59.47,0.026
144.08,59.68,0.026
144.10,59.90,0.026
144.13,60.12,0.026
144.15,60.33,0.026
144.17,60.55,0.026
144.19,60.77,0.026
144.21,60.98,0.026
144.23,61.20,0.026
144.26,61.42,0.026
144.28,61.64,0.026
144.30,61.85,0.026
144.32,62.07,0.026
144.34,62.29,0.026
144.37,62.50,0.026
144.39,62.72,0.026
144.41,62.94,0.026
144.43,63.15,0.026
144.45,63.37,0.026
144.47,63.59,0.026
144.50,63.80,0.026
144.52,64.02,0.026
144.54,64.24,0.026
144.56,64.46,0.026
144.58,64.67,0.026
144.60,64.89,0.026
144.63,65.11,0.027
144.65,65.32,0.027
144.67,65.54,0.027
144.69,65.76,0.027
144.71,65.97,0.027
144.73,66.19,0.027
144.75,66.41,0.027
144.78,66.63,0.027
144.80,66.84,0.027
144.82,67.06,0.027
144.84,67.28,0.027
144.86,67.49,0.027
144.88,67.71,0.027
144.91,67.93,0.027
144.93,68.14,0.027
144.95,68.36,0.027
144.97,68.58,0.027
144.99,68.79,0.027
145.02,69.01,0.027
145.04,69.23,0.027
145.06,69.45,0.027
145.08,69.66,0.027
145.10,69.88,0.027
145.12,70.10,0.027
145.15,70.31,0.027
145.17,70.53,0.027
145.19,70.75,0.027
145.21,70.96,0.027
145.23,71.18,0.027
145.25,71.40,0.027
145.28,71.61,0.027
145.30,71.83,0.027
145.32,72.05,0.027
145.34,72.26,0.027
145.36,72.48,0.027
145.38,72.70,0.027
145.40,72.91,0.027
145.43,73.13,0.027
145.45,73.35,0.027
145.47,73.56,0.027
145.49,73.78,0.027
145.51,74.00,0.027
145.53,74.22,0.027
145.56,74.43,0.027
145.58,74.65,0.027
145.60,74.87,0.027
145.62,75.08,0.027
145.64,75.30,0.027
145.67,75.52,0.027
145.69,75.73,0.027
145.71,75.95,0.027
145.73,76.17,0.027
145.75,76.38,0.027
145.77,76.60,0.027
145.80,76.82,0.027
145.82,77.03,0.027
145.84,77.25,0.027
145.86,77.47,0.027
145.88,77.68,0.027
145.90,77.90,0.027
145.93,78.12,0.027
145.95,78.34,0.027
145.97,78.55,0.027
145.99,78.77,0.027
146.01,78.99,0.027
146.03,79.20,0.027
146.05,79.42,0.027
146.08,79.64,0.027
146.10,79.85,0.027
146.12,80.07,0.027
146.14,80.29,0.027
146.16,80.50,0.027
146.18,80.72,0.027
146.21,80.94,0.027
146.23,81.15,0.027
146.25,81.37,0.027
146.27,81.59,0.027
146.29,81.80,0.027
146.32,82.02,0.027
146.34,82.24,0.027
146.36,82.45,0.027
146.38,82.67,0.027
146.40,82.89,0.027
146.42,83.11,0.027
146.45,83.32,0.027
146.47,83.54,0.027
146.49,83.76,0.027
146.51,83.97,0.027
146.53,84.19,0.027
146.55,84.41,0.027
146.58,84.62,0.027
146.60,84.84,0.027
146.62,85.06,0.027
146.64,85.27,0.027
146.66,85.49,0.027
146.68,85.71,0.027
146.70,85.92,0.027
146.73,86.14,0.027
146.75,86.36,0.027
146.77,86.58,0.027
146.79,86.79,0.027
146.81,87.01,0.027
146.83,87.23,0.027
146.86,87.44,0.027
146.88,87.66,0.027
146.90,87.88,0.027
146.92,88.09,0.027
146.94,88.31,0.027
146.97,88.53,0.027
146.99,88.74,0.027
147.01,88.96,0.027
147.03,89.18,0.027
147.05,89.39,0.027
147.07,89.61,0.027
147.10,89.83,0.027
147.12,90.04,0.027
147.14,90.26,0.027
147.16,90.48,0.027
147.18,90.70,0.027
147.20,90.91,0.027
147.23,91.13,0.027
147.25,91.35,0.027
147.27,91.56,0.027
147.29,91.78,0.027
147.31,92.00,0.027
147.33,92.21,0.027
147.35,92.43,0.027
147.38,92.65,0.027
147.40,92.86,0.027
147.42,93.08,0.027
147.44,93.30,0.028
147.46,93.52,0.028
147.48,93.73,0.028
147.51,93.95,0.028
147.53,94.17,0.028
147.55,94.38,0.028
147.57,94.60,0.028
147.59,94.82,0.028
147.62,95.03,0.028
147.64,95.25,0.028
147.66,95.47,0.028
147.68,95.68,0.028
147.70,95.90,0.028
147.72,96.12,0.028
147.75,96.33,0.028
147.77,96.55,0.028
147.79,96.77,0.028
147.81,96.98,0.028
147.83,97.20,0.028
147.85,97.42,0.028
147.88,97.63,0.028
147.90,97.85,0.028
147.92,98.07,0.028
147.94,98.29,0.028
147.96,98.50,0.028
147.98,98.72,0.028
148.00,98.94,0.028
148.03,99.15,0.028
148.05,99.37,0.028
148.07,99.59,0.028
148.09,99.80,0.028
148.11,100.02,0.028
148.13,100.24,0.028
148.16,100.45,0.028
148.18,100.67,0.028
148.20,100.89,0.028
148.22,101.11,0.028
148.24,101.32,0.028
148.27,101.54,0.028
148.29,101.76,0.028
148.31,101.97,0.028
148.33,102.19,0.028
148.35,102.41,0.028
148.37,102.62,0.028
148.40,102.84,0.028
148.42,103.06,0.028
148.44,103.27,0.028
148.46,103.49,0.028
148.48,103.71,0.028
148.50,103.92,0.028
148.53,104.14,0.028
148.55,104.36,0.028
148.57,104.57,0.028
148.59,104.79,0.028
148.61,105.01,0.028
148.63,105.22,0.028
148.65,105.44,0.028
148.68,105.66,0.028
148.70,105.88,0.028
148.72,106.09,0.028
148.74,106.31,0.028
148.76,106.53,0.028
148.78,106.74,0.028
148.81,106.96,0.028
148.83,107.18,0.028
148.85,107.39,0.028
148.87,107.61,0.028
148.89,107.83,0.028
148.92,108.04,0.028
148.94,108.26,0.028
148.96,108.48,0.028
148.98,108.70,0.028
149.00,108.91,0.028
149.02,109.13,0.028
149.05,109.35,0.028
149.07,109.56,0.028
149.09,109.78,0.028
149.11,110.00,0.028
149.13,110.21,0.028
149.15,110.43,0.028
149.18,110.65,0.028
149.20,110.86,0.028
149.22,111.08,0.028
149.24,111.30,0.028
149.26,111.51,0.028
149.28,111.73,0.028
149.30,111.95,0.028
149.33,112.16,0.028
149.35,112.38,0.028
149.37,112.60,0.028
149.39,112.82,0.028
149.41,113.03,0.028
149.43,113.25,0.028
149.46,113.47,0.028
149.48,113.68,0.028
149.50,113.90,0.028
149.52,114.12,0.028
149.54,114.33,0.028
149.57,114.55,0.028
149.59,114.77,0.028
149.61,114.98,0.028
149.63,115.20,0.028
149.65,115.42,0.028
149.67,115.63,0.028
149.70,115.85,0.028
149.72,116.07,0.028
149.74,116.28,0.028
149.76,116.50,0.028
149.78,116.72,0.028
149.80,116.93,0.028
149.83,117.15,0.028
149.85,117.37,0.028
149.87,117.59,0.028
149.89,117.80,0.028
149.91,118.02,0.028
149.93,118.24,0.028
149.95,118.45,0.028
149.98,118.67,0.028
150.00,118.89,0.028
150.02,119.11,0.028
150.04,119.32,0.028
150.06,119.54,0.028
150.08,119.76,0.028
150.11,119.97,0.028
150.13,120.19,0.028
150.15,120.41,0.029
150.17,120.62,0.029
150.19,120.84,0.029
150.22,121.06,0.029
150.24,121.27,0.029
150.26,121.49,0.029
150.28,121.71,0.029
150.30,121.92,0.029
150.32,122.14,0.029
150.35,122.36,0.029
150.37,122.57,0.029
150.39,122.79,0.029
150.41,123.01,0.029
150.43,123.23,0.029
150.45,123.44,0.029
150.48,123.66,0.029
150.50,123.88,0.029
150.52,124.09,0.029
150.54,124.31,0.029
150.56,124.53,0.029
150.58,124.74,0.029
150.60,124.96,0.029
150.63,125.18,0.029
150.65,125.39,0.029
150.67,125.61,0.029
150.69,125.83,0.029
150.71,126.04,0.029
150.73,126.26,0.029
150.76,126.48,0.029
150.78,126.69,0.029
150.80,126.91,0.029
150.82,127.13,0.029
150.84,127.34,0.029
150.87,127.56,0.029
150.89,127.78,0.029
150.91,127.99,0.029
150.93,128.21,0.029
150.95,128.43,0.029
150.97,128.64,0.029
151.00,128.86,0.029
151.02,129.08,0.029
151.04,129.30,0.029
151.06,129.51,0.029
151.08,129.73,0.029
151.10,129.95,0.029
151.13,130.16,0.029
151.15,130.38,0.029
151.17,130.60,0.029
151.19,130.81,0.029
151.21,131.03,0.029
151.23,131.25,0.029
151.25,131.46,0.029
151.28,131.68,0.029
151.30,131.90,0.029
151.32,132.11,0.029
151.34,132.33,0.029
151.36,132.55,0.029
151.38,132.77,0.029
151.41,132.98,0.029
151.43,133.20,0.029
151.45,133.42,0.029
151.47,133.63,0.029
151.49,133.85,0.029
151.52,134.07,0.029
151.54,134.28,0.029
151.56,134.50,0.029
151.58,134.72,0.029
151.60,134.93,0.029
151.62,135.15,0.029
151.65,135.37,0.029
151.67,135.58,0.029
151.69,135.80,0.029
151.71,136.02,0.029
151.73,136.23,0.029
151.75,136.45,0.029
151.78,136.67,0.029
151.80,136.89,0.029
151.82,137.10,0.029
151.84,137.32,0.029
151.86,137.54,0.029
151.88,137.75,0.029
151.90,137.97,0.029
151.93,138.19,0.029
151.95,138.40,0.029
151.97,138.62,0.029
151.99,138.84,0.029
152.01,139.05,0.029
152.03,139.27,0.029
152.06,139.49,0.029
152.08,139.70,0.029
152.10,139.92,0.029
152.12,140.14,0.029
152.14,140.35,0.029
152.17,140.57,0.029
152.19,140.79,0.029
152.21,141.00,0.029
152.23,141.22,0.029
152.25,141.44,0.029
152.27,141.66,0.029
152.30,141.87,0.029
152.32,142.09,0.029
152.34,142.31,0.029
152.36,142.52,0.029
152.38,142.74,0.029
152.40,142.96,0.029
152.43,143.17,0.029
152.45,143.39,0.029
152.47,143.61,0.029
152.49,143.82,0.029
152.51,144.04,0.029
152.53,144.26,0.029
152.55,144.48,0.029
152.58,144.69,0.029
152.60,144.91,0.029
152.62,145.13,0.029
152.64,145.34,0.029
152.66,145.56,0.029
152.68,145.78,0.029
152.71,145.99,0.029
152.73,146.21,0.029
152.75,146.43,0.029
152.77,146.64,0.029
152.79,146.86,0.029
152.82,147.08,0.029
152.84,147.29,0.029
152.86,147.51,0.029
152.88,147.73,0.029
152.90,147.94,0.029
152.92,148.16,0.029
152.95,148.38,0.029
152.97,148.59,0.029
152.99,148.81,0.029
153.01,149.03,0.029
153.03,149.24,0.029
153.05,149.46,0.029
153.08,149.68,0.029
153.10,149.89,0.029
153.12,150.11,0.029
153.14,150.33,0.029
153.16,150.55,0.029
153.18,150.76,0.029
153.20,150.98,0.029
153.23,151.20,0.029
153.25,151.41,0.029
153.27,151.63,0.029
153.29,151.85,0.029
153.31,152.06,0.029
153.33,152.28,0.029
153.36,152.50,0.029
153.38,152.71,0.029
153.40,152.93,0.029
153.42,153.15,0.029
153.44,153.36,0.029
153.47,153.58,0.030
153.49,153.80,0.030
153.51,154.02,0.030
153.53,154.23,0.030
153.55,154.45,0.030
153.57,154.67,0.030
153.60,154.88,0.030
153.62,155.10,0.030
153.64,155.32,0.030
153.66,155.53,0.030
153.68,155.75,0.030
153.70,155.97,0.030
153.73,156.18,0.030
153.75,156.40,0.030
153.77,156.62,0.030
153.79,156.83,0.030
153.81,157.05,0.030
153.83,157.27,0.030
153.85,157.48,0.030
153.88,157.70,0.030
153.90,157.92,0.030
153.92,158.13,0.030
153.94,158.35,0.030
153.96,158.57,0.030
153.98,158.78,0.030
154.01,159.00,0.030
154.03,159.22,0.030
154.05,159.43,0.030
154.07,159.65,0.030
154.09,159.87,0.030
154.12,160.08,0.030
154.14,160.30,0.030
154.16,160.52,0.030
154.18,160.73,0.030
154.20,160.95,0.030
154.22,161.17,0.030
154.25,161.39,0.030
154.27,161.60,0.030
154.29,161.82,0.030
154.31,162.04,0.030
154.33,162.25,0.030
154.35,162.47,0.030
154.38,162.69,0.030
154.40,162.90,0.030
154.42,163.12,0.030
154.44,163.34,0.030
154.46,163.55,0.030
154.48,163.77,0.030
154.50,163.99,0.030
154.53,164.21,0.030
154.55,164.42,0.030
154.57,164.64,0.030
154.59,164.86,0.030
154.61,165.07,0.030
154.63,165.29,0.030
154.66,165.51,0.030
154.68,165.72,0.030
154.70,165.94,0.030
154.72,166.16,0.030
154.74,166.37,0.030
154.77,166.59,0.030
154.79,166.81,0.030
154.81,167.02,0.030
154.83,167.24,0.030
154.85,167.46,0.030
154.87,167.67,0.030
154.90,167.89,0.030
154.92,168.11,0.030
154.94,168.33,0.030
154.96,168.54,0.030
154.98,168.76,0.030
155.00,168.98,0.030
155.03,169.19,0.030
155.05,169.41,0.030
155.07,169.63,0.030
155.09,169.84,0.030
155.11,170.06,0.030
155.13,170.28,0.030
155.15,170.49,0.030
155.18,170.71,0.030
155.20,170.93,0.030
155.22,171.14,0.030
155.24,171.36,0.030
155.26,171.58,0.030
155.28,171.79,0.030
155.31,172.01,0.030
155.33,172.23,0.030
155.35,172.45,0.030
155.37,172.66,0.030
155.39,172.88,0.030
155.42,173.09,0.030
155.44,173.31,0.030
155.46,173.53,0.030
155.48,173.74,0.030
155.50,173.96,0.030
155.52,174.18,0.030
155.55,174.40,0.030
155.57,174.61,0.030
155.59,174.83,0.030
155.61,175.05,0.030
155.63,175.26,0.030
155.65,175.48,0.030
155.68,175.70,0.030
155.70,175.91,0.030
155.72,176.13,0.030
155.74,176.35,0.030
155.76,176.56,0.030
155.78,176.78,0.030
155.80,177.00,0.030
155.83,177.21,0.030
155.85,177.43,0.030
155.87,177.65,0.030
155.89,177.86,0.030
155.91,178.08,0.030
155.93,178.30,0.030
155.96,178.51,0.030
155.98,178.73,0.030
156.00,178.95,0.030
156.02,179.17,0.030
156.04,179.38,0.030
156.07,179.60,0.030
156.09,179.82,0.030
156.11,180.03,0.030
156.13,180.25,0.030
156.15,180.47,0.030
156.17,180.68,0.030
156.20,180.90,0.030
156.22,181.12,0.030
156.24,181.33,0.030
156.26,181.55,0.030
156.28,181.77,0.030
156.30,181.98,0.030
156.33,182.20,0.030
156.35,182.42,0.030
156.37,182.64,0.030
156.39,182.85,0.030
156.41,183.07,0.030
156.43,183.29,0.030
156.45,183.50,0.030
156.48,183.72,0.030
156.50,183.94,0.030
156.52,184.15,0.030
156.54,184.37,0.030
156.56,184.59,0.030
156.58,184.80,0.030
156.61,185.02,0.030
156.63,185.24,0.030
156.65,185.45,0.030
156.67,185.67,0.030
156.69,185.89,0.030
156.72,186.10,0.030
156.74,186.32,0.030
156.76,186.54,0.030
156.78,186.75,0.030
156.80,186.97,0.030
156.82,187.19,0.030
156.85,187.41,0.030
156.87,187.62,0.030
156.89,187.84,0.030
156.91,188.06,0.030
156.93,188.27,0.030
156.95,188.49,0.030
156.98,188.71,0.030
157.00,188.92,0.030
157.02,189.14,0.030
157.04,189.36,0.030
157.06,189.57,0.030
157.08,189.79,0.030
157.10,190.01,0.031
157.13,190.22,0.031
157.15,190.44,0.031
157.17,190.66,0.031
157.19,190.88,0.031
157.21,191.09,0.031
157.23,191.31,0.031
157.26,191.52,0.031
157.28,191.74,0.031
157.30,191.96,0.031
157.32,192.18,0.031
157.34,192.39,0.031
157.37,192.61,0.031
157.39,192.83,0.031
157.41,193.04,0.031
157.43,193.26,0.031
157.45,193.48,0.031
157.47,193.69,0.031
157.50,193.91,0.031
157.52,194.13,0.031
157.54,194.34,0.031
157.56,194.56,0.031
157.58,194.78,0.031
157.60,195.00,0.031
157.63,195.21,0.031
157.65,195.43,0.031
157.67,195.64,0.031
157.69,195.86,0.031
157.71,196.08,0.031
157.73,196.29,0.031
157.75,196.51,0.031
157.78,196.73,0.031
157.80,196.94,0.031
157.82,197.16,0.031
157.84,197.38,0.031
157.86,197.59,0.031
157.88,197.81,0.031
157.91,198.03,0.031
157.93,198.25,0.031
157.95,198.46,0.031
157.97,198.68,0.031
157.99,198.90,0.031
158.02,199.11,0.031
158.04,199.33,0.031
158.06,199.55,0.031
158.08,199.76,0.031
158.10,199.98,0.031
158.12,200.20,0.031
158.15,200.41,0.031
158.17,200.63,0.031
158.19,200.85,0.031
158.21,201.06,0.031
158.23,201.28,0.031
158.25,201.50,0.031
158.28,201.72,0.031
158.30,201.93,0.031
158.32,202.15,0.031
158.34,202.36,0.031
158.36,202.58,0.031
158.38,202.80,0.031
158.40,203.02,0.031
158.43,203.23,0.031
158.45,203.45,0.031
158.47,203.67,0.031
158.49,203.88,0.031
158.51,204.10,0.031
158.53,204.32,0.031
158.56,204.53,0.031
158.58,204.75,0.031
158.60,204.97,0.031
158.62,205.18,0.031
158.64,205.40,0.031
158.67,205.62,0.031
158.69,205.83,0.031
158.71,206.05,0.031
158.73,206.27,0.031
158.75,206.48,0.031
158.77,206.70,0.031
158.80,206.92,0.031
158.82,207.13,0.031
158.84,207.35,0.031
158.86,207.57,0.031
158.88,207.79,0.031
158.90,208.00,0.031
158.93,208.22,0.031
158.95,208.44,0.031
158.97,208.65,0.031
158.99,208.87,0.031
159.01,209.09,0.031
159.03,209.30,0.031
159.05,209.52,0.031
159.08,209.74,0.031
159.10,209.95,0.031
159.12,210.17,0.031
159.14,210.39,0.031
159.16,210.60,0.031
159.18,210.82,0.031
159.21,211.04,0.031
159.23,211.25,0.031
159.25,211.47,0.031
159.27,211.69,0.031
159.29,211.90,0.031
159.32,212.12,0.031
159.34,212.34,0.031
159.36,212.55,0.031
159.38,212.77,0.031
159.40,212.99,0.031
159.42,213.20,0.031
159.45,213.42,0.031
159.47,213.64,0.031
159.49,213.86,0.031
159.51,214.07,0.031
159.53,214.29,0.031
159.55,214.51,0.031
159.58,214.72,0.031
159.60,214.94,0.031
159.62,215.16,0.031
159.64,215.38,0.031
159.66,215.60,0.031
159.68,215.81,0.031
159.70,216.03,0.031
159.73,216.25,0.031
159.75,216.47,0.031
159.77,216.68,0.031
159.79,216.90,0.031
159.81,217.12,0.031
159.83,217.33,0.031
159.86,217.55,0.031
159.88,217.77,0.031
159.90,217.98,0.031
159.92,218.20,0.031
159.94,218.41,0.031
159.97,218.63,0.031
159.99,218.85,0.031
160.01,219.06,0.031
160.03,219.28,0.031
160.05,219.50,0.031
160.07,219.71,0.031
160.10,219.93,0.031
160.12,220.15,0.031
160.14,220.36,0.031
160.16,220.58,0.031
160.18,220.80,0.031
160.20,221.01,0.031
160.23,221.23,0.031
160.25,221.45,0.031
160.27,221.66,0.031
160.29,221.88,0.031
160.31,222.10,0.031
160.33,222.31,0.031
160.35,222.53,0.031
160.38,222.74,0.031
160.40,222.96,0.031
160.42,223.18,0.031
160.44,223.40,0.031
160.46,223.61,0.031
160.48,223.83,0.031
160.51,224.05,0.031
160.53,224.26,0.031
160.55,224.48,0.031
160.57,224.70,0.031
160.59,224.91,0.031
160.62,225.13,0.031
160.64,225.35,0.031
160.66,225.56,0.031
160.68,225.78,0.031
160.70,226.00,0.031
160.72,226.21,0.031
160.75,226.43,0.031
160.77,226.65,0.031
160.79,226.86,0.031
160.81,227.08,0.031
160.83,227.30,0.031
160.85,227.51,0.031
160.88,227.73,0.031
160.90,227.95,0.031
160.92,228.16,0.031
160.94,228.38,0.031
160.96,228.60,0.031
160.98,228.81,0.031
161.00,229.03,0.031
161.03,229.25,0.031
161.05,229.47,0.031
161.07,229.68,0.031
161.09,229.90,0.031
161.11,230.12,0.031
161.13,230.33,0.031
161.16,230.55,0.031
161.18,230.76,0.031
161.20,230.98,0.031
161.22,231.20,0.031
161.24,231.42,0.031
161.27,231.63,0.031
161.29,231.85,0.031
161.31,232.07,0.031
161.33,232.28,0.031
161.35,232.50,0.031
161.37,232.72,0.031
161.40,232.93,0.031
161.42,233.15,0.031
161.44,233.37,0.031
161.46,233.58,0.031
161.48,233.80,0.031
161.50,234.02,0.031
161.53,234.23,0.031
161.55,234.45,0.031
161.57,234.67,0.031
161.59,234.88,0.031
161.61,235.10,0.031
161.63,235.32,0.031
161.65,235.53,0.031
161.68,235.75,0.031
161.70,235.97,0.031
161.72,236.18,0.031
161.74,236.40,0.031
161.76,236.62,0.031
161.78,236.83,0.031
161.81,237.05,0.032
161.83,237.27,0.032
161.85,237.49,0.032
161.87,237.70,0.032
161.89,237.92,0.032
161.92,238.14,0.032
161.94,238.35,0.032
161.96,238.57,0.032
161.98,238.79,0.032
162.00,239.00,0.032
162.02,239.22,0.032
162.05,239.44,0.032
162.07,239.65,0.032
162.09,239.87,0.032
162.11,240.09,0.032
162.13,240.31,0.032
162.15,240.52,0.032
162.18,240.74,0.032
162.20,240.96,0.031
162.22,241.17,0.031
162.24,241.39,0.031
162.26,241.60,0.032
162.28,241.82,0.032
162.30,242.04,0.032
162.33,242.25,0.032
162.35,242.47,0.032
162.37,242.69,0.032
162.39,242.91,0.032
162.41,243.12,0.032
162.43,243.34,0.032
162.46,243.56,0.032
162.48,243.77,0.032
162.50,243.99,0.032
162.52,244.21,0.032
162.54,244.42,0.032
162.57,244.64,0.032
162.59,244.86,0.032
162.61,245.07,0.032
162.63,245.29,0.032
162.65,245.51,0.032
162.67,245.72,0.032
162.70,245.94,0.032
162.72,246.16,0.032
162.74,246.37,0.032
162.76,246.59,0.032
162.78,246.81,0.032
162.80,247.02,0.032
162.83,247.24,0.032
162.85,247.46,0.032
162.87,247.67,0.032
162.89,247.89,0.032
162.91,248.11,0.032
162.93,248.32,0.032
162.95,248.54,
162.98,248.76,
162.99,,