File: DSC/Olivia/2025_08_05_TS_Sapphire_n60C_250C_10Cmin_x3.csv
Filename,2025_08_05_TS_Sapphire_n60C_250C_10Cmin_x3
Instrument name,DSC2A-00468 (192.168.1.100)
Operator,Yarger
rundate,8/5/2025
Sample name,2025_08_05_TS_Sapphire_n60C_250C_10Cmin_x3
proceduresegments,Data Off ; Equilibrate -60.00 °C; Data On ; Ramp 10.00 °C/min to 250.00 °C; Data Off ; Isothermal 2.0 min; Data On ; Ramp 10.00 °C/min to -60.00 °C; Data Off ; Isothermal 2.0 min; Data On ; Ramp 10.00 °C/min to 250.00 °C; Data Off ; Isothermal 2.0 min; Data On ; Ramp 10.00 °C/min to -60.00 °C; Data Off ; Isothermal 2.0 min; Data On ; Ramp 10.00 °C/min to 250.00 °C
[File Parameters]
Run date,8/5/2025 6:54:30 PM
Trios version,5.1.1.46572
Original File Name,
Current File Name,D:\DSC2500\JYarger\2025_08_05_TS_Sapphire_n60C_250C_10Cmin_x3.tri
[Procedure]
Procedure Name,Sapphire_TS_Pans_n60C_250C_10Cmin_x3
Sample Name,2025_08_05_TS_Sapphire_n60C_250C_10Cmin_x3
Sample Mass,5.38 mg
Reference Sample Mass,0 mg
Pan Mass,32.9 mg
Pan Number,6
Reference Pan Mass,32.52 mg
Reference Pan Number,37
Pan Type,Aluminum
Comments,Thermal support Al pans/lids. DSC_Samples_A2_Tray_July2025 google sheet.
Project Name,Calibration
Operator,Yarger
Test,Custom
Unload Max Temperature,30
Unload Min Temperature,30
Load Max Temperature,30
Load Min Temperature,30
Stop on Gas Flow Error,Yes
[Signal List]
Signal #1,Time (min)
Signal #2,Temperature (°C)
Signal #3,Heat Flow (mW)
Signal #4,Delta T (µV)
Signal #5,Delta Tzero (µV)
Signal #6,Tzero Temperature (°C)
Signal #7,Cell Purge (mL/min)
Signal #8,Heater Temp (°C)
Signal #9,Power Delivered (W)
Signal #10,Reference Junction Temperature (°C)
Signal #11,Flange Temperature (°C)
Signal #12,Heat Flow Phase (rad)
Signal #13,Total Heat Capacity (J/°C)
Signal #14,Heat Capacity (J/°C)
[Configuration]
Company Name,ASU
Instrument Name,DSC2A-00468
Instrument Type,DSC2500
Serial Number,DSC2A-00468
IP,192.168.1.100
Location of Instrument,MRRC
DisplayType,Unknown
Sample Interval ,0.1 s/pt
Selected Heat Flow,T4P
Exotherm Direction,Down
Cell Serial,DRC2-00792
Lid Type,Standard
Cooler,RCS 90
Leave Cooler on at End of Sequence,On
Gas 2,Nitrogen
Gas Selected,Channel 1
Flow Rate,50 mL/min
Secondary Purge,On
Licensed Heat Flow,Heat Flow T4P
Modulation Licensed,Yes
[Versions]
Common IDD Version,1
Cortex Version,VER 2.10.2.31
Driver,5.0.0.6
GDM Version,1.0.3.3
TouchscreenVersion,1.0.0.16145
FEP Version,1.2.1.21
FEP Bootloader,2.0.0.5
AutoSampler Version,2.1.1.26
Auto Sampler Bootloader,2.0.0.5
FCM Version,1.1.0.3
FCM Bootloader,2.0.0.5
[Experiment Logs]
Experiment Log Entry # 2,Air Cool is off.
Experiment Log Entry # 4,Data On set to 0
Experiment Log Entry # 6,Equilibrate Segment -60 (C) Started
Experiment Log Entry # 8,Data On set to 1
Experiment Log Entry # 10,Ramp Segment 10 C/min to 250 Started
Experiment Log Entry # 12,Data On set to 0
Experiment Log Entry # 14,Isothermal Segment 2 min started
Experiment Log Entry # 16,Data On set to 1
Experiment Log Entry # 18,Ramp Segment 10 C/min to -60 Started
Experiment Log Entry # 20,Data On set to 0
Experiment Log Entry # 22,Isothermal Segment 2 min started
Experiment Log Entry # 24,Data On set to 1
Experiment Log Entry # 26,Ramp Segment 10 C/min to 250 Started
Experiment Log Entry # 28,Data On set to 0
Experiment Log Entry # 30,Isothermal Segment 2 min started
Experiment Log Entry # 32,Data On set to 1
Experiment Log Entry # 34,Ramp Segment 10 C/min to -60 Started
Experiment Log Entry # 36,Data On set to 0
Experiment Log Entry # 38,Isothermal Segment 2 min started
Experiment Log Entry # 40,Data On set to 1
Experiment Log Entry # 42,Ramp Segment 10 C/min to 250 Started
[Method Log]
Method Log Entry # 1,Data Off
Method Log Entry # 2,Equilibrate -60 °C
Method Log Entry # 3,Data On
Method Log Entry # 4,(Ramp 247534) Ramp 10 °C/minute to 250 °C
Method Log Entry # 5,Data Off
Method Log Entry # 6,Isothermal 2 minutes
Method Log Entry # 7,Data On
Method Log Entry # 8,(Ramp 247538) Ramp 10 °C/minute to -60 °C
Method Log Entry # 9,Data Off
Method Log Entry # 10,Isothermal 2 minutes
Method Log Entry # 11,Data On
Method Log Entry # 12,(Ramp 247542) Ramp 10 °C/minute to 250 °C
Method Log Entry # 13,Data Off
Method Log Entry # 14,Isothermal 2 minutes
Method Log Entry # 15,Data On
Method Log Entry # 16,(Ramp 247546) Ramp 10 °C/minute to -60 °C
Method Log Entry # 17,Data Off
Method Log Entry # 18,Isothermal 2 minutes
Method Log Entry # 19,Data On
Method Log Entry # 20,(Ramp 247550) Ramp 10 °C/minute to 250 °C
Cell Serial,DRC2-00792
[T1 Calibration]
Slope,-0.008529666
Offset,9.636258
Initial Temperature,98.23
GUID,f8bfdadc-4977-4fdf-ba6d-0ba9134940c3
[TZero Calibration]
Date Applied,11/29/2022 4:06:13 PM
Description,From -89.059 °C to 396.009 °C at 20.000°C/min
Gas Type,Nitrogen
Pan Type,None
Source Files 1,C:\Users\yargerlab\Desktop\DSC Data\General\TZero_calibration_11_29_22_2nd(2).tri
Source Files 2,C:\Users\yargerlab\Desktop\DSC Data\General\TZero_calibration_11_29_22_2nd(3).tri
Delta T Offset,13.05235
Delta T Slope,-0.007271007
Delta T0 Offset,-13.69128
Delta T0 Slope,0.06063341
[Temperature Calibration]
Date Applied,11/29/2022 7:12:28 PM
Description,From 106.590 °C to 186.590 °C at 10.000°C/min
Gas Type,Nitrogen
Pan Type,Tzero Aluminum Hermetic
Source Files 1,C:\Users\yargerlab\Desktop\DSC Data\General\Indium(6).tri
Measured 1,157.391
Known 1,156.598
[Cell Constant Calibration]
Date Applied,11/29/2022 7:12:29 PM
Description,From 106.590 °C to 186.590 °C at 10.000°C/min
Gas Type,Nitrogen
Pan Type,Tzero Aluminum Hermetic
Source Files 1,C:\Users\yargerlab\Desktop\DSC Data\General\Indium(6).tri
T4P KCell,1.006051
Onset Slope,63.26126 mW/°C
[Direct Cp Calibration]
Date Applied,11/30/2022 11:04:51 AM
Description,From -79.983 °C to 298.409 °C at 10.000°C/min
Gas Type,Nitrogen
Pan Type,Tzero Aluminum Hermetic
Source Files 1,C:\Users\yargerlab\Desktop\DSC Data\General\Sapphire_Heat_Capacity_11_30_22.tri
[Rev Cp Calibration]
Date Applied,11/30/2022 1:58:51 PM
Description,From -79.996 °C to 292.812 °C at 3.000°C/min
Gas Type,Nitrogen
Pan Type,Tzero Aluminum Hermetic
Source Files 1,C:\Users\yargerlab\Desktop\DSC Data\General\Sapphire_MDSC_Calibration_11_30_22.tri
[step]
Ramp 10.00 °C/min to 250.00 °C
Time,Temperature,Heat Flow (Normalized)
min,°C,W/g
0.00,-59.81,-0.039
0.02,-59.82,-0.036
0.04,-59.82,-0.034
0.07,-59.79,-0.040
0.09,-59.74,-0.060
0.11,-59.65,-0.067
0.13,-59.53,-0.064
0.15,-59.38,-0.049
0.17,-59.21,-0.023
0.19,-59.03,0.002
0.22,-58.84,0.025
0.24,-58.64,0.046
0.26,-58.44,0.062
0.28,-58.23,0.073
0.30,-58.03,0.083
0.33,-57.82,0.090
0.35,-57.61,0.095
0.37,-57.40,0.099
0.39,-57.19,0.101
0.41,-56.98,0.103
0.43,-56.77,0.104
0.45,-56.56,0.106
0.48,-56.35,0.106
0.50,-56.13,0.107
0.52,-55.92,0.108
0.54,-55.71,0.108
0.56,-55.50,0.109
0.58,-55.28,0.109
0.61,-55.07,0.110
0.63,-54.85,0.110
0.65,-54.64,0.110
0.67,-54.43,0.111
0.69,-54.21,0.111
0.72,-54.00,0.112
0.74,-53.78,0.112
0.76,-53.57,0.112
0.78,-53.36,0.113
0.80,-53.14,0.113
0.82,-52.92,0.113
0.85,-52.71,0.114
0.87,-52.49,0.114
0.89,-52.28,0.114
0.91,-52.06,0.115
0.93,-51.85,0.115
0.95,-51.63,0.115
0.98,-51.42,0.116
1.00,-51.20,0.116
1.02,-50.99,0.116
1.04,-50.77,0.116
1.06,-50.55,0.117
1.08,-50.34,0.117
1.11,-50.12,0.117
1.13,-49.91,0.117
1.15,-49.69,0.117
1.17,-49.47,0.118
1.19,-49.26,0.118
1.21,-49.05,0.118
1.23,-48.83,0.118
1.26,-48.61,0.118
1.28,-48.40,0.118
1.30,-48.18,0.119
1.32,-47.96,0.119
1.34,-47.75,0.119
1.37,-47.53,0.119
1.39,-47.31,0.119
1.41,-47.10,0.119
1.43,-46.88,0.119
1.45,-46.66,0.119
1.47,-46.45,0.120
1.49,-46.23,0.120
1.52,-46.02,0.120
1.54,-45.80,0.120
1.56,-45.58,0.120
1.58,-45.36,0.120
1.60,-45.15,0.120
1.63,-44.93,0.120
1.65,-44.71,0.120
1.67,-44.50,0.120
1.69,-44.28,0.120
1.71,-44.06,0.121
1.73,-43.85,0.121
1.76,-43.63,0.121
1.78,-43.41,0.121
1.80,-43.20,0.121
1.82,-42.98,0.121
1.84,-42.76,0.121
1.86,-42.55,0.121
1.88,-42.33,0.121
1.91,-42.11,0.121
1.93,-41.90,0.121
1.95,-41.68,0.121
1.97,-41.46,0.121
1.99,-41.25,0.121
2.02,-41.03,0.121
2.04,-40.81,0.121
2.06,-40.59,0.121
2.08,-40.38,0.121
2.10,-40.16,0.122
2.12,-39.94,0.122
2.14,-39.73,0.122
2.17,-39.51,0.122
2.19,-39.29,0.122
2.21,-39.08,0.122
2.23,-38.86,0.122
2.25,-38.64,0.122
2.28,-38.43,0.122
2.30,-38.21,0.122
2.32,-37.99,0.122
2.34,-37.78,0.122
2.36,-37.56,0.122
2.38,-37.34,0.122
2.41,-37.12,0.122
2.43,-36.91,0.122
2.45,-36.69,0.122
2.47,-36.47,0.122
2.49,-36.26,0.122
2.51,-36.04,0.122
2.54,-35.82,0.122
2.56,-35.61,0.122
2.58,-35.39,0.122
2.60,-35.17,0.122
2.62,-34.95,0.122
2.64,-34.74,0.122
2.66,-34.52,0.122
2.69,-34.30,0.122
2.71,-34.09,0.122
2.73,-33.87,0.122
2.75,-33.65,0.122
2.77,-33.44,0.122
2.79,-33.22,0.122
2.82,-33.00,0.122
2.84,-32.79,0.122
2.86,-32.57,0.122
2.88,-32.35,0.122
2.90,-32.13,0.123
2.93,-31.92,0.123
2.95,-31.70,0.123
2.97,-31.48,0.123
2.99,-31.27,0.123
3.01,-31.05,0.123
3.03,-30.83,0.123
3.06,-30.61,0.123
3.08,-30.40,0.123
3.10,-30.18,0.123
3.12,-29.96,0.123
3.14,-29.75,0.123
3.16,-29.53,0.123
3.19,-29.31,0.123
3.21,-29.10,0.123
3.23,-28.88,0.123
3.25,-28.66,0.123
3.27,-28.45,0.123
3.29,-28.23,0.123
3.31,-28.01,0.123
3.34,-27.80,0.123
3.36,-27.58,0.123
3.38,-27.36,0.123
3.40,-27.14,0.123
3.42,-26.93,0.123
3.44,-26.71,0.123
3.47,-26.50,0.123
3.49,-26.28,0.123
3.51,-26.06,0.123
3.53,-25.84,0.123
3.55,-25.63,0.123
3.58,-25.41,0.123
3.60,-25.20,0.123
3.62,-24.98,0.123
3.64,-24.76,0.123
3.66,-24.54,0.123
3.68,-24.33,0.123
3.71,-24.11,0.123
3.73,-23.89,0.123
3.75,-23.67,0.123
3.77,-23.46,0.124
3.79,-23.24,0.124
3.81,-23.02,0.124
3.84,-22.81,0.124
3.86,-22.59,0.124
3.88,-22.37,0.124
3.90,-22.15,0.124
3.92,-21.94,0.124
3.94,-21.72,0.124
3.96,-21.50,0.124
3.99,-21.29,0.124
4.01,-21.07,0.124
4.03,-20.85,0.124
4.05,-20.64,0.124
4.07,-20.42,0.124
4.09,-20.20,0.124
4.12,-19.99,0.124
4.14,-19.77,0.124
4.16,-19.55,0.124
4.18,-19.34,0.124
4.20,-19.12,0.124
4.23,-18.90,0.124
4.25,-18.68,0.124
4.27,-18.47,0.124
4.29,-18.25,0.124
4.31,-18.03,0.124
4.33,-17.82,0.124
4.35,-17.60,0.124
4.38,-17.38,0.125
4.40,-17.17,0.125
4.42,-16.95,0.125
4.44,-16.73,0.125
4.46,-16.51,0.125
4.49,-16.30,0.125
4.51,-16.08,0.125
4.53,-15.86,0.125
4.55,-15.65,0.125
4.57,-15.43,0.125
4.59,-15.21,0.125
4.61,-15.00,0.125
4.64,-14.78,0.125
4.66,-14.56,0.125
4.68,-14.35,0.125
4.70,-14.13,0.125
4.72,-13.91,0.125
4.75,-13.69,0.125
4.77,-13.48,0.125
4.79,-13.26,0.125
4.81,-13.04,0.125
4.83,-12.83,0.125
4.85,-12.61,0.125
4.88,-12.39,0.125
4.90,-12.18,0.125
4.92,-11.96,0.125
4.94,-11.74,0.125
4.96,-11.53,0.125
4.98,-11.31,0.125
5.00,-11.09,0.125
5.03,-10.87,0.126
5.05,-10.66,0.126
5.07,-10.44,0.126
5.09,-10.22,0.126
5.11,-10.01,0.126
5.14,-9.79,0.126
5.16,-9.57,0.126
5.18,-9.36,0.126
5.20,-9.14,0.126
5.22,-8.92,0.126
5.24,-8.71,0.126
5.26,-8.49,0.126
5.29,-8.27,0.126
5.31,-8.06,0.126
5.33,-7.84,0.126
5.35,-7.62,0.126
5.37,-7.40,0.126
5.40,-7.19,0.126
5.42,-6.97,0.126
5.44,-6.75,0.126
5.46,-6.54,0.127
5.48,-6.32,0.127
5.50,-6.10,0.127
5.53,-5.89,0.127
5.55,-5.67,0.127
5.57,-5.45,0.127
5.59,-5.24,0.127
5.61,-5.02,0.127
5.63,-4.80,0.127
5.65,-4.58,0.127
5.68,-4.37,0.127
5.70,-4.15,0.127
5.72,-3.93,0.127
5.74,-3.72,0.127
5.76,-3.50,0.127
5.79,-3.28,0.127
5.81,-3.07,0.127
5.83,-2.85,0.127
5.85,-2.63,0.127
5.87,-2.41,0.128
5.89,-2.20,0.128
5.91,-1.98,0.128
5.94,-1.76,0.128
5.96,-1.55,0.128
5.98,-1.33,0.128
6.00,-1.11,0.128
6.02,-0.90,0.128
6.05,-0.68,0.128
6.07,-0.46,0.128
6.09,-0.25,0.128
6.11,-0.03,0.128
6.13,0.19,0.128
6.15,0.40,0.128
6.18,0.62,0.128
6.20,0.84,0.128
6.22,1.06,0.128
6.24,1.27,0.128
6.26,1.49,0.128
6.28,1.71,0.128
6.30,1.92,0.128
6.33,2.14,0.128
6.35,2.36,0.128
6.37,2.57,0.128
6.39,2.79,0.128
6.41,3.01,0.129
6.44,3.23,0.129
6.46,3.44,0.129
6.48,3.66,0.129
6.50,3.88,0.129
6.52,4.09,0.129
6.54,4.31,0.129
6.56,4.53,0.129
6.59,4.74,0.129
6.61,4.96,0.129
6.63,5.18,0.129
6.65,5.39,0.129
6.67,5.61,0.129
6.70,5.83,0.129
6.72,6.04,0.129
6.74,6.26,0.129
6.76,6.48,0.129
6.78,6.69,0.129
6.80,6.91,0.130
6.83,7.13,0.130
6.85,7.35,0.130
6.87,7.56,0.130
6.89,7.78,0.130
6.91,8.00,0.130
6.93,8.21,0.130
6.95,8.43,0.130
6.98,8.65,0.130
7.00,8.86,0.130
7.02,9.08,0.130
7.04,9.30,0.130
7.06,9.51,0.130
7.09,9.73,0.130
7.11,9.95,0.130
7.13,10.17,0.130
7.15,10.38,0.130
7.17,10.60,0.130
7.19,10.82,0.130
7.21,11.03,0.130
7.24,11.25,0.130
7.26,11.47,0.131
7.28,11.68,0.131
7.30,11.90,0.131
7.32,12.12,0.131
7.35,12.34,0.131
7.37,12.55,0.131
7.39,12.77,0.131
7.41,12.99,0.131
7.43,13.20,0.131
7.45,13.42,0.131
7.48,13.64,0.131
7.50,13.85,0.131
7.52,14.07,0.131
7.54,14.29,0.131
7.56,14.50,0.131
7.58,14.72,0.131
7.60,14.94,0.131
7.63,15.16,0.131
7.65,15.37,0.132
7.67,15.59,0.132
7.69,15.80,0.132
7.71,16.02,0.132
7.74,16.24,0.132
7.76,16.46,0.132
7.78,16.67,0.132
7.80,16.89,0.132
7.82,17.11,0.132
7.84,17.32,0.132
7.86,17.54,0.132
7.89,17.76,0.132
7.91,17.97,0.132
7.93,18.19,0.132
7.95,18.41,0.132
7.97,18.62,0.132
8.00,18.84,0.132
8.02,19.06,0.132
8.04,19.27,0.132
8.06,19.49,0.133
8.08,19.71,0.133
8.10,19.93,0.133
8.13,20.14,0.133
8.15,20.36,0.133
8.17,20.58,0.133
8.19,20.79,0.133
8.21,21.01,0.133
8.23,21.23,0.133
8.25,21.44,0.133
8.28,21.66,0.133
8.30,21.88,0.133
8.32,22.09,0.133
8.34,22.31,0.133
8.36,22.53,0.133
8.39,22.74,0.133
8.41,22.96,0.133
8.43,23.18,0.134
8.45,23.40,0.134
8.47,23.61,0.134
8.49,23.83,0.134
8.51,24.04,0.134
8.54,24.26,0.134
8.56,24.48,0.134
8.58,24.70,0.134
8.60,24.91,0.134
8.62,25.13,0.134
8.65,25.35,0.134
8.67,25.56,0.134
8.69,25.78,0.134
8.71,26.00,0.134
8.73,26.21,0.134
8.75,26.43,0.134
8.78,26.65,0.134
8.80,26.86,0.135
8.82,27.08,0.135
8.84,27.30,0.135
8.86,27.52,0.135
8.88,27.73,0.135
8.90,27.95,0.135
8.93,28.17,0.135
8.95,28.38,0.135
8.97,28.60,0.135
8.99,28.82,0.135
9.01,29.03,0.135
9.03,29.25,0.135
9.06,29.47,0.135
9.08,29.68,0.135
9.10,29.90,0.135
9.12,30.12,0.135
9.14,30.33,0.135
9.17,30.55,0.135
9.19,30.77,0.136
9.21,30.98,0.136
9.23,31.20,0.136
9.25,31.42,0.136
9.27,31.64,0.136
9.30,31.85,0.136
9.32,32.07,0.136
9.34,32.29,0.136
9.36,32.51,0.136
9.38,32.72,0.136
9.40,32.94,0.136
9.43,33.16,0.136
9.45,33.37,0.136
9.47,33.59,0.136
9.49,33.81,0.136
9.51,34.02,0.136
9.53,34.24,0.136
9.55,34.46,0.136
9.58,34.67,0.136
9.60,34.89,0.137
9.62,35.11,0.137
9.64,35.32,0.137
9.66,35.54,0.137
9.68,35.76,0.137
9.71,35.98,0.137
9.73,36.19,0.137
9.75,36.41,0.137
9.77,36.63,0.137
9.79,36.84,0.137
9.82,37.06,0.137
9.84,37.28,0.137
9.86,37.49,0.137
9.88,37.71,0.137
9.90,37.93,0.137
9.92,38.14,0.137
9.95,38.36,0.137
9.97,38.58,0.137
9.99,38.79,0.137
10.01,39.01,0.137
10.03,39.23,0.137
10.05,39.45,0.137
10.08,39.66,0.138
10.10,39.88,0.138
10.12,40.10,0.138
10.14,40.31,0.138
10.16,40.53,0.138
10.18,40.75,0.138
10.20,40.96,0.138
10.23,41.18,0.138
10.25,41.40,0.138
10.27,41.62,0.138
10.29,41.83,0.138
10.31,42.05,0.138
10.33,42.27,0.138
10.36,42.48,0.138
10.38,42.70,0.138
10.40,42.92,0.138
10.42,43.13,0.138
10.44,43.35,0.138
10.47,43.57,0.139
10.49,43.78,0.139
10.51,44.00,0.139
10.53,44.22,0.139
10.55,44.43,0.139
10.57,44.65,0.139
10.60,44.87,0.139
10.62,45.09,0.139
10.64,45.30,0.139
10.66,45.52,0.139
10.68,45.74,0.139
10.70,45.95,0.139
10.73,46.17,0.139
10.75,46.39,0.139
10.77,46.60,0.139
10.79,46.82,0.139
10.81,47.04,0.139
10.83,47.25,0.139
10.85,47.47,0.139
10.88,47.69,0.140
10.90,47.91,0.140
10.92,48.12,0.140
10.94,48.34,0.140
10.96,48.55,0.140
10.98,48.77,0.140
11.01,48.99,0.140
11.03,49.21,0.140
11.05,49.42,0.140
11.07,49.64,0.140
11.09,49.86,0.140
11.12,50.07,0.140
11.14,50.29,0.140
11.16,50.51,0.140
11.18,50.72,0.140
11.20,50.94,0.140
11.22,51.16,0.140
11.25,51.37,0.140
11.27,51.59,0.141
11.29,51.81,0.141
11.31,52.03,0.141
11.33,52.24,0.141
11.35,52.46,0.141
11.38,52.68,0.141
11.40,52.89,0.141
11.42,53.11,0.141
11.44,53.33,0.141
11.46,53.54,0.141
11.48,53.76,0.141
11.50,53.98,0.141
11.53,54.19,0.141
11.55,54.41,0.141
11.57,54.63,0.141
11.59,54.84,0.141
11.61,55.06,0.141
11.63,55.28,0.141
11.66,55.49,0.141
11.68,55.71,0.141
11.70,55.93,0.142
11.72,56.15,0.142
11.74,56.36,0.142
11.77,56.58,0.142
11.79,56.80,0.142
11.81,57.01,0.142
11.83,57.23,0.142
11.85,57.45,0.142
11.87,57.66,0.142
11.90,57.88,0.142
11.92,58.10,0.142
11.94,58.32,0.142
11.96,58.53,0.142
11.98,58.75,0.142
12.00,58.97,0.142
12.03,59.18,0.142
12.05,59.40,0.142
12.07,59.62,0.142
12.09,59.83,0.142
12.11,60.05,0.142
12.13,60.27,0.143
12.15,60.48,0.143
12.18,60.70,0.143
12.20,60.92,0.143
12.22,61.14,0.143
12.24,61.35,0.143
12.26,61.57,0.143
12.28,61.78,0.143
12.31,62.00,0.143
12.33,62.22,0.143
12.35,62.44,0.143
12.37,62.65,0.143
12.39,62.87,0.143
12.42,63.09,0.143
12.44,63.30,0.143
12.46,63.52,0.143
12.48,63.74,0.143
12.50,63.95,0.143
12.52,64.17,0.143
12.55,64.39,0.143
12.57,64.60,0.143
12.59,64.82,0.144
12.61,65.04,0.144
12.63,65.25,0.144
12.65,65.47,0.144
12.68,65.69,0.144
12.70,65.90,0.144
12.72,66.12,0.144
12.74,66.34,0.144
12.76,66.56,0.144
12.78,66.77,0.144
12.80,66.99,0.144
12.83,67.21,0.144
12.85,67.42,0.144
12.87,67.64,0.144
12.89,67.86,0.144
12.91,68.07,0.144
12.93,68.29,0.144
12.96,68.51,0.144
12.98,68.72,0.144
13.00,68.94,0.145
13.02,69.16,0.145
13.04,69.38,0.145
13.07,69.59,0.145
13.09,69.81,0.145
13.11,70.03,0.145
13.13,70.24,0.145
13.15,70.46,0.145
13.17,70.68,0.145
13.20,70.89,0.145
13.22,71.11,0.145
13.24,71.33,0.145
13.26,71.55,0.145
13.28,71.76,0.145
13.30,71.98,0.145
13.33,72.20,0.145
13.35,72.41,0.145
13.37,72.63,0.145
13.39,72.85,0.145
13.41,73.06,0.145
13.43,73.28,0.145
13.45,73.50,0.146
13.48,73.71,0.146
13.50,73.93,0.146
13.52,74.15,0.146
13.54,74.36,0.146
13.56,74.58,0.146
13.58,74.80,0.146
13.61,75.02,0.146
13.63,75.23,0.146
13.65,75.45,0.146
13.67,75.67,0.146
13.69,75.88,0.146
13.72,76.10,0.146
13.74,76.32,0.146
13.76,76.53,0.146
13.78,76.75,0.146
13.80,76.97,0.146
13.82,77.19,0.146
13.85,77.40,0.146
13.87,77.62,0.146
13.89,77.84,0.146
13.91,78.05,0.147
13.93,78.27,0.147
13.95,78.49,0.147
13.98,78.70,0.147
14.00,78.92,0.147
14.02,79.14,0.147
14.04,79.35,0.147
14.06,79.57,0.147
14.08,79.79,0.147
14.10,80.01,0.147
14.13,80.22,0.147
14.15,80.44,0.147
14.17,80.66,0.147
14.19,80.87,0.147
14.21,81.09,0.147
14.23,81.31,0.147
14.26,81.52,0.147
14.28,81.74,0.147
14.30,81.96,0.147
14.32,82.17,0.147
14.34,82.39,0.147
14.37,82.61,0.147
14.39,82.82,0.147
14.41,83.04,0.147
14.43,83.26,0.147
14.45,83.47,0.147
14.47,83.69,0.147
14.50,83.91,0.148
14.52,84.12,0.147
14.54,84.34,0.147
14.56,84.56,0.148
14.58,84.77,0.148
14.60,84.99,0.148
14.63,85.21,0.148
14.65,85.42,0.148
14.67,85.64,0.148
14.69,85.86,0.148
14.71,86.07,0.148
14.73,86.29,0.148
14.75,86.51,0.148
14.78,86.73,0.148
14.80,86.94,0.148
14.82,87.16,0.148
14.84,87.38,0.148
14.86,87.59,0.148
14.88,87.81,0.148
14.91,88.03,0.148
14.93,88.24,0.148
14.95,88.46,0.148
14.97,88.68,0.148
14.99,88.89,0.148
15.02,89.11,0.148
15.04,89.33,0.148
15.06,89.54,0.148
15.08,89.76,0.148
15.10,89.98,0.148
15.12,90.20,0.148
15.15,90.41,0.149
15.17,90.63,0.149
15.19,90.85,0.149
15.21,91.06,0.149
15.23,91.28,0.149
15.25,91.50,0.149
15.28,91.71,0.149
15.30,91.93,0.149
15.32,92.15,0.149
15.34,92.36,0.149
15.36,92.58,0.149
15.38,92.80,0.149
15.40,93.01,0.149
15.43,93.23,0.149
15.45,93.45,0.149
15.47,93.67,0.149
15.49,93.88,0.149
15.51,94.10,0.149
15.53,94.31,0.150
15.56,94.53,0.150
15.58,94.75,0.150
15.60,94.97,0.150
15.62,95.18,0.150
15.64,95.40,0.150
15.67,95.62,0.150
15.69,95.83,0.150
15.71,96.05,0.150
15.73,96.27,0.150
15.75,96.48,0.150
15.77,96.70,0.150
15.80,96.92,0.150
15.82,97.13,0.150
15.84,97.35,0.150
15.86,97.57,0.150
15.88,97.78,0.150
15.90,98.00,0.150
15.93,98.22,0.150
15.95,98.44,0.150
15.97,98.65,0.150
15.99,98.87,0.150
16.01,99.09,0.150
16.03,99.30,0.150
16.05,99.52,0.151
16.08,99.74,0.151
16.10,99.95,0.151
16.12,100.17,0.151
16.14,100.39,0.151
16.16,100.60,0.151
16.18,100.82,0.151
16.21,101.04,0.151
16.23,101.25,0.151
16.25,101.47,0.151
16.27,101.69,0.151
16.29,101.90,0.151
16.32,102.12,0.151
16.34,102.34,0.151
16.36,102.56,0.151
16.38,102.77,0.151
16.40,102.99,0.151
16.42,103.21,0.151
16.45,103.42,0.151
16.47,103.64,0.151
16.49,103.86,0.151
16.51,104.07,0.151
16.53,104.29,0.151
16.55,104.51,0.151
16.58,104.72,0.152
16.60,104.94,0.152
16.62,105.16,0.152
16.64,105.37,0.152
16.66,105.59,0.152
16.68,105.81,0.152
16.70,106.03,0.152
16.73,106.24,0.152
16.75,106.46,0.152
16.77,106.68,0.152
16.79,106.89,0.152
16.81,107.11,0.152
16.83,107.33,0.152
16.86,107.54,0.152
16.88,107.76,0.152
16.90,107.98,0.152
16.92,108.19,0.152
16.94,108.41,0.152
16.97,108.63,0.152
16.99,108.85,0.152
17.01,109.06,0.152
17.03,109.28,0.152
17.05,109.50,0.152
17.07,109.71,0.152
17.09,109.93,0.153
17.12,110.14,0.153
17.14,110.36,0.153
17.16,110.58,0.153
17.18,110.80,0.153
17.20,111.01,0.153
17.23,111.23,0.153
17.25,111.45,0.153
17.27,111.66,0.153
17.29,111.88,0.153
17.31,112.10,0.153
17.33,112.31,0.153
17.36,112.53,0.153
17.38,112.75,0.153
17.40,112.96,0.153
17.42,113.18,0.153
17.44,113.40,0.153
17.46,113.61,0.153
17.48,113.83,0.153
17.51,114.05,0.153
17.53,114.27,0.153
17.55,114.48,0.153
17.57,114.70,0.153
17.59,114.92,0.153
17.62,115.13,0.153
17.64,115.35,0.154
17.66,115.57,0.154
17.68,115.78,0.154
17.70,116.00,0.154
17.72,116.22,0.154
17.74,116.43,0.154
17.77,116.65,0.154
17.79,116.87,0.154
17.81,117.08,0.154
17.83,117.30,0.154
17.85,117.52,0.154
17.88,117.73,0.154
17.90,117.95,0.154
17.92,118.17,0.154
17.94,118.39,0.154
17.96,118.60,0.154
17.98,118.82,0.154
18.01,119.04,0.154
18.03,119.25,0.154
18.05,119.47,0.154
18.07,119.69,0.154
18.09,119.90,0.154
18.11,120.12,0.154
18.13,120.34,0.154
18.16,120.55,0.154
18.18,120.77,0.154
18.20,120.99,0.154
18.22,121.20,0.154
18.24,121.42,0.154
18.27,121.64,0.154
18.29,121.86,0.155
18.31,122.07,0.155
18.33,122.29,0.155
18.35,122.51,0.155
18.37,122.72,0.155
18.39,122.94,0.155
18.42,123.15,0.155
18.44,123.37,0.155
18.46,123.59,0.155
18.48,123.81,0.155
18.50,124.02,0.155
18.53,124.24,0.155
18.55,124.46,0.155
18.57,124.67,0.155
18.59,124.89,0.155
18.61,125.11,0.155
18.63,125.32,0.155
18.66,125.54,0.155
18.68,125.76,0.155
18.70,125.98,0.155
18.72,126.19,0.155
18.74,126.41,0.155
18.76,126.63,0.155
18.78,126.84,0.155
18.81,127.06,0.155
18.83,127.28,0.155
18.85,127.49,0.155
18.87,127.71,0.155
18.89,127.93,0.156
18.92,128.14,0.156
18.94,128.36,0.156
18.96,128.58,0.156
18.98,128.79,0.156
19.00,129.01,0.156
19.02,129.23,0.156
19.04,129.44,0.156
19.07,129.66,0.156
19.09,129.88,0.156
19.11,130.10,0.156
19.13,130.31,0.156
19.15,130.53,0.156
19.18,130.75,0.156
19.20,130.96,0.156
19.22,131.18,0.156
19.24,131.40,0.156
19.26,131.61,0.156
19.28,131.83,0.156
19.31,132.05,0.156
19.33,132.26,0.156
19.35,132.48,0.156
19.37,132.70,0.156
19.39,132.91,0.156
19.41,133.13,0.156
19.43,133.35,0.156
19.46,133.56,0.156
19.48,133.78,0.156
19.50,134.00,0.156
19.52,134.22,0.156
19.54,134.43,0.156
19.57,134.65,0.156
19.59,134.87,0.156
19.61,135.08,0.156
19.63,135.30,0.156
19.65,135.52,0.156
19.67,135.73,0.157
19.69,135.95,0.157
19.72,136.17,0.157
19.74,136.38,0.157
19.76,136.60,0.157
19.78,136.82,0.157
19.80,137.03,0.157
19.83,137.25,0.157
19.85,137.47,0.157
19.87,137.68,0.157
19.89,137.90,0.157
19.91,138.12,0.157
19.93,138.33,0.157
19.96,138.55,0.157
19.98,138.77,0.157
20.00,138.99,0.157
20.02,139.20,0.157
20.04,139.42,0.157
20.06,139.64,0.157
20.08,139.85,0.157
20.11,140.07,0.157
20.13,140.29,0.157
20.15,140.50,0.157
20.17,140.72,0.157
20.19,140.94,0.157
20.22,141.15,0.157
20.24,141.37,0.157
20.26,141.59,0.157
20.28,141.80,0.157
20.30,142.02,0.157
20.32,142.24,0.157
20.34,142.45,0.157
20.37,142.67,0.157
20.39,142.89,0.157
20.41,143.10,0.157
20.43,143.32,0.157
20.45,143.54,0.157
20.48,143.76,0.157
20.50,143.97,0.157
20.52,144.19,0.158
20.54,144.41,0.158
20.56,144.62,0.158
20.58,144.84,0.158
20.61,145.06,0.158
20.63,145.27,0.158
20.65,145.49,0.158
20.67,145.71,0.158
20.69,145.92,0.158
20.71,146.14,0.158
20.73,146.36,0.158
20.76,146.57,0.158
20.78,146.79,0.158
20.80,147.01,0.158
20.82,147.22,0.158
20.84,147.44,0.158
20.87,147.66,0.158
20.89,147.88,0.158
20.91,148.09,0.158
20.93,148.31,0.158
20.95,148.53,0.158
20.97,148.74,0.158
20.99,148.96,0.158
21.02,149.18,0.158
21.04,149.39,0.158
21.06,149.61,0.158
21.08,149.83,0.158
21.10,150.04,0.158
21.13,150.26,0.158
21.15,150.48,0.158
21.17,150.69,0.158
21.19,150.91,0.159
21.21,151.13,0.159
21.23,151.34,0.159
21.26,151.56,0.159
21.28,151.78,0.159
21.30,151.99,0.159
21.32,152.21,0.159
21.34,152.43,0.159
21.36,152.65,0.159
21.38,152.86,0.159
21.41,153.08,0.159
21.43,153.30,0.159
21.45,153.51,0.159
21.47,153.73,0.159
21.49,153.95,0.159
21.52,154.16,0.159
21.54,154.38,0.159
21.56,154.60,0.159
21.58,154.82,0.159
21.60,155.03,0.159
21.62,155.25,0.159
21.64,155.47,0.159
21.67,155.68,0.159
21.69,155.90,0.159
21.71,156.12,0.159
21.73,156.33,0.159
21.75,156.55,0.159
21.78,156.77,0.159
21.80,156.98,0.159
21.82,157.20,0.159
21.84,157.42,0.159
21.86,157.63,0.159
21.88,157.85,0.159
21.91,158.07,0.159
21.93,158.28,0.159
21.95,158.50,0.159
21.97,158.72,0.159
21.99,158.93,0.159
22.01,159.15,0.159
22.03,159.37,0.159
22.06,159.59,0.159
22.08,159.80,0.159
22.10,160.02,0.159
22.12,160.23,0.160
22.14,160.45,0.160
22.17,160.67,0.160
22.19,160.89,0.160
22.21,161.10,0.160
22.23,161.32,0.160
22.25,161.54,0.160
22.27,161.75,0.160
22.29,161.97,0.160
22.32,162.19,0.160
22.34,162.40,0.160
22.36,162.62,0.160
22.38,162.84,0.160
22.40,163.05,0.160
22.43,163.27,0.160
22.45,163.49,0.160
22.47,163.70,0.160
22.49,163.92,0.160
22.51,164.14,0.160
22.53,164.35,0.160
22.56,164.57,0.160
22.58,164.79,0.160
22.60,165.00,0.160
22.62,165.22,0.160
22.64,165.44,0.160
22.66,165.65,0.160
22.68,165.87,0.160
22.71,166.09,0.160
22.73,166.30,0.160
22.75,166.52,0.160
22.77,166.74,0.160
22.79,166.96,0.160
22.82,167.17,0.160
22.84,167.39,0.160
22.86,167.61,0.160
22.88,167.82,0.160
22.90,168.04,0.160
22.92,168.26,0.160
22.94,168.47,0.161
22.97,168.69,0.161
22.99,168.91,0.161
23.01,169.12,0.161
23.03,169.34,0.161
23.05,169.56,0.161
23.08,169.77,0.161
23.10,169.99,0.161
23.12,170.21,0.161
23.14,170.43,0.161
23.16,170.64,0.161
23.18,170.86,0.161
23.21,171.08,0.161
23.23,171.29,0.161
23.25,171.51,0.161
23.27,171.73,0.161
23.29,171.94,0.161
23.31,172.16,0.161
23.33,172.38,0.161
23.36,172.59,0.161
23.38,172.81,0.161
23.40,173.03,0.161
23.42,173.24,0.161
23.44,173.46,0.161
23.47,173.68,0.161
23.49,173.89,0.161
23.51,174.11,0.161
23.53,174.33,0.161
23.55,174.55,0.161
23.57,174.76,0.161
23.59,174.98,0.161
23.62,175.20,0.161
23.64,175.41,0.161
23.66,175.63,0.161
23.68,175.85,0.161
23.70,176.06,0.161
23.73,176.28,0.161
23.75,176.50,0.161
23.77,176.71,0.161
23.79,176.93,0.161
23.81,177.15,0.161
23.83,177.36,0.161
23.86,177.58,0.161
23.88,177.80,0.162
23.90,178.01,0.162
23.92,178.23,0.162
23.94,178.45,0.162
23.96,178.66,0.162
23.98,178.88,0.162
24.01,179.10,0.162
24.03,179.31,0.162
24.05,179.53,0.162
24.07,179.75,0.162
24.09,179.97,0.162
24.12,180.18,0.162
24.14,180.40,0.162
24.16,180.61,0.162
24.18,180.83,0.162
24.20,181.05,0.162
24.22,181.27,0.162
24.24,181.48,0.162
24.27,181.70,0.162
24.29,181.92,0.162
24.31,182.13,0.162
24.33,182.35,0.162
24.35,182.57,0.162
24.38,182.78,0.162
24.40,183.00,0.162
24.42,183.22,0.162
24.44,183.43,0.162
24.46,183.65,0.162
24.48,183.87,0.162
24.51,184.08,0.162
24.53,184.30,0.162
24.55,184.52,0.162
24.57,184.74,0.162
24.59,184.95,0.162
24.61,185.17,0.162
24.63,185.39,0.163
24.66,185.60,0.163
24.68,185.82,0.163
24.70,186.04,0.163
24.72,186.25,0.163
24.74,186.47,0.163
24.77,186.69,0.163
24.79,186.90,0.163
24.81,187.12,0.163
24.83,187.34,0.163
24.85,187.56,0.163
24.87,187.77,0.163
24.89,187.99,0.163
24.92,188.20,0.163
24.94,188.42,0.163
24.96,188.64,0.163
24.98,188.85,0.163
25.00,189.07,0.163
25.03,189.29,0.163
25.05,189.51,0.163
25.07,189.72,0.163
25.09,189.94,0.163
25.11,190.16,0.163
25.13,190.37,0.163
25.16,190.59,0.163
25.18,190.81,0.163
25.20,191.02,0.163
25.22,191.24,0.163
25.24,191.46,0.163
25.26,191.67,0.163
25.28,191.89,0.163
25.31,192.11,0.163
25.33,192.33,0.163
25.35,192.54,0.163
25.37,192.76,0.163
25.39,192.97,0.163
25.42,193.19,0.163
25.44,193.41,0.163
25.46,193.62,0.163
25.48,193.84,0.163
25.50,194.06,0.163
25.52,194.27,0.163
25.54,194.49,0.163
25.57,194.71,0.164
25.59,194.92,0.164
25.61,195.14,0.164
25.63,195.36,0.164
25.65,195.58,0.164
25.68,195.79,0.164
25.70,196.01,0.164
25.72,196.23,0.164
25.74,196.44,0.164
25.76,196.66,0.164
25.78,196.88,0.164
25.81,197.09,0.164
25.83,197.31,0.164
25.85,197.53,0.164
25.87,197.74,0.164
25.89,197.96,0.164
25.91,198.18,0.164
25.93,198.39,0.164
25.96,198.61,0.164
25.98,198.83,0.164
26.00,199.04,0.164
26.02,199.26,0.164
26.04,199.48,0.164
26.07,199.70,0.164
26.09,199.91,0.164
26.11,200.13,0.164
26.13,200.35,0.164
26.15,200.57,0.164
26.17,200.78,0.164
26.19,201.00,0.165
26.22,201.22,0.165
26.24,201.43,0.165
26.26,201.65,0.165
26.28,201.86,0.165
26.30,202.08,0.165
26.33,202.30,0.164
26.35,202.51,0.164
26.37,202.73,0.164
26.39,202.95,0.164
26.41,203.16,0.164
26.43,203.38,0.164
26.46,203.60,0.164
26.48,203.81,0.164
26.50,204.03,0.164
26.52,204.25,0.165
26.54,204.46,0.165
26.56,204.68,0.165
26.58,204.90,0.165
26.61,205.11,0.165
26.63,205.33,0.165
26.65,205.55,0.165
26.67,205.77,0.165
26.69,205.98,0.165
26.72,206.20,0.165
26.74,206.42,0.165
26.76,206.63,0.165
26.78,206.85,0.165
26.80,207.07,0.165
26.82,207.28,0.165
26.84,207.50,0.165
26.87,207.72,0.165
26.89,207.93,0.165
26.91,208.15,0.165
26.93,208.37,0.165
26.95,208.58,0.165
26.98,208.80,0.165
27.00,209.02,0.165
27.02,209.24,0.165
27.04,209.45,0.165
27.06,209.67,0.165
27.08,209.89,0.165
27.11,210.10,0.165
27.13,210.32,0.165
27.15,210.54,0.165
27.17,210.75,0.165
27.19,210.97,0.165
27.21,211.19,0.165
27.23,211.40,0.165
27.26,211.62,0.165
27.28,211.84,0.165
27.30,212.05,0.165
27.32,212.27,0.165
27.34,212.49,0.165
27.37,212.70,0.165
27.39,212.92,0.165
27.41,213.14,0.166
27.43,213.36,0.166
27.45,213.57,0.166
27.47,213.79,0.166
27.49,214.00,0.166
27.52,214.22,0.166
27.54,214.44,0.166
27.56,214.65,0.166
27.58,214.87,0.166
27.60,215.09,0.166
27.63,215.31,0.166
27.65,215.52,0.166
27.67,215.74,0.166
27.69,215.96,0.166
27.71,216.17,0.166
27.73,216.39,0.166
27.76,216.61,0.166
27.78,216.82,0.166
27.80,217.04,0.166
27.82,217.26,0.166
27.84,217.47,0.166
27.86,217.69,0.166
27.88,217.91,0.166
27.91,218.13,0.166
27.93,218.34,0.166
27.95,218.56,0.166
27.97,218.77,0.166
27.99,218.99,0.166
28.02,219.21,0.166
28.04,219.42,0.166
28.06,219.64,0.166
28.08,219.86,0.166
28.10,220.07,0.166
28.12,220.29,0.166
28.14,220.51,0.166
28.17,220.72,0.166
28.19,220.94,0.166
28.21,221.16,0.167
28.23,221.38,0.167
28.25,221.59,0.167
28.28,221.81,0.167
28.30,222.03,0.167
28.32,222.24,0.167
28.34,222.46,0.167
28.36,222.68,0.167
28.38,222.89,0.167
28.41,223.11,0.167
28.43,223.33,0.167
28.45,223.54,0.167
28.47,223.76,0.167
28.49,223.98,0.167
28.51,224.20,0.167
28.53,224.41,0.167
28.56,224.63,0.167
28.58,224.84,0.167
28.60,225.06,0.167
28.62,225.28,0.167
28.64,225.50,0.167
28.67,225.71,0.167
28.69,225.93,0.167
28.71,226.15,0.167
28.73,226.36,0.167
28.75,226.58,0.167
28.77,226.80,0.167
28.79,227.01,0.167
28.82,227.23,0.167
28.84,227.45,0.167
28.86,227.66,0.167
28.88,227.88,0.167
28.90,228.10,0.167
28.93,228.31,0.167
28.95,228.53,0.167
28.97,228.75,0.167
28.99,228.96,0.167
29.01,229.18,0.167
29.03,229.40,0.167
29.06,229.61,0.167
29.08,229.83,0.167
29.10,230.05,0.167
29.12,230.26,0.168
29.14,230.48,0.168
29.16,230.70,0.168
29.18,230.92,0.168
29.21,231.13,0.168
29.23,231.35,0.168
29.25,231.56,0.168
29.27,231.78,0.168
29.29,232.00,0.168
29.32,232.21,0.168
29.34,232.43,0.168
29.36,232.65,0.168
29.38,232.87,0.168
29.40,233.08,0.168
29.42,233.30,0.168
29.44,233.52,0.168
29.47,233.73,0.168
29.49,233.95,0.168
29.51,234.17,0.168
29.53,234.38,0.168
29.55,234.60,0.168
29.58,234.82,0.168
29.60,235.03,0.168
29.62,235.25,0.168
29.64,235.47,0.168
29.66,235.68,0.168
29.68,235.90,0.168
29.71,236.12,0.168
29.73,236.34,0.168
29.75,236.55,0.168
29.77,236.77,0.168
29.79,236.99,0.168
29.81,237.20,0.168
29.83,237.42,0.168
29.86,237.64,0.168
29.88,237.85,0.168
29.90,238.07,0.168
29.92,238.29,0.169
29.94,238.50,0.169
29.97,238.72,0.169
29.99,238.94,0.169
30.01,239.15,0.169
30.03,239.37,0.169
30.05,239.59,0.169
30.07,239.80,0.169
30.09,240.02,0.169
30.12,240.24,0.169
30.14,240.45,0.169
30.16,240.67,0.169
30.18,240.89,0.169
30.20,241.10,0.169
30.23,241.32,0.169
30.25,241.54,0.169
30.27,241.75,0.169
30.29,241.97,0.169
30.31,242.19,0.169
30.33,242.41,0.169
30.36,242.62,0.169
30.38,242.84,0.169
30.40,243.06,0.170
30.42,243.27,0.170
30.44,243.49,0.170
30.46,243.71,0.170
30.48,243.92,0.170
30.51,244.14,0.170
30.53,244.36,0.170
30.55,244.57,0.170
30.57,244.79,0.170
30.59,245.01,0.170
30.62,245.22,0.170
30.64,245.44,0.170
30.66,245.66,0.170
30.68,245.87,0.170
30.70,246.09,0.170
30.72,246.31,0.170
30.74,246.52,0.170
30.77,246.74,0.170
30.79,246.96,0.170
30.81,247.17,0.170
30.83,247.39,0.170
30.85,247.61,0.170
30.88,247.82,0.170
30.90,248.04,0.170
30.92,248.26,0.170
30.94,248.47,
30.96,248.69,
30.98,248.91,
30.99,,

[step]
Ramp 10.00 °C/min to -60.00 °C
Time,Temperature,Heat Flow (Normalized)
min,°C,W/g
32.99,250.17,-0.031
33.02,250.17,-0.031
33.04,250.16,-0.030
33.06,250.14,-0.012
33.08,250.08,0.000
33.10,250.00,-0.004
33.12,249.87,-0.033
33.14,249.72,-0.072
33.17,249.55,-0.113
33.19,249.36,-0.151
33.21,249.16,-0.178
33.23,248.95,-0.196
33.25,248.75,-0.210
33.28,248.53,-0.215
33.30,248.32,-0.219
33.32,248.11,-0.222
33.34,247.90,-0.224
33.36,247.68,-0.224
33.38,247.47,-0.226
33.41,247.25,-0.226
33.43,247.04,-0.227
33.45,246.83,-0.227
33.47,246.61,-0.228
33.49,246.40,-0.228
33.51,246.18,-0.228
33.53,245.96,-0.228
33.56,245.75,-0.228
33.58,245.53,-0.229
33.60,245.32,-0.229
33.62,245.10,-0.229
33.64,244.89,-0.229
33.67,244.67,-0.229
33.69,244.46,-0.230
33.71,244.24,-0.230
33.73,244.03,-0.230
33.75,243.81,-0.230
33.77,243.60,-0.230
33.79,243.38,-0.230
33.82,243.17,-0.230
33.84,242.95,-0.230
33.86,242.74,-0.230
33.88,242.52,-0.230
33.90,242.30,-0.230
33.93,242.09,-0.230
33.95,241.87,-0.230
33.97,241.65,-0.230
33.99,241.44,-0.231
34.01,241.22,-0.231
34.03,241.01,-0.230
34.06,240.79,-0.230
34.08,240.58,-0.230
34.10,240.36,-0.230
34.12,240.14,-0.230
34.14,239.93,-0.230
34.16,239.71,-0.230
34.19,239.50,-0.230
34.21,239.28,-0.230
34.23,239.06,-0.230
34.25,238.85,-0.230
34.27,238.63,-0.230
34.29,238.42,-0.230
34.31,238.20,-0.230
34.34,237.99,-0.230
34.36,237.77,-0.230
34.38,237.55,-0.230
34.40,237.34,-0.230
34.42,237.12,-0.230
34.44,236.90,-0.230
34.47,236.69,-0.230
34.49,236.47,-0.230
34.51,236.25,-0.230
34.53,236.04,-0.229
34.55,235.82,-0.229
34.58,235.61,-0.229
34.60,235.39,-0.229
34.62,235.17,-0.229
34.64,234.96,-0.229
34.66,234.74,-0.229
34.68,234.52,-0.229
34.71,234.31,-0.229
34.73,234.09,-0.229
34.75,233.87,-0.229
34.77,233.66,-0.229
34.79,233.44,-0.229
34.81,233.23,-0.229
34.84,233.01,-0.228
34.86,232.79,-0.228
34.88,232.58,-0.228
34.90,232.36,-0.228
34.92,232.14,-0.228
34.94,231.93,-0.228
34.96,231.71,-0.228
34.99,231.49,-0.228
35.01,231.28,-0.228
35.03,231.06,-0.228
35.05,230.84,-0.228
35.07,230.63,-0.228
35.09,230.41,-0.228
35.12,230.20,-0.228
35.14,229.98,-0.228
35.16,229.76,-0.228
35.18,229.55,-0.228
35.20,229.33,-0.228
35.23,229.11,-0.227
35.25,228.90,-0.228
35.27,228.68,-0.227
35.29,228.46,-0.227
35.31,228.24,-0.227
35.33,228.03,-0.227
35.36,227.81,-0.227
35.38,227.60,-0.227
35.40,227.38,-0.227
35.42,227.16,-0.227
35.44,226.95,-0.227
35.46,226.73,-0.227
35.49,226.51,-0.227
35.51,226.30,-0.227
35.53,226.08,-0.227
35.55,225.86,-0.227
35.57,225.65,-0.227
35.59,225.43,-0.227
35.61,225.21,-0.227
35.64,225.00,-0.227
35.66,224.78,-0.227
35.68,224.56,-0.227
35.70,224.35,-0.227
35.72,224.13,-0.226
35.74,223.92,-0.226
35.77,223.70,-0.226
35.79,223.48,-0.226
35.81,223.27,-0.226
35.83,223.05,-0.226
35.85,222.83,-0.226
35.88,222.62,-0.226
35.90,222.40,-0.226
35.92,222.18,-0.226
35.94,221.97,-0.226
35.96,221.75,-0.226
35.98,221.53,-0.226
36.01,221.32,-0.226
36.03,221.10,-0.226
36.05,220.88,-0.226
36.07,220.66,-0.226
36.09,220.45,-0.226
36.11,220.23,-0.226
36.14,220.02,-0.226
36.16,219.80,-0.226
36.18,219.58,-0.226
36.20,219.37,-0.225
36.22,219.15,-0.225
36.24,218.93,-0.225
36.26,218.72,-0.225
36.29,218.50,-0.225
36.31,218.28,-0.225
36.33,218.07,-0.225
36.35,217.85,-0.225
36.37,217.63,-0.225
36.39,217.42,-0.225
36.42,217.20,-0.225
36.44,216.99,-0.225
36.46,216.77,-0.225
36.48,216.55,-0.225
36.50,216.34,-0.225
36.53,216.12,-0.225
36.55,215.90,-0.225
36.57,215.69,-0.225
36.59,215.47,-0.225
36.61,215.25,-0.225
36.63,215.04,-0.224
36.66,214.82,-0.224
36.68,214.60,-0.224
36.70,214.38,-0.225
36.72,214.17,-0.225
36.74,213.95,-0.225
36.76,213.74,-0.225
36.79,213.52,-0.224
36.81,213.30,-0.224
36.83,213.09,-0.224
36.85,212.87,-0.224
36.87,212.65,-0.224
36.89,212.44,-0.224
36.91,212.22,-0.224
36.94,212.00,-0.224
36.96,211.79,-0.224
36.98,211.57,-0.224
37.00,211.35,-0.224
37.02,211.14,-0.224
37.04,210.92,-0.224
37.07,210.70,-0.224
37.09,210.49,-0.224
37.11,210.27,-0.224
37.13,210.05,-0.224
37.15,209.84,-0.224
37.18,209.62,-0.224
37.20,209.40,-0.224
37.22,209.19,-0.223
37.24,208.97,-0.223
37.26,208.75,-0.223
37.28,208.54,-0.223
37.31,208.32,-0.223
37.33,208.10,-0.223
37.35,207.89,-0.223
37.37,207.67,-0.223
37.39,207.46,-0.223
37.41,207.24,-0.223
37.44,207.02,-0.223
37.46,206.81,-0.223
37.48,206.59,-0.223
37.50,206.37,-0.223
37.52,206.16,-0.223
37.54,205.94,-0.223
37.56,205.72,-0.223
37.59,205.51,-0.223
37.61,205.29,-0.223
37.63,205.07,-0.223
37.65,204.86,-0.223
37.67,204.64,-0.223
37.69,204.42,-0.223
37.72,204.21,-0.223
37.74,203.99,-0.223
37.76,203.77,-0.223
37.78,203.56,-0.223
37.80,203.34,-0.223
37.83,203.13,-0.222
37.85,202.91,-0.222
37.87,202.69,-0.222
37.89,202.47,-0.222
37.91,202.26,-0.222
37.93,202.04,-0.222
37.96,201.82,-0.222
37.98,201.61,-0.222
38.00,201.39,-0.222
38.02,201.17,-0.222
38.04,200.96,-0.222
38.06,200.74,-0.222
38.09,200.52,-0.222
38.11,200.31,-0.222
38.13,200.09,-0.222
38.15,199.87,-0.222
38.17,199.66,-0.222
38.19,199.44,-0.222
38.21,199.22,-0.222
38.24,199.01,-0.222
38.26,198.79,-0.222
38.28,198.57,-0.222
38.30,198.36,-0.222
38.32,198.14,-0.222
38.34,197.93,-0.222
38.37,197.71,-0.222
38.39,197.49,-0.222
38.41,197.28,-0.222
38.43,197.06,-0.222
38.45,196.84,-0.222
38.48,196.63,-0.222
38.50,196.41,-0.222
38.52,196.19,-0.222
38.54,195.98,-0.222
38.56,195.76,-0.222
38.58,195.54,-0.222
38.61,195.32,-0.222
38.63,195.11,-0.222
38.65,194.89,-0.222
38.67,194.67,-0.222
38.69,194.46,-0.222
38.71,194.24,-0.222
38.74,194.02,-0.222
38.76,193.81,-0.222
38.78,193.59,-0.221
38.80,193.38,-0.221
38.82,193.16,-0.221
38.84,192.94,-0.221
38.86,192.73,-0.221
38.89,192.51,-0.221
38.91,192.29,-0.221
38.93,192.08,-0.221
38.95,191.86,-0.221
38.97,191.64,-0.221
38.99,191.43,-0.221
39.02,191.21,-0.221
39.04,190.99,-0.221
39.06,190.78,-0.221
39.08,190.56,-0.221
39.10,190.34,-0.221
39.13,190.13,-0.221
39.15,189.91,-0.221
39.17,189.70,-0.221
39.19,189.48,-0.221
39.21,189.26,-0.221
39.23,189.04,-0.221
39.26,188.83,-0.221
39.28,188.61,-0.221
39.30,188.39,-0.221
39.32,188.18,-0.221
39.34,187.96,-0.221
39.36,187.74,-0.221
39.39,187.53,-0.221
39.41,187.31,-0.221
39.43,187.10,-0.221
39.45,186.88,-0.221
39.47,186.66,-0.221
39.49,186.45,-0.220
39.51,186.23,-0.220
39.54,186.01,-0.220
39.56,185.80,-0.220
39.58,185.58,-0.220
39.60,185.37,-0.220
39.62,185.15,-0.220
39.64,184.93,-0.220
39.67,184.71,-0.220
39.69,184.50,-0.220
39.71,184.28,-0.220
39.73,184.06,-0.220
39.75,183.85,-0.220
39.78,183.63,-0.220
39.80,183.41,-0.220
39.82,183.20,-0.220
39.84,182.98,-0.220
39.86,182.76,-0.220
39.88,182.55,-0.220
39.91,182.33,-0.220
39.93,182.11,-0.220
39.95,181.90,-0.220
39.97,181.68,-0.220
39.99,181.46,-0.220
40.01,181.25,-0.220
40.04,181.03,-0.220
40.06,180.81,-0.220
40.08,180.60,-0.220
40.10,180.38,-0.220
40.12,180.16,-0.219
40.14,179.95,-0.219
40.16,179.73,-0.219
40.19,179.51,-0.219
40.21,179.30,-0.219
40.23,179.08,-0.219
40.25,178.86,-0.219
40.27,178.65,-0.219
40.29,178.43,-0.219
40.32,178.22,-0.219
40.34,178.00,-0.219
40.36,177.78,-0.219
40.38,177.57,-0.219
40.40,177.35,-0.219
40.43,177.13,-0.219
40.45,176.91,-0.219
40.47,176.70,-0.219
40.49,176.48,-0.219
40.51,176.26,-0.219
40.53,176.05,-0.219
40.56,175.83,-0.219
40.58,175.62,-0.219
40.60,175.40,-0.219
40.62,175.18,-0.219
40.64,174.97,-0.219
40.66,174.75,-0.219
40.69,174.53,-0.219
40.71,174.32,-0.219
40.73,174.10,-0.219
40.75,173.88,-0.219
40.77,173.67,-0.219
40.79,173.45,-0.219
40.81,173.23,-0.219
40.84,173.02,-0.219
40.86,172.80,-0.219
40.88,172.58,-0.219
40.90,172.37,-0.219
40.92,172.15,-0.219
40.94,171.93,-0.219
40.97,171.72,-0.219
40.99,171.50,-0.219
41.01,171.28,-0.218
41.03,171.07,-0.218
41.05,170.85,-0.218
41.08,170.63,-0.218
41.10,170.42,-0.218
41.12,170.20,-0.218
41.14,169.98,-0.218
[...]
140.99,28.67,0.135
141.01,28.89,0.135
141.03,29.10,0.135
141.05,29.32,0.135
141.07,29.54,0.135
141.10,29.76,0.135
141.12,29.97,0.135
141.14,30.19,0.135
141.16,30.41,0.136
141.18,30.62,0.136
141.20,30.84,0.136
141.23,31.06,0.136
141.25,31.28,0.136
141.27,31.49,0.136
141.29,31.71,0.136
141.31,31.93,0.136
141.33,32.14,0.136
141.35,32.36,0.136
141.38,32.58,0.136
141.40,32.79,0.136
141.42,33.01,0.136
141.44,33.23,0.136
141.46,33.44,0.136
141.48,33.66,0.136
141.51,33.88,0.136
141.53,34.10,0.136
141.55,34.31,0.136
141.57,34.53,0.136
141.59,34.75,0.136
141.62,34.96,0.137
141.64,35.18,0.137
141.66,35.40,0.137
141.68,35.61,0.137
141.70,35.83,0.137
141.72,36.05,0.137
141.75,36.27,0.137
141.77,36.48,0.137
141.79,36.70,0.137
141.81,36.92,0.137
141.83,37.13,0.137
141.85,37.35,0.137
141.88,37.57,0.137
141.90,37.78,0.137
141.92,38.00,0.137
141.94,38.22,0.138
141.96,38.43,0.138
141.98,38.65,0.138
142.00,38.87,0.138
142.03,39.08,0.138
142.05,39.30,0.138
142.07,39.52,0.138
142.09,39.73,0.138
142.11,39.95,0.138
142.13,40.17,0.138
142.16,40.38,0.138
142.18,40.60,0.138
142.20,40.82,0.138
142.22,41.04,0.138
142.24,41.25,0.138
142.27,41.47,0.138
142.29,41.69,0.138
142.31,41.90,0.138
142.33,42.12,0.138
142.35,42.34,0.138
142.37,42.55,0.138
142.40,42.77,0.139
142.42,42.99,0.139
142.44,43.20,0.139
142.46,43.42,0.139
142.48,43.64,0.139
142.50,43.86,0.139
142.53,44.07,0.139
142.55,44.29,0.139
142.57,44.51,0.139
142.59,44.72,0.139
142.61,44.94,0.139
142.63,45.16,0.139
142.65,45.37,0.139
142.68,45.59,0.139
142.70,45.81,0.139
142.72,46.02,0.139
142.74,46.24,0.139
142.76,46.46,0.139
142.78,46.67,0.139
142.81,46.89,0.140
142.83,47.11,0.140
142.85,47.33,0.140
142.87,47.54,0.140
142.89,47.76,0.140
142.92,47.98,0.140
142.94,48.19,0.140
142.96,48.41,0.140
142.98,48.63,0.140
143.00,48.84,0.140
143.02,49.06,0.140
143.05,49.28,0.140
143.07,49.49,0.140
143.09,49.71,0.140
143.11,49.93,0.140
143.13,50.14,0.140
143.15,50.36,0.140
143.18,50.58,0.140
143.20,50.80,0.140
143.22,51.01,0.140
143.24,51.23,0.141
143.26,51.45,0.141
143.28,51.66,0.141
143.30,51.88,0.141
143.33,52.10,0.141
143.35,52.31,0.141
143.37,52.53,0.141
143.39,52.75,0.141
143.41,52.96,0.141
143.43,53.18,0.141
143.46,53.40,0.141
143.48,53.62,0.141
143.50,53.83,0.141
143.52,54.05,0.141
143.54,54.27,0.141
143.57,54.48,0.141
143.59,54.70,0.141
143.61,54.92,0.141
143.63,55.13,0.142
143.65,55.35,0.142
143.67,55.57,0.142
143.70,55.78,0.142
143.72,56.00,0.142
143.74,56.22,0.142
143.76,56.44,0.142
143.78,56.65,0.142
143.80,56.87,0.142
143.83,57.08,0.142
143.85,57.30,0.142
143.87,57.52,0.142
143.89,57.74,0.142
143.91,57.95,0.142
143.93,58.17,0.142
143.95,58.39,0.142
143.98,58.60,0.142
144.00,58.82,0.142
144.02,59.04,0.142
144.04,59.25,0.142
144.06,59.47,0.142
144.08,59.69,0.143
144.11,59.90,0.143
144.13,60.12,0.143
144.15,60.34,0.143
144.17,60.56,0.143
144.19,60.77,0.143
144.22,60.99,0.143
144.24,61.21,0.143
144.26,61.42,0.143
144.28,61.64,0.143
144.30,61.86,0.143
144.32,62.07,0.143
144.35,62.29,0.143
144.37,62.51,0.143
144.39,62.73,0.143
144.41,62.94,0.143
144.43,63.16,0.143
144.45,63.38,0.143
144.48,63.59,0.143
144.50,63.81,0.144
144.52,64.03,0.144
144.54,64.24,0.144
144.56,64.46,0.144
144.58,64.68,0.144
144.60,64.89,0.144
144.63,65.11,0.144
144.65,65.33,0.144
144.67,65.54,0.144
144.69,65.76,0.144
144.71,65.98,0.144
144.73,66.20,0.144
144.76,66.41,0.144
144.78,66.63,0.144
144.80,66.84,0.144
144.82,67.06,0.144
144.84,67.28,0.144
144.87,67.50,0.144
144.89,67.72,0.144
144.91,67.94,0.144
144.93,68.15,0.145
144.95,68.37,0.145
144.97,68.59,0.145
145.00,68.80,0.145
145.02,69.02,0.145
145.04,69.24,0.145
145.06,69.45,0.145
145.08,69.67,0.145
145.10,69.89,0.145
145.13,70.10,0.145
145.15,70.32,0.145
145.17,70.54,0.145
145.19,70.75,0.145
145.21,70.97,0.145
145.23,71.19,0.145
145.25,71.40,0.145
145.28,71.62,0.145
145.30,71.84,0.145
145.32,72.05,0.145
145.34,72.27,0.145
145.36,72.49,0.145
145.38,72.70,0.145
145.41,72.92,0.145
145.43,73.14,0.145
145.45,73.35,0.146
145.47,73.57,0.145
145.49,73.79,0.145
145.52,74.00,0.145
145.54,74.22,0.146
145.56,74.44,0.146
145.58,74.65,0.146
145.60,74.87,0.146
145.62,75.09,0.146
145.65,75.31,0.146
145.67,75.52,0.146
145.69,75.74,0.146
145.71,75.96,0.146
145.73,76.18,0.146
145.75,76.39,0.146
145.78,76.61,0.146
145.80,76.82,0.146
145.82,77.04,0.146
145.84,77.26,0.146
145.86,77.48,0.146
145.88,77.69,0.146
145.90,77.91,0.146
145.93,78.13,0.146
145.95,78.34,0.146
145.97,78.56,0.146
145.99,78.78,0.147
146.01,78.99,0.146
146.03,79.21,0.147
146.06,79.43,0.147
146.08,79.65,0.147
146.10,79.86,0.147
146.12,80.08,0.147
146.14,80.30,0.147
146.17,80.51,0.147
146.19,80.73,0.147
146.21,80.95,0.147
146.23,81.16,0.147
146.25,81.38,0.147
146.27,81.59,0.147
146.30,81.81,0.147
146.32,82.03,0.147
146.34,82.24,0.147
146.36,82.46,0.147
146.38,82.68,0.147
146.40,82.90,0.147
146.43,83.11,0.147
146.45,83.33,0.147
146.47,83.55,0.147
146.49,83.76,0.147
146.51,83.98,0.147
146.53,84.20,0.147
146.55,84.41,0.147
146.58,84.63,0.147
146.60,84.85,0.147
146.62,85.06,0.147
146.64,85.28,0.147
146.66,85.50,0.147
146.68,85.72,0.147
146.71,85.93,0.147
146.73,86.15,0.148
146.75,86.37,0.148
146.77,86.58,0.148
146.79,86.80,0.148
146.82,87.01,0.148
146.84,87.23,0.148
146.86,87.45,0.148
146.88,87.67,0.148
146.90,87.88,0.148
146.92,88.10,0.148
146.95,88.31,0.148
146.97,88.53,0.148
146.99,88.75,0.148
147.01,88.97,0.148
147.03,89.18,0.148
147.05,89.40,0.148
147.08,89.62,0.148
147.10,89.83,0.148
147.12,90.05,0.148
147.14,90.27,0.148
147.16,90.48,0.148
147.18,90.70,0.148
147.20,90.92,0.148
147.23,91.13,0.148
147.25,91.35,0.149
147.27,91.57,0.149
147.29,91.79,0.149
147.31,92.00,0.149
147.33,92.22,0.149
147.36,92.44,0.149
147.38,92.65,0.149
147.40,92.87,0.149
147.42,93.09,0.149
147.44,93.30,0.149
147.47,93.52,0.149
147.49,93.74,0.149
147.51,93.95,0.149
147.53,94.17,0.149
147.55,94.39,0.149
147.57,94.60,0.149
147.60,94.82,0.149
147.62,95.04,0.149
147.64,95.26,0.149
147.66,95.47,0.150
147.68,95.69,0.150
147.70,95.91,0.150
147.73,96.12,0.150
147.75,96.34,0.150
147.77,96.56,0.150
147.79,96.77,0.150
147.81,96.99,0.150
147.83,97.21,0.150
147.85,97.42,0.150
147.88,97.64,0.150
147.90,97.86,0.150
147.92,98.07,0.150
147.94,98.29,0.150
147.96,98.51,0.150
147.98,98.72,0.150
148.01,98.94,0.150
148.03,99.16,0.150
148.05,99.38,0.150
148.07,99.59,0.150
148.09,99.81,0.151
148.12,100.03,0.151
148.14,100.24,0.151
148.16,100.46,0.151
148.18,100.68,0.151
148.20,100.89,0.151
148.22,101.11,0.151
148.25,101.33,0.151
148.27,101.54,0.151
148.29,101.76,0.151
148.31,101.98,0.151
148.33,102.20,0.151
148.35,102.41,0.151
148.38,102.63,0.151
148.40,102.84,0.151
148.42,103.06,0.151
148.44,103.28,0.152
148.46,103.50,0.152
148.48,103.71,0.152
148.50,103.93,0.152
148.53,104.15,0.152
148.55,104.36,0.152
148.57,104.58,0.152
148.59,104.80,0.152
148.61,105.01,0.152
148.63,105.23,0.152
148.66,105.45,0.152
148.68,105.66,0.152
148.70,105.88,0.152
148.72,106.10,0.152
148.74,106.32,0.152
148.77,106.53,0.152
148.79,106.75,0.152
148.81,106.97,0.152
148.83,107.18,0.152
148.85,107.40,0.152
148.87,107.62,0.152
148.90,107.83,0.152
148.92,108.05,0.152
148.94,108.27,0.152
148.96,108.48,0.153
148.98,108.70,0.153
149.00,108.92,0.153
149.03,109.14,0.153
149.05,109.35,0.153
149.07,109.57,0.153
149.09,109.79,0.153
149.11,110.00,0.153
149.13,110.22,0.153
149.15,110.44,0.153
149.18,110.65,0.153
149.20,110.87,0.153
149.22,111.09,0.153
149.24,111.30,0.153
149.26,111.52,0.153
149.28,111.74,0.153
149.31,111.95,0.153
149.33,112.17,0.153
149.35,112.39,0.153
149.37,112.60,0.153
149.39,112.82,0.153
149.42,113.04,0.153
149.44,113.25,0.153
149.46,113.47,0.153
149.48,113.69,0.153
149.50,113.90,0.153
149.52,114.12,0.154
149.55,114.34,0.154
149.57,114.55,0.154
149.59,114.77,0.154
149.61,114.99,0.154
149.63,115.21,0.154
149.65,115.42,0.154
149.68,115.64,0.154
149.70,115.86,0.154
149.72,116.07,0.154
149.74,116.29,0.154
149.76,116.51,0.154
149.78,116.72,0.154
149.80,116.94,0.154
149.83,117.16,0.154
149.85,117.37,0.154
149.87,117.59,0.154
149.89,117.81,0.154
149.91,118.02,0.154
149.93,118.24,0.154
149.96,118.46,0.154
149.98,118.67,0.155
150.00,118.89,0.155
150.02,119.11,0.155
150.04,119.32,0.155
150.07,119.54,0.155
150.09,119.76,0.155
150.11,119.97,0.155
150.13,120.19,0.155
150.15,120.41,0.155
150.17,120.63,0.155
150.20,120.84,0.155
150.22,121.06,0.155
150.24,121.28,0.155
150.26,121.49,0.155
150.28,121.71,0.155
150.30,121.93,0.155
150.33,122.15,0.155
150.35,122.36,0.155
150.37,122.58,0.155
150.39,122.80,0.155
150.41,123.01,0.155
150.43,123.23,0.155
150.45,123.45,0.155
150.48,123.66,0.155
150.50,123.88,0.155
150.52,124.10,0.155
150.54,124.31,0.155
150.56,124.53,0.155
150.58,124.75,0.155
150.61,124.96,0.155
150.63,125.18,0.156
150.65,125.40,0.156
150.67,125.61,0.156
150.69,125.83,0.156
150.72,126.05,0.156
150.74,126.27,0.156
150.76,126.48,0.156
150.78,126.70,0.156
150.80,126.92,0.156
150.82,127.13,0.156
150.85,127.35,0.156
150.87,127.57,0.156
150.89,127.78,0.156
150.91,128.00,0.156
150.93,128.22,0.156
150.95,128.43,0.156
150.98,128.65,0.156
151.00,128.87,0.156
151.02,129.08,0.156
151.04,129.30,0.156
151.06,129.52,0.156
151.08,129.73,0.156
151.10,129.95,0.156
151.13,130.17,0.156
151.15,130.38,0.156
151.17,130.60,0.156
151.19,130.82,0.156
151.21,131.03,0.156
151.23,131.25,0.156
151.26,131.47,0.156
151.28,131.68,0.157
151.30,131.90,0.157
151.32,132.12,0.157
151.34,132.34,0.157
151.37,132.55,0.157
151.39,132.77,0.157
151.41,132.99,0.157
151.43,133.20,0.157
151.45,133.42,0.157
151.47,133.64,0.157
151.50,133.85,0.157
151.52,134.07,0.157
151.54,134.29,0.157
151.56,134.51,0.157
151.58,134.72,0.157
151.60,134.94,0.157
151.63,135.16,0.157
151.65,135.37,0.157
151.67,135.59,0.157
151.69,135.81,0.157
151.71,136.02,0.157
151.73,136.24,0.157
151.75,136.46,0.157
151.78,136.67,0.157
151.80,136.89,0.157
151.82,137.11,0.157
151.84,137.32,0.157
151.86,137.54,0.157
151.88,137.76,0.157
151.91,137.97,0.157
151.93,138.19,0.157
151.95,138.41,0.157
151.97,138.63,0.157
151.99,138.84,0.157
152.02,139.06,0.157
152.04,139.28,0.157
152.06,139.49,0.157
152.08,139.71,0.157
152.10,139.93,0.158
152.12,140.14,0.158
152.15,140.36,0.158
152.17,140.58,0.158
152.19,140.79,0.158
152.21,141.01,0.158
152.23,141.23,0.158
152.25,141.44,0.158
152.28,141.66,0.158
152.30,141.88,0.158
152.32,142.09,0.158
152.34,142.31,0.158
152.36,142.53,0.158
152.38,142.74,0.158
152.40,142.96,0.158
152.43,143.18,0.158
152.45,143.40,0.158
152.47,143.61,0.158
152.49,143.83,0.158
152.51,144.05,0.158
152.53,144.26,0.158
152.56,144.48,0.158
152.58,144.70,0.158
152.60,144.91,0.158
152.62,145.13,0.158
152.64,145.35,0.158
152.67,145.56,0.158
152.69,145.78,0.158
152.71,146.00,0.158
152.73,146.21,0.158
152.75,146.43,0.158
152.77,146.65,0.158
152.80,146.87,0.159
152.82,147.08,0.159
152.84,147.30,0.159
152.86,147.52,0.159
152.88,147.73,0.159
152.90,147.95,0.159
152.93,148.17,0.159
152.95,148.38,0.159
152.97,148.60,0.159
152.99,148.82,0.159
153.01,149.03,0.159
153.03,149.25,0.159
153.05,149.47,0.159
153.08,149.68,0.159
153.10,149.90,0.159
153.12,150.12,0.159
153.14,150.33,0.159
153.16,150.55,0.159
153.18,150.77,0.159
153.21,150.98,0.159
153.23,151.20,0.159
153.25,151.42,0.159
153.27,151.63,0.159
153.29,151.85,0.159
153.32,152.07,0.159
153.34,152.29,0.159
153.36,152.50,0.159
153.38,152.72,0.159
153.40,152.94,0.159
153.42,153.15,0.160
153.45,153.37,0.160
153.47,153.59,0.160
153.49,153.80,0.160
153.51,154.02,0.160
153.53,154.24,0.160
153.55,154.45,0.160
153.58,154.67,0.160
153.60,154.89,0.160
153.62,155.10,0.160
153.64,155.32,0.160
153.66,155.54,0.160
153.68,155.75,0.160
153.70,155.97,0.160
153.73,156.19,0.160
153.75,156.41,0.160
153.77,156.62,0.160
153.79,156.84,0.160
153.81,157.06,0.160
153.83,157.27,0.160
153.86,157.49,0.160
153.88,157.70,0.160
153.90,157.92,0.160
153.92,158.14,0.160
153.94,158.35,0.160
153.97,158.57,0.160
153.99,158.79,0.160
154.01,159.01,0.160
154.03,159.22,0.160
154.05,159.44,0.161
154.07,159.66,0.161
154.10,159.87,0.161
154.12,160.09,0.161
154.14,160.31,0.161
154.16,160.52,0.161
154.18,160.74,0.161
154.20,160.96,0.161
154.23,161.17,0.161
154.25,161.39,0.161
154.27,161.61,0.161
154.29,161.82,0.161
154.31,162.04,0.161
154.33,162.26,0.161
154.35,162.47,0.161
154.38,162.69,0.161
154.40,162.91,0.161
154.42,163.12,0.161
154.44,163.34,0.161
154.46,163.56,0.161
154.48,163.78,0.161
154.51,163.99,0.161
154.53,164.21,0.161
154.55,164.43,0.161
154.57,164.64,0.161
154.59,164.86,0.161
154.62,165.08,0.161
154.64,165.29,0.161
154.66,165.51,0.161
154.68,165.73,0.161
154.70,165.94,0.161
154.72,166.16,0.161
154.75,166.38,0.161
154.77,166.60,0.161
154.79,166.81,0.162
154.81,167.03,0.162
154.83,167.25,0.162
154.85,167.46,0.162
154.88,167.68,0.162
154.90,167.90,0.162
154.92,168.11,0.162
154.94,168.33,0.162
154.96,168.55,0.162
154.98,168.76,0.162
155.00,168.98,0.162
155.03,169.20,0.162
155.05,169.41,0.162
155.07,169.63,0.162
155.09,169.85,0.162
155.11,170.06,0.162
155.13,170.28,0.162
155.16,170.50,0.162
155.18,170.72,0.162
155.20,170.93,0.162
155.22,171.15,0.162
155.24,171.37,0.162
155.27,171.58,0.162
155.29,171.80,0.162
155.31,172.02,0.162
155.33,172.23,0.162
155.35,172.45,0.162
155.37,172.67,0.163
155.40,172.88,0.163
155.42,173.10,0.163
155.44,173.32,0.163
155.46,173.53,0.163
155.48,173.75,0.163
155.50,173.97,0.163
155.53,174.18,0.163
155.55,174.40,0.163
155.57,174.62,0.163
155.59,174.83,0.163
155.61,175.05,0.163
155.63,175.27,0.163
155.65,175.49,0.163
155.68,175.70,0.163
155.70,175.92,0.163
155.72,176.14,0.163
155.74,176.35,0.163
155.76,176.57,0.163
155.78,176.79,0.163
155.81,177.00,0.163
155.83,177.22,0.163
155.85,177.44,0.164
155.87,177.65,0.164
155.89,177.87,0.164
155.92,178.09,0.164
155.94,178.30,0.164
155.96,178.52,0.164
155.98,178.74,0.164
156.00,178.95,0.164
156.02,179.17,0.164
156.05,179.39,0.164
156.07,179.60,0.164
156.09,179.82,0.164
156.11,180.04,0.164
156.13,180.26,0.164
156.15,180.47,0.164
156.18,180.69,0.164
156.20,180.90,0.164
156.22,181.12,0.164
156.24,181.34,0.164
156.26,181.56,0.164
156.28,181.77,0.164
156.30,181.99,0.164
156.33,182.21,0.164
156.35,182.42,0.164
156.37,182.64,0.164
156.39,182.86,0.164
156.41,183.07,0.164
156.43,183.29,0.164
156.46,183.51,0.164
156.48,183.72,0.164
156.50,183.94,0.164
156.52,184.16,0.164
156.54,184.37,0.164
156.57,184.59,0.164
156.59,184.81,0.164
156.61,185.03,0.164
156.63,185.24,0.165
156.65,185.46,0.165
156.67,185.68,0.165
156.70,185.89,0.165
156.72,186.11,0.165
156.74,186.33,0.165
156.76,186.54,0.165
156.78,186.76,0.165
156.80,186.98,0.165
156.83,187.19,0.165
156.85,187.41,0.165
156.87,187.63,0.165
156.89,187.84,0.165
156.91,188.06,0.165
156.93,188.28,0.165
156.95,188.49,0.165
156.98,188.71,0.165
157.00,188.93,0.165
157.02,189.14,0.165
157.04,189.36,0.165
157.06,189.58,0.165
157.08,189.80,0.165
157.11,190.01,0.165
157.13,190.23,0.165
157.15,190.45,0.165
157.17,190.66,0.165
157.19,190.88,0.165
157.22,191.10,0.165
157.24,191.31,0.165
157.26,191.53,0.165
157.28,191.75,0.165
157.30,191.96,0.165
157.32,192.18,0.166
157.35,192.40,0.166
157.37,192.61,0.166
157.39,192.83,0.166
157.41,193.05,0.166
157.43,193.26,0.166
157.45,193.48,0.166
157.48,193.70,0.166
157.50,193.91,0.166
157.52,194.13,0.166
157.54,194.35,0.166
157.56,194.56,0.166
157.58,194.78,0.166
157.60,195.00,0.166
157.63,195.22,0.166
157.65,195.43,0.166
157.67,195.65,0.166
157.69,195.86,0.166
157.71,196.08,0.166
157.73,196.30,0.166
157.76,196.52,0.166
157.78,196.73,0.166
157.80,196.95,0.166
157.82,197.17,0.166
157.84,197.38,0.166
157.87,197.60,0.166
157.89,197.81,0.166
157.91,198.03,0.166
157.93,198.25,0.166
157.95,198.46,0.166
157.97,198.68,0.166
158.00,198.90,0.166
158.02,199.12,0.166
158.04,199.33,0.166
158.06,199.55,0.167
158.08,199.77,0.167
158.10,199.99,0.167
158.13,200.20,0.167
158.15,200.42,0.167
158.17,200.63,0.167
158.19,200.85,0.167
158.21,201.07,0.167
158.23,201.29,0.167
158.25,201.50,0.167
158.28,201.72,0.167
158.30,201.93,0.167
158.32,202.15,0.167
158.34,202.37,0.167
158.36,202.58,0.167
158.38,202.80,0.167
158.41,203.02,0.167
158.43,203.24,0.167
158.45,203.45,0.167
158.47,203.67,0.167
158.49,203.89,0.167
158.52,204.10,0.167
158.54,204.32,0.167
158.56,204.54,0.167
158.58,204.75,0.167
158.60,204.97,0.167
158.62,205.19,0.167
158.65,205.40,0.167
158.67,205.62,0.167
158.69,205.84,0.167
158.71,206.06,0.167
158.73,206.27,0.168
158.75,206.49,0.168
158.78,206.71,0.168
158.80,206.92,0.168
158.82,207.14,0.168
158.84,207.36,0.168
158.86,207.57,0.168
158.88,207.79,0.168
158.90,208.01,0.168
158.93,208.22,0.168
158.95,208.44,0.168
158.97,208.66,0.168
158.99,208.87,0.168
159.01,209.09,0.168
159.03,209.31,0.168
159.06,209.52,0.168
159.08,209.74,0.168
159.10,209.96,0.168
159.12,210.17,0.168
159.14,210.39,0.168
159.17,210.61,0.168
159.19,210.83,0.168
159.21,211.04,0.168
159.23,211.26,0.168
159.25,211.48,0.168
159.27,211.69,0.168
159.30,211.91,0.168
159.32,212.12,0.169
159.34,212.34,0.168
159.36,212.56,0.168
159.38,212.77,0.168
159.40,212.99,0.168
159.43,213.21,0.169
159.45,213.43,0.169
159.47,213.64,0.169
159.49,213.86,0.169
159.51,214.07,0.169
159.53,214.29,0.169
159.55,214.51,0.169
159.58,214.73,0.169
159.60,214.94,0.169
159.62,215.16,0.169
159.64,215.38,0.169
159.66,215.60,0.169
159.68,215.81,0.169
159.71,216.03,0.169
159.73,216.25,0.169
159.75,216.46,0.169
159.77,216.68,0.169
159.79,216.89,0.169
159.82,217.11,0.169
159.84,217.33,0.169
159.86,217.55,0.169
159.88,217.76,0.169
159.90,217.98,0.169
159.92,218.20,0.169
159.95,218.41,0.169
159.97,218.63,0.169
159.99,218.85,0.169
160.01,219.06,0.169
160.03,219.28,0.169
160.05,219.50,0.169
160.08,219.71,0.169
160.10,219.93,0.169
160.12,220.15,0.169
160.14,220.36,0.170
160.16,220.58,0.170
160.18,220.80,0.170
160.20,221.01,0.170
160.23,221.23,0.170
160.25,221.45,0.170
160.27,221.66,0.170
160.29,221.88,0.170
160.31,222.10,0.170
160.33,222.31,0.170
160.36,222.53,0.170
160.38,222.75,0.170
160.40,222.96,0.170
160.42,223.18,0.170
160.44,223.40,0.170
160.47,223.62,0.170
160.49,223.83,0.170
160.51,224.05,0.170
160.53,224.27,0.170
160.55,224.49,0.170
160.57,224.70,0.170
160.60,224.92,0.170
160.62,225.14,0.170
160.64,225.35,0.170
160.66,225.57,0.170
160.68,225.78,0.170
160.70,226.00,0.170
160.73,226.22,0.170
160.75,226.43,0.170
160.77,226.65,0.170
160.79,226.87,0.170
160.81,227.08,0.170
160.83,227.30,0.170
160.85,227.52,0.170
160.88,227.73,0.170
160.90,227.95,0.170
160.92,228.17,0.170
160.94,228.38,0.170
160.96,228.60,0.170
160.98,228.82,0.170
161.01,229.03,0.170
161.03,229.25,0.170
161.05,229.47,0.170
161.07,229.69,0.170
161.09,229.90,0.170
161.12,230.12,0.170
161.14,230.34,0.170
161.16,230.55,0.170
161.18,230.77,0.171
161.20,230.99,0.171
161.22,231.20,0.170
161.25,231.42,0.170
161.27,231.64,0.170
161.29,231.86,0.170
161.31,232.07,0.170
161.33,232.29,0.170
161.35,232.51,0.170
161.38,232.72,0.170
161.40,232.94,0.170
161.42,233.16,0.170
161.44,233.37,0.170
161.46,233.59,0.170
161.48,233.81,0.170
161.50,234.02,0.170
161.53,234.24,0.170
161.55,234.46,0.170
161.57,234.67,0.170
161.59,234.89,0.171
161.61,235.11,0.171
161.63,235.32,0.171
161.66,235.54,0.171
161.68,235.76,0.171
161.70,235.97,0.171
161.72,236.19,0.171
161.74,236.41,0.171
161.77,236.62,0.171
161.79,236.84,0.171
161.81,237.06,0.171
161.83,237.27,0.171
161.85,237.49,0.171
161.87,237.71,0.171
161.90,237.92,0.171
161.92,238.14,0.171
161.94,238.36,0.171
161.96,238.57,0.171
161.98,238.79,0.171
162.00,239.01,0.171
162.03,239.22,0.171
162.05,239.44,0.171
162.07,239.66,0.171
162.09,239.87,0.171
162.11,240.09,0.171
162.13,240.31,0.171
162.15,240.53,0.171
162.18,240.74,0.171
162.20,240.96,0.171
162.22,241.17,0.171
162.24,241.39,0.171
162.26,241.61,0.171
162.28,241.83,0.171
162.31,242.04,0.171
162.33,242.26,0.171
162.35,242.48,0.171
162.37,242.69,0.172
162.39,242.91,0.172
162.42,243.13,0.172
162.44,243.34,0.172
162.46,243.56,0.172
162.48,243.78,0.172
162.50,243.99,0.172
162.52,244.21,0.172
162.55,244.43,0.172
162.57,244.64,0.172
162.59,244.86,0.172
162.61,245.08,0.172
162.63,245.29,0.172
162.65,245.51,0.172
162.68,245.73,0.172
162.70,245.95,0.172
162.72,246.16,0.172
162.74,246.38,0.172
162.76,246.60,0.172
162.78,246.81,0.172
162.80,247.03,0.172
162.83,247.25,0.172
162.85,247.46,0.172
162.87,247.68,0.172
162.89,247.90,0.172
162.91,248.11,0.172
162.93,248.33,0.172
162.96,248.55,
162.98,248.76,
162.99,,