File: DSC/Olivia/2025_07_17_1CBN_3PVP10kDa_MeOH_n60_180_5Cmin_x4.csv
Filename,2025_07_17_1CBN_3PVP10kDa_MeOH_n60_180_5Cmin_x4
Instrument name,DSC2A-00468 (192.168.1.100)
Operator,Gibbons
rundate,7/17/2025
Sample name,2025_07_17_1CBN_3PVP10kDa_MeOH_n60_180_5Cmin_x4
proceduresegments,Data Off ; Equilibrate -60.00 °C; Data On ; Ramp 5.00 °C/min to 160.00 °C; Data Off ; Isothermal 2.0 min; Data On ; Ramp 5.00 °C/min to -60.00 °C; Data Off ; Isothermal 2.0 min; Data On ; Ramp 5.00 °C/min to 160.00 °C; Data Off ; Isothermal 2.0 min; Data On ; Ramp 5.00 °C/min to 60.00 °C; Data Off ; Isothermal 2.0 min; Data On ; Ramp 5.00 °C/min to 160.00 °C; Data Off ; Isothermal 2.0 min; Data On ; Ramp 5.00 °C/min to -60.00 °C; Data Off ; Isothermal 2.0 min; Data On ; Ramp 5.00 °C/min to 30.00 °C
[File Parameters]
Run date,7/17/2025 10:02:46 AM
Trios version,5.1.1.46572
Original File Name,D:\DSC2500\Gibbons\2025_07_17_1CBN_3PVP10kDa_MeOH_n60_180_5Cmin_x4.tri
Current File Name,D:\DSC2500\Gibbons\2025_07_17_1CBN_3PVP10kDa_MeOH_n60_180_5Cmin_x4.tri
[Procedure]
Procedure Name,1CBN_3PVP10kDa_MeOH_n60_180_5Cmin_x4
Sample Name,2025_07_17_1CBN_3PVP10kDa_MeOH_n60_180_5Cmin_x4
Sample Mass,9.28 mg
Reference Sample Mass,0 mg
Pan Mass,56.32 mg
Pan Number,21
Reference Pan Mass,56.6 mg
Reference Pan Number,1
Pan Type,Tzero Aluminum Hermetic
Comments,DSC Consumables Al Hermetically Sealed Pan. A2 Tray (Google Sheet: DSC_Samples_A2_Tray_July2025).
Project Name,Pharmaceuticals - Cannabinoids
Operator,Gibbons
Test,Custom
Unload Max Temperature,30
Unload Min Temperature,30
Load Max Temperature,30
Load Min Temperature,30
Stop on Gas Flow Error,Yes
[Signal List]
Signal #1,Time (min)
Signal #2,Temperature (°C)
Signal #3,Heat Flow (mW)
Signal #4,Delta T (µV)
Signal #5,Delta Tzero (µV)
Signal #6,Tzero Temperature (°C)
Signal #7,Cell Purge (mL/min)
Signal #8,Heater Temp (°C)
Signal #9,Power Delivered (W)
Signal #10,Reference Junction Temperature (°C)
Signal #11,Flange Temperature (°C)
Signal #12,Heat Flow Phase (rad)
Signal #13,Total Heat Capacity (J/°C)
Signal #14,Heat Capacity (J/°C)
[Configuration]
Company Name,ASU
Instrument Name,DSC2A-00468
Instrument Type,DSC2500
Serial Number,DSC2A-00468
IP,192.168.1.100
Location of Instrument,MRRC
DisplayType,Unknown
Sample Interval ,0.1 s/pt
Selected Heat Flow,T4P
Exotherm Direction,Down
Cell Serial,DRC2-00792
Lid Type,Standard
Cooler,RCS 90
Leave Cooler on at End of Sequence,On
Gas 2,Nitrogen
Gas Selected,Channel 1
Flow Rate,50 mL/min
Secondary Purge,On
Licensed Heat Flow,Heat Flow T4P
Modulation Licensed,Yes
[Versions]
Common IDD Version,1
Cortex Version,VER 2.10.2.31
Driver,5.0.0.6
GDM Version,1.0.3.3
TouchscreenVersion,1.0.0.16145
FEP Version,1.2.1.21
FEP Bootloader,2.0.0.5
AutoSampler Version,2.1.1.26
Auto Sampler Bootloader,2.0.0.5
FCM Version,1.1.0.3
FCM Bootloader,2.0.0.5
[Experiment Logs]
Experiment Log Entry # 1,Data On set to 0
Experiment Log Entry # 3,Equilibrate Segment -60 (C) Started
Experiment Log Entry # 5,Air Cool is off.
Experiment Log Entry # 7,Data On set to 1
Experiment Log Entry # 9,Ramp Segment 5 C/min to 180 Started
Experiment Log Entry # 11,Ramp Segment 5 C/min to 160 Started
Experiment Log Entry # 13,User modified running procedure
Experiment Log Entry # 15,Data On set to 0
Experiment Log Entry # 17,Isothermal Segment 2 min started
Experiment Log Entry # 19,Data On set to 1
Experiment Log Entry # 21,Ramp Segment 5 C/min to -60 Started
Experiment Log Entry # 23,Data On set to 0
Experiment Log Entry # 25,Isothermal Segment 2 min started
Experiment Log Entry # 27,Data On set to 1
Experiment Log Entry # 29,Ramp Segment 5 C/min to 160 Started
Experiment Log Entry # 31,Data On set to 0
Experiment Log Entry # 33,Isothermal Segment 2 min started
Experiment Log Entry # 35,Data On set to 1
Experiment Log Entry # 37,Ramp Segment 5 C/min to 60 Started
Experiment Log Entry # 39,Auto sampler has detected that GDM has gone offline
Experiment Log Entry # 41,Data On set to 0
Experiment Log Entry # 43,Isothermal Segment 2 min started
Experiment Log Entry # 45,Data On set to 1
Experiment Log Entry # 47,Ramp Segment 5 C/min to 160 Started
Experiment Log Entry # 49,Data On set to 0
Experiment Log Entry # 51,Isothermal Segment 2 min started
Experiment Log Entry # 53,Data On set to 1
Experiment Log Entry # 55,Ramp Segment 5 C/min to -60 Started
Experiment Log Entry # 57,Data On set to 0
Experiment Log Entry # 59,Isothermal Segment 2 min started
Experiment Log Entry # 61,Data On set to 1
Experiment Log Entry # 63,Ramp Segment 5 C/min to 30 Started
[Method Log]
Method Log Entry # 1,Data Off
Method Log Entry # 2,Equilibrate -60 °C
Method Log Entry # 3,Data On
Method Log Entry # 4,(Ramp 259660) Ramp 5 °C/minute to 160 °C
Method Log Entry # 5,Data Off
Method Log Entry # 6,Isothermal 2 minutes
Method Log Entry # 7,Data On
Method Log Entry # 8,(Ramp 259664) Ramp 5 °C/minute to -60 °C
Method Log Entry # 9,Data Off
Method Log Entry # 10,Isothermal 2 minutes
Method Log Entry # 11,Data On
Method Log Entry # 12,(Ramp 259668) Ramp 5 °C/minute to 160 °C
Method Log Entry # 13,Data Off
Method Log Entry # 14,Isothermal 2 minutes
Method Log Entry # 15,Data On
Method Log Entry # 16,(Ramp 259672) Ramp 5 °C/minute to 60 °C
Method Log Entry # 17,Data Off
Method Log Entry # 18,Isothermal 2 minutes
Method Log Entry # 19,Data On
Method Log Entry # 20,(Ramp 259676) Ramp 5 °C/minute to 160 °C
Method Log Entry # 21,Data Off
Method Log Entry # 22,Isothermal 2 minutes
Method Log Entry # 23,Data On
Method Log Entry # 24,(Ramp 259680) Ramp 5 °C/minute to -60 °C
Method Log Entry # 25,Data Off
Method Log Entry # 26,Isothermal 2 minutes
Method Log Entry # 27,Data On
Method Log Entry # 28,(Ramp 259684) Ramp 5 °C/minute to 30 °C
Cell Serial,DRC2-00792
[T1 Calibration]
Slope,-0.008529666
Offset,9.636258
Initial Temperature,98.23
GUID,f8bfdadc-4977-4fdf-ba6d-0ba9134940c3
[TZero Calibration]
Date Applied,11/29/2022 4:06:13 PM
Description,From -89.059 °C to 396.009 °C at 20.000°C/min
Gas Type,Nitrogen
Pan Type,None
Source Files 1,C:\Users\yargerlab\Desktop\DSC Data\General\TZero_calibration_11_29_22_2nd(2).tri
Source Files 2,C:\Users\yargerlab\Desktop\DSC Data\General\TZero_calibration_11_29_22_2nd(3).tri
Delta T Offset,13.05235
Delta T Slope,-0.007271007
Delta T0 Offset,-13.69128
Delta T0 Slope,0.06063341
[Temperature Calibration]
Date Applied,11/29/2022 7:12:28 PM
Description,From 106.590 °C to 186.590 °C at 10.000°C/min
Gas Type,Nitrogen
Pan Type,Tzero Aluminum Hermetic
Source Files 1,C:\Users\yargerlab\Desktop\DSC Data\General\Indium(6).tri
Measured 1,157.391
Known 1,156.598
[Cell Constant Calibration]
Date Applied,11/29/2022 7:12:29 PM
Description,From 106.590 °C to 186.590 °C at 10.000°C/min
Gas Type,Nitrogen
Pan Type,Tzero Aluminum Hermetic
Source Files 1,C:\Users\yargerlab\Desktop\DSC Data\General\Indium(6).tri
T4P KCell,1.006051
Onset Slope,63.26126 mW/°C
[Direct Cp Calibration]
Date Applied,11/30/2022 11:04:51 AM
Description,From -79.983 °C to 298.409 °C at 10.000°C/min
Gas Type,Nitrogen
Pan Type,Tzero Aluminum Hermetic
Source Files 1,C:\Users\yargerlab\Desktop\DSC Data\General\Sapphire_Heat_Capacity_11_30_22.tri
[Rev Cp Calibration]
Date Applied,11/30/2022 1:58:51 PM
Description,From -79.996 °C to 292.812 °C at 3.000°C/min
Gas Type,Nitrogen
Pan Type,Tzero Aluminum Hermetic
Source Files 1,C:\Users\yargerlab\Desktop\DSC Data\General\Sapphire_MDSC_Calibration_11_30_22.tri
[step]
Ramp 5.00 °C/min to 160.00 °C
Time,Temperature,Heat Flow (Normalized)
min,°C,W/g
0.00,-59.71,-0.036
0.03,-59.73,-0.035
0.06,-59.74,-0.026
0.09,-59.72,-0.015
0.12,-59.67,-0.003
0.15,-59.59,0.012
0.18,-59.49,0.027
0.21,-59.39,0.039
0.24,-59.27,0.050
0.27,-59.15,0.058
0.30,-59.02,0.065
0.33,-58.89,0.069
0.36,-58.75,0.073
0.39,-58.62,0.076
0.42,-58.48,0.079
0.45,-58.33,0.081
0.48,-58.19,0.082
0.51,-58.05,0.083
0.54,-57.91,0.084
0.57,-57.76,0.085
0.60,-57.62,0.086
0.63,-57.47,0.086
0.66,-57.32,0.086
0.69,-57.18,0.087
0.72,-57.03,0.087
0.75,-56.88,0.087
0.78,-56.73,0.087
0.81,-56.59,0.088
0.84,-56.44,0.088
0.87,-56.29,0.088
0.90,-56.14,0.088
0.93,-55.99,0.088
0.96,-55.85,0.089
0.99,-55.70,0.089
1.02,-55.55,0.089
1.05,-55.40,0.089
1.08,-55.25,0.089
1.11,-55.10,0.089
1.14,-54.95,0.089
1.17,-54.80,0.089
1.20,-54.65,0.090
1.23,-54.50,0.090
1.26,-54.36,0.090
1.29,-54.21,0.090
1.32,-54.06,0.090
1.35,-53.91,0.090
1.38,-53.76,0.090
1.41,-53.61,0.090
1.44,-53.46,0.090
1.47,-53.31,0.090
1.50,-53.16,0.090
1.53,-53.01,0.090
1.56,-52.86,0.090
1.59,-52.71,0.090
1.62,-52.56,0.090
1.65,-52.41,0.090
1.68,-52.26,0.090
1.71,-52.11,0.090
1.74,-51.96,0.090
1.77,-51.81,0.090
1.80,-51.66,0.090
1.83,-51.51,0.090
1.86,-51.36,0.090
1.89,-51.21,0.090
1.92,-51.06,0.090
1.95,-50.91,0.090
1.98,-50.77,0.090
2.01,-50.61,0.090
2.04,-50.47,0.090
2.07,-50.31,0.091
2.10,-50.17,0.091
2.13,-50.01,0.091
2.16,-49.86,0.091
2.19,-49.72,0.091
2.22,-49.56,0.091
2.25,-49.41,0.091
2.28,-49.26,0.091
2.31,-49.11,0.091
2.34,-48.97,0.091
2.37,-48.82,0.091
2.40,-48.67,0.091
2.43,-48.52,0.091
2.46,-48.37,0.091
2.49,-48.22,0.091
2.52,-48.07,0.091
2.55,-47.92,0.091
2.58,-47.77,0.091
2.61,-47.62,0.091
2.64,-47.47,0.091
2.67,-47.32,0.091
2.70,-47.17,0.091
2.73,-47.02,0.091
2.76,-46.87,0.091
2.79,-46.72,0.091
2.82,-46.57,0.091
2.85,-46.42,0.091
2.88,-46.27,0.091
2.91,-46.12,0.091
2.94,-45.97,0.091
2.97,-45.82,0.091
3.00,-45.67,0.091
3.03,-45.52,0.091
3.06,-45.37,0.091
3.09,-45.22,0.091
3.12,-45.07,0.091
3.15,-44.92,0.091
3.18,-44.77,0.091
3.21,-44.62,0.091
3.24,-44.47,0.091
3.27,-44.32,0.091
3.30,-44.17,0.091
3.33,-44.02,0.091
3.36,-43.87,0.091
3.39,-43.72,0.091
3.42,-43.57,0.091
3.45,-43.42,0.091
3.48,-43.27,0.091
3.51,-43.12,0.091
3.54,-42.97,0.091
3.57,-42.82,0.092
3.60,-42.67,0.092
3.63,-42.52,0.091
3.66,-42.37,0.092
3.69,-42.22,0.092
3.72,-42.07,0.092
3.75,-41.92,0.092
3.78,-41.77,0.092
3.81,-41.62,0.092
3.84,-41.47,0.092
3.87,-41.32,0.092
3.90,-41.17,0.092
3.93,-41.02,0.092
3.96,-40.87,0.092
3.99,-40.72,0.092
4.02,-40.57,0.092
4.05,-40.42,0.092
4.08,-40.27,0.092
4.11,-40.12,0.092
4.14,-39.97,0.092
4.17,-39.82,0.092
4.20,-39.67,0.092
4.23,-39.52,0.092
4.26,-39.37,0.092
4.29,-39.22,0.092
4.32,-39.07,0.092
4.35,-38.92,0.092
4.38,-38.77,0.092
4.41,-38.61,0.092
4.44,-38.47,0.092
4.47,-38.31,0.092
4.50,-38.16,0.093
4.53,-38.01,0.093
4.56,-37.86,0.093
4.59,-37.71,0.093
4.62,-37.56,0.093
4.65,-37.41,0.093
4.68,-37.26,0.093
4.71,-37.11,0.093
4.74,-36.96,0.093
4.77,-36.81,0.093
4.80,-36.66,0.093
4.83,-36.51,0.093
4.86,-36.36,0.093
4.89,-36.21,0.093
4.92,-36.06,0.093
4.95,-35.91,0.093
4.98,-35.76,0.093
5.01,-35.61,0.093
5.04,-35.46,0.093
5.07,-35.31,0.093
5.10,-35.16,0.093
5.13,-35.01,0.093
5.16,-34.86,0.093
5.19,-34.71,0.093
5.22,-34.56,0.093
5.25,-34.41,0.093
5.28,-34.26,0.093
5.31,-34.11,0.093
5.34,-33.96,0.094
5.37,-33.81,0.093
5.40,-33.66,0.094
5.43,-33.51,0.094
5.46,-33.36,0.094
5.49,-33.21,0.094
5.52,-33.06,0.094
5.55,-32.91,0.094
5.58,-32.76,0.094
5.61,-32.61,0.094
5.64,-32.46,0.094
5.67,-32.31,0.094
5.70,-32.16,0.094
5.73,-32.01,0.094
5.76,-31.86,0.094
5.79,-31.70,0.094
5.82,-31.55,0.094
5.85,-31.41,0.094
5.88,-31.25,0.094
5.91,-31.11,0.094
5.94,-30.95,0.094
5.97,-30.80,0.094
6.00,-30.66,0.094
6.03,-30.51,0.094
6.06,-30.36,0.094
6.09,-30.21,0.094
6.12,-30.06,0.094
6.15,-29.91,0.094
6.18,-29.76,0.094
6.21,-29.61,0.094
6.24,-29.46,0.094
6.27,-29.31,0.094
6.30,-29.16,0.094
6.33,-29.01,0.095
6.36,-28.86,0.095
6.39,-28.71,0.095
6.42,-28.56,0.095
6.45,-28.41,0.095
6.48,-28.26,0.095
6.51,-28.11,0.095
6.54,-27.96,0.095
6.57,-27.80,0.095
6.60,-27.65,0.095
6.63,-27.50,0.095
6.66,-27.35,0.095
6.69,-27.20,0.095
6.72,-27.05,0.095
6.75,-26.90,0.096
6.78,-26.75,0.096
6.81,-26.60,0.096
6.84,-26.45,0.096
6.87,-26.30,0.096
6.90,-26.15,0.096
6.93,-26.00,0.096
6.96,-25.85,0.096
6.99,-25.70,0.096
7.02,-25.55,0.096
7.05,-25.40,0.096
7.08,-25.25,0.096
7.11,-25.10,0.096
7.14,-24.95,0.096
7.17,-24.80,0.096
7.20,-24.65,0.096
7.23,-24.50,0.096
7.26,-24.35,0.096
7.29,-24.20,0.096
7.32,-24.05,0.096
7.35,-23.90,0.096
7.38,-23.75,0.096
7.41,-23.60,0.096
7.44,-23.45,0.096
7.47,-23.30,0.096
7.50,-23.15,0.096
7.53,-23.00,0.096
7.56,-22.85,0.096
7.59,-22.70,0.097
7.62,-22.55,0.097
7.65,-22.39,0.097
7.68,-22.25,0.097
7.71,-22.10,0.097
7.74,-21.95,0.097
7.77,-21.80,0.097
7.80,-21.65,0.097
7.83,-21.50,0.097
7.86,-21.34,0.097
7.89,-21.19,0.097
7.92,-21.04,0.097
7.95,-20.89,0.097
7.98,-20.74,0.097
8.01,-20.59,0.097
8.04,-20.45,0.097
8.07,-20.29,0.097
8.10,-20.14,0.097
8.13,-19.99,0.097
8.16,-19.84,0.097
8.19,-19.69,0.097
8.22,-19.54,0.098
8.25,-19.39,0.098
8.28,-19.24,0.098
8.31,-19.09,0.098
8.34,-18.94,0.098
8.37,-18.79,0.098
8.40,-18.64,0.098
8.43,-18.49,0.098
8.46,-18.34,0.098
8.49,-18.19,0.098
8.52,-18.04,0.098
8.55,-17.89,0.098
8.58,-17.74,0.098
8.61,-17.59,0.098
8.64,-17.44,0.098
8.67,-17.29,0.098
8.70,-17.14,0.098
8.73,-16.99,0.098
8.76,-16.84,0.098
8.79,-16.69,0.098
8.82,-16.54,0.099
8.85,-16.39,0.099
8.88,-16.24,0.099
8.91,-16.09,0.099
8.94,-15.94,0.099
8.97,-15.79,0.099
9.00,-15.64,0.099
9.03,-15.49,0.099
9.06,-15.34,0.099
9.09,-15.19,0.099
9.12,-15.04,0.099
9.15,-14.89,0.099
9.18,-14.74,0.099
9.21,-14.59,0.099
9.24,-14.44,0.099
9.27,-14.29,0.099
9.30,-14.14,0.099
9.33,-13.99,0.099
9.36,-13.84,0.099
9.39,-13.69,0.099
9.42,-13.54,0.099
9.45,-13.39,0.099
9.48,-13.24,0.099
9.51,-13.09,0.100
9.54,-12.94,0.100
9.57,-12.79,0.100
9.60,-12.64,0.100
9.63,-12.49,0.100
9.66,-12.34,0.100
9.69,-12.19,0.100
9.72,-12.04,0.100
9.75,-11.89,0.100
9.78,-11.74,0.100
9.81,-11.59,0.100
9.84,-11.44,0.100
9.87,-11.29,0.100
9.90,-11.14,0.100
9.93,-10.99,0.100
9.96,-10.84,0.100
9.99,-10.68,0.100
10.02,-10.53,0.100
10.05,-10.39,0.100
10.08,-10.23,0.101
10.11,-10.09,0.101
10.14,-9.94,0.101
10.17,-9.79,0.101
10.20,-9.64,0.101
10.23,-9.48,0.101
10.26,-9.33,0.101
10.29,-9.18,0.101
10.32,-9.04,0.101
10.35,-8.89,0.101
10.38,-8.73,0.101
10.41,-8.58,0.101
10.44,-8.44,0.101
10.47,-8.29,0.101
10.50,-8.13,0.101
10.53,-7.98,0.101
10.56,-7.83,0.101
10.59,-7.68,0.101
10.62,-7.53,0.101
10.65,-7.38,0.101
10.68,-7.23,0.101
10.71,-7.08,0.102
10.74,-6.93,0.102
10.77,-6.78,0.102
10.80,-6.63,0.102
10.83,-6.48,0.102
10.86,-6.33,0.102
10.89,-6.18,0.102
10.92,-6.03,0.102
10.95,-5.88,0.102
10.98,-5.73,0.102
11.01,-5.58,0.102
11.04,-5.43,0.102
11.07,-5.28,0.102
11.10,-5.13,0.102
11.13,-4.98,0.102
11.16,-4.83,0.102
11.19,-4.68,0.102
11.22,-4.53,0.102
11.25,-4.38,0.102
11.28,-4.23,0.102
11.31,-4.08,0.103
11.34,-3.93,0.103
11.37,-3.78,0.103
11.40,-3.63,0.103
11.43,-3.48,0.103
11.46,-3.33,0.103
11.49,-3.18,0.103
11.52,-3.03,0.103
11.55,-2.88,0.103
11.58,-2.73,0.103
11.61,-2.58,0.103
11.64,-2.43,0.103
11.67,-2.28,0.103
11.70,-2.13,0.103
11.73,-1.98,0.103
11.76,-1.83,0.103
11.79,-1.68,0.103
11.82,-1.53,0.103
11.85,-1.38,0.103
11.88,-1.23,0.104
11.91,-1.08,0.104
11.94,-0.93,0.104
11.97,-0.78,0.104
12.00,-0.63,0.104
12.03,-0.48,0.104
12.06,-0.33,0.104
12.09,-0.18,0.104
12.12,-0.03,0.104
12.15,0.12,0.104
12.18,0.27,0.104
12.21,0.42,0.104
12.24,0.57,0.104
12.27,0.72,0.104
12.30,0.88,0.104
12.33,1.03,0.104
12.36,1.18,0.105
12.39,1.33,0.105
12.42,1.48,0.105
12.45,1.64,0.105
12.48,1.78,0.105
12.51,1.93,0.105
12.54,2.08,0.105
12.57,2.23,0.105
12.60,2.38,0.105
12.63,2.53,0.105
12.66,2.68,0.105
12.69,2.83,0.105
12.72,2.98,0.105
12.75,3.13,0.105
12.78,3.28,0.105
12.81,3.43,0.105
12.84,3.58,0.105
12.87,3.73,0.105
12.90,3.88,0.105
12.93,4.03,0.105
12.96,4.18,0.105
12.99,4.33,0.105
13.02,4.48,0.105
13.05,4.63,0.105
13.08,4.78,0.105
13.11,4.93,0.105
13.14,5.08,0.105
13.17,5.23,0.106
13.20,5.38,0.106
13.23,5.53,0.106
13.26,5.68,0.106
13.29,5.83,0.106
13.32,5.98,0.106
13.35,6.13,0.106
13.38,6.28,0.106
13.41,6.43,0.106
13.44,6.58,0.106
13.47,6.73,0.106
13.50,6.88,0.106
13.53,7.03,0.106
13.56,7.18,0.106
13.59,7.33,0.106
13.62,7.48,0.106
13.65,7.63,0.107
13.68,7.78,0.107
13.71,7.93,0.107
13.74,8.08,0.107
13.77,8.23,0.107
13.80,8.38,0.107
13.83,8.53,0.107
13.86,8.68,0.107
13.89,8.83,0.107
13.92,8.98,0.107
13.95,9.13,0.107
13.98,9.28,0.107
14.01,9.43,0.107
14.04,9.58,0.107
14.07,9.73,0.107
14.10,9.88,0.107
14.13,10.03,0.108
14.16,10.18,0.108
14.19,10.33,0.108
14.22,10.48,0.108
14.25,10.63,0.108
14.28,10.78,0.108
14.31,10.93,0.108
14.34,11.08,0.108
14.37,11.23,0.108
14.40,11.38,0.108
14.43,11.53,0.108
14.46,11.68,0.108
14.49,11.83,0.108
14.52,11.98,0.108
14.55,12.13,0.108
14.58,12.28,0.108
14.61,12.43,0.108
14.64,12.58,0.108
14.67,12.73,0.109
14.70,12.88,0.109
14.73,13.03,0.109
14.76,13.18,0.109
14.79,13.33,0.109
14.82,13.48,0.109
14.85,13.63,0.109
14.88,13.78,0.109
14.91,13.94,0.109
14.94,14.09,0.109
14.97,14.24,0.109
15.00,14.38,0.109
15.03,14.53,0.109
15.06,14.69,0.109
15.09,14.83,0.110
15.12,14.99,0.110
15.15,15.14,0.110
15.18,15.29,0.110
15.21,15.44,0.110
15.24,15.59,0.110
15.27,15.73,0.110
15.30,15.89,0.110
15.33,16.04,0.110
15.36,16.19,0.110
15.39,16.34,0.110
15.42,16.49,0.110
15.45,16.64,0.110
15.48,16.79,0.110
15.51,16.94,0.110
15.54,17.09,0.111
15.57,17.24,0.111
15.60,17.39,0.111
15.63,17.54,0.111
15.66,17.69,0.111
15.69,17.84,0.111
15.72,17.99,0.111
15.75,18.14,0.111
15.78,18.29,0.111
15.81,18.43,0.111
15.84,18.59,0.111
15.87,18.73,0.111
15.90,18.88,0.111
15.93,19.03,0.111
15.96,19.18,0.111
15.99,19.33,0.112
16.02,19.48,0.112
16.05,19.63,0.112
16.08,19.78,0.112
16.11,19.93,0.112
16.14,20.09,0.112
16.17,20.24,0.112
16.20,20.39,0.112
16.23,20.54,0.112
16.26,20.69,0.112
16.29,20.84,0.112
16.32,20.99,0.112
16.35,21.14,0.112
16.38,21.29,0.112
16.41,21.44,0.113
16.44,21.59,0.113
16.47,21.74,0.113
16.50,21.89,0.113
16.53,22.04,0.113
16.56,22.19,0.113
16.59,22.34,0.113
16.62,22.49,0.113
16.65,22.64,0.113
16.68,22.79,0.113
16.71,22.94,0.113
16.74,23.09,0.113
16.77,23.24,0.113
16.80,23.39,0.113
16.83,23.54,0.114
16.86,23.69,0.114
16.89,23.84,0.114
16.92,23.99,0.114
16.95,24.14,0.114
16.98,24.29,0.114
17.01,24.44,0.114
17.04,24.59,0.114
17.07,24.74,0.114
17.10,24.89,0.114
17.13,25.04,0.114
17.16,25.19,0.114
17.19,25.34,0.114
17.22,25.49,0.115
17.25,25.64,0.115
17.28,25.79,0.115
17.31,25.94,0.115
17.34,26.09,0.115
17.37,26.24,0.115
17.40,26.39,0.115
17.43,26.54,0.115
17.46,26.69,0.115
17.49,26.84,0.115
17.52,26.99,0.115
17.55,27.14,0.115
17.58,27.29,0.115
17.61,27.44,0.116
17.64,27.59,0.116
17.67,27.74,0.116
17.70,27.89,0.116
17.73,28.04,0.116
17.76,28.19,0.116
17.79,28.34,0.116
17.82,28.49,0.116
17.85,28.64,0.116
17.88,28.79,0.116
17.91,28.94,0.116
17.94,29.09,0.117
17.97,29.24,0.117
18.00,29.39,0.117
18.03,29.54,0.117
18.06,29.69,0.117
18.09,29.84,0.117
18.12,29.99,0.117
18.15,30.14,0.117
18.18,30.29,0.117
18.21,30.44,0.117
18.24,30.59,0.118
18.27,30.74,0.118
18.30,30.89,0.118
18.33,31.05,0.118
18.36,31.20,0.118
18.39,31.35,0.118
18.42,31.50,0.118
18.45,31.64,0.118
18.48,31.80,0.118
18.51,31.95,0.118
18.54,32.09,0.118
18.57,32.25,0.119
18.60,32.40,0.119
18.63,32.55,0.119
18.66,32.70,0.119
18.69,32.85,0.119
18.72,33.00,0.119
18.75,33.15,0.119
18.78,33.30,0.119
18.81,33.45,0.119
18.84,33.60,0.119
18.87,33.75,0.119
18.90,33.90,0.120
18.93,34.05,0.120
18.96,34.20,0.120
18.99,34.35,0.120
19.02,34.50,0.120
19.05,34.65,0.120
19.08,34.80,0.120
19.11,34.95,0.120
19.14,35.10,0.120
19.17,35.25,0.120
19.20,35.40,0.121
19.23,35.55,0.121
19.26,35.70,0.121
19.29,35.85,0.121
19.32,36.00,0.121
19.35,36.15,0.121
19.38,36.30,0.121
19.41,36.45,0.121
19.44,36.60,0.121
19.47,36.75,0.122
19.50,36.90,0.122
19.53,37.05,0.122
19.56,37.20,0.122
19.59,37.35,0.122
19.62,37.50,0.122
19.65,37.65,0.122
19.68,37.80,0.123
19.71,37.95,0.123
19.74,38.10,0.123
19.77,38.25,0.123
19.80,38.40,0.123
19.83,38.55,0.123
19.86,38.70,0.123
19.89,38.85,0.123
19.92,39.00,0.124
19.95,39.15,0.124
19.98,39.30,0.124
20.01,39.45,0.124
20.04,39.60,0.124
20.07,39.75,0.124
20.10,39.90,0.124
20.13,40.05,0.125
20.16,40.20,0.125
20.19,40.35,0.125
20.22,40.50,0.125
20.25,40.65,0.125
20.28,40.80,0.125
20.31,40.95,0.126
20.34,41.10,0.126
20.37,41.25,0.126
20.40,41.40,0.126
20.43,41.55,0.126
20.46,41.70,0.127
20.49,41.85,0.127
20.52,42.00,0.127
20.55,42.15,0.127
20.58,42.30,0.127
20.61,42.45,0.127
20.64,42.60,0.128
20.67,42.75,0.128
20.70,42.90,0.128
20.73,43.05,0.128
20.76,43.20,0.129
20.79,43.35,0.129
20.82,43.50,0.129
20.85,43.65,0.129
20.88,43.80,0.130
20.91,43.95,0.130
20.94,44.10,0.130
20.97,44.25,0.130
21.00,44.40,0.131
21.03,44.55,0.131
21.06,44.70,0.131
21.09,44.85,0.132
21.12,45.00,0.132
21.15,45.15,0.132
21.18,45.30,0.132
21.21,45.45,0.133
21.24,45.60,0.133
21.27,45.75,0.133
21.30,45.90,0.134
21.33,46.05,0.134
21.36,46.20,0.134
21.39,46.35,0.135
21.42,46.50,0.135
21.45,46.65,0.135
21.48,46.80,0.136
21.51,46.95,0.136
21.54,47.10,0.136
21.57,47.25,0.137
21.60,47.40,0.137
21.63,47.55,0.137
21.66,47.70,0.138
21.69,47.85,0.138
21.72,48.00,0.138
21.75,48.15,0.139
21.78,48.30,0.139
21.81,48.45,0.140
21.84,48.60,0.140
21.87,48.75,0.140
21.90,48.89,0.141
21.93,49.04,0.141
21.96,49.19,0.142
21.99,49.34,0.142
22.02,49.49,0.142
22.05,49.64,0.143
22.08,49.79,0.143
22.11,49.94,0.143
22.14,50.09,0.144
22.17,50.24,0.144
22.20,50.39,0.145
22.23,50.54,0.145
22.26,50.69,0.145
22.29,50.84,0.146
22.32,50.99,0.146
22.35,51.14,0.147
22.38,51.29,0.147
22.41,51.44,0.147
22.44,51.59,0.148
22.47,51.74,0.148
22.50,51.89,0.149
22.53,52.04,0.149
22.56,52.19,0.149
22.59,52.34,0.150
22.62,52.49,0.150
22.65,52.64,0.150
22.68,52.79,0.151
22.71,52.94,0.151
22.74,53.09,0.151
22.77,53.24,0.152
22.80,53.39,0.152
22.83,53.54,0.152
22.86,53.69,0.152
22.89,53.84,0.153
22.92,53.99,0.153
22.95,54.14,0.153
22.98,54.29,0.154
23.01,54.44,0.154
23.04,54.59,0.155
23.07,54.74,0.155
23.10,54.89,0.155
23.13,55.04,0.156
23.16,55.19,0.156
23.19,55.34,0.157
23.22,55.49,0.157
23.25,55.64,0.157
23.28,55.79,0.158
23.31,55.94,0.158
23.34,56.09,0.159
23.37,56.24,0.159
23.40,56.39,0.160
23.43,56.54,0.160
23.46,56.69,0.161
23.49,56.84,0.161
23.52,56.99,0.162
23.55,57.14,0.163
23.58,57.29,0.163
23.61,57.44,0.164
23.64,57.59,0.165
23.67,57.74,0.165
23.70,57.89,0.166
23.73,58.03,0.167
23.76,58.19,0.167
23.79,58.33,0.168
23.82,58.48,0.169
23.85,58.63,0.169
23.88,58.79,0.170
23.91,58.93,0.170
23.94,59.08,0.171
23.97,59.23,0.172
24.00,59.38,0.172
24.03,59.53,0.174
24.06,59.68,0.174
24.09,59.83,0.175
24.12,59.98,0.175
24.15,60.13,0.176
24.18,60.28,0.176
24.21,60.43,0.177
24.24,60.58,0.177
24.27,60.73,0.178
24.30,60.88,0.178
24.33,61.03,0.179
24.36,61.18,0.179
24.39,61.33,0.179
24.42,61.48,0.180
24.45,61.63,0.180
24.48,61.78,0.180
24.51,61.93,0.181
24.54,62.08,0.181
24.57,62.23,0.181
24.60,62.38,0.181
24.63,62.53,0.181
24.66,62.68,0.182
24.69,62.83,0.182
24.72,62.98,0.182
24.75,63.13,0.181
24.78,63.28,0.181
24.81,63.43,0.181
24.84,63.58,0.181
24.87,63.73,0.181
24.90,63.88,0.181
24.93,64.03,0.180
24.96,64.19,0.180
24.99,64.34,0.179
25.02,64.49,0.179
25.05,64.64,0.178
25.08,64.79,0.178
25.11,64.94,0.177
25.14,65.09,0.177
25.17,65.24,0.176
25.20,65.39,0.176
25.23,65.54,0.175
25.26,65.69,0.175
25.29,65.84,0.174
25.32,65.99,0.174
25.35,66.14,0.173
25.38,66.29,0.173
25.41,66.44,0.172
25.44,66.59,0.172
25.47,66.74,0.171
25.50,66.89,0.171
25.53,67.04,0.171
25.56,67.20,0.170
25.59,67.35,0.170
25.62,67.50,0.170
25.65,67.65,0.169
25.68,67.80,0.169
25.71,67.95,0.169
25.74,68.10,0.169
25.77,68.25,0.168
25.80,68.40,0.168
25.83,68.55,0.168
25.86,68.70,0.168
25.89,68.85,0.168
25.92,69.00,0.168
25.95,69.15,0.167
25.98,69.30,0.167
26.01,69.45,0.167
26.04,69.60,0.167
26.07,69.75,0.167
26.10,69.90,0.167
26.13,70.05,0.167
26.16,70.20,0.167
26.19,70.35,0.167
26.22,70.50,0.167
26.25,70.65,0.167
26.28,70.80,0.167
26.31,70.95,0.167
26.34,71.10,0.167
26.37,71.25,0.167
26.40,71.40,0.167
26.43,71.55,0.167
26.46,71.70,0.167
26.49,71.85,0.167
26.52,72.00,0.167
26.55,72.15,0.167
26.58,72.30,0.167
26.61,72.45,0.167
26.64,72.60,0.167
26.67,72.75,0.167
26.70,72.90,0.167
26.73,73.05,0.167
26.76,73.20,0.167
26.79,73.35,0.167
26.82,73.50,0.167
26.85,73.65,0.167
26.88,73.80,0.167
26.91,73.95,0.167
26.94,74.10,0.168
26.97,74.25,0.168
27.00,74.40,0.168
27.03,74.55,0.168
27.06,74.70,0.168
27.09,74.85,0.168
27.12,75.00,0.168
27.15,75.15,0.168
27.18,75.30,0.168
27.21,75.45,0.168
27.24,75.60,0.168
27.27,75.75,0.168
27.30,75.90,0.168
27.33,76.05,0.168
27.36,76.20,0.168
27.39,76.35,0.168
27.42,76.50,0.168
27.45,76.65,0.168
27.48,76.80,0.168
27.51,76.95,0.169
27.54,77.10,0.169
27.57,77.25,0.169
27.60,77.40,0.169
27.63,77.55,0.169
27.66,77.70,0.169
27.69,77.85,0.169
27.72,78.00,0.169
27.75,78.15,0.169
27.78,78.30,0.169
27.81,78.45,0.169
27.84,78.60,0.169
27.87,78.75,0.169
27.90,78.90,0.169
27.93,79.05,0.169
27.96,79.20,0.169
27.99,79.35,0.169
28.02,79.50,0.169
28.05,79.66,0.169
28.08,79.80,0.169
28.11,79.96,0.170
28.14,80.11,0.170
28.17,80.25,0.170
28.20,80.40,0.170
28.23,80.55,0.170
28.26,80.70,0.170
28.29,80.85,0.170
28.32,81.01,0.170
28.35,81.16,0.170
28.38,81.31,0.170
28.41,81.45,0.170
28.44,81.61,0.170
28.47,81.76,0.170
28.50,81.90,0.170
28.53,82.06,0.170
28.56,82.21,0.170
28.59,82.36,0.170
28.62,82.51,0.170
28.65,82.66,0.170
28.68,82.81,0.170
28.71,82.96,0.171
28.74,83.11,0.171
28.77,83.26,0.171
28.80,83.41,0.171
28.83,83.56,0.171
28.86,83.71,0.171
28.89,83.86,0.171
28.92,84.01,0.171
28.95,84.16,0.171
28.98,84.31,0.171
29.01,84.46,0.171
29.04,84.61,0.171
29.07,84.76,0.171
29.10,84.91,0.171
29.13,85.06,0.171
29.16,85.21,0.171
29.19,85.36,0.171
29.22,85.51,0.171
29.25,85.66,0.171
29.28,85.81,0.171
29.31,85.96,0.171
29.34,86.11,0.172
29.37,86.26,0.172
29.40,86.41,0.172
29.43,86.56,0.172
29.46,86.71,0.172
29.49,86.86,0.172
29.52,87.01,0.172
29.55,87.16,0.172
29.58,87.31,0.172
29.61,87.46,0.172
29.64,87.61,0.172
29.67,87.76,0.172
29.70,87.91,0.172
29.73,88.06,0.172
29.76,88.21,0.172
29.79,88.36,0.172
29.82,88.51,0.173
29.85,88.66,0.173
29.88,88.81,0.173
29.91,88.96,0.173
29.94,89.11,0.173
29.97,89.26,0.173
30.00,89.41,0.173
30.03,89.56,0.173
30.06,89.71,0.173
30.09,89.86,0.173
30.12,90.01,0.173
30.15,90.16,0.174
30.18,90.31,0.174
30.21,90.46,0.174
30.24,90.61,0.174
30.27,90.76,0.174
30.30,90.91,0.174
30.33,91.06,0.174
30.36,91.22,0.175
30.39,91.37,0.175
30.42,91.52,0.175
30.45,91.67,0.175
30.48,91.82,0.175
30.51,91.97,0.175
30.54,92.12,0.175
30.57,92.27,0.175
30.60,92.42,0.175
30.63,92.57,0.175
30.66,92.72,0.175
30.69,92.86,0.175
30.72,93.02,0.175
30.75,93.16,0.175
30.78,93.31,0.175
30.81,93.46,0.175
30.84,93.61,0.175
30.87,93.76,0.175
30.90,93.91,0.176
30.93,94.06,0.176
30.96,94.21,0.176
30.99,94.36,0.176
31.02,94.51,0.176
31.05,94.66,0.176
31.08,94.81,0.176
31.11,94.96,0.176
31.14,95.11,0.176
31.17,95.26,0.176
31.20,95.41,0.176
31.23,95.56,0.176
31.26,95.71,0.176
31.29,95.86,0.176
31.32,96.01,0.176
31.35,96.16,0.176
31.38,96.31,0.176
31.41,96.47,0.176
31.44,96.61,0.176
31.47,96.76,0.176
31.50,96.92,0.176
31.53,97.06,0.176
31.56,97.22,0.176
31.59,97.37,0.176
31.62,97.52,0.176
31.65,97.67,0.176
31.68,97.82,0.176
31.71,97.96,0.176
31.74,98.12,0.176
31.77,98.27,0.176
31.80,98.41,0.176
31.83,98.57,0.176
31.86,98.72,0.176
31.89,98.87,0.176
31.92,99.02,0.176
31.95,99.17,0.176
31.98,99.32,0.175
32.01,99.47,0.175
32.04,99.62,0.175
32.07,99.77,0.175
32.10,99.92,0.175
32.13,100.07,0.175
32.16,100.22,0.175
32.19,100.37,0.175
32.22,100.52,0.175
32.25,100.67,0.175
32.28,100.82,0.175
32.31,100.97,0.175
32.34,101.12,0.175
32.37,101.27,0.175
32.40,101.42,0.175
32.43,101.57,0.176
32.46,101.72,0.176
32.49,101.87,0.176
32.52,102.02,0.176
32.55,102.17,0.176
32.58,102.32,0.176
32.61,102.47,0.176
32.64,102.62,0.176
32.67,102.77,0.176
32.70,102.92,0.176
32.73,103.07,0.176
32.76,103.22,0.176
32.79,103.37,0.176
32.82,103.52,0.176
32.85,103.67,0.176
32.88,103.82,0.176
32.91,103.97,0.176
32.94,104.12,0.176
32.97,104.27,0.176
33.00,104.42,0.176
33.03,104.57,0.176
33.06,104.72,0.176
33.09,104.87,0.176
33.12,105.02,0.176
33.15,105.17,0.176
33.18,105.32,0.176
33.21,105.47,0.176
33.24,105.62,0.176
33.27,105.77,0.176
33.30,105.92,0.176
33.33,106.07,0.176
33.36,106.22,0.176
33.39,106.37,0.176
33.42,106.52,0.176
33.45,106.67,0.176
33.48,106.82,0.177
33.51,106.97,0.177
33.54,107.12,0.177
33.57,107.27,0.177
33.60,107.42,0.177
33.63,107.57,0.177
33.66,107.72,0.177
33.69,107.87,0.177
33.72,108.02,0.177
33.75,108.17,0.177
33.78,108.32,0.177
33.81,108.47,0.177
33.84,108.62,0.177
33.87,108.77,0.177
33.90,108.92,0.177
33.93,109.07,0.177
33.96,109.22,0.177
33.99,109.37,0.177
34.02,109.52,0.177
34.05,109.67,0.177
34.08,109.82,0.177
34.11,109.97,0.177
34.14,110.12,0.177
34.17,110.27,0.177
34.20,110.42,0.177
34.23,110.57,0.177
34.26,110.72,0.177
34.29,110.87,0.177
34.32,111.02,0.177
34.35,111.17,0.178
34.38,111.32,0.178
34.41,111.47,0.178
34.44,111.62,0.178
34.47,111.77,0.178
34.50,111.92,0.178
34.53,112.07,0.178
34.56,112.22,0.178
34.59,112.37,0.178
34.62,112.52,0.178
34.65,112.67,0.178
34.68,112.82,0.178
34.71,112.97,0.178
34.74,113.12,0.178
34.77,113.27,0.178
34.80,113.42,0.178
34.83,113.57,0.178
34.86,113.72,0.178
34.89,113.87,0.178
34.92,114.02,0.179
34.95,114.17,0.179
34.98,114.33,0.179
35.01,114.48,0.179
35.04,114.63,0.179
35.07,114.78,0.179
35.10,114.92,0.179
35.13,115.08,0.179
35.16,115.23,0.179
35.19,115.37,0.179
35.22,115.53,0.179
35.25,115.67,0.179
35.28,115.83,0.179
35.31,115.97,0.179
35.34,116.13,0.179
35.37,116.28,0.179
35.40,116.43,0.179
35.43,116.57,0.179
35.46,116.72,0.179
35.49,116.87,0.179
35.52,117.02,0.179
35.55,117.17,0.179
35.58,117.32,0.179
35.61,117.48,0.179
35.64,117.63,0.179
35.67,117.78,0.179
35.70,117.93,0.179
35.73,118.08,0.179
35.76,118.23,0.179
35.79,118.38,0.179
35.82,118.53,0.179
35.85,118.68,0.180
35.88,118.83,0.180
35.91,118.98,0.180
35.94,119.13,0.180
35.97,119.28,0.180
36.00,119.43,0.180
36.03,119.58,0.180
36.06,119.73,0.180
36.09,119.88,0.180
36.12,120.03,0.180
36.15,120.18,0.180
36.18,120.33,0.180
36.21,120.48,0.180
36.24,120.63,0.180
36.27,120.78,0.180
36.30,120.93,0.180
36.33,121.08,0.180
36.36,121.23,0.180
36.39,121.38,0.180
36.42,121.53,0.180
36.45,121.68,0.180
36.48,121.83,0.180
36.51,121.98,0.180
36.54,122.13,0.180
36.57,122.28,0.180
36.60,122.43,0.180
36.63,122.58,0.180
36.66,122.73,0.180
36.69,122.88,0.180
36.72,123.03,0.180
36.75,123.18,0.180
36.78,123.33,0.180
36.81,123.48,0.180
36.84,123.63,0.180
36.87,123.78,0.180
36.90,123.93,0.180
36.93,124.08,0.180
36.96,124.23,0.180
36.99,124.38,0.180
37.02,124.53,0.180
37.05,124.68,0.180
37.08,124.83,0.180
37.11,124.98,0.181
37.14,125.13,0.181
37.17,125.28,0.181
37.20,125.43,0.181
37.23,125.58,0.181
37.26,125.73,0.181
37.29,125.88,0.181
37.32,126.03,0.181
37.35,126.18,0.181
37.38,126.33,0.181
37.41,126.48,0.181
37.44,126.63,0.181
37.47,126.78,0.181
37.50,126.93,0.181
37.53,127.08,0.180
37.56,127.23,0.180
37.59,127.39,0.180
37.62,127.53,0.180
37.65,127.68,0.180
37.68,127.83,0.180
37.71,127.98,0.180
37.74,128.13,0.180
37.77,128.28,0.180
37.80,128.43,0.180
37.83,128.58,0.180
37.86,128.73,0.180
37.89,128.88,0.180
37.92,129.04,0.180
37.95,129.19,0.180
37.98,129.34,0.180
38.01,129.49,0.180
38.04,129.64,0.180
38.07,129.79,0.180
38.10,129.94,0.180
38.13,130.09,0.180
38.16,130.24,0.180
38.19,130.39,0.180
38.22,130.54,0.180
38.25,130.68,0.180
38.28,130.83,0.180
38.31,130.98,0.180
38.34,131.13,0.180
38.37,131.28,0.180
38.40,131.43,0.180
38.43,131.58,0.180
38.46,131.74,0.180
38.49,131.88,0.180
38.52,132.03,0.180
38.55,132.19,0.180
38.58,132.34,0.180
38.61,132.49,0.180
38.64,132.64,0.180
38.67,132.78,0.180
38.70,132.93,0.180
38.73,133.09,0.180
38.76,133.24,0.180
38.79,133.39,0.180
38.82,133.54,0.180
38.85,133.69,0.180
38.88,133.84,0.180
38.91,133.99,0.180
38.94,134.13,0.180
38.97,134.29,0.180
39.00,134.44,0.180
39.03,134.59,0.180
39.06,134.74,0.180
39.09,134.89,0.180
39.12,135.04,0.180
39.15,135.19,0.180
39.18,135.34,0.180
39.21,135.49,0.180
39.24,135.64,0.180
39.27,135.79,0.180
39.30,135.94,0.180
39.33,136.09,0.180
39.36,136.24,0.180
39.39,136.39,0.180
39.42,136.54,0.180
39.45,136.69,0.180
39.48,136.84,0.180
39.51,136.99,0.180
39.54,137.14,0.180
39.57,137.29,0.180
39.60,137.44,0.180
39.63,137.59,0.180
39.66,137.74,0.180
39.69,137.89,0.180
39.72,138.04,0.180
39.75,138.19,0.180
39.78,138.34,0.180
39.81,138.49,0.180
39.84,138.64,0.180
39.87,138.79,0.180
39.90,138.94,0.180
39.93,139.09,0.180
39.96,139.24,0.180
39.99,139.39,0.180
40.02,139.54,0.180
40.05,139.69,0.180
40.08,139.84,0.180
40.11,139.99,0.180
40.14,140.14,0.180
40.17,140.29,0.180
40.20,140.44,0.180
40.23,140.59,0.180
40.26,140.74,0.180
40.29,140.89,0.180
40.32,141.04,0.180
40.35,141.19,0.180
40.38,141.34,0.180
40.41,141.49,0.180
40.44,141.64,0.180
40.47,141.79,0.180
40.50,141.94,0.180
40.53,142.09,0.180
40.56,142.24,0.180
40.59,142.39,0.180
40.62,142.54,0.180
40.65,142.69,0.181
40.68,142.84,0.181
40.71,142.99,0.181
40.74,143.14,0.181
40.77,143.29,0.181
40.80,143.44,0.181
40.83,143.59,0.181
40.86,143.74,0.182
40.89,143.89,0.182
40.92,144.04,0.182
40.95,144.19,0.182
40.98,144.34,0.182
41.01,144.49,0.182
41.04,144.64,0.182
41.07,144.79,0.182
41.10,144.94,0.182
41.13,145.09,0.182
41.16,145.24,0.183
41.19,145.39,0.183
41.22,145.54,0.183
41.25,145.69,0.183
41.28,145.84,0.183
41.31,145.99,0.183
41.34,146.14,0.183
41.37,146.29,0.182
41.40,146.44,0.182
41.43,146.59,0.182
41.46,146.74,0.182
41.49,146.89,0.182
41.52,147.04,0.182
41.55,147.19,0.182
41.58,147.34,0.182
41.61,147.49,0.182
41.64,147.64,0.182
41.67,147.79,0.182
41.70,147.94,0.182
41.73,148.09,0.182
41.76,148.24,0.182
41.79,148.39,0.182
41.82,148.54,0.182
41.85,148.69,0.182
41.88,148.84,0.182
41.91,148.99,0.182
41.94,149.14,0.182
41.97,149.29,0.182
42.00,149.44,0.182
42.03,149.59,0.182
42.06,149.74,0.182
42.09,149.89,0.182
42.12,150.04,0.182
42.15,150.19,0.182
42.18,150.34,0.183
42.21,150.49,0.183
42.24,150.64,0.183
42.27,150.79,0.184
42.30,150.94,0.186
42.33,151.09,0.191
42.36,151.24,0.200
42.39,151.38,0.210
42.42,151.53,0.217
42.45,151.68,0.218
42.48,151.83,0.218
42.51,151.98,0.218
42.54,152.12,0.218
42.57,152.27,0.218
42.60,152.43,0.218
42.63,152.58,0.217
42.66,152.73,0.217
42.69,152.88,0.217
42.72,153.03,0.217
42.75,153.17,0.217
42.78,153.33,0.217
42.81,153.48,0.217
42.84,153.63,0.217
42.87,153.78,0.217
42.90,153.93,0.217
42.93,154.08,0.217
42.96,154.22,0.217
42.99,154.38,0.218
43.02,154.52,0.218
43.05,154.67,0.219
43.08,154.82,0.219
43.11,154.97,0.219
43.14,155.13,0.219
43.17,155.27,0.220
43.20,155.42,0.220
43.23,155.57,0.220
43.26,155.72,0.220
43.29,155.87,0.221
43.32,156.02,0.221
43.35,156.17,0.221
43.38,156.32,0.221
43.41,156.47,0.222
43.44,156.62,0.222
43.47,156.77,0.222
43.50,156.92,0.222
43.53,157.07,0.222
43.56,157.22,0.222
43.59,157.37,0.223
43.62,157.52,0.223
43.65,157.67,0.223
43.68,157.82,0.223
43.71,157.97,0.223
43.74,158.13,0.223
43.77,158.28,0.223
43.80,158.43,0.223
43.83,158.58,0.223
43.86,158.73,0.222
43.89,158.88,0.222
43.92,159.03,0.222
43.95,159.18,
43.98,,
43.99,,

[step]
Ramp 5.00 °C/min to -60.00 °C
Time,Temperature,Heat Flow (Normalized)
min,°C,W/g
45.99,160.12,-0.027
46.02,160.12,-0.027
46.05,160.11,-0.028
46.08,160.09,-0.046
46.11,160.04,-0.076
46.14,159.96,-0.113
46.17,159.87,-0.147
46.20,159.76,-0.173
46.23,159.64,-0.192
46.26,159.52,-0.206
46.29,159.39,-0.217
46.32,159.25,-0.226
46.35,159.12,-0.232
46.38,158.98,-0.238
46.41,158.83,-0.241
46.44,158.69,-0.243
46.47,158.55,-0.246
46.50,158.40,-0.248
46.53,158.25,-0.249
46.56,158.11,-0.250
46.59,157.96,-0.251
46.62,157.81,-0.251
46.65,157.66,-0.252
46.68,157.52,-0.252
46.71,157.37,-0.253
46.74,157.22,-0.253
46.77,157.07,-0.253
46.80,156.92,-0.253
46.83,156.77,-0.254
46.86,156.62,-0.254
46.89,156.47,-0.254
46.92,156.32,-0.254
46.95,156.18,-0.254
46.98,156.03,-0.254
47.01,155.88,-0.255
47.04,155.73,-0.255
47.07,155.58,-0.255
47.10,155.43,-0.255
47.13,155.28,-0.255
47.16,155.13,-0.255
47.19,154.98,-0.255
47.22,154.83,-0.255
47.25,154.68,-0.255
47.28,154.53,-0.255
47.31,154.38,-0.255
47.34,154.23,-0.255
47.37,154.08,-0.255
47.40,153.93,-0.255
47.43,153.78,-0.255
47.46,153.63,-0.254
47.49,153.48,-0.254
47.52,153.33,-0.254
47.55,153.18,-0.254
47.58,153.03,-0.254
47.61,152.89,-0.254
47.64,152.73,-0.254
47.67,152.58,-0.254
47.70,152.43,-0.254
47.73,152.28,-0.254
47.76,152.13,-0.254
47.79,151.98,-0.253
47.82,151.83,-0.253
47.85,151.68,-0.253
47.88,151.53,-0.253
47.91,151.38,-0.253
47.94,151.23,-0.253
47.97,151.08,-0.253
48.00,150.93,-0.253
48.03,150.78,-0.253
48.06,150.63,-0.253
48.09,150.48,-0.252
48.12,150.34,-0.252
48.15,150.18,-0.252
48.18,150.03,-0.252
48.21,149.89,-0.252
48.24,149.74,-0.252
48.27,149.59,-0.252
48.30,149.44,-0.251
48.33,149.28,-0.251
48.36,149.13,-0.251
48.39,148.99,-0.251
48.42,148.84,-0.251
48.45,148.69,-0.251
48.48,148.54,-0.251
48.51,148.39,-0.250
48.54,148.24,-0.250
48.57,148.09,-0.250
48.60,147.94,-0.250
48.63,147.79,-0.250
48.66,147.64,-0.250
48.69,147.49,-0.250
48.72,147.34,-0.250
48.75,147.19,-0.249
48.78,147.04,-0.249
48.81,146.89,-0.249
48.84,146.74,-0.249
48.87,146.59,-0.249
48.90,146.44,-0.249
48.93,146.29,-0.249
48.96,146.14,-0.249
48.99,145.99,-0.248
49.02,145.84,-0.248
49.05,145.69,-0.248
49.08,145.54,-0.248
49.11,145.39,-0.248
49.14,145.24,-0.248
49.17,145.09,-0.248
49.20,144.94,-0.248
49.23,144.79,-0.248
49.26,144.64,-0.247
49.29,144.49,-0.247
49.32,144.34,-0.247
49.35,144.19,-0.247
49.38,144.04,-0.247
49.41,143.89,-0.247
49.44,143.74,-0.247
49.47,143.59,-0.247
49.50,143.44,-0.247
49.53,143.29,-0.247
49.56,143.14,-0.246
49.59,142.99,-0.246
49.62,142.84,-0.246
49.65,142.69,-0.246
49.68,142.54,-0.246
49.71,142.39,-0.246
49.74,142.24,-0.246
49.77,142.09,-0.246
49.80,141.94,-0.246
49.83,141.79,-0.245
49.86,141.64,-0.245
49.89,141.49,-0.245
49.92,141.34,-0.245
49.95,141.19,-0.245
49.98,141.04,-0.245
50.01,140.89,-0.245
50.04,140.74,-0.245
50.07,140.59,-0.245
50.10,140.44,-0.245
50.13,140.29,-0.245
50.16,140.14,-0.245
50.19,139.99,-0.244
50.22,139.84,-0.244
50.25,139.69,-0.244
50.28,139.54,-0.244
50.31,139.39,-0.244
50.34,139.24,-0.244
50.37,139.09,-0.244
50.40,138.94,-0.244
50.43,138.79,-0.244
50.46,138.64,-0.244
50.49,138.49,-0.244
50.52,138.34,-0.244
50.55,138.19,-0.244
50.58,138.04,-0.243
50.61,137.89,-0.243
50.64,137.74,-0.243
50.67,137.59,-0.243
50.70,137.44,-0.243
50.73,137.29,-0.243
50.76,137.14,-0.243
50.79,136.99,-0.243
50.82,136.84,-0.243
50.85,136.69,-0.242
50.88,136.54,-0.242
50.91,136.39,-0.242
50.94,136.24,-0.242
50.97,136.09,-0.242
51.00,135.94,-0.242
51.03,135.79,-0.242
51.06,135.64,-0.242
51.09,135.49,-0.242
51.12,135.34,-0.242
51.15,135.19,-0.241
51.18,135.04,-0.241
51.21,134.89,-0.241
51.24,134.74,-0.241
51.27,134.59,-0.241
51.30,134.44,-0.241
51.33,134.29,-0.241
51.36,134.14,-0.241
51.39,133.99,-0.241
51.42,133.84,-0.241
51.45,133.69,-0.241
51.48,133.54,-0.241
51.51,133.39,-0.241
51.54,133.24,-0.241
51.57,133.09,-0.240
51.60,132.94,-0.240
51.63,132.79,-0.240
51.66,132.64,-0.240
51.69,132.49,-0.240
51.72,132.34,-0.240
51.75,132.19,-0.240
51.78,132.04,-0.240
51.81,131.89,-0.240
51.84,131.74,-0.240
51.87,131.59,-0.240
51.90,131.44,-0.240
51.93,131.29,-0.239
51.96,131.14,-0.239
51.99,130.99,-0.239
52.02,130.84,-0.239
52.05,130.69,-0.239
52.08,130.54,-0.239
52.11,130.39,-0.239
52.14,130.24,-0.239
52.17,130.09,-0.239
52.20,129.94,-0.239
52.23,129.79,-0.239
52.26,129.64,-0.238
52.29,129.49,-0.238
52.32,129.34,-0.238
52.35,129.19,-0.238
52.38,129.04,-0.238
52.41,128.89,-0.238
52.44,128.74,-0.238
52.47,128.59,-0.238
52.50,128.45,-0.238
52.53,128.29,-0.238
52.56,128.15,-0.238
52.59,128.00,-0.237
52.62,127.85,-0.237
52.65,127.69,-0.237
52.68,127.55,-0.237
52.71,127.40,-0.237
52.74,127.24,-0.237
52.77,127.10,-0.237
52.80,126.94,-0.237
52.83,126.79,-0.237
52.86,126.64,-0.237
52.89,126.50,-0.237
52.92,126.35,-0.236
52.95,126.20,-0.236
52.98,126.05,-0.236
53.01,125.90,-0.236
53.04,125.75,-0.236
53.07,125.60,-0.236
53.10,125.45,-0.236
53.13,125.30,-0.236
53.16,125.15,-0.236
53.19,125.00,-0.236
53.22,124.85,-0.236
53.25,124.70,-0.236
53.28,124.55,-0.236
53.31,124.40,-0.236
53.34,124.25,-0.235
53.37,124.10,-0.235
53.40,123.95,-0.235
53.43,123.80,-0.235
53.46,123.65,-0.235
53.49,123.50,-0.235
53.52,123.35,-0.235
53.55,123.20,-0.235
53.58,123.05,-0.235
53.61,122.90,-0.235
53.64,122.75,-0.235
53.67,122.60,-0.235
53.70,122.45,-0.235
53.73,122.30,-0.235
53.76,122.15,-0.235
53.79,122.00,-0.235
53.82,121.85,-0.234
53.85,121.70,-0.234
53.88,121.55,-0.234
53.91,121.40,-0.234
53.94,121.25,-0.234
53.97,121.10,-0.234
54.00,120.95,-0.234
54.03,120.80,-0.234
54.06,120.65,-0.234
54.09,120.50,-0.234
54.12,120.35,-0.234
54.15,120.19,-0.234
54.18,120.04,-0.234
54.21,119.89,-0.234
54.24,119.74,-0.234
54.27,119.59,-0.234
54.30,119.44,-0.233
54.33,119.29,-0.233
54.36,119.14,-0.233
54.39,118.99,-0.233
54.42,118.84,-0.233
54.45,118.69,-0.233
54.48,118.55,-0.233
54.51,118.40,-0.232
54.54,118.25,-0.232
54.57,118.10,-0.232
54.60,117.95,-0.232
[...]
232.16,-39.94,0.082
232.18,-39.87,0.082
232.19,-39.80,0.082
232.20,-39.74,0.082
232.22,-39.67,0.082
232.23,-39.60,0.082
232.24,-39.54,0.082
232.25,-39.47,0.082
232.27,-39.40,0.082
232.28,-39.34,0.082
232.30,-39.27,0.082
232.31,-39.20,0.082
232.32,-39.14,0.082
232.33,-39.07,0.082
232.35,-39.00,0.082
232.36,-38.94,0.082
232.38,-38.87,0.082
232.39,-38.80,0.082
232.40,-38.74,0.082
232.42,-38.67,0.083
232.43,-38.60,0.083
232.44,-38.54,0.083
232.45,-38.47,0.083
232.47,-38.40,0.083
232.48,-38.33,0.083
232.50,-38.27,0.083
232.51,-38.20,0.083
232.52,-38.14,0.083
232.53,-38.07,0.083
232.55,-38.00,0.083
232.56,-37.93,0.083
232.58,-37.87,0.083
232.59,-37.80,0.083
232.60,-37.73,0.083
232.62,-37.67,0.083
232.63,-37.60,0.083
232.64,-37.53,0.083
232.65,-37.47,0.083
232.67,-37.40,0.083
232.68,-37.33,0.083
232.70,-37.27,0.083
232.71,-37.20,0.083
232.72,-37.13,0.083
232.73,-37.07,0.083
232.75,-37.00,0.083
232.76,-36.93,0.083
232.78,-36.87,0.083
232.79,-36.80,0.083
232.80,-36.73,0.083
232.82,-36.67,0.083
232.83,-36.60,0.083
232.84,-36.53,0.083
232.85,-36.47,0.083
232.87,-36.40,0.083
232.88,-36.33,0.083
232.90,-36.27,0.083
232.91,-36.20,0.083
232.92,-36.13,0.083
232.93,-36.07,0.083
232.95,-36.00,0.083
232.96,-35.93,0.083
232.98,-35.87,0.083
232.99,-35.80,0.083
233.00,-35.73,0.083
233.02,-35.67,0.083
233.03,-35.60,0.083
233.04,-35.53,0.083
233.05,-35.46,0.083
233.07,-35.40,0.083
233.08,-35.33,0.084
233.10,-35.27,0.083
233.11,-35.20,0.084
233.12,-35.13,0.084
233.13,-35.06,0.084
233.15,-35.00,0.084
233.16,-34.93,0.084
233.18,-34.86,0.084
233.19,-34.80,0.084
233.20,-34.73,0.084
233.22,-34.66,0.084
233.23,-34.60,0.084
233.24,-34.53,0.084
233.25,-34.46,0.084
233.27,-34.40,0.084
233.28,-34.33,0.084
233.30,-34.26,0.084
233.31,-34.20,0.084
233.32,-34.13,0.084
233.33,-34.06,0.084
233.35,-34.00,0.084
233.36,-33.93,0.084
233.38,-33.86,0.084
233.39,-33.80,0.084
233.40,-33.73,0.084
233.42,-33.66,0.084
233.43,-33.60,0.084
233.44,-33.53,0.084
233.45,-33.46,0.084
233.47,-33.40,0.084
233.48,-33.33,0.084
233.50,-33.26,0.084
233.51,-33.20,0.084
233.52,-33.13,0.084
233.53,-33.06,0.084
233.55,-33.00,0.084
233.56,-32.93,0.084
233.58,-32.86,0.084
233.59,-32.80,0.084
233.60,-32.73,0.084
233.62,-32.66,0.084
233.63,-32.60,0.084
233.64,-32.53,0.084
233.65,-32.46,0.084
233.67,-32.40,0.084
233.68,-32.33,0.085
233.70,-32.26,0.085
233.71,-32.19,0.085
233.72,-32.13,0.085
233.73,-32.06,0.085
233.75,-32.00,0.085
233.76,-31.93,0.085
233.78,-31.86,0.085
233.79,-31.79,0.085
233.80,-31.73,0.085
233.82,-31.66,0.085
233.83,-31.59,0.085
233.84,-31.53,0.085
233.85,-31.46,0.085
233.87,-31.39,0.085
233.88,-31.33,0.085
233.90,-31.26,0.085
233.91,-31.19,0.085
233.92,-31.13,0.085
233.93,-31.06,0.085
233.95,-30.99,0.085
233.96,-30.93,0.085
233.98,-30.86,0.085
233.99,-30.79,0.085
234.00,-30.73,0.085
234.02,-30.66,0.085
234.03,-30.59,0.085
234.04,-30.53,0.085
234.05,-30.46,0.085
234.07,-30.39,0.085
234.08,-30.33,0.085
234.10,-30.26,0.085
234.11,-30.19,0.085
234.12,-30.13,0.085
234.13,-30.06,0.085
234.15,-29.99,0.085
234.16,-29.93,0.085
234.18,-29.86,0.085
234.19,-29.79,0.085
234.20,-29.72,0.085
234.22,-29.66,0.085
234.23,-29.59,0.085
234.24,-29.52,0.085
234.25,-29.46,0.085
234.27,-29.39,0.085
234.28,-29.33,0.085
234.30,-29.26,0.085
234.31,-29.19,0.086
234.32,-29.12,0.086
234.33,-29.06,0.086
234.35,-28.99,0.086
234.36,-28.92,0.086
234.38,-28.86,0.086
234.39,-28.79,0.086
234.40,-28.72,0.086
234.42,-28.66,0.086
234.43,-28.59,0.086
234.44,-28.52,0.086
234.45,-28.46,0.086
234.47,-28.39,0.086
234.48,-28.32,0.086
234.50,-28.25,0.086
234.51,-28.19,0.086
234.52,-28.12,0.086
234.53,-28.06,0.086
234.55,-27.99,0.086
234.56,-27.92,0.086
234.58,-27.85,0.086
234.59,-27.79,0.086
234.60,-27.72,0.086
234.62,-27.66,0.086
234.63,-27.59,0.086
234.64,-27.52,0.086
234.65,-27.45,0.086
234.67,-27.39,0.086
234.68,-27.32,0.086
234.70,-27.26,0.086
234.71,-27.19,0.086
234.72,-27.12,0.086
234.73,-27.06,0.086
234.75,-26.99,0.086
234.76,-26.92,0.086
234.78,-26.85,0.086
234.79,-26.79,0.086
234.80,-26.72,0.086
234.82,-26.66,0.086
234.83,-26.59,0.086
234.84,-26.52,0.086
234.85,-26.45,0.086
234.87,-26.39,0.086
234.88,-26.32,0.086
234.90,-26.25,0.086
234.91,-26.19,0.087
234.92,-26.12,0.087
234.93,-26.05,0.087
234.95,-25.99,0.087
234.96,-25.92,0.087
234.98,-25.85,0.087
234.99,-25.79,0.087
235.00,-25.72,0.087
235.02,-25.65,0.087
235.03,-25.59,0.087
235.04,-25.52,0.087
235.05,-25.45,0.087
235.07,-25.39,0.087
235.08,-25.32,0.087
235.10,-25.25,0.087
235.11,-25.19,0.087
235.12,-25.12,0.087
235.13,-25.05,0.087
235.15,-24.99,0.087
235.16,-24.92,0.087
235.18,-24.85,0.087
235.19,-24.79,0.087
235.20,-24.72,0.087
235.22,-24.65,0.087
235.23,-24.59,0.087
235.24,-24.52,0.087
235.25,-24.45,0.087
235.27,-24.39,0.087
235.28,-24.32,0.087
235.30,-24.25,0.087
235.31,-24.19,0.087
235.32,-24.12,0.087
235.33,-24.05,0.087
235.35,-23.99,0.087
235.36,-23.92,0.087
235.38,-23.85,0.087
235.39,-23.78,0.087
235.40,-23.72,0.087
235.42,-23.65,0.087
235.43,-23.59,0.087
235.44,-23.52,0.087
235.45,-23.45,0.087
235.47,-23.38,0.087
235.48,-23.32,0.087
235.50,-23.25,0.087
235.51,-23.19,0.088
235.52,-23.12,0.088
235.53,-23.05,0.088
235.55,-22.99,0.088
235.56,-22.92,0.088
235.58,-22.85,0.088
235.59,-22.79,0.088
235.60,-22.72,0.088
235.62,-22.65,0.088
235.63,-22.58,0.088
235.64,-22.52,0.088
235.65,-22.45,0.088
235.67,-22.39,0.088
235.68,-22.32,0.088
235.70,-22.25,0.088
235.71,-22.19,0.088
235.72,-22.12,0.088
235.73,-22.05,0.088
235.75,-21.99,0.088
235.76,-21.92,0.088
235.78,-21.85,0.088
235.79,-21.79,0.088
235.80,-21.72,0.088
235.82,-21.65,0.088
235.83,-21.59,0.088
235.84,-21.52,0.088
235.85,-21.45,0.088
235.87,-21.39,0.088
235.88,-21.32,0.088
235.90,-21.25,0.088
235.91,-21.19,0.088
235.92,-21.12,0.088
235.93,-21.05,0.088
235.95,-20.99,0.088
235.96,-20.92,0.088
235.98,-20.85,0.088
235.99,-20.79,0.088
236.00,-20.72,0.088
236.02,-20.65,0.088
236.03,-20.59,0.088
236.04,-20.52,0.088
236.05,-20.45,0.088
236.07,-20.39,0.089
236.08,-20.32,0.089
236.10,-20.25,0.089
236.11,-20.18,0.089
236.12,-20.12,0.089
236.13,-20.05,0.089
236.15,-19.98,0.089
236.16,-19.92,0.089
236.18,-19.85,0.089
236.19,-19.78,0.089
236.20,-19.72,0.089
236.22,-19.65,0.089
236.23,-19.58,0.089
236.24,-19.52,0.089
236.25,-19.45,0.089
236.27,-19.38,0.089
236.28,-19.32,0.089
236.30,-19.25,0.089
236.31,-19.18,0.089
236.32,-19.12,0.089
236.33,-19.05,0.089
236.35,-18.98,0.089
236.36,-18.92,0.089
236.38,-18.85,0.089
236.39,-18.78,0.089
236.40,-18.72,0.089
236.42,-18.65,0.089
236.43,-18.58,0.089
236.44,-18.52,0.089
236.45,-18.45,0.089
236.47,-18.38,0.089
236.48,-18.32,0.089
236.50,-18.25,0.089
236.51,-18.18,0.089
236.52,-18.12,0.089
236.53,-18.05,0.089
236.55,-17.98,0.089
236.56,-17.92,0.089
236.58,-17.85,0.090
236.59,-17.78,0.090
236.60,-17.72,0.090
236.62,-17.65,0.090
236.63,-17.58,0.090
236.64,-17.51,0.090
236.65,-17.45,0.090
236.67,-17.38,0.090
236.68,-17.31,0.090
236.70,-17.25,0.090
236.71,-17.18,0.090
236.72,-17.11,0.090
236.73,-17.04,0.090
236.75,-16.97,0.090
236.76,-16.91,0.090
236.78,-16.84,0.090
236.79,-16.78,0.090
236.80,-16.71,0.090
236.82,-16.64,0.090
236.83,-16.57,0.090
236.84,-16.51,0.090
236.85,-16.44,0.090
236.87,-16.37,0.090
236.88,-16.31,0.090
236.90,-16.24,0.090
236.91,-16.18,0.090
236.92,-16.11,0.090
236.93,-16.04,0.090
236.95,-15.98,0.090
236.96,-15.91,0.090
236.98,-15.84,0.090
236.99,-15.78,0.090
237.00,-15.71,0.090
237.02,-15.64,0.090
237.03,-15.58,0.090
237.04,-15.51,0.090
237.05,-15.44,0.090
237.07,-15.38,0.090
237.08,-15.31,0.090
237.10,-15.24,0.090
237.11,-15.18,0.090
237.12,-15.11,0.090
237.13,-15.04,0.090
237.15,-14.98,0.090
237.16,-14.91,0.090
237.18,-14.84,0.090
237.19,-14.78,0.091
237.20,-14.71,0.091
237.22,-14.64,0.091
237.23,-14.58,0.091
237.24,-14.51,0.091
237.25,-14.44,0.091
237.27,-14.38,0.091
237.28,-14.31,0.091
237.30,-14.24,0.091
237.31,-14.18,0.091
237.32,-14.11,0.091
237.33,-14.04,0.091
237.35,-13.98,0.091
237.36,-13.91,0.091
237.38,-13.84,0.091
237.39,-13.78,0.091
237.40,-13.71,0.091
237.42,-13.64,0.091
237.43,-13.58,0.091
237.44,-13.51,0.091
237.45,-13.44,0.091
237.47,-13.38,0.091
237.48,-13.31,0.091
237.50,-13.24,0.091
237.51,-13.18,0.091
237.52,-13.11,0.091
237.53,-13.04,0.091
237.55,-12.98,0.091
237.56,-12.91,0.091
237.58,-12.84,0.091
237.59,-12.78,0.091
237.60,-12.71,0.091
237.62,-12.64,0.091
237.63,-12.58,0.091
237.64,-12.51,0.091
237.65,-12.44,0.091
237.67,-12.38,0.091
237.68,-12.31,0.091
237.70,-12.24,0.091
237.71,-12.18,0.092
237.72,-12.11,0.092
237.73,-12.04,0.092
237.75,-11.98,0.092
237.76,-11.91,0.092
237.78,-11.84,0.092
237.79,-11.78,0.092
237.80,-11.71,0.092
237.82,-11.64,0.092
237.83,-11.58,0.092
237.84,-11.51,0.092
237.85,-11.44,0.092
237.87,-11.38,0.092
237.88,-11.31,0.092
237.90,-11.24,0.092
237.91,-11.18,0.092
237.92,-11.11,0.092
237.93,-11.04,0.092
237.95,-10.98,0.092
237.96,-10.91,0.092
237.98,-10.84,0.092
237.99,-10.78,0.092
238.00,-10.71,0.092
238.02,-10.64,0.092
238.03,-10.58,0.092
238.04,-10.51,0.092
238.05,-10.45,0.092
238.07,-10.38,0.092
238.08,-10.31,0.092
238.10,-10.24,0.092
238.11,-10.18,0.092
238.12,-10.11,0.092
238.13,-10.04,0.092
238.15,-9.98,0.092
238.16,-9.91,0.092
238.18,-9.84,0.092
238.19,-9.78,0.092
238.20,-9.71,0.092
238.22,-9.64,0.093
238.23,-9.57,0.093
238.24,-9.51,0.093
238.25,-9.44,0.093
238.27,-9.38,0.093
238.28,-9.31,0.093
238.30,-9.24,0.093
238.31,-9.17,0.093
238.32,-9.11,0.093
238.33,-9.04,0.093
238.35,-8.98,0.093
238.36,-8.91,0.093
238.38,-8.84,0.093
238.39,-8.77,0.093
238.40,-8.71,0.093
238.42,-8.64,0.093
238.43,-8.58,0.093
238.44,-8.51,0.093
238.45,-8.44,0.093
238.47,-8.38,0.093
238.48,-8.31,0.093
238.50,-8.25,0.093
238.51,-8.18,0.093
238.52,-8.11,0.093
238.53,-8.04,0.093
238.55,-7.98,0.093
238.56,-7.91,0.093
238.58,-7.84,0.093
238.59,-7.78,0.093
238.60,-7.71,0.093
238.62,-7.64,0.093
238.63,-7.58,0.093
238.64,-7.51,0.093
238.65,-7.44,0.093
238.67,-7.38,0.093
238.68,-7.31,0.093
238.70,-7.24,0.093
238.71,-7.18,0.093
238.72,-7.11,0.093
238.73,-7.04,0.093
238.75,-6.97,0.094
238.76,-6.91,0.094
238.78,-6.84,0.094
238.79,-6.77,0.094
238.80,-6.71,0.094
238.82,-6.64,0.094
238.83,-6.57,0.094
238.84,-6.51,0.094
238.85,-6.44,0.094
238.87,-6.37,0.094
238.88,-6.31,0.094
238.90,-6.24,0.094
238.91,-6.17,0.094
238.92,-6.11,0.094
238.93,-6.04,0.094
238.95,-5.97,0.094
238.96,-5.91,0.094
238.98,-5.84,0.094
238.99,-5.77,0.094
239.00,-5.71,0.094
239.02,-5.64,0.094
239.03,-5.57,0.094
239.04,-5.51,0.094
239.05,-5.44,0.094
239.07,-5.37,0.094
239.08,-5.31,0.094
239.10,-5.24,0.094
239.11,-5.17,0.094
239.12,-5.11,0.094
239.13,-5.04,0.094
239.15,-4.97,0.095
239.16,-4.90,0.095
239.18,-4.84,0.095
239.19,-4.77,0.095
239.20,-4.70,0.095
239.22,-4.64,0.095
239.23,-4.57,0.095
239.24,-4.50,0.095
239.25,-4.44,0.095
239.27,-4.37,0.095
239.28,-4.30,0.095
239.30,-4.23,0.095
239.31,-4.16,0.095
239.32,-4.10,0.095
239.33,-4.03,0.095
239.35,-3.97,0.095
239.36,-3.90,0.095
239.38,-3.83,0.095
239.39,-3.77,0.095
239.40,-3.70,0.095
239.42,-3.63,0.095
239.43,-3.56,0.095
239.44,-3.50,0.095
239.45,-3.43,0.095
239.47,-3.37,0.095
239.48,-3.30,0.095
239.50,-3.23,0.095
239.51,-3.17,0.095
239.52,-3.10,0.095
239.53,-3.03,0.095
239.55,-2.97,0.095
239.56,-2.90,0.095
239.58,-2.83,0.095
239.59,-2.77,0.095
239.60,-2.70,0.095
239.62,-2.63,0.095
239.63,-2.57,0.095
239.64,-2.50,0.096
239.65,-2.43,0.096
239.67,-2.37,0.096
239.68,-2.30,0.096
239.70,-2.23,0.096
239.71,-2.17,0.096
239.72,-2.10,0.096
239.73,-2.03,0.096
239.75,-1.97,0.096
239.76,-1.90,0.096
239.78,-1.83,0.096
239.79,-1.77,0.096
239.80,-1.70,0.096
239.82,-1.63,0.096
239.83,-1.57,0.096
239.84,-1.50,0.096
239.85,-1.43,0.096
239.87,-1.37,0.096
239.88,-1.30,0.096
239.90,-1.23,0.096
239.91,-1.17,0.096
239.92,-1.10,0.096
239.93,-1.03,0.096
239.95,-0.97,0.096
239.96,-0.90,0.096
239.98,-0.83,0.096
239.99,-0.77,0.096
240.00,-0.70,0.096
240.02,-0.63,0.096
240.03,-0.57,0.096
240.04,-0.50,0.096
240.05,-0.43,0.096
240.07,-0.37,0.096
240.08,-0.30,0.096
240.10,-0.23,0.096
240.11,-0.17,0.096
240.12,-0.10,0.096
240.13,-0.03,0.096
240.15,0.03,0.096
240.16,0.10,0.096
240.18,0.17,0.096
240.19,0.23,0.096
240.20,0.30,0.096
240.22,0.37,0.097
240.23,0.43,0.097
240.24,0.50,0.097
240.25,0.57,0.097
240.27,0.63,0.097
240.28,0.70,0.097
240.30,0.77,0.097
240.31,0.83,0.097
240.32,0.90,0.097
240.33,0.97,0.097
240.35,1.03,0.097
240.36,1.10,0.097
240.38,1.17,0.097
240.39,1.23,0.097
240.40,1.30,0.097
240.42,1.37,0.097
240.43,1.43,0.097
240.44,1.50,0.097
240.45,1.57,0.097
240.47,1.63,0.097
240.48,1.70,0.097
240.50,1.77,0.097
240.51,1.83,0.097
240.52,1.90,0.097
240.53,1.97,0.097
240.55,2.04,0.097
240.56,2.10,0.097
240.58,2.17,0.097
240.59,2.24,0.097
240.60,2.30,0.097
240.62,2.37,0.098
240.63,2.44,0.098
240.64,2.50,0.098
240.65,2.57,0.098
240.67,2.64,0.098
240.68,2.70,0.098
240.70,2.77,0.098
240.71,2.84,0.098
240.72,2.90,0.098
240.73,2.97,0.098
240.75,3.04,0.098
240.76,3.10,0.098
240.78,3.17,0.098
240.79,3.24,0.098
240.80,3.30,0.098
240.82,3.37,0.098
240.83,3.44,0.098
240.84,3.50,0.098
240.85,3.57,0.098
240.87,3.64,0.098
240.88,3.70,0.098
240.90,3.77,0.098
240.91,3.84,0.098
240.92,3.90,0.098
240.93,3.97,0.098
240.95,4.04,0.098
240.96,4.10,0.098
240.98,4.17,0.098
240.99,4.24,0.098
241.00,4.30,0.098
241.02,4.37,0.098
241.03,4.44,0.098
241.04,4.50,0.098
241.05,4.57,0.099
241.07,4.64,0.099
241.08,4.70,0.099
241.10,4.77,0.099
241.11,4.84,0.099
241.12,4.90,0.099
241.13,4.97,0.099
241.15,5.04,0.099
241.16,5.10,0.099
241.18,5.17,0.099
241.19,5.24,0.099
241.20,5.30,0.099
241.22,5.37,0.099
241.23,5.44,0.099
241.24,5.50,0.099
241.25,5.57,0.099
241.27,5.64,0.099
241.28,5.70,0.099
241.30,5.77,0.099
241.31,5.84,0.099
241.32,5.90,0.099
241.33,5.97,0.099
241.35,6.04,0.099
241.36,6.10,0.099
241.38,6.17,0.099
241.39,6.24,0.099
241.40,6.30,0.099
241.42,6.37,0.099
241.43,6.44,0.099
241.44,6.51,0.099
241.45,6.57,0.099
241.47,6.64,0.099
241.48,6.71,0.099
241.50,6.77,0.099
241.51,6.84,0.099
241.52,6.90,0.100
241.53,6.97,0.100
241.55,7.04,0.100
241.56,7.11,0.100
241.58,7.17,0.100
241.59,7.24,0.100
241.60,7.30,0.100
241.62,7.37,0.100
241.63,7.44,0.100
241.64,7.51,0.100
241.65,7.57,0.100
241.67,7.64,0.100
241.68,7.71,0.100
241.70,7.77,0.100
241.71,7.84,0.100
241.72,7.91,0.100
241.73,7.97,0.100
241.75,8.04,0.100
241.76,8.11,0.100
241.78,8.17,0.100
241.79,8.24,0.100
241.80,8.31,0.100
241.82,8.37,0.100
241.83,8.44,0.100
241.84,8.51,0.100
241.85,8.57,0.100
241.87,8.64,0.100
241.88,8.71,0.100
241.90,8.77,0.100
241.91,8.84,0.100
241.92,8.91,0.100
241.93,8.97,0.100
241.95,9.04,0.100
241.96,9.11,0.100
241.98,9.17,0.101
241.99,9.24,0.101
242.00,9.31,0.101
242.02,9.37,0.101
242.03,9.44,0.101
242.04,9.51,0.101
242.05,9.57,0.101
242.07,9.64,0.101
242.08,9.71,0.101
242.10,9.77,0.101
242.11,9.84,0.101
242.12,9.91,0.101
242.13,9.97,0.101
242.15,10.04,0.101
242.16,10.11,0.101
242.18,10.17,0.101
242.19,10.24,0.101
242.20,10.31,0.101
242.22,10.38,0.101
242.23,10.44,0.101
242.24,10.51,0.101
242.25,10.57,0.101
242.27,10.64,0.101
242.28,10.71,0.101
242.30,10.77,0.101
242.31,10.84,0.101
242.32,10.91,0.101
242.33,10.98,0.101
242.35,11.04,0.101
242.36,11.11,0.101
242.38,11.17,0.101
242.39,11.24,0.101
242.40,11.31,0.102
242.42,11.37,0.102
242.43,11.44,0.102
242.44,11.51,0.102
242.45,11.58,0.102
242.47,11.64,0.102
242.48,11.71,0.102
242.50,11.78,0.102
242.51,11.84,0.102
242.52,11.91,0.102
242.53,11.97,0.102
242.55,12.04,0.102
242.56,12.11,0.102
242.58,12.17,0.102
242.59,12.24,0.102
242.60,12.31,0.102
242.62,12.37,0.102
242.63,12.44,0.102
242.64,12.51,0.102
242.65,12.58,0.102
242.67,12.64,0.102
242.68,12.71,0.102
242.70,12.78,0.102
242.71,12.84,0.102
242.72,12.91,0.102
242.73,12.98,0.102
242.75,13.04,0.102
242.76,13.11,0.102
242.78,13.18,0.102
242.79,13.24,0.102
242.80,13.31,0.102
242.82,13.38,0.103
242.83,13.44,0.103
242.84,13.51,0.103
242.85,13.58,0.103
242.87,13.64,0.103
242.88,13.71,0.103
242.90,13.78,0.103
242.91,13.84,0.103
242.92,13.91,0.103
242.93,13.98,0.103
242.95,14.04,0.103
242.96,14.11,0.103
242.98,14.18,0.103
242.99,14.24,0.103
243.00,14.31,0.103
243.02,14.38,0.103
243.03,14.44,0.103
243.04,14.51,0.103
243.05,14.58,0.103
243.07,14.64,0.103
243.08,14.71,0.103
243.10,14.78,0.103
243.11,14.84,0.103
243.12,14.91,0.103
243.13,14.98,0.103
243.15,15.04,0.103
243.16,15.11,0.103
243.18,15.18,0.103
243.19,15.24,0.103
243.20,15.31,0.103
243.22,15.38,0.103
243.23,15.45,0.104
243.24,15.51,0.104
243.25,15.58,0.104
243.27,15.65,0.104
243.28,15.71,0.104
243.30,15.78,0.104
243.31,15.84,0.104
243.32,15.91,0.104
243.33,15.98,0.104
243.35,16.04,0.104
243.36,16.11,0.104
243.38,16.18,0.104
243.39,16.24,0.104
243.40,16.31,0.104
243.42,16.38,0.104
243.43,16.44,0.104
243.44,16.51,0.104
243.45,16.58,0.104
243.47,16.65,0.104
243.48,16.71,0.104
243.50,16.78,0.104
243.51,16.85,0.104
243.52,16.91,0.104
243.53,16.98,0.104
243.55,17.04,0.104
243.56,17.11,0.104
243.58,17.18,0.105
243.59,17.25,0.105
243.60,17.31,0.105
243.62,17.38,0.105
243.63,17.44,0.105
243.64,17.51,0.105
243.65,17.58,0.105
243.67,17.65,0.105
243.68,17.71,0.105
243.70,17.78,0.105
243.71,17.85,0.105
243.72,17.91,0.105
243.73,17.98,0.105
243.75,18.05,0.105
243.76,18.11,0.105
243.78,18.18,0.105
243.79,18.25,0.105
243.80,18.31,0.105
243.82,18.38,0.105
243.83,18.45,0.105
243.84,18.51,0.105
243.85,18.58,0.105
243.87,18.65,0.105
243.88,18.71,0.105
243.90,18.78,0.105
243.91,18.85,0.105
243.92,18.91,0.105
243.93,18.98,0.105
243.95,19.05,0.106
243.96,19.11,0.106
243.98,19.18,0.106
243.99,19.25,0.106
244.00,19.31,0.106
244.02,19.38,0.106
244.03,19.45,0.106
244.04,19.51,0.106
244.05,19.58,0.106
244.07,19.65,0.106
244.08,19.71,0.106
244.10,19.78,0.106
244.11,19.85,0.106
244.12,19.91,0.106
244.13,19.98,0.106
244.15,20.05,0.106
244.16,20.11,0.106
244.18,20.18,0.106
244.19,20.25,0.106
244.20,20.31,0.106
244.22,20.38,0.106
244.23,20.45,0.106
244.24,20.51,0.106
244.25,20.58,0.106
244.27,20.65,0.106
244.28,20.71,0.106
244.30,20.78,0.106
244.31,20.85,0.106
244.32,20.91,0.107
244.33,20.98,0.107
244.35,21.05,0.107
244.36,21.11,0.107
244.38,21.18,0.107
244.39,21.25,0.107
244.40,21.31,0.107
244.42,21.38,0.107
244.43,21.45,0.107
244.44,21.51,0.107
244.45,21.58,0.107
244.47,21.65,0.107
244.48,21.72,0.107
244.50,21.78,0.107
244.51,21.85,0.107
244.52,21.92,0.107
244.53,21.98,0.107
244.55,22.05,0.107
244.56,22.12,0.107
244.58,22.18,0.107
244.59,22.25,0.107
244.60,22.32,0.107
244.62,22.38,0.107
244.63,22.45,0.107
244.64,22.52,0.107
244.65,22.58,0.107
244.67,22.65,0.108
244.68,22.72,0.108
244.70,22.78,0.108
244.71,22.85,0.108
244.72,22.92,0.108
244.73,22.98,0.108
244.75,23.05,0.108
244.76,23.12,0.108
244.78,23.18,0.108
244.79,23.25,0.108
244.80,23.32,0.108
244.82,23.38,0.108
244.83,23.45,0.108
244.84,23.52,0.108
244.85,23.58,0.108
244.87,23.65,0.108
244.88,23.72,0.108
244.90,23.78,0.108
244.91,23.85,0.108
244.92,23.92,0.108
244.93,23.98,0.108
244.95,24.05,0.108
244.96,24.12,0.108
244.98,24.18,0.108
244.99,24.25,0.108
245.00,24.32,0.108
245.02,24.38,0.108
245.03,24.45,0.109
245.04,24.52,0.109
245.05,24.58,0.109
245.07,24.65,0.109
245.08,24.72,0.109
245.10,24.78,0.109
245.11,24.85,0.109
245.12,24.92,0.109
245.13,24.98,0.109
245.15,25.05,0.109
245.16,25.12,0.109
245.18,25.18,0.109
245.19,25.25,0.109
245.20,25.32,0.109
245.22,25.38,0.109
245.23,25.45,0.109
245.24,25.52,0.109
245.25,25.58,0.109
245.27,25.65,0.109
245.28,25.72,0.109
245.30,25.78,0.109
245.31,25.85,0.109
245.32,25.92,0.109
245.33,25.98,0.109
245.35,26.05,0.110
245.36,26.12,0.110
245.38,26.18,0.110
245.39,26.25,0.110
245.40,26.32,0.110
245.42,26.38,0.110
245.43,26.45,0.110
245.44,26.52,0.110
245.45,26.58,0.110
245.47,26.65,0.110
245.48,26.72,0.110
245.50,26.78,0.110
245.51,26.85,0.110
245.52,26.92,0.110
245.53,26.98,0.110
245.55,27.05,0.110
245.56,27.12,0.110
245.58,27.18,0.110
245.59,27.25,0.110
245.60,27.32,0.110
245.62,27.38,0.110
245.63,27.45,0.110
245.64,27.52,0.110
245.65,27.59,0.110
245.67,27.65,0.111
245.68,27.72,0.111
245.70,27.79,0.111
245.71,27.85,0.111
245.72,27.92,0.111
245.73,27.99,0.111
245.75,28.05,0.111
245.76,28.12,0.111
245.78,28.19,0.111
245.79,28.25,0.111
245.80,28.32,0.111
245.82,28.38,0.111
245.83,28.45,0.111
245.84,28.52,0.111
245.85,28.58,0.111
245.87,28.65,0.111
245.88,28.72,0.111
245.90,28.79,0.111
245.91,28.85,0.111
245.92,28.92,0.111
245.93,28.99,
245.95,29.05,
245.96,29.12,
245.98,29.19,
245.99,,