File: DSC/Olivia/2025_08_05_TS_Empty_Baseline_n60C_250C_10Cmin_x3.csv
Filename,2025_08_05_TS_Empty_Baseline_n60C_250C_10Cmin_x3
Instrument name,DSC2A-00468 (192.168.1.100)
Operator,Yarger
rundate,8/5/2025
Sample name,2025_08_05_TS_Empty_Baseline_n60C_250C_10Cmin_x3
proceduresegments,Data Off ; Equilibrate -60.00 °C; Data On ; Ramp 10.00 °C/min to 250.00 °C; Data Off ; Isothermal 2.0 min; Data On ; Ramp 10.00 °C/min to -60.00 °C; Data Off ; Isothermal 2.0 min; Data On ; Ramp 10.00 °C/min to 250.00 °C; Data Off ; Isothermal 2.0 min; Data On ; Ramp 10.00 °C/min to -60.00 °C; Data Off ; Isothermal 2.0 min; Data On ; Ramp 10.00 °C/min to 250.00 °C
[File Parameters]
Run date,8/5/2025 4:00:44 PM
Trios version,5.1.1.46572
Original File Name,
Current File Name,D:\DSC2500\JYarger\2025_08_05_TS_Empty_Baseline_n60C_250C_10Cmin_x3.tri
[Procedure]
Procedure Name,Empty_TS_Pans_n60C_250C_10Cmin_x3
Sample Name,2025_08_05_TS_Empty_Baseline_n60C_250C_10Cmin_x3
Sample Mass,0 mg
Reference Sample Mass,0 mg
Pan Mass,32.37 mg
Pan Number,5
Reference Pan Mass,32.52 mg
Reference Pan Number,37
Pan Type,Aluminum
Comments,Thermal support Al pans/lids. DSC_Samples_A2_Tray_July2025 google sheet.
Project Name,Demo
Operator,Yarger
Test,Custom
Unload Max Temperature,30
Unload Min Temperature,30
Load Max Temperature,30
Load Min Temperature,30
Stop on Gas Flow Error,Yes
[Signal List]
Signal #1,Time (min)
Signal #2,Temperature (°C)
Signal #3,Heat Flow (mW)
Signal #4,Delta T (µV)
Signal #5,Delta Tzero (µV)
Signal #6,Tzero Temperature (°C)
Signal #7,Cell Purge (mL/min)
Signal #8,Heater Temp (°C)
Signal #9,Power Delivered (W)
Signal #10,Reference Junction Temperature (°C)
Signal #11,Flange Temperature (°C)
Signal #12,Heat Flow Phase (rad)
Signal #13,Total Heat Capacity (J/°C)
Signal #14,Heat Capacity (J/°C)
[Configuration]
Company Name,ASU
Instrument Name,DSC2A-00468
Instrument Type,DSC2500
Serial Number,DSC2A-00468
IP,192.168.1.100
Location of Instrument,MRRC
DisplayType,Unknown
Sample Interval ,0.1 s/pt
Selected Heat Flow,T4P
Exotherm Direction,Down
Cell Serial,DRC2-00792
Lid Type,Standard
Cooler,RCS 90
Leave Cooler on at End of Sequence,On
Gas 2,Nitrogen
Gas Selected,Channel 1
Flow Rate,50 mL/min
Secondary Purge,On
Licensed Heat Flow,Heat Flow T4P
Modulation Licensed,Yes
[Versions]
Common IDD Version,1
Cortex Version,VER 2.10.2.31
Driver,5.0.0.6
GDM Version,1.0.3.3
TouchscreenVersion,1.0.0.16145
FEP Version,1.2.1.21
FEP Bootloader,2.0.0.5
AutoSampler Version,2.1.1.26
Auto Sampler Bootloader,2.0.0.5
FCM Version,1.1.0.3
FCM Bootloader,2.0.0.5
[Experiment Logs]
Experiment Log Entry # 1,Data On set to 0
Experiment Log Entry # 3,Equilibrate Segment -60 (C) Started
Experiment Log Entry # 5,Air Cool is off.
Experiment Log Entry # 7,Data On set to 1
Experiment Log Entry # 9,Ramp Segment 10 C/min to 250 Started
Experiment Log Entry # 11,Data On set to 0
Experiment Log Entry # 13,Isothermal Segment 2 min started
Experiment Log Entry # 15,Data On set to 1
Experiment Log Entry # 17,Ramp Segment 10 C/min to -60 Started
Experiment Log Entry # 19,Data On set to 0
Experiment Log Entry # 21,Isothermal Segment 2 min started
Experiment Log Entry # 23,Data On set to 1
Experiment Log Entry # 25,Ramp Segment 10 C/min to 250 Started
Experiment Log Entry # 27,Data On set to 0
Experiment Log Entry # 29,Isothermal Segment 2 min started
Experiment Log Entry # 31,Data On set to 1
Experiment Log Entry # 33,Ramp Segment 10 C/min to -60 Started
Experiment Log Entry # 35,Data On set to 0
Experiment Log Entry # 37,Isothermal Segment 2 min started
Experiment Log Entry # 39,Data On set to 1
Experiment Log Entry # 41,Ramp Segment 10 C/min to 250 Started
[Method Log]
Method Log Entry # 1,Data Off
Method Log Entry # 2,Equilibrate -60 °C
Method Log Entry # 3,Data On
Method Log Entry # 4,(Ramp 209757) Ramp 10 °C/minute to 250 °C
Method Log Entry # 5,Data Off
Method Log Entry # 6,Isothermal 2 minutes
Method Log Entry # 7,Data On
Method Log Entry # 8,(Ramp 209761) Ramp 10 °C/minute to -60 °C
Method Log Entry # 9,Data Off
Method Log Entry # 10,Isothermal 2 minutes
Method Log Entry # 11,Data On
Method Log Entry # 12,(Ramp 209765) Ramp 10 °C/minute to 250 °C
Method Log Entry # 13,Data Off
Method Log Entry # 14,Isothermal 2 minutes
Method Log Entry # 15,Data On
Method Log Entry # 16,(Ramp 209769) Ramp 10 °C/minute to -60 °C
Method Log Entry # 17,Data Off
Method Log Entry # 18,Isothermal 2 minutes
Method Log Entry # 19,Data On
Method Log Entry # 20,(Ramp 209773) Ramp 10 °C/minute to 250 °C
Cell Serial,DRC2-00792
[T1 Calibration]
Slope,-0.008529666
Offset,9.636258
Initial Temperature,98.23
GUID,f8bfdadc-4977-4fdf-ba6d-0ba9134940c3
[TZero Calibration]
Date Applied,11/29/2022 4:06:13 PM
Description,From -89.059 °C to 396.009 °C at 20.000°C/min
Gas Type,Nitrogen
Pan Type,None
Source Files 1,C:\Users\yargerlab\Desktop\DSC Data\General\TZero_calibration_11_29_22_2nd(2).tri
Source Files 2,C:\Users\yargerlab\Desktop\DSC Data\General\TZero_calibration_11_29_22_2nd(3).tri
Delta T Offset,13.05235
Delta T Slope,-0.007271007
Delta T0 Offset,-13.69128
Delta T0 Slope,0.06063341
[Temperature Calibration]
Date Applied,11/29/2022 7:12:28 PM
Description,From 106.590 °C to 186.590 °C at 10.000°C/min
Gas Type,Nitrogen
Pan Type,Tzero Aluminum Hermetic
Source Files 1,C:\Users\yargerlab\Desktop\DSC Data\General\Indium(6).tri
Measured 1,157.391
Known 1,156.598
[Cell Constant Calibration]
Date Applied,11/29/2022 7:12:29 PM
Description,From 106.590 °C to 186.590 °C at 10.000°C/min
Gas Type,Nitrogen
Pan Type,Tzero Aluminum Hermetic
Source Files 1,C:\Users\yargerlab\Desktop\DSC Data\General\Indium(6).tri
T4P KCell,1.006051
Onset Slope,63.26126 mW/°C
[Direct Cp Calibration]
Date Applied,11/30/2022 11:04:51 AM
Description,From -79.983 °C to 298.409 °C at 10.000°C/min
Gas Type,Nitrogen
Pan Type,Tzero Aluminum Hermetic
Source Files 1,C:\Users\yargerlab\Desktop\DSC Data\General\Sapphire_Heat_Capacity_11_30_22.tri
[Rev Cp Calibration]
Date Applied,11/30/2022 1:58:51 PM
Description,From -79.996 °C to 292.812 °C at 3.000°C/min
Gas Type,Nitrogen
Pan Type,Tzero Aluminum Hermetic
Source Files 1,C:\Users\yargerlab\Desktop\DSC Data\General\Sapphire_MDSC_Calibration_11_30_22.tri
[step]
Ramp 10.00 °C/min to 250.00 °C
Time,Temperature,Heat Flow (Normalized)
min,°C,W/g
0.00,-59.82,
0.02,-59.82,
0.04,-59.82,
0.07,-59.80,
0.09,-59.74,
0.11,-59.65,
0.13,-59.53,
0.15,-59.38,
0.17,-59.21,
0.19,-59.02,
0.22,-58.83,
0.24,-58.62,
0.26,-58.42,
0.28,-58.21,
0.30,-58.00,
0.33,-57.79,
0.35,-57.58,
0.37,-57.37,
0.39,-57.15,
0.41,-56.94,
0.43,-56.73,
0.45,-56.52,
0.48,-56.31,
0.50,-56.09,
0.52,-55.88,
0.54,-55.67,
0.56,-55.45,
0.58,-55.24,
0.61,-55.02,
0.63,-54.81,
0.65,-54.60,
0.67,-54.38,
0.69,-54.17,
0.72,-53.95,
0.74,-53.74,
0.76,-53.53,
0.78,-53.31,
0.80,-53.10,
0.82,-52.88,
0.85,-52.66,
0.87,-52.45,
0.89,-52.24,
0.91,-52.02,
0.93,-51.81,
0.95,-51.59,
0.98,-51.37,
1.00,-51.16,
1.02,-50.94,
1.04,-50.73,
1.06,-50.51,
1.08,-50.29,
1.11,-50.08,
1.13,-49.86,
1.15,-49.65,
1.17,-49.43,
1.19,-49.22,
1.21,-49.00,
1.23,-48.78,
1.26,-48.57,
1.28,-48.35,
1.30,-48.13,
1.32,-47.92,
1.34,-47.70,
1.37,-47.49,
1.39,-47.27,
1.41,-47.05,
1.43,-46.83,
1.45,-46.62,
1.47,-46.40,
1.49,-46.19,
1.52,-45.97,
1.54,-45.75,
1.56,-45.54,
1.58,-45.32,
1.60,-45.10,
1.63,-44.89,
1.65,-44.67,
1.67,-44.45,
1.69,-44.24,
1.71,-44.02,
1.73,-43.80,
1.76,-43.59,
1.78,-43.37,
1.80,-43.15,
1.82,-42.94,
1.84,-42.72,
1.86,-42.50,
1.88,-42.28,
1.91,-42.07,
1.93,-41.85,
1.95,-41.63,
1.97,-41.42,
1.99,-41.20,
2.02,-40.98,
2.04,-40.77,
2.06,-40.55,
2.08,-40.33,
2.10,-40.12,
2.12,-39.90,
2.14,-39.68,
2.17,-39.46,
2.19,-39.25,
2.21,-39.03,
2.23,-38.81,
2.25,-38.60,
2.28,-38.38,
2.30,-38.16,
2.32,-37.95,
2.34,-37.73,
2.36,-37.51,
2.38,-37.29,
2.41,-37.08,
2.43,-36.86,
2.45,-36.64,
2.47,-36.43,
2.49,-36.21,
2.51,-35.99,
2.54,-35.78,
2.56,-35.56,
2.58,-35.34,
2.60,-35.13,
2.62,-34.91,
2.64,-34.69,
2.66,-34.47,
2.69,-34.26,
2.71,-34.04,
2.73,-33.82,
2.75,-33.61,
2.77,-33.39,
2.79,-33.17,
2.82,-32.95,
2.84,-32.74,
2.86,-32.52,
2.88,-32.30,
2.90,-32.09,
2.93,-31.87,
2.95,-31.65,
2.97,-31.43,
2.99,-31.22,
3.01,-31.00,
3.03,-30.78,
3.06,-30.57,
3.08,-30.35,
3.10,-30.13,
3.12,-29.92,
3.14,-29.70,
3.16,-29.48,
3.19,-29.26,
3.21,-29.05,
3.23,-28.83,
3.25,-28.61,
3.27,-28.40,
3.29,-28.18,
3.31,-27.96,
3.34,-27.75,
3.36,-27.53,
3.38,-27.32,
3.40,-27.10,
3.42,-26.88,
3.44,-26.66,
3.47,-26.45,
3.49,-26.23,
3.51,-26.01,
3.53,-25.79,
3.55,-25.58,
3.58,-25.36,
3.60,-25.14,
3.62,-24.93,
3.64,-24.71,
3.66,-24.49,
3.68,-24.28,
3.71,-24.06,
3.73,-23.84,
3.75,-23.62,
3.77,-23.41,
3.79,-23.19,
3.81,-22.97,
3.84,-22.76,
3.86,-22.54,
3.88,-22.32,
3.90,-22.11,
3.92,-21.89,
3.94,-21.67,
3.96,-21.45,
3.99,-21.24,
4.01,-21.02,
4.03,-20.80,
4.05,-20.59,
4.07,-20.37,
4.09,-20.15,
4.12,-19.94,
4.14,-19.72,
4.16,-19.50,
4.18,-19.29,
4.20,-19.07,
4.23,-18.85,
4.25,-18.63,
4.27,-18.42,
4.29,-18.20,
4.31,-17.98,
4.33,-17.77,
4.35,-17.55,
4.38,-17.33,
4.40,-17.12,
4.42,-16.90,
4.44,-16.68,
4.46,-16.47,
4.49,-16.25,
4.51,-16.03,
4.53,-15.81,
4.55,-15.60,
4.57,-15.38,
4.59,-15.16,
4.61,-14.95,
4.64,-14.73,
4.66,-14.51,
4.68,-14.30,
4.70,-14.08,
4.72,-13.86,
4.75,-13.65,
4.77,-13.43,
4.79,-13.21,
4.81,-12.99,
4.83,-12.78,
4.85,-12.56,
4.88,-12.34,
4.90,-12.13,
4.92,-11.91,
4.94,-11.69,
4.96,-11.48,
4.98,-11.26,
5.00,-11.04,
5.03,-10.83,
5.05,-10.61,
5.07,-10.39,
5.09,-10.17,
5.11,-9.96,
5.14,-9.74,
5.16,-9.52,
5.18,-9.31,
5.20,-9.09,
5.22,-8.87,
5.24,-8.66,
5.26,-8.44,
5.29,-8.22,
5.31,-8.00,
5.33,-7.79,
5.35,-7.57,
5.37,-7.36,
5.40,-7.14,
5.42,-6.92,
5.44,-6.70,
5.46,-6.49,
5.48,-6.27,
5.50,-6.05,
5.53,-5.84,
5.55,-5.62,
5.57,-5.40,
5.59,-5.19,
5.61,-4.97,
5.63,-4.75,
5.65,-4.53,
5.68,-4.32,
5.70,-4.10,
5.72,-3.88,
5.74,-3.67,
5.76,-3.45,
5.79,-3.23,
5.81,-3.02,
5.83,-2.80,
5.85,-2.58,
5.87,-2.36,
5.89,-2.15,
5.91,-1.93,
5.94,-1.71,
5.96,-1.50,
5.98,-1.28,
6.00,-1.06,
6.02,-0.85,
6.05,-0.63,
6.07,-0.41,
6.09,-0.19,
6.11,0.02,
6.13,0.24,
6.15,0.45,
6.18,0.67,
6.20,0.89,
6.22,1.11,
6.24,1.32,
6.26,1.54,
6.28,1.76,
6.30,1.97,
6.33,2.19,
6.35,2.41,
6.37,2.63,
6.39,2.84,
6.41,3.06,
6.44,3.28,
6.46,3.49,
6.48,3.71,
6.50,3.93,
6.52,4.14,
6.54,4.36,
6.56,4.58,
6.59,4.79,
6.61,5.01,
6.63,5.23,
6.65,5.45,
6.67,5.66,
6.70,5.88,
6.72,6.10,
6.74,6.31,
6.76,6.53,
6.78,6.75,
6.80,6.96,
6.83,7.18,
6.85,7.40,
6.87,7.61,
6.89,7.83,
6.91,8.05,
6.93,8.27,
6.95,8.48,
6.98,8.70,
7.00,8.92,
7.02,9.13,
7.04,9.35,
7.06,9.57,
7.09,9.78,
7.11,10.00,
7.13,10.22,
7.15,10.43,
7.17,10.65,
7.19,10.87,
7.21,11.09,
7.24,11.30,
7.26,11.52,
7.28,11.74,
7.30,11.95,
7.32,12.17,
7.35,12.39,
7.37,12.60,
7.39,12.82,
7.41,13.04,
7.43,13.26,
7.45,13.47,
7.48,13.69,
7.50,13.91,
7.52,14.12,
7.54,14.34,
7.56,14.56,
7.58,14.77,
7.60,14.99,
7.63,15.21,
7.65,15.42,
7.67,15.64,
7.69,15.86,
7.71,16.07,
7.74,16.29,
7.76,16.51,
7.78,16.73,
7.80,16.94,
7.82,17.16,
7.84,17.38,
7.86,17.59,
7.89,17.81,
7.91,18.03,
7.93,18.24,
7.95,18.46,
7.97,18.68,
8.00,18.89,
8.02,19.11,
8.04,19.33,
8.06,19.54,
8.08,19.76,
8.10,19.98,
8.13,20.19,
8.15,20.41,
8.17,20.63,
8.19,20.85,
8.21,21.06,
8.23,21.28,
8.25,21.50,
8.28,21.71,
8.30,21.93,
8.32,22.15,
8.34,22.36,
8.36,22.58,
8.39,22.80,
8.41,23.01,
8.43,23.23,
8.45,23.45,
8.47,23.66,
8.49,23.88,
8.51,24.10,
8.54,24.31,
8.56,24.53,
8.58,24.75,
8.60,24.97,
8.62,25.18,
8.65,25.40,
8.67,25.62,
8.69,25.83,
8.71,26.05,
8.73,26.27,
8.75,26.48,
8.78,26.70,
8.80,26.92,
8.82,27.13,
8.84,27.35,
8.86,27.57,
8.88,27.79,
8.90,28.00,
8.93,28.22,
8.95,28.44,
8.97,28.65,
8.99,28.87,
9.01,29.09,
9.03,29.30,
9.06,29.52,
9.08,29.74,
9.10,29.95,
9.12,30.17,
9.14,30.39,
9.17,30.61,
9.19,30.82,
9.21,31.04,
9.23,31.26,
9.25,31.47,
9.27,31.69,
9.30,31.91,
9.32,32.12,
9.34,32.34,
9.36,32.56,
9.38,32.77,
9.40,32.99,
9.43,33.21,
9.45,33.43,
9.47,33.64,
9.49,33.86,
9.51,34.08,
9.53,34.29,
9.55,34.51,
9.58,34.73,
9.60,34.94,
9.62,35.16,
9.64,35.38,
9.66,35.59,
9.68,35.81,
9.71,36.03,
9.73,36.24,
9.75,36.46,
9.77,36.68,
9.79,36.90,
9.82,37.11,
9.84,37.33,
9.86,37.55,
9.88,37.76,
9.90,37.98,
9.92,38.20,
9.95,38.41,
9.97,38.63,
9.99,38.85,
10.01,39.07,
10.03,39.28,
10.05,39.50,
10.08,39.72,
10.10,39.93,
10.12,40.15,
10.14,40.37,
10.16,40.58,
10.18,40.80,
10.20,41.02,
10.23,41.23,
10.25,41.45,
10.27,41.67,
10.29,41.89,
10.31,42.10,
10.33,42.32,
10.36,42.54,
10.38,42.75,
10.40,42.97,
10.42,43.19,
10.44,43.40,
10.47,43.62,
10.49,43.84,
10.51,44.05,
10.53,44.27,
10.55,44.49,
10.57,44.70,
10.60,44.92,
10.62,45.14,
10.64,45.36,
10.66,45.57,
10.68,45.79,
10.70,46.01,
10.73,46.22,
10.75,46.44,
10.77,46.66,
10.79,46.87,
10.81,47.09,
10.83,47.31,
10.85,47.52,
10.88,47.74,
10.90,47.96,
10.92,48.18,
10.94,48.39,
10.96,48.61,
10.98,48.83,
11.01,49.04,
11.03,49.26,
11.05,49.48,
11.07,49.69,
11.09,49.91,
11.12,50.13,
11.14,50.34,
11.16,50.56,
11.18,50.78,
11.20,51.00,
11.22,51.21,
11.25,51.43,
11.27,51.65,
11.29,51.86,
11.31,52.08,
11.33,52.30,
11.35,52.51,
11.38,52.73,
11.40,52.95,
11.42,53.16,
11.44,53.38,
11.46,53.60,
11.48,53.81,
11.50,54.03,
11.53,54.25,
11.55,54.47,
11.57,54.68,
11.59,54.90,
11.61,55.12,
11.63,55.33,
11.66,55.55,
11.68,55.77,
11.70,55.98,
11.72,56.20,
11.74,56.42,
11.77,56.63,
11.79,56.85,
11.81,57.07,
11.83,57.29,
11.85,57.50,
11.87,57.72,
11.90,57.94,
11.92,58.15,
11.94,58.37,
11.96,58.59,
11.98,58.80,
12.00,59.02,
12.03,59.24,
12.05,59.45,
12.07,59.67,
12.09,59.89,
12.11,60.11,
12.13,60.32,
12.15,60.54,
12.18,60.76,
12.20,60.97,
12.22,61.19,
12.24,61.41,
12.26,61.62,
12.28,61.84,
12.31,62.06,
12.33,62.27,
12.35,62.49,
12.37,62.71,
12.39,62.92,
12.42,63.14,
12.44,63.36,
12.46,63.57,
12.48,63.79,
12.50,64.01,
12.52,64.23,
12.55,64.44,
12.57,64.66,
12.59,64.88,
12.61,65.09,
12.63,65.31,
12.65,65.53,
12.68,65.74,
12.70,65.96,
12.72,66.18,
12.74,66.40,
12.76,66.61,
12.78,66.83,
12.80,67.05,
12.83,67.26,
12.85,67.48,
12.87,67.70,
12.89,67.92,
12.91,68.13,
12.93,68.35,
12.96,68.57,
12.98,68.78,
13.00,69.00,
13.02,69.22,
13.04,69.43,
13.07,69.65,
13.09,69.87,
13.11,70.08,
13.13,70.30,
13.15,70.52,
13.17,70.73,
13.20,70.95,
13.22,71.17,
13.24,71.38,
13.26,71.60,
13.28,71.82,
13.30,72.04,
13.33,72.26,
13.35,72.47,
13.37,72.69,
13.39,72.91,
13.41,73.13,
13.43,73.34,
13.45,73.56,
13.48,73.78,
13.50,73.99,
13.52,74.21,
13.54,74.43,
13.56,74.64,
13.58,74.86,
13.61,75.07,
13.63,75.29,
13.65,75.51,
13.67,75.72,
13.69,75.94,
13.72,76.16,
13.74,76.37,
13.76,76.59,
13.78,76.81,
13.80,77.02,
13.82,77.24,
13.85,77.46,
13.87,77.67,
13.89,77.89,
13.91,78.11,
13.93,78.33,
13.95,78.54,
13.98,78.76,
14.00,78.97,
14.02,79.19,
14.04,79.41,
14.06,79.62,
14.08,79.84,
14.10,80.06,
14.13,80.27,
14.15,80.49,
14.17,80.71,
14.19,80.92,
14.21,81.14,
14.23,81.36,
14.26,81.57,
14.28,81.79,
14.30,82.01,
14.32,82.22,
14.34,82.44,
14.37,82.66,
14.39,82.88,
14.41,83.09,
14.43,83.31,
14.45,83.53,
14.47,83.74,
14.50,83.96,
14.52,84.18,
14.54,84.39,
14.56,84.61,
14.58,84.83,
14.60,85.05,
14.63,85.26,
14.65,85.48,
14.67,85.70,
14.69,85.91,
14.71,86.13,
14.73,86.35,
14.75,86.56,
14.78,86.78,
14.80,87.00,
14.82,87.21,
14.84,87.43,
14.86,87.65,
14.88,87.87,
14.91,88.08,
14.93,88.30,
14.95,88.52,
14.97,88.73,
14.99,88.95,
15.02,89.17,
15.04,89.38,
15.06,89.60,
15.08,89.82,
15.10,90.03,
15.12,90.25,
15.15,90.47,
15.17,90.68,
15.19,90.90,
15.21,91.12,
15.23,91.33,
15.25,91.55,
15.28,91.77,
15.30,91.98,
15.32,92.20,
15.34,92.42,
15.36,92.64,
15.38,92.85,
15.40,93.07,
15.43,93.29,
15.45,93.50,
15.47,93.72,
15.49,93.94,
15.51,94.15,
15.53,94.37,
15.56,94.59,
15.58,94.80,
15.60,95.02,
15.62,95.24,
15.64,95.45,
15.67,95.67,
15.69,95.89,
15.71,96.11,
15.73,96.32,
15.75,96.54,
15.77,96.76,
15.80,96.97,
15.82,97.19,
15.84,97.41,
15.86,97.62,
15.88,97.84,
15.90,98.06,
15.93,98.27,
15.95,98.49,
15.97,98.71,
15.99,98.93,
16.01,99.14,
16.03,99.36,
16.05,99.58,
16.08,99.79,
16.10,100.01,
16.12,100.23,
16.14,100.44,
16.16,100.66,
16.18,100.88,
16.21,101.09,
16.23,101.31,
16.25,101.53,
16.27,101.74,
16.29,101.96,
16.32,102.18,
16.34,102.39,
16.36,102.61,
16.38,102.83,
16.40,103.04,
16.42,103.26,
16.45,103.48,
16.47,103.70,
16.49,103.91,
16.51,104.13,
16.53,104.34,
16.55,104.56,
16.58,104.78,
16.60,104.99,
16.62,105.21,
16.64,105.43,
16.66,105.65,
16.68,105.86,
16.70,106.08,
16.73,106.30,
16.75,106.52,
16.77,106.73,
16.79,106.95,
16.81,107.16,
16.83,107.38,
16.86,107.60,
16.88,107.81,
16.90,108.03,
16.92,108.25,
16.94,108.47,
16.97,108.68,
16.99,108.90,
17.01,109.12,
17.03,109.33,
17.05,109.55,
17.07,109.77,
17.09,109.98,
17.12,110.20,
17.14,110.42,
17.16,110.63,
17.18,110.85,
17.20,111.07,
17.23,111.29,
17.25,111.50,
17.27,111.72,
17.29,111.94,
17.31,112.15,
17.33,112.37,
17.36,112.59,
17.38,112.80,
17.40,113.02,
17.42,113.24,
17.44,113.46,
17.46,113.67,
17.48,113.89,
17.51,114.10,
17.53,114.32,
17.55,114.54,
17.57,114.75,
17.59,114.97,
17.62,115.19,
17.64,115.40,
17.66,115.62,
17.68,115.84,
17.70,116.06,
17.72,116.27,
17.74,116.49,
17.77,116.71,
17.79,116.92,
17.81,117.14,
17.83,117.36,
17.85,117.57,
17.88,117.79,
17.90,118.01,
17.92,118.22,
17.94,118.44,
17.96,118.66,
17.98,118.87,
18.01,119.09,
18.03,119.31,
18.05,119.53,
18.07,119.74,
18.09,119.96,
18.11,120.18,
18.13,120.39,
18.16,120.61,
18.18,120.83,
18.20,121.04,
18.22,121.26,
18.24,121.48,
18.27,121.69,
18.29,121.91,
18.31,122.13,
18.33,122.34,
18.35,122.56,
18.37,122.78,
18.39,122.99,
18.42,123.21,
18.44,123.43,
18.46,123.65,
18.48,123.86,
18.50,124.08,
18.53,124.30,
18.55,124.51,
18.57,124.73,
18.59,124.95,
18.61,125.17,
18.63,125.38,
18.66,125.60,
18.68,125.82,
18.70,126.03,
18.72,126.25,
18.74,126.47,
18.76,126.68,
18.78,126.90,
18.81,127.11,
18.83,127.33,
18.85,127.55,
18.87,127.77,
18.89,127.98,
18.92,128.20,
18.94,128.42,
18.96,128.63,
18.98,128.85,
19.00,129.07,
19.02,129.28,
19.04,129.50,
19.07,129.72,
19.09,129.93,
19.11,130.15,
19.13,130.37,
19.15,130.58,
19.18,130.80,
19.20,131.02,
19.22,131.24,
19.24,131.45,
19.26,131.67,
19.28,131.89,
19.31,132.10,
19.33,132.32,
19.35,132.53,
19.37,132.75,
19.39,132.97,
19.41,133.19,
19.43,133.40,
19.46,133.62,
19.48,133.84,
19.50,134.05,
19.52,134.27,
19.54,134.49,
19.57,134.71,
19.59,134.92,
19.61,135.14,
19.63,135.36,
19.65,135.57,
19.67,135.79,
19.69,136.01,
19.72,136.22,
19.74,136.44,
19.76,136.65,
19.78,136.87,
19.80,137.09,
19.83,137.30,
19.85,137.52,
19.87,137.74,
19.89,137.95,
19.91,138.17,
19.93,138.39,
19.96,138.61,
19.98,138.82,
20.00,139.04,
20.02,139.26,
20.04,139.47,
20.06,139.69,
20.08,139.91,
20.11,140.12,
20.13,140.34,
20.15,140.56,
20.17,140.77,
20.19,140.99,
20.22,141.21,
20.24,141.43,
20.26,141.64,
20.28,141.86,
20.30,142.08,
20.32,142.29,
20.34,142.51,
20.37,142.73,
20.39,142.94,
20.41,143.16,
20.43,143.38,
20.45,143.59,
20.48,143.81,
20.50,144.03,
20.52,144.24,
20.54,144.46,
20.56,144.68,
20.58,144.89,
20.61,145.11,
20.63,145.33,
20.65,145.55,
20.67,145.76,
20.69,145.98,
20.71,146.20,
20.73,146.41,
20.76,146.63,
20.78,146.85,
20.80,147.06,
20.82,147.28,
20.84,147.50,
20.87,147.71,
20.89,147.93,
20.91,148.15,
20.93,148.37,
20.95,148.58,
20.97,148.80,
20.99,149.02,
21.02,149.23,
21.04,149.45,
21.06,149.67,
21.08,149.88,
21.10,150.10,
21.13,150.32,
21.15,150.53,
21.17,150.75,
21.19,150.97,
21.21,151.18,
21.23,151.40,
21.26,151.62,
21.28,151.83,
21.30,152.05,
21.32,152.27,
21.34,152.49,
21.36,152.70,
21.38,152.92,
21.41,153.14,
21.43,153.35,
21.45,153.57,
21.47,153.79,
21.49,154.00,
21.52,154.22,
21.54,154.44,
21.56,154.65,
21.58,154.87,
21.60,155.09,
21.62,155.30,
21.64,155.52,
21.67,155.74,
21.69,155.96,
21.71,156.17,
21.73,156.39,
21.75,156.60,
21.78,156.82,
21.80,157.04,
21.82,157.25,
21.84,157.47,
21.86,157.69,
21.88,157.91,
21.91,158.12,
21.93,158.34,
21.95,158.55,
21.97,158.77,
21.99,158.99,
22.01,159.21,
22.03,159.42,
22.06,159.64,
22.08,159.86,
22.10,160.07,
22.12,160.29,
22.14,160.51,
22.17,160.72,
22.19,160.94,
22.21,161.16,
22.23,161.37,
22.25,161.59,
22.27,161.81,
22.29,162.03,
22.32,162.24,
22.34,162.46,
22.36,162.67,
22.38,162.89,
22.40,163.11,
22.43,163.32,
22.45,163.54,
22.47,163.76,
22.49,163.98,
22.51,164.19,
22.53,164.41,
22.56,164.63,
22.58,164.84,
22.60,165.06,
22.62,165.28,
22.64,165.49,
22.66,165.71,
22.68,165.93,
22.71,166.14,
22.73,166.36,
22.75,166.58,
22.77,166.79,
22.79,167.01,
22.82,167.23,
22.84,167.45,
22.86,167.66,
22.88,167.88,
22.90,168.09,
22.92,168.31,
22.94,168.53,
22.97,168.75,
22.99,168.96,
23.01,169.18,
23.03,169.39,
23.05,169.61,
23.08,169.83,
23.10,170.05,
23.12,170.26,
23.14,170.48,
23.16,170.70,
23.18,170.91,
23.21,171.13,
23.23,171.35,
23.25,171.56,
23.27,171.78,
23.29,172.00,
23.31,172.22,
23.33,172.43,
23.36,172.65,
23.38,172.87,
23.40,173.08,
23.42,173.30,
23.44,173.51,
23.47,173.73,
23.49,173.95,
23.51,174.17,
23.53,174.38,
23.55,174.60,
23.57,174.82,
23.59,175.03,
23.62,175.25,
23.64,175.47,
23.66,175.68,
23.68,175.90,
23.70,176.12,
23.73,176.33,
23.75,176.55,
23.77,176.77,
23.79,176.99,
23.81,177.20,
23.83,177.42,
23.86,177.64,
23.88,177.85,
23.90,178.07,
23.92,178.29,
23.94,178.50,
23.96,178.72,
23.98,178.94,
24.01,179.15,
24.03,179.37,
24.05,179.59,
24.07,179.80,
24.09,180.02,
24.12,180.23,
24.14,180.45,
24.16,180.67,
24.18,180.89,
24.20,181.10,
24.22,181.32,
24.24,181.54,
24.27,181.75,
24.29,181.97,
24.31,182.19,
24.33,182.40,
24.35,182.62,
24.38,182.84,
24.40,183.05,
24.42,183.27,
24.44,183.49,
24.46,183.71,
24.48,183.92,
24.51,184.14,
24.53,184.35,
24.55,184.57,
24.57,184.79,
24.59,185.01,
24.61,185.22,
24.63,185.44,
24.66,185.66,
24.68,185.87,
24.70,186.09,
24.72,186.31,
24.74,186.52,
24.77,186.74,
24.79,186.96,
24.81,187.17,
24.83,187.39,
24.85,187.61,
24.87,187.82,
24.89,188.04,
24.92,188.26,
24.94,188.47,
24.96,188.69,
24.98,188.91,
25.00,189.12,
25.03,189.34,
25.05,189.56,
25.07,189.78,
25.09,189.99,
25.11,190.21,
25.13,190.43,
25.16,190.64,
25.18,190.86,
25.20,191.08,
25.22,191.29,
25.24,191.51,
25.26,191.73,
25.28,191.94,
25.31,192.16,
25.33,192.38,
25.35,192.59,
25.37,192.81,
25.39,193.03,
25.42,193.25,
25.44,193.46,
25.46,193.68,
25.48,193.90,
25.50,194.11,
25.52,194.33,
25.54,194.55,
25.57,194.76,
25.59,194.98,
25.61,195.20,
25.63,195.41,
25.65,195.63,
25.68,195.85,
25.70,196.06,
25.72,196.28,
25.74,196.50,
25.76,196.71,
25.78,196.93,
25.81,197.15,
25.83,197.37,
25.85,197.58,
25.87,197.80,
25.89,198.02,
25.91,198.23,
25.93,198.45,
25.96,198.67,
25.98,198.88,
26.00,199.10,
26.02,199.32,
26.04,199.53,
26.07,199.75,
26.09,199.97,
26.11,200.18,
26.13,200.40,
26.15,200.62,
26.17,200.83,
26.19,201.05,
26.22,201.27,
26.24,201.48,
26.26,201.70,
26.28,201.92,
26.30,202.14,
26.33,202.35,
26.35,202.57,
26.37,202.79,
26.39,203.00,
26.41,203.22,
26.43,203.44,
26.46,203.65,
26.48,203.87,
26.50,204.09,
26.52,204.30,
26.54,204.52,
26.56,204.74,
26.58,204.95,
26.61,205.17,
26.63,205.39,
26.65,205.60,
26.67,205.82,
26.69,206.04,
26.72,206.25,
26.74,206.47,
26.76,206.69,
26.78,206.91,
26.80,207.12,
26.82,207.34,
26.84,207.56,
26.87,207.77,
26.89,207.99,
26.91,208.20,
26.93,208.42,
26.95,208.64,
26.98,208.85,
27.00,209.07,
27.02,209.29,
27.04,209.51,
27.06,209.72,
27.08,209.94,
27.11,210.16,
27.13,210.37,
27.15,210.59,
27.17,210.81,
27.19,211.02,
27.21,211.24,
27.23,211.46,
27.26,211.68,
27.28,211.89,
27.30,212.11,
27.32,212.32,
27.34,212.54,
27.37,212.76,
27.39,212.97,
27.41,213.19,
27.43,213.41,
27.45,213.63,
27.47,213.84,
27.49,214.06,
27.52,214.27,
27.54,214.49,
27.56,214.71,
27.58,214.92,
27.60,215.14,
27.63,215.36,
27.65,215.57,
27.67,215.79,
27.69,216.01,
27.71,216.22,
27.73,216.44,
27.76,216.66,
27.78,216.88,
27.80,217.09,
27.82,217.31,
27.84,217.53,
27.86,217.74,
27.88,217.96,
27.91,218.18,
27.93,218.39,
27.95,218.61,
27.97,218.83,
27.99,219.04,
28.02,219.26,
28.04,219.48,
28.06,219.70,
28.08,219.91,
28.10,220.13,
28.12,220.35,
28.14,220.56,
28.17,220.78,
28.19,221.00,
28.21,221.21,
28.23,221.43,
28.25,221.65,
28.28,221.86,
28.30,222.08,
28.32,222.30,
28.34,222.51,
28.36,222.73,
28.38,222.95,
28.41,223.16,
28.43,223.38,
28.45,223.60,
28.47,223.81,
28.49,224.03,
28.51,224.25,
28.53,224.46,
28.56,224.68,
28.58,224.90,
28.60,225.11,
28.62,225.33,
28.64,225.55,
28.67,225.77,
28.69,225.98,
28.71,226.20,
28.73,226.42,
28.75,226.63,
28.77,226.85,
28.79,227.07,
28.82,227.28,
28.84,227.50,
28.86,227.72,
28.88,227.93,
28.90,228.15,
28.93,228.37,
28.95,228.58,
28.97,228.80,
28.99,229.02,
29.01,229.23,
29.03,229.45,
29.06,229.67,
29.08,229.88,
29.10,230.10,
29.12,230.32,
29.14,230.53,
29.16,230.75,
29.18,230.97,
29.21,231.18,
29.23,231.40,
29.25,231.62,
29.27,231.84,
29.29,232.05,
29.32,232.27,
29.34,232.49,
29.36,232.70,
29.38,232.92,
29.40,233.14,
29.42,233.36,
29.44,233.57,
29.47,233.79,
29.49,234.00,
29.51,234.22,
29.53,234.44,
29.55,234.65,
29.58,234.87,
29.60,235.09,
29.62,235.30,
29.64,235.52,
29.66,235.74,
29.68,235.95,
29.71,236.17,
29.73,236.39,
29.75,236.60,
29.77,236.82,
29.79,237.04,
29.81,237.25,
29.83,237.47,
29.86,237.69,
29.88,237.90,
29.90,238.12,
29.92,238.34,
29.94,238.56,
29.97,238.77,
29.99,238.99,
30.01,239.21,
30.03,239.42,
30.05,239.64,
30.07,239.86,
30.09,240.07,
30.12,240.29,
30.14,240.51,
30.16,240.72,
30.18,240.94,
30.20,241.16,
30.23,241.37,
30.25,241.59,
30.27,241.81,
30.29,242.02,
30.31,242.24,
30.33,242.46,
30.36,242.67,
30.38,242.89,
30.40,243.11,
30.42,243.32,
30.44,243.54,
30.46,243.76,
30.48,243.97,
30.51,244.19,
30.53,244.41,
30.55,244.62,
30.57,244.84,
30.59,245.06,
30.62,245.28,
30.64,245.49,
30.66,245.71,
30.68,245.93,
30.70,246.14,
30.72,246.36,
30.74,246.58,
30.77,246.79,
30.79,247.01,
30.81,247.23,
30.83,247.44,
30.85,247.66,
30.88,247.88,
30.90,248.09,
30.92,248.31,
30.94,248.53,
30.96,248.74,
30.98,248.96,
30.99,,

[step]
Ramp 10.00 °C/min to -60.00 °C
Time,Temperature,Heat Flow (Normalized)
min,°C,W/g
32.99,250.17,
33.02,250.17,
33.04,250.16,
33.06,250.14,
33.08,250.08,
33.10,249.99,
33.12,249.87,
33.14,249.71,
33.17,249.53,
33.19,249.33,
33.21,249.13,
33.23,248.92,
33.25,248.71,
33.28,248.49,
33.30,248.28,
33.32,248.06,
33.34,247.85,
33.36,247.63,
33.38,247.42,
33.41,247.20,
33.43,246.99,
33.45,246.77,
33.47,246.56,
33.49,246.34,
33.51,246.13,
33.53,245.91,
33.56,245.70,
33.58,245.48,
33.60,245.27,
33.62,245.05,
33.64,244.84,
33.67,244.62,
33.69,244.41,
33.71,244.19,
33.73,243.98,
33.75,243.76,
33.77,243.55,
33.79,243.33,
33.82,243.11,
33.84,242.90,
33.86,242.68,
33.88,242.47,
33.90,242.25,
33.93,242.03,
33.95,241.82,
33.97,241.60,
33.99,241.39,
34.01,241.17,
34.03,240.95,
34.06,240.74,
34.08,240.52,
34.10,240.31,
34.12,240.09,
34.14,239.88,
34.16,239.66,
34.19,239.44,
34.21,239.23,
34.23,239.01,
34.25,238.79,
34.27,238.58,
34.29,238.36,
34.31,238.15,
34.34,237.93,
34.36,237.71,
34.38,237.50,
34.40,237.28,
34.42,237.07,
34.44,236.85,
34.47,236.63,
34.49,236.42,
34.51,236.20,
34.53,235.98,
34.55,235.77,
34.58,235.55,
34.60,235.34,
34.62,235.12,
34.64,234.90,
34.66,234.69,
34.68,234.47,
34.71,234.25,
34.73,234.04,
34.75,233.82,
34.77,233.60,
34.79,233.39,
34.81,233.17,
34.84,232.95,
34.86,232.74,
34.88,232.52,
34.90,232.30,
34.92,232.09,
34.94,231.87,
34.96,231.65,
34.99,231.44,
35.01,231.22,
35.03,231.01,
35.05,230.79,
35.07,230.57,
35.09,230.36,
35.12,230.14,
35.14,229.92,
35.16,229.71,
35.18,229.49,
35.20,229.27,
35.23,229.06,
35.25,228.84,
35.27,228.62,
35.29,228.41,
35.31,228.19,
35.33,227.97,
35.36,227.76,
35.38,227.54,
35.40,227.32,
35.42,227.11,
35.44,226.89,
35.46,226.67,
35.49,226.46,
35.51,226.24,
35.53,226.03,
35.55,225.81,
35.57,225.59,
35.59,225.38,
35.61,225.16,
35.64,224.94,
35.66,224.73,
35.68,224.51,
35.70,224.29,
35.72,224.08,
35.74,223.86,
35.77,223.64,
35.79,223.43,
35.81,223.21,
35.83,222.99,
35.85,222.78,
35.88,222.56,
35.90,222.34,
35.92,222.13,
35.94,221.91,
35.96,221.69,
35.98,221.48,
36.01,221.26,
36.03,221.04,
36.05,220.83,
36.07,220.61,
36.09,220.40,
36.11,220.18,
36.14,219.96,
36.16,219.74,
36.18,219.53,
36.20,219.31,
36.22,219.09,
36.24,218.88,
36.26,218.66,
36.29,218.44,
36.31,218.23,
36.33,218.01,
36.35,217.80,
36.37,217.58,
36.39,217.36,
36.42,217.15,
36.44,216.93,
36.46,216.71,
36.48,216.50,
36.50,216.28,
36.53,216.06,
36.55,215.85,
36.57,215.63,
36.59,215.41,
36.61,215.20,
36.63,214.98,
36.66,214.76,
36.68,214.55,
36.70,214.33,
36.72,214.11,
36.74,213.90,
36.76,213.68,
36.79,213.47,
36.81,213.25,
36.83,213.03,
36.85,212.82,
36.87,212.60,
36.89,212.38,
36.91,212.17,
36.94,211.95,
36.96,211.73,
36.98,211.52,
37.00,211.30,
37.02,211.08,
37.04,210.87,
37.07,210.65,
37.09,210.43,
37.11,210.22,
37.13,210.00,
37.15,209.78,
37.18,209.56,
37.20,209.35,
37.22,209.13,
37.24,208.91,
37.26,208.70,
37.28,208.48,
37.31,208.26,
37.33,208.05,
37.35,207.83,
37.37,207.61,
37.39,207.40,
37.41,207.18,
37.44,206.97,
37.46,206.75,
37.48,206.53,
37.50,206.32,
37.52,206.10,
37.54,205.88,
37.56,205.67,
37.59,205.45,
37.61,205.23,
37.63,205.02,
37.65,204.80,
37.67,204.58,
37.69,204.37,
37.72,204.15,
37.74,203.94,
37.76,203.72,
37.78,203.50,
37.80,203.28,
37.83,203.07,
37.85,202.85,
37.87,202.63,
37.89,202.42,
37.91,202.20,
37.93,201.98,
37.96,201.77,
37.98,201.55,
38.00,201.33,
38.02,201.12,
38.04,200.90,
38.06,200.69,
38.09,200.47,
38.11,200.25,
38.13,200.04,
38.15,199.82,
38.17,199.60,
38.19,199.39,
38.21,199.17,
38.24,198.95,
38.26,198.73,
38.28,198.52,
38.30,198.30,
38.32,198.08,
38.34,197.87,
38.37,197.65,
38.39,197.43,
38.41,197.22,
38.43,197.00,
38.45,196.79,
38.48,196.57,
38.50,196.35,
38.52,196.14,
38.54,195.92,
38.56,195.70,
38.58,195.49,
38.61,195.27,
38.63,195.05,
38.65,194.84,
38.67,194.62,
38.69,194.40,
38.71,194.19,
38.74,193.97,
38.76,193.76,
38.78,193.54,
38.80,193.32,
38.82,193.11,
38.84,192.89,
38.86,192.67,
38.89,192.46,
38.91,192.24,
38.93,192.02,
38.95,191.80,
38.97,191.59,
38.99,191.37,
39.02,191.16,
39.04,190.94,
39.06,190.72,
39.08,190.51,
39.10,190.29,
39.13,190.07,
39.15,189.85,
39.17,189.64,
39.19,189.42,
39.21,189.21,
39.23,188.99,
39.26,188.77,
39.28,188.56,
39.30,188.34,
39.32,188.12,
39.34,187.91,
39.36,187.69,
39.39,187.47,
39.41,187.26,
39.43,187.04,
39.45,186.82,
39.47,186.61,
39.49,186.39,
39.51,186.17,
39.54,185.96,
39.56,185.74,
39.58,185.52,
39.60,185.31,
39.62,185.09,
39.64,184.87,
39.67,184.66,
39.69,184.44,
39.71,184.22,
39.73,184.01,
39.75,183.79,
39.78,183.57,
39.80,183.36,
39.82,183.14,
39.84,182.92,
39.86,182.71,
39.88,182.49,
39.91,182.27,
39.93,182.06,
39.95,181.84,
39.97,181.62,
39.99,181.41,
40.01,181.19,
40.04,180.98,
40.06,180.76,
40.08,180.54,
40.10,180.32,
40.12,180.11,
40.14,179.89,
40.16,179.67,
40.19,179.46,
40.21,179.24,
40.23,179.02,
40.25,178.81,
40.27,178.59,
40.29,178.37,
40.32,178.16,
40.34,177.94,
40.36,177.73,
40.38,177.51,
40.40,177.29,
40.43,177.07,
40.45,176.86,
40.47,176.64,
40.49,176.42,
40.51,176.21,
40.53,175.99,
40.56,175.77,
40.58,175.56,
40.60,175.34,
40.62,175.12,
40.64,174.91,
40.66,174.69,
40.69,174.48,
40.71,174.26,
40.73,174.04,
40.75,173.83,
40.77,173.61,
40.79,173.39,
40.81,173.18,
40.84,172.96,
40.86,172.74,
40.88,172.52,
40.90,172.31,
40.92,172.09,
40.94,171.88,
40.97,171.66,
40.99,171.44,
41.01,171.23,
41.03,171.01,
41.05,170.79,
41.08,170.58,
41.10,170.36,
41.12,170.14,
41.14,169.93,
41.16,169.71,
41.18,169.49,
41.21,169.28,
41.23,169.06,
41.25,168.84,
41.27,168.63,
41.29,168.41,
41.31,168.19,
41.34,167.98,
41.36,167.76,
41.38,167.54,
41.40,167.33,
41.42,167.11,
41.44,166.89,
41.46,166.68,
41.49,166.46,
41.51,166.24,
41.53,166.03,
41.55,165.81,
41.57,165.59,
41.59,165.38,
41.62,165.16,
41.64,164.94,
41.66,164.73,
41.68,164.51,
41.70,164.30,
41.73,164.08,
41.75,163.86,
41.77,163.65,
41.79,163.43,
41.81,163.21,
41.83,163.00,
41.86,162.78,
41.88,162.56,
41.90,162.35,
41.92,162.13,
41.94,161.91,
41.96,161.70,
41.99,161.48,
42.01,161.26,
42.03,161.05,
42.05,160.83,
42.07,160.61,
42.09,160.40,
42.11,160.18,
42.14,159.96,
42.16,159.75,
42.18,159.53,
42.20,159.31,
42.22,159.10,
42.24,158.88,
42.27,158.66,
42.29,158.45,
42.31,158.23,
42.33,158.01,
42.35,157.80,
42.38,157.58,
42.40,157.36,
42.42,157.15,
42.44,156.93,
42.46,156.71,
42.48,156.50,
42.51,156.28,
42.53,156.06,
42.55,155.85,
42.57,155.63,
42.59,155.41,
42.61,155.20,
42.64,154.98,
42.66,154.76,
42.68,154.55,
42.70,154.33,
42.72,154.11,
42.74,153.90,
42.76,153.68,
42.79,153.46,
42.81,153.25,
42.83,153.03,
42.85,152.81,
42.87,152.60,
42.89,152.38,
42.92,152.16,
42.94,151.95,
42.96,151.73,
42.98,151.52,
43.00,151.30,
43.03,151.08,
43.05,150.87,
43.07,150.65,
43.09,150.43,
43.11,150.22,
43.13,150.00,
43.16,149.78,
43.18,149.57,
43.20,149.35,
43.22,149.13,
43.24,148.92,
43.26,148.70,
43.29,148.48,
43.31,148.26,
43.33,148.05,
43.35,147.83,
43.37,147.61,
43.39,147.40,
43.41,147.18,
43.44,146.96,
43.46,146.75,
43.48,146.53,
43.50,146.31,
43.52,146.10,
43.54,145.88,
43.57,145.67,
43.59,145.45,
43.61,145.23,
43.63,145.02,
43.65,144.80,
43.68,144.58,
43.70,144.37,
43.72,144.15,
43.74,143.93,
43.76,143.72,
43.78,143.50,
43.81,143.28,
43.83,143.07,
43.85,142.85,
43.87,142.63,
43.89,142.42,
43.91,142.20,
43.94,141.98,
43.96,141.77,
43.98,141.55,
44.00,141.33,
44.02,141.12,
44.04,140.90,
44.06,140.68,
44.09,140.47,
44.11,140.25,
44.13,140.03,
44.15,139.82,
44.17,139.60,
44.19,139.39,
44.22,139.17,
44.24,138.95,
44.26,138.74,
44.28,138.52,
44.30,138.30,
44.33,138.08,
44.35,137.87,
44.37,137.65,
44.39,137.43,
44.41,137.22,
44.43,137.00,
44.46,136.78,
44.48,136.57,
44.50,136.35,
44.52,136.13,
44.54,135.92,
44.56,135.70,
44.59,135.48,
44.61,135.27,
44.63,135.05,
44.65,134.83,
44.67,134.62,
44.69,134.40,
44.71,134.18,
44.74,133.97,
44.76,133.75,
44.78,133.53,
44.80,133.32,
44.82,133.10,
44.84,132.88,
44.87,132.67,
44.89,132.45,
44.91,132.23,
44.93,132.02,
44.95,131.80,
44.98,131.58,
45.00,131.37,
45.02,131.15,
45.04,130.94,
45.06,130.72,
45.08,130.50,
45.11,130.29,
45.13,130.07,
45.15,129.85,
45.17,129.64,
45.19,129.42,
45.21,129.20,
45.24,128.99,
45.26,128.77,
45.28,128.55,
45.30,128.34,
45.32,128.12,
45.34,127.90,
45.36,127.69,
45.39,127.47,
45.41,127.25,
45.43,127.04,
45.45,126.82,
45.47,126.60,
45.49,126.39,
45.52,126.17,
45.54,125.95,
45.56,125.74,
45.58,125.52,
45.60,125.30,
45.63,125.09,
45.65,124.87,
45.67,124.65,
45.69,124.44,
45.71,124.22,
45.73,124.00,
45.76,123.79,
45.78,123.57,
45.80,123.35,
45.82,123.14,
45.84,122.92,
45.86,122.70,
45.89,122.49,
45.91,122.27,
45.93,122.05,
45.95,121.84,
45.97,121.62,
45.99,121.40,
46.01,121.19,
46.04,120.97,
46.06,120.75,
46.08,120.54,
46.10,120.32,
46.12,120.10,
46.14,119.89,
46.17,119.67,
46.19,119.45,
46.21,119.24,
46.23,119.02,
46.25,118.80,
46.28,118.59,
46.30,118.37,
46.32,118.16,
46.34,117.94,
46.36,117.72,
46.38,117.50,
46.41,117.29,
46.43,117.07,
46.45,116.85,
46.47,116.64,
46.49,116.42,
46.51,116.20,
46.54,115.99,
46.56,115.77,
46.58,115.56,
46.60,115.34,
46.62,115.12,
46.64,114.91,
46.66,114.69,
46.69,114.47,
46.71,114.26,
46.73,114.04,
46.75,113.82,
46.77,113.61,
46.79,113.39,
46.82,113.17,
46.84,112.96,
46.86,112.74,
46.88,112.52,
46.90,112.31,
46.93,112.09,
46.95,111.87,
46.97,111.66,
46.99,111.44,
47.01,111.22,
47.03,111.01,
47.06,110.79,
47.08,110.57,
47.10,110.36,
47.12,110.14,
47.14,109.92,
47.16,109.71,
47.19,109.49,
47.21,109.27,
47.23,109.06,
47.25,108.84,
47.27,108.62,
47.29,108.41,
47.31,108.19,
47.34,107.97,
47.36,107.76,
47.38,107.54,
47.40,107.32,
47.42,107.11,
47.44,106.89,
47.47,106.67,
47.49,106.46,
47.51,106.24,
47.53,106.02,
47.55,105.81,
47.58,105.59,
47.60,105.37,
47.62,105.16,
47.64,104.94,
47.66,104.72,
47.68,104.51,
47.71,104.29,
47.73,104.08,
47.75,103.86,
47.77,103.64,
47.79,103.42,
47.81,103.21,
47.84,102.99,
47.86,102.77,
47.88,102.56,
47.90,102.34,
47.92,102.13,
47.94,101.91,
47.96,101.69,
47.99,101.47,
48.01,101.26,
48.03,101.04,
48.05,100.82,
48.07,100.61,
48.09,100.39,
48.12,100.17,
48.14,99.96,
48.16,99.74,
48.18,99.52,
48.20,99.31,
48.23,99.09,
48.25,98.88,
48.27,98.66,
48.29,98.44,
48.31,98.22,
48.33,98.01,
48.36,97.79,
48.38,97.58,
48.40,97.36,
48.42,97.14,
48.44,96.93,
48.46,96.71,
48.49,96.49,
48.51,96.28,
48.53,96.06,
48.55,95.84,
48.57,95.63,
48.59,95.41,
48.61,95.19,
48.64,94.98,
48.66,94.76,
48.68,94.54,
48.70,94.33,
48.72,94.11,
48.74,93.89,
48.77,93.68,
48.79,93.46,
48.81,93.24,
48.83,93.03,
48.85,92.81,
48.88,92.59,
48.90,92.38,
48.92,92.16,
48.94,91.94,
48.96,91.73,
48.98,91.51,
49.01,91.29,
49.03,91.08,
49.05,90.86,
49.07,90.64,
49.09,90.43,
49.11,90.21,
49.14,89.99,
49.16,89.78,
49.18,89.56,
49.20,89.34,
49.22,89.13,
49.24,88.91,
49.26,88.69,
49.29,88.48,
49.31,88.26,
49.33,88.04,
49.35,87.83,
49.37,87.61,
49.39,87.40,
49.42,87.18,
49.44,86.96,
49.46,86.75,
49.48,86.53,
49.50,86.31,
49.53,86.10,
49.55,85.88,
49.57,85.66,
49.59,85.45,
49.61,85.23,
49.63,85.01,
49.66,84.80,
49.68,84.58,
49.70,84.36,
49.72,84.14,
49.74,83.93,
49.76,83.71,
49.79,83.49,
49.81,83.28,
49.83,83.06,
49.85,82.85,
49.87,82.63,
49.89,82.41,
49.91,82.20,
49.94,81.98,
49.96,81.76,
49.98,81.55,
50.00,81.33,
50.02,81.11,
50.04,80.90,
50.07,80.68,
50.09,80.46,
50.11,80.25,
50.13,80.03,
50.15,79.81,
50.18,79.60,
50.20,79.38,
50.22,79.16,
50.24,78.95,
50.26,78.73,
50.28,78.51,
50.31,78.30,
50.33,78.08,
50.35,77.86,
50.37,77.65,
50.39,77.43,
50.41,77.21,
50.44,77.00,
50.46,76.78,
50.48,76.56,
50.50,76.35,
50.52,76.13,
50.54,75.91,
50.56,75.70,
50.59,75.48,
50.61,75.27,
50.63,75.05,
50.65,74.83,
50.67,74.62,
50.69,74.40,
50.72,74.18,
50.74,73.97,
50.76,73.75,
50.78,73.53,
50.80,73.31,
50.83,73.10,
50.85,72.88,
50.87,72.67,
50.89,72.45,
50.91,72.23,
50.93,72.02,
50.96,71.80,
50.98,71.58,
51.00,71.37,
51.02,71.15,
51.04,70.93,
51.06,70.72,
51.09,70.50,
51.11,70.28,
51.13,70.07,
51.15,69.85,
51.17,69.63,
51.19,69.42,
51.21,69.20,
51.24,68.98,
51.26,68.77,
51.28,68.55,
51.30,68.33,
51.32,68.12,
51.34,67.90,
51.37,67.68,
51.39,67.47,
51.41,67.25,
51.43,67.03,
51.45,66.82,
51.48,66.60,
51.50,66.38,
51.52,66.17,
51.54,65.95,
51.56,65.73,
51.58,65.52,
51.61,65.30,
51.63,65.08,
51.65,64.87,
51.67,64.65,
51.69,64.44,
51.71,64.22,
51.74,64.00,
51.76,63.78,
51.78,63.57,
51.80,63.35,
51.82,63.13,
51.84,62.92,
51.86,62.70,
51.89,62.48,
51.91,62.27,
51.93,62.05,
51.95,61.83,
51.97,61.62,
51.99,61.40,
52.02,61.18,
52.04,60.97,
52.06,60.75,
52.08,60.54,
52.10,60.32,
52.13,60.10,
52.15,59.89,
52.17,59.67,
52.19,59.45,
52.21,59.24,
52.23,59.02,
52.26,58.80,
52.28,58.59,
52.30,58.37,
52.32,58.15,
52.34,57.93,
52.36,57.72,
52.39,57.50,
52.41,57.29,
52.43,57.07,
52.45,56.85,
52.47,56.64,
52.49,56.42,
52.51,56.20,
52.54,55.99,
52.56,55.77,
52.58,55.55,
52.60,55.34,
52.62,55.12,
52.64,54.90,
52.67,54.69,
52.69,54.47,
52.71,54.25,
52.73,54.04,
52.75,53.82,
52.78,53.60,
52.80,53.39,
52.82,53.17,
52.84,52.95,
52.86,52.74,
52.88,52.52,
52.91,52.30,
52.93,52.09,
52.95,51.87,
52.97,51.65,
52.99,51.44,
53.01,51.22,
53.04,51.00,
53.06,50.79,
53.08,50.57,
53.10,50.35,
53.12,50.14,
53.14,49.92,
53.16,49.71,
53.19,49.49,
53.21,49.27,
53.23,49.06,
53.25,48.84,
53.27,48.62,
53.29,48.40,
53.32,48.19,
53.34,47.97,
53.36,47.75,
53.38,47.54,
53.40,47.32,
53.43,47.11,
53.45,46.89,
53.47,46.67,
53.49,46.46,
53.51,46.24,
53.53,46.02,
53.56,45.81,
53.58,45.59,
53.60,45.37,
53.62,45.16,
53.64,44.94,
53.66,44.72,
53.69,44.51,
53.71,44.29,
53.73,44.07,
53.75,43.86,
53.77,43.64,
53.79,43.42,
53.81,43.21,
53.84,42.99,
53.86,42.77,
53.88,42.56,
53.90,42.34,
53.92,42.12,
53.94,41.91,
53.97,41.69,
53.99,41.47,
54.01,41.26,
54.03,41.04,
54.05,40.82,
54.08,40.61,
54.10,40.39,
54.12,40.17,
54.14,39.96,
54.16,39.74,
54.18,39.52,
54.21,39.31,
54.23,39.09,
54.25,38.87,
54.27,38.66,
54.29,38.44,
54.31,38.22,
54.34,38.01,
54.36,37.79,
54.38,37.57,
54.40,37.36,
54.42,37.14,
54.44,36.92,
54.46,36.71,
54.49,36.49,
54.51,36.27,
54.53,36.06,
54.55,35.84,
54.57,35.62,
54.59,35.41,
54.62,35.19,
54.64,34.98,
54.66,34.76,
54.68,34.54,
54.70,34.33,
54.73,34.11,
54.75,33.89,
54.77,33.68,
54.79,33.46,
54.81,33.24,
54.83,33.03,
54.86,32.81,
54.88,32.59,
54.90,32.38,
54.92,32.16,
54.94,31.94,
54.96,31.73,
54.99,31.51,
55.01,31.29,
55.03,31.07,
55.05,30.86,
55.07,30.64,
55.09,30.43,
55.11,30.21,
55.14,29.99,
55.16,29.78,
55.18,29.56,
55.20,29.34,
55.22,29.13,
55.24,28.91,
55.27,28.69,
55.29,28.48,
55.31,28.26,
55.33,28.04,
55.35,27.83,
55.38,27.61,
55.40,27.40,
55.42,27.18,
55.44,26.96,
55.46,26.75,
55.48,26.53,
55.51,26.31,
55.53,26.10,
55.55,25.88,
55.57,25.66,
55.59,25.45,
55.61,25.23,
55.64,25.01,
55.66,24.80,
55.68,24.58,
55.70,24.36,
55.72,24.15,
55.74,23.93,
55.76,23.71,
55.79,23.50,
55.81,23.28,
55.83,23.06,
55.85,22.85,
55.87,22.63,
55.89,22.41,
55.92,22.20,
55.94,21.98,
55.96,21.76,
55.98,21.54,
56.00,21.33,
56.03,21.11,
56.05,20.89,
56.07,20.68,
56.09,20.46,
56.11,20.25,
56.13,20.03,
56.16,19.81,
56.18,19.60,
56.20,19.38,
56.22,19.16,
56.24,18.95,
56.26,18.73,
56.29,18.51,
[...]
143.09,49.76,,-0.040
143.11,49.98,,-0.040
143.13,50.20,,-0.040
143.15,50.41,,-0.040
143.18,50.63,,-0.040
143.20,50.85,,-0.040
143.22,51.07,,-0.040
143.24,51.28,,-0.041
143.26,51.50,,-0.041
143.28,51.72,,-0.041
143.31,51.93,,-0.041
143.33,52.15,,-0.041
143.35,52.37,,-0.041
143.37,52.58,,-0.041
143.39,52.80,,-0.042
143.42,53.02,,-0.042
143.44,53.23,,-0.042
143.46,53.45,,-0.042
143.48,53.67,,-0.042
143.50,53.88,,-0.042
143.52,54.10,,-0.042
143.55,54.32,,-0.043
143.57,54.53,,-0.043
143.59,54.75,,-0.043
143.61,54.97,,-0.043
143.63,55.19,,-0.043
143.65,55.40,,-0.043
143.68,55.62,,-0.043
143.70,55.84,,-0.043
143.72,56.05,,-0.043
143.74,56.27,,-0.044
143.76,56.49,,-0.044
143.78,56.70,,-0.044
143.80,56.92,,-0.044
143.83,57.14,,-0.044
143.85,57.35,,-0.044
143.87,57.57,,-0.044
143.89,57.79,,-0.044
143.91,58.00,,-0.045
143.93,58.22,,-0.045
143.96,58.44,,-0.045
143.98,58.66,,-0.045
144.00,58.87,,-0.045
144.02,59.09,,-0.045
144.04,59.31,,-0.045
144.07,59.52,,-0.045
144.09,59.74,,-0.045
144.11,59.96,,-0.045
144.13,60.17,,-0.045
144.15,60.39,,-0.045
144.17,60.61,,-0.046
144.20,60.82,,-0.046
144.22,61.04,,-0.046
144.24,61.26,,-0.046
144.26,61.48,,-0.046
144.28,61.69,,-0.046
144.30,61.91,,-0.046
144.33,62.13,,-0.046
144.35,62.34,,-0.047
144.37,62.56,,-0.047
144.39,62.78,,-0.047
144.41,62.99,,-0.047
144.43,63.21,,-0.047
144.45,63.43,,-0.047
144.48,63.64,,-0.047
144.50,63.86,,-0.047
144.52,64.08,,-0.048
144.54,64.30,,-0.048
144.56,64.51,,-0.048
144.58,64.73,,-0.048
144.61,64.95,,-0.048
144.63,65.16,,-0.049
144.65,65.38,,-0.049
144.67,65.60,,-0.049
144.69,65.82,,-0.049
144.72,66.03,,-0.049
144.74,66.25,,-0.049
144.76,66.47,,-0.050
144.78,66.68,,-0.050
144.80,66.90,,-0.050
144.82,67.12,,-0.050
144.85,67.33,,-0.051
144.87,67.55,,-0.051
144.89,67.77,,-0.051
144.91,67.98,,-0.051
144.93,68.20,,-0.052
144.95,68.42,,-0.052
144.98,68.64,,-0.052
145.00,68.85,,-0.052
145.02,69.07,,-0.052
145.04,69.29,,-0.052
145.06,69.50,,-0.053
145.08,69.72,,-0.053
145.10,69.93,,-0.053
145.13,70.15,,-0.053
145.15,70.37,,-0.053
145.17,70.59,,-0.054
145.19,70.80,,-0.054
145.21,71.02,,-0.054
145.23,71.24,,-0.054
145.26,71.45,,-0.054
145.28,71.67,,-0.054
145.30,71.89,,-0.055
145.32,72.10,,-0.055
145.34,72.32,,-0.055
145.37,72.54,,-0.055
145.39,72.75,,-0.055
145.41,72.97,,-0.055
145.43,73.19,,-0.055
145.45,73.40,,-0.056
145.47,73.62,,-0.056
145.50,73.84,,-0.056
145.52,74.06,,-0.056
145.54,74.27,,-0.056
145.56,74.49,,-0.056
145.58,74.71,,-0.056
145.60,74.92,,-0.056
145.63,75.14,,-0.056
145.65,75.36,,-0.056
145.67,75.57,,-0.056
145.69,75.79,,-0.056
145.71,76.01,,-0.057
145.73,76.22,,-0.057
145.75,76.44,,-0.057
145.78,76.66,,-0.057
145.80,76.87,,-0.057
145.82,77.09,,-0.057
145.84,77.31,,-0.057
145.86,77.53,,-0.057
145.88,77.74,,-0.057
145.91,77.96,,-0.057
145.93,78.18,,-0.058
145.95,78.39,,-0.058
145.97,78.61,,-0.058
145.99,78.83,,-0.058
146.02,79.04,,-0.058
146.04,79.26,,-0.059
146.06,79.48,,-0.059
146.08,79.69,,-0.059
146.10,79.91,,-0.059
146.12,80.13,,-0.059
146.15,80.35,,-0.059
146.17,80.56,,-0.059
146.19,80.78,,-0.059
146.21,81.00,,-0.060
146.23,81.21,,-0.059
146.25,81.43,,-0.059
146.28,81.65,,-0.059
146.30,81.86,,-0.059
146.32,82.08,,-0.060
146.34,82.30,,-0.060
146.36,82.52,,-0.060
146.38,82.73,,-0.061
146.40,82.95,,-0.061
146.43,83.17,,-0.061
146.45,83.38,,-0.061
146.47,83.60,,-0.061
146.49,83.82,,-0.061
146.51,84.04,,-0.061
146.53,84.25,,-0.061
146.56,84.47,,-0.061
146.58,84.68,,-0.062
146.60,84.90,,-0.062
146.62,85.12,,-0.062
146.64,85.34,,-0.062
146.67,85.55,,-0.062
146.69,85.77,,-0.062
146.71,85.98,,-0.063
146.73,86.20,,-0.063
146.75,86.42,,-0.063
146.77,86.63,,-0.063
146.80,86.85,,-0.063
146.82,87.07,,-0.064
146.84,87.29,,-0.064
146.86,87.50,,-0.064
146.88,87.72,,-0.064
146.90,87.94,,-0.065
146.93,88.15,,-0.065
146.95,88.37,,-0.065
146.97,88.59,,-0.065
146.99,88.80,,-0.065
147.01,89.02,,-0.065
147.03,89.24,,-0.065
147.05,89.45,,-0.065
147.08,89.67,,-0.066
147.10,89.89,,-0.066
147.12,90.10,,-0.066
147.14,90.32,,-0.066
147.16,90.54,,-0.066
147.18,90.75,,-0.066
147.21,90.97,,-0.066
147.23,91.19,,-0.066
147.25,91.41,,-0.066
147.27,91.62,,-0.066
147.29,91.84,,-0.066
147.32,92.05,,-0.066
147.34,92.27,,-0.066
147.36,92.49,,-0.066
147.38,92.70,,-0.066
147.40,92.92,,-0.066
147.42,93.14,,-0.066
147.45,93.35,,-0.065
147.47,93.57,,-0.066
147.49,93.79,,-0.066
147.51,94.00,,-0.066
147.53,94.22,,-0.066
147.55,94.44,,-0.066
147.58,94.66,,-0.066
147.60,94.87,,-0.065
147.62,95.09,,-0.066
147.64,95.31,,-0.066
147.66,95.53,,-0.066
147.68,95.74,,-0.066
147.70,95.96,,-0.066
147.73,96.18,,-0.066
147.75,96.39,,-0.066
147.77,96.61,,-0.066
147.79,96.83,,-0.066
147.81,97.04,,-0.066
147.83,97.26,,-0.066
147.86,97.48,,-0.066
147.88,97.69,,-0.066
147.90,97.91,,-0.067
147.92,98.13,,-0.067
147.94,98.34,,-0.066
147.97,98.56,,-0.067
147.99,98.78,,-0.067
148.01,98.99,,-0.067
148.03,99.21,,-0.067
148.05,99.43,,-0.067
148.07,99.64,,-0.067
148.10,99.86,,-0.067
148.12,100.08,,-0.067
148.14,100.30,,-0.067
148.16,100.51,,-0.067
148.18,100.73,,-0.067
148.20,100.95,,-0.067
148.23,101.16,,-0.067
148.25,101.38,,-0.067
148.27,101.60,,-0.067
148.29,101.81,,-0.067
148.31,102.03,,-0.067
148.33,102.25,,-0.067
148.35,102.46,,-0.067
148.38,102.68,,-0.067
148.40,102.90,,-0.067
148.42,103.11,,-0.067
148.44,103.33,,-0.068
148.46,103.55,,-0.068
148.48,103.77,,-0.067
148.51,103.98,,-0.067
148.53,104.20,,-0.068
148.55,104.42,,-0.068
148.57,104.63,,-0.068
148.59,104.85,,-0.068
148.62,105.07,,-0.068
148.64,105.29,,-0.068
148.66,105.50,,-0.068
148.68,105.72,,-0.068
148.70,105.93,,-0.069
148.72,106.15,,-0.069
148.75,106.37,,-0.069
148.77,106.59,,-0.069
148.79,106.80,,-0.069
148.81,107.02,,-0.069
148.83,107.23,,-0.069
148.85,107.45,,-0.069
148.88,107.67,,-0.069
148.90,107.89,,-0.069
148.92,108.10,,-0.069
148.94,108.32,,-0.069
148.96,108.54,,-0.069
148.98,108.75,,-0.069
149.00,108.97,,-0.069
149.03,109.19,,-0.069
149.05,109.40,,-0.069
149.07,109.62,,-0.069
149.09,109.84,,-0.069
149.11,110.05,,-0.069
149.13,110.27,,-0.069
149.16,110.49,,-0.069
149.18,110.70,,-0.069
149.20,110.92,,-0.069
149.22,111.14,,-0.070
149.24,111.35,,-0.069
149.27,111.57,,-0.070
149.29,111.79,,-0.070
149.31,112.01,,-0.070
149.33,112.22,,-0.070
149.35,112.44,,-0.070
149.37,112.66,,-0.070
149.40,112.87,,-0.070
149.42,113.09,,-0.070
149.44,113.31,,-0.070
149.46,113.52,,-0.070
149.48,113.74,,-0.070
149.50,113.96,,-0.070
149.53,114.17,,-0.070
149.55,114.39,,-0.070
149.57,114.61,,-0.071
149.59,114.82,,-0.070
149.61,115.04,,-0.071
149.63,115.26,,-0.071
149.65,115.47,,-0.071
149.68,115.69,,-0.071
149.70,115.91,,-0.071
149.72,116.13,,-0.071
149.74,116.34,,-0.071
149.76,116.56,,-0.071
149.78,116.78,,-0.071
149.81,116.99,,-0.071
149.83,117.21,,-0.071
149.85,117.43,,-0.071
149.87,117.64,,-0.071
149.89,117.86,,-0.071
149.92,118.08,,-0.072
149.94,118.29,,-0.072
149.96,118.51,,-0.072
149.98,118.73,,-0.072
150.00,118.95,,-0.072
150.02,119.16,,-0.072
150.05,119.38,,-0.072
150.07,119.59,,-0.072
150.09,119.81,,-0.072
150.11,120.03,,-0.072
150.13,120.24,,-0.072
150.15,120.46,,-0.072
150.18,120.68,,-0.072
150.20,120.90,,-0.073
150.22,121.11,,-0.072
150.24,121.33,,-0.073
150.26,121.55,,-0.073
150.28,121.76,,-0.073
150.30,121.98,,-0.073
150.33,122.20,,-0.073
150.35,122.41,,-0.073
150.37,122.63,,-0.073
150.39,122.85,,-0.073
150.41,123.07,,-0.073
150.43,123.28,,-0.073
150.46,123.50,,-0.073
150.48,123.71,,-0.074
150.50,123.93,,-0.074
150.52,124.15,,-0.074
150.54,124.37,,-0.074
150.57,124.58,,-0.074
150.59,124.80,,-0.074
150.61,125.02,,-0.075
150.63,125.24,,-0.075
150.65,125.45,,-0.075
150.67,125.67,,-0.075
150.70,125.89,,-0.075
150.72,126.10,,-0.075
150.74,126.32,,-0.076
150.76,126.54,,-0.076
150.78,126.75,,-0.076
150.80,126.97,,-0.076
150.83,127.19,,-0.076
150.85,127.40,,-0.076
150.87,127.62,,-0.076
150.89,127.84,,-0.076
150.91,128.05,,-0.077
150.93,128.27,,-0.077
150.95,128.49,,-0.077
150.98,128.70,,-0.077
151.00,128.92,,-0.077
151.02,129.14,,-0.078
151.04,129.35,,-0.078
151.06,129.57,,-0.078
151.08,129.79,,-0.078
151.11,130.00,,-0.078
151.13,130.22,,-0.078
151.15,130.44,,-0.078
151.17,130.66,,-0.078
151.19,130.87,,-0.078
151.22,131.09,,-0.078
151.24,131.30,,-0.078
151.26,131.52,,-0.078
151.28,131.74,,-0.078
151.30,131.95,,-0.078
151.32,132.17,,-0.079
151.35,132.39,,-0.079
151.37,132.60,,-0.079
151.39,132.82,,-0.079
151.41,133.04,,-0.079
151.43,133.25,,-0.079
151.45,133.47,,-0.079
151.48,133.69,,-0.079
151.50,133.91,,-0.079
151.52,134.12,,-0.079
151.54,134.34,,-0.079
151.56,134.56,,-0.079
151.58,134.77,,-0.079
151.60,134.99,,-0.078
151.63,135.21,,-0.079
151.65,135.43,,-0.079
151.67,135.64,,-0.079
151.69,135.86,,-0.079
151.71,136.08,,-0.079
151.73,136.29,,-0.079
151.76,136.51,,-0.079
151.78,136.73,,-0.079
151.80,136.94,,-0.079
151.82,137.16,,-0.079
151.84,137.38,,-0.079
151.87,137.59,,-0.079
151.89,137.81,,-0.080
151.91,138.03,,-0.080
151.93,138.24,,-0.080
151.95,138.46,,-0.080
151.97,138.68,,-0.081
152.00,138.89,,-0.081
152.02,139.11,,-0.081
152.04,139.33,,-0.081
152.06,139.55,,-0.081
152.08,139.76,,-0.081
152.10,139.98,,-0.081
152.13,140.20,,-0.081
152.15,140.41,,-0.081
152.17,140.63,,-0.081
152.19,140.85,,-0.082
152.21,141.06,,-0.082
152.23,141.28,,-0.082
152.25,141.49,,-0.082
152.28,141.71,,-0.082
152.30,141.93,,-0.082
152.32,142.15,,-0.083
152.34,142.36,,-0.083
152.36,142.58,,-0.083
152.38,142.80,,-0.083
152.41,143.01,,-0.083
152.43,143.23,,-0.084
152.45,143.45,,-0.084
152.47,143.67,,-0.084
152.49,143.88,,-0.084
152.52,144.10,,-0.084
152.54,144.31,,-0.085
152.56,144.53,,-0.085
152.58,144.75,,-0.085
152.60,144.97,,-0.085
152.62,145.18,,-0.085
152.65,145.40,,-0.085
152.67,145.62,,-0.085
152.69,145.83,,-0.085
152.71,146.05,,-0.086
152.73,146.27,,-0.086
152.75,146.48,,-0.086
152.78,146.70,,-0.086
152.80,146.92,,-0.086
152.82,147.13,,-0.086
152.84,147.35,,-0.086
152.86,147.57,,-0.086
152.88,147.79,,-0.086
152.90,148.00,,-0.086
152.93,148.22,,-0.086
152.95,148.43,,-0.086
152.97,148.65,,-0.086
152.99,148.87,,-0.086
153.01,149.09,,-0.086
153.03,149.30,,-0.086
153.06,149.52,,-0.086
153.08,149.74,,-0.086
153.10,149.95,,-0.086
153.12,150.17,,-0.086
153.14,150.38,,-0.086
153.17,150.60,,-0.086
153.19,150.82,,-0.086
153.21,151.03,,-0.086
153.23,151.25,,-0.086
153.25,151.47,,-0.086
153.27,151.69,,-0.086
153.30,151.90,,-0.086
153.32,152.12,,-0.086
153.34,152.34,,-0.087
153.36,152.55,,-0.087
153.38,152.77,,-0.087
153.40,152.99,,-0.087
153.43,153.20,,-0.087
153.45,153.42,,-0.087
153.47,153.64,,-0.087
153.49,153.85,,-0.087
153.51,154.07,,-0.087
153.53,154.29,,-0.087
153.55,154.50,,-0.087
153.58,154.72,,-0.087
153.60,154.94,,-0.087
153.62,155.15,,-0.088
153.64,155.37,,-0.088
153.66,155.59,,-0.088
153.68,155.80,,-0.088
153.71,156.02,,-0.088
153.73,156.24,,-0.088
153.75,156.46,,-0.088
153.77,156.67,,-0.088
153.79,156.89,,-0.088
153.82,157.11,,-0.088
153.84,157.32,,-0.088
153.86,157.54,,-0.089
153.88,157.76,,-0.089
153.90,157.97,,-0.089
153.92,158.19,,-0.089
153.95,158.41,,-0.089
153.97,158.63,,-0.089
153.99,158.84,,-0.089
154.01,159.06,,-0.089
154.03,159.28,,-0.089
154.05,159.49,,-0.090
154.08,159.71,,-0.090
154.10,159.93,,-0.090
154.12,160.14,,-0.090
154.14,160.36,,-0.090
154.16,160.58,,-0.090
154.18,160.79,,-0.090
154.20,161.01,,-0.090
154.23,161.23,,-0.091
154.25,161.44,,-0.091
154.27,161.66,,-0.091
154.29,161.88,,-0.091
154.31,162.10,,-0.091
154.33,162.31,,-0.091
154.36,162.53,,-0.091
154.38,162.75,,-0.091
154.40,162.96,,-0.091
154.42,163.18,,-0.091
154.44,163.40,,-0.091
154.47,163.61,,-0.091
154.49,163.83,,-0.091
154.51,164.05,,-0.091
154.53,164.26,,-0.092
154.55,164.48,,-0.092
154.57,164.69,,-0.092
154.60,164.91,,-0.092
154.62,165.13,,-0.092
154.64,165.34,,-0.092
154.66,165.56,,-0.092
154.68,165.78,,-0.092
154.70,166.00,,-0.093
154.73,166.21,,-0.093
154.75,166.43,,-0.093
154.77,166.65,,-0.093
154.79,166.87,,-0.093
154.81,167.08,,-0.092
154.83,167.30,,-0.092
154.85,167.51,,-0.092
154.88,167.73,,-0.092
154.90,167.95,,-0.092
154.92,168.16,,-0.092
154.94,168.38,,-0.092
154.96,168.60,,-0.092
154.98,168.81,,-0.092
155.01,169.03,,-0.092
155.03,169.25,,-0.092
155.05,169.46,,-0.092
155.07,169.68,,-0.093
155.09,169.90,,-0.093
155.12,170.12,,-0.093
155.14,170.33,,-0.093
155.16,170.55,,-0.093
155.18,170.77,,-0.093
155.20,170.98,,-0.093
155.22,171.20,,-0.093
155.25,171.42,,-0.093
155.27,171.63,,-0.093
155.29,171.85,,-0.093
155.31,172.07,,-0.093
155.33,172.28,,-0.093
155.35,172.50,,-0.093
155.38,172.72,,-0.093
155.40,172.93,,-0.093
155.42,173.15,,-0.093
155.44,173.37,,-0.093
155.46,173.58,,-0.094
155.48,173.80,,-0.094
155.50,174.02,,-0.094
155.53,174.24,,-0.094
155.55,174.45,,-0.094
155.57,174.67,,-0.094
155.59,174.89,,-0.094
155.61,175.10,,-0.095
155.63,175.32,,-0.095
155.66,175.54,,-0.095
155.68,175.75,,-0.095
155.70,175.97,,-0.096
155.72,176.19,,-0.096
155.74,176.40,,-0.096
155.77,176.62,,-0.096
155.79,176.84,,-0.096
155.81,177.05,,-0.096
155.83,177.27,,-0.096
155.85,177.49,,-0.097
155.87,177.70,,-0.097
155.90,177.92,,-0.097
155.92,178.14,,-0.097
155.94,178.35,,-0.098
155.96,178.57,,-0.098
155.98,178.79,,-0.098
156.00,179.00,,-0.098
156.03,179.22,,-0.098
156.05,179.44,,-0.098
156.07,179.66,,-0.098
156.09,179.87,,-0.098
156.11,180.09,,-0.098
156.13,180.31,,-0.098
156.15,180.52,,-0.098
156.18,180.74,,-0.098
156.20,180.96,,-0.098
156.22,181.17,,-0.098
156.24,181.39,,-0.099
156.26,181.61,,-0.099
156.28,181.82,,-0.099
156.31,182.04,,-0.099
156.33,182.26,,-0.099
156.35,182.47,,-0.100
156.37,182.69,,-0.100
156.39,182.91,,-0.100
156.42,183.13,,-0.100
156.44,183.34,,-0.100
156.46,183.56,,-0.100
156.48,183.78,,-0.100
156.50,183.99,,-0.101
156.52,184.21,,-0.101
156.55,184.43,,-0.101
156.57,184.64,,-0.101
156.59,184.86,,-0.101
156.61,185.08,,-0.101
156.63,185.29,,-0.101
156.65,185.51,,-0.101
156.68,185.73,,-0.101
156.70,185.94,,-0.101
156.72,186.16,,-0.101
156.74,186.38,,-0.101
156.76,186.59,,-0.102
156.78,186.81,,-0.101
156.80,187.03,,-0.102
156.83,187.24,,-0.102
156.85,187.46,,-0.102
156.87,187.68,,-0.102
156.89,187.90,,-0.102
156.91,188.11,,-0.102
156.93,188.33,,-0.102
156.96,188.54,,-0.102
156.98,188.76,,-0.102
157.00,188.98,,-0.102
157.02,189.20,,-0.102
157.04,189.41,,-0.102
157.07,189.63,,-0.102
157.09,189.85,,-0.102
157.11,190.06,,-0.102
157.13,190.28,,-0.102
157.15,190.50,,-0.102
157.17,190.71,,-0.102
157.20,190.93,,-0.102
157.22,191.15,,-0.102
157.24,191.36,,-0.103
157.26,191.58,,-0.103
157.28,191.80,,-0.103
157.30,192.01,,-0.102
157.33,192.23,,-0.103
157.35,192.45,,-0.103
157.37,192.66,,-0.103
157.39,192.88,,-0.103
157.41,193.10,,-0.103
157.43,193.31,,-0.103
157.45,193.53,,-0.103
157.48,193.75,,-0.103
157.50,193.97,,-0.104
157.52,194.18,,-0.104
157.54,194.40,,-0.104
157.56,194.62,,-0.104
157.58,194.83,,-0.104
157.61,195.05,,-0.104
157.63,195.27,,-0.104
157.65,195.48,,-0.104
157.67,195.70,,-0.104
157.69,195.92,,-0.104
157.72,196.13,,-0.104
157.74,196.35,,-0.104
157.76,196.57,,-0.104
157.78,196.78,,-0.104
157.80,197.00,,-0.104
157.82,197.22,,-0.104
157.85,197.43,,-0.104
157.87,197.65,,-0.104
157.89,197.87,,-0.104
157.91,198.08,,-0.104
157.93,198.30,,-0.104
157.95,198.52,,-0.104
157.98,198.74,,-0.104
158.00,198.95,,-0.104
158.02,199.17,,-0.104
158.04,199.39,,-0.105
158.06,199.60,,-0.105
158.08,199.82,,-0.105
158.10,200.04,,-0.105
158.13,200.25,,-0.105
158.15,200.47,,-0.105
158.17,200.69,,-0.105
158.19,200.90,,-0.105
158.21,201.12,,-0.105
158.23,201.34,,-0.105
158.26,201.55,,-0.106
158.28,201.77,,-0.106
158.30,201.99,,-0.106
158.32,202.20,,-0.106
158.34,202.42,,-0.106
158.37,202.64,,-0.105
158.39,202.85,,-0.106
158.41,203.07,,-0.106
158.43,203.29,,-0.106
158.45,203.50,,-0.106
158.47,203.72,,-0.106
158.50,203.94,,-0.106
158.52,204.15,,-0.106
158.54,204.37,,-0.106
158.56,204.59,,-0.106
158.58,204.81,,-0.106
158.60,205.02,,-0.106
158.63,205.24,,-0.106
158.65,205.45,,-0.106
158.67,205.67,,-0.107
158.69,205.89,,-0.107
158.71,206.11,,-0.107
158.73,206.32,,-0.107
158.75,206.54,,-0.107
158.78,206.76,,-0.107
158.80,206.97,,-0.107
158.82,207.19,,-0.107
158.84,207.41,,-0.107
158.86,207.62,,-0.107
158.88,207.84,,-0.107
158.91,208.06,,-0.108
158.93,208.27,,-0.108
158.95,208.49,,-0.108
158.97,208.71,,-0.108
158.99,208.92,,-0.108
159.02,209.14,,-0.108
159.04,209.36,,-0.108
159.06,209.57,,-0.108
159.08,209.79,,-0.109
159.10,210.01,,-0.109
159.12,210.23,,-0.109
159.15,210.44,,-0.109
159.17,210.66,,-0.109
159.19,210.88,,-0.110
159.21,211.09,,-0.110
159.23,211.31,,-0.110
159.25,211.53,,-0.110
159.28,211.74,,-0.110
159.30,211.96,,-0.110
159.32,212.18,,-0.110
159.34,212.39,,-0.110
159.36,212.61,,-0.110
159.38,212.83,,-0.111
159.40,213.04,,-0.111
159.43,213.26,,-0.111
159.45,213.48,,-0.111
159.47,213.69,,-0.111
159.49,213.91,,-0.112
159.51,214.13,,-0.112
159.53,214.34,,-0.112
159.56,214.56,,-0.112
159.58,214.78,,-0.112
159.60,214.99,,-0.112
159.62,215.21,,-0.112
159.64,215.43,,-0.113
159.67,215.65,,-0.113
159.69,215.86,,-0.113
159.71,216.08,,-0.113
159.73,216.30,,-0.113
159.75,216.51,,-0.113
159.77,216.73,,-0.113
159.80,216.95,,-0.113
159.82,217.16,,-0.113
159.84,217.38,,-0.113
159.86,217.60,,-0.113
159.88,217.81,,-0.114
159.90,218.03,,-0.114
159.93,218.25,,-0.114
159.95,218.46,,-0.114
159.97,218.68,,-0.114
159.99,218.90,,-0.114
160.01,219.11,,-0.114
160.03,219.33,,-0.114
160.05,219.55,,-0.114
160.08,219.77,,-0.115
160.10,219.98,,-0.115
160.12,220.20,,-0.115
160.14,220.42,,-0.115
160.16,220.63,,-0.115
160.18,220.85,,-0.115
160.21,221.06,,-0.115
160.23,221.28,,-0.114
160.25,221.50,,-0.115
160.27,221.72,,-0.115
160.29,221.93,,-0.115
160.32,222.15,,-0.115
160.34,222.37,,-0.115
160.36,222.58,,-0.115
160.38,222.80,,-0.115
160.40,223.02,,-0.115
160.42,223.23,,-0.115
160.45,223.45,,-0.115
160.47,223.67,,-0.115
160.49,223.88,,-0.115
160.51,224.10,,-0.115
160.53,224.32,,-0.116
160.55,224.53,,-0.116
160.58,224.75,,-0.116
160.60,224.97,,-0.116
160.62,225.18,,-0.116
160.64,225.40,,-0.116
160.66,225.62,,-0.116
160.68,225.84,,-0.116
160.70,226.05,,-0.117
160.73,226.27,,-0.117
160.75,226.49,,-0.117
160.77,226.70,,-0.117
160.79,226.92,,-0.117
160.81,227.14,,-0.117
160.83,227.35,,-0.117
160.86,227.57,,-0.117
160.88,227.79,,-0.117
160.90,228.00,,-0.117
160.92,228.22,,-0.118
160.94,228.44,,-0.118
160.97,228.65,,-0.118
160.99,228.87,,-0.118
161.01,229.09,,-0.118
161.03,229.30,,-0.118
161.05,229.52,,-0.119
161.07,229.74,,-0.119
161.10,229.95,,-0.119
161.12,230.17,,-0.119
161.14,230.39,,-0.119
161.16,230.60,,-0.119
161.18,230.82,,-0.119
161.20,231.04,,-0.119
161.23,231.25,,-0.119
161.25,231.47,,-0.119
161.27,231.69,,-0.119
161.29,231.90,,-0.120
161.31,232.12,,-0.120
161.33,232.34,,-0.120
161.35,232.56,,-0.120
161.38,232.77,,-0.120
161.40,232.99,,-0.120
161.42,233.21,,-0.120
161.44,233.42,,-0.120
161.46,233.64,,-0.120
161.48,233.86,,-0.120
161.51,234.07,,-0.121
161.53,234.29,,-0.121
161.55,234.51,,-0.121
161.57,234.72,,-0.121
161.59,234.94,,-0.121
161.62,235.16,,-0.122
161.64,235.37,,-0.122
161.66,235.59,,-0.122
161.68,235.81,,-0.122
161.70,236.02,,-0.122
161.72,236.24,,-0.122
161.75,236.46,,-0.123
161.77,236.67,,-0.123
161.79,236.89,,-0.123
161.81,237.11,,-0.123
161.83,237.32,,-0.123
161.85,237.54,,-0.123
161.88,237.76,,-0.124
161.90,237.98,,-0.124
161.92,238.19,,-0.124
161.94,238.41,,-0.124
161.96,238.63,,-0.124
161.98,238.84,,-0.124
162.00,239.06,,-0.124
162.03,239.28,,-0.124
162.05,239.49,,-0.124
162.07,239.71,,-0.124
162.09,239.93,,-0.124
162.11,240.14,,-0.124
162.13,240.36,,-0.125
162.16,240.58,,-0.125
162.18,240.79,,-0.125
162.20,241.01,,-0.125
162.22,241.23,,-0.125
162.24,241.44,,-0.126
162.27,241.66,,-0.126
162.29,241.88,,-0.126
162.31,242.09,,-0.126
162.33,242.31,,-0.126
162.35,242.53,,-0.126
162.37,242.75,,-0.126
162.40,242.96,,-0.126
162.42,243.18,,-0.126
162.44,243.39,,-0.126
162.46,243.61,,-0.126
162.48,243.83,,-0.127
162.50,244.04,,-0.127
162.53,244.26,,-0.127
162.55,244.48,,-0.127
162.57,244.70,,-0.127
162.59,244.91,,-0.128
162.61,245.13,,-0.128
162.63,245.35,,-0.128
162.65,245.56,,-0.128
162.68,245.78,,-0.128
162.70,246.00,,-0.128
162.72,246.21,,-0.128
162.74,246.43,,-0.129
162.76,246.65,,-0.129
162.78,246.86,,-0.129
162.81,247.08,,-0.129
162.83,247.30,,-0.129
162.85,247.51,,-0.129
162.87,247.73,,-0.129
162.89,247.95,,-0.129
162.92,248.16,,-0.130
162.94,248.38,,-0.130
162.96,248.60,,
162.98,248.81,,
163.00,,,