File: DSC/Olivia/2025_08_09_PVP10_n60C_180C_10Cmin_x3_2.csv
Filename,2025_08_09_PVP10_n60C_180C_10Cmin_x3_2
Instrument name,DSC2A-00468 (192.168.1.100)
Operator,Yarger
rundate,8/9/2025
Sample name,2025_08_09_PVP10_n60C_180C_10Cmin_x3_2
proceduresegments,Data Off ; Equilibrate -60.00 °C; Data On ; Ramp 10.00 °C/min to 180.00 °C; Data Off ; Isothermal 2.0 min; Data On ; Ramp 10.00 °C/min to -60.00 °C; Data Off ; Isothermal 2.0 min; Data On ; Ramp 10.00 °C/min to 180.00 °C; Data Off ; Isothermal 2.0 min; Data On ; Ramp 10.00 °C/min to -60.00 °C; Data Off ; Isothermal 2.0 min; Data On ; Ramp 10.00 °C/min to 180.00 °C
[File Parameters]
Run date,8/9/2025 7:51:15 PM
Trios version,5.1.1.46572
Original File Name,
Current File Name,D:\DSC2500\JYarger\2025_08_09_PVP10_n60C_180C_10Cmin_x3_2.tri
[Procedure]
Procedure Name,TS_n60C_250C_10Cmin_x3
Sample Name,2025_08_09_PVP10_n60C_180C_10Cmin_x3_2
Sample Mass,32.25 mg
Reference Sample Mass,0 mg
Pan Mass,4.19 mg
Pan Number,42
Reference Pan Mass,32.52 mg
Reference Pan Number,37
Pan Type,Aluminum
Comments,Thermal support Al pans/lids. DSC_Samples_A2_Tray_August2025 google sheet.
Project Name,Pharma
Operator,Yarger
Test,Custom
Unload Max Temperature,30
Unload Min Temperature,30
Load Max Temperature,30
Load Min Temperature,30
Stop on Gas Flow Error,Yes
[Signal List]
Signal #1,Time (min)
Signal #2,Temperature (°C)
Signal #3,Heat Flow (mW)
Signal #4,Delta T (µV)
Signal #5,Delta Tzero (µV)
Signal #6,Tzero Temperature (°C)
Signal #7,Cell Purge (mL/min)
Signal #8,Heater Temp (°C)
Signal #9,Power Delivered (W)
Signal #10,Reference Junction Temperature (°C)
Signal #11,Flange Temperature (°C)
Signal #12,Heat Flow Phase (rad)
Signal #13,Total Heat Capacity (J/°C)
Signal #14,Heat Capacity (J/°C)
[Configuration]
Company Name,ASU
Instrument Name,DSC2A-00468
Instrument Type,DSC2500
Serial Number,DSC2A-00468
IP,192.168.1.100
Location of Instrument,MRRC
DisplayType,Unknown
Sample Interval ,0.1 s/pt
Selected Heat Flow,T4P
Exotherm Direction,Down
Cell Serial,DRC2-00792
Lid Type,Standard
Cooler,RCS 90
Leave Cooler on at End of Sequence,On
Gas 2,Nitrogen
Gas Selected,Channel 1
Flow Rate,50 mL/min
Secondary Purge,On
Licensed Heat Flow,Heat Flow T4P
Modulation Licensed,Yes
[Versions]
Common IDD Version,1
Cortex Version,VER 2.10.2.31
Driver,5.0.0.6
GDM Version,1.0.3.3
TouchscreenVersion,1.0.0.16145
FEP Version,1.2.1.21
FEP Bootloader,2.0.0.5
AutoSampler Version,2.1.1.26
Auto Sampler Bootloader,2.0.0.5
FCM Version,1.1.0.3
FCM Bootloader,2.0.0.5
[Experiment Logs]
Experiment Log Entry # 1,Data On set to 0
Experiment Log Entry # 3,Equilibrate Segment -60 (C) Started
Experiment Log Entry # 5,Air Cool is off.
Experiment Log Entry # 7,Data On set to 1
Experiment Log Entry # 9,Ramp Segment 10 C/min to 180 Started
Experiment Log Entry # 11,Data On set to 0
Experiment Log Entry # 13,Isothermal Segment 2 min started
Experiment Log Entry # 15,Data On set to 1
Experiment Log Entry # 17,Ramp Segment 10 C/min to -60 Started
Experiment Log Entry # 19,Data On set to 0
Experiment Log Entry # 21,Isothermal Segment 2 min started
Experiment Log Entry # 23,Data On set to 1
Experiment Log Entry # 25,Ramp Segment 10 C/min to 180 Started
Experiment Log Entry # 27,Data On set to 0
Experiment Log Entry # 29,Isothermal Segment 2 min started
Experiment Log Entry # 31,Data On set to 1
Experiment Log Entry # 33,Ramp Segment 10 C/min to -60 Started
Experiment Log Entry # 35,Data On set to 0
Experiment Log Entry # 37,Isothermal Segment 2 min started
Experiment Log Entry # 39,Data On set to 1
Experiment Log Entry # 41,Ramp Segment 10 C/min to 180 Started
[Method Log]
Method Log Entry # 1,Data Off
Method Log Entry # 2,Equilibrate -60 °C
Method Log Entry # 3,Data On
Method Log Entry # 4,(Ramp 738351) Ramp 10 °C/minute to 180 °C
Method Log Entry # 5,Data Off
Method Log Entry # 6,Isothermal 2 minutes
Method Log Entry # 7,Data On
Method Log Entry # 8,(Ramp 738355) Ramp 10 °C/minute to -60 °C
Method Log Entry # 9,Data Off
Method Log Entry # 10,Isothermal 2 minutes
Method Log Entry # 11,Data On
Method Log Entry # 12,(Ramp 738359) Ramp 10 °C/minute to 180 °C
Method Log Entry # 13,Data Off
Method Log Entry # 14,Isothermal 2 minutes
Method Log Entry # 15,Data On
Method Log Entry # 16,(Ramp 738363) Ramp 10 °C/minute to -60 °C
Method Log Entry # 17,Data Off
Method Log Entry # 18,Isothermal 2 minutes
Method Log Entry # 19,Data On
Method Log Entry # 20,(Ramp 738367) Ramp 10 °C/minute to 180 °C
Cell Serial,DRC2-00792
[T1 Calibration]
Slope,-0.008529666
Offset,9.636258
Initial Temperature,98.23
GUID,f8bfdadc-4977-4fdf-ba6d-0ba9134940c3
[TZero Calibration]
Date Applied,11/29/2022 4:06:13 PM
Description,From -89.059 °C to 396.009 °C at 20.000°C/min
Gas Type,Nitrogen
Pan Type,None
Source Files 1,C:\Users\yargerlab\Desktop\DSC Data\General\TZero_calibration_11_29_22_2nd(2).tri
Source Files 2,C:\Users\yargerlab\Desktop\DSC Data\General\TZero_calibration_11_29_22_2nd(3).tri
Delta T Offset,13.05235
Delta T Slope,-0.007271007
Delta T0 Offset,-13.69128
Delta T0 Slope,0.06063341
[Temperature Calibration]
Date Applied,11/29/2022 7:12:28 PM
Description,From 106.590 °C to 186.590 °C at 10.000°C/min
Gas Type,Nitrogen
Pan Type,Tzero Aluminum Hermetic
Source Files 1,C:\Users\yargerlab\Desktop\DSC Data\General\Indium(6).tri
Measured 1,157.391
Known 1,156.598
[Cell Constant Calibration]
Date Applied,11/29/2022 7:12:29 PM
Description,From 106.590 °C to 186.590 °C at 10.000°C/min
Gas Type,Nitrogen
Pan Type,Tzero Aluminum Hermetic
Source Files 1,C:\Users\yargerlab\Desktop\DSC Data\General\Indium(6).tri
T4P KCell,1.006051
Onset Slope,63.26126 mW/°C
[Direct Cp Calibration]
Date Applied,11/30/2022 11:04:51 AM
Description,From -79.983 °C to 298.409 °C at 10.000°C/min
Gas Type,Nitrogen
Pan Type,Tzero Aluminum Hermetic
Source Files 1,C:\Users\yargerlab\Desktop\DSC Data\General\Sapphire_Heat_Capacity_11_30_22.tri
[Rev Cp Calibration]
Date Applied,11/30/2022 1:58:51 PM
Description,From -79.996 °C to 292.812 °C at 3.000°C/min
Gas Type,Nitrogen
Pan Type,Tzero Aluminum Hermetic
Source Files 1,C:\Users\yargerlab\Desktop\DSC Data\General\Sapphire_MDSC_Calibration_11_30_22.tri
[step]
Ramp 10.00 °C/min to 180.00 °C
Time,Temperature,Heat Flow (Normalized)
min,°C,W/g
0.00,-59.81,-0.007
0.02,-59.82,-0.007
0.03,-59.82,-0.006
0.05,-59.81,-0.006
0.07,-59.79,-0.005
0.08,-59.75,-0.003
0.10,-59.69,-0.001
0.12,-59.62,0.002
0.13,-59.52,0.005
0.15,-59.41,0.009
0.17,-59.29,0.012
0.18,-59.15,0.015
0.20,-59.01,0.018
0.22,-58.87,0.020
0.23,-58.72,0.022
0.25,-58.56,0.024
0.27,-58.41,0.025
0.28,-58.25,0.027
0.30,-58.09,0.028
0.32,-57.93,0.028
0.33,-57.77,0.029
0.35,-57.61,0.029
0.37,-57.45,0.030
0.38,-57.29,0.030
0.40,-57.13,0.030
0.42,-56.96,0.030
0.43,-56.80,0.031
0.45,-56.64,0.031
0.47,-56.48,0.031
0.48,-56.31,0.031
0.50,-56.15,0.031
0.52,-55.98,0.031
0.53,-55.82,0.031
0.55,-55.66,0.031
0.57,-55.49,0.031
0.58,-55.33,0.032
0.60,-55.16,0.032
0.62,-55.00,0.032
0.63,-54.83,0.032
0.65,-54.67,0.032
0.67,-54.51,0.032
0.68,-54.34,0.032
0.70,-54.18,0.032
0.72,-54.01,0.032
0.73,-53.85,0.032
0.75,-53.68,0.032
0.77,-53.52,0.032
0.78,-53.35,0.032
0.80,-53.19,0.032
0.82,-53.02,0.032
0.83,-52.86,0.032
0.85,-52.69,0.032
0.87,-52.53,0.032
0.88,-52.36,0.032
0.90,-52.19,0.032
0.92,-52.03,0.032
0.93,-51.87,0.033
0.95,-51.70,0.033
0.97,-51.53,0.033
0.98,-51.37,0.033
1.00,-51.20,0.033
1.02,-51.04,0.033
1.03,-50.87,0.033
1.05,-50.70,0.033
1.07,-50.54,0.033
1.08,-50.37,0.033
1.10,-50.21,0.033
1.12,-50.04,0.033
1.13,-49.87,0.033
1.15,-49.71,0.033
1.17,-49.54,0.033
1.18,-49.37,0.033
1.20,-49.21,0.033
1.22,-49.04,0.033
1.23,-48.88,0.033
1.25,-48.71,0.033
1.27,-48.54,0.033
1.28,-48.38,0.033
1.30,-48.21,0.033
1.32,-48.05,0.033
1.33,-47.88,0.033
1.35,-47.71,0.033
1.37,-47.55,0.033
1.38,-47.38,0.033
1.40,-47.21,0.033
1.42,-47.05,0.033
1.43,-46.88,0.033
1.45,-46.71,0.033
1.47,-46.55,0.033
1.48,-46.38,0.034
1.50,-46.21,0.034
1.52,-46.05,0.034
1.53,-45.88,0.034
1.55,-45.71,0.034
1.57,-45.55,0.034
1.58,-45.38,0.034
1.60,-45.21,0.034
1.62,-45.05,0.034
1.63,-44.88,0.034
1.65,-44.71,0.034
1.67,-44.55,0.034
1.68,-44.38,0.034
1.70,-44.21,0.034
1.72,-44.05,0.034
1.73,-43.88,0.034
1.75,-43.71,0.034
1.77,-43.55,0.034
1.78,-43.38,0.034
1.80,-43.21,0.034
1.82,-43.05,0.034
1.83,-42.88,0.034
1.85,-42.71,0.034
1.87,-42.55,0.034
1.88,-42.38,0.034
1.90,-42.21,0.034
1.92,-42.05,0.034
1.93,-41.88,0.034
1.95,-41.71,0.034
1.97,-41.55,0.034
1.98,-41.38,0.034
2.00,-41.21,0.034
2.02,-41.05,0.034
2.03,-40.88,0.034
2.05,-40.71,0.034
2.07,-40.54,0.034
2.08,-40.38,0.034
2.10,-40.21,0.034
2.12,-40.04,0.034
2.13,-39.88,0.034
2.15,-39.71,0.034
2.17,-39.55,0.034
2.18,-39.38,0.034
2.20,-39.21,0.034
2.22,-39.05,0.034
2.23,-38.88,0.034
2.25,-38.71,0.034
2.27,-38.54,0.034
2.28,-38.38,0.034
2.30,-38.21,0.034
2.32,-38.04,0.034
2.33,-37.88,0.034
2.35,-37.71,0.034
2.37,-37.54,0.034
2.38,-37.38,0.034
2.40,-37.21,0.034
2.42,-37.04,0.034
2.43,-36.87,0.034
2.45,-36.71,0.034
2.47,-36.54,0.034
2.48,-36.37,0.034
2.50,-36.21,0.034
2.52,-36.04,0.034
2.53,-35.87,0.034
2.55,-35.70,0.034
2.57,-35.54,0.034
2.58,-35.37,0.034
2.60,-35.20,0.034
2.62,-35.04,0.034
2.63,-34.87,0.034
2.65,-34.70,0.034
2.67,-34.54,0.034
2.68,-34.37,0.034
2.70,-34.20,0.034
2.72,-34.03,0.034
2.73,-33.87,0.034
2.75,-33.70,0.034
2.77,-33.53,0.034
2.78,-33.37,0.034
2.80,-33.20,0.034
2.82,-33.03,0.034
2.83,-32.87,0.034
2.85,-32.70,0.034
2.87,-32.53,0.034
2.88,-32.37,0.034
2.90,-32.20,0.034
2.92,-32.03,0.034
2.93,-31.87,0.034
2.95,-31.70,0.034
2.97,-31.53,0.035
2.98,-31.37,0.035
3.00,-31.20,0.035
3.02,-31.03,0.035
3.03,-30.86,0.035
3.05,-30.70,0.035
3.07,-30.53,0.035
3.08,-30.37,0.035
3.10,-30.20,0.035
3.12,-30.03,0.035
3.13,-29.86,0.035
3.15,-29.70,0.035
3.17,-29.53,0.035
3.18,-29.36,0.035
3.20,-29.20,0.035
3.22,-29.03,0.035
3.23,-28.86,0.035
3.25,-28.70,0.035
3.27,-28.53,0.035
3.28,-28.36,0.035
3.30,-28.20,0.035
3.32,-28.03,0.035
3.33,-27.86,0.035
3.35,-27.70,0.035
3.37,-27.53,0.035
3.38,-27.36,0.035
3.40,-27.19,0.035
3.42,-27.03,0.035
3.43,-26.86,0.035
3.45,-26.69,0.035
3.47,-26.53,0.035
3.48,-26.36,0.035
3.50,-26.19,0.035
3.52,-26.03,0.035
3.53,-25.86,0.035
3.55,-25.69,0.035
3.57,-25.53,0.035
3.58,-25.36,0.035
3.60,-25.19,0.035
3.62,-25.03,0.035
3.63,-24.86,0.035
3.65,-24.69,0.035
3.67,-24.52,0.035
3.68,-24.36,0.035
3.70,-24.19,0.035
3.72,-24.02,0.035
3.73,-23.86,0.035
3.75,-23.69,0.035
3.77,-23.52,0.035
3.78,-23.36,0.035
3.80,-23.19,0.035
3.82,-23.02,0.035
3.83,-22.86,0.035
3.85,-22.69,0.035
3.87,-22.52,0.035
3.88,-22.36,0.035
3.90,-22.19,0.035
3.92,-22.02,0.035
3.93,-21.86,0.035
3.95,-21.69,0.035
3.97,-21.52,0.035
3.98,-21.36,0.035
4.00,-21.19,0.035
4.02,-21.02,0.035
4.03,-20.86,0.035
4.05,-20.69,0.035
4.07,-20.52,0.035
4.08,-20.35,0.035
4.10,-20.19,0.035
4.12,-20.02,0.035
4.13,-19.85,0.035
4.15,-19.69,0.035
4.17,-19.52,0.035
4.18,-19.35,0.035
4.20,-19.19,0.035
4.22,-19.02,0.035
4.23,-18.85,0.035
4.25,-18.68,0.035
4.27,-18.52,0.035
4.28,-18.35,0.035
4.30,-18.18,0.036
4.32,-18.02,0.036
4.33,-17.85,0.036
4.35,-17.68,0.036
4.37,-17.52,0.036
4.38,-17.35,0.036
4.40,-17.18,0.036
4.42,-17.02,0.036
4.43,-16.85,0.036
4.45,-16.68,0.036
4.47,-16.52,0.036
4.48,-16.35,0.036
4.50,-16.18,0.036
4.52,-16.02,0.036
4.53,-15.85,0.036
4.55,-15.68,0.036
4.57,-15.52,0.036
4.58,-15.35,0.036
4.60,-15.18,0.036
4.62,-15.02,0.036
4.63,-14.85,0.036
4.65,-14.68,0.036
4.67,-14.51,0.036
4.68,-14.35,0.036
4.70,-14.18,0.036
4.72,-14.01,0.036
4.73,-13.85,0.036
4.75,-13.68,0.036
4.77,-13.51,0.036
4.78,-13.34,0.036
4.80,-13.18,0.036
4.82,-13.01,0.036
4.83,-12.84,0.036
4.85,-12.68,0.036
4.87,-12.51,0.036
4.88,-12.34,0.036
4.90,-12.18,0.036
4.92,-12.01,0.036
4.93,-11.84,0.036
4.95,-11.68,0.036
4.97,-11.51,0.036
4.98,-11.34,0.036
5.00,-11.18,0.036
5.02,-11.01,0.036
5.03,-10.84,0.036
5.05,-10.68,0.036
5.07,-10.51,0.036
5.08,-10.34,0.036
5.10,-10.18,0.036
5.12,-10.01,0.036
5.13,-9.84,0.036
5.15,-9.68,0.036
5.17,-9.51,0.036
5.18,-9.34,0.036
5.20,-9.18,0.036
5.22,-9.01,0.036
5.23,-8.84,0.036
5.25,-8.68,0.036
5.27,-8.51,0.036
5.28,-8.34,0.036
5.30,-8.18,0.036
5.32,-8.01,0.037
5.33,-7.84,0.037
5.35,-7.67,0.037
5.37,-7.51,0.037
5.38,-7.34,0.037
5.40,-7.17,0.037
5.42,-7.01,0.037
5.43,-6.84,0.037
5.45,-6.67,0.037
5.47,-6.51,0.037
5.48,-6.34,0.037
5.50,-6.17,0.037
5.52,-6.01,0.037
5.53,-5.84,0.037
5.55,-5.67,0.037
5.57,-5.51,0.037
5.58,-5.34,0.037
5.60,-5.17,0.037
5.62,-5.00,0.037
5.63,-4.84,0.037
5.65,-4.67,0.037
5.67,-4.50,0.037
5.68,-4.34,0.037
5.70,-4.17,0.037
5.72,-4.00,0.037
5.73,-3.84,0.037
5.75,-3.67,0.037
5.77,-3.50,0.037
5.78,-3.34,0.037
5.80,-3.17,0.037
5.82,-3.00,0.037
5.83,-2.84,0.037
5.85,-2.67,0.037
5.87,-2.50,0.037
5.88,-2.34,0.037
5.90,-2.17,0.037
5.92,-2.00,0.037
5.93,-1.83,0.037
5.95,-1.67,0.037
5.97,-1.50,0.037
5.98,-1.33,0.037
6.00,-1.17,0.037
6.02,-1.00,0.037
6.03,-0.83,0.037
6.05,-0.67,0.037
6.07,-0.50,0.037
6.08,-0.33,0.038
6.10,-0.17,0.038
6.12,0.00,0.038
6.13,0.17,0.038
6.15,0.33,0.038
6.17,0.50,0.038
6.18,0.67,0.038
6.20,0.84,0.038
6.22,1.00,0.038
6.23,1.17,0.038
6.25,1.34,0.038
6.27,1.50,0.038
6.28,1.67,0.038
6.30,1.84,0.038
6.32,2.00,0.038
6.33,2.17,0.038
6.35,2.34,0.038
6.37,2.50,0.038
6.38,2.67,0.038
6.40,2.84,0.038
6.42,3.00,0.038
6.43,3.17,0.038
6.45,3.34,0.038
6.47,3.50,0.038
6.48,3.67,0.038
6.50,3.84,0.038
6.52,4.01,0.038
6.53,4.17,0.038
6.55,4.34,0.038
6.57,4.51,0.038
6.58,4.67,0.038
6.60,4.84,0.038
6.62,5.01,0.038
6.63,5.17,0.038
6.65,5.34,0.038
6.67,5.51,0.038
6.68,5.67,0.038
6.70,5.84,0.038
6.72,6.01,0.038
6.73,6.17,0.039
6.75,6.34,0.039
6.77,6.51,0.039
6.78,6.67,0.039
6.80,6.84,0.039
6.82,7.01,0.039
6.83,7.17,0.039
6.85,7.34,0.039
6.87,7.51,0.039
6.88,7.67,0.039
6.90,7.84,0.039
6.92,8.01,0.039
6.93,8.17,0.039
6.95,8.34,0.039
6.97,8.51,0.039
6.98,8.67,0.039
7.00,8.84,0.039
7.02,9.01,0.039
7.03,9.18,0.039
7.05,9.34,0.039
7.07,9.51,0.039
7.08,9.68,0.039
7.10,9.84,0.039
7.12,10.01,0.039
7.13,10.18,0.039
7.15,10.34,0.039
7.17,10.51,0.039
7.18,10.68,0.039
7.20,10.84,0.039
7.22,11.01,0.039
7.23,11.18,0.039
7.25,11.34,0.039
7.27,11.51,0.039
7.28,11.68,0.040
7.30,11.84,0.040
7.32,12.01,0.040
7.33,12.18,0.040
7.35,12.35,0.040
7.37,12.51,0.040
7.38,12.68,0.040
7.40,12.85,0.040
7.42,13.01,0.040
7.43,13.18,0.040
7.45,13.35,0.040
7.47,13.51,0.040
7.48,13.68,0.040
7.50,13.85,0.040
7.52,14.01,0.040
7.53,14.18,0.040
7.55,14.35,0.040
7.57,14.51,0.040
7.58,14.68,0.040
7.60,14.85,0.040
7.62,15.01,0.040
7.63,15.18,0.040
7.65,15.35,0.040
7.67,15.51,0.040
7.68,15.68,0.040
7.70,15.85,0.040
7.72,16.01,0.040
7.73,16.18,0.041
7.75,16.35,0.041
7.77,16.52,0.041
7.78,16.68,0.041
7.80,16.85,0.041
7.82,17.01,0.041
7.83,17.18,0.041
7.85,17.35,0.041
7.87,17.52,0.041
7.88,17.68,0.041
7.90,17.85,0.041
7.92,18.01,0.041
7.93,18.18,0.041
7.95,18.35,0.041
7.97,18.51,0.041
7.98,18.68,0.041
8.00,18.85,0.041
8.02,19.02,0.041
8.03,19.18,0.041
8.05,19.35,0.041
8.07,19.52,0.041
8.08,19.68,0.041
8.10,19.85,0.041
8.12,20.02,0.042
8.13,20.18,0.042
8.15,20.35,0.042
8.17,20.52,0.042
8.18,20.68,0.042
8.20,20.85,0.042
8.22,21.01,0.042
8.23,21.18,0.042
8.25,21.35,0.042
8.27,21.51,0.042
8.28,21.68,0.042
8.30,21.85,0.042
8.32,22.01,0.042
8.33,22.18,0.042
8.35,22.35,0.042
8.37,22.52,0.042
8.38,22.68,0.042
8.40,22.85,0.042
8.42,23.02,0.042
8.43,23.18,0.043
8.45,23.35,0.043
8.47,23.52,0.043
8.48,23.68,0.043
8.50,23.85,0.043
8.52,24.02,0.043
8.53,24.18,0.043
8.55,24.35,0.043
8.57,24.52,0.043
8.58,24.68,0.043
8.60,24.85,0.043
8.62,25.02,0.043
8.63,25.18,0.043
8.65,25.35,0.043
8.67,25.52,0.043
8.68,25.68,0.043
8.70,25.85,0.043
8.72,26.02,0.044
8.73,26.18,0.044
8.75,26.35,0.044
8.77,26.52,0.044
8.78,26.68,0.044
8.80,26.85,0.044
8.82,27.02,0.044
8.83,27.18,0.044
8.85,27.35,0.044
8.87,27.52,0.044
8.88,27.68,0.044
8.90,27.85,0.044
8.92,28.02,0.044
8.93,28.19,0.044
8.95,28.35,0.044
8.97,28.52,0.045
8.98,28.69,0.045
9.00,28.85,0.045
9.02,29.02,0.045
9.03,29.19,0.045
9.05,29.35,0.045
9.07,29.52,0.045
9.08,29.69,0.045
9.10,29.85,0.045
9.12,30.02,0.045
9.13,30.19,0.045
9.15,30.35,0.045
9.17,30.52,0.045
9.18,30.69,0.046
9.20,30.85,0.046
9.22,31.02,0.046
9.23,31.19,0.046
9.25,31.35,0.046
9.27,31.52,0.046
9.28,31.69,0.046
9.30,31.85,0.046
9.32,32.02,0.046
9.33,32.19,0.046
9.35,32.35,0.046
9.37,32.52,0.047
9.38,32.69,0.047
9.40,32.85,0.047
9.42,33.02,0.047
9.43,33.19,0.047
9.45,33.35,0.047
9.47,33.52,0.047
9.48,33.69,0.047
9.50,33.85,0.047
9.52,34.02,0.048
9.53,34.18,0.048
9.55,34.35,0.048
9.57,34.52,0.048
9.58,34.69,0.048
9.60,34.85,0.048
9.62,35.02,0.048
9.63,35.19,0.048
9.65,35.35,0.048
9.67,35.52,0.049
9.68,35.69,0.049
9.70,35.85,0.049
9.72,36.02,0.049
9.73,36.19,0.049
9.75,36.35,0.049
9.77,36.52,0.050
9.78,36.69,0.050
9.80,36.85,0.050
9.82,37.02,0.050
9.83,37.18,0.050
9.85,37.35,0.050
9.87,37.52,0.050
9.88,37.68,0.051
9.90,37.85,0.051
9.92,38.02,0.051
9.93,38.18,0.051
9.95,38.35,0.051
9.97,38.52,0.051
9.98,38.68,0.052
10.00,38.85,0.052
10.02,39.02,0.052
10.03,39.18,0.052
10.05,39.35,0.052
10.07,39.51,0.052
10.08,39.68,0.052
10.10,39.85,0.053
10.12,40.01,0.053
10.13,40.18,0.053
10.15,40.35,0.053
10.17,40.52,0.053
10.18,40.68,0.053
10.20,40.85,0.054
10.22,41.01,0.054
10.23,41.18,0.054
10.25,41.35,0.054
10.27,41.51,0.054
10.28,41.68,0.054
10.30,41.85,0.054
10.32,42.02,0.054
10.33,42.18,0.054
10.35,42.35,0.054
10.37,42.52,0.054
10.38,42.68,0.054
10.40,42.85,0.055
10.42,43.02,0.055
10.43,43.18,0.055
10.45,43.35,0.055
10.47,43.52,0.055
10.48,43.68,0.055
10.50,43.85,0.055
10.52,44.01,0.055
10.53,44.18,0.055
10.55,44.35,0.055
10.57,44.52,0.055
10.58,44.68,0.055
10.60,44.85,0.055
10.62,45.02,0.055
10.63,45.18,0.055
10.65,45.35,0.055
10.67,45.52,0.055
10.68,45.68,0.055
10.70,45.85,0.055
10.72,46.02,0.055
10.73,46.18,0.055
10.75,46.35,0.055
10.77,46.52,0.056
10.78,46.68,0.056
10.80,46.85,0.056
10.82,47.02,0.056
10.83,47.18,0.056
10.85,47.35,0.056
10.87,47.52,0.056
10.88,47.69,0.056
10.90,47.85,0.056
10.92,48.02,0.056
10.93,48.19,0.056
10.95,48.35,0.056
10.97,48.52,0.056
10.98,48.68,0.056
11.00,48.85,0.056
11.02,49.02,0.056
11.03,49.19,0.056
11.05,49.35,0.056
11.07,49.52,0.057
11.08,49.69,0.057
11.10,49.85,0.057
11.12,50.02,0.057
11.13,50.19,0.057
11.15,50.35,0.057
11.17,50.52,0.057
11.18,50.69,0.057
11.20,50.85,0.057
11.22,51.02,0.058
11.23,51.19,0.058
11.25,51.35,0.058
11.27,51.52,0.058
11.28,51.69,0.058
11.30,51.85,0.058
11.32,52.02,0.059
11.33,52.18,0.059
11.35,52.35,0.059
11.37,52.52,0.059
11.38,52.68,0.060
11.40,52.85,0.060
11.42,53.02,0.060
11.43,53.18,0.060
11.45,53.35,0.060
11.47,53.52,0.060
11.48,53.68,0.061
11.50,53.85,0.061
11.52,54.02,0.061
11.53,54.18,0.061
11.55,54.35,0.062
11.57,54.51,0.062
11.58,54.68,0.062
11.60,54.85,0.062
11.62,55.01,0.062
11.63,55.18,0.063
11.65,55.35,0.063
11.67,55.51,0.063
11.68,55.68,0.063
11.70,55.85,0.064
11.72,56.01,0.064
11.73,56.18,0.064
11.75,56.34,0.064
11.77,56.51,0.065
11.78,56.68,0.065
11.80,56.84,0.065
11.82,57.01,0.065
11.83,57.18,0.066
11.85,57.34,0.066
11.87,57.51,0.066
11.88,57.68,0.066
11.90,57.84,0.067
11.92,58.01,0.067
11.93,58.17,0.067
11.95,58.34,0.067
11.97,58.51,0.068
11.98,58.67,0.068
12.00,58.84,0.068
12.02,59.01,0.068
12.03,59.17,0.069
12.05,59.34,0.069
12.07,59.50,0.069
12.08,59.67,0.069
12.10,59.84,0.070
12.12,60.00,0.070
12.13,60.17,0.070
12.15,60.34,0.071
12.17,60.50,0.071
12.18,60.67,0.071
12.20,60.84,0.071
12.22,61.00,0.072
12.23,61.17,0.072
12.25,61.33,0.072
12.27,61.50,0.072
12.28,61.67,0.073
12.30,61.83,0.073
12.32,62.00,0.073
12.33,62.17,0.073
12.35,62.33,0.074
12.37,62.50,0.074
12.38,62.66,0.074
12.40,62.83,0.075
12.42,63.00,0.075
12.43,63.16,0.075
12.45,63.33,0.075
12.47,63.50,0.076
12.48,63.66,0.076
12.50,63.83,0.076
12.52,64.00,0.077
12.53,64.16,0.077
12.55,64.33,0.077
12.57,64.49,0.077
12.58,64.66,0.078
12.60,64.83,0.078
12.62,64.99,0.078
12.63,65.16,0.078
12.65,65.33,0.079
12.67,65.49,0.079
12.68,65.66,0.079
12.70,65.82,0.079
12.72,65.99,0.080
12.73,66.16,0.080
12.75,66.32,0.080
12.77,66.49,0.081
12.78,66.66,0.081
12.80,66.82,0.081
12.82,66.99,0.081
12.83,67.16,0.082
12.85,67.32,0.082
12.87,67.49,0.082
12.88,67.65,0.082
12.90,67.82,0.083
12.92,67.99,0.083
12.93,68.15,0.083
12.95,68.32,0.083
12.97,68.49,0.084
12.98,68.65,0.084
13.00,68.82,0.084
13.02,68.98,0.084
13.03,69.15,0.085
13.05,69.32,0.085
13.07,69.48,0.085
13.08,69.65,0.085
13.10,69.82,0.086
13.12,69.98,0.086
13.13,70.15,0.086
13.15,70.32,0.086
13.17,70.48,0.087
13.18,70.65,0.087
13.20,70.81,0.087
13.22,70.98,0.087
13.23,71.15,0.088
13.25,71.31,0.088
13.27,71.48,0.088
13.28,71.65,0.088
13.30,71.81,0.089
13.32,71.98,0.089
13.33,72.15,0.089
13.35,72.31,0.089
13.37,72.48,0.090
13.38,72.64,0.090
13.40,72.81,0.090
13.42,72.98,0.090
13.43,73.14,0.091
13.45,73.31,0.091
13.47,73.48,0.091
13.48,73.64,0.091
13.50,73.81,0.092
13.52,73.97,0.092
13.53,74.14,0.092
13.55,74.31,0.092
13.57,74.47,0.093
13.58,74.64,0.093
13.60,74.81,0.093
13.62,74.97,0.093
13.63,75.14,0.094
13.65,75.31,0.094
13.67,75.47,0.094
13.68,75.64,0.094
13.70,75.81,0.095
13.72,75.97,0.095
13.73,76.14,0.095
13.75,76.30,0.095
13.77,76.47,0.096
13.78,76.64,0.096
13.80,76.80,0.096
13.82,76.97,0.096
13.83,77.13,0.097
13.85,77.30,0.097
13.87,77.47,0.097
13.88,77.63,0.097
13.90,77.80,0.098
13.92,77.97,0.098
13.93,78.13,0.098
13.95,78.30,0.098
13.97,78.47,0.099
13.98,78.63,0.099
14.00,78.80,0.099
14.02,78.96,0.099
14.03,79.13,0.100
14.05,79.30,0.100
14.07,79.46,0.100
14.08,79.63,0.100
14.10,79.80,0.101
14.12,79.96,0.101
14.13,80.13,0.101
14.15,80.29,0.101
14.17,80.46,0.102
14.18,80.63,0.102
14.20,80.79,0.102
14.22,80.96,0.102
14.23,81.13,0.103
14.25,81.29,0.103
14.27,81.46,0.103
14.28,81.62,0.103
14.30,81.79,0.103
14.32,81.96,0.104
14.33,82.13,0.104
14.35,82.29,0.104
14.37,82.46,0.105
14.38,82.62,0.105
14.40,82.79,0.105
14.42,82.96,0.105
14.43,83.12,0.105
14.45,83.29,0.106
14.47,83.46,0.106
14.48,83.62,0.106
14.50,83.79,0.106
14.52,83.96,0.107
14.53,84.12,0.107
14.55,84.29,0.107
14.57,84.45,0.107
14.58,84.62,0.108
14.60,84.79,0.108
14.62,84.95,0.108
14.63,85.12,0.108
14.65,85.29,0.108
14.67,85.45,0.109
14.68,85.62,0.109
14.70,85.79,0.109
14.72,85.95,0.109
14.73,86.12,0.109
14.75,86.28,0.110
14.77,86.45,0.110
14.78,86.62,0.110
14.80,86.79,0.110
14.82,86.95,0.111
14.83,87.12,0.111
14.85,87.28,0.111
14.87,87.45,0.111
14.88,87.62,0.111
14.90,87.78,0.112
14.92,87.95,0.112
14.93,88.12,0.112
14.95,88.28,0.112
14.97,88.45,0.112
14.98,88.61,0.113
15.00,88.78,0.113
15.02,88.95,0.113
15.03,89.12,0.113
15.05,89.28,0.113
15.07,89.45,0.114
15.08,89.61,0.114
15.10,89.78,0.114
15.12,89.95,0.114
15.13,90.11,0.114
15.15,90.28,0.114
15.17,90.45,0.115
15.18,90.61,0.115
15.20,90.78,0.115
15.22,90.95,0.115
15.23,91.11,0.115
15.25,91.28,0.116
15.27,91.45,0.116
15.28,91.61,0.116
15.30,91.78,0.116
15.32,91.94,0.116
15.33,92.11,0.116
15.35,92.28,0.116
15.37,92.44,0.116
15.38,92.61,0.117
15.40,92.78,0.117
15.42,92.94,0.117
15.43,93.11,0.117
15.45,93.28,0.117
15.47,93.44,0.117
15.48,93.61,0.117
15.50,93.78,0.118
15.52,93.94,0.118
15.53,94.11,0.118
15.55,94.28,0.118
15.57,94.44,0.118
15.58,94.61,0.118
15.60,94.78,0.118
15.62,94.94,0.118
15.63,95.11,0.118
15.65,95.28,0.118
15.67,95.44,0.118
15.68,95.61,0.119
15.70,95.78,0.119
15.72,95.94,0.119
15.73,96.11,0.119
15.75,96.28,0.119
15.77,96.44,0.119
15.78,96.61,0.119
15.80,96.78,0.119
15.82,96.94,0.119
15.83,97.11,0.119
15.85,97.28,0.119
15.87,97.45,0.120
15.88,97.61,0.120
15.90,97.78,0.120
15.92,97.95,0.120
15.93,98.11,0.120
15.95,98.28,0.120
15.97,98.45,0.120
15.98,98.61,0.120
16.00,98.78,0.120
16.02,98.95,0.120
16.03,99.11,0.120
16.05,99.28,0.120
16.07,99.45,0.120
16.08,99.61,0.120
16.10,99.78,0.120
16.12,99.95,0.120
16.13,100.11,0.120
16.15,100.28,0.121
16.17,100.45,0.121
16.18,100.61,0.121
16.20,100.78,0.121
16.22,100.95,0.121
16.23,101.11,0.121
16.25,101.28,0.121
16.27,101.45,0.121
16.28,101.61,0.121
16.30,101.78,0.121
16.32,101.95,0.121
16.33,102.12,0.121
16.35,102.28,0.121
16.37,102.45,0.121
16.38,102.62,0.121
16.40,102.78,0.121
16.42,102.95,0.121
16.43,103.12,0.121
16.45,103.28,0.121
16.47,103.45,0.121
16.48,103.62,0.121
16.50,103.78,0.121
16.52,103.95,0.121
16.53,104.12,0.121
16.55,104.29,0.121
16.57,104.45,0.120
16.58,104.62,0.120
16.60,104.79,0.120
16.62,104.95,0.120
16.63,105.12,0.120
16.65,105.29,0.120
16.67,105.46,0.120
16.68,105.62,0.120
16.70,105.79,0.120
16.72,105.96,0.120
16.73,106.12,0.120
16.75,106.29,0.120
16.77,106.46,0.120
16.78,106.62,0.120
16.80,106.79,0.120
16.82,106.96,0.119
16.83,107.12,0.119
16.85,107.29,0.119
16.87,107.46,0.119
16.88,107.63,0.119
16.90,107.79,0.119
16.92,107.96,0.119
16.93,108.13,0.119
16.95,108.29,0.119
16.97,108.46,0.119
16.98,108.63,0.118
17.00,108.80,0.118
17.02,108.96,0.118
17.03,109.13,0.118
17.05,109.30,0.118
17.07,109.46,0.118
17.08,109.63,0.117
17.10,109.80,0.117
17.12,109.97,0.117
17.13,110.13,0.117
17.15,110.30,0.117
17.17,110.47,0.117
17.18,110.63,0.116
17.20,110.80,0.116
17.22,110.97,0.116
17.23,111.14,0.116
17.25,111.30,0.116
17.27,111.47,0.116
17.28,111.64,0.115
17.30,111.80,0.115
17.32,111.97,0.115
17.33,112.14,0.115
17.35,112.31,0.115
17.37,112.47,0.115
17.38,112.64,0.114
17.40,112.81,0.114
17.42,112.97,0.114
17.43,113.14,0.114
17.45,113.31,0.114
17.47,113.48,0.114
17.48,113.64,0.113
17.50,113.81,0.113
17.52,113.98,0.113
17.53,114.15,0.113
17.55,114.31,0.113
17.57,114.48,0.112
17.58,114.65,0.112
17.60,114.82,0.112
17.62,114.98,0.112
17.63,115.15,0.112
17.65,115.32,0.111
17.67,115.49,0.111
17.68,115.65,0.111
17.70,115.82,0.111
17.72,115.99,0.111
17.73,116.15,0.110
17.75,116.32,0.110
17.77,116.49,0.110
17.78,116.66,0.110
17.80,116.82,0.109
17.82,116.99,0.109
17.83,117.16,0.109
17.85,117.32,0.109
17.87,117.49,0.109
17.88,117.66,0.108
17.90,117.83,0.108
17.92,117.99,0.108
17.93,118.16,0.108
17.95,118.33,0.108
17.97,118.50,0.107
17.98,118.66,0.107
18.00,118.83,0.107
18.02,119.00,0.107
18.03,119.16,0.107
18.05,119.33,0.106
18.07,119.50,0.106
18.08,119.67,0.106
18.10,119.83,0.106
18.12,120.00,0.106
18.13,120.17,0.105
18.15,120.33,0.105
18.17,120.50,0.105
18.18,120.67,0.105
18.20,120.84,0.105
18.22,121.00,0.104
18.23,121.17,0.104
18.25,121.34,0.104
18.27,121.51,0.104
18.28,121.67,0.104
18.30,121.84,0.103
18.32,122.01,0.103
18.33,122.18,0.103
18.35,122.34,0.103
18.37,122.51,0.103
18.38,122.68,0.102
18.40,122.84,0.102
18.42,123.01,0.102
18.43,123.18,0.102
18.45,123.35,0.102
18.47,123.51,0.101
18.48,123.68,0.101
18.50,123.85,0.101
18.52,124.01,0.101
18.53,124.18,0.101
18.55,124.35,0.101
18.57,124.52,0.100
18.58,124.68,0.100
18.60,124.85,0.100
18.62,125.02,0.100
18.63,125.18,0.100
18.65,125.35,0.099
18.67,125.52,0.099
18.68,125.69,0.099
18.70,125.85,0.099
18.72,126.02,0.099
18.73,126.19,0.099
18.75,126.36,0.098
18.77,126.52,0.098
18.78,126.69,0.098
18.80,126.86,0.098
18.82,127.02,0.098
18.83,127.19,0.097
18.85,127.36,0.097
18.87,127.53,0.097
18.88,127.69,0.097
18.90,127.86,0.097
18.92,128.03,0.096
18.93,128.20,0.096
18.95,128.36,0.096
18.97,128.53,0.096
18.98,128.70,0.096
19.00,128.86,0.096
19.02,129.03,0.095
19.03,129.20,0.095
19.05,129.36,0.095
19.07,129.53,0.095
19.08,129.70,0.095
19.10,129.87,0.095
19.12,130.03,0.094
19.13,130.20,0.094
19.15,130.37,0.094
19.17,130.54,0.094
19.18,130.70,0.094
19.20,130.87,0.094
19.22,131.04,0.093
19.23,131.20,0.093
19.25,131.37,0.093
19.27,131.54,0.093
19.28,131.71,0.093
19.30,131.87,0.093
19.32,132.04,0.093
19.33,132.21,0.092
19.35,132.38,0.092
19.37,132.54,0.092
19.38,132.71,0.092
19.40,132.88,0.092
19.42,133.04,0.092
19.43,133.21,0.091
19.45,133.38,0.091
19.47,133.55,0.091
19.48,133.71,0.091
19.50,133.88,0.091
19.52,134.05,0.091
19.53,134.22,0.090
19.55,134.38,0.090
19.57,134.55,0.090
19.58,134.72,0.090
19.60,134.88,0.090
19.62,135.05,0.090
19.63,135.22,0.090
19.65,135.38,0.089
19.67,135.55,0.089
19.68,135.72,0.089
19.70,135.89,0.089
19.72,136.05,0.089
19.73,136.22,0.089
19.75,136.39,0.089
19.77,136.56,0.088
19.78,136.72,0.088
19.80,136.89,0.088
19.82,137.06,0.088
19.83,137.22,0.088
19.85,137.39,0.088
19.87,137.56,0.088
19.88,137.72,0.087
19.90,137.89,0.087
19.92,138.06,0.087
19.93,138.23,0.087
19.95,138.39,0.087
19.97,138.56,0.087
19.98,138.73,0.087
20.00,138.90,0.087
20.02,139.07,0.086
20.03,139.24,0.086
20.05,139.40,0.086
20.07,139.57,0.086
20.08,139.74,0.086
20.10,139.91,0.086
20.12,140.07,0.086
20.13,140.24,0.085
20.15,140.41,0.085
20.17,140.58,0.085
20.18,140.74,0.085
20.20,140.91,0.085
20.22,141.07,0.084
20.23,141.24,0.084
20.25,141.41,0.084
20.27,141.57,0.084
20.28,141.74,0.084
20.30,141.91,0.084
20.32,142.07,0.084
20.33,142.24,0.084
20.35,142.41,0.084
20.37,142.57,0.083
20.38,142.74,0.083
20.40,142.91,0.083
20.42,143.07,0.083
20.43,143.24,0.083
20.45,143.41,0.083
20.47,143.57,0.083
20.48,143.74,0.083
20.50,143.91,0.083
20.52,144.07,0.083
20.53,144.24,0.083
20.55,144.41,0.082
20.57,144.58,0.082
20.58,144.74,0.082
20.60,144.91,0.082
20.62,145.08,0.082
20.63,145.24,0.082
20.65,145.41,0.082
20.67,145.58,0.082
20.68,145.74,0.082
20.70,145.91,0.082
20.72,146.08,0.082
20.73,146.24,0.082
20.75,146.41,0.081
20.77,146.58,0.081
20.78,146.74,0.081
20.80,146.91,0.081
20.82,147.08,0.081
20.83,147.24,0.081
20.85,147.41,0.081
20.87,147.58,0.081
20.88,147.75,0.081
20.90,147.91,0.081
20.92,148.08,0.081
20.93,148.25,0.080
20.95,148.41,0.080
20.97,148.58,0.080
20.98,148.75,0.080
21.00,148.91,0.080
21.02,149.08,0.080
21.03,149.25,0.080
21.05,149.41,0.080
21.07,149.58,0.080
21.08,149.75,0.080
21.10,149.92,0.080
21.12,150.08,0.079
21.13,150.25,0.079
21.15,150.42,0.079
21.17,150.58,0.079
21.18,150.75,0.079
21.20,150.92,0.079
21.22,151.08,0.079
21.23,151.25,0.079
21.25,151.42,0.079
21.27,151.59,0.079
21.28,151.75,0.079
21.30,151.92,0.079
21.32,152.09,0.078
21.33,152.25,0.078
21.35,152.42,0.078
21.37,152.59,0.078
21.38,152.75,0.078
21.40,152.92,0.078
21.42,153.09,0.078
21.43,153.25,0.078
21.45,153.42,0.078
21.47,153.59,0.077
21.48,153.76,0.077
21.50,153.92,0.077
21.52,154.09,0.077
21.53,154.26,0.077
21.55,154.42,0.077
21.57,154.59,0.077
21.58,154.76,0.077
21.60,154.92,0.077
21.62,155.09,0.076
21.63,155.26,0.076
21.65,155.43,0.076
21.67,155.59,0.076
21.68,155.76,0.076
21.70,155.93,0.076
21.72,156.09,0.076
21.73,156.26,0.076
21.75,156.43,0.076
21.77,156.59,0.075
21.78,156.76,0.075
21.80,156.93,0.075
21.82,157.10,0.075
21.83,157.26,0.075
21.85,157.43,0.075
21.87,157.60,0.075
21.88,157.76,0.074
21.90,157.93,0.074
21.92,158.10,0.074
21.93,158.27,0.074
21.95,158.43,0.074
21.97,158.60,0.074
21.98,158.77,0.074
22.00,158.93,0.073
22.02,159.10,0.073
22.03,159.27,0.073
22.05,159.44,0.073
22.07,159.60,0.073
22.08,159.77,0.073
22.10,159.94,0.072
22.12,160.10,0.072
22.13,160.27,0.072
22.15,160.44,0.072
22.17,160.61,0.072
22.18,160.77,0.072
22.20,160.94,0.072
22.22,161.11,0.071
22.23,161.28,0.071
22.25,161.44,0.071
22.27,161.61,0.070
22.28,161.78,0.070
22.30,161.94,0.070
22.32,162.11,0.070
22.33,162.28,0.070
22.35,162.44,0.069
22.37,162.61,0.069
22.38,162.78,0.069
22.40,162.95,0.069
22.42,163.11,0.069
22.43,163.28,0.069
22.45,163.45,0.068
22.47,163.62,0.068
22.48,163.78,0.068
22.50,163.95,0.068
22.52,164.12,0.067
22.53,164.28,0.067
22.55,164.45,0.067
22.57,164.62,0.067
22.58,164.79,0.067
22.60,164.95,0.067
22.62,165.12,0.066
22.63,165.29,0.066
22.65,165.46,0.066
22.67,165.62,0.066
22.68,165.79,0.066
22.70,165.96,0.065
22.72,166.12,0.065
22.73,166.29,0.065
22.75,166.46,0.065
22.77,166.62,0.065
22.78,166.79,0.065
22.80,166.96,0.065
22.82,167.12,0.065
22.83,167.29,0.064
22.85,167.46,0.064
22.87,167.63,0.064
22.88,167.79,0.064
22.90,167.96,0.064
22.92,168.13,0.064
22.93,168.29,0.064
22.95,168.46,0.064
22.97,168.63,0.064
22.98,168.79,0.064
23.00,168.96,0.064
23.02,169.13,0.063
23.03,169.30,0.063
23.05,169.46,0.063
23.07,169.63,0.063
23.08,169.80,0.063
23.10,169.96,0.063
23.12,170.13,0.063
23.13,170.30,0.063
23.15,170.46,0.063
23.17,170.63,0.063
23.18,170.80,0.063
23.20,170.96,0.063
23.22,171.13,0.063
23.23,171.30,0.062
23.25,171.46,0.062
23.27,171.63,0.062
23.28,171.80,0.062
23.30,171.97,0.062
23.32,172.13,0.062
23.33,172.30,0.062
23.35,172.47,0.062
23.37,172.63,0.062
23.38,172.80,0.062
23.40,172.97,0.062
23.42,173.14,0.062
23.43,173.30,0.062
23.45,173.47,0.062
23.47,173.64,0.062
23.48,173.80,0.062
23.50,173.97,0.061
23.52,174.14,0.061
23.53,174.31,0.061
23.55,174.47,0.061
23.57,174.64,0.061
23.58,174.81,0.061
23.60,174.97,0.061
23.62,175.14,0.061
23.63,175.31,0.061
23.65,175.47,0.061
23.67,175.64,0.061
23.68,175.81,0.061
23.70,175.97,0.061
23.72,176.14,0.061
23.73,176.31,0.061
23.75,176.47,0.061
23.77,176.64,0.061
23.78,176.81,0.061
23.80,176.97,0.061
23.82,177.14,0.060
23.83,177.31,0.060
23.85,177.48,0.060
23.87,177.64,0.060
23.88,177.81,0.060
23.90,177.98,0.060
23.92,178.14,0.060
23.93,178.31,0.060
23.95,178.48,
23.97,178.64,
23.98,178.81,
23.99,,

[step]
Ramp 10.00 °C/min to -60.00 °C
Time,Temperature,Heat Flow (Normalized)
min,°C,W/g
25.99,180.16,-0.001
26.01,180.16,-0.001
26.03,180.15,-0.001
26.04,180.14,-0.002
26.06,180.12,-0.003
26.08,180.09,-0.007
26.09,180.03,-0.011
26.11,179.95,-0.018
26.13,179.85,-0.024
26.14,179.73,-0.031
26.16,179.60,-0.036
26.18,179.46,-0.041
26.19,179.32,-0.045
26.21,179.17,-0.047
26.23,179.01,-0.050
26.24,178.86,-0.051
26.26,178.70,-0.052
26.28,178.54,-0.053
26.29,178.38,-0.054
26.31,178.22,-0.054
26.33,178.06,-0.055
26.34,177.89,-0.055
26.36,177.73,-0.055
26.38,177.56,-0.056
26.39,177.40,-0.056
26.41,177.23,-0.056
26.43,177.07,-0.056
26.44,176.91,-0.056
26.46,176.74,-0.056
26.48,176.57,-0.056
26.49,176.41,-0.056
26.51,176.24,-0.056
26.53,176.08,-0.057
26.54,175.91,-0.057
26.56,175.75,-0.057
26.58,175.58,-0.057
26.59,175.42,-0.057
26.61,175.25,-0.057
26.63,175.09,-0.057
26.64,174.92,-0.057
26.66,174.75,-0.057
26.68,174.59,-0.057
26.69,174.42,-0.057
26.71,174.26,-0.057
26.73,174.09,-0.057
26.74,173.93,-0.057
26.76,173.76,-0.057
26.78,173.60,-0.057
26.79,173.43,-0.057
26.81,173.26,-0.057
26.83,173.10,-0.057
26.84,172.93,-0.057
26.86,172.77,-0.057
26.88,172.60,-0.057
26.89,172.43,-0.057
26.91,172.27,-0.057
26.93,172.10,-0.057
26.94,171.93,-0.057
26.96,171.77,-0.057
26.98,171.60,-0.057
26.99,171.44,-0.057
27.01,171.27,-0.057
27.03,171.10,-0.057
27.04,170.94,-0.057
27.06,170.77,-0.057
27.08,170.61,-0.057
27.09,170.44,-0.058
27.11,170.27,-0.058
27.13,170.11,-0.058
27.14,169.94,-0.058
27.16,169.78,-0.058
27.18,169.61,-0.058
27.19,169.44,-0.058
27.21,169.28,-0.058
27.23,169.11,-0.058
27.24,168.94,-0.058
27.26,168.78,-0.058
27.28,168.61,-0.058
27.29,168.44,-0.058
27.31,168.28,-0.058
27.33,168.11,-0.058
27.34,167.94,-0.058
27.36,167.78,-0.058
27.38,167.61,-0.058
27.39,167.45,-0.058
27.41,167.28,-0.058
27.43,167.11,-0.058
27.44,166.95,-0.058
27.46,166.78,-0.058
27.48,166.61,-0.058
27.49,166.45,-0.058
27.51,166.28,-0.058
27.53,166.12,-0.058
27.54,165.95,-0.058
27.56,165.78,-0.058
27.58,165.62,-0.058
27.59,165.45,-0.058
27.61,165.28,-0.058
27.63,165.12,-0.058
27.64,164.95,-0.058
27.66,164.78,-0.058
27.68,164.62,-0.058
27.69,164.45,-0.058
27.71,164.28,-0.058
27.73,164.12,-0.058
27.74,163.95,-0.058
27.76,163.78,-0.058
27.78,163.62,-0.058
27.79,163.45,-0.058
27.81,163.28,-0.058
27.83,163.12,-0.058
27.84,162.95,-0.058
27.86,162.78,-0.058
27.88,162.62,-0.058
27.89,162.45,-0.058
27.91,162.28,-0.058
27.93,162.12,-0.058
27.94,161.95,-0.058
27.96,161.79,-0.058
27.98,161.62,-0.058
27.99,161.45,-0.058
28.01,161.29,-0.058
28.03,161.12,-0.058
28.04,160.95,-0.058
28.06,160.79,-0.058
28.08,160.62,-0.058
28.09,160.45,-0.058
28.11,160.29,-0.058
28.13,160.12,-0.058
28.14,159.95,-0.058
28.16,159.79,-0.058
28.18,159.62,-0.058
28.19,159.45,-0.058
28.21,159.29,-0.058
28.23,159.12,-0.058
28.24,158.95,-0.057
28.26,158.79,-0.057
28.28,158.62,-0.057
28.29,158.45,-0.057
28.31,158.29,-0.057
28.33,158.12,-0.057
28.34,157.95,-0.057
28.36,157.79,-0.057
28.38,157.62,-0.057
28.39,157.45,-0.057
28.41,157.29,-0.057
28.43,157.12,-0.057
28.44,156.95,-0.057
28.46,156.78,-0.057
28.48,156.62,-0.057
28.49,156.45,-0.057
28.51,156.28,-0.057
28.53,156.12,-0.057
28.54,155.95,-0.057
28.56,155.79,-0.057
28.58,155.62,-0.057
28.59,155.46,-0.057
28.61,155.29,-0.057
28.63,155.12,-0.057
28.64,154.96,-0.057
28.66,154.79,-0.057
28.68,154.62,-0.057
28.69,154.46,-0.057
28.71,154.29,-0.057
28.73,154.12,-0.057
28.74,153.96,-0.057
28.76,153.79,-0.057
28.78,153.62,-0.057
28.79,153.46,-0.057
28.81,153.29,-0.057
28.83,153.12,-0.057
28.84,152.96,-0.057
28.86,152.79,-0.057
28.88,152.62,-0.057
28.89,152.46,-0.057
28.91,152.29,-0.057
28.93,152.12,-0.057
28.94,151.96,-0.057
28.96,151.79,-0.057
28.98,151.62,-0.057
28.99,151.46,-0.057
29.01,151.29,-0.057
29.03,151.12,-0.057
29.04,150.96,-0.057
29.06,150.79,-0.057
29.08,150.62,-0.057
29.09,150.46,-0.057
29.11,150.29,-0.057
29.13,150.12,-0.057
29.14,149.96,-0.057
29.16,149.79,-0.057
29.18,149.62,-0.057
29.19,149.46,-0.057
29.21,149.29,-0.057
29.23,149.13,-0.057
29.24,148.96,-0.057
29.26,148.79,-0.057
29.28,148.62,-0.057
29.29,148.46,-0.057
29.31,148.29,-0.057
29.33,148.12,-0.057
29.34,147.96,-0.057
29.36,147.79,-0.057
29.38,147.63,-0.057
29.39,147.46,-0.057
29.41,147.29,-0.057
29.43,147.12,-0.057
29.44,146.96,-0.057
29.46,146.79,-0.057
29.48,146.63,-0.057
29.49,146.46,-0.057
29.51,146.29,-0.057
29.53,146.12,-0.057
29.54,145.96,-0.057
29.56,145.79,-0.057
29.58,145.62,-0.057
29.59,145.46,-0.057
29.61,145.29,-0.057
29.63,145.12,-0.057
29.64,144.96,-0.057
29.66,144.79,-0.057
29.68,144.63,-0.057
29.69,144.46,-0.057
29.71,144.29,-0.057
29.73,144.12,-0.057
29.74,143.96,-0.056
29.76,143.79,-0.056
29.78,143.62,-0.056
29.79,143.46,-0.056
29.81,143.29,-0.056
29.83,143.13,-0.056
29.84,142.96,-0.056
29.86,142.79,-0.056
29.88,142.62,-0.056
29.89,142.46,-0.056
29.91,142.29,-0.056
29.93,142.13,-0.056
29.94,141.96,-0.056
29.96,141.79,-0.056
29.98,141.62,-0.056
29.99,141.46,-0.056
30.01,141.29,-0.056
30.03,141.12,-0.056
30.04,140.96,-0.056
30.06,140.79,-0.056
30.08,140.62,-0.056
30.09,140.46,-0.056
30.11,140.29,-0.056
30.13,140.12,-0.056
30.14,139.96,-0.056
30.16,139.79,-0.056
30.18,139.63,-0.056
30.19,139.46,-0.056
30.21,139.29,-0.056
30.23,139.13,-0.056
30.24,138.96,-0.056
30.26,138.79,-0.055
30.28,138.63,-0.055
30.29,138.46,-0.055
30.31,138.29,-0.055
30.33,138.13,-0.055
30.34,137.96,-0.055
30.36,137.79,-0.055
30.38,137.63,-0.055
30.39,137.46,-0.055
30.41,137.29,-0.055
30.43,137.13,-0.055
30.44,136.96,-0.055
30.46,136.79,-0.055
30.48,136.62,-0.055
30.49,136.46,-0.055
30.51,136.29,-0.055
30.53,136.12,-0.055
30.54,135.96,-0.055
30.56,135.79,-0.055
30.58,135.62,-0.055
30.59,135.46,-0.055
30.61,135.29,-0.055
30.63,135.12,-0.055
30.64,134.96,-0.054
30.66,134.79,-0.054
30.68,134.62,-0.054
30.69,134.45,-0.054
30.71,134.29,-0.054
30.73,134.12,-0.054
30.74,133.95,-0.054
30.76,133.79,-0.054
30.78,133.62,-0.054
30.79,133.45,-0.054
30.81,133.29,-0.054
30.83,133.12,-0.054
30.84,132.95,-0.054
30.86,132.79,-0.054
30.88,132.62,-0.054
30.89,132.45,-0.054
30.91,132.29,-0.054
30.93,132.12,-0.053
30.94,131.95,-0.053
30.96,131.79,-0.053
30.98,131.62,-0.053
30.99,131.45,-0.053
31.01,131.29,-0.053
31.03,131.12,-0.053
31.04,130.95,-0.053
31.06,130.79,-0.053
31.08,130.62,-0.053
31.09,130.45,-0.053
31.11,130.29,-0.053
31.13,130.12,-0.053
31.14,129.95,-0.053
31.16,129.79,-0.053
31.18,129.62,-0.053
31.19,129.45,-0.053
31.21,129.29,-0.053
31.23,129.12,-0.053
31.24,128.95,-0.053
31.26,128.79,-0.053
31.28,128.62,-0.052
31.29,128.45,-0.052
31.31,128.29,-0.052
31.33,128.12,-0.052
31.34,127.95,-0.052
31.36,127.79,-0.052
31.38,127.62,-0.052
31.39,127.46,-0.052
31.41,127.29,-0.052
31.43,127.12,-0.052
31.44,126.96,-0.052
31.46,126.79,-0.052
31.48,126.62,-0.052
31.49,126.46,-0.052
31.51,126.29,-0.052
31.53,126.12,-0.052
31.54,125.95,-0.052
31.56,125.79,-0.052
31.58,125.62,-0.052
31.59,125.45,-0.052
31.61,125.29,-0.052
31.63,125.12,-0.051
31.64,124.95,-0.051
31.66,124.79,-0.051
31.68,124.62,-0.051
31.69,124.45,-0.051
31.71,124.29,-0.051
31.73,124.12,-0.051
31.74,123.95,-0.051
31.76,123.79,-0.051
31.78,123.62,-0.051
31.79,123.45,-0.051
31.81,123.29,-0.051
31.83,123.12,-0.051
31.84,122.95,-0.051
31.86,122.79,-0.051
31.88,122.62,-0.051
31.89,122.46,-0.051
31.91,122.29,-0.051
31.93,122.12,-0.051
31.94,121.96,-0.051
31.96,121.79,-0.051
31.98,121.62,-0.051
31.99,121.46,-0.051
32.01,121.29,-0.051
32.03,121.12,-0.051
32.04,120.95,-0.051
32.06,120.79,-0.050
32.08,120.62,-0.050
32.09,120.45,-0.050
32.11,120.29,-0.050
32.13,120.12,-0.050
32.14,119.95,-0.050
32.16,119.79,-0.050
32.18,119.62,-0.050
32.19,119.45,-0.050
32.21,119.29,-0.050
32.23,119.12,-0.050
32.24,118.95,-0.050
32.26,118.79,-0.050
32.28,118.62,-0.050
32.29,118.45,-0.050
32.31,118.29,-0.050
32.33,118.12,-0.050
32.34,117.95,-0.050
32.36,117.79,-0.050
32.38,117.62,-0.050
32.39,117.46,-0.050
32.41,117.29,-0.050
[...]
110.85,7.22,0.030
110.86,7.39,0.031
110.88,7.55,0.031
110.90,7.72,0.031
110.91,7.89,0.031
110.93,8.05,0.031
110.95,8.22,0.031
110.96,8.39,0.031
110.98,8.56,0.031
111.00,8.72,0.031
111.01,8.89,0.031
111.03,9.06,0.031
111.05,9.22,0.031
111.06,9.39,0.031
111.08,9.56,0.031
111.10,9.72,0.031
111.11,9.89,0.031
111.13,10.06,0.031
111.15,10.22,0.031
111.16,10.39,0.031
111.18,10.56,0.031
111.20,10.72,0.031
111.21,10.89,0.031
111.23,11.06,0.031
111.25,11.22,0.031
111.26,11.39,0.031
111.28,11.56,0.031
111.30,11.73,0.031
111.31,11.89,0.031
111.33,12.06,0.031
111.35,12.22,0.031
111.36,12.39,0.031
111.38,12.56,0.031
111.40,12.73,0.031
111.41,12.89,0.031
111.43,13.06,0.031
111.45,13.23,0.031
111.46,13.39,0.031
111.48,13.56,0.031
111.50,13.73,0.031
111.51,13.89,0.031
111.53,14.06,0.031
111.55,14.23,0.031
111.56,14.39,0.031
111.58,14.56,0.031
111.60,14.73,0.031
111.61,14.89,0.031
111.63,15.06,0.031
111.65,15.23,0.031
111.66,15.39,0.031
111.68,15.56,0.031
111.70,15.73,0.031
111.71,15.90,0.031
111.73,16.06,0.031
111.75,16.23,0.031
111.76,16.39,0.031
111.78,16.56,0.031
111.80,16.73,0.031
111.81,16.90,0.031
111.83,17.06,0.031
111.85,17.23,0.031
111.86,17.40,0.031
111.88,17.56,0.031
111.90,17.73,0.031
111.91,17.90,0.031
111.93,18.06,0.031
111.95,18.23,0.031
111.96,18.40,0.031
111.98,18.56,0.031
112.00,18.73,0.031
112.01,18.90,0.031
112.03,19.06,0.031
112.05,19.23,0.031
112.06,19.40,0.031
112.08,19.56,0.031
112.10,19.73,0.031
112.11,19.90,0.031
112.13,20.06,0.031
112.15,20.23,0.031
112.16,20.40,0.031
112.18,20.56,0.031
112.20,20.73,0.031
112.21,20.90,0.031
112.23,21.07,0.031
112.25,21.23,0.032
112.26,21.40,0.032
112.28,21.57,0.032
112.30,21.73,0.032
112.31,21.90,0.032
112.33,22.07,0.032
112.35,22.23,0.032
112.36,22.40,0.032
112.38,22.57,0.032
112.40,22.74,0.032
112.41,22.90,0.032
112.43,23.07,0.032
112.45,23.23,0.032
112.46,23.40,0.032
112.48,23.57,0.032
112.50,23.74,0.032
112.51,23.90,0.032
112.53,24.07,0.032
112.55,24.24,0.032
112.56,24.40,0.032
112.58,24.57,0.032
112.60,24.74,0.032
112.61,24.90,0.032
112.63,25.07,0.032
112.65,25.24,0.032
112.66,25.40,0.032
112.68,25.57,0.032
112.70,25.74,0.032
112.71,25.90,0.032
112.73,26.07,0.032
112.75,26.24,0.032
112.76,26.40,0.032
112.78,26.57,0.032
112.80,26.74,0.032
112.81,26.91,0.032
112.83,27.07,0.032
112.85,27.24,0.032
112.86,27.41,0.032
112.88,27.57,0.032
112.90,27.74,0.032
112.91,27.91,0.032
112.93,28.07,0.032
112.95,28.24,0.032
112.96,28.41,0.032
112.98,28.57,0.032
113.00,28.74,0.032
113.01,28.91,0.032
113.03,29.07,0.032
113.05,29.24,0.032
113.06,29.41,0.032
113.08,29.58,0.032
113.10,29.74,0.032
113.11,29.91,0.032
113.13,30.08,0.032
113.15,30.24,0.032
113.16,30.41,0.032
113.18,30.58,0.032
113.20,30.74,0.032
113.21,30.91,0.032
113.23,31.08,0.032
113.25,31.24,0.032
113.26,31.41,0.032
113.28,31.58,0.032
113.30,31.74,0.032
113.31,31.91,0.032
113.33,32.08,0.032
113.35,32.24,0.032
113.36,32.41,0.032
113.38,32.58,0.032
113.40,32.75,0.032
113.41,32.91,0.032
113.43,33.08,0.032
113.45,33.25,0.032
113.46,33.41,0.032
113.48,33.58,0.032
113.50,33.74,0.032
113.51,33.91,0.032
113.53,34.08,0.033
113.55,34.25,0.033
113.56,34.41,0.033
113.58,34.58,0.033
113.60,34.75,0.033
113.61,34.91,0.033
113.63,35.08,0.033
113.65,35.25,0.033
113.66,35.42,0.033
113.68,35.58,0.033
113.70,35.75,0.033
113.71,35.92,0.033
113.73,36.08,0.033
113.75,36.25,0.033
113.76,36.42,0.033
113.78,36.58,0.033
113.80,36.75,0.033
113.81,36.92,0.033
113.83,37.08,0.033
113.85,37.25,0.033
113.86,37.42,0.033
113.88,37.58,0.033
113.90,37.75,0.033
113.91,37.92,0.033
113.93,38.08,0.033
113.95,38.25,0.033
113.96,38.42,0.033
113.98,38.58,0.033
114.00,38.75,0.033
114.01,38.92,0.033
114.03,39.08,0.033
114.05,39.25,0.033
114.06,39.42,0.033
114.08,39.59,0.033
114.10,39.75,0.033
114.11,39.92,0.033
114.13,40.09,0.033
114.15,40.25,0.033
114.16,40.42,0.033
114.18,40.59,0.033
114.20,40.75,0.033
114.21,40.92,0.033
114.23,41.09,0.033
114.25,41.25,0.033
114.26,41.42,0.033
114.28,41.59,0.033
114.30,41.75,0.033
114.31,41.92,0.033
114.33,42.09,0.033
114.35,42.25,0.033
114.36,42.42,0.033
114.38,42.59,0.033
114.40,42.76,0.033
114.41,42.92,0.033
114.43,43.09,0.033
114.45,43.26,0.033
114.46,43.42,0.033
114.48,43.59,0.033
114.50,43.76,0.033
114.51,43.92,0.033
114.53,44.09,0.033
114.55,44.26,0.033
114.56,44.42,0.033
114.58,44.59,0.033
114.60,44.76,0.033
114.61,44.92,0.033
114.63,45.09,0.033
114.65,45.26,0.033
114.66,45.42,0.033
114.68,45.59,0.033
114.70,45.76,0.033
114.71,45.92,0.033
114.73,46.09,0.033
114.75,46.26,0.033
114.76,46.43,0.033
114.78,46.59,0.033
114.80,46.76,0.033
114.81,46.93,0.034
114.83,47.09,0.034
114.85,47.26,0.034
114.86,47.43,0.034
114.88,47.59,0.034
114.90,47.76,0.034
114.91,47.93,0.034
114.93,48.09,0.034
114.95,48.26,0.034
114.96,48.43,0.034
114.98,48.59,0.034
115.00,48.76,0.034
115.01,48.93,0.034
115.03,49.10,0.034
115.05,49.26,0.034
115.06,49.43,0.034
115.08,49.60,0.034
115.10,49.76,0.034
115.11,49.93,0.034
115.13,50.10,0.034
115.15,50.26,0.034
115.16,50.43,0.034
115.18,50.60,0.034
115.20,50.76,0.034
115.21,50.93,0.034
115.23,51.10,0.034
115.25,51.26,0.034
115.26,51.43,0.034
115.28,51.60,0.034
115.30,51.76,0.034
115.31,51.93,0.034
115.33,52.10,0.034
115.35,52.27,0.034
115.36,52.43,0.034
115.38,52.60,0.034
115.40,52.77,0.034
115.41,52.93,0.034
115.43,53.10,0.034
115.45,53.27,0.034
115.46,53.43,0.034
115.48,53.60,0.034
115.50,53.77,0.034
115.51,53.93,0.034
115.53,54.10,0.034
115.55,54.27,0.034
115.56,54.43,0.034
115.58,54.60,0.034
115.60,54.77,0.034
115.61,54.93,0.034
115.63,55.10,0.034
115.65,55.27,0.034
115.66,55.43,0.034
115.68,55.60,0.034
115.70,55.77,0.034
115.71,55.93,0.034
115.73,56.10,0.034
115.75,56.27,0.034
115.76,56.43,0.034
115.78,56.60,0.034
115.80,56.77,0.034
115.81,56.94,0.034
115.83,57.10,0.034
115.85,57.27,0.034
115.86,57.44,0.034
115.88,57.60,0.034
115.90,57.77,0.034
115.91,57.94,0.034
115.93,58.10,0.034
115.95,58.27,0.034
115.96,58.44,0.034
115.98,58.60,0.034
116.00,58.77,0.034
116.01,58.94,0.034
116.03,59.10,0.035
116.05,59.27,0.035
116.06,59.44,0.035
116.08,59.60,0.035
116.10,59.77,0.035
116.11,59.94,0.035
116.13,60.10,0.035
116.15,60.27,0.035
116.16,60.44,0.035
116.18,60.61,0.035
116.20,60.77,0.035
116.21,60.94,0.035
116.23,61.11,0.035
116.25,61.27,0.035
116.26,61.44,0.035
116.28,61.61,0.035
116.30,61.77,0.035
116.31,61.94,0.035
116.33,62.11,0.035
116.35,62.27,0.035
116.36,62.44,0.035
116.38,62.61,0.035
116.40,62.77,0.035
116.41,62.94,0.035
116.43,63.11,0.035
116.45,63.27,0.035
116.46,63.44,0.035
116.48,63.61,0.035
116.50,63.78,0.035
116.51,63.94,0.035
116.53,64.11,0.035
116.55,64.28,0.035
116.56,64.44,0.035
116.58,64.61,0.035
116.60,64.78,0.035
116.61,64.94,0.035
116.63,65.11,0.035
116.65,65.28,0.035
116.66,65.44,0.035
116.68,65.61,0.035
116.70,65.78,0.035
116.71,65.94,0.035
116.73,66.11,0.035
116.75,66.28,0.035
116.76,66.45,0.035
116.78,66.61,0.035
116.80,66.78,0.035
116.81,66.95,0.035
116.83,67.11,0.035
116.85,67.28,0.035
116.86,67.45,0.035
116.88,67.61,0.035
116.90,67.78,0.035
116.91,67.95,0.035
116.93,68.11,0.035
116.95,68.28,0.035
116.96,68.45,0.035
116.98,68.62,0.035
117.00,68.78,0.035
117.01,68.95,0.035
117.03,69.12,0.035
117.05,69.28,0.035
117.06,69.45,0.035
117.08,69.62,0.035
117.10,69.78,0.035
117.11,69.95,0.035
117.13,70.12,0.035
117.15,70.28,0.035
117.16,70.45,0.035
117.18,70.62,0.035
117.20,70.78,0.035
117.21,70.95,0.035
117.23,71.12,0.035
117.25,71.28,0.035
117.26,71.45,0.036
117.28,71.62,0.036
117.30,71.78,0.036
117.31,71.95,0.036
117.33,72.12,0.036
117.35,72.28,0.036
117.36,72.45,0.036
117.38,72.62,0.036
117.40,72.78,0.036
117.41,72.95,0.036
117.43,73.12,0.036
117.45,73.29,0.036
117.46,73.45,0.036
117.48,73.62,0.036
117.50,73.79,0.036
117.51,73.95,0.036
117.53,74.12,0.036
117.55,74.29,0.036
117.56,74.45,0.036
117.58,74.62,0.036
117.60,74.79,0.036
117.61,74.95,0.036
117.63,75.12,0.036
117.65,75.29,0.036
117.66,75.45,0.036
117.68,75.62,0.036
117.70,75.79,0.036
117.71,75.95,0.036
117.73,76.12,0.036
117.75,76.29,0.036
117.76,76.45,0.036
117.78,76.62,0.036
117.80,76.79,0.036
117.81,76.95,0.036
117.83,77.12,0.036
117.85,77.29,0.036
117.86,77.45,0.036
117.88,77.62,0.036
117.90,77.79,0.036
117.91,77.95,0.036
117.93,78.12,0.036
117.95,78.29,0.036
117.96,78.46,0.036
117.98,78.62,0.036
118.00,78.79,0.036
118.01,78.96,0.036
118.03,79.12,0.036
118.05,79.29,0.036
118.06,79.46,0.036
118.08,79.62,0.036
118.10,79.79,0.036
118.11,79.96,0.036
118.13,80.12,0.036
118.15,80.29,0.036
118.16,80.46,0.036
118.18,80.62,0.036
118.20,80.79,0.036
118.21,80.96,0.036
118.23,81.12,0.036
118.25,81.29,0.036
118.26,81.46,0.036
118.28,81.62,0.036
118.30,81.79,0.036
118.31,81.96,0.036
118.33,82.13,0.036
118.35,82.29,0.036
118.36,82.46,0.036
118.38,82.63,0.036
118.40,82.79,0.036
118.41,82.96,0.036
118.43,83.13,0.036
118.45,83.29,0.037
118.46,83.46,0.037
118.48,83.63,0.037
118.50,83.79,0.037
118.51,83.96,0.037
118.53,84.13,0.037
118.55,84.29,0.037
118.56,84.46,0.037
118.58,84.63,0.037
118.60,84.79,0.037
118.61,84.96,0.037
118.63,85.13,0.037
118.65,85.29,0.037
118.66,85.46,0.037
118.68,85.63,0.037
118.70,85.79,0.037
118.71,85.96,0.037
118.73,86.13,0.037
118.75,86.30,0.037
118.76,86.46,0.037
118.78,86.63,0.037
118.80,86.80,0.037
118.81,86.96,0.037
118.83,87.13,0.037
118.85,87.30,0.037
118.86,87.46,0.037
118.88,87.63,0.037
118.90,87.79,0.037
118.91,87.96,0.037
118.93,88.13,0.037
118.95,88.30,0.037
118.96,88.46,0.037
118.98,88.63,0.037
119.00,88.80,0.037
119.01,88.96,0.037
119.03,89.13,0.037
119.05,89.30,0.037
119.06,89.46,0.037
119.08,89.63,0.037
119.10,89.80,0.037
119.11,89.96,0.037
119.13,90.13,0.037
119.15,90.30,0.037
119.16,90.46,0.037
119.18,90.63,0.037
119.20,90.80,0.037
119.21,90.96,0.037
119.23,91.13,0.037
119.25,91.30,0.037
119.26,91.46,0.037
119.28,91.63,0.037
119.30,91.80,0.037
119.31,91.97,0.037
119.33,92.13,0.037
119.35,92.30,0.037
119.36,92.47,0.037
119.38,92.63,0.037
119.40,92.80,0.037
119.41,92.97,0.037
119.43,93.13,0.037
119.45,93.30,0.037
119.46,93.47,0.037
119.48,93.63,0.037
119.50,93.80,0.037
119.51,93.97,0.037
119.53,94.13,0.037
119.55,94.30,0.037
119.56,94.47,0.038
119.58,94.63,0.038
119.60,94.80,0.038
119.61,94.97,0.038
119.63,95.13,0.038
119.65,95.30,0.038
119.66,95.47,0.038
119.68,95.63,0.038
119.70,95.80,0.038
119.71,95.97,0.038
119.73,96.13,0.038
119.75,96.30,0.038
119.76,96.47,0.038
119.78,96.64,0.038
119.80,96.80,0.038
119.81,96.97,0.038
119.83,97.14,0.038
119.85,97.30,0.038
119.86,97.47,0.038
119.88,97.64,0.038
119.90,97.80,0.038
119.91,97.97,0.038
119.93,98.14,0.038
119.95,98.30,0.038
119.96,98.47,0.038
119.98,98.64,0.038
120.00,98.80,0.038
120.01,98.97,0.038
120.03,99.14,0.038
120.05,99.30,0.038
120.06,99.47,0.038
120.08,99.64,0.038
120.10,99.80,0.038
120.11,99.97,0.038
120.13,100.14,0.038
120.15,100.31,0.038
120.16,100.47,0.038
120.18,100.64,0.038
120.20,100.80,0.038
120.21,100.97,0.038
120.23,101.14,0.038
120.25,101.31,0.038
120.26,101.47,0.038
120.28,101.64,0.038
120.30,101.81,0.038
120.31,101.97,0.038
120.33,102.14,0.038
120.35,102.31,0.038
120.36,102.47,0.038
120.38,102.64,0.038
120.40,102.81,0.038
120.41,102.97,0.038
120.43,103.14,0.038
120.45,103.31,0.038
120.46,103.47,0.038
120.48,103.64,0.038
120.50,103.81,0.038
120.51,103.97,0.038
120.53,104.14,0.038
120.55,104.31,0.038
120.56,104.47,0.039
120.58,104.64,0.039
120.60,104.81,0.039
120.61,104.98,0.039
120.63,105.14,0.039
120.65,105.31,0.039
120.66,105.48,0.039
120.68,105.64,0.039
120.70,105.81,0.039
120.71,105.98,0.039
120.73,106.14,0.039
120.75,106.31,0.039
120.76,106.48,0.039
120.78,106.64,0.039
120.80,106.81,0.039
120.81,106.98,0.039
120.83,107.14,0.039
120.85,107.31,0.039
120.86,107.48,0.039
120.88,107.64,0.039
120.90,107.81,0.039
120.91,107.98,0.039
120.93,108.14,0.039
120.95,108.31,0.039
120.96,108.48,0.039
120.98,108.64,0.039
121.00,108.81,0.039
121.01,108.98,0.039
121.03,109.15,0.039
121.05,109.31,0.039
121.06,109.48,0.039
121.08,109.65,0.039
121.10,109.81,0.039
121.11,109.98,0.039
121.13,110.15,0.039
121.15,110.31,0.039
121.16,110.48,0.039
121.18,110.65,0.039
121.20,110.81,0.039
121.21,110.98,0.039
121.23,111.15,0.039
121.25,111.31,0.039
121.26,111.48,0.039
121.28,111.65,0.039
121.30,111.81,0.039
121.31,111.98,0.039
121.33,112.15,0.039
121.35,112.31,0.039
121.36,112.48,0.039
121.38,112.65,0.039
121.40,112.81,0.039
121.41,112.98,0.039
121.43,113.15,0.039
121.45,113.32,0.039
121.46,113.48,0.039
121.48,113.65,0.039
121.50,113.81,0.039
121.51,113.98,0.040
121.53,114.15,0.040
121.55,114.32,0.040
121.56,114.48,0.040
121.58,114.65,0.040
121.60,114.82,0.040
121.61,114.98,0.040
121.63,115.15,0.040
121.65,115.31,0.040
121.66,115.48,0.040
121.68,115.65,0.040
121.70,115.82,0.040
121.71,115.98,0.040
121.73,116.15,0.040
121.75,116.32,0.040
121.76,116.48,0.040
121.78,116.65,0.040
121.80,116.82,0.040
121.81,116.98,0.040
121.83,117.15,0.040
121.85,117.32,0.040
121.86,117.48,0.040
121.88,117.65,0.040
121.90,117.82,0.040
121.91,117.98,0.040
121.93,118.15,0.040
121.95,118.32,0.040
121.96,118.49,0.040
121.98,118.65,0.040
122.00,118.82,0.040
122.01,118.99,0.040
122.03,119.15,0.040
122.05,119.32,0.040
122.06,119.49,0.040
122.08,119.65,0.040
122.10,119.82,0.040
122.11,119.99,0.040
122.13,120.15,0.040
122.15,120.32,0.040
122.16,120.49,0.040
122.18,120.65,0.040
122.20,120.82,0.040
122.21,120.99,0.040
122.23,121.16,0.040
122.25,121.32,0.040
122.26,121.49,0.040
122.28,121.66,0.040
122.30,121.82,0.040
122.31,121.99,0.040
122.33,122.16,0.041
122.35,122.32,0.041
122.36,122.49,0.041
122.38,122.66,0.041
122.40,122.82,0.041
122.41,122.99,0.041
122.43,123.16,0.041
122.45,123.32,0.041
122.46,123.49,0.041
122.48,123.66,0.041
122.50,123.82,0.041
122.51,123.99,0.041
122.53,124.15,0.041
122.55,124.32,0.041
122.56,124.49,0.041
122.58,124.66,0.041
122.60,124.82,0.041
122.61,124.99,0.041
122.63,125.16,0.041
122.65,125.32,0.041
122.66,125.49,0.041
122.68,125.66,0.041
122.70,125.82,0.041
122.71,125.99,0.041
122.73,126.16,0.041
122.75,126.32,0.041
122.76,126.49,0.041
122.78,126.66,0.041
122.80,126.82,0.041
122.81,126.99,0.041
122.83,127.16,0.041
122.85,127.33,0.041
122.86,127.49,0.041
122.88,127.66,0.041
122.90,127.83,0.041
122.91,127.99,0.041
122.93,128.16,0.041
122.95,128.33,0.042
122.96,128.49,0.042
122.98,128.66,0.042
123.00,128.83,0.042
123.01,128.99,0.042
123.03,129.16,0.042
123.05,129.33,0.042
123.06,129.49,0.042
123.08,129.66,0.042
123.10,129.83,0.042
123.11,129.99,0.042
123.13,130.16,0.042
123.15,130.33,0.042
123.16,130.49,0.042
123.18,130.66,0.042
123.20,130.83,0.042
123.21,130.99,0.042
123.23,131.16,0.042
123.25,131.33,0.042
123.26,131.49,0.042
123.28,131.66,0.042
123.30,131.83,0.042
123.31,132.00,0.042
123.33,132.16,0.043
123.35,132.33,0.043
123.36,132.49,0.043
123.38,132.66,0.043
123.40,132.83,0.043
123.41,133.00,0.043
123.43,133.16,0.043
123.45,133.33,0.043
123.46,133.50,0.043
123.48,133.66,0.043
123.50,133.83,0.043
123.51,134.00,0.043
123.53,134.16,0.043
123.55,134.33,0.043
123.56,134.50,0.043
123.58,134.66,0.043
123.60,134.83,0.043
123.61,135.00,0.044
123.63,135.16,0.044
123.65,135.33,0.044
123.66,135.50,0.044
123.68,135.66,0.044
123.70,135.83,0.044
123.71,136.00,0.044
123.73,136.16,0.044
123.75,136.33,0.044
123.76,136.50,0.044
123.78,136.66,0.044
123.80,136.83,0.044
123.81,137.00,0.044
123.83,137.16,0.045
123.85,137.33,0.045
123.86,137.50,0.045
123.88,137.66,0.045
123.90,137.83,0.045
123.91,138.00,0.045
123.93,138.16,0.045
123.95,138.33,0.045
123.96,138.50,0.045
123.98,138.66,0.045
124.00,138.83,0.046
124.01,138.99,0.046
124.03,139.16,0.046
124.05,139.33,0.046
124.06,139.49,0.046
124.08,139.66,0.046
124.10,139.83,0.046
124.11,139.99,0.046
124.13,140.16,0.046
124.15,140.33,0.046
124.16,140.49,0.046
124.18,140.66,0.047
124.20,140.83,0.047
124.21,140.99,0.047
124.23,141.16,0.047
124.25,141.33,0.047
124.26,141.49,0.047
124.28,141.66,0.047
124.30,141.83,0.047
124.31,141.99,0.047
124.33,142.16,0.047
124.35,142.32,0.047
124.36,142.49,0.047
124.38,142.66,0.048
124.40,142.82,0.048
124.41,142.99,0.048
124.43,143.16,0.048
124.45,143.33,0.048
124.46,143.49,0.048
124.48,143.66,0.048
124.50,143.83,0.048
124.51,143.99,0.048
124.53,144.16,0.048
124.55,144.33,0.048
124.56,144.49,0.048
124.58,144.66,0.048
124.60,144.83,0.048
124.61,144.99,0.048
124.63,145.16,0.048
124.65,145.33,0.048
124.66,145.49,0.048
124.68,145.66,0.048
124.70,145.83,0.049
124.71,145.99,0.049
124.73,146.16,0.049
124.75,146.33,0.049
124.76,146.49,0.049
124.78,146.66,0.049
124.80,146.83,0.049
124.81,146.99,0.049
124.83,147.16,0.049
124.85,147.33,0.049
124.86,147.49,0.049
124.88,147.66,0.049
124.90,147.83,0.049
124.91,147.99,0.049
124.93,148.16,0.049
124.95,148.33,0.049
124.96,148.50,0.049
124.98,148.66,0.049
125.00,148.83,0.049
125.01,149.00,0.049
125.03,149.16,0.049
125.05,149.33,0.049
125.06,149.50,0.049
125.08,149.67,0.049
125.10,149.83,0.049
125.11,150.00,0.049
125.13,150.17,0.049
125.15,150.33,0.049
125.16,150.50,0.049
125.18,150.67,0.049
125.20,150.83,0.049
125.21,151.00,0.049
125.23,151.17,0.049
125.25,151.33,0.049
125.26,151.50,0.049
125.28,151.67,0.049
125.30,151.83,0.049
125.31,152.00,0.049
125.33,152.16,0.049
125.35,152.33,0.049
125.36,152.50,0.049
125.38,152.67,0.049
125.40,152.83,0.049
125.41,153.00,0.049
125.43,153.17,0.049
125.45,153.33,0.049
125.46,153.50,0.049
125.48,153.67,0.049
125.50,153.83,0.049
125.51,154.00,0.049
125.53,154.17,0.049
125.55,154.33,0.049
125.56,154.50,0.049
125.58,154.67,0.049
125.60,154.83,0.049
125.61,155.00,0.049
125.63,155.17,0.049
125.65,155.33,0.049
125.66,155.50,0.049
125.68,155.67,0.049
125.70,155.83,0.049
125.71,156.00,0.049
125.73,156.17,0.049
125.75,156.34,0.049
125.76,156.50,0.049
125.78,156.67,0.049
125.80,156.84,0.049
125.81,157.00,0.049
125.83,157.17,0.049
125.85,157.34,0.049
125.86,157.50,0.049
125.88,157.67,0.049
125.90,157.84,0.049
125.91,158.00,0.049
125.93,158.17,0.049
125.95,158.34,0.049
125.96,158.50,0.049
125.98,158.67,0.049
126.00,158.84,0.049
126.01,159.00,0.049
126.03,159.17,0.049
126.05,159.34,0.049
126.06,159.50,0.049
126.08,159.67,0.049
126.10,159.84,0.049
126.11,160.01,0.049
126.13,160.17,0.049
126.15,160.34,0.049
126.16,160.51,0.049
126.18,160.67,0.049
126.20,160.84,0.049
126.21,161.01,0.049
126.23,161.17,0.049
126.25,161.34,0.049
126.26,161.51,0.049
126.28,161.67,0.049
126.30,161.84,0.049
126.31,162.01,0.049
126.33,162.17,0.049
126.35,162.34,0.049
126.36,162.51,0.049
126.38,162.67,0.049
126.40,162.84,0.049
126.41,163.01,0.049
126.43,163.17,0.049
126.45,163.34,0.049
126.46,163.51,0.049
126.48,163.67,0.049
126.50,163.84,0.049
126.51,164.01,0.049
126.53,164.17,0.049
126.55,164.34,0.049
126.56,164.51,0.049
126.58,164.68,0.049
126.60,164.84,0.049
126.61,165.01,0.049
126.63,165.18,0.049
126.65,165.34,0.049
126.66,165.51,0.049
126.68,165.68,0.049
126.70,165.84,0.049
126.71,166.01,0.049
126.73,166.18,0.049
126.75,166.34,0.049
126.76,166.51,0.049
126.78,166.68,0.049
126.80,166.84,0.049
126.81,167.01,0.049
126.83,167.18,0.049
126.85,167.34,0.049
126.86,167.51,0.049
126.88,167.68,0.050
126.90,167.84,0.050
126.91,168.01,0.050
126.93,168.18,0.050
126.95,168.34,0.050
126.96,168.51,0.050
126.98,168.68,0.050
127.00,168.85,0.050
127.01,169.01,0.050
127.03,169.18,0.050
127.05,169.34,0.050
127.06,169.51,0.050
127.08,169.68,0.050
127.10,169.84,0.050
127.11,170.01,0.050
127.13,170.18,0.050
127.15,170.34,0.050
127.16,170.51,0.050
127.18,170.68,0.050
127.20,170.84,0.050
127.21,171.01,0.050
127.23,171.18,0.050
127.25,171.35,0.050
127.26,171.51,0.050
127.28,171.68,0.050
127.30,171.85,0.050
127.31,172.01,0.050
127.33,172.18,0.050
127.35,172.35,0.050
127.36,172.51,0.050
127.38,172.68,0.050
127.40,172.85,0.050
127.41,173.01,0.050
127.43,173.18,0.050
127.45,173.35,0.050
127.46,173.51,0.050
127.48,173.68,0.050
127.50,173.85,0.050
127.51,174.01,0.050
127.53,174.18,0.050
127.55,174.35,0.050
127.56,174.51,0.050
127.58,174.68,0.050
127.60,174.85,0.050
127.61,175.01,0.050
127.63,175.18,0.050
127.65,175.35,0.050
127.66,175.52,0.050
127.68,175.68,0.050
127.70,175.85,0.050
127.71,176.02,0.050
127.73,176.18,0.050
127.75,176.35,0.050
127.76,176.52,0.050
127.78,176.68,0.050
127.80,176.85,0.050
127.81,177.02,0.050
127.83,177.18,0.050
127.85,177.35,0.050
127.86,177.52,0.050
127.88,177.68,0.050
127.90,177.85,0.050
127.91,178.02,0.050
127.93,178.18,0.050
127.95,178.35,
127.96,178.52,
127.98,178.68,
128.00,,