File: DSC/Olivia/2025_07_17_1CBN_3PVP40kDa_MeOH_n60_160_5Cmin_x4.csv
Filename,2025_07_17_1CBN_3PVP40kDa_MeOH_n60_160_5Cmin_x4
Instrument name,DSC2A-00468 (192.168.1.100)
Operator,Gibbons
rundate,7/17/2025
Sample name,2025_07_17_1CBN_3PVP40kDa_MeOH_n60_160_5Cmin_x4
proceduresegments,Data Off ; Equilibrate -60.00 °C; Data On ; Ramp 5.00 °C/min to 160.00 °C; Data Off ; Isothermal 2.0 min; Data On ; Ramp 5.00 °C/min to -60.00 °C; Data Off ; Isothermal 2.0 min; Data On ; Ramp 5.00 °C/min to 160.00 °C; Data Off ; Isothermal 2.0 min; Data On ; Ramp 5.00 °C/min to -60.00 °C; Data Off ; Isothermal 2.0 min; Data On ; Ramp 5.00 °C/min to 160.00 °C; Data Off ; Isothermal 2.0 min; Data On ; Ramp 5.00 °C/min to -60.00 °C; Data Off ; Isothermal 2.0 min; Data On ; Ramp 5.00 °C/min to 30.00 °C
[File Parameters]
Run date,7/17/2025 7:17:05 PM
Trios version,5.1.1.46572
Original File Name,D:\DSC2500\Gibbons\2025_07_17_1CBN_3PVP40kDa_MeOH_n60_160_5Cmin_x4.tri
Current File Name,D:\DSC2500\Gibbons\2025_07_17_1CBN_3PVP40kDa_MeOH_n60_160_5Cmin_x4.tri
[Procedure]
Procedure Name,1CBN_3PVP40kDa_MeOH_n60_160_5Cmin_x4
Sample Name,2025_07_17_1CBN_3PVP40kDa_MeOH_n60_160_5Cmin_x4
Sample Mass,7.21 mg
Reference Sample Mass,0 mg
Pan Mass,55.98 mg
Pan Number,23
Reference Pan Mass,56.03 mg
Reference Pan Number,10
Pan Type,Tzero Aluminum Hermetic
Comments,DSC Consumables Al Hermetically Sealed Pan. A2 Tray (Google Sheet: DSC_Samples_A2_Tray_July2025).
Project Name,Pharmaceuticals - Cannabinoids
Operator,Gibbons
Test,Custom
Unload Max Temperature,30
Unload Min Temperature,30
Load Max Temperature,30
Load Min Temperature,30
Stop on Gas Flow Error,Yes
[Signal List]
Signal #1,Time (min)
Signal #2,Temperature (°C)
Signal #3,Heat Flow (mW)
Signal #4,Delta T (µV)
Signal #5,Delta Tzero (µV)
Signal #6,Tzero Temperature (°C)
Signal #7,Cell Purge (mL/min)
Signal #8,Heater Temp (°C)
Signal #9,Power Delivered (W)
Signal #10,Reference Junction Temperature (°C)
Signal #11,Flange Temperature (°C)
Signal #12,Heat Flow Phase (rad)
Signal #13,Total Heat Capacity (J/°C)
Signal #14,Heat Capacity (J/°C)
[Configuration]
Company Name,ASU
Instrument Name,DSC2A-00468
Instrument Type,DSC2500
Serial Number,DSC2A-00468
IP,192.168.1.100
Location of Instrument,MRRC
DisplayType,Unknown
Sample Interval ,0.1 s/pt
Selected Heat Flow,T4P
Exotherm Direction,Down
Cell Serial,DRC2-00792
Lid Type,Standard
Cooler,RCS 90
Leave Cooler on at End of Sequence,On
Gas 2,Nitrogen
Gas Selected,Channel 1
Flow Rate,50 mL/min
Secondary Purge,On
Licensed Heat Flow,Heat Flow T4P
Modulation Licensed,Yes
[Versions]
Common IDD Version,1
Cortex Version,VER 2.10.2.31
Driver,5.0.0.6
GDM Version,1.0.3.3
TouchscreenVersion,1.0.0.16145
FEP Version,1.2.1.21
FEP Bootloader,2.0.0.5
AutoSampler Version,2.1.1.26
Auto Sampler Bootloader,2.0.0.5
FCM Version,1.1.0.3
FCM Bootloader,2.0.0.5
[Experiment Logs]
Experiment Log Entry # 1,Data On set to 0
Experiment Log Entry # 3,Equilibrate Segment -60 (C) Started
Experiment Log Entry # 5,Data On set to 1
Experiment Log Entry # 7,Ramp Segment 5 C/min to 160 Started
Experiment Log Entry # 9,Auto sampler has detected that GDM has gone offline
Experiment Log Entry # 11,Data On set to 0
Experiment Log Entry # 13,Isothermal Segment 2 min started
Experiment Log Entry # 15,Data On set to 1
Experiment Log Entry # 17,Ramp Segment 5 C/min to -60 Started
Experiment Log Entry # 19,Data On set to 0
Experiment Log Entry # 21,Isothermal Segment 2 min started
Experiment Log Entry # 23,Data On set to 1
Experiment Log Entry # 25,Ramp Segment 5 C/min to 160 Started
Experiment Log Entry # 27,Data On set to 0
Experiment Log Entry # 29,Isothermal Segment 2 min started
Experiment Log Entry # 31,Data On set to 1
Experiment Log Entry # 33,Ramp Segment 5 C/min to -60 Started
Experiment Log Entry # 35,Data On set to 0
Experiment Log Entry # 37,Isothermal Segment 2 min started
Experiment Log Entry # 39,Data On set to 1
Experiment Log Entry # 41,Ramp Segment 5 C/min to 160 Started
Experiment Log Entry # 43,Data On set to 0
Experiment Log Entry # 45,Isothermal Segment 2 min started
Experiment Log Entry # 47,Data On set to 1
Experiment Log Entry # 49,Ramp Segment 5 C/min to -60 Started
Experiment Log Entry # 51,Data On set to 0
Experiment Log Entry # 53,Isothermal Segment 2 min started
Experiment Log Entry # 55,Data On set to 1
Experiment Log Entry # 57,Ramp Segment 5 C/min to 30 Started
[Method Log]
Method Log Entry # 1,Data Off
Method Log Entry # 2,Equilibrate -60 °C
Method Log Entry # 3,Data On
Method Log Entry # 4,(Ramp 400658) Ramp 5 °C/minute to 160 °C
Method Log Entry # 5,Data Off
Method Log Entry # 6,Isothermal 2 minutes
Method Log Entry # 7,Data On
Method Log Entry # 8,(Ramp 400662) Ramp 5 °C/minute to -60 °C
Method Log Entry # 9,Data Off
Method Log Entry # 10,Isothermal 2 minutes
Method Log Entry # 11,Data On
Method Log Entry # 12,(Ramp 400666) Ramp 5 °C/minute to 160 °C
Method Log Entry # 13,Data Off
Method Log Entry # 14,Isothermal 2 minutes
Method Log Entry # 15,Data On
Method Log Entry # 16,(Ramp 400670) Ramp 5 °C/minute to -60 °C
Method Log Entry # 17,Data Off
Method Log Entry # 18,Isothermal 2 minutes
Method Log Entry # 19,Data On
Method Log Entry # 20,(Ramp 400674) Ramp 5 °C/minute to 160 °C
Method Log Entry # 21,Data Off
Method Log Entry # 22,Isothermal 2 minutes
Method Log Entry # 23,Data On
Method Log Entry # 24,(Ramp 400678) Ramp 5 °C/minute to -60 °C
Method Log Entry # 25,Data Off
Method Log Entry # 26,Isothermal 2 minutes
Method Log Entry # 27,Data On
Method Log Entry # 28,(Ramp 400682) Ramp 5 °C/minute to 30 °C
Cell Serial,DRC2-00792
[T1 Calibration]
Slope,-0.008529666
Offset,9.636258
Initial Temperature,98.23
GUID,f8bfdadc-4977-4fdf-ba6d-0ba9134940c3
[TZero Calibration]
Date Applied,11/29/2022 4:06:13 PM
Description,From -89.059 °C to 396.009 °C at 20.000°C/min
Gas Type,Nitrogen
Pan Type,None
Source Files 1,C:\Users\yargerlab\Desktop\DSC Data\General\TZero_calibration_11_29_22_2nd(2).tri
Source Files 2,C:\Users\yargerlab\Desktop\DSC Data\General\TZero_calibration_11_29_22_2nd(3).tri
Delta T Offset,13.05235
Delta T Slope,-0.007271007
Delta T0 Offset,-13.69128
Delta T0 Slope,0.06063341
[Temperature Calibration]
Date Applied,11/29/2022 7:12:28 PM
Description,From 106.590 °C to 186.590 °C at 10.000°C/min
Gas Type,Nitrogen
Pan Type,Tzero Aluminum Hermetic
Source Files 1,C:\Users\yargerlab\Desktop\DSC Data\General\Indium(6).tri
Measured 1,157.391
Known 1,156.598
[Cell Constant Calibration]
Date Applied,11/29/2022 7:12:29 PM
Description,From 106.590 °C to 186.590 °C at 10.000°C/min
Gas Type,Nitrogen
Pan Type,Tzero Aluminum Hermetic
Source Files 1,C:\Users\yargerlab\Desktop\DSC Data\General\Indium(6).tri
T4P KCell,1.006051
Onset Slope,63.26126 mW/°C
[Direct Cp Calibration]
Date Applied,11/30/2022 11:04:51 AM
Description,From -79.983 °C to 298.409 °C at 10.000°C/min
Gas Type,Nitrogen
Pan Type,Tzero Aluminum Hermetic
Source Files 1,C:\Users\yargerlab\Desktop\DSC Data\General\Sapphire_Heat_Capacity_11_30_22.tri
[Rev Cp Calibration]
Date Applied,11/30/2022 1:58:51 PM
Description,From -79.996 °C to 292.812 °C at 3.000°C/min
Gas Type,Nitrogen
Pan Type,Tzero Aluminum Hermetic
Source Files 1,C:\Users\yargerlab\Desktop\DSC Data\General\Sapphire_MDSC_Calibration_11_30_22.tri
[step]
Ramp 5.00 °C/min to 160.00 °C
Time,Temperature,Heat Flow (Normalized)
min,°C,W/g
0.00,-59.71,-0.051
0.03,-59.73,-0.048
0.06,-59.74,-0.040
0.09,-59.71,-0.034
0.12,-59.66,-0.025
0.15,-59.57,-0.009
0.18,-59.48,0.007
0.21,-59.36,0.022
0.24,-59.25,0.036
0.27,-59.12,0.045
0.30,-59.00,0.053
0.33,-58.86,0.059
0.36,-58.73,0.064
0.39,-58.59,0.069
0.42,-58.45,0.072
0.45,-58.31,0.075
0.48,-58.17,0.077
0.51,-58.02,0.079
0.54,-57.88,0.080
0.57,-57.74,0.081
0.60,-57.59,0.082
0.63,-57.44,0.082
0.66,-57.30,0.083
0.69,-57.15,0.083
0.72,-57.00,0.084
0.75,-56.86,0.085
0.78,-56.71,0.085
0.81,-56.56,0.085
0.84,-56.41,0.086
0.87,-56.26,0.086
0.90,-56.12,0.086
0.93,-55.97,0.087
0.96,-55.82,0.087
0.99,-55.67,0.087
1.02,-55.52,0.087
1.05,-55.37,0.088
1.08,-55.22,0.088
1.11,-55.07,0.088
1.14,-54.93,0.088
1.17,-54.78,0.088
1.20,-54.63,0.088
1.23,-54.48,0.088
1.26,-54.33,0.089
1.29,-54.18,0.089
1.32,-54.03,0.089
1.35,-53.88,0.089
1.38,-53.73,0.089
1.41,-53.58,0.089
1.44,-53.43,0.089
1.47,-53.28,0.089
1.50,-53.13,0.089
1.53,-52.98,0.089
1.56,-52.84,0.089
1.59,-52.68,0.089
1.62,-52.53,0.089
1.65,-52.39,0.089
1.68,-52.24,0.089
1.71,-52.09,0.089
1.74,-51.94,0.089
1.77,-51.79,0.089
1.80,-51.64,0.089
1.83,-51.49,0.089
1.86,-51.34,0.089
1.89,-51.19,0.089
1.92,-51.04,0.089
1.95,-50.89,0.090
1.98,-50.74,0.090
2.01,-50.59,0.090
2.04,-50.44,0.090
2.07,-50.29,0.090
2.10,-50.14,0.090
2.13,-49.99,0.090
2.16,-49.84,0.090
2.19,-49.69,0.090
2.22,-49.54,0.090
2.25,-49.39,0.090
2.28,-49.24,0.090
2.31,-49.09,0.090
2.34,-48.94,0.090
2.37,-48.79,0.090
2.40,-48.64,0.090
2.43,-48.49,0.090
2.46,-48.34,0.090
2.49,-48.19,0.090
2.52,-48.04,0.090
2.55,-47.89,0.090
2.58,-47.74,0.090
2.61,-47.59,0.090
2.64,-47.44,0.090
2.67,-47.29,0.090
2.70,-47.14,0.090
2.73,-46.99,0.090
2.76,-46.84,0.090
2.79,-46.69,0.090
2.82,-46.54,0.090
2.85,-46.39,0.090
2.88,-46.24,0.090
2.91,-46.09,0.090
2.94,-45.94,0.090
2.97,-45.79,0.090
3.00,-45.64,0.090
3.03,-45.49,0.090
3.06,-45.34,0.090
3.09,-45.19,0.090
3.12,-45.04,0.090
3.15,-44.89,0.090
3.18,-44.74,0.090
3.21,-44.59,0.090
3.24,-44.44,0.090
3.27,-44.29,0.090
3.30,-44.14,0.091
3.33,-43.99,0.091
3.36,-43.84,0.091
3.39,-43.69,0.091
3.42,-43.54,0.091
3.45,-43.39,0.091
3.48,-43.24,0.091
3.51,-43.09,0.091
3.54,-42.94,0.091
3.57,-42.79,0.091
3.60,-42.64,0.091
3.63,-42.49,0.091
3.66,-42.34,0.091
3.69,-42.19,0.091
3.72,-42.04,0.091
3.75,-41.89,0.091
3.78,-41.74,0.091
3.81,-41.59,0.091
3.84,-41.44,0.091
3.87,-41.29,0.091
3.90,-41.14,0.091
3.93,-40.99,0.091
3.96,-40.84,0.091
3.99,-40.69,0.091
4.02,-40.54,0.091
4.05,-40.39,0.091
4.08,-40.24,0.091
4.11,-40.09,0.091
4.14,-39.94,0.091
4.17,-39.79,0.091
4.20,-39.64,0.091
4.23,-39.49,0.091
4.26,-39.34,0.091
4.29,-39.19,0.091
4.32,-39.04,0.091
4.35,-38.89,0.092
4.38,-38.74,0.092
4.41,-38.59,0.092
4.44,-38.44,0.092
4.47,-38.29,0.092
4.50,-38.14,0.092
4.53,-37.99,0.092
4.56,-37.84,0.092
4.59,-37.69,0.092
4.62,-37.54,0.092
4.65,-37.39,0.092
4.68,-37.24,0.092
4.71,-37.08,0.092
4.74,-36.93,0.092
4.77,-36.79,0.092
4.80,-36.63,0.092
4.83,-36.48,0.092
4.86,-36.33,0.092
4.89,-36.18,0.092
4.92,-36.03,0.092
4.95,-35.88,0.092
4.98,-35.73,0.092
5.01,-35.58,0.092
5.04,-35.43,0.092
5.07,-35.28,0.092
5.10,-35.13,0.092
5.13,-34.98,0.092
5.16,-34.83,0.092
5.19,-34.68,0.093
5.22,-34.53,0.093
5.25,-34.38,0.093
5.28,-34.23,0.093
5.31,-34.08,0.093
5.34,-33.93,0.093
5.37,-33.78,0.093
5.40,-33.63,0.093
5.43,-33.48,0.093
5.46,-33.33,0.093
5.49,-33.18,0.093
5.52,-33.03,0.093
5.55,-32.88,0.093
5.58,-32.73,0.093
5.61,-32.58,0.093
5.64,-32.43,0.093
5.67,-32.28,0.093
5.70,-32.13,0.093
5.73,-31.98,0.093
5.76,-31.83,0.093
5.79,-31.68,0.093
5.82,-31.53,0.093
5.85,-31.38,0.093
5.88,-31.23,0.093
5.91,-31.08,0.093
5.94,-30.93,0.093
5.97,-30.78,0.093
6.00,-30.63,0.093
6.03,-30.48,0.093
6.06,-30.33,0.094
6.09,-30.18,0.094
6.12,-30.03,0.094
6.15,-29.88,0.094
6.18,-29.72,0.094
6.21,-29.57,0.094
6.24,-29.43,0.094
6.27,-29.28,0.094
6.30,-29.12,0.094
6.33,-28.98,0.094
6.36,-28.82,0.094
6.39,-28.67,0.094
6.42,-28.52,0.094
6.45,-28.37,0.094
6.48,-28.22,0.094
6.51,-28.07,0.094
6.54,-27.92,0.094
6.57,-27.77,0.094
6.60,-27.62,0.094
6.63,-27.47,0.094
6.66,-27.32,0.094
6.69,-27.17,0.094
6.72,-27.02,0.094
6.75,-26.87,0.094
6.78,-26.72,0.094
6.81,-26.57,0.094
6.84,-26.43,0.095
6.87,-26.27,0.095
6.90,-26.12,0.095
6.93,-25.97,0.095
6.96,-25.82,0.095
6.99,-25.67,0.095
7.02,-25.52,0.095
7.05,-25.37,0.095
7.08,-25.22,0.095
7.11,-25.07,0.095
7.14,-24.92,0.095
7.17,-24.77,0.095
7.20,-24.62,0.095
7.23,-24.47,0.095
7.26,-24.32,0.095
7.29,-24.17,0.095
7.32,-24.02,0.095
7.35,-23.87,0.095
7.38,-23.72,0.095
7.41,-23.57,0.095
7.44,-23.42,0.095
7.47,-23.27,0.096
7.50,-23.12,0.096
7.53,-22.97,0.096
7.56,-22.82,0.096
7.59,-22.67,0.096
7.62,-22.52,0.096
7.65,-22.37,0.096
7.68,-22.22,0.096
7.71,-22.07,0.096
7.74,-21.92,0.096
7.77,-21.77,0.096
7.80,-21.62,0.096
7.83,-21.47,0.096
7.86,-21.32,0.096
7.89,-21.17,0.096
7.92,-21.02,0.096
7.95,-20.87,0.096
7.98,-20.72,0.096
8.01,-20.57,0.096
8.04,-20.42,0.096
8.07,-20.26,0.096
8.10,-20.12,0.096
8.13,-19.96,0.096
8.16,-19.81,0.096
8.19,-19.66,0.096
8.22,-19.51,0.097
8.25,-19.37,0.097
8.28,-19.22,0.097
8.31,-19.06,0.097
8.34,-18.92,0.097
8.37,-18.77,0.097
8.40,-18.61,0.097
8.43,-18.46,0.097
8.46,-18.31,0.097
8.49,-18.16,0.097
8.52,-18.01,0.097
8.55,-17.86,0.097
8.58,-17.71,0.097
8.61,-17.56,0.097
8.64,-17.41,0.097
8.67,-17.26,0.097
8.70,-17.11,0.097
8.73,-16.96,0.097
8.76,-16.81,0.097
8.79,-16.66,0.097
8.82,-16.51,0.098
8.85,-16.36,0.098
8.88,-16.21,0.098
8.91,-16.06,0.098
8.94,-15.91,0.098
8.97,-15.76,0.098
9.00,-15.61,0.098
9.03,-15.46,0.098
9.06,-15.31,0.098
9.09,-15.16,0.098
9.12,-15.01,0.098
9.15,-14.86,0.098
9.18,-14.71,0.098
9.21,-14.56,0.098
9.24,-14.41,0.098
9.27,-14.26,0.098
9.30,-14.11,0.098
9.33,-13.96,0.098
9.36,-13.81,0.098
9.39,-13.66,0.098
9.42,-13.51,0.098
9.45,-13.36,0.098
9.48,-13.21,0.099
9.51,-13.06,0.099
9.54,-12.91,0.099
9.57,-12.76,0.099
9.60,-12.61,0.099
9.63,-12.46,0.099
9.66,-12.31,0.099
9.69,-12.16,0.099
9.72,-12.01,0.099
9.75,-11.86,0.099
9.78,-11.71,0.099
9.81,-11.56,0.099
9.84,-11.41,0.099
9.87,-11.26,0.099
9.90,-11.11,0.099
9.93,-10.96,0.099
9.96,-10.81,0.099
9.99,-10.66,0.099
10.02,-10.51,0.099
10.05,-10.36,0.099
10.08,-10.21,0.099
10.11,-10.06,0.099
10.14,-9.91,0.099
10.17,-9.76,0.100
10.20,-9.60,0.100
10.23,-9.46,0.100
10.26,-9.31,0.100
10.29,-9.16,0.100
10.32,-9.01,0.100
10.35,-8.86,0.100
10.38,-8.71,0.100
10.41,-8.56,0.100
10.44,-8.41,0.100
10.47,-8.25,0.100
10.50,-8.10,0.100
10.53,-7.95,0.100
10.56,-7.80,0.100
10.59,-7.65,0.100
10.62,-7.50,0.100
10.65,-7.35,0.100
10.68,-7.21,0.101
10.71,-7.05,0.101
10.74,-6.90,0.101
10.77,-6.76,0.101
10.80,-6.61,0.101
10.83,-6.45,0.101
10.86,-6.30,0.101
10.89,-6.15,0.101
10.92,-6.00,0.101
10.95,-5.85,0.101
10.98,-5.70,0.101
11.01,-5.55,0.101
11.04,-5.40,0.101
11.07,-5.25,0.101
11.10,-5.10,0.101
11.13,-4.95,0.101
11.16,-4.80,0.101
11.19,-4.65,0.102
11.22,-4.50,0.102
11.25,-4.35,0.102
11.28,-4.20,0.102
11.31,-4.05,0.102
11.34,-3.90,0.102
11.37,-3.75,0.102
11.40,-3.60,0.102
11.43,-3.45,0.102
11.46,-3.30,0.102
11.49,-3.15,0.102
11.52,-3.00,0.102
11.55,-2.85,0.102
11.58,-2.70,0.102
11.61,-2.55,0.102
11.64,-2.40,0.102
11.67,-2.25,0.102
11.70,-2.10,0.102
11.73,-1.95,0.102
11.76,-1.80,0.102
11.79,-1.65,0.103
11.82,-1.50,0.103
11.85,-1.35,0.103
11.88,-1.20,0.103
11.91,-1.05,0.103
11.94,-0.90,0.103
11.97,-0.75,0.103
12.00,-0.60,0.103
12.03,-0.45,0.103
12.06,-0.30,0.103
12.09,-0.15,0.103
12.12,0.00,0.103
12.15,0.15,0.103
12.18,0.30,0.103
12.21,0.45,0.103
12.24,0.60,0.103
12.27,0.75,0.103
12.30,0.90,0.103
12.33,1.05,0.103
12.36,1.20,0.104
12.39,1.35,0.104
12.42,1.50,0.104
12.45,1.65,0.104
12.48,1.80,0.104
12.51,1.95,0.104
12.54,2.10,0.104
12.57,2.26,0.104
12.60,2.40,0.104
12.63,2.55,0.104
12.66,2.71,0.104
12.69,2.86,0.104
12.72,3.00,0.104
12.75,3.16,0.104
12.78,3.30,0.104
12.81,3.46,0.104
12.84,3.61,0.104
12.87,3.75,0.104
12.90,3.90,0.104
12.93,4.05,0.104
12.96,4.21,0.104
12.99,4.35,0.105
13.02,4.50,0.105
13.05,4.65,0.105
13.08,4.80,0.105
13.11,4.96,0.105
13.14,5.11,0.105
13.17,5.26,0.105
13.20,5.41,0.105
13.23,5.56,0.105
13.26,5.71,0.105
13.29,5.86,0.105
13.32,6.01,0.105
13.35,6.16,0.105
13.38,6.31,0.105
13.41,6.46,0.105
13.44,6.61,0.106
13.47,6.76,0.106
13.50,6.91,0.106
13.53,7.06,0.106
13.56,7.21,0.106
13.59,7.36,0.106
13.62,7.51,0.106
13.65,7.66,0.106
13.68,7.81,0.106
13.71,7.96,0.106
13.74,8.11,0.106
13.77,8.26,0.106
13.80,8.41,0.106
13.83,8.56,0.106
13.86,8.71,0.106
13.89,8.86,0.106
13.92,9.01,0.106
13.95,9.16,0.107
13.98,9.31,0.107
14.01,9.46,0.107
14.04,9.61,0.107
14.07,9.76,0.107
14.10,9.91,0.107
14.13,10.06,0.107
14.16,10.21,0.107
14.19,10.36,0.107
14.22,10.51,0.107
14.25,10.66,0.107
14.28,10.81,0.107
14.31,10.96,0.107
14.34,11.11,0.107
14.37,11.26,0.108
14.40,11.41,0.108
14.43,11.56,0.108
14.46,11.71,0.108
14.49,11.86,0.108
14.52,12.01,0.108
14.55,12.16,0.108
14.58,12.31,0.108
14.61,12.46,0.108
14.64,12.61,0.108
14.67,12.76,0.108
14.70,12.91,0.108
14.73,13.06,0.108
14.76,13.21,0.108
14.79,13.36,0.108
14.82,13.51,0.109
14.85,13.66,0.109
14.88,13.81,0.109
14.91,13.96,0.109
14.94,14.11,0.109
14.97,14.26,0.109
15.00,14.41,0.109
15.03,14.56,0.109
15.06,14.71,0.109
15.09,14.86,0.109
15.12,15.01,0.109
15.15,15.16,0.109
15.18,15.31,0.109
15.21,15.47,0.109
15.24,15.62,0.110
15.27,15.76,0.110
15.30,15.91,0.110
15.33,16.06,0.110
15.36,16.21,0.110
15.39,16.36,0.110
15.42,16.51,0.110
15.45,16.66,0.110
15.48,16.81,0.110
15.51,16.96,0.110
15.54,17.11,0.110
15.57,17.26,0.110
15.60,17.41,0.110
15.63,17.56,0.110
15.66,17.72,0.110
15.69,17.87,0.110
15.72,18.02,0.111
15.75,18.17,0.111
15.78,18.31,0.111
15.81,18.47,0.111
15.84,18.62,0.111
15.87,18.76,0.111
15.90,18.92,0.111
15.93,19.07,0.111
15.96,19.22,0.111
15.99,19.37,0.111
16.02,19.52,0.111
16.05,19.67,0.111
16.08,19.82,0.112
16.11,19.97,0.112
16.14,20.12,0.112
16.17,20.27,0.112
16.20,20.42,0.112
16.23,20.57,0.112
16.26,20.72,0.112
16.29,20.87,0.112
16.32,21.02,0.112
16.35,21.17,0.112
16.38,21.32,0.112
16.41,21.47,0.112
16.44,21.62,0.112
16.47,21.77,0.113
16.50,21.92,0.113
16.53,22.07,0.113
16.56,22.22,0.113
16.59,22.37,0.113
16.62,22.52,0.113
16.65,22.67,0.113
16.68,22.82,0.113
16.71,22.97,0.113
16.74,23.12,0.113
16.77,23.27,0.113
16.80,23.42,0.113
16.83,23.57,0.113
16.86,23.72,0.114
16.89,23.87,0.114
16.92,24.02,0.114
16.95,24.17,0.114
16.98,24.32,0.114
17.01,24.47,0.114
17.04,24.62,0.114
17.07,24.77,0.114
17.10,24.92,0.114
17.13,25.07,0.114
17.16,25.22,0.114
17.19,25.37,0.115
17.22,25.52,0.115
17.25,25.67,0.115
17.28,25.82,0.115
17.31,25.97,0.115
17.34,26.12,0.115
17.37,26.27,0.115
17.40,26.42,0.115
17.43,26.57,0.115
17.46,26.72,0.115
17.49,26.87,0.115
17.52,27.02,0.115
17.55,27.17,0.115
17.58,27.32,0.116
17.61,27.47,0.116
17.64,27.62,0.116
17.67,27.77,0.116
17.70,27.92,0.116
17.73,28.07,0.116
17.76,28.22,0.116
17.79,28.37,0.116
17.82,28.52,0.116
17.85,28.67,0.116
17.88,28.82,0.116
17.91,28.97,0.116
17.94,29.12,0.117
17.97,29.27,0.117
18.00,29.42,0.117
18.03,29.57,0.117
18.06,29.72,0.117
18.09,29.87,0.117
18.12,30.02,0.117
18.15,30.17,0.117
18.18,30.33,0.117
18.21,30.48,0.117
18.24,30.62,0.118
18.27,30.78,0.118
18.30,30.92,0.118
18.33,31.08,0.118
18.36,31.23,0.118
18.39,31.38,0.118
18.42,31.53,0.118
18.45,31.67,0.118
18.48,31.83,0.118
18.51,31.98,0.118
18.54,32.13,0.118
18.57,32.28,0.118
18.60,32.43,0.118
18.63,32.57,0.119
18.66,32.73,0.119
18.69,32.88,0.119
18.72,33.02,0.119
18.75,33.17,0.119
18.78,33.32,0.119
18.81,33.48,0.119
18.84,33.63,0.119
18.87,33.78,0.119
18.90,33.92,0.119
18.93,34.08,0.119
18.96,34.23,0.119
18.99,34.38,0.120
19.02,34.53,0.120
19.05,34.68,0.120
19.08,34.83,0.120
19.11,34.98,0.120
19.14,35.13,0.120
19.17,35.28,0.120
19.20,35.43,0.120
19.23,35.58,0.120
19.26,35.73,0.120
19.29,35.88,0.120
19.32,36.03,0.121
19.35,36.18,0.121
19.38,36.33,0.121
19.41,36.48,0.121
19.44,36.63,0.121
19.47,36.78,0.121
19.50,36.93,0.121
19.53,37.08,0.121
19.56,37.23,0.122
19.59,37.38,0.122
19.62,37.53,0.122
19.65,37.68,0.122
19.68,37.83,0.122
19.71,37.98,0.122
19.74,38.13,0.122
19.77,38.28,0.122
19.80,38.43,0.122
19.83,38.58,0.122
19.86,38.73,0.123
19.89,38.88,0.123
19.92,39.03,0.123
19.95,39.18,0.123
19.98,39.33,0.123
20.01,39.48,0.123
20.04,39.63,0.123
20.07,39.78,0.123
20.10,39.93,0.123
20.13,40.08,0.123
20.16,40.23,0.124
20.19,40.38,0.124
20.22,40.53,0.124
20.25,40.68,0.124
20.28,40.83,0.124
20.31,40.98,0.124
20.34,41.13,0.124
20.37,41.28,0.124
20.40,41.43,0.124
20.43,41.58,0.125
20.46,41.73,0.125
20.49,41.88,0.125
20.52,42.03,0.125
20.55,42.18,0.125
20.58,42.33,0.125
20.61,42.48,0.125
20.64,42.63,0.126
20.67,42.78,0.126
20.70,42.93,0.126
20.73,43.08,0.126
20.76,43.23,0.126
20.79,43.38,0.126
20.82,43.53,0.126
20.85,43.68,0.126
20.88,43.83,0.127
20.91,43.98,0.127
20.94,44.13,0.127
20.97,44.28,0.127
21.00,44.43,0.127
21.03,44.58,0.127
21.06,44.73,0.128
21.09,44.88,0.128
21.12,45.03,0.128
21.15,45.18,0.128
21.18,45.33,0.128
21.21,45.48,0.128
21.24,45.63,0.129
21.27,45.78,0.129
21.30,45.93,0.129
21.33,46.08,0.129
21.36,46.23,0.129
21.39,46.38,0.129
21.42,46.53,0.129
21.45,46.68,0.129
21.48,46.83,0.130
21.51,46.98,0.130
21.54,47.13,0.130
21.57,47.28,0.130
21.60,47.43,0.130
21.63,47.58,0.130
21.66,47.73,0.131
21.69,47.88,0.131
21.72,48.03,0.131
21.75,48.18,0.131
21.78,48.33,0.131
21.81,48.48,0.132
21.84,48.63,0.132
21.87,48.78,0.132
21.90,48.93,0.132
21.93,49.08,0.132
21.96,49.23,0.132
21.99,49.38,0.133
22.02,49.53,0.133
22.05,49.68,0.133
22.08,49.83,0.133
22.11,49.98,0.133
22.14,50.13,0.133
22.17,50.28,0.134
22.20,50.43,0.134
22.23,50.58,0.134
22.26,50.73,0.134
22.29,50.89,0.135
22.32,51.03,0.135
22.35,51.19,0.135
22.38,51.33,0.135
22.41,51.49,0.135
22.44,51.63,0.135
22.47,51.78,0.136
22.50,51.94,0.136
22.53,52.09,0.136
22.56,52.24,0.136
22.59,52.39,0.136
22.62,52.53,0.136
22.65,52.68,0.137
22.68,52.84,0.137
22.71,52.98,0.137
22.74,53.13,0.137
22.77,53.29,0.137
22.80,53.43,0.137
22.83,53.58,0.137
22.86,53.73,0.138
22.89,53.88,0.138
22.92,54.03,0.138
22.95,54.19,0.138
22.98,54.33,0.138
23.01,54.49,0.138
23.04,54.63,0.138
23.07,54.78,0.139
23.10,54.93,0.139
23.13,55.08,0.139
23.16,55.23,0.139
23.19,55.39,0.139
23.22,55.53,0.139
23.25,55.69,0.140
23.28,55.84,0.140
23.31,55.99,0.140
23.34,56.13,0.140
23.37,56.29,0.140
23.40,56.44,0.140
23.43,56.59,0.141
23.46,56.74,0.141
23.49,56.89,0.141
23.52,57.04,0.141
23.55,57.19,0.141
23.58,57.34,0.141
23.61,57.49,0.142
23.64,57.64,0.142
23.67,57.79,0.142
23.70,57.94,0.142
23.73,58.09,0.142
23.76,58.24,0.142
23.79,58.39,0.143
23.82,58.54,0.143
23.85,58.69,0.143
23.88,58.84,0.143
23.91,58.99,0.143
23.94,59.14,0.144
23.97,59.29,0.144
24.00,59.44,0.144
24.03,59.59,0.144
24.06,59.74,0.145
24.09,59.89,0.145
24.12,60.03,0.145
24.15,60.18,0.145
24.18,60.34,0.146
24.21,60.49,0.146
24.24,60.63,0.146
24.27,60.78,0.147
24.30,60.93,0.147
24.33,61.08,0.147
24.36,61.23,0.148
24.39,61.38,0.148
24.42,61.53,0.149
24.45,61.68,0.149
24.48,61.83,0.149
24.51,61.98,0.150
24.54,62.13,0.150
24.57,62.28,0.151
24.60,62.43,0.151
24.63,62.58,0.152
24.66,62.73,0.153
24.69,62.88,0.153
24.72,63.03,0.154
24.75,63.18,0.154
24.78,63.33,0.155
24.81,63.48,0.156
24.84,63.63,0.156
24.87,63.78,0.157
24.90,63.93,0.158
24.93,64.08,0.159
24.96,64.23,0.160
24.99,64.38,0.161
25.02,64.53,0.162
25.05,64.68,0.163
25.08,64.83,0.164
25.11,64.98,0.165
25.14,65.13,0.166
25.17,65.28,0.167
25.20,65.43,0.169
25.23,65.58,0.170
25.26,65.73,0.171
25.29,65.88,0.172
25.32,66.03,0.173
25.35,66.18,0.174
25.38,66.33,0.175
25.41,66.48,0.177
25.44,66.62,0.178
25.47,66.77,0.179
25.50,66.93,0.180
25.53,67.07,0.181
25.56,67.22,0.182
25.59,67.37,0.183
25.62,67.52,0.184
25.65,67.67,0.184
25.68,67.82,0.185
25.71,67.97,0.186
25.74,68.12,0.186
25.77,68.27,0.187
25.80,68.42,0.188
25.83,68.57,0.188
25.86,68.72,0.189
25.89,68.87,0.189
25.92,69.02,0.190
25.95,69.17,0.190
25.98,69.32,0.191
26.01,69.47,0.191
26.04,69.62,0.191
26.07,69.77,0.192
26.10,69.92,0.192
26.13,70.07,0.192
26.16,70.22,0.192
26.19,70.37,0.191
26.22,70.52,0.191
26.25,70.67,0.191
26.28,70.82,0.190
26.31,70.97,0.190
26.34,71.13,0.189
26.37,71.28,0.188
26.40,71.43,0.188
26.43,71.58,0.187
26.46,71.73,0.186
26.49,71.88,0.185
26.52,72.03,0.184
26.55,72.18,0.183
26.58,72.33,0.182
26.61,72.48,0.182
26.64,72.63,0.181
26.67,72.78,0.180
26.70,72.93,0.180
26.73,73.08,0.179
26.76,73.23,0.178
26.79,73.38,0.177
26.82,73.54,0.177
26.85,73.69,0.176
26.88,73.84,0.176
26.91,73.99,0.175
26.94,74.14,0.175
26.97,74.29,0.174
27.00,74.44,0.174
27.03,74.59,0.173
27.06,74.74,0.173
27.09,74.89,0.173
27.12,75.04,0.172
27.15,75.19,0.172
27.18,75.34,0.172
27.21,75.49,0.172
27.24,75.64,0.171
27.27,75.79,0.171
27.30,75.94,0.171
27.33,76.09,0.171
27.36,76.24,0.171
27.39,76.39,0.171
27.42,76.54,0.171
27.45,76.69,0.170
27.48,76.84,0.170
27.51,76.99,0.170
27.54,77.14,0.170
27.57,77.29,0.170
27.60,77.44,0.170
27.63,77.59,0.170
27.66,77.74,0.170
27.69,77.89,0.170
27.72,78.04,0.170
27.75,78.19,0.170
27.78,78.34,0.170
27.81,78.49,0.170
27.84,78.64,0.170
27.87,78.79,0.170
27.90,78.94,0.170
27.93,79.09,0.170
27.96,79.24,0.170
27.99,79.39,0.170
28.02,79.54,0.170
28.05,79.69,0.170
28.08,79.84,0.170
28.11,79.99,0.171
28.14,80.14,0.171
28.17,80.29,0.171
28.20,80.44,0.171
28.23,80.59,0.171
28.26,80.74,0.171
28.29,80.89,0.171
28.32,81.04,0.171
28.35,81.19,0.171
28.38,81.34,0.171
28.41,81.49,0.171
28.44,81.64,0.171
28.47,81.79,0.171
28.50,81.94,0.171
28.53,82.09,0.171
28.56,82.24,0.171
28.59,82.39,0.171
28.62,82.54,0.171
28.65,82.69,0.171
28.68,82.84,0.171
28.71,82.99,0.171
28.74,83.14,0.171
28.77,83.29,0.171
28.80,83.44,0.171
28.83,83.59,0.171
28.86,83.74,0.171
28.89,83.89,0.171
28.92,84.04,0.171
28.95,84.19,0.171
28.98,84.34,0.171
29.01,84.49,0.171
29.04,84.64,0.172
29.07,84.80,0.172
29.10,84.94,0.172
29.13,85.09,0.172
29.16,85.24,0.172
29.19,85.39,0.172
29.22,85.54,0.172
29.25,85.69,0.172
29.28,85.84,0.172
29.31,85.99,0.172
29.34,86.14,0.172
29.37,86.30,0.172
29.40,86.45,0.172
29.43,86.60,0.172
29.46,86.75,0.172
29.49,86.90,0.172
29.52,87.05,0.172
29.55,87.20,0.172
29.58,87.35,0.173
29.61,87.50,0.173
29.64,87.65,0.173
29.67,87.80,0.173
29.70,87.95,0.173
29.73,88.10,0.173
29.76,88.25,0.173
29.79,88.40,0.173
29.82,88.55,0.173
29.85,88.70,0.173
29.88,88.85,0.173
29.91,89.00,0.173
29.94,89.15,0.173
29.97,89.30,0.173
30.00,89.45,0.173
30.03,89.60,0.173
30.06,89.75,0.173
30.09,89.90,0.173
30.12,90.05,0.173
30.15,90.20,0.173
30.18,90.35,0.173
30.21,90.50,0.173
30.24,90.65,0.173
30.27,90.80,0.173
30.30,90.95,0.173
30.33,91.10,0.174
30.36,91.25,0.174
30.39,91.40,0.174
30.42,91.55,0.174
30.45,91.70,0.174
30.48,91.85,0.174
30.51,92.00,0.174
30.54,92.15,0.174
30.57,92.30,0.174
30.60,92.45,0.174
30.63,92.60,0.174
30.66,92.75,0.174
30.69,92.90,0.174
30.72,93.05,0.174
30.75,93.20,0.174
30.78,93.35,0.174
30.81,93.50,0.174
30.84,93.65,0.174
30.87,93.80,0.175
30.90,93.95,0.175
30.93,94.10,0.175
30.96,94.25,0.175
30.99,94.40,0.175
31.02,94.55,0.175
31.05,94.70,0.175
31.08,94.85,0.175
31.11,95.00,0.175
31.14,95.15,0.175
31.17,95.30,0.175
31.20,95.45,0.175
31.23,95.60,0.175
31.26,95.75,0.175
31.29,95.90,0.175
31.32,96.05,0.175
31.35,96.20,0.176
31.38,96.35,0.176
31.41,96.50,0.176
31.44,96.65,0.176
31.47,96.80,0.176
31.50,96.95,0.176
31.53,97.10,0.176
31.56,97.25,0.176
31.59,97.40,0.176
31.62,97.55,0.176
31.65,97.70,0.176
31.68,97.85,0.176
31.71,98.00,0.176
31.74,98.15,0.176
31.77,98.30,0.176
31.80,98.45,0.177
31.83,98.60,0.177
31.86,98.75,0.177
31.89,98.90,0.177
31.92,99.05,0.177
31.95,99.20,0.177
31.98,99.35,0.177
32.01,99.50,0.177
32.04,99.65,0.177
32.07,99.80,0.177
32.10,99.95,0.177
32.13,100.10,0.177
32.16,100.25,0.177
32.19,100.40,0.178
32.22,100.55,0.178
32.25,100.70,0.178
32.28,100.85,0.178
32.31,101.00,0.178
32.34,101.15,0.178
32.37,101.30,0.178
32.40,101.45,0.178
32.43,101.60,0.178
32.46,101.75,0.178
32.49,101.90,0.178
32.52,102.05,0.178
32.55,102.20,0.178
32.58,102.35,0.179
32.61,102.50,0.179
32.64,102.65,0.179
32.67,102.80,0.179
32.70,102.95,0.179
32.73,103.10,0.179
32.76,103.25,0.179
32.79,103.40,0.179
32.82,103.55,0.179
32.85,103.70,0.179
32.88,103.85,0.179
32.91,104.00,0.179
32.94,104.16,0.180
32.97,104.30,0.180
33.00,104.45,0.180
33.03,104.61,0.180
33.06,104.75,0.180
33.09,104.91,0.180
33.12,105.05,0.180
33.15,105.20,0.180
33.18,105.35,0.180
33.21,105.50,0.180
33.24,105.66,0.180
33.27,105.80,0.180
33.30,105.95,0.181
33.33,106.10,0.181
33.36,106.25,0.181
33.39,106.40,0.181
33.42,106.55,0.181
33.45,106.70,0.181
33.48,106.86,0.181
33.51,107.00,0.181
33.54,107.15,0.181
33.57,107.31,0.181
33.60,107.46,0.181
33.63,107.60,0.181
33.66,107.76,0.181
33.69,107.90,0.182
33.72,108.06,0.182
33.75,108.21,0.182
33.78,108.36,0.182
33.81,108.51,0.182
33.84,108.66,0.182
33.87,108.81,0.182
33.90,108.96,0.182
33.93,109.11,0.182
33.96,109.26,0.183
33.99,109.41,0.183
34.02,109.56,0.183
34.05,109.71,0.183
34.08,109.86,0.183
34.11,110.01,0.183
34.14,110.16,0.183
34.17,110.31,0.183
34.20,110.46,0.183
34.23,110.61,0.183
34.26,110.76,0.183
34.29,110.91,0.184
34.32,111.06,0.184
34.35,111.21,0.184
34.38,111.36,0.184
34.41,111.51,0.184
34.44,111.66,0.184
34.47,111.81,0.184
34.50,111.96,0.184
34.53,112.11,0.184
34.56,112.26,0.184
34.59,112.41,0.184
34.62,112.56,0.185
34.65,112.71,0.185
34.68,112.86,0.185
34.71,113.01,0.185
34.74,113.16,0.185
34.77,113.31,0.185
34.80,113.46,0.185
34.83,113.61,0.185
34.86,113.76,0.185
34.89,113.91,0.185
34.92,114.06,0.185
34.95,114.21,0.185
34.98,114.36,0.186
35.01,114.51,0.186
35.04,114.66,0.186
35.07,114.81,0.186
35.10,114.96,0.186
35.13,115.11,0.186
35.16,115.26,0.186
35.19,115.41,0.186
35.22,115.56,0.186
35.25,115.71,0.187
35.28,115.86,0.187
35.31,116.01,0.187
35.34,116.16,0.187
35.37,116.31,0.187
35.40,116.46,0.187
35.43,116.61,0.187
35.46,116.76,0.187
35.49,116.91,0.187
35.52,117.06,0.187
35.55,117.21,0.187
35.58,117.36,0.188
35.61,117.51,0.188
35.64,117.66,0.188
35.67,117.81,0.188
35.70,117.96,0.188
35.73,118.11,0.188
35.76,118.26,0.188
35.79,118.41,0.189
35.82,118.56,0.189
35.85,118.71,0.189
35.88,118.86,0.189
35.91,119.01,0.189
35.94,119.16,0.189
35.97,119.31,0.189
36.00,119.46,0.189
36.03,119.61,0.189
36.06,119.76,0.189
36.09,119.91,0.190
36.12,120.06,0.190
36.15,120.21,0.190
36.18,120.36,0.190
36.21,120.51,0.190
36.24,120.66,0.190
36.27,120.81,0.190
36.30,120.96,0.190
36.33,121.11,0.190
36.36,121.26,0.190
36.39,121.41,0.190
36.42,121.56,0.190
36.45,121.71,0.190
36.48,121.86,0.190
36.51,122.01,0.190
36.54,122.16,0.190
36.57,122.31,0.190
36.60,122.46,0.190
36.63,122.61,0.190
36.66,122.76,0.190
36.69,122.91,0.190
36.72,123.06,0.191
36.75,123.21,0.191
36.78,123.36,0.191
36.81,123.51,0.191
36.84,123.66,0.191
36.87,123.81,0.191
36.90,123.96,0.191
36.93,124.11,0.191
36.96,124.26,0.191
36.99,124.41,0.191
37.02,124.56,0.191
37.05,124.71,0.191
37.08,124.86,0.191
37.11,125.01,0.191
37.14,125.16,0.191
37.17,125.31,0.191
37.20,125.46,0.191
37.23,125.61,0.191
37.26,125.76,0.192
37.29,125.91,0.192
37.32,126.06,0.192
37.35,126.21,0.192
37.38,126.36,0.192
37.41,126.51,0.192
37.44,126.66,0.192
37.47,126.81,0.192
37.50,126.96,0.192
37.53,127.11,0.192
37.56,127.26,0.192
37.59,127.41,0.192
37.62,127.56,0.192
37.65,127.71,0.192
37.68,127.86,0.192
37.71,128.01,0.192
37.74,128.16,0.193
37.77,128.31,0.193
37.80,128.46,0.193
37.83,128.61,0.193
37.86,128.76,0.193
37.89,128.92,0.193
37.92,129.07,0.193
37.95,129.22,0.193
37.98,129.36,0.193
38.01,129.51,0.194
38.04,129.67,0.194
38.07,129.82,0.194
38.10,129.96,0.194
38.13,130.11,0.194
38.16,130.26,0.194
38.19,130.42,0.194
38.22,130.56,0.194
38.25,130.72,0.194
38.28,130.87,0.194
38.31,131.02,0.194
38.34,131.17,0.194
38.37,131.31,0.194
38.40,131.46,0.194
38.43,131.61,0.194
38.46,131.77,0.194
38.49,131.91,0.194
38.52,132.06,0.194
38.55,132.21,0.195
38.58,132.36,0.195
38.61,132.51,0.195
38.64,132.66,0.195
38.67,132.81,0.195
38.70,132.96,0.195
38.73,133.12,0.195
38.76,133.27,0.195
38.79,133.42,0.195
38.82,133.57,0.195
38.85,133.71,0.195
38.88,133.86,0.195
38.91,134.02,0.195
38.94,134.16,0.195
38.97,134.32,0.195
39.00,134.47,0.195
39.03,134.62,0.195
39.06,134.77,0.195
39.09,134.92,0.196
39.12,135.07,0.196
39.15,135.22,0.196
39.18,135.37,0.196
39.21,135.52,0.196
39.24,135.67,0.196
39.27,135.82,0.196
39.30,135.97,0.196
39.33,136.12,0.196
39.36,136.27,0.196
39.39,136.42,0.196
39.42,136.57,0.196
39.45,136.72,0.196
39.48,136.87,0.196
39.51,137.02,0.196
39.54,137.17,0.196
39.57,137.32,0.197
39.60,137.47,0.197
39.63,137.62,0.197
39.66,137.77,0.197
39.69,137.92,0.197
39.72,138.07,0.197
39.75,138.22,0.197
39.78,138.37,0.197
39.81,138.52,0.197
39.84,138.67,0.197
39.87,138.82,0.197
39.90,138.97,0.197
39.93,139.12,0.197
39.96,139.27,0.197
39.99,139.42,0.197
40.02,139.57,0.198
40.05,139.72,0.198
40.08,139.87,0.198
40.11,140.02,0.198
40.14,140.17,0.198
40.17,140.32,0.198
40.20,140.47,0.198
40.23,140.62,0.198
40.26,140.77,0.198
40.29,140.92,0.198
40.32,141.07,0.198
40.35,141.22,0.198
40.38,141.37,0.199
40.41,141.52,0.199
40.44,141.67,0.199
40.47,141.82,0.199
40.50,141.97,0.199
40.53,142.12,0.199
40.56,142.27,0.200
40.59,142.42,0.200
40.62,142.57,0.200
40.65,142.72,0.200
40.68,142.87,0.200
40.71,143.02,0.201
40.74,143.17,0.201
40.77,143.32,0.201
40.80,143.47,0.202
40.83,143.62,0.202
40.86,143.77,0.203
40.89,143.92,0.203
40.92,144.07,0.203
40.95,144.22,0.204
40.98,144.37,0.204
41.01,144.52,0.204
41.04,144.67,0.204
41.07,144.82,0.204
41.10,144.97,0.204
41.13,145.12,0.205
41.16,145.27,0.205
41.19,145.42,0.205
41.22,145.57,0.205
41.25,145.72,0.205
41.28,145.87,0.206
41.31,146.02,0.206
41.34,146.17,0.206
41.37,146.32,0.206
41.40,146.47,0.206
41.43,146.62,0.207
41.46,146.77,0.207
41.49,146.92,0.207
41.52,147.06,0.208
41.55,147.22,0.208
41.58,147.37,0.209
41.61,147.52,0.209
41.64,147.67,0.210
41.67,147.81,0.210
41.70,147.96,0.211
41.73,148.11,0.211
41.76,148.26,0.212
41.79,148.41,0.212
41.82,148.56,0.213
41.85,148.71,0.214
41.88,148.86,0.214
41.91,149.01,0.215
41.94,149.16,0.215
41.97,149.31,0.216
42.00,149.46,0.216
42.03,149.61,0.217
42.06,149.76,0.217
42.09,149.91,0.218
42.12,150.06,0.218
42.15,150.21,0.219
42.18,150.36,0.219
42.21,150.51,0.220
42.24,150.66,0.220
42.27,150.81,0.221
42.30,150.96,0.221
42.33,151.11,0.222
42.36,151.26,0.222
42.39,151.41,0.223
42.42,151.56,0.223
42.45,151.71,0.224
42.48,151.86,0.224
42.51,152.01,0.225
42.54,152.16,0.226
42.57,152.31,0.226
42.60,152.46,0.227
42.63,152.61,0.227
42.66,152.76,0.228
42.69,152.91,0.228
42.72,153.06,0.229
42.75,153.21,0.230
42.78,153.36,0.230
42.81,153.51,0.231
42.84,153.66,0.231
42.87,153.81,0.232
42.90,153.96,0.233
42.93,154.11,0.233
42.96,154.26,0.234
42.99,154.41,0.235
43.02,154.56,0.235
43.05,154.71,0.236
43.08,154.86,0.237
43.11,155.01,0.237
43.14,155.16,0.238
43.17,155.31,0.239
43.20,155.46,0.239
43.23,155.61,0.240
43.26,155.76,0.241
43.29,155.91,0.241
43.32,156.06,0.242
43.35,156.21,0.243
43.38,156.35,0.243
43.41,156.50,0.244
43.44,156.65,0.244
43.47,156.80,0.245
43.50,156.95,0.246
43.53,157.10,0.246
43.56,157.25,0.247
43.59,157.40,0.247
43.62,157.55,0.248
43.65,157.70,0.249
43.68,157.85,0.250
43.71,158.00,0.251
43.74,158.15,0.252
43.77,158.30,0.253
43.80,158.45,0.253
43.83,158.60,0.254
43.86,158.75,0.255
43.89,158.90,0.256
43.92,159.05,0.257
43.95,159.20,
43.98,,
43.98,,

[step]
Ramp 5.00 °C/min to -60.00 °C
Time,Temperature,Heat Flow (Normalized)
min,°C,W/g
45.99,160.12,-0.009
46.01,160.12,-0.009
46.04,160.11,-0.010
46.08,160.08,-0.021
46.11,160.03,-0.047
46.14,159.95,-0.082
46.16,159.85,-0.120
46.19,159.74,-0.150
46.23,159.62,-0.173
46.26,159.49,-0.190
46.29,159.36,-0.201
46.31,159.22,-0.212
46.34,159.08,-0.220
46.38,158.94,-0.226
46.41,158.80,-0.231
46.44,158.66,-0.235
46.46,158.51,-0.238
46.49,158.37,-0.240
46.53,158.22,-0.242
46.56,158.07,-0.244
46.59,157.92,-0.245
46.61,157.78,-0.246
46.64,157.63,-0.247
46.68,157.48,-0.248
46.71,157.33,-0.248
46.74,157.18,-0.249
46.76,157.03,-0.249
46.79,156.89,-0.250
46.83,156.74,-0.250
46.86,156.59,-0.250
46.89,156.44,-0.251
46.91,156.29,-0.251
46.94,156.14,-0.252
46.98,155.99,-0.252
47.01,155.84,-0.252
47.04,155.69,-0.253
47.06,155.54,-0.253
47.09,155.40,-0.253
47.13,155.25,-0.253
47.16,155.10,-0.254
47.19,154.95,-0.254
47.21,154.80,-0.254
47.24,154.65,-0.254
47.28,154.50,-0.254
47.31,154.35,-0.255
47.34,154.20,-0.255
47.36,154.05,-0.255
47.39,153.90,-0.255
47.43,153.75,-0.255
47.46,153.60,-0.255
47.49,153.45,-0.255
47.51,153.30,-0.255
47.54,153.15,-0.255
47.58,153.00,-0.255
47.61,152.85,-0.255
47.64,152.70,-0.256
47.66,152.55,-0.256
47.69,152.40,-0.256
47.73,152.25,-0.256
47.76,152.10,-0.256
47.79,151.95,-0.256
47.81,151.80,-0.256
47.84,151.65,-0.256
47.88,151.50,-0.256
47.91,151.35,-0.256
47.94,151.20,-0.256
47.96,151.05,-0.256
47.99,150.91,-0.255
48.03,150.75,-0.255
48.06,150.61,-0.255
48.09,150.46,-0.255
48.11,150.31,-0.255
48.14,150.15,-0.255
48.18,150.00,-0.255
48.21,149.85,-0.255
48.24,149.70,-0.255
48.26,149.56,-0.255
48.29,149.41,-0.255
48.33,149.26,-0.255
48.36,149.11,-0.255
48.39,148.96,-0.255
48.41,148.81,-0.255
48.44,148.66,-0.255
48.48,148.51,-0.255
48.51,148.36,-0.255
48.54,148.21,-0.254
48.56,148.06,-0.254
48.59,147.91,-0.254
48.63,147.76,-0.254
48.66,147.61,-0.254
48.69,147.46,-0.254
48.71,147.31,-0.254
48.74,147.16,-0.254
48.78,147.01,-0.254
48.81,146.86,-0.254
48.84,146.71,-0.254
48.86,146.56,-0.254
48.89,146.41,-0.254
48.93,146.26,-0.254
48.96,146.11,-0.254
48.99,145.96,-0.253
49.01,145.81,-0.254
49.04,145.66,-0.253
49.08,145.51,-0.253
49.11,145.36,-0.253
49.14,145.21,-0.253
49.16,145.06,-0.253
49.19,144.91,-0.253
49.23,144.76,-0.253
49.26,144.61,-0.253
49.29,144.46,-0.253
49.31,144.31,-0.253
49.34,144.16,-0.253
49.38,144.01,-0.252
49.41,143.86,-0.252
49.44,143.71,-0.252
49.46,143.56,-0.252
49.49,143.41,-0.252
49.53,143.26,-0.252
49.56,143.11,-0.252
49.59,142.96,-0.252
49.61,142.81,-0.252
49.64,142.66,-0.252
49.68,142.51,-0.252
49.71,142.36,-0.252
49.74,142.21,-0.252
49.76,142.06,-0.252
49.79,141.91,-0.252
49.83,141.76,-0.252
49.86,141.61,-0.252
49.89,141.46,-0.251
49.91,141.31,-0.251
49.94,141.16,-0.251
49.98,141.01,-0.251
50.01,140.86,-0.251
50.04,140.71,-0.251
50.06,140.56,-0.251
50.09,140.41,-0.251
50.13,140.26,-0.251
50.16,140.11,-0.251
50.19,139.96,-0.251
50.21,139.81,-0.251
50.24,139.66,-0.250
50.28,139.51,-0.250
50.31,139.36,-0.250
50.34,139.21,-0.250
50.36,139.06,-0.250
50.39,138.91,-0.250
50.43,138.76,-0.250
50.46,138.61,-0.250
50.49,138.46,-0.250
50.51,138.31,-0.250
50.54,138.16,-0.249
50.58,138.01,-0.249
50.61,137.86,-0.249
50.64,137.71,-0.249
50.66,137.56,-0.249
50.69,137.41,-0.249
50.73,137.26,-0.249
50.76,137.11,-0.249
50.79,136.96,-0.249
50.81,136.81,-0.249
50.84,136.66,-0.249
50.88,136.51,-0.249
50.91,136.36,-0.249
50.94,136.21,-0.249
50.96,136.06,-0.249
50.99,135.91,-0.249
51.03,135.76,-0.249
51.06,135.61,-0.249
51.09,135.46,-0.248
51.11,135.31,-0.248
51.14,135.16,-0.248
51.18,135.01,-0.248
51.21,134.86,-0.248
51.24,134.71,-0.248
51.26,134.56,-0.248
51.29,134.41,-0.248
51.33,134.26,-0.248
51.36,134.11,-0.248
51.39,133.96,-0.248
51.41,133.81,-0.248
51.44,133.66,-0.248
51.48,133.51,-0.248
51.51,133.36,-0.248
51.54,133.21,-0.247
51.56,133.06,-0.247
51.59,132.91,-0.247
51.63,132.76,-0.247
51.66,132.61,-0.247
51.69,132.46,-0.247
51.71,132.31,-0.247
51.74,132.16,-0.247
51.78,132.01,-0.247
51.81,131.86,-0.247
51.84,131.71,-0.247
51.86,131.57,-0.246
51.89,131.42,-0.246
51.93,131.27,-0.246
51.96,131.11,-0.246
51.99,130.97,-0.246
52.01,130.82,-0.246
52.04,130.67,-0.246
52.08,130.51,-0.246
52.11,130.37,-0.246
52.14,130.22,-0.246
52.16,130.07,-0.246
52.19,129.92,-0.246
52.23,129.77,-0.246
52.26,129.62,-0.246
52.29,129.47,-0.246
52.31,129.32,-0.246
52.34,129.17,-0.246
52.38,129.02,-0.246
52.41,128.86,-0.246
52.44,128.71,-0.246
52.46,128.56,-0.246
52.49,128.41,-0.245
52.53,128.26,-0.245
52.56,128.11,-0.245
52.59,127.97,-0.245
52.61,127.82,-0.245
52.64,127.67,-0.245
52.68,127.52,-0.245
52.71,127.37,-0.245
52.74,127.22,-0.244
52.76,127.07,-0.244
52.79,126.92,-0.244
52.83,126.77,-0.244
52.86,126.62,-0.244
52.89,126.47,-0.244
52.91,126.32,-0.244
52.94,126.17,-0.244
52.98,126.02,-0.244
53.01,125.87,-0.244
53.04,125.72,-0.244
53.06,125.57,-0.244
53.09,125.42,-0.244
53.13,125.27,-0.244
53.16,125.12,-0.244
53.19,124.97,-0.244
53.21,124.82,-0.243
53.24,124.67,-0.243
53.28,124.52,-0.243
53.31,124.37,-0.243
53.34,124.22,-0.243
53.36,124.07,-0.243
53.39,123.92,-0.243
53.43,123.77,-0.243
53.46,123.62,-0.243
53.49,123.47,-0.243
53.51,123.32,-0.243
53.54,123.17,-0.242
53.58,123.02,-0.242
53.61,122.87,-0.242
53.64,122.72,-0.242
53.66,122.57,-0.242
53.69,122.42,-0.242
53.73,122.27,-0.242
53.76,122.12,-0.242
53.79,121.97,-0.242
53.81,121.82,-0.242
53.84,121.67,-0.242
53.88,121.52,-0.242
53.91,121.37,-0.242
53.94,121.22,-0.242
53.96,121.07,-0.242
53.99,120.92,-0.242
54.03,120.77,-0.241
54.06,120.62,-0.241
54.09,120.47,-0.241
54.11,120.32,-0.241
54.14,120.17,-0.241
54.18,120.02,-0.241
54.21,119.87,-0.241
54.24,119.72,-0.241
54.26,119.57,-0.241
54.29,119.42,-0.241
54.33,119.27,-0.241
54.36,119.12,-0.241
54.39,118.97,-0.241
54.41,118.82,-0.241
54.44,118.67,-0.241
54.48,118.52,-0.240
54.51,118.37,-0.240
54.54,118.22,-0.240
54.56,118.07,-0.240
54.59,117.92,-0.240
54.63,117.77,-0.240
54.66,117.62,-0.240
54.69,117.47,-0.240
54.71,117.32,-0.240
54.74,117.17,-0.240
54.78,117.02,-0.240
54.81,116.87,-0.240
54.84,116.72,-0.240
[...]
280.16,-39.91,0.087
280.18,-39.85,0.087
280.19,-39.78,0.087
280.20,-39.71,0.087
280.22,-39.65,0.088
280.23,-39.58,0.088
280.24,-39.51,0.088
280.26,-39.45,0.088
280.27,-39.38,0.088
280.28,-39.31,0.088
280.30,-39.25,0.088
280.31,-39.18,0.088
280.32,-39.11,0.088
280.34,-39.05,0.088
280.35,-38.98,0.088
280.36,-38.91,0.088
280.38,-38.85,0.088
280.39,-38.78,0.088
280.40,-38.71,0.088
280.42,-38.65,0.088
280.43,-38.58,0.088
280.44,-38.51,0.088
280.46,-38.45,0.088
280.47,-38.38,0.088
280.48,-38.31,0.088
280.50,-38.25,0.088
280.51,-38.18,0.088
280.52,-38.11,0.088
280.54,-38.04,0.088
280.55,-37.98,0.088
280.56,-37.91,0.088
280.58,-37.85,0.088
280.59,-37.78,0.088
280.60,-37.71,0.088
280.62,-37.65,0.088
280.63,-37.58,0.088
280.64,-37.51,0.088
280.66,-37.44,0.089
280.67,-37.38,0.089
280.68,-37.31,0.089
280.70,-37.25,0.089
280.71,-37.18,0.089
280.72,-37.11,0.089
280.74,-37.04,0.089
280.75,-36.98,0.089
280.76,-36.91,0.089
280.78,-36.84,0.089
280.79,-36.78,0.089
280.80,-36.71,0.089
280.82,-36.64,0.089
280.83,-36.58,0.089
280.84,-36.51,0.089
280.86,-36.44,0.089
280.87,-36.38,0.089
280.88,-36.31,0.089
280.90,-36.24,0.089
280.91,-36.18,0.089
280.92,-36.11,0.089
280.94,-36.04,0.089
280.95,-35.98,0.089
280.96,-35.91,0.089
280.98,-35.84,0.089
280.99,-35.78,0.089
281.00,-35.71,0.089
281.02,-35.64,0.089
281.03,-35.58,0.089
281.04,-35.51,0.089
281.06,-35.44,0.089
281.07,-35.38,0.089
281.08,-35.31,0.089
281.10,-35.24,0.089
281.11,-35.18,0.089
281.12,-35.11,0.089
281.14,-35.04,0.089
281.15,-34.97,0.089
281.16,-34.91,0.089
281.18,-34.84,0.090
281.19,-34.77,0.090
281.20,-34.71,0.090
281.22,-34.64,0.090
281.23,-34.57,0.090
281.24,-34.51,0.090
281.26,-34.44,0.090
281.27,-34.37,0.090
281.28,-34.31,0.090
281.30,-34.24,0.090
281.31,-34.17,0.090
281.32,-34.11,0.090
281.34,-34.04,0.090
281.35,-33.97,0.090
281.36,-33.91,0.090
281.38,-33.84,0.090
281.39,-33.77,0.090
281.40,-33.71,0.090
281.42,-33.64,0.090
281.43,-33.57,0.090
281.44,-33.51,0.090
281.46,-33.44,0.090
281.47,-33.37,0.090
281.48,-33.31,0.090
281.50,-33.24,0.090
281.51,-33.17,0.090
281.52,-33.11,0.090
281.54,-33.04,0.090
281.55,-32.97,0.090
281.56,-32.91,0.090
281.58,-32.84,0.090
281.59,-32.77,0.090
281.60,-32.71,0.090
281.62,-32.64,0.090
281.63,-32.57,0.090
281.64,-32.51,0.090
281.66,-32.44,0.091
281.67,-32.37,0.091
281.68,-32.31,0.091
281.70,-32.24,0.091
281.71,-32.17,0.091
281.72,-32.10,0.091
281.74,-32.04,0.091
281.75,-31.97,0.091
281.76,-31.90,0.091
281.78,-31.84,0.091
281.79,-31.77,0.091
281.80,-31.70,0.091
281.82,-31.64,0.091
281.83,-31.57,0.091
281.84,-31.50,0.091
281.86,-31.44,0.091
281.87,-31.37,0.091
281.88,-31.30,0.091
281.90,-31.24,0.091
281.91,-31.17,0.091
281.92,-31.10,0.091
281.94,-31.04,0.091
281.95,-30.97,0.091
281.96,-30.90,0.091
281.98,-30.84,0.091
281.99,-30.77,0.091
282.00,-30.70,0.091
282.02,-30.64,0.091
282.03,-30.57,0.091
282.04,-30.50,0.091
282.06,-30.44,0.091
282.07,-30.37,0.091
282.08,-30.30,0.091
282.10,-30.24,0.091
282.11,-30.17,0.091
282.12,-30.10,0.091
282.14,-30.03,0.091
282.15,-29.97,0.091
282.16,-29.90,0.091
282.18,-29.84,0.091
282.19,-29.77,0.092
282.20,-29.70,0.092
282.22,-29.64,0.092
282.23,-29.57,0.092
282.24,-29.50,0.092
282.26,-29.43,0.092
282.27,-29.37,0.092
282.28,-29.30,0.092
282.30,-29.23,0.092
282.31,-29.17,0.092
282.32,-29.10,0.092
282.34,-29.03,0.092
282.35,-28.97,0.092
282.36,-28.90,0.092
282.38,-28.83,0.092
282.39,-28.77,0.092
282.40,-28.70,0.092
282.42,-28.64,0.092
282.43,-28.57,0.092
282.44,-28.50,0.092
282.46,-28.43,0.092
282.47,-28.37,0.092
282.48,-28.30,0.092
282.50,-28.23,0.092
282.51,-28.17,0.092
282.52,-28.10,0.092
282.54,-28.03,0.092
282.55,-27.97,0.092
282.56,-27.90,0.092
282.58,-27.83,0.092
282.59,-27.77,0.092
282.60,-27.70,0.092
282.62,-27.63,0.092
282.63,-27.57,0.092
282.64,-27.50,0.093
282.66,-27.43,0.093
282.67,-27.37,0.093
282.68,-27.30,0.093
282.70,-27.23,0.093
282.71,-27.17,0.093
282.72,-27.10,0.093
282.74,-27.03,0.093
282.75,-26.97,0.093
282.76,-26.90,0.093
282.78,-26.83,0.093
282.79,-26.76,0.093
282.80,-26.70,0.093
282.82,-26.63,0.093
282.83,-26.56,0.093
282.84,-26.50,0.093
282.86,-26.43,0.093
282.87,-26.37,0.093
282.88,-26.30,0.093
282.90,-26.23,0.093
282.91,-26.16,0.093
282.92,-26.10,0.093
282.94,-26.03,0.093
282.95,-25.96,0.093
282.96,-25.90,0.093
282.98,-25.83,0.093
282.99,-25.76,0.093
283.00,-25.70,0.093
283.02,-25.63,0.093
283.03,-25.56,0.093
283.04,-25.50,0.093
283.06,-25.43,0.093
283.07,-25.36,0.093
283.08,-25.30,0.093
283.10,-25.23,0.093
283.11,-25.16,0.093
283.12,-25.10,0.094
283.14,-25.03,0.094
283.15,-24.96,0.094
283.16,-24.90,0.094
283.18,-24.83,0.094
283.19,-24.76,0.094
283.20,-24.70,0.094
283.22,-24.63,0.094
283.23,-24.56,0.094
283.24,-24.50,0.094
283.26,-24.43,0.094
283.27,-24.36,0.094
283.28,-24.30,0.094
283.30,-24.23,0.094
283.31,-24.16,0.094
283.32,-24.10,0.094
283.34,-24.03,0.094
283.35,-23.96,0.094
283.36,-23.90,0.094
283.38,-23.83,0.094
283.39,-23.76,0.094
283.40,-23.70,0.094
283.42,-23.63,0.094
283.43,-23.56,0.094
283.44,-23.50,0.094
283.46,-23.43,0.094
283.47,-23.36,0.094
283.48,-23.30,0.094
283.50,-23.23,0.094
283.51,-23.16,0.094
283.52,-23.09,0.094
283.54,-23.03,0.094
283.55,-22.96,0.094
283.56,-22.90,0.094
283.58,-22.83,0.094
283.59,-22.76,0.094
283.60,-22.70,0.094
283.62,-22.63,0.095
283.63,-22.56,0.095
283.64,-22.50,0.095
283.66,-22.43,0.095
283.67,-22.36,0.095
283.68,-22.30,0.095
283.70,-22.23,0.095
283.71,-22.16,0.095
283.72,-22.09,0.095
283.74,-22.03,0.095
283.75,-21.96,0.095
283.76,-21.90,0.095
283.78,-21.83,0.095
283.79,-21.76,0.095
283.80,-21.69,0.095
283.82,-21.63,0.095
283.83,-21.56,0.095
283.84,-21.49,0.095
283.86,-21.43,0.095
283.87,-21.36,0.095
283.88,-21.29,0.095
283.90,-21.23,0.095
283.91,-21.16,0.095
283.92,-21.09,0.095
283.94,-21.03,0.095
283.95,-20.96,0.095
283.96,-20.89,0.095
283.98,-20.83,0.095
283.99,-20.76,0.095
284.00,-20.69,0.095
284.02,-20.63,0.096
284.03,-20.56,0.096
284.04,-20.49,0.096
284.06,-20.43,0.096
284.07,-20.36,0.096
284.08,-20.29,0.096
284.10,-20.23,0.096
284.11,-20.16,0.096
284.12,-20.09,0.096
284.14,-20.03,0.096
284.15,-19.96,0.096
284.16,-19.89,0.096
284.18,-19.83,0.096
284.19,-19.76,0.096
284.20,-19.69,0.096
284.22,-19.63,0.096
284.23,-19.56,0.096
284.24,-19.49,0.096
284.26,-19.43,0.096
284.27,-19.36,0.096
284.28,-19.29,0.096
284.30,-19.23,0.096
284.31,-19.16,0.096
284.32,-19.09,0.096
284.34,-19.03,0.096
284.35,-18.96,0.096
284.36,-18.89,0.096
284.38,-18.83,0.096
284.39,-18.76,0.096
284.40,-18.69,0.096
284.42,-18.63,0.096
284.43,-18.56,0.096
284.44,-18.49,0.096
284.46,-18.43,0.096
284.47,-18.36,0.096
284.48,-18.29,0.096
284.50,-18.23,0.096
284.51,-18.16,0.096
284.52,-18.09,0.096
284.54,-18.03,0.097
284.55,-17.96,0.097
284.56,-17.89,0.097
284.58,-17.83,0.097
284.59,-17.76,0.097
284.60,-17.69,0.097
284.62,-17.62,0.097
284.63,-17.56,0.097
284.64,-17.49,0.097
284.66,-17.43,0.097
284.67,-17.36,0.097
284.68,-17.29,0.097
284.70,-17.22,0.097
284.71,-17.16,0.097
284.72,-17.09,0.097
284.74,-17.03,0.097
284.75,-16.96,0.097
284.76,-16.89,0.097
284.78,-16.83,0.097
284.79,-16.76,0.097
284.80,-16.69,0.097
284.82,-16.63,0.097
284.83,-16.56,0.097
284.84,-16.49,0.097
284.86,-16.43,0.097
284.87,-16.36,0.097
284.88,-16.29,0.097
284.90,-16.23,0.097
284.91,-16.16,0.097
284.92,-16.09,0.097
284.94,-16.03,0.097
284.95,-15.96,0.097
284.96,-15.89,0.097
284.98,-15.82,0.097
284.99,-15.76,0.097
285.00,-15.69,0.097
285.02,-15.62,0.097
285.03,-15.56,0.098
285.04,-15.49,0.098
285.06,-15.42,0.098
285.07,-15.36,0.098
285.08,-15.29,0.098
285.10,-15.22,0.098
285.11,-15.16,0.098
285.12,-15.09,0.098
285.14,-15.03,0.098
285.15,-14.96,0.098
285.16,-14.89,0.098
285.18,-14.82,0.098
285.19,-14.76,0.098
285.20,-14.69,0.098
285.22,-14.62,0.098
285.23,-14.56,0.098
285.24,-14.49,0.098
285.26,-14.42,0.098
285.27,-14.36,0.098
285.28,-14.29,0.098
285.30,-14.22,0.098
285.31,-14.16,0.098
285.32,-14.09,0.098
285.34,-14.02,0.098
285.35,-13.96,0.098
285.36,-13.89,0.098
285.38,-13.82,0.098
285.39,-13.76,0.098
285.40,-13.69,0.098
285.42,-13.62,0.098
285.43,-13.56,0.098
285.44,-13.49,0.098
285.46,-13.42,0.099
285.47,-13.36,0.099
285.48,-13.29,0.099
285.50,-13.22,0.099
285.51,-13.15,0.099
285.52,-13.09,0.099
285.54,-13.02,0.099
285.55,-12.95,0.099
285.56,-12.89,0.099
285.58,-12.82,0.099
285.59,-12.75,0.099
285.60,-12.69,0.099
285.62,-12.62,0.099
285.63,-12.55,0.099
285.64,-12.49,0.099
285.66,-12.42,0.099
285.67,-12.35,0.099
285.68,-12.29,0.099
285.70,-12.22,0.099
285.71,-12.15,0.099
285.72,-12.09,0.099
285.74,-12.02,0.099
285.75,-11.95,0.099
285.76,-11.89,0.099
285.78,-11.82,0.099
285.79,-11.75,0.099
285.80,-11.69,0.099
285.82,-11.62,0.099
285.83,-11.55,0.099
285.84,-11.49,0.099
285.86,-11.42,0.099
285.87,-11.35,0.099
285.88,-11.29,0.099
285.90,-11.22,0.099
285.91,-11.15,0.099
285.92,-11.09,0.099
285.94,-11.02,0.100
285.95,-10.95,0.100
285.96,-10.89,0.100
285.98,-10.82,0.100
285.99,-10.75,0.100
286.00,-10.69,0.100
286.02,-10.62,0.100
286.03,-10.55,0.100
286.04,-10.49,0.100
286.06,-10.42,0.100
286.07,-10.35,0.100
286.08,-10.29,0.100
286.10,-10.22,0.100
286.11,-10.15,0.100
286.12,-10.08,0.100
286.14,-10.02,0.100
286.15,-9.95,0.100
286.16,-9.89,0.100
286.18,-9.82,0.100
286.19,-9.75,0.100
286.20,-9.68,0.100
286.22,-9.62,0.100
286.23,-9.55,0.100
286.24,-9.48,0.100
286.26,-9.42,0.100
286.27,-9.35,0.100
286.28,-9.28,0.100
286.30,-9.22,0.100
286.31,-9.15,0.100
286.32,-9.08,0.100
286.34,-9.02,0.100
286.35,-8.95,0.101
286.36,-8.88,0.101
286.38,-8.82,0.101
286.39,-8.75,0.101
286.40,-8.68,0.101
286.42,-8.62,0.101
286.43,-8.55,0.101
286.44,-8.48,0.101
286.46,-8.42,0.101
286.47,-8.35,0.101
286.48,-8.28,0.101
286.50,-8.22,0.101
286.51,-8.15,0.101
286.52,-8.08,0.101
286.54,-8.02,0.101
286.55,-7.95,0.101
286.56,-7.88,0.101
286.58,-7.82,0.101
286.59,-7.75,0.101
286.60,-7.69,0.101
286.62,-7.62,0.101
286.63,-7.55,0.101
286.64,-7.48,0.101
286.66,-7.42,0.101
286.67,-7.35,0.101
286.68,-7.28,0.101
286.70,-7.22,0.101
286.71,-7.15,0.101
286.72,-7.08,0.101
286.74,-7.02,0.101
286.75,-6.95,0.101
286.76,-6.88,0.101
286.78,-6.82,0.101
286.79,-6.75,0.101
286.80,-6.68,0.102
286.82,-6.62,0.102
286.83,-6.55,0.102
286.84,-6.48,0.102
286.86,-6.42,0.102
286.87,-6.35,0.102
286.88,-6.28,0.102
286.90,-6.22,0.102
286.91,-6.15,0.102
286.92,-6.08,0.102
286.94,-6.01,0.102
286.95,-5.95,0.102
286.96,-5.88,0.102
286.98,-5.82,0.102
286.99,-5.75,0.102
287.00,-5.68,0.102
287.02,-5.62,0.102
287.03,-5.55,0.102
287.04,-5.48,0.102
287.06,-5.41,0.102
287.07,-5.35,0.102
287.08,-5.28,0.102
287.10,-5.22,0.102
287.11,-5.15,0.102
287.12,-5.08,0.102
287.14,-5.01,0.102
287.15,-4.95,0.102
287.16,-4.88,0.102
287.18,-4.81,0.102
287.19,-4.75,0.103
287.20,-4.68,0.103
287.22,-4.61,0.103
287.23,-4.55,0.103
287.24,-4.48,0.103
287.26,-4.41,0.103
287.27,-4.35,0.103
287.28,-4.28,0.103
287.30,-4.21,0.103
287.31,-4.15,0.103
287.32,-4.08,0.103
287.34,-4.01,0.103
287.35,-3.95,0.103
287.36,-3.88,0.103
287.38,-3.81,0.103
287.39,-3.75,0.103
287.40,-3.68,0.103
287.42,-3.61,0.103
287.43,-3.55,0.103
287.44,-3.48,0.103
287.46,-3.41,0.103
287.47,-3.35,0.103
287.48,-3.28,0.103
287.50,-3.21,0.103
287.51,-3.15,0.103
287.52,-3.08,0.103
287.54,-3.01,0.103
287.55,-2.95,0.103
287.56,-2.88,0.104
287.58,-2.81,0.104
287.59,-2.75,0.104
287.60,-2.68,0.104
287.62,-2.61,0.104
287.63,-2.55,0.104
287.64,-2.48,0.104
287.66,-2.41,0.104
287.67,-2.35,0.104
287.68,-2.28,0.104
287.70,-2.21,0.104
287.71,-2.15,0.104
287.72,-2.08,0.104
287.74,-2.01,0.104
287.75,-1.95,0.104
287.76,-1.88,0.104
287.78,-1.81,0.104
287.79,-1.74,0.104
287.80,-1.68,0.104
287.82,-1.61,0.104
287.83,-1.55,0.104
287.84,-1.48,0.104
287.86,-1.41,0.104
287.87,-1.34,0.104
287.88,-1.28,0.104
287.90,-1.21,0.104
287.91,-1.14,0.104
287.92,-1.08,0.104
287.94,-1.01,0.104
287.95,-0.94,0.104
287.96,-0.88,0.104
287.98,-0.81,0.104
287.99,-0.74,0.104
288.00,-0.68,0.104
288.02,-0.61,0.105
288.03,-0.54,0.105
288.04,-0.48,0.105
288.06,-0.41,0.105
288.07,-0.34,0.105
288.08,-0.28,0.105
288.10,-0.21,0.105
288.11,-0.14,0.105
288.12,-0.08,0.105
288.14,-0.01,0.105
288.15,0.06,0.105
288.16,0.12,0.105
288.18,0.19,0.105
288.19,0.26,0.105
288.20,0.33,0.105
288.22,0.39,0.105
288.23,0.46,0.105
288.24,0.52,0.105
288.26,0.59,0.105
288.27,0.66,0.105
288.28,0.72,0.105
288.30,0.79,0.105
288.31,0.86,0.105
288.32,0.93,0.105
288.34,0.99,0.105
288.35,1.06,0.105
288.36,1.12,0.105
288.38,1.19,0.105
288.39,1.26,0.105
288.40,1.32,0.105
288.42,1.39,0.105
288.43,1.46,0.105
288.44,1.52,0.106
288.46,1.59,0.106
288.47,1.66,0.106
288.48,1.73,0.106
288.50,1.79,0.106
288.51,1.86,0.106
288.52,1.92,0.106
288.54,1.99,0.106
288.55,2.06,0.106
288.56,2.13,0.106
288.58,2.19,0.106
288.59,2.26,0.106
288.60,2.33,0.106
288.62,2.39,0.106
288.63,2.46,0.106
288.64,2.53,0.106
288.66,2.59,0.106
288.67,2.66,0.106
288.68,2.73,0.106
288.70,2.79,0.106
288.71,2.86,0.106
288.72,2.93,0.106
288.74,2.99,0.106
288.75,3.06,0.107
288.76,3.13,0.106
288.78,3.19,0.107
288.79,3.26,0.107
288.80,3.33,0.107
288.82,3.39,0.107
288.83,3.46,0.107
288.84,3.53,0.107
288.86,3.59,0.107
288.87,3.66,0.107
288.88,3.73,0.107
288.90,3.79,0.107
288.91,3.86,0.107
288.92,3.93,0.107
288.94,3.99,0.107
288.95,4.06,0.107
288.96,4.13,0.107
288.98,4.19,0.107
288.99,4.26,0.107
289.00,4.33,0.107
289.02,4.40,0.107
289.03,4.46,0.107
289.04,4.53,0.107
289.06,4.59,0.107
289.07,4.66,0.107
289.08,4.73,0.107
289.10,4.79,0.107
289.11,4.86,0.107
289.12,4.93,0.107
289.14,4.99,0.107
289.15,5.06,0.107
289.16,5.13,0.107
289.18,5.19,0.107
289.19,5.26,0.107
289.20,5.33,0.107
289.22,5.40,0.107
289.23,5.46,0.107
289.24,5.53,0.107
289.26,5.59,0.108
289.27,5.66,0.108
289.28,5.73,0.108
289.30,5.80,0.108
289.31,5.86,0.108
289.32,5.93,0.108
289.34,5.99,0.108
289.35,6.06,0.108
289.36,6.13,0.108
289.38,6.19,0.108
289.39,6.26,0.108
289.40,6.33,0.108
289.42,6.40,0.108
289.43,6.46,0.108
289.44,6.53,0.108
289.46,6.60,0.108
289.47,6.66,0.108
289.48,6.73,0.108
289.50,6.79,0.108
289.51,6.86,0.108
289.52,6.93,0.108
289.54,7.00,0.108
289.55,7.06,0.108
289.56,7.13,0.108
289.58,7.20,0.108
289.59,7.26,0.108
289.60,7.33,0.108
289.62,7.40,0.108
289.63,7.46,0.108
289.64,7.53,0.108
289.66,7.60,0.109
289.67,7.66,0.109
289.68,7.73,0.109
289.70,7.80,0.109
289.71,7.86,0.109
289.72,7.93,0.109
289.74,8.00,0.109
289.75,8.06,0.109
289.76,8.13,0.109
289.78,8.20,0.109
289.79,8.26,0.109
289.80,8.33,0.109
289.82,8.40,0.109
289.83,8.46,0.109
289.84,8.53,0.109
289.86,8.60,0.109
289.87,8.66,0.109
289.88,8.73,0.109
289.90,8.80,0.109
289.91,8.86,0.109
289.92,8.93,0.109
289.94,9.00,0.109
289.95,9.07,0.109
289.96,9.13,0.109
289.98,9.20,0.109
289.99,9.27,0.109
290.00,9.33,0.110
290.02,9.40,0.110
290.03,9.47,0.110
290.04,9.54,0.110
290.06,9.60,0.110
290.07,9.67,0.110
290.08,9.73,0.110
290.10,9.80,0.110
290.11,9.87,0.110
290.12,9.93,0.110
290.14,10.00,0.110
290.15,10.07,0.110
290.16,10.13,0.110
290.18,10.20,0.110
290.19,10.27,0.110
290.20,10.33,0.110
290.22,10.40,0.110
290.23,10.47,0.110
290.24,10.53,0.110
290.26,10.60,0.110
290.27,10.67,0.110
290.28,10.73,0.110
290.30,10.80,0.110
290.31,10.87,0.110
290.32,10.93,0.110
290.34,11.00,0.110
290.35,11.07,0.110
290.36,11.13,0.111
290.38,11.20,0.111
290.39,11.27,0.111
290.40,11.33,0.111
290.42,11.40,0.111
290.43,11.47,0.111
290.44,11.53,0.111
290.46,11.60,0.111
290.47,11.67,0.111
290.48,11.73,0.111
290.50,11.80,0.111
290.51,11.87,0.111
290.52,11.93,0.111
290.54,12.00,0.111
290.55,12.07,0.111
290.56,12.13,0.111
290.58,12.20,0.111
290.59,12.27,0.111
290.60,12.33,0.111
290.62,12.40,0.111
290.63,12.47,0.111
290.64,12.53,0.111
290.66,12.60,0.111
290.67,12.67,0.111
290.68,12.73,0.111
290.70,12.80,0.111
290.71,12.87,0.111
290.72,12.93,0.111
290.74,13.00,0.111
290.75,13.06,0.111
290.76,13.13,0.111
290.78,13.20,0.111
290.79,13.26,0.111
290.80,13.33,0.111
290.82,13.40,0.112
290.83,13.46,0.112
290.84,13.53,0.112
290.86,13.60,0.112
290.87,13.67,0.112
290.88,13.73,0.112
290.90,13.80,0.112
290.91,13.86,0.112
290.92,13.93,0.112
290.94,14.00,0.112
290.95,14.07,0.112
290.96,14.13,0.112
290.98,14.20,0.112
290.99,14.27,0.112
291.00,14.33,0.112
291.02,14.40,0.112
291.03,14.47,0.112
291.04,14.53,0.112
291.06,14.60,0.112
291.07,14.67,0.112
291.08,14.73,0.113
291.10,14.80,0.113
291.11,14.87,0.113
291.12,14.93,0.113
291.14,15.00,0.113
291.15,15.07,0.113
291.16,15.13,0.113
291.18,15.20,0.113
291.19,15.27,0.113
291.20,15.34,0.113
291.22,15.40,0.113
291.23,15.47,0.113
291.24,15.54,0.113
291.26,15.61,0.113
291.27,15.67,0.113
291.28,15.74,0.113
291.30,15.81,0.113
291.31,15.87,0.113
291.32,15.94,0.113
291.34,16.01,0.114
291.35,16.07,0.114
291.36,16.14,0.114
291.38,16.21,0.114
291.39,16.27,0.114
291.40,16.34,0.114
291.42,16.41,0.114
291.43,16.47,0.114
291.44,16.54,0.114
291.46,16.61,0.114
291.47,16.67,0.114
291.48,16.74,0.114
291.50,16.81,0.114
291.51,16.87,0.114
291.52,16.94,0.114
291.54,17.01,0.114
291.55,17.07,0.114
291.56,17.14,0.114
291.58,17.21,0.114
291.59,17.27,0.114
291.60,17.34,0.114
291.62,17.41,0.114
291.63,17.47,0.114
291.64,17.54,0.114
291.66,17.61,0.114
291.67,17.67,0.114
291.68,17.74,0.115
291.70,17.81,0.115
291.71,17.87,0.115
291.72,17.94,0.115
291.74,18.00,0.115
291.75,18.07,0.115
291.76,18.14,0.115
291.78,18.21,0.115
291.79,18.27,0.115
291.80,18.34,0.115
291.82,18.41,0.115
291.83,18.47,0.115
291.84,18.54,0.115
291.86,18.61,0.115
291.87,18.67,0.115
291.88,18.74,0.115
291.90,18.81,0.115
291.91,18.87,0.115
291.92,18.94,0.115
291.94,19.00,0.115
291.95,19.07,0.115
291.96,19.14,0.115
291.98,19.20,0.115
291.99,19.27,0.115
292.00,19.34,0.115
292.02,19.41,0.115
292.03,19.47,0.115
292.04,19.54,0.115
292.06,19.61,0.115
292.07,19.67,0.115
292.08,19.74,0.116
292.10,19.80,0.116
292.11,19.87,0.116
292.12,19.94,0.116
292.14,20.01,0.116
292.15,20.07,0.116
292.16,20.14,0.116
292.18,20.21,0.116
292.19,20.27,0.116
292.20,20.34,0.116
292.22,20.41,0.116
292.23,20.47,0.116
292.24,20.54,0.116
292.26,20.61,0.116
292.27,20.67,0.116
292.28,20.74,0.116
292.30,20.81,0.116
292.31,20.87,0.116
292.32,20.94,0.116
292.34,21.01,0.116
292.35,21.07,0.116
292.36,21.14,0.116
292.38,21.21,0.117
292.39,21.27,0.117
292.40,21.34,0.117
292.42,21.41,0.117
292.43,21.47,0.117
292.44,21.54,0.117
292.46,21.61,0.117
292.47,21.67,0.117
292.48,21.74,0.117
292.50,21.81,0.117
292.51,21.87,0.117
292.52,21.94,0.117
292.54,22.01,0.117
292.55,22.07,0.117
292.56,22.14,0.117
292.58,22.21,0.117
292.59,22.27,0.117
292.60,22.34,0.117
292.62,22.41,0.117
292.63,22.47,0.117
292.64,22.54,0.117
292.66,22.61,0.117
292.67,22.67,0.117
292.68,22.74,0.117
292.70,22.81,0.117
292.71,22.87,0.118
292.72,22.94,0.118
292.74,23.01,0.118
292.75,23.07,0.118
292.76,23.14,0.118
292.78,23.21,0.118
292.79,23.27,0.118
292.80,23.34,0.118
292.82,23.41,0.118
292.83,23.47,0.118
292.84,23.54,0.118
292.86,23.61,0.118
292.87,23.67,0.118
292.88,23.74,0.118
292.90,23.81,0.118
292.91,23.87,0.118
292.92,23.94,0.118
292.94,24.01,0.118
292.95,24.07,0.118
292.96,24.14,0.118
292.98,24.21,0.118
292.99,24.27,0.118
293.00,24.34,0.119
293.02,24.41,0.119
293.03,24.47,0.119
293.04,24.54,0.119
293.06,24.61,0.119
293.07,24.67,0.119
293.08,24.74,0.119
293.10,24.81,0.119
293.11,24.87,0.119
293.12,24.94,0.119
293.14,25.01,0.119
293.15,25.07,0.119
293.16,25.14,0.119
293.18,25.21,0.119
293.19,25.28,0.119
293.20,25.34,0.119
293.22,25.41,0.119
293.23,25.48,0.119
293.24,25.54,0.119
293.26,25.61,0.119
293.27,25.67,0.119
293.28,25.74,0.120
293.30,25.81,0.120
293.31,25.87,0.120
293.32,25.94,0.120
293.34,26.01,0.120
293.35,26.08,0.120
293.36,26.14,0.120
293.38,26.21,0.120
293.39,26.28,0.120
293.40,26.34,0.120
293.42,26.41,0.120
293.43,26.47,0.120
293.44,26.54,0.120
293.46,26.61,0.120
293.47,26.68,0.120
293.48,26.74,0.120
293.50,26.81,0.120
293.51,26.87,0.120
293.52,26.94,0.120
293.54,27.01,0.120
293.55,27.08,0.120
293.56,27.14,0.120
293.58,27.21,0.120
293.59,27.28,0.120
293.60,27.34,0.121
293.62,27.41,0.121
293.63,27.48,0.121
293.64,27.54,0.121
293.66,27.61,0.121
293.67,27.68,0.121
293.68,27.74,0.121
293.70,27.81,0.121
293.71,27.88,0.121
293.72,27.94,0.121
293.74,28.01,0.121
293.75,28.08,0.121
293.76,28.14,0.121
293.78,28.21,0.121
293.79,28.28,0.121
293.80,28.34,0.121
293.82,28.41,0.121
293.83,28.48,0.121
293.84,28.54,0.121
293.86,28.61,0.121
293.87,28.68,0.122
293.88,28.74,0.122
293.90,28.81,0.122
293.91,28.88,0.122
293.92,28.94,0.122
293.94,29.01,
293.95,29.08,
293.96,29.14,
293.98,29.21,
293.99,,