File: DSC/Olivia/2025_08_05_PVP90_TS_n60C_250C_10Cmin_x3.csv
Filename,2025_08_05_PVP90_TS_n60C_250C_10Cmin_x3
Instrument name,DSC2A-00468 (192.168.1.100)
Operator,Yarger
rundate,8/6/2025
Sample name,2025_08_05_PVP90_TS_n60C_250C_10Cmin_x3
proceduresegments,Data Off ; Equilibrate -60.00 °C; Data On ; Ramp 10.00 °C/min to 250.00 °C; Data Off ; Isothermal 2.0 min; Data On ; Ramp 10.00 °C/min to -60.00 °C; Data Off ; Isothermal 2.0 min; Data On ; Ramp 10.00 °C/min to 250.00 °C; Data Off ; Isothermal 2.0 min; Data On ; Ramp 10.00 °C/min to -60.00 °C; Data Off ; Isothermal 2.0 min; Data On ; Ramp 10.00 °C/min to 250.00 °C
[File Parameters]
Run date,8/6/2025 12:42:07 AM
Trios version,5.1.1.46572
Original File Name,
Current File Name,D:\DSC2500\JYarger\2025_08_05_PVP90_TS_n60C_250C_10Cmin_x3.tri
[Procedure]
Procedure Name,PVP90_TS_Pans_n60C_250C_10Cmin_x3
Sample Name,2025_08_05_PVP90_TS_n60C_250C_10Cmin_x3
Sample Mass,4.42 mg
Reference Sample Mass,0 mg
Pan Mass,32.38 mg
Pan Number,8
Reference Pan Mass,32.52 mg
Reference Pan Number,37
Pan Type,Aluminum
Comments,Thermal support Al pans/lids. DSC_Samples_A2_Tray_July2025 google sheet.
Project Name,Pharma
Operator,Yarger
Test,Custom
Unload Max Temperature,30
Unload Min Temperature,30
Load Max Temperature,30
Load Min Temperature,30
Stop on Gas Flow Error,Yes
[Signal List]
Signal #1,Time (min)
Signal #2,Temperature (°C)
Signal #3,Heat Flow (mW)
Signal #4,Delta T (µV)
Signal #5,Delta Tzero (µV)
Signal #6,Tzero Temperature (°C)
Signal #7,Cell Purge (mL/min)
Signal #8,Heater Temp (°C)
Signal #9,Power Delivered (W)
Signal #10,Reference Junction Temperature (°C)
Signal #11,Flange Temperature (°C)
Signal #12,Heat Flow Phase (rad)
Signal #13,Total Heat Capacity (J/°C)
Signal #14,Heat Capacity (J/°C)
[Configuration]
Company Name,ASU
Instrument Name,DSC2A-00468
Instrument Type,DSC2500
Serial Number,DSC2A-00468
IP,192.168.1.100
Location of Instrument,MRRC
DisplayType,Unknown
Sample Interval ,0.1 s/pt
Selected Heat Flow,T4P
Exotherm Direction,Down
Cell Serial,DRC2-00792
Lid Type,Standard
Cooler,RCS 90
Leave Cooler on at End of Sequence,On
Gas 2,Nitrogen
Gas Selected,Channel 1
Flow Rate,50 mL/min
Secondary Purge,On
Licensed Heat Flow,Heat Flow T4P
Modulation Licensed,Yes
[Versions]
Common IDD Version,1
Cortex Version,VER 2.10.2.31
Driver,5.0.0.6
GDM Version,1.0.3.3
TouchscreenVersion,1.0.0.16145
FEP Version,1.2.1.21
FEP Bootloader,2.0.0.5
AutoSampler Version,2.1.1.26
Auto Sampler Bootloader,2.0.0.5
FCM Version,1.1.0.3
FCM Bootloader,2.0.0.5
[Experiment Logs]
Experiment Log Entry # 1,Data On set to 0
Experiment Log Entry # 3,Equilibrate Segment -60 (C) Started
Experiment Log Entry # 5,Air Cool is off.
Experiment Log Entry # 7,Data On set to 1
Experiment Log Entry # 9,Ramp Segment 10 C/min to 250 Started
Experiment Log Entry # 11,Data On set to 0
Experiment Log Entry # 13,Isothermal Segment 2 min started
Experiment Log Entry # 15,Data On set to 1
Experiment Log Entry # 17,Ramp Segment 10 C/min to -60 Started
Experiment Log Entry # 19,Data On set to 0
Experiment Log Entry # 21,Isothermal Segment 2 min started
Experiment Log Entry # 23,Data On set to 1
Experiment Log Entry # 25,Ramp Segment 10 C/min to 250 Started
Experiment Log Entry # 27,Data On set to 0
Experiment Log Entry # 29,Isothermal Segment 2 min started
Experiment Log Entry # 31,Data On set to 1
Experiment Log Entry # 33,Ramp Segment 10 C/min to -60 Started
Experiment Log Entry # 35,Data On set to 0
Experiment Log Entry # 37,Isothermal Segment 2 min started
Experiment Log Entry # 39,Data On set to 1
Experiment Log Entry # 41,Ramp Segment 10 C/min to 250 Started
[Method Log]
Method Log Entry # 1,Data Off
Method Log Entry # 2,Equilibrate -60 °C
Method Log Entry # 3,Data On
Method Log Entry # 4,(Ramp 321912) Ramp 10 °C/minute to 250 °C
Method Log Entry # 5,Data Off
Method Log Entry # 6,Isothermal 2 minutes
Method Log Entry # 7,Data On
Method Log Entry # 8,(Ramp 321916) Ramp 10 °C/minute to -60 °C
Method Log Entry # 9,Data Off
Method Log Entry # 10,Isothermal 2 minutes
Method Log Entry # 11,Data On
Method Log Entry # 12,(Ramp 321920) Ramp 10 °C/minute to 250 °C
Method Log Entry # 13,Data Off
Method Log Entry # 14,Isothermal 2 minutes
Method Log Entry # 15,Data On
Method Log Entry # 16,(Ramp 321924) Ramp 10 °C/minute to -60 °C
Method Log Entry # 17,Data Off
Method Log Entry # 18,Isothermal 2 minutes
Method Log Entry # 19,Data On
Method Log Entry # 20,(Ramp 321928) Ramp 10 °C/minute to 250 °C
Cell Serial,DRC2-00792
[T1 Calibration]
Slope,-0.008529666
Offset,9.636258
Initial Temperature,98.23
GUID,f8bfdadc-4977-4fdf-ba6d-0ba9134940c3
[TZero Calibration]
Date Applied,11/29/2022 4:06:13 PM
Description,From -89.059 °C to 396.009 °C at 20.000°C/min
Gas Type,Nitrogen
Pan Type,None
Source Files 1,C:\Users\yargerlab\Desktop\DSC Data\General\TZero_calibration_11_29_22_2nd(2).tri
Source Files 2,C:\Users\yargerlab\Desktop\DSC Data\General\TZero_calibration_11_29_22_2nd(3).tri
Delta T Offset,13.05235
Delta T Slope,-0.007271007
Delta T0 Offset,-13.69128
Delta T0 Slope,0.06063341
[Temperature Calibration]
Date Applied,11/29/2022 7:12:28 PM
Description,From 106.590 °C to 186.590 °C at 10.000°C/min
Gas Type,Nitrogen
Pan Type,Tzero Aluminum Hermetic
Source Files 1,C:\Users\yargerlab\Desktop\DSC Data\General\Indium(6).tri
Measured 1,157.391
Known 1,156.598
[Cell Constant Calibration]
Date Applied,11/29/2022 7:12:29 PM
Description,From 106.590 °C to 186.590 °C at 10.000°C/min
Gas Type,Nitrogen
Pan Type,Tzero Aluminum Hermetic
Source Files 1,C:\Users\yargerlab\Desktop\DSC Data\General\Indium(6).tri
T4P KCell,1.006051
Onset Slope,63.26126 mW/°C
[Direct Cp Calibration]
Date Applied,11/30/2022 11:04:51 AM
Description,From -79.983 °C to 298.409 °C at 10.000°C/min
Gas Type,Nitrogen
Pan Type,Tzero Aluminum Hermetic
Source Files 1,C:\Users\yargerlab\Desktop\DSC Data\General\Sapphire_Heat_Capacity_11_30_22.tri
[Rev Cp Calibration]
Date Applied,11/30/2022 1:58:51 PM
Description,From -79.996 °C to 292.812 °C at 3.000°C/min
Gas Type,Nitrogen
Pan Type,Tzero Aluminum Hermetic
Source Files 1,C:\Users\yargerlab\Desktop\DSC Data\General\Sapphire_MDSC_Calibration_11_30_22.tri
[step]
Ramp 10.00 °C/min to 250.00 °C
Time,Temperature,Heat Flow (Normalized)
min,°C,W/g
0.00,-59.80,-0.060
0.02,-59.81,-0.055
0.04,-59.81,-0.051
0.07,-59.79,-0.054
0.09,-59.74,-0.055
0.11,-59.65,-0.053
0.13,-59.54,-0.024
0.15,-59.39,0.009
0.17,-59.23,0.048
0.19,-59.05,0.084
0.22,-58.86,0.117
0.24,-58.66,0.144
0.26,-58.46,0.164
0.28,-58.26,0.180
0.30,-58.05,0.192
0.33,-57.84,0.199
0.35,-57.64,0.207
0.37,-57.43,0.212
0.39,-57.22,0.215
0.41,-57.01,0.217
0.43,-56.79,0.219
0.45,-56.58,0.221
0.48,-56.37,0.222
0.50,-56.16,0.223
0.52,-55.95,0.224
0.54,-55.73,0.226
0.56,-55.52,0.226
0.58,-55.31,0.227
0.61,-55.09,0.228
0.63,-54.88,0.228
0.65,-54.67,0.229
0.67,-54.45,0.229
0.69,-54.24,0.230
0.72,-54.02,0.230
0.74,-53.81,0.231
0.76,-53.59,0.231
0.78,-53.38,0.232
0.80,-53.17,0.232
0.82,-52.95,0.233
0.85,-52.74,0.233
0.87,-52.52,0.233
0.89,-52.31,0.234
0.91,-52.09,0.234
0.93,-51.87,0.235
0.95,-51.66,0.235
0.98,-51.44,0.236
1.00,-51.23,0.236
1.02,-51.01,0.236
1.04,-50.80,0.237
1.06,-50.58,0.237
1.08,-50.37,0.238
1.11,-50.15,0.238
1.13,-49.93,0.238
1.15,-49.72,0.239
1.17,-49.50,0.239
1.19,-49.29,0.239
1.21,-49.07,0.239
1.23,-48.85,0.240
1.26,-48.64,0.240
1.28,-48.42,0.240
1.30,-48.21,0.240
1.32,-47.99,0.241
1.34,-47.77,0.241
1.37,-47.56,0.241
1.39,-47.34,0.241
1.41,-47.12,0.242
1.43,-46.91,0.242
1.45,-46.69,0.242
1.47,-46.47,0.242
1.49,-46.26,0.242
1.52,-46.04,0.243
1.54,-45.83,0.243
1.56,-45.61,0.243
1.58,-45.39,0.243
1.60,-45.18,0.243
1.63,-44.96,0.243
1.65,-44.74,0.244
1.67,-44.52,0.244
1.69,-44.31,0.244
1.71,-44.09,0.244
1.73,-43.87,0.244
1.76,-43.66,0.244
1.78,-43.44,0.245
1.80,-43.22,0.245
1.82,-43.01,0.245
1.84,-42.79,0.245
1.86,-42.57,0.245
1.88,-42.36,0.245
1.91,-42.14,0.246
1.93,-41.92,0.246
1.95,-41.71,0.246
1.97,-41.49,0.246
1.99,-41.27,0.246
2.02,-41.06,0.246
2.04,-40.84,0.246
2.06,-40.62,0.246
2.08,-40.41,0.246
2.10,-40.19,0.247
2.12,-39.97,0.247
2.14,-39.75,0.247
2.17,-39.54,0.247
2.19,-39.32,0.247
2.21,-39.10,0.247
2.23,-38.89,0.247
2.25,-38.67,0.247
2.28,-38.45,0.247
2.30,-38.24,0.248
2.32,-38.02,0.248
2.34,-37.80,0.248
2.36,-37.59,0.248
2.38,-37.37,0.248
2.41,-37.15,0.248
2.43,-36.93,0.248
2.45,-36.72,0.248
2.47,-36.50,0.248
2.49,-36.28,0.248
2.51,-36.07,0.249
2.54,-35.85,0.249
2.56,-35.63,0.249
2.58,-35.41,0.249
2.60,-35.20,0.249
2.62,-34.98,0.249
2.64,-34.76,0.249
2.66,-34.55,0.249
2.69,-34.33,0.249
2.71,-34.11,0.250
2.73,-33.90,0.250
2.75,-33.68,0.250
2.77,-33.46,0.250
2.79,-33.25,0.250
2.82,-33.03,0.250
2.84,-32.81,0.250
2.86,-32.60,0.250
2.88,-32.38,0.250
2.90,-32.16,0.251
2.93,-31.95,0.251
2.95,-31.73,0.251
2.97,-31.51,0.251
2.99,-31.29,0.251
3.01,-31.08,0.251
3.03,-30.86,0.251
3.06,-30.64,0.251
3.08,-30.43,0.252
3.10,-30.21,0.252
3.12,-29.99,0.252
3.14,-29.77,0.252
3.16,-29.56,0.252
3.19,-29.34,0.252
3.21,-29.12,0.252
3.23,-28.91,0.252
3.25,-28.69,0.252
3.27,-28.47,0.253
3.29,-28.26,0.253
3.31,-28.04,0.253
3.34,-27.82,0.253
3.36,-27.61,0.253
3.38,-27.39,0.253
3.40,-27.17,0.253
3.42,-26.95,0.253
3.44,-26.74,0.254
3.47,-26.52,0.254
3.49,-26.30,0.254
3.51,-26.09,0.254
3.53,-25.87,0.254
3.55,-25.65,0.254
3.58,-25.44,0.254
3.60,-25.22,0.254
3.62,-25.00,0.255
3.64,-24.79,0.255
3.66,-24.57,0.255
3.68,-24.35,0.255
3.71,-24.13,0.255
3.73,-23.92,0.255
3.75,-23.70,0.255
3.77,-23.48,0.256
3.79,-23.27,0.256
3.81,-23.05,0.256
3.84,-22.83,0.256
3.86,-22.62,0.256
3.88,-22.40,0.256
3.90,-22.18,0.256
3.92,-21.97,0.257
3.94,-21.75,0.257
3.96,-21.53,0.257
3.99,-21.32,0.257
4.01,-21.10,0.257
4.03,-20.88,0.257
4.05,-20.66,0.258
4.07,-20.45,0.258
4.09,-20.23,0.258
4.12,-20.01,0.258
4.14,-19.80,0.258
4.16,-19.58,0.258
4.18,-19.36,0.258
4.20,-19.15,0.258
4.23,-18.93,0.259
4.25,-18.71,0.259
4.27,-18.50,0.259
4.29,-18.28,0.259
4.31,-18.06,0.259
4.33,-17.85,0.259
4.35,-17.63,0.259
4.38,-17.41,0.260
4.40,-17.19,0.260
4.42,-16.98,0.260
4.44,-16.76,0.260
4.46,-16.54,0.260
4.49,-16.33,0.260
4.51,-16.11,0.260
4.53,-15.89,0.261
4.55,-15.68,0.261
4.57,-15.46,0.261
4.59,-15.24,0.261
4.61,-15.03,0.261
4.64,-14.81,0.261
4.66,-14.59,0.262
4.68,-14.37,0.262
4.70,-14.16,0.262
4.72,-13.94,0.262
4.75,-13.72,0.262
4.77,-13.51,0.262
4.79,-13.29,0.263
4.81,-13.07,0.263
4.83,-12.86,0.263
4.85,-12.64,0.263
4.88,-12.42,0.263
4.90,-12.21,0.264
4.92,-11.99,0.264
4.94,-11.77,0.264
4.96,-11.56,0.264
4.98,-11.34,0.264
5.00,-11.12,0.265
5.03,-10.90,0.265
5.05,-10.69,0.265
5.07,-10.47,0.265
5.09,-10.25,0.265
5.11,-10.04,0.265
5.14,-9.82,0.266
5.16,-9.60,0.266
5.18,-9.39,0.266
5.20,-9.17,0.266
5.22,-8.95,0.266
5.24,-8.74,0.266
5.26,-8.52,0.267
5.29,-8.30,0.267
5.31,-8.09,0.267
5.33,-7.87,0.267
5.35,-7.65,0.267
5.37,-7.43,0.268
5.40,-7.22,0.268
5.42,-7.00,0.268
5.44,-6.78,0.268
5.46,-6.57,0.268
5.48,-6.35,0.268
5.50,-6.13,0.269
5.53,-5.92,0.269
5.55,-5.70,0.269
5.57,-5.48,0.269
5.59,-5.27,0.270
5.61,-5.05,0.270
5.63,-4.83,0.270
5.65,-4.62,0.270
5.68,-4.40,0.270
5.70,-4.18,0.271
5.72,-3.97,0.271
5.74,-3.75,0.271
5.76,-3.53,0.271
5.79,-3.31,0.271
5.81,-3.10,0.272
5.83,-2.88,0.272
5.85,-2.66,0.272
5.87,-2.45,0.272
5.89,-2.23,0.273
5.91,-2.01,0.273
5.94,-1.80,0.273
5.96,-1.58,0.273
5.98,-1.36,0.273
6.00,-1.15,0.274
6.02,-0.93,0.274
6.05,-0.71,0.274
6.07,-0.49,0.274
6.09,-0.28,0.274
6.11,-0.06,0.275
6.13,0.16,0.275
6.15,0.37,0.275
6.18,0.59,0.275
6.20,0.81,0.276
6.22,1.02,0.276
6.24,1.24,0.276
6.26,1.46,0.276
6.28,1.67,0.276
6.30,1.89,0.277
6.33,2.11,0.277
6.35,2.33,0.277
6.37,2.54,0.277
6.39,2.76,0.278
6.41,2.98,0.278
6.44,3.19,0.278
6.46,3.41,0.278
6.48,3.63,0.278
6.50,3.84,0.279
6.52,4.06,0.279
6.54,4.28,0.279
6.56,4.49,0.279
6.59,4.71,0.279
6.61,4.93,0.280
6.63,5.14,0.280
6.65,5.36,0.280
6.67,5.58,0.280
6.70,5.79,0.281
6.72,6.01,0.281
6.74,6.23,0.281
6.76,6.45,0.282
6.78,6.66,0.282
6.80,6.88,0.282
6.83,7.10,0.282
6.85,7.31,0.283
6.87,7.53,0.283
6.89,7.75,0.283
6.91,7.96,0.283
6.93,8.18,0.284
6.95,8.40,0.284
6.98,8.61,0.284
7.00,8.83,0.284
7.02,9.05,0.285
7.04,9.27,0.285
7.06,9.48,0.285
7.09,9.70,0.286
7.11,9.92,0.286
7.13,10.13,0.286
7.15,10.35,0.286
7.17,10.57,0.287
7.19,10.78,0.287
7.21,11.00,0.287
7.24,11.22,0.288
7.26,11.43,0.288
7.28,11.65,0.288
7.30,11.87,0.288
7.32,12.08,0.289
7.35,12.30,0.289
7.37,12.52,0.289
7.39,12.73,0.290
7.41,12.95,0.290
7.43,13.17,0.290
7.45,13.39,0.291
7.48,13.60,0.291
7.50,13.82,0.291
7.52,14.04,0.291
7.54,14.25,0.292
7.56,14.47,0.292
7.58,14.69,0.292
7.60,14.90,0.293
7.63,15.12,0.293
7.65,15.34,0.293
7.67,15.55,0.294
7.69,15.77,0.294
7.71,15.99,0.294
7.74,16.20,0.294
7.76,16.42,0.295
7.78,16.64,0.295
7.80,16.85,0.295
7.82,17.07,0.296
7.84,17.29,0.296
7.86,17.50,0.296
7.89,17.72,0.297
7.91,17.94,0.297
7.93,18.15,0.297
7.95,18.37,0.298
7.97,18.59,0.298
8.00,18.81,0.299
8.02,19.02,0.299
8.04,19.24,0.299
8.06,19.45,0.300
8.08,19.67,0.300
8.10,19.89,0.300
8.13,20.11,0.301
8.15,20.32,0.301
8.17,20.54,0.301
8.19,20.76,0.302
8.21,20.97,0.302
8.23,21.19,0.303
8.25,21.41,0.303
8.28,21.62,0.303
8.30,21.84,0.304
8.32,22.06,0.304
8.34,22.27,0.304
8.36,22.49,0.305
8.39,22.71,0.305
8.41,22.92,0.306
8.43,23.14,0.306
8.45,23.36,0.306
8.47,23.57,0.307
8.49,23.79,0.307
8.51,24.01,0.308
8.54,24.23,0.308
8.56,24.44,0.309
8.58,24.66,0.309
8.60,24.88,0.309
8.62,25.09,0.310
8.65,25.31,0.311
8.67,25.52,0.311
8.69,25.74,0.311
8.71,25.96,0.312
8.73,26.17,0.312
8.75,26.39,0.313
8.78,26.61,0.313
8.80,26.82,0.314
8.82,27.04,0.314
8.84,27.26,0.315
8.86,27.48,0.315
8.88,27.69,0.316
8.90,27.91,0.316
8.93,28.13,0.317
8.95,28.34,0.317
8.97,28.56,0.317
8.99,28.78,0.318
9.01,28.99,0.318
9.03,29.21,0.319
9.06,29.43,0.319
9.08,29.64,0.320
9.10,29.86,0.320
9.12,30.08,0.321
9.14,30.29,0.321
9.17,30.51,0.322
9.19,30.73,0.323
9.21,30.94,0.323
9.23,31.16,0.324
9.25,31.38,0.324
9.27,31.60,0.325
9.30,31.81,0.325
9.32,32.03,0.326
9.34,32.25,0.326
9.36,32.46,0.327
9.38,32.68,0.327
9.40,32.90,0.328
9.43,33.11,0.329
9.45,33.33,0.329
9.47,33.55,0.330
9.49,33.76,0.331
9.51,33.98,0.331
9.53,34.20,0.332
9.55,34.41,0.333
9.58,34.63,0.333
9.60,34.85,0.334
9.62,35.06,0.335
9.64,35.28,0.335
9.66,35.50,0.336
9.68,35.71,0.337
9.71,35.93,0.338
9.73,36.15,0.338
9.75,36.36,0.339
9.77,36.58,0.340
9.79,36.80,0.340
9.82,37.01,0.342
9.84,37.23,0.342
9.86,37.45,0.343
9.88,37.66,0.344
9.90,37.88,0.345
9.92,38.10,0.346
9.95,38.31,0.347
9.97,38.53,0.348
9.99,38.75,0.349
10.01,38.96,0.349
10.03,39.18,0.350
10.05,39.40,0.351
10.08,39.61,0.352
10.10,39.83,0.353
10.12,40.05,0.354
10.14,40.26,0.354
10.16,40.48,0.355
10.18,40.70,0.356
10.20,40.91,0.357
10.23,41.13,0.358
10.25,41.35,0.359
10.27,41.56,0.360
10.29,41.78,0.361
10.31,42.00,0.362
10.33,42.21,0.363
10.36,42.43,0.364
10.38,42.65,0.365
10.40,42.86,0.366
10.42,43.08,0.366
10.44,43.30,0.367
10.47,43.51,0.368
10.49,43.73,0.369
10.51,43.95,0.370
10.53,44.16,0.371
10.55,44.38,0.371
10.57,44.60,0.372
10.60,44.81,0.373
10.62,45.03,0.373
10.64,45.25,0.374
10.66,45.46,0.375
10.68,45.68,0.376
10.70,45.90,0.376
10.73,46.11,0.377
10.75,46.33,0.377
10.77,46.55,0.378
10.79,46.76,0.378
10.81,46.98,0.378
10.83,47.20,0.379
10.85,47.42,0.379
10.88,47.63,0.380
10.90,47.85,0.380
10.92,48.07,0.380
10.94,48.28,0.381
10.96,48.50,0.381
10.98,48.72,0.381
11.01,48.93,0.381
11.03,49.15,0.381
11.05,49.37,0.382
11.07,49.58,0.382
11.09,49.80,0.382
11.12,50.02,0.382
11.14,50.23,0.382
11.16,50.45,0.382
11.18,50.67,0.382
11.20,50.88,0.383
11.22,51.10,0.383
11.25,51.32,0.383
11.27,51.54,0.383
11.29,51.75,0.384
11.31,51.97,0.384
11.33,52.19,0.384
11.35,52.40,0.385
11.38,52.62,0.385
11.40,52.84,0.385
11.42,53.05,0.386
11.44,53.27,0.387
11.46,53.49,0.387
11.48,53.70,0.388
11.50,53.92,0.388
11.53,54.14,0.389
11.55,54.35,0.389
11.57,54.57,0.390
11.59,54.79,0.391
11.61,55.00,0.392
11.63,55.22,0.392
11.66,55.44,0.393
11.68,55.65,0.394
11.70,55.87,0.394
11.72,56.09,0.395
11.74,56.30,0.396
11.77,56.52,0.397
11.79,56.74,0.398
11.81,56.95,0.399
11.83,57.17,0.400
11.85,57.39,0.401
11.87,57.60,0.402
11.90,57.82,0.403
11.92,58.04,0.404
11.94,58.25,0.406
11.96,58.47,0.407
11.98,58.69,0.408
12.00,58.90,0.409
12.03,59.12,0.410
12.05,59.34,0.412
12.07,59.55,0.413
12.09,59.77,0.414
12.11,59.99,0.415
12.13,60.20,0.416
12.15,60.42,0.418
12.18,60.63,0.419
12.20,60.85,0.420
12.22,61.07,0.421
12.24,61.28,0.423
12.26,61.50,0.426
12.28,61.72,0.427
12.31,61.93,0.429
12.33,62.15,0.430
12.35,62.37,0.432
12.37,62.58,0.433
12.39,62.80,0.434
12.42,63.02,0.435
12.44,63.23,0.437
12.46,63.45,0.439
12.48,63.67,0.440
12.50,63.88,0.442
12.52,64.10,0.444
12.55,64.32,0.445
12.57,64.53,0.446
12.59,64.75,0.448
12.61,64.96,0.450
12.63,65.18,0.452
12.65,65.40,0.454
12.68,65.61,0.456
12.70,65.83,0.457
12.72,66.05,0.459
12.74,66.26,0.460
12.76,66.48,0.462
12.78,66.70,0.464
12.80,66.91,0.465
12.83,67.13,0.467
12.85,67.35,0.470
12.87,67.56,0.472
12.89,67.78,0.474
12.91,68.00,0.475
12.93,68.21,0.477
12.96,68.43,0.478
12.98,68.64,0.480
13.00,68.86,0.482
13.02,69.08,0.484
13.04,69.29,0.487
13.07,69.51,0.489
13.09,69.73,0.490
13.11,69.94,0.492
13.13,70.16,0.495
13.15,70.37,0.497
13.17,70.59,0.499
13.20,70.81,0.502
13.22,71.02,0.505
13.24,71.24,0.508
13.26,71.46,0.509
13.28,71.67,0.511
13.30,71.89,0.513
13.33,72.11,0.515
13.35,72.32,0.517
13.37,72.54,0.519
13.39,72.76,0.521
13.41,72.97,0.523
13.43,73.19,0.525
13.45,73.40,0.528
13.48,73.62,0.530
13.50,73.84,0.532
13.52,74.05,0.534
13.54,74.27,0.536
13.56,74.48,0.539
13.58,74.70,0.541
13.61,74.92,0.545
13.63,75.13,0.548
13.65,75.35,0.551
13.67,75.57,0.553
13.69,75.78,0.556
13.72,76.00,0.557
13.74,76.21,0.560
13.76,76.43,0.563
13.78,76.65,0.566
13.80,76.86,0.568
13.82,77.08,0.571
13.85,77.30,0.574
13.87,77.51,0.577
13.89,77.73,0.581
13.91,77.94,0.584
13.93,78.16,0.587
13.95,78.38,0.589
13.98,78.59,0.591
14.00,78.81,0.594
14.02,79.02,0.597
14.04,79.24,0.600
14.06,79.46,0.603
14.08,79.67,0.606
14.10,79.89,0.609
14.13,80.10,0.612
14.15,80.32,0.616
14.17,80.54,0.618
14.19,80.75,0.621
14.21,80.97,0.624
14.23,81.18,0.628
14.26,81.40,0.632
14.28,81.62,0.635
14.30,81.83,0.638
14.32,82.05,0.642
14.34,82.26,0.645
14.37,82.48,0.649
14.39,82.70,0.652
14.41,82.91,0.656
14.43,83.13,0.659
14.45,83.34,0.663
14.47,83.56,0.665
14.50,83.77,0.669
14.52,83.99,0.674
14.54,84.21,0.677
14.56,84.42,0.681
14.58,84.64,0.685
14.60,84.85,0.688
14.63,85.07,0.691
14.65,85.29,0.695
14.67,85.50,0.699
14.69,85.72,0.702
14.71,85.93,0.706
14.73,86.15,0.710
14.75,86.37,0.714
14.78,86.58,0.717
14.80,86.80,0.722
14.82,87.01,0.725
14.84,87.23,0.728
14.86,87.44,0.731
14.88,87.66,0.735
14.91,87.88,0.739
14.93,88.09,0.743
14.95,88.31,0.747
14.97,88.52,0.751
14.99,88.74,0.755
15.02,88.96,0.759
15.04,89.17,0.764
15.06,89.39,0.768
15.08,89.60,0.771
15.10,89.82,0.775
15.12,90.03,0.779
15.15,90.25,0.783
15.17,90.47,0.787
15.19,90.68,0.791
15.21,90.90,0.796
15.23,91.11,0.800
15.25,91.33,0.804
15.28,91.54,0.808
15.30,91.76,0.812
15.32,91.98,0.815
15.34,92.19,0.820
15.36,92.41,0.823
15.38,92.63,0.828
15.40,92.84,0.832
15.43,93.06,0.836
15.45,93.27,0.840
15.47,93.49,0.843
15.49,93.70,0.848
15.51,93.92,0.852
15.53,94.14,0.856
15.56,94.35,0.861
15.58,94.57,0.865
15.60,94.78,0.869
15.62,95.00,0.873
15.64,95.22,0.877
15.67,95.43,0.882
15.69,95.65,0.886
15.71,95.86,0.890
15.73,96.08,0.895
15.75,96.29,0.899
15.77,96.51,0.903
15.80,96.72,0.907
15.82,96.94,0.911
15.84,97.16,0.916
15.86,97.37,0.921
15.88,97.59,0.925
15.90,97.80,0.929
15.93,98.02,0.934
15.95,98.23,0.939
15.97,98.45,0.943
15.99,98.66,0.947
16.01,98.88,0.952
16.03,99.10,0.957
16.05,99.31,0.962
16.08,99.53,0.967
16.10,99.74,0.971
16.12,99.96,0.977
16.14,100.18,0.981
16.16,100.39,0.985
16.18,100.61,0.990
16.21,100.82,0.994
16.23,101.04,1.000
16.25,101.25,1.004
16.27,101.47,1.009
16.29,101.68,1.014
16.32,101.90,1.019
16.34,102.12,1.024
16.36,102.33,1.029
16.38,102.55,1.034
16.40,102.76,1.039
16.42,102.98,1.043
16.45,103.19,1.048
16.47,103.41,1.054
16.49,103.63,1.058
16.51,103.84,1.063
16.53,104.06,1.068
16.55,104.27,1.074
16.58,104.49,1.079
16.60,104.70,1.083
16.62,104.92,1.088
16.64,105.13,1.093
16.66,105.35,1.097
16.68,105.57,1.103
16.70,105.78,1.108
16.73,106.00,1.113
16.75,106.21,1.118
16.77,106.43,1.122
16.79,106.64,1.127
16.81,106.86,1.132
16.83,107.07,1.136
16.86,107.29,1.141
16.88,107.50,1.146
16.90,107.72,1.152
16.92,107.94,1.156
16.94,108.15,1.160
16.97,108.37,1.166
16.99,108.58,1.170
17.01,108.80,1.175
17.03,109.02,1.179
17.05,109.23,1.183
17.07,109.45,1.188
17.09,109.66,1.192
17.12,109.88,1.196
17.14,110.10,1.200
17.16,110.31,1.205
17.18,110.53,1.208
17.20,110.74,1.213
17.23,110.96,1.217
17.25,111.17,1.220
17.27,111.39,1.224
17.29,111.60,1.227
17.31,111.82,1.231
17.33,112.04,1.234
17.36,112.25,1.238
17.38,112.47,1.241
17.40,112.68,1.244
17.42,112.90,1.247
17.44,113.12,1.250
17.46,113.33,1.253
17.48,113.55,1.256
17.51,113.77,1.258
17.53,113.98,1.261
17.55,114.20,1.264
17.57,114.41,1.266
17.59,114.63,1.268
17.62,114.85,1.269
17.64,115.06,1.270
17.66,115.28,1.272
17.68,115.49,1.273
17.70,115.71,1.275
17.72,115.93,1.276
17.74,116.15,1.277
17.77,116.36,1.278
17.79,116.58,1.278
17.81,116.79,1.279
17.83,117.01,1.280
17.85,117.23,1.281
17.88,117.44,1.281
17.90,117.66,1.282
17.92,117.88,1.282
17.94,118.10,1.283
17.96,118.31,1.283
17.98,118.53,1.283
18.01,118.75,1.284
18.03,118.96,1.284
18.05,119.18,1.284
18.07,119.40,1.284
18.09,119.61,1.283
18.11,119.83,1.283
18.13,120.05,1.283
18.16,120.27,1.282
18.18,120.49,1.280
18.20,120.70,1.279
18.22,120.92,1.277
18.24,121.14,1.275
18.27,121.36,1.272
18.29,121.57,1.268
18.31,121.79,1.265
18.33,122.01,1.261
18.35,122.23,1.258
18.37,122.44,1.255
18.39,122.66,1.251
18.42,122.88,1.247
18.44,123.10,1.242
18.46,123.32,1.239
18.48,123.53,1.235
18.50,123.75,1.231
18.53,123.97,1.227
18.55,124.19,1.222
18.57,124.41,1.217
18.59,124.62,1.213
18.61,124.84,1.208
18.63,125.06,1.203
18.66,125.28,1.198
18.68,125.50,1.192
18.70,125.72,1.187
18.72,125.93,1.182
18.74,126.15,1.177
18.76,126.37,1.171
18.78,126.59,1.165
18.81,126.81,1.159
18.83,127.03,1.155
18.85,127.24,1.148
18.87,127.46,1.143
18.89,127.68,1.137
18.92,127.90,1.131
18.94,128.12,1.125
18.96,128.34,1.119
18.98,128.55,1.114
19.00,128.77,1.107
19.02,128.99,1.102
19.04,129.21,1.096
19.07,129.43,1.090
19.09,129.65,1.084
19.11,129.86,1.077
19.13,130.08,1.072
19.15,130.30,1.065
19.18,130.52,1.059
19.20,130.74,1.052
19.22,130.96,1.047
19.24,131.17,1.041
19.26,131.39,1.036
19.28,131.61,1.030
19.31,131.83,1.023
19.33,132.05,1.018
19.35,132.27,1.012
19.37,132.49,1.005
19.39,132.70,1.000
19.41,132.92,0.994
19.43,133.14,0.988
19.46,133.36,0.982
19.48,133.58,0.976
19.50,133.80,0.969
19.52,134.02,0.964
19.54,134.23,0.958
19.57,134.45,0.952
19.59,134.67,0.947
19.61,134.89,0.941
19.63,135.11,0.935
19.65,135.33,0.928
19.67,135.55,0.922
19.69,135.76,0.916
19.72,135.98,0.911
19.74,136.20,0.906
19.76,136.42,0.900
19.78,136.64,0.895
19.80,136.86,0.889
19.83,137.07,0.883
19.85,137.29,0.878
19.87,137.51,0.872
19.89,137.73,0.867
19.91,137.95,0.861
19.93,138.17,0.856
19.96,138.38,0.851
19.98,138.60,0.845
20.00,138.82,0.839
20.02,139.04,0.835
20.04,139.26,0.830
20.06,139.48,0.824
20.08,139.69,0.819
20.11,139.91,0.814
20.13,140.13,0.809
20.15,140.35,0.803
20.17,140.57,0.799
20.19,140.78,0.794
20.22,141.00,0.789
20.24,141.22,0.784
20.26,141.44,0.780
20.28,141.66,0.775
20.30,141.87,0.769
20.32,142.09,0.765
20.34,142.31,0.760
20.37,142.53,0.755
20.39,142.75,0.751
20.41,142.97,0.747
20.43,143.18,0.742
20.45,143.40,0.737
20.48,143.62,0.732
20.50,143.84,0.727
20.52,144.06,0.723
20.54,144.27,0.719
20.56,144.49,0.714
20.58,144.71,0.710
20.61,144.93,0.705
20.63,145.15,0.701
20.65,145.36,0.698
20.67,145.58,0.693
20.69,145.80,0.688
20.71,146.02,0.685
20.73,146.24,0.680
20.76,146.46,0.676
20.78,146.67,0.672
20.80,146.89,0.667
20.82,147.11,0.664
20.84,147.33,0.659
20.87,147.55,0.655
20.89,147.76,0.651
20.91,147.98,0.647
20.93,148.20,0.643
20.95,148.42,0.639
20.97,148.63,0.635
20.99,148.85,0.631
21.02,149.07,0.628
21.04,149.29,0.624
21.06,149.51,0.621
21.08,149.72,0.616
21.10,149.94,0.613
21.13,150.16,0.609
21.15,150.38,0.605
21.17,150.59,0.601
21.19,150.81,0.598
21.21,151.03,0.594
21.23,151.25,0.591
21.26,151.47,0.587
21.28,151.68,0.584
21.30,151.90,0.581
21.32,152.12,0.578
21.34,152.34,0.574
21.36,152.56,0.570
21.38,152.77,0.567
21.41,152.99,0.563
21.43,153.21,0.560
21.45,153.43,0.557
21.47,153.64,0.553
21.49,153.86,0.550
21.52,154.08,0.547
21.54,154.30,0.543
21.56,154.51,0.540
21.58,154.73,0.537
21.60,154.95,0.534
21.62,155.17,0.531
21.64,155.38,0.528
21.67,155.60,0.525
21.69,155.82,0.522
21.71,156.04,0.519
21.73,156.26,0.516
21.75,156.47,0.513
21.78,156.69,0.510
21.80,156.91,0.506
21.82,157.13,0.504
21.84,157.35,0.501
21.86,157.56,0.499
21.88,157.78,0.495
21.91,158.00,0.492
21.93,158.21,0.489
21.95,158.43,0.486
21.97,158.65,0.483
21.99,158.87,0.481
22.01,159.08,0.479
22.03,159.30,0.477
22.06,159.52,0.474
22.08,159.74,0.471
22.10,159.96,0.468
22.12,160.17,0.466
22.14,160.39,0.463
22.17,160.61,0.460
22.19,160.83,0.458
22.21,161.04,0.456
22.23,161.26,0.453
22.25,161.48,0.451
22.27,161.70,0.448
22.29,161.91,0.446
22.32,162.13,0.444
22.34,162.35,0.441
22.36,162.56,0.439
22.38,162.78,0.437
22.40,163.00,0.434
22.43,163.22,0.432
22.45,163.44,0.430
22.47,163.65,0.427
22.49,163.87,0.425
22.51,164.09,0.424
22.53,164.31,0.422
22.56,164.52,0.420
22.58,164.74,0.418
22.60,164.96,0.415
22.62,165.17,0.413
22.64,165.39,0.410
22.66,165.61,0.407
22.68,165.83,0.406
22.71,166.04,0.404
22.73,166.26,0.403
22.75,166.48,0.402
22.77,166.70,0.400
22.79,166.91,0.398
22.82,167.13,0.396
22.84,167.35,0.394
22.86,167.57,0.392
22.88,167.78,0.391
22.90,168.00,0.389
22.92,168.22,0.387
22.94,168.44,0.386
22.97,168.65,0.384
22.99,168.87,0.383
23.01,169.09,0.381
23.03,169.30,0.379
23.05,169.52,0.378
23.08,169.74,0.376
23.10,169.95,0.374
23.12,170.17,0.373
23.14,170.39,0.372
23.16,170.61,0.371
23.18,170.82,0.370
23.21,171.04,0.369
23.23,171.26,0.368
23.25,171.48,0.367
23.27,171.69,0.365
23.29,171.91,0.364
23.31,172.13,0.364
23.33,172.34,0.362
23.36,172.56,0.361
23.38,172.78,0.360
23.40,173.00,0.359
23.42,173.21,0.358
23.44,173.43,0.357
23.47,173.65,0.356
23.49,173.86,0.356
23.51,174.08,0.355
23.53,174.30,0.354
23.55,174.51,0.353
23.57,174.73,0.352
23.59,174.95,0.352
23.62,175.16,0.351
23.64,175.38,0.350
23.66,175.60,0.350
23.68,175.82,0.349
23.70,176.03,0.349
23.73,176.25,0.348
23.75,176.47,0.348
23.77,176.68,0.347
23.79,176.90,0.347
23.81,177.12,0.347
23.83,177.33,0.346
23.86,177.55,0.346
23.88,177.77,0.346
23.90,177.98,0.346
23.92,178.20,0.346
23.94,178.42,0.346
23.96,178.63,0.346
23.98,178.85,0.346
24.01,179.07,0.346
24.03,179.29,0.346
24.05,179.50,0.347
24.07,179.72,0.347
24.09,179.94,0.347
24.12,180.15,0.348
24.14,180.37,0.348
24.16,180.58,0.349
24.18,180.80,0.349
24.20,181.02,0.350
24.22,181.23,0.350
24.24,181.45,0.351
24.27,181.67,0.351
24.29,181.88,0.351
24.31,182.10,0.351
24.33,182.32,0.352
24.35,182.54,0.352
24.38,182.75,0.352
24.40,182.97,0.351
24.42,183.19,0.351
24.44,183.40,0.351
24.46,183.62,0.349
24.48,183.84,0.348
24.51,184.05,0.347
24.53,184.27,0.346
24.55,184.49,0.345
24.57,184.71,0.345
24.59,184.92,0.344
24.61,185.14,0.344
24.63,185.36,0.343
24.66,185.58,0.342
24.68,185.79,0.342
24.70,186.01,0.341
24.72,186.23,0.341
24.74,186.44,0.340
24.77,186.66,0.340
24.79,186.88,0.340
24.81,187.09,0.339
24.83,187.31,0.339
24.85,187.53,0.339
24.87,187.74,0.339
24.89,187.96,0.339
24.92,188.18,0.339
24.94,188.39,0.339
24.96,188.61,0.339
24.98,188.83,0.339
25.00,189.04,0.339
25.03,189.26,0.339
25.05,189.48,0.339
25.07,189.69,0.339
25.09,189.91,0.339
25.11,190.13,0.339
25.13,190.34,0.339
25.16,190.56,0.340
25.18,190.78,0.340
25.20,190.99,0.340
25.22,191.21,0.340
25.24,191.43,0.341
25.26,191.64,0.341
25.28,191.86,0.341
25.31,192.08,0.342
25.33,192.29,0.342
25.35,192.51,0.342
25.37,192.73,0.342
25.39,192.94,0.343
25.42,193.16,0.343
25.44,193.38,0.343
25.46,193.59,0.344
25.48,193.81,0.344
25.50,194.03,0.344
25.52,194.25,0.344
25.54,194.46,0.345
25.57,194.68,0.345
25.59,194.90,0.345
25.61,195.12,0.345
25.63,195.33,0.345
25.65,195.55,0.346
25.68,195.76,0.346
25.70,195.98,0.346
25.72,196.20,0.346
25.74,196.41,0.347
25.76,196.63,0.347
25.78,196.85,0.347
25.81,197.06,0.347
25.83,197.28,0.347
25.85,197.50,0.347
25.87,197.71,0.347
25.89,197.93,0.347
25.91,198.15,0.348
25.93,198.36,0.348
25.96,198.58,0.348
25.98,198.80,0.348
26.00,199.01,0.348
26.02,199.23,0.348
26.04,199.45,0.349
26.07,199.66,0.349
26.09,199.88,0.349
26.11,200.10,0.349
26.13,200.32,0.349
26.15,200.53,0.349
26.17,200.75,0.350
26.19,200.97,0.350
26.22,201.18,0.350
26.24,201.40,0.350
26.26,201.62,0.350
26.28,201.83,0.350
26.30,202.05,0.350
26.33,202.27,0.350
26.35,202.48,0.350
26.37,202.70,0.350
26.39,202.92,0.350
26.41,203.13,0.350
26.43,203.35,0.350
26.46,203.57,0.351
26.48,203.79,0.351
26.50,204.00,0.351
26.52,204.22,0.351
26.54,204.44,0.351
26.56,204.65,0.351
26.58,204.87,0.351
26.61,205.09,0.351
26.63,205.30,0.351
26.65,205.52,0.351
26.67,205.74,0.351
26.69,205.95,0.352
26.72,206.17,0.352
26.74,206.39,0.352
26.76,206.61,0.352
26.78,206.82,0.352
26.80,207.04,0.352
26.82,207.26,0.352
26.84,207.47,0.352
26.87,207.69,0.352
26.89,207.90,0.352
26.91,208.12,0.352
26.93,208.34,0.352
26.95,208.55,0.352
26.98,208.77,0.352
27.00,208.99,0.353
27.02,209.20,0.353
27.04,209.42,0.353
27.06,209.64,0.353
27.08,209.86,0.353
27.11,210.07,0.353
27.13,210.29,0.353
27.15,210.51,0.353
27.17,210.72,0.353
27.19,210.94,0.353
27.21,211.16,0.353
27.23,211.38,0.354
27.26,211.59,0.354
27.28,211.81,0.354
27.30,212.02,0.354
27.32,212.24,0.354
27.34,212.46,0.354
27.37,212.67,0.354
27.39,212.89,0.354
27.41,213.11,0.354
27.43,213.32,0.354
27.45,213.54,0.354
27.47,213.76,0.354
27.49,213.97,0.354
27.52,214.19,0.354
27.54,214.41,0.355
27.56,214.63,0.355
27.58,214.84,0.355
27.60,215.06,0.355
27.63,215.28,0.355
27.65,215.49,0.355
27.67,215.71,0.355
27.69,215.93,0.355
27.71,216.14,0.356
27.73,216.36,0.356
27.76,216.58,0.356
27.78,216.79,0.356
27.80,217.01,0.356
27.82,217.23,0.356
27.84,217.44,0.356
27.86,217.66,0.356
27.88,217.88,0.356
27.91,218.09,0.356
27.93,218.31,0.356
27.95,218.53,0.356
27.97,218.74,0.357
27.99,218.96,0.357
28.02,219.18,0.357
28.04,219.40,0.357
28.06,219.61,0.357
28.08,219.83,0.357
28.10,220.04,0.357
28.12,220.26,0.357
28.14,220.48,0.357
28.17,220.69,0.357
28.19,220.91,0.357
28.21,221.13,0.358
28.23,221.34,0.358
28.25,221.56,0.358
28.28,221.78,0.358
28.30,222.00,0.358
28.32,222.21,0.358
28.34,222.43,0.358
28.36,222.64,0.358
28.38,222.86,0.358
28.41,223.08,0.359
28.43,223.30,0.359
28.45,223.51,0.359
28.47,223.73,0.359
28.49,223.95,0.359
28.51,224.17,0.359
28.53,224.38,0.360
28.56,224.60,0.360
28.58,224.82,0.360
28.60,225.03,0.360
28.62,225.25,0.360
28.64,225.47,0.360
28.67,225.68,0.360
28.69,225.90,0.360
28.71,226.12,0.360
28.73,226.33,0.360
28.75,226.55,0.360
28.77,226.77,0.360
28.79,226.98,0.360
28.82,227.20,0.360
28.84,227.42,0.360
28.86,227.63,0.360
28.88,227.85,0.360
28.90,228.07,0.361
28.93,228.28,0.361
28.95,228.50,0.361
28.97,228.72,0.361
28.99,228.93,0.361
29.01,229.15,0.361
29.03,229.37,0.361
29.06,229.58,0.361
29.08,229.80,0.361
29.10,230.02,0.362
29.12,230.24,0.362
29.14,230.45,0.362
29.16,230.67,0.362
29.18,230.89,0.362
29.21,231.10,0.362
29.23,231.32,0.362
29.25,231.53,0.362
29.27,231.75,0.362
29.29,231.97,0.362
29.32,232.19,0.362
29.34,232.40,0.362
29.36,232.62,0.363
29.38,232.84,0.363
29.40,233.05,0.363
29.42,233.27,0.363
29.44,233.48,0.363
29.47,233.70,0.363
29.49,233.92,0.363
29.51,234.14,0.363
29.53,234.35,0.363
29.55,234.57,0.363
29.58,234.79,0.364
29.60,235.00,0.364
29.62,235.22,0.364
29.64,235.44,0.364
29.66,235.65,0.364
29.68,235.87,0.364
29.71,236.09,0.364
29.73,236.30,0.364
29.75,236.52,0.364
29.77,236.74,0.364
29.79,236.95,0.364
29.81,237.17,0.365
29.83,237.39,0.365
29.86,237.60,0.365
29.88,237.82,0.365
29.90,238.04,0.365
29.92,238.25,0.365
29.94,238.47,0.365
29.97,238.69,0.365
29.99,238.91,0.365
30.01,239.12,0.365
30.03,239.34,0.366
30.05,239.55,0.366
30.07,239.77,0.366
30.09,239.99,0.366
30.12,240.21,0.366
30.14,240.42,0.366
30.16,240.64,0.366
30.18,240.86,0.366
30.20,241.07,0.366
30.23,241.29,0.366
30.25,241.51,0.367
30.27,241.72,0.367
30.29,241.94,0.367
30.31,242.16,0.367
30.33,242.37,0.367
30.36,242.59,0.367
30.38,242.81,0.367
30.40,243.02,0.367
30.42,243.24,0.367
30.44,243.46,0.367
30.46,243.67,0.367
30.48,243.89,0.367
30.51,244.11,0.368
30.53,244.32,0.368
30.55,244.54,0.368
30.57,244.76,0.368
30.59,244.97,0.368
30.62,245.19,0.368
30.64,245.41,0.368
30.66,245.62,0.368
30.68,245.84,0.368
30.70,246.06,0.368
30.72,246.28,0.369
30.74,246.49,0.369
30.77,246.71,0.369
30.79,246.93,0.369
30.81,247.14,0.369
30.83,247.36,0.369
30.85,247.58,0.369
30.88,247.79,0.369
30.90,248.01,0.369
30.92,248.23,0.369
30.94,248.44,
30.96,248.66,
30.98,248.88,
30.99,,

[step]
Ramp 10.00 °C/min to -60.00 °C
Time,Temperature,Heat Flow (Normalized)
min,°C,W/g
32.99,250.17,-0.045
33.02,250.17,-0.045
33.04,250.16,-0.045
33.06,250.14,-0.043
33.08,250.09,-0.042
33.10,250.01,-0.084
33.12,249.89,-0.147
33.14,249.74,-0.218
33.17,249.57,-0.287
33.19,249.38,-0.342
33.21,249.19,-0.380
33.23,248.98,-0.408
33.25,248.78,-0.424
33.28,248.57,-0.434
33.30,248.36,-0.441
33.32,248.14,-0.446
33.34,247.93,-0.448
33.36,247.72,-0.450
33.38,247.50,-0.451
33.41,247.29,-0.452
33.43,247.08,-0.453
33.45,246.86,-0.454
33.47,246.64,-0.455
33.49,246.43,-0.455
33.51,246.21,-0.455
33.53,246.00,-0.456
33.56,245.79,-0.456
33.58,245.57,-0.456
33.60,245.35,-0.456
33.62,245.14,-0.457
33.64,244.92,-0.457
33.67,244.71,-0.457
33.69,244.49,-0.457
33.71,244.28,-0.457
33.73,244.06,-0.458
33.75,243.85,-0.458
33.77,243.63,-0.458
33.79,243.42,-0.458
33.82,243.20,-0.458
33.84,242.99,-0.458
33.86,242.77,-0.458
33.88,242.55,-0.458
33.90,242.34,-0.458
33.93,242.12,-0.459
33.95,241.91,-0.459
33.97,241.69,-0.459
33.99,241.48,-0.459
34.01,241.26,-0.459
34.03,241.05,-0.458
34.06,240.83,-0.458
34.08,240.61,-0.458
34.10,240.40,-0.458
34.12,240.18,-0.458
34.14,239.96,-0.458
34.16,239.75,-0.458
34.19,239.53,-0.458
34.21,239.32,-0.458
34.23,239.10,-0.458
34.25,238.89,-0.458
34.27,238.67,-0.458
34.29,238.45,-0.457
34.31,238.24,-0.457
34.34,238.02,-0.457
34.36,237.80,-0.457
34.38,237.59,-0.457
34.40,237.37,-0.457
34.42,237.15,-0.457
34.44,236.94,-0.457
34.47,236.72,-0.457
34.49,236.51,-0.457
34.51,236.29,-0.457
34.53,236.07,-0.457
34.55,235.86,-0.457
34.58,235.64,-0.456
34.60,235.42,-0.456
34.62,235.21,-0.456
34.64,234.99,-0.456
34.66,234.78,-0.456
34.68,234.56,-0.456
34.71,234.34,-0.456
34.73,234.13,-0.456
34.75,233.91,-0.456
34.77,233.69,-0.455
34.79,233.48,-0.455
34.81,233.26,-0.455
34.84,233.04,-0.455
34.86,232.83,-0.455
34.88,232.61,-0.455
34.90,232.40,-0.455
34.92,232.18,-0.455
34.94,231.96,-0.454
34.96,231.75,-0.454
34.99,231.53,-0.454
35.01,231.31,-0.454
35.03,231.10,-0.454
35.05,230.88,-0.454
35.07,230.66,-0.454
35.09,230.45,-0.454
35.12,230.23,-0.454
35.14,230.01,-0.454
35.16,229.80,-0.453
35.18,229.58,-0.453
35.20,229.36,-0.453
35.23,229.15,-0.453
35.25,228.93,-0.453
35.27,228.72,-0.453
35.29,228.50,-0.453
35.31,228.28,-0.453
35.33,228.06,-0.453
35.36,227.85,-0.452
35.38,227.63,-0.452
35.40,227.41,-0.452
35.42,227.20,-0.452
35.44,226.98,-0.452
35.46,226.77,-0.452
35.49,226.55,-0.452
35.51,226.33,-0.452
35.53,226.12,-0.451
35.55,225.90,-0.451
35.57,225.68,-0.451
35.59,225.47,-0.451
35.61,225.25,-0.451
35.64,225.03,-0.451
35.66,224.82,-0.451
35.68,224.60,-0.451
35.70,224.38,-0.451
35.72,224.17,-0.451
35.74,223.95,-0.451
35.77,223.73,-0.451
35.79,223.52,-0.450
35.81,223.30,-0.450
35.83,223.08,-0.450
35.85,222.87,-0.450
35.88,222.65,-0.450
35.90,222.43,-0.450
35.92,222.22,-0.450
35.94,222.00,-0.450
35.96,221.78,-0.450
35.98,221.57,-0.450
36.01,221.35,-0.450
36.03,221.14,-0.450
36.05,220.92,-0.449
36.07,220.70,-0.449
36.09,220.49,-0.449
36.11,220.27,-0.449
36.14,220.05,-0.449
36.16,219.84,-0.449
36.18,219.62,-0.449
36.20,219.40,-0.449
36.22,219.19,-0.448
36.24,218.97,-0.448
36.26,218.75,-0.448
36.29,218.54,-0.448
36.31,218.32,-0.448
36.33,218.10,-0.448
36.35,217.89,-0.448
36.37,217.67,-0.448
36.39,217.45,-0.448
36.42,217.24,-0.448
36.44,217.02,-0.447
36.46,216.80,-0.447
36.48,216.59,-0.447
36.50,216.37,-0.447
36.53,216.15,-0.447
36.55,215.94,-0.447
36.57,215.72,-0.447
36.59,215.50,-0.447
36.61,215.29,-0.446
36.63,215.07,-0.446
36.66,214.85,-0.446
36.68,214.64,-0.446
36.70,214.42,-0.446
36.72,214.20,-0.446
36.74,213.99,-0.446
36.76,213.77,-0.446
36.79,213.56,-0.446
36.81,213.34,-0.446
36.83,213.12,-0.445
36.85,212.91,-0.445
36.87,212.69,-0.445
36.89,212.47,-0.445
36.91,212.26,-0.445
36.94,212.04,-0.445
36.96,211.82,-0.445
36.98,211.61,-0.445
37.00,211.39,-0.445
37.02,211.17,-0.444
37.04,210.96,-0.444
37.07,210.74,-0.444
37.09,210.52,-0.444
37.11,210.31,-0.444
37.13,210.09,-0.444
37.15,209.87,-0.444
37.18,209.66,-0.444
37.20,209.44,-0.444
37.22,209.22,-0.444
37.24,209.01,-0.443
37.26,208.79,-0.443
37.28,208.57,-0.443
37.31,208.36,-0.443
37.33,208.14,-0.443
37.35,207.92,-0.443
37.37,207.71,-0.443
37.39,207.49,-0.443
37.41,207.27,-0.443
37.44,207.06,-0.443
37.46,206.84,-0.442
37.48,206.62,-0.442
37.50,206.41,-0.442
37.52,206.19,-0.442
37.54,205.97,-0.442
37.56,205.76,-0.442
37.59,205.54,-0.442
37.61,205.33,-0.442
37.63,205.11,-0.442
37.65,204.89,-0.442
37.67,204.68,-0.442
37.69,204.46,-0.441
37.72,204.24,-0.441
37.74,204.03,-0.441
37.76,203.81,-0.441
37.78,203.59,-0.441
37.80,203.38,-0.441
37.83,203.16,-0.441
37.85,202.94,-0.441
37.87,202.73,-0.441
37.89,202.51,-0.441
37.91,202.29,-0.441
37.93,202.07,-0.441
37.96,201.86,-0.441
37.98,201.64,-0.441
38.00,201.43,-0.441
38.02,201.21,-0.441
38.04,200.99,-0.440
38.06,200.78,-0.440
38.09,200.56,-0.440
38.11,200.34,-0.440
38.13,200.13,-0.440
38.15,199.91,-0.440
38.17,199.69,-0.440
38.19,199.48,-0.440
38.21,199.26,-0.440
38.24,199.04,-0.440
38.26,198.83,-0.439
38.28,198.61,-0.439
38.30,198.39,-0.439
38.32,198.18,-0.439
38.34,197.96,-0.439
38.37,197.74,-0.439
38.39,197.53,-0.439
38.41,197.31,-0.439
38.43,197.09,-0.439
38.45,196.88,-0.439
38.48,196.66,-0.439
38.50,196.44,-0.439
38.52,196.23,-0.438
38.54,196.01,-0.438
38.56,195.79,-0.438
38.58,195.58,-0.438
38.61,195.36,-0.438
38.63,195.14,-0.438
38.65,194.93,-0.438
38.67,194.71,-0.438
38.69,194.49,-0.438
38.71,194.28,-0.437
38.74,194.06,-0.437
38.76,193.85,-0.437
38.78,193.63,-0.437
38.80,193.41,-0.437
38.82,193.20,-0.437
38.84,192.98,-0.437
38.86,192.76,-0.437
38.89,192.54,-0.437
38.91,192.33,-0.436
38.93,192.11,-0.436
38.95,191.90,-0.436
38.97,191.68,-0.436
38.99,191.46,-0.436
39.02,191.25,-0.436
39.04,191.03,-0.436
39.06,190.81,-0.436
39.08,190.60,-0.436
39.10,190.38,-0.436
39.13,190.16,-0.435
39.15,189.95,-0.435
39.17,189.73,-0.435
39.19,189.51,-0.435
39.21,189.30,-0.435
39.23,189.08,-0.435
39.26,188.86,-0.434
39.28,188.65,-0.434
39.30,188.43,-0.434
39.32,188.21,-0.434
39.34,188.00,-0.434
39.36,187.78,-0.434
39.39,187.56,-0.434
39.41,187.35,-0.434
39.43,187.13,-0.433
39.45,186.91,-0.433
39.47,186.70,-0.433
39.49,186.48,-0.433
39.51,186.27,-0.433
39.54,186.05,-0.432
39.56,185.83,-0.432
39.58,185.61,-0.432
39.60,185.40,-0.432
39.62,185.18,-0.432
39.64,184.96,-0.432
39.67,184.75,-0.432
39.69,184.53,-0.431
39.71,184.31,-0.431
39.73,184.10,-0.431
39.75,183.88,-0.431
39.78,183.66,-0.431
39.80,183.45,-0.430
39.82,183.23,-0.430
39.84,183.01,-0.430
39.86,182.80,-0.429
39.88,182.58,-0.429
39.91,182.36,-0.429
39.93,182.15,-0.429
39.95,181.93,-0.428
39.97,181.71,-0.428
39.99,181.50,-0.428
40.01,181.28,-0.428
40.04,181.06,-0.427
40.06,180.85,-0.426
40.08,180.63,-0.426
40.10,180.41,-0.425
40.12,180.20,-0.425
40.14,179.98,-0.425
40.16,179.76,-0.424
40.19,179.55,-0.424
40.21,179.33,-0.423
40.23,179.11,-0.423
40.25,178.90,-0.422
40.27,178.68,-0.422
40.29,178.46,-0.421
40.32,178.25,-0.421
40.34,178.03,-0.420
40.36,177.81,-0.419
40.38,177.60,-0.419
40.40,177.38,-0.418
40.43,177.17,-0.418
40.45,176.95,-0.417
40.47,176.73,-0.417
40.49,176.51,-0.416
40.51,176.30,-0.416
40.53,176.08,-0.415
40.56,175.86,-0.415
40.58,175.65,-0.414
40.60,175.43,-0.413
40.62,175.21,-0.413
40.64,175.00,-0.412
40.66,174.78,-0.412
40.69,174.56,-0.411
40.71,174.35,-0.410
40.73,174.13,-0.410
40.75,173.91,-0.409
40.77,173.70,-0.409
40.79,173.48,-0.408
40.81,173.26,-0.407
40.84,173.05,-0.407
40.86,172.83,-0.406
40.88,172.61,-0.406
40.90,172.40,-0.405
40.92,172.18,-0.405
40.94,171.96,-0.404
40.97,171.74,-0.404
40.99,171.53,-0.403
41.01,171.31,-0.403
41.03,171.09,-0.402
41.05,170.88,-0.402
41.08,170.66,-0.401
41.10,170.44,-0.401
41.12,170.23,-0.400
41.14,170.01,-0.400
41.16,169.79,-0.399
[...]
140.99,28.65,0.213
141.01,28.86,0.213
141.03,29.08,0.213
141.05,29.30,0.214
141.07,29.52,0.214
141.10,29.73,0.214
141.12,29.95,0.214
141.14,30.17,0.214
141.16,30.38,0.214
141.18,30.60,0.214
141.20,30.82,0.214
141.23,31.03,0.215
141.25,31.25,0.215
141.27,31.47,0.215
141.29,31.68,0.215
141.31,31.90,0.215
141.33,32.12,0.215
141.35,32.33,0.215
141.38,32.55,0.215
141.40,32.77,0.215
141.42,32.99,0.216
141.44,33.20,0.216
141.46,33.42,0.216
141.48,33.64,0.216
141.51,33.85,0.216
141.53,34.07,0.216
141.55,34.29,0.216
141.57,34.51,0.216
141.59,34.72,0.217
141.62,34.94,0.217
141.64,35.15,0.217
141.66,35.37,0.217
141.68,35.59,0.217
141.70,35.81,0.217
141.72,36.02,0.217
141.75,36.24,0.217
141.77,36.46,0.217
141.79,36.67,0.218
141.81,36.89,0.218
141.83,37.11,0.218
141.85,37.32,0.218
141.88,37.54,0.218
141.90,37.76,0.218
141.92,37.97,0.218
141.94,38.19,0.218
141.96,38.41,0.218
141.98,38.63,0.218
142.00,38.84,0.219
142.03,39.06,0.219
142.05,39.28,0.219
142.07,39.49,0.219
142.09,39.71,0.219
142.11,39.93,0.219
142.13,40.14,0.219
142.16,40.36,0.219
142.18,40.58,0.219
142.20,40.79,0.220
142.22,41.01,0.220
142.24,41.23,0.220
142.27,41.44,0.220
142.29,41.66,0.220
142.31,41.88,0.220
142.33,42.09,0.220
142.35,42.31,0.220
142.37,42.53,0.221
142.40,42.74,0.221
142.42,42.96,0.221
142.44,43.18,0.221
142.46,43.40,0.221
142.48,43.61,0.221
142.50,43.83,0.221
142.53,44.05,0.221
142.55,44.26,0.221
142.57,44.48,0.222
142.59,44.70,0.222
142.61,44.91,0.222
142.63,45.13,0.222
142.65,45.35,0.222
142.68,45.56,0.222
142.70,45.78,0.222
142.72,46.00,0.222
142.74,46.22,0.223
142.76,46.43,0.223
142.78,46.65,0.223
142.81,46.87,0.223
142.83,47.08,0.223
142.85,47.30,0.223
142.87,47.52,0.223
142.89,47.74,0.223
142.92,47.95,0.224
142.94,48.17,0.224
142.96,48.38,0.224
142.98,48.60,0.224
143.00,48.82,0.224
143.02,49.04,0.224
143.05,49.25,0.224
143.07,49.47,0.224
143.09,49.69,0.225
143.11,49.90,0.225
143.13,50.12,0.225
143.15,50.34,0.225
143.18,50.55,0.225
143.20,50.77,0.225
143.22,50.99,0.225
143.24,51.20,0.225
143.26,51.42,0.226
143.28,51.64,0.226
143.30,51.85,0.226
143.33,52.07,0.226
143.35,52.29,0.226
143.37,52.51,0.226
143.39,52.72,0.226
143.41,52.94,0.226
143.43,53.15,0.227
143.46,53.37,0.227
143.48,53.59,0.227
143.50,53.81,0.227
143.52,54.02,0.227
143.54,54.24,0.227
143.57,54.46,0.227
143.59,54.67,0.227
143.61,54.89,0.228
143.63,55.11,0.228
143.65,55.32,0.228
143.67,55.54,0.228
143.70,55.76,0.228
143.72,55.97,0.228
143.74,56.19,0.228
143.76,56.41,0.228
143.78,56.63,0.228
143.80,56.84,0.229
143.83,57.06,0.229
143.85,57.28,0.229
143.87,57.49,0.229
143.89,57.71,0.229
143.91,57.93,0.229
143.93,58.14,0.229
143.95,58.36,0.229
143.98,58.58,0.230
144.00,58.79,0.230
144.02,59.01,0.230
144.04,59.23,0.230
144.06,59.44,0.230
144.08,59.66,0.230
144.11,59.88,0.230
144.13,60.09,0.230
144.15,60.31,0.230
144.17,60.53,0.231
144.19,60.74,0.231
144.22,60.96,0.231
144.24,61.18,0.231
144.26,61.40,0.231
144.28,61.61,0.231
144.30,61.83,0.231
144.32,62.05,0.231
144.35,62.26,0.232
144.37,62.48,0.232
144.39,62.70,0.232
144.41,62.91,0.232
144.43,63.13,0.232
144.45,63.35,0.232
144.48,63.56,0.232
144.50,63.78,0.232
144.52,64.00,0.232
144.54,64.21,0.233
144.56,64.43,0.233
144.58,64.65,0.233
144.60,64.87,0.233
144.63,65.08,0.233
144.65,65.30,0.233
144.67,65.52,0.233
144.69,65.73,0.234
144.71,65.95,0.234
144.73,66.17,0.234
144.76,66.38,0.234
144.78,66.60,0.234
144.80,66.82,0.234
144.82,67.04,0.234
144.84,67.25,0.234
144.87,67.47,0.234
144.89,67.69,0.234
144.91,67.90,0.235
144.93,68.12,0.235
144.95,68.34,0.235
144.97,68.55,0.235
145.00,68.77,0.235
145.02,68.99,0.235
145.04,69.21,0.235
145.06,69.42,0.236
145.08,69.64,0.236
145.10,69.86,0.236
145.13,70.07,0.236
145.15,70.29,0.236
145.17,70.51,0.236
145.19,70.72,0.236
145.21,70.94,0.236
145.23,71.16,0.237
145.25,71.37,0.237
145.28,71.59,0.237
145.30,71.81,0.237
145.32,72.02,0.237
145.34,72.24,0.237
145.36,72.46,0.237
145.38,72.68,0.237
145.41,72.90,0.238
145.43,73.11,0.238
145.45,73.33,0.238
145.47,73.55,0.238
145.49,73.77,0.239
145.52,73.98,0.239
145.54,74.20,0.239
145.56,74.42,0.239
145.58,74.63,0.239
145.60,74.85,0.239
145.62,75.07,0.239
145.65,75.28,0.239
145.67,75.50,0.239
145.69,75.72,0.239
145.71,75.93,0.239
145.73,76.15,0.239
145.75,76.37,0.239
145.78,76.59,0.239
145.80,76.80,0.239
145.82,77.02,0.239
145.84,77.23,0.239
145.86,77.45,0.240
145.88,77.67,0.240
145.90,77.88,0.240
145.93,78.10,0.240
145.95,78.32,0.240
145.97,78.53,0.240
145.99,78.75,0.240
146.01,78.97,0.240
146.03,79.18,0.240
146.06,79.40,0.240
146.08,79.62,0.240
146.10,79.83,0.241
146.12,80.05,0.241
146.14,80.27,0.241
146.17,80.48,0.241
146.19,80.70,0.241
146.21,80.92,0.241
146.23,81.13,0.241
146.25,81.35,0.241
146.27,81.56,0.241
146.30,81.78,0.242
146.32,82.00,0.242
146.34,82.22,0.242
146.36,82.43,0.242
146.38,82.65,0.242
146.40,82.87,0.242
146.43,83.08,0.242
146.45,83.30,0.242
146.47,83.52,0.242
146.49,83.73,0.243
146.51,83.95,0.243
146.53,84.17,0.243
146.55,84.38,0.243
146.58,84.60,0.243
146.60,84.82,0.243
146.62,85.03,0.243
146.64,85.25,0.243
146.66,85.47,0.244
146.68,85.69,0.244
146.71,85.90,0.244
146.73,86.12,0.244
146.75,86.34,0.244
146.77,86.55,0.244
146.79,86.77,0.244
146.82,86.98,0.244
146.84,87.20,0.244
146.86,87.42,0.245
146.88,87.64,0.245
146.90,87.85,0.245
146.92,88.07,0.245
146.95,88.29,0.245
146.97,88.50,0.245
146.99,88.72,0.245
147.01,88.94,0.245
147.03,89.16,0.246
147.05,89.37,0.246
147.08,89.59,0.246
147.10,89.81,0.246
147.12,90.02,0.246
147.14,90.24,0.246
147.16,90.46,0.246
147.18,90.67,0.246
147.20,90.89,0.247
147.23,91.11,0.247
147.25,91.32,0.247
147.27,91.54,0.247
147.29,91.76,0.247
147.31,91.97,0.247
147.33,92.19,0.247
147.36,92.41,0.247
147.38,92.62,0.248
147.40,92.84,0.248
147.42,93.06,0.248
147.44,93.28,0.248
147.47,93.49,0.248
147.49,93.71,0.248
147.51,93.93,0.248
147.53,94.14,0.249
147.55,94.36,0.249
147.57,94.58,0.249
147.60,94.79,0.249
147.62,95.01,0.249
147.64,95.23,0.249
147.66,95.44,0.249
147.68,95.66,0.250
147.70,95.88,0.250
147.73,96.09,0.250
147.75,96.31,0.250
147.77,96.53,0.250
147.79,96.74,0.250
147.81,96.96,0.250
147.83,97.18,0.250
147.85,97.39,0.250
147.88,97.61,0.250
147.90,97.83,0.251
147.92,98.04,0.251
147.94,98.26,0.251
147.96,98.48,0.251
147.98,98.69,0.251
148.01,98.91,0.251
148.03,99.13,0.252
148.05,99.35,0.252
148.07,99.56,0.252
148.09,99.78,0.252
148.12,100.00,0.252
148.14,100.21,0.252
148.16,100.43,0.253
148.18,100.65,0.253
148.20,100.86,0.253
148.22,101.08,0.253
148.25,101.30,0.253
148.27,101.51,0.253
148.29,101.73,0.253
148.31,101.95,0.253
148.33,102.17,0.254
148.35,102.38,0.254
148.38,102.60,0.254
148.40,102.82,0.254
148.42,103.03,0.254
148.44,103.25,0.254
148.46,103.47,0.254
148.48,103.68,0.255
148.50,103.90,0.255
148.53,104.12,0.255
148.55,104.33,0.255
148.57,104.55,0.255
148.59,104.77,0.255
148.61,104.98,0.255
148.63,105.20,0.255
148.66,105.42,0.255
148.68,105.64,0.255
148.70,105.85,0.256
148.72,106.07,0.256
148.74,106.29,0.256
148.77,106.50,0.256
148.79,106.72,0.256
148.81,106.94,0.256
148.83,107.15,0.256
148.85,107.37,0.256
148.87,107.59,0.256
148.90,107.80,0.257
148.92,108.02,0.257
148.94,108.24,0.257
148.96,108.45,0.257
148.98,108.67,0.257
149.00,108.89,0.257
149.03,109.10,0.257
149.05,109.32,0.258
149.07,109.54,0.258
149.09,109.75,0.258
149.11,109.97,0.258
149.13,110.19,0.258
149.15,110.40,0.258
149.18,110.62,0.258
149.20,110.84,0.258
149.22,111.05,0.258
149.24,111.27,0.259
149.26,111.49,0.259
149.28,111.70,0.259
149.31,111.92,0.259
149.33,112.14,0.259
149.35,112.36,0.259
149.37,112.57,0.259
149.39,112.79,0.260
149.42,113.01,0.260
149.44,113.22,0.260
149.46,113.44,0.260
149.48,113.66,0.260
149.50,113.87,0.260
149.52,114.09,0.261
149.55,114.31,0.261
149.57,114.53,0.261
149.59,114.74,0.261
149.61,114.96,0.261
149.63,115.18,0.261
149.65,115.39,0.261
149.68,115.61,0.261
149.70,115.83,0.262
149.72,116.04,0.262
149.74,116.26,0.262
149.76,116.47,0.262
149.78,116.69,0.262
149.80,116.91,0.262
149.83,117.12,0.262
149.85,117.34,0.262
149.87,117.56,0.262
149.89,117.78,0.262
149.91,117.99,0.263
149.93,118.21,0.263
149.96,118.43,0.263
149.98,118.64,0.263
150.00,118.86,0.263
150.02,119.08,0.263
150.04,119.29,0.263
150.07,119.51,0.263
150.09,119.73,0.264
150.11,119.95,0.264
150.13,120.16,0.264
150.15,120.38,0.264
150.17,120.60,0.264
150.20,120.81,0.264
150.22,121.03,0.264
150.24,121.25,0.264
150.26,121.46,0.264
150.28,121.68,0.264
150.30,121.90,0.265
150.33,122.11,0.265
150.35,122.33,0.265
150.37,122.55,0.265
150.39,122.76,0.265
150.41,122.98,0.265
150.43,123.20,0.265
150.45,123.41,0.265
150.48,123.63,0.265
150.50,123.85,0.265
150.52,124.07,0.266
150.54,124.28,0.266
150.56,124.50,0.266
150.58,124.72,0.266
150.61,124.93,0.266
150.63,125.15,0.266
150.65,125.37,0.266
150.67,125.58,0.266
150.69,125.80,0.267
150.72,126.01,0.267
150.74,126.23,0.267
150.76,126.45,0.267
150.78,126.67,0.267
150.80,126.89,0.267
150.82,127.10,0.267
150.85,127.32,0.267
150.87,127.53,0.268
150.89,127.75,0.268
150.91,127.97,0.268
150.93,128.18,0.268
150.95,128.40,0.268
150.98,128.62,0.268
151.00,128.83,0.268
151.02,129.05,0.268
151.04,129.27,0.269
151.06,129.49,0.269
151.08,129.70,0.269
151.10,129.92,0.269
151.13,130.14,0.269
151.15,130.35,0.269
151.17,130.57,0.269
151.19,130.79,0.269
151.21,131.00,0.269
151.23,131.22,0.270
151.26,131.44,0.270
151.28,131.65,0.270
151.30,131.87,0.270
151.32,132.09,0.270
151.34,132.30,0.270
151.37,132.52,0.270
151.39,132.74,0.271
151.41,132.95,0.271
151.43,133.17,0.271
151.45,133.39,0.271
151.47,133.60,0.271
151.50,133.82,0.271
151.52,134.04,0.271
151.54,134.26,0.272
151.56,134.47,0.272
151.58,134.69,0.272
151.60,134.91,0.272
151.63,135.12,0.272
151.65,135.34,0.272
151.67,135.56,0.272
151.69,135.77,0.272
151.71,135.99,0.272
151.73,136.21,0.273
151.75,136.42,0.273
151.78,136.64,0.273
151.80,136.86,0.273
151.82,137.07,0.273
151.84,137.29,0.273
151.86,137.51,0.273
151.88,137.73,0.273
151.91,137.94,0.273
151.93,138.16,0.273
151.95,138.38,0.274
151.97,138.59,0.274
151.99,138.81,0.274
152.02,139.03,0.274
152.04,139.24,0.274
152.06,139.46,0.274
152.08,139.68,0.274
152.10,139.89,0.275
152.12,140.11,0.275
152.15,140.33,0.275
152.17,140.54,0.275
152.19,140.76,0.275
152.21,140.98,0.275
152.23,141.19,0.275
152.25,141.41,0.275
152.28,141.63,0.276
152.30,141.84,0.276
152.32,142.06,0.276
152.34,142.28,0.276
152.36,142.49,0.276
152.38,142.71,0.276
152.40,142.93,0.276
152.43,143.15,0.276
152.45,143.36,0.277
152.47,143.58,0.277
152.49,143.80,0.277
152.51,144.01,0.277
152.53,144.23,0.277
152.56,144.45,0.277
152.58,144.66,0.277
152.60,144.88,0.277
152.62,145.10,0.278
152.64,145.31,0.278
152.67,145.53,0.278
152.69,145.75,0.278
152.71,145.96,0.278
152.73,146.18,0.278
152.75,146.40,0.278
152.77,146.62,0.279
152.80,146.83,0.279
152.82,147.05,0.279
152.84,147.27,0.279
152.86,147.48,0.279
152.88,147.70,0.279
152.90,147.92,0.279
152.93,148.13,0.279
152.95,148.35,0.279
152.97,148.56,0.280
152.99,148.78,0.280
153.01,149.00,0.280
153.03,149.22,0.280
153.05,149.43,0.280
153.08,149.65,0.280
153.10,149.87,0.281
153.12,150.08,0.281
153.14,150.30,0.281
153.16,150.52,0.281
153.18,150.73,0.281
153.21,150.95,0.281
153.23,151.17,0.281
153.25,151.38,0.281
153.27,151.60,0.282
153.29,151.82,0.282
153.32,152.03,0.282
153.34,152.25,0.282
153.36,152.47,0.282
153.38,152.69,0.282
153.40,152.90,0.282
153.42,153.12,0.283
153.45,153.34,0.283
153.47,153.55,0.283
153.49,153.77,0.283
153.51,153.99,0.283
153.53,154.20,0.283
153.55,154.42,0.283
153.58,154.64,0.284
153.60,154.85,0.284
153.62,155.07,0.284
153.64,155.29,0.284
153.66,155.50,0.284
153.68,155.72,0.284
153.70,155.94,0.284
153.73,156.15,0.284
153.75,156.37,0.285
153.77,156.59,0.285
153.79,156.80,0.285
153.81,157.02,0.285
153.83,157.24,0.285
153.86,157.46,0.285
153.88,157.67,0.286
153.90,157.89,0.286
153.92,158.10,0.286
153.94,158.32,0.286
153.97,158.54,0.286
153.99,158.76,0.286
154.01,158.97,0.286
154.03,159.19,0.286
154.05,159.41,0.287
154.07,159.62,0.287
154.10,159.84,0.287
154.12,160.06,0.287
154.14,160.27,0.287
154.16,160.49,0.287
154.18,160.71,0.288
154.20,160.92,0.288
154.23,161.14,0.288
154.25,161.36,0.288
154.27,161.57,0.288
154.29,161.79,0.288
154.31,162.01,0.289
154.33,162.22,0.289
154.35,162.44,0.289
154.38,162.66,0.289
154.40,162.87,0.289
154.42,163.09,0.289
154.44,163.31,0.289
154.46,163.52,0.290
154.48,163.74,0.290
154.51,163.96,0.290
154.53,164.18,0.290
154.55,164.39,0.290
154.57,164.61,0.291
154.59,164.83,0.291
154.62,165.04,0.291
154.64,165.26,0.291
154.66,165.48,0.291
154.68,165.69,0.292
154.70,165.91,0.292
154.72,166.13,0.292
154.75,166.34,0.292
154.77,166.56,0.292
154.79,166.78,0.293
154.81,166.99,0.293
154.83,167.21,0.293
154.85,167.43,0.293
154.88,167.64,0.293
154.90,167.86,0.294
154.92,168.08,0.294
154.94,168.30,0.294
154.96,168.51,0.294
154.98,168.73,0.295
155.00,168.95,0.295
155.03,169.16,0.295
155.05,169.38,0.295
155.07,169.59,0.295
155.09,169.81,0.296
155.11,170.03,0.296
155.13,170.24,0.296
155.16,170.46,0.296
155.18,170.68,0.297
155.20,170.89,0.297
155.22,171.11,0.297
155.24,171.33,0.298
155.27,171.54,0.298
155.29,171.76,0.298
155.31,171.98,0.298
155.33,172.19,0.299
155.35,172.41,0.299
155.37,172.63,0.299
155.40,172.84,0.300
155.42,173.06,0.300
155.44,173.28,0.301
155.46,173.50,0.301
155.48,173.71,0.302
155.50,173.93,0.302
155.53,174.15,0.303
155.55,174.36,0.303
155.57,174.58,0.304
155.59,174.80,0.304
155.61,175.01,0.305
155.63,175.23,0.305
155.65,175.45,0.305
155.68,175.66,0.306
155.70,175.88,0.307
155.72,176.10,0.307
155.74,176.31,0.308
155.76,176.53,0.308
155.78,176.75,0.309
155.81,176.96,0.309
155.83,177.18,0.310
155.85,177.40,0.311
155.87,177.61,0.312
155.89,177.83,0.313
155.92,178.04,0.314
155.94,178.26,0.315
155.96,178.48,0.315
155.98,178.70,0.317
156.00,178.91,0.318
156.02,179.13,0.320
156.05,179.34,0.321
156.07,179.56,0.322
156.09,179.78,0.324
156.11,179.99,0.325
156.13,180.21,0.327
156.15,180.43,0.328
156.18,180.64,0.329
156.20,180.86,0.331
156.22,181.08,0.333
156.24,181.29,0.336
156.26,181.51,0.338
156.28,181.73,0.340
156.30,181.94,0.341
156.33,182.16,0.343
156.35,182.38,0.345
156.37,182.59,0.346
156.39,182.81,0.347
156.41,183.03,0.348
156.43,183.24,0.349
156.46,183.46,0.350
156.48,183.67,0.351
156.50,183.89,0.352
156.52,184.11,0.353
156.54,184.32,0.353
156.57,184.54,0.354
156.59,184.76,0.355
156.61,184.97,0.355
156.63,185.19,0.356
156.65,185.41,0.356
156.67,185.62,0.356
156.70,185.84,0.356
156.72,186.06,0.356
156.74,186.28,0.356
156.76,186.49,0.356
156.78,186.71,0.355
156.80,186.93,0.355
156.83,187.14,0.355
156.85,187.36,0.354
156.87,187.58,0.354
156.89,187.80,0.354
156.91,188.01,0.353
156.93,188.23,0.353
156.95,188.45,0.352
156.98,188.66,0.352
157.00,188.88,0.351
157.02,189.10,0.351
157.04,189.31,0.351
157.06,189.53,0.350
157.08,189.75,0.350
157.11,189.96,0.350
157.13,190.18,0.350
157.15,190.40,0.349
157.17,190.61,0.349
157.19,190.83,0.349
157.22,191.05,0.349
157.24,191.27,0.349
157.26,191.48,0.349
157.28,191.70,0.349
157.30,191.92,0.349
157.32,192.13,0.348
157.35,192.35,0.348
157.37,192.57,0.348
157.39,192.78,0.348
157.41,193.00,0.348
157.43,193.22,0.348
157.45,193.43,0.348
157.48,193.65,0.348
157.50,193.87,0.348
157.52,194.08,0.348
157.54,194.30,0.348
157.56,194.52,0.348
157.58,194.73,0.348
157.60,194.95,0.348
157.63,195.17,0.348
157.65,195.38,0.348
157.67,195.60,0.348
157.69,195.82,0.348
157.71,196.03,0.348
157.73,196.25,0.348
157.76,196.47,0.348
157.78,196.69,0.349
157.80,196.90,0.349
157.82,197.12,0.349
157.84,197.34,0.349
157.87,197.55,0.349
157.89,197.77,0.349
157.91,197.99,0.349
157.93,198.20,0.349
157.95,198.42,0.349
157.97,198.64,0.349
158.00,198.85,0.349
158.02,199.07,0.349
158.04,199.29,0.349
158.06,199.50,0.349
158.08,199.72,0.350
158.10,199.94,0.350
158.13,200.15,0.350
158.15,200.37,0.350
158.17,200.59,0.350
158.19,200.81,0.350
158.21,201.02,0.350
158.23,201.24,0.350
158.25,201.45,0.350
158.28,201.67,0.350
158.30,201.89,0.350
158.32,202.11,0.351
158.34,202.32,0.351
158.36,202.54,0.351
158.38,202.76,0.351
158.41,202.97,0.351
158.43,203.19,0.351
158.45,203.41,0.351
158.47,203.62,0.351
158.49,203.84,0.351
158.52,204.06,0.351
158.54,204.27,0.352
158.56,204.49,0.352
158.58,204.71,0.352
158.60,204.93,0.352
158.62,205.14,0.352
158.65,205.36,0.352
158.67,205.57,0.352
158.69,205.79,0.352
158.71,206.01,0.352
158.73,206.22,0.352
158.75,206.44,0.352
158.78,206.66,0.352
158.80,206.87,0.352
158.82,207.09,0.352
158.84,207.31,0.352
158.86,207.52,0.352
158.88,207.74,0.352
158.90,207.96,0.352
158.93,208.17,0.353
158.95,208.39,0.353
158.97,208.61,0.353
158.99,208.83,0.353
159.01,209.04,0.353
159.03,209.26,0.353
159.06,209.48,0.353
159.08,209.69,0.353
159.10,209.91,0.353
159.12,210.13,0.353
159.14,210.34,0.354
159.17,210.56,0.354
159.19,210.78,0.354
159.21,210.99,0.354
159.23,211.21,0.354
159.25,211.43,0.354
159.27,211.64,0.354
159.30,211.86,0.354
159.32,212.08,0.354
159.34,212.29,0.354
159.36,212.51,0.354
159.38,212.73,0.354
159.40,212.94,0.355
159.43,213.16,0.355
159.45,213.38,0.355
159.47,213.60,0.355
159.49,213.81,0.355
159.51,214.03,0.355
159.53,214.25,0.355
159.55,214.46,0.355
159.58,214.68,0.355
159.60,214.90,0.355
159.62,215.11,0.355
159.64,215.33,0.355
159.66,215.55,0.356
159.68,215.76,0.356
159.71,215.98,0.356
159.73,216.20,0.356
159.75,216.41,0.356
159.77,216.63,0.356
159.79,216.85,0.356
159.82,217.06,0.356
159.84,217.28,0.356
159.86,217.50,0.356
159.88,217.71,0.356
159.90,217.93,0.356
159.92,218.15,0.356
159.95,218.36,0.356
159.97,218.58,0.357
159.99,218.80,0.357
160.01,219.02,0.357
160.03,219.23,0.357
160.05,219.45,0.357
160.08,219.67,0.357
160.10,219.88,0.357
160.12,220.10,0.357
160.14,220.32,0.357
160.16,220.53,0.357
160.18,220.75,0.357
160.20,220.97,0.358
160.23,221.18,0.358
160.25,221.40,0.358
160.27,221.62,0.358
160.29,221.83,0.358
160.31,222.05,0.358
160.33,222.27,0.358
160.36,222.48,0.358
160.38,222.70,0.358
160.40,222.92,0.358
160.42,223.13,0.358
160.44,223.35,0.358
160.47,223.57,0.358
160.49,223.79,0.359
160.51,224.00,0.359
160.53,224.22,0.359
160.55,224.44,0.359
160.57,224.65,0.359
160.60,224.87,0.359
160.62,225.09,0.359
160.64,225.30,0.359
160.66,225.52,0.359
160.68,225.74,0.359
160.70,225.95,0.360
160.73,226.17,0.360
160.75,226.39,0.360
160.77,226.60,0.360
160.79,226.82,0.360
160.81,227.04,0.360
160.83,227.25,0.360
160.85,227.47,0.360
160.88,227.69,0.360
160.90,227.91,0.360
160.92,228.12,0.360
160.94,228.34,0.360
160.96,228.55,0.360
160.98,228.77,0.360
161.01,228.99,0.360
161.03,229.20,0.360
161.05,229.42,0.360
161.07,229.64,0.360
161.09,229.85,0.361
161.12,230.07,0.361
161.14,230.29,0.361
161.16,230.51,0.361
161.18,230.72,0.361
161.20,230.94,0.361
161.22,231.16,0.361
161.25,231.37,0.361
161.27,231.59,0.361
161.29,231.81,0.362
161.31,232.02,0.362
161.33,232.24,0.362
161.35,232.46,0.362
161.38,232.67,0.362
161.40,232.89,0.362
161.42,233.11,0.362
161.44,233.32,0.362
161.46,233.54,0.362
161.48,233.76,0.362
161.50,233.97,0.362
161.53,234.19,0.362
161.55,234.41,0.362
161.57,234.62,0.363
161.59,234.84,0.363
161.61,235.06,0.363
161.63,235.28,0.363
161.66,235.49,0.363
161.68,235.71,0.363
161.70,235.92,0.363
161.72,236.14,0.363
161.74,236.36,0.363
161.77,236.57,0.363
161.79,236.79,0.363
161.81,237.01,0.363
161.83,237.23,0.363
161.85,237.44,0.363
161.87,237.66,0.364
161.90,237.88,0.364
161.92,238.09,0.364
161.94,238.31,0.364
161.96,238.53,0.364
161.98,238.75,0.364
162.00,238.96,0.364
162.03,239.18,0.365
162.05,239.40,0.365
162.07,239.61,0.365
162.09,239.83,0.365
162.11,240.05,0.365
162.13,240.26,0.365
162.15,240.48,0.365
162.18,240.69,0.365
162.20,240.91,0.365
162.22,241.13,0.365
162.24,241.34,0.365
162.26,241.56,0.365
162.28,241.78,0.365
162.31,242.00,0.365
162.33,242.21,0.366
162.35,242.43,0.366
162.37,242.65,0.366
162.39,242.86,0.366
162.42,243.08,0.366
162.44,243.29,0.366
162.46,243.51,0.366
162.48,243.73,0.366
162.50,243.95,0.366
162.52,244.16,0.366
162.55,244.38,0.366
162.57,244.60,0.366
162.59,244.82,0.367
162.61,245.03,0.367
162.63,245.25,0.367
162.65,245.46,0.367
162.68,245.68,0.367
162.70,245.90,0.367
162.72,246.12,0.367
162.74,246.33,0.367
162.76,246.55,0.367
162.78,246.77,0.367
162.80,246.98,0.367
162.83,247.20,0.367
162.85,247.42,0.368
162.87,247.63,0.368
162.89,247.85,0.368
162.91,248.07,0.368
162.93,248.28,0.368
162.96,248.50,
162.98,248.72,
162.99,,