File: DSC/Olivia/2025_08_09_1CBN_3PVP10_MeOH_ASD_n60C_200C_10Cmin_x3.csv
Filename,2025_08_09_1CBN_3PVP10_MeOH_ASD_n60C_200C_10Cmin_x3
Instrument name,DSC2A-00468 (192.168.1.100)
Operator,Yarger
rundate,8/9/2025
Sample name,2025_08_09_1CBN_3PVP10_MeOH_ASD_n60C_200C_10Cmin_x3
proceduresegments,Data Off ; Equilibrate -60.00 °C; Data On ; Ramp 10.00 °C/min to 200.00 °C; Data Off ; Isothermal 2.0 min; Data On ; Ramp 10.00 °C/min to -60.00 °C; Data Off ; Isothermal 2.0 min; Data On ; Ramp 10.00 °C/min to 200.00 °C; Data Off ; Isothermal 2.0 min; Data On ; Ramp 10.00 °C/min to -60.00 °C; Data Off ; Isothermal 2.0 min; Data On ; Ramp 10.00 °C/min to 200.00 °C
[File Parameters]
Run date,8/9/2025 3:46:47 PM
Trios version,5.1.1.46572
Original File Name,
Current File Name,D:\DSC2500\JYarger\2025_08_09_1CBN_3PVP10_MeOH_ASD_n60C_200C_10Cmin_x3.tri
[Procedure]
Procedure Name,CBN_PVP10_TS_n60C_200C_10Cmin_x3
Sample Name,2025_08_09_1CBN_3PVP10_MeOH_ASD_n60C_200C_10Cmin_x3
Sample Mass,32.66 mg
Reference Sample Mass,0 mg
Pan Mass,9.3 mg
Pan Number,11
Reference Pan Mass,32.42 mg
Reference Pan Number,10
Pan Type,Aluminum
Comments,Thermal support Al pans/lids. DSC_Samples_A2_Tray_August2025 google sheet.
Project Name,Pharma
Operator,Yarger
Test,Custom
Unload Max Temperature,30
Unload Min Temperature,30
Load Max Temperature,30
Load Min Temperature,30
Stop on Gas Flow Error,Yes
[Signal List]
Signal #1,Time (min)
Signal #2,Temperature (°C)
Signal #3,Heat Flow (mW)
Signal #4,Delta T (µV)
Signal #5,Delta Tzero (µV)
Signal #6,Tzero Temperature (°C)
Signal #7,Cell Purge (mL/min)
Signal #8,Heater Temp (°C)
Signal #9,Power Delivered (W)
Signal #10,Reference Junction Temperature (°C)
Signal #11,Flange Temperature (°C)
Signal #12,Heat Flow Phase (rad)
Signal #13,Total Heat Capacity (J/°C)
Signal #14,Heat Capacity (J/°C)
[Configuration]
Company Name,ASU
Instrument Name,DSC2A-00468
Instrument Type,DSC2500
Serial Number,DSC2A-00468
IP,192.168.1.100
Location of Instrument,MRRC
DisplayType,Unknown
Sample Interval ,0.1 s/pt
Selected Heat Flow,T4P
Exotherm Direction,Down
Cell Serial,DRC2-00792
Lid Type,Standard
Cooler,RCS 90
Leave Cooler on at End of Sequence,On
Gas 2,Nitrogen
Gas Selected,Channel 1
Flow Rate,50 mL/min
Secondary Purge,On
Licensed Heat Flow,Heat Flow T4P
Modulation Licensed,Yes
[Versions]
Common IDD Version,1
Cortex Version,VER 2.10.2.31
Driver,5.0.0.6
GDM Version,1.0.3.3
TouchscreenVersion,1.0.0.16145
FEP Version,1.2.1.21
FEP Bootloader,2.0.0.5
AutoSampler Version,2.1.1.26
Auto Sampler Bootloader,2.0.0.5
FCM Version,1.1.0.3
FCM Bootloader,2.0.0.5
[Experiment Logs]
Experiment Log Entry # 1,Data On set to 0
Experiment Log Entry # 3,Equilibrate Segment -60 (C) Started
Experiment Log Entry # 5,Air Cool is off.
Experiment Log Entry # 7,Data On set to 1
Experiment Log Entry # 9,Ramp Segment 10 C/min to 200 Started
Experiment Log Entry # 11,Data On set to 0
Experiment Log Entry # 13,Isothermal Segment 2 min started
Experiment Log Entry # 15,Data On set to 1
Experiment Log Entry # 17,Ramp Segment 10 C/min to -60 Started
Experiment Log Entry # 19,Data On set to 0
Experiment Log Entry # 21,Isothermal Segment 2 min started
Experiment Log Entry # 23,Data On set to 1
Experiment Log Entry # 25,Ramp Segment 10 C/min to 200 Started
Experiment Log Entry # 27,Data On set to 0
Experiment Log Entry # 29,Isothermal Segment 2 min started
Experiment Log Entry # 31,Data On set to 1
Experiment Log Entry # 33,Ramp Segment 10 C/min to -60 Started
Experiment Log Entry # 35,Data On set to 0
Experiment Log Entry # 37,Isothermal Segment 2 min started
Experiment Log Entry # 39,Data On set to 1
Experiment Log Entry # 41,Ramp Segment 10 C/min to 200 Started
[Method Log]
Method Log Entry # 1,Data Off
Method Log Entry # 2,Equilibrate -60 °C
Method Log Entry # 3,Data On
Method Log Entry # 4,(Ramp 703226) Ramp 10 °C/minute to 200 °C
Method Log Entry # 5,Data Off
Method Log Entry # 6,Isothermal 2 minutes
Method Log Entry # 7,Data On
Method Log Entry # 8,(Ramp 703230) Ramp 10 °C/minute to -60 °C
Method Log Entry # 9,Data Off
Method Log Entry # 10,Isothermal 2 minutes
Method Log Entry # 11,Data On
Method Log Entry # 12,(Ramp 703234) Ramp 10 °C/minute to 200 °C
Method Log Entry # 13,Data Off
Method Log Entry # 14,Isothermal 2 minutes
Method Log Entry # 15,Data On
Method Log Entry # 16,(Ramp 703238) Ramp 10 °C/minute to -60 °C
Method Log Entry # 17,Data Off
Method Log Entry # 18,Isothermal 2 minutes
Method Log Entry # 19,Data On
Method Log Entry # 20,(Ramp 703242) Ramp 10 °C/minute to 200 °C
Cell Serial,DRC2-00792
[T1 Calibration]
Slope,-0.008529666
Offset,9.636258
Initial Temperature,98.23
GUID,f8bfdadc-4977-4fdf-ba6d-0ba9134940c3
[TZero Calibration]
Date Applied,11/29/2022 4:06:13 PM
Description,From -89.059 °C to 396.009 °C at 20.000°C/min
Gas Type,Nitrogen
Pan Type,None
Source Files 1,C:\Users\yargerlab\Desktop\DSC Data\General\TZero_calibration_11_29_22_2nd(2).tri
Source Files 2,C:\Users\yargerlab\Desktop\DSC Data\General\TZero_calibration_11_29_22_2nd(3).tri
Delta T Offset,13.05235
Delta T Slope,-0.007271007
Delta T0 Offset,-13.69128
Delta T0 Slope,0.06063341
[Temperature Calibration]
Date Applied,11/29/2022 7:12:28 PM
Description,From 106.590 °C to 186.590 °C at 10.000°C/min
Gas Type,Nitrogen
Pan Type,Tzero Aluminum Hermetic
Source Files 1,C:\Users\yargerlab\Desktop\DSC Data\General\Indium(6).tri
Measured 1,157.391
Known 1,156.598
[Cell Constant Calibration]
Date Applied,11/29/2022 7:12:29 PM
Description,From 106.590 °C to 186.590 °C at 10.000°C/min
Gas Type,Nitrogen
Pan Type,Tzero Aluminum Hermetic
Source Files 1,C:\Users\yargerlab\Desktop\DSC Data\General\Indium(6).tri
T4P KCell,1.006051
Onset Slope,63.26126 mW/°C
[Direct Cp Calibration]
Date Applied,11/30/2022 11:04:51 AM
Description,From -79.983 °C to 298.409 °C at 10.000°C/min
Gas Type,Nitrogen
Pan Type,Tzero Aluminum Hermetic
Source Files 1,C:\Users\yargerlab\Desktop\DSC Data\General\Sapphire_Heat_Capacity_11_30_22.tri
[Rev Cp Calibration]
Date Applied,11/30/2022 1:58:51 PM
Description,From -79.996 °C to 292.812 °C at 3.000°C/min
Gas Type,Nitrogen
Pan Type,Tzero Aluminum Hermetic
Source Files 1,C:\Users\yargerlab\Desktop\DSC Data\General\Sapphire_MDSC_Calibration_11_30_22.tri
[step]
Ramp 10.00 °C/min to 200.00 °C
Time,Temperature,Heat Flow (Normalized)
min,°C,W/g
0.00,-59.79,-0.012
0.02,-59.79,-0.012
0.04,-59.80,-0.010
0.05,-59.79,-0.008
0.07,-59.76,-0.004
0.09,-59.71,0.000
0.11,-59.64,0.006
0.13,-59.55,0.013
0.15,-59.43,0.020
0.16,-59.30,0.026
0.18,-59.16,0.032
0.20,-59.01,0.037
0.22,-58.85,0.041
0.24,-58.69,0.044
0.26,-58.53,0.047
0.28,-58.36,0.050
0.29,-58.19,0.051
0.31,-58.02,0.053
0.33,-57.84,0.054
0.35,-57.67,0.055
0.37,-57.49,0.056
0.39,-57.32,0.057
0.40,-57.14,0.057
0.42,-56.96,0.058
0.44,-56.78,0.058
0.46,-56.60,0.059
0.48,-56.43,0.059
0.50,-56.25,0.060
0.51,-56.07,0.060
0.53,-55.89,0.060
0.55,-55.71,0.060
0.57,-55.53,0.060
0.59,-55.35,0.061
0.60,-55.17,0.061
0.62,-54.99,0.061
0.64,-54.81,0.061
0.66,-54.63,0.061
0.68,-54.45,0.061
0.70,-54.27,0.061
0.72,-54.08,0.062
0.73,-53.90,0.062
0.75,-53.72,0.062
0.77,-53.54,0.062
0.79,-53.36,0.062
0.81,-53.18,0.062
0.83,-53.00,0.062
0.84,-52.81,0.062
0.86,-52.63,0.062
0.88,-52.45,0.062
0.90,-52.27,0.063
0.92,-52.09,0.063
0.93,-51.90,0.063
0.95,-51.72,0.063
0.97,-51.54,0.063
0.99,-51.36,0.063
1.01,-51.18,0.063
1.03,-50.99,0.063
1.05,-50.81,0.063
1.06,-50.63,0.063
1.08,-50.45,0.063
1.10,-50.26,0.063
1.12,-50.08,0.063
1.14,-49.90,0.064
1.16,-49.72,0.064
1.17,-49.53,0.064
1.19,-49.35,0.064
1.21,-49.17,0.064
1.23,-48.98,0.064
1.25,-48.80,0.064
1.27,-48.62,0.064
1.28,-48.44,0.064
1.30,-48.25,0.064
1.32,-48.07,0.064
1.34,-47.89,0.064
1.36,-47.70,0.064
1.38,-47.52,0.064
1.39,-47.34,0.064
1.41,-47.15,0.065
1.43,-46.97,0.065
1.45,-46.79,0.065
1.47,-46.60,0.065
1.48,-46.42,0.065
1.50,-46.24,0.065
1.52,-46.05,0.065
1.54,-45.87,0.065
1.56,-45.69,0.065
1.58,-45.50,0.065
1.59,-45.32,0.065
1.61,-45.14,0.065
1.63,-44.96,0.065
1.65,-44.77,0.065
1.67,-44.59,0.065
1.69,-44.41,0.065
1.71,-44.22,0.065
1.72,-44.04,0.065
1.74,-43.85,0.065
1.76,-43.67,0.065
1.78,-43.49,0.065
1.80,-43.30,0.066
1.82,-43.12,0.066
1.83,-42.94,0.066
1.85,-42.75,0.066
1.87,-42.57,0.066
1.89,-42.39,0.066
1.91,-42.20,0.066
1.93,-42.02,0.066
1.94,-41.84,0.066
1.96,-41.65,0.066
1.98,-41.47,0.066
2.00,-41.29,0.066
2.02,-41.10,0.066
2.03,-40.92,0.066
2.05,-40.74,0.066
2.07,-40.55,0.066
2.09,-40.37,0.066
2.11,-40.19,0.066
2.13,-40.00,0.066
2.14,-39.82,0.066
2.16,-39.64,0.066
2.18,-39.45,0.066
2.20,-39.27,0.066
2.22,-39.09,0.066
2.24,-38.90,0.066
2.26,-38.72,0.066
2.27,-38.54,0.067
2.29,-38.35,0.067
2.31,-38.17,0.067
2.33,-37.98,0.067
2.35,-37.80,0.067
2.36,-37.62,0.067
2.38,-37.44,0.067
2.40,-37.25,0.067
2.42,-37.07,0.067
2.44,-36.88,0.067
2.46,-36.70,0.067
2.48,-36.52,0.067
2.49,-36.33,0.067
2.51,-36.15,0.067
2.53,-35.97,0.067
2.55,-35.78,0.067
2.57,-35.60,0.067
2.59,-35.42,0.067
2.60,-35.23,0.067
2.62,-35.05,0.067
2.64,-34.86,0.067
2.66,-34.68,0.067
2.68,-34.50,0.067
2.69,-34.31,0.067
2.71,-34.13,0.067
2.73,-33.95,0.067
2.75,-33.76,0.067
2.77,-33.58,0.067
2.79,-33.40,0.067
2.81,-33.21,0.068
2.82,-33.03,0.068
2.84,-32.84,0.068
2.86,-32.66,0.068
2.88,-32.48,0.068
2.90,-32.29,0.068
2.91,-32.11,0.068
2.93,-31.93,0.068
2.95,-31.74,0.068
2.97,-31.56,0.068
2.99,-31.38,0.068
3.01,-31.19,0.068
3.03,-31.01,0.068
3.04,-30.83,0.068
3.06,-30.64,0.068
3.08,-30.46,0.068
3.10,-30.27,0.068
3.12,-30.09,0.068
3.14,-29.91,0.068
3.15,-29.73,0.068
3.17,-29.54,0.068
3.19,-29.36,0.068
3.21,-29.17,0.068
3.23,-28.99,0.068
3.24,-28.81,0.068
3.26,-28.62,0.068
3.28,-28.44,0.068
3.30,-28.25,0.068
3.32,-28.07,0.068
3.34,-27.89,0.069
3.36,-27.71,0.069
3.37,-27.52,0.069
3.39,-27.34,0.069
3.41,-27.15,0.069
3.43,-26.97,0.069
3.45,-26.79,0.069
3.46,-26.60,0.069
3.48,-26.42,0.069
3.50,-26.24,0.069
3.52,-26.05,0.069
3.54,-25.87,0.069
3.56,-25.69,0.069
3.58,-25.50,0.069
3.59,-25.32,0.069
3.61,-25.14,0.069
3.63,-24.95,0.069
3.65,-24.77,0.069
3.67,-24.59,0.069
3.69,-24.40,0.069
3.70,-24.22,0.069
3.72,-24.03,0.069
3.74,-23.85,0.069
3.76,-23.67,0.069
3.78,-23.49,0.069
3.79,-23.30,0.069
3.81,-23.12,0.069
3.83,-22.93,0.070
3.85,-22.75,0.070
3.87,-22.57,0.070
3.89,-22.38,0.070
3.91,-22.20,0.070
3.92,-22.02,0.070
3.94,-21.83,0.070
3.96,-21.65,0.070
3.98,-21.47,0.070
4.00,-21.28,0.070
4.01,-21.10,0.070
4.03,-20.92,0.070
4.05,-20.73,0.070
4.07,-20.55,0.070
4.09,-20.37,0.070
4.11,-20.18,0.070
4.13,-20.00,0.070
4.14,-19.82,0.070
4.16,-19.63,0.070
4.18,-19.45,0.070
4.20,-19.26,0.070
4.22,-19.08,0.070
4.24,-18.90,0.070
4.25,-18.71,0.070
4.27,-18.53,0.070
4.29,-18.35,0.071
4.31,-18.16,0.071
4.33,-17.98,0.071
4.35,-17.80,0.071
4.36,-17.61,0.071
4.38,-17.43,0.071
4.40,-17.25,0.071
4.42,-17.06,0.071
4.44,-16.88,0.071
4.45,-16.69,0.071
4.47,-16.51,0.071
4.49,-16.33,0.071
4.51,-16.15,0.071
4.53,-15.96,0.071
4.55,-15.78,0.071
4.56,-15.60,0.071
4.58,-15.41,0.071
4.60,-15.23,0.071
4.62,-15.05,0.071
4.64,-14.86,0.071
4.66,-14.68,0.071
4.68,-14.49,0.071
4.69,-14.31,0.071
4.71,-14.13,0.071
4.73,-13.94,0.072
4.75,-13.76,0.072
4.77,-13.58,0.072
4.79,-13.39,0.072
4.80,-13.21,0.072
4.82,-13.03,0.072
4.84,-12.84,0.072
4.86,-12.66,0.072
4.88,-12.48,0.072
4.90,-12.29,0.072
4.91,-12.11,0.072
4.93,-11.93,0.072
4.95,-11.74,0.072
4.97,-11.56,0.072
4.99,-11.37,0.072
5.00,-11.19,0.072
5.02,-11.01,0.072
5.04,-10.82,0.072
5.06,-10.64,0.072
5.08,-10.46,0.072
5.10,-10.27,0.072
5.11,-10.09,0.072
5.13,-9.91,0.072
5.15,-9.72,0.072
5.17,-9.54,0.073
5.19,-9.36,0.073
5.21,-9.17,0.073
5.23,-8.99,0.073
5.24,-8.81,0.073
5.26,-8.62,0.073
5.28,-8.44,0.073
5.30,-8.26,0.073
5.32,-8.07,0.073
5.34,-7.89,0.073
5.35,-7.71,0.073
5.37,-7.52,0.073
5.39,-7.34,0.073
5.41,-7.15,0.073
5.43,-6.97,0.073
5.45,-6.79,0.073
5.46,-6.60,0.073
5.48,-6.42,0.073
5.50,-6.24,0.073
5.52,-6.05,0.073
5.54,-5.87,0.073
5.55,-5.69,0.074
5.57,-5.50,0.074
5.59,-5.32,0.074
5.61,-5.14,0.074
5.63,-4.95,0.074
5.65,-4.77,0.074
5.66,-4.59,0.074
5.68,-4.40,0.074
5.70,-4.22,0.074
5.72,-4.04,0.074
5.74,-3.85,0.074
5.76,-3.67,0.074
5.78,-3.48,0.074
5.79,-3.30,0.074
5.81,-3.12,0.074
5.83,-2.93,0.074
5.85,-2.75,0.074
5.87,-2.57,0.074
5.89,-2.38,0.074
5.90,-2.20,0.074
5.92,-2.02,0.075
5.94,-1.83,0.075
5.96,-1.65,0.075
5.98,-1.46,0.075
6.00,-1.28,0.075
6.01,-1.10,0.075
6.03,-0.92,0.075
6.05,-0.73,0.075
6.07,-0.55,0.075
6.09,-0.36,0.075
6.10,-0.18,0.075
6.12,0.00,0.075
6.14,0.19,0.075
6.16,0.37,0.075
6.18,0.55,0.075
6.20,0.74,0.075
6.21,0.92,0.075
6.23,1.10,0.075
6.25,1.29,0.075
6.27,1.47,0.075
6.29,1.65,0.076
6.31,1.84,0.076
6.33,2.02,0.076
6.34,2.20,0.076
6.36,2.39,0.076
6.38,2.57,0.076
6.40,2.75,0.076
6.42,2.94,0.076
6.44,3.12,0.076
6.45,3.31,0.076
6.47,3.49,0.076
6.49,3.67,0.076
6.51,3.85,0.076
6.53,4.04,0.076
6.55,4.22,0.076
6.56,4.41,0.076
6.58,4.59,0.076
6.60,4.77,0.076
6.62,4.95,0.076
6.64,5.14,0.077
6.65,5.32,0.077
6.67,5.51,0.077
6.69,5.69,0.077
6.71,5.87,0.077
6.73,6.06,0.077
6.75,6.24,0.077
6.76,6.42,0.077
6.78,6.61,0.077
6.80,6.79,0.077
6.82,6.97,0.077
6.84,7.16,0.077
6.86,7.34,0.077
6.88,7.52,0.077
6.89,7.71,0.077
6.91,7.89,0.077
6.93,8.07,0.077
6.95,8.26,0.078
6.97,8.44,0.078
6.99,8.62,0.078
7.00,8.81,0.078
7.02,8.99,0.078
7.04,9.17,0.078
7.06,9.36,0.078
7.08,9.54,0.078
7.10,9.73,0.078
7.11,9.91,0.078
7.13,10.09,0.078
7.15,10.28,0.078
7.17,10.46,0.078
7.19,10.64,0.078
7.20,10.83,0.079
7.22,11.01,0.079
7.24,11.19,0.079
7.26,11.38,0.079
7.28,11.56,0.079
7.30,11.74,0.079
7.31,11.93,0.079
7.33,12.11,0.079
7.35,12.29,0.079
7.37,12.48,0.079
7.39,12.66,0.079
7.41,12.84,0.079
7.43,13.03,0.079
7.44,13.21,0.079
7.46,13.39,0.079
7.48,13.58,0.080
7.50,13.76,0.080
7.52,13.94,0.080
7.54,14.13,0.080
7.55,14.31,0.080
7.57,14.49,0.080
7.59,14.68,0.080
7.61,14.86,0.080
7.63,15.04,0.080
7.65,15.23,0.080
7.66,15.41,0.080
7.68,15.59,0.080
7.70,15.78,0.080
7.72,15.96,0.080
7.74,16.15,0.081
7.75,16.33,0.081
7.77,16.51,0.081
7.79,16.70,0.081
7.81,16.88,0.081
7.83,17.06,0.081
7.85,17.25,0.081
7.86,17.43,0.081
7.88,17.61,0.081
7.90,17.79,0.081
7.92,17.98,0.081
7.94,18.16,0.081
7.96,18.34,0.081
7.98,18.53,0.082
7.99,18.71,0.082
8.01,18.89,0.082
8.03,19.08,0.082
8.05,19.26,0.082
8.07,19.44,0.082
8.09,19.63,0.082
8.10,19.81,0.082
8.12,20.00,0.082
8.14,20.18,0.082
8.16,20.36,0.082
8.18,20.54,0.082
8.20,20.73,0.083
8.21,20.91,0.083
8.23,21.10,0.083
8.25,21.28,0.083
8.27,21.46,0.083
8.29,21.64,0.083
8.30,21.83,0.083
8.32,22.01,0.083
8.34,22.20,0.083
8.36,22.38,0.083
8.38,22.56,0.084
8.40,22.75,0.084
8.41,22.93,0.084
8.43,23.11,0.084
8.45,23.30,0.084
8.47,23.48,0.084
8.49,23.66,0.084
8.51,23.84,0.084
8.53,24.03,0.084
8.54,24.21,0.084
8.56,24.40,0.085
8.58,24.58,0.085
8.60,24.76,0.085
8.62,24.95,0.085
8.63,25.13,0.085
8.65,25.31,0.085
8.67,25.50,0.085
8.69,25.68,0.085
8.71,25.86,0.085
8.73,26.05,0.085
8.75,26.23,0.086
8.76,26.41,0.086
8.78,26.60,0.086
8.80,26.78,0.086
8.82,26.96,0.086
8.84,27.15,0.086
8.85,27.33,0.086
8.87,27.51,0.086
8.89,27.70,0.086
8.91,27.88,0.087
8.93,28.06,0.087
8.95,28.25,0.087
8.97,28.43,0.087
8.98,28.61,0.087
9.00,28.80,0.087
9.02,28.98,0.087
9.04,29.16,0.087
9.06,29.35,0.087
9.08,29.53,0.088
9.09,29.71,0.088
9.11,29.90,0.088
9.13,30.08,0.088
9.15,30.26,0.088
9.17,30.45,0.088
9.18,30.63,0.088
9.20,30.81,0.089
9.22,31.00,0.089
9.24,31.18,0.089
9.26,31.36,0.089
9.28,31.55,0.089
9.30,31.73,0.089
9.31,31.91,0.089
9.33,32.09,0.089
9.35,32.28,0.090
9.37,32.46,0.090
9.39,32.65,0.090
9.40,32.83,0.090
9.42,33.01,0.090
9.44,33.19,0.090
9.46,33.38,0.090
9.48,33.56,0.091
9.50,33.74,0.091
9.52,33.93,0.091
9.53,34.11,0.091
9.55,34.29,0.091
9.57,34.48,0.091
9.59,34.66,0.092
9.61,34.84,0.092
9.63,35.03,0.092
9.64,35.21,0.092
9.66,35.39,0.092
9.68,35.58,0.092
9.70,35.76,0.093
9.72,35.94,0.093
9.73,36.13,0.093
9.75,36.31,0.093
9.77,36.49,0.093
9.79,36.68,0.094
9.81,36.86,0.094
9.83,37.04,0.094
9.85,37.23,0.094
9.86,37.41,0.094
9.88,37.59,0.094
9.90,37.78,0.095
9.92,37.96,0.095
9.94,38.14,0.095
9.95,38.33,0.095
9.97,38.51,0.095
9.99,38.69,0.096
10.01,38.87,0.096
10.03,39.06,0.096
10.05,39.24,0.096
10.07,39.42,0.097
10.08,39.61,0.097
10.10,39.79,0.097
10.12,39.97,0.097
10.14,40.16,0.097
10.16,40.34,0.098
10.18,40.52,0.098
10.19,40.71,0.098
10.21,40.89,0.098
10.23,41.07,0.099
10.25,41.25,0.099
10.27,41.44,0.099
10.28,41.62,0.100
10.30,41.80,0.100
10.32,41.99,0.100
10.34,42.17,0.101
10.36,42.35,0.101
10.38,42.54,0.101
10.40,42.72,0.101
10.41,42.90,0.102
10.43,43.09,0.102
10.45,43.27,0.102
10.47,43.45,0.102
10.49,43.63,0.103
10.50,43.82,0.103
10.52,44.00,0.103
10.54,44.18,0.104
10.56,44.37,0.104
10.58,44.55,0.104
10.60,44.73,0.105
10.62,44.92,0.105
10.63,45.10,0.105
10.65,45.28,0.106
10.67,45.46,0.106
10.69,45.65,0.107
10.71,45.83,0.107
10.73,46.01,0.107
10.74,46.19,0.108
10.76,46.38,0.108
10.78,46.56,0.109
10.80,46.74,0.109
10.82,46.92,0.110
10.83,47.11,0.110
10.85,47.29,0.111
10.87,47.47,0.111
10.89,47.66,0.112
10.91,47.84,0.112
10.93,48.02,0.113
10.95,48.20,0.113
10.96,48.38,0.114
10.98,48.57,0.114
11.00,48.75,0.115
11.02,48.93,0.116
11.04,49.11,0.116
11.05,49.30,0.117
11.07,49.48,0.118
11.09,49.66,0.118
11.11,49.84,0.119
11.13,50.02,0.120
11.15,50.21,0.121
11.17,50.39,0.122
11.18,50.57,0.123
11.20,50.75,0.124
11.22,50.93,0.124
11.24,51.12,0.125
11.26,51.30,0.126
11.28,51.48,0.127
11.29,51.66,0.128
11.31,51.84,0.130
11.33,52.02,0.131
11.35,52.21,0.132
11.37,52.39,0.133
11.38,52.57,0.134
11.40,52.75,0.136
11.42,52.93,0.137
11.44,53.11,0.139
11.46,53.29,0.140
11.48,53.47,0.141
11.50,53.65,0.143
11.51,53.83,0.145
11.53,54.01,0.146
11.55,54.19,0.148
11.57,54.37,0.149
11.59,54.55,0.151
11.60,54.73,0.153
11.62,54.91,0.155
11.64,55.09,0.156
11.66,55.27,0.158
11.68,55.45,0.160
11.70,55.63,0.161
11.72,55.81,0.163
11.73,55.99,0.165
11.75,56.17,0.166
11.77,56.35,0.168
11.79,56.53,0.169
11.81,56.71,0.171
11.83,56.89,0.172
11.84,57.07,0.173
11.86,57.25,0.174
11.88,57.44,0.175
11.90,57.62,0.175
11.92,57.80,0.176
11.93,57.98,0.176
11.95,58.16,0.176
11.97,58.35,0.176
11.99,58.53,0.176
12.01,58.71,0.175
12.03,58.90,0.174
12.05,59.08,0.173
12.06,59.27,0.172
12.08,59.45,0.170
12.10,59.64,0.169
12.12,59.83,0.168
12.14,60.01,0.166
12.15,60.20,0.165
12.17,60.39,0.164
12.19,60.57,0.162
12.21,60.76,0.161
12.23,60.95,0.159
12.25,61.13,0.158
12.27,61.32,0.157
12.28,61.51,0.156
12.30,61.69,0.155
12.32,61.88,0.154
12.34,62.06,0.153
12.36,62.25,0.153
12.38,62.43,0.152
12.39,62.62,0.152
12.41,62.81,0.151
12.43,62.99,0.151
12.45,63.17,0.151
12.47,63.36,0.151
12.48,63.54,0.151
12.50,63.73,0.151
12.52,63.91,0.151
12.54,64.09,0.150
12.56,64.28,0.150
12.58,64.46,0.150
12.60,64.64,0.150
12.61,64.83,0.151
12.63,65.01,0.151
12.65,65.19,0.151
12.67,65.38,0.151
12.69,65.56,0.151
12.70,65.74,0.151
12.72,65.93,0.152
12.74,66.11,0.152
12.76,66.29,0.152
12.78,66.48,0.152
12.80,66.66,0.153
12.82,66.84,0.153
12.83,67.03,0.153
12.85,67.21,0.154
12.87,67.39,0.154
12.89,67.57,0.155
12.91,67.76,0.155
12.93,67.94,0.155
12.94,68.12,0.156
12.96,68.30,0.156
12.98,68.49,0.156
13.00,68.67,0.157
13.02,68.85,0.157
13.03,69.03,0.158
13.05,69.22,0.158
13.07,69.40,0.158
13.09,69.58,0.159
13.11,69.77,0.159
13.13,69.95,0.160
13.15,70.13,0.160
13.16,70.31,0.161
13.18,70.50,0.161
13.20,70.68,0.161
13.22,70.86,0.162
13.24,71.05,0.162
13.25,71.23,0.163
13.27,71.41,0.163
13.29,71.59,0.164
13.31,71.78,0.164
13.33,71.96,0.164
13.35,72.14,0.165
13.37,72.32,0.165
13.38,72.51,0.166
13.40,72.69,0.166
13.42,72.87,0.167
13.44,73.06,0.167
13.46,73.24,0.167
13.48,73.42,0.168
13.49,73.60,0.168
13.51,73.78,0.169
13.53,73.97,0.169
13.55,74.15,0.170
13.57,74.33,0.170
13.58,74.52,0.171
13.60,74.70,0.171
13.62,74.88,0.171
13.64,75.06,0.172
13.66,75.25,0.172
13.68,75.43,0.173
13.70,75.61,0.173
13.71,75.79,0.174
13.73,75.98,0.174
13.75,76.16,0.175
13.77,76.34,0.175
13.79,76.53,0.176
13.80,76.71,0.176
13.82,76.89,0.177
13.84,77.07,0.177
13.86,77.26,0.178
13.88,77.44,0.178
13.90,77.62,0.178
13.92,77.80,0.179
13.93,77.99,0.179
13.95,78.17,0.180
13.97,78.35,0.180
13.99,78.53,0.181
14.01,78.71,0.181
14.03,78.90,0.182
14.04,79.08,0.183
14.06,79.26,0.183
14.08,79.45,0.184
14.10,79.63,0.184
14.12,79.81,0.185
14.13,79.99,0.185
14.15,80.18,0.186
14.17,80.36,0.186
14.19,80.54,0.187
14.21,80.72,0.187
14.23,80.91,0.188
14.25,81.09,0.188
14.26,81.27,0.189
14.28,81.45,0.189
14.30,81.64,0.190
14.32,81.82,0.190
14.34,82.00,0.191
14.35,82.18,0.192
14.37,82.37,0.192
14.39,82.55,0.193
14.41,82.73,0.193
14.43,82.91,0.194
14.45,83.10,0.194
14.47,83.28,0.194
14.48,83.46,0.195
14.50,83.64,0.196
14.52,83.83,0.196
14.54,84.01,0.197
14.56,84.19,0.197
14.58,84.37,0.198
14.59,84.55,0.198
14.61,84.74,0.199
14.63,84.92,0.199
14.65,85.10,0.200
14.67,85.28,0.200
14.68,85.47,0.201
14.70,85.65,0.202
14.72,85.83,0.202
14.74,86.02,0.203
14.76,86.20,0.203
14.78,86.38,0.204
14.80,86.56,0.204
14.81,86.75,0.205
14.83,86.93,0.205
14.85,87.11,0.206
14.87,87.29,0.206
14.89,87.48,0.206
14.90,87.66,0.207
14.92,87.84,0.208
14.94,88.02,0.208
14.96,88.21,0.208
14.98,88.39,0.209
15.00,88.57,0.209
15.02,88.75,0.210
15.03,88.94,0.210
15.05,89.12,0.211
15.07,89.30,0.212
15.09,89.48,0.212
15.11,89.67,0.213
15.13,89.85,0.213
15.14,90.03,0.214
15.16,90.21,0.214
15.18,90.40,0.214
15.20,90.58,0.215
15.22,90.76,0.215
15.23,90.95,0.216
15.25,91.13,0.216
15.27,91.31,0.217
15.29,91.49,0.217
15.31,91.68,0.218
15.33,91.86,0.218
15.35,92.04,0.218
15.36,92.23,0.219
15.38,92.41,0.219
15.40,92.59,0.220
15.42,92.77,0.220
15.44,92.96,0.220
15.45,93.14,0.221
15.47,93.32,0.221
15.49,93.51,0.221
15.51,93.69,0.221
15.53,93.87,0.222
15.55,94.05,0.222
15.57,94.24,0.222
15.58,94.42,0.223
15.60,94.60,0.223
15.62,94.79,0.223
15.64,94.97,0.224
15.66,95.15,0.224
15.68,95.34,0.224
15.69,95.52,0.224
15.71,95.70,0.225
15.73,95.88,0.225
15.75,96.07,0.225
15.77,96.25,0.225
15.78,96.43,0.225
15.80,96.62,0.226
15.82,96.80,0.226
15.84,96.98,0.226
15.86,97.17,0.226
15.88,97.35,0.226
15.90,97.53,0.226
15.91,97.71,0.227
15.93,97.90,0.227
15.95,98.08,0.227
15.97,98.27,0.227
15.99,98.45,0.227
16.00,98.63,0.227
16.02,98.81,0.227
16.04,99.00,0.227
16.06,99.18,0.227
16.08,99.36,0.227
16.10,99.55,0.227
16.12,99.73,0.227
16.13,99.91,0.227
16.15,100.10,0.227
16.17,100.28,0.228
16.19,100.47,0.228
16.21,100.65,0.228
16.23,100.83,0.228
16.24,101.02,0.228
16.26,101.20,0.228
16.28,101.38,0.228
16.30,101.57,0.228
16.32,101.75,0.228
16.33,101.94,0.228
16.35,102.12,0.228
16.37,102.30,0.228
16.39,102.49,0.228
16.41,102.67,0.228
16.43,102.86,0.227
16.45,103.04,0.227
16.46,103.22,0.227
16.48,103.41,0.227
16.50,103.59,0.227
16.52,103.77,0.227
16.54,103.96,0.226
16.55,104.14,0.226
16.57,104.33,0.226
16.59,104.51,0.226
16.61,104.70,0.226
16.63,104.88,0.225
16.65,105.07,0.225
16.67,105.25,0.225
16.68,105.43,0.224
16.70,105.62,0.224
16.72,105.80,0.223
16.74,105.99,0.223
16.76,106.17,0.223
16.78,106.35,0.222
16.79,106.54,0.222
16.81,106.72,0.222
16.83,106.91,0.221
16.85,107.09,0.221
16.87,107.28,0.221
16.88,107.46,0.220
16.90,107.64,0.220
16.92,107.83,0.219
16.94,108.01,0.219
16.96,108.20,0.218
16.98,108.38,0.218
17.00,108.57,0.217
17.01,108.75,0.217
17.03,108.94,0.216
17.05,109.12,0.216
17.07,109.31,0.216
17.09,109.49,0.215
17.11,109.68,0.215
17.12,109.86,0.214
17.14,110.04,0.214
17.16,110.23,0.213
17.18,110.41,0.213
17.20,110.60,0.212
17.22,110.78,0.212
17.23,110.97,0.211
17.25,111.15,0.210
17.27,111.34,0.210
17.29,111.52,0.209
17.31,111.71,0.209
17.33,111.89,0.208
17.34,112.07,0.208
17.36,112.26,0.207
17.38,112.44,0.207
17.40,112.63,0.206
17.42,112.81,0.206
17.43,113.00,0.205
17.45,113.18,0.204
17.47,113.37,0.204
17.49,113.55,0.203
17.51,113.74,0.203
17.53,113.92,0.202
17.54,114.11,0.202
17.56,114.29,0.201
17.58,114.48,0.201
17.60,114.66,0.200
17.62,114.85,0.199
17.64,115.03,0.199
17.66,115.21,0.198
17.67,115.40,0.198
17.69,115.58,0.197
17.71,115.77,0.196
17.73,115.95,0.196
17.75,116.14,0.195
17.77,116.32,0.195
17.78,116.51,0.194
17.80,116.69,0.193
17.82,116.88,0.193
17.84,117.06,0.192
17.86,117.25,0.192
17.88,117.43,0.191
17.89,117.62,0.190
17.91,117.80,0.190
17.93,117.99,0.189
17.95,118.17,0.189
17.97,118.36,0.188
17.98,118.54,0.187
18.00,118.72,0.187
18.02,118.91,0.186
18.04,119.09,0.185
18.06,119.28,0.185
18.08,119.46,0.184
18.09,119.65,0.184
18.11,119.83,0.183
18.13,120.02,0.183
18.15,120.20,0.182
18.17,120.39,0.181
18.19,120.57,0.181
18.21,120.76,0.180
18.22,120.94,0.180
18.24,121.13,0.179
18.26,121.31,0.178
18.28,121.50,0.178
18.30,121.68,0.177
18.32,121.87,0.176
18.33,122.05,0.176
18.35,122.23,0.175
18.37,122.42,0.175
18.39,122.60,0.174
18.41,122.79,0.174
18.43,122.97,0.173
18.44,123.16,0.173
18.46,123.34,0.172
18.48,123.53,0.171
18.50,123.71,0.171
18.52,123.90,0.170
18.53,124.08,0.169
18.55,124.27,0.169
18.57,124.45,0.168
18.59,124.64,0.167
18.61,124.82,0.167
18.63,125.01,0.166
18.64,125.19,0.165
18.66,125.38,0.165
18.68,125.56,0.164
18.70,125.75,0.163
18.72,125.93,0.163
18.74,126.12,0.162
18.76,126.30,0.161
18.77,126.49,0.161
18.79,126.67,0.160
18.81,126.86,0.159
18.83,127.04,0.159
18.85,127.23,0.158
18.87,127.41,0.157
18.88,127.60,0.157
18.90,127.78,0.156
18.92,127.97,0.155
18.94,128.15,0.155
18.96,128.34,0.154
18.98,128.52,0.153
18.99,128.71,0.153
19.01,128.90,0.152
19.03,129.08,0.151
19.05,129.26,0.151
19.07,129.45,0.150
19.08,129.63,0.149
19.10,129.82,0.149
19.12,130.00,0.148
19.14,130.19,0.147
19.16,130.37,0.147
19.18,130.56,0.146
19.19,130.74,0.146
19.21,130.93,0.145
19.23,131.11,0.144
19.25,131.29,0.144
19.27,131.48,0.143
19.29,131.66,0.142
19.31,131.85,0.142
19.32,132.03,0.141
19.34,132.22,0.141
19.36,132.40,0.140
19.38,132.59,0.139
19.40,132.77,0.139
19.42,132.96,0.138
19.43,133.14,0.138
19.45,133.33,0.137
19.47,133.51,0.136
19.49,133.70,0.136
19.51,133.88,0.135
19.53,134.07,0.134
19.54,134.25,0.134
19.56,134.44,0.133
19.58,134.62,0.133
19.60,134.80,0.132
19.62,134.99,0.132
19.63,135.17,0.131
19.65,135.36,0.131
19.67,135.54,0.130
19.69,135.73,0.130
19.71,135.91,0.129
19.73,136.09,0.129
19.74,136.28,0.129
19.76,136.46,0.128
19.78,136.65,0.128
19.80,136.83,0.127
19.82,137.01,0.127
19.84,137.20,0.127
19.86,137.38,0.126
19.87,137.57,0.126
19.89,137.75,0.126
19.91,137.94,0.126
19.93,138.12,0.125
19.95,138.30,0.125
19.97,138.49,0.125
19.98,138.67,0.124
20.00,138.86,0.124
20.02,139.04,0.124
20.04,139.22,0.123
20.06,139.41,0.123
20.08,139.59,0.123
20.09,139.78,0.122
20.11,139.96,0.122
20.13,140.14,0.122
20.15,140.33,0.122
20.17,140.51,0.121
20.18,140.70,0.121
20.20,140.88,0.121
20.22,141.07,0.121
20.24,141.25,0.120
20.26,141.44,0.120
20.28,141.62,0.120
20.29,141.80,0.119
20.31,141.99,0.119
20.33,142.17,0.119
20.35,142.36,0.119
20.37,142.54,0.119
20.39,142.72,0.119
20.41,142.91,0.118
20.42,143.09,0.118
20.44,143.27,0.118
20.46,143.46,0.118
20.48,143.64,0.118
20.50,143.83,0.118
20.52,144.01,0.117
20.53,144.19,0.117
20.55,144.38,0.117
20.57,144.56,0.117
20.59,144.74,0.117
20.61,144.93,0.117
20.63,145.11,0.117
20.64,145.30,0.117
20.66,145.48,0.117
20.68,145.66,0.117
20.70,145.84,0.117
20.72,146.03,0.117
20.73,146.21,0.117
20.75,146.39,0.117
20.77,146.58,0.117
20.79,146.76,0.117
20.81,146.94,0.117
20.83,147.13,0.117
20.84,147.31,0.117
20.86,147.49,0.117
20.88,147.68,0.117
20.90,147.86,0.117
20.92,148.05,0.117
20.94,148.23,0.117
20.96,148.41,0.117
20.97,148.60,0.117
20.99,148.78,0.117
21.01,148.97,0.117
21.03,149.15,0.116
21.05,149.33,0.116
21.07,149.52,0.115
21.08,149.70,0.115
21.10,149.89,0.114
21.12,150.07,0.114
21.14,150.25,0.113
21.16,150.44,0.113
21.18,150.62,0.113
21.19,150.81,0.113
21.21,150.99,0.113
21.23,151.17,0.112
21.25,151.36,0.112
21.27,151.54,0.112
21.28,151.73,0.112
21.30,151.91,0.111
21.32,152.10,0.111
21.34,152.28,0.111
21.36,152.46,0.111
21.38,152.65,0.110
21.39,152.83,0.110
21.41,153.02,0.110
21.43,153.20,0.110
21.45,153.38,0.110
21.47,153.57,0.110
21.49,153.75,0.110
21.51,153.93,0.110
21.52,154.12,0.110
21.54,154.30,0.110
21.56,154.48,0.110
21.58,154.67,0.110
21.60,154.85,0.110
21.62,155.03,0.110
21.63,155.22,0.110
21.65,155.40,0.110
21.67,155.58,0.110
21.69,155.77,0.110
21.71,155.95,0.110
21.73,156.13,0.110
21.74,156.32,0.110
21.76,156.50,0.110
21.78,156.69,0.110
21.80,156.87,0.110
21.82,157.05,0.110
21.83,157.24,0.110
21.85,157.42,0.110
21.87,157.60,0.110
21.89,157.79,0.110
21.91,157.97,0.110
21.93,158.15,0.110
21.94,158.34,0.110
21.96,158.52,0.110
21.98,158.70,0.110
22.00,158.89,0.110
22.02,159.07,0.110
22.04,159.25,0.110
22.06,159.44,0.110
22.07,159.62,0.110
22.09,159.81,0.110
22.11,159.99,0.110
22.13,160.17,0.110
22.15,160.36,0.110
22.17,160.54,0.110
22.18,160.72,0.110
22.20,160.91,0.110
22.22,161.09,0.110
22.24,161.27,0.110
22.26,161.46,0.110
22.28,161.64,0.110
22.29,161.82,0.110
22.31,162.01,0.110
22.33,162.19,0.110
22.35,162.37,0.110
22.37,162.56,0.110
22.38,162.74,0.110
22.40,162.92,0.110
22.42,163.11,0.110
22.44,163.29,0.110
22.46,163.47,0.110
22.48,163.66,0.110
22.49,163.84,0.110
22.51,164.03,0.110
22.53,164.21,0.110
22.55,164.39,0.110
22.57,164.58,0.110
22.59,164.76,0.110
22.61,164.94,0.110
22.62,165.13,0.110
22.64,165.31,0.110
22.66,165.49,0.110
22.68,165.68,0.110
22.70,165.86,0.110
22.72,166.04,0.110
22.73,166.22,0.162
22.75,166.28,0.260
22.77,166.43,0.214
22.79,166.61,0.204
22.81,166.79,0.204
22.83,166.96,0.221
22.84,167.13,0.217
22.86,167.32,0.209
22.88,167.51,0.200
22.90,167.70,0.193
22.92,167.90,0.185
22.93,168.10,0.178
22.95,168.29,0.171
22.97,168.49,0.165
22.99,168.69,0.159
23.01,168.88,0.152
23.03,169.08,0.146
23.04,169.27,0.143
23.06,169.46,0.140
23.08,169.65,0.138
23.10,169.84,0.136
23.12,170.03,0.134
23.14,170.22,0.134
23.16,170.40,0.133
23.17,170.59,0.132
23.19,170.77,0.132
23.21,170.96,0.132
23.23,171.14,0.131
23.25,171.33,0.131
23.27,171.51,0.131
23.28,171.69,0.131
23.30,171.88,0.131
23.32,172.06,0.131
23.34,172.25,0.131
23.36,172.43,0.131
23.38,172.61,0.131
23.39,172.80,0.131
23.41,172.98,0.131
23.43,173.16,0.131
23.45,173.35,0.131
23.47,173.53,0.131
23.48,173.71,0.131
23.50,173.90,0.131
23.52,174.08,0.131
23.54,174.26,0.131
23.56,174.45,0.131
23.58,174.63,0.131
23.59,174.81,0.131
23.61,175.00,0.131
23.63,175.18,0.131
23.65,175.36,0.131
23.67,175.55,0.131
23.69,175.73,0.131
23.71,175.91,0.131
23.72,176.10,0.131
23.74,176.28,0.131
23.76,176.47,0.131
23.78,176.65,0.131
23.80,176.83,0.131
23.82,177.02,0.131
23.83,177.20,0.131
23.85,177.39,0.131
23.87,177.57,0.131
23.89,177.75,0.131
23.91,177.94,0.131
23.93,178.12,0.131
23.94,178.30,0.131
23.96,178.49,0.131
23.98,178.67,0.131
24.00,178.85,0.131
24.02,179.04,0.131
24.03,179.22,0.131
24.05,179.40,0.131
24.07,179.59,0.131
24.09,179.77,0.131
24.11,179.95,0.131
24.13,180.14,0.131
24.14,180.32,0.131
24.16,180.50,0.131
24.18,180.69,0.131
24.20,180.87,0.131
24.22,181.05,0.131
24.24,181.24,0.131
24.26,181.42,0.131
24.27,181.60,0.131
24.29,181.79,0.131
24.31,181.97,0.131
24.33,182.15,0.131
24.35,182.34,0.131
24.37,182.52,0.131
24.38,182.70,0.132
24.40,182.89,0.132
24.42,183.07,0.132
24.44,183.25,0.132
24.46,183.44,0.132
24.48,183.62,0.132
24.49,183.80,0.132
24.51,183.99,0.132
24.53,184.17,0.132
24.55,184.35,0.132
24.57,184.54,0.132
24.58,184.72,0.132
24.60,184.90,0.132
24.62,185.09,0.132
24.64,185.27,0.132
24.66,185.45,0.132
24.68,185.64,0.132
24.69,185.82,0.132
24.71,186.01,0.133
24.73,186.19,0.133
24.75,186.37,0.133
24.77,186.55,0.133
24.79,186.74,0.133
24.81,186.92,0.133
24.82,187.11,0.133
24.84,187.29,0.133
24.86,187.47,0.133
24.88,187.66,0.133
24.90,187.84,0.133
24.92,188.02,0.133
24.93,188.21,0.133
24.95,188.39,0.133
24.97,188.58,0.133
24.99,188.76,0.133
25.01,188.94,0.133
25.03,189.13,0.133
25.04,189.31,0.133
25.06,189.49,0.133
25.08,189.68,0.133
25.10,189.86,0.133
25.12,190.04,0.133
25.13,190.23,0.133
25.15,190.41,0.133
25.17,190.59,0.133
25.19,190.78,0.133
25.21,190.96,0.133
25.23,191.14,0.133
25.24,191.33,0.133
25.26,191.51,0.134
25.28,191.69,0.134
25.30,191.88,0.134
25.32,192.06,0.134
25.34,192.24,0.134
25.36,192.43,0.134
25.37,192.61,0.134
25.39,192.79,0.134
25.41,192.98,0.134
25.43,193.16,0.134
25.45,193.34,0.134
25.47,193.53,0.134
25.48,193.71,0.134
25.50,193.89,0.134
25.52,194.08,0.134
25.54,194.26,0.134
25.56,194.45,0.134
25.58,194.63,0.134
25.59,194.81,0.134
25.61,195.00,0.134
25.63,195.18,0.134
25.65,195.36,0.134
25.67,195.55,0.134
25.68,195.73,0.134
25.70,195.91,0.134
25.72,196.10,0.134
25.74,196.28,0.134
25.76,196.46,0.134
25.78,196.65,0.134
25.79,196.83,0.134
25.81,197.01,0.134
25.83,197.20,0.134
25.85,197.38,0.134
25.87,197.56,0.134
25.89,197.75,0.134
25.91,197.93,0.134
25.92,198.11,0.134
25.94,198.30,
25.96,198.48,
25.98,198.66,
25.99,,

[step]
Ramp 10.00 °C/min to -60.00 °C
Time,Temperature,Heat Flow (Normalized)
min,°C,W/g
27.99,200.14,0.011
28.01,200.14,0.011
28.03,200.13,0.011
28.05,200.12,0.009
28.07,200.09,0.004
28.08,200.05,-0.003
28.10,199.97,-0.014
28.12,199.88,-0.027
28.14,199.76,-0.040
28.16,199.63,-0.053
28.18,199.49,-0.063
28.19,199.34,-0.072
28.21,199.18,-0.079
28.23,199.02,-0.084
28.25,198.85,-0.088
28.27,198.68,-0.092
28.29,198.51,-0.094
28.31,198.34,-0.097
28.32,198.16,-0.099
28.34,197.99,-0.101
28.36,197.81,-0.102
28.38,197.63,-0.103
28.40,197.45,-0.105
28.42,197.27,-0.106
28.43,197.09,-0.106
28.45,196.91,-0.107
28.47,196.73,-0.108
28.49,196.55,-0.108
28.51,196.37,-0.108
28.53,196.19,-0.109
28.54,196.01,-0.109
28.56,195.83,-0.110
28.58,195.65,-0.110
28.60,195.47,-0.110
28.62,195.29,-0.111
28.63,195.11,-0.111
28.65,194.92,-0.111
28.67,194.74,-0.111
28.69,194.56,-0.112
28.71,194.38,-0.112
28.73,194.20,-0.112
28.74,194.01,-0.112
28.76,193.83,-0.113
28.78,193.65,-0.113
28.80,193.47,-0.113
28.82,193.29,-0.113
28.84,193.10,-0.113
28.86,192.92,-0.113
28.87,192.74,-0.113
28.89,192.56,-0.114
28.91,192.38,-0.114
28.93,192.19,-0.114
28.95,192.01,-0.114
28.97,191.83,-0.114
28.98,191.65,-0.114
29.00,191.46,-0.115
29.02,191.28,-0.115
29.04,191.10,-0.115
29.06,190.92,-0.115
29.08,190.73,-0.115
29.09,190.55,-0.115
29.11,190.37,-0.115
29.13,190.19,-0.115
29.15,190.00,-0.115
29.17,189.82,-0.115
29.18,189.64,-0.115
29.20,189.46,-0.115
29.22,189.27,-0.115
29.24,189.09,-0.115
29.26,188.91,-0.115
29.28,188.73,-0.116
29.29,188.54,-0.116
29.31,188.36,-0.116
29.33,188.18,-0.116
29.35,187.99,-0.116
29.37,187.81,-0.116
29.39,187.63,-0.116
29.41,187.44,-0.116
29.42,187.26,-0.116
29.44,187.08,-0.116
29.46,186.89,-0.116
29.48,186.71,-0.116
29.50,186.53,-0.116
29.52,186.34,-0.116
29.53,186.16,-0.116
29.55,185.98,-0.116
29.57,185.80,-0.116
29.59,185.62,-0.117
29.61,185.43,-0.117
29.63,185.25,-0.117
29.64,185.07,-0.117
29.66,184.88,-0.117
29.68,184.70,-0.117
29.70,184.52,-0.117
29.72,184.33,-0.117
29.73,184.15,-0.117
29.75,183.97,-0.117
29.77,183.78,-0.117
29.79,183.60,-0.117
29.81,183.42,-0.117
29.83,183.24,-0.117
29.84,183.05,-0.117
29.86,182.87,-0.117
29.88,182.69,-0.117
29.90,182.50,-0.117
29.92,182.32,-0.117
29.94,182.14,-0.117
29.96,181.95,-0.117
29.97,181.77,-0.117
29.99,181.59,-0.117
30.01,181.40,-0.117
30.03,181.22,-0.117
30.05,181.04,-0.117
30.07,180.85,-0.117
30.08,180.67,-0.117
30.10,180.49,-0.118
30.12,180.30,-0.118
30.14,180.12,-0.118
30.16,179.94,-0.118
30.18,179.75,-0.118
30.19,179.57,-0.118
30.21,179.39,-0.118
30.23,179.20,-0.118
30.25,179.02,-0.118
30.27,178.84,-0.118
30.28,178.65,-0.118
30.30,178.47,-0.118
30.32,178.29,-0.118
30.34,178.11,-0.118
30.36,177.92,-0.118
30.38,177.74,-0.118
30.39,177.56,-0.118
30.41,177.37,-0.118
30.43,177.19,-0.118
30.45,177.01,-0.118
30.47,176.82,-0.118
30.49,176.64,-0.118
30.51,176.46,-0.118
30.52,176.27,-0.118
30.54,176.09,-0.118
30.56,175.91,-0.118
30.58,175.72,-0.118
30.60,175.54,-0.118
30.62,175.36,-0.118
30.63,175.17,-0.118
30.65,174.99,-0.118
30.67,174.81,-0.118
30.69,174.62,-0.118
30.71,174.44,-0.118
30.73,174.26,-0.118
30.74,174.07,-0.118
30.76,173.89,-0.118
30.78,173.71,-0.118
30.80,173.53,-0.118
30.82,173.34,-0.118
30.83,173.16,-0.118
30.85,172.98,-0.118
30.87,172.79,-0.118
30.89,172.61,-0.118
30.91,172.43,-0.118
30.93,172.24,-0.118
30.94,172.06,-0.118
30.96,171.88,-0.118
30.98,171.69,-0.118
31.00,171.51,-0.118
31.02,171.33,-0.118
31.04,171.14,-0.118
31.06,170.96,-0.118
31.07,170.78,-0.118
31.09,170.59,-0.118
31.11,170.41,-0.118
31.13,170.23,-0.118
31.15,170.04,-0.118
31.17,169.86,-0.118
31.18,169.68,-0.118
31.20,169.49,-0.118
31.22,169.31,-0.118
31.24,169.13,-0.118
31.26,168.94,-0.118
31.28,168.76,-0.118
31.29,168.58,-0.118
31.31,168.39,-0.117
31.33,168.21,-0.117
31.35,168.03,-0.117
31.37,167.84,-0.117
31.38,167.66,-0.117
31.40,167.48,-0.117
31.42,167.30,-0.117
31.44,167.11,-0.117
31.46,166.93,-0.117
31.48,166.75,-0.117
31.49,166.56,-0.117
31.51,166.38,-0.117
31.53,166.20,-0.117
31.55,166.01,-0.117
31.57,165.83,-0.117
31.59,165.65,-0.117
31.61,165.46,-0.117
31.62,165.28,-0.117
31.64,165.10,-0.117
31.66,164.91,-0.117
31.68,164.73,-0.117
31.70,164.55,-0.117
31.72,164.36,-0.117
31.73,164.18,-0.117
31.75,164.00,-0.117
31.77,163.81,-0.117
31.79,163.63,-0.117
31.81,163.45,-0.117
31.83,163.26,-0.117
31.84,163.08,-0.117
31.86,162.90,-0.117
31.88,162.71,-0.117
31.90,162.53,-0.117
31.92,162.35,-0.117
31.93,162.16,-0.117
31.95,161.98,-0.117
31.97,161.80,-0.117
31.99,161.61,-0.117
32.01,161.43,-0.117
32.03,161.25,-0.117
32.04,161.06,-0.117
32.06,160.88,-0.117
32.08,160.69,-0.117
32.10,160.51,-0.117
32.12,160.33,-0.117
32.14,160.15,-0.117
32.16,159.96,-0.117
32.17,159.78,-0.117
32.19,159.60,-0.117
32.21,159.41,-0.117
32.23,159.23,-0.117
32.25,159.05,-0.117
32.27,158.86,-0.117
32.28,158.68,-0.117
32.30,158.50,-0.117
32.32,158.31,-0.117
32.34,158.13,-0.117
32.36,157.95,-0.117
32.38,157.76,-0.117
32.39,157.58,-0.117
32.41,157.40,-0.117
32.43,157.21,-0.117
32.45,157.03,-0.116
32.47,156.85,-0.116
32.48,156.67,-0.116
32.50,156.48,-0.116
32.52,156.30,-0.116
32.54,156.11,-0.116
32.56,155.93,-0.116
32.58,155.75,-0.116
32.59,155.57,-0.116
32.61,155.38,-0.116
32.63,155.20,-0.116
32.65,155.02,-0.116
32.67,154.83,-0.116
32.69,154.65,-0.116
32.71,154.47,-0.116
32.72,154.28,-0.116
32.74,154.10,-0.116
32.76,153.92,-0.116
32.78,153.73,-0.116
32.80,153.55,-0.116
32.82,153.37,-0.116
32.83,153.18,-0.116
32.85,153.00,-0.116
32.87,152.82,-0.116
32.89,152.63,-0.116
32.91,152.45,-0.116
32.93,152.27,-0.116
32.94,152.08,-0.116
32.96,151.90,-0.116
32.98,151.72,-0.116
33.00,151.53,-0.116
33.02,151.35,-0.116
33.03,151.17,-0.116
33.05,150.98,-0.116
33.07,150.80,-0.116
33.09,150.62,-0.116
33.11,150.43,-0.116
33.13,150.25,-0.116
33.14,150.07,-0.116
33.16,149.88,-0.116
33.18,149.70,-0.116
33.20,149.52,-0.116
33.22,149.33,-0.116
33.24,149.15,-0.116
33.26,148.97,-0.116
33.27,148.78,-0.116
33.29,148.60,-0.116
33.31,148.42,-0.116
33.33,148.23,-0.116
33.35,148.05,-0.116
33.37,147.87,-0.116
33.38,147.68,-0.116
33.40,147.50,-0.116
33.42,147.32,-0.115
33.44,147.13,-0.115
33.46,146.95,-0.115
33.48,146.77,-0.115
33.49,146.58,-0.115
33.51,146.40,-0.115
33.53,146.22,-0.115
33.55,146.03,-0.115
33.57,145.85,-0.115
33.58,145.67,-0.115
33.60,145.49,-0.115
33.62,145.30,-0.115
33.64,145.12,-0.115
33.66,144.93,-0.115
33.68,144.75,-0.115
33.69,144.57,-0.115
33.71,144.39,-0.115
33.73,144.20,-0.115
33.75,144.02,-0.115
33.77,143.84,-0.115
33.79,143.65,-0.115
33.81,143.47,-0.115
33.82,143.29,-0.115
33.84,143.10,-0.115
33.86,142.92,-0.115
33.88,142.74,-0.115
33.90,142.55,-0.115
33.92,142.37,-0.115
33.93,142.18,-0.115
33.95,142.00,-0.115
33.97,141.82,-0.115
33.99,141.64,-0.115
34.01,141.45,-0.115
34.03,141.27,-0.115
34.04,141.09,-0.115
34.06,140.90,-0.115
34.08,140.72,-0.115
34.10,140.54,-0.115
34.12,140.35,-0.115
34.14,140.17,-0.115
34.15,139.99,-0.115
34.17,139.80,-0.114
34.19,139.62,-0.114
34.21,139.44,-0.114
34.23,139.25,-0.114
34.24,139.07,-0.114
34.26,138.89,-0.114
34.28,138.70,-0.114
34.30,138.52,-0.114
34.32,138.34,-0.114
34.34,138.15,-0.114
34.36,137.97,-0.114
34.37,137.78,-0.114
34.39,137.60,-0.114
34.41,137.42,-0.114
34.43,137.24,-0.114
34.45,137.05,-0.114
34.46,136.87,-0.114
34.48,136.69,-0.114
34.50,136.50,-0.114
34.52,136.32,-0.114
34.54,136.14,-0.114
34.56,135.95,-0.114
34.58,135.77,-0.114
34.59,135.59,-0.114
34.61,135.40,-0.114
34.63,135.22,-0.114
34.65,135.04,-0.114
34.67,134.86,-0.113
34.69,134.67,-0.113
34.70,134.49,-0.113
34.72,134.30,-0.113
34.74,134.12,-0.113
34.76,133.94,-0.113
34.78,133.75,-0.113
34.79,133.57,-0.113
34.81,133.39,-0.113
34.83,133.20,-0.113
34.85,133.02,-0.113
34.87,132.84,-0.113
34.89,132.65,-0.113
34.91,132.47,-0.113
34.92,132.29,-0.113
34.94,132.10,-0.113
34.96,131.92,-0.113
34.98,131.74,-0.113
35.00,131.55,-0.113
35.01,131.37,-0.113
35.03,131.19,-0.113
35.05,131.00,-0.113
35.07,130.82,-0.113
35.09,130.64,-0.113
35.11,130.45,-0.113
35.13,130.27,-0.113
35.14,130.09,-0.113
35.16,129.90,-0.113
35.18,129.72,-0.113
35.20,129.54,-0.113
35.22,129.35,-0.113
35.24,129.17,-0.113
35.25,128.99,-0.113
35.27,128.80,-0.113
[...]
119.22,10.89,0.065
119.24,11.07,0.065
119.26,11.25,0.065
119.28,11.44,0.065
119.29,11.62,0.065
119.31,11.80,0.065
119.33,11.99,0.065
119.35,12.17,0.065
119.37,12.35,0.066
119.39,12.54,0.066
119.40,12.72,0.066
119.42,12.90,0.066
119.44,13.09,0.066
119.46,13.27,0.066
119.48,13.45,0.066
119.50,13.64,0.066
119.51,13.82,0.066
119.53,14.01,0.066
119.55,14.19,0.066
119.57,14.37,0.066
119.59,14.56,0.066
119.60,14.74,0.066
119.62,14.92,0.066
119.64,15.11,0.066
119.66,15.29,0.066
119.68,15.47,0.066
119.70,15.66,0.066
119.71,15.84,0.066
119.73,16.02,0.066
119.75,16.21,0.066
119.77,16.39,0.066
119.79,16.57,0.066
119.81,16.76,0.066
119.83,16.94,0.066
119.84,17.12,0.066
119.86,17.31,0.066
119.88,17.49,0.067
119.90,17.67,0.067
119.92,17.86,0.067
119.94,18.04,0.067
119.95,18.23,0.067
119.97,18.41,0.067
119.99,18.59,0.067
120.01,18.77,0.067
120.03,18.96,0.067
120.05,19.14,0.067
120.06,19.32,0.067
120.08,19.51,0.067
120.10,19.69,0.067
120.12,19.87,0.067
120.14,20.06,0.067
120.15,20.24,0.067
120.17,20.42,0.067
120.19,20.61,0.067
120.21,20.79,0.067
120.23,20.97,0.067
120.25,21.16,0.067
120.26,21.34,0.067
120.28,21.52,0.067
120.30,21.71,0.067
120.32,21.89,0.067
120.34,22.08,0.067
120.36,22.26,0.068
120.38,22.44,0.068
120.39,22.63,0.068
120.41,22.81,0.068
120.43,22.99,0.068
120.45,23.18,0.068
120.47,23.36,0.068
120.49,23.54,0.068
120.50,23.73,0.068
120.52,23.91,0.068
120.54,24.09,0.068
120.56,24.28,0.068
120.58,24.46,0.068
120.60,24.65,0.068
120.61,24.83,0.068
120.63,25.01,0.068
120.65,25.20,0.068
120.67,25.38,0.068
120.69,25.56,0.068
120.70,25.75,0.068
120.72,25.93,0.068
120.74,26.11,0.068
120.76,26.30,0.068
120.78,26.48,0.068
120.80,26.66,0.069
120.81,26.85,0.069
120.83,27.03,0.069
120.85,27.21,0.069
120.87,27.40,0.069
120.89,27.58,0.069
120.91,27.76,0.069
120.93,27.95,0.069
120.94,28.13,0.069
120.96,28.31,0.069
120.98,28.50,0.069
121.00,28.68,0.069
121.02,28.87,0.069
121.04,29.05,0.069
121.05,29.23,0.069
121.07,29.42,0.069
121.09,29.60,0.069
121.11,29.78,0.069
121.13,29.97,0.069
121.15,30.15,0.069
121.16,30.33,0.069
121.18,30.52,0.069
121.20,30.70,0.069
121.22,30.88,0.069
121.24,31.07,0.069
121.25,31.25,0.069
121.27,31.44,0.069
121.29,31.62,0.070
121.31,31.80,0.070
121.33,31.99,0.070
121.35,32.17,0.070
121.36,32.35,0.070
121.38,32.54,0.070
121.40,32.72,0.070
121.42,32.90,0.070
121.44,33.09,0.070
121.46,33.27,0.070
121.48,33.46,0.070
121.49,33.64,0.070
121.51,33.82,0.070
121.53,34.00,0.070
121.55,34.19,0.070
121.57,34.37,0.070
121.59,34.55,0.070
121.60,34.74,0.070
121.62,34.92,0.070
121.64,35.11,0.070
121.66,35.29,0.070
121.68,35.47,0.070
121.70,35.66,0.070
121.71,35.84,0.070
121.73,36.02,0.070
121.75,36.21,0.070
121.77,36.39,0.070
121.79,36.57,0.070
121.80,36.76,0.071
121.82,36.94,0.071
121.84,37.12,0.071
121.86,37.31,0.071
121.88,37.49,0.071
121.90,37.67,0.071
121.91,37.86,0.071
121.93,38.04,0.071
121.95,38.22,0.071
121.97,38.41,0.071
121.99,38.59,0.071
122.01,38.78,0.071
122.03,38.96,0.071
122.04,39.14,0.071
122.06,39.33,0.071
122.08,39.51,0.071
122.10,39.69,0.071
122.12,39.88,0.071
122.14,40.06,0.071
122.15,40.24,0.071
122.17,40.43,0.071
122.19,40.61,0.071
122.21,40.79,0.071
122.23,40.98,0.071
122.25,41.16,0.071
122.26,41.34,0.071
122.28,41.53,0.071
122.30,41.71,0.071
122.32,41.90,0.071
122.34,42.08,0.071
122.35,42.26,0.072
122.37,42.45,0.072
122.39,42.63,0.072
122.41,42.81,0.072
122.43,43.00,0.072
122.45,43.18,0.072
122.46,43.36,0.072
122.48,43.55,0.072
122.50,43.73,0.072
122.52,43.91,0.072
122.54,44.10,0.072
122.56,44.28,0.072
122.58,44.46,0.072
122.59,44.65,0.072
122.61,44.83,0.072
122.63,45.01,0.072
122.65,45.20,0.072
122.67,45.38,0.072
122.69,45.57,0.072
122.70,45.75,0.072
122.72,45.93,0.072
122.74,46.11,0.072
122.76,46.30,0.072
122.78,46.48,0.072
122.80,46.67,0.072
122.81,46.85,0.072
122.83,47.03,0.072
122.85,47.22,0.073
122.87,47.40,0.073
122.89,47.58,0.073
122.90,47.77,0.073
122.92,47.95,0.073
122.94,48.13,0.073
122.96,48.32,0.073
122.98,48.50,0.073
123.00,48.69,0.073
123.01,48.87,0.073
123.03,49.05,0.073
123.05,49.24,0.073
123.07,49.42,0.073
123.09,49.60,0.073
123.11,49.79,0.073
123.13,49.97,0.073
123.14,50.15,0.073
123.16,50.34,0.073
123.18,50.52,0.073
123.20,50.70,0.073
123.22,50.89,0.073
123.24,51.07,0.073
123.25,51.25,0.073
123.27,51.44,0.073
123.29,51.62,0.073
123.31,51.80,0.073
123.33,51.99,0.073
123.35,52.17,0.073
123.36,52.35,0.073
123.38,52.54,0.074
123.40,52.72,0.074
123.42,52.90,0.074
123.44,53.09,0.074
123.45,53.27,0.074
123.47,53.45,0.074
123.49,53.64,0.074
123.51,53.82,0.074
123.53,54.00,0.074
123.55,54.19,0.074
123.56,54.37,0.074
123.58,54.55,0.074
123.60,54.74,0.074
123.62,54.92,0.074
123.64,55.11,0.074
123.66,55.29,0.074
123.68,55.47,0.074
123.69,55.66,0.074
123.71,55.84,0.074
123.73,56.02,0.074
123.75,56.21,0.074
123.77,56.39,0.074
123.79,56.57,0.074
123.80,56.76,0.074
123.82,56.94,0.074
123.84,57.12,0.074
123.86,57.31,0.074
123.88,57.49,0.075
123.90,57.68,0.075
123.91,57.86,0.075
123.93,58.04,0.075
123.95,58.23,0.075
123.97,58.41,0.075
123.99,58.59,0.075
124.00,58.78,0.075
124.02,58.96,0.075
124.04,59.14,0.075
124.06,59.33,0.075
124.08,59.51,0.075
124.10,59.69,0.075
124.11,59.88,0.075
124.13,60.06,0.075
124.15,60.24,0.075
124.17,60.43,0.075
124.19,60.61,0.075
124.21,60.79,0.075
124.23,60.98,0.075
124.24,61.16,0.075
124.26,61.35,0.075
124.28,61.53,0.075
124.30,61.71,0.075
124.32,61.90,0.075
124.34,62.08,0.076
124.35,62.26,0.076
124.37,62.45,0.076
124.39,62.63,0.076
124.41,62.81,0.076
124.43,63.00,0.076
124.45,63.18,0.076
124.46,63.36,0.076
124.48,63.55,0.076
124.50,63.73,0.076
124.52,63.91,0.076
124.54,64.10,0.076
124.55,64.28,0.076
124.57,64.46,0.076
124.59,64.65,0.076
124.61,64.83,0.076
124.63,65.01,0.076
124.65,65.20,0.076
124.66,65.38,0.076
124.68,65.57,0.076
124.70,65.75,0.076
124.72,65.93,0.076
124.74,66.12,0.076
124.76,66.30,0.077
124.78,66.48,0.077
124.79,66.67,0.077
124.81,66.85,0.077
124.83,67.03,0.077
124.85,67.22,0.077
124.87,67.40,0.077
124.89,67.58,0.077
124.90,67.77,0.077
124.92,67.95,0.077
124.94,68.13,0.077
124.96,68.32,0.077
124.98,68.50,0.077
125.00,68.68,0.077
125.01,68.87,0.077
125.03,69.05,0.077
125.05,69.23,0.077
125.07,69.42,0.077
125.09,69.60,0.077
125.10,69.78,0.077
125.12,69.97,0.077
125.14,70.15,0.078
125.16,70.34,0.078
125.18,70.52,0.078
125.20,70.70,0.078
125.21,70.88,0.078
125.23,71.07,0.078
125.25,71.25,0.078
125.27,71.43,0.078
125.29,71.62,0.078
125.31,71.80,0.078
125.33,71.98,0.078
125.34,72.17,0.078
125.36,72.35,0.078
125.38,72.54,0.078
125.40,72.72,0.078
125.42,72.90,0.078
125.44,73.08,0.078
125.45,73.27,0.078
125.47,73.45,0.078
125.49,73.64,0.079
125.51,73.82,0.079
125.53,74.00,0.079
125.55,74.18,0.079
125.56,74.37,0.079
125.58,74.55,0.079
125.60,74.74,0.079
125.62,74.92,0.079
125.64,75.10,0.079
125.65,75.29,0.079
125.67,75.47,0.079
125.69,75.65,0.079
125.71,75.84,0.079
125.73,76.02,0.079
125.75,76.20,0.079
125.76,76.39,0.080
125.78,76.57,0.080
125.80,76.75,0.080
125.82,76.94,0.080
125.84,77.12,0.080
125.86,77.30,0.080
125.88,77.49,0.080
125.89,77.67,0.080
125.91,77.85,0.080
125.93,78.04,0.080
125.95,78.22,0.081
125.97,78.40,0.081
125.99,78.59,0.081
126.00,78.77,0.081
126.02,78.95,0.081
126.04,79.14,0.081
126.06,79.32,0.081
126.08,79.50,0.081
126.10,79.69,0.081
126.11,79.87,0.081
126.13,80.05,0.081
126.15,80.24,0.081
126.17,80.42,0.081
126.19,80.60,0.081
126.20,80.79,0.082
126.22,80.97,0.082
126.24,81.15,0.082
126.26,81.34,0.082
126.28,81.52,0.082
126.30,81.70,0.082
126.31,81.89,0.082
126.33,82.07,0.082
126.35,82.25,0.082
126.37,82.44,0.082
126.39,82.62,0.083
126.41,82.80,0.083
126.43,82.99,0.083
126.44,83.17,0.083
126.46,83.35,0.083
126.48,83.54,0.083
126.50,83.72,0.083
126.52,83.90,0.083
126.54,84.09,0.084
126.55,84.27,0.084
126.57,84.45,0.084
126.59,84.64,0.084
126.61,84.82,0.084
126.63,85.00,0.084
126.65,85.19,0.084
126.66,85.37,0.084
126.68,85.55,0.085
126.70,85.73,0.085
126.72,85.92,0.085
126.74,86.10,0.085
126.75,86.28,0.085
126.77,86.47,0.086
126.79,86.65,0.086
126.81,86.83,0.086
126.83,87.02,0.086
126.85,87.20,0.086
126.86,87.38,0.087
126.88,87.57,0.087
126.90,87.75,0.087
126.92,87.93,0.087
126.94,88.11,0.088
126.96,88.30,0.088
126.98,88.48,0.088
126.99,88.66,0.088
127.01,88.85,0.088
127.03,89.03,0.089
127.05,89.21,0.089
127.07,89.40,0.089
127.09,89.58,0.089
127.10,89.76,0.090
127.12,89.95,0.090
127.14,90.13,0.090
127.16,90.31,0.090
127.18,90.50,0.091
127.20,90.68,0.091
127.21,90.86,0.091
127.23,91.05,0.091
127.25,91.23,0.092
127.27,91.41,0.092
127.29,91.59,0.092
127.30,91.78,0.092
127.32,91.96,0.092
127.34,92.14,0.093
127.36,92.33,0.093
127.38,92.51,0.093
127.40,92.69,0.093
127.41,92.87,0.093
127.43,93.06,0.094
127.45,93.24,0.094
127.47,93.43,0.094
127.49,93.61,0.094
127.51,93.79,0.094
127.53,93.97,0.095
127.54,94.16,0.095
127.56,94.34,0.095
127.58,94.52,0.095
127.60,94.71,0.095
127.62,94.89,0.095
127.64,95.07,0.095
127.65,95.26,0.095
127.67,95.44,0.096
127.69,95.62,0.096
127.71,95.81,0.096
127.73,95.99,0.096
127.75,96.17,0.096
127.76,96.36,0.096
127.78,96.54,0.096
127.80,96.72,0.096
127.82,96.91,0.096
127.84,97.09,0.097
127.85,97.27,0.097
127.87,97.46,0.097
127.89,97.64,0.097
127.91,97.83,0.097
127.93,98.01,0.097
127.95,98.19,0.097
127.96,98.38,0.097
127.98,98.56,0.097
128.00,98.74,0.097
128.02,98.93,0.097
128.04,99.11,0.097
128.06,99.29,0.097
128.08,99.47,0.097
128.09,99.66,0.097
128.11,99.84,0.098
128.13,100.02,0.098
128.15,100.21,0.098
128.17,100.39,0.098
128.19,100.58,0.098
128.20,100.76,0.098
128.22,100.94,0.098
128.24,101.13,0.098
128.26,101.31,0.098
128.28,101.49,0.098
128.30,101.68,0.098
128.31,101.86,0.098
128.33,102.04,0.098
128.35,102.23,0.098
128.37,102.41,0.098
128.39,102.60,0.098
128.40,102.78,0.098
128.42,102.96,0.098
128.44,103.15,0.098
128.46,103.33,0.098
128.48,103.51,0.098
128.50,103.70,0.098
128.51,103.88,0.098
128.53,104.07,0.098
128.55,104.25,0.098
128.57,104.43,0.098
128.59,104.62,0.098
128.61,104.80,0.098
128.63,104.98,0.098
128.64,105.17,0.098
128.66,105.35,0.098
128.68,105.53,0.098
128.70,105.72,0.098
128.72,105.90,0.098
128.74,106.08,0.098
128.75,106.27,0.098
128.77,106.45,0.098
128.79,106.63,0.098
128.81,106.82,0.098
128.83,107.00,0.098
128.85,107.18,0.098
128.86,107.37,0.098
128.88,107.55,0.098
128.90,107.74,0.098
128.92,107.92,0.098
128.94,108.10,0.098
128.95,108.28,0.098
128.97,108.47,0.098
128.99,108.65,0.098
129.01,108.83,0.098
129.03,109.02,0.098
129.05,109.20,0.098
129.06,109.39,0.098
129.08,109.57,0.098
129.10,109.75,0.098
129.12,109.94,0.098
129.14,110.12,0.098
129.16,110.30,0.098
129.18,110.49,0.098
129.19,110.67,0.098
129.21,110.86,0.098
129.23,111.04,0.098
129.25,111.22,0.098
129.27,111.41,0.098
129.29,111.59,0.098
129.30,111.77,0.098
129.32,111.95,0.098
129.34,112.14,0.098
129.36,112.32,0.098
129.38,112.50,0.098
129.40,112.69,0.098
129.41,112.87,0.098
129.43,113.06,0.098
129.45,113.24,0.098
129.47,113.42,0.098
129.49,113.61,0.098
129.50,113.79,0.098
129.52,113.97,0.098
129.54,114.15,0.098
129.56,114.34,0.098
129.58,114.52,0.098
129.60,114.70,0.098
129.61,114.89,0.098
129.63,115.07,0.098
129.65,115.26,0.098
129.67,115.44,0.098
129.69,115.62,0.098
129.71,115.81,0.098
129.73,115.99,0.098
129.74,116.17,0.098
129.76,116.36,0.098
129.78,116.54,0.098
129.80,116.73,0.098
129.82,116.91,0.098
129.84,117.09,0.099
129.85,117.27,0.099
129.87,117.46,0.099
129.89,117.64,0.099
129.91,117.83,0.099
129.93,118.01,0.099
129.95,118.19,0.099
129.96,118.38,0.099
129.98,118.56,0.099
130.00,118.74,0.099
130.02,118.93,0.099
130.04,119.11,0.099
130.05,119.29,0.099
130.07,119.48,0.099
130.09,119.66,0.099
130.11,119.84,0.099
130.13,120.03,0.099
130.15,120.21,0.099
130.16,120.39,0.099
130.18,120.58,0.099
130.20,120.76,0.099
130.22,120.95,0.099
130.24,121.13,0.099
130.26,121.31,0.099
130.28,121.50,0.099
130.29,121.68,0.099
130.31,121.86,0.099
130.33,122.05,0.099
130.35,122.23,0.099
130.37,122.41,0.099
130.39,122.60,0.099
130.40,122.78,0.099
130.42,122.96,0.099
130.44,123.15,0.099
130.46,123.33,0.099
130.48,123.51,0.099
130.50,123.70,0.099
130.51,123.88,0.099
130.53,124.07,0.099
130.55,124.25,0.099
130.57,124.43,0.099
130.59,124.62,0.099
130.60,124.80,0.099
130.62,124.98,0.099
130.64,125.17,0.099
130.66,125.35,0.099
130.68,125.53,0.099
130.70,125.72,0.099
130.71,125.90,0.099
130.73,126.08,0.099
130.75,126.27,0.099
130.77,126.45,0.099
130.79,126.64,0.099
130.81,126.82,0.099
130.83,127.00,0.100
130.84,127.18,0.100
130.86,127.37,0.100
130.88,127.55,0.100
130.90,127.73,0.100
130.92,127.92,0.100
130.94,128.10,0.100
130.95,128.29,0.100
130.97,128.47,0.100
130.99,128.65,0.100
131.01,128.84,0.100
131.03,129.02,0.100
131.05,129.20,0.100
131.06,129.39,0.100
131.08,129.57,0.100
131.10,129.75,0.100
131.12,129.94,0.100
131.14,130.12,0.100
131.15,130.31,0.100
131.17,130.49,0.100
131.19,130.67,0.100
131.21,130.85,0.100
131.23,131.04,0.100
131.25,131.22,0.100
131.26,131.41,0.100
131.28,131.59,0.100
131.30,131.77,0.100
131.32,131.96,0.100
131.34,132.14,0.100
131.36,132.32,0.100
131.38,132.51,0.100
131.39,132.69,0.100
131.41,132.87,0.100
131.43,133.06,0.101
131.45,133.24,0.101
131.47,133.42,0.101
131.49,133.61,0.101
131.50,133.79,0.101
131.52,133.97,0.101
131.54,134.16,0.101
131.56,134.34,0.101
131.58,134.52,0.101
131.60,134.71,0.101
131.61,134.89,0.101
131.63,135.07,0.101
131.65,135.26,0.101
131.67,135.44,0.101
131.69,135.63,0.102
131.70,135.81,0.102
131.72,135.99,0.102
131.74,136.18,0.102
131.76,136.36,0.102
131.78,136.54,0.102
131.80,136.73,0.102
131.81,136.91,0.102
131.83,137.09,0.103
131.85,137.28,0.103
131.87,137.46,0.103
131.89,137.65,0.104
131.91,137.83,0.104
131.93,138.02,0.105
131.94,138.20,0.105
131.96,138.38,0.105
131.98,138.57,0.105
132.00,138.75,0.105
132.02,138.93,0.105
132.04,139.12,0.105
132.05,139.30,0.105
132.07,139.48,0.105
132.09,139.66,0.105
132.11,139.85,0.105
132.13,140.03,0.105
132.15,140.21,0.105
132.16,140.39,0.105
132.18,140.58,0.105
132.20,140.76,0.105
132.22,140.95,0.105
132.24,141.13,0.105
132.25,141.31,0.105
132.27,141.49,0.105
132.29,141.68,0.105
132.31,141.86,0.105
132.33,142.04,0.105
132.35,142.23,0.105
132.36,142.41,0.105
132.38,142.59,0.105
132.40,142.78,0.105
132.42,142.96,0.105
132.44,143.14,0.105
132.46,143.33,0.105
132.48,143.51,0.105
132.49,143.70,0.105
132.51,143.88,0.105
132.53,144.06,0.105
132.55,144.24,0.105
132.57,144.43,0.105
132.59,144.61,0.105
132.60,144.79,0.105
132.62,144.98,0.105
132.64,145.16,0.105
132.66,145.34,0.105
132.68,145.53,0.105
132.70,145.71,0.105
132.71,145.89,0.105
132.73,146.08,0.105
132.75,146.26,0.106
132.77,146.45,0.106
132.79,146.63,0.106
132.80,146.81,0.106
132.82,146.99,0.106
132.84,147.18,0.106
132.86,147.36,0.106
132.88,147.54,0.106
132.90,147.73,0.106
132.91,147.91,0.106
132.93,148.09,0.106
132.95,148.28,0.106
132.97,148.46,0.106
132.99,148.65,0.106
133.01,148.83,0.106
133.03,149.01,0.106
133.04,149.20,0.106
133.06,149.38,0.106
133.08,149.56,0.106
133.10,149.75,0.106
133.12,149.93,0.106
133.14,150.11,0.106
133.15,150.30,0.106
133.17,150.48,0.106
133.19,150.66,0.106
133.21,150.85,0.106
133.23,151.03,0.106
133.25,151.21,0.106
133.26,151.40,0.106
133.28,151.58,0.106
133.30,151.76,0.106
133.32,151.95,0.106
133.34,152.13,0.106
133.35,152.31,0.107
133.37,152.50,0.107
133.39,152.68,0.107
133.41,152.86,0.107
133.43,153.05,0.107
133.45,153.23,0.107
133.46,153.41,0.107
133.48,153.60,0.107
133.50,153.78,0.107
133.52,153.96,0.107
133.54,154.15,0.107
133.56,154.33,0.107
133.58,154.51,0.107
133.59,154.70,0.107
133.61,154.88,0.107
133.63,155.07,0.107
133.65,155.25,0.107
133.67,155.43,0.107
133.69,155.62,0.107
133.70,155.80,0.107
133.72,155.98,0.107
133.74,156.17,0.107
133.76,156.35,0.107
133.78,156.53,0.107
133.80,156.72,0.107
133.81,156.90,0.108
133.83,157.08,0.108
133.85,157.27,0.108
133.87,157.45,0.108
133.89,157.63,0.108
133.90,157.82,0.108
133.92,158.00,0.108
133.94,158.18,0.108
133.96,158.37,0.108
133.98,158.55,0.108
134.00,158.73,0.108
134.01,158.92,0.108
134.03,159.10,0.108
134.05,159.28,0.108
134.07,159.47,0.108
134.09,159.65,0.108
134.11,159.83,0.108
134.13,160.02,0.108
134.14,160.20,0.108
134.16,160.38,0.108
134.18,160.57,0.108
134.20,160.75,0.108
134.22,160.93,0.108
134.24,161.12,0.109
134.25,161.30,0.109
134.27,161.48,0.109
134.29,161.67,0.109
134.31,161.85,0.109
134.33,162.03,0.109
134.35,162.22,0.109
134.36,162.40,0.109
134.38,162.58,0.109
134.40,162.77,0.109
134.42,162.95,0.109
134.44,163.14,0.109
134.45,163.32,0.109
134.47,163.50,0.109
134.49,163.69,0.109
134.51,163.87,0.109
134.53,164.05,0.109
134.55,164.23,0.109
134.56,164.42,0.109
134.58,164.60,0.110
134.60,164.79,0.110
134.62,164.97,0.110
134.64,165.15,0.110
134.66,165.34,0.110
134.68,165.52,0.110
134.69,165.70,0.110
134.71,165.89,0.110
134.73,166.07,0.110
134.75,166.26,0.110
134.77,166.44,0.110
134.79,166.62,0.110
134.80,166.81,0.110
134.82,166.99,0.110
134.84,167.17,0.110
134.86,167.35,0.110
134.88,167.54,0.110
134.90,167.72,0.110
134.91,167.91,0.110
134.93,168.09,0.111
134.95,168.27,0.111
134.97,168.46,0.111
134.99,168.64,0.111
135.00,168.82,0.111
135.02,169.01,0.111
135.04,169.19,0.111
135.06,169.37,0.111
135.08,169.56,0.111
135.10,169.74,0.111
135.11,169.92,0.111
135.13,170.11,0.111
135.15,170.29,0.111
135.17,170.47,0.111
135.19,170.66,0.111
135.21,170.84,0.111
135.23,171.02,0.111
135.24,171.21,0.111
135.26,171.39,0.111
135.28,171.57,0.111
135.30,171.76,0.112
135.32,171.94,0.112
135.34,172.12,0.112
135.35,172.31,0.112
135.37,172.49,0.112
135.39,172.67,0.112
135.41,172.86,0.112
135.43,173.04,0.112
135.45,173.22,0.112
135.46,173.41,0.112
135.48,173.59,0.112
135.50,173.77,0.112
135.52,173.96,0.112
135.54,174.14,0.112
135.55,174.32,0.112
135.57,174.51,0.112
135.59,174.69,0.113
135.61,174.87,0.113
135.63,175.06,0.113
135.65,175.24,0.113
135.66,175.43,0.113
135.68,175.61,0.113
135.70,175.79,0.113
135.72,175.98,0.113
135.74,176.16,0.113
135.76,176.34,0.113
135.78,176.52,0.113
135.79,176.71,0.113
135.81,176.89,0.113
135.83,177.07,0.113
135.85,177.26,0.113
135.87,177.44,0.114
135.89,177.62,0.114
135.90,177.81,0.114
135.92,177.99,0.114
135.94,178.17,0.114
135.96,178.36,0.114
135.98,178.54,0.114
136.00,178.72,0.114
136.01,178.91,0.114
136.03,179.09,0.114
136.05,179.28,0.114
136.07,179.46,0.114
136.09,179.64,0.114
136.10,179.83,0.114
136.12,180.01,0.115
136.14,180.19,0.115
136.16,180.38,0.115
136.18,180.56,0.115
136.20,180.74,0.115
136.21,180.93,0.115
136.23,181.11,0.115
136.25,181.29,0.115
136.27,181.48,0.115
136.29,181.66,0.115
136.31,181.84,0.115
136.33,182.03,0.115
136.34,182.21,0.116
136.36,182.39,0.116
136.38,182.57,0.116
136.40,182.76,0.116
136.42,182.94,0.116
136.44,183.12,0.116
136.45,183.31,0.116
136.47,183.49,0.116
136.49,183.68,0.116
136.51,183.86,0.116
136.53,184.04,0.117
136.55,184.23,0.117
136.56,184.41,0.117
136.58,184.59,0.117
136.60,184.78,0.117
136.62,184.96,0.117
136.64,185.14,0.117
136.65,185.33,0.117
136.67,185.51,0.117
136.69,185.69,0.117
136.71,185.87,0.117
136.73,186.06,0.118
136.75,186.24,0.118
136.77,186.42,0.118
136.78,186.61,0.118
136.80,186.79,0.118
136.82,186.97,0.118
136.84,187.16,0.118
136.86,187.34,0.118
136.88,187.52,0.118
136.89,187.71,0.119
136.91,187.89,0.119
136.93,188.07,0.119
136.95,188.26,0.119
136.97,188.44,0.119
136.98,188.62,0.119
137.00,188.81,0.119
137.02,188.99,0.119
137.04,189.17,0.120
137.06,189.36,0.120
137.08,189.54,0.120
137.10,189.73,0.120
137.11,189.91,0.120
137.13,190.09,0.120
137.15,190.28,0.120
137.17,190.46,0.120
137.19,190.64,0.120
137.20,190.82,0.121
137.22,191.01,0.121
137.24,191.19,0.121
137.26,191.38,0.121
137.28,191.56,0.121
137.30,191.74,0.121
137.32,191.93,0.121
137.33,192.11,0.121
137.35,192.29,0.121
137.37,192.48,0.121
137.39,192.66,0.121
137.41,192.84,0.122
137.43,193.02,0.122
137.44,193.21,0.122
137.46,193.39,0.122
137.48,193.57,0.122
137.50,193.76,0.122
137.52,193.94,0.122
137.53,194.12,0.123
137.55,194.31,0.123
137.57,194.49,0.123
137.59,194.67,0.123
137.61,194.86,0.123
137.63,195.04,0.123
137.65,195.22,0.123
137.66,195.41,0.123
137.68,195.59,0.123
137.70,195.77,0.123
137.72,195.96,0.124
137.74,196.14,0.124
137.75,196.32,0.124
137.77,196.51,0.124
137.79,196.69,0.124
137.81,196.87,0.124
137.83,197.06,0.124
137.85,197.24,0.124
137.87,197.42,0.124
137.88,197.61,0.124
137.90,197.79,0.124
137.92,197.97,0.124
137.94,198.16,
137.96,198.34,
137.98,198.53,
137.99,,
138.00,,