File: DSC/Olivia/2025_07_07_CBD_PVP_5p5_Vac_SealedPan_n60C_90C_10Cmin_x4.csv
Filename,2025_07_07_CBD_PVP_5p5_Vac_SealedPan_n60C_90C_10Cmin_x4
Instrument name,DSC2A-00468 (192.168.1.100)
Operator,Gibbons
rundate,7/7/2025
Sample name,2025_07_07_CBD_PVP_5p5_Vac_SealedPan_n60C_90C_10Cmin_x4
proceduresegments,Data Off ; Equilibrate -60.00 °C; Data On ; Ramp 10.00 °C/min to 90.00 °C; Data Off ; Isothermal 2.0 min; Data On ; Ramp 10.00 °C/min to -60.00 °C; Data Off ; Isothermal 2.0 min; Data On ; Ramp 10.00 °C/min to 90.00 °C; Data Off ; Isothermal 2.0 min; Data On ; Ramp 10.00 °C/min to -60.00 °C; Data Off ; Isothermal 2.0 min; Data On ; Ramp 10.00 °C/min to 90.00 °C; Data Off ; Isothermal 2.0 min; Data On ; Ramp 10.00 °C/min to -60.00 °C; Data Off ; Isothermal 2.0 min; Data On ; Ramp 10.00 °C/min to 30.00 °C
[File Parameters]
Run date,7/7/2025 4:36:55 PM
Trios version,5.1.1.46572
Original File Name,
Current File Name,D:\DSC2500\Gibbons\2025_07_07_CBD_PVP_5p5_Vac_SealedPan_n60C_90C_10Cmin_x4.tri
[Procedure]
Procedure Name,CBD_PVP_5p5_Vac_SealedPan_n60C_90C_10Cmin_x4
Sample Name,2025_07_07_CBD_PVP_5p5_Vac_SealedPan_n60C_90C_10Cmin_x4
Sample Mass,2.69 mg
Reference Sample Mass,0 mg
Pan Mass,56.51 mg
Pan Number,51
Reference Pan Mass,56.76 mg
Reference Pan Number,10
Pan Type,Tzero Aluminum Hermetic
Comments,DSC Consumables Al Hermetically Sealed Pan. Y1 Tray (Google Sheet: DSC_Samples_Y1_Tray_June2025).
Project Name,Pharma - Biopolymers
Operator,Gibbons
Test,Custom
Unload Max Temperature,30
Unload Min Temperature,30
Load Max Temperature,30
Load Min Temperature,30
Stop on Gas Flow Error,Yes
[Signal List]
Signal #1,Time (min)
Signal #2,Temperature (°C)
Signal #3,Heat Flow (mW)
Signal #4,Delta T (µV)
Signal #5,Delta Tzero (µV)
Signal #6,Tzero Temperature (°C)
Signal #7,Cell Purge (mL/min)
Signal #8,Heater Temp (°C)
Signal #9,Power Delivered (W)
Signal #10,Reference Junction Temperature (°C)
Signal #11,Flange Temperature (°C)
Signal #12,Heat Flow Phase (rad)
Signal #13,Total Heat Capacity (J/°C)
Signal #14,Heat Capacity (J/°C)
[Configuration]
Company Name,ASU
Instrument Name,DSC2A-00468
Instrument Type,DSC2500
Serial Number,DSC2A-00468
IP,192.168.1.100
Location of Instrument,MRRC
DisplayType,Unknown
Sample Interval ,0.1 s/pt
Selected Heat Flow,T4P
Exotherm Direction,Down
Cell Serial,DRC2-00792
Lid Type,Standard
Cooler,RCS 90
Leave Cooler on at End of Sequence,On
Gas 2,Nitrogen
Gas Selected,Channel 1
Flow Rate,50 mL/min
Secondary Purge,On
Licensed Heat Flow,Heat Flow T4P
Modulation Licensed,Yes
[Versions]
Common IDD Version,1
Cortex Version,VER 2.10.2.31
Driver,5.0.0.6
GDM Version,1.0.3.3
TouchscreenVersion,1.0.0.16145
FEP Version,1.2.1.21
FEP Bootloader,2.0.0.5
AutoSampler Version,2.1.1.26
Auto Sampler Bootloader,2.0.0.5
FCM Version,1.1.0.3
FCM Bootloader,2.0.0.5
[Experiment Logs]
Experiment Log Entry # 1,Data On set to 0
Experiment Log Entry # 3,Equilibrate Segment -60 (C) Started
Experiment Log Entry # 5,Air Cool is off.
Experiment Log Entry # 7,Data On set to 1
Experiment Log Entry # 9,Ramp Segment 10 C/min to 90 Started
Experiment Log Entry # 11,Auto sampler has detected that GDM has gone offline
Experiment Log Entry # 13,Data On set to 0
Experiment Log Entry # 15,Isothermal Segment 2 min started
Experiment Log Entry # 17,Data On set to 1
Experiment Log Entry # 19,Ramp Segment 10 C/min to -60 Started
Experiment Log Entry # 21,Data On set to 0
Experiment Log Entry # 23,Isothermal Segment 2 min started
Experiment Log Entry # 25,Data On set to 1
Experiment Log Entry # 27,Ramp Segment 10 C/min to 90 Started
Experiment Log Entry # 29,Data On set to 0
Experiment Log Entry # 31,Isothermal Segment 2 min started
Experiment Log Entry # 33,Data On set to 1
Experiment Log Entry # 35,Ramp Segment 10 C/min to -60 Started
Experiment Log Entry # 37,Data On set to 0
Experiment Log Entry # 39,Isothermal Segment 2 min started
Experiment Log Entry # 41,Data On set to 1
Experiment Log Entry # 43,Ramp Segment 10 C/min to 90 Started
Experiment Log Entry # 45,Data On set to 0
Experiment Log Entry # 47,Isothermal Segment 2 min started
Experiment Log Entry # 49,Data On set to 1
Experiment Log Entry # 51,Ramp Segment 10 C/min to -60 Started
Experiment Log Entry # 53,Data On set to 0
Experiment Log Entry # 55,Isothermal Segment 2 min started
Experiment Log Entry # 57,Data On set to 1
Experiment Log Entry # 59,Ramp Segment 10 C/min to 30 Started
[Method Log]
Method Log Entry # 1,Data Off
Method Log Entry # 2,Equilibrate -60 °C
Method Log Entry # 3,Data On
Method Log Entry # 4,(Ramp 1448421) Ramp 10 °C/minute to 90 °C
Method Log Entry # 5,Data Off
Method Log Entry # 6,Isothermal 2 minutes
Method Log Entry # 7,Data On
Method Log Entry # 8,(Ramp 1448425) Ramp 10 °C/minute to -60 °C
Method Log Entry # 9,Data Off
Method Log Entry # 10,Isothermal 2 minutes
Method Log Entry # 11,Data On
Method Log Entry # 12,(Ramp 1448429) Ramp 10 °C/minute to 90 °C
Method Log Entry # 13,Data Off
Method Log Entry # 14,Isothermal 2 minutes
Method Log Entry # 15,Data On
Method Log Entry # 16,(Ramp 1448433) Ramp 10 °C/minute to -60 °C
Method Log Entry # 17,Data Off
Method Log Entry # 18,Isothermal 2 minutes
Method Log Entry # 19,Data On
Method Log Entry # 20,(Ramp 1448437) Ramp 10 °C/minute to 90 °C
Method Log Entry # 21,Data Off
Method Log Entry # 22,Isothermal 2 minutes
Method Log Entry # 23,Data On
Method Log Entry # 24,(Ramp 1448441) Ramp 10 °C/minute to -60 °C
Method Log Entry # 25,Data Off
Method Log Entry # 26,Isothermal 2 minutes
Method Log Entry # 27,Data On
Method Log Entry # 28,(Ramp 1448445) Ramp 10 °C/minute to 30 °C
Cell Serial,DRC2-00792
[T1 Calibration]
Slope,-0.008529666
Offset,9.636258
Initial Temperature,98.23
GUID,f8bfdadc-4977-4fdf-ba6d-0ba9134940c3
[TZero Calibration]
Date Applied,11/29/2022 4:06:13 PM
Description,From -89.059 °C to 396.009 °C at 20.000°C/min
Gas Type,Nitrogen
Pan Type,None
Source Files 1,C:\Users\yargerlab\Desktop\DSC Data\General\TZero_calibration_11_29_22_2nd(2).tri
Source Files 2,C:\Users\yargerlab\Desktop\DSC Data\General\TZero_calibration_11_29_22_2nd(3).tri
Delta T Offset,13.05235
Delta T Slope,-0.007271007
Delta T0 Offset,-13.69128
Delta T0 Slope,0.06063341
[Temperature Calibration]
Date Applied,11/29/2022 7:12:28 PM
Description,From 106.590 °C to 186.590 °C at 10.000°C/min
Gas Type,Nitrogen
Pan Type,Tzero Aluminum Hermetic
Source Files 1,C:\Users\yargerlab\Desktop\DSC Data\General\Indium(6).tri
Measured 1,157.391
Known 1,156.598
[Cell Constant Calibration]
Date Applied,11/29/2022 7:12:29 PM
Description,From 106.590 °C to 186.590 °C at 10.000°C/min
Gas Type,Nitrogen
Pan Type,Tzero Aluminum Hermetic
Source Files 1,C:\Users\yargerlab\Desktop\DSC Data\General\Indium(6).tri
T4P KCell,1.006051
Onset Slope,63.26126 mW/°C
[Direct Cp Calibration]
Date Applied,11/30/2022 11:04:51 AM
Description,From -79.983 °C to 298.409 °C at 10.000°C/min
Gas Type,Nitrogen
Pan Type,Tzero Aluminum Hermetic
Source Files 1,C:\Users\yargerlab\Desktop\DSC Data\General\Sapphire_Heat_Capacity_11_30_22.tri
[Rev Cp Calibration]
Date Applied,11/30/2022 1:58:51 PM
Description,From -79.996 °C to 292.812 °C at 3.000°C/min
Gas Type,Nitrogen
Pan Type,Tzero Aluminum Hermetic
Source Files 1,C:\Users\yargerlab\Desktop\DSC Data\General\Sapphire_MDSC_Calibration_11_30_22.tri
[step]
Ramp 10.00 °C/min to 90.00 °C
Time,Temperature,Heat Flow (Normalized)
min,°C,W/g
0.00,-59.72,-0.053
0.01,-59.73,-0.053
0.02,-59.74,-0.051
0.03,-59.74,-0.047
0.04,-59.74,-0.045
0.05,-59.74,-0.044
0.06,-59.74,-0.044
0.07,-59.73,-0.044
0.08,-59.71,-0.046
0.09,-59.69,-0.051
0.10,-59.67,-0.054
0.11,-59.64,-0.058
0.12,-59.60,-0.060
0.13,-59.55,-0.060
0.14,-59.51,-0.059
0.15,-59.45,-0.055
0.16,-59.39,-0.038
0.17,-59.33,-0.021
0.18,-59.26,-0.001
0.19,-59.20,0.013
0.20,-59.12,0.028
0.21,-59.05,0.043
0.22,-58.97,0.059
0.23,-58.89,0.071
0.24,-58.81,0.084
0.25,-58.72,0.097
0.26,-58.64,0.106
0.27,-58.55,0.118
0.28,-58.47,0.127
0.29,-58.38,0.132
0.30,-58.29,0.144
0.31,-58.20,0.150
0.32,-58.11,0.152
0.33,-58.02,0.162
0.34,-57.93,0.164
0.35,-57.83,0.168
0.36,-57.74,0.171
0.37,-57.65,0.177
0.38,-57.56,0.178
0.39,-57.46,0.181
0.40,-57.37,0.186
0.41,-57.27,0.187
0.42,-57.18,0.188
0.43,-57.08,0.190
0.44,-56.99,0.191
0.45,-56.89,0.193
0.46,-56.80,0.194
0.47,-56.70,0.195
0.48,-56.60,0.196
0.49,-56.51,0.197
0.50,-56.41,0.197
0.51,-56.32,0.198
0.52,-56.22,0.199
0.53,-56.12,0.199
0.54,-56.03,0.200
0.55,-55.93,0.201
0.56,-55.83,0.201
0.57,-55.73,0.202
0.58,-55.64,0.203
0.59,-55.54,0.203
0.60,-55.44,0.203
0.61,-55.34,0.203
0.62,-55.24,0.204
0.63,-55.15,0.204
0.64,-55.05,0.205
0.65,-54.95,0.205
0.66,-54.85,0.205
0.67,-54.75,0.205
0.68,-54.66,0.206
0.69,-54.56,0.206
0.70,-54.46,0.207
0.71,-54.36,0.207
0.72,-54.26,0.207
0.73,-54.16,0.207
0.74,-54.07,0.207
0.75,-53.97,0.208
0.76,-53.87,0.208
0.77,-53.77,0.208
0.78,-53.67,0.208
0.79,-53.57,0.208
0.80,-53.48,0.209
0.81,-53.38,0.209
0.82,-53.28,0.209
0.83,-53.18,0.209
0.84,-53.08,0.209
0.85,-52.98,0.209
0.86,-52.88,0.210
0.87,-52.78,0.210
0.88,-52.68,0.210
0.89,-52.58,0.210
0.90,-52.49,0.210
0.91,-52.39,0.210
0.92,-52.29,0.210
0.93,-52.19,0.210
0.94,-52.09,0.210
0.95,-51.99,0.210
0.96,-51.89,0.211
0.97,-51.79,0.211
0.98,-51.69,0.211
0.99,-51.59,0.211
1.00,-51.50,0.211
1.01,-51.40,0.211
1.02,-51.30,0.211
1.03,-51.20,0.211
1.04,-51.10,0.211
1.05,-51.00,0.211
1.06,-50.90,0.211
1.07,-50.80,0.211
1.08,-50.71,0.211
1.09,-50.61,0.211
1.10,-50.51,0.211
1.11,-50.41,0.211
1.12,-50.31,0.211
1.13,-50.21,0.211
1.14,-50.11,0.211
1.15,-50.01,0.211
1.16,-49.91,0.211
1.17,-49.81,0.211
1.18,-49.71,0.211
1.19,-49.61,0.211
1.20,-49.51,0.211
1.21,-49.41,0.211
1.22,-49.31,0.211
1.23,-49.21,0.211
1.24,-49.11,0.211
1.25,-49.01,0.211
1.26,-48.91,0.211
1.27,-48.81,0.211
1.28,-48.71,0.211
1.29,-48.61,0.211
1.30,-48.51,0.211
1.31,-48.41,0.211
1.32,-48.32,0.211
1.33,-48.21,0.211
1.34,-48.11,0.211
1.35,-48.01,0.211
1.36,-47.91,0.211
1.37,-47.81,0.211
1.38,-47.71,0.211
1.39,-47.61,0.211
1.40,-47.52,0.211
1.41,-47.41,0.211
1.42,-47.31,0.211
1.43,-47.21,0.211
1.44,-47.11,0.211
1.45,-47.01,0.211
1.46,-46.91,0.211
1.47,-46.81,0.211
1.48,-46.71,0.211
1.49,-46.62,0.211
1.50,-46.52,0.211
1.51,-46.41,0.211
1.52,-46.31,0.211
1.53,-46.22,0.211
1.54,-46.12,0.211
1.55,-46.01,0.211
1.56,-45.91,0.211
1.57,-45.81,0.211
1.58,-45.71,0.211
1.59,-45.61,0.211
1.60,-45.51,0.211
1.61,-45.41,0.211
1.62,-45.31,0.211
1.63,-45.21,0.211
1.64,-45.11,0.211
1.65,-45.01,0.211
1.66,-44.91,0.211
1.67,-44.81,0.211
1.68,-44.71,0.211
1.69,-44.61,0.211
1.70,-44.51,0.211
1.71,-44.41,0.211
1.72,-44.31,0.211
1.73,-44.21,0.211
1.74,-44.11,0.211
1.75,-44.01,0.211
1.76,-43.91,0.211
1.77,-43.81,0.211
1.78,-43.71,0.211
1.79,-43.61,0.211
1.80,-43.51,0.211
1.81,-43.41,0.211
1.82,-43.31,0.211
1.83,-43.21,0.211
1.84,-43.11,0.211
1.85,-43.01,0.211
1.86,-42.91,0.211
1.87,-42.81,0.211
1.88,-42.71,0.211
1.89,-42.61,0.211
1.90,-42.51,0.211
1.91,-42.41,0.211
1.92,-42.31,0.211
1.93,-42.21,0.211
1.94,-42.11,0.211
1.95,-42.01,0.211
1.96,-41.91,0.211
1.97,-41.81,0.211
1.98,-41.71,0.211
1.99,-41.61,0.211
2.00,-41.51,0.211
2.01,-41.41,0.211
2.02,-41.31,0.211
2.03,-41.21,0.211
2.04,-41.11,0.211
2.05,-41.01,0.211
2.06,-40.91,0.211
2.07,-40.81,0.211
2.08,-40.71,0.211
2.09,-40.61,0.211
2.10,-40.51,0.211
2.11,-40.41,0.211
2.12,-40.31,0.211
2.13,-40.21,0.210
2.14,-40.11,0.210
2.15,-40.01,0.210
2.16,-39.91,0.210
2.17,-39.81,0.211
2.18,-39.71,0.211
2.19,-39.61,0.211
2.20,-39.51,0.211
2.21,-39.41,0.210
2.22,-39.31,0.210
2.23,-39.21,0.210
2.24,-39.11,0.210
2.25,-39.01,0.210
2.26,-38.91,0.210
2.27,-38.81,0.210
2.28,-38.71,0.210
2.29,-38.61,0.210
2.30,-38.51,0.210
2.31,-38.41,0.210
2.32,-38.31,0.210
2.33,-38.21,0.210
2.34,-38.10,0.210
2.35,-38.00,0.210
2.36,-37.91,0.210
2.37,-37.81,0.210
2.38,-37.71,0.210
2.39,-37.60,0.210
2.40,-37.50,0.210
2.41,-37.40,0.210
2.42,-37.30,0.210
2.43,-37.21,0.210
2.44,-37.10,0.210
2.45,-37.00,0.210
2.46,-36.90,0.210
2.47,-36.80,0.210
2.48,-36.70,0.210
2.49,-36.60,0.210
2.50,-36.50,0.210
2.51,-36.40,0.210
2.52,-36.30,0.210
2.53,-36.20,0.210
2.54,-36.10,0.210
2.55,-36.00,0.210
2.56,-35.90,0.210
2.57,-35.80,0.210
2.58,-35.70,0.210
2.59,-35.60,0.210
2.60,-35.50,0.210
2.61,-35.40,0.210
2.62,-35.30,0.210
2.63,-35.20,0.210
2.64,-35.10,0.210
2.65,-35.00,0.210
2.66,-34.90,0.210
2.67,-34.80,0.210
2.68,-34.70,0.210
2.69,-34.60,0.210
2.70,-34.50,0.210
2.71,-34.40,0.210
2.72,-34.30,0.210
2.73,-34.20,0.210
2.74,-34.10,0.210
2.75,-34.00,0.210
2.76,-33.90,0.210
2.77,-33.80,0.210
2.78,-33.70,0.210
2.79,-33.60,0.210
2.80,-33.50,0.210
2.81,-33.40,0.210
2.82,-33.30,0.210
2.83,-33.20,0.210
2.84,-33.10,0.210
2.85,-33.00,0.210
2.86,-32.90,0.210
2.87,-32.80,0.210
2.88,-32.70,0.210
2.89,-32.60,0.210
2.90,-32.50,0.210
2.91,-32.40,0.210
2.92,-32.30,0.210
2.93,-32.19,0.210
2.94,-32.09,0.210
2.95,-32.00,0.210
2.96,-31.90,0.210
2.97,-31.80,0.210
2.98,-31.70,0.210
2.99,-31.59,0.210
3.00,-31.49,0.209
3.01,-31.39,0.210
3.02,-31.29,0.210
3.03,-31.19,0.209
3.04,-31.09,0.210
3.05,-30.99,0.210
3.06,-30.89,0.209
3.07,-30.79,0.210
3.08,-30.69,0.210
3.09,-30.59,0.210
3.10,-30.49,0.209
3.11,-30.39,0.209
3.12,-30.29,0.209
3.13,-30.19,0.209
3.14,-30.09,0.209
3.15,-29.99,0.209
3.16,-29.89,0.210
3.17,-29.79,0.210
3.18,-29.69,0.209
3.19,-29.59,0.209
3.20,-29.49,0.209
3.21,-29.39,0.209
3.22,-29.29,0.209
3.23,-29.19,0.209
3.24,-29.09,0.209
3.25,-28.99,0.209
3.26,-28.89,0.209
3.27,-28.79,0.209
3.28,-28.69,0.210
3.29,-28.59,0.210
3.30,-28.49,0.210
3.31,-28.39,0.210
3.32,-28.29,0.210
3.33,-28.19,0.209
3.34,-28.09,0.209
3.35,-27.99,0.209
3.36,-27.89,0.209
3.37,-27.79,0.209
3.38,-27.69,0.209
3.39,-27.59,0.209
3.40,-27.49,0.209
3.41,-27.39,0.209
3.42,-27.28,0.209
3.43,-27.18,0.209
3.44,-27.08,0.210
3.45,-26.98,0.210
3.46,-26.88,0.209
3.47,-26.78,0.210
3.48,-26.68,0.210
3.49,-26.58,0.210
3.50,-26.48,0.210
3.51,-26.38,0.210
3.52,-26.28,0.210
3.53,-26.18,0.210
3.54,-26.08,0.210
3.55,-25.98,0.210
3.56,-25.88,0.210
3.57,-25.78,0.210
3.58,-25.68,0.210
3.59,-25.58,0.210
3.60,-25.48,0.210
3.61,-25.38,0.210
3.62,-25.28,0.210
3.63,-25.18,0.210
3.64,-25.08,0.210
3.65,-24.98,0.210
3.66,-24.88,0.210
3.67,-24.78,0.210
3.68,-24.68,0.210
3.69,-24.58,0.210
3.70,-24.48,0.210
3.71,-24.38,0.210
3.72,-24.28,0.210
3.73,-24.18,0.210
3.74,-24.08,0.210
3.75,-23.98,0.210
3.76,-23.88,0.210
3.77,-23.78,0.210
3.78,-23.68,0.210
3.79,-23.58,0.210
3.80,-23.48,0.210
3.81,-23.38,0.210
3.82,-23.28,0.210
3.83,-23.18,0.210
3.84,-23.08,0.210
3.85,-22.98,0.210
3.86,-22.88,0.210
3.87,-22.78,0.209
3.88,-22.68,0.210
3.89,-22.58,0.210
3.90,-22.48,0.210
3.91,-22.38,0.209
3.92,-22.28,0.209
3.93,-22.18,0.209
3.94,-22.08,0.209
3.95,-21.98,0.209
3.96,-21.88,0.210
3.97,-21.78,0.210
3.98,-21.68,0.210
3.99,-21.58,0.210
4.00,-21.48,0.210
4.01,-21.38,0.210
4.02,-21.28,0.210
4.03,-21.18,0.210
4.04,-21.08,0.210
4.05,-20.98,0.210
4.06,-20.88,0.210
4.07,-20.78,0.210
4.08,-20.67,0.210
4.09,-20.57,0.210
4.10,-20.48,0.210
4.11,-20.38,0.210
4.12,-20.27,0.210
4.13,-20.17,0.210
4.14,-20.07,0.210
4.15,-19.97,0.210
4.16,-19.87,0.210
4.17,-19.77,0.210
4.18,-19.68,0.210
4.19,-19.57,0.210
4.20,-19.47,0.210
4.21,-19.37,0.210
4.22,-19.27,0.210
4.23,-19.17,0.210
4.24,-19.07,0.210
4.25,-18.97,0.210
4.26,-18.87,0.210
4.27,-18.77,0.210
4.28,-18.67,0.210
4.29,-18.57,0.210
4.30,-18.47,0.210
4.31,-18.37,0.210
4.32,-18.27,0.210
4.33,-18.17,0.210
4.34,-18.07,0.211
4.35,-17.97,0.211
4.36,-17.87,0.210
4.37,-17.77,0.211
4.38,-17.67,0.211
4.39,-17.57,0.211
4.40,-17.47,0.211
4.41,-17.37,0.211
4.42,-17.27,0.211
4.43,-17.17,0.211
4.44,-17.07,0.211
4.45,-16.97,0.211
4.46,-16.87,0.211
4.47,-16.77,0.211
4.48,-16.67,0.211
4.49,-16.57,0.211
4.50,-16.47,0.211
4.51,-16.37,0.211
4.52,-16.27,0.211
4.53,-16.17,0.211
4.54,-16.07,0.211
4.55,-15.97,0.211
4.56,-15.87,0.211
4.57,-15.77,0.211
4.58,-15.67,0.211
4.59,-15.57,0.211
4.60,-15.47,0.211
4.61,-15.37,0.211
4.62,-15.27,0.211
4.63,-15.17,0.211
4.64,-15.07,0.211
4.65,-14.97,0.211
4.66,-14.87,0.211
4.67,-14.77,0.211
4.68,-14.67,0.211
4.69,-14.57,0.211
4.70,-14.47,0.211
4.71,-14.37,0.211
4.72,-14.27,0.211
4.73,-14.17,0.211
4.74,-14.07,0.211
4.75,-13.97,0.211
4.76,-13.87,0.211
4.77,-13.77,0.211
4.78,-13.67,0.211
4.79,-13.57,0.211
4.80,-13.47,0.211
4.81,-13.37,0.211
4.82,-13.27,0.211
4.83,-13.17,0.211
4.84,-13.07,0.211
4.85,-12.97,0.211
4.86,-12.87,0.211
4.87,-12.77,0.211
4.88,-12.67,0.211
4.89,-12.57,0.211
4.90,-12.47,0.211
4.91,-12.37,0.211
4.92,-12.27,0.211
4.93,-12.16,0.211
4.94,-12.07,0.211
4.95,-11.97,0.212
4.96,-11.86,0.212
4.97,-11.76,0.212
4.98,-11.66,0.212
4.99,-11.56,0.212
5.00,-11.46,0.212
5.01,-11.36,0.212
5.02,-11.26,0.212
5.03,-11.16,0.212
5.04,-11.06,0.212
5.05,-10.96,0.212
5.06,-10.86,0.212
5.07,-10.76,0.212
5.08,-10.66,0.212
5.09,-10.56,0.212
5.10,-10.46,0.212
5.11,-10.36,0.212
5.12,-10.26,0.212
5.13,-10.16,0.212
5.14,-10.06,0.212
5.15,-9.96,0.212
5.16,-9.86,0.212
5.17,-9.76,0.212
5.18,-9.66,0.212
5.19,-9.56,0.212
5.20,-9.46,0.212
5.21,-9.36,0.212
5.22,-9.26,0.212
5.23,-9.16,0.212
5.24,-9.06,0.212
5.25,-8.96,0.212
5.26,-8.86,0.212
5.27,-8.76,0.212
5.28,-8.66,0.212
5.29,-8.56,0.213
5.30,-8.46,0.212
5.31,-8.36,0.213
5.32,-8.26,0.213
5.33,-8.16,0.213
5.34,-8.06,0.213
5.35,-7.96,0.213
5.36,-7.86,0.213
5.37,-7.76,0.213
5.38,-7.66,0.213
5.39,-7.56,0.213
5.40,-7.46,0.213
5.41,-7.36,0.213
5.42,-7.26,0.213
5.43,-7.16,0.213
5.44,-7.06,0.213
5.45,-6.96,0.213
5.46,-6.86,0.213
5.47,-6.76,0.213
5.48,-6.66,0.213
5.49,-6.56,0.213
5.50,-6.46,0.213
5.51,-6.36,0.213
5.52,-6.26,0.213
5.53,-6.16,0.213
5.54,-6.06,0.213
5.55,-5.96,0.213
5.56,-5.86,0.213
5.57,-5.76,0.213
5.58,-5.66,0.213
5.59,-5.56,0.213
5.60,-5.46,0.213
5.61,-5.36,0.213
5.62,-5.26,0.213
5.63,-5.16,0.213
5.64,-5.06,0.213
5.65,-4.96,0.213
5.66,-4.86,0.213
5.67,-4.76,0.213
5.68,-4.66,0.213
5.69,-4.56,0.213
5.70,-4.46,0.213
5.71,-4.36,0.214
5.72,-4.26,0.214
5.73,-4.16,0.214
5.74,-4.06,0.214
5.75,-3.96,0.214
5.76,-3.86,0.214
5.77,-3.75,0.214
5.78,-3.65,0.214
5.79,-3.56,0.214
5.80,-3.46,0.214
5.81,-3.35,0.214
5.82,-3.25,0.214
5.83,-3.15,0.214
5.84,-3.05,0.214
5.85,-2.95,0.214
5.86,-2.85,0.214
5.87,-2.75,0.214
5.88,-2.65,0.214
5.89,-2.55,0.214
5.90,-2.45,0.215
5.91,-2.35,0.215
5.92,-2.25,0.215
5.93,-2.15,0.215
5.94,-2.05,0.215
5.95,-1.95,0.215
5.96,-1.85,0.215
5.97,-1.75,0.215
5.98,-1.65,0.215
5.99,-1.55,0.215
6.00,-1.45,0.215
6.01,-1.35,0.215
6.02,-1.25,0.216
6.03,-1.15,0.216
6.04,-1.05,0.216
6.05,-0.95,0.216
6.06,-0.85,0.216
6.07,-0.75,0.216
6.08,-0.65,0.216
6.09,-0.55,0.216
6.10,-0.45,0.216
6.11,-0.35,0.216
6.12,-0.25,0.216
6.13,-0.15,0.216
6.14,-0.05,0.216
6.15,0.05,0.216
6.16,0.15,0.216
6.17,0.25,0.216
6.18,0.35,0.216
6.19,0.45,0.216
6.20,0.55,0.216
6.21,0.65,0.216
6.22,0.75,0.217
6.23,0.85,0.217
6.24,0.95,0.217
6.25,1.05,0.217
6.26,1.15,0.217
6.27,1.25,0.217
6.28,1.35,0.217
6.29,1.45,0.217
6.30,1.55,0.217
6.31,1.65,0.217
6.32,1.75,0.217
6.33,1.85,0.217
6.34,1.95,0.217
6.35,2.05,0.217
6.36,2.15,0.217
6.37,2.25,0.217
6.38,2.35,0.218
6.39,2.45,0.218
6.40,2.55,0.218
6.41,2.65,0.218
6.42,2.75,0.218
6.43,2.85,0.218
6.44,2.95,0.218
6.45,3.05,0.218
6.46,3.15,0.218
6.47,3.25,0.218
6.48,3.36,0.218
6.49,3.46,0.218
6.50,3.55,0.218
6.51,3.66,0.218
6.52,3.76,0.219
6.53,3.86,0.219
6.54,3.96,0.219
6.55,4.06,0.219
6.56,4.16,0.219
6.57,4.26,0.219
6.58,4.36,0.219
6.59,4.46,0.219
6.60,4.56,0.219
6.61,4.66,0.219
6.62,4.76,0.219
6.63,4.86,0.219
6.64,4.96,0.219
6.65,5.06,0.219
6.66,5.16,0.219
6.67,5.26,0.219
6.68,5.36,0.219
6.69,5.46,0.220
6.70,5.56,0.220
6.71,5.66,0.220
6.72,5.76,0.220
6.73,5.86,0.220
6.74,5.96,0.220
6.75,6.06,0.220
6.76,6.16,0.220
6.77,6.26,0.220
6.78,6.36,0.220
6.79,6.46,0.220
6.80,6.56,0.220
6.81,6.66,0.221
6.82,6.76,0.221
6.83,6.86,0.221
6.84,6.96,0.221
6.85,7.06,0.221
6.86,7.16,0.221
6.87,7.26,0.221
6.88,7.36,0.221
6.89,7.46,0.221
6.90,7.56,0.221
6.91,7.66,0.221
6.92,7.76,0.222
6.93,7.86,0.222
6.94,7.96,0.222
6.95,8.06,0.222
6.96,8.16,0.222
6.97,8.26,0.222
6.98,8.36,0.222
6.99,8.46,0.222
7.00,8.56,0.222
7.01,8.66,0.222
7.02,8.76,0.223
7.03,8.86,0.223
7.04,8.96,0.223
7.05,9.06,0.223
7.06,9.16,0.223
7.07,9.26,0.223
7.08,9.36,0.223
7.09,9.46,0.223
7.10,9.56,0.223
7.11,9.66,0.223
7.12,9.76,0.224
7.13,9.86,0.224
7.14,9.96,0.224
7.15,10.06,0.224
7.16,10.16,0.224
7.17,10.26,0.224
7.18,10.36,0.224
7.19,10.46,0.224
7.20,10.56,0.224
7.21,10.66,0.224
7.22,10.76,0.225
7.23,10.86,0.225
7.24,10.96,0.225
7.25,11.06,0.225
7.26,11.16,0.225
7.27,11.26,0.225
7.28,11.36,0.225
7.29,11.46,0.225
7.30,11.56,0.226
7.31,11.66,0.226
7.32,11.76,0.226
7.33,11.86,0.226
7.34,11.96,0.226
7.35,12.06,0.226
7.36,12.17,0.226
7.37,12.26,0.226
7.38,12.37,0.227
7.39,12.46,0.227
7.40,12.56,0.227
7.41,12.67,0.227
7.42,12.76,0.227
7.43,12.87,0.227
7.44,12.97,0.227
7.45,13.07,0.227
7.46,13.17,0.228
7.47,13.27,0.228
7.48,13.37,0.228
7.49,13.46,0.228
7.50,13.57,0.228
7.51,13.67,0.228
7.52,13.77,0.228
7.53,13.87,0.228
7.54,13.97,0.229
7.55,14.07,0.229
7.56,14.17,0.229
7.57,14.27,0.229
7.58,14.37,0.229
7.59,14.47,0.230
7.60,14.57,0.230
7.61,14.67,0.230
7.62,14.77,0.230
7.63,14.87,0.230
7.64,14.97,0.230
7.65,15.07,0.230
7.66,15.17,0.231
7.67,15.27,0.231
7.68,15.37,0.231
7.69,15.47,0.231
7.70,15.57,0.231
7.71,15.67,0.231
7.72,15.77,0.231
7.73,15.87,0.232
7.74,15.97,0.232
7.75,16.07,0.232
7.76,16.17,0.232
7.77,16.27,0.232
7.78,16.37,0.233
7.79,16.47,0.233
7.80,16.57,0.233
7.81,16.67,0.233
7.82,16.77,0.233
7.83,16.87,0.234
7.84,16.97,0.234
7.85,17.07,0.234
7.86,17.17,0.234
7.87,17.27,0.234
7.88,17.37,0.234
7.89,17.47,0.234
7.90,17.57,0.235
7.91,17.67,0.235
7.92,17.77,0.235
7.93,17.87,0.235
7.94,17.97,0.235
7.95,18.07,0.236
7.96,18.17,0.236
7.97,18.27,0.236
7.98,18.37,0.236
7.99,18.47,0.236
8.00,18.57,0.236
8.01,18.67,0.236
8.02,18.77,0.237
8.03,18.87,0.237
8.04,18.97,0.237
8.05,19.07,0.237
8.06,19.17,0.237
8.07,19.27,0.238
8.08,19.37,0.238
8.09,19.47,0.238
8.10,19.57,0.238
8.11,19.67,0.238
8.12,19.77,0.238
8.13,19.87,0.239
8.14,19.97,0.239
8.15,20.07,0.239
8.16,20.17,0.239
8.17,20.27,0.239
8.18,20.37,0.240
8.19,20.47,0.240
8.20,20.57,0.240
8.21,20.67,0.240
8.22,20.77,0.240
8.23,20.87,0.241
8.24,20.97,0.241
8.25,21.07,0.241
8.26,21.17,0.242
8.27,21.27,0.242
8.28,21.37,0.242
8.29,21.47,0.242
8.30,21.57,0.243
8.31,21.67,0.243
8.32,21.77,0.243
8.33,21.87,0.244
8.34,21.97,0.244
8.35,22.07,0.244
8.36,22.17,0.244
8.37,22.27,0.245
8.38,22.37,0.245
8.39,22.47,0.245
8.40,22.57,0.245
8.41,22.67,0.245
8.42,22.77,0.246
8.43,22.87,0.246
8.44,22.97,0.246
8.45,23.07,0.247
8.46,23.17,0.247
8.47,23.27,0.247
8.48,23.37,0.247
8.49,23.47,0.248
8.50,23.58,0.248
8.51,23.67,0.248
8.52,23.77,0.249
8.53,23.87,0.249
8.54,23.97,0.249
8.55,24.08,0.249
8.56,24.18,0.250
8.57,24.28,0.250
8.58,24.38,0.250
8.59,24.48,0.251
8.60,24.58,0.251
8.61,24.68,0.251
8.62,24.78,0.252
8.63,24.88,0.252
8.64,24.98,0.252
8.65,25.08,0.252
8.66,25.18,0.253
8.67,25.28,0.254
8.68,25.38,0.254
8.69,25.48,0.254
8.70,25.58,0.255
8.71,25.68,0.255
8.72,25.78,0.255
8.73,25.88,0.255
8.74,25.97,0.256
8.75,26.08,0.256
8.76,26.18,0.257
8.77,26.28,0.257
8.78,26.38,0.258
8.79,26.48,0.258
8.80,26.58,0.258
8.81,26.68,0.259
8.82,26.78,0.259
8.83,26.88,0.259
8.84,26.98,0.260
8.85,27.08,0.260
8.86,27.18,0.261
8.87,27.28,0.261
8.88,27.38,0.261
8.89,27.48,0.262
8.90,27.58,0.262
8.91,27.68,0.262
8.92,27.78,0.263
8.93,27.88,0.263
8.94,27.98,0.264
8.95,28.08,0.264
8.96,28.18,0.265
8.97,28.28,0.265
8.98,28.38,0.266
8.99,28.48,0.266
9.00,28.58,0.267
9.01,28.68,0.268
9.02,28.78,0.268
9.03,28.88,0.269
9.04,28.98,0.269
9.05,29.08,0.269
9.06,29.18,0.270
9.07,29.28,0.270
9.08,29.38,0.271
9.09,29.48,0.271
9.10,29.58,0.272
9.11,29.68,0.272
9.12,29.78,0.273
9.13,29.88,0.273
9.14,29.98,0.274
9.15,30.08,0.274
9.16,30.18,0.275
9.17,30.28,0.275
9.18,30.38,0.276
9.19,30.48,0.276
9.20,30.58,0.277
9.21,30.68,0.278
9.22,30.78,0.278
9.23,30.88,0.279
9.24,30.98,0.280
9.25,31.08,0.280
9.26,31.18,0.281
9.27,31.28,0.281
9.28,31.38,0.282
9.29,31.48,0.283
9.30,31.58,0.283
9.31,31.68,0.285
9.32,31.78,0.285
9.33,31.88,0.286
9.34,31.98,0.287
9.35,32.08,0.287
9.36,32.18,0.288
9.37,32.28,0.289
9.38,32.38,0.289
9.39,32.48,0.290
9.40,32.58,0.291
9.41,32.68,0.291
9.42,32.78,0.292
9.43,32.88,0.293
9.44,32.98,0.293
9.45,33.08,0.295
9.46,33.18,0.296
9.47,33.28,0.296
9.48,33.38,0.297
9.49,33.48,0.298
9.50,33.58,0.298
9.51,33.68,0.299
9.52,33.78,0.300
9.53,33.88,0.300
9.54,33.98,0.301
9.55,34.08,0.302
9.56,34.18,0.303
9.57,34.28,0.304
9.58,34.38,0.304
9.59,34.48,0.305
9.60,34.58,0.306
9.61,34.68,0.308
9.62,34.78,0.308
9.63,34.88,0.309
9.64,34.98,0.310
9.65,35.08,0.311
9.66,35.18,0.312
9.67,35.28,0.313
9.68,35.38,0.314
9.69,35.48,0.315
9.70,35.58,0.315
9.71,35.68,0.316
9.72,35.78,0.316
9.73,35.88,0.316
9.74,35.98,0.317
9.75,36.08,0.318
9.76,36.18,0.319
9.77,36.28,0.320
9.78,36.38,0.321
9.79,36.48,0.322
9.80,36.58,0.322
9.81,36.68,0.323
9.82,36.78,0.323
9.83,36.88,0.323
9.84,36.98,0.324
9.85,37.08,0.324
9.86,37.18,0.325
9.87,37.28,0.326
9.88,37.38,0.326
9.89,37.48,0.327
9.90,37.58,0.327
9.91,37.68,0.328
9.92,37.78,0.328
9.93,37.88,0.329
9.94,37.98,0.329
9.95,38.08,0.330
9.96,38.18,0.330
9.97,38.28,0.330
9.98,38.38,0.331
9.99,38.48,0.331
10.00,38.58,0.332
10.01,38.68,0.332
10.02,38.78,0.332
10.03,38.88,0.333
10.04,38.98,0.333
10.05,39.08,0.333
10.06,39.18,0.334
10.07,39.28,0.334
10.08,39.38,0.334
10.09,39.48,0.335
10.10,39.58,0.335
10.11,39.68,0.335
10.12,39.78,0.336
10.13,39.88,0.336
10.14,39.98,0.336
10.15,40.08,0.336
10.16,40.18,0.337
10.17,40.28,0.337
10.18,40.38,0.337
10.19,40.48,0.337
10.20,40.58,0.338
10.21,40.68,0.338
10.22,40.78,0.338
10.23,40.88,0.338
10.24,40.98,0.338
10.25,41.08,0.339
10.26,41.18,0.339
10.27,41.28,0.339
10.28,41.38,0.339
10.29,41.48,0.339
10.30,41.58,0.339
10.31,41.68,0.339
10.32,41.78,0.339
10.33,41.88,0.339
10.34,41.98,0.339
10.35,42.08,0.339
10.36,42.18,0.339
10.37,42.28,0.340
10.38,42.38,0.340
10.39,42.48,0.340
10.40,42.58,0.340
10.41,42.68,0.340
10.42,42.78,0.340
10.43,42.88,0.340
10.44,42.98,0.340
10.45,43.08,0.339
10.46,43.18,0.339
10.47,43.28,0.339
10.48,43.38,0.339
10.49,43.48,0.339
10.50,43.58,0.339
10.51,43.68,0.339
10.52,43.78,0.339
10.53,43.89,0.339
10.54,43.98,0.339
10.55,44.08,0.339
10.56,44.18,0.339
10.57,44.29,0.339
10.58,44.39,0.338
10.59,44.49,0.338
10.60,44.59,0.338
10.61,44.69,0.338
10.62,44.79,0.338
10.63,44.89,0.338
10.64,44.99,0.337
10.65,45.09,0.337
10.66,45.19,0.337
10.67,45.29,0.337
10.68,45.39,0.337
10.69,45.49,0.337
10.70,45.59,0.337
10.71,45.69,0.336
10.72,45.79,0.336
10.73,45.89,0.336
10.74,45.99,0.336
10.75,46.09,0.335
10.76,46.19,0.335
10.77,46.29,0.335
10.78,46.39,0.335
10.79,46.49,0.335
10.80,46.59,0.335
10.81,46.69,0.334
10.82,46.79,0.334
10.83,46.89,0.333
10.84,46.99,0.333
10.85,47.09,0.333
10.86,47.19,0.333
10.87,47.29,0.333
10.88,47.39,0.333
10.89,47.49,0.332
10.90,47.59,0.332
10.91,47.69,0.332
10.92,47.79,0.332
10.93,47.89,0.332
10.94,47.99,0.332
10.95,48.09,0.331
10.96,48.19,0.331
10.97,48.29,0.331
10.98,48.39,0.331
10.99,48.49,0.331
11.00,48.59,0.331
11.01,48.69,0.330
11.02,48.79,0.330
11.03,48.89,0.330
11.04,48.99,0.330
11.05,49.09,0.330
11.06,49.19,0.330
11.07,49.29,0.329
11.08,49.39,0.329
11.09,49.49,0.329
11.10,49.59,0.329
11.11,49.70,0.329
11.12,49.79,0.329
11.13,49.90,0.329
11.14,50.00,0.329
11.15,50.10,0.329
11.16,50.20,0.328
11.17,50.30,0.328
11.18,50.40,0.328
11.19,50.50,0.328
11.20,50.60,0.328
11.21,50.70,0.328
11.22,50.80,0.328
11.23,50.90,0.328
11.24,51.00,0.327
11.25,51.10,0.327
11.26,51.20,0.327
11.27,51.30,0.327
11.28,51.40,0.327
11.29,51.50,0.327
11.30,51.60,0.327
11.31,51.70,0.327
11.32,51.80,0.327
11.33,51.90,0.327
11.34,52.00,0.327
11.35,52.10,0.327
11.36,52.20,0.327
11.37,52.30,0.326
11.38,52.40,0.326
11.39,52.50,0.326
11.40,52.60,0.326
11.41,52.70,0.326
11.42,52.80,0.326
11.43,52.90,0.326
11.44,53.00,0.326
11.45,53.10,0.326
11.46,53.20,0.326
11.47,53.30,0.326
11.48,53.40,0.326
11.49,53.50,0.326
11.50,53.60,0.326
11.51,53.70,0.326
11.52,53.80,0.326
11.53,53.90,0.326
11.54,54.00,0.326
11.55,54.10,0.326
11.56,54.20,0.326
11.57,54.30,0.326
11.58,54.40,0.326
11.59,54.50,0.326
11.60,54.60,0.326
11.61,54.70,0.326
11.62,54.80,0.326
11.63,54.90,0.326
11.64,55.00,0.326
11.65,55.10,0.326
11.66,55.20,0.326
11.67,55.30,0.326
11.68,55.40,0.326
11.69,55.50,0.326
11.70,55.60,0.326
11.71,55.70,0.326
11.72,55.80,0.326
11.73,55.90,0.326
11.74,56.00,0.326
11.75,56.10,0.326
11.76,56.20,0.326
11.77,56.30,0.326
11.78,56.40,0.326
11.79,56.50,0.326
11.80,56.60,0.326
11.81,56.70,0.326
11.82,56.80,0.326
11.83,56.90,0.326
11.84,57.00,0.326
11.85,57.11,0.326
11.86,57.20,0.326
11.87,57.30,0.326
11.88,57.40,0.326
11.89,57.50,0.326
11.90,57.60,0.326
11.91,57.71,0.326
11.92,57.80,0.326
11.93,57.91,0.326
11.94,58.01,0.326
11.95,58.11,0.326
11.96,58.21,0.326
11.97,58.31,0.326
11.98,58.41,0.326
11.99,58.51,0.326
12.00,58.61,0.326
12.01,58.71,0.326
12.02,58.81,0.327
12.03,58.91,0.327
12.04,59.01,0.327
12.05,59.11,0.327
12.06,59.21,0.327
12.07,59.31,0.327
12.08,59.41,0.327
12.09,59.51,0.327
12.10,59.61,0.327
12.11,59.71,0.327
12.12,59.81,0.327
12.13,59.91,0.327
12.14,60.01,0.327
12.15,60.11,0.327
12.16,60.21,0.327
12.17,60.31,0.327
12.18,60.41,0.327
12.19,60.51,0.327
12.20,60.61,0.328
12.21,60.71,0.328
12.22,60.81,0.328
12.23,60.91,0.328
12.24,61.01,0.328
12.25,61.11,0.328
12.26,61.21,0.328
12.27,61.31,0.328
12.28,61.41,0.328
12.29,61.51,0.328
12.30,61.61,0.328
12.31,61.71,0.328
12.32,61.81,0.328
12.33,61.91,0.328
12.34,62.01,0.328
12.35,62.11,0.328
12.36,62.21,0.328
12.37,62.31,0.329
12.38,62.41,0.329
12.39,62.51,0.329
12.40,62.61,0.329
12.41,62.71,0.329
12.42,62.81,0.329
12.43,62.91,0.329
12.44,63.01,0.329
12.45,63.11,0.329
12.46,63.21,0.329
12.47,63.31,0.329
12.48,63.41,0.329
12.49,63.51,0.329
12.50,63.61,0.329
12.51,63.71,0.329
12.52,63.81,0.329
12.53,63.91,0.329
12.54,64.01,0.329
12.55,64.11,0.329
12.56,64.21,0.329
12.57,64.31,0.330
12.58,64.41,0.330
12.59,64.51,0.330
12.60,64.61,0.330
12.61,64.71,0.330
12.62,64.81,0.330
12.63,64.91,0.330
12.64,65.01,0.330
12.65,65.11,0.330
12.66,65.21,0.330
12.67,65.31,0.330
12.68,65.41,0.330
12.69,65.51,0.330
12.70,65.61,0.330
12.71,65.71,0.330
12.72,65.81,0.330
12.73,65.92,0.330
12.74,66.01,0.330
12.75,66.11,0.330
12.76,66.21,0.330
12.77,66.31,0.330
12.78,66.41,0.331
12.79,66.52,0.331
12.80,66.62,0.331
12.81,66.71,0.331
12.82,66.82,0.331
12.83,66.91,0.331
12.84,67.02,0.331
12.85,67.12,0.331
12.86,67.22,0.331
12.87,67.32,0.331
12.88,67.42,0.331
12.89,67.52,0.331
12.90,67.62,0.331
12.91,67.72,0.331
12.92,67.82,0.331
12.93,67.92,0.332
12.94,68.02,0.332
12.95,68.12,0.332
12.96,68.22,0.332
12.97,68.32,0.332
12.98,68.42,0.332
12.99,68.52,0.332
13.00,68.62,0.332
13.01,68.72,0.332
13.02,68.82,0.332
13.03,68.92,0.332
13.04,69.02,0.332
13.05,69.12,0.333
13.06,69.22,0.333
13.07,69.32,0.333
13.08,69.42,0.333
13.09,69.52,0.333
13.10,69.62,0.333
13.11,69.72,0.333
13.12,69.82,0.333
13.13,69.92,0.333
13.14,70.02,0.333
13.15,70.12,0.333
13.16,70.22,0.333
13.17,70.32,0.333
13.18,70.42,0.333
13.19,70.52,0.333
13.20,70.62,0.333
13.21,70.72,0.333
13.22,70.82,0.334
13.23,70.92,0.334
13.24,71.02,0.334
13.25,71.12,0.334
13.26,71.22,0.334
13.27,71.32,0.334
13.28,71.42,0.334
13.29,71.52,0.334
13.30,71.62,0.334
13.31,71.72,0.334
13.32,71.82,0.334
13.33,71.92,0.334
13.34,72.02,0.334
13.35,72.12,0.334
13.36,72.22,0.335
13.37,72.32,0.335
13.38,72.42,0.335
13.39,72.52,0.335
13.40,72.62,0.335
13.41,72.72,0.335
13.42,72.82,0.335
13.43,72.92,0.335
13.44,73.02,0.335
13.45,73.12,0.335
13.46,73.22,0.335
13.47,73.32,0.335
13.48,73.42,0.335
13.49,73.52,0.335
13.50,73.62,0.334
13.51,73.72,0.334
13.52,73.82,0.334
13.53,73.92,0.334
13.54,74.02,0.334
13.55,74.12,0.334
13.56,74.22,0.334
13.57,74.32,0.334
13.58,74.42,0.334
13.59,74.52,0.334
13.60,74.62,0.334
13.61,74.72,0.334
13.62,74.83,0.334
13.63,74.92,0.334
13.64,75.02,0.334
13.65,75.12,0.334
13.66,75.23,0.334
13.67,75.33,0.334
13.68,75.43,0.333
13.69,75.52,0.333
13.70,75.63,0.333
13.71,75.73,0.333
13.72,75.83,0.333
13.73,75.93,0.333
13.74,76.03,0.333
13.75,76.13,0.333
13.76,76.23,0.333
13.77,76.33,0.333
13.78,76.43,0.333
13.79,76.53,0.333
13.80,76.63,0.333
13.81,76.73,0.333
13.82,76.83,0.333
13.83,76.93,0.333
13.84,77.03,0.333
13.85,77.13,0.332
13.86,77.23,0.332
13.87,77.33,0.332
13.88,77.43,0.332
13.89,77.53,0.332
13.90,77.63,0.332
13.91,77.73,0.332
13.92,77.83,0.332
13.93,77.93,0.332
13.94,78.03,0.332
13.95,78.13,0.331
13.96,78.23,0.331
13.97,78.33,0.331
13.98,78.43,0.331
13.99,78.53,0.331
14.00,78.63,0.331
14.01,78.73,0.331
14.02,78.83,0.331
14.03,78.93,0.331
14.04,79.03,0.331
14.05,79.13,0.331
14.06,79.23,0.330
14.07,79.33,0.330
14.08,79.43,0.330
14.09,79.53,0.330
14.10,79.63,0.330
14.11,79.73,0.330
14.12,79.83,0.330
14.13,79.93,0.330
14.14,80.03,0.330
14.15,80.13,0.330
14.16,80.23,0.330
14.17,80.33,0.330
14.18,80.43,0.330
14.19,80.53,0.330
14.20,80.63,0.330
14.21,80.73,0.329
14.22,80.83,0.329
14.23,80.93,0.329
14.24,81.03,0.329
14.25,81.13,0.329
14.26,81.23,0.329
14.27,81.33,0.329
14.28,81.43,0.329
14.29,81.53,0.329
14.30,81.63,0.329
14.31,81.73,0.329
14.32,81.84,0.329
14.33,81.94,0.329
14.34,82.04,0.328
14.35,82.14,0.328
14.36,82.24,0.328
14.37,82.34,0.328
14.38,82.44,0.328
14.39,82.54,0.328
14.40,82.64,0.328
14.41,82.74,0.328
14.42,82.84,0.328
14.43,82.94,0.328
14.44,83.04,0.328
14.45,83.14,0.328
14.46,83.24,0.328
14.47,83.33,0.327
14.48,83.44,0.327
14.49,83.54,0.327
14.50,83.64,0.327
14.51,83.74,0.327
14.52,83.84,0.327
14.53,83.94,0.327
14.54,84.04,0.327
14.55,84.14,0.327
14.56,84.24,0.327
14.57,84.34,0.327
14.58,84.44,0.327
14.59,84.54,0.327
14.60,84.64,0.326
14.61,84.74,0.326
14.62,84.84,0.326
14.63,84.94,0.326
14.64,85.04,0.326
14.65,85.14,0.326
14.66,85.24,0.326
14.67,85.34,0.326
14.68,85.44,0.326
14.69,85.54,0.326
14.70,85.64,0.326
14.71,85.74,0.325
14.72,85.84,0.325
14.73,85.94,0.325
14.74,86.04,0.325
14.75,86.14,0.325
14.76,86.24,0.325
14.77,86.34,0.325
14.78,86.44,0.325
14.79,86.54,0.325
14.80,86.64,0.325
14.81,86.74,0.325
14.82,86.84,0.325
14.83,86.94,0.325
14.84,87.04,0.325
14.85,87.14,0.325
14.86,87.24,0.324
14.87,87.34,0.325
14.88,87.44,0.324
14.89,87.54,0.324
14.90,87.64,0.324
14.91,87.74,0.324
14.92,87.84,0.324
14.93,87.94,0.324
14.94,88.04,
14.95,88.14,
14.96,88.24,
14.97,88.34,
14.98,88.44,
14.99,,
14.99,,

[step]
Ramp 10.00 °C/min to -60.00 °C
Time,Temperature,Heat Flow (Normalized)
min,°C,W/g
16.99,90.13,-0.101
17.00,90.13,-0.101
17.02,90.13,-0.101
17.03,90.13,-0.101
17.04,90.12,-0.100
17.05,90.11,-0.096
17.06,90.09,-0.087
17.08,90.07,-0.076
17.09,90.04,-0.073
17.10,90.00,-0.073
17.11,89.95,-0.086
17.12,89.89,-0.123
17.13,89.83,-0.161
17.14,89.75,-0.194
17.16,89.67,-0.230
17.17,89.59,-0.267
17.18,89.51,-0.295
17.19,89.42,-0.320
17.20,89.32,-0.342
17.22,89.23,-0.362
17.23,89.13,-0.381
17.24,89.03,-0.391
17.25,88.93,-0.407
17.26,88.83,-0.415
17.27,88.73,-0.428
17.28,88.62,-0.438
17.30,88.52,-0.446
17.31,88.41,-0.451
17.32,88.30,-0.463
17.33,88.19,-0.467
17.34,88.08,-0.473
17.36,87.97,-0.475
17.37,87.86,-0.480
17.38,87.75,-0.484
17.39,87.64,-0.488
17.40,87.53,-0.489
17.41,87.41,-0.494
17.43,87.30,-0.494
17.44,87.19,-0.497
17.45,87.08,-0.498
17.46,86.96,-0.498
17.47,86.85,-0.499
17.48,86.73,-0.500
17.49,86.62,-0.502
17.51,86.50,-0.503
17.52,86.39,-0.503
17.53,86.28,-0.503
17.54,86.16,-0.504
17.55,86.05,-0.504
17.57,85.93,-0.504
17.58,85.82,-0.505
17.59,85.70,-0.505
17.60,85.59,-0.505
17.61,85.47,-0.505
17.62,85.36,-0.506
17.63,85.24,-0.506
17.65,85.13,-0.506
17.66,85.01,-0.507
17.67,84.90,-0.507
17.68,84.78,-0.507
17.69,84.67,-0.507
17.71,84.55,-0.508
17.72,84.43,-0.508
17.73,84.32,-0.508
17.74,84.20,-0.508
17.75,84.09,-0.508
17.76,83.97,-0.509
17.78,83.85,-0.509
17.79,83.74,-0.509
17.80,83.62,-0.509
17.81,83.51,-0.509
17.82,83.39,-0.509
17.83,83.28,-0.509
17.84,83.16,-0.509
17.86,83.04,-0.509
17.87,82.93,-0.509
17.88,82.81,-0.509
17.89,82.70,-0.509
17.90,82.58,-0.509
17.92,82.46,-0.509
17.93,82.35,-0.509
17.94,82.23,-0.509
17.95,82.11,-0.510
17.96,82.00,-0.510
17.97,81.88,-0.510
17.98,81.77,-0.509
18.00,81.65,-0.510
18.01,81.53,-0.509
18.02,81.42,-0.509
18.03,81.30,-0.509
18.04,81.19,-0.509
18.06,81.07,-0.509
18.07,80.95,-0.509
18.08,80.84,-0.509
18.09,80.72,-0.509
18.10,80.60,-0.509
18.11,80.49,-0.509
18.13,80.37,-0.508
18.14,80.25,-0.508
18.15,80.14,-0.508
18.16,80.02,-0.508
18.17,79.91,-0.508
18.18,79.79,-0.508
18.19,79.67,-0.508
18.21,79.56,-0.508
18.22,79.44,-0.508
18.23,79.32,-0.507
18.24,79.21,-0.507
18.25,79.09,-0.507
18.27,78.97,-0.507
18.28,78.86,-0.507
18.29,78.74,-0.507
18.30,78.63,-0.507
18.31,78.51,-0.506
18.32,78.39,-0.506
18.33,78.28,-0.506
18.35,78.16,-0.506
18.36,78.04,-0.506
18.37,77.93,-0.505
18.38,77.81,-0.505
18.39,77.69,-0.505
18.41,77.58,-0.505
18.42,77.46,-0.504
18.43,77.35,-0.504
18.44,77.23,-0.504
18.45,77.11,-0.504
18.46,77.00,-0.504
18.48,76.88,-0.504
18.49,76.76,-0.503
18.50,76.65,-0.503
18.51,76.53,-0.503
18.52,76.41,-0.503
18.53,76.30,-0.502
18.54,76.18,-0.502
18.56,76.06,-0.502
18.57,75.95,-0.502
18.58,75.83,-0.502
18.59,75.72,-0.501
18.60,75.60,-0.501
18.62,75.48,-0.501
18.63,75.37,-0.500
18.64,75.25,-0.500
18.65,75.13,-0.500
18.66,75.02,-0.500
18.67,74.90,-0.500
18.68,74.78,-0.499
18.70,74.67,-0.499
18.71,74.55,-0.499
18.72,74.43,-0.499
18.73,74.32,-0.499
18.74,74.20,-0.498
18.76,74.08,-0.498
18.77,73.97,-0.498
18.78,73.85,-0.498
18.79,73.73,-0.497
18.80,73.62,-0.497
18.81,73.50,-0.497
18.83,73.39,-0.496
18.84,73.27,-0.496
18.85,73.15,-0.496
18.86,73.04,-0.496
18.87,72.92,-0.495
18.88,72.80,-0.495
18.89,72.69,-0.495
18.91,72.57,-0.495
18.92,72.45,-0.495
18.93,72.34,-0.494
18.94,72.22,-0.494
18.95,72.10,-0.494
18.97,71.99,-0.494
18.98,71.87,-0.493
18.99,71.75,-0.493
19.00,71.64,-0.493
19.01,71.52,-0.493
19.02,71.40,-0.493
19.03,71.29,-0.493
19.05,71.17,-0.492
19.06,71.05,-0.492
19.07,70.94,-0.492
19.08,70.82,-0.491
19.09,70.70,-0.491
19.11,70.59,-0.491
19.12,70.47,-0.491
19.13,70.36,-0.491
19.14,70.24,-0.490
19.15,70.12,-0.490
19.16,70.01,-0.490
19.18,69.89,-0.490
19.19,69.77,-0.490
19.20,69.66,-0.489
19.21,69.54,-0.489
19.22,69.42,-0.489
19.23,69.31,-0.489
19.24,69.19,-0.489
19.26,69.07,-0.488
19.27,68.96,-0.488
19.28,68.84,-0.488
19.29,68.72,-0.488
19.30,68.61,-0.487
19.32,68.49,-0.487
19.33,68.37,-0.487
19.34,68.26,-0.487
19.35,68.14,-0.487
19.36,68.02,-0.487
19.37,67.91,-0.486
19.38,67.79,-0.486
19.40,67.68,-0.486
19.41,67.56,-0.485
19.42,67.44,-0.485
19.43,67.32,-0.485
19.44,67.21,-0.485
19.46,67.09,-0.485
19.47,66.98,-0.484
19.48,66.86,-0.484
19.49,66.74,-0.484
19.50,66.62,-0.484
19.51,66.51,-0.483
19.53,66.39,-0.483
19.54,66.28,-0.483
19.55,66.16,-0.483
19.56,66.04,-0.483
19.57,65.93,-0.482
19.58,65.81,-0.482
19.59,65.69,-0.482
19.61,65.58,-0.482
19.62,65.46,-0.481
19.63,65.34,-0.481
19.64,65.23,-0.481
19.65,65.11,-0.481
19.67,64.99,-0.481
19.68,64.88,-0.480
19.69,64.76,-0.480
19.70,64.64,-0.480
19.71,64.53,-0.480
19.72,64.41,-0.480
19.73,64.29,-0.479
19.75,64.18,-0.479
19.76,64.06,-0.479
19.77,63.94,-0.479
19.78,63.83,-0.479
19.79,63.71,-0.478
19.81,63.60,-0.478
19.82,63.48,-0.478
19.83,63.36,-0.478
19.84,63.24,-0.478
19.85,63.13,-0.477
19.86,63.01,-0.477
19.88,62.89,-0.477
19.89,62.78,-0.476
19.90,62.66,-0.476
19.91,62.54,-0.476
19.92,62.43,-0.476
19.93,62.31,-0.476
19.94,62.19,-0.475
19.96,62.08,-0.475
19.97,61.96,-0.475
19.98,61.85,-0.475
19.99,61.73,-0.475
20.00,61.61,-0.474
20.02,61.50,-0.474
20.03,61.38,-0.474
20.04,61.26,-0.474
20.05,61.15,-0.474
20.06,61.03,-0.474
20.07,60.91,-0.473
20.08,60.80,-0.473
20.10,60.68,-0.473
20.11,60.56,-0.472
20.12,60.45,-0.472
20.13,60.33,-0.472
20.14,60.21,-0.472
20.16,60.10,-0.472
20.17,59.98,-0.472
20.18,59.86,-0.471
20.19,59.75,-0.471
20.20,59.63,-0.471
20.21,59.52,-0.471
20.23,59.40,-0.471
20.24,59.28,-0.470
20.25,59.17,-0.470
20.26,59.05,-0.470
20.27,58.93,-0.470
20.28,58.82,-0.470
20.29,58.70,-0.469
20.31,58.58,-0.469
20.32,58.47,-0.468
20.33,58.35,-0.468
20.34,58.23,-0.468
20.35,58.12,-0.468
20.37,58.00,-0.468
20.38,57.88,-0.467
20.39,57.77,-0.467
20.40,57.65,-0.467
20.41,57.53,-0.467
20.42,57.42,-0.467
20.43,57.30,-0.467
20.45,57.18,-0.467
20.46,57.07,-0.467
20.47,56.95,-0.466
20.48,56.83,-0.466
20.49,56.72,-0.466
20.51,56.60,-0.466
20.52,56.49,-0.466
20.53,56.37,-0.465
20.54,56.25,-0.465
20.55,56.14,-0.465
20.56,56.02,-0.465
20.58,55.90,-0.465
20.59,55.79,-0.465
20.60,55.67,-0.465
20.61,55.55,-0.464
20.62,55.44,-0.464
20.63,55.32,-0.464
20.64,55.20,-0.464
20.66,55.09,-0.464
20.67,54.97,-0.463
20.68,54.85,-0.463
20.69,54.74,-0.463
20.70,54.62,-0.463
20.72,54.50,-0.463
20.73,54.39,-0.462
20.74,54.27,-0.462
20.75,54.15,-0.462
20.76,54.04,-0.462
20.77,53.92,-0.462
20.78,53.80,-0.461
20.80,53.69,-0.461
20.81,53.57,-0.461
[...]
104.08,-40.86,0.207
104.08,-40.79,0.207
104.09,-40.73,0.208
104.10,-40.66,0.208
104.10,-40.59,0.208
104.11,-40.52,0.208
104.11,-40.46,0.208
104.12,-40.39,0.208
104.13,-40.32,0.208
104.14,-40.26,0.208
104.14,-40.19,0.208
104.15,-40.12,0.208
104.15,-40.06,0.208
104.16,-39.99,0.208
104.17,-39.92,0.208
104.18,-39.86,0.208
104.18,-39.79,0.208
104.19,-39.73,0.208
104.20,-39.66,0.208
104.20,-39.59,0.208
104.21,-39.52,0.208
104.21,-39.46,0.208
104.22,-39.39,0.208
104.23,-39.32,0.208
104.24,-39.26,0.208
104.24,-39.19,0.208
104.25,-39.12,0.208
104.25,-39.06,0.208
104.26,-38.99,0.208
104.27,-38.92,0.208
104.28,-38.86,0.208
104.28,-38.79,0.208
104.29,-38.72,0.208
104.30,-38.65,0.208
104.30,-38.59,0.208
104.31,-38.52,0.208
104.31,-38.45,0.208
104.32,-38.39,0.208
104.33,-38.32,0.208
104.34,-38.25,0.208
104.34,-38.19,0.208
104.35,-38.12,0.208
104.35,-38.05,0.208
104.36,-37.99,0.208
104.37,-37.92,0.208
104.38,-37.85,0.208
104.38,-37.79,0.208
104.39,-37.72,0.208
104.40,-37.65,0.208
104.40,-37.59,0.208
104.41,-37.52,0.208
104.41,-37.45,0.208
104.42,-37.39,0.208
104.43,-37.32,0.208
104.44,-37.25,0.208
104.44,-37.18,0.208
104.45,-37.12,0.208
104.45,-37.05,0.208
104.46,-36.99,0.208
104.47,-36.92,0.208
104.48,-36.85,0.208
104.48,-36.78,0.208
104.49,-36.72,0.208
104.50,-36.65,0.208
104.50,-36.58,0.208
104.51,-36.52,0.208
104.51,-36.45,0.208
104.52,-36.38,0.208
104.53,-36.32,0.208
104.54,-36.25,0.208
104.54,-36.18,0.208
104.55,-36.12,0.208
104.55,-36.05,0.208
104.56,-35.98,0.208
104.57,-35.92,0.208
104.58,-35.85,0.208
104.58,-35.78,0.208
104.59,-35.72,0.208
104.60,-35.65,0.208
104.60,-35.58,0.208
104.61,-35.52,0.208
104.61,-35.45,0.208
104.62,-35.38,0.208
104.63,-35.31,0.208
104.64,-35.25,0.208
104.64,-35.18,0.208
104.65,-35.12,0.208
104.65,-35.05,0.208
104.66,-34.98,0.208
104.67,-34.92,0.208
104.68,-34.85,0.208
104.68,-34.78,0.208
104.69,-34.71,0.208
104.70,-34.65,0.208
104.70,-34.58,0.208
104.71,-34.51,0.208
104.71,-34.45,0.208
104.72,-34.38,0.208
104.73,-34.31,0.208
104.74,-34.24,0.208
104.74,-34.18,0.208
104.75,-34.11,0.208
104.75,-34.04,0.208
104.76,-33.98,0.208
104.77,-33.91,0.208
104.78,-33.84,0.208
104.78,-33.78,0.208
104.79,-33.71,0.208
104.80,-33.64,0.208
104.80,-33.57,0.208
104.81,-33.51,0.208
104.81,-33.44,0.208
104.82,-33.37,0.208
104.83,-33.31,0.208
104.84,-33.24,0.208
104.84,-33.17,0.209
104.85,-33.11,0.209
104.85,-33.04,0.209
104.86,-32.97,0.209
104.87,-32.91,0.209
104.88,-32.84,0.209
104.88,-32.77,0.209
104.89,-32.71,0.209
104.90,-32.64,0.209
104.90,-32.57,0.209
104.91,-32.50,0.209
104.91,-32.44,0.209
104.92,-32.37,0.209
104.93,-32.31,0.209
104.94,-32.24,0.209
104.94,-32.17,0.209
104.95,-32.11,0.209
104.95,-32.04,0.209
104.96,-31.97,0.209
104.97,-31.91,0.209
104.98,-31.84,0.209
104.98,-31.77,0.209
104.99,-31.70,0.209
105.00,-31.64,0.209
105.00,-31.57,0.209
105.01,-31.50,0.209
105.01,-31.44,0.209
105.02,-31.37,0.209
105.03,-31.30,0.209
105.04,-31.24,0.209
105.04,-31.17,0.209
105.05,-31.11,0.209
105.05,-31.04,0.208
105.06,-30.97,0.208
105.07,-30.90,0.209
105.08,-30.84,0.209
105.08,-30.77,0.209
105.09,-30.71,0.209
105.10,-30.64,0.209
105.10,-30.57,0.208
105.11,-30.50,0.208
105.11,-30.44,0.208
105.12,-30.37,0.208
105.13,-30.30,0.208
105.14,-30.24,0.208
105.14,-30.17,0.208
105.15,-30.10,0.208
105.15,-30.04,0.209
105.16,-29.97,0.209
105.17,-29.90,0.209
105.18,-29.84,0.209
105.18,-29.77,0.208
105.19,-29.70,0.208
105.20,-29.64,0.208
105.20,-29.57,0.208
105.21,-29.50,0.208
105.21,-29.44,0.208
105.22,-29.37,0.208
105.23,-29.31,0.208
105.24,-29.24,0.208
105.24,-29.17,0.208
105.25,-29.11,0.208
105.25,-29.04,0.208
105.26,-28.97,0.208
105.27,-28.90,0.208
105.28,-28.84,0.208
105.28,-28.77,0.208
105.29,-28.70,0.208
105.30,-28.64,0.208
105.30,-28.57,0.208
105.31,-28.50,0.208
105.31,-28.44,0.208
105.32,-28.37,0.208
105.33,-28.30,0.208
105.34,-28.24,0.208
105.34,-28.17,0.208
105.35,-28.10,0.208
105.35,-28.04,0.208
105.36,-27.97,0.208
105.37,-27.90,0.208
105.38,-27.83,0.208
105.38,-27.77,0.208
105.39,-27.70,0.208
105.40,-27.64,0.209
105.40,-27.57,0.209
105.41,-27.50,0.209
105.41,-27.44,0.209
105.42,-27.37,0.209
105.43,-27.30,0.209
105.44,-27.24,0.209
105.44,-27.17,0.209
105.45,-27.10,0.209
105.45,-27.03,0.209
105.46,-26.97,0.209
105.47,-26.90,0.209
105.48,-26.84,0.208
105.48,-26.77,0.208
105.49,-26.70,0.208
105.50,-26.63,0.209
105.50,-26.57,0.209
105.51,-26.50,0.209
105.51,-26.43,0.209
105.52,-26.37,0.209
105.53,-26.30,0.209
105.54,-26.23,0.209
105.54,-26.17,0.209
105.55,-26.10,0.209
105.55,-26.03,0.209
105.56,-25.97,0.209
105.57,-25.90,0.209
105.58,-25.83,0.209
105.58,-25.77,0.209
105.59,-25.70,0.209
105.60,-25.63,0.209
105.60,-25.57,0.209
105.61,-25.50,0.209
105.61,-25.43,0.209
105.62,-25.37,0.209
105.63,-25.30,0.209
105.64,-25.23,0.209
105.64,-25.17,0.209
105.65,-25.10,0.209
105.65,-25.03,0.209
105.66,-24.97,0.209
105.67,-24.90,0.209
105.68,-24.83,0.209
105.68,-24.77,0.209
105.69,-24.70,0.209
105.70,-24.63,0.209
105.70,-24.57,0.209
105.71,-24.50,0.209
105.71,-24.43,0.209
105.72,-24.36,0.209
105.73,-24.30,0.209
105.74,-24.23,0.209
105.74,-24.16,0.209
105.75,-24.10,0.209
105.75,-24.03,0.209
105.76,-23.96,0.209
105.77,-23.90,0.209
105.78,-23.83,0.209
105.78,-23.76,0.209
105.79,-23.70,0.209
105.80,-23.63,0.209
105.80,-23.56,0.209
105.81,-23.50,0.209
105.81,-23.43,0.209
105.82,-23.36,0.209
105.83,-23.30,0.209
105.84,-23.23,0.209
105.84,-23.16,0.209
105.85,-23.10,0.209
105.85,-23.03,0.209
105.86,-22.96,0.209
105.87,-22.90,0.209
105.88,-22.83,0.209
105.88,-22.76,0.209
105.89,-22.70,0.209
105.90,-22.63,0.209
105.90,-22.56,0.209
105.91,-22.49,0.209
105.91,-22.43,0.210
105.92,-22.36,0.210
105.93,-22.29,0.210
105.94,-22.23,0.210
105.94,-22.16,0.210
105.95,-22.09,0.210
105.95,-22.03,0.210
105.96,-21.96,0.210
105.97,-21.89,0.210
105.98,-21.83,0.210
105.98,-21.76,0.210
105.99,-21.69,0.210
106.00,-21.63,0.210
106.00,-21.56,0.210
106.01,-21.49,0.210
106.01,-21.43,0.210
106.02,-21.36,0.210
106.03,-21.29,0.210
106.04,-21.23,0.210
106.04,-21.16,0.210
106.05,-21.09,0.210
106.05,-21.03,0.210
106.06,-20.96,0.210
106.07,-20.89,0.210
106.08,-20.83,0.210
106.08,-20.76,0.210
106.09,-20.69,0.210
106.10,-20.63,0.210
106.10,-20.56,0.210
106.11,-20.49,0.210
106.11,-20.43,0.210
106.12,-20.36,0.210
106.13,-20.29,0.210
106.14,-20.23,0.210
106.14,-20.16,0.210
106.15,-20.09,0.210
106.15,-20.03,0.210
106.16,-19.96,0.210
106.17,-19.89,0.210
106.18,-19.83,0.210
106.18,-19.76,0.210
106.19,-19.69,0.210
106.20,-19.63,0.210
106.20,-19.56,0.210
106.21,-19.49,0.210
106.21,-19.43,0.210
106.22,-19.36,0.210
106.23,-19.29,0.210
106.24,-19.23,0.210
106.24,-19.16,0.210
106.25,-19.09,0.210
106.25,-19.02,0.210
106.26,-18.96,0.210
106.27,-18.89,0.210
106.28,-18.82,0.210
106.28,-18.76,0.210
106.29,-18.69,0.210
106.30,-18.62,0.210
106.30,-18.56,0.210
106.31,-18.49,0.210
106.31,-18.42,0.211
106.32,-18.36,0.211
106.33,-18.29,0.210
106.34,-18.22,0.210
106.34,-18.16,0.210
106.35,-18.09,0.210
106.35,-18.02,0.210
106.36,-17.96,0.210
106.37,-17.89,0.210
106.38,-17.82,0.210
106.38,-17.76,0.210
106.39,-17.69,0.210
106.40,-17.62,0.210
106.40,-17.56,0.210
106.41,-17.49,0.210
106.41,-17.42,0.210
106.42,-17.36,0.210
106.43,-17.29,0.211
106.44,-17.22,0.211
106.44,-17.16,0.211
106.45,-17.09,0.211
106.45,-17.02,0.211
106.46,-16.96,0.210
106.47,-16.89,0.211
106.48,-16.82,0.211
106.48,-16.76,0.211
106.49,-16.69,0.211
106.50,-16.62,0.211
106.50,-16.55,0.211
106.51,-16.49,0.211
106.51,-16.42,0.211
106.52,-16.35,0.211
106.53,-16.29,0.211
106.54,-16.22,0.211
106.54,-16.16,0.211
106.55,-16.09,0.211
106.55,-16.02,0.211
106.56,-15.95,0.211
106.57,-15.89,0.211
106.58,-15.82,0.211
106.58,-15.75,0.211
106.59,-15.69,0.211
106.60,-15.62,0.211
106.60,-15.55,0.211
106.61,-15.49,0.211
106.61,-15.42,0.211
106.62,-15.35,0.211
106.63,-15.29,0.211
106.64,-15.22,0.211
106.64,-15.15,0.211
106.65,-15.09,0.211
106.65,-15.02,0.211
106.66,-14.95,0.211
106.67,-14.89,0.211
106.68,-14.82,0.211
106.68,-14.75,0.211
106.69,-14.68,0.211
106.70,-14.62,0.211
106.70,-14.55,0.211
106.71,-14.49,0.211
106.71,-14.42,0.211
106.72,-14.35,0.211
106.73,-14.28,0.211
106.74,-14.22,0.211
106.74,-14.15,0.211
106.75,-14.08,0.211
106.75,-14.02,0.211
106.76,-13.95,0.211
106.77,-13.88,0.211
106.78,-13.82,0.211
106.78,-13.75,0.211
106.79,-13.68,0.211
106.80,-13.62,0.211
106.80,-13.55,0.211
106.81,-13.48,0.211
106.81,-13.42,0.211
106.82,-13.35,0.211
106.83,-13.28,0.212
106.84,-13.22,0.212
106.84,-13.15,0.212
106.85,-13.08,0.212
106.85,-13.02,0.212
106.86,-12.95,0.212
106.87,-12.88,0.212
106.88,-12.82,0.212
106.88,-12.75,0.212
106.89,-12.68,0.212
106.90,-12.62,0.212
106.90,-12.55,0.212
106.91,-12.48,0.212
106.91,-12.42,0.212
106.92,-12.35,0.212
106.93,-12.28,0.212
106.94,-12.22,0.212
106.94,-12.15,0.212
106.95,-12.08,0.212
106.95,-12.02,0.212
106.96,-11.95,0.212
106.97,-11.88,0.212
106.98,-11.82,0.212
106.98,-11.75,0.212
106.99,-11.68,0.212
107.00,-11.61,0.212
107.00,-11.55,0.212
107.01,-11.48,0.212
107.01,-11.41,0.212
107.02,-11.35,0.212
107.03,-11.28,0.212
107.04,-11.21,0.212
107.04,-11.15,0.212
107.05,-11.08,0.212
107.05,-11.01,0.212
107.06,-10.95,0.212
107.07,-10.88,0.212
107.08,-10.81,0.212
107.08,-10.75,0.212
107.09,-10.68,0.212
107.10,-10.61,0.213
107.10,-10.55,0.213
107.11,-10.48,0.213
107.11,-10.41,0.213
107.12,-10.35,0.213
107.13,-10.28,0.213
107.14,-10.21,0.213
107.14,-10.14,0.213
107.15,-10.08,0.213
107.15,-10.01,0.213
107.16,-9.95,0.213
107.17,-9.88,0.213
107.18,-9.81,0.213
107.18,-9.75,0.213
107.19,-9.68,0.213
107.20,-9.61,0.213
107.20,-9.55,0.213
107.21,-9.48,0.213
107.21,-9.41,0.213
107.22,-9.35,0.213
107.23,-9.28,0.213
107.24,-9.21,0.213
107.24,-9.15,0.213
107.25,-9.08,0.213
107.25,-9.01,0.213
107.26,-8.95,0.213
107.27,-8.88,0.213
107.28,-8.81,0.213
107.28,-8.75,0.213
107.29,-8.68,0.213
107.30,-8.61,0.213
107.30,-8.55,0.213
107.31,-8.48,0.213
107.31,-8.41,0.213
107.32,-8.35,0.213
107.33,-8.28,0.213
107.34,-8.21,0.213
107.34,-8.15,0.213
107.35,-8.08,0.213
107.35,-8.01,0.213
107.36,-7.95,0.213
107.37,-7.88,0.213
107.38,-7.81,0.213
107.38,-7.74,0.213
107.39,-7.68,0.213
107.40,-7.61,0.213
107.40,-7.54,0.213
107.41,-7.48,0.213
107.41,-7.41,0.213
107.42,-7.34,0.213
107.43,-7.28,0.213
107.44,-7.21,0.213
107.44,-7.14,0.213
107.45,-7.08,0.213
107.45,-7.01,0.213
107.46,-6.94,0.213
107.47,-6.88,0.213
107.48,-6.81,0.213
107.48,-6.74,0.213
107.49,-6.68,0.214
107.50,-6.61,0.214
107.50,-6.54,0.214
107.51,-6.48,0.214
107.51,-6.41,0.214
107.52,-6.34,0.214
107.53,-6.27,0.214
107.54,-6.21,0.214
107.54,-6.14,0.214
107.55,-6.07,0.214
107.55,-6.01,0.214
107.56,-5.94,0.214
107.57,-5.87,0.214
107.58,-5.81,0.214
107.58,-5.74,0.214
107.59,-5.67,0.214
107.60,-5.61,0.214
107.60,-5.54,0.214
107.61,-5.47,0.214
107.61,-5.41,0.214
107.62,-5.34,0.214
107.63,-5.27,0.214
107.64,-5.21,0.214
107.64,-5.14,0.214
107.65,-5.07,0.214
107.65,-5.01,0.214
107.66,-4.94,0.214
107.67,-4.87,0.214
107.68,-4.81,0.214
107.68,-4.74,0.214
107.69,-4.67,0.214
107.70,-4.61,0.214
107.70,-4.54,0.215
107.71,-4.47,0.215
107.71,-4.40,0.215
107.72,-4.34,0.215
107.73,-4.27,0.215
107.74,-4.21,0.215
107.74,-4.14,0.215
107.75,-4.07,0.215
107.75,-4.01,0.215
107.76,-3.94,0.215
107.77,-3.87,0.215
107.78,-3.80,0.215
107.78,-3.74,0.215
107.79,-3.67,0.215
107.80,-3.60,0.215
107.80,-3.54,0.215
107.81,-3.47,0.215
107.81,-3.40,0.215
107.82,-3.34,0.215
107.83,-3.27,0.215
107.84,-3.20,0.215
107.84,-3.14,0.215
107.85,-3.07,0.215
107.85,-3.00,0.215
107.86,-2.94,0.215
107.87,-2.87,0.215
107.88,-2.80,0.215
107.88,-2.74,0.215
107.89,-2.67,0.215
107.90,-2.60,0.215
107.90,-2.54,0.215
107.91,-2.47,0.215
107.91,-2.40,0.215
107.92,-2.34,0.215
107.93,-2.27,0.215
107.94,-2.20,0.215
107.94,-2.13,0.216
107.95,-2.07,0.216
107.95,-2.00,0.216
107.96,-1.94,0.216
107.97,-1.87,0.216
107.98,-1.80,0.216
107.98,-1.73,0.216
107.99,-1.67,0.216
108.00,-1.60,0.216
108.00,-1.53,0.216
108.01,-1.47,0.216
108.01,-1.40,0.216
108.02,-1.33,0.216
108.03,-1.27,0.216
108.04,-1.20,0.216
108.04,-1.13,0.216
108.05,-1.07,0.216
108.05,-1.00,0.216
108.06,-0.93,0.216
108.07,-0.87,0.216
108.08,-0.80,0.216
108.08,-0.74,0.216
108.09,-0.67,0.216
108.10,-0.60,0.216
108.10,-0.53,0.216
108.11,-0.47,0.216
108.11,-0.40,0.217
108.12,-0.33,0.217
108.13,-0.27,0.217
108.14,-0.20,0.217
108.14,-0.13,0.217
108.15,-0.07,0.217
108.15,0.00,0.217
108.16,0.07,0.217
108.17,0.13,0.217
108.18,0.20,0.217
108.18,0.27,0.217
108.19,0.33,0.217
108.20,0.40,0.217
108.20,0.47,0.217
108.21,0.53,0.217
108.21,0.60,0.217
108.22,0.67,0.217
108.23,0.73,0.217
108.24,0.80,0.217
108.24,0.87,0.217
108.25,0.94,0.217
108.25,1.00,0.217
108.26,1.07,0.217
108.27,1.14,0.217
108.28,1.20,0.218
108.28,1.27,0.218
108.29,1.33,0.218
108.30,1.40,0.218
108.30,1.47,0.218
108.31,1.54,0.218
108.31,1.60,0.218
108.32,1.67,0.218
108.33,1.74,0.218
108.34,1.80,0.218
108.34,1.87,0.218
108.35,1.94,0.218
108.35,2.00,0.218
108.36,2.07,0.218
108.37,2.14,0.218
108.38,2.20,0.218
108.38,2.27,0.218
108.39,2.34,0.218
108.40,2.40,0.218
108.40,2.47,0.218
108.41,2.54,0.218
108.41,2.60,0.218
108.42,2.67,0.218
108.43,2.74,0.218
108.44,2.80,0.218
108.44,2.87,0.219
108.45,2.94,0.219
108.45,3.00,0.219
108.46,3.07,0.219
108.47,3.14,0.219
108.48,3.21,0.219
108.48,3.27,0.219
108.49,3.34,0.219
108.50,3.41,0.219
108.50,3.47,0.219
108.51,3.54,0.219
108.51,3.61,0.219
108.52,3.67,0.219
108.53,3.74,0.219
108.54,3.81,0.219
108.54,3.87,0.219
108.55,3.94,0.219
108.55,4.01,0.219
108.56,4.07,0.220
108.57,4.14,0.220
108.58,4.21,0.220
108.58,4.27,0.220
108.59,4.34,0.220
108.60,4.41,0.220
108.60,4.47,0.220
108.61,4.54,0.220
108.61,4.61,0.220
108.62,4.67,0.220
108.63,4.74,0.220
108.64,4.81,0.220
108.64,4.87,0.220
108.65,4.94,0.220
108.65,5.01,0.220
108.66,5.07,0.220
108.67,5.14,0.220
108.68,5.21,0.220
108.68,5.28,0.220
108.69,5.34,0.220
108.70,5.41,0.221
108.70,5.48,0.221
108.71,5.54,0.221
108.71,5.61,0.221
108.72,5.68,0.221
108.73,5.74,0.221
108.74,5.81,0.221
108.74,5.88,0.221
108.75,5.94,0.221
108.75,6.01,0.221
108.76,6.08,0.221
108.77,6.14,0.221
108.78,6.21,0.221
108.78,6.28,0.221
108.79,6.34,0.221
108.80,6.41,0.222
108.80,6.48,0.222
108.81,6.54,0.222
108.81,6.61,0.222
108.82,6.68,0.222
108.83,6.74,0.222
108.84,6.81,0.222
108.84,6.88,0.222
108.85,6.94,0.222
108.85,7.01,0.222
108.86,7.08,0.222
108.87,7.14,0.222
108.88,7.21,0.222
108.88,7.28,0.222
108.89,7.34,0.222
108.90,7.41,0.222
108.90,7.48,0.223
108.91,7.54,0.223
108.91,7.61,0.223
108.92,7.68,0.223
108.93,7.75,0.223
108.94,7.81,0.223
108.94,7.88,0.223
108.95,7.94,0.223
108.95,8.01,0.223
108.96,8.08,0.223
108.97,8.14,0.223
108.98,8.21,0.223
108.98,8.28,0.223
108.99,8.35,0.223
109.00,8.41,0.223
109.00,8.48,0.223
109.01,8.55,0.224
109.01,8.61,0.224
109.02,8.68,0.224
109.03,8.75,0.224
109.04,8.81,0.224
109.04,8.88,0.224
109.05,8.95,0.224
109.05,9.01,0.224
109.06,9.08,0.224
109.07,9.15,0.224
109.08,9.21,0.225
109.08,9.28,0.225
109.09,9.35,0.225
109.10,9.41,0.225
109.10,9.48,0.225
109.11,9.55,0.225
109.11,9.61,0.225
109.12,9.68,0.225
109.13,9.75,0.225
109.14,9.81,0.225
109.14,9.88,0.225
109.15,9.95,0.225
109.15,10.01,0.225
109.16,10.08,0.225
109.17,10.15,0.226
109.18,10.21,0.226
109.18,10.28,0.226
109.19,10.35,0.226
109.20,10.41,0.226
109.20,10.48,0.226
109.21,10.55,0.226
109.21,10.61,0.226
109.22,10.68,0.226
109.23,10.75,0.226
109.24,10.82,0.226
109.24,10.88,0.226
109.25,10.95,0.227
109.25,11.01,0.227
109.26,11.08,0.227
109.27,11.15,0.227
109.28,11.21,0.227
109.28,11.28,0.227
109.29,11.35,0.227
109.30,11.41,0.227
109.30,11.48,0.227
109.31,11.55,0.227
109.31,11.62,0.227
109.32,11.68,0.227
109.33,11.75,0.227
109.34,11.81,0.228
109.34,11.88,0.228
109.35,11.95,0.228
109.35,12.02,0.228
109.36,12.08,0.228
109.37,12.15,0.228
109.38,12.22,0.228
109.38,12.28,0.228
109.39,12.35,0.228
109.40,12.42,0.228
109.40,12.48,0.229
109.41,12.55,0.229
109.41,12.62,0.229
109.42,12.68,0.229
109.43,12.75,0.229
109.44,12.82,0.229
109.44,12.88,0.229
109.45,12.95,0.229
109.45,13.02,0.229
109.46,13.08,0.229
109.47,13.15,0.229
109.48,13.22,0.230
109.48,13.28,0.230
109.49,13.35,0.230
109.50,13.42,0.230
109.50,13.48,0.230
109.51,13.55,0.230
109.51,13.62,0.230
109.52,13.68,0.230
109.53,13.75,0.231
109.54,13.82,0.231
109.54,13.88,0.231
109.55,13.95,0.231
109.55,14.02,0.231
109.56,14.08,0.231
109.57,14.15,0.231
109.58,14.22,0.231
109.58,14.28,0.232
109.59,14.35,0.232
109.60,14.42,0.232
109.60,14.48,0.232
109.61,14.55,0.232
109.61,14.62,0.232
109.62,14.69,0.232
109.63,14.75,0.233
109.64,14.82,0.233
109.64,14.88,0.233
109.65,14.95,0.233
109.65,15.02,0.233
109.66,15.09,0.233
109.67,15.15,0.233
109.68,15.22,0.233
109.68,15.29,0.233
109.69,15.35,0.233
109.70,15.42,0.234
109.70,15.49,0.234
109.71,15.55,0.234
109.71,15.62,0.234
109.72,15.69,0.234
109.73,15.75,0.234
109.74,15.82,0.234
109.74,15.89,0.234
109.75,15.95,0.234
109.75,16.02,0.235
109.76,16.09,0.235
109.77,16.15,0.235
109.78,16.22,0.235
109.78,16.29,0.235
109.79,16.35,0.235
109.80,16.42,0.235
109.80,16.49,0.236
109.81,16.55,0.236
109.81,16.62,0.236
109.82,16.69,0.236
109.83,16.75,0.236
109.84,16.82,0.236
109.84,16.89,0.236
109.85,16.95,0.236
109.85,17.02,0.237
109.86,17.09,0.237
109.87,17.15,0.237
109.88,17.22,0.237
109.88,17.29,0.237
109.89,17.35,0.237
109.90,17.42,0.237
109.90,17.49,0.237
109.91,17.55,0.238
109.91,17.62,0.238
109.92,17.69,0.238
109.93,17.75,0.238
109.94,17.82,0.238
109.94,17.89,0.239
109.95,17.95,0.239
109.95,18.02,0.239
109.96,18.09,0.239
109.97,18.15,0.239
109.98,18.22,0.239
109.98,18.29,0.239
109.99,18.35,0.240
110.00,18.42,0.240
110.00,18.49,0.240
110.01,18.55,0.240
110.01,18.62,0.240
110.02,18.69,0.240
110.03,18.75,0.240
110.04,18.82,0.241
110.04,18.89,0.241
110.05,18.95,0.241
110.05,19.02,0.241
110.06,19.09,0.241
110.07,19.15,0.241
110.08,19.22,0.241
110.08,19.29,0.242
110.09,19.35,0.242
110.10,19.42,0.242
110.10,19.49,0.242
110.11,19.55,0.242
110.11,19.62,0.243
110.12,19.69,0.243
110.13,19.75,0.243
110.14,19.82,0.243
110.14,19.89,0.243
110.15,19.95,0.243
110.15,20.02,0.244
110.16,20.09,0.244
110.17,20.15,0.244
110.18,20.22,0.244
110.18,20.29,0.244
110.19,20.35,0.245
110.20,20.42,0.245
110.20,20.49,0.245
110.21,20.55,0.245
110.21,20.62,0.245
110.22,20.69,0.245
110.23,20.75,0.245
110.24,20.82,0.246
110.24,20.89,0.246
110.25,20.95,0.246
110.25,21.02,0.246
110.26,21.09,0.247
110.27,21.15,0.247
110.28,21.22,0.247
110.28,21.29,0.247
110.29,21.35,0.247
110.30,21.42,0.248
110.30,21.49,0.248
110.31,21.55,0.248
110.31,21.62,0.248
110.32,21.69,0.248
110.33,21.75,0.249
110.34,21.82,0.249
110.34,21.89,0.249
110.35,21.95,0.249
110.35,22.02,0.249
110.36,22.09,0.250
110.37,22.15,0.250
110.38,22.22,0.250
110.38,22.29,0.250
110.39,22.36,0.251
110.40,22.42,0.251
110.40,22.49,0.251
110.41,22.56,0.251
110.41,22.62,0.251
110.42,22.69,0.252
110.43,22.75,0.252
110.44,22.82,0.252
110.44,22.89,0.252
110.45,22.96,0.252
110.45,23.02,0.253
110.46,23.09,0.253
110.47,23.16,0.253
110.48,23.22,0.253
110.48,23.29,0.254
110.49,23.36,0.254
110.50,23.42,0.254
110.50,23.49,0.254
110.51,23.56,0.255
110.51,23.62,0.255
110.52,23.69,0.255
110.53,23.76,0.256
110.54,23.82,0.256
110.54,23.89,0.256
110.55,23.96,0.256
110.55,24.02,0.256
110.56,24.09,0.257
110.57,24.16,0.257
110.58,24.22,0.257
110.58,24.29,0.257
110.59,24.36,0.258
110.60,24.42,0.258
110.60,24.49,0.258
110.61,24.56,0.258
110.61,24.62,0.258
110.62,24.69,0.259
110.63,24.76,0.259
110.64,24.82,0.259
110.64,24.89,0.259
110.65,24.96,0.260
110.65,25.02,0.260
110.66,25.09,0.260
110.67,25.16,0.261
110.68,25.22,0.261
110.68,25.29,0.261
110.69,25.36,0.261
110.70,25.43,0.262
110.70,25.49,0.262
110.71,25.56,0.262
110.71,25.63,0.262
110.72,25.69,0.263
110.73,25.76,0.263
110.74,25.83,0.263
110.74,25.89,0.263
110.75,25.96,0.264
110.75,26.02,0.264
110.76,26.09,0.264
110.77,26.16,0.264
110.78,26.23,0.265
110.78,26.29,0.265
110.79,26.36,0.265
110.80,26.42,0.265
110.80,26.49,0.266
110.81,26.56,0.266
110.81,26.62,0.266
110.82,26.69,0.266
110.83,26.76,0.267
110.84,26.82,0.267
110.84,26.89,0.267
110.85,26.96,0.267
110.85,27.03,0.268
110.86,27.09,0.268
110.87,27.16,0.268
110.88,27.23,0.269
110.88,27.29,0.269
110.89,27.36,0.269
110.90,27.43,0.270
110.90,27.49,0.271
110.91,27.56,0.271
110.91,27.63,0.271
110.92,27.69,0.271
110.93,27.76,0.272
110.94,27.83,0.273
110.94,27.89,
110.95,27.96,
110.95,28.03,
110.96,28.09,
110.97,28.16,
110.98,28.23,
110.98,28.29,
110.99,,
110.99,,