File: DSC/Olivia/2025_08_09_1CBN_3PVP29_MeOH_n60C_200C_10Cmin_x3.csv
Filename,2025_08_09_1CBN_3PVP29_MeOH_n60C_200C_10Cmin_x3
Instrument name,DSC2A-00468 (192.168.1.100)
Operator,Yarger
rundate,8/9/2025
Sample name,2025_08_09_1CBN_3PVP29_MeOH_n60C_200C_10Cmin_x3
proceduresegments,Data Off ; Equilibrate -60.00 °C; Data On ; Ramp 10.00 °C/min to 200.00 °C; Data Off ; Isothermal 2.0 min; Data On ; Ramp 10.00 °C/min to -60.00 °C; Data Off ; Isothermal 2.0 min; Data On ; Ramp 10.00 °C/min to 200.00 °C; Data Off ; Isothermal 2.0 min; Data On ; Ramp 10.00 °C/min to -60.00 °C; Data Off ; Isothermal 2.0 min; Data On ; Ramp 10.00 °C/min to 200.00 °C
[File Parameters]
Run date,8/9/2025 3:18:20 AM
Trios version,5.1.1.46572
Original File Name,
Current File Name,D:\DSC2500\JYarger\2025_08_09_1CBN_3PVP29_MeOH_n60C_200C_10Cmin_x3.tri
[Procedure]
Procedure Name,CBN_PVP29_TS_Pans_n60C_200C_10Cmin_x3
Sample Name,2025_08_09_1CBN_3PVP29_MeOH_n60C_200C_10Cmin_x3
Sample Mass,5.36 mg
Reference Sample Mass,0 mg
Pan Mass,32.61 mg
Pan Number,48
Reference Pan Mass,32.73 mg
Reference Pan Number,46
Pan Type,Aluminum
Comments,Thermal support Al pans/lids. DSC_Samples_A2_Tray_July2025 google sheet.
Project Name,Pharma
Operator,Yarger
Test,Custom
Unload Max Temperature,30
Unload Min Temperature,30
Load Max Temperature,30
Load Min Temperature,30
Stop on Gas Flow Error,Yes
[Signal List]
Signal #1,Time (min)
Signal #2,Temperature (°C)
Signal #3,Heat Flow (mW)
Signal #4,Delta T (µV)
Signal #5,Delta Tzero (µV)
Signal #6,Tzero Temperature (°C)
Signal #7,Cell Purge (mL/min)
Signal #8,Heater Temp (°C)
Signal #9,Power Delivered (W)
Signal #10,Reference Junction Temperature (°C)
Signal #11,Flange Temperature (°C)
Signal #12,Heat Flow Phase (rad)
Signal #13,Total Heat Capacity (J/°C)
Signal #14,Heat Capacity (J/°C)
[Configuration]
Company Name,ASU
Instrument Name,DSC2A-00468
Instrument Type,DSC2500
Serial Number,DSC2A-00468
IP,192.168.1.100
Location of Instrument,MRRC
DisplayType,Unknown
Sample Interval ,0.1 s/pt
Selected Heat Flow,T4P
Exotherm Direction,Down
Cell Serial,DRC2-00792
Lid Type,Standard
Cooler,RCS 90
Leave Cooler on at End of Sequence,On
Gas 2,Nitrogen
Gas Selected,Channel 1
Flow Rate,50 mL/min
Secondary Purge,On
Licensed Heat Flow,Heat Flow T4P
Modulation Licensed,Yes
[Versions]
Common IDD Version,1
Cortex Version,VER 2.10.2.31
Driver,5.0.0.6
GDM Version,1.0.3.3
TouchscreenVersion,1.0.0.16145
FEP Version,1.2.1.21
FEP Bootloader,2.0.0.5
AutoSampler Version,2.1.1.26
Auto Sampler Bootloader,2.0.0.5
FCM Version,1.1.0.3
FCM Bootloader,2.0.0.5
[Experiment Logs]
Experiment Log Entry # 1,Data On set to 0
Experiment Log Entry # 3,Equilibrate Segment -60 (C) Started
Experiment Log Entry # 5,Air Cool is off.
Experiment Log Entry # 7,Data On set to 1
Experiment Log Entry # 9,Ramp Segment 10 C/min to 200 Started
Experiment Log Entry # 11,Data On set to 0
Experiment Log Entry # 13,Isothermal Segment 2 min started
Experiment Log Entry # 15,Data On set to 1
Experiment Log Entry # 17,Ramp Segment 10 C/min to -60 Started
Experiment Log Entry # 19,Data On set to 0
Experiment Log Entry # 21,Isothermal Segment 2 min started
Experiment Log Entry # 23,Data On set to 1
Experiment Log Entry # 25,Ramp Segment 10 C/min to 200 Started
Experiment Log Entry # 27,Data On set to 0
Experiment Log Entry # 29,Isothermal Segment 2 min started
Experiment Log Entry # 31,Data On set to 1
Experiment Log Entry # 33,Ramp Segment 10 C/min to -60 Started
Experiment Log Entry # 35,Data On set to 0
Experiment Log Entry # 37,Isothermal Segment 2 min started
Experiment Log Entry # 39,Data On set to 1
Experiment Log Entry # 41,Ramp Segment 10 C/min to 200 Started
[Method Log]
Method Log Entry # 1,Data Off
Method Log Entry # 2,Equilibrate -60 °C
Method Log Entry # 3,Data On
Method Log Entry # 4,(Ramp 542501) Ramp 10 °C/minute to 200 °C
Method Log Entry # 5,Data Off
Method Log Entry # 6,Isothermal 2 minutes
Method Log Entry # 7,Data On
Method Log Entry # 8,(Ramp 542505) Ramp 10 °C/minute to -60 °C
Method Log Entry # 9,Data Off
Method Log Entry # 10,Isothermal 2 minutes
Method Log Entry # 11,Data On
Method Log Entry # 12,(Ramp 542509) Ramp 10 °C/minute to 200 °C
Method Log Entry # 13,Data Off
Method Log Entry # 14,Isothermal 2 minutes
Method Log Entry # 15,Data On
Method Log Entry # 16,(Ramp 542513) Ramp 10 °C/minute to -60 °C
Method Log Entry # 17,Data Off
Method Log Entry # 18,Isothermal 2 minutes
Method Log Entry # 19,Data On
Method Log Entry # 20,(Ramp 542517) Ramp 10 °C/minute to 200 °C
Cell Serial,DRC2-00792
[T1 Calibration]
Slope,-0.008529666
Offset,9.636258
Initial Temperature,98.23
GUID,f8bfdadc-4977-4fdf-ba6d-0ba9134940c3
[TZero Calibration]
Date Applied,11/29/2022 4:06:13 PM
Description,From -89.059 °C to 396.009 °C at 20.000°C/min
Gas Type,Nitrogen
Pan Type,None
Source Files 1,C:\Users\yargerlab\Desktop\DSC Data\General\TZero_calibration_11_29_22_2nd(2).tri
Source Files 2,C:\Users\yargerlab\Desktop\DSC Data\General\TZero_calibration_11_29_22_2nd(3).tri
Delta T Offset,13.05235
Delta T Slope,-0.007271007
Delta T0 Offset,-13.69128
Delta T0 Slope,0.06063341
[Temperature Calibration]
Date Applied,11/29/2022 7:12:28 PM
Description,From 106.590 °C to 186.590 °C at 10.000°C/min
Gas Type,Nitrogen
Pan Type,Tzero Aluminum Hermetic
Source Files 1,C:\Users\yargerlab\Desktop\DSC Data\General\Indium(6).tri
Measured 1,157.391
Known 1,156.598
[Cell Constant Calibration]
Date Applied,11/29/2022 7:12:29 PM
Description,From 106.590 °C to 186.590 °C at 10.000°C/min
Gas Type,Nitrogen
Pan Type,Tzero Aluminum Hermetic
Source Files 1,C:\Users\yargerlab\Desktop\DSC Data\General\Indium(6).tri
T4P KCell,1.006051
Onset Slope,63.26126 mW/°C
[Direct Cp Calibration]
Date Applied,11/30/2022 11:04:51 AM
Description,From -79.983 °C to 298.409 °C at 10.000°C/min
Gas Type,Nitrogen
Pan Type,Tzero Aluminum Hermetic
Source Files 1,C:\Users\yargerlab\Desktop\DSC Data\General\Sapphire_Heat_Capacity_11_30_22.tri
[Rev Cp Calibration]
Date Applied,11/30/2022 1:58:51 PM
Description,From -79.996 °C to 292.812 °C at 3.000°C/min
Gas Type,Nitrogen
Pan Type,Tzero Aluminum Hermetic
Source Files 1,C:\Users\yargerlab\Desktop\DSC Data\General\Sapphire_MDSC_Calibration_11_30_22.tri
[step]
Ramp 10.00 °C/min to 200.00 °C
Time,Temperature,Heat Flow (Normalized)
min,°C,W/g
0.00,-59.81,-0.038
0.02,-59.81,-0.037
0.04,-59.81,-0.033
0.05,-59.80,-0.031
0.07,-59.77,-0.030
0.09,-59.72,-0.028
0.11,-59.65,-0.016
0.13,-59.55,0.003
0.15,-59.43,0.022
0.16,-59.30,0.044
0.18,-59.15,0.067
0.20,-59.00,0.088
0.22,-58.83,0.105
0.24,-58.67,0.121
0.26,-58.50,0.133
0.28,-58.33,0.143
0.29,-58.15,0.150
0.31,-57.98,0.157
0.33,-57.80,0.163
0.35,-57.63,0.165
0.37,-57.45,0.168
0.39,-57.27,0.171
0.40,-57.09,0.172
0.42,-56.91,0.173
0.44,-56.74,0.175
0.46,-56.56,0.176
0.48,-56.38,0.177
0.50,-56.20,0.177
0.51,-56.02,0.178
0.53,-55.84,0.178
0.55,-55.66,0.179
0.57,-55.48,0.179
0.59,-55.30,0.179
0.60,-55.12,0.179
0.62,-54.94,0.180
0.64,-54.75,0.180
0.66,-54.57,0.180
0.68,-54.39,0.181
0.70,-54.21,0.181
0.72,-54.03,0.181
0.73,-53.85,0.182
0.75,-53.67,0.182
0.77,-53.49,0.182
0.79,-53.30,0.182
0.81,-53.12,0.183
0.83,-52.94,0.183
0.84,-52.76,0.183
0.86,-52.58,0.183
0.88,-52.39,0.184
0.90,-52.21,0.184
0.92,-52.03,0.184
0.93,-51.85,0.184
0.95,-51.67,0.185
0.97,-51.48,0.185
0.99,-51.30,0.185
1.01,-51.12,0.185
1.03,-50.94,0.186
1.05,-50.76,0.186
1.06,-50.57,0.186
1.08,-50.39,0.186
1.10,-50.21,0.186
1.12,-50.02,0.187
1.14,-49.84,0.187
1.16,-49.66,0.187
1.17,-49.48,0.187
1.19,-49.29,0.187
1.21,-49.11,0.187
1.23,-48.93,0.188
1.25,-48.75,0.188
1.27,-48.56,0.188
1.28,-48.38,0.188
1.30,-48.20,0.188
1.32,-48.01,0.188
1.34,-47.83,0.188
1.36,-47.65,0.188
1.38,-47.46,0.189
1.39,-47.28,0.189
1.41,-47.10,0.189
1.43,-46.91,0.189
1.45,-46.73,0.189
1.47,-46.55,0.189
1.48,-46.36,0.189
1.50,-46.18,0.189
1.52,-46.00,0.189
1.54,-45.81,0.190
1.56,-45.63,0.190
1.58,-45.45,0.190
1.59,-45.26,0.190
1.61,-45.08,0.190
1.63,-44.90,0.190
1.65,-44.71,0.190
1.67,-44.53,0.190
1.69,-44.35,0.190
1.71,-44.16,0.190
1.72,-43.98,0.190
1.74,-43.80,0.191
1.76,-43.62,0.191
1.78,-43.43,0.191
1.80,-43.25,0.191
1.82,-43.06,0.191
1.83,-42.88,0.191
1.85,-42.70,0.191
1.87,-42.51,0.191
1.89,-42.33,0.191
1.91,-42.14,0.191
1.93,-41.96,0.191
1.94,-41.78,0.192
1.96,-41.60,0.192
1.98,-41.41,0.192
2.00,-41.23,0.192
2.02,-41.05,0.192
2.03,-40.86,0.192
2.05,-40.68,0.192
2.07,-40.50,0.192
2.09,-40.31,0.192
2.11,-40.13,0.192
2.13,-39.94,0.192
2.14,-39.76,0.192
2.16,-39.58,0.192
2.18,-39.39,0.193
2.20,-39.21,0.193
2.22,-39.03,0.193
2.24,-38.84,0.193
2.26,-38.66,0.193
2.27,-38.48,0.193
2.29,-38.29,0.193
2.31,-38.11,0.193
2.33,-37.92,0.193
2.35,-37.74,0.193
2.36,-37.56,0.193
2.38,-37.37,0.193
2.40,-37.19,0.193
2.42,-37.01,0.193
2.44,-36.82,0.193
2.46,-36.64,0.194
2.48,-36.46,0.194
2.49,-36.27,0.194
2.51,-36.09,0.194
2.53,-35.91,0.194
2.55,-35.72,0.194
2.57,-35.54,0.194
2.59,-35.36,0.194
2.60,-35.17,0.194
2.62,-34.99,0.194
2.64,-34.81,0.194
2.66,-34.62,0.194
2.68,-34.44,0.194
2.69,-34.25,0.194
2.71,-34.07,0.194
2.73,-33.89,0.194
2.75,-33.70,0.194
2.77,-33.52,0.194
2.79,-33.34,0.195
2.81,-33.15,0.195
2.82,-32.97,0.195
2.84,-32.79,0.195
2.86,-32.60,0.195
2.88,-32.42,0.195
2.90,-32.23,0.195
2.91,-32.05,0.195
2.93,-31.87,0.195
2.95,-31.68,0.195
2.97,-31.50,0.195
2.99,-31.32,0.195
3.01,-31.13,0.196
3.03,-30.95,0.196
3.04,-30.76,0.196
3.06,-30.58,0.196
3.08,-30.40,0.196
3.10,-30.21,0.196
3.12,-30.03,0.196
3.14,-29.85,0.196
3.15,-29.66,0.196
3.17,-29.48,0.196
3.19,-29.30,0.196
3.21,-29.11,0.196
3.23,-28.93,0.196
3.24,-28.75,0.196
3.26,-28.56,0.197
3.28,-28.38,0.197
3.30,-28.19,0.197
3.32,-28.01,0.197
3.34,-27.83,0.197
3.36,-27.65,0.197
3.37,-27.46,0.197
3.39,-27.28,0.197
3.41,-27.10,0.197
3.43,-26.91,0.197
3.45,-26.73,0.197
3.46,-26.54,0.198
3.48,-26.36,0.198
3.50,-26.18,0.198
3.52,-25.99,0.198
3.54,-25.81,0.198
3.56,-25.63,0.198
3.58,-25.44,0.198
3.59,-25.26,0.198
3.61,-25.08,0.198
3.63,-24.89,0.198
3.65,-24.71,0.199
3.67,-24.53,0.199
3.69,-24.34,0.199
3.70,-24.16,0.199
3.72,-23.97,0.199
3.74,-23.79,0.199
3.76,-23.61,0.199
3.78,-23.42,0.199
3.79,-23.24,0.199
3.81,-23.06,0.199
3.83,-22.87,0.200
3.85,-22.69,0.200
3.87,-22.51,0.200
3.89,-22.32,0.200
3.91,-22.14,0.200
3.92,-21.96,0.200
3.94,-21.77,0.200
3.96,-21.59,0.200
3.98,-21.41,0.200
4.00,-21.22,0.200
4.01,-21.04,0.201
4.03,-20.85,0.201
4.05,-20.67,0.201
4.07,-20.49,0.201
4.09,-20.30,0.201
4.11,-20.12,0.201
4.13,-19.94,0.201
4.14,-19.75,0.201
4.16,-19.57,0.201
4.18,-19.39,0.201
4.20,-19.20,0.202
4.22,-19.02,0.202
4.24,-18.83,0.202
4.25,-18.65,0.202
4.27,-18.47,0.202
4.29,-18.29,0.202
4.31,-18.10,0.202
4.33,-17.92,0.202
4.35,-17.73,0.202
4.36,-17.55,0.203
4.38,-17.37,0.203
4.40,-17.18,0.203
4.42,-17.00,0.203
4.44,-16.82,0.203
4.45,-16.63,0.203
4.47,-16.45,0.203
4.49,-16.27,0.203
4.51,-16.08,0.203
4.53,-15.90,0.204
4.55,-15.72,0.204
4.56,-15.53,0.204
4.58,-15.35,0.204
4.60,-15.17,0.204
4.62,-14.98,0.204
4.64,-14.80,0.204
4.66,-14.62,0.204
4.68,-14.43,0.205
4.69,-14.25,0.205
4.71,-14.06,0.205
4.73,-13.88,0.205
4.75,-13.70,0.205
4.77,-13.51,0.205
4.79,-13.33,0.205
4.80,-13.15,0.205
4.82,-12.96,0.206
4.84,-12.78,0.206
4.86,-12.60,0.206
4.88,-12.41,0.206
4.90,-12.23,0.206
4.91,-12.04,0.206
4.93,-11.86,0.206
4.95,-11.68,0.206
4.97,-11.49,0.207
4.99,-11.31,0.207
5.00,-11.13,0.207
5.02,-10.94,0.207
5.04,-10.76,0.207
5.06,-10.58,0.207
5.08,-10.39,0.207
5.10,-10.21,0.207
5.11,-10.03,0.208
5.13,-9.84,0.208
5.15,-9.66,0.208
5.17,-9.48,0.208
5.19,-9.30,0.208
5.21,-9.11,0.208
5.23,-8.93,0.208
5.24,-8.75,0.208
5.26,-8.56,0.209
5.28,-8.38,0.209
5.30,-8.19,0.209
5.32,-8.01,0.209
5.34,-7.83,0.209
5.35,-7.64,0.209
5.37,-7.46,0.209
5.39,-7.28,0.210
5.41,-7.09,0.210
5.43,-6.91,0.210
5.45,-6.73,0.210
5.46,-6.54,0.210
5.48,-6.36,0.210
5.50,-6.17,0.211
5.52,-5.99,0.211
5.54,-5.81,0.211
5.55,-5.62,0.211
5.57,-5.44,0.211
5.59,-5.26,0.211
5.61,-5.07,0.212
5.63,-4.89,0.212
5.65,-4.71,0.212
5.66,-4.52,0.212
5.68,-4.34,0.212
5.70,-4.16,0.212
5.72,-3.97,0.213
5.74,-3.79,0.213
5.76,-3.61,0.213
5.78,-3.42,0.213
5.79,-3.24,0.213
5.81,-3.05,0.213
5.83,-2.87,0.214
5.85,-2.69,0.214
5.87,-2.50,0.214
5.89,-2.32,0.214
5.90,-2.14,0.214
5.92,-1.95,0.214
5.94,-1.77,0.215
5.96,-1.58,0.215
5.98,-1.40,0.215
6.00,-1.22,0.215
6.01,-1.03,0.215
6.03,-0.85,0.216
6.05,-0.67,0.216
6.07,-0.48,0.216
6.09,-0.30,0.216
6.10,-0.12,0.216
6.12,0.07,0.216
6.14,0.25,0.217
6.16,0.43,0.217
6.18,0.62,0.217
6.20,0.80,0.217
6.21,0.98,0.217
6.23,1.17,0.217
6.25,1.35,0.218
6.27,1.54,0.218
6.29,1.72,0.218
6.31,1.90,0.218
6.33,2.09,0.218
6.34,2.27,0.219
6.36,2.45,0.219
6.38,2.64,0.219
6.40,2.82,0.219
6.42,3.00,0.219
6.44,3.19,0.219
6.45,3.37,0.220
6.47,3.55,0.220
6.49,3.74,0.220
6.51,3.92,0.220
6.53,4.10,0.220
6.55,4.29,0.221
6.56,4.47,0.221
6.58,4.65,0.221
6.60,4.84,0.221
6.62,5.02,0.221
6.64,5.21,0.221
6.65,5.39,0.222
6.67,5.57,0.222
6.69,5.75,0.222
6.71,5.94,0.222
6.73,6.12,0.223
6.75,6.31,0.223
6.76,6.49,0.223
6.78,6.67,0.223
6.80,6.86,0.223
6.82,7.04,0.224
6.84,7.22,0.224
6.86,7.41,0.224
6.88,7.59,0.224
6.89,7.77,0.224
6.91,7.96,0.225
6.93,8.14,0.225
6.95,8.32,0.225
6.97,8.51,0.226
6.99,8.69,0.226
7.00,8.87,0.226
7.02,9.06,0.226
7.04,9.24,0.226
7.06,9.42,0.227
7.08,9.61,0.227
7.10,9.79,0.227
7.11,9.98,0.227
7.13,10.16,0.228
7.15,10.34,0.228
7.17,10.53,0.228
7.19,10.71,0.228
7.20,10.89,0.229
7.22,11.07,0.229
7.24,11.26,0.229
7.26,11.44,0.229
7.28,11.63,0.230
7.30,11.81,0.230
7.31,11.99,0.230
7.33,12.18,0.230
7.35,12.36,0.231
7.37,12.54,0.231
7.39,12.73,0.231
7.41,12.91,0.232
7.43,13.09,0.232
7.44,13.28,0.232
7.46,13.46,0.233
7.48,13.64,0.233
7.50,13.83,0.233
7.52,14.01,0.233
7.54,14.19,0.234
7.55,14.38,0.234
7.57,14.56,0.234
7.59,14.74,0.234
7.61,14.93,0.235
7.63,15.11,0.235
7.65,15.30,0.235
7.66,15.48,0.236
7.68,15.66,0.236
7.70,15.85,0.236
7.72,16.03,0.236
7.74,16.21,0.237
7.75,16.40,0.237
7.77,16.58,0.237
7.79,16.76,0.238
7.81,16.95,0.238
7.83,17.13,0.238
7.85,17.31,0.239
7.86,17.50,0.239
7.88,17.68,0.240
7.90,17.86,0.240
7.92,18.05,0.240
7.94,18.23,0.240
7.96,18.42,0.241
7.98,18.60,0.241
7.99,18.79,0.242
8.01,18.97,0.242
8.03,19.15,0.243
8.05,19.34,0.243
8.07,19.52,0.243
8.09,19.70,0.244
8.10,19.88,0.244
8.12,20.07,0.244
8.14,20.25,0.244
8.16,20.43,0.245
8.18,20.62,0.245
8.20,20.80,0.245
8.21,20.98,0.246
8.23,21.16,0.246
8.25,21.35,0.246
8.27,21.53,0.246
8.29,21.71,0.247
8.30,21.90,0.247
8.32,22.08,0.248
8.34,22.27,0.248
8.36,22.45,0.248
8.38,22.63,0.249
8.40,22.82,0.249
8.41,23.00,0.250
8.43,23.18,0.250
8.45,23.36,0.250
8.47,23.55,0.251
8.49,23.73,0.251
8.51,23.91,0.252
8.53,24.10,0.252
8.54,24.28,0.252
8.56,24.46,0.253
8.58,24.65,0.253
8.60,24.83,0.254
8.62,25.01,0.254
8.63,25.20,0.255
8.65,25.38,0.255
8.67,25.57,0.255
8.69,25.75,0.256
8.71,25.93,0.256
8.73,26.12,0.257
8.75,26.30,0.257
8.76,26.48,0.258
8.78,26.67,0.258
8.80,26.85,0.259
8.82,27.03,0.259
8.84,27.22,0.260
8.85,27.40,0.260
8.87,27.58,0.261
8.89,27.76,0.261
8.91,27.95,0.262
8.93,28.13,0.262
8.95,28.32,0.263
8.97,28.50,0.264
8.98,28.68,0.264
9.00,28.87,0.265
9.02,29.05,0.265
9.04,29.23,0.266
9.06,29.42,0.266
9.08,29.60,0.267
9.09,29.78,0.267
9.11,29.96,0.268
9.13,30.15,0.268
9.15,30.33,0.269
9.17,30.52,0.269
9.18,30.70,0.270
9.20,30.88,0.271
9.22,31.06,0.271
9.24,31.25,0.272
9.26,31.43,0.272
9.28,31.62,0.273
9.30,31.80,0.273
9.31,31.98,0.274
9.33,32.17,0.275
9.35,32.35,0.275
9.37,32.53,0.276
9.39,32.72,0.276
9.40,32.90,0.277
9.42,33.08,0.278
9.44,33.27,0.278
9.46,33.45,0.279
9.48,33.63,0.280
9.50,33.82,0.281
9.52,34.00,0.281
9.53,34.18,0.282
9.55,34.36,0.282
9.57,34.55,0.283
9.59,34.73,0.284
9.61,34.92,0.284
9.63,35.10,0.285
9.64,35.28,0.286
9.66,35.47,0.287
9.68,35.65,0.288
9.70,35.83,0.288
9.72,36.02,0.289
9.73,36.20,0.290
9.75,36.38,0.290
9.77,36.57,0.291
9.79,36.75,0.292
9.81,36.93,0.293
9.83,37.12,0.294
9.85,37.30,0.295
9.86,37.48,0.295
9.88,37.67,0.296
9.90,37.85,0.297
9.92,38.03,0.298
9.94,38.21,0.299
9.95,38.40,0.300
9.97,38.58,0.301
9.99,38.77,0.302
10.01,38.95,0.303
10.03,39.13,0.304
10.05,39.31,0.305
10.07,39.50,0.306
10.08,39.68,0.307
10.10,39.86,0.308
10.12,40.05,0.309
10.14,40.23,0.310
10.16,40.41,0.311
10.18,40.60,0.312
10.19,40.78,0.313
10.21,40.96,0.314
10.23,41.15,0.315
10.25,41.33,0.316
10.27,41.51,0.317
10.28,41.69,0.318
10.30,41.88,0.319
10.32,42.06,0.321
10.34,42.24,0.322
10.36,42.43,0.323
10.38,42.61,0.325
10.40,42.79,0.326
10.41,42.98,0.327
10.43,43.16,0.328
10.45,43.34,0.329
10.47,43.53,0.331
10.49,43.71,0.332
10.50,43.89,0.334
10.52,44.08,0.336
10.54,44.26,0.337
10.56,44.44,0.339
10.58,44.62,0.340
10.60,44.81,0.342
10.62,44.99,0.344
10.63,45.17,0.345
10.65,45.36,0.347
10.67,45.54,0.349
10.69,45.72,0.350
10.71,45.91,0.351
10.73,46.09,0.353
10.74,46.27,0.355
10.76,46.46,0.356
10.78,46.64,0.359
10.80,46.82,0.360
10.82,47.00,0.362
10.83,47.19,0.364
10.85,47.37,0.367
10.87,47.55,0.368
10.89,47.74,0.371
10.91,47.92,0.373
10.93,48.10,0.375
10.95,48.28,0.377
10.96,48.47,0.379
10.98,48.65,0.381
11.00,48.83,0.383
11.02,49.02,0.386
11.04,49.20,0.389
11.05,49.38,0.391
11.07,49.56,0.394
11.09,49.75,0.396
11.11,49.93,0.398
11.13,50.11,0.401
11.15,50.29,0.403
11.17,50.48,0.406
11.18,50.66,0.408
11.20,50.84,0.411
11.22,51.03,0.413
11.24,51.21,0.417
11.26,51.39,0.418
11.28,51.57,0.422
11.29,51.76,0.423
11.31,51.94,0.425
11.33,52.12,0.427
11.35,52.30,0.430
11.37,52.49,0.432
11.38,52.67,0.433
11.40,52.85,0.435
11.42,53.03,0.436
11.44,53.22,0.438
11.46,53.40,0.439
11.48,53.58,0.440
11.50,53.77,0.441
11.51,53.95,0.442
11.53,54.13,0.442
11.55,54.32,0.443
11.57,54.50,0.443
11.59,54.68,0.443
11.60,54.87,0.444
11.62,55.05,0.444
11.64,55.23,0.444
11.66,55.42,0.445
11.68,55.60,0.445
11.70,55.78,0.445
11.72,55.97,0.446
11.73,56.15,0.446
11.75,56.33,0.446
11.77,56.52,0.447
11.79,56.70,0.447
11.81,56.88,0.447
11.83,57.07,0.447
11.84,57.25,0.448
11.86,57.43,0.448
11.88,57.62,0.448
11.90,57.80,0.449
11.92,57.98,0.449
11.93,58.17,0.450
11.95,58.35,0.450
11.97,58.53,0.451
11.99,58.72,0.451
12.01,58.90,0.453
12.03,59.08,0.454
12.05,59.27,0.454
12.06,59.45,0.456
12.08,59.63,0.457
12.10,59.82,0.459
12.12,60.00,0.460
12.14,60.18,0.462
12.15,60.36,0.464
12.17,60.55,0.465
12.19,60.73,0.468
12.21,60.91,0.470
12.23,61.10,0.472
12.25,61.28,0.473
12.27,61.46,0.476
12.28,61.65,0.477
12.30,61.83,0.479
12.32,62.01,0.481
12.34,62.20,0.483
12.36,62.38,0.485
12.38,62.56,0.487
12.39,62.75,0.489
12.41,62.93,0.491
12.43,63.11,0.493
12.45,63.30,0.494
12.47,63.48,0.495
12.48,63.66,0.497
12.50,63.84,0.498
12.52,64.03,0.500
12.54,64.21,0.502
12.56,64.39,0.504
12.58,64.58,0.505
12.60,64.76,0.507
12.61,64.94,0.508
12.63,65.12,0.510
12.65,65.31,0.512
12.67,65.49,0.514
12.69,65.67,0.516
12.70,65.86,0.518
12.72,66.04,0.520
12.74,66.22,0.521
12.76,66.40,0.523
12.78,66.59,0.524
12.80,66.77,0.526
12.82,66.95,0.528
12.83,67.14,0.530
12.85,67.32,0.531
12.87,67.50,0.533
12.89,67.68,0.535
12.91,67.87,0.537
12.93,68.05,0.538
12.94,68.23,0.540
12.96,68.42,0.541
12.98,68.60,0.543
13.00,68.78,0.544
13.02,68.97,0.546
13.03,69.15,0.547
13.05,69.33,0.549
13.07,69.51,0.551
13.09,69.70,0.552
13.11,69.88,0.554
13.13,70.06,0.556
13.15,70.25,0.558
13.16,70.43,0.560
13.18,70.61,0.561
13.20,70.80,0.563
13.22,70.98,0.564
13.24,71.16,0.566
13.25,71.34,0.567
13.27,71.53,0.569
13.29,71.71,0.572
13.31,71.89,0.573
13.33,72.08,0.575
13.35,72.26,0.577
13.37,72.44,0.578
13.38,72.63,0.579
13.40,72.81,0.581
13.42,72.99,0.582
13.44,73.17,0.584
13.46,73.36,0.586
13.48,73.54,0.587
13.49,73.72,0.588
13.51,73.91,0.590
13.53,74.09,0.592
13.55,74.27,0.593
13.57,74.46,0.595
13.58,74.64,0.596
13.60,74.82,0.598
13.62,75.00,0.599
13.64,75.19,0.601
13.66,75.37,0.603
13.68,75.55,0.604
13.70,75.73,0.606
13.71,75.92,0.608
13.73,76.10,0.609
13.75,76.28,0.611
13.77,76.47,0.613
13.79,76.65,0.614
13.80,76.83,0.616
13.82,77.02,0.618
13.84,77.20,0.619
13.86,77.38,0.620
13.88,77.57,0.621
13.90,77.75,0.623
13.92,77.93,0.624
13.93,78.12,0.626
13.95,78.30,0.627
13.97,78.48,0.629
13.99,78.67,0.630
14.01,78.85,0.631
14.03,79.03,0.633
14.04,79.21,0.634
14.06,79.40,0.636
14.08,79.58,0.637
14.10,79.76,0.638
14.12,79.95,0.640
14.13,80.13,0.641
14.15,80.31,0.642
14.17,80.50,0.644
14.19,80.68,0.645
14.21,80.86,0.646
14.23,81.04,0.647
14.25,81.23,0.649
14.26,81.41,0.650
14.28,81.59,0.652
14.30,81.78,0.653
14.32,81.96,0.654
14.34,82.14,0.656
14.35,82.33,0.658
14.37,82.51,0.658
14.39,82.69,0.659
14.41,82.88,0.661
14.43,83.06,0.662
14.45,83.24,0.663
14.47,83.43,0.664
14.48,83.61,0.665
14.50,83.79,0.666
14.52,83.97,0.666
14.54,84.16,0.668
14.56,84.34,0.669
14.58,84.52,0.670
14.59,84.71,0.671
14.61,84.89,0.672
14.63,85.07,0.673
14.65,85.25,0.675
14.67,85.44,0.676
14.68,85.62,0.677
14.70,85.80,0.678
14.72,85.99,0.679
14.74,86.17,0.680
14.76,86.35,0.681
14.78,86.54,0.682
14.80,86.72,0.682
14.81,86.90,0.684
14.83,87.09,0.685
14.85,87.27,0.686
14.87,87.45,0.686
14.89,87.64,0.687
14.90,87.82,0.688
14.92,88.00,0.689
14.94,88.19,0.690
14.96,88.37,0.691
14.98,88.55,0.692
15.00,88.74,0.692
15.02,88.92,0.693
15.03,89.10,0.694
15.05,89.29,0.695
15.07,89.47,0.696
15.09,89.65,0.697
15.11,89.84,0.697
15.13,90.02,0.698
15.14,90.20,0.698
15.16,90.39,0.699
15.18,90.57,0.700
15.20,90.75,0.701
15.22,90.94,0.701
15.23,91.12,0.702
15.25,91.31,0.703
15.27,91.49,0.703
15.29,91.67,0.704
15.31,91.86,0.704
15.33,92.04,0.705
15.35,92.22,0.705
15.36,92.41,0.706
15.38,92.59,0.706
15.40,92.77,0.707
15.42,92.96,0.707
15.44,93.14,0.708
15.45,93.32,0.708
15.47,93.51,0.709
15.49,93.69,0.709
15.51,93.87,0.709
15.53,94.06,0.710
15.55,94.24,0.710
15.57,94.42,0.711
15.58,94.61,0.711
15.60,94.79,0.711
15.62,94.97,0.712
15.64,95.16,0.712
15.66,95.34,0.712
15.68,95.52,0.712
15.69,95.71,0.713
15.71,95.89,0.713
15.73,96.07,0.713
15.75,96.26,0.713
15.77,96.44,0.714
15.78,96.62,0.714
15.80,96.81,0.714
15.82,96.99,0.714
15.84,97.17,0.714
15.86,97.36,0.714
15.88,97.54,0.715
15.90,97.72,0.715
15.91,97.91,0.715
15.93,98.09,0.715
15.95,98.28,0.715
15.97,98.46,0.715
15.99,98.64,0.715
16.00,98.83,0.715
16.02,99.01,0.715
16.04,99.19,0.715
16.06,99.38,0.715
16.08,99.56,0.715
16.10,99.75,0.715
16.12,99.93,0.715
16.13,100.11,0.714
16.15,100.30,0.714
16.17,100.48,0.714
16.19,100.66,0.714
16.21,100.85,0.713
16.23,101.03,0.713
16.24,101.22,0.713
16.26,101.40,0.712
16.28,101.58,0.712
16.30,101.77,0.712
16.32,101.95,0.711
16.33,102.14,0.711
16.35,102.32,0.711
16.37,102.50,0.710
16.39,102.69,0.710
16.41,102.87,0.709
16.43,103.05,0.709
16.45,103.24,0.708
16.46,103.42,0.707
16.48,103.61,0.706
16.50,103.79,0.706
16.52,103.97,0.705
16.54,104.16,0.704
16.55,104.34,0.703
16.57,104.53,0.702
16.59,104.71,0.702
16.61,104.89,0.701
16.63,105.08,0.700
16.65,105.26,0.699
16.67,105.44,0.698
16.68,105.63,0.697
16.70,105.81,0.696
16.72,106.00,0.695
16.74,106.18,0.694
16.76,106.36,0.693
16.78,106.55,0.692
16.79,106.73,0.690
16.81,106.92,0.690
16.83,107.10,0.689
16.85,107.28,0.688
16.87,107.47,0.687
16.88,107.65,0.685
16.90,107.84,0.684
16.92,108.02,0.683
16.94,108.20,0.682
16.96,108.39,0.681
16.98,108.57,0.679
17.00,108.75,0.678
17.01,108.94,0.676
17.03,109.12,0.675
17.05,109.31,0.673
17.07,109.49,0.671
17.09,109.67,0.670
17.11,109.86,0.669
17.12,110.04,0.668
17.14,110.22,0.666
17.16,110.41,0.665
17.18,110.59,0.664
17.20,110.78,0.662
17.22,110.96,0.661
17.23,111.14,0.660
17.25,111.33,0.658
17.27,111.51,0.657
17.29,111.70,0.656
17.31,111.88,0.654
17.33,112.06,0.653
17.34,112.25,0.651
17.36,112.43,0.649
17.38,112.62,0.648
17.40,112.80,0.647
17.42,112.99,0.646
17.43,113.17,0.643
17.45,113.35,0.641
17.47,113.54,0.640
17.49,113.72,0.638
17.51,113.90,0.636
17.53,114.09,0.635
17.54,114.27,0.633
17.56,114.46,0.632
17.58,114.64,0.631
17.60,114.82,0.629
17.62,115.01,0.627
17.64,115.19,0.626
17.66,115.38,0.624
17.67,115.56,0.623
17.69,115.74,0.621
17.71,115.93,0.620
17.73,116.11,0.618
17.75,116.30,0.616
17.77,116.48,0.615
17.78,116.67,0.612
17.80,116.85,0.611
17.82,117.03,0.609
17.84,117.22,0.607
17.86,117.40,0.606
17.88,117.59,0.604
17.89,117.77,0.603
17.91,117.96,0.600
17.93,118.14,0.599
17.95,118.32,0.597
17.97,118.51,0.595
17.98,118.69,0.593
18.00,118.88,0.592
18.02,119.06,0.590
18.04,119.24,0.588
18.06,119.43,0.586
18.08,119.61,0.585
18.09,119.79,0.583
18.11,119.98,0.582
18.13,120.16,0.580
18.15,120.35,0.579
18.17,120.53,0.577
18.19,120.72,0.575
18.21,120.90,0.574
18.22,121.08,0.572
18.24,121.27,0.570
18.26,121.45,0.568
18.28,121.64,0.566
18.30,121.82,0.564
18.32,122.01,0.562
18.33,122.19,0.560
18.35,122.37,0.559
18.37,122.56,0.557
18.39,122.74,0.555
18.41,122.92,0.554
18.43,123.11,0.552
18.44,123.29,0.551
18.46,123.48,0.549
18.48,123.66,0.547
18.50,123.84,0.545
18.52,124.03,0.544
18.53,124.21,0.542
18.55,124.40,0.540
18.57,124.58,0.538
18.59,124.77,0.537
18.61,124.95,0.535
18.63,125.13,0.534
18.64,125.32,0.532
18.66,125.50,0.530
18.68,125.69,0.529
18.70,125.87,0.526
18.72,126.05,0.525
18.74,126.24,0.523
18.76,126.42,0.522
18.77,126.61,0.520
18.79,126.79,0.518
18.81,126.97,0.516
18.83,127.16,0.514
18.85,127.34,0.513
18.87,127.53,0.511
18.88,127.71,0.509
18.90,127.89,0.508
18.92,128.08,0.506
18.94,128.26,0.504
18.96,128.45,0.503
18.98,128.63,0.502
18.99,128.81,0.500
19.01,129.00,0.499
19.03,129.18,0.497
19.05,129.37,0.495
19.07,129.55,0.494
19.08,129.74,0.492
19.10,129.92,0.489
19.12,130.10,0.488
19.14,130.29,0.486
19.16,130.47,0.485
19.18,130.66,0.483
19.19,130.84,0.482
19.21,131.02,0.480
19.23,131.21,0.479
19.25,131.39,0.477
19.27,131.58,0.475
19.29,131.76,0.474
19.31,131.94,0.472
19.32,132.13,0.470
19.34,132.31,0.468
19.36,132.50,0.467
19.38,132.68,0.466
19.40,132.86,0.464
19.42,133.05,0.463
19.43,133.23,0.461
19.45,133.42,0.460
19.47,133.60,0.458
19.49,133.78,0.457
19.51,133.97,0.455
19.53,134.15,0.453
19.54,134.34,0.452
19.56,134.52,0.451
19.58,134.70,0.450
19.60,134.89,0.448
19.62,135.07,0.447
19.63,135.26,0.445
19.65,135.44,0.443
19.67,135.62,0.442
19.69,135.81,0.440
19.71,135.99,0.439
19.73,136.18,0.438
19.74,136.36,0.437
19.76,136.54,0.435
19.78,136.73,0.434
19.80,136.91,0.433
19.82,137.09,0.432
19.84,137.28,0.430
19.86,137.46,0.429
19.87,137.65,0.428
19.89,137.83,0.427
19.91,138.01,0.425
19.93,138.20,0.424
19.95,138.38,0.423
19.97,138.57,0.421
19.98,138.75,0.419
20.00,138.93,0.418
20.02,139.12,0.416
20.04,139.30,0.416
20.06,139.49,0.415
20.08,139.67,0.414
20.09,139.85,0.413
20.11,140.04,0.411
20.13,140.22,0.410
20.15,140.40,0.409
20.17,140.59,0.408
20.18,140.77,0.407
20.20,140.96,0.406
20.22,141.14,0.404
20.24,141.32,0.403
20.26,141.51,0.402
20.28,141.69,0.400
20.29,141.88,0.399
20.31,142.06,0.398
20.33,142.24,0.397
20.35,142.43,0.396
20.37,142.61,0.396
20.39,142.80,0.394
20.41,142.98,0.394
20.42,143.16,0.393
20.44,143.35,0.392
20.46,143.53,0.391
20.48,143.71,0.390
20.50,143.90,0.389
20.52,144.08,0.388
20.53,144.27,0.387
20.55,144.45,0.386
20.57,144.63,0.385
20.59,144.82,0.384
20.61,145.00,0.383
20.63,145.19,0.382
20.64,145.37,0.381
20.66,145.55,0.380
20.68,145.74,0.379
20.70,145.92,0.378
20.72,146.11,0.378
20.73,146.29,0.377
20.75,146.47,0.376
20.77,146.66,0.375
20.79,146.84,0.373
20.81,147.02,0.372
20.83,147.21,0.371
20.84,147.39,0.371
20.86,147.58,0.370
20.88,147.76,0.369
20.90,147.94,0.369
20.92,148.13,0.368
20.94,148.31,0.367
20.96,148.49,0.367
20.97,148.68,0.366
20.99,148.86,0.365
21.01,149.04,0.365
21.03,149.23,0.364
21.05,149.41,0.363
21.07,149.60,0.362
21.08,149.78,0.361
21.10,149.96,0.361
21.12,150.15,0.360
21.14,150.33,0.359
21.16,150.51,0.359
21.18,150.70,0.358
21.19,150.88,0.358
21.21,151.07,0.357
21.23,151.25,0.356
21.25,151.43,0.356
21.27,151.62,0.355
21.28,151.80,0.355
21.30,151.98,0.354
21.32,152.17,0.353
21.34,152.35,0.353
21.36,152.54,0.352
21.38,152.72,0.351
21.39,152.90,0.350
21.41,153.09,0.350
21.43,153.27,0.349
21.45,153.45,0.349
21.47,153.64,0.348
21.49,153.82,0.347
21.51,154.01,0.347
21.52,154.19,0.346
21.54,154.37,0.346
21.56,154.56,0.345
21.58,154.74,0.345
21.60,154.92,0.344
21.62,155.11,0.344
21.63,155.29,0.343
21.65,155.47,0.343
21.67,155.66,0.342
21.69,155.84,0.342
21.71,156.02,0.341
21.73,156.21,0.341
21.74,156.39,0.340
21.76,156.58,0.340
21.78,156.76,0.340
21.80,156.94,0.339
21.82,157.13,0.339
21.83,157.31,0.338
21.85,157.49,0.338
21.87,157.68,0.337
21.89,157.86,0.337
21.91,158.04,0.336
21.93,158.23,0.336
21.94,158.41,0.336
21.96,158.60,0.335
21.98,158.78,0.335
22.00,158.96,0.334
22.02,159.15,0.334
22.04,159.33,0.334
22.06,159.51,0.333
22.07,159.70,0.333
22.09,159.88,0.333
22.11,160.06,0.332
22.13,160.25,0.332
22.15,160.43,0.332
22.17,160.61,0.331
22.18,160.80,0.331
22.20,160.98,0.331
22.22,161.17,0.331
22.24,161.35,0.330
22.26,161.53,0.330
22.28,161.72,0.330
22.29,161.90,0.329
22.31,162.08,0.329
22.33,162.27,0.329
22.35,162.45,0.329
22.37,162.63,0.328
22.38,162.82,0.328
22.40,163.00,0.328
22.42,163.18,0.328
22.44,163.37,0.328
22.46,163.55,0.327
22.48,163.73,0.327
22.49,163.92,0.327
22.51,164.10,0.327
22.53,164.28,0.327
22.55,164.47,0.326
22.57,164.65,0.326
22.59,164.84,0.326
22.61,165.02,0.326
22.62,165.20,0.326
22.64,165.39,0.326
22.66,165.57,0.326
22.68,165.75,0.326
22.70,165.94,0.325
22.72,166.12,0.325
22.73,166.30,0.325
22.75,166.49,0.325
22.77,166.67,0.325
22.79,166.85,0.325
22.81,167.04,0.325
22.83,167.22,0.325
22.84,167.40,0.325
22.86,167.59,0.324
22.88,167.77,0.324
22.90,167.95,0.324
22.92,168.14,0.324
22.93,168.32,0.324
22.95,168.50,0.324
22.97,168.69,0.324
22.99,168.87,0.324
23.01,169.06,0.324
23.03,169.24,0.324
23.04,169.42,0.324
23.06,169.61,0.324
23.08,169.79,0.324
23.10,169.97,0.324
23.12,170.16,0.324
23.14,170.34,0.324
23.16,170.52,0.324
23.17,170.71,0.324
23.19,170.89,0.324
23.21,171.07,0.324
23.23,171.26,0.324
23.25,171.44,0.324
23.27,171.62,0.324
23.28,171.81,0.324
23.30,171.99,0.324
23.32,172.17,0.324
23.34,172.36,0.324
23.36,172.54,0.324
23.38,172.73,0.324
23.39,172.91,0.325
23.41,173.09,0.325
23.43,173.28,0.325
23.45,173.46,0.325
23.47,173.64,0.325
23.48,173.83,0.325
23.50,174.01,0.325
23.52,174.19,0.325
23.54,174.38,0.325
23.56,174.56,0.325
23.58,174.74,0.325
23.59,174.93,0.325
23.61,175.11,0.325
23.63,175.29,0.325
23.65,175.48,0.325
23.67,175.66,0.325
23.69,175.84,0.325
23.71,176.03,0.325
23.72,176.21,0.326
23.74,176.40,0.326
23.76,176.58,0.326
23.78,176.76,0.326
23.80,176.95,0.326
23.82,177.13,0.326
23.83,177.31,0.326
23.85,177.50,0.326
23.87,177.68,0.326
23.89,177.86,0.326
23.91,178.05,0.326
23.93,178.23,0.327
23.94,178.41,0.327
23.96,178.60,0.327
23.98,178.78,0.327
24.00,178.96,0.327
24.02,179.15,0.327
24.03,179.33,0.327
24.05,179.51,0.327
24.07,179.70,0.327
24.09,179.88,0.327
24.11,180.06,0.327
24.13,180.25,0.327
24.14,180.43,0.328
24.16,180.62,0.328
24.18,180.80,0.328
24.20,180.98,0.328
24.22,181.17,0.328
24.24,181.35,0.328
24.26,181.53,0.328
24.27,181.71,0.328
24.29,181.90,0.328
24.31,182.08,0.328
24.33,182.26,0.329
24.35,182.45,0.329
24.37,182.63,0.329
24.38,182.81,0.329
24.40,183.00,0.329
24.42,183.18,0.329
24.44,183.37,0.329
24.46,183.55,0.329
24.48,183.73,0.330
24.49,183.92,0.330
24.51,184.10,0.330
24.53,184.28,0.330
24.55,184.47,0.330
24.57,184.65,0.330
24.58,184.83,0.331
24.60,185.02,0.331
24.62,185.20,0.331
24.64,185.38,0.331
24.66,185.57,0.331
24.68,185.75,0.331
24.69,185.93,0.331
24.71,186.12,0.331
24.73,186.30,0.331
24.75,186.48,0.331
24.77,186.67,0.331
24.79,186.85,0.332
24.81,187.03,0.332
24.82,187.22,0.332
24.84,187.40,0.332
24.86,187.58,0.332
24.88,187.77,0.332
24.90,187.95,0.332
24.92,188.14,0.332
24.93,188.32,0.333
24.95,188.50,0.333
24.97,188.69,0.333
24.99,188.87,0.333
25.01,189.05,0.333
25.03,189.24,0.333
25.04,189.42,0.334
25.06,189.60,0.334
25.08,189.79,0.334
25.10,189.97,0.334
25.12,190.15,0.334
25.13,190.34,0.334
25.15,190.52,0.334
25.17,190.70,0.334
25.19,190.89,0.334
25.21,191.07,0.335
25.23,191.25,0.335
25.24,191.44,0.335
25.26,191.62,0.335
25.28,191.80,0.335
25.30,191.99,0.335
25.32,192.17,0.335
25.34,192.35,0.335
25.36,192.54,0.335
25.37,192.72,0.336
25.39,192.90,0.336
25.41,193.09,0.336
25.43,193.27,0.336
25.45,193.45,0.336
25.47,193.64,0.336
25.48,193.82,0.336
25.50,194.01,0.337
25.52,194.19,0.337
25.54,194.37,0.337
25.56,194.56,0.337
25.58,194.74,0.337
25.59,194.92,0.337
25.61,195.11,0.337
25.63,195.29,0.337
25.65,195.47,0.337
25.67,195.66,0.338
25.68,195.84,0.338
25.70,196.02,0.338
25.72,196.21,0.338
25.74,196.39,0.338
25.76,196.57,0.338
25.78,196.76,0.338
25.79,196.94,0.338
25.81,197.12,0.338
25.83,197.31,0.339
25.85,197.49,0.339
25.87,197.68,0.339
25.89,197.86,0.339
25.91,198.04,0.339
25.92,198.22,0.339
25.94,198.41,
25.96,198.59,
25.98,198.77,
25.99,,

[step]
Ramp 10.00 °C/min to -60.00 °C
Time,Temperature,Heat Flow (Normalized)
min,°C,W/g
27.99,200.16,-0.034
28.01,200.16,-0.034
28.03,200.15,-0.034
28.05,200.14,-0.034
28.07,200.12,-0.036
28.08,200.07,-0.061
28.10,199.99,-0.094
28.12,199.89,-0.139
28.14,199.77,-0.188
28.16,199.63,-0.236
28.18,199.48,-0.276
28.19,199.32,-0.309
28.21,199.16,-0.330
28.23,198.99,-0.348
28.25,198.82,-0.361
28.27,198.64,-0.369
28.29,198.47,-0.376
28.31,198.29,-0.380
28.32,198.11,-0.383
28.34,197.93,-0.386
28.36,197.75,-0.389
28.38,197.57,-0.391
28.40,197.39,-0.392
28.42,197.21,-0.393
28.43,197.03,-0.394
28.45,196.85,-0.394
28.47,196.67,-0.395
28.49,196.49,-0.395
28.51,196.30,-0.395
28.53,196.12,-0.395
28.54,195.94,-0.396
28.56,195.76,-0.396
28.58,195.58,-0.396
28.60,195.39,-0.396
28.62,195.21,-0.396
28.63,195.03,-0.397
28.65,194.85,-0.397
28.67,194.67,-0.397
28.69,194.48,-0.397
28.71,194.30,-0.397
28.73,194.12,-0.397
28.74,193.94,-0.397
28.76,193.76,-0.398
28.78,193.57,-0.398
28.80,193.39,-0.398
28.82,193.21,-0.398
28.84,193.02,-0.398
28.86,192.84,-0.398
28.87,192.66,-0.398
28.89,192.48,-0.398
28.91,192.30,-0.398
28.93,192.11,-0.398
28.95,191.93,-0.398
28.97,191.75,-0.398
28.98,191.57,-0.398
29.00,191.38,-0.398
29.02,191.20,-0.399
29.04,191.02,-0.399
29.06,190.84,-0.399
29.08,190.65,-0.399
29.09,190.47,-0.399
29.11,190.29,-0.399
29.13,190.10,-0.399
29.15,189.92,-0.399
29.17,189.74,-0.399
29.18,189.55,-0.399
29.20,189.37,-0.399
29.22,189.19,-0.399
29.24,189.01,-0.399
29.26,188.82,-0.399
29.28,188.64,-0.399
29.29,188.46,-0.399
29.31,188.27,-0.399
29.33,188.09,-0.398
29.35,187.91,-0.398
29.37,187.73,-0.398
29.39,187.54,-0.398
29.41,187.36,-0.398
29.42,187.18,-0.398
29.44,186.99,-0.398
29.46,186.81,-0.398
29.48,186.63,-0.398
29.50,186.44,-0.398
29.52,186.26,-0.398
29.53,186.08,-0.398
29.55,185.89,-0.398
29.57,185.71,-0.398
29.59,185.53,-0.398
29.61,185.35,-0.398
29.63,185.16,-0.397
29.64,184.98,-0.397
29.66,184.80,-0.397
29.68,184.61,-0.397
29.70,184.43,-0.397
29.72,184.25,-0.397
29.73,184.06,-0.397
29.75,183.88,-0.397
29.77,183.70,-0.397
29.79,183.51,-0.397
29.81,183.33,-0.397
29.83,183.15,-0.397
29.84,182.96,-0.397
29.86,182.78,-0.396
29.88,182.60,-0.396
29.90,182.42,-0.396
29.92,182.23,-0.396
29.94,182.05,-0.396
29.96,181.87,-0.396
29.97,181.68,-0.396
29.99,181.50,-0.396
30.01,181.32,-0.396
30.03,181.13,-0.396
30.05,180.95,-0.396
30.07,180.77,-0.395
30.08,180.58,-0.395
30.10,180.40,-0.395
30.12,180.22,-0.395
30.14,180.04,-0.395
30.16,179.85,-0.395
30.18,179.67,-0.395
30.19,179.49,-0.395
30.21,179.30,-0.395
30.23,179.12,-0.395
30.25,178.93,-0.395
30.27,178.75,-0.395
30.28,178.57,-0.395
30.30,178.39,-0.394
30.32,178.20,-0.394
30.34,178.02,-0.394
30.36,177.84,-0.394
30.38,177.65,-0.394
30.39,177.47,-0.394
30.41,177.29,-0.394
30.43,177.10,-0.394
30.45,176.92,-0.394
30.47,176.74,-0.394
30.49,176.55,-0.394
30.51,176.37,-0.394
30.52,176.18,-0.394
30.54,176.00,-0.393
30.56,175.82,-0.393
30.58,175.64,-0.393
30.60,175.45,-0.393
30.62,175.27,-0.393
30.63,175.08,-0.393
30.65,174.90,-0.393
30.67,174.72,-0.393
30.69,174.54,-0.393
30.71,174.35,-0.393
30.73,174.17,-0.393
30.74,173.99,-0.392
30.76,173.80,-0.392
30.78,173.62,-0.392
30.80,173.44,-0.392
30.82,173.25,-0.392
30.83,173.07,-0.392
30.85,172.89,-0.392
30.87,172.70,-0.392
30.89,172.52,-0.392
30.91,172.34,-0.391
30.93,172.15,-0.391
30.94,171.97,-0.391
30.96,171.79,-0.391
30.98,171.60,-0.391
31.00,171.42,-0.391
31.02,171.24,-0.391
31.04,171.05,-0.391
31.06,170.87,-0.391
31.07,170.69,-0.391
31.09,170.50,-0.391
31.11,170.32,-0.390
31.13,170.14,-0.390
31.15,169.95,-0.390
31.17,169.77,-0.390
31.18,169.59,-0.390
31.20,169.40,-0.390
31.22,169.22,-0.390
31.24,169.04,-0.390
31.26,168.85,-0.389
31.28,168.67,-0.389
31.29,168.49,-0.389
31.31,168.30,-0.389
31.33,168.12,-0.389
31.35,167.94,-0.389
31.37,167.75,-0.389
31.38,167.57,-0.389
31.40,167.39,-0.389
31.42,167.20,-0.389
31.44,167.02,-0.389
31.46,166.84,-0.389
31.48,166.65,-0.388
31.49,166.47,-0.388
31.51,166.29,-0.388
31.53,166.10,-0.388
31.55,165.92,-0.388
31.57,165.74,-0.388
31.59,165.56,-0.388
31.61,165.37,-0.388
31.62,165.19,-0.388
31.64,165.00,-0.387
31.66,164.82,-0.387
31.68,164.64,-0.387
31.70,164.46,-0.387
31.72,164.27,-0.387
31.73,164.09,-0.387
31.75,163.91,-0.387
31.77,163.72,-0.387
31.79,163.54,-0.387
31.81,163.36,-0.386
31.83,163.17,-0.386
31.84,162.99,-0.386
31.86,162.81,-0.386
31.88,162.62,-0.386
31.90,162.44,-0.386
31.92,162.26,-0.386
31.93,162.07,-0.386
31.95,161.89,-0.386
31.97,161.70,-0.386
31.99,161.52,-0.386
32.01,161.34,-0.386
32.03,161.15,-0.386
32.04,160.97,-0.386
32.06,160.79,-0.385
32.08,160.60,-0.385
32.10,160.42,-0.385
32.12,160.24,-0.385
32.14,160.06,-0.385
32.16,159.87,-0.385
32.17,159.69,-0.385
32.19,159.51,-0.384
32.21,159.32,-0.384
32.23,159.14,-0.384
32.25,158.96,-0.384
32.27,158.77,-0.384
32.28,158.59,-0.384
32.30,158.41,-0.384
32.32,158.22,-0.384
32.34,158.04,-0.384
32.36,157.86,-0.384
32.38,157.67,-0.384
32.39,157.49,-0.384
32.41,157.31,-0.384
32.43,157.12,-0.384
32.45,156.94,-0.383
32.47,156.76,-0.383
32.48,156.57,-0.383
32.50,156.39,-0.383
32.52,156.21,-0.383
32.54,156.02,-0.383
32.56,155.84,-0.383
32.58,155.66,-0.383
32.59,155.47,-0.383
32.61,155.29,-0.383
32.63,155.11,-0.382
32.65,154.92,-0.382
32.67,154.74,-0.382
32.69,154.56,-0.382
32.71,154.37,-0.382
32.72,154.19,-0.382
32.74,154.01,-0.382
32.76,153.83,-0.382
32.78,153.64,-0.382
32.80,153.46,-0.381
32.82,153.27,-0.381
32.83,153.09,-0.381
32.85,152.91,-0.381
32.87,152.73,-0.381
32.89,152.54,-0.381
32.91,152.36,-0.381
32.93,152.18,-0.381
32.94,151.99,-0.381
32.96,151.81,-0.381
32.98,151.63,-0.381
33.00,151.44,-0.381
33.02,151.26,-0.381
33.03,151.08,-0.380
33.05,150.89,-0.380
33.07,150.71,-0.380
33.09,150.53,-0.380
33.11,150.34,-0.380
33.13,150.16,-0.380
33.14,149.98,-0.380
33.16,149.79,-0.380
33.18,149.61,-0.380
33.20,149.43,-0.380
33.22,149.24,-0.380
33.24,149.06,-0.379
33.26,148.88,-0.379
33.27,148.69,-0.379
33.29,148.51,-0.379
33.31,148.33,-0.379
33.33,148.14,-0.379
33.35,147.96,-0.379
33.37,147.78,-0.379
33.38,147.59,-0.379
33.40,147.41,-0.379
33.42,147.23,-0.379
33.44,147.04,-0.379
33.46,146.86,-0.378
33.48,146.68,-0.378
33.49,146.49,-0.378
33.51,146.31,-0.378
33.53,146.13,-0.378
33.55,145.94,-0.378
33.57,145.76,-0.378
33.58,145.58,-0.378
33.60,145.39,-0.378
33.62,145.21,-0.378
33.64,145.03,-0.378
33.66,144.84,-0.377
33.68,144.66,-0.377
33.69,144.48,-0.377
33.71,144.29,-0.377
33.73,144.11,-0.377
33.75,143.93,-0.377
33.77,143.74,-0.377
33.79,143.56,-0.377
33.81,143.38,-0.377
33.82,143.20,-0.376
33.84,143.01,-0.376
33.86,142.83,-0.376
33.88,142.64,-0.376
33.90,142.46,-0.376
33.92,142.28,-0.376
33.93,142.09,-0.376
33.95,141.91,-0.376
33.97,141.73,-0.376
33.99,141.54,-0.376
34.01,141.36,-0.376
34.03,141.18,-0.376
34.04,141.00,-0.375
34.06,140.81,-0.375
34.08,140.63,-0.375
34.10,140.45,-0.375
34.12,140.26,-0.375
34.14,140.08,-0.375
34.15,139.90,-0.375
34.17,139.71,-0.375
34.19,139.53,-0.375
34.21,139.35,-0.374
34.23,139.16,-0.374
34.24,138.98,-0.374
34.26,138.80,-0.374
34.28,138.61,-0.374
34.30,138.43,-0.374
34.32,138.25,-0.374
34.34,138.06,-0.374
34.36,137.88,-0.374
34.37,137.70,-0.374
34.39,137.51,-0.374
34.41,137.33,-0.374
34.43,137.15,-0.374
34.45,136.96,-0.373
34.46,136.78,-0.373
34.48,136.60,-0.373
34.50,136.41,-0.373
34.52,136.23,-0.373
34.54,136.05,-0.373
34.56,135.86,-0.373
34.58,135.68,-0.373
34.59,135.50,-0.373
34.61,135.31,-0.373
34.63,135.13,-0.373
34.65,134.95,-0.372
34.67,134.76,-0.372
34.69,134.58,-0.372
34.70,134.40,-0.372
34.72,134.21,-0.372
34.74,134.03,-0.372
34.76,133.84,-0.372
34.78,133.66,-0.372
34.79,133.48,-0.372
34.81,133.29,-0.372
34.83,133.11,-0.372
34.85,132.93,-0.371
34.87,132.75,-0.371
34.89,132.56,-0.371
34.91,132.38,-0.371
34.92,132.20,-0.371
34.94,132.01,-0.371
34.96,131.83,-0.371
34.98,131.65,-0.371
35.00,131.46,-0.371
35.01,131.28,-0.370
35.03,131.10,-0.370
35.05,130.91,-0.370
35.07,130.73,-0.370
35.09,130.55,-0.370
35.11,130.36,-0.370
35.13,130.18,-0.370
35.14,130.00,-0.370
35.16,129.81,-0.370
35.18,129.63,-0.370
35.20,129.45,-0.369
35.22,129.26,-0.369
35.24,129.08,-0.369
35.25,128.90,-0.369
35.27,128.72,-0.369
[...]
119.22,10.94,0.179
119.24,11.12,0.180
119.25,11.31,0.180
119.27,11.49,0.180
119.29,11.67,0.180
119.31,11.85,0.180
119.33,12.04,0.180
119.35,12.22,0.180
119.36,12.41,0.180
119.38,12.59,0.180
119.40,12.77,0.180
119.42,12.96,0.180
119.44,13.14,0.180
119.46,13.32,0.181
119.48,13.51,0.181
119.49,13.69,0.181
119.51,13.87,0.181
119.53,14.06,0.181
119.55,14.24,0.181
119.57,14.42,0.181
119.59,14.61,0.181
119.60,14.79,0.181
119.62,14.97,0.181
119.64,15.16,0.181
119.66,15.34,0.181
119.68,15.52,0.182
119.70,15.71,0.182
119.71,15.89,0.182
119.73,16.07,0.182
119.75,16.26,0.182
119.77,16.44,0.182
119.79,16.62,0.182
119.80,16.81,0.182
119.82,16.99,0.182
119.84,17.18,0.182
119.86,17.36,0.183
119.88,17.54,0.183
119.90,17.73,0.183
119.91,17.91,0.183
119.93,18.09,0.183
119.95,18.28,0.183
119.97,18.46,0.183
119.99,18.64,0.183
120.01,18.83,0.183
120.03,19.01,0.183
120.04,19.19,0.183
120.06,19.38,0.184
120.08,19.56,0.184
120.10,19.74,0.184
120.12,19.93,0.184
120.14,20.11,0.184
120.15,20.30,0.184
120.17,20.48,0.184
120.19,20.66,0.184
120.21,20.85,0.184
120.23,21.03,0.185
120.25,21.21,0.185
120.26,21.40,0.185
120.28,21.58,0.185
120.30,21.76,0.185
120.32,21.95,0.185
120.34,22.13,0.185
120.35,22.31,0.185
120.37,22.50,0.185
120.39,22.68,0.185
120.41,22.86,0.186
120.43,23.05,0.186
120.45,23.23,0.186
120.46,23.42,0.186
120.48,23.60,0.186
120.50,23.78,0.186
120.52,23.97,0.186
120.54,24.15,0.186
120.56,24.33,0.186
120.58,24.52,0.186
120.59,24.70,0.186
120.61,24.88,0.187
120.63,25.07,0.187
120.65,25.25,0.187
120.67,25.43,0.187
120.69,25.62,0.187
120.70,25.80,0.187
120.72,25.98,0.187
120.74,26.17,0.187
120.76,26.35,0.187
120.78,26.54,0.187
120.80,26.72,0.188
120.81,26.90,0.188
120.83,27.09,0.188
120.85,27.27,0.188
120.87,27.45,0.188
120.89,27.64,0.188
120.90,27.82,0.188
120.92,28.00,0.188
120.94,28.19,0.188
120.96,28.37,0.188
120.98,28.55,0.189
121.00,28.74,0.189
121.01,28.92,0.189
121.03,29.11,0.189
121.05,29.29,0.189
121.07,29.47,0.189
121.09,29.65,0.189
121.11,29.84,0.189
121.13,30.02,0.189
121.14,30.21,0.189
121.16,30.39,0.190
121.18,30.57,0.190
121.20,30.76,0.190
121.22,30.94,0.190
121.24,31.12,0.190
121.25,31.31,0.190
121.27,31.49,0.190
121.29,31.68,0.190
121.31,31.86,0.190
121.33,32.04,0.190
121.35,32.22,0.191
121.36,32.41,0.191
121.38,32.59,0.191
121.40,32.78,0.191
121.42,32.96,0.191
121.44,33.14,0.191
121.45,33.33,0.191
121.47,33.51,0.191
121.49,33.69,0.191
121.51,33.88,0.191
121.53,34.06,0.192
121.55,34.24,0.192
121.56,34.43,0.192
121.58,34.61,0.192
121.60,34.79,0.192
121.62,34.98,0.192
121.64,35.16,0.192
121.66,35.34,0.192
121.68,35.53,0.192
121.69,35.71,0.192
121.71,35.89,0.192
121.73,36.08,0.193
121.75,36.26,0.193
121.77,36.44,0.193
121.79,36.63,0.193
121.80,36.81,0.193
121.82,36.99,0.193
121.84,37.18,0.193
121.86,37.36,0.193
121.88,37.55,0.193
121.90,37.73,0.193
121.91,37.91,0.194
121.93,38.10,0.194
121.95,38.28,0.194
121.97,38.46,0.194
121.99,38.65,0.194
122.00,38.83,0.194
122.02,39.01,0.194
122.04,39.20,0.194
122.06,39.38,0.194
122.08,39.57,0.195
122.10,39.75,0.195
122.11,39.93,0.195
122.13,40.12,0.195
122.15,40.30,0.195
122.17,40.48,0.195
122.19,40.67,0.195
122.21,40.85,0.195
122.23,41.03,0.195
122.24,41.22,0.195
122.26,41.40,0.196
122.28,41.58,0.196
122.30,41.77,0.196
122.32,41.95,0.196
122.34,42.13,0.196
122.35,42.32,0.196
122.37,42.50,0.196
122.39,42.68,0.196
122.41,42.87,0.196
122.43,43.05,0.196
122.45,43.24,0.196
122.46,43.42,0.197
122.48,43.60,0.197
122.50,43.79,0.197
122.52,43.97,0.197
122.54,44.15,0.197
122.55,44.34,0.197
122.57,44.52,0.197
122.59,44.70,0.197
122.61,44.89,0.197
122.63,45.07,0.197
122.65,45.26,0.198
122.66,45.44,0.198
122.68,45.62,0.198
122.70,45.80,0.198
122.72,45.99,0.198
122.74,46.17,0.198
122.76,46.35,0.198
122.78,46.54,0.198
122.79,46.72,0.198
122.81,46.91,0.198
122.83,47.09,0.199
122.85,47.27,0.199
122.87,47.46,0.199
122.89,47.64,0.199
122.90,47.82,0.199
122.92,48.01,0.199
122.94,48.19,0.199
122.96,48.37,0.199
122.98,48.56,0.199
123.00,48.74,0.200
123.01,48.92,0.200
123.03,49.11,0.200
123.05,49.29,0.200
123.07,49.47,0.200
123.09,49.66,0.200
123.10,49.84,0.200
123.12,50.02,0.200
123.14,50.21,0.200
123.16,50.39,0.201
123.18,50.57,0.201
123.20,50.76,0.201
123.21,50.94,0.201
123.23,51.12,0.201
123.25,51.31,0.201
123.27,51.49,0.201
123.29,51.67,0.201
123.31,51.86,0.201
123.33,52.04,0.201
123.34,52.23,0.202
123.36,52.41,0.202
123.38,52.59,0.202
123.40,52.78,0.202
123.42,52.96,0.202
123.44,53.14,0.202
123.45,53.33,0.202
123.47,53.51,0.202
123.49,53.69,0.202
123.51,53.88,0.203
123.53,54.06,0.203
123.55,54.24,0.203
123.56,54.43,0.203
123.58,54.61,0.203
123.60,54.79,0.203
123.62,54.98,0.203
123.64,55.16,0.203
123.65,55.35,0.203
123.67,55.53,0.203
123.69,55.71,0.204
123.71,55.90,0.204
123.73,56.08,0.204
123.75,56.26,0.204
123.76,56.45,0.204
123.78,56.63,0.204
123.80,56.81,0.204
123.82,57.00,0.204
123.84,57.18,0.204
123.86,57.37,0.205
123.88,57.55,0.205
123.89,57.73,0.205
123.91,57.91,0.205
123.93,58.10,0.205
123.95,58.28,0.205
123.97,58.46,0.205
123.99,58.65,0.205
124.00,58.83,0.205
124.02,59.02,0.205
124.04,59.20,0.205
124.06,59.38,0.206
124.08,59.57,0.206
124.10,59.75,0.206
124.11,59.93,0.206
124.13,60.12,0.206
124.15,60.30,0.206
124.17,60.48,0.206
124.19,60.67,0.206
124.20,60.85,0.207
124.22,61.03,0.207
124.24,61.22,0.207
124.26,61.40,0.207
124.28,61.59,0.207
124.30,61.77,0.207
124.31,61.95,0.207
124.33,62.14,0.207
124.35,62.32,0.207
124.37,62.50,0.207
124.39,62.69,0.208
124.41,62.87,0.208
124.43,63.05,0.208
124.44,63.24,0.208
124.46,63.42,0.208
124.48,63.60,0.208
124.50,63.79,0.208
124.52,63.97,0.208
124.54,64.15,0.208
124.55,64.34,0.209
124.57,64.52,0.209
124.59,64.70,0.209
124.61,64.89,0.209
124.63,65.07,0.209
124.65,65.26,0.209
124.66,65.44,0.209
124.68,65.62,0.209
124.70,65.81,0.209
124.72,65.99,0.209
124.74,66.17,0.210
124.75,66.36,0.210
124.77,66.54,0.210
124.79,66.72,0.210
124.81,66.91,0.210
124.83,67.09,0.210
124.85,67.27,0.210
124.86,67.46,0.210
124.88,67.64,0.210
124.90,67.82,0.211
124.92,68.01,0.211
124.94,68.19,0.211
124.96,68.37,0.211
124.98,68.56,0.211
124.99,68.74,0.211
125.01,68.92,0.211
125.03,69.11,0.211
125.05,69.29,0.211
125.07,69.48,0.212
125.09,69.66,0.212
125.10,69.84,0.212
125.12,70.03,0.212
125.14,70.21,0.212
125.16,70.39,0.212
125.18,70.58,0.212
125.20,70.76,0.212
125.21,70.94,0.212
125.23,71.13,0.213
125.25,71.31,0.213
125.27,71.49,0.213
125.29,71.68,0.213
125.30,71.86,0.213
125.32,72.04,0.213
125.34,72.23,0.213
125.36,72.41,0.213
125.38,72.59,0.214
125.40,72.78,0.214
125.41,72.96,0.214
125.43,73.15,0.214
125.45,73.33,0.214
125.47,73.52,0.214
125.49,73.70,0.215
125.51,73.89,0.215
125.53,74.07,0.215
125.54,74.26,0.215
125.56,74.44,0.215
125.58,74.62,0.215
125.60,74.81,0.216
125.62,74.99,0.216
125.64,75.17,0.216
125.65,75.35,0.216
125.67,75.54,0.216
125.69,75.72,0.216
125.71,75.90,0.216
125.73,76.09,0.216
125.75,76.27,0.216
125.76,76.45,0.216
125.78,76.64,0.216
125.80,76.82,0.216
125.82,77.00,0.216
125.84,77.19,0.216
125.85,77.37,0.216
125.87,77.55,0.216
125.89,77.74,0.216
125.91,77.92,0.216
125.93,78.10,0.217
125.95,78.28,0.217
125.96,78.47,0.217
125.98,78.65,0.217
126.00,78.83,0.217
126.02,79.02,0.217
126.04,79.20,0.217
126.06,79.38,0.217
126.08,79.57,0.217
126.09,79.75,0.218
126.11,79.93,0.218
126.13,80.12,0.218
126.15,80.30,0.218
126.17,80.48,0.218
126.19,80.67,0.218
126.20,80.85,0.218
126.22,81.03,0.218
126.24,81.22,0.219
126.26,81.40,0.219
126.28,81.59,0.219
126.30,81.77,0.219
126.31,81.95,0.219
126.33,82.14,0.219
126.35,82.32,0.219
126.37,82.50,0.220
126.39,82.69,0.220
126.40,82.87,0.220
126.42,83.05,0.220
126.44,83.24,0.220
126.46,83.42,0.220
126.48,83.60,0.220
126.50,83.79,0.220
126.51,83.97,0.220
126.53,84.15,0.221
126.55,84.34,0.221
126.57,84.52,0.221
126.59,84.70,0.221
126.61,84.89,0.221
126.63,85.07,0.221
126.64,85.25,0.221
126.66,85.44,0.221
126.68,85.62,0.222
126.70,85.80,0.222
126.72,85.99,0.222
126.74,86.17,0.222
126.75,86.35,0.222
126.77,86.54,0.222
126.79,86.72,0.222
126.81,86.90,0.222
126.83,87.09,0.223
126.85,87.27,0.223
126.86,87.46,0.223
126.88,87.64,0.223
126.90,87.82,0.223
126.92,88.01,0.223
126.94,88.19,0.223
126.95,88.37,0.224
126.97,88.56,0.224
126.99,88.74,0.224
127.01,88.92,0.224
127.03,89.11,0.224
127.05,89.29,0.224
127.06,89.47,0.225
127.08,89.66,0.225
127.10,89.84,0.225
127.12,90.03,0.225
127.14,90.21,0.225
127.16,90.39,0.225
127.18,90.58,0.226
127.19,90.76,0.226
127.21,90.94,0.226
127.23,91.13,0.226
127.25,91.31,0.226
127.27,91.49,0.226
127.29,91.68,0.226
127.30,91.86,0.227
127.32,92.04,0.227
127.34,92.23,0.227
127.36,92.41,0.227
127.38,92.60,0.227
127.40,92.78,0.228
127.41,92.96,0.228
127.43,93.15,0.228
127.45,93.33,0.228
127.47,93.51,0.228
127.49,93.70,0.228
127.50,93.88,0.229
127.52,94.06,0.229
127.54,94.25,0.229
127.56,94.43,0.229
127.58,94.61,0.229
127.60,94.80,0.229
127.61,94.98,0.229
127.63,95.16,0.230
127.65,95.35,0.230
127.67,95.53,0.230
127.69,95.71,0.230
127.71,95.90,0.230
127.73,96.08,0.231
127.74,96.26,0.231
127.76,96.45,0.231
127.78,96.63,0.231
127.80,96.81,0.231
127.82,97.00,0.232
127.84,97.18,0.232
127.85,97.36,0.232
127.87,97.55,0.232
127.89,97.73,0.233
127.91,97.92,0.233
127.93,98.10,0.233
127.95,98.28,0.233
127.96,98.47,0.234
127.98,98.65,0.234
128.00,98.83,0.234
128.02,99.02,0.234
128.04,99.20,0.234
128.05,99.38,0.235
128.07,99.57,0.235
128.09,99.75,0.235
128.11,99.93,0.235
128.13,100.12,0.236
128.15,100.30,0.236
128.16,100.48,0.236
128.18,100.67,0.236
128.20,100.85,0.237
128.22,101.03,0.237
128.24,101.22,0.237
128.26,101.40,0.237
128.28,101.58,0.238
128.29,101.77,0.238
128.31,101.95,0.238
128.33,102.13,0.238
128.35,102.32,0.239
128.37,102.50,0.239
128.39,102.68,0.239
128.40,102.87,0.240
128.42,103.05,0.240
128.44,103.23,0.240
128.46,103.42,0.240
128.48,103.60,0.241
128.50,103.78,0.241
128.51,103.97,0.241
128.53,104.15,0.242
128.55,104.33,0.242
128.57,104.52,0.242
128.59,104.70,0.243
128.60,104.88,0.243
128.62,105.07,0.244
128.64,105.25,0.244
128.66,105.43,0.245
128.68,105.62,0.245
128.70,105.80,0.245
128.71,105.98,0.246
128.73,106.17,0.246
128.75,106.35,0.246
128.77,106.53,0.247
128.79,106.72,0.247
128.81,106.90,0.248
128.83,107.08,0.248
128.84,107.27,0.249
128.86,107.45,0.249
128.88,107.64,0.250
128.90,107.82,0.250
128.92,108.00,0.250
128.94,108.19,0.251
128.95,108.37,0.251
128.97,108.55,0.252
128.99,108.74,0.252
129.01,108.92,0.253
129.03,109.10,0.253
129.05,109.28,0.254
129.06,109.47,0.254
129.08,109.65,0.255
129.10,109.83,0.255
129.12,110.02,0.256
129.14,110.20,0.256
129.15,110.38,0.257
129.17,110.57,0.257
129.19,110.75,0.258
129.21,110.93,0.259
129.23,111.12,0.259
129.25,111.30,0.260
129.26,111.48,0.260
129.28,111.67,0.261
129.30,111.85,0.262
129.32,112.03,0.262
129.34,112.21,0.263
129.36,112.40,0.264
129.38,112.58,0.265
129.39,112.77,0.265
129.41,112.95,0.266
129.43,113.13,0.267
129.45,113.32,0.267
129.47,113.50,0.268
129.49,113.68,0.268
129.50,113.86,0.269
129.52,114.05,0.270
129.54,114.23,0.270
129.56,114.41,0.271
129.58,114.60,0.272
129.60,114.78,0.272
129.61,114.97,0.273
129.63,115.15,0.274
129.65,115.33,0.274
129.67,115.52,0.275
129.69,115.70,0.275
129.70,115.88,0.276
129.72,116.07,0.277
129.74,116.25,0.277
129.76,116.43,0.278
129.78,116.62,0.278
129.80,116.80,0.279
129.81,116.98,0.279
129.83,117.16,0.280
129.85,117.35,0.280
129.87,117.53,0.281
129.89,117.72,0.281
129.91,117.90,0.282
129.93,118.08,0.283
129.94,118.27,0.283
129.96,118.45,0.283
129.98,118.63,0.284
130.00,118.82,0.284
130.02,119.00,0.285
130.04,119.18,0.285
130.05,119.37,0.286
130.07,119.55,0.286
130.09,119.73,0.286
130.11,119.92,0.287
130.13,120.10,0.287
130.15,120.28,0.287
130.16,120.47,0.288
130.18,120.65,0.288
130.20,120.83,0.288
130.22,121.02,0.288
130.24,121.20,0.289
130.25,121.38,0.289
130.27,121.57,0.289
130.29,121.75,0.289
130.31,121.93,0.290
130.33,122.12,0.290
130.35,122.30,0.290
130.36,122.48,0.290
130.38,122.67,0.291
130.40,122.85,0.291
130.42,123.03,0.291
130.44,123.22,0.291
130.46,123.40,0.291
130.48,123.59,0.291
130.49,123.77,0.292
130.51,123.95,0.292
130.53,124.14,0.292
130.55,124.32,0.292
130.57,124.50,0.292
130.59,124.69,0.292
130.60,124.87,0.292
130.62,125.06,0.293
130.64,125.24,0.293
130.66,125.42,0.293
130.68,125.61,0.293
130.70,125.79,0.293
130.71,125.97,0.293
130.73,126.15,0.293
130.75,126.34,0.293
130.77,126.52,0.293
130.79,126.71,0.293
130.80,126.89,0.293
130.82,127.07,0.293
130.84,127.26,0.293
130.86,127.44,0.293
130.88,127.62,0.293
130.90,127.81,0.293
130.91,127.99,0.293
130.93,128.17,0.293
130.95,128.36,0.293
130.97,128.54,0.293
130.99,128.72,0.293
131.01,128.91,0.293
131.03,129.09,0.293
131.04,129.27,0.293
131.06,129.46,0.293
131.08,129.64,0.293
131.10,129.82,0.293
131.12,130.01,0.293
131.14,130.19,0.293
131.15,130.37,0.293
131.17,130.56,0.293
131.19,130.74,0.293
131.21,130.92,0.293
131.23,131.11,0.293
131.25,131.29,0.293
131.26,131.48,0.293
131.28,131.66,0.293
131.30,131.84,0.293
131.32,132.02,0.293
131.34,132.21,0.293
131.35,132.39,0.293
131.37,132.58,0.293
131.39,132.76,0.293
131.41,132.94,0.293
131.43,133.13,0.293
131.45,133.31,0.294
131.46,133.49,0.294
131.48,133.68,0.294
131.50,133.86,0.294
131.52,134.05,0.294
131.54,134.23,0.294
131.56,134.41,0.294
131.58,134.60,0.294
131.59,134.78,0.294
131.61,134.96,0.294
131.63,135.15,0.294
131.65,135.33,0.294
131.67,135.51,0.294
131.69,135.70,0.294
131.70,135.88,0.294
131.72,136.06,0.294
131.74,136.25,0.294
131.76,136.43,0.294
131.78,136.61,0.294
131.80,136.80,0.294
131.81,136.98,0.294
131.83,137.16,0.294
131.85,137.35,0.294
131.87,137.53,0.295
131.89,137.71,0.295
131.90,137.90,0.295
131.92,138.08,0.295
131.94,138.27,0.295
131.96,138.45,0.295
131.98,138.63,0.295
132.00,138.81,0.295
132.01,139.00,0.295
132.03,139.18,0.295
132.05,139.36,0.295
132.07,139.55,0.295
132.09,139.73,0.295
132.11,139.92,0.295
132.13,140.10,0.296
132.14,140.28,0.296
132.16,140.46,0.296
132.18,140.65,0.296
132.20,140.83,0.296
132.22,141.02,0.296
132.24,141.20,0.296
132.25,141.38,0.296
132.27,141.57,0.296
132.29,141.75,0.296
132.31,141.93,0.296
132.33,142.12,0.296
132.35,142.30,0.297
132.36,142.48,0.297
132.38,142.67,0.297
132.40,142.85,0.297
132.42,143.03,0.297
132.44,143.22,0.297
132.45,143.40,0.297
132.47,143.58,0.297
132.49,143.77,0.297
132.51,143.95,0.297
132.53,144.14,0.297
132.55,144.32,0.297
132.56,144.50,0.297
132.58,144.69,0.297
132.60,144.87,0.297
132.62,145.05,0.297
132.64,145.24,0.298
132.66,145.42,0.298
132.68,145.60,0.298
132.69,145.79,0.298
132.71,145.97,0.298
132.73,146.15,0.298
132.75,146.34,0.298
132.77,146.52,0.298
132.79,146.70,0.298
132.80,146.89,0.298
132.82,147.07,0.298
132.84,147.25,0.298
132.86,147.44,0.298
132.88,147.62,0.298
132.90,147.80,0.298
132.91,147.99,0.299
132.93,148.17,0.299
132.95,148.36,0.299
132.97,148.54,0.299
132.99,148.72,0.299
133.00,148.91,0.299
133.02,149.09,0.299
133.04,149.27,0.299
133.06,149.46,0.299
133.08,149.64,0.299
133.10,149.82,0.299
133.11,150.01,0.299
133.13,150.19,0.299
133.15,150.37,0.300
133.17,150.56,0.300
133.19,150.74,0.300
133.21,150.92,0.300
133.23,151.11,0.300
133.24,151.29,0.300
133.26,151.48,0.300
133.28,151.66,0.300
133.30,151.84,0.300
133.32,152.03,0.300
133.34,152.21,0.300
133.35,152.39,0.300
133.37,152.58,0.300
133.39,152.76,0.300
133.41,152.94,0.301
133.43,153.13,0.301
133.45,153.31,0.301
133.46,153.49,0.301
133.48,153.67,0.301
133.50,153.86,0.301
133.52,154.04,0.301
133.54,154.23,0.301
133.55,154.41,0.301
133.57,154.59,0.301
133.59,154.78,0.301
133.61,154.96,0.301
133.63,155.14,0.301
133.65,155.33,0.301
133.66,155.51,0.302
133.68,155.69,0.302
133.70,155.88,0.302
133.72,156.06,0.302
133.74,156.24,0.302
133.76,156.43,0.302
133.78,156.61,0.302
133.79,156.79,0.302
133.81,156.98,0.302
133.83,157.16,0.302
133.85,157.34,0.302
133.87,157.53,0.302
133.89,157.71,0.302
133.90,157.90,0.302
133.92,158.08,0.302
133.94,158.26,0.303
133.96,158.45,0.303
133.98,158.63,0.303
134.00,158.81,0.303
134.01,159.00,0.303
134.03,159.18,0.303
134.05,159.36,0.303
134.07,159.55,0.303
134.09,159.73,0.303
134.10,159.91,0.303
134.12,160.10,0.303
134.14,160.28,0.303
134.16,160.46,0.303
134.18,160.65,0.304
134.20,160.83,0.304
134.21,161.01,0.304
134.23,161.20,0.304
134.25,161.38,0.304
134.27,161.56,0.304
134.29,161.75,0.304
134.31,161.93,0.304
134.33,162.12,0.304
134.34,162.30,0.304
134.36,162.48,0.304
134.38,162.66,0.304
134.40,162.85,0.304
134.42,163.03,0.304
134.44,163.22,0.305
134.45,163.40,0.305
134.47,163.58,0.305
134.49,163.77,0.305
134.51,163.95,0.305
134.53,164.13,0.305
134.55,164.32,0.305
134.56,164.50,0.305
134.58,164.68,0.305
134.60,164.87,0.305
134.62,165.05,0.305
134.64,165.23,0.305
134.65,165.42,0.305
134.67,165.60,0.305
134.69,165.78,0.306
134.71,165.97,0.306
134.73,166.15,0.306
134.75,166.34,0.306
134.76,166.52,0.306
134.78,166.70,0.306
134.80,166.89,0.306
134.82,167.07,0.306
134.84,167.25,0.306
134.86,167.44,0.306
134.88,167.62,0.306
134.89,167.80,0.306
134.91,167.99,0.306
134.93,168.17,0.306
134.95,168.35,0.306
134.97,168.54,0.306
134.99,168.72,0.306
135.00,168.90,0.306
135.02,169.09,0.306
135.04,169.27,0.307
135.06,169.45,0.307
135.08,169.64,0.307
135.10,169.82,0.307
135.11,170.00,0.307
135.13,170.19,0.307
135.15,170.37,0.307
135.17,170.55,0.307
135.19,170.74,0.307
135.20,170.92,0.307
135.22,171.10,0.307
135.24,171.29,0.307
135.26,171.47,0.307
135.28,171.65,0.307
135.30,171.84,0.307
135.31,172.02,0.308
135.33,172.20,0.308
135.35,172.39,0.308
135.37,172.57,0.308
135.39,172.76,0.308
135.41,172.94,0.308
135.43,173.12,0.308
135.44,173.31,0.308
135.46,173.49,0.308
135.48,173.67,0.308
135.50,173.86,0.308
135.52,174.04,0.308
135.54,174.22,0.308
135.55,174.41,0.308
135.57,174.59,0.309
135.59,174.77,0.309
135.61,174.96,0.309
135.63,175.14,0.309
135.65,175.32,0.309
135.66,175.51,0.309
135.68,175.69,0.309
135.70,175.87,0.309
135.72,176.06,0.309
135.74,176.24,0.309
135.75,176.42,0.309
135.77,176.61,0.309
135.79,176.79,0.309
135.81,176.98,0.310
135.83,177.16,0.310
135.85,177.34,0.310
135.86,177.53,0.310
135.88,177.71,0.310
135.90,177.89,0.310
135.92,178.08,0.310
135.94,178.26,0.310
135.96,178.44,0.310
135.98,178.63,0.310
135.99,178.81,0.310
136.01,178.99,0.310
136.03,179.18,0.310
136.05,179.36,0.311
136.07,179.55,0.311
136.09,179.73,0.311
136.10,179.91,0.311
136.12,180.10,0.311
136.14,180.28,0.311
136.16,180.46,0.311
136.18,180.65,0.311
136.20,180.83,0.311
136.21,181.01,0.311
136.23,181.20,0.311
136.25,181.38,0.311
136.27,181.56,0.311
136.29,181.74,0.311
136.30,181.93,0.311
136.32,182.11,0.311
136.34,182.29,0.311
136.36,182.48,0.311
136.38,182.66,0.311
136.40,182.85,0.311
136.41,183.03,0.312
136.43,183.21,0.312
136.45,183.40,0.312
136.47,183.58,0.312
136.49,183.76,0.312
136.51,183.95,0.312
136.53,184.13,0.312
136.54,184.31,0.312
136.56,184.50,0.312
136.58,184.68,0.312
136.60,184.86,0.312
136.62,185.05,0.312
136.63,185.23,0.313
136.65,185.41,0.313
136.67,185.60,0.313
136.69,185.78,0.313
136.71,185.96,0.313
136.73,186.15,0.313
136.75,186.33,0.313
136.76,186.51,0.313
136.78,186.70,0.313
136.80,186.88,0.313
136.82,187.06,0.313
136.84,187.25,0.313
136.85,187.43,0.314
136.87,187.62,0.314
136.89,187.80,0.314
136.91,187.98,0.314
136.93,188.17,0.314
136.95,188.35,0.314
136.97,188.53,0.314
136.98,188.72,0.314
137.00,188.90,0.314
137.02,189.09,0.314
137.04,189.27,0.315
137.06,189.45,0.315
137.08,189.63,0.315
137.09,189.82,0.315
137.11,190.00,0.315
137.13,190.18,0.315
137.15,190.37,0.315
137.17,190.55,0.315
137.18,190.73,0.315
137.20,190.92,0.315
137.22,191.10,0.315
137.24,191.29,0.315
137.26,191.47,0.315
137.28,191.65,0.315
137.30,191.84,0.315
137.31,192.02,0.316
137.33,192.20,0.316
137.35,192.39,0.316
137.37,192.57,0.316
137.39,192.75,0.316
137.40,192.94,0.316
137.42,193.12,0.316
137.44,193.30,0.316
137.46,193.49,0.316
137.48,193.67,0.316
137.50,193.85,0.316
137.52,194.04,0.316
137.53,194.22,0.316
137.55,194.41,0.316
137.57,194.59,0.316
137.59,194.77,0.316
137.61,194.96,0.316
137.63,195.14,0.316
137.64,195.32,0.317
137.66,195.51,0.317
137.68,195.69,0.317
137.70,195.87,0.317
137.72,196.06,0.317
137.73,196.24,0.317
137.75,196.42,0.317
137.77,196.61,0.317
137.79,196.79,0.317
137.81,196.97,0.317
137.83,197.16,0.317
137.85,197.34,0.317
137.86,197.52,0.317
137.88,197.71,0.317
137.90,197.89,0.317
137.92,198.07,0.317
137.94,198.26,
137.95,198.44,
137.97,198.62,
137.99,,
137.99,,