File: DSC/Olivia/2025_07_17_1CBN_1PVP40kDa_MeOH_n60_160_5Cmin_x4.csv
Filename,2025_07_17_1CBN_1PVP40kDa_MeOH_n60_160_5Cmin_x4
Instrument name,DSC2A-00468 (192.168.1.100)
Operator,Gibbons
rundate,7/17/2025
Sample name,2025_07_17_1CBN_1PVP40kDa_MeOH_n60_160_5Cmin_x4
proceduresegments,Data Off ; Equilibrate -60.00 °C; Data On ; Ramp 5.00 °C/min to 160.00 °C; Data Off ; Isothermal 2.0 min; Data On ; Ramp 5.00 °C/min to -60.00 °C; Data Off ; Isothermal 2.0 min; Data On ; Ramp 5.00 °C/min to 160.00 °C; Data Off ; Isothermal 2.0 min; Data On ; Ramp 5.00 °C/min to -60.00 °C; Data Off ; Isothermal 2.0 min; Data On ; Ramp 5.00 °C/min to 160.00 °C; Data Off ; Isothermal 2.0 min; Data On ; Ramp 5.00 °C/min to -60.00 °C; Data Off ; Isothermal 2.0 min; Data On ; Ramp 5.00 °C/min to 30.00 °C
[File Parameters]
Run date,7/17/2025 2:15:17 PM
Trios version,5.1.1.46572
Original File Name,D:\DSC2500\Gibbons\2025_07_17_1CBN_1PVP40kDa_MeOH_n60_160_5Cmin_x4.tri
Current File Name,D:\DSC2500\Gibbons\2025_07_17_1CBN_1PVP40kDa_MeOH_n60_160_5Cmin_x4.tri
[Procedure]
Procedure Name,1CBN_1PVP40kDa_MeOH_n60_160_5Cmin_x4
Sample Name,2025_07_17_1CBN_1PVP40kDa_MeOH_n60_160_5Cmin_x4
Sample Mass,5.75 mg
Reference Sample Mass,0 mg
Pan Mass,55.87 mg
Pan Number,22
Reference Pan Mass,56.03 mg
Reference Pan Number,10
Pan Type,Tzero Aluminum Hermetic
Comments,DSC Consumables Al Hermetically Sealed Pan. A2 Tray (Google Sheet: DSC_Samples_A2_Tray_July2025).
Project Name,Pharmaceuticals - Cannabinoids
Operator,Gibbons
Test,Custom
Unload Max Temperature,30
Unload Min Temperature,30
Load Max Temperature,30
Load Min Temperature,30
Stop on Gas Flow Error,Yes
[Signal List]
Signal #1,Time (min)
Signal #2,Temperature (°C)
Signal #3,Heat Flow (mW)
Signal #4,Delta T (µV)
Signal #5,Delta Tzero (µV)
Signal #6,Tzero Temperature (°C)
Signal #7,Cell Purge (mL/min)
Signal #8,Heater Temp (°C)
Signal #9,Power Delivered (W)
Signal #10,Reference Junction Temperature (°C)
Signal #11,Flange Temperature (°C)
Signal #12,Heat Flow Phase (rad)
Signal #13,Total Heat Capacity (J/°C)
Signal #14,Heat Capacity (J/°C)
[Configuration]
Company Name,ASU
Instrument Name,DSC2A-00468
Instrument Type,DSC2500
Serial Number,DSC2A-00468
IP,192.168.1.100
Location of Instrument,MRRC
DisplayType,Unknown
Sample Interval ,0.1 s/pt
Selected Heat Flow,T4P
Exotherm Direction,Down
Cell Serial,DRC2-00792
Lid Type,Standard
Cooler,RCS 90
Leave Cooler on at End of Sequence,On
Gas 2,Nitrogen
Gas Selected,Channel 1
Flow Rate,50 mL/min
Secondary Purge,On
Licensed Heat Flow,Heat Flow T4P
Modulation Licensed,Yes
[Versions]
Common IDD Version,1
Cortex Version,VER 2.10.2.31
Driver,5.0.0.6
GDM Version,1.0.3.3
TouchscreenVersion,1.0.0.16145
FEP Version,1.2.1.21
FEP Bootloader,2.0.0.5
AutoSampler Version,2.1.1.26
Auto Sampler Bootloader,2.0.0.5
FCM Version,1.1.0.3
FCM Bootloader,2.0.0.5
[Experiment Logs]
Experiment Log Entry # 1,Data On set to 0
Experiment Log Entry # 3,Equilibrate Segment -60 (C) Started
Experiment Log Entry # 5,Air Cool is off.
Experiment Log Entry # 7,Data On set to 1
Experiment Log Entry # 9,Ramp Segment 5 C/min to 160 Started
Experiment Log Entry # 11,Ramp Segment 5 C/min to 160 Started
Experiment Log Entry # 13,User modified running procedure
Experiment Log Entry # 15,Data On set to 0
Experiment Log Entry # 17,Isothermal Segment 2 min started
Experiment Log Entry # 19,Data On set to 1
Experiment Log Entry # 21,Ramp Segment 5 C/min to -60 Started
Experiment Log Entry # 23,Data On set to 0
Experiment Log Entry # 25,Isothermal Segment 2 min started
Experiment Log Entry # 27,Data On set to 1
Experiment Log Entry # 29,Ramp Segment 5 C/min to 160 Started
Experiment Log Entry # 31,Data On set to 0
Experiment Log Entry # 33,Isothermal Segment 2 min started
Experiment Log Entry # 35,Data On set to 1
Experiment Log Entry # 37,Ramp Segment 5 C/min to -60 Started
Experiment Log Entry # 39,Data On set to 0
Experiment Log Entry # 41,Isothermal Segment 2 min started
Experiment Log Entry # 43,Data On set to 1
Experiment Log Entry # 45,Ramp Segment 5 C/min to 160 Started
Experiment Log Entry # 47,Data On set to 0
Experiment Log Entry # 49,Isothermal Segment 2 min started
Experiment Log Entry # 51,Data On set to 1
Experiment Log Entry # 53,Ramp Segment 5 C/min to -60 Started
Experiment Log Entry # 55,Data On set to 0
Experiment Log Entry # 57,Isothermal Segment 2 min started
Experiment Log Entry # 59,Data On set to 1
Experiment Log Entry # 61,Ramp Segment 5 C/min to 30 Started
[Method Log]
Method Log Entry # 1,Data Off
Method Log Entry # 2,Equilibrate -60 °C
Method Log Entry # 3,Data On
Method Log Entry # 4,(Ramp 324231) Ramp 5 °C/minute to 160 °C
Method Log Entry # 5,Data Off
Method Log Entry # 6,Isothermal 2 minutes
Method Log Entry # 7,Data On
Method Log Entry # 8,(Ramp 324235) Ramp 5 °C/minute to -60 °C
Method Log Entry # 9,Data Off
Method Log Entry # 10,Isothermal 2 minutes
Method Log Entry # 11,Data On
Method Log Entry # 12,(Ramp 324239) Ramp 5 °C/minute to 160 °C
Method Log Entry # 13,Data Off
Method Log Entry # 14,Isothermal 2 minutes
Method Log Entry # 15,Data On
Method Log Entry # 16,(Ramp 324243) Ramp 5 °C/minute to -60 °C
Method Log Entry # 17,Data Off
Method Log Entry # 18,Isothermal 2 minutes
Method Log Entry # 19,Data On
Method Log Entry # 20,(Ramp 324247) Ramp 5 °C/minute to 160 °C
Method Log Entry # 21,Data Off
Method Log Entry # 22,Isothermal 2 minutes
Method Log Entry # 23,Data On
Method Log Entry # 24,(Ramp 324251) Ramp 5 °C/minute to -60 °C
Method Log Entry # 25,Data Off
Method Log Entry # 26,Isothermal 2 minutes
Method Log Entry # 27,Data On
Method Log Entry # 28,(Ramp 324255) Ramp 5 °C/minute to 30 °C
Cell Serial,DRC2-00792
[T1 Calibration]
Slope,-0.008529666
Offset,9.636258
Initial Temperature,98.23
GUID,f8bfdadc-4977-4fdf-ba6d-0ba9134940c3
[TZero Calibration]
Date Applied,11/29/2022 4:06:13 PM
Description,From -89.059 °C to 396.009 °C at 20.000°C/min
Gas Type,Nitrogen
Pan Type,None
Source Files 1,C:\Users\yargerlab\Desktop\DSC Data\General\TZero_calibration_11_29_22_2nd(2).tri
Source Files 2,C:\Users\yargerlab\Desktop\DSC Data\General\TZero_calibration_11_29_22_2nd(3).tri
Delta T Offset,13.05235
Delta T Slope,-0.007271007
Delta T0 Offset,-13.69128
Delta T0 Slope,0.06063341
[Temperature Calibration]
Date Applied,11/29/2022 7:12:28 PM
Description,From 106.590 °C to 186.590 °C at 10.000°C/min
Gas Type,Nitrogen
Pan Type,Tzero Aluminum Hermetic
Source Files 1,C:\Users\yargerlab\Desktop\DSC Data\General\Indium(6).tri
Measured 1,157.391
Known 1,156.598
[Cell Constant Calibration]
Date Applied,11/29/2022 7:12:29 PM
Description,From 106.590 °C to 186.590 °C at 10.000°C/min
Gas Type,Nitrogen
Pan Type,Tzero Aluminum Hermetic
Source Files 1,C:\Users\yargerlab\Desktop\DSC Data\General\Indium(6).tri
T4P KCell,1.006051
Onset Slope,63.26126 mW/°C
[Direct Cp Calibration]
Date Applied,11/30/2022 11:04:51 AM
Description,From -79.983 °C to 298.409 °C at 10.000°C/min
Gas Type,Nitrogen
Pan Type,Tzero Aluminum Hermetic
Source Files 1,C:\Users\yargerlab\Desktop\DSC Data\General\Sapphire_Heat_Capacity_11_30_22.tri
[Rev Cp Calibration]
Date Applied,11/30/2022 1:58:51 PM
Description,From -79.996 °C to 292.812 °C at 3.000°C/min
Gas Type,Nitrogen
Pan Type,Tzero Aluminum Hermetic
Source Files 1,C:\Users\yargerlab\Desktop\DSC Data\General\Sapphire_MDSC_Calibration_11_30_22.tri
[step]
Ramp 5.00 °C/min to 160.00 °C
Time,Temperature,Heat Flow (Normalized)
min,°C,W/g
0.00,-59.72,-0.052
0.03,-59.74,-0.050
0.06,-59.74,-0.039
0.09,-59.72,-0.024
0.12,-59.67,-0.007
0.15,-59.58,0.012
0.18,-59.48,0.029
0.21,-59.37,0.045
0.24,-59.25,0.057
0.27,-59.13,0.065
0.30,-59.00,0.073
0.33,-58.87,0.078
0.36,-58.73,0.082
0.39,-58.59,0.087
0.42,-58.45,0.090
0.45,-58.31,0.091
0.48,-58.17,0.092
0.51,-58.02,0.094
0.54,-57.88,0.095
0.57,-57.73,0.096
0.60,-57.59,0.096
0.63,-57.44,0.097
0.66,-57.30,0.098
0.69,-57.15,0.098
0.72,-57.00,0.099
0.75,-56.85,0.099
0.78,-56.70,0.099
0.81,-56.56,0.100
0.84,-56.41,0.100
0.87,-56.26,0.101
0.90,-56.11,0.101
0.93,-55.96,0.101
0.96,-55.82,0.102
0.99,-55.67,0.102
1.02,-55.52,0.102
1.05,-55.37,0.102
1.08,-55.22,0.103
1.11,-55.07,0.103
1.14,-54.92,0.103
1.17,-54.77,0.103
1.20,-54.62,0.103
1.23,-54.47,0.103
1.26,-54.32,0.104
1.29,-54.17,0.104
1.32,-54.02,0.104
1.35,-53.88,0.104
1.38,-53.73,0.104
1.41,-53.58,0.104
1.44,-53.43,0.104
1.47,-53.28,0.104
1.50,-53.13,0.104
1.53,-52.98,0.104
1.56,-52.83,0.104
1.59,-52.68,0.104
1.62,-52.53,0.105
1.65,-52.38,0.105
1.68,-52.23,0.105
1.71,-52.08,0.105
1.74,-51.93,0.105
1.77,-51.78,0.105
1.80,-51.63,0.105
1.83,-51.48,0.105
1.86,-51.33,0.105
1.89,-51.18,0.105
1.92,-51.03,0.105
1.95,-50.88,0.105
1.98,-50.73,0.105
2.01,-50.58,0.105
2.04,-50.43,0.105
2.07,-50.28,0.105
2.10,-50.13,0.105
2.13,-49.98,0.105
2.16,-49.83,0.105
2.19,-49.68,0.105
2.22,-49.53,0.105
2.25,-49.38,0.105
2.28,-49.23,0.105
2.31,-49.08,0.105
2.34,-48.93,0.105
2.37,-48.78,0.105
2.40,-48.63,0.105
2.43,-48.48,0.105
2.46,-48.33,0.105
2.49,-48.18,0.105
2.52,-48.03,0.105
2.55,-47.88,0.105
2.58,-47.73,0.105
2.61,-47.58,0.105
2.64,-47.43,0.105
2.67,-47.28,0.105
2.70,-47.13,0.105
2.73,-46.98,0.105
2.76,-46.83,0.105
2.79,-46.68,0.105
2.82,-46.53,0.105
2.85,-46.38,0.105
2.88,-46.23,0.105
2.91,-46.08,0.105
2.94,-45.93,0.105
2.97,-45.78,0.105
3.00,-45.63,0.105
3.03,-45.48,0.105
3.06,-45.34,0.105
3.09,-45.19,0.105
3.12,-45.04,0.105
3.15,-44.89,0.105
3.18,-44.74,0.105
3.21,-44.59,0.105
3.24,-44.44,0.105
3.27,-44.29,0.105
3.30,-44.14,0.105
3.33,-43.99,0.105
3.36,-43.84,0.105
3.39,-43.69,0.105
3.42,-43.54,0.105
3.45,-43.39,0.105
3.48,-43.24,0.105
3.51,-43.08,0.106
3.54,-42.94,0.106
3.57,-42.79,0.106
3.60,-42.64,0.106
3.63,-42.49,0.106
3.66,-42.34,0.106
3.69,-42.19,0.106
3.72,-42.04,0.106
3.75,-41.89,0.106
3.78,-41.74,0.106
3.81,-41.58,0.106
3.84,-41.44,0.106
3.87,-41.29,0.106
3.90,-41.13,0.106
3.93,-40.99,0.106
3.96,-40.83,0.106
3.99,-40.68,0.106
4.02,-40.53,0.106
4.05,-40.38,0.106
4.08,-40.23,0.106
4.11,-40.08,0.106
4.14,-39.93,0.106
4.17,-39.78,0.106
4.20,-39.63,0.106
4.23,-39.48,0.106
4.26,-39.33,0.106
4.29,-39.18,0.106
4.32,-39.03,0.106
4.35,-38.88,0.106
4.38,-38.73,0.106
4.41,-38.58,0.106
4.44,-38.43,0.106
4.47,-38.28,0.106
4.50,-38.13,0.106
4.53,-37.98,0.107
4.56,-37.83,0.107
4.59,-37.68,0.107
4.62,-37.53,0.107
4.65,-37.38,0.107
4.68,-37.23,0.107
4.71,-37.08,0.107
4.74,-36.93,0.107
4.77,-36.78,0.107
4.80,-36.63,0.107
4.83,-36.48,0.107
4.86,-36.33,0.107
4.89,-36.18,0.107
4.92,-36.03,0.107
4.95,-35.88,0.107
4.98,-35.73,0.107
5.01,-35.58,0.107
5.04,-35.43,0.107
5.07,-35.28,0.107
5.10,-35.13,0.107
5.13,-34.98,0.107
5.16,-34.83,0.107
5.19,-34.67,0.107
5.22,-34.53,0.107
5.25,-34.38,0.107
5.28,-34.23,0.107
5.31,-34.08,0.107
5.34,-33.93,0.107
5.37,-33.78,0.107
5.40,-33.63,0.107
5.43,-33.48,0.107
5.46,-33.33,0.107
5.49,-33.18,0.107
5.52,-33.03,0.108
5.55,-32.88,0.108
5.58,-32.73,0.108
5.61,-32.58,0.108
5.64,-32.43,0.108
5.67,-32.28,0.108
5.70,-32.13,0.108
5.73,-31.98,0.108
5.76,-31.82,0.108
5.79,-31.68,0.108
5.82,-31.52,0.108
5.85,-31.37,0.108
5.88,-31.22,0.108
5.91,-31.07,0.108
5.94,-30.92,0.108
5.97,-30.77,0.108
6.00,-30.62,0.108
6.03,-30.47,0.108
6.06,-30.32,0.108
6.09,-30.17,0.108
6.12,-30.02,0.108
6.15,-29.87,0.108
6.18,-29.72,0.108
6.21,-29.57,0.108
6.24,-29.42,0.108
6.27,-29.27,0.109
6.30,-29.12,0.109
6.33,-28.97,0.109
6.36,-28.82,0.109
6.39,-28.67,0.109
6.42,-28.52,0.109
6.45,-28.37,0.109
6.48,-28.22,0.109
6.51,-28.07,0.109
6.54,-27.92,0.109
6.57,-27.77,0.109
6.60,-27.62,0.109
6.63,-27.47,0.109
6.66,-27.32,0.109
6.69,-27.17,0.109
6.72,-27.02,0.109
6.75,-26.87,0.109
6.78,-26.72,0.109
6.81,-26.57,0.109
6.84,-26.42,0.109
6.87,-26.27,0.109
6.90,-26.12,0.109
6.93,-25.97,0.109
6.96,-25.82,0.109
6.99,-25.67,0.109
7.02,-25.51,0.109
7.05,-25.37,0.109
7.08,-25.22,0.110
7.11,-25.06,0.110
7.14,-24.91,0.110
7.17,-24.76,0.110
7.20,-24.61,0.110
7.23,-24.46,0.110
7.26,-24.31,0.110
7.29,-24.16,0.110
7.32,-24.01,0.110
7.35,-23.86,0.110
7.38,-23.71,0.110
7.41,-23.56,0.110
7.44,-23.41,0.110
7.47,-23.26,0.110
7.50,-23.11,0.110
7.53,-22.96,0.110
7.56,-22.81,0.110
7.59,-22.66,0.110
7.62,-22.51,0.110
7.65,-22.36,0.110
7.68,-22.21,0.110
7.71,-22.06,0.110
7.74,-21.91,0.110
7.77,-21.76,0.110
7.80,-21.61,0.110
7.83,-21.46,0.110
7.86,-21.31,0.110
7.89,-21.16,0.111
7.92,-21.01,0.111
7.95,-20.86,0.111
7.98,-20.71,0.111
8.01,-20.56,0.111
8.04,-20.41,0.111
8.07,-20.26,0.111
8.10,-20.11,0.111
8.13,-19.96,0.111
8.16,-19.81,0.111
8.19,-19.66,0.111
8.22,-19.51,0.111
8.25,-19.36,0.111
8.28,-19.21,0.111
8.31,-19.06,0.111
8.34,-18.91,0.111
8.37,-18.76,0.111
8.40,-18.61,0.111
8.43,-18.46,0.111
8.46,-18.31,0.111
8.49,-18.16,0.111
8.52,-18.01,0.111
8.55,-17.86,0.111
8.58,-17.71,0.111
8.61,-17.56,0.111
8.64,-17.41,0.111
8.67,-17.26,0.112
8.70,-17.11,0.112
8.73,-16.96,0.112
8.76,-16.81,0.112
8.79,-16.66,0.112
8.82,-16.51,0.112
8.85,-16.36,0.112
8.88,-16.21,0.112
8.91,-16.06,0.112
8.94,-15.90,0.112
8.97,-15.76,0.112
9.00,-15.61,0.112
9.03,-15.45,0.112
9.06,-15.30,0.112
9.09,-15.15,0.112
9.12,-15.00,0.112
9.15,-14.86,0.112
9.18,-14.70,0.112
9.21,-14.55,0.112
9.24,-14.40,0.112
9.27,-14.25,0.112
9.30,-14.10,0.112
9.33,-13.95,0.112
9.36,-13.80,0.112
9.39,-13.65,0.113
9.42,-13.50,0.113
9.45,-13.35,0.113
9.48,-13.20,0.113
9.51,-13.05,0.113
9.54,-12.90,0.113
9.57,-12.75,0.113
9.60,-12.60,0.113
9.63,-12.45,0.113
9.66,-12.30,0.113
9.69,-12.15,0.113
9.72,-12.00,0.113
9.75,-11.85,0.113
9.78,-11.70,0.113
9.81,-11.55,0.113
9.84,-11.40,0.113
9.87,-11.25,0.113
9.90,-11.10,0.113
9.93,-10.95,0.113
9.96,-10.80,0.113
9.99,-10.65,0.113
10.02,-10.50,0.113
10.05,-10.35,0.113
10.08,-10.20,0.114
10.11,-10.05,0.114
10.14,-9.90,0.114
10.17,-9.75,0.114
10.20,-9.60,0.114
10.23,-9.45,0.114
10.26,-9.30,0.114
10.29,-9.15,0.114
10.32,-9.00,0.114
10.35,-8.85,0.114
10.38,-8.70,0.114
10.41,-8.55,0.114
10.44,-8.40,0.114
10.47,-8.25,0.114
10.50,-8.10,0.114
10.53,-7.95,0.114
10.56,-7.80,0.114
10.59,-7.65,0.114
10.62,-7.50,0.114
10.65,-7.35,0.114
10.68,-7.20,0.115
10.71,-7.05,0.115
10.74,-6.90,0.115
10.77,-6.75,0.115
10.80,-6.60,0.115
10.83,-6.44,0.115
10.86,-6.29,0.115
10.89,-6.14,0.115
10.92,-5.99,0.115
10.95,-5.84,0.115
10.98,-5.69,0.116
11.01,-5.54,0.116
11.04,-5.39,0.116
11.07,-5.24,0.116
11.10,-5.09,0.116
11.13,-4.94,0.116
11.16,-4.79,0.116
11.19,-4.64,0.116
11.22,-4.49,0.116
11.25,-4.34,0.116
11.28,-4.19,0.116
11.31,-4.04,0.116
11.34,-3.89,0.116
11.37,-3.74,0.116
11.40,-3.59,0.116
11.43,-3.44,0.116
11.46,-3.29,0.116
11.49,-3.14,0.116
11.52,-2.99,0.116
11.55,-2.84,0.116
11.58,-2.69,0.116
11.61,-2.54,0.116
11.64,-2.39,0.116
11.67,-2.24,0.116
11.70,-2.09,0.116
11.73,-1.94,0.116
11.76,-1.79,0.117
11.79,-1.64,0.117
11.82,-1.49,0.117
11.85,-1.34,0.117
11.88,-1.19,0.117
11.91,-1.04,0.117
11.94,-0.89,0.117
11.97,-0.74,0.117
12.00,-0.59,0.117
12.03,-0.44,0.117
12.06,-0.29,0.117
12.09,-0.14,0.117
12.12,0.01,0.117
12.15,0.16,0.117
12.18,0.31,0.117
12.21,0.46,0.117
12.24,0.61,0.117
12.27,0.76,0.117
12.30,0.91,0.117
12.33,1.06,0.118
12.36,1.21,0.118
12.39,1.36,0.118
12.42,1.51,0.118
12.45,1.66,0.118
12.48,1.81,0.118
12.51,1.96,0.118
12.54,2.11,0.118
12.57,2.26,0.118
12.60,2.41,0.118
12.63,2.56,0.118
12.66,2.71,0.118
12.69,2.86,0.118
12.72,3.01,0.118
12.75,3.16,0.118
12.78,3.31,0.118
12.81,3.46,0.118
12.84,3.61,0.118
12.87,3.76,0.118
12.90,3.91,0.118
12.93,4.06,0.118
12.96,4.21,0.118
12.99,4.36,0.118
13.02,4.51,0.118
13.05,4.66,0.119
13.08,4.81,0.119
13.11,4.96,0.119
13.14,5.11,0.119
13.17,5.26,0.119
13.20,5.41,0.119
13.23,5.56,0.119
13.26,5.71,0.119
13.29,5.86,0.119
13.32,6.01,0.119
13.35,6.16,0.119
13.38,6.31,0.119
13.41,6.46,0.120
13.44,6.61,0.120
13.47,6.76,0.120
13.50,6.91,0.120
13.53,7.07,0.120
13.56,7.21,0.120
13.59,7.37,0.120
13.62,7.52,0.120
13.65,7.66,0.120
13.68,7.82,0.120
13.71,7.96,0.120
13.74,8.12,0.120
13.77,8.27,0.120
13.80,8.42,0.120
13.83,8.57,0.120
13.86,8.72,0.120
13.89,8.87,0.120
13.92,9.02,0.120
13.95,9.17,0.121
13.98,9.32,0.121
14.01,9.47,0.121
14.04,9.62,0.121
14.07,9.76,0.121
14.10,9.91,0.121
14.13,10.07,0.121
14.16,10.22,0.121
14.19,10.37,0.121
14.22,10.52,0.121
14.25,10.67,0.121
14.28,10.82,0.121
14.31,10.97,0.121
14.34,11.12,0.122
14.37,11.27,0.122
14.40,11.42,0.122
14.43,11.57,0.122
14.46,11.72,0.122
14.49,11.87,0.122
14.52,12.02,0.122
14.55,12.17,0.122
14.58,12.32,0.122
14.61,12.47,0.122
14.64,12.62,0.122
14.67,12.77,0.122
14.70,12.92,0.122
14.73,13.07,0.122
14.76,13.22,0.123
14.79,13.37,0.123
14.82,13.52,0.123
14.85,13.67,0.123
14.88,13.82,0.123
14.91,13.97,0.123
14.94,14.12,0.123
14.97,14.27,0.123
15.00,14.42,0.123
15.03,14.57,0.123
15.06,14.72,0.123
15.09,14.87,0.123
15.12,15.02,0.123
15.15,15.17,0.123
15.18,15.32,0.123
15.21,15.47,0.124
15.24,15.62,0.124
15.27,15.77,0.124
15.30,15.92,0.124
15.33,16.07,0.124
15.36,16.22,0.124
15.39,16.37,0.124
15.42,16.52,0.124
15.45,16.67,0.124
15.48,16.82,0.124
15.51,16.97,0.124
15.54,17.12,0.124
15.57,17.27,0.124
15.60,17.42,0.124
15.63,17.57,0.125
15.66,17.72,0.125
15.69,17.87,0.125
15.72,18.02,0.125
15.75,18.17,0.125
15.78,18.32,0.125
15.81,18.47,0.125
15.84,18.62,0.125
15.87,18.77,0.125
15.90,18.93,0.125
15.93,19.07,0.125
15.96,19.22,0.125
15.99,19.37,0.125
16.02,19.52,0.125
16.05,19.67,0.125
16.08,19.82,0.126
16.11,19.98,0.126
16.14,20.13,0.126
16.17,20.28,0.126
16.20,20.43,0.126
16.23,20.58,0.126
16.26,20.73,0.126
16.29,20.88,0.126
16.32,21.03,0.126
16.35,21.18,0.126
16.38,21.33,0.126
16.41,21.48,0.127
16.44,21.63,0.127
16.47,21.78,0.127
16.50,21.93,0.127
16.53,22.08,0.127
16.56,22.23,0.127
16.59,22.38,0.127
16.62,22.53,0.127
16.65,22.68,0.127
16.68,22.83,0.127
16.71,22.98,0.127
16.74,23.13,0.127
16.77,23.28,0.128
16.80,23.43,0.128
16.83,23.58,0.128
16.86,23.73,0.128
16.89,23.88,0.128
16.92,24.03,0.128
16.95,24.18,0.128
16.98,24.33,0.128
17.01,24.48,0.128
17.04,24.63,0.128
17.07,24.78,0.128
17.10,24.93,0.128
17.13,25.08,0.128
17.16,25.23,0.128
17.19,25.38,0.128
17.22,25.53,0.129
17.25,25.68,0.129
17.28,25.83,0.129
17.31,25.98,0.129
17.34,26.13,0.129
17.37,26.28,0.129
17.40,26.43,0.129
17.43,26.58,0.129
17.46,26.73,0.129
17.49,26.88,0.130
17.52,27.03,0.130
17.55,27.18,0.130
17.58,27.33,0.130
17.61,27.48,0.130
17.64,27.63,0.130
17.67,27.78,0.130
17.70,27.93,0.130
17.73,28.08,0.130
17.76,28.23,0.130
17.79,28.38,0.130
17.82,28.53,0.130
17.85,28.68,0.131
17.88,28.83,0.131
17.91,28.98,0.131
17.94,29.13,0.131
17.97,29.28,0.131
18.00,29.43,0.131
18.03,29.58,0.131
18.06,29.73,0.131
18.09,29.88,0.131
18.12,30.03,0.131
18.15,30.18,0.131
18.18,30.33,0.132
18.21,30.48,0.132
18.24,30.63,0.132
18.27,30.78,0.132
18.30,30.93,0.132
18.33,31.08,0.132
18.36,31.23,0.132
18.39,31.38,0.132
18.42,31.53,0.132
18.45,31.68,0.132
18.48,31.83,0.133
18.51,31.98,0.133
18.54,32.13,0.133
18.57,32.28,0.133
18.60,32.43,0.133
18.63,32.58,0.133
18.66,32.73,0.133
18.69,32.88,0.133
18.72,33.03,0.133
18.75,33.18,0.133
18.78,33.33,0.133
18.81,33.48,0.133
18.84,33.64,0.134
18.87,33.78,0.134
18.90,33.93,0.134
18.93,34.09,0.134
18.96,34.24,0.134
18.99,34.38,0.134
19.02,34.53,0.134
19.05,34.69,0.134
19.08,34.84,0.134
19.11,34.98,0.135
19.14,35.14,0.135
19.17,35.29,0.135
19.20,35.44,0.135
19.23,35.59,0.135
19.26,35.74,0.135
19.29,35.89,0.135
19.32,36.04,0.135
19.35,36.19,0.135
19.38,36.34,0.136
19.41,36.49,0.136
19.44,36.64,0.136
19.47,36.79,0.136
19.50,36.94,0.136
19.53,37.09,0.136
19.56,37.24,0.136
19.59,37.39,0.136
19.62,37.54,0.137
19.65,37.69,0.137
19.68,37.84,0.137
19.71,37.99,0.137
19.74,38.14,0.137
19.77,38.29,0.137
19.80,38.44,0.137
19.83,38.59,0.138
19.86,38.74,0.138
19.89,38.89,0.138
19.92,39.04,0.138
19.95,39.19,0.138
19.98,39.34,0.138
20.01,39.49,0.138
20.04,39.64,0.138
20.07,39.79,0.139
20.10,39.94,0.139
20.13,40.09,0.139
20.16,40.24,0.139
20.19,40.39,0.139
20.22,40.54,0.139
20.25,40.69,0.139
20.28,40.84,0.140
20.31,40.99,0.140
20.34,41.14,0.140
20.37,41.29,0.140
20.40,41.44,0.140
20.43,41.59,0.140
20.46,41.74,0.141
20.49,41.89,0.141
20.52,42.04,0.141
20.55,42.19,0.141
20.58,42.34,0.141
20.61,42.49,0.142
20.64,42.64,0.142
20.67,42.79,0.142
20.70,42.94,0.142
20.73,43.09,0.142
20.76,43.24,0.143
20.79,43.39,0.143
20.82,43.54,0.143
20.85,43.69,0.143
20.88,43.84,0.143
20.91,43.99,0.144
20.94,44.14,0.144
20.97,44.29,0.144
21.00,44.44,0.144
21.03,44.59,0.145
21.06,44.74,0.145
21.09,44.89,0.145
21.12,45.04,0.145
21.15,45.19,0.146
21.18,45.34,0.146
21.21,45.49,0.146
21.24,45.64,0.147
21.27,45.79,0.147
21.30,45.94,0.147
21.33,46.09,0.147
21.36,46.24,0.148
21.39,46.39,0.148
21.42,46.54,0.148
21.45,46.69,0.149
21.48,46.84,0.149
21.51,46.99,0.149
21.54,47.14,0.150
21.57,47.29,0.150
21.60,47.44,0.151
21.63,47.59,0.151
21.66,47.74,0.151
21.69,47.89,0.152
21.72,48.04,0.152
21.75,48.19,0.152
21.78,48.34,0.153
21.81,48.49,0.153
21.84,48.64,0.154
21.87,48.79,0.154
21.90,48.94,0.155
21.93,49.09,0.155
21.96,49.24,0.156
21.99,49.39,0.156
22.02,49.54,0.157
22.05,49.69,0.157
22.08,49.84,0.158
22.11,49.99,0.158
22.14,50.14,0.159
22.17,50.29,0.160
22.20,50.44,0.161
22.23,50.59,0.161
22.26,50.74,0.162
22.29,50.89,0.162
22.32,51.04,0.163
22.35,51.19,0.164
22.38,51.34,0.165
22.41,51.49,0.165
22.44,51.64,0.166
22.47,51.79,0.167
22.50,51.94,0.168
22.53,52.09,0.168
22.56,52.24,0.169
22.59,52.39,0.171
22.62,52.54,0.171
22.65,52.68,0.172
22.68,52.83,0.173
22.71,52.98,0.174
22.74,53.13,0.175
22.77,53.28,0.176
22.80,53.43,0.177
22.83,53.58,0.178
22.86,53.73,0.179
22.89,53.88,0.180
22.92,54.03,0.181
22.95,54.18,0.182
22.98,54.33,0.183
23.01,54.48,0.184
23.04,54.63,0.185
23.07,54.78,0.186
23.10,54.93,0.187
23.13,55.08,0.188
23.16,55.23,0.189
23.19,55.38,0.190
23.22,55.53,0.191
23.25,55.68,0.192
23.28,55.83,0.192
23.31,55.98,0.193
23.34,56.13,0.194
23.37,56.28,0.195
23.40,56.43,0.195
23.43,56.58,0.196
23.46,56.73,0.196
23.49,56.88,0.197
23.52,57.03,0.198
23.55,57.18,0.198
23.58,57.33,0.198
23.61,57.48,0.199
23.64,57.63,0.199
23.67,57.78,0.200
23.70,57.93,0.200
23.73,58.08,0.200
23.76,58.23,0.200
23.79,58.38,0.201
23.82,58.53,0.201
23.85,58.68,0.201
23.88,58.83,0.201
23.91,58.98,0.201
23.94,59.13,0.201
23.97,59.28,0.201
24.00,59.43,0.201
24.03,59.58,0.201
24.06,59.73,0.200
24.09,59.88,0.200
24.12,60.03,0.200
24.15,60.18,0.199
24.18,60.33,0.199
24.21,60.48,0.198
24.24,60.63,0.198
24.27,60.78,0.198
24.30,60.93,0.197
24.33,61.08,0.197
24.36,61.23,0.196
24.39,61.39,0.196
24.42,61.54,0.195
24.45,61.69,0.195
24.48,61.84,0.194
24.51,61.99,0.194
24.54,62.14,0.193
24.57,62.29,0.193
24.60,62.44,0.192
24.63,62.59,0.192
24.66,62.74,0.191
24.69,62.89,0.190
24.72,63.04,0.190
24.75,63.19,0.189
24.78,63.34,0.189
24.81,63.49,0.188
24.84,63.64,0.188
24.87,63.79,0.187
24.90,63.94,0.187
24.93,64.09,0.187
24.96,64.24,0.186
24.99,64.39,0.186
25.02,64.54,0.185
25.05,64.69,0.185
25.08,64.84,0.185
25.11,64.99,0.185
25.14,65.14,0.184
25.17,65.29,0.184
25.20,65.44,0.184
25.23,65.59,0.184
25.26,65.74,0.184
25.29,65.89,0.183
25.32,66.04,0.183
25.35,66.19,0.183
25.38,66.34,0.183
25.41,66.49,0.183
25.44,66.64,0.183
25.47,66.79,0.183
25.50,66.94,0.183
25.53,67.09,0.183
25.56,67.25,0.183
25.59,67.39,0.182
25.62,67.54,0.182
25.65,67.69,0.182
25.68,67.84,0.182
25.71,68.00,0.182
25.74,68.14,0.183
25.77,68.29,0.182
25.80,68.45,0.182
25.83,68.60,0.183
25.86,68.75,0.183
25.89,68.90,0.183
25.92,69.05,0.183
25.95,69.20,0.183
25.98,69.35,0.183
26.01,69.50,0.183
26.04,69.64,0.183
26.07,69.80,0.183
26.10,69.95,0.183
26.13,70.10,0.183
26.16,70.25,0.183
26.19,70.40,0.183
26.22,70.55,0.183
26.25,70.70,0.183
26.28,70.85,0.183
26.31,71.00,0.183
26.34,71.15,0.183
26.37,71.30,0.183
26.40,71.45,0.183
26.43,71.60,0.183
26.46,71.75,0.183
26.49,71.90,0.183
26.52,72.05,0.183
26.55,72.20,0.183
26.58,72.35,0.183
26.61,72.50,0.183
26.64,72.65,0.183
26.67,72.80,0.183
26.70,72.95,0.183
26.73,73.10,0.183
26.76,73.25,0.183
26.79,73.40,0.183
26.82,73.55,0.184
26.85,73.70,0.184
26.88,73.85,0.184
26.91,74.00,0.184
26.94,74.15,0.184
26.97,74.30,0.184
27.00,74.45,0.184
27.03,74.60,0.184
27.06,74.75,0.184
27.09,74.90,0.184
27.12,75.05,0.184
27.15,75.20,0.184
27.18,75.35,0.184
27.21,75.50,0.184
27.24,75.65,0.184
27.27,75.80,0.184
27.30,75.95,0.184
27.33,76.10,0.184
27.36,76.25,0.184
27.39,76.40,0.184
27.42,76.55,0.184
27.45,76.70,0.184
27.48,76.85,0.185
27.51,77.00,0.185
27.54,77.15,0.185
27.57,77.30,0.185
27.60,77.45,0.185
27.63,77.60,0.185
27.66,77.75,0.185
27.69,77.90,0.185
27.72,78.05,0.185
27.75,78.20,0.185
27.78,78.35,0.185
27.81,78.50,0.185
27.84,78.65,0.185
27.87,78.80,0.186
27.90,78.95,0.186
27.93,79.10,0.186
27.96,79.25,0.186
27.99,79.40,0.186
28.02,79.55,0.186
28.05,79.70,0.186
28.08,79.85,0.186
28.11,80.00,0.186
28.14,80.15,0.186
28.17,80.30,0.186
28.20,80.45,0.186
28.23,80.60,0.186
28.26,80.75,0.186
28.29,80.90,0.186
28.32,81.05,0.186
28.35,81.20,0.187
28.38,81.35,0.187
28.41,81.50,0.187
28.44,81.65,0.187
28.47,81.80,0.187
28.50,81.95,0.187
28.53,82.10,0.187
28.56,82.25,0.187
28.59,82.40,0.187
28.62,82.56,0.187
28.65,82.70,0.187
28.68,82.85,0.187
28.71,83.00,0.187
28.74,83.15,0.187
28.77,83.30,0.187
28.80,83.45,0.187
28.83,83.61,0.187
28.86,83.76,0.187
28.89,83.91,0.187
28.92,84.06,0.187
28.95,84.20,0.188
28.98,84.36,0.188
29.01,84.51,0.188
29.04,84.66,0.188
29.07,84.81,0.188
29.10,84.96,0.188
29.13,85.11,0.188
29.16,85.26,0.188
29.19,85.41,0.188
29.22,85.56,0.188
29.25,85.71,0.188
29.28,85.86,0.188
29.31,86.01,0.188
29.34,86.16,0.188
29.37,86.31,0.188
29.40,86.46,0.188
29.43,86.61,0.188
29.46,86.76,0.188
29.49,86.91,0.188
29.52,87.06,0.188
29.55,87.21,0.188
29.58,87.36,0.189
29.61,87.51,0.189
29.64,87.66,0.189
29.67,87.81,0.189
29.70,87.96,0.189
29.73,88.11,0.189
29.76,88.26,0.189
29.79,88.41,0.189
29.82,88.56,0.189
29.85,88.71,0.189
29.88,88.86,0.189
29.91,89.01,0.189
29.94,89.16,0.189
29.97,89.31,0.190
30.00,89.46,0.190
30.03,89.61,0.190
30.06,89.76,0.190
30.09,89.91,0.190
30.12,90.06,0.190
30.15,90.21,0.190
30.18,90.36,0.190
30.21,90.51,0.190
30.24,90.66,0.190
30.27,90.81,0.190
30.30,90.96,0.190
30.33,91.11,0.190
30.36,91.26,0.190
30.39,91.41,0.190
30.42,91.56,0.191
30.45,91.71,0.191
30.48,91.86,0.191
30.51,92.01,0.191
30.54,92.16,0.191
30.57,92.31,0.191
30.60,92.46,0.191
30.63,92.61,0.191
30.66,92.76,0.191
30.69,92.91,0.191
30.72,93.06,0.191
30.75,93.21,0.191
30.78,93.36,0.191
30.81,93.51,0.192
30.84,93.66,0.192
30.87,93.81,0.192
30.90,93.96,0.192
30.93,94.11,0.192
30.96,94.26,0.192
30.99,94.41,0.192
31.02,94.56,0.192
31.05,94.71,0.192
31.08,94.86,0.192
31.11,95.01,0.192
31.14,95.16,0.192
31.17,95.31,0.192
31.20,95.46,0.193
31.23,95.61,0.193
31.26,95.76,0.193
31.29,95.91,0.193
31.32,96.06,0.193
31.35,96.21,0.193
31.38,96.36,0.193
31.41,96.51,0.193
31.44,96.66,0.193
31.47,96.81,0.193
31.50,96.96,0.193
31.53,97.11,0.193
31.56,97.26,0.193
31.59,97.41,0.194
31.62,97.56,0.194
31.65,97.71,0.194
31.68,97.86,0.194
31.71,98.01,0.194
31.74,98.16,0.194
31.77,98.31,0.194
31.80,98.46,0.194
31.83,98.61,0.194
31.86,98.76,0.194
31.89,98.91,0.194
31.92,99.06,0.194
31.95,99.21,0.194
31.98,99.36,0.195
32.01,99.51,0.195
32.04,99.66,0.195
32.07,99.82,0.195
32.10,99.96,0.195
32.13,100.11,0.195
32.16,100.26,0.195
32.19,100.42,0.195
32.22,100.57,0.195
32.25,100.72,0.195
32.28,100.87,0.195
32.31,101.01,0.195
32.34,101.17,0.195
32.37,101.32,0.195
32.40,101.47,0.196
32.43,101.62,0.196
32.46,101.77,0.196
32.49,101.92,0.196
32.52,102.07,0.196
32.55,102.22,0.196
32.58,102.37,0.196
32.61,102.52,0.196
32.64,102.67,0.196
32.67,102.82,0.196
32.70,102.97,0.196
32.73,103.12,0.196
32.76,103.27,0.196
32.79,103.42,0.196
32.82,103.57,0.196
32.85,103.72,0.196
32.88,103.87,0.197
32.91,104.02,0.197
32.94,104.17,0.197
32.97,104.32,0.197
33.00,104.47,0.197
33.03,104.62,0.197
33.06,104.77,0.197
33.09,104.92,0.197
33.12,105.07,0.197
33.15,105.22,0.197
33.18,105.37,0.197
33.21,105.52,0.197
33.24,105.67,0.197
33.27,105.82,0.197
33.30,105.97,0.197
33.33,106.12,0.197
33.36,106.27,0.197
33.39,106.42,0.198
33.42,106.57,0.198
33.45,106.72,0.198
33.48,106.87,0.198
33.51,107.02,0.198
33.54,107.17,0.198
33.57,107.32,0.198
33.60,107.47,0.198
33.63,107.62,0.198
33.66,107.77,0.198
33.69,107.92,0.198
33.72,108.07,0.198
33.75,108.22,0.198
33.78,108.37,0.198
33.81,108.52,0.198
33.84,108.67,0.198
33.87,108.82,0.198
33.90,108.97,0.198
33.93,109.12,0.198
33.96,109.27,0.198
33.99,109.42,0.198
34.02,109.57,0.199
34.05,109.72,0.199
34.08,109.87,0.199
34.11,110.02,0.199
34.14,110.17,0.199
34.17,110.32,0.199
34.20,110.47,0.199
34.23,110.62,0.199
34.26,110.77,0.199
34.29,110.92,0.199
34.32,111.07,0.199
34.35,111.22,0.199
34.38,111.37,0.199
34.41,111.52,0.199
34.44,111.67,0.199
34.47,111.82,0.199
34.50,111.97,0.199
34.53,112.12,0.199
34.56,112.27,0.199
34.59,112.42,0.199
34.62,112.57,0.199
34.65,112.72,0.199
34.68,112.87,0.199
34.71,113.02,0.199
34.74,113.17,0.199
34.77,113.32,0.199
34.80,113.47,0.199
34.83,113.62,0.199
34.86,113.77,0.199
34.89,113.92,0.200
34.92,114.07,0.200
34.95,114.22,0.200
34.98,114.37,0.199
35.01,114.52,0.199
35.04,114.67,0.199
35.07,114.82,0.199
35.10,114.97,0.200
35.13,115.12,0.200
35.16,115.27,0.200
35.19,115.42,0.200
35.22,115.57,0.200
35.25,115.72,0.200
35.28,115.87,0.200
35.31,116.02,0.200
35.34,116.17,0.200
35.37,116.32,0.200
35.40,116.47,0.200
35.43,116.62,0.200
35.46,116.77,0.200
35.49,116.92,0.200
35.52,117.08,0.200
35.55,117.22,0.200
35.58,117.37,0.200
35.61,117.53,0.200
35.64,117.67,0.201
35.67,117.82,0.201
35.70,117.97,0.201
35.73,118.12,0.201
35.76,118.28,0.201
35.79,118.43,0.201
35.82,118.58,0.202
35.85,118.73,0.202
35.88,118.88,0.202
35.91,119.03,0.202
35.94,119.19,0.202
35.97,119.33,0.202
36.00,119.48,0.202
36.03,119.64,0.202
36.06,119.78,0.202
36.09,119.93,0.202
36.12,120.08,0.202
36.15,120.23,0.202
36.18,120.38,0.202
36.21,120.53,0.202
36.24,120.68,0.202
36.27,120.83,0.202
36.30,120.98,0.202
36.33,121.13,0.202
36.36,121.28,0.202
36.39,121.43,0.202
36.42,121.58,0.202
36.45,121.73,0.202
36.48,121.88,0.202
36.51,122.03,0.202
36.54,122.18,0.202
36.57,122.33,0.202
36.60,122.48,0.202
36.63,122.63,0.202
36.66,122.78,0.202
36.69,122.93,0.202
36.72,123.08,0.202
36.75,123.23,0.202
36.78,123.38,0.202
36.81,123.53,0.203
36.84,123.68,0.203
36.87,123.83,0.203
36.90,123.98,0.203
36.93,124.13,0.203
36.96,124.28,0.203
36.99,124.43,0.203
37.02,124.58,0.203
37.05,124.73,0.203
37.08,124.88,0.203
37.11,125.03,0.203
37.14,125.18,0.203
37.17,125.33,0.203
37.20,125.48,0.204
37.23,125.63,0.204
37.26,125.78,0.204
37.29,125.93,0.204
37.32,126.08,0.204
37.35,126.23,0.204
37.38,126.38,0.204
37.41,126.53,0.204
37.44,126.68,0.204
37.47,126.83,0.204
37.50,126.98,0.204
37.53,127.13,0.205
37.56,127.28,0.205
37.59,127.43,0.205
37.62,127.58,0.205
37.65,127.73,0.205
37.68,127.88,0.205
37.71,128.03,0.205
37.74,128.18,0.205
37.77,128.33,0.205
37.80,128.48,0.205
37.83,128.63,0.205
37.86,128.78,0.205
37.89,128.93,0.205
37.92,129.08,0.205
37.95,129.23,0.205
37.98,129.38,0.205
38.01,129.53,0.205
38.04,129.68,0.205
38.07,129.83,0.206
38.10,129.98,0.206
38.13,130.13,0.206
38.16,130.28,0.206
38.19,130.43,0.206
38.22,130.58,0.206
38.25,130.73,0.206
38.28,130.88,0.206
38.31,131.03,0.206
38.34,131.18,0.206
38.37,131.33,0.206
38.40,131.48,0.206
38.43,131.63,0.206
38.46,131.78,0.206
38.49,131.93,0.206
38.52,132.08,0.207
38.55,132.23,0.207
38.58,132.38,0.207
38.61,132.53,0.207
38.64,132.68,0.207
38.67,132.83,0.207
38.70,132.98,0.207
38.73,133.13,0.207
38.76,133.28,0.207
38.79,133.43,0.207
38.82,133.58,0.207
38.85,133.73,0.207
38.88,133.88,0.207
38.91,134.03,0.207
38.94,134.18,0.207
38.97,134.33,0.207
39.00,134.48,0.207
39.03,134.63,0.207
39.06,134.78,0.207
39.09,134.93,0.208
39.12,135.08,0.208
39.15,135.23,0.208
39.18,135.38,0.208
39.21,135.53,0.208
39.24,135.68,0.208
39.27,135.83,0.208
39.30,135.98,0.208
39.33,136.13,0.208
39.36,136.28,0.208
39.39,136.43,0.208
39.42,136.58,0.208
39.45,136.73,0.208
39.48,136.88,0.208
39.51,137.03,0.208
39.54,137.18,0.208
39.57,137.33,0.208
39.60,137.48,0.208
39.63,137.63,0.208
39.66,137.78,0.208
39.69,137.93,0.209
39.72,138.08,0.209
39.75,138.23,0.209
39.78,138.38,0.209
39.81,138.53,0.209
39.84,138.68,0.209
39.87,138.83,0.209
39.90,138.98,0.209
39.93,139.13,0.209
39.96,139.28,0.209
39.99,139.43,0.209
40.02,139.58,0.209
40.05,139.73,0.210
40.08,139.88,0.210
40.11,140.03,0.210
40.14,140.18,0.210
40.17,140.33,0.210
40.20,140.48,0.210
40.23,140.63,0.210
40.26,140.78,0.210
40.29,140.93,0.210
40.32,141.08,0.210
40.35,141.23,0.210
40.38,141.38,0.210
40.41,141.53,0.210
40.44,141.68,0.210
40.47,141.84,0.210
40.50,141.98,0.211
40.53,142.13,0.211
40.56,142.29,0.211
40.59,142.43,0.211
40.62,142.59,0.211
40.65,142.74,0.211
40.68,142.89,0.211
40.71,143.04,0.211
40.74,143.19,0.211
40.77,143.34,0.211
40.80,143.49,0.211
40.83,143.64,0.211
40.86,143.79,0.211
40.89,143.93,0.211
40.92,144.08,0.211
40.95,144.23,0.211
40.98,144.38,0.211
41.01,144.53,0.211
41.04,144.68,0.211
41.07,144.83,0.211
41.10,144.98,0.211
41.13,145.13,0.212
41.16,145.29,0.212
41.19,145.43,0.212
41.22,145.59,0.212
41.25,145.74,0.212
41.28,145.89,0.212
41.31,146.04,0.212
41.34,146.19,0.212
41.37,146.34,0.212
41.40,146.48,0.212
41.43,146.64,0.212
41.46,146.79,0.212
41.49,146.94,0.212
41.52,147.09,0.212
41.55,147.24,0.212
41.58,147.39,0.212
41.61,147.54,0.213
41.64,147.69,0.213
41.67,147.84,0.213
41.70,147.99,0.213
41.73,148.14,0.213
41.76,148.29,0.213
41.79,148.44,0.213
41.82,148.59,0.213
41.85,148.74,0.213
41.88,148.89,0.213
41.91,149.04,0.213
41.94,149.19,0.213
41.97,149.34,0.213
42.00,149.49,0.213
42.03,149.64,0.213
42.06,149.79,0.213
42.09,149.94,0.214
42.12,150.09,0.214
42.15,150.24,0.214
42.18,150.39,0.214
42.21,150.54,0.214
42.24,150.69,0.214
42.27,150.84,0.214
42.30,150.99,0.214
42.33,151.14,0.214
42.36,151.29,0.214
42.39,151.44,0.214
42.42,151.59,0.214
42.45,151.74,0.214
42.48,151.89,0.214
42.51,152.04,0.214
42.54,152.19,0.214
42.57,152.34,0.215
42.60,152.49,0.215
42.63,152.64,0.215
42.66,152.79,0.215
42.69,152.94,0.215
42.72,153.09,0.215
42.75,153.24,0.215
42.78,153.39,0.215
42.81,153.54,0.215
42.84,153.69,0.215
42.87,153.84,0.215
42.90,153.99,0.215
42.93,154.14,0.215
42.96,154.29,0.215
42.99,154.44,0.216
43.02,154.59,0.216
43.05,154.74,0.216
43.08,154.89,0.216
43.11,155.04,0.216
43.14,155.19,0.216
43.17,155.34,0.216
43.20,155.49,0.216
43.23,155.64,0.217
43.26,155.79,0.217
43.29,155.94,0.217
43.32,156.09,0.217
43.35,156.24,0.218
43.38,156.39,0.218
43.41,156.54,0.218
43.44,156.69,0.218
43.47,156.84,0.218
43.50,156.99,0.218
43.53,157.14,0.219
43.56,157.29,0.219
43.59,157.44,0.219
43.62,157.59,0.220
43.65,157.74,0.220
43.68,157.89,0.221
43.71,158.04,0.221
43.74,158.19,0.221
43.77,158.34,0.222
43.80,158.49,0.222
43.83,158.64,0.223
43.86,158.79,0.224
43.89,158.94,0.226
43.92,159.09,0.227
43.95,159.24,
43.98,,
43.98,,

[step]
Ramp 5.00 °C/min to -60.00 °C
Time,Temperature,Heat Flow (Normalized)
min,°C,W/g
45.99,160.12,-0.020
46.01,160.12,-0.020
46.04,160.11,-0.023
46.08,160.08,-0.050
46.11,160.03,-0.089
46.14,159.95,-0.129
46.16,159.85,-0.165
46.19,159.74,-0.190
46.23,159.62,-0.209
46.26,159.49,-0.221
46.29,159.36,-0.231
46.31,159.22,-0.241
46.34,159.08,-0.245
46.38,158.93,-0.250
46.41,158.79,-0.253
46.44,158.64,-0.254
46.46,158.50,-0.257
46.49,158.35,-0.258
46.53,158.20,-0.259
46.56,158.06,-0.260
46.59,157.91,-0.261
46.61,157.76,-0.261
46.64,157.61,-0.261
46.68,157.46,-0.262
46.71,157.32,-0.262
46.74,157.17,-0.263
46.76,157.02,-0.263
46.79,156.87,-0.264
46.83,156.72,-0.264
46.86,156.57,-0.264
46.89,156.42,-0.265
46.91,156.27,-0.265
46.94,156.13,-0.265
46.98,155.98,-0.266
47.01,155.83,-0.266
47.04,155.68,-0.266
47.06,155.53,-0.266
47.09,155.38,-0.267
47.13,155.23,-0.267
47.16,155.08,-0.267
47.19,154.93,-0.267
47.21,154.78,-0.267
47.24,154.63,-0.267
47.28,154.48,-0.267
47.31,154.33,-0.267
47.34,154.18,-0.268
47.36,154.03,-0.268
47.39,153.88,-0.268
47.43,153.73,-0.268
47.46,153.58,-0.268
47.49,153.43,-0.268
47.51,153.28,-0.268
47.54,153.13,-0.268
47.58,152.98,-0.268
47.61,152.83,-0.268
47.64,152.68,-0.268
47.66,152.53,-0.268
47.69,152.38,-0.268
47.73,152.24,-0.268
47.76,152.08,-0.268
47.79,151.93,-0.268
47.81,151.78,-0.268
47.84,151.64,-0.268
47.88,151.49,-0.268
47.91,151.33,-0.268
47.94,151.19,-0.268
47.96,151.04,-0.268
47.99,150.89,-0.268
48.03,150.74,-0.268
48.06,150.59,-0.268
48.09,150.44,-0.268
48.11,150.29,-0.268
48.14,150.14,-0.268
48.18,149.99,-0.268
48.21,149.84,-0.268
48.24,149.69,-0.268
48.26,149.54,-0.267
48.29,149.39,-0.267
48.33,149.24,-0.267
48.36,149.09,-0.267
48.39,148.94,-0.267
48.41,148.79,-0.267
48.44,148.64,-0.267
48.48,148.49,-0.267
48.51,148.34,-0.267
48.54,148.19,-0.267
48.56,148.04,-0.267
48.59,147.89,-0.267
48.63,147.74,-0.267
48.66,147.59,-0.267
48.69,147.44,-0.267
48.71,147.29,-0.267
48.74,147.14,-0.266
48.78,146.99,-0.266
48.81,146.84,-0.266
48.84,146.69,-0.266
48.86,146.54,-0.266
48.89,146.39,-0.266
48.93,146.24,-0.266
48.96,146.09,-0.266
48.99,145.94,-0.266
49.01,145.79,-0.266
49.04,145.64,-0.266
49.08,145.49,-0.266
49.11,145.34,-0.266
49.14,145.19,-0.265
49.16,145.04,-0.265
49.19,144.89,-0.265
49.23,144.74,-0.265
49.26,144.59,-0.265
49.29,144.44,-0.265
49.31,144.29,-0.265
49.34,144.14,-0.265
49.38,143.99,-0.265
49.41,143.84,-0.265
49.44,143.69,-0.265
49.46,143.54,-0.265
49.49,143.39,-0.265
49.53,143.24,-0.265
49.56,143.09,-0.265
49.59,142.94,-0.265
49.61,142.79,-0.265
49.64,142.64,-0.265
49.68,142.49,-0.265
49.71,142.34,-0.265
49.74,142.19,-0.265
49.76,142.04,-0.265
49.79,141.89,-0.265
49.83,141.74,-0.264
49.86,141.59,-0.264
49.89,141.44,-0.264
49.91,141.29,-0.264
49.94,141.14,-0.264
49.98,140.99,-0.264
50.01,140.84,-0.264
50.04,140.69,-0.264
50.06,140.54,-0.264
50.09,140.39,-0.264
50.13,140.24,-0.264
50.16,140.09,-0.264
50.19,139.94,-0.264
50.21,139.79,-0.264
50.24,139.64,-0.264
50.28,139.49,-0.264
50.31,139.34,-0.264
50.34,139.19,-0.264
50.36,139.04,-0.263
50.39,138.89,-0.263
50.43,138.74,-0.263
50.46,138.59,-0.263
50.49,138.44,-0.263
50.51,138.29,-0.263
50.54,138.14,-0.263
50.58,138.00,-0.263
50.61,137.84,-0.263
50.64,137.70,-0.263
50.66,137.54,-0.263
50.69,137.40,-0.263
50.73,137.25,-0.263
50.76,137.10,-0.263
50.79,136.94,-0.263
50.81,136.79,-0.263
50.84,136.64,-0.263
50.88,136.50,-0.263
50.91,136.35,-0.262
50.94,136.19,-0.262
50.96,136.05,-0.262
50.99,135.89,-0.262
51.03,135.74,-0.262
51.06,135.60,-0.262
51.09,135.45,-0.262
51.11,135.30,-0.262
51.14,135.15,-0.262
51.18,135.00,-0.262
51.21,134.84,-0.262
51.24,134.70,-0.262
51.26,134.55,-0.262
51.29,134.40,-0.262
51.33,134.25,-0.262
51.36,134.10,-0.262
51.39,133.95,-0.262
51.41,133.80,-0.262
51.44,133.65,-0.261
51.48,133.50,-0.261
51.51,133.35,-0.261
51.54,133.20,-0.261
51.56,133.05,-0.261
51.59,132.90,-0.261
51.63,132.75,-0.261
51.66,132.60,-0.261
51.69,132.45,-0.261
51.71,132.30,-0.261
51.74,132.15,-0.261
51.78,132.00,-0.261
51.81,131.85,-0.261
51.84,131.70,-0.261
51.86,131.55,-0.261
51.89,131.40,-0.261
51.93,131.25,-0.261
51.96,131.10,-0.261
51.99,130.95,-0.261
52.01,130.80,-0.261
52.04,130.65,-0.261
52.08,130.50,-0.261
52.11,130.35,-0.260
52.14,130.20,-0.260
52.16,130.05,-0.260
52.19,129.90,-0.260
52.23,129.75,-0.260
52.26,129.60,-0.260
52.29,129.45,-0.260
52.31,129.30,-0.260
52.34,129.15,-0.260
52.38,129.00,-0.260
52.41,128.85,-0.260
52.44,128.70,-0.260
52.46,128.55,-0.260
52.49,128.40,-0.260
52.53,128.25,-0.260
52.56,128.10,-0.260
52.59,127.95,-0.260
52.61,127.80,-0.260
52.64,127.65,-0.260
52.68,127.50,-0.260
52.71,127.35,-0.260
52.74,127.20,-0.259
52.76,127.05,-0.259
52.79,126.90,-0.259
52.83,126.75,-0.259
52.86,126.60,-0.259
52.89,126.45,-0.259
52.91,126.30,-0.259
52.94,126.15,-0.259
52.98,126.00,-0.259
53.01,125.85,-0.259
53.04,125.70,-0.259
53.06,125.55,-0.259
53.09,125.40,-0.259
53.13,125.25,-0.259
53.16,125.10,-0.259
53.19,124.95,-0.259
53.21,124.80,-0.259
53.24,124.65,-0.259
53.28,124.50,-0.259
53.31,124.35,-0.258
53.34,124.20,-0.258
53.36,124.05,-0.258
53.39,123.90,-0.258
53.43,123.75,-0.258
53.46,123.60,-0.258
53.49,123.45,-0.258
53.51,123.30,-0.258
53.54,123.15,-0.258
53.58,123.00,-0.258
53.61,122.85,-0.258
53.64,122.70,-0.258
53.66,122.55,-0.258
53.69,122.40,-0.258
53.73,122.25,-0.258
53.76,122.10,-0.258
53.79,121.95,-0.258
53.81,121.80,-0.258
53.84,121.65,-0.257
53.88,121.50,-0.257
53.91,121.35,-0.257
53.94,121.20,-0.257
53.96,121.05,-0.257
53.99,120.90,-0.257
54.03,120.75,-0.257
54.06,120.60,-0.257
54.09,120.45,-0.257
54.11,120.30,-0.257
54.14,120.15,-0.257
54.18,120.00,-0.257
54.21,119.85,-0.257
54.24,119.70,-0.257
54.26,119.55,-0.257
54.29,119.40,-0.257
54.33,119.25,-0.257
54.36,119.10,-0.256
54.39,118.95,-0.256
54.41,118.80,-0.256
54.44,118.65,-0.256
54.48,118.50,-0.256
54.51,118.35,-0.256
54.54,118.20,-0.256
54.56,118.05,-0.256
54.59,117.90,-0.256
54.63,117.76,-0.256
54.66,117.61,-0.256
54.69,117.46,-0.256
54.71,117.31,-0.256
[...]
280.16,-39.89,0.065
280.18,-39.82,0.065
280.19,-39.76,0.065
280.20,-39.69,0.065
280.22,-39.63,0.065
280.23,-39.56,0.065
280.24,-39.49,0.065
280.26,-39.42,0.065
280.27,-39.36,0.065
280.28,-39.29,0.065
280.29,-39.23,0.065
280.31,-39.16,0.065
280.32,-39.09,0.065
280.33,-39.03,0.065
280.35,-38.96,0.065
280.36,-38.89,0.065
280.38,-38.82,0.065
280.39,-38.76,0.065
280.40,-38.69,0.065
280.42,-38.62,0.065
280.43,-38.56,0.065
280.44,-38.49,0.065
280.46,-38.42,0.065
280.47,-38.36,0.065
280.48,-38.29,0.065
280.49,-38.22,0.065
280.51,-38.16,0.065
280.52,-38.09,0.066
280.53,-38.02,0.066
280.55,-37.96,0.066
280.56,-37.89,0.066
280.58,-37.82,0.066
280.59,-37.76,0.066
280.60,-37.69,0.066
280.62,-37.62,0.066
280.63,-37.56,0.066
280.64,-37.49,0.066
280.66,-37.42,0.066
280.67,-37.35,0.066
280.68,-37.29,0.066
280.69,-37.22,0.066
280.71,-37.16,0.066
280.72,-37.09,0.066
280.73,-37.02,0.066
280.75,-36.95,0.066
280.76,-36.89,0.066
280.78,-36.82,0.066
280.79,-36.75,0.066
280.80,-36.69,0.066
280.82,-36.62,0.066
280.83,-36.55,0.066
280.84,-36.49,0.066
280.86,-36.42,0.066
280.87,-36.35,0.066
280.88,-36.29,0.066
280.89,-36.22,0.066
280.91,-36.15,0.066
280.92,-36.09,0.066
280.93,-36.02,0.066
280.95,-35.95,0.066
280.96,-35.89,0.066
280.98,-35.82,0.066
280.99,-35.75,0.066
281.00,-35.69,0.066
281.02,-35.62,0.066
281.03,-35.55,0.066
281.04,-35.49,0.066
281.06,-35.42,0.066
281.07,-35.35,0.066
281.08,-35.29,0.066
281.09,-35.22,0.066
281.11,-35.15,0.066
281.12,-35.09,0.066
281.13,-35.02,0.066
281.15,-34.95,0.066
281.16,-34.89,0.066
281.18,-34.82,0.066
281.19,-34.75,0.066
281.20,-34.68,0.066
281.22,-34.62,0.066
281.23,-34.55,0.066
281.24,-34.48,0.066
281.26,-34.42,0.066
281.27,-34.35,0.066
281.28,-34.29,0.066
281.29,-34.22,0.066
281.31,-34.15,0.066
281.32,-34.08,0.066
281.33,-34.02,0.066
281.35,-33.95,0.066
281.36,-33.88,0.066
281.38,-33.82,0.066
281.39,-33.75,0.066
281.40,-33.68,0.066
281.42,-33.62,0.066
281.43,-33.55,0.066
281.44,-33.48,0.066
281.46,-33.42,0.066
281.47,-33.35,0.067
281.48,-33.28,0.067
281.49,-33.22,0.067
281.51,-33.15,0.067
281.52,-33.08,0.067
281.53,-33.02,0.067
281.55,-32.95,0.067
281.56,-32.89,0.067
281.58,-32.82,0.067
281.59,-32.75,0.067
281.60,-32.68,0.067
281.62,-32.62,0.067
281.63,-32.55,0.067
281.64,-32.48,0.067
281.66,-32.42,0.067
281.67,-32.35,0.067
281.68,-32.28,0.067
281.69,-32.22,0.067
281.71,-32.15,0.067
281.72,-32.08,0.067
281.73,-32.01,0.067
281.75,-31.95,0.067
281.76,-31.88,0.067
281.78,-31.81,0.067
281.79,-31.75,0.067
281.80,-31.68,0.067
281.82,-31.62,0.067
281.83,-31.55,0.067
281.84,-31.48,0.067
281.86,-31.42,0.067
281.87,-31.35,0.067
281.88,-31.28,0.067
281.89,-31.21,0.067
281.91,-31.15,0.067
281.92,-31.08,0.067
281.93,-31.01,0.067
281.95,-30.95,0.067
281.96,-30.88,0.067
281.98,-30.81,0.067
281.99,-30.75,0.067
282.00,-30.68,0.067
282.02,-30.61,0.067
282.03,-30.55,0.067
282.04,-30.48,0.067
282.06,-30.41,0.067
282.07,-30.35,0.067
282.08,-30.28,0.067
282.09,-30.21,0.068
282.11,-30.15,0.068
282.12,-30.08,0.068
282.13,-30.01,0.068
282.15,-29.94,0.068
282.16,-29.88,0.068
282.18,-29.81,0.068
282.19,-29.75,0.068
282.20,-29.68,0.068
282.22,-29.61,0.068
282.23,-29.55,0.068
282.24,-29.48,0.068
282.26,-29.41,0.068
282.27,-29.35,0.068
282.28,-29.28,0.068
282.29,-29.21,0.068
282.31,-29.15,0.068
282.32,-29.08,0.068
282.33,-29.01,0.068
282.35,-28.95,0.068
282.36,-28.88,0.068
282.38,-28.81,0.068
282.39,-28.74,0.068
282.40,-28.68,0.068
282.42,-28.61,0.068
282.43,-28.54,0.068
282.44,-28.48,0.068
282.46,-28.41,0.068
282.47,-28.34,0.068
282.48,-28.28,0.068
282.49,-28.21,0.068
282.51,-28.14,0.068
282.52,-28.08,0.068
282.53,-28.01,0.068
282.55,-27.94,0.068
282.56,-27.88,0.068
282.58,-27.81,0.068
282.59,-27.74,0.068
282.60,-27.68,0.068
282.62,-27.61,0.068
282.63,-27.54,0.068
282.64,-27.48,0.068
282.66,-27.41,0.068
282.67,-27.34,0.068
282.68,-27.28,0.068
282.69,-27.21,0.068
282.71,-27.14,0.068
282.72,-27.08,0.068
282.73,-27.01,0.068
282.75,-26.94,0.069
282.76,-26.88,0.069
282.78,-26.81,0.069
282.79,-26.74,0.069
282.80,-26.68,0.069
282.82,-26.61,0.069
282.83,-26.54,0.069
282.84,-26.48,0.069
282.86,-26.41,0.069
282.87,-26.34,0.069
282.88,-26.28,0.069
282.89,-26.21,0.069
282.91,-26.14,0.069
282.92,-26.08,0.069
282.93,-26.01,0.069
282.95,-25.94,0.069
282.96,-25.88,0.069
282.98,-25.81,0.069
282.99,-25.74,0.069
283.00,-25.68,0.069
283.02,-25.61,0.069
283.03,-25.54,0.069
283.04,-25.47,0.069
283.06,-25.41,0.069
283.07,-25.34,0.069
283.08,-25.27,0.069
283.09,-25.21,0.069
283.11,-25.14,0.069
283.12,-25.07,0.069
283.13,-25.01,0.069
283.15,-24.94,0.069
283.16,-24.87,0.069
283.18,-24.81,0.069
283.19,-24.74,0.069
283.20,-24.67,0.069
283.22,-24.61,0.069
283.23,-24.54,0.069
283.24,-24.47,0.069
283.26,-24.41,0.069
283.27,-24.34,0.069
283.28,-24.27,0.069
283.29,-24.21,0.069
283.31,-24.14,0.069
283.32,-24.07,0.069
283.33,-24.01,0.069
283.35,-23.94,0.069
283.36,-23.87,0.069
283.38,-23.81,0.069
283.39,-23.74,0.069
283.40,-23.67,0.069
283.42,-23.61,0.069
283.43,-23.54,0.069
283.44,-23.47,0.069
283.46,-23.41,0.069
283.47,-23.34,0.070
283.48,-23.27,0.070
283.49,-23.21,0.070
283.51,-23.14,0.070
283.52,-23.07,0.070
283.53,-23.01,0.070
283.55,-22.94,0.070
283.56,-22.87,0.070
283.58,-22.80,0.070
283.59,-22.74,0.070
283.60,-22.67,0.070
283.62,-22.61,0.070
283.63,-22.54,0.070
283.64,-22.47,0.070
283.66,-22.41,0.070
283.67,-22.34,0.070
283.68,-22.27,0.070
283.69,-22.21,0.070
283.71,-22.14,0.070
283.72,-22.07,0.070
283.73,-22.01,0.070
283.75,-21.94,0.070
283.76,-21.87,0.070
283.78,-21.80,0.070
283.79,-21.74,0.070
283.80,-21.67,0.070
283.82,-21.60,0.070
283.83,-21.54,0.070
283.84,-21.47,0.070
283.86,-21.41,0.070
283.87,-21.34,0.070
283.88,-21.27,0.070
283.89,-21.20,0.070
283.91,-21.14,0.070
283.92,-21.07,0.070
283.93,-21.00,0.070
283.95,-20.94,0.070
283.96,-20.87,0.070
283.98,-20.80,0.070
283.99,-20.74,0.070
284.00,-20.67,0.070
284.02,-20.60,0.070
284.03,-20.54,0.070
284.04,-20.47,0.070
284.06,-20.40,0.070
284.07,-20.34,0.070
284.08,-20.27,0.071
284.09,-20.20,0.071
284.11,-20.14,0.071
284.12,-20.07,0.071
284.13,-20.00,0.071
284.15,-19.94,0.071
284.16,-19.87,0.071
284.18,-19.80,0.071
284.19,-19.74,0.071
284.20,-19.67,0.071
284.22,-19.60,0.071
284.23,-19.54,0.071
284.24,-19.47,0.071
284.26,-19.40,0.071
284.27,-19.34,0.071
284.28,-19.27,0.071
284.29,-19.20,0.071
284.31,-19.14,0.071
284.32,-19.07,0.071
284.33,-19.00,0.071
284.35,-18.94,0.071
284.36,-18.87,0.071
284.38,-18.80,0.071
284.39,-18.73,0.071
284.40,-18.67,0.071
284.42,-18.60,0.071
284.43,-18.54,0.071
284.44,-18.47,0.071
284.46,-18.40,0.071
284.47,-18.33,0.071
284.48,-18.27,0.071
284.49,-18.20,0.071
284.51,-18.13,0.071
284.52,-18.07,0.071
284.53,-18.00,0.071
284.55,-17.93,0.071
284.56,-17.87,0.071
284.58,-17.80,0.071
284.59,-17.73,0.071
284.60,-17.67,0.071
284.62,-17.60,0.071
284.63,-17.53,0.071
284.64,-17.47,0.071
284.66,-17.40,0.071
284.67,-17.33,0.071
284.68,-17.27,0.071
284.69,-17.20,0.071
284.71,-17.13,0.071
284.72,-17.07,0.071
284.73,-17.00,0.071
284.75,-16.93,0.071
284.76,-16.87,0.072
284.78,-16.80,0.072
284.79,-16.73,0.072
284.80,-16.67,0.072
284.82,-16.60,0.072
284.83,-16.53,0.072
284.84,-16.46,0.072
284.86,-16.40,0.072
284.87,-16.33,0.072
284.88,-16.27,0.072
284.89,-16.20,0.072
284.91,-16.13,0.072
284.92,-16.07,0.072
284.93,-16.00,0.072
284.95,-15.93,0.072
284.96,-15.87,0.072
284.98,-15.80,0.072
284.99,-15.73,0.072
285.00,-15.67,0.072
285.02,-15.60,0.072
285.03,-15.53,0.072
285.04,-15.47,0.072
285.06,-15.40,0.072
285.07,-15.33,0.072
285.08,-15.27,0.072
285.09,-15.20,0.072
285.11,-15.13,0.072
285.12,-15.07,0.072
285.13,-15.00,0.072
285.15,-14.93,0.072
285.16,-14.86,0.072
285.18,-14.80,0.072
285.19,-14.73,0.072
285.20,-14.66,0.072
285.22,-14.60,0.072
285.23,-14.53,0.072
285.24,-14.46,0.072
285.26,-14.40,0.072
285.27,-14.33,0.072
285.28,-14.26,0.072
285.29,-14.20,0.072
285.31,-14.13,0.072
285.32,-14.06,0.072
285.33,-14.00,0.072
285.35,-13.93,0.072
285.36,-13.86,0.072
285.38,-13.80,0.072
285.39,-13.73,0.073
285.40,-13.66,0.073
285.42,-13.60,0.073
285.43,-13.53,0.073
285.44,-13.46,0.073
285.46,-13.40,0.073
285.47,-13.33,0.073
285.48,-13.26,0.073
285.49,-13.20,0.073
285.51,-13.13,0.073
285.52,-13.06,0.073
285.53,-13.00,0.073
285.55,-12.93,0.073
285.56,-12.86,0.073
285.58,-12.80,0.073
285.59,-12.73,0.073
285.60,-12.66,0.073
285.62,-12.60,0.073
285.63,-12.53,0.073
285.64,-12.47,0.073
285.66,-12.40,0.073
285.67,-12.33,0.073
285.68,-12.26,0.073
285.69,-12.20,0.073
285.71,-12.13,0.073
285.72,-12.06,0.073
285.73,-12.00,0.073
285.75,-11.93,0.073
285.76,-11.86,0.073
285.78,-11.80,0.073
285.79,-11.73,0.073
285.80,-11.66,0.073
285.82,-11.60,0.073
285.83,-11.53,0.073
285.84,-11.46,0.073
285.86,-11.40,0.073
285.87,-11.33,0.073
285.88,-11.26,0.073
285.89,-11.20,0.073
285.91,-11.13,0.073
285.92,-11.06,0.073
285.93,-11.00,0.073
285.95,-10.93,0.073
285.96,-10.86,0.073
285.98,-10.80,0.073
285.99,-10.73,0.073
286.00,-10.66,0.073
286.02,-10.60,0.073
286.03,-10.53,0.074
286.04,-10.46,0.074
286.06,-10.40,0.074
286.07,-10.33,0.074
286.08,-10.26,0.074
286.09,-10.20,0.074
286.11,-10.13,0.074
286.12,-10.06,0.074
286.13,-10.00,0.074
286.15,-9.93,0.074
286.16,-9.86,0.074
286.18,-9.80,0.074
286.19,-9.73,0.074
286.20,-9.66,0.074
286.22,-9.59,0.074
286.23,-9.53,0.074
286.24,-9.46,0.074
286.26,-9.40,0.074
286.27,-9.33,0.074
286.28,-9.26,0.074
286.29,-9.20,0.074
286.31,-9.13,0.074
286.32,-9.06,0.074
286.33,-8.99,0.074
286.35,-8.93,0.074
286.36,-8.86,0.074
286.38,-8.79,0.074
286.39,-8.73,0.074
286.40,-8.66,0.074
286.42,-8.59,0.074
286.43,-8.53,0.074
286.44,-8.46,0.074
286.46,-8.39,0.074
286.47,-8.33,0.074
286.48,-8.26,0.074
286.49,-8.19,0.074
286.51,-8.13,0.074
286.52,-8.06,0.074
286.53,-7.99,0.075
286.55,-7.93,0.075
286.56,-7.86,0.075
286.58,-7.79,0.075
286.59,-7.73,0.075
286.60,-7.66,0.075
286.62,-7.59,0.075
286.63,-7.52,0.075
286.64,-7.46,0.075
286.66,-7.39,0.075
286.67,-7.33,0.075
286.68,-7.26,0.075
286.69,-7.19,0.075
286.71,-7.13,0.075
286.72,-7.06,0.075
286.73,-6.99,0.075
286.75,-6.93,0.075
286.76,-6.86,0.075
286.78,-6.79,0.075
286.79,-6.73,0.075
286.80,-6.66,0.075
286.82,-6.59,0.075
286.83,-6.53,0.075
286.84,-6.46,0.075
286.86,-6.39,0.075
286.87,-6.32,0.075
286.88,-6.26,0.075
286.89,-6.19,0.075
286.91,-6.12,0.075
286.92,-6.06,0.075
286.93,-5.99,0.075
286.95,-5.93,0.075
286.96,-5.86,0.076
286.98,-5.79,0.076
286.99,-5.73,0.076
287.00,-5.66,0.076
287.02,-5.59,0.076
287.03,-5.52,0.076
287.04,-5.46,0.076
287.06,-5.39,0.076
287.07,-5.33,0.076
287.08,-5.26,0.076
287.09,-5.19,0.076
287.11,-5.12,0.076
287.12,-5.06,0.076
287.13,-4.99,0.076
287.15,-4.92,0.076
287.16,-4.86,0.076
287.18,-4.79,0.076
287.19,-4.72,0.076
287.20,-4.66,0.076
287.22,-4.59,0.076
287.23,-4.52,0.076
287.24,-4.46,0.076
287.26,-4.39,0.076
287.27,-4.32,0.076
287.28,-4.26,0.076
287.29,-4.19,0.076
287.31,-4.12,0.076
287.32,-4.06,0.076
287.33,-3.99,0.076
287.35,-3.92,0.076
287.36,-3.86,0.076
287.38,-3.79,0.077
287.39,-3.72,0.077
287.40,-3.66,0.077
287.42,-3.59,0.077
287.43,-3.52,0.077
287.44,-3.45,0.077
287.46,-3.39,0.077
287.47,-3.32,0.077
287.48,-3.26,0.077
287.49,-3.19,0.077
287.51,-3.12,0.077
287.52,-3.06,0.077
287.53,-2.99,0.077
287.55,-2.92,0.077
287.56,-2.85,0.077
287.58,-2.79,0.077
287.59,-2.72,0.077
287.60,-2.65,0.077
287.62,-2.59,0.077
287.63,-2.52,0.077
287.64,-2.45,0.077
287.66,-2.39,0.077
287.67,-2.32,0.077
287.68,-2.26,0.077
287.69,-2.19,0.077
287.71,-2.12,0.077
287.72,-2.05,0.077
287.73,-1.99,0.077
287.75,-1.92,0.077
287.76,-1.85,0.077
287.78,-1.79,0.077
287.79,-1.72,0.077
287.80,-1.65,0.077
287.82,-1.59,0.077
287.83,-1.52,0.077
287.84,-1.45,0.077
287.86,-1.39,0.077
287.87,-1.32,0.078
287.88,-1.25,0.078
287.89,-1.19,0.078
287.91,-1.12,0.078
287.92,-1.05,0.078
287.93,-0.99,0.078
287.95,-0.92,0.078
287.96,-0.85,0.078
287.98,-0.79,0.078
287.99,-0.72,0.078
288.00,-0.65,0.078
288.02,-0.59,0.078
288.03,-0.52,0.078
288.04,-0.45,0.078
288.06,-0.38,0.078
288.07,-0.32,0.078
288.08,-0.25,0.078
288.09,-0.19,0.078
288.11,-0.12,0.078
288.12,-0.05,0.078
288.13,0.01,0.078
288.15,0.08,0.078
288.16,0.15,0.078
288.18,0.21,0.078
288.19,0.28,0.078
288.20,0.35,0.078
288.22,0.41,0.078
288.23,0.48,0.078
288.24,0.55,0.078
288.26,0.62,0.078
288.27,0.68,0.078
288.28,0.75,0.078
288.29,0.82,0.078
288.31,0.88,0.078
288.32,0.95,0.078
288.33,1.01,0.078
288.35,1.08,0.078
288.36,1.15,0.078
288.38,1.22,0.078
288.39,1.28,0.078
288.40,1.35,0.079
288.42,1.42,0.079
288.43,1.48,0.079
288.44,1.55,0.079
288.46,1.62,0.079
288.47,1.68,0.079
288.48,1.75,0.079
288.49,1.82,0.079
288.51,1.88,0.079
288.52,1.95,0.079
288.53,2.02,0.079
288.55,2.08,0.079
288.56,2.15,0.079
288.58,2.22,0.079
288.59,2.28,0.079
288.60,2.35,0.079
288.62,2.42,0.079
288.63,2.48,0.079
288.64,2.55,0.079
288.66,2.62,0.079
288.67,2.68,0.079
288.68,2.75,0.079
288.69,2.82,0.079
288.71,2.88,0.079
288.72,2.95,0.079
288.73,3.02,0.079
288.75,3.08,0.079
288.76,3.15,0.079
288.78,3.22,0.079
288.79,3.28,0.079
288.80,3.35,0.079
288.82,3.42,0.079
288.83,3.49,0.080
288.84,3.55,0.080
288.86,3.62,0.080
288.87,3.68,0.080
288.88,3.75,0.080
288.89,3.82,0.080
288.91,3.89,0.080
288.92,3.95,0.080
288.93,4.02,0.080
288.95,4.09,0.080
288.96,4.15,0.080
288.98,4.22,0.080
288.99,4.28,0.080
289.00,4.35,0.080
289.02,4.42,0.080
289.03,4.48,0.080
289.04,4.55,0.080
289.06,4.62,0.080
289.07,4.69,0.080
289.08,4.75,0.080
289.09,4.82,0.080
289.11,4.89,0.080
289.12,4.95,0.080
289.13,5.02,0.080
289.15,5.09,0.080
289.16,5.15,0.080
289.18,5.22,0.080
289.19,5.28,0.080
289.20,5.35,0.080
289.22,5.42,0.080
289.23,5.48,0.080
289.24,5.55,0.080
289.26,5.62,0.080
289.27,5.69,0.080
289.28,5.75,0.080
289.29,5.82,0.080
289.31,5.89,0.080
289.32,5.95,0.081
289.33,6.02,0.081
289.35,6.09,0.081
289.36,6.15,0.081
289.38,6.22,0.081
289.39,6.29,0.081
289.40,6.35,0.081
289.42,6.42,0.081
289.43,6.49,0.081
289.44,6.55,0.081
289.46,6.62,0.081
289.47,6.69,0.081
289.48,6.75,0.081
289.49,6.82,0.081
289.51,6.89,0.081
289.52,6.95,0.081
289.53,7.02,0.081
289.55,7.09,0.081
289.56,7.15,0.081
289.58,7.22,0.081
289.59,7.29,0.081
289.60,7.35,0.081
289.62,7.42,0.081
289.63,7.49,0.081
289.64,7.56,0.081
289.66,7.62,0.081
289.67,7.69,0.081
289.68,7.75,0.081
289.69,7.82,0.081
289.71,7.89,0.081
289.72,7.96,0.082
289.73,8.02,0.082
289.75,8.09,0.082
289.76,8.16,0.082
289.78,8.22,0.082
289.79,8.29,0.082
289.80,8.36,0.082
289.82,8.42,0.082
289.83,8.49,0.082
289.84,8.55,0.082
289.86,8.62,0.082
289.87,8.69,0.082
289.88,8.76,0.082
289.89,8.82,0.082
289.91,8.89,0.082
289.92,8.95,0.082
289.93,9.02,0.082
289.95,9.09,0.082
289.96,9.16,0.082
289.98,9.22,0.082
289.99,9.29,0.082
290.00,9.36,0.082
290.02,9.42,0.082
290.03,9.49,0.082
290.04,9.56,0.082
290.06,9.62,0.082
290.07,9.69,0.082
290.08,9.76,0.082
290.09,9.82,0.082
290.11,9.89,0.083
290.12,9.96,0.083
290.13,10.02,0.083
290.15,10.09,0.083
290.16,10.16,0.083
290.18,10.22,0.083
290.19,10.29,0.083
290.20,10.36,0.083
290.22,10.42,0.083
290.23,10.49,0.083
290.24,10.56,0.083
290.26,10.62,0.083
290.27,10.69,0.083
290.28,10.76,0.083
290.29,10.82,0.083
290.31,10.89,0.083
290.32,10.96,0.083
290.33,11.02,0.083
290.35,11.09,0.083
290.36,11.16,0.083
290.38,11.23,0.083
290.39,11.29,0.083
290.40,11.36,0.083
290.42,11.42,0.083
290.43,11.49,0.083
290.44,11.56,0.083
290.46,11.63,0.083
290.47,11.69,0.083
290.48,11.76,0.083
290.49,11.82,0.083
290.51,11.89,0.083
290.52,11.96,0.084
290.53,12.02,0.084
290.55,12.09,0.084
290.56,12.16,0.084
290.58,12.22,0.084
290.59,12.29,0.084
290.60,12.36,0.084
290.62,12.43,0.084
290.63,12.49,0.084
290.64,12.56,0.084
290.66,12.63,0.084
290.67,12.69,0.084
290.68,12.76,0.084
290.69,12.83,0.084
290.71,12.89,0.084
290.72,12.96,0.084
290.73,13.03,0.084
290.75,13.09,0.084
290.76,13.16,0.084
290.78,13.22,0.084
290.79,13.29,0.084
290.80,13.36,0.084
290.82,13.43,0.084
290.83,13.49,0.084
290.84,13.56,0.084
290.86,13.63,0.085
290.87,13.69,0.085
290.88,13.76,0.085
290.89,13.83,0.085
290.91,13.89,0.085
290.92,13.96,0.085
290.93,14.03,0.085
290.95,14.09,0.085
290.96,14.16,0.085
290.98,14.23,0.085
290.99,14.29,0.085
291.00,14.36,0.085
291.02,14.43,0.085
291.03,14.49,0.085
291.04,14.56,0.085
291.06,14.63,0.085
291.07,14.69,0.085
291.08,14.76,0.085
291.09,14.83,0.085
291.11,14.89,0.085
291.12,14.96,0.085
291.13,15.03,0.085
291.15,15.09,0.085
291.16,15.16,0.086
291.18,15.23,0.086
291.19,15.29,0.086
291.20,15.36,0.086
291.22,15.43,0.086
291.23,15.49,0.086
291.24,15.56,0.086
291.26,15.63,0.086
291.27,15.69,0.086
291.28,15.76,0.086
291.29,15.83,0.086
291.31,15.89,0.086
291.32,15.96,0.086
291.33,16.03,0.086
291.35,16.09,0.086
291.36,16.16,0.086
291.38,16.23,0.086
291.39,16.29,0.086
291.40,16.36,0.086
291.42,16.43,0.086
291.43,16.49,0.086
291.44,16.56,0.086
291.46,16.63,0.086
291.47,16.69,0.086
291.48,16.76,0.086
291.49,16.83,0.086
291.51,16.89,0.087
291.52,16.96,0.087
291.53,17.03,0.087
291.55,17.10,0.087
291.56,17.16,0.087
291.58,17.23,0.087
291.59,17.29,0.087
291.60,17.36,0.087
291.62,17.43,0.087
291.63,17.49,0.087
291.64,17.56,0.087
291.66,17.63,0.087
291.67,17.69,0.087
291.68,17.76,0.087
291.69,17.83,0.087
291.71,17.90,0.087
291.72,17.96,0.087
291.73,18.03,0.087
291.75,18.10,0.087
291.76,18.16,0.087
291.78,18.23,0.087
291.79,18.30,0.087
291.80,18.36,0.087
291.82,18.43,0.087
291.83,18.50,0.087
291.84,18.56,0.087
291.86,18.63,0.087
291.87,18.70,0.088
291.88,18.76,0.088
291.89,18.83,0.088
291.91,18.90,0.088
291.92,18.96,0.088
291.93,19.03,0.088
291.95,19.10,0.088
291.96,19.16,0.088
291.98,19.23,0.088
291.99,19.30,0.088
292.00,19.36,0.088
292.02,19.43,0.088
292.03,19.50,0.088
292.04,19.56,0.088
292.06,19.63,0.088
292.07,19.70,0.088
292.08,19.76,0.088
292.09,19.83,0.088
292.11,19.90,0.088
292.12,19.96,0.088
292.13,20.03,0.088
292.15,20.10,0.088
292.16,20.16,0.088
292.18,20.23,0.088
292.19,20.30,0.088
292.20,20.36,0.088
292.22,20.43,0.089
292.23,20.50,0.089
292.24,20.56,0.089
292.26,20.63,0.089
292.27,20.70,0.089
292.28,20.76,0.089
292.29,20.83,0.089
292.31,20.90,0.089
292.32,20.97,0.089
292.33,21.03,0.089
292.35,21.10,0.089
292.36,21.17,0.089
292.38,21.23,0.089
292.39,21.30,0.089
292.40,21.37,0.089
292.42,21.43,0.089
292.43,21.50,0.089
292.44,21.57,0.089
292.46,21.63,0.089
292.47,21.70,0.089
292.48,21.77,0.089
292.49,21.83,0.090
292.51,21.90,0.090
292.52,21.97,0.090
292.53,22.03,0.090
292.55,22.10,0.090
292.56,22.17,0.090
292.58,22.23,0.090
292.59,22.30,0.090
292.60,22.37,0.090
292.62,22.43,0.090
292.63,22.50,0.090
292.64,22.57,0.090
292.66,22.63,0.090
292.67,22.70,0.090
292.68,22.77,0.090
292.69,22.83,0.090
292.71,22.90,0.090
292.72,22.97,0.090
292.73,23.03,0.090
292.75,23.10,0.090
292.76,23.17,0.090
292.78,23.23,0.090
292.79,23.30,0.090
292.80,23.37,0.090
292.82,23.43,0.090
292.83,23.50,0.091
292.84,23.57,0.091
292.86,23.63,0.091
292.87,23.70,0.091
292.88,23.77,0.091
292.89,23.83,0.091
292.91,23.90,0.091
292.92,23.97,0.091
292.93,24.03,0.091
292.95,24.10,0.091
292.96,24.17,0.091
292.98,24.23,0.091
292.99,24.30,0.091
293.00,24.37,0.091
293.02,24.43,0.091
293.03,24.50,0.091
293.04,24.57,0.091
293.06,24.64,0.091
293.07,24.70,0.091
293.08,24.77,0.091
293.09,24.84,0.091
293.11,24.90,0.091
293.12,24.97,0.091
293.13,25.03,0.091
293.15,25.10,0.092
293.16,25.17,0.092
293.18,25.23,0.092
293.19,25.30,0.092
293.20,25.37,0.092
293.22,25.43,0.092
293.23,25.50,0.092
293.24,25.57,0.092
293.26,25.63,0.092
293.27,25.70,0.092
293.28,25.77,0.092
293.29,25.83,0.092
293.31,25.90,0.092
293.32,25.97,0.092
293.33,26.03,0.092
293.35,26.10,0.092
293.36,26.17,0.092
293.38,26.23,0.092
293.39,26.30,0.092
293.40,26.37,0.092
293.42,26.43,0.092
293.43,26.50,0.092
293.44,26.57,0.093
293.46,26.63,0.093
293.47,26.70,0.093
293.48,26.77,0.093
293.49,26.83,0.093
293.51,26.90,0.093
293.52,26.97,0.093
293.53,27.04,0.093
293.55,27.10,0.093
293.56,27.17,0.093
293.58,27.23,0.093
293.59,27.30,0.093
293.60,27.37,0.093
293.62,27.43,0.093
293.63,27.50,0.093
293.64,27.57,0.093
293.66,27.63,0.093
293.67,27.70,0.093
293.68,27.77,0.093
293.69,27.83,0.094
293.71,27.90,0.094
293.72,27.97,0.094
293.73,28.04,0.094
293.75,28.10,0.094
293.76,28.17,0.094
293.78,28.24,0.094
293.79,28.30,0.094
293.80,28.37,0.094
293.82,28.43,0.094
293.83,28.50,0.094
293.84,28.57,0.094
293.86,28.64,0.094
293.87,28.70,0.094
293.88,28.77,0.094
293.89,28.84,0.094
293.91,28.90,0.094
293.92,28.97,0.094
293.93,29.04,
293.95,29.10,
293.96,29.17,
293.98,29.24,
293.99,,