File: DSC/Olivia/2025_08_05_PVP29_TS_n60C_200C_10Cmin_x3.csv
Filename,2025_08_05_PVP29_TS_n60C_200C_10Cmin_x3
Instrument name,DSC2A-00468 (192.168.1.100)
Operator,Yarger
rundate,8/6/2025
Sample name,2025_08_05_PVP29_TS_n60C_200C_10Cmin_x3
proceduresegments,Data Off ; Equilibrate -60.00 °C; Data On ; Ramp 10.00 °C/min to 200.00 °C; Data Off ; Isothermal 2.0 min; Data On ; Ramp 10.00 °C/min to -60.00 °C; Data Off ; Isothermal 2.0 min; Data On ; Ramp 10.00 °C/min to 200.00 °C; Data Off ; Isothermal 2.0 min; Data On ; Ramp 10.00 °C/min to -60.00 °C; Data Off ; Isothermal 2.0 min; Data On ; Ramp 10.00 °C/min to 200.00 °C
[File Parameters]
Run date,8/6/2025 3:35:56 AM
Trios version,5.1.1.46572
Original File Name,
Current File Name,D:\DSC2500\JYarger\2025_08_05_PVP29_TS_n60C_200C_10Cmin_x3.tri
[Procedure]
Procedure Name,PVP29_TS_Pans_n60C_200C_10Cmin_x3
Sample Name,2025_08_05_PVP29_TS_n60C_200C_10Cmin_x3
Sample Mass,2.76 mg
Reference Sample Mass,0 mg
Pan Mass,32.49 mg
Pan Number,9
Reference Pan Mass,32.52 mg
Reference Pan Number,37
Pan Type,Aluminum
Comments,Thermal support Al pans/lids. DSC_Samples_A2_Tray_July2025 google sheet.
Project Name,Pharma
Operator,Yarger
Test,Custom
Unload Max Temperature,30
Unload Min Temperature,30
Load Max Temperature,30
Load Min Temperature,30
Stop on Gas Flow Error,Yes
[Signal List]
Signal #1,Time (min)
Signal #2,Temperature (°C)
Signal #3,Heat Flow (mW)
Signal #4,Delta T (µV)
Signal #5,Delta Tzero (µV)
Signal #6,Tzero Temperature (°C)
Signal #7,Cell Purge (mL/min)
Signal #8,Heater Temp (°C)
Signal #9,Power Delivered (W)
Signal #10,Reference Junction Temperature (°C)
Signal #11,Flange Temperature (°C)
Signal #12,Heat Flow Phase (rad)
Signal #13,Total Heat Capacity (J/°C)
Signal #14,Heat Capacity (J/°C)
[Configuration]
Company Name,ASU
Instrument Name,DSC2A-00468
Instrument Type,DSC2500
Serial Number,DSC2A-00468
IP,192.168.1.100
Location of Instrument,MRRC
DisplayType,Unknown
Sample Interval ,0.1 s/pt
Selected Heat Flow,T4P
Exotherm Direction,Down
Cell Serial,DRC2-00792
Lid Type,Standard
Cooler,RCS 90
Leave Cooler on at End of Sequence,On
Gas 2,Nitrogen
Gas Selected,Channel 1
Flow Rate,50 mL/min
Secondary Purge,On
Licensed Heat Flow,Heat Flow T4P
Modulation Licensed,Yes
[Versions]
Common IDD Version,1
Cortex Version,VER 2.10.2.31
Driver,5.0.0.6
GDM Version,1.0.3.3
TouchscreenVersion,1.0.0.16145
FEP Version,1.2.1.21
FEP Bootloader,2.0.0.5
AutoSampler Version,2.1.1.26
Auto Sampler Bootloader,2.0.0.5
FCM Version,1.1.0.3
FCM Bootloader,2.0.0.5
[Experiment Logs]
Experiment Log Entry # 1,Data On set to 0
Experiment Log Entry # 3,Equilibrate Segment -60 (C) Started
Experiment Log Entry # 5,Data On set to 1
Experiment Log Entry # 7,Ramp Segment 10 C/min to 200 Started
Experiment Log Entry # 9,Data On set to 0
Experiment Log Entry # 11,Isothermal Segment 2 min started
Experiment Log Entry # 13,Data On set to 1
Experiment Log Entry # 15,Ramp Segment 10 C/min to -60 Started
Experiment Log Entry # 17,Data On set to 0
Experiment Log Entry # 19,Isothermal Segment 2 min started
Experiment Log Entry # 21,Data On set to 1
Experiment Log Entry # 23,Ramp Segment 10 C/min to 200 Started
Experiment Log Entry # 25,Data On set to 0
Experiment Log Entry # 27,Isothermal Segment 2 min started
Experiment Log Entry # 29,Data On set to 1
Experiment Log Entry # 31,Ramp Segment 10 C/min to -60 Started
Experiment Log Entry # 33,Data On set to 0
Experiment Log Entry # 35,Isothermal Segment 2 min started
Experiment Log Entry # 37,Data On set to 1
Experiment Log Entry # 39,Ramp Segment 10 C/min to 200 Started
[Method Log]
Method Log Entry # 1,Data Off
Method Log Entry # 2,Equilibrate -60 °C
Method Log Entry # 3,Data On
Method Log Entry # 4,(Ramp 359041) Ramp 10 °C/minute to 200 °C
Method Log Entry # 5,Data Off
Method Log Entry # 6,Isothermal 2 minutes
Method Log Entry # 7,Data On
Method Log Entry # 8,(Ramp 359045) Ramp 10 °C/minute to -60 °C
Method Log Entry # 9,Data Off
Method Log Entry # 10,Isothermal 2 minutes
Method Log Entry # 11,Data On
Method Log Entry # 12,(Ramp 359049) Ramp 10 °C/minute to 200 °C
Method Log Entry # 13,Data Off
Method Log Entry # 14,Isothermal 2 minutes
Method Log Entry # 15,Data On
Method Log Entry # 16,(Ramp 359053) Ramp 10 °C/minute to -60 °C
Method Log Entry # 17,Data Off
Method Log Entry # 18,Isothermal 2 minutes
Method Log Entry # 19,Data On
Method Log Entry # 20,(Ramp 359057) Ramp 10 °C/minute to 200 °C
Cell Serial,DRC2-00792
[T1 Calibration]
Slope,-0.008529666
Offset,9.636258
Initial Temperature,98.23
GUID,f8bfdadc-4977-4fdf-ba6d-0ba9134940c3
[TZero Calibration]
Date Applied,11/29/2022 4:06:13 PM
Description,From -89.059 °C to 396.009 °C at 20.000°C/min
Gas Type,Nitrogen
Pan Type,None
Source Files 1,C:\Users\yargerlab\Desktop\DSC Data\General\TZero_calibration_11_29_22_2nd(2).tri
Source Files 2,C:\Users\yargerlab\Desktop\DSC Data\General\TZero_calibration_11_29_22_2nd(3).tri
Delta T Offset,13.05235
Delta T Slope,-0.007271007
Delta T0 Offset,-13.69128
Delta T0 Slope,0.06063341
[Temperature Calibration]
Date Applied,11/29/2022 7:12:28 PM
Description,From 106.590 °C to 186.590 °C at 10.000°C/min
Gas Type,Nitrogen
Pan Type,Tzero Aluminum Hermetic
Source Files 1,C:\Users\yargerlab\Desktop\DSC Data\General\Indium(6).tri
Measured 1,157.391
Known 1,156.598
[Cell Constant Calibration]
Date Applied,11/29/2022 7:12:29 PM
Description,From 106.590 °C to 186.590 °C at 10.000°C/min
Gas Type,Nitrogen
Pan Type,Tzero Aluminum Hermetic
Source Files 1,C:\Users\yargerlab\Desktop\DSC Data\General\Indium(6).tri
T4P KCell,1.006051
Onset Slope,63.26126 mW/°C
[Direct Cp Calibration]
Date Applied,11/30/2022 11:04:51 AM
Description,From -79.983 °C to 298.409 °C at 10.000°C/min
Gas Type,Nitrogen
Pan Type,Tzero Aluminum Hermetic
Source Files 1,C:\Users\yargerlab\Desktop\DSC Data\General\Sapphire_Heat_Capacity_11_30_22.tri
[Rev Cp Calibration]
Date Applied,11/30/2022 1:58:51 PM
Description,From -79.996 °C to 292.812 °C at 3.000°C/min
Gas Type,Nitrogen
Pan Type,Tzero Aluminum Hermetic
Source Files 1,C:\Users\yargerlab\Desktop\DSC Data\General\Sapphire_MDSC_Calibration_11_30_22.tri
[step]
Ramp 10.00 °C/min to 200.00 °C
Time,Temperature,Heat Flow (Normalized)
min,°C,W/g
0.00,-59.81,-0.073
0.02,-59.82,-0.069
0.04,-59.82,-0.064
0.05,-59.81,-0.066
0.07,-59.78,-0.072
0.09,-59.72,-0.083
0.11,-59.65,-0.084
0.13,-59.55,-0.076
0.15,-59.43,-0.036
0.16,-59.29,0.004
0.18,-59.14,0.044
0.20,-58.98,0.083
0.22,-58.82,0.114
0.24,-58.65,0.143
0.26,-58.48,0.166
0.28,-58.31,0.182
0.29,-58.13,0.198
0.31,-57.95,0.207
0.33,-57.78,0.215
0.35,-57.60,0.222
0.37,-57.42,0.226
0.39,-57.24,0.229
0.40,-57.07,0.231
0.42,-56.89,0.234
0.44,-56.71,0.235
0.46,-56.53,0.236
0.48,-56.35,0.237
0.50,-56.17,0.238
0.51,-55.99,0.239
0.53,-55.81,0.239
0.55,-55.63,0.240
0.57,-55.45,0.240
0.59,-55.27,0.241
0.60,-55.09,0.242
0.62,-54.91,0.242
0.64,-54.72,0.243
0.66,-54.54,0.244
0.68,-54.36,0.244
0.70,-54.18,0.245
0.72,-54.00,0.246
0.73,-53.82,0.246
0.75,-53.64,0.247
0.77,-53.45,0.247
0.79,-53.27,0.248
0.81,-53.09,0.248
0.83,-52.91,0.249
0.84,-52.73,0.249
0.86,-52.54,0.250
0.88,-52.36,0.250
0.90,-52.18,0.251
0.92,-52.00,0.251
0.93,-51.82,0.251
0.95,-51.63,0.252
0.97,-51.45,0.252
0.99,-51.27,0.253
1.01,-51.09,0.253
1.03,-50.91,0.253
1.05,-50.72,0.253
1.06,-50.54,0.254
1.08,-50.36,0.254
1.10,-50.17,0.254
1.12,-49.99,0.255
1.14,-49.81,0.255
1.16,-49.63,0.255
1.17,-49.44,0.255
1.19,-49.26,0.256
1.21,-49.08,0.256
1.23,-48.89,0.256
1.25,-48.71,0.256
1.27,-48.53,0.257
1.28,-48.35,0.257
1.30,-48.16,0.257
1.32,-47.98,0.257
1.34,-47.80,0.257
1.36,-47.61,0.257
1.38,-47.43,0.258
1.39,-47.25,0.258
1.41,-47.06,0.258
1.43,-46.88,0.258
1.45,-46.70,0.258
1.47,-46.52,0.258
1.48,-46.33,0.258
1.50,-46.15,0.258
1.52,-45.97,0.259
1.54,-45.78,0.259
1.56,-45.60,0.259
1.58,-45.42,0.259
1.59,-45.23,0.259
1.61,-45.05,0.259
1.63,-44.86,0.259
1.65,-44.68,0.259
1.67,-44.50,0.259
1.69,-44.32,0.260
1.71,-44.13,0.260
1.72,-43.95,0.260
1.74,-43.77,0.260
1.76,-43.58,0.260
1.78,-43.40,0.260
1.80,-43.22,0.260
1.82,-43.03,0.260
1.83,-42.85,0.260
1.85,-42.66,0.260
1.87,-42.48,0.260
1.89,-42.30,0.260
1.91,-42.11,0.260
1.93,-41.93,0.261
1.94,-41.75,0.261
1.96,-41.56,0.261
1.98,-41.38,0.261
2.00,-41.20,0.261
2.02,-41.01,0.261
2.03,-40.83,0.261
2.05,-40.65,0.261
2.07,-40.46,0.261
2.09,-40.28,0.261
2.11,-40.10,0.261
2.13,-39.91,0.261
2.14,-39.73,0.261
2.16,-39.55,0.261
2.18,-39.36,0.261
2.20,-39.18,0.261
2.22,-38.99,0.261
2.24,-38.81,0.261
2.26,-38.63,0.261
2.27,-38.44,0.261
2.29,-38.26,0.261
2.31,-38.08,0.261
2.33,-37.89,0.262
2.35,-37.71,0.262
2.36,-37.53,0.262
2.38,-37.34,0.262
2.40,-37.16,0.262
2.42,-36.98,0.262
2.44,-36.79,0.262
2.46,-36.61,0.262
2.48,-36.42,0.262
2.49,-36.24,0.262
2.51,-36.06,0.262
2.53,-35.87,0.262
2.55,-35.69,0.262
2.57,-35.51,0.262
2.59,-35.32,0.262
2.60,-35.14,0.262
2.62,-34.95,0.262
2.64,-34.77,0.262
2.66,-34.59,0.262
2.68,-34.40,0.262
2.69,-34.22,0.262
2.71,-34.04,0.262
2.73,-33.85,0.262
2.75,-33.67,0.262
2.77,-33.49,0.262
2.79,-33.30,0.262
2.81,-33.12,0.262
2.82,-32.94,0.262
2.84,-32.75,0.262
2.86,-32.57,0.262
2.88,-32.39,0.262
2.90,-32.20,0.262
2.91,-32.02,0.262
2.93,-31.83,0.263
2.95,-31.65,0.263
2.97,-31.47,0.263
2.99,-31.28,0.263
3.01,-31.10,0.263
3.03,-30.92,0.263
3.04,-30.73,0.263
3.06,-30.55,0.263
3.08,-30.37,0.263
3.10,-30.18,0.263
3.12,-30.00,0.263
3.14,-29.82,0.263
3.15,-29.63,0.263
3.17,-29.45,0.263
3.19,-29.27,0.263
3.21,-29.08,0.263
3.23,-28.90,0.263
3.24,-28.71,0.263
3.26,-28.53,0.263
3.28,-28.35,0.263
3.30,-28.16,0.263
3.32,-27.98,0.264
3.34,-27.80,0.264
3.36,-27.61,0.264
3.37,-27.43,0.264
3.39,-27.24,0.264
3.41,-27.06,0.264
3.43,-26.88,0.264
3.45,-26.69,0.264
3.46,-26.51,0.264
3.48,-26.33,0.264
3.50,-26.14,0.264
3.52,-25.96,0.264
3.54,-25.78,0.264
3.56,-25.59,0.264
3.58,-25.41,0.264
3.59,-25.23,0.265
3.61,-25.04,0.265
3.63,-24.86,0.265
3.65,-24.68,0.265
3.67,-24.49,0.265
3.69,-24.31,0.265
3.70,-24.13,0.265
3.72,-23.94,0.265
3.74,-23.76,0.265
3.76,-23.57,0.265
3.78,-23.39,0.265
3.79,-23.21,0.265
3.81,-23.02,0.265
3.83,-22.84,0.265
3.85,-22.65,0.266
3.87,-22.47,0.266
3.89,-22.29,0.266
3.91,-22.10,0.266
3.92,-21.92,0.266
3.94,-21.74,0.266
3.96,-21.55,0.266
3.98,-21.37,0.266
4.00,-21.19,0.266
4.01,-21.00,0.266
4.03,-20.82,0.267
4.05,-20.64,0.267
4.07,-20.45,0.267
4.09,-20.27,0.267
4.11,-20.09,0.267
4.13,-19.90,0.267
4.14,-19.72,0.267
4.16,-19.53,0.267
4.18,-19.35,0.267
4.20,-19.17,0.267
4.22,-18.98,0.268
4.24,-18.80,0.268
4.25,-18.62,0.268
4.27,-18.43,0.268
4.29,-18.25,0.268
4.31,-18.07,0.268
4.33,-17.88,0.268
4.35,-17.70,0.268
4.36,-17.52,0.268
4.38,-17.33,0.268
4.40,-17.15,0.269
4.42,-16.97,0.269
4.44,-16.78,0.269
4.45,-16.60,0.269
4.47,-16.41,0.269
4.49,-16.23,0.269
4.51,-16.05,0.269
4.53,-15.87,0.269
4.55,-15.68,0.270
4.56,-15.50,0.270
4.58,-15.32,0.270
4.60,-15.13,0.270
4.62,-14.95,0.270
4.64,-14.76,0.270
4.66,-14.58,0.270
4.68,-14.40,0.270
4.69,-14.21,0.270
4.71,-14.03,0.270
4.73,-13.85,0.271
4.75,-13.66,0.271
4.77,-13.48,0.271
4.79,-13.30,0.271
4.80,-13.11,0.271
4.82,-12.93,0.271
4.84,-12.75,0.271
4.86,-12.56,0.271
4.88,-12.38,0.272
4.90,-12.19,0.272
4.91,-12.01,0.272
4.93,-11.83,0.272
4.95,-11.64,0.272
4.97,-11.46,0.272
4.99,-11.28,0.272
5.00,-11.09,0.273
5.02,-10.91,0.273
5.04,-10.73,0.273
5.06,-10.54,0.273
5.08,-10.36,0.273
5.10,-10.18,0.273
5.11,-9.99,0.273
5.13,-9.81,0.273
5.15,-9.63,0.274
5.17,-9.44,0.274
5.19,-9.26,0.274
5.21,-9.07,0.274
5.23,-8.89,0.274
5.24,-8.71,0.274
5.26,-8.52,0.275
5.28,-8.34,0.275
5.30,-8.16,0.275
5.32,-7.97,0.275
5.34,-7.79,0.275
5.35,-7.61,0.275
5.37,-7.42,0.276
5.39,-7.24,0.276
5.41,-7.06,0.276
5.43,-6.87,0.276
5.45,-6.69,0.276
5.46,-6.51,0.276
5.48,-6.32,0.277
5.50,-6.14,0.277
5.52,-5.96,0.277
5.54,-5.77,0.277
5.55,-5.59,0.277
5.57,-5.40,0.278
5.59,-5.22,0.278
5.61,-5.04,0.278
5.63,-4.85,0.278
5.65,-4.67,0.278
5.66,-4.49,0.278
5.68,-4.30,0.279
5.70,-4.12,0.279
5.72,-3.94,0.279
5.74,-3.75,0.279
5.76,-3.57,0.279
5.78,-3.39,0.280
5.79,-3.20,0.280
5.81,-3.02,0.280
5.83,-2.83,0.280
5.85,-2.65,0.280
5.87,-2.47,0.281
5.89,-2.28,0.281
5.90,-2.10,0.281
5.92,-1.92,0.281
5.94,-1.73,0.281
5.96,-1.55,0.282
5.98,-1.37,0.282
6.00,-1.18,0.282
6.01,-1.00,0.282
6.03,-0.82,0.282
6.05,-0.63,0.282
6.07,-0.45,0.282
6.09,-0.27,0.283
6.10,-0.08,0.283
6.12,0.10,0.283
6.14,0.28,0.283
6.16,0.47,0.283
6.18,0.65,0.284
6.20,0.83,0.284
6.21,1.02,0.284
6.23,1.20,0.284
6.25,1.39,0.285
6.27,1.57,0.285
6.29,1.75,0.285
6.31,1.94,0.285
6.33,2.12,0.285
6.34,2.30,0.286
6.36,2.49,0.286
6.38,2.67,0.286
6.40,2.85,0.286
6.42,3.04,0.287
6.44,3.22,0.287
6.45,3.41,0.287
6.47,3.59,0.287
6.49,3.77,0.288
6.51,3.96,0.288
6.53,4.14,0.288
6.55,4.32,0.288
6.56,4.51,0.289
6.58,4.69,0.289
6.60,4.87,0.289
6.62,5.06,0.289
6.64,5.24,0.289
6.65,5.42,0.290
6.67,5.61,0.290
6.69,5.79,0.290
6.71,5.97,0.291
6.73,6.16,0.291
6.75,6.34,0.291
6.76,6.52,0.291
6.78,6.71,0.292
6.80,6.89,0.292
6.82,7.07,0.292
6.84,7.26,0.292
6.86,7.44,0.293
6.88,7.62,0.293
6.89,7.81,0.293
6.91,7.99,0.293
6.93,8.18,0.294
6.95,8.36,0.294
6.97,8.54,0.294
6.99,8.73,0.295
7.00,8.91,0.295
7.02,9.09,0.295
7.04,9.28,0.296
7.06,9.46,0.296
7.08,9.64,0.296
7.10,9.83,0.297
7.11,10.01,0.297
7.13,10.19,0.297
7.15,10.38,0.297
7.17,10.56,0.298
7.19,10.75,0.298
7.20,10.93,0.298
7.22,11.11,0.299
7.24,11.30,0.299
7.26,11.48,0.299
7.28,11.66,0.300
7.30,11.84,0.300
7.31,12.03,0.300
7.33,12.21,0.301
7.35,12.40,0.301
7.37,12.58,0.301
7.39,12.76,0.302
7.41,12.95,0.302
7.43,13.13,0.302
7.44,13.31,0.303
7.46,13.50,0.303
7.48,13.68,0.303
7.50,13.86,0.304
7.52,14.05,0.304
7.54,14.23,0.304
7.55,14.41,0.305
7.57,14.60,0.305
7.59,14.78,0.306
7.61,14.96,0.306
7.63,15.15,0.306
7.65,15.33,0.307
7.66,15.51,0.307
7.68,15.70,0.307
7.70,15.88,0.308
7.72,16.06,0.308
7.74,16.25,0.308
7.75,16.43,0.309
7.77,16.62,0.309
7.79,16.80,0.310
7.81,16.98,0.310
7.83,17.17,0.311
7.85,17.35,0.311
7.86,17.53,0.312
7.88,17.72,0.312
7.90,17.90,0.312
7.92,18.08,0.313
7.94,18.27,0.313
7.96,18.45,0.314
7.98,18.63,0.314
7.99,18.82,0.314
8.01,19.00,0.315
8.03,19.18,0.315
8.05,19.37,0.316
8.07,19.55,0.316
8.09,19.73,0.317
8.10,19.92,0.317
8.12,20.10,0.318
8.14,20.28,0.318
8.16,20.47,0.319
8.18,20.65,0.319
8.20,20.83,0.320
8.21,21.02,0.320
8.23,21.20,0.321
8.25,21.38,0.321
8.27,21.57,0.322
8.29,21.75,0.322
8.30,21.93,0.323
8.32,22.12,0.323
8.34,22.30,0.324
8.36,22.48,0.324
8.38,22.67,0.325
8.40,22.85,0.326
8.41,23.04,0.326
8.43,23.22,0.327
8.45,23.40,0.327
8.47,23.58,0.328
8.49,23.77,0.328
8.51,23.95,0.329
8.53,24.14,0.329
8.54,24.32,0.330
8.56,24.50,0.331
8.58,24.69,0.331
8.60,24.87,0.332
8.62,25.05,0.332
8.63,25.24,0.333
8.65,25.42,0.333
8.67,25.60,0.334
8.69,25.79,0.335
8.71,25.97,0.335
8.73,26.15,0.336
8.75,26.34,0.337
8.76,26.52,0.337
8.78,26.70,0.338
8.80,26.89,0.339
8.82,27.07,0.339
8.84,27.26,0.340
8.85,27.44,0.341
8.87,27.62,0.341
8.89,27.80,0.342
8.91,27.99,0.343
8.93,28.17,0.343
8.95,28.35,0.344
8.97,28.54,0.345
8.98,28.72,0.345
9.00,28.90,0.346
9.02,29.09,0.347
9.04,29.27,0.347
9.06,29.46,0.348
9.08,29.64,0.349
9.09,29.82,0.350
9.11,30.01,0.350
9.13,30.19,0.351
9.15,30.37,0.352
9.17,30.55,0.353
9.18,30.74,0.353
9.20,30.92,0.354
9.22,31.11,0.355
9.24,31.29,0.356
9.26,31.47,0.356
9.28,31.66,0.357
9.30,31.84,0.358
9.31,32.02,0.359
9.33,32.21,0.359
9.35,32.39,0.360
9.37,32.57,0.361
9.39,32.76,0.362
9.40,32.94,0.362
9.42,33.12,0.363
9.44,33.31,0.364
9.46,33.49,0.365
9.48,33.67,0.366
9.50,33.86,0.367
9.52,34.04,0.368
9.53,34.22,0.369
9.55,34.41,0.370
9.57,34.59,0.371
9.59,34.77,0.372
9.61,34.96,0.373
9.63,35.14,0.373
9.64,35.32,0.374
9.66,35.51,0.375
9.68,35.69,0.376
9.70,35.87,0.377
9.72,36.06,0.378
9.73,36.24,0.379
9.75,36.42,0.380
9.77,36.61,0.381
9.79,36.79,0.382
9.81,36.97,0.383
9.83,37.16,0.384
9.85,37.34,0.385
9.86,37.52,0.386
9.88,37.71,0.387
9.90,37.89,0.388
9.92,38.07,0.389
9.94,38.26,0.390
9.95,38.44,0.391
9.97,38.63,0.393
9.99,38.81,0.394
10.01,38.99,0.395
10.03,39.17,0.396
10.05,39.36,0.397
10.07,39.54,0.399
10.08,39.72,0.400
10.10,39.91,0.401
10.12,40.09,0.402
10.14,40.27,0.404
10.16,40.46,0.405
10.18,40.64,0.406
10.19,40.82,0.408
10.21,41.01,0.409
10.23,41.19,0.410
10.25,41.37,0.411
10.27,41.56,0.413
10.28,41.74,0.415
10.30,41.92,0.416
10.32,42.11,0.417
10.34,42.29,0.418
10.36,42.47,0.420
10.38,42.66,0.422
10.40,42.84,0.423
10.41,43.02,0.424
10.43,43.20,0.426
10.45,43.39,0.427
10.47,43.57,0.430
10.49,43.76,0.431
10.50,43.94,0.432
10.52,44.12,0.434
10.54,44.31,0.436
10.56,44.49,0.437
10.58,44.67,0.440
10.60,44.86,0.442
10.62,45.04,0.443
10.63,45.22,0.445
10.65,45.40,0.447
10.67,45.59,0.448
10.69,45.77,0.451
10.71,45.95,0.452
10.73,46.14,0.454
10.74,46.32,0.456
10.76,46.50,0.457
10.78,46.69,0.459
10.80,46.87,0.461
10.82,47.05,0.463
10.83,47.24,0.465
10.85,47.42,0.467
10.87,47.60,0.469
10.89,47.79,0.471
10.91,47.97,0.474
10.93,48.15,0.478
10.95,48.34,0.479
10.96,48.52,0.481
10.98,48.70,0.484
11.00,48.89,0.486
11.02,49.07,0.488
11.04,49.25,0.491
11.05,49.44,0.494
11.07,49.62,0.496
11.09,49.80,0.498
11.11,49.98,0.501
11.13,50.17,0.503
11.15,50.35,0.506
11.17,50.53,0.508
11.18,50.72,0.511
11.20,50.90,0.514
11.22,51.08,0.517
11.24,51.27,0.520
11.26,51.45,0.524
11.28,51.63,0.527
11.29,51.82,0.528
11.31,52.00,0.532
11.33,52.18,0.537
11.35,52.36,0.540
11.37,52.55,0.542
11.38,52.73,0.546
11.40,52.91,0.549
11.42,53.10,0.552
11.44,53.28,0.556
11.46,53.46,0.558
11.48,53.65,0.561
11.50,53.83,0.564
11.51,54.01,0.567
11.53,54.19,0.570
11.55,54.38,0.573
11.57,54.56,0.576
11.59,54.74,0.579
11.60,54.93,0.583
11.62,55.11,0.585
11.64,55.29,0.587
11.66,55.47,0.590
11.68,55.66,0.592
11.70,55.84,0.594
11.72,56.02,0.597
11.73,56.21,0.599
11.75,56.39,0.601
11.77,56.57,0.603
11.79,56.76,0.604
11.81,56.94,0.606
11.83,57.12,0.608
11.84,57.31,0.610
11.86,57.49,0.611
11.88,57.67,0.613
11.90,57.86,0.614
11.92,58.04,0.615
11.93,58.22,0.617
11.95,58.41,0.618
11.97,58.59,0.620
11.99,58.77,0.621
12.01,58.96,0.622
12.03,59.14,0.624
12.05,59.32,0.625
12.06,59.51,0.626
12.08,59.69,0.627
12.10,59.87,0.629
12.12,60.06,0.631
12.14,60.24,0.633
12.15,60.42,0.635
12.17,60.60,0.636
12.19,60.79,0.638
12.21,60.97,0.639
12.23,61.15,0.640
12.25,61.34,0.642
12.27,61.52,0.644
12.28,61.70,0.646
12.30,61.89,0.649
12.32,62.07,0.653
12.34,62.25,0.656
12.36,62.44,0.658
12.38,62.62,0.660
12.39,62.80,0.662
12.41,62.99,0.665
12.43,63.17,0.666
12.45,63.35,0.669
12.47,63.54,0.671
12.48,63.72,0.674
12.50,63.90,0.677
12.52,64.09,0.679
12.54,64.27,0.680
12.56,64.45,0.683
12.58,64.64,0.685
12.60,64.82,0.688
12.61,65.00,0.689
12.63,65.19,0.692
12.65,65.37,0.696
12.67,65.55,0.698
12.69,65.74,0.701
12.70,65.92,0.703
12.72,66.10,0.705
12.74,66.29,0.707
12.76,66.47,0.710
12.78,66.65,0.712
12.80,66.83,0.714
12.82,67.02,0.718
12.83,67.20,0.721
12.85,67.38,0.723
12.87,67.56,0.725
12.89,67.75,0.729
12.91,67.93,0.733
12.93,68.11,0.736
12.94,68.30,0.738
12.96,68.48,0.742
12.98,68.66,0.745
13.00,68.85,0.747
13.02,69.03,0.750
13.03,69.21,0.753
13.05,69.39,0.756
13.07,69.58,0.759
13.09,69.76,0.761
13.11,69.94,0.765
13.13,70.13,0.769
13.15,70.31,0.771
13.16,70.49,0.775
13.18,70.67,0.777
13.20,70.86,0.780
13.22,71.04,0.784
13.24,71.22,0.787
13.25,71.41,0.790
13.27,71.59,0.793
13.29,71.77,0.796
13.31,71.96,0.800
13.33,72.14,0.803
13.35,72.32,0.805
13.37,72.50,0.808
13.38,72.69,0.811
13.40,72.87,0.815
13.42,73.05,0.818
13.44,73.24,0.821
13.46,73.42,0.824
13.48,73.60,0.828
13.49,73.78,0.831
13.51,73.97,0.833
13.53,74.15,0.837
13.55,74.33,0.840
13.57,74.52,0.845
13.58,74.70,0.847
13.60,74.88,0.850
13.62,75.06,0.854
13.64,75.25,0.857
13.66,75.43,0.861
13.68,75.61,0.864
13.70,75.80,0.867
13.71,75.98,0.870
13.73,76.16,0.874
13.75,76.35,0.876
13.77,76.53,0.881
13.79,76.71,0.884
13.80,76.89,0.887
13.82,77.08,0.890
13.84,77.26,0.895
13.86,77.44,0.899
13.88,77.63,0.902
13.90,77.81,0.906
13.92,77.99,0.909
13.93,78.18,0.913
13.95,78.36,0.916
13.97,78.54,0.919
13.99,78.73,0.922
14.01,78.91,0.926
14.03,79.09,0.929
14.04,79.27,0.932
14.06,79.46,0.936
14.08,79.64,0.940
14.10,79.82,0.944
14.12,80.01,0.948
14.13,80.19,0.951
14.15,80.37,0.954
14.17,80.56,0.959
14.19,80.74,0.962
14.21,80.92,0.966
14.23,81.10,0.969
14.25,81.29,0.973
14.26,81.47,0.977
14.28,81.65,0.981
14.30,81.83,0.983
14.32,82.02,0.987
14.34,82.20,0.992
14.35,82.38,0.996
14.37,82.56,1.000
14.39,82.75,1.003
14.41,82.93,1.008
14.43,83.11,1.012
14.45,83.30,1.016
14.47,83.48,1.020
14.48,83.66,1.025
14.50,83.85,1.028
14.52,84.03,1.031
14.54,84.21,1.035
14.56,84.40,1.038
14.58,84.58,1.041
14.59,84.76,1.047
14.61,84.94,1.051
14.63,85.13,1.056
14.65,85.31,1.059
14.67,85.49,1.064
14.68,85.67,1.067
14.70,85.86,1.070
14.72,86.04,1.075
14.74,86.22,1.078
14.76,86.41,1.082
14.78,86.59,1.087
14.80,86.77,1.091
14.81,86.95,1.095
14.83,87.14,1.099
14.85,87.32,1.103
14.87,87.50,1.105
14.89,87.69,1.110
14.90,87.87,1.114
14.92,88.05,1.119
14.94,88.23,1.122
14.96,88.42,1.127
14.98,88.60,1.131
15.00,88.78,1.134
15.02,88.97,1.137
15.03,89.15,1.142
15.05,89.33,1.147
15.07,89.52,1.149
15.09,89.70,1.155
15.11,89.88,1.158
15.13,90.06,1.164
15.14,90.25,1.167
15.16,90.43,1.170
15.18,90.61,1.174
15.20,90.80,1.177
15.22,90.98,1.181
15.23,91.16,1.185
15.25,91.34,1.188
15.27,91.53,1.193
15.29,91.71,1.197
15.31,91.89,1.200
15.33,92.08,1.204
15.35,92.26,1.207
15.36,92.44,1.211
15.38,92.62,1.213
15.40,92.81,1.218
15.42,92.99,1.221
15.44,93.17,1.224
15.45,93.36,1.228
15.47,93.54,1.232
15.49,93.72,1.234
15.51,93.90,1.238
15.53,94.09,1.240
15.55,94.27,1.244
15.57,94.45,1.247
15.58,94.64,1.251
15.60,94.82,1.255
15.62,95.00,1.258
15.64,95.19,1.261
15.66,95.37,1.264
15.68,95.55,1.268
15.69,95.73,1.271
15.71,95.92,1.273
15.73,96.10,1.276
15.75,96.28,1.278
15.77,96.47,1.280
15.78,96.65,1.283
15.80,96.83,1.285
15.82,97.01,1.287
15.84,97.20,1.290
15.86,97.38,1.292
15.88,97.56,1.295
15.90,97.75,1.297
15.91,97.93,1.300
15.93,98.11,1.301
15.95,98.30,1.304
15.97,98.48,1.306
15.99,98.66,1.307
16.00,98.85,1.309
16.02,99.03,1.311
16.04,99.21,1.314
16.06,99.39,1.316
16.08,99.58,1.317
16.10,99.76,1.319
16.12,99.94,1.320
16.13,100.13,1.321
16.15,100.31,1.322
16.17,100.50,1.323
16.19,100.68,1.325
16.21,100.86,1.326
16.23,101.05,1.327
16.24,101.23,1.328
16.26,101.41,1.329
16.28,101.59,1.330
16.30,101.78,1.331
16.32,101.96,1.332
16.33,102.15,1.333
16.35,102.33,1.334
16.37,102.51,1.335
16.39,102.70,1.336
16.41,102.88,1.336
16.43,103.06,1.337
16.45,103.25,1.338
16.46,103.43,1.338
16.48,103.61,1.339
16.50,103.79,1.339
16.52,103.98,1.339
16.54,104.16,1.340
16.55,104.35,1.340
16.57,104.53,1.340
16.59,104.71,1.340
16.61,104.90,1.340
16.63,105.08,1.340
16.65,105.27,1.340
16.67,105.45,1.340
16.68,105.63,1.340
16.70,105.82,1.339
16.72,106.00,1.339
16.74,106.19,1.338
16.76,106.37,1.337
16.78,106.55,1.336
16.79,106.74,1.335
16.81,106.92,1.334
16.83,107.11,1.331
16.85,107.29,1.329
16.87,107.47,1.327
16.88,107.66,1.325
16.90,107.84,1.323
16.92,108.02,1.321
16.94,108.21,1.317
16.96,108.39,1.314
16.98,108.58,1.310
17.00,108.76,1.307
17.01,108.94,1.303
17.03,109.13,1.299
17.05,109.31,1.294
17.07,109.49,1.291
17.09,109.68,1.287
17.11,109.86,1.284
17.12,110.05,1.279
17.14,110.23,1.276
17.16,110.42,1.272
17.18,110.60,1.269
17.20,110.79,1.262
17.22,110.97,1.258
17.23,111.15,1.254
17.25,111.34,1.248
17.27,111.52,1.242
17.29,111.71,1.238
17.31,111.89,1.233
17.33,112.08,1.228
17.34,112.26,1.223
17.36,112.45,1.216
17.38,112.63,1.212
17.40,112.81,1.206
17.42,113.00,1.200
17.43,113.18,1.194
17.45,113.37,1.189
17.47,113.55,1.183
17.49,113.74,1.177
17.51,113.92,1.171
17.53,114.10,1.166
17.54,114.29,1.159
17.56,114.47,1.153
17.58,114.66,1.148
17.60,114.84,1.141
17.62,115.03,1.135
17.64,115.21,1.130
17.66,115.40,1.123
17.67,115.58,1.116
17.69,115.77,1.109
17.71,115.95,1.104
17.73,116.14,1.098
17.75,116.32,1.090
17.77,116.50,1.083
17.78,116.69,1.076
17.80,116.87,1.071
17.82,117.06,1.062
17.84,117.24,1.056
17.86,117.43,1.051
17.88,117.61,1.042
17.89,117.80,1.036
17.91,117.98,1.030
17.93,118.17,1.023
17.95,118.35,1.017
17.97,118.54,1.008
17.98,118.72,1.003
18.00,118.91,0.996
18.02,119.09,0.990
18.04,119.28,0.982
18.06,119.46,0.975
18.08,119.65,0.968
18.09,119.83,0.961
18.11,120.01,0.955
18.13,120.20,0.948
18.15,120.38,0.941
18.17,120.57,0.936
18.19,120.75,0.928
18.21,120.94,0.923
18.22,121.12,0.914
18.24,121.31,0.908
18.26,121.49,0.901
18.28,121.68,0.894
18.30,121.86,0.888
18.32,122.05,0.881
18.33,122.23,0.874
18.35,122.41,0.868
18.37,122.60,0.861
18.39,122.78,0.855
18.41,122.97,0.848
18.43,123.15,0.842
18.44,123.34,0.836
18.46,123.52,0.830
18.48,123.71,0.823
18.50,123.89,0.817
18.52,124.08,0.810
18.53,124.26,0.805
18.55,124.45,0.799
18.57,124.63,0.793
18.59,124.81,0.788
18.61,125.00,0.781
18.63,125.18,0.775
18.64,125.37,0.769
18.66,125.55,0.762
18.68,125.74,0.757
18.70,125.92,0.751
18.72,126.11,0.746
18.74,126.29,0.740
18.76,126.47,0.735
18.77,126.66,0.729
18.79,126.84,0.723
18.81,127.03,0.718
18.83,127.21,0.711
18.85,127.40,0.706
18.87,127.58,0.700
18.88,127.76,0.694
18.90,127.95,0.690
18.92,128.13,0.686
18.94,128.32,0.680
18.96,128.50,0.675
18.98,128.69,0.670
18.99,128.87,0.665
19.01,129.06,0.661
19.03,129.24,0.657
19.05,129.43,0.650
19.07,129.61,0.646
19.08,129.79,0.640
19.10,129.98,0.634
19.12,130.16,0.630
19.14,130.35,0.625
19.16,130.53,0.621
19.18,130.71,0.616
19.19,130.90,0.612
19.21,131.08,0.608
19.23,131.27,0.604
19.25,131.45,0.599
19.27,131.64,0.594
19.29,131.82,0.590
19.31,132.00,0.585
19.32,132.19,0.581
19.34,132.37,0.576
19.36,132.56,0.571
19.38,132.74,0.568
19.40,132.93,0.563
19.42,133.11,0.560
19.43,133.29,0.556
19.45,133.48,0.552
19.47,133.66,0.548
19.49,133.85,0.544
19.51,134.03,0.540
19.53,134.21,0.536
19.54,134.40,0.532
19.56,134.58,0.529
19.58,134.77,0.526
19.60,134.95,0.521
19.62,135.14,0.519
19.63,135.32,0.516
19.65,135.50,0.512
19.67,135.69,0.507
19.69,135.87,0.504
19.71,136.06,0.500
19.73,136.24,0.497
19.74,136.42,0.493
19.76,136.61,0.491
19.78,136.79,0.488
19.80,136.98,0.484
19.82,137.16,0.481
19.84,137.35,0.478
19.86,137.53,0.475
19.87,137.71,0.472
19.89,137.90,0.469
19.91,138.08,0.466
19.93,138.26,0.463
19.95,138.45,0.460
19.97,138.63,0.458
19.98,138.82,0.456
20.00,139.00,0.451
20.02,139.18,0.449
20.04,139.37,0.447
20.06,139.55,0.444
20.08,139.73,0.441
20.09,139.92,0.439
20.11,140.10,0.437
20.13,140.29,0.435
20.15,140.47,0.433
20.17,140.66,0.431
20.18,140.84,0.429
20.20,141.02,0.427
20.22,141.21,0.424
20.24,141.39,0.421
20.26,141.58,0.420
20.28,141.76,0.418
20.29,141.94,0.416
20.31,142.13,0.414
20.33,142.31,0.411
20.35,142.49,0.408
20.37,142.68,0.406
20.39,142.86,0.404
20.41,143.05,0.402
20.42,143.23,0.401
20.44,143.41,0.400
20.46,143.60,0.398
20.48,143.78,0.396
20.50,143.96,0.394
20.52,144.15,0.393
20.53,144.33,0.391
20.55,144.52,0.389
20.57,144.70,0.388
20.59,144.88,0.387
20.61,145.07,0.386
20.63,145.25,0.384
20.64,145.43,0.383
20.66,145.62,0.382
20.68,145.80,0.380
20.70,145.99,0.379
20.72,146.17,0.378
20.73,146.35,0.377
20.75,146.54,0.376
20.77,146.72,0.375
20.79,146.90,0.374
20.81,147.09,0.373
20.83,147.27,0.372
20.84,147.46,0.371
20.86,147.64,0.370
20.88,147.82,0.369
20.90,148.01,0.368
20.92,148.19,0.367
20.94,148.37,0.366
20.96,148.56,0.365
20.97,148.74,0.364
20.99,148.92,0.363
21.01,149.11,0.362
21.03,149.29,0.361
21.05,149.48,0.361
21.07,149.66,0.360
21.08,149.84,0.359
21.10,150.03,0.358
21.12,150.21,0.358
21.14,150.39,0.357
21.16,150.58,0.357
21.18,150.76,0.356
21.19,150.94,0.356
21.21,151.13,0.355
21.23,151.31,0.355
21.25,151.49,0.355
21.27,151.68,0.354
21.28,151.86,0.354
21.30,152.04,0.354
21.32,152.23,0.354
21.34,152.41,0.354
21.36,152.59,0.354
21.38,152.78,0.354
21.39,152.96,0.354
21.41,153.14,0.354
21.43,153.33,0.354
21.45,153.51,0.354
21.47,153.69,0.354
21.49,153.88,0.354
21.51,154.06,0.354
21.52,154.24,0.354
21.54,154.43,0.354
21.56,154.61,0.355
21.58,154.79,0.355
21.60,154.98,0.355
21.62,155.16,0.356
21.63,155.35,0.356
21.65,155.53,0.356
21.67,155.71,0.357
21.69,155.90,0.357
21.71,156.08,0.358
21.73,156.26,0.358
21.74,156.45,0.358
21.76,156.63,0.359
21.78,156.81,0.359
21.80,157.00,0.359
21.82,157.18,0.359
21.83,157.36,0.359
21.85,157.55,0.359
21.87,157.73,0.360
21.89,157.91,0.360
21.91,158.10,0.360
21.93,158.28,0.360
21.94,158.46,0.359
21.96,158.65,0.359
21.98,158.83,0.359
22.00,159.01,0.359
22.02,159.20,0.359
22.04,159.38,0.359
22.06,159.57,0.358
22.07,159.75,0.358
22.09,159.93,0.358
22.11,160.12,0.358
22.13,160.30,0.357
22.15,160.48,0.357
22.17,160.67,0.356
22.18,160.85,0.356
22.20,161.03,0.355
22.22,161.22,0.355
22.24,161.40,0.354
22.26,161.59,0.354
22.28,161.77,0.353
22.29,161.95,0.353
22.31,162.14,0.352
22.33,162.32,0.352
22.35,162.50,0.351
22.37,162.69,0.351
22.38,162.87,0.350
22.40,163.05,0.350
22.42,163.24,0.349
22.44,163.42,0.349
22.46,163.60,0.349
22.48,163.79,0.348
22.49,163.97,0.348
22.51,164.15,0.347
22.53,164.34,0.347
22.55,164.52,0.347
22.57,164.70,0.347
22.59,164.89,0.346
22.61,165.07,0.346
22.62,165.25,0.346
22.64,165.44,0.346
22.66,165.62,0.346
22.68,165.80,0.345
22.70,165.99,0.345
22.72,166.17,0.345
22.73,166.36,0.345
22.75,166.54,0.345
22.77,166.72,0.345
22.79,166.91,0.345
22.81,167.09,0.345
22.83,167.27,0.345
22.84,167.46,0.345
22.86,167.64,0.345
22.88,167.82,0.345
22.90,168.01,0.345
22.92,168.19,0.345
22.93,168.37,0.345
22.95,168.56,0.345
22.97,168.74,0.345
22.99,168.92,0.345
23.01,169.11,0.345
23.03,169.29,0.345
23.04,169.47,0.345
23.06,169.66,0.345
23.08,169.84,0.345
23.10,170.02,0.345
23.12,170.21,0.345
23.14,170.39,0.345
23.16,170.58,0.345
23.17,170.76,0.345
23.19,170.94,0.345
23.21,171.13,0.345
23.23,171.31,0.345
23.25,171.49,0.346
23.27,171.68,0.346
23.28,171.86,0.346
23.30,172.04,0.346
23.32,172.23,0.346
23.34,172.41,0.346
23.36,172.59,0.346
23.38,172.78,0.346
23.39,172.96,0.346
23.41,173.14,0.346
23.43,173.33,0.346
23.45,173.51,0.346
23.47,173.69,0.346
23.48,173.88,0.347
23.50,174.06,0.347
23.52,174.24,0.347
23.54,174.43,0.347
23.56,174.61,0.347
23.58,174.79,0.347
23.59,174.98,0.348
23.61,175.16,0.348
23.63,175.34,0.348
23.65,175.53,0.348
23.67,175.71,0.348
23.69,175.89,0.348
23.71,176.08,0.349
23.72,176.26,0.349
23.74,176.45,0.349
23.76,176.63,0.349
23.78,176.81,0.349
23.80,177.00,0.350
23.82,177.18,0.350
23.83,177.36,0.350
23.85,177.55,0.350
23.87,177.73,0.350
23.89,177.91,0.350
23.91,178.10,0.350
23.93,178.28,0.350
23.94,178.46,0.351
23.96,178.65,0.351
23.98,178.83,0.351
24.00,179.01,0.351
24.02,179.20,0.351
24.03,179.38,0.351
24.05,179.56,0.351
24.07,179.75,0.352
24.09,179.93,0.352
24.11,180.11,0.352
24.13,180.30,0.352
24.14,180.48,0.352
24.16,180.66,0.352
24.18,180.85,0.353
24.20,181.03,0.353
24.22,181.21,0.353
24.24,181.40,0.353
24.26,181.58,0.353
24.27,181.76,0.353
24.29,181.95,0.354
24.31,182.13,0.354
24.33,182.31,0.354
24.35,182.50,0.354
24.37,182.68,0.354
24.38,182.87,0.355
24.40,183.05,0.355
24.42,183.23,0.355
24.44,183.42,0.355
24.46,183.60,0.355
24.48,183.78,0.356
24.49,183.97,0.356
24.51,184.15,0.356
24.53,184.33,0.356
24.55,184.52,0.356
24.57,184.70,0.356
24.58,184.88,0.356
24.60,185.07,0.356
24.62,185.25,0.357
24.64,185.43,0.357
24.66,185.62,0.357
24.68,185.80,0.357
24.69,185.98,0.357
24.71,186.17,0.357
24.73,186.35,0.358
24.75,186.53,0.358
24.77,186.72,0.358
24.79,186.90,0.358
24.81,187.08,0.358
24.82,187.27,0.358
24.84,187.45,0.358
24.86,187.63,0.359
24.88,187.82,0.359
24.90,188.00,0.359
24.92,188.18,0.359
24.93,188.37,0.359
24.95,188.55,0.360
24.97,188.73,0.360
24.99,188.92,0.360
25.01,189.10,0.360
25.03,189.29,0.360
25.04,189.47,0.361
25.06,189.65,0.361
25.08,189.84,0.361
25.10,190.02,0.361
25.12,190.20,0.362
25.13,190.39,0.362
25.15,190.57,0.362
25.17,190.75,0.362
25.19,190.94,0.362
25.21,191.12,0.362
25.23,191.30,0.363
25.24,191.49,0.363
25.26,191.67,0.363
25.28,191.85,0.363
25.30,192.04,0.364
25.32,192.22,0.364
25.34,192.40,0.364
25.36,192.59,0.364
25.37,192.77,0.365
25.39,192.96,0.365
25.41,193.14,0.365
25.43,193.32,0.365
25.45,193.50,0.365
25.47,193.69,0.366
25.48,193.87,0.366
25.50,194.05,0.366
25.52,194.24,0.366
25.54,194.42,0.366
25.56,194.60,0.366
25.58,194.79,0.366
25.59,194.97,0.367
25.61,195.16,0.367
25.63,195.34,0.367
25.65,195.52,0.367
25.67,195.71,0.368
25.68,195.89,0.368
25.70,196.07,0.368
25.72,196.26,0.368
25.74,196.44,0.368
25.76,196.62,0.369
25.78,196.81,0.369
25.79,196.99,0.369
25.81,197.17,0.369
25.83,197.36,0.369
25.85,197.54,0.370
25.87,197.72,0.370
25.89,197.91,0.370
25.91,198.09,0.370
25.92,198.27,0.370
25.94,198.46,
25.96,198.64,
25.98,198.82,
25.99,,

[step]
Ramp 10.00 °C/min to -60.00 °C
Time,Temperature,Heat Flow (Normalized)
min,°C,W/g
27.99,200.16,-0.053
28.01,200.16,-0.053
28.03,200.16,-0.053
28.05,200.15,-0.052
28.07,200.12,-0.048
28.08,200.07,-0.049
28.10,200.00,-0.091
28.12,199.89,-0.147
28.14,199.77,-0.212
28.16,199.62,-0.277
28.18,199.47,-0.331
28.19,199.31,-0.370
28.21,199.14,-0.399
28.23,198.96,-0.420
28.25,198.79,-0.435
28.27,198.61,-0.443
28.29,198.43,-0.448
28.31,198.26,-0.453
28.32,198.08,-0.455
28.34,197.90,-0.456
28.36,197.71,-0.458
28.38,197.53,-0.460
28.40,197.35,-0.461
28.42,197.17,-0.462
28.43,196.99,-0.463
28.45,196.81,-0.464
28.47,196.63,-0.464
28.49,196.44,-0.465
28.51,196.26,-0.465
28.53,196.08,-0.466
28.54,195.90,-0.466
28.56,195.72,-0.466
28.58,195.53,-0.467
28.60,195.35,-0.467
28.62,195.17,-0.468
28.63,194.99,-0.468
28.65,194.81,-0.468
28.67,194.62,-0.469
28.69,194.44,-0.469
28.71,194.26,-0.469
28.73,194.08,-0.470
28.74,193.89,-0.470
28.76,193.71,-0.470
28.78,193.53,-0.470
28.80,193.35,-0.471
28.82,193.16,-0.471
28.84,192.98,-0.471
28.86,192.80,-0.471
28.87,192.62,-0.471
28.89,192.44,-0.472
28.91,192.25,-0.472
28.93,192.07,-0.472
28.95,191.89,-0.472
28.97,191.71,-0.472
28.98,191.52,-0.472
29.00,191.34,-0.472
29.02,191.16,-0.472
29.04,190.97,-0.472
29.06,190.79,-0.473
29.08,190.61,-0.473
29.09,190.43,-0.473
29.11,190.24,-0.473
29.13,190.06,-0.473
29.15,189.88,-0.473
29.17,189.69,-0.473
29.18,189.51,-0.473
29.20,189.33,-0.473
29.22,189.15,-0.473
29.24,188.96,-0.473
29.26,188.78,-0.473
29.28,188.60,-0.473
29.29,188.41,-0.473
29.31,188.23,-0.473
29.33,188.05,-0.473
29.35,187.86,-0.473
29.37,187.68,-0.473
29.39,187.50,-0.473
29.41,187.32,-0.473
29.42,187.13,-0.473
29.44,186.95,-0.473
29.46,186.77,-0.473
29.48,186.58,-0.473
29.50,186.40,-0.473
29.52,186.22,-0.473
29.53,186.03,-0.473
29.55,185.85,-0.473
29.57,185.67,-0.473
29.59,185.49,-0.473
29.61,185.30,-0.473
29.63,185.12,-0.473
29.64,184.94,-0.473
29.66,184.75,-0.473
29.68,184.57,-0.473
29.70,184.39,-0.473
29.72,184.21,-0.473
29.73,184.02,-0.473
29.75,183.84,-0.473
29.77,183.66,-0.473
29.79,183.47,-0.473
29.81,183.29,-0.473
29.83,183.11,-0.473
29.84,182.92,-0.473
29.86,182.74,-0.472
29.88,182.56,-0.472
29.90,182.37,-0.472
29.92,182.19,-0.472
29.94,182.01,-0.473
29.96,181.82,-0.472
29.97,181.64,-0.472
29.99,181.46,-0.472
30.01,181.27,-0.472
30.03,181.09,-0.472
30.05,180.91,-0.472
30.07,180.72,-0.472
30.08,180.54,-0.472
30.10,180.36,-0.472
30.12,180.17,-0.472
30.14,179.99,-0.472
30.16,179.81,-0.472
30.18,179.63,-0.472
30.19,179.44,-0.471
30.21,179.26,-0.471
30.23,179.08,-0.471
30.25,178.89,-0.471
30.27,178.71,-0.471
30.28,178.52,-0.471
30.30,178.34,-0.471
30.32,178.16,-0.471
30.34,177.98,-0.471
30.36,177.79,-0.471
30.38,177.61,-0.471
30.39,177.43,-0.471
30.41,177.24,-0.471
30.43,177.06,-0.471
30.45,176.88,-0.471
30.47,176.69,-0.470
30.49,176.51,-0.470
30.51,176.33,-0.470
30.52,176.14,-0.470
30.54,175.96,-0.470
30.56,175.78,-0.470
30.58,175.59,-0.470
30.60,175.41,-0.470
30.62,175.23,-0.470
30.63,175.04,-0.470
30.65,174.86,-0.470
30.67,174.68,-0.470
30.69,174.49,-0.470
30.71,174.31,-0.470
30.73,174.13,-0.470
30.74,173.94,-0.470
30.76,173.76,-0.470
30.78,173.58,-0.470
30.80,173.39,-0.469
30.82,173.21,-0.469
30.83,173.03,-0.469
30.85,172.84,-0.469
30.87,172.66,-0.469
30.89,172.48,-0.469
30.91,172.29,-0.469
30.93,172.11,-0.469
30.94,171.93,-0.469
30.96,171.74,-0.469
30.98,171.56,-0.468
31.00,171.38,-0.468
31.02,171.19,-0.468
31.04,171.01,-0.468
31.06,170.83,-0.468
31.07,170.64,-0.468
31.09,170.46,-0.468
31.11,170.28,-0.468
31.13,170.09,-0.467
31.15,169.91,-0.467
31.17,169.73,-0.467
31.18,169.54,-0.467
31.20,169.36,-0.467
31.22,169.18,-0.467
31.24,168.99,-0.466
31.26,168.81,-0.466
31.28,168.63,-0.466
31.29,168.44,-0.466
31.31,168.26,-0.466
31.33,168.08,-0.466
31.35,167.89,-0.466
31.37,167.71,-0.465
31.38,167.53,-0.465
31.40,167.34,-0.465
31.42,167.16,-0.465
31.44,166.98,-0.464
31.46,166.79,-0.464
31.48,166.61,-0.464
31.49,166.43,-0.464
31.51,166.24,-0.464
31.53,166.06,-0.464
31.55,165.88,-0.463
31.57,165.69,-0.463
31.59,165.51,-0.463
31.61,165.33,-0.463
31.62,165.14,-0.463
31.64,164.96,-0.462
31.66,164.78,-0.462
31.68,164.59,-0.462
31.70,164.41,-0.461
31.72,164.23,-0.461
31.73,164.04,-0.461
31.75,163.86,-0.461
31.77,163.68,-0.460
31.79,163.49,-0.460
31.81,163.31,-0.460
31.83,163.13,-0.459
31.84,162.94,-0.459
31.86,162.76,-0.459
31.88,162.58,-0.458
31.90,162.39,-0.458
31.92,162.21,-0.458
31.93,162.03,-0.457
31.95,161.84,-0.457
31.97,161.66,-0.457
31.99,161.48,-0.456
32.01,161.30,-0.456
32.03,161.11,-0.456
32.04,160.93,-0.455
32.06,160.75,-0.455
32.08,160.56,-0.455
32.10,160.38,-0.454
32.12,160.19,-0.454
32.14,160.01,-0.453
32.16,159.83,-0.453
32.17,159.65,-0.453
32.19,159.46,-0.452
32.21,159.28,-0.452
32.23,159.09,-0.452
32.25,158.91,-0.451
32.27,158.73,-0.451
32.28,158.55,-0.451
32.30,158.36,-0.450
32.32,158.18,-0.450
32.34,157.99,-0.449
32.36,157.81,-0.449
32.38,157.63,-0.448
32.39,157.45,-0.448
32.41,157.26,-0.447
32.43,157.08,-0.447
32.45,156.89,-0.447
32.47,156.71,-0.446
32.48,156.53,-0.446
32.50,156.34,-0.445
32.52,156.16,-0.445
32.54,155.98,-0.445
32.56,155.79,-0.444
32.58,155.61,-0.444
32.59,155.43,-0.443
32.61,155.25,-0.443
32.63,155.06,-0.442
32.65,154.88,-0.442
32.67,154.69,-0.441
32.69,154.51,-0.441
32.71,154.33,-0.441
32.72,154.14,-0.440
32.74,153.96,-0.440
32.76,153.78,-0.439
32.78,153.59,-0.439
32.80,153.41,-0.438
32.82,153.23,-0.438
32.83,153.04,-0.438
32.85,152.86,-0.437
32.87,152.68,-0.437
32.89,152.49,-0.436
32.91,152.31,-0.436
32.93,152.13,-0.436
32.94,151.94,-0.435
32.96,151.76,-0.435
32.98,151.58,-0.434
33.00,151.39,-0.434
33.02,151.21,-0.433
33.03,151.03,-0.433
33.05,150.84,-0.433
33.07,150.66,-0.432
33.09,150.48,-0.432
33.11,150.29,-0.431
33.13,150.11,-0.431
33.14,149.93,-0.431
33.16,149.74,-0.430
33.18,149.56,-0.430
33.20,149.38,-0.429
33.22,149.19,-0.429
33.24,149.01,-0.429
33.26,148.83,-0.428
33.27,148.64,-0.428
33.29,148.46,-0.427
33.31,148.28,-0.427
33.33,148.09,-0.427
33.35,147.91,-0.426
33.37,147.73,-0.426
33.38,147.55,-0.426
33.40,147.36,-0.425
33.42,147.18,-0.425
33.44,146.99,-0.424
33.46,146.81,-0.424
33.48,146.63,-0.424
33.49,146.44,-0.424
33.51,146.26,-0.423
33.53,146.08,-0.423
33.55,145.89,-0.423
33.57,145.71,-0.422
33.58,145.53,-0.422
33.60,145.34,-0.422
33.62,145.16,-0.421
33.64,144.98,-0.421
33.66,144.79,-0.421
33.68,144.61,-0.420
33.69,144.43,-0.420
33.71,144.24,-0.420
33.73,144.06,-0.419
33.75,143.88,-0.419
33.77,143.69,-0.419
33.79,143.51,-0.418
33.81,143.33,-0.418
33.82,143.14,-0.418
33.84,142.96,-0.417
33.86,142.78,-0.417
33.88,142.59,-0.417
33.90,142.41,-0.417
33.92,142.23,-0.416
33.93,142.04,-0.416
33.95,141.86,-0.416
33.97,141.68,-0.416
33.99,141.49,-0.415
34.01,141.31,-0.415
34.03,141.13,-0.414
34.04,140.94,-0.414
34.06,140.76,-0.414
34.08,140.58,-0.414
34.10,140.40,-0.413
34.12,140.21,-0.413
34.14,140.03,-0.413
34.15,139.85,-0.413
34.17,139.66,-0.412
34.19,139.48,-0.412
34.21,139.30,-0.412
34.23,139.11,-0.412
34.24,138.93,-0.412
34.26,138.75,-0.411
34.28,138.56,-0.411
34.30,138.38,-0.411
34.32,138.20,-0.411
34.34,138.01,-0.411
34.36,137.83,-0.411
34.37,137.64,-0.410
34.39,137.46,-0.410
34.41,137.28,-0.410
34.43,137.10,-0.410
34.45,136.91,-0.410
34.46,136.73,-0.409
34.48,136.55,-0.409
34.50,136.36,-0.409
34.52,136.18,-0.409
34.54,136.00,-0.408
34.56,135.81,-0.408
34.58,135.63,-0.408
34.59,135.45,-0.408
34.61,135.26,-0.408
34.63,135.08,-0.408
34.65,134.90,-0.407
34.67,134.71,-0.407
34.69,134.53,-0.407
34.70,134.35,-0.407
34.72,134.16,-0.407
34.74,133.98,-0.406
34.76,133.79,-0.406
34.78,133.61,-0.406
34.79,133.43,-0.406
34.81,133.24,-0.406
34.83,133.06,-0.405
34.85,132.88,-0.405
34.87,132.70,-0.405
34.89,132.51,-0.405
34.91,132.33,-0.405
34.92,132.15,-0.404
34.94,131.96,-0.404
34.96,131.78,-0.404
34.98,131.60,-0.404
35.00,131.41,-0.404
35.01,131.23,-0.403
35.03,131.05,-0.403
35.05,130.86,-0.403
35.07,130.68,-0.403
35.09,130.50,-0.403
35.11,130.31,-0.402
35.13,130.13,-0.402
35.14,129.95,-0.402
35.16,129.76,-0.402
35.18,129.58,-0.402
35.20,129.40,-0.402
35.22,129.21,-0.402
35.24,129.03,-0.401
35.25,128.85,-0.401
35.27,128.66,-0.401
35.29,128.48,-0.401
35.31,128.30,-0.401
35.33,128.11,-0.400
35.34,127.93,-0.400
[...]
119.22,10.98,0.214
119.24,11.16,0.214
119.25,11.34,0.214
119.27,11.53,0.214
119.29,11.71,0.214
119.31,11.90,0.214
119.33,12.08,0.214
119.35,12.26,0.214
119.36,12.44,0.214
119.38,12.63,0.214
119.40,12.81,0.214
119.42,12.99,0.214
119.44,13.18,0.214
119.46,13.36,0.214
119.48,13.55,0.214
119.49,13.73,0.214
119.51,13.91,0.214
119.53,14.10,0.214
119.55,14.28,0.215
119.57,14.46,0.215
119.59,14.65,0.215
119.60,14.83,0.215
119.62,15.01,0.215
119.64,15.19,0.215
119.66,15.38,0.215
119.68,15.56,0.215
119.70,15.74,0.215
119.71,15.93,0.215
119.73,16.11,0.215
119.75,16.29,0.215
119.77,16.48,0.215
119.79,16.66,0.215
119.80,16.85,0.215
119.82,17.03,0.215
119.84,17.21,0.215
119.86,17.40,0.215
119.88,17.58,0.215
119.90,17.76,0.215
119.91,17.95,0.216
119.93,18.13,0.216
119.95,18.31,0.216
119.97,18.50,0.216
119.99,18.68,0.216
120.01,18.86,0.216
120.03,19.05,0.216
120.04,19.23,0.216
120.06,19.41,0.216
120.08,19.60,0.216
120.10,19.78,0.216
120.12,19.96,0.216
120.14,20.15,0.216
120.15,20.33,0.216
120.17,20.51,0.216
120.19,20.70,0.217
120.21,20.88,0.217
120.23,21.06,0.217
120.25,21.25,0.217
120.26,21.43,0.217
120.28,21.61,0.217
120.30,21.80,0.217
120.32,21.98,0.217
120.34,22.17,0.217
120.35,22.35,0.217
120.37,22.53,0.217
120.39,22.72,0.217
120.41,22.90,0.218
120.43,23.08,0.218
120.45,23.27,0.218
120.46,23.45,0.218
120.48,23.63,0.218
120.50,23.82,0.218
120.52,24.00,0.218
120.54,24.18,0.218
120.56,24.37,0.218
120.58,24.55,0.218
120.59,24.74,0.219
120.61,24.92,0.219
120.63,25.10,0.219
120.65,25.29,0.219
120.67,25.47,0.219
120.69,25.65,0.219
120.70,25.84,0.219
120.72,26.02,0.219
120.74,26.20,0.219
120.76,26.39,0.219
120.78,26.57,0.219
120.80,26.75,0.219
120.81,26.94,0.220
120.83,27.12,0.220
120.85,27.30,0.220
120.87,27.49,0.220
120.89,27.67,0.220
120.90,27.86,0.220
120.92,28.04,0.220
120.94,28.22,0.220
120.96,28.41,0.220
120.98,28.59,0.220
121.00,28.77,0.220
121.01,28.96,0.221
121.03,29.14,0.221
121.05,29.32,0.221
121.07,29.51,0.221
121.09,29.69,0.221
121.11,29.87,0.221
121.13,30.06,0.221
121.14,30.24,0.221
121.16,30.43,0.221
121.18,30.61,0.221
121.20,30.79,0.221
121.22,30.98,0.221
121.24,31.16,0.222
121.25,31.34,0.222
121.27,31.53,0.222
121.29,31.71,0.222
121.31,31.89,0.222
121.33,32.08,0.222
121.35,32.26,0.222
121.36,32.44,0.222
121.38,32.63,0.222
121.40,32.81,0.222
121.42,32.99,0.222
121.44,33.18,0.222
121.45,33.36,0.222
121.47,33.55,0.222
121.49,33.73,0.222
121.51,33.91,0.223
121.53,34.10,0.223
121.55,34.28,0.223
121.56,34.46,0.223
121.58,34.65,0.223
121.60,34.83,0.223
121.62,35.01,0.223
121.64,35.20,0.223
121.66,35.38,0.223
121.68,35.56,0.223
121.69,35.75,0.223
121.71,35.93,0.223
121.73,36.12,0.223
121.75,36.30,0.224
121.77,36.48,0.224
121.79,36.67,0.224
121.80,36.85,0.224
121.82,37.03,0.224
121.84,37.22,0.224
121.86,37.40,0.224
121.88,37.58,0.224
121.90,37.77,0.224
121.91,37.95,0.224
121.93,38.13,0.224
121.95,38.32,0.224
121.97,38.50,0.224
121.99,38.68,0.224
122.00,38.87,0.225
122.02,39.05,0.225
122.04,39.23,0.225
122.06,39.42,0.225
122.08,39.60,0.225
122.10,39.78,0.225
122.11,39.97,0.225
122.13,40.15,0.225
122.15,40.34,0.225
122.17,40.52,0.225
122.19,40.70,0.225
122.21,40.89,0.225
122.23,41.07,0.225
122.24,41.25,0.226
122.26,41.44,0.226
122.28,41.62,0.226
122.30,41.80,0.226
122.32,41.99,0.226
122.34,42.17,0.226
122.35,42.35,0.226
122.37,42.54,0.226
122.39,42.72,0.226
122.41,42.90,0.226
122.43,43.09,0.226
122.45,43.27,0.226
122.46,43.45,0.226
122.48,43.64,0.226
122.50,43.82,0.226
122.52,44.00,0.227
122.54,44.19,0.227
122.55,44.37,0.227
122.57,44.56,0.227
122.59,44.74,0.227
122.61,44.92,0.227
122.63,45.11,0.227
122.65,45.29,0.227
122.66,45.47,0.227
122.68,45.66,0.227
122.70,45.84,0.227
122.72,46.03,0.227
122.74,46.21,0.227
122.76,46.39,0.228
122.78,46.58,0.228
122.79,46.76,0.228
122.81,46.94,0.228
122.83,47.13,0.228
122.85,47.31,0.228
122.87,47.49,0.228
122.89,47.68,0.228
122.90,47.86,0.228
122.92,48.04,0.228
122.94,48.23,0.228
122.96,48.41,0.229
122.98,48.59,0.229
123.00,48.78,0.229
123.01,48.96,0.229
123.03,49.14,0.229
123.05,49.33,0.229
123.07,49.51,0.229
123.09,49.70,0.229
123.10,49.88,0.229
123.12,50.06,0.229
123.14,50.25,0.229
123.16,50.43,0.230
123.18,50.61,0.230
123.20,50.80,0.230
123.21,50.98,0.230
123.23,51.16,0.230
123.25,51.35,0.230
123.27,51.53,0.230
123.29,51.71,0.230
123.31,51.90,0.230
123.33,52.08,0.230
123.34,52.26,0.230
123.36,52.45,0.230
123.38,52.63,0.231
123.40,52.81,0.231
123.42,53.00,0.231
123.44,53.18,0.231
123.45,53.37,0.231
123.47,53.55,0.231
123.49,53.73,0.231
123.51,53.92,0.231
123.53,54.10,0.231
123.55,54.28,0.231
123.56,54.47,0.231
123.58,54.65,0.232
123.60,54.83,0.232
123.62,55.02,0.232
123.64,55.20,0.232
123.65,55.38,0.232
123.67,55.57,0.232
123.69,55.75,0.232
123.71,55.93,0.232
123.73,56.12,0.232
123.75,56.30,0.232
123.76,56.48,0.232
123.78,56.67,0.233
123.80,56.85,0.233
123.82,57.04,0.233
123.84,57.22,0.233
123.86,57.40,0.233
123.88,57.59,0.233
123.89,57.77,0.233
123.91,57.95,0.233
123.93,58.14,0.233
123.95,58.32,0.233
123.97,58.50,0.234
123.99,58.69,0.234
124.00,58.87,0.234
124.02,59.05,0.234
124.04,59.24,0.234
124.06,59.42,0.234
124.08,59.60,0.234
124.10,59.79,0.234
124.11,59.97,0.234
124.13,60.15,0.234
124.15,60.34,0.234
124.17,60.52,0.234
124.19,60.71,0.234
124.20,60.89,0.234
124.22,61.07,0.235
124.24,61.26,0.235
124.26,61.44,0.235
124.28,61.62,0.235
124.30,61.81,0.235
124.31,61.99,0.235
124.33,62.17,0.235
124.35,62.36,0.235
124.37,62.54,0.235
124.39,62.72,0.235
124.41,62.91,0.235
124.43,63.09,0.236
124.44,63.28,0.236
124.46,63.46,0.236
124.48,63.64,0.236
124.50,63.83,0.236
124.52,64.01,0.236
124.54,64.19,0.236
124.55,64.38,0.236
124.57,64.56,0.236
124.59,64.74,0.236
124.61,64.93,0.236
124.63,65.11,0.237
124.65,65.29,0.237
124.66,65.48,0.237
124.68,65.66,0.237
124.70,65.85,0.237
124.72,66.03,0.237
124.74,66.21,0.237
124.75,66.40,0.237
124.77,66.58,0.237
124.79,66.76,0.237
124.81,66.95,0.237
124.83,67.13,0.238
124.85,67.31,0.238
124.86,67.50,0.238
124.88,67.68,0.238
124.90,67.86,0.238
124.92,68.05,0.238
124.94,68.23,0.238
124.96,68.41,0.238
124.98,68.60,0.238
124.99,68.78,0.238
125.01,68.97,0.239
125.03,69.15,0.239
125.05,69.33,0.239
125.07,69.52,0.239
125.09,69.70,0.239
125.10,69.88,0.239
125.12,70.07,0.239
125.14,70.25,0.239
125.16,70.44,0.240
125.18,70.62,0.240
125.20,70.81,0.240
125.21,70.99,0.240
125.23,71.18,0.240
125.25,71.36,0.241
125.27,71.54,0.241
125.29,71.73,0.241
125.30,71.91,0.241
125.32,72.09,0.241
125.34,72.28,0.241
125.36,72.46,0.241
125.38,72.64,0.241
125.40,72.82,0.241
125.41,73.01,0.241
125.43,73.19,0.241
125.45,73.37,0.241
125.47,73.56,0.241
125.49,73.74,0.241
125.51,73.92,0.241
125.53,74.11,0.241
125.54,74.29,0.241
125.56,74.47,0.241
125.58,74.66,0.241
125.60,74.84,0.241
125.62,75.02,0.241
125.64,75.21,0.241
125.65,75.39,0.241
125.67,75.57,0.241
125.69,75.76,0.241
125.71,75.94,0.241
125.73,76.12,0.241
125.75,76.31,0.241
125.76,76.49,0.241
125.78,76.67,0.241
125.80,76.86,0.241
125.82,77.04,0.241
125.84,77.22,0.242
125.85,77.41,0.242
125.87,77.59,0.242
125.89,77.77,0.242
125.91,77.96,0.242
125.93,78.14,0.242
125.95,78.32,0.242
125.96,78.51,0.242
125.98,78.69,0.242
126.00,78.87,0.242
126.02,79.06,0.242
126.04,79.24,0.242
126.06,79.42,0.242
126.08,79.61,0.242
126.09,79.79,0.243
126.11,79.97,0.243
126.13,80.16,0.243
126.15,80.34,0.243
126.17,80.52,0.243
126.19,80.71,0.243
126.20,80.89,0.243
126.22,81.07,0.243
126.24,81.26,0.244
126.26,81.44,0.244
126.28,81.63,0.244
126.30,81.81,0.244
126.31,81.99,0.244
126.33,82.18,0.244
126.35,82.36,0.244
126.37,82.54,0.244
126.39,82.73,0.244
126.40,82.91,0.245
126.42,83.09,0.245
126.44,83.28,0.245
126.46,83.46,0.245
126.48,83.64,0.245
126.50,83.83,0.245
126.51,84.01,0.245
126.53,84.19,0.245
126.55,84.38,0.245
126.57,84.56,0.245
126.59,84.74,0.245
126.61,84.93,0.245
126.63,85.11,0.245
126.64,85.29,0.245
126.66,85.48,0.245
126.68,85.66,0.245
126.70,85.84,0.245
126.72,86.03,0.246
126.74,86.21,0.246
126.75,86.39,0.246
126.77,86.58,0.246
126.79,86.76,0.246
126.81,86.95,0.246
126.83,87.13,0.246
126.85,87.31,0.246
126.86,87.50,0.246
126.88,87.68,0.246
126.90,87.86,0.246
126.92,88.05,0.247
126.94,88.23,0.247
126.95,88.41,0.247
126.97,88.60,0.247
126.99,88.78,0.247
127.01,88.97,0.247
127.03,89.15,0.247
127.05,89.33,0.247
127.06,89.52,0.247
127.08,89.70,0.248
127.10,89.88,0.248
127.12,90.07,0.248
127.14,90.25,0.248
127.16,90.43,0.248
127.18,90.62,0.248
127.19,90.80,0.248
127.21,90.98,0.248
127.23,91.17,0.248
127.25,91.35,0.248
127.27,91.53,0.248
127.29,91.72,0.248
127.30,91.90,0.248
127.32,92.08,0.248
127.34,92.27,0.248
127.36,92.45,0.248
127.38,92.63,0.249
127.40,92.82,0.249
127.41,93.00,0.249
127.43,93.18,0.249
127.45,93.37,0.249
127.47,93.55,0.249
127.49,93.74,0.249
127.50,93.92,0.249
127.52,94.10,0.250
127.54,94.29,0.250
127.56,94.47,0.250
127.58,94.65,0.250
127.60,94.84,0.250
127.61,95.02,0.250
127.63,95.20,0.250
127.65,95.39,0.250
127.67,95.57,0.250
127.69,95.76,0.251
127.71,95.94,0.251
127.73,96.12,0.251
127.74,96.30,0.251
127.76,96.49,0.251
127.78,96.67,0.251
127.80,96.86,0.251
127.82,97.04,0.251
127.84,97.22,0.251
127.85,97.41,0.251
127.87,97.59,0.251
127.89,97.77,0.251
127.91,97.96,0.252
127.93,98.14,0.252
127.95,98.32,0.252
127.96,98.51,0.252
127.98,98.69,0.252
128.00,98.87,0.252
128.02,99.06,0.252
128.04,99.24,0.252
128.05,99.42,0.252
128.07,99.61,0.253
128.09,99.79,0.253
128.11,99.97,0.253
128.13,100.16,0.253
128.15,100.34,0.253
128.16,100.52,0.253
128.18,100.71,0.253
128.20,100.89,0.253
128.22,101.08,0.253
128.24,101.26,0.253
128.26,101.44,0.254
128.28,101.62,0.254
128.29,101.81,0.254
128.31,101.99,0.254
128.33,102.17,0.254
128.35,102.36,0.254
128.37,102.54,0.254
128.39,102.73,0.254
128.40,102.91,0.255
128.42,103.09,0.255
128.44,103.28,0.255
128.46,103.46,0.255
128.48,103.64,0.255
128.50,103.83,0.255
128.51,104.01,0.255
128.53,104.19,0.255
128.55,104.38,0.256
128.57,104.56,0.256
128.59,104.74,0.256
128.60,104.93,0.256
128.62,105.11,0.256
128.64,105.29,0.256
128.66,105.48,0.256
128.68,105.66,0.256
128.70,105.84,0.256
128.71,106.03,0.256
128.73,106.21,0.257
128.75,106.40,0.257
128.77,106.58,0.257
128.79,106.76,0.257
128.81,106.95,0.257
128.83,107.13,0.257
128.84,107.31,0.257
128.86,107.50,0.257
128.88,107.68,0.258
128.90,107.87,0.258
128.92,108.05,0.258
128.94,108.23,0.258
128.95,108.42,0.258
128.97,108.60,0.258
128.99,108.78,0.258
129.01,108.97,0.259
129.03,109.15,0.259
129.05,109.33,0.259
129.06,109.52,0.259
129.08,109.70,0.259
129.10,109.88,0.259
129.12,110.07,0.259
129.14,110.25,0.259
129.15,110.43,0.259
129.17,110.62,0.259
129.19,110.80,0.259
129.21,110.98,0.259
129.23,111.17,0.259
129.25,111.35,0.259
129.26,111.53,0.259
129.28,111.72,0.260
129.30,111.90,0.260
129.32,112.08,0.260
129.34,112.27,0.260
129.36,112.45,0.260
129.38,112.64,0.260
129.39,112.82,0.260
129.41,113.00,0.260
129.43,113.19,0.260
129.45,113.37,0.260
129.47,113.55,0.260
129.49,113.74,0.261
129.50,113.92,0.261
129.52,114.10,0.261
129.54,114.29,0.261
129.56,114.47,0.261
129.58,114.65,0.261
129.60,114.84,0.261
129.61,115.02,0.261
129.63,115.20,0.261
129.65,115.39,0.261
129.67,115.57,0.261
129.69,115.75,0.261
129.70,115.94,0.261
129.72,116.12,0.262
129.74,116.30,0.262
129.76,116.49,0.262
129.78,116.67,0.262
129.80,116.85,0.262
129.81,117.04,0.262
129.83,117.22,0.262
129.85,117.40,0.262
129.87,117.59,0.262
129.89,117.77,0.262
129.91,117.95,0.262
129.93,118.14,0.262
129.94,118.32,0.263
129.96,118.51,0.263
129.98,118.69,0.263
130.00,118.87,0.263
130.02,119.06,0.263
130.04,119.24,0.263
130.05,119.42,0.263
130.07,119.61,0.264
130.09,119.79,0.264
130.11,119.97,0.264
130.13,120.16,0.264
130.15,120.34,0.264
130.16,120.52,0.264
130.18,120.71,0.264
130.20,120.89,0.264
130.22,121.07,0.264
130.24,121.26,0.264
130.25,121.44,0.265
130.27,121.63,0.265
130.29,121.81,0.265
130.31,121.99,0.265
130.33,122.18,0.265
130.35,122.36,0.265
130.36,122.54,0.265
130.38,122.73,0.265
130.40,122.91,0.265
130.42,123.09,0.265
130.44,123.28,0.265
130.46,123.46,0.265
130.48,123.64,0.266
130.49,123.83,0.266
130.51,124.01,0.266
130.53,124.19,0.266
130.55,124.38,0.266
130.57,124.56,0.266
130.59,124.74,0.266
130.60,124.93,0.266
130.62,125.11,0.266
130.64,125.29,0.266
130.66,125.48,0.266
130.68,125.66,0.266
130.70,125.84,0.267
130.71,126.03,0.267
130.73,126.21,0.267
130.75,126.40,0.267
130.77,126.58,0.267
130.79,126.76,0.267
130.80,126.95,0.267
130.82,127.13,0.267
130.84,127.31,0.267
130.86,127.50,0.268
130.88,127.68,0.268
130.90,127.86,0.268
130.91,128.05,0.268
130.93,128.23,0.268
130.95,128.41,0.268
130.97,128.60,0.268
130.99,128.78,0.268
131.01,128.96,0.268
131.03,129.15,0.268
131.04,129.33,0.268
131.06,129.51,0.269
131.08,129.70,0.269
131.10,129.88,0.269
131.12,130.06,0.269
131.14,130.25,0.269
131.15,130.43,0.269
131.17,130.62,0.269
131.19,130.80,0.269
131.21,130.98,0.269
131.23,131.17,0.269
131.25,131.35,0.269
131.26,131.53,0.269
131.28,131.72,0.269
131.30,131.90,0.269
131.32,132.08,0.270
131.34,132.27,0.270
131.35,132.45,0.270
131.37,132.63,0.270
131.39,132.82,0.270
131.41,133.00,0.270
131.43,133.19,0.270
131.45,133.37,0.270
131.46,133.55,0.270
131.48,133.73,0.270
131.50,133.92,0.271
131.52,134.10,0.271
131.54,134.29,0.271
131.56,134.47,0.271
131.58,134.65,0.271
131.59,134.84,0.271
131.61,135.02,0.271
131.63,135.20,0.271
131.65,135.39,0.271
131.67,135.57,0.271
131.69,135.75,0.271
131.70,135.94,0.272
131.72,136.12,0.272
131.74,136.30,0.272
131.76,136.48,0.272
131.78,136.67,0.272
131.80,136.85,0.272
131.81,137.04,0.272
131.83,137.22,0.272
131.85,137.40,0.272
131.87,137.59,0.272
131.89,137.77,0.272
131.90,137.95,0.273
131.92,138.14,0.273
131.94,138.32,0.273
131.96,138.50,0.273
131.98,138.69,0.273
132.00,138.87,0.273
132.01,139.05,0.273
132.03,139.24,0.274
132.05,139.42,0.274
132.07,139.60,0.274
132.09,139.79,0.274
132.11,139.97,0.274
132.13,140.15,0.274
132.14,140.34,0.274
132.16,140.52,0.274
132.18,140.70,0.275
132.20,140.89,0.275
132.22,141.07,0.275
132.24,141.26,0.275
132.25,141.44,0.275
132.27,141.62,0.275
132.29,141.81,0.275
132.31,141.99,0.275
132.33,142.17,0.276
132.35,142.36,0.276
132.36,142.54,0.276
132.38,142.72,0.276
132.40,142.91,0.276
132.42,143.09,0.276
132.44,143.27,0.276
132.45,143.46,0.276
132.47,143.64,0.276
132.49,143.82,0.276
132.51,144.01,0.277
132.53,144.19,0.277
132.55,144.37,0.277
132.56,144.56,0.277
132.58,144.74,0.277
132.60,144.92,0.277
132.62,145.11,0.277
132.64,145.29,0.278
132.66,145.47,0.278
132.68,145.66,0.278
132.69,145.84,0.278
132.71,146.03,0.278
132.73,146.21,0.278
132.75,146.40,0.278
132.77,146.58,0.279
132.79,146.76,0.279
132.80,146.94,0.279
132.82,147.13,0.279
132.84,147.31,0.279
132.86,147.49,0.279
132.88,147.68,0.279
132.90,147.86,0.279
132.91,148.05,0.280
132.93,148.23,0.280
132.95,148.41,0.280
132.97,148.60,0.280
132.99,148.78,0.280
133.00,148.96,0.280
133.02,149.15,0.281
133.04,149.33,0.281
133.06,149.51,0.281
133.08,149.70,0.281
133.10,149.88,0.281
133.11,150.06,0.281
133.13,150.25,0.282
133.15,150.43,0.282
133.17,150.61,0.282
133.19,150.80,0.282
133.21,150.98,0.282
133.23,151.16,0.282
133.24,151.34,0.283
133.26,151.53,0.283
133.28,151.71,0.283
133.30,151.90,0.283
133.32,152.08,0.283
133.34,152.26,0.284
133.35,152.45,0.284
133.37,152.63,0.284
133.39,152.81,0.284
133.41,153.00,0.285
133.43,153.18,0.285
133.45,153.36,0.285
133.46,153.55,0.285
133.48,153.73,0.286
133.50,153.91,0.286
133.52,154.10,0.286
133.54,154.28,0.286
133.55,154.46,0.287
133.57,154.65,0.287
133.59,154.83,0.287
133.61,155.01,0.288
133.63,155.20,0.288
133.65,155.38,0.288
133.66,155.56,0.288
133.68,155.75,0.289
133.70,155.93,0.289
133.72,156.11,0.289
133.74,156.30,0.290
133.76,156.48,0.290
133.78,156.66,0.290
133.79,156.85,0.291
133.81,157.03,0.291
133.83,157.21,0.292
133.85,157.40,0.292
133.87,157.58,0.292
133.89,157.76,0.293
133.90,157.95,0.293
133.92,158.13,0.293
133.94,158.32,0.294
133.96,158.50,0.294
133.98,158.68,0.295
134.00,158.87,0.295
134.01,159.05,0.296
134.03,159.23,0.296
134.05,159.42,0.296
134.07,159.60,0.297
134.09,159.78,0.298
134.10,159.97,0.298
134.12,160.15,0.299
134.14,160.33,0.299
134.16,160.52,0.300
134.18,160.70,0.300
134.20,160.88,0.301
134.21,161.07,0.301
134.23,161.25,0.302
134.25,161.43,0.303
134.27,161.62,0.303
134.29,161.80,0.304
134.31,161.98,0.305
134.33,162.17,0.305
134.34,162.35,0.306
134.36,162.53,0.306
134.38,162.72,0.307
134.40,162.90,0.308
134.42,163.08,0.308
134.44,163.27,0.309
134.45,163.45,0.310
134.47,163.63,0.311
134.49,163.82,0.311
134.51,164.00,0.312
134.53,164.18,0.313
134.55,164.37,0.314
134.56,164.55,0.314
134.58,164.73,0.315
134.60,164.92,0.316
134.62,165.10,0.317
134.64,165.29,0.317
134.65,165.47,0.318
134.67,165.65,0.319
134.69,165.84,0.319
134.71,166.02,0.320
134.73,166.20,0.321
134.75,166.39,0.321
134.76,166.57,0.322
134.78,166.75,0.323
134.80,166.94,0.324
134.82,167.12,0.324
134.84,167.30,0.325
134.86,167.49,0.325
134.88,167.67,0.326
134.89,167.85,0.326
134.91,168.04,0.327
134.93,168.22,0.327
134.95,168.40,0.328
134.97,168.59,0.329
134.99,168.77,0.329
135.00,168.95,0.330
135.02,169.14,0.330
135.04,169.32,0.330
135.06,169.50,0.331
135.08,169.69,0.331
135.10,169.87,0.331
135.11,170.05,0.332
135.13,170.24,0.332
135.15,170.42,0.333
135.17,170.60,0.333
135.19,170.79,0.333
135.20,170.97,0.333
135.22,171.15,0.334
135.24,171.34,0.334
135.26,171.52,0.334
135.28,171.70,0.334
135.30,171.89,0.334
135.31,172.07,0.335
135.33,172.25,0.335
135.35,172.44,0.335
135.37,172.62,0.335
135.39,172.80,0.335
135.41,172.99,0.335
135.43,173.17,0.335
135.44,173.35,0.335
135.46,173.54,0.335
135.48,173.72,0.335
135.50,173.90,0.336
135.52,174.09,0.336
135.54,174.27,0.336
135.55,174.46,0.336
135.57,174.64,0.336
135.59,174.82,0.336
135.61,175.01,0.336
135.63,175.19,0.336
135.65,175.37,0.336
135.66,175.56,0.336
135.68,175.74,0.336
135.70,175.92,0.335
135.72,176.11,0.335
135.74,176.29,0.335
135.75,176.47,0.335
135.77,176.66,0.335
135.79,176.84,0.335
135.81,177.02,0.335
135.83,177.21,0.335
135.85,177.39,0.335
135.86,177.57,0.335
135.88,177.76,0.335
135.90,177.94,0.335
135.92,178.12,0.335
135.94,178.31,0.335
135.96,178.49,0.335
135.98,178.67,0.335
135.99,178.86,0.335
136.01,179.04,0.335
136.03,179.23,0.335
136.05,179.41,0.335
136.07,179.59,0.335
136.09,179.78,0.335
136.10,179.96,0.335
136.12,180.14,0.335
136.14,180.33,0.335
136.16,180.51,0.335
136.18,180.69,0.335
136.20,180.88,0.335
136.21,181.06,0.335
136.23,181.24,0.335
136.25,181.43,0.335
136.27,181.61,0.335
136.29,181.79,0.335
136.30,181.98,0.335
136.32,182.16,0.335
136.34,182.34,0.335
136.36,182.53,0.335
136.38,182.71,0.336
136.40,182.89,0.336
136.41,183.08,0.336
136.43,183.26,0.336
136.45,183.45,0.336
136.47,183.63,0.336
136.49,183.81,0.336
136.51,183.99,0.336
136.53,184.18,0.336
136.54,184.36,0.336
136.56,184.54,0.336
136.58,184.73,0.336
136.60,184.91,0.336
136.62,185.10,0.336
136.63,185.28,0.336
136.65,185.46,0.336
136.67,185.64,0.337
136.69,185.83,0.337
136.71,186.01,0.337
136.73,186.19,0.337
136.75,186.38,0.337
136.76,186.56,0.337
136.78,186.75,0.337
136.80,186.93,0.337
136.82,187.11,0.337
136.84,187.30,0.337
136.85,187.48,0.337
136.87,187.66,0.338
136.89,187.85,0.338
136.91,188.03,0.338
136.93,188.22,0.338
136.95,188.40,0.338
136.97,188.58,0.338
136.98,188.77,0.338
137.00,188.95,0.338
137.02,189.13,0.338
137.04,189.32,0.338
137.06,189.50,0.338
137.08,189.68,0.339
137.09,189.87,0.339
137.11,190.05,0.339
137.13,190.23,0.339
137.15,190.42,0.339
137.17,190.60,0.339
137.18,190.78,0.339
137.20,190.97,0.339
137.22,191.15,0.339
137.24,191.33,0.339
137.26,191.52,0.339
137.28,191.70,0.339
137.30,191.88,0.340
137.31,192.07,0.340
137.33,192.25,0.340
137.35,192.43,0.340
137.37,192.62,0.340
137.39,192.80,0.340
137.40,192.98,0.340
137.42,193.17,0.340
137.44,193.35,0.340
137.46,193.53,0.340
137.48,193.72,0.340
137.50,193.90,0.340
137.52,194.08,0.340
137.53,194.27,0.341
137.55,194.45,0.341
137.57,194.63,0.341
137.59,194.82,0.341
137.61,195.00,0.341
137.63,195.18,0.341
137.64,195.37,0.341
137.66,195.55,0.342
137.68,195.74,0.342
137.70,195.92,0.342
137.72,196.10,0.342
137.73,196.29,0.342
137.75,196.47,0.342
137.77,196.65,0.342
137.79,196.84,0.342
137.81,197.02,0.342
137.83,197.20,0.342
137.85,197.39,0.342
137.86,197.57,0.342
137.88,197.75,0.343
137.90,197.94,0.343
137.92,198.12,0.343
137.94,198.30,
137.95,198.49,
137.97,198.67,
137.99,,
137.99,,