File: DSC/Olivia/2025_08_10_Al2O3_TS_n60C_250C_10Cmin_x3.csv
Filename,2025_08_10_Al2O3_TS_n60C_250C_10Cmin_x3
Instrument name,DSC2A-00468 (192.168.1.100)
Operator,Yarger
rundate,8/11/2025
Sample name,2025_08_10_Al2O3_TS_n60C_250C_10Cmin_x3
proceduresegments,Data Off ; Equilibrate -60.00 °C; Data On ; Ramp 10.00 °C/min to 250.00 °C; Data Off ; Isothermal 2.0 min; Data On ; Ramp 10.00 °C/min to -60.00 °C; Data Off ; Isothermal 2.0 min; Data On ; Ramp 10.00 °C/min to 250.00 °C; Data Off ; Isothermal 2.0 min; Data On ; Ramp 10.00 °C/min to -60.00 °C; Data Off ; Isothermal 2.0 min; Data On ; Ramp 10.00 °C/min to 250.00 °C
[File Parameters]
Run date,8/11/2025 1:05:40 AM
Trios version,5.1.1.46572
Original File Name,
Current File Name,D:\DSC2500\JYarger\2025_08_10_Al2O3_TS_n60C_250C_10Cmin_x3.tri
[Procedure]
Procedure Name,TS_n60C_250C_10Cmin_x3
Sample Name,2025_08_10_Al2O3_TS_n60C_250C_10Cmin_x3
Sample Mass,32.82 mg
Reference Sample Mass,0 mg
Pan Mass,4.15 mg
Pan Number,7
Reference Pan Mass,32.42 mg
Reference Pan Number,10
Pan Type,Aluminum
Comments,Thermal support Al pans/lids. DSC_Samples_A2_Tray_August2025 google sheet.
Project Name,Pharma
Operator,Yarger
Test,Custom
Unload Max Temperature,30
Unload Min Temperature,30
Load Max Temperature,30
Load Min Temperature,30
Stop on Gas Flow Error,Yes
[Signal List]
Signal #1,Time (min)
Signal #2,Temperature (°C)
Signal #3,Heat Flow (mW)
Signal #4,Delta T (µV)
Signal #5,Delta Tzero (µV)
Signal #6,Tzero Temperature (°C)
Signal #7,Cell Purge (mL/min)
Signal #8,Heater Temp (°C)
Signal #9,Power Delivered (W)
Signal #10,Reference Junction Temperature (°C)
Signal #11,Flange Temperature (°C)
Signal #12,Heat Flow Phase (rad)
Signal #13,Total Heat Capacity (J/°C)
Signal #14,Heat Capacity (J/°C)
[Configuration]
Company Name,ASU
Instrument Name,DSC2A-00468
Instrument Type,DSC2500
Serial Number,DSC2A-00468
IP,192.168.1.100
Location of Instrument,MRRC
DisplayType,Unknown
Sample Interval ,0.1 s/pt
Selected Heat Flow,T4P
Exotherm Direction,Down
Cell Serial,DRC2-00792
Lid Type,Standard
Cooler,RCS 90
Leave Cooler on at End of Sequence,On
Gas 2,Nitrogen
Gas Selected,Channel 1
Flow Rate,50 mL/min
Secondary Purge,On
Licensed Heat Flow,Heat Flow T4P
Modulation Licensed,Yes
[Versions]
Common IDD Version,1
Cortex Version,VER 2.10.2.31
Driver,5.0.0.6
GDM Version,1.0.3.3
TouchscreenVersion,1.0.0.16145
FEP Version,1.2.1.21
FEP Bootloader,2.0.0.5
AutoSampler Version,2.1.1.26
Auto Sampler Bootloader,2.0.0.5
FCM Version,1.1.0.3
FCM Bootloader,2.0.0.5
[Experiment Logs]
Experiment Log Entry # 1,Data On set to 0
Experiment Log Entry # 3,Equilibrate Segment -60 (C) Started
Experiment Log Entry # 5,Air Cool is off.
Experiment Log Entry # 7,Data On set to 1
Experiment Log Entry # 9,Ramp Segment 10 C/min to 250 Started
Experiment Log Entry # 11,Data On set to 0
Experiment Log Entry # 13,Isothermal Segment 2 min started
Experiment Log Entry # 15,Data On set to 1
Experiment Log Entry # 17,Ramp Segment 10 C/min to -60 Started
Experiment Log Entry # 19,Data On set to 0
Experiment Log Entry # 21,Isothermal Segment 2 min started
Experiment Log Entry # 23,Data On set to 1
Experiment Log Entry # 25,Ramp Segment 10 C/min to 250 Started
Experiment Log Entry # 27,Data On set to 0
Experiment Log Entry # 29,Isothermal Segment 2 min started
Experiment Log Entry # 31,Data On set to 1
Experiment Log Entry # 33,Ramp Segment 10 C/min to -60 Started
Experiment Log Entry # 35,Data On set to 0
Experiment Log Entry # 37,Isothermal Segment 2 min started
Experiment Log Entry # 39,Data On set to 1
Experiment Log Entry # 41,Ramp Segment 10 C/min to 250 Started
[Method Log]
Method Log Entry # 1,Data Off
Method Log Entry # 2,Equilibrate -60 °C
Method Log Entry # 3,Data On
Method Log Entry # 4,(Ramp 1114526) Ramp 10 °C/minute to 250 °C
Method Log Entry # 5,Data Off
Method Log Entry # 6,Isothermal 2 minutes
Method Log Entry # 7,Data On
Method Log Entry # 8,(Ramp 1114530) Ramp 10 °C/minute to -60 °C
Method Log Entry # 9,Data Off
Method Log Entry # 10,Isothermal 2 minutes
Method Log Entry # 11,Data On
Method Log Entry # 12,(Ramp 1114534) Ramp 10 °C/minute to 250 °C
Method Log Entry # 13,Data Off
Method Log Entry # 14,Isothermal 2 minutes
Method Log Entry # 15,Data On
Method Log Entry # 16,(Ramp 1114538) Ramp 10 °C/minute to -60 °C
Method Log Entry # 17,Data Off
Method Log Entry # 18,Isothermal 2 minutes
Method Log Entry # 19,Data On
Method Log Entry # 20,(Ramp 1114542) Ramp 10 °C/minute to 250 °C
Cell Serial,DRC2-00792
[T1 Calibration]
Slope,-0.008529666
Offset,9.636258
Initial Temperature,98.23
GUID,f8bfdadc-4977-4fdf-ba6d-0ba9134940c3
[TZero Calibration]
Date Applied,11/29/2022 4:06:13 PM
Description,From -89.059 °C to 396.009 °C at 20.000°C/min
Gas Type,Nitrogen
Pan Type,None
Source Files 1,C:\Users\yargerlab\Desktop\DSC Data\General\TZero_calibration_11_29_22_2nd(2).tri
Source Files 2,C:\Users\yargerlab\Desktop\DSC Data\General\TZero_calibration_11_29_22_2nd(3).tri
Delta T Offset,13.05235
Delta T Slope,-0.007271007
Delta T0 Offset,-13.69128
Delta T0 Slope,0.06063341
[Temperature Calibration]
Date Applied,11/29/2022 7:12:28 PM
Description,From 106.590 °C to 186.590 °C at 10.000°C/min
Gas Type,Nitrogen
Pan Type,Tzero Aluminum Hermetic
Source Files 1,C:\Users\yargerlab\Desktop\DSC Data\General\Indium(6).tri
Measured 1,157.391
Known 1,156.598
[Cell Constant Calibration]
Date Applied,11/29/2022 7:12:29 PM
Description,From 106.590 °C to 186.590 °C at 10.000°C/min
Gas Type,Nitrogen
Pan Type,Tzero Aluminum Hermetic
Source Files 1,C:\Users\yargerlab\Desktop\DSC Data\General\Indium(6).tri
T4P KCell,1.006051
Onset Slope,63.26126 mW/°C
[Direct Cp Calibration]
Date Applied,11/30/2022 11:04:51 AM
Description,From -79.983 °C to 298.409 °C at 10.000°C/min
Gas Type,Nitrogen
Pan Type,Tzero Aluminum Hermetic
Source Files 1,C:\Users\yargerlab\Desktop\DSC Data\General\Sapphire_Heat_Capacity_11_30_22.tri
[Rev Cp Calibration]
Date Applied,11/30/2022 1:58:51 PM
Description,From -79.996 °C to 292.812 °C at 3.000°C/min
Gas Type,Nitrogen
Pan Type,Tzero Aluminum Hermetic
Source Files 1,C:\Users\yargerlab\Desktop\DSC Data\General\Sapphire_MDSC_Calibration_11_30_22.tri
[step]
Ramp 10.00 °C/min to 250.00 °C
Time,Temperature,Heat Flow (Normalized)
min,°C,W/g
0.00,-59.81,-0.006
0.02,-59.82,-0.005
0.04,-59.81,-0.005
0.07,-59.79,-0.006
0.09,-59.74,-0.008
0.11,-59.65,-0.009
0.13,-59.53,-0.009
0.15,-59.38,-0.006
0.17,-59.21,-0.002
0.19,-59.03,0.001
0.22,-58.83,0.005
0.24,-58.64,0.007
0.26,-58.43,0.010
0.28,-58.23,0.011
0.30,-58.02,0.013
0.33,-57.81,0.013
0.35,-57.60,0.014
0.37,-57.39,0.015
0.39,-57.18,0.015
0.41,-56.97,0.015
0.43,-56.76,0.016
0.45,-56.55,0.016
0.48,-56.34,0.016
0.50,-56.12,0.016
0.52,-55.91,0.016
0.54,-55.70,0.016
0.56,-55.49,0.016
0.58,-55.27,0.016
0.61,-55.06,0.016
0.63,-54.85,0.016
0.65,-54.63,0.016
0.67,-54.42,0.016
0.69,-54.20,0.017
0.72,-53.99,0.017
0.74,-53.77,0.017
0.76,-53.56,0.017
0.78,-53.34,0.017
0.80,-53.13,0.017
0.82,-52.92,0.017
0.85,-52.70,0.017
0.87,-52.49,0.017
0.89,-52.27,0.017
0.91,-52.06,0.017
0.93,-51.84,0.017
0.95,-51.62,0.017
0.98,-51.41,0.017
1.00,-51.19,0.017
1.02,-50.98,0.017
1.04,-50.76,0.017
1.06,-50.55,0.017
1.08,-50.33,0.017
1.11,-50.11,0.017
1.13,-49.90,0.017
1.15,-49.68,0.017
1.17,-49.47,0.017
1.19,-49.25,0.017
1.21,-49.03,0.017
1.23,-48.82,0.017
1.26,-48.60,0.017
1.28,-48.39,0.018
1.30,-48.17,0.018
1.32,-47.95,0.018
1.34,-47.74,0.018
1.37,-47.52,0.018
1.39,-47.30,0.018
1.41,-47.09,0.018
1.43,-46.87,0.018
1.45,-46.65,0.018
1.47,-46.44,0.018
1.49,-46.22,0.018
1.52,-46.00,0.018
1.54,-45.79,0.018
1.56,-45.57,0.018
1.58,-45.35,0.018
1.60,-45.14,0.018
1.63,-44.92,0.018
1.65,-44.70,0.018
1.67,-44.49,0.018
1.69,-44.27,0.018
1.71,-44.05,0.018
1.73,-43.84,0.018
1.76,-43.62,0.018
1.78,-43.40,0.018
1.80,-43.19,0.018
1.82,-42.97,0.018
1.84,-42.75,0.018
1.86,-42.54,0.018
1.88,-42.32,0.018
1.91,-42.10,0.018
1.93,-41.88,0.018
1.95,-41.67,0.018
1.97,-41.45,0.018
1.99,-41.23,0.018
2.02,-41.02,0.018
2.04,-40.80,0.018
2.06,-40.58,0.018
2.08,-40.37,0.018
2.10,-40.15,0.018
2.12,-39.93,0.018
2.14,-39.72,0.018
2.17,-39.50,0.018
2.19,-39.28,0.018
2.21,-39.07,0.018
2.23,-38.85,0.018
2.25,-38.63,0.018
2.28,-38.42,0.018
2.30,-38.20,0.018
2.32,-37.98,0.018
2.34,-37.76,0.018
2.36,-37.55,0.018
2.38,-37.33,0.018
2.41,-37.11,0.018
2.43,-36.90,0.018
2.45,-36.68,0.018
2.47,-36.46,0.018
2.49,-36.24,0.018
2.51,-36.03,0.018
2.54,-35.81,0.018
2.56,-35.59,0.018
2.58,-35.38,0.018
2.60,-35.16,0.018
2.62,-34.94,0.018
2.64,-34.73,0.018
2.66,-34.51,0.018
2.69,-34.29,0.018
2.71,-34.08,0.018
2.73,-33.86,0.018
2.75,-33.64,0.018
2.77,-33.42,0.018
2.79,-33.21,0.018
2.82,-32.99,0.018
2.84,-32.77,0.018
2.86,-32.56,0.018
2.88,-32.34,0.018
2.90,-32.12,0.018
2.93,-31.91,0.018
2.95,-31.69,0.018
2.97,-31.47,0.018
2.99,-31.25,0.018
3.01,-31.04,0.018
3.03,-30.82,0.018
3.06,-30.60,0.018
3.08,-30.39,0.018
3.10,-30.17,0.018
3.12,-29.95,0.018
3.14,-29.74,0.018
3.16,-29.52,0.018
3.19,-29.30,0.018
3.21,-29.09,0.018
3.23,-28.87,0.018
3.25,-28.65,0.018
3.27,-28.44,0.018
3.29,-28.22,0.018
3.31,-28.00,0.018
3.34,-27.78,0.018
3.36,-27.57,0.018
3.38,-27.35,0.018
3.40,-27.13,0.018
3.42,-26.91,0.018
3.44,-26.70,0.018
3.47,-26.48,0.018
3.49,-26.27,0.018
3.51,-26.05,0.018
3.53,-25.83,0.018
3.55,-25.61,0.018
3.58,-25.40,0.018
3.60,-25.18,0.018
3.62,-24.96,0.018
3.64,-24.75,0.018
3.66,-24.53,0.018
3.68,-24.31,0.018
3.71,-24.09,0.018
3.73,-23.88,0.018
3.75,-23.66,0.018
3.77,-23.44,0.018
3.79,-23.23,0.018
3.81,-23.01,0.018
3.84,-22.79,0.018
3.86,-22.58,0.018
3.88,-22.36,0.018
3.90,-22.14,0.018
3.92,-21.93,0.018
3.94,-21.71,0.018
3.96,-21.49,0.018
3.99,-21.27,0.018
4.01,-21.06,0.018
4.03,-20.84,0.018
4.05,-20.62,0.018
4.07,-20.41,0.018
4.09,-20.19,0.018
4.12,-19.97,0.018
4.14,-19.76,0.018
4.16,-19.54,0.018
4.18,-19.32,0.018
4.20,-19.11,0.018
4.23,-18.89,0.018
4.25,-18.67,0.018
4.27,-18.46,0.018
4.29,-18.24,0.018
4.31,-18.02,0.018
4.33,-17.80,0.018
4.35,-17.59,0.018
4.38,-17.37,0.018
4.40,-17.15,0.018
4.42,-16.94,0.018
4.44,-16.72,0.018
4.46,-16.50,0.018
4.49,-16.28,0.018
4.51,-16.07,0.018
4.53,-15.85,0.018
4.55,-15.63,0.018
4.57,-15.42,0.018
4.59,-15.20,0.018
4.61,-14.98,0.018
4.64,-14.77,0.018
4.66,-14.55,0.018
4.68,-14.33,0.018
4.70,-14.12,0.018
4.72,-13.90,0.018
4.75,-13.68,0.018
4.77,-13.47,0.018
4.79,-13.25,0.018
4.81,-13.03,0.018
4.83,-12.82,0.018
4.85,-12.60,0.018
4.88,-12.38,0.018
4.90,-12.16,0.018
4.92,-11.95,0.018
4.94,-11.73,0.018
4.96,-11.51,0.018
4.98,-11.30,0.018
5.00,-11.08,0.018
5.03,-10.86,0.018
5.05,-10.65,0.018
5.07,-10.43,0.018
5.09,-10.21,0.018
5.11,-9.99,0.018
5.14,-9.78,0.018
5.16,-9.56,0.018
5.18,-9.34,0.018
5.20,-9.13,0.018
5.22,-8.91,0.018
5.24,-8.70,0.018
5.26,-8.48,0.018
5.29,-8.26,0.018
5.31,-8.04,0.018
5.33,-7.83,0.018
5.35,-7.61,0.018
5.37,-7.39,0.018
5.40,-7.18,0.018
5.42,-6.96,0.018
5.44,-6.74,0.018
5.46,-6.53,0.018
5.48,-6.31,0.018
5.50,-6.09,0.018
5.53,-5.87,0.018
5.55,-5.66,0.018
5.57,-5.44,0.018
5.59,-5.22,0.018
5.61,-5.01,0.018
5.63,-4.79,0.018
5.65,-4.57,0.018
5.68,-4.36,0.018
5.70,-4.14,0.018
5.72,-3.92,0.018
5.74,-3.71,0.018
5.76,-3.49,0.018
5.79,-3.27,0.018
5.81,-3.06,0.018
5.83,-2.84,0.018
5.85,-2.62,0.018
5.87,-2.40,0.018
5.89,-2.19,0.018
5.91,-1.97,0.018
5.94,-1.75,0.018
5.96,-1.53,0.018
5.98,-1.32,0.018
6.00,-1.10,0.018
6.02,-0.89,0.018
6.05,-0.67,0.018
6.07,-0.45,0.018
6.09,-0.24,0.018
6.11,-0.02,0.018
6.13,0.20,0.018
6.15,0.42,0.018
6.18,0.63,0.018
6.20,0.85,0.018
6.22,1.07,0.018
6.24,1.29,0.018
6.26,1.50,0.018
6.28,1.72,0.018
6.30,1.93,0.019
6.33,2.15,0.019
6.35,2.37,0.019
6.37,2.59,0.019
6.39,2.80,0.019
6.41,3.02,0.019
6.44,3.24,0.019
6.46,3.45,0.019
6.48,3.67,0.019
6.50,3.89,0.019
6.52,4.10,0.019
6.54,4.32,0.019
6.56,4.54,0.019
6.59,4.76,0.019
6.61,4.97,0.019
6.63,5.19,0.019
6.65,5.40,0.019
6.67,5.62,0.019
6.70,5.84,0.019
6.72,6.06,0.019
6.74,6.27,0.019
6.76,6.49,0.019
6.78,6.71,0.019
6.80,6.92,0.019
6.83,7.14,0.019
6.85,7.36,0.019
6.87,7.57,0.019
6.89,7.79,0.019
6.91,8.01,0.019
6.93,8.23,0.019
6.95,8.44,0.019
6.98,8.66,0.019
7.00,8.88,0.019
7.02,9.09,0.019
7.04,9.31,0.019
7.06,9.53,0.019
7.09,9.74,0.019
7.11,9.96,0.019
7.13,10.18,0.019
7.15,10.39,0.019
7.17,10.61,0.019
7.19,10.83,0.019
7.21,11.04,0.019
7.24,11.26,0.019
7.26,11.48,0.019
7.28,11.69,0.019
7.30,11.91,0.019
7.32,12.13,0.019
7.35,12.35,0.019
7.37,12.56,0.019
7.39,12.78,0.019
7.41,13.00,0.019
7.43,13.21,0.019
7.45,13.43,0.019
7.48,13.65,0.019
7.50,13.86,0.019
7.52,14.08,0.019
7.54,14.30,0.019
7.56,14.51,0.019
7.58,14.73,0.019
7.60,14.95,0.019
7.63,15.16,0.019
7.65,15.38,0.019
7.67,15.60,0.019
7.69,15.81,0.019
7.71,16.03,0.019
7.74,16.25,0.019
7.76,16.46,0.019
7.78,16.68,0.019
7.80,16.90,0.020
7.82,17.11,0.020
7.84,17.33,0.020
7.86,17.55,0.020
7.89,17.76,0.020
7.91,17.98,0.020
7.93,18.20,0.020
7.95,18.42,0.020
7.97,18.63,0.020
8.00,18.85,0.020
8.02,19.06,0.020
8.04,19.28,0.020
8.06,19.50,0.020
8.08,19.72,0.020
8.10,19.93,0.020
8.13,20.15,0.020
8.15,20.37,0.020
8.17,20.59,0.020
8.19,20.80,0.020
8.21,21.02,0.020
8.23,21.24,0.020
8.25,21.45,0.020
8.28,21.67,0.020
8.30,21.89,0.020
8.32,22.10,0.020
8.34,22.32,0.020
8.36,22.54,0.020
8.39,22.75,0.020
8.41,22.97,0.020
8.43,23.19,0.020
8.45,23.40,0.020
8.47,23.62,0.020
8.49,23.84,0.020
8.51,24.06,0.020
8.54,24.27,0.020
8.56,24.49,0.020
8.58,24.71,0.020
8.60,24.92,0.020
8.62,25.14,0.020
8.65,25.36,0.020
8.67,25.57,0.020
8.69,25.79,0.021
8.71,26.01,0.021
8.73,26.22,0.021
8.75,26.44,0.021
8.78,26.66,0.021
8.80,26.88,0.021
8.82,27.09,0.021
8.84,27.31,0.021
8.86,27.52,0.021
8.88,27.74,0.021
8.90,27.96,0.021
8.93,28.18,0.021
8.95,28.39,0.021
8.97,28.61,0.021
8.99,28.83,0.021
9.01,29.04,0.021
9.03,29.26,0.021
9.06,29.48,0.021
9.08,29.69,0.021
9.10,29.91,0.021
9.12,30.13,0.021
9.14,30.34,0.021
9.17,30.56,0.021
9.19,30.78,0.021
9.21,30.99,0.021
9.23,31.21,0.021
9.25,31.43,0.021
9.27,31.65,0.021
9.30,31.86,0.021
9.32,32.08,0.021
9.34,32.30,0.021
9.36,32.51,0.021
9.38,32.73,0.022
9.40,32.95,0.022
9.43,33.16,0.022
9.45,33.38,0.022
9.47,33.60,0.022
9.49,33.82,0.022
9.51,34.03,0.022
9.53,34.25,0.022
9.55,34.46,0.022
9.58,34.68,0.022
9.60,34.90,0.022
9.62,35.11,0.022
9.64,35.33,0.022
9.66,35.55,0.022
9.68,35.77,0.022
9.71,35.98,0.022
9.73,36.20,0.022
9.75,36.41,0.022
9.77,36.63,0.022
9.79,36.85,0.022
9.82,37.07,0.022
9.84,37.28,0.022
9.86,37.50,0.022
9.88,37.72,0.022
9.90,37.93,0.022
9.92,38.15,0.023
9.95,38.37,0.023
9.97,38.58,0.023
9.99,38.80,0.023
10.01,39.02,0.023
10.03,39.24,0.023
10.05,39.45,0.023
10.08,39.67,0.023
10.10,39.88,0.023
10.12,40.10,0.023
10.14,40.32,0.023
10.16,40.54,0.023
10.18,40.75,0.023
10.20,40.97,0.023
10.23,41.19,0.023
10.25,41.40,0.023
10.27,41.62,0.023
10.29,41.84,0.023
10.31,42.05,0.023
10.33,42.27,0.023
10.36,42.49,0.023
10.38,42.70,0.023
10.40,42.92,0.023
10.42,43.14,0.024
10.44,43.35,0.024
10.47,43.57,0.024
10.49,43.79,0.024
10.51,44.00,0.024
10.53,44.22,0.024
10.55,44.44,0.024
10.57,44.65,0.024
10.60,44.87,0.024
10.62,45.09,0.024
10.64,45.31,0.024
10.66,45.52,0.024
10.68,45.74,0.024
10.70,45.96,0.024
10.73,46.17,0.024
10.75,46.39,0.024
10.77,46.61,0.024
10.79,46.82,0.024
10.81,47.04,0.024
10.83,47.26,0.024
10.85,47.47,0.025
10.88,47.69,0.025
10.90,47.91,0.025
10.92,48.12,0.025
10.94,48.34,0.025
10.96,48.56,0.025
10.98,48.77,0.025
11.01,48.99,0.025
11.03,49.21,0.025
11.05,49.42,0.025
11.07,49.64,0.025
11.09,49.86,0.025
11.12,50.08,0.025
11.14,50.29,0.025
11.16,50.51,0.025
11.18,50.72,0.025
11.20,50.94,0.025
11.22,51.16,0.025
11.25,51.37,0.025
11.27,51.59,0.026
11.29,51.81,0.026
11.31,52.02,0.026
11.33,52.24,0.026
11.35,52.46,0.026
11.38,52.68,0.026
11.40,52.89,0.026
11.42,53.11,0.026
11.44,53.33,0.026
11.46,53.54,0.026
11.48,53.76,0.026
11.50,53.98,0.026
11.53,54.19,0.026
11.55,54.41,0.026
11.57,54.63,0.026
11.59,54.84,0.026
11.61,55.06,0.026
11.63,55.28,0.026
11.66,55.49,0.027
11.68,55.71,0.027
11.70,55.93,0.027
11.72,56.14,0.027
11.74,56.36,0.027
11.77,56.58,0.027
11.79,56.79,0.027
11.81,57.01,0.027
11.83,57.23,0.027
11.85,57.44,0.027
11.87,57.66,0.027
11.90,57.88,0.027
11.92,58.10,0.027
11.94,58.31,0.027
11.96,58.53,0.027
11.98,58.75,0.027
12.00,58.96,0.027
12.03,59.18,0.027
12.05,59.40,0.028
12.07,59.61,0.028
12.09,59.83,0.028
12.11,60.05,0.028
12.13,60.26,0.028
12.15,60.48,0.028
12.18,60.70,0.028
12.20,60.91,0.028
12.22,61.13,0.028
12.24,61.35,0.028
12.26,61.56,0.028
12.28,61.78,0.028
12.31,62.00,0.028
12.33,62.21,0.028
12.35,62.43,0.028
12.37,62.65,0.028
12.39,62.87,0.028
12.42,63.08,0.028
12.44,63.30,0.028
12.46,63.51,0.028
12.48,63.73,0.029
12.50,63.95,0.029
12.52,64.17,0.029
12.55,64.38,0.029
12.57,64.60,0.029
12.59,64.82,0.029
12.61,65.03,0.029
12.63,65.25,0.029
12.65,65.47,0.029
12.68,65.68,0.029
12.70,65.90,0.029
12.72,66.12,0.029
12.74,66.33,0.029
12.76,66.55,0.029
12.78,66.77,0.029
12.80,66.98,0.029
12.83,67.20,0.029
12.85,67.42,0.029
12.87,67.63,0.029
12.89,67.85,0.029
12.91,68.07,0.029
12.93,68.28,0.030
12.96,68.50,0.030
12.98,68.72,0.030
13.00,68.93,0.030
13.02,69.15,0.030
13.04,69.37,0.030
13.07,69.58,0.030
13.09,69.80,0.030
13.11,70.02,0.030
13.13,70.24,0.030
13.15,70.45,0.030
13.17,70.67,0.030
13.20,70.89,0.030
13.22,71.10,0.030
13.24,71.32,0.030
13.26,71.54,0.030
13.28,71.75,0.030
13.30,71.97,0.030
13.33,72.19,0.030
13.35,72.40,0.030
13.37,72.62,0.030
13.39,72.84,0.030
13.41,73.05,0.030
13.43,73.27,0.030
13.45,73.49,0.030
13.48,73.70,0.030
13.50,73.92,0.030
13.52,74.14,0.031
13.54,74.36,0.031
13.56,74.57,0.031
13.58,74.79,0.031
13.61,75.01,0.031
13.63,75.22,0.031
13.65,75.44,0.031
13.67,75.66,0.031
13.69,75.87,0.031
13.72,76.09,0.031
13.74,76.31,0.031
13.76,76.52,0.031
13.78,76.74,0.031
13.80,76.96,0.031
13.82,77.18,0.031
13.85,77.39,0.031
13.87,77.61,0.031
13.89,77.83,0.031
13.91,78.04,0.031
13.93,78.26,0.031
13.95,78.48,0.031
13.98,78.69,0.031
14.00,78.91,0.031
14.02,79.13,0.031
14.04,79.34,0.031
14.06,79.56,0.031
14.08,79.78,0.031
14.10,79.99,0.031
14.13,80.21,0.031
14.15,80.43,0.031
14.17,80.64,0.031
14.19,80.86,0.031
14.21,81.08,0.031
14.23,81.30,0.031
14.26,81.51,0.031
14.28,81.73,0.031
14.30,81.94,0.031
14.32,82.16,0.031
14.34,82.38,0.031
14.37,82.60,0.031
14.39,82.81,0.031
14.41,83.03,0.031
14.43,83.25,0.031
14.45,83.46,0.031
14.47,83.68,0.031
14.50,83.90,0.031
14.52,84.11,0.031
14.54,84.33,0.031
14.56,84.55,0.031
14.58,84.76,0.031
14.60,84.98,0.031
14.63,85.20,0.031
14.65,85.42,0.031
14.67,85.63,0.031
14.69,85.85,0.031
14.71,86.07,0.031
14.73,86.28,0.031
14.75,86.50,0.031
14.78,86.72,0.031
14.80,86.93,0.031
14.82,87.15,0.031
14.84,87.37,0.031
14.86,87.58,0.031
14.88,87.80,0.031
14.91,88.02,0.031
14.93,88.24,0.031
14.95,88.45,0.031
14.97,88.67,0.031
14.99,88.89,0.031
15.02,89.10,0.031
15.04,89.32,0.031
15.06,89.54,0.031
15.08,89.75,0.031
15.10,89.97,0.031
15.12,90.19,0.031
15.15,90.40,0.031
15.17,90.62,0.031
15.19,90.84,0.031
15.21,91.06,0.031
15.23,91.27,0.031
15.25,91.49,0.031
15.28,91.71,0.031
15.30,91.92,0.030
15.32,92.14,0.030
15.34,92.36,0.030
15.36,92.57,0.030
15.38,92.79,0.030
15.40,93.01,0.030
15.43,93.22,0.030
15.45,93.44,0.030
15.47,93.66,0.030
15.49,93.88,0.030
15.51,94.09,0.030
15.53,94.31,0.030
15.56,94.53,0.030
15.58,94.74,0.030
15.60,94.96,0.030
15.62,95.18,0.030
15.64,95.39,0.030
15.67,95.61,0.030
15.69,95.83,0.030
15.71,96.05,0.030
15.73,96.26,0.030
15.75,96.48,0.030
15.77,96.70,0.030
15.80,96.91,0.030
15.82,97.13,0.030
15.84,97.34,0.030
15.86,97.56,0.030
15.88,97.78,0.030
15.90,98.00,0.030
15.93,98.21,0.030
15.95,98.43,0.030
15.97,98.65,0.030
15.99,98.87,0.029
16.01,99.08,0.029
16.03,99.30,0.029
16.05,99.52,0.029
16.08,99.73,0.029
16.10,99.95,0.029
16.12,100.17,0.029
16.14,100.38,0.029
16.16,100.60,0.029
16.18,100.82,0.029
16.21,101.03,0.029
16.23,101.25,0.029
16.25,101.47,0.029
16.27,101.68,0.029
16.29,101.90,0.029
16.32,102.12,0.029
16.34,102.33,0.029
16.36,102.55,0.029
16.38,102.77,0.029
16.40,102.99,0.029
16.42,103.20,0.029
16.45,103.42,0.029
16.47,103.64,0.029
16.49,103.85,0.029
16.51,104.07,0.029
16.53,104.29,0.029
16.55,104.51,0.029
16.58,104.72,0.028
16.60,104.94,0.028
16.62,105.16,0.028
16.64,105.37,0.028
16.66,105.59,0.028
16.68,105.81,0.028
16.70,106.02,0.028
16.73,106.24,0.028
16.75,106.46,0.028
16.77,106.68,0.028
16.79,106.89,0.028
16.81,107.11,0.028
16.83,107.33,0.028
16.86,107.54,0.028
16.88,107.76,0.028
16.90,107.98,0.028
16.92,108.19,0.028
16.94,108.41,0.028
16.97,108.63,0.028
16.99,108.84,0.028
17.01,109.06,0.028
17.03,109.28,0.028
17.05,109.50,0.028
17.07,109.71,0.028
17.09,109.93,0.028
17.12,110.15,0.028
17.14,110.36,0.027
17.16,110.58,0.027
17.18,110.80,0.027
17.20,111.01,0.027
17.23,111.23,0.027
17.25,111.45,0.027
17.27,111.67,0.027
17.29,111.88,0.027
17.31,112.10,0.027
17.33,112.32,0.027
17.36,112.53,0.027
17.38,112.75,0.027
17.40,112.97,0.027
17.42,113.19,0.027
17.44,113.40,0.027
17.46,113.62,0.027
17.48,113.84,0.027
17.51,114.05,0.027
17.53,114.27,0.027
17.55,114.49,0.027
17.57,114.70,0.027
17.59,114.92,0.027
17.62,115.14,0.027
17.64,115.35,0.027
17.66,115.57,0.027
17.68,115.79,0.027
17.70,116.00,0.027
17.72,116.22,0.027
17.74,116.44,0.027
17.77,116.65,0.027
17.79,116.87,0.026
17.81,117.09,0.026
17.83,117.30,0.026
17.85,117.52,0.026
17.88,117.74,0.026
17.90,117.96,0.026
17.92,118.17,0.026
17.94,118.39,0.026
17.96,118.61,0.026
17.98,118.83,0.026
18.01,119.04,0.026
18.03,119.26,0.026
18.05,119.48,0.026
18.07,119.69,0.026
18.09,119.91,0.026
18.11,120.13,0.026
18.13,120.34,0.026
18.16,120.56,0.026
18.18,120.78,0.026
18.20,121.00,0.026
18.22,121.21,0.026
18.24,121.43,0.026
18.27,121.65,0.026
18.29,121.86,0.026
18.31,122.08,0.026
18.33,122.29,0.026
18.35,122.51,0.026
18.37,122.73,0.026
18.39,122.95,0.026
18.42,123.16,0.026
18.44,123.38,0.026
18.46,123.60,0.026
18.48,123.81,0.026
18.50,124.03,0.026
18.53,124.25,0.026
18.55,124.46,0.025
18.57,124.68,0.025
18.59,124.90,0.025
18.61,125.12,0.025
18.63,125.33,0.025
18.66,125.55,0.025
18.68,125.76,0.025
18.70,125.98,0.025
18.72,126.20,0.025
18.74,126.41,0.025
18.76,126.63,0.025
18.78,126.85,0.025
18.81,127.07,0.025
18.83,127.28,0.025
18.85,127.50,0.025
18.87,127.72,0.025
18.89,127.94,0.025
18.92,128.15,0.025
18.94,128.37,0.025
18.96,128.59,0.025
18.98,128.80,0.025
19.00,129.02,0.025
19.02,129.24,0.025
19.04,129.46,0.025
19.07,129.67,0.025
19.09,129.89,0.025
19.11,130.11,0.025
19.13,130.32,0.025
19.15,130.54,0.025
19.18,130.76,0.025
19.20,130.97,0.025
19.22,131.19,0.025
19.24,131.41,0.025
19.26,131.62,0.025
19.28,131.84,0.025
19.31,132.06,0.025
19.33,132.27,0.025
19.35,132.49,0.025
19.37,132.71,0.025
19.39,132.92,0.025
19.41,133.14,0.025
19.43,133.36,0.025
19.46,133.58,0.025
19.48,133.79,0.025
19.50,134.01,0.025
19.52,134.23,0.025
19.54,134.44,0.025
19.57,134.66,0.025
19.59,134.88,0.025
19.61,135.09,0.025
19.63,135.31,0.024
19.65,135.53,0.024
19.67,135.74,0.024
19.69,135.96,0.024
19.72,136.18,0.024
19.74,136.39,0.024
19.76,136.61,0.024
19.78,136.83,0.024
19.80,137.04,0.024
19.83,137.26,0.024
19.85,137.48,0.024
19.87,137.70,0.024
19.89,137.91,0.024
19.91,138.13,0.024
19.93,138.35,0.024
19.96,138.56,0.024
19.98,138.78,0.024
20.00,139.00,0.024
20.02,139.21,0.024
20.04,139.43,0.024
20.06,139.65,0.024
20.08,139.86,0.024
20.11,140.08,0.024
20.13,140.30,0.024
20.15,140.51,0.024
20.17,140.73,0.024
20.19,140.95,0.024
20.22,141.16,0.024
20.24,141.38,0.024
20.26,141.60,0.024
20.28,141.81,0.024
20.30,142.03,0.024
20.32,142.25,0.024
20.34,142.47,0.024
20.37,142.68,0.024
20.39,142.90,0.024
20.41,143.11,0.024
20.43,143.33,0.024
20.45,143.55,0.024
20.48,143.76,0.024
20.50,143.98,0.024
20.52,144.20,0.024
20.54,144.42,0.024
20.56,144.63,0.024
20.58,144.85,0.024
20.61,145.07,0.024
20.63,145.28,0.024
20.65,145.50,0.024
20.67,145.72,0.024
20.69,145.93,0.024
20.71,146.15,0.024
20.73,146.37,0.024
20.76,146.58,0.024
20.78,146.80,0.024
20.80,147.02,0.024
20.82,147.24,0.024
20.84,147.45,0.024
20.87,147.67,0.024
20.89,147.89,0.024
20.91,148.10,0.024
20.93,148.32,0.024
20.95,148.54,0.024
20.97,148.75,0.024
20.99,148.97,0.024
21.02,149.19,0.024
21.04,149.40,0.024
21.06,149.62,0.024
21.08,149.84,0.024
21.10,150.05,0.024
21.13,150.27,0.024
21.15,150.49,0.024
21.17,150.70,0.024
21.19,150.92,0.024
21.21,151.14,0.024
21.23,151.36,0.024
21.26,151.57,0.024
21.28,151.79,0.024
21.30,152.01,0.024
21.32,152.22,0.024
21.34,152.44,0.024
21.36,152.66,0.024
21.38,152.87,0.024
21.41,153.09,0.024
21.43,153.31,0.024
21.45,153.52,0.024
21.47,153.74,0.024
21.49,153.96,0.024
21.52,154.18,0.024
21.54,154.39,0.024
21.56,154.61,0.024
21.58,154.83,0.023
21.60,155.04,0.023
21.62,155.26,0.023
21.64,155.48,0.023
21.67,155.69,0.023
21.69,155.91,0.023
21.71,156.13,0.023
21.73,156.34,0.023
21.75,156.56,0.023
21.78,156.78,0.023
21.80,156.99,0.023
21.82,157.21,0.023
21.84,157.43,0.023
21.86,157.64,0.023
21.88,157.86,0.023
21.91,158.08,0.023
21.93,158.30,0.023
21.95,158.51,0.023
21.97,158.73,0.023
21.99,158.95,0.023
22.01,159.16,0.023
22.03,159.38,0.023
22.06,159.60,0.023
22.08,159.81,0.023
22.10,160.03,0.023
22.12,160.25,0.023
22.14,160.46,0.023
22.17,160.68,0.023
22.19,160.90,0.023
22.21,161.11,0.023
22.23,161.33,0.023
22.25,161.55,0.023
22.27,161.77,0.023
22.29,161.98,0.023
22.32,162.20,0.023
22.34,162.41,0.023
22.36,162.63,0.023
22.38,162.85,0.023
22.40,163.06,0.023
22.43,163.28,0.023
22.45,163.50,0.023
22.47,163.72,0.023
22.49,163.93,0.023
22.51,164.15,0.023
22.53,164.37,0.023
22.56,164.58,0.023
22.58,164.80,0.023
22.60,165.02,0.023
22.62,165.23,0.023
22.64,165.45,0.023
22.66,165.67,0.023
22.68,165.89,0.023
22.71,166.10,0.023
22.73,166.32,0.023
22.75,166.54,0.023
22.77,166.75,0.023
22.79,166.97,0.023
22.82,167.19,0.023
22.84,167.40,0.023
22.86,167.62,0.023
22.88,167.84,0.023
22.90,168.05,0.023
22.92,168.27,0.023
22.94,168.49,0.023
22.97,168.70,0.023
22.99,168.92,0.023
23.01,169.14,0.023
23.03,169.35,0.023
23.05,169.57,0.023
23.08,169.79,0.023
23.10,170.00,0.023
23.12,170.22,0.023
23.14,170.44,0.023
23.16,170.65,0.023
23.18,170.87,0.023
23.21,171.09,0.023
23.23,171.30,0.023
23.25,171.52,0.023
23.27,171.74,0.023
23.29,171.96,0.023
23.31,172.17,0.023
23.33,172.39,0.023
23.36,172.61,0.023
23.38,172.82,0.023
23.40,173.04,0.023
23.42,173.26,0.023
23.44,173.47,0.023
23.47,173.69,0.023
23.49,173.91,0.023
23.51,174.12,0.023
23.53,174.34,0.023
23.55,174.56,0.023
23.57,174.77,0.023
23.59,174.99,0.023
23.62,175.21,0.023
23.64,175.42,0.023
23.66,175.64,0.023
23.68,175.86,0.023
23.70,176.07,0.023
23.73,176.29,0.023
23.75,176.51,0.023
23.77,176.73,0.023
23.79,176.94,0.023
23.81,177.16,0.023
23.83,177.38,0.023
23.86,177.59,0.023
23.88,177.81,0.023
23.90,178.03,0.023
23.92,178.24,0.023
23.94,178.46,0.023
23.96,178.68,0.023
23.98,178.90,0.023
24.01,179.11,0.023
24.03,179.33,0.023
24.05,179.55,0.023
24.07,179.76,0.023
24.09,179.98,0.023
24.12,180.20,0.023
24.14,180.41,0.023
24.16,180.63,0.023
24.18,180.85,0.023
24.20,181.06,0.023
24.22,181.28,0.023
24.24,181.50,0.023
24.27,181.71,0.023
24.29,181.93,0.023
24.31,182.15,0.023
24.33,182.36,0.023
24.35,182.58,0.023
24.38,182.80,0.023
24.40,183.02,0.023
24.42,183.23,0.023
24.44,183.45,0.023
24.46,183.67,0.023
24.48,183.88,0.023
24.51,184.10,0.023
24.53,184.31,0.023
24.55,184.53,0.023
24.57,184.75,0.023
24.59,184.96,0.023
24.61,185.18,0.023
24.63,185.40,0.023
24.66,185.61,0.023
24.68,185.83,0.023
24.70,186.05,0.023
24.72,186.27,0.023
24.74,186.48,0.023
24.77,186.70,0.023
24.79,186.92,0.023
24.81,187.13,0.023
24.83,187.35,0.023
24.85,187.57,0.023
24.87,187.78,0.023
24.89,188.00,0.023
24.92,188.22,0.023
24.94,188.43,0.023
24.96,188.65,0.023
24.98,188.87,0.023
25.00,189.08,0.023
25.03,189.30,0.023
25.05,189.52,0.023
25.07,189.73,0.023
25.09,189.95,0.023
25.11,190.17,0.023
25.13,190.39,0.023
25.16,190.60,0.023
25.18,190.82,0.023
25.20,191.04,0.023
25.22,191.25,0.023
25.24,191.47,0.023
25.26,191.69,0.023
25.28,191.90,0.023
25.31,192.12,0.023
25.33,192.34,0.023
25.35,192.56,0.023
25.37,192.77,0.023
25.39,192.99,0.023
25.42,193.21,0.023
25.44,193.42,0.023
25.46,193.64,0.023
25.48,193.86,0.023
25.50,194.07,0.023
25.52,194.29,0.023
25.54,194.51,0.023
25.57,194.72,0.023
25.59,194.94,0.023
25.61,195.16,0.023
25.63,195.37,0.023
25.65,195.59,0.023
25.68,195.81,0.023
25.70,196.02,0.023
25.72,196.24,0.023
25.74,196.46,0.023
25.76,196.67,0.023
25.78,196.89,0.023
25.81,197.11,0.023
25.83,197.32,0.023
25.85,197.54,0.023
25.87,197.76,0.023
25.89,197.98,0.023
25.91,198.19,0.023
25.93,198.41,0.023
25.96,198.62,0.023
25.98,198.84,0.023
26.00,199.06,0.023
26.02,199.28,0.023
26.04,199.49,0.023
26.07,199.71,0.023
26.09,199.93,0.023
26.11,200.14,0.023
26.13,200.36,0.023
26.15,200.58,0.023
26.17,200.79,0.023
26.19,201.01,0.023
26.22,201.23,0.023
26.24,201.44,0.023
26.26,201.66,0.023
26.28,201.88,0.023
26.30,202.09,0.023
26.33,202.31,0.023
26.35,202.53,0.023
26.37,202.74,0.023
26.39,202.96,0.023
26.41,203.18,0.023
26.43,203.39,0.023
26.46,203.61,0.023
26.48,203.83,0.023
26.50,204.05,0.023
26.52,204.26,0.023
26.54,204.48,0.023
26.56,204.70,0.023
26.58,204.91,0.023
26.61,205.13,0.023
26.63,205.35,0.023
26.65,205.56,0.023
26.67,205.78,0.023
26.69,206.00,0.023
26.72,206.21,0.023
26.74,206.43,0.023
26.76,206.65,0.023
26.78,206.86,0.023
26.80,207.08,0.023
26.82,207.30,0.023
26.84,207.51,0.023
26.87,207.73,0.023
26.89,207.95,0.023
26.91,208.17,0.023
26.93,208.38,0.023
26.95,208.60,0.023
26.98,208.82,0.023
27.00,209.03,0.023
27.02,209.25,0.023
27.04,209.47,0.023
27.06,209.68,0.023
27.08,209.90,0.023
27.11,210.12,0.023
27.13,210.33,0.023
27.15,210.55,0.023
27.17,210.77,0.023
27.19,210.98,0.023
27.21,211.20,0.023
27.23,211.42,0.023
27.26,211.63,0.023
27.28,211.85,0.023
27.30,212.07,0.023
27.32,212.28,0.023
27.34,212.50,0.023
27.37,212.72,0.023
27.39,212.93,0.023
27.41,213.15,0.023
27.43,213.37,0.023
27.45,213.59,0.023
27.47,213.80,0.023
27.49,214.02,0.023
27.52,214.24,0.023
27.54,214.45,0.023
27.56,214.67,0.023
27.58,214.89,0.023
27.60,215.10,0.023
27.63,215.32,0.023
27.65,215.54,0.023
27.67,215.75,0.023
27.69,215.97,0.023
27.71,216.19,0.023
27.73,216.40,0.023
27.76,216.62,0.023
27.78,216.84,0.023
27.80,217.05,0.023
27.82,217.27,0.023
27.84,217.49,0.023
27.86,217.70,0.023
27.88,217.92,0.023
27.91,218.14,0.023
27.93,218.35,0.023
27.95,218.57,0.023
27.97,218.79,0.023
27.99,219.00,0.023
28.02,219.22,0.023
28.04,219.44,0.023
28.06,219.66,0.023
28.08,219.87,0.023
28.10,220.09,0.023
28.12,220.31,0.023
28.14,220.52,0.023
28.17,220.74,0.023
28.19,220.96,0.023
28.21,221.17,0.023
28.23,221.39,0.023
28.25,221.61,0.023
28.28,221.82,0.023
28.30,222.04,0.023
28.32,222.26,0.023
28.34,222.47,0.023
28.36,222.69,0.023
28.38,222.91,0.023
28.41,223.12,0.023
28.43,223.34,0.023
28.45,223.56,0.023
28.47,223.77,0.023
28.49,223.99,0.023
28.51,224.21,0.023
28.53,224.43,0.023
28.56,224.64,0.023
28.58,224.86,0.023
28.60,225.07,0.023
28.62,225.29,0.023
28.64,225.51,0.023
28.67,225.73,0.023
28.69,225.94,0.023
28.71,226.16,0.023
28.73,226.38,0.023
28.75,226.59,0.023
28.77,226.81,0.023
28.79,227.03,0.023
28.82,227.24,0.023
28.84,227.46,0.023
28.86,227.68,0.023
28.88,227.89,0.023
28.90,228.11,0.023
28.93,228.33,0.023
28.95,228.54,0.023
28.97,228.76,0.023
28.99,228.98,0.023
29.01,229.19,0.023
29.03,229.41,0.023
29.06,229.63,0.023
29.08,229.84,0.023
29.10,230.06,0.023
29.12,230.28,0.023
29.14,230.50,0.023
29.16,230.71,0.023
29.18,230.93,0.023
29.21,231.14,0.023
29.23,231.36,0.023
29.25,231.58,0.023
29.27,231.80,0.023
29.29,232.01,0.023
29.32,232.23,0.023
29.34,232.45,0.023
29.36,232.66,0.023
29.38,232.88,0.023
29.40,233.10,0.023
29.42,233.32,0.023
29.44,233.53,0.023
29.47,233.75,0.023
29.49,233.96,0.023
29.51,234.18,0.023
29.53,234.40,0.023
29.55,234.61,0.023
29.58,234.83,0.023
29.60,235.05,0.023
29.62,235.26,0.023
29.64,235.48,0.023
29.66,235.70,0.023
29.68,235.92,0.023
29.71,236.13,0.023
29.73,236.35,0.023
29.75,236.57,0.023
29.77,236.78,0.023
29.79,237.00,0.023
29.81,237.22,0.023
29.83,237.43,0.023
29.86,237.65,0.023
29.88,237.87,0.023
29.90,238.08,0.023
29.92,238.30,0.023
29.94,238.52,0.023
29.97,238.73,0.023
29.99,238.95,0.023
30.01,239.17,0.023
30.03,239.38,0.023
30.05,239.60,0.023
30.07,239.82,0.023
30.09,240.04,0.023
30.12,240.25,0.023
30.14,240.47,0.023
30.16,240.68,0.023
30.18,240.90,0.023
30.20,241.12,0.023
30.23,241.34,0.023
30.25,241.55,0.023
30.27,241.77,0.023
30.29,241.99,0.023
30.31,242.20,0.023
30.33,242.42,0.023
30.36,242.64,0.023
30.38,242.85,0.023
30.40,243.07,0.023
30.42,243.28,0.023
30.44,243.50,0.023
30.46,243.72,0.023
30.48,243.94,0.023
30.51,244.15,0.023
30.53,244.37,0.023
30.55,244.59,0.023
30.57,244.80,0.023
30.59,245.02,0.023
30.62,245.24,0.023
30.64,245.45,0.023
30.66,245.67,0.023
30.68,245.89,0.023
30.70,246.10,0.023
30.72,246.32,0.023
30.74,246.54,0.023
30.77,246.75,0.023
30.79,246.97,0.023
30.81,247.19,0.023
30.83,247.40,0.023
30.85,247.62,0.023
30.88,247.84,0.023
30.90,248.05,0.023
30.92,248.27,0.023
30.94,248.49,
30.96,248.71,
30.98,248.92,
30.99,,

[step]
Ramp 10.00 °C/min to -60.00 °C
Time,Temperature,Heat Flow (Normalized)
min,°C,W/g
32.99,250.17,-0.005
33.02,250.17,-0.005
33.04,250.16,-0.005
33.06,250.14,-0.003
33.08,250.08,-0.001
33.10,250.00,-0.001
33.12,249.87,-0.005
33.14,249.72,-0.010
33.17,249.55,-0.016
33.19,249.35,-0.021
33.21,249.16,-0.024
33.23,248.95,-0.027
33.25,248.74,-0.029
33.28,248.53,-0.030
33.30,248.32,-0.031
33.32,248.10,-0.031
33.34,247.89,-0.031
33.36,247.68,-0.032
33.38,247.46,-0.032
33.41,247.25,-0.032
33.43,247.03,-0.032
33.45,246.82,-0.032
33.47,246.60,-0.032
33.49,246.39,-0.032
33.51,246.17,-0.032
33.53,245.96,-0.032
33.56,245.74,-0.032
33.58,245.53,-0.032
33.60,245.31,-0.032
33.62,245.10,-0.032
33.64,244.88,-0.032
33.67,244.67,-0.032
33.69,244.45,-0.032
33.71,244.24,-0.032
33.73,244.02,-0.032
33.75,243.81,-0.033
33.77,243.59,-0.033
33.79,243.38,-0.033
33.82,243.16,-0.033
33.84,242.95,-0.033
33.86,242.73,-0.033
33.88,242.51,-0.033
33.90,242.30,-0.033
33.93,242.08,-0.033
33.95,241.87,-0.033
33.97,241.65,-0.033
33.99,241.44,-0.033
34.01,241.22,-0.033
34.03,241.00,-0.033
34.06,240.79,-0.033
34.08,240.57,-0.033
34.10,240.36,-0.033
34.12,240.14,-0.033
34.14,239.92,-0.033
34.16,239.71,-0.033
34.19,239.49,-0.033
34.21,239.28,-0.033
34.23,239.06,-0.033
34.25,238.84,-0.033
34.27,238.63,-0.033
34.29,238.41,-0.033
34.31,238.20,-0.033
34.34,237.98,-0.033
34.36,237.76,-0.033
34.38,237.55,-0.033
34.40,237.33,-0.033
34.42,237.12,-0.033
34.44,236.90,-0.033
34.47,236.69,-0.033
34.49,236.47,-0.033
34.51,236.25,-0.033
34.53,236.04,-0.033
34.55,235.82,-0.033
34.58,235.60,-0.033
34.60,235.39,-0.033
34.62,235.17,-0.033
34.64,234.95,-0.033
34.66,234.74,-0.033
34.68,234.52,-0.033
34.71,234.30,-0.033
34.73,234.09,-0.033
34.75,233.87,-0.033
34.77,233.65,-0.033
34.79,233.44,-0.033
34.81,233.22,-0.033
34.84,233.00,-0.033
34.86,232.79,-0.033
34.88,232.57,-0.033
34.90,232.35,-0.033
34.92,232.14,-0.033
34.94,231.92,-0.033
34.96,231.71,-0.033
34.99,231.49,-0.033
35.01,231.27,-0.033
35.03,231.06,-0.033
35.05,230.84,-0.033
35.07,230.62,-0.033
35.09,230.41,-0.033
35.12,230.19,-0.033
35.14,229.97,-0.033
35.16,229.76,-0.033
35.18,229.54,-0.033
35.20,229.32,-0.033
35.23,229.11,-0.033
35.25,228.89,-0.033
35.27,228.68,-0.033
35.29,228.46,-0.033
35.31,228.24,-0.033
35.33,228.03,-0.033
35.36,227.81,-0.033
35.38,227.59,-0.033
35.40,227.38,-0.033
35.42,227.16,-0.033
35.44,226.94,-0.033
35.46,226.73,-0.033
35.49,226.51,-0.033
35.51,226.29,-0.033
35.53,226.08,-0.033
35.55,225.86,-0.033
35.57,225.64,-0.033
35.59,225.43,-0.033
35.61,225.21,-0.033
35.64,224.99,-0.033
35.66,224.78,-0.033
35.68,224.56,-0.033
35.70,224.35,-0.032
35.72,224.13,-0.032
35.74,223.91,-0.032
35.77,223.70,-0.032
35.79,223.48,-0.032
35.81,223.26,-0.032
35.83,223.05,-0.032
35.85,222.83,-0.032
35.88,222.61,-0.032
35.90,222.40,-0.032
35.92,222.18,-0.032
35.94,221.96,-0.032
35.96,221.74,-0.032
35.98,221.53,-0.032
36.01,221.31,-0.032
36.03,221.10,-0.032
36.05,220.88,-0.032
36.07,220.66,-0.032
36.09,220.45,-0.032
36.11,220.23,-0.032
36.14,220.01,-0.032
36.16,219.80,-0.032
36.18,219.58,-0.032
36.20,219.36,-0.032
36.22,219.15,-0.032
36.24,218.93,-0.032
36.26,218.71,-0.032
36.29,218.50,-0.032
36.31,218.28,-0.032
36.33,218.06,-0.032
36.35,217.85,-0.032
36.37,217.63,-0.032
36.39,217.42,-0.032
36.42,217.20,-0.032
36.44,216.98,-0.032
36.46,216.76,-0.032
36.48,216.55,-0.032
36.50,216.33,-0.032
36.53,216.11,-0.032
36.55,215.90,-0.032
36.57,215.68,-0.032
36.59,215.47,-0.032
36.61,215.25,-0.032
36.63,215.03,-0.032
36.66,214.82,-0.032
36.68,214.60,-0.032
36.70,214.38,-0.032
36.72,214.17,-0.032
36.74,213.95,-0.032
36.76,213.73,-0.032
36.79,213.52,-0.032
36.81,213.30,-0.032
36.83,213.08,-0.032
36.85,212.87,-0.032
36.87,212.65,-0.032
36.89,212.43,-0.032
36.91,212.22,-0.032
36.94,212.00,-0.032
36.96,211.78,-0.032
36.98,211.57,-0.032
37.00,211.35,-0.032
37.02,211.13,-0.032
37.04,210.92,-0.032
37.07,210.70,-0.032
37.09,210.48,-0.032
37.11,210.27,-0.032
37.13,210.05,-0.032
37.15,209.83,-0.032
37.18,209.62,-0.032
37.20,209.40,-0.032
37.22,209.18,-0.032
37.24,208.97,-0.032
37.26,208.75,-0.032
37.28,208.53,-0.032
37.31,208.32,-0.032
37.33,208.10,-0.032
37.35,207.88,-0.032
37.37,207.67,-0.032
37.39,207.45,-0.032
37.41,207.23,-0.032
37.44,207.02,-0.032
37.46,206.80,-0.032
37.48,206.58,-0.032
37.50,206.37,-0.032
37.52,206.15,-0.032
37.54,205.93,-0.032
37.56,205.72,-0.032
37.59,205.50,-0.032
37.61,205.29,-0.032
37.63,205.07,-0.032
37.65,204.85,-0.032
37.67,204.63,-0.032
37.69,204.42,-0.032
37.72,204.20,-0.032
37.74,203.99,-0.032
37.76,203.77,-0.032
37.78,203.55,-0.032
37.80,203.34,-0.032
37.83,203.12,-0.032
37.85,202.90,-0.032
37.87,202.69,-0.032
37.89,202.47,-0.032
37.91,202.25,-0.032
37.93,202.04,-0.032
37.96,201.82,-0.032
37.98,201.60,-0.032
38.00,201.39,-0.032
38.02,201.17,-0.032
38.04,200.95,-0.032
38.06,200.74,-0.032
38.09,200.52,-0.032
38.11,200.30,-0.032
38.13,200.09,-0.032
38.15,199.87,-0.032
38.17,199.65,-0.032
38.19,199.44,-0.032
38.21,199.22,-0.032
38.24,199.00,-0.032
38.26,198.79,-0.032
38.28,198.57,-0.032
38.30,198.35,-0.032
38.32,198.14,-0.032
38.34,197.92,-0.032
38.37,197.70,-0.032
38.39,197.49,-0.032
38.41,197.27,-0.032
38.43,197.05,-0.032
38.45,196.84,-0.032
38.48,196.62,-0.032
38.50,196.40,-0.032
38.52,196.19,-0.032
38.54,195.97,-0.032
38.56,195.75,-0.032
38.58,195.54,-0.032
38.61,195.32,-0.032
38.63,195.10,-0.032
38.65,194.89,-0.032
38.67,194.67,-0.032
38.69,194.46,-0.032
38.71,194.24,-0.032
38.74,194.02,-0.032
38.76,193.81,-0.032
38.78,193.59,-0.032
38.80,193.37,-0.032
38.82,193.16,-0.032
38.84,192.94,-0.032
38.86,192.72,-0.032
38.89,192.51,-0.032
38.91,192.29,-0.032
38.93,192.07,-0.032
38.95,191.86,-0.032
38.97,191.64,-0.032
38.99,191.42,-0.032
39.02,191.21,-0.032
39.04,190.99,-0.032
39.06,190.77,-0.032
39.08,190.56,-0.032
39.10,190.34,-0.032
39.13,190.12,-0.032
39.15,189.91,-0.032
39.17,189.69,-0.032
39.19,189.47,-0.032
39.21,189.26,-0.032
39.23,189.04,-0.032
39.26,188.82,-0.032
39.28,188.61,-0.032
39.30,188.39,-0.032
39.32,188.17,-0.032
39.34,187.96,-0.032
39.36,187.74,-0.032
39.39,187.52,-0.032
39.41,187.31,-0.032
39.43,187.09,-0.032
39.45,186.88,-0.032
39.47,186.66,-0.032
39.49,186.44,-0.032
39.51,186.23,-0.032
39.54,186.01,-0.032
39.56,185.79,-0.032
39.58,185.58,-0.032
39.60,185.36,-0.032
39.62,185.14,-0.032
39.64,184.93,-0.032
39.67,184.71,-0.032
39.69,184.49,-0.032
39.71,184.28,-0.032
39.73,184.06,-0.032
39.75,183.84,-0.032
39.78,183.63,-0.032
39.80,183.41,-0.032
39.82,183.19,-0.032
39.84,182.98,-0.032
39.86,182.76,-0.032
39.88,182.54,-0.032
39.91,182.33,-0.032
39.93,182.11,-0.032
39.95,181.89,-0.032
39.97,181.68,-0.032
39.99,181.46,-0.032
40.01,181.24,-0.032
40.04,181.03,-0.032
40.06,180.81,-0.032
40.08,180.59,-0.032
40.10,180.38,-0.032
40.12,180.16,-0.032
40.14,179.94,-0.032
40.16,179.73,-0.032
40.19,179.51,-0.032
40.21,179.29,-0.032
40.23,179.08,-0.032
40.25,178.86,-0.032
40.27,178.65,-0.032
40.29,178.43,-0.032
40.32,178.21,-0.032
40.34,178.00,-0.032
40.36,177.78,-0.032
40.38,177.56,-0.032
40.40,177.35,-0.032
40.43,177.13,-0.032
40.45,176.91,-0.032
40.47,176.70,-0.032
40.49,176.48,-0.032
40.51,176.26,-0.032
40.53,176.05,-0.032
40.56,175.83,-0.032
40.58,175.61,-0.032
40.60,175.40,-0.032
40.62,175.18,-0.032
40.64,174.96,-0.032
40.66,174.75,-0.032
40.69,174.53,-0.032
40.71,174.31,-0.032
40.73,174.10,-0.032
40.75,173.88,-0.032
40.77,173.66,-0.032
40.79,173.45,-0.032
40.81,173.23,-0.032
40.84,173.01,-0.032
40.86,172.80,-0.032
40.88,172.58,-0.032
40.90,172.36,-0.032
40.92,172.15,-0.032
40.94,171.93,-0.032
40.97,171.71,-0.032
40.99,171.50,-0.031
41.01,171.28,-0.031
41.03,171.06,-0.031
41.05,170.84,-0.031
41.08,170.63,-0.031
41.10,170.41,-0.031
41.12,170.20,-0.031
41.14,169.98,-0.031
41.16,169.76,-0.031
[...]
140.99,28.69,0.018
141.01,28.91,0.018
141.03,29.12,0.018
141.05,29.34,0.018
141.07,29.56,0.018
141.10,29.77,0.018
141.12,29.99,0.018
141.14,30.21,0.018
141.16,30.42,0.018
141.18,30.64,0.018
141.20,30.86,0.018
141.23,31.07,0.018
141.25,31.29,0.018
141.27,31.51,0.018
141.29,31.72,0.018
141.31,31.94,0.018
141.33,32.16,0.018
141.35,32.38,0.018
141.38,32.59,0.018
141.40,32.81,0.018
141.42,33.03,0.018
141.44,33.24,0.018
141.46,33.46,0.018
141.48,33.68,0.018
141.51,33.89,0.018
141.53,34.11,0.018
141.55,34.33,0.018
141.57,34.54,0.018
141.59,34.76,0.018
141.62,34.98,0.018
141.64,35.20,0.018
141.66,35.41,0.018
141.68,35.63,0.018
141.70,35.85,0.018
141.72,36.06,0.018
141.75,36.28,0.018
141.77,36.50,0.018
141.79,36.71,0.018
141.81,36.93,0.018
141.83,37.15,0.018
141.85,37.36,0.018
141.88,37.58,0.018
141.90,37.80,0.018
141.92,38.01,0.018
141.94,38.23,0.018
141.96,38.45,0.018
141.98,38.66,0.018
142.00,38.88,0.018
142.03,39.10,0.018
142.05,39.32,0.018
142.07,39.53,0.018
142.09,39.75,0.018
142.11,39.97,0.018
142.13,40.18,0.018
142.16,40.40,0.018
142.18,40.62,0.018
142.20,40.83,0.018
142.22,41.05,0.018
142.24,41.27,0.018
142.27,41.48,0.018
142.29,41.70,0.018
142.31,41.92,0.018
142.33,42.14,0.018
142.35,42.35,0.018
142.37,42.57,0.018
142.40,42.79,0.018
142.42,43.00,0.018
142.44,43.22,0.018
142.46,43.44,0.018
142.48,43.65,0.018
142.50,43.87,0.018
142.53,44.09,0.018
142.55,44.30,0.018
142.57,44.52,0.018
142.59,44.74,0.018
142.61,44.96,0.018
142.63,45.17,0.018
142.65,45.39,0.018
142.68,45.61,0.018
142.70,45.82,0.018
142.72,46.04,0.018
142.74,46.26,0.018
142.76,46.47,0.018
142.78,46.69,0.018
142.81,46.91,0.018
142.83,47.12,0.018
142.85,47.34,0.018
142.87,47.56,0.018
142.89,47.78,0.018
142.92,47.99,0.018
142.94,48.21,0.018
142.96,48.42,0.018
142.98,48.64,0.018
143.00,48.86,0.018
143.02,49.08,0.018
143.05,49.29,0.018
143.07,49.51,0.018
143.09,49.73,0.018
143.11,49.94,0.018
143.13,50.16,0.018
143.15,50.38,0.018
143.18,50.59,0.018
143.20,50.81,0.018
143.22,51.03,0.018
143.24,51.24,0.018
143.26,51.46,0.018
143.28,51.68,0.018
143.30,51.90,0.018
143.33,52.11,0.018
143.35,52.33,0.018
143.37,52.55,0.018
143.39,52.76,0.018
143.41,52.98,0.018
143.43,53.20,0.018
143.46,53.41,0.018
143.48,53.63,0.018
143.50,53.85,0.018
143.52,54.06,0.018
143.54,54.28,0.018
143.57,54.50,0.018
143.59,54.72,0.018
143.61,54.93,0.018
143.63,55.15,0.018
143.65,55.37,0.018
143.67,55.58,0.018
143.70,55.80,0.018
143.72,56.02,0.018
143.74,56.23,0.018
143.76,56.45,0.018
143.78,56.67,0.018
143.80,56.88,0.018
143.83,57.10,0.018
143.85,57.32,0.018
143.87,57.54,0.018
143.89,57.75,0.018
143.91,57.97,0.018
143.93,58.19,0.018
143.95,58.40,0.018
143.98,58.62,0.018
144.00,58.84,0.018
144.02,59.06,0.018
144.04,59.27,0.018
144.06,59.49,0.018
144.08,59.71,0.018
144.11,59.92,0.018
144.13,60.14,0.018
144.15,60.36,0.018
144.17,60.57,0.018
144.19,60.79,0.018
144.22,61.01,0.018
144.24,61.22,0.018
144.26,61.44,0.018
144.28,61.66,0.018
144.30,61.87,0.018
144.32,62.09,0.018
144.35,62.31,0.018
144.37,62.52,0.018
144.39,62.74,0.018
144.41,62.96,0.018
144.43,63.17,0.018
144.45,63.39,0.018
144.48,63.61,0.018
144.50,63.82,0.018
144.52,64.04,0.018
144.54,64.26,0.018
144.56,64.48,0.018
144.58,64.69,0.018
144.60,64.91,0.018
144.63,65.13,0.018
144.65,65.34,0.018
144.67,65.56,0.018
144.69,65.78,0.018
144.71,65.99,0.018
144.73,66.21,0.018
144.76,66.43,0.018
144.78,66.64,0.018
144.80,66.86,0.018
144.82,67.08,0.018
144.84,67.30,0.018
144.87,67.51,0.018
144.89,67.73,0.018
144.91,67.94,0.018
144.93,68.16,0.018
144.95,68.38,0.018
144.97,68.59,0.018
145.00,68.81,0.018
145.02,69.03,0.018
145.04,69.25,0.018
145.06,69.46,0.018
145.08,69.68,0.018
145.10,69.90,0.018
145.13,70.11,0.018
145.15,70.33,0.018
145.17,70.55,0.019
145.19,70.76,0.019
145.21,70.98,0.019
145.23,71.20,0.019
145.25,71.42,0.019
145.28,71.63,0.019
145.30,71.85,0.019
145.32,72.07,0.019
145.34,72.28,0.019
145.36,72.50,0.019
145.38,72.72,0.019
145.41,72.93,0.019
145.43,73.15,0.019
145.45,73.37,0.019
145.47,73.58,0.019
145.49,73.80,0.019
145.52,74.02,0.019
145.54,74.24,0.019
145.56,74.45,0.019
145.58,74.67,0.019
145.60,74.88,0.019
145.62,75.10,0.019
145.65,75.32,0.019
145.67,75.54,0.019
145.69,75.75,0.019
145.71,75.97,0.019
145.73,76.19,0.019
145.75,76.40,0.019
145.78,76.62,0.019
145.80,76.84,0.019
145.82,77.05,0.019
145.84,77.27,0.019
145.86,77.49,0.019
145.88,77.70,0.019
145.90,77.92,0.019
145.93,78.14,0.019
145.95,78.35,0.019
145.97,78.57,0.019
145.99,78.79,0.019
146.01,79.01,0.019
146.03,79.22,0.019
146.06,79.44,0.019
146.08,79.66,0.019
146.10,79.87,0.019
146.12,80.09,0.019
146.14,80.31,0.019
146.17,80.52,0.019
146.19,80.74,0.019
146.21,80.96,0.019
146.23,81.17,0.019
146.25,81.39,0.019
146.27,81.61,0.019
146.30,81.82,0.019
146.32,82.04,0.019
146.34,82.26,0.019
146.36,82.48,0.019
146.38,82.69,0.019
146.40,82.91,0.019
146.43,83.13,0.019
146.45,83.34,0.019
146.47,83.56,0.019
146.49,83.78,0.019
146.51,83.99,0.019
146.53,84.21,0.019
146.55,84.43,0.019
146.58,84.64,0.019
146.60,84.86,0.019
146.62,85.08,0.019
146.64,85.29,0.019
146.66,85.51,0.019
146.68,85.73,0.019
146.71,85.95,0.019
146.73,86.16,0.019
146.75,86.38,0.019
146.77,86.60,0.019
146.79,86.81,0.019
146.82,87.03,0.019
146.84,87.25,0.019
146.86,87.46,0.019
146.88,87.68,0.019
146.90,87.90,0.019
146.92,88.11,0.019
146.95,88.33,0.019
146.97,88.55,0.019
146.99,88.76,0.019
147.01,88.98,0.019
147.03,89.20,0.019
147.05,89.41,0.019
147.08,89.63,0.019
147.10,89.85,0.019
147.12,90.06,0.019
147.14,90.28,0.019
147.16,90.50,0.019
147.18,90.72,0.019
147.20,90.93,0.019
147.23,91.15,0.019
147.25,91.36,0.019
147.27,91.58,0.019
147.29,91.80,0.019
147.31,92.01,0.019
147.33,92.23,0.019
147.36,92.45,0.019
147.38,92.67,0.019
147.40,92.88,0.019
147.42,93.10,0.019
147.44,93.32,0.019
147.47,93.54,0.019
147.49,93.75,0.019
147.51,93.97,0.019
147.53,94.19,0.019
147.55,94.40,0.019
147.57,94.62,0.019
147.60,94.84,0.019
147.62,95.05,0.019
147.64,95.27,0.019
147.66,95.49,0.019
147.68,95.70,0.019
147.70,95.92,0.019
147.73,96.14,0.019
147.75,96.35,0.019
147.77,96.57,0.019
147.79,96.79,0.019
147.81,97.00,0.019
147.83,97.22,0.019
147.85,97.44,0.019
147.88,97.65,0.019
147.90,97.87,0.019
147.92,98.09,0.019
147.94,98.31,0.019
147.96,98.52,0.019
147.98,98.74,0.019
148.01,98.96,0.019
148.03,99.17,0.019
148.05,99.39,0.019
148.07,99.61,0.019
148.09,99.83,0.019
148.12,100.04,0.019
148.14,100.26,0.019
148.16,100.48,0.019
148.18,100.69,0.019
148.20,100.91,0.019
148.22,101.12,0.019
148.25,101.34,0.019
148.27,101.56,0.019
148.29,101.78,0.019
148.31,101.99,0.019
148.33,102.21,0.019
148.35,102.43,0.019
148.38,102.64,0.019
148.40,102.86,0.019
148.42,103.08,0.019
148.44,103.29,0.019
148.46,103.51,0.019
148.48,103.73,0.019
148.50,103.94,0.019
148.53,104.16,0.019
148.55,104.38,0.019
148.57,104.59,0.019
148.59,104.81,0.019
148.61,105.03,0.019
148.63,105.24,0.019
148.66,105.46,0.019
148.68,105.68,0.019
148.70,105.89,0.019
148.72,106.11,0.019
148.74,106.33,0.019
148.77,106.55,0.019
148.79,106.76,0.019
148.81,106.98,0.019
148.83,107.20,0.019
148.85,107.41,0.019
148.87,107.63,0.019
148.90,107.85,0.019
148.92,108.06,0.019
148.94,108.28,0.019
148.96,108.50,0.019
148.98,108.71,0.019
149.00,108.93,0.019
149.03,109.15,0.019
149.05,109.37,0.019
149.07,109.58,0.019
149.09,109.80,0.019
149.11,110.02,0.019
149.13,110.23,0.019
149.15,110.45,0.019
149.18,110.67,0.019
149.20,110.88,0.019
149.22,111.10,0.019
149.24,111.32,0.019
149.26,111.53,0.020
149.28,111.75,0.020
149.31,111.97,0.020
149.33,112.18,0.020
149.35,112.40,0.020
149.37,112.62,0.020
149.39,112.84,0.020
149.42,113.05,0.020
149.44,113.27,0.020
149.46,113.48,0.020
149.48,113.70,0.020
149.50,113.92,0.020
149.52,114.13,0.020
149.55,114.35,0.020
149.57,114.57,0.020
149.59,114.79,0.020
149.61,115.00,0.020
149.63,115.22,0.020
149.65,115.44,0.020
149.68,115.65,0.020
149.70,115.87,0.020
149.72,116.09,0.020
149.74,116.30,0.020
149.76,116.52,0.020
149.78,116.74,0.020
149.80,116.96,0.020
149.83,117.17,0.020
149.85,117.39,0.020
149.87,117.61,0.020
149.89,117.82,0.020
149.91,118.04,0.020
149.93,118.26,0.020
149.96,118.47,0.020
149.98,118.69,0.020
150.00,118.91,0.020
150.02,119.12,0.020
150.04,119.34,0.020
150.07,119.56,0.020
150.09,119.77,0.020
150.11,119.99,0.020
150.13,120.21,0.020
150.15,120.42,0.020
150.17,120.64,0.020
150.20,120.86,0.020
150.22,121.07,0.020
150.24,121.29,0.020
150.26,121.51,0.020
150.28,121.73,0.020
150.30,121.94,0.020
150.33,122.16,0.020
150.35,122.38,0.020
150.37,122.59,0.020
150.39,122.81,0.020
150.41,123.03,0.020
150.43,123.25,0.020
150.45,123.46,0.020
150.48,123.68,0.020
150.50,123.89,0.020
150.52,124.11,0.020
150.54,124.33,0.020
150.56,124.55,0.020
150.58,124.76,0.020
150.61,124.98,0.020
150.63,125.20,0.020
150.65,125.41,0.020
150.67,125.63,0.020
150.69,125.85,0.020
150.72,126.06,0.020
150.74,126.28,0.020
150.76,126.50,0.020
150.78,126.71,0.020
150.80,126.93,0.020
150.82,127.15,0.020
150.85,127.37,0.020
150.87,127.58,0.020
150.89,127.80,0.020
150.91,128.02,0.020
150.93,128.23,0.020
150.95,128.45,0.020
150.98,128.67,0.020
151.00,128.88,0.020
151.02,129.10,0.020
151.04,129.32,0.020
151.06,129.53,0.020
151.08,129.75,0.020
151.10,129.97,0.020
151.13,130.18,0.020
151.15,130.40,0.020
151.17,130.62,0.020
151.19,130.84,0.020
151.21,131.05,0.020
151.23,131.27,0.020
151.26,131.49,0.020
151.28,131.70,0.020
151.30,131.92,0.020
151.32,132.14,0.020
151.34,132.35,0.020
151.37,132.57,0.020
151.39,132.79,0.020
151.41,133.00,0.020
151.43,133.22,0.020
151.45,133.44,0.020
151.47,133.65,0.020
151.50,133.87,0.020
151.52,134.09,0.020
151.54,134.31,0.020
151.56,134.52,0.020
151.58,134.74,0.020
151.60,134.96,0.020
151.63,135.17,0.020
151.65,135.39,0.020
151.67,135.61,0.020
151.69,135.82,0.020
151.71,136.04,0.020
151.73,136.26,0.020
151.75,136.47,0.020
151.78,136.69,0.020
151.80,136.90,0.020
151.82,137.12,0.020
151.84,137.34,0.020
151.86,137.56,0.020
151.88,137.77,0.020
151.91,137.99,0.020
151.93,138.21,0.020
151.95,138.42,0.020
151.97,138.64,0.020
151.99,138.86,0.020
152.02,139.07,0.020
152.04,139.29,0.020
152.06,139.51,0.020
152.08,139.72,0.020
152.10,139.94,0.020
152.12,140.16,0.020
152.15,140.37,0.020
152.17,140.59,0.020
152.19,140.81,0.020
152.21,141.02,0.020
152.23,141.24,0.020
152.25,141.46,0.020
152.28,141.68,0.020
152.30,141.89,0.020
152.32,142.11,0.020
152.34,142.33,0.020
152.36,142.54,0.020
152.38,142.76,0.020
152.40,142.97,0.020
152.43,143.19,0.020
152.45,143.41,0.020
152.47,143.62,0.020
152.49,143.84,0.020
152.51,144.06,0.020
152.53,144.28,0.020
152.56,144.49,0.020
152.58,144.71,0.020
152.60,144.93,0.020
152.62,145.14,0.020
152.64,145.36,0.020
152.67,145.58,0.020
152.69,145.79,0.020
152.71,146.01,0.020
152.73,146.23,0.020
152.75,146.45,0.020
152.77,146.66,0.020
152.80,146.88,0.020
152.82,147.10,0.020
152.84,147.31,0.020
152.86,147.53,0.020
152.88,147.75,0.020
152.90,147.96,0.020
152.93,148.18,0.020
152.95,148.40,0.020
152.97,148.61,0.020
152.99,148.83,0.020
153.01,149.05,0.020
153.03,149.26,0.020
153.05,149.48,0.020
153.08,149.70,0.020
153.10,149.91,0.020
153.12,150.13,0.020
153.14,150.35,0.020
153.16,150.56,0.020
153.18,150.78,0.020
153.21,151.00,0.020
153.23,151.22,0.020
153.25,151.43,0.020
153.27,151.65,0.020
153.29,151.87,0.020
153.32,152.08,0.020
153.34,152.30,0.020
153.36,152.52,0.020
153.38,152.73,0.020
153.40,152.95,0.020
153.42,153.17,0.020
153.45,153.38,0.020
153.47,153.60,0.020
153.49,153.82,0.020
153.51,154.03,0.020
153.53,154.25,0.020
153.55,154.47,0.020
153.58,154.68,0.020
153.60,154.90,0.020
153.62,155.12,0.020
153.64,155.33,0.020
153.66,155.55,0.020
153.68,155.77,0.020
153.70,155.99,0.020
153.73,156.20,0.020
153.75,156.42,0.020
153.77,156.64,0.020
153.79,156.85,0.020
153.81,157.07,0.020
153.83,157.29,0.020
153.86,157.50,0.020
153.88,157.72,0.020
153.90,157.94,0.020
153.92,158.15,0.020
153.94,158.37,0.020
153.97,158.59,0.020
153.99,158.81,0.020
154.01,159.02,0.020
154.03,159.24,0.020
154.05,159.46,0.020
154.07,159.67,0.020
154.10,159.89,0.020
154.12,160.11,0.020
154.14,160.32,0.020
154.16,160.54,0.020
154.18,160.75,0.020
154.20,160.97,0.020
154.23,161.19,0.020
154.25,161.41,0.020
154.27,161.62,0.020
154.29,161.84,0.020
154.31,162.06,0.020
154.33,162.27,0.020
154.35,162.49,0.020
154.38,162.71,0.020
154.40,162.92,0.020
154.42,163.14,0.020
154.44,163.36,0.020
154.46,163.57,0.020
154.48,163.79,0.020
154.51,164.01,0.020
154.53,164.23,0.020
154.55,164.44,0.020
154.57,164.66,0.020
154.59,164.88,0.020
154.62,165.09,0.020
154.64,165.31,0.021
154.66,165.53,0.021
154.68,165.74,0.021
154.70,165.96,0.021
154.72,166.18,0.021
154.75,166.39,0.021
154.77,166.61,0.021
154.79,166.83,0.021
154.81,167.04,0.021
154.83,167.26,0.021
154.85,167.48,0.021
154.88,167.69,0.021
154.90,167.91,0.021
154.92,168.13,0.021
154.94,168.35,0.021
154.96,168.56,0.021
154.98,168.78,0.021
155.00,169.00,0.021
155.03,169.21,0.021
155.05,169.43,0.021
155.07,169.65,0.021
155.09,169.86,0.021
155.11,170.08,0.021
155.13,170.30,0.021
155.16,170.51,0.021
155.18,170.73,0.021
155.20,170.95,0.021
155.22,171.16,0.021
155.24,171.38,0.021
155.27,171.60,0.021
155.29,171.81,0.021
155.31,172.03,0.021
155.33,172.25,0.021
155.35,172.46,0.021
155.37,172.68,0.021
155.40,172.90,0.021
155.42,173.11,0.021
155.44,173.33,0.021
155.46,173.55,0.021
155.48,173.76,0.021
155.50,173.98,0.021
155.53,174.20,0.021
155.55,174.41,0.021
155.57,174.63,0.021
155.59,174.85,0.021
155.61,175.06,0.021
155.63,175.28,0.021
155.65,175.50,0.021
155.68,175.71,0.021
155.70,175.93,0.021
155.72,176.15,0.021
155.74,176.37,0.021
155.76,176.58,0.021
155.78,176.80,0.021
155.81,177.02,0.021
155.83,177.23,0.021
155.85,177.45,0.021
155.87,177.67,0.021
155.89,177.88,0.021
155.92,178.10,0.021
155.94,178.32,0.021
155.96,178.54,0.021
155.98,178.75,0.021
156.00,178.97,0.021
156.02,179.19,0.021
156.05,179.40,0.021
156.07,179.62,0.021
156.09,179.84,0.021
156.11,180.05,0.021
156.13,180.27,0.021
156.15,180.49,0.021
156.18,180.70,0.021
156.20,180.92,0.021
156.22,181.14,0.021
156.24,181.35,0.021
156.26,181.57,0.021
156.28,181.79,0.021
156.30,182.00,0.021
156.33,182.22,0.021
156.35,182.44,0.021
156.37,182.65,0.021
156.39,182.87,0.021
156.41,183.09,0.021
156.43,183.31,0.021
156.46,183.52,0.021
156.48,183.74,0.021
156.50,183.96,0.021
156.52,184.17,0.021
156.54,184.39,0.021
156.57,184.61,0.021
156.59,184.82,0.021
156.61,185.04,0.021
156.63,185.26,0.021
156.65,185.47,0.021
156.67,185.69,0.021
156.70,185.91,0.021
156.72,186.12,0.021
156.74,186.34,0.021
156.76,186.56,0.021
156.78,186.77,0.021
156.80,186.99,0.021
156.83,187.21,0.021
156.85,187.43,0.021
156.87,187.64,0.021
156.89,187.86,0.021
156.91,188.08,0.021
156.93,188.29,0.021
156.95,188.51,0.021
156.98,188.73,0.021
157.00,188.94,0.021
157.02,189.16,0.021
157.04,189.38,0.021
157.06,189.59,0.021
157.08,189.81,0.021
157.11,190.03,0.021
157.13,190.24,0.021
157.15,190.46,0.021
157.17,190.68,0.021
157.19,190.89,0.021
157.22,191.11,0.021
157.24,191.33,0.021
157.26,191.54,0.021
157.28,191.76,0.021
157.30,191.98,0.021
157.32,192.19,0.021
157.35,192.41,0.021
157.37,192.63,0.021
157.39,192.84,0.021
157.41,193.06,0.021
157.43,193.28,0.021
157.45,193.50,0.021
157.48,193.71,0.021
157.50,193.93,0.021
157.52,194.15,0.021
157.54,194.36,0.021
157.56,194.58,0.021
157.58,194.80,0.021
157.60,195.01,0.021
157.63,195.23,0.021
157.65,195.45,0.021
157.67,195.66,0.021
157.69,195.88,0.021
157.71,196.10,0.021
157.73,196.31,0.021
157.76,196.53,0.021
157.78,196.75,0.021
157.80,196.96,0.021
157.82,197.18,0.021
157.84,197.40,0.021
157.87,197.61,0.021
157.89,197.83,0.021
157.91,198.05,0.021
157.93,198.26,0.021
157.95,198.48,0.021
157.97,198.70,0.021
158.00,198.92,0.021
158.02,199.13,0.021
158.04,199.35,0.021
158.06,199.56,0.021
158.08,199.78,0.021
158.10,200.00,0.021
158.13,200.21,0.021
158.15,200.43,0.021
158.17,200.65,0.021
158.19,200.87,0.021
158.21,201.08,0.021
158.23,201.30,0.021
158.25,201.52,0.021
158.28,201.73,0.021
158.30,201.95,0.021
158.32,202.17,0.021
158.34,202.38,0.021
158.36,202.60,0.021
158.38,202.82,0.021
158.41,203.03,0.021
158.43,203.25,0.021
158.45,203.47,0.021
158.47,203.68,0.021
158.49,203.90,0.021
158.52,204.12,0.021
158.54,204.34,0.021
158.56,204.55,0.021
158.58,204.77,0.021
158.60,204.98,0.021
158.62,205.20,0.021
158.65,205.42,0.021
158.67,205.64,0.021
158.69,205.85,0.021
158.71,206.07,0.021
158.73,206.29,0.021
158.75,206.50,0.021
158.78,206.72,0.021
158.80,206.94,0.021
158.82,207.15,0.021
158.84,207.37,0.021
158.86,207.59,0.021
158.88,207.80,0.021
158.90,208.02,0.021
158.93,208.24,0.021
158.95,208.45,0.021
158.97,208.67,0.021
158.99,208.89,0.021
159.01,209.11,0.021
159.03,209.32,0.021
159.06,209.54,0.021
159.08,209.76,0.021
159.10,209.97,0.021
159.12,210.19,0.021
159.14,210.40,0.021
159.17,210.62,0.021
159.19,210.84,0.021
159.21,211.06,0.021
159.23,211.27,0.021
159.25,211.49,0.021
159.27,211.71,0.021
159.30,211.92,0.021
159.32,212.14,0.021
159.34,212.36,0.021
159.36,212.57,0.021
159.38,212.79,0.021
159.40,213.01,0.021
159.43,213.22,0.021
159.45,213.44,0.021
159.47,213.66,0.021
159.49,213.87,0.021
159.51,214.09,0.021
159.53,214.31,0.021
159.55,214.52,0.021
159.58,214.74,0.021
159.60,214.96,0.021
159.62,215.17,0.021
159.64,215.39,0.021
159.66,215.61,0.021
159.68,215.83,0.021
159.71,216.04,0.021
159.73,216.26,0.021
159.75,216.48,0.021
159.77,216.69,0.021
159.79,216.91,0.021
159.82,217.13,0.022
159.84,217.34,0.022
159.86,217.56,0.022
159.88,217.78,0.022
159.90,217.99,0.022
159.92,218.21,0.022
159.95,218.43,0.022
159.97,218.64,0.022
159.99,218.86,0.022
160.01,219.08,0.022
160.03,219.29,0.022
160.05,219.51,0.022
160.08,219.73,0.022
160.10,219.94,0.022
160.12,220.16,0.022
160.14,220.38,0.022
160.16,220.60,0.022
160.18,220.81,0.022
160.20,221.03,0.022
160.23,221.25,0.022
160.25,221.46,0.022
160.27,221.68,0.022
160.29,221.90,0.022
160.31,222.11,0.022
160.33,222.33,0.022
160.36,222.55,0.022
160.38,222.76,0.022
160.40,222.98,0.022
160.42,223.20,0.022
160.44,223.41,0.022
160.47,223.63,0.022
160.49,223.85,0.022
160.51,224.07,0.022
160.53,224.28,0.022
160.55,224.50,0.022
160.57,224.72,0.022
160.60,224.93,0.022
160.62,225.15,0.022
160.64,225.36,0.022
160.66,225.58,0.022
160.68,225.80,0.022
160.70,226.02,0.022
160.73,226.23,0.022
160.75,226.45,0.022
160.77,226.67,0.022
160.79,226.88,0.022
160.81,227.10,0.022
160.83,227.32,0.022
160.85,227.53,0.022
160.88,227.75,0.022
160.90,227.97,0.022
160.92,228.18,0.022
160.94,228.40,0.022
160.96,228.62,0.022
160.98,228.83,0.022
161.01,229.05,0.022
161.03,229.27,0.022
161.05,229.48,0.022
161.07,229.70,0.022
161.09,229.92,0.022
161.12,230.13,0.022
161.14,230.35,0.022
161.16,230.57,0.022
161.18,230.78,0.022
161.20,231.00,0.022
161.22,231.22,0.022
161.25,231.43,0.022
161.27,231.65,0.022
161.29,231.87,0.022
161.31,232.08,0.022
161.33,232.30,0.022
161.35,232.52,0.022
161.38,232.73,0.022
161.40,232.95,0.022
161.42,233.17,0.022
161.44,233.38,0.022
161.46,233.60,0.022
161.48,233.82,0.022
161.50,234.03,0.022
161.53,234.25,0.022
161.55,234.47,0.022
161.57,234.69,0.022
161.59,234.90,0.022
161.61,235.12,0.022
161.63,235.34,0.022
161.66,235.56,0.022
161.68,235.77,0.022
161.70,235.99,0.022
161.72,236.21,0.022
161.74,236.42,0.022
161.77,236.64,0.022
161.79,236.86,0.022
161.81,237.07,0.022
161.83,237.29,0.022
161.85,237.50,0.022
161.87,237.72,0.022
161.90,237.94,0.022
161.92,238.16,0.022
161.94,238.37,0.022
161.96,238.59,0.022
161.98,238.81,0.022
162.00,239.02,0.022
162.03,239.24,0.022
162.05,239.46,0.022
162.07,239.67,0.022
162.09,239.89,0.022
162.11,240.11,0.022
162.13,240.32,0.022
162.15,240.54,0.022
162.18,240.76,0.022
162.20,240.97,0.022
162.22,241.19,0.022
162.24,241.41,0.022
162.26,241.62,0.022
162.28,241.84,0.022
162.31,242.06,0.022
162.33,242.27,0.022
162.35,242.49,0.022
162.37,242.71,0.022
162.39,242.93,0.022
162.42,243.14,0.022
162.44,243.36,0.022
162.46,243.57,0.022
162.48,243.79,0.022
162.50,244.01,0.022
162.52,244.23,0.022
162.55,244.44,0.022
162.57,244.66,0.022
162.59,244.88,0.022
162.61,245.09,0.022
162.63,245.31,0.022
162.65,245.53,0.022
162.68,245.74,0.022
162.70,245.96,0.022
162.72,246.18,0.022
162.74,246.39,0.022
162.76,246.61,0.022
162.78,246.83,0.022
162.80,247.04,0.022
162.83,247.26,0.022
162.85,247.48,0.022
162.87,247.70,0.022
162.89,247.91,0.022
162.91,248.13,0.022
162.93,248.34,0.022
162.96,248.56,
162.98,248.78,
162.99,,