File: DSC/Olivia/2025_08_09_PVP10_n60C_180C_10Cmin_x3.csv
Filename,2025_08_09_PVP10_n60C_180C_10Cmin_x3
Instrument name,DSC2A-00468 (192.168.1.100)
Operator,Yarger
rundate,8/9/2025
Sample name,2025_08_09_PVP10_n60C_180C_10Cmin_x3
proceduresegments,Data Off ; Equilibrate -60.00 °C; Data On ; Ramp 10.00 °C/min to 180.00 °C; Data Off ; Isothermal 2.0 min; Data On ; Ramp 10.00 °C/min to -60.00 °C; Data Off ; Isothermal 2.0 min; Data On ; Ramp 10.00 °C/min to 180.00 °C; Data Off ; Isothermal 2.0 min; Data On ; Ramp 10.00 °C/min to -60.00 °C; Data Off ; Isothermal 2.0 min; Data On ; Ramp 10.00 °C/min to 180.00 °C
[File Parameters]
Run date,8/9/2025 7:48:54 AM
Trios version,5.1.1.46572
Original File Name,
Current File Name,D:\DSC2500\JYarger\2025_08_09_PVP10_n60C_180C_10Cmin_x3.tri
[Procedure]
Procedure Name,PVP10_TS_Pans_n60C_180C_10Cmin_x3
Sample Name,2025_08_09_PVP10_n60C_180C_10Cmin_x3
Sample Mass,4.19 mg
Reference Sample Mass,0 mg
Pan Mass,32.25 mg
Pan Number,42
Reference Pan Mass,32.52 mg
Reference Pan Number,37
Pan Type,Aluminum
Comments,Thermal support Al pans/lids. DSC_Samples_A2_Tray_July2025 google sheet.
Project Name,Pharma
Operator,Yarger
Test,Custom
Unload Max Temperature,30
Unload Min Temperature,30
Load Max Temperature,30
Load Min Temperature,30
Stop on Gas Flow Error,Yes
[Signal List]
Signal #1,Time (min)
Signal #2,Temperature (°C)
Signal #3,Heat Flow (mW)
Signal #4,Delta T (µV)
Signal #5,Delta Tzero (µV)
Signal #6,Tzero Temperature (°C)
Signal #7,Cell Purge (mL/min)
Signal #8,Heater Temp (°C)
Signal #9,Power Delivered (W)
Signal #10,Reference Junction Temperature (°C)
Signal #11,Flange Temperature (°C)
Signal #12,Heat Flow Phase (rad)
Signal #13,Total Heat Capacity (J/°C)
Signal #14,Heat Capacity (J/°C)
[Configuration]
Company Name,ASU
Instrument Name,DSC2A-00468
Instrument Type,DSC2500
Serial Number,DSC2A-00468
IP,192.168.1.100
Location of Instrument,MRRC
DisplayType,Unknown
Sample Interval ,0.1 s/pt
Selected Heat Flow,T4P
Exotherm Direction,Down
Cell Serial,DRC2-00792
Lid Type,Standard
Cooler,RCS 90
Leave Cooler on at End of Sequence,On
Gas 2,Nitrogen
Gas Selected,Channel 1
Flow Rate,50 mL/min
Secondary Purge,On
Licensed Heat Flow,Heat Flow T4P
Modulation Licensed,Yes
[Versions]
Common IDD Version,1
Cortex Version,VER 2.10.2.31
Driver,5.0.0.6
GDM Version,1.0.3.3
TouchscreenVersion,1.0.0.16145
FEP Version,1.2.1.21
FEP Bootloader,2.0.0.5
AutoSampler Version,2.1.1.26
Auto Sampler Bootloader,2.0.0.5
FCM Version,1.1.0.3
FCM Bootloader,2.0.0.5
[Experiment Logs]
Experiment Log Entry # 1,Data On set to 0
Experiment Log Entry # 3,Equilibrate Segment -60 (C) Started
Experiment Log Entry # 5,Air Cool is off.
Experiment Log Entry # 7,Data On set to 1
Experiment Log Entry # 9,Ramp Segment 10 C/min to 180 Started
Experiment Log Entry # 11,Data On set to 0
Experiment Log Entry # 13,Isothermal Segment 2 min started
Experiment Log Entry # 15,Data On set to 1
Experiment Log Entry # 17,Ramp Segment 10 C/min to -60 Started
Experiment Log Entry # 19,Data On set to 0
Experiment Log Entry # 21,Isothermal Segment 2 min started
Experiment Log Entry # 23,Data On set to 1
Experiment Log Entry # 25,Ramp Segment 10 C/min to 180 Started
Experiment Log Entry # 27,Data On set to 0
Experiment Log Entry # 29,Isothermal Segment 2 min started
Experiment Log Entry # 31,Data On set to 1
Experiment Log Entry # 33,Ramp Segment 10 C/min to -60 Started
Experiment Log Entry # 35,Data On set to 0
Experiment Log Entry # 37,Isothermal Segment 2 min started
Experiment Log Entry # 39,Data On set to 1
Experiment Log Entry # 41,Ramp Segment 10 C/min to 180 Started
[Method Log]
Method Log Entry # 1,Data Off
Method Log Entry # 2,Equilibrate -60 °C
Method Log Entry # 3,Data On
Method Log Entry # 4,(Ramp 601179) Ramp 10 °C/minute to 180 °C
Method Log Entry # 5,Data Off
Method Log Entry # 6,Isothermal 2 minutes
Method Log Entry # 7,Data On
Method Log Entry # 8,(Ramp 601183) Ramp 10 °C/minute to -60 °C
Method Log Entry # 9,Data Off
Method Log Entry # 10,Isothermal 2 minutes
Method Log Entry # 11,Data On
Method Log Entry # 12,(Ramp 601187) Ramp 10 °C/minute to 180 °C
Method Log Entry # 13,Data Off
Method Log Entry # 14,Isothermal 2 minutes
Method Log Entry # 15,Data On
Method Log Entry # 16,(Ramp 601191) Ramp 10 °C/minute to -60 °C
Method Log Entry # 17,Data Off
Method Log Entry # 18,Isothermal 2 minutes
Method Log Entry # 19,Data On
Method Log Entry # 20,(Ramp 601195) Ramp 10 °C/minute to 180 °C
Cell Serial,DRC2-00792
[T1 Calibration]
Slope,-0.008529666
Offset,9.636258
Initial Temperature,98.23
GUID,f8bfdadc-4977-4fdf-ba6d-0ba9134940c3
[TZero Calibration]
Date Applied,11/29/2022 4:06:13 PM
Description,From -89.059 °C to 396.009 °C at 20.000°C/min
Gas Type,Nitrogen
Pan Type,None
Source Files 1,C:\Users\yargerlab\Desktop\DSC Data\General\TZero_calibration_11_29_22_2nd(2).tri
Source Files 2,C:\Users\yargerlab\Desktop\DSC Data\General\TZero_calibration_11_29_22_2nd(3).tri
Delta T Offset,13.05235
Delta T Slope,-0.007271007
Delta T0 Offset,-13.69128
Delta T0 Slope,0.06063341
[Temperature Calibration]
Date Applied,11/29/2022 7:12:28 PM
Description,From 106.590 °C to 186.590 °C at 10.000°C/min
Gas Type,Nitrogen
Pan Type,Tzero Aluminum Hermetic
Source Files 1,C:\Users\yargerlab\Desktop\DSC Data\General\Indium(6).tri
Measured 1,157.391
Known 1,156.598
[Cell Constant Calibration]
Date Applied,11/29/2022 7:12:29 PM
Description,From 106.590 °C to 186.590 °C at 10.000°C/min
Gas Type,Nitrogen
Pan Type,Tzero Aluminum Hermetic
Source Files 1,C:\Users\yargerlab\Desktop\DSC Data\General\Indium(6).tri
T4P KCell,1.006051
Onset Slope,63.26126 mW/°C
[Direct Cp Calibration]
Date Applied,11/30/2022 11:04:51 AM
Description,From -79.983 °C to 298.409 °C at 10.000°C/min
Gas Type,Nitrogen
Pan Type,Tzero Aluminum Hermetic
Source Files 1,C:\Users\yargerlab\Desktop\DSC Data\General\Sapphire_Heat_Capacity_11_30_22.tri
[Rev Cp Calibration]
Date Applied,11/30/2022 1:58:51 PM
Description,From -79.996 °C to 292.812 °C at 3.000°C/min
Gas Type,Nitrogen
Pan Type,Tzero Aluminum Hermetic
Source Files 1,C:\Users\yargerlab\Desktop\DSC Data\General\Sapphire_MDSC_Calibration_11_30_22.tri
[step]
Ramp 10.00 °C/min to 180.00 °C
Time,Temperature,Heat Flow (Normalized)
min,°C,W/g
0.00,-59.81,-0.053
0.02,-59.81,-0.051
0.03,-59.81,-0.048
0.05,-59.81,-0.045
0.07,-59.79,-0.042
0.08,-59.75,-0.035
0.10,-59.69,-0.020
0.12,-59.62,0.000
0.13,-59.52,0.024
0.15,-59.41,0.051
0.17,-59.29,0.080
0.18,-59.15,0.106
0.20,-59.01,0.130
0.22,-58.87,0.153
0.23,-58.71,0.169
0.25,-58.56,0.185
0.27,-58.40,0.196
0.28,-58.25,0.206
0.30,-58.09,0.213
0.32,-57.93,0.219
0.33,-57.76,0.224
0.35,-57.60,0.227
0.37,-57.44,0.231
0.38,-57.28,0.232
0.40,-57.12,0.235
0.42,-56.96,0.236
0.43,-56.79,0.237
0.45,-56.63,0.238
0.47,-56.47,0.239
0.48,-56.31,0.240
0.50,-56.14,0.241
0.52,-55.98,0.241
0.53,-55.81,0.242
0.55,-55.65,0.242
0.57,-55.49,0.243
0.58,-55.32,0.243
0.60,-55.16,0.244
0.62,-54.99,0.244
0.63,-54.83,0.245
0.65,-54.66,0.245
0.67,-54.50,0.245
0.68,-54.34,0.246
0.70,-54.17,0.246
0.72,-54.01,0.247
0.73,-53.84,0.247
0.75,-53.68,0.247
0.77,-53.51,0.248
0.78,-53.34,0.248
0.80,-53.18,0.248
0.82,-53.02,0.249
0.83,-52.85,0.249
0.85,-52.68,0.250
0.87,-52.52,0.250
0.88,-52.35,0.250
0.90,-52.19,0.251
0.92,-52.02,0.251
0.93,-51.86,0.251
0.95,-51.69,0.252
0.97,-51.52,0.252
0.98,-51.36,0.252
1.00,-51.19,0.252
1.02,-51.03,0.253
1.03,-50.86,0.253
1.05,-50.70,0.253
1.07,-50.53,0.254
1.08,-50.36,0.254
1.10,-50.20,0.254
1.12,-50.03,0.254
1.13,-49.87,0.255
1.15,-49.70,0.255
1.17,-49.53,0.255
1.18,-49.37,0.255
1.20,-49.20,0.256
1.22,-49.04,0.256
1.23,-48.87,0.256
1.25,-48.70,0.256
1.27,-48.54,0.256
1.28,-48.37,0.257
1.30,-48.20,0.257
1.32,-48.04,0.257
1.33,-47.87,0.257
1.35,-47.70,0.257
1.37,-47.54,0.257
1.38,-47.37,0.258
1.40,-47.21,0.258
1.42,-47.04,0.258
1.43,-46.87,0.258
1.45,-46.71,0.258
1.47,-46.54,0.259
1.48,-46.37,0.259
1.50,-46.21,0.259
1.52,-46.04,0.259
1.53,-45.87,0.259
1.55,-45.71,0.259
1.57,-45.54,0.259
1.58,-45.37,0.260
1.60,-45.21,0.260
1.62,-45.04,0.260
1.63,-44.87,0.260
1.65,-44.71,0.260
1.67,-44.54,0.260
1.68,-44.37,0.260
1.70,-44.21,0.260
1.72,-44.04,0.261
1.73,-43.87,0.261
1.75,-43.70,0.261
1.77,-43.54,0.261
1.78,-43.37,0.261
1.80,-43.21,0.261
1.82,-43.04,0.261
1.83,-42.87,0.261
1.85,-42.71,0.262
1.87,-42.54,0.262
1.88,-42.37,0.262
1.90,-42.20,0.262
1.92,-42.04,0.262
1.93,-41.87,0.262
1.95,-41.70,0.262
1.97,-41.54,0.262
1.98,-41.37,0.262
2.00,-41.21,0.262
2.02,-41.04,0.263
2.03,-40.87,0.263
2.05,-40.70,0.263
2.07,-40.54,0.263
2.08,-40.37,0.263
2.10,-40.20,0.263
2.12,-40.03,0.263
2.13,-39.87,0.263
2.15,-39.70,0.263
2.17,-39.53,0.263
2.18,-39.37,0.264
2.20,-39.20,0.264
2.22,-39.03,0.264
2.23,-38.87,0.264
2.25,-38.70,0.264
2.27,-38.53,0.264
2.28,-38.37,0.264
2.30,-38.20,0.264
2.32,-38.03,0.264
2.33,-37.87,0.264
2.35,-37.70,0.264
2.37,-37.53,0.264
2.38,-37.37,0.264
2.40,-37.20,0.265
2.42,-37.03,0.265
2.43,-36.86,0.265
2.45,-36.70,0.265
2.47,-36.53,0.265
2.48,-36.36,0.265
2.50,-36.20,0.265
2.52,-36.03,0.265
2.53,-35.87,0.265
2.55,-35.70,0.265
2.57,-35.53,0.265
2.58,-35.36,0.266
2.60,-35.20,0.266
2.62,-35.03,0.266
2.63,-34.86,0.266
2.65,-34.70,0.266
2.67,-34.53,0.266
2.68,-34.36,0.266
2.70,-34.19,0.266
2.72,-34.03,0.266
2.73,-33.86,0.266
2.75,-33.69,0.266
2.77,-33.53,0.267
2.78,-33.36,0.267
2.80,-33.19,0.267
2.82,-33.03,0.267
2.83,-32.86,0.267
2.85,-32.69,0.267
2.87,-32.53,0.267
2.88,-32.36,0.267
2.90,-32.19,0.267
2.92,-32.03,0.267
2.93,-31.86,0.267
2.95,-31.69,0.267
2.97,-31.53,0.268
2.98,-31.36,0.268
3.00,-31.19,0.268
3.02,-31.03,0.268
3.03,-30.86,0.268
3.05,-30.69,0.268
3.07,-30.52,0.268
3.08,-30.36,0.268
3.10,-30.19,0.268
3.12,-30.02,0.268
3.13,-29.86,0.268
3.15,-29.69,0.269
3.17,-29.53,0.269
3.18,-29.36,0.269
3.20,-29.19,0.269
3.22,-29.02,0.269
3.23,-28.86,0.269
3.25,-28.69,0.269
3.27,-28.52,0.269
3.28,-28.36,0.269
3.30,-28.19,0.269
3.32,-28.02,0.270
3.33,-27.86,0.270
3.35,-27.69,0.270
3.37,-27.52,0.270
3.38,-27.35,0.270
3.40,-27.19,0.270
3.42,-27.02,0.270
3.43,-26.85,0.270
3.45,-26.68,0.271
3.47,-26.52,0.271
3.48,-26.35,0.271
3.50,-26.18,0.271
3.52,-26.02,0.271
3.53,-25.85,0.271
3.55,-25.68,0.271
3.57,-25.52,0.272
3.58,-25.35,0.272
3.60,-25.18,0.272
3.62,-25.02,0.272
3.63,-24.85,0.272
3.65,-24.68,0.272
3.67,-24.52,0.272
3.68,-24.35,0.272
3.70,-24.18,0.272
3.72,-24.02,0.272
3.73,-23.85,0.272
3.75,-23.68,0.273
3.77,-23.51,0.273
3.78,-23.35,0.273
3.80,-23.18,0.273
3.82,-23.01,0.273
3.83,-22.85,0.273
3.85,-22.68,0.273
3.87,-22.51,0.273
3.88,-22.35,0.274
3.90,-22.18,0.274
3.92,-22.01,0.274
3.93,-21.85,0.274
3.95,-21.68,0.274
3.97,-21.51,0.274
3.98,-21.35,0.274
4.00,-21.18,0.274
4.02,-21.01,0.275
4.03,-20.84,0.275
4.05,-20.68,0.275
4.07,-20.51,0.275
4.08,-20.34,0.275
4.10,-20.18,0.275
4.12,-20.01,0.275
4.13,-19.84,0.275
4.15,-19.68,0.276
4.17,-19.51,0.276
4.18,-19.35,0.276
4.20,-19.18,0.276
4.22,-19.01,0.276
4.23,-18.85,0.276
4.25,-18.68,0.276
4.27,-18.51,0.276
4.28,-18.34,0.276
4.30,-18.18,0.277
4.32,-18.01,0.277
4.33,-17.84,0.277
4.35,-17.68,0.277
4.37,-17.51,0.277
4.38,-17.34,0.277
4.40,-17.18,0.278
4.42,-17.01,0.278
4.43,-16.84,0.278
4.45,-16.68,0.278
4.47,-16.51,0.278
4.48,-16.34,0.278
4.50,-16.17,0.278
4.52,-16.01,0.279
4.53,-15.84,0.279
4.55,-15.67,0.279
4.57,-15.51,0.279
4.58,-15.34,0.279
4.60,-15.17,0.279
4.62,-15.01,0.280
4.63,-14.84,0.280
4.65,-14.67,0.280
4.67,-14.50,0.280
4.68,-14.34,0.280
4.70,-14.17,0.280
4.72,-14.00,0.280
4.73,-13.84,0.281
4.75,-13.67,0.281
4.77,-13.51,0.281
4.78,-13.34,0.281
4.80,-13.17,0.281
4.82,-13.00,0.281
4.83,-12.84,0.281
4.85,-12.67,0.282
4.87,-12.50,0.282
4.88,-12.34,0.282
4.90,-12.17,0.282
4.92,-12.00,0.282
4.93,-11.84,0.282
4.95,-11.67,0.283
4.97,-11.50,0.283
4.98,-11.33,0.283
5.00,-11.17,0.283
5.02,-11.00,0.283
5.03,-10.83,0.283
5.05,-10.67,0.284
5.07,-10.50,0.284
5.08,-10.34,0.284
5.10,-10.17,0.284
5.12,-10.00,0.284
5.13,-9.84,0.284
5.15,-9.67,0.284
5.17,-9.50,0.285
5.18,-9.34,0.285
5.20,-9.17,0.285
5.22,-9.00,0.285
5.23,-8.83,0.285
5.25,-8.67,0.285
5.27,-8.50,0.286
5.28,-8.33,0.286
5.30,-8.17,0.286
5.32,-8.00,0.286
5.33,-7.83,0.286
5.35,-7.67,0.287
5.37,-7.50,0.287
5.38,-7.33,0.287
5.40,-7.17,0.287
5.42,-7.00,0.287
5.43,-6.83,0.288
5.45,-6.67,0.288
5.47,-6.50,0.288
5.48,-6.33,0.288
5.50,-6.17,0.288
5.52,-6.00,0.289
5.53,-5.83,0.289
5.55,-5.67,0.289
5.57,-5.50,0.289
5.58,-5.33,0.289
5.60,-5.17,0.290
5.62,-5.00,0.290
5.63,-4.83,0.290
5.65,-4.66,0.290
5.67,-4.50,0.290
5.68,-4.33,0.291
5.70,-4.16,0.291
5.72,-4.00,0.291
5.73,-3.83,0.291
5.75,-3.66,0.291
5.77,-3.50,0.292
5.78,-3.33,0.292
5.80,-3.16,0.292
5.82,-3.00,0.292
5.83,-2.83,0.292
5.85,-2.66,0.293
5.87,-2.50,0.293
5.88,-2.33,0.293
5.90,-2.16,0.293
5.92,-2.00,0.293
5.93,-1.83,0.294
5.95,-1.66,0.294
5.97,-1.49,0.294
5.98,-1.33,0.294
6.00,-1.16,0.295
6.02,-0.99,0.295
6.03,-0.83,0.295
6.05,-0.66,0.295
6.07,-0.49,0.295
6.08,-0.33,0.295
6.10,-0.16,0.296
6.12,0.01,0.296
6.13,0.17,0.296
6.15,0.34,0.296
6.17,0.51,0.296
6.18,0.67,0.297
6.20,0.84,0.297
6.22,1.01,0.297
6.23,1.18,0.297
6.25,1.34,0.298
6.27,1.51,0.298
6.28,1.68,0.298
6.30,1.84,0.298
6.32,2.01,0.298
6.33,2.18,0.299
6.35,2.34,0.299
6.37,2.51,0.299
6.38,2.68,0.299
6.40,2.84,0.300
6.42,3.01,0.300
6.43,3.18,0.300
6.45,3.35,0.300
6.47,3.51,0.301
6.48,3.68,0.301
6.50,3.85,0.301
6.52,4.01,0.301
6.53,4.18,0.302
6.55,4.35,0.302
6.57,4.51,0.302
6.58,4.68,0.302
6.60,4.85,0.302
6.62,5.01,0.303
6.63,5.18,0.303
6.65,5.35,0.303
6.67,5.52,0.303
6.68,5.68,0.304
6.70,5.85,0.304
6.72,6.02,0.304
6.73,6.18,0.304
6.75,6.35,0.305
6.77,6.52,0.305
6.78,6.68,0.305
6.80,6.85,0.305
6.82,7.02,0.306
6.83,7.18,0.306
6.85,7.35,0.306
6.87,7.52,0.306
6.88,7.68,0.307
6.90,7.85,0.307
6.92,8.02,0.307
6.93,8.18,0.307
6.95,8.35,0.308
6.97,8.52,0.308
6.98,8.68,0.308
7.00,8.85,0.309
7.02,9.02,0.309
7.03,9.18,0.309
7.05,9.35,0.309
7.07,9.52,0.310
7.08,9.68,0.310
7.10,9.85,0.310
7.12,10.02,0.311
7.13,10.18,0.311
7.15,10.35,0.311
7.17,10.52,0.312
7.18,10.68,0.312
7.20,10.85,0.312
7.22,11.02,0.313
7.23,11.18,0.313
7.25,11.35,0.313
7.27,11.52,0.313
7.28,11.68,0.314
7.30,11.85,0.314
7.32,12.02,0.314
7.33,12.18,0.315
7.35,12.35,0.315
7.37,12.52,0.315
7.38,12.69,0.316
7.40,12.85,0.316
7.42,13.02,0.316
7.43,13.19,0.317
7.45,13.35,0.317
7.47,13.52,0.317
7.48,13.69,0.318
7.50,13.85,0.318
7.52,14.02,0.318
7.53,14.19,0.319
7.55,14.35,0.319
7.57,14.52,0.319
7.58,14.69,0.319
7.60,14.85,0.320
7.62,15.02,0.320
7.63,15.19,0.321
7.65,15.36,0.321
7.67,15.52,0.321
7.68,15.69,0.322
7.70,15.86,0.322
7.72,16.02,0.323
7.73,16.19,0.323
7.75,16.36,0.323
7.77,16.52,0.324
7.78,16.69,0.324
7.80,16.86,0.324
7.82,17.03,0.325
7.83,17.19,0.325
7.85,17.36,0.325
7.87,17.52,0.326
7.88,17.69,0.326
7.90,17.86,0.327
7.92,18.02,0.327
7.93,18.19,0.327
7.95,18.36,0.327
7.97,18.52,0.328
7.98,18.69,0.328
8.00,18.86,0.328
8.02,19.02,0.329
8.03,19.19,0.329
8.05,19.36,0.329
8.07,19.52,0.330
8.08,19.69,0.330
8.10,19.85,0.331
8.12,20.02,0.331
8.13,20.19,0.331
8.15,20.35,0.332
8.17,20.52,0.332
8.18,20.69,0.333
8.20,20.86,0.333
8.22,21.02,0.334
8.23,21.19,0.334
8.25,21.36,0.334
8.27,21.52,0.335
8.28,21.69,0.335
8.30,21.86,0.336
8.32,22.02,0.336
8.33,22.19,0.337
8.35,22.36,0.337
8.37,22.52,0.337
8.38,22.69,0.338
8.40,22.86,0.338
8.42,23.02,0.339
8.43,23.19,0.340
8.45,23.35,0.340
8.47,23.52,0.340
8.48,23.69,0.341
8.50,23.86,0.341
8.52,24.02,0.342
8.53,24.19,0.342
8.55,24.36,0.343
8.57,24.52,0.343
8.58,24.69,0.344
8.60,24.86,0.344
8.62,25.02,0.345
8.63,25.19,0.345
8.65,25.36,0.346
8.67,25.52,0.347
8.68,25.69,0.347
8.70,25.86,0.348
8.72,26.02,0.348
8.73,26.19,0.349
8.75,26.36,0.349
8.77,26.52,0.350
8.78,26.69,0.350
8.80,26.86,0.351
8.82,27.02,0.351
8.83,27.19,0.352
8.85,27.36,0.353
8.87,27.52,0.353
8.88,27.69,0.354
8.90,27.86,0.354
8.92,28.02,0.355
8.93,28.19,0.356
8.95,28.36,0.356
8.97,28.52,0.357
8.98,28.69,0.357
9.00,28.86,0.358
9.02,29.02,0.359
9.03,29.19,0.359
9.05,29.36,0.360
9.07,29.52,0.361
9.08,29.69,0.361
9.10,29.86,0.362
9.12,30.02,0.363
9.13,30.19,0.363
9.15,30.36,0.364
9.17,30.52,0.365
9.18,30.69,0.365
9.20,30.86,0.366
9.22,31.02,0.367
9.23,31.19,0.367
9.25,31.36,0.368
9.27,31.52,0.369
9.28,31.69,0.371
9.30,31.86,0.371
9.32,32.02,0.372
9.33,32.19,0.373
9.35,32.36,0.374
9.37,32.52,0.374
9.38,32.69,0.375
9.40,32.86,0.376
9.42,33.02,0.377
9.43,33.19,0.378
9.45,33.36,0.379
9.47,33.52,0.380
9.48,33.69,0.380
9.50,33.85,0.381
9.52,34.02,0.382
9.53,34.19,0.383
9.55,34.36,0.384
9.57,34.52,0.385
9.58,34.69,0.386
9.60,34.86,0.388
9.62,35.02,0.389
9.63,35.19,0.390
9.65,35.36,0.391
9.67,35.52,0.393
9.68,35.69,0.394
9.70,35.86,0.395
9.72,36.02,0.397
9.73,36.19,0.399
9.75,36.35,0.400
9.77,36.52,0.402
9.78,36.69,0.403
9.80,36.85,0.404
9.82,37.02,0.406
9.83,37.19,0.408
9.85,37.35,0.410
9.87,37.52,0.412
9.88,37.69,0.413
9.90,37.85,0.415
9.92,38.02,0.417
9.93,38.19,0.420
9.95,38.35,0.422
9.97,38.52,0.424
9.98,38.68,0.426
10.00,38.85,0.428
10.02,39.02,0.432
10.03,39.18,0.435
10.05,39.35,0.438
10.07,39.52,0.440
10.08,39.68,0.444
10.10,39.85,0.446
10.12,40.01,0.450
10.13,40.18,0.453
10.15,40.35,0.456
10.17,40.51,0.459
10.18,40.68,0.463
10.20,40.84,0.468
10.22,41.01,0.471
10.23,41.18,0.476
10.25,41.34,0.482
10.27,41.51,0.486
10.28,41.67,0.490
10.30,41.84,0.497
10.32,42.00,0.502
10.33,42.17,0.508
10.35,42.33,0.514
10.37,42.50,0.520
10.38,42.67,0.527
10.40,42.83,0.534
10.42,43.00,0.541
10.43,43.16,0.549
10.45,43.32,0.556
10.47,43.49,0.564
10.48,43.65,0.571
10.50,43.82,0.580
10.52,43.98,0.586
10.53,44.15,0.597
10.55,44.31,0.603
10.57,44.48,0.609
10.58,44.64,0.618
10.60,44.81,0.623
10.62,44.97,0.629
10.63,45.14,0.634
10.65,45.30,0.639
10.67,45.47,0.643
10.68,45.63,0.646
10.70,45.80,0.647
10.72,45.97,0.648
10.73,46.13,0.649
10.75,46.30,0.649
10.77,46.46,0.649
10.78,46.63,0.648
10.80,46.80,0.646
10.82,46.97,0.638
10.83,47.13,0.632
10.85,47.30,0.625
10.87,47.47,0.619
10.88,47.64,0.612
10.90,47.81,0.606
10.92,47.98,0.600
10.93,48.15,0.593
10.95,48.31,0.587
10.97,48.48,0.581
10.98,48.65,0.576
11.00,48.82,0.571
11.02,48.99,0.566
11.03,49.16,0.564
11.05,49.33,0.561
11.07,49.49,0.558
11.08,49.66,0.556
11.10,49.83,0.554
11.12,50.00,0.553
11.13,50.16,0.551
11.15,50.33,0.550
11.17,50.50,0.549
11.18,50.67,0.549
11.20,50.83,0.548
11.22,51.00,0.548
11.23,51.17,0.547
11.25,51.33,0.547
11.27,51.50,0.547
11.28,51.67,0.547
11.30,51.83,0.547
11.32,52.00,0.546
11.33,52.17,0.546
11.35,52.34,0.546
11.37,52.50,0.546
11.38,52.67,0.547
11.40,52.83,0.547
11.42,53.00,0.547
11.43,53.17,0.547
11.45,53.33,0.548
11.47,53.50,0.549
11.48,53.67,0.549
11.50,53.83,0.550
11.52,54.00,0.551
11.53,54.17,0.551
11.55,54.33,0.552
11.57,54.50,0.553
11.58,54.67,0.554
11.60,54.83,0.554
11.62,55.00,0.556
11.63,55.16,0.557
11.65,55.33,0.558
11.67,55.50,0.560
11.68,55.67,0.561
11.70,55.83,0.562
11.72,56.00,0.563
11.73,56.17,0.565
11.75,56.33,0.566
11.77,56.50,0.567
11.78,56.66,0.569
11.80,56.83,0.570
11.82,57.00,0.571
11.83,57.16,0.574
11.85,57.33,0.575
11.87,57.50,0.577
11.88,57.66,0.578
11.90,57.83,0.579
11.92,58.00,0.581
11.93,58.16,0.582
11.95,58.33,0.584
11.97,58.50,0.586
11.98,58.66,0.588
12.00,58.83,0.589
12.02,59.00,0.590
12.03,59.16,0.592
12.05,59.33,0.593
12.07,59.50,0.594
12.08,59.66,0.596
12.10,59.83,0.597
12.12,60.00,0.599
12.13,60.16,0.601
12.15,60.33,0.603
12.17,60.49,0.604
12.18,60.66,0.605
12.20,60.83,0.607
12.22,60.99,0.610
12.23,61.16,0.612
12.25,61.33,0.613
12.27,61.49,0.615
12.28,61.66,0.616
12.30,61.82,0.618
12.32,61.99,0.620
12.33,62.16,0.621
12.35,62.32,0.623
12.37,62.49,0.625
12.38,62.66,0.628
12.40,62.82,0.629
12.42,62.99,0.631
12.43,63.15,0.632
12.45,63.32,0.635
12.47,63.49,0.636
12.48,63.65,0.639
12.50,63.82,0.641
12.52,63.99,0.642
12.53,64.15,0.645
12.55,64.32,0.647
12.57,64.49,0.649
12.58,64.65,0.651
12.60,64.82,0.652
12.62,64.99,0.654
12.63,65.15,0.656
12.65,65.32,0.658
12.67,65.48,0.660
12.68,65.65,0.662
12.70,65.82,0.664
12.72,65.98,0.667
12.73,66.15,0.669
12.75,66.32,0.670
12.77,66.48,0.673
12.78,66.65,0.675
12.80,66.82,0.676
12.82,66.98,0.679
12.83,67.15,0.681
12.85,67.32,0.683
12.87,67.48,0.685
12.88,67.65,0.687
12.90,67.81,0.689
12.92,67.98,0.691
12.93,68.15,0.693
12.95,68.31,0.695
12.97,68.48,0.698
12.98,68.65,0.699
13.00,68.81,0.702
13.02,68.98,0.703
13.03,69.14,0.707
13.05,69.31,0.708
13.07,69.48,0.711
13.08,69.64,0.713
13.10,69.81,0.715
13.12,69.98,0.718
13.13,70.14,0.720
13.15,70.31,0.722
13.17,70.47,0.724
13.18,70.64,0.726
13.20,70.81,0.728
13.22,70.97,0.730
13.23,71.14,0.733
13.25,71.31,0.735
13.27,71.47,0.737
13.28,71.64,0.740
13.30,71.80,0.743
13.32,71.97,0.745
13.33,72.13,0.747
13.35,72.30,0.750
13.37,72.47,0.753
13.38,72.64,0.756
13.40,72.80,0.758
13.42,72.97,0.762
13.43,73.13,0.764
13.45,73.30,0.767
13.47,73.47,0.769
13.48,73.63,0.771
13.50,73.80,0.773
13.52,73.97,0.776
13.53,74.13,0.777
13.55,74.30,0.779
13.57,74.46,0.782
13.58,74.63,0.785
13.60,74.80,0.787
13.62,74.96,0.792
13.63,75.13,0.794
13.65,75.29,0.796
13.67,75.46,0.799
13.68,75.63,0.801
13.70,75.79,0.804
13.72,75.96,0.806
13.73,76.13,0.809
13.75,76.29,0.811
13.77,76.46,0.815
13.78,76.62,0.817
13.80,76.79,0.820
13.82,76.96,0.822
13.83,77.12,0.825
13.85,77.29,0.827
13.87,77.46,0.830
13.88,77.62,0.833
13.90,77.79,0.836
13.92,77.95,0.839
13.93,78.12,0.842
13.95,78.29,0.845
13.97,78.45,0.848
13.98,78.62,0.850
14.00,78.78,0.853
14.02,78.95,0.855
14.03,79.12,0.858
14.05,79.28,0.861
14.07,79.45,0.863
14.08,79.62,0.866
14.10,79.78,0.868
14.12,79.95,0.872
14.13,80.11,0.875
14.15,80.28,0.878
14.17,80.44,0.881
14.18,80.61,0.884
14.20,80.78,0.886
14.22,80.94,0.889
14.23,81.11,0.892
14.25,81.28,0.894
14.27,81.44,0.898
14.28,81.61,0.901
14.30,81.77,0.904
14.32,81.94,0.907
14.33,82.11,0.910
14.35,82.27,0.912
14.37,82.44,0.915
14.38,82.60,0.919
14.40,82.77,0.922
14.42,82.94,0.925
14.43,83.10,0.927
14.45,83.27,0.931
14.47,83.43,0.934
14.48,83.60,0.937
14.50,83.77,0.940
14.52,83.93,0.943
14.53,84.10,0.946
14.55,84.26,0.948
14.57,84.43,0.952
14.58,84.60,0.955
14.60,84.76,0.957
14.62,84.93,0.961
14.63,85.10,0.965
14.65,85.26,0.967
14.67,85.43,0.971
14.68,85.59,0.973
14.70,85.76,0.975
14.72,85.93,0.979
14.73,86.09,0.983
14.75,86.26,0.986
14.77,86.42,0.989
14.78,86.59,0.991
14.80,86.75,0.994
14.82,86.92,0.998
14.83,87.09,1.000
14.85,87.25,1.003
14.87,87.42,1.007
14.88,87.59,1.010
14.90,87.75,1.013
14.92,87.92,1.016
14.93,88.08,1.019
14.95,88.25,1.022
14.97,88.42,1.025
14.98,88.58,1.028
15.00,88.75,1.032
15.02,88.91,1.035
15.03,89.08,1.038
15.05,89.25,1.040
15.07,89.41,1.044
15.08,89.58,1.047
15.10,89.74,1.050
15.12,89.91,1.053
15.13,90.08,1.056
15.15,90.24,1.059
15.17,90.41,1.062
15.18,90.57,1.065
15.20,90.74,1.069
15.22,90.91,1.072
15.23,91.07,1.074
15.25,91.24,1.077
15.27,91.41,1.080
15.28,91.57,1.083
15.30,91.74,1.086
15.32,91.90,1.090
15.33,92.07,1.092
15.35,92.24,1.095
15.37,92.40,1.097
15.38,92.57,1.100
15.40,92.74,1.103
15.42,92.90,1.105
15.43,93.07,1.107
15.45,93.23,1.111
15.47,93.40,1.114
15.48,93.57,1.117
15.50,93.73,1.119
15.52,93.90,1.122
15.53,94.07,1.124
15.55,94.23,1.128
15.57,94.40,1.130
15.58,94.56,1.133
15.60,94.73,1.135
15.62,94.90,1.138
15.63,95.06,1.140
15.65,95.23,1.142
15.67,95.39,1.145
15.68,95.56,1.147
15.70,95.72,1.149
15.72,95.89,1.152
15.73,96.06,1.154
15.75,96.22,1.156
15.77,96.39,1.158
15.78,96.56,1.161
15.80,96.72,1.164
15.82,96.89,1.167
15.83,97.05,1.170
15.85,97.22,1.171
15.87,97.39,1.173
15.88,97.55,1.176
15.90,97.72,1.177
15.92,97.89,1.179
15.93,98.05,1.182
15.95,98.22,1.184
15.97,98.39,1.186
15.98,98.55,1.187
16.00,98.72,1.189
16.02,98.88,1.191
16.03,99.05,1.192
16.05,99.22,1.194
16.07,99.38,1.195
16.08,99.55,1.196
16.10,99.72,1.198
16.12,99.88,1.201
16.13,100.05,1.202
16.15,100.22,1.203
16.17,100.38,1.205
16.18,100.55,1.206
16.20,100.72,1.207
16.22,100.88,1.208
16.23,101.05,1.209
16.25,101.21,1.210
16.27,101.38,1.211
16.28,101.55,1.212
16.30,101.71,1.214
16.32,101.88,1.215
16.33,102.05,1.216
16.35,102.22,1.217
16.37,102.38,1.218
16.38,102.55,1.219
16.40,102.72,1.219
16.42,102.88,1.220
16.43,103.05,1.221
16.45,103.22,1.222
16.47,103.38,1.223
16.48,103.55,1.224
16.50,103.72,1.224
16.52,103.88,1.225
16.53,104.05,1.225
16.55,104.22,1.226
16.57,104.38,1.227
16.58,104.55,1.227
16.60,104.72,1.228
16.62,104.88,1.228
16.63,105.05,1.229
16.65,105.22,1.229
16.67,105.38,1.230
16.68,105.55,1.230
16.70,105.72,1.230
16.72,105.88,1.231
16.73,106.05,1.231
16.75,106.22,1.231
16.77,106.39,1.231
16.78,106.55,1.232
16.80,106.72,1.232
16.82,106.89,1.232
16.83,107.05,1.232
16.85,107.22,1.233
16.87,107.39,1.233
16.88,107.55,1.233
16.90,107.72,1.233
16.92,107.89,1.233
16.93,108.05,1.232
16.95,108.22,1.232
16.97,108.39,1.232
16.98,108.56,1.232
17.00,108.72,1.232
17.02,108.89,1.231
17.03,109.06,1.231
17.05,109.22,1.231
17.07,109.39,1.230
17.08,109.56,1.230
17.10,109.72,1.229
17.12,109.89,1.229
17.13,110.06,1.228
17.15,110.23,1.227
17.17,110.39,1.227
17.18,110.56,1.226
17.20,110.73,1.225
17.22,110.90,1.224
17.23,111.06,1.223
17.25,111.23,1.222
17.27,111.40,1.221
17.28,111.56,1.220
17.30,111.73,1.218
17.32,111.90,1.216
17.33,112.07,1.214
17.35,112.23,1.213
17.37,112.40,1.211
17.38,112.57,1.210
17.40,112.74,1.210
17.42,112.90,1.209
17.43,113.07,1.207
17.45,113.24,1.205
17.47,113.40,1.202
17.48,113.57,1.200
17.50,113.74,1.199
17.52,113.91,1.197
17.53,114.07,1.194
17.55,114.24,1.192
17.57,114.41,1.190
17.58,114.58,1.188
17.60,114.74,1.187
17.62,114.91,1.184
17.63,115.08,1.182
17.65,115.24,1.180
17.67,115.41,1.178
17.68,115.58,1.176
17.70,115.75,1.174
17.72,115.91,1.172
17.73,116.08,1.170
17.75,116.25,1.168
17.77,116.42,1.167
17.78,116.58,1.164
17.80,116.75,1.162
17.82,116.92,1.159
17.83,117.09,1.157
17.85,117.25,1.155
17.87,117.42,1.152
17.88,117.59,1.151
17.90,117.75,1.149
17.92,117.92,1.146
17.93,118.09,1.144
17.95,118.26,1.142
17.97,118.42,1.140
17.98,118.59,1.137
18.00,118.76,1.135
18.02,118.93,1.132
18.03,119.09,1.130
18.05,119.26,1.128
18.07,119.43,1.126
18.08,119.60,1.124
18.10,119.76,1.122
18.12,119.93,1.120
18.13,120.10,1.117
18.15,120.27,1.115
18.17,120.43,1.113
18.18,120.60,1.110
18.20,120.77,1.107
18.22,120.94,1.105
18.23,121.10,1.102
18.25,121.27,1.100
18.27,121.44,1.097
18.28,121.60,1.095
18.30,121.77,1.091
18.32,121.94,1.089
18.33,122.10,1.086
18.35,122.27,1.084
18.37,122.44,1.081
18.38,122.61,1.079
18.40,122.78,1.077
18.42,122.94,1.075
18.43,123.11,1.072
18.45,123.28,1.069
18.47,123.45,1.067
18.48,123.61,1.064
18.50,123.78,1.062
18.52,123.95,1.059
18.53,124.12,1.056
18.55,124.29,1.052
18.57,124.45,1.049
18.58,124.62,1.046
18.60,124.79,1.043
18.62,124.95,1.039
18.63,125.12,1.036
18.65,125.29,1.033
18.67,125.46,1.031
18.68,125.63,1.028
18.70,125.79,1.025
18.72,125.96,1.022
18.73,126.13,1.020
18.75,126.30,1.016
18.77,126.46,1.013
18.78,126.63,1.010
18.80,126.80,1.008
18.82,126.97,1.005
18.83,127.13,1.002
18.85,127.30,0.998
18.87,127.47,0.995
18.88,127.64,0.992
18.90,127.80,0.989
18.92,127.97,0.986
18.93,128.14,0.984
18.95,128.31,0.981
18.97,128.47,0.977
18.98,128.64,0.974
19.00,128.81,0.972
19.02,128.98,0.968
19.03,129.15,0.965
19.05,129.31,0.962
19.07,129.48,0.958
19.08,129.65,0.955
19.10,129.82,0.951
19.12,129.98,0.948
19.13,130.15,0.945
19.15,130.32,0.943
19.17,130.49,0.939
19.18,130.66,0.937
19.20,130.82,0.933
19.22,130.99,0.931
19.23,131.16,0.928
19.25,131.33,0.924
19.27,131.49,0.922
19.28,131.66,0.919
19.30,131.83,0.915
19.32,132.00,0.913
19.33,132.16,0.909
19.35,132.33,0.907
19.37,132.50,0.904
19.38,132.67,0.902
19.40,132.83,0.899
19.42,133.00,0.896
19.43,133.17,0.893
19.45,133.34,0.890
19.47,133.50,0.886
19.48,133.67,0.884
19.50,133.84,0.881
19.52,134.01,0.877
19.53,134.18,0.874
19.55,134.34,0.870
19.57,134.51,0.868
19.58,134.68,0.863
19.60,134.85,0.860
19.62,135.01,0.856
19.63,135.18,0.853
19.65,135.35,0.850
19.67,135.52,0.847
19.68,135.68,0.843
19.70,135.85,0.839
19.72,136.02,0.836
19.73,136.19,0.832
19.75,136.35,0.829
19.77,136.52,0.826
19.78,136.69,0.823
19.80,136.86,0.820
19.82,137.02,0.816
19.83,137.19,0.813
19.85,137.36,0.810
19.87,137.53,0.806
19.88,137.69,0.803
19.90,137.86,0.800
19.92,138.03,0.797
19.93,138.20,0.793
19.95,138.37,0.790
19.97,138.53,0.786
19.98,138.70,0.783
20.00,138.87,0.778
20.02,139.04,0.775
20.03,139.20,0.771
20.05,139.37,0.768
20.07,139.54,0.765
20.08,139.70,0.761
20.10,139.87,0.757
20.12,140.04,0.755
20.13,140.21,0.752
20.15,140.38,0.748
20.17,140.54,0.746
20.18,140.71,0.743
20.20,140.88,0.740
20.22,141.05,0.737
20.23,141.22,0.734
20.25,141.38,0.730
20.27,141.55,0.727
20.28,141.72,0.724
20.30,141.89,0.721
20.32,142.05,0.718
20.33,142.22,0.716
20.35,142.39,0.712
20.37,142.56,0.710
20.38,142.72,0.707
20.40,142.89,0.703
20.42,143.06,0.702
20.43,143.23,0.698
20.45,143.39,0.696
20.47,143.56,0.693
20.48,143.73,0.690
20.50,143.90,0.688
20.52,144.06,0.685
20.53,144.23,0.683
20.55,144.40,0.680
20.57,144.57,0.677
20.58,144.73,0.675
20.60,144.90,0.672
20.62,145.07,0.670
20.63,145.24,0.667
20.65,145.40,0.665
20.67,145.57,0.662
20.68,145.74,0.660
20.70,145.91,0.657
20.72,146.08,0.655
20.73,146.24,0.653
20.75,146.41,0.650
20.77,146.58,0.648
20.78,146.74,0.645
20.80,146.91,0.643
20.82,147.08,0.641
20.83,147.25,0.638
20.85,147.41,0.637
20.87,147.58,0.634
20.88,147.75,0.632
20.90,147.91,0.630
20.92,148.08,0.629
20.93,148.25,0.627
20.95,148.42,0.626
20.97,148.58,0.624
20.98,148.75,0.623
21.00,148.92,0.621
21.02,149.09,0.619
21.03,149.25,0.618
21.05,149.42,0.617
21.07,149.59,0.615
21.08,149.75,0.613
21.10,149.92,0.612
21.12,150.09,0.609
21.13,150.26,0.607
21.15,150.43,0.606
21.17,150.59,0.605
21.18,150.76,0.603
21.20,150.93,0.602
21.22,151.09,0.600
21.23,151.26,0.599
21.25,151.43,0.598
21.27,151.60,0.597
21.28,151.76,0.596
21.30,151.93,0.594
21.32,152.10,0.593
21.33,152.26,0.592
21.35,152.43,0.591
21.37,152.60,0.589
21.38,152.77,0.588
21.40,152.93,0.587
21.42,153.10,0.586
21.43,153.27,0.585
21.45,153.43,0.584
21.47,153.60,0.583
21.48,153.77,0.581
21.50,153.93,0.581
21.52,154.10,0.580
21.53,154.27,0.578
21.55,154.44,0.577
21.57,154.60,0.577
21.58,154.77,0.576
21.60,154.94,0.575
21.62,155.10,0.574
21.63,155.27,0.573
21.65,155.44,0.572
21.67,155.61,0.571
21.68,155.77,0.570
21.70,155.94,0.569
21.72,156.11,0.568
21.73,156.27,0.567
21.75,156.44,0.566
21.77,156.61,0.565
21.78,156.77,0.564
21.80,156.94,0.563
21.82,157.11,0.563
21.83,157.28,0.562
21.85,157.44,0.561
21.87,157.61,0.560
21.88,157.78,0.559
21.90,157.94,0.559
21.92,158.11,0.558
21.93,158.28,0.557
21.95,158.44,0.557
21.97,158.61,0.556
21.98,158.78,0.555
22.00,158.95,0.554
22.02,159.11,0.553
22.03,159.28,0.552
22.05,159.45,0.551
22.07,159.61,0.550
22.08,159.78,0.549
22.10,159.95,0.547
22.12,160.12,0.547
22.13,160.28,0.546
22.15,160.45,0.545
22.17,160.62,0.543
22.18,160.78,0.542
22.20,160.95,0.541
22.22,161.12,0.539
22.23,161.29,0.538
22.25,161.45,0.537
22.27,161.62,0.535
22.28,161.79,0.533
22.30,161.95,0.531
22.32,162.12,0.530
22.33,162.29,0.529
22.35,162.45,0.527
22.37,162.62,0.525
22.38,162.79,0.524
22.40,162.96,0.523
22.42,163.12,0.521
22.43,163.29,0.520
22.45,163.46,0.518
22.47,163.62,0.516
22.48,163.79,0.514
22.50,163.96,0.512
22.52,164.13,0.510
22.53,164.29,0.508
22.55,164.46,0.506
22.57,164.63,0.504
22.58,164.80,0.503
22.60,164.96,0.501
22.62,165.13,0.499
22.63,165.30,0.498
22.65,165.47,0.497
22.67,165.63,0.496
22.68,165.80,0.494
22.70,165.97,0.493
22.72,166.13,0.492
22.73,166.30,0.490
22.75,166.47,0.487
22.77,166.64,0.486
22.78,166.80,0.484
22.80,166.97,0.483
22.82,167.14,0.481
22.83,167.30,0.480
22.85,167.47,0.478
22.87,167.64,0.477
22.88,167.80,0.476
22.90,167.97,0.475
22.92,168.14,0.474
22.93,168.30,0.473
22.95,168.47,0.472
22.97,168.64,0.472
22.98,168.81,0.471
23.00,168.97,0.470
23.02,169.14,0.470
23.03,169.31,0.469
23.05,169.47,0.468
23.07,169.64,0.467
23.08,169.81,0.466
23.10,169.98,0.465
23.12,170.14,0.464
23.13,170.31,0.464
23.15,170.48,0.463
23.17,170.64,0.462
23.18,170.81,0.462
23.20,170.98,0.461
23.22,171.14,0.460
23.23,171.31,0.460
23.25,171.48,0.459
23.27,171.65,0.458
23.28,171.81,0.458
23.30,171.98,0.457
23.32,172.15,0.456
23.33,172.31,0.456
23.35,172.48,0.455
23.37,172.65,0.454
23.38,172.82,0.454
23.40,172.98,0.453
23.42,173.15,0.453
23.43,173.32,0.452
23.45,173.48,0.451
23.47,173.65,0.451
23.48,173.82,0.450
23.50,173.98,0.450
23.52,174.15,0.449
23.53,174.32,0.448
23.55,174.48,0.447
23.57,174.65,0.447
23.58,174.82,0.446
23.60,174.99,0.446
23.62,175.15,0.445
23.63,175.32,0.445
23.65,175.49,0.444
23.67,175.65,0.443
23.68,175.82,0.443
23.70,175.99,0.442
23.72,176.15,0.442
23.73,176.32,0.441
23.75,176.49,0.440
23.77,176.65,0.440
23.78,176.82,0.439
23.80,176.99,0.439
23.82,177.15,0.438
23.83,177.32,0.438
23.85,177.49,0.437
23.87,177.65,0.436
23.88,177.82,0.436
23.90,177.99,0.435
23.92,178.16,0.435
23.93,178.32,0.434
23.95,178.49,
23.97,178.66,
23.98,178.82,
23.99,,

[step]
Ramp 10.00 °C/min to -60.00 °C
Time,Temperature,Heat Flow (Normalized)
min,°C,W/g
25.99,180.15,0.004
26.01,180.15,0.004
26.03,180.15,0.003
26.04,180.14,0.002
26.06,180.12,0.002
26.08,180.08,-0.013
26.09,180.02,-0.047
26.11,179.94,-0.089
26.13,179.84,-0.142
26.14,179.72,-0.193
26.16,179.59,-0.241
26.18,179.45,-0.282
26.19,179.31,-0.314
26.21,179.16,-0.339
26.23,179.00,-0.356
26.24,178.85,-0.368
26.26,178.69,-0.379
26.28,178.53,-0.385
26.29,178.37,-0.390
26.31,178.21,-0.395
26.33,178.05,-0.398
26.34,177.88,-0.401
26.36,177.72,-0.404
26.38,177.56,-0.405
26.39,177.39,-0.407
26.41,177.23,-0.409
26.43,177.06,-0.411
26.44,176.90,-0.411
26.46,176.73,-0.412
26.48,176.57,-0.413
26.49,176.40,-0.413
26.51,176.24,-0.413
26.53,176.07,-0.414
26.54,175.91,-0.414
26.56,175.74,-0.415
26.58,175.58,-0.415
26.59,175.41,-0.416
26.61,175.24,-0.416
26.63,175.08,-0.416
26.64,174.91,-0.417
26.66,174.75,-0.417
26.68,174.58,-0.418
26.69,174.42,-0.418
26.71,174.25,-0.418
26.73,174.08,-0.419
26.74,173.92,-0.419
26.76,173.75,-0.419
26.78,173.59,-0.420
26.79,173.42,-0.420
26.81,173.26,-0.420
26.83,173.09,-0.421
26.84,172.93,-0.421
26.86,172.76,-0.422
26.88,172.59,-0.422
26.89,172.43,-0.422
26.91,172.26,-0.423
26.93,172.09,-0.423
26.94,171.93,-0.423
26.96,171.76,-0.423
26.98,171.60,-0.424
26.99,171.43,-0.424
27.01,171.26,-0.424
27.03,171.10,-0.425
27.04,170.93,-0.425
27.06,170.77,-0.425
27.08,170.60,-0.425
27.09,170.44,-0.425
27.11,170.27,-0.426
27.13,170.10,-0.426
27.14,169.94,-0.426
27.16,169.77,-0.426
27.18,169.60,-0.426
27.19,169.44,-0.427
27.21,169.27,-0.427
27.23,169.10,-0.427
27.24,168.94,-0.427
27.26,168.77,-0.427
27.28,168.61,-0.427
27.29,168.44,-0.428
27.31,168.27,-0.428
27.33,168.11,-0.428
27.34,167.94,-0.428
27.36,167.77,-0.428
27.38,167.61,-0.428
27.39,167.44,-0.428
27.41,167.27,-0.429
27.43,167.11,-0.429
27.44,166.94,-0.429
27.46,166.78,-0.429
27.48,166.61,-0.429
27.49,166.44,-0.429
27.51,166.28,-0.429
27.53,166.11,-0.429
27.54,165.94,-0.429
27.56,165.78,-0.429
27.58,165.61,-0.429
27.59,165.44,-0.430
27.61,165.28,-0.430
27.63,165.11,-0.430
27.64,164.94,-0.430
27.66,164.78,-0.430
27.68,164.61,-0.430
27.69,164.45,-0.430
27.71,164.28,-0.430
27.73,164.11,-0.430
27.74,163.95,-0.430
27.76,163.78,-0.430
27.78,163.61,-0.430
27.79,163.45,-0.430
27.81,163.28,-0.430
27.83,163.11,-0.430
27.84,162.95,-0.430
27.86,162.78,-0.430
27.88,162.61,-0.430
27.89,162.45,-0.430
27.91,162.28,-0.430
27.93,162.11,-0.430
27.94,161.95,-0.430
27.96,161.78,-0.430
27.98,161.61,-0.430
27.99,161.45,-0.430
28.01,161.28,-0.430
28.03,161.11,-0.430
28.04,160.95,-0.430
28.06,160.78,-0.430
28.08,160.61,-0.430
28.09,160.45,-0.430
28.11,160.28,-0.430
28.13,160.11,-0.430
28.14,159.95,-0.430
28.16,159.78,-0.430
28.18,159.62,-0.430
28.19,159.45,-0.430
28.21,159.28,-0.430
28.23,159.11,-0.430
28.24,158.95,-0.430
28.26,158.78,-0.430
28.28,158.62,-0.430
28.29,158.45,-0.430
28.31,158.28,-0.430
28.33,158.12,-0.430
28.34,157.95,-0.430
28.36,157.78,-0.430
28.38,157.62,-0.430
28.39,157.45,-0.430
28.41,157.28,-0.430
28.43,157.12,-0.430
28.44,156.95,-0.430
28.46,156.78,-0.430
28.48,156.62,-0.430
28.49,156.45,-0.430
28.51,156.28,-0.430
28.53,156.12,-0.430
28.54,155.95,-0.430
28.56,155.78,-0.430
28.58,155.62,-0.430
28.59,155.45,-0.430
28.61,155.28,-0.430
28.63,155.12,-0.429
28.64,154.95,-0.429
28.66,154.78,-0.429
28.68,154.62,-0.429
28.69,154.45,-0.429
28.71,154.28,-0.429
28.73,154.12,-0.429
28.74,153.95,-0.429
28.76,153.78,-0.429
28.78,153.62,-0.429
28.79,153.45,-0.429
28.81,153.28,-0.429
28.83,153.12,-0.429
28.84,152.95,-0.429
28.86,152.78,-0.429
28.88,152.62,-0.429
28.89,152.45,-0.429
28.91,152.28,-0.429
28.93,152.12,-0.429
28.94,151.95,-0.429
28.96,151.78,-0.429
28.98,151.62,-0.429
28.99,151.45,-0.429
29.01,151.28,-0.429
29.03,151.12,-0.429
29.04,150.95,-0.428
29.06,150.78,-0.428
29.08,150.62,-0.428
29.09,150.45,-0.428
29.11,150.28,-0.428
29.13,150.12,-0.428
29.14,149.95,-0.428
29.16,149.79,-0.428
29.18,149.62,-0.428
29.19,149.45,-0.428
29.21,149.29,-0.428
29.23,149.12,-0.428
29.24,148.95,-0.428
29.26,148.78,-0.427
29.28,148.62,-0.427
29.29,148.45,-0.427
29.31,148.29,-0.427
29.33,148.12,-0.427
29.34,147.95,-0.427
29.36,147.79,-0.427
29.38,147.62,-0.427
29.39,147.45,-0.427
29.41,147.29,-0.427
29.43,147.12,-0.427
29.44,146.95,-0.427
29.46,146.78,-0.426
29.48,146.62,-0.426
29.49,146.45,-0.426
29.51,146.29,-0.426
29.53,146.12,-0.426
29.54,145.95,-0.426
29.56,145.79,-0.425
29.58,145.62,-0.425
29.59,145.45,-0.425
29.61,145.28,-0.425
29.63,145.12,-0.425
29.64,144.95,-0.425
29.66,144.78,-0.425
29.68,144.62,-0.425
29.69,144.45,-0.424
29.71,144.29,-0.424
29.73,144.12,-0.424
29.74,143.95,-0.424
29.76,143.79,-0.424
29.78,143.62,-0.424
29.79,143.45,-0.423
29.81,143.29,-0.423
29.83,143.12,-0.423
29.84,142.95,-0.423
29.86,142.79,-0.422
29.88,142.62,-0.422
29.89,142.45,-0.422
29.91,142.29,-0.422
29.93,142.12,-0.421
29.94,141.95,-0.421
29.96,141.79,-0.421
29.98,141.62,-0.421
29.99,141.45,-0.421
30.01,141.29,-0.421
30.03,141.12,-0.420
30.04,140.95,-0.420
30.06,140.79,-0.420
30.08,140.62,-0.420
30.09,140.45,-0.420
30.11,140.29,-0.419
30.13,140.12,-0.419
30.14,139.95,-0.419
30.16,139.79,-0.419
30.18,139.62,-0.418
30.19,139.45,-0.418
30.21,139.29,-0.418
30.23,139.12,-0.417
30.24,138.95,-0.417
30.26,138.79,-0.417
30.28,138.62,-0.417
30.29,138.45,-0.416
30.31,138.29,-0.416
30.33,138.12,-0.416
30.34,137.95,-0.415
30.36,137.79,-0.415
30.38,137.62,-0.414
30.39,137.45,-0.414
30.41,137.29,-0.414
30.43,137.12,-0.414
30.44,136.95,-0.413
30.46,136.79,-0.413
30.48,136.62,-0.413
30.49,136.45,-0.412
30.51,136.29,-0.412
30.53,136.12,-0.411
30.54,135.95,-0.411
30.56,135.78,-0.411
30.58,135.62,-0.410
30.59,135.45,-0.410
30.61,135.29,-0.409
30.63,135.12,-0.409
30.64,134.95,-0.409
30.66,134.78,-0.408
30.68,134.62,-0.408
30.69,134.45,-0.407
30.71,134.28,-0.407
30.73,134.12,-0.407
30.74,133.95,-0.406
30.76,133.79,-0.406
30.78,133.62,-0.406
30.79,133.45,-0.405
30.81,133.28,-0.405
30.83,133.12,-0.404
30.84,132.95,-0.404
30.86,132.79,-0.404
30.88,132.62,-0.403
30.89,132.45,-0.403
30.91,132.29,-0.402
30.93,132.12,-0.402
30.94,131.95,-0.402
30.96,131.79,-0.401
30.98,131.62,-0.401
30.99,131.45,-0.400
31.01,131.29,-0.400
31.03,131.12,-0.399
31.04,130.95,-0.399
31.06,130.79,-0.398
31.08,130.62,-0.398
31.09,130.45,-0.398
31.11,130.28,-0.397
31.13,130.12,-0.397
31.14,129.95,-0.397
31.16,129.78,-0.396
31.18,129.62,-0.396
31.19,129.45,-0.395
31.21,129.28,-0.395
31.23,129.12,-0.395
31.24,128.95,-0.394
31.26,128.78,-0.394
31.28,128.62,-0.394
31.29,128.45,-0.393
31.31,128.28,-0.393
31.33,128.12,-0.392
31.34,127.95,-0.392
31.36,127.78,-0.392
31.38,127.62,-0.391
31.39,127.45,-0.391
31.41,127.28,-0.390
31.43,127.12,-0.390
31.44,126.95,-0.390
31.46,126.78,-0.389
31.48,126.62,-0.389
31.49,126.45,-0.389
31.51,126.28,-0.388
31.53,126.12,-0.388
31.54,125.95,-0.388
31.56,125.79,-0.387
31.58,125.62,-0.387
31.59,125.45,-0.387
31.61,125.28,-0.386
31.63,125.12,-0.386
31.64,124.95,-0.386
31.66,124.78,-0.385
31.68,124.62,-0.385
31.69,124.45,-0.385
31.71,124.28,-0.385
31.73,124.12,-0.384
31.74,123.95,-0.384
31.76,123.78,-0.384
31.78,123.62,-0.383
31.79,123.45,-0.383
31.81,123.28,-0.383
31.83,123.12,-0.382
31.84,122.95,-0.382
31.86,122.78,-0.382
31.88,122.62,-0.381
31.89,122.45,-0.381
31.91,122.28,-0.381
31.93,122.12,-0.380
31.94,121.95,-0.380
31.96,121.78,-0.380
31.98,121.61,-0.380
31.99,121.45,-0.379
32.01,121.28,-0.379
32.03,121.11,-0.379
32.04,120.95,-0.378
32.06,120.78,-0.378
32.08,120.62,-0.378
32.09,120.45,-0.377
32.11,120.28,-0.377
32.13,120.12,-0.377
32.14,119.95,-0.376
32.16,119.78,-0.376
32.18,119.62,-0.376
32.19,119.45,-0.376
32.21,119.28,-0.375
32.23,119.12,-0.375
32.24,118.95,-0.375
32.26,118.78,-0.375
32.28,118.62,-0.374
32.29,118.45,-0.374
32.31,118.28,-0.374
32.33,118.12,-0.374
32.34,117.95,-0.373
32.36,117.78,-0.373
32.38,117.62,-0.373
32.39,117.45,-0.373
32.41,117.28,-0.373
[...]
110.85,7.23,0.215
110.86,7.40,0.215
110.88,7.57,0.215
110.90,7.73,0.215
110.91,7.90,0.215
110.93,8.07,0.215
110.95,8.23,0.215
110.96,8.40,0.216
110.98,8.57,0.216
111.00,8.73,0.216
111.01,8.90,0.216
111.03,9.07,0.216
111.05,9.24,0.216
111.06,9.40,0.216
111.08,9.57,0.216
111.10,9.74,0.216
111.11,9.90,0.216
111.13,10.07,0.217
111.15,10.24,0.217
111.16,10.40,0.217
111.18,10.57,0.217
111.20,10.74,0.217
111.21,10.90,0.217
111.23,11.07,0.217
111.25,11.24,0.217
111.26,11.40,0.217
111.28,11.57,0.217
111.30,11.74,0.217
111.31,11.90,0.217
111.33,12.07,0.217
111.35,12.24,0.218
111.36,12.40,0.218
111.38,12.57,0.218
111.40,12.74,0.218
111.41,12.91,0.218
111.43,13.07,0.218
111.45,13.24,0.218
111.46,13.41,0.218
111.48,13.57,0.218
111.50,13.74,0.218
111.51,13.91,0.218
111.53,14.07,0.219
111.55,14.24,0.219
111.56,14.41,0.219
111.58,14.57,0.219
111.60,14.74,0.219
111.61,14.91,0.219
111.63,15.07,0.219
111.65,15.24,0.219
111.66,15.41,0.219
111.68,15.57,0.219
111.70,15.74,0.219
111.71,15.91,0.219
111.73,16.07,0.219
111.75,16.24,0.219
111.76,16.41,0.220
111.78,16.57,0.220
111.80,16.74,0.220
111.81,16.91,0.220
111.83,17.07,0.220
111.85,17.24,0.220
111.86,17.41,0.220
111.88,17.57,0.220
111.90,17.74,0.220
111.91,17.91,0.220
111.93,18.07,0.220
111.95,18.24,0.221
111.96,18.41,0.221
111.98,18.58,0.221
112.00,18.74,0.221
112.01,18.91,0.221
112.03,19.07,0.221
112.05,19.24,0.221
112.06,19.41,0.221
112.08,19.58,0.221
112.10,19.74,0.221
112.11,19.91,0.221
112.13,20.08,0.221
112.15,20.24,0.222
112.16,20.41,0.222
112.18,20.58,0.222
112.20,20.74,0.222
112.21,20.91,0.222
112.23,21.08,0.222
112.25,21.24,0.222
112.26,21.41,0.222
112.28,21.58,0.222
112.30,21.74,0.222
112.31,21.91,0.222
112.33,22.08,0.223
112.35,22.25,0.223
112.36,22.41,0.223
112.38,22.58,0.223
112.40,22.75,0.223
112.41,22.91,0.223
112.43,23.08,0.223
112.45,23.25,0.223
112.46,23.41,0.224
112.48,23.58,0.224
112.50,23.75,0.224
112.51,23.91,0.224
112.53,24.08,0.224
112.55,24.25,0.224
112.56,24.41,0.224
112.58,24.58,0.224
112.60,24.75,0.224
112.61,24.92,0.224
112.63,25.08,0.224
112.65,25.25,0.224
112.66,25.42,0.225
112.68,25.58,0.225
112.70,25.75,0.225
112.71,25.92,0.225
112.73,26.08,0.225
112.75,26.25,0.225
112.76,26.42,0.225
112.78,26.58,0.225
112.80,26.75,0.225
112.81,26.92,0.225
112.83,27.09,0.225
112.85,27.25,0.226
112.86,27.42,0.226
112.88,27.59,0.226
112.90,27.75,0.226
112.91,27.92,0.226
112.93,28.09,0.226
112.95,28.25,0.226
112.96,28.42,0.226
112.98,28.59,0.226
113.00,28.75,0.226
113.01,28.92,0.226
113.03,29.09,0.227
113.05,29.26,0.227
113.06,29.42,0.227
113.08,29.59,0.227
113.10,29.75,0.227
113.11,29.92,0.227
113.13,30.09,0.227
113.15,30.26,0.227
113.16,30.42,0.227
113.18,30.59,0.227
113.20,30.76,0.227
113.21,30.92,0.227
113.23,31.09,0.228
113.25,31.26,0.228
113.26,31.42,0.228
113.28,31.59,0.228
113.30,31.76,0.228
113.31,31.92,0.228
113.33,32.09,0.228
113.35,32.26,0.228
113.36,32.42,0.228
113.38,32.59,0.228
113.40,32.76,0.228
113.41,32.92,0.228
113.43,33.09,0.229
113.45,33.26,0.229
113.46,33.42,0.229
113.48,33.59,0.229
113.50,33.76,0.229
113.51,33.93,0.229
113.53,34.09,0.229
113.55,34.26,0.229
113.56,34.43,0.229
113.58,34.59,0.229
113.60,34.76,0.229
113.61,34.93,0.230
113.63,35.09,0.230
113.65,35.26,0.230
113.66,35.43,0.230
113.68,35.59,0.230
113.70,35.76,0.230
113.71,35.93,0.230
113.73,36.09,0.230
113.75,36.26,0.230
113.76,36.43,0.230
113.78,36.59,0.230
113.80,36.76,0.231
113.81,36.93,0.231
113.83,37.10,0.231
113.85,37.26,0.231
113.86,37.43,0.231
113.88,37.60,0.231
113.90,37.76,0.231
113.91,37.93,0.231
113.93,38.10,0.231
113.95,38.26,0.231
113.96,38.43,0.231
113.98,38.60,0.231
114.00,38.76,0.231
114.01,38.93,0.232
114.03,39.10,0.232
114.05,39.26,0.232
114.06,39.43,0.232
114.08,39.60,0.232
114.10,39.76,0.232
114.11,39.93,0.232
114.13,40.10,0.232
114.15,40.27,0.232
114.16,40.43,0.232
114.18,40.60,0.232
114.20,40.77,0.233
114.21,40.93,0.233
114.23,41.10,0.233
114.25,41.27,0.233
114.26,41.43,0.233
114.28,41.60,0.233
114.30,41.77,0.233
114.31,41.93,0.233
114.33,42.10,0.233
114.35,42.27,0.233
114.36,42.43,0.234
114.38,42.60,0.234
114.40,42.77,0.234
114.41,42.94,0.234
114.43,43.10,0.234
114.45,43.27,0.234
114.46,43.44,0.234
114.48,43.60,0.234
114.50,43.77,0.234
114.51,43.94,0.234
114.53,44.10,0.234
114.55,44.27,0.235
114.56,44.44,0.235
114.58,44.60,0.235
114.60,44.77,0.235
114.61,44.94,0.235
114.63,45.10,0.235
114.65,45.27,0.235
114.66,45.44,0.235
114.68,45.60,0.235
114.70,45.77,0.235
114.71,45.94,0.235
114.73,46.11,0.235
114.75,46.27,0.236
114.76,46.44,0.236
114.78,46.61,0.236
114.80,46.77,0.236
114.81,46.94,0.236
114.83,47.11,0.236
114.85,47.27,0.236
114.86,47.44,0.236
114.88,47.61,0.236
114.90,47.77,0.236
114.91,47.94,0.236
114.93,48.11,0.237
114.95,48.27,0.237
114.96,48.44,0.237
114.98,48.61,0.237
115.00,48.77,0.237
115.01,48.94,0.237
115.03,49.11,0.237
115.05,49.27,0.237
115.06,49.44,0.237
115.08,49.61,0.237
115.10,49.78,0.237
115.11,49.94,0.238
115.13,50.11,0.238
115.15,50.28,0.238
115.16,50.44,0.238
115.18,50.61,0.238
115.20,50.78,0.238
115.21,50.94,0.238
115.23,51.11,0.238
115.25,51.28,0.238
115.26,51.44,0.238
115.28,51.61,0.238
115.30,51.78,0.239
115.31,51.94,0.239
115.33,52.11,0.239
115.35,52.28,0.239
115.36,52.44,0.239
115.38,52.61,0.239
115.40,52.78,0.239
115.41,52.94,0.239
115.43,53.11,0.239
115.45,53.28,0.239
115.46,53.45,0.239
115.48,53.61,0.240
115.50,53.78,0.240
115.51,53.95,0.240
115.53,54.11,0.240
115.55,54.28,0.240
115.56,54.45,0.240
115.58,54.61,0.240
115.60,54.78,0.240
115.61,54.95,0.240
115.63,55.11,0.240
115.65,55.28,0.241
115.66,55.45,0.241
115.68,55.61,0.241
115.70,55.78,0.241
115.71,55.95,0.241
115.73,56.11,0.241
115.75,56.28,0.241
115.76,56.45,0.241
115.78,56.61,0.241
115.80,56.78,0.241
115.81,56.95,0.241
115.83,57.11,0.241
115.85,57.28,0.242
115.86,57.45,0.242
115.88,57.62,0.242
115.90,57.78,0.242
115.91,57.95,0.242
115.93,58.11,0.242
115.95,58.28,0.242
115.96,58.45,0.242
115.98,58.62,0.242
116.00,58.78,0.242
116.01,58.95,0.242
116.03,59.12,0.242
116.05,59.28,0.243
116.06,59.45,0.243
116.08,59.62,0.243
116.10,59.78,0.243
116.11,59.95,0.243
116.13,60.12,0.243
116.15,60.28,0.243
116.16,60.45,0.243
116.18,60.62,0.243
116.20,60.78,0.244
116.21,60.95,0.244
116.23,61.12,0.244
116.25,61.29,0.244
116.26,61.45,0.244
116.28,61.62,0.244
116.30,61.79,0.244
116.31,61.95,0.244
116.33,62.12,0.244
116.35,62.29,0.244
116.36,62.45,0.244
116.38,62.62,0.245
116.40,62.79,0.245
116.41,62.96,0.245
116.43,63.12,0.245
116.45,63.29,0.245
116.46,63.45,0.245
116.48,63.62,0.245
116.50,63.79,0.245
116.51,63.95,0.245
116.53,64.12,0.245
116.55,64.29,0.246
116.56,64.45,0.246
116.58,64.62,0.246
116.60,64.79,0.246
116.61,64.96,0.246
116.63,65.12,0.246
116.65,65.29,0.246
116.66,65.46,0.246
116.68,65.62,0.246
116.70,65.79,0.246
116.71,65.96,0.246
116.73,66.12,0.247
116.75,66.29,0.247
116.76,66.46,0.247
116.78,66.62,0.247
116.80,66.79,0.247
116.81,66.96,0.247
116.83,67.12,0.247
116.85,67.29,0.247
116.86,67.46,0.247
116.88,67.62,0.247
116.90,67.79,0.247
116.91,67.96,0.248
116.93,68.12,0.248
116.95,68.29,0.248
116.96,68.46,0.248
116.98,68.62,0.248
117.00,68.79,0.248
117.01,68.96,0.248
117.03,69.12,0.248
117.05,69.29,0.248
117.06,69.46,0.248
117.08,69.63,0.248
117.10,69.79,0.249
117.11,69.96,0.249
117.13,70.13,0.249
117.15,70.29,0.249
117.16,70.46,0.249
117.18,70.63,0.249
117.20,70.79,0.249
117.21,70.96,0.249
117.23,71.13,0.250
117.25,71.29,0.250
117.26,71.46,0.250
117.28,71.63,0.250
117.30,71.80,0.250
117.31,71.96,0.250
117.33,72.13,0.250
117.35,72.30,0.250
117.36,72.46,0.250
117.38,72.63,0.250
117.40,72.80,0.251
117.41,72.96,0.251
117.43,73.13,0.251
117.45,73.30,0.251
117.46,73.46,0.251
117.48,73.63,0.251
117.50,73.80,0.251
117.51,73.96,0.251
117.53,74.13,0.251
117.55,74.30,0.251
117.56,74.46,0.251
117.58,74.63,0.252
117.60,74.80,0.252
117.61,74.96,0.252
117.63,75.13,0.252
117.65,75.30,0.252
117.66,75.46,0.252
117.68,75.63,0.252
117.70,75.80,0.252
117.71,75.96,0.252
117.73,76.13,0.252
117.75,76.30,0.253
117.76,76.47,0.253
117.78,76.63,0.253
117.80,76.80,0.253
117.81,76.97,0.253
117.83,77.13,0.253
117.85,77.30,0.253
117.86,77.47,0.253
117.88,77.63,0.253
117.90,77.80,0.253
117.91,77.97,0.253
117.93,78.13,0.254
117.95,78.30,0.254
117.96,78.47,0.254
117.98,78.63,0.254
118.00,78.80,0.254
118.01,78.97,0.254
118.03,79.13,0.254
118.05,79.30,0.254
118.06,79.47,0.254
118.08,79.64,0.254
118.10,79.80,0.254
118.11,79.97,0.254
118.13,80.14,0.255
118.15,80.30,0.255
118.16,80.47,0.255
118.18,80.64,0.255
118.20,80.80,0.255
118.21,80.97,0.255
118.23,81.14,0.255
118.25,81.30,0.255
118.26,81.47,0.255
118.28,81.64,0.255
118.30,81.80,0.255
118.31,81.97,0.256
118.33,82.13,0.256
118.35,82.30,0.256
118.36,82.47,0.256
118.38,82.64,0.256
118.40,82.80,0.256
118.41,82.97,0.256
118.43,83.14,0.256
118.45,83.30,0.256
118.46,83.47,0.256
118.48,83.64,0.256
118.50,83.80,0.257
118.51,83.97,0.257
118.53,84.14,0.257
118.55,84.31,0.257
118.56,84.47,0.257
118.58,84.64,0.257
118.60,84.81,0.257
118.61,84.97,0.257
118.63,85.14,0.257
118.65,85.31,0.257
118.66,85.47,0.257
118.68,85.64,0.258
118.70,85.81,0.258
118.71,85.97,0.258
118.73,86.14,0.258
118.75,86.31,0.258
118.76,86.47,0.258
118.78,86.64,0.258
118.80,86.81,0.258
118.81,86.97,0.258
118.83,87.14,0.258
118.85,87.31,0.258
118.86,87.47,0.259
118.88,87.64,0.259
118.90,87.81,0.259
118.91,87.98,0.259
118.93,88.14,0.259
118.95,88.31,0.259
118.96,88.48,0.259
118.98,88.64,0.259
119.00,88.81,0.259
119.01,88.98,0.259
119.03,89.14,0.260
119.05,89.31,0.260
119.06,89.48,0.260
119.08,89.64,0.260
119.10,89.81,0.260
119.11,89.98,0.260
119.13,90.14,0.260
119.15,90.31,0.260
119.16,90.48,0.260
119.18,90.64,0.261
119.20,90.81,0.261
119.21,90.98,0.261
119.23,91.14,0.261
119.25,91.31,0.261
119.26,91.48,0.261
119.28,91.65,0.261
119.30,91.81,0.261
119.31,91.98,0.261
119.33,92.15,0.261
119.35,92.31,0.261
119.36,92.48,0.262
119.38,92.65,0.262
119.40,92.81,0.262
119.41,92.98,0.262
119.43,93.15,0.262
119.45,93.31,0.262
119.46,93.48,0.262
119.48,93.65,0.262
119.50,93.81,0.262
119.51,93.98,0.262
119.53,94.15,0.263
119.55,94.31,0.263
119.56,94.48,0.263
119.58,94.65,0.263
119.60,94.81,0.263
119.61,94.98,0.263
119.63,95.15,0.263
119.65,95.31,0.263
119.66,95.48,0.263
119.68,95.65,0.263
119.70,95.81,0.264
119.71,95.98,0.264
119.73,96.15,0.264
119.75,96.32,0.264
119.76,96.48,0.264
119.78,96.65,0.264
119.80,96.82,0.264
119.81,96.98,0.264
119.83,97.15,0.265
119.85,97.32,0.265
119.86,97.48,0.265
119.88,97.65,0.265
119.90,97.82,0.265
119.91,97.98,0.265
119.93,98.15,0.265
119.95,98.32,0.265
119.96,98.48,0.265
119.98,98.65,0.266
120.00,98.82,0.266
120.01,98.99,0.266
120.03,99.15,0.266
120.05,99.32,0.266
120.06,99.48,0.266
120.08,99.65,0.266
120.10,99.82,0.266
120.11,99.99,0.266
120.13,100.15,0.267
120.15,100.32,0.267
120.16,100.49,0.267
120.18,100.65,0.267
120.20,100.82,0.267
120.21,100.99,0.267
120.23,101.15,0.267
120.25,101.32,0.267
120.26,101.49,0.268
120.28,101.65,0.268
120.30,101.82,0.268
120.31,101.99,0.268
120.33,102.15,0.268
120.35,102.32,0.268
120.36,102.49,0.268
120.38,102.65,0.268
120.40,102.82,0.268
120.41,102.99,0.268
120.43,103.15,0.269
120.45,103.32,0.269
120.46,103.49,0.269
120.48,103.65,0.269
120.50,103.82,0.269
120.51,103.99,0.269
120.53,104.16,0.269
120.55,104.32,0.269
120.56,104.49,0.270
120.58,104.66,0.270
120.60,104.82,0.270
120.61,104.99,0.270
120.63,105.16,0.270
120.65,105.32,0.270
120.66,105.49,0.270
120.68,105.66,0.270
120.70,105.83,0.271
120.71,105.99,0.271
120.73,106.16,0.271
120.75,106.33,0.271
120.76,106.49,0.271
120.78,106.66,0.271
120.80,106.83,0.271
120.81,106.99,0.271
120.83,107.16,0.271
120.85,107.33,0.271
120.86,107.49,0.272
120.88,107.66,0.272
120.90,107.83,0.272
120.91,107.99,0.272
120.93,108.16,0.272
120.95,108.33,0.272
120.96,108.49,0.272
120.98,108.66,0.272
121.00,108.83,0.272
121.01,108.99,0.272
121.03,109.16,0.273
121.05,109.33,0.273
121.06,109.49,0.273
121.08,109.66,0.273
121.10,109.83,0.273
121.11,109.99,0.273
121.13,110.16,0.273
121.15,110.33,0.273
121.16,110.49,0.274
121.18,110.66,0.274
121.20,110.83,0.274
121.21,110.99,0.274
121.23,111.16,0.274
121.25,111.33,0.274
121.26,111.50,0.274
121.28,111.66,0.274
121.30,111.83,0.274
121.31,111.99,0.275
121.33,112.16,0.275
121.35,112.33,0.275
121.36,112.50,0.275
121.38,112.66,0.275
121.40,112.83,0.275
121.41,113.00,0.275
121.43,113.16,0.276
121.45,113.33,0.276
121.46,113.50,0.276
121.48,113.66,0.276
121.50,113.83,0.276
121.51,114.00,0.276
121.53,114.16,0.276
121.55,114.33,0.276
121.56,114.50,0.277
121.58,114.66,0.277
121.60,114.83,0.277
121.61,114.99,0.277
121.63,115.16,0.277
121.65,115.33,0.277
121.66,115.50,0.277
121.68,115.66,0.277
121.70,115.83,0.278
121.71,116.00,0.278
121.73,116.16,0.278
121.75,116.33,0.278
121.76,116.50,0.278
121.78,116.66,0.278
121.80,116.83,0.278
121.81,117.00,0.279
121.83,117.16,0.279
121.85,117.33,0.279
121.86,117.50,0.279
121.88,117.66,0.279
121.90,117.83,0.279
121.91,118.00,0.279
121.93,118.17,0.280
121.95,118.33,0.280
121.96,118.50,0.280
121.98,118.67,0.280
122.00,118.83,0.280
122.01,119.00,0.280
122.03,119.17,0.281
122.05,119.33,0.281
122.06,119.50,0.281
122.08,119.67,0.281
122.10,119.83,0.281
122.11,120.00,0.281
122.13,120.16,0.281
122.15,120.33,0.281
122.16,120.50,0.281
122.18,120.66,0.282
122.20,120.83,0.282
122.21,121.00,0.282
122.23,121.17,0.282
122.25,121.33,0.282
122.26,121.50,0.282
122.28,121.67,0.282
122.30,121.83,0.283
122.31,122.00,0.283
122.33,122.17,0.283
122.35,122.33,0.283
122.36,122.50,0.283
122.38,122.67,0.284
122.40,122.83,0.284
122.41,123.00,0.284
122.43,123.17,0.284
122.45,123.34,0.284
122.46,123.50,0.284
122.48,123.67,0.285
122.50,123.84,0.285
122.51,124.00,0.285
122.53,124.17,0.285
122.55,124.34,0.285
122.56,124.50,0.285
122.58,124.67,0.286
122.60,124.84,0.286
122.61,125.00,0.286
122.63,125.17,0.286
122.65,125.33,0.286
122.66,125.50,0.287
122.68,125.67,0.287
122.70,125.84,0.287
122.71,126.00,0.287
122.73,126.17,0.287
122.75,126.34,0.288
122.76,126.50,0.288
122.78,126.67,0.288
122.80,126.84,0.289
122.81,127.01,0.289
122.83,127.18,0.290
122.85,127.35,0.291
122.86,127.52,0.291
122.88,127.69,0.292
122.90,127.85,0.292
122.91,128.02,0.292
122.93,128.18,0.292
122.95,128.35,0.293
122.96,128.52,0.293
122.98,128.68,0.293
123.00,128.85,0.293
123.01,129.02,0.293
123.03,129.18,0.293
123.05,129.35,0.293
123.06,129.51,0.293
123.08,129.68,0.293
123.10,129.85,0.294
123.11,130.01,0.294
123.13,130.18,0.294
123.15,130.34,0.294
123.16,130.51,0.294
123.18,130.68,0.294
123.20,130.84,0.295
123.21,131.01,0.295
123.23,131.18,0.295
123.25,131.34,0.296
123.26,131.51,0.296
123.28,131.68,0.296
123.30,131.84,0.296
123.31,132.01,0.297
123.33,132.18,0.297
123.35,132.34,0.297
123.36,132.51,0.298
123.38,132.67,0.298
123.40,132.84,0.299
123.41,133.01,0.299
123.43,133.17,0.299
123.45,133.34,0.300
123.46,133.51,0.301
123.48,133.68,0.301
123.50,133.84,0.302
123.51,134.01,0.302
123.53,134.18,0.303
123.55,134.34,0.303
123.56,134.51,0.303
123.58,134.68,0.304
123.60,134.84,0.304
123.61,135.01,0.305
123.63,135.18,0.305
123.65,135.34,0.306
123.66,135.51,0.307
123.68,135.68,0.307
123.70,135.84,0.308
123.71,136.01,0.308
123.73,136.17,0.309
123.75,136.34,0.309
123.76,136.51,0.310
123.78,136.67,0.310
123.80,136.84,0.311
123.81,137.01,0.311
123.83,137.17,0.312
123.85,137.34,0.313
123.86,137.51,0.313
123.88,137.67,0.314
123.90,137.84,0.315
123.91,138.01,0.316
123.93,138.17,0.317
123.95,138.34,0.317
123.96,138.51,0.318
123.98,138.67,0.319
124.00,138.84,0.320
124.01,139.01,0.320
124.03,139.17,0.321
124.05,139.34,0.322
124.06,139.50,0.323
124.08,139.67,0.323
124.10,139.84,0.324
124.11,140.00,0.325
124.13,140.17,0.326
124.15,140.34,0.326
124.16,140.50,0.327
124.18,140.67,0.328
124.20,140.84,0.328
124.21,141.00,0.329
124.23,141.17,0.330
124.25,141.34,0.331
124.26,141.50,0.331
124.28,141.67,0.332
124.30,141.84,0.333
124.31,142.00,0.333
124.33,142.17,0.334
124.35,142.34,0.334
124.36,142.51,0.335
124.38,142.67,0.335
124.40,142.84,0.336
124.41,143.01,0.336
124.43,143.17,0.337
124.45,143.34,0.337
124.46,143.51,0.338
124.48,143.67,0.338
124.50,143.84,0.339
124.51,144.01,0.339
124.53,144.17,0.339
124.55,144.34,0.340
124.56,144.51,0.340
124.58,144.67,0.340
124.60,144.84,0.341
124.61,145.01,0.341
124.63,145.17,0.341
124.65,145.34,0.341
124.66,145.51,0.342
124.68,145.67,0.342
124.70,145.84,0.342
124.71,146.01,0.342
124.73,146.17,0.342
124.75,146.34,0.342
124.76,146.51,0.343
124.78,146.67,0.343
124.80,146.84,0.343
124.81,147.01,0.343
124.83,147.17,0.343
124.85,147.34,0.343
124.86,147.51,0.343
124.88,147.67,0.343
124.90,147.84,0.343
124.91,148.01,0.343
124.93,148.17,0.343
124.95,148.34,0.343
124.96,148.51,0.343
124.98,148.68,0.343
125.00,148.84,0.343
125.01,149.01,0.343
125.03,149.18,0.343
125.05,149.34,0.343
125.06,149.51,0.343
125.08,149.68,0.343
125.10,149.84,0.343
125.11,150.01,0.343
125.13,150.18,0.343
125.15,150.34,0.343
125.16,150.51,0.343
125.18,150.68,0.343
125.20,150.84,0.343
125.21,151.01,0.343
125.23,151.18,0.343
125.25,151.34,0.342
125.26,151.51,0.342
125.28,151.68,0.342
125.30,151.84,0.342
125.31,152.01,0.342
125.33,152.18,0.342
125.35,152.35,0.342
125.36,152.51,0.342
125.38,152.68,0.342
125.40,152.85,0.342
125.41,153.01,0.342
125.43,153.18,0.342
125.45,153.35,0.342
125.46,153.51,0.342
125.48,153.68,0.342
125.50,153.85,0.342
125.51,154.01,0.342
125.53,154.18,0.342
125.55,154.35,0.342
125.56,154.51,0.342
125.58,154.68,0.342
125.60,154.85,0.342
125.61,155.02,0.342
125.63,155.18,0.342
125.65,155.35,0.342
125.66,155.51,0.342
125.68,155.68,0.342
125.70,155.85,0.342
125.71,156.01,0.342
125.73,156.18,0.342
125.75,156.35,0.342
125.76,156.52,0.342
125.78,156.68,0.343
125.80,156.85,0.343
125.81,157.02,0.343
125.83,157.18,0.343
125.85,157.35,0.343
125.86,157.52,0.343
125.88,157.68,0.343
125.90,157.85,0.343
125.91,158.02,0.343
125.93,158.18,0.343
125.95,158.35,0.343
125.96,158.52,0.343
125.98,158.68,0.343
126.00,158.85,0.343
126.01,159.02,0.343
126.03,159.18,0.343
126.05,159.35,0.343
126.06,159.52,0.343
126.08,159.68,0.343
126.10,159.85,0.343
126.11,160.02,0.343
126.13,160.19,0.344
126.15,160.35,0.344
126.16,160.52,0.344
126.18,160.69,0.344
126.20,160.85,0.344
126.21,161.02,0.344
126.23,161.19,0.344
126.25,161.35,0.344
126.26,161.52,0.344
126.28,161.69,0.344
126.30,161.86,0.344
126.31,162.02,0.344
126.33,162.19,0.344
126.35,162.36,0.344
126.36,162.52,0.344
126.38,162.69,0.345
126.40,162.85,0.345
126.41,163.02,0.345
126.43,163.19,0.345
126.45,163.35,0.345
126.46,163.52,0.345
126.48,163.69,0.345
126.50,163.85,0.345
126.51,164.02,0.345
126.53,164.19,0.345
126.55,164.35,0.345
126.56,164.52,0.345
126.58,164.69,0.345
126.60,164.86,0.345
126.61,165.02,0.345
126.63,165.19,0.345
126.65,165.36,0.346
126.66,165.52,0.346
126.68,165.69,0.346
126.70,165.86,0.346
126.71,166.02,0.346
126.73,166.19,0.346
126.75,166.36,0.346
126.76,166.52,0.346
126.78,166.69,0.346
126.80,166.86,0.346
126.81,167.02,0.346
126.83,167.19,0.347
126.85,167.36,0.347
126.86,167.52,0.347
126.88,167.69,0.347
126.90,167.86,0.347
126.91,168.02,0.347
126.93,168.19,0.347
126.95,168.36,0.347
126.96,168.52,0.347
126.98,168.69,0.347
127.00,168.86,0.347
127.01,169.02,0.347
127.03,169.19,0.347
127.05,169.36,0.348
127.06,169.53,0.348
127.08,169.69,0.348
127.10,169.86,0.348
127.11,170.03,0.348
127.13,170.19,0.348
127.15,170.36,0.348
127.16,170.53,0.348
127.18,170.69,0.348
127.20,170.86,0.348
127.21,171.03,0.348
127.23,171.19,0.348
127.25,171.36,0.349
127.26,171.53,0.349
127.28,171.69,0.349
127.30,171.86,0.349
127.31,172.03,0.349
127.33,172.19,0.349
127.35,172.36,0.349
127.36,172.53,0.349
127.38,172.69,0.349
127.40,172.86,0.349
127.41,173.03,0.349
127.43,173.19,0.349
127.45,173.36,0.349
127.46,173.53,0.349
127.48,173.69,0.350
127.50,173.86,0.350
127.51,174.03,0.350
127.53,174.19,0.350
127.55,174.36,0.350
127.56,174.53,0.350
127.58,174.69,0.350
127.60,174.86,0.350
127.61,175.03,0.350
127.63,175.20,0.350
127.65,175.36,0.350
127.66,175.53,0.350
127.68,175.69,0.351
127.70,175.86,0.351
127.71,176.03,0.351
127.73,176.19,0.351
127.75,176.36,0.351
127.76,176.53,0.351
127.78,176.70,0.351
127.80,176.86,0.351
127.81,177.03,0.351
127.83,177.20,0.351
127.85,177.36,0.351
127.86,177.53,0.351
127.88,177.70,0.352
127.90,177.86,0.352
127.91,178.03,0.352
127.93,178.20,0.352
127.95,178.36,
127.96,178.53,
127.98,178.70,
127.99,,