File: DSC/Olivia/2025_08_09_1CBN_3PVP29_MeOH_ASD_n60C_200C_10Cmin_x3.csv
Filename,2025_08_09_1CBN_3PVP29_MeOH_ASD_n60C_200C_10Cmin_x3
Instrument name,DSC2A-00468 (192.168.1.100)
Operator,Yarger
rundate,8/10/2025
Sample name,2025_08_09_1CBN_3PVP29_MeOH_ASD_n60C_200C_10Cmin_x3
proceduresegments,Data Off ; Equilibrate -60.00 °C; Data On ; Ramp 10.00 °C/min to 200.00 °C; Data Off ; Isothermal 2.0 min; Data On ; Ramp 10.00 °C/min to -60.00 °C; Data Off ; Isothermal 2.0 min; Data On ; Ramp 10.00 °C/min to 200.00 °C; Data Off ; Isothermal 2.0 min; Data On ; Ramp 10.00 °C/min to -60.00 °C; Data Off ; Isothermal 2.0 min; Data On ; Ramp 10.00 °C/min to 200.00 °C
[File Parameters]
Run date,8/10/2025 5:34:58 AM
Trios version,5.1.1.46572
Original File Name,
Current File Name,D:\DSC2500\JYarger\2025_08_09_1CBN_3PVP29_MeOH_ASD_n60C_200C_10Cmin_x3.tri
[Procedure]
Procedure Name,CBN_PVP_TS_n60C_200C_10Cmin_x3
Sample Name,2025_08_09_1CBN_3PVP29_MeOH_ASD_n60C_200C_10Cmin_x3
Sample Mass,32.29 mg
Reference Sample Mass,0 mg
Pan Mass,6.02 mg
Pan Number,13
Reference Pan Mass,32.42 mg
Reference Pan Number,10
Pan Type,Aluminum
Comments,Thermal support Al pans/lids. DSC_Samples_A2_Tray_August2025 google sheet.
Project Name,Pharma
Operator,Yarger
Test,Custom
Unload Max Temperature,30
Unload Min Temperature,30
Load Max Temperature,30
Load Min Temperature,30
Stop on Gas Flow Error,Yes
[Signal List]
Signal #1,Time (min)
Signal #2,Temperature (°C)
Signal #3,Heat Flow (mW)
Signal #4,Delta T (µV)
Signal #5,Delta Tzero (µV)
Signal #6,Tzero Temperature (°C)
Signal #7,Cell Purge (mL/min)
Signal #8,Heater Temp (°C)
Signal #9,Power Delivered (W)
Signal #10,Reference Junction Temperature (°C)
Signal #11,Flange Temperature (°C)
Signal #12,Heat Flow Phase (rad)
Signal #13,Total Heat Capacity (J/°C)
Signal #14,Heat Capacity (J/°C)
[Configuration]
Company Name,ASU
Instrument Name,DSC2A-00468
Instrument Type,DSC2500
Serial Number,DSC2A-00468
IP,192.168.1.100
Location of Instrument,MRRC
DisplayType,Unknown
Sample Interval ,0.1 s/pt
Selected Heat Flow,T4P
Exotherm Direction,Down
Cell Serial,DRC2-00792
Lid Type,Standard
Cooler,RCS 90
Leave Cooler on at End of Sequence,On
Gas 2,Nitrogen
Gas Selected,Channel 1
Flow Rate,50 mL/min
Secondary Purge,On
Licensed Heat Flow,Heat Flow T4P
Modulation Licensed,Yes
[Versions]
Common IDD Version,1
Cortex Version,VER 2.10.2.31
Driver,5.0.0.6
GDM Version,1.0.3.3
TouchscreenVersion,1.0.0.16145
FEP Version,1.2.1.21
FEP Bootloader,2.0.0.5
AutoSampler Version,2.1.1.26
Auto Sampler Bootloader,2.0.0.5
FCM Version,1.1.0.3
FCM Bootloader,2.0.0.5
[Experiment Logs]
Experiment Log Entry # 1,Data On set to 0
Experiment Log Entry # 3,Equilibrate Segment -60 (C) Started
Experiment Log Entry # 5,Air Cool is off.
Experiment Log Entry # 7,Data On set to 1
Experiment Log Entry # 9,Ramp Segment 10 C/min to 200 Started
Experiment Log Entry # 11,Data On set to 0
Experiment Log Entry # 13,Isothermal Segment 2 min started
Experiment Log Entry # 15,Data On set to 1
Experiment Log Entry # 17,Ramp Segment 10 C/min to -60 Started
Experiment Log Entry # 19,Data On set to 0
Experiment Log Entry # 21,Isothermal Segment 2 min started
Experiment Log Entry # 23,Data On set to 1
Experiment Log Entry # 25,Ramp Segment 10 C/min to 200 Started
Experiment Log Entry # 27,Data On set to 0
Experiment Log Entry # 29,Isothermal Segment 2 min started
Experiment Log Entry # 31,Data On set to 1
Experiment Log Entry # 33,Ramp Segment 10 C/min to -60 Started
Experiment Log Entry # 35,Data On set to 0
Experiment Log Entry # 37,Isothermal Segment 2 min started
Experiment Log Entry # 39,Data On set to 1
Experiment Log Entry # 41,Ramp Segment 10 C/min to 200 Started
[Method Log]
Method Log Entry # 1,Data Off
Method Log Entry # 2,Equilibrate -60 °C
Method Log Entry # 3,Data On
Method Log Entry # 4,(Ramp 863463) Ramp 10 °C/minute to 200 °C
Method Log Entry # 5,Data Off
Method Log Entry # 6,Isothermal 2 minutes
Method Log Entry # 7,Data On
Method Log Entry # 8,(Ramp 863467) Ramp 10 °C/minute to -60 °C
Method Log Entry # 9,Data Off
Method Log Entry # 10,Isothermal 2 minutes
Method Log Entry # 11,Data On
Method Log Entry # 12,(Ramp 863471) Ramp 10 °C/minute to 200 °C
Method Log Entry # 13,Data Off
Method Log Entry # 14,Isothermal 2 minutes
Method Log Entry # 15,Data On
Method Log Entry # 16,(Ramp 863475) Ramp 10 °C/minute to -60 °C
Method Log Entry # 17,Data Off
Method Log Entry # 18,Isothermal 2 minutes
Method Log Entry # 19,Data On
Method Log Entry # 20,(Ramp 863479) Ramp 10 °C/minute to 200 °C
Cell Serial,DRC2-00792
[T1 Calibration]
Slope,-0.008529666
Offset,9.636258
Initial Temperature,98.23
GUID,f8bfdadc-4977-4fdf-ba6d-0ba9134940c3
[TZero Calibration]
Date Applied,11/29/2022 4:06:13 PM
Description,From -89.059 °C to 396.009 °C at 20.000°C/min
Gas Type,Nitrogen
Pan Type,None
Source Files 1,C:\Users\yargerlab\Desktop\DSC Data\General\TZero_calibration_11_29_22_2nd(2).tri
Source Files 2,C:\Users\yargerlab\Desktop\DSC Data\General\TZero_calibration_11_29_22_2nd(3).tri
Delta T Offset,13.05235
Delta T Slope,-0.007271007
Delta T0 Offset,-13.69128
Delta T0 Slope,0.06063341
[Temperature Calibration]
Date Applied,11/29/2022 7:12:28 PM
Description,From 106.590 °C to 186.590 °C at 10.000°C/min
Gas Type,Nitrogen
Pan Type,Tzero Aluminum Hermetic
Source Files 1,C:\Users\yargerlab\Desktop\DSC Data\General\Indium(6).tri
Measured 1,157.391
Known 1,156.598
[Cell Constant Calibration]
Date Applied,11/29/2022 7:12:29 PM
Description,From 106.590 °C to 186.590 °C at 10.000°C/min
Gas Type,Nitrogen
Pan Type,Tzero Aluminum Hermetic
Source Files 1,C:\Users\yargerlab\Desktop\DSC Data\General\Indium(6).tri
T4P KCell,1.006051
Onset Slope,63.26126 mW/°C
[Direct Cp Calibration]
Date Applied,11/30/2022 11:04:51 AM
Description,From -79.983 °C to 298.409 °C at 10.000°C/min
Gas Type,Nitrogen
Pan Type,Tzero Aluminum Hermetic
Source Files 1,C:\Users\yargerlab\Desktop\DSC Data\General\Sapphire_Heat_Capacity_11_30_22.tri
[Rev Cp Calibration]
Date Applied,11/30/2022 1:58:51 PM
Description,From -79.996 °C to 292.812 °C at 3.000°C/min
Gas Type,Nitrogen
Pan Type,Tzero Aluminum Hermetic
Source Files 1,C:\Users\yargerlab\Desktop\DSC Data\General\Sapphire_MDSC_Calibration_11_30_22.tri
[step]
Ramp 10.00 °C/min to 200.00 °C
Time,Temperature,Heat Flow (Normalized)
min,°C,W/g
0.00,-59.81,-0.007
0.02,-59.81,-0.007
0.04,-59.81,-0.006
0.05,-59.80,-0.006
0.07,-59.77,-0.006
0.09,-59.72,-0.006
0.11,-59.65,-0.003
0.13,-59.55,0.000
0.15,-59.43,0.004
0.16,-59.30,0.009
0.18,-59.15,0.013
0.20,-59.00,0.017
0.22,-58.84,0.021
0.24,-58.67,0.024
0.26,-58.50,0.026
0.28,-58.33,0.028
0.29,-58.16,0.030
0.31,-57.99,0.032
0.33,-57.81,0.032
0.35,-57.63,0.033
0.37,-57.46,0.034
0.39,-57.28,0.034
0.40,-57.10,0.035
0.42,-56.92,0.035
0.44,-56.75,0.035
0.46,-56.57,0.035
0.48,-56.39,0.036
0.50,-56.21,0.036
0.51,-56.03,0.036
0.53,-55.85,0.036
0.55,-55.67,0.036
0.57,-55.49,0.036
0.59,-55.31,0.036
0.60,-55.13,0.036
0.62,-54.95,0.036
0.64,-54.77,0.036
0.66,-54.59,0.036
0.68,-54.40,0.036
0.70,-54.22,0.036
0.72,-54.04,0.037
0.73,-53.86,0.037
0.75,-53.68,0.037
0.77,-53.50,0.037
0.79,-53.31,0.037
0.81,-53.13,0.037
0.83,-52.95,0.037
0.84,-52.77,0.037
0.86,-52.59,0.037
0.88,-52.41,0.037
0.90,-52.22,0.037
0.92,-52.04,0.037
0.93,-51.86,0.037
0.95,-51.68,0.037
0.97,-51.49,0.037
0.99,-51.31,0.037
1.01,-51.13,0.037
1.03,-50.95,0.037
1.05,-50.77,0.038
1.06,-50.58,0.038
1.08,-50.40,0.038
1.10,-50.22,0.038
1.12,-50.04,0.038
1.14,-49.85,0.038
1.16,-49.67,0.038
1.17,-49.49,0.038
1.19,-49.30,0.038
1.21,-49.12,0.038
1.23,-48.94,0.038
1.25,-48.76,0.038
1.27,-48.57,0.038
1.28,-48.39,0.038
1.30,-48.21,0.038
1.32,-48.02,0.038
1.34,-47.84,0.038
1.36,-47.66,0.038
1.38,-47.47,0.038
1.39,-47.29,0.038
1.41,-47.11,0.038
1.43,-46.93,0.038
1.45,-46.74,0.038
1.47,-46.56,0.038
1.48,-46.38,0.038
1.50,-46.19,0.038
1.52,-46.01,0.038
1.54,-45.83,0.038
1.56,-45.64,0.038
1.58,-45.46,0.038
1.59,-45.28,0.038
1.61,-45.09,0.038
1.63,-44.91,0.039
1.65,-44.73,0.039
1.67,-44.54,0.039
1.69,-44.36,0.039
1.71,-44.17,0.039
1.72,-43.99,0.039
1.74,-43.81,0.039
1.76,-43.62,0.039
1.78,-43.44,0.039
1.80,-43.26,0.039
1.82,-43.07,0.039
1.83,-42.89,0.039
1.85,-42.71,0.039
1.87,-42.52,0.039
1.89,-42.34,0.039
1.91,-42.16,0.039
1.93,-41.97,0.039
1.94,-41.79,0.039
1.96,-41.61,0.039
1.98,-41.42,0.039
2.00,-41.24,0.039
2.02,-41.06,0.039
2.03,-40.87,0.039
2.05,-40.69,0.039
2.07,-40.50,0.039
2.09,-40.32,0.039
2.11,-40.14,0.039
2.13,-39.95,0.039
2.14,-39.77,0.039
2.16,-39.59,0.039
2.18,-39.41,0.039
2.20,-39.22,0.039
2.22,-39.04,0.039
2.24,-38.85,0.039
2.26,-38.67,0.039
2.27,-38.49,0.039
2.29,-38.30,0.039
2.31,-38.12,0.039
2.33,-37.94,0.039
2.35,-37.75,0.039
2.36,-37.57,0.039
2.38,-37.39,0.039
2.40,-37.20,0.039
2.42,-37.02,0.039
2.44,-36.83,0.039
2.46,-36.65,0.039
2.48,-36.47,0.039
2.49,-36.28,0.039
2.51,-36.10,0.039
2.53,-35.92,0.039
2.55,-35.73,0.039
2.57,-35.55,0.039
2.59,-35.37,0.039
2.60,-35.18,0.039
2.62,-35.00,0.040
2.64,-34.82,0.040
2.66,-34.63,0.040
2.68,-34.45,0.040
2.69,-34.26,0.040
2.71,-34.08,0.040
2.73,-33.90,0.040
2.75,-33.71,0.040
2.77,-33.53,0.040
2.79,-33.35,0.040
2.81,-33.16,0.040
2.82,-32.98,0.040
2.84,-32.80,0.040
2.86,-32.61,0.040
2.88,-32.43,0.040
2.90,-32.25,0.040
2.91,-32.06,0.040
2.93,-31.88,0.040
2.95,-31.70,0.040
2.97,-31.51,0.040
2.99,-31.33,0.040
3.01,-31.14,0.040
3.03,-30.96,0.040
3.04,-30.78,0.040
3.06,-30.59,0.040
3.08,-30.41,0.040
3.10,-30.23,0.040
3.12,-30.04,0.040
3.14,-29.86,0.040
3.15,-29.68,0.040
3.17,-29.49,0.040
3.19,-29.31,0.040
3.21,-29.12,0.040
3.23,-28.94,0.040
3.24,-28.76,0.040
3.26,-28.57,0.040
3.28,-28.39,0.040
3.30,-28.21,0.040
3.32,-28.03,0.040
3.34,-27.84,0.040
3.36,-27.66,0.040
3.37,-27.47,0.040
3.39,-27.29,0.040
3.41,-27.11,0.040
3.43,-26.92,0.040
3.45,-26.74,0.040
3.46,-26.56,0.040
3.48,-26.37,0.040
3.50,-26.19,0.040
3.52,-26.01,0.040
3.54,-25.82,0.040
3.56,-25.64,0.040
3.58,-25.45,0.040
3.59,-25.27,0.040
3.61,-25.09,0.041
3.63,-24.90,0.041
3.65,-24.72,0.041
3.67,-24.54,0.041
3.69,-24.35,0.041
3.70,-24.17,0.041
3.72,-23.99,0.041
3.74,-23.80,0.041
3.76,-23.62,0.041
3.78,-23.44,0.041
3.79,-23.25,0.041
3.81,-23.07,0.041
3.83,-22.88,0.041
3.85,-22.70,0.041
3.87,-22.52,0.041
3.89,-22.33,0.041
3.91,-22.15,0.041
3.92,-21.97,0.041
3.94,-21.78,0.041
3.96,-21.60,0.041
3.98,-21.42,0.041
4.00,-21.23,0.041
4.01,-21.05,0.041
4.03,-20.87,0.041
4.05,-20.68,0.041
4.07,-20.50,0.041
4.09,-20.32,0.041
4.11,-20.13,0.041
4.13,-19.95,0.041
4.14,-19.77,0.041
4.16,-19.58,0.041
4.18,-19.40,0.041
4.20,-19.21,0.041
4.22,-19.03,0.041
4.24,-18.85,0.041
4.25,-18.66,0.041
4.27,-18.48,0.041
4.29,-18.30,0.041
4.31,-18.11,0.041
4.33,-17.93,0.041
4.35,-17.75,0.041
4.36,-17.56,0.041
4.38,-17.38,0.041
4.40,-17.20,0.041
4.42,-17.01,0.041
4.44,-16.83,0.042
4.45,-16.65,0.042
4.47,-16.46,0.042
4.49,-16.28,0.042
4.51,-16.10,0.042
4.53,-15.91,0.042
4.55,-15.73,0.042
4.56,-15.54,0.042
4.58,-15.36,0.042
4.60,-15.18,0.042
4.62,-14.99,0.042
4.64,-14.81,0.042
4.66,-14.63,0.042
4.68,-14.44,0.042
4.69,-14.26,0.042
4.71,-14.08,0.042
4.73,-13.89,0.042
4.75,-13.71,0.042
4.77,-13.52,0.042
4.79,-13.34,0.042
4.80,-13.16,0.042
4.82,-12.97,0.042
4.84,-12.79,0.042
4.86,-12.61,0.042
4.88,-12.42,0.042
4.90,-12.24,0.042
4.91,-12.06,0.042
4.93,-11.87,0.042
4.95,-11.69,0.042
4.97,-11.51,0.042
4.99,-11.32,0.042
5.00,-11.14,0.042
5.02,-10.96,0.042
5.04,-10.77,0.042
5.06,-10.59,0.042
5.08,-10.41,0.042
5.10,-10.22,0.042
5.11,-10.04,0.042
5.13,-9.86,0.042
5.15,-9.67,0.043
5.17,-9.49,0.043
5.19,-9.31,0.043
5.21,-9.12,0.043
5.23,-8.94,0.043
5.24,-8.76,0.043
5.26,-8.57,0.043
5.28,-8.39,0.043
5.30,-8.21,0.043
5.32,-8.02,0.043
5.34,-7.84,0.043
5.35,-7.65,0.043
5.37,-7.47,0.043
5.39,-7.29,0.043
5.41,-7.11,0.043
5.43,-6.92,0.043
5.45,-6.74,0.043
5.46,-6.55,0.043
5.48,-6.37,0.043
5.50,-6.19,0.043
5.52,-6.00,0.043
5.54,-5.82,0.043
5.55,-5.63,0.043
5.57,-5.45,0.043
5.59,-5.27,0.043
5.61,-5.08,0.043
5.63,-4.90,0.043
5.65,-4.72,0.043
5.66,-4.54,0.043
5.68,-4.35,0.043
5.70,-4.17,0.043
5.72,-3.98,0.043
5.74,-3.80,0.044
5.76,-3.62,0.044
5.78,-3.43,0.044
5.79,-3.25,0.044
5.81,-3.07,0.044
5.83,-2.88,0.044
5.85,-2.70,0.044
5.87,-2.52,0.044
5.89,-2.33,0.044
5.90,-2.15,0.044
5.92,-1.96,0.044
5.94,-1.78,0.044
5.96,-1.60,0.044
5.98,-1.41,0.044
6.00,-1.23,0.044
6.01,-1.05,0.044
6.03,-0.86,0.044
6.05,-0.68,0.044
6.07,-0.50,0.044
6.09,-0.32,0.044
6.10,-0.13,0.044
6.12,0.05,0.044
6.14,0.24,0.044
6.16,0.42,0.044
6.18,0.60,0.044
6.20,0.79,0.044
6.21,0.97,0.044
6.23,1.15,0.044
6.25,1.34,0.044
6.27,1.52,0.044
6.29,1.70,0.045
6.31,1.89,0.045
6.33,2.07,0.045
6.34,2.25,0.045
6.36,2.44,0.045
6.38,2.62,0.045
6.40,2.81,0.045
6.42,2.99,0.045
6.44,3.17,0.045
6.45,3.36,0.045
6.47,3.54,0.045
6.49,3.72,0.045
6.51,3.91,0.045
6.53,4.09,0.045
6.55,4.27,0.045
6.56,4.46,0.045
6.58,4.64,0.045
6.60,4.83,0.045
6.62,5.01,0.045
6.64,5.19,0.045
6.65,5.38,0.045
6.67,5.56,0.045
6.69,5.74,0.045
6.71,5.93,0.045
6.73,6.11,0.045
6.75,6.29,0.046
6.76,6.48,0.046
6.78,6.66,0.046
6.80,6.84,0.046
6.82,7.03,0.046
6.84,7.21,0.046
6.86,7.39,0.046
6.88,7.58,0.046
6.89,7.76,0.046
6.91,7.94,0.046
6.93,8.13,0.046
6.95,8.31,0.046
6.97,8.49,0.046
6.99,8.68,0.046
7.00,8.86,0.046
7.02,9.04,0.046
7.04,9.23,0.046
7.06,9.41,0.046
7.08,9.59,0.046
7.10,9.78,0.046
7.11,9.96,0.046
7.13,10.14,0.046
7.15,10.33,0.046
7.17,10.51,0.047
7.19,10.70,0.047
7.20,10.88,0.047
7.22,11.06,0.047
7.24,11.24,0.047
7.26,11.43,0.047
7.28,11.61,0.047
7.30,11.80,0.047
7.31,11.98,0.047
7.33,12.16,0.047
7.35,12.35,0.047
7.37,12.53,0.047
7.39,12.71,0.047
7.41,12.90,0.047
7.43,13.08,0.047
7.44,13.26,0.047
7.46,13.45,0.047
7.48,13.63,0.047
7.50,13.81,0.047
7.52,14.00,0.047
7.54,14.18,0.048
7.55,14.36,0.048
7.57,14.55,0.048
7.59,14.73,0.048
7.61,14.91,0.048
7.63,15.10,0.048
7.65,15.28,0.048
7.66,15.46,0.048
7.68,15.65,0.048
7.70,15.83,0.048
7.72,16.01,0.048
7.74,16.20,0.048
7.75,16.38,0.048
7.77,16.56,0.048
7.79,16.75,0.048
7.81,16.93,0.048
7.83,17.11,0.048
7.85,17.30,0.049
7.86,17.48,0.049
7.88,17.66,0.049
7.90,17.85,0.049
7.92,18.03,0.049
7.94,18.21,0.049
7.96,18.40,0.049
7.98,18.58,0.049
7.99,18.76,0.049
8.01,18.95,0.049
8.03,19.13,0.049
8.05,19.31,0.049
8.07,19.50,0.049
8.09,19.68,0.049
8.10,19.86,0.049
8.12,20.05,0.049
8.14,20.23,0.050
8.16,20.41,0.050
8.18,20.60,0.050
8.20,20.78,0.050
8.21,20.96,0.050
8.23,21.15,0.050
8.25,21.33,0.050
8.27,21.51,0.050
8.29,21.70,0.050
8.30,21.88,0.050
8.32,22.06,0.050
8.34,22.25,0.050
8.36,22.43,0.050
8.38,22.61,0.051
8.40,22.80,0.051
8.41,22.98,0.051
8.43,23.16,0.051
8.45,23.35,0.051
8.47,23.53,0.051
8.49,23.72,0.051
8.51,23.90,0.051
8.53,24.08,0.051
8.54,24.27,0.051
8.56,24.45,0.051
8.58,24.63,0.051
8.60,24.82,0.051
8.62,25.00,0.052
8.63,25.18,0.052
8.65,25.37,0.052
8.67,25.55,0.052
8.69,25.73,0.052
8.71,25.92,0.052
8.73,26.10,0.052
8.75,26.28,0.052
8.76,26.47,0.052
8.78,26.65,0.052
8.80,26.83,0.052
8.82,27.02,0.053
8.84,27.20,0.053
8.85,27.38,0.053
8.87,27.57,0.053
8.89,27.75,0.053
8.91,27.93,0.053
8.93,28.12,0.053
8.95,28.30,0.053
8.97,28.48,0.053
8.98,28.67,0.053
9.00,28.85,0.054
9.02,29.03,0.054
9.04,29.22,0.054
9.06,29.40,0.054
9.08,29.58,0.054
9.09,29.77,0.054
9.11,29.95,0.054
9.13,30.13,0.054
9.15,30.32,0.054
9.17,30.50,0.054
9.18,30.68,0.055
9.20,30.87,0.055
9.22,31.05,0.055
9.24,31.23,0.055
9.26,31.42,0.055
9.28,31.60,0.055
9.30,31.78,0.055
9.31,31.97,0.055
9.33,32.15,0.055
9.35,32.33,0.056
9.37,32.52,0.056
9.39,32.70,0.056
9.40,32.88,0.056
9.42,33.07,0.056
9.44,33.25,0.056
9.46,33.43,0.056
9.48,33.62,0.056
9.50,33.80,0.057
9.52,33.98,0.057
9.53,34.17,0.057
9.55,34.35,0.057
9.57,34.53,0.057
9.59,34.72,0.057
9.61,34.90,0.058
9.63,35.08,0.058
9.64,35.27,0.058
9.66,35.45,0.058
9.68,35.63,0.058
9.70,35.82,0.058
9.72,36.00,0.058
9.73,36.18,0.058
9.75,36.37,0.059
9.77,36.55,0.059
9.79,36.73,0.059
9.81,36.92,0.059
9.83,37.10,0.059
9.85,37.28,0.059
9.86,37.46,0.060
9.88,37.65,0.060
9.90,37.83,0.060
9.92,38.02,0.060
9.94,38.20,0.060
9.95,38.38,0.060
9.97,38.56,0.060
9.99,38.75,0.061
10.01,38.93,0.061
10.03,39.12,0.061
10.05,39.30,0.061
10.07,39.48,0.061
10.08,39.66,0.062
10.10,39.85,0.062
10.12,40.03,0.062
10.14,40.21,0.062
10.16,40.40,0.062
10.18,40.58,0.062
10.19,40.76,0.063
10.21,40.95,0.063
10.23,41.13,0.063
10.25,41.31,0.063
10.27,41.50,0.063
10.28,41.68,0.064
10.30,41.86,0.064
10.32,42.04,0.064
10.34,42.23,0.064
10.36,42.41,0.064
10.38,42.59,0.065
10.40,42.78,0.065
10.41,42.96,0.065
10.43,43.14,0.065
10.45,43.33,0.066
10.47,43.51,0.066
10.49,43.69,0.066
10.50,43.88,0.066
10.52,44.06,0.067
10.54,44.24,0.067
10.56,44.42,0.067
10.58,44.61,0.067
10.60,44.79,0.068
10.62,44.97,0.068
10.63,45.16,0.068
10.65,45.34,0.068
10.67,45.52,0.069
10.69,45.71,0.069
10.71,45.89,0.069
10.73,46.07,0.070
10.74,46.26,0.070
10.76,46.44,0.070
10.78,46.62,0.070
10.80,46.80,0.071
10.82,46.99,0.071
10.83,47.17,0.071
10.85,47.35,0.072
10.87,47.54,0.072
10.89,47.72,0.072
10.91,47.90,0.073
10.93,48.08,0.073
10.95,48.27,0.073
10.96,48.45,0.074
10.98,48.63,0.074
11.00,48.82,0.074
11.02,49.00,0.075
11.04,49.18,0.075
11.05,49.37,0.075
11.07,49.55,0.076
11.09,49.73,0.076
11.11,49.91,0.077
11.13,50.09,0.077
11.15,50.28,0.078
11.17,50.46,0.078
11.18,50.64,0.078
11.20,50.83,0.079
11.22,51.01,0.079
11.24,51.19,0.080
11.26,51.37,0.080
11.28,51.56,0.081
11.29,51.74,0.081
11.31,51.92,0.082
11.33,52.10,0.082
11.35,52.29,0.083
11.37,52.47,0.083
11.38,52.65,0.084
11.40,52.83,0.084
11.42,53.02,0.085
11.44,53.20,0.086
11.46,53.38,0.086
11.48,53.56,0.087
11.50,53.75,0.087
11.51,53.93,0.088
11.53,54.11,0.089
11.55,54.29,0.089
11.57,54.47,0.090
11.59,54.66,0.091
11.60,54.84,0.091
11.62,55.02,0.092
11.64,55.20,0.093
11.66,55.39,0.093
11.68,55.57,0.094
11.70,55.75,0.095
11.72,55.93,0.095
11.73,56.11,0.096
11.75,56.29,0.097
11.77,56.48,0.097
11.79,56.66,0.098
11.81,56.84,0.099
11.83,57.02,0.099
11.84,57.21,0.100
11.86,57.39,0.101
11.88,57.57,0.101
11.90,57.75,0.102
11.92,57.93,0.103
11.93,58.12,0.103
11.95,58.30,0.104
11.97,58.48,0.104
11.99,58.66,0.105
12.01,58.85,0.106
12.03,59.03,0.106
12.05,59.21,0.107
12.06,59.39,0.107
12.08,59.58,0.108
12.10,59.76,0.109
12.12,59.94,0.109
12.14,60.12,0.110
12.15,60.31,0.110
12.17,60.49,0.111
12.19,60.67,0.111
12.21,60.85,0.112
12.23,61.04,0.112
12.25,61.22,0.112
12.27,61.40,0.113
12.28,61.58,0.113
12.30,61.77,0.113
12.32,61.95,0.114
12.34,62.13,0.114
12.36,62.32,0.114
12.38,62.50,0.114
12.39,62.68,0.114
12.41,62.86,0.114
12.43,63.05,0.114
12.45,63.23,0.115
12.47,63.41,0.115
12.48,63.60,0.115
12.50,63.78,0.115
12.52,63.97,0.115
12.54,64.15,0.115
12.56,64.33,0.115
12.58,64.52,0.115
12.60,64.70,0.115
12.61,64.88,0.115
12.63,65.06,0.115
12.65,65.25,0.115
12.67,65.43,0.115
12.69,65.62,0.115
12.70,65.80,0.115
12.72,65.98,0.115
12.74,66.17,0.115
12.76,66.35,0.115
12.78,66.53,0.115
12.80,66.72,0.115
12.82,66.90,0.115
12.83,67.08,0.115
12.85,67.27,0.116
12.87,67.45,0.116
12.89,67.63,0.116
12.91,67.82,0.116
12.93,68.00,0.116
12.94,68.18,0.116
12.96,68.37,0.117
12.98,68.55,0.117
13.00,68.73,0.117
13.02,68.92,0.117
13.03,69.10,0.118
13.05,69.28,0.118
13.07,69.46,0.118
13.09,69.65,0.119
13.11,69.83,0.119
13.13,70.01,0.119
13.15,70.20,0.120
13.16,70.38,0.120
13.18,70.56,0.120
13.20,70.74,0.121
13.22,70.93,0.121
13.24,71.11,0.122
13.25,71.29,0.122
13.27,71.48,0.122
13.29,71.66,0.123
13.31,71.84,0.123
13.33,72.02,0.124
13.35,72.21,0.124
13.37,72.39,0.124
13.38,72.57,0.125
13.40,72.76,0.125
13.42,72.94,0.126
13.44,73.12,0.126
13.46,73.30,0.126
13.48,73.49,0.127
13.49,73.67,0.127
13.51,73.85,0.128
13.53,74.03,0.128
13.55,74.22,0.129
13.57,74.40,0.129
13.58,74.58,0.129
13.60,74.76,0.130
13.62,74.95,0.130
13.64,75.13,0.131
13.66,75.31,0.131
13.68,75.50,0.132
13.70,75.68,0.132
13.71,75.86,0.133
13.73,76.04,0.133
13.75,76.23,0.133
13.77,76.41,0.134
13.79,76.59,0.134
13.80,76.78,0.135
13.82,76.96,0.135
13.84,77.14,0.135
13.86,77.32,0.136
13.88,77.50,0.136
13.90,77.69,0.137
13.92,77.87,0.137
13.93,78.05,0.138
13.95,78.24,0.138
13.97,78.42,0.139
13.99,78.60,0.139
14.01,78.78,0.139
14.03,78.97,0.140
14.04,79.15,0.140
14.06,79.33,0.141
14.08,79.51,0.141
14.10,79.70,0.142
14.12,79.88,0.142
14.13,80.06,0.143
14.15,80.24,0.143
14.17,80.43,0.143
14.19,80.61,0.144
14.21,80.79,0.144
14.23,80.98,0.145
14.25,81.16,0.145
14.26,81.34,0.146
14.28,81.52,0.146
14.30,81.71,0.146
14.32,81.89,0.147
14.34,82.07,0.147
14.35,82.25,0.148
14.37,82.44,0.148
14.39,82.62,0.149
14.41,82.80,0.149
14.43,82.99,0.150
14.45,83.17,0.150
14.47,83.35,0.150
14.48,83.53,0.151
14.50,83.72,0.151
14.52,83.90,0.152
14.54,84.08,0.152
14.56,84.26,0.152
14.58,84.45,0.153
14.59,84.63,0.153
14.61,84.81,0.154
14.63,84.99,0.154
14.65,85.18,0.155
14.67,85.36,0.155
14.68,85.54,0.155
14.70,85.73,0.156
14.72,85.91,0.156
14.74,86.09,0.157
14.76,86.27,0.157
14.78,86.46,0.157
14.80,86.64,0.158
14.81,86.82,0.158
14.83,87.01,0.159
14.85,87.19,0.159
14.87,87.37,0.159
14.89,87.55,0.160
14.90,87.74,0.160
14.92,87.92,0.160
14.94,88.10,0.161
14.96,88.28,0.161
14.98,88.47,0.161
15.00,88.65,0.162
15.02,88.83,0.162
15.03,89.02,0.162
15.05,89.20,0.163
15.07,89.38,0.163
15.09,89.56,0.163
15.11,89.75,0.164
15.13,89.93,0.164
15.14,90.11,0.164
15.16,90.30,0.165
15.18,90.48,0.165
15.20,90.66,0.165
15.22,90.84,0.165
15.23,91.03,0.166
15.25,91.21,0.166
15.27,91.39,0.166
15.29,91.58,0.166
15.31,91.76,0.167
15.33,91.94,0.167
15.35,92.13,0.167
15.36,92.31,0.167
15.38,92.49,0.167
15.40,92.67,0.168
15.42,92.86,0.168
15.44,93.04,0.168
15.45,93.22,0.168
15.47,93.41,0.168
15.49,93.59,0.169
15.51,93.77,0.169
15.53,93.96,0.169
15.55,94.14,0.169
15.57,94.32,0.169
15.58,94.51,0.169
15.60,94.69,0.169
15.62,94.87,0.169
15.64,95.06,0.169
15.66,95.24,0.169
15.68,95.42,0.170
15.69,95.61,0.170
15.71,95.79,0.170
15.73,95.97,0.170
15.75,96.16,0.170
15.77,96.34,0.170
15.78,96.52,0.170
15.80,96.71,0.170
15.82,96.89,0.170
15.84,97.08,0.170
15.86,97.26,0.170
15.88,97.44,0.170
15.90,97.63,0.170
15.91,97.81,0.170
15.93,97.99,0.170
15.95,98.18,0.170
15.97,98.36,0.170
15.99,98.55,0.170
16.00,98.73,0.170
16.02,98.91,0.170
16.04,99.10,0.170
16.06,99.28,0.170
16.08,99.46,0.170
16.10,99.65,0.170
16.12,99.83,0.170
16.13,100.02,0.170
16.15,100.20,0.170
16.17,100.38,0.170
16.19,100.57,0.170
16.21,100.75,0.170
16.23,100.94,0.169
16.24,101.12,0.169
16.26,101.30,0.169
16.28,101.49,0.169
16.30,101.67,0.168
16.32,101.86,0.168
16.33,102.04,0.168
16.35,102.22,0.167
16.37,102.41,0.167
16.39,102.59,0.167
16.41,102.77,0.166
16.43,102.96,0.166
16.45,103.14,0.166
16.46,103.33,0.165
16.48,103.51,0.165
16.50,103.70,0.164
16.52,103.88,0.164
16.54,104.06,0.164
16.55,104.25,0.163
16.57,104.43,0.163
16.59,104.62,0.162
16.61,104.80,0.162
16.63,104.99,0.161
16.65,105.17,0.161
16.67,105.36,0.161
16.68,105.54,0.160
16.70,105.72,0.160
16.72,105.91,0.159
16.74,106.09,0.159
16.76,106.28,0.158
16.78,106.46,0.158
16.79,106.65,0.157
16.81,106.83,0.157
16.83,107.02,0.156
16.85,107.20,0.156
16.87,107.38,0.155
16.88,107.57,0.155
16.90,107.76,0.154
16.92,107.94,0.154
16.94,108.12,0.153
16.96,108.31,0.153
16.98,108.49,0.152
17.00,108.68,0.151
17.01,108.86,0.151
17.03,109.05,0.150
17.05,109.23,0.150
17.07,109.42,0.149
17.09,109.60,0.149
17.11,109.79,0.148
17.12,109.97,0.147
17.14,110.16,0.147
17.16,110.34,0.146
17.18,110.53,0.145
17.20,110.71,0.145
17.22,110.89,0.144
17.23,111.08,0.143
17.25,111.26,0.143
17.27,111.45,0.142
17.29,111.63,0.142
17.31,111.82,0.141
17.33,112.00,0.140
17.34,112.19,0.140
17.36,112.37,0.139
17.38,112.56,0.138
17.40,112.74,0.138
17.42,112.93,0.137
17.43,113.11,0.137
17.45,113.30,0.136
17.47,113.48,0.135
17.49,113.67,0.134
17.51,113.85,0.134
17.53,114.04,0.133
17.54,114.22,0.133
17.56,114.41,0.132
17.58,114.59,0.131
17.60,114.78,0.130
17.62,114.96,0.130
17.64,115.14,0.129
17.66,115.33,0.128
17.67,115.51,0.128
17.69,115.70,0.127
17.71,115.88,0.126
17.73,116.07,0.126
17.75,116.25,0.125
17.77,116.44,0.125
17.78,116.63,0.124
17.80,116.81,0.123
17.82,116.99,0.123
17.84,117.18,0.122
17.86,117.37,0.121
17.88,117.55,0.121
17.89,117.73,0.120
17.91,117.92,0.119
17.93,118.10,0.119
17.95,118.29,0.118
17.97,118.47,0.117
17.98,118.66,0.117
18.00,118.84,0.116
18.02,119.03,0.115
18.04,119.21,0.115
18.06,119.40,0.114
18.08,119.58,0.114
18.09,119.77,0.113
18.11,119.95,0.112
18.13,120.14,0.112
18.15,120.32,0.111
18.17,120.51,0.111
18.19,120.69,0.110
18.21,120.88,0.109
18.22,121.06,0.109
18.24,121.25,0.108
18.26,121.43,0.108
18.28,121.62,0.107
18.30,121.80,0.106
18.32,121.98,0.106
18.33,122.17,0.105
18.35,122.35,0.105
18.37,122.54,0.104
18.39,122.72,0.104
18.41,122.91,0.103
18.43,123.09,0.102
18.44,123.28,0.102
18.46,123.46,0.101
18.48,123.65,0.101
18.50,123.83,0.100
18.52,124.02,0.100
18.53,124.20,0.099
18.55,124.39,0.099
18.57,124.57,0.098
18.59,124.75,0.098
18.61,124.94,0.097
18.63,125.12,0.096
18.64,125.31,0.096
18.66,125.49,0.095
18.68,125.68,0.095
18.70,125.86,0.094
18.72,126.05,0.094
18.74,126.23,0.094
18.76,126.42,0.093
18.77,126.60,0.093
18.79,126.78,0.092
18.81,126.97,0.092
18.83,127.15,0.091
18.85,127.34,0.091
18.87,127.52,0.090
18.88,127.71,0.090
18.90,127.89,0.089
18.92,128.08,0.089
18.94,128.26,0.088
18.96,128.45,0.088
18.98,128.63,0.088
18.99,128.81,0.087
19.01,129.00,0.087
19.03,129.19,0.086
19.05,129.37,0.086
19.07,129.55,0.086
19.08,129.74,0.085
19.10,129.92,0.085
19.12,130.11,0.084
19.14,130.29,0.084
19.16,130.48,0.084
19.18,130.66,0.083
19.19,130.84,0.083
19.21,131.03,0.082
19.23,131.21,0.082
19.25,131.40,0.082
19.27,131.58,0.081
19.29,131.76,0.081
19.31,131.95,0.081
19.32,132.13,0.080
19.34,132.32,0.080
19.36,132.50,0.080
19.38,132.69,0.080
19.40,132.87,0.079
19.42,133.05,0.079
19.43,133.24,0.079
19.45,133.42,0.078
19.47,133.61,0.078
19.49,133.79,0.078
19.51,133.97,0.077
19.53,134.16,0.077
19.54,134.34,0.077
19.56,134.53,0.077
19.58,134.71,0.076
19.60,134.89,0.076
19.62,135.08,0.076
19.63,135.26,0.076
19.65,135.44,0.075
19.67,135.63,0.075
19.69,135.81,0.075
19.71,136.00,0.075
19.73,136.18,0.074
19.74,136.36,0.074
19.76,136.55,0.074
19.78,136.73,0.074
19.80,136.92,0.074
19.82,137.10,0.073
19.84,137.28,0.073
19.86,137.47,0.073
19.87,137.65,0.073
19.89,137.84,0.073
19.91,138.02,0.072
19.93,138.20,0.072
19.95,138.39,0.072
19.97,138.57,0.072
19.98,138.75,0.072
20.00,138.94,0.071
20.02,139.12,0.071
20.04,139.31,0.071
20.06,139.49,0.071
20.08,139.67,0.071
20.09,139.86,0.071
20.11,140.04,0.071
20.13,140.22,0.070
20.15,140.41,0.070
20.17,140.59,0.070
20.18,140.78,0.070
20.20,140.96,0.070
20.22,141.14,0.070
20.24,141.33,0.070
20.26,141.51,0.070
20.28,141.69,0.069
20.29,141.88,0.069
20.31,142.06,0.069
20.33,142.25,0.069
20.35,142.43,0.069
20.37,142.61,0.069
20.39,142.80,0.069
20.41,142.98,0.069
20.42,143.16,0.068
20.44,143.35,0.068
20.46,143.53,0.068
20.48,143.71,0.068
20.50,143.90,0.068
20.52,144.08,0.068
20.53,144.27,0.068
20.55,144.45,0.068
20.57,144.63,0.068
20.59,144.82,0.068
20.61,145.00,0.067
20.63,145.19,0.067
20.64,145.37,0.067
20.66,145.55,0.067
20.68,145.74,0.067
20.70,145.92,0.067
20.72,146.10,0.067
20.73,146.29,0.067
20.75,146.47,0.067
20.77,146.66,0.067
20.79,146.84,0.067
20.81,147.02,0.067
20.83,147.21,0.066
20.84,147.39,0.066
20.86,147.57,0.066
20.88,147.76,0.066
20.90,147.94,0.066
20.92,148.12,0.066
20.94,148.31,0.066
20.96,148.49,0.066
20.97,148.67,0.066
20.99,148.86,0.066
21.01,149.04,0.066
21.03,149.22,0.066
21.05,149.41,0.066
21.07,149.59,0.066
21.08,149.78,0.066
21.10,149.96,0.065
21.12,150.14,0.065
21.14,150.33,0.065
21.16,150.51,0.065
21.18,150.69,0.065
21.19,150.88,0.065
21.21,151.06,0.065
21.23,151.24,0.065
21.25,151.43,0.065
21.27,151.61,0.065
21.28,151.79,0.065
21.30,151.98,0.065
21.32,152.16,0.065
21.34,152.34,0.065
21.36,152.53,0.065
21.38,152.71,0.065
21.39,152.90,0.065
21.41,153.08,0.065
21.43,153.26,0.065
21.45,153.45,0.065
21.47,153.63,0.065
21.49,153.81,0.065
21.51,154.00,0.065
21.52,154.18,0.065
21.54,154.36,0.065
21.56,154.55,0.065
21.58,154.73,0.065
21.60,154.91,0.065
21.62,155.10,0.065
21.63,155.28,0.065
21.65,155.46,0.065
21.67,155.65,0.065
21.69,155.83,0.065
21.71,156.01,0.065
21.73,156.20,0.065
21.74,156.38,0.065
21.76,156.56,0.065
21.78,156.75,0.065
21.80,156.93,0.065
21.82,157.12,0.065
21.83,157.30,0.065
21.85,157.48,0.065
21.87,157.67,0.065
21.89,157.85,0.065
21.91,158.03,0.065
21.93,158.22,0.065
21.94,158.40,0.065
21.96,158.58,0.065
21.98,158.77,0.065
22.00,158.95,0.065
22.02,159.13,0.065
22.04,159.32,0.065
22.06,159.50,0.065
22.07,159.69,0.065
22.09,159.87,0.065
22.11,160.05,0.065
22.13,160.24,0.065
22.15,160.42,0.065
22.17,160.60,0.065
22.18,160.79,0.065
22.20,160.97,0.065
22.22,161.15,0.065
22.24,161.34,0.065
22.26,161.52,0.065
22.28,161.70,0.065
22.29,161.89,0.065
22.31,162.07,0.065
22.33,162.25,0.065
22.35,162.44,0.065
22.37,162.62,0.065
22.38,162.80,0.065
22.40,162.99,0.065
22.42,163.17,0.065
22.44,163.35,0.065
22.46,163.54,0.065
22.48,163.72,0.066
22.49,163.90,0.066
22.51,164.09,0.066
22.53,164.27,0.066
22.55,164.45,0.066
22.57,164.64,0.066
22.59,164.82,0.066
22.61,165.00,0.066
22.62,165.19,0.066
22.64,165.37,0.066
22.66,165.55,0.066
22.68,165.74,0.066
22.70,165.92,0.066
22.72,166.10,0.066
22.73,166.29,0.066
22.75,166.47,0.066
22.77,166.65,0.066
22.79,166.84,0.066
22.81,167.02,0.066
22.83,167.20,0.066
22.84,167.39,0.066
22.86,167.57,0.066
22.88,167.75,0.066
22.90,167.94,0.066
22.92,168.12,0.066
22.93,168.30,0.066
22.95,168.49,0.066
22.97,168.67,0.066
22.99,168.85,0.066
23.01,169.04,0.066
23.03,169.22,0.066
23.04,169.40,0.066
23.06,169.59,0.066
23.08,169.77,0.067
23.10,169.96,0.067
23.12,170.14,0.067
23.14,170.32,0.067
23.16,170.51,0.067
23.17,170.69,0.067
23.19,170.87,0.067
23.21,171.06,0.067
23.23,171.24,0.067
23.25,171.43,0.067
23.27,171.61,0.067
23.28,171.79,0.067
23.30,171.98,0.067
23.32,172.16,0.067
23.34,172.34,0.067
23.36,172.52,0.067
23.38,172.71,0.067
23.39,172.89,0.067
23.41,173.08,0.067
23.43,173.26,0.067
23.45,173.44,0.067
23.47,173.63,0.067
23.48,173.81,0.067
23.50,173.99,0.067
23.52,174.18,0.067
23.54,174.36,0.067
23.56,174.54,0.067
23.58,174.73,0.067
23.59,174.91,0.067
23.61,175.10,0.067
23.63,175.28,0.068
23.65,175.47,0.068
23.67,175.65,0.068
23.69,175.84,0.068
23.71,176.02,0.068
23.72,176.20,0.068
23.74,176.38,0.068
23.76,176.57,0.068
23.78,176.75,0.068
23.80,176.93,0.068
23.82,177.12,0.068
23.83,177.30,0.068
23.85,177.48,0.068
23.87,177.67,0.068
23.89,177.85,0.068
23.91,178.03,0.068
23.93,178.22,0.068
23.94,178.40,0.068
23.96,178.58,0.068
23.98,178.77,0.068
24.00,178.95,0.068
24.02,179.13,0.068
24.03,179.32,0.068
24.05,179.50,0.068
24.07,179.68,0.068
24.09,179.86,0.068
24.11,180.05,0.068
24.13,180.23,0.068
24.14,180.42,0.068
24.16,180.60,0.068
24.18,180.78,0.068
24.20,180.96,0.068
24.22,181.15,0.068
24.24,181.33,0.068
24.26,181.51,0.068
24.27,181.70,0.068
24.29,181.88,0.068
24.31,182.06,0.068
24.33,182.25,0.068
24.35,182.43,0.068
24.37,182.61,0.068
24.38,182.80,0.068
24.40,182.98,0.068
24.42,183.16,0.068
24.44,183.35,0.068
24.46,183.53,0.068
24.48,183.71,0.068
24.49,183.90,0.068
24.51,184.08,0.068
24.53,184.26,0.068
24.55,184.45,0.068
24.57,184.63,0.068
24.58,184.81,0.068
24.60,185.00,0.068
24.62,185.18,0.068
24.64,185.37,0.068
24.66,185.55,0.068
24.68,185.73,0.068
24.69,185.92,0.068
24.71,186.10,0.068
24.73,186.28,0.068
24.75,186.47,0.068
24.77,186.65,0.068
24.79,186.83,0.068
24.81,187.02,0.068
24.82,187.20,0.068
24.84,187.38,0.068
24.86,187.57,0.068
24.88,187.75,0.068
24.90,187.94,0.068
24.92,188.12,0.068
24.93,188.30,0.068
24.95,188.49,0.068
24.97,188.67,0.068
24.99,188.85,0.069
25.01,189.04,0.069
25.03,189.22,0.069
25.04,189.40,0.069
25.06,189.59,0.069
25.08,189.77,0.069
25.10,189.95,0.069
25.12,190.14,0.069
25.13,190.32,0.069
25.15,190.50,0.069
25.17,190.69,0.069
25.19,190.87,0.069
25.21,191.05,0.069
25.23,191.24,0.069
25.24,191.42,0.069
25.26,191.60,0.069
25.28,191.79,0.069
25.30,191.97,0.069
25.32,192.15,0.069
25.34,192.34,0.069
25.36,192.52,0.069
25.37,192.71,0.069
25.39,192.89,0.069
25.41,193.07,0.069
25.43,193.26,0.069
25.45,193.44,0.069
25.47,193.62,0.069
25.48,193.81,0.069
25.50,193.99,0.069
25.52,194.17,0.069
25.54,194.36,0.069
25.56,194.54,0.069
25.58,194.72,0.069
25.59,194.91,0.069
25.61,195.09,0.069
25.63,195.27,0.069
25.65,195.46,0.069
25.67,195.64,0.069
25.68,195.82,0.069
25.70,196.01,0.069
25.72,196.19,0.069
25.74,196.38,0.069
25.76,196.56,0.069
25.78,196.74,0.068
25.79,196.93,0.068
25.81,197.11,0.068
25.83,197.29,0.068
25.85,197.48,0.068
25.87,197.66,0.068
25.89,197.84,0.068
25.91,198.03,0.068
25.92,198.21,0.068
25.94,198.39,
25.96,198.58,
25.98,198.76,
25.99,,

[step]
Ramp 10.00 °C/min to -60.00 °C
Time,Temperature,Heat Flow (Normalized)
min,°C,W/g
27.99,200.16,-0.005
28.01,200.16,-0.005
28.03,200.16,-0.005
28.05,200.15,-0.005
28.07,200.12,-0.005
28.08,200.07,-0.010
28.10,200.00,-0.017
28.12,199.90,-0.026
28.14,199.78,-0.036
28.16,199.65,-0.045
28.18,199.50,-0.053
28.19,199.34,-0.058
28.21,199.18,-0.063
28.23,199.01,-0.066
28.25,198.84,-0.069
28.27,198.66,-0.070
28.29,198.49,-0.072
28.31,198.31,-0.072
28.32,198.13,-0.073
28.34,197.96,-0.074
28.36,197.78,-0.074
28.38,197.60,-0.075
28.40,197.41,-0.075
28.42,197.23,-0.075
28.43,197.05,-0.075
28.45,196.87,-0.075
28.47,196.69,-0.075
28.49,196.51,-0.075
28.51,196.33,-0.075
28.53,196.14,-0.075
28.54,195.96,-0.076
28.56,195.78,-0.076
28.58,195.60,-0.076
28.60,195.42,-0.076
28.62,195.23,-0.076
28.63,195.05,-0.076
28.65,194.87,-0.076
28.67,194.69,-0.076
28.69,194.51,-0.076
28.71,194.33,-0.076
28.73,194.14,-0.076
28.74,193.96,-0.076
28.76,193.78,-0.076
28.78,193.60,-0.076
28.80,193.41,-0.076
28.82,193.23,-0.076
28.84,193.05,-0.076
28.86,192.87,-0.076
28.87,192.68,-0.076
28.89,192.50,-0.076
28.91,192.32,-0.076
28.93,192.13,-0.076
28.95,191.95,-0.076
28.97,191.77,-0.076
28.98,191.59,-0.076
29.00,191.41,-0.076
29.02,191.22,-0.076
29.04,191.04,-0.076
29.06,190.86,-0.076
29.08,190.67,-0.076
29.09,190.49,-0.076
29.11,190.31,-0.076
29.13,190.13,-0.076
29.15,189.94,-0.076
29.17,189.76,-0.076
29.18,189.58,-0.076
29.20,189.39,-0.076
29.22,189.21,-0.076
29.24,189.03,-0.076
29.26,188.85,-0.076
29.28,188.66,-0.076
29.29,188.48,-0.076
29.31,188.30,-0.076
29.33,188.11,-0.076
29.35,187.93,-0.076
29.37,187.75,-0.076
29.39,187.56,-0.076
29.41,187.38,-0.076
29.42,187.20,-0.076
29.44,187.02,-0.076
29.46,186.83,-0.076
29.48,186.65,-0.076
29.50,186.47,-0.076
29.52,186.28,-0.076
29.53,186.10,-0.076
29.55,185.92,-0.076
29.57,185.73,-0.076
29.59,185.55,-0.076
29.61,185.37,-0.076
29.63,185.19,-0.076
29.64,185.00,-0.076
29.66,184.82,-0.076
29.68,184.63,-0.076
29.70,184.45,-0.076
29.72,184.27,-0.076
29.73,184.09,-0.076
29.75,183.90,-0.076
29.77,183.72,-0.076
29.79,183.54,-0.076
29.81,183.35,-0.076
29.83,183.17,-0.076
29.84,182.99,-0.076
29.86,182.80,-0.076
29.88,182.62,-0.076
29.90,182.44,-0.076
29.92,182.25,-0.076
29.94,182.07,-0.076
29.96,181.89,-0.076
29.97,181.70,-0.076
29.99,181.52,-0.076
30.01,181.34,-0.076
30.03,181.15,-0.075
30.05,180.97,-0.075
30.07,180.79,-0.075
30.08,180.60,-0.075
30.10,180.42,-0.075
30.12,180.24,-0.075
30.14,180.05,-0.075
30.16,179.87,-0.075
30.18,179.69,-0.075
30.19,179.50,-0.075
30.21,179.32,-0.075
30.23,179.14,-0.075
30.25,178.95,-0.075
30.27,178.77,-0.075
30.28,178.59,-0.075
30.30,178.40,-0.075
30.32,178.22,-0.075
30.34,178.04,-0.075
30.36,177.85,-0.075
30.38,177.67,-0.075
30.39,177.49,-0.075
30.41,177.30,-0.075
30.43,177.12,-0.075
30.45,176.94,-0.075
30.47,176.76,-0.075
30.49,176.57,-0.075
30.51,176.39,-0.075
30.52,176.21,-0.075
30.54,176.02,-0.075
30.56,175.84,-0.075
30.58,175.66,-0.075
30.60,175.47,-0.075
30.62,175.29,-0.075
30.63,175.11,-0.075
30.65,174.92,-0.075
30.67,174.74,-0.075
30.69,174.56,-0.075
30.71,174.37,-0.075
30.73,174.19,-0.075
30.74,174.01,-0.075
30.76,173.82,-0.075
30.78,173.64,-0.075
30.80,173.46,-0.075
30.82,173.27,-0.075
30.83,173.09,-0.075
30.85,172.91,-0.075
30.87,172.72,-0.075
30.89,172.54,-0.075
30.91,172.36,-0.075
30.93,172.17,-0.075
30.94,171.99,-0.075
30.96,171.81,-0.075
30.98,171.63,-0.075
31.00,171.44,-0.074
31.02,171.26,-0.074
31.04,171.08,-0.074
31.06,170.89,-0.074
31.07,170.71,-0.074
31.09,170.53,-0.074
31.11,170.34,-0.074
31.13,170.16,-0.074
31.15,169.98,-0.074
31.17,169.79,-0.074
31.18,169.61,-0.074
31.20,169.42,-0.074
31.22,169.24,-0.074
31.24,169.06,-0.074
31.26,168.88,-0.074
31.28,168.69,-0.074
31.29,168.51,-0.074
31.31,168.33,-0.074
31.33,168.14,-0.074
31.35,167.96,-0.074
31.37,167.78,-0.074
31.38,167.59,-0.074
31.40,167.41,-0.074
31.42,167.23,-0.074
31.44,167.04,-0.074
31.46,166.86,-0.074
31.48,166.68,-0.074
31.49,166.49,-0.074
31.51,166.31,-0.074
31.53,166.13,-0.074
31.55,165.94,-0.074
31.57,165.76,-0.074
31.59,165.58,-0.074
31.61,165.39,-0.074
31.62,165.21,-0.074
31.64,165.03,-0.074
31.66,164.84,-0.074
31.68,164.66,-0.074
31.70,164.48,-0.074
31.72,164.29,-0.074
31.73,164.11,-0.074
31.75,163.93,-0.074
31.77,163.75,-0.074
31.79,163.56,-0.074
31.81,163.38,-0.074
31.83,163.19,-0.074
31.84,163.01,-0.074
31.86,162.83,-0.074
31.88,162.65,-0.074
31.90,162.46,-0.074
31.92,162.28,-0.074
31.93,162.09,-0.074
31.95,161.91,-0.074
31.97,161.73,-0.074
31.99,161.54,-0.074
32.01,161.36,-0.074
32.03,161.18,-0.074
32.04,161.00,-0.074
32.06,160.81,-0.074
32.08,160.63,-0.073
32.10,160.45,-0.073
32.12,160.26,-0.073
32.14,160.08,-0.073
32.16,159.89,-0.073
32.17,159.71,-0.073
32.19,159.53,-0.073
32.21,159.35,-0.073
32.23,159.16,-0.073
32.25,158.98,-0.073
32.27,158.80,-0.073
32.28,158.61,-0.073
32.30,158.43,-0.073
32.32,158.25,-0.073
32.34,158.06,-0.073
32.36,157.88,-0.073
32.38,157.70,-0.073
32.39,157.51,-0.073
32.41,157.33,-0.073
32.43,157.15,-0.073
32.45,156.96,-0.073
32.47,156.78,-0.073
32.48,156.60,-0.073
32.50,156.41,-0.073
32.52,156.23,-0.073
32.54,156.05,-0.073
32.56,155.86,-0.073
32.58,155.68,-0.073
32.59,155.50,-0.073
32.61,155.31,-0.073
32.63,155.13,-0.073
32.65,154.95,-0.073
32.67,154.76,-0.073
32.69,154.58,-0.073
32.71,154.40,-0.073
32.72,154.21,-0.073
32.74,154.03,-0.073
32.76,153.85,-0.073
32.78,153.66,-0.073
32.80,153.48,-0.073
32.82,153.30,-0.073
32.83,153.11,-0.073
32.85,152.93,-0.073
32.87,152.75,-0.073
32.89,152.57,-0.073
32.91,152.38,-0.073
32.93,152.20,-0.073
32.94,152.02,-0.073
32.96,151.83,-0.073
32.98,151.65,-0.073
33.00,151.46,-0.073
33.02,151.28,-0.073
33.03,151.10,-0.073
33.05,150.91,-0.073
33.07,150.73,-0.073
33.09,150.55,-0.073
33.11,150.36,-0.073
33.13,150.18,-0.073
33.14,150.00,-0.073
33.16,149.81,-0.073
33.18,149.63,-0.073
33.20,149.45,-0.073
33.22,149.27,-0.073
33.24,149.08,-0.073
33.26,148.90,-0.073
33.27,148.71,-0.072
33.29,148.53,-0.072
33.31,148.35,-0.072
33.33,148.16,-0.072
33.35,147.98,-0.072
33.37,147.80,-0.072
33.38,147.62,-0.072
33.40,147.43,-0.072
33.42,147.25,-0.072
33.44,147.07,-0.072
33.46,146.88,-0.072
33.48,146.70,-0.072
33.49,146.52,-0.072
33.51,146.33,-0.072
33.53,146.15,-0.072
33.55,145.97,-0.072
33.57,145.78,-0.072
33.58,145.60,-0.072
33.60,145.42,-0.072
33.62,145.23,-0.072
33.64,145.05,-0.072
33.66,144.87,-0.072
33.68,144.68,-0.072
33.69,144.50,-0.072
33.71,144.32,-0.072
33.73,144.13,-0.072
33.75,143.95,-0.072
33.77,143.76,-0.072
33.79,143.58,-0.072
33.81,143.40,-0.072
33.82,143.22,-0.072
33.84,143.03,-0.072
33.86,142.85,-0.072
33.88,142.67,-0.072
33.90,142.48,-0.072
33.92,142.30,-0.072
33.93,142.12,-0.072
33.95,141.93,-0.072
33.97,141.75,-0.072
33.99,141.57,-0.072
34.01,141.38,-0.072
34.03,141.20,-0.072
34.04,141.02,-0.072
34.06,140.83,-0.072
34.08,140.65,-0.072
34.10,140.47,-0.072
34.12,140.28,-0.072
34.14,140.10,-0.072
34.15,139.92,-0.072
34.17,139.73,-0.072
34.19,139.55,-0.072
34.21,139.37,-0.072
34.23,139.18,-0.072
34.24,139.00,-0.072
34.26,138.82,-0.072
34.28,138.63,-0.072
34.30,138.45,-0.072
34.32,138.27,-0.072
34.34,138.08,-0.072
34.36,137.90,-0.072
34.37,137.72,-0.071
34.39,137.53,-0.071
34.41,137.35,-0.071
34.43,137.17,-0.071
34.45,136.98,-0.071
34.46,136.80,-0.071
34.48,136.62,-0.071
34.50,136.43,-0.071
34.52,136.25,-0.071
34.54,136.07,-0.071
34.56,135.88,-0.071
34.58,135.70,-0.071
34.59,135.52,-0.071
34.61,135.33,-0.071
34.63,135.15,-0.071
34.65,134.97,-0.071
34.67,134.78,-0.071
34.69,134.60,-0.071
34.70,134.42,-0.071
34.72,134.24,-0.071
34.74,134.05,-0.071
34.76,133.87,-0.071
34.78,133.69,-0.071
34.79,133.50,-0.071
34.81,133.32,-0.071
34.83,133.14,-0.071
34.85,132.95,-0.071
34.87,132.77,-0.071
34.89,132.59,-0.071
34.91,132.40,-0.071
34.92,132.22,-0.071
34.94,132.04,-0.071
34.96,131.85,-0.071
34.98,131.67,-0.071
35.00,131.49,-0.071
35.01,131.30,-0.071
35.03,131.12,-0.071
35.05,130.94,-0.071
35.07,130.75,-0.071
35.09,130.57,-0.071
35.11,130.39,-0.071
35.13,130.20,-0.071
35.14,130.02,-0.071
35.16,129.84,-0.071
35.18,129.65,-0.071
35.20,129.47,-0.071
35.22,129.29,-0.071
35.24,129.10,-0.071
35.25,128.92,-0.071
35.27,128.74,-0.071
[...]
119.22,10.93,0.037
119.24,11.12,0.037
119.26,11.30,0.037
119.28,11.48,0.037
119.29,11.67,0.037
119.31,11.85,0.037
119.33,12.03,0.037
119.35,12.22,0.037
119.37,12.40,0.037
119.39,12.58,0.037
119.40,12.77,0.037
119.42,12.95,0.037
119.44,13.13,0.037
119.46,13.32,0.037
119.48,13.50,0.037
119.50,13.69,0.037
119.51,13.87,0.037
119.53,14.05,0.037
119.55,14.24,0.038
119.57,14.42,0.038
119.59,14.60,0.038
119.60,14.79,0.038
119.62,14.97,0.038
119.64,15.15,0.038
119.66,15.34,0.038
119.68,15.52,0.038
119.70,15.71,0.038
119.71,15.89,0.038
119.73,16.07,0.038
119.75,16.26,0.038
119.77,16.44,0.038
119.79,16.62,0.038
119.81,16.81,0.038
119.83,16.99,0.038
119.84,17.17,0.038
119.86,17.36,0.038
119.88,17.54,0.038
119.90,17.72,0.038
119.92,17.91,0.038
119.94,18.09,0.038
119.95,18.27,0.038
119.97,18.46,0.038
119.99,18.64,0.038
120.01,18.83,0.038
120.03,19.01,0.038
120.05,19.19,0.038
120.06,19.38,0.038
120.08,19.56,0.038
120.10,19.74,0.038
120.12,19.93,0.038
120.14,20.11,0.038
120.15,20.29,0.038
120.17,20.48,0.038
120.19,20.66,0.038
120.21,20.84,0.038
120.23,21.03,0.038
120.25,21.21,0.038
120.26,21.39,0.038
120.28,21.58,0.038
120.30,21.76,0.038
120.32,21.94,0.038
120.34,22.13,0.038
120.36,22.31,0.038
120.38,22.49,0.038
120.39,22.68,0.038
120.41,22.86,0.038
120.43,23.04,0.038
120.45,23.23,0.038
120.47,23.41,0.038
120.49,23.59,0.039
120.50,23.78,0.039
120.52,23.96,0.039
120.54,24.14,0.039
120.56,24.33,0.039
120.58,24.51,0.039
120.60,24.69,0.039
120.61,24.88,0.039
120.63,25.06,0.039
120.65,25.24,0.039
120.67,25.43,0.039
120.69,25.61,0.039
120.70,25.80,0.039
120.72,25.98,0.039
120.74,26.16,0.039
120.76,26.35,0.039
120.78,26.53,0.039
120.80,26.71,0.039
120.81,26.90,0.039
120.83,27.08,0.039
120.85,27.26,0.039
120.87,27.45,0.039
120.89,27.63,0.039
120.91,27.81,0.039
120.93,28.00,0.039
120.94,28.18,0.039
120.96,28.36,0.039
120.98,28.55,0.039
121.00,28.73,0.039
121.02,28.92,0.039
121.04,29.10,0.039
121.05,29.28,0.039
121.07,29.47,0.039
121.09,29.65,0.039
121.11,29.83,0.039
121.13,30.02,0.039
121.15,30.20,0.039
121.16,30.38,0.039
121.18,30.57,0.039
121.20,30.75,0.039
121.22,30.93,0.039
121.24,31.12,0.039
121.25,31.30,0.039
121.27,31.49,0.039
121.29,31.67,0.039
121.31,31.85,0.039
121.33,32.04,0.040
121.35,32.22,0.040
121.36,32.40,0.040
121.38,32.59,0.040
121.40,32.77,0.040
121.42,32.95,0.040
121.44,33.14,0.040
121.46,33.32,0.040
121.48,33.50,0.040
121.49,33.69,0.040
121.51,33.87,0.040
121.53,34.05,0.040
121.55,34.24,0.040
121.57,34.42,0.040
121.59,34.61,0.040
121.60,34.79,0.040
121.62,34.97,0.040
121.64,35.16,0.040
121.66,35.34,0.040
121.68,35.52,0.040
121.70,35.71,0.040
121.71,35.89,0.040
121.73,36.07,0.040
121.75,36.26,0.040
121.77,36.44,0.040
121.79,36.62,0.040
121.80,36.81,0.040
121.82,36.99,0.040
121.84,37.17,0.040
121.86,37.36,0.040
121.88,37.54,0.040
121.90,37.72,0.040
121.91,37.91,0.040
121.93,38.09,0.040
121.95,38.28,0.040
121.97,38.46,0.040
121.99,38.64,0.040
122.01,38.83,0.040
122.03,39.01,0.040
122.04,39.19,0.040
122.06,39.38,0.040
122.08,39.56,0.040
122.10,39.74,0.040
122.12,39.93,0.040
122.14,40.11,0.040
122.15,40.29,0.040
122.17,40.48,0.040
122.19,40.66,0.040
122.21,40.84,0.040
122.23,41.03,0.040
122.25,41.21,0.041
122.26,41.39,0.041
122.28,41.58,0.041
122.30,41.76,0.041
122.32,41.94,0.041
122.34,42.13,0.041
122.35,42.31,0.041
122.37,42.50,0.041
122.39,42.68,0.041
122.41,42.86,0.041
122.43,43.05,0.041
122.45,43.23,0.041
122.46,43.41,0.041
122.48,43.60,0.041
122.50,43.78,0.041
122.52,43.96,0.041
122.54,44.15,0.041
122.56,44.33,0.041
122.58,44.51,0.041
122.59,44.70,0.041
122.61,44.88,0.041
122.63,45.07,0.041
122.65,45.25,0.041
122.67,45.43,0.041
122.69,45.62,0.041
122.70,45.80,0.041
122.72,45.98,0.041
122.74,46.17,0.041
122.76,46.35,0.041
122.78,46.53,0.041
122.80,46.72,0.041
122.81,46.90,0.041
122.83,47.08,0.041
122.85,47.27,0.041
122.87,47.45,0.041
122.89,47.63,0.041
122.90,47.82,0.041
122.92,48.00,0.041
122.94,48.18,0.041
122.96,48.37,0.041
122.98,48.55,0.041
123.00,48.74,0.041
123.01,48.92,0.041
123.03,49.10,0.041
123.05,49.29,0.041
123.07,49.47,0.042
123.09,49.65,0.042
123.11,49.84,0.042
123.13,50.02,0.042
123.14,50.20,0.042
123.16,50.39,0.042
123.18,50.57,0.042
123.20,50.75,0.042
123.22,50.94,0.042
123.24,51.12,0.042
123.25,51.30,0.042
123.27,51.49,0.042
123.29,51.67,0.042
123.31,51.85,0.042
123.33,52.04,0.042
123.35,52.22,0.042
123.36,52.41,0.042
123.38,52.59,0.042
123.40,52.77,0.042
123.42,52.96,0.042
123.44,53.14,0.042
123.45,53.32,0.042
123.47,53.51,0.042
123.49,53.69,0.042
123.51,53.87,0.042
123.53,54.06,0.042
123.55,54.24,0.042
123.56,54.42,0.042
123.58,54.61,0.042
123.60,54.79,0.042
123.62,54.97,0.042
123.64,55.16,0.042
123.66,55.34,0.042
123.68,55.52,0.042
123.69,55.71,0.042
123.71,55.89,0.042
123.73,56.07,0.042
123.75,56.26,0.042
123.77,56.44,0.042
123.79,56.63,0.042
123.80,56.81,0.042
123.82,56.99,0.042
123.84,57.18,0.042
123.86,57.36,0.042
123.88,57.54,0.042
123.90,57.73,0.043
123.91,57.91,0.043
123.93,58.09,0.043
123.95,58.28,0.043
123.97,58.46,0.043
123.99,58.64,0.043
124.00,58.83,0.043
124.02,59.01,0.043
124.04,59.19,0.043
124.06,59.38,0.043
124.08,59.56,0.043
124.10,59.75,0.043
124.11,59.93,0.043
124.13,60.11,0.043
124.15,60.29,0.043
124.17,60.48,0.043
124.19,60.66,0.043
124.21,60.85,0.043
124.23,61.03,0.043
124.24,61.21,0.043
124.26,61.40,0.043
124.28,61.58,0.043
124.30,61.76,0.043
124.32,61.95,0.043
124.34,62.13,0.043
124.35,62.31,0.043
124.37,62.50,0.043
124.39,62.68,0.043
124.41,62.86,0.043
124.43,63.05,0.043
124.45,63.23,0.043
124.46,63.42,0.043
124.48,63.60,0.043
124.50,63.78,0.043
124.52,63.97,0.043
124.54,64.15,0.043
124.55,64.33,0.043
124.57,64.52,0.043
124.59,64.70,0.043
124.61,64.88,0.043
124.63,65.07,0.043
124.65,65.25,0.043
124.66,65.43,0.043
124.68,65.62,0.043
124.70,65.80,0.044
124.72,65.98,0.044
124.74,66.17,0.044
124.76,66.35,0.044
124.78,66.54,0.044
124.79,66.72,0.044
124.81,66.90,0.044
124.83,67.09,0.044
124.85,67.27,0.044
124.87,67.45,0.044
124.89,67.64,0.044
124.90,67.82,0.044
124.92,68.00,0.044
124.94,68.19,0.044
124.96,68.37,0.044
124.98,68.55,0.044
125.00,68.74,0.044
125.01,68.92,0.044
125.03,69.10,0.044
125.05,69.29,0.044
125.07,69.47,0.044
125.09,69.65,0.044
125.10,69.84,0.044
125.12,70.02,0.044
125.14,70.21,0.044
125.16,70.39,0.044
125.18,70.57,0.044
125.20,70.76,0.044
125.21,70.94,0.044
125.23,71.12,0.044
125.25,71.31,0.044
125.27,71.49,0.044
125.29,71.67,0.044
125.31,71.86,0.044
125.33,72.04,0.044
125.34,72.22,0.044
125.36,72.41,0.044
125.38,72.59,0.044
125.40,72.77,0.044
125.42,72.96,0.044
125.44,73.14,0.044
125.45,73.33,0.044
125.47,73.51,0.045
125.49,73.69,0.045
125.51,73.88,0.045
125.53,74.06,0.045
125.55,74.24,0.045
125.56,74.43,0.045
125.58,74.61,0.045
125.60,74.79,0.045
125.62,74.98,0.045
125.64,75.16,0.045
125.65,75.34,0.045
125.67,75.53,0.045
125.69,75.71,0.045
125.71,75.89,0.045
125.73,76.08,0.045
125.75,76.26,0.045
125.76,76.44,0.045
125.78,76.63,0.045
125.80,76.81,0.045
125.82,76.99,0.045
125.84,77.18,0.045
125.86,77.36,0.045
125.88,77.54,0.045
125.89,77.73,0.045
125.91,77.91,0.045
125.93,78.09,0.045
125.95,78.28,0.045
125.97,78.46,0.045
125.99,78.64,0.045
126.00,78.83,0.045
126.02,79.01,0.045
126.04,79.19,0.045
126.06,79.38,0.045
126.08,79.56,0.045
126.10,79.75,0.045
126.11,79.93,0.045
126.13,80.11,0.045
126.15,80.30,0.045
126.17,80.48,0.046
126.19,80.66,0.046
126.20,80.85,0.046
126.22,81.03,0.046
126.24,81.21,0.046
126.26,81.40,0.046
126.28,81.58,0.046
126.30,81.76,0.046
126.31,81.95,0.046
126.33,82.13,0.046
126.35,82.31,0.046
126.37,82.50,0.046
126.39,82.68,0.046
126.41,82.86,0.046
126.43,83.05,0.046
126.44,83.23,0.046
126.46,83.41,0.046
126.48,83.60,0.046
126.50,83.78,0.046
126.52,83.96,0.046
126.54,84.15,0.046
126.55,84.33,0.046
126.57,84.51,0.046
126.59,84.70,0.046
126.61,84.88,0.046
126.63,85.07,0.046
126.65,85.25,0.046
126.66,85.43,0.046
126.68,85.62,0.046
126.70,85.80,0.046
126.72,85.98,0.046
126.74,86.17,0.046
126.75,86.35,0.046
126.77,86.53,0.046
126.79,86.72,0.046
126.81,86.90,0.046
126.83,87.08,0.046
126.85,87.27,0.047
126.86,87.45,0.047
126.88,87.63,0.047
126.90,87.82,0.047
126.92,88.00,0.047
126.94,88.18,0.047
126.96,88.37,0.047
126.98,88.55,0.047
126.99,88.74,0.047
127.01,88.92,0.047
127.03,89.10,0.047
127.05,89.29,0.047
127.07,89.47,0.047
127.09,89.65,0.047
127.10,89.84,0.047
127.12,90.02,0.047
127.14,90.20,0.047
127.16,90.39,0.047
127.18,90.57,0.047
127.20,90.75,0.047
127.21,90.94,0.047
127.23,91.12,0.047
127.25,91.30,0.047
127.27,91.49,0.047
127.29,91.67,0.047
127.30,91.85,0.047
127.32,92.04,0.047
127.34,92.22,0.047
127.36,92.40,0.048
127.38,92.59,0.048
127.40,92.77,0.048
127.41,92.95,0.048
127.43,93.14,0.048
127.45,93.32,0.048
127.47,93.50,0.048
127.49,93.69,0.048
127.51,93.87,0.048
127.53,94.05,0.048
127.54,94.24,0.048
127.56,94.42,0.048
127.58,94.61,0.048
127.60,94.79,0.048
127.62,94.97,0.048
127.64,95.15,0.048
127.65,95.34,0.048
127.67,95.52,0.048
127.69,95.71,0.048
127.71,95.89,0.048
127.73,96.07,0.048
127.75,96.26,0.048
127.76,96.44,0.049
127.78,96.62,0.049
127.80,96.80,0.049
127.82,96.99,0.049
127.84,97.17,0.049
127.85,97.36,0.049
127.87,97.54,0.049
127.89,97.72,0.049
127.91,97.91,0.049
127.93,98.09,0.049
127.95,98.27,0.049
127.96,98.46,0.049
127.98,98.64,0.049
128.00,98.82,0.049
128.02,99.01,0.049
128.04,99.19,0.049
128.06,99.37,0.049
128.08,99.56,0.050
128.09,99.74,0.050
128.11,99.92,0.050
128.13,100.11,0.050
128.15,100.29,0.050
128.17,100.47,0.050
128.19,100.66,0.050
128.20,100.84,0.050
128.22,101.02,0.050
128.24,101.21,0.050
128.26,101.39,0.050
128.28,101.57,0.050
128.30,101.76,0.050
128.31,101.94,0.050
128.33,102.12,0.051
128.35,102.31,0.051
128.37,102.49,0.051
128.39,102.67,0.051
128.40,102.86,0.051
128.42,103.04,0.051
128.44,103.22,0.051
128.46,103.41,0.051
128.48,103.59,0.051
128.50,103.77,0.051
128.51,103.96,0.051
128.53,104.14,0.052
128.55,104.32,0.052
128.57,104.51,0.052
128.59,104.69,0.052
128.61,104.87,0.052
128.63,105.06,0.052
128.64,105.24,0.052
128.66,105.42,0.052
128.68,105.61,0.053
128.70,105.79,0.053
128.72,105.97,0.053
128.74,106.16,0.053
128.75,106.34,0.053
128.77,106.52,0.053
128.79,106.71,0.053
128.81,106.89,0.053
128.83,107.07,0.053
128.85,107.26,0.054
128.86,107.44,0.054
128.88,107.62,0.054
128.90,107.80,0.054
128.92,107.99,0.054
128.94,108.17,0.054
128.95,108.35,0.054
128.97,108.54,0.055
128.99,108.72,0.055
129.01,108.90,0.055
129.03,109.09,0.055
129.05,109.27,0.055
129.06,109.45,0.055
129.08,109.64,0.055
129.10,109.82,0.055
129.12,110.00,0.056
129.14,110.19,0.056
129.16,110.37,0.056
129.18,110.55,0.056
129.19,110.74,0.056
129.21,110.92,0.056
129.23,111.10,0.056
129.25,111.29,0.056
129.27,111.47,0.057
129.29,111.65,0.057
129.30,111.84,0.057
129.32,112.02,0.057
129.34,112.20,0.057
129.36,112.39,0.057
129.38,112.57,0.057
129.40,112.75,0.057
129.41,112.94,0.057
129.43,113.12,0.058
129.45,113.30,0.058
129.47,113.49,0.058
129.49,113.67,0.058
129.50,113.85,0.058
129.52,114.04,0.058
129.54,114.22,0.058
129.56,114.40,0.058
129.58,114.59,0.058
129.60,114.77,0.058
129.61,114.95,0.058
129.63,115.14,0.058
129.65,115.32,0.059
129.67,115.50,0.059
129.69,115.69,0.059
129.71,115.87,0.059
129.73,116.05,0.059
129.74,116.24,0.059
129.76,116.42,0.059
129.78,116.60,0.059
129.80,116.79,0.059
129.82,116.97,0.059
129.84,117.15,0.059
129.85,117.34,0.059
129.87,117.52,0.059
129.89,117.71,0.059
129.91,117.89,0.059
129.93,118.07,0.059
129.95,118.26,0.059
129.96,118.44,0.059
129.98,118.62,0.060
130.00,118.81,0.060
130.02,118.99,0.060
130.04,119.17,0.060
130.05,119.36,0.060
130.07,119.54,0.060
130.09,119.72,0.060
130.11,119.91,0.060
130.13,120.09,0.060
130.15,120.28,0.060
130.16,120.46,0.060
130.18,120.64,0.060
130.20,120.83,0.060
130.22,121.01,0.060
130.24,121.19,0.060
130.26,121.37,0.060
130.28,121.56,0.060
130.29,121.74,0.060
130.31,121.92,0.060
130.33,122.11,0.060
130.35,122.29,0.060
130.37,122.48,0.060
130.39,122.66,0.060
130.40,122.84,0.060
130.42,123.03,0.060
130.44,123.21,0.060
130.46,123.39,0.060
130.48,123.58,0.060
130.50,123.76,0.060
130.51,123.94,0.060
130.53,124.13,0.060
130.55,124.31,0.060
130.57,124.49,0.060
130.59,124.68,0.060
130.60,124.86,0.060
130.62,125.04,0.060
130.64,125.23,0.060
130.66,125.41,0.060
130.68,125.59,0.060
130.70,125.78,0.060
130.71,125.96,0.060
130.73,126.14,0.060
130.75,126.33,0.060
130.77,126.51,0.060
130.79,126.69,0.060
130.81,126.88,0.060
130.83,127.06,0.060
130.84,127.25,0.060
130.86,127.43,0.060
130.88,127.61,0.060
130.90,127.80,0.060
130.92,127.98,0.060
130.94,128.16,0.060
130.95,128.35,0.060
130.97,128.53,0.060
130.99,128.71,0.060
131.01,128.90,0.060
131.03,129.08,0.060
131.05,129.26,0.060
131.06,129.45,0.060
131.08,129.63,0.060
131.10,129.81,0.060
131.12,130.00,0.060
131.14,130.18,0.060
131.15,130.36,0.060
131.17,130.55,0.060
131.19,130.73,0.060
131.21,130.91,0.060
131.23,131.10,0.060
131.25,131.28,0.060
131.26,131.47,0.060
131.28,131.65,0.060
131.30,131.83,0.060
131.32,132.01,0.060
131.34,132.20,0.060
131.36,132.38,0.060
131.38,132.57,0.060
131.39,132.75,0.060
131.41,132.93,0.060
131.43,133.12,0.060
131.45,133.30,0.060
131.47,133.48,0.060
131.49,133.67,0.060
131.50,133.85,0.060
131.52,134.04,0.060
131.54,134.22,0.060
131.56,134.40,0.060
131.58,134.59,0.061
131.60,134.77,0.061
131.61,134.95,0.061
131.63,135.14,0.061
131.65,135.32,0.061
131.67,135.50,0.061
131.69,135.69,0.061
131.70,135.87,0.061
131.72,136.05,0.061
131.74,136.24,0.061
131.76,136.42,0.061
131.78,136.60,0.061
131.80,136.79,0.061
131.81,136.97,0.061
131.83,137.15,0.061
131.85,137.34,0.061
131.87,137.52,0.061
131.89,137.70,0.061
131.91,137.89,0.061
131.93,138.07,0.061
131.94,138.26,0.061
131.96,138.44,0.061
131.98,138.62,0.061
132.00,138.81,0.061
132.02,138.99,0.061
132.04,139.17,0.061
132.05,139.36,0.061
132.07,139.54,0.061
132.09,139.72,0.061
132.11,139.91,0.061
132.13,140.09,0.061
132.15,140.27,0.061
132.16,140.46,0.061
132.18,140.64,0.061
132.20,140.82,0.061
132.22,141.01,0.061
132.24,141.19,0.061
132.25,141.37,0.061
132.27,141.56,0.061
132.29,141.74,0.061
132.31,141.92,0.061
132.33,142.11,0.061
132.35,142.29,0.061
132.36,142.48,0.061
132.38,142.66,0.061
132.40,142.84,0.061
132.42,143.02,0.061
132.44,143.21,0.061
132.46,143.39,0.061
132.48,143.58,0.061
132.49,143.76,0.061
132.51,143.94,0.061
132.53,144.13,0.061
132.55,144.31,0.061
132.57,144.50,0.061
132.59,144.68,0.061
132.60,144.86,0.061
132.62,145.04,0.061
132.64,145.23,0.061
132.66,145.41,0.061
132.68,145.60,0.062
132.70,145.78,0.062
132.71,145.96,0.062
132.73,146.14,0.062
132.75,146.33,0.062
132.77,146.51,0.062
132.79,146.69,0.062
132.80,146.88,0.062
132.82,147.06,0.062
132.84,147.24,0.062
132.86,147.43,0.062
132.88,147.61,0.062
132.90,147.79,0.062
132.91,147.98,0.062
132.93,148.16,0.062
132.95,148.34,0.062
132.97,148.53,0.062
132.99,148.71,0.062
133.01,148.90,0.062
133.03,149.08,0.062
133.04,149.26,0.062
133.06,149.45,0.062
133.08,149.63,0.062
133.10,149.81,0.062
133.12,150.00,0.062
133.14,150.18,0.062
133.15,150.36,0.062
133.17,150.55,0.062
133.19,150.73,0.062
133.21,150.91,0.062
133.23,151.10,0.062
133.25,151.28,0.062
133.26,151.46,0.062
133.28,151.65,0.062
133.30,151.83,0.062
133.32,152.01,0.062
133.34,152.20,0.062
133.35,152.38,0.062
133.37,152.57,0.062
133.39,152.75,0.062
133.41,152.94,0.062
133.43,153.12,0.062
133.45,153.30,0.062
133.46,153.49,0.062
133.48,153.67,0.062
133.50,153.85,0.062
133.52,154.04,0.062
133.54,154.22,0.062
133.56,154.40,0.062
133.58,154.59,0.062
133.59,154.77,0.062
133.61,154.95,0.062
133.63,155.14,0.062
133.65,155.32,0.062
133.67,155.50,0.062
133.69,155.69,0.062
133.70,155.87,0.062
133.72,156.05,0.062
133.74,156.24,0.062
133.76,156.42,0.062
133.78,156.61,0.062
133.80,156.79,0.062
133.81,156.97,0.062
133.83,157.16,0.062
133.85,157.34,0.062
133.87,157.52,0.062
133.89,157.71,0.062
133.90,157.89,0.062
133.92,158.07,0.062
133.94,158.25,0.062
133.96,158.44,0.062
133.98,158.62,0.063
134.00,158.81,0.063
134.01,158.99,0.063
134.03,159.17,0.063
134.05,159.35,0.063
134.07,159.54,0.063
134.09,159.72,0.063
134.11,159.91,0.063
134.13,160.09,0.063
134.14,160.27,0.063
134.16,160.46,0.063
134.18,160.64,0.063
134.20,160.82,0.063
134.22,161.01,0.063
134.24,161.19,0.063
134.25,161.37,0.063
134.27,161.56,0.063
134.29,161.74,0.063
134.31,161.92,0.063
134.33,162.11,0.063
134.35,162.29,0.063
134.36,162.47,0.063
134.38,162.65,0.063
134.40,162.84,0.063
134.42,163.02,0.063
134.44,163.20,0.063
134.45,163.39,0.063
134.47,163.57,0.063
134.49,163.75,0.063
134.51,163.94,0.063
134.53,164.12,0.063
134.55,164.31,0.063
134.56,164.49,0.063
134.58,164.67,0.063
134.60,164.86,0.063
134.62,165.04,0.063
134.64,165.22,0.063
134.66,165.41,0.063
134.68,165.59,0.063
134.69,165.78,0.063
134.71,165.96,0.063
134.73,166.14,0.063
134.75,166.32,0.063
134.77,166.51,0.063
134.79,166.69,0.063
134.80,166.87,0.063
134.82,167.06,0.063
134.84,167.24,0.063
134.86,167.42,0.063
134.88,167.61,0.063
134.90,167.79,0.063
134.91,167.98,0.063
134.93,168.16,0.063
134.95,168.34,0.063
134.97,168.53,0.063
134.99,168.71,0.063
135.00,168.89,0.063
135.02,169.08,0.063
135.04,169.26,0.063
135.06,169.44,0.063
135.08,169.63,0.063
135.10,169.81,0.063
135.11,170.00,0.063
135.13,170.18,0.064
135.15,170.36,0.064
135.17,170.55,0.064
135.19,170.73,0.064
135.21,170.91,0.064
135.23,171.10,0.064
135.24,171.28,0.064
135.26,171.46,0.064
135.28,171.65,0.064
135.30,171.83,0.064
135.32,172.01,0.064
135.34,172.20,0.064
135.35,172.38,0.064
135.37,172.56,0.064
135.39,172.75,0.064
135.41,172.93,0.064
135.43,173.11,0.064
135.45,173.30,0.064
135.46,173.48,0.064
135.48,173.66,0.064
135.50,173.85,0.064
135.52,174.03,0.064
135.54,174.21,0.064
135.55,174.40,0.064
135.57,174.58,0.064
135.59,174.77,0.064
135.61,174.95,0.064
135.63,175.13,0.064
135.65,175.31,0.064
135.66,175.50,0.064
135.68,175.68,0.064
135.70,175.86,0.064
135.72,176.05,0.064
135.74,176.23,0.064
135.76,176.41,0.064
135.78,176.60,0.064
135.79,176.78,0.064
135.81,176.97,0.064
135.83,177.15,0.064
135.85,177.33,0.064
135.87,177.51,0.064
135.89,177.70,0.064
135.90,177.88,0.064
135.92,178.07,0.064
135.94,178.25,0.064
135.96,178.43,0.064
135.98,178.62,0.064
136.00,178.80,0.064
136.01,178.98,0.064
136.03,179.17,0.064
136.05,179.35,0.064
136.07,179.53,0.064
136.09,179.72,0.064
136.10,179.90,0.064
136.12,180.08,0.064
136.14,180.27,0.064
136.16,180.45,0.064
136.18,180.63,0.064
136.20,180.82,0.064
136.21,181.00,0.064
136.23,181.18,0.064
136.25,181.37,0.064
136.27,181.55,0.064
136.29,181.74,0.064
136.31,181.92,0.065
136.33,182.10,0.065
136.34,182.29,0.065
136.36,182.47,0.065
136.38,182.65,0.065
136.40,182.84,0.065
136.42,183.02,0.065
136.44,183.20,0.065
136.45,183.39,0.065
136.47,183.57,0.065
136.49,183.75,0.065
136.51,183.94,0.065
136.53,184.12,0.065
136.55,184.31,0.065
136.56,184.49,0.065
136.58,184.67,0.065
136.60,184.85,0.065
136.62,185.04,0.065
136.64,185.22,0.065
136.65,185.40,0.065
136.67,185.59,0.065
136.69,185.77,0.065
136.71,185.96,0.065
136.73,186.14,0.065
136.75,186.32,0.065
136.77,186.50,0.065
136.78,186.69,0.065
136.80,186.87,0.065
136.82,187.06,0.065
136.84,187.24,0.065
136.86,187.42,0.065
136.88,187.61,0.065
136.89,187.79,0.065
136.91,187.98,0.065
136.93,188.16,0.065
136.95,188.34,0.065
136.97,188.53,0.065
136.98,188.71,0.065
137.00,188.89,0.065
137.02,189.07,0.065
137.04,189.26,0.065
137.06,189.44,0.065
137.08,189.62,0.065
137.10,189.81,0.065
137.11,189.99,0.065
137.13,190.17,0.065
137.15,190.36,0.065
137.17,190.54,0.065
137.19,190.72,0.065
137.20,190.91,0.065
137.22,191.09,0.065
137.24,191.27,0.065
137.26,191.46,0.065
137.28,191.64,0.065
137.30,191.83,0.065
137.32,192.01,0.065
137.33,192.19,0.065
137.35,192.38,0.065
137.37,192.56,0.065
137.39,192.74,0.065
137.41,192.93,0.065
137.43,193.11,0.065
137.44,193.29,0.065
137.46,193.48,0.065
137.48,193.66,0.065
137.50,193.84,0.065
137.52,194.03,0.066
137.53,194.21,0.066
137.55,194.40,0.066
137.57,194.58,0.066
137.59,194.76,0.066
137.61,194.94,0.066
137.63,195.13,0.066
137.65,195.31,0.066
137.66,195.50,0.066
137.68,195.68,0.066
137.70,195.86,0.066
137.72,196.05,0.066
137.74,196.23,0.066
137.75,196.41,0.066
137.77,196.60,0.066
137.79,196.78,0.066
137.81,196.96,0.066
137.83,197.15,0.066
137.85,197.33,0.066
137.87,197.51,0.066
137.88,197.70,0.066
137.90,197.88,0.066
137.92,198.06,0.066
137.94,198.25,
137.96,198.43,
137.98,198.61,
137.99,,
138.00,,