File: DSC/Olivia/2025_08_11_1CBN_3PVP29_MP_n60C_200C_10Cmin_x3.csv
Filename,2025_08_11_1CBN_3PVP29_MP_n60C_200C_10Cmin_x3
Instrument name,DSC2A-00468 (192.168.1.100)
Operator,Yarger
rundate,8/11/2025
Sample name,2025_08_11_1CBN_3PVP29_MP_n60C_200C_10Cmin_x3
proceduresegments,Data Off ; Equilibrate -60.00 °C; Data On ; Ramp 10.00 °C/min to 200.00 °C; Data Off ; Isothermal 2.0 min; Data On ; Ramp 10.00 °C/min to -60.00 °C; Data Off ; Isothermal 2.0 min; Data On ; Ramp 10.00 °C/min to 200.00 °C; Data Off ; Isothermal 2.0 min; Data On ; Ramp 10.00 °C/min to -60.00 °C; Data Off ; Isothermal 2.0 min; Data On ; Ramp 10.00 °C/min to 200.00 °C
[File Parameters]
Run date,8/11/2025 5:38:49 PM
Trios version,5.1.1.46572
Original File Name,
Current File Name,D:\DSC2500\JYarger\2025_08_11_1CBN_3PVP29_MP_n60C_200C_10Cmin_x3.tri
[Procedure]
Procedure Name,TS_n60C_200C_10Cmin_x3
Sample Name,2025_08_11_1CBN_3PVP29_MP_n60C_200C_10Cmin_x3
Sample Mass,8.05 mg
Reference Sample Mass,0 mg
Pan Mass,32.64 mg
Pan Number,14
Reference Pan Mass,32.42 mg
Reference Pan Number,10
Pan Type,Aluminum
Comments,Thermal support Al pans/lids. DSC_Samples_A2_Tray_August2025 google sheet.
Project Name,Pharma
Operator,Yarger
Test,Custom
Unload Max Temperature,30
Unload Min Temperature,30
Load Max Temperature,30
Load Min Temperature,30
Stop on Gas Flow Error,Yes
[Signal List]
Signal #1,Time (min)
Signal #2,Temperature (°C)
Signal #3,Heat Flow (mW)
Signal #4,Delta T (µV)
Signal #5,Delta Tzero (µV)
Signal #6,Tzero Temperature (°C)
Signal #7,Cell Purge (mL/min)
Signal #8,Heater Temp (°C)
Signal #9,Power Delivered (W)
Signal #10,Reference Junction Temperature (°C)
Signal #11,Flange Temperature (°C)
Signal #12,Heat Flow Phase (rad)
Signal #13,Total Heat Capacity (J/°C)
Signal #14,Heat Capacity (J/°C)
[Configuration]
Company Name,ASU
Instrument Name,DSC2A-00468
Instrument Type,DSC2500
Serial Number,DSC2A-00468
IP,192.168.1.100
Location of Instrument,MRRC
DisplayType,Unknown
Sample Interval ,0.1 s/pt
Selected Heat Flow,T4P
Exotherm Direction,Down
Cell Serial,DRC2-00792
Lid Type,Standard
Cooler,RCS 90
Leave Cooler on at End of Sequence,On
Gas 2,Nitrogen
Gas Selected,Channel 1
Flow Rate,50 mL/min
Secondary Purge,On
Licensed Heat Flow,Heat Flow T4P
Modulation Licensed,Yes
[Versions]
Common IDD Version,1
Cortex Version,VER 2.10.2.31
Driver,5.0.0.6
GDM Version,1.0.3.3
TouchscreenVersion,1.0.0.16145
FEP Version,1.2.1.21
FEP Bootloader,2.0.0.5
AutoSampler Version,2.1.1.26
Auto Sampler Bootloader,2.0.0.5
FCM Version,1.1.0.3
FCM Bootloader,2.0.0.5
[Experiment Logs]
Experiment Log Entry # 1,Data On set to 0
Experiment Log Entry # 3,Equilibrate Segment -60 (C) Started
Experiment Log Entry # 5,Air Cool is off.
Experiment Log Entry # 7,Data On set to 1
Experiment Log Entry # 9,Ramp Segment 10 C/min to 200 Started
Experiment Log Entry # 11,Data On set to 0
Experiment Log Entry # 13,Isothermal Segment 2 min started
Experiment Log Entry # 15,Data On set to 1
Experiment Log Entry # 17,Ramp Segment 10 C/min to -60 Started
Experiment Log Entry # 19,Data On set to 0
Experiment Log Entry # 21,Isothermal Segment 2 min started
Experiment Log Entry # 23,Data On set to 1
Experiment Log Entry # 25,Ramp Segment 10 C/min to 200 Started
Experiment Log Entry # 27,Data On set to 0
Experiment Log Entry # 29,Isothermal Segment 2 min started
Experiment Log Entry # 31,Data On set to 1
Experiment Log Entry # 33,Ramp Segment 10 C/min to -60 Started
Experiment Log Entry # 35,Data On set to 0
Experiment Log Entry # 37,Isothermal Segment 2 min started
Experiment Log Entry # 39,Data On set to 1
Experiment Log Entry # 41,Ramp Segment 10 C/min to 200 Started
[Method Log]
Method Log Entry # 1,Data Off
Method Log Entry # 2,Equilibrate -60 °C
Method Log Entry # 3,Data On
Method Log Entry # 4,(Ramp 1152211) Ramp 10 °C/minute to 200 °C
Method Log Entry # 5,Data Off
Method Log Entry # 6,Isothermal 2 minutes
Method Log Entry # 7,Data On
Method Log Entry # 8,(Ramp 1152215) Ramp 10 °C/minute to -60 °C
Method Log Entry # 9,Data Off
Method Log Entry # 10,Isothermal 2 minutes
Method Log Entry # 11,Data On
Method Log Entry # 12,(Ramp 1152219) Ramp 10 °C/minute to 200 °C
Method Log Entry # 13,Data Off
Method Log Entry # 14,Isothermal 2 minutes
Method Log Entry # 15,Data On
Method Log Entry # 16,(Ramp 1152223) Ramp 10 °C/minute to -60 °C
Method Log Entry # 17,Data Off
Method Log Entry # 18,Isothermal 2 minutes
Method Log Entry # 19,Data On
Method Log Entry # 20,(Ramp 1152227) Ramp 10 °C/minute to 200 °C
Cell Serial,DRC2-00792
[T1 Calibration]
Slope,-0.008529666
Offset,9.636258
Initial Temperature,98.23
GUID,f8bfdadc-4977-4fdf-ba6d-0ba9134940c3
[TZero Calibration]
Date Applied,11/29/2022 4:06:13 PM
Description,From -89.059 °C to 396.009 °C at 20.000°C/min
Gas Type,Nitrogen
Pan Type,None
Source Files 1,C:\Users\yargerlab\Desktop\DSC Data\General\TZero_calibration_11_29_22_2nd(2).tri
Source Files 2,C:\Users\yargerlab\Desktop\DSC Data\General\TZero_calibration_11_29_22_2nd(3).tri
Delta T Offset,13.05235
Delta T Slope,-0.007271007
Delta T0 Offset,-13.69128
Delta T0 Slope,0.06063341
[Temperature Calibration]
Date Applied,11/29/2022 7:12:28 PM
Description,From 106.590 °C to 186.590 °C at 10.000°C/min
Gas Type,Nitrogen
Pan Type,Tzero Aluminum Hermetic
Source Files 1,C:\Users\yargerlab\Desktop\DSC Data\General\Indium(6).tri
Measured 1,157.391
Known 1,156.598
[Cell Constant Calibration]
Date Applied,11/29/2022 7:12:29 PM
Description,From 106.590 °C to 186.590 °C at 10.000°C/min
Gas Type,Nitrogen
Pan Type,Tzero Aluminum Hermetic
Source Files 1,C:\Users\yargerlab\Desktop\DSC Data\General\Indium(6).tri
T4P KCell,1.006051
Onset Slope,63.26126 mW/°C
[Direct Cp Calibration]
Date Applied,11/30/2022 11:04:51 AM
Description,From -79.983 °C to 298.409 °C at 10.000°C/min
Gas Type,Nitrogen
Pan Type,Tzero Aluminum Hermetic
Source Files 1,C:\Users\yargerlab\Desktop\DSC Data\General\Sapphire_Heat_Capacity_11_30_22.tri
[Rev Cp Calibration]
Date Applied,11/30/2022 1:58:51 PM
Description,From -79.996 °C to 292.812 °C at 3.000°C/min
Gas Type,Nitrogen
Pan Type,Tzero Aluminum Hermetic
Source Files 1,C:\Users\yargerlab\Desktop\DSC Data\General\Sapphire_MDSC_Calibration_11_30_22.tri
[step]
Ramp 10.00 °C/min to 200.00 °C
Time,Temperature,Heat Flow (Normalized)
min,°C,W/g
0.00,-59.81,-0.030
0.02,-59.81,-0.028
0.04,-59.81,-0.025
0.05,-59.80,-0.024
0.07,-59.78,-0.024
0.09,-59.72,-0.024
0.11,-59.65,-0.015
0.13,-59.55,-0.002
0.15,-59.43,0.015
0.16,-59.30,0.033
0.18,-59.16,0.050
0.20,-59.00,0.068
0.22,-58.84,0.082
0.24,-58.68,0.095
0.26,-58.51,0.106
0.28,-58.34,0.114
0.29,-58.17,0.120
0.31,-57.99,0.125
0.33,-57.82,0.129
0.35,-57.64,0.133
0.37,-57.47,0.135
0.39,-57.29,0.137
0.40,-57.11,0.138
0.42,-56.93,0.139
0.44,-56.75,0.141
0.46,-56.58,0.141
0.48,-56.40,0.142
0.50,-56.22,0.142
0.51,-56.04,0.143
0.53,-55.86,0.143
0.55,-55.68,0.143
0.57,-55.50,0.144
0.59,-55.32,0.144
0.60,-55.14,0.145
0.62,-54.95,0.145
0.64,-54.77,0.145
0.66,-54.59,0.145
0.68,-54.41,0.146
0.70,-54.23,0.146
0.72,-54.05,0.146
0.73,-53.87,0.146
0.75,-53.69,0.147
0.77,-53.51,0.147
0.79,-53.32,0.147
0.81,-53.14,0.147
0.83,-52.96,0.147
0.84,-52.78,0.148
0.86,-52.60,0.148
0.88,-52.42,0.148
0.90,-52.23,0.148
0.92,-52.05,0.148
0.93,-51.87,0.148
0.95,-51.69,0.149
0.97,-51.50,0.149
0.99,-51.32,0.149
1.01,-51.14,0.149
1.03,-50.96,0.149
1.05,-50.77,0.150
1.06,-50.59,0.150
1.08,-50.41,0.150
1.10,-50.23,0.150
1.12,-50.04,0.150
1.14,-49.86,0.150
1.16,-49.68,0.150
1.17,-49.49,0.151
1.19,-49.31,0.151
1.21,-49.13,0.151
1.23,-48.95,0.151
1.25,-48.76,0.151
1.27,-48.58,0.151
1.28,-48.40,0.151
1.30,-48.21,0.151
1.32,-48.03,0.152
1.34,-47.85,0.152
1.36,-47.66,0.152
1.38,-47.48,0.152
1.39,-47.30,0.152
1.41,-47.12,0.152
1.43,-46.93,0.152
1.45,-46.75,0.152
1.47,-46.57,0.152
1.48,-46.38,0.153
1.50,-46.20,0.153
1.52,-46.01,0.153
1.54,-45.83,0.153
1.56,-45.65,0.153
1.58,-45.47,0.153
1.59,-45.28,0.153
1.61,-45.10,0.153
1.63,-44.92,0.153
1.65,-44.73,0.153
1.67,-44.55,0.153
1.69,-44.36,0.154
1.71,-44.18,0.154
1.72,-44.00,0.154
1.74,-43.81,0.154
1.76,-43.63,0.154
1.78,-43.45,0.154
1.80,-43.26,0.154
1.82,-43.08,0.154
1.83,-42.90,0.154
1.85,-42.72,0.154
1.87,-42.53,0.154
1.89,-42.35,0.154
1.91,-42.16,0.154
1.93,-41.98,0.154
1.94,-41.80,0.155
1.96,-41.62,0.155
1.98,-41.43,0.155
2.00,-41.25,0.155
2.02,-41.06,0.155
2.03,-40.88,0.155
2.05,-40.70,0.155
2.07,-40.51,0.155
2.09,-40.33,0.155
2.11,-40.15,0.155
2.13,-39.96,0.155
2.14,-39.78,0.155
2.16,-39.60,0.155
2.18,-39.41,0.155
2.20,-39.23,0.155
2.22,-39.05,0.155
2.24,-38.86,0.156
2.26,-38.68,0.156
2.27,-38.50,0.156
2.29,-38.31,0.156
2.31,-38.13,0.156
2.33,-37.94,0.156
2.35,-37.76,0.156
2.36,-37.58,0.156
2.38,-37.39,0.156
2.40,-37.21,0.156
2.42,-37.03,0.156
2.44,-36.84,0.156
2.46,-36.66,0.156
2.48,-36.47,0.156
2.49,-36.29,0.157
2.51,-36.11,0.157
2.53,-35.92,0.157
2.55,-35.74,0.157
2.57,-35.56,0.157
2.59,-35.37,0.157
2.60,-35.19,0.157
2.62,-35.01,0.157
2.64,-34.82,0.157
2.66,-34.64,0.157
2.68,-34.45,0.157
2.69,-34.27,0.157
2.71,-34.09,0.157
2.73,-33.90,0.157
2.75,-33.72,0.157
2.77,-33.54,0.157
2.79,-33.35,0.157
2.81,-33.17,0.158
2.82,-32.99,0.158
2.84,-32.80,0.158
2.86,-32.62,0.158
2.88,-32.44,0.158
2.90,-32.25,0.158
2.91,-32.07,0.158
2.93,-31.88,0.158
2.95,-31.70,0.158
2.97,-31.52,0.158
2.99,-31.33,0.158
3.01,-31.15,0.158
3.03,-30.97,0.158
3.04,-30.78,0.158
3.06,-30.60,0.158
3.08,-30.42,0.158
3.10,-30.23,0.159
3.12,-30.05,0.159
3.14,-29.87,0.159
3.15,-29.68,0.159
3.17,-29.50,0.159
3.19,-29.32,0.159
3.21,-29.13,0.159
3.23,-28.95,0.159
3.24,-28.76,0.159
3.26,-28.58,0.159
3.28,-28.40,0.159
3.30,-28.21,0.159
3.32,-28.03,0.159
3.34,-27.85,0.159
3.36,-27.66,0.159
3.37,-27.48,0.160
3.39,-27.30,0.160
3.41,-27.11,0.160
3.43,-26.93,0.160
3.45,-26.74,0.160
3.46,-26.56,0.160
3.48,-26.38,0.160
3.50,-26.19,0.160
3.52,-26.01,0.160
3.54,-25.83,0.160
3.56,-25.64,0.160
3.58,-25.46,0.160
3.59,-25.28,0.160
3.61,-25.09,0.161
3.63,-24.91,0.161
3.65,-24.73,0.161
3.67,-24.54,0.161
3.69,-24.36,0.161
3.70,-24.17,0.161
3.72,-23.99,0.161
3.74,-23.81,0.161
3.76,-23.62,0.161
3.78,-23.44,0.161
3.79,-23.25,0.161
3.81,-23.07,0.162
3.83,-22.89,0.162
3.85,-22.70,0.162
3.87,-22.52,0.162
3.89,-22.34,0.162
3.91,-22.15,0.162
3.92,-21.97,0.162
3.94,-21.79,0.162
3.96,-21.61,0.162
3.98,-21.42,0.162
4.00,-21.24,0.162
4.01,-21.06,0.162
4.03,-20.87,0.162
4.05,-20.69,0.162
4.07,-20.51,0.162
4.09,-20.32,0.162
4.11,-20.14,0.162
4.13,-19.96,0.163
4.14,-19.77,0.163
4.16,-19.59,0.163
4.18,-19.41,0.163
4.20,-19.22,0.163
4.22,-19.04,0.163
4.24,-18.86,0.163
4.25,-18.67,0.163
4.27,-18.49,0.163
4.29,-18.30,0.163
4.31,-18.12,0.163
4.33,-17.94,0.164
4.35,-17.75,0.164
4.36,-17.57,0.164
4.38,-17.39,0.164
4.40,-17.20,0.164
4.42,-17.02,0.164
4.44,-16.84,0.164
4.45,-16.65,0.164
4.47,-16.47,0.164
4.49,-16.28,0.164
4.51,-16.10,0.164
4.53,-15.92,0.165
4.55,-15.73,0.165
4.56,-15.55,0.165
4.58,-15.37,0.165
4.60,-15.18,0.165
4.62,-15.00,0.165
4.64,-14.81,0.165
4.66,-14.63,0.165
4.68,-14.45,0.165
4.69,-14.27,0.165
4.71,-14.08,0.166
4.73,-13.90,0.166
4.75,-13.71,0.166
4.77,-13.53,0.166
4.79,-13.35,0.166
4.80,-13.16,0.166
4.82,-12.98,0.166
4.84,-12.80,0.166
4.86,-12.61,0.166
4.88,-12.43,0.166
4.90,-12.24,0.166
4.91,-12.06,0.167
4.93,-11.88,0.167
4.95,-11.69,0.167
4.97,-11.51,0.167
4.99,-11.33,0.167
5.00,-11.14,0.167
5.02,-10.96,0.167
5.04,-10.78,0.167
5.06,-10.59,0.167
5.08,-10.41,0.167
5.10,-10.23,0.167
5.11,-10.04,0.167
5.13,-9.86,0.168
5.15,-9.68,0.168
5.17,-9.49,0.168
5.19,-9.31,0.168
5.21,-9.13,0.168
5.23,-8.94,0.168
5.24,-8.76,0.168
5.26,-8.57,0.168
5.28,-8.39,0.168
5.30,-8.21,0.169
5.32,-8.02,0.169
5.34,-7.84,0.169
5.35,-7.66,0.169
5.37,-7.47,0.169
5.39,-7.29,0.169
5.41,-7.11,0.169
5.43,-6.92,0.169
5.45,-6.74,0.169
5.46,-6.56,0.170
5.48,-6.37,0.170
5.50,-6.19,0.170
5.52,-6.01,0.170
5.54,-5.82,0.170
5.55,-5.64,0.170
5.57,-5.45,0.170
5.59,-5.27,0.170
5.61,-5.09,0.170
5.63,-4.90,0.170
5.65,-4.72,0.171
5.66,-4.54,0.171
5.68,-4.36,0.171
5.70,-4.17,0.171
5.72,-3.99,0.171
5.74,-3.80,0.171
5.76,-3.62,0.171
5.78,-3.44,0.171
5.79,-3.26,0.172
5.81,-3.07,0.172
5.83,-2.89,0.172
5.85,-2.70,0.172
5.87,-2.52,0.172
5.89,-2.34,0.172
5.90,-2.15,0.172
5.92,-1.97,0.172
5.94,-1.79,0.173
5.96,-1.60,0.173
5.98,-1.42,0.173
6.00,-1.23,0.173
6.01,-1.05,0.173
6.03,-0.87,0.173
6.05,-0.68,0.173
6.07,-0.50,0.173
6.09,-0.32,0.174
6.10,-0.13,0.174
6.12,0.05,0.174
6.14,0.23,0.174
6.16,0.42,0.174
6.18,0.60,0.174
6.20,0.78,0.174
6.21,0.97,0.174
6.23,1.15,0.174
6.25,1.33,0.175
6.27,1.52,0.175
6.29,1.70,0.175
6.31,1.88,0.175
6.33,2.07,0.175
6.34,2.25,0.175
6.36,2.43,0.175
6.38,2.62,0.175
6.40,2.80,0.176
6.42,2.99,0.176
6.44,3.17,0.176
6.45,3.35,0.176
6.47,3.54,0.176
6.49,3.72,0.176
6.51,3.90,0.176
6.53,4.09,0.176
6.55,4.27,0.177
6.56,4.45,0.177
6.58,4.64,0.177
6.60,4.82,0.177
6.62,5.00,0.177
6.64,5.19,0.177
6.65,5.37,0.177
6.67,5.55,0.177
6.69,5.74,0.178
6.71,5.92,0.178
6.73,6.11,0.178
6.75,6.29,0.178
6.76,6.47,0.178
6.78,6.65,0.178
6.80,6.84,0.178
6.82,7.02,0.178
6.84,7.21,0.179
6.86,7.39,0.179
6.88,7.57,0.179
6.89,7.76,0.179
6.91,7.94,0.179
6.93,8.12,0.179
6.95,8.31,0.179
6.97,8.49,0.180
6.99,8.68,0.180
7.00,8.86,0.180
7.02,9.04,0.180
7.04,9.22,0.180
7.06,9.41,0.180
7.08,9.59,0.180
7.10,9.78,0.181
7.11,9.96,0.181
7.13,10.14,0.181
7.15,10.32,0.181
7.17,10.51,0.181
7.19,10.69,0.181
7.20,10.88,0.181
7.22,11.06,0.181
7.24,11.24,0.182
7.26,11.43,0.182
7.28,11.61,0.182
7.30,11.79,0.182
7.31,11.98,0.182
7.33,12.16,0.182
7.35,12.34,0.183
7.37,12.53,0.183
7.39,12.71,0.183
7.41,12.90,0.183
7.43,13.08,0.183
7.44,13.26,0.183
7.46,13.45,0.183
7.48,13.63,0.184
7.50,13.81,0.184
7.52,14.00,0.184
7.54,14.18,0.184
7.55,14.36,0.184
7.57,14.55,0.184
7.59,14.73,0.185
7.61,14.91,0.185
7.63,15.10,0.185
7.65,15.28,0.185
7.66,15.46,0.185
7.68,15.65,0.185
7.70,15.83,0.185
7.72,16.01,0.186
7.74,16.20,0.186
7.75,16.38,0.186
7.77,16.56,0.186
7.79,16.74,0.186
7.81,16.93,0.186
7.83,17.11,0.186
7.85,17.30,0.187
7.86,17.48,0.187
7.88,17.66,0.187
7.90,17.85,0.187
7.92,18.03,0.187
7.94,18.21,0.187
7.96,18.40,0.188
7.98,18.58,0.188
7.99,18.76,0.188
8.01,18.95,0.188
8.03,19.13,0.188
8.05,19.31,0.188
8.07,19.50,0.189
8.09,19.68,0.189
8.10,19.86,0.189
8.12,20.05,0.189
8.14,20.23,0.189
8.16,20.41,0.190
8.18,20.60,0.190
8.20,20.78,0.190
8.21,20.97,0.190
8.23,21.15,0.190
8.25,21.33,0.190
8.27,21.52,0.191
8.29,21.70,0.191
8.30,21.88,0.191
8.32,22.07,0.191
8.34,22.25,0.191
8.36,22.43,0.191
8.38,22.62,0.192
8.40,22.80,0.192
8.41,22.98,0.192
8.43,23.17,0.192
8.45,23.35,0.192
8.47,23.53,0.192
8.49,23.72,0.193
8.51,23.90,0.193
8.53,24.08,0.193
8.54,24.27,0.193
8.56,24.45,0.193
8.58,24.63,0.194
8.60,24.82,0.194
8.62,25.00,0.194
8.63,25.19,0.194
8.65,25.37,0.194
8.67,25.55,0.195
8.69,25.74,0.195
8.71,25.92,0.195
8.73,26.10,0.195
8.75,26.29,0.195
8.76,26.47,0.196
8.78,26.65,0.196
8.80,26.84,0.196
8.82,27.02,0.196
8.84,27.20,0.196
8.85,27.39,0.196
8.87,27.57,0.197
8.89,27.75,0.197
8.91,27.94,0.197
8.93,28.12,0.197
8.95,28.30,0.197
8.97,28.49,0.198
8.98,28.67,0.198
9.00,28.86,0.198
9.02,29.04,0.198
9.04,29.22,0.198
9.06,29.41,0.198
9.08,29.59,0.199
9.09,29.77,0.199
9.11,29.96,0.199
9.13,30.14,0.199
9.15,30.32,0.199
9.17,30.51,0.200
9.18,30.69,0.200
9.20,30.87,0.200
9.22,31.06,0.200
9.24,31.24,0.200
9.26,31.42,0.200
9.28,31.61,0.201
9.30,31.79,0.201
9.31,31.97,0.201
9.33,32.16,0.201
9.35,32.34,0.201
9.37,32.52,0.202
9.39,32.71,0.202
9.40,32.89,0.202
9.42,33.08,0.202
9.44,33.26,0.202
9.46,33.44,0.203
9.48,33.63,0.203
9.50,33.81,0.203
9.52,33.99,0.203
9.53,34.18,0.203
9.55,34.36,0.204
9.57,34.54,0.204
9.59,34.73,0.204
9.61,34.91,0.204
9.63,35.09,0.204
9.64,35.28,0.204
9.66,35.46,0.205
9.68,35.64,0.205
9.70,35.83,0.205
9.72,36.01,0.205
9.73,36.19,0.205
9.75,36.38,0.206
9.77,36.56,0.206
9.79,36.74,0.206
9.81,36.93,0.206
9.83,37.11,0.206
9.85,37.29,0.207
9.86,37.48,0.207
9.88,37.66,0.207
9.90,37.85,0.207
9.92,38.03,0.207
9.94,38.21,0.208
9.95,38.40,0.208
9.97,38.58,0.208
9.99,38.76,0.208
10.01,38.95,0.208
10.03,39.13,0.209
10.05,39.31,0.209
10.07,39.50,0.209
10.08,39.68,0.209
10.10,39.86,0.209
10.12,40.05,0.210
10.14,40.23,0.210
10.16,40.41,0.210
10.18,40.60,0.210
10.19,40.78,0.210
10.21,40.96,0.211
10.23,41.15,0.211
10.25,41.33,0.211
10.27,41.51,0.211
10.28,41.70,0.211
10.30,41.88,0.212
10.32,42.06,0.212
10.34,42.25,0.212
10.36,42.43,0.212
10.38,42.61,0.212
10.40,42.80,0.213
10.41,42.98,0.213
10.43,43.17,0.213
10.45,43.35,0.213
10.47,43.53,0.213
10.49,43.72,0.214
10.50,43.90,0.214
10.52,44.08,0.214
10.54,44.27,0.214
10.56,44.45,0.214
10.58,44.63,0.215
10.60,44.82,0.215
10.62,45.00,0.215
10.63,45.18,0.215
10.65,45.37,0.215
10.67,45.55,0.216
10.69,45.73,0.216
10.71,45.92,0.216
10.73,46.10,0.216
10.74,46.28,0.217
10.76,46.47,0.217
10.78,46.65,0.217
10.80,46.83,0.217
10.82,47.02,0.217
10.83,47.20,0.218
10.85,47.39,0.218
10.87,47.57,0.218
10.89,47.75,0.218
10.91,47.94,0.218
10.93,48.12,0.219
10.95,48.30,0.219
10.96,48.49,0.219
10.98,48.67,0.219
11.00,48.85,0.219
11.02,49.04,0.220
11.04,49.22,0.220
11.05,49.40,0.220
11.07,49.59,0.220
11.09,49.77,0.221
11.11,49.95,0.221
11.13,50.14,0.221
11.15,50.32,0.221
11.17,50.50,0.221
11.18,50.69,0.222
11.20,50.87,0.222
11.22,51.05,0.222
11.24,51.24,0.222
11.26,51.42,0.222
11.28,51.60,0.223
11.29,51.79,0.223
11.31,51.97,0.223
11.33,52.15,0.223
11.35,52.34,0.224
11.37,52.52,0.224
11.38,52.71,0.224
11.40,52.89,0.224
11.42,53.07,0.225
11.44,53.26,0.225
11.46,53.44,0.225
11.48,53.62,0.225
11.50,53.81,0.225
11.51,53.99,0.226
11.53,54.17,0.226
11.55,54.36,0.226
11.57,54.54,0.226
11.59,54.72,0.226
11.60,54.91,0.227
11.62,55.09,0.227
11.64,55.27,0.227
11.66,55.46,0.227
11.68,55.64,0.228
11.70,55.82,0.228
11.72,56.01,0.228
11.73,56.19,0.228
11.75,56.37,0.228
11.77,56.56,0.229
11.79,56.74,0.229
11.81,56.92,0.229
11.83,57.11,0.229
11.84,57.29,0.230
11.86,57.47,0.230
11.88,57.66,0.230
11.90,57.84,0.230
11.92,58.02,0.230
11.93,58.21,0.231
11.95,58.39,0.231
11.97,58.57,0.231
11.99,58.76,0.231
12.01,58.94,0.232
12.03,59.13,0.232
12.05,59.31,0.232
12.06,59.49,0.232
12.08,59.67,0.232
12.10,59.86,0.233
12.12,60.04,0.233
12.14,60.22,0.233
12.15,60.41,0.233
12.17,60.59,0.234
12.19,60.77,0.234
12.21,60.96,0.234
12.23,61.14,0.234
12.25,61.33,0.235
12.27,61.51,0.235
12.28,61.69,0.235
12.30,61.88,0.235
12.32,62.06,0.235
12.34,62.24,0.236
12.36,62.43,0.236
12.38,62.61,0.236
12.39,62.79,0.237
12.41,62.98,0.237
12.43,63.16,0.237
12.45,63.34,0.237
12.47,63.53,0.237
12.48,63.71,0.238
12.50,63.89,0.238
12.52,64.08,0.238
12.54,64.26,0.238
12.56,64.44,0.238
12.58,64.63,0.239
12.60,64.81,0.239
12.61,64.99,0.239
12.63,65.18,0.239
12.65,65.36,0.240
12.67,65.54,0.240
12.69,65.73,0.240
12.70,65.91,0.240
12.72,66.09,0.240
12.74,66.28,0.241
12.76,66.46,0.241
12.78,66.64,0.241
12.80,66.83,0.241
12.82,67.01,0.241
12.83,67.20,0.242
12.85,67.38,0.242
12.87,67.56,0.242
12.89,67.75,0.242
12.91,67.93,0.243
12.93,68.11,0.243
12.94,68.30,0.243
12.96,68.48,0.243
12.98,68.66,0.243
13.00,68.85,0.244
13.02,69.03,0.244
13.03,69.21,0.244
13.05,69.39,0.244
13.07,69.58,0.244
13.09,69.76,0.245
13.11,69.95,0.245
13.13,70.13,0.245
13.15,70.31,0.245
13.16,70.50,0.245
13.18,70.68,0.246
13.20,70.86,0.246
13.22,71.05,0.246
13.24,71.23,0.246
13.25,71.41,0.246
13.27,71.60,0.247
13.29,71.78,0.247
13.31,71.96,0.247
13.33,72.15,0.247
13.35,72.33,0.247
13.37,72.51,0.248
13.38,72.70,0.248
13.40,72.88,0.248
13.42,73.06,0.248
13.44,73.25,0.248
13.46,73.43,0.248
13.48,73.61,0.249
13.49,73.80,0.249
13.51,73.98,0.249
13.53,74.16,0.249
13.55,74.35,0.249
13.57,74.53,0.250
13.58,74.72,0.250
13.60,74.90,0.250
13.62,75.08,0.250
13.64,75.27,0.250
13.66,75.45,0.250
13.68,75.63,0.251
13.70,75.82,0.251
13.71,76.00,0.251
13.73,76.18,0.251
13.75,76.37,0.251
13.77,76.55,0.251
13.79,76.73,0.252
13.80,76.92,0.252
13.82,77.10,0.252
13.84,77.28,0.252
13.86,77.47,0.252
13.88,77.65,0.253
13.90,77.83,0.253
13.92,78.02,0.253
13.93,78.20,0.253
13.95,78.38,0.253
13.97,78.57,0.253
13.99,78.75,0.254
14.01,78.93,0.254
14.03,79.12,0.254
14.04,79.30,0.254
14.06,79.48,0.254
14.08,79.67,0.254
14.10,79.85,0.255
14.12,80.04,0.255
14.13,80.22,0.255
14.15,80.40,0.255
14.17,80.58,0.255
14.19,80.77,0.256
14.21,80.95,0.256
14.23,81.14,0.256
14.25,81.32,0.256
14.26,81.50,0.256
14.28,81.69,0.256
14.30,81.87,0.257
14.32,82.05,0.257
14.34,82.24,0.257
14.35,82.42,0.257
14.37,82.60,0.257
14.39,82.79,0.257
14.41,82.97,0.258
14.43,83.15,0.258
14.45,83.34,0.258
14.47,83.52,0.258
14.48,83.70,0.258
14.50,83.89,0.259
14.52,84.07,0.259
14.54,84.25,0.259
14.56,84.44,0.259
14.58,84.62,0.259
14.59,84.80,0.259
14.61,84.99,0.260
14.63,85.17,0.260
14.65,85.35,0.260
14.67,85.54,0.260
14.68,85.72,0.260
14.70,85.90,0.261
14.72,86.09,0.261
14.74,86.27,0.261
14.76,86.45,0.261
14.78,86.64,0.261
14.80,86.82,0.262
14.81,87.01,0.262
14.83,87.19,0.262
14.85,87.37,0.262
14.87,87.56,0.263
14.89,87.74,0.263
14.90,87.92,0.263
14.92,88.11,0.263
14.94,88.29,0.263
14.96,88.47,0.264
14.98,88.65,0.264
15.00,88.84,0.264
15.02,89.02,0.264
15.03,89.21,0.264
15.05,89.39,0.265
15.07,89.57,0.265
15.09,89.75,0.265
15.11,89.94,0.265
15.13,90.12,0.266
15.14,90.31,0.266
15.16,90.49,0.266
15.18,90.67,0.266
15.20,90.86,0.267
15.22,91.04,0.267
15.23,91.22,0.267
15.25,91.41,0.268
15.27,91.59,0.268
15.29,91.77,0.268
15.31,91.96,0.268
15.33,92.14,0.269
15.35,92.32,0.269
15.36,92.51,0.269
15.38,92.69,0.269
15.40,92.87,0.270
15.42,93.06,0.270
15.44,93.24,0.270
15.45,93.42,0.270
15.47,93.61,0.271
15.49,93.79,0.271
15.51,93.97,0.271
15.53,94.16,0.272
15.55,94.34,0.272
15.57,94.52,0.272
15.58,94.71,0.273
15.60,94.89,0.273
15.62,95.07,0.273
15.64,95.26,0.273
15.66,95.44,0.274
15.68,95.62,0.274
15.69,95.81,0.274
15.71,95.99,0.275
15.73,96.18,0.275
15.75,96.36,0.276
15.77,96.54,0.276
15.78,96.72,0.276
15.80,96.91,0.276
15.82,97.09,0.277
15.84,97.27,0.277
15.86,97.46,0.277
15.88,97.64,0.278
15.90,97.82,0.278
15.91,98.01,0.279
15.93,98.19,0.279
15.95,98.37,0.279
15.97,98.56,0.280
15.99,98.74,0.280
16.00,98.92,0.280
16.02,99.11,0.281
16.04,99.29,0.281
16.06,99.47,0.281
16.08,99.66,0.282
16.10,99.84,0.282
16.12,100.02,0.282
16.13,100.21,0.283
16.15,100.39,0.283
16.17,100.57,0.283
16.19,100.76,0.284
16.21,100.94,0.284
16.23,101.13,0.285
16.24,101.31,0.285
16.26,101.49,0.286
16.28,101.68,0.286
16.30,101.86,0.286
16.32,102.04,0.287
16.33,102.23,0.287
16.35,102.41,0.287
16.37,102.59,0.288
16.39,102.78,0.288
16.41,102.96,0.288
16.43,103.14,0.289
16.45,103.33,0.289
16.46,103.51,0.290
16.48,103.69,0.290
16.50,103.88,0.290
16.52,104.06,0.291
16.54,104.24,0.291
16.55,104.42,0.292
16.57,104.61,0.292
16.59,104.79,0.292
16.61,104.97,0.293
16.63,105.16,0.293
16.65,105.34,0.293
16.67,105.52,0.294
16.68,105.71,0.294
16.70,105.89,0.295
16.72,106.08,0.295
16.74,106.26,0.295
16.76,106.44,0.296
16.78,106.63,0.296
16.79,106.81,0.296
16.81,106.99,0.297
16.83,107.17,0.297
16.85,107.36,0.297
16.87,107.54,0.298
16.88,107.73,0.298
16.90,107.91,0.298
16.92,108.09,0.298
16.94,108.28,0.299
16.96,108.46,0.299
16.98,108.64,0.299
17.00,108.83,0.300
17.01,109.01,0.300
17.03,109.19,0.300
17.05,109.38,0.300
17.07,109.56,0.301
17.09,109.74,0.301
17.11,109.93,0.301
17.12,110.11,0.301
17.14,110.29,0.302
17.16,110.48,0.302
17.18,110.66,0.302
17.20,110.84,0.302
17.22,111.03,0.303
17.23,111.21,0.303
17.25,111.39,0.303
17.27,111.58,0.303
17.29,111.76,0.303
17.31,111.94,0.304
17.33,112.13,0.304
17.34,112.31,0.304
17.36,112.49,0.304
17.38,112.68,0.304
17.40,112.86,0.304
17.42,113.05,0.305
17.43,113.23,0.305
17.45,113.41,0.305
17.47,113.60,0.305
17.49,113.78,0.305
17.51,113.96,0.305
17.53,114.15,0.305
17.54,114.33,0.306
17.56,114.51,0.306
17.58,114.70,0.306
17.60,114.88,0.306
17.62,115.06,0.306
17.64,115.25,0.306
17.66,115.43,0.306
17.67,115.62,0.306
17.69,115.80,0.306
17.71,115.98,0.306
17.73,116.17,0.306
17.75,116.35,0.306
17.77,116.53,0.306
17.78,116.72,0.306
17.80,116.90,0.307
17.82,117.09,0.307
17.84,117.27,0.307
17.86,117.45,0.307
17.88,117.64,0.307
17.89,117.82,0.307
17.91,118.00,0.307
17.93,118.19,0.307
17.95,118.37,0.307
17.97,118.55,0.307
17.98,118.74,0.307
18.00,118.92,0.307
18.02,119.11,0.307
18.04,119.29,0.307
18.06,119.47,0.307
18.08,119.66,0.307
18.09,119.84,0.307
18.11,120.02,0.307
18.13,120.21,0.307
18.15,120.39,0.307
18.17,120.57,0.307
18.19,120.76,0.307
18.21,120.94,0.306
18.22,121.13,0.306
18.24,121.31,0.306
18.26,121.49,0.306
18.28,121.68,0.306
18.30,121.86,0.306
18.32,122.04,0.306
18.33,122.22,0.306
18.35,122.41,0.306
18.37,122.59,0.306
18.39,122.77,0.306
18.41,122.96,0.306
18.43,123.14,0.306
18.44,123.33,0.306
18.46,123.51,0.306
18.48,123.69,0.306
18.50,123.88,0.306
18.52,124.06,0.306
18.53,124.24,0.306
18.55,124.43,0.306
18.57,124.61,0.306
18.59,124.79,0.306
18.61,124.98,0.306
18.63,125.16,0.306
18.64,125.34,0.306
18.66,125.53,0.305
18.68,125.71,0.305
18.70,125.89,0.305
18.72,126.08,0.305
18.74,126.26,0.305
18.76,126.44,0.305
18.77,126.63,0.305
18.79,126.81,0.305
18.81,126.99,0.305
18.83,127.18,0.305
18.85,127.36,0.305
18.87,127.55,0.305
18.88,127.73,0.305
18.90,127.91,0.305
18.92,128.10,0.305
18.94,128.28,0.305
18.96,128.46,0.305
18.98,128.65,0.305
18.99,128.83,0.305
19.01,129.01,0.305
19.03,129.20,0.305
19.05,129.38,0.305
19.07,129.56,0.305
19.08,129.75,0.305
19.10,129.93,0.305
19.12,130.11,0.305
19.14,130.30,0.305
19.16,130.48,0.305
19.18,130.67,0.305
19.19,130.85,0.305
19.21,131.03,0.305
19.23,131.22,0.305
19.25,131.40,0.305
19.27,131.58,0.305
19.29,131.77,0.305
19.31,131.95,0.305
19.32,132.13,0.305
19.34,132.32,0.305
19.36,132.50,0.305
19.38,132.68,0.305
19.40,132.87,0.305
19.42,133.05,0.305
19.43,133.24,0.305
19.45,133.42,0.305
19.47,133.60,0.305
19.49,133.79,0.305
19.51,133.97,0.305
19.53,134.15,0.305
19.54,134.33,0.305
19.56,134.52,0.305
19.58,134.70,0.305
19.60,134.88,0.305
19.62,135.07,0.305
19.63,135.25,0.305
19.65,135.44,0.305
19.67,135.62,0.305
19.69,135.80,0.305
19.71,135.99,0.305
19.73,136.17,0.305
19.74,136.35,0.305
19.76,136.54,0.305
19.78,136.72,0.305
19.80,136.90,0.305
19.82,137.09,0.305
19.84,137.27,0.305
19.86,137.45,0.305
19.87,137.64,0.305
19.89,137.82,0.305
19.91,138.01,0.305
19.93,138.19,0.305
19.95,138.37,0.305
19.97,138.56,0.305
19.98,138.74,0.305
20.00,138.92,0.305
20.02,139.11,0.305
20.04,139.29,0.305
20.06,139.47,0.305
20.08,139.66,0.305
20.09,139.84,0.305
20.11,140.02,0.305
20.13,140.21,0.305
20.15,140.39,0.305
20.17,140.57,0.305
20.18,140.76,0.305
20.20,140.94,0.305
20.22,141.12,0.306
20.24,141.31,0.306
20.26,141.49,0.306
20.28,141.67,0.306
20.29,141.86,0.306
20.31,142.04,0.306
20.33,142.22,0.306
20.35,142.41,0.306
20.37,142.59,0.306
20.39,142.77,0.306
20.41,142.96,0.306
20.42,143.14,0.306
20.44,143.33,0.306
20.46,143.51,0.306
20.48,143.69,0.306
20.50,143.88,0.306
20.52,144.06,0.306
20.53,144.24,0.307
20.55,144.43,0.307
20.57,144.61,0.307
20.59,144.79,0.307
20.61,144.98,0.307
20.63,145.16,0.307
20.64,145.34,0.307
20.66,145.53,0.307
20.68,145.71,0.307
20.70,145.90,0.307
20.72,146.08,0.307
20.73,146.26,0.307
20.75,146.45,0.307
20.77,146.63,0.307
20.79,146.81,0.307
20.81,147.00,0.307
20.83,147.18,0.307
20.84,147.36,0.307
20.86,147.55,0.308
20.88,147.73,0.308
20.90,147.91,0.308
20.92,148.10,0.308
20.94,148.28,0.308
20.96,148.46,0.308
20.97,148.65,0.308
20.99,148.83,0.308
21.01,149.01,0.308
21.03,149.20,0.308
21.05,149.38,0.308
21.07,149.56,0.308
21.08,149.75,0.308
21.10,149.93,0.308
21.12,150.11,0.308
21.14,150.30,0.308
21.16,150.48,0.308
21.18,150.67,0.309
21.19,150.85,0.309
21.21,151.03,0.309
21.23,151.22,0.309
21.25,151.40,0.309
21.27,151.58,0.309
21.28,151.77,0.309
21.30,151.95,0.309
21.32,152.14,0.309
21.34,152.32,0.309
21.36,152.50,0.310
21.38,152.68,0.310
21.39,152.87,0.310
21.41,153.05,0.310
21.43,153.23,0.310
21.45,153.42,0.310
21.47,153.60,0.310
21.49,153.79,0.310
21.51,153.97,0.310
21.52,154.15,0.310
21.54,154.33,0.310
21.56,154.52,0.310
21.58,154.70,0.310
21.60,154.88,0.310
21.62,155.07,0.311
21.63,155.25,0.311
21.65,155.44,0.311
21.67,155.62,0.311
21.69,155.80,0.311
21.71,155.99,0.311
21.73,156.17,0.311
21.74,156.35,0.311
21.76,156.54,0.311
21.78,156.72,0.311
21.80,156.90,0.311
21.82,157.09,0.311
21.83,157.27,0.312
21.85,157.45,0.312
21.87,157.64,0.312
21.89,157.82,0.312
21.91,158.00,0.312
21.93,158.19,0.312
21.94,158.37,0.312
21.96,158.55,0.312
21.98,158.74,0.312
22.00,158.92,0.312
22.02,159.10,0.312
22.04,159.29,0.312
22.06,159.47,0.312
22.07,159.65,0.313
22.09,159.84,0.313
22.11,160.02,0.313
22.13,160.20,0.313
22.15,160.39,0.313
22.17,160.57,0.313
22.18,160.76,0.313
22.20,160.94,0.313
22.22,161.12,0.313
22.24,161.30,0.313
22.26,161.49,0.313
22.28,161.67,0.314
22.29,161.85,0.314
22.31,162.04,0.314
22.33,162.22,0.314
22.35,162.40,0.314
22.37,162.59,0.314
22.38,162.77,0.314
22.40,162.95,0.314
22.42,163.14,0.314
22.44,163.32,0.314
22.46,163.51,0.314
22.48,163.69,0.315
22.49,163.87,0.315
22.51,164.06,0.315
22.53,164.24,0.315
22.55,164.42,0.315
22.57,164.61,0.315
22.59,164.79,0.315
22.61,164.98,0.315
22.62,165.16,0.315
22.64,165.34,0.316
22.66,165.53,0.316
22.68,165.71,0.316
22.70,165.89,0.316
22.72,166.08,0.316
22.73,166.26,0.316
22.75,166.44,0.316
22.77,166.63,0.316
22.79,166.81,0.316
22.81,166.99,0.316
22.83,167.18,0.316
22.84,167.36,0.317
22.86,167.54,0.317
22.88,167.73,0.317
22.90,167.91,0.317
22.92,168.09,0.317
22.93,168.28,0.317
22.95,168.46,0.317
22.97,168.64,0.317
22.99,168.83,0.317
23.01,169.01,0.317
23.03,169.19,0.318
23.04,169.38,0.318
23.06,169.56,0.318
23.08,169.74,0.318
23.10,169.93,0.318
23.12,170.11,0.318
23.14,170.29,0.318
23.16,170.48,0.318
23.17,170.66,0.318
23.19,170.84,0.318
23.21,171.03,0.318
23.23,171.21,0.318
23.25,171.40,0.319
23.27,171.58,0.319
23.28,171.76,0.319
23.30,171.95,0.319
23.32,172.13,0.319
23.34,172.31,0.319
23.36,172.50,0.319
23.38,172.68,0.320
23.39,172.86,0.320
23.41,173.05,0.320
23.43,173.23,0.320
23.45,173.41,0.320
23.47,173.60,0.320
23.48,173.78,0.320
23.50,173.96,0.320
23.52,174.15,0.320
23.54,174.33,0.320
23.56,174.51,0.321
23.58,174.70,0.321
23.59,174.88,0.321
23.61,175.06,0.321
23.63,175.25,0.321
23.65,175.43,0.321
23.67,175.61,0.321
23.69,175.80,0.321
23.71,175.98,0.321
23.72,176.16,0.321
23.74,176.35,0.322
23.76,176.53,0.322
23.78,176.72,0.322
23.80,176.90,0.322
23.82,177.08,0.322
23.83,177.27,0.322
23.85,177.45,0.322
23.87,177.63,0.323
23.89,177.82,0.323
23.91,178.00,0.323
23.93,178.18,0.323
23.94,178.37,0.323
23.96,178.55,0.323
23.98,178.73,0.323
24.00,178.92,0.323
24.02,179.10,0.323
24.03,179.28,0.324
24.05,179.47,0.324
24.07,179.65,0.324
24.09,179.84,0.324
24.11,180.02,0.324
24.13,180.20,0.324
24.14,180.39,0.324
24.16,180.57,0.324
24.18,180.75,0.324
24.20,180.94,0.324
24.22,181.12,0.325
24.24,181.30,0.325
24.26,181.49,0.325
24.27,181.67,0.325
24.29,181.85,0.325
24.31,182.04,0.325
24.33,182.22,0.325
24.35,182.40,0.325
24.37,182.59,0.325
24.38,182.77,0.325
24.40,182.95,0.326
24.42,183.14,0.326
24.44,183.32,0.326
24.46,183.50,0.326
24.48,183.69,0.326
24.49,183.87,0.326
24.51,184.05,0.326
24.53,184.24,0.326
24.55,184.42,0.326
24.57,184.60,0.326
24.58,184.79,0.326
24.60,184.97,0.327
24.62,185.15,0.327
24.64,185.34,0.327
24.66,185.52,0.327
24.68,185.70,0.327
24.69,185.89,0.327
24.71,186.07,0.327
24.73,186.25,0.327
24.75,186.44,0.327
24.77,186.62,0.328
24.79,186.81,0.328
24.81,186.99,0.328
24.82,187.17,0.328
24.84,187.36,0.328
24.86,187.54,0.328
24.88,187.72,0.328
24.90,187.91,0.328
24.92,188.09,0.328
24.93,188.27,0.329
24.95,188.46,0.329
24.97,188.64,0.329
24.99,188.82,0.329
25.01,189.01,0.329
25.03,189.19,0.329
25.04,189.37,0.329
25.06,189.56,0.329
25.08,189.74,0.329
25.10,189.92,0.329
25.12,190.11,0.329
25.13,190.29,0.329
25.15,190.47,0.330
25.17,190.66,0.330
25.19,190.84,0.330
25.21,191.03,0.330
25.23,191.21,0.330
25.24,191.39,0.330
25.26,191.58,0.330
25.28,191.76,0.330
25.30,191.94,0.330
25.32,192.13,0.330
25.34,192.31,0.330
25.36,192.49,0.331
25.37,192.68,0.331
25.39,192.86,0.331
25.41,193.04,0.331
25.43,193.23,0.331
25.45,193.41,0.331
25.47,193.59,0.331
25.48,193.78,0.331
25.50,193.96,0.331
25.52,194.14,0.331
25.54,194.33,0.331
25.56,194.51,0.332
25.58,194.69,0.332
25.59,194.88,0.332
25.61,195.06,0.332
25.63,195.24,0.332
25.65,195.43,0.332
25.67,195.61,0.332
25.68,195.80,0.332
25.70,195.98,0.332
25.72,196.16,0.332
25.74,196.34,0.333
25.76,196.53,0.333
25.78,196.71,0.333
25.79,196.89,0.333
25.81,197.08,0.333
25.83,197.26,0.333
25.85,197.45,0.333
25.87,197.63,0.333
25.89,197.81,0.333
25.91,198.00,0.333
25.92,198.18,0.333
25.94,198.36,
25.96,198.55,
25.98,198.73,
25.99,,

[step]
Ramp 10.00 °C/min to -60.00 °C
Time,Temperature,Heat Flow (Normalized)
min,°C,W/g
27.99,200.16,-0.014
28.01,200.16,-0.014
28.03,200.16,-0.014
28.05,200.15,-0.015
28.07,200.12,-0.017
28.08,200.07,-0.037
28.10,200.00,-0.066
28.12,199.90,-0.106
28.14,199.78,-0.151
28.16,199.65,-0.194
28.18,199.50,-0.233
28.19,199.35,-0.263
28.21,199.19,-0.286
28.23,199.02,-0.303
28.25,198.85,-0.315
28.27,198.68,-0.324
28.29,198.51,-0.331
28.31,198.33,-0.337
28.32,198.15,-0.341
28.34,197.98,-0.344
28.36,197.80,-0.348
28.38,197.62,-0.350
28.40,197.44,-0.351
28.42,197.26,-0.352
28.43,197.08,-0.353
28.45,196.90,-0.354
28.47,196.72,-0.355
28.49,196.53,-0.355
28.51,196.35,-0.356
28.53,196.17,-0.356
28.54,195.99,-0.357
28.56,195.81,-0.357
28.58,195.63,-0.357
28.60,195.44,-0.357
28.62,195.26,-0.357
28.63,195.08,-0.357
28.65,194.90,-0.357
28.67,194.72,-0.358
28.69,194.53,-0.358
28.71,194.35,-0.358
28.73,194.17,-0.358
28.74,193.99,-0.358
28.76,193.81,-0.358
28.78,193.62,-0.358
28.80,193.44,-0.358
28.82,193.26,-0.358
28.84,193.08,-0.358
28.86,192.89,-0.358
28.87,192.71,-0.359
28.89,192.53,-0.359
28.91,192.34,-0.359
28.93,192.16,-0.359
28.95,191.98,-0.359
28.97,191.80,-0.359
28.98,191.61,-0.359
29.00,191.43,-0.359
29.02,191.25,-0.359
29.04,191.07,-0.359
29.06,190.88,-0.359
29.08,190.70,-0.359
29.09,190.52,-0.359
29.11,190.34,-0.359
29.13,190.15,-0.359
29.15,189.97,-0.359
29.17,189.79,-0.359
29.18,189.61,-0.359
29.20,189.42,-0.359
29.22,189.24,-0.359
29.24,189.06,-0.359
29.26,188.87,-0.359
29.28,188.69,-0.359
29.29,188.51,-0.359
29.31,188.32,-0.359
29.33,188.14,-0.359
29.35,187.96,-0.359
29.37,187.78,-0.359
29.39,187.59,-0.359
29.41,187.41,-0.359
29.42,187.23,-0.358
29.44,187.04,-0.358
29.46,186.86,-0.358
29.48,186.68,-0.358
29.50,186.49,-0.358
29.52,186.31,-0.358
29.53,186.13,-0.358
29.55,185.95,-0.358
29.57,185.76,-0.358
29.59,185.58,-0.358
29.61,185.40,-0.358
29.63,185.21,-0.358
29.64,185.03,-0.358
29.66,184.85,-0.358
29.68,184.66,-0.358
29.70,184.48,-0.358
29.72,184.30,-0.358
29.73,184.11,-0.358
29.75,183.93,-0.358
29.77,183.75,-0.358
29.79,183.56,-0.358
29.81,183.38,-0.357
29.83,183.20,-0.357
29.84,183.01,-0.357
29.86,182.83,-0.357
29.88,182.65,-0.357
29.90,182.46,-0.357
29.92,182.28,-0.357
29.94,182.10,-0.357
29.96,181.92,-0.357
29.97,181.73,-0.357
29.99,181.55,-0.357
30.01,181.37,-0.356
30.03,181.18,-0.356
30.05,181.00,-0.356
30.07,180.82,-0.356
30.08,180.63,-0.356
30.10,180.45,-0.356
30.12,180.27,-0.356
30.14,180.08,-0.356
30.16,179.90,-0.356
30.18,179.72,-0.356
30.19,179.53,-0.356
30.21,179.35,-0.356
30.23,179.17,-0.356
30.25,178.98,-0.356
30.27,178.80,-0.356
30.28,178.62,-0.355
30.30,178.43,-0.355
30.32,178.25,-0.355
30.34,178.07,-0.355
30.36,177.89,-0.355
30.38,177.70,-0.355
30.39,177.52,-0.355
30.41,177.33,-0.355
30.43,177.15,-0.355
30.45,176.97,-0.355
30.47,176.79,-0.355
30.49,176.60,-0.355
30.51,176.42,-0.355
30.52,176.23,-0.354
30.54,176.05,-0.354
30.56,175.87,-0.354
30.58,175.69,-0.354
30.60,175.50,-0.354
30.62,175.32,-0.354
30.63,175.14,-0.354
30.65,174.95,-0.354
30.67,174.77,-0.354
30.69,174.59,-0.354
30.71,174.40,-0.354
30.73,174.22,-0.354
30.74,174.03,-0.354
30.76,173.85,-0.353
30.78,173.67,-0.353
30.80,173.49,-0.353
30.82,173.30,-0.353
30.83,173.12,-0.353
30.85,172.94,-0.353
30.87,172.75,-0.353
30.89,172.57,-0.353
30.91,172.39,-0.353
30.93,172.20,-0.353
30.94,172.02,-0.353
30.96,171.84,-0.353
30.98,171.65,-0.353
31.00,171.47,-0.352
31.02,171.29,-0.352
31.04,171.10,-0.352
31.06,170.92,-0.352
31.07,170.74,-0.352
31.09,170.55,-0.352
31.11,170.37,-0.352
31.13,170.19,-0.352
31.15,170.00,-0.352
31.17,169.82,-0.352
31.18,169.64,-0.352
31.20,169.45,-0.352
31.22,169.27,-0.351
31.24,169.09,-0.351
31.26,168.90,-0.351
31.28,168.72,-0.351
31.29,168.54,-0.351
31.31,168.35,-0.351
31.33,168.17,-0.351
31.35,167.99,-0.351
31.37,167.80,-0.351
31.38,167.62,-0.351
31.40,167.44,-0.351
31.42,167.26,-0.351
31.44,167.07,-0.350
31.46,166.89,-0.350
31.48,166.70,-0.350
31.49,166.52,-0.350
31.51,166.34,-0.350
31.53,166.15,-0.350
31.55,165.97,-0.350
31.57,165.79,-0.350
31.59,165.61,-0.350
31.61,165.42,-0.350
31.62,165.24,-0.350
31.64,165.05,-0.350
31.66,164.87,-0.350
31.68,164.69,-0.349
31.70,164.51,-0.349
31.72,164.32,-0.349
31.73,164.14,-0.349
31.75,163.96,-0.349
31.77,163.77,-0.349
31.79,163.59,-0.349
31.81,163.41,-0.349
31.83,163.22,-0.349
31.84,163.04,-0.349
31.86,162.86,-0.349
31.88,162.68,-0.349
31.90,162.49,-0.349
31.92,162.31,-0.348
31.93,162.12,-0.348
31.95,161.94,-0.348
31.97,161.76,-0.348
31.99,161.57,-0.348
32.01,161.39,-0.348
32.03,161.21,-0.348
32.04,161.02,-0.348
32.06,160.84,-0.348
32.08,160.66,-0.348
32.10,160.47,-0.348
32.12,160.29,-0.348
32.14,160.11,-0.348
32.16,159.92,-0.347
32.17,159.74,-0.347
32.19,159.56,-0.347
32.21,159.37,-0.347
32.23,159.19,-0.347
32.25,159.01,-0.347
32.27,158.82,-0.347
32.28,158.64,-0.347
32.30,158.46,-0.347
32.32,158.27,-0.347
32.34,158.09,-0.347
32.36,157.91,-0.347
32.38,157.72,-0.347
32.39,157.54,-0.346
32.41,157.36,-0.346
32.43,157.17,-0.346
32.45,156.99,-0.346
32.47,156.81,-0.346
32.48,156.62,-0.346
32.50,156.44,-0.346
32.52,156.26,-0.346
32.54,156.08,-0.346
32.56,155.89,-0.346
32.58,155.71,-0.346
32.59,155.53,-0.346
32.61,155.34,-0.346
32.63,155.16,-0.345
32.65,154.97,-0.345
32.67,154.79,-0.345
32.69,154.61,-0.345
32.71,154.42,-0.345
32.72,154.24,-0.345
32.74,154.06,-0.345
32.76,153.87,-0.345
32.78,153.69,-0.345
32.80,153.51,-0.345
32.82,153.33,-0.345
32.83,153.14,-0.345
32.85,152.96,-0.345
32.87,152.78,-0.345
32.89,152.59,-0.344
32.91,152.41,-0.344
32.93,152.23,-0.344
32.94,152.04,-0.344
32.96,151.86,-0.344
32.98,151.68,-0.344
33.00,151.49,-0.344
33.02,151.31,-0.344
33.03,151.13,-0.344
33.05,150.94,-0.344
33.07,150.76,-0.344
33.09,150.58,-0.344
33.11,150.39,-0.343
33.13,150.21,-0.343
33.14,150.02,-0.343
33.16,149.84,-0.343
33.18,149.66,-0.343
33.20,149.48,-0.343
33.22,149.29,-0.343
33.24,149.11,-0.343
33.26,148.93,-0.343
33.27,148.74,-0.343
33.29,148.56,-0.343
33.31,148.38,-0.343
33.33,148.19,-0.343
33.35,148.01,-0.343
33.37,147.83,-0.342
33.38,147.64,-0.342
33.40,147.46,-0.342
33.42,147.28,-0.342
33.44,147.09,-0.342
33.46,146.91,-0.342
33.48,146.73,-0.342
33.49,146.54,-0.342
33.51,146.36,-0.342
33.53,146.18,-0.342
33.55,145.99,-0.342
33.57,145.81,-0.342
33.58,145.63,-0.342
33.60,145.44,-0.341
33.62,145.26,-0.341
33.64,145.08,-0.341
33.66,144.89,-0.341
33.68,144.71,-0.341
33.69,144.53,-0.341
33.71,144.34,-0.341
33.73,144.16,-0.341
33.75,143.98,-0.341
33.77,143.79,-0.341
33.79,143.61,-0.341
33.81,143.43,-0.340
33.82,143.25,-0.340
33.84,143.06,-0.340
33.86,142.88,-0.340
33.88,142.69,-0.340
33.90,142.51,-0.340
33.92,142.33,-0.340
33.93,142.14,-0.340
33.95,141.96,-0.340
33.97,141.78,-0.340
33.99,141.59,-0.340
34.01,141.41,-0.340
34.03,141.23,-0.339
34.04,141.05,-0.339
34.06,140.86,-0.339
34.08,140.68,-0.339
34.10,140.50,-0.339
34.12,140.31,-0.339
34.14,140.13,-0.339
34.15,139.94,-0.339
34.17,139.76,-0.339
34.19,139.58,-0.339
34.21,139.39,-0.339
34.23,139.21,-0.339
34.24,139.03,-0.339
34.26,138.85,-0.338
34.28,138.66,-0.338
34.30,138.48,-0.338
34.32,138.29,-0.338
34.34,138.11,-0.338
34.36,137.93,-0.338
34.37,137.74,-0.338
34.39,137.56,-0.338
34.41,137.38,-0.338
34.43,137.20,-0.338
34.45,137.01,-0.338
34.46,136.83,-0.338
34.48,136.65,-0.337
34.50,136.46,-0.337
34.52,136.28,-0.337
34.54,136.10,-0.337
34.56,135.91,-0.337
34.58,135.73,-0.337
34.59,135.55,-0.337
34.61,135.36,-0.337
34.63,135.18,-0.337
34.65,134.99,-0.337
34.67,134.81,-0.337
34.69,134.63,-0.336
34.70,134.45,-0.336
34.72,134.26,-0.336
34.74,134.08,-0.336
34.76,133.90,-0.336
34.78,133.71,-0.336
34.79,133.53,-0.336
34.81,133.35,-0.336
34.83,133.16,-0.336
34.85,132.98,-0.336
34.87,132.80,-0.336
34.89,132.61,-0.336
34.91,132.43,-0.335
34.92,132.25,-0.335
34.94,132.06,-0.335
34.96,131.88,-0.335
34.98,131.70,-0.335
35.00,131.51,-0.335
35.01,131.33,-0.335
35.03,131.15,-0.335
35.05,130.96,-0.335
35.07,130.78,-0.335
35.09,130.60,-0.335
35.11,130.41,-0.335
35.13,130.23,-0.335
35.14,130.05,-0.334
35.16,129.86,-0.334
35.18,129.68,-0.334
35.20,129.50,-0.334
35.22,129.31,-0.334
35.24,129.13,-0.334
35.25,128.95,-0.334
35.27,128.76,-0.334
35.29,128.58,-0.334
[...]
119.22,10.91,0.181
119.24,11.09,0.181
119.25,11.28,0.181
119.27,11.46,0.181
119.29,11.64,0.181
119.31,11.83,0.182
119.33,12.01,0.182
119.35,12.19,0.182
119.36,12.38,0.182
119.38,12.56,0.182
119.40,12.75,0.182
119.42,12.93,0.182
119.44,13.11,0.182
119.45,13.30,0.183
119.47,13.48,0.183
119.49,13.66,0.183
119.51,13.85,0.183
119.53,14.03,0.183
119.55,14.21,0.183
119.56,14.40,0.183
119.58,14.58,0.183
119.60,14.76,0.183
119.62,14.95,0.183
119.64,15.13,0.184
119.66,15.32,0.184
119.68,15.50,0.184
119.69,15.68,0.184
119.71,15.87,0.184
119.73,16.05,0.184
119.75,16.23,0.184
119.77,16.42,0.184
119.79,16.60,0.184
119.80,16.78,0.184
119.82,16.97,0.185
119.84,17.15,0.185
119.86,17.33,0.185
119.88,17.52,0.185
119.90,17.70,0.185
119.91,17.88,0.185
119.93,18.07,0.185
119.95,18.25,0.185
119.97,18.44,0.185
119.99,18.62,0.186
120.00,18.80,0.186
120.02,18.99,0.186
120.04,19.17,0.186
120.06,19.35,0.186
120.08,19.54,0.186
120.10,19.72,0.186
120.11,19.90,0.186
120.13,20.09,0.186
120.15,20.27,0.186
120.17,20.45,0.187
120.19,20.64,0.187
120.21,20.82,0.187
120.23,21.00,0.187
120.24,21.19,0.187
120.26,21.37,0.187
120.28,21.55,0.187
120.30,21.74,0.187
120.32,21.92,0.187
120.34,22.10,0.188
120.35,22.29,0.188
120.37,22.47,0.188
120.39,22.66,0.188
120.41,22.84,0.188
120.43,23.02,0.188
120.45,23.21,0.188
120.46,23.39,0.188
120.48,23.57,0.188
120.50,23.76,0.188
120.52,23.94,0.189
120.54,24.12,0.189
120.55,24.31,0.189
120.57,24.49,0.189
120.59,24.67,0.189
120.61,24.86,0.189
120.63,25.04,0.189
120.65,25.22,0.189
120.66,25.41,0.189
120.68,25.59,0.190
120.70,25.77,0.190
120.72,25.96,0.190
120.74,26.14,0.190
120.76,26.32,0.190
120.78,26.51,0.190
120.79,26.69,0.190
120.81,26.88,0.190
120.83,27.06,0.191
120.85,27.24,0.191
120.87,27.43,0.191
120.89,27.61,0.191
120.90,27.79,0.191
120.92,27.98,0.191
120.94,28.16,0.191
120.96,28.34,0.191
120.98,28.53,0.191
121.00,28.71,0.191
121.01,28.89,0.192
121.03,29.08,0.192
121.05,29.26,0.192
121.07,29.44,0.192
121.09,29.63,0.192
121.10,29.81,0.192
121.12,30.00,0.192
121.14,30.18,0.192
121.16,30.36,0.192
121.18,30.55,0.193
121.20,30.73,0.193
121.21,30.91,0.193
121.23,31.10,0.193
121.25,31.28,0.193
121.27,31.46,0.193
121.29,31.65,0.193
121.31,31.83,0.193
121.33,32.01,0.193
121.34,32.20,0.194
121.36,32.38,0.194
121.38,32.56,0.194
121.40,32.75,0.194
121.42,32.93,0.194
121.44,33.12,0.194
121.45,33.30,0.194
121.47,33.48,0.194
121.49,33.67,0.194
121.51,33.85,0.194
121.53,34.03,0.195
121.55,34.22,0.195
121.56,34.40,0.195
121.58,34.58,0.195
121.60,34.77,0.195
121.62,34.95,0.195
121.64,35.13,0.195
121.65,35.32,0.195
121.67,35.50,0.195
121.69,35.68,0.196
121.71,35.87,0.196
121.73,36.05,0.196
121.75,36.23,0.196
121.76,36.42,0.196
121.78,36.60,0.196
121.80,36.78,0.196
121.82,36.97,0.196
121.84,37.15,0.196
121.86,37.34,0.197
121.88,37.52,0.197
121.89,37.70,0.197
121.91,37.89,0.197
121.93,38.07,0.197
121.95,38.25,0.197
121.97,38.44,0.197
121.99,38.62,0.197
122.00,38.80,0.197
122.02,38.99,0.197
122.04,39.17,0.198
122.06,39.35,0.198
122.08,39.54,0.198
122.10,39.72,0.198
122.11,39.90,0.198
122.13,40.09,0.198
122.15,40.27,0.198
122.17,40.45,0.198
122.19,40.64,0.198
122.20,40.82,0.199
122.22,41.01,0.199
122.24,41.19,0.199
122.26,41.37,0.199
122.28,41.56,0.199
122.30,41.74,0.199
122.31,41.92,0.199
122.33,42.11,0.199
122.35,42.29,0.199
122.37,42.47,0.200
122.39,42.66,0.200
122.41,42.84,0.200
122.43,43.02,0.200
122.44,43.21,0.200
122.46,43.39,0.200
122.48,43.57,0.200
122.50,43.76,0.200
122.52,43.94,0.200
122.54,44.13,0.201
122.55,44.31,0.201
122.57,44.49,0.201
122.59,44.67,0.201
122.61,44.86,0.201
122.63,45.04,0.201
122.65,45.23,0.201
122.66,45.41,0.201
122.68,45.59,0.201
122.70,45.78,0.202
122.72,45.96,0.202
122.74,46.14,0.202
122.75,46.33,0.202
122.77,46.51,0.202
122.79,46.69,0.202
122.81,46.88,0.202
122.83,47.06,0.202
122.85,47.24,0.202
122.86,47.43,0.203
122.88,47.61,0.203
122.90,47.80,0.203
122.92,47.98,0.203
122.94,48.16,0.203
122.96,48.35,0.203
122.98,48.53,0.203
122.99,48.71,0.203
123.01,48.90,0.203
123.03,49.08,0.204
123.05,49.26,0.204
123.07,49.45,0.204
123.09,49.63,0.204
123.10,49.81,0.204
123.12,50.00,0.204
123.14,50.18,0.204
123.16,50.36,0.204
123.18,50.55,0.204
123.20,50.73,0.205
123.21,50.91,0.205
123.23,51.10,0.205
123.25,51.28,0.205
123.27,51.47,0.205
123.29,51.65,0.205
123.30,51.83,0.205
123.32,52.02,0.205
123.34,52.20,0.206
123.36,52.38,0.206
123.38,52.57,0.206
123.40,52.75,0.206
123.41,52.93,0.206
123.43,53.12,0.206
123.45,53.30,0.206
123.47,53.48,0.206
123.49,53.67,0.206
123.51,53.85,0.207
123.53,54.04,0.207
123.54,54.22,0.207
123.56,54.40,0.207
123.58,54.59,0.207
123.60,54.77,0.207
123.62,54.95,0.207
123.64,55.14,0.207
123.65,55.32,0.207
123.67,55.50,0.208
123.69,55.69,0.208
123.71,55.87,0.208
123.73,56.05,0.208
123.75,56.24,0.208
123.76,56.42,0.208
123.78,56.60,0.208
123.80,56.79,0.208
123.82,56.97,0.208
123.84,57.15,0.209
123.85,57.34,0.209
123.87,57.52,0.209
123.89,57.70,0.209
123.91,57.89,0.209
123.93,58.07,0.209
123.95,58.25,0.209
123.96,58.44,0.209
123.98,58.62,0.209
124.00,58.80,0.210
124.02,58.99,0.210
124.04,59.17,0.210
124.06,59.36,0.210
124.08,59.54,0.210
124.09,59.72,0.210
124.11,59.90,0.210
124.13,60.09,0.210
124.15,60.27,0.210
124.17,60.46,0.211
124.19,60.64,0.211
124.20,60.82,0.211
124.22,61.01,0.211
124.24,61.19,0.211
124.26,61.37,0.211
124.28,61.56,0.211
124.30,61.74,0.211
124.31,61.92,0.211
124.33,62.11,0.212
124.35,62.29,0.212
124.37,62.47,0.212
124.39,62.66,0.212
124.40,62.84,0.212
124.42,63.03,0.212
124.44,63.21,0.212
124.46,63.39,0.212
124.48,63.57,0.213
124.50,63.76,0.213
124.51,63.94,0.213
124.53,64.12,0.213
124.55,64.31,0.213
124.57,64.49,0.213
124.59,64.67,0.213
124.61,64.86,0.213
124.63,65.04,0.214
124.64,65.23,0.214
124.66,65.41,0.214
124.68,65.59,0.214
124.70,65.78,0.214
124.72,65.96,0.214
124.74,66.14,0.214
124.75,66.33,0.214
124.77,66.51,0.214
124.79,66.69,0.215
124.81,66.88,0.215
124.83,67.06,0.215
124.85,67.24,0.215
124.86,67.43,0.215
124.88,67.61,0.215
124.90,67.79,0.215
124.92,67.98,0.216
124.94,68.16,0.216
124.95,68.34,0.216
124.97,68.53,0.216
124.99,68.71,0.216
125.01,68.90,0.216
125.03,69.08,0.216
125.05,69.26,0.216
125.06,69.45,0.216
125.08,69.63,0.217
125.10,69.81,0.217
125.12,70.00,0.217
125.14,70.18,0.217
125.16,70.36,0.217
125.18,70.55,0.217
125.19,70.73,0.217
125.21,70.91,0.217
125.23,71.10,0.218
125.25,71.28,0.218
125.27,71.46,0.218
125.29,71.65,0.218
125.30,71.83,0.218
125.32,72.01,0.218
125.34,72.20,0.218
125.36,72.38,0.219
125.38,72.56,0.219
125.40,72.75,0.219
125.41,72.93,0.219
125.43,73.11,0.219
125.45,73.30,0.219
125.47,73.48,0.219
125.49,73.66,0.220
125.50,73.85,0.220
125.52,74.03,0.220
125.54,74.22,0.220
125.56,74.40,0.220
125.58,74.58,0.220
125.60,74.77,0.220
125.61,74.95,0.220
125.63,75.13,0.221
125.65,75.32,0.221
125.67,75.50,0.221
125.69,75.68,0.221
125.71,75.87,0.221
125.73,76.05,0.221
125.74,76.23,0.221
125.76,76.42,0.222
125.78,76.60,0.222
125.80,76.78,0.222
125.82,76.97,0.222
125.84,77.15,0.222
125.85,77.33,0.222
125.87,77.52,0.222
125.89,77.70,0.223
125.91,77.88,0.223
125.93,78.07,0.223
125.95,78.25,0.223
125.96,78.44,0.223
125.98,78.62,0.223
126.00,78.80,0.223
126.02,78.99,0.223
126.04,79.17,0.224
126.05,79.35,0.224
126.07,79.54,0.224
126.09,79.72,0.224
126.11,79.90,0.224
126.13,80.09,0.224
126.15,80.27,0.224
126.16,80.45,0.225
126.18,80.64,0.225
126.20,80.82,0.225
126.22,81.00,0.225
126.24,81.19,0.225
126.26,81.37,0.225
126.28,81.55,0.225
126.29,81.74,0.226
126.31,81.92,0.226
126.33,82.10,0.226
126.35,82.29,0.226
126.37,82.47,0.226
126.39,82.66,0.226
126.40,82.84,0.226
126.42,83.02,0.227
126.44,83.20,0.227
126.46,83.39,0.227
126.48,83.57,0.227
126.50,83.76,0.227
126.51,83.94,0.227
126.53,84.12,0.227
126.55,84.31,0.228
126.57,84.49,0.228
126.59,84.67,0.228
126.60,84.86,0.228
126.62,85.04,0.228
126.64,85.22,0.228
126.66,85.41,0.228
126.68,85.59,0.229
126.70,85.77,0.229
126.71,85.96,0.229
126.73,86.14,0.229
126.75,86.32,0.229
126.77,86.51,0.229
126.79,86.69,0.229
126.81,86.87,0.230
126.83,87.06,0.230
126.84,87.24,0.230
126.86,87.43,0.230
126.88,87.61,0.230
126.90,87.79,0.230
126.92,87.97,0.231
126.94,88.16,0.231
126.95,88.34,0.231
126.97,88.52,0.231
126.99,88.71,0.231
127.01,88.89,0.231
127.03,89.07,0.232
127.05,89.26,0.232
127.06,89.44,0.232
127.08,89.62,0.232
127.10,89.81,0.232
127.12,89.99,0.233
127.14,90.17,0.233
127.15,90.36,0.233
127.17,90.54,0.233
127.19,90.72,0.233
127.21,90.91,0.234
127.23,91.09,0.234
127.25,91.28,0.234
127.26,91.46,0.234
127.28,91.64,0.234
127.30,91.83,0.235
127.32,92.01,0.235
127.34,92.19,0.235
127.36,92.38,0.235
127.38,92.56,0.236
127.39,92.74,0.236
127.41,92.93,0.236
127.43,93.11,0.236
127.45,93.29,0.237
127.47,93.48,0.237
127.49,93.66,0.237
127.50,93.84,0.237
127.52,94.03,0.237
127.54,94.21,0.238
127.56,94.39,0.238
127.58,94.57,0.238
127.60,94.76,0.238
127.61,94.94,0.239
127.63,95.13,0.239
127.65,95.31,0.239
127.67,95.49,0.239
127.69,95.68,0.239
127.70,95.86,0.240
127.72,96.04,0.240
127.74,96.23,0.240
127.76,96.41,0.241
127.78,96.59,0.241
127.80,96.78,0.241
127.81,96.96,0.242
127.83,97.14,0.242
127.85,97.33,0.242
127.87,97.51,0.242
127.89,97.69,0.243
127.91,97.88,0.243
127.93,98.06,0.243
127.94,98.24,0.244
127.96,98.43,0.244
127.98,98.61,0.244
128.00,98.80,0.245
128.02,98.98,0.245
128.04,99.16,0.245
128.05,99.34,0.246
128.07,99.53,0.246
128.09,99.71,0.246
128.11,99.89,0.247
128.13,100.08,0.247
128.15,100.26,0.247
128.16,100.44,0.248
128.18,100.63,0.248
128.20,100.81,0.248
128.22,100.99,0.249
128.24,101.18,0.249
128.25,101.36,0.250
128.27,101.54,0.250
128.29,101.73,0.250
128.31,101.91,0.251
128.33,102.10,0.251
128.35,102.28,0.252
128.36,102.46,0.252
128.38,102.65,0.253
128.40,102.83,0.253
128.42,103.01,0.254
128.44,103.20,0.254
128.46,103.38,0.255
128.48,103.56,0.255
128.49,103.75,0.256
128.51,103.93,0.256
128.53,104.11,0.256
128.55,104.30,0.257
128.57,104.48,0.257
128.59,104.66,0.258
128.60,104.84,0.259
128.62,105.03,0.259
128.64,105.21,0.260
128.66,105.39,0.260
128.68,105.58,0.261
128.70,105.76,0.261
128.71,105.94,0.262
128.73,106.13,0.262
128.75,106.31,0.263
128.77,106.49,0.264
128.79,106.68,0.264
128.80,106.86,0.265
128.82,107.04,0.265
128.84,107.23,0.266
128.86,107.41,0.267
128.88,107.59,0.267
128.90,107.78,0.268
128.91,107.96,0.268
128.93,108.14,0.269
128.95,108.33,0.269
128.97,108.51,0.270
128.99,108.69,0.271
129.01,108.88,0.271
129.03,109.06,0.272
129.04,109.24,0.273
129.06,109.43,0.273
129.08,109.61,0.274
129.10,109.79,0.274
129.12,109.98,0.275
129.14,110.16,0.275
129.15,110.34,0.275
129.17,110.52,0.276
129.19,110.71,0.276
129.21,110.89,0.277
129.23,111.07,0.278
129.25,111.26,0.278
129.26,111.44,0.279
129.28,111.62,0.279
129.30,111.81,0.279
129.32,111.99,0.280
129.34,112.17,0.280
129.35,112.36,0.281
129.37,112.54,0.281
129.39,112.72,0.282
129.41,112.91,0.282
129.43,113.09,0.283
129.45,113.27,0.283
129.46,113.46,0.284
129.48,113.64,0.284
129.50,113.82,0.285
129.52,114.01,0.285
129.54,114.19,0.286
129.56,114.37,0.286
129.58,114.56,0.286
129.59,114.74,0.287
129.61,114.92,0.287
129.63,115.11,0.288
129.65,115.29,0.288
129.67,115.47,0.288
129.69,115.66,0.289
129.70,115.84,0.289
129.72,116.02,0.289
129.74,116.21,0.290
129.76,116.39,0.290
129.78,116.58,0.290
129.80,116.76,0.291
129.81,116.94,0.291
129.83,117.12,0.291
129.85,117.31,0.292
129.87,117.49,0.292
129.89,117.68,0.292
129.90,117.86,0.292
129.92,118.04,0.293
129.94,118.23,0.293
129.96,118.41,0.293
129.98,118.59,0.293
130.00,118.78,0.294
130.01,118.96,0.294
130.03,119.14,0.294
130.05,119.33,0.294
130.07,119.51,0.295
130.09,119.69,0.295
130.11,119.88,0.295
130.13,120.06,0.295
130.14,120.24,0.295
130.16,120.43,0.295
130.18,120.61,0.296
130.20,120.79,0.296
130.22,120.98,0.296
130.24,121.16,0.296
130.25,121.34,0.296
130.27,121.53,0.296
130.29,121.71,0.296
130.31,121.90,0.296
130.33,122.08,0.297
130.35,122.26,0.297
130.36,122.45,0.297
130.38,122.63,0.297
130.40,122.81,0.297
130.42,123.00,0.297
130.44,123.18,0.297
130.45,123.37,0.297
130.47,123.55,0.298
130.49,123.73,0.298
130.51,123.92,0.298
130.53,124.10,0.298
130.55,124.28,0.298
130.56,124.47,0.298
130.58,124.65,0.298
130.60,124.83,0.298
130.62,125.02,0.298
130.64,125.20,0.298
130.66,125.38,0.298
130.68,125.57,0.298
130.69,125.75,0.298
130.71,125.93,0.298
130.73,126.12,0.298
130.75,126.30,0.299
130.77,126.48,0.299
130.79,126.67,0.299
130.80,126.85,0.299
130.82,127.03,0.299
130.84,127.22,0.299
130.86,127.40,0.299
130.88,127.58,0.299
130.90,127.77,0.299
130.91,127.95,0.299
130.93,128.14,0.299
130.95,128.32,0.299
130.97,128.50,0.299
130.99,128.69,0.299
131.00,128.87,0.299
131.02,129.05,0.299
131.04,129.23,0.299
131.06,129.42,0.299
131.08,129.60,0.299
131.10,129.78,0.299
131.11,129.97,0.299
131.13,130.15,0.300
131.15,130.34,0.300
131.17,130.52,0.300
131.19,130.70,0.300
131.21,130.88,0.300
131.23,131.07,0.300
131.24,131.25,0.300
131.26,131.44,0.300
131.28,131.62,0.300
131.30,131.80,0.300
131.32,131.99,0.300
131.34,132.17,0.300
131.35,132.35,0.300
131.37,132.54,0.300
131.39,132.72,0.301
131.41,132.90,0.301
131.43,133.09,0.301
131.45,133.27,0.301
131.46,133.45,0.301
131.48,133.64,0.301
131.50,133.82,0.301
131.52,134.00,0.301
131.54,134.19,0.301
131.55,134.37,0.301
131.57,134.56,0.301
131.59,134.74,0.301
131.61,134.92,0.301
131.63,135.11,0.302
131.65,135.29,0.302
131.66,135.47,0.302
131.68,135.65,0.302
131.70,135.84,0.302
131.72,136.02,0.302
131.74,136.21,0.302
131.76,136.39,0.302
131.78,136.57,0.302
131.79,136.75,0.302
131.81,136.94,0.302
131.83,137.12,0.302
131.85,137.31,0.302
131.87,137.49,0.302
131.89,137.67,0.302
131.90,137.86,0.303
131.92,138.04,0.303
131.94,138.22,0.303
131.96,138.41,0.303
131.98,138.59,0.303
132.00,138.77,0.303
132.01,138.96,0.303
132.03,139.14,0.303
132.05,139.32,0.303
132.07,139.51,0.303
132.09,139.69,0.303
132.10,139.87,0.303
132.12,140.06,0.304
132.14,140.24,0.304
132.16,140.42,0.304
132.18,140.61,0.304
132.20,140.79,0.304
132.21,140.97,0.304
132.23,141.16,0.304
132.25,141.34,0.304
132.27,141.53,0.304
132.29,141.71,0.304
132.31,141.89,0.304
132.33,142.08,0.305
132.34,142.26,0.305
132.36,142.44,0.305
132.38,142.63,0.305
132.40,142.81,0.306
132.42,142.99,0.306
132.44,143.18,0.306
132.45,143.36,0.306
132.47,143.54,0.306
132.49,143.73,0.306
132.51,143.91,0.306
132.53,144.09,0.306
132.55,144.28,0.306
132.56,144.46,0.306
132.58,144.64,0.306
132.60,144.83,0.306
132.62,145.01,0.306
132.64,145.19,0.306
132.65,145.38,0.306
132.67,145.56,0.307
132.69,145.74,0.307
132.71,145.93,0.307
132.73,146.11,0.307
132.75,146.30,0.307
132.76,146.48,0.307
132.78,146.66,0.307
132.80,146.85,0.307
132.82,147.03,0.307
132.84,147.21,0.307
132.86,147.40,0.307
132.88,147.58,0.307
132.89,147.76,0.308
132.91,147.95,0.308
132.93,148.13,0.308
132.95,148.32,0.308
132.97,148.50,0.308
132.99,148.68,0.308
133.00,148.87,0.308
133.02,149.05,0.308
133.04,149.23,0.308
133.06,149.42,0.308
133.08,149.60,0.309
133.10,149.78,0.309
133.11,149.97,0.309
133.13,150.15,0.309
133.15,150.33,0.309
133.17,150.52,0.309
133.19,150.70,0.309
133.20,150.88,0.309
133.22,151.07,0.309
133.24,151.25,0.309
133.26,151.43,0.309
133.28,151.62,0.309
133.30,151.80,0.309
133.31,151.98,0.309
133.33,152.17,0.309
133.35,152.35,0.310
133.37,152.53,0.310
133.39,152.72,0.310
133.41,152.90,0.310
133.43,153.08,0.310
133.44,153.27,0.310
133.46,153.45,0.310
133.48,153.64,0.310
133.50,153.82,0.310
133.52,154.00,0.310
133.54,154.19,0.311
133.55,154.37,0.311
133.57,154.55,0.311
133.59,154.74,0.311
133.61,154.92,0.311
133.63,155.10,0.311
133.65,155.29,0.311
133.66,155.47,0.311
133.68,155.65,0.311
133.70,155.84,0.311
133.72,156.02,0.311
133.74,156.20,0.311
133.75,156.39,0.311
133.77,156.57,0.311
133.79,156.75,0.312
133.81,156.94,0.312
133.83,157.12,0.312
133.85,157.30,0.312
133.86,157.49,0.312
133.88,157.67,0.312
133.90,157.86,0.312
133.92,158.04,0.312
133.94,158.22,0.312
133.96,158.41,0.312
133.98,158.59,0.313
133.99,158.77,0.313
134.01,158.95,0.313
134.03,159.14,0.313
134.05,159.32,0.313
134.07,159.51,0.313
134.09,159.69,0.313
134.10,159.87,0.313
134.12,160.06,0.313
134.14,160.24,0.313
134.16,160.42,0.313
134.18,160.61,0.313
134.20,160.79,0.313
134.21,160.97,0.313
134.23,161.16,0.313
134.25,161.34,0.314
134.27,161.52,0.314
134.29,161.71,0.314
134.30,161.89,0.314
134.32,162.07,0.314
134.34,162.26,0.314
134.36,162.44,0.314
134.38,162.62,0.314
134.40,162.81,0.314
134.41,162.99,0.314
134.43,163.17,0.314
134.45,163.36,0.314
134.47,163.54,0.314
134.49,163.72,0.315
134.51,163.91,0.315
134.53,164.09,0.315
134.54,164.27,0.315
134.56,164.46,0.315
134.58,164.64,0.315
134.60,164.83,0.315
134.62,165.01,0.315
134.64,165.19,0.315
134.65,165.38,0.316
134.67,165.56,0.316
134.69,165.75,0.316
134.71,165.93,0.316
134.73,166.11,0.316
134.75,166.29,0.316
134.76,166.48,0.316
134.78,166.66,0.316
134.80,166.84,0.316
134.82,167.03,0.316
134.84,167.21,0.316
134.85,167.39,0.316
134.87,167.58,0.316
134.89,167.76,0.316
134.91,167.94,0.316
134.93,168.13,0.316
134.95,168.31,0.317
134.96,168.50,0.317
134.98,168.68,0.317
135.00,168.86,0.317
135.02,169.05,0.317
135.04,169.23,0.317
135.06,169.41,0.317
135.08,169.60,0.317
135.09,169.78,0.317
135.11,169.96,0.317
135.13,170.15,0.317
135.15,170.33,0.318
135.17,170.51,0.318
135.19,170.70,0.318
135.20,170.88,0.318
135.22,171.06,0.318
135.24,171.25,0.318
135.26,171.43,0.318
135.28,171.62,0.318
135.30,171.80,0.318
135.31,171.98,0.318
135.33,172.16,0.318
135.35,172.35,0.319
135.37,172.53,0.319
135.39,172.72,0.319
135.40,172.90,0.319
135.42,173.08,0.319
135.44,173.27,0.319
135.46,173.45,0.319
135.48,173.63,0.319
135.50,173.82,0.319
135.51,174.00,0.319
135.53,174.18,0.319
135.55,174.37,0.320
135.57,174.55,0.320
135.59,174.73,0.320
135.61,174.92,0.320
135.63,175.10,0.320
135.64,175.28,0.320
135.66,175.47,0.320
135.68,175.65,0.320
135.70,175.84,0.320
135.72,176.02,0.321
135.74,176.20,0.321
135.75,176.39,0.321
135.77,176.57,0.321
135.79,176.75,0.321
135.81,176.93,0.321
135.83,177.12,0.321
135.85,177.30,0.321
135.86,177.49,0.321
135.88,177.67,0.321
135.90,177.85,0.321
135.92,178.04,0.321
135.94,178.22,0.321
135.95,178.40,0.322
135.97,178.59,0.322
135.99,178.77,0.322
136.01,178.95,0.322
136.03,179.14,0.322
136.05,179.32,0.322
136.06,179.51,0.322
136.08,179.69,0.322
136.10,179.87,0.322
136.12,180.05,0.322
136.14,180.24,0.323
136.16,180.42,0.323
136.18,180.60,0.323
136.19,180.79,0.323
136.21,180.97,0.323
136.23,181.15,0.323
136.25,181.34,0.323
136.27,181.52,0.323
136.29,181.70,0.323
136.30,181.89,0.323
136.32,182.07,0.323
136.34,182.25,0.323
136.36,182.44,0.323
136.38,182.62,0.323
136.40,182.81,0.324
136.41,182.99,0.324
136.43,183.17,0.324
136.45,183.36,0.324
136.47,183.54,0.324
136.49,183.72,0.324
136.50,183.91,0.324
136.52,184.09,0.324
136.54,184.27,0.324
136.56,184.45,0.324
136.58,184.64,0.324
136.60,184.82,0.325
136.62,185.00,0.325
136.63,185.19,0.325
136.65,185.37,0.325
136.67,185.55,0.325
136.69,185.74,0.325
136.71,185.92,0.325
136.73,186.11,0.325
136.74,186.29,0.325
136.76,186.47,0.325
136.78,186.66,0.325
136.80,186.84,0.326
136.82,187.02,0.326
136.83,187.21,0.326
136.85,187.39,0.326
136.87,187.58,0.326
136.89,187.76,0.326
136.91,187.94,0.326
136.93,188.13,0.326
136.95,188.31,0.326
136.96,188.49,0.327
136.98,188.67,0.327
137.00,188.86,0.327
137.02,189.04,0.327
137.04,189.23,0.327
137.05,189.41,0.327
137.07,189.59,0.327
137.09,189.78,0.327
137.11,189.96,0.327
137.13,190.14,0.327
137.15,190.33,0.327
137.17,190.51,0.327
137.18,190.69,0.328
137.20,190.88,0.328
137.22,191.06,0.328
137.24,191.24,0.328
137.26,191.43,0.328
137.28,191.61,0.328
137.29,191.79,0.328
137.31,191.98,0.328
137.33,192.16,0.328
137.35,192.34,0.328
137.37,192.53,0.328
137.38,192.71,0.329
137.40,192.90,0.329
137.42,193.08,0.329
137.44,193.26,0.329
137.46,193.45,0.329
137.48,193.63,0.329
137.50,193.81,0.329
137.51,194.00,0.329
137.53,194.18,0.329
137.55,194.36,0.329
137.57,194.55,0.330
137.59,194.73,0.330
137.60,194.91,0.330
137.62,195.10,0.330
137.64,195.28,0.330
137.66,195.46,0.330
137.68,195.65,0.330
137.70,195.83,0.330
137.72,196.01,0.330
137.73,196.20,0.330
137.75,196.38,0.330
137.77,196.56,0.330
137.79,196.75,0.330
137.81,196.93,0.331
137.83,197.11,0.331
137.84,197.30,0.331
137.86,197.48,0.331
137.88,197.67,0.331
137.90,197.85,0.331
137.92,198.03,0.331
137.93,198.22,
137.95,198.40,
137.97,198.58,
137.99,,
137.99,,