File: DSC/Olivia/2025_08_10_1CBN_3PVP40_MeOH_ASD_n60C_230C_10Cmin_x3.csv
Filename,2025_08_10_1CBN_3PVP40_MeOH_ASD_n60C_230C_10Cmin_x3
Instrument name,DSC2A-00468 (192.168.1.100)
Operator,Yarger
rundate,8/10/2025
Sample name,2025_08_10_1CBN_3PVP40_MeOH_ASD_n60C_230C_10Cmin_x3
proceduresegments,Data Off ; Equilibrate -60.00 °C; Data On ; Ramp 10.00 °C/min to 230.00 °C; Data Off ; Isothermal 2.0 min; Data On ; Ramp 10.00 °C/min to -60.00 °C; Data Off ; Isothermal 2.0 min; Data On ; Ramp 10.00 °C/min to 230.00 °C; Data Off ; Isothermal 2.0 min; Data On ; Ramp 10.00 °C/min to -60.00 °C; Data Off ; Isothermal 2.0 min; Data On ; Ramp 10.00 °C/min to 230.00 °C
[File Parameters]
Run date,8/10/2025 1:50:44 PM
Trios version,5.1.1.46572
Original File Name,
Current File Name,D:\DSC2500\JYarger\2025_08_10_1CBN_3PVP40_MeOH_ASD_n60C_230C_10Cmin_x3.tri
[Procedure]
Procedure Name,TS_n60C_230C_10Cmin_x3
Sample Name,2025_08_10_1CBN_3PVP40_MeOH_ASD_n60C_230C_10Cmin_x3
Sample Mass,32.26 mg
Reference Sample Mass,0 mg
Pan Mass,4.31 mg
Pan Number,15
Reference Pan Mass,32.42 mg
Reference Pan Number,10
Pan Type,Aluminum
Comments,Thermal support Al pans/lids. DSC_Samples_A2_Tray_August2025 google sheet.
Project Name,Pharma
Operator,Yarger
Test,Custom
Unload Max Temperature,30
Unload Min Temperature,30
Load Max Temperature,30
Load Min Temperature,30
Stop on Gas Flow Error,Yes
[Signal List]
Signal #1,Time (min)
Signal #2,Temperature (°C)
Signal #3,Heat Flow (mW)
Signal #4,Delta T (µV)
Signal #5,Delta Tzero (µV)
Signal #6,Tzero Temperature (°C)
Signal #7,Cell Purge (mL/min)
Signal #8,Heater Temp (°C)
Signal #9,Power Delivered (W)
Signal #10,Reference Junction Temperature (°C)
Signal #11,Flange Temperature (°C)
Signal #12,Heat Flow Phase (rad)
Signal #13,Total Heat Capacity (J/°C)
Signal #14,Heat Capacity (J/°C)
[Configuration]
Company Name,ASU
Instrument Name,DSC2A-00468
Instrument Type,DSC2500
Serial Number,DSC2A-00468
IP,192.168.1.100
Location of Instrument,MRRC
DisplayType,Unknown
Sample Interval ,0.1 s/pt
Selected Heat Flow,T4P
Exotherm Direction,Down
Cell Serial,DRC2-00792
Lid Type,Standard
Cooler,RCS 90
Leave Cooler on at End of Sequence,On
Gas 2,Nitrogen
Gas Selected,Channel 1
Flow Rate,50 mL/min
Secondary Purge,On
Licensed Heat Flow,Heat Flow T4P
Modulation Licensed,Yes
[Versions]
Common IDD Version,1
Cortex Version,VER 2.10.2.31
Driver,5.0.0.6
GDM Version,1.0.3.3
TouchscreenVersion,1.0.0.16145
FEP Version,1.2.1.21
FEP Bootloader,2.0.0.5
AutoSampler Version,2.1.1.26
Auto Sampler Bootloader,2.0.0.5
FCM Version,1.1.0.3
FCM Bootloader,2.0.0.5
[Experiment Logs]
Experiment Log Entry # 1,Air Cool is off.
Experiment Log Entry # 3,Data On set to 0
Experiment Log Entry # 5,Equilibrate Segment -60 (C) Started
Experiment Log Entry # 7,Data On set to 1
Experiment Log Entry # 9,Ramp Segment 10 C/min to 230 Started
Experiment Log Entry # 11,Data On set to 0
Experiment Log Entry # 13,Isothermal Segment 2 min started
Experiment Log Entry # 15,Data On set to 1
Experiment Log Entry # 17,Ramp Segment 10 C/min to -60 Started
Experiment Log Entry # 19,Data On set to 0
Experiment Log Entry # 21,Isothermal Segment 2 min started
Experiment Log Entry # 23,Data On set to 1
Experiment Log Entry # 25,Ramp Segment 10 C/min to 230 Started
Experiment Log Entry # 27,Data On set to 0
Experiment Log Entry # 29,Isothermal Segment 2 min started
Experiment Log Entry # 31,Data On set to 1
Experiment Log Entry # 33,Ramp Segment 10 C/min to -60 Started
Experiment Log Entry # 35,Data On set to 0
Experiment Log Entry # 37,Isothermal Segment 2 min started
Experiment Log Entry # 39,Data On set to 1
Experiment Log Entry # 41,Ramp Segment 10 C/min to 230 Started
[Method Log]
Method Log Entry # 1,Data Off
Method Log Entry # 2,Equilibrate -60 °C
Method Log Entry # 3,Data On
Method Log Entry # 4,(Ramp 969982) Ramp 10 °C/minute to 230 °C
Method Log Entry # 5,Data Off
Method Log Entry # 6,Isothermal 2 minutes
Method Log Entry # 7,Data On
Method Log Entry # 8,(Ramp 969986) Ramp 10 °C/minute to -60 °C
Method Log Entry # 9,Data Off
Method Log Entry # 10,Isothermal 2 minutes
Method Log Entry # 11,Data On
Method Log Entry # 12,(Ramp 969990) Ramp 10 °C/minute to 230 °C
Method Log Entry # 13,Data Off
Method Log Entry # 14,Isothermal 2 minutes
Method Log Entry # 15,Data On
Method Log Entry # 16,(Ramp 969994) Ramp 10 °C/minute to -60 °C
Method Log Entry # 17,Data Off
Method Log Entry # 18,Isothermal 2 minutes
Method Log Entry # 19,Data On
Method Log Entry # 20,(Ramp 969998) Ramp 10 °C/minute to 230 °C
Cell Serial,DRC2-00792
[T1 Calibration]
Slope,-0.008529666
Offset,9.636258
Initial Temperature,98.23
GUID,f8bfdadc-4977-4fdf-ba6d-0ba9134940c3
[TZero Calibration]
Date Applied,11/29/2022 4:06:13 PM
Description,From -89.059 °C to 396.009 °C at 20.000°C/min
Gas Type,Nitrogen
Pan Type,None
Source Files 1,C:\Users\yargerlab\Desktop\DSC Data\General\TZero_calibration_11_29_22_2nd(2).tri
Source Files 2,C:\Users\yargerlab\Desktop\DSC Data\General\TZero_calibration_11_29_22_2nd(3).tri
Delta T Offset,13.05235
Delta T Slope,-0.007271007
Delta T0 Offset,-13.69128
Delta T0 Slope,0.06063341
[Temperature Calibration]
Date Applied,11/29/2022 7:12:28 PM
Description,From 106.590 °C to 186.590 °C at 10.000°C/min
Gas Type,Nitrogen
Pan Type,Tzero Aluminum Hermetic
Source Files 1,C:\Users\yargerlab\Desktop\DSC Data\General\Indium(6).tri
Measured 1,157.391
Known 1,156.598
[Cell Constant Calibration]
Date Applied,11/29/2022 7:12:29 PM
Description,From 106.590 °C to 186.590 °C at 10.000°C/min
Gas Type,Nitrogen
Pan Type,Tzero Aluminum Hermetic
Source Files 1,C:\Users\yargerlab\Desktop\DSC Data\General\Indium(6).tri
T4P KCell,1.006051
Onset Slope,63.26126 mW/°C
[Direct Cp Calibration]
Date Applied,11/30/2022 11:04:51 AM
Description,From -79.983 °C to 298.409 °C at 10.000°C/min
Gas Type,Nitrogen
Pan Type,Tzero Aluminum Hermetic
Source Files 1,C:\Users\yargerlab\Desktop\DSC Data\General\Sapphire_Heat_Capacity_11_30_22.tri
[Rev Cp Calibration]
Date Applied,11/30/2022 1:58:51 PM
Description,From -79.996 °C to 292.812 °C at 3.000°C/min
Gas Type,Nitrogen
Pan Type,Tzero Aluminum Hermetic
Source Files 1,C:\Users\yargerlab\Desktop\DSC Data\General\Sapphire_MDSC_Calibration_11_30_22.tri
[step]
Ramp 10.00 °C/min to 230.00 °C
Time,Temperature,Heat Flow (Normalized)
min,°C,W/g
0.00,-59.81,-0.006
0.02,-59.82,-0.006
0.04,-59.82,-0.005
0.06,-59.80,-0.005
0.08,-59.76,-0.005
0.10,-59.69,-0.004
0.12,-59.60,-0.001
0.14,-59.48,0.002
0.16,-59.33,0.006
0.18,-59.18,0.010
0.20,-59.01,0.013
0.22,-58.83,0.016
0.24,-58.65,0.018
0.26,-58.46,0.020
0.28,-58.27,0.022
0.30,-58.08,0.023
0.32,-57.89,0.023
0.34,-57.69,0.024
0.36,-57.50,0.025
0.38,-57.30,0.025
0.40,-57.11,0.025
0.42,-56.92,0.025
0.44,-56.72,0.026
0.46,-56.53,0.026
0.48,-56.33,0.026
0.50,-56.13,0.026
0.52,-55.94,0.026
0.54,-55.74,0.026
0.56,-55.54,0.026
0.58,-55.35,0.026
0.60,-55.15,0.026
0.62,-54.95,0.026
0.64,-54.76,0.026
0.66,-54.56,0.026
0.68,-54.36,0.026
0.70,-54.16,0.026
0.72,-53.96,0.027
0.74,-53.77,0.027
0.76,-53.57,0.027
0.78,-53.37,0.027
0.80,-53.17,0.027
0.82,-52.97,0.027
0.84,-52.77,0.027
0.86,-52.58,0.027
0.88,-52.38,0.027
0.90,-52.18,0.027
0.92,-51.98,0.027
0.94,-51.78,0.027
0.96,-51.58,0.027
0.98,-51.38,0.027
1.00,-51.18,0.027
1.02,-50.99,0.027
1.04,-50.79,0.027
1.06,-50.59,0.027
1.08,-50.39,0.027
1.10,-50.19,0.027
1.12,-49.99,0.027
1.14,-49.79,0.027
1.16,-49.59,0.027
1.18,-49.39,0.027
1.20,-49.19,0.028
1.22,-48.99,0.028
1.24,-48.79,0.028
1.26,-48.59,0.028
1.28,-48.39,0.028
1.30,-48.19,0.028
1.32,-47.99,0.028
1.34,-47.80,0.028
1.36,-47.59,0.028
1.38,-47.40,0.028
1.40,-47.20,0.028
1.42,-47.00,0.028
1.44,-46.79,0.028
1.46,-46.60,0.028
1.48,-46.40,0.028
1.50,-46.20,0.028
1.52,-46.00,0.028
1.54,-45.80,0.028
1.56,-45.60,0.028
1.58,-45.40,0.028
1.60,-45.20,0.028
1.62,-45.00,0.028
1.64,-44.80,0.028
1.66,-44.60,0.028
1.68,-44.40,0.028
1.70,-44.20,0.028
1.72,-44.00,0.028
1.74,-43.80,0.028
1.76,-43.60,0.028
1.78,-43.40,0.028
1.80,-43.20,0.028
1.82,-42.99,0.028
1.84,-42.79,0.028
1.86,-42.59,0.028
1.88,-42.39,0.028
1.90,-42.19,0.028
1.92,-41.99,0.028
1.94,-41.79,0.028
1.96,-41.60,0.028
1.98,-41.39,0.028
2.00,-41.19,0.028
2.02,-40.99,0.028
2.04,-40.79,0.028
2.06,-40.59,0.028
2.08,-40.39,0.028
2.10,-40.19,0.028
2.12,-39.99,0.028
2.14,-39.79,0.028
2.16,-39.59,0.028
2.18,-39.39,0.028
2.20,-39.19,0.028
2.22,-38.99,0.028
2.24,-38.79,0.028
2.26,-38.59,0.028
2.28,-38.39,0.028
2.30,-38.19,0.028
2.32,-37.99,0.028
2.34,-37.79,0.028
2.36,-37.59,0.028
2.38,-37.39,0.028
2.40,-37.19,0.028
2.42,-36.99,0.028
2.44,-36.79,0.028
2.46,-36.59,0.028
2.48,-36.39,0.028
2.50,-36.19,0.028
2.52,-35.99,0.028
2.54,-35.79,0.028
2.56,-35.59,0.028
2.58,-35.39,0.028
2.60,-35.19,0.028
2.62,-34.99,0.028
2.64,-34.78,0.028
2.66,-34.59,0.028
2.68,-34.39,0.028
2.70,-34.18,0.028
2.72,-33.99,0.028
2.74,-33.78,0.028
2.76,-33.58,0.029
2.78,-33.38,0.029
2.80,-33.18,0.029
2.82,-32.98,0.029
2.84,-32.78,0.029
2.86,-32.58,0.029
2.88,-32.38,0.029
2.90,-32.18,0.029
2.92,-31.98,0.029
2.94,-31.78,0.029
2.96,-31.58,0.029
2.98,-31.38,0.029
3.00,-31.18,0.029
3.02,-30.98,0.029
3.04,-30.78,0.029
3.06,-30.58,0.029
3.08,-30.38,0.029
3.10,-30.18,0.029
3.12,-29.98,0.029
3.14,-29.78,0.029
3.16,-29.58,0.029
3.18,-29.38,0.029
3.20,-29.18,0.029
3.22,-28.98,0.029
3.24,-28.78,0.029
3.26,-28.58,0.029
3.28,-28.38,0.029
3.30,-28.18,0.029
3.32,-27.98,0.029
3.34,-27.78,0.029
3.36,-27.58,0.029
3.38,-27.38,0.029
3.40,-27.18,0.029
3.42,-26.98,0.029
3.44,-26.77,0.029
3.46,-26.57,0.029
3.48,-26.37,0.029
3.50,-26.17,0.029
3.52,-25.97,0.029
3.54,-25.77,0.029
3.56,-25.57,0.029
3.58,-25.37,0.029
3.60,-25.17,0.029
3.62,-24.97,0.029
3.64,-24.77,0.029
3.66,-24.57,0.029
3.68,-24.37,0.029
3.70,-24.17,0.029
3.72,-23.97,0.029
3.74,-23.77,0.029
3.76,-23.57,0.029
3.78,-23.37,0.029
3.80,-23.17,0.029
3.82,-22.97,0.029
3.84,-22.77,0.029
3.86,-22.57,0.029
3.88,-22.37,0.029
3.90,-22.17,0.029
3.92,-21.97,0.029
3.94,-21.77,0.029
3.96,-21.57,0.029
3.98,-21.37,0.029
4.00,-21.17,0.029
4.02,-20.97,0.029
4.04,-20.77,0.029
4.06,-20.57,0.029
4.08,-20.37,0.029
4.10,-20.17,0.029
4.12,-19.97,0.029
4.14,-19.77,0.029
4.16,-19.57,0.029
4.18,-19.37,0.029
4.20,-19.17,0.029
4.22,-18.97,0.029
4.24,-18.77,0.029
4.26,-18.57,0.029
4.28,-18.36,0.029
4.30,-18.17,0.029
4.32,-17.97,0.029
4.34,-17.77,0.029
4.36,-17.57,0.030
4.38,-17.37,0.030
4.40,-17.16,0.030
4.42,-16.97,0.030
4.44,-16.76,0.030
4.46,-16.56,0.030
4.48,-16.36,0.030
4.50,-16.16,0.030
4.52,-15.96,0.030
4.54,-15.76,0.030
4.56,-15.56,0.030
4.58,-15.36,0.030
4.60,-15.16,0.030
4.62,-14.96,0.030
4.64,-14.76,0.030
4.66,-14.56,0.030
4.68,-14.36,0.030
4.70,-14.16,0.030
4.72,-13.96,0.030
4.74,-13.76,0.030
4.76,-13.56,0.030
4.78,-13.36,0.030
4.80,-13.16,0.030
4.82,-12.96,0.030
4.84,-12.76,0.030
4.86,-12.56,0.030
4.88,-12.36,0.030
4.90,-12.16,0.030
4.92,-11.96,0.030
4.94,-11.76,0.030
4.96,-11.56,0.030
4.98,-11.36,0.030
5.00,-11.16,0.030
5.02,-10.96,0.030
5.04,-10.76,0.030
5.06,-10.56,0.030
5.08,-10.36,0.030
5.10,-10.16,0.030
5.12,-9.96,0.030
5.14,-9.76,0.030
5.16,-9.56,0.030
5.18,-9.36,0.030
5.20,-9.16,0.030
5.22,-8.96,0.030
5.24,-8.76,0.030
5.26,-8.56,0.030
5.28,-8.36,0.030
5.30,-8.16,0.030
5.32,-7.96,0.030
5.34,-7.76,0.030
5.36,-7.56,0.030
5.38,-7.36,0.030
5.40,-7.16,0.030
5.42,-6.96,0.030
5.44,-6.76,0.030
5.46,-6.56,0.030
5.48,-6.36,0.031
5.50,-6.16,0.031
5.52,-5.96,0.031
5.54,-5.76,0.031
5.56,-5.56,0.031
5.58,-5.36,0.031
5.60,-5.16,0.031
5.62,-4.95,0.031
5.64,-4.75,0.031
5.66,-4.55,0.031
5.68,-4.35,0.031
5.70,-4.15,0.031
5.72,-3.95,0.031
5.74,-3.75,0.031
5.76,-3.55,0.031
5.78,-3.35,0.031
5.80,-3.15,0.031
5.82,-2.95,0.031
5.84,-2.75,0.031
5.86,-2.55,0.031
5.88,-2.35,0.031
5.90,-2.15,0.031
5.92,-1.95,0.031
5.94,-1.75,0.031
5.96,-1.55,0.031
5.98,-1.35,0.031
6.00,-1.15,0.031
6.02,-0.95,0.031
6.04,-0.75,0.031
6.06,-0.55,0.031
6.08,-0.35,0.031
6.10,-0.15,0.031
6.12,0.05,0.031
6.14,0.25,0.031
6.16,0.45,0.031
6.18,0.65,0.031
6.20,0.85,0.031
6.22,1.05,0.031
6.24,1.25,0.031
6.26,1.45,0.031
6.28,1.65,0.031
6.30,1.85,0.032
6.32,2.06,0.032
6.34,2.25,0.032
6.36,2.46,0.032
6.38,2.65,0.032
6.40,2.86,0.032
6.42,3.06,0.032
6.44,3.26,0.032
6.46,3.46,0.032
6.48,3.66,0.032
6.50,3.86,0.032
6.52,4.06,0.032
6.54,4.26,0.032
6.56,4.46,0.032
6.58,4.66,0.032
6.60,4.86,0.032
6.62,5.06,0.032
6.64,5.26,0.032
6.66,5.46,0.032
6.68,5.66,0.032
6.70,5.86,0.032
6.72,6.06,0.032
6.74,6.26,0.032
6.76,6.46,0.032
6.78,6.66,0.032
6.80,6.86,0.032
6.82,7.06,0.032
6.84,7.26,0.032
6.86,7.46,0.032
6.88,7.66,0.032
6.90,7.86,0.032
6.92,8.06,0.032
6.94,8.26,0.032
6.96,8.46,0.032
6.98,8.66,0.033
7.00,8.86,0.033
7.02,9.06,0.033
7.04,9.26,0.033
7.06,9.46,0.033
7.08,9.66,0.033
7.10,9.86,0.033
7.12,10.06,0.033
7.14,10.26,0.033
7.16,10.46,0.033
7.18,10.66,0.033
7.20,10.86,0.033
7.22,11.06,0.033
7.24,11.26,0.033
7.26,11.46,0.033
7.28,11.66,0.033
7.30,11.86,0.033
7.32,12.06,0.033
7.34,12.26,0.033
7.36,12.46,0.033
7.38,12.66,0.033
7.40,12.86,0.033
7.42,13.06,0.033
7.44,13.26,0.033
7.46,13.47,0.033
7.48,13.66,0.033
7.50,13.87,0.034
7.52,14.06,0.034
7.54,14.26,0.034
7.56,14.47,0.034
7.58,14.67,0.034
7.60,14.87,0.034
7.62,15.07,0.034
7.64,15.27,0.034
7.66,15.47,0.034
7.68,15.67,0.034
7.70,15.87,0.034
7.72,16.07,0.034
7.74,16.27,0.034
7.76,16.47,0.034
7.78,16.67,0.034
7.80,16.87,0.034
7.82,17.07,0.034
7.84,17.27,0.034
7.86,17.47,0.034
7.88,17.67,0.034
7.90,17.87,0.034
7.92,18.07,0.034
7.94,18.27,0.034
7.96,18.47,0.035
7.98,18.67,0.035
8.00,18.87,0.035
8.02,19.07,0.035
8.04,19.27,0.035
8.06,19.47,0.035
8.08,19.67,0.035
8.10,19.87,0.035
8.12,20.07,0.035
8.14,20.27,0.035
8.16,20.47,0.035
8.18,20.67,0.035
8.20,20.87,0.035
8.22,21.07,0.035
8.24,21.27,0.035
8.26,21.47,0.035
8.28,21.67,0.035
8.30,21.87,0.035
8.32,22.07,0.035
8.34,22.27,0.036
8.36,22.47,0.036
8.38,22.67,0.036
8.40,22.87,0.036
8.42,23.07,0.036
8.44,23.27,0.036
8.46,23.47,0.036
8.48,23.67,0.036
8.50,23.87,0.036
8.52,24.07,0.036
8.54,24.27,0.036
8.56,24.47,0.036
8.58,24.67,0.036
8.60,24.87,0.036
8.62,25.07,0.036
8.64,25.27,0.036
8.66,25.47,0.037
8.68,25.67,0.037
8.70,25.87,0.037
8.72,26.07,0.037
8.74,26.27,0.037
8.76,26.47,0.037
8.78,26.67,0.037
8.80,26.87,0.037
8.82,27.07,0.037
8.84,27.27,0.037
8.86,27.47,0.037
8.88,27.67,0.037
8.90,27.87,0.037
8.92,28.07,0.037
8.94,28.27,0.038
8.96,28.47,0.038
8.98,28.67,0.038
9.00,28.87,0.038
9.02,29.07,0.038
9.04,29.27,0.038
9.06,29.47,0.038
9.08,29.67,0.038
9.10,29.87,0.038
9.12,30.07,0.038
9.14,30.27,0.038
9.16,30.47,0.038
9.18,30.67,0.038
9.20,30.87,0.039
9.22,31.07,0.039
9.24,31.27,0.039
9.26,31.47,0.039
9.28,31.67,0.039
9.30,31.87,0.039
9.32,32.07,0.039
9.34,32.27,0.039
9.36,32.47,0.039
9.38,32.67,0.039
9.40,32.87,0.039
9.42,33.07,0.040
9.44,33.27,0.040
9.46,33.47,0.040
9.48,33.67,0.040
9.50,33.87,0.040
9.52,34.07,0.040
9.54,34.27,0.040
9.56,34.47,0.040
9.58,34.67,0.040
9.60,34.87,0.040
9.62,35.07,0.040
9.64,35.27,0.041
9.66,35.47,0.041
9.68,35.67,0.041
9.70,35.87,0.041
9.72,36.07,0.041
9.74,36.27,0.041
9.76,36.47,0.041
9.78,36.67,0.041
9.80,36.87,0.041
9.82,37.07,0.042
9.84,37.27,0.042
9.86,37.47,0.042
9.88,37.67,0.042
9.90,37.87,0.042
9.92,38.07,0.042
9.94,38.27,0.042
9.96,38.47,0.042
9.98,38.67,0.042
10.00,38.87,0.043
10.02,39.07,0.043
10.04,39.27,0.043
10.06,39.47,0.043
10.08,39.67,0.043
10.10,39.87,0.043
10.12,40.07,0.043
10.14,40.27,0.043
10.16,40.47,0.044
10.18,40.67,0.044
10.20,40.87,0.044
10.22,41.07,0.044
10.24,41.27,0.044
10.26,41.47,0.044
10.28,41.67,0.045
10.30,41.87,0.045
10.32,42.07,0.045
10.34,42.27,0.045
10.36,42.47,0.045
10.38,42.67,0.045
10.40,42.87,0.045
10.42,43.07,0.046
10.44,43.27,0.046
10.46,43.47,0.046
10.48,43.67,0.046
10.50,43.87,0.046
10.52,44.07,0.047
10.54,44.27,0.047
10.56,44.47,0.047
10.58,44.67,0.047
10.60,44.87,0.047
10.62,45.07,0.048
10.64,45.27,0.048
10.66,45.47,0.048
10.68,45.67,0.048
10.70,45.87,0.048
10.72,46.07,0.049
10.74,46.27,0.049
10.76,46.47,0.049
10.78,46.67,0.049
10.80,46.87,0.049
10.82,47.07,0.050
10.84,47.27,0.050
10.86,47.47,0.050
10.88,47.67,0.051
10.90,47.87,0.051
10.92,48.07,0.051
10.94,48.27,0.051
10.96,48.46,0.051
10.98,48.66,0.052
11.00,48.86,0.052
11.02,49.06,0.052
11.04,49.26,0.052
11.06,49.46,0.053
11.08,49.66,0.053
11.10,49.86,0.053
11.12,50.06,0.054
11.14,50.26,0.054
11.16,50.46,0.054
11.18,50.66,0.055
11.20,50.86,0.055
11.22,51.06,0.055
11.24,51.26,0.056
11.26,51.46,0.056
11.28,51.66,0.057
11.30,51.86,0.057
11.32,52.06,0.057
11.34,52.26,0.058
11.36,52.46,0.058
11.38,52.66,0.058
11.40,52.86,0.059
11.42,53.06,0.059
11.44,53.26,0.060
11.46,53.46,0.060
11.48,53.65,0.060
11.50,53.85,0.061
11.52,54.05,0.061
11.54,54.25,0.062
11.56,54.45,0.062
11.58,54.65,0.063
11.60,54.85,0.063
11.62,55.05,0.063
11.64,55.25,0.064
11.66,55.45,0.064
11.68,55.65,0.065
11.70,55.85,0.065
11.72,56.05,0.066
11.74,56.25,0.066
11.76,56.44,0.067
11.78,56.64,0.067
11.80,56.84,0.068
11.82,57.04,0.068
11.84,57.24,0.068
11.86,57.44,0.069
11.88,57.64,0.069
11.90,57.84,0.070
11.92,58.04,0.070
11.94,58.24,0.070
11.96,58.44,0.071
11.98,58.64,0.071
12.00,58.84,0.071
12.02,59.04,0.072
12.04,59.24,0.072
12.06,59.44,0.072
12.08,59.64,0.073
12.10,59.83,0.073
12.12,60.03,0.074
12.14,60.23,0.074
12.16,60.43,0.074
12.18,60.63,0.075
12.20,60.83,0.075
12.22,61.03,0.076
12.24,61.23,0.076
12.26,61.43,0.076
12.28,61.63,0.077
12.30,61.83,0.077
12.32,62.03,0.077
12.34,62.23,0.078
12.36,62.43,0.078
12.38,62.63,0.078
12.40,62.83,0.079
12.42,63.03,0.079
12.44,63.23,0.079
12.46,63.42,0.079
12.48,63.62,0.079
12.50,63.82,0.080
12.52,64.02,0.080
12.54,64.22,0.080
12.56,64.42,0.080
12.58,64.62,0.080
12.60,64.82,0.081
12.62,65.02,0.081
12.64,65.22,0.081
12.66,65.42,0.081
12.68,65.62,0.081
12.70,65.82,0.081
12.72,66.02,0.081
12.74,66.22,0.082
12.76,66.42,0.082
12.78,66.62,0.082
12.80,66.82,0.082
12.82,67.02,0.082
12.84,67.22,0.083
12.86,67.42,0.083
12.88,67.62,0.083
12.90,67.82,0.083
12.92,68.02,0.083
12.94,68.22,0.083
12.96,68.42,0.083
12.98,68.62,0.084
13.00,68.82,0.084
13.02,69.02,0.084
13.04,69.22,0.084
13.06,69.42,0.084
13.08,69.62,0.085
13.10,69.82,0.085
13.12,70.02,0.085
13.14,70.22,0.085
13.16,70.42,0.085
13.18,70.62,0.086
13.20,70.82,0.086
13.22,71.02,0.086
13.24,71.22,0.087
13.26,71.42,0.087
13.28,71.62,0.087
13.30,71.82,0.087
13.32,72.02,0.088
13.34,72.21,0.088
13.36,72.42,0.088
13.38,72.61,0.089
13.40,72.81,0.089
13.42,73.01,0.089
13.44,73.21,0.090
13.46,73.41,0.090
13.48,73.61,0.090
13.50,73.81,0.091
13.52,74.01,0.091
13.54,74.21,0.091
13.56,74.41,0.092
13.58,74.61,0.092
13.60,74.81,0.092
13.62,75.01,0.093
13.64,75.21,0.093
13.66,75.41,0.093
13.68,75.61,0.094
13.70,75.81,0.094
13.72,76.01,0.094
13.74,76.21,0.095
13.76,76.41,0.095
13.78,76.61,0.095
13.80,76.81,0.096
13.82,77.01,0.096
13.84,77.21,0.096
13.86,77.41,0.097
13.88,77.60,0.097
13.90,77.80,0.097
13.92,78.00,0.098
13.94,78.20,0.098
13.96,78.40,0.098
13.98,78.60,0.099
14.00,78.80,0.099
14.02,79.00,0.099
14.04,79.20,0.100
14.06,79.40,0.100
14.08,79.60,0.100
14.10,79.80,0.101
14.12,80.00,0.101
14.14,80.20,0.101
14.16,80.40,0.102
14.18,80.60,0.102
14.20,80.80,0.102
14.22,81.00,0.103
14.24,81.20,0.103
14.26,81.39,0.103
14.28,81.59,0.104
14.30,81.79,0.104
14.32,81.99,0.104
14.34,82.19,0.105
14.36,82.39,0.105
14.38,82.59,0.105
14.40,82.79,0.106
14.42,82.99,0.106
14.44,83.19,0.106
14.46,83.39,0.107
14.48,83.59,0.107
14.50,83.79,0.107
14.52,83.99,0.108
14.54,84.19,0.108
14.56,84.39,0.108
14.58,84.59,0.109
14.60,84.79,0.109
14.62,84.99,0.109
14.64,85.19,0.109
14.66,85.39,0.110
14.68,85.59,0.110
14.70,85.79,0.110
14.72,85.99,0.111
14.74,86.18,0.111
14.76,86.38,0.111
14.78,86.58,0.111
14.80,86.78,0.112
14.82,86.98,0.112
14.84,87.18,0.112
14.86,87.38,0.113
14.88,87.58,0.113
14.90,87.78,0.113
14.92,87.98,0.113
14.94,88.18,0.114
14.96,88.38,0.114
14.98,88.58,0.114
15.00,88.78,0.114
15.02,88.98,0.115
15.04,89.18,0.115
15.06,89.38,0.115
15.08,89.58,0.115
15.10,89.78,0.116
15.12,89.98,0.116
15.14,90.18,0.116
15.16,90.38,0.116
15.18,90.58,0.116
15.20,90.78,0.117
15.22,90.98,0.117
15.24,91.18,0.117
15.26,91.38,0.117
15.28,91.58,0.117
15.30,91.78,0.118
15.32,91.98,0.118
15.34,92.18,0.118
15.36,92.38,0.118
15.38,92.58,0.118
15.40,92.78,0.118
15.42,92.98,0.118
15.44,93.18,0.118
15.46,93.38,0.119
15.48,93.58,0.119
15.50,93.78,0.119
15.52,93.98,0.119
15.54,94.18,0.119
15.56,94.38,0.119
15.58,94.58,0.119
15.60,94.78,0.119
15.62,94.98,0.119
15.64,95.18,0.120
15.66,95.38,0.120
15.68,95.58,0.120
15.70,95.78,0.120
15.72,95.98,0.120
15.74,96.18,0.120
15.76,96.38,0.120
15.78,96.58,0.120
15.80,96.78,0.120
15.82,96.98,0.120
15.84,97.18,0.120
15.86,97.38,0.120
15.88,97.58,0.120
15.90,97.78,0.120
15.92,97.98,0.120
15.94,98.18,0.120
15.96,98.38,0.120
15.98,98.58,0.120
16.00,98.78,0.120
16.02,98.98,0.120
16.04,99.18,0.120
16.06,99.38,0.120
16.08,99.58,0.120
16.10,99.78,0.120
16.12,99.98,0.120
16.14,100.18,0.120
16.16,100.38,0.120
16.18,100.59,0.120
16.20,100.79,0.120
16.22,100.99,0.120
16.24,101.19,0.120
16.26,101.39,0.120
16.28,101.59,0.119
16.30,101.79,0.119
16.32,101.99,0.119
16.34,102.19,0.119
16.36,102.39,0.119
16.38,102.59,0.119
16.40,102.79,0.118
16.42,102.99,0.118
16.44,103.19,0.118
16.46,103.39,0.117
16.48,103.59,0.117
16.50,103.79,0.117
16.52,103.99,0.116
16.54,104.20,0.116
16.56,104.40,0.116
16.58,104.60,0.116
16.60,104.80,0.115
16.62,105.00,0.115
16.64,105.20,0.115
16.66,105.40,0.114
16.68,105.60,0.114
16.70,105.80,0.114
16.72,106.00,0.113
16.74,106.21,0.113
16.76,106.41,0.113
16.78,106.61,0.112
16.80,106.81,0.112
16.82,107.01,0.111
16.84,107.21,0.111
16.86,107.41,0.111
16.88,107.61,0.110
16.90,107.81,0.110
16.92,108.01,0.109
16.94,108.21,0.109
16.96,108.42,0.109
16.98,108.62,0.108
17.00,108.82,0.108
17.02,109.02,0.107
17.04,109.22,0.107
17.06,109.42,0.107
17.08,109.62,0.106
17.10,109.82,0.106
17.12,110.02,0.105
17.14,110.22,0.105
17.16,110.43,0.104
17.18,110.63,0.104
17.20,110.83,0.103
17.22,111.03,0.103
17.24,111.23,0.103
17.26,111.43,0.102
17.28,111.63,0.102
17.30,111.83,0.101
17.32,112.03,0.101
17.34,112.24,0.100
17.36,112.44,0.100
17.38,112.64,0.099
17.40,112.84,0.099
17.42,113.04,0.099
17.44,113.24,0.098
17.46,113.44,0.098
17.48,113.64,0.097
17.50,113.85,0.097
17.52,114.05,0.096
17.54,114.25,0.096
17.56,114.45,0.095
17.58,114.65,0.095
17.60,114.85,0.094
17.62,115.05,0.094
17.64,115.25,0.093
17.66,115.45,0.093
17.68,115.65,0.092
17.70,115.86,0.092
17.72,116.06,0.092
17.74,116.26,0.091
17.76,116.46,0.091
17.78,116.66,0.090
17.80,116.86,0.090
17.82,117.06,0.089
17.84,117.26,0.089
17.86,117.47,0.088
17.88,117.67,0.088
17.90,117.87,0.087
17.92,118.07,0.087
17.94,118.27,0.086
17.96,118.47,0.086
17.98,118.67,0.085
18.00,118.87,0.085
18.02,119.08,0.084
18.04,119.28,0.084
18.06,119.48,0.084
18.08,119.68,0.083
18.10,119.88,0.083
18.12,120.08,0.082
18.14,120.28,0.082
18.16,120.48,0.081
18.18,120.68,0.081
18.20,120.88,0.080
18.22,121.09,0.080
18.24,121.29,0.080
18.26,121.49,0.079
18.28,121.69,0.079
18.30,121.89,0.078
18.32,122.09,0.078
18.34,122.29,0.078
18.36,122.49,0.077
18.38,122.70,0.077
18.40,122.90,0.076
18.42,123.10,0.076
18.44,123.30,0.075
18.46,123.50,0.075
18.48,123.70,0.075
18.50,123.90,0.074
18.52,124.10,0.074
18.54,124.30,0.073
18.56,124.50,0.073
18.58,124.71,0.073
18.60,124.91,0.072
18.62,125.11,0.072
18.64,125.31,0.072
18.66,125.51,0.071
18.68,125.71,0.071
18.70,125.91,0.070
18.72,126.11,0.070
18.74,126.31,0.070
18.76,126.51,0.069
18.78,126.71,0.069
18.80,126.92,0.069
18.82,127.12,0.068
18.84,127.32,0.068
18.86,127.52,0.068
18.88,127.72,0.067
18.90,127.92,0.067
18.92,128.12,0.067
18.94,128.32,0.066
18.96,128.52,0.066
18.98,128.72,0.066
19.00,128.93,0.065
19.02,129.13,0.065
19.04,129.33,0.065
19.06,129.53,0.064
19.08,129.73,0.064
19.10,129.93,0.064
19.12,130.13,0.063
19.14,130.33,0.063
19.16,130.53,0.063
19.18,130.73,0.063
19.20,130.93,0.062
19.22,131.14,0.062
19.24,131.34,0.062
19.26,131.54,0.062
19.28,131.74,0.061
19.30,131.94,0.061
19.32,132.14,0.061
19.34,132.34,0.060
19.36,132.54,0.060
19.38,132.74,0.060
19.40,132.94,0.060
19.42,133.14,0.059
19.44,133.34,0.059
19.46,133.54,0.059
19.48,133.74,0.059
19.50,133.94,0.058
19.52,134.15,0.058
19.54,134.35,0.058
19.56,134.55,0.058
19.58,134.75,0.057
19.60,134.95,0.057
19.62,135.15,0.057
19.64,135.35,0.057
19.66,135.55,0.057
19.68,135.75,0.056
19.70,135.95,0.056
19.72,136.15,0.056
19.74,136.35,0.056
19.76,136.55,0.056
19.78,136.75,0.055
19.80,136.95,0.055
19.82,137.15,0.055
19.84,137.35,0.055
19.86,137.55,0.055
19.88,137.75,0.055
19.90,137.96,0.054
19.92,138.15,0.054
19.94,138.36,0.054
19.96,138.56,0.054
19.98,138.76,0.054
20.00,138.96,0.054
20.02,139.16,0.053
20.04,139.36,0.053
20.06,139.56,0.053
20.08,139.76,0.053
20.10,139.96,0.053
20.12,140.16,0.053
20.14,140.36,0.052
20.16,140.56,0.052
20.18,140.76,0.052
20.20,140.96,0.052
20.22,141.16,0.052
20.24,141.36,0.052
20.26,141.56,0.052
20.28,141.76,0.052
20.30,141.96,0.051
20.32,142.16,0.051
20.34,142.37,0.051
20.36,142.57,0.051
20.38,142.77,0.051
20.40,142.97,0.051
20.42,143.17,0.051
20.44,143.37,0.050
20.46,143.57,0.050
20.48,143.77,0.050
20.50,143.97,0.050
20.52,144.17,0.050
20.54,144.37,0.050
20.56,144.57,0.050
20.58,144.77,0.050
20.60,144.97,0.050
20.62,145.17,0.049
20.64,145.37,0.049
20.66,145.57,0.049
20.68,145.77,0.049
20.70,145.97,0.049
20.72,146.17,0.049
20.74,146.37,0.049
20.76,146.57,0.049
20.78,146.77,0.049
20.80,146.97,0.049
20.82,147.17,0.048
20.84,147.37,0.048
20.86,147.58,0.048
20.88,147.78,0.048
20.90,147.98,0.048
20.92,148.18,0.048
20.94,148.38,0.048
20.96,148.58,0.048
20.98,148.78,0.048
21.00,148.98,0.048
21.02,149.18,0.048
21.04,149.38,0.047
21.06,149.58,0.047
21.08,149.78,0.047
21.10,149.98,0.047
21.12,150.18,0.047
21.14,150.38,0.047
21.16,150.58,0.047
21.18,150.78,0.047
21.20,150.98,0.047
21.22,151.18,0.047
21.24,151.38,0.047
21.26,151.58,0.047
21.28,151.78,0.047
21.30,151.98,0.047
21.32,152.18,0.047
21.34,152.38,0.046
21.36,152.58,0.046
21.38,152.78,0.046
21.40,152.98,0.046
21.42,153.18,0.046
21.44,153.38,0.046
21.46,153.58,0.046
21.48,153.78,0.046
21.50,153.98,0.046
21.52,154.18,0.046
21.54,154.38,0.046
21.56,154.58,0.046
21.58,154.78,0.046
21.60,154.98,0.046
21.62,155.18,0.046
21.64,155.38,0.046
21.66,155.58,0.046
21.68,155.78,0.046
21.70,155.99,0.046
21.72,156.18,0.046
21.74,156.39,0.046
21.76,156.59,0.046
21.78,156.79,0.045
21.80,156.99,0.045
21.82,157.19,0.045
21.84,157.39,0.045
21.86,157.59,0.045
21.88,157.79,0.045
21.90,157.99,0.045
21.92,158.19,0.045
21.94,158.39,0.045
21.96,158.59,0.045
21.98,158.79,0.045
22.00,158.99,0.045
22.02,159.19,0.045
22.04,159.39,0.045
22.06,159.59,0.045
22.08,159.79,0.045
22.10,159.99,0.045
22.12,160.19,0.045
22.14,160.39,0.045
22.16,160.59,0.045
22.18,160.79,0.045
22.20,160.99,0.045
22.22,161.19,0.045
22.24,161.39,0.045
22.26,161.59,0.045
22.28,161.79,0.045
22.30,161.99,0.045
22.32,162.19,0.045
22.34,162.39,0.045
22.36,162.59,0.045
22.38,162.79,0.045
22.40,162.99,0.045
22.42,163.19,0.045
22.44,163.39,0.045
22.46,163.59,0.045
22.48,163.79,0.045
22.50,163.99,0.045
22.52,164.19,0.045
22.54,164.39,0.045
22.56,164.59,0.045
22.58,164.79,0.045
22.60,164.99,0.045
22.62,165.19,0.045
22.64,165.39,0.045
22.66,165.59,0.045
22.68,165.79,0.045
22.70,165.99,0.045
22.72,166.19,0.045
22.74,166.39,0.045
22.76,166.59,0.045
22.78,166.79,0.045
22.80,166.99,0.045
22.82,167.19,0.045
22.84,167.39,0.045
22.86,167.59,0.045
22.88,167.80,0.045
22.90,168.00,0.045
22.92,168.20,0.045
22.94,168.40,0.045
22.96,168.60,0.045
22.98,168.80,0.045
23.00,169.00,0.045
23.02,169.20,0.045
23.04,169.40,0.045
23.06,169.60,0.045
23.08,169.80,0.045
23.10,170.00,0.045
23.12,170.20,0.045
23.14,170.40,0.045
23.16,170.60,0.045
23.18,170.80,0.045
23.20,171.00,0.045
23.22,171.20,0.045
23.24,171.40,0.045
23.26,171.60,0.045
23.28,171.80,0.045
23.30,172.00,0.045
23.32,172.20,0.045
23.34,172.40,0.045
23.36,172.60,0.045
23.38,172.80,0.045
23.40,173.00,0.045
23.42,173.20,0.045
23.44,173.40,0.045
23.46,173.60,0.045
23.48,173.80,0.045
23.50,174.00,0.045
23.52,174.20,0.045
23.54,174.40,0.045
23.56,174.60,0.045
23.58,174.80,0.045
23.60,175.00,0.045
23.62,175.20,0.045
23.64,175.40,0.045
23.66,175.60,0.045
23.68,175.80,0.045
23.70,176.00,0.045
23.72,176.20,0.045
23.74,176.40,0.045
23.76,176.60,0.045
23.78,176.80,0.045
23.80,177.00,0.045
23.82,177.20,0.046
23.84,177.40,0.046
23.86,177.60,0.046
23.88,177.80,0.046
23.90,178.00,0.046
23.92,178.20,0.046
23.94,178.40,0.046
23.96,178.60,0.046
23.98,178.80,0.046
24.00,179.00,0.046
24.02,179.20,0.046
24.04,179.40,0.046
24.06,179.60,0.046
24.08,179.80,0.046
24.10,180.00,0.046
24.12,180.21,0.046
24.14,180.40,0.046
24.16,180.61,0.046
24.18,180.81,0.046
24.20,181.01,0.046
24.22,181.20,0.046
24.24,181.40,0.046
24.26,181.61,0.046
24.28,181.80,0.046
24.30,182.01,0.046
24.32,182.21,0.046
24.34,182.41,0.046
24.36,182.61,0.046
24.38,182.81,0.046
24.40,183.01,0.046
24.42,183.21,0.046
24.44,183.41,0.046
24.46,183.61,0.046
24.48,183.81,0.046
24.50,184.01,0.046
24.52,184.21,0.046
24.54,184.41,0.046
24.56,184.61,0.046
24.58,184.81,0.046
24.60,185.01,0.046
24.62,185.21,0.046
24.64,185.41,0.046
24.66,185.61,0.046
24.68,185.81,0.046
24.70,186.01,0.046
24.72,186.21,0.046
24.74,186.41,0.046
24.76,186.61,0.046
24.78,186.81,0.046
24.80,187.01,0.046
24.82,187.21,0.046
24.84,187.41,0.046
24.86,187.61,0.046
24.88,187.81,0.046
24.90,188.01,0.046
24.92,188.21,0.046
24.94,188.41,0.046
24.96,188.61,0.046
24.98,188.81,0.046
25.00,189.01,0.046
25.02,189.21,0.046
25.04,189.41,0.046
25.06,189.61,0.046
25.08,189.81,0.046
25.10,190.01,0.046
25.12,190.21,0.046
25.14,190.41,0.046
25.16,190.61,0.046
25.18,190.81,0.046
25.20,191.01,0.046
25.22,191.21,0.046
25.24,191.41,0.046
25.26,191.61,0.046
25.28,191.81,0.046
25.30,192.01,0.046
25.32,192.21,0.046
25.34,192.41,0.046
25.36,192.61,0.046
25.38,192.81,0.046
25.40,193.01,0.046
25.42,193.21,0.046
25.44,193.41,0.046
25.46,193.61,0.046
25.48,193.81,0.046
25.50,194.01,0.046
25.52,194.21,0.046
25.54,194.41,0.047
25.56,194.62,0.047
25.58,194.82,0.047
25.60,195.02,0.047
25.62,195.22,0.047
25.64,195.42,0.047
25.66,195.62,0.047
25.68,195.82,0.047
25.70,196.02,0.047
25.72,196.22,0.047
25.74,196.42,0.047
25.76,196.62,0.047
25.78,196.82,0.047
25.80,197.02,0.047
25.82,197.22,0.047
25.84,197.42,0.047
25.86,197.62,0.047
25.88,197.82,0.047
25.90,198.02,0.047
25.92,198.22,0.047
25.94,198.42,0.047
25.96,198.62,0.047
25.98,198.82,0.047
26.00,199.02,0.047
26.02,199.22,0.047
26.04,199.42,0.047
26.06,199.62,0.047
26.08,199.82,0.047
26.10,200.02,0.047
26.12,200.22,0.047
26.14,200.42,0.047
26.16,200.62,0.047
26.18,200.82,0.047
26.20,201.02,0.047
26.22,201.22,0.047
26.24,201.42,0.047
26.26,201.62,0.047
26.28,201.82,0.047
26.30,202.02,0.047
26.32,202.22,0.047
26.34,202.42,0.047
26.36,202.62,0.047
26.38,202.82,0.047
26.40,203.02,0.047
26.42,203.22,0.047
26.44,203.42,0.047
26.46,203.62,0.047
26.48,203.82,0.047
26.50,204.02,0.047
26.52,204.22,0.047
26.54,204.42,0.047
26.56,204.62,0.047
26.58,204.82,0.047
26.60,205.02,0.047
26.62,205.22,0.047
26.64,205.42,0.047
26.66,205.62,0.047
26.68,205.82,0.047
26.70,206.02,0.047
26.72,206.22,0.047
26.74,206.42,0.047
26.76,206.62,0.047
26.78,206.82,0.047
26.80,207.02,0.047
26.82,207.22,0.047
26.84,207.42,0.047
26.86,207.62,0.047
26.88,207.82,0.047
26.90,208.02,0.047
26.92,208.22,0.047
26.94,208.42,0.047
26.96,208.62,0.047
26.98,208.82,0.047
27.00,209.02,0.047
27.02,209.22,0.047
27.04,209.42,0.047
27.06,209.62,0.047
27.08,209.82,0.047
27.10,210.02,0.047
27.12,210.22,0.047
27.14,210.42,0.047
27.16,210.62,0.047
27.18,210.82,0.047
27.20,211.02,0.047
27.22,211.22,0.047
27.24,211.42,0.047
27.26,211.62,0.047
27.28,211.82,0.047
27.30,212.02,0.047
27.32,212.22,0.047
27.34,212.42,0.047
27.36,212.62,0.047
27.38,212.82,0.047
27.40,213.03,0.047
27.42,213.23,0.047
27.44,213.43,0.047
27.46,213.63,0.047
27.48,213.83,0.047
27.50,214.03,0.047
27.52,214.23,0.047
27.54,214.43,0.047
27.56,214.63,0.047
27.58,214.83,0.047
27.60,215.03,0.047
27.62,215.23,0.047
27.64,215.43,0.047
27.66,215.63,0.047
27.68,215.83,0.047
27.70,216.03,0.047
27.72,216.23,0.047
27.74,216.43,0.047
27.76,216.63,0.047
27.78,216.83,0.047
27.80,217.03,0.047
27.82,217.23,0.047
27.84,217.43,0.047
27.86,217.63,0.047
27.88,217.83,0.047
27.90,218.03,0.047
27.92,218.23,0.047
27.94,218.43,0.047
27.96,218.63,0.047
27.98,218.83,0.047
28.00,219.03,0.047
28.02,219.23,0.047
28.04,219.43,0.047
28.06,219.63,0.047
28.08,219.83,0.047
28.10,220.03,0.047
28.12,220.23,0.047
28.14,220.43,0.047
28.16,220.63,0.047
28.18,220.83,0.047
28.20,221.03,0.047
28.22,221.23,0.047
28.24,221.43,0.047
28.26,221.63,0.047
28.28,221.83,0.048
28.30,222.03,0.048
28.32,222.23,0.048
28.34,222.43,0.048
28.36,222.63,0.048
28.38,222.83,0.048
28.40,223.03,0.048
28.42,223.23,0.048
28.44,223.43,0.048
28.46,223.63,0.048
28.48,223.83,0.048
28.50,224.03,0.048
28.52,224.23,0.048
28.54,224.43,0.048
28.56,224.63,0.048
28.58,224.83,0.048
28.60,225.03,0.048
28.62,225.23,0.048
28.64,225.43,0.048
28.66,225.63,0.048
28.68,225.83,0.048
28.70,226.03,0.048
28.72,226.23,0.048
28.74,226.43,0.048
28.76,226.63,0.048
28.78,226.83,0.048
28.80,227.03,0.048
28.82,227.23,0.048
28.84,227.43,0.048
28.86,227.63,0.048
28.88,227.84,0.048
28.90,228.03,0.048
28.92,228.24,0.048
28.94,228.44,
28.96,228.64,
28.98,228.84,
28.99,,

[step]
Ramp 10.00 °C/min to -60.00 °C
Time,Temperature,Heat Flow (Normalized)
min,°C,W/g
30.99,230.17,-0.005
31.01,230.16,-0.005
31.03,230.16,-0.005
31.05,230.15,-0.006
31.07,230.11,-0.008
31.09,230.05,-0.013
31.11,229.96,-0.021
31.13,229.83,-0.029
31.15,229.69,-0.036
31.17,229.53,-0.043
31.19,229.35,-0.048
31.21,229.17,-0.051
31.23,228.98,-0.054
31.25,228.79,-0.055
31.27,228.59,-0.056
31.29,228.40,-0.057
31.31,228.20,-0.057
31.33,228.01,-0.057
31.35,227.81,-0.058
31.37,227.61,-0.058
31.39,227.42,-0.058
31.41,227.22,-0.058
31.43,227.02,-0.058
31.45,226.82,-0.058
31.47,226.62,-0.058
31.49,226.42,-0.058
31.51,226.23,-0.058
31.53,226.03,-0.058
31.55,225.83,-0.058
31.57,225.63,-0.058
31.59,225.43,-0.058
31.61,225.23,-0.058
31.63,225.03,-0.058
31.65,224.84,-0.058
31.67,224.64,-0.058
31.69,224.44,-0.058
31.71,224.24,-0.058
31.73,224.04,-0.058
31.75,223.84,-0.058
31.77,223.64,-0.058
31.79,223.44,-0.058
31.81,223.25,-0.058
31.83,223.05,-0.058
31.85,222.85,-0.058
31.87,222.65,-0.058
31.89,222.45,-0.058
31.91,222.25,-0.058
31.93,222.05,-0.058
31.95,221.85,-0.058
31.97,221.65,-0.058
31.99,221.45,-0.058
32.01,221.25,-0.058
32.03,221.05,-0.058
32.05,220.85,-0.058
32.07,220.66,-0.058
32.09,220.46,-0.058
32.11,220.26,-0.058
32.13,220.06,-0.058
32.15,219.86,-0.058
32.17,219.66,-0.058
32.19,219.46,-0.058
32.21,219.26,-0.058
32.23,219.06,-0.058
32.25,218.86,-0.058
32.27,218.66,-0.058
32.29,218.46,-0.058
32.31,218.26,-0.058
32.33,218.06,-0.058
32.35,217.86,-0.058
32.37,217.66,-0.058
32.39,217.46,-0.058
32.41,217.26,-0.058
32.43,217.06,-0.058
32.45,216.87,-0.058
32.47,216.67,-0.058
32.49,216.47,-0.058
32.51,216.27,-0.058
32.53,216.07,-0.058
32.55,215.87,-0.058
32.57,215.67,-0.058
32.59,215.47,-0.058
32.61,215.27,-0.058
32.63,215.07,-0.058
32.65,214.87,-0.058
32.67,214.67,-0.058
32.69,214.47,-0.058
32.71,214.27,-0.058
32.73,214.07,-0.058
32.75,213.87,-0.058
32.77,213.67,-0.058
32.79,213.47,-0.058
32.81,213.27,-0.058
32.83,213.07,-0.058
32.85,212.87,-0.058
32.87,212.67,-0.058
32.89,212.47,-0.058
32.91,212.27,-0.058
32.93,212.07,-0.058
32.95,211.87,-0.058
32.97,211.67,-0.058
32.99,211.47,-0.058
33.01,211.27,-0.058
33.03,211.07,-0.058
33.05,210.87,-0.058
33.07,210.67,-0.058
33.09,210.47,-0.058
33.11,210.27,-0.058
33.13,210.07,-0.058
33.15,209.87,-0.058
33.17,209.67,-0.058
33.19,209.47,-0.058
33.21,209.27,-0.058
33.23,209.07,-0.058
33.25,208.87,-0.058
33.27,208.67,-0.058
33.29,208.47,-0.058
33.31,208.27,-0.058
33.33,208.07,-0.058
33.35,207.87,-0.058
33.37,207.68,-0.058
33.39,207.48,-0.058
33.41,207.28,-0.057
33.43,207.08,-0.057
33.45,206.88,-0.057
33.47,206.68,-0.057
33.49,206.48,-0.057
33.51,206.28,-0.057
33.53,206.07,-0.057
33.55,205.88,-0.057
33.57,205.68,-0.057
33.59,205.48,-0.057
33.61,205.28,-0.057
33.63,205.07,-0.057
33.65,204.88,-0.057
33.67,204.68,-0.057
33.69,204.48,-0.057
33.71,204.28,-0.057
33.73,204.08,-0.057
33.75,203.87,-0.057
33.77,203.68,-0.057
33.79,203.48,-0.057
33.81,203.28,-0.057
33.83,203.08,-0.057
33.85,202.88,-0.057
33.87,202.68,-0.057
33.89,202.48,-0.057
33.91,202.28,-0.057
33.93,202.08,-0.057
33.95,201.88,-0.057
33.97,201.68,-0.057
33.99,201.48,-0.057
34.01,201.28,-0.057
34.03,201.08,-0.057
34.05,200.88,-0.057
34.07,200.68,-0.057
34.09,200.48,-0.057
34.11,200.28,-0.057
34.13,200.08,-0.057
34.15,199.88,-0.057
34.17,199.68,-0.057
34.19,199.48,-0.057
34.21,199.28,-0.057
34.23,199.08,-0.057
34.25,198.88,-0.057
34.27,198.68,-0.057
34.29,198.48,-0.057
34.31,198.28,-0.057
34.33,198.08,-0.057
34.35,197.88,-0.057
34.37,197.68,-0.057
34.39,197.48,-0.057
34.41,197.28,-0.057
34.43,197.08,-0.057
34.45,196.88,-0.057
34.47,196.68,-0.057
34.49,196.48,-0.057
34.51,196.28,-0.057
34.53,196.08,-0.057
34.55,195.88,-0.057
34.57,195.68,-0.057
34.59,195.48,-0.057
34.61,195.28,-0.057
34.63,195.08,-0.057
34.65,194.88,-0.057
34.67,194.68,-0.057
34.69,194.48,-0.057
34.71,194.28,-0.057
34.73,194.08,-0.057
34.75,193.88,-0.057
34.77,193.68,-0.057
34.79,193.48,-0.057
34.81,193.28,-0.057
34.83,193.08,-0.057
34.85,192.88,-0.057
34.87,192.68,-0.057
34.89,192.48,-0.056
34.91,192.28,-0.056
34.93,192.08,-0.056
34.95,191.88,-0.056
34.97,191.68,-0.056
34.99,191.48,-0.056
35.01,191.28,-0.056
35.03,191.08,-0.056
35.05,190.88,-0.056
35.07,190.68,-0.056
35.09,190.48,-0.056
35.11,190.28,-0.056
35.13,190.08,-0.056
35.15,189.88,-0.056
35.17,189.68,-0.056
35.19,189.48,-0.056
35.21,189.28,-0.056
35.23,189.08,-0.056
35.25,188.88,-0.056
35.27,188.68,-0.056
35.29,188.48,-0.056
35.31,188.28,-0.056
35.33,188.08,-0.056
35.35,187.88,-0.056
35.37,187.68,-0.056
35.39,187.48,-0.056
35.41,187.28,-0.056
35.43,187.08,-0.056
35.45,186.88,-0.056
35.47,186.68,-0.056
35.49,186.48,-0.056
35.51,186.28,-0.056
35.53,186.08,-0.056
35.55,185.88,-0.056
35.57,185.68,-0.056
35.59,185.48,-0.056
35.61,185.28,-0.056
35.63,185.08,-0.056
35.65,184.88,-0.056
35.67,184.68,-0.056
35.69,184.48,-0.056
35.71,184.28,-0.056
35.73,184.08,-0.056
35.75,183.88,-0.056
35.77,183.68,-0.056
35.79,183.48,-0.056
35.81,183.28,-0.056
35.83,183.08,-0.056
35.85,182.88,-0.056
35.87,182.68,-0.056
35.89,182.48,-0.056
35.91,182.28,-0.056
35.93,182.08,-0.056
35.95,181.88,-0.056
35.97,181.68,-0.056
35.99,181.48,-0.056
36.01,181.28,-0.056
36.03,181.08,-0.056
36.05,180.88,-0.056
36.07,180.68,-0.056
36.09,180.48,-0.056
36.11,180.28,-0.056
36.13,180.08,-0.056
36.15,179.88,-0.056
36.17,179.68,-0.056
36.19,179.48,-0.056
36.21,179.28,-0.056
36.23,179.08,-0.056
36.25,178.88,-0.056
36.27,178.68,-0.056
36.29,178.48,-0.056
36.31,178.29,-0.055
36.33,178.08,-0.055
36.35,177.89,-0.055
36.37,177.68,-0.055
36.39,177.49,-0.055
36.41,177.29,-0.055
36.43,177.09,-0.055
36.45,176.89,-0.055
36.47,176.69,-0.055
36.49,176.49,-0.055
36.51,176.29,-0.055
36.53,176.09,-0.055
36.55,175.89,-0.055
36.57,175.68,-0.055
36.59,175.48,-0.055
36.61,175.28,-0.055
36.63,175.08,-0.055
36.65,174.88,-0.055
36.67,174.69,-0.055
36.69,174.48,-0.055
36.71,174.28,-0.055
36.73,174.08,-0.055
36.75,173.89,-0.055
36.77,173.68,-0.055
36.79,173.48,-0.055
36.81,173.28,-0.055
36.83,173.08,-0.055
36.85,172.88,-0.055
36.87,172.68,-0.055
36.89,172.48,-0.055
36.91,172.28,-0.055
36.93,172.09,-0.055
36.95,171.89,-0.055
36.97,171.69,-0.055
36.99,171.49,-0.055
37.01,171.29,-0.055
37.03,171.09,-0.055
37.05,170.89,-0.055
37.07,170.69,-0.055
37.09,170.48,-0.055
37.11,170.29,-0.055
37.13,170.08,-0.055
37.15,169.88,-0.055
37.17,169.68,-0.055
37.19,169.49,-0.055
37.21,169.28,-0.055
37.23,169.09,-0.055
37.25,168.89,-0.055
37.27,168.69,-0.055
37.29,168.49,-0.055
37.31,168.29,-0.055
37.33,168.09,-0.055
37.35,167.89,-0.055
37.37,167.69,-0.055
37.39,167.49,-0.055
37.41,167.29,-0.055
37.43,167.09,-0.055
37.45,166.89,-0.055
37.47,166.69,-0.055
37.49,166.49,-0.055
37.51,166.29,-0.055
37.53,166.09,-0.055
37.55,165.89,-0.055
37.57,165.69,-0.055
37.59,165.49,-0.055
37.61,165.29,-0.055
37.63,165.09,-0.055
37.65,164.89,-0.055
37.67,164.69,-0.055
37.69,164.49,-0.055
37.71,164.29,-0.055
37.73,164.09,-0.055
37.75,163.89,-0.055
37.77,163.69,-0.055
37.79,163.49,-0.055
37.81,163.29,-0.055
37.83,163.09,-0.055
37.85,162.89,-0.055
37.87,162.69,-0.055
37.89,162.49,-0.054
37.91,162.29,-0.054
37.93,162.09,-0.054
37.95,161.89,-0.054
37.97,161.69,-0.054
37.99,161.49,-0.054
38.01,161.29,-0.054
38.03,161.09,-0.054
38.05,160.89,-0.054
38.07,160.69,-0.054
38.09,160.49,-0.054
38.11,160.29,-0.054
38.13,160.09,-0.054
38.15,159.89,-0.054
38.17,159.69,-0.054
38.19,159.49,-0.054
38.21,159.29,-0.054
38.23,159.09,-0.054
[...]
132.64,25.14,0.026
132.65,25.34,0.026
132.68,25.54,0.026
132.70,25.74,0.026
132.71,25.94,0.026
132.74,26.14,0.026
132.75,26.35,0.026
132.78,26.55,0.027
132.80,26.74,0.027
132.81,26.95,0.027
132.84,27.14,0.027
132.85,27.35,0.027
132.88,27.55,0.027
132.90,27.75,0.027
132.91,27.95,0.027
132.94,28.15,0.027
132.95,28.35,0.027
132.98,28.55,0.027
133.00,28.75,0.027
133.01,28.95,0.027
133.04,29.15,0.027
133.05,29.35,0.027
133.08,29.55,0.027
133.10,29.75,0.027
133.11,29.95,0.027
133.14,30.15,0.027
133.15,30.35,0.027
133.18,30.55,0.027
133.20,30.75,0.027
133.21,30.95,0.027
133.24,31.15,0.027
133.25,31.35,0.027
133.28,31.55,0.027
133.30,31.75,0.027
133.31,31.95,0.027
133.34,32.15,0.027
133.35,32.35,0.027
133.38,32.55,0.027
133.40,32.75,0.027
133.41,32.95,0.027
133.44,33.16,0.027
133.45,33.35,0.027
133.48,33.56,0.027
133.50,33.76,0.027
133.51,33.96,0.027
133.54,34.16,0.027
133.55,34.36,0.027
133.58,34.56,0.027
133.60,34.76,0.027
133.61,34.96,0.027
133.64,35.16,0.027
133.65,35.36,0.027
133.68,35.56,0.027
133.70,35.76,0.027
133.71,35.96,0.027
133.74,36.16,0.027
133.75,36.36,0.027
133.78,36.56,0.027
133.80,36.76,0.027
133.81,36.96,0.027
133.84,37.16,0.027
133.85,37.36,0.027
133.88,37.56,0.027
133.90,37.76,0.027
133.91,37.96,0.027
133.94,38.16,0.027
133.95,38.36,0.027
133.98,38.56,0.027
134.00,38.76,0.027
134.01,38.96,0.027
134.04,39.16,0.027
134.05,39.36,0.027
134.08,39.56,0.027
134.10,39.76,0.027
134.11,39.96,0.027
134.14,40.16,0.027
134.15,40.36,0.028
134.18,40.56,0.028
134.20,40.76,0.028
134.21,40.96,0.028
134.24,41.16,0.028
134.25,41.36,0.028
134.28,41.56,0.028
134.30,41.76,0.028
134.31,41.96,0.028
134.34,42.16,0.028
134.35,42.36,0.028
134.38,42.56,0.028
134.40,42.76,0.028
134.41,42.96,0.028
134.44,43.16,0.028
134.45,43.36,0.028
134.48,43.56,0.028
134.50,43.76,0.028
134.51,43.96,0.028
134.54,44.16,0.028
134.55,44.36,0.028
134.58,44.56,0.028
134.60,44.76,0.028
134.61,44.97,0.028
134.64,45.17,0.028
134.65,45.37,0.028
134.68,45.57,0.028
134.70,45.77,0.028
134.71,45.97,0.028
134.74,46.17,0.028
134.75,46.37,0.028
134.78,46.57,0.028
134.80,46.77,0.028
134.81,46.97,0.028
134.84,47.17,0.028
134.85,47.37,0.028
134.88,47.57,0.028
134.90,47.77,0.028
134.91,47.97,0.028
134.94,48.17,0.028
134.95,48.37,0.028
134.98,48.57,0.028
135.00,48.77,0.028
135.01,48.97,0.028
135.04,49.17,0.028
135.05,49.37,0.028
135.08,49.57,0.028
135.10,49.77,0.028
135.11,49.97,0.028
135.14,50.17,0.028
135.15,50.37,0.028
135.18,50.57,0.028
135.20,50.77,0.028
135.21,50.97,0.028
135.24,51.17,0.028
135.25,51.37,0.028
135.28,51.57,0.028
135.30,51.77,0.028
135.31,51.97,0.028
135.34,52.17,0.028
135.35,52.37,0.028
135.38,52.57,0.028
135.40,52.77,0.028
135.41,52.97,0.028
135.44,53.17,0.028
135.45,53.37,0.029
135.48,53.57,0.029
135.50,53.77,0.029
135.51,53.97,0.029
135.54,54.17,0.029
135.55,54.38,0.029
135.58,54.57,0.029
135.60,54.77,0.029
135.61,54.98,0.029
135.64,55.17,0.029
135.65,55.38,0.029
135.68,55.58,0.029
135.70,55.78,0.029
135.71,55.98,0.029
135.74,56.18,0.029
135.75,56.38,0.029
135.78,56.58,0.029
135.80,56.78,0.029
135.81,56.98,0.029
135.84,57.18,0.029
135.85,57.38,0.029
135.88,57.58,0.029
135.90,57.78,0.029
135.91,57.98,0.029
135.94,58.18,0.029
135.95,58.38,0.029
135.98,58.58,0.029
136.00,58.78,0.029
136.01,58.98,0.029
136.04,59.18,0.029
136.05,59.38,0.029
136.08,59.58,0.029
136.10,59.78,0.029
136.11,59.98,0.029
136.14,60.18,0.029
136.15,60.38,0.029
136.18,60.58,0.029
136.20,60.78,0.029
136.21,60.98,0.029
136.24,61.18,0.029
136.25,61.38,0.029
136.28,61.58,0.029
136.30,61.78,0.029
136.31,61.98,0.029
136.34,62.18,0.029
136.35,62.38,0.029
136.38,62.58,0.029
136.40,62.78,0.029
136.41,62.98,0.029
136.44,63.18,0.029
136.45,63.38,0.029
136.48,63.58,0.029
136.50,63.78,0.029
136.51,63.98,0.029
136.53,64.18,0.029
136.55,64.38,0.029
136.58,64.59,0.029
136.60,64.79,0.029
136.62,64.99,0.029
136.63,65.19,0.029
136.65,65.39,0.029
136.68,65.59,0.029
136.70,65.79,0.029
136.72,65.99,0.029
136.73,66.19,0.029
136.75,66.39,0.030
136.78,66.59,0.030
136.80,66.79,0.030
136.82,66.99,0.030
136.83,67.19,0.030
136.85,67.39,0.030
136.88,67.59,0.030
136.90,67.79,0.030
136.92,67.99,0.030
136.93,68.19,0.030
136.95,68.39,0.030
136.98,68.59,0.030
137.00,68.79,0.030
137.02,68.99,0.030
137.03,69.19,0.030
137.05,69.39,0.030
137.08,69.59,0.030
137.10,69.79,0.030
137.12,69.99,0.030
137.13,70.19,0.030
137.15,70.39,0.030
137.18,70.59,0.030
137.20,70.79,0.030
137.22,70.99,0.030
137.23,71.19,0.030
137.25,71.39,0.030
137.28,71.59,0.030
137.30,71.79,0.030
137.32,71.99,0.030
137.33,72.19,0.030
137.35,72.39,0.030
137.38,72.59,0.030
137.40,72.79,0.030
137.42,72.99,0.030
137.43,73.19,0.030
137.45,73.39,0.030
137.48,73.59,0.030
137.50,73.79,0.030
137.52,73.99,0.030
137.53,74.19,0.030
137.55,74.39,0.030
137.58,74.59,0.030
137.60,74.79,0.030
137.62,74.99,0.030
137.63,75.19,0.030
137.65,75.39,0.030
137.68,75.59,0.030
137.70,75.79,0.030
137.72,75.99,0.030
137.73,76.19,0.030
137.75,76.40,0.030
137.78,76.60,0.030
137.80,76.79,0.030
137.82,77.00,0.030
137.83,77.20,0.030
137.85,77.39,0.030
137.88,77.60,0.030
137.90,77.80,0.030
137.92,78.00,0.030
137.93,78.20,0.030
137.95,78.40,0.030
137.98,78.60,0.031
138.00,78.80,0.031
138.02,79.00,0.031
138.03,79.20,0.031
138.05,79.40,0.031
138.08,79.60,0.031
138.10,79.80,0.031
138.12,80.00,0.031
138.13,80.20,0.031
138.15,80.40,0.031
138.18,80.60,0.031
138.20,80.80,0.031
138.22,81.00,0.031
138.23,81.20,0.031
138.25,81.40,0.031
138.28,81.60,0.031
138.30,81.80,0.031
138.32,82.00,0.031
138.33,82.20,0.031
138.35,82.40,0.031
138.38,82.60,0.031
138.40,82.80,0.031
138.42,83.00,0.031
138.43,83.20,0.031
138.45,83.40,0.031
138.48,83.60,0.031
138.50,83.80,0.031
138.52,84.00,0.031
138.53,84.20,0.031
138.55,84.40,0.031
138.58,84.60,0.031
138.60,84.80,0.031
138.62,85.00,0.031
138.63,85.20,0.031
138.65,85.40,0.031
138.68,85.60,0.031
138.70,85.80,0.031
138.72,86.00,0.031
138.73,86.20,0.031
138.75,86.40,0.031
138.78,86.60,0.031
138.80,86.80,0.031
138.82,87.00,0.031
138.83,87.20,0.031
138.85,87.40,0.031
138.88,87.60,0.031
138.90,87.80,0.031
138.92,88.00,0.031
138.93,88.20,0.031
138.95,88.40,0.031
138.98,88.61,0.031
139.00,88.81,0.031
139.02,89.01,0.031
139.03,89.21,0.031
139.05,89.41,0.031
139.08,89.60,0.031
139.10,89.81,0.031
139.12,90.01,0.032
139.13,90.21,0.032
139.15,90.41,0.032
139.18,90.61,0.032
139.20,90.81,0.032
139.22,91.01,0.032
139.23,91.21,0.032
139.25,91.41,0.032
139.28,91.61,0.032
139.30,91.81,0.032
139.32,92.01,0.032
139.33,92.21,0.032
139.35,92.41,0.032
139.38,92.61,0.032
139.40,92.81,0.032
139.42,93.01,0.032
139.43,93.21,0.032
139.45,93.41,0.032
139.48,93.61,0.032
139.50,93.81,0.032
139.52,94.01,0.032
139.53,94.21,0.032
139.55,94.41,0.032
139.58,94.61,0.032
139.60,94.81,0.032
139.62,95.01,0.032
139.63,95.21,0.032
139.65,95.41,0.032
139.68,95.61,0.032
139.70,95.81,0.032
139.72,96.01,0.032
139.73,96.21,0.032
139.75,96.41,0.032
139.78,96.61,0.032
139.80,96.81,0.032
139.82,97.01,0.032
139.83,97.21,0.032
139.85,97.41,0.032
139.88,97.61,0.032
139.90,97.81,0.032
139.92,98.01,0.032
139.93,98.21,0.032
139.95,98.41,0.033
139.98,98.61,0.033
140.00,98.81,0.033
140.02,99.01,0.033
140.03,99.21,0.033
140.05,99.41,0.033
140.08,99.61,0.033
140.10,99.81,0.033
140.12,100.01,0.033
140.13,100.21,0.033
140.15,100.41,0.033
140.18,100.61,0.033
140.20,100.81,0.033
140.22,101.01,0.033
140.23,101.21,0.033
140.25,101.42,0.033
140.28,101.61,0.033
140.30,101.82,0.033
140.32,102.02,0.033
140.33,102.22,0.033
140.35,102.41,0.033
140.38,102.61,0.033
140.40,102.81,0.033
140.42,103.01,0.033
140.43,103.21,0.033
140.45,103.41,0.033
140.48,103.61,0.033
140.50,103.81,0.033
140.52,104.01,0.033
140.53,104.22,0.033
140.55,104.42,0.033
140.58,104.62,0.033
140.60,104.82,0.034
140.62,105.02,0.034
140.63,105.22,0.034
140.65,105.42,0.034
140.68,105.62,0.034
140.70,105.82,0.034
140.72,106.02,0.034
140.73,106.22,0.034
140.75,106.42,0.034
140.78,106.62,0.034
140.80,106.82,0.034
140.82,107.02,0.034
140.83,107.22,0.034
140.85,107.42,0.034
140.88,107.62,0.034
140.90,107.82,0.034
140.92,108.02,0.034
140.93,108.22,0.034
140.95,108.42,0.034
140.98,108.62,0.034
141.00,108.82,0.034
141.02,109.02,0.034
141.03,109.22,0.035
141.05,109.42,0.035
141.08,109.62,0.035
141.10,109.82,0.035
141.12,110.02,0.035
141.13,110.21,0.035
141.15,110.42,0.035
141.18,110.62,0.035
141.20,110.81,0.035
141.22,111.01,0.035
141.23,111.22,0.035
141.25,111.41,0.035
141.28,111.62,0.035
141.30,111.82,0.035
141.32,112.02,0.035
141.33,112.21,0.036
141.35,112.42,0.036
141.38,112.62,0.036
141.40,112.82,0.036
141.42,113.02,0.036
141.43,113.22,0.036
141.45,113.42,0.036
141.48,113.62,0.036
141.50,113.82,0.036
141.52,114.02,0.036
141.53,114.22,0.036
141.55,114.42,0.037
141.58,114.62,0.037
141.60,114.82,0.037
141.62,115.02,0.037
141.63,115.22,0.037
141.65,115.42,0.037
141.68,115.62,0.037
141.70,115.82,0.037
141.72,116.02,0.037
141.73,116.22,0.037
141.75,116.42,0.038
141.78,116.62,0.038
141.80,116.82,0.038
141.82,117.02,0.038
141.83,117.22,0.038
141.85,117.42,0.038
141.88,117.62,0.038
141.90,117.82,0.038
141.92,118.02,0.038
141.93,118.22,0.038
141.95,118.42,0.038
141.98,118.62,0.039
142.00,118.82,0.039
142.02,119.02,0.039
142.03,119.22,0.039
142.05,119.42,0.039
142.08,119.62,0.039
142.10,119.82,0.039
142.12,120.02,0.039
142.13,120.22,0.039
142.15,120.42,0.039
142.18,120.62,0.040
142.20,120.82,0.040
142.22,121.02,0.040
142.23,121.22,0.040
142.25,121.42,0.040
142.28,121.62,0.040
142.30,121.82,0.040
142.32,122.02,0.040
142.33,122.22,0.040
142.35,122.42,0.040
142.38,122.62,0.040
142.40,122.82,0.040
142.42,123.02,0.040
142.43,123.22,0.041
142.45,123.42,0.041
142.48,123.62,0.041
142.50,123.82,0.041
142.52,124.02,0.041
142.53,124.22,0.041
142.55,124.42,0.041
142.58,124.62,0.041
142.60,124.82,0.041
142.62,125.02,0.041
142.63,125.22,0.041
142.65,125.42,0.041
142.68,125.62,0.041
142.70,125.82,0.041
142.72,126.02,0.041
142.73,126.22,0.041
142.75,126.42,0.041
142.78,126.62,0.041
142.80,126.82,0.041
142.82,127.02,0.041
142.83,127.22,0.041
142.85,127.42,0.041
142.88,127.62,0.041
142.90,127.82,0.041
142.92,128.02,0.041
142.93,128.22,0.041
142.95,128.42,0.041
142.98,128.62,0.041
143.00,128.82,0.041
143.02,129.02,0.041
143.03,129.22,0.041
143.05,129.42,0.041
143.08,129.62,0.041
143.10,129.83,0.041
143.12,130.02,0.041
143.13,130.22,0.041
143.15,130.42,0.041
143.18,130.62,0.041
143.20,130.82,0.041
143.22,131.03,0.041
143.23,131.22,0.041
143.25,131.42,0.041
143.28,131.63,0.041
143.30,131.83,0.041
143.32,132.03,0.041
143.33,132.23,0.041
143.35,132.43,0.041
143.38,132.63,0.041
143.40,132.83,0.042
143.42,133.03,0.042
143.43,133.23,0.042
143.45,133.43,0.042
143.48,133.63,0.042
143.50,133.83,0.042
143.52,134.03,0.042
143.53,134.23,0.042
143.55,134.43,0.042
143.58,134.63,0.042
143.60,134.83,0.042
143.62,135.03,0.042
143.63,135.23,0.042
143.65,135.43,0.042
143.68,135.63,0.042
143.70,135.83,0.042
143.72,136.03,0.042
143.73,136.23,0.042
143.75,136.43,0.042
143.78,136.63,0.042
143.80,136.83,0.042
143.82,137.03,0.042
143.83,137.23,0.042
143.85,137.43,0.042
143.88,137.63,0.042
143.90,137.83,0.042
143.92,138.03,0.042
143.93,138.23,0.042
143.95,138.43,0.042
143.98,138.63,0.042
144.00,138.83,0.042
144.02,139.03,0.042
144.03,139.23,0.042
144.05,139.43,0.042
144.08,139.63,0.042
144.10,139.83,0.042
144.12,140.03,0.042
144.13,140.23,0.042
144.15,140.43,0.042
144.18,140.63,0.042
144.20,140.83,0.042
144.22,141.03,0.042
144.23,141.23,0.042
144.25,141.43,0.042
144.28,141.63,0.042
144.30,141.83,0.042
144.32,142.03,0.042
144.33,142.23,0.042
144.35,142.43,0.042
144.38,142.64,0.042
144.40,142.84,0.042
144.42,143.03,0.042
144.43,143.23,0.042
144.45,143.44,0.042
144.48,143.64,0.042
144.50,143.84,0.042
144.52,144.04,0.042
144.53,144.24,0.042
144.55,144.44,0.042
144.58,144.64,0.042
144.60,144.84,0.042
144.62,145.04,0.042
144.63,145.24,0.042
144.65,145.44,0.042
144.68,145.64,0.042
144.70,145.84,0.042
144.72,146.04,0.042
144.73,146.24,0.042
144.75,146.44,0.042
144.78,146.64,0.042
144.80,146.84,0.042
144.82,147.04,0.042
144.83,147.24,0.042
144.85,147.44,0.042
144.88,147.64,0.042
144.90,147.84,0.042
144.92,148.04,0.042
144.93,148.24,0.042
144.95,148.44,0.042
144.98,148.64,0.042
145.00,148.84,0.042
145.02,149.04,0.042
145.03,149.24,0.042
145.05,149.44,0.042
145.08,149.64,0.042
145.10,149.84,0.042
145.12,150.04,0.042
145.13,150.24,0.042
145.15,150.44,0.042
145.18,150.64,0.042
145.20,150.84,0.042
145.22,151.04,0.042
145.23,151.24,0.042
145.25,151.44,0.042
145.28,151.64,0.042
145.30,151.84,0.042
145.32,152.04,0.042
145.33,152.24,0.042
145.35,152.44,0.042
145.38,152.64,0.042
145.40,152.84,0.043
145.42,153.04,0.043
145.43,153.24,0.043
145.45,153.44,0.043
145.48,153.64,0.043
145.50,153.84,0.043
145.52,154.04,0.043
145.53,154.24,0.043
145.55,154.44,0.043
145.58,154.64,0.043
145.60,154.84,0.043
145.62,155.04,0.043
145.63,155.24,0.043
145.65,155.44,0.043
145.68,155.64,0.043
145.70,155.84,0.043
145.72,156.04,0.043
145.73,156.24,0.043
145.75,156.44,0.043
145.78,156.64,0.043
145.80,156.84,0.043
145.82,157.04,0.043
145.83,157.24,0.043
145.85,157.44,0.043
145.88,157.64,0.043
145.90,157.84,0.043
145.92,158.04,0.043
145.93,158.24,0.043
145.95,158.44,0.043
145.98,158.64,0.043
146.00,158.85,0.043
146.02,159.05,0.043
146.03,159.25,0.043
146.05,159.45,0.043
146.08,159.65,0.043
146.10,159.85,0.043
146.12,160.05,0.043
146.13,160.25,0.043
146.15,160.45,0.043
146.18,160.65,0.043
146.20,160.84,0.043
146.22,161.05,0.043
146.23,161.25,0.043
146.25,161.45,0.043
146.28,161.65,0.043
146.30,161.85,0.043
146.32,162.05,0.043
146.33,162.25,0.043
146.35,162.45,0.043
146.38,162.65,0.043
146.40,162.85,0.043
146.42,163.05,0.043
146.43,163.25,0.043
146.45,163.45,0.043
146.48,163.65,0.043
146.50,163.85,0.043
146.52,164.05,0.043
146.53,164.25,0.043
146.55,164.45,0.043
146.58,164.65,0.043
146.60,164.85,0.043
146.62,165.05,0.044
146.63,165.25,0.044
146.65,165.45,0.044
146.68,165.65,0.044
146.70,165.85,0.044
146.72,166.05,0.044
146.73,166.25,0.044
146.75,166.45,0.044
146.78,166.65,0.044
146.80,166.85,0.044
146.82,167.05,0.044
146.83,167.25,0.044
146.85,167.45,0.044
146.88,167.65,0.044
146.90,167.85,0.044
146.92,168.05,0.044
146.93,168.25,0.044
146.95,168.45,0.044
146.98,168.65,0.044
147.00,168.85,0.044
147.02,169.05,0.044
147.03,169.25,0.044
147.05,169.45,0.044
147.08,169.65,0.044
147.10,169.85,0.044
147.12,170.05,0.044
147.13,170.25,0.044
147.15,170.45,0.044
147.18,170.65,0.044
147.20,170.85,0.044
147.22,171.05,0.044
147.23,171.25,0.044
147.25,171.45,0.044
147.28,171.65,0.044
147.30,171.85,0.044
147.32,172.05,0.044
147.33,172.25,0.044
147.35,172.46,0.044
147.38,172.66,0.044
147.40,172.86,0.044
147.42,173.05,0.044
147.43,173.25,0.044
147.45,173.45,0.044
147.48,173.65,0.044
147.50,173.85,0.044
147.52,174.05,0.044
147.53,174.25,0.044
147.55,174.45,0.044
147.58,174.65,0.044
147.60,174.85,0.044
147.62,175.05,0.044
147.63,175.26,0.044
147.65,175.46,0.044
147.68,175.66,0.044
147.70,175.86,0.044
147.72,176.06,0.044
147.73,176.26,0.044
147.75,176.45,0.044
147.78,176.66,0.044
147.80,176.85,0.044
147.82,177.06,0.044
147.83,177.26,0.044
147.85,177.46,0.044
147.88,177.66,0.044
147.90,177.86,0.044
147.92,178.06,0.044
147.93,178.26,0.044
147.95,178.46,0.044
147.98,178.66,0.044
148.00,178.86,0.044
148.02,179.06,0.044
148.03,179.26,0.044
148.05,179.46,0.044
148.08,179.66,0.044
148.10,179.86,0.044
148.12,180.06,0.044
148.13,180.26,0.044
148.15,180.46,0.044
148.18,180.66,0.044
148.20,180.86,0.044
148.22,181.06,0.044
148.23,181.26,0.045
148.25,181.46,0.045
148.28,181.66,0.045
148.30,181.86,0.045
148.32,182.06,0.045
148.33,182.26,0.045
148.35,182.46,0.045
148.38,182.66,0.045
148.40,182.86,0.045
148.42,183.06,0.045
148.43,183.26,0.045
148.45,183.46,0.045
148.48,183.66,0.045
148.50,183.86,0.045
148.52,184.06,0.045
148.53,184.26,0.045
148.55,184.46,0.045
148.58,184.66,0.045
148.60,184.86,0.045
148.62,185.06,0.045
148.63,185.26,0.045
148.65,185.46,0.045
148.68,185.66,0.045
148.70,185.86,0.045
148.72,186.06,0.045
148.73,186.26,0.045
148.75,186.46,0.045
148.78,186.66,0.045
148.80,186.86,0.045
148.82,187.07,0.045
148.83,187.27,0.045
148.85,187.46,0.045
148.88,187.67,0.045
148.90,187.86,0.045
148.92,188.06,0.045
148.93,188.27,0.045
148.95,188.47,0.045
148.98,188.67,0.045
149.00,188.86,0.045
149.02,189.07,0.045
149.03,189.27,0.045
149.05,189.46,0.045
149.08,189.67,0.045
149.10,189.87,0.045
149.12,190.07,0.045
149.13,190.27,0.045
149.15,190.47,0.045
149.18,190.67,0.045
149.20,190.87,0.045
149.22,191.07,0.045
149.23,191.27,0.045
149.25,191.47,0.045
149.28,191.67,0.045
149.30,191.87,0.045
149.32,192.07,0.045
149.33,192.27,0.045
149.35,192.47,0.045
149.38,192.67,0.045
149.40,192.87,0.045
149.42,193.07,0.045
149.43,193.27,0.045
149.45,193.47,0.045
149.48,193.67,0.045
149.50,193.87,0.045
149.52,194.07,0.045
149.53,194.27,0.045
149.55,194.47,0.045
149.58,194.67,0.045
149.60,194.87,0.045
149.62,195.07,0.045
149.63,195.27,0.045
149.65,195.47,0.045
149.68,195.67,0.045
149.70,195.87,0.045
149.72,196.07,0.045
149.73,196.27,0.045
149.75,196.47,0.045
149.78,196.67,0.045
149.80,196.87,0.045
149.82,197.07,0.045
149.83,197.27,0.045
149.85,197.47,0.045
149.88,197.67,0.045
149.90,197.87,0.046
149.92,198.07,0.046
149.93,198.27,0.046
149.95,198.47,0.046
149.98,198.67,0.046
150.00,198.87,0.046
150.02,199.07,0.046
150.03,199.27,0.046
150.05,199.47,0.046
150.08,199.67,0.046
150.10,199.87,0.046
150.12,200.07,0.046
150.13,200.27,0.046
150.15,200.47,0.046
150.18,200.67,0.046
150.20,200.87,0.046
150.22,201.07,0.046
150.23,201.27,0.046
150.25,201.47,0.046
150.28,201.67,0.046
150.30,201.87,0.046
150.32,202.07,0.046
150.33,202.27,0.046
150.35,202.47,0.046
150.38,202.67,0.046
150.40,202.87,0.046
150.42,203.07,0.046
150.43,203.27,0.046
150.45,203.47,0.046
150.48,203.67,0.046
150.50,203.87,0.046
150.52,204.08,0.046
150.53,204.27,0.046
150.55,204.47,0.046
150.58,204.68,0.046
150.60,204.88,0.046
150.62,205.08,0.046
150.63,205.28,0.046
150.65,205.48,0.046
150.68,205.68,0.046
150.70,205.88,0.046
150.72,206.08,0.046
150.73,206.28,0.046
150.75,206.48,0.046
150.78,206.68,0.046
150.80,206.88,0.046
150.82,207.08,0.046
150.83,207.28,0.046
150.85,207.48,0.046
150.88,207.68,0.046
150.90,207.88,0.046
150.92,208.08,0.046
150.93,208.28,0.046
150.95,208.48,0.046
150.98,208.68,0.046
151.00,208.88,0.046
151.02,209.08,0.046
151.03,209.28,0.046
151.05,209.48,0.046
151.08,209.68,0.046
151.10,209.88,0.046
151.12,210.08,0.046
151.13,210.28,0.046
151.15,210.48,0.046
151.18,210.68,0.046
151.20,210.88,0.046
151.22,211.08,0.046
151.23,211.28,0.046
151.25,211.48,0.046
151.28,211.68,0.046
151.30,211.88,0.046
151.32,212.08,0.046
151.33,212.28,0.046
151.35,212.48,0.046
151.38,212.68,0.046
151.40,212.88,0.046
151.42,213.08,0.046
151.43,213.28,0.046
151.45,213.48,0.046
151.48,213.68,0.046
151.50,213.88,0.046
151.52,214.08,0.047
151.53,214.28,0.047
151.55,214.48,0.047
151.58,214.68,0.047
151.60,214.88,0.047
151.62,215.08,0.047
151.63,215.28,0.047
151.65,215.48,0.047
151.68,215.68,0.047
151.70,215.88,0.047
151.72,216.08,0.047
151.73,216.28,0.047
151.75,216.48,0.047
151.78,216.68,0.047
151.80,216.88,0.047
151.82,217.08,0.047
151.83,217.28,0.047
151.85,217.48,0.047
151.88,217.68,0.047
151.90,217.88,0.047
151.92,218.08,0.047
151.93,218.28,0.047
151.95,218.48,0.047
151.98,218.68,0.047
152.00,218.88,0.047
152.02,219.08,0.047
152.03,219.28,0.047
152.05,219.48,0.047
152.08,219.68,0.047
152.10,219.88,0.047
152.12,220.08,0.047
152.13,220.28,0.047
152.15,220.48,0.047
152.18,220.68,0.047
152.20,220.88,0.047
152.22,221.08,0.047
152.23,221.28,0.047
152.25,221.48,0.047
152.28,221.68,0.047
152.30,221.88,0.047
152.32,222.08,0.047
152.33,222.28,0.047
152.35,222.48,0.047
152.38,222.68,0.047
152.40,222.88,0.047
152.42,223.08,0.047
152.43,223.28,0.047
152.45,223.49,0.047
152.48,223.69,0.047
152.50,223.89,0.047
152.52,224.09,0.047
152.53,224.29,0.047
152.55,224.49,0.047
152.58,224.69,0.047
152.60,224.89,0.047
152.62,225.09,0.047
152.63,225.29,0.047
152.65,225.49,0.047
152.68,225.69,0.047
152.70,225.89,0.047
152.72,226.09,0.047
152.73,226.29,0.047
152.75,226.49,0.047
152.78,226.69,0.047
152.80,226.89,0.047
152.82,227.09,0.047
152.83,227.29,0.047
152.85,227.49,0.047
152.88,227.69,0.047
152.90,227.89,0.047
152.92,228.09,0.047
152.93,228.29,0.047
152.95,228.49,
152.98,228.69,
152.99,,