File: DSC/Olivia/2025_07_16_CBN_n60_90_10Cmin_x4.csv
Filename,2025_07_16_CBN_n60_90_10Cmin_x4
Instrument name,DSC2A-00468 (192.168.1.100)
Operator,Gibbons
rundate,7/16/2025
Sample name,2025_07_16_CBN_n60_90_10Cmin_x4
proceduresegments,Data Off ; Equilibrate -60.00 °C; Data On ; Ramp 10.00 °C/min to 90.00 °C; Data Off ; Isothermal 2.0 min; Data On ; Ramp 10.00 °C/min to -60.00 °C; Data Off ; Isothermal 2.0 min; Data On ; Ramp 10.00 °C/min to 90.00 °C; Data Off ; Isothermal 2.0 min; Data On ; Ramp 10.00 °C/min to -60.00 °C; Data Off ; Isothermal 2.0 min; Data On ; Ramp 10.00 °C/min to 90.00 °C; Data Off ; Isothermal 2.0 min; Data On ; Ramp 10.00 °C/min to -60.00 °C; Data Off ; Isothermal 2.0 min; Data On ; Ramp 10.00 °C/min to 30.00 °C
[File Parameters]
Run date,7/16/2025 6:11:59 PM
Trios version,5.1.1.46572
Original File Name,D:\DSC2500\Gibbons\2025_07_16_CBN_n60_90_10Cmin_x4.tri
Current File Name,D:\DSC2500\Gibbons\2025_07_16_CBN_n60_90_10Cmin_x4.tri
[Procedure]
Procedure Name,CBN_n60_90_10Cmin_x4
Sample Name,2025_07_16_CBN_n60_90_10Cmin_x4
Sample Mass,4.11 mg
Reference Sample Mass,0 mg
Pan Mass,56.79 mg
Pan Number,20
Reference Pan Mass,56.6 mg
Reference Pan Number,1
Pan Type,Tzero Aluminum Hermetic
Comments,DSC Consumables Al Hermetically Sealed Pan. Y1 Tray (Google Sheet: DSC_Samples_Y1_Tray_June2025).
Project Name,Pharmaceuticals - Cannabinoids
Operator,Gibbons
Test,Custom
Unload Max Temperature,30
Unload Min Temperature,30
Load Max Temperature,30
Load Min Temperature,30
Stop on Gas Flow Error,Yes
[Signal List]
Signal #1,Time (min)
Signal #2,Temperature (°C)
Signal #3,Heat Flow (mW)
Signal #4,Delta T (µV)
Signal #5,Delta Tzero (µV)
Signal #6,Tzero Temperature (°C)
Signal #7,Cell Purge (mL/min)
Signal #8,Heater Temp (°C)
Signal #9,Power Delivered (W)
Signal #10,Reference Junction Temperature (°C)
Signal #11,Flange Temperature (°C)
Signal #12,Heat Flow Phase (rad)
Signal #13,Total Heat Capacity (J/°C)
Signal #14,Heat Capacity (J/°C)
[Configuration]
Company Name,ASU
Instrument Name,DSC2A-00468
Instrument Type,DSC2500
Serial Number,DSC2A-00468
IP,192.168.1.100
Location of Instrument,MRRC
DisplayType,Unknown
Sample Interval ,0.1 s/pt
Selected Heat Flow,T4P
Exotherm Direction,Down
Cell Serial,DRC2-00792
Lid Type,Standard
Cooler,RCS 90
Leave Cooler on at End of Sequence,On
Gas 2,Nitrogen
Gas Selected,Channel 1
Flow Rate,50 mL/min
Secondary Purge,On
Licensed Heat Flow,Heat Flow T4P
Modulation Licensed,Yes
[Versions]
Common IDD Version,1
Cortex Version,VER 2.10.2.31
Driver,5.0.0.6
GDM Version,1.0.3.3
TouchscreenVersion,1.0.0.16145
FEP Version,1.2.1.21
FEP Bootloader,2.0.0.5
AutoSampler Version,2.1.1.26
Auto Sampler Bootloader,2.0.0.5
FCM Version,1.1.0.3
FCM Bootloader,2.0.0.5
[Experiment Logs]
Experiment Log Entry # 1,Data On set to 0
Experiment Log Entry # 3,Equilibrate Segment -60 (C) Started
Experiment Log Entry # 5,Air Cool is off.
Experiment Log Entry # 7,Data On set to 1
Experiment Log Entry # 9,Ramp Segment 10 C/min to 90 Started
Experiment Log Entry # 11,Data On set to 0
Experiment Log Entry # 13,Isothermal Segment 2 min started
Experiment Log Entry # 15,Data On set to 1
Experiment Log Entry # 17,Ramp Segment 10 C/min to -60 Started
Experiment Log Entry # 19,Data On set to 0
Experiment Log Entry # 21,Isothermal Segment 2 min started
Experiment Log Entry # 23,Data On set to 1
Experiment Log Entry # 25,Ramp Segment 10 C/min to 90 Started
Experiment Log Entry # 27,Data On set to 0
Experiment Log Entry # 29,Isothermal Segment 2 min started
Experiment Log Entry # 31,Data On set to 1
Experiment Log Entry # 33,Ramp Segment 10 C/min to -60 Started
Experiment Log Entry # 35,Data On set to 0
Experiment Log Entry # 37,Isothermal Segment 2 min started
Experiment Log Entry # 39,Data On set to 1
Experiment Log Entry # 41,Ramp Segment 10 C/min to 90 Started
Experiment Log Entry # 43,Data On set to 0
Experiment Log Entry # 45,Isothermal Segment 2 min started
Experiment Log Entry # 47,Data On set to 1
Experiment Log Entry # 49,Ramp Segment 10 C/min to -60 Started
Experiment Log Entry # 51,Data On set to 0
Experiment Log Entry # 53,Isothermal Segment 2 min started
Experiment Log Entry # 55,Data On set to 1
Experiment Log Entry # 57,Ramp Segment 10 C/min to 30 Started
[Method Log]
Method Log Entry # 1,Data Off
Method Log Entry # 2,Equilibrate -60 °C
Method Log Entry # 3,Data On
Method Log Entry # 4,(Ramp 88076) Ramp 10 °C/minute to 90 °C
Method Log Entry # 5,Data Off
Method Log Entry # 6,Isothermal 2 minutes
Method Log Entry # 7,Data On
Method Log Entry # 8,(Ramp 88080) Ramp 10 °C/minute to -60 °C
Method Log Entry # 9,Data Off
Method Log Entry # 10,Isothermal 2 minutes
Method Log Entry # 11,Data On
Method Log Entry # 12,(Ramp 88084) Ramp 10 °C/minute to 90 °C
Method Log Entry # 13,Data Off
Method Log Entry # 14,Isothermal 2 minutes
Method Log Entry # 15,Data On
Method Log Entry # 16,(Ramp 88088) Ramp 10 °C/minute to -60 °C
Method Log Entry # 17,Data Off
Method Log Entry # 18,Isothermal 2 minutes
Method Log Entry # 19,Data On
Method Log Entry # 20,(Ramp 88092) Ramp 10 °C/minute to 90 °C
Method Log Entry # 21,Data Off
Method Log Entry # 22,Isothermal 2 minutes
Method Log Entry # 23,Data On
Method Log Entry # 24,(Ramp 88096) Ramp 10 °C/minute to -60 °C
Method Log Entry # 25,Data Off
Method Log Entry # 26,Isothermal 2 minutes
Method Log Entry # 27,Data On
Method Log Entry # 28,(Ramp 88100) Ramp 10 °C/minute to 30 °C
Cell Serial,DRC2-00792
[T1 Calibration]
Slope,-0.008529666
Offset,9.636258
Initial Temperature,98.23
GUID,f8bfdadc-4977-4fdf-ba6d-0ba9134940c3
[TZero Calibration]
Date Applied,11/29/2022 4:06:13 PM
Description,From -89.059 °C to 396.009 °C at 20.000°C/min
Gas Type,Nitrogen
Pan Type,None
Source Files 1,C:\Users\yargerlab\Desktop\DSC Data\General\TZero_calibration_11_29_22_2nd(2).tri
Source Files 2,C:\Users\yargerlab\Desktop\DSC Data\General\TZero_calibration_11_29_22_2nd(3).tri
Delta T Offset,13.05235
Delta T Slope,-0.007271007
Delta T0 Offset,-13.69128
Delta T0 Slope,0.06063341
[Temperature Calibration]
Date Applied,11/29/2022 7:12:28 PM
Description,From 106.590 °C to 186.590 °C at 10.000°C/min
Gas Type,Nitrogen
Pan Type,Tzero Aluminum Hermetic
Source Files 1,C:\Users\yargerlab\Desktop\DSC Data\General\Indium(6).tri
Measured 1,157.391
Known 1,156.598
[Cell Constant Calibration]
Date Applied,11/29/2022 7:12:29 PM
Description,From 106.590 °C to 186.590 °C at 10.000°C/min
Gas Type,Nitrogen
Pan Type,Tzero Aluminum Hermetic
Source Files 1,C:\Users\yargerlab\Desktop\DSC Data\General\Indium(6).tri
T4P KCell,1.006051
Onset Slope,63.26126 mW/°C
[Direct Cp Calibration]
Date Applied,11/30/2022 11:04:51 AM
Description,From -79.983 °C to 298.409 °C at 10.000°C/min
Gas Type,Nitrogen
Pan Type,Tzero Aluminum Hermetic
Source Files 1,C:\Users\yargerlab\Desktop\DSC Data\General\Sapphire_Heat_Capacity_11_30_22.tri
[Rev Cp Calibration]
Date Applied,11/30/2022 1:58:51 PM
Description,From -79.996 °C to 292.812 °C at 3.000°C/min
Gas Type,Nitrogen
Pan Type,Tzero Aluminum Hermetic
Source Files 1,C:\Users\yargerlab\Desktop\DSC Data\General\Sapphire_MDSC_Calibration_11_30_22.tri
[step]
Ramp 10.00 °C/min to 90.00 °C
Time,Temperature,Heat Flow (Normalized)
min,°C,W/g
0.00,-59.73,-0.041
0.01,-59.74,-0.040
0.02,-59.75,-0.039
0.03,-59.75,-0.037
0.04,-59.75,-0.033
0.05,-59.75,-0.029
0.06,-59.75,-0.025
0.07,-59.74,-0.021
0.08,-59.72,-0.017
0.09,-59.71,-0.012
0.10,-59.68,-0.006
0.11,-59.65,0.002
0.12,-59.61,0.010
0.13,-59.57,0.018
0.14,-59.53,0.027
0.15,-59.47,0.037
0.16,-59.42,0.046
0.17,-59.35,0.058
0.18,-59.29,0.067
0.19,-59.22,0.078
0.20,-59.15,0.086
0.21,-59.07,0.095
0.22,-59.00,0.103
0.23,-58.92,0.115
0.24,-58.84,0.118
0.25,-58.76,0.128
0.26,-58.67,0.134
0.27,-58.59,0.139
0.28,-58.50,0.145
0.29,-58.42,0.150
0.30,-58.33,0.155
0.31,-58.24,0.158
0.32,-58.15,0.162
0.33,-58.06,0.164
0.34,-57.97,0.168
0.35,-57.87,0.172
0.36,-57.78,0.173
0.37,-57.69,0.175
0.38,-57.60,0.177
0.39,-57.51,0.180
0.40,-57.41,0.182
0.41,-57.32,0.182
0.42,-57.22,0.184
0.43,-57.13,0.187
0.44,-57.03,0.187
0.45,-56.94,0.188
0.46,-56.84,0.189
0.47,-56.75,0.190
0.48,-56.65,0.190
0.49,-56.56,0.191
0.50,-56.46,0.192
0.51,-56.36,0.193
0.52,-56.27,0.193
0.53,-56.17,0.194
0.54,-56.08,0.194
0.55,-55.98,0.194
0.56,-55.88,0.195
0.57,-55.78,0.195
0.58,-55.68,0.196
0.59,-55.59,0.196
0.60,-55.49,0.197
0.61,-55.39,0.197
0.62,-55.30,0.198
0.63,-55.20,0.198
0.64,-55.10,0.198
0.65,-55.00,0.198
0.66,-54.90,0.198
0.67,-54.81,0.199
0.68,-54.71,0.199
0.69,-54.61,0.199
0.70,-54.51,0.199
0.71,-54.42,0.199
0.72,-54.32,0.199
0.73,-54.22,0.200
0.74,-54.12,0.200
0.75,-54.02,0.200
0.76,-53.92,0.201
0.77,-53.83,0.201
0.78,-53.73,0.201
0.79,-53.63,0.201
0.80,-53.53,0.201
0.81,-53.43,0.201
0.82,-53.33,0.202
0.83,-53.23,0.202
0.84,-53.13,0.202
0.85,-53.04,0.202
0.86,-52.94,0.202
0.87,-52.84,0.202
0.88,-52.74,0.203
0.89,-52.64,0.203
0.90,-52.54,0.203
0.91,-52.44,0.203
0.92,-52.34,0.203
0.93,-52.24,0.203
0.94,-52.15,0.203
0.95,-52.05,0.203
0.96,-51.95,0.204
0.97,-51.85,0.204
0.98,-51.75,0.204
0.99,-51.65,0.204
1.00,-51.55,0.204
1.01,-51.45,0.204
1.02,-51.35,0.205
1.03,-51.25,0.205
1.04,-51.15,0.205
1.05,-51.05,0.205
1.06,-50.95,0.205
1.07,-50.85,0.205
1.08,-50.76,0.205
1.09,-50.66,0.205
1.10,-50.56,0.205
1.11,-50.46,0.205
1.12,-50.36,0.205
1.13,-50.26,0.206
1.14,-50.16,0.206
1.15,-50.06,0.206
1.16,-49.96,0.206
1.17,-49.86,0.206
1.18,-49.76,0.206
1.19,-49.66,0.206
1.20,-49.56,0.206
1.21,-49.46,0.206
1.22,-49.36,0.206
1.23,-49.26,0.206
1.24,-49.16,0.207
1.25,-49.06,0.207
1.26,-48.96,0.207
1.27,-48.87,0.207
1.28,-48.76,0.207
1.29,-48.67,0.207
1.30,-48.56,0.207
1.31,-48.46,0.207
1.32,-48.37,0.207
1.33,-48.27,0.207
1.34,-48.16,0.207
1.35,-48.07,0.207
1.36,-47.97,0.207
1.37,-47.87,0.207
1.38,-47.77,0.207
1.39,-47.67,0.207
1.40,-47.57,0.207
1.41,-47.47,0.207
1.42,-47.37,0.207
1.43,-47.27,0.207
1.44,-47.17,0.207
1.45,-47.07,0.208
1.46,-46.97,0.208
1.47,-46.87,0.208
1.48,-46.77,0.208
1.49,-46.67,0.208
1.50,-46.57,0.208
1.51,-46.47,0.208
1.52,-46.37,0.208
1.53,-46.27,0.208
1.54,-46.17,0.208
1.55,-46.07,0.208
1.56,-45.97,0.208
1.57,-45.87,0.208
1.58,-45.77,0.208
1.59,-45.67,0.208
1.60,-45.57,0.208
1.61,-45.47,0.208
1.62,-45.37,0.208
1.63,-45.27,0.208
1.64,-45.17,0.208
1.65,-45.07,0.208
1.66,-44.97,0.208
1.67,-44.87,0.208
1.68,-44.77,0.208
1.69,-44.67,0.208
1.70,-44.57,0.208
1.71,-44.47,0.208
1.72,-44.37,0.208
1.73,-44.27,0.209
1.74,-44.17,0.208
1.75,-44.07,0.208
1.76,-43.97,0.208
1.77,-43.87,0.209
1.78,-43.77,0.209
1.79,-43.67,0.209
1.80,-43.57,0.209
1.81,-43.47,0.209
1.82,-43.37,0.209
1.83,-43.27,0.209
1.84,-43.17,0.209
1.85,-43.07,0.209
1.86,-42.97,0.209
1.87,-42.87,0.209
1.88,-42.77,0.209
1.89,-42.67,0.209
1.90,-42.57,0.209
1.91,-42.47,0.209
1.92,-42.37,0.209
1.93,-42.27,0.209
1.94,-42.17,0.209
1.95,-42.07,0.209
1.96,-41.97,0.209
1.97,-41.87,0.209
1.98,-41.77,0.209
1.99,-41.67,0.209
2.00,-41.57,0.209
2.01,-41.47,0.209
2.02,-41.36,0.209
2.03,-41.26,0.209
2.04,-41.17,0.209
2.05,-41.07,0.209
2.06,-40.96,0.209
2.07,-40.87,0.209
2.08,-40.77,0.209
2.09,-40.66,0.209
2.10,-40.57,0.209
2.11,-40.47,0.209
2.12,-40.37,0.210
2.13,-40.26,0.210
2.14,-40.16,0.210
2.15,-40.06,0.210
2.16,-39.96,0.210
2.17,-39.86,0.210
2.18,-39.76,0.210
2.19,-39.66,0.210
2.20,-39.56,0.210
2.21,-39.46,0.210
2.22,-39.36,0.210
2.23,-39.26,0.210
2.24,-39.16,0.210
2.25,-39.06,0.210
2.26,-38.96,0.210
2.27,-38.86,0.210
2.28,-38.76,0.210
2.29,-38.66,0.210
2.30,-38.56,0.210
2.31,-38.46,0.210
2.32,-38.36,0.210
2.33,-38.26,0.210
2.34,-38.16,0.210
2.35,-38.06,0.210
2.36,-37.96,0.210
2.37,-37.86,0.210
2.38,-37.76,0.210
2.39,-37.66,0.210
2.40,-37.56,0.210
2.41,-37.46,0.210
2.42,-37.36,0.210
2.43,-37.26,0.210
2.44,-37.16,0.210
2.45,-37.06,0.210
2.46,-36.96,0.210
2.47,-36.86,0.210
2.48,-36.76,0.211
2.49,-36.66,0.211
2.50,-36.56,0.211
2.51,-36.46,0.211
2.52,-36.36,0.211
2.53,-36.26,0.211
2.54,-36.16,0.211
2.55,-36.06,0.211
2.56,-35.96,0.211
2.57,-35.86,0.211
2.58,-35.76,0.211
2.59,-35.66,0.211
2.60,-35.56,0.211
2.61,-35.45,0.211
2.62,-35.36,0.211
2.63,-35.26,0.211
2.64,-35.16,0.211
2.65,-35.06,0.211
2.66,-34.96,0.211
2.67,-34.86,0.211
2.68,-34.76,0.211
2.69,-34.66,0.211
2.70,-34.56,0.211
2.71,-34.45,0.211
2.72,-34.36,0.211
2.73,-34.25,0.211
2.74,-34.15,0.211
2.75,-34.05,0.211
2.76,-33.95,0.211
2.77,-33.85,0.211
2.78,-33.75,0.211
2.79,-33.65,0.211
2.80,-33.55,0.211
2.81,-33.45,0.211
2.82,-33.35,0.212
2.83,-33.25,0.212
2.84,-33.15,0.212
2.85,-33.05,0.212
2.86,-32.95,0.212
2.87,-32.85,0.212
2.88,-32.75,0.212
2.89,-32.65,0.212
2.90,-32.55,0.212
2.91,-32.45,0.212
2.92,-32.35,0.212
2.93,-32.25,0.212
2.94,-32.15,0.212
2.95,-32.05,0.212
2.96,-31.95,0.212
2.97,-31.85,0.212
2.98,-31.75,0.212
2.99,-31.65,0.212
3.00,-31.55,0.212
3.01,-31.45,0.212
3.02,-31.35,0.212
3.03,-31.25,0.212
3.04,-31.15,0.212
3.05,-31.05,0.212
3.06,-30.95,0.212
3.07,-30.85,0.212
3.08,-30.75,0.212
3.09,-30.65,0.212
3.10,-30.55,0.212
3.11,-30.45,0.212
3.12,-30.35,0.212
3.13,-30.25,0.212
3.14,-30.15,0.212
3.15,-30.05,0.213
3.16,-29.95,0.213
3.17,-29.85,0.213
3.18,-29.75,0.213
3.19,-29.65,0.213
3.20,-29.55,0.213
3.21,-29.45,0.213
3.22,-29.35,0.213
3.23,-29.25,0.213
3.24,-29.15,0.213
3.25,-29.05,0.213
3.26,-28.95,0.213
3.27,-28.85,0.213
3.28,-28.75,0.213
3.29,-28.65,0.213
3.30,-28.55,0.213
3.31,-28.45,0.213
3.32,-28.35,0.213
3.33,-28.25,0.213
3.34,-28.15,0.213
3.35,-28.05,0.213
3.36,-27.94,0.213
3.37,-27.85,0.213
3.38,-27.75,0.213
3.39,-27.65,0.213
3.40,-27.55,0.213
3.41,-27.44,0.213
3.42,-27.35,0.213
3.43,-27.24,0.213
3.44,-27.15,0.213
3.45,-27.04,0.213
3.46,-26.94,0.213
3.47,-26.84,0.213
3.48,-26.74,0.214
3.49,-26.64,0.214
3.50,-26.54,0.214
3.51,-26.44,0.214
3.52,-26.34,0.214
3.53,-26.24,0.214
3.54,-26.14,0.214
3.55,-26.04,0.214
3.56,-25.94,0.214
3.57,-25.84,0.214
3.58,-25.74,0.214
3.59,-25.64,0.214
3.60,-25.54,0.214
3.61,-25.44,0.214
3.62,-25.34,0.214
3.63,-25.24,0.214
3.64,-25.14,0.214
3.65,-25.04,0.214
3.66,-24.94,0.214
3.67,-24.84,0.214
3.68,-24.74,0.214
3.69,-24.64,0.214
3.70,-24.54,0.214
3.71,-24.44,0.214
3.72,-24.34,0.214
3.73,-24.24,0.214
3.74,-24.14,0.214
3.75,-24.04,0.214
3.76,-23.94,0.215
3.77,-23.84,0.214
3.78,-23.74,0.215
3.79,-23.64,0.215
3.80,-23.54,0.215
3.81,-23.44,0.215
3.82,-23.34,0.215
3.83,-23.24,0.215
3.84,-23.14,0.215
3.85,-23.04,0.215
3.86,-22.94,0.215
3.87,-22.84,0.215
3.88,-22.74,0.215
3.89,-22.64,0.215
3.90,-22.54,0.215
3.91,-22.44,0.215
3.92,-22.34,0.215
3.93,-22.24,0.215
3.94,-22.13,0.215
3.95,-22.04,0.215
3.96,-21.94,0.216
3.97,-21.83,0.215
3.98,-21.74,0.216
3.99,-21.63,0.216
4.00,-21.53,0.216
4.01,-21.43,0.216
4.02,-21.33,0.216
4.03,-21.23,0.216
4.04,-21.13,0.216
4.05,-21.03,0.216
4.06,-20.93,0.216
4.07,-20.83,0.216
4.08,-20.73,0.216
4.09,-20.63,0.216
4.10,-20.53,0.216
4.11,-20.43,0.216
4.12,-20.33,0.216
4.13,-20.23,0.216
4.14,-20.13,0.216
4.15,-20.03,0.216
4.16,-19.93,0.216
4.17,-19.83,0.216
4.18,-19.73,0.216
4.19,-19.63,0.216
4.20,-19.53,0.217
4.21,-19.43,0.217
4.22,-19.33,0.217
4.23,-19.23,0.217
4.24,-19.13,0.217
4.25,-19.03,0.217
4.26,-18.93,0.217
4.27,-18.83,0.217
4.28,-18.73,0.217
4.29,-18.63,0.217
4.30,-18.53,0.217
4.31,-18.43,0.217
4.32,-18.33,0.217
4.33,-18.23,0.217
4.34,-18.13,0.217
4.35,-18.03,0.217
4.36,-17.93,0.217
4.37,-17.83,0.217
4.38,-17.73,0.217
4.39,-17.63,0.217
4.40,-17.53,0.217
4.41,-17.43,0.217
4.42,-17.33,0.217
4.43,-17.23,0.217
4.44,-17.13,0.218
4.45,-17.03,0.218
4.46,-16.93,0.218
4.47,-16.83,0.218
4.48,-16.73,0.218
4.49,-16.63,0.218
4.50,-16.53,0.218
4.51,-16.43,0.218
4.52,-16.33,0.218
4.53,-16.23,0.218
4.54,-16.13,0.218
4.55,-16.03,0.218
4.56,-15.93,0.218
4.57,-15.83,0.218
4.58,-15.73,0.218
4.59,-15.63,0.218
4.60,-15.53,0.218
4.61,-15.43,0.219
4.62,-15.33,0.219
4.63,-15.23,0.219
4.64,-15.13,0.219
4.65,-15.03,0.219
4.66,-14.93,0.219
4.67,-14.82,0.219
4.68,-14.73,0.219
4.69,-14.62,0.219
4.70,-14.53,0.219
4.71,-14.43,0.219
4.72,-14.33,0.219
4.73,-14.23,0.219
4.74,-14.13,0.219
4.75,-14.03,0.219
4.76,-13.92,0.219
4.77,-13.82,0.219
4.78,-13.73,0.219
4.79,-13.62,0.219
4.80,-13.52,0.219
4.81,-13.42,0.219
4.82,-13.32,0.220
4.83,-13.22,0.220
4.84,-13.12,0.220
4.85,-13.02,0.220
4.86,-12.92,0.220
4.87,-12.82,0.220
4.88,-12.72,0.220
4.89,-12.62,0.220
4.90,-12.52,0.220
4.91,-12.42,0.220
4.92,-12.32,0.220
4.93,-12.22,0.220
4.94,-12.12,0.220
4.95,-12.02,0.220
4.96,-11.92,0.220
4.97,-11.82,0.220
4.98,-11.72,0.220
4.99,-11.62,0.221
5.00,-11.52,0.221
5.01,-11.42,0.221
5.02,-11.32,0.221
5.03,-11.22,0.221
5.04,-11.12,0.221
5.05,-11.02,0.221
5.06,-10.92,0.221
5.07,-10.82,0.221
5.08,-10.72,0.221
5.09,-10.62,0.221
5.10,-10.52,0.221
5.11,-10.42,0.221
5.12,-10.32,0.221
5.13,-10.22,0.221
5.14,-10.12,0.221
5.15,-10.02,0.221
5.16,-9.92,0.221
5.17,-9.82,0.222
5.18,-9.72,0.222
5.19,-9.62,0.222
5.20,-9.52,0.222
5.21,-9.42,0.222
5.22,-9.32,0.222
5.23,-9.22,0.222
5.24,-9.12,0.222
5.25,-9.02,0.222
5.26,-8.92,0.222
5.27,-8.82,0.222
5.28,-8.72,0.222
5.29,-8.62,0.222
5.30,-8.52,0.222
5.31,-8.42,0.223
5.32,-8.32,0.223
5.33,-8.22,0.223
5.34,-8.12,0.223
5.35,-8.02,0.223
5.36,-7.92,0.223
5.37,-7.82,0.223
5.38,-7.72,0.223
5.39,-7.62,0.223
5.40,-7.52,0.223
5.41,-7.42,0.223
5.42,-7.32,0.223
5.43,-7.22,0.223
5.44,-7.12,0.223
5.45,-7.02,0.223
5.46,-6.92,0.223
5.47,-6.82,0.223
5.48,-6.72,0.223
5.49,-6.62,0.223
5.50,-6.52,0.223
5.51,-6.42,0.223
5.52,-6.32,0.223
5.53,-6.22,0.224
5.54,-6.12,0.224
5.55,-6.02,0.224
5.56,-5.92,0.224
5.57,-5.82,0.224
5.58,-5.72,0.224
5.59,-5.62,0.224
5.60,-5.52,0.224
5.61,-5.42,0.224
5.62,-5.31,0.224
5.63,-5.22,0.224
5.64,-5.12,0.224
5.65,-5.02,0.224
5.66,-4.92,0.224
5.67,-4.82,0.224
5.68,-4.72,0.224
5.69,-4.62,0.225
5.70,-4.51,0.225
5.71,-4.41,0.225
5.72,-4.32,0.225
5.73,-4.22,0.225
5.74,-4.11,0.225
5.75,-4.01,0.225
5.76,-3.91,0.225
5.77,-3.81,0.225
5.78,-3.71,0.225
5.79,-3.61,0.225
5.80,-3.51,0.225
5.81,-3.41,0.225
5.82,-3.31,0.225
5.83,-3.21,0.226
5.84,-3.11,0.226
5.85,-3.01,0.226
5.86,-2.91,0.226
5.87,-2.81,0.226
5.88,-2.71,0.226
5.89,-2.61,0.226
5.90,-2.51,0.226
5.91,-2.41,0.226
5.92,-2.31,0.226
5.93,-2.21,0.226
5.94,-2.11,0.226
5.95,-2.01,0.226
5.96,-1.91,0.226
5.97,-1.81,0.226
5.98,-1.71,0.227
5.99,-1.61,0.227
6.00,-1.51,0.227
6.01,-1.41,0.227
6.02,-1.31,0.227
6.03,-1.21,0.227
6.04,-1.11,0.227
6.05,-1.01,0.227
6.06,-0.91,0.227
6.07,-0.81,0.227
6.08,-0.71,0.227
6.09,-0.61,0.227
6.10,-0.51,0.227
6.11,-0.41,0.227
6.12,-0.31,0.227
6.13,-0.21,0.227
6.14,-0.11,0.227
6.15,0.00,0.228
6.16,0.09,0.228
6.17,0.19,0.228
6.18,0.29,0.228
6.19,0.39,0.228
6.20,0.49,0.228
6.21,0.60,0.228
6.22,0.70,0.228
6.23,0.79,0.228
6.24,0.90,0.228
6.25,1.00,0.228
6.26,1.10,0.228
6.27,1.20,0.228
6.28,1.29,0.228
6.29,1.40,0.228
6.30,1.50,0.228
6.31,1.60,0.228
6.32,1.70,0.229
6.33,1.80,0.229
6.34,1.90,0.229
6.35,2.00,0.229
6.36,2.10,0.229
6.37,2.20,0.229
6.38,2.30,0.229
6.39,2.40,0.229
6.40,2.50,0.229
6.41,2.60,0.229
6.42,2.70,0.229
6.43,2.80,0.229
6.44,2.90,0.229
6.45,3.00,0.229
6.46,3.10,0.230
6.47,3.20,0.230
6.48,3.30,0.230
6.49,3.40,0.230
6.50,3.50,0.230
6.51,3.60,0.230
6.52,3.70,0.230
6.53,3.80,0.230
6.54,3.90,0.230
6.55,4.00,0.230
6.56,4.10,0.230
6.57,4.20,0.230
6.58,4.30,0.230
6.59,4.40,0.231
6.60,4.50,0.231
6.61,4.60,0.231
6.62,4.70,0.231
6.63,4.80,0.231
6.64,4.90,0.231
6.65,5.00,0.231
6.66,5.10,0.231
6.67,5.20,0.231
6.68,5.30,0.231
6.69,5.40,0.231
6.70,5.50,0.231
6.71,5.60,0.231
6.72,5.70,0.231
6.73,5.80,0.231
6.74,5.90,0.231
6.75,6.00,0.232
6.76,6.10,0.232
6.77,6.20,0.232
6.78,6.30,0.232
6.79,6.40,0.232
6.80,6.50,0.232
6.81,6.60,0.232
6.82,6.70,0.232
6.83,6.80,0.232
6.84,6.90,0.232
6.85,7.00,0.232
6.86,7.10,0.232
6.87,7.20,0.232
6.88,7.30,0.233
6.89,7.40,0.233
6.90,7.50,0.233
6.91,7.60,0.233
6.92,7.70,0.233
6.93,7.80,0.233
6.94,7.90,0.233
6.95,8.00,0.233
6.96,8.10,0.233
6.97,8.20,0.233
6.98,8.30,0.233
6.99,8.40,0.233
7.00,8.50,0.233
7.01,8.61,0.233
7.02,8.70,0.233
7.03,8.80,0.234
7.04,8.91,0.234
7.05,9.00,0.234
7.06,9.11,0.234
7.07,9.21,0.234
7.08,9.31,0.234
7.09,9.41,0.234
7.10,9.50,0.234
7.11,9.60,0.234
7.12,9.70,0.234
7.13,9.81,0.234
7.14,9.91,0.234
7.15,10.01,0.234
7.16,10.11,0.235
7.17,10.20,0.235
7.18,10.31,0.235
7.19,10.41,0.235
7.20,10.51,0.235
7.21,10.61,0.235
7.22,10.71,0.235
7.23,10.81,0.235
7.24,10.91,0.235
7.25,11.01,0.235
7.26,11.11,0.235
7.27,11.21,0.235
7.28,11.31,0.236
7.29,11.41,0.236
7.30,11.51,0.236
7.31,11.61,0.236
7.32,11.71,0.236
7.33,11.81,0.236
7.34,11.91,0.236
7.35,12.01,0.236
7.36,12.11,0.236
7.37,12.21,0.236
7.38,12.31,0.236
7.39,12.41,0.236
7.40,12.51,0.236
7.41,12.61,0.236
7.42,12.71,0.237
7.43,12.81,0.237
7.44,12.91,0.237
7.45,13.01,0.237
7.46,13.11,0.237
7.47,13.21,0.237
7.48,13.31,0.237
7.49,13.41,0.237
7.50,13.51,0.237
7.51,13.61,0.237
7.52,13.71,0.237
7.53,13.81,0.237
7.54,13.91,0.237
7.55,14.01,0.237
7.56,14.11,0.238
7.57,14.21,0.238
7.58,14.31,0.238
7.59,14.41,0.238
7.60,14.51,0.238
7.61,14.61,0.238
7.62,14.71,0.238
7.63,14.81,0.238
7.64,14.91,0.238
7.65,15.01,0.238
7.66,15.11,0.238
7.67,15.21,0.238
7.68,15.31,0.239
7.69,15.41,0.239
7.70,15.51,0.239
7.71,15.61,0.239
7.72,15.71,0.239
7.73,15.81,0.239
7.74,15.91,0.239
7.75,16.01,0.239
7.76,16.11,0.239
7.77,16.22,0.239
7.78,16.31,0.239
7.79,16.41,0.239
7.80,16.51,0.239
7.81,16.61,0.239
7.82,16.71,0.240
7.83,16.81,0.240
7.84,16.91,0.240
7.85,17.01,0.240
7.86,17.11,0.240
7.87,17.21,0.240
7.88,17.31,0.240
7.89,17.41,0.240
7.90,17.51,0.240
7.91,17.61,0.240
7.92,17.71,0.240
7.93,17.81,0.240
7.94,17.91,0.240
7.95,18.01,0.240
7.96,18.11,0.241
7.97,18.21,0.241
7.98,18.32,0.241
7.99,18.42,0.241
8.00,18.51,0.241
8.01,18.62,0.241
8.02,18.72,0.241
8.03,18.82,0.241
8.04,18.92,0.241
8.05,19.02,0.241
8.06,19.12,0.241
8.07,19.22,0.242
8.08,19.32,0.242
8.09,19.42,0.242
8.10,19.52,0.242
8.11,19.62,0.242
8.12,19.72,0.242
8.13,19.82,0.242
8.14,19.92,0.242
8.15,20.02,0.242
8.16,20.12,0.242
8.17,20.22,0.242
8.18,20.32,0.242
8.19,20.42,0.242
8.20,20.52,0.242
8.21,20.62,0.243
8.22,20.72,0.243
8.23,20.82,0.243
8.24,20.92,0.243
8.25,21.02,0.243
8.26,21.12,0.243
8.27,21.22,0.243
8.28,21.32,0.243
8.29,21.42,0.243
8.30,21.52,0.243
8.31,21.62,0.243
8.32,21.72,0.243
8.33,21.82,0.244
8.34,21.92,0.244
8.35,22.02,0.244
8.36,22.12,0.244
8.37,22.22,0.244
8.38,22.32,0.244
8.39,22.42,0.244
8.40,22.52,0.244
8.41,22.62,0.244
8.42,22.72,0.244
8.43,22.82,0.244
8.44,22.92,0.244
8.45,23.02,0.244
8.46,23.12,0.244
8.47,23.22,0.244
8.48,23.32,0.244
8.49,23.42,0.245
8.50,23.52,0.245
8.51,23.62,0.245
8.52,23.72,0.245
8.53,23.82,0.245
8.54,23.92,0.245
8.55,24.02,0.245
8.56,24.12,0.245
8.57,24.22,0.245
8.58,24.32,0.245
8.59,24.42,0.245
8.60,24.52,0.245
8.61,24.62,0.245
8.62,24.72,0.246
8.63,24.82,0.246
8.64,24.92,0.246
8.65,25.02,0.246
8.66,25.12,0.246
8.67,25.22,0.246
8.68,25.32,0.246
8.69,25.42,0.246
8.70,25.52,0.246
8.71,25.62,0.246
8.72,25.72,0.246
8.73,25.82,0.246
8.74,25.92,0.246
8.75,26.02,0.247
8.76,26.12,0.247
8.77,26.22,0.247
8.78,26.32,0.247
8.79,26.42,0.247
8.80,26.52,0.247
8.81,26.62,0.247
8.82,26.72,0.247
8.83,26.83,0.247
8.84,26.92,0.247
8.85,27.03,0.247
8.86,27.13,0.247
8.87,27.23,0.247
8.88,27.32,0.248
8.89,27.43,0.248
8.90,27.53,0.248
8.91,27.63,0.248
8.92,27.73,0.248
8.93,27.83,0.248
8.94,27.92,0.248
8.95,28.03,0.248
8.96,28.13,0.248
8.97,28.23,0.248
8.98,28.33,0.248
8.99,28.43,0.248
9.00,28.53,0.249
9.01,28.63,0.249
9.02,28.73,0.249
9.03,28.83,0.249
9.04,28.93,0.249
9.05,29.03,0.249
9.06,29.13,0.249
9.07,29.23,0.249
9.08,29.33,0.249
9.09,29.43,0.250
9.10,29.53,0.250
9.11,29.63,0.250
9.12,29.73,0.250
9.13,29.83,0.250
9.14,29.93,0.250
9.15,30.03,0.250
9.16,30.13,0.250
9.17,30.23,0.250
9.18,30.33,0.251
9.19,30.43,0.251
9.20,30.53,0.251
9.21,30.63,0.251
9.22,30.73,0.251
9.23,30.83,0.251
9.24,30.93,0.251
9.25,31.03,0.251
9.26,31.13,0.251
9.27,31.23,0.251
9.28,31.33,0.251
9.29,31.43,0.251
9.30,31.53,0.252
9.31,31.63,0.252
9.32,31.73,0.252
9.33,31.83,0.252
9.34,31.93,0.252
9.35,32.03,0.252
9.36,32.13,0.252
9.37,32.23,0.252
9.38,32.33,0.252
9.39,32.43,0.252
9.40,32.53,0.252
9.41,32.63,0.253
9.42,32.73,0.253
9.43,32.83,0.253
9.44,32.93,0.253
9.45,33.03,0.253
9.46,33.13,0.253
9.47,33.23,0.253
9.48,33.33,0.253
9.49,33.43,0.253
9.50,33.53,0.253
9.51,33.63,0.254
9.52,33.73,0.254
9.53,33.83,0.254
9.54,33.93,0.254
9.55,34.03,0.254
9.56,34.13,0.254
9.57,34.23,0.254
9.58,34.33,0.254
9.59,34.43,0.254
9.60,34.53,0.254
9.61,34.63,0.254
9.62,34.73,0.254
9.63,34.83,0.255
9.64,34.93,0.255
9.65,35.03,0.255
9.66,35.13,0.255
9.67,35.23,0.255
9.68,35.33,0.255
9.69,35.43,0.255
9.70,35.53,0.255
9.71,35.63,0.255
9.72,35.74,0.255
9.73,35.83,0.255
9.74,35.94,0.256
9.75,36.04,0.256
9.76,36.14,0.256
9.77,36.24,0.256
9.78,36.34,0.256
9.79,36.44,0.256
9.80,36.53,0.256
9.81,36.64,0.256
9.82,36.74,0.256
9.83,36.84,0.256
9.84,36.94,0.256
9.85,37.04,0.257
9.86,37.14,0.257
9.87,37.24,0.257
9.88,37.33,0.257
9.89,37.44,0.257
9.90,37.54,0.257
9.91,37.64,0.257
9.92,37.74,0.257
9.93,37.84,0.257
9.94,37.94,0.257
9.95,38.04,0.257
9.96,38.14,0.257
9.97,38.24,0.257
9.98,38.34,0.257
9.99,38.44,0.257
10.00,38.54,0.258
10.01,38.64,0.258
10.02,38.74,0.258
10.03,38.84,0.258
10.04,38.94,0.258
10.05,39.04,0.258
10.06,39.14,0.258
10.07,39.24,0.258
10.08,39.34,0.258
10.09,39.44,0.258
10.10,39.54,0.258
10.11,39.64,0.259
10.12,39.74,0.259
10.13,39.84,0.259
10.14,39.94,0.259
10.15,40.04,0.259
10.16,40.14,0.259
10.17,40.24,0.259
10.18,40.34,0.259
10.19,40.44,0.259
10.20,40.54,0.259
10.21,40.64,0.259
10.22,40.74,0.259
10.23,40.84,0.260
10.24,40.94,0.260
10.25,41.04,0.260
10.26,41.14,0.260
10.27,41.24,0.260
10.28,41.34,0.260
10.29,41.44,0.260
10.30,41.54,0.260
10.31,41.64,0.260
10.32,41.74,0.260
10.33,41.84,0.260
10.34,41.94,0.260
10.35,42.04,0.260
10.36,42.14,0.261
10.37,42.24,0.261
10.38,42.34,0.261
10.39,42.44,0.261
10.40,42.54,0.261
10.41,42.64,0.261
10.42,42.74,0.261
10.43,42.84,0.261
10.44,42.94,0.261
10.45,43.05,0.261
10.46,43.14,0.261
10.47,43.24,0.262
10.48,43.34,0.262
10.49,43.44,0.262
10.50,43.55,0.262
10.51,43.64,0.262
10.52,43.75,0.262
10.53,43.84,0.262
10.54,43.94,0.262
10.55,44.05,0.262
10.56,44.15,0.263
10.57,44.24,0.263
10.58,44.35,0.263
10.59,44.45,0.263
10.60,44.55,0.263
10.61,44.65,0.263
10.62,44.75,0.263
10.63,44.85,0.263
10.64,44.95,0.263
10.65,45.05,0.263
10.66,45.15,0.263
10.67,45.25,0.263
10.68,45.35,0.263
10.69,45.45,0.264
10.70,45.55,0.264
10.71,45.65,0.264
10.72,45.75,0.264
10.73,45.85,0.264
10.74,45.95,0.264
10.75,46.05,0.264
10.76,46.15,0.264
10.77,46.25,0.264
10.78,46.35,0.264
10.79,46.45,0.264
10.80,46.55,0.264
10.81,46.65,0.265
10.82,46.75,0.265
10.83,46.85,0.265
10.84,46.95,0.265
10.85,47.05,0.265
10.86,47.15,0.265
10.87,47.25,0.265
10.88,47.35,0.265
10.89,47.45,0.265
10.90,47.55,0.265
10.91,47.65,0.265
10.92,47.75,0.265
10.93,47.85,0.265
10.94,47.95,0.266
10.95,48.05,0.266
10.96,48.15,0.266
10.97,48.25,0.266
10.98,48.35,0.266
10.99,48.45,0.266
11.00,48.55,0.266
11.01,48.65,0.266
11.02,48.75,0.266
11.03,48.85,0.266
11.04,48.95,0.266
11.05,49.05,0.267
11.06,49.15,0.267
11.07,49.25,0.267
11.08,49.35,0.267
11.09,49.45,0.267
11.10,49.55,0.267
11.11,49.65,0.267
11.12,49.75,0.267
11.13,49.85,0.267
11.14,49.95,0.267
11.15,50.05,0.267
11.16,50.15,0.267
11.17,50.25,0.267
11.18,50.35,0.268
11.19,50.45,0.268
11.20,50.55,0.268
11.21,50.65,0.268
11.22,50.75,0.268
11.23,50.85,0.268
11.24,50.95,0.268
11.25,51.05,0.268
11.26,51.15,0.268
11.27,51.25,0.268
11.28,51.35,0.268
11.29,51.45,0.268
11.30,51.55,0.269
11.31,51.65,0.269
11.32,51.75,0.269
11.33,51.86,0.269
11.34,51.96,0.269
11.35,52.05,0.269
11.36,52.16,0.269
11.37,52.26,0.269
11.38,52.35,0.269
11.39,52.46,0.269
11.40,52.56,0.269
11.41,52.66,0.270
11.42,52.76,0.270
11.43,52.86,0.270
11.44,52.96,0.270
11.45,53.06,0.270
11.46,53.16,0.270
11.47,53.26,0.270
11.48,53.36,0.270
11.49,53.46,0.270
11.50,53.56,0.270
11.51,53.66,0.270
11.52,53.76,0.271
11.53,53.86,0.271
11.54,53.96,0.271
11.55,54.06,0.271
11.56,54.16,0.271
11.57,54.26,0.271
11.58,54.36,0.271
11.59,54.46,0.271
11.60,54.56,0.271
11.61,54.66,0.271
11.62,54.76,0.272
11.63,54.86,0.272
11.64,54.96,0.272
11.65,55.06,0.272
11.66,55.16,0.272
11.67,55.26,0.272
11.68,55.36,0.272
11.69,55.46,0.272
11.70,55.56,0.272
11.71,55.66,0.272
11.72,55.76,0.272
11.73,55.86,0.272
11.74,55.96,0.273
11.75,56.06,0.273
11.76,56.16,0.273
11.77,56.26,0.273
11.78,56.36,0.273
11.79,56.46,0.273
11.80,56.56,0.273
11.81,56.66,0.273
11.82,56.76,0.273
11.83,56.86,0.273
11.84,56.96,0.274
11.85,57.06,0.274
11.86,57.16,0.274
11.87,57.26,0.274
11.88,57.36,0.274
11.89,57.46,0.274
11.90,57.56,0.274
11.91,57.66,0.274
11.92,57.76,0.274
11.93,57.86,0.274
11.94,57.96,0.275
11.95,58.06,0.275
11.96,58.16,0.275
11.97,58.26,0.275
11.98,58.36,0.275
11.99,58.46,0.275
12.00,58.56,0.275
12.01,58.66,0.275
12.02,58.76,0.276
12.03,58.86,0.276
12.04,58.96,0.276
12.05,59.06,0.276
12.06,59.16,0.276
12.07,59.26,0.276
12.08,59.36,0.276
12.09,59.46,0.276
12.10,59.56,0.276
12.11,59.66,0.277
12.12,59.76,0.277
12.13,59.86,0.277
12.14,59.96,0.277
12.15,60.06,0.277
12.16,60.16,0.277
12.17,60.26,0.277
12.18,60.36,0.277
12.19,60.46,0.278
12.20,60.56,0.278
12.21,60.66,0.278
12.22,60.76,0.278
12.23,60.86,0.278
12.24,60.96,0.278
12.25,61.06,0.278
12.26,61.16,0.278
12.27,61.26,0.279
12.28,61.36,0.279
12.29,61.46,0.279
12.30,61.56,0.279
12.31,61.67,0.279
12.32,61.76,0.279
12.33,61.86,0.279
12.34,61.96,0.280
12.35,62.07,0.280
12.36,62.16,0.280
12.37,62.26,0.280
12.38,62.37,0.280
12.39,62.47,0.280
12.40,62.57,0.281
12.41,62.66,0.281
12.42,62.76,0.281
12.43,62.86,0.281
12.44,62.97,0.281
12.45,63.06,0.281
12.46,63.17,0.282
12.47,63.26,0.282
12.48,63.36,0.282
12.49,63.46,0.282
12.50,63.56,0.282
12.51,63.66,0.282
12.52,63.77,0.283
12.53,63.87,0.283
12.54,63.97,0.283
12.55,64.07,0.283
12.56,64.17,0.283
12.57,64.27,0.284
12.58,64.37,0.284
12.59,64.47,0.284
12.60,64.57,0.284
12.61,64.67,0.285
12.62,64.77,0.285
12.63,64.87,0.285
12.64,64.97,0.285
12.65,65.07,0.285
12.66,65.17,0.286
12.67,65.27,0.286
12.68,65.37,0.286
12.69,65.47,0.286
12.70,65.57,0.287
12.71,65.67,0.287
12.72,65.77,0.287
12.73,65.87,0.288
12.74,65.97,0.288
12.75,66.07,0.288
12.76,66.17,0.289
12.77,66.27,0.289
12.78,66.37,0.289
12.79,66.47,0.290
12.80,66.57,0.290
12.81,66.67,0.290
12.82,66.77,0.291
12.83,66.87,0.291
12.84,66.97,0.291
12.85,67.07,0.292
12.86,67.17,0.292
12.87,67.27,0.292
12.88,67.37,0.293
12.89,67.47,0.293
12.90,67.57,0.294
12.91,67.67,0.294
12.92,67.77,0.294
12.93,67.87,0.295
12.94,67.97,0.295
12.95,68.07,0.296
12.96,68.17,0.296
12.97,68.27,0.297
12.98,68.37,0.298
12.99,68.47,0.298
13.00,68.57,0.299
13.01,68.67,0.301
13.02,68.77,0.302
13.03,68.87,0.303
13.04,68.97,0.304
13.05,69.07,0.305
13.06,69.16,0.306
13.07,69.26,0.307
13.08,69.36,0.309
13.09,69.47,0.310
13.10,69.56,0.311
13.11,69.67,0.313
13.12,69.76,0.314
13.13,69.86,0.315
13.14,69.97,0.317
13.15,70.07,0.318
13.16,70.16,0.321
13.17,70.26,0.322
13.18,70.36,0.324
13.19,70.46,0.327
13.20,70.56,0.329
13.21,70.66,0.332
13.22,70.76,0.333
13.23,70.86,0.336
13.24,70.96,0.337
13.25,71.06,0.340
13.26,71.16,0.344
13.27,71.26,0.348
13.28,71.36,0.350
13.29,71.46,0.353
13.30,71.56,0.356
13.31,71.66,0.359
13.32,71.76,0.364
13.33,71.86,0.369
13.34,71.96,0.374
13.35,72.05,0.376
13.36,72.15,0.383
13.37,72.25,0.388
13.38,72.35,0.393
13.39,72.45,0.400
13.40,72.55,0.408
13.41,72.65,0.411
13.42,72.75,0.423
13.43,72.85,0.430
13.44,72.94,0.437
13.45,73.04,0.447
13.46,73.14,0.458
13.47,73.24,0.469
13.48,73.34,0.481
13.49,73.43,0.497
13.50,73.53,0.511
13.51,73.63,0.527
13.52,73.73,0.546
13.53,73.82,0.565
13.54,73.92,0.587
13.55,74.01,0.614
13.56,74.11,0.641
13.57,74.20,0.671
13.58,74.30,0.706
13.59,74.39,0.744
13.60,74.48,0.788
13.61,74.57,0.835
13.62,74.66,0.889
13.63,74.75,0.948
13.64,74.84,1.011
13.65,74.93,1.084
13.66,75.02,1.160
13.67,75.10,1.244
13.68,75.18,1.330
13.69,75.27,1.420
13.70,75.35,1.517
13.71,75.43,1.616
13.72,75.51,1.727
13.73,75.58,1.835
13.74,75.66,1.941
13.75,75.73,2.073
13.76,75.80,2.192
13.77,75.88,2.315
13.78,75.95,2.458
13.79,76.01,2.591
13.80,76.08,2.726
13.81,76.15,2.845
13.82,76.22,2.957
13.83,76.29,3.063
13.84,76.35,3.164
13.85,76.42,3.259
13.86,76.49,3.363
13.87,76.56,3.449
13.88,76.64,3.497
13.89,76.71,3.532
13.90,76.79,3.550
13.91,76.87,3.539
13.92,76.96,3.528
13.93,77.04,3.526
13.94,77.14,3.516
13.95,77.23,3.487
13.96,77.33,3.435
13.97,77.42,3.353
13.98,77.53,3.246
13.99,77.64,3.127
14.00,77.75,2.996
14.01,77.87,2.862
14.02,77.99,2.724
14.03,78.11,2.583
14.04,78.24,2.448
14.05,78.37,2.312
14.06,78.49,2.174
14.07,78.63,2.045
14.08,78.76,1.924
14.09,78.89,1.803
14.10,79.02,1.681
14.11,79.15,1.567
14.12,79.28,1.455
14.13,79.42,1.349
14.14,79.55,1.248
14.15,79.68,1.159
14.16,79.81,1.080
14.17,79.94,1.001
14.18,80.06,0.929
14.19,80.19,0.879
14.20,80.31,0.814
14.21,80.43,0.762
14.22,80.55,0.718
14.23,80.67,0.669
14.24,80.79,0.633
14.25,80.91,0.596
14.26,81.02,0.567
14.27,81.14,0.544
14.28,81.25,0.524
14.29,81.36,0.507
14.30,81.47,0.488
14.31,81.58,0.479
14.32,81.69,0.464
14.33,81.80,0.453
14.34,81.91,0.444
14.35,82.02,0.433
14.36,82.12,0.427
14.37,82.23,0.420
14.38,82.33,0.412
14.39,82.44,0.405
14.40,82.54,0.401
14.41,82.64,0.396
14.42,82.74,0.391
14.43,82.85,0.388
14.44,82.95,0.384
14.45,83.05,0.380
14.46,83.15,0.377
14.47,83.26,0.377
14.48,83.36,0.372
14.49,83.46,0.371
14.50,83.56,0.370
14.51,83.66,0.369
14.52,83.76,0.368
14.53,83.86,0.367
14.54,83.97,0.366
14.55,84.07,0.365
14.56,84.17,0.364
14.57,84.27,0.364
14.58,84.37,0.363
14.59,84.47,0.363
14.60,84.57,0.362
14.61,84.67,0.361
14.62,84.77,0.361
14.63,84.87,0.360
14.64,84.97,0.360
14.65,85.07,0.360
14.66,85.17,0.359
14.67,85.27,0.359
14.68,85.37,0.359
14.69,85.47,0.359
14.70,85.57,0.359
14.71,85.67,0.359
14.72,85.77,0.359
14.73,85.87,0.358
14.74,85.97,0.358
14.75,86.07,0.358
14.76,86.17,0.358
14.77,86.27,0.358
14.78,86.37,0.358
14.79,86.48,0.358
14.80,86.57,0.358
14.81,86.67,0.358
14.82,86.77,0.358
14.83,86.88,0.358
14.84,86.98,0.358
14.85,87.08,0.357
14.86,87.18,0.357
14.87,87.28,0.357
14.88,87.38,0.357
14.89,87.48,0.357
14.90,87.58,0.357
14.91,87.68,0.357
14.92,87.78,0.357
14.93,87.88,0.357
14.94,87.98,
14.95,88.08,
14.96,88.18,
14.97,88.28,
14.98,88.38,
14.99,,
14.99,,

[step]
Ramp 10.00 °C/min to -60.00 °C
Time,Temperature,Heat Flow (Normalized)
min,°C,W/g
16.99,90.11,-0.038
17.00,90.11,-0.038
17.01,90.11,-0.038
17.02,90.11,-0.038
17.03,90.10,-0.038
17.04,90.10,-0.038
17.05,90.09,-0.040
17.06,90.07,-0.050
17.07,90.06,-0.061
17.08,90.03,-0.075
17.09,90.00,-0.091
17.10,89.96,-0.111
17.11,89.92,-0.131
17.12,89.87,-0.154
17.13,89.81,-0.175
17.14,89.75,-0.198
17.15,89.69,-0.219
17.16,89.62,-0.238
17.17,89.55,-0.257
17.18,89.48,-0.273
17.19,89.40,-0.286
17.20,89.32,-0.299
17.21,89.24,-0.311
17.22,89.16,-0.321
17.23,89.08,-0.331
17.24,88.99,-0.339
17.25,88.91,-0.347
17.26,88.82,-0.356
17.27,88.73,-0.362
17.28,88.64,-0.368
17.29,88.55,-0.373
17.30,88.46,-0.379
17.31,88.37,-0.382
17.32,88.28,-0.387
17.33,88.18,-0.392
17.34,88.09,-0.393
17.35,88.00,-0.396
17.36,87.90,-0.401
17.37,87.81,-0.404
17.38,87.71,-0.405
17.39,87.62,-0.406
17.40,87.52,-0.408
17.41,87.42,-0.410
17.42,87.33,-0.411
17.43,87.23,-0.412
17.44,87.14,-0.413
17.45,87.04,-0.414
17.46,86.94,-0.414
17.47,86.84,-0.416
17.48,86.75,-0.418
17.49,86.65,-0.418
17.50,86.55,-0.419
17.51,86.45,-0.419
17.52,86.36,-0.419
17.53,86.26,-0.420
17.54,86.16,-0.420
17.55,86.06,-0.421
17.56,85.96,-0.422
17.57,85.86,-0.422
17.58,85.77,-0.422
17.59,85.67,-0.423
17.60,85.57,-0.423
17.61,85.47,-0.423
17.62,85.37,-0.423
17.63,85.27,-0.423
17.64,85.17,-0.424
17.65,85.07,-0.424
17.66,84.97,-0.424
17.67,84.88,-0.424
17.68,84.78,-0.425
17.69,84.68,-0.425
17.70,84.58,-0.425
17.71,84.48,-0.425
17.72,84.38,-0.425
17.73,84.28,-0.426
17.74,84.18,-0.426
17.75,84.08,-0.426
17.76,83.98,-0.426
17.77,83.89,-0.426
17.78,83.79,-0.426
17.79,83.69,-0.426
17.80,83.59,-0.426
17.81,83.49,-0.427
17.82,83.39,-0.427
17.83,83.29,-0.427
17.84,83.19,-0.427
17.85,83.09,-0.427
17.86,82.99,-0.427
17.87,82.89,-0.427
17.88,82.79,-0.428
17.89,82.69,-0.428
17.90,82.59,-0.428
17.91,82.49,-0.428
17.92,82.40,-0.428
17.93,82.29,-0.428
17.94,82.20,-0.428
17.95,82.10,-0.428
17.96,82.00,-0.428
17.97,81.90,-0.428
17.98,81.80,-0.428
17.99,81.70,-0.428
18.00,81.60,-0.429
18.01,81.50,-0.429
18.02,81.40,-0.429
18.03,81.30,-0.429
18.04,81.20,-0.429
18.05,81.10,-0.429
18.06,81.00,-0.429
18.07,80.90,-0.429
18.08,80.80,-0.429
18.09,80.70,-0.429
18.10,80.60,-0.429
18.11,80.50,-0.429
18.12,80.40,-0.429
18.13,80.30,-0.429
18.14,80.20,-0.429
18.15,80.11,-0.429
18.16,80.01,-0.429
18.17,79.91,-0.429
18.18,79.81,-0.429
18.19,79.71,-0.429
18.20,79.61,-0.429
18.21,79.51,-0.429
18.22,79.41,-0.429
18.23,79.31,-0.429
18.24,79.21,-0.429
18.25,79.11,-0.429
18.26,79.01,-0.429
18.27,78.91,-0.429
18.28,78.81,-0.429
18.29,78.71,-0.429
18.30,78.61,-0.429
18.31,78.51,-0.429
18.32,78.41,-0.429
18.33,78.31,-0.429
18.34,78.21,-0.429
18.35,78.11,-0.429
18.36,78.01,-0.429
18.37,77.91,-0.429
18.38,77.81,-0.429
18.39,77.71,-0.429
18.40,77.61,-0.428
18.41,77.51,-0.428
18.42,77.41,-0.428
18.43,77.31,-0.428
18.44,77.21,-0.428
18.45,77.11,-0.428
18.46,77.01,-0.428
18.47,76.91,-0.428
18.48,76.81,-0.428
18.49,76.71,-0.428
18.50,76.61,-0.428
18.51,76.51,-0.428
18.52,76.41,-0.428
18.53,76.31,-0.428
18.54,76.22,-0.428
18.55,76.12,-0.428
18.56,76.02,-0.428
18.57,75.92,-0.428
18.58,75.82,-0.427
18.59,75.72,-0.427
18.60,75.62,-0.427
18.61,75.52,-0.427
18.62,75.42,-0.427
18.63,75.32,-0.427
18.64,75.22,-0.427
18.65,75.12,-0.427
18.66,75.02,-0.427
18.67,74.92,-0.427
18.68,74.82,-0.427
18.69,74.72,-0.427
18.70,74.62,-0.427
18.71,74.52,-0.427
18.72,74.42,-0.427
18.73,74.32,-0.427
18.74,74.22,-0.426
18.75,74.12,-0.426
18.76,74.02,-0.426
18.77,73.92,-0.426
18.78,73.82,-0.426
18.79,73.72,-0.426
18.80,73.62,-0.426
18.81,73.52,-0.426
18.82,73.42,-0.426
18.83,73.32,-0.426
18.84,73.22,-0.426
18.85,73.12,-0.426
18.86,73.02,-0.425
18.87,72.92,-0.425
18.88,72.82,-0.425
18.89,72.72,-0.425
18.90,72.62,-0.425
18.91,72.52,-0.425
18.92,72.42,-0.425
18.93,72.32,-0.425
18.94,72.22,-0.425
18.95,72.12,-0.425
18.96,72.02,-0.425
18.97,71.92,-0.425
18.98,71.82,-0.424
18.99,71.72,-0.424
19.00,71.62,-0.424
19.01,71.52,-0.424
19.02,71.42,-0.424
19.03,71.32,-0.424
19.04,71.22,-0.424
19.05,71.12,-0.424
19.06,71.02,-0.424
19.07,70.92,-0.424
19.08,70.83,-0.424
19.09,70.72,-0.424
19.10,70.62,-0.424
19.11,70.52,-0.423
19.12,70.42,-0.423
19.13,70.32,-0.423
19.14,70.22,-0.423
19.15,70.12,-0.423
19.16,70.02,-0.423
19.17,69.93,-0.423
19.18,69.82,-0.423
19.19,69.73,-0.423
19.20,69.62,-0.423
19.21,69.53,-0.423
19.22,69.43,-0.422
19.23,69.33,-0.422
19.24,69.23,-0.422
19.25,69.13,-0.422
19.26,69.02,-0.422
19.27,68.93,-0.422
19.28,68.83,-0.422
19.29,68.73,-0.422
19.30,68.63,-0.422
19.31,68.53,-0.422
19.32,68.43,-0.422
19.33,68.33,-0.421
19.34,68.23,-0.421
19.35,68.13,-0.421
19.36,68.03,-0.421
19.37,67.93,-0.421
19.38,67.83,-0.421
19.39,67.73,-0.421
19.40,67.63,-0.421
19.41,67.53,-0.421
19.42,67.43,-0.421
19.43,67.33,-0.421
19.44,67.23,-0.421
19.45,67.13,-0.421
19.46,67.03,-0.420
19.47,66.93,-0.420
19.48,66.83,-0.420
19.49,66.73,-0.420
19.50,66.63,-0.420
19.51,66.53,-0.420
19.52,66.43,-0.420
19.53,66.33,-0.420
19.54,66.23,-0.419
19.55,66.13,-0.419
19.56,66.03,-0.419
19.57,65.93,-0.419
19.58,65.83,-0.419
19.59,65.73,-0.419
19.60,65.63,-0.419
19.61,65.53,-0.419
19.62,65.43,-0.419
19.63,65.33,-0.419
19.64,65.23,-0.419
19.65,65.13,-0.419
19.66,65.03,-0.419
19.67,64.93,-0.419
19.68,64.83,-0.419
19.69,64.73,-0.418
19.70,64.63,-0.418
19.71,64.53,-0.418
19.72,64.43,-0.418
19.73,64.33,-0.418
19.74,64.23,-0.418
19.75,64.13,-0.418
19.76,64.03,-0.418
19.77,63.93,-0.418
19.78,63.83,-0.418
19.79,63.73,-0.418
19.80,63.63,-0.418
19.81,63.53,-0.418
19.82,63.43,-0.417
19.83,63.33,-0.417
19.84,63.23,-0.417
19.85,63.13,-0.417
19.86,63.03,-0.417
19.87,62.93,-0.417
19.88,62.83,-0.417
19.89,62.73,-0.417
19.90,62.63,-0.417
19.91,62.53,-0.417
19.92,62.43,-0.417
19.93,62.33,-0.417
19.94,62.23,-0.417
19.95,62.13,-0.416
19.96,62.03,-0.416
19.97,61.93,-0.416
19.98,61.83,-0.416
19.99,61.73,-0.416
20.00,61.63,-0.416
20.01,61.53,-0.415
20.02,61.43,-0.415
20.03,61.33,-0.416
20.04,61.23,-0.415
20.05,61.13,-0.415
20.06,61.03,-0.415
20.07,60.93,-0.415
20.08,60.83,-0.415
20.09,60.73,-0.415
20.10,60.63,-0.415
20.11,60.53,-0.415
20.12,60.43,-0.415
20.13,60.34,-0.415
20.14,60.23,-0.415
20.15,60.13,-0.415
20.16,60.03,-0.415
20.17,59.94,-0.414
20.18,59.84,-0.414
20.19,59.74,-0.414
20.20,59.64,-0.414
20.21,59.54,-0.414
20.22,59.44,-0.414
20.23,59.34,-0.414
20.24,59.24,-0.414
20.25,59.14,-0.414
20.26,59.03,-0.414
20.27,58.94,-0.414
20.28,58.84,-0.414
20.29,58.74,-0.414
20.30,58.64,-0.414
20.31,58.54,-0.414
20.32,58.44,-0.414
20.33,58.34,-0.414
20.34,58.24,-0.413
[...]
104.08,-40.85,0.203
104.09,-40.78,0.203
104.10,-40.71,0.203
104.10,-40.64,0.203
104.11,-40.58,0.203
104.12,-40.51,0.204
104.12,-40.44,0.204
104.13,-40.38,0.204
104.14,-40.31,0.204
104.14,-40.24,0.204
104.15,-40.18,0.204
104.16,-40.11,0.204
104.16,-40.04,0.204
104.17,-39.98,0.204
104.18,-39.91,0.204
104.18,-39.84,0.204
104.19,-39.78,0.204
104.20,-39.71,0.204
104.20,-39.64,0.204
104.21,-39.58,0.204
104.22,-39.51,0.204
104.22,-39.44,0.204
104.23,-39.38,0.204
104.24,-39.31,0.204
104.24,-39.24,0.204
104.25,-39.17,0.204
104.26,-39.11,0.204
104.26,-39.04,0.204
104.27,-38.97,0.204
104.28,-38.91,0.204
104.28,-38.84,0.204
104.29,-38.77,0.204
104.30,-38.71,0.204
104.30,-38.64,0.204
104.31,-38.57,0.204
104.32,-38.51,0.204
104.32,-38.44,0.205
104.33,-38.37,0.205
104.34,-38.31,0.205
104.34,-38.24,0.205
104.35,-38.17,0.205
104.36,-38.10,0.205
104.36,-38.04,0.205
104.37,-37.97,0.205
104.38,-37.90,0.205
104.38,-37.83,0.205
104.39,-37.77,0.205
104.40,-37.70,0.205
104.40,-37.63,0.205
104.41,-37.57,0.205
104.42,-37.50,0.205
104.42,-37.43,0.205
104.43,-37.36,0.205
104.44,-37.30,0.205
104.44,-37.23,0.205
104.45,-37.16,0.205
104.46,-37.10,0.205
104.46,-37.03,0.205
104.47,-36.96,0.205
104.48,-36.90,0.205
104.48,-36.83,0.205
104.49,-36.76,0.205
104.50,-36.70,0.205
104.50,-36.63,0.205
104.51,-36.56,0.205
104.52,-36.50,0.205
104.52,-36.43,0.205
104.53,-36.36,0.205
104.54,-36.30,0.205
104.54,-36.23,0.205
104.55,-36.16,0.205
104.56,-36.10,0.205
104.56,-36.03,0.205
104.57,-35.96,0.205
104.58,-35.90,0.205
104.58,-35.83,0.205
104.59,-35.76,0.205
104.60,-35.70,0.205
104.60,-35.63,0.205
104.61,-35.56,0.205
104.62,-35.50,0.205
104.62,-35.43,0.205
104.63,-35.36,0.205
104.64,-35.30,0.205
104.64,-35.23,0.205
104.65,-35.16,0.205
104.66,-35.10,0.205
104.66,-35.03,0.205
104.67,-34.96,0.205
104.68,-34.90,0.205
104.68,-34.83,0.206
104.69,-34.76,0.206
104.70,-34.70,0.206
104.70,-34.63,0.206
104.71,-34.56,0.206
104.72,-34.50,0.206
104.72,-34.43,0.206
104.73,-34.36,0.206
104.74,-34.30,0.206
104.74,-34.23,0.206
104.75,-34.16,0.206
104.76,-34.10,0.206
104.76,-34.03,0.206
104.77,-33.96,0.206
104.78,-33.90,0.206
104.78,-33.83,0.206
104.79,-33.76,0.206
104.80,-33.70,0.206
104.80,-33.63,0.206
104.81,-33.56,0.206
104.82,-33.50,0.206
104.82,-33.43,0.206
104.83,-33.36,0.206
104.84,-33.30,0.206
104.84,-33.23,0.206
104.85,-33.16,0.206
104.86,-33.10,0.206
104.86,-33.03,0.206
104.87,-32.96,0.206
104.88,-32.89,0.206
104.88,-32.83,0.206
104.89,-32.76,0.206
104.90,-32.70,0.206
104.90,-32.63,0.206
104.91,-32.56,0.206
104.92,-32.49,0.206
104.92,-32.43,0.206
104.93,-32.36,0.206
104.94,-32.29,0.206
104.94,-32.23,0.206
104.95,-32.16,0.206
104.96,-32.10,0.206
104.96,-32.03,0.206
104.97,-31.96,0.206
104.98,-31.90,0.206
104.98,-31.83,0.206
104.99,-31.76,0.206
105.00,-31.69,0.206
105.00,-31.63,0.206
105.01,-31.56,0.206
105.02,-31.49,0.206
105.02,-31.43,0.207
105.03,-31.36,0.207
105.04,-31.29,0.206
105.04,-31.23,0.206
105.05,-31.16,0.207
105.06,-31.09,0.207
105.06,-31.03,0.207
105.07,-30.96,0.207
105.08,-30.89,0.207
105.08,-30.83,0.207
105.09,-30.76,0.207
105.10,-30.69,0.207
105.10,-30.63,0.207
105.11,-30.56,0.207
105.12,-30.49,0.207
105.12,-30.43,0.207
105.13,-30.36,0.207
105.14,-30.29,0.207
105.14,-30.23,0.207
105.15,-30.16,0.207
105.16,-30.09,0.207
105.16,-30.03,0.207
105.17,-29.96,0.207
105.18,-29.89,0.207
105.18,-29.83,0.207
105.19,-29.76,0.207
105.20,-29.69,0.207
105.20,-29.63,0.207
105.21,-29.56,0.207
105.22,-29.49,0.207
105.22,-29.43,0.208
105.23,-29.36,0.208
105.24,-29.29,0.208
105.24,-29.23,0.208
105.25,-29.16,0.208
105.26,-29.09,0.208
105.26,-29.03,0.208
105.27,-28.96,0.208
105.28,-28.89,0.208
105.28,-28.83,0.208
105.29,-28.76,0.208
105.30,-28.69,0.208
105.30,-28.62,0.208
105.31,-28.56,0.208
105.32,-28.49,0.208
105.32,-28.42,0.208
105.33,-28.36,0.208
105.34,-28.29,0.208
105.34,-28.22,0.208
105.35,-28.16,0.208
105.36,-28.09,0.208
105.36,-28.02,0.208
105.37,-27.96,0.208
105.38,-27.89,0.208
105.38,-27.82,0.208
105.39,-27.76,0.208
105.40,-27.69,0.208
105.40,-27.62,0.208
105.41,-27.56,0.208
105.42,-27.49,0.208
105.42,-27.42,0.208
105.43,-27.36,0.209
105.44,-27.29,0.208
105.44,-27.22,0.208
105.45,-27.16,0.208
105.46,-27.09,0.209
105.46,-27.02,0.209
105.47,-26.96,0.209
105.48,-26.89,0.209
105.48,-26.82,0.209
105.49,-26.76,0.209
105.50,-26.69,0.209
105.50,-26.62,0.209
105.51,-26.56,0.209
105.52,-26.49,0.209
105.52,-26.42,0.209
105.53,-26.36,0.209
105.54,-26.29,0.209
105.54,-26.22,0.209
105.55,-26.16,0.209
105.56,-26.09,0.209
105.56,-26.02,0.209
105.57,-25.95,0.209
105.58,-25.89,0.209
105.58,-25.82,0.209
105.59,-25.75,0.209
105.60,-25.69,0.209
105.60,-25.62,0.209
105.61,-25.55,0.209
105.62,-25.49,0.209
105.62,-25.42,0.209
105.63,-25.35,0.209
105.64,-25.29,0.209
105.64,-25.22,0.209
105.65,-25.15,0.209
105.66,-25.09,0.210
105.66,-25.02,0.210
105.67,-24.95,0.210
105.68,-24.89,0.210
105.68,-24.82,0.210
105.69,-24.75,0.210
105.70,-24.69,0.210
105.70,-24.62,0.210
105.71,-24.55,0.210
105.72,-24.49,0.210
105.72,-24.42,0.210
105.73,-24.35,0.210
105.74,-24.29,0.210
105.74,-24.22,0.210
105.75,-24.15,0.210
105.76,-24.08,0.210
105.76,-24.02,0.210
105.77,-23.95,0.210
105.78,-23.89,0.210
105.78,-23.82,0.210
105.79,-23.75,0.210
105.80,-23.68,0.210
105.80,-23.62,0.210
105.81,-23.55,0.210
105.82,-23.48,0.210
105.82,-23.42,0.210
105.83,-23.35,0.210
105.84,-23.28,0.210
105.84,-23.22,0.210
105.85,-23.15,0.210
105.86,-23.09,0.210
105.86,-23.02,0.210
105.87,-22.95,0.210
105.88,-22.88,0.210
105.88,-22.82,0.210
105.89,-22.75,0.210
105.90,-22.68,0.210
105.90,-22.62,0.210
105.91,-22.55,0.210
105.92,-22.48,0.211
105.92,-22.42,0.211
105.93,-22.35,0.211
105.94,-22.28,0.211
105.94,-22.22,0.211
105.95,-22.15,0.211
105.96,-22.08,0.211
105.96,-22.02,0.211
105.97,-21.95,0.211
105.98,-21.88,0.211
105.98,-21.82,0.211
105.99,-21.75,0.211
106.00,-21.68,0.211
106.00,-21.61,0.211
106.01,-21.55,0.211
106.02,-21.48,0.211
106.02,-21.42,0.211
106.03,-21.35,0.211
106.04,-21.28,0.211
106.04,-21.21,0.211
106.05,-21.15,0.211
106.06,-21.08,0.211
106.06,-21.01,0.211
106.07,-20.95,0.212
106.08,-20.88,0.212
106.08,-20.81,0.212
106.09,-20.75,0.212
106.10,-20.68,0.212
106.10,-20.61,0.212
106.11,-20.55,0.212
106.12,-20.48,0.212
106.12,-20.41,0.212
106.13,-20.35,0.212
106.14,-20.28,0.212
106.14,-20.21,0.212
106.15,-20.15,0.212
106.16,-20.08,0.212
106.16,-20.01,0.212
106.17,-19.95,0.212
106.18,-19.88,0.212
106.18,-19.81,0.212
106.19,-19.75,0.212
106.20,-19.68,0.212
106.20,-19.61,0.212
106.21,-19.55,0.212
106.22,-19.48,0.212
106.22,-19.41,0.212
106.23,-19.35,0.212
106.24,-19.28,0.212
106.24,-19.21,0.212
106.25,-19.15,0.213
106.26,-19.08,0.213
106.26,-19.01,0.213
106.27,-18.95,0.213
106.28,-18.88,0.213
106.28,-18.81,0.213
106.29,-18.75,0.213
106.30,-18.68,0.213
106.30,-18.61,0.213
106.31,-18.54,0.213
106.32,-18.48,0.213
106.32,-18.41,0.213
106.33,-18.34,0.213
106.34,-18.28,0.213
106.34,-18.21,0.213
106.35,-18.14,0.213
106.36,-18.08,0.213
106.36,-18.01,0.213
106.37,-17.94,0.213
106.38,-17.88,0.213
106.38,-17.81,0.213
106.39,-17.75,0.214
106.40,-17.68,0.214
106.40,-17.61,0.214
106.41,-17.54,0.214
106.42,-17.48,0.214
106.42,-17.41,0.214
106.43,-17.34,0.214
106.44,-17.28,0.214
106.44,-17.21,0.214
106.45,-17.14,0.214
106.46,-17.08,0.214
106.46,-17.01,0.214
106.47,-16.94,0.214
106.48,-16.88,0.214
106.48,-16.81,0.214
106.49,-16.74,0.214
106.50,-16.67,0.214
106.50,-16.61,0.214
106.51,-16.54,0.215
106.52,-16.47,0.215
106.52,-16.41,0.215
106.53,-16.34,0.215
106.54,-16.27,0.215
106.54,-16.21,0.215
106.55,-16.14,0.215
106.56,-16.07,0.215
106.56,-16.01,0.215
106.57,-15.94,0.215
106.58,-15.87,0.215
106.58,-15.81,0.215
106.59,-15.74,0.215
106.60,-15.67,0.215
106.60,-15.61,0.215
106.61,-15.54,0.215
106.62,-15.47,0.215
106.62,-15.41,0.215
106.63,-15.34,0.215
106.64,-15.27,0.216
106.64,-15.21,0.216
106.65,-15.14,0.216
106.66,-15.07,0.216
106.66,-15.01,0.216
106.67,-14.94,0.216
106.68,-14.87,0.216
106.68,-14.81,0.216
106.69,-14.74,0.216
106.70,-14.67,0.216
106.70,-14.61,0.216
106.71,-14.54,0.216
106.72,-14.47,0.216
106.72,-14.41,0.216
106.73,-14.34,0.216
106.74,-14.27,0.217
106.74,-14.20,0.217
106.75,-14.14,0.217
106.76,-14.07,0.217
106.76,-14.01,0.217
106.77,-13.94,0.217
106.78,-13.87,0.217
106.78,-13.80,0.217
106.79,-13.74,0.217
106.80,-13.67,0.217
106.80,-13.60,0.217
106.81,-13.54,0.217
106.82,-13.47,0.217
106.82,-13.40,0.217
106.83,-13.34,0.217
106.84,-13.27,0.217
106.84,-13.20,0.217
106.85,-13.14,0.217
106.86,-13.07,0.217
106.86,-13.00,0.218
106.87,-12.94,0.218
106.88,-12.87,0.218
106.88,-12.81,0.218
106.89,-12.74,0.218
106.90,-12.67,0.218
106.90,-12.60,0.218
106.91,-12.54,0.218
106.92,-12.47,0.218
106.92,-12.40,0.218
106.93,-12.34,0.218
106.94,-12.27,0.218
106.94,-12.20,0.218
106.95,-12.14,0.218
106.96,-12.07,0.218
106.96,-12.00,0.218
106.97,-11.94,0.219
106.98,-11.87,0.219
106.98,-11.80,0.219
106.99,-11.74,0.219
107.00,-11.67,0.219
107.00,-11.60,0.219
107.01,-11.54,0.219
107.02,-11.47,0.219
107.02,-11.40,0.219
107.03,-11.34,0.219
107.04,-11.27,0.219
107.04,-11.20,0.219
107.05,-11.14,0.220
107.06,-11.07,0.220
107.06,-11.00,0.220
107.07,-10.94,0.220
107.08,-10.87,0.220
107.08,-10.80,0.220
107.09,-10.73,0.220
107.10,-10.67,0.220
107.10,-10.60,0.220
107.11,-10.53,0.220
107.12,-10.47,0.220
107.12,-10.40,0.221
107.13,-10.34,0.221
107.14,-10.27,0.221
107.14,-10.20,0.221
107.15,-10.13,0.221
107.16,-10.07,0.221
107.16,-10.00,0.221
107.17,-9.93,0.221
107.18,-9.87,0.221
107.18,-9.80,0.222
107.19,-9.73,0.222
107.20,-9.67,0.222
107.20,-9.60,0.222
107.21,-9.53,0.222
107.22,-9.47,0.222
107.22,-9.40,0.222
107.23,-9.33,0.222
107.24,-9.27,0.222
107.24,-9.20,0.222
107.25,-9.14,0.223
107.26,-9.07,0.223
107.26,-9.00,0.223
107.27,-8.93,0.223
107.28,-8.87,0.223
107.28,-8.80,0.223
107.29,-8.73,0.223
107.30,-8.67,0.223
107.30,-8.60,0.223
107.31,-8.53,0.223
107.32,-8.47,0.224
107.32,-8.40,0.224
107.33,-8.33,0.224
107.34,-8.27,0.224
107.34,-8.20,0.224
107.35,-8.13,0.224
107.36,-8.07,0.224
107.36,-8.00,0.224
107.37,-7.93,0.225
107.38,-7.87,0.225
107.38,-7.80,0.225
107.39,-7.73,0.225
107.40,-7.67,0.225
107.40,-7.60,0.225
107.41,-7.53,0.226
107.42,-7.47,0.226
107.42,-7.40,0.226
107.43,-7.33,0.226
107.44,-7.27,0.226
107.44,-7.20,0.226
107.45,-7.13,0.226
107.46,-7.07,0.227
107.46,-7.00,0.227
107.47,-6.93,0.227
107.48,-6.87,0.227
107.48,-6.80,0.227
107.49,-6.73,0.227
107.50,-6.67,0.228
107.50,-6.60,0.228
107.51,-6.53,0.228
107.52,-6.47,0.228
107.52,-6.40,0.229
107.53,-6.33,0.229
107.54,-6.27,0.229
107.54,-6.20,0.229
107.55,-6.13,0.229
107.56,-6.07,0.230
107.56,-6.00,0.230
107.57,-5.93,0.230
107.58,-5.87,0.230
107.58,-5.80,0.230
107.59,-5.73,0.231
107.60,-5.67,0.231
107.60,-5.60,0.231
107.61,-5.53,0.232
107.62,-5.47,0.232
107.62,-5.40,0.233
107.63,-5.33,0.233
107.64,-5.27,0.233
107.64,-5.20,0.233
107.65,-5.13,0.233
107.66,-5.07,0.234
107.66,-5.00,0.234
107.67,-4.93,0.234
107.68,-4.87,0.235
107.68,-4.80,0.235
107.69,-4.73,0.236
107.70,-4.67,0.236
107.70,-4.60,0.236
107.71,-4.53,0.237
107.72,-4.47,0.237
107.72,-4.40,0.237
107.73,-4.33,0.238
107.74,-4.27,0.239
107.74,-4.20,0.240
107.75,-4.13,0.240
107.76,-4.07,0.241
107.76,-4.00,0.242
107.77,-3.93,0.242
107.78,-3.87,0.242
107.78,-3.80,0.242
107.79,-3.73,0.243
107.80,-3.67,0.244
107.80,-3.60,0.244
107.81,-3.53,0.245
107.82,-3.47,0.245
107.82,-3.40,0.246
107.83,-3.33,0.247
107.84,-3.27,0.248
107.84,-3.20,0.248
107.85,-3.13,0.249
107.86,-3.07,0.250
107.86,-3.00,0.250
107.87,-2.93,0.251
107.88,-2.87,0.252
107.88,-2.80,0.252
107.89,-2.73,0.253
107.90,-2.67,0.255
107.90,-2.60,0.256
107.91,-2.54,0.256
107.92,-2.47,0.257
107.92,-2.40,0.258
107.93,-2.33,0.259
107.94,-2.27,0.260
107.94,-2.20,0.260
107.95,-2.13,0.262
107.96,-2.07,0.263
107.96,-2.00,0.263
107.97,-1.94,0.265
107.98,-1.87,0.267
107.98,-1.80,0.267
107.99,-1.74,0.268
108.00,-1.67,0.269
108.00,-1.60,0.270
108.01,-1.54,0.271
108.02,-1.47,0.272
108.02,-1.40,0.274
108.03,-1.34,0.275
108.04,-1.27,0.276
108.04,-1.20,0.278
108.05,-1.14,0.279
108.06,-1.07,0.279
108.06,-1.00,0.281
108.07,-0.94,0.282
108.08,-0.87,0.283
108.08,-0.81,0.285
108.09,-0.74,0.286
108.10,-0.67,0.287
108.10,-0.61,0.287
108.11,-0.54,0.289
108.12,-0.47,0.292
108.12,-0.41,0.294
108.13,-0.34,0.294
108.14,-0.27,0.295
108.14,-0.21,0.296
108.15,-0.14,0.297
108.16,-0.07,0.298
108.16,-0.01,0.300
108.17,0.06,0.303
108.18,0.12,0.304
108.18,0.19,0.305
108.19,0.26,0.306
108.20,0.32,0.307
108.20,0.39,0.308
108.21,0.46,0.310
108.22,0.52,0.310
108.22,0.59,0.311
108.23,0.65,0.313
108.24,0.72,0.315
108.24,0.79,0.316
108.25,0.85,0.316
108.26,0.92,0.316
108.26,0.99,0.318
108.27,1.05,0.320
108.28,1.12,0.320
108.28,1.19,0.321
108.29,1.25,0.322
108.30,1.32,0.323
108.30,1.39,0.323
108.31,1.45,0.324
108.32,1.52,0.326
108.32,1.58,0.326
108.33,1.65,0.326
108.34,1.72,0.327
108.34,1.78,0.327
108.35,1.85,0.328
108.36,1.92,0.328
108.36,1.98,0.329
108.37,2.05,0.330
108.38,2.12,0.330
108.38,2.18,0.330
108.39,2.25,0.331
108.40,2.32,0.331
108.40,2.38,0.331
108.41,2.45,0.331
108.42,2.52,0.331
108.42,2.58,0.331
108.43,2.65,0.331
108.44,2.72,0.331
108.44,2.78,0.331
108.45,2.85,0.331
108.46,2.92,0.331
108.46,2.98,0.331
108.47,3.05,0.331
108.48,3.12,0.331
108.48,3.18,0.330
108.49,3.25,0.330
108.50,3.32,0.329
108.50,3.38,0.329
108.51,3.45,0.328
108.52,3.52,0.328
108.52,3.59,0.328
108.53,3.65,0.326
108.54,3.72,0.325
108.54,3.79,0.324
108.55,3.85,0.324
108.56,3.92,0.323
108.56,3.99,0.322
108.57,4.05,0.321
108.58,4.12,0.320
108.58,4.19,0.319
108.59,4.26,0.319
108.60,4.32,0.318
108.60,4.39,0.317
108.61,4.46,0.317
108.62,4.52,0.317
108.62,4.59,0.316
108.63,4.66,0.316
108.64,4.72,0.316
108.64,4.79,0.315
108.65,4.86,0.315
108.66,4.92,0.315
108.66,4.99,0.315
108.67,5.06,0.314
108.68,5.13,0.314
108.68,5.19,0.313
108.69,5.26,0.313
108.70,5.33,0.313
108.70,5.39,0.313
108.71,5.46,0.313
108.72,5.53,0.312
108.72,5.59,0.312
108.73,5.66,0.312
108.74,5.73,0.312
108.74,5.80,0.311
108.75,5.86,0.311
108.76,5.93,0.311
108.76,6.00,0.311
108.77,6.06,0.310
108.78,6.13,0.310
108.78,6.20,0.310
108.79,6.26,0.310
108.80,6.33,0.310
108.80,6.40,0.310
108.81,6.46,0.310
108.82,6.53,0.309
108.82,6.60,0.309
108.83,6.66,0.309
108.84,6.73,0.309
108.84,6.80,0.309
108.85,6.86,0.309
108.86,6.93,0.308
108.86,7.00,0.308
108.87,7.07,0.308
108.88,7.13,0.308
108.88,7.20,0.308
108.89,7.27,0.308
108.90,7.33,0.308
108.90,7.40,0.307
108.91,7.47,0.307
108.92,7.53,0.307
108.92,7.60,0.307
108.93,7.67,0.307
108.94,7.73,0.307
108.94,7.80,0.307
108.95,7.87,0.307
108.96,7.93,0.307
108.96,8.00,0.307
108.97,8.07,0.307
108.98,8.13,0.306
108.98,8.20,0.306
108.99,8.27,0.306
109.00,8.33,0.306
109.00,8.40,0.306
109.01,8.47,0.306
109.02,8.54,0.306
109.02,8.60,0.306
109.03,8.67,0.306
109.04,8.74,0.306
109.04,8.80,0.306
109.05,8.87,0.306
109.06,8.94,0.306
109.06,9.00,0.306
109.07,9.07,0.306
109.08,9.14,0.305
109.08,9.20,0.305
109.09,9.27,0.305
109.10,9.34,0.305
109.10,9.40,0.305
109.11,9.47,0.305
109.12,9.54,0.305
109.12,9.60,0.305
109.13,9.67,0.305
109.14,9.74,0.305
109.14,9.80,0.305
109.15,9.87,0.305
109.16,9.94,0.305
109.16,10.00,0.305
109.17,10.07,0.305
109.18,10.14,0.305
109.18,10.20,0.305
109.19,10.27,0.305
109.20,10.34,0.305
109.20,10.40,0.305
109.21,10.47,0.305
109.22,10.54,0.305
109.22,10.60,0.305
109.23,10.67,0.305
109.24,10.74,0.305
109.24,10.80,0.305
109.25,10.87,0.305
109.26,10.94,0.305
109.26,11.01,0.305
109.27,11.07,0.305
109.28,11.14,0.305
109.28,11.20,0.305
109.29,11.27,0.305
109.30,11.34,0.305
109.30,11.41,0.305
109.31,11.47,0.305
109.32,11.54,0.305
109.32,11.61,0.305
109.33,11.67,0.305
109.34,11.74,0.305
109.34,11.81,0.305
109.35,11.87,0.305
109.36,11.94,0.305
109.36,12.01,0.305
109.37,12.07,0.305
109.38,12.14,0.305
109.38,12.21,0.305
109.39,12.27,0.305
109.40,12.34,0.305
109.40,12.41,0.305
109.41,12.47,0.305
109.42,12.54,0.305
109.42,12.61,0.305
109.43,12.67,0.305
109.44,12.74,0.305
109.44,12.81,0.305
109.45,12.87,0.305
109.46,12.94,0.305
109.46,13.01,0.305
109.47,13.07,0.305
109.48,13.14,0.305
109.48,13.21,0.305
109.49,13.27,0.305
109.50,13.34,0.305
109.50,13.41,0.305
109.51,13.47,0.305
109.52,13.54,0.305
109.52,13.61,0.305
109.53,13.68,0.305
109.54,13.74,0.305
109.54,13.81,0.305
109.55,13.88,0.305
109.56,13.94,0.305
109.56,14.01,0.305
109.57,14.08,0.305
109.58,14.14,0.305
109.58,14.21,0.305
109.59,14.27,0.305
109.60,14.34,0.305
109.60,14.41,0.305
109.61,14.48,0.305
109.62,14.54,0.305
109.62,14.61,0.305
109.63,14.68,0.305
109.64,14.74,0.305
109.64,14.81,0.306
109.65,14.88,0.306
109.66,14.94,0.306
109.66,15.01,0.306
109.67,15.08,0.306
109.68,15.14,0.306
109.68,15.21,0.306
109.69,15.28,0.306
109.70,15.34,0.306
109.70,15.41,0.306
109.71,15.48,0.306
109.72,15.54,0.306
109.72,15.61,0.306
109.73,15.68,0.306
109.74,15.74,0.306
109.74,15.81,0.306
109.75,15.88,0.306
109.76,15.94,0.306
109.76,16.01,0.306
109.77,16.08,0.306
109.78,16.15,0.306
109.78,16.21,0.306
109.79,16.28,0.306
109.80,16.34,0.306
109.80,16.41,0.306
109.81,16.48,0.306
109.82,16.54,0.306
109.82,16.61,0.306
109.83,16.68,0.306
109.84,16.75,0.306
109.84,16.81,0.306
109.85,16.88,0.306
109.86,16.94,0.306
109.86,17.01,0.307
109.87,17.08,0.307
109.88,17.15,0.307
109.88,17.21,0.307
109.89,17.28,0.307
109.90,17.35,0.307
109.90,17.41,0.307
109.91,17.48,0.307
109.92,17.55,0.307
109.92,17.61,0.307
109.93,17.68,0.307
109.94,17.75,0.307
109.94,17.81,0.307
109.95,17.88,0.307
109.96,17.95,0.307
109.96,18.01,0.307
109.97,18.08,0.307
109.98,18.15,0.307
109.98,18.21,0.307
109.99,18.28,0.307
110.00,18.35,0.307
110.00,18.41,0.307
110.01,18.48,0.307
110.02,18.55,0.308
110.02,18.61,0.308
110.03,18.68,0.308
110.04,18.75,0.308
110.04,18.81,0.308
110.05,18.88,0.308
110.06,18.95,0.308
110.06,19.01,0.308
110.07,19.08,0.308
110.08,19.15,0.308
110.08,19.21,0.308
110.09,19.28,0.308
110.10,19.35,0.308
110.10,19.42,0.308
110.11,19.48,0.308
110.12,19.55,0.308
110.12,19.62,0.308
110.13,19.68,0.308
110.14,19.75,0.308
110.14,19.82,0.308
110.15,19.88,0.308
110.16,19.95,0.309
110.16,20.02,0.309
110.17,20.08,0.309
110.18,20.15,0.309
110.18,20.22,0.309
110.19,20.28,0.309
110.20,20.35,0.309
110.20,20.42,0.309
110.21,20.48,0.309
110.22,20.55,0.309
110.22,20.62,0.309
110.23,20.68,0.309
110.24,20.75,0.309
110.24,20.82,0.309
110.25,20.88,0.309
110.26,20.95,0.309
110.26,21.02,0.309
110.27,21.08,0.309
110.28,21.15,0.309
110.28,21.22,0.309
110.29,21.28,0.309
110.30,21.35,0.309
110.30,21.42,0.309
110.31,21.49,0.309
110.32,21.55,0.309
110.32,21.62,0.309
110.33,21.69,0.310
110.34,21.75,0.310
110.34,21.82,0.310
110.35,21.89,0.310
110.36,21.95,0.310
110.36,22.02,0.310
110.37,22.09,0.310
110.38,22.15,0.310
110.38,22.22,0.310
110.39,22.28,0.310
110.40,22.35,0.310
110.40,22.42,0.310
110.41,22.49,0.310
110.42,22.55,0.310
110.42,22.62,0.310
110.43,22.69,0.310
110.44,22.75,0.310
110.44,22.82,0.310
110.45,22.89,0.310
110.46,22.95,0.310
110.46,23.02,0.310
110.47,23.09,0.310
110.48,23.15,0.310
110.48,23.22,0.310
110.49,23.29,0.310
110.50,23.35,0.310
110.50,23.42,0.310
110.51,23.49,0.310
110.52,23.56,0.310
110.52,23.62,0.310
110.53,23.69,0.310
110.54,23.75,0.310
110.54,23.82,0.310
110.55,23.89,0.311
110.56,23.96,0.311
110.56,24.02,0.311
110.57,24.09,0.311
110.58,24.16,0.311
110.58,24.22,0.311
110.59,24.29,0.311
110.60,24.36,0.311
110.60,24.42,0.311
110.61,24.49,0.311
110.62,24.56,0.311
110.62,24.62,0.311
110.63,24.69,0.311
110.64,24.76,0.311
110.64,24.82,0.311
110.65,24.89,0.311
110.66,24.96,0.311
110.66,25.02,0.311
110.67,25.09,0.311
110.68,25.16,0.311
110.68,25.22,0.311
110.69,25.29,0.311
110.70,25.36,0.312
110.70,25.42,0.312
110.71,25.49,0.312
110.72,25.56,0.312
110.72,25.62,0.312
110.73,25.69,0.312
110.74,25.76,0.312
110.74,25.82,0.312
110.75,25.89,0.312
110.76,25.96,0.312
110.76,26.02,0.312
110.77,26.09,0.312
110.78,26.16,0.312
110.78,26.22,0.312
110.79,26.29,0.312
110.80,26.36,0.312
110.80,26.42,0.312
110.81,26.49,0.312
110.82,26.56,0.312
110.82,26.63,0.312
110.83,26.69,0.312
110.84,26.76,0.312
110.84,26.83,0.312
110.85,26.89,0.313
110.86,26.96,0.313
110.86,27.03,0.313
110.87,27.09,0.313
110.88,27.16,0.313
110.88,27.23,0.313
110.89,27.29,0.313
110.90,27.36,0.313
110.90,27.43,0.313
110.91,27.49,0.313
110.92,27.56,0.313
110.92,27.63,0.313
110.93,27.69,0.313
110.94,27.76,0.313
110.94,27.83,
110.95,27.89,
110.96,27.96,
110.96,28.03,
110.97,28.09,
110.98,28.16,
110.98,28.23,
110.99,,
111.00,,