File: DSC/Olivia/2025_08_02_1CBN_3PVP_Vortex_n60C_130C_10Cmin_x3.csv
Filename,2025_08_02_1CBN_3PVP_Vortex_n60C_130C_10Cmin_x3
Instrument name,DSC2A-00468 (192.168.1.100)
Operator,Yarger
rundate,8/2/2025
Sample name,2025_08_02_1CBN_3PVP_Vortex_n60C_130C_10Cmin_x3
proceduresegments,Data Off ; Equilibrate -60.00 °C; Data On ; Ramp 10.00 °C/min to 130.00 °C; Data Off ; Isothermal 2.0 min; Data On ; Ramp 10.00 °C/min to -60.00 °C; Data Off ; Isothermal 2.0 min; Data On ; Ramp 10.00 °C/min to 130.00 °C; Data Off ; Isothermal 2.0 min; Data On ; Ramp 10.00 °C/min to -60.00 °C; Data Off ; Isothermal 2.0 min; Data On ; Ramp 10.00 °C/min to 130.00 °C
[File Parameters]
Run date,8/2/2025 2:19:32 PM
Trios version,5.1.1.46572
Original File Name,
Current File Name,D:\DSC2500\Gibbons\2025_08_02_1CBN_3PVP_Vortex_n60C_130C_10Cmin_x3.tri
[Procedure]
Procedure Name,CBNPVP_n60C_130C_10Cmin_x3
Sample Name,2025_08_02_1CBN_3PVP_Vortex_n60C_130C_10Cmin_x3
Sample Mass,8.51 mg
Reference Sample Mass,0 mg
Pan Mass,32.85 mg
Pan Number,52
Reference Pan Mass,32.73 mg
Reference Pan Number,46
Pan Type,Aluminum
Comments,Thermal support Al pans/lids. DSC_Samples_A2_Tray_July2025 google sheet.
Project Name,Pharma - Cocrystals
Operator,Yarger
Test,Custom
Unload Max Temperature,30
Unload Min Temperature,30
Load Max Temperature,30
Load Min Temperature,30
Stop on Gas Flow Error,Yes
[Signal List]
Signal #1,Time (min)
Signal #2,Temperature (°C)
Signal #3,Heat Flow (mW)
Signal #4,Delta T (µV)
Signal #5,Delta Tzero (µV)
Signal #6,Tzero Temperature (°C)
Signal #7,Cell Purge (mL/min)
Signal #8,Heater Temp (°C)
Signal #9,Power Delivered (W)
Signal #10,Reference Junction Temperature (°C)
Signal #11,Flange Temperature (°C)
Signal #12,Heat Flow Phase (rad)
Signal #13,Total Heat Capacity (J/°C)
Signal #14,Heat Capacity (J/°C)
[Configuration]
Company Name,ASU
Instrument Name,DSC2A-00468
Instrument Type,DSC2500
Serial Number,DSC2A-00468
IP,192.168.1.100
Location of Instrument,MRRC
DisplayType,Unknown
Sample Interval ,0.1 s/pt
Selected Heat Flow,T4P
Exotherm Direction,Down
Cell Serial,DRC2-00792
Lid Type,Standard
Cooler,RCS 90
Leave Cooler on at End of Sequence,On
Gas 2,Nitrogen
Gas Selected,Channel 1
Flow Rate,50 mL/min
Secondary Purge,On
Licensed Heat Flow,Heat Flow T4P
Modulation Licensed,Yes
[Versions]
Common IDD Version,1
Cortex Version,VER 2.10.2.31
Driver,5.0.0.6
GDM Version,1.0.3.3
TouchscreenVersion,1.0.0.16145
FEP Version,1.2.1.21
FEP Bootloader,2.0.0.5
AutoSampler Version,2.1.1.26
Auto Sampler Bootloader,2.0.0.5
FCM Version,1.1.0.3
FCM Bootloader,2.0.0.5
[Experiment Logs]
Experiment Log Entry # 1,Data On set to 0
Experiment Log Entry # 3,Equilibrate Segment -60 (C) Started
Experiment Log Entry # 5,Air Cool is off.
Experiment Log Entry # 7,Data On set to 1
Experiment Log Entry # 9,Ramp Segment 10 C/min to 130 Started
Experiment Log Entry # 11,Data On set to 0
Experiment Log Entry # 13,Isothermal Segment 2 min started
Experiment Log Entry # 15,Data On set to 1
Experiment Log Entry # 17,Ramp Segment 10 C/min to -60 Started
Experiment Log Entry # 19,Data On set to 0
Experiment Log Entry # 21,Isothermal Segment 2 min started
Experiment Log Entry # 23,Data On set to 1
Experiment Log Entry # 25,Ramp Segment 10 C/min to 130 Started
Experiment Log Entry # 27,Data On set to 0
Experiment Log Entry # 29,Isothermal Segment 2 min started
Experiment Log Entry # 31,Data On set to 1
Experiment Log Entry # 33,Ramp Segment 10 C/min to -60 Started
Experiment Log Entry # 35,Data On set to 0
Experiment Log Entry # 37,Isothermal Segment 2 min started
Experiment Log Entry # 39,Data On set to 1
Experiment Log Entry # 41,Ramp Segment 10 C/min to 130 Started
[Method Log]
Method Log Entry # 1,Data Off
Method Log Entry # 2,Equilibrate -60 °C
Method Log Entry # 3,Data On
Method Log Entry # 4,(Ramp 158539) Ramp 10 °C/minute to 130 °C
Method Log Entry # 5,Data Off
Method Log Entry # 6,Isothermal 2 minutes
Method Log Entry # 7,Data On
Method Log Entry # 8,(Ramp 158543) Ramp 10 °C/minute to -60 °C
Method Log Entry # 9,Data Off
Method Log Entry # 10,Isothermal 2 minutes
Method Log Entry # 11,Data On
Method Log Entry # 12,(Ramp 158547) Ramp 10 °C/minute to 130 °C
Method Log Entry # 13,Data Off
Method Log Entry # 14,Isothermal 2 minutes
Method Log Entry # 15,Data On
Method Log Entry # 16,(Ramp 158551) Ramp 10 °C/minute to -60 °C
Method Log Entry # 17,Data Off
Method Log Entry # 18,Isothermal 2 minutes
Method Log Entry # 19,Data On
Method Log Entry # 20,(Ramp 158555) Ramp 10 °C/minute to 130 °C
Cell Serial,DRC2-00792
[T1 Calibration]
Slope,-0.008529666
Offset,9.636258
Initial Temperature,98.23
GUID,f8bfdadc-4977-4fdf-ba6d-0ba9134940c3
[TZero Calibration]
Date Applied,11/29/2022 4:06:13 PM
Description,From -89.059 °C to 396.009 °C at 20.000°C/min
Gas Type,Nitrogen
Pan Type,None
Source Files 1,C:\Users\yargerlab\Desktop\DSC Data\General\TZero_calibration_11_29_22_2nd(2).tri
Source Files 2,C:\Users\yargerlab\Desktop\DSC Data\General\TZero_calibration_11_29_22_2nd(3).tri
Delta T Offset,13.05235
Delta T Slope,-0.007271007
Delta T0 Offset,-13.69128
Delta T0 Slope,0.06063341
[Temperature Calibration]
Date Applied,11/29/2022 7:12:28 PM
Description,From 106.590 °C to 186.590 °C at 10.000°C/min
Gas Type,Nitrogen
Pan Type,Tzero Aluminum Hermetic
Source Files 1,C:\Users\yargerlab\Desktop\DSC Data\General\Indium(6).tri
Measured 1,157.391
Known 1,156.598
[Cell Constant Calibration]
Date Applied,11/29/2022 7:12:29 PM
Description,From 106.590 °C to 186.590 °C at 10.000°C/min
Gas Type,Nitrogen
Pan Type,Tzero Aluminum Hermetic
Source Files 1,C:\Users\yargerlab\Desktop\DSC Data\General\Indium(6).tri
T4P KCell,1.006051
Onset Slope,63.26126 mW/°C
[Direct Cp Calibration]
Date Applied,11/30/2022 11:04:51 AM
Description,From -79.983 °C to 298.409 °C at 10.000°C/min
Gas Type,Nitrogen
Pan Type,Tzero Aluminum Hermetic
Source Files 1,C:\Users\yargerlab\Desktop\DSC Data\General\Sapphire_Heat_Capacity_11_30_22.tri
[Rev Cp Calibration]
Date Applied,11/30/2022 1:58:51 PM
Description,From -79.996 °C to 292.812 °C at 3.000°C/min
Gas Type,Nitrogen
Pan Type,Tzero Aluminum Hermetic
Source Files 1,C:\Users\yargerlab\Desktop\DSC Data\General\Sapphire_MDSC_Calibration_11_30_22.tri
[step]
Ramp 10.00 °C/min to 130.00 °C
Time,Temperature,Heat Flow (Normalized)
min,°C,W/g
0.00,-59.80,-0.042
0.01,-59.80,-0.041
0.03,-59.80,-0.038
0.04,-59.80,-0.035
0.05,-59.80,-0.035
0.07,-59.78,-0.036
0.08,-59.75,-0.037
0.09,-59.71,-0.037
0.11,-59.65,-0.037
0.12,-59.58,-0.032
0.13,-59.51,-0.022
0.15,-59.42,-0.011
0.16,-59.32,0.002
0.17,-59.22,0.016
0.19,-59.12,0.030
0.20,-59.01,0.045
0.21,-58.89,0.059
0.23,-58.78,0.072
0.24,-58.66,0.082
0.25,-58.54,0.093
0.27,-58.42,0.102
0.28,-58.29,0.110
0.29,-58.17,0.117
0.31,-58.05,0.123
0.32,-57.92,0.128
0.33,-57.80,0.134
0.35,-57.67,0.136
0.36,-57.54,0.141
0.37,-57.42,0.143
0.39,-57.29,0.146
0.40,-57.16,0.149
0.41,-57.04,0.150
0.43,-56.91,0.153
0.44,-56.78,0.154
0.45,-56.65,0.155
0.47,-56.52,0.156
0.48,-56.39,0.158
0.49,-56.26,0.159
0.51,-56.13,0.159
0.52,-56.00,0.161
0.53,-55.87,0.162
0.55,-55.74,0.162
0.56,-55.61,0.163
0.57,-55.47,0.163
0.59,-55.34,0.164
0.60,-55.21,0.164
0.61,-55.08,0.165
0.63,-54.95,0.165
0.64,-54.82,0.165
0.65,-54.69,0.166
0.67,-54.56,0.166
0.68,-54.43,0.166
0.69,-54.29,0.166
0.71,-54.16,0.167
0.72,-54.03,0.167
0.73,-53.90,0.167
0.75,-53.77,0.167
0.76,-53.64,0.168
0.77,-53.50,0.168
0.79,-53.37,0.168
0.80,-53.24,0.168
0.81,-53.11,0.169
0.83,-52.98,0.169
0.84,-52.84,0.169
0.85,-52.71,0.169
0.87,-52.58,0.169
0.88,-52.45,0.170
0.89,-52.31,0.170
0.91,-52.18,0.170
0.92,-52.05,0.170
0.93,-51.92,0.170
0.95,-51.79,0.170
0.96,-51.66,0.171
0.97,-51.52,0.171
0.99,-51.39,0.171
1.00,-51.26,0.171
1.01,-51.12,0.171
1.03,-50.99,0.171
1.04,-50.86,0.172
1.05,-50.73,0.172
1.07,-50.59,0.172
1.08,-50.46,0.172
1.09,-50.33,0.172
1.11,-50.20,0.173
1.12,-50.06,0.173
1.13,-49.93,0.173
1.15,-49.80,0.173
1.16,-49.66,0.173
1.17,-49.53,0.173
1.19,-49.40,0.174
1.20,-49.27,0.174
1.21,-49.13,0.174
1.23,-49.00,0.174
1.24,-48.87,0.174
1.25,-48.73,0.174
1.27,-48.60,0.174
1.28,-48.47,0.175
1.29,-48.34,0.175
1.31,-48.20,0.175
1.32,-48.07,0.175
1.33,-47.94,0.175
1.35,-47.80,0.175
1.36,-47.67,0.175
1.37,-47.54,0.176
1.39,-47.41,0.176
1.40,-47.27,0.176
1.41,-47.14,0.176
1.43,-47.01,0.176
1.44,-46.87,0.176
1.45,-46.74,0.176
1.47,-46.61,0.176
1.48,-46.47,0.177
1.49,-46.34,0.177
1.51,-46.21,0.177
1.52,-46.08,0.177
1.53,-45.94,0.177
1.55,-45.81,0.177
1.56,-45.67,0.177
1.57,-45.54,0.177
1.59,-45.41,0.178
1.60,-45.27,0.178
1.61,-45.14,0.178
1.63,-45.01,0.178
1.64,-44.87,0.178
1.65,-44.74,0.178
1.67,-44.61,0.178
1.68,-44.47,0.178
1.69,-44.34,0.178
1.71,-44.21,0.179
1.72,-44.07,0.179
1.73,-43.94,0.179
1.75,-43.81,0.179
1.76,-43.67,0.179
1.77,-43.54,0.179
1.79,-43.41,0.179
1.80,-43.27,0.179
1.81,-43.14,0.179
1.83,-43.01,0.180
1.84,-42.87,0.180
1.85,-42.74,0.180
1.87,-42.60,0.180
1.88,-42.47,0.180
1.89,-42.34,0.180
1.91,-42.20,0.180
1.92,-42.07,0.180
1.93,-41.94,0.180
1.95,-41.80,0.180
1.96,-41.67,0.180
1.97,-41.54,0.181
1.99,-41.40,0.181
2.00,-41.27,0.181
2.01,-41.14,0.181
2.03,-41.00,0.181
2.04,-40.87,0.181
2.05,-40.74,0.181
2.07,-40.60,0.181
2.08,-40.47,0.181
2.09,-40.34,0.181
2.11,-40.20,0.181
2.12,-40.07,0.181
2.13,-39.93,0.182
2.15,-39.80,0.182
2.16,-39.67,0.182
2.17,-39.54,0.182
2.19,-39.40,0.182
2.20,-39.27,0.182
2.21,-39.13,0.182
2.23,-39.00,0.182
2.24,-38.87,0.182
2.25,-38.73,0.182
2.27,-38.60,0.182
2.28,-38.47,0.182
2.29,-38.33,0.183
2.31,-38.20,0.183
2.32,-38.07,0.183
2.33,-37.93,0.183
2.35,-37.80,0.183
2.36,-37.67,0.183
2.37,-37.53,0.183
2.39,-37.40,0.183
2.40,-37.26,0.183
2.41,-37.13,0.183
2.43,-37.00,0.183
2.44,-36.86,0.183
2.45,-36.73,0.184
2.47,-36.60,0.184
2.48,-36.47,0.184
2.49,-36.33,0.184
2.51,-36.20,0.184
2.52,-36.06,0.184
2.53,-35.93,0.184
2.55,-35.80,0.184
2.56,-35.66,0.184
2.57,-35.53,0.184
2.59,-35.40,0.184
2.60,-35.26,0.184
2.61,-35.13,0.185
2.63,-35.00,0.185
2.64,-34.86,0.185
2.65,-34.73,0.185
2.67,-34.60,0.185
2.68,-34.46,0.185
2.69,-34.33,0.185
2.71,-34.20,0.185
2.72,-34.06,0.185
2.73,-33.93,0.185
2.75,-33.79,0.185
2.76,-33.66,0.185
2.77,-33.53,0.186
2.79,-33.39,0.186
2.80,-33.26,0.186
2.81,-33.13,0.186
2.83,-32.99,0.186
2.84,-32.86,0.186
2.85,-32.73,0.186
2.87,-32.59,0.186
2.88,-32.46,0.186
2.89,-32.33,0.186
2.91,-32.19,0.186
2.92,-32.06,0.186
2.93,-31.93,0.186
2.95,-31.79,0.187
2.96,-31.66,0.187
2.97,-31.53,0.187
2.99,-31.39,0.187
3.00,-31.26,0.187
3.01,-31.12,0.187
3.03,-30.99,0.187
3.04,-30.86,0.187
3.05,-30.72,0.187
3.07,-30.59,0.187
3.08,-30.46,0.187
3.09,-30.32,0.187
3.11,-30.19,0.188
3.12,-30.06,0.188
3.13,-29.92,0.188
3.15,-29.79,0.188
3.16,-29.66,0.188
3.17,-29.52,0.188
3.19,-29.39,0.188
3.20,-29.26,0.188
3.21,-29.12,0.188
3.23,-28.99,0.188
3.24,-28.86,0.188
3.25,-28.72,0.189
3.27,-28.59,0.189
3.28,-28.45,0.189
3.29,-28.32,0.189
3.31,-28.19,0.189
3.32,-28.05,0.189
3.33,-27.92,0.189
3.35,-27.79,0.189
3.36,-27.65,0.189
3.37,-27.52,0.189
3.39,-27.39,0.189
3.40,-27.25,0.190
3.41,-27.12,0.190
3.43,-26.99,0.190
3.44,-26.85,0.190
3.45,-26.72,0.190
3.47,-26.59,0.190
3.48,-26.45,0.190
3.49,-26.32,0.190
3.51,-26.19,0.190
3.52,-26.05,0.190
3.53,-25.92,0.190
3.55,-25.78,0.191
3.56,-25.65,0.191
3.57,-25.51,0.191
3.59,-25.38,0.191
3.60,-25.25,0.191
3.61,-25.12,0.191
3.63,-24.98,0.191
3.64,-24.85,0.191
3.65,-24.72,0.192
3.67,-24.58,0.192
3.68,-24.45,0.192
3.69,-24.32,0.192
3.71,-24.18,0.192
3.72,-24.05,0.192
3.73,-23.92,0.192
3.75,-23.78,0.192
3.76,-23.65,0.192
3.77,-23.51,0.192
3.79,-23.38,0.192
3.80,-23.25,0.192
3.81,-23.11,0.193
3.83,-22.98,0.193
3.84,-22.85,0.193
3.85,-22.71,0.193
3.87,-22.58,0.193
3.88,-22.45,0.193
3.89,-22.31,0.193
3.91,-22.18,0.193
3.92,-22.05,0.193
3.93,-21.91,0.193
3.95,-21.78,0.193
3.96,-21.65,0.193
3.97,-21.51,0.194
3.99,-21.38,0.194
4.00,-21.25,0.194
4.01,-21.11,0.194
4.03,-20.98,0.194
4.04,-20.85,0.194
4.05,-20.71,0.194
4.07,-20.58,0.194
4.08,-20.45,0.194
4.09,-20.31,0.194
4.11,-20.18,0.195
4.12,-20.04,0.195
4.13,-19.91,0.195
4.15,-19.78,0.195
4.16,-19.65,0.195
4.17,-19.51,0.195
4.19,-19.38,0.195
4.20,-19.25,0.195
4.21,-19.11,0.195
4.23,-18.98,0.195
4.24,-18.84,0.196
4.25,-18.71,0.196
4.27,-18.58,0.196
4.28,-18.44,0.196
4.29,-18.31,0.196
4.31,-18.18,0.196
4.32,-18.04,0.196
4.33,-17.91,0.196
4.35,-17.78,0.196
4.36,-17.64,0.197
4.37,-17.51,0.197
4.39,-17.38,0.197
4.40,-17.24,0.197
4.41,-17.11,0.197
4.43,-16.98,0.197
4.44,-16.84,0.197
4.45,-16.71,0.197
4.47,-16.58,0.197
4.48,-16.44,0.197
4.49,-16.31,0.198
4.51,-16.18,0.198
4.52,-16.04,0.198
4.53,-15.91,0.198
4.55,-15.78,0.198
4.56,-15.64,0.198
4.57,-15.51,0.198
4.59,-15.38,0.198
4.60,-15.24,0.198
4.61,-15.11,0.199
4.63,-14.98,0.199
4.64,-14.84,0.199
4.65,-14.71,0.199
4.67,-14.58,0.199
4.68,-14.44,0.199
4.69,-14.31,0.199
4.71,-14.18,0.199
4.72,-14.04,0.199
4.73,-13.91,0.200
4.75,-13.77,0.200
4.76,-13.64,0.200
4.77,-13.51,0.200
4.79,-13.37,0.200
4.80,-13.24,0.200
4.81,-13.11,0.200
4.83,-12.97,0.201
4.84,-12.84,0.201
4.85,-12.71,0.201
4.87,-12.57,0.201
4.88,-12.44,0.201
4.89,-12.31,0.201
4.91,-12.17,0.201
4.92,-12.04,0.201
4.93,-11.91,0.201
4.95,-11.77,0.201
4.96,-11.64,0.201
4.97,-11.51,0.202
4.99,-11.37,0.202
5.00,-11.24,0.202
5.01,-11.11,0.202
5.03,-10.98,0.202
5.04,-10.84,0.202
5.05,-10.71,0.202
5.07,-10.57,0.202
5.08,-10.44,0.203
5.09,-10.31,0.203
5.11,-10.17,0.203
5.12,-10.04,0.203
5.13,-9.91,0.203
5.15,-9.77,0.203
5.16,-9.64,0.203
5.17,-9.51,0.203
5.19,-9.37,0.204
5.20,-9.24,0.204
5.21,-9.10,0.204
5.23,-8.97,0.204
5.24,-8.84,0.204
5.25,-8.71,0.204
5.27,-8.57,0.204
5.28,-8.44,0.204
5.29,-8.31,0.205
5.31,-8.17,0.205
5.32,-8.04,0.205
5.33,-7.90,0.205
5.35,-7.77,0.205
5.36,-7.64,0.205
5.37,-7.50,0.205
5.39,-7.37,0.205
5.40,-7.24,0.206
5.41,-7.10,0.206
5.43,-6.97,0.206
5.44,-6.84,0.206
5.45,-6.70,0.206
5.47,-6.57,0.206
5.48,-6.44,0.206
5.49,-6.30,0.206
5.51,-6.17,0.207
5.52,-6.04,0.207
5.53,-5.90,0.207
5.55,-5.77,0.207
5.56,-5.64,0.207
5.57,-5.50,0.207
5.59,-5.37,0.207
5.60,-5.24,0.207
5.61,-5.10,0.208
5.63,-4.97,0.208
5.64,-4.84,0.208
5.65,-4.70,0.208
5.67,-4.57,0.208
5.68,-4.44,0.208
5.69,-4.30,0.208
5.71,-4.17,0.208
5.72,-4.03,0.209
5.73,-3.90,0.209
5.75,-3.77,0.209
5.76,-3.63,0.209
5.77,-3.50,0.209
5.79,-3.37,0.209
5.80,-3.23,0.209
5.81,-3.10,0.210
5.83,-2.97,0.210
5.84,-2.83,0.210
5.85,-2.70,0.210
5.87,-2.57,0.210
5.88,-2.43,0.210
5.89,-2.30,0.210
5.91,-2.17,0.210
5.92,-2.03,0.211
5.93,-1.90,0.211
5.95,-1.77,0.211
5.96,-1.63,0.211
5.97,-1.50,0.211
5.99,-1.37,0.211
6.00,-1.23,0.211
6.01,-1.10,0.212
6.03,-0.97,0.212
6.04,-0.83,0.212
6.05,-0.70,0.212
6.07,-0.57,0.212
6.08,-0.43,0.212
6.09,-0.30,0.212
6.11,-0.17,0.212
6.12,-0.03,0.213
6.13,0.10,0.213
6.15,0.24,0.213
6.16,0.37,0.213
6.17,0.50,0.213
6.19,0.64,0.213
6.20,0.77,0.213
6.21,0.90,0.214
6.23,1.04,0.214
6.24,1.17,0.214
6.25,1.30,0.214
6.27,1.43,0.214
6.28,1.57,0.214
6.29,1.70,0.214
6.31,1.84,0.215
6.32,1.97,0.215
6.33,2.10,0.215
6.35,2.24,0.215
6.36,2.37,0.215
6.37,2.50,0.215
6.39,2.64,0.215
6.40,2.77,0.216
6.41,2.90,0.216
6.43,3.04,0.216
6.44,3.17,0.216
6.45,3.31,0.216
6.47,3.44,0.216
6.48,3.57,0.216
6.49,3.71,0.217
6.51,3.84,0.217
6.52,3.97,0.217
6.53,4.11,0.217
6.55,4.24,0.217
6.56,4.37,0.217
6.57,4.51,0.217
6.59,4.64,0.218
6.60,4.77,0.218
6.61,4.91,0.218
6.63,5.04,0.218
6.64,5.17,0.218
6.65,5.30,0.218
6.67,5.44,0.218
6.68,5.57,0.219
6.69,5.71,0.219
6.71,5.84,0.219
6.72,5.97,0.219
6.73,6.11,0.219
6.75,6.24,0.219
6.76,6.37,0.220
6.77,6.51,0.220
6.79,6.64,0.220
6.80,6.77,0.220
6.81,6.91,0.220
6.83,7.04,0.220
6.84,7.17,0.221
6.85,7.31,0.221
6.87,7.44,0.221
6.88,7.57,0.221
6.89,7.71,0.221
6.91,7.84,0.221
6.92,7.97,0.222
6.93,8.11,0.222
6.95,8.24,0.222
6.96,8.37,0.222
6.97,8.51,0.222
6.99,8.64,0.222
7.00,8.77,0.223
7.01,8.91,0.223
7.03,9.04,0.223
7.04,9.17,0.223
7.05,9.31,0.223
7.07,9.44,0.223
7.08,9.58,0.224
7.09,9.71,0.224
7.11,9.84,0.224
7.12,9.98,0.224
7.13,10.11,0.224
7.15,10.24,0.224
7.16,10.38,0.225
7.17,10.51,0.225
7.19,10.64,0.225
7.20,10.78,0.225
7.21,10.91,0.225
7.23,11.04,0.226
7.24,11.18,0.226
7.25,11.31,0.226
7.27,11.44,0.226
7.28,11.58,0.226
7.29,11.71,0.226
7.31,11.84,0.227
7.32,11.98,0.227
7.33,12.11,0.227
7.35,12.24,0.227
7.36,12.38,0.227
7.37,12.51,0.227
7.39,12.64,0.228
7.40,12.78,0.228
7.41,12.91,0.228
7.43,13.04,0.228
7.44,13.18,0.228
7.45,13.31,0.229
7.47,13.44,0.229
7.48,13.58,0.229
7.49,13.71,0.229
7.51,13.84,0.229
7.52,13.98,0.229
7.53,14.11,0.230
7.55,14.24,0.230
7.56,14.38,0.230
7.57,14.51,0.230
7.59,14.64,0.230
7.60,14.78,0.231
7.61,14.91,0.231
7.63,15.04,0.231
7.64,15.18,0.231
7.65,15.31,0.231
7.67,15.44,0.232
7.68,15.58,0.232
7.69,15.71,0.232
7.71,15.84,0.232
7.72,15.98,0.232
7.73,16.11,0.233
7.75,16.24,0.233
7.76,16.38,0.233
7.77,16.51,0.233
7.79,16.64,0.233
7.80,16.78,0.234
7.81,16.91,0.234
7.83,17.05,0.234
7.84,17.18,0.234
7.85,17.31,0.234
7.87,17.45,0.235
7.88,17.58,0.235
7.89,17.71,0.235
7.91,17.85,0.235
7.92,17.98,0.236
7.93,18.11,0.236
7.95,18.24,0.236
7.96,18.38,0.236
7.97,18.51,0.236
7.99,18.64,0.236
8.00,18.78,0.237
8.01,18.91,0.237
8.03,19.05,0.237
8.04,19.18,0.237
8.05,19.31,0.237
8.07,19.44,0.238
8.08,19.58,0.238
8.09,19.71,0.238
8.11,19.85,0.238
8.12,19.98,0.239
8.13,20.11,0.239
8.15,20.24,0.239
8.16,20.38,0.239
8.17,20.51,0.239
8.19,20.64,0.240
8.20,20.78,0.240
8.21,20.91,0.240
8.23,21.04,0.240
8.24,21.18,0.241
8.25,21.31,0.241
8.27,21.44,0.241
8.28,21.58,0.241
8.29,21.71,0.242
8.31,21.84,0.242
8.32,21.98,0.242
8.33,22.11,0.242
8.35,22.24,0.242
8.36,22.38,0.243
8.37,22.51,0.243
8.39,22.64,0.243
8.40,22.78,0.243
8.41,22.91,0.244
8.43,23.04,0.244
8.44,23.18,0.244
8.45,23.31,0.244
8.47,23.44,0.245
8.48,23.58,0.245
8.49,23.71,0.245
8.51,23.84,0.246
8.52,23.98,0.246
8.53,24.11,0.246
8.55,24.24,0.246
8.56,24.38,0.247
8.57,24.51,0.247
8.59,24.65,0.247
8.60,24.78,0.247
8.61,24.91,0.248
8.63,25.04,0.248
8.64,25.18,0.248
8.65,25.31,0.249
8.67,25.44,0.249
8.68,25.58,0.249
8.69,25.71,0.249
8.71,25.84,0.250
8.72,25.98,0.250
8.73,26.11,0.250
8.75,26.25,0.250
8.76,26.38,0.251
8.77,26.51,0.251
8.79,26.65,0.251
8.80,26.78,0.252
8.81,26.91,0.252
8.83,27.05,0.252
8.84,27.18,0.252
8.85,27.31,0.253
8.87,27.45,0.253
8.88,27.58,0.253
8.89,27.71,0.254
8.91,27.85,0.254
8.92,27.98,0.254
8.93,28.11,0.255
8.95,28.25,0.255
8.96,28.38,0.255
8.97,28.51,0.255
8.99,28.65,0.256
9.00,28.78,0.256
9.01,28.91,0.256
9.03,29.05,0.257
9.04,29.18,0.257
9.05,29.31,0.257
9.07,29.45,0.258
9.08,29.58,0.258
9.09,29.71,0.259
9.11,29.85,0.259
9.12,29.98,0.259
9.13,30.11,0.259
9.15,30.25,0.260
9.16,30.38,0.260
9.17,30.51,0.260
9.19,30.65,0.261
9.20,30.78,0.261
9.21,30.91,0.261
9.23,31.05,0.262
9.24,31.18,0.262
9.25,31.31,0.262
9.27,31.45,0.263
9.28,31.58,0.263
9.29,31.71,0.263
9.31,31.85,0.264
9.32,31.98,0.264
9.33,32.11,0.264
9.35,32.25,0.264
9.36,32.38,0.265
9.37,32.51,0.265
9.39,32.65,0.266
9.40,32.78,0.266
9.41,32.91,0.266
9.43,33.04,0.267
9.44,33.18,0.267
9.45,33.31,0.268
9.47,33.44,0.268
9.48,33.58,0.268
9.49,33.71,0.269
9.51,33.85,0.269
9.52,33.98,0.270
9.53,34.11,0.270
9.55,34.24,0.270
9.56,34.38,0.271
9.57,34.51,0.271
9.59,34.64,0.272
9.60,34.78,0.272
9.61,34.91,0.273
9.63,35.04,0.273
9.64,35.18,0.273
9.65,35.31,0.274
9.67,35.45,0.274
9.68,35.58,0.275
9.69,35.71,0.275
9.71,35.84,0.276
9.72,35.98,0.276
9.73,36.11,0.277
9.75,36.24,0.277
9.76,36.38,0.278
9.77,36.51,0.278
9.79,36.64,0.279
9.80,36.78,0.279
9.81,36.91,0.280
9.83,37.04,0.280
9.84,37.18,0.280
9.85,37.31,0.281
9.87,37.44,0.281
9.88,37.58,0.282
9.89,37.71,0.282
9.91,37.84,0.283
9.92,37.98,0.283
9.93,38.11,0.283
9.95,38.24,0.284
9.96,38.38,0.285
9.97,38.51,0.285
9.99,38.64,0.286
10.00,38.78,0.286
10.01,38.91,0.287
10.03,39.04,0.288
10.04,39.18,0.288
10.05,39.31,0.289
10.07,39.44,0.290
10.08,39.58,0.290
10.09,39.71,0.290
10.11,39.84,0.291
10.12,39.97,0.292
10.13,40.11,0.293
10.15,40.24,0.293
10.16,40.37,0.294
10.17,40.51,0.295
10.19,40.64,0.295
10.20,40.77,0.296
10.21,40.91,0.296
10.23,41.04,0.297
10.24,41.17,0.298
10.25,41.31,0.298
10.27,41.44,0.299
10.28,41.57,0.300
10.29,41.71,0.301
10.31,41.84,0.301
10.32,41.97,0.303
10.33,42.11,0.303
10.35,42.24,0.304
10.36,42.37,0.305
10.37,42.50,0.305
10.39,42.64,0.306
10.40,42.77,0.307
10.41,42.90,0.308
10.43,43.04,0.309
10.44,43.17,0.310
10.45,43.30,0.310
10.47,43.44,0.311
10.48,43.57,0.312
10.49,43.70,0.313
10.51,43.83,0.314
10.52,43.97,0.315
10.53,44.10,0.316
10.55,44.23,0.317
10.56,44.37,0.318
10.57,44.50,0.319
10.59,44.63,0.320
10.60,44.76,0.321
10.61,44.90,0.322
10.63,45.03,0.324
10.64,45.16,0.324
10.65,45.30,0.326
10.67,45.43,0.327
10.68,45.56,0.329
10.69,45.70,0.330
10.71,45.83,0.331
10.72,45.96,0.333
10.73,46.09,0.334
10.75,46.23,0.336
10.76,46.36,0.338
10.77,46.49,0.339
10.79,46.62,0.340
10.80,46.76,0.342
10.81,46.89,0.344
10.83,47.02,0.346
10.84,47.16,0.348
10.85,47.29,0.350
10.87,47.42,0.352
10.88,47.55,0.354
10.89,47.69,0.356
10.91,47.82,0.359
10.92,47.95,0.361
10.93,48.08,0.364
10.95,48.21,0.367
10.96,48.35,0.369
10.97,48.48,0.372
10.99,48.61,0.376
11.00,48.74,0.378
11.01,48.87,0.383
11.03,49.01,0.386
11.04,49.14,0.390
11.05,49.27,0.395
11.07,49.40,0.398
11.08,49.53,0.403
11.09,49.66,0.407
11.11,49.79,0.412
11.12,49.93,0.417
11.13,50.06,0.422
11.15,50.19,0.426
11.16,50.32,0.432
11.17,50.45,0.436
11.19,50.58,0.442
11.20,50.71,0.445
11.21,50.84,0.450
11.23,50.97,0.453
11.24,51.10,0.456
11.25,51.23,0.458
11.27,51.37,0.460
11.28,51.50,0.460
11.29,51.63,0.461
11.31,51.76,0.461
11.32,51.90,0.460
11.33,52.03,0.460
11.35,52.16,0.459
11.36,52.30,0.457
11.37,52.43,0.454
11.39,52.57,0.450
11.40,52.70,0.447
11.41,52.84,0.443
11.43,52.97,0.440
11.44,53.11,0.437
11.45,53.24,0.434
11.47,53.38,0.431
11.48,53.51,0.428
11.49,53.64,0.425
11.51,53.78,0.422
11.52,53.92,0.420
11.53,54.05,0.417
11.55,54.19,0.417
11.56,54.32,0.415
11.57,54.46,0.413
11.59,54.59,0.412
11.60,54.73,0.411
11.61,54.86,0.410
11.63,54.99,0.409
11.64,55.13,0.409
11.65,55.26,0.408
11.67,55.40,0.408
11.68,55.53,0.408
11.69,55.66,0.408
11.71,55.80,0.408
11.72,55.93,0.408
11.73,56.06,0.407
11.75,56.20,0.407
11.76,56.33,0.407
11.77,56.47,0.407
11.79,56.60,0.407
11.80,56.73,0.407
11.81,56.87,0.407
11.83,57.00,0.407
11.84,57.13,0.408
11.85,57.27,0.408
11.87,57.40,0.408
11.88,57.53,0.408
11.89,57.66,0.409
11.91,57.80,0.409
11.92,57.93,0.409
11.93,58.06,0.410
11.95,58.20,0.411
11.96,58.33,0.412
11.97,58.46,0.412
11.99,58.60,0.413
12.00,58.73,0.414
12.01,58.86,0.414
12.03,59.00,0.415
12.04,59.13,0.416
12.05,59.26,0.417
12.07,59.40,0.418
12.08,59.53,0.419
12.09,59.66,0.420
12.11,59.80,0.421
12.12,59.93,0.421
12.13,60.06,0.422
12.15,60.19,0.423
12.16,60.33,0.424
12.17,60.46,0.425
12.19,60.59,0.426
12.20,60.73,0.427
12.21,60.86,0.427
12.23,60.99,0.428
12.24,61.13,0.430
12.25,61.26,0.430
12.27,61.39,0.431
12.28,61.52,0.432
12.29,61.66,0.433
12.31,61.79,0.434
12.32,61.92,0.435
12.33,62.06,0.436
12.35,62.19,0.437
12.36,62.32,0.439
12.37,62.45,0.440
12.39,62.59,0.441
12.40,62.72,0.442
12.41,62.85,0.443
12.43,62.99,0.444
12.44,63.12,0.445
12.45,63.25,0.447
12.47,63.39,0.448
12.48,63.52,0.449
12.49,63.65,0.450
12.51,63.78,0.451
12.52,63.92,0.453
12.53,64.05,0.454
12.55,64.18,0.455
12.56,64.32,0.457
12.57,64.45,0.458
12.59,64.58,0.459
12.60,64.72,0.461
12.61,64.85,0.462
12.63,64.98,0.464
12.64,65.11,0.465
12.65,65.25,0.467
12.67,65.38,0.469
12.68,65.51,0.470
12.69,65.64,0.472
12.71,65.78,0.473
12.72,65.91,0.475
12.73,66.04,0.477
12.75,66.17,0.479
12.76,66.31,0.480
12.77,66.44,0.483
12.79,66.57,0.485
12.80,66.70,0.487
12.81,66.84,0.489
12.83,66.97,0.491
12.84,67.10,0.495
12.85,67.23,0.496
12.87,67.37,0.499
12.88,67.50,0.502
12.89,67.63,0.505
12.91,67.76,0.507
12.92,67.90,0.510
12.93,68.03,0.514
12.95,68.16,0.517
12.96,68.29,0.520
12.97,68.42,0.524
12.99,68.55,0.528
13.00,68.69,0.532
13.01,68.82,0.537
13.03,68.95,0.542
13.04,69.08,0.546
13.05,69.21,0.551
13.07,69.34,0.556
13.08,69.47,0.563
13.09,69.60,0.569
13.11,69.73,0.575
13.12,69.86,0.583
13.13,69.99,0.591
13.15,70.12,0.599
13.16,70.25,0.608
13.17,70.38,0.618
13.19,70.51,0.628
13.20,70.64,0.640
13.21,70.77,0.653
13.23,70.89,0.667
13.24,71.02,0.681
13.25,71.15,0.696
13.27,71.27,0.714
13.28,71.40,0.733
13.29,71.52,0.754
13.31,71.64,0.777
13.32,71.77,0.801
13.33,71.89,0.824
13.35,72.01,0.848
13.36,72.13,0.873
13.37,72.25,0.897
13.39,72.38,0.920
13.40,72.50,0.941
13.41,72.62,0.958
13.43,72.75,0.974
13.44,72.87,0.985
13.45,72.99,0.993
13.47,73.12,0.997
13.48,73.25,0.996
13.49,73.38,0.992
13.51,73.51,0.985
13.52,73.65,0.974
13.53,73.78,0.959
13.55,73.92,0.942
13.56,74.06,0.922
13.57,74.20,0.899
13.59,74.34,0.875
13.60,74.49,0.850
13.61,74.63,0.821
13.63,74.78,0.793
13.64,74.93,0.764
13.65,75.07,0.736
13.67,75.22,0.709
13.68,75.37,0.680
13.69,75.52,0.653
13.71,75.67,0.629
13.72,75.81,0.608
13.73,75.96,0.588
13.75,76.11,0.567
13.76,76.25,0.549
13.77,76.40,0.535
13.79,76.54,0.521
13.80,76.68,0.510
13.81,76.82,0.499
13.83,76.96,0.490
13.84,77.10,0.483
13.85,77.24,0.476
13.87,77.38,0.469
13.88,77.52,0.464
13.89,77.66,0.460
13.91,77.79,0.456
13.92,77.93,0.454
13.93,78.06,0.453
13.95,78.20,0.450
13.96,78.34,0.450
13.97,78.47,0.448
13.99,78.61,0.448
14.00,78.74,0.447
14.01,78.87,0.447
14.03,79.01,0.448
14.04,79.14,0.448
14.05,79.27,0.448
14.07,79.41,0.449
14.08,79.54,0.450
14.09,79.67,0.450
14.11,79.81,0.451
14.12,79.94,0.452
14.13,80.07,0.453
14.15,80.20,0.454
14.16,80.34,0.455
14.17,80.47,0.456
14.19,80.60,0.456
14.20,80.74,0.457
14.21,80.87,0.458
14.23,81.00,0.460
14.24,81.13,0.462
14.25,81.27,0.464
14.27,81.40,0.465
14.28,81.53,0.468
14.29,81.66,0.469
14.31,81.80,0.471
14.32,81.93,0.472
14.33,82.06,0.474
14.35,82.20,0.476
14.36,82.33,0.477
14.37,82.46,0.479
14.39,82.59,0.481
14.40,82.73,0.482
14.41,82.86,0.484
14.43,82.99,0.485
14.44,83.12,0.486
14.45,83.26,0.488
14.47,83.39,0.489
14.48,83.52,0.491
14.49,83.66,0.493
14.51,83.79,0.494
14.52,83.92,0.496
14.53,84.05,0.497
14.55,84.19,0.498
14.56,84.32,0.500
14.57,84.45,0.501
14.59,84.59,0.503
14.60,84.72,0.504
14.61,84.85,0.505
14.63,84.98,0.507
14.64,85.11,0.508
14.65,85.25,0.509
14.67,85.38,0.510
14.68,85.51,0.511
14.69,85.65,0.512
14.71,85.78,0.514
14.72,85.91,0.515
14.73,86.04,0.516
14.75,86.18,0.517
14.76,86.31,0.518
14.77,86.44,0.519
14.79,86.58,0.521
14.80,86.71,0.522
14.81,86.84,0.523
14.83,86.97,0.524
14.84,87.11,0.526
14.85,87.24,0.526
14.87,87.37,0.527
14.88,87.51,0.528
14.89,87.64,0.529
14.91,87.77,0.531
14.92,87.90,0.532
14.93,88.04,0.533
14.95,88.17,0.533
14.96,88.30,0.535
14.97,88.44,0.536
14.99,88.57,0.537
15.00,88.70,0.539
15.01,88.84,0.540
15.03,88.97,0.541
15.04,89.10,0.542
15.05,89.23,0.544
15.07,89.37,0.545
15.08,89.50,0.546
15.09,89.63,0.547
15.11,89.76,0.548
15.12,89.90,0.549
15.13,90.03,0.550
15.15,90.16,0.550
15.16,90.30,0.551
15.17,90.43,0.552
15.19,90.56,0.553
15.20,90.70,0.554
15.21,90.83,0.556
15.23,90.96,0.557
15.24,91.10,0.558
15.25,91.23,0.560
15.27,91.36,0.561
15.28,91.50,0.562
15.29,91.63,0.563
15.31,91.76,0.564
15.32,91.89,0.565
15.33,92.03,0.566
15.35,92.16,0.567
15.36,92.29,0.568
15.37,92.43,0.569
15.39,92.56,0.570
15.40,92.69,0.571
15.41,92.82,0.572
15.43,92.96,0.573
15.44,93.09,0.574
15.45,93.22,0.575
15.47,93.36,0.576
15.48,93.49,0.577
15.49,93.62,0.578
15.51,93.75,0.580
15.52,93.89,0.581
15.53,94.02,0.582
15.55,94.15,0.583
15.56,94.29,0.583
15.57,94.42,0.585
15.59,94.55,0.586
15.60,94.69,0.587
15.61,94.82,0.588
15.63,94.95,0.589
15.64,95.09,0.590
15.65,95.22,0.591
15.67,95.35,0.592
15.68,95.48,0.593
15.69,95.62,0.594
15.71,95.75,0.595
15.72,95.88,0.596
15.73,96.01,0.597
15.75,96.15,0.599
15.76,96.28,0.600
15.77,96.41,0.601
15.79,96.55,0.602
15.80,96.68,0.603
15.81,96.81,0.605
15.83,96.95,0.606
15.84,97.08,0.607
15.85,97.21,0.608
15.87,97.34,0.609
15.88,97.48,0.609
15.89,97.61,0.610
15.91,97.74,0.611
15.92,97.88,0.612
15.93,98.01,0.613
15.95,98.14,0.613
15.96,98.27,0.614
15.97,98.41,0.615
15.99,98.54,0.617
16.00,98.67,0.618
16.01,98.81,0.619
16.03,98.94,0.620
16.04,99.07,0.621
16.05,99.21,0.622
16.07,99.34,0.622
16.08,99.47,0.624
16.09,99.61,0.625
16.11,99.74,0.626
16.12,99.87,0.627
16.13,100.01,0.628
16.15,100.14,0.628
16.16,100.27,0.629
16.17,100.40,0.630
16.19,100.54,0.631
16.20,100.67,0.632
16.21,100.80,0.633
16.23,100.94,0.633
16.24,101.07,0.634
16.25,101.20,0.635
16.27,101.33,0.637
16.28,101.47,0.637
16.29,101.60,0.638
16.31,101.73,0.639
16.32,101.87,0.640
16.33,102.00,0.641
16.35,102.13,0.642
16.36,102.27,0.643
16.37,102.40,0.644
16.39,102.53,0.644
16.40,102.67,0.645
16.41,102.80,0.646
16.43,102.93,0.647
16.44,103.06,0.647
16.45,103.20,0.648
16.47,103.33,0.649
16.48,103.46,0.649
16.49,103.60,0.650
16.51,103.73,0.651
16.52,103.86,0.651
16.53,104.00,0.652
16.55,104.13,0.653
16.56,104.26,0.653
16.57,104.40,0.654
16.59,104.53,0.655
16.60,104.66,0.656
16.61,104.80,0.656
16.63,104.93,0.657
16.64,105.06,0.657
16.65,105.20,0.658
16.67,105.33,0.658
16.68,105.46,0.659
16.69,105.59,0.659
16.71,105.73,0.659
16.72,105.86,0.660
16.73,105.99,0.660
16.75,106.13,0.660
16.76,106.26,0.660
16.77,106.39,0.661
16.79,106.53,0.661
16.80,106.66,0.661
16.81,106.79,0.661
16.83,106.93,0.662
16.84,107.06,0.662
16.85,107.19,0.662
16.87,107.33,0.662
16.88,107.46,0.662
16.89,107.59,0.662
16.91,107.73,0.663
16.92,107.86,0.663
16.93,107.99,0.663
16.95,108.13,0.663
16.96,108.26,0.663
16.97,108.40,0.663
16.99,108.53,0.663
17.00,108.66,0.663
17.01,108.80,0.663
17.03,108.93,0.663
17.04,109.06,0.663
17.05,109.20,0.663
17.07,109.33,0.663
17.08,109.46,0.663
17.09,109.60,0.663
17.11,109.73,0.663
17.12,109.87,0.663
17.13,110.00,0.663
17.15,110.13,0.663
17.16,110.27,0.662
17.17,110.40,0.662
17.19,110.53,0.660
17.20,110.67,0.660
17.21,110.80,0.658
17.23,110.94,0.657
17.24,111.07,0.655
17.25,111.20,0.654
17.27,111.34,0.652
17.28,111.47,0.649
17.29,111.61,0.644
17.31,111.74,0.639
17.32,111.88,0.634
17.33,112.01,0.630
17.35,112.15,0.625
17.36,112.28,0.619
17.37,112.42,0.613
17.39,112.56,0.604
17.40,112.69,0.595
17.41,112.83,0.585
17.43,112.97,0.575
17.44,113.11,0.566
17.45,113.24,0.556
17.47,113.38,0.545
17.48,113.52,0.534
17.49,113.66,0.524
17.51,113.80,0.516
17.52,113.94,0.508
17.53,114.07,0.500
17.55,114.21,0.493
17.56,114.35,0.485
17.57,114.49,0.477
17.59,114.63,0.471
17.60,114.76,0.464
17.61,114.90,0.455
17.63,115.04,0.449
17.64,115.17,0.441
17.65,115.31,0.432
17.67,115.45,0.421
17.68,115.59,0.414
17.69,115.73,0.406
17.71,115.87,0.398
17.72,116.00,0.392
17.73,116.14,0.387
17.75,116.28,0.381
17.76,116.41,0.375
17.77,116.55,0.370
17.79,116.69,0.366
17.80,116.82,0.363
17.81,116.96,0.360
17.83,117.10,0.357
17.84,117.23,0.355
17.85,117.37,0.353
17.87,117.50,0.352
17.88,117.63,0.350
17.89,117.77,0.349
17.91,117.90,0.348
17.92,118.04,0.347
17.93,118.17,0.346
17.95,118.31,0.345
17.96,118.44,0.344
17.97,118.57,0.344
17.99,118.71,0.344
18.00,118.84,0.343
18.01,118.98,0.343
18.03,119.11,0.343
18.04,119.24,0.343
18.05,119.38,0.342
18.07,119.51,0.342
18.08,119.64,0.342
18.09,119.78,0.342
18.11,119.91,0.342
18.12,120.05,0.342
18.13,120.18,0.342
18.15,120.31,0.342
18.16,120.45,0.342
18.17,120.58,0.342
18.19,120.71,0.342
18.20,120.85,0.342
18.21,120.98,0.342
18.23,121.11,0.342
18.24,121.25,0.342
18.25,121.38,0.342
18.27,121.51,0.342
18.28,121.65,0.342
18.29,121.78,0.342
18.31,121.91,0.345
18.32,122.01,1.074
18.33,121.82,2.506
18.35,121.72,2.420
18.36,121.73,2.251
18.37,121.80,2.144
18.39,121.89,2.126
18.40,121.99,2.113
18.41,122.11,2.083
18.43,122.24,2.043
18.44,122.37,1.999
18.45,122.52,1.964
18.47,122.66,1.960
18.48,122.80,1.960
18.49,122.94,1.947
18.51,123.08,1.930
18.52,123.22,1.901
18.53,123.36,1.867
18.55,123.51,1.831
18.56,123.66,1.797
18.57,123.81,1.762
18.59,123.96,1.728
18.60,124.11,1.691
18.61,124.26,1.653
18.63,124.41,1.614
18.64,124.56,1.576
18.65,124.72,1.540
18.67,124.87,1.505
18.68,125.02,1.469
18.69,125.17,1.437
18.71,125.32,1.407
18.72,125.47,1.378
18.73,125.62,1.351
18.75,125.77,1.324
18.76,125.92,1.298
18.77,126.07,1.273
18.79,126.22,1.248
18.80,126.36,1.225
18.81,126.51,1.203
18.83,126.65,1.182
18.84,126.80,1.162
18.85,126.94,1.141
18.87,127.09,1.123
18.88,127.23,1.105
18.89,127.38,1.087
18.91,127.52,1.068
18.92,127.66,1.057
18.93,127.80,1.061
18.95,127.94,
18.96,128.08,
18.97,128.22,
18.99,,
18.99,,

[step]
Ramp 10.00 °C/min to -60.00 °C
Time,Temperature,Heat Flow (Normalized)
min,°C,W/g
20.99,130.12,0.024
21.01,130.12,0.021
21.02,130.12,0.019
21.03,130.12,0.018
21.05,130.11,0.018
21.06,130.09,0.018
21.07,130.06,0.018
21.09,130.01,0.014
21.10,129.95,-0.002
21.11,129.87,-0.024
21.13,129.79,-0.051
21.14,129.70,-0.081
21.15,129.60,-0.112
21.17,129.49,-0.141
21.18,129.39,-0.166
21.19,129.28,-0.188
21.21,129.16,-0.208
21.22,129.05,-0.223
21.23,128.93,-0.236
21.25,128.81,-0.249
21.26,128.69,-0.258
21.27,128.57,-0.267
21.29,128.45,-0.275
21.30,128.32,-0.282
21.31,128.20,-0.287
21.33,128.07,-0.294
21.34,127.94,-0.299
21.35,127.82,-0.304
21.37,127.69,-0.307
21.38,127.56,-0.311
21.39,127.43,-0.314
21.41,127.30,-0.317
21.42,127.17,-0.319
21.43,127.04,-0.321
21.45,126.91,-0.322
21.46,126.78,-0.324
21.47,126.65,-0.326
21.49,126.52,-0.326
21.50,126.39,-0.326
21.51,126.25,-0.326
21.53,126.12,-0.328
21.54,125.99,-0.330
21.55,125.86,-0.332
21.57,125.73,-0.332
21.58,125.60,-0.333
21.59,125.46,-0.333
21.61,125.33,-0.333
21.62,125.20,-0.334
21.63,125.07,-0.334
21.65,124.94,-0.334
21.66,124.80,-0.334
21.67,124.67,-0.334
21.69,124.54,-0.335
21.70,124.41,-0.335
21.71,124.27,-0.335
21.73,124.14,-0.335
21.74,124.01,-0.336
21.75,123.87,-0.336
21.77,123.74,-0.336
21.78,123.61,-0.336
21.79,123.48,-0.337
21.81,123.34,-0.337
21.82,123.21,-0.337
21.83,123.08,-0.337
21.85,122.95,-0.337
21.86,122.81,-0.337
21.87,122.68,-0.337
21.89,122.55,-0.337
21.90,122.42,-0.337
21.91,122.28,-0.337
21.93,122.15,-0.337
21.94,122.02,-0.337
21.95,121.88,-0.337
21.97,121.75,-0.337
21.98,121.62,-0.338
21.99,121.49,-0.338
22.01,121.35,-0.338
22.02,121.22,-0.338
22.03,121.09,-0.338
22.05,120.95,-0.338
22.06,120.82,-0.338
22.07,120.69,-0.338
22.09,120.56,-0.338
22.10,120.42,-0.338
22.11,120.29,-0.338
22.13,120.16,-0.338
22.14,120.02,-0.337
22.15,119.89,-0.337
22.17,119.76,-0.337
22.18,119.62,-0.336
22.19,119.49,-0.336
22.21,119.36,-0.336
22.22,119.22,-0.336
22.23,119.09,-0.336
22.25,118.96,-0.336
22.26,118.82,-0.336
22.27,118.69,-0.335
22.29,118.56,-0.336
22.30,118.42,-0.336
22.31,118.29,-0.334
22.33,118.16,-0.332
22.34,118.02,-0.331
22.35,117.89,-0.331
22.37,117.76,-0.331
22.38,117.62,-0.331
22.39,117.49,-0.331
22.41,117.36,-0.331
22.42,117.22,-0.330
22.43,117.09,-0.330
22.45,116.96,-0.330
22.46,116.82,-0.330
22.47,116.69,-0.330
22.49,116.56,-0.330
22.50,116.42,-0.330
22.51,116.29,-0.330
22.53,116.16,-0.330
22.54,116.03,-0.330
22.55,115.89,-0.330
22.57,115.76,-0.330
22.58,115.62,-0.330
22.59,115.49,-0.330
22.61,115.36,-0.330
22.62,115.23,-0.330
22.63,115.09,-0.331
22.65,114.96,-0.330
22.66,114.83,-0.329
22.67,114.69,-0.329
22.69,114.56,-0.328
22.70,114.43,-0.328
22.71,114.29,-0.328
22.73,114.16,-0.328
22.74,114.03,-0.328
22.75,113.89,-0.328
22.77,113.76,-0.328
22.78,113.63,-0.328
22.79,113.49,-0.328
22.81,113.36,-0.328
22.82,113.23,-0.328
22.83,113.09,-0.328
22.85,112.96,-0.327
22.86,112.83,-0.327
22.87,112.69,-0.327
22.89,112.56,-0.327
22.90,112.43,-0.327
22.91,112.29,-0.327
22.93,112.16,-0.327
22.94,112.03,-0.327
22.95,111.89,-0.327
22.97,111.76,-0.327
22.98,111.63,-0.327
22.99,111.49,-0.327
23.01,111.36,-0.327
23.02,111.23,-0.330
23.03,111.09,-0.328
23.05,110.96,-0.324
23.06,110.83,-0.322
23.07,110.69,-0.322
23.09,110.56,-0.322
23.10,110.43,-0.323
23.11,110.29,-0.323
23.13,110.16,-0.323
23.14,110.03,-0.323
23.15,109.89,-0.323
23.17,109.76,-0.323
23.18,109.63,-0.323
23.19,109.49,-0.323
23.21,109.36,-0.323
23.22,109.23,-0.323
23.23,109.10,-0.323
23.25,108.96,-0.323
23.26,108.83,-0.323
23.27,108.69,-0.323
23.29,108.56,-0.323
23.30,108.43,-0.323
23.31,108.30,-0.323
23.33,108.16,-0.323
23.34,108.03,-0.323
23.35,107.90,-0.323
23.37,107.76,-0.323
23.38,107.63,-0.323
23.39,107.50,-0.323
23.41,107.36,-0.323
23.42,107.23,-0.323
23.43,107.09,-0.323
23.45,106.96,-0.323
23.46,106.83,-0.323
23.47,106.70,-0.324
23.49,106.56,-0.327
23.50,106.43,-0.325
23.51,106.30,-0.320
23.53,106.16,-0.318
23.54,106.03,-0.317
23.55,105.89,-0.317
23.57,105.76,-0.317
23.58,105.63,-0.317
23.59,105.50,-0.318
23.61,105.36,-0.318
23.62,105.23,-0.318
23.63,105.09,-0.319
23.65,104.96,-0.319
23.66,104.83,-0.319
23.67,104.70,-0.319
23.69,104.56,-0.319
23.70,104.43,-0.319
23.71,104.30,-0.319
23.73,104.16,-0.320
23.74,104.03,-0.320
23.75,103.90,-0.320
23.77,103.76,-0.320
23.78,103.63,-0.320
23.79,103.50,-0.320
23.81,103.36,-0.320
23.82,103.23,-0.320
23.83,103.10,-0.320
23.85,102.96,-0.320
23.86,102.83,-0.320
23.87,102.70,-0.320
23.89,102.56,-0.320
23.90,102.43,-0.320
23.91,102.29,-0.320
23.93,102.16,-0.320
23.94,102.03,-0.320
23.95,101.90,-0.320
23.97,101.76,-0.320
23.98,101.63,-0.320
23.99,101.50,-0.320
24.01,101.36,-0.320
24.02,101.23,-0.320
24.03,101.10,-0.320
24.05,100.96,-0.320
24.06,100.83,-0.324
24.07,100.70,-0.321
24.09,100.56,-0.317
24.10,100.43,-0.315
24.11,100.30,-0.314
24.13,100.16,-0.313
24.14,100.03,-0.313
24.15,99.89,-0.313
24.17,99.76,-0.313
24.18,99.63,-0.313
24.19,99.49,-0.313
24.21,99.36,-0.313
24.22,99.23,-0.313
24.23,99.09,-0.313
24.25,98.96,-0.312
24.26,98.83,-0.312
24.27,98.69,-0.312
24.29,98.56,-0.312
24.30,98.43,-0.312
24.31,98.29,-0.312
24.33,98.16,-0.312
24.34,98.03,-0.312
24.35,97.89,-0.312
24.37,97.76,-0.312
24.38,97.63,-0.312
24.39,97.50,-0.313
24.41,97.36,-0.313
24.42,97.23,-0.313
24.43,97.10,-0.313
24.45,96.96,-0.313
24.46,96.83,-0.313
24.47,96.70,-0.314
24.49,96.56,-0.314
24.50,96.43,-0.314
24.51,96.30,-0.314
24.53,96.16,-0.314
24.54,96.03,-0.314
24.55,95.90,-0.314
24.57,95.76,-0.314
24.58,95.63,-0.314
24.59,95.50,-0.314
24.61,95.37,-0.314
24.62,95.23,-0.314
24.63,95.10,-0.314
24.65,94.97,-0.314
24.66,94.83,-0.314
24.67,94.70,-0.314
24.69,94.56,-0.314
24.70,94.43,-0.314
24.71,94.30,-0.314
24.73,94.16,-0.314
24.74,94.03,-0.314
24.75,93.90,-0.314
24.77,93.76,-0.314
24.78,93.63,-0.314
24.79,93.50,-0.314
24.81,93.36,-0.314
24.82,93.23,-0.314
24.83,93.10,-0.314
24.85,92.97,-0.314
24.86,92.83,-0.314
24.87,92.70,-0.314
24.89,92.56,-0.314
24.90,92.43,-0.314
24.91,92.30,-0.313
24.93,92.16,-0.313
24.94,92.03,-0.313
24.95,91.90,-0.313
24.97,91.76,-0.313
24.98,91.63,-0.313
24.99,91.50,-0.313
25.01,91.36,-0.313
25.02,91.23,-0.313
25.03,91.10,-0.313
25.05,90.96,-0.312
25.06,90.83,-0.312
25.07,90.70,-0.312
25.09,90.56,-0.312
25.10,90.43,-0.312
25.11,90.30,-0.312
25.13,90.16,-0.312
25.14,90.03,-0.312
25.15,89.90,-0.311
25.17,89.76,-0.311
25.18,89.63,-0.311
25.19,89.50,-0.311
25.21,89.36,-0.311
25.22,89.23,-0.311
25.23,89.10,-0.311
25.25,88.96,-0.310
25.26,88.83,-0.310
25.27,88.70,-0.310
25.29,88.56,-0.310
25.30,88.43,-0.310
25.31,88.30,-0.310
25.33,88.16,-0.309
25.34,88.03,-0.309
25.35,87.90,-0.309
25.37,87.76,-0.310
25.38,87.63,-0.314
25.39,87.50,-0.313
25.41,87.36,-0.308
25.42,87.23,-0.306
25.43,87.10,-0.305
25.45,86.96,-0.304
25.46,86.83,-0.304
25.47,86.70,-0.304
25.49,86.56,-0.303
25.50,86.43,-0.303
25.51,86.29,-0.303
25.53,86.16,-0.303
25.54,86.03,-0.303
25.55,85.89,-0.302
25.57,85.76,-0.302
25.58,85.63,-0.302
25.59,85.49,-0.302
25.61,85.36,-0.302
25.62,85.23,-0.301
25.63,85.09,-0.301
25.65,84.96,-0.301
25.66,84.83,-0.301
25.67,84.69,-0.301
25.69,84.56,-0.301
25.70,84.43,-0.300
25.71,84.29,-0.300
25.73,84.16,-0.300
25.74,84.03,-0.300
25.75,83.89,-0.300
25.77,83.76,-0.300
25.78,83.63,-0.299
25.79,83.49,-0.299
25.81,83.36,-0.299
25.82,83.23,-0.299
25.83,83.09,-0.299
25.85,82.96,-0.298
25.86,82.83,-0.298
25.87,82.69,-0.298
25.89,82.56,-0.298
25.90,82.43,-0.298
25.91,82.29,-0.298
25.93,82.16,-0.297
25.94,82.03,-0.297
25.95,81.89,-0.297
25.97,81.76,-0.297
25.98,81.63,-0.297
25.99,81.49,-0.297
26.01,81.36,-0.296
26.02,81.23,-0.296
26.03,81.09,-0.296
26.05,80.96,-0.296
26.06,80.83,-0.296
26.07,80.69,-0.295
26.09,80.56,-0.295
26.10,80.42,-0.295
26.11,80.29,-0.295
26.13,80.16,-0.295
26.14,80.03,-0.295
26.15,79.89,-0.294
26.17,79.76,-0.294
26.18,79.62,-0.294
26.19,79.49,-0.294
26.21,79.36,-0.294
26.22,79.23,-0.293
26.23,79.09,-0.293
26.25,78.96,-0.293
26.26,78.83,-0.293
26.27,78.69,-0.292
26.29,78.56,-0.292
26.30,78.43,-0.292
26.31,78.29,-0.292
26.33,78.16,-0.291
26.34,78.02,-0.291
26.35,77.89,-0.291
26.37,77.76,-0.291
26.38,77.62,-0.290
26.39,77.49,-0.290
26.41,77.36,-0.290
26.42,77.23,-0.290
26.43,77.09,-0.289
26.45,76.96,-0.289
26.46,76.82,-0.289
26.47,76.69,-0.289
26.49,76.56,-0.288
26.50,76.42,-0.288
26.51,76.29,-0.288
26.53,76.16,-0.288
26.54,76.02,-0.288
26.55,75.89,-0.287
26.57,75.76,-0.287
26.58,75.62,-0.287
26.59,75.49,-0.287
26.61,75.36,-0.286
26.62,75.22,-0.286
26.63,75.09,-0.286
[...]
88.49,-16.43,0.158
88.50,-16.29,0.158
88.51,-16.16,0.158
88.53,-16.03,0.158
88.54,-15.89,0.158
88.55,-15.76,0.158
88.57,-15.63,0.158
88.58,-15.49,0.158
88.60,-15.36,0.158
88.61,-15.23,0.159
88.62,-15.09,0.159
88.64,-14.96,0.159
88.65,-14.83,0.159
88.66,-14.69,0.159
88.68,-14.56,0.159
88.69,-14.43,0.159
88.70,-14.29,0.159
88.71,-14.16,0.159
88.73,-14.02,0.159
88.74,-13.89,0.159
88.75,-13.76,0.159
88.77,-13.62,0.159
88.78,-13.49,0.159
88.80,-13.36,0.160
88.81,-13.22,0.160
88.82,-13.09,0.160
88.84,-12.96,0.160
88.85,-12.82,0.160
88.86,-12.69,0.160
88.88,-12.56,0.160
88.89,-12.42,0.160
88.90,-12.29,0.160
88.91,-12.16,0.160
88.93,-12.02,0.160
88.94,-11.89,0.160
88.95,-11.76,0.160
88.97,-11.62,0.160
88.98,-11.49,0.161
89.00,-11.36,0.161
89.01,-11.22,0.161
89.02,-11.09,0.161
89.04,-10.96,0.161
89.05,-10.82,0.161
89.06,-10.69,0.161
89.08,-10.55,0.161
89.09,-10.42,0.161
89.10,-10.29,0.161
89.11,-10.15,0.161
89.13,-10.02,0.161
89.14,-9.89,0.161
89.15,-9.75,0.161
89.17,-9.62,0.162
89.18,-9.49,0.162
89.20,-9.35,0.162
89.21,-9.22,0.162
89.22,-9.09,0.162
89.24,-8.95,0.162
89.25,-8.82,0.162
89.26,-8.69,0.162
89.28,-8.55,0.162
89.29,-8.42,0.162
89.30,-8.29,0.162
89.31,-8.15,0.162
89.33,-8.02,0.162
89.34,-7.88,0.162
89.35,-7.75,0.163
89.37,-7.62,0.163
89.38,-7.48,0.163
89.40,-7.35,0.163
89.41,-7.22,0.163
89.42,-7.08,0.163
89.44,-6.95,0.163
89.45,-6.82,0.163
89.46,-6.68,0.163
89.48,-6.55,0.163
89.49,-6.42,0.163
89.50,-6.28,0.163
89.51,-6.15,0.163
89.53,-6.02,0.164
89.54,-5.88,0.164
89.55,-5.75,0.164
89.57,-5.62,0.164
89.58,-5.48,0.164
89.60,-5.35,0.164
89.61,-5.22,0.164
89.62,-5.08,0.164
89.64,-4.95,0.164
89.65,-4.82,0.164
89.66,-4.68,0.164
89.68,-4.55,0.164
89.69,-4.42,0.164
89.70,-4.28,0.164
89.71,-4.15,0.165
89.73,-4.01,0.165
89.74,-3.88,0.165
89.75,-3.75,0.165
89.77,-3.61,0.165
89.78,-3.48,0.165
89.80,-3.35,0.165
89.81,-3.21,0.165
89.82,-3.08,0.165
89.84,-2.95,0.165
89.85,-2.81,0.165
89.86,-2.68,0.165
89.88,-2.55,0.165
89.89,-2.41,0.166
89.90,-2.28,0.166
89.91,-2.15,0.166
89.93,-2.01,0.166
89.94,-1.88,0.166
89.95,-1.75,0.166
89.97,-1.61,0.166
89.98,-1.48,0.166
90.00,-1.35,0.166
90.01,-1.21,0.166
90.02,-1.08,0.166
90.04,-0.94,0.166
90.05,-0.81,0.166
90.06,-0.68,0.167
90.08,-0.55,0.167
90.09,-0.41,0.167
90.10,-0.28,0.167
90.11,-0.14,0.167
90.13,-0.01,0.167
90.14,0.12,0.167
90.15,0.25,0.167
90.17,0.39,0.167
90.18,0.52,0.167
90.20,0.66,0.167
90.21,0.79,0.167
90.22,0.92,0.168
90.24,1.06,0.168
90.25,1.19,0.168
90.26,1.33,0.168
90.28,1.46,0.168
90.29,1.59,0.168
90.30,1.72,0.168
90.31,1.86,0.168
90.33,1.99,0.168
90.34,2.12,0.168
90.35,2.26,0.168
90.37,2.39,0.168
90.38,2.52,0.169
90.40,2.66,0.169
90.41,2.79,0.169
90.42,2.93,0.169
90.44,3.06,0.169
90.45,3.19,0.169
90.46,3.33,0.169
90.48,3.46,0.169
90.49,3.59,0.169
90.50,3.73,0.169
90.51,3.86,0.169
90.53,3.99,0.169
90.54,4.13,0.170
90.55,4.26,0.170
90.57,4.39,0.170
90.58,4.53,0.170
90.60,4.66,0.170
90.61,4.79,0.170
90.62,4.93,0.170
90.64,5.06,0.170
90.65,5.19,0.170
90.66,5.33,0.170
90.68,5.46,0.170
90.69,5.60,0.170
90.70,5.73,0.171
90.71,5.86,0.171
90.73,6.00,0.171
90.74,6.13,0.171
90.75,6.26,0.171
90.77,6.40,0.171
90.78,6.53,0.171
90.80,6.66,0.171
90.81,6.80,0.171
90.82,6.93,0.171
90.84,7.06,0.171
90.85,7.20,0.171
90.86,7.33,0.172
90.88,7.46,0.172
90.89,7.60,0.172
90.90,7.73,0.172
90.91,7.86,0.172
90.93,8.00,0.172
90.94,8.13,0.172
90.95,8.26,0.172
90.97,8.40,0.172
90.98,8.53,0.172
91.00,8.66,0.172
91.01,8.80,0.173
91.02,8.93,0.173
91.04,9.07,0.173
91.05,9.20,0.173
91.06,9.33,0.173
91.08,9.47,0.173
91.09,9.60,0.173
91.10,9.73,0.173
91.11,9.87,0.173
91.13,10.00,0.173
91.14,10.13,0.173
91.15,10.27,0.173
91.17,10.40,0.174
91.18,10.53,0.174
91.20,10.67,0.174
91.21,10.80,0.174
91.22,10.93,0.174
91.24,11.07,0.174
91.25,11.20,0.174
91.26,11.33,0.174
91.28,11.47,0.174
91.29,11.60,0.174
91.30,11.73,0.174
91.31,11.87,0.175
91.33,12.00,0.175
91.34,12.13,0.175
91.35,12.27,0.175
91.37,12.40,0.175
91.38,12.53,0.175
91.40,12.67,0.175
91.41,12.80,0.175
91.42,12.93,0.175
91.44,13.07,0.175
91.45,13.20,0.175
91.46,13.33,0.176
91.48,13.47,0.176
91.49,13.60,0.176
91.50,13.74,0.176
91.51,13.87,0.176
91.53,14.00,0.176
91.54,14.13,0.176
91.55,14.27,0.176
91.57,14.40,0.176
91.58,14.53,0.176
91.60,14.67,0.176
91.61,14.80,0.177
91.62,14.94,0.177
91.64,15.07,0.177
91.65,15.20,0.177
91.66,15.34,0.177
91.68,15.47,0.177
91.69,15.60,0.177
91.70,15.74,0.177
91.71,15.87,0.177
91.73,16.00,0.177
91.74,16.14,0.178
91.75,16.27,0.178
91.77,16.40,0.178
91.78,16.54,0.178
91.80,16.67,0.178
91.81,16.80,0.178
91.82,16.94,0.178
91.84,17.07,0.178
91.85,17.20,0.178
91.86,17.34,0.178
91.88,17.47,0.178
91.89,17.60,0.179
91.90,17.74,0.179
91.91,17.87,0.179
91.93,18.01,0.179
91.94,18.14,0.179
91.95,18.27,0.179
91.97,18.40,0.179
91.98,18.54,0.179
92.00,18.67,0.179
92.01,18.81,0.179
92.02,18.94,0.179
92.04,19.07,0.180
92.05,19.20,0.180
92.06,19.34,0.180
92.08,19.47,0.180
92.09,19.60,0.180
92.10,19.74,0.180
92.11,19.87,0.180
92.13,20.00,0.180
92.14,20.14,0.180
92.15,20.27,0.180
92.17,20.41,0.180
92.18,20.54,0.181
92.20,20.67,0.181
92.21,20.81,0.181
92.22,20.94,0.181
92.24,21.07,0.181
92.25,21.21,0.181
92.26,21.34,0.181
92.28,21.47,0.181
92.29,21.61,0.181
92.30,21.74,0.181
92.31,21.87,0.181
92.33,22.01,0.182
92.34,22.14,0.182
92.35,22.27,0.182
92.37,22.41,0.182
92.38,22.54,0.182
92.40,22.67,0.182
92.41,22.81,0.182
92.42,22.94,0.182
92.44,23.07,0.182
92.45,23.21,0.183
92.46,23.34,0.183
92.48,23.48,0.183
92.49,23.61,0.183
92.50,23.74,0.183
92.51,23.88,0.183
92.53,24.01,0.183
92.54,24.14,0.183
92.55,24.28,0.183
92.57,24.41,0.184
92.58,24.54,0.184
92.60,24.68,0.184
92.61,24.81,0.184
92.62,24.94,0.184
92.64,25.08,0.184
92.65,25.21,0.184
92.66,25.34,0.184
92.68,25.48,0.184
92.69,25.61,0.184
92.70,25.74,0.185
92.71,25.88,0.185
92.73,26.01,0.185
92.74,26.14,0.185
92.75,26.28,0.185
92.77,26.41,0.185
92.78,26.55,0.185
92.80,26.68,0.185
92.81,26.81,0.185
92.82,26.95,0.185
92.84,27.08,0.186
92.85,27.21,0.186
92.86,27.35,0.186
92.88,27.48,0.186
92.89,27.61,0.186
92.90,27.75,0.186
92.91,27.88,0.186
92.93,28.01,0.186
92.94,28.15,0.186
92.95,28.28,0.186
92.97,28.41,0.187
92.98,28.55,0.187
93.00,28.68,0.187
93.01,28.81,0.187
93.02,28.95,0.187
93.04,29.08,0.187
93.05,29.21,0.187
93.06,29.35,0.187
93.08,29.48,0.187
93.09,29.61,0.187
93.10,29.75,0.188
93.11,29.88,0.188
93.13,30.02,0.188
93.14,30.15,0.188
93.15,30.28,0.188
93.17,30.41,0.188
93.18,30.55,0.188
93.20,30.68,0.188
93.21,30.81,0.188
93.22,30.95,0.188
93.24,31.08,0.189
93.25,31.22,0.189
93.26,31.35,0.189
93.28,31.48,0.189
93.29,31.62,0.189
93.30,31.75,0.189
93.31,31.88,0.189
93.33,32.02,0.189
93.34,32.15,0.189
93.35,32.28,0.189
93.37,32.42,0.190
93.38,32.55,0.190
93.40,32.68,0.190
93.41,32.82,0.190
93.42,32.95,0.190
93.44,33.08,0.190
93.45,33.22,0.190
93.46,33.35,0.190
93.48,33.49,0.190
93.49,33.62,0.190
93.50,33.75,0.191
93.51,33.89,0.191
93.53,34.02,0.191
93.54,34.15,0.191
93.55,34.29,0.191
93.57,34.42,0.191
93.58,34.55,0.191
93.60,34.69,0.191
93.61,34.82,0.191
93.62,34.95,0.191
93.64,35.09,0.192
93.65,35.22,0.192
93.66,35.35,0.192
93.68,35.49,0.192
93.69,35.62,0.192
93.70,35.75,0.192
93.71,35.89,0.192
93.73,36.02,0.192
93.74,36.15,0.192
93.75,36.29,0.193
93.77,36.42,0.193
93.78,36.55,0.193
93.80,36.69,0.193
93.81,36.82,0.193
93.82,36.95,0.193
93.84,37.09,0.193
93.85,37.22,0.193
93.86,37.35,0.193
93.88,37.49,0.193
93.89,37.62,0.194
93.90,37.75,0.194
93.91,37.89,0.194
93.93,38.02,0.194
93.94,38.16,0.194
93.95,38.29,0.194
93.97,38.42,0.194
93.98,38.56,0.194
94.00,38.69,0.194
94.01,38.82,0.195
94.02,38.96,0.195
94.04,39.09,0.195
94.05,39.22,0.195
94.06,39.36,0.195
94.08,39.49,0.195
94.09,39.62,0.195
94.10,39.76,0.195
94.11,39.89,0.195
94.13,40.02,0.196
94.14,40.16,0.196
94.15,40.29,0.196
94.17,40.42,0.196
94.18,40.56,0.196
94.20,40.69,0.196
94.21,40.82,0.196
94.22,40.96,0.196
94.24,41.09,0.196
94.25,41.22,0.197
94.26,41.36,0.197
94.28,41.49,0.197
94.29,41.62,0.197
94.30,41.76,0.197
94.31,41.89,0.197
94.33,42.03,0.197
94.34,42.16,0.197
94.35,42.29,0.197
94.37,42.43,0.198
94.38,42.56,0.198
94.40,42.69,0.198
94.41,42.82,0.198
94.42,42.96,0.198
94.44,43.09,0.198
94.45,43.23,0.198
94.46,43.36,0.198
94.48,43.49,0.198
94.49,43.63,0.199
94.50,43.76,0.199
94.51,43.89,0.199
94.53,44.03,0.199
94.54,44.16,0.199
94.55,44.29,0.199
94.57,44.42,0.199
94.58,44.56,0.199
94.60,44.69,0.200
94.61,44.83,0.200
94.62,44.96,0.200
94.64,45.09,0.200
94.65,45.23,0.200
94.66,45.36,0.200
94.68,45.49,0.200
94.69,45.63,0.200
94.70,45.76,0.201
94.71,45.89,0.201
94.73,46.03,0.201
94.74,46.16,0.201
94.75,46.30,0.201
94.77,46.43,0.201
94.78,46.56,0.201
94.80,46.69,0.201
94.81,46.83,0.202
94.82,46.96,0.202
94.84,47.09,0.202
94.85,47.23,0.202
94.86,47.36,0.202
94.88,47.49,0.202
94.89,47.63,0.202
94.90,47.76,0.202
94.91,47.89,0.203
94.93,48.03,0.203
94.94,48.16,0.203
94.95,48.30,0.203
94.97,48.43,0.203
94.98,48.56,0.203
95.00,48.69,0.203
95.01,48.83,0.204
95.02,48.96,0.204
95.04,49.10,0.204
95.05,49.23,0.204
95.06,49.36,0.204
95.08,49.50,0.204
95.09,49.63,0.204
95.10,49.76,0.204
95.11,49.90,0.205
95.13,50.03,0.205
95.14,50.16,0.205
95.15,50.30,0.205
95.17,50.43,0.205
95.18,50.56,0.205
95.20,50.70,0.205
95.21,50.83,0.205
95.22,50.96,0.206
95.24,51.10,0.206
95.25,51.23,0.206
95.26,51.36,0.206
95.28,51.50,0.206
95.29,51.63,0.206
95.30,51.76,0.206
95.31,51.90,0.207
95.33,52.03,0.207
95.34,52.16,0.207
95.35,52.30,0.207
95.37,52.43,0.207
95.38,52.56,0.207
95.40,52.70,0.207
95.41,52.83,0.207
95.42,52.96,0.208
95.44,53.10,0.208
95.45,53.23,0.208
95.46,53.37,0.208
95.48,53.50,0.208
95.49,53.63,0.208
95.50,53.77,0.208
95.51,53.90,0.209
95.53,54.03,0.209
95.54,54.17,0.209
95.55,54.30,0.209
95.57,54.43,0.209
95.58,54.57,0.209
95.60,54.70,0.209
95.61,54.83,0.210
95.62,54.97,0.210
95.64,55.10,0.210
95.65,55.23,0.210
95.66,55.37,0.210
95.68,55.50,0.210
95.69,55.63,0.210
95.70,55.77,0.211
95.71,55.90,0.211
95.73,56.03,0.211
95.74,56.17,0.211
95.75,56.30,0.211
95.77,56.43,0.211
95.78,56.57,0.211
95.80,56.70,0.212
95.81,56.83,0.212
95.82,56.97,0.212
95.84,57.10,0.212
95.85,57.23,0.212
95.86,57.37,0.212
95.88,57.50,0.213
95.89,57.63,0.213
95.90,57.77,0.213
95.91,57.90,0.213
95.93,58.04,0.213
95.94,58.17,0.213
95.95,58.30,0.213
95.97,58.43,0.214
95.98,58.57,0.214
96.00,58.70,0.214
96.01,58.84,0.214
96.02,58.97,0.214
96.04,59.10,0.214
96.05,59.24,0.215
96.06,59.37,0.215
96.08,59.50,0.215
96.09,59.64,0.215
96.10,59.77,0.215
96.11,59.90,0.215
96.13,60.04,0.216
96.14,60.17,0.216
96.15,60.30,0.216
96.17,60.44,0.216
96.18,60.57,0.216
96.20,60.70,0.216
96.21,60.84,0.217
96.22,60.97,0.217
96.24,61.10,0.217
96.25,61.24,0.217
96.26,61.37,0.217
96.28,61.50,0.217
96.29,61.64,0.218
96.30,61.77,0.218
96.31,61.90,0.218
96.33,62.04,0.218
96.34,62.17,0.218
96.35,62.30,0.219
96.37,62.44,0.219
96.38,62.57,0.219
96.40,62.70,0.219
96.41,62.84,0.219
96.42,62.97,0.220
96.44,63.10,0.220
96.45,63.24,0.220
96.46,63.37,0.220
96.48,63.50,0.220
96.49,63.64,0.220
96.50,63.77,0.221
96.51,63.90,0.221
96.53,64.04,0.221
96.54,64.17,0.221
96.55,64.30,0.221
96.57,64.44,0.222
96.58,64.57,0.222
96.60,64.70,0.222
96.61,64.84,0.222
96.62,64.97,0.223
96.64,65.10,0.223
96.65,65.24,0.223
96.66,65.37,0.223
96.68,65.50,0.223
96.69,65.64,0.224
96.70,65.77,0.224
96.71,65.90,0.224
96.73,66.04,0.224
96.74,66.17,0.225
96.75,66.30,0.225
96.77,66.44,0.225
96.78,66.57,0.225
96.80,66.70,0.225
96.81,66.84,0.226
96.82,66.97,0.226
96.84,67.10,0.226
96.85,67.24,0.226
96.86,67.37,0.227
96.88,67.50,0.227
96.89,67.64,0.227
96.90,67.77,0.227
96.91,67.90,0.228
96.93,68.04,0.228
96.94,68.17,0.228
96.95,68.30,0.228
96.97,68.44,0.229
96.98,68.57,0.229
97.00,68.70,0.229
97.01,68.84,0.230
97.02,68.97,0.230
97.04,69.10,0.230
97.05,69.24,0.230
97.06,69.37,0.231
97.08,69.50,0.231
97.09,69.64,0.231
97.10,69.77,0.231
97.11,69.90,0.232
97.13,70.04,0.232
97.14,70.17,0.232
97.15,70.30,0.233
97.17,70.44,0.233
97.18,70.57,0.233
97.20,70.70,0.233
97.21,70.84,0.234
97.22,70.97,0.234
97.24,71.10,0.234
97.25,71.24,0.235
97.26,71.37,0.235
97.28,71.50,0.236
97.29,71.64,0.236
97.30,71.77,0.236
97.31,71.90,0.237
97.33,72.04,0.237
97.34,72.17,0.237
97.35,72.31,0.237
97.37,72.44,0.238
97.38,72.57,0.238
97.40,72.70,0.238
97.41,72.84,0.239
97.42,72.97,0.239
97.44,73.10,0.239
97.45,73.24,0.240
97.46,73.37,0.240
97.48,73.50,0.240
97.49,73.64,0.241
97.50,73.77,0.241
97.51,73.90,0.241
97.53,74.04,0.242
97.54,74.17,0.242
97.55,74.30,0.242
97.57,74.44,0.243
97.58,74.57,0.243
97.60,74.70,0.243
97.61,74.84,0.244
97.62,74.97,0.244
97.64,75.10,0.245
97.65,75.24,0.245
97.66,75.37,0.245
97.68,75.50,0.246
97.69,75.64,0.246
97.70,75.77,0.246
97.71,75.90,0.247
97.73,76.04,0.247
97.74,76.17,0.247
97.75,76.30,0.248
97.77,76.44,0.248
97.78,76.57,0.249
97.80,76.70,0.249
97.81,76.84,0.249
97.82,76.97,0.250
97.84,77.10,0.250
97.85,77.23,0.251
97.86,77.37,0.251
97.88,77.50,0.251
97.89,77.64,0.252
97.90,77.77,0.252
97.91,77.90,0.253
97.93,78.04,0.253
97.94,78.17,0.253
97.95,78.30,0.254
97.97,78.44,0.254
97.98,78.57,0.255
98.00,78.70,0.255
98.01,78.84,0.255
98.02,78.97,0.256
98.04,79.10,0.256
98.05,79.24,0.256
98.06,79.37,0.256
98.08,79.50,0.257
98.09,79.64,0.257
98.10,79.77,0.257
98.11,79.90,0.258
98.13,80.04,0.258
98.14,80.17,0.258
98.15,80.30,0.259
98.17,80.44,0.259
98.18,80.57,0.259
98.20,80.70,0.260
98.21,80.84,0.260
98.22,80.97,0.261
98.24,81.10,0.261
98.25,81.23,0.261
98.26,81.37,0.262
98.28,81.50,0.262
98.29,81.63,0.262
98.30,81.77,0.263
98.31,81.90,0.263
98.33,82.03,0.263
98.34,82.17,0.264
98.35,82.30,0.264
98.37,82.43,0.264
98.38,82.57,0.265
98.40,82.70,0.265
98.41,82.83,0.266
98.42,82.97,0.266
98.44,83.10,0.266
98.45,83.23,0.266
98.46,83.37,0.267
98.48,83.50,0.267
98.49,83.64,0.267
98.50,83.77,0.268
98.51,83.90,0.268
98.53,84.04,0.268
98.54,84.17,0.268
98.55,84.30,0.269
98.57,84.44,0.269
98.58,84.57,0.269
98.60,84.70,0.269
98.61,84.84,0.269
98.62,84.97,0.270
98.64,85.10,0.270
98.65,85.24,0.270
98.66,85.37,0.271
98.68,85.50,0.271
98.69,85.64,0.271
98.70,85.77,0.271
98.71,85.90,0.272
98.73,86.04,0.272
98.74,86.17,0.272
98.75,86.31,0.272
98.77,86.44,0.272
98.78,86.58,0.273
98.80,86.71,0.274
98.81,86.84,0.274
98.82,86.98,0.274
98.84,87.11,0.275
98.85,87.24,0.275
98.86,87.38,0.275
98.88,87.51,0.276
98.89,87.64,0.276
98.90,87.78,0.276
98.91,87.91,0.276
98.93,88.04,0.276
98.94,88.18,0.276
98.95,88.31,0.277
98.97,88.44,0.277
98.98,88.58,0.277
99.00,88.71,0.277
99.01,88.84,0.277
99.02,88.97,0.277
99.04,89.11,0.278
99.05,89.24,0.278
99.06,89.37,0.278
99.08,89.51,0.278
99.09,89.64,0.278
99.10,89.77,0.278
99.11,89.91,0.278
99.13,90.04,0.279
99.14,90.17,0.279
99.15,90.31,0.279
99.17,90.44,0.279
99.18,90.57,0.279
99.20,90.70,0.279
99.21,90.84,0.280
99.22,90.97,0.280
99.24,91.10,0.280
99.25,91.24,0.280
99.26,91.37,0.280
99.28,91.51,0.281
99.29,91.64,0.281
99.30,91.77,0.281
99.31,91.90,0.281
99.33,92.04,0.281
99.34,92.17,0.282
99.35,92.30,0.282
99.37,92.44,0.282
99.38,92.57,0.282
99.40,92.71,0.282
99.41,92.84,0.282
99.42,92.97,0.283
99.44,93.10,0.283
99.45,93.24,0.283
99.46,93.37,0.283
99.48,93.50,0.283
99.49,93.64,0.283
99.50,93.77,0.284
99.51,93.91,0.284
99.53,94.04,0.284
99.54,94.17,0.284
99.55,94.31,0.284
99.57,94.44,0.285
99.58,94.57,0.285
99.60,94.71,0.285
99.61,94.84,0.285
99.62,94.97,0.285
99.64,95.11,0.285
99.65,95.24,0.286
99.66,95.37,0.286
99.68,95.51,0.286
99.69,95.64,0.286
99.70,95.77,0.286
99.71,95.91,0.286
99.73,96.04,0.287
99.74,96.17,0.287
99.75,96.31,0.287
99.77,96.44,0.287
99.78,96.57,0.287
99.80,96.70,0.287
99.81,96.84,0.288
99.82,96.97,0.288
99.84,97.10,0.288
99.85,97.24,0.288
99.86,97.37,0.288
99.88,97.50,0.288
99.89,97.64,0.288
99.90,97.77,0.289
99.91,97.90,0.289
99.93,98.04,0.289
99.94,98.17,0.289
99.95,98.30,0.289
99.97,98.44,0.289
99.98,98.57,0.290
100.00,98.70,0.290
100.01,98.84,0.291
100.02,98.97,0.291
100.04,99.10,0.292
100.05,99.24,0.292
100.06,99.37,0.292
100.08,99.50,0.292
100.09,99.64,0.292
100.10,99.77,0.293
100.11,99.90,0.293
100.13,100.04,0.293
100.14,100.17,0.293
100.15,100.30,0.293
100.17,100.44,0.293
100.18,100.57,0.294
100.20,100.70,0.294
100.21,100.84,0.294
100.22,100.97,0.294
100.24,101.11,0.294
100.25,101.24,0.294
100.26,101.37,0.294
100.28,101.51,0.294
100.29,101.64,0.295
100.30,101.77,0.295
100.31,101.91,0.295
100.33,102.04,0.295
100.34,102.17,0.296
100.35,102.31,0.296
100.37,102.44,0.296
100.38,102.58,0.296
100.40,102.71,0.296
100.41,102.84,0.297
100.42,102.97,0.297
100.44,103.11,0.297
100.45,103.24,0.297
100.46,103.38,0.297
100.48,103.51,0.297
100.49,103.64,0.298
100.50,103.77,0.307
100.51,103.90,0.338
100.53,104.03,0.324
100.54,104.17,0.319
100.55,104.30,0.315
100.57,104.43,0.313
100.58,104.57,0.311
100.60,104.70,0.310
100.61,104.84,0.309
100.62,104.97,0.309
100.64,105.10,0.308
100.65,105.24,0.308
100.66,105.37,0.308
100.68,105.51,0.308
100.69,105.64,0.307
100.70,105.77,0.307
100.71,105.91,0.307
100.73,106.04,0.307
100.74,106.17,0.307
100.75,106.31,0.307
100.77,106.44,0.307
100.78,106.57,0.307
100.80,106.71,0.307
100.81,106.84,0.307
100.82,106.97,0.307
100.84,107.11,0.306
100.85,107.24,0.306
100.86,107.37,0.306
100.88,107.51,0.306
100.89,107.64,0.306
100.90,107.77,0.306
100.91,107.91,0.306
100.93,108.04,0.306
100.94,108.17,0.306
100.95,108.31,0.306
100.97,108.44,0.306
100.98,108.57,0.306
101.00,108.71,0.306
101.01,108.84,0.306
101.02,108.98,0.306
101.04,109.11,0.306
101.05,109.24,0.307
101.06,109.38,0.307
101.08,109.51,0.307
101.09,109.64,0.307
101.10,109.78,0.307
101.11,109.91,0.307
101.13,110.04,0.307
101.14,110.18,0.307
101.15,110.31,0.307
101.17,110.44,0.307
101.18,110.58,0.307
101.20,110.71,0.307
101.21,110.84,0.308
101.22,110.98,0.308
101.24,111.11,0.308
101.25,111.24,0.308
101.26,111.38,0.308
101.28,111.51,0.308
101.29,111.64,0.308
101.30,111.78,0.308
101.31,111.91,0.308
101.33,112.04,0.308
101.34,112.18,0.308
101.35,112.31,0.308
101.37,112.44,0.309
101.38,112.58,0.309
101.40,112.71,0.309
101.41,112.85,0.309
101.42,112.98,0.309
101.44,113.11,0.309
101.45,113.25,0.309
101.46,113.38,0.309
101.48,113.51,0.310
101.49,113.65,0.310
101.50,113.78,0.310
101.51,113.91,0.310
101.53,114.05,0.311
101.54,114.18,0.312
101.55,114.31,0.312
101.57,114.44,0.312
101.58,114.58,0.312
101.60,114.71,0.313
101.61,114.84,0.313
101.62,114.98,0.313
101.64,115.11,0.313
101.65,115.25,0.313
101.66,115.38,0.313
101.68,115.51,0.313
101.69,115.65,0.313
101.70,115.78,0.313
101.71,115.91,0.314
101.73,116.05,0.314
101.74,116.18,0.314
101.75,116.31,0.314
101.77,116.45,0.314
101.78,116.58,0.314
101.80,116.71,0.314
101.81,116.85,0.314
101.82,116.98,0.315
101.84,117.11,0.315
101.85,117.25,0.315
101.86,117.38,0.315
101.88,117.51,0.315
101.89,117.65,0.315
101.90,117.78,0.315
101.91,117.91,0.315
101.93,118.05,0.315
101.94,118.18,0.315
101.95,118.31,0.315
101.97,118.45,0.315
101.98,118.58,0.315
102.00,118.71,0.316
102.01,118.85,0.316
102.02,118.98,0.317
102.04,119.11,0.318
102.05,119.25,0.318
102.06,119.38,0.318
102.08,119.51,0.318
102.09,119.65,0.318
102.10,119.78,0.318
102.11,119.91,0.319
102.13,120.05,0.319
102.14,120.18,0.319
102.15,120.31,0.320
102.17,120.45,0.320
102.18,120.58,0.321
102.20,120.71,0.321
102.21,120.85,0.321
102.22,120.98,0.321
102.24,121.11,0.321
102.25,121.25,0.321
102.26,121.38,0.321
102.28,121.51,0.321
102.29,121.65,0.322
102.30,121.78,0.322
102.31,121.91,0.322
102.33,122.05,0.322
102.34,122.18,0.322
102.35,122.31,0.322
102.37,122.45,0.322
102.38,122.58,0.323
102.40,122.71,0.323
102.41,122.85,0.323
102.42,122.98,0.324
102.44,123.11,0.324
102.45,123.25,0.324
102.46,123.38,0.324
102.48,123.51,0.324
102.49,123.65,0.325
102.50,123.78,0.326
102.51,123.91,0.326
102.53,124.05,0.327
102.54,124.18,0.327
102.55,124.31,0.327
102.57,124.45,0.327
102.58,124.58,0.327
102.60,124.71,0.328
102.61,124.85,0.328
102.62,124.98,0.328
102.64,125.11,0.328
102.65,125.25,0.328
102.66,125.38,0.329
102.68,125.51,0.329
102.69,125.65,0.329
102.70,125.78,0.330
102.71,125.91,0.330
102.73,126.05,0.331
102.74,126.18,0.331
102.75,126.31,0.331
102.77,126.45,0.331
102.78,126.58,0.331
102.80,126.71,0.331
102.81,126.85,0.332
102.82,126.98,0.332
102.84,127.11,0.332
102.85,127.25,0.332
102.86,127.38,0.333
102.88,127.51,0.333
102.89,127.65,0.333
102.90,127.78,0.333
102.91,127.91,0.333
102.93,128.05,0.334
102.94,128.18,
102.95,128.31,
102.97,128.45,
102.98,128.58,
103.00,,