File: DSC/Olivia/2025_07_02_ReCBD_PVP_5p5_Vac_Std_Al_Pan_n60C_200C_10Cmin_x4.csv
Filename,2025_07_02_ReCBD_PVP_5p5_Vac_Std_Al_Pan_n60C_200C_10Cmin_x4
Instrument name,DSC2A-00468 (192.168.1.100)
Operator,Gibbons
rundate,7/2/2025
Sample name,2025_07_02_ReCBD_PVP_5p5_Vac_Std_Al_Pan_n60C_200C_10Cmin_x4
proceduresegments,Data Off ; Equilibrate -60.00 °C; Data On ; Ramp 10.00 °C/min to 200.00 °C; Data Off ; Isothermal 2.0 min; Data On ; Ramp 10.00 °C/min to -60.00 °C; Data Off ; Isothermal 2.0 min; Data On ; Ramp 10.00 °C/min to 200.00 °C; Data Off ; Isothermal 2.0 min; Data On ; Ramp 10.00 °C/min to -60.00 °C; Data Off ; Isothermal 2.0 min; Data On ; Ramp 10.00 °C/min to 200.00 °C; Data Off ; Isothermal 2.0 min; Data On ; Ramp 10.00 °C/min to -60.00 °C; Data Off ; Isothermal 2.0 min; Data On ; Ramp 10.00 °C/min to 30.00 °C
[File Parameters]
Run date,7/2/2025 5:44:23 PM
Trios version,5.1.1.46572
Original File Name,
Current File Name,D:\DSC2500\Gibbons\2025_07_02_ReCBD_PVP_5p5_Vac_Std_Al_Pan_n60C_200C_10Cmin_x4.tri
[Procedure]
Procedure Name,ReCBD_PVP_5p5_Vac_Std_Al_Pan_n60C_200C_10Cmin_x4
Sample Name,2025_07_02_ReCBD_PVP_5p5_Vac_Std_Al_Pan_n60C_200C_10Cmin_x4
Sample Mass,3.96 mg
Reference Sample Mass,0 mg
Pan Mass,20.12 mg
Pan Number,50
Reference Pan Mass,20 mg
Reference Pan Number,46
Pan Type,Aluminum
Comments,Al Pan/Lid Std. Y1 Tray (Google Sheet: DSC_Samples_Y1_Tray_June2025).
Project Name,Pharma - Cocrystals
Operator,Gibbons
Test,Custom
Unload Max Temperature,30
Unload Min Temperature,30
Load Max Temperature,30
Load Min Temperature,30
Stop on Gas Flow Error,Yes
[Signal List]
Signal #1,Time (min)
Signal #2,Temperature (°C)
Signal #3,Heat Flow (mW)
Signal #4,Delta T (µV)
Signal #5,Delta Tzero (µV)
Signal #6,Tzero Temperature (°C)
Signal #7,Cell Purge (mL/min)
Signal #8,Heater Temp (°C)
Signal #9,Power Delivered (W)
Signal #10,Reference Junction Temperature (°C)
Signal #11,Flange Temperature (°C)
Signal #12,Heat Flow Phase (rad)
Signal #13,Total Heat Capacity (J/°C)
Signal #14,Heat Capacity (J/°C)
[Configuration]
Company Name,ASU
Instrument Name,DSC2A-00468
Instrument Type,DSC2500
Serial Number,DSC2A-00468
IP,192.168.1.100
Location of Instrument,MRRC
DisplayType,Unknown
Sample Interval ,0.1 s/pt
Selected Heat Flow,T4P
Exotherm Direction,Down
Cell Serial,DRC2-00792
Lid Type,Standard
Cooler,RCS 90
Leave Cooler on at End of Sequence,On
Gas 2,Nitrogen
Gas Selected,Channel 1
Flow Rate,50 mL/min
Secondary Purge,On
Licensed Heat Flow,Heat Flow T4P
Modulation Licensed,Yes
[Versions]
Common IDD Version,1
Cortex Version,VER 2.10.2.31
Driver,5.0.0.6
GDM Version,1.0.3.3
TouchscreenVersion,1.0.0.16145
FEP Version,1.2.1.21
FEP Bootloader,2.0.0.5
AutoSampler Version,2.1.1.26
Auto Sampler Bootloader,2.0.0.5
FCM Version,1.1.0.3
FCM Bootloader,2.0.0.5
[Experiment Logs]
Experiment Log Entry # 1,Data On set to 0
Experiment Log Entry # 3,Equilibrate Segment -60 (C) Started
Experiment Log Entry # 5,Air Cool is off.
Experiment Log Entry # 7,Data On set to 1
Experiment Log Entry # 9,Ramp Segment 10 C/min to 200 Started
Experiment Log Entry # 11,Data On set to 0
Experiment Log Entry # 13,Isothermal Segment 2 min started
Experiment Log Entry # 15,Data On set to 1
Experiment Log Entry # 17,Ramp Segment 10 C/min to -60 Started
Experiment Log Entry # 19,Data On set to 0
Experiment Log Entry # 21,Isothermal Segment 2 min started
Experiment Log Entry # 23,Data On set to 1
Experiment Log Entry # 25,Ramp Segment 10 C/min to 200 Started
Experiment Log Entry # 27,Data On set to 0
Experiment Log Entry # 29,Isothermal Segment 2 min started
Experiment Log Entry # 31,Data On set to 1
Experiment Log Entry # 33,Ramp Segment 10 C/min to -60 Started
Experiment Log Entry # 35,Data On set to 0
Experiment Log Entry # 37,Isothermal Segment 2 min started
Experiment Log Entry # 39,Data On set to 1
Experiment Log Entry # 41,Ramp Segment 10 C/min to 200 Started
Experiment Log Entry # 43,Data On set to 0
Experiment Log Entry # 45,Isothermal Segment 2 min started
Experiment Log Entry # 47,Data On set to 1
Experiment Log Entry # 49,Ramp Segment 10 C/min to -60 Started
Experiment Log Entry # 51,Data On set to 0
Experiment Log Entry # 53,Isothermal Segment 2 min started
Experiment Log Entry # 55,Data On set to 1
Experiment Log Entry # 57,Ramp Segment 10 C/min to 30 Started
[Method Log]
Method Log Entry # 1,Data Off
Method Log Entry # 2,Equilibrate -60 °C
Method Log Entry # 3,Data On
Method Log Entry # 4,(Ramp 1275819) Ramp 10 °C/minute to 200 °C
Method Log Entry # 5,Data Off
Method Log Entry # 6,Isothermal 2 minutes
Method Log Entry # 7,Data On
Method Log Entry # 8,(Ramp 1275823) Ramp 10 °C/minute to -60 °C
Method Log Entry # 9,Data Off
Method Log Entry # 10,Isothermal 2 minutes
Method Log Entry # 11,Data On
Method Log Entry # 12,(Ramp 1275827) Ramp 10 °C/minute to 200 °C
Method Log Entry # 13,Data Off
Method Log Entry # 14,Isothermal 2 minutes
Method Log Entry # 15,Data On
Method Log Entry # 16,(Ramp 1275831) Ramp 10 °C/minute to -60 °C
Method Log Entry # 17,Data Off
Method Log Entry # 18,Isothermal 2 minutes
Method Log Entry # 19,Data On
Method Log Entry # 20,(Ramp 1275835) Ramp 10 °C/minute to 200 °C
Method Log Entry # 21,Data Off
Method Log Entry # 22,Isothermal 2 minutes
Method Log Entry # 23,Data On
Method Log Entry # 24,(Ramp 1275839) Ramp 10 °C/minute to -60 °C
Method Log Entry # 25,Data Off
Method Log Entry # 26,Isothermal 2 minutes
Method Log Entry # 27,Data On
Method Log Entry # 28,(Ramp 1275843) Ramp 10 °C/minute to 30 °C
Cell Serial,DRC2-00792
[T1 Calibration]
Slope,-0.008529666
Offset,9.636258
Initial Temperature,98.23
GUID,f8bfdadc-4977-4fdf-ba6d-0ba9134940c3
[TZero Calibration]
Date Applied,11/29/2022 4:06:13 PM
Description,From -89.059 °C to 396.009 °C at 20.000°C/min
Gas Type,Nitrogen
Pan Type,None
Source Files 1,C:\Users\yargerlab\Desktop\DSC Data\General\TZero_calibration_11_29_22_2nd(2).tri
Source Files 2,C:\Users\yargerlab\Desktop\DSC Data\General\TZero_calibration_11_29_22_2nd(3).tri
Delta T Offset,13.05235
Delta T Slope,-0.007271007
Delta T0 Offset,-13.69128
Delta T0 Slope,0.06063341
[Temperature Calibration]
Date Applied,11/29/2022 7:12:28 PM
Description,From 106.590 °C to 186.590 °C at 10.000°C/min
Gas Type,Nitrogen
Pan Type,Tzero Aluminum Hermetic
Source Files 1,C:\Users\yargerlab\Desktop\DSC Data\General\Indium(6).tri
Measured 1,157.391
Known 1,156.598
[Cell Constant Calibration]
Date Applied,11/29/2022 7:12:29 PM
Description,From 106.590 °C to 186.590 °C at 10.000°C/min
Gas Type,Nitrogen
Pan Type,Tzero Aluminum Hermetic
Source Files 1,C:\Users\yargerlab\Desktop\DSC Data\General\Indium(6).tri
T4P KCell,1.006051
Onset Slope,63.26126 mW/°C
[Direct Cp Calibration]
Date Applied,11/30/2022 11:04:51 AM
Description,From -79.983 °C to 298.409 °C at 10.000°C/min
Gas Type,Nitrogen
Pan Type,Tzero Aluminum Hermetic
Source Files 1,C:\Users\yargerlab\Desktop\DSC Data\General\Sapphire_Heat_Capacity_11_30_22.tri
[Rev Cp Calibration]
Date Applied,11/30/2022 1:58:51 PM
Description,From -79.996 °C to 292.812 °C at 3.000°C/min
Gas Type,Nitrogen
Pan Type,Tzero Aluminum Hermetic
Source Files 1,C:\Users\yargerlab\Desktop\DSC Data\General\Sapphire_MDSC_Calibration_11_30_22.tri
[step]
Ramp 10.00 °C/min to 200.00 °C
Time,Temperature,Heat Flow (Normalized)
min,°C,W/g
0.00,-59.82,-0.053
0.02,-59.83,-0.050
0.04,-59.83,-0.048
0.05,-59.81,-0.048
0.07,-59.78,-0.051
0.09,-59.72,-0.058
0.11,-59.62,-0.061
0.13,-59.51,-0.060
0.15,-59.37,-0.039
0.16,-59.23,-0.012
0.18,-59.06,0.013
0.20,-58.90,0.036
0.22,-58.72,0.058
0.24,-58.54,0.077
0.26,-58.37,0.092
0.28,-58.19,0.104
0.29,-58.01,0.113
0.31,-57.84,0.119
0.33,-57.66,0.125
0.35,-57.48,0.128
0.37,-57.30,0.131
0.39,-57.12,0.133
0.40,-56.94,0.135
0.42,-56.76,0.136
0.44,-56.58,0.137
0.46,-56.40,0.138
0.48,-56.22,0.139
0.50,-56.04,0.139
0.51,-55.86,0.140
0.53,-55.68,0.140
0.55,-55.50,0.141
0.57,-55.32,0.142
0.59,-55.14,0.142
0.60,-54.95,0.143
0.62,-54.77,0.143
0.64,-54.59,0.144
0.66,-54.41,0.144
0.68,-54.23,0.145
0.70,-54.05,0.146
0.72,-53.87,0.146
0.73,-53.69,0.147
0.75,-53.51,0.147
0.77,-53.32,0.148
0.79,-53.14,0.148
0.81,-52.96,0.149
0.83,-52.78,0.149
0.84,-52.60,0.150
0.86,-52.41,0.150
0.88,-52.23,0.151
0.90,-52.05,0.151
0.92,-51.87,0.152
0.93,-51.69,0.152
0.95,-51.50,0.153
0.97,-51.32,0.153
0.99,-51.14,0.154
1.01,-50.96,0.154
1.03,-50.77,0.154
1.05,-50.59,0.155
1.06,-50.41,0.155
1.08,-50.22,0.155
1.10,-50.04,0.156
1.12,-49.86,0.156
1.14,-49.68,0.156
1.16,-49.49,0.157
1.17,-49.31,0.157
1.19,-49.13,0.157
1.21,-48.95,0.158
1.23,-48.76,0.158
1.25,-48.58,0.158
1.27,-48.40,0.158
1.28,-48.21,0.159
1.30,-48.03,0.159
1.32,-47.85,0.159
1.34,-47.66,0.159
1.36,-47.48,0.159
1.38,-47.30,0.160
1.39,-47.12,0.160
1.41,-46.93,0.160
1.43,-46.75,0.160
1.45,-46.57,0.160
1.47,-46.38,0.161
1.48,-46.20,0.161
1.50,-46.02,0.161
1.52,-45.83,0.161
1.54,-45.65,0.161
1.56,-45.47,0.161
1.58,-45.28,0.162
1.59,-45.10,0.162
1.61,-44.92,0.162
1.63,-44.73,0.162
1.65,-44.55,0.162
1.67,-44.37,0.162
1.69,-44.18,0.162
1.71,-44.00,0.162
1.72,-43.82,0.162
1.74,-43.63,0.163
1.76,-43.45,0.163
1.78,-43.27,0.163
1.80,-43.08,0.163
1.82,-42.90,0.163
1.83,-42.71,0.163
1.85,-42.53,0.163
1.87,-42.35,0.163
1.89,-42.16,0.163
1.91,-41.98,0.163
1.93,-41.80,0.163
1.94,-41.61,0.163
1.96,-41.43,0.163
1.98,-41.25,0.163
2.00,-41.06,0.163
2.02,-40.88,0.163
2.03,-40.70,0.164
2.05,-40.51,0.164
2.07,-40.33,0.164
2.09,-40.15,0.164
2.11,-39.96,0.164
2.13,-39.78,0.164
2.14,-39.59,0.164
2.16,-39.41,0.164
2.18,-39.23,0.164
2.20,-39.05,0.164
2.22,-38.86,0.164
2.24,-38.68,0.164
2.26,-38.49,0.164
2.27,-38.31,0.164
2.29,-38.13,0.164
2.31,-37.94,0.164
2.33,-37.76,0.164
2.35,-37.58,0.164
2.36,-37.39,0.164
2.38,-37.21,0.164
2.40,-37.03,0.164
2.42,-36.84,0.164
2.44,-36.66,0.164
2.46,-36.48,0.164
2.48,-36.29,0.165
2.49,-36.11,0.165
2.51,-35.92,0.165
2.53,-35.74,0.165
2.55,-35.56,0.165
2.57,-35.37,0.165
2.59,-35.19,0.165
2.60,-35.01,0.165
2.62,-34.82,0.165
2.64,-34.64,0.165
2.66,-34.46,0.165
2.68,-34.27,0.165
2.69,-34.09,0.165
2.71,-33.91,0.165
2.73,-33.72,0.165
2.75,-33.54,0.165
2.77,-33.36,0.165
2.79,-33.17,0.165
2.81,-32.99,0.165
2.82,-32.80,0.165
2.84,-32.62,0.165
2.86,-32.44,0.165
2.88,-32.25,0.165
2.90,-32.07,0.165
2.91,-31.89,0.165
2.93,-31.70,0.165
2.95,-31.52,0.165
2.97,-31.34,0.165
2.99,-31.15,0.165
3.01,-30.97,0.165
3.03,-30.79,0.165
3.04,-30.60,0.165
3.06,-30.42,0.165
3.08,-30.23,0.165
3.10,-30.05,0.165
3.12,-29.87,0.165
3.14,-29.68,0.165
3.15,-29.50,0.165
3.17,-29.32,0.165
3.19,-29.13,0.165
3.21,-28.95,0.165
3.23,-28.77,0.165
3.24,-28.58,0.165
3.26,-28.40,0.166
3.28,-28.21,0.166
3.30,-28.03,0.166
3.32,-27.85,0.166
3.34,-27.66,0.166
3.36,-27.48,0.166
3.37,-27.30,0.166
3.39,-27.11,0.166
3.41,-26.93,0.166
3.43,-26.75,0.166
3.45,-26.56,0.166
3.46,-26.38,0.166
3.48,-26.19,0.166
3.50,-26.01,0.166
3.52,-25.83,0.166
3.54,-25.64,0.166
3.56,-25.46,0.166
3.58,-25.28,0.166
3.59,-25.09,0.167
3.61,-24.91,0.167
3.63,-24.73,0.167
3.65,-24.54,0.167
3.67,-24.36,0.167
3.69,-24.18,0.167
3.70,-23.99,0.167
3.72,-23.81,0.167
3.74,-23.62,0.167
3.76,-23.44,0.167
3.78,-23.26,0.167
3.79,-23.07,0.167
3.81,-22.89,0.167
3.83,-22.71,0.167
3.85,-22.52,0.167
3.87,-22.34,0.167
3.89,-22.16,0.167
3.91,-21.97,0.167
3.92,-21.79,0.167
3.94,-21.60,0.168
3.96,-21.42,0.168
3.98,-21.24,0.168
4.00,-21.05,0.168
4.01,-20.87,0.168
4.03,-20.68,0.168
4.05,-20.50,0.168
4.07,-20.32,0.168
4.09,-20.13,0.168
4.11,-19.95,0.168
4.13,-19.77,0.168
4.14,-19.59,0.168
4.16,-19.40,0.168
4.18,-19.22,0.168
4.20,-19.03,0.169
4.22,-18.85,0.169
4.24,-18.67,0.169
4.25,-18.48,0.169
4.27,-18.30,0.169
4.29,-18.12,0.169
4.31,-17.94,0.169
4.33,-17.75,0.169
4.35,-17.57,0.169
4.36,-17.39,0.169
4.38,-17.20,0.169
4.40,-17.02,0.169
4.42,-16.84,0.169
4.44,-16.65,0.169
4.45,-16.47,0.169
4.47,-16.28,0.169
4.49,-16.10,0.169
4.51,-15.92,0.170
4.53,-15.73,0.170
4.55,-15.55,0.170
4.56,-15.36,0.170
4.58,-15.18,0.170
4.60,-15.00,0.170
4.62,-14.81,0.170
4.64,-14.63,0.170
4.66,-14.45,0.170
4.68,-14.26,0.170
4.69,-14.08,0.171
4.71,-13.90,0.171
4.73,-13.71,0.171
4.75,-13.53,0.171
4.77,-13.35,0.171
4.79,-13.16,0.171
4.80,-12.98,0.171
4.82,-12.80,0.171
4.84,-12.61,0.171
4.86,-12.43,0.171
4.88,-12.24,0.171
4.90,-12.06,0.172
4.91,-11.88,0.172
4.93,-11.69,0.172
4.95,-11.51,0.172
4.97,-11.33,0.172
4.99,-11.14,0.172
5.00,-10.96,0.172
5.02,-10.78,0.172
5.04,-10.59,0.172
5.06,-10.41,0.172
5.08,-10.23,0.172
5.10,-10.04,0.173
5.11,-9.86,0.173
5.13,-9.68,0.173
5.15,-9.49,0.173
5.17,-9.31,0.173
5.19,-9.13,0.173
5.21,-8.94,0.173
5.23,-8.76,0.173
5.24,-8.58,0.173
5.26,-8.39,0.174
5.28,-8.21,0.174
5.30,-8.03,0.174
5.32,-7.84,0.174
5.34,-7.66,0.174
5.35,-7.47,0.174
5.37,-7.29,0.174
5.39,-7.11,0.174
5.41,-6.92,0.174
5.43,-6.74,0.175
5.45,-6.56,0.175
5.46,-6.37,0.175
5.48,-6.19,0.175
5.50,-6.01,0.175
5.52,-5.82,0.175
5.54,-5.64,0.175
5.55,-5.46,0.176
5.57,-5.27,0.176
5.59,-5.09,0.176
5.61,-4.90,0.176
5.63,-4.72,0.176
5.65,-4.54,0.176
5.66,-4.36,0.176
5.68,-4.17,0.176
5.70,-3.99,0.177
5.72,-3.80,0.177
5.74,-3.62,0.177
5.76,-3.44,0.177
5.78,-3.25,0.177
5.79,-3.07,0.177
5.81,-2.89,0.177
5.83,-2.70,0.178
5.85,-2.52,0.178
5.87,-2.34,0.178
5.89,-2.15,0.178
5.90,-1.97,0.178
5.92,-1.79,0.178
5.94,-1.60,0.178
5.96,-1.42,0.179
5.98,-1.23,0.179
6.00,-1.05,0.179
6.01,-0.87,0.179
6.03,-0.68,0.179
6.05,-0.50,0.179
6.07,-0.32,0.179
6.09,-0.13,0.180
6.10,0.05,0.180
6.12,0.23,0.180
6.14,0.42,0.180
6.16,0.60,0.180
6.18,0.78,0.180
6.20,0.97,0.181
6.21,1.15,0.181
6.23,1.33,0.181
6.25,1.52,0.181
6.27,1.70,0.181
6.29,1.88,0.181
6.31,2.07,0.181
6.33,2.25,0.182
6.34,2.44,0.182
6.36,2.62,0.182
6.38,2.80,0.182
6.40,2.99,0.182
6.42,3.17,0.182
6.44,3.35,0.183
6.45,3.54,0.183
6.47,3.72,0.183
6.49,3.90,0.183
6.51,4.09,0.183
6.53,4.27,0.184
6.55,4.45,0.184
6.56,4.64,0.184
6.58,4.82,0.184
6.60,5.00,0.184
6.62,5.19,0.184
6.64,5.37,0.185
6.65,5.55,0.185
6.67,5.74,0.185
6.69,5.92,0.185
6.71,6.11,0.186
6.73,6.29,0.186
6.75,6.47,0.186
6.76,6.66,0.186
6.78,6.84,0.186
6.80,7.02,0.187
6.82,7.21,0.187
6.84,7.39,0.187
6.86,7.57,0.187
6.88,7.76,0.187
6.89,7.94,0.188
6.91,8.12,0.188
6.93,8.31,0.188
6.95,8.49,0.188
6.97,8.68,0.189
6.99,8.86,0.189
7.00,9.04,0.189
7.02,9.22,0.189
7.04,9.41,0.189
7.06,9.59,0.190
7.08,9.77,0.190
7.10,9.96,0.190
7.11,10.14,0.190
7.13,10.32,0.191
7.15,10.51,0.191
7.17,10.69,0.191
7.19,10.88,0.191
7.20,11.06,0.191
7.22,11.24,0.192
7.24,11.43,0.192
7.26,11.61,0.192
7.28,11.79,0.192
7.30,11.98,0.193
7.31,12.16,0.193
7.33,12.34,0.193
7.35,12.53,0.193
7.37,12.71,0.194
7.39,12.89,0.194
7.41,13.08,0.194
7.43,13.26,0.194
7.44,13.44,0.195
7.46,13.63,0.195
7.48,13.81,0.195
7.50,14.00,0.196
7.52,14.18,0.196
7.54,14.36,0.196
7.55,14.55,0.196
7.57,14.73,0.197
7.59,14.91,0.197
7.61,15.09,0.197
7.63,15.28,0.197
7.65,15.46,0.198
7.66,15.65,0.198
7.68,15.83,0.198
7.70,16.01,0.199
7.72,16.20,0.199
7.74,16.38,0.199
7.75,16.56,0.199
7.77,16.75,0.200
7.79,16.93,0.200
7.81,17.11,0.200
7.83,17.30,0.200
7.85,17.48,0.201
7.86,17.66,0.201
7.88,17.85,0.201
7.90,18.03,0.202
7.92,18.21,0.202
7.94,18.40,0.202
7.96,18.58,0.203
7.98,18.76,0.203
7.99,18.95,0.203
8.01,19.13,0.204
8.03,19.31,0.204
8.05,19.50,0.204
8.07,19.68,0.205
8.09,19.87,0.205
8.10,20.05,0.205
8.12,20.23,0.206
8.14,20.41,0.206
8.16,20.60,0.207
8.18,20.78,0.207
8.20,20.96,0.207
8.21,21.15,0.208
8.23,21.33,0.208
8.25,21.52,0.209
8.27,21.70,0.209
8.29,21.88,0.209
8.30,22.07,0.210
8.32,22.25,0.210
8.34,22.43,0.211
8.36,22.62,0.211
8.38,22.80,0.211
8.40,22.98,0.212
8.41,23.17,0.212
8.43,23.35,0.213
8.45,23.53,0.213
8.47,23.72,0.213
8.49,23.90,0.214
8.51,24.08,0.214
8.53,24.27,0.215
8.54,24.45,0.215
8.56,24.63,0.216
8.58,24.81,0.216
8.60,25.00,0.217
8.62,25.18,0.217
8.63,25.37,0.218
8.65,25.55,0.218
8.67,25.73,0.219
8.69,25.92,0.219
8.71,26.10,0.220
8.73,26.28,0.220
8.75,26.46,0.221
8.76,26.65,0.222
8.78,26.83,0.222
8.80,27.02,0.223
8.82,27.20,0.223
8.84,27.38,0.224
8.85,27.56,0.224
8.87,27.75,0.225
8.89,27.93,0.226
8.91,28.11,0.226
8.93,28.30,0.227
8.95,28.48,0.227
8.97,28.66,0.228
8.98,28.85,0.229
9.00,29.03,0.229
9.02,29.22,0.230
9.04,29.40,0.231
9.06,29.58,0.231
9.08,29.76,0.232
9.09,29.95,0.233
9.11,30.13,0.234
9.13,30.31,0.234
9.15,30.50,0.235
9.17,30.68,0.236
9.18,30.86,0.237
9.20,31.05,0.238
9.22,31.23,0.238
9.24,31.41,0.239
9.26,31.60,0.240
9.28,31.78,0.241
9.30,31.97,0.242
9.31,32.15,0.243
9.33,32.33,0.244
9.35,32.51,0.244
9.37,32.70,0.246
9.39,32.88,0.247
9.40,33.06,0.247
9.42,33.25,0.248
9.44,33.43,0.249
9.46,33.61,0.250
9.48,33.80,0.251
9.50,33.98,0.252
9.52,34.16,0.253
9.53,34.35,0.255
9.55,34.53,0.256
9.57,34.71,0.257
9.59,34.90,0.258
9.61,35.08,0.260
9.63,35.26,0.261
9.64,35.45,0.262
9.66,35.63,0.263
9.68,35.81,0.264
9.70,36.00,0.265
9.72,36.18,0.266
9.73,36.36,0.267
9.75,36.55,0.268
9.77,36.73,0.269
9.79,36.91,0.270
9.81,37.10,0.271
9.83,37.28,0.272
9.85,37.46,0.274
9.86,37.65,0.275
9.88,37.83,0.276
9.90,38.01,0.277
9.92,38.20,0.278
9.94,38.38,0.279
9.95,38.56,0.280
9.97,38.74,0.281
9.99,38.93,0.281
10.01,39.11,0.282
10.03,39.30,0.283
10.05,39.48,0.284
10.07,39.66,0.285
10.08,39.84,0.286
10.10,40.03,0.287
10.12,40.21,0.288
10.14,40.39,0.288
10.16,40.58,0.289
10.18,40.76,0.290
10.19,40.94,0.291
10.21,41.13,0.291
10.23,41.31,0.292
10.25,41.50,0.293
10.27,41.68,0.294
10.28,41.86,0.294
10.30,42.04,0.295
10.32,42.23,0.296
10.34,42.41,0.296
10.36,42.60,0.297
10.38,42.78,0.297
10.40,42.96,0.298
10.41,43.15,0.299
10.43,43.33,0.299
10.45,43.51,0.299
10.47,43.70,0.300
10.49,43.88,0.300
10.50,44.06,0.301
10.52,44.25,0.301
10.54,44.43,0.301
10.56,44.61,0.302
10.58,44.80,0.302
10.60,44.98,0.302
10.62,45.17,0.302
10.63,45.35,0.302
10.65,45.53,0.303
10.67,45.72,0.303
10.69,45.90,0.303
10.71,46.08,0.303
10.73,46.27,0.303
10.74,46.45,0.303
10.76,46.63,0.303
10.78,46.82,0.303
10.80,47.00,0.302
10.82,47.18,0.302
10.83,47.37,0.302
10.85,47.55,0.302
10.87,47.74,0.302
10.89,47.92,0.302
10.91,48.10,0.301
10.93,48.29,0.301
10.95,48.47,0.301
10.96,48.65,0.301
10.98,48.84,0.300
11.00,49.02,0.300
11.02,49.20,0.300
11.04,49.39,0.300
11.05,49.57,0.299
11.07,49.76,0.299
11.09,49.94,0.299
11.11,50.12,0.298
11.13,50.31,0.298
11.15,50.49,0.297
11.17,50.67,0.297
11.18,50.86,0.297
11.20,51.04,0.296
11.22,51.22,0.296
11.24,51.41,0.295
11.26,51.59,0.295
11.28,51.77,0.295
11.29,51.96,0.294
11.31,52.14,0.294
11.33,52.33,0.293
11.35,52.51,0.293
11.37,52.69,0.293
11.38,52.88,0.292
11.40,53.06,0.292
11.42,53.24,0.292
11.44,53.43,0.291
11.46,53.61,0.291
11.48,53.79,0.290
11.50,53.98,0.290
11.51,54.16,0.290
11.53,54.35,0.289
11.55,54.53,0.289
11.57,54.71,0.289
11.59,54.90,0.289
11.60,55.08,0.288
11.62,55.26,0.288
11.64,55.45,0.288
11.66,55.63,0.287
11.68,55.82,0.287
11.70,56.00,0.287
11.72,56.18,0.287
11.73,56.37,0.286
11.75,56.55,0.286
11.77,56.73,0.286
11.79,56.92,0.286
11.81,57.10,0.285
11.83,57.28,0.285
11.84,57.47,0.285
11.86,57.65,0.285
11.88,57.83,0.285
11.90,58.02,0.284
11.92,58.20,0.284
11.93,58.39,0.284
11.95,58.57,0.284
11.97,58.75,0.284
11.99,58.94,0.284
12.01,59.12,0.283
12.03,59.30,0.283
12.05,59.49,0.283
12.06,59.67,0.283
12.08,59.85,0.283
12.10,60.04,0.283
12.12,60.22,0.283
12.14,60.40,0.283
12.15,60.59,0.283
12.17,60.77,0.283
12.19,60.95,0.282
12.21,61.14,0.282
12.23,61.32,0.282
12.25,61.50,0.282
12.27,61.69,0.282
12.28,61.87,0.282
12.30,62.06,0.282
12.32,62.24,0.282
12.34,62.42,0.282
12.36,62.61,0.282
12.38,62.79,0.282
12.39,62.97,0.282
12.41,63.16,0.282
12.43,63.34,0.282
12.45,63.52,0.282
12.47,63.71,0.282
12.48,63.89,0.282
12.50,64.07,0.282
12.52,64.26,0.282
12.54,64.44,0.282
12.56,64.62,0.282
12.58,64.81,0.282
12.60,64.99,0.282
12.61,65.18,0.282
12.63,65.36,0.282
12.65,65.55,0.282
12.67,65.73,0.283
12.69,65.91,0.283
12.70,66.10,0.283
12.72,66.28,0.283
12.74,66.46,0.283
12.76,66.65,0.283
12.78,66.83,0.283
12.80,67.01,0.283
12.82,67.20,0.283
12.83,67.38,0.283
12.85,67.56,0.283
12.87,67.75,0.283
12.89,67.93,0.283
12.91,68.11,0.283
12.93,68.29,0.283
12.94,68.48,0.283
12.96,68.66,0.283
12.98,68.84,0.283
13.00,69.03,0.283
13.02,69.21,0.283
13.03,69.39,0.283
13.05,69.58,0.283
13.07,69.76,0.283
13.09,69.95,0.283
13.11,70.13,0.284
13.13,70.31,0.284
13.15,70.50,0.284
13.16,70.68,0.284
13.18,70.86,0.284
13.20,71.05,0.284
13.22,71.23,0.284
13.24,71.42,0.284
13.25,71.60,0.285
13.27,71.78,0.285
13.29,71.97,0.285
13.31,72.15,0.285
13.33,72.33,0.285
13.35,72.52,0.285
13.37,72.70,0.286
13.38,72.88,0.286
13.40,73.07,0.286
13.42,73.25,0.286
13.44,73.44,0.286
13.46,73.62,0.286
13.48,73.80,0.286
13.49,73.98,0.286
13.51,74.17,0.286
13.53,74.35,0.286
13.55,74.54,0.286
13.57,74.72,0.287
13.58,74.90,0.287
13.60,75.09,0.287
13.62,75.27,0.287
13.64,75.45,0.287
13.66,75.64,0.287
13.68,75.82,0.287
13.70,76.00,0.287
13.71,76.19,0.287
13.73,76.37,0.287
13.75,76.55,0.287
13.77,76.74,0.288
13.79,76.92,0.288
13.80,77.10,0.288
13.82,77.29,0.288
13.84,77.47,0.288
13.86,77.65,0.288
13.88,77.84,0.288
13.90,78.02,0.288
13.92,78.20,0.288
13.93,78.39,0.288
13.95,78.57,0.288
13.97,78.75,0.288
13.99,78.94,0.289
14.01,79.12,0.289
14.03,79.30,0.289
14.04,79.49,0.289
14.06,79.67,0.289
14.08,79.85,0.289
14.10,80.04,0.289
14.12,80.22,0.289
14.13,80.40,0.289
14.15,80.59,0.289
14.17,80.77,0.289
14.19,80.96,0.289
14.21,81.14,0.289
14.23,81.33,0.290
14.25,81.51,0.290
14.26,81.69,0.290
14.28,81.88,0.290
14.30,82.06,0.290
14.32,82.24,0.290
14.34,82.43,0.290
14.35,82.61,0.290
14.37,82.79,0.290
14.39,82.98,0.290
14.41,83.16,0.290
14.43,83.34,0.290
14.45,83.53,0.290
14.47,83.71,0.290
14.48,83.89,0.290
14.50,84.08,0.290
14.52,84.26,0.290
14.54,84.44,0.290
14.56,84.63,0.290
14.58,84.81,0.290
14.59,84.99,0.290
14.61,85.18,0.290
14.63,85.36,0.290
14.65,85.54,0.290
14.67,85.73,0.290
14.68,85.91,0.290
14.70,86.09,0.290
14.72,86.28,0.290
14.74,86.46,0.290
14.76,86.64,0.290
14.78,86.82,0.290
14.80,87.01,0.289
14.81,87.19,0.289
14.83,87.37,0.289
14.85,87.56,0.289
14.87,87.74,0.289
14.89,87.92,0.289
14.90,88.11,0.289
14.92,88.29,0.289
14.94,88.48,0.290
14.96,88.66,0.290
14.98,88.84,0.290
15.00,89.03,0.290
15.02,89.21,0.290
15.03,89.39,0.290
15.05,89.58,0.290
15.07,89.76,0.290
15.09,89.95,0.291
15.11,90.13,0.291
15.13,90.31,0.291
15.14,90.50,0.291
15.16,90.68,0.291
15.18,90.86,0.291
15.20,91.05,0.291
15.22,91.23,0.291
15.23,91.41,0.291
15.25,91.60,0.291
15.27,91.78,0.291
15.29,91.96,0.292
15.31,92.15,0.292
15.33,92.33,0.292
15.35,92.51,0.292
15.36,92.70,0.292
15.38,92.88,0.292
15.40,93.07,0.292
15.42,93.25,0.292
15.44,93.43,0.292
15.45,93.62,0.292
15.47,93.80,0.292
15.49,93.98,0.292
15.51,94.17,0.292
15.53,94.35,0.292
15.55,94.53,0.292
15.57,94.72,0.293
15.58,94.90,0.293
15.60,95.09,0.293
15.62,95.27,0.293
15.64,95.45,0.293
15.66,95.64,0.293
15.68,95.82,0.293
15.69,96.00,0.293
15.71,96.19,0.293
15.73,96.37,0.293
15.75,96.55,0.293
15.77,96.74,0.293
15.78,96.92,0.293
15.80,97.10,0.293
15.82,97.29,0.293
15.84,97.47,0.293
15.86,97.65,0.293
15.88,97.84,0.293
15.90,98.02,0.294
15.91,98.20,0.294
15.93,98.39,0.294
15.95,98.57,0.294
15.97,98.75,0.294
15.99,98.94,0.294
16.00,99.12,0.294
16.02,99.30,0.294
16.04,99.49,0.294
16.06,99.67,0.294
16.08,99.86,0.294
16.10,100.04,0.294
16.12,100.22,0.294
16.13,100.41,0.294
16.15,100.60,0.295
16.17,100.78,0.295
16.19,100.96,0.295
16.21,101.15,0.295
16.23,101.33,0.295
16.24,101.51,0.295
16.26,101.70,0.295
16.28,101.88,0.295
16.30,102.06,0.295
16.32,102.25,0.295
16.33,102.43,0.295
16.35,102.61,0.295
16.37,102.80,0.295
16.39,102.98,0.295
16.41,103.16,0.295
16.43,103.35,0.295
16.45,103.53,0.295
16.46,103.71,0.295
16.48,103.90,0.295
16.50,104.08,0.295
16.52,104.26,0.295
16.54,104.45,0.295
16.55,104.63,0.295
16.57,104.81,0.295
16.59,105.00,0.295
16.61,105.18,0.295
16.63,105.36,0.295
16.65,105.55,0.295
16.67,105.73,0.295
16.68,105.91,0.295
16.70,106.10,0.295
16.72,106.28,0.295
16.74,106.46,0.295
16.76,106.65,0.295
16.78,106.83,0.295
16.79,107.01,0.295
16.81,107.20,0.295
16.83,107.38,0.295
16.85,107.56,0.295
16.87,107.75,0.295
16.88,107.93,0.295
16.90,108.11,0.295
16.92,108.30,0.295
16.94,108.48,0.295
16.96,108.66,0.295
16.98,108.85,0.295
17.00,109.03,0.295
17.01,109.22,0.295
17.03,109.40,0.295
17.05,109.58,0.295
17.07,109.76,0.295
17.09,109.95,0.295
17.11,110.13,0.295
17.12,110.31,0.295
17.14,110.50,0.295
17.16,110.68,0.295
17.18,110.87,0.295
17.20,111.05,0.295
17.22,111.23,0.295
17.23,111.42,0.295
17.25,111.60,0.295
17.27,111.79,0.295
17.29,111.97,0.295
17.31,112.15,0.295
17.33,112.33,0.295
17.34,112.52,0.295
17.36,112.70,0.295
17.38,112.88,0.295
17.40,113.07,0.295
17.42,113.25,0.295
17.43,113.43,0.295
17.45,113.62,0.295
17.47,113.80,0.295
17.49,113.99,0.295
17.51,114.17,0.295
17.53,114.35,0.295
17.54,114.54,0.295
17.56,114.72,0.295
17.58,114.90,0.295
17.60,115.09,0.295
17.62,115.27,0.295
17.64,115.45,0.295
17.66,115.64,0.295
17.67,115.82,0.295
17.69,116.00,0.295
17.71,116.19,0.295
17.73,116.37,0.295
17.75,116.56,0.295
17.77,116.74,0.295
17.78,116.92,0.295
17.80,117.11,0.295
17.82,117.29,0.295
17.84,117.47,0.295
17.86,117.65,0.295
17.88,117.84,0.295
17.89,118.02,0.295
17.91,118.20,0.295
17.93,118.39,0.295
17.95,118.57,0.295
17.97,118.75,0.295
17.98,118.94,0.295
18.00,119.12,0.295
18.02,119.31,0.295
18.04,119.49,0.295
18.06,119.67,0.295
18.08,119.86,0.295
18.09,120.04,0.295
18.11,120.22,0.295
18.13,120.41,0.295
18.15,120.59,0.295
18.17,120.77,0.295
18.19,120.96,0.295
18.21,121.14,0.295
18.22,121.32,0.295
18.24,121.51,0.294
18.26,121.69,0.294
18.28,121.88,0.294
18.30,122.06,0.294
18.32,122.24,0.294
18.33,122.43,0.294
18.35,122.61,0.294
18.37,122.79,0.294
18.39,122.98,0.294
18.41,123.16,0.294
18.43,123.34,0.294
18.44,123.53,0.294
18.46,123.71,0.294
18.48,123.89,0.294
18.50,124.08,0.294
18.52,124.26,0.294
18.53,124.44,0.294
18.55,124.63,0.294
18.57,124.81,0.294
18.59,124.99,0.294
18.61,125.18,0.294
18.63,125.36,0.294
18.64,125.54,0.294
18.66,125.73,0.294
18.68,125.91,0.294
18.70,126.09,0.294
18.72,126.28,0.294
18.74,126.46,0.294
18.76,126.65,0.293
18.77,126.83,0.293
18.79,127.01,0.293
18.81,127.20,0.293
18.83,127.38,0.293
18.85,127.56,0.293
18.87,127.75,0.293
18.88,127.93,0.293
18.90,128.11,0.293
18.92,128.30,0.293
18.94,128.48,0.293
18.96,128.67,0.293
18.98,128.85,0.293
18.99,129.03,0.293
19.01,129.21,0.293
19.03,129.40,0.293
19.05,129.58,0.292
19.07,129.76,0.292
19.08,129.95,0.292
19.10,130.13,0.292
19.12,130.32,0.292
19.14,130.50,0.292
19.16,130.68,0.292
19.18,130.87,0.292
19.19,131.05,0.292
19.21,131.23,0.292
19.23,131.42,0.291
19.25,131.60,0.291
19.27,131.78,0.291
19.29,131.97,0.291
19.31,132.15,0.291
19.32,132.33,0.291
19.34,132.52,0.291
19.36,132.70,0.291
19.38,132.88,0.290
19.40,133.07,0.290
19.42,133.25,0.290
19.43,133.44,0.290
19.45,133.62,0.290
19.47,133.80,0.290
19.49,133.99,0.290
19.51,134.17,0.290
19.53,134.35,0.290
19.54,134.54,0.290
19.56,134.72,0.290
19.58,134.90,0.290
19.60,135.09,0.289
19.62,135.27,0.289
19.63,135.45,0.289
19.65,135.64,0.289
19.67,135.82,0.289
19.69,136.00,0.289
19.71,136.19,0.289
19.73,136.37,0.289
19.74,136.55,0.289
19.76,136.74,0.288
19.78,136.92,0.288
19.80,137.10,0.288
19.82,137.29,0.288
19.84,137.47,0.288
19.86,137.65,0.288
19.87,137.84,0.288
19.89,138.02,0.288
19.91,138.20,0.288
19.93,138.39,0.288
19.95,138.57,0.288
19.97,138.76,0.288
19.98,138.94,0.288
20.00,139.12,0.288
20.02,139.31,0.288
20.04,139.49,0.287
20.06,139.67,0.287
20.08,139.86,0.287
20.09,140.04,0.287
20.11,140.22,0.287
20.13,140.41,0.287
20.15,140.59,0.287
20.17,140.77,0.287
20.18,140.96,0.287
20.20,141.14,0.287
20.22,141.33,0.287
20.24,141.51,0.287
20.26,141.69,0.287
20.28,141.88,0.287
20.29,142.06,0.287
20.31,142.24,0.286
20.33,142.43,0.286
20.35,142.61,0.286
20.37,142.79,0.286
20.39,142.98,0.286
20.41,143.16,0.286
20.42,143.34,0.286
20.44,143.53,0.286
20.46,143.71,0.286
20.48,143.89,0.286
20.50,144.08,0.286
20.52,144.26,0.285
20.53,144.44,0.285
20.55,144.63,0.285
20.57,144.81,0.285
20.59,144.99,0.285
20.61,145.18,0.285
20.63,145.36,0.285
20.64,145.54,0.285
20.66,145.73,0.285
20.68,145.91,0.285
20.70,146.10,0.285
20.72,146.28,0.284
20.73,146.46,0.284
20.75,146.65,0.284
20.77,146.83,0.284
20.79,147.01,0.284
20.81,147.20,0.284
20.83,147.38,0.284
20.84,147.56,0.284
20.86,147.75,0.284
20.88,147.93,0.284
20.90,148.11,0.284
20.92,148.30,0.284
20.94,148.48,0.284
20.96,148.67,0.283
20.97,148.85,0.283
20.99,149.03,0.283
21.01,149.21,0.283
21.03,149.40,0.283
21.05,149.58,0.283
21.07,149.77,0.283
21.08,149.95,0.283
21.10,150.13,0.283
21.12,150.32,0.283
21.14,150.50,0.283
21.16,150.68,0.283
21.18,150.87,0.282
21.19,151.05,0.282
21.21,151.23,0.282
21.23,151.42,0.282
21.25,151.60,0.282
21.27,151.78,0.282
21.28,151.97,0.282
21.30,152.15,0.282
21.32,152.33,0.282
21.34,152.52,0.282
21.36,152.70,0.282
21.38,152.89,0.282
21.39,153.07,0.282
21.41,153.25,0.282
21.43,153.44,0.282
21.45,153.62,0.282
21.47,153.80,0.282
21.49,153.99,0.282
21.51,154.17,0.282
21.52,154.35,0.282
21.54,154.54,0.282
21.56,154.72,0.282
21.58,154.90,0.282
21.60,155.09,0.282
21.62,155.27,0.282
21.63,155.45,0.282
21.65,155.64,0.282
21.67,155.82,0.282
21.69,156.00,0.282
21.71,156.19,0.282
21.73,156.37,0.282
21.74,156.55,0.282
21.76,156.74,0.282
21.78,156.92,0.282
21.80,157.11,0.282
21.82,157.29,0.282
21.83,157.47,0.282
21.85,157.66,0.282
21.87,157.84,0.282
21.89,158.02,0.283
21.91,158.20,0.283
21.93,158.39,0.283
21.94,158.57,0.283
21.96,158.76,0.283
21.98,158.94,0.283
22.00,159.12,0.283
22.02,159.31,0.283
22.04,159.49,0.284
22.06,159.67,0.284
22.07,159.86,0.284
22.09,160.04,0.284
22.11,160.22,0.285
22.13,160.41,0.285
22.15,160.59,0.285
22.17,160.77,0.285
22.18,160.96,0.286
22.20,161.14,0.286
22.22,161.32,0.286
22.24,161.51,0.287
22.26,161.69,0.287
22.28,161.87,0.287
22.29,162.06,0.288
22.31,162.24,0.288
22.33,162.42,0.289
22.35,162.61,0.289
22.37,162.79,0.289
22.38,162.97,0.290
22.40,163.16,0.290
22.42,163.34,0.291
22.44,163.52,0.291
22.46,163.71,0.292
22.48,163.89,0.292
22.49,164.08,0.293
22.51,164.26,0.293
22.53,164.44,0.294
22.55,164.62,0.295
22.57,164.81,0.296
22.59,164.99,0.296
22.61,165.17,0.297
22.62,165.36,0.297
22.64,165.54,0.298
22.66,165.72,0.299
22.68,165.91,0.299
22.70,166.09,0.300
22.72,166.27,0.301
22.73,166.45,0.302
22.75,166.64,0.303
22.77,166.82,0.303
22.79,167.01,0.304
22.81,167.19,0.305
22.83,167.37,0.307
22.84,167.56,0.308
22.86,167.74,0.309
22.88,167.92,0.310
22.90,168.11,0.311
22.92,168.29,0.312
22.93,168.47,0.313
22.95,168.66,0.314
22.97,168.84,0.315
22.99,169.02,0.315
23.01,169.21,0.316
23.03,169.39,0.317
23.04,169.57,0.318
23.06,169.76,0.319
23.08,169.94,0.320
23.10,170.12,0.321
23.12,170.31,0.322
23.14,170.49,0.323
23.16,170.67,0.324
23.17,170.86,0.325
23.19,171.04,0.326
23.21,171.22,0.326
23.23,171.41,0.327
23.25,171.59,0.328
23.27,171.77,0.329
23.28,171.95,0.330
23.30,172.14,0.331
23.32,172.32,0.331
23.34,172.50,0.332
23.36,172.69,0.333
23.38,172.87,0.333
23.39,173.05,0.334
23.41,173.24,0.335
23.43,173.42,0.335
23.45,173.60,0.336
23.47,173.79,0.337
23.48,173.97,0.338
23.50,174.15,0.338
23.52,174.34,0.339
23.54,174.52,0.339
23.56,174.70,0.340
23.58,174.89,0.341
23.59,175.07,0.341
23.61,175.25,0.342
23.63,175.44,0.342
23.65,175.62,0.343
23.67,175.80,0.343
23.69,175.99,0.344
23.71,176.17,0.344
23.72,176.35,0.345
23.74,176.54,0.345
23.76,176.72,0.345
23.78,176.90,0.346
23.80,177.09,0.346
23.82,177.27,0.347
23.83,177.45,0.347
23.85,177.64,0.347
23.87,177.82,0.348
23.89,178.00,0.348
23.91,178.19,0.348
23.93,178.37,0.349
23.94,178.56,0.349
23.96,178.74,0.349
23.98,178.92,0.350
24.00,179.11,0.350
24.02,179.29,0.350
24.03,179.47,0.351
24.05,179.66,0.351
24.07,179.84,0.351
24.09,180.02,0.352
24.11,180.21,0.352
24.13,180.39,0.352
24.14,180.57,0.352
24.16,180.75,0.352
24.18,180.94,0.353
24.20,181.12,0.353
24.22,181.31,0.353
24.24,181.49,0.353
24.26,181.67,0.353
24.27,181.85,0.354
24.29,182.04,0.354
24.31,182.22,0.354
24.33,182.41,0.355
24.35,182.59,0.355
24.37,182.77,0.355
24.38,182.96,0.355
24.40,183.14,0.356
24.42,183.32,0.356
24.44,183.51,0.356
24.46,183.69,0.356
24.48,183.87,0.357
24.49,184.06,0.357
24.51,184.24,0.357
24.53,184.42,0.357
24.55,184.61,0.357
24.57,184.79,0.358
24.58,184.97,0.358
24.60,185.16,0.358
24.62,185.34,0.358
24.64,185.52,0.359
24.66,185.71,0.359
24.68,185.89,0.359
24.69,186.07,0.359
24.71,186.26,0.359
24.73,186.44,0.360
24.75,186.62,0.360
24.77,186.81,0.360
24.79,186.99,0.360
24.81,187.18,0.361
24.82,187.36,0.361
24.84,187.54,0.361
24.86,187.73,0.361
24.88,187.91,0.362
24.90,188.09,0.362
24.92,188.28,0.362
24.93,188.46,0.362
24.95,188.64,0.363
24.97,188.83,0.363
24.99,189.01,0.363
25.01,189.19,0.363
25.03,189.38,0.364
25.04,189.56,0.364
25.06,189.74,0.364
25.08,189.93,0.364
25.10,190.11,0.364
25.12,190.29,0.365
25.13,190.48,0.365
25.15,190.66,0.365
25.17,190.84,0.365
25.19,191.03,0.365
25.21,191.21,0.366
25.23,191.39,0.366
25.24,191.58,0.366
25.26,191.76,0.366
25.28,191.94,0.367
25.30,192.12,0.367
25.32,192.31,0.367
25.34,192.49,0.367
25.36,192.68,0.368
25.37,192.86,0.368
25.39,193.04,0.368
25.41,193.23,0.368
25.43,193.41,0.369
25.45,193.59,0.369
25.47,193.78,0.369
25.48,193.96,0.370
25.50,194.14,0.370
25.52,194.33,0.370
25.54,194.51,0.370
25.56,194.69,0.370
25.58,194.88,0.371
25.59,195.06,0.371
25.61,195.25,0.371
25.63,195.43,0.371
25.65,195.61,0.372
25.67,195.80,0.372
25.68,195.98,0.372
25.70,196.16,0.372
25.72,196.34,0.373
25.74,196.53,0.373
25.76,196.71,0.373
25.78,196.90,0.374
25.79,197.08,0.374
25.81,197.26,0.374
25.83,197.45,0.375
25.85,197.63,0.375
25.87,197.81,0.375
25.89,198.00,0.376
25.91,198.18,0.376
25.92,198.36,0.376
25.94,198.55,
25.96,198.73,
25.98,198.91,
25.99,,

[step]
Ramp 10.00 °C/min to -60.00 °C
Time,Temperature,Heat Flow (Normalized)
min,°C,W/g
27.99,200.16,-0.012
28.01,200.16,-0.012
28.03,200.16,-0.012
28.05,200.15,-0.012
28.07,200.12,-0.013
28.08,200.06,-0.037
28.10,199.98,-0.078
28.12,199.86,-0.131
28.14,199.73,-0.191
28.16,199.58,-0.245
28.18,199.41,-0.290
28.19,199.24,-0.325
28.21,199.07,-0.349
28.23,198.89,-0.365
28.25,198.72,-0.375
28.27,198.54,-0.382
28.29,198.36,-0.385
28.31,198.18,-0.390
28.32,198.00,-0.391
28.34,197.82,-0.393
28.36,197.64,-0.394
28.38,197.45,-0.395
28.40,197.27,-0.397
28.42,197.09,-0.398
28.43,196.91,-0.398
28.45,196.73,-0.400
28.47,196.54,-0.400
28.49,196.36,-0.401
28.51,196.18,-0.401
28.53,196.00,-0.402
28.54,195.82,-0.402
28.56,195.64,-0.402
28.58,195.45,-0.403
28.60,195.27,-0.403
28.62,195.09,-0.403
28.63,194.91,-0.404
28.65,194.73,-0.404
28.67,194.54,-0.404
28.69,194.36,-0.404
28.71,194.18,-0.405
28.73,194.00,-0.405
28.74,193.81,-0.405
28.76,193.63,-0.406
28.78,193.45,-0.406
28.80,193.27,-0.406
28.82,193.08,-0.406
28.84,192.90,-0.407
28.86,192.72,-0.407
28.87,192.54,-0.407
28.89,192.35,-0.408
28.91,192.17,-0.408
28.93,191.99,-0.408
28.95,191.81,-0.408
28.97,191.62,-0.408
28.98,191.44,-0.408
29.00,191.26,-0.408
29.02,191.08,-0.408
29.04,190.89,-0.409
29.06,190.71,-0.409
29.08,190.53,-0.409
29.09,190.35,-0.409
29.11,190.16,-0.409
29.13,189.98,-0.409
29.15,189.80,-0.409
29.17,189.61,-0.409
29.18,189.43,-0.409
29.20,189.25,-0.410
29.22,189.06,-0.410
29.24,188.88,-0.410
29.26,188.70,-0.410
29.28,188.52,-0.410
29.29,188.33,-0.410
29.31,188.15,-0.410
29.33,187.97,-0.410
29.35,187.78,-0.410
29.37,187.60,-0.410
29.39,187.42,-0.410
29.41,187.23,-0.410
29.42,187.05,-0.410
29.44,186.87,-0.410
29.46,186.68,-0.410
29.48,186.50,-0.410
29.50,186.32,-0.410
29.52,186.13,-0.410
29.53,185.95,-0.410
29.55,185.77,-0.410
29.57,185.59,-0.410
29.59,185.40,-0.410
29.61,185.22,-0.410
29.63,185.04,-0.410
29.64,184.85,-0.410
29.66,184.67,-0.410
29.68,184.49,-0.410
29.70,184.31,-0.410
29.72,184.12,-0.410
29.73,183.94,-0.410
29.75,183.76,-0.410
29.77,183.57,-0.410
29.79,183.39,-0.410
29.81,183.21,-0.410
29.83,183.02,-0.410
29.84,182.84,-0.410
29.86,182.66,-0.410
29.88,182.47,-0.410
29.90,182.29,-0.410
29.92,182.11,-0.410
29.94,181.92,-0.410
29.96,181.74,-0.410
29.97,181.56,-0.410
29.99,181.37,-0.410
30.01,181.19,-0.410
30.03,181.01,-0.410
30.05,180.82,-0.410
30.07,180.64,-0.410
30.08,180.46,-0.410
30.10,180.27,-0.410
30.12,180.09,-0.410
30.14,179.91,-0.410
30.16,179.72,-0.409
30.18,179.54,-0.409
30.19,179.36,-0.409
30.21,179.18,-0.409
30.23,178.99,-0.409
30.25,178.81,-0.409
30.27,178.63,-0.409
30.28,178.44,-0.409
30.30,178.26,-0.409
30.32,178.08,-0.409
30.34,177.89,-0.409
30.36,177.71,-0.409
30.38,177.53,-0.409
30.39,177.34,-0.409
30.41,177.16,-0.409
30.43,176.98,-0.409
30.45,176.79,-0.409
30.47,176.61,-0.409
30.49,176.43,-0.409
30.51,176.24,-0.409
30.52,176.06,-0.409
30.54,175.88,-0.409
30.56,175.69,-0.409
30.58,175.51,-0.409
30.60,175.33,-0.409
30.62,175.14,-0.408
30.63,174.96,-0.408
30.65,174.78,-0.408
30.67,174.59,-0.408
30.69,174.41,-0.408
30.71,174.23,-0.408
30.73,174.04,-0.408
30.74,173.86,-0.408
30.76,173.68,-0.408
30.78,173.49,-0.408
30.80,173.31,-0.408
30.82,173.13,-0.408
30.83,172.94,-0.408
30.85,172.76,-0.408
30.87,172.58,-0.408
30.89,172.39,-0.408
30.91,172.21,-0.408
30.93,172.03,-0.408
30.94,171.84,-0.408
30.96,171.66,-0.408
30.98,171.48,-0.408
31.00,171.29,-0.408
31.02,171.11,-0.407
31.04,170.93,-0.408
31.06,170.74,-0.407
31.07,170.56,-0.407
31.09,170.38,-0.407
31.11,170.19,-0.407
31.13,170.01,-0.407
31.15,169.83,-0.407
31.17,169.64,-0.407
31.18,169.46,-0.407
31.20,169.28,-0.407
31.22,169.09,-0.407
31.24,168.91,-0.407
31.26,168.73,-0.407
31.28,168.54,-0.407
31.29,168.36,-0.407
31.31,168.18,-0.406
31.33,167.99,-0.406
31.35,167.81,-0.406
31.37,167.63,-0.406
31.38,167.44,-0.406
31.40,167.26,-0.406
31.42,167.08,-0.406
31.44,166.89,-0.406
31.46,166.71,-0.406
31.48,166.53,-0.406
31.49,166.34,-0.406
31.51,166.16,-0.406
31.53,165.98,-0.406
31.55,165.80,-0.406
31.57,165.61,-0.406
31.59,165.43,-0.406
31.61,165.25,-0.405
31.62,165.06,-0.405
31.64,164.88,-0.406
31.66,164.69,-0.406
31.68,164.51,-0.406
31.70,164.33,-0.406
31.72,164.14,-0.406
31.73,163.96,-0.406
31.75,163.78,-0.405
31.77,163.60,-0.405
31.79,163.41,-0.405
31.81,163.23,-0.405
31.83,163.05,-0.405
31.84,162.86,-0.405
31.86,162.68,-0.405
31.88,162.50,-0.405
31.90,162.31,-0.405
31.92,162.13,-0.405
31.93,161.94,-0.405
31.95,161.76,-0.405
31.97,161.58,-0.405
31.99,161.39,-0.405
32.01,161.21,-0.405
32.03,161.03,-0.405
32.04,160.84,-0.404
32.06,160.66,-0.404
32.08,160.48,-0.404
32.10,160.29,-0.404
32.12,160.11,-0.404
32.14,159.93,-0.404
32.16,159.74,-0.404
32.17,159.56,-0.404
32.19,159.38,-0.404
32.21,159.19,-0.404
32.23,159.01,-0.404
32.25,158.83,-0.404
32.27,158.64,-0.404
32.28,158.46,-0.404
32.30,158.28,-0.404
32.32,158.09,-0.404
32.34,157.91,-0.404
32.36,157.73,-0.404
32.38,157.55,-0.403
32.39,157.36,-0.403
32.41,157.18,-0.403
32.43,156.99,-0.403
32.45,156.81,-0.403
32.47,156.63,-0.403
32.48,156.44,-0.403
32.50,156.26,-0.403
32.52,156.08,-0.403
32.54,155.89,-0.403
32.56,155.71,-0.403
32.58,155.53,-0.403
32.59,155.35,-0.403
32.61,155.16,-0.403
32.63,154.98,-0.403
32.65,154.80,-0.402
32.67,154.61,-0.402
32.69,154.43,-0.402
32.71,154.25,-0.402
32.72,154.06,-0.402
32.74,153.88,-0.402
32.76,153.70,-0.402
32.78,153.51,-0.402
32.80,153.33,-0.402
32.82,153.15,-0.402
32.83,152.96,-0.402
32.85,152.78,-0.402
32.87,152.60,-0.402
32.89,152.41,-0.402
32.91,152.23,-0.402
32.93,152.05,-0.402
32.94,151.86,-0.401
32.96,151.68,-0.401
32.98,151.50,-0.401
33.00,151.31,-0.401
33.02,151.13,-0.401
33.03,150.95,-0.401
33.05,150.76,-0.401
33.07,150.58,-0.401
33.09,150.40,-0.401
33.11,150.21,-0.401
33.13,150.03,-0.401
33.14,149.85,-0.401
33.16,149.66,-0.401
33.18,149.48,-0.401
33.20,149.30,-0.401
33.22,149.11,-0.401
33.24,148.93,-0.401
33.26,148.75,-0.401
33.27,148.56,-0.401
33.29,148.38,-0.400
33.31,148.20,-0.400
33.33,148.01,-0.400
33.35,147.83,-0.400
33.37,147.65,-0.400
33.38,147.46,-0.400
33.40,147.28,-0.400
33.42,147.10,-0.400
33.44,146.91,-0.400
33.46,146.73,-0.400
33.48,146.55,-0.400
33.49,146.36,-0.400
33.51,146.18,-0.400
33.53,146.00,-0.400
33.55,145.81,-0.400
33.57,145.63,-0.400
33.58,145.45,-0.399
33.60,145.26,-0.399
33.62,145.08,-0.399
33.64,144.90,-0.399
33.66,144.71,-0.399
33.68,144.53,-0.399
33.69,144.34,-0.399
33.71,144.16,-0.399
33.73,143.98,-0.399
33.75,143.79,-0.399
33.77,143.61,-0.399
33.79,143.43,-0.399
33.81,143.24,-0.399
33.82,143.06,-0.399
33.84,142.88,-0.399
33.86,142.69,-0.398
33.88,142.51,-0.398
33.90,142.33,-0.398
33.92,142.14,-0.398
33.93,141.96,-0.398
33.95,141.78,-0.398
33.97,141.59,-0.398
33.99,141.41,-0.398
34.01,141.23,-0.398
34.03,141.04,-0.397
34.04,140.86,-0.397
34.06,140.68,-0.397
34.08,140.49,-0.397
34.10,140.31,-0.397
34.12,140.13,-0.397
34.14,139.94,-0.397
34.15,139.76,-0.397
34.17,139.58,-0.397
34.19,139.39,-0.397
34.21,139.21,-0.397
34.23,139.03,-0.397
34.24,138.85,-0.397
34.26,138.66,-0.396
34.28,138.48,-0.396
34.30,138.30,-0.396
34.32,138.11,-0.396
34.34,137.93,-0.396
34.36,137.75,-0.396
34.37,137.56,-0.396
34.39,137.38,-0.396
[...]
170.40,-36.89,-0.593
170.41,-36.82,-0.594
170.41,-36.75,-0.594
170.42,-36.69,-0.594
170.43,-36.62,-0.594
170.43,-36.56,-0.594
170.44,-36.49,-0.594
170.45,-36.42,-0.594
170.45,-36.36,-0.594
170.46,-36.29,-0.595
170.47,-36.22,-0.595
170.47,-36.15,-0.595
170.48,-36.09,-0.595
170.49,-36.02,-0.595
170.49,-35.95,-0.595
170.50,-35.89,-0.595
170.51,-35.82,-0.595
170.51,-35.76,-0.595
170.52,-35.69,-0.596
170.53,-35.62,-0.596
170.53,-35.55,-0.596
170.54,-35.49,-0.596
170.55,-35.42,-0.596
170.55,-35.35,-0.596
170.56,-35.29,-0.596
170.57,-35.22,-0.596
170.57,-35.15,-0.597
170.58,-35.09,-0.597
170.59,-35.02,-0.597
170.59,-34.95,-0.597
170.60,-34.89,-0.597
170.61,-34.82,-0.597
170.61,-34.75,-0.597
170.62,-34.69,-0.598
170.63,-34.62,-0.598
170.63,-34.55,-0.598
170.64,-34.49,-0.598
170.65,-34.42,-0.598
170.65,-34.35,-0.598
170.66,-34.29,-0.598
170.67,-34.22,-0.598
170.67,-34.15,-0.599
170.68,-34.09,-0.599
170.69,-34.02,-0.599
170.69,-33.95,-0.599
170.70,-33.89,-0.599
170.71,-33.82,-0.599
170.71,-33.75,-0.599
170.72,-33.69,-0.599
170.73,-33.62,-0.599
170.73,-33.55,-0.600
170.74,-33.48,-0.600
170.75,-33.42,-0.600
170.75,-33.35,-0.600
170.76,-33.28,-0.600
170.77,-33.22,-0.600
170.77,-33.15,-0.600
170.78,-33.08,-0.600
170.79,-33.02,-0.600
170.79,-32.95,-0.601
170.80,-32.88,-0.601
170.81,-32.82,-0.601
170.81,-32.75,-0.601
170.82,-32.68,-0.601
170.83,-32.62,-0.601
170.83,-32.55,-0.601
170.84,-32.48,-0.601
170.85,-32.42,-0.601
170.85,-32.35,-0.601
170.86,-32.28,-0.602
170.87,-32.22,-0.602
170.87,-32.15,-0.602
170.88,-32.08,-0.602
170.89,-32.01,-0.602
170.89,-31.95,-0.602
170.90,-31.88,-0.602
170.91,-31.82,-0.602
170.91,-31.75,-0.603
170.92,-31.68,-0.603
170.93,-31.61,-0.603
170.93,-31.55,-0.603
170.94,-31.48,-0.603
170.95,-31.41,-0.603
170.95,-31.35,-0.603
170.96,-31.28,-0.603
170.97,-31.21,-0.604
170.97,-31.15,-0.604
170.98,-31.08,-0.604
170.99,-31.01,-0.604
170.99,-30.95,-0.604
171.00,-30.88,-0.604
171.01,-30.81,-0.604
171.01,-30.75,-0.604
171.02,-30.68,-0.604
171.03,-30.61,-0.605
171.03,-30.55,-0.605
171.04,-30.48,-0.605
171.05,-30.41,-0.605
171.05,-30.35,-0.605
171.06,-30.28,-0.605
171.07,-30.21,-0.605
171.07,-30.14,-0.605
171.08,-30.08,-0.605
171.09,-30.01,-0.606
171.09,-29.94,-0.606
171.10,-29.88,-0.606
171.11,-29.81,-0.606
171.11,-29.75,-0.606
171.12,-29.68,-0.606
171.13,-29.61,-0.606
171.13,-29.55,-0.606
171.14,-29.48,-0.606
171.15,-29.41,-0.606
171.15,-29.34,-0.607
171.16,-29.28,-0.607
171.17,-29.21,-0.607
171.17,-29.14,-0.607
171.18,-29.08,-0.607
171.19,-29.01,-0.607
171.19,-28.94,-0.607
171.20,-28.88,-0.607
171.21,-28.81,-0.607
171.21,-28.74,-0.608
171.22,-28.68,-0.608
171.23,-28.61,-0.608
171.23,-28.54,-0.608
171.24,-28.48,-0.608
171.25,-28.41,-0.608
171.25,-28.34,-0.608
171.26,-28.28,-0.608
171.27,-28.21,-0.608
171.27,-28.14,-0.608
171.28,-28.08,-0.609
171.29,-28.01,-0.609
171.29,-27.94,-0.609
171.30,-27.88,-0.609
171.31,-27.81,-0.609
171.31,-27.74,-0.609
171.32,-27.68,-0.609
171.33,-27.61,-0.609
171.33,-27.54,-0.609
171.34,-27.48,-0.610
171.35,-27.41,-0.610
171.35,-27.34,-0.610
171.36,-27.28,-0.610
171.37,-27.21,-0.610
171.37,-27.14,-0.610
171.38,-27.08,-0.610
171.39,-27.01,-0.610
171.39,-26.94,-0.610
171.40,-26.88,-0.610
171.41,-26.81,-0.611
171.41,-26.74,-0.611
171.42,-26.67,-0.611
171.43,-26.61,-0.611
171.43,-26.54,-0.611
171.44,-26.47,-0.611
171.45,-26.41,-0.611
171.45,-26.34,-0.611
171.46,-26.27,-0.612
171.47,-26.21,-0.612
171.47,-26.14,-0.612
171.48,-26.07,-0.612
171.49,-26.01,-0.612
171.49,-25.94,-0.612
171.50,-25.87,-0.612
171.51,-25.81,-0.612
171.51,-25.74,-0.612
171.52,-25.67,-0.612
171.53,-25.61,-0.612
171.53,-25.54,-0.613
171.54,-25.47,-0.613
171.55,-25.40,-0.613
171.55,-25.34,-0.613
171.56,-25.27,-0.613
171.57,-25.21,-0.613
171.57,-25.14,-0.613
171.58,-25.07,-0.613
171.59,-25.00,-0.613
171.59,-24.94,-0.614
171.60,-24.87,-0.614
171.61,-24.80,-0.614
171.61,-24.74,-0.614
171.62,-24.67,-0.614
171.63,-24.60,-0.614
171.63,-24.54,-0.614
171.64,-24.47,-0.614
171.65,-24.40,-0.614
171.65,-24.34,-0.614
171.66,-24.27,-0.614
171.67,-24.20,-0.615
171.67,-24.14,-0.615
171.68,-24.07,-0.615
171.69,-24.00,-0.615
171.69,-23.94,-0.615
171.70,-23.87,-0.615
171.71,-23.80,-0.615
171.71,-23.74,-0.615
171.72,-23.67,-0.615
171.73,-23.60,-0.615
171.73,-23.54,-0.616
171.74,-23.47,-0.616
171.75,-23.40,-0.616
171.75,-23.34,-0.616
171.76,-23.27,-0.616
171.77,-23.20,-0.616
171.77,-23.14,-0.616
171.78,-23.07,-0.616
171.79,-23.00,-0.616
171.79,-22.94,-0.616
171.80,-22.87,-0.617
171.81,-22.80,-0.617
171.81,-22.74,-0.617
171.82,-22.67,-0.617
171.83,-22.60,-0.617
171.83,-22.54,-0.617
171.84,-22.47,-0.617
171.85,-22.40,-0.617
171.85,-22.34,-0.617
171.86,-22.27,-0.617
171.87,-22.20,-0.618
171.87,-22.13,-0.618
171.88,-22.07,-0.618
171.89,-22.00,-0.618
171.89,-21.93,-0.618
171.90,-21.87,-0.618
171.91,-21.80,-0.618
171.91,-21.73,-0.618
171.92,-21.67,-0.618
171.93,-21.60,-0.618
171.93,-21.53,-0.619
171.94,-21.47,-0.619
171.95,-21.40,-0.619
171.95,-21.33,-0.619
171.96,-21.27,-0.619
171.97,-21.20,-0.619
171.97,-21.13,-0.619
171.98,-21.07,-0.619
171.99,-21.00,-0.619
171.99,-20.93,-0.620
172.00,-20.87,-0.620
172.01,-20.80,-0.620
172.01,-20.73,-0.620
172.02,-20.67,-0.620
172.03,-20.60,-0.620
172.03,-20.53,-0.620
172.04,-20.47,-0.620
172.05,-20.40,-0.620
172.05,-20.33,-0.620
172.06,-20.27,-0.620
172.07,-20.20,-0.621
172.07,-20.13,-0.621
172.08,-20.07,-0.621
172.09,-20.00,-0.621
172.09,-19.93,-0.621
172.10,-19.87,-0.621
172.11,-19.80,-0.621
172.11,-19.73,-0.621
172.12,-19.67,-0.621
172.13,-19.60,-0.621
172.13,-19.53,-0.622
172.14,-19.46,-0.622
172.15,-19.40,-0.622
172.15,-19.33,-0.622
172.16,-19.26,-0.622
172.17,-19.20,-0.622
172.17,-19.13,-0.622
172.18,-19.06,-0.622
172.19,-19.00,-0.622
172.19,-18.93,-0.622
172.20,-18.86,-0.623
172.21,-18.80,-0.623
172.21,-18.73,-0.623
172.22,-18.66,-0.623
172.23,-18.60,-0.623
172.23,-18.53,-0.623
172.24,-18.46,-0.623
172.25,-18.40,-0.623
172.25,-18.33,-0.623
172.26,-18.26,-0.623
172.27,-18.20,-0.623
172.27,-18.13,-0.623
172.28,-18.06,-0.624
172.29,-18.00,-0.624
172.29,-17.93,-0.624
172.30,-17.86,-0.624
172.31,-17.80,-0.624
172.31,-17.73,-0.624
172.32,-17.66,-0.624
172.33,-17.60,-0.624
172.33,-17.53,-0.624
172.34,-17.46,-0.624
172.35,-17.40,-0.625
172.35,-17.33,-0.625
172.36,-17.26,-0.625
172.37,-17.19,-0.625
172.37,-17.13,-0.625
172.38,-17.06,-0.625
172.39,-16.99,-0.625
172.39,-16.93,-0.625
172.40,-16.86,-0.625
172.41,-16.79,-0.626
172.41,-16.73,-0.626
172.42,-16.66,-0.626
172.43,-16.59,-0.626
172.43,-16.53,-0.626
172.44,-16.46,-0.626
172.45,-16.39,-0.626
172.45,-16.33,-0.626
172.46,-16.26,-0.626
172.47,-16.19,-0.627
172.47,-16.13,-0.627
172.48,-16.06,-0.627
172.49,-15.99,-0.627
172.49,-15.93,-0.627
172.50,-15.86,-0.627
172.51,-15.79,-0.627
172.51,-15.73,-0.627
172.52,-15.66,-0.627
172.53,-15.59,-0.627
172.53,-15.53,-0.627
172.54,-15.46,-0.628
172.55,-15.39,-0.628
172.55,-15.33,-0.628
172.56,-15.26,-0.628
172.57,-15.19,-0.628
172.57,-15.13,-0.628
172.58,-15.06,-0.628
172.59,-14.99,-0.628
172.59,-14.93,-0.628
172.60,-14.86,-0.628
172.61,-14.79,-0.628
172.61,-14.73,-0.629
172.62,-14.66,-0.629
172.63,-14.59,-0.629
172.63,-14.53,-0.629
172.64,-14.46,-0.629
172.65,-14.39,-0.629
172.65,-14.32,-0.629
172.66,-14.26,-0.629
172.67,-14.19,-0.629
172.67,-14.12,-0.630
172.68,-14.06,-0.630
172.69,-13.99,-0.630
172.69,-13.92,-0.630
172.70,-13.86,-0.630
172.71,-13.79,-0.630
172.71,-13.72,-0.630
172.72,-13.66,-0.630
172.73,-13.59,-0.630
172.73,-13.53,-0.630
172.74,-13.46,-0.631
172.75,-13.39,-0.631
172.75,-13.32,-0.631
172.76,-13.26,-0.631
172.77,-13.19,-0.631
172.77,-13.12,-0.631
172.78,-13.06,-0.631
172.79,-12.99,-0.631
172.79,-12.92,-0.631
172.80,-12.86,-0.631
172.81,-12.79,-0.631
172.81,-12.72,-0.632
172.82,-12.66,-0.632
172.83,-12.59,-0.632
172.83,-12.52,-0.632
172.84,-12.46,-0.632
172.85,-12.39,-0.632
172.85,-12.32,-0.632
172.86,-12.26,-0.632
172.87,-12.19,-0.632
172.87,-12.12,-0.632
172.88,-12.05,-0.632
172.89,-11.99,-0.633
172.89,-11.92,-0.633
172.90,-11.86,-0.633
172.91,-11.79,-0.633
172.91,-11.72,-0.633
172.92,-11.66,-0.633
172.93,-11.59,-0.633
172.93,-11.52,-0.633
172.94,-11.46,-0.633
172.95,-11.39,-0.633
172.95,-11.32,-0.633
172.96,-11.25,-0.634
172.97,-11.19,-0.634
172.97,-11.12,-0.634
172.98,-11.06,-0.634
172.99,-10.99,-0.634
172.99,-10.92,-0.634
173.00,-10.85,-0.634
173.01,-10.79,-0.634
173.01,-10.72,-0.634
173.02,-10.65,-0.634
173.03,-10.59,-0.635
173.03,-10.52,-0.635
173.04,-10.45,-0.635
173.05,-10.39,-0.635
173.05,-10.32,-0.635
173.06,-10.25,-0.635
173.07,-10.19,-0.635
173.07,-10.12,-0.635
173.08,-10.05,-0.636
173.09,-9.99,-0.636
173.09,-9.92,-0.636
173.10,-9.85,-0.636
173.11,-9.78,-0.636
173.11,-9.72,-0.636
173.12,-9.65,-0.636
173.13,-9.58,-0.636
173.13,-9.52,-0.636
173.14,-9.45,-0.637
173.15,-9.38,-0.637
173.15,-9.32,-0.637
173.16,-9.25,-0.637
173.17,-9.18,-0.637
173.17,-9.12,-0.637
173.18,-9.05,-0.637
173.19,-8.98,-0.637
173.19,-8.92,-0.637
173.20,-8.85,-0.637
173.21,-8.79,-0.637
173.21,-8.72,-0.637
173.22,-8.65,-0.637
173.23,-8.58,-0.638
173.23,-8.52,-0.638
173.24,-8.45,-0.638
173.25,-8.38,-0.638
173.25,-8.32,-0.638
173.26,-8.25,-0.638
173.27,-8.18,-0.638
173.27,-8.12,-0.638
173.28,-8.05,-0.638
173.29,-7.98,-0.638
173.29,-7.92,-0.639
173.30,-7.85,-0.639
173.31,-7.78,-0.639
173.31,-7.72,-0.639
173.32,-7.65,-0.639
173.33,-7.58,-0.639
173.33,-7.52,-0.639
173.34,-7.45,-0.639
173.35,-7.38,-0.639
173.35,-7.32,-0.639
173.36,-7.25,-0.639
173.37,-7.18,-0.639
173.37,-7.12,-0.640
173.38,-7.05,-0.640
173.39,-6.98,-0.640
173.39,-6.92,-0.640
173.40,-6.85,-0.640
173.41,-6.78,-0.640
173.41,-6.72,-0.640
173.42,-6.65,-0.640
173.43,-6.58,-0.640
173.43,-6.51,-0.640
173.44,-6.45,-0.640
173.45,-6.38,-0.640
173.45,-6.32,-0.641
173.46,-6.25,-0.641
173.47,-6.18,-0.641
173.47,-6.11,-0.641
173.48,-6.05,-0.641
173.49,-5.98,-0.641
173.49,-5.91,-0.641
173.50,-5.85,-0.641
173.51,-5.78,-0.641
173.51,-5.71,-0.641
173.52,-5.65,-0.641
173.53,-5.58,-0.641
173.53,-5.52,-0.642
173.54,-5.45,-0.642
173.55,-5.38,-0.642
173.55,-5.31,-0.642
173.56,-5.25,-0.642
173.57,-5.18,-0.642
173.57,-5.11,-0.642
173.58,-5.05,-0.642
173.59,-4.98,-0.642
173.59,-4.91,-0.642
173.60,-4.85,-0.642
173.61,-4.78,-0.643
173.61,-4.71,-0.643
173.62,-4.65,-0.643
173.63,-4.58,-0.643
173.63,-4.51,-0.643
173.64,-4.45,-0.643
173.65,-4.38,-0.643
173.65,-4.31,-0.643
173.66,-4.25,-0.643
173.67,-4.18,-0.643
173.67,-4.11,-0.643
173.68,-4.05,-0.643
173.69,-3.98,-0.644
173.69,-3.91,-0.644
173.70,-3.85,-0.644
173.71,-3.78,-0.644
173.71,-3.71,-0.644
173.72,-3.65,-0.644
173.73,-3.58,-0.644
173.73,-3.51,-0.644
173.74,-3.45,-0.644
173.75,-3.38,-0.645
173.75,-3.31,-0.645
173.76,-3.25,-0.645
173.77,-3.18,-0.645
173.77,-3.11,-0.645
173.78,-3.05,-0.645
173.79,-2.98,-0.645
173.79,-2.91,-0.645
173.80,-2.84,-0.645
173.81,-2.78,-0.645
173.81,-2.71,-0.645
173.82,-2.64,-0.646
173.83,-2.58,-0.646
173.83,-2.51,-0.646
173.84,-2.44,-0.646
173.85,-2.38,-0.646
173.85,-2.31,-0.646
173.86,-2.24,-0.646
173.87,-2.18,-0.646
173.87,-2.11,-0.646
173.88,-2.04,-0.646
173.89,-1.98,-0.646
173.89,-1.91,-0.647
173.90,-1.84,-0.647
173.91,-1.78,-0.647
173.91,-1.71,-0.647
173.92,-1.64,-0.647
173.93,-1.58,-0.647
173.93,-1.51,-0.647
173.94,-1.44,-0.647
173.95,-1.38,-0.647
173.95,-1.31,-0.647
173.96,-1.24,-0.647
173.97,-1.18,-0.647
173.97,-1.11,-0.648
173.98,-1.04,-0.648
173.99,-0.98,-0.648
173.99,-0.91,-0.648
174.00,-0.84,-0.648
174.01,-0.78,-0.648
174.01,-0.71,-0.648
174.02,-0.64,-0.648
174.03,-0.58,-0.648
174.03,-0.51,-0.648
174.04,-0.44,-0.648
174.05,-0.38,-0.648
174.05,-0.31,-0.648
174.06,-0.24,-0.649
174.07,-0.18,-0.649
174.07,-0.11,-0.649
174.08,-0.04,-0.649
174.09,0.02,-0.649
174.09,0.09,-0.649
174.10,0.16,-0.649
174.11,0.22,-0.649
174.11,0.29,-0.649
174.12,0.36,-0.649
174.13,0.43,-0.649
174.13,0.49,-0.650
174.14,0.56,-0.650
174.15,0.63,-0.650
174.15,0.69,-0.650
174.16,0.76,-0.650
174.17,0.83,-0.650
174.17,0.89,-0.650
174.18,0.96,-0.650
174.19,1.03,-0.650
174.19,1.09,-0.650
174.20,1.16,-0.650
174.21,1.23,-0.650
174.21,1.29,-0.651
174.22,1.36,-0.651
174.23,1.43,-0.651
174.23,1.49,-0.651
174.24,1.56,-0.651
174.25,1.63,-0.651
174.25,1.69,-0.651
174.26,1.76,-0.651
174.27,1.83,-0.651
174.27,1.89,-0.651
174.28,1.96,-0.651
174.29,2.03,-0.651
174.29,2.09,-0.651
174.30,2.16,-0.651
174.31,2.23,-0.651
174.31,2.29,-0.652
174.32,2.36,-0.652
174.33,2.43,-0.652
174.33,2.49,-0.652
174.34,2.56,-0.652
174.35,2.63,-0.652
174.35,2.69,-0.652
174.36,2.76,-0.652
174.37,2.83,-0.652
174.37,2.89,-0.652
174.38,2.96,-0.652
174.39,3.03,-0.652
174.39,3.09,-0.652
174.40,3.16,-0.653
174.41,3.23,-0.653
174.41,3.29,-0.653
174.42,3.36,-0.653
174.43,3.43,-0.653
174.43,3.49,-0.653
174.44,3.56,-0.653
174.45,3.63,-0.653
174.45,3.69,-0.653
174.46,3.76,-0.653
174.47,3.83,-0.653
174.47,3.89,-0.653
174.48,3.96,-0.654
174.49,4.03,-0.654
174.49,4.09,-0.654
174.50,4.16,-0.654
174.51,4.23,-0.654
174.51,4.30,-0.654
174.52,4.36,-0.654
174.53,4.43,-0.654
174.53,4.50,-0.654
174.54,4.56,-0.654
174.55,4.63,-0.654
174.55,4.70,-0.655
174.56,4.76,-0.655
174.57,4.83,-0.655
174.57,4.90,-0.655
174.58,4.96,-0.655
174.59,5.03,-0.655
174.59,5.10,-0.655
174.60,5.16,-0.655
174.61,5.23,-0.655
174.61,5.30,-0.655
174.62,5.36,-0.655
174.63,5.43,-0.655
174.63,5.50,-0.656
174.64,5.56,-0.656
174.65,5.63,-0.656
174.65,5.70,-0.656
174.66,5.76,-0.656
174.67,5.83,-0.656
174.67,5.90,-0.656
174.68,5.97,-0.656
174.69,6.03,-0.656
174.69,6.10,-0.656
174.70,6.16,-0.657
174.71,6.23,-0.657
174.71,6.30,-0.657
174.72,6.37,-0.657
174.73,6.43,-0.657
174.73,6.50,-0.657
174.74,6.57,-0.657
174.75,6.63,-0.657
174.75,6.70,-0.657
174.76,6.77,-0.657
174.77,6.83,-0.657
174.77,6.90,-0.657
174.78,6.97,-0.657
174.79,7.03,-0.658
174.79,7.10,-0.658
174.80,7.17,-0.658
174.81,7.23,-0.658
174.81,7.30,-0.658
174.82,7.37,-0.658
174.83,7.43,-0.658
174.83,7.50,-0.658
174.84,7.57,-0.658
174.85,7.63,-0.658
174.85,7.70,-0.658
174.86,7.77,-0.658
174.87,7.83,-0.659
174.87,7.90,-0.659
174.88,7.97,-0.659
174.89,8.03,-0.659
174.89,8.10,-0.659
174.90,8.17,-0.659
174.91,8.23,-0.659
174.91,8.30,-0.659
174.92,8.37,-0.659
174.93,8.43,-0.659
174.93,8.50,-0.659
174.94,8.57,-0.659
174.95,8.63,-0.659
174.95,8.70,-0.659
174.96,8.77,-0.659
174.97,8.83,-0.660
174.97,8.90,-0.660
174.98,8.97,-0.660
174.99,9.03,-0.660
174.99,9.10,-0.660
175.00,9.17,-0.660
175.01,9.23,-0.660
175.01,9.30,-0.660
175.02,9.37,-0.660
175.03,9.43,-0.660
175.03,9.50,-0.660
175.04,9.57,-0.660
175.05,9.64,-0.660
175.05,9.70,-0.661
175.06,9.77,-0.661
175.07,9.83,-0.661
175.07,9.90,-0.661
175.08,9.97,-0.661
175.09,10.04,-0.661
175.09,10.10,-0.661
175.10,10.17,-0.661
175.11,10.23,-0.661
175.11,10.30,-0.661
175.12,10.37,-0.661
175.13,10.44,-0.662
175.13,10.50,-0.662
175.14,10.57,-0.662
175.15,10.64,-0.662
175.15,10.70,-0.662
175.16,10.77,-0.662
175.17,10.84,-0.662
175.17,10.90,-0.662
175.18,10.97,-0.662
175.19,11.04,-0.662
175.19,11.10,-0.662
175.20,11.17,-0.662
175.21,11.24,-0.663
175.21,11.30,-0.663
175.22,11.37,-0.663
175.23,11.44,-0.663
175.23,11.50,-0.663
175.24,11.57,-0.663
175.25,11.64,-0.663
175.25,11.70,-0.663
175.26,11.77,-0.663
175.27,11.84,-0.663
175.27,11.90,-0.663
175.28,11.97,-0.663
175.29,12.04,-0.663
175.29,12.10,-0.663
175.30,12.17,-0.663
175.31,12.24,-0.664
175.31,12.30,-0.664
175.32,12.37,-0.664
175.33,12.44,-0.664
175.33,12.50,-0.664
175.34,12.57,-0.664
175.35,12.64,-0.664
175.35,12.70,-0.664
175.36,12.77,-0.664
175.37,12.84,-0.664
175.37,12.90,-0.664
175.38,12.97,-0.665
175.39,13.04,-0.665
175.39,13.10,-0.665
175.40,13.17,-0.665
175.41,13.24,-0.665
175.41,13.30,-0.665
175.42,13.37,-0.665
175.43,13.44,-0.665
175.43,13.51,-0.665
175.44,13.57,-0.665
175.45,13.64,-0.665
175.45,13.71,-0.665
175.46,13.77,-0.666
175.47,13.84,-0.666
175.47,13.91,-0.666
175.48,13.97,-0.666
175.49,14.04,-0.666
175.49,14.11,-0.666
175.50,14.17,-0.666
175.51,14.24,-0.666
175.51,14.31,-0.666
175.52,14.37,-0.666
175.53,14.44,-0.666
175.53,14.51,-0.666
175.54,14.57,-0.666
175.55,14.64,-0.666
175.55,14.71,-0.666
175.56,14.77,-0.667
175.57,14.84,-0.667
175.57,14.91,-0.667
175.58,14.97,-0.667
175.59,15.04,-0.667
175.59,15.11,-0.667
175.60,15.17,-0.667
175.61,15.24,-0.667
175.61,15.30,-0.667
175.62,15.37,-0.667
175.63,15.44,-0.667
175.63,15.51,-0.667
175.64,15.57,-0.667
175.65,15.64,-0.668
175.65,15.71,-0.668
175.66,15.77,-0.668
175.67,15.84,-0.668
175.67,15.91,-0.668
175.68,15.97,-0.668
175.69,16.04,-0.668
175.69,16.11,-0.668
175.70,16.17,-0.668
175.71,16.24,-0.668
175.71,16.31,-0.668
175.72,16.37,-0.669
175.73,16.44,-0.669
175.73,16.51,-0.669
175.74,16.57,-0.669
175.75,16.64,-0.669
175.75,16.71,-0.669
175.76,16.77,-0.669
175.77,16.84,-0.669
175.77,16.91,-0.669
175.78,16.97,-0.669
175.79,17.04,-0.669
175.79,17.11,-0.669
175.80,17.17,-0.669
175.81,17.24,-0.669
175.81,17.31,-0.669
175.82,17.37,-0.670
175.83,17.44,-0.670
175.83,17.51,-0.670
175.84,17.57,-0.670
175.85,17.64,-0.670
175.85,17.71,-0.670
175.86,17.77,-0.670
175.87,17.84,-0.670
175.87,17.91,-0.670
175.88,17.98,-0.670
175.89,18.04,-0.670
175.89,18.11,-0.671
175.90,18.18,-0.671
175.91,18.24,-0.671
175.91,18.31,-0.671
175.92,18.38,-0.671
175.93,18.44,-0.671
175.93,18.51,-0.671
175.94,18.58,-0.671
175.95,18.64,-0.671
175.95,18.71,-0.671
175.96,18.78,-0.671
175.97,18.84,-0.672
175.97,18.91,-0.672
175.98,18.98,-0.672
175.99,19.04,-0.672
175.99,19.11,-0.672
176.00,19.18,-0.672
176.01,19.24,-0.672
176.01,19.31,-0.672
176.02,19.38,-0.672
176.03,19.44,-0.672
176.03,19.51,-0.672
176.04,19.58,-0.672
176.05,19.64,-0.672
176.05,19.71,-0.672
176.06,19.78,-0.673
176.07,19.84,-0.673
176.07,19.91,-0.673
176.08,19.98,-0.673
176.09,20.04,-0.673
176.09,20.11,-0.673
176.10,20.18,-0.673
176.11,20.25,-0.673
176.11,20.31,-0.673
176.12,20.38,-0.674
176.13,20.45,-0.674
176.13,20.51,-0.674
176.14,20.58,-0.674
176.15,20.64,-0.674
176.15,20.71,-0.674
176.16,20.78,-0.674
176.17,20.85,-0.674
176.17,20.91,-0.674
176.18,20.98,-0.674
176.19,21.05,-0.674
176.19,21.11,-0.675
176.20,21.18,-0.675
176.21,21.25,-0.675
176.21,21.31,-0.675
176.22,21.38,-0.675
176.23,21.45,-0.675
176.23,21.51,-0.675
176.24,21.58,-0.675
176.25,21.65,-0.675
176.25,21.71,-0.675
176.26,21.78,-0.675
176.27,21.85,-0.675
176.27,21.91,-0.675
176.28,21.98,-0.675
176.29,22.05,-0.676
176.29,22.11,-0.676
176.30,22.18,-0.676
176.31,22.25,-0.676
176.31,22.31,-0.676
176.32,22.38,-0.676
176.33,22.45,-0.676
176.33,22.51,-0.676
176.34,22.58,-0.676
176.35,22.65,-0.676
176.35,22.71,-0.677
176.36,22.78,-0.677
176.37,22.85,-0.677
176.37,22.91,-0.677
176.38,22.98,-0.677
176.39,23.05,-0.677
176.39,23.11,-0.677
176.40,23.18,-0.677
176.41,23.25,-0.677
176.41,23.32,-0.677
176.42,23.38,-0.677
176.43,23.45,-0.677
176.43,23.52,-0.677
176.44,23.58,-0.677
176.45,23.65,-0.677
176.45,23.72,-0.678
176.46,23.78,-0.678
176.47,23.85,-0.678
176.47,23.92,-0.678
176.48,23.98,-0.678
176.49,24.05,-0.678
176.49,24.12,-0.678
176.50,24.18,-0.678
176.51,24.25,-0.678
176.51,24.32,-0.678
176.52,24.38,-0.678
176.53,24.45,-0.678
176.53,24.52,-0.678
176.54,24.58,-0.678
176.55,24.65,-0.678
176.55,24.72,-0.678
176.56,24.78,-0.679
176.57,24.85,-0.679
176.57,24.92,-0.679
176.58,24.98,-0.679
176.59,25.05,-0.679
176.59,25.12,-0.679
176.60,25.18,-0.679
176.61,25.25,-0.679
176.61,25.32,-0.679
176.62,25.38,-0.679
176.63,25.45,-0.679
176.63,25.52,-0.679
176.64,25.58,-0.679
176.65,25.65,-0.679
176.65,25.72,-0.679
176.66,25.78,-0.680
176.67,25.85,-0.680
176.67,25.92,-0.680
176.68,25.98,-0.680
176.69,26.05,-0.680
176.69,26.12,-0.680
176.70,26.19,-0.680
176.71,26.25,-0.680
176.71,26.32,-0.680
176.72,26.38,-0.680
176.73,26.45,-0.680
176.73,26.52,-0.680
176.74,26.58,-0.680
176.75,26.65,-0.680
176.75,26.72,-0.681
176.76,26.79,-0.681
176.77,26.85,-0.681
176.77,26.92,-0.681
176.78,26.98,-0.681
176.79,27.05,-0.681
176.79,27.12,-0.681
176.80,27.19,-0.681
176.81,27.25,-0.681
176.81,27.32,-0.681
176.82,27.39,-0.681
176.83,27.45,-0.681
176.83,27.52,-0.681
176.84,27.59,-0.681
176.85,27.65,-0.681
176.85,27.72,-0.681
176.86,27.79,-0.682
176.87,27.85,-0.682
176.87,27.92,-0.682
176.88,27.99,-0.682
176.89,28.05,-0.682
176.89,28.12,-0.682
176.90,28.19,-0.682
176.91,28.25,-0.682
176.91,28.32,-0.682
176.92,28.39,-0.682
176.93,28.45,-0.682
176.93,28.52,-0.682
176.94,28.59,
176.95,28.65,
176.95,28.72,
176.96,28.79,
176.97,28.85,
176.97,28.92,
176.98,28.99,
176.99,,
176.99,,