File: DSC/Olivia/2025_08_09_1CBN_3PVP10_MeOH_ASD_n60C_150C_10Cmin_x3.csv
Filename,2025_08_09_1CBN_3PVP10_MeOH_ASD_n60C_150C_10Cmin_x3
Instrument name,DSC2A-00468 (192.168.1.100)
Operator,Yarger
rundate,8/9/2025
Sample name,2025_08_09_1CBN_3PVP10_MeOH_ASD_n60C_150C_10Cmin_x3
proceduresegments,Data Off ; Equilibrate -60.00 °C; Data On ; Ramp 10.00 °C/min to 150.00 °C; Data Off ; Isothermal 2.0 min; Data On ; Ramp 10.00 °C/min to -60.00 °C; Data Off ; Isothermal 2.0 min; Data On ; Ramp 10.00 °C/min to 150.00 °C; Data Off ; Isothermal 2.0 min; Data On ; Ramp 10.00 °C/min to -60.00 °C; Data Off ; Isothermal 2.0 min; Data On ; Ramp 10.00 °C/min to 150.00 °C
[File Parameters]
Run date,8/9/2025 1:14:37 AM
Trios version,5.1.1.46572
Original File Name,
Current File Name,D:\DSC2500\JYarger\2025_08_09_1CBN_3PVP10_MeOH_ASD_n60C_150C_10Cmin_x3.tri
[Procedure]
Procedure Name,CBN_PVP_TS_Pans_n60C_150C_10Cmin_x3
Sample Name,2025_08_09_1CBN_3PVP10_MeOH_ASD_n60C_150C_10Cmin_x3
Sample Mass,4.54 mg
Reference Sample Mass,0 mg
Pan Mass,32.72 mg
Pan Number,47
Reference Pan Mass,32.73 mg
Reference Pan Number,46
Pan Type,Aluminum
Comments,Thermal support Al pans/lids. DSC_Samples_A2_Tray_July2025 google sheet.
Project Name,Pharma
Operator,Yarger
Test,Custom
Unload Max Temperature,30
Unload Min Temperature,30
Load Max Temperature,30
Load Min Temperature,30
Stop on Gas Flow Error,Yes
[Signal List]
Signal #1,Time (min)
Signal #2,Temperature (°C)
Signal #3,Heat Flow (mW)
Signal #4,Delta T (µV)
Signal #5,Delta Tzero (µV)
Signal #6,Tzero Temperature (°C)
Signal #7,Cell Purge (mL/min)
Signal #8,Heater Temp (°C)
Signal #9,Power Delivered (W)
Signal #10,Reference Junction Temperature (°C)
Signal #11,Flange Temperature (°C)
Signal #12,Heat Flow Phase (rad)
Signal #13,Total Heat Capacity (J/°C)
Signal #14,Heat Capacity (J/°C)
[Configuration]
Company Name,ASU
Instrument Name,DSC2A-00468
Instrument Type,DSC2500
Serial Number,DSC2A-00468
IP,192.168.1.100
Location of Instrument,MRRC
DisplayType,Unknown
Sample Interval ,0.1 s/pt
Selected Heat Flow,T4P
Exotherm Direction,Down
Cell Serial,DRC2-00792
Lid Type,Standard
Cooler,RCS 90
Leave Cooler on at End of Sequence,On
Gas 2,Nitrogen
Gas Selected,Channel 1
Flow Rate,50 mL/min
Secondary Purge,On
Licensed Heat Flow,Heat Flow T4P
Modulation Licensed,Yes
[Versions]
Common IDD Version,1
Cortex Version,VER 2.10.2.31
Driver,5.0.0.6
GDM Version,1.0.3.3
TouchscreenVersion,1.0.0.16145
FEP Version,1.2.1.21
FEP Bootloader,2.0.0.5
AutoSampler Version,2.1.1.26
Auto Sampler Bootloader,2.0.0.5
FCM Version,1.1.0.3
FCM Bootloader,2.0.0.5
[Experiment Logs]
Experiment Log Entry # 1,Data On set to 0
Experiment Log Entry # 3,Equilibrate Segment -60 (C) Started
Experiment Log Entry # 5,Air Cool is off.
Experiment Log Entry # 7,Data On set to 1
Experiment Log Entry # 9,Ramp Segment 10 C/min to 150 Started
Experiment Log Entry # 11,Data On set to 0
Experiment Log Entry # 13,Isothermal Segment 2 min started
Experiment Log Entry # 15,Data On set to 1
Experiment Log Entry # 17,Ramp Segment 10 C/min to -60 Started
Experiment Log Entry # 19,Data On set to 0
Experiment Log Entry # 21,Isothermal Segment 2 min started
Experiment Log Entry # 23,Data On set to 1
Experiment Log Entry # 25,Ramp Segment 10 C/min to 150 Started
Experiment Log Entry # 27,Data On set to 0
Experiment Log Entry # 29,Isothermal Segment 2 min started
Experiment Log Entry # 31,Data On set to 1
Experiment Log Entry # 33,Ramp Segment 10 C/min to -60 Started
Experiment Log Entry # 35,Data On set to 0
Experiment Log Entry # 37,Isothermal Segment 2 min started
Experiment Log Entry # 39,Data On set to 1
Experiment Log Entry # 41,Ramp Segment 10 C/min to 150 Started
[Method Log]
Method Log Entry # 1,Data Off
Method Log Entry # 2,Equilibrate -60 °C
Method Log Entry # 3,Data On
Method Log Entry # 4,(Ramp 516396) Ramp 10 °C/minute to 150 °C
Method Log Entry # 5,Data Off
Method Log Entry # 6,Isothermal 2 minutes
Method Log Entry # 7,Data On
Method Log Entry # 8,(Ramp 516400) Ramp 10 °C/minute to -60 °C
Method Log Entry # 9,Data Off
Method Log Entry # 10,Isothermal 2 minutes
Method Log Entry # 11,Data On
Method Log Entry # 12,(Ramp 516404) Ramp 10 °C/minute to 150 °C
Method Log Entry # 13,Data Off
Method Log Entry # 14,Isothermal 2 minutes
Method Log Entry # 15,Data On
Method Log Entry # 16,(Ramp 516408) Ramp 10 °C/minute to -60 °C
Method Log Entry # 17,Data Off
Method Log Entry # 18,Isothermal 2 minutes
Method Log Entry # 19,Data On
Method Log Entry # 20,(Ramp 516412) Ramp 10 °C/minute to 150 °C
Cell Serial,DRC2-00792
[T1 Calibration]
Slope,-0.008529666
Offset,9.636258
Initial Temperature,98.23
GUID,f8bfdadc-4977-4fdf-ba6d-0ba9134940c3
[TZero Calibration]
Date Applied,11/29/2022 4:06:13 PM
Description,From -89.059 °C to 396.009 °C at 20.000°C/min
Gas Type,Nitrogen
Pan Type,None
Source Files 1,C:\Users\yargerlab\Desktop\DSC Data\General\TZero_calibration_11_29_22_2nd(2).tri
Source Files 2,C:\Users\yargerlab\Desktop\DSC Data\General\TZero_calibration_11_29_22_2nd(3).tri
Delta T Offset,13.05235
Delta T Slope,-0.007271007
Delta T0 Offset,-13.69128
Delta T0 Slope,0.06063341
[Temperature Calibration]
Date Applied,11/29/2022 7:12:28 PM
Description,From 106.590 °C to 186.590 °C at 10.000°C/min
Gas Type,Nitrogen
Pan Type,Tzero Aluminum Hermetic
Source Files 1,C:\Users\yargerlab\Desktop\DSC Data\General\Indium(6).tri
Measured 1,157.391
Known 1,156.598
[Cell Constant Calibration]
Date Applied,11/29/2022 7:12:29 PM
Description,From 106.590 °C to 186.590 °C at 10.000°C/min
Gas Type,Nitrogen
Pan Type,Tzero Aluminum Hermetic
Source Files 1,C:\Users\yargerlab\Desktop\DSC Data\General\Indium(6).tri
T4P KCell,1.006051
Onset Slope,63.26126 mW/°C
[Direct Cp Calibration]
Date Applied,11/30/2022 11:04:51 AM
Description,From -79.983 °C to 298.409 °C at 10.000°C/min
Gas Type,Nitrogen
Pan Type,Tzero Aluminum Hermetic
Source Files 1,C:\Users\yargerlab\Desktop\DSC Data\General\Sapphire_Heat_Capacity_11_30_22.tri
[Rev Cp Calibration]
Date Applied,11/30/2022 1:58:51 PM
Description,From -79.996 °C to 292.812 °C at 3.000°C/min
Gas Type,Nitrogen
Pan Type,Tzero Aluminum Hermetic
Source Files 1,C:\Users\yargerlab\Desktop\DSC Data\General\Sapphire_MDSC_Calibration_11_30_22.tri
[step]
Ramp 10.00 °C/min to 150.00 °C
Time,Temperature,Heat Flow (Normalized)
min,°C,W/g
0.00,-59.80,-0.043
0.01,-59.81,-0.041
0.03,-59.81,-0.039
0.05,-59.81,-0.036
0.06,-59.80,-0.033
0.08,-59.77,-0.028
0.09,-59.73,-0.017
0.11,-59.67,-0.004
0.12,-59.60,0.013
0.14,-59.51,0.031
0.15,-59.41,0.052
0.16,-59.30,0.073
0.18,-59.18,0.092
0.19,-59.06,0.111
0.21,-58.93,0.127
0.23,-58.79,0.141
0.24,-58.66,0.153
0.26,-58.52,0.163
0.27,-58.38,0.171
0.29,-58.23,0.177
0.30,-58.09,0.183
0.31,-57.95,0.187
0.33,-57.80,0.191
0.35,-57.66,0.193
0.36,-57.51,0.196
0.38,-57.37,0.197
0.39,-57.22,0.199
0.40,-57.08,0.200
0.42,-56.93,0.201
0.44,-56.78,0.202
0.45,-56.64,0.202
0.46,-56.49,0.203
0.48,-56.34,0.203
0.50,-56.20,0.204
0.51,-56.05,0.204
0.53,-55.90,0.204
0.54,-55.76,0.205
0.55,-55.61,0.206
0.57,-55.46,0.206
0.58,-55.31,0.206
0.60,-55.16,0.206
0.62,-55.02,0.207
0.63,-54.87,0.207
0.65,-54.72,0.207
0.66,-54.57,0.207
0.68,-54.42,0.208
0.69,-54.27,0.208
0.70,-54.13,0.208
0.72,-53.98,0.209
0.73,-53.83,0.209
0.75,-53.68,0.209
0.77,-53.53,0.210
0.78,-53.38,0.210
0.80,-53.24,0.210
0.81,-53.09,0.210
0.83,-52.94,0.211
0.84,-52.79,0.211
0.85,-52.64,0.211
0.87,-52.49,0.211
0.88,-52.34,0.212
0.90,-52.20,0.212
0.92,-52.05,0.212
0.93,-51.90,0.212
0.95,-51.75,0.212
0.96,-51.60,0.212
0.98,-51.45,0.213
0.99,-51.30,0.213
1.00,-51.15,0.213
1.02,-51.00,0.213
1.03,-50.85,0.214
1.05,-50.70,0.214
1.07,-50.55,0.214
1.08,-50.40,0.214
1.09,-50.26,0.214
1.11,-50.11,0.214
1.13,-49.95,0.215
1.14,-49.81,0.215
1.16,-49.66,0.215
1.17,-49.51,0.215
1.18,-49.36,0.215
1.20,-49.21,0.215
1.22,-49.06,0.215
1.23,-48.91,0.216
1.24,-48.76,0.216
1.26,-48.61,0.216
1.28,-48.46,0.216
1.29,-48.31,0.216
1.31,-48.16,0.216
1.32,-48.01,0.216
1.33,-47.86,0.216
1.35,-47.71,0.216
1.37,-47.56,0.217
1.38,-47.41,0.217
1.39,-47.26,0.217
1.41,-47.11,0.217
1.43,-46.96,0.217
1.44,-46.81,0.217
1.46,-46.66,0.217
1.47,-46.51,0.217
1.48,-46.36,0.217
1.50,-46.21,0.218
1.52,-46.06,0.218
1.53,-45.91,0.218
1.54,-45.76,0.218
1.56,-45.61,0.218
1.58,-45.46,0.218
1.59,-45.31,0.218
1.61,-45.16,0.218
1.62,-45.01,0.218
1.63,-44.86,0.218
1.65,-44.71,0.218
1.67,-44.56,0.218
1.68,-44.41,0.219
1.69,-44.26,0.219
1.71,-44.11,0.219
1.73,-43.96,0.219
1.74,-43.81,0.219
1.76,-43.66,0.219
1.77,-43.51,0.219
1.78,-43.36,0.219
1.80,-43.21,0.219
1.82,-43.06,0.219
1.83,-42.91,0.219
1.84,-42.76,0.219
1.86,-42.61,0.219
1.88,-42.46,0.220
1.89,-42.31,0.220
1.91,-42.16,0.220
1.92,-42.01,0.220
1.93,-41.86,0.220
1.95,-41.71,0.220
1.97,-41.56,0.220
1.98,-41.41,0.220
1.99,-41.26,0.220
2.01,-41.11,0.220
2.03,-40.96,0.220
2.04,-40.81,0.220
2.06,-40.66,0.220
2.07,-40.51,0.220
2.08,-40.36,0.220
2.10,-40.21,0.220
2.12,-40.06,0.220
2.13,-39.91,0.220
2.14,-39.76,0.220
2.16,-39.61,0.220
2.18,-39.46,0.220
2.19,-39.31,0.220
2.21,-39.16,0.220
2.22,-39.01,0.221
2.24,-38.86,0.221
2.25,-38.71,0.221
2.26,-38.56,0.221
2.28,-38.41,0.221
2.29,-38.26,0.221
2.31,-38.11,0.221
2.33,-37.96,0.221
2.34,-37.81,0.221
2.36,-37.66,0.221
2.37,-37.51,0.221
2.39,-37.36,0.221
2.40,-37.21,0.221
2.41,-37.06,0.221
2.43,-36.91,0.221
2.44,-36.76,0.222
2.46,-36.60,0.222
2.48,-36.45,0.222
2.49,-36.30,0.222
2.51,-36.15,0.222
2.52,-36.00,0.222
2.54,-35.85,0.222
2.55,-35.70,0.222
2.56,-35.55,0.222
2.58,-35.40,0.222
2.59,-35.25,0.222
2.61,-35.10,0.222
2.63,-34.95,0.222
2.64,-34.80,0.222
2.66,-34.65,0.222
2.67,-34.50,0.222
2.69,-34.35,0.222
2.70,-34.20,0.223
2.71,-34.05,0.223
2.73,-33.90,0.223
2.74,-33.75,0.223
2.76,-33.60,0.223
2.78,-33.45,0.223
2.79,-33.30,0.223
2.81,-33.15,0.223
2.82,-33.00,0.223
2.84,-32.85,0.223
2.85,-32.70,0.223
2.86,-32.55,0.223
2.88,-32.40,0.223
2.89,-32.25,0.223
2.91,-32.10,0.223
2.93,-31.95,0.223
2.94,-31.80,0.223
2.96,-31.65,0.223
2.97,-31.50,0.223
2.99,-31.35,0.223
3.00,-31.20,0.223
3.01,-31.05,0.223
3.03,-30.90,0.224
3.04,-30.75,0.224
3.06,-30.60,0.224
3.08,-30.45,0.224
3.09,-30.30,0.224
3.11,-30.15,0.224
3.12,-30.00,0.224
3.14,-29.85,0.224
3.15,-29.70,0.224
3.16,-29.55,0.224
3.18,-29.39,0.224
3.19,-29.25,0.224
3.21,-29.10,0.225
3.23,-28.95,0.225
3.24,-28.80,0.225
3.26,-28.64,0.225
3.27,-28.50,0.225
3.29,-28.35,0.225
3.30,-28.19,0.225
3.31,-28.04,0.225
3.33,-27.89,0.225
3.34,-27.74,0.225
3.36,-27.59,0.225
3.38,-27.44,0.225
3.39,-27.29,0.225
3.41,-27.14,0.225
3.42,-26.99,0.225
3.44,-26.84,0.225
3.45,-26.69,0.226
3.46,-26.54,0.226
3.48,-26.39,0.226
3.49,-26.24,0.226
3.51,-26.09,0.226
3.53,-25.94,0.226
3.54,-25.79,0.226
3.56,-25.64,0.226
3.57,-25.49,0.226
3.59,-25.34,0.226
3.60,-25.19,0.226
3.61,-25.04,0.226
3.63,-24.89,0.226
3.64,-24.74,0.226
3.66,-24.59,0.226
3.68,-24.44,0.227
3.69,-24.29,0.227
3.71,-24.14,0.227
3.72,-23.99,0.227
3.74,-23.84,0.227
3.75,-23.69,0.227
3.76,-23.54,0.227
3.78,-23.39,0.227
3.79,-23.24,0.227
3.81,-23.09,0.227
3.83,-22.94,0.227
3.84,-22.79,0.227
3.86,-22.64,0.227
3.87,-22.49,0.228
3.89,-22.34,0.228
3.90,-22.19,0.228
3.91,-22.04,0.228
3.93,-21.89,0.228
3.94,-21.74,0.228
3.96,-21.59,0.228
3.98,-21.43,0.228
3.99,-21.29,0.228
4.01,-21.13,0.228
4.02,-20.98,0.228
4.04,-20.83,0.228
4.05,-20.68,0.229
4.06,-20.53,0.229
4.08,-20.38,0.229
4.09,-20.23,0.229
4.11,-20.08,0.229
4.13,-19.93,0.229
4.14,-19.78,0.229
4.16,-19.63,0.229
4.17,-19.48,0.229
4.19,-19.33,0.229
4.20,-19.18,0.229
4.21,-19.03,0.229
4.23,-18.88,0.229
4.24,-18.73,0.229
4.26,-18.58,0.230
4.28,-18.43,0.230
4.29,-18.28,0.230
4.30,-18.13,0.230
4.32,-17.98,0.230
4.34,-17.83,0.230
4.35,-17.68,0.230
4.36,-17.53,0.230
4.38,-17.38,0.230
4.40,-17.23,0.230
4.41,-17.08,0.230
4.43,-16.93,0.230
4.44,-16.78,0.230
4.45,-16.63,0.231
4.47,-16.48,0.231
4.49,-16.33,0.231
4.50,-16.18,0.231
4.51,-16.03,0.231
4.53,-15.88,0.231
4.55,-15.73,0.231
4.56,-15.58,0.231
4.58,-15.43,0.231
4.59,-15.28,0.231
4.60,-15.13,0.232
4.62,-14.98,0.232
4.64,-14.83,0.232
4.65,-14.68,0.232
4.66,-14.53,0.232
4.68,-14.38,0.232
4.70,-14.23,0.232
4.71,-14.08,0.232
4.73,-13.93,0.232
4.74,-13.78,0.232
4.75,-13.63,0.232
4.77,-13.48,0.233
4.79,-13.33,0.233
4.80,-13.18,0.233
4.81,-13.03,0.233
4.83,-12.88,0.233
4.85,-12.73,0.233
4.86,-12.57,0.233
4.88,-12.42,0.233
4.89,-12.28,0.233
4.90,-12.12,0.233
4.92,-11.97,0.234
4.94,-11.82,0.234
4.95,-11.67,0.234
4.96,-11.52,0.234
4.98,-11.37,0.234
5.00,-11.22,0.234
5.01,-11.07,0.234
5.03,-10.92,0.234
5.04,-10.77,0.234
5.05,-10.62,0.235
5.07,-10.47,0.235
5.09,-10.32,0.235
5.10,-10.17,0.235
5.11,-10.02,0.235
5.13,-9.87,0.235
5.15,-9.72,0.235
5.16,-9.57,0.235
5.18,-9.42,0.235
5.19,-9.27,0.235
5.20,-9.12,0.236
5.22,-8.97,0.236
5.24,-8.82,0.236
5.25,-8.67,0.236
5.26,-8.52,0.236
5.28,-8.37,0.236
5.30,-8.22,0.236
5.31,-8.07,0.236
5.33,-7.92,0.236
5.34,-7.77,0.237
5.35,-7.62,0.237
5.37,-7.47,0.237
5.39,-7.32,0.237
5.40,-7.17,0.237
5.41,-7.02,0.237
5.43,-6.87,0.237
5.45,-6.72,0.237
5.46,-6.57,0.238
5.48,-6.42,0.238
5.49,-6.27,0.238
5.50,-6.12,0.238
5.52,-5.97,0.238
5.54,-5.82,0.238
5.55,-5.67,0.238
5.56,-5.52,0.238
5.58,-5.37,0.238
5.60,-5.22,0.239
5.61,-5.07,0.239
5.63,-4.92,0.239
5.64,-4.77,0.239
5.65,-4.62,0.239
5.67,-4.47,0.239
5.69,-4.32,0.239
5.70,-4.17,0.239
5.71,-4.02,0.240
5.73,-3.87,0.240
5.75,-3.72,0.240
5.76,-3.57,0.240
5.78,-3.42,0.240
5.79,-3.27,0.240
5.80,-3.12,0.240
5.82,-2.97,0.241
5.84,-2.82,0.241
5.85,-2.67,0.241
5.86,-2.52,0.241
5.88,-2.37,0.241
5.90,-2.22,0.241
5.91,-2.07,0.241
5.93,-1.92,0.241
5.94,-1.77,0.242
5.95,-1.61,0.242
5.97,-1.46,0.242
5.99,-1.31,0.242
6.00,-1.17,0.242
6.01,-1.01,0.242
6.03,-0.86,0.243
6.05,-0.71,0.243
6.06,-0.56,0.243
6.08,-0.41,0.243
6.09,-0.26,0.243
6.10,-0.11,0.243
6.12,0.04,0.243
6.14,0.19,0.243
6.15,0.34,0.244
6.16,0.49,0.244
6.18,0.64,0.244
6.20,0.79,0.244
6.21,0.94,0.244
6.23,1.09,0.244
6.24,1.24,0.244
6.25,1.39,0.244
6.27,1.53,0.244
6.29,1.69,0.245
6.30,1.84,0.245
6.31,1.99,0.245
6.33,2.14,0.245
6.35,2.29,0.245
6.36,2.44,0.245
6.38,2.59,0.246
6.39,2.74,0.246
6.40,2.89,0.246
6.42,3.04,0.246
6.44,3.19,0.246
6.45,3.34,0.246
6.46,3.49,0.247
6.48,3.64,0.247
6.50,3.79,0.247
6.51,3.94,0.247
6.53,4.09,0.247
6.54,4.24,0.247
6.55,4.39,0.247
6.57,4.54,0.248
6.59,4.69,0.248
6.60,4.84,0.248
6.61,4.99,0.248
6.63,5.14,0.248
6.65,5.29,0.248
6.66,5.44,0.249
6.68,5.59,0.249
6.69,5.74,0.249
6.70,5.89,0.249
6.72,6.04,0.249
6.74,6.19,0.250
6.75,6.34,0.250
6.76,6.49,0.250
6.78,6.64,0.250
6.80,6.79,0.250
6.81,6.94,0.250
6.83,7.09,0.251
6.84,7.24,0.251
6.85,7.39,0.251
6.87,7.54,0.251
6.89,7.69,0.251
6.90,7.84,0.251
6.91,7.99,0.252
6.93,8.14,0.252
6.95,8.29,0.252
6.96,8.44,0.252
6.98,8.59,0.252
6.99,8.74,0.252
7.00,8.89,0.253
7.02,9.05,0.253
7.04,9.19,0.253
7.05,9.34,0.253
7.06,9.50,0.253
7.08,9.65,0.254
7.10,9.80,0.254
7.11,9.95,0.254
7.13,10.10,0.254
7.14,10.25,0.255
7.15,10.40,0.255
7.17,10.55,0.255
7.19,10.70,0.255
7.20,10.85,0.255
7.21,11.00,0.256
7.23,11.15,0.256
7.25,11.30,0.256
7.26,11.45,0.256
7.28,11.60,0.256
7.29,11.75,0.257
7.30,11.90,0.257
7.32,12.05,0.257
7.34,12.20,0.257
7.35,12.35,0.257
7.36,12.50,0.257
7.38,12.65,0.258
7.40,12.80,0.258
7.41,12.95,0.258
7.43,13.10,0.258
7.44,13.25,0.259
7.45,13.40,0.259
7.47,13.55,0.259
7.49,13.70,0.259
7.50,13.85,0.259
7.51,14.00,0.260
7.53,14.15,0.260
7.55,14.30,0.260
7.56,14.45,0.260
7.58,14.60,0.260
7.59,14.75,0.261
7.60,14.90,0.261
7.62,15.05,0.261
7.64,15.20,0.261
7.65,15.35,0.262
7.66,15.50,0.262
7.68,15.65,0.262
7.70,15.80,0.262
7.71,15.95,0.263
7.73,16.10,0.263
7.74,16.25,0.263
7.75,16.40,0.263
7.77,16.55,0.264
7.79,16.70,0.264
7.80,16.85,0.264
7.81,17.00,0.264
7.83,17.15,0.265
7.85,17.30,0.265
7.86,17.45,0.265
7.88,17.60,0.265
7.89,17.75,0.266
7.90,17.90,0.266
7.92,18.05,0.266
7.94,18.20,0.266
7.95,18.35,0.267
7.96,18.50,0.267
7.98,18.65,0.267
8.00,18.80,0.267
8.01,18.95,0.268
8.03,19.10,0.268
8.04,19.25,0.268
8.05,19.40,0.268
8.07,19.55,0.269
8.09,19.70,0.269
8.10,19.85,0.269
8.11,20.00,0.270
8.13,20.15,0.270
8.15,20.30,0.270
8.16,20.45,0.270
8.18,20.60,0.271
8.19,20.75,0.271
8.20,20.90,0.271
8.22,21.05,0.271
8.24,21.20,0.272
8.25,21.35,0.272
8.26,21.50,0.272
8.28,21.65,0.273
8.30,21.80,0.273
8.31,21.95,0.273
8.33,22.10,0.273
8.34,22.25,0.274
8.35,22.40,0.274
8.37,22.55,0.274
8.39,22.70,0.275
8.40,22.85,0.275
8.41,23.00,0.275
8.43,23.15,0.276
8.45,23.30,0.276
8.46,23.45,0.276
8.48,23.60,0.277
8.49,23.75,0.277
8.50,23.90,0.277
8.52,24.05,0.277
8.53,24.20,0.278
8.55,24.35,0.278
8.57,24.50,0.278
8.58,24.65,0.279
8.60,24.80,0.279
8.61,24.95,0.279
8.63,25.10,0.280
8.64,25.25,0.280
8.65,25.40,0.280
8.67,25.55,0.281
8.68,25.70,0.281
8.70,25.85,0.281
8.72,26.00,0.282
8.73,26.15,0.282
8.75,26.30,0.282
8.76,26.45,0.283
8.78,26.60,0.283
8.79,26.75,0.283
8.80,26.90,0.284
8.82,27.05,0.284
8.83,27.21,0.284
8.85,27.35,0.285
8.87,27.51,0.285
8.88,27.65,0.286
8.90,27.81,0.286
8.91,27.96,0.286
8.93,28.10,0.287
8.94,28.25,0.287
8.95,28.40,0.288
8.97,28.56,0.288
8.98,28.70,0.288
9.00,28.86,0.289
9.02,29.01,0.289
9.03,29.15,0.290
9.05,29.31,0.290
9.06,29.45,0.290
9.08,29.60,0.291
9.09,29.75,0.291
9.10,29.90,0.291
9.12,30.05,0.292
9.13,30.20,0.292
9.15,30.36,0.293
9.17,30.51,0.293
9.18,30.65,0.294
9.20,30.81,0.294
9.21,30.96,0.295
9.23,31.11,0.295
9.24,31.26,0.295
9.25,31.41,0.296
9.27,31.56,0.296
9.28,31.71,0.297
9.30,31.86,0.297
9.32,32.00,0.298
9.33,32.16,0.298
9.35,32.31,0.299
9.36,32.46,0.299
9.38,32.61,0.300
9.39,32.76,0.300
9.40,32.91,0.300
9.42,33.06,0.301
9.43,33.21,0.301
9.45,33.36,0.302
9.47,33.51,0.302
9.48,33.66,0.303
9.50,33.81,0.303
9.51,33.96,0.304
9.53,34.11,0.304
9.54,34.26,0.305
9.55,34.41,0.305
9.57,34.56,0.306
9.58,34.71,0.306
9.60,34.86,0.307
9.62,35.01,0.307
9.63,35.16,0.308
9.65,35.31,0.308
9.66,35.46,0.309
9.68,35.61,0.310
9.69,35.76,0.310
9.70,35.91,0.311
9.72,36.06,0.311
9.73,36.21,0.312
9.75,36.36,0.312
9.77,36.51,0.313
9.78,36.66,0.313
9.80,36.81,0.314
9.81,36.96,0.315
9.83,37.11,0.315
9.84,37.26,0.316
9.85,37.41,0.316
9.87,37.56,0.317
9.88,37.71,0.318
9.90,37.86,0.318
9.92,38.01,0.319
9.93,38.16,0.320
9.95,38.31,0.321
9.96,38.46,0.322
9.98,38.61,0.322
9.99,38.76,0.323
10.00,38.91,0.324
10.02,39.06,0.325
10.03,39.21,0.325
10.05,39.36,0.326
10.07,39.51,0.326
10.08,39.66,0.327
10.10,39.81,0.328
10.11,39.96,0.329
10.13,40.11,0.330
10.14,40.26,0.330
10.15,40.41,0.331
10.17,40.56,0.332
10.18,40.71,0.332
10.20,40.86,0.333
10.22,41.01,0.334
10.23,41.16,0.335
10.25,41.31,0.336
10.26,41.46,0.336
10.28,41.61,0.338
10.29,41.76,0.339
10.30,41.90,0.340
10.32,42.06,0.340
10.33,42.21,0.342
10.35,42.36,0.343
10.37,42.50,0.344
10.38,42.65,0.345
10.40,42.80,0.346
10.41,42.95,0.347
10.43,43.10,0.348
10.44,43.25,0.349
10.45,43.40,0.350
10.47,43.55,0.351
10.48,43.70,0.353
10.50,43.85,0.354
10.52,44.00,0.356
10.53,44.15,0.357
10.55,44.30,0.359
10.56,44.45,0.360
10.58,44.60,0.361
10.59,44.75,0.363
10.60,44.90,0.365
10.62,45.05,0.367
10.63,45.20,0.368
10.65,45.35,0.370
10.67,45.50,0.372
10.68,45.65,0.373
10.70,45.80,0.375
10.71,45.95,0.377
10.73,46.10,0.379
10.74,46.25,0.381
10.75,46.40,0.383
10.77,46.55,0.384
10.78,46.70,0.386
10.80,46.85,0.389
10.82,47.00,0.391
10.83,47.15,0.392
10.85,47.30,0.395
10.86,47.45,0.398
10.88,47.60,0.399
10.89,47.75,0.402
10.90,47.90,0.405
10.92,48.04,0.407
10.93,48.20,0.410
10.95,48.34,0.412
10.97,48.49,0.416
10.98,48.64,0.418
11.00,48.79,0.422
11.01,48.94,0.425
11.03,49.09,0.427
11.04,49.24,0.431
11.05,49.39,0.433
11.07,49.54,0.438
11.08,49.69,0.440
11.10,49.84,0.444
11.12,49.99,0.447
11.13,50.14,0.452
11.15,50.28,0.454
11.16,50.43,0.458
11.18,50.58,0.461
11.19,50.73,0.464
11.20,50.88,0.467
11.22,51.03,0.470
11.23,51.18,0.473
11.25,51.33,0.476
11.27,51.48,0.478
11.28,51.63,0.481
11.30,51.78,0.483
11.31,51.93,0.486
11.33,52.08,0.487
11.34,52.23,0.489
11.35,52.38,0.490
11.37,52.52,0.491
11.38,52.67,0.492
11.40,52.82,0.492
11.42,52.97,0.493
11.43,53.12,0.493
11.45,53.27,0.493
11.46,53.42,0.494
11.48,53.57,0.494
11.49,53.72,0.494
11.50,53.87,0.494
11.52,54.02,0.494
11.53,54.17,0.494
11.55,54.32,0.494
11.57,54.47,0.494
11.58,54.63,0.493
11.60,54.78,0.493
11.61,54.93,0.493
11.63,55.08,0.493
11.64,55.23,0.492
11.65,55.38,0.492
11.67,55.53,0.492
11.68,55.68,0.491
11.70,55.83,0.491
11.72,55.98,0.491
11.73,56.13,0.490
11.75,56.28,0.490
11.76,56.43,0.490
11.78,56.58,0.490
11.79,56.74,0.490
11.80,56.89,0.490
11.82,57.04,0.490
11.83,57.19,0.490
11.85,57.34,0.490
11.87,57.49,0.490
11.88,57.64,0.490
11.90,57.79,0.490
11.91,57.94,0.490
11.93,58.09,0.490
11.94,58.24,0.490
11.95,58.39,0.490
11.97,58.54,0.490
11.98,58.69,0.490
12.00,58.84,0.490
12.02,58.99,0.491
12.03,59.14,0.491
12.05,59.29,0.492
12.06,59.44,0.492
12.08,59.58,0.492
12.09,59.74,0.493
12.10,59.88,0.493
12.12,60.03,0.494
12.13,60.18,0.494
12.15,60.33,0.495
12.17,60.48,0.496
12.18,60.63,0.497
12.20,60.78,0.497
12.21,60.93,0.498
12.23,61.08,0.499
12.24,61.23,0.500
12.25,61.38,0.501
12.27,61.53,0.503
12.28,61.68,0.503
12.30,61.83,0.505
12.32,61.98,0.505
12.33,62.13,0.506
12.35,62.28,0.507
12.36,62.43,0.508
12.38,62.58,0.509
12.39,62.73,0.510
12.40,62.88,0.511
12.42,63.03,0.512
12.43,63.18,0.513
12.45,63.33,0.514
12.47,63.48,0.515
12.48,63.63,0.516
12.50,63.78,0.517
12.51,63.93,0.518
12.53,64.08,0.519
12.54,64.23,0.521
12.55,64.38,0.522
12.57,64.53,0.523
12.58,64.68,0.524
12.60,64.83,0.525
12.62,64.98,0.526
12.63,65.13,0.527
12.65,65.28,0.527
12.66,65.43,0.528
12.68,65.58,0.530
12.69,65.73,0.531
12.70,65.88,0.532
12.72,66.03,0.533
12.73,66.18,0.533
12.75,66.32,0.535
12.77,66.48,0.536
12.78,66.63,0.537
12.80,66.78,0.538
12.81,66.93,0.540
12.83,67.07,0.541
12.84,67.22,0.541
12.85,67.37,0.542
12.87,67.52,0.543
12.88,67.67,0.544
12.90,67.82,0.545
12.92,67.97,0.546
12.93,68.12,0.547
12.95,68.27,0.548
12.96,68.42,0.549
12.98,68.57,0.550
12.99,68.72,0.551
13.00,68.87,0.552
13.02,69.02,0.553
13.03,69.17,0.555
13.05,69.32,0.556
13.07,69.47,0.557
13.08,69.62,0.558
13.10,69.77,0.559
13.11,69.92,0.560
13.13,70.07,0.561
13.14,70.22,0.562
13.15,70.37,0.563
13.17,70.52,0.564
13.18,70.67,0.565
13.20,70.82,0.566
13.22,70.97,0.567
13.23,71.12,0.568
13.25,71.27,0.569
13.26,71.42,0.570
13.28,71.57,0.570
13.29,71.72,0.572
13.30,71.87,0.573
13.32,72.02,0.574
13.33,72.17,0.575
13.35,72.32,0.576
13.37,72.47,0.577
13.38,72.62,0.578
13.40,72.77,0.579
13.41,72.92,0.580
13.43,73.07,0.581
13.44,73.22,0.582
13.45,73.37,0.583
13.47,73.52,0.584
13.48,73.67,0.585
13.50,73.82,0.587
13.52,73.97,0.588
13.53,74.12,0.589
13.55,74.27,0.590
13.56,74.42,0.591
13.58,74.57,0.592
13.59,74.72,0.593
13.60,74.87,0.595
13.62,75.02,0.595
13.63,75.17,0.596
13.65,75.32,0.597
13.67,75.47,0.599
13.68,75.62,0.599
13.70,75.77,0.600
13.71,75.92,0.601
13.73,76.07,0.602
13.74,76.22,0.603
13.75,76.37,0.604
13.77,76.52,0.605
13.78,76.67,0.606
13.80,76.82,0.606
13.82,76.97,0.608
13.83,77.12,0.609
13.85,77.27,0.610
13.86,77.42,0.611
13.88,77.57,0.612
13.89,77.72,0.613
13.90,77.87,0.614
13.92,78.02,0.615
13.93,78.17,0.616
13.95,78.32,0.617
13.97,78.47,0.618
13.98,78.61,0.619
14.00,78.77,0.620
14.01,78.92,0.621
14.03,79.07,0.621
14.04,79.22,0.622
14.05,79.37,0.623
14.07,79.52,0.624
14.08,79.67,0.625
14.10,79.82,0.626
14.12,79.96,0.627
14.13,80.11,0.627
14.15,80.26,0.628
14.16,80.41,0.629
14.18,80.57,0.630
14.19,80.71,0.631
14.20,80.86,0.632
14.22,81.02,0.633
14.23,81.16,0.634
14.25,81.32,0.635
14.27,81.46,0.635
14.28,81.61,0.636
14.30,81.77,0.637
14.31,81.91,0.638
14.33,82.07,0.638
14.34,82.21,0.639
14.35,82.36,0.641
14.37,82.52,0.641
14.38,82.67,0.642
14.40,82.81,0.643
14.42,82.96,0.644
14.43,83.11,0.644
14.45,83.26,0.645
14.46,83.41,0.646
14.48,83.56,0.647
14.49,83.71,0.647
14.50,83.86,0.648
14.52,84.01,0.649
14.53,84.16,0.650
14.55,84.31,0.650
14.57,84.46,0.651
14.58,84.61,0.652
14.60,84.76,0.652
14.61,84.91,0.653
14.63,85.06,0.654
14.64,85.21,0.655
14.65,85.36,0.656
14.67,85.51,0.657
14.68,85.66,0.657
14.70,85.81,0.658
14.72,85.96,0.659
14.73,86.11,0.659
14.75,86.26,0.660
14.76,86.41,0.660
14.78,86.56,0.661
14.79,86.71,0.662
14.80,86.86,0.662
14.82,87.01,0.663
14.83,87.16,0.663
14.85,87.31,0.664
14.87,87.46,0.665
14.88,87.61,0.665
14.90,87.76,0.666
14.91,87.91,0.667
14.93,88.06,0.668
14.94,88.21,0.668
14.95,88.36,0.669
14.97,88.51,0.670
14.98,88.66,0.670
15.00,88.81,0.671
15.02,88.96,0.671
15.03,89.11,0.672
15.05,89.26,0.673
15.06,89.41,0.673
15.08,89.56,0.674
15.09,89.71,0.674
15.10,89.86,0.675
15.12,90.01,0.675
15.13,90.16,0.676
15.15,90.31,0.676
15.17,90.46,0.677
15.18,90.61,0.678
15.20,90.76,0.678
15.21,90.91,0.679
15.23,91.06,0.679
15.24,91.21,0.680
15.25,91.36,0.680
15.27,91.51,0.681
15.28,91.66,0.681
15.30,91.81,0.682
15.32,91.96,0.682
15.33,92.11,0.683
15.35,92.26,0.683
15.36,92.41,0.683
15.38,92.56,0.684
15.39,92.71,0.684
15.40,92.86,0.685
15.42,93.01,0.685
15.43,93.16,0.685
15.45,93.31,0.686
15.47,93.46,0.686
15.48,93.61,0.687
15.50,93.76,0.687
15.51,93.91,0.687
15.53,94.07,0.688
15.54,94.21,0.688
15.55,94.37,0.688
15.57,94.52,0.689
15.58,94.67,0.689
15.60,94.82,0.689
15.62,94.97,0.690
15.63,95.12,0.690
15.65,95.27,0.690
15.66,95.42,0.691
15.68,95.57,0.691
15.69,95.72,0.691
15.70,95.87,0.691
15.72,96.02,0.692
15.73,96.17,0.692
15.75,96.32,0.692
15.77,96.47,0.692
15.78,96.62,0.692
15.80,96.77,0.693
15.81,96.92,0.693
15.83,97.07,0.693
15.84,97.22,0.693
15.85,97.37,0.693
15.87,97.52,0.693
15.88,97.67,0.693
15.90,97.82,0.694
15.92,97.97,0.694
15.93,98.12,0.694
15.95,98.27,0.694
15.96,98.42,0.694
15.98,98.57,0.694
15.99,98.72,0.694
16.00,98.87,0.694
16.02,99.02,0.694
16.03,99.17,0.694
16.05,99.32,0.694
16.07,99.47,0.694
16.08,99.62,0.694
16.10,99.77,0.694
16.11,99.92,0.694
16.13,100.07,0.694
16.14,100.22,0.694
16.15,100.37,0.694
16.17,100.52,0.694
16.18,100.67,0.694
16.20,100.82,0.694
16.22,100.97,0.694
16.23,101.12,0.693
16.25,101.27,0.693
16.26,101.42,0.693
16.28,101.57,0.693
16.29,101.72,0.693
16.30,101.87,0.693
16.32,102.02,0.693
16.33,102.17,0.693
16.35,102.32,0.692
16.37,102.47,0.692
16.38,102.63,0.692
16.40,102.78,0.692
16.41,102.93,0.692
16.43,103.08,0.691
16.44,103.23,0.691
16.45,103.38,0.691
16.47,103.53,0.691
16.48,103.68,0.690
16.50,103.83,0.690
16.52,103.98,0.690
16.53,104.13,0.690
16.55,104.28,0.689
16.56,104.43,0.689
16.58,104.58,0.688
16.59,104.73,0.688
16.60,104.88,0.688
16.62,105.03,0.687
16.63,105.18,0.687
16.65,105.33,0.687
16.67,105.48,0.686
16.68,105.63,0.686
16.70,105.78,0.685
16.71,105.93,0.685
16.73,106.08,0.685
16.74,106.23,0.684
16.75,106.38,0.684
16.77,106.54,0.683
16.78,106.68,0.682
16.80,106.84,0.682
16.82,106.99,0.681
16.83,107.14,0.681
16.85,107.29,0.680
16.86,107.44,0.680
16.88,107.59,0.679
16.89,107.74,0.679
16.90,107.89,0.678
16.92,108.04,0.678
16.93,108.19,0.677
16.95,108.34,0.676
16.97,108.49,0.676
16.98,108.64,0.675
17.00,108.79,0.675
17.01,108.94,0.674
17.03,109.09,0.673
17.04,109.24,0.672
17.05,109.39,0.672
17.07,109.54,0.671
17.08,109.69,0.670
17.10,109.84,0.670
17.12,109.99,0.669
17.13,110.14,0.669
17.14,110.29,0.668
17.16,110.44,0.667
17.18,110.59,0.666
17.19,110.74,0.665
17.21,110.89,0.665
17.22,111.04,0.664
17.23,111.19,0.663
17.25,111.34,0.662
17.27,111.49,0.661
17.28,111.65,0.661
17.29,111.80,0.660
17.31,111.95,0.659
17.33,112.10,0.658
17.34,112.25,0.657
17.36,112.40,0.656
17.37,112.55,0.656
17.38,112.70,0.655
17.40,112.85,0.654
17.42,113.00,0.653
17.43,113.15,0.652
17.44,113.30,0.651
17.46,113.45,0.650
17.48,113.60,0.649
17.49,113.75,0.649
17.51,113.90,0.648
17.52,114.05,0.647
17.53,114.20,0.646
17.55,114.35,0.645
17.57,114.50,0.645
17.58,114.65,0.644
17.59,114.80,0.643
17.61,114.95,0.642
17.63,115.10,0.641
17.64,115.26,0.640
17.66,115.41,0.639
17.67,115.56,0.638
17.68,115.71,0.637
17.70,115.86,0.636
17.72,116.01,0.635
17.73,116.16,0.634
17.74,116.31,0.634
17.76,116.46,0.633
17.78,116.61,0.631
17.79,116.76,0.630
17.81,116.91,0.629
17.82,117.06,0.628
17.83,117.21,0.627
17.85,117.36,0.626
17.87,117.51,0.626
17.88,117.66,0.625
17.89,117.81,0.624
17.91,117.96,0.623
17.93,118.11,0.622
17.94,118.26,0.622
17.96,118.41,0.620
17.97,118.56,0.619
17.98,118.71,0.618
18.00,118.86,0.617
18.02,119.01,0.616
18.03,119.16,0.615
18.04,119.32,0.614
18.06,119.47,0.613
18.08,119.62,0.612
18.09,119.77,0.611
18.11,119.92,0.610
18.12,120.07,0.609
18.13,120.22,0.609
18.15,120.37,0.608
18.17,120.52,0.607
18.18,120.67,0.606
18.19,120.82,0.605
18.21,120.97,0.604
18.23,121.12,0.603
18.24,121.27,0.602
18.26,121.42,0.601
18.27,121.57,0.600
18.28,121.72,0.599
18.30,121.87,0.598
18.32,122.02,0.597
18.33,122.17,0.596
18.34,122.32,0.595
18.36,122.47,0.594
18.38,122.63,0.593
18.39,122.77,0.592
18.41,122.92,0.591
18.42,123.07,0.590
18.43,123.22,0.589
18.45,123.38,0.588
18.47,123.52,0.587
18.48,123.68,0.586
18.49,123.83,0.585
18.51,123.98,0.585
18.53,124.13,0.584
18.54,124.28,0.583
18.56,124.43,0.582
18.57,124.58,0.581
18.58,124.73,0.580
18.60,124.88,0.579
18.62,125.03,0.578
18.63,125.18,0.576
18.64,125.33,0.575
18.66,125.48,0.574
18.68,125.63,0.573
18.69,125.78,0.573
18.71,125.93,0.571
18.72,126.08,0.571
18.73,126.23,0.569
18.75,126.38,0.568
18.77,126.53,0.567
18.78,126.69,0.566
18.79,126.84,0.566
18.81,126.99,0.565
18.83,127.14,0.564
18.84,127.29,0.563
18.86,127.44,0.562
18.87,127.59,0.561
18.88,127.74,0.560
18.90,127.89,0.559
18.92,128.04,0.558
18.93,128.19,0.556
18.94,128.34,0.556
18.96,128.49,0.554
18.98,128.64,0.554
18.99,128.79,0.553
19.01,128.94,0.552
19.02,129.09,0.551
19.03,129.24,0.550
19.05,129.39,0.550
19.07,129.54,0.548
19.08,129.69,0.547
19.09,129.85,0.546
19.11,130.00,0.545
19.13,130.15,0.544
19.14,130.30,0.543
19.16,130.45,0.542
19.17,130.60,0.541
19.18,130.75,0.540
19.20,130.90,0.540
19.22,131.05,0.539
19.23,131.20,0.538
19.24,131.35,0.536
19.26,131.50,0.536
19.28,131.65,0.534
19.29,131.80,0.534
19.31,131.95,0.533
19.32,132.10,0.532
19.33,132.25,0.531
19.35,132.40,0.530
19.37,132.55,0.529
19.38,132.70,0.528
19.39,132.85,0.527
19.41,133.00,0.527
19.43,133.15,0.526
19.44,133.30,0.524
19.46,133.45,0.523
19.47,133.60,0.521
19.48,133.76,0.521
19.50,133.90,0.520
19.52,134.06,0.519
19.53,134.21,0.518
19.54,134.36,0.518
19.56,134.51,0.517
19.58,134.66,0.515
19.59,134.81,0.514
19.61,134.96,0.512
19.62,135.11,0.511
19.63,135.26,0.510
19.65,135.41,0.509
19.67,135.56,0.508
19.68,135.71,0.506
19.69,135.86,0.505
19.71,136.01,0.504
19.73,136.16,0.503
19.74,136.31,0.501
19.76,136.46,0.501
19.77,136.61,0.500
19.78,136.76,0.498
19.80,136.91,0.498
19.82,137.06,0.497
19.83,137.21,0.495
19.84,137.36,0.494
19.86,137.52,0.493
19.88,137.67,0.492
19.89,137.82,0.491
19.91,137.97,0.489
19.92,138.12,0.488
19.93,138.27,0.487
19.95,138.42,0.486
19.97,138.57,0.486
19.98,138.72,0.484
19.99,138.87,0.483
20.01,139.02,0.481
20.03,139.17,0.481
20.04,139.32,0.480
20.06,139.47,0.479
20.07,139.62,0.478
20.08,139.77,0.477
20.10,139.92,0.477
20.12,140.07,0.476
20.13,140.22,0.474
20.14,140.37,0.474
20.16,140.52,0.473
20.18,140.67,0.472
20.19,140.82,0.471
20.21,140.98,0.470
20.22,141.12,0.468
20.23,141.28,0.468
20.25,141.43,0.467
20.27,141.58,0.466
20.28,141.73,0.465
20.29,141.88,0.463
20.31,142.03,0.462
20.33,142.18,0.461
20.34,142.33,0.460
20.36,142.48,0.459
20.37,142.63,0.458
20.38,142.78,0.457
20.40,142.93,0.456
20.42,143.08,0.456
20.43,143.23,0.455
20.44,143.38,0.454
20.46,143.53,0.453
20.48,143.68,0.452
20.49,143.83,0.451
20.51,143.98,0.451
20.52,144.13,0.449
20.53,144.29,0.449
20.55,144.43,0.448
20.57,144.59,0.447
20.58,144.74,0.446
20.59,144.89,0.446
20.61,145.04,0.445
20.63,145.19,0.444
20.64,145.34,0.443
20.66,145.49,0.442
20.67,145.64,0.442
20.68,145.79,0.441
20.70,145.94,0.440
20.72,146.09,0.439
20.73,146.24,0.438
20.74,146.39,0.437
20.76,146.54,0.436
20.78,146.69,0.436
20.79,146.84,0.435
20.81,146.99,0.434
20.82,147.14,0.433
20.83,147.29,0.433
20.85,147.44,0.432
20.87,147.59,0.432
20.88,147.74,0.431
20.89,147.89,0.430
20.91,148.04,0.429
20.93,148.19,0.429
20.94,148.34,
20.96,148.50,
20.97,148.64,
20.98,,
20.99,,

[step]
Ramp 10.00 °C/min to -60.00 °C
Time,Temperature,Heat Flow (Normalized)
min,°C,W/g
22.99,150.15,-0.015
23.01,150.15,-0.015
23.02,150.15,-0.015
23.04,150.14,-0.016
23.05,150.12,-0.016
23.07,150.10,-0.030
23.08,150.05,-0.055
23.10,149.99,-0.084
23.11,149.91,-0.125
23.13,149.82,-0.169
23.14,149.71,-0.211
23.16,149.60,-0.250
23.17,149.47,-0.280
23.19,149.35,-0.305
23.20,149.21,-0.325
23.22,149.08,-0.340
23.23,148.94,-0.352
23.25,148.80,-0.360
23.26,148.66,-0.369
23.28,148.52,-0.375
23.29,148.38,-0.379
23.31,148.23,-0.383
23.32,148.08,-0.388
23.34,147.94,-0.390
23.35,147.79,-0.392
23.37,147.64,-0.394
23.38,147.50,-0.395
23.40,147.35,-0.396
23.41,147.20,-0.397
23.43,147.05,-0.398
23.44,146.91,-0.398
23.46,146.76,-0.399
23.47,146.61,-0.400
23.49,146.46,-0.400
23.50,146.31,-0.400
23.52,146.16,-0.401
23.53,146.01,-0.401
23.55,145.87,-0.401
23.56,145.72,-0.402
23.58,145.57,-0.402
23.59,145.42,-0.402
23.61,145.27,-0.402
23.62,145.12,-0.403
23.64,144.97,-0.403
23.65,144.82,-0.403
23.67,144.67,-0.403
23.68,144.52,-0.404
23.70,144.37,-0.404
23.71,144.23,-0.404
23.73,144.08,-0.404
23.74,143.93,-0.404
23.76,143.78,-0.405
23.77,143.63,-0.405
23.79,143.48,-0.405
23.80,143.33,-0.405
23.82,143.18,-0.405
23.83,143.03,-0.405
23.85,142.88,-0.406
23.86,142.73,-0.406
23.88,142.58,-0.406
23.89,142.43,-0.406
23.91,142.28,-0.406
23.92,142.14,-0.406
23.94,141.99,-0.406
23.95,141.84,-0.406
23.97,141.69,-0.406
23.98,141.54,-0.407
24.00,141.39,-0.407
24.01,141.24,-0.407
24.03,141.09,-0.407
24.04,140.94,-0.407
24.06,140.79,-0.407
24.07,140.64,-0.407
24.09,140.49,-0.407
24.10,140.34,-0.407
24.12,140.19,-0.407
24.13,140.04,-0.407
24.15,139.89,-0.407
24.16,139.74,-0.407
24.18,139.60,-0.407
24.19,139.45,-0.407
24.21,139.30,-0.407
24.22,139.15,-0.407
24.24,139.00,-0.407
24.25,138.85,-0.407
24.27,138.70,-0.408
24.28,138.55,-0.408
24.30,138.40,-0.408
24.31,138.25,-0.408
24.33,138.10,-0.408
24.34,137.95,-0.408
24.36,137.80,-0.408
24.37,137.65,-0.408
24.39,137.50,-0.408
24.40,137.35,-0.408
24.42,137.20,-0.408
24.43,137.05,-0.408
24.45,136.90,-0.408
24.46,136.75,-0.408
24.48,136.60,-0.408
24.49,136.45,-0.408
24.51,136.30,-0.408
24.52,136.15,-0.408
24.54,136.00,-0.408
24.55,135.85,-0.408
24.57,135.70,-0.408
24.58,135.55,-0.408
24.60,135.40,-0.408
24.61,135.25,-0.408
24.63,135.10,-0.408
24.64,134.95,-0.408
24.66,134.80,-0.407
24.67,134.65,-0.407
24.69,134.50,-0.407
24.70,134.35,-0.407
24.72,134.20,-0.407
24.73,134.05,-0.407
24.75,133.90,-0.407
24.76,133.75,-0.407
24.78,133.60,-0.407
24.79,133.45,-0.407
24.81,133.30,-0.407
24.82,133.15,-0.407
24.84,133.00,-0.407
24.85,132.85,-0.407
24.87,132.70,-0.407
24.88,132.55,-0.407
24.90,132.40,-0.407
24.91,132.25,-0.407
24.93,132.10,-0.407
24.94,131.95,-0.407
24.96,131.80,-0.407
24.97,131.65,-0.407
24.99,131.50,-0.407
25.00,131.35,-0.407
25.02,131.20,-0.407
25.03,131.06,-0.407
25.05,130.90,-0.407
25.06,130.76,-0.406
25.08,130.61,-0.406
25.09,130.46,-0.406
25.11,130.31,-0.406
25.12,130.16,-0.406
25.14,130.00,-0.406
25.15,129.86,-0.406
25.17,129.71,-0.406
25.18,129.56,-0.406
25.20,129.41,-0.406
25.21,129.25,-0.406
25.23,129.10,-0.406
25.24,128.95,-0.406
25.26,128.80,-0.406
25.27,128.65,-0.406
25.29,128.50,-0.406
25.30,128.35,-0.406
25.32,128.20,-0.406
25.33,128.05,-0.406
25.35,127.90,-0.406
25.36,127.75,-0.406
25.38,127.60,-0.406
25.39,127.45,-0.406
25.41,127.30,-0.406
25.42,127.15,-0.406
25.44,127.00,-0.406
25.45,126.85,-0.406
25.47,126.70,-0.406
25.48,126.55,-0.406
25.50,126.41,-0.405
25.51,126.25,-0.405
25.53,126.11,-0.405
25.54,125.95,-0.405
25.56,125.80,-0.405
25.57,125.66,-0.405
25.59,125.50,-0.405
25.60,125.36,-0.405
25.62,125.20,-0.405
25.63,125.06,-0.405
25.65,124.91,-0.405
25.66,124.76,-0.405
25.68,124.61,-0.405
25.69,124.46,-0.404
25.71,124.31,-0.404
25.72,124.16,-0.404
25.74,124.01,-0.404
25.75,123.86,-0.404
25.77,123.71,-0.404
25.78,123.56,-0.404
25.80,123.41,-0.404
25.81,123.26,-0.404
25.83,123.11,-0.404
25.84,122.96,-0.404
25.86,122.81,-0.404
25.87,122.66,-0.404
25.89,122.51,-0.404
25.90,122.36,-0.403
25.92,122.21,-0.403
25.93,122.06,-0.403
25.95,121.91,-0.403
25.96,121.76,-0.403
25.98,121.61,-0.403
25.99,121.46,-0.403
26.01,121.31,-0.403
26.02,121.16,-0.403
26.04,121.01,-0.403
26.05,120.86,-0.403
26.07,120.71,-0.403
26.08,120.56,-0.403
26.10,120.41,-0.403
26.11,120.26,-0.403
26.13,120.11,-0.403
26.14,119.96,-0.403
26.16,119.81,-0.403
26.17,119.66,-0.402
26.19,119.51,-0.402
26.20,119.36,-0.402
26.22,119.21,-0.402
26.23,119.06,-0.402
26.25,118.91,-0.402
26.26,118.76,-0.402
26.28,118.61,-0.402
26.29,118.46,-0.402
26.31,118.31,-0.402
26.32,118.16,-0.402
26.34,118.01,-0.402
26.35,117.86,-0.402
26.37,117.71,-0.402
26.38,117.56,-0.402
26.40,117.41,-0.402
26.41,117.26,-0.401
26.43,117.11,-0.401
26.44,116.96,-0.401
26.46,116.81,-0.401
26.47,116.66,-0.401
26.49,116.51,-0.401
26.50,116.36,-0.401
26.52,116.21,-0.401
26.53,116.06,-0.401
26.55,115.91,-0.401
26.56,115.76,-0.401
26.58,115.61,-0.401
26.59,115.46,-0.401
26.61,115.31,-0.401
26.62,115.16,-0.401
26.64,115.01,-0.401
26.65,114.86,-0.401
26.67,114.71,-0.400
26.68,114.56,-0.400
26.70,114.41,-0.400
26.71,114.26,-0.400
26.73,114.11,-0.400
26.74,113.96,-0.400
26.76,113.81,-0.400
26.77,113.66,-0.400
26.79,113.51,-0.400
26.80,113.36,-0.400
26.82,113.21,-0.400
26.83,113.06,-0.400
26.85,112.91,-0.399
26.86,112.76,-0.399
26.88,112.61,-0.399
26.89,112.46,-0.399
26.91,112.31,-0.399
26.92,112.16,-0.399
26.94,112.01,-0.399
26.95,111.86,-0.399
26.97,111.71,-0.399
26.98,111.56,-0.399
27.00,111.41,-0.399
27.01,111.26,-0.399
27.03,111.11,-0.399
27.04,110.96,-0.399
27.06,110.80,-0.399
27.07,110.65,-0.399
27.09,110.50,-0.399
27.10,110.35,-0.399
27.12,110.20,-0.398
27.13,110.06,-0.398
27.15,109.91,-0.398
27.16,109.76,-0.398
27.18,109.61,-0.398
27.19,109.46,-0.397
27.21,109.31,-0.397
27.22,109.16,-0.397
27.24,109.01,-0.397
27.25,108.86,-0.397
27.27,108.70,-0.397
27.28,108.56,-0.397
27.30,108.41,-0.397
27.31,108.26,-0.396
27.33,108.11,-0.396
27.34,107.96,-0.396
27.36,107.81,-0.396
27.37,107.66,-0.396
27.39,107.51,-0.396
27.40,107.36,-0.395
27.42,107.21,-0.395
27.43,107.06,-0.395
27.45,106.91,-0.395
27.46,106.76,-0.395
27.48,106.61,-0.395
27.49,106.46,-0.394
27.51,106.31,-0.394
27.52,106.16,-0.394
27.54,106.01,-0.394
27.55,105.86,-0.394
27.57,105.71,-0.394
27.58,105.56,-0.393
27.60,105.41,-0.393
27.61,105.26,-0.393
27.63,105.11,-0.393
27.64,104.96,-0.393
27.66,104.81,-0.393
27.67,104.66,-0.393
27.69,104.51,-0.392
27.70,104.36,-0.392
27.72,104.21,-0.392
27.73,104.06,-0.392
27.75,103.91,-0.392
27.76,103.76,-0.391
27.78,103.61,-0.391
27.79,103.46,-0.391
27.81,103.31,-0.391
27.82,103.16,-0.391
27.84,103.01,-0.390
27.85,102.86,-0.390
27.87,102.71,-0.390
27.88,102.56,-0.390
27.90,102.41,-0.390
27.91,102.26,-0.389
27.93,102.11,-0.389
27.94,101.96,-0.389
27.96,101.81,-0.389
27.97,101.66,-0.388
27.99,101.51,-0.388
28.00,101.36,-0.388
28.02,101.21,-0.388
28.03,101.06,-0.387
28.05,100.91,-0.387
28.06,100.76,-0.387
28.08,100.61,-0.387
28.09,100.46,-0.387
28.11,100.31,-0.386
28.12,100.16,-0.386
28.14,100.01,-0.386
28.15,99.86,-0.385
28.17,99.71,-0.385
28.18,99.56,-0.385
28.20,99.41,-0.385
28.21,99.26,-0.384
28.23,99.11,-0.384
28.24,98.96,-0.384
28.26,98.81,-0.384
28.27,98.66,-0.383
28.29,98.51,-0.383
28.30,98.36,-0.383
28.32,98.21,-0.382
28.33,98.06,-0.382
28.35,97.91,-0.382
28.36,97.76,-0.381
28.38,97.61,-0.381
28.39,97.46,-0.381
28.41,97.31,-0.380
28.42,97.16,-0.380
28.44,97.01,-0.380
28.45,96.86,-0.379
28.47,96.71,-0.379
28.48,96.56,-0.378
28.50,96.41,-0.378
28.51,96.26,-0.378
28.53,96.11,-0.377
28.54,95.96,-0.377
28.56,95.81,-0.377
28.57,95.66,-0.376
28.59,95.51,-0.376
28.60,95.36,-0.375
28.62,95.21,-0.375
28.63,95.06,-0.375
28.65,94.91,-0.374
28.66,94.76,-0.374
28.68,94.61,-0.374
28.69,94.46,-0.373
28.71,94.31,-0.373
28.72,94.16,-0.373
28.74,94.01,-0.372
28.75,93.86,-0.372
28.77,93.71,-0.372
28.78,93.56,-0.371
28.80,93.41,-0.371
28.81,93.26,-0.370
28.83,93.11,-0.370
28.84,92.96,-0.370
28.86,92.81,-0.369
28.87,92.66,-0.369
28.89,92.51,-0.368
28.90,92.36,-0.368
28.92,92.21,-0.368
28.93,92.06,-0.367
28.95,91.91,-0.367
28.96,91.76,-0.366
28.98,91.61,-0.366
28.99,91.46,-0.365
29.01,91.31,-0.365
29.02,91.16,-0.365
29.04,91.01,-0.364
29.05,90.86,-0.364
29.07,90.71,-0.363
29.08,90.56,-0.363
29.10,90.41,-0.363
29.11,90.26,-0.362
29.13,90.11,-0.362
29.14,89.96,-0.362
29.16,89.81,-0.361
29.17,89.66,-0.361
29.19,89.51,-0.360
29.20,89.36,-0.360
29.22,89.21,-0.360
29.23,89.06,-0.359
29.25,88.91,-0.358
29.26,88.76,-0.358
29.28,88.61,-0.358
29.29,88.46,-0.357
29.31,88.31,-0.357
29.32,88.16,-0.357
29.34,88.01,-0.356
29.35,87.86,-0.356
29.37,87.71,-0.356
29.38,87.56,-0.355
29.40,87.41,-0.354
29.41,87.26,-0.354
29.43,87.11,-0.354
29.44,86.96,-0.353
29.46,86.81,-0.353
29.47,86.66,-0.353
[...]
97.26,-8.67,0.198
97.27,-8.52,0.198
97.29,-8.37,0.198
97.30,-8.22,0.198
97.32,-8.07,0.198
97.33,-7.92,0.198
97.35,-7.77,0.198
97.36,-7.62,0.198
97.38,-7.47,0.199
97.39,-7.32,0.199
97.41,-7.17,0.199
97.42,-7.02,0.199
97.44,-6.87,0.199
97.45,-6.72,0.199
97.47,-6.57,0.199
97.48,-6.42,0.199
97.50,-6.27,0.199
97.51,-6.11,0.199
97.53,-5.96,0.199
97.54,-5.81,0.199
97.56,-5.66,0.199
97.57,-5.52,0.199
97.59,-5.36,0.199
97.60,-5.21,0.200
97.62,-5.06,0.200
97.63,-4.91,0.200
97.65,-4.76,0.200
97.66,-4.61,0.200
97.68,-4.46,0.200
97.69,-4.31,0.200
97.71,-4.16,0.200
97.72,-4.01,0.200
97.74,-3.86,0.200
97.75,-3.71,0.200
97.77,-3.56,0.200
97.78,-3.41,0.200
97.80,-3.26,0.200
97.81,-3.11,0.200
97.83,-2.96,0.200
97.84,-2.81,0.201
97.86,-2.66,0.201
97.87,-2.51,0.201
97.89,-2.36,0.201
97.90,-2.21,0.201
97.92,-2.06,0.201
97.93,-1.91,0.201
97.95,-1.76,0.201
97.96,-1.61,0.201
97.98,-1.46,0.201
97.99,-1.31,0.201
98.01,-1.16,0.201
98.02,-1.01,0.201
98.04,-0.86,0.201
98.05,-0.71,0.201
98.07,-0.56,0.201
98.08,-0.41,0.201
98.10,-0.26,0.202
98.11,-0.11,0.202
98.13,0.04,0.202
98.14,0.19,0.202
98.16,0.34,0.202
98.17,0.49,0.202
98.19,0.64,0.202
98.20,0.79,0.202
98.22,0.94,0.202
98.23,1.09,0.202
98.25,1.24,0.202
98.26,1.39,0.202
98.28,1.54,0.202
98.29,1.69,0.202
98.31,1.85,0.203
98.32,1.99,0.203
98.34,2.14,0.203
98.35,2.29,0.203
98.37,2.45,0.203
98.38,2.60,0.203
98.40,2.75,0.203
98.41,2.90,0.203
98.43,3.05,0.203
98.44,3.19,0.203
98.46,3.35,0.203
98.47,3.50,0.203
98.49,3.65,0.203
98.50,3.80,0.204
98.52,3.95,0.204
98.53,4.10,0.204
98.55,4.25,0.204
98.56,4.40,0.204
98.58,4.55,0.204
98.59,4.70,0.204
98.61,4.85,0.204
98.62,5.00,0.204
98.64,5.16,0.205
98.65,5.31,0.205
98.67,5.46,0.205
98.68,5.61,0.205
98.70,5.76,0.205
98.71,5.91,0.205
98.73,6.06,0.205
98.74,6.21,0.205
98.76,6.36,0.205
98.77,6.51,0.205
98.79,6.66,0.205
98.80,6.81,0.205
98.82,6.96,0.206
98.83,7.11,0.206
98.85,7.26,0.206
98.86,7.41,0.206
98.88,7.56,0.206
98.89,7.71,0.206
98.91,7.86,0.206
98.92,8.01,0.206
98.94,8.16,0.206
98.95,8.31,0.206
98.97,8.46,0.206
98.98,8.61,0.206
99.00,8.76,0.206
99.01,8.91,0.206
99.03,9.06,0.206
99.04,9.21,0.206
99.06,9.36,0.206
99.07,9.51,0.206
99.09,9.66,0.206
99.10,9.81,0.206
99.12,9.96,0.207
99.13,10.11,0.207
99.15,10.26,0.207
99.16,10.41,0.207
99.18,10.56,0.207
99.19,10.71,0.207
99.21,10.86,0.207
99.22,11.01,0.207
99.24,11.16,0.207
99.25,11.31,0.207
99.27,11.46,0.207
99.28,11.61,0.207
99.30,11.76,0.207
99.31,11.91,0.207
99.33,12.06,0.208
99.34,12.21,0.208
99.36,12.36,0.208
99.37,12.51,0.208
99.39,12.66,0.208
99.40,12.81,0.208
99.42,12.96,0.208
99.43,13.11,0.208
99.45,13.26,0.208
99.46,13.41,0.208
99.48,13.56,0.208
99.49,13.71,0.208
99.51,13.86,0.209
99.52,14.01,0.209
99.54,14.16,0.209
99.55,14.31,0.209
99.57,14.46,0.209
99.58,14.61,0.209
99.60,14.76,0.209
99.61,14.91,0.209
99.63,15.06,0.209
99.64,15.21,0.209
99.66,15.36,0.209
99.67,15.51,0.209
99.69,15.66,0.210
99.70,15.81,0.210
99.72,15.96,0.210
99.73,16.11,0.210
99.75,16.26,0.210
99.76,16.41,0.210
99.78,16.56,0.210
99.79,16.71,0.210
99.81,16.86,0.210
99.82,17.01,0.210
99.84,17.16,0.210
99.85,17.31,0.211
99.87,17.46,0.211
99.88,17.61,0.211
99.90,17.76,0.211
99.91,17.91,0.211
99.93,18.06,0.211
99.94,18.21,0.211
99.96,18.36,0.211
99.97,18.51,0.211
99.99,18.66,0.211
100.00,18.81,0.211
100.02,18.96,0.212
100.03,19.11,0.212
100.05,19.26,0.212
100.06,19.41,0.212
100.08,19.56,0.212
100.09,19.71,0.212
100.11,19.86,0.212
100.12,20.01,0.212
100.14,20.16,0.212
100.15,20.31,0.212
100.17,20.46,0.212
100.18,20.61,0.212
100.20,20.76,0.213
100.21,20.91,0.213
100.23,21.06,0.213
100.24,21.21,0.213
100.26,21.36,0.213
100.27,21.51,0.213
100.29,21.66,0.213
100.30,21.81,0.213
100.32,21.96,0.213
100.33,22.11,0.213
100.35,22.26,0.213
100.36,22.41,0.213
100.38,22.56,0.214
100.39,22.71,0.214
100.41,22.86,0.214
100.42,23.01,0.214
100.44,23.16,0.214
100.45,23.32,0.214
100.47,23.47,0.214
100.48,23.61,0.214
100.50,23.77,0.214
100.51,23.91,0.214
100.53,24.07,0.215
100.54,24.22,0.215
100.56,24.37,0.215
100.57,24.52,0.215
100.59,24.67,0.215
100.60,24.82,0.215
100.62,24.97,0.215
100.63,25.12,0.215
100.65,25.27,0.215
100.66,25.42,0.215
100.68,25.57,0.216
100.69,25.72,0.216
100.71,25.87,0.216
100.72,26.02,0.216
100.74,26.17,0.216
100.75,26.32,0.216
100.77,26.47,0.216
100.78,26.62,0.216
100.80,26.77,0.216
100.81,26.92,0.216
100.83,27.07,0.216
100.84,27.22,0.217
100.86,27.37,0.217
100.87,27.52,0.217
100.89,27.67,0.217
100.90,27.82,0.217
100.92,27.97,0.217
100.93,28.12,0.217
100.95,28.27,0.217
100.96,28.42,0.217
100.98,28.57,0.217
100.99,28.72,0.217
101.01,28.87,0.218
101.02,29.02,0.218
101.04,29.17,0.218
101.05,29.32,0.218
101.07,29.47,0.218
101.08,29.62,0.218
101.10,29.77,0.218
101.11,29.92,0.218
101.13,30.07,0.218
101.14,30.22,0.218
101.16,30.37,0.219
101.17,30.52,0.219
101.19,30.67,0.219
101.20,30.82,0.219
101.22,30.97,0.219
101.23,31.12,0.219
101.25,31.27,0.219
101.26,31.42,0.219
101.28,31.57,0.219
101.29,31.72,0.219
101.31,31.87,0.220
101.32,32.02,0.220
101.34,32.17,0.220
101.35,32.32,0.220
101.37,32.47,0.220
101.38,32.63,0.220
101.40,32.77,0.220
101.41,32.92,0.220
101.43,33.07,0.220
101.44,33.23,0.220
101.46,33.37,0.220
101.47,33.52,0.221
101.49,33.68,0.221
101.50,33.82,0.221
101.52,33.98,0.221
101.53,34.13,0.221
101.55,34.28,0.221
101.56,34.43,0.221
101.58,34.58,0.221
101.59,34.73,0.221
101.61,34.88,0.221
101.62,35.03,0.222
101.64,35.18,0.222
101.65,35.33,0.222
101.67,35.48,0.222
101.68,35.63,0.222
101.70,35.78,0.222
101.71,35.93,0.222
101.73,36.08,0.222
101.74,36.23,0.222
101.76,36.38,0.222
101.77,36.53,0.222
101.79,36.68,0.223
101.80,36.83,0.223
101.82,36.98,0.223
101.83,37.13,0.223
101.85,37.28,0.223
101.86,37.43,0.223
101.88,37.58,0.223
101.89,37.73,0.223
101.91,37.88,0.223
101.92,38.03,0.223
101.94,38.18,0.224
101.95,38.33,0.224
101.97,38.48,0.224
101.98,38.63,0.224
102.00,38.78,0.224
102.01,38.93,0.224
102.03,39.08,0.224
102.04,39.23,0.224
102.06,39.38,0.224
102.07,39.53,0.224
102.09,39.68,0.224
102.10,39.83,0.225
102.12,39.98,0.225
102.13,40.13,0.225
102.15,40.28,0.225
102.16,40.43,0.225
102.18,40.58,0.225
102.19,40.73,0.225
102.21,40.88,0.225
102.22,41.03,0.225
102.24,41.18,0.225
102.25,41.33,0.225
102.27,41.48,0.226
102.28,41.63,0.226
102.30,41.78,0.226
102.31,41.93,0.226
102.33,42.08,0.226
102.34,42.23,0.226
102.36,42.38,0.226
102.37,42.53,0.226
102.39,42.69,0.226
102.40,42.83,0.226
102.42,42.99,0.227
102.43,43.14,0.227
102.45,43.29,0.227
102.46,43.44,0.227
102.48,43.58,0.227
102.49,43.74,0.227
102.51,43.89,0.227
102.52,44.04,0.227
102.54,44.19,0.227
102.55,44.34,0.227
102.57,44.49,0.227
102.58,44.64,0.228
102.60,44.79,0.228
102.61,44.94,0.228
102.63,45.09,0.228
102.64,45.24,0.228
102.66,45.39,0.228
102.67,45.54,0.228
102.69,45.69,0.228
102.70,45.84,0.228
102.72,45.99,0.228
102.73,46.14,0.229
102.75,46.29,0.229
102.76,46.44,0.229
102.78,46.59,0.229
102.79,46.74,0.229
102.81,46.89,0.229
102.82,47.04,0.229
102.84,47.19,0.229
102.85,47.34,0.229
102.87,47.49,0.229
102.88,47.64,0.229
102.90,47.79,0.230
102.91,47.94,0.230
102.93,48.09,0.230
102.94,48.24,0.230
102.96,48.39,0.230
102.97,48.54,0.230
102.99,48.69,0.230
103.00,48.84,0.230
103.02,48.99,0.230
103.03,49.14,0.230
103.05,49.29,0.230
103.06,49.44,0.231
103.08,49.59,0.231
103.09,49.74,0.231
103.11,49.89,0.231
103.12,50.04,0.231
103.14,50.19,0.231
103.15,50.34,0.231
103.17,50.49,0.231
103.18,50.64,0.231
103.20,50.79,0.231
103.21,50.94,0.232
103.23,51.09,0.232
103.24,51.24,0.232
103.26,51.39,0.232
103.27,51.54,0.232
103.29,51.69,0.232
103.30,51.84,0.232
103.32,51.99,0.232
103.33,52.14,0.232
103.35,52.29,0.232
103.36,52.44,0.233
103.38,52.59,0.233
103.39,52.74,0.233
103.41,52.89,0.233
103.42,53.05,0.233
103.44,53.19,0.233
103.45,53.35,0.233
103.47,53.50,0.233
103.48,53.65,0.233
103.50,53.80,0.234
103.51,53.95,0.234
103.53,54.10,0.234
103.54,54.25,0.234
103.56,54.40,0.234
103.57,54.55,0.234
103.59,54.70,0.234
103.60,54.85,0.234
103.62,55.00,0.234
103.63,55.15,0.234
103.65,55.30,0.235
103.66,55.45,0.235
103.68,55.60,0.235
103.69,55.75,0.235
103.71,55.90,0.235
103.72,56.05,0.235
103.74,56.20,0.235
103.75,56.35,0.235
103.77,56.50,0.235
103.78,56.65,0.235
103.80,56.80,0.236
103.81,56.95,0.236
103.83,57.10,0.236
103.84,57.25,0.236
103.86,57.40,0.236
103.87,57.55,0.236
103.89,57.70,0.236
103.90,57.85,0.236
103.92,58.00,0.236
103.93,58.15,0.236
103.95,58.30,0.237
103.96,58.45,0.237
103.98,58.60,0.237
103.99,58.75,0.237
104.01,58.90,0.237
104.02,59.05,0.237
104.04,59.20,0.237
104.05,59.35,0.237
104.07,59.50,0.237
104.08,59.65,0.238
104.10,59.80,0.238
104.11,59.95,0.238
104.13,60.10,0.238
104.14,60.25,0.238
104.16,60.40,0.238
104.17,60.55,0.238
104.19,60.70,0.238
104.20,60.85,0.238
104.22,61.00,0.238
104.23,61.15,0.239
104.25,61.30,0.239
104.26,61.45,0.239
104.28,61.60,0.239
104.29,61.75,0.239
104.31,61.90,0.239
104.32,62.05,0.239
104.34,62.20,0.239
104.35,62.35,0.240
104.37,62.50,0.240
104.38,62.65,0.240
104.40,62.80,0.240
104.41,62.95,0.240
104.43,63.10,0.240
104.44,63.25,0.240
104.46,63.40,0.240
104.47,63.55,0.240
104.49,63.70,0.240
104.50,63.85,0.241
104.52,64.00,0.241
104.53,64.15,0.241
104.55,64.30,0.241
104.56,64.45,0.241
104.58,64.60,0.241
104.59,64.76,0.241
104.61,64.90,0.241
104.62,65.06,0.241
104.64,65.20,0.242
104.65,65.35,0.242
104.67,65.51,0.242
104.68,65.66,0.242
104.70,65.81,0.242
104.71,65.95,0.242
104.73,66.11,0.242
104.74,66.26,0.242
104.76,66.41,0.242
104.77,66.56,0.243
104.79,66.71,0.243
104.80,66.86,0.243
104.82,67.01,0.243
104.83,67.16,0.243
104.85,67.31,0.243
104.86,67.46,0.243
104.88,67.61,0.243
104.89,67.76,0.243
104.91,67.91,0.244
104.92,68.06,0.244
104.94,68.21,0.244
104.95,68.36,0.244
104.97,68.51,0.244
104.98,68.66,0.244
105.00,68.81,0.244
105.01,68.96,0.244
105.03,69.11,0.245
105.04,69.26,0.245
105.06,69.41,0.245
105.07,69.56,0.245
105.09,69.71,0.245
105.10,69.86,0.245
105.12,70.01,0.245
105.13,70.16,0.245
105.15,70.31,0.245
105.16,70.46,0.246
105.18,70.61,0.246
105.19,70.76,0.246
105.21,70.91,0.246
105.22,71.06,0.246
105.24,71.21,0.246
105.25,71.36,0.246
105.27,71.51,0.247
105.28,71.66,0.247
105.30,71.81,0.247
105.31,71.96,0.247
105.33,72.11,0.247
105.34,72.26,0.247
105.36,72.41,0.247
105.37,72.56,0.247
105.39,72.71,0.248
105.40,72.86,0.248
105.42,73.01,0.248
105.43,73.16,0.248
105.45,73.31,0.248
105.46,73.46,0.248
105.48,73.61,0.248
105.49,73.76,0.249
105.51,73.91,0.249
105.52,74.06,0.249
105.54,74.21,0.249
105.55,74.36,0.249
105.57,74.51,0.249
105.58,74.66,0.249
105.60,74.81,0.249
105.61,74.96,0.250
105.63,75.11,0.250
105.64,75.26,0.250
105.66,75.41,0.250
105.67,75.56,0.250
105.69,75.72,0.250
105.70,75.86,0.250
105.72,76.01,0.251
105.73,76.17,0.251
105.75,76.32,0.251
105.76,76.46,0.251
105.78,76.61,0.251
105.79,76.76,0.251
105.81,76.91,0.251
105.82,77.07,0.252
105.84,77.21,0.252
105.85,77.37,0.252
105.87,77.52,0.252
105.88,77.66,0.252
105.90,77.81,0.252
105.91,77.96,0.252
105.93,78.11,0.252
105.94,78.27,0.253
105.96,78.42,0.253
105.97,78.56,0.253
105.99,78.72,0.253
106.00,78.87,0.253
106.02,79.02,0.253
106.03,79.17,0.254
106.05,79.32,0.254
106.06,79.47,0.254
106.08,79.62,0.254
106.09,79.77,0.254
106.11,79.92,0.254
106.12,80.07,0.255
106.14,80.22,0.255
106.15,80.37,0.255
106.17,80.52,0.255
106.18,80.67,0.255
106.20,80.82,0.255
106.21,80.97,0.255
106.23,81.12,0.256
106.24,81.27,0.256
106.26,81.42,0.256
106.27,81.57,0.256
106.29,81.72,0.256
106.30,81.87,0.256
106.32,82.02,0.257
106.33,82.17,0.257
106.35,82.32,0.257
106.36,82.47,0.257
106.38,82.62,0.257
106.39,82.77,0.257
106.41,82.92,0.258
106.42,83.07,0.258
106.44,83.22,0.258
106.45,83.37,0.258
106.47,83.52,0.258
106.48,83.67,0.259
106.50,83.82,0.259
106.51,83.97,0.259
106.53,84.12,0.259
106.54,84.27,0.259
106.56,84.42,0.259
106.57,84.57,0.260
106.59,84.72,0.260
106.60,84.87,0.260
106.62,85.02,0.260
106.63,85.17,0.260
106.65,85.32,0.260
106.66,85.47,0.261
106.68,85.62,0.261
106.69,85.77,0.261
106.71,85.92,0.261
106.72,86.07,0.262
106.74,86.22,0.262
106.75,86.37,0.262
106.77,86.52,0.262
106.78,86.67,0.262
106.80,86.82,0.263
106.81,86.97,0.263
106.83,87.12,0.263
106.84,87.27,0.263
106.86,87.42,0.263
106.87,87.57,0.264
106.89,87.72,0.264
106.90,87.87,0.264
106.92,88.02,0.264
106.93,88.17,0.265
106.95,88.32,0.265
106.96,88.47,0.265
106.98,88.62,0.265
106.99,88.77,0.266
107.01,88.92,0.266
107.02,89.07,0.266
107.04,89.22,0.266
107.05,89.37,0.267
107.07,89.52,0.267
107.08,89.67,0.267
107.10,89.82,0.268
107.11,89.97,0.268
107.13,90.12,0.268
107.14,90.27,0.269
107.16,90.42,0.269
107.17,90.57,0.269
107.19,90.72,0.269
107.20,90.87,0.270
107.22,91.02,0.270
107.23,91.17,0.270
107.25,91.32,0.271
107.26,91.47,0.271
107.28,91.62,0.271
107.29,91.77,0.272
107.31,91.92,0.272
107.32,92.07,0.273
107.34,92.22,0.273
107.35,92.38,0.273
107.37,92.52,0.274
107.38,92.67,0.274
107.40,92.83,0.274
107.41,92.97,0.275
107.43,93.12,0.275
107.44,93.27,0.275
107.46,93.42,0.276
107.47,93.57,0.276
107.49,93.72,0.277
107.50,93.87,0.277
107.52,94.03,0.277
107.53,94.17,0.278
107.55,94.32,0.278
107.56,94.47,0.279
107.58,94.62,0.279
107.59,94.77,0.279
107.61,94.92,0.280
107.62,95.07,0.280
107.64,95.22,0.281
107.65,95.37,0.281
107.67,95.52,0.282
107.68,95.68,0.282
107.70,95.83,0.283
107.71,95.98,0.284
107.73,96.13,0.285
107.74,96.28,0.286
107.76,96.43,0.287
107.77,96.59,0.288
107.79,96.74,0.289
107.80,96.89,0.289
107.82,97.04,0.290
107.83,97.19,0.290
107.85,97.34,0.290
107.86,97.48,0.291
107.88,97.64,0.291
107.89,97.78,0.291
107.91,97.93,0.292
107.92,98.08,0.292
107.94,98.23,0.293
107.95,98.38,0.293
107.97,98.53,0.293
107.98,98.68,0.294
108.00,98.83,0.294
108.01,98.98,0.295
108.03,99.13,0.295
108.04,99.28,0.296
108.06,99.43,0.296
108.07,99.58,0.297
108.09,99.73,0.298
108.10,99.88,0.298
108.12,100.03,0.299
108.13,100.18,0.300
108.15,100.33,0.300
108.16,100.48,0.301
108.18,100.63,0.301
108.19,100.78,0.302
108.21,100.93,0.303
108.22,101.08,0.303
108.24,101.23,0.304
108.25,101.38,0.304
108.27,101.53,0.305
108.28,101.68,0.306
108.30,101.83,0.306
108.31,101.98,0.307
108.33,102.13,0.307
108.34,102.28,0.308
108.36,102.43,0.308
108.37,102.58,0.309
108.39,102.73,0.310
108.40,102.88,0.310
108.42,103.03,0.311
108.43,103.18,0.311
108.45,103.33,0.312
108.46,103.48,0.312
108.48,103.63,0.313
108.49,103.77,0.313
108.51,103.93,0.314
108.52,104.08,0.314
108.54,104.23,0.315
108.55,104.38,0.315
108.57,104.53,0.316
108.58,104.68,0.316
108.60,104.83,0.316
108.61,104.98,0.317
108.63,105.13,0.317
108.64,105.28,0.318
108.66,105.43,0.318
108.67,105.58,0.319
108.69,105.73,0.319
108.70,105.88,0.319
108.72,106.03,0.320
108.73,106.18,0.320
108.75,106.33,0.320
108.76,106.48,0.321
108.78,106.63,0.321
108.79,106.78,0.321
108.81,106.93,0.322
108.82,107.08,0.322
108.84,107.23,0.322
108.85,107.38,0.322
108.87,107.53,0.323
108.88,107.68,0.323
108.90,107.83,0.323
108.91,107.98,0.323
108.93,108.13,0.323
108.94,108.28,0.324
108.96,108.43,0.324
108.97,108.58,0.324
108.99,108.73,0.324
109.00,108.88,0.324
109.02,109.03,0.324
109.03,109.18,0.324
109.05,109.33,0.324
109.06,109.48,0.325
109.08,109.63,0.325
109.09,109.78,0.325
109.11,109.93,0.325
109.12,110.08,0.325
109.14,110.23,0.325
109.15,110.38,0.325
109.17,110.53,0.325
109.18,110.68,0.325
109.20,110.83,0.325
109.21,110.98,0.325
109.23,111.13,0.325
109.24,111.28,0.325
109.26,111.43,0.325
109.27,111.58,0.325
109.29,111.73,0.325
109.30,111.88,0.325
109.32,112.03,0.325
109.33,112.18,0.325
109.35,112.33,0.325
109.36,112.48,0.325
109.38,112.63,0.325
109.39,112.78,0.325
109.41,112.93,0.325
109.42,113.08,0.325
109.44,113.23,0.325
109.45,113.38,0.325
109.47,113.53,0.325
109.48,113.68,0.325
109.50,113.83,0.325
109.51,113.98,0.325
109.53,114.13,0.325
109.54,114.28,0.325
109.56,114.43,0.325
109.57,114.58,0.325
109.59,114.73,0.325
109.60,114.88,0.325
109.62,115.03,0.325
109.63,115.18,0.325
109.65,115.33,0.325
109.66,115.48,0.325
109.68,115.63,0.325
109.69,115.78,0.325
109.71,115.93,0.325
109.72,116.08,0.325
109.74,116.23,0.325
109.75,116.38,0.325
109.77,116.54,0.325
109.78,116.68,0.325
109.80,116.83,0.325
109.81,116.99,0.325
109.83,117.14,0.325
109.84,117.29,0.325
109.86,117.44,0.325
109.87,117.59,0.325
109.89,117.74,0.325
109.90,117.89,0.325
109.92,118.04,0.325
109.93,118.19,0.325
109.95,118.34,0.325
109.96,118.49,0.325
109.98,118.64,0.325
109.99,118.79,0.325
110.01,118.94,0.325
110.02,119.09,0.325
110.04,119.24,0.325
110.05,119.39,0.325
110.07,119.54,0.325
110.08,119.69,0.325
110.10,119.84,0.325
110.11,119.99,0.325
110.13,120.14,0.325
110.14,120.29,0.326
110.16,120.44,0.326
110.17,120.59,0.326
110.19,120.74,0.326
110.20,120.89,0.326
110.22,121.04,0.326
110.23,121.19,0.326
110.25,121.34,0.326
110.26,121.49,0.326
110.28,121.64,0.326
110.29,121.79,0.326
110.31,121.94,0.326
110.32,122.09,0.326
110.34,122.24,0.326
110.35,122.39,0.326
110.37,122.54,0.326
110.38,122.69,0.326
110.40,122.84,0.326
110.41,122.99,0.326
110.43,123.14,0.326
110.44,123.29,0.326
110.46,123.44,0.326
110.47,123.59,0.326
110.49,123.74,0.326
110.50,123.89,0.327
110.52,124.04,0.327
110.53,124.19,0.327
110.55,124.34,0.327
110.56,124.49,0.327
110.58,124.64,0.327
110.59,124.79,0.327
110.61,124.94,0.327
110.62,125.09,0.327
110.64,125.24,0.327
110.65,125.39,0.327
110.67,125.54,0.327
110.68,125.69,0.327
110.70,125.84,0.327
110.71,125.99,0.328
110.73,126.14,0.328
110.74,126.29,0.328
110.76,126.44,0.328
110.77,126.59,0.328
110.79,126.74,0.328
110.80,126.89,0.328
110.82,127.04,0.328
110.83,127.19,0.328
110.85,127.34,0.328
110.86,127.49,0.328
110.88,127.64,0.328
110.89,127.79,0.329
110.91,127.94,0.329
110.92,128.09,0.329
110.94,128.24,0.329
110.95,128.39,0.329
110.97,128.54,0.329
110.98,128.69,0.329
111.00,128.84,0.329
111.01,128.99,0.329
111.03,129.14,0.329
111.04,129.29,0.329
111.06,129.44,0.330
111.07,129.59,0.330
111.09,129.74,0.330
111.10,129.89,0.330
111.12,130.04,0.330
111.13,130.19,0.330
111.15,130.35,0.330
111.16,130.49,0.330
111.18,130.64,0.330
111.19,130.79,0.330
111.21,130.94,0.330
111.22,131.10,0.330
111.24,131.24,0.330
111.25,131.40,0.330
111.27,131.55,0.331
111.28,131.70,0.331
111.30,131.85,0.331
111.31,132.00,0.331
111.33,132.15,0.331
111.34,132.30,0.331
111.36,132.45,0.331
111.37,132.60,0.331
111.39,132.75,0.331
111.40,132.90,0.331
111.42,133.05,0.331
111.43,133.20,0.331
111.45,133.35,0.331
111.46,133.50,0.331
111.48,133.65,0.331
111.49,133.80,0.331
111.51,133.95,0.332
111.52,134.10,0.332
111.54,134.25,0.332
111.55,134.40,0.332
111.57,134.55,0.332
111.58,134.70,0.332
111.60,134.85,0.332
111.61,135.00,0.332
111.63,135.15,0.332
111.64,135.30,0.332
111.66,135.45,0.332
111.67,135.60,0.332
111.69,135.75,0.332
111.70,135.90,0.333
111.72,136.05,0.333
111.73,136.20,0.333
111.75,136.35,0.333
111.76,136.50,0.333
111.78,136.65,0.333
111.79,136.80,0.333
111.81,136.95,0.333
111.82,137.10,0.333
111.84,137.25,0.333
111.85,137.40,0.333
111.87,137.55,0.333
111.88,137.70,0.334
111.90,137.85,0.334
111.91,138.00,0.334
111.93,138.15,0.334
111.94,138.30,0.334
111.96,138.45,0.334
111.97,138.60,0.334
111.99,138.75,0.334
112.00,138.90,0.334
112.02,139.05,0.334
112.03,139.20,0.334
112.05,139.35,0.334
112.06,139.50,0.334
112.08,139.65,0.334
112.09,139.80,0.334
112.11,139.95,0.334
112.12,140.10,0.334
112.14,140.25,0.334
112.15,140.40,0.335
112.17,140.55,0.335
112.18,140.70,0.335
112.20,140.85,0.335
112.21,141.00,0.335
112.23,141.15,0.335
112.24,141.30,0.335
112.26,141.46,0.335
112.27,141.60,0.335
112.29,141.75,0.335
112.30,141.90,0.336
112.32,142.05,0.336
112.33,142.20,0.336
112.35,142.35,0.336
112.36,142.50,0.336
112.38,142.65,0.336
112.39,142.80,0.336
112.41,142.96,0.336
112.42,143.11,0.336
112.44,143.26,0.336
112.45,143.40,0.336
112.47,143.56,0.336
112.48,143.71,0.336
112.50,143.86,0.337
112.51,144.01,0.337
112.53,144.15,0.337
112.54,144.31,0.337
112.56,144.46,0.337
112.57,144.61,0.337
112.59,144.76,0.337
112.60,144.91,0.337
112.62,145.05,0.337
112.63,145.21,0.337
112.65,145.36,0.337
112.66,145.51,0.337
112.68,145.66,0.337
112.69,145.81,0.338
112.71,145.96,0.338
112.72,146.11,0.338
112.74,146.26,0.338
112.75,146.41,0.338
112.77,146.56,0.338
112.78,146.71,0.338
112.80,146.86,0.338
112.81,147.01,0.338
112.83,147.16,0.338
112.84,147.31,0.338
112.86,147.46,0.338
112.87,147.61,0.338
112.89,147.76,0.338
112.90,147.91,0.339
112.92,148.06,0.339
112.93,148.21,0.339
112.95,148.36,
112.96,148.51,
112.98,148.66,
112.99,,