File: DSC/Olivia/2025_08_02_1CBN_3PVP29_MeOH_n60C_150C_10Cmin_x3.csv
Filename,2025_08_02_1CBN_3PVP29_MeOH_n60C_150C_10Cmin_x3
Instrument name,DSC2A-00468 (192.168.1.100)
Operator,Yarger
rundate,8/2/2025
Sample name,2025_08_02_1CBN_3PVP29_MeOH_n60C_150C_10Cmin_x3
proceduresegments,Data Off ; Equilibrate -60.00 °C; Data On ; Ramp 10.00 °C/min to 150.00 °C; Data Off ; Isothermal 2.0 min; Data On ; Ramp 10.00 °C/min to -60.00 °C; Data Off ; Isothermal 2.0 min; Data On ; Ramp 10.00 °C/min to 150.00 °C; Data Off ; Isothermal 2.0 min; Data On ; Ramp 10.00 °C/min to -60.00 °C; Data Off ; Isothermal 2.0 min; Data On ; Ramp 10.00 °C/min to 150.00 °C
[File Parameters]
Run date,8/2/2025 4:11:03 PM
Trios version,5.1.1.46572
Original File Name,
Current File Name,D:\DSC2500\Gibbons\2025_08_02_1CBN_3PVP29_MeOH_n60C_150C_10Cmin_x3.tri
[Procedure]
Procedure Name,CBNPVP_n60C_150C_10Cmin_x3
Sample Name,2025_08_02_1CBN_3PVP29_MeOH_n60C_150C_10Cmin_x3
Sample Mass,5.36 mg
Reference Sample Mass,0 mg
Pan Mass,32.61 mg
Pan Number,48
Reference Pan Mass,32.73 mg
Reference Pan Number,46
Pan Type,Aluminum
Comments,Thermal support Al pans/lids. DSC_Samples_A2_Tray_July2025 google sheet.
Project Name,Pharma - Cocrystals
Operator,Yarger
Test,Custom
Unload Max Temperature,30
Unload Min Temperature,30
Load Max Temperature,30
Load Min Temperature,30
Stop on Gas Flow Error,Yes
[Signal List]
Signal #1,Time (min)
Signal #2,Temperature (°C)
Signal #3,Heat Flow (mW)
Signal #4,Delta T (µV)
Signal #5,Delta Tzero (µV)
Signal #6,Tzero Temperature (°C)
Signal #7,Cell Purge (mL/min)
Signal #8,Heater Temp (°C)
Signal #9,Power Delivered (W)
Signal #10,Reference Junction Temperature (°C)
Signal #11,Flange Temperature (°C)
Signal #12,Heat Flow Phase (rad)
Signal #13,Total Heat Capacity (J/°C)
Signal #14,Heat Capacity (J/°C)
[Configuration]
Company Name,ASU
Instrument Name,DSC2A-00468
Instrument Type,DSC2500
Serial Number,DSC2A-00468
IP,192.168.1.100
Location of Instrument,MRRC
DisplayType,Unknown
Sample Interval ,0.1 s/pt
Selected Heat Flow,T4P
Exotherm Direction,Down
Cell Serial,DRC2-00792
Lid Type,Standard
Cooler,RCS 90
Leave Cooler on at End of Sequence,On
Gas 2,Nitrogen
Gas Selected,Channel 1
Flow Rate,50 mL/min
Secondary Purge,On
Licensed Heat Flow,Heat Flow T4P
Modulation Licensed,Yes
[Versions]
Common IDD Version,1
Cortex Version,VER 2.10.2.31
Driver,5.0.0.6
GDM Version,1.0.3.3
TouchscreenVersion,1.0.0.16145
FEP Version,1.2.1.21
FEP Bootloader,2.0.0.5
AutoSampler Version,2.1.1.26
Auto Sampler Bootloader,2.0.0.5
FCM Version,1.1.0.3
FCM Bootloader,2.0.0.5
[Experiment Logs]
Experiment Log Entry # 1,Data On set to 0
Experiment Log Entry # 3,Equilibrate Segment -60 (C) Started
Experiment Log Entry # 5,Data On set to 1
Experiment Log Entry # 7,Ramp Segment 10 C/min to 150 Started
Experiment Log Entry # 9,Data On set to 0
Experiment Log Entry # 11,Isothermal Segment 2 min started
Experiment Log Entry # 13,Data On set to 1
Experiment Log Entry # 15,Ramp Segment 10 C/min to -60 Started
Experiment Log Entry # 17,Data On set to 0
Experiment Log Entry # 19,Isothermal Segment 2 min started
Experiment Log Entry # 21,Data On set to 1
Experiment Log Entry # 23,Ramp Segment 10 C/min to 150 Started
Experiment Log Entry # 25,Data On set to 0
Experiment Log Entry # 27,Isothermal Segment 2 min started
Experiment Log Entry # 29,Data On set to 1
Experiment Log Entry # 31,Ramp Segment 10 C/min to -60 Started
Experiment Log Entry # 33,Auto sampler has detected that GDM has gone offline
Experiment Log Entry # 35,Data On set to 0
Experiment Log Entry # 37,Isothermal Segment 2 min started
Experiment Log Entry # 39,Data On set to 1
Experiment Log Entry # 41,Ramp Segment 10 C/min to 150 Started
[Method Log]
Method Log Entry # 1,Data Off
Method Log Entry # 2,Equilibrate -60 °C
Method Log Entry # 3,Data On
Method Log Entry # 4,(Ramp 182856) Ramp 10 °C/minute to 150 °C
Method Log Entry # 5,Data Off
Method Log Entry # 6,Isothermal 2 minutes
Method Log Entry # 7,Data On
Method Log Entry # 8,(Ramp 182860) Ramp 10 °C/minute to -60 °C
Method Log Entry # 9,Data Off
Method Log Entry # 10,Isothermal 2 minutes
Method Log Entry # 11,Data On
Method Log Entry # 12,(Ramp 182864) Ramp 10 °C/minute to 150 °C
Method Log Entry # 13,Data Off
Method Log Entry # 14,Isothermal 2 minutes
Method Log Entry # 15,Data On
Method Log Entry # 16,(Ramp 182868) Ramp 10 °C/minute to -60 °C
Method Log Entry # 17,Data Off
Method Log Entry # 18,Isothermal 2 minutes
Method Log Entry # 19,Data On
Method Log Entry # 20,(Ramp 182872) Ramp 10 °C/minute to 150 °C
Cell Serial,DRC2-00792
[T1 Calibration]
Slope,-0.008529666
Offset,9.636258
Initial Temperature,98.23
GUID,f8bfdadc-4977-4fdf-ba6d-0ba9134940c3
[TZero Calibration]
Date Applied,11/29/2022 4:06:13 PM
Description,From -89.059 °C to 396.009 °C at 20.000°C/min
Gas Type,Nitrogen
Pan Type,None
Source Files 1,C:\Users\yargerlab\Desktop\DSC Data\General\TZero_calibration_11_29_22_2nd(2).tri
Source Files 2,C:\Users\yargerlab\Desktop\DSC Data\General\TZero_calibration_11_29_22_2nd(3).tri
Delta T Offset,13.05235
Delta T Slope,-0.007271007
Delta T0 Offset,-13.69128
Delta T0 Slope,0.06063341
[Temperature Calibration]
Date Applied,11/29/2022 7:12:28 PM
Description,From 106.590 °C to 186.590 °C at 10.000°C/min
Gas Type,Nitrogen
Pan Type,Tzero Aluminum Hermetic
Source Files 1,C:\Users\yargerlab\Desktop\DSC Data\General\Indium(6).tri
Measured 1,157.391
Known 1,156.598
[Cell Constant Calibration]
Date Applied,11/29/2022 7:12:29 PM
Description,From 106.590 °C to 186.590 °C at 10.000°C/min
Gas Type,Nitrogen
Pan Type,Tzero Aluminum Hermetic
Source Files 1,C:\Users\yargerlab\Desktop\DSC Data\General\Indium(6).tri
T4P KCell,1.006051
Onset Slope,63.26126 mW/°C
[Direct Cp Calibration]
Date Applied,11/30/2022 11:04:51 AM
Description,From -79.983 °C to 298.409 °C at 10.000°C/min
Gas Type,Nitrogen
Pan Type,Tzero Aluminum Hermetic
Source Files 1,C:\Users\yargerlab\Desktop\DSC Data\General\Sapphire_Heat_Capacity_11_30_22.tri
[Rev Cp Calibration]
Date Applied,11/30/2022 1:58:51 PM
Description,From -79.996 °C to 292.812 °C at 3.000°C/min
Gas Type,Nitrogen
Pan Type,Tzero Aluminum Hermetic
Source Files 1,C:\Users\yargerlab\Desktop\DSC Data\General\Sapphire_MDSC_Calibration_11_30_22.tri
[step]
Ramp 10.00 °C/min to 150.00 °C
Time,Temperature,Heat Flow (Normalized)
min,°C,W/g
0.00,-59.81,-0.043
0.01,-59.82,-0.041
0.03,-59.82,-0.039
0.05,-59.81,-0.035
0.06,-59.80,-0.033
0.08,-59.77,-0.028
0.09,-59.73,-0.022
0.11,-59.67,-0.010
0.12,-59.60,0.002
0.14,-59.51,0.018
0.15,-59.41,0.035
0.16,-59.30,0.053
0.18,-59.18,0.071
0.19,-59.06,0.088
0.21,-58.93,0.102
0.23,-58.79,0.115
0.24,-58.66,0.126
0.26,-58.52,0.137
0.27,-58.38,0.143
0.29,-58.24,0.151
0.30,-58.10,0.156
0.31,-57.95,0.160
0.33,-57.81,0.163
0.35,-57.66,0.167
0.36,-57.52,0.170
0.38,-57.37,0.171
0.39,-57.23,0.173
0.40,-57.08,0.174
0.42,-56.94,0.175
0.44,-56.79,0.176
0.45,-56.64,0.177
0.46,-56.50,0.178
0.48,-56.35,0.178
0.50,-56.20,0.179
0.51,-56.06,0.180
0.53,-55.91,0.180
0.54,-55.76,0.180
0.55,-55.62,0.181
0.57,-55.47,0.181
0.58,-55.32,0.181
0.60,-55.17,0.182
0.62,-55.02,0.182
0.63,-54.88,0.182
0.65,-54.73,0.183
0.66,-54.58,0.183
0.68,-54.43,0.183
0.69,-54.29,0.184
0.70,-54.14,0.184
0.72,-53.99,0.184
0.73,-53.84,0.184
0.75,-53.69,0.185
0.77,-53.54,0.185
0.78,-53.40,0.185
0.80,-53.25,0.186
0.81,-53.10,0.186
0.83,-52.95,0.186
0.84,-52.80,0.186
0.85,-52.65,0.187
0.87,-52.50,0.187
0.88,-52.35,0.187
0.90,-52.20,0.188
0.92,-52.06,0.188
0.93,-51.91,0.188
0.95,-51.76,0.188
0.96,-51.61,0.188
0.98,-51.46,0.189
0.99,-51.31,0.189
1.00,-51.16,0.189
1.02,-51.01,0.189
1.03,-50.86,0.190
1.05,-50.71,0.190
1.07,-50.57,0.190
1.08,-50.42,0.190
1.09,-50.27,0.190
1.11,-50.12,0.190
1.13,-49.97,0.191
1.14,-49.82,0.191
1.16,-49.67,0.191
1.17,-49.52,0.191
1.18,-49.37,0.191
1.20,-49.22,0.192
1.22,-49.07,0.192
1.23,-48.92,0.192
1.24,-48.77,0.192
1.26,-48.62,0.192
1.28,-48.47,0.192
1.29,-48.32,0.193
1.31,-48.17,0.193
1.32,-48.02,0.193
1.33,-47.87,0.193
1.35,-47.72,0.193
1.37,-47.57,0.193
1.38,-47.42,0.193
1.39,-47.27,0.194
1.41,-47.12,0.194
1.43,-46.97,0.194
1.44,-46.82,0.194
1.46,-46.67,0.194
1.47,-46.52,0.194
1.48,-46.37,0.194
1.50,-46.22,0.194
1.52,-46.07,0.194
1.53,-45.92,0.195
1.54,-45.77,0.195
1.56,-45.63,0.195
1.58,-45.47,0.195
1.59,-45.32,0.195
1.61,-45.17,0.195
1.62,-45.02,0.195
1.63,-44.87,0.195
1.65,-44.72,0.195
1.67,-44.57,0.195
1.68,-44.42,0.195
1.69,-44.27,0.196
1.71,-44.12,0.196
1.73,-43.97,0.196
1.74,-43.82,0.196
1.76,-43.67,0.196
1.77,-43.52,0.196
1.78,-43.37,0.196
1.80,-43.22,0.196
1.82,-43.07,0.196
1.83,-42.92,0.196
1.84,-42.77,0.196
1.86,-42.62,0.196
1.88,-42.47,0.196
1.89,-42.32,0.197
1.91,-42.17,0.197
1.92,-42.02,0.197
1.93,-41.87,0.197
1.95,-41.72,0.197
1.97,-41.57,0.197
1.98,-41.42,0.197
1.99,-41.27,0.197
2.01,-41.12,0.197
2.03,-40.97,0.197
2.04,-40.82,0.197
2.06,-40.67,0.197
2.07,-40.52,0.197
2.08,-40.37,0.198
2.10,-40.22,0.198
2.12,-40.07,0.198
2.13,-39.92,0.198
2.14,-39.77,0.198
2.16,-39.62,0.198
2.18,-39.47,0.198
2.19,-39.32,0.198
2.21,-39.17,0.198
2.22,-39.02,0.198
2.24,-38.87,0.198
2.25,-38.72,0.198
2.26,-38.57,0.198
2.28,-38.42,0.198
2.29,-38.27,0.198
2.31,-38.12,0.198
2.33,-37.97,0.199
2.34,-37.82,0.199
2.36,-37.67,0.199
2.37,-37.52,0.199
2.39,-37.37,0.199
2.40,-37.22,0.199
2.41,-37.07,0.199
2.43,-36.92,0.199
2.44,-36.77,0.199
2.46,-36.62,0.199
2.48,-36.47,0.199
2.49,-36.32,0.199
2.51,-36.16,0.199
2.52,-36.01,0.199
2.54,-35.86,0.199
2.55,-35.71,0.199
2.56,-35.56,0.199
2.58,-35.42,0.200
2.59,-35.27,0.200
2.61,-35.11,0.200
2.63,-34.96,0.200
2.64,-34.81,0.200
2.66,-34.66,0.200
2.67,-34.51,0.200
2.69,-34.36,0.200
2.70,-34.21,0.200
2.71,-34.06,0.200
2.73,-33.91,0.200
2.74,-33.76,0.200
2.76,-33.61,0.200
2.78,-33.46,0.200
2.79,-33.31,0.200
2.81,-33.16,0.200
2.82,-33.01,0.200
2.84,-32.86,0.201
2.85,-32.71,0.201
2.86,-32.56,0.201
2.88,-32.41,0.201
2.89,-32.26,0.201
2.91,-32.11,0.201
2.93,-31.96,0.201
2.94,-31.81,0.201
2.96,-31.66,0.201
2.97,-31.51,0.201
2.99,-31.36,0.201
3.00,-31.21,0.201
3.01,-31.06,0.201
3.03,-30.91,0.201
3.04,-30.76,0.201
3.06,-30.61,0.201
3.08,-30.46,0.201
3.09,-30.31,0.201
3.11,-30.16,0.201
3.12,-30.01,0.202
3.14,-29.86,0.202
3.15,-29.71,0.202
3.16,-29.56,0.202
3.18,-29.41,0.202
3.19,-29.26,0.202
3.21,-29.11,0.202
3.23,-28.96,0.202
3.24,-28.81,0.202
3.26,-28.66,0.202
3.27,-28.51,0.202
3.29,-28.36,0.202
3.30,-28.21,0.202
3.31,-28.05,0.202
3.33,-27.91,0.203
3.34,-27.75,0.203
3.36,-27.60,0.203
3.38,-27.45,0.203
3.39,-27.30,0.203
3.41,-27.15,0.203
3.42,-27.00,0.203
3.44,-26.85,0.203
3.45,-26.70,0.203
3.46,-26.55,0.203
3.48,-26.40,0.203
3.49,-26.25,0.203
3.51,-26.10,0.203
3.53,-25.95,0.203
3.54,-25.80,0.204
3.56,-25.65,0.204
3.57,-25.50,0.204
3.59,-25.35,0.204
3.60,-25.20,0.204
3.61,-25.05,0.204
3.63,-24.90,0.204
3.64,-24.75,0.204
3.66,-24.60,0.204
3.68,-24.45,0.204
3.69,-24.30,0.204
3.71,-24.15,0.204
3.72,-24.00,0.204
3.74,-23.85,0.205
3.75,-23.70,0.205
3.76,-23.55,0.205
3.78,-23.40,0.205
3.79,-23.25,0.205
3.81,-23.10,0.205
3.83,-22.95,0.205
3.84,-22.80,0.205
3.86,-22.65,0.205
3.87,-22.50,0.205
3.89,-22.35,0.205
3.90,-22.20,0.205
3.91,-22.05,0.205
3.93,-21.90,0.206
3.94,-21.75,0.206
3.96,-21.60,0.206
3.98,-21.45,0.206
3.99,-21.30,0.206
4.01,-21.15,0.206
4.02,-21.00,0.206
4.04,-20.85,0.206
4.05,-20.70,0.206
4.06,-20.55,0.206
4.08,-20.40,0.206
4.09,-20.24,0.206
4.11,-20.09,0.207
4.13,-19.94,0.207
4.14,-19.79,0.207
4.16,-19.64,0.207
4.17,-19.49,0.207
4.19,-19.34,0.207
4.20,-19.19,0.207
4.21,-19.04,0.207
4.23,-18.89,0.207
4.24,-18.74,0.207
4.26,-18.59,0.207
4.28,-18.44,0.207
4.29,-18.29,0.208
4.30,-18.14,0.208
4.32,-17.99,0.208
4.34,-17.84,0.208
4.35,-17.69,0.208
4.36,-17.54,0.208
4.38,-17.39,0.208
4.40,-17.24,0.208
4.41,-17.09,0.208
4.43,-16.94,0.208
4.44,-16.79,0.208
4.45,-16.64,0.208
4.47,-16.49,0.209
4.49,-16.34,0.209
4.50,-16.19,0.209
4.51,-16.04,0.209
4.53,-15.89,0.209
4.55,-15.74,0.209
4.56,-15.59,0.209
4.58,-15.44,0.209
4.59,-15.29,0.209
4.60,-15.14,0.209
4.62,-14.99,0.209
4.64,-14.84,0.210
4.65,-14.69,0.210
4.66,-14.54,0.210
4.68,-14.39,0.210
4.70,-14.24,0.210
4.71,-14.09,0.210
4.73,-13.94,0.210
4.74,-13.79,0.210
4.75,-13.64,0.210
4.77,-13.49,0.210
4.79,-13.34,0.211
4.80,-13.19,0.211
4.81,-13.04,0.211
4.83,-12.89,0.211
4.85,-12.74,0.211
4.86,-12.59,0.211
4.88,-12.44,0.211
4.89,-12.29,0.211
4.90,-12.14,0.211
4.92,-11.99,0.211
4.94,-11.84,0.211
4.95,-11.69,0.212
4.96,-11.54,0.212
4.98,-11.39,0.212
5.00,-11.24,0.212
5.01,-11.09,0.212
5.03,-10.93,0.212
5.04,-10.79,0.212
5.05,-10.64,0.212
5.07,-10.49,0.212
5.09,-10.34,0.212
5.10,-10.19,0.212
5.11,-10.04,0.213
5.13,-9.89,0.213
5.15,-9.74,0.213
5.16,-9.59,0.213
5.18,-9.44,0.213
5.19,-9.29,0.213
5.20,-9.14,0.213
5.22,-8.99,0.213
5.24,-8.84,0.213
5.25,-8.69,0.214
5.26,-8.54,0.214
5.28,-8.38,0.214
5.30,-8.24,0.214
5.31,-8.09,0.214
5.33,-7.94,0.214
5.34,-7.79,0.214
5.35,-7.64,0.214
5.37,-7.48,0.215
5.39,-7.33,0.215
5.40,-7.18,0.215
5.41,-7.03,0.215
5.43,-6.88,0.215
5.45,-6.73,0.215
5.46,-6.58,0.215
5.48,-6.43,0.215
5.49,-6.28,0.215
5.50,-6.13,0.216
5.52,-5.98,0.216
5.54,-5.83,0.216
5.55,-5.68,0.216
5.56,-5.53,0.216
5.58,-5.38,0.216
5.60,-5.23,0.216
5.61,-5.08,0.216
5.63,-4.93,0.217
5.64,-4.78,0.217
5.65,-4.63,0.217
5.67,-4.48,0.217
5.69,-4.33,0.217
5.70,-4.18,0.217
5.71,-4.03,0.217
5.73,-3.88,0.217
5.75,-3.73,0.218
5.76,-3.58,0.218
5.78,-3.43,0.218
5.79,-3.28,0.218
5.80,-3.13,0.218
5.82,-2.98,0.218
5.84,-2.83,0.218
5.85,-2.68,0.218
5.86,-2.53,0.218
5.88,-2.38,0.218
5.90,-2.23,0.219
5.91,-2.08,0.219
5.93,-1.93,0.219
5.94,-1.78,0.219
5.95,-1.63,0.219
5.97,-1.48,0.219
5.99,-1.33,0.219
6.00,-1.18,0.219
6.01,-1.03,0.220
6.03,-0.88,0.220
6.05,-0.73,0.220
6.06,-0.58,0.220
6.08,-0.43,0.220
6.09,-0.28,0.220
6.10,-0.13,0.220
6.12,0.02,0.220
6.14,0.17,0.221
6.15,0.32,0.221
6.16,0.47,0.221
6.18,0.62,0.221
6.20,0.77,0.221
6.21,0.92,0.221
6.23,1.07,0.221
6.24,1.23,0.221
6.25,1.37,0.222
6.27,1.53,0.222
6.29,1.68,0.222
6.30,1.83,0.222
6.31,1.98,0.222
6.33,2.13,0.222
6.35,2.28,0.222
6.36,2.43,0.223
6.38,2.58,0.223
6.39,2.73,0.223
6.40,2.88,0.223
6.42,3.03,0.223
6.44,3.18,0.223
6.45,3.33,0.223
6.46,3.48,0.224
6.48,3.63,0.224
6.50,3.78,0.224
6.51,3.93,0.224
6.53,4.08,0.224
6.54,4.23,0.224
6.55,4.38,0.224
6.57,4.53,0.224
6.59,4.68,0.225
6.60,4.83,0.225
6.61,4.98,0.225
6.63,5.13,0.225
6.65,5.28,0.225
6.66,5.43,0.225
6.68,5.58,0.226
6.69,5.73,0.226
6.70,5.88,0.226
6.72,6.03,0.226
6.74,6.18,0.226
6.75,6.33,0.226
6.76,6.48,0.227
6.78,6.63,0.227
6.80,6.78,0.227
6.81,6.93,0.227
6.83,7.08,0.227
6.84,7.23,0.227
6.85,7.38,0.227
6.87,7.53,0.228
6.89,7.68,0.228
6.90,7.83,0.228
6.91,7.98,0.228
6.93,8.13,0.228
6.95,8.28,0.228
6.96,8.43,0.229
6.98,8.58,0.229
6.99,8.73,0.229
7.00,8.88,0.229
7.02,9.03,0.229
7.04,9.18,0.229
7.05,9.33,0.230
7.06,9.48,0.230
7.08,9.63,0.230
7.10,9.78,0.230
7.11,9.93,0.230
7.13,10.08,0.230
7.14,10.23,0.231
7.15,10.38,0.231
7.17,10.53,0.231
7.19,10.68,0.231
7.20,10.84,0.231
7.21,10.98,0.231
7.23,11.13,0.232
7.25,11.28,0.232
7.26,11.44,0.232
7.28,11.59,0.232
7.29,11.74,0.232
7.30,11.89,0.233
7.32,12.04,0.233
7.34,12.19,0.233
7.35,12.34,0.233
7.36,12.48,0.233
7.38,12.64,0.233
7.40,12.79,0.234
7.41,12.94,0.234
7.43,13.09,0.234
7.44,13.24,0.234
7.45,13.39,0.234
7.47,13.54,0.235
7.49,13.69,0.235
7.50,13.84,0.235
7.51,13.99,0.235
7.53,14.14,0.235
7.55,14.29,0.236
7.56,14.44,0.236
7.58,14.59,0.236
7.59,14.74,0.236
7.60,14.89,0.236
7.62,15.04,0.237
7.64,15.19,0.237
7.65,15.34,0.237
7.66,15.49,0.237
7.68,15.64,0.237
7.70,15.79,0.238
7.71,15.94,0.238
7.73,16.09,0.238
7.74,16.24,0.238
7.75,16.39,0.238
7.77,16.54,0.239
7.79,16.69,0.239
7.80,16.84,0.239
7.81,16.99,0.239
7.83,17.14,0.239
7.85,17.29,0.240
7.86,17.44,0.240
7.88,17.59,0.240
7.89,17.74,0.240
7.90,17.89,0.241
7.92,18.04,0.241
7.94,18.19,0.241
7.95,18.34,0.241
7.96,18.49,0.242
7.98,18.64,0.242
8.00,18.79,0.242
8.01,18.94,0.242
8.03,19.09,0.242
8.04,19.24,0.243
8.05,19.39,0.243
8.07,19.54,0.243
8.09,19.69,0.243
8.10,19.84,0.244
8.11,19.99,0.244
8.13,20.14,0.244
8.15,20.29,0.244
8.16,20.44,0.245
8.18,20.59,0.245
8.19,20.74,0.245
8.20,20.89,0.245
8.22,21.04,0.246
8.24,21.19,0.246
8.25,21.34,0.246
8.26,21.49,0.246
8.28,21.64,0.247
8.30,21.79,0.247
8.31,21.94,0.247
8.33,22.09,0.248
8.34,22.24,0.248
8.35,22.39,0.248
8.37,22.54,0.248
8.39,22.69,0.249
8.40,22.84,0.249
8.41,22.99,0.249
8.43,23.14,0.249
8.45,23.29,0.250
8.46,23.44,0.250
8.48,23.59,0.250
8.49,23.74,0.250
8.50,23.89,0.251
8.52,24.04,0.251
8.53,24.19,0.251
8.55,24.34,0.252
8.57,24.49,0.252
8.58,24.64,0.252
8.60,24.79,0.252
8.61,24.94,0.253
8.63,25.09,0.253
8.64,25.24,0.253
8.65,25.39,0.254
8.67,25.54,0.254
8.68,25.69,0.254
8.70,25.84,0.255
8.72,25.99,0.255
8.73,26.14,0.255
8.75,26.29,0.255
8.76,26.44,0.256
8.78,26.59,0.256
8.79,26.74,0.257
8.80,26.89,0.257
8.82,27.04,0.257
8.83,27.19,0.258
8.85,27.34,0.258
8.87,27.49,0.258
8.88,27.64,0.259
8.90,27.79,0.259
8.91,27.94,0.259
8.93,28.09,0.259
8.94,28.24,0.260
8.95,28.39,0.260
8.97,28.54,0.261
8.98,28.69,0.261
9.00,28.84,0.261
9.02,28.99,0.262
9.03,29.14,0.262
9.05,29.29,0.262
9.06,29.44,0.263
9.08,29.59,0.263
9.09,29.74,0.263
9.10,29.89,0.264
9.12,30.04,0.264
9.13,30.19,0.264
9.15,30.34,0.265
9.17,30.49,0.265
9.18,30.64,0.266
9.20,30.79,0.266
9.21,30.94,0.266
9.23,31.09,0.267
9.24,31.24,0.267
9.25,31.39,0.268
9.27,31.54,0.268
9.28,31.69,0.268
9.30,31.84,0.269
9.32,31.99,0.269
9.33,32.14,0.270
9.35,32.29,0.270
9.36,32.44,0.270
9.38,32.59,0.271
9.39,32.74,0.271
9.40,32.89,0.272
9.42,33.04,0.272
9.43,33.20,0.272
9.45,33.34,0.273
9.47,33.49,0.273
9.48,33.65,0.273
9.50,33.79,0.274
9.51,33.95,0.274
9.53,34.10,0.275
9.54,34.25,0.275
9.55,34.40,0.275
9.57,34.54,0.276
9.58,34.70,0.276
9.60,34.84,0.277
9.62,35.00,0.277
9.63,35.14,0.278
9.65,35.30,0.278
9.66,35.45,0.278
9.68,35.60,0.279
9.69,35.75,0.279
9.70,35.90,0.280
9.72,36.05,0.280
9.73,36.20,0.280
9.75,36.34,0.281
9.77,36.49,0.282
9.78,36.64,0.282
9.80,36.80,0.283
9.81,36.94,0.283
9.83,37.09,0.284
9.84,37.25,0.284
9.85,37.39,0.285
9.87,37.55,0.285
9.88,37.69,0.286
9.90,37.85,0.286
9.92,38.00,0.286
9.93,38.14,0.287
9.95,38.29,0.287
9.96,38.45,0.288
9.98,38.59,0.288
9.99,38.75,0.289
10.00,38.90,0.290
10.02,39.05,0.290
10.03,39.20,0.291
10.05,39.35,0.291
10.07,39.50,0.292
10.08,39.65,0.292
10.10,39.80,0.293
10.11,39.94,0.293
10.13,40.09,0.294
10.14,40.25,0.295
10.15,40.39,0.295
10.17,40.55,0.296
10.18,40.70,0.296
10.20,40.85,0.298
10.22,41.00,0.298
10.23,41.14,0.299
10.25,41.30,0.299
10.26,41.44,0.300
10.28,41.59,0.300
10.29,41.74,0.301
10.30,41.89,0.302
10.32,42.05,0.302
10.33,42.19,0.303
10.35,42.35,0.304
10.37,42.49,0.304
10.38,42.64,0.305
10.40,42.80,0.306
10.41,42.94,0.307
10.43,43.10,0.307
10.44,43.25,0.308
10.45,43.39,0.308
10.47,43.54,0.309
10.48,43.69,0.310
10.50,43.84,0.311
10.52,43.99,0.311
10.53,44.14,0.312
10.55,44.29,0.313
10.56,44.44,0.313
10.58,44.59,0.314
10.59,44.74,0.315
10.60,44.89,0.315
10.62,45.04,0.317
10.63,45.19,0.317
10.65,45.34,0.318
10.67,45.49,0.319
10.68,45.64,0.320
10.70,45.79,0.320
10.71,45.94,0.322
10.73,46.09,0.322
10.74,46.24,0.323
10.75,46.39,0.324
10.77,46.54,0.325
10.78,46.69,0.326
10.80,46.84,0.327
10.82,46.99,0.328
10.83,47.14,0.329
10.85,47.29,0.329
10.86,47.44,0.330
10.88,47.59,0.331
10.89,47.74,0.333
10.90,47.89,0.333
10.92,48.04,0.335
10.93,48.19,0.335
10.95,48.34,0.336
10.97,48.49,0.338
10.98,48.64,0.339
11.00,48.79,0.339
11.01,48.94,0.341
11.03,49.09,0.342
11.04,49.24,0.343
11.05,49.39,0.344
11.07,49.54,0.346
11.08,49.69,0.347
11.10,49.84,0.348
11.12,49.99,0.348
11.13,50.14,0.349
11.15,50.29,0.350
11.16,50.44,0.352
11.18,50.59,0.353
11.19,50.74,0.355
11.20,50.89,0.356
11.22,51.04,0.357
11.23,51.19,0.359
11.25,51.34,0.360
11.27,51.49,0.361
11.28,51.64,0.363
11.30,51.79,0.364
11.31,51.94,0.366
11.33,52.09,0.367
11.34,52.24,0.368
11.35,52.39,0.369
11.37,52.54,0.370
11.38,52.69,0.371
11.40,52.84,0.372
11.42,52.99,0.374
11.43,53.14,0.374
11.45,53.29,0.376
11.46,53.44,0.377
11.48,53.59,0.378
11.49,53.74,0.380
11.50,53.89,0.381
11.52,54.03,0.383
11.53,54.18,0.384
11.55,54.33,0.386
11.57,54.48,0.387
11.58,54.63,0.389
11.60,54.78,0.391
11.61,54.93,0.392
11.63,55.08,0.394
11.64,55.23,0.396
11.65,55.38,0.397
11.67,55.53,0.398
11.68,55.68,0.401
11.70,55.83,0.402
11.72,55.98,0.405
11.73,56.13,0.407
11.75,56.28,0.409
11.76,56.43,0.410
11.78,56.58,0.412
11.79,56.72,0.413
11.80,56.88,0.416
11.82,57.02,0.417
11.83,57.17,0.419
11.85,57.32,0.422
11.87,57.47,0.423
11.88,57.62,0.426
11.90,57.77,0.428
11.91,57.92,0.431
11.93,58.07,0.433
11.94,58.22,0.435
11.95,58.37,0.437
11.97,58.52,0.440
11.98,58.67,0.442
12.00,58.82,0.444
12.02,58.97,0.447
12.03,59.12,0.450
12.05,59.27,0.451
12.06,59.41,0.453
12.08,59.56,0.456
12.09,59.71,0.457
12.10,59.86,0.460
12.12,60.01,0.463
12.13,60.16,0.464
12.15,60.31,0.465
12.17,60.46,0.468
12.18,60.61,0.470
12.20,60.76,0.472
12.21,60.91,0.473
12.23,61.06,0.475
12.24,61.21,0.477
12.25,61.36,0.479
12.27,61.51,0.480
12.28,61.65,0.482
12.30,61.80,0.483
12.32,61.95,0.485
12.33,62.11,0.486
12.35,62.25,0.488
12.36,62.40,0.490
12.38,62.55,0.491
12.39,62.70,0.493
12.40,62.85,0.494
12.42,63.00,0.496
12.43,63.15,0.497
12.45,63.30,0.498
12.47,63.45,0.499
12.48,63.60,0.501
12.50,63.75,0.502
12.51,63.90,0.504
12.53,64.05,0.506
12.54,64.20,0.507
12.55,64.35,0.509
12.57,64.50,0.510
12.58,64.65,0.512
12.60,64.80,0.513
12.62,64.95,0.514
12.63,65.10,0.516
12.65,65.25,0.517
12.66,65.40,0.519
12.68,65.55,0.520
12.69,65.70,0.523
12.70,65.85,0.524
12.72,66.00,0.526
12.73,66.15,0.527
12.75,66.30,0.529
12.77,66.45,0.531
12.78,66.60,0.532
12.80,66.74,0.534
12.81,66.89,0.535
12.83,67.04,0.537
12.84,67.19,0.539
12.85,67.34,0.540
12.87,67.49,0.541
12.88,67.64,0.543
12.90,67.79,0.544
12.92,67.94,0.545
12.93,68.09,0.547
12.95,68.24,0.549
12.96,68.39,0.551
12.98,68.54,0.553
12.99,68.69,0.554
13.00,68.84,0.556
13.02,68.99,0.558
13.03,69.14,0.560
13.05,69.29,0.561
13.07,69.44,0.562
13.08,69.59,0.564
13.10,69.74,0.565
13.11,69.89,0.567
13.13,70.03,0.568
13.14,70.19,0.570
13.15,70.34,0.571
13.17,70.48,0.573
13.18,70.63,0.574
13.20,70.78,0.575
13.22,70.93,0.576
13.23,71.08,0.578
13.25,71.23,0.579
13.26,71.38,0.581
13.28,71.53,0.582
13.29,71.68,0.584
13.30,71.83,0.585
13.32,71.98,0.587
13.33,72.13,0.588
13.35,72.28,0.589
13.37,72.43,0.590
13.38,72.58,0.591
13.40,72.73,0.593
13.41,72.88,0.594
13.43,73.03,0.595
13.44,73.18,0.596
13.45,73.33,0.597
13.47,73.48,0.598
13.48,73.63,0.600
13.50,73.78,0.601
13.52,73.93,0.602
13.53,74.08,0.603
13.55,74.23,0.605
13.56,74.38,0.606
13.58,74.53,0.607
13.59,74.68,0.608
13.60,74.83,0.610
13.62,74.98,0.611
13.63,75.13,0.611
13.65,75.28,0.612
13.67,75.43,0.613
13.68,75.58,0.614
13.70,75.73,0.615
13.71,75.88,0.616
13.73,76.02,0.617
13.74,76.18,0.618
13.75,76.32,0.619
13.77,76.47,0.620
13.78,76.62,0.621
13.80,76.77,0.622
13.82,76.92,0.623
13.83,77.07,0.624
13.85,77.22,0.625
13.86,77.37,0.626
13.88,77.52,0.627
13.89,77.67,0.628
13.90,77.82,0.629
13.92,77.97,0.630
13.93,78.12,0.631
13.95,78.27,0.632
13.97,78.42,0.632
13.98,78.57,0.634
14.00,78.72,0.635
14.01,78.87,0.637
14.03,79.02,0.637
14.04,79.17,0.638
14.05,79.32,0.639
14.07,79.47,0.640
14.08,79.62,0.640
14.10,79.77,0.641
14.12,79.92,0.642
14.13,80.07,0.643
14.15,80.22,0.644
14.16,80.37,0.645
14.18,80.52,0.646
14.19,80.67,0.647
14.20,80.82,0.648
14.22,80.97,0.649
14.23,81.12,0.650
14.25,81.27,0.651
14.27,81.42,0.652
14.28,81.57,0.653
14.30,81.72,0.654
14.31,81.87,0.656
14.33,82.02,0.656
14.34,82.17,0.657
14.35,82.32,0.659
14.37,82.47,0.660
14.38,82.62,0.660
14.40,82.77,0.662
14.42,82.92,0.663
14.43,83.07,0.664
14.45,83.22,0.665
14.46,83.37,0.666
14.48,83.52,0.667
14.49,83.67,0.668
14.50,83.82,0.669
14.52,83.97,0.670
14.53,84.12,0.672
14.55,84.27,0.672
14.57,84.42,0.673
14.58,84.57,0.675
14.60,84.72,0.676
14.61,84.87,0.677
14.63,85.02,0.678
14.64,85.17,0.679
14.65,85.32,0.680
14.67,85.47,0.682
14.68,85.62,0.683
14.70,85.77,0.684
14.72,85.92,0.685
14.73,86.07,0.686
14.75,86.22,0.687
14.76,86.37,0.687
14.78,86.52,0.688
14.79,86.67,0.689
14.80,86.82,0.691
14.82,86.96,0.692
14.83,87.12,0.692
14.85,87.26,0.693
14.87,87.41,0.695
14.88,87.56,0.695
14.90,87.71,0.697
14.91,87.86,0.698
14.93,88.01,0.699
14.94,88.16,0.699
14.95,88.31,0.700
14.97,88.46,0.701
14.98,88.61,0.702
15.00,88.76,0.703
15.02,88.91,0.704
15.03,89.06,0.705
15.05,89.21,0.705
15.06,89.36,0.707
15.08,89.51,0.708
15.09,89.66,0.709
15.10,89.81,0.710
15.12,89.96,0.711
15.13,90.11,0.712
15.15,90.26,0.712
15.17,90.41,0.713
15.18,90.56,0.714
15.20,90.71,0.715
15.21,90.86,0.715
15.23,91.01,0.716
15.24,91.16,0.716
15.25,91.31,0.717
15.27,91.46,0.718
15.28,91.61,0.718
15.30,91.76,0.719
15.32,91.91,0.720
15.33,92.06,0.720
15.35,92.21,0.721
15.36,92.36,0.722
15.38,92.51,0.722
15.39,92.66,0.723
15.40,92.81,0.724
15.42,92.96,0.724
15.43,93.11,0.724
15.45,93.26,0.725
15.47,93.41,0.725
15.48,93.56,0.726
15.50,93.71,0.726
15.51,93.86,0.726
15.53,94.01,0.727
15.54,94.16,0.727
15.55,94.31,0.728
15.57,94.46,0.728
15.58,94.61,0.729
15.60,94.76,0.729
15.62,94.91,0.730
15.63,95.06,0.730
15.65,95.21,0.730
15.66,95.36,0.731
15.68,95.51,0.731
15.69,95.66,0.732
15.70,95.81,0.732
15.72,95.96,0.732
15.73,96.11,0.733
15.75,96.26,0.733
15.77,96.41,0.733
15.78,96.56,0.734
15.80,96.71,0.734
15.81,96.86,0.734
15.83,97.01,0.735
15.84,97.16,0.735
15.85,97.31,0.735
15.87,97.46,0.735
15.88,97.61,0.735
15.90,97.76,0.736
15.92,97.91,0.736
15.93,98.06,0.736
15.95,98.21,0.736
15.96,98.36,0.736
15.98,98.51,0.736
15.99,98.66,0.736
16.00,98.81,0.737
16.02,98.96,0.737
16.03,99.11,0.737
16.05,99.26,0.737
16.07,99.42,0.737
16.08,99.57,0.737
16.10,99.72,0.737
16.11,99.87,0.737
16.13,100.02,0.737
16.14,100.17,0.737
16.15,100.32,0.736
16.17,100.47,0.736
16.18,100.62,0.736
16.20,100.77,0.736
16.22,100.92,0.736
16.23,101.07,0.736
16.25,101.22,0.736
16.26,101.37,0.735
16.28,101.52,0.735
16.29,101.67,0.735
16.30,101.82,0.734
16.32,101.97,0.734
16.33,102.12,0.734
16.35,102.27,0.733
16.37,102.42,0.733
16.38,102.57,0.733
16.40,102.72,0.732
16.41,102.87,0.732
16.43,103.02,0.731
16.44,103.17,0.731
16.45,103.32,0.730
16.47,103.47,0.729
16.48,103.62,0.728
16.50,103.77,0.728
16.52,103.92,0.727
16.53,104.07,0.726
16.55,104.23,0.726
16.56,104.37,0.725
16.58,104.53,0.725
16.59,104.68,0.723
16.60,104.83,0.723
16.62,104.98,0.722
16.63,105.13,0.721
16.65,105.28,0.720
16.67,105.43,0.719
16.68,105.58,0.718
16.70,105.73,0.716
16.71,105.88,0.715
16.73,106.03,0.714
16.74,106.18,0.713
16.75,106.33,0.711
16.77,106.48,0.710
16.78,106.63,0.709
16.80,106.78,0.708
16.82,106.94,0.707
16.83,107.09,0.706
16.85,107.24,0.705
16.86,107.39,0.703
16.88,107.54,0.702
16.89,107.69,0.701
16.90,107.84,0.699
16.92,107.99,0.698
16.93,108.14,0.697
16.95,108.29,0.696
16.97,108.44,0.694
16.98,108.59,0.693
17.00,108.74,0.691
17.01,108.89,0.689
17.03,109.04,0.688
17.04,109.19,0.687
17.05,109.35,0.685
17.07,109.50,0.684
17.08,109.65,0.683
17.10,109.80,0.681
17.12,109.95,0.679
17.13,110.10,0.678
17.14,110.25,0.676
17.16,110.40,0.675
17.18,110.55,0.673
17.19,110.70,0.672
17.21,110.85,0.671
17.22,111.00,0.669
17.23,111.15,0.668
17.25,111.30,0.667
17.27,111.45,0.664
17.28,111.60,0.663
17.29,111.75,0.661
17.31,111.90,0.660
17.33,112.05,0.659
17.34,112.21,0.657
17.36,112.36,0.656
17.37,112.51,0.655
17.38,112.66,0.653
17.40,112.81,0.652
17.42,112.96,0.650
17.43,113.11,0.648
17.44,113.26,0.646
17.46,113.41,0.645
17.48,113.56,0.643
17.49,113.71,0.642
17.51,113.86,0.639
17.52,114.01,0.638
17.53,114.16,0.637
17.55,114.32,0.634
17.57,114.47,0.633
17.58,114.62,0.632
17.59,114.77,0.630
17.61,114.92,0.629
17.63,115.07,0.627
17.64,115.22,0.625
17.66,115.37,0.623
17.67,115.52,0.622
17.68,115.67,0.620
17.70,115.82,0.618
17.72,115.97,0.617
17.73,116.12,0.615
17.74,116.27,0.614
17.76,116.43,0.613
17.78,116.58,0.611
17.79,116.73,0.609
17.81,116.88,0.607
17.82,117.03,0.606
17.83,117.18,0.604
17.85,117.33,0.602
17.87,117.48,0.599
17.88,117.63,0.598
17.89,117.78,0.597
17.91,117.93,0.595
17.93,118.08,0.593
17.94,118.24,0.591
17.96,118.39,0.590
17.97,118.54,0.588
17.98,118.69,0.586
18.00,118.84,0.584
18.02,118.99,0.583
18.03,119.14,0.581
18.04,119.29,0.580
18.06,119.44,0.578
18.08,119.59,0.576
18.09,119.74,0.575
18.11,119.89,0.573
18.12,120.04,0.572
18.13,120.19,0.570
18.15,120.35,0.568
18.17,120.50,0.567
18.18,120.65,0.565
18.19,120.80,0.563
18.21,120.95,0.561
18.23,121.10,0.560
18.24,121.25,0.558
18.26,121.40,0.556
18.27,121.55,0.555
18.28,121.70,0.553
18.30,121.85,0.551
18.32,122.00,0.550
18.33,122.15,0.548
18.34,122.31,0.546
18.36,122.46,0.545
18.38,122.61,0.543
18.39,122.76,0.542
18.41,122.91,0.540
18.42,123.06,0.538
18.43,123.21,0.536
18.45,123.36,0.535
18.47,123.51,0.533
18.48,123.66,0.531
18.49,123.81,0.530
18.51,123.96,0.528
18.53,124.11,0.527
18.54,124.26,0.525
18.56,124.41,0.524
18.57,124.56,0.522
18.58,124.71,0.521
18.60,124.86,0.519
18.62,125.02,0.518
18.63,125.17,0.516
18.64,125.32,0.515
18.66,125.47,0.513
18.68,125.62,0.512
18.69,125.77,0.510
18.71,125.92,0.509
18.72,126.07,0.507
18.73,126.22,0.505
18.75,126.37,0.504
18.77,126.52,0.503
18.78,126.67,0.502
18.79,126.82,0.500
18.81,126.97,0.499
18.83,127.13,0.497
18.84,127.28,0.495
18.86,127.43,0.494
18.87,127.58,0.492
18.88,127.73,0.491
18.90,127.88,0.489
18.92,128.03,0.487
18.93,128.18,0.486
18.94,128.33,0.485
18.96,128.48,0.483
18.98,128.63,0.482
18.99,128.78,0.481
19.01,128.93,0.479
19.02,129.08,0.479
19.03,129.23,0.477
19.05,129.38,0.476
19.07,129.54,0.475
19.08,129.69,0.474
19.09,129.84,0.472
19.11,129.99,0.470
19.13,130.14,0.469
19.14,130.29,0.468
19.16,130.44,0.466
19.17,130.59,0.464
19.18,130.74,0.463
19.20,130.89,0.460
19.22,131.04,0.460
19.23,131.19,0.459
19.24,131.34,0.458
19.26,131.49,0.456
19.28,131.64,0.455
19.29,131.79,0.454
19.31,131.94,0.453
19.32,132.09,0.452
19.33,132.24,0.451
19.35,132.40,0.450
19.37,132.55,0.450
19.38,132.70,0.448
19.39,132.85,0.446
19.41,133.00,0.445
19.43,133.15,0.444
19.44,133.30,0.443
19.46,133.45,0.442
19.47,133.60,0.440
19.48,133.75,0.439
19.50,133.90,0.438
19.52,134.05,0.436
19.53,134.20,0.435
19.54,134.35,0.434
19.56,134.50,0.433
19.58,134.66,0.431
19.59,134.80,0.430
19.61,134.96,0.429
19.62,135.11,0.428
19.63,135.26,0.428
19.65,135.41,0.427
19.67,135.56,0.425
19.68,135.71,0.424
19.69,135.86,0.423
19.71,136.01,0.422
19.73,136.16,0.421
19.74,136.31,0.420
19.76,136.46,0.419
19.77,136.61,0.418
19.78,136.76,0.417
19.80,136.91,0.416
19.82,137.06,0.415
19.83,137.21,0.414
19.84,137.36,0.413
19.86,137.51,0.412
19.88,137.66,0.411
19.89,137.81,0.411
19.91,137.96,0.410
19.92,138.11,0.409
19.93,138.26,0.407
19.95,138.41,0.407
19.97,138.57,0.406
19.98,138.72,0.405
19.99,138.87,0.405
20.01,139.02,0.404
20.03,139.17,0.403
20.04,139.32,0.402
20.06,139.47,0.401
20.07,139.62,0.400
20.08,139.77,0.399
20.10,139.92,0.398
20.12,140.07,0.397
20.13,140.22,0.396
20.14,140.37,0.395
20.16,140.52,0.394
20.18,140.67,0.394
20.19,140.82,0.393
20.21,140.97,0.392
20.22,141.12,0.391
20.23,141.27,0.391
20.25,141.42,0.390
20.27,141.57,0.389
20.28,141.72,0.388
20.29,141.87,0.388
20.31,142.03,0.387
20.33,142.17,0.386
20.34,142.32,0.385
20.36,142.48,0.385
20.37,142.63,0.384
20.38,142.78,0.383
20.40,142.93,0.382
20.42,143.08,0.382
20.43,143.23,0.381
20.44,143.38,0.381
20.46,143.53,0.380
20.48,143.68,0.379
20.49,143.83,0.379
20.51,143.98,0.378
20.52,144.13,0.377
20.53,144.28,0.377
20.55,144.43,0.376
20.57,144.58,0.375
20.58,144.73,0.375
20.59,144.88,0.374
20.61,145.03,0.374
20.63,145.18,0.373
20.64,145.33,0.372
20.66,145.48,0.372
20.67,145.64,0.371
20.68,145.79,0.371
20.70,145.94,0.370
20.72,146.09,0.370
20.73,146.24,0.369
20.74,146.39,0.368
20.76,146.54,0.368
20.78,146.69,0.367
20.79,146.84,0.367
20.81,146.99,0.366
20.82,147.14,0.366
20.83,147.29,0.365
20.85,147.44,0.365
20.87,147.59,0.364
20.88,147.74,0.364
20.89,147.89,0.363
20.91,148.04,0.363
20.93,148.19,0.362
20.94,148.34,
20.96,148.49,
20.97,148.64,
20.98,,
20.99,,

[step]
Ramp 10.00 °C/min to -60.00 °C
Time,Temperature,Heat Flow (Normalized)
min,°C,W/g
22.99,150.15,-0.028
23.01,150.15,-0.028
23.02,150.15,-0.028
23.04,150.14,-0.028
23.05,150.12,-0.029
23.07,150.10,-0.039
23.08,150.05,-0.060
23.10,149.99,-0.086
23.11,149.91,-0.119
23.13,149.81,-0.159
23.14,149.71,-0.196
23.16,149.59,-0.230
23.17,149.47,-0.259
23.19,149.34,-0.281
23.20,149.21,-0.300
23.22,149.07,-0.316
23.23,148.94,-0.326
23.25,148.80,-0.335
23.26,148.66,-0.342
23.28,148.51,-0.349
23.29,148.37,-0.353
23.31,148.23,-0.358
23.32,148.08,-0.360
23.34,147.94,-0.364
23.35,147.79,-0.366
23.37,147.64,-0.368
23.38,147.50,-0.370
23.40,147.35,-0.371
23.41,147.20,-0.372
23.43,147.05,-0.373
23.44,146.90,-0.373
23.46,146.76,-0.374
23.47,146.61,-0.375
23.49,146.46,-0.375
23.50,146.31,-0.375
23.52,146.16,-0.375
23.53,146.01,-0.376
23.55,145.86,-0.376
23.56,145.72,-0.376
23.58,145.57,-0.376
23.59,145.42,-0.376
23.61,145.27,-0.377
23.62,145.12,-0.377
23.64,144.97,-0.377
23.65,144.82,-0.377
23.67,144.68,-0.377
23.68,144.52,-0.377
23.70,144.38,-0.378
23.71,144.23,-0.378
23.73,144.08,-0.378
23.74,143.93,-0.378
23.76,143.78,-0.378
23.77,143.63,-0.378
23.79,143.48,-0.378
23.80,143.33,-0.379
23.82,143.18,-0.379
23.83,143.03,-0.379
23.85,142.88,-0.379
23.86,142.73,-0.379
23.88,142.58,-0.379
23.89,142.43,-0.379
23.91,142.29,-0.379
23.92,142.14,-0.380
23.94,141.99,-0.380
23.95,141.84,-0.380
23.97,141.68,-0.380
23.98,141.54,-0.380
24.00,141.39,-0.380
24.01,141.24,-0.380
24.03,141.09,-0.380
24.04,140.94,-0.380
24.06,140.79,-0.380
24.07,140.64,-0.380
24.09,140.49,-0.380
24.10,140.34,-0.380
24.12,140.19,-0.380
24.13,140.04,-0.380
24.15,139.89,-0.380
24.16,139.74,-0.380
24.18,139.59,-0.380
24.19,139.44,-0.380
24.21,139.29,-0.380
24.22,139.14,-0.380
24.24,138.99,-0.380
24.25,138.84,-0.380
24.27,138.69,-0.380
24.28,138.54,-0.380
24.30,138.39,-0.380
24.31,138.24,-0.380
24.33,138.09,-0.380
24.34,137.94,-0.380
24.36,137.79,-0.380
24.37,137.64,-0.380
24.39,137.49,-0.380
24.40,137.34,-0.380
24.42,137.19,-0.380
24.43,137.04,-0.380
24.45,136.89,-0.380
24.46,136.74,-0.379
24.48,136.59,-0.379
24.49,136.44,-0.379
24.51,136.29,-0.379
24.52,136.14,-0.379
24.54,135.99,-0.379
24.55,135.84,-0.379
24.57,135.69,-0.379
24.58,135.54,-0.379
24.60,135.39,-0.379
24.61,135.25,-0.379
24.63,135.10,-0.379
24.64,134.95,-0.378
24.66,134.80,-0.378
24.67,134.65,-0.378
24.69,134.50,-0.378
24.70,134.35,-0.378
24.72,134.20,-0.378
24.73,134.05,-0.378
24.75,133.90,-0.378
24.76,133.75,-0.378
24.78,133.60,-0.378
24.79,133.45,-0.378
24.81,133.30,-0.378
24.82,133.15,-0.378
24.84,133.00,-0.378
24.85,132.85,-0.377
24.87,132.70,-0.377
24.88,132.55,-0.377
24.90,132.40,-0.377
24.91,132.25,-0.377
24.93,132.10,-0.377
24.94,131.95,-0.377
24.96,131.80,-0.377
24.97,131.65,-0.377
24.99,131.50,-0.377
25.00,131.35,-0.377
25.02,131.20,-0.377
25.03,131.05,-0.377
25.05,130.90,-0.376
25.06,130.75,-0.376
25.08,130.60,-0.376
25.09,130.45,-0.376
25.11,130.30,-0.376
25.12,130.15,-0.376
25.14,130.00,-0.376
25.15,129.85,-0.376
25.17,129.70,-0.376
25.18,129.55,-0.376
25.20,129.40,-0.376
25.21,129.25,-0.376
25.23,129.10,-0.375
25.24,128.95,-0.375
25.26,128.80,-0.375
25.27,128.65,-0.375
25.29,128.50,-0.375
25.30,128.35,-0.375
25.32,128.20,-0.375
25.33,128.05,-0.375
25.35,127.90,-0.375
25.36,127.75,-0.375
25.38,127.60,-0.375
25.39,127.45,-0.375
25.41,127.30,-0.374
25.42,127.15,-0.374
25.44,127.00,-0.374
25.45,126.85,-0.374
25.47,126.71,-0.374
25.48,126.56,-0.374
25.50,126.40,-0.374
25.51,126.26,-0.374
25.53,126.10,-0.373
25.54,125.95,-0.373
25.56,125.80,-0.373
25.57,125.65,-0.373
25.59,125.50,-0.373
25.60,125.35,-0.373
25.62,125.20,-0.373
25.63,125.05,-0.373
25.65,124.90,-0.373
25.66,124.75,-0.373
25.68,124.60,-0.373
25.69,124.45,-0.373
25.71,124.30,-0.373
25.72,124.15,-0.373
25.74,124.00,-0.373
25.75,123.85,-0.373
25.77,123.70,-0.372
25.78,123.55,-0.372
25.80,123.40,-0.372
25.81,123.25,-0.372
25.83,123.10,-0.372
25.84,122.95,-0.372
25.86,122.80,-0.372
25.87,122.65,-0.372
25.89,122.50,-0.372
25.90,122.35,-0.371
25.92,122.20,-0.371
25.93,122.05,-0.371
25.95,121.90,-0.371
25.96,121.75,-0.371
25.98,121.60,-0.371
25.99,121.45,-0.371
26.01,121.31,-0.371
26.02,121.15,-0.370
26.04,121.01,-0.370
26.05,120.86,-0.370
26.07,120.71,-0.370
26.08,120.55,-0.370
26.10,120.41,-0.370
26.11,120.26,-0.370
26.13,120.11,-0.370
26.14,119.95,-0.369
26.16,119.81,-0.369
26.17,119.65,-0.369
26.19,119.50,-0.369
26.20,119.35,-0.369
26.22,119.20,-0.369
26.23,119.05,-0.369
26.25,118.90,-0.369
26.26,118.75,-0.369
26.28,118.60,-0.369
26.29,118.45,-0.369
26.31,118.30,-0.368
26.32,118.15,-0.368
26.34,118.00,-0.368
26.35,117.85,-0.368
26.37,117.70,-0.368
26.38,117.55,-0.368
26.40,117.40,-0.368
26.41,117.25,-0.368
26.43,117.10,-0.367
26.44,116.95,-0.367
26.46,116.80,-0.367
26.47,116.65,-0.367
26.49,116.50,-0.367
26.50,116.35,-0.367
26.52,116.20,-0.366
26.53,116.05,-0.366
26.55,115.90,-0.366
26.56,115.75,-0.366
26.58,115.60,-0.366
26.59,115.45,-0.366
26.61,115.30,-0.365
26.62,115.15,-0.365
26.64,115.00,-0.365
26.65,114.85,-0.365
26.67,114.70,-0.365
26.68,114.55,-0.365
26.70,114.40,-0.364
26.71,114.25,-0.364
26.73,114.10,-0.364
26.74,113.95,-0.364
26.76,113.80,-0.364
26.77,113.65,-0.363
26.79,113.50,-0.363
26.80,113.35,-0.363
26.82,113.20,-0.363
26.83,113.05,-0.363
26.85,112.90,-0.362
26.86,112.75,-0.362
26.88,112.60,-0.362
26.89,112.45,-0.362
26.91,112.30,-0.362
26.92,112.15,-0.361
26.94,112.00,-0.361
26.95,111.85,-0.361
26.97,111.70,-0.361
26.98,111.55,-0.360
27.00,111.40,-0.360
27.01,111.25,-0.360
27.03,111.10,-0.360
27.04,110.95,-0.359
27.06,110.80,-0.359
27.07,110.65,-0.359
27.09,110.50,-0.359
27.10,110.35,-0.358
27.12,110.20,-0.358
27.13,110.05,-0.358
27.15,109.90,-0.358
27.16,109.75,-0.357
27.18,109.60,-0.357
27.19,109.45,-0.357
27.21,109.30,-0.357
27.22,109.15,-0.356
27.24,109.00,-0.356
27.25,108.85,-0.356
27.27,108.70,-0.355
27.28,108.55,-0.355
27.30,108.40,-0.355
27.31,108.25,-0.354
27.33,108.10,-0.354
27.34,107.95,-0.354
27.36,107.80,-0.353
27.37,107.65,-0.353
27.39,107.50,-0.352
27.40,107.35,-0.352
27.42,107.20,-0.352
27.43,107.05,-0.352
27.45,106.90,-0.351
27.46,106.75,-0.351
27.48,106.60,-0.350
27.49,106.45,-0.350
27.51,106.30,-0.350
27.52,106.15,-0.349
27.54,106.00,-0.349
27.55,105.85,-0.349
27.57,105.70,-0.348
27.58,105.55,-0.348
27.60,105.40,-0.348
27.61,105.25,-0.348
27.63,105.10,-0.347
27.64,104.95,-0.347
27.66,104.80,-0.347
27.67,104.65,-0.346
27.69,104.50,-0.346
27.70,104.35,-0.346
27.72,104.20,-0.345
27.73,104.05,-0.345
27.75,103.90,-0.345
27.76,103.75,-0.344
27.78,103.60,-0.344
27.79,103.45,-0.344
27.81,103.30,-0.343
27.82,103.15,-0.343
27.84,103.00,-0.342
27.85,102.85,-0.342
27.87,102.70,-0.342
27.88,102.55,-0.341
27.90,102.40,-0.341
27.91,102.25,-0.340
27.93,102.10,-0.340
27.94,101.95,-0.340
27.96,101.80,-0.339
27.97,101.65,-0.339
27.99,101.50,-0.339
28.00,101.35,-0.338
28.02,101.20,-0.338
28.03,101.05,-0.338
28.05,100.90,-0.337
28.06,100.75,-0.337
28.08,100.60,-0.337
28.09,100.45,-0.336
28.11,100.30,-0.336
28.12,100.15,-0.335
28.14,100.00,-0.335
28.15,99.85,-0.335
28.17,99.70,-0.334
28.18,99.55,-0.334
28.20,99.40,-0.334
28.21,99.25,-0.333
28.23,99.10,-0.333
28.24,98.95,-0.333
28.26,98.80,-0.332
28.27,98.65,-0.332
28.29,98.50,-0.332
28.30,98.35,-0.331
28.32,98.20,-0.331
28.33,98.05,-0.330
28.35,97.90,-0.330
28.36,97.75,-0.330
28.38,97.60,-0.329
28.39,97.45,-0.329
28.41,97.30,-0.329
28.42,97.15,-0.328
28.44,97.00,-0.328
28.45,96.85,-0.328
28.47,96.70,-0.327
28.48,96.55,-0.327
28.50,96.40,-0.327
28.51,96.25,-0.326
28.53,96.10,-0.326
28.54,95.95,-0.326
28.56,95.80,-0.325
28.57,95.65,-0.325
28.59,95.50,-0.325
28.60,95.35,-0.324
28.62,95.20,-0.324
28.63,95.05,-0.324
28.65,94.90,-0.323
28.66,94.75,-0.323
28.68,94.60,-0.323
28.69,94.45,-0.322
28.71,94.30,-0.322
28.72,94.15,-0.322
28.74,94.00,-0.322
28.75,93.85,-0.321
28.77,93.70,-0.321
28.78,93.55,-0.321
28.80,93.40,-0.320
28.81,93.25,-0.320
28.83,93.10,-0.320
28.84,92.95,-0.320
28.86,92.80,-0.319
28.87,92.65,-0.319
28.89,92.50,-0.319
28.90,92.35,-0.318
28.92,92.20,-0.318
28.93,92.05,-0.318
28.95,91.90,-0.317
28.96,91.75,-0.317
28.98,91.60,-0.317
28.99,91.45,-0.317
29.01,91.30,-0.316
29.02,91.15,-0.316
29.04,91.00,-0.316
29.05,90.85,-0.315
29.07,90.70,-0.315
29.08,90.55,-0.315
29.10,90.40,-0.315
29.11,90.25,-0.314
29.13,90.10,-0.314
29.14,89.95,-0.314
29.16,89.80,-0.313
29.17,89.65,-0.313
29.19,89.50,-0.313
29.20,89.35,-0.313
29.22,89.20,-0.312
29.23,89.05,-0.312
29.25,88.90,-0.312
29.26,88.75,-0.312
29.28,88.60,-0.311
29.29,88.45,-0.311
29.31,88.30,-0.311
29.32,88.15,-0.311
29.34,88.00,-0.310
29.35,87.85,-0.310
29.37,87.70,-0.310
29.38,87.55,-0.310
29.40,87.40,-0.309
29.41,87.25,-0.309
29.43,87.10,-0.309
29.44,86.95,-0.309
29.46,86.80,-0.308
[...]
97.26,-8.67,0.180
97.27,-8.52,0.180
97.29,-8.37,0.180
97.30,-8.22,0.180
97.32,-8.07,0.181
97.33,-7.92,0.181
97.35,-7.77,0.181
97.36,-7.62,0.181
97.38,-7.47,0.181
97.39,-7.32,0.181
97.41,-7.17,0.181
97.42,-7.02,0.181
97.44,-6.87,0.181
97.45,-6.72,0.181
97.47,-6.57,0.181
97.48,-6.42,0.181
97.50,-6.27,0.181
97.51,-6.12,0.181
97.53,-5.97,0.181
97.54,-5.82,0.181
97.56,-5.67,0.181
97.57,-5.52,0.182
97.59,-5.37,0.182
97.60,-5.22,0.182
97.62,-5.07,0.182
97.63,-4.92,0.182
97.65,-4.77,0.182
97.66,-4.62,0.182
97.68,-4.47,0.182
97.69,-4.32,0.182
97.71,-4.17,0.182
97.72,-4.02,0.182
97.74,-3.87,0.182
97.75,-3.72,0.182
97.77,-3.57,0.182
97.78,-3.42,0.183
97.80,-3.27,0.183
97.81,-3.12,0.183
97.83,-2.97,0.183
97.84,-2.82,0.183
97.86,-2.67,0.183
97.87,-2.52,0.183
97.89,-2.37,0.183
97.90,-2.22,0.183
97.92,-2.07,0.183
97.93,-1.92,0.183
97.95,-1.77,0.183
97.96,-1.61,0.183
97.98,-1.46,0.183
97.99,-1.32,0.184
98.01,-1.16,0.184
98.02,-1.01,0.184
98.04,-0.86,0.184
98.05,-0.71,0.184
98.07,-0.56,0.184
98.08,-0.41,0.184
98.10,-0.26,0.184
98.11,-0.11,0.184
98.13,0.04,0.184
98.14,0.19,0.184
98.16,0.34,0.184
98.17,0.49,0.184
98.19,0.64,0.184
98.20,0.79,0.184
98.22,0.94,0.185
98.23,1.09,0.185
98.25,1.24,0.185
98.26,1.39,0.185
98.28,1.54,0.185
98.29,1.69,0.185
98.31,1.84,0.185
98.32,1.99,0.185
98.34,2.14,0.185
98.35,2.29,0.185
98.37,2.44,0.185
98.38,2.59,0.185
98.40,2.74,0.185
98.41,2.89,0.186
98.43,3.04,0.186
98.44,3.19,0.186
98.46,3.34,0.186
98.47,3.49,0.186
98.49,3.64,0.186
98.50,3.79,0.186
98.52,3.94,0.186
98.53,4.09,0.186
98.55,4.24,0.186
98.56,4.39,0.186
98.58,4.54,0.186
98.59,4.69,0.186
98.61,4.84,0.186
98.62,4.99,0.187
98.64,5.14,0.187
98.65,5.29,0.187
98.67,5.44,0.187
98.68,5.59,0.187
98.70,5.74,0.187
98.71,5.89,0.187
98.73,6.04,0.187
98.74,6.19,0.187
98.76,6.34,0.187
98.77,6.49,0.187
98.79,6.64,0.187
98.80,6.79,0.187
98.82,6.94,0.187
98.83,7.09,0.188
98.85,7.24,0.188
98.86,7.39,0.188
98.88,7.54,0.188
98.89,7.69,0.188
98.91,7.84,0.188
98.92,7.99,0.188
98.94,8.14,0.188
98.95,8.29,0.188
98.97,8.45,0.188
98.98,8.60,0.188
99.00,8.74,0.188
99.01,8.89,0.189
99.03,9.04,0.189
99.04,9.20,0.189
99.06,9.35,0.189
99.07,9.50,0.189
99.09,9.65,0.189
99.10,9.80,0.189
99.12,9.95,0.189
99.13,10.10,0.189
99.15,10.25,0.189
99.16,10.40,0.189
99.18,10.55,0.189
99.19,10.70,0.189
99.21,10.85,0.190
99.22,11.00,0.190
99.24,11.15,0.190
99.25,11.30,0.190
99.27,11.45,0.190
99.28,11.60,0.190
99.30,11.75,0.190
99.31,11.90,0.190
99.33,12.05,0.190
99.34,12.20,0.190
99.36,12.35,0.190
99.37,12.50,0.191
99.39,12.65,0.191
99.40,12.80,0.191
99.42,12.95,0.191
99.43,13.10,0.191
99.45,13.25,0.191
99.46,13.40,0.191
99.48,13.55,0.191
99.49,13.70,0.191
99.51,13.85,0.191
99.52,14.00,0.191
99.54,14.15,0.191
99.55,14.30,0.192
99.57,14.45,0.192
99.58,14.60,0.192
99.60,14.75,0.192
99.61,14.90,0.192
99.63,15.05,0.192
99.64,15.20,0.192
99.66,15.35,0.192
99.67,15.50,0.192
99.69,15.65,0.192
99.70,15.80,0.192
99.72,15.95,0.193
99.73,16.10,0.193
99.75,16.25,0.193
99.76,16.40,0.193
99.78,16.55,0.193
99.79,16.70,0.193
99.81,16.85,0.193
99.82,17.00,0.193
99.84,17.15,0.193
99.85,17.30,0.193
99.87,17.45,0.193
99.88,17.60,0.194
99.90,17.76,0.194
99.91,17.90,0.194
99.93,18.06,0.194
99.94,18.20,0.194
99.96,18.36,0.194
99.97,18.51,0.194
99.99,18.66,0.194
100.00,18.81,0.194
100.02,18.96,0.194
100.03,19.11,0.194
100.05,19.26,0.194
100.06,19.41,0.195
100.08,19.56,0.195
100.09,19.71,0.195
100.11,19.86,0.195
100.12,20.01,0.195
100.14,20.16,0.195
100.15,20.31,0.195
100.17,20.46,0.195
100.18,20.61,0.195
100.20,20.76,0.195
100.21,20.91,0.195
100.23,21.06,0.196
100.24,21.21,0.196
100.26,21.36,0.196
100.27,21.51,0.196
100.29,21.66,0.196
100.30,21.81,0.196
100.32,21.96,0.196
100.33,22.11,0.196
100.35,22.26,0.196
100.36,22.41,0.196
100.38,22.56,0.196
100.39,22.71,0.196
100.41,22.86,0.197
100.42,23.01,0.197
100.44,23.16,0.197
100.45,23.31,0.197
100.47,23.46,0.197
100.48,23.61,0.197
100.50,23.76,0.197
100.51,23.91,0.197
100.53,24.06,0.197
100.54,24.21,0.197
100.56,24.36,0.197
100.57,24.51,0.197
100.59,24.66,0.198
100.60,24.81,0.198
100.62,24.96,0.198
100.63,25.11,0.198
100.65,25.26,0.198
100.66,25.41,0.198
100.68,25.56,0.198
100.69,25.71,0.198
100.71,25.86,0.198
100.72,26.01,0.198
100.74,26.16,0.198
100.75,26.31,0.199
100.77,26.46,0.199
100.78,26.61,0.199
100.80,26.76,0.199
100.81,26.91,0.199
100.83,27.06,0.199
100.84,27.21,0.199
100.86,27.36,0.199
100.87,27.51,0.199
100.89,27.66,0.199
100.90,27.81,0.199
100.92,27.97,0.200
100.93,28.12,0.200
100.95,28.27,0.200
100.96,28.42,0.200
100.98,28.57,0.200
100.99,28.72,0.200
101.01,28.87,0.200
101.02,29.02,0.200
101.04,29.16,0.200
101.05,29.32,0.200
101.07,29.47,0.200
101.08,29.62,0.201
101.10,29.77,0.201
101.11,29.92,0.201
101.13,30.07,0.201
101.14,30.22,0.201
101.16,30.37,0.201
101.17,30.52,0.201
101.19,30.67,0.201
101.20,30.82,0.201
101.22,30.97,0.201
101.23,31.12,0.201
101.25,31.27,0.202
101.26,31.42,0.202
101.28,31.57,0.202
101.29,31.72,0.202
101.31,31.87,0.202
101.32,32.02,0.202
101.34,32.17,0.202
101.35,32.32,0.202
101.37,32.47,0.202
101.38,32.62,0.202
101.40,32.77,0.202
101.41,32.92,0.202
101.43,33.07,0.203
101.44,33.22,0.203
101.46,33.37,0.203
101.47,33.52,0.203
101.49,33.67,0.203
101.50,33.82,0.203
101.52,33.97,0.203
101.53,34.12,0.203
101.55,34.27,0.203
101.56,34.42,0.203
101.58,34.57,0.203
101.59,34.72,0.204
101.61,34.87,0.204
101.62,35.02,0.204
101.64,35.17,0.204
101.65,35.32,0.204
101.67,35.47,0.204
101.68,35.62,0.204
101.70,35.77,0.204
101.71,35.92,0.204
101.73,36.07,0.204
101.74,36.22,0.204
101.76,36.37,0.204
101.77,36.52,0.205
101.79,36.68,0.205
101.80,36.82,0.205
101.82,36.97,0.205
101.83,37.12,0.205
101.85,37.27,0.205
101.86,37.42,0.205
101.88,37.57,0.205
101.89,37.73,0.205
101.91,37.88,0.205
101.92,38.03,0.205
101.94,38.18,0.206
101.95,38.33,0.206
101.97,38.48,0.206
101.98,38.63,0.206
102.00,38.78,0.206
102.01,38.93,0.206
102.03,39.08,0.206
102.04,39.23,0.206
102.06,39.38,0.206
102.07,39.53,0.206
102.09,39.68,0.206
102.10,39.83,0.206
102.12,39.98,0.207
102.13,40.13,0.207
102.15,40.28,0.207
102.16,40.43,0.207
102.18,40.58,0.207
102.19,40.73,0.207
102.21,40.88,0.207
102.22,41.03,0.207
102.24,41.18,0.207
102.25,41.33,0.207
102.27,41.48,0.207
102.28,41.63,0.208
102.30,41.78,0.208
102.31,41.93,0.208
102.33,42.08,0.208
102.34,42.23,0.208
102.36,42.38,0.208
102.37,42.53,0.208
102.39,42.68,0.208
102.40,42.83,0.208
102.42,42.98,0.208
102.43,43.13,0.209
102.45,43.28,0.209
102.46,43.43,0.209
102.48,43.58,0.209
102.49,43.73,0.209
102.51,43.88,0.209
102.52,44.03,0.209
102.54,44.18,0.209
102.55,44.33,0.209
102.57,44.48,0.209
102.58,44.63,0.209
102.60,44.78,0.210
102.61,44.93,0.210
102.63,45.08,0.210
102.64,45.23,0.210
102.66,45.38,0.210
102.67,45.53,0.210
102.69,45.68,0.210
102.70,45.83,0.210
102.72,45.98,0.210
102.73,46.13,0.210
102.75,46.28,0.211
102.76,46.43,0.211
102.78,46.58,0.211
102.79,46.73,0.211
102.81,46.88,0.211
102.82,47.03,0.211
102.84,47.18,0.211
102.85,47.33,0.211
102.87,47.48,0.211
102.88,47.63,0.211
102.90,47.78,0.211
102.91,47.93,0.212
102.93,48.08,0.212
102.94,48.23,0.212
102.96,48.38,0.212
102.97,48.53,0.212
102.99,48.68,0.212
103.00,48.83,0.212
103.02,48.99,0.212
103.03,49.13,0.212
103.05,49.29,0.212
103.06,49.43,0.213
103.08,49.58,0.213
103.09,49.73,0.213
103.11,49.89,0.213
103.12,50.04,0.213
103.14,50.19,0.213
103.15,50.34,0.213
103.17,50.49,0.213
103.18,50.64,0.213
103.20,50.79,0.213
103.21,50.94,0.214
103.23,51.09,0.214
103.24,51.24,0.214
103.26,51.39,0.214
103.27,51.54,0.214
103.29,51.69,0.214
103.30,51.84,0.214
103.32,51.99,0.214
103.33,52.14,0.214
103.35,52.29,0.214
103.36,52.44,0.214
103.38,52.59,0.215
103.39,52.74,0.215
103.41,52.89,0.215
103.42,53.04,0.215
103.44,53.19,0.215
103.45,53.34,0.215
103.47,53.49,0.215
103.48,53.64,0.215
103.50,53.79,0.215
103.51,53.94,0.215
103.53,54.09,0.215
103.54,54.24,0.215
103.56,54.39,0.216
103.57,54.54,0.216
103.59,54.69,0.216
103.60,54.84,0.216
103.62,54.99,0.216
103.63,55.14,0.216
103.65,55.29,0.216
103.66,55.44,0.216
103.68,55.59,0.216
103.69,55.74,0.216
103.71,55.89,0.216
103.72,56.04,0.217
103.74,56.19,0.217
103.75,56.34,0.217
103.77,56.49,0.217
103.78,56.64,0.217
103.80,56.79,0.217
103.81,56.94,0.217
103.83,57.09,0.217
103.84,57.24,0.217
103.86,57.39,0.217
103.87,57.54,0.217
103.89,57.69,0.218
103.90,57.84,0.218
103.92,57.99,0.218
103.93,58.14,0.218
103.95,58.29,0.218
103.96,58.44,0.218
103.98,58.59,0.218
103.99,58.74,0.218
104.01,58.89,0.218
104.02,59.04,0.219
104.04,59.19,0.219
104.05,59.34,0.219
104.07,59.49,0.219
104.08,59.64,0.219
104.10,59.79,0.219
104.11,59.95,0.219
104.13,60.09,0.219
104.14,60.25,0.219
104.16,60.40,0.219
104.17,60.55,0.220
104.19,60.69,0.220
104.20,60.85,0.220
104.22,61.00,0.220
104.23,61.15,0.220
104.25,61.30,0.220
104.26,61.45,0.220
104.28,61.60,0.220
104.29,61.75,0.220
104.31,61.90,0.220
104.32,62.05,0.220
104.34,62.20,0.221
104.35,62.35,0.221
104.37,62.50,0.221
104.38,62.65,0.221
104.40,62.80,0.221
104.41,62.95,0.221
104.43,63.10,0.221
104.44,63.25,0.221
104.46,63.40,0.221
104.47,63.55,0.221
104.49,63.70,0.222
104.50,63.85,0.222
104.52,64.00,0.222
104.53,64.15,0.222
104.55,64.30,0.222
104.56,64.45,0.222
104.58,64.60,0.222
104.59,64.75,0.222
104.61,64.90,0.222
104.62,65.05,0.222
104.64,65.20,0.223
104.65,65.35,0.223
104.67,65.50,0.223
104.68,65.65,0.223
104.70,65.80,0.223
104.71,65.95,0.223
104.73,66.10,0.223
104.74,66.25,0.223
104.76,66.40,0.223
104.77,66.55,0.223
104.79,66.70,0.224
104.80,66.85,0.224
104.82,67.00,0.224
104.83,67.15,0.224
104.85,67.30,0.224
104.86,67.45,0.224
104.88,67.60,0.224
104.89,67.75,0.224
104.91,67.90,0.224
104.92,68.05,0.224
104.94,68.20,0.225
104.95,68.35,0.225
104.97,68.50,0.225
104.98,68.65,0.225
105.00,68.80,0.225
105.01,68.95,0.225
105.03,69.10,0.225
105.04,69.25,0.225
105.06,69.40,0.225
105.07,69.55,0.225
105.09,69.70,0.226
105.10,69.85,0.226
105.12,70.00,0.226
105.13,70.15,0.226
105.15,70.30,0.226
105.16,70.45,0.226
105.18,70.60,0.226
105.19,70.75,0.226
105.21,70.90,0.226
105.22,71.05,0.226
105.24,71.20,0.226
105.25,71.35,0.227
105.27,71.50,0.227
105.28,71.65,0.227
105.30,71.80,0.227
105.31,71.95,0.227
105.33,72.10,0.227
105.34,72.25,0.227
105.36,72.40,0.227
105.37,72.55,0.227
105.39,72.70,0.228
105.40,72.86,0.228
105.42,73.01,0.228
105.43,73.16,0.228
105.45,73.31,0.228
105.46,73.46,0.228
105.48,73.61,0.228
105.49,73.76,0.228
105.51,73.91,0.229
105.52,74.06,0.229
105.54,74.21,0.229
105.55,74.36,0.229
105.57,74.51,0.229
105.58,74.66,0.229
105.60,74.81,0.229
105.61,74.96,0.229
105.63,75.11,0.229
105.64,75.26,0.230
105.66,75.41,0.230
105.67,75.56,0.230
105.69,75.71,0.230
105.70,75.86,0.230
105.72,76.01,0.230
105.73,76.16,0.230
105.75,76.31,0.230
105.76,76.46,0.230
105.78,76.61,0.231
105.79,76.76,0.231
105.81,76.91,0.231
105.82,77.06,0.231
105.84,77.21,0.231
105.85,77.36,0.231
105.87,77.51,0.231
105.88,77.66,0.231
105.90,77.81,0.231
105.91,77.96,0.232
105.93,78.11,0.232
105.94,78.26,0.232
105.96,78.41,0.232
105.97,78.56,0.232
105.99,78.71,0.232
106.00,78.86,0.232
106.02,79.01,0.232
106.03,79.16,0.233
106.05,79.31,0.233
106.06,79.46,0.233
106.08,79.61,0.233
106.09,79.76,0.233
106.11,79.91,0.233
106.12,80.06,0.233
106.14,80.21,0.233
106.15,80.36,0.233
106.17,80.51,0.234
106.18,80.66,0.234
106.20,80.81,0.234
106.21,80.96,0.234
106.23,81.11,0.234
106.24,81.26,0.234
106.26,81.41,0.234
106.27,81.56,0.234
106.29,81.71,0.235
106.30,81.86,0.235
106.32,82.01,0.235
106.33,82.16,0.235
106.35,82.31,0.235
106.36,82.46,0.235
106.38,82.61,0.235
106.39,82.76,0.235
106.41,82.91,0.236
106.42,83.06,0.236
106.44,83.21,0.236
106.45,83.36,0.236
106.47,83.51,0.236
106.48,83.66,0.236
106.50,83.81,0.236
106.51,83.96,0.236
106.53,84.12,0.236
106.54,84.27,0.237
106.56,84.41,0.237
106.57,84.57,0.237
106.59,84.72,0.237
106.60,84.87,0.237
106.62,85.02,0.237
106.63,85.17,0.237
106.65,85.32,0.237
106.66,85.47,0.238
106.68,85.62,0.238
106.69,85.77,0.238
106.71,85.92,0.238
106.72,86.07,0.238
106.74,86.22,0.238
106.75,86.37,0.238
106.77,86.52,0.238
106.78,86.67,0.239
106.80,86.82,0.239
106.81,86.97,0.239
106.83,87.12,0.239
106.84,87.27,0.239
106.86,87.42,0.239
106.87,87.57,0.239
106.89,87.72,0.239
106.90,87.87,0.240
106.92,88.02,0.240
106.93,88.17,0.240
106.95,88.32,0.240
106.96,88.47,0.240
106.98,88.62,0.240
106.99,88.77,0.240
107.01,88.92,0.241
107.02,89.07,0.241
107.04,89.22,0.241
107.05,89.37,0.241
107.07,89.52,0.241
107.08,89.67,0.241
107.10,89.82,0.242
107.11,89.97,0.242
107.13,90.12,0.242
107.14,90.27,0.242
107.16,90.42,0.242
107.17,90.57,0.242
107.19,90.72,0.243
107.20,90.87,0.243
107.22,91.02,0.243
107.23,91.17,0.243
107.25,91.32,0.243
107.26,91.47,0.243
107.28,91.62,0.244
107.29,91.77,0.244
107.31,91.92,0.244
107.32,92.07,0.244
107.34,92.22,0.244
107.35,92.37,0.244
107.37,92.52,0.245
107.38,92.67,0.245
107.40,92.82,0.245
107.41,92.97,0.245
107.43,93.12,0.245
107.44,93.27,0.245
107.46,93.42,0.246
107.47,93.57,0.246
107.49,93.72,0.246
107.50,93.87,0.246
107.52,94.02,0.246
107.53,94.17,0.247
107.55,94.32,0.247
107.56,94.47,0.247
107.58,94.62,0.247
107.59,94.77,0.247
107.61,94.92,0.248
107.62,95.07,0.248
107.64,95.22,0.248
107.65,95.37,0.248
107.67,95.52,0.249
107.68,95.67,0.249
107.70,95.82,0.249
107.71,95.97,0.249
107.73,96.12,0.249
107.74,96.27,0.250
107.76,96.42,0.250
107.77,96.57,0.250
107.79,96.72,0.250
107.80,96.87,0.251
107.82,97.02,0.251
107.83,97.17,0.251
107.85,97.32,0.251
107.86,97.47,0.252
107.88,97.62,0.252
107.89,97.77,0.252
107.91,97.92,0.252
107.92,98.07,0.253
107.94,98.23,0.253
107.95,98.38,0.253
107.97,98.53,0.254
107.98,98.68,0.254
108.00,98.83,0.255
108.01,98.98,0.255
108.03,99.13,0.256
108.04,99.29,0.256
108.06,99.44,0.257
108.07,99.59,0.257
108.09,99.74,0.257
108.10,99.89,0.257
108.12,100.04,0.258
108.13,100.18,0.258
108.15,100.33,0.258
108.16,100.48,0.258
108.18,100.63,0.258
108.19,100.78,0.258
108.21,100.93,0.259
108.22,101.08,0.259
108.24,101.23,0.259
108.25,101.38,0.259
108.27,101.53,0.260
108.28,101.68,0.260
108.30,101.83,0.260
108.31,101.98,0.260
108.33,102.13,0.261
108.34,102.28,0.261
108.36,102.43,0.261
108.37,102.58,0.262
108.39,102.73,0.262
108.40,102.88,0.262
108.42,103.03,0.263
108.43,103.18,0.263
108.45,103.33,0.263
108.46,103.48,0.264
108.48,103.63,0.264
108.49,103.78,0.264
108.51,103.92,0.265
108.52,104.07,0.265
108.54,104.23,0.265
108.55,104.38,0.266
108.57,104.52,0.266
108.58,104.68,0.267
108.60,104.83,0.267
108.61,104.98,0.268
108.63,105.13,0.268
108.64,105.28,0.269
108.66,105.43,0.269
108.67,105.58,0.270
108.69,105.73,0.270
108.70,105.88,0.271
108.72,106.03,0.271
108.73,106.18,0.272
108.75,106.32,0.272
108.76,106.47,0.273
108.78,106.63,0.273
108.79,106.77,0.274
108.81,106.92,0.274
108.82,107.07,0.275
108.84,107.22,0.275
108.85,107.37,0.276
108.87,107.52,0.276
108.88,107.67,0.277
108.90,107.82,0.277
108.91,107.97,0.278
108.93,108.12,0.279
108.94,108.27,0.279
108.96,108.42,0.280
108.97,108.57,0.280
108.99,108.72,0.281
109.00,108.87,0.281
109.02,109.02,0.282
109.03,109.17,0.282
109.05,109.32,0.283
109.06,109.47,0.283
109.08,109.62,0.284
109.09,109.77,0.284
109.11,109.92,0.285
109.12,110.07,0.285
109.14,110.22,0.286
109.15,110.37,0.287
109.17,110.52,0.287
109.18,110.67,0.288
109.20,110.82,0.288
109.21,110.97,0.289
109.23,111.12,0.289
109.24,111.27,0.290
109.26,111.42,0.290
109.27,111.57,0.291
109.29,111.72,0.291
109.30,111.87,0.292
109.32,112.02,0.292
109.33,112.17,0.293
109.35,112.32,0.293
109.36,112.47,0.294
109.38,112.62,0.294
109.39,112.77,0.295
109.41,112.92,0.295
109.42,113.07,0.296
109.44,113.22,0.296
109.45,113.38,0.297
109.47,113.52,0.297
109.48,113.67,0.298
109.50,113.83,0.298
109.51,113.97,0.298
109.53,114.12,0.299
109.54,114.27,0.299
109.56,114.42,0.299
109.57,114.57,0.300
109.59,114.72,0.300
109.60,114.87,0.300
109.62,115.02,0.301
109.63,115.17,0.301
109.65,115.32,0.301
109.66,115.47,0.302
109.68,115.62,0.302
109.69,115.77,0.302
109.71,115.92,0.303
109.72,116.07,0.303
109.74,116.22,0.303
109.75,116.37,0.303
109.77,116.53,0.304
109.78,116.67,0.304
109.80,116.82,0.304
109.81,116.97,0.304
109.83,117.12,0.305
109.84,117.28,0.305
109.86,117.43,0.305
109.87,117.58,0.305
109.89,117.73,0.305
109.90,117.88,0.305
109.92,118.03,0.306
109.93,118.18,0.306
109.95,118.33,0.306
109.96,118.48,0.306
109.98,118.63,0.306
109.99,118.78,0.306
110.01,118.93,0.306
110.02,119.08,0.306
110.04,119.23,0.307
110.05,119.38,0.307
110.07,119.53,0.307
110.08,119.68,0.307
110.10,119.83,0.307
110.11,119.98,0.307
110.13,120.13,0.307
110.14,120.28,0.307
110.16,120.43,0.307
110.17,120.58,0.307
110.19,120.73,0.307
110.20,120.88,0.307
110.22,121.03,0.307
110.23,121.18,0.307
110.25,121.33,0.307
110.26,121.48,0.307
110.28,121.63,0.307
110.29,121.78,0.307
110.31,121.93,0.307
110.32,122.08,0.307
110.34,122.23,0.307
110.35,122.38,0.307
110.37,122.53,0.307
110.38,122.68,0.307
110.40,122.83,0.307
110.41,122.98,0.307
110.43,123.13,0.307
110.44,123.28,0.307
110.46,123.43,0.307
110.47,123.58,0.307
110.49,123.73,0.307
110.50,123.88,0.307
110.52,124.03,0.307
110.53,124.18,0.307
110.55,124.33,0.307
110.56,124.48,0.307
110.58,124.63,0.307
110.59,124.78,0.307
110.61,124.93,0.307
110.62,125.08,0.307
110.64,125.23,0.307
110.65,125.38,0.307
110.67,125.53,0.308
110.68,125.68,0.308
110.70,125.83,0.308
110.71,125.98,0.308
110.73,126.13,0.308
110.74,126.28,0.308
110.76,126.43,0.308
110.77,126.58,0.308
110.79,126.73,0.308
110.80,126.88,0.308
110.82,127.03,0.308
110.83,127.18,0.308
110.85,127.33,0.308
110.86,127.48,0.308
110.88,127.63,0.308
110.89,127.79,0.308
110.91,127.93,0.308
110.92,128.09,0.308
110.94,128.23,0.308
110.95,128.38,0.308
110.97,128.53,0.308
110.98,128.69,0.308
111.00,128.84,0.308
111.01,128.99,0.308
111.03,129.14,0.308
111.04,129.28,0.308
111.06,129.44,0.308
111.07,129.59,0.308
111.09,129.74,0.308
111.10,129.89,0.309
111.12,130.04,0.309
111.13,130.19,0.309
111.15,130.34,0.309
111.16,130.49,0.309
111.18,130.64,0.309
111.19,130.79,0.309
111.21,130.94,0.309
111.22,131.09,0.309
111.24,131.24,0.309
111.25,131.39,0.309
111.27,131.54,0.309
111.28,131.69,0.309
111.30,131.84,0.309
111.31,131.99,0.309
111.33,132.14,0.309
111.34,132.29,0.310
111.36,132.44,0.310
111.37,132.59,0.310
111.39,132.74,0.310
111.40,132.89,0.310
111.42,133.04,0.310
111.43,133.19,0.310
111.45,133.34,0.310
111.46,133.49,0.310
111.48,133.64,0.310
111.49,133.79,0.310
111.51,133.94,0.310
111.52,134.09,0.311
111.54,134.24,0.311
111.55,134.39,0.311
111.57,134.54,0.311
111.58,134.69,0.311
111.60,134.84,0.311
111.61,134.99,0.311
111.63,135.14,0.311
111.64,135.29,0.311
111.66,135.44,0.311
111.67,135.59,0.311
111.69,135.74,0.311
111.70,135.89,0.311
111.72,136.04,0.312
111.73,136.19,0.312
111.75,136.34,0.312
111.76,136.49,0.312
111.78,136.64,0.312
111.79,136.79,0.312
111.81,136.94,0.312
111.82,137.09,0.312
111.84,137.24,0.312
111.85,137.39,0.312
111.87,137.54,0.312
111.88,137.69,0.312
111.90,137.84,0.312
111.91,137.99,0.313
111.93,138.14,0.313
111.94,138.29,0.313
111.96,138.44,0.313
111.97,138.59,0.313
111.99,138.74,0.313
112.00,138.89,0.313
112.02,139.04,0.313
112.03,139.19,0.313
112.05,139.34,0.313
112.06,139.49,0.313
112.08,139.64,0.314
112.09,139.79,0.314
112.11,139.94,0.314
112.12,140.09,0.314
112.14,140.24,0.314
112.15,140.39,0.314
112.17,140.54,0.314
112.18,140.69,0.314
112.20,140.84,0.314
112.21,140.99,0.314
112.23,141.14,0.314
112.24,141.29,0.314
112.26,141.44,0.315
112.27,141.59,0.315
112.29,141.74,0.315
112.30,141.89,0.315
112.32,142.04,0.315
112.33,142.19,0.315
112.35,142.34,0.315
112.36,142.49,0.315
112.38,142.64,0.315
112.39,142.79,0.315
112.41,142.94,0.315
112.42,143.09,0.315
112.44,143.24,0.316
112.45,143.39,0.316
112.47,143.54,0.316
112.48,143.69,0.316
112.50,143.85,0.316
112.51,144.00,0.316
112.53,144.14,0.316
112.54,144.30,0.316
112.56,144.45,0.316
112.57,144.60,0.316
112.59,144.75,0.317
112.60,144.90,0.317
112.62,145.05,0.317
112.63,145.20,0.317
112.65,145.35,0.317
112.66,145.50,0.317
112.68,145.65,0.317
112.69,145.80,0.317
112.71,145.95,0.317
112.72,146.10,0.317
112.74,146.25,0.317
112.75,146.40,0.318
112.77,146.55,0.318
112.78,146.70,0.318
112.80,146.85,0.318
112.81,147.00,0.318
112.83,147.15,0.318
112.84,147.30,0.318
112.86,147.45,0.318
112.87,147.60,0.318
112.89,147.75,0.318
112.90,147.90,0.318
112.92,148.05,0.319
112.93,148.20,0.319
112.95,148.35,
112.96,148.50,
112.98,148.65,
112.99,,